{"op":"mcm","clk":"11924058765","pt":1724621882271,"mc":[{"id":"1.232283784","marketDefinition":{"bspMarket":false,"turnInPlayEnabled":true,"persistenceEnabled":true,"marketBaseRate":5.0,"eventId":"33527241","eventTypeId":"4","numberOfWinners":1,"bettingType":"ODDS","marketType":"MATCH_ODDS","marketTime":"2024-08-30T09:30:00.000Z","suspendTime":"2024-08-30T09:30:00.000Z","bspReconciled":false,"complete":true,"inPlay":false,"crossMatching":false,"runnersVoidable":false,"numberOfActiveRunners":2,"betDelay":0,"status":"OPEN","runners":[{"status":"ACTIVE","sortPriority":1,"id":35736915,"name":"Central Sparks"},{"status":"ACTIVE","sortPriority":2,"id":11445382,"name":"Southern Vipers"}],"regulators":["MR_INT"],"countryCode":"GB","discountAllowed":false,"timezone":"GMT","openDate":"2024-08-30T09:30:00.000Z","version":6100646655,"name":"Match Odds","eventName":"Central Sparks v Southern Vipers"},"rc":[{"batb":[[0,1.03,200],[1,1.02,200],[2,1.01,220]],"ltp":0.0,"tv":0.0,"id":35736915},{"batb":[[0,1.03,200],[1,1.02,200],[2,1.01,220]],"ltp":0.0,"tv":0.0,"id":11445382}]}]}
{"op":"mcm","clk":"11924058918","pt":1724621883869,"mc":[{"id":"1.232283784","marketDefinition":{"bspMarket":false,"turnInPlayEnabled":true,"persistenceEnabled":true,"marketBaseRate":5.0,"eventId":"33527241","eventTypeId":"4","numberOfWinners":1,"bettingType":"ODDS","marketType":"MATCH_ODDS","marketTime":"2024-08-30T09:30:00.000Z","suspendTime":"2024-08-30T09:30:00.000Z","bspReconciled":false,"complete":true,"inPlay":false,"crossMatching":false,"runnersVoidable":false,"numberOfActiveRunners":2,"betDelay":0,"status":"OPEN","runners":[{"status":"ACTIVE","sortPriority":1,"id":35736915,"name":"Central Sparks"},{"status":"ACTIVE","sortPriority":2,"id":11445382,"name":"Southern Vipers"}],"regulators":["MR_INT"],"countryCode":"GB","discountAllowed":true,"timezone":"GMT","openDate":"2024-08-30T09:30:00.000Z","version":6100646655,"name":"Match Odds","eventName":"Central Sparks v Southern Vipers"}}]}
{"op":"mcm","clk":"11925115383","pt":1724639454362,"mc":[{"id":"1.232283784","rc":[{"batb":[[2,1.01,480.05]],"ltp":0.0,"tv":0.0,"id":35736915},{"batb":[[2,1.01,480.05]],"ltp":0.0,"tv":0.0,"id":11445382}]}]}
{"op":"mcm","clk":"11925405494","pt":1724645574805,"mc":[{"id":"1.232283784","rc":[{"batb":[[2,1.01,480.03]],"ltp":0.0,"tv":0.0,"id":35736915},{"batb":[[2,1.01,480.03]],"ltp":0.0,"tv":0.0,"id":11445382}]}]}
{"op":"mcm","clk":"11925669069","pt":1724650974822,"mc":[{"id":"1.232283784","rc":[{"batb":[[2,1.01,480.1]],"ltp":0.0,"tv":0.0,"id":35736915},{"batb":[[2,1.01,480.1]],"ltp":0.0,"tv":0.0,"id":11445382}]}]}
{"op":"mcm","clk":"11925918562","pt":1724656374803,"mc":[{"id":"1.232283784","rc":[{"batb":[[2,1.01,479.96]],"ltp":0.0,"tv":0.0,"id":35736915},{"batb":[[2,1.01,479.96]],"ltp":0.0,"tv":0.0,"id":11445382}]}]}
{"op":"mcm","clk":"11926160811","pt":1724661774799,"mc":[{"id":"1.232283784","rc":[{"batb":[[2,1.01,480.47]],"ltp":0.0,"tv":0.0,"id":35736915},{"batb":[[2,1.01,480.47]],"ltp":0.0,"tv":0.0,"id":11445382}]}]}
{"op":"mcm","clk":"11926295270","pt":1724664674860,"mc":[{"id":"1.232283784","rc":[{"batb":[[0,1.4,250],[1,1.2,500],[2,1.15,333.33]],"ltp":0.0,"tv":0.0,"id":35736915},{"batb":[[0,1.4,250],[1,1.3,333.33],[2,1.2,500]],"ltp":0.0,"tv":0.0,"id":11445382}]}]}
{"op":"mcm","clk":"11926295290","pt":1724664675378,"mc":[{"id":"1.232283784","rc":[{"batb":[[1,1.3,333.33],[2,1.25,200]],"ltp":0.0,"tv":0.0,"id":35736915},{"batb":[[2,1.25,200]],"ltp":0.0,"tv":0.0,"id":11445382}]}]}
{"op":"mcm","clk":"11926296323","pt":1724664698812,"mc":[{"id":"1.232283784","marketDefinition":{"bspMarket":false,"turnInPlayEnabled":true,"persistenceEnabled":true,"marketBaseRate":5.0,"eventId":"33527241","eventTypeId":"4","numberOfWinners":1,"bettingType":"ODDS","marketType":"MATCH_ODDS","marketTime":"2024-08-30T09:30:00.000Z","suspendTime":"2024-08-30T09:30:00.000Z","bspReconciled":false,"complete":true,"inPlay":false,"crossMatching":true,"runnersVoidable":false,"numberOfActiveRunners":2,"betDelay":0,"status":"OPEN","runners":[{"status":"ACTIVE","sortPriority":1,"id":35736915,"name":"Central Sparks"},{"status":"ACTIVE","sortPriority":2,"id":11445382,"name":"Southern Vipers"}],"regulators":["MR_INT"],"countryCode":"GB","discountAllowed":true,"timezone":"GMT","openDate":"2024-08-30T09:30:00.000Z","version":6100646655,"name":"Match Odds","eventName":"Central Sparks v Southern Vipers"}}]}
{"op":"mcm","clk":"11926322285","pt":1724665255661,"mc":[{"id":"1.232283784","rc":[{"batl":[[0,3.2,0.93]],"ltp":0.0,"tv":0.0,"id":35736915}]}]}
{"op":"mcm","clk":"11926322753","pt":1724665265649,"mc":[{"id":"1.232283784","rc":[{"batl":[[0,3.2,0.93]],"ltp":0.0,"tv":0.0,"id":11445382}]}]}
{"op":"mcm","clk":"11926349599","pt":1724666020853,"mc":[{"id":"1.232283784","rc":[{"batb":[[0,1.41,12.38],[1,1.4,250],[2,1.3,333.33]],"batl":[[0,3.45,5.88]],"ltp":0.0,"tv":0.0,"id":35736915},{"batb":[[0,1.41,12.38],[1,1.4,250],[2,1.3,333.33]],"batl":[[0,3.45,5.88]],"ltp":0.0,"tv":0.0,"id":11445382}]}]}
{"op":"mcm","clk":"11926398429","pt":1724667174808,"mc":[{"id":"1.232283784","rc":[{"batb":[[0,1.41,12.38]],"batl":[[0,3.45,5.88]],"ltp":0.0,"tv":0.0,"id":35736915},{"batb":[[0,1.41,12.38]],"batl":[[0,3.45,5.88]],"ltp":0.0,"tv":0.0,"id":11445382}]}]}
{"op":"mcm","clk":"11926470287","pt":1724668524692,"mc":[{"id":"1.232283784","rc":[{"batb":[[0,1.41,18.88]],"ltp":0.0,"tv":0.0,"id":35736915}]}]}
{"op":"mcm","clk":"11926470296","pt":1724668524901,"mc":[{"id":"1.232283784","rc":[{"batb":[[0,1.41,19.36]],"ltp":0.0,"tv":0.0,"id":11445382}]}]}
{"op":"mcm","clk":"11926520966","pt":1724669513751,"mc":[{"id":"1.232283784","rc":[{"batb":[[1,1.03,200],[2,1.02,200]],"ltp":0.0,"tv":0.0,"id":35736915},{"batb":[[1,1.03,200],[2,1.02,200]],"ltp":0.0,"tv":0.0,"id":11445382}]}]}
{"op":"mcm","clk":"11926521035","pt":1724669515246,"mc":[{"id":"1.232283784","rc":[{"batb":[[0,1.41,6.5]],"batl":[[0,3.2,0.93]],"ltp":0.0,"tv":0.0,"id":35736915},{"batb":[[0,1.41,6.98]],"batl":[[0,3.2,0.93]],"ltp":0.0,"tv":0.0,"id":11445382}]}]}
{"op":"mcm","clk":"11926523631","pt":1724669565666,"mc":[{"id":"1.232283784","rc":[{"batb":[[1,1.2,125],[2,1.03,200]],"ltp":0.0,"tv":0.0,"id":35736915},{"batb":[[1,1.2,125],[2,1.03,200]],"ltp":0.0,"tv":0.0,"id":11445382}]}]}
{"op":"mcm","clk":"11926673628","pt":1724672574807,"mc":[{"id":"1.232283784","rc":[{"batb":[[0,1.41,6.49]],"ltp":0.0,"tv":0.0,"id":35736915},{"batb":[[0,1.41,6.98]],"ltp":0.0,"tv":0.0,"id":11445382}]}]}
{"op":"mcm","clk":"11926687661","pt":1724672638459,"mc":[{"id":"1.232283784","rc":[{"batb":[[0,1.21,6.49]],"ltp":0.0,"tv":0.0,"id":35736915}]}]}
{"op":"mcm","clk":"11926687696","pt":1724672638981,"mc":[{"id":"1.232283784","rc":[{"batb":[[0,1.21,6.98]],"ltp":0.0,"tv":0.0,"id":11445382}]}]}
{"op":"mcm","clk":"11926856889","pt":1724675569047,"mc":[{"id":"1.232283784","rc":[{"batb":[[0,1.46,18.5],[1,1.21,6.5],[2,1.2,125]],"ltp":0.0,"tv":0.0,"id":35736915},{"batb":[[0,1.46,18.5],[1,1.21,6.98],[2,1.2,125]],"ltp":0.0,"tv":0.0,"id":11445382}]}]}
{"op":"mcm","clk":"11926959049","pt":1724677371866,"mc":[{"id":"1.232283784","rc":[{"batb":[[0,1.21,6.49],[1,1.2,125],[2,1.03,200]],"ltp":0.0,"tv":0.0,"id":35736915},{"batb":[[0,1.46,18.48],[1,1.21,6.98]],"ltp":0.0,"tv":0.0,"id":11445382}]}]}
{"op":"mcm","clk":"11926959060","pt":1724677371970,"mc":[{"id":"1.232283784","rc":[{"batb":[[0,1.21,6.98],[1,1.2,125],[2,1.03,200]],"ltp":0.0,"tv":0.0,"id":11445382}]}]}
{"op":"mcm","clk":"11926970319","pt":1724677523223,"mc":[{"id":"1.232283784","rc":[{"batb":[[0,1.46,18.48],[1,1.21,6.49],[2,1.2,125]],"ltp":0.0,"tv":0.0,"id":35736915},{"batb":[[0,1.46,18.48],[1,1.21,6.98],[2,1.2,125]],"ltp":0.0,"tv":0.0,"id":11445382}]}]}
{"op":"mcm","clk":"11927144868","pt":1724679324295,"mc":[{"id":"1.232283784","rc":[{"batb":[[0,1.21,6.49],[1,1.2,125],[2,1.03,200]],"ltp":0.0,"tv":0.0,"id":35736915},{"batb":[[0,1.21,6.98],[1,1.2,125],[2,1.03,200]],"ltp":0.0,"tv":0.0,"id":11445382}]}]}
{"op":"mcm","clk":"11927160473","pt":1724679475592,"mc":[{"id":"1.232283784","rc":[{"batb":[[0,1.46,18.48],[1,1.21,6.49],[2,1.2,125]],"ltp":0.0,"tv":0.0,"id":35736915},{"batb":[[0,1.46,18.48],[1,1.21,6.98],[2,1.2,125]],"ltp":0.0,"tv":0.0,"id":11445382}]}]}
{"op":"mcm","clk":"11927374733","pt":1724681277227,"mc":[{"id":"1.232283784","rc":[{"batb":[[0,1.21,6.5],[1,1.2,125],[2,1.03,200]],"ltp":0.0,"tv":0.0,"id":35736915},{"batb":[[0,1.21,6.98],[1,1.2,125],[2,1.03,200]],"ltp":0.0,"tv":0.0,"id":11445382}]}]}
{"op":"mcm","clk":"11927402499","pt":1724681426584,"mc":[{"id":"1.232283784","rc":[{"batb":[[0,1.46,18.49],[1,1.21,6.5],[2,1.2,125]],"ltp":0.0,"tv":0.0,"id":35736915},{"batb":[[0,1.46,18.49],[1,1.21,6.98],[2,1.2,125]],"ltp":0.0,"tv":0.0,"id":11445382}]}]}
{"op":"mcm","clk":"11927764156","pt":1724683226780,"mc":[{"id":"1.232283784","rc":[{"batb":[[0,1.21,6.5],[1,1.2,125],[2,1.03,200]],"ltp":0.0,"tv":0.0,"id":35736915}]}]}
{"op":"mcm","clk":"11927764198","pt":1724683226988,"mc":[{"id":"1.232283784","rc":[{"batb":[[0,1.21,6.98],[1,1.2,125],[2,1.03,200]],"ltp":0.0,"tv":0.0,"id":11445382}]}]}
{"op":"mcm","clk":"11927808590","pt":1724683383555,"mc":[{"id":"1.232283784","rc":[{"batb":[[0,1.46,18.49],[1,1.21,6.5],[2,1.2,125]],"ltp":0.0,"tv":0.0,"id":35736915},{"batb":[[0,1.46,18.49],[1,1.21,6.98],[2,1.2,125]],"ltp":0.0,"tv":0.0,"id":11445382}]}]}
{"op":"mcm","clk":"11928096534","pt":1724685188577,"mc":[{"id":"1.232283784","rc":[{"batb":[[0,1.21,6.49],[1,1.2,125],[2,1.03,200]],"ltp":0.0,"tv":0.0,"id":35736915},{"batb":[[0,1.21,6.98],[1,1.2,125],[2,1.03,200]],"ltp":0.0,"tv":0.0,"id":11445382}]}]}
{"op":"mcm","clk":"11928123035","pt":1724685328354,"mc":[{"id":"1.232283784","rc":[{"batb":[[0,1.46,18.5],[1,1.21,6.49],[2,1.2,125]],"ltp":0.0,"tv":0.0,"id":35736915},{"batb":[[0,1.46,18.5],[1,1.21,6.98],[2,1.2,125]],"ltp":0.0,"tv":0.0,"id":11445382}]}]}
{"op":"mcm","clk":"11928338975","pt":1724686466046,"mc":[{"id":"1.232283784","rc":[{"batb":[[2,1.03,200]],"ltp":0.0,"tv":0.0,"id":35736915},{"batb":[[2,1.03,200]],"ltp":0.0,"tv":0.0,"id":11445382}]}]}
{"op":"mcm","clk":"11928352076","pt":1724686536025,"mc":[{"id":"1.232283784","rc":[{"batb":[[2,1.2,1000]],"ltp":0.0,"tv":0.0,"id":35736915},{"batb":[[2,1.2,1000]],"ltp":0.0,"tv":0.0,"id":11445382}]}]}
{"op":"mcm","clk":"11928455359","pt":1724687131074,"mc":[{"id":"1.232283784","rc":[{"batb":[[0,1.21,6.49],[1,1.2,1000],[2,1.03,200]],"ltp":0.0,"tv":0.0,"id":35736915},{"batb":[[0,1.21,6.98],[1,1.2,1000],[2,1.03,200]],"ltp":0.0,"tv":0.0,"id":11445382}]}]}
{"op":"mcm","clk":"11928475271","pt":1724687254192,"mc":[{"id":"1.232283784","rc":[{"batb":[[0,1.46,18.5],[1,1.21,6.49],[2,1.2,1000]],"ltp":0.0,"tv":0.0,"id":35736915},{"batb":[[0,1.46,18.5],[1,1.21,6.98],[2,1.2,1000]],"ltp":0.0,"tv":0.0,"id":11445382}]}]}
{"op":"mcm","clk":"11928657958","pt":1724688774834,"mc":[{"id":"1.232283784","rc":[{"batb":[[0,1.46,18.51],[1,1.21,6.5]],"batl":[[0,3.2,0.93]],"ltp":0.0,"tv":0.0,"id":35736915},{"batb":[[0,1.46,18.51],[1,1.21,6.99]],"batl":[[0,3.2,0.93]],"ltp":0.0,"tv":0.0,"id":11445382}]}]}
{"op":"mcm","clk":"11928703408","pt":1724689059804,"mc":[{"id":"1.232283784","rc":[{"batb":[[0,1.21,6.5],[1,1.2,1000],[2,1.03,200]],"ltp":0.0,"tv":0.0,"id":35736915},{"batb":[[0,1.21,6.99],[1,1.2,1000],[2,1.03,200]],"ltp":0.0,"tv":0.0,"id":11445382}]}]}
{"op":"mcm","clk":"11928703697","pt":1724689062129,"mc":[{"id":"1.232283784","rc":[{"batl":[[0,5.9,10.86]],"ltp":0.0,"tv":0.0,"id":35736915},{"batl":[[0,5.9,10.86]],"ltp":0.0,"tv":0.0,"id":11445382}]}]}
{"op":"mcm","clk":"11928711296","pt":1724689126320,"mc":[{"id":"1.232283784","rc":[{"batb":[[0,1.46,18.51],[1,1.21,6.5],[2,1.2,1000]],"ltp":0.0,"tv":0.0,"id":35736915},{"batb":[[0,1.46,18.51],[1,1.21,6.99],[2,1.2,1000]],"ltp":0.0,"tv":0.0,"id":11445382}]}]}
{"op":"mcm","clk":"11928711860","pt":1724689130702,"mc":[{"id":"1.232283784","rc":[{"batl":[[0,3.2,0.93]],"ltp":0.0,"tv":0.0,"id":35736915},{"batl":[[0,3.2,0.93]],"ltp":0.0,"tv":0.0,"id":11445382}]}]}
{"op":"mcm","clk":"11928923598","pt":1724690931811,"mc":[{"id":"1.232283784","rc":[{"batb":[[0,1.21,6.99],[1,1.2,1000],[2,1.03,200]],"ltp":0.0,"tv":0.0,"id":11445382}]}]}
{"op":"mcm","clk":"11928923622","pt":1724690932023,"mc":[{"id":"1.232283784","rc":[{"batb":[[0,1.21,6.5],[1,1.2,1000],[2,1.03,200]],"ltp":0.0,"tv":0.0,"id":35736915}]}]}
{"op":"mcm","clk":"11928923904","pt":1724690934537,"mc":[{"id":"1.232283784","rc":[{"batl":[[0,5.9,10.86]],"ltp":0.0,"tv":0.0,"id":35736915},{"batl":[[0,5.9,10.86]],"ltp":0.0,"tv":0.0,"id":11445382}]}]}
{"op":"mcm","clk":"11928924312","pt":1724690938031,"mc":[{"id":"1.232283784","rc":[{"batb":[[0,2.3,3.13],[1,1.21,6.5],[2,1.2,1000]],"ltp":0.0,"tv":0.0,"id":35736915},{"batb":[[0,1.7,5.83],[1,1.21,6.99],[2,1.2,1000]],"ltp":0.0,"tv":0.0,"id":11445382}]}]}
{"op":"mcm","clk":"11929188019","pt":1724693091394,"mc":[{"id":"1.232283784","rc":[{"batb":[[1,1.2,1000],[2,1.03,200]],"batl":[[0,5.9,10.86]],"ltp":0.0,"tv":0.0,"id":35736915},{"batb":[[1,1.2,1000],[2,1.03,200]],"batl":[[0,5.9,10.86]],"ltp":0.0,"tv":0.0,"id":11445382}]}]}
{"op":"mcm","clk":"11930589106","pt":1724704974798,"mc":[{"id":"1.232283784","rc":[{"batl":[[0,5.9,10.86]],"ltp":0.0,"tv":0.0,"id":35736915},{"batl":[[0,5.9,10.86]],"ltp":0.0,"tv":0.0,"id":11445382}]}]}
{"op":"mcm","clk":"11930908873","pt":1724709941541,"mc":[{"id":"1.232283784","rc":[{"batl":[[0,5.9,10.85]],"ltp":0.0,"tv":0.0,"id":35736915},{"batl":[[0,5.9,10.85]],"ltp":0.0,"tv":0.0,"id":11445382}]}]}
{"op":"mcm","clk":"11931233929","pt":1724715774802,"mc":[{"id":"1.232283784","rc":[{"batl":[[0,5.9,10.86]],"ltp":0.0,"tv":0.0,"id":35736915},{"batl":[[0,5.9,10.86]],"ltp":0.0,"tv":0.0,"id":11445382}]}]}
{"op":"mcm","clk":"11931525133","pt":1724720287797,"mc":[{"id":"1.232283784","rc":[{"batl":[[0,5.9,9.93]],"ltp":0.0,"tv":0.0,"id":11445382}]}]}
{"op":"mcm","clk":"11931525360","pt":1724720291699,"mc":[{"id":"1.232283784","rc":[{"batl":[[0,5.9,9.93]],"ltp":0.0,"tv":0.0,"id":35736915}]}]}
{"op":"mcm","clk":"11931527516","pt":1724720334699,"mc":[{"id":"1.232283784","rc":[{"batb":[[1,1.33,7.39],[2,1.2,1000]],"ltp":0.0,"tv":0.0,"id":11445382}]}]}
{"op":"mcm","clk":"11931529211","pt":1724720368645,"mc":[{"id":"1.232283784","rc":[{"batl":[[0,3.8,2.78],[1,5.9,9.93]],"ltp":0.0,"tv":0.0,"id":11445382}]}]}
{"op":"mcm","clk":"11931529903","pt":1724720383772,"mc":[{"id":"1.232283784","rc":[{"batl":[[0,5.9,9.93],[1,5.9,0]],"ltp":0.0,"tv":0.0,"id":11445382}]}]}
{"op":"mcm","clk":"11931529908","pt":1724720383876,"mc":[{"id":"1.232283784","rc":[{"batl":[[0,3.8,2.78],[1,5.9,9.93]],"ltp":0.0,"tv":0.0,"id":11445382}]}]}
{"op":"mcm","clk":"11931566026","pt":1724721174790,"mc":[{"id":"1.232283784","rc":[{"batl":[[0,5.9,9.93]],"ltp":0.0,"tv":0.0,"id":35736915},{"batb":[[1,1.33,7.39]],"batl":[[0,3.8,2.78],[1,5.9,9.93]],"ltp":0.0,"tv":0.0,"id":11445382}]}]}
{"op":"mcm","clk":"11931786615","pt":1724726574788,"mc":[{"id":"1.232283784","rc":[{"batl":[[0,5.9,9.93]],"ltp":0.0,"tv":0.0,"id":35736915},{"batb":[[1,1.33,7.39]],"batl":[[0,3.8,2.78],[1,5.9,9.93]],"ltp":0.0,"tv":0.0,"id":11445382}]}]}
{"op":"mcm","clk":"11931985563","pt":1724731974789,"mc":[{"id":"1.232283784","rc":[{"batb":[[1,1.33,7.39]],"ltp":0.0,"tv":0.0,"id":11445382}]}]}
{"op":"mcm","clk":"11932409139","pt":1724742774789,"mc":[{"id":"1.232283784","rc":[{"batl":[[0,5.9,9.92]],"ltp":0.0,"tv":0.0,"id":35736915},{"batb":[[1,1.33,7.39]],"batl":[[1,5.9,9.92]],"ltp":0.0,"tv":0.0,"id":11445382}]}]}
{"op":"mcm","clk":"11932641799","pt":1724748174792,"mc":[{"id":"1.232283784","rc":[{"batl":[[0,5.9,9.92]],"ltp":0.0,"tv":0.0,"id":35736915},{"batb":[[1,1.33,7.38]],"batl":[[0,3.8,2.78],[1,5.9,9.92]],"ltp":0.0,"tv":0.0,"id":11445382}]}]}
{"op":"mcm","clk":"11932944721","pt":1724753574790,"mc":[{"id":"1.232283784","rc":[{"batl":[[0,5.9,9.9]],"ltp":0.0,"tv":0.0,"id":35736915},{"batb":[[1,1.33,7.36]],"batl":[[0,3.8,2.77],[1,5.9,9.9]],"ltp":0.0,"tv":0.0,"id":11445382}]}]}
{"op":"mcm","clk":"11933031021","pt":1724754624332,"mc":[{"id":"1.232283784","rc":[{"batb":[[1,1.03,200],[2,1.02,200]],"ltp":0.0,"tv":0.0,"id":35736915},{"batb":[[2,1.03,200]],"ltp":0.0,"tv":0.0,"id":11445382}]}]}
{"op":"mcm","clk":"11933031089","pt":1724754625267,"mc":[{"id":"1.232283784","rc":[{"batl":[[1,5.9,0]],"ltp":0.0,"tv":0.0,"id":11445382}]}]}
{"op":"mcm","clk":"11933397774","pt":1724758974795,"mc":[{"id":"1.232283784","rc":[{"batb":[[1,1.33,7.37]],"batl":[[0,3.8,2.77]],"ltp":0.0,"tv":0.0,"id":11445382}]}]}
{"op":"mcm","clk":"11933791582","pt":1724763617909,"mc":[{"id":"1.232283784","rc":[{"batb":[[1,1.2,1000],[2,1.03,200]],"ltp":0.0,"tv":0.0,"id":35736915},{"batb":[[2,1.2,1000]],"ltp":0.0,"tv":0.0,"id":11445382}]}]}
{"op":"mcm","clk":"11933791810","pt":1724763621305,"mc":[{"id":"1.232283784","rc":[{"batl":[[0,5.9,10.13]],"ltp":0.0,"tv":0.0,"id":35736915},{"batl":[[1,5.9,10.16]],"ltp":0.0,"tv":0.0,"id":11445382}]}]}
{"op":"mcm","clk":"11933954264","pt":1724765716024,"mc":[{"id":"1.232283784","rc":[{"batb":[[0,2.3,3.1]],"ltp":0.0,"tv":0.0,"id":35736915},{"batb":[[0,1.7,5.77]],"ltp":0.0,"tv":0.0,"id":11445382}]}]}
{"op":"mcm","clk":"11934231562","pt":1724769408341,"mc":[{"id":"1.232283784","rc":[{"batb":[[2,1.04,1.05]],"batl":[[0,5.9,10.13]],"ltp":0.0,"tv":0.0,"id":35736915},{"batb":[[1,1.33,7.36]],"batl":[[0,3.8,2.77],[1,5.9,10.16]],"ltp":0.0,"tv":0.0,"id":11445382}]}]}
{"op":"mcm","clk":"11934597312","pt":1724772736318,"mc":[{"id":"1.232283784","rc":[{"batl":[[0,5.9,10.13]],"ltp":0.0,"tv":0.0,"id":35736915},{"batb":[[1,1.2,1000],[2,1.04,1.05]],"batl":[[0,5.9,10.15],[1,5.9,0]],"ltp":0.0,"tv":0.0,"id":11445382}]}]}
{"op":"mcm","clk":"11934900992","pt":1724775174794,"mc":[{"id":"1.232283784","rc":[{"batl":[[0,5.9,10.12]],"ltp":0.0,"tv":0.0,"id":35736915},{"batl":[[0,5.9,10.15]],"ltp":0.0,"tv":0.0,"id":11445382}]}]}
{"op":"mcm","clk":"11935616219","pt":1724780574789,"mc":[{"id":"1.232283784","rc":[{"batl":[[0,5.9,10.13]],"ltp":0.0,"tv":0.0,"id":35736915},{"batl":[[0,5.9,10.15]],"ltp":0.0,"tv":0.0,"id":11445382}]}]}
{"op":"mcm","clk":"11936519012","pt":1724785974809,"mc":[{"id":"1.232283784","rc":[{"batl":[[0,5.9,10.12]],"ltp":0.0,"tv":0.0,"id":35736915},{"batl":[[0,5.9,10.15]],"ltp":0.0,"tv":0.0,"id":11445382}]}]}
{"op":"mcm","clk":"11937321874","pt":1724791374779,"mc":[{"id":"1.232283784","rc":[{"batl":[[0,5.9,10.12]],"ltp":0.0,"tv":0.0,"id":35736915},{"batl":[[0,5.9,10.15]],"ltp":0.0,"tv":0.0,"id":11445382}]}]}
{"op":"mcm","clk":"11937623544","pt":1724796774778,"mc":[{"id":"1.232283784","rc":[{"batl":[[0,5.9,10.12]],"ltp":0.0,"tv":0.0,"id":35736915},{"batl":[[0,5.9,10.15]],"ltp":0.0,"tv":0.0,"id":11445382}]}]}
{"op":"mcm","clk":"11937860730","pt":1724802174775,"mc":[{"id":"1.232283784","rc":[{"batl":[[0,5.9,10.12]],"ltp":0.0,"tv":0.0,"id":35736915},{"batl":[[0,5.9,10.15]],"ltp":0.0,"tv":0.0,"id":11445382}]}]}
{"op":"mcm","clk":"11938145444","pt":1724807574774,"mc":[{"id":"1.232283784","rc":[{"batl":[[0,5.9,10.12]],"ltp":0.0,"tv":0.0,"id":35736915},{"batl":[[0,5.9,10.14]],"ltp":0.0,"tv":0.0,"id":11445382}]}]}
{"op":"mcm","clk":"11938654427","pt":1724818374775,"mc":[{"id":"1.232283784","rc":[{"batl":[[0,5.9,10.11]],"ltp":0.0,"tv":0.0,"id":35736915},{"batl":[[0,5.9,10.14]],"ltp":0.0,"tv":0.0,"id":11445382}]}]}
{"op":"mcm","clk":"11938851702","pt":1724823774782,"mc":[{"id":"1.232283784","rc":[{"batl":[[0,5.9,10.11]],"ltp":0.0,"tv":0.0,"id":35736915},{"batl":[[0,5.9,10.14]],"ltp":0.0,"tv":0.0,"id":11445382}]}]}
{"op":"mcm","clk":"11938867405","pt":1724824022819,"mc":[{"id":"1.232283784","rc":[{"trd":[[2.3,6.2]],"batb":[[0,1.2,1000],[1,1.04,1.05],[2,1.03,200]],"batl":[[0,5.9,10.91]],"ltp":2.3,"tv":6.2,"id":35736915}],"tv":6.2}]}
{"op":"mcm","clk":"11938867488","pt":1724824025486,"mc":[{"id":"1.232283784","rc":[{"batb":[[0,2.22,3.31],[1,1.2,1000],[2,1.04,1.05]],"ltp":2.3,"tv":6.2,"id":35736915}]}]}
{"op":"mcm","clk":"11938869642","pt":1724824109720,"mc":[{"id":"1.232283784","rc":[{"batl":[[0,5.9,10.11]],"ltp":2.3,"tv":6.2,"id":35736915}]}]}
{"op":"mcm","clk":"11938870317","pt":1724824135841,"mc":[{"id":"1.232283784","rc":[{"trd":[[2.22,6.62]],"batb":[[0,2.14,3.54]],"batl":[[0,2.22,1],[1,5.9,10.11]],"ltp":2.22,"tv":12.82,"id":35736915}],"tv":12.82}]}
{"op":"mcm","clk":"11938872020","pt":1724824200589,"mc":[{"id":"1.232283784","rc":[{"trd":[[2.22,7.62]],"batl":[[0,5.9,10.11],[1,5.9,0]],"ltp":2.22,"tv":13.82,"id":35736915},{"trd":[[1.81,1.23]],"batl":[[0,1.81,4.77]],"ltp":1.81,"tv":1.23,"id":11445382}],"tv":15.05}]}
{"op":"mcm","clk":"11938872417","pt":1724824213713,"mc":[{"id":"1.232283784","rc":[{"batl":[[0,5.9,10.02]],"ltp":1.81,"tv":1.23,"id":11445382}]}]}
{"op":"mcm","clk":"11938873929","pt":1724824263165,"mc":[{"id":"1.232283784","rc":[{"trd":[[2.14,7.08]],"batb":[[0,1.2,1000],[1,1.04,1.05],[2,1.03,200]],"batl":[[0,2.14,1.46],[1,5.9,10.11]],"ltp":2.14,"tv":20.9,"id":35736915}],"tv":22.13}]}
{"op":"mcm","clk":"11938874025","pt":1724824266187,"mc":[{"id":"1.232283784","rc":[{"batb":[[0,2.06,3.81],[1,1.2,1000],[2,1.04,1.05]],"ltp":2.14,"tv":20.9,"id":35736915}]}]}
{"op":"mcm","clk":"11938874054","pt":1724824267062,"mc":[{"id":"1.232283784","rc":[{"batl":[[0,5.9,10.11],[1,5.9,0]],"ltp":2.14,"tv":20.9,"id":35736915}]}]}
{"op":"mcm","clk":"11939155162","pt":1724833212090,"mc":[{"id":"1.232283784","rc":[{"batl":[[0,5.9,10.12]],"ltp":2.14,"tv":20.9,"id":35736915},{"trd":[[1.7,11.54]],"batb":[[0,1.2,1000],[1,1.04,1.05],[2,1.03,200]],"batl":[[0,1.7,86.65],[1,5.9,10.02]],"ltp":1.7,"tv":12.77,"id":11445382}],"tv":33.67}]}
{"op":"mcm","clk":"11939155225","pt":1724833214184,"mc":[{"id":"1.232283784","rc":[{"batl":[[1,5.9,0]],"ltp":1.7,"tv":12.77,"id":11445382}]}]}
{"op":"mcm","clk":"11939155281","pt":1724833215410,"mc":[{"id":"1.232283784","rc":[{"batb":[[0,1.66,6.12],[1,1.2,1000],[2,1.04,1.05]],"ltp":1.7,"tv":12.77,"id":11445382}]}]}
{"op":"mcm","clk":"11939159841","pt":1724833330321,"mc":[{"id":"1.232283784","rc":[{"trd":[[1.66,12.24]],"batb":[[0,1.2,1000],[1,1.04,1.05],[2,1.03,200]],"batl":[[0,1.66,80.53]],"ltp":1.66,"tv":25.01,"id":11445382}],"tv":45.91}]}
{"op":"mcm","clk":"11939159861","pt":1724833330889,"mc":[{"id":"1.232283784","rc":[{"batb":[[0,1.62,6.51],[1,1.2,1000],[2,1.04,1.05]],"ltp":1.66,"tv":25.01,"id":11445382}]}]}
{"op":"mcm","clk":"11939354881","pt":1724837401747,"mc":[{"id":"1.232283784","rc":[{"batb":[[0,2.06,38.12]],"batl":[[0,5.9,10.11]],"ltp":2.14,"tv":20.9,"id":35736915},{"trd":[[1.66,12.25],[1.7,11.55]],"batb":[[0,1.62,65.18]],"batl":[[0,1.66,80.59]],"ltp":1.66,"tv":25.02,"id":11445382}],"tv":45.92}]}
{"op":"mcm","clk":"11939499651","pt":1724839967772,"mc":[{"id":"1.232283784","rc":[{"trd":[[1.62,129.46],[1.66,12.24],[1.7,11.54]],"batb":[[0,1.23,199.16]],"batl":[[0,1.66,80.58]],"ltp":1.62,"tv":154.47,"id":11445382}],"tv":175.37}]}
{"op":"mcm","clk":"11939499690","pt":1724839968695,"mc":[{"id":"1.232283784","rc":[{"batb":[[0,1.58,69.68],[1,1.23,198.71],[2,1.2,1000]],"ltp":1.62,"tv":154.47,"id":11445382}]}]}
{"op":"mcm","clk":"11939518952","pt":1724840133472,"mc":[{"id":"1.232283784","rc":[{"batb":[[1,1.2,1000],[2,1.04,1.05]],"ltp":1.62,"tv":154.47,"id":11445382}]}]}
{"op":"mcm","clk":"11939868084","pt":1724845374775,"mc":[{"id":"1.232283784","rc":[{"trd":[[1.62,129.44],[1.66,12.24],[1.7,11.54]],"batl":[[0,1.66,80.55]],"ltp":1.62,"tv":154.45,"id":11445382}],"tv":175.35}]}
{"op":"mcm","clk":"11940357906","pt":1724850774780,"mc":[{"id":"1.232283784","rc":[{"trd":[[1.62,129.34],[1.66,12.23],[1.7,11.53]],"batl":[[0,1.66,80.43]],"ltp":1.62,"tv":154.33,"id":11445382}],"tv":175.23}]}
{"op":"mcm","clk":"11940499004","pt":1724852113826,"mc":[{"id":"1.232283784","rc":[{"batb":[[0,2.06,74.55]],"ltp":2.14,"tv":20.9,"id":35736915},{"batb":[[0,1.58,136.26]],"ltp":1.62,"tv":154.33,"id":11445382}]}]}
{"op":"mcm","clk":"11940499015","pt":1724852113931,"mc":[{"id":"1.232283784","rc":[{"batb":[[0,2.06,36.43]],"ltp":2.14,"tv":20.9,"id":35736915},{"batb":[[0,1.58,66.58]],"ltp":1.62,"tv":154.33,"id":11445382}]}]}
{"op":"mcm","clk":"11940896841","pt":1724856174780,"mc":[{"id":"1.232283784","rc":[{"trd":[[1.62,129.44],[1.66,12.24],[1.7,11.54]],"batl":[[0,1.66,80.55]],"ltp":1.62,"tv":154.45,"id":11445382}],"tv":175.35}]}
{"op":"mcm","clk":"11941673840","pt":1724861574784,"mc":[{"id":"1.232283784","rc":[{"trd":[[1.62,129.46],[1.66,12.24],[1.7,11.54]],"batl":[[0,1.66,80.58]],"ltp":1.62,"tv":154.47,"id":11445382}],"tv":175.37}]}
{"op":"mcm","clk":"11942474537","pt":1724866656678,"mc":[{"id":"1.232283784","rc":[{"batb":[[0,1.2,1000],[1,1.04,1.05],[2,1.03,200]],"ltp":2.14,"tv":20.9,"id":35736915},{"trd":[[1.62,129.47],[1.66,12.25],[1.7,11.55]],"batb":[[0,1.2,1000],[1,1.04,1.05],[2,1.03,200]],"batl":[[0,1.66,80.59]],"ltp":1.62,"tv":154.49,"id":11445382}],"tv":175.39}]}
{"op":"mcm","clk":"11942474661","pt":1724866657310,"mc":[{"id":"1.232283784","rc":[{"batb":[[0,1.23,202.44],[1,1.2,1000],[2,1.04,1.05]],"ltp":1.62,"tv":154.49,"id":11445382}]}]}
{"op":"mcm","clk":"11942568704","pt":1724867183719,"mc":[{"id":"1.232283784","rc":[{"batb":[[0,1.23,203.32]],"ltp":1.62,"tv":154.49,"id":11445382}]}]}
{"op":"mcm","clk":"11942572931","pt":1724867210716,"mc":[{"id":"1.232283784","rc":[{"batl":[[0,1.66,81.47]],"ltp":1.62,"tv":154.49,"id":11445382}]}]}
{"op":"mcm","clk":"11942648396","pt":1724867744219,"mc":[{"id":"1.232283784","rc":[{"batb":[[0,1.24,7.36],[1,1.23,202.44],[2,1.2,1000]],"ltp":1.62,"tv":154.49,"id":11445382}]}]}
{"op":"mcm","clk":"11942701279","pt":1724868138341,"mc":[{"id":"1.232283784","rc":[{"trd":[[1.62,129.46],[1.66,12.24],[1.7,11.54]],"batb":[[0,1.25,200.06],[1,1.24,6.49]],"batl":[[0,1.66,81.46]],"ltp":1.62,"tv":154.47,"id":11445382}],"tv":175.37}]}
{"op":"mcm","clk":"11942755453","pt":1724868482534,"mc":[{"id":"1.232283784","rc":[{"batb":[[0,1.24,7.37],[1,1.2,1000],[2,1.04,1.05]],"ltp":1.62,"tv":154.47,"id":11445382}]}]}
{"op":"mcm","clk":"11942756183","pt":1724868486728,"mc":[{"id":"1.232283784","rc":[{"batl":[[0,5.9,9.91]],"ltp":2.14,"tv":20.9,"id":35736915}]}]}
{"op":"mcm","clk":"11942756244","pt":1724868487143,"mc":[{"id":"1.232283784","rc":[{"batb":[[0,1.21,5],[1,1.2,1000],[2,1.04,1.05]],"ltp":2.14,"tv":20.9,"id":35736915}]}]}
{"op":"mcm","clk":"11942756748","pt":1724868490322,"mc":[{"id":"1.232283784","rc":[{"batb":[[0,1.2,1000],[1,1.04,1.05],[2,1.03,200]],"ltp":2.14,"tv":20.9,"id":35736915}]}]}
{"op":"mcm","clk":"11942758008","pt":1724868497740,"mc":[{"id":"1.232283784","rc":[{"batb":[[0,1.21,5],[1,1.2,1000],[2,1.04,1.05]],"ltp":2.14,"tv":20.9,"id":35736915}]}]}
{"op":"mcm","clk":"11942758581","pt":1724868501102,"mc":[{"id":"1.232283784","rc":[{"batb":[[0,1.2,1000],[1,1.04,1.05],[2,1.03,200]],"ltp":2.14,"tv":20.9,"id":35736915}]}]}
{"op":"mcm","clk":"11942759153","pt":1724868504319,"mc":[{"id":"1.232283784","rc":[{"batb":[[0,1.21,5],[1,1.2,1000],[2,1.04,1.05]],"ltp":2.14,"tv":20.9,"id":35736915}]}]}
{"op":"mcm","clk":"11942759701","pt":1724868507543,"mc":[{"id":"1.232283784","rc":[{"batb":[[0,1.2,1000],[1,1.04,1.05],[2,1.03,200]],"ltp":2.14,"tv":20.9,"id":35736915}]}]}
{"op":"mcm","clk":"11942760235","pt":1724868510528,"mc":[{"id":"1.232283784","rc":[{"batb":[[0,1.21,5],[1,1.2,1000],[2,1.04,1.05]],"ltp":2.14,"tv":20.9,"id":35736915}]}]}
{"op":"mcm","clk":"11942760795","pt":1724868513957,"mc":[{"id":"1.232283784","rc":[{"batb":[[0,1.2,1000],[1,1.04,1.05],[2,1.03,200]],"ltp":2.14,"tv":20.9,"id":35736915}]}]}
{"op":"mcm","clk":"11942761312","pt":1724868517066,"mc":[{"id":"1.232283784","rc":[{"batb":[[0,1.21,5],[1,1.2,1000],[2,1.04,1.05]],"ltp":2.14,"tv":20.9,"id":35736915}]}]}
{"op":"mcm","clk":"11942761883","pt":1724868520894,"mc":[{"id":"1.232283784","rc":[{"batb":[[0,1.2,1000],[1,1.04,1.05],[2,1.03,200]],"ltp":2.14,"tv":20.9,"id":35736915}]}]}
{"op":"mcm","clk":"11942762275","pt":1724868523387,"mc":[{"id":"1.232283784","rc":[{"batb":[[0,1.21,5],[1,1.2,1000],[2,1.04,1.05]],"ltp":2.14,"tv":20.9,"id":35736915}]}]}
{"op":"mcm","clk":"11942762818","pt":1724868526896,"mc":[{"id":"1.232283784","rc":[{"batb":[[0,1.2,1000],[1,1.04,1.05],[2,1.03,200]],"ltp":2.14,"tv":20.9,"id":35736915}]}]}
{"op":"mcm","clk":"11942763444","pt":1724868530585,"mc":[{"id":"1.232283784","rc":[{"batb":[[0,1.21,5],[1,1.2,1000],[2,1.04,1.05]],"ltp":2.14,"tv":20.9,"id":35736915}]}]}
{"op":"mcm","clk":"11942763949","pt":1724868533890,"mc":[{"id":"1.232283784","rc":[{"batb":[[0,1.2,1000],[1,1.04,1.05],[2,1.03,200]],"ltp":2.14,"tv":20.9,"id":35736915}]}]}
{"op":"mcm","clk":"11942764514","pt":1724868537301,"mc":[{"id":"1.232283784","rc":[{"batb":[[0,1.21,5],[1,1.2,1000],[2,1.04,1.05]],"ltp":2.14,"tv":20.9,"id":35736915}]}]}
{"op":"mcm","clk":"11942765056","pt":1724868540518,"mc":[{"id":"1.232283784","rc":[{"batb":[[0,1.2,1000],[1,1.04,1.05],[2,1.03,200]],"ltp":2.14,"tv":20.9,"id":35736915}]}]}
{"op":"mcm","clk":"11942765609","pt":1724868543610,"mc":[{"id":"1.232283784","rc":[{"batb":[[0,1.21,5],[1,1.2,1000],[2,1.04,1.05]],"ltp":2.14,"tv":20.9,"id":35736915}]}]}
{"op":"mcm","clk":"11942766227","pt":1724868547199,"mc":[{"id":"1.232283784","rc":[{"batb":[[0,1.2,1000],[1,1.04,1.05],[2,1.03,200]],"ltp":2.14,"tv":20.9,"id":35736915}]}]}
{"op":"mcm","clk":"11942766762","pt":1724868550413,"mc":[{"id":"1.232283784","rc":[{"batb":[[0,1.21,5],[1,1.2,1000],[2,1.04,1.05]],"ltp":2.14,"tv":20.9,"id":35736915}]}]}
{"op":"mcm","clk":"11942767391","pt":1724868553991,"mc":[{"id":"1.232283784","rc":[{"batb":[[0,1.2,1000],[1,1.04,1.05],[2,1.03,200]],"ltp":2.14,"tv":20.9,"id":35736915}]}]}
{"op":"mcm","clk":"11942767871","pt":1724868556724,"mc":[{"id":"1.232283784","rc":[{"batb":[[0,1.21,5],[1,1.2,1000],[2,1.04,1.05]],"ltp":2.14,"tv":20.9,"id":35736915}]}]}
{"op":"mcm","clk":"11942768468","pt":1724868560300,"mc":[{"id":"1.232283784","rc":[{"batb":[[0,1.2,1000],[1,1.04,1.05],[2,1.03,200]],"ltp":2.14,"tv":20.9,"id":35736915}]}]}
{"op":"mcm","clk":"11942768863","pt":1724868562827,"mc":[{"id":"1.232283784","rc":[{"batb":[[0,1.21,5],[1,1.2,1000],[2,1.04,1.05]],"ltp":2.14,"tv":20.9,"id":35736915}]}]}
{"op":"mcm","clk":"11942769452","pt":1724868566331,"mc":[{"id":"1.232283784","rc":[{"batb":[[0,1.2,1000],[1,1.04,1.05],[2,1.03,200]],"ltp":2.14,"tv":20.9,"id":35736915}]}]}
{"op":"mcm","clk":"11942770050","pt":1724868569463,"mc":[{"id":"1.232283784","rc":[{"batb":[[0,1.21,5],[1,1.2,1000],[2,1.04,1.05]],"ltp":2.14,"tv":20.9,"id":35736915}]}]}
{"op":"mcm","clk":"11942770713","pt":1724868573227,"mc":[{"id":"1.232283784","rc":[{"batb":[[0,1.2,1000],[1,1.04,1.05],[2,1.03,200]],"ltp":2.14,"tv":20.9,"id":35736915}]}]}
{"op":"mcm","clk":"11942771125","pt":1724868575732,"mc":[{"id":"1.232283784","rc":[{"batb":[[0,1.21,5],[1,1.2,1000],[2,1.04,1.05]],"ltp":2.14,"tv":20.9,"id":35736915}]}]}
{"op":"mcm","clk":"11942771738","pt":1724868579356,"mc":[{"id":"1.232283784","rc":[{"batb":[[0,1.2,1000],[1,1.04,1.05],[2,1.03,200]],"ltp":2.14,"tv":20.9,"id":35736915}]}]}
{"op":"mcm","clk":"11942772265","pt":1724868582427,"mc":[{"id":"1.232283784","rc":[{"batb":[[0,1.21,5],[1,1.2,1000],[2,1.04,1.05]],"ltp":2.14,"tv":20.9,"id":35736915}]}]}
{"op":"mcm","clk":"11942772836","pt":1724868585875,"mc":[{"id":"1.232283784","rc":[{"batb":[[0,1.2,1000],[1,1.04,1.05],[2,1.03,200]],"ltp":2.14,"tv":20.9,"id":35736915}]}]}
{"op":"mcm","clk":"11942773334","pt":1724868588773,"mc":[{"id":"1.232283784","rc":[{"batb":[[0,1.21,5],[1,1.2,1000],[2,1.04,1.05]],"ltp":2.14,"tv":20.9,"id":35736915}]}]}
{"op":"mcm","clk":"11942773928","pt":1724868592290,"mc":[{"id":"1.232283784","rc":[{"batb":[[0,1.2,1000],[1,1.04,1.05],[2,1.03,200]],"ltp":2.14,"tv":20.9,"id":35736915}]}]}
{"op":"mcm","clk":"11942774295","pt":1724868594486,"mc":[{"id":"1.232283784","rc":[{"batb":[[0,1.21,5],[1,1.2,1000],[2,1.04,1.05]],"ltp":2.14,"tv":20.9,"id":35736915}]}]}
{"op":"mcm","clk":"11942774996","pt":1724868598206,"mc":[{"id":"1.232283784","rc":[{"batb":[[0,1.2,1000],[1,1.04,1.05],[2,1.03,200]],"ltp":2.14,"tv":20.9,"id":35736915}]}]}
{"op":"mcm","clk":"11942775666","pt":1724868601997,"mc":[{"id":"1.232283784","rc":[{"batb":[[0,1.21,5],[1,1.2,1000],[2,1.04,1.05]],"ltp":2.14,"tv":20.9,"id":35736915}]}]}
{"op":"mcm","clk":"11942776260","pt":1724868605395,"mc":[{"id":"1.232283784","rc":[{"batb":[[0,1.2,1000],[1,1.04,1.05],[2,1.03,200]],"ltp":2.14,"tv":20.9,"id":35736915}]}]}
{"op":"mcm","clk":"11942776894","pt":1724868608499,"mc":[{"id":"1.232283784","rc":[{"batb":[[0,1.21,5],[1,1.2,1000],[2,1.04,1.05]],"ltp":2.14,"tv":20.9,"id":35736915}]}]}
{"op":"mcm","clk":"11942777497","pt":1724868612085,"mc":[{"id":"1.232283784","rc":[{"batb":[[0,1.2,1000],[1,1.04,1.05],[2,1.03,200]],"ltp":2.14,"tv":20.9,"id":35736915}]}]}
{"op":"mcm","clk":"11942777971","pt":1724868614797,"mc":[{"id":"1.232283784","rc":[{"batb":[[0,1.21,5],[1,1.2,1000],[2,1.04,1.05]],"ltp":2.14,"tv":20.9,"id":35736915}]}]}
{"op":"mcm","clk":"11942778636","pt":1724868618586,"mc":[{"id":"1.232283784","rc":[{"batb":[[0,1.2,1000],[1,1.04,1.05],[2,1.03,200]],"ltp":2.14,"tv":20.9,"id":35736915}]}]}
{"op":"mcm","clk":"11942779062","pt":1724868621096,"mc":[{"id":"1.232283784","rc":[{"batb":[[0,1.21,5],[1,1.2,1000],[2,1.04,1.05]],"ltp":2.14,"tv":20.9,"id":35736915}]}]}
{"op":"mcm","clk":"11942779642","pt":1724868624602,"mc":[{"id":"1.232283784","rc":[{"batb":[[0,1.2,1000],[1,1.04,1.05],[2,1.03,200]],"ltp":2.14,"tv":20.9,"id":35736915}]}]}
{"op":"mcm","clk":"11942780274","pt":1724868628622,"mc":[{"id":"1.232283784","rc":[{"batb":[[0,1.21,5],[1,1.2,1000],[2,1.04,1.05]],"ltp":2.14,"tv":20.9,"id":35736915}]}]}
{"op":"mcm","clk":"11942780836","pt":1724868632030,"mc":[{"id":"1.232283784","rc":[{"batb":[[0,1.2,1000],[1,1.04,1.05],[2,1.03,200]],"ltp":2.14,"tv":20.9,"id":35736915}]}]}
{"op":"mcm","clk":"11942781189","pt":1724868634388,"mc":[{"id":"1.232283784","rc":[{"batb":[[0,1.21,5],[1,1.2,1000],[2,1.04,1.05]],"ltp":2.14,"tv":20.9,"id":35736915}]}]}
{"op":"mcm","clk":"11942781777","pt":1724868638009,"mc":[{"id":"1.232283784","rc":[{"batb":[[0,1.2,1000],[1,1.04,1.05],[2,1.03,200]],"ltp":2.14,"tv":20.9,"id":35736915}]}]}
{"op":"mcm","clk":"11942782315","pt":1724868641533,"mc":[{"id":"1.232283784","rc":[{"batb":[[0,1.21,5],[1,1.2,1000],[2,1.04,1.05]],"ltp":2.14,"tv":20.9,"id":35736915}]}]}
{"op":"mcm","clk":"11942782881","pt":1724868644926,"mc":[{"id":"1.232283784","rc":[{"batb":[[0,1.2,1000],[1,1.04,1.05],[2,1.03,200]],"ltp":2.14,"tv":20.9,"id":35736915}]}]}
{"op":"mcm","clk":"11942783358","pt":1724868648030,"mc":[{"id":"1.232283784","rc":[{"batb":[[0,1.21,5],[1,1.2,1000],[2,1.04,1.05]],"ltp":2.14,"tv":20.9,"id":35736915}]}]}
{"op":"mcm","clk":"11942783933","pt":1724868651827,"mc":[{"id":"1.232283784","rc":[{"batb":[[0,1.2,1000],[1,1.04,1.05],[2,1.03,200]],"ltp":2.14,"tv":20.9,"id":35736915}]}]}
{"op":"mcm","clk":"11942784430","pt":1724868654936,"mc":[{"id":"1.232283784","rc":[{"batb":[[0,1.21,5],[1,1.2,1000],[2,1.04,1.05]],"ltp":2.14,"tv":20.9,"id":35736915}]}]}
{"op":"mcm","clk":"11942785048","pt":1724868658551,"mc":[{"id":"1.232283784","rc":[{"batb":[[0,1.2,1000],[1,1.04,1.05],[2,1.03,200]],"ltp":2.14,"tv":20.9,"id":35736915}]}]}
{"op":"mcm","clk":"11942785492","pt":1724868661345,"mc":[{"id":"1.232283784","rc":[{"batb":[[0,1.21,5],[1,1.2,1000],[2,1.04,1.05]],"ltp":2.14,"tv":20.9,"id":35736915}]}]}
{"op":"mcm","clk":"11942786088","pt":1724868664825,"mc":[{"id":"1.232283784","rc":[{"batb":[[0,1.2,1000],[1,1.04,1.05],[2,1.03,200]],"ltp":2.14,"tv":20.9,"id":35736915}]}]}
{"op":"mcm","clk":"11942786429","pt":1724868667028,"mc":[{"id":"1.232283784","rc":[{"batb":[[0,1.21,5],[1,1.2,1000],[2,1.04,1.05]],"ltp":2.14,"tv":20.9,"id":35736915}]}]}
{"op":"mcm","clk":"11942787009","pt":1724868670339,"mc":[{"id":"1.232283784","rc":[{"batb":[[0,1.2,1000],[1,1.04,1.05],[2,1.03,200]],"ltp":2.14,"tv":20.9,"id":35736915}]}]}
{"op":"mcm","clk":"11942787986","pt":1724868676402,"mc":[{"id":"1.232283784","rc":[{"batb":[[0,1.21,5],[1,1.2,1000],[2,1.04,1.05]],"ltp":2.14,"tv":20.9,"id":35736915}]}]}
{"op":"mcm","clk":"11942788575","pt":1724868680063,"mc":[{"id":"1.232283784","rc":[{"batb":[[0,1.2,1000],[1,1.04,1.05],[2,1.03,200]],"ltp":2.14,"tv":20.9,"id":35736915}]}]}
{"op":"mcm","clk":"11942789087","pt":1724868683475,"mc":[{"id":"1.232283784","rc":[{"batb":[[0,1.21,5],[1,1.2,1000],[2,1.04,1.05]],"ltp":2.14,"tv":20.9,"id":35736915}]}]}
{"op":"mcm","clk":"11942789578","pt":1724868686892,"mc":[{"id":"1.232283784","rc":[{"batb":[[0,1.2,1000],[1,1.04,1.05],[2,1.03,200]],"ltp":2.14,"tv":20.9,"id":35736915}]}]}
{"op":"mcm","clk":"11942790070","pt":1724868690092,"mc":[{"id":"1.232283784","rc":[{"batb":[[0,1.21,5],[1,1.2,1000],[2,1.04,1.05]],"ltp":2.14,"tv":20.9,"id":35736915}]}]}
{"op":"mcm","clk":"11942790702","pt":1724868693786,"mc":[{"id":"1.232283784","rc":[{"batb":[[0,1.2,1000],[1,1.04,1.05],[2,1.03,200]],"ltp":2.14,"tv":20.9,"id":35736915}]}]}
{"op":"mcm","clk":"11942791405","pt":1724868697503,"mc":[{"id":"1.232283784","rc":[{"batb":[[0,1.21,5],[1,1.2,1000],[2,1.04,1.05]],"ltp":2.14,"tv":20.9,"id":35736915}]}]}
{"op":"mcm","clk":"11942791962","pt":1724868701226,"mc":[{"id":"1.232283784","rc":[{"batb":[[0,1.2,1000],[1,1.04,1.05],[2,1.03,200]],"ltp":2.14,"tv":20.9,"id":35736915}]}]}
{"op":"mcm","clk":"11942792442","pt":1724868704316,"mc":[{"id":"1.232283784","rc":[{"batb":[[0,1.21,5],[1,1.2,1000],[2,1.04,1.05]],"ltp":2.14,"tv":20.9,"id":35736915}]}]}
{"op":"mcm","clk":"11942793058","pt":1724868708026,"mc":[{"id":"1.232283784","rc":[{"batb":[[0,1.2,1000],[1,1.04,1.05],[2,1.03,200]],"ltp":2.14,"tv":20.9,"id":35736915}]}]}
{"op":"mcm","clk":"11942793486","pt":1724868710537,"mc":[{"id":"1.232283784","rc":[{"batb":[[0,1.21,5],[1,1.2,1000],[2,1.04,1.05]],"ltp":2.14,"tv":20.9,"id":35736915}]}]}
{"op":"mcm","clk":"11942794000","pt":1724868713847,"mc":[{"id":"1.232283784","rc":[{"batb":[[0,1.2,1000],[1,1.04,1.05],[2,1.03,200]],"ltp":2.14,"tv":20.9,"id":35736915}]}]}
{"op":"mcm","clk":"11942794538","pt":1724868717112,"mc":[{"id":"1.232283784","rc":[{"batb":[[0,1.21,5],[1,1.2,1000],[2,1.04,1.05]],"ltp":2.14,"tv":20.9,"id":35736915}]}]}
{"op":"mcm","clk":"11942795112","pt":1724868720424,"mc":[{"id":"1.232283784","rc":[{"batb":[[0,1.2,1000],[1,1.04,1.05],[2,1.03,200]],"ltp":2.14,"tv":20.9,"id":35736915}]}]}
{"op":"mcm","clk":"11942795765","pt":1724868724121,"mc":[{"id":"1.232283784","rc":[{"batb":[[0,1.21,5],[1,1.2,1000],[2,1.04,1.05]],"ltp":2.14,"tv":20.9,"id":35736915}]}]}
{"op":"mcm","clk":"11942796314","pt":1724868727543,"mc":[{"id":"1.232283784","rc":[{"batb":[[0,1.2,1000],[1,1.04,1.05],[2,1.03,200]],"ltp":2.14,"tv":20.9,"id":35736915}]}]}
{"op":"mcm","clk":"11942796769","pt":1724868730246,"mc":[{"id":"1.232283784","rc":[{"batb":[[0,1.21,5],[1,1.2,1000],[2,1.04,1.05]],"ltp":2.14,"tv":20.9,"id":35736915}]}]}
{"op":"mcm","clk":"11942797319","pt":1724868733652,"mc":[{"id":"1.232283784","rc":[{"batb":[[0,1.2,1000],[1,1.04,1.05],[2,1.03,200]],"ltp":2.14,"tv":20.9,"id":35736915}]}]}
{"op":"mcm","clk":"11942797730","pt":1724868736334,"mc":[{"id":"1.232283784","rc":[{"batb":[[0,1.21,5],[1,1.2,1000],[2,1.04,1.05]],"ltp":2.14,"tv":20.9,"id":35736915}]}]}
{"op":"mcm","clk":"11942798240","pt":1724868739542,"mc":[{"id":"1.232283784","rc":[{"batb":[[0,1.2,1000],[1,1.04,1.05],[2,1.03,200]],"ltp":2.14,"tv":20.9,"id":35736915}]}]}
{"op":"mcm","clk":"11942798811","pt":1724868743158,"mc":[{"id":"1.232283784","rc":[{"batb":[[0,1.21,5],[1,1.2,1000],[2,1.04,1.05]],"ltp":2.14,"tv":20.9,"id":35736915}]}]}
{"op":"mcm","clk":"11942799418","pt":1724868746782,"mc":[{"id":"1.232283784","rc":[{"batb":[[0,1.2,1000],[1,1.04,1.05],[2,1.03,200]],"ltp":2.14,"tv":20.9,"id":35736915}]}]}
{"op":"mcm","clk":"11942799862","pt":1724868749507,"mc":[{"id":"1.232283784","rc":[{"batb":[[0,1.21,5],[1,1.2,1000],[2,1.04,1.05]],"ltp":2.14,"tv":20.9,"id":35736915}]}]}
{"op":"mcm","clk":"11942800463","pt":1724868753087,"mc":[{"id":"1.232283784","rc":[{"batb":[[0,1.2,1000],[1,1.04,1.05],[2,1.03,200]],"ltp":2.14,"tv":20.9,"id":35736915}]}]}
{"op":"mcm","clk":"11942800864","pt":1724868755601,"mc":[{"id":"1.232283784","rc":[{"batb":[[0,1.21,5],[1,1.2,1000],[2,1.04,1.05]],"ltp":2.14,"tv":20.9,"id":35736915}]}]}
{"op":"mcm","clk":"11942801518","pt":1724868759307,"mc":[{"id":"1.232283784","rc":[{"batb":[[0,1.2,1000],[1,1.04,1.05],[2,1.03,200]],"ltp":2.14,"tv":20.9,"id":35736915}]}]}
{"op":"mcm","clk":"11942801948","pt":1724868761833,"mc":[{"id":"1.232283784","rc":[{"batb":[[0,1.21,5],[1,1.2,1000],[2,1.04,1.05]],"ltp":2.14,"tv":20.9,"id":35736915}]}]}
{"op":"mcm","clk":"11942802509","pt":1724868765425,"mc":[{"id":"1.232283784","rc":[{"batb":[[0,1.2,1000],[1,1.04,1.05],[2,1.03,200]],"ltp":2.14,"tv":20.9,"id":35736915}]}]}
{"op":"mcm","clk":"11942802938","pt":1724868768031,"mc":[{"id":"1.232283784","rc":[{"batb":[[0,1.21,5],[1,1.2,1000],[2,1.04,1.05]],"ltp":2.14,"tv":20.9,"id":35736915}]}]}
{"op":"mcm","clk":"11942803471","pt":1724868771639,"mc":[{"id":"1.232283784","rc":[{"batb":[[0,1.2,1000],[1,1.04,1.05],[2,1.03,200]],"ltp":2.14,"tv":20.9,"id":35736915}]}]}
{"op":"mcm","clk":"11942803890","pt":1724868774347,"mc":[{"id":"1.232283784","rc":[{"batb":[[0,1.21,5],[1,1.2,1000],[2,1.04,1.05]],"ltp":2.14,"tv":20.9,"id":35736915}]}]}
{"op":"mcm","clk":"11942804604","pt":1724868777958,"mc":[{"id":"1.232283784","rc":[{"batb":[[0,1.2,1000],[1,1.04,1.05],[2,1.03,200]],"ltp":2.14,"tv":20.9,"id":35736915}]}]}
{"op":"mcm","clk":"11942805044","pt":1724868780448,"mc":[{"id":"1.232283784","rc":[{"batb":[[0,1.21,5],[1,1.2,1000],[2,1.04,1.05]],"ltp":2.14,"tv":20.9,"id":35736915}]}]}
{"op":"mcm","clk":"11942805800","pt":1724868784158,"mc":[{"id":"1.232283784","rc":[{"batb":[[0,1.2,1000],[1,1.04,1.05],[2,1.03,200]],"ltp":2.14,"tv":20.9,"id":35736915}]}]}
{"op":"mcm","clk":"11942806310","pt":1724868786652,"mc":[{"id":"1.232283784","rc":[{"batb":[[0,1.21,5],[1,1.2,1000],[2,1.04,1.05]],"ltp":2.14,"tv":20.9,"id":35736915}]}]}
{"op":"mcm","clk":"11942806848","pt":1724868789865,"mc":[{"id":"1.232283784","rc":[{"batb":[[0,1.2,1000],[1,1.04,1.05],[2,1.03,200]],"ltp":2.14,"tv":20.9,"id":35736915}]}]}
{"op":"mcm","clk":"11942807201","pt":1724868792083,"mc":[{"id":"1.232283784","rc":[{"batb":[[0,1.21,5],[1,1.2,1000],[2,1.04,1.05]],"ltp":2.14,"tv":20.9,"id":35736915}]}]}
{"op":"mcm","clk":"11942807789","pt":1724868795569,"mc":[{"id":"1.232283784","rc":[{"batb":[[0,1.2,1000],[1,1.04,1.05],[2,1.03,200]],"ltp":2.14,"tv":20.9,"id":35736915}]}]}
{"op":"mcm","clk":"11942808202","pt":1724868798170,"mc":[{"id":"1.232283784","rc":[{"batb":[[0,1.21,5],[1,1.2,1000],[2,1.04,1.05]],"ltp":2.14,"tv":20.9,"id":35736915}]}]}
{"op":"mcm","clk":"11942809273","pt":1724868805061,"mc":[{"id":"1.232283784","rc":[{"batb":[[0,1.2,1000],[1,1.04,1.05],[2,1.03,200]],"ltp":2.14,"tv":20.9,"id":35736915}]}]}
{"op":"mcm","clk":"11942810302","pt":1724868811280,"mc":[{"id":"1.232283784","rc":[{"batb":[[0,1.21,5],[1,1.2,1000],[2,1.04,1.05]],"ltp":2.14,"tv":20.9,"id":35736915}]}]}
{"op":"mcm","clk":"11942811283","pt":1724868817405,"mc":[{"id":"1.232283784","rc":[{"batb":[[0,1.2,1000],[1,1.04,1.05],[2,1.03,200]],"ltp":2.14,"tv":20.9,"id":35736915}]}]}
{"op":"mcm","clk":"11942811794","pt":1724868820892,"mc":[{"id":"1.232283784","rc":[{"batb":[[0,1.21,5],[1,1.2,1000],[2,1.04,1.05]],"ltp":2.14,"tv":20.9,"id":35736915}]}]}
{"op":"mcm","clk":"11942812353","pt":1724868824508,"mc":[{"id":"1.232283784","rc":[{"batb":[[0,1.2,1000],[1,1.04,1.05],[2,1.03,200]],"ltp":2.14,"tv":20.9,"id":35736915}]}]}
{"op":"mcm","clk":"11942812805","pt":1724868827519,"mc":[{"id":"1.232283784","rc":[{"batb":[[0,1.21,5],[1,1.2,1000],[2,1.04,1.05]],"ltp":2.14,"tv":20.9,"id":35736915}]}]}
{"op":"mcm","clk":"11942813405","pt":1724868831234,"mc":[{"id":"1.232283784","rc":[{"batb":[[0,2.3,29.7]],"ltp":2.14,"tv":20.9,"id":35736915}]}]}
{"op":"mcm","clk":"11942814318","pt":1724868836510,"mc":[{"id":"1.232283784","rc":[{"batb":[[0,2.32,5],[1,2.3,29.7],[2,1.2,1000]],"ltp":2.14,"tv":20.9,"id":35736915}]}]}
{"op":"mcm","clk":"11942814936","pt":1724868840121,"mc":[{"id":"1.232283784","rc":[{"batb":[[0,2.3,29.7],[1,1.2,1000],[2,1.04,1.05]],"ltp":2.14,"tv":20.9,"id":35736915}]}]}
{"op":"mcm","clk":"11942815376","pt":1724868842657,"mc":[{"id":"1.232283784","rc":[{"batb":[[0,2.32,5],[1,2.3,29.7],[2,1.2,1000]],"ltp":2.14,"tv":20.9,"id":35736915}]}]}
{"op":"mcm","clk":"11942815968","pt":1724868846234,"mc":[{"id":"1.232283784","rc":[{"batb":[[0,2.3,29.7],[1,1.2,1000],[2,1.04,1.05]],"ltp":2.14,"tv":20.9,"id":35736915}]}]}
{"op":"mcm","clk":"11942816438","pt":1724868848962,"mc":[{"id":"1.232283784","rc":[{"batb":[[0,2.32,5],[1,2.3,29.7],[2,1.2,1000]],"ltp":2.14,"tv":20.9,"id":35736915}]}]}
{"op":"mcm","clk":"11942817017","pt":1724868852439,"mc":[{"id":"1.232283784","rc":[{"batb":[[0,2.3,29.7],[1,1.2,1000],[2,1.04,1.05]],"ltp":2.14,"tv":20.9,"id":35736915}]}]}
{"op":"mcm","clk":"11942818687","pt":1724868861452,"mc":[{"id":"1.232283784","rc":[{"batb":[[0,2.32,5],[1,2.3,29.7],[2,1.2,1000]],"ltp":2.14,"tv":20.9,"id":35736915}]}]}
{"op":"mcm","clk":"11942819330","pt":1724868865149,"mc":[{"id":"1.232283784","rc":[{"batb":[[0,2.3,29.7],[1,1.2,1000],[2,1.04,1.05]],"ltp":2.14,"tv":20.9,"id":35736915}]}]}
{"op":"mcm","clk":"11942819780","pt":1724868867651,"mc":[{"id":"1.232283784","rc":[{"batb":[[0,2.32,5],[1,2.3,29.7],[2,1.2,1000]],"ltp":2.14,"tv":20.9,"id":35736915}]}]}
{"op":"mcm","clk":"11942820330","pt":1724868870843,"mc":[{"id":"1.232283784","rc":[{"batb":[[0,2.3,29.7],[1,1.2,1000],[2,1.04,1.05]],"ltp":2.14,"tv":20.9,"id":35736915}]}]}
{"op":"mcm","clk":"11942820712","pt":1724868873165,"mc":[{"id":"1.232283784","rc":[{"batb":[[0,2.32,5],[1,2.3,29.7],[2,1.2,1000]],"ltp":2.14,"tv":20.9,"id":35736915}]}]}
{"op":"mcm","clk":"11942821317","pt":1724868876566,"mc":[{"id":"1.232283784","rc":[{"batb":[[0,2.3,29.7],[1,1.2,1000],[2,1.04,1.05]],"ltp":2.14,"tv":20.9,"id":35736915}]}]}
{"op":"mcm","clk":"11942821950","pt":1724868880153,"mc":[{"id":"1.232283784","rc":[{"batb":[[0,2.32,5],[1,2.3,29.7],[2,1.2,1000]],"ltp":2.14,"tv":20.9,"id":35736915}]}]}
{"op":"mcm","clk":"11942822545","pt":1724868883691,"mc":[{"id":"1.232283784","rc":[{"batb":[[0,2.3,29.7],[1,1.2,1000],[2,1.04,1.05]],"ltp":2.14,"tv":20.9,"id":35736915}]}]}
{"op":"mcm","clk":"11942823033","pt":1724868887088,"mc":[{"id":"1.232283784","rc":[{"batb":[[0,2.32,5],[1,2.3,29.7],[2,1.2,1000]],"ltp":2.14,"tv":20.9,"id":35736915}]}]}
{"op":"mcm","clk":"11942823568","pt":1724868890511,"mc":[{"id":"1.232283784","rc":[{"batb":[[0,2.3,29.7],[1,1.2,1000],[2,1.04,1.05]],"ltp":2.14,"tv":20.9,"id":35736915}]}]}
{"op":"mcm","clk":"11942824068","pt":1724868893576,"mc":[{"id":"1.232283784","rc":[{"batb":[[0,2.32,5],[1,2.3,29.7],[2,1.2,1000]],"ltp":2.14,"tv":20.9,"id":35736915}]}]}
{"op":"mcm","clk":"11942824581","pt":1724868897205,"mc":[{"id":"1.232283784","rc":[{"batb":[[0,2.3,29.7],[1,1.2,1000],[2,1.04,1.05]],"ltp":2.14,"tv":20.9,"id":35736915}]}]}
{"op":"mcm","clk":"11942825482","pt":1724868902403,"mc":[{"id":"1.232283784","rc":[{"batb":[[0,2.32,5],[1,2.3,29.7],[2,1.2,1000]],"ltp":2.14,"tv":20.9,"id":35736915}]}]}
{"op":"mcm","clk":"11942826092","pt":1724868905688,"mc":[{"id":"1.232283784","rc":[{"batb":[[0,2.3,29.7],[1,1.2,1000],[2,1.04,1.05]],"ltp":2.14,"tv":20.9,"id":35736915}]}]}
{"op":"mcm","clk":"11942826560","pt":1724868908508,"mc":[{"id":"1.232283784","rc":[{"batb":[[0,2.32,5],[1,2.3,29.7],[2,1.2,1000]],"ltp":2.14,"tv":20.9,"id":35736915}]}]}
{"op":"mcm","clk":"11942827098","pt":1724868911807,"mc":[{"id":"1.232283784","rc":[{"batb":[[0,2.3,29.7],[1,1.2,1000],[2,1.04,1.05]],"ltp":2.14,"tv":20.9,"id":35736915}]}]}
{"op":"mcm","clk":"11942827475","pt":1724868914195,"mc":[{"id":"1.232283784","rc":[{"batb":[[0,2.32,5],[1,2.3,29.7],[2,1.2,1000]],"ltp":2.14,"tv":20.9,"id":35736915}]}]}
{"op":"mcm","clk":"11942828018","pt":1724868917502,"mc":[{"id":"1.232283784","rc":[{"batb":[[0,2.3,29.7],[1,1.2,1000],[2,1.04,1.05]],"ltp":2.14,"tv":20.9,"id":35736915}]}]}
{"op":"mcm","clk":"11942828796","pt":1724868922526,"mc":[{"id":"1.232283784","rc":[{"batb":[[0,2.32,5],[1,2.3,29.7],[2,1.2,1000]],"ltp":2.14,"tv":20.9,"id":35736915}]}]}
{"op":"mcm","clk":"11942829400","pt":1724868926011,"mc":[{"id":"1.232283784","rc":[{"batb":[[0,2.3,29.7],[1,1.2,1000],[2,1.04,1.05]],"ltp":2.14,"tv":20.9,"id":35736915}]}]}
{"op":"mcm","clk":"11942829909","pt":1724868929334,"mc":[{"id":"1.232283784","rc":[{"batb":[[0,2.32,5],[1,2.3,29.7],[2,1.2,1000]],"ltp":2.14,"tv":20.9,"id":35736915}]}]}
{"op":"mcm","clk":"11942830526","pt":1724868933034,"mc":[{"id":"1.232283784","rc":[{"batb":[[0,2.3,29.7],[1,1.2,1000],[2,1.04,1.05]],"ltp":2.14,"tv":20.9,"id":35736915}]}]}
{"op":"mcm","clk":"11942831136","pt":1724868936464,"mc":[{"id":"1.232283784","rc":[{"batb":[[0,2.32,5],[1,2.3,29.7],[2,1.2,1000]],"ltp":2.14,"tv":20.9,"id":35736915}]}]}
{"op":"mcm","clk":"11942831660","pt":1724868939727,"mc":[{"id":"1.232283784","rc":[{"batb":[[0,2.3,29.7],[1,1.2,1000],[2,1.04,1.05]],"ltp":2.14,"tv":20.9,"id":35736915}]}]}
{"op":"mcm","clk":"11942832117","pt":1724868942765,"mc":[{"id":"1.232283784","rc":[{"batb":[[0,2.32,5],[1,2.3,29.7],[2,1.2,1000]],"ltp":2.14,"tv":20.9,"id":35736915}]}]}
{"op":"mcm","clk":"11942832745","pt":1724868946365,"mc":[{"id":"1.232283784","rc":[{"batb":[[0,2.3,29.7],[1,1.2,1000],[2,1.04,1.05]],"ltp":2.14,"tv":20.9,"id":35736915}]}]}
{"op":"mcm","clk":"11942833165","pt":1724868948947,"mc":[{"id":"1.232283784","rc":[{"batb":[[0,2.32,5],[1,2.3,29.7],[2,1.2,1000]],"ltp":2.14,"tv":20.9,"id":35736915}]}]}
{"op":"mcm","clk":"11942833748","pt":1724868952550,"mc":[{"id":"1.232283784","rc":[{"batb":[[0,2.3,29.7],[1,1.2,1000],[2,1.04,1.05]],"ltp":2.14,"tv":20.9,"id":35736915}]}]}
{"op":"mcm","clk":"11942834187","pt":1724868955392,"mc":[{"id":"1.232283784","rc":[{"batb":[[0,2.32,5],[1,2.3,29.7],[2,1.2,1000]],"ltp":2.14,"tv":20.9,"id":35736915}]}]}
{"op":"mcm","clk":"11942834695","pt":1724868958856,"mc":[{"id":"1.232283784","rc":[{"batb":[[0,2.3,29.7],[1,1.2,1000],[2,1.04,1.05]],"ltp":2.14,"tv":20.9,"id":35736915}]}]}
{"op":"mcm","clk":"11942835098","pt":1724868961490,"mc":[{"id":"1.232283784","rc":[{"batb":[[0,2.32,5],[1,2.3,29.7],[2,1.2,1000]],"ltp":2.14,"tv":20.9,"id":35736915}]}]}
{"op":"mcm","clk":"11942835785","pt":1724868965391,"mc":[{"id":"1.232283784","rc":[{"batb":[[0,2.3,29.7],[1,1.2,1000],[2,1.04,1.05]],"ltp":2.14,"tv":20.9,"id":35736915}]}]}
{"op":"mcm","clk":"11942836224","pt":1724868968285,"mc":[{"id":"1.232283784","rc":[{"batb":[[0,2.32,5],[1,2.3,29.7],[2,1.2,1000]],"ltp":2.14,"tv":20.9,"id":35736915}]}]}
{"op":"mcm","clk":"11942836803","pt":1724868971690,"mc":[{"id":"1.232283784","rc":[{"batb":[[0,2.3,29.7],[1,1.2,1000],[2,1.04,1.05]],"ltp":2.14,"tv":20.9,"id":35736915}]}]}
{"op":"mcm","clk":"11942837407","pt":1724868975192,"mc":[{"id":"1.232283784","rc":[{"batb":[[0,2.32,5],[1,2.3,29.7],[2,1.2,1000]],"ltp":2.14,"tv":20.9,"id":35736915}]}]}
{"op":"mcm","clk":"11942837979","pt":1724868978681,"mc":[{"id":"1.232283784","rc":[{"batb":[[0,2.3,29.7],[1,1.2,1000],[2,1.04,1.05]],"ltp":2.14,"tv":20.9,"id":35736915}]}]}
{"op":"mcm","clk":"11942838681","pt":1724868983105,"mc":[{"id":"1.232283784","rc":[{"batb":[[0,2.32,5],[1,2.3,29.7],[2,1.2,1000]],"ltp":2.14,"tv":20.9,"id":35736915}]}]}
{"op":"mcm","clk":"11942839214","pt":1724868986517,"mc":[{"id":"1.232283784","rc":[{"batb":[[0,2.3,29.7],[1,1.2,1000],[2,1.04,1.05]],"ltp":2.14,"tv":20.9,"id":35736915}]}]}
{"op":"mcm","clk":"11942839668","pt":1724868989408,"mc":[{"id":"1.232283784","rc":[{"batb":[[0,2.32,5],[1,2.3,29.7],[2,1.2,1000]],"ltp":2.14,"tv":20.9,"id":35736915}]}]}
{"op":"mcm","clk":"11942840282","pt":1724868993205,"mc":[{"id":"1.232283784","rc":[{"batb":[[0,2.3,29.7],[1,1.2,1000],[2,1.04,1.05]],"ltp":2.14,"tv":20.9,"id":35736915}]}]}
{"op":"mcm","clk":"11942840961","pt":1724868997320,"mc":[{"id":"1.232283784","rc":[{"batb":[[0,2.32,5],[1,2.3,29.7],[2,1.2,1000]],"ltp":2.14,"tv":20.9,"id":35736915}]}]}
{"op":"mcm","clk":"11942841513","pt":1724869000523,"mc":[{"id":"1.232283784","rc":[{"batb":[[0,2.3,29.7],[1,1.2,1000],[2,1.04,1.05]],"ltp":2.14,"tv":20.9,"id":35736915}]}]}
{"op":"mcm","clk":"11942841871","pt":1724869002787,"mc":[{"id":"1.232283784","rc":[{"batb":[[0,2.32,5],[1,2.3,29.7],[2,1.2,1000]],"ltp":2.14,"tv":20.9,"id":35736915}]}]}
{"op":"mcm","clk":"11942842399","pt":1724869006225,"mc":[{"id":"1.232283784","rc":[{"batb":[[0,2.3,29.7],[1,1.2,1000],[2,1.04,1.05]],"ltp":2.14,"tv":20.9,"id":35736915}]}]}
{"op":"mcm","clk":"11942843109","pt":1724869010448,"mc":[{"id":"1.232283784","rc":[{"batb":[[0,2.32,5],[1,2.3,29.7],[2,1.2,1000]],"ltp":2.14,"tv":20.9,"id":35736915}]}]}
{"op":"mcm","clk":"11942843772","pt":1724869014148,"mc":[{"id":"1.232283784","rc":[{"batb":[[0,2.3,29.7],[1,1.2,1000],[2,1.04,1.05]],"ltp":2.14,"tv":20.9,"id":35736915}]}]}
{"op":"mcm","clk":"11942844302","pt":1724869017453,"mc":[{"id":"1.232283784","rc":[{"batb":[[0,2.32,5],[1,2.3,29.7],[2,1.2,1000]],"ltp":2.14,"tv":20.9,"id":35736915}]}]}
{"op":"mcm","clk":"11942844939","pt":1724869021233,"mc":[{"id":"1.232283784","rc":[{"batb":[[0,2.3,29.7],[1,1.2,1000],[2,1.04,1.05]],"ltp":2.14,"tv":20.9,"id":35736915}]}]}
{"op":"mcm","clk":"11942845516","pt":1724869024433,"mc":[{"id":"1.232283784","rc":[{"batb":[[0,2.32,5],[1,2.3,29.7],[2,1.2,1000]],"ltp":2.14,"tv":20.9,"id":35736915}]}]}
{"op":"mcm","clk":"11942846106","pt":1724869028062,"mc":[{"id":"1.232283784","rc":[{"batb":[[0,2.3,29.7],[1,1.2,1000],[2,1.04,1.05]],"ltp":2.14,"tv":20.9,"id":35736915}]}]}
{"op":"mcm","clk":"11942846860","pt":1724869032270,"mc":[{"id":"1.232283784","rc":[{"batb":[[0,2.32,5],[1,2.3,29.7],[2,1.2,1000]],"ltp":2.14,"tv":20.9,"id":35736915}]}]}
{"op":"mcm","clk":"11942847441","pt":1724869035864,"mc":[{"id":"1.232283784","rc":[{"batb":[[0,2.3,29.7],[1,1.2,1000],[2,1.04,1.05]],"ltp":2.14,"tv":20.9,"id":35736915}]}]}
{"op":"mcm","clk":"11942847869","pt":1724869038274,"mc":[{"id":"1.232283784","rc":[{"batb":[[0,2.32,5],[1,2.3,29.7],[2,1.2,1000]],"ltp":2.14,"tv":20.9,"id":35736915}]}]}
{"op":"mcm","clk":"11942848403","pt":1724869041559,"mc":[{"id":"1.232283784","rc":[{"batb":[[0,2.3,29.7],[1,1.2,1000],[2,1.04,1.05]],"ltp":2.14,"tv":20.9,"id":35736915}]}]}
{"op":"mcm","clk":"11942848869","pt":1724869044608,"mc":[{"id":"1.232283784","rc":[{"batb":[[0,2.32,5],[1,2.3,29.7],[2,1.2,1000]],"ltp":2.14,"tv":20.9,"id":35736915}]}]}
{"op":"mcm","clk":"11942849453","pt":1724869048136,"mc":[{"id":"1.232283784","rc":[{"batb":[[0,2.3,29.7],[1,1.2,1000],[2,1.04,1.05]],"ltp":2.14,"tv":20.9,"id":35736915}]}]}
{"op":"mcm","clk":"11942849848","pt":1724869050605,"mc":[{"id":"1.232283784","rc":[{"batb":[[0,2.32,5],[1,2.3,29.7],[2,1.2,1000]],"ltp":2.14,"tv":20.9,"id":35736915}]}]}
{"op":"mcm","clk":"11942850408","pt":1724869054295,"mc":[{"id":"1.232283784","rc":[{"batb":[[0,2.3,29.7],[1,1.2,1000],[2,1.04,1.05]],"ltp":2.14,"tv":20.9,"id":35736915}]}]}
{"op":"mcm","clk":"11942850780","pt":1724869056466,"mc":[{"id":"1.232283784","rc":[{"batb":[[0,2.32,5],[1,2.3,29.7],[2,1.2,1000]],"ltp":2.14,"tv":20.9,"id":35736915}]}]}
{"op":"mcm","clk":"11942851261","pt":1724869059794,"mc":[{"id":"1.232283784","rc":[{"batb":[[0,2.3,29.7],[1,1.2,1000],[2,1.04,1.05]],"ltp":2.14,"tv":20.9,"id":35736915}]}]}
{"op":"mcm","clk":"11942851588","pt":1724869062005,"mc":[{"id":"1.232283784","rc":[{"batb":[[0,2.32,5],[1,2.3,29.7],[2,1.2,1000]],"ltp":2.14,"tv":20.9,"id":35736915}]}]}
{"op":"mcm","clk":"11942852212","pt":1724869065801,"mc":[{"id":"1.232283784","rc":[{"batb":[[0,2.3,29.7],[1,1.2,1000],[2,1.04,1.05]],"ltp":2.14,"tv":20.9,"id":35736915}]}]}
{"op":"mcm","clk":"11942852533","pt":1724869067998,"mc":[{"id":"1.232283784","rc":[{"batb":[[0,2.32,5],[1,2.3,29.7],[2,1.2,1000]],"ltp":2.14,"tv":20.9,"id":35736915}]}]}
{"op":"mcm","clk":"11942853087","pt":1724869071602,"mc":[{"id":"1.232283784","rc":[{"batb":[[0,2.3,29.7],[1,1.2,1000],[2,1.04,1.05]],"ltp":2.14,"tv":20.9,"id":35736915}]}]}
{"op":"mcm","clk":"11942853573","pt":1724869074705,"mc":[{"id":"1.232283784","rc":[{"batb":[[0,2.32,5],[1,2.3,29.7],[2,1.2,1000]],"ltp":2.14,"tv":20.9,"id":35736915}]}]}
{"op":"mcm","clk":"11942854102","pt":1724869078209,"mc":[{"id":"1.232283784","rc":[{"batb":[[0,2.3,29.7],[1,1.2,1000],[2,1.04,1.05]],"ltp":2.14,"tv":20.9,"id":35736915}]}]}
{"op":"mcm","clk":"11942854626","pt":1724869081603,"mc":[{"id":"1.232283784","rc":[{"batb":[[0,2.32,5],[1,2.3,29.7],[2,1.2,1000]],"ltp":2.14,"tv":20.9,"id":35736915}]}]}
{"op":"mcm","clk":"11942855244","pt":1724869085554,"mc":[{"id":"1.232283784","rc":[{"batb":[[0,2.3,29.7],[1,1.2,1000],[2,1.04,1.05]],"ltp":2.14,"tv":20.9,"id":35736915}]}]}
{"op":"mcm","clk":"11942855726","pt":1724869088584,"mc":[{"id":"1.232283784","rc":[{"batb":[[0,2.32,5],[1,2.3,29.7],[2,1.2,1000]],"ltp":2.14,"tv":20.9,"id":35736915}]}]}
{"op":"mcm","clk":"11942856182","pt":1724869091886,"mc":[{"id":"1.232283784","rc":[{"batb":[[0,2.3,29.7],[1,1.2,1000],[2,1.04,1.05]],"ltp":2.14,"tv":20.9,"id":35736915}]}]}
{"op":"mcm","clk":"11942856562","pt":1724869094614,"mc":[{"id":"1.232283784","rc":[{"batb":[[0,2.32,5],[1,2.3,29.7],[2,1.2,1000]],"ltp":2.14,"tv":20.9,"id":35736915}]}]}
{"op":"mcm","clk":"11942857028","pt":1724869098109,"mc":[{"id":"1.232283784","rc":[{"batb":[[0,2.3,29.7],[1,1.2,1000],[2,1.04,1.05]],"ltp":2.14,"tv":20.9,"id":35736915}]}]}
{"op":"mcm","clk":"11942857472","pt":1724869101403,"mc":[{"id":"1.232283784","rc":[{"batb":[[0,2.32,5],[1,2.3,29.7],[2,1.2,1000]],"ltp":2.14,"tv":20.9,"id":35736915}]}]}
{"op":"mcm","clk":"11942857936","pt":1724869104800,"mc":[{"id":"1.232283784","rc":[{"batb":[[0,2.3,29.7],[1,1.2,1000],[2,1.04,1.05]],"ltp":2.14,"tv":20.9,"id":35736915}]}]}
{"op":"mcm","clk":"11942858437","pt":1724869108096,"mc":[{"id":"1.232283784","rc":[{"batb":[[0,2.32,5],[1,2.3,29.7],[2,1.2,1000]],"ltp":2.14,"tv":20.9,"id":35736915}]}]}
{"op":"mcm","clk":"11942858919","pt":1724869111395,"mc":[{"id":"1.232283784","rc":[{"batb":[[0,2.3,29.7],[1,1.2,1000],[2,1.04,1.05]],"ltp":2.14,"tv":20.9,"id":35736915}]}]}
{"op":"mcm","clk":"11942859411","pt":1724869114708,"mc":[{"id":"1.232283784","rc":[{"batb":[[0,2.32,5],[1,2.3,29.7],[2,1.2,1000]],"ltp":2.14,"tv":20.9,"id":35736915}]}]}
{"op":"mcm","clk":"11942859970","pt":1724869118425,"mc":[{"id":"1.232283784","rc":[{"batb":[[0,2.3,29.7],[1,1.2,1000],[2,1.04,1.05]],"ltp":2.14,"tv":20.9,"id":35736915}]}]}
{"op":"mcm","clk":"11942860273","pt":1724869120622,"mc":[{"id":"1.232283784","rc":[{"batb":[[0,2.32,5],[1,2.3,29.7],[2,1.2,1000]],"ltp":2.14,"tv":20.9,"id":35736915}]}]}
{"op":"mcm","clk":"11942860827","pt":1724869124192,"mc":[{"id":"1.232283784","rc":[{"batb":[[0,2.3,29.7],[1,1.2,1000],[2,1.04,1.05]],"ltp":2.14,"tv":20.9,"id":35736915}]}]}
{"op":"mcm","clk":"11942861242","pt":1724869126802,"mc":[{"id":"1.232283784","rc":[{"batb":[[0,2.32,5],[1,2.3,29.7],[2,1.2,1000]],"ltp":2.14,"tv":20.9,"id":35736915}]}]}
{"op":"mcm","clk":"11942861848","pt":1724869130632,"mc":[{"id":"1.232283784","rc":[{"batb":[[0,2.3,29.7],[1,1.2,1000],[2,1.04,1.05]],"ltp":2.14,"tv":20.9,"id":35736915}]}]}
{"op":"mcm","clk":"11942862408","pt":1724869134340,"mc":[{"id":"1.232283784","rc":[{"batb":[[0,2.32,5],[1,2.3,29.7],[2,1.2,1000]],"ltp":2.14,"tv":20.9,"id":35736915}]}]}
{"op":"mcm","clk":"11942862887","pt":1724869137622,"mc":[{"id":"1.232283784","rc":[{"batb":[[0,2.3,29.7],[1,1.2,1000],[2,1.04,1.05]],"ltp":2.14,"tv":20.9,"id":35736915}]}]}
{"op":"mcm","clk":"11942863524","pt":1724869142025,"mc":[{"id":"1.232283784","rc":[{"batb":[[0,2.32,5],[1,2.3,29.7],[2,1.2,1000]],"ltp":2.14,"tv":20.9,"id":35736915}]}]}
{"op":"mcm","clk":"11942863997","pt":1724869145220,"mc":[{"id":"1.232283784","rc":[{"batb":[[0,2.3,29.7],[1,1.2,1000],[2,1.04,1.05]],"ltp":2.14,"tv":20.9,"id":35736915}]}]}
{"op":"mcm","clk":"11942864465","pt":1724869148431,"mc":[{"id":"1.232283784","rc":[{"batb":[[0,2.32,5],[1,2.3,29.7],[2,1.2,1000]],"ltp":2.14,"tv":20.9,"id":35736915}]}]}
{"op":"mcm","clk":"11942865033","pt":1724869152157,"mc":[{"id":"1.232283784","rc":[{"batb":[[0,2.3,29.7],[1,1.2,1000],[2,1.04,1.05]],"ltp":2.14,"tv":20.9,"id":35736915}]}]}
{"op":"mcm","clk":"11942865737","pt":1724869156746,"mc":[{"id":"1.232283784","rc":[{"batb":[[0,2.32,5],[1,2.3,29.7],[2,1.2,1000]],"ltp":2.14,"tv":20.9,"id":35736915}]}]}
{"op":"mcm","clk":"11942866299","pt":1724869160354,"mc":[{"id":"1.232283784","rc":[{"batb":[[0,2.3,29.7],[1,1.2,1000],[2,1.04,1.05]],"ltp":2.14,"tv":20.9,"id":35736915}]}]}
{"op":"mcm","clk":"11942866776","pt":1724869163748,"mc":[{"id":"1.232283784","rc":[{"batb":[[0,2.32,5],[1,2.3,29.7],[2,1.2,1000]],"ltp":2.14,"tv":20.9,"id":35736915}]}]}
{"op":"mcm","clk":"11942867279","pt":1724869167090,"mc":[{"id":"1.232283784","rc":[{"batb":[[0,2.3,29.7],[1,1.2,1000],[2,1.04,1.05]],"ltp":2.14,"tv":20.9,"id":35736915}]}]}
{"op":"mcm","clk":"11942867634","pt":1724869169291,"mc":[{"id":"1.232283784","rc":[{"batb":[[0,2.32,5],[1,2.3,29.7],[2,1.2,1000]],"ltp":2.14,"tv":20.9,"id":35736915}]}]}
{"op":"mcm","clk":"11942868234","pt":1724869173090,"mc":[{"id":"1.232283784","rc":[{"batb":[[0,2.3,29.7],[1,1.2,1000],[2,1.04,1.05]],"ltp":2.14,"tv":20.9,"id":35736915}]}]}
{"op":"mcm","clk":"11942868692","pt":1724869175894,"mc":[{"id":"1.232283784","rc":[{"batb":[[0,2.32,5],[1,2.3,29.7],[2,1.2,1000]],"ltp":2.14,"tv":20.9,"id":35736915}]}]}
{"op":"mcm","clk":"11942869273","pt":1724869179230,"mc":[{"id":"1.232283784","rc":[{"batb":[[0,2.3,29.7],[1,1.2,1000],[2,1.04,1.05]],"ltp":2.14,"tv":20.9,"id":35736915}]}]}
{"op":"mcm","clk":"11942869840","pt":1724869183016,"mc":[{"id":"1.232283784","rc":[{"batb":[[0,2.32,5],[1,2.3,29.7],[2,1.2,1000]],"ltp":2.14,"tv":20.9,"id":35736915}]}]}
{"op":"mcm","clk":"11942870455","pt":1724869186811,"mc":[{"id":"1.232283784","rc":[{"batb":[[0,2.3,29.7],[1,1.2,1000],[2,1.04,1.05]],"ltp":2.14,"tv":20.9,"id":35736915}]}]}
{"op":"mcm","clk":"11942871395","pt":1724869192403,"mc":[{"id":"1.232283784","rc":[{"batb":[[0,2.32,5],[1,2.3,29.7],[2,1.2,1000]],"ltp":2.14,"tv":20.9,"id":35736915}]}]}
{"op":"mcm","clk":"11942871980","pt":1724869196119,"mc":[{"id":"1.232283784","rc":[{"batb":[[0,2.3,29.7],[1,1.2,1000],[2,1.04,1.05]],"ltp":2.14,"tv":20.9,"id":35736915}]}]}
{"op":"mcm","clk":"11942872500","pt":1724869199432,"mc":[{"id":"1.232283784","rc":[{"batb":[[0,2.32,5],[1,2.3,29.7],[2,1.2,1000]],"ltp":2.14,"tv":20.9,"id":35736915}]}]}
{"op":"mcm","clk":"11942873104","pt":1724869203114,"mc":[{"id":"1.232283784","rc":[{"batb":[[0,2.3,29.7],[1,1.2,1000],[2,1.04,1.05]],"ltp":2.14,"tv":20.9,"id":35736915}]}]}
{"op":"mcm","clk":"11942873458","pt":1724869205330,"mc":[{"id":"1.232283784","rc":[{"batb":[[0,2.32,5],[1,2.3,29.7],[2,1.2,1000]],"ltp":2.14,"tv":20.9,"id":35736915}]}]}
{"op":"mcm","clk":"11942874002","pt":1724869208632,"mc":[{"id":"1.232283784","rc":[{"batb":[[0,2.3,29.7],[1,1.2,1000],[2,1.04,1.05]],"ltp":2.14,"tv":20.9,"id":35736915}]}]}
{"op":"mcm","clk":"11942874453","pt":1724869211356,"mc":[{"id":"1.232283784","rc":[{"batb":[[0,2.32,5],[1,2.3,29.7],[2,1.2,1000]],"ltp":2.14,"tv":20.9,"id":35736915}]}]}
{"op":"mcm","clk":"11942875086","pt":1724869214933,"mc":[{"id":"1.232283784","rc":[{"batb":[[0,2.3,29.7],[1,1.2,1000],[2,1.04,1.05]],"ltp":2.14,"tv":20.9,"id":35736915}]}]}
{"op":"mcm","clk":"11942875665","pt":1724869218483,"mc":[{"id":"1.232283784","rc":[{"batb":[[0,2.32,5],[1,2.3,29.7],[2,1.2,1000]],"ltp":2.14,"tv":20.9,"id":35736915}]}]}
{"op":"mcm","clk":"11942876234","pt":1724869221930,"mc":[{"id":"1.232283784","rc":[{"batb":[[0,2.3,29.7],[1,1.2,1000],[2,1.04,1.05]],"ltp":2.14,"tv":20.9,"id":35736915}]}]}
{"op":"mcm","clk":"11942876684","pt":1724869224660,"mc":[{"id":"1.232283784","rc":[{"batb":[[0,2.32,5],[1,2.3,29.7],[2,1.2,1000]],"ltp":2.14,"tv":20.9,"id":35736915}]}]}
{"op":"mcm","clk":"11942877255","pt":1724869228138,"mc":[{"id":"1.232283784","rc":[{"batb":[[0,2.3,29.7],[1,1.2,1000],[2,1.04,1.05]],"ltp":2.14,"tv":20.9,"id":35736915}]}]}
{"op":"mcm","clk":"11942878001","pt":1724869232867,"mc":[{"id":"1.232283784","rc":[{"batb":[[0,2.32,5],[1,2.3,29.7],[2,1.2,1000]],"ltp":2.14,"tv":20.9,"id":35736915}]}]}
{"op":"mcm","clk":"11942878505","pt":1724869236386,"mc":[{"id":"1.232283784","rc":[{"batb":[[0,2.3,29.7],[1,1.2,1000],[2,1.04,1.05]],"ltp":2.14,"tv":20.9,"id":35736915}]}]}
{"op":"mcm","clk":"11942878977","pt":1724869239166,"mc":[{"id":"1.232283784","rc":[{"batb":[[0,2.32,5],[1,2.3,29.7],[2,1.2,1000]],"ltp":2.14,"tv":20.9,"id":35736915}]}]}
{"op":"mcm","clk":"11942879549","pt":1724869242582,"mc":[{"id":"1.232283784","rc":[{"batb":[[0,2.3,29.7],[1,1.2,1000],[2,1.04,1.05]],"ltp":2.14,"tv":20.9,"id":35736915}]}]}
{"op":"mcm","clk":"11942880011","pt":1724869245380,"mc":[{"id":"1.232283784","rc":[{"batb":[[0,2.32,5],[1,2.3,29.7],[2,1.2,1000]],"ltp":2.14,"tv":20.9,"id":35736915}]}]}
{"op":"mcm","clk":"11942880547","pt":1724869248785,"mc":[{"id":"1.232283784","rc":[{"batb":[[0,2.3,29.7],[1,1.2,1000],[2,1.04,1.05]],"ltp":2.14,"tv":20.9,"id":35736915}]}]}
{"op":"mcm","clk":"11942880939","pt":1724869251498,"mc":[{"id":"1.232283784","rc":[{"batb":[[0,2.32,5],[1,2.3,29.7],[2,1.2,1000]],"ltp":2.14,"tv":20.9,"id":35736915}]}]}
{"op":"mcm","clk":"11942881629","pt":1724869255809,"mc":[{"id":"1.232283784","rc":[{"batb":[[0,2.3,29.7],[1,1.2,1000],[2,1.04,1.05]],"ltp":2.14,"tv":20.9,"id":35736915}]}]}
{"op":"mcm","clk":"11942882017","pt":1724869258011,"mc":[{"id":"1.232283784","rc":[{"batb":[[0,2.32,5],[1,2.3,29.7],[2,1.2,1000]],"ltp":2.14,"tv":20.9,"id":35736915}]}]}
{"op":"mcm","clk":"11942882614","pt":1724869261711,"mc":[{"id":"1.232283784","rc":[{"batb":[[0,2.3,29.7],[1,1.2,1000],[2,1.04,1.05]],"ltp":2.14,"tv":20.9,"id":35736915}]}]}
{"op":"mcm","clk":"11942883003","pt":1724869264098,"mc":[{"id":"1.232283784","rc":[{"batb":[[0,2.32,5],[1,2.3,29.7],[2,1.2,1000]],"ltp":2.14,"tv":20.9,"id":35736915}]}]}
{"op":"mcm","clk":"11942883623","pt":1724869268018,"mc":[{"id":"1.232283784","rc":[{"batb":[[0,2.3,29.7],[1,1.2,1000],[2,1.04,1.05]],"ltp":2.14,"tv":20.9,"id":35736915}]}]}
{"op":"mcm","clk":"11942884018","pt":1724869270313,"mc":[{"id":"1.232283784","rc":[{"batb":[[0,2.32,5],[1,2.3,29.7],[2,1.2,1000]],"ltp":2.14,"tv":20.9,"id":35736915}]}]}
{"op":"mcm","clk":"11942884571","pt":1724869273886,"mc":[{"id":"1.232283784","rc":[{"batb":[[0,2.3,29.7],[1,1.2,1000],[2,1.04,1.05]],"ltp":2.14,"tv":20.9,"id":35736915}]}]}
{"op":"mcm","clk":"11942884955","pt":1724869276401,"mc":[{"id":"1.232283784","rc":[{"batb":[[0,2.32,5],[1,2.3,29.7],[2,1.2,1000]],"ltp":2.14,"tv":20.9,"id":35736915},{"batb":[[0,1.25,80.3],[1,1.24,6.49],[2,1.2,1000]],"ltp":1.62,"tv":154.47,"id":11445382}]}]}
{"op":"mcm","clk":"11942885515","pt":1724869280123,"mc":[{"id":"1.232283784","rc":[{"batb":[[0,2.3,29.7],[1,1.2,1000],[2,1.04,1.05]],"ltp":2.14,"tv":20.9,"id":35736915}]}]}
{"op":"mcm","clk":"11943062362","pt":1724870350469,"mc":[{"id":"1.232283784","rc":[{"batb":[[0,2.52,5.82],[1,2.3,29.7],[2,1.2,1000]],"ltp":2.14,"tv":20.9,"id":35736915},{"batb":[[0,1.26,7.37],[1,1.25,79.42]],"ltp":1.62,"tv":154.47,"id":11445382}]}]}
{"op":"mcm","clk":"11943121033","pt":1724870723664,"mc":[{"id":"1.232283784","rc":[{"batb":[[0,1.27,196.9],[1,1.26,6.49]],"ltp":1.62,"tv":154.47,"id":11445382}]}]}
{"op":"mcm","clk":"11943178927","pt":1724871133292,"mc":[{"id":"1.232283784","rc":[{"batl":[[0,1.65,5.32],[1,1.66,80.58]],"ltp":1.62,"tv":154.47,"id":11445382}]}]}
{"op":"mcm","clk":"11943361681","pt":1724872374784,"mc":[{"id":"1.232283784","rc":[{"batb":[[0,2.52,5.81]],"ltp":2.14,"tv":20.9,"id":35736915},{"trd":[[1.62,129.49],[1.66,12.25],[1.7,11.55]],"batb":[[1,1.26,6.48]],"batl":[[0,1.65,5.32],[1,1.66,80.62]],"ltp":1.62,"tv":154.51,"id":11445382}],"tv":175.41}]}
{"op":"mcm","clk":"11943481059","pt":1724873033509,"mc":[{"id":"1.232283784","rc":[{"batb":[[0,1.28,6.48],[1,1.27,196.9]],"ltp":1.62,"tv":154.51,"id":11445382}]}]}
{"op":"mcm","clk":"11944107141","pt":1724877774781,"mc":[{"id":"1.232283784","rc":[{"trd":[[1.62,129.52],[1.66,12.25],[1.7,11.55]],"batl":[[0,1.65,5.31],[1,1.66,80.65]],"ltp":1.62,"tv":154.55,"id":11445382}],"tv":175.45}]}
{"op":"mcm","clk":"11944366529","pt":1724881533677,"mc":[{"id":"1.232283784","rc":[{"batb":[[0,2.52,5.81]],"ltp":2.14,"tv":20.9,"id":35736915},{"trd":[[1.62,129.54],[1.66,12.25],[1.7,11.55]],"batb":[[0,1.3,7.01],[1,1.28,6.48],[2,1.27,196.9]],"batl":[[1,1.66,80.67]],"ltp":1.62,"tv":154.57,"id":11445382}],"tv":175.47}]}
{"op":"mcm","clk":"11944366547","pt":1724881534139,"mc":[{"id":"1.232283784","rc":[{"batb":[[0,1.31,165.88],[1,1.3,7.01],[2,1.28,6.48]],"ltp":1.62,"tv":154.57,"id":11445382}]}]}
{"op":"mcm","clk":"11944367196","pt":1724881546664,"mc":[{"id":"1.232283784","rc":[{"batb":[[0,1.31,166.81]],"ltp":1.62,"tv":154.57,"id":11445382}]}]}
{"op":"mcm","clk":"11944367616","pt":1724881554766,"mc":[{"id":"1.232283784","rc":[{"batb":[[1,1.28,6.48],[2,1.2,1000.88]],"ltp":1.62,"tv":154.57,"id":11445382}]}]}
{"op":"mcm","clk":"11944367622","pt":1724881554872,"mc":[{"id":"1.232283784","rc":[{"batb":[[0,1.32,7.94],[1,1.31,165.88],[2,1.28,6.48]],"ltp":1.62,"tv":154.57,"id":11445382}]}]}
{"op":"mcm","clk":"11944371994","pt":1724881626447,"mc":[{"id":"1.232283784","rc":[{"batb":[[0,1.34,163.07],[1,1.32,7.01]],"ltp":1.62,"tv":154.57,"id":11445382}]}]}
{"op":"mcm","clk":"11944471328","pt":1724883174778,"mc":[{"id":"1.232283784","rc":[{"trd":[[1.62,129.52],[1.66,12.25],[1.7,11.55]],"batl":[[1,1.66,80.65]],"ltp":1.62,"tv":154.55,"id":11445382}],"tv":175.45}]}
{"op":"mcm","clk":"11944504641","pt":1724883511686,"mc":[{"id":"1.232283784","rc":[{"batb":[[0,1.35,7.41],[1,1.34,162.14],[2,1.32,7.01]],"ltp":1.62,"tv":154.55,"id":11445382}]}]}
{"op":"mcm","clk":"11944511218","pt":1724883601846,"mc":[{"id":"1.232283784","rc":[{"batb":[[0,1.36,117.88],[1,1.35,7.41]],"ltp":1.62,"tv":154.55,"id":11445382}]}]}
{"op":"mcm","clk":"11944569225","pt":1724884402122,"mc":[{"id":"1.232283784","rc":[{"batb":[[0,1.35,7.41],[1,1.32,7.01],[2,1.2,1000.88]],"ltp":1.62,"tv":154.55,"id":11445382}]}]}
{"op":"mcm","clk":"11944569287","pt":1724884403089,"mc":[{"id":"1.232283784","rc":[{"batb":[[0,2.54,5],[1,2.52,5.81],[2,2.3,29.7]],"batl":[[0,5.9,10.06]],"ltp":2.14,"tv":20.9,"id":35736915}]}]}
{"op":"mcm","clk":"11944569513","pt":1724884406537,"mc":[{"id":"1.232283784","rc":[{"batb":[[0,2.52,5.81],[1,2.3,29.7],[2,1.2,1000]],"ltp":2.14,"tv":20.9,"id":35736915}]}]}
{"op":"mcm","clk":"11944569753","pt":1724884409617,"mc":[{"id":"1.232283784","rc":[{"batb":[[0,2.54,5],[1,2.52,5.81],[2,2.3,29.7]],"ltp":2.14,"tv":20.9,"id":35736915}]}]}
{"op":"mcm","clk":"11944570134","pt":1724884414510,"mc":[{"id":"1.232283784","rc":[{"batb":[[0,2.52,5.81],[1,2.3,29.7],[2,1.2,1000]],"ltp":2.14,"tv":20.9,"id":35736915}]}]}
{"op":"mcm","clk":"11944570507","pt":1724884419847,"mc":[{"id":"1.232283784","rc":[{"batb":[[0,2.54,5],[1,2.52,5.81],[2,2.3,29.7]],"ltp":2.14,"tv":20.9,"id":35736915}]}]}
{"op":"mcm","clk":"11944570743","pt":1724884423544,"mc":[{"id":"1.232283784","rc":[{"batb":[[0,2.52,5.81],[1,2.3,29.7],[2,1.2,1000]],"ltp":2.14,"tv":20.9,"id":35736915}]}]}
{"op":"mcm","clk":"11944570914","pt":1724884426014,"mc":[{"id":"1.232283784","rc":[{"batb":[[0,2.54,5],[1,2.52,5.81],[2,2.3,29.7]],"ltp":2.14,"tv":20.9,"id":35736915}]}]}
{"op":"mcm","clk":"11944571167","pt":1724884429621,"mc":[{"id":"1.232283784","rc":[{"batb":[[0,2.52,5.81],[1,2.3,29.7],[2,1.2,1000]],"ltp":2.14,"tv":20.9,"id":35736915}]}]}
{"op":"mcm","clk":"11944571395","pt":1724884432929,"mc":[{"id":"1.232283784","rc":[{"batb":[[0,2.54,5],[1,2.52,5.81],[2,2.3,29.7]],"ltp":2.14,"tv":20.9,"id":35736915}]}]}
{"op":"mcm","clk":"11944571673","pt":1724884436523,"mc":[{"id":"1.232283784","rc":[{"batb":[[0,2.52,5.81],[1,2.3,29.7],[2,1.2,1000]],"ltp":2.14,"tv":20.9,"id":35736915}]}]}
{"op":"mcm","clk":"11944571912","pt":1724884439764,"mc":[{"id":"1.232283784","rc":[{"batb":[[0,2.54,5],[1,2.52,5.81],[2,2.3,29.7]],"ltp":2.14,"tv":20.9,"id":35736915}]}]}
{"op":"mcm","clk":"11944572158","pt":1724884443248,"mc":[{"id":"1.232283784","rc":[{"batb":[[0,2.52,5.81],[1,2.3,29.7],[2,1.2,1000]],"ltp":2.14,"tv":20.9,"id":35736915}]}]}
{"op":"mcm","clk":"11944572356","pt":1724884446030,"mc":[{"id":"1.232283784","rc":[{"batb":[[0,2.54,5],[1,2.52,5.81],[2,2.3,29.7]],"ltp":2.14,"tv":20.9,"id":35736915}]}]}
{"op":"mcm","clk":"11944572613","pt":1724884449433,"mc":[{"id":"1.232283784","rc":[{"batb":[[0,2.52,5.81],[1,2.3,29.7],[2,1.2,1000]],"ltp":2.14,"tv":20.9,"id":35736915}]}]}
{"op":"mcm","clk":"11944572797","pt":1724884452158,"mc":[{"id":"1.232283784","rc":[{"batb":[[0,2.54,5],[1,2.52,5.81],[2,2.3,29.7]],"ltp":2.14,"tv":20.9,"id":35736915}]}]}
{"op":"mcm","clk":"11944573047","pt":1724884455655,"mc":[{"id":"1.232283784","rc":[{"batb":[[0,2.52,5.81],[1,2.3,29.7],[2,1.2,1000]],"ltp":2.14,"tv":20.9,"id":35736915}]}]}
{"op":"mcm","clk":"11944573279","pt":1724884459158,"mc":[{"id":"1.232283784","rc":[{"batb":[[0,2.54,5],[1,2.52,5.81],[2,2.3,29.7]],"ltp":2.14,"tv":20.9,"id":35736915}]}]}
{"op":"mcm","clk":"11944573521","pt":1724884462462,"mc":[{"id":"1.232283784","rc":[{"batb":[[0,2.52,5.81],[1,2.3,29.7],[2,1.2,1000]],"ltp":2.14,"tv":20.9,"id":35736915}]}]}
{"op":"mcm","clk":"11944573780","pt":1724884465862,"mc":[{"id":"1.232283784","rc":[{"batb":[[0,2.54,5],[1,2.52,5.81],[2,2.3,29.7]],"ltp":2.14,"tv":20.9,"id":35736915}]}]}
{"op":"mcm","clk":"11944574036","pt":1724884469257,"mc":[{"id":"1.232283784","rc":[{"batb":[[0,2.52,5.81],[1,2.3,29.7],[2,1.2,1000]],"ltp":2.14,"tv":20.9,"id":35736915}]}]}
{"op":"mcm","clk":"11944574238","pt":1724884472083,"mc":[{"id":"1.232283784","rc":[{"batb":[[0,2.54,5],[1,2.52,5.81],[2,2.3,29.7]],"ltp":2.14,"tv":20.9,"id":35736915}]}]}
{"op":"mcm","clk":"11944574515","pt":1724884476156,"mc":[{"id":"1.232283784","rc":[{"batb":[[0,2.52,5.81],[1,2.3,29.7],[2,1.2,1000]],"ltp":2.14,"tv":20.9,"id":35736915}]}]}
{"op":"mcm","clk":"11944574742","pt":1724884478983,"mc":[{"id":"1.232283784","rc":[{"batb":[[0,2.54,5],[1,2.52,5.81],[2,2.3,29.7]],"ltp":2.14,"tv":20.9,"id":35736915}]}]}
{"op":"mcm","clk":"11944574967","pt":1724884482279,"mc":[{"id":"1.232283784","rc":[{"batb":[[0,2.52,5.81],[1,2.3,29.7],[2,1.2,1000]],"ltp":2.14,"tv":20.9,"id":35736915}]}]}
{"op":"mcm","clk":"11944575203","pt":1724884485581,"mc":[{"id":"1.232283784","rc":[{"batb":[[0,2.54,5],[1,2.52,5.81],[2,2.3,29.7]],"ltp":2.14,"tv":20.9,"id":35736915}]}]}
{"op":"mcm","clk":"11944575420","pt":1724884488866,"mc":[{"id":"1.232283784","rc":[{"batb":[[0,2.52,5.81],[1,2.3,29.7],[2,1.2,1000]],"ltp":2.14,"tv":20.9,"id":35736915}]}]}
{"op":"mcm","clk":"11944575595","pt":1724884491393,"mc":[{"id":"1.232283784","rc":[{"batb":[[0,2.54,5],[1,2.52,5.81],[2,2.3,29.7]],"ltp":2.14,"tv":20.9,"id":35736915}]}]}
{"op":"mcm","clk":"11944575854","pt":1724884494886,"mc":[{"id":"1.232283784","rc":[{"batb":[[0,2.52,5.81],[1,2.3,29.7],[2,1.2,1000]],"ltp":2.14,"tv":20.9,"id":35736915}]}]}
{"op":"mcm","clk":"11944576031","pt":1724884497506,"mc":[{"id":"1.232283784","rc":[{"batb":[[0,2.54,5],[1,2.52,5.81],[2,2.3,29.7]],"ltp":2.14,"tv":20.9,"id":35736915}]}]}
{"op":"mcm","clk":"11944576231","pt":1724884500897,"mc":[{"id":"1.232283784","rc":[{"batb":[[0,2.52,5.81],[1,2.3,29.7],[2,1.2,1000]],"ltp":2.14,"tv":20.9,"id":35736915}]}]}
{"op":"mcm","clk":"11944576390","pt":1724884503368,"mc":[{"id":"1.232283784","rc":[{"batb":[[0,2.54,5],[1,2.52,5.81],[2,2.3,29.7]],"ltp":2.14,"tv":20.9,"id":35736915}]}]}
{"op":"mcm","clk":"11944576631","pt":1724884507118,"mc":[{"id":"1.232283784","rc":[{"batb":[[0,2.52,5.81],[1,2.3,29.7],[2,1.2,1000]],"ltp":2.14,"tv":20.9,"id":35736915}]}]}
{"op":"mcm","clk":"11944576824","pt":1724884509893,"mc":[{"id":"1.232283784","rc":[{"batb":[[0,2.54,5],[1,2.52,5.81],[2,2.3,29.7]],"ltp":2.14,"tv":20.9,"id":35736915}]}]}
{"op":"mcm","clk":"11944577066","pt":1724884513582,"mc":[{"id":"1.232283784","rc":[{"batb":[[0,2.52,5.81],[1,2.3,29.7],[2,1.2,1000]],"ltp":2.14,"tv":20.9,"id":35736915}]}]}
{"op":"mcm","clk":"11944577238","pt":1724884516000,"mc":[{"id":"1.232283784","rc":[{"batb":[[0,2.54,5],[1,2.52,5.81],[2,2.3,29.7]],"ltp":2.14,"tv":20.9,"id":35736915}]}]}
{"op":"mcm","clk":"11944577485","pt":1724884519404,"mc":[{"id":"1.232283784","rc":[{"batb":[[0,2.52,5.81],[1,2.3,29.7],[2,1.2,1000]],"ltp":2.14,"tv":20.9,"id":35736915}]}]}
{"op":"mcm","clk":"11944577682","pt":1724884522222,"mc":[{"id":"1.232283784","rc":[{"batb":[[0,2.54,5],[1,2.52,5.81],[2,2.3,29.7]],"ltp":2.14,"tv":20.9,"id":35736915}]}]}
{"op":"mcm","clk":"11944577951","pt":1724884525614,"mc":[{"id":"1.232283784","rc":[{"batb":[[0,2.52,5.81],[1,2.3,29.7],[2,1.2,1000]],"ltp":2.14,"tv":20.9,"id":35736915}]}]}
{"op":"mcm","clk":"11944578175","pt":1724884528593,"mc":[{"id":"1.232283784","rc":[{"batb":[[0,2.54,5],[1,2.52,5.81],[2,2.3,29.7]],"ltp":2.14,"tv":20.9,"id":35736915}]}]}
{"op":"mcm","clk":"11944578376","pt":1724884532026,"mc":[{"id":"1.232283784","rc":[{"batb":[[0,2.52,5.81],[1,2.3,29.7],[2,1.2,1000]],"ltp":2.14,"tv":20.9,"id":35736915}]}]}
{"op":"mcm","clk":"11944578562","pt":1724884535005,"mc":[{"id":"1.232283784","rc":[{"batb":[[0,2.54,5],[1,2.52,5.81],[2,2.3,29.7]],"ltp":2.14,"tv":20.9,"id":35736915}]}]}
{"op":"mcm","clk":"11944578801","pt":1724884538604,"mc":[{"id":"1.232283784","rc":[{"batb":[[0,2.52,5.81],[1,2.3,29.7],[2,1.2,1000]],"ltp":2.14,"tv":20.9,"id":35736915}]}]}
{"op":"mcm","clk":"11944578988","pt":1724884541426,"mc":[{"id":"1.232283784","rc":[{"batb":[[0,2.54,5],[1,2.52,5.81],[2,2.3,29.7]],"ltp":2.14,"tv":20.9,"id":35736915}]}]}
{"op":"mcm","clk":"11944579227","pt":1724884545125,"mc":[{"id":"1.232283784","rc":[{"batb":[[0,2.52,5.81],[1,2.3,29.7],[2,1.2,1000]],"ltp":2.14,"tv":20.9,"id":35736915}]}]}
{"op":"mcm","clk":"11944579415","pt":1724884548116,"mc":[{"id":"1.232283784","rc":[{"batb":[[0,2.54,5],[1,2.52,5.81],[2,2.3,29.7]],"ltp":2.14,"tv":20.9,"id":35736915}]}]}
{"op":"mcm","clk":"11944579625","pt":1724884551550,"mc":[{"id":"1.232283784","rc":[{"batb":[[0,2.52,5.81],[1,2.3,29.7],[2,1.2,1000]],"ltp":2.14,"tv":20.9,"id":35736915}]}]}
{"op":"mcm","clk":"11944579837","pt":1724884554023,"mc":[{"id":"1.232283784","rc":[{"batb":[[0,2.54,5],[1,2.52,5.81],[2,2.3,29.7]],"ltp":2.14,"tv":20.9,"id":35736915}]}]}
{"op":"mcm","clk":"11944580089","pt":1724884557735,"mc":[{"id":"1.232283784","rc":[{"batb":[[0,2.52,5.81],[1,2.3,29.7],[2,1.2,1000]],"ltp":2.14,"tv":20.9,"id":35736915}]}]}
{"op":"mcm","clk":"11944580289","pt":1724884560516,"mc":[{"id":"1.232283784","rc":[{"batb":[[0,2.54,5],[1,2.52,5.81],[2,2.3,29.7]],"ltp":2.14,"tv":20.9,"id":35736915}]}]}
{"op":"mcm","clk":"11944580550","pt":1724884564319,"mc":[{"id":"1.232283784","rc":[{"batb":[[0,2.52,5.81],[1,2.3,29.7],[2,1.2,1000]],"ltp":2.14,"tv":20.9,"id":35736915}]}]}
{"op":"mcm","clk":"11944580723","pt":1724884566629,"mc":[{"id":"1.232283784","rc":[{"batb":[[0,2.54,5],[1,2.52,5.81],[2,2.3,29.7]],"ltp":2.14,"tv":20.9,"id":35736915}]}]}
{"op":"mcm","clk":"11944580981","pt":1724884570529,"mc":[{"id":"1.232283784","rc":[{"batb":[[0,2.52,5.81],[1,2.3,29.7],[2,1.2,1000]],"ltp":2.14,"tv":20.9,"id":35736915}]}]}
{"op":"mcm","clk":"11944581159","pt":1724884573248,"mc":[{"id":"1.232283784","rc":[{"batb":[[0,2.54,5],[1,2.52,5.81],[2,2.3,29.7]],"ltp":2.14,"tv":20.9,"id":35736915}]}]}
{"op":"mcm","clk":"11944581407","pt":1724884576755,"mc":[{"id":"1.232283784","rc":[{"batb":[[0,2.52,5.81],[1,2.3,29.7],[2,1.2,1000]],"ltp":2.14,"tv":20.9,"id":35736915}]}]}
{"op":"mcm","clk":"11944581601","pt":1724884579584,"mc":[{"id":"1.232283784","rc":[{"batb":[[0,2.54,5],[1,2.52,5.81],[2,2.3,29.7]],"ltp":2.14,"tv":20.9,"id":35736915}]}]}
{"op":"mcm","clk":"11944581846","pt":1724884583094,"mc":[{"id":"1.232283784","rc":[{"batb":[[0,2.52,5.81],[1,2.3,29.7],[2,1.2,1000]],"ltp":2.14,"tv":20.9,"id":35736915}]}]}
{"op":"mcm","clk":"11944582035","pt":1724884585875,"mc":[{"id":"1.232283784","rc":[{"batb":[[0,2.54,5],[1,2.52,5.81],[2,2.3,29.7]],"ltp":2.14,"tv":20.9,"id":35736915}]}]}
{"op":"mcm","clk":"11944582294","pt":1724884589381,"mc":[{"id":"1.232283784","rc":[{"batb":[[0,2.52,5.81],[1,2.3,29.7],[2,1.2,1000]],"ltp":2.14,"tv":20.9,"id":35736915}]}]}
{"op":"mcm","clk":"11944582484","pt":1724884592057,"mc":[{"id":"1.232283784","rc":[{"batb":[[0,2.54,5],[1,2.52,5.81],[2,2.3,29.7]],"ltp":2.14,"tv":20.9,"id":35736915}]}]}
{"op":"mcm","clk":"11944582736","pt":1724884595663,"mc":[{"id":"1.232283784","rc":[{"batb":[[0,2.52,5.81],[1,2.3,29.7],[2,1.2,1000]],"ltp":2.14,"tv":20.9,"id":35736915}]}]}
{"op":"mcm","clk":"11944582930","pt":1724884598294,"mc":[{"id":"1.232283784","rc":[{"batb":[[0,2.54,5],[1,2.52,5.81],[2,2.3,29.7]],"ltp":2.14,"tv":20.9,"id":35736915}]}]}
{"op":"mcm","clk":"11944583161","pt":1724884601584,"mc":[{"id":"1.232283784","rc":[{"batb":[[0,2.52,5.81],[1,2.3,29.7],[2,1.2,1000]],"ltp":2.14,"tv":20.9,"id":35736915}]}]}
{"op":"mcm","clk":"11944583259","pt":1724884602866,"mc":[{"id":"1.232283784","rc":[{"batb":[[0,1.36,117.88],[1,1.35,7.41],[2,1.32,7.01]],"ltp":1.62,"tv":154.55,"id":11445382}]}]}
{"op":"mcm","clk":"11944583382","pt":1724884604459,"mc":[{"id":"1.232283784","rc":[{"batb":[[0,2.54,5],[1,2.52,5.81],[2,2.3,29.7]],"ltp":2.14,"tv":20.9,"id":35736915}]}]}
{"op":"mcm","clk":"11944583623","pt":1724884608006,"mc":[{"id":"1.232283784","rc":[{"batb":[[0,2.52,5.81],[1,2.3,29.7],[2,1.2,1000]],"ltp":2.14,"tv":20.9,"id":35736915}]}]}
{"op":"mcm","clk":"11944679783","pt":1724886110525,"mc":[{"id":"1.232283784","rc":[{"trd":[[1.62,129.52]],"batb":[[0,1.37,6.48],[1,1.36,117.88],[2,1.32,7.94]],"batl":[[0,1.65,5.32],[1,1.66,80.65]],"ltp":1.62,"tv":154.55,"id":11445382}],"tv":175.45}]}
{"op":"mcm","clk":"11945082257","pt":1724892760465,"mc":[{"id":"1.232283784","rc":[{"trd":[[1.62,129.51],[1.66,12.25],[1.7,11.55]],"batb":[[1,1.32,7.94],[2,1.2,1000.88]],"batl":[[1,1.66,80.63]],"ltp":1.62,"tv":154.53,"id":11445382}],"tv":175.43}]}
{"op":"mcm","clk":"11945083570","pt":1724892782803,"mc":[{"id":"1.232283784","rc":[{"batl":[[0,5.9,10.08]],"ltp":2.14,"tv":20.9,"id":35736915}]}]}
{"op":"mcm","clk":"11945083581","pt":1724892782908,"mc":[{"id":"1.232283784","rc":[{"batb":[[0,2.54,5],[1,2.52,5.81],[2,2.3,29.7]],"ltp":2.14,"tv":20.9,"id":35736915}]}]}
{"op":"mcm","clk":"11945083792","pt":1724892786203,"mc":[{"id":"1.232283784","rc":[{"batb":[[0,2.52,5.81],[1,2.3,29.7],[2,1.2,1000]],"ltp":2.14,"tv":20.9,"id":35736915}]}]}
{"op":"mcm","clk":"11945083956","pt":1724892788583,"mc":[{"id":"1.232283784","rc":[{"batb":[[0,2.54,5],[1,2.52,5.81],[2,2.3,29.7]],"ltp":2.14,"tv":20.9,"id":35736915}]}]}
{"op":"mcm","clk":"11945084147","pt":1724892791883,"mc":[{"id":"1.232283784","rc":[{"batb":[[0,2.52,5.81],[1,2.3,29.7],[2,1.2,1000]],"ltp":2.14,"tv":20.9,"id":35736915}]}]}
{"op":"mcm","clk":"11945084318","pt":1724892794979,"mc":[{"id":"1.232283784","rc":[{"batb":[[0,2.54,5],[1,2.52,5.81],[2,2.3,29.7]],"ltp":2.14,"tv":20.9,"id":35736915}]}]}
{"op":"mcm","clk":"11945084552","pt":1724892798486,"mc":[{"id":"1.232283784","rc":[{"batb":[[0,2.52,5.81],[1,2.3,29.7],[2,1.2,1000]],"ltp":2.14,"tv":20.9,"id":35736915}]}]}
{"op":"mcm","clk":"11945084719","pt":1724892801006,"mc":[{"id":"1.232283784","rc":[{"batb":[[0,2.54,5],[1,2.52,5.81],[2,2.3,29.7]],"ltp":2.14,"tv":20.9,"id":35736915}]}]}
{"op":"mcm","clk":"11945084953","pt":1724892804522,"mc":[{"id":"1.232283784","rc":[{"batb":[[0,2.52,5.81],[1,2.3,29.7],[2,1.2,1000]],"ltp":2.14,"tv":20.9,"id":35736915}]}]}
{"op":"mcm","clk":"11945085126","pt":1724892806998,"mc":[{"id":"1.232283784","rc":[{"batb":[[0,2.54,5],[1,2.52,5.81],[2,2.3,29.7]],"ltp":2.14,"tv":20.9,"id":35736915}]}]}
{"op":"mcm","clk":"11945085320","pt":1724892810495,"mc":[{"id":"1.232283784","rc":[{"batb":[[0,2.52,5.81],[1,2.3,29.7],[2,1.2,1000]],"ltp":2.14,"tv":20.9,"id":35736915}]}]}
{"op":"mcm","clk":"11945085489","pt":1724892812922,"mc":[{"id":"1.232283784","rc":[{"batb":[[0,2.54,5],[1,2.52,5.81],[2,2.3,29.7]],"ltp":2.14,"tv":20.9,"id":35736915}]}]}
{"op":"mcm","clk":"11945085682","pt":1724892816313,"mc":[{"id":"1.232283784","rc":[{"batb":[[0,2.52,5.81],[1,2.3,29.7],[2,1.2,1000]],"ltp":2.14,"tv":20.9,"id":35736915}]}]}
{"op":"mcm","clk":"11945085863","pt":1724892818707,"mc":[{"id":"1.232283784","rc":[{"batb":[[0,2.54,5],[1,2.52,5.81],[2,2.3,29.7]],"ltp":2.14,"tv":20.9,"id":35736915}]}]}
{"op":"mcm","clk":"11945086047","pt":1724892821950,"mc":[{"id":"1.232283784","rc":[{"batb":[[0,2.52,5.81],[1,2.3,29.7],[2,1.2,1000]],"ltp":2.14,"tv":20.9,"id":35736915}]}]}
{"op":"mcm","clk":"11945086220","pt":1724892824550,"mc":[{"id":"1.232283784","rc":[{"batb":[[0,2.54,5],[1,2.52,5.81],[2,2.3,29.7]],"ltp":2.14,"tv":20.9,"id":35736915}]}]}
{"op":"mcm","clk":"11945086422","pt":1724892827949,"mc":[{"id":"1.232283784","rc":[{"batb":[[0,2.52,5.81],[1,2.3,29.7],[2,1.2,1000]],"ltp":2.14,"tv":20.9,"id":35736915}]}]}
{"op":"mcm","clk":"11945086554","pt":1724892830424,"mc":[{"id":"1.232283784","rc":[{"batb":[[0,2.54,5],[1,2.52,5.81],[2,2.3,29.7]],"ltp":2.14,"tv":20.9,"id":35736915}]}]}
{"op":"mcm","clk":"11945086745","pt":1724892833727,"mc":[{"id":"1.232283784","rc":[{"batb":[[0,2.52,5.81],[1,2.3,29.7],[2,1.2,1000]],"ltp":2.14,"tv":20.9,"id":35736915}]}]}
{"op":"mcm","clk":"11945086888","pt":1724892836249,"mc":[{"id":"1.232283784","rc":[{"batb":[[0,2.54,5],[1,2.52,5.81],[2,2.3,29.7]],"ltp":2.14,"tv":20.9,"id":35736915}]}]}
{"op":"mcm","clk":"11945087063","pt":1724892839546,"mc":[{"id":"1.232283784","rc":[{"batb":[[0,2.52,5.81],[1,2.3,29.7],[2,1.2,1000]],"ltp":2.14,"tv":20.9,"id":35736915}]}]}
{"op":"mcm","clk":"11945087218","pt":1724892841935,"mc":[{"id":"1.232283784","rc":[{"batb":[[0,2.54,5],[1,2.52,5.81],[2,2.3,29.7]],"ltp":2.14,"tv":20.9,"id":35736915}]}]}
{"op":"mcm","clk":"11945087411","pt":1724892845340,"mc":[{"id":"1.232283784","rc":[{"batb":[[0,2.52,5.81],[1,2.3,29.7],[2,1.2,1000]],"ltp":2.14,"tv":20.9,"id":35736915}]}]}
{"op":"mcm","clk":"11945087550","pt":1724892847771,"mc":[{"id":"1.232283784","rc":[{"batb":[[0,2.54,5],[1,2.52,5.81],[2,2.3,29.7]],"ltp":2.14,"tv":20.9,"id":35736915}]}]}
{"op":"mcm","clk":"11945087729","pt":1724892851061,"mc":[{"id":"1.232283784","rc":[{"batb":[[0,2.52,5.81],[1,2.3,29.7],[2,1.2,1000]],"ltp":2.14,"tv":20.9,"id":35736915}]}]}
{"op":"mcm","clk":"11945087904","pt":1724892854167,"mc":[{"id":"1.232283784","rc":[{"batb":[[0,2.54,5],[1,2.52,5.81],[2,2.3,29.7]],"ltp":2.14,"tv":20.9,"id":35736915}]}]}
{"op":"mcm","clk":"11945088114","pt":1724892857576,"mc":[{"id":"1.232283784","rc":[{"batb":[[0,2.52,5.81],[1,2.3,29.7],[2,1.2,1000]],"ltp":2.14,"tv":20.9,"id":35736915}]}]}
{"op":"mcm","clk":"11945088333","pt":1724892861186,"mc":[{"id":"1.232283784","rc":[{"batb":[[0,2.54,5],[1,2.52,5.81],[2,2.3,29.7]],"ltp":2.14,"tv":20.9,"id":35736915}]}]}
{"op":"mcm","clk":"11945088546","pt":1724892864490,"mc":[{"id":"1.232283784","rc":[{"batb":[[0,2.52,5.81],[1,2.3,29.7],[2,1.2,1000]],"ltp":2.14,"tv":20.9,"id":35736915}]}]}
{"op":"mcm","clk":"11945088737","pt":1724892867791,"mc":[{"id":"1.232283784","rc":[{"batb":[[0,2.54,5],[1,2.52,5.81],[2,2.3,29.7]],"ltp":2.14,"tv":20.9,"id":35736915}]}]}
{"op":"mcm","clk":"11945088975","pt":1724892871303,"mc":[{"id":"1.232283784","rc":[{"batb":[[0,2.52,5.81],[1,2.3,29.7],[2,1.2,1000]],"ltp":2.14,"tv":20.9,"id":35736915}]}]}
{"op":"mcm","clk":"11945089103","pt":1724892873675,"mc":[{"id":"1.232283784","rc":[{"batb":[[0,2.54,5],[1,2.52,5.81],[2,2.3,29.7]],"ltp":2.14,"tv":20.9,"id":35736915}]}]}
{"op":"mcm","clk":"11945089311","pt":1724892877090,"mc":[{"id":"1.232283784","rc":[{"batb":[[0,2.52,5.81],[1,2.3,29.7],[2,1.2,1000]],"ltp":2.14,"tv":20.9,"id":35736915}]}]}
{"op":"mcm","clk":"11945089468","pt":1724892879511,"mc":[{"id":"1.232283784","rc":[{"batb":[[0,2.54,5],[1,2.52,5.81],[2,2.3,29.7]],"ltp":2.14,"tv":20.9,"id":35736915}]}]}
{"op":"mcm","clk":"11945089699","pt":1724892882915,"mc":[{"id":"1.232283784","rc":[{"batb":[[0,2.52,5.81],[1,2.3,29.7],[2,1.2,1000]],"ltp":2.14,"tv":20.9,"id":35736915}]}]}
{"op":"mcm","clk":"11945089835","pt":1724892885290,"mc":[{"id":"1.232283784","rc":[{"batb":[[0,2.54,5],[1,2.52,5.81],[2,2.3,29.7]],"ltp":2.14,"tv":20.9,"id":35736915}]}]}
{"op":"mcm","clk":"11945090023","pt":1724892888606,"mc":[{"id":"1.232283784","rc":[{"batb":[[0,2.52,5.81],[1,2.3,29.7],[2,1.2,1000]],"ltp":2.14,"tv":20.9,"id":35736915}]}]}
{"op":"mcm","clk":"11945090166","pt":1724892891028,"mc":[{"id":"1.232283784","rc":[{"batb":[[0,2.54,5],[1,2.52,5.81],[2,2.3,29.7]],"ltp":2.14,"tv":20.9,"id":35736915}]}]}
{"op":"mcm","clk":"11945090339","pt":1724892894322,"mc":[{"id":"1.232283784","rc":[{"batb":[[0,2.52,5.81],[1,2.3,29.7],[2,1.2,1000]],"ltp":2.14,"tv":20.9,"id":35736915}]}]}
{"op":"mcm","clk":"11945090494","pt":1724892896920,"mc":[{"id":"1.232283784","rc":[{"batb":[[0,2.54,5],[1,2.52,5.81],[2,2.3,29.7]],"ltp":2.14,"tv":20.9,"id":35736915}]}]}
{"op":"mcm","clk":"11945090669","pt":1724892900223,"mc":[{"id":"1.232283784","rc":[{"batb":[[0,2.52,5.81],[1,2.3,29.7],[2,1.2,1000]],"ltp":2.14,"tv":20.9,"id":35736915}]}]}
{"op":"mcm","clk":"11945090819","pt":1724892902626,"mc":[{"id":"1.232283784","rc":[{"batb":[[0,2.54,5],[1,2.52,5.81],[2,2.3,29.7]],"ltp":2.14,"tv":20.9,"id":35736915}]}]}
{"op":"mcm","clk":"11945091050","pt":1724892905827,"mc":[{"id":"1.232283784","rc":[{"batb":[[0,2.52,5.81],[1,2.3,29.7],[2,1.2,1000]],"ltp":2.14,"tv":20.9,"id":35736915}]}]}
{"op":"mcm","clk":"11945091256","pt":1724892908325,"mc":[{"id":"1.232283784","rc":[{"batb":[[0,2.54,5],[1,2.52,5.81],[2,2.3,29.7]],"ltp":2.14,"tv":20.9,"id":35736915}]}]}
{"op":"mcm","clk":"11945091501","pt":1724892911630,"mc":[{"id":"1.232283784","rc":[{"batb":[[0,2.52,5.81],[1,2.3,29.7],[2,1.2,1000]],"ltp":2.14,"tv":20.9,"id":35736915}]}]}
{"op":"mcm","clk":"11945091672","pt":1724892914111,"mc":[{"id":"1.232283784","rc":[{"batb":[[0,2.54,5],[1,2.52,5.81],[2,2.3,29.7]],"ltp":2.14,"tv":20.9,"id":35736915}]}]}
{"op":"mcm","clk":"11945091931","pt":1724892917520,"mc":[{"id":"1.232283784","rc":[{"batb":[[0,2.52,5.81],[1,2.3,29.7],[2,1.2,1000]],"ltp":2.14,"tv":20.9,"id":35736915}]}]}
{"op":"mcm","clk":"11945092096","pt":1724892919949,"mc":[{"id":"1.232283784","rc":[{"batb":[[0,2.54,5],[1,2.52,5.81],[2,2.3,29.7]],"ltp":2.14,"tv":20.9,"id":35736915}]}]}
{"op":"mcm","clk":"11945092307","pt":1724892923142,"mc":[{"id":"1.232283784","rc":[{"batb":[[0,2.52,5.81],[1,2.3,29.7],[2,1.2,1000]],"ltp":2.14,"tv":20.9,"id":35736915}]}]}
{"op":"mcm","clk":"11945092469","pt":1724892925668,"mc":[{"id":"1.232283784","rc":[{"batb":[[0,2.54,5],[1,2.52,5.81],[2,2.3,29.7]],"ltp":2.14,"tv":20.9,"id":35736915}]}]}
{"op":"mcm","clk":"11945092694","pt":1724892929169,"mc":[{"id":"1.232283784","rc":[{"batb":[[0,2.52,5.81],[1,2.3,29.7],[2,1.2,1000]],"ltp":2.14,"tv":20.9,"id":35736915}]}]}
{"op":"mcm","clk":"11945092833","pt":1724892931537,"mc":[{"id":"1.232283784","rc":[{"batb":[[0,2.54,5],[1,2.52,5.81],[2,2.3,29.7]],"ltp":2.14,"tv":20.9,"id":35736915}]}]}
{"op":"mcm","clk":"11945093057","pt":1724892934934,"mc":[{"id":"1.232283784","rc":[{"batb":[[0,2.52,5.81],[1,2.3,29.7],[2,1.2,1000]],"ltp":2.14,"tv":20.9,"id":35736915}]}]}
{"op":"mcm","clk":"11945093218","pt":1724892937356,"mc":[{"id":"1.232283784","rc":[{"batb":[[0,2.54,5],[1,2.52,5.81],[2,2.3,29.7]],"ltp":2.14,"tv":20.9,"id":35736915}]}]}
{"op":"mcm","clk":"11945093412","pt":1724892940552,"mc":[{"id":"1.232283784","rc":[{"batb":[[0,2.52,5.81],[1,2.3,29.7],[2,1.2,1000]],"ltp":2.14,"tv":20.9,"id":35736915}]}]}
{"op":"mcm","clk":"11945093602","pt":1724892943077,"mc":[{"id":"1.232283784","rc":[{"batb":[[0,2.54,5],[1,2.52,5.81],[2,2.3,29.7]],"ltp":2.14,"tv":20.9,"id":35736915}]}]}
{"op":"mcm","clk":"11945093828","pt":1724892946579,"mc":[{"id":"1.232283784","rc":[{"batb":[[0,2.52,5.81],[1,2.3,29.7],[2,1.2,1000]],"ltp":2.14,"tv":20.9,"id":35736915}]}]}
{"op":"mcm","clk":"11945094027","pt":1724892949064,"mc":[{"id":"1.232283784","rc":[{"batb":[[0,2.54,5],[1,2.52,5.81],[2,2.3,29.7]],"ltp":2.14,"tv":20.9,"id":35736915}]}]}
{"op":"mcm","clk":"11945094226","pt":1724892952363,"mc":[{"id":"1.232283784","rc":[{"batb":[[0,2.52,5.81],[1,2.3,29.7],[2,1.2,1000]],"ltp":2.14,"tv":20.9,"id":35736915}]}]}
{"op":"mcm","clk":"11945094450","pt":1724892955777,"mc":[{"id":"1.232283784","rc":[{"batb":[[0,2.54,5],[1,2.52,5.81],[2,2.3,29.7]],"ltp":2.14,"tv":20.9,"id":35736915}]}]}
{"op":"mcm","clk":"11945094661","pt":1724892959009,"mc":[{"id":"1.232283784","rc":[{"batb":[[0,2.52,5.81],[1,2.3,29.7],[2,1.2,1000]],"ltp":2.14,"tv":20.9,"id":35736915}]}]}
{"op":"mcm","clk":"11945094816","pt":1724892961378,"mc":[{"id":"1.232283784","rc":[{"batb":[[0,2.54,5],[1,2.52,5.81],[2,2.3,29.7]],"ltp":2.14,"tv":20.9,"id":35736915},{"batb":[[0,1.38,66.57],[1,1.37,6.48],[2,1.32,7.94]],"ltp":1.62,"tv":154.53,"id":11445382}]}]}
{"op":"mcm","clk":"11945095042","pt":1724892964890,"mc":[{"id":"1.232283784","rc":[{"batb":[[0,2.52,5.81],[1,2.3,29.7],[2,1.2,1000]],"ltp":2.14,"tv":20.9,"id":35736915}]}]}
{"op":"mcm","clk":"11945155188","pt":1724893974797,"mc":[{"id":"1.232283784","rc":[{"batb":[[0,2.52,5.8]],"ltp":2.14,"tv":20.9,"id":35736915},{"trd":[[1.62,129.6],[1.66,12.26],[1.7,11.56]],"batb":[[1,1.37,6.47],[2,1.32,7.93]],"batl":[[0,1.65,5.31],[1,1.66,80.75]],"ltp":1.62,"tv":154.64,"id":11445382}],"tv":175.54}]}
{"op":"mcm","clk":"11945167577","pt":1724894018531,"mc":[{"id":"1.232283784","rc":[{"batb":[[1,1.32,7.93],[2,1.2,1000.88]],"ltp":1.62,"tv":154.64,"id":11445382}]}]}
{"op":"mcm","clk":"11945279845","pt":1724896085275,"mc":[{"id":"1.232283784","rc":[{"batb":[[0,1.32,7.93],[1,1.2,1000.88],[2,1.04,1.05]],"ltp":1.62,"tv":154.64,"id":11445382}]}]}
{"op":"mcm","clk":"11945279930","pt":1724896086973,"mc":[{"id":"1.232283784","rc":[{"batl":[[0,5.9,9.95]],"ltp":2.14,"tv":20.9,"id":35736915}]}]}
{"op":"mcm","clk":"11945290144","pt":1724896286285,"mc":[{"id":"1.232283784","rc":[{"batb":[[0,1.33,112.89],[1,1.32,7],[2,1.2,1000.88]],"ltp":1.62,"tv":154.64,"id":11445382}]}]}
{"op":"mcm","clk":"11945308286","pt":1724896636298,"mc":[{"id":"1.232283784","rc":[{"batb":[[0,1.34,7.86],[1,1.33,111.96],[2,1.32,7]],"ltp":1.62,"tv":154.64,"id":11445382}]}]}
{"op":"mcm","clk":"11945351253","pt":1724897483346,"mc":[{"id":"1.232283784","rc":[{"batb":[[0,2.52,5.8]],"ltp":2.14,"tv":20.9,"id":35736915},{"trd":[[1.62,129.53],[1.66,12.25],[1.7,11.55]],"batb":[[0,1.35,161.86],[1,1.34,6.94],[2,1.32,7.01]],"batl":[[1,1.66,80.66]],"ltp":1.62,"tv":154.55,"id":11445382}],"tv":175.45}]}
{"op":"mcm","clk":"11945365778","pt":1724897777003,"mc":[{"id":"1.232283784","rc":[{"batl":[[1,1.66,0]],"ltp":1.62,"tv":154.55,"id":11445382}]}]}
{"op":"mcm","clk":"11945365853","pt":1724897778814,"mc":[{"id":"1.232283784","rc":[{"batl":[[0,1.64,0.88]],"ltp":1.62,"tv":154.55,"id":11445382}]}]}
{"op":"mcm","clk":"11945436973","pt":1724899324790,"mc":[{"id":"1.232283784","rc":[{"batb":[[0,2.32,5.8]],"ltp":2.14,"tv":20.9,"id":35736915},{"batb":[[0,1.36,6.94],[1,1.35,161.86]],"ltp":1.62,"tv":154.55,"id":11445382}]}]}
{"op":"mcm","clk":"11945551815","pt":1724901994748,"mc":[{"id":"1.232283784","rc":[{"batb":[[0,2.3,29.7],[1,1.2,1000],[2,1.04,1.05]],"ltp":2.14,"tv":20.9,"id":35736915},{"trd":[[1.62,129.54],[1.66,12.25],[1.7,11.55]],"batb":[[0,1.37,117.02],[1,1.36,6.94],[2,1.32,7.93]],"ltp":1.62,"tv":154.57,"id":11445382}],"tv":175.47}]}
{"op":"mcm","clk":"11945587749","pt":1724903006321,"mc":[{"id":"1.232283784","rc":[{"batb":[[0,1.36,6.94],[1,1.32,7.93],[2,1.2,1000.88]],"ltp":1.62,"tv":154.57,"id":11445382}]}]}
{"op":"mcm","clk":"11945588177","pt":1724903017639,"mc":[{"id":"1.232283784","rc":[{"batl":[[0,5.9,10.08]],"ltp":2.14,"tv":20.9,"id":35736915}]}]}
{"op":"mcm","clk":"11945618487","pt":1724903851104,"mc":[{"id":"1.232283784","rc":[{"batb":[[0,1.37,49.55],[1,1.36,6.94],[2,1.32,7.93]],"ltp":1.62,"tv":154.57,"id":11445382}]}]}
{"op":"mcm","clk":"11945626191","pt":1724904091748,"mc":[{"id":"1.232283784","rc":[{"trd":[[1.62,129.58],[1.66,12.25],[1.7,11.55]],"batb":[[0,1.4,7],[1,1.37,49.55],[2,1.36,6.94]],"ltp":1.62,"tv":154.61,"id":11445382}],"tv":175.51}]}
{"op":"mcm","clk":"11945632734","pt":1724904295706,"mc":[{"id":"1.232283784","rc":[{"batb":[[0,1.41,113.67],[1,1.4,7]],"ltp":1.62,"tv":154.61,"id":11445382}]}]}
{"op":"mcm","clk":"11945647953","pt":1724904712528,"mc":[{"id":"1.232283784","rc":[{"batb":[[2,1.27,1.8]],"ltp":1.62,"tv":154.61,"id":11445382}]}]}
{"op":"mcm","clk":"11945679556","pt":1724905218334,"mc":[{"id":"1.232283784","rc":[{"batb":[[0,1.42,5.58],[1,1.41,113.67],[2,1.4,7]],"ltp":1.62,"tv":154.61,"id":11445382}]}]}
{"op":"mcm","clk":"11945699013","pt":1724905820611,"mc":[{"id":"1.232283784","rc":[{"batb":[[0,1.44,53.9],[1,1.42,5.58]],"ltp":1.62,"tv":154.61,"id":11445382}]}]}
{"op":"mcm","clk":"11945699032","pt":1724905821074,"mc":[{"id":"1.232283784","rc":[{"batb":[[1,1.4,7],[2,1.27,1.8]],"ltp":1.62,"tv":154.61,"id":11445382}]}]}
{"op":"mcm","clk":"11945819398","pt":1724910174798,"mc":[{"id":"1.232283784","rc":[{"trd":[[1.62,129.61],[1.66,12.26],[1.7,11.56]],"batb":[[1,1.4,7]],"ltp":1.62,"tv":154.65,"id":11445382}],"tv":175.55}]}
{"op":"mcm","clk":"11945836104","pt":1724910435786,"mc":[{"id":"1.232283784","rc":[{"trd":[[2.3,6.29]],"batb":[[0,2.3,59.31]],"ltp":2.3,"tv":20.99,"id":35736915},{"trd":[[1.64,1.76],[1.77,0.12]],"batb":[[0,1.7,55.17],[1,1.44,53.9],[2,1.4,7]],"ltp":1.77,"tv":156.53,"id":11445382}],"tv":177.52}]}
{"op":"mcm","clk":"11945836108","pt":1724910435888,"mc":[{"id":"1.232283784","rc":[{"batb":[[0,2.3,29.7]],"ltp":2.3,"tv":20.99,"id":35736915}]}]}
{"op":"mcm","clk":"11945837774","pt":1724910493856,"mc":[{"id":"1.232283784","rc":[{"trd":[[2.44,1]],"ltp":2.44,"tv":21.99,"id":35736915},{"trd":[[1.7,13]],"batb":[[0,1.7,53.73],[1,1.4,7],[2,1.27,1.8]],"ltp":1.7,"tv":157.97,"id":11445382}],"tv":179.96}]}
{"op":"mcm","clk":"11945837852","pt":1724910496078,"mc":[{"id":"1.232283784","rc":[{"batb":[[0,1.7,55.17]],"ltp":1.7,"tv":157.97,"id":11445382}]}]}
{"op":"mcm","clk":"11945838750","pt":1724910522588,"mc":[{"id":"1.232283784","rc":[{"trd":[[2.3,7.06]],"batb":[[0,2.3,28.93]],"ltp":2.3,"tv":22.75,"id":35736915},{"trd":[[1.77,1.12]],"ltp":1.77,"tv":158.97,"id":11445382}],"tv":181.73}]}
{"op":"mcm","clk":"11945838845","pt":1724910526113,"mc":[{"id":"1.232283784","rc":[{"batb":[[0,2.3,29.7]],"ltp":2.3,"tv":22.75,"id":35736915}]}]}
{"op":"mcm","clk":"11945903753","pt":1724912692766,"mc":[{"id":"1.232283784","rc":[{"trd":[[2.3,66.46]],"batb":[[0,1.2,1000],[1,1.04,1.05],[2,1.03,200]],"batl":[[0,2.3,170.3]],"ltp":2.3,"tv":82.16,"id":35736915},{"trd":[[1.62,129.61]],"batb":[[1,1.4,7]],"ltp":1.77,"tv":158.98,"id":11445382}],"tv":241.14}]}
{"op":"mcm","clk":"11945903757","pt":1724912692869,"mc":[{"id":"1.232283784","rc":[{"batb":[[0,1.54,150.31],[1,1.2,1000],[2,1.04,1.05]],"ltp":2.3,"tv":82.16,"id":35736915}]}]}
{"op":"mcm","clk":"11945903802","pt":1724912694759,"mc":[{"id":"1.232283784","rc":[{"batb":[[0,2.22,31.65],[1,1.54,150.31],[2,1.2,1000]],"ltp":2.3,"tv":82.16,"id":35736915}]}]}
{"op":"mcm","clk":"11945904333","pt":1724912713759,"mc":[{"id":"1.232283784","rc":[{"trd":[[2.22,70.92]],"batb":[[0,1.53,151.29],[1,1.2,1000],[2,1.04,1.05]],"batl":[[0,2.14,50],[1,2.18,50],[2,2.22,18.35]],"ltp":2.22,"tv":145.45,"id":35736915}],"tv":304.44}]}
{"op":"mcm","clk":"11945904383","pt":1724912715804,"mc":[{"id":"1.232283784","rc":[{"batl":[[0,2,50],[1,2.14,50],[2,2.18,50]],"ltp":2.22,"tv":145.45,"id":35736915}]}]}
{"op":"mcm","clk":"11945904396","pt":1724912716161,"mc":[{"id":"1.232283784","rc":[{"batl":[[1,2.06,50],[2,2.12,50]],"ltp":2.22,"tv":145.45,"id":35736915}]}]}
{"op":"mcm","clk":"11945904444","pt":1724912717669,"mc":[{"id":"1.232283784","rc":[{"trd":[[1.95,36.62]],"batb":[[0,1.63,94.44]],"batl":[[0,1.95,81.69],[1,1.98,50],[2,2,50]],"ltp":1.95,"tv":182.07,"id":35736915}],"tv":341.06}]}
{"op":"mcm","clk":"11945904479","pt":1724912718799,"mc":[{"id":"1.232283784","rc":[{"trd":[[1.95,95.64]],"batl":[[0,1.9,50],[1,1.92,50],[2,1.95,52.18]],"ltp":1.95,"tv":241.09,"id":35736915}],"tv":400.08}]}
{"op":"mcm","clk":"11945904520","pt":1724912719776,"mc":[{"id":"1.232283784","rc":[{"batl":[[2,1.93,50]],"ltp":1.95,"tv":241.09,"id":35736915}]}]}
{"op":"mcm","clk":"11945904653","pt":1724912723509,"mc":[{"id":"1.232283784","rc":[{"trd":[[1.9,37.72]],"batb":[[0,1.66,92.81]],"batl":[[0,1.9,31.14]],"ltp":1.9,"tv":278.82,"id":35736915}],"tv":437.8}]}
{"op":"mcm","clk":"11945904691","pt":1724912724790,"mc":[{"id":"1.232283784","rc":[{"trd":[[1.9,98.04]],"batb":[[0,1.68,91.87]],"batl":[[0,1.92,50.98],[1,1.93,50],[2,1.95,52.18]],"ltp":1.9,"tv":339.14,"id":35736915}],"tv":498.12}]}
{"op":"mcm","clk":"11945904925","pt":1724912733799,"mc":[{"id":"1.232283784","rc":[{"trd":[[1.9,100],[1.92,35.92]],"batb":[[0,1.69,91.36]],"batl":[[0,1.92,32.04]],"ltp":1.92,"tv":377.02,"id":35736915}],"tv":536.0}]}
{"op":"mcm","clk":"11945904951","pt":1724912734424,"mc":[{"id":"1.232283784","rc":[{"trd":[[1.92,95.3]],"batb":[[0,1.7,90.91]],"batl":[[0,1.92,2.35]],"ltp":1.92,"tv":436.4,"id":35736915}],"tv":595.38}]}
{"op":"mcm","clk":"11945904982","pt":1724912735699,"mc":[{"id":"1.232283784","rc":[{"trd":[[1.92,97.65]],"batl":[[0,1.93,50],[1,1.95,52.18],[2,1.96,50]],"ltp":1.92,"tv":438.75,"id":35736915},{"trd":[[2.08,2.17]],"batl":[[0,2.08,72.73]],"ltp":2.08,"tv":161.15,"id":11445382}],"tv":599.9}]}
{"op":"mcm","clk":"11945904987","pt":1724912736006,"mc":[{"id":"1.232283784","rc":[{"batb":[[0,1.2,1000],[1,1.04,1.05],[2,1.03,200]],"ltp":1.92,"tv":438.75,"id":35736915}]}]}
{"op":"mcm","clk":"11945905069","pt":1724912738720,"mc":[{"id":"1.232283784","rc":[{"batb":[[0,1.65,5.63],[1,1.2,1000],[2,1.04,1.05]],"ltp":1.92,"tv":438.75,"id":35736915}]}]}
{"op":"mcm","clk":"11945905152","pt":1724912741632,"mc":[{"id":"1.232283784","rc":[{"trd":[[1.93,50]],"batb":[[0,1.68,91.91],[1,1.65,5.63],[2,1.2,1000]],"batl":[[0,1.95,52.18],[1,1.96,50],[2,1.98,100]],"ltp":1.93,"tv":488.75,"id":35736915},{"trd":[[2.06,46.84]],"batl":[[0,2.06,25.89]],"ltp":2.06,"tv":207.99,"id":11445382}],"tv":696.74}]}
{"op":"mcm","clk":"11945905220","pt":1724912744042,"mc":[{"id":"1.232283784","rc":[{"batb":[[0,1.65,5.63],[1,1.2,1000],[2,1.04,1.05]],"ltp":1.93,"tv":488.75,"id":35736915}]}]}
{"op":"mcm","clk":"11945905436","pt":1724912753349,"mc":[{"id":"1.232283784","rc":[{"trd":[[1.95,147.82],[1.96,26.84]],"batl":[[0,1.96,23.16],[1,1.98,100],[2,2,100]],"ltp":1.96,"tv":567.77,"id":35736915},{"trd":[[2.04,75.66]],"ltp":2.04,"tv":283.65,"id":11445382}],"tv":851.42}]}
{"op":"mcm","clk":"11945905522","pt":1724912757346,"mc":[{"id":"1.232283784","rc":[{"batb":[[0,1.66,139.56],[1,1.65,5.63],[2,1.2,1000]],"ltp":1.96,"tv":567.77,"id":35736915}]}]}
{"op":"mcm","clk":"11945907079","pt":1724912819010,"mc":[{"id":"1.232283784","rc":[{"trd":[[1.96,49.68]],"batl":[[0,1.98,100.32],[1,2,100],[2,2.04,50]],"ltp":1.96,"tv":590.61,"id":35736915},{"trd":[[2.04,97.6]],"ltp":2.04,"tv":305.59,"id":11445382}],"tv":896.2}]}
{"op":"mcm","clk":"11945907567","pt":1724912835859,"mc":[{"id":"1.232283784","rc":[{"trd":[[1.96,50],[1.98,99.26]],"batl":[[0,2,100.74],[1,2.04,50],[2,2.06,50]],"ltp":1.98,"tv":690.19,"id":35736915},{"trd":[[2.02,97.29],[2.04,97.91]],"ltp":2.02,"tv":403.19,"id":11445382}],"tv":1093.38}]}
{"op":"mcm","clk":"11945908458","pt":1724912865703,"mc":[{"id":"1.232283784","rc":[{"batb":[[0,1.67,6.65],[1,1.66,139.56],[2,1.65,5.63]],"ltp":1.98,"tv":690.19,"id":35736915}]}]}
{"op":"mcm","clk":"11945908463","pt":1724912865908,"mc":[{"id":"1.232283784","rc":[{"batb":[[0,2.02,6.8],[1,1.7,55.17],[2,1.4,7]],"ltp":2.02,"tv":403.19,"id":11445382}]}]}
{"op":"mcm","clk":"11945909242","pt":1724912893734,"mc":[{"id":"1.232283784","rc":[{"batb":[[1,1.65,5.63],[2,1.2,1000]],"ltp":1.98,"tv":690.19,"id":35736915},{"batl":[[0,2.04,23.64]],"ltp":2.02,"tv":403.19,"id":11445382}]}]}
{"op":"mcm","clk":"11945909465","pt":1724912900743,"mc":[{"id":"1.232283784","rc":[{"batb":[[0,1.68,137.89],[1,1.67,6.65],[2,1.65,5.63]],"ltp":1.98,"tv":690.19,"id":35736915}]}]}
{"op":"mcm","clk":"11945909678","pt":1724912909432,"mc":[{"id":"1.232283784","rc":[{"trd":[[1.98,100],[2,16.12]],"batl":[[0,2,83.88]],"ltp":2.0,"tv":707.05,"id":35736915},{"trd":[[2,16.12],[2.02,111.62]],"batb":[[0,1.7,55.17],[1,1.4,7],[2,1.27,1.8]],"ltp":2.0,"tv":433.64,"id":11445382}],"tv":1140.69}]}
{"op":"mcm","clk":"11945911008","pt":1724912952689,"mc":[{"id":"1.232283784","rc":[{"trd":[[2,54.08]],"batl":[[0,2,45.92]],"ltp":2.0,"tv":745.01,"id":35736915},{"trd":[[2,54.07]],"ltp":2.0,"tv":471.6,"id":11445382}],"tv":1216.61}]}
{"op":"mcm","clk":"11945911154","pt":1724912957694,"mc":[{"id":"1.232283784","rc":[{"trd":[[2,73.38]],"batl":[[0,2,36.27]],"ltp":2.0,"tv":764.31,"id":35736915}],"tv":1235.91}]}
{"op":"mcm","clk":"11945911911","pt":1724912982626,"mc":[{"id":"1.232283784","rc":[{"trd":[[2,92.44]],"batl":[[0,2,26.74]],"ltp":2.0,"tv":783.36,"id":35736915}],"tv":1254.96}]}
{"op":"mcm","clk":"11945912105","pt":1724912987855,"mc":[{"id":"1.232283784","rc":[{"batb":[[2,1.2,1000]],"ltp":2.0,"tv":783.36,"id":35736915}]}]}
{"op":"mcm","clk":"11945912109","pt":1724912987955,"mc":[{"id":"1.232283784","rc":[{"batb":[[0,1.7,5.28],[1,1.68,137.89],[2,1.67,6.65]],"ltp":2.0,"tv":783.36,"id":35736915}]}]}
{"op":"mcm","clk":"11945913431","pt":1724913024718,"mc":[{"id":"1.232283784","rc":[{"trd":[[2,98.48]],"batl":[[0,2,23.72]],"ltp":2.0,"tv":789.4,"id":35736915}],"tv":1261.01}]}
{"op":"mcm","clk":"11945913442","pt":1724913024975,"mc":[{"id":"1.232283784","rc":[{"batb":[[0,1.73,112.66],[1,1.7,5.28]],"ltp":2.0,"tv":789.4,"id":35736915}]}]}
{"op":"mcm","clk":"11945914477","pt":1724913053713,"mc":[{"id":"1.232283784","rc":[{"trd":[[2,111.44]],"batl":[[0,2,17.24]],"ltp":2.0,"tv":802.36,"id":35736915}],"tv":1273.97}]}
{"op":"mcm","clk":"11945915140","pt":1724913071538,"mc":[{"id":"1.232283784","rc":[{"trd":[[2,136.06]],"batl":[[0,2,4.93]],"ltp":2.0,"tv":826.98,"id":35736915}],"tv":1298.59}]}
{"op":"mcm","clk":"11945915428","pt":1724913080182,"mc":[{"id":"1.232283784","rc":[{"trd":[[2,145.92],[2.04,2.86]],"batl":[[0,2.04,48.57],[1,2.06,50],[2,2.08,50]],"ltp":2.04,"tv":839.7,"id":35736915}],"tv":1311.31}]}
{"op":"mcm","clk":"11945916359","pt":1724913105895,"mc":[{"id":"1.232283784","rc":[{"trd":[[2.04,15.58]],"batl":[[0,2.04,42.21]],"ltp":2.04,"tv":852.42,"id":35736915}],"tv":1324.03}]}
{"op":"mcm","clk":"11945922821","pt":1724913261726,"mc":[{"id":"1.232283784","rc":[{"trd":[[2.04,84.18]],"batl":[[0,2.04,7.91]],"ltp":2.04,"tv":921.03,"id":35736915}],"tv":1392.63}]}
{"op":"mcm","clk":"11945923125","pt":1724913269140,"mc":[{"id":"1.232283784","rc":[{"batb":[[0,1.74,16.76],[1,1.73,112.66],[2,1.7,5.28]],"ltp":2.04,"tv":921.03,"id":35736915}]}]}
{"op":"mcm","clk":"11945923211","pt":1724913271034,"mc":[{"id":"1.232283784","rc":[{"trd":[[2.04,96.9]],"batl":[[0,2.04,1.55]],"ltp":2.04,"tv":933.75,"id":35736915}],"tv":1405.35}]}
{"op":"mcm","clk":"11945923968","pt":1724913289770,"mc":[{"id":"1.232283784","rc":[{"batb":[[0,1.75,132.34],[1,1.74,16.76]],"ltp":2.04,"tv":933.75,"id":35736915}]}]}
{"op":"mcm","clk":"11945925062","pt":1724913320004,"mc":[{"id":"1.232283784","rc":[{"trd":[[2.04,100],[2.06,1.5]],"batl":[[0,2.06,49.25],[1,2.08,50],[2,2.1,50]],"ltp":2.06,"tv":938.35,"id":35736915}],"tv":1409.95}]}
{"op":"mcm","clk":"11945925307","pt":1724913326509,"mc":[{"id":"1.232283784","rc":[{"trd":[[2.06,31.92]],"batl":[[0,2.06,34.04]],"ltp":2.06,"tv":968.77,"id":35736915}],"tv":1440.37}]}
{"op":"mcm","clk":"11945926386","pt":1724913359838,"mc":[{"id":"1.232283784","rc":[{"trd":[[2.06,59.38]],"batl":[[0,2.06,20.31]],"ltp":2.06,"tv":996.23,"id":35736915}],"tv":1467.83}]}
{"op":"mcm","clk":"11945926399","pt":1724913360147,"mc":[{"id":"1.232283784","rc":[{"batb":[[0,1.77,110.66]],"ltp":2.06,"tv":996.23,"id":35736915}]}]}
{"op":"mcm","clk":"11945927267","pt":1724913385432,"mc":[{"id":"1.232283784","rc":[{"trd":[[2.06,70.46]],"batl":[[0,2.06,14.77]],"ltp":2.06,"tv":1007.31,"id":35736915}],"tv":1478.91}]}
{"op":"mcm","clk":"11945927422","pt":1724913390857,"mc":[{"id":"1.232283784","rc":[{"trd":[[2.06,100]],"batb":[[0,2.06,6.29],[1,1.77,110.66],[2,1.74,16.76]],"batl":[[0,2.08,50],[1,2.1,50],[2,2.12,50]],"ltp":2.06,"tv":1036.85,"id":35736915}],"tv":1508.45}]}
{"op":"mcm","clk":"11945927431","pt":1724913391166,"mc":[{"id":"1.232283784","rc":[{"batb":[[1,1.74,16.76],[2,1.7,5.28]],"ltp":2.06,"tv":1036.85,"id":35736915}]}]}
{"op":"mcm","clk":"11945928295","pt":1724913417582,"mc":[{"id":"1.232283784","rc":[{"trd":[[2.08,42.12]],"batl":[[0,2.08,28.94]],"ltp":2.08,"tv":1078.97,"id":35736915}],"tv":1550.57}]}
{"op":"mcm","clk":"11945929696","pt":1724913458344,"mc":[{"id":"1.232283784","rc":[{"trd":[[2.08,80.71]],"batl":[[0,2.08,9.65]],"ltp":2.08,"tv":1117.56,"id":35736915}],"tv":1589.16}]}
{"op":"mcm","clk":"11945930963","pt":1724913508115,"mc":[{"id":"1.232283784","rc":[{"trd":[[2.08,93.29]],"batb":[[0,1.75,111.92]],"batl":[[0,2.08,3.36]],"ltp":2.08,"tv":1130.14,"id":35736915}],"tv":1601.74}]}
{"op":"mcm","clk":"11945932501","pt":1724913569889,"mc":[{"id":"1.232283784","rc":[{"trd":[[2.08,100.01],[2.1,58.24]],"batl":[[0,2.1,20.88],[1,2.12,50],[2,2.14,50]],"ltp":2.1,"tv":1195.1,"id":35736915}],"tv":1666.7}]}
{"op":"mcm","clk":"11945933740","pt":1724913621642,"mc":[{"id":"1.232283784","rc":[{"batb":[[0,1.98,36.97],[1,1.75,111.92],[2,1.74,16.76]],"ltp":2.1,"tv":1195.1,"id":35736915}]}]}
{"op":"mcm","clk":"11945935767","pt":1724913699701,"mc":[{"id":"1.232283784","rc":[{"trd":[[2.1,100],[2.12,27.8]],"batl":[[0,2.12,36.1],[1,2.14,50],[2,2.18,50]],"ltp":2.12,"tv":1264.66,"id":35736915}],"tv":1736.26}]}
{"op":"mcm","clk":"11945935770","pt":1724913699905,"mc":[{"id":"1.232283784","rc":[{"batb":[[1,1.74,16.76],[2,1.7,5.28]],"ltp":2.12,"tv":1264.66,"id":35736915}]}]}
{"op":"mcm","clk":"11945936476","pt":1724913724048,"mc":[{"id":"1.232283784","rc":[{"trd":[[2.12,63.9],[2.14,57.08],[2.18,50]],"batl":[[0,2.22,18.35],[1,2.26,50],[2,2.28,50]],"ltp":2.18,"tv":1400.76,"id":35736915},{"trd":[[1.84,59.24],[1.87,57.22],[1.89,40.49]],"batl":[[0,1.84,23.29]],"ltp":1.84,"tv":628.55,"id":11445382}],"tv":2029.31}]}
{"op":"mcm","clk":"11945937297","pt":1724913752273,"mc":[{"id":"1.232283784","rc":[{"batl":[[1,1.9,67.46]],"ltp":1.84,"tv":628.55,"id":11445382}]}]}
{"op":"mcm","clk":"11945937686","pt":1724913766385,"mc":[{"id":"1.232283784","rc":[{"trd":[[2.22,89.27]],"batl":[[0,2.26,50],[1,2.28,50],[2,2.3,220.3]],"ltp":2.22,"tv":1419.11,"id":35736915},{"trd":[[1.81,23.74]],"batl":[[0,1.9,68.24],[1,1.9,0]],"ltp":1.81,"tv":651.05,"id":11445382}],"tv":2070.17}]}
{"op":"mcm","clk":"11945937818","pt":1724913770802,"mc":[{"id":"1.232283784","rc":[{"batb":[[0,1.74,16.76],[1,1.7,5.28],[2,1.67,6.65]],"ltp":2.22,"tv":1419.11,"id":35736915}]}]}
{"op":"mcm","clk":"11945938249","pt":1724913784916,"mc":[{"id":"1.232283784","rc":[{"batb":[[0,2.22,205.38],[1,1.74,16.76],[2,1.7,5.28]],"ltp":2.22,"tv":1419.11,"id":35736915}]}]}
{"op":"mcm","clk":"11945938348","pt":1724913789011,"mc":[{"id":"1.232283784","rc":[{"batb":[[0,1.74,16.76],[1,1.7,5.28],[2,1.67,6.65]],"ltp":2.22,"tv":1419.11,"id":35736915}]}]}
{"op":"mcm","clk":"11945938671","pt":1724913800307,"mc":[{"id":"1.232283784","rc":[{"batb":[[0,2.1,205.38],[1,1.74,16.76],[2,1.7,5.28]],"ltp":2.22,"tv":1419.11,"id":35736915}]}]}
{"op":"mcm","clk":"11945939323","pt":1724913829062,"mc":[{"id":"1.232283784","rc":[{"trd":[[2.26,21.42]],"batl":[[0,2.26,39.29]],"ltp":2.26,"tv":1440.53,"id":35736915}],"tv":2091.59}]}
{"op":"mcm","clk":"11945939329","pt":1724913829876,"mc":[{"id":"1.232283784","rc":[{"trd":[[2.26,60.71],[2.28,50],[2.3,286.76]],"batl":[[0,2.34,50],[1,2.38,50],[2,2.42,50]],"ltp":2.3,"tv":1750.12,"id":35736915},{"trd":[[1.76,287.89],[1.78,64.05],[1.79,49.61]],"batl":[[0,1.76,17.12],[1,1.9,68.24]],"ltp":1.76,"tv":1052.6,"id":11445382}],"tv":2802.73}]}
{"op":"mcm","clk":"11945939558","pt":1724913843713,"mc":[{"id":"1.232283784","rc":[{"batl":[[0,1.9,85.35],[1,1.9,0]],"ltp":1.76,"tv":1052.6,"id":11445382}]}]}
{"op":"mcm","clk":"11945939734","pt":1724913850805,"mc":[{"id":"1.232283784","rc":[{"trd":[[1.81,25.3],[1.9,169.16]],"batb":[[0,1.9,114.64]],"ltp":1.9,"tv":1223.31,"id":11445382}],"tv":2973.44}]}
{"op":"mcm","clk":"11945939821","pt":1724913853796,"mc":[{"id":"1.232283784","rc":[{"trd":[[2.1,305.38]],"batb":[[0,1.75,111.92]],"ltp":2.1,"tv":1955.5,"id":35736915},{"trd":[[1.91,225.81]],"batb":[[0,1.91,174.19],[1,1.9,114.64],[2,1.4,7]],"ltp":1.91,"tv":1449.12,"id":11445382}],"tv":3404.63}]}
{"op":"mcm","clk":"11945939878","pt":1724913855797,"mc":[{"id":"1.232283784","rc":[{"batb":[[2,1.7,55.17]],"ltp":1.91,"tv":1449.12,"id":11445382}]}]}
{"op":"mcm","clk":"11945940454","pt":1724913888125,"mc":[{"id":"1.232283784","rc":[{"trd":[[1.9,398.44],[1.91,574.19]],"batb":[[0,1.7,55.17],[1,1.4,7],[2,1.27,1.8]],"batl":[[0,1.9,92.24]],"ltp":1.9,"tv":2026.78,"id":11445382}],"tv":3982.29}]}
{"op":"mcm","clk":"11945940647","pt":1724913896829,"mc":[{"id":"1.232283784","rc":[{"batl":[[0,2,92.24]],"ltp":1.9,"tv":2026.78,"id":11445382}]}]}
{"op":"mcm","clk":"11945940812","pt":1724913906459,"mc":[{"id":"1.232283784","rc":[{"trd":[[2.34,20.68]],"batl":[[0,2.34,39.66]],"ltp":2.34,"tv":1976.18,"id":35736915}],"tv":4002.97}]}
{"op":"mcm","clk":"11945941429","pt":1724913935204,"mc":[{"id":"1.232283784","rc":[{"batb":[[0,1.74,16.76],[1,1.7,5.28],[2,1.67,6.65]],"ltp":2.34,"tv":1976.18,"id":35736915}]}]}
{"op":"mcm","clk":"11945943052","pt":1724913990889,"mc":[{"id":"1.232283784","rc":[{"batb":[[0,2.1,230.77],[1,1.74,16.76],[2,1.7,5.28]],"ltp":2.34,"tv":1976.18,"id":35736915}]}]}
{"op":"mcm","clk":"11945946333","pt":1724914089879,"mc":[{"id":"1.232283784","rc":[{"trd":[[2,152.25],[2.1,766.92]],"batb":[[0,1.74,16.76],[1,1.7,5.28],[2,1.67,6.65]],"ltp":2.0,"tv":2444.05,"id":35736915},{"trd":[[2,60.4]],"batl":[[0,2,85.92]],"ltp":2.0,"tv":2033.11,"id":11445382}],"tv":4477.16}]}
{"op":"mcm","clk":"11945955052","pt":1724914347039,"mc":[{"id":"1.232283784","rc":[{"batb":[[0,2.02,4.22],[1,1.74,16.76],[2,1.7,5.28]],"ltp":2.0,"tv":2444.05,"id":35736915}]}]}
{"op":"mcm","clk":"11945955484","pt":1724914357829,"mc":[{"id":"1.232283784","rc":[{"batb":[[0,1.74,16.76],[1,1.7,5.28],[2,1.67,6.65]],"ltp":2.0,"tv":2444.05,"id":35736915}]}]}
{"op":"mcm","clk":"11945955488","pt":1724914357930,"mc":[{"id":"1.232283784","rc":[{"batb":[[0,1.75,111.37],[1,1.74,16.76],[2,1.7,5.28]],"ltp":2.0,"tv":2444.05,"id":35736915}]}]}
{"op":"mcm","clk":"11945964433","pt":1724914603937,"mc":[{"id":"1.232283784","rc":[{"batb":[[0,1.76,5.47],[1,1.75,111.37],[2,1.74,16.76]],"ltp":2.0,"tv":2444.05,"id":35736915}]}]}
{"op":"mcm","clk":"11945964658","pt":1724914611422,"mc":[{"id":"1.232283784","rc":[{"batb":[[0,1.91,8.38],[1,1.76,5.47],[2,1.75,111.37]],"ltp":2.0,"tv":2444.05,"id":35736915}]}]}
{"op":"mcm","clk":"11945970056","pt":1724914801138,"mc":[{"id":"1.232283784","rc":[{"batb":[[0,1.93,38.98],[1,1.92,5],[2,1.91,8.38]],"ltp":2.0,"tv":2444.05,"id":35736915}]}]}
{"op":"mcm","clk":"11945970219","pt":1724914804234,"mc":[{"id":"1.232283784","rc":[{"trd":[[2,152.24],[2.04,99.99],[2.06,99.98],[2.08,99.97],[2.1,766.87]],"batb":[[1,1.91,8.38],[2,1.74,16.76]],"ltp":2.0,"tv":2443.91,"id":35736915},{"trd":[[1.62,129.63],[1.66,12.26],[1.7,13],[1.76,287.98],[1.78,64.07],[1.79,49.62],[1.81,25.3],[1.84,59.26],[1.87,57.23],[1.89,40.5],[1.9,398.5],[1.91,574.24],[2,60.39],[2.02,111.6],[2.04,97.89],[2.06,46.83]],"batb":[[1,1.4,7]],"ltp":2.0,"tv":2033.36,"id":11445382}],"tv":4477.27}]}
{"op":"mcm","clk":"11945970673","pt":1724914812681,"mc":[{"id":"1.232283784","rc":[{"batb":[[0,1.94,5],[1,1.93,38.98],[2,1.91,8.38]],"ltp":2.0,"tv":2443.91,"id":35736915}]}]}
{"op":"mcm","clk":"11945970807","pt":1724914816167,"mc":[{"id":"1.232283784","rc":[{"batb":[[0,1.93,38.98],[1,1.91,8.38],[2,1.74,16.76]],"ltp":2.0,"tv":2443.91,"id":35736915}]}]}
{"op":"mcm","clk":"11945970935","pt":1724914818783,"mc":[{"id":"1.232283784","rc":[{"batb":[[0,1.94,5],[1,1.93,38.98],[2,1.91,8.38]],"ltp":2.0,"tv":2443.91,"id":35736915}]}]}
{"op":"mcm","clk":"11945971041","pt":1724914822091,"mc":[{"id":"1.232283784","rc":[{"batb":[[0,1.93,38.98],[1,1.91,8.38],[2,1.74,16.76]],"ltp":2.0,"tv":2443.91,"id":35736915}]}]}
{"op":"mcm","clk":"11945971206","pt":1724914826190,"mc":[{"id":"1.232283784","rc":[{"batb":[[0,1.94,5],[1,1.93,38.98],[2,1.91,8.38]],"ltp":2.0,"tv":2443.91,"id":35736915}]}]}
{"op":"mcm","clk":"11945971312","pt":1724914829589,"mc":[{"id":"1.232283784","rc":[{"batb":[[0,1.93,38.98],[1,1.91,8.38],[2,1.74,16.76]],"ltp":2.0,"tv":2443.91,"id":35736915}]}]}
{"op":"mcm","clk":"11945971440","pt":1724914834107,"mc":[{"id":"1.232283784","rc":[{"batb":[[0,1.94,5],[1,1.93,38.98],[2,1.91,8.38]],"ltp":2.0,"tv":2443.91,"id":35736915}]}]}
{"op":"mcm","clk":"11945971550","pt":1724914837396,"mc":[{"id":"1.232283784","rc":[{"batb":[[0,1.93,38.98],[1,1.91,8.38],[2,1.74,16.76]],"ltp":2.0,"tv":2443.91,"id":35736915}]}]}
{"op":"mcm","clk":"11945971702","pt":1724914841088,"mc":[{"id":"1.232283784","rc":[{"batb":[[0,1.94,5],[1,1.93,38.98],[2,1.91,8.38]],"ltp":2.0,"tv":2443.91,"id":35736915}]}]}
{"op":"mcm","clk":"11945971781","pt":1724914844618,"mc":[{"id":"1.232283784","rc":[{"batb":[[0,1.93,38.98],[1,1.91,8.38],[2,1.74,16.76]],"ltp":2.0,"tv":2443.91,"id":35736915}]}]}
{"op":"mcm","clk":"11945971835","pt":1724914846917,"mc":[{"id":"1.232283784","rc":[{"batb":[[0,1.94,5],[1,1.93,38.98],[2,1.91,8.38]],"ltp":2.0,"tv":2443.91,"id":35736915}]}]}
{"op":"mcm","clk":"11945971945","pt":1724914850306,"mc":[{"id":"1.232283784","rc":[{"batb":[[0,1.93,38.98],[1,1.91,8.38],[2,1.74,16.76]],"ltp":2.0,"tv":2443.91,"id":35736915}]}]}
{"op":"mcm","clk":"11945972112","pt":1724914854918,"mc":[{"id":"1.232283784","rc":[{"batb":[[0,1.94,5],[1,1.93,38.98],[2,1.91,8.38]],"ltp":2.0,"tv":2443.91,"id":35736915}]}]}
{"op":"mcm","clk":"11945972225","pt":1724914858202,"mc":[{"id":"1.232283784","rc":[{"batb":[[0,1.93,38.98],[1,1.91,8.38],[2,1.74,16.76]],"ltp":2.0,"tv":2443.91,"id":35736915}]}]}
{"op":"mcm","clk":"11945972303","pt":1724914861108,"mc":[{"id":"1.232283784","rc":[{"batb":[[0,1.94,5],[1,1.93,38.98],[2,1.91,8.38]],"ltp":2.0,"tv":2443.91,"id":35736915}]}]}
{"op":"mcm","clk":"11945972380","pt":1724914864330,"mc":[{"id":"1.232283784","rc":[{"batb":[[0,1.93,38.98],[1,1.91,8.38],[2,1.74,16.76]],"ltp":2.0,"tv":2443.91,"id":35736915}]}]}
{"op":"mcm","clk":"11945972454","pt":1724914866636,"mc":[{"id":"1.232283784","rc":[{"batb":[[0,1.94,5],[1,1.93,38.98],[2,1.91,8.38]],"ltp":2.0,"tv":2443.91,"id":35736915}]}]}
{"op":"mcm","clk":"11945972567","pt":1724914869911,"mc":[{"id":"1.232283784","rc":[{"batb":[[0,1.93,38.98],[1,1.91,8.38],[2,1.74,16.76]],"ltp":2.0,"tv":2443.91,"id":35736915}]}]}
{"op":"mcm","clk":"11945972697","pt":1724914872536,"mc":[{"id":"1.232283784","rc":[{"batb":[[0,1.94,5],[1,1.93,38.98],[2,1.91,8.38]],"ltp":2.0,"tv":2443.91,"id":35736915}]}]}
{"op":"mcm","clk":"11945972837","pt":1724914876022,"mc":[{"id":"1.232283784","rc":[{"batb":[[0,1.93,38.98],[1,1.91,8.38],[2,1.74,16.76]],"ltp":2.0,"tv":2443.91,"id":35736915}]}]}
{"op":"mcm","clk":"11945972975","pt":1724914879917,"mc":[{"id":"1.232283784","rc":[{"batb":[[0,1.94,5],[1,1.93,38.98],[2,1.91,8.38]],"ltp":2.0,"tv":2443.91,"id":35736915}]}]}
{"op":"mcm","clk":"11945973072","pt":1724914883334,"mc":[{"id":"1.232283784","rc":[{"batb":[[0,1.93,38.98],[1,1.91,8.38],[2,1.74,16.76]],"ltp":2.0,"tv":2443.91,"id":35736915}]}]}
{"op":"mcm","clk":"11945973139","pt":1724914885832,"mc":[{"id":"1.232283784","rc":[{"batb":[[0,1.94,5],[1,1.93,38.98],[2,1.91,8.38]],"ltp":2.0,"tv":2443.91,"id":35736915}]}]}
{"op":"mcm","clk":"11945973241","pt":1724914889153,"mc":[{"id":"1.232283784","rc":[{"batb":[[0,1.93,38.98],[1,1.91,8.38],[2,1.74,16.76]],"ltp":2.0,"tv":2443.91,"id":35736915}]}]}
{"op":"mcm","clk":"11945973380","pt":1724914894759,"mc":[{"id":"1.232283784","rc":[{"batb":[[0,1.94,5],[1,1.93,38.98],[2,1.91,8.38]],"ltp":2.0,"tv":2443.91,"id":35736915}]}]}
{"op":"mcm","clk":"11945973491","pt":1724914898128,"mc":[{"id":"1.232283784","rc":[{"batb":[[0,1.93,38.98],[1,1.91,8.38],[2,1.74,16.76]],"ltp":2.0,"tv":2443.91,"id":35736915}]}]}
{"op":"mcm","clk":"11945973775","pt":1724914905961,"mc":[{"id":"1.232283784","rc":[{"batb":[[0,1.94,5],[1,1.93,38.98],[2,1.91,8.38]],"ltp":2.0,"tv":2443.91,"id":35736915}]}]}
{"op":"mcm","clk":"11945973877","pt":1724914909379,"mc":[{"id":"1.232283784","rc":[{"batb":[[0,1.93,38.98],[1,1.91,8.38],[2,1.74,16.76]],"ltp":2.0,"tv":2443.91,"id":35736915}]}]}
{"op":"mcm","clk":"11945973972","pt":1724914911887,"mc":[{"id":"1.232283784","rc":[{"batb":[[0,1.94,5],[1,1.93,38.98],[2,1.91,8.38]],"ltp":2.0,"tv":2443.91,"id":35736915}]}]}
{"op":"mcm","clk":"11945974087","pt":1724914915268,"mc":[{"id":"1.232283784","rc":[{"batb":[[0,1.93,38.98],[1,1.91,8.38],[2,1.74,16.76]],"ltp":2.0,"tv":2443.91,"id":35736915}]}]}
{"op":"mcm","clk":"11945974166","pt":1724914917566,"mc":[{"id":"1.232283784","rc":[{"batb":[[0,1.94,5],[1,1.93,38.98],[2,1.91,8.38]],"ltp":2.0,"tv":2443.91,"id":35736915}]}]}
{"op":"mcm","clk":"11945974270","pt":1724914920990,"mc":[{"id":"1.232283784","rc":[{"batb":[[0,1.93,38.98],[1,1.91,8.38],[2,1.74,16.76]],"ltp":2.0,"tv":2443.91,"id":35736915}]}]}
{"op":"mcm","clk":"11945974471","pt":1724914926792,"mc":[{"id":"1.232283784","rc":[{"batb":[[0,1.94,5],[1,1.93,38.98],[2,1.91,8.38]],"ltp":2.0,"tv":2443.91,"id":35736915}]}]}
{"op":"mcm","clk":"11945974564","pt":1724914930270,"mc":[{"id":"1.232283784","rc":[{"batb":[[0,1.93,38.98],[1,1.91,8.38],[2,1.74,16.76]],"ltp":2.0,"tv":2443.91,"id":35736915}]}]}
{"op":"mcm","clk":"11945974647","pt":1724914932670,"mc":[{"id":"1.232283784","rc":[{"batb":[[0,1.94,5],[1,1.93,38.98],[2,1.91,8.38]],"ltp":2.0,"tv":2443.91,"id":35736915}]}]}
{"op":"mcm","clk":"11945974782","pt":1724914936084,"mc":[{"id":"1.232283784","rc":[{"batb":[[0,1.93,38.98],[1,1.91,8.38],[2,1.74,16.76]],"ltp":2.0,"tv":2443.91,"id":35736915}]}]}
{"op":"mcm","clk":"11945974925","pt":1724914939970,"mc":[{"id":"1.232283784","rc":[{"batb":[[0,1.94,5],[1,1.93,38.98],[2,1.91,8.38]],"ltp":2.0,"tv":2443.91,"id":35736915}]}]}
{"op":"mcm","clk":"11945975024","pt":1724914943385,"mc":[{"id":"1.232283784","rc":[{"batb":[[0,1.93,38.98],[1,1.91,8.38],[2,1.74,16.76]],"ltp":2.0,"tv":2443.91,"id":35736915}]}]}
{"op":"mcm","clk":"11945975086","pt":1724914945988,"mc":[{"id":"1.232283784","rc":[{"batb":[[0,1.94,5],[1,1.93,38.98],[2,1.91,8.38]],"ltp":2.0,"tv":2443.91,"id":35736915}]}]}
{"op":"mcm","clk":"11945975173","pt":1724914949508,"mc":[{"id":"1.232283784","rc":[{"batb":[[0,1.93,38.98],[1,1.91,8.38],[2,1.74,16.76]],"ltp":2.0,"tv":2443.91,"id":35736915}]}]}
{"op":"mcm","clk":"11945975307","pt":1724914952721,"mc":[{"id":"1.232283784","rc":[{"batb":[[0,1.94,5],[1,1.93,38.98],[2,1.91,8.38]],"ltp":2.0,"tv":2443.91,"id":35736915}]}]}
{"op":"mcm","clk":"11945975437","pt":1724914956088,"mc":[{"id":"1.232283784","rc":[{"batb":[[0,1.93,38.98],[1,1.91,8.38],[2,1.74,16.76]],"ltp":2.0,"tv":2443.91,"id":35736915}]}]}
{"op":"mcm","clk":"11945975528","pt":1724914958592,"mc":[{"id":"1.232283784","rc":[{"batb":[[0,1.94,5],[1,1.93,38.98],[2,1.91,8.38]],"ltp":2.0,"tv":2443.91,"id":35736915}]}]}
{"op":"mcm","clk":"11945975641","pt":1724914962104,"mc":[{"id":"1.232283784","rc":[{"batb":[[0,1.93,38.98],[1,1.91,8.38],[2,1.74,16.76]],"ltp":2.0,"tv":2443.91,"id":35736915}]}]}
{"op":"mcm","clk":"11945975716","pt":1724914964810,"mc":[{"id":"1.232283784","rc":[{"batb":[[0,1.94,5],[1,1.93,38.98],[2,1.91,8.38]],"ltp":2.0,"tv":2443.91,"id":35736915}]}]}
{"op":"mcm","clk":"11945975823","pt":1724914968103,"mc":[{"id":"1.232283784","rc":[{"batb":[[0,1.93,38.98],[1,1.91,8.38],[2,1.74,16.76]],"ltp":2.0,"tv":2443.91,"id":35736915}]}]}
{"op":"mcm","clk":"11945975942","pt":1724914970924,"mc":[{"id":"1.232283784","rc":[{"batb":[[0,1.94,5],[1,1.93,38.98],[2,1.91,8.38]],"ltp":2.0,"tv":2443.91,"id":35736915}]}]}
{"op":"mcm","clk":"11945976104","pt":1724914974241,"mc":[{"id":"1.232283784","rc":[{"batb":[[0,1.93,38.98],[1,1.91,8.38],[2,1.74,16.76]],"ltp":2.0,"tv":2443.91,"id":35736915}]}]}
{"op":"mcm","clk":"11945976184","pt":1724914976743,"mc":[{"id":"1.232283784","rc":[{"batb":[[0,1.94,5],[1,1.93,38.98],[2,1.91,8.38]],"ltp":2.0,"tv":2443.91,"id":35736915}]}]}
{"op":"mcm","clk":"11945976300","pt":1724914980130,"mc":[{"id":"1.232283784","rc":[{"batb":[[0,1.93,38.98],[1,1.91,8.38],[2,1.74,16.76]],"ltp":2.0,"tv":2443.91,"id":35736915}]}]}
{"op":"mcm","clk":"11945976410","pt":1724914982536,"mc":[{"id":"1.232283784","rc":[{"batb":[[0,1.94,5],[1,1.93,38.98],[2,1.91,8.38]],"ltp":2.0,"tv":2443.91,"id":35736915}]}]}
{"op":"mcm","clk":"11945976543","pt":1724914986015,"mc":[{"id":"1.232283784","rc":[{"batb":[[0,1.93,38.98],[1,1.91,8.38],[2,1.74,16.76]],"ltp":2.0,"tv":2443.91,"id":35736915}]}]}
{"op":"mcm","clk":"11945976694","pt":1724914990464,"mc":[{"id":"1.232283784","rc":[{"batb":[[0,1.94,5],[1,1.93,38.98],[2,1.91,8.38]],"ltp":2.0,"tv":2443.91,"id":35736915}]}]}
{"op":"mcm","clk":"11945976799","pt":1724914993823,"mc":[{"id":"1.232283784","rc":[{"batb":[[0,1.93,38.98],[1,1.91,8.38],[2,1.74,16.76]],"ltp":2.0,"tv":2443.91,"id":35736915}]}]}
{"op":"mcm","clk":"11945977032","pt":1724915000929,"mc":[{"id":"1.232283784","rc":[{"batb":[[0,1.94,5],[1,1.93,38.98],[2,1.91,8.38]],"ltp":2.0,"tv":2443.91,"id":35736915}]}]}
{"op":"mcm","clk":"11945977157","pt":1724915004350,"mc":[{"id":"1.232283784","rc":[{"batb":[[0,1.93,38.98],[1,1.91,8.38],[2,1.74,16.76]],"ltp":2.0,"tv":2443.91,"id":35736915}]}]}
{"op":"mcm","clk":"11945977237","pt":1724915006857,"mc":[{"id":"1.232283784","rc":[{"batb":[[0,1.94,5],[1,1.93,38.98],[2,1.91,8.38]],"ltp":2.0,"tv":2443.91,"id":35736915}]}]}
{"op":"mcm","clk":"11945977354","pt":1724915010384,"mc":[{"id":"1.232283784","rc":[{"batb":[[0,1.93,38.98],[1,1.91,8.38],[2,1.74,16.76]],"ltp":2.0,"tv":2443.91,"id":35736915}]}]}
{"op":"mcm","clk":"11945977496","pt":1724915014778,"mc":[{"id":"1.232283784","rc":[{"batb":[[0,1.94,5],[1,1.93,38.98],[2,1.91,8.38]],"ltp":2.0,"tv":2443.91,"id":35736915}]}]}
{"op":"mcm","clk":"11945977590","pt":1724915017945,"mc":[{"id":"1.232283784","rc":[{"batb":[[0,1.93,38.98],[1,1.91,8.38],[2,1.74,16.76]],"ltp":2.0,"tv":2443.91,"id":35736915}]}]}
{"op":"mcm","clk":"11945977743","pt":1724915022170,"mc":[{"id":"1.232283784","rc":[{"batb":[[0,1.94,5],[1,1.93,38.98],[2,1.91,8.38]],"ltp":2.0,"tv":2443.91,"id":35736915}]}]}
{"op":"mcm","clk":"11945977845","pt":1724915025590,"mc":[{"id":"1.232283784","rc":[{"batb":[[0,1.93,38.98],[1,1.91,8.38],[2,1.74,16.76]],"ltp":2.0,"tv":2443.91,"id":35736915}]}]}
{"op":"mcm","clk":"11945978069","pt":1724915031963,"mc":[{"id":"1.232283784","rc":[{"batb":[[0,1.94,5],[1,1.93,38.98],[2,1.91,8.38]],"ltp":2.0,"tv":2443.91,"id":35736915}]}]}
{"op":"mcm","clk":"11945978199","pt":1724915035308,"mc":[{"id":"1.232283784","rc":[{"batb":[[0,1.93,38.98],[1,1.91,8.38],[2,1.74,16.76]],"ltp":2.0,"tv":2443.91,"id":35736915}]}]}
{"op":"mcm","clk":"11945978342","pt":1724915039964,"mc":[{"id":"1.232283784","rc":[{"batb":[[0,1.94,5],[1,1.93,38.98],[2,1.91,8.38]],"ltp":2.0,"tv":2443.91,"id":35736915}]}]}
{"op":"mcm","clk":"11945978466","pt":1724915043193,"mc":[{"id":"1.232283784","rc":[{"batb":[[0,1.93,38.98],[1,1.91,8.38],[2,1.74,16.76]],"ltp":2.0,"tv":2443.91,"id":35736915}]}]}
{"op":"mcm","clk":"11945978650","pt":1724915047807,"mc":[{"id":"1.232283784","rc":[{"batb":[[0,1.94,5],[1,1.93,38.98],[2,1.91,8.38]],"ltp":2.0,"tv":2443.91,"id":35736915}]}]}
{"op":"mcm","clk":"11945978799","pt":1724915051185,"mc":[{"id":"1.232283784","rc":[{"batb":[[0,1.93,38.98],[1,1.91,8.38],[2,1.74,16.76]],"ltp":2.0,"tv":2443.91,"id":35736915}]}]}
{"op":"mcm","clk":"11945978949","pt":1724915054203,"mc":[{"id":"1.232283784","rc":[{"batb":[[0,1.94,5],[1,1.93,38.98],[2,1.91,8.38]],"ltp":2.0,"tv":2443.91,"id":35736915}]}]}
{"op":"mcm","clk":"11945979072","pt":1724915057622,"mc":[{"id":"1.232283784","rc":[{"batb":[[0,1.93,38.98],[1,1.91,8.38],[2,1.74,16.76]],"ltp":2.0,"tv":2443.91,"id":35736915}]}]}
{"op":"mcm","clk":"11945979228","pt":1724915062222,"mc":[{"id":"1.232283784","rc":[{"batb":[[0,1.94,5],[1,1.93,38.98],[2,1.91,8.38]],"ltp":2.0,"tv":2443.91,"id":35736915}]}]}
{"op":"mcm","clk":"11945979347","pt":1724915065708,"mc":[{"id":"1.232283784","rc":[{"batb":[[0,1.93,38.98],[1,1.91,8.38],[2,1.74,16.76]],"ltp":2.0,"tv":2443.91,"id":35736915}]}]}
{"op":"mcm","clk":"11945979555","pt":1724915071949,"mc":[{"id":"1.232283784","rc":[{"batb":[[0,1.94,5],[1,1.93,38.98],[2,1.91,8.38]],"ltp":2.0,"tv":2443.91,"id":35736915}]}]}
{"op":"mcm","clk":"11945979689","pt":1724915075141,"mc":[{"id":"1.232283784","rc":[{"batb":[[0,1.93,38.98],[1,1.91,8.38],[2,1.74,16.76]],"ltp":2.0,"tv":2443.91,"id":35736915}]}]}
{"op":"mcm","clk":"11945979784","pt":1724915077651,"mc":[{"id":"1.232283784","rc":[{"batb":[[0,1.94,5],[1,1.93,38.98],[2,1.91,8.38]],"ltp":2.0,"tv":2443.91,"id":35736915}]}]}
{"op":"mcm","clk":"11945979911","pt":1724915080937,"mc":[{"id":"1.232283784","rc":[{"batb":[[0,1.93,38.98],[1,1.91,8.38],[2,1.74,16.76]],"ltp":2.0,"tv":2443.91,"id":35736915}]}]}
{"op":"mcm","clk":"11945979989","pt":1724915083650,"mc":[{"id":"1.232283784","rc":[{"batb":[[0,1.94,5],[1,1.93,38.98],[2,1.91,8.38]],"ltp":2.0,"tv":2443.91,"id":35736915}]}]}
{"op":"mcm","clk":"11945980108","pt":1724915087045,"mc":[{"id":"1.232283784","rc":[{"batb":[[0,1.93,38.98],[1,1.91,8.38],[2,1.74,16.76]],"ltp":2.0,"tv":2443.91,"id":35736915}]}]}
{"op":"mcm","clk":"11945980232","pt":1724915090629,"mc":[{"id":"1.232283784","rc":[{"batb":[[0,1.94,5],[1,1.93,38.98],[2,1.91,8.38]],"ltp":2.0,"tv":2443.91,"id":35736915}]}]}
{"op":"mcm","clk":"11945980376","pt":1724915093856,"mc":[{"id":"1.232283784","rc":[{"batb":[[0,1.93,38.98],[1,1.91,8.38],[2,1.74,16.76]],"ltp":2.0,"tv":2443.91,"id":35736915}]}]}
{"op":"mcm","clk":"11945980477","pt":1724915097077,"mc":[{"id":"1.232283784","rc":[{"batb":[[0,1.94,5],[1,1.93,38.98],[2,1.91,8.38]],"ltp":2.0,"tv":2443.91,"id":35736915}]}]}
{"op":"mcm","clk":"11945980585","pt":1724915100459,"mc":[{"id":"1.232283784","rc":[{"batb":[[0,1.93,38.98],[1,1.91,8.38],[2,1.74,16.76]],"ltp":2.0,"tv":2443.91,"id":35736915}]}]}
{"op":"mcm","clk":"11945980803","pt":1724915106467,"mc":[{"id":"1.232283784","rc":[{"batb":[[0,1.94,5],[1,1.93,38.98],[2,1.91,8.38]],"ltp":2.0,"tv":2443.91,"id":35736915}]}]}
{"op":"mcm","clk":"11945980928","pt":1724915109992,"mc":[{"id":"1.232283784","rc":[{"batb":[[0,1.93,38.98],[1,1.91,8.38],[2,1.74,16.76]],"ltp":2.0,"tv":2443.91,"id":35736915}]}]}
{"op":"mcm","clk":"11945981067","pt":1724915113468,"mc":[{"id":"1.232283784","rc":[{"batb":[[0,1.94,5],[1,1.93,38.98],[2,1.91,8.38]],"ltp":2.0,"tv":2443.91,"id":35736915}]}]}
{"op":"mcm","clk":"11945981177","pt":1724915116687,"mc":[{"id":"1.232283784","rc":[{"batb":[[0,1.93,38.98],[1,1.91,8.38],[2,1.74,16.76]],"ltp":2.0,"tv":2443.91,"id":35736915}]}]}
{"op":"mcm","clk":"11945981273","pt":1724915119293,"mc":[{"id":"1.232283784","rc":[{"batb":[[0,1.94,5],[1,1.93,38.98],[2,1.91,8.38]],"ltp":2.0,"tv":2443.91,"id":35736915}]}]}
{"op":"mcm","clk":"11945981382","pt":1724915122668,"mc":[{"id":"1.232283784","rc":[{"batb":[[0,1.93,38.98],[1,1.91,8.38],[2,1.74,16.76]],"ltp":2.0,"tv":2443.91,"id":35736915}]}]}
{"op":"mcm","clk":"11945981489","pt":1724915125110,"mc":[{"id":"1.232283784","rc":[{"batb":[[0,1.94,5],[1,1.93,38.98],[2,1.91,8.38]],"ltp":2.0,"tv":2443.91,"id":35736915}]}]}
{"op":"mcm","clk":"11945981610","pt":1724915128499,"mc":[{"id":"1.232283784","rc":[{"batb":[[0,1.93,38.98],[1,1.91,8.38],[2,1.74,16.76]],"ltp":2.0,"tv":2443.91,"id":35736915}]}]}
{"op":"mcm","clk":"11945981709","pt":1724915131009,"mc":[{"id":"1.232283784","rc":[{"batb":[[0,1.94,5],[1,1.93,38.98],[2,1.91,8.38]],"ltp":2.0,"tv":2443.91,"id":35736915}]}]}
{"op":"mcm","clk":"11945981818","pt":1724915134428,"mc":[{"id":"1.232283784","rc":[{"batb":[[0,1.93,38.98],[1,1.91,8.38],[2,1.74,16.76]],"ltp":2.0,"tv":2443.91,"id":35736915}]}]}
{"op":"mcm","clk":"11945981887","pt":1724915136681,"mc":[{"id":"1.232283784","rc":[{"batb":[[0,1.94,5],[1,1.93,38.98],[2,1.91,8.38]],"ltp":2.0,"tv":2443.91,"id":35736915}]}]}
{"op":"mcm","clk":"11945982010","pt":1724915139914,"mc":[{"id":"1.232283784","rc":[{"batb":[[0,1.93,38.98],[1,1.91,8.38],[2,1.74,16.76]],"ltp":2.0,"tv":2443.91,"id":35736915}]}]}
{"op":"mcm","clk":"11945982262","pt":1724915146423,"mc":[{"id":"1.232283784","rc":[{"batb":[[0,1.94,5],[1,1.93,38.98],[2,1.91,8.38]],"ltp":2.0,"tv":2443.91,"id":35736915}]}]}
{"op":"mcm","clk":"11945982396","pt":1724915149912,"mc":[{"id":"1.232283784","rc":[{"batb":[[0,1.93,38.98],[1,1.91,8.38],[2,1.74,16.76]],"ltp":2.0,"tv":2443.91,"id":35736915}]}]}
{"op":"mcm","clk":"11945982517","pt":1724915153035,"mc":[{"id":"1.232283784","rc":[{"batb":[[0,1.94,5],[1,1.93,38.98],[2,1.91,8.38]],"ltp":2.0,"tv":2443.91,"id":35736915}]}]}
{"op":"mcm","clk":"11945982618","pt":1724915156204,"mc":[{"id":"1.232283784","rc":[{"batb":[[0,1.93,38.98],[1,1.91,8.38],[2,1.74,16.76]],"ltp":2.0,"tv":2443.91,"id":35736915}]}]}
{"op":"mcm","clk":"11945982804","pt":1724915161061,"mc":[{"id":"1.232283784","rc":[{"batb":[[0,1.94,5],[1,1.93,38.98],[2,1.91,8.38]],"ltp":2.0,"tv":2443.91,"id":35736915}]}]}
{"op":"mcm","clk":"11945982920","pt":1724915164239,"mc":[{"id":"1.232283784","rc":[{"batb":[[0,1.93,38.98],[1,1.91,8.38],[2,1.74,16.76]],"ltp":2.0,"tv":2443.91,"id":35736915}]}]}
{"op":"mcm","clk":"11945983043","pt":1724915166918,"mc":[{"id":"1.232283784","rc":[{"batb":[[0,1.94,5],[1,1.93,38.98],[2,1.91,8.38]],"ltp":2.0,"tv":2443.91,"id":35736915}]}]}
{"op":"mcm","clk":"11945983176","pt":1724915170251,"mc":[{"id":"1.232283784","rc":[{"batb":[[0,1.93,38.98],[1,1.91,8.38],[2,1.74,16.76]],"ltp":2.0,"tv":2443.91,"id":35736915}]}]}
{"op":"mcm","clk":"11945983302","pt":1724915172930,"mc":[{"id":"1.232283784","rc":[{"batb":[[0,1.94,5],[1,1.93,38.98],[2,1.91,8.38]],"ltp":2.0,"tv":2443.91,"id":35736915}]}]}
{"op":"mcm","clk":"11945983420","pt":1724915176260,"mc":[{"id":"1.232283784","rc":[{"batb":[[0,1.93,38.98],[1,1.91,8.38],[2,1.74,16.76]],"ltp":2.0,"tv":2443.91,"id":35736915}]}]}
{"op":"mcm","clk":"11945983568","pt":1724915180043,"mc":[{"id":"1.232283784","rc":[{"batb":[[0,1.94,5],[1,1.93,38.98],[2,1.91,8.38]],"ltp":2.0,"tv":2443.91,"id":35736915}]}]}
{"op":"mcm","clk":"11945983708","pt":1724915183474,"mc":[{"id":"1.232283784","rc":[{"batb":[[0,1.93,38.98],[1,1.91,8.38],[2,1.74,16.76]],"ltp":2.0,"tv":2443.91,"id":35736915}]}]}
{"op":"mcm","clk":"11945983821","pt":1724915186748,"mc":[{"id":"1.232283784","rc":[{"batb":[[0,1.94,5],[1,1.93,38.98],[2,1.91,8.38]],"ltp":2.0,"tv":2443.91,"id":35736915}]}]}
{"op":"mcm","clk":"11945983940","pt":1724915190076,"mc":[{"id":"1.232283784","rc":[{"batb":[[0,1.93,38.98],[1,1.91,8.38],[2,1.74,16.76]],"ltp":2.0,"tv":2443.91,"id":35736915}]}]}
{"op":"mcm","clk":"11945984071","pt":1724915192748,"mc":[{"id":"1.232283784","rc":[{"batb":[[0,1.94,5],[1,1.93,38.98],[2,1.91,8.38]],"ltp":2.0,"tv":2443.91,"id":35736915}]}]}
{"op":"mcm","clk":"11945984219","pt":1724915196275,"mc":[{"id":"1.232283784","rc":[{"batb":[[0,1.93,38.98],[1,1.91,8.38],[2,1.74,16.76]],"ltp":2.0,"tv":2443.91,"id":35736915}]}]}
{"op":"mcm","clk":"11945984462","pt":1724915201866,"mc":[{"id":"1.232283784","rc":[{"batb":[[0,1.94,5],[1,1.93,38.98],[2,1.91,8.38]],"ltp":2.0,"tv":2443.91,"id":35736915}]}]}
{"op":"mcm","clk":"11945984604","pt":1724915205195,"mc":[{"id":"1.232283784","rc":[{"batb":[[0,1.93,38.98],[1,1.91,8.38],[2,1.74,16.76]],"ltp":2.0,"tv":2443.91,"id":35736915}]}]}
{"op":"mcm","clk":"11945984715","pt":1724915207800,"mc":[{"id":"1.232283784","rc":[{"batb":[[0,1.94,5],[1,1.93,38.98],[2,1.91,8.38]],"ltp":2.0,"tv":2443.91,"id":35736915}]}]}
{"op":"mcm","clk":"11945984825","pt":1724915211176,"mc":[{"id":"1.232283784","rc":[{"batb":[[0,1.93,38.98],[1,1.91,8.38],[2,1.74,16.76]],"ltp":2.0,"tv":2443.91,"id":35736915}]}]}
{"op":"mcm","clk":"11945985045","pt":1724915216039,"mc":[{"id":"1.232283784","rc":[{"batb":[[0,1.94,5],[1,1.93,38.98],[2,1.91,8.38]],"ltp":2.0,"tv":2443.91,"id":35736915}]}]}
{"op":"mcm","clk":"11945985172","pt":1724915219308,"mc":[{"id":"1.232283784","rc":[{"batb":[[0,1.93,38.98],[1,1.91,8.38],[2,1.74,16.76]],"ltp":2.0,"tv":2443.91,"id":35736915}]}]}
{"op":"mcm","clk":"11945985423","pt":1724915225515,"mc":[{"id":"1.232283784","rc":[{"batb":[[0,1.94,5],[1,1.93,38.98],[2,1.91,8.38]],"ltp":2.0,"tv":2443.91,"id":35736915}]}]}
{"op":"mcm","clk":"11945985587","pt":1724915229056,"mc":[{"id":"1.232283784","rc":[{"batb":[[0,1.93,38.98],[1,1.91,8.38],[2,1.74,16.76]],"ltp":2.0,"tv":2443.91,"id":35736915}]}]}
{"op":"mcm","clk":"11945985856","pt":1724915235462,"mc":[{"id":"1.232283784","rc":[{"batb":[[0,1.94,5],[1,1.93,38.98],[2,1.91,8.38]],"ltp":2.0,"tv":2443.91,"id":35736915}]}]}
{"op":"mcm","clk":"11945986027","pt":1724915239154,"mc":[{"id":"1.232283784","rc":[{"batb":[[0,1.93,38.98],[1,1.91,8.38],[2,1.74,16.76]],"ltp":2.0,"tv":2443.91,"id":35736915}]}]}
{"op":"mcm","clk":"11945986335","pt":1724915245956,"mc":[{"id":"1.232283784","rc":[{"batb":[[0,1.94,5],[1,1.93,38.98],[2,1.91,8.38]],"ltp":2.0,"tv":2443.91,"id":35736915}]}]}
{"op":"mcm","clk":"11945986489","pt":1724915249349,"mc":[{"id":"1.232283784","rc":[{"batb":[[0,1.93,38.98],[1,1.91,8.38],[2,1.74,16.76]],"ltp":2.0,"tv":2443.91,"id":35736915}]}]}
{"op":"mcm","clk":"11945986641","pt":1724915252892,"mc":[{"id":"1.232283784","rc":[{"batb":[[0,1.94,5],[1,1.93,38.98],[2,1.91,8.38]],"ltp":2.0,"tv":2443.91,"id":35736915}]}]}
{"op":"mcm","clk":"11945986759","pt":1724915256160,"mc":[{"id":"1.232283784","rc":[{"batb":[[0,1.93,38.98],[1,1.91,8.38],[2,1.74,16.76]],"ltp":2.0,"tv":2443.91,"id":35736915}]}]}
{"op":"mcm","clk":"11945986874","pt":1724915259904,"mc":[{"id":"1.232283784","rc":[{"batb":[[0,1.94,5],[1,1.93,38.98],[2,1.91,8.38]],"ltp":2.0,"tv":2443.91,"id":35736915}]}]}
{"op":"mcm","clk":"11945987009","pt":1724915263082,"mc":[{"id":"1.232283784","rc":[{"batb":[[0,1.93,38.98],[1,1.91,8.38],[2,1.74,16.76]],"ltp":2.0,"tv":2443.91,"id":35736915}]}]}
{"op":"mcm","clk":"11945987244","pt":1724915269170,"mc":[{"id":"1.232283784","rc":[{"batb":[[0,1.94,5],[1,1.93,38.98],[2,1.91,8.38]],"ltp":2.0,"tv":2443.91,"id":35736915}]}]}
{"op":"mcm","clk":"11945987377","pt":1724915272598,"mc":[{"id":"1.232283784","rc":[{"batb":[[0,1.93,38.98],[1,1.91,8.38],[2,1.74,16.76]],"ltp":2.0,"tv":2443.91,"id":35736915}]}]}
{"op":"mcm","clk":"11945987495","pt":1724915275195,"mc":[{"id":"1.232283784","rc":[{"batb":[[0,1.94,5],[1,1.93,38.98],[2,1.91,8.38]],"ltp":2.0,"tv":2443.91,"id":35736915}]}]}
{"op":"mcm","clk":"11945987639","pt":1724915278472,"mc":[{"id":"1.232283784","rc":[{"batb":[[0,1.93,38.98],[1,1.91,8.38],[2,1.74,16.76]],"ltp":2.0,"tv":2443.91,"id":35736915}]}]}
{"op":"mcm","clk":"11945987783","pt":1724915282114,"mc":[{"id":"1.232283784","rc":[{"batb":[[0,1.94,5],[1,1.93,38.98],[2,1.91,8.38]],"ltp":2.0,"tv":2443.91,"id":35736915}]}]}
{"op":"mcm","clk":"11945987923","pt":1724915285406,"mc":[{"id":"1.232283784","rc":[{"batb":[[0,1.93,38.98],[1,1.91,8.38],[2,1.74,16.76]],"ltp":2.0,"tv":2443.91,"id":35736915}]}]}
{"op":"mcm","clk":"11945988124","pt":1724915289401,"mc":[{"id":"1.232283784","rc":[{"batb":[[0,1.94,5],[1,1.93,38.98],[2,1.91,8.38]],"ltp":2.0,"tv":2443.91,"id":35736915}]}]}
{"op":"mcm","clk":"11945988284","pt":1724915292786,"mc":[{"id":"1.232283784","rc":[{"batb":[[0,1.93,38.98],[1,1.91,8.38],[2,1.74,16.76]],"ltp":2.0,"tv":2443.91,"id":35736915}]}]}
{"op":"mcm","clk":"11945988412","pt":1724915296108,"mc":[{"id":"1.232283784","rc":[{"batb":[[0,1.94,5],[1,1.93,38.98],[2,1.91,8.38]],"ltp":2.0,"tv":2443.91,"id":35736915}]}]}
{"op":"mcm","clk":"11945988562","pt":1724915299396,"mc":[{"id":"1.232283784","rc":[{"batb":[[0,1.93,38.98],[1,1.91,8.38],[2,1.74,16.76]],"ltp":2.0,"tv":2443.91,"id":35736915}]}]}
{"op":"mcm","clk":"11945988595","pt":1724915300214,"mc":[{"id":"1.232283784","rc":[{"trd":[[2.34,25.86]],"batl":[[0,2.34,37.07]],"ltp":2.34,"tv":2449.09,"id":35736915}],"tv":4482.45}]}
{"op":"mcm","clk":"11945988697","pt":1724915302725,"mc":[{"id":"1.232283784","rc":[{"batb":[[0,1.94,5],[1,1.93,38.98],[2,1.91,8.38]],"ltp":2.34,"tv":2449.09,"id":35736915}]}]}
{"op":"mcm","clk":"11945988850","pt":1724915305922,"mc":[{"id":"1.232283784","rc":[{"batb":[[0,1.93,38.98],[1,1.91,8.38],[2,1.74,16.76]],"ltp":2.34,"tv":2449.09,"id":35736915}]}]}
{"op":"mcm","clk":"11945989041","pt":1724915310853,"mc":[{"id":"1.232283784","rc":[{"batb":[[0,1.94,5],[1,1.93,38.98],[2,1.91,8.38]],"ltp":2.34,"tv":2449.09,"id":35736915}]}]}
{"op":"mcm","clk":"11945989165","pt":1724915314230,"mc":[{"id":"1.232283784","rc":[{"batb":[[0,1.93,38.98],[1,1.91,8.38],[2,1.74,16.76]],"ltp":2.34,"tv":2449.09,"id":35736915}]}]}
{"op":"mcm","clk":"11945989296","pt":1724915317508,"mc":[{"id":"1.232283784","rc":[{"batb":[[0,1.94,5],[1,1.93,38.98],[2,1.91,8.38]],"ltp":2.34,"tv":2449.09,"id":35736915}]}]}
{"op":"mcm","clk":"11945989453","pt":1724915320635,"mc":[{"id":"1.232283784","rc":[{"batb":[[0,1.93,38.98],[1,1.91,8.38],[2,1.74,16.76]],"ltp":2.34,"tv":2449.09,"id":35736915}]}]}
{"op":"mcm","clk":"11945989602","pt":1724915323417,"mc":[{"id":"1.232283784","rc":[{"batb":[[0,1.94,5],[1,1.93,38.98],[2,1.91,8.38]],"ltp":2.34,"tv":2449.09,"id":35736915}]}]}
{"op":"mcm","clk":"11945989709","pt":1724915326644,"mc":[{"id":"1.232283784","rc":[{"batb":[[0,1.93,38.98],[1,1.91,8.38],[2,1.74,16.76]],"ltp":2.34,"tv":2449.09,"id":35736915}]}]}
{"op":"mcm","clk":"11945989831","pt":1724915329464,"mc":[{"id":"1.232283784","rc":[{"batb":[[0,1.94,5],[1,1.93,38.98],[2,1.91,8.38]],"ltp":2.34,"tv":2449.09,"id":35736915}]}]}
{"op":"mcm","clk":"11945989989","pt":1724915332658,"mc":[{"id":"1.232283784","rc":[{"batb":[[0,1.93,38.98],[1,1.91,8.38],[2,1.74,16.76]],"ltp":2.34,"tv":2449.09,"id":35736915}]}]}
{"op":"mcm","clk":"11945990125","pt":1724915336450,"mc":[{"id":"1.232283784","rc":[{"batb":[[0,1.94,5],[1,1.93,38.98],[2,1.91,8.38]],"ltp":2.34,"tv":2449.09,"id":35736915}]}]}
{"op":"mcm","clk":"11945990247","pt":1724915339879,"mc":[{"id":"1.232283784","rc":[{"batb":[[0,1.93,38.98],[1,1.91,8.38],[2,1.74,16.76]],"ltp":2.34,"tv":2449.09,"id":35736915}]}]}
{"op":"mcm","clk":"11945990450","pt":1724915343538,"mc":[{"id":"1.232283784","rc":[{"batb":[[0,1.94,5],[1,1.93,38.98],[2,1.91,8.38]],"ltp":2.34,"tv":2449.09,"id":35736915}]}]}
{"op":"mcm","clk":"11945990585","pt":1724915346767,"mc":[{"id":"1.232283784","rc":[{"batb":[[0,1.93,38.98],[1,1.91,8.38],[2,1.74,16.76]],"ltp":2.34,"tv":2449.09,"id":35736915}]}]}
{"op":"mcm","clk":"11945990693","pt":1724915349685,"mc":[{"id":"1.232283784","rc":[{"batb":[[0,1.94,5],[1,1.93,38.98],[2,1.91,8.38]],"ltp":2.34,"tv":2449.09,"id":35736915}]}]}
{"op":"mcm","clk":"11945990817","pt":1724915353163,"mc":[{"id":"1.232283784","rc":[{"batb":[[0,1.93,38.98],[1,1.91,8.38],[2,1.74,16.76]],"ltp":2.34,"tv":2449.09,"id":35736915}]}]}
{"op":"mcm","clk":"11945990941","pt":1724915356807,"mc":[{"id":"1.232283784","rc":[{"batb":[[0,1.94,5],[1,1.93,38.98],[2,1.91,8.38]],"ltp":2.34,"tv":2449.09,"id":35736915}]}]}
{"op":"mcm","clk":"11945991061","pt":1724915360096,"mc":[{"id":"1.232283784","rc":[{"batb":[[0,1.93,38.98],[1,1.91,8.38],[2,1.74,16.76]],"ltp":2.34,"tv":2449.09,"id":35736915}]}]}
{"op":"mcm","clk":"11945991185","pt":1724915362479,"mc":[{"id":"1.232283784","rc":[{"batb":[[0,1.94,5],[1,1.93,38.98],[2,1.91,8.38]],"ltp":2.34,"tv":2449.09,"id":35736915}]}]}
{"op":"mcm","clk":"11945991300","pt":1724915365816,"mc":[{"id":"1.232283784","rc":[{"batb":[[0,1.93,38.98],[1,1.91,8.38],[2,1.74,16.76]],"ltp":2.34,"tv":2449.09,"id":35736915}]}]}
{"op":"mcm","clk":"11945991420","pt":1724915369189,"mc":[{"id":"1.232283784","rc":[{"batb":[[0,1.94,5],[1,1.93,38.98],[2,1.91,8.38]],"ltp":2.34,"tv":2449.09,"id":35736915}]}]}
{"op":"mcm","clk":"11945991533","pt":1724915372468,"mc":[{"id":"1.232283784","rc":[{"batb":[[0,1.93,38.98],[1,1.91,8.38],[2,1.74,16.76]],"ltp":2.34,"tv":2449.09,"id":35736915}]}]}
{"op":"mcm","clk":"11945991666","pt":1724915376201,"mc":[{"id":"1.232283784","rc":[{"batb":[[0,1.94,5],[1,1.93,38.98],[2,1.91,8.38]],"ltp":2.34,"tv":2449.09,"id":35736915}]}]}
{"op":"mcm","clk":"11945991787","pt":1724915379583,"mc":[{"id":"1.232283784","rc":[{"batb":[[0,1.93,38.98],[1,1.91,8.38],[2,1.74,16.76]],"ltp":2.34,"tv":2449.09,"id":35736915}]}]}
{"op":"mcm","clk":"11945991891","pt":1724915382623,"mc":[{"id":"1.232283784","rc":[{"batb":[[0,1.94,5],[1,1.93,38.98],[2,1.91,8.38]],"ltp":2.34,"tv":2449.09,"id":35736915}]}]}
{"op":"mcm","clk":"11945991997","pt":1724915385999,"mc":[{"id":"1.232283784","rc":[{"batb":[[0,1.93,38.98],[1,1.91,8.38],[2,1.74,16.76]],"ltp":2.34,"tv":2449.09,"id":35736915}]}]}
{"op":"mcm","clk":"11945992098","pt":1724915389524,"mc":[{"id":"1.232283784","rc":[{"batb":[[0,1.94,5],[1,1.93,38.98],[2,1.91,8.38]],"ltp":2.34,"tv":2449.09,"id":35736915}]}]}
{"op":"mcm","clk":"11945992236","pt":1724915392798,"mc":[{"id":"1.232283784","rc":[{"batb":[[0,1.93,38.98],[1,1.91,8.38],[2,1.74,16.76]],"ltp":2.34,"tv":2449.09,"id":35736915}]}]}
{"op":"mcm","clk":"11945992362","pt":1724915396226,"mc":[{"id":"1.232283784","rc":[{"batb":[[0,1.94,5],[1,1.93,38.98],[2,1.91,8.38]],"ltp":2.34,"tv":2449.09,"id":35736915}]}]}
{"op":"mcm","clk":"11945992481","pt":1724915399617,"mc":[{"id":"1.232283784","rc":[{"batb":[[0,1.93,38.98],[1,1.91,8.38],[2,1.74,16.76]],"ltp":2.34,"tv":2449.09,"id":35736915}]}]}
{"op":"mcm","clk":"11945992606","pt":1724915403233,"mc":[{"id":"1.232283784","rc":[{"batb":[[0,1.94,5],[1,1.93,38.98],[2,1.91,8.38]],"ltp":2.34,"tv":2449.09,"id":35736915}]}]}
{"op":"mcm","clk":"11945992726","pt":1724915406660,"mc":[{"id":"1.232283784","rc":[{"batb":[[0,1.93,38.98],[1,1.91,8.38],[2,1.74,16.76]],"ltp":2.34,"tv":2449.09,"id":35736915}]}]}
{"op":"mcm","clk":"11945992842","pt":1724915409577,"mc":[{"id":"1.232283784","rc":[{"batb":[[0,1.94,5],[1,1.93,38.98],[2,1.91,8.38]],"ltp":2.34,"tv":2449.09,"id":35736915}]}]}
{"op":"mcm","clk":"11945992979","pt":1724915412950,"mc":[{"id":"1.232283784","rc":[{"batb":[[0,1.93,38.98],[1,1.91,8.38],[2,1.74,16.76]],"ltp":2.34,"tv":2449.09,"id":35736915}]}]}
{"op":"mcm","clk":"11945993088","pt":1724915415692,"mc":[{"id":"1.232283784","rc":[{"batb":[[0,1.94,5],[1,1.93,38.98],[2,1.91,8.38]],"ltp":2.34,"tv":2449.09,"id":35736915}]}]}
{"op":"mcm","clk":"11945993187","pt":1724915418989,"mc":[{"id":"1.232283784","rc":[{"batb":[[0,1.93,38.98],[1,1.91,8.38],[2,1.74,16.76]],"ltp":2.34,"tv":2449.09,"id":35736915}]}]}
{"op":"mcm","clk":"11945993397","pt":1724915426399,"mc":[{"id":"1.232283784","rc":[{"batb":[[0,1.94,5],[1,1.93,38.98],[2,1.91,8.38]],"ltp":2.34,"tv":2449.09,"id":35736915}]}]}
{"op":"mcm","clk":"11945993488","pt":1724915429774,"mc":[{"id":"1.232283784","rc":[{"batb":[[0,1.93,38.98],[1,1.91,8.38],[2,1.74,16.76]],"ltp":2.34,"tv":2449.09,"id":35736915}]}]}
{"op":"mcm","clk":"11945993580","pt":1724915432171,"mc":[{"id":"1.232283784","rc":[{"batb":[[0,1.94,5],[1,1.93,38.98],[2,1.91,8.38]],"ltp":2.34,"tv":2449.09,"id":35736915}]}]}
{"op":"mcm","clk":"11945993677","pt":1724915435800,"mc":[{"id":"1.232283784","rc":[{"batb":[[0,1.93,38.98],[1,1.91,8.38],[2,1.74,16.76]],"ltp":2.34,"tv":2449.09,"id":35736915}]}]}
{"op":"mcm","clk":"11945993805","pt":1724915439792,"mc":[{"id":"1.232283784","rc":[{"batb":[[0,1.94,5],[1,1.93,38.98],[2,1.91,8.38]],"ltp":2.34,"tv":2449.09,"id":35736915}]}]}
{"op":"mcm","clk":"11945993919","pt":1724915443312,"mc":[{"id":"1.232283784","rc":[{"batb":[[0,1.93,38.98],[1,1.91,8.38],[2,1.74,16.76]],"ltp":2.34,"tv":2449.09,"id":35736915}]}]}
{"op":"mcm","clk":"11945993998","pt":1724915445820,"mc":[{"id":"1.232283784","rc":[{"batb":[[0,1.94,5],[1,1.93,38.98],[2,1.91,8.38]],"ltp":2.34,"tv":2449.09,"id":35736915}]}]}
{"op":"mcm","clk":"11945994115","pt":1724915449221,"mc":[{"id":"1.232283784","rc":[{"batb":[[0,1.93,38.98],[1,1.91,8.38],[2,1.74,16.76]],"ltp":2.34,"tv":2449.09,"id":35736915}]}]}
{"op":"mcm","clk":"11945994194","pt":1724915451721,"mc":[{"id":"1.232283784","rc":[{"batb":[[0,1.94,5],[1,1.93,38.98],[2,1.91,8.38]],"ltp":2.34,"tv":2449.09,"id":35736915}]}]}
{"op":"mcm","clk":"11945994323","pt":1724915455024,"mc":[{"id":"1.232283784","rc":[{"batb":[[0,1.93,38.98],[1,1.91,8.38],[2,1.74,16.76]],"ltp":2.34,"tv":2449.09,"id":35736915}]}]}
{"op":"mcm","clk":"11945994401","pt":1724915457189,"mc":[{"id":"1.232283784","rc":[{"batb":[[0,1.94,5],[1,1.93,38.98],[2,1.91,8.38]],"ltp":2.34,"tv":2449.09,"id":35736915}]}]}
{"op":"mcm","clk":"11945994541","pt":1724915460725,"mc":[{"id":"1.232283784","rc":[{"batb":[[0,1.93,38.98],[1,1.91,8.38],[2,1.74,16.76]],"ltp":2.34,"tv":2449.09,"id":35736915}]}]}
{"op":"mcm","clk":"11945994621","pt":1724915463343,"mc":[{"id":"1.232283784","rc":[{"batb":[[0,1.94,5],[1,1.93,38.98],[2,1.91,8.38]],"ltp":2.34,"tv":2449.09,"id":35736915}]}]}
{"op":"mcm","clk":"11945994730","pt":1724915466734,"mc":[{"id":"1.232283784","rc":[{"trd":[[2.34,75.42]],"batb":[[0,1.93,38.98],[1,1.91,8.38],[2,1.74,16.76]],"batl":[[0,2.34,12.29]],"ltp":2.34,"tv":2498.65,"id":35736915}],"tv":4532.01}]}
{"op":"mcm","clk":"11945994808","pt":1724915469142,"mc":[{"id":"1.232283784","rc":[{"batb":[[0,1.94,5],[1,1.93,38.98],[2,1.91,8.38]],"ltp":2.34,"tv":2498.65,"id":35736915}]}]}
{"op":"mcm","clk":"11945994919","pt":1724915472629,"mc":[{"id":"1.232283784","rc":[{"batb":[[0,1.93,38.98],[1,1.91,8.38],[2,1.74,16.76]],"ltp":2.34,"tv":2498.65,"id":35736915}]}]}
{"op":"mcm","clk":"11945994996","pt":1724915474836,"mc":[{"id":"1.232283784","rc":[{"batb":[[0,1.94,5],[1,1.93,38.98],[2,1.91,8.38]],"ltp":2.34,"tv":2498.65,"id":35736915}]}]}
{"op":"mcm","clk":"11945995138","pt":1724915478218,"mc":[{"id":"1.232283784","rc":[{"batb":[[0,1.93,38.98],[1,1.91,8.38],[2,1.74,16.76]],"ltp":2.34,"tv":2498.65,"id":35736915}]}]}
{"op":"mcm","clk":"11945995207","pt":1724915480714,"mc":[{"id":"1.232283784","rc":[{"batb":[[0,1.94,5],[1,1.93,38.98],[2,1.91,8.38]],"ltp":2.34,"tv":2498.65,"id":35736915}]}]}
{"op":"mcm","clk":"11945995316","pt":1724915484151,"mc":[{"id":"1.232283784","rc":[{"batb":[[0,1.93,38.98],[1,1.91,8.38],[2,1.74,16.76]],"ltp":2.34,"tv":2498.65,"id":35736915}]}]}
{"op":"mcm","clk":"11945995382","pt":1724915486350,"mc":[{"id":"1.232283784","rc":[{"batb":[[0,1.94,5],[1,1.93,38.98],[2,1.91,8.38]],"ltp":2.34,"tv":2498.65,"id":35736915}]}]}
{"op":"mcm","clk":"11945995466","pt":1724915489829,"mc":[{"id":"1.232283784","rc":[{"batb":[[0,1.93,38.98],[1,1.91,8.38],[2,1.74,16.76]],"ltp":2.34,"tv":2498.65,"id":35736915}]}]}
{"op":"mcm","clk":"11945995544","pt":1724915492243,"mc":[{"id":"1.232283784","rc":[{"batb":[[0,1.94,5],[1,1.93,38.98],[2,1.91,8.38]],"ltp":2.34,"tv":2498.65,"id":35736915}]}]}
{"op":"mcm","clk":"11945995626","pt":1724915495564,"mc":[{"id":"1.232283784","rc":[{"batb":[[0,1.93,38.98],[1,1.91,8.38],[2,1.74,16.76]],"ltp":2.34,"tv":2498.65,"id":35736915}]}]}
{"op":"mcm","clk":"11945995713","pt":1724915497970,"mc":[{"id":"1.232283784","rc":[{"batb":[[0,1.94,5],[1,1.93,38.98],[2,1.91,8.38]],"ltp":2.34,"tv":2498.65,"id":35736915}]}]}
{"op":"mcm","clk":"11945995822","pt":1724915501147,"mc":[{"id":"1.232283784","rc":[{"batb":[[0,1.93,38.98],[1,1.91,8.38],[2,1.74,16.76]],"ltp":2.34,"tv":2498.65,"id":35736915}]}]}
{"op":"mcm","clk":"11945995938","pt":1724915503777,"mc":[{"id":"1.232283784","rc":[{"batb":[[0,1.94,5],[1,1.93,38.98],[2,1.91,8.38]],"ltp":2.34,"tv":2498.65,"id":35736915}]}]}
{"op":"mcm","clk":"11945996036","pt":1724915507154,"mc":[{"id":"1.232283784","rc":[{"batb":[[0,1.93,38.98],[1,1.91,8.38],[2,1.74,16.76]],"ltp":2.34,"tv":2498.65,"id":35736915}]}]}
{"op":"mcm","clk":"11945996147","pt":1724915509580,"mc":[{"id":"1.232283784","rc":[{"batb":[[0,1.94,5],[1,1.93,38.98],[2,1.91,8.38]],"ltp":2.34,"tv":2498.65,"id":35736915}]}]}
{"op":"mcm","clk":"11945996295","pt":1724915512894,"mc":[{"id":"1.232283784","rc":[{"batb":[[0,1.93,38.98],[1,1.91,8.38],[2,1.74,16.76]],"ltp":2.34,"tv":2498.65,"id":35736915}]}]}
{"op":"mcm","clk":"11945996423","pt":1724915516177,"mc":[{"id":"1.232283784","rc":[{"batb":[[0,1.94,5],[1,1.93,38.98],[2,1.91,8.38]],"ltp":2.34,"tv":2498.65,"id":35736915}]}]}
{"op":"mcm","clk":"11945996564","pt":1724915519565,"mc":[{"id":"1.232283784","rc":[{"batb":[[0,1.93,38.98],[1,1.91,8.38],[2,1.74,16.76]],"ltp":2.34,"tv":2498.65,"id":35736915}]}]}
{"op":"mcm","clk":"11945996653","pt":1724915521981,"mc":[{"id":"1.232283784","rc":[{"batb":[[0,1.94,5],[1,1.93,38.98],[2,1.91,8.38]],"ltp":2.34,"tv":2498.65,"id":35736915}]}]}
{"op":"mcm","clk":"11945996793","pt":1724915525384,"mc":[{"id":"1.232283784","rc":[{"batb":[[0,1.93,38.98],[1,1.91,8.38],[2,1.74,16.76]],"ltp":2.34,"tv":2498.65,"id":35736915}]}]}
{"op":"mcm","clk":"11945996891","pt":1724915527587,"mc":[{"id":"1.232283784","rc":[{"batb":[[0,1.94,5],[1,1.93,38.98],[2,1.91,8.38]],"ltp":2.34,"tv":2498.65,"id":35736915}]}]}
{"op":"mcm","clk":"11945997011","pt":1724915530915,"mc":[{"id":"1.232283784","rc":[{"batb":[[0,1.93,38.98],[1,1.91,8.38],[2,1.74,16.76]],"ltp":2.34,"tv":2498.65,"id":35736915}]}]}
{"op":"mcm","clk":"11945997150","pt":1724915535113,"mc":[{"id":"1.232283784","rc":[{"batb":[[0,1.94,5],[1,1.93,38.98],[2,1.91,8.38]],"ltp":2.34,"tv":2498.65,"id":35736915}]}]}
{"op":"mcm","clk":"11945997242","pt":1724915538495,"mc":[{"id":"1.232283784","rc":[{"batb":[[0,1.93,38.98],[1,1.91,8.38],[2,1.74,16.76]],"ltp":2.34,"tv":2498.65,"id":35736915}]}]}
{"op":"mcm","clk":"11945997405","pt":1724915543510,"mc":[{"id":"1.232283784","rc":[{"batb":[[0,1.94,5],[1,1.93,38.98],[2,1.91,8.38]],"ltp":2.34,"tv":2498.65,"id":35736915}]}]}
{"op":"mcm","clk":"11945997503","pt":1724915546893,"mc":[{"id":"1.232283784","rc":[{"batb":[[0,1.93,38.98],[1,1.91,8.38],[2,1.74,16.76]],"ltp":2.34,"tv":2498.65,"id":35736915}]}]}
{"op":"mcm","clk":"11945997626","pt":1724915550986,"mc":[{"id":"1.232283784","rc":[{"batb":[[0,1.94,5],[1,1.93,38.98],[2,1.91,8.38]],"ltp":2.34,"tv":2498.65,"id":35736915}]}]}
{"op":"mcm","clk":"11945997711","pt":1724915554413,"mc":[{"id":"1.232283784","rc":[{"batb":[[0,1.93,38.98],[1,1.91,8.38],[2,1.74,16.76]],"ltp":2.34,"tv":2498.65,"id":35736915}]}]}
{"op":"mcm","clk":"11945997764","pt":1724915556504,"mc":[{"id":"1.232283784","rc":[{"batb":[[0,1.94,5],[1,1.93,38.98],[2,1.91,8.38]],"ltp":2.34,"tv":2498.65,"id":35736915}]}]}
{"op":"mcm","clk":"11945997880","pt":1724915559828,"mc":[{"id":"1.232283784","rc":[{"batb":[[0,1.93,38.98],[1,1.91,8.38],[2,1.74,16.76]],"ltp":2.34,"tv":2498.65,"id":35736915}]}]}
{"op":"mcm","clk":"11945997981","pt":1724915562535,"mc":[{"id":"1.232283784","rc":[{"batb":[[0,1.94,5],[1,1.93,38.98],[2,1.91,8.38]],"ltp":2.34,"tv":2498.65,"id":35736915}]}]}
{"op":"mcm","clk":"11945998073","pt":1724915565955,"mc":[{"id":"1.232283784","rc":[{"batb":[[0,1.93,38.98],[1,1.91,8.38],[2,1.74,16.76]],"ltp":2.34,"tv":2498.65,"id":35736915}]}]}
{"op":"mcm","clk":"11945998207","pt":1724915568937,"mc":[{"id":"1.232283784","rc":[{"batb":[[0,1.94,5],[1,1.93,38.98],[2,1.91,8.38]],"ltp":2.34,"tv":2498.65,"id":35736915}]}]}
{"op":"mcm","clk":"11945998309","pt":1724915572359,"mc":[{"id":"1.232283784","rc":[{"batb":[[0,1.93,38.98],[1,1.91,8.38],[2,1.74,16.76]],"ltp":2.34,"tv":2498.65,"id":35736915}]}]}
{"op":"mcm","clk":"11946008941","pt":1724915575105,"mc":[{"id":"1.232283784","rc":[{"batb":[[0,1.94,5],[1,1.93,38.98],[2,1.91,8.38]],"ltp":2.34,"tv":2498.65,"id":35736915}]}]}
{"op":"mcm","clk":"11946009077","pt":1724915578441,"mc":[{"id":"1.232283784","rc":[{"batb":[[0,1.93,38.98],[1,1.91,8.38],[2,1.74,16.76]],"ltp":2.34,"tv":2498.65,"id":35736915}]}]}
{"op":"mcm","clk":"11946009154","pt":1724915580945,"mc":[{"id":"1.232283784","rc":[{"batb":[[0,1.94,5],[1,1.93,38.98],[2,1.91,8.38]],"ltp":2.34,"tv":2498.65,"id":35736915}]}]}
{"op":"mcm","clk":"11946009293","pt":1724915584273,"mc":[{"id":"1.232283784","rc":[{"batb":[[0,1.93,38.98],[1,1.91,8.38],[2,1.74,16.76]],"ltp":2.34,"tv":2498.65,"id":35736915}]}]}
{"op":"mcm","clk":"11946009473","pt":1724915588742,"mc":[{"id":"1.232283784","rc":[{"batb":[[0,2,5],[1,1.99,36.96],[2,1.93,38.98]],"ltp":2.34,"tv":2498.65,"id":35736915}]}]}
{"op":"mcm","clk":"11946009604","pt":1724915591956,"mc":[{"id":"1.232283784","rc":[{"batb":[[0,1.99,36.96],[1,1.93,38.98],[2,1.91,8.38]],"ltp":2.34,"tv":2498.65,"id":35736915}]}]}
{"op":"mcm","clk":"11946009723","pt":1724915595866,"mc":[{"id":"1.232283784","rc":[{"batb":[[0,2.02,36.96]],"ltp":2.34,"tv":2498.65,"id":35736915}]}]}
{"op":"mcm","clk":"11946009736","pt":1724915596377,"mc":[{"id":"1.232283784","rc":[{"batb":[[1,1.94,5],[2,1.93,38.98]],"ltp":2.34,"tv":2498.65,"id":35736915}]}]}
{"op":"mcm","clk":"11946009850","pt":1724915599856,"mc":[{"id":"1.232283784","rc":[{"batb":[[1,1.93,38.98],[2,1.91,8.38]],"ltp":2.34,"tv":2498.65,"id":35736915}]}]}
{"op":"mcm","clk":"11946009853","pt":1724915599960,"mc":[{"id":"1.232283784","rc":[{"batb":[[0,2.04,6.65],[1,2.02,36.96],[2,1.93,38.98]],"ltp":2.34,"tv":2498.65,"id":35736915}]}]}
{"op":"mcm","clk":"11946010032","pt":1724915606099,"mc":[{"id":"1.232283784","rc":[{"batb":[[0,2.06,5],[1,2.04,6.65],[2,2.02,36.96]],"ltp":2.34,"tv":2498.65,"id":35736915}]}]}
{"op":"mcm","clk":"11946010124","pt":1724915609164,"mc":[{"id":"1.232283784","rc":[{"batb":[[0,2.04,6.65],[1,2.02,36.96],[2,1.91,8.38]],"ltp":2.34,"tv":2498.65,"id":35736915}]}]}
{"op":"mcm","clk":"11946010192","pt":1724915611772,"mc":[{"id":"1.232283784","rc":[{"batb":[[0,2.06,5],[1,2.04,6.65],[2,2.02,36.96]],"ltp":2.34,"tv":2498.65,"id":35736915}]}]}
{"op":"mcm","clk":"11946010304","pt":1724915615074,"mc":[{"id":"1.232283784","rc":[{"batb":[[0,2.04,6.65],[1,2.02,36.96],[2,1.91,8.38]],"ltp":2.34,"tv":2498.65,"id":35736915}]}]}
{"op":"mcm","clk":"11946010417","pt":1724915617701,"mc":[{"id":"1.232283784","rc":[{"batb":[[0,2.06,5],[1,2.04,6.65],[2,2.02,36.96]],"ltp":2.34,"tv":2498.65,"id":35736915}]}]}
{"op":"mcm","clk":"11946010535","pt":1724915620984,"mc":[{"id":"1.232283784","rc":[{"batb":[[0,2.04,6.65],[1,2.02,36.96],[2,1.91,8.38]],"ltp":2.34,"tv":2498.65,"id":35736915}]}]}
{"op":"mcm","clk":"11946010690","pt":1724915624715,"mc":[{"id":"1.232283784","rc":[{"batb":[[1,1.91,8.38],[2,1.74,16.76]],"ltp":2.34,"tv":2498.65,"id":35736915}]}]}
{"op":"mcm","clk":"11946010708","pt":1724915625119,"mc":[{"id":"1.232283784","rc":[{"batb":[[0,2.06,5],[1,2.04,6.65],[2,1.91,8.38]],"ltp":2.34,"tv":2498.65,"id":35736915}]}]}
{"op":"mcm","clk":"11946010842","pt":1724915628307,"mc":[{"id":"1.232283784","rc":[{"batb":[[0,2.04,6.65],[1,1.91,8.38],[2,1.74,16.76]],"ltp":2.34,"tv":2498.65,"id":35736915}]}]}
{"op":"mcm","clk":"11946011041","pt":1724915632522,"mc":[{"id":"1.232283784","rc":[{"batb":[[0,2.06,5],[1,2.04,6.65],[2,1.91,8.38]],"ltp":2.34,"tv":2498.65,"id":35736915}]}]}
{"op":"mcm","clk":"11946011153","pt":1724915635902,"mc":[{"id":"1.232283784","rc":[{"batb":[[0,2.04,6.65],[1,1.91,8.38],[2,1.74,16.76]],"ltp":2.34,"tv":2498.65,"id":35736915}]}]}
{"op":"mcm","clk":"11946011239","pt":1724915639333,"mc":[{"id":"1.232283784","rc":[{"batb":[[0,2.06,5],[1,2.04,6.65],[2,1.91,8.38]],"ltp":2.34,"tv":2498.65,"id":35736915}]}]}
{"op":"mcm","clk":"11946011413","pt":1724915642631,"mc":[{"id":"1.232283784","rc":[{"batb":[[0,2.04,6.65],[1,1.91,8.38],[2,1.74,16.76]],"ltp":2.34,"tv":2498.65,"id":35736915}]}]}
{"op":"mcm","clk":"11946011509","pt":1724915644938,"mc":[{"id":"1.232283784","rc":[{"batb":[[0,2.06,5],[1,2.04,6.65],[2,1.91,8.38]],"ltp":2.34,"tv":2498.65,"id":35736915}]}]}
{"op":"mcm","clk":"11946011656","pt":1724915648214,"mc":[{"id":"1.232283784","rc":[{"batb":[[0,2.04,6.65],[1,1.91,8.38],[2,1.74,16.76]],"ltp":2.34,"tv":2498.65,"id":35736915}]}]}
{"op":"mcm","clk":"11946011830","pt":1724915652843,"mc":[{"id":"1.232283784","rc":[{"batb":[[0,2.06,5],[1,2.04,6.65],[2,1.91,8.38]],"ltp":2.34,"tv":2498.65,"id":35736915}]}]}
{"op":"mcm","clk":"11946011945","pt":1724915656228,"mc":[{"id":"1.232283784","rc":[{"batb":[[0,2.04,6.65],[1,1.91,8.38],[2,1.74,16.76]],"ltp":2.34,"tv":2498.65,"id":35736915}]}]}
{"op":"mcm","clk":"11946012039","pt":1724915658837,"mc":[{"id":"1.232283784","rc":[{"batb":[[0,2.06,5],[1,2.04,6.65],[2,1.91,8.38]],"ltp":2.34,"tv":2498.65,"id":35736915}]}]}
{"op":"mcm","clk":"11946012130","pt":1724915662264,"mc":[{"id":"1.232283784","rc":[{"batb":[[0,2.04,6.65],[1,1.91,8.38],[2,1.74,16.76]],"ltp":2.34,"tv":2498.65,"id":35736915}]}]}
{"op":"mcm","clk":"11946012225","pt":1724915664526,"mc":[{"id":"1.232283784","rc":[{"batb":[[0,2.06,5],[1,2.04,6.65],[2,1.91,8.38]],"ltp":2.34,"tv":2498.65,"id":35736915}]}]}
{"op":"mcm","clk":"11946012334","pt":1724915667854,"mc":[{"id":"1.232283784","rc":[{"batb":[[0,2.04,6.65],[1,1.91,8.38],[2,1.74,16.76]],"ltp":2.34,"tv":2498.65,"id":35736915}]}]}
{"op":"mcm","clk":"11946012433","pt":1724915671079,"mc":[{"id":"1.232283784","rc":[{"batb":[[0,2.06,5],[1,2.04,6.65],[2,1.91,8.38]],"ltp":2.34,"tv":2498.65,"id":35736915}]}]}
{"op":"mcm","clk":"11946012533","pt":1724915674355,"mc":[{"id":"1.232283784","rc":[{"batb":[[0,2.04,6.65],[1,1.91,8.38],[2,1.74,16.76]],"ltp":2.34,"tv":2498.65,"id":35736915}]}]}
{"op":"mcm","clk":"11946012677","pt":1724915678207,"mc":[{"id":"1.232283784","rc":[{"batb":[[0,2.06,5],[1,2.04,6.65],[2,1.91,8.38]],"ltp":2.34,"tv":2498.65,"id":35736915}]}]}
{"op":"mcm","clk":"11946012810","pt":1724915681446,"mc":[{"id":"1.232283784","rc":[{"batb":[[0,2.04,6.65],[1,1.91,8.38],[2,1.74,16.76]],"ltp":2.34,"tv":2498.65,"id":35736915}]}]}
{"op":"mcm","clk":"11946012913","pt":1724915684169,"mc":[{"id":"1.232283784","rc":[{"batb":[[0,2.06,5],[1,2.04,6.65],[2,1.91,8.38]],"ltp":2.34,"tv":2498.65,"id":35736915}]}]}
{"op":"mcm","clk":"11946013041","pt":1724915687662,"mc":[{"id":"1.232283784","rc":[{"batb":[[0,2.04,6.65],[1,1.91,8.38],[2,1.74,16.76]],"ltp":2.34,"tv":2498.65,"id":35736915}]}]}
{"op":"mcm","clk":"11946013154","pt":1724915690394,"mc":[{"id":"1.232283784","rc":[{"batb":[[0,2.06,5],[1,2.04,6.65],[2,1.91,8.38]],"ltp":2.34,"tv":2498.65,"id":35736915}]}]}
{"op":"mcm","clk":"11946013193","pt":1724915691273,"mc":[{"id":"1.232283784","rc":[{"batl":[[0,1.94,5.02]],"ltp":2.0,"tv":2033.36,"id":11445382}]}]}
{"op":"mcm","clk":"11946013291","pt":1724915693696,"mc":[{"id":"1.232283784","rc":[{"batb":[[0,2.04,6.65],[1,1.91,8.38],[2,1.74,16.76]],"ltp":2.34,"tv":2498.65,"id":35736915}]}]}
{"op":"mcm","clk":"11946013402","pt":1724915696074,"mc":[{"id":"1.232283784","rc":[{"batb":[[0,2.06,5],[1,2.04,6.65],[2,1.91,8.38]],"ltp":2.34,"tv":2498.65,"id":35736915}]}]}
{"op":"mcm","clk":"11946013498","pt":1724915699467,"mc":[{"id":"1.232283784","rc":[{"batb":[[0,2.04,6.65],[1,1.91,8.38],[2,1.74,16.76]],"ltp":2.34,"tv":2498.65,"id":35736915}]}]}
{"op":"mcm","clk":"11946013589","pt":1724915702013,"mc":[{"id":"1.232283784","rc":[{"batb":[[0,2.06,5],[1,2.04,6.65],[2,1.91,8.38]],"ltp":2.34,"tv":2498.65,"id":35736915}]}]}
{"op":"mcm","clk":"11946013729","pt":1724915705410,"mc":[{"id":"1.232283784","rc":[{"batb":[[0,2.04,6.65],[1,1.91,8.38],[2,1.74,16.76]],"ltp":2.34,"tv":2498.65,"id":35736915}]}]}
{"op":"mcm","clk":"11946013830","pt":1724915707980,"mc":[{"id":"1.232283784","rc":[{"batb":[[0,2.06,5],[1,2.04,6.65],[2,1.91,8.38]],"ltp":2.34,"tv":2498.65,"id":35736915}]}]}
{"op":"mcm","clk":"11946013970","pt":1724915711418,"mc":[{"id":"1.232283784","rc":[{"batb":[[0,2.04,6.65],[1,1.91,8.38],[2,1.74,16.76]],"ltp":2.34,"tv":2498.65,"id":35736915}]}]}
{"op":"mcm","clk":"11946014130","pt":1724915715110,"mc":[{"id":"1.232283784","rc":[{"batb":[[0,2.06,5],[1,2.04,6.65],[2,1.91,8.38]],"ltp":2.34,"tv":2498.65,"id":35736915}]}]}
{"op":"mcm","clk":"11946014262","pt":1724915718496,"mc":[{"id":"1.232283784","rc":[{"batb":[[0,2.04,6.65],[1,1.91,8.38],[2,1.74,16.76]],"ltp":2.34,"tv":2498.65,"id":35736915}]}]}
{"op":"mcm","clk":"11946014443","pt":1724915723518,"mc":[{"id":"1.232283784","rc":[{"batb":[[0,2.06,5],[1,2.04,6.65],[2,1.91,8.38]],"ltp":2.34,"tv":2498.65,"id":35736915}]}]}
{"op":"mcm","clk":"11946014549","pt":1724915727007,"mc":[{"id":"1.232283784","rc":[{"batb":[[0,2.04,6.65],[1,1.91,8.38],[2,1.74,16.76]],"ltp":2.34,"tv":2498.65,"id":35736915}]}]}
{"op":"mcm","clk":"11946014634","pt":1724915729422,"mc":[{"id":"1.232283784","rc":[{"batb":[[0,2.06,5],[1,2.04,6.65],[2,1.91,8.38]],"ltp":2.34,"tv":2498.65,"id":35736915}]}]}
{"op":"mcm","clk":"11946014743","pt":1724915732926,"mc":[{"id":"1.232283784","rc":[{"batb":[[0,2.04,6.65],[1,1.91,8.38],[2,1.74,16.76]],"ltp":2.34,"tv":2498.65,"id":35736915}]}]}
{"op":"mcm","clk":"11946014837","pt":1724915735332,"mc":[{"id":"1.232283784","rc":[{"batb":[[0,2.06,5],[1,2.04,6.65],[2,1.91,8.38]],"ltp":2.34,"tv":2498.65,"id":35736915}]}]}
{"op":"mcm","clk":"11946014982","pt":1724915738626,"mc":[{"id":"1.232283784","rc":[{"batb":[[0,2.04,6.65],[1,1.91,8.38],[2,1.74,16.76]],"ltp":2.34,"tv":2498.65,"id":35736915}]}]}
{"op":"mcm","clk":"11946015194","pt":1724915743252,"mc":[{"id":"1.232283784","rc":[{"batb":[[0,2.06,5],[1,2.04,6.65],[2,1.91,8.38]],"ltp":2.34,"tv":2498.65,"id":35736915}]}]}
{"op":"mcm","clk":"11946015349","pt":1724915746662,"mc":[{"id":"1.232283784","rc":[{"batb":[[0,2.04,6.65],[1,1.91,8.38],[2,1.74,16.76]],"ltp":2.34,"tv":2498.65,"id":35736915}]}]}
{"op":"mcm","clk":"11946015551","pt":1724915752138,"mc":[{"id":"1.232283784","rc":[{"batb":[[0,2.06,5],[1,2.04,6.65],[2,1.91,8.38]],"ltp":2.34,"tv":2498.65,"id":35736915}]}]}
{"op":"mcm","clk":"11946015698","pt":1724915755430,"mc":[{"id":"1.232283784","rc":[{"batb":[[0,2.04,6.65],[1,1.91,8.38],[2,1.74,16.76]],"ltp":2.34,"tv":2498.65,"id":35736915}]}]}
{"op":"mcm","clk":"11946015830","pt":1724915759350,"mc":[{"id":"1.232283784","rc":[{"batb":[[0,2.06,5],[1,2.04,6.65],[2,1.91,8.38]],"ltp":2.34,"tv":2498.65,"id":35736915}]}]}
{"op":"mcm","clk":"11946015961","pt":1724915762873,"mc":[{"id":"1.232283784","rc":[{"batb":[[0,2.04,6.65],[1,1.91,8.38],[2,1.74,16.76]],"ltp":2.34,"tv":2498.65,"id":35736915}]}]}
{"op":"mcm","clk":"11946016067","pt":1724915765481,"mc":[{"id":"1.232283784","rc":[{"batb":[[0,2.06,5],[1,2.04,6.65],[2,1.91,8.38]],"ltp":2.34,"tv":2498.65,"id":35736915}]}]}
{"op":"mcm","clk":"11946016185","pt":1724915768668,"mc":[{"id":"1.232283784","rc":[{"batb":[[0,2.04,6.65],[1,1.91,8.38],[2,1.74,16.76]],"ltp":2.34,"tv":2498.65,"id":35736915}]}]}
{"op":"mcm","clk":"11946016365","pt":1724915772380,"mc":[{"id":"1.232283784","rc":[{"batb":[[0,2.06,5],[1,2.04,6.65],[2,1.91,8.38]],"ltp":2.34,"tv":2498.65,"id":35736915}]}]}
{"op":"mcm","clk":"11946016501","pt":1724915775780,"mc":[{"id":"1.232283784","rc":[{"batb":[[0,2.04,6.65],[1,1.91,8.38],[2,1.74,16.76]],"ltp":2.34,"tv":2498.65,"id":35736915}]}]}
{"op":"mcm","clk":"11946016604","pt":1724915778285,"mc":[{"id":"1.232283784","rc":[{"batb":[[0,2.06,5],[1,2.04,6.65],[2,1.91,8.38]],"ltp":2.34,"tv":2498.65,"id":35736915}]}]}
{"op":"mcm","clk":"11946016735","pt":1724915781708,"mc":[{"id":"1.232283784","rc":[{"batb":[[0,2.04,6.65],[1,1.91,8.38],[2,1.74,16.76]],"ltp":2.34,"tv":2498.65,"id":35736915}]}]}
{"op":"mcm","clk":"11946016822","pt":1724915783990,"mc":[{"id":"1.232283784","rc":[{"batb":[[0,2.06,5],[1,2.04,6.65],[2,1.91,8.38]],"ltp":2.34,"tv":2498.65,"id":35736915}]}]}
{"op":"mcm","clk":"11946016953","pt":1724915787525,"mc":[{"id":"1.232283784","rc":[{"batb":[[0,2.04,6.65],[1,1.91,8.38],[2,1.74,16.76]],"ltp":2.34,"tv":2498.65,"id":35736915}]}]}
{"op":"mcm","clk":"11946017021","pt":1724915789924,"mc":[{"id":"1.232283784","rc":[{"batb":[[0,2.06,5],[1,2.04,6.65],[2,1.91,8.38]],"ltp":2.34,"tv":2498.65,"id":35736915}]}]}
{"op":"mcm","clk":"11946017125","pt":1724915793306,"mc":[{"id":"1.232283784","rc":[{"batb":[[0,2.04,6.65],[1,1.91,8.38],[2,1.74,16.76]],"ltp":2.34,"tv":2498.65,"id":35736915}]}]}
{"op":"mcm","clk":"11946017377","pt":1724915799609,"mc":[{"id":"1.232283784","rc":[{"batb":[[0,2.06,5],[1,2.04,6.65],[2,1.91,8.38]],"ltp":2.34,"tv":2498.65,"id":35736915}]}]}
{"op":"mcm","clk":"11946017457","pt":1724915803031,"mc":[{"id":"1.232283784","rc":[{"batb":[[0,2.04,6.65],[1,1.91,8.38],[2,1.74,16.76]],"ltp":2.34,"tv":2498.65,"id":35736915}]}]}
{"op":"mcm","clk":"11946017512","pt":1724915804422,"mc":[{"id":"1.232283784","rc":[{"batb":[[0,2.24,31.14],[1,2.04,6.65],[2,1.91,8.38]],"ltp":2.34,"tv":2498.65,"id":35736915},{"batb":[[0,1.73,52.9]],"ltp":2.0,"tv":2033.36,"id":11445382}]}]}
{"op":"mcm","clk":"11946017590","pt":1724915806727,"mc":[{"id":"1.232283784","rc":[{"batb":[[0,2.26,5],[1,2.24,31.14],[2,2.04,6.65]],"ltp":2.34,"tv":2498.65,"id":35736915}]}]}
{"op":"mcm","clk":"11946017692","pt":1724915810207,"mc":[{"id":"1.232283784","rc":[{"batb":[[0,2.24,31.14],[1,2.04,6.65],[2,1.91,8.38]],"ltp":2.34,"tv":2498.65,"id":35736915}]}]}
{"op":"mcm","clk":"11946017771","pt":1724915813127,"mc":[{"id":"1.232283784","rc":[{"batb":[[0,2.26,5],[1,2.24,31.14],[2,2.04,6.65]],"ltp":2.34,"tv":2498.65,"id":35736915}]}]}
{"op":"mcm","clk":"11946017852","pt":1724915815749,"mc":[{"id":"1.232283784","rc":[{"batb":[[0,2.26,9]],"batl":[[0,2.34,16.29]],"ltp":2.34,"tv":2498.65,"id":35736915},{"batb":[[0,1.75,4],[1,1.74,4],[2,1.73,52.9]],"batl":[[0,1.8,4],[1,1.94,5.02]],"ltp":2.0,"tv":2033.36,"id":11445382}]}]}
{"op":"mcm","clk":"11946017882","pt":1724915816522,"mc":[{"id":"1.232283784","rc":[{"batb":[[0,2.26,4]],"ltp":2.34,"tv":2498.65,"id":35736915}]}]}
{"op":"mcm","clk":"11946018057","pt":1724915821543,"mc":[{"id":"1.232283784","rc":[{"batl":[[1,1.94,0]],"ltp":2.0,"tv":2033.36,"id":11445382}]}]}
{"op":"mcm","clk":"11946020001","pt":1724915878792,"mc":[{"id":"1.232283784","rc":[{"batl":[[0,1.79,2],[1,1.8,4]],"ltp":2.0,"tv":2033.36,"id":11445382}]}]}
{"op":"mcm","clk":"11946020864","pt":1724915906351,"mc":[{"id":"1.232283784","rc":[{"batl":[[0,1.79,6]],"ltp":2.0,"tv":2033.36,"id":11445382}]}]}
{"op":"mcm","clk":"11946035854","pt":1724916272032,"mc":[{"id":"1.232283784","rc":[{"trd":[[1.79,61.62]],"batb":[[0,1.79,10.76],[1,1.75,4],[2,1.74,4]],"batl":[[0,1.8,4],[1,1.8,0]],"ltp":1.79,"tv":2045.36,"id":11445382}],"tv":4544.01}]}
{"op":"mcm","clk":"11946036409","pt":1724916284637,"mc":[{"id":"1.232283784","rc":[{"batb":[[0,1.79,14.76]],"ltp":1.79,"tv":2045.36,"id":11445382}]}]}
{"op":"mcm","clk":"11946036985","pt":1724916299885,"mc":[{"id":"1.232283784","rc":[{"batl":[[0,2.28,4],[1,2.34,16.29],[2,2.38,50]],"ltp":2.34,"tv":2498.65,"id":35736915}]}]}
{"op":"mcm","clk":"11946043019","pt":1724916478888,"mc":[{"id":"1.232283784","rc":[{"batb":[[1,1.76,2.03],[2,1.75,4]],"ltp":1.79,"tv":2045.36,"id":11445382}]}]}
{"op":"mcm","clk":"11946047638","pt":1724916639261,"mc":[{"id":"1.232283784","rc":[{"batb":[[0,1.79,4]],"ltp":1.79,"tv":2045.36,"id":11445382}]}]}
{"op":"mcm","clk":"11946047666","pt":1724916639928,"mc":[{"id":"1.232283784","rc":[{"batl":[[0,2.34,16.29],[1,2.38,50],[2,2.42,50]],"ltp":2.34,"tv":2498.65,"id":35736915},{"batb":[[0,1.76,2.03],[1,1.73,52.9],[2,1.4,7]],"ltp":1.79,"tv":2045.36,"id":11445382}]}]}
{"op":"mcm","clk":"11946047960","pt":1724916648737,"mc":[{"id":"1.232283784","rc":[{"batl":[[0,2.32,4],[1,2.34,16.29],[2,2.38,50]],"ltp":2.34,"tv":2498.65,"id":35736915}]}]}
{"op":"mcm","clk":"11946116924","pt":1724918382677,"mc":[{"id":"1.232283784","rc":[{"batb":[[2,1.74,16.76]],"ltp":2.34,"tv":2498.65,"id":35736915}]}]}
{"op":"mcm","clk":"11946170805","pt":1724919601756,"mc":[{"id":"1.232283784","rc":[{"trd":[[2,152.23],[2.04,99.98],[2.1,766.83]],"ltp":2.34,"tv":2498.6,"id":35736915},{"trd":[[1.62,129.64],[1.76,288.01],[1.78,64.07],[1.79,61.63],[1.81,25.31],[1.84,59.27],[1.87,57.24],[1.89,40.51],[1.9,398.52],[1.91,574.26],[2,60.37],[2.02,111.58],[2.04,97.87],[2.06,46.82]],"batb":[[2,1.27,1.8]],"ltp":1.79,"tv":2045.41,"id":11445382}],"tv":4544.01}]}
{"op":"mcm","clk":"11946171006","pt":1724919605790,"mc":[{"id":"1.232283784","rc":[{"batb":[[2,1.2,1000.88]],"ltp":1.79,"tv":2045.41,"id":11445382}]}]}
{"op":"mcm","clk":"11946247979","pt":1724921214824,"mc":[{"id":"1.232283784","rc":[{"trd":[[1.76,291.71]],"batb":[[0,1.73,53.08],[1,1.2,1000.88],[2,1.04,1.05]],"ltp":1.76,"tv":2049.11,"id":11445382}],"tv":4547.71}]}
{"op":"mcm","clk":"11946248016","pt":1724921215648,"mc":[{"id":"1.232283784","rc":[{"batb":[[0,1.75,4.18],[1,1.73,52.9],[2,1.2,1000.88]],"ltp":1.76,"tv":2049.11,"id":11445382}]}]}
{"op":"mcm","clk":"11946248561","pt":1724921229057,"mc":[{"id":"1.232283784","rc":[{"batb":[[0,1.75,42.3]],"ltp":1.76,"tv":2049.11,"id":11445382}]}]}
{"op":"mcm","clk":"11946248631","pt":1724921230855,"mc":[{"id":"1.232283784","rc":[{"batb":[[0,1.76,4.18],[1,1.75,42.12],[2,1.73,52.9]],"ltp":1.76,"tv":2049.11,"id":11445382}]}]}
{"op":"mcm","clk":"11946248942","pt":1724921239182,"mc":[{"id":"1.232283784","rc":[{"trd":[[1.76,300.07]],"batb":[[0,1.75,42.12],[1,1.73,52.9],[2,1.2,1000.88]],"batl":[[0,1.8,4.01]],"ltp":1.76,"tv":2057.47,"id":11445382}],"tv":4556.07}]}
{"op":"mcm","clk":"11946249244","pt":1724921246081,"mc":[{"id":"1.232283784","rc":[{"trd":[[1.76,300.09]],"batb":[[0,1.76,3.99],[1,1.75,42.12],[2,1.73,52.9]],"batl":[[0,1.8,4]],"ltp":1.76,"tv":2057.49,"id":11445382}],"tv":4556.09}]}
{"op":"mcm","clk":"11946250441","pt":1724921277321,"mc":[{"id":"1.232283784","rc":[{"batb":[[0,1.75,4],[1,1.73,52.9],[2,1.2,1000.88]],"ltp":1.76,"tv":2057.49,"id":11445382}]}]}
{"op":"mcm","clk":"11946252433","pt":1724921327640,"mc":[{"id":"1.232283784","rc":[{"batb":[[0,1.75,42.12]],"ltp":1.76,"tv":2057.49,"id":11445382}]}]}
{"op":"mcm","clk":"11946253521","pt":1724921353365,"mc":[{"id":"1.232283784","rc":[{"trd":[[2.26,64.2]],"batb":[[0,2.24,31.65],[1,1.74,16.76],[2,1.7,5.27]],"ltp":2.26,"tv":2502.09,"id":35736915},{"trd":[[1.8,12.38]],"ltp":1.8,"tv":2069.87,"id":11445382}],"tv":4571.96}]}
{"op":"mcm","clk":"11946254023","pt":1724921366906,"mc":[{"id":"1.232283784","rc":[{"batb":[[0,2.24,35.65]],"ltp":2.26,"tv":2502.09,"id":35736915},{"batb":[[0,1.76,4],[1,1.75,42.12],[2,1.73,52.9]],"batl":[[0,1.81,4]],"ltp":1.8,"tv":2069.87,"id":11445382}]}]}
{"op":"mcm","clk":"11946254409","pt":1724921377822,"mc":[{"id":"1.232283784","rc":[{"batb":[[0,2.26,30.39],[1,2.24,35.14],[2,1.74,16.76]],"ltp":2.26,"tv":2502.09,"id":35736915},{"batb":[[1,1.75,4]],"ltp":1.8,"tv":2069.87,"id":11445382}]}]}
{"op":"mcm","clk":"11946254417","pt":1724921378027,"mc":[{"id":"1.232283784","rc":[{"batb":[[0,1.75,4],[1,1.73,52.9],[2,1.2,1000.88]],"ltp":1.8,"tv":2069.87,"id":11445382}]}]}
{"op":"mcm","clk":"11946254589","pt":1724921382002,"mc":[{"id":"1.232283784","rc":[{"batl":[[0,1.8,4],[1,1.81,4]],"ltp":1.8,"tv":2069.87,"id":11445382}]}]}
{"op":"mcm","clk":"11946255446","pt":1724921402145,"mc":[{"id":"1.232283784","rc":[{"batb":[[0,1.76,16.76],[1,1.75,4],[2,1.73,52.9]],"ltp":1.8,"tv":2069.87,"id":11445382}]}]}
{"op":"mcm","clk":"11946255959","pt":1724921412323,"mc":[{"id":"1.232283784","rc":[{"batb":[[0,1.76,20.76]],"ltp":1.8,"tv":2069.87,"id":11445382}]}]}
{"op":"mcm","clk":"11946256526","pt":1724921426134,"mc":[{"id":"1.232283784","rc":[{"batb":[[0,1.76,58.88]],"ltp":1.8,"tv":2069.87,"id":11445382}]}]}
{"op":"mcm","clk":"11946256598","pt":1724921427471,"mc":[{"id":"1.232283784","rc":[{"batb":[[0,1.77,4],[1,1.76,58.88],[2,1.75,4]],"ltp":1.8,"tv":2069.87,"id":11445382}]}]}
{"op":"mcm","clk":"11946256721","pt":1724921430158,"mc":[{"id":"1.232283784","rc":[{"batb":[[1,1.76,42.12]],"ltp":1.8,"tv":2069.87,"id":11445382}]}]}
{"op":"mcm","clk":"11946257197","pt":1724921442587,"mc":[{"id":"1.232283784","rc":[{"batl":[[0,2.3,4],[1,2.32,4],[2,2.34,16.29]],"ltp":2.26,"tv":2502.09,"id":35736915}]}]}
{"op":"mcm","clk":"11946258356","pt":1724921468782,"mc":[{"id":"1.232283784","rc":[{"trd":[[1.76,325.61],[1.77,9.12]],"batb":[[0,1.76,29.36],[1,1.75,4],[2,1.73,52.9]],"ltp":1.76,"tv":2103.38,"id":11445382}],"tv":4605.48}]}
{"op":"mcm","clk":"11946258552","pt":1724921472770,"mc":[{"id":"1.232283784","rc":[{"batb":[[0,1.76,33.36]],"batl":[[0,1.79,4],[1,1.8,4],[2,1.81,4]],"ltp":1.76,"tv":2103.38,"id":11445382}]}]}
{"op":"mcm","clk":"11946258710","pt":1724921476463,"mc":[{"id":"1.232283784","rc":[{"batb":[[0,1.76,4]],"ltp":1.76,"tv":2103.38,"id":11445382}]}]}
{"op":"mcm","clk":"11946258730","pt":1724921476872,"mc":[{"id":"1.232283784","rc":[{"batl":[[0,2.32,4],[1,2.34,16.29],[2,2.38,50]],"ltp":2.26,"tv":2502.09,"id":35736915},{"batb":[[0,1.75,4],[1,1.73,52.9],[2,1.2,1000.88]],"ltp":1.76,"tv":2103.38,"id":11445382}]}]}
{"op":"mcm","clk":"11946260575","pt":1724921525809,"mc":[{"id":"1.232283784","rc":[{"batb":[[0,1.75,33.36]],"ltp":1.76,"tv":2103.38,"id":11445382}]}]}
{"op":"mcm","clk":"11946293155","pt":1724922182098,"mc":[{"id":"1.232283784","rc":[{"trd":[[2,152.29],[2.04,100.07],[2.06,99.93],[2.08,99.9],[2.1,767.41],[2.32,8]],"batb":[[0,2.26,30.44]],"batl":[[0,2.34,16.29],[1,2.38,50],[2,2.42,50]],"ltp":2.32,"tv":2510.69,"id":35736915},{"trd":[[1.62,129.75],[1.64,1.76],[1.66,12.27],[1.7,13.01],[1.76,326.08],[1.78,64.17],[1.79,61.71],[1.81,25.34],[1.84,59.36],[1.87,57.33],[1.89,40.57],[1.9,398.84],[1.91,574.54],[2,60.52],[2.02,111.86],[2.04,98.12],[2.06,46.94],[2.08,2.18]],"batb":[[0,1.75,33.41],[2,1.2,1000.88]],"ltp":1.76,"tv":2105.84,"id":11445382}],"tv":4616.54}]}
{"op":"mcm","clk":"11946295242","pt":1724922223227,"mc":[{"id":"1.232283784","rc":[{"trd":[[2.34,96.22]],"batl":[[0,2.34,5.89]],"ltp":2.34,"tv":2531.49,"id":35736915}],"tv":4637.34}]}
{"op":"mcm","clk":"11946295547","pt":1724922229349,"mc":[{"id":"1.232283784","rc":[{"batb":[[0,2.28,4],[1,2.26,30.44],[2,2.24,35.14]],"ltp":2.34,"tv":2531.49,"id":35736915}]}]}
{"op":"mcm","clk":"11946296979","pt":1724922253705,"mc":[{"id":"1.232283784","rc":[{"batb":[[0,2.24,35.65],[1,1.74,16.76],[2,1.7,5.29]],"batl":[[0,2.34,1.89]],"ltp":2.34,"tv":2531.49,"id":35736915},{"batb":[[0,1.73,52.9],[1,1.2,1000.88],[2,1.04,1.05]],"batl":[[0,1.8,4],[1,1.81,4],[2,1.81,0]],"ltp":1.76,"tv":2105.84,"id":11445382}]}]}
{"op":"mcm","clk":"11946296986","pt":1724922253909,"mc":[{"id":"1.232283784","rc":[{"batb":[[0,2.26,5.51],[1,2.24,35.14],[2,1.74,16.76]],"ltp":2.34,"tv":2531.49,"id":35736915}]}]}
{"op":"mcm","clk":"11946297189","pt":1724922257207,"mc":[{"id":"1.232283784","rc":[{"batb":[[0,2.24,35.65],[1,1.74,16.76],[2,1.7,5.29]],"ltp":2.34,"tv":2531.49,"id":35736915}]}]}
{"op":"mcm","clk":"11946297320","pt":1724922259625,"mc":[{"id":"1.232283784","rc":[{"batb":[[0,2.26,4.51],[1,2.24,35.14],[2,1.74,16.76]],"ltp":2.34,"tv":2531.49,"id":35736915},{"batb":[[0,1.74,4],[1,1.73,52.9],[2,1.2,1000.88]],"ltp":1.76,"tv":2105.84,"id":11445382}]}]}
{"op":"mcm","clk":"11946298708","pt":1724922284829,"mc":[{"id":"1.232283784","rc":[{"batl":[[1,2.36,7.01],[2,2.38,50]],"ltp":2.34,"tv":2531.49,"id":35736915}]}]}
{"op":"mcm","clk":"11946299002","pt":1724922289942,"mc":[{"id":"1.232283784","rc":[{"batl":[[0,2.34,5.89]],"ltp":2.34,"tv":2531.49,"id":35736915}]}]}
{"op":"mcm","clk":"11946299100","pt":1724922291577,"mc":[{"id":"1.232283784","rc":[{"batb":[[0,1.74,8.69]],"ltp":1.76,"tv":2105.84,"id":11445382}]}]}
{"op":"mcm","clk":"11946300787","pt":1724922321087,"mc":[{"id":"1.232283784","rc":[{"batb":[[0,2.26,34.44]],"ltp":2.34,"tv":2531.49,"id":35736915},{"batb":[[0,1.74,38.62]],"ltp":1.76,"tv":2105.84,"id":11445382}]}]}
{"op":"mcm","clk":"11946301547","pt":1724922335307,"mc":[{"id":"1.232283784","rc":[{"batl":[[0,1.79,4],[1,1.8,4],[2,1.81,4]],"ltp":1.76,"tv":2105.84,"id":11445382}]}]}
{"op":"mcm","clk":"11946304688","pt":1724922408060,"mc":[{"id":"1.232283784","rc":[{"trd":[[1.79,69.71]],"batb":[[0,1.79,196],[1,1.74,38.62],[2,1.73,52.9]],"batl":[[0,1.8,4],[1,1.81,4],[2,1.81,0]],"ltp":1.79,"tv":2113.84,"id":11445382}],"tv":4645.34}]}
{"op":"mcm","clk":"11946304763","pt":1724922409597,"mc":[{"id":"1.232283784","rc":[{"batb":[[0,2.26,29.93],[1,1.74,16.76],[2,1.7,5.29]],"batl":[[1,2.38,50],[2,2.42,50]],"ltp":2.34,"tv":2531.49,"id":35736915},{"batb":[[1,1.74,33.93],[2,1.2,1000.88]],"ltp":1.79,"tv":2113.84,"id":11445382}]}]}
{"op":"mcm","clk":"11946304818","pt":1724922410780,"mc":[{"id":"1.232283784","rc":[{"batl":[[0,2.28,4],[1,2.34,5.89],[2,2.38,50]],"ltp":2.34,"tv":2531.49,"id":35736915},{"batb":[[0,1.79,200]],"ltp":1.79,"tv":2113.84,"id":11445382}]}]}
{"op":"mcm","clk":"11946304844","pt":1724922411397,"mc":[{"id":"1.232283784","rc":[{"batb":[[0,1.75,116.37]],"ltp":2.34,"tv":2531.49,"id":35736915},{"batb":[[0,1.8,200],[1,1.79,200],[2,1.74,4]],"ltp":1.79,"tv":2113.84,"id":11445382}]}]}
{"op":"mcm","clk":"11946304995","pt":1724922414481,"mc":[{"id":"1.232283784","rc":[{"batb":[[0,2.24,31.14],[1,1.75,111.37],[2,1.74,16.76]],"ltp":2.34,"tv":2531.49,"id":35736915}]}]}
{"op":"mcm","clk":"11946305455","pt":1724922426223,"mc":[{"id":"1.232283784","rc":[{"batb":[[1,1.74,16.76],[2,1.7,5.29]],"batl":[[0,2.26,4],[1,2.28,4],[2,2.34,5.89]],"ltp":2.34,"tv":2531.49,"id":35736915},{"batb":[[0,1.8,204]],"ltp":1.79,"tv":2113.84,"id":11445382}]}]}
{"op":"mcm","clk":"11946322213","pt":1724922836013,"mc":[{"id":"1.232283784","rc":[{"trd":[[2.26,78.91]],"batl":[[0,2.28,4],[1,2.34,5.89],[2,2.38,50]],"ltp":2.26,"tv":2546.2,"id":35736915},{"trd":[[1.8,20.8]],"batb":[[0,1.8,195.58]],"ltp":1.8,"tv":2122.26,"id":11445382}],"tv":4668.47}]}
{"op":"mcm","clk":"11946322769","pt":1724922849601,"mc":[{"id":"1.232283784","rc":[{"batl":[[0,2.26,4],[1,2.28,4],[2,2.34,5.89]],"ltp":2.26,"tv":2546.2,"id":35736915}]}]}
{"op":"mcm","clk":"11946330438","pt":1724923035331,"mc":[{"id":"1.232283784","rc":[{"trd":[[2.26,242.68]],"batb":[[0,2.26,40.23],[1,2.24,31.14],[2,1.74,16.76]],"batl":[[0,2.28,4],[1,2.34,5.89],[2,2.38,50]],"ltp":2.26,"tv":2709.97,"id":35736915},{"trd":[[1.8,216.38]],"batb":[[0,1.79,200],[1,1.74,4],[2,1.73,52.9]],"ltp":1.8,"tv":2317.84,"id":11445382}],"tv":5027.82}]}
{"op":"mcm","clk":"11946330500","pt":1724923036875,"mc":[{"id":"1.232283784","rc":[{"batb":[[1,1.74,16.76],[2,1.7,5.29]],"ltp":2.26,"tv":2709.97,"id":35736915},{"batb":[[2,1.2,1000.88]],"ltp":1.8,"tv":2317.84,"id":11445382}]}]}
{"op":"mcm","clk":"11946333141","pt":1724923100218,"mc":[{"id":"1.232283784","rc":[{"trd":[[2.28,120.67]],"batl":[[0,2.34,5.89],[1,2.38,50],[2,2.42,50]],"ltp":2.28,"tv":2780.64,"id":35736915},{"trd":[[1.79,149.54]],"batb":[[0,1.79,120.17]],"ltp":1.79,"tv":2397.67,"id":11445382}],"tv":5178.32}]}
{"op":"mcm","clk":"11946333447","pt":1724923106632,"mc":[{"id":"1.232283784","rc":[{"batl":[[0,2.28,4],[1,2.34,5.89],[2,2.38,50]],"ltp":2.28,"tv":2780.64,"id":35736915}]}]}
{"op":"mcm","clk":"11946333979","pt":1724923119798,"mc":[{"id":"1.232283784","rc":[{"batb":[[0,1.74,16.76],[1,1.7,5.29],[2,1.2,1000]],"ltp":2.28,"tv":2780.64,"id":35736915}]}]}
{"op":"mcm","clk":"11946334010","pt":1724923120441,"mc":[{"id":"1.232283784","rc":[{"trd":[[2.28,164.9]],"batb":[[0,1.76,8.36],[1,1.75,116.37],[2,1.74,16.76]],"batl":[[0,2.34,1.89],[1,2.38,50],[2,2.42,50]],"ltp":2.28,"tv":2824.87,"id":35736915},{"trd":[[1.79,195.69]],"batb":[[0,1.8,5],[1,1.79,74.02],[2,1.74,4]],"batl":[[0,2.32,6.25]],"ltp":1.79,"tv":2443.82,"id":11445382}],"tv":5268.7}]}
{"op":"mcm","clk":"11946334073","pt":1724923122143,"mc":[{"id":"1.232283784","rc":[{"batb":[[0,2.24,31.14],[1,1.76,8.36],[2,1.75,116.37]],"ltp":2.28,"tv":2824.87,"id":35736915}]}]}
{"op":"mcm","clk":"11946334136","pt":1724923123638,"mc":[{"id":"1.232283784","rc":[{"batb":[[1,1.75,111.37],[2,1.74,16.76]],"ltp":2.28,"tv":2824.87,"id":35736915},{"batb":[[0,1.79,74.02],[1,1.74,4],[2,1.73,52.9]],"ltp":1.79,"tv":2443.82,"id":11445382}]}]}
{"op":"mcm","clk":"11946334232","pt":1724923125605,"mc":[{"id":"1.232283784","rc":[{"batb":[[0,2.26,5],[1,2.24,31.14],[2,1.75,111.37]],"ltp":2.28,"tv":2824.87,"id":35736915}]}]}
{"op":"mcm","clk":"11946334322","pt":1724923127219,"mc":[{"id":"1.232283784","rc":[{"batb":[[1,1.75,111.37],[2,1.74,16.76]],"ltp":2.28,"tv":2824.87,"id":35736915},{"batb":[[2,1.2,1000.88]],"ltp":1.79,"tv":2443.82,"id":11445382}]}]}
{"op":"mcm","clk":"11946334412","pt":1724923129238,"mc":[{"id":"1.232283784","rc":[{"batb":[[0,1.75,111.37],[1,1.74,16.76],[2,1.7,5.29]],"ltp":2.28,"tv":2824.87,"id":35736915}]}]}
{"op":"mcm","clk":"11946334609","pt":1724923132228,"mc":[{"id":"1.232283784","rc":[{"batb":[[0,2.26,5],[1,2.24,31.14],[2,1.75,111.37]],"ltp":2.28,"tv":2824.87,"id":35736915},{"batb":[[2,1.73,52.9]],"ltp":1.79,"tv":2443.82,"id":11445382}]}]}
{"op":"mcm","clk":"11946334765","pt":1724923135616,"mc":[{"id":"1.232283784","rc":[{"batb":[[0,2.24,31.14],[1,1.75,111.37],[2,1.74,16.76]],"ltp":2.28,"tv":2824.87,"id":35736915}]}]}
{"op":"mcm","clk":"11946334825","pt":1724923136859,"mc":[{"id":"1.232283784","rc":[{"batb":[[0,2.24,35.14],[1,1.75,149.55]],"batl":[[0,2.28,4],[1,2.34,1.89],[2,2.38,50]],"ltp":2.28,"tv":2824.87,"id":35736915},{"batb":[[0,1.79,102.92]],"batl":[[0,1.81,4]],"ltp":1.79,"tv":2443.82,"id":11445382}]}]}
{"op":"mcm","clk":"11946336743","pt":1724923180700,"mc":[{"id":"1.232283784","rc":[{"batb":[[1,2.22,30.44]],"ltp":2.28,"tv":2824.87,"id":35736915}]}]}
{"op":"mcm","clk":"11946336838","pt":1724923182813,"mc":[{"id":"1.232283784","rc":[{"batb":[[0,2.24,4]],"batl":[[0,2.26,6.37],[1,2.28,4],[2,2.34,1.89]],"ltp":2.28,"tv":2824.87,"id":35736915},{"batb":[[0,1.8,7.73],[1,1.79,102.92],[2,1.74,4]],"ltp":1.79,"tv":2443.82,"id":11445382}]}]}
{"op":"mcm","clk":"11946337423","pt":1724923197319,"mc":[{"id":"1.232283784","rc":[{"batl":[[0,2.26,10.37]],"ltp":2.28,"tv":2824.87,"id":35736915}]}]}
{"op":"mcm","clk":"11946338755","pt":1724923224646,"mc":[{"id":"1.232283784","rc":[{"batb":[[0,1.75,116.37],[1,1.74,16.76],[2,1.7,5.29]],"ltp":2.28,"tv":2824.87,"id":35736915},{"batb":[[1,1.79,74.02]],"ltp":1.79,"tv":2443.82,"id":11445382}]}]}
{"op":"mcm","clk":"11946338831","pt":1724923226080,"mc":[{"id":"1.232283784","rc":[{"batb":[[0,1.76,8.74],[1,1.75,116.37],[2,1.74,16.76]],"ltp":2.28,"tv":2824.87,"id":35736915},{"batb":[[0,1.81,5],[1,1.8,7.73],[2,1.79,74.02]],"batl":[[0,2.32,6.54]],"ltp":1.79,"tv":2443.82,"id":11445382}]}]}
{"op":"mcm","clk":"11946338906","pt":1724923227464,"mc":[{"id":"1.232283784","rc":[{"trd":[[2.24,4.04]],"batb":[[0,2.24,27.1],[1,1.76,8.74],[2,1.75,116.37]],"ltp":2.24,"tv":2828.91,"id":35736915},{"trd":[[1.81,30.34]],"batb":[[0,1.8,7.73],[1,1.79,74.02],[2,1.74,4]],"ltp":1.81,"tv":2448.82,"id":11445382}],"tv":5277.74}]}
{"op":"mcm","clk":"11946338958","pt":1724923228644,"mc":[{"id":"1.232283784","rc":[{"batb":[[1,1.75,111.37],[2,1.74,16.76]],"batl":[[0,2.28,4],[1,2.34,1.89],[2,2.38,50]],"ltp":2.24,"tv":2828.91,"id":35736915},{"batb":[[0,1.79,74.02],[1,1.74,4],[2,1.73,52.9]],"ltp":1.81,"tv":2448.82,"id":11445382}]}]}
{"op":"mcm","clk":"11946339150","pt":1724923232544,"mc":[{"id":"1.232283784","rc":[{"batb":[[0,2.24,31.14]],"ltp":2.24,"tv":2828.91,"id":35736915}]}]}
{"op":"mcm","clk":"11946339606","pt":1724923242772,"mc":[{"id":"1.232283784","rc":[{"batb":[[0,2.24,35.14],[1,1.74,16.76],[2,1.7,5.29]],"ltp":2.24,"tv":2828.91,"id":35736915},{"batl":[[0,1.81,4]],"ltp":1.81,"tv":2448.82,"id":11445382}]}]}
{"op":"mcm","clk":"11946341265","pt":1724923276195,"mc":[{"id":"1.232283784","rc":[{"batb":[[0,2.24,65.07]],"ltp":2.24,"tv":2828.91,"id":35736915},{"batb":[[0,1.79,102.92]],"ltp":1.81,"tv":2448.82,"id":11445382}]}]}
{"op":"mcm","clk":"11946341325","pt":1724923277583,"mc":[{"id":"1.232283784","rc":[{"batb":[[0,2.24,33.93]],"ltp":2.24,"tv":2828.91,"id":35736915},{"batb":[[2,1.2,1000.88]],"ltp":1.81,"tv":2448.82,"id":11445382}]}]}
{"op":"mcm","clk":"11946343554","pt":1724923327798,"mc":[{"id":"1.232283784","rc":[{"batb":[[0,2.24,31.14],[1,1.75,5],[2,1.74,16.76]],"batl":[[0,2.26,4.66],[1,2.28,4],[2,2.34,1.89]],"ltp":2.24,"tv":2828.91,"id":35736915},{"batb":[[0,1.8,5.56],[1,1.79,74.02],[2,1.74,4]],"ltp":1.81,"tv":2448.82,"id":11445382}]}]}
{"op":"mcm","clk":"11946343560","pt":1724923327897,"mc":[{"id":"1.232283784","rc":[{"batb":[[1,1.75,116.37]],"ltp":2.24,"tv":2828.91,"id":35736915}]}]}
{"op":"mcm","clk":"11946343724","pt":1724923330962,"mc":[{"id":"1.232283784","rc":[{"batb":[[1,1.75,111.37]],"batl":[[0,2.28,4],[1,2.34,1.89],[2,2.38,50]],"ltp":2.24,"tv":2828.91,"id":35736915},{"batb":[[0,1.79,74.02],[1,1.74,4],[2,1.73,52.9]],"ltp":1.81,"tv":2448.82,"id":11445382}]}]}
{"op":"mcm","clk":"11946343840","pt":1724923333285,"mc":[{"id":"1.232283784","rc":[{"batb":[[0,2.24,35.14]],"ltp":2.24,"tv":2828.91,"id":35736915},{"batl":[[0,1.81,4]],"ltp":1.81,"tv":2448.82,"id":11445382}]}]}
{"op":"mcm","clk":"11946345869","pt":1724923374619,"mc":[{"id":"1.232283784","rc":[{"batb":[[0,2.24,65.07],[1,1.74,16.76],[2,1.7,5.29]],"ltp":2.24,"tv":2828.91,"id":35736915},{"batb":[[0,1.79,102.92]],"ltp":1.81,"tv":2448.82,"id":11445382}]}]}
{"op":"mcm","clk":"11946346034","pt":1724923378048,"mc":[{"id":"1.232283784","rc":[{"batb":[[0,2.24,33.93]],"ltp":2.24,"tv":2828.91,"id":35736915},{"batb":[[2,1.2,1000.88]],"ltp":1.81,"tv":2448.82,"id":11445382}]}]}
{"op":"mcm","clk":"11946348204","pt":1724923423605,"mc":[{"id":"1.232283784","rc":[{"batb":[[0,2.24,4]],"ltp":2.24,"tv":2828.91,"id":35736915},{"batb":[[0,1.79,74.02]],"ltp":1.81,"tv":2448.82,"id":11445382}]}]}
{"op":"mcm","clk":"11946348262","pt":1724923424484,"mc":[{"id":"1.232283784","rc":[{"batb":[[0,1.78,85.89],[1,1.75,5],[2,1.74,16.76]],"batl":[[0,2.26,4.66],[1,2.28,4],[2,2.34,1.89]],"ltp":2.24,"tv":2828.91,"id":35736915},{"batb":[[0,1.8,5.56],[1,1.79,74.02],[2,1.74,4]],"ltp":1.81,"tv":2448.82,"id":11445382}]}]}
{"op":"mcm","clk":"11946348418","pt":1724923427401,"mc":[{"id":"1.232283784","rc":[{"batb":[[1,1.74,16.76],[2,1.7,5.29]],"ltp":2.24,"tv":2828.91,"id":35736915}]}]}
{"op":"mcm","clk":"11946348456","pt":1724923428077,"mc":[{"id":"1.232283784","rc":[{"batb":[[0,2.24,31.14],[1,1.78,85.89],[2,1.74,16.76]],"ltp":2.24,"tv":2828.91,"id":35736915}]}]}
{"op":"mcm","clk":"11946348556","pt":1724923430187,"mc":[{"id":"1.232283784","rc":[{"batl":[[0,2.28,4],[1,2.34,1.89],[2,2.38,50]],"ltp":2.24,"tv":2828.91,"id":35736915},{"batb":[[0,1.79,74.02],[1,1.74,4],[2,1.73,52.9]],"ltp":1.81,"tv":2448.82,"id":11445382}]}]}
{"op":"mcm","clk":"11946349015","pt":1724923439596,"mc":[{"id":"1.232283784","rc":[{"batb":[[0,2.24,35.14],[1,1.74,16.76],[2,1.7,5.29]],"ltp":2.24,"tv":2828.91,"id":35736915},{"batl":[[0,1.81,4]],"ltp":1.81,"tv":2448.82,"id":11445382}]}]}
{"op":"mcm","clk":"11946350490","pt":1724923471460,"mc":[{"id":"1.232283784","rc":[{"batb":[[0,2.24,65.07]],"ltp":2.24,"tv":2828.91,"id":35736915},{"batb":[[0,1.79,102.92]],"ltp":1.81,"tv":2448.82,"id":11445382}]}]}
{"op":"mcm","clk":"11946350583","pt":1724923473366,"mc":[{"id":"1.232283784","rc":[{"batb":[[0,2.24,33.93]],"ltp":2.24,"tv":2828.91,"id":35736915},{"batb":[[2,1.2,1000.88]],"ltp":1.81,"tv":2448.82,"id":11445382}]}]}
{"op":"mcm","clk":"11946352893","pt":1724923521177,"mc":[{"id":"1.232283784","rc":[{"batb":[[0,1.75,116.37]],"batl":[[0,2.26,4.66],[1,2.28,4],[2,2.34,1.89]],"ltp":2.24,"tv":2828.91,"id":35736915},{"batb":[[0,1.8,5.56],[1,1.79,74.02],[2,1.74,4]],"ltp":1.81,"tv":2448.82,"id":11445382}]}]}
{"op":"mcm","clk":"11946353023","pt":1724923523487,"mc":[{"id":"1.232283784","rc":[{"batb":[[0,2.24,31.14],[1,1.75,116.37],[2,1.74,16.76]],"ltp":2.24,"tv":2828.91,"id":35736915}]}]}
{"op":"mcm","clk":"11946353072","pt":1724923524716,"mc":[{"id":"1.232283784","rc":[{"batb":[[1,1.75,111.37]],"batl":[[0,2.28,4],[1,2.34,1.89],[2,2.38,50]],"ltp":2.24,"tv":2828.91,"id":35736915},{"batb":[[0,1.79,74.02],[1,1.74,4],[2,1.73,52.9]],"ltp":1.81,"tv":2448.82,"id":11445382}]}]}
{"op":"mcm","clk":"11946353323","pt":1724923531038,"mc":[{"id":"1.232283784","rc":[{"batb":[[0,2.24,35.14]],"ltp":2.24,"tv":2828.91,"id":35736915},{"batl":[[0,1.81,4]],"ltp":1.81,"tv":2448.82,"id":11445382}]}]}
{"op":"mcm","clk":"11946354557","pt":1724923566270,"mc":[{"id":"1.232283784","rc":[{"batb":[[0,2.24,65.07],[1,1.74,16.76],[2,1.7,5.29]],"ltp":2.24,"tv":2828.91,"id":35736915},{"batb":[[0,1.79,102.92]],"ltp":1.81,"tv":2448.82,"id":11445382}]}]}
{"op":"mcm","clk":"11946354628","pt":1724923568683,"mc":[{"id":"1.232283784","rc":[{"batb":[[0,2.24,33.93]],"ltp":2.24,"tv":2828.91,"id":35736915},{"batb":[[2,1.2,1000.88]],"ltp":1.81,"tv":2448.82,"id":11445382}]}]}
{"op":"mcm","clk":"11946356019","pt":1724923611802,"mc":[{"id":"1.232283784","rc":[{"batb":[[0,1.76,67.83],[1,1.75,5],[2,1.74,16.76]],"ltp":2.24,"tv":2828.91,"id":35736915},{"batb":[[0,1.79,74.02]],"ltp":1.81,"tv":2448.82,"id":11445382}]}]}
{"op":"mcm","clk":"11946356022","pt":1724923611904,"mc":[{"id":"1.232283784","rc":[{"batl":[[0,2.26,4.66],[1,2.28,4],[2,2.34,1.89]],"ltp":2.24,"tv":2828.91,"id":35736915},{"batb":[[0,1.8,5.56],[1,1.79,74.02],[2,1.74,4]],"ltp":1.81,"tv":2448.82,"id":11445382}]}]}
{"op":"mcm","clk":"11946356084","pt":1724923613794,"mc":[{"id":"1.232283784","rc":[{"batb":[[0,2.24,31.14],[1,1.76,67.83],[2,1.75,5]],"ltp":2.24,"tv":2828.91,"id":35736915}]}]}
{"op":"mcm","clk":"11946356108","pt":1724923614512,"mc":[{"id":"1.232283784","rc":[{"batl":[[0,2.28,4],[1,2.34,1.89],[2,2.38,50]],"ltp":2.24,"tv":2828.91,"id":35736915},{"batb":[[0,1.79,74.02],[1,1.74,4],[2,1.73,52.9]],"ltp":1.81,"tv":2448.82,"id":11445382}]}]}
{"op":"mcm","clk":"11946356126","pt":1724923615022,"mc":[{"id":"1.232283784","rc":[{"batb":[[2,1.74,16.76]],"ltp":2.24,"tv":2828.91,"id":35736915}]}]}
{"op":"mcm","clk":"11946356373","pt":1724923622019,"mc":[{"id":"1.232283784","rc":[{"batb":[[0,2.24,35.14]],"ltp":2.24,"tv":2828.91,"id":35736915},{"batl":[[0,1.81,4]],"ltp":1.81,"tv":2448.82,"id":11445382}]}]}
{"op":"mcm","clk":"11946357512","pt":1724923654678,"mc":[{"id":"1.232283784","rc":[{"batb":[[0,2.24,65.07]],"ltp":2.24,"tv":2828.91,"id":35736915},{"batb":[[0,1.79,102.92]],"ltp":1.81,"tv":2448.82,"id":11445382}]}]}
{"op":"mcm","clk":"11946357524","pt":1724923654984,"mc":[{"id":"1.232283784","rc":[{"batb":[[1,1.74,16.76],[2,1.7,5.29]],"ltp":2.24,"tv":2828.91,"id":35736915}]}]}
{"op":"mcm","clk":"11946357701","pt":1724923659094,"mc":[{"id":"1.232283784","rc":[{"batb":[[0,2.24,33.93]],"ltp":2.24,"tv":2828.91,"id":35736915},{"batb":[[2,1.2,1000.88]],"ltp":1.81,"tv":2448.82,"id":11445382}]}]}
{"op":"mcm","clk":"11946357889","pt":1724923664073,"mc":[{"id":"1.232283784","rc":[{"trd":[[1.79,212.45]],"batb":[[0,1.79,94.54]],"ltp":1.79,"tv":2465.58,"id":11445382}],"tv":5294.5}]}
{"op":"mcm","clk":"11946358692","pt":1724923685820,"mc":[{"id":"1.232283784","rc":[{"trd":[[1.79,229.21]],"batb":[[0,1.79,86.16]],"ltp":1.79,"tv":2482.34,"id":11445382}],"tv":5311.26}]}
{"op":"mcm","clk":"11946359075","pt":1724923696415,"mc":[{"id":"1.232283784","rc":[{"trd":[[1.79,262.73]],"batb":[[0,1.79,69.4]],"ltp":1.79,"tv":2515.86,"id":11445382}],"tv":5344.78}]}
{"op":"mcm","clk":"11946359194","pt":1724923700840,"mc":[{"id":"1.232283784","rc":[{"batb":[[0,1.76,67.83],[1,1.75,5],[2,1.74,16.76]],"ltp":2.24,"tv":2828.91,"id":35736915},{"batb":[[0,1.79,40.5]],"ltp":1.79,"tv":2515.86,"id":11445382}]}]}
{"op":"mcm","clk":"11946359340","pt":1724923704138,"mc":[{"id":"1.232283784","rc":[{"batb":[[0,2.24,31.14],[1,1.76,67.83]],"ltp":2.24,"tv":2828.91,"id":35736915},{"batb":[[2,1.73,52.9]],"ltp":1.79,"tv":2515.86,"id":11445382}]}]}
{"op":"mcm","clk":"11946359633","pt":1724923712941,"mc":[{"id":"1.232283784","rc":[{"batb":[[0,2.24,35.14]],"ltp":2.24,"tv":2828.91,"id":35736915},{"batl":[[0,1.81,4]],"ltp":1.79,"tv":2515.86,"id":11445382}]}]}
{"op":"mcm","clk":"11946360754","pt":1724923743450,"mc":[{"id":"1.232283784","rc":[{"batb":[[0,2.24,65.07],[1,1.74,16.76],[2,1.7,5.29]],"ltp":2.24,"tv":2828.91,"id":35736915},{"batb":[[0,1.79,69.4]],"ltp":1.79,"tv":2515.86,"id":11445382}]}]}
{"op":"mcm","clk":"11946360781","pt":1724923744373,"mc":[{"id":"1.232283784","rc":[{"batb":[[0,2.24,33.93]],"ltp":2.24,"tv":2828.91,"id":35736915},{"batb":[[2,1.2,1000.88]],"ltp":1.79,"tv":2515.86,"id":11445382}]}]}
{"op":"mcm","clk":"11946362538","pt":1724923788820,"mc":[{"id":"1.232283784","rc":[{"batb":[[0,1.74,16.76],[1,1.7,5.29],[2,1.2,1000]],"ltp":2.24,"tv":2828.91,"id":35736915},{"batb":[[0,1.79,40.5]],"ltp":1.79,"tv":2515.86,"id":11445382}]}]}
{"op":"mcm","clk":"11946362562","pt":1724923789433,"mc":[{"id":"1.232283784","rc":[{"batb":[[0,2.24,31.14],[1,1.75,73.22],[2,1.74,16.76]],"batl":[[0,2.34,1.89],[1,2.38,50],[2,2.42,50]],"ltp":2.24,"tv":2828.91,"id":35736915},{"batb":[[0,1.79,36.5],[1,1.73,52.9]],"ltp":1.79,"tv":2515.86,"id":11445382}]}]}
{"op":"mcm","clk":"11946362669","pt":1724923792460,"mc":[{"id":"1.232283784","rc":[{"batb":[[1,1.75,68.22]],"ltp":2.24,"tv":2828.91,"id":35736915}]}]}
{"op":"mcm","clk":"11946362839","pt":1724923795754,"mc":[{"id":"1.232283784","rc":[{"batb":[[0,2.26,5],[1,2.24,31.14],[2,1.75,68.22]],"ltp":2.24,"tv":2828.91,"id":35736915}]}]}
{"op":"mcm","clk":"11946363003","pt":1724923798928,"mc":[{"id":"1.232283784","rc":[{"batb":[[0,2.24,31.14],[1,1.75,68.22],[2,1.74,16.76]],"ltp":2.24,"tv":2828.91,"id":35736915}]}]}
{"op":"mcm","clk":"11946363133","pt":1724923801659,"mc":[{"id":"1.232283784","rc":[{"batb":[[0,2.26,5],[1,2.24,31.14],[2,1.75,68.22]],"ltp":2.24,"tv":2828.91,"id":35736915}]}]}
{"op":"mcm","clk":"11946363142","pt":1724923801873,"mc":[{"id":"1.232283784","rc":[{"batb":[[2,1.74,16.76]],"ltp":2.24,"tv":2828.91,"id":35736915}]}]}
{"op":"mcm","clk":"11946363232","pt":1724923803737,"mc":[{"id":"1.232283784","rc":[{"batl":[[0,2.28,4],[1,2.34,1.89],[2,2.38,50]],"ltp":2.24,"tv":2828.91,"id":35736915},{"batb":[[0,1.79,40.5]],"ltp":1.79,"tv":2515.86,"id":11445382}]}]}
{"op":"mcm","clk":"11946363256","pt":1724923804553,"mc":[{"id":"1.232283784","rc":[{"batb":[[1,1.74,16.76],[2,1.7,5.29]],"ltp":2.24,"tv":2828.91,"id":35736915},{"batb":[[1,1.2,1000.88],[2,1.04,1.05]],"ltp":1.79,"tv":2515.86,"id":11445382}]}]}
{"op":"mcm","clk":"11946363287","pt":1724923805272,"mc":[{"id":"1.232283784","rc":[{"batb":[[0,1.75,68.22]],"ltp":2.24,"tv":2828.91,"id":35736915}]}]}
{"op":"mcm","clk":"11946363401","pt":1724923807757,"mc":[{"id":"1.232283784","rc":[{"batb":[[0,1.76,5],[1,1.75,68.22],[2,1.74,16.76]],"ltp":2.24,"tv":2828.91,"id":35736915}]}]}
{"op":"mcm","clk":"11946363479","pt":1724923809551,"mc":[{"id":"1.232283784","rc":[{"batb":[[0,2.24,31.14],[1,1.76,5],[2,1.75,68.22]],"ltp":2.24,"tv":2828.91,"id":35736915},{"batb":[[1,1.73,52.9],[2,1.2,1000.88]],"ltp":1.79,"tv":2515.86,"id":11445382}]}]}
{"op":"mcm","clk":"11946363565","pt":1724923811056,"mc":[{"id":"1.232283784","rc":[{"batb":[[1,1.75,68.22],[2,1.74,16.76]],"ltp":2.24,"tv":2828.91,"id":35736915}]}]}
{"op":"mcm","clk":"11946363922","pt":1724923818860,"mc":[{"id":"1.232283784","rc":[{"batb":[[0,2.24,35.14]],"ltp":2.24,"tv":2828.91,"id":35736915},{"batl":[[0,1.81,4]],"ltp":1.79,"tv":2515.86,"id":11445382}]}]}
{"op":"mcm","clk":"11946363932","pt":1724923819065,"mc":[{"id":"1.232283784","rc":[{"batb":[[1,1.74,16.76],[2,1.7,5.29]],"ltp":2.24,"tv":2828.91,"id":35736915}]}]}
{"op":"mcm","clk":"11946364706","pt":1724923836093,"mc":[{"id":"1.232283784","rc":[{"batb":[[0,2.24,65.07]],"ltp":2.24,"tv":2828.91,"id":35736915},{"batb":[[0,1.79,69.4]],"ltp":1.79,"tv":2515.86,"id":11445382}]}]}
{"op":"mcm","clk":"11946364873","pt":1724923839694,"mc":[{"id":"1.232283784","rc":[{"batb":[[0,2.24,33.93]],"ltp":2.24,"tv":2828.91,"id":35736915},{"batb":[[1,1.2,1000.88],[2,1.04,1.05]],"ltp":1.79,"tv":2515.86,"id":11445382}]}]}
{"op":"mcm","clk":"11946367098","pt":1724923886866,"mc":[{"id":"1.232283784","rc":[{"batb":[[0,1.75,5]],"ltp":2.24,"tv":2828.91,"id":35736915},{"batb":[[0,1.79,40.5]],"ltp":1.79,"tv":2515.86,"id":11445382}]}]}
{"op":"mcm","clk":"11946367130","pt":1724923887478,"mc":[{"id":"1.232283784","rc":[{"batb":[[0,1.75,389.41]],"batl":[[0,2.34,1.89],[1,2.38,50],[2,2.42,50]],"ltp":2.24,"tv":2828.91,"id":35736915},{"batb":[[0,1.79,36.5]],"ltp":1.79,"tv":2515.86,"id":11445382}]}]}
{"op":"mcm","clk":"11946367177","pt":1724923888462,"mc":[{"id":"1.232283784","rc":[{"batb":[[0,1.77,67.44],[1,1.76,16.81],[2,1.75,5]],"ltp":2.24,"tv":2828.91,"id":35736915}]}]}
{"op":"mcm","clk":"11946367240","pt":1724923889956,"mc":[{"id":"1.232283784","rc":[{"batb":[[0,2.24,31.14],[1,1.77,67.44],[2,1.74,16.76]],"ltp":2.24,"tv":2828.91,"id":35736915},{"batb":[[1,1.73,52.9],[2,1.2,1000.88]],"ltp":1.79,"tv":2515.86,"id":11445382}]}]}
{"op":"mcm","clk":"11946367519","pt":1724923895047,"mc":[{"id":"1.232283784","rc":[{"batb":[[0,2.26,5],[1,2.24,35.14],[2,1.77,67.44]],"batl":[[0,2.28,4],[1,2.34,1.89],[2,2.38,50]],"ltp":2.24,"tv":2828.91,"id":35736915},{"batb":[[0,1.79,40.5]],"batl":[[0,1.81,4]],"ltp":1.79,"tv":2515.86,"id":11445382}]}]}
{"op":"mcm","clk":"11946367736","pt":1724923898279,"mc":[{"id":"1.232283784","rc":[{"batb":[[0,2.24,35.14],[1,1.77,67.44],[2,1.74,16.76]],"ltp":2.24,"tv":2828.91,"id":35736915}]}]}
{"op":"mcm","clk":"11946369636","pt":1724923937599,"mc":[{"id":"1.232283784","rc":[{"batb":[[0,2.24,65.07],[1,1.74,16.76],[2,1.7,5.29]],"ltp":2.24,"tv":2828.91,"id":35736915},{"batb":[[0,1.79,69.4]],"ltp":1.79,"tv":2515.86,"id":11445382}]}]}
{"op":"mcm","clk":"11946369742","pt":1724923940114,"mc":[{"id":"1.232283784","rc":[{"batb":[[0,2.24,33.93]],"ltp":2.24,"tv":2828.91,"id":35736915},{"batb":[[1,1.2,1000.88],[2,1.04,1.05]],"ltp":1.79,"tv":2515.86,"id":11445382}]}]}
{"op":"mcm","clk":"11946371960","pt":1724923986834,"mc":[{"id":"1.232283784","rc":[{"batb":[[0,1.76,67.83],[1,1.75,5],[2,1.74,16.76]],"ltp":2.24,"tv":2828.91,"id":35736915},{"batb":[[0,1.79,40.5]],"ltp":1.79,"tv":2515.86,"id":11445382}]}]}
{"op":"mcm","clk":"11946372122","pt":1724923990444,"mc":[{"id":"1.232283784","rc":[{"batb":[[0,2.24,31.14],[1,1.76,67.83]],"ltp":2.24,"tv":2828.91,"id":35736915},{"batb":[[1,1.73,52.9],[2,1.2,1000.88]],"ltp":1.79,"tv":2515.86,"id":11445382}]}]}
{"op":"mcm","clk":"11946372858","pt":1724924001755,"mc":[{"id":"1.232283784","rc":[{"batb":[[0,2.24,35.14],[1,1.74,16.76],[2,1.7,5.29]],"ltp":2.24,"tv":2828.91,"id":35736915},{"batl":[[0,1.81,4]],"ltp":1.79,"tv":2515.86,"id":11445382}]}]}
{"op":"mcm","clk":"11946375640","pt":1724924033591,"mc":[{"id":"1.232283784","rc":[{"batb":[[0,2.24,65.07]],"ltp":2.24,"tv":2828.91,"id":35736915},{"batb":[[0,1.79,69.4]],"ltp":1.79,"tv":2515.86,"id":11445382}]}]}
{"op":"mcm","clk":"11946375755","pt":1724924035498,"mc":[{"id":"1.232283784","rc":[{"batb":[[0,2.24,33.93]],"ltp":2.24,"tv":2828.91,"id":35736915},{"batb":[[1,1.2,1000.88],[2,1.04,1.05]],"ltp":1.79,"tv":2515.86,"id":11445382}]}]}
{"op":"mcm","clk":"11946376246","pt":1724924045221,"mc":[{"id":"1.232283784","rc":[{"trd":[[1.79,279.49]],"batb":[[0,1.79,61.02]],"ltp":1.79,"tv":2532.62,"id":11445382}],"tv":5361.54}]}
{"op":"mcm","clk":"11946378073","pt":1724924081760,"mc":[{"id":"1.232283784","rc":[{"batb":[[0,2.24,4]],"ltp":2.24,"tv":2828.91,"id":35736915},{"batb":[[0,1.79,32.12]],"ltp":1.79,"tv":2532.62,"id":11445382}]}]}
