{"op":"mcm","clk":"11966477836","pt":1724623579660,"mc":[{"id":"1.232283863","marketDefinition":{"bspMarket":false,"turnInPlayEnabled":true,"persistenceEnabled":true,"marketBaseRate":5.0,"eventId":"33527219","eventTypeId":"4","numberOfWinners":1,"bettingType":"ODDS","marketType":"MATCH_ODDS","marketTime":"2024-08-30T06:00:00.000Z","suspendTime":"2024-08-30T06:00:00.000Z","bspReconciled":false,"complete":true,"inPlay":false,"crossMatching":false,"runnersVoidable":false,"numberOfActiveRunners":2,"betDelay":0,"status":"OPEN","runners":[{"status":"ACTIVE","sortPriority":1,"id":8858694,"name":"Kuwait"},{"status":"ACTIVE","sortPriority":2,"id":61044843,"name":"Mongolia"}],"regulators":["MR_INT"],"countryCode":"GB","discountAllowed":true,"timezone":"GMT","openDate":"2024-08-30T06:00:00.000Z","version":6100687007,"name":"Match Odds","eventName":"Kuwait v Mongolia"},"rc":[{"batb":[[0,1.01,20]],"ltp":0.0,"tv":0.0,"id":8858694},{"batb":[[0,1.01,20]],"ltp":0.0,"tv":0.0,"id":61044843}]}]}
{"op":"mcm","clk":"11966477860","pt":1724623579968,"mc":[{"id":"1.232283863","rc":[{"batb":[[0,1.03,200],[1,1.02,200],[2,1.01,220]],"ltp":0.0,"tv":0.0,"id":8858694},{"batb":[[0,1.03,200],[1,1.02,200],[2,1.01,220]],"ltp":0.0,"tv":0.0,"id":61044843}]}]}
{"op":"mcm","clk":"11966580889","pt":1724625225900,"mc":[{"id":"1.232283863","rc":[{"batb":[[2,1.01,220.76]],"ltp":0.0,"tv":0.0,"id":8858694},{"batb":[[2,1.01,220.76]],"ltp":0.0,"tv":0.0,"id":61044843}]}]}
{"op":"mcm","clk":"11966933432","pt":1724634105684,"mc":[{"id":"1.232283863","rc":[{"batb":[[0,1.13,5.52],[1,1.03,200],[2,1.02,200]],"ltp":0.0,"tv":0.0,"id":61044843}]}]}
{"op":"mcm","clk":"11966934476","pt":1724634131207,"mc":[{"id":"1.232283863","marketDefinition":{"bspMarket":false,"turnInPlayEnabled":true,"persistenceEnabled":true,"marketBaseRate":5.0,"eventId":"33527219","eventTypeId":"4","numberOfWinners":1,"bettingType":"ODDS","marketType":"MATCH_ODDS","marketTime":"2024-08-30T06:00:00.000Z","suspendTime":"2024-08-30T06:00:00.000Z","bspReconciled":false,"complete":true,"inPlay":false,"crossMatching":true,"runnersVoidable":false,"numberOfActiveRunners":2,"betDelay":0,"status":"OPEN","runners":[{"status":"ACTIVE","sortPriority":1,"id":8858694,"name":"Kuwait"},{"status":"ACTIVE","sortPriority":2,"id":61044843,"name":"Mongolia"}],"regulators":["MR_INT"],"countryCode":"GB","discountAllowed":true,"timezone":"GMT","openDate":"2024-08-30T06:00:00.000Z","version":6100687007,"name":"Match Odds","eventName":"Kuwait v Mongolia"}}]}
{"op":"mcm","clk":"11967074617","pt":1724638374826,"mc":[{"id":"1.232283863","rc":[{"batb":[[0,1.13,5.52]],"ltp":0.0,"tv":0.0,"id":61044843}]}]}
{"op":"mcm","clk":"11967118577","pt":1724639465239,"mc":[{"id":"1.232283863","rc":[{"batb":[[2,1.01,480.8]],"ltp":0.0,"tv":0.0,"id":8858694}]}]}
{"op":"mcm","clk":"11967226096","pt":1724643774831,"mc":[{"id":"1.232283863","rc":[{"batb":[[2,1.01,480.83]],"ltp":0.0,"tv":0.0,"id":8858694},{"batb":[[0,1.13,5.52]],"ltp":0.0,"tv":0.0,"id":61044843}]}]}
{"op":"mcm","clk":"11967309236","pt":1724647521383,"mc":[{"id":"1.232283863","marketDefinition":{"bspMarket":false,"turnInPlayEnabled":true,"persistenceEnabled":true,"marketBaseRate":5.0,"eventId":"33527219","eventTypeId":"4","numberOfWinners":1,"bettingType":"ODDS","marketType":"MATCH_ODDS","marketTime":"2024-08-30T05:45:00.000Z","suspendTime":"2024-08-30T05:45:00.000Z","bspReconciled":false,"complete":true,"inPlay":false,"crossMatching":true,"runnersVoidable":false,"numberOfActiveRunners":2,"betDelay":0,"status":"OPEN","runners":[{"status":"ACTIVE","sortPriority":1,"id":8858694,"name":"Kuwait"},{"status":"ACTIVE","sortPriority":2,"id":61044843,"name":"Mongolia"}],"regulators":["MR_INT"],"countryCode":"GB","discountAllowed":true,"timezone":"GMT","openDate":"2024-08-30T06:00:00.000Z","version":6101005069,"name":"Match Odds","eventName":"Kuwait v Mongolia"}}]}
{"op":"mcm","clk":"11967309257","pt":1724647522384,"mc":[{"id":"1.232283863","marketDefinition":{"bspMarket":false,"turnInPlayEnabled":true,"persistenceEnabled":true,"marketBaseRate":5.0,"eventId":"33527219","eventTypeId":"4","numberOfWinners":1,"bettingType":"ODDS","marketType":"MATCH_ODDS","marketTime":"2024-08-30T05:45:00.000Z","suspendTime":"2024-08-30T05:45:00.000Z","bspReconciled":false,"complete":true,"inPlay":false,"crossMatching":true,"runnersVoidable":false,"numberOfActiveRunners":2,"betDelay":0,"status":"OPEN","runners":[{"status":"ACTIVE","sortPriority":1,"id":8858694,"name":"Kuwait"},{"status":"ACTIVE","sortPriority":2,"id":61044843,"name":"Mongolia"}],"regulators":["MR_INT"],"countryCode":"GB","discountAllowed":true,"timezone":"GMT","openDate":"2024-08-30T05:45:00.000Z","version":6101005069,"name":"Match Odds","eventName":"Kuwait v Mongolia"}}]}
{"op":"mcm","clk":"11967340380","pt":1724649174818,"mc":[{"id":"1.232283863","rc":[{"batb":[[2,1.01,480.85]],"ltp":0.0,"tv":0.0,"id":8858694},{"batb":[[0,1.13,5.52]],"ltp":0.0,"tv":0.0,"id":61044843}]}]}
{"op":"mcm","clk":"11967477102","pt":1724654574809,"mc":[{"id":"1.232283863","rc":[{"batb":[[2,1.01,480.68]],"ltp":0.0,"tv":0.0,"id":8858694}]}]}
{"op":"mcm","clk":"11967639890","pt":1724659974815,"mc":[{"id":"1.232283863","rc":[{"batb":[[2,1.01,481.23]],"ltp":0.0,"tv":0.0,"id":8858694},{"batb":[[0,1.13,5.52]],"ltp":0.0,"tv":0.0,"id":61044843}]}]}
{"op":"mcm","clk":"11967890702","pt":1724665374824,"mc":[{"id":"1.232283863","rc":[{"batb":[[2,1.01,480.71]],"ltp":0.0,"tv":0.0,"id":8858694}]}]}
{"op":"mcm","clk":"11968181001","pt":1724669593647,"mc":[{"id":"1.232283863","rc":[{"batb":[[0,1.05,200],[1,1.04,250],[2,1.03,533.33]],"ltp":0.0,"tv":0.0,"id":8858694},{"batb":[[0,1.13,5.53],[1,1.05,200],[2,1.03,533.33]],"ltp":0.0,"tv":0.0,"id":61044843}]}]}
{"op":"mcm","clk":"11968181022","pt":1724669594058,"mc":[{"id":"1.232283863","rc":[{"batb":[[2,1.04,250]],"ltp":0.0,"tv":0.0,"id":61044843}]}]}
{"op":"mcm","clk":"11968248835","pt":1724670774812,"mc":[{"id":"1.232283863","rc":[{"batb":[[0,1.13,5.52]],"ltp":0.0,"tv":0.0,"id":61044843}]}]}
{"op":"mcm","clk":"11968595838","pt":1724675571121,"mc":[{"id":"1.232283863","rc":[{"batb":[[0,1.06,141.83],[1,1.05,200],[2,1.04,250]],"ltp":0.0,"tv":0.0,"id":8858694},{"batb":[[0,1.14,60.78],[1,1.13,5.53],[2,1.05,200]],"ltp":0.0,"tv":0.0,"id":61044843}]}]}
{"op":"mcm","clk":"11968748515","pt":1724677374615,"mc":[{"id":"1.232283863","rc":[{"batb":[[0,1.05,200],[1,1.04,250],[2,1.03,533.33]],"ltp":0.0,"tv":0.0,"id":8858694},{"batb":[[0,1.13,5.52],[1,1.05,200],[2,1.04,250]],"ltp":0.0,"tv":0.0,"id":61044843}]}]}
{"op":"mcm","clk":"11968761925","pt":1724677525003,"mc":[{"id":"1.232283863","rc":[{"batb":[[0,1.06,141.65],[1,1.05,200],[2,1.04,250]],"ltp":0.0,"tv":0.0,"id":8858694},{"batb":[[0,1.14,60.71],[1,1.13,5.52],[2,1.05,200]],"ltp":0.0,"tv":0.0,"id":61044843}]}]}
{"op":"mcm","clk":"11968936380","pt":1724679327262,"mc":[{"id":"1.232283863","rc":[{"batb":[[0,1.05,200],[1,1.04,250],[2,1.03,533.33]],"ltp":0.0,"tv":0.0,"id":8858694},{"batb":[[0,1.13,5.52],[1,1.05,200],[2,1.04,250]],"ltp":0.0,"tv":0.0,"id":61044843}]}]}
{"op":"mcm","clk":"11968952597","pt":1724679477404,"mc":[{"id":"1.232283863","rc":[{"batb":[[0,1.06,141.65],[1,1.05,200],[2,1.04,250]],"ltp":0.0,"tv":0.0,"id":8858694},{"batb":[[0,1.14,60.71],[1,1.13,5.52],[2,1.05,200]],"ltp":0.0,"tv":0.0,"id":61044843}]}]}
{"op":"mcm","clk":"11969159986","pt":1724681280657,"mc":[{"id":"1.232283863","rc":[{"batb":[[0,1.06,141.78]],"ltp":0.0,"tv":0.0,"id":8858694},{"batb":[[0,1.13,5.53],[1,1.05,200],[2,1.04,250]],"ltp":0.0,"tv":0.0,"id":61044843}]}]}
{"op":"mcm","clk":"11969160013","pt":1724681280861,"mc":[{"id":"1.232283863","rc":[{"batb":[[0,1.05,200],[1,1.04,250],[2,1.03,533.33]],"ltp":0.0,"tv":0.0,"id":8858694}]}]}
{"op":"mcm","clk":"11969181733","pt":1724681428421,"mc":[{"id":"1.232283863","rc":[{"batb":[[0,1.06,141.78],[1,1.05,200],[2,1.04,250]],"ltp":0.0,"tv":0.0,"id":8858694},{"batb":[[0,1.14,60.76],[1,1.13,5.53],[2,1.05,200]],"ltp":0.0,"tv":0.0,"id":61044843}]}]}
{"op":"mcm","clk":"11969466912","pt":1724683230590,"mc":[{"id":"1.232283863","rc":[{"batb":[[0,1.05,200],[1,1.04,250],[2,1.03,533.33]],"ltp":0.0,"tv":0.0,"id":8858694},{"batb":[[0,1.13,5.53],[1,1.05,200],[2,1.04,250]],"ltp":0.0,"tv":0.0,"id":61044843}]}]}
{"op":"mcm","clk":"11969492486","pt":1724683385235,"mc":[{"id":"1.232283863","rc":[{"batb":[[0,1.06,141.78],[1,1.05,200],[2,1.04,250]],"ltp":0.0,"tv":0.0,"id":8858694},{"batb":[[0,1.14,60.76],[1,1.13,5.53],[2,1.05,200]],"ltp":0.0,"tv":0.0,"id":61044843}]}]}
{"op":"mcm","clk":"11969723382","pt":1724685186445,"mc":[{"id":"1.232283863","rc":[{"batb":[[0,1.05,200],[1,1.04,250],[2,1.03,533.33]],"ltp":0.0,"tv":0.0,"id":8858694},{"batb":[[0,1.13,5.52],[1,1.05,200],[2,1.04,250]],"ltp":0.0,"tv":0.0,"id":61044843}]}]}
{"op":"mcm","clk":"11969749017","pt":1724685330323,"mc":[{"id":"1.232283863","rc":[{"batb":[[0,1.06,141.82],[1,1.05,200],[2,1.04,250]],"ltp":0.0,"tv":0.0,"id":8858694},{"batb":[[0,1.14,60.78],[1,1.13,5.52],[2,1.05,200]],"ltp":0.0,"tv":0.0,"id":61044843}]}]}
{"op":"mcm","clk":"11970041277","pt":1724687133628,"mc":[{"id":"1.232283863","rc":[{"batb":[[0,1.05,200],[1,1.04,250],[2,1.03,533.33]],"ltp":0.0,"tv":0.0,"id":8858694},{"batb":[[0,1.13,5.52],[1,1.05,200],[2,1.04,250]],"ltp":0.0,"tv":0.0,"id":61044843}]}]}
{"op":"mcm","clk":"11970058664","pt":1724687256129,"mc":[{"id":"1.232283863","rc":[{"batb":[[0,1.06,141.82],[1,1.05,200],[2,1.04,250]],"ltp":0.0,"tv":0.0,"id":8858694},{"batb":[[0,1.14,60.78],[1,1.13,5.52],[2,1.05,200]],"ltp":0.0,"tv":0.0,"id":61044843}]}]}
{"op":"mcm","clk":"11970271685","pt":1724689057767,"mc":[{"id":"1.232283863","rc":[{"batb":[[0,1.05,200],[1,1.04,250],[2,1.03,533.33]],"ltp":0.0,"tv":0.0,"id":8858694},{"batb":[[0,1.13,5.53],[1,1.05,200],[2,1.04,250]],"ltp":0.0,"tv":0.0,"id":61044843}]}]}
{"op":"mcm","clk":"11970278604","pt":1724689128245,"mc":[{"id":"1.232283863","rc":[{"batb":[[0,1.06,141.88],[1,1.05,200],[2,1.04,250]],"ltp":0.0,"tv":0.0,"id":8858694},{"batb":[[0,1.14,60.81],[1,1.13,5.53],[2,1.05,200]],"ltp":0.0,"tv":0.0,"id":61044843}]}]}
{"op":"mcm","clk":"11970475084","pt":1724690930135,"mc":[{"id":"1.232283863","rc":[{"batb":[[0,1.05,200],[1,1.04,250],[2,1.03,533.33]],"ltp":0.0,"tv":0.0,"id":8858694},{"batb":[[0,1.13,5.53],[1,1.05,200],[2,1.04,250]],"ltp":0.0,"tv":0.0,"id":61044843}]}]}
{"op":"mcm","clk":"11970478132","pt":1724690954454,"mc":[{"id":"1.232283863","rc":[{"batb":[[0,1.06,141.88],[1,1.05,200],[2,1.04,250]],"ltp":0.0,"tv":0.0,"id":8858694},{"batb":[[0,1.14,60.81],[1,1.13,5.53],[2,1.05,200]],"ltp":0.0,"tv":0.0,"id":61044843}]}]}
{"op":"mcm","clk":"11970668643","pt":1724692374814,"mc":[{"id":"1.232283863","rc":[{"batb":[[0,1.06,141.82]],"ltp":0.0,"tv":0.0,"id":8858694},{"batb":[[0,1.14,60.78],[1,1.13,5.52]],"ltp":0.0,"tv":0.0,"id":61044843}]}]}
{"op":"mcm","clk":"11970709953","pt":1724692582194,"mc":[{"id":"1.232283863","rc":[{"batb":[[0,1.5,15],[1,1.14,60.78],[2,1.13,5.52]],"ltp":0.0,"tv":0.0,"id":61044843}]}]}
{"op":"mcm","clk":"11970737616","pt":1724692757321,"mc":[{"id":"1.232283863","rc":[{"batb":[[0,1.05,200],[1,1.04,250],[2,1.03,533.33]],"ltp":0.0,"tv":0.0,"id":8858694},{"batb":[[1,1.13,5.52],[2,1.05,200]],"ltp":0.0,"tv":0.0,"id":61044843}]}]}
{"op":"mcm","clk":"11970740554","pt":1724692775643,"mc":[{"id":"1.232283863","rc":[{"batb":[[0,1.06,141.82],[1,1.05,200],[2,1.04,250]],"ltp":0.0,"tv":0.0,"id":8858694},{"batb":[[0,1.51,16.69],[1,1.5,15],[2,1.13,5.52]],"ltp":0.0,"tv":0.0,"id":61044843}]}]}
{"op":"mcm","clk":"11971028480","pt":1724694578056,"mc":[{"id":"1.232283863","rc":[{"batb":[[0,1.05,200],[1,1.04,250],[2,1.03,533.33]],"ltp":0.0,"tv":0.0,"id":8858694},{"batb":[[0,1.5,15],[1,1.13,5.52],[2,1.05,200]],"ltp":0.0,"tv":0.0,"id":61044843}]}]}
{"op":"mcm","clk":"11971028772","pt":1724694580084,"mc":[{"id":"1.232283863","rc":[{"batb":[[0,1.06,141.82],[1,1.05,200],[2,1.04,250]],"ltp":0.0,"tv":0.0,"id":8858694},{"batb":[[0,1.51,16.69],[1,1.5,15],[2,1.13,5.52]],"ltp":0.0,"tv":0.0,"id":61044843}]}]}
{"op":"mcm","clk":"11971307655","pt":1724696380497,"mc":[{"id":"1.232283863","rc":[{"batb":[[0,1.06,141.85]],"ltp":0.0,"tv":0.0,"id":8858694},{"batb":[[0,1.5,15],[1,1.13,5.52],[2,1.05,200]],"ltp":0.0,"tv":0.0,"id":61044843}]}]}
{"op":"mcm","clk":"11971307691","pt":1724696380670,"mc":[{"id":"1.232283863","rc":[{"batb":[[0,1.05,200],[1,1.04,250],[2,1.03,533.33]],"ltp":0.0,"tv":0.0,"id":8858694}]}]}
{"op":"mcm","clk":"11971336694","pt":1724696543480,"mc":[{"id":"1.232283863","rc":[{"batb":[[0,1.06,141.85],[1,1.05,200],[2,1.04,250]],"ltp":0.0,"tv":0.0,"id":8858694},{"batb":[[0,1.51,16.69],[1,1.5,15],[2,1.13,5.52]],"ltp":0.0,"tv":0.0,"id":61044843}]}]}
{"op":"mcm","clk":"11971653383","pt":1724698345126,"mc":[{"id":"1.232283863","rc":[{"batb":[[0,1.05,200],[1,1.04,250],[2,1.03,533.33]],"ltp":0.0,"tv":0.0,"id":8858694},{"batb":[[0,1.5,15],[1,1.13,5.52],[2,1.05,200]],"ltp":0.0,"tv":0.0,"id":61044843}]}]}
{"op":"mcm","clk":"11971671108","pt":1724698473639,"mc":[{"id":"1.232283863","rc":[{"batb":[[0,1.06,141.85],[1,1.05,200],[2,1.04,250]],"ltp":0.0,"tv":0.0,"id":8858694},{"batb":[[0,1.51,16.69],[1,1.5,15],[2,1.13,5.52]],"ltp":0.0,"tv":0.0,"id":61044843}]}]}
{"op":"mcm","clk":"11971909912","pt":1724700275589,"mc":[{"id":"1.232283863","rc":[{"batb":[[0,1.06,141.8]],"ltp":0.0,"tv":0.0,"id":8858694},{"batb":[[0,1.5,15],[1,1.13,5.53],[2,1.05,200]],"ltp":0.0,"tv":0.0,"id":61044843}]}]}
{"op":"mcm","clk":"11971909932","pt":1724700275798,"mc":[{"id":"1.232283863","rc":[{"batb":[[0,1.05,200],[1,1.04,250],[2,1.03,533.33]],"ltp":0.0,"tv":0.0,"id":8858694}]}]}
{"op":"mcm","clk":"11971920434","pt":1724700355810,"mc":[{"id":"1.232283863","rc":[{"batb":[[0,1.06,141.8],[1,1.05,200],[2,1.04,250]],"ltp":0.0,"tv":0.0,"id":8858694},{"batb":[[0,1.51,16.68],[1,1.5,15],[2,1.13,5.53]],"ltp":0.0,"tv":0.0,"id":61044843}]}]}
{"op":"mcm","clk":"11972151085","pt":1724702158517,"mc":[{"id":"1.232283863","rc":[{"batb":[[0,1.05,200],[1,1.04,250],[2,1.03,533.33]],"ltp":0.0,"tv":0.0,"id":8858694}]}]}
{"op":"mcm","clk":"11972151113","pt":1724702158728,"mc":[{"id":"1.232283863","rc":[{"batb":[[0,1.5,15],[1,1.13,5.53],[2,1.05,200]],"ltp":0.0,"tv":0.0,"id":61044843}]}]}
{"op":"mcm","clk":"11972157163","pt":1724702211539,"mc":[{"id":"1.232283863","rc":[{"batb":[[0,1.06,141.8],[1,1.05,200],[2,1.04,250]],"ltp":0.0,"tv":0.0,"id":8858694},{"batb":[[0,1.51,16.68],[1,1.5,15],[2,1.13,5.53]],"ltp":0.0,"tv":0.0,"id":61044843}]}]}
{"op":"mcm","clk":"11972273805","pt":1724703174801,"mc":[{"id":"1.232283863","rc":[{"batb":[[0,1.06,141.83]],"ltp":0.0,"tv":0.0,"id":8858694},{"batb":[[0,1.51,16.69],[2,1.13,5.53]],"ltp":0.0,"tv":0.0,"id":61044843}]}]}
{"op":"mcm","clk":"11972389472","pt":1724704013520,"mc":[{"id":"1.232283863","rc":[{"batb":[[0,1.05,200],[1,1.04,250],[2,1.03,533.33]],"ltp":0.0,"tv":0.0,"id":8858694},{"batb":[[0,1.5,15],[1,1.13,5.53],[2,1.05,200]],"ltp":0.0,"tv":0.0,"id":61044843}]}]}
{"op":"mcm","clk":"11972391295","pt":1724704027459,"mc":[{"id":"1.232283863","rc":[{"batb":[[0,1.06,141.83],[1,1.05,200],[2,1.04,250]],"ltp":0.0,"tv":0.0,"id":8858694},{"batb":[[0,1.51,16.69],[1,1.5,15],[2,1.13,5.53]],"ltp":0.0,"tv":0.0,"id":61044843}]}]}
{"op":"mcm","clk":"11972579271","pt":1724705830174,"mc":[{"id":"1.232283863","rc":[{"batb":[[0,1.05,200],[1,1.04,250],[2,1.03,533.33]],"ltp":0.0,"tv":0.0,"id":8858694},{"batb":[[0,1.5,15],[1,1.13,5.53],[2,1.05,200]],"ltp":0.0,"tv":0.0,"id":61044843}]}]}
{"op":"mcm","clk":"11972589744","pt":1724705985620,"mc":[{"id":"1.232283863","rc":[{"batb":[[0,1.06,141.83],[1,1.05,200],[2,1.04,250]],"ltp":0.0,"tv":0.0,"id":8858694},{"batb":[[0,1.51,16.69],[1,1.5,15],[2,1.13,5.53]],"ltp":0.0,"tv":0.0,"id":61044843}]}]}
{"op":"mcm","clk":"11972721603","pt":1724707787873,"mc":[{"id":"1.232283863","rc":[{"batb":[[0,1.05,200],[1,1.04,250],[2,1.03,533.33]],"ltp":0.0,"tv":0.0,"id":8858694},{"batb":[[0,1.5,15],[1,1.13,5.53],[2,1.05,200]],"ltp":0.0,"tv":0.0,"id":61044843}]}]}
{"op":"mcm","clk":"11972729009","pt":1724707894687,"mc":[{"id":"1.232283863","rc":[{"batb":[[0,1.06,141.8],[1,1.05,200],[2,1.04,250]],"ltp":0.0,"tv":0.0,"id":8858694},{"batb":[[0,1.51,16.68],[1,1.5,15],[2,1.13,5.53]],"ltp":0.0,"tv":0.0,"id":61044843}]}]}
{"op":"mcm","clk":"11972848836","pt":1724709696609,"mc":[{"id":"1.232283863","rc":[{"batb":[[0,1.05,200],[1,1.04,250],[2,1.03,533.33]],"ltp":0.0,"tv":0.0,"id":8858694},{"batb":[[0,1.51,16.68],[2,1.13,5.53]],"ltp":0.0,"tv":0.0,"id":61044843}]}]}
{"op":"mcm","clk":"11972848846","pt":1724709696816,"mc":[{"id":"1.232283863","rc":[{"batb":[[0,1.5,15],[1,1.13,5.53],[2,1.05,200]],"ltp":0.0,"tv":0.0,"id":61044843}]}]}
{"op":"mcm","clk":"11972853034","pt":1724709786280,"mc":[{"id":"1.232283863","rc":[{"batb":[[0,1.06,141.77],[1,1.05,200],[2,1.04,250]],"ltp":0.0,"tv":0.0,"id":8858694},{"batb":[[0,1.51,16.68],[1,1.5,15],[2,1.13,5.53]],"ltp":0.0,"tv":0.0,"id":61044843}]}]}
{"op":"mcm","clk":"11972942088","pt":1724711587485,"mc":[{"id":"1.232283863","rc":[{"batb":[[0,1.05,200],[1,1.04,250],[2,1.03,533.33]],"ltp":0.0,"tv":0.0,"id":8858694}]}]}
{"op":"mcm","clk":"11972942098","pt":1724711587692,"mc":[{"id":"1.232283863","rc":[{"batb":[[0,1.5,15],[1,1.13,5.53],[2,1.05,200]],"ltp":0.0,"tv":0.0,"id":61044843}]}]}
{"op":"mcm","clk":"11972945383","pt":1724711649382,"mc":[{"id":"1.232283863","rc":[{"batb":[[0,1.06,141.77],[1,1.05,200],[2,1.04,250]],"ltp":0.0,"tv":0.0,"id":8858694},{"batb":[[0,1.51,16.68],[1,1.5,15],[2,1.13,5.53]],"ltp":0.0,"tv":0.0,"id":61044843}]}]}
{"op":"mcm","clk":"11973047093","pt":1724713451116,"mc":[{"id":"1.232283863","rc":[{"batb":[[0,1.05,200],[1,1.04,250],[2,1.03,533.33]],"ltp":0.0,"tv":0.0,"id":8858694},{"batb":[[0,1.5,15],[1,1.13,5.53],[2,1.05,200]],"ltp":0.0,"tv":0.0,"id":61044843}]}]}
{"op":"mcm","clk":"11973050217","pt":1724713501592,"mc":[{"id":"1.232283863","rc":[{"batb":[[0,1.06,141.81],[1,1.05,200],[2,1.04,250]],"ltp":0.0,"tv":0.0,"id":8858694},{"batb":[[0,1.51,16.68],[1,1.5,15],[2,1.13,5.53]],"ltp":0.0,"tv":0.0,"id":61044843}]}]}
{"op":"mcm","clk":"11973175173","pt":1724715303520,"mc":[{"id":"1.232283863","rc":[{"batb":[[0,1.05,200],[1,1.04,250],[2,1.03,533.33]],"ltp":0.0,"tv":0.0,"id":8858694}]}]}
{"op":"mcm","clk":"11973175182","pt":1724715303728,"mc":[{"id":"1.232283863","rc":[{"batb":[[0,1.5,15],[1,1.13,5.53],[2,1.05,200]],"ltp":0.0,"tv":0.0,"id":61044843}]}]}
{"op":"mcm","clk":"11973177383","pt":1724715340995,"mc":[{"id":"1.232283863","rc":[{"batb":[[0,1.06,141.81],[1,1.05,200],[2,1.04,250]],"ltp":0.0,"tv":0.0,"id":8858694},{"batb":[[0,1.51,16.68],[1,1.5,15],[2,1.13,5.53]],"ltp":0.0,"tv":0.0,"id":61044843}]}]}
{"op":"mcm","clk":"11973254243","pt":1724717142468,"mc":[{"id":"1.232283863","rc":[{"batb":[[0,1.05,200],[1,1.04,250],[2,1.03,533.33]],"ltp":0.0,"tv":0.0,"id":8858694},{"batb":[[0,1.5,15],[1,1.13,5.53],[2,1.05,200]],"ltp":0.0,"tv":0.0,"id":61044843}]}]}
{"op":"mcm","clk":"11973254948","pt":1724717163814,"mc":[{"id":"1.232283863","rc":[{"batb":[[0,1.06,141.8],[1,1.05,200],[2,1.04,250]],"ltp":0.0,"tv":0.0,"id":8858694},{"batb":[[0,1.51,16.68],[1,1.5,15],[2,1.13,5.53]],"ltp":0.0,"tv":0.0,"id":61044843}]}]}
{"op":"mcm","clk":"11973321094","pt":1724718964344,"mc":[{"id":"1.232283863","rc":[{"batb":[[0,1.05,200],[1,1.04,250],[2,1.03,533.33]],"ltp":0.0,"tv":0.0,"id":8858694},{"batb":[[0,1.5,15],[1,1.13,5.53],[2,1.05,200]],"ltp":0.0,"tv":0.0,"id":61044843}]}]}
{"op":"mcm","clk":"11973321462","pt":1724718974756,"mc":[{"id":"1.232283863","rc":[{"batb":[[0,1.06,141.8],[1,1.05,200],[2,1.04,250]],"ltp":0.0,"tv":0.0,"id":8858694},{"batb":[[0,1.51,16.68],[1,1.5,15],[2,1.13,5.53]],"ltp":0.0,"tv":0.0,"id":61044843}]}]}
{"op":"mcm","clk":"11973393106","pt":1724720775153,"mc":[{"id":"1.232283863","rc":[{"batb":[[0,1.05,200],[1,1.04,250],[2,1.03,533.33]],"ltp":0.0,"tv":0.0,"id":8858694},{"batb":[[0,1.5,15],[1,1.13,5.53],[2,1.05,200]],"ltp":0.0,"tv":0.0,"id":61044843}]}]}
{"op":"mcm","clk":"11973393293","pt":1724720779075,"mc":[{"id":"1.232283863","rc":[{"batb":[[0,1.06,141.85],[1,1.05,200],[2,1.04,250]],"ltp":0.0,"tv":0.0,"id":8858694},{"batb":[[0,1.51,16.69],[1,1.5,15],[2,1.13,5.53]],"ltp":0.0,"tv":0.0,"id":61044843}]}]}
{"op":"mcm","clk":"11973459643","pt":1724722582381,"mc":[{"id":"1.232283863","rc":[{"batb":[[0,1.05,200],[1,1.04,250],[2,1.03,533.33]],"ltp":0.0,"tv":0.0,"id":8858694},{"batb":[[0,1.5,15],[1,1.13,5.53],[2,1.05,200]],"ltp":0.0,"tv":0.0,"id":61044843}]}]}
{"op":"mcm","clk":"11973465269","pt":1724722712161,"mc":[{"id":"1.232283863","rc":[{"batb":[[0,1.06,141.85],[1,1.05,200],[2,1.04,250]],"ltp":0.0,"tv":0.0,"id":8858694},{"batb":[[0,1.51,16.69],[1,1.5,15],[2,1.13,5.53]],"ltp":0.0,"tv":0.0,"id":61044843}]}]}
{"op":"mcm","clk":"11973542383","pt":1724724512507,"mc":[{"id":"1.232283863","rc":[{"batb":[[0,1.06,141.83]],"ltp":0.0,"tv":0.0,"id":8858694},{"batb":[[0,1.5,15],[1,1.13,5.52],[2,1.05,200]],"ltp":0.0,"tv":0.0,"id":61044843}]}]}
{"op":"mcm","clk":"11973542392","pt":1724724512711,"mc":[{"id":"1.232283863","rc":[{"batb":[[0,1.05,200],[1,1.04,250],[2,1.03,533.33]],"ltp":0.0,"tv":0.0,"id":8858694}]}]}
{"op":"mcm","clk":"11973547131","pt":1724724621269,"mc":[{"id":"1.232283863","rc":[{"batb":[[0,1.06,141.83],[1,1.05,200],[2,1.04,250]],"ltp":0.0,"tv":0.0,"id":8858694},{"batb":[[0,1.51,16.69],[1,1.5,15],[2,1.13,5.52]],"ltp":0.0,"tv":0.0,"id":61044843}]}]}
{"op":"mcm","clk":"11973638485","pt":1724726421653,"mc":[{"id":"1.232283863","rc":[{"batb":[[0,1.5,15],[1,1.13,5.52],[2,1.05,200]],"ltp":0.0,"tv":0.0,"id":61044843}]}]}
{"op":"mcm","clk":"11973638492","pt":1724726421857,"mc":[{"id":"1.232283863","rc":[{"batb":[[0,1.05,200],[1,1.04,250],[2,1.03,533.33]],"ltp":0.0,"tv":0.0,"id":8858694}]}]}
{"op":"mcm","clk":"11973642864","pt":1724726513833,"mc":[{"id":"1.232283863","rc":[{"batb":[[0,1.06,141.83],[1,1.05,200],[2,1.04,250]],"ltp":0.0,"tv":0.0,"id":8858694},{"batb":[[0,1.51,16.69],[1,1.5,15],[2,1.13,5.52]],"ltp":0.0,"tv":0.0,"id":61044843}]}]}
{"op":"mcm","clk":"11973696351","pt":1724728097777,"mc":[{"id":"1.232283863","rc":[{"batb":[[0,1.06,141.85]],"ltp":0.0,"tv":0.0,"id":8858694},{"batb":[[0,1.51,16.69],[2,1.05,200]],"ltp":0.0,"tv":0.0,"id":61044843}]}]}
{"op":"mcm","clk":"11973696928","pt":1724728116716,"mc":[{"id":"1.232283863","rc":[{"batl":[[0,2.52,0.93]],"ltp":0.0,"tv":0.0,"id":8858694}]}]}
{"op":"mcm","clk":"11973702094","pt":1724728314634,"mc":[{"id":"1.232283863","rc":[{"batb":[[0,1.5,15],[1,1.05,200],[2,1.04,250]],"ltp":0.0,"tv":0.0,"id":61044843}]}]}
{"op":"mcm","clk":"11973702104","pt":1724728314821,"mc":[{"id":"1.232283863","rc":[{"batb":[[0,1.05,200],[1,1.04,250],[2,1.03,533.33]],"ltp":0.0,"tv":0.0,"id":8858694}]}]}
{"op":"mcm","clk":"11973703997","pt":1724728380591,"mc":[{"id":"1.232283863","rc":[{"batb":[[0,1.06,141.85],[1,1.05,200],[2,1.04,250]],"ltp":0.0,"tv":0.0,"id":8858694},{"batb":[[0,1.51,16.69],[1,1.5,15],[2,1.05,200]],"ltp":0.0,"tv":0.0,"id":61044843}]}]}
{"op":"mcm","clk":"11973756872","pt":1724730181463,"mc":[{"id":"1.232283863","rc":[{"batb":[[0,1.05,200],[1,1.04,250],[2,1.03,533.33]],"ltp":0.0,"tv":0.0,"id":8858694},{"batb":[[0,1.5,15],[1,1.05,200],[2,1.04,250]],"ltp":0.0,"tv":0.0,"id":61044843}]}]}
{"op":"mcm","clk":"11973757749","pt":1724730231515,"mc":[{"id":"1.232283863","rc":[{"batb":[[0,1.06,141.85],[1,1.05,200],[2,1.04,250]],"ltp":0.0,"tv":0.0,"id":8858694},{"batb":[[0,1.51,16.69],[1,1.5,15],[2,1.05,200]],"ltp":0.0,"tv":0.0,"id":61044843}]}]}
{"op":"mcm","clk":"11973762786","pt":1724730495686,"mc":[{"id":"1.232283863","rc":[{"batb":[[0,1.51,17.57]],"ltp":0.0,"tv":0.0,"id":61044843}]}]}
{"op":"mcm","clk":"11973798409","pt":1724732032566,"mc":[{"id":"1.232283863","rc":[{"batb":[[0,1.05,200],[1,1.04,250],[2,1.03,533.33]],"ltp":0.0,"tv":0.0,"id":8858694},{"batb":[[0,1.5,15.88],[1,1.05,200],[2,1.04,250]],"ltp":0.0,"tv":0.0,"id":61044843}]}]}
{"op":"mcm","clk":"11973799271","pt":1724732070772,"mc":[{"id":"1.232283863","rc":[{"batb":[[0,1.06,141.84],[1,1.05,200],[2,1.04,250]],"ltp":0.0,"tv":0.0,"id":8858694},{"batb":[[0,1.66,13.78],[1,1.5,15],[2,1.05,200]],"ltp":0.0,"tv":0.0,"id":61044843}]}]}
{"op":"mcm","clk":"11973826800","pt":1724733871475,"mc":[{"id":"1.232283863","rc":[{"batb":[[0,1.5,15.88],[1,1.05,200],[2,1.04,250]],"ltp":0.0,"tv":0.0,"id":61044843}]}]}
{"op":"mcm","clk":"11973826803","pt":1724733871677,"mc":[{"id":"1.232283863","rc":[{"batb":[[0,1.05,200],[1,1.04,250],[2,1.03,533.33]],"ltp":0.0,"tv":0.0,"id":8858694}]}]}
{"op":"mcm","clk":"11973827204","pt":1724733895286,"mc":[{"id":"1.232283863","rc":[{"batb":[[0,1.06,141.84],[1,1.05,200],[2,1.04,250]],"ltp":0.0,"tv":0.0,"id":8858694},{"batb":[[0,1.66,13.78],[1,1.5,15],[2,1.05,200]],"ltp":0.0,"tv":0.0,"id":61044843}]}]}
{"op":"mcm","clk":"11973852953","pt":1724735574793,"mc":[{"id":"1.232283863","rc":[{"batb":[[0,1.06,141.83]],"ltp":0.0,"tv":0.0,"id":8858694},{"batb":[[0,1.66,13.77]],"ltp":0.0,"tv":0.0,"id":61044843}]}]}
{"op":"mcm","clk":"11973863140","pt":1724735696457,"mc":[{"id":"1.232283863","rc":[{"batb":[[0,1.05,200],[1,1.04,250],[2,1.03,533.33]],"ltp":0.0,"tv":0.0,"id":8858694},{"batb":[[0,1.5,15.88],[1,1.05,200],[2,1.04,250]],"ltp":0.0,"tv":0.0,"id":61044843}]}]}
{"op":"mcm","clk":"11973863427","pt":1724735720451,"mc":[{"id":"1.232283863","rc":[{"batb":[[0,1.06,141.83],[1,1.05,200],[2,1.04,250]],"ltp":0.0,"tv":0.0,"id":8858694},{"batb":[[0,1.66,13.77],[1,1.5,15],[2,1.05,200]],"ltp":0.0,"tv":0.0,"id":61044843}]}]}
{"op":"mcm","clk":"11973864385","pt":1724735785825,"mc":[{"id":"1.232283863","rc":[{"batl":[[0,2.52,2.23]],"ltp":0.0,"tv":0.0,"id":8858694}]}]}
{"op":"mcm","clk":"11973889194","pt":1724737520985,"mc":[{"id":"1.232283863","rc":[{"batb":[[0,1.05,200],[1,1.04,250],[2,1.03,533.33]],"ltp":0.0,"tv":0.0,"id":8858694},{"batb":[[0,1.5,15.88],[1,1.05,200],[2,1.04,250]],"ltp":0.0,"tv":0.0,"id":61044843}]}]}
{"op":"mcm","clk":"11973889453","pt":1724737533429,"mc":[{"id":"1.232283863","rc":[{"batb":[[0,1.06,141.83],[1,1.05,200],[2,1.04,250]],"ltp":0.0,"tv":0.0,"id":8858694},{"batb":[[0,1.66,13.77],[1,1.5,15],[2,1.05,200]],"ltp":0.0,"tv":0.0,"id":61044843}]}]}
{"op":"mcm","clk":"11973923259","pt":1724739334948,"mc":[{"id":"1.232283863","rc":[{"batb":[[0,1.05,200],[1,1.04,250],[2,1.03,533.33]],"ltp":0.0,"tv":0.0,"id":8858694},{"batb":[[0,1.5,15.88],[1,1.05,200],[2,1.04,250]],"ltp":0.0,"tv":0.0,"id":61044843}]}]}
{"op":"mcm","clk":"11973923386","pt":1724739343243,"mc":[{"id":"1.232283863","rc":[{"batb":[[0,1.06,141.78],[1,1.05,200],[2,1.04,250]],"ltp":0.0,"tv":0.0,"id":8858694},{"batb":[[0,1.66,13.77],[1,1.5,15],[2,1.05,200]],"ltp":0.0,"tv":0.0,"id":61044843}]}]}
{"op":"mcm","clk":"11973965652","pt":1724741143522,"mc":[{"id":"1.232283863","rc":[{"batb":[[0,1.05,200],[1,1.04,250],[2,1.03,533.33]],"ltp":0.0,"tv":0.0,"id":8858694}]}]}
{"op":"mcm","clk":"11973965656","pt":1724741143726,"mc":[{"id":"1.232283863","rc":[{"batb":[[0,1.5,15.88],[1,1.05,200],[2,1.04,250]],"ltp":0.0,"tv":0.0,"id":61044843}]}]}
{"op":"mcm","clk":"11973965921","pt":1724741154073,"mc":[{"id":"1.232283863","rc":[{"batb":[[0,1.06,141.78],[1,1.05,200],[2,1.04,250]],"ltp":0.0,"tv":0.0,"id":8858694},{"batb":[[0,1.66,13.77],[1,1.5,15],[2,1.05,200]],"ltp":0.0,"tv":0.0,"id":61044843}]}]}
{"op":"mcm","clk":"11974011467","pt":1724742954542,"mc":[{"id":"1.232283863","rc":[{"batb":[[0,1.05,200],[1,1.04,250],[2,1.03,533.33]],"ltp":0.0,"tv":0.0,"id":8858694},{"batb":[[0,1.66,13.77]],"ltp":0.0,"tv":0.0,"id":61044843}]}]}
{"op":"mcm","clk":"11974011473","pt":1724742954748,"mc":[{"id":"1.232283863","rc":[{"batb":[[0,1.5,15.88],[1,1.05,200],[2,1.04,250]],"ltp":0.0,"tv":0.0,"id":61044843}]}]}
{"op":"mcm","clk":"11974011773","pt":1724742963753,"mc":[{"id":"1.232283863","rc":[{"batb":[[0,1.06,141.74],[1,1.05,200],[2,1.04,250]],"ltp":0.0,"tv":0.0,"id":8858694},{"batb":[[0,1.66,13.77],[1,1.5,15],[2,1.05,200]],"ltp":0.0,"tv":0.0,"id":61044843}]}]}
{"op":"mcm","clk":"11974073068","pt":1724744765043,"mc":[{"id":"1.232283863","rc":[{"batb":[[0,1.05,200],[1,1.04,250],[2,1.03,533.33]],"ltp":0.0,"tv":0.0,"id":8858694},{"batb":[[0,1.5,15.88],[1,1.05,200],[2,1.04,250]],"ltp":0.0,"tv":0.0,"id":61044843}]}]}
{"op":"mcm","clk":"11974073413","pt":1724744774777,"mc":[{"id":"1.232283863","rc":[{"batb":[[0,1.06,141.74],[1,1.05,200],[2,1.04,250]],"ltp":0.0,"tv":0.0,"id":8858694},{"batb":[[0,1.66,13.77],[1,1.5,15],[2,1.05,200]],"ltp":0.0,"tv":0.0,"id":61044843}]}]}
{"op":"mcm","clk":"11974134833","pt":1724746374794,"mc":[{"id":"1.232283863","rc":[{"batb":[[0,1.06,141.71]],"ltp":0.0,"tv":0.0,"id":8858694},{"batb":[[0,1.66,13.76]],"ltp":0.0,"tv":0.0,"id":61044843}]}]}
{"op":"mcm","clk":"11974151873","pt":1724746575315,"mc":[{"id":"1.232283863","rc":[{"batb":[[0,1.05,200],[1,1.04,250],[2,1.03,533.33]],"ltp":0.0,"tv":0.0,"id":8858694},{"batb":[[0,1.5,15.88],[1,1.05,200],[2,1.04,250]],"ltp":0.0,"tv":0.0,"id":61044843}]}]}
{"op":"mcm","clk":"11974152219","pt":1724746582994,"mc":[{"id":"1.232283863","rc":[{"batb":[[0,1.06,141.71],[1,1.05,200],[2,1.04,250]],"ltp":0.0,"tv":0.0,"id":8858694},{"batb":[[0,1.66,13.76],[1,1.5,15],[2,1.05,200]],"ltp":0.0,"tv":0.0,"id":61044843}]}]}
{"op":"mcm","clk":"11974170861","pt":1724747113255,"mc":[{"id":"1.232283863","rc":[{"batl":[[0,1.9,30],[1,2.52,2.23]],"ltp":0.0,"tv":0.0,"id":8858694}]}]}
{"op":"mcm","clk":"11974224679","pt":1724748384389,"mc":[{"id":"1.232283863","rc":[{"batb":[[0,1.05,200],[1,1.04,250],[2,1.03,533.33]],"ltp":0.0,"tv":0.0,"id":8858694},{"batb":[[0,1.5,15.88],[1,1.05,200],[2,1.04,250]],"ltp":0.0,"tv":0.0,"id":61044843}]}]}
{"op":"mcm","clk":"11974224915","pt":1724748390090,"mc":[{"id":"1.232283863","rc":[{"batb":[[0,1.06,141.71],[1,1.05,200],[2,1.04,250]],"ltp":0.0,"tv":0.0,"id":8858694},{"batb":[[0,2.12,7.59],[1,1.5,15.88],[2,1.05,200]],"ltp":0.0,"tv":0.0,"id":61044843}]}]}
{"op":"mcm","clk":"11974307879","pt":1724750191220,"mc":[{"id":"1.232283863","rc":[{"batb":[[0,1.05,200],[1,1.04,250],[2,1.03,533.33]],"batl":[[1,2.52,2.22]],"ltp":0.0,"tv":0.0,"id":8858694},{"batb":[[0,1.5,15.88],[1,1.05,200],[2,1.04,250]],"ltp":0.0,"tv":0.0,"id":61044843}]}]}
{"op":"mcm","clk":"11974308129","pt":1724750196565,"mc":[{"id":"1.232283863","rc":[{"batb":[[0,1.06,141.55],[1,1.05,200],[2,1.04,250]],"ltp":0.0,"tv":0.0,"id":8858694},{"batb":[[0,2.12,7.58],[1,1.5,15.88],[2,1.05,200]],"ltp":0.0,"tv":0.0,"id":61044843}]}]}
{"op":"mcm","clk":"11974336239","pt":1724750729865,"mc":[{"id":"1.232283863","rc":[{"batl":[[1,2.52,0]],"ltp":0.0,"tv":0.0,"id":8858694}]}]}
{"op":"mcm","clk":"11974421236","pt":1724751997090,"mc":[{"id":"1.232283863","rc":[{"batb":[[0,1.05,200],[1,1.04,250],[2,1.03,533.33]],"ltp":0.0,"tv":0.0,"id":8858694},{"batb":[[0,1.5,15.88],[1,1.05,200],[2,1.04,250]],"ltp":0.0,"tv":0.0,"id":61044843}]}]}
{"op":"mcm","clk":"11974428642","pt":1724752134241,"mc":[{"id":"1.232283863","rc":[{"batb":[[0,1.06,141.55],[1,1.05,200],[2,1.04,250]],"ltp":0.0,"tv":0.0,"id":8858694},{"batb":[[0,2.12,7.58],[1,1.5,15.88],[2,1.05,200]],"ltp":0.0,"tv":0.0,"id":61044843}]}]}
{"op":"mcm","clk":"11974549872","pt":1724753935282,"mc":[{"id":"1.232283863","rc":[{"batb":[[0,1.05,200],[1,1.04,250],[2,1.03,533.33]],"ltp":0.0,"tv":0.0,"id":8858694},{"batb":[[0,1.5,15.88],[1,1.05,200],[2,1.04,250]],"ltp":0.0,"tv":0.0,"id":61044843}]}]}
{"op":"mcm","clk":"11974559019","pt":1724754070749,"mc":[{"id":"1.232283863","rc":[{"batb":[[0,1.06,141.37],[1,1.05,200],[2,1.04,250]],"ltp":0.0,"tv":0.0,"id":8858694},{"batb":[[0,2.12,7.57],[1,1.5,15.88],[2,1.05,200]],"ltp":0.0,"tv":0.0,"id":61044843}]}]}
{"op":"mcm","clk":"11974682603","pt":1724755871305,"mc":[{"id":"1.232283863","rc":[{"batb":[[0,1.05,200],[1,1.04,250],[2,1.03,533.33]],"ltp":0.0,"tv":0.0,"id":8858694},{"batb":[[0,1.5,15.88],[1,1.05,200],[2,1.04,250]],"ltp":0.0,"tv":0.0,"id":61044843}]}]}
{"op":"mcm","clk":"11974690704","pt":1724756006034,"mc":[{"id":"1.232283863","rc":[{"batb":[[0,1.06,141.37],[1,1.05,200],[2,1.04,250]],"ltp":0.0,"tv":0.0,"id":8858694},{"batb":[[0,2.12,7.57],[1,1.5,15.88],[2,1.05,200]],"ltp":0.0,"tv":0.0,"id":61044843}]}]}
{"op":"mcm","clk":"11974767032","pt":1724757174806,"mc":[{"id":"1.232283863","rc":[{"batb":[[0,1.06,141.56]],"ltp":0.0,"tv":0.0,"id":8858694},{"batb":[[0,2.12,7.58],[1,1.5,15.88]],"ltp":0.0,"tv":0.0,"id":61044843}]}]}
{"op":"mcm","clk":"11974811344","pt":1724757806484,"mc":[{"id":"1.232283863","rc":[{"batb":[[0,1.05,200],[1,1.04,250],[2,1.03,533.33]],"ltp":0.0,"tv":0.0,"id":8858694},{"batb":[[0,1.5,15.88],[1,1.05,200],[2,1.04,250]],"ltp":0.0,"tv":0.0,"id":61044843}]}]}
{"op":"mcm","clk":"11974818593","pt":1724757930295,"mc":[{"id":"1.232283863","rc":[{"batb":[[0,1.06,141.56],[1,1.05,200],[2,1.04,250]],"ltp":0.0,"tv":0.0,"id":8858694},{"batb":[[0,2.12,7.58],[1,1.5,15.88],[2,1.05,200]],"ltp":0.0,"tv":0.0,"id":61044843}]}]}
{"op":"mcm","clk":"11974910490","pt":1724759410721,"mc":[{"id":"1.232283863","rc":[{"batb":[[1,1.5,15]],"ltp":0.0,"tv":0.0,"id":61044843}]}]}
{"op":"mcm","clk":"11974931189","pt":1724759730874,"mc":[{"id":"1.232283863","rc":[{"batb":[[0,1.05,200],[1,1.04,250],[2,1.03,533.33]],"ltp":0.0,"tv":0.0,"id":8858694},{"batb":[[0,1.5,15],[1,1.05,200],[2,1.04,250]],"ltp":0.0,"tv":0.0,"id":61044843}]}]}
{"op":"mcm","clk":"11974938284","pt":1724759843712,"mc":[{"id":"1.232283863","rc":[{"batb":[[0,1.06,141.56],[1,1.05,200],[2,1.04,250]],"ltp":0.0,"tv":0.0,"id":8858694},{"batb":[[0,2.12,7.58],[1,1.5,15],[2,1.05,200]],"ltp":0.0,"tv":0.0,"id":61044843}]}]}
{"op":"mcm","clk":"11974977568","pt":1724760356190,"mc":[{"id":"1.232283863","rc":[{"batb":[[0,1.06,141.45]],"ltp":0.0,"tv":0.0,"id":8858694},{"batb":[[0,2.12,7.58],[1,1.05,200],[2,1.04,250]],"ltp":0.0,"tv":0.0,"id":61044843}]}]}
{"op":"mcm","clk":"11974978163","pt":1724760363108,"mc":[{"id":"1.232283863","rc":[{"batl":[[0,1.49,10],[1,1.9,30]],"ltp":0.0,"tv":0.0,"id":8858694}]}]}
{"op":"mcm","clk":"11974996091","pt":1724760579751,"mc":[{"id":"1.232283863","rc":[{"batl":[[0,1.35,10],[1,1.49,10],[2,1.9,30]],"ltp":0.0,"tv":0.0,"id":8858694}]}]}
{"op":"mcm","clk":"11975079277","pt":1724761644262,"mc":[{"id":"1.232283863","rc":[{"batb":[[0,1.05,200],[1,1.04,250],[2,1.03,533.33]],"ltp":0.0,"tv":0.0,"id":8858694},{"batb":[[0,1.05,200],[1,1.04,250],[2,1.03,533.33]],"ltp":0.0,"tv":0.0,"id":61044843}]}]}
{"op":"mcm","clk":"11975118390","pt":1724762122549,"mc":[{"id":"1.232283863","rc":[{"batl":[[0,1.49,10],[1,1.9,30],[2,1.9,0]],"ltp":0.0,"tv":0.0,"id":8858694}]}]}
{"op":"mcm","clk":"11975120578","pt":1724762151368,"mc":[{"id":"1.232283863","rc":[{"batb":[[0,1.06,141.45],[1,1.05,200],[2,1.04,250]],"ltp":0.0,"tv":0.0,"id":8858694},{"batb":[[0,3.05,4.14],[1,1.05,200],[2,1.04,250]],"ltp":0.0,"tv":0.0,"id":61044843}]}]}
{"op":"mcm","clk":"11975243512","pt":1724763774683,"mc":[{"id":"1.232283863","rc":[{"batb":[[0,1.06,141.49]],"batl":[[0,1.49,10.92]],"ltp":0.0,"tv":0.0,"id":8858694},{"batb":[[0,3.05,4.14]],"ltp":0.0,"tv":0.0,"id":61044843}]}]}
{"op":"mcm","clk":"11975256821","pt":1724763951632,"mc":[{"id":"1.232283863","rc":[{"batb":[[0,1.05,200],[1,1.04,250],[2,1.03,533.33]],"ltp":0.0,"tv":0.0,"id":61044843}]}]}
{"op":"mcm","clk":"11975256830","pt":1724763951842,"mc":[{"id":"1.232283863","rc":[{"batb":[[0,1.05,200],[1,1.04,250],[2,1.03,533.33]],"ltp":0.0,"tv":0.0,"id":8858694}]}]}
{"op":"mcm","clk":"11975263405","pt":1724764038791,"mc":[{"id":"1.232283863","rc":[{"batb":[[0,1.06,141.49],[1,1.05,200],[2,1.04,250]],"ltp":0.0,"tv":0.0,"id":8858694},{"batb":[[0,3.05,4.14],[1,1.05,200],[2,1.04,250]],"ltp":0.0,"tv":0.0,"id":61044843}]}]}
{"op":"mcm","clk":"11975419708","pt":1724765839116,"mc":[{"id":"1.232283863","rc":[{"batb":[[0,1.05,200],[1,1.04,250],[2,1.03,533.33]],"ltp":0.0,"tv":0.0,"id":8858694},{"batb":[[0,1.05,200],[1,1.04,250],[2,1.03,533.33]],"ltp":0.0,"tv":0.0,"id":61044843}]}]}
{"op":"mcm","clk":"11975424935","pt":1724765885730,"mc":[{"id":"1.232283863","rc":[{"batb":[[0,1.06,141.49],[1,1.05,200],[2,1.04,250]],"ltp":0.0,"tv":0.0,"id":8858694},{"batb":[[0,3.05,4.14],[1,1.05,200],[2,1.04,250]],"ltp":0.0,"tv":0.0,"id":61044843}]}]}
{"op":"mcm","clk":"11975577552","pt":1724767686132,"mc":[{"id":"1.232283863","rc":[{"batb":[[0,1.05,200],[1,1.04,250],[2,1.03,533.33]],"batl":[[0,1.49,10.92]],"ltp":0.0,"tv":0.0,"id":8858694},{"batb":[[0,1.05,200],[1,1.04,250],[2,1.03,533.33]],"ltp":0.0,"tv":0.0,"id":61044843}]}]}
{"op":"mcm","clk":"11975588617","pt":1724767837159,"mc":[{"id":"1.232283863","rc":[{"batb":[[0,1.06,141.45],[1,1.05,200],[2,1.04,250]],"ltp":0.0,"tv":0.0,"id":8858694},{"batb":[[0,3.05,4.14],[1,1.05,200],[2,1.04,250]],"ltp":0.0,"tv":0.0,"id":61044843}]}]}
{"op":"mcm","clk":"11975731046","pt":1724769295353,"mc":[{"id":"1.232283863","rc":[{"batb":[[2,1.04,251.05]],"ltp":0.0,"tv":0.0,"id":8858694},{"batb":[[2,1.04,251.05]],"ltp":0.0,"tv":0.0,"id":61044843}]}]}
{"op":"mcm","clk":"11975761429","pt":1724769637509,"mc":[{"id":"1.232283863","rc":[{"batb":[[0,1.05,200],[1,1.04,251.05],[2,1.03,533.33]],"ltp":0.0,"tv":0.0,"id":8858694},{"batb":[[0,1.05,200],[1,1.04,251.05],[2,1.03,533.33]],"ltp":0.0,"tv":0.0,"id":61044843}]}]}
{"op":"mcm","clk":"11975778108","pt":1724769786265,"mc":[{"id":"1.232283863","rc":[{"batb":[[0,1.06,141.45],[1,1.05,200],[2,1.04,251.05]],"ltp":0.0,"tv":0.0,"id":8858694},{"batb":[[0,3.05,4.14],[1,1.05,200],[2,1.04,251.05]],"ltp":0.0,"tv":0.0,"id":61044843}]}]}
{"op":"mcm","clk":"11975970028","pt":1724771586598,"mc":[{"id":"1.232283863","rc":[{"batb":[[0,1.05,200],[1,1.04,251.05],[2,1.03,533.33]],"ltp":0.0,"tv":0.0,"id":8858694},{"batb":[[0,1.05,200],[1,1.04,251.05],[2,1.03,533.33]],"ltp":0.0,"tv":0.0,"id":61044843}]}]}
{"op":"mcm","clk":"11975988174","pt":1724771715760,"mc":[{"id":"1.232283863","rc":[{"batb":[[0,1.06,141.39],[1,1.05,200],[2,1.04,251.05]],"ltp":0.0,"tv":0.0,"id":8858694},{"batb":[[0,3.05,4.14],[1,1.05,200],[2,1.04,251.05]],"ltp":0.0,"tv":0.0,"id":61044843}]}]}
{"op":"mcm","clk":"11976109921","pt":1724772736053,"mc":[{"id":"1.232283863","rc":[{"batl":[[0,1.49,10]],"ltp":0.0,"tv":0.0,"id":8858694}]}]}
{"op":"mcm","clk":"11976206924","pt":1724773516072,"mc":[{"id":"1.232283863","rc":[{"batb":[[0,1.05,200],[1,1.04,251.05],[2,1.03,533.33]],"ltp":0.0,"tv":0.0,"id":8858694},{"batb":[[0,1.05,200],[1,1.04,251.05],[2,1.03,533.33]],"ltp":0.0,"tv":0.0,"id":61044843}]}]}
{"op":"mcm","clk":"11976222126","pt":1724773636309,"mc":[{"id":"1.232283863","rc":[{"batb":[[0,1.06,141.39],[1,1.05,200],[2,1.04,251.05]],"ltp":0.0,"tv":0.0,"id":8858694},{"batb":[[0,3.05,4.14],[1,1.05,200],[2,1.04,251.05]],"ltp":0.0,"tv":0.0,"id":61044843}]}]}
{"op":"mcm","clk":"11976431939","pt":1724775436581,"mc":[{"id":"1.232283863","rc":[{"batb":[[0,1.05,200],[1,1.04,251.05],[2,1.03,533.33]],"ltp":0.0,"tv":0.0,"id":8858694},{"batb":[[0,1.05,200],[1,1.04,251.05],[2,1.03,533.33]],"ltp":0.0,"tv":0.0,"id":61044843}]}]}
{"op":"mcm","clk":"11976443704","pt":1724775546223,"mc":[{"id":"1.232283863","rc":[{"batb":[[0,1.06,141.31],[1,1.05,200],[2,1.04,251.05]],"ltp":0.0,"tv":0.0,"id":8858694},{"batb":[[0,3.05,4.14],[1,1.05,200],[2,1.04,251.05]],"ltp":0.0,"tv":0.0,"id":61044843}]}]}
{"op":"mcm","clk":"11976454626","pt":1724775642534,"mc":[{"id":"1.232283863","rc":[{"batl":[[1,1.8,1],[2,1.9,30]],"ltp":0.0,"tv":0.0,"id":8858694}]}]}
{"op":"mcm","clk":"11976461476","pt":1724775697900,"mc":[{"id":"1.232283863","rc":[{"batl":[[1,1.7,1]],"ltp":0.0,"tv":0.0,"id":8858694}]}]}
{"op":"mcm","clk":"11976463494","pt":1724775716002,"mc":[{"id":"1.232283863","rc":[{"batl":[[1,1.6,1]],"ltp":0.0,"tv":0.0,"id":8858694}]}]}
{"op":"mcm","clk":"11976466264","pt":1724775740411,"mc":[{"id":"1.232283863","rc":[{"batl":[[1,1.9,30],[2,1.9,0]],"ltp":0.0,"tv":0.0,"id":8858694}]}]}
{"op":"mcm","clk":"11976468693","pt":1724775762359,"mc":[{"id":"1.232283863","rc":[{"batl":[[1,1.5,1],[2,1.9,30]],"ltp":0.0,"tv":0.0,"id":8858694}]}]}
{"op":"mcm","clk":"11976469907","pt":1724775773091,"mc":[{"id":"1.232283863","rc":[{"batl":[[1,1.9,30],[2,20,1]],"ltp":0.0,"tv":0.0,"id":8858694}]}]}
{"op":"mcm","clk":"11976472227","pt":1724775794028,"mc":[{"id":"1.232283863","rc":[{"batl":[[2,20,0]],"ltp":0.0,"tv":0.0,"id":8858694}]}]}
{"op":"mcm","clk":"11976473852","pt":1724775807333,"mc":[{"id":"1.232283863","rc":[{"trd":[[1.49,2]],"batl":[[0,1.49,9]],"ltp":1.49,"tv":2.0,"id":8858694}],"tv":2.0}]}
{"op":"mcm","clk":"11976476435","pt":1724775829137,"mc":[{"id":"1.232283863","rc":[{"batb":[[0,1.2,1],[1,1.06,141.31],[2,1.05,200]],"ltp":1.49,"tv":2.0,"id":8858694}]}]}
{"op":"mcm","clk":"11976478241","pt":1724775843357,"mc":[{"id":"1.232283863","rc":[{"batb":[[0,1.3,1]],"ltp":1.49,"tv":2.0,"id":8858694}]}]}
{"op":"mcm","clk":"11976540627","pt":1724776349700,"mc":[{"id":"1.232283863","rc":[{"trd":[[1.3,0.14]],"batb":[[0,1.06,142.24],[1,1.05,200],[2,1.04,251.05]],"ltp":1.3,"tv":2.14,"id":8858694}],"tv":2.14}]}
{"op":"mcm","clk":"11976671484","pt":1724777346440,"mc":[{"id":"1.232283863","rc":[{"batb":[[0,1.05,200.93],[1,1.04,251.05],[2,1.03,533.33]],"ltp":1.3,"tv":2.14,"id":8858694},{"batb":[[0,1.05,200],[1,1.04,251.05],[2,1.03,533.33]],"ltp":0.0,"tv":0.0,"id":61044843}]}]}
{"op":"mcm","clk":"11976683147","pt":1724777442418,"mc":[{"id":"1.232283863","rc":[{"batb":[[0,1.06,142.24],[1,1.05,200],[2,1.04,251.05]],"ltp":1.3,"tv":2.14,"id":8858694},{"batb":[[0,3.05,4.14],[1,1.05,200],[2,1.04,251.05]],"ltp":0.0,"tv":0.0,"id":61044843}]}]}
{"op":"mcm","clk":"11976862099","pt":1724778774814,"mc":[{"id":"1.232283863","rc":[{"batb":[[0,1.06,142.33]],"ltp":1.3,"tv":2.14,"id":8858694},{"batb":[[0,3.05,4.14]],"ltp":0.0,"tv":0.0,"id":61044843}]}]}
{"op":"mcm","clk":"11976932384","pt":1724779242486,"mc":[{"id":"1.232283863","rc":[{"batb":[[0,1.05,200.93],[1,1.04,251.05],[2,1.03,533.33]],"ltp":1.3,"tv":2.14,"id":8858694}]}]}
{"op":"mcm","clk":"11976932406","pt":1724779242697,"mc":[{"id":"1.232283863","rc":[{"batb":[[0,1.05,200],[1,1.04,251.05],[2,1.03,533.33]],"ltp":0.0,"tv":0.0,"id":61044843}]}]}
{"op":"mcm","clk":"11976940805","pt":1724779304211,"mc":[{"id":"1.232283863","rc":[{"batb":[[0,1.06,142.33],[1,1.05,200],[2,1.04,251.05]],"ltp":1.3,"tv":2.14,"id":8858694},{"batb":[[0,3.05,4.14],[1,1.05,200],[2,1.04,251.05]],"ltp":0.0,"tv":0.0,"id":61044843}]}]}
{"op":"mcm","clk":"11977164143","pt":1724781104472,"mc":[{"id":"1.232283863","rc":[{"batb":[[0,1.05,200],[1,1.04,251.05],[2,1.03,533.33]],"ltp":0.0,"tv":0.0,"id":61044843}]}]}
{"op":"mcm","clk":"11977164162","pt":1724781104670,"mc":[{"id":"1.232283863","rc":[{"batb":[[0,1.05,200.93],[1,1.04,251.05],[2,1.03,533.33]],"ltp":1.3,"tv":2.14,"id":8858694}]}]}
{"op":"mcm","clk":"11977167104","pt":1724781132823,"mc":[{"id":"1.232283863","rc":[{"batb":[[0,1.06,142.33],[1,1.05,200],[2,1.04,251.05]],"ltp":1.3,"tv":2.14,"id":8858694},{"batb":[[0,3.05,4.14],[1,1.05,200],[2,1.04,251.05]],"ltp":0.0,"tv":0.0,"id":61044843}]}]}
{"op":"mcm","clk":"11977283823","pt":1724782174971,"mc":[{"id":"1.232283863","rc":[{"batb":[[0,1.06,142.36]],"batl":[[0,1.47,15],[1,1.49,9],[2,1.9,30]],"ltp":1.3,"tv":2.14,"id":8858694},{"batb":[[0,3.05,4.14]],"ltp":0.0,"tv":0.0,"id":61044843}]}]}
{"op":"mcm","clk":"11977290488","pt":1724782227312,"mc":[{"id":"1.232283863","rc":[{"batl":[[0,1.9,30],[1,1.49,0],[2,1.9,0]],"ltp":1.3,"tv":2.14,"id":8858694}]}]}
{"op":"mcm","clk":"11977290505","pt":1724782227786,"mc":[{"id":"1.232283863","rc":[{"batl":[[0,1.4,15],[1,1.41,9],[2,1.9,30]],"ltp":1.3,"tv":2.14,"id":8858694}]}]}
{"op":"mcm","clk":"11977307225","pt":1724782360936,"mc":[{"id":"1.232283863","rc":[{"trd":[[1.4,0.14]],"batl":[[0,1.4,14.93]],"ltp":1.4,"tv":2.28,"id":8858694}],"tv":2.28}]}
{"op":"mcm","clk":"11977376700","pt":1724782933121,"mc":[{"id":"1.232283863","rc":[{"batb":[[0,1.05,200.93],[1,1.04,251.05],[2,1.03,533.33]],"ltp":1.4,"tv":2.28,"id":8858694},{"batb":[[0,1.05,200],[1,1.04,251.05],[2,1.03,533.33]],"ltp":0.0,"tv":0.0,"id":61044843}]}]}
{"op":"mcm","clk":"11977454028","pt":1724783551949,"mc":[{"id":"1.232283863","rc":[{"trd":[[1.4,0.28]],"batl":[[0,1.4,14.86]],"ltp":1.4,"tv":2.42,"id":8858694}],"tv":2.42}]}
{"op":"mcm","clk":"11977498466","pt":1724783874757,"mc":[{"id":"1.232283863","rc":[{"trd":[[1.3,2]],"batb":[[0,1.05,200]],"batl":[[0,1.4,14.93]],"ltp":1.3,"tv":4.28,"id":8858694}],"tv":4.28}]}
{"op":"mcm","clk":"11977501438","pt":1724783896259,"mc":[{"id":"1.232283863","rc":[{"batl":[[0,1.4,14.86]],"ltp":1.3,"tv":4.28,"id":8858694}]}]}
{"op":"mcm","clk":"11977635910","pt":1724784752038,"mc":[{"id":"1.232283863","rc":[{"trd":[[1.4,0.42]],"batl":[[0,1.4,14.79]],"ltp":1.4,"tv":4.42,"id":8858694}],"tv":4.42}]}
{"op":"mcm","clk":"11977810918","pt":1724785961258,"mc":[{"id":"1.232283863","rc":[{"trd":[[1.4,0.56]],"batl":[[0,1.4,14.72]],"ltp":1.4,"tv":4.56,"id":8858694}],"tv":4.56}]}
{"op":"mcm","clk":"11977990051","pt":1724787161560,"mc":[{"id":"1.232283863","rc":[{"trd":[[1.4,0.7]],"batl":[[0,1.4,14.65]],"ltp":1.4,"tv":4.7,"id":8858694}],"tv":4.7}]}
{"op":"mcm","clk":"11978142772","pt":1724788370007,"mc":[{"id":"1.232283863","rc":[{"trd":[[1.4,0.84]],"batl":[[0,1.4,14.58]],"ltp":1.4,"tv":4.84,"id":8858694}],"tv":4.84}]}
{"op":"mcm","clk":"11978307756","pt":1724789569012,"mc":[{"id":"1.232283863","rc":[{"trd":[[1.4,0.98]],"batl":[[0,1.4,14.51]],"ltp":1.4,"tv":4.98,"id":8858694}],"tv":4.98}]}
{"op":"mcm","clk":"11978473685","pt":1724790752505,"mc":[{"id":"1.232283863","rc":[{"trd":[[1.4,1.12]],"batl":[[0,1.4,14.44]],"ltp":1.4,"tv":5.12,"id":8858694}],"tv":5.12}]}
{"op":"mcm","clk":"11978574852","pt":1724791952824,"mc":[{"id":"1.232283863","rc":[{"trd":[[1.4,1.26]],"batl":[[0,1.4,14.37]],"ltp":1.4,"tv":5.26,"id":8858694}],"tv":5.26}]}
{"op":"mcm","clk":"11978638932","pt":1724793152465,"mc":[{"id":"1.232283863","rc":[{"trd":[[1.4,1.4]],"batl":[[0,1.4,14.3]],"ltp":1.4,"tv":5.4,"id":8858694}],"tv":5.4}]}
{"op":"mcm","clk":"11978693453","pt":1724794352928,"mc":[{"id":"1.232283863","rc":[{"trd":[[1.4,1.54]],"batl":[[0,1.4,14.23]],"ltp":1.4,"tv":5.54,"id":8858694}],"tv":5.54}]}
{"op":"mcm","clk":"11978756973","pt":1724795552756,"mc":[{"id":"1.232283863","rc":[{"trd":[[1.4,1.68]],"batl":[[0,1.4,14.16]],"ltp":1.4,"tv":5.68,"id":8858694}],"tv":5.68}]}
{"op":"mcm","clk":"11978821805","pt":1724796975417,"mc":[{"id":"1.232283863","rc":[{"batl":[[0,1.39,14.16],[1,1.4,9]],"ltp":1.4,"tv":5.68,"id":8858694}]}]}
{"op":"mcm","clk":"11979732289","pt":1724818444582,"mc":[{"id":"1.232283863","rc":[{"batl":[[0,1.3,25.67],[1,1.39,14.16],[2,1.4,9]],"ltp":1.4,"tv":5.68,"id":8858694}]}]}
{"op":"mcm","clk":"11979762624","pt":1724819551719,"mc":[{"id":"1.232283863","rc":[{"trd":[[1.3,2.14]],"batl":[[0,1.3,25.59]],"ltp":1.3,"tv":5.82,"id":8858694}],"tv":5.82}]}
{"op":"mcm","clk":"11979827522","pt":1724821974799,"mc":[{"id":"1.232283863","rc":[{"batl":[[0,1.3,25.58]],"ltp":1.3,"tv":5.82,"id":8858694}]}]}
{"op":"mcm","clk":"11979959971","pt":1724825431138,"mc":[{"id":"1.232283863","rc":[{"batl":[[0,1.29,14.16],[1,1.3,25.58],[2,1.9,30]],"ltp":1.3,"tv":5.82,"id":8858694}]}]}
{"op":"mcm","clk":"11979960451","pt":1724825441041,"mc":[{"id":"1.232283863","rc":[{"batl":[[0,1.28,10],[1,1.29,14.16],[2,1.3,25.58]],"ltp":1.3,"tv":5.82,"id":8858694}]}]}
{"op":"mcm","clk":"11980172212","pt":1724830461088,"mc":[{"id":"1.232283863","rc":[{"batl":[[0,1.25,10],[1,1.26,14.16],[2,1.3,25.61]],"ltp":1.3,"tv":5.82,"id":8858694}]}]}
{"op":"mcm","clk":"11980257642","pt":1724832314221,"mc":[{"id":"1.232283863","rc":[{"trd":[[1.25,10]],"batl":[[0,1.26,14.16],[1,1.3,25.6],[2,1.9,30]],"ltp":1.25,"tv":15.82,"id":8858694},{"trd":[[5,2.5]],"batl":[[0,5,0.5]],"ltp":5.0,"tv":2.5,"id":61044843}],"tv":18.32}]}
{"op":"mcm","clk":"11980261325","pt":1724832382879,"mc":[{"id":"1.232283863","rc":[{"trd":[[1.25,12]],"ltp":1.25,"tv":17.82,"id":8858694},{"trd":[[5,3]],"ltp":5.0,"tv":3.0,"id":61044843}],"tv":20.82}]}
{"op":"mcm","clk":"11980262841","pt":1724832411231,"mc":[{"id":"1.232283863","rc":[{"batb":[[0,1.1,2],[1,1.05,200],[2,1.04,251.05]],"ltp":1.25,"tv":17.82,"id":8858694}]}]}
{"op":"mcm","clk":"11980263521","pt":1724832424415,"mc":[{"id":"1.232283863","rc":[{"trd":[[1.26,14.16]],"batl":[[0,1.3,25.6],[1,1.9,30],[2,1.9,0]],"ltp":1.26,"tv":31.98,"id":8858694},{"trd":[[4.8,3.72]],"batl":[[0,4.8,1.28]],"ltp":4.8,"tv":6.72,"id":61044843}],"tv":38.7}]}
{"op":"mcm","clk":"11980265775","pt":1724832473577,"mc":[{"id":"1.232283863","rc":[{"batl":[[0,5.1,1.28]],"ltp":4.8,"tv":6.72,"id":61044843}]}]}
{"op":"mcm","clk":"11980266948","pt":1724832498382,"mc":[{"id":"1.232283863","rc":[{"trd":[[1.24,3]],"ltp":1.24,"tv":34.98,"id":8858694},{"trd":[[5.1,0.73]],"batl":[[0,5.1,0.55]],"ltp":5.1,"tv":7.45,"id":61044843}],"tv":42.43}]}
{"op":"mcm","clk":"11980267180","pt":1724832504781,"mc":[{"id":"1.232283863","rc":[{"trd":[[1.24,5]],"ltp":1.24,"tv":36.98,"id":8858694},{"trd":[[5.1,1.22]],"batl":[[0,5.1,0.06]],"ltp":5.1,"tv":7.94,"id":61044843}],"tv":44.92}]}
{"op":"mcm","clk":"11980268054","pt":1724832526806,"mc":[{"id":"1.232283863","rc":[{"batb":[[0,1.1,9]],"ltp":1.24,"tv":36.98,"id":8858694}]}]}
{"op":"mcm","clk":"11980268960","pt":1724832547140,"mc":[{"id":"1.232283863","rc":[{"batb":[[0,1.1,7]],"ltp":1.24,"tv":36.98,"id":8858694}]}]}
{"op":"mcm","clk":"11980318874","pt":1724833326103,"mc":[{"id":"1.232283863","rc":[{"trd":[[1.24,5.25]],"batl":[[0,1.24,25.43],[1,1.3,25.6],[2,1.9,30]],"ltp":1.24,"tv":37.22,"id":8858694},{"trd":[[5.1,1.28]],"ltp":5.1,"tv":8.0,"id":61044843}],"tv":45.22}]}
{"op":"mcm","clk":"11980319081","pt":1724833330167,"mc":[{"id":"1.232283863","rc":[{"batl":[[0,1.3,25.6],[1,1.9,30],[2,1.9,0]],"ltp":1.24,"tv":37.22,"id":8858694}]}]}
{"op":"mcm","clk":"11980321847","pt":1724833381911,"mc":[{"id":"1.232283863","rc":[{"batl":[[0,1.25,51.35],[1,1.3,25.6],[2,1.9,30]],"ltp":1.24,"tv":37.22,"id":8858694}]}]}
{"op":"mcm","clk":"11980321942","pt":1724833383609,"mc":[{"id":"1.232283863","rc":[{"batl":[[0,1.25,77.02]],"ltp":1.24,"tv":37.22,"id":8858694}]}]}
{"op":"mcm","clk":"11980462484","pt":1724836010809,"mc":[{"id":"1.232283863","rc":[{"batl":[[0,1.24,30],[1,1.25,77.08],[2,1.3,25.62]],"ltp":1.24,"tv":37.22,"id":8858694}]}]}
{"op":"mcm","clk":"11980463706","pt":1724836029945,"mc":[{"id":"1.232283863","rc":[{"batl":[[0,1.24,50]],"ltp":1.24,"tv":37.22,"id":8858694}]}]}
{"op":"mcm","clk":"11980511629","pt":1724836892365,"mc":[{"id":"1.232283863","rc":[{"batl":[[0,1.2,77.08],[1,1.24,50],[2,1.25,77.08]],"ltp":1.24,"tv":37.22,"id":8858694}]}]}
{"op":"mcm","clk":"11980616256","pt":1724838467114,"mc":[{"id":"1.232283863","rc":[{"batl":[[0,1.19,50],[1,1.2,77.08]],"ltp":1.24,"tv":37.22,"id":8858694}]}]}
{"op":"mcm","clk":"11980617035","pt":1724838478904,"mc":[{"id":"1.232283863","rc":[{"trd":[[1.1,14]],"batb":[[0,1.05,200],[1,1.04,251.05],[2,1.03,533.33]],"ltp":1.1,"tv":51.22,"id":8858694}],"tv":59.22}]}
{"op":"mcm","clk":"11980623383","pt":1724838590042,"mc":[{"id":"1.232283863","rc":[{"batb":[[0,1.07,1],[1,1.05,200],[2,1.04,251.05]],"ltp":1.1,"tv":51.22,"id":8858694}]}]}
{"op":"mcm","clk":"11980696831","pt":1724839705425,"mc":[{"id":"1.232283863","rc":[{"batl":[[0,1.15,25.69],[1,1.19,50],[2,1.2,77.06]],"ltp":1.1,"tv":51.22,"id":8858694}]}]}
{"op":"mcm","clk":"11980832817","pt":1724841680177,"mc":[{"id":"1.232283863","rc":[{"batl":[[0,1.14,30],[1,1.15,25.69],[2,1.19,20]],"ltp":1.1,"tv":51.22,"id":8858694}]}]}
{"op":"mcm","clk":"11980958270","pt":1724843574808,"mc":[{"id":"1.232283863","rc":[{"batl":[[1,1.15,25.68]],"ltp":1.1,"tv":51.22,"id":8858694}]}]}
{"op":"mcm","clk":"11981136365","pt":1724846351271,"mc":[{"id":"1.232283863","rc":[{"batl":[[0,1.13,30],[1,1.14,30],[2,1.15,25.68]],"ltp":1.1,"tv":51.22,"id":8858694}]}]}
{"op":"mcm","clk":"11981198978","pt":1724847421570,"mc":[{"id":"1.232283863","rc":[{"trd":[[1.07,2]],"batb":[[0,1.05,200],[1,1.04,251.05],[2,1.03,533.33]],"batl":[[0,1.07,2],[1,1.13,30],[2,1.14,30]],"ltp":1.07,"tv":53.22,"id":8858694}],"tv":61.22}]}
{"op":"mcm","clk":"11981200893","pt":1724847449985,"mc":[{"id":"1.232283863","rc":[{"batl":[[0,1.1,2]],"ltp":1.07,"tv":53.22,"id":8858694}]}]}
{"op":"mcm","clk":"11981371748","pt":1724850510243,"mc":[{"id":"1.232283863","rc":[{"batl":[[0,1.09,50],[1,1.1,2],[2,1.13,30]],"ltp":1.07,"tv":53.22,"id":8858694}]}]}
{"op":"mcm","clk":"11981372105","pt":1724850517430,"mc":[{"id":"1.232283863","rc":[{"batl":[[0,1.09,80]],"ltp":1.07,"tv":53.22,"id":8858694}]}]}
{"op":"mcm","clk":"11982202637","pt":1724860560300,"mc":[{"id":"1.232283863","rc":[{"batb":[[0,1.04,251.05],[1,1.03,533.33],[2,1.02,700]],"ltp":1.07,"tv":53.22,"id":8858694}]}]}
{"op":"mcm","clk":"11982202730","pt":1724860561020,"mc":[{"id":"1.232283863","rc":[{"batb":[[0,1.04,1.05]],"ltp":1.07,"tv":53.22,"id":8858694}]}]}
{"op":"mcm","clk":"11982203099","pt":1724860563798,"mc":[{"id":"1.232283863","rc":[{"batb":[[1,1.03,200]],"ltp":1.07,"tv":53.22,"id":8858694}]}]}
{"op":"mcm","clk":"11982204195","pt":1724860572004,"mc":[{"id":"1.232283863","rc":[{"batl":[[0,1.09,50]],"ltp":1.07,"tv":53.22,"id":8858694}]}]}
{"op":"mcm","clk":"11982507350","pt":1724862664620,"mc":[{"id":"1.232283863","rc":[{"batl":[[0,1.08,25.69],[1,1.09,50],[2,1.1,2]],"ltp":1.07,"tv":53.22,"id":8858694}]}]}
{"op":"mcm","clk":"11982507394","pt":1724862664890,"mc":[{"id":"1.232283863","rc":[{"batl":[[0,1.08,51.37]],"ltp":1.07,"tv":53.22,"id":8858694}]}]}
{"op":"mcm","clk":"11982507934","pt":1724862668867,"mc":[{"id":"1.232283863","rc":[{"batl":[[0,1.09,50],[1,1.1,2],[2,1.13,30]],"ltp":1.07,"tv":53.22,"id":8858694}]}]}
{"op":"mcm","clk":"11983765364","pt":1724873349482,"mc":[{"id":"1.232283863","rc":[{"batl":[[0,1.08,771.01],[1,1.09,50],[2,1.1,2]],"ltp":1.07,"tv":53.22,"id":8858694}]}]}
{"op":"mcm","clk":"11984036282","pt":1724875974813,"mc":[{"id":"1.232283863","rc":[{"batl":[[0,1.08,771.37]],"ltp":1.07,"tv":53.22,"id":8858694}]}]}
{"op":"mcm","clk":"11984262613","pt":1724878919147,"mc":[{"id":"1.232283863","rc":[{"batl":[[0,1.07,50],[1,1.08,771.57]],"ltp":1.07,"tv":53.22,"id":8858694}]}]}
{"op":"mcm","clk":"11984608109","pt":1724886774802,"mc":[{"id":"1.232283863","rc":[{"batl":[[1,1.08,771.37]],"ltp":1.07,"tv":53.22,"id":8858694}]}]}
{"op":"mcm","clk":"11984953512","pt":1724892174820,"mc":[{"id":"1.232283863","rc":[{"batl":[[1,1.08,771.17]],"ltp":1.07,"tv":53.22,"id":8858694}]}]}
{"op":"mcm","clk":"11985289739","pt":1724897574796,"mc":[{"id":"1.232283863","rc":[{"batl":[[1,1.08,771.41]],"ltp":1.07,"tv":53.22,"id":8858694}]}]}
{"op":"mcm","clk":"11985568711","pt":1724902974802,"mc":[{"id":"1.232283863","rc":[{"batl":[[1,1.08,771.6]],"ltp":1.07,"tv":53.22,"id":8858694}]}]}
{"op":"mcm","clk":"11985764636","pt":1724908374829,"mc":[{"id":"1.232283863","rc":[{"batl":[[1,1.08,772.4]],"ltp":1.07,"tv":53.22,"id":8858694}]}]}
{"op":"mcm","clk":"11985936031","pt":1724913774802,"mc":[{"id":"1.232283863","rc":[{"batl":[[1,1.08,772.44]],"ltp":1.07,"tv":53.22,"id":8858694}]}]}
{"op":"mcm","clk":"11985990657","pt":1724915066221,"mc":[{"id":"1.232283863","rc":[{"trd":[[1.04,2.1]],"batb":[[0,1.02,700],[1,1.01,1481.54],[2,1.02,0]],"batl":[[0,1.04,3.95],[1,1.07,50],[2,1.08,772.68]],"ltp":1.04,"tv":55.32,"id":8858694}],"tv":63.32}]}
{"op":"mcm","clk":"11985991919","pt":1724915107494,"mc":[{"id":"1.232283863","rc":[{"batl":[[0,1.07,50],[1,1.08,772.68],[2,1.1,2]],"ltp":1.04,"tv":55.32,"id":8858694}]}]}
{"op":"mcm","clk":"11986014873","pt":1724915800274,"mc":[{"id":"1.232283863","rc":[{"batb":[[0,1.03,2],[1,1.02,700],[2,1.01,1481.54]],"batl":[[0,1.06,2],[1,1.07,50],[2,1.08,772.68]],"ltp":1.04,"tv":55.32,"id":8858694}]}]}
{"op":"mcm","clk":"11986038177","pt":1724916345441,"mc":[{"id":"1.232283863","rc":[{"trd":[[1.03,4]],"batb":[[0,1.02,700],[1,1.01,1481.54],[2,1.01,0]],"batl":[[0,1.03,3],[1,1.06,2],[2,1.07,50]],"ltp":1.03,"tv":59.32,"id":8858694}],"tv":67.32}]}
{"op":"mcm","clk":"11986039908","pt":1724916383702,"mc":[{"id":"1.232283863","rc":[{"batl":[[0,1.06,2],[1,1.07,50],[2,1.08,772.68]],"ltp":1.03,"tv":59.32,"id":8858694}]}]}
{"op":"mcm","clk":"11986068087","pt":1724917077262,"mc":[{"id":"1.232283863","rc":[{"batl":[[0,1.06,6956.1]],"ltp":1.03,"tv":59.32,"id":8858694}]}]}
{"op":"mcm","clk":"11986133765","pt":1724918735249,"mc":[{"id":"1.232283863","rc":[{"batb":[[1,1.01,1481.76]],"batl":[[0,1.06,6956.82],[1,1.08,772.76],[2,1.25,77.28]],"ltp":1.03,"tv":59.32,"id":8858694}]}]}
{"op":"mcm","clk":"11986134772","pt":1724918758959,"mc":[{"id":"1.232283863","rc":[{"batb":[[0,1.03,34],[1,1.02,700],[2,1.01,1481.76]],"ltp":1.03,"tv":59.32,"id":8858694}]}]}
{"op":"mcm","clk":"11986425697","pt":1724924249597,"mc":[{"id":"1.232283863","rc":[{"batb":[[2,1.01,1481.19]],"batl":[[0,1.05,1.8],[1,1.06,6967.94],[2,1.08,773.99]],"ltp":1.03,"tv":59.32,"id":8858694}]}]}
{"op":"mcm","clk":"11986577380","pt":1724926042631,"mc":[{"id":"1.232283863","rc":[{"trd":[[1.05,3.6]],"batb":[[0,1.05,1.2],[1,1.03,34],[2,1.02,700]],"batl":[[0,1.06,6981.63],[1,1.08,775.51],[2,1.25,77.55]],"ltp":1.05,"tv":62.93,"id":8858694}],"tv":70.93}]}
{"op":"mcm","clk":"11986578605","pt":1724926062230,"mc":[{"id":"1.232283863","rc":[{"batb":[[0,1.03,35.2],[1,1.02,700],[2,1.01,1481.38]],"ltp":1.05,"tv":62.93,"id":8858694}]}]}
{"op":"mcm","clk":"11986582871","pt":1724926127338,"mc":[{"id":"1.232283863","rc":[{"batb":[[0,1.03,34]],"ltp":1.05,"tv":62.93,"id":8858694}]}]}
{"op":"mcm","clk":"11986591312","pt":1724926242623,"mc":[{"id":"1.232283863","rc":[{"batb":[[0,1.04,2],[1,1.03,34],[2,1.02,700]],"ltp":1.05,"tv":62.93,"id":8858694}]}]}
{"op":"mcm","clk":"11986881131","pt":1724929974811,"mc":[{"id":"1.232283863","rc":[{"batl":[[0,1.06,6980.55],[1,1.08,775.39],[2,1.25,77.54]],"ltp":1.05,"tv":62.93,"id":8858694}]}]}
{"op":"mcm","clk":"11986990822","pt":1724931370772,"mc":[{"id":"1.232283863","rc":[{"trd":[[1.04,6.1]],"batb":[[0,1.03,34],[1,1.02,700],[2,1.01,1481.46]],"batl":[[0,1.06,6981.35]],"ltp":1.04,"tv":66.93,"id":8858694}],"tv":74.93}]}
{"op":"mcm","clk":"11986991774","pt":1724931386232,"mc":[{"id":"1.232283863","rc":[{"batb":[[0,1.02,700],[1,1.01,1481.46],[2,1.01,0]],"ltp":1.04,"tv":66.93,"id":8858694}]}]}
{"op":"mcm","clk":"11987005904","pt":1724931596260,"mc":[{"id":"1.232283863","rc":[{"batl":[[0,1.06,6980.55],[2,1.25,78.34]],"ltp":1.04,"tv":66.93,"id":8858694}]}]}
{"op":"mcm","clk":"11987006885","pt":1724931608645,"mc":[{"id":"1.232283863","rc":[{"batl":[[0,1.04,176.22],[1,1.06,6980.55],[2,1.08,775.39]],"ltp":1.04,"tv":66.93,"id":8858694}]}]}
{"op":"mcm","clk":"11987009581","pt":1724931648897,"mc":[{"id":"1.232283863","rc":[{"batl":[[0,1.06,6980.55],[1,1.08,775.39],[2,1.25,78.34]],"ltp":1.04,"tv":66.93,"id":8858694}]}]}
{"op":"mcm","clk":"11987019655","pt":1724931791056,"mc":[{"id":"1.232283863","rc":[{"trd":[[1.02,1.6]],"batb":[[0,1.02,699.2]],"batl":[[2,1.25,77.54]],"ltp":1.02,"tv":68.53,"id":8858694}],"tv":76.53}]}
{"op":"mcm","clk":"11987046193","pt":1724932144570,"mc":[{"id":"1.232283863","rc":[{"batb":[[0,1.06,5],[1,1.05,200],[2,1.04,251.05]],"batl":[[0,30,0.52]],"ltp":5.1,"tv":8.0,"id":61044843}]}]}
{"op":"mcm","clk":"11987046502","pt":1724932147884,"mc":[{"id":"1.232283863","rc":[{"batb":[[0,1.05,200],[1,1.04,251.05],[2,1.03,533.33]],"ltp":5.1,"tv":8.0,"id":61044843}]}]}
{"op":"mcm","clk":"11987046690","pt":1724932150268,"mc":[{"id":"1.232283863","rc":[{"batb":[[0,1.06,5],[1,1.05,200],[2,1.04,251.05]],"ltp":5.1,"tv":8.0,"id":61044843}]}]}
{"op":"mcm","clk":"11987046929","pt":1724932153486,"mc":[{"id":"1.232283863","rc":[{"batb":[[0,1.05,200],[1,1.04,251.05],[2,1.03,533.33]],"ltp":5.1,"tv":8.0,"id":61044843}]}]}
{"op":"mcm","clk":"11987047601","pt":1724932162590,"mc":[{"id":"1.232283863","rc":[{"batb":[[0,1.06,5],[1,1.05,200],[2,1.04,251.05]],"ltp":5.1,"tv":8.0,"id":61044843}]}]}
{"op":"mcm","clk":"11987047860","pt":1724932166001,"mc":[{"id":"1.232283863","rc":[{"batb":[[0,1.05,200],[1,1.04,251.05],[2,1.03,533.33]],"ltp":5.1,"tv":8.0,"id":61044843}]}]}
{"op":"mcm","clk":"11987048858","pt":1724932178291,"mc":[{"id":"1.232283863","rc":[{"batb":[[0,1.06,5],[1,1.05,200],[2,1.04,251.05]],"ltp":5.1,"tv":8.0,"id":61044843}]}]}
{"op":"mcm","clk":"11987049112","pt":1724932181595,"mc":[{"id":"1.232283863","rc":[{"batb":[[0,1.05,200],[1,1.04,251.05],[2,1.03,533.33]],"ltp":5.1,"tv":8.0,"id":61044843}]}]}
{"op":"mcm","clk":"11987049392","pt":1724932185138,"mc":[{"id":"1.232283863","rc":[{"batb":[[0,1.06,5],[1,1.05,200],[2,1.04,251.05]],"ltp":5.1,"tv":8.0,"id":61044843}]}]}
{"op":"mcm","clk":"11987049626","pt":1724932188433,"mc":[{"id":"1.232283863","rc":[{"batb":[[0,1.05,200],[1,1.04,251.05],[2,1.03,533.33]],"ltp":5.1,"tv":8.0,"id":61044843}]}]}
{"op":"mcm","clk":"11987050462","pt":1724932200124,"mc":[{"id":"1.232283863","rc":[{"batb":[[0,1.06,5],[1,1.05,200],[2,1.04,251.05]],"ltp":5.1,"tv":8.0,"id":61044843}]}]}
{"op":"mcm","clk":"11987050779","pt":1724932203546,"mc":[{"id":"1.232283863","rc":[{"batb":[[0,1.05,200],[1,1.04,251.05],[2,1.03,533.33]],"ltp":5.1,"tv":8.0,"id":61044843}]}]}
{"op":"mcm","clk":"11987051232","pt":1724932209366,"mc":[{"id":"1.232283863","rc":[{"batb":[[0,1.06,5],[1,1.05,200],[2,1.04,251.05]],"ltp":5.1,"tv":8.0,"id":61044843}]}]}
{"op":"mcm","clk":"11987051481","pt":1724932212667,"mc":[{"id":"1.232283863","rc":[{"batb":[[0,1.05,200],[1,1.04,251.05],[2,1.03,533.33]],"ltp":5.1,"tv":8.0,"id":61044843}]}]}
{"op":"mcm","clk":"11987051648","pt":1724932214738,"mc":[{"id":"1.232283863","rc":[{"batb":[[0,1.06,5],[1,1.05,200],[2,1.04,251.05]],"ltp":5.1,"tv":8.0,"id":61044843}]}]}
{"op":"mcm","clk":"11987051899","pt":1724932217935,"mc":[{"id":"1.232283863","rc":[{"batb":[[0,1.05,200],[1,1.04,251.05],[2,1.03,533.33]],"ltp":5.1,"tv":8.0,"id":61044843}]}]}
{"op":"mcm","clk":"11987052371","pt":1724932224578,"mc":[{"id":"1.232283863","rc":[{"batb":[[0,1.06,5],[1,1.05,200],[2,1.04,251.05]],"ltp":5.1,"tv":8.0,"id":61044843}]}]}
{"op":"mcm","clk":"11987052658","pt":1724932227988,"mc":[{"id":"1.232283863","rc":[{"batb":[[0,1.05,200],[1,1.04,251.05],[2,1.03,533.33]],"ltp":5.1,"tv":8.0,"id":61044843}]}]}
{"op":"mcm","clk":"11987052957","pt":1724932231501,"mc":[{"id":"1.232283863","rc":[{"batb":[[0,1.06,5],[1,1.05,200],[2,1.04,251.05]],"ltp":5.1,"tv":8.0,"id":61044843}]}]}
{"op":"mcm","clk":"11987053263","pt":1724932234962,"mc":[{"id":"1.232283863","rc":[{"batb":[[0,1.05,200],[1,1.04,251.05],[2,1.03,533.33]],"ltp":5.1,"tv":8.0,"id":61044843}]}]}
{"op":"mcm","clk":"11987053677","pt":1724932239903,"mc":[{"id":"1.232283863","rc":[{"batb":[[0,1.06,5],[1,1.05,200],[2,1.04,251.05]],"ltp":5.1,"tv":8.0,"id":61044843}]}]}
{"op":"mcm","clk":"11987053962","pt":1724932243398,"mc":[{"id":"1.232283863","rc":[{"batb":[[0,1.05,200],[1,1.04,251.05],[2,1.03,533.33]],"ltp":5.1,"tv":8.0,"id":61044843}]}]}
{"op":"mcm","clk":"11987054235","pt":1724932247071,"mc":[{"id":"1.232283863","rc":[{"batb":[[0,1.06,5],[1,1.05,200],[2,1.04,251.05]],"ltp":5.1,"tv":8.0,"id":61044843}]}]}
{"op":"mcm","clk":"11987054482","pt":1724932250310,"mc":[{"id":"1.232283863","rc":[{"batb":[[0,1.05,200],[1,1.04,251.05],[2,1.03,533.33]],"ltp":5.1,"tv":8.0,"id":61044843}]}]}
{"op":"mcm","clk":"11987055202","pt":1724932258608,"mc":[{"id":"1.232283863","rc":[{"batb":[[0,1.06,5],[1,1.05,200],[2,1.04,251.05]],"ltp":5.1,"tv":8.0,"id":61044843}]}]}
{"op":"mcm","clk":"11987055486","pt":1724932262021,"mc":[{"id":"1.232283863","rc":[{"batb":[[0,1.05,200],[1,1.04,251.05],[2,1.03,533.33]],"ltp":5.1,"tv":8.0,"id":61044843}]}]}
{"op":"mcm","clk":"11987055743","pt":1724932265223,"mc":[{"id":"1.232283863","rc":[{"batb":[[0,1.06,5],[1,1.05,200],[2,1.04,251.05]],"ltp":5.1,"tv":8.0,"id":61044843}]}]}
{"op":"mcm","clk":"11987056001","pt":1724932268420,"mc":[{"id":"1.232283863","rc":[{"batb":[[0,1.05,200],[1,1.04,251.05],[2,1.03,533.33]],"ltp":5.1,"tv":8.0,"id":61044843}]}]}
{"op":"mcm","clk":"11987056693","pt":1724932278400,"mc":[{"id":"1.232283863","rc":[{"batb":[[0,1.06,5],[1,1.05,200],[2,1.04,251.05]],"ltp":5.1,"tv":8.0,"id":61044843}]}]}
{"op":"mcm","clk":"11987056920","pt":1724932281901,"mc":[{"id":"1.232283863","rc":[{"batl":[[2,1.1,1]],"ltp":1.02,"tv":68.53,"id":8858694},{"batb":[[0,1.05,200],[1,1.04,251.05],[2,1.03,533.33]],"ltp":5.1,"tv":8.0,"id":61044843}]}]}
{"op":"mcm","clk":"11987057117","pt":1724932284325,"mc":[{"id":"1.232283863","rc":[{"batb":[[0,1.06,5],[1,1.05,200],[2,1.04,251.05]],"ltp":5.1,"tv":8.0,"id":61044843}]}]}
{"op":"mcm","clk":"11987057354","pt":1724932287730,"mc":[{"id":"1.232283863","rc":[{"batb":[[0,1.05,200],[1,1.04,251.05],[2,1.03,533.33]],"ltp":5.1,"tv":8.0,"id":61044843}]}]}
{"op":"mcm","clk":"11987057913","pt":1724932295119,"mc":[{"id":"1.232283863","rc":[{"batb":[[0,1.06,5],[1,1.05,200],[2,1.04,251.05]],"ltp":5.1,"tv":8.0,"id":61044843}]}]}
{"op":"mcm","clk":"11987058131","pt":1724932298418,"mc":[{"id":"1.232283863","rc":[{"batb":[[0,1.05,200],[1,1.04,251.05],[2,1.03,533.33]],"ltp":5.1,"tv":8.0,"id":61044843}]}]}
{"op":"mcm","clk":"11987058883","pt":1724932309378,"mc":[{"id":"1.232283863","rc":[{"batb":[[0,1.06,5],[1,1.05,200],[2,1.04,251.05]],"ltp":5.1,"tv":8.0,"id":61044843}]}]}
{"op":"mcm","clk":"11987059154","pt":1724932312626,"mc":[{"id":"1.232283863","rc":[{"batb":[[0,1.05,200],[1,1.04,251.05],[2,1.03,533.33]],"ltp":5.1,"tv":8.0,"id":61044843}]}]}
{"op":"mcm","clk":"11987061510","pt":1724932343661,"mc":[{"id":"1.232283863","rc":[{"batb":[[0,1.06,5],[1,1.05,200],[2,1.04,251.05]],"ltp":5.1,"tv":8.0,"id":61044843}]}]}
{"op":"mcm","clk":"11987061774","pt":1724932346870,"mc":[{"id":"1.232283863","rc":[{"batb":[[0,1.05,200],[1,1.04,251.05],[2,1.03,533.33]],"ltp":5.1,"tv":8.0,"id":61044843}]}]}
{"op":"mcm","clk":"11987062499","pt":1724932357868,"mc":[{"id":"1.232283863","rc":[{"batb":[[0,1.06,5],[1,1.05,200],[2,1.04,251.05]],"ltp":5.1,"tv":8.0,"id":61044843}]}]}
{"op":"mcm","clk":"11987062723","pt":1724932361078,"mc":[{"id":"1.232283863","rc":[{"batb":[[0,1.05,200],[1,1.04,251.05],[2,1.03,533.33]],"ltp":5.1,"tv":8.0,"id":61044843}]}]}
{"op":"mcm","clk":"11987062868","pt":1724932363284,"mc":[{"id":"1.232283863","rc":[{"batb":[[0,1.06,5],[1,1.05,200],[2,1.04,251.05]],"ltp":5.1,"tv":8.0,"id":61044843}]}]}
{"op":"mcm","clk":"11987063083","pt":1724932366476,"mc":[{"id":"1.232283863","rc":[{"batb":[[0,1.05,200],[1,1.04,251.05],[2,1.03,533.33]],"ltp":5.1,"tv":8.0,"id":61044843}]}]}
{"op":"mcm","clk":"11987063335","pt":1724932370979,"mc":[{"id":"1.232283863","rc":[{"batb":[[0,1.06,5],[1,1.05,200],[2,1.04,251.05]],"ltp":5.1,"tv":8.0,"id":61044843}]}]}
{"op":"mcm","clk":"11987063603","pt":1724932374510,"mc":[{"id":"1.232283863","rc":[{"batb":[[0,1.05,200],[1,1.04,251.05],[2,1.03,533.33]],"ltp":5.1,"tv":8.0,"id":61044843}]}]}
{"op":"mcm","clk":"11987063946","pt":1724932379417,"mc":[{"id":"1.232283863","rc":[{"batb":[[0,1.06,5],[1,1.05,200],[2,1.04,251.05]],"ltp":5.1,"tv":8.0,"id":61044843}]}]}
{"op":"mcm","clk":"11987064209","pt":1724932382717,"mc":[{"id":"1.232283863","rc":[{"batb":[[0,1.05,200],[1,1.04,251.05],[2,1.03,533.33]],"ltp":5.1,"tv":8.0,"id":61044843}]}]}
{"op":"mcm","clk":"11987064444","pt":1724932386011,"mc":[{"id":"1.232283863","rc":[{"batb":[[0,1.06,5],[1,1.05,200],[2,1.04,251.05]],"ltp":5.1,"tv":8.0,"id":61044843}]}]}
{"op":"mcm","clk":"11987064692","pt":1724932389416,"mc":[{"id":"1.232283863","rc":[{"batb":[[0,1.05,200],[1,1.04,251.05],[2,1.03,533.33]],"ltp":5.1,"tv":8.0,"id":61044843}]}]}
{"op":"mcm","clk":"11987064865","pt":1724932391794,"mc":[{"id":"1.232283863","rc":[{"batb":[[0,1.06,5],[1,1.05,200],[2,1.04,251.05]],"ltp":5.1,"tv":8.0,"id":61044843}]}]}
{"op":"mcm","clk":"11987065092","pt":1724932395327,"mc":[{"id":"1.232283863","rc":[{"batb":[[0,1.05,200],[1,1.04,251.05],[2,1.03,533.33]],"ltp":5.1,"tv":8.0,"id":61044843}]}]}
{"op":"mcm","clk":"11987065264","pt":1724932398314,"mc":[{"id":"1.232283863","rc":[{"batb":[[0,1.06,5],[1,1.05,200],[2,1.04,251.05]],"ltp":5.1,"tv":8.0,"id":61044843}]}]}
{"op":"mcm","clk":"11987065501","pt":1724932401914,"mc":[{"id":"1.232283863","rc":[{"batb":[[0,1.05,200],[1,1.04,251.05],[2,1.03,533.33]],"ltp":5.1,"tv":8.0,"id":61044843}]}]}
{"op":"mcm","clk":"11987065800","pt":1724932406048,"mc":[{"id":"1.232283863","rc":[{"batb":[[0,1.06,5],[1,1.05,200],[2,1.04,251.05]],"ltp":5.1,"tv":8.0,"id":61044843}]}]}
{"op":"mcm","clk":"11987066027","pt":1724932409445,"mc":[{"id":"1.232283863","rc":[{"batb":[[0,1.05,200],[1,1.04,251.05],[2,1.03,533.33]],"ltp":5.1,"tv":8.0,"id":61044843}]}]}
{"op":"mcm","clk":"11987066669","pt":1724932417233,"mc":[{"id":"1.232283863","rc":[{"batb":[[0,1.06,5],[1,1.05,200],[2,1.04,251.05]],"ltp":5.1,"tv":8.0,"id":61044843}]}]}
{"op":"mcm","clk":"11987066938","pt":1724932420633,"mc":[{"id":"1.232283863","rc":[{"batb":[[0,1.05,200],[1,1.04,251.05],[2,1.03,533.33]],"ltp":5.1,"tv":8.0,"id":61044843}]}]}
{"op":"mcm","clk":"11987067164","pt":1724932424140,"mc":[{"id":"1.232283863","rc":[{"batb":[[0,1.06,5],[1,1.05,200],[2,1.04,251.05]],"ltp":5.1,"tv":8.0,"id":61044843}]}]}
{"op":"mcm","clk":"11987067368","pt":1724932427648,"mc":[{"id":"1.232283863","rc":[{"batb":[[0,1.05,200],[1,1.04,251.05],[2,1.03,533.33]],"ltp":5.1,"tv":8.0,"id":61044843}]}]}
{"op":"mcm","clk":"11987067590","pt":1724932431251,"mc":[{"id":"1.232283863","rc":[{"batb":[[0,1.06,5],[1,1.05,200],[2,1.04,251.05]],"ltp":5.1,"tv":8.0,"id":61044843}]}]}
{"op":"mcm","clk":"11987067857","pt":1724932434666,"mc":[{"id":"1.232283863","rc":[{"batb":[[0,1.05,200],[1,1.04,251.05],[2,1.03,533.33]],"ltp":5.1,"tv":8.0,"id":61044843}]}]}
{"op":"mcm","clk":"11987069040","pt":1724932449454,"mc":[{"id":"1.232283863","rc":[{"batb":[[0,1.06,5],[1,1.05,200],[2,1.04,251.05]],"ltp":5.1,"tv":8.0,"id":61044843}]}]}
{"op":"mcm","clk":"11987069288","pt":1724932452762,"mc":[{"id":"1.232283863","rc":[{"batb":[[0,1.05,200],[1,1.04,251.05],[2,1.03,533.33]],"ltp":5.1,"tv":8.0,"id":61044843}]}]}
{"op":"mcm","clk":"11987069738","pt":1724932458587,"mc":[{"id":"1.232283863","rc":[{"batb":[[0,1.06,5],[1,1.05,200],[2,1.04,251.05]],"ltp":5.1,"tv":8.0,"id":61044843}]}]}
{"op":"mcm","clk":"11987069939","pt":1724932461885,"mc":[{"id":"1.232283863","rc":[{"batb":[[0,1.05,200],[1,1.04,251.05],[2,1.03,533.33]],"ltp":5.1,"tv":8.0,"id":61044843}]}]}
{"op":"mcm","clk":"11987070149","pt":1724932464695,"mc":[{"id":"1.232283863","rc":[{"batb":[[0,1.06,5],[1,1.05,200],[2,1.04,251.05]],"ltp":5.1,"tv":8.0,"id":61044843}]}]}
{"op":"mcm","clk":"11987070402","pt":1724932468092,"mc":[{"id":"1.232283863","rc":[{"batb":[[0,1.05,200],[1,1.04,251.05],[2,1.03,533.33]],"ltp":5.1,"tv":8.0,"id":61044843}]}]}
{"op":"mcm","clk":"11987070679","pt":1724932471908,"mc":[{"id":"1.232283863","rc":[{"batb":[[0,1.06,5],[1,1.05,200],[2,1.04,251.05]],"ltp":5.1,"tv":8.0,"id":61044843}]}]}
{"op":"mcm","clk":"11987070945","pt":1724932475286,"mc":[{"id":"1.232283863","rc":[{"batb":[[0,1.05,200],[1,1.04,251.05],[2,1.03,533.33]],"ltp":5.1,"tv":8.0,"id":61044843}]}]}
{"op":"mcm","clk":"11987071374","pt":1724932480910,"mc":[{"id":"1.232283863","rc":[{"batb":[[0,1.06,5],[1,1.05,200],[2,1.04,251.05]],"ltp":5.1,"tv":8.0,"id":61044843}]}]}
{"op":"mcm","clk":"11987071631","pt":1724932484413,"mc":[{"id":"1.232283863","rc":[{"batb":[[0,1.05,200],[1,1.04,251.05],[2,1.03,533.33]],"ltp":5.1,"tv":8.0,"id":61044843}]}]}
{"op":"mcm","clk":"11987071803","pt":1724932486731,"mc":[{"id":"1.232283863","rc":[{"batb":[[0,1.06,5],[1,1.05,200],[2,1.04,251.05]],"ltp":5.1,"tv":8.0,"id":61044843}]}]}
{"op":"mcm","clk":"11987072022","pt":1724932490097,"mc":[{"id":"1.232283863","rc":[{"batb":[[0,1.05,200],[1,1.04,251.05],[2,1.03,533.33]],"ltp":5.1,"tv":8.0,"id":61044843}]}]}
{"op":"mcm","clk":"11987072489","pt":1724932496537,"mc":[{"id":"1.232283863","rc":[{"batb":[[0,1.06,5],[1,1.05,200],[2,1.04,251.05]],"ltp":5.1,"tv":8.0,"id":61044843}]}]}
{"op":"mcm","clk":"11987072751","pt":1724932499950,"mc":[{"id":"1.232283863","rc":[{"batb":[[0,1.05,200],[1,1.04,251.05],[2,1.03,533.33]],"ltp":5.1,"tv":8.0,"id":61044843}]}]}
{"op":"mcm","clk":"11987073136","pt":1724932504024,"mc":[{"id":"1.232283863","rc":[{"batb":[[0,1.06,5],[1,1.05,200],[2,1.04,251.05]],"ltp":5.1,"tv":8.0,"id":61044843}]}]}
{"op":"mcm","clk":"11987073423","pt":1724932507548,"mc":[{"id":"1.232283863","rc":[{"batb":[[0,1.05,200],[1,1.04,251.05],[2,1.03,533.33]],"ltp":5.1,"tv":8.0,"id":61044843}]}]}
{"op":"mcm","clk":"11987073770","pt":1724932511842,"mc":[{"id":"1.232283863","rc":[{"batb":[[0,1.06,5],[1,1.05,200],[2,1.04,251.05]],"ltp":5.1,"tv":8.0,"id":61044843}]}]}
{"op":"mcm","clk":"11987074042","pt":1724932515251,"mc":[{"id":"1.232283863","rc":[{"batb":[[0,1.05,200],[1,1.04,251.05],[2,1.03,533.33]],"ltp":5.1,"tv":8.0,"id":61044843}]}]}
{"op":"mcm","clk":"11987074382","pt":1724932520357,"mc":[{"id":"1.232283863","rc":[{"batb":[[0,1.06,5],[1,1.05,200],[2,1.04,251.05]],"ltp":5.1,"tv":8.0,"id":61044843}]}]}
{"op":"mcm","clk":"11987074631","pt":1724932523708,"mc":[{"id":"1.232283863","rc":[{"batb":[[0,1.05,200],[1,1.04,251.05],[2,1.03,533.33]],"ltp":5.1,"tv":8.0,"id":61044843}]}]}
{"op":"mcm","clk":"11987074793","pt":1724932526026,"mc":[{"id":"1.232283863","rc":[{"batb":[[0,1.06,5],[1,1.05,200],[2,1.04,251.05]],"ltp":5.1,"tv":8.0,"id":61044843}]}]}
{"op":"mcm","clk":"11987074997","pt":1724932529735,"mc":[{"id":"1.232283863","rc":[{"batb":[[0,1.05,200],[1,1.04,251.05],[2,1.03,533.33]],"ltp":5.1,"tv":8.0,"id":61044843}]}]}
{"op":"mcm","clk":"11987075162","pt":1724932532337,"mc":[{"id":"1.232283863","rc":[{"batb":[[0,1.06,5],[1,1.05,200],[2,1.04,251.05]],"ltp":5.1,"tv":8.0,"id":61044843}]}]}
{"op":"mcm","clk":"11987075383","pt":1724932535841,"mc":[{"id":"1.232283863","rc":[{"batb":[[0,1.05,200],[1,1.04,251.05],[2,1.03,533.33]],"ltp":5.1,"tv":8.0,"id":61044843}]}]}
{"op":"mcm","clk":"11987075690","pt":1724932540154,"mc":[{"id":"1.232283863","rc":[{"batb":[[0,1.06,5],[1,1.05,200],[2,1.04,251.05]],"ltp":5.1,"tv":8.0,"id":61044843}]}]}
{"op":"mcm","clk":"11987075896","pt":1724932543652,"mc":[{"id":"1.232283863","rc":[{"batb":[[0,1.05,200],[1,1.04,251.05],[2,1.03,533.33]],"ltp":5.1,"tv":8.0,"id":61044843}]}]}
{"op":"mcm","clk":"11987076485","pt":1724932552264,"mc":[{"id":"1.232283863","rc":[{"batb":[[0,1.06,5],[1,1.05,200],[2,1.04,251.05]],"ltp":5.1,"tv":8.0,"id":61044843}]}]}
{"op":"mcm","clk":"11987076709","pt":1724932555586,"mc":[{"id":"1.232283863","rc":[{"batb":[[0,1.05,200],[1,1.04,251.05],[2,1.03,533.33]],"ltp":5.1,"tv":8.0,"id":61044843}]}]}
{"op":"mcm","clk":"11987077018","pt":1724932560893,"mc":[{"id":"1.232283863","rc":[{"batb":[[0,1.06,5],[1,1.05,200],[2,1.04,251.05]],"ltp":5.1,"tv":8.0,"id":61044843}]}]}
{"op":"mcm","clk":"11987077263","pt":1724932564302,"mc":[{"id":"1.232283863","rc":[{"batb":[[0,1.05,200],[1,1.04,251.05],[2,1.03,533.33]],"ltp":5.1,"tv":8.0,"id":61044843}]}]}
{"op":"mcm","clk":"11987077409","pt":1724932566883,"mc":[{"id":"1.232283863","rc":[{"batb":[[0,1.06,5],[1,1.05,200],[2,1.04,251.05]],"ltp":5.1,"tv":8.0,"id":61044843}]}]}
{"op":"mcm","clk":"11987077628","pt":1724932570271,"mc":[{"id":"1.232283863","rc":[{"batb":[[0,1.05,200],[1,1.04,251.05],[2,1.03,533.33]],"ltp":5.1,"tv":8.0,"id":61044843}]}]}
{"op":"mcm","clk":"11987077748","pt":1724932572801,"mc":[{"id":"1.232283863","rc":[{"batb":[[0,1.06,5],[1,1.05,200],[2,1.04,251.05]],"ltp":5.1,"tv":8.0,"id":61044843}]}]}
{"op":"mcm","clk":"11987077980","pt":1724932576101,"mc":[{"id":"1.232283863","rc":[{"batb":[[0,1.05,200],[1,1.04,251.05],[2,1.03,533.33]],"ltp":5.1,"tv":8.0,"id":61044843}]}]}
{"op":"mcm","clk":"11987078812","pt":1724932588722,"mc":[{"id":"1.232283863","rc":[{"batb":[[0,1.06,5],[1,1.05,200],[2,1.04,251.05]],"ltp":5.1,"tv":8.0,"id":61044843}]}]}
{"op":"mcm","clk":"11987079062","pt":1724932592135,"mc":[{"id":"1.232283863","rc":[{"batb":[[0,1.05,200],[1,1.04,251.05],[2,1.03,533.33]],"ltp":5.1,"tv":8.0,"id":61044843}]}]}
{"op":"mcm","clk":"11987079727","pt":1724932602823,"mc":[{"id":"1.232283863","rc":[{"batb":[[0,1.06,5],[1,1.05,200],[2,1.04,251.05]],"ltp":5.1,"tv":8.0,"id":61044843}]}]}
{"op":"mcm","clk":"11987079960","pt":1724932606325,"mc":[{"id":"1.232283863","rc":[{"batb":[[0,1.05,200],[1,1.04,251.05],[2,1.03,533.33]],"ltp":5.1,"tv":8.0,"id":61044843}]}]}
{"op":"mcm","clk":"11987080456","pt":1724932614251,"mc":[{"id":"1.232283863","rc":[{"batb":[[0,1.06,5],[1,1.05,200],[2,1.04,251.05]],"ltp":5.1,"tv":8.0,"id":61044843}]}]}
{"op":"mcm","clk":"11987080664","pt":1724932617659,"mc":[{"id":"1.232283863","rc":[{"batb":[[0,1.05,200],[1,1.04,251.05],[2,1.03,533.33]],"ltp":5.1,"tv":8.0,"id":61044843}]}]}
{"op":"mcm","clk":"11987080834","pt":1724932620342,"mc":[{"id":"1.232283863","rc":[{"batb":[[0,1.06,5],[1,1.05,200],[2,1.04,251.05]],"ltp":5.1,"tv":8.0,"id":61044843}]}]}
{"op":"mcm","clk":"11987081054","pt":1724932623750,"mc":[{"id":"1.232283863","rc":[{"batb":[[0,1.05,200],[1,1.04,251.05],[2,1.03,533.33]],"ltp":5.1,"tv":8.0,"id":61044843}]}]}
{"op":"mcm","clk":"11987082413","pt":1724932641366,"mc":[{"id":"1.232283863","rc":[{"batb":[[0,1.06,5],[1,1.05,200],[2,1.04,251.05]],"ltp":5.1,"tv":8.0,"id":61044843}]}]}
{"op":"mcm","clk":"11987082642","pt":1724932644770,"mc":[{"id":"1.232283863","rc":[{"batb":[[0,1.05,200],[1,1.04,251.05],[2,1.03,533.33]],"ltp":5.1,"tv":8.0,"id":61044843}]}]}
{"op":"mcm","clk":"11987083191","pt":1724932652215,"mc":[{"id":"1.232283863","rc":[{"batb":[[0,1.06,5],[1,1.05,200],[2,1.04,251.05]],"ltp":5.1,"tv":8.0,"id":61044843}]}]}
{"op":"mcm","clk":"11987083408","pt":1724932655686,"mc":[{"id":"1.232283863","rc":[{"batb":[[0,1.05,200],[1,1.04,251.05],[2,1.03,533.33]],"ltp":5.1,"tv":8.0,"id":61044843}]}]}
{"op":"mcm","clk":"11987083591","pt":1724932658521,"mc":[{"id":"1.232283863","rc":[{"batb":[[0,1.06,5],[1,1.05,200],[2,1.04,251.05]],"ltp":5.1,"tv":8.0,"id":61044843}]}]}
{"op":"mcm","clk":"11987083846","pt":1724932662086,"mc":[{"id":"1.232283863","rc":[{"batb":[[0,1.05,200],[1,1.04,251.05],[2,1.03,533.33]],"ltp":5.1,"tv":8.0,"id":61044843}]}]}
{"op":"mcm","clk":"11987084572","pt":1724932671934,"mc":[{"id":"1.232283863","rc":[{"batb":[[0,1.06,5],[1,1.05,200],[2,1.04,251.05]],"ltp":5.1,"tv":8.0,"id":61044843}]}]}
{"op":"mcm","clk":"11987084794","pt":1724932675495,"mc":[{"id":"1.232283863","rc":[{"batb":[[0,1.05,200],[1,1.04,251.05],[2,1.03,533.33]],"ltp":5.1,"tv":8.0,"id":61044843}]}]}
{"op":"mcm","clk":"11987085073","pt":1724932679028,"mc":[{"id":"1.232283863","rc":[{"batb":[[0,1.06,5],[1,1.05,200],[2,1.04,251.05]],"ltp":5.1,"tv":8.0,"id":61044843}]}]}
{"op":"mcm","clk":"11987085321","pt":1724932682420,"mc":[{"id":"1.232283863","rc":[{"batb":[[0,1.05,200],[1,1.04,251.05],[2,1.03,533.33]],"ltp":5.1,"tv":8.0,"id":61044843}]}]}
{"op":"mcm","clk":"11987085940","pt":1724932690606,"mc":[{"id":"1.232283863","rc":[{"batb":[[0,1.06,5],[1,1.05,200],[2,1.04,251.05]],"ltp":5.1,"tv":8.0,"id":61044843}]}]}
{"op":"mcm","clk":"11987086155","pt":1724932694138,"mc":[{"id":"1.232283863","rc":[{"batb":[[0,1.05,200],[1,1.04,251.05],[2,1.03,533.33]],"ltp":5.1,"tv":8.0,"id":61044843}]}]}
{"op":"mcm","clk":"11987086879","pt":1724932704744,"mc":[{"id":"1.232283863","rc":[{"batb":[[0,1.06,5],[1,1.05,200],[2,1.04,251.05]],"ltp":5.1,"tv":8.0,"id":61044843}]}]}
{"op":"mcm","clk":"11987087121","pt":1724932708142,"mc":[{"id":"1.232283863","rc":[{"batb":[[0,1.05,200],[1,1.04,251.05],[2,1.03,533.33]],"ltp":5.1,"tv":8.0,"id":61044843}]}]}
{"op":"mcm","clk":"11987087243","pt":1724932710259,"mc":[{"id":"1.232283863","rc":[{"batb":[[0,1.06,5],[1,1.05,200],[2,1.04,251.05]],"ltp":5.1,"tv":8.0,"id":61044843}]}]}
{"op":"mcm","clk":"11987087448","pt":1724932713467,"mc":[{"id":"1.232283863","rc":[{"batb":[[0,1.05,200],[1,1.04,251.05],[2,1.03,533.33]],"ltp":5.1,"tv":8.0,"id":61044843}]}]}
{"op":"mcm","clk":"11987087608","pt":1724932715840,"mc":[{"id":"1.232283863","rc":[{"batb":[[0,1.06,5],[1,1.05,200],[2,1.04,251.05]],"ltp":5.1,"tv":8.0,"id":61044843}]}]}
{"op":"mcm","clk":"11987087852","pt":1724932719153,"mc":[{"id":"1.232283863","rc":[{"batb":[[0,1.05,200],[1,1.04,251.05],[2,1.03,533.33]],"ltp":5.1,"tv":8.0,"id":61044843}]}]}
{"op":"mcm","clk":"11987088075","pt":1724932722567,"mc":[{"id":"1.232283863","rc":[{"batb":[[0,1.06,5],[1,1.05,200],[2,1.04,251.05]],"ltp":5.1,"tv":8.0,"id":61044843}]}]}
{"op":"mcm","clk":"11987088341","pt":1724932725983,"mc":[{"id":"1.232283863","rc":[{"batb":[[0,1.05,200],[1,1.04,251.05],[2,1.03,533.33]],"ltp":5.1,"tv":8.0,"id":61044843}]}]}
{"op":"mcm","clk":"11987088691","pt":1724932731181,"mc":[{"id":"1.232283863","rc":[{"batb":[[0,1.06,5],[1,1.05,200],[2,1.04,251.05]],"ltp":5.1,"tv":8.0,"id":61044843}]}]}
{"op":"mcm","clk":"11987088912","pt":1724932734571,"mc":[{"id":"1.232283863","rc":[{"batb":[[0,1.05,200],[1,1.04,251.05],[2,1.03,533.33]],"ltp":5.1,"tv":8.0,"id":61044843}]}]}
{"op":"mcm","clk":"11987089191","pt":1724932738301,"mc":[{"id":"1.232283863","rc":[{"batb":[[0,1.06,5],[1,1.05,200],[2,1.04,251.05]],"ltp":5.1,"tv":8.0,"id":61044843}]}]}
{"op":"mcm","clk":"11987089466","pt":1724932741787,"mc":[{"id":"1.232283863","rc":[{"batb":[[0,1.05,200],[1,1.04,251.05],[2,1.03,533.33]],"ltp":5.1,"tv":8.0,"id":61044843}]}]}
{"op":"mcm","clk":"11987090053","pt":1724932750217,"mc":[{"id":"1.232283863","rc":[{"batb":[[0,1.06,5],[1,1.05,200],[2,1.04,251.05]],"ltp":5.1,"tv":8.0,"id":61044843}]}]}
{"op":"mcm","clk":"11987090310","pt":1724932753578,"mc":[{"id":"1.232283863","rc":[{"batb":[[0,1.05,200],[1,1.04,251.05],[2,1.03,533.33]],"ltp":5.1,"tv":8.0,"id":61044843}]}]}
{"op":"mcm","clk":"11987091423","pt":1724932770805,"mc":[{"id":"1.232283863","rc":[{"batb":[[0,1.06,5],[1,1.05,200],[2,1.04,251.05]],"ltp":5.1,"tv":8.0,"id":61044843}]}]}
{"op":"mcm","clk":"11987091665","pt":1724932774298,"mc":[{"id":"1.232283863","rc":[{"batb":[[0,1.05,200],[1,1.04,251.05],[2,1.03,533.33]],"ltp":5.1,"tv":8.0,"id":61044843}]}]}
{"op":"mcm","clk":"11987091913","pt":1724932777826,"mc":[{"id":"1.232283863","rc":[{"batb":[[0,1.06,5],[1,1.05,200],[2,1.04,251.05]],"ltp":5.1,"tv":8.0,"id":61044843}]}]}
{"op":"mcm","clk":"11987092146","pt":1724932781328,"mc":[{"id":"1.232283863","rc":[{"batb":[[0,1.05,200],[1,1.04,251.05],[2,1.03,533.33]],"ltp":5.1,"tv":8.0,"id":61044843}]}]}
{"op":"mcm","clk":"11987092286","pt":1724932783598,"mc":[{"id":"1.232283863","rc":[{"batb":[[0,1.06,5],[1,1.05,200],[2,1.04,251.05]],"ltp":5.1,"tv":8.0,"id":61044843}]}]}
{"op":"mcm","clk":"11987092520","pt":1724932786995,"mc":[{"id":"1.232283863","rc":[{"batb":[[0,1.05,200],[1,1.04,251.05],[2,1.03,533.33]],"ltp":5.1,"tv":8.0,"id":61044843}]}]}
{"op":"mcm","clk":"11987092942","pt":1724932793332,"mc":[{"id":"1.232283863","rc":[{"batb":[[0,1.06,5],[1,1.05,200],[2,1.04,251.05]],"ltp":5.1,"tv":8.0,"id":61044843}]}]}
{"op":"mcm","clk":"11987093160","pt":1724932796826,"mc":[{"id":"1.232283863","rc":[{"batb":[[0,1.05,200],[1,1.04,251.05],[2,1.03,533.33]],"ltp":5.1,"tv":8.0,"id":61044843}]}]}
{"op":"mcm","clk":"11987093323","pt":1724932799140,"mc":[{"id":"1.232283863","rc":[{"batb":[[0,1.06,5],[1,1.05,200],[2,1.04,251.05]],"ltp":5.1,"tv":8.0,"id":61044843}]}]}
{"op":"mcm","clk":"11987093577","pt":1724932802458,"mc":[{"id":"1.232283863","rc":[{"batb":[[0,1.05,200],[1,1.04,251.05],[2,1.03,533.33]],"ltp":5.1,"tv":8.0,"id":61044843}]}]}
{"op":"mcm","clk":"11987093890","pt":1724932805837,"mc":[{"id":"1.232283863","rc":[{"batb":[[1,1.01,1481.41]],"batl":[[0,1.06,6983.8],[1,1.08,775.76]],"ltp":1.02,"tv":68.53,"id":8858694},{"batb":[[0,1.06,5],[1,1.05,200],[2,1.04,251.05]],"ltp":5.1,"tv":8.0,"id":61044843}]}]}
{"op":"mcm","clk":"11987094162","pt":1724932809234,"mc":[{"id":"1.232283863","rc":[{"batb":[[0,1.05,200],[1,1.04,251.05],[2,1.03,533.33]],"ltp":5.1,"tv":8.0,"id":61044843}]}]}
{"op":"mcm","clk":"11987094429","pt":1724932812836,"mc":[{"id":"1.232283863","rc":[{"batb":[[0,1.06,5],[1,1.05,200],[2,1.04,251.05]],"ltp":5.1,"tv":8.0,"id":61044843}]}]}
{"op":"mcm","clk":"11987094625","pt":1724932816174,"mc":[{"id":"1.232283863","rc":[{"batb":[[0,1.05,200],[1,1.04,251.05],[2,1.03,533.33]],"ltp":5.1,"tv":8.0,"id":61044843}]}]}
{"op":"mcm","clk":"11987094900","pt":1724932820466,"mc":[{"id":"1.232283863","rc":[{"batb":[[0,1.06,5],[1,1.05,200],[2,1.04,251.05]],"ltp":5.1,"tv":8.0,"id":61044843}]}]}
{"op":"mcm","clk":"11987095135","pt":1724932823858,"mc":[{"id":"1.232283863","rc":[{"batb":[[0,1.05,200],[1,1.04,251.05],[2,1.03,533.33]],"ltp":5.1,"tv":8.0,"id":61044843}]}]}
{"op":"mcm","clk":"11987095286","pt":1724932826172,"mc":[{"id":"1.232283863","rc":[{"batb":[[0,1.06,5],[1,1.05,200],[2,1.04,251.05]],"ltp":5.1,"tv":8.0,"id":61044843}]}]}
{"op":"mcm","clk":"11987095562","pt":1724932829776,"mc":[{"id":"1.232283863","rc":[{"batb":[[0,1.05,200],[1,1.04,251.05],[2,1.03,533.33]],"ltp":5.1,"tv":8.0,"id":61044843}]}]}
{"op":"mcm","clk":"11987095768","pt":1724932832565,"mc":[{"id":"1.232283863","rc":[{"batb":[[0,1.06,5],[1,1.05,200],[2,1.04,251.05]],"ltp":5.1,"tv":8.0,"id":61044843}]}]}
{"op":"mcm","clk":"11987096063","pt":1724932836177,"mc":[{"id":"1.232283863","rc":[{"batb":[[0,1.05,200],[1,1.04,251.05],[2,1.03,533.33]],"ltp":5.1,"tv":8.0,"id":61044843}]}]}
{"op":"mcm","clk":"11987096383","pt":1724932840352,"mc":[{"id":"1.232283863","rc":[{"batb":[[0,1.06,5],[1,1.05,200],[2,1.04,251.05]],"ltp":5.1,"tv":8.0,"id":61044843}]}]}
{"op":"mcm","clk":"11987096649","pt":1724932843870,"mc":[{"id":"1.232283863","rc":[{"batb":[[0,1.05,200],[1,1.04,251.05],[2,1.03,533.33]],"ltp":5.1,"tv":8.0,"id":61044843}]}]}
{"op":"mcm","clk":"11987097026","pt":1724932849064,"mc":[{"id":"1.232283863","rc":[{"batb":[[0,1.06,5],[1,1.05,200],[2,1.04,251.05]],"ltp":5.1,"tv":8.0,"id":61044843}]}]}
{"op":"mcm","clk":"11987097299","pt":1724932852487,"mc":[{"id":"1.232283863","rc":[{"batb":[[0,1.05,200],[1,1.04,251.05],[2,1.03,533.33]],"ltp":5.1,"tv":8.0,"id":61044843}]}]}
{"op":"mcm","clk":"11987097469","pt":1724932854769,"mc":[{"id":"1.232283863","rc":[{"batb":[[0,1.06,5],[1,1.05,200],[2,1.04,251.05]],"ltp":5.1,"tv":8.0,"id":61044843}]}]}
{"op":"mcm","clk":"11987097755","pt":1724932858078,"mc":[{"id":"1.232283863","rc":[{"batb":[[0,1.05,200],[1,1.04,251.05],[2,1.03,533.33]],"ltp":5.1,"tv":8.0,"id":61044843}]}]}
{"op":"mcm","clk":"11987098574","pt":1724932867819,"mc":[{"id":"1.232283863","rc":[{"batb":[[0,1.06,5],[1,1.05,200],[2,1.04,251.05]],"ltp":5.1,"tv":8.0,"id":61044843}]}]}
{"op":"mcm","clk":"11987098818","pt":1724932871335,"mc":[{"id":"1.232283863","rc":[{"batb":[[0,1.05,200],[1,1.04,251.05],[2,1.03,533.33]],"ltp":5.1,"tv":8.0,"id":61044843}]}]}
{"op":"mcm","clk":"11987099650","pt":1724932882801,"mc":[{"id":"1.232283863","rc":[{"batb":[[0,1.06,5],[1,1.05,200],[2,1.04,251.05]],"ltp":5.1,"tv":8.0,"id":61044843}]}]}
{"op":"mcm","clk":"11987099905","pt":1724932886147,"mc":[{"id":"1.232283863","rc":[{"batb":[[0,1.05,200],[1,1.04,251.05],[2,1.03,533.33]],"ltp":5.1,"tv":8.0,"id":61044843}]}]}
{"op":"mcm","clk":"11987100545","pt":1724932894063,"mc":[{"id":"1.232283863","rc":[{"batb":[[0,1.06,5],[1,1.05,200],[2,1.04,251.05]],"ltp":5.1,"tv":8.0,"id":61044843}]}]}
{"op":"mcm","clk":"11987100829","pt":1724932897378,"mc":[{"id":"1.232283863","rc":[{"batb":[[0,1.05,200],[1,1.04,251.05],[2,1.03,533.33]],"ltp":5.1,"tv":8.0,"id":61044843}]}]}
{"op":"mcm","clk":"11987101268","pt":1724932902665,"mc":[{"id":"1.232283863","rc":[{"batb":[[0,1.06,5],[1,1.05,200],[2,1.04,251.05]],"ltp":5.1,"tv":8.0,"id":61044843}]}]}
{"op":"mcm","clk":"11987101488","pt":1724932905977,"mc":[{"id":"1.232283863","rc":[{"batb":[[0,1.05,200],[1,1.04,251.05],[2,1.03,533.33]],"ltp":5.1,"tv":8.0,"id":61044843}]}]}
{"op":"mcm","clk":"11987101743","pt":1724932909160,"mc":[{"id":"1.232283863","rc":[{"batb":[[0,1.06,5],[1,1.05,200],[2,1.04,251.05]],"ltp":5.1,"tv":8.0,"id":61044843}]}]}
{"op":"mcm","clk":"11987102044","pt":1724932912475,"mc":[{"id":"1.232283863","rc":[{"batb":[[0,1.05,200],[1,1.04,251.05],[2,1.03,533.33]],"ltp":5.1,"tv":8.0,"id":61044843}]}]}
{"op":"mcm","clk":"11987102257","pt":1724932914855,"mc":[{"id":"1.232283863","rc":[{"batb":[[0,1.06,5],[1,1.05,200],[2,1.04,251.05]],"ltp":5.1,"tv":8.0,"id":61044843}]}]}
{"op":"mcm","clk":"11987102517","pt":1724932918208,"mc":[{"id":"1.232283863","rc":[{"batb":[[0,1.05,200],[1,1.04,251.05],[2,1.03,533.33]],"ltp":5.1,"tv":8.0,"id":61044843}]}]}
{"op":"mcm","clk":"11987102827","pt":1724932921863,"mc":[{"id":"1.232283863","rc":[{"batb":[[0,1.06,5],[1,1.05,200],[2,1.04,251.05]],"ltp":5.1,"tv":8.0,"id":61044843}]}]}
{"op":"mcm","clk":"11987103111","pt":1724932925062,"mc":[{"id":"1.232283863","rc":[{"batb":[[0,1.05,200],[1,1.04,251.05],[2,1.03,533.33]],"ltp":5.1,"tv":8.0,"id":61044843}]}]}
{"op":"mcm","clk":"11987104223","pt":1724932935001,"mc":[{"id":"1.232283863","rc":[{"batb":[[0,1.06,5],[1,1.05,200],[2,1.04,251.05]],"ltp":5.1,"tv":8.0,"id":61044843}]}]}
{"op":"mcm","clk":"11987104545","pt":1724932938608,"mc":[{"id":"1.232283863","rc":[{"batl":[[0,1.05,2.1],[1,1.06,6983.8],[2,1.08,775.76]],"ltp":1.02,"tv":68.53,"id":8858694},{"batb":[[0,1.05,200],[1,1.04,251.05],[2,1.03,533.33]],"ltp":5.1,"tv":8.0,"id":61044843}]}]}
{"op":"mcm","clk":"11987104853","pt":1724932942131,"mc":[{"id":"1.232283863","rc":[{"batb":[[0,1.06,5],[1,1.05,200],[2,1.04,251.05]],"ltp":5.1,"tv":8.0,"id":61044843}]}]}
{"op":"mcm","clk":"11987105107","pt":1724932945536,"mc":[{"id":"1.232283863","rc":[{"batb":[[0,1.05,200],[1,1.04,251.05],[2,1.03,533.33]],"ltp":5.1,"tv":8.0,"id":61044843}]}]}
{"op":"mcm","clk":"11987105548","pt":1724932951819,"mc":[{"id":"1.232283863","rc":[{"batb":[[0,1.06,5],[1,1.05,200],[2,1.04,251.05]],"ltp":5.1,"tv":8.0,"id":61044843}]}]}
{"op":"mcm","clk":"11987105857","pt":1724932955337,"mc":[{"id":"1.232283863","rc":[{"batb":[[0,1.05,200],[1,1.04,251.05],[2,1.03,533.33]],"ltp":5.1,"tv":8.0,"id":61044843}]}]}
{"op":"mcm","clk":"11987106582","pt":1724932963746,"mc":[{"id":"1.232283863","rc":[{"batb":[[0,1.06,5],[1,1.05,200],[2,1.04,251.05]],"ltp":5.1,"tv":8.0,"id":61044843}]}]}
{"op":"mcm","clk":"11987106847","pt":1724932967346,"mc":[{"id":"1.232283863","rc":[{"batb":[[0,1.05,200],[1,1.04,251.05],[2,1.03,533.33]],"ltp":5.1,"tv":8.0,"id":61044843}]}]}
{"op":"mcm","clk":"11987107347","pt":1724932973942,"mc":[{"id":"1.232283863","rc":[{"batb":[[0,1.06,5],[1,1.05,200],[2,1.04,251.05]],"ltp":5.1,"tv":8.0,"id":61044843}]}]}
{"op":"mcm","clk":"11987107594","pt":1724932977252,"mc":[{"id":"1.232283863","rc":[{"batb":[[0,1.05,200],[1,1.04,251.05],[2,1.03,533.33]],"ltp":5.1,"tv":8.0,"id":61044843}]}]}
{"op":"mcm","clk":"11987108008","pt":1724932983151,"mc":[{"id":"1.232283863","rc":[{"batb":[[0,1.06,5],[1,1.05,200],[2,1.04,251.05]],"ltp":5.1,"tv":8.0,"id":61044843}]}]}
{"op":"mcm","clk":"11987108300","pt":1724932986664,"mc":[{"id":"1.232283863","rc":[{"batb":[[0,1.05,200],[1,1.04,251.05],[2,1.03,533.33]],"ltp":5.1,"tv":8.0,"id":61044843}]}]}
{"op":"mcm","clk":"11987108547","pt":1724932989776,"mc":[{"id":"1.232283863","rc":[{"batb":[[0,1.06,5],[1,1.05,200],[2,1.04,251.05]],"ltp":5.1,"tv":8.0,"id":61044843}]}]}
{"op":"mcm","clk":"11987108845","pt":1724932993293,"mc":[{"id":"1.232283863","rc":[{"batb":[[0,1.05,200],[1,1.04,251.05],[2,1.03,533.33]],"ltp":5.1,"tv":8.0,"id":61044843}]}]}
{"op":"mcm","clk":"11987109784","pt":1724933005086,"mc":[{"id":"1.232283863","rc":[{"batb":[[0,1.06,5],[1,1.05,200],[2,1.04,251.05]],"ltp":5.1,"tv":8.0,"id":61044843}]}]}
{"op":"mcm","clk":"11987110060","pt":1724933008502,"mc":[{"id":"1.232283863","rc":[{"batb":[[0,1.05,200],[1,1.04,251.05],[2,1.03,533.33]],"ltp":5.1,"tv":8.0,"id":61044843}]}]}
{"op":"mcm","clk":"11987110357","pt":1724933012111,"mc":[{"id":"1.232283863","rc":[{"batb":[[0,1.06,5],[1,1.05,200],[2,1.04,251.05]],"ltp":5.1,"tv":8.0,"id":61044843}]}]}
{"op":"mcm","clk":"11987110603","pt":1724933015615,"mc":[{"id":"1.232283863","rc":[{"batb":[[0,1.05,200],[1,1.04,251.05],[2,1.03,533.33]],"ltp":5.1,"tv":8.0,"id":61044843}]}]}
{"op":"mcm","clk":"11987111023","pt":1724933021017,"mc":[{"id":"1.232283863","rc":[{"batb":[[0,1.06,5],[1,1.05,200],[2,1.04,251.05]],"ltp":5.1,"tv":8.0,"id":61044843}]}]}
{"op":"mcm","clk":"11987111296","pt":1724933024496,"mc":[{"id":"1.232283863","rc":[{"batb":[[0,1.05,200],[1,1.04,251.05],[2,1.03,533.33]],"ltp":5.1,"tv":8.0,"id":61044843}]}]}
{"op":"mcm","clk":"11987111942","pt":1724933033121,"mc":[{"id":"1.232283863","rc":[{"batb":[[0,1.06,5],[1,1.05,200],[2,1.04,251.05]],"ltp":5.1,"tv":8.0,"id":61044843}]}]}
{"op":"mcm","clk":"11987112185","pt":1724933036723,"mc":[{"id":"1.232283863","rc":[{"batb":[[0,1.05,200],[1,1.04,251.05],[2,1.03,533.33]],"ltp":5.1,"tv":8.0,"id":61044843}]}]}
{"op":"mcm","clk":"11987112319","pt":1724933038934,"mc":[{"id":"1.232283863","rc":[{"batb":[[0,1.06,5],[1,1.05,200],[2,1.04,251.05]],"ltp":5.1,"tv":8.0,"id":61044843}]}]}
{"op":"mcm","clk":"11987112584","pt":1724933042448,"mc":[{"id":"1.232283863","rc":[{"batb":[[0,1.05,200],[1,1.04,251.05],[2,1.03,533.33]],"ltp":5.1,"tv":8.0,"id":61044843}]}]}
{"op":"mcm","clk":"11987112884","pt":1724933045926,"mc":[{"id":"1.232283863","rc":[{"batb":[[0,1.06,5],[1,1.05,200],[2,1.04,251.05]],"ltp":5.1,"tv":8.0,"id":61044843}]}]}
{"op":"mcm","clk":"11987113161","pt":1724933049432,"mc":[{"id":"1.232283863","rc":[{"batb":[[0,1.05,200],[1,1.04,251.05],[2,1.03,533.33]],"ltp":5.1,"tv":8.0,"id":61044843}]}]}
{"op":"mcm","clk":"11987113560","pt":1724933054646,"mc":[{"id":"1.232283863","rc":[{"batb":[[0,1.06,5],[1,1.05,200],[2,1.04,251.05]],"ltp":5.1,"tv":8.0,"id":61044843}]}]}
{"op":"mcm","clk":"11987113822","pt":1724933058047,"mc":[{"id":"1.232283863","rc":[{"batb":[[0,1.05,200],[1,1.04,251.05],[2,1.03,533.33]],"ltp":5.1,"tv":8.0,"id":61044843}]}]}
{"op":"mcm","clk":"11987114051","pt":1724933061259,"mc":[{"id":"1.232283863","rc":[{"batb":[[0,1.06,5],[1,1.05,200],[2,1.04,251.05]],"ltp":5.1,"tv":8.0,"id":61044843}]}]}
{"op":"mcm","clk":"11987114329","pt":1724933064664,"mc":[{"id":"1.232283863","rc":[{"batb":[[0,1.05,200],[1,1.04,251.05],[2,1.03,533.33]],"ltp":5.1,"tv":8.0,"id":61044843}]}]}
{"op":"mcm","clk":"11987114717","pt":1724933069473,"mc":[{"id":"1.232283863","rc":[{"batb":[[0,1.06,5],[1,1.05,200],[2,1.04,251.05]],"ltp":5.1,"tv":8.0,"id":61044843}]}]}
{"op":"mcm","clk":"11987115010","pt":1724933072767,"mc":[{"id":"1.232283863","rc":[{"batb":[[0,1.05,200],[1,1.04,251.05],[2,1.03,533.33]],"ltp":5.1,"tv":8.0,"id":61044843}]}]}
{"op":"mcm","clk":"11987115311","pt":1724933075873,"mc":[{"id":"1.232283863","rc":[{"batb":[[0,1.06,5],[1,1.05,200],[2,1.04,251.05]],"ltp":5.1,"tv":8.0,"id":61044843}]}]}
{"op":"mcm","clk":"11987115646","pt":1724933079346,"mc":[{"id":"1.232283863","rc":[{"batb":[[0,1.05,200],[1,1.04,251.05],[2,1.03,533.33]],"ltp":5.1,"tv":8.0,"id":61044843}]}]}
{"op":"mcm","clk":"11987116013","pt":1724933084763,"mc":[{"id":"1.232283863","rc":[{"batb":[[0,1.06,5],[1,1.05,200],[2,1.04,251.05]],"ltp":5.1,"tv":8.0,"id":61044843}]}]}
{"op":"mcm","clk":"11987116257","pt":1724933088186,"mc":[{"id":"1.232283863","rc":[{"batb":[[0,1.05,200],[1,1.04,251.05],[2,1.03,533.33]],"ltp":5.1,"tv":8.0,"id":61044843}]}]}
{"op":"mcm","clk":"11987116549","pt":1724933092057,"mc":[{"id":"1.232283863","rc":[{"batb":[[0,1.06,5],[1,1.05,200],[2,1.04,251.05]],"ltp":5.1,"tv":8.0,"id":61044843}]}]}
{"op":"mcm","clk":"11987116817","pt":1724933095855,"mc":[{"id":"1.232283863","rc":[{"batb":[[0,1.05,200],[1,1.04,251.05],[2,1.03,533.33]],"ltp":5.1,"tv":8.0,"id":61044843}]}]}
{"op":"mcm","clk":"11987117993","pt":1724933110507,"mc":[{"id":"1.232283863","rc":[{"batb":[[0,1.06,5],[1,1.05,200],[2,1.04,251.05]],"ltp":5.1,"tv":8.0,"id":61044843}]}]}
{"op":"mcm","clk":"11987118252","pt":1724933114004,"mc":[{"id":"1.232283863","rc":[{"batb":[[0,1.05,200],[1,1.04,251.05],[2,1.03,533.33]],"ltp":5.1,"tv":8.0,"id":61044843}]}]}
{"op":"mcm","clk":"11987118743","pt":1724933120997,"mc":[{"id":"1.232283863","rc":[{"batb":[[0,1.06,5],[1,1.05,200],[2,1.04,251.05]],"ltp":5.1,"tv":8.0,"id":61044843}]}]}
{"op":"mcm","clk":"11987119003","pt":1724933124295,"mc":[{"id":"1.232283863","rc":[{"batb":[[0,1.05,200],[1,1.04,251.05],[2,1.03,533.33]],"ltp":5.1,"tv":8.0,"id":61044843}]}]}
{"op":"mcm","clk":"11987119838","pt":1724933135415,"mc":[{"id":"1.232283863","rc":[{"batb":[[0,1.06,5],[1,1.05,200],[2,1.04,251.05]],"ltp":5.1,"tv":8.0,"id":61044843}]}]}
{"op":"mcm","clk":"11987120112","pt":1724933138814,"mc":[{"id":"1.232283863","rc":[{"batb":[[0,1.05,200],[1,1.04,251.05],[2,1.03,533.33]],"ltp":5.1,"tv":8.0,"id":61044843}]}]}
{"op":"mcm","clk":"11987120245","pt":1724933141037,"mc":[{"id":"1.232283863","rc":[{"batb":[[0,1.06,5],[1,1.05,200],[2,1.04,251.05]],"ltp":5.1,"tv":8.0,"id":61044843}]}]}
{"op":"mcm","clk":"11987120499","pt":1724933144225,"mc":[{"id":"1.232283863","rc":[{"batb":[[0,1.05,200],[1,1.04,251.05],[2,1.03,533.33]],"ltp":5.1,"tv":8.0,"id":61044843}]}]}
{"op":"mcm","clk":"11987121257","pt":1724933155520,"mc":[{"id":"1.232283863","rc":[{"batb":[[0,1.06,5],[1,1.05,200],[2,1.04,251.05]],"ltp":5.1,"tv":8.0,"id":61044843}]}]}
{"op":"mcm","clk":"11987121486","pt":1724933158916,"mc":[{"id":"1.232283863","rc":[{"batb":[[0,1.05,200],[1,1.04,251.05],[2,1.03,533.33]],"ltp":5.1,"tv":8.0,"id":61044843}]}]}
{"op":"mcm","clk":"11987121800","pt":1724933163047,"mc":[{"id":"1.232283863","rc":[{"batb":[[0,1.06,5],[1,1.05,200],[2,1.04,251.05]],"ltp":5.1,"tv":8.0,"id":61044843}]}]}
{"op":"mcm","clk":"11987122015","pt":1724933165529,"mc":[{"id":"1.232283863","rc":[{"batb":[[0,1.02,199.2]],"ltp":1.02,"tv":68.53,"id":8858694}]}]}
{"op":"mcm","clk":"11987122083","pt":1724933166659,"mc":[{"id":"1.232283863","rc":[{"batb":[[0,1.05,200],[1,1.04,251.05],[2,1.03,533.33]],"ltp":5.1,"tv":8.0,"id":61044843}]}]}
{"op":"mcm","clk":"11987123212","pt":1724933182383,"mc":[{"id":"1.232283863","rc":[{"batb":[[0,1.06,5],[1,1.05,200],[2,1.04,251.05]],"ltp":5.1,"tv":8.0,"id":61044843}]}]}
{"op":"mcm","clk":"11987123491","pt":1724933185994,"mc":[{"id":"1.232283863","rc":[{"batb":[[0,1.05,200],[1,1.04,251.05],[2,1.03,533.33]],"ltp":5.1,"tv":8.0,"id":61044843}]}]}
{"op":"mcm","clk":"11987123568","pt":1724933187080,"mc":[{"id":"1.232283863","rc":[{"batl":[[0,990,5.52]],"ltp":5.1,"tv":8.0,"id":61044843}]}]}
{"op":"mcm","clk":"11987123863","pt":1724933190844,"mc":[{"id":"1.232283863","rc":[{"batb":[[0,1.06,5],[1,1.05,200],[2,1.04,251.05]],"ltp":5.1,"tv":8.0,"id":61044843}]}]}
{"op":"mcm","clk":"11987124117","pt":1724933194251,"mc":[{"id":"1.232283863","rc":[{"batb":[[0,1.05,200],[1,1.04,251.05],[2,1.03,533.33]],"ltp":5.1,"tv":8.0,"id":61044843}]}]}
{"op":"mcm","clk":"11987124321","pt":1724933196975,"mc":[{"id":"1.232283863","rc":[{"batb":[[0,1.06,5],[1,1.05,200],[2,1.04,251.05]],"ltp":5.1,"tv":8.0,"id":61044843}]}]}
{"op":"mcm","clk":"11987124611","pt":1724933200382,"mc":[{"id":"1.232283863","rc":[{"batb":[[0,1.05,200],[1,1.04,251.05],[2,1.03,533.33]],"ltp":5.1,"tv":8.0,"id":61044843}]}]}
{"op":"mcm","clk":"11987125088","pt":1724933207606,"mc":[{"id":"1.232283863","rc":[{"batb":[[0,1.06,5],[1,1.05,200],[2,1.04,251.05]],"ltp":5.1,"tv":8.0,"id":61044843}]}]}
{"op":"mcm","clk":"11987125362","pt":1724933211019,"mc":[{"id":"1.232283863","rc":[{"batb":[[0,1.05,200],[1,1.04,251.05],[2,1.03,533.33]],"ltp":5.1,"tv":8.0,"id":61044843}]}]}
{"op":"mcm","clk":"11987125629","pt":1724933214501,"mc":[{"id":"1.232283863","rc":[{"batb":[[0,1.06,5],[1,1.05,200],[2,1.04,251.05]],"ltp":5.1,"tv":8.0,"id":61044843}]}]}
{"op":"mcm","clk":"11987125846","pt":1724933217815,"mc":[{"id":"1.232283863","rc":[{"batb":[[0,1.05,200],[1,1.04,251.05],[2,1.03,533.33]],"ltp":5.1,"tv":8.0,"id":61044843}]}]}
{"op":"mcm","clk":"11987126091","pt":1724933220729,"mc":[{"id":"1.232283863","rc":[{"batb":[[0,1.06,5],[1,1.05,200],[2,1.04,251.05]],"ltp":5.1,"tv":8.0,"id":61044843}]}]}
{"op":"mcm","clk":"11987126390","pt":1724933224180,"mc":[{"id":"1.232283863","rc":[{"batb":[[0,1.05,200],[1,1.04,251.05],[2,1.03,533.33]],"ltp":5.1,"tv":8.0,"id":61044843}]}]}
{"op":"mcm","clk":"11987126578","pt":1724933226823,"mc":[{"id":"1.232283863","rc":[{"batb":[[0,1.06,5],[1,1.05,200],[2,1.04,251.05]],"ltp":5.1,"tv":8.0,"id":61044843}]}]}
{"op":"mcm","clk":"11987126835","pt":1724933230239,"mc":[{"id":"1.232283863","rc":[{"batb":[[0,1.05,200],[1,1.04,251.05],[2,1.03,533.33]],"ltp":5.1,"tv":8.0,"id":61044843}]}]}
{"op":"mcm","clk":"11987127529","pt":1724933238831,"mc":[{"id":"1.232283863","rc":[{"batb":[[0,1.06,5],[1,1.05,200],[2,1.04,251.05]],"ltp":5.1,"tv":8.0,"id":61044843}]}]}
{"op":"mcm","clk":"11987127803","pt":1724933242347,"mc":[{"id":"1.232283863","rc":[{"batb":[[0,1.05,200],[1,1.04,251.05],[2,1.03,533.33]],"ltp":5.1,"tv":8.0,"id":61044843}]}]}
{"op":"mcm","clk":"11987128029","pt":1724933245408,"mc":[{"id":"1.232283863","rc":[{"batb":[[0,1.06,5],[1,1.05,200],[2,1.04,251.05]],"ltp":5.1,"tv":8.0,"id":61044843}]}]}
{"op":"mcm","clk":"11987128301","pt":1724933248908,"mc":[{"id":"1.232283863","rc":[{"batb":[[0,1.05,200],[1,1.04,251.05],[2,1.03,533.33]],"ltp":5.1,"tv":8.0,"id":61044843}]}]}
{"op":"mcm","clk":"11987128823","pt":1724933256345,"mc":[{"id":"1.232283863","rc":[{"batb":[[0,1.06,5],[1,1.05,200],[2,1.04,251.05]],"ltp":5.1,"tv":8.0,"id":61044843}]}]}
{"op":"mcm","clk":"11987129135","pt":1724933259859,"mc":[{"id":"1.232283863","rc":[{"batb":[[0,1.05,200],[1,1.04,251.05],[2,1.03,533.33]],"ltp":5.1,"tv":8.0,"id":61044843}]}]}
{"op":"mcm","clk":"11987129376","pt":1724933263467,"mc":[{"id":"1.232283863","rc":[{"batb":[[0,1.06,5],[1,1.05,200],[2,1.04,251.05]],"ltp":5.1,"tv":8.0,"id":61044843}]}]}
{"op":"mcm","clk":"11987129573","pt":1724933266723,"mc":[{"id":"1.232283863","rc":[{"batb":[[0,1.05,200],[1,1.04,251.05],[2,1.03,533.33]],"ltp":5.1,"tv":8.0,"id":61044843}]}]}
{"op":"mcm","clk":"11987129836","pt":1724933270049,"mc":[{"id":"1.232283863","rc":[{"batb":[[0,1.06,5],[1,1.05,200],[2,1.04,251.05]],"ltp":5.1,"tv":8.0,"id":61044843}]}]}
{"op":"mcm","clk":"11987130087","pt":1724933273547,"mc":[{"id":"1.232283863","rc":[{"batb":[[0,1.05,200],[1,1.04,251.05],[2,1.03,533.33]],"ltp":5.1,"tv":8.0,"id":61044843}]}]}
{"op":"mcm","clk":"11987130386","pt":1724933277870,"mc":[{"id":"1.232283863","rc":[{"batb":[[0,1.06,5],[1,1.05,200],[2,1.04,251.05]],"ltp":5.1,"tv":8.0,"id":61044843}]}]}
{"op":"mcm","clk":"11987130674","pt":1724933281281,"mc":[{"id":"1.232283863","rc":[{"batb":[[0,1.05,200],[1,1.04,251.05],[2,1.03,533.33]],"ltp":5.1,"tv":8.0,"id":61044843}]}]}
{"op":"mcm","clk":"11987130941","pt":1724933284475,"mc":[{"id":"1.232283863","rc":[{"batb":[[0,1.06,5],[1,1.05,200],[2,1.04,251.05]],"ltp":5.1,"tv":8.0,"id":61044843}]}]}
{"op":"mcm","clk":"11987131214","pt":1724933287778,"mc":[{"id":"1.232283863","rc":[{"batb":[[0,1.05,200],[1,1.04,251.05],[2,1.03,533.33]],"ltp":5.1,"tv":8.0,"id":61044843}]}]}
{"op":"mcm","clk":"11987131615","pt":1724933293067,"mc":[{"id":"1.232283863","rc":[{"batb":[[0,1.06,5],[1,1.05,200],[2,1.04,251.05]],"ltp":5.1,"tv":8.0,"id":61044843}]}]}
{"op":"mcm","clk":"11987131904","pt":1724933296561,"mc":[{"id":"1.232283863","rc":[{"batb":[[0,1.05,200],[1,1.04,251.05],[2,1.03,533.33]],"ltp":5.1,"tv":8.0,"id":61044843}]}]}
{"op":"mcm","clk":"11987132049","pt":1724933298872,"mc":[{"id":"1.232283863","rc":[{"batb":[[0,1.06,5],[1,1.05,200],[2,1.04,251.05]],"ltp":5.1,"tv":8.0,"id":61044843}]}]}
{"op":"mcm","clk":"11987132300","pt":1724933302370,"mc":[{"id":"1.232283863","rc":[{"batb":[[0,1.05,200],[1,1.04,251.05],[2,1.03,533.33]],"ltp":5.1,"tv":8.0,"id":61044843}]}]}
{"op":"mcm","clk":"11987132782","pt":1724933308495,"mc":[{"id":"1.232283863","rc":[{"batb":[[0,1.06,5],[1,1.05,200],[2,1.04,251.05]],"ltp":5.1,"tv":8.0,"id":61044843}]}]}
{"op":"mcm","clk":"11987133067","pt":1724933312682,"mc":[{"id":"1.232283863","rc":[{"batb":[[0,1.05,200],[1,1.04,251.05],[2,1.03,533.33]],"ltp":5.1,"tv":8.0,"id":61044843}]}]}
{"op":"mcm","clk":"11987133696","pt":1724933321114,"mc":[{"id":"1.232283863","rc":[{"batb":[[0,1.06,5],[1,1.05,200],[2,1.04,251.05]],"ltp":5.1,"tv":8.0,"id":61044843}]}]}
{"op":"mcm","clk":"11987133933","pt":1724933324512,"mc":[{"id":"1.232283863","rc":[{"batb":[[0,1.05,200],[1,1.04,251.05],[2,1.03,533.33]],"ltp":5.1,"tv":8.0,"id":61044843}]}]}
{"op":"mcm","clk":"11987134096","pt":1724933326827,"mc":[{"id":"1.232283863","rc":[{"batb":[[0,1.06,5],[1,1.05,200],[2,1.04,251.05]],"ltp":5.1,"tv":8.0,"id":61044843}]}]}
{"op":"mcm","clk":"11987134323","pt":1724933330125,"mc":[{"id":"1.232283863","rc":[{"batb":[[0,1.05,200],[1,1.04,251.05],[2,1.03,533.33]],"ltp":5.1,"tv":8.0,"id":61044843}]}]}
{"op":"mcm","clk":"11987135163","pt":1724933342011,"mc":[{"id":"1.232283863","rc":[{"batb":[[0,1.06,5],[1,1.05,200],[2,1.04,251.05]],"ltp":5.1,"tv":8.0,"id":61044843}]}]}
{"op":"mcm","clk":"11987135423","pt":1724933345305,"mc":[{"id":"1.232283863","rc":[{"batb":[[0,1.05,200],[1,1.04,251.05],[2,1.03,533.33]],"ltp":5.1,"tv":8.0,"id":61044843}]}]}
{"op":"mcm","clk":"11987135723","pt":1724933349642,"mc":[{"id":"1.232283863","rc":[{"batb":[[0,1.06,5],[1,1.05,200],[2,1.04,251.05]],"ltp":5.1,"tv":8.0,"id":61044843}]}]}
{"op":"mcm","clk":"11987135993","pt":1724933353047,"mc":[{"id":"1.232283863","rc":[{"batb":[[0,1.05,200],[1,1.04,251.05],[2,1.03,533.33]],"ltp":5.1,"tv":8.0,"id":61044843}]}]}
{"op":"mcm","clk":"11987136565","pt":1724933361128,"mc":[{"id":"1.232283863","rc":[{"batb":[[0,1.06,5],[1,1.05,200],[2,1.04,251.05]],"ltp":5.1,"tv":8.0,"id":61044843}]}]}
{"op":"mcm","clk":"11987136884","pt":1724933364834,"mc":[{"id":"1.232283863","rc":[{"batb":[[0,1.05,200],[1,1.04,251.05],[2,1.03,533.33]],"ltp":5.1,"tv":8.0,"id":61044843}]}]}
{"op":"mcm","clk":"11987137111","pt":1724933368072,"mc":[{"id":"1.232283863","rc":[{"batb":[[0,1.06,5],[1,1.05,200],[2,1.04,251.05]],"ltp":5.1,"tv":8.0,"id":61044843}]}]}
{"op":"mcm","clk":"11987137321","pt":1724933371467,"mc":[{"id":"1.232283863","rc":[{"batb":[[0,1.05,200],[1,1.04,251.05],[2,1.03,533.33]],"ltp":5.1,"tv":8.0,"id":61044843}]}]}
{"op":"mcm","clk":"11987137570","pt":1724933374557,"mc":[{"id":"1.232283863","rc":[{"batb":[[0,1.06,5],[1,1.05,200],[2,1.04,251.05]],"ltp":5.1,"tv":8.0,"id":61044843}]}]}
{"op":"mcm","clk":"11987137824","pt":1724933377963,"mc":[{"id":"1.232283863","rc":[{"batb":[[0,1.05,200],[1,1.04,251.05],[2,1.03,533.33]],"ltp":5.1,"tv":8.0,"id":61044843}]}]}
{"op":"mcm","clk":"11987138290","pt":1724933384146,"mc":[{"id":"1.232283863","rc":[{"batb":[[0,1.06,5],[1,1.05,200],[2,1.04,251.05]],"ltp":5.1,"tv":8.0,"id":61044843}]}]}
{"op":"mcm","clk":"11987138538","pt":1724933387487,"mc":[{"id":"1.232283863","rc":[{"batb":[[0,1.05,200],[1,1.04,251.05],[2,1.03,533.33]],"ltp":5.1,"tv":8.0,"id":61044843}]}]}
{"op":"mcm","clk":"11987138849","pt":1724933391564,"mc":[{"id":"1.232283863","rc":[{"batb":[[0,1.06,5],[1,1.05,200],[2,1.04,251.05]],"ltp":5.1,"tv":8.0,"id":61044843}]}]}
{"op":"mcm","clk":"11987139131","pt":1724933394972,"mc":[{"id":"1.232283863","rc":[{"batb":[[0,1.05,200],[1,1.04,251.05],[2,1.03,533.33]],"ltp":5.1,"tv":8.0,"id":61044843}]}]}
{"op":"mcm","clk":"11987139336","pt":1724933397966,"mc":[{"id":"1.232283863","rc":[{"batb":[[0,1.06,5],[1,1.05,200],[2,1.04,251.05]],"ltp":5.1,"tv":8.0,"id":61044843}]}]}
{"op":"mcm","clk":"11987139577","pt":1724933401275,"mc":[{"id":"1.232283863","rc":[{"batb":[[0,1.05,200],[1,1.04,251.05],[2,1.03,533.33]],"ltp":5.1,"tv":8.0,"id":61044843}]}]}
{"op":"mcm","clk":"11987139857","pt":1724933404173,"mc":[{"id":"1.232283863","rc":[{"batb":[[0,1.06,5],[1,1.05,200],[2,1.04,251.05]],"ltp":5.1,"tv":8.0,"id":61044843}]}]}
{"op":"mcm","clk":"11987140176","pt":1724933407377,"mc":[{"id":"1.232283863","rc":[{"batb":[[0,1.05,200],[1,1.04,251.05],[2,1.03,533.33]],"ltp":5.1,"tv":8.0,"id":61044843}]}]}
{"op":"mcm","clk":"11987140384","pt":1724933409911,"mc":[{"id":"1.232283863","rc":[{"batb":[[0,1.06,5],[1,1.05,200],[2,1.04,251.05]],"ltp":5.1,"tv":8.0,"id":61044843}]}]}
{"op":"mcm","clk":"11987140618","pt":1724933413275,"mc":[{"id":"1.232283863","rc":[{"batb":[[0,1.05,200],[1,1.04,251.05],[2,1.03,533.33]],"ltp":5.1,"tv":8.0,"id":61044843}]}]}
{"op":"mcm","clk":"11987141436","pt":1724933424126,"mc":[{"id":"1.232283863","rc":[{"batb":[[0,1.06,5],[1,1.05,200],[2,1.04,251.05]],"ltp":5.1,"tv":8.0,"id":61044843}]}]}
{"op":"mcm","clk":"11987141703","pt":1724933427485,"mc":[{"id":"1.232283863","rc":[{"batb":[[0,1.05,200],[1,1.04,251.05],[2,1.03,533.33]],"ltp":5.1,"tv":8.0,"id":61044843}]}]}
{"op":"mcm","clk":"11987142011","pt":1724933431206,"mc":[{"id":"1.232283863","rc":[{"batb":[[0,1.06,5],[1,1.05,200],[2,1.04,251.05]],"ltp":5.1,"tv":8.0,"id":61044843}]}]}
{"op":"mcm","clk":"11987142319","pt":1724933434716,"mc":[{"id":"1.232283863","rc":[{"batb":[[0,1.05,200],[1,1.04,251.05],[2,1.03,533.33]],"ltp":5.1,"tv":8.0,"id":61044843}]}]}
{"op":"mcm","clk":"11987142684","pt":1724933438531,"mc":[{"id":"1.232283863","rc":[{"batb":[[0,1.06,5],[1,1.05,200],[2,1.04,251.05]],"ltp":5.1,"tv":8.0,"id":61044843}]}]}
{"op":"mcm","clk":"11987142945","pt":1724933441830,"mc":[{"id":"1.232283863","rc":[{"batb":[[0,1.05,200],[1,1.04,251.05],[2,1.03,533.33]],"ltp":5.1,"tv":8.0,"id":61044843}]}]}
{"op":"mcm","clk":"11987143161","pt":1724933444934,"mc":[{"id":"1.232283863","rc":[{"batb":[[0,1.06,5],[1,1.05,200],[2,1.04,251.05]],"ltp":5.1,"tv":8.0,"id":61044843}]}]}
{"op":"mcm","clk":"11987143397","pt":1724933448207,"mc":[{"id":"1.232283863","rc":[{"batb":[[0,1.05,200],[1,1.04,251.05],[2,1.03,533.33]],"ltp":5.1,"tv":8.0,"id":61044843}]}]}
{"op":"mcm","clk":"11987143592","pt":1724933450523,"mc":[{"id":"1.232283863","rc":[{"batb":[[0,1.06,5],[1,1.05,200],[2,1.04,251.05]],"ltp":5.1,"tv":8.0,"id":61044843}]}]}
{"op":"mcm","clk":"11987143874","pt":1724933453815,"mc":[{"id":"1.232283863","rc":[{"batb":[[0,1.05,200],[1,1.04,251.05],[2,1.03,533.33]],"ltp":5.1,"tv":8.0,"id":61044843}]}]}
{"op":"mcm","clk":"11987147130","pt":1724933489785,"mc":[{"id":"1.232283863","rc":[{"batb":[[0,1.06,5],[1,1.05,200],[2,1.04,251.05]],"ltp":5.1,"tv":8.0,"id":61044843}]}]}
{"op":"mcm","clk":"11987147429","pt":1724933492982,"mc":[{"id":"1.232283863","rc":[{"batb":[[0,1.05,200],[1,1.04,251.05],[2,1.03,533.33]],"ltp":5.1,"tv":8.0,"id":61044843}]}]}
{"op":"mcm","clk":"11987147678","pt":1724933495558,"mc":[{"id":"1.232283863","rc":[{"batb":[[0,1.06,5],[1,1.05,200],[2,1.04,251.05]],"ltp":5.1,"tv":8.0,"id":61044843}]}]}
{"op":"mcm","clk":"11987148004","pt":1724933498957,"mc":[{"id":"1.232283863","rc":[{"batb":[[0,1.05,200],[1,1.04,251.05],[2,1.03,533.33]],"ltp":5.1,"tv":8.0,"id":61044843}]}]}
{"op":"mcm","clk":"11987148611","pt":1724933505872,"mc":[{"id":"1.232283863","rc":[{"batb":[[0,1.06,5],[1,1.05,200],[2,1.04,251.05]],"ltp":5.1,"tv":8.0,"id":61044843}]}]}
{"op":"mcm","clk":"11987148918","pt":1724933509107,"mc":[{"id":"1.232283863","rc":[{"batb":[[0,1.05,200],[1,1.04,251.05],[2,1.03,533.33]],"ltp":5.1,"tv":8.0,"id":61044843}]}]}
{"op":"mcm","clk":"11987149506","pt":1724933515394,"mc":[{"id":"1.232283863","rc":[{"batb":[[0,1.06,5],[1,1.05,200],[2,1.04,251.05]],"ltp":5.1,"tv":8.0,"id":61044843}]}]}
{"op":"mcm","clk":"11987149765","pt":1724933518583,"mc":[{"id":"1.232283863","rc":[{"batb":[[0,1.05,200],[1,1.04,251.05],[2,1.03,533.33]],"ltp":5.1,"tv":8.0,"id":61044843}]}]}
{"op":"mcm","clk":"11987150257","pt":1724933523422,"mc":[{"id":"1.232283863","rc":[{"batb":[[0,1.06,5],[1,1.05,200],[2,1.04,251.05]],"ltp":5.1,"tv":8.0,"id":61044843}]}]}
{"op":"mcm","clk":"11987150629","pt":1724933526890,"mc":[{"id":"1.232283863","rc":[{"batb":[[0,1.05,200],[1,1.04,251.05],[2,1.03,533.33]],"ltp":5.1,"tv":8.0,"id":61044843}]}]}
{"op":"mcm","clk":"11987151282","pt":1724933533281,"mc":[{"id":"1.232283863","rc":[{"batb":[[0,1.06,5],[1,1.05,200],[2,1.04,251.05]],"ltp":5.1,"tv":8.0,"id":61044843}]}]}
{"op":"mcm","clk":"11987151628","pt":1724933536687,"mc":[{"id":"1.232283863","rc":[{"batb":[[0,1.05,200],[1,1.04,251.05],[2,1.03,533.33]],"ltp":5.1,"tv":8.0,"id":61044843}]}]}
{"op":"mcm","clk":"11987152383","pt":1724933544630,"mc":[{"id":"1.232283863","rc":[{"batb":[[0,1.06,5],[1,1.05,200],[2,1.04,251.05]],"ltp":5.1,"tv":8.0,"id":61044843}]}]}
{"op":"mcm","clk":"11987152690","pt":1724933548024,"mc":[{"id":"1.232283863","rc":[{"batb":[[0,1.05,200],[1,1.04,251.05],[2,1.03,533.33]],"ltp":5.1,"tv":8.0,"id":61044843}]}]}
{"op":"mcm","clk":"11987152929","pt":1724933550447,"mc":[{"id":"1.232283863","rc":[{"batb":[[0,1.06,5],[1,1.05,200],[2,1.04,251.05]],"ltp":5.1,"tv":8.0,"id":61044843}]}]}
{"op":"mcm","clk":"11987153262","pt":1724933553870,"mc":[{"id":"1.232283863","rc":[{"batb":[[0,1.05,200],[1,1.04,251.05],[2,1.03,533.33]],"ltp":5.1,"tv":8.0,"id":61044843}]}]}
{"op":"mcm","clk":"11987154637","pt":1724933568378,"mc":[{"id":"1.232283863","rc":[{"batb":[[0,1.06,5],[1,1.05,200],[2,1.04,251.05]],"ltp":5.1,"tv":8.0,"id":61044843}]}]}
{"op":"mcm","clk":"11987154998","pt":1724933571855,"mc":[{"id":"1.232283863","rc":[{"batb":[[0,1.05,200],[1,1.04,251.05],[2,1.03,533.33]],"ltp":5.1,"tv":8.0,"id":61044843}]}]}
{"op":"mcm","clk":"11987155431","pt":1724933576491,"mc":[{"id":"1.232283863","rc":[{"batb":[[0,1.06,5],[1,1.05,200],[2,1.04,251.05]],"ltp":5.1,"tv":8.0,"id":61044843}]}]}
{"op":"mcm","clk":"11987155720","pt":1724933579690,"mc":[{"id":"1.232283863","rc":[{"batb":[[0,1.05,200],[1,1.04,251.05],[2,1.03,533.33]],"ltp":5.1,"tv":8.0,"id":61044843}]}]}
{"op":"mcm","clk":"11987156187","pt":1724933584604,"mc":[{"id":"1.232283863","rc":[{"batb":[[0,1.06,5],[1,1.05,200],[2,1.04,251.05]],"ltp":5.1,"tv":8.0,"id":61044843}]}]}
{"op":"mcm","clk":"11987156535","pt":1724933588115,"mc":[{"id":"1.232283863","rc":[{"batb":[[0,1.05,200],[1,1.04,251.05],[2,1.03,533.33]],"ltp":5.1,"tv":8.0,"id":61044843}]}]}
{"op":"mcm","clk":"11987157212","pt":1724933595891,"mc":[{"id":"1.232283863","rc":[{"batb":[[0,1.06,5],[1,1.05,200],[2,1.04,251.05]],"ltp":5.1,"tv":8.0,"id":61044843}]}]}
{"op":"mcm","clk":"11987157501","pt":1724933599307,"mc":[{"id":"1.232283863","rc":[{"batb":[[0,1.05,200],[1,1.04,251.05],[2,1.03,533.33]],"ltp":5.1,"tv":8.0,"id":61044843}]}]}
{"op":"mcm","clk":"11987157744","pt":1724933601897,"mc":[{"id":"1.232283863","rc":[{"batb":[[0,1.06,5],[1,1.05,200],[2,1.04,251.05]],"ltp":5.1,"tv":8.0,"id":61044843}]}]}
{"op":"mcm","clk":"11987158047","pt":1724933605319,"mc":[{"id":"1.232283863","rc":[{"batb":[[0,1.05,200],[1,1.04,251.05],[2,1.03,533.33]],"ltp":5.1,"tv":8.0,"id":61044843}]}]}
{"op":"mcm","clk":"11987158532","pt":1724933611011,"mc":[{"id":"1.232283863","rc":[{"batb":[[0,1.06,5],[1,1.05,200],[2,1.04,251.05]],"ltp":5.1,"tv":8.0,"id":61044843}]}]}
{"op":"mcm","clk":"11987158827","pt":1724933614351,"mc":[{"id":"1.232283863","rc":[{"batb":[[0,1.05,200],[1,1.04,251.05],[2,1.03,533.33]],"ltp":5.1,"tv":8.0,"id":61044843}]}]}
{"op":"mcm","clk":"11987159619","pt":1724933624215,"mc":[{"id":"1.232283863","rc":[{"batb":[[0,1.06,5],[1,1.05,200],[2,1.04,251.05]],"ltp":5.1,"tv":8.0,"id":61044843}]}]}
{"op":"mcm","clk":"11987159914","pt":1724933627609,"mc":[{"id":"1.232283863","rc":[{"batb":[[0,1.05,200],[1,1.04,251.05],[2,1.03,533.33]],"ltp":5.1,"tv":8.0,"id":61044843}]}]}
{"op":"mcm","clk":"11987160615","pt":1724933636558,"mc":[{"id":"1.232283863","rc":[{"batb":[[0,1.06,5],[1,1.05,200],[2,1.04,251.05]],"ltp":5.1,"tv":8.0,"id":61044843}]}]}
{"op":"mcm","clk":"11987160845","pt":1724933639849,"mc":[{"id":"1.232283863","rc":[{"batb":[[0,1.05,200],[1,1.04,251.05],[2,1.03,533.33]],"ltp":5.1,"tv":8.0,"id":61044843}]}]}
{"op":"mcm","clk":"11987161094","pt":1724933642851,"mc":[{"id":"1.232283863","rc":[{"batb":[[0,1.06,5],[1,1.05,200],[2,1.04,251.05]],"ltp":5.1,"tv":8.0,"id":61044843}]}]}
{"op":"mcm","clk":"11987161404","pt":1724933646163,"mc":[{"id":"1.232283863","rc":[{"batb":[[0,1.05,200],[1,1.04,251.05],[2,1.03,533.33]],"ltp":5.1,"tv":8.0,"id":61044843}]}]}
{"op":"mcm","clk":"11987161891","pt":1724933651847,"mc":[{"id":"1.232283863","rc":[{"batb":[[0,1.06,5],[1,1.05,200],[2,1.04,251.05]],"ltp":5.1,"tv":8.0,"id":61044843}]}]}
{"op":"mcm","clk":"11987162208","pt":1724933655342,"mc":[{"id":"1.232283863","rc":[{"batb":[[0,1.05,200],[1,1.04,251.05],[2,1.03,533.33]],"ltp":5.1,"tv":8.0,"id":61044843}]}]}
{"op":"mcm","clk":"11987162396","pt":1724933657463,"mc":[{"id":"1.232283863","rc":[{"batb":[[0,1.06,5],[1,1.05,200],[2,1.04,251.05]],"ltp":5.1,"tv":8.0,"id":61044843}]}]}
{"op":"mcm","clk":"11987162645","pt":1724933660869,"mc":[{"id":"1.232283863","rc":[{"batb":[[0,1.05,200],[1,1.04,251.05],[2,1.03,533.33]],"ltp":5.1,"tv":8.0,"id":61044843}]}]}
{"op":"mcm","clk":"11987163251","pt":1724933668574,"mc":[{"id":"1.232283863","rc":[{"batb":[[0,1.06,5],[1,1.05,200],[2,1.04,251.05]],"ltp":5.1,"tv":8.0,"id":61044843}]}]}
{"op":"mcm","clk":"11987163542","pt":1724933671982,"mc":[{"id":"1.232283863","rc":[{"batb":[[0,1.05,200],[1,1.04,251.05],[2,1.03,533.33]],"ltp":5.1,"tv":8.0,"id":61044843}]}]}
{"op":"mcm","clk":"11987163786","pt":1724933675293,"mc":[{"id":"1.232283863","rc":[{"batb":[[0,1.06,5],[1,1.05,200],[2,1.04,251.05]],"ltp":5.1,"tv":8.0,"id":61044843}]}]}
{"op":"mcm","clk":"11987164124","pt":1724933678702,"mc":[{"id":"1.232283863","rc":[{"batb":[[0,1.05,200],[1,1.04,251.05],[2,1.03,533.33]],"ltp":5.1,"tv":8.0,"id":61044843}]}]}
{"op":"mcm","clk":"11987165215","pt":1724933692918,"mc":[{"id":"1.232283863","rc":[{"batb":[[0,1.06,5],[1,1.05,200],[2,1.04,251.05]],"ltp":5.1,"tv":8.0,"id":61044843}]}]}
{"op":"mcm","clk":"11987165431","pt":1724933696213,"mc":[{"id":"1.232283863","rc":[{"batb":[[0,1.05,200],[1,1.04,251.05],[2,1.03,533.33]],"ltp":5.1,"tv":8.0,"id":61044843}]}]}
{"op":"mcm","clk":"11987165859","pt":1724933701325,"mc":[{"id":"1.232283863","rc":[{"batb":[[0,1.06,5],[1,1.05,200],[2,1.04,251.05]],"ltp":5.1,"tv":8.0,"id":61044843}]}]}
{"op":"mcm","clk":"11987166178","pt":1724933704803,"mc":[{"id":"1.232283863","rc":[{"batb":[[0,1.05,200],[1,1.04,251.05],[2,1.03,533.33]],"ltp":5.1,"tv":8.0,"id":61044843}]}]}
{"op":"mcm","clk":"11987166505","pt":1724933708212,"mc":[{"id":"1.232283863","rc":[{"batb":[[0,1.06,5],[1,1.05,200],[2,1.04,251.05]],"ltp":5.1,"tv":8.0,"id":61044843}]}]}
{"op":"mcm","clk":"11987166827","pt":1724933711636,"mc":[{"id":"1.232283863","rc":[{"batb":[[0,1.05,200],[1,1.04,251.05],[2,1.03,533.33]],"ltp":5.1,"tv":8.0,"id":61044843}]}]}
{"op":"mcm","clk":"11987167040","pt":1724933714014,"mc":[{"id":"1.232283863","rc":[{"batb":[[0,1.06,5],[1,1.05,200],[2,1.04,251.05]],"ltp":5.1,"tv":8.0,"id":61044843}]}]}
{"op":"mcm","clk":"11987167362","pt":1724933717427,"mc":[{"id":"1.232283863","rc":[{"batb":[[0,1.05,200],[1,1.04,251.05],[2,1.03,533.33]],"ltp":5.1,"tv":8.0,"id":61044843}]}]}
{"op":"mcm","clk":"11987167623","pt":1724933720014,"mc":[{"id":"1.232283863","rc":[{"batb":[[0,1.06,5],[1,1.05,200],[2,1.04,251.05]],"ltp":5.1,"tv":8.0,"id":61044843}]}]}
{"op":"mcm","clk":"11987167926","pt":1724933723357,"mc":[{"id":"1.232283863","rc":[{"batb":[[0,1.05,200],[1,1.04,251.05],[2,1.03,533.33]],"ltp":5.1,"tv":8.0,"id":61044843}]}]}
{"op":"mcm","clk":"11987168363","pt":1724933728168,"mc":[{"id":"1.232283863","rc":[{"batb":[[0,1.06,5],[1,1.05,200],[2,1.04,251.05]],"ltp":5.1,"tv":8.0,"id":61044843}]}]}
{"op":"mcm","clk":"11987168659","pt":1724933731540,"mc":[{"id":"1.232283863","rc":[{"batb":[[0,1.05,200],[1,1.04,251.05],[2,1.03,533.33]],"ltp":5.1,"tv":8.0,"id":61044843}]}]}
{"op":"mcm","clk":"11987168888","pt":1724933734273,"mc":[{"id":"1.232283863","rc":[{"batb":[[0,1.06,5],[1,1.05,200],[2,1.04,251.05]],"ltp":5.1,"tv":8.0,"id":61044843}]}]}
{"op":"mcm","clk":"11987169207","pt":1724933737581,"mc":[{"id":"1.232283863","rc":[{"batb":[[0,1.05,200],[1,1.04,251.05],[2,1.03,533.33]],"ltp":5.1,"tv":8.0,"id":61044843}]}]}
{"op":"mcm","clk":"11987169487","pt":1724933740167,"mc":[{"id":"1.232283863","rc":[{"batb":[[0,1.06,5],[1,1.05,200],[2,1.04,251.05]],"ltp":5.1,"tv":8.0,"id":61044843}]}]}
{"op":"mcm","clk":"11987169789","pt":1724933743585,"mc":[{"id":"1.232283863","rc":[{"batb":[[0,1.05,200],[1,1.04,251.05],[2,1.03,533.33]],"ltp":5.1,"tv":8.0,"id":61044843}]}]}
{"op":"mcm","clk":"11987170102","pt":1724933747463,"mc":[{"id":"1.232283863","rc":[{"batb":[[0,1.06,5],[1,1.05,200],[2,1.04,251.05]],"ltp":5.1,"tv":8.0,"id":61044843}]}]}
{"op":"mcm","clk":"11987170398","pt":1724933750965,"mc":[{"id":"1.232283863","rc":[{"batb":[[0,1.05,200],[1,1.04,251.05],[2,1.03,533.33]],"ltp":5.1,"tv":8.0,"id":61044843}]}]}
{"op":"mcm","clk":"11987170643","pt":1724933753767,"mc":[{"id":"1.232283863","rc":[{"batb":[[0,1.06,5],[1,1.05,200],[2,1.04,251.05]],"ltp":5.1,"tv":8.0,"id":61044843}]}]}
{"op":"mcm","clk":"11987170940","pt":1724933757282,"mc":[{"id":"1.232283863","rc":[{"batb":[[0,1.05,200],[1,1.04,251.05],[2,1.03,533.33]],"ltp":5.1,"tv":8.0,"id":61044843}]}]}
{"op":"mcm","clk":"11987171591","pt":1724933764608,"mc":[{"id":"1.232283863","rc":[{"batb":[[0,1.06,5],[1,1.05,200],[2,1.04,251.05]],"ltp":5.1,"tv":8.0,"id":61044843}]}]}
{"op":"mcm","clk":"11987171868","pt":1724933767890,"mc":[{"id":"1.232283863","rc":[{"batb":[[0,1.05,200],[1,1.04,251.05],[2,1.03,533.33]],"ltp":5.1,"tv":8.0,"id":61044843}]}]}
{"op":"mcm","clk":"11987172690","pt":1724933777086,"mc":[{"id":"1.232283863","rc":[{"batb":[[0,1.06,5],[1,1.05,200],[2,1.04,251.05]],"ltp":5.1,"tv":8.0,"id":61044843}]}]}
{"op":"mcm","clk":"11987172967","pt":1724933780309,"mc":[{"id":"1.232283863","rc":[{"batb":[[0,1.05,200],[1,1.04,251.05],[2,1.03,533.33]],"ltp":5.1,"tv":8.0,"id":61044843}]}]}
{"op":"mcm","clk":"11987173208","pt":1724933783010,"mc":[{"id":"1.232283863","rc":[{"batb":[[0,1.06,5],[1,1.05,200],[2,1.04,251.05]],"ltp":5.1,"tv":8.0,"id":61044843}]}]}
{"op":"mcm","clk":"11987173549","pt":1724933786497,"mc":[{"id":"1.232283863","rc":[{"batb":[[0,1.05,200],[1,1.04,251.05],[2,1.03,533.33]],"ltp":5.1,"tv":8.0,"id":61044843}]}]}
{"op":"mcm","clk":"11987173850","pt":1724933790335,"mc":[{"id":"1.232283863","rc":[{"batb":[[0,1.06,5],[1,1.05,200],[2,1.04,251.05]],"ltp":5.1,"tv":8.0,"id":61044843}]}]}
{"op":"mcm","clk":"11987174152","pt":1724933793792,"mc":[{"id":"1.232283863","rc":[{"batb":[[0,1.05,200],[1,1.04,251.05],[2,1.03,533.33]],"ltp":5.1,"tv":8.0,"id":61044843}]}]}
{"op":"mcm","clk":"11987174724","pt":1724933800299,"mc":[{"id":"1.232283863","rc":[{"batb":[[0,1.06,5],[1,1.05,200],[2,1.04,251.05]],"ltp":5.1,"tv":8.0,"id":61044843}]}]}
{"op":"mcm","clk":"11987174996","pt":1724933803704,"mc":[{"id":"1.232283863","rc":[{"batb":[[0,1.05,200],[1,1.04,251.05],[2,1.03,533.33]],"ltp":5.1,"tv":8.0,"id":61044843}]}]}
{"op":"mcm","clk":"11987175604","pt":1724933812027,"mc":[{"id":"1.232283863","rc":[{"batb":[[0,1.06,5],[1,1.05,200],[2,1.04,251.05]],"ltp":5.1,"tv":8.0,"id":61044843}]}]}
{"op":"mcm","clk":"11987175886","pt":1724933815435,"mc":[{"id":"1.232283863","rc":[{"batb":[[0,1.05,200],[1,1.04,251.05],[2,1.03,533.33]],"ltp":5.1,"tv":8.0,"id":61044843}]}]}
{"op":"mcm","clk":"11987176071","pt":1724933817713,"mc":[{"id":"1.232283863","rc":[{"batb":[[0,1.06,5],[1,1.05,200],[2,1.04,251.05]],"ltp":5.1,"tv":8.0,"id":61044843}]}]}
{"op":"mcm","clk":"11987176331","pt":1724933821123,"mc":[{"id":"1.232283863","rc":[{"batb":[[0,1.05,200],[1,1.04,251.05],[2,1.03,533.33]],"ltp":5.1,"tv":8.0,"id":61044843}]}]}
{"op":"mcm","clk":"11987176514","pt":1724933823617,"mc":[{"id":"1.232283863","rc":[{"batb":[[0,1.06,5],[1,1.05,200],[2,1.04,251.05]],"ltp":5.1,"tv":8.0,"id":61044843}]}]}
{"op":"mcm","clk":"11987176758","pt":1724933826974,"mc":[{"id":"1.232283863","rc":[{"batb":[[0,1.05,200],[1,1.04,251.05],[2,1.03,533.33]],"ltp":5.1,"tv":8.0,"id":61044843}]}]}
{"op":"mcm","clk":"11987177034","pt":1724933830564,"mc":[{"id":"1.232283863","rc":[{"batb":[[0,1.06,5],[1,1.05,200],[2,1.04,251.05]],"ltp":5.1,"tv":8.0,"id":61044843}]}]}
{"op":"mcm","clk":"11987177324","pt":1724933833958,"mc":[{"id":"1.232283863","rc":[{"batb":[[0,1.05,200],[1,1.04,251.05],[2,1.03,533.33]],"ltp":5.1,"tv":8.0,"id":61044843}]}]}
{"op":"mcm","clk":"11987178121","pt":1724933843555,"mc":[{"id":"1.232283863","rc":[{"batb":[[0,1.06,5],[1,1.05,200],[2,1.04,251.05]],"ltp":5.1,"tv":8.0,"id":61044843}]}]}
{"op":"mcm","clk":"11987178352","pt":1724933846760,"mc":[{"id":"1.232283863","rc":[{"batb":[[0,1.05,200],[1,1.04,251.05],[2,1.03,533.33]],"ltp":5.1,"tv":8.0,"id":61044843}]}]}
{"op":"mcm","clk":"11987178550","pt":1724933849438,"mc":[{"id":"1.232283863","rc":[{"batb":[[0,1.06,5],[1,1.05,200],[2,1.04,251.05]],"ltp":5.1,"tv":8.0,"id":61044843}]}]}
{"op":"mcm","clk":"11987178809","pt":1724933852744,"mc":[{"id":"1.232283863","rc":[{"batb":[[0,1.05,200],[1,1.04,251.05],[2,1.03,533.33]],"ltp":5.1,"tv":8.0,"id":61044843}]}]}
{"op":"mcm","clk":"11987179117","pt":1724933856878,"mc":[{"id":"1.232283863","rc":[{"batb":[[0,1.06,5],[1,1.05,200],[2,1.04,251.05]],"ltp":5.1,"tv":8.0,"id":61044843}]}]}
{"op":"mcm","clk":"11987179426","pt":1724933860437,"mc":[{"id":"1.232283863","rc":[{"batb":[[0,1.05,200],[1,1.04,251.05],[2,1.03,533.33]],"ltp":5.1,"tv":8.0,"id":61044843}]}]}
{"op":"mcm","clk":"11987180352","pt":1724933873010,"mc":[{"id":"1.232283863","rc":[{"batb":[[0,1.06,5],[1,1.05,200],[2,1.04,251.05]],"ltp":5.1,"tv":8.0,"id":61044843}]}]}
{"op":"mcm","clk":"11987180601","pt":1724933876354,"mc":[{"id":"1.232283863","rc":[{"batb":[[0,1.05,200],[1,1.04,251.05],[2,1.03,533.33]],"ltp":5.1,"tv":8.0,"id":61044843}]}]}
{"op":"mcm","clk":"11987180740","pt":1724933878554,"mc":[{"id":"1.232283863","rc":[{"batb":[[0,1.06,5],[1,1.05,200],[2,1.04,251.05]],"ltp":5.1,"tv":8.0,"id":61044843}]}]}
{"op":"mcm","clk":"11987180995","pt":1724933881970,"mc":[{"id":"1.232283863","rc":[{"batb":[[0,1.05,200],[1,1.04,251.05],[2,1.03,533.33]],"ltp":5.1,"tv":8.0,"id":61044843}]}]}
{"op":"mcm","clk":"11987181878","pt":1724933893980,"mc":[{"id":"1.232283863","rc":[{"batb":[[0,1.06,5],[1,1.05,200],[2,1.04,251.05]],"ltp":5.1,"tv":8.0,"id":61044843}]}]}
{"op":"mcm","clk":"11987182161","pt":1724933897399,"mc":[{"id":"1.232283863","rc":[{"batb":[[0,1.05,200],[1,1.04,251.05],[2,1.03,533.33]],"ltp":5.1,"tv":8.0,"id":61044843}]}]}
{"op":"mcm","clk":"11987182558","pt":1724933902390,"mc":[{"id":"1.232283863","rc":[{"batb":[[0,1.06,5],[1,1.05,200],[2,1.04,251.05]],"ltp":5.1,"tv":8.0,"id":61044843}]}]}
{"op":"mcm","clk":"11987182804","pt":1724933905645,"mc":[{"id":"1.232283863","rc":[{"batb":[[0,1.05,200],[1,1.04,251.05],[2,1.03,533.33]],"ltp":5.1,"tv":8.0,"id":61044843}]}]}
{"op":"mcm","clk":"11987183159","pt":1724933909850,"mc":[{"id":"1.232283863","rc":[{"batb":[[0,1.06,5],[1,1.05,200],[2,1.04,251.05]],"ltp":5.1,"tv":8.0,"id":61044843}]}]}
{"op":"mcm","clk":"11987183501","pt":1724933913533,"mc":[{"id":"1.232283863","rc":[{"batb":[[0,1.05,200],[1,1.04,251.05],[2,1.03,533.33]],"ltp":5.1,"tv":8.0,"id":61044843}]}]}
{"op":"mcm","clk":"11987184083","pt":1724933919960,"mc":[{"id":"1.232283863","rc":[{"batb":[[0,1.06,5],[1,1.05,200],[2,1.04,251.05]],"ltp":5.1,"tv":8.0,"id":61044843}]}]}
{"op":"mcm","clk":"11987184363","pt":1724933923337,"mc":[{"id":"1.232283863","rc":[{"batb":[[0,1.05,200],[1,1.04,251.05],[2,1.03,533.33]],"ltp":5.1,"tv":8.0,"id":61044843}]}]}
{"op":"mcm","clk":"11987185199","pt":1724933934969,"mc":[{"id":"1.232283863","rc":[{"batb":[[0,1.06,5],[1,1.05,200],[2,1.04,251.05]],"ltp":5.1,"tv":8.0,"id":61044843}]}]}
{"op":"mcm","clk":"11987185434","pt":1724933938279,"mc":[{"id":"1.232283863","rc":[{"batb":[[0,1.05,200],[1,1.04,251.05],[2,1.03,533.33]],"ltp":5.1,"tv":8.0,"id":61044843}]}]}
{"op":"mcm","clk":"11987186749","pt":1724933956764,"mc":[{"id":"1.232283863","rc":[{"batb":[[0,1.06,5],[1,1.05,200],[2,1.04,251.05]],"ltp":5.1,"tv":8.0,"id":61044843}]}]}
{"op":"mcm","clk":"11987186988","pt":1724933960290,"mc":[{"id":"1.232283863","rc":[{"batb":[[0,1.05,200],[1,1.04,251.05],[2,1.03,533.33]],"ltp":5.1,"tv":8.0,"id":61044843}]}]}
{"op":"mcm","clk":"11987187255","pt":1724933964366,"mc":[{"id":"1.232283863","rc":[{"batb":[[0,1.06,5],[1,1.05,200],[2,1.04,251.05]],"ltp":5.1,"tv":8.0,"id":61044843}]}]}
{"op":"mcm","clk":"11987187527","pt":1724933967920,"mc":[{"id":"1.232283863","rc":[{"batb":[[0,1.05,200],[1,1.04,251.05],[2,1.03,533.33]],"ltp":5.1,"tv":8.0,"id":61044843}]}]}
{"op":"mcm","clk":"11987187736","pt":1724933970497,"mc":[{"id":"1.232283863","rc":[{"batb":[[0,1.06,5],[1,1.05,200],[2,1.04,251.05]],"ltp":5.1,"tv":8.0,"id":61044843}]}]}
{"op":"mcm","clk":"11987188003","pt":1724933973695,"mc":[{"id":"1.232283863","rc":[{"batb":[[0,1.05,200],[1,1.04,251.05],[2,1.03,533.33]],"ltp":5.1,"tv":8.0,"id":61044843}]}]}
{"op":"mcm","clk":"11987188891","pt":1724933985316,"mc":[{"id":"1.232283863","rc":[{"batb":[[0,1.06,5],[1,1.05,200],[2,1.04,251.05]],"ltp":5.1,"tv":8.0,"id":61044843}]}]}
{"op":"mcm","clk":"11987189098","pt":1724933988716,"mc":[{"id":"1.232283863","rc":[{"batb":[[0,1.05,200],[1,1.04,251.05],[2,1.03,533.33]],"ltp":5.1,"tv":8.0,"id":61044843}]}]}
{"op":"mcm","clk":"11987189384","pt":1724933992629,"mc":[{"id":"1.232283863","rc":[{"batb":[[0,1.06,5],[1,1.05,200],[2,1.04,251.05]],"ltp":5.1,"tv":8.0,"id":61044843}]}]}
{"op":"mcm","clk":"11987189611","pt":1724933996034,"mc":[{"id":"1.232283863","rc":[{"batb":[[0,1.05,200],[1,1.04,251.05],[2,1.03,533.33]],"ltp":5.1,"tv":8.0,"id":61044843}]}]}
{"op":"mcm","clk":"11987189912","pt":1724933999837,"mc":[{"id":"1.232283863","rc":[{"batb":[[0,1.06,5],[1,1.05,200],[2,1.04,251.05]],"ltp":5.1,"tv":8.0,"id":61044843}]}]}
{"op":"mcm","clk":"11987190186","pt":1724934003151,"mc":[{"id":"1.232283863","rc":[{"batb":[[0,1.05,200],[1,1.04,251.05],[2,1.03,533.33]],"ltp":5.1,"tv":8.0,"id":61044843}]}]}
{"op":"mcm","clk":"11987190698","pt":1724934009240,"mc":[{"id":"1.232283863","rc":[{"batb":[[0,1.06,5],[1,1.05,200],[2,1.04,251.05]],"ltp":5.1,"tv":8.0,"id":61044843}]}]}
{"op":"mcm","clk":"11987190966","pt":1724934012531,"mc":[{"id":"1.232283863","rc":[{"batb":[[0,1.05,200],[1,1.04,251.05],[2,1.03,533.33]],"ltp":5.1,"tv":8.0,"id":61044843}]}]}
{"op":"mcm","clk":"11987191625","pt":1724934020935,"mc":[{"id":"1.232283863","rc":[{"batb":[[0,1.06,5],[1,1.05,200],[2,1.04,251.05]],"ltp":5.1,"tv":8.0,"id":61044843}]}]}
{"op":"mcm","clk":"11987191882","pt":1724934024442,"mc":[{"id":"1.232283863","rc":[{"batb":[[0,1.05,200],[1,1.04,251.05],[2,1.03,533.33]],"ltp":5.1,"tv":8.0,"id":61044843}]}]}
{"op":"mcm","clk":"11987192491","pt":1724934032237,"mc":[{"id":"1.232283863","rc":[{"batb":[[0,1.06,5],[1,1.05,200],[2,1.04,251.05]],"ltp":5.1,"tv":8.0,"id":61044843}]}]}
{"op":"mcm","clk":"11987192781","pt":1724934035757,"mc":[{"id":"1.232283863","rc":[{"batb":[[0,1.05,200],[1,1.04,251.05],[2,1.03,533.33]],"ltp":5.1,"tv":8.0,"id":61044843}]}]}
{"op":"mcm","clk":"11987193101","pt":1724934039268,"mc":[{"id":"1.232283863","rc":[{"batb":[[0,1.06,5],[1,1.05,200],[2,1.04,251.05]],"ltp":5.1,"tv":8.0,"id":61044843}]}]}
{"op":"mcm","clk":"11987193323","pt":1724934042574,"mc":[{"id":"1.232283863","rc":[{"batb":[[0,1.05,200],[1,1.04,251.05],[2,1.03,533.33]],"ltp":5.1,"tv":8.0,"id":61044843}]}]}
{"op":"mcm","clk":"11987193554","pt":1724934045357,"mc":[{"id":"1.232283863","rc":[{"batb":[[0,1.06,5],[1,1.05,200],[2,1.04,251.05]],"ltp":5.1,"tv":8.0,"id":61044843}]}]}
{"op":"mcm","clk":"11987193836","pt":1724934048768,"mc":[{"id":"1.232283863","rc":[{"batb":[[0,1.05,200],[1,1.04,251.05],[2,1.03,533.33]],"ltp":5.1,"tv":8.0,"id":61044843}]}]}
{"op":"mcm","clk":"11987194025","pt":1724934050984,"mc":[{"id":"1.232283863","rc":[{"batb":[[0,1.06,5],[1,1.05,200],[2,1.04,251.05]],"ltp":5.1,"tv":8.0,"id":61044843}]}]}
{"op":"mcm","clk":"11987194313","pt":1724934054289,"mc":[{"id":"1.232283863","rc":[{"batb":[[0,1.05,200],[1,1.04,251.05],[2,1.03,533.33]],"ltp":5.1,"tv":8.0,"id":61044843}]}]}
{"op":"mcm","clk":"11987194702","pt":1724934059082,"mc":[{"id":"1.232283863","rc":[{"batb":[[0,1.06,5],[1,1.05,200],[2,1.04,251.05]],"ltp":5.1,"tv":8.0,"id":61044843}]}]}
{"op":"mcm","clk":"11987194995","pt":1724934062595,"mc":[{"id":"1.232283863","rc":[{"batb":[[0,1.05,200],[1,1.04,251.05],[2,1.03,533.33]],"ltp":5.1,"tv":8.0,"id":61044843}]}]}
{"op":"mcm","clk":"11987195305","pt":1724934066216,"mc":[{"id":"1.232283863","rc":[{"batb":[[0,1.06,5],[1,1.05,200],[2,1.04,251.05]],"ltp":5.1,"tv":8.0,"id":61044843}]}]}
{"op":"mcm","clk":"11987195562","pt":1724934069616,"mc":[{"id":"1.232283863","rc":[{"batb":[[0,1.05,200],[1,1.04,251.05],[2,1.03,533.33]],"ltp":5.1,"tv":8.0,"id":61044843}]}]}
{"op":"mcm","clk":"11987196011","pt":1724934075936,"mc":[{"id":"1.232283863","rc":[{"batb":[[0,1.06,5],[1,1.05,200],[2,1.04,251.05]],"ltp":5.1,"tv":8.0,"id":61044843}]}]}
{"op":"mcm","clk":"11987196280","pt":1724934079519,"mc":[{"id":"1.232283863","rc":[{"batb":[[0,1.05,200],[1,1.04,251.05],[2,1.03,533.33]],"ltp":5.1,"tv":8.0,"id":61044843}]}]}
{"op":"mcm","clk":"11987196647","pt":1724934083817,"mc":[{"id":"1.232283863","rc":[{"batb":[[0,1.06,5],[1,1.05,200],[2,1.04,251.05]],"ltp":5.1,"tv":8.0,"id":61044843}]}]}
{"op":"mcm","clk":"11987196904","pt":1724934087233,"mc":[{"id":"1.232283863","rc":[{"batb":[[0,1.05,200],[1,1.04,251.05],[2,1.03,533.33]],"ltp":5.1,"tv":8.0,"id":61044843}]}]}
{"op":"mcm","clk":"11987197141","pt":1724934090123,"mc":[{"id":"1.232283863","rc":[{"batb":[[0,1.06,5],[1,1.05,200],[2,1.04,251.05]],"ltp":5.1,"tv":8.0,"id":61044843}]}]}
{"op":"mcm","clk":"11987197443","pt":1724934093606,"mc":[{"id":"1.232283863","rc":[{"batb":[[0,1.05,200],[1,1.04,251.05],[2,1.03,533.33]],"ltp":5.1,"tv":8.0,"id":61044843}]}]}
{"op":"mcm","clk":"11987198851","pt":1724934109554,"mc":[{"id":"1.232283863","rc":[{"batb":[[0,1.06,5],[1,1.05,200],[2,1.04,251.05]],"ltp":5.1,"tv":8.0,"id":61044843}]}]}
{"op":"mcm","clk":"11987199131","pt":1724934112968,"mc":[{"id":"1.232283863","rc":[{"batb":[[0,1.05,200],[1,1.04,251.05],[2,1.03,533.33]],"ltp":5.1,"tv":8.0,"id":61044843}]}]}
{"op":"mcm","clk":"11987199661","pt":1724934119071,"mc":[{"id":"1.232283863","rc":[{"batb":[[0,1.06,5],[1,1.05,200],[2,1.04,251.05]],"ltp":5.1,"tv":8.0,"id":61044843}]}]}
{"op":"mcm","clk":"11987199945","pt":1724934122460,"mc":[{"id":"1.232283863","rc":[{"batb":[[0,1.05,200],[1,1.04,251.05],[2,1.03,533.33]],"ltp":5.1,"tv":8.0,"id":61044843}]}]}
{"op":"mcm","clk":"11987200164","pt":1724934124871,"mc":[{"id":"1.232283863","rc":[{"batb":[[0,1.06,5],[1,1.05,200],[2,1.04,251.05]],"ltp":5.1,"tv":8.0,"id":61044843}]}]}
{"op":"mcm","clk":"11987200460","pt":1724934128180,"mc":[{"id":"1.232283863","rc":[{"batb":[[0,1.05,200],[1,1.04,251.05],[2,1.03,533.33]],"ltp":5.1,"tv":8.0,"id":61044843}]}]}
{"op":"mcm","clk":"11987200838","pt":1724934132055,"mc":[{"id":"1.232283863","rc":[{"batb":[[0,1.06,5],[1,1.05,200],[2,1.04,251.05]],"ltp":5.1,"tv":8.0,"id":61044843}]}]}
{"op":"mcm","clk":"11987201102","pt":1724934135474,"mc":[{"id":"1.232283863","rc":[{"batb":[[0,1.05,200],[1,1.04,251.05],[2,1.03,533.33]],"ltp":5.1,"tv":8.0,"id":61044843}]}]}
{"op":"mcm","clk":"11987201719","pt":1724934142999,"mc":[{"id":"1.232283863","rc":[{"batb":[[0,1.06,5],[1,1.05,200],[2,1.04,251.05]],"ltp":5.1,"tv":8.0,"id":61044843}]}]}
{"op":"mcm","clk":"11987202007","pt":1724934146511,"mc":[{"id":"1.232283863","rc":[{"batb":[[0,1.05,200],[1,1.04,251.05],[2,1.03,533.33]],"ltp":5.1,"tv":8.0,"id":61044843}]}]}
{"op":"mcm","clk":"11987202199","pt":1724934148676,"mc":[{"id":"1.232283863","rc":[{"batb":[[0,1.06,5],[1,1.05,200],[2,1.04,251.05]],"ltp":5.1,"tv":8.0,"id":61044843}]}]}
{"op":"mcm","clk":"11987202500","pt":1724934152184,"mc":[{"id":"1.232283863","rc":[{"batb":[[0,1.05,200],[1,1.04,251.05],[2,1.03,533.33]],"ltp":5.1,"tv":8.0,"id":61044843}]}]}
{"op":"mcm","clk":"11987202669","pt":1724934154390,"mc":[{"id":"1.232283863","rc":[{"batb":[[0,1.06,5],[1,1.05,200],[2,1.04,251.05]],"ltp":5.1,"tv":8.0,"id":61044843}]}]}
{"op":"mcm","clk":"11987202981","pt":1724934157688,"mc":[{"id":"1.232283863","rc":[{"batb":[[0,1.05,200],[1,1.04,251.05],[2,1.03,533.33]],"ltp":5.1,"tv":8.0,"id":61044843}]}]}
{"op":"mcm","clk":"11987203499","pt":1724934164103,"mc":[{"id":"1.232283863","rc":[{"batb":[[0,1.06,5],[1,1.05,200],[2,1.04,251.05]],"ltp":5.1,"tv":8.0,"id":61044843}]}]}
{"op":"mcm","clk":"11987203739","pt":1724934167400,"mc":[{"id":"1.232283863","rc":[{"batb":[[0,1.05,200],[1,1.04,251.05],[2,1.03,533.33]],"ltp":5.1,"tv":8.0,"id":61044843}]}]}
{"op":"mcm","clk":"11987203986","pt":1724934170243,"mc":[{"id":"1.232283863","rc":[{"batb":[[0,1.06,5],[1,1.05,200],[2,1.04,251.05]],"ltp":5.1,"tv":8.0,"id":61044843}]}]}
{"op":"mcm","clk":"11987204276","pt":1724934173643,"mc":[{"id":"1.232283863","rc":[{"batb":[[0,1.05,200],[1,1.04,251.05],[2,1.03,533.33]],"ltp":5.1,"tv":8.0,"id":61044843}]}]}
{"op":"mcm","clk":"11987204763","pt":1724934179710,"mc":[{"id":"1.232283863","rc":[{"batb":[[0,1.06,5],[1,1.05,200],[2,1.04,251.05]],"ltp":5.1,"tv":8.0,"id":61044843}]}]}
{"op":"mcm","clk":"11987205053","pt":1724934183245,"mc":[{"id":"1.232283863","rc":[{"batb":[[0,1.05,200],[1,1.04,251.05],[2,1.03,533.33]],"ltp":5.1,"tv":8.0,"id":61044843}]}]}
{"op":"mcm","clk":"11987205412","pt":1724934187923,"mc":[{"id":"1.232283863","rc":[{"batb":[[0,1.06,5],[1,1.05,200],[2,1.04,251.05]],"ltp":5.1,"tv":8.0,"id":61044843}]}]}
{"op":"mcm","clk":"11987205692","pt":1724934191270,"mc":[{"id":"1.232283863","rc":[{"batb":[[0,1.05,200],[1,1.04,251.05],[2,1.03,533.33]],"ltp":5.1,"tv":8.0,"id":61044843}]}]}
{"op":"mcm","clk":"11987205982","pt":1724934194775,"mc":[{"id":"1.232283863","rc":[{"batb":[[0,1.06,5],[1,1.05,200],[2,1.04,251.05]],"ltp":5.1,"tv":8.0,"id":61044843}]}]}
{"op":"mcm","clk":"11987206253","pt":1724934198172,"mc":[{"id":"1.232283863","rc":[{"batb":[[0,1.05,200],[1,1.04,251.05],[2,1.03,533.33]],"ltp":5.1,"tv":8.0,"id":61044843}]}]}
{"op":"mcm","clk":"11987206499","pt":1724934201166,"mc":[{"id":"1.232283863","rc":[{"batb":[[0,1.06,5],[1,1.05,200],[2,1.04,251.05]],"ltp":5.1,"tv":8.0,"id":61044843}]}]}
{"op":"mcm","clk":"11987206724","pt":1724934204557,"mc":[{"id":"1.232283863","rc":[{"batb":[[0,1.05,200],[1,1.04,251.05],[2,1.03,533.33]],"ltp":5.1,"tv":8.0,"id":61044843}]}]}
{"op":"mcm","clk":"11987207002","pt":1724934207954,"mc":[{"id":"1.232283863","rc":[{"batb":[[0,1.06,5],[1,1.05,200],[2,1.04,251.05]],"ltp":5.1,"tv":8.0,"id":61044843}]}]}
{"op":"mcm","clk":"11987207288","pt":1724934211254,"mc":[{"id":"1.232283863","rc":[{"batb":[[0,1.05,200],[1,1.04,251.05],[2,1.03,533.33]],"ltp":5.1,"tv":8.0,"id":61044843}]}]}
{"op":"mcm","clk":"11987207609","pt":1724934214958,"mc":[{"id":"1.232283863","rc":[{"batb":[[0,1.06,5],[1,1.05,200],[2,1.04,251.05]],"ltp":5.1,"tv":8.0,"id":61044843}]}]}
{"op":"mcm","clk":"11987207867","pt":1724934218161,"mc":[{"id":"1.232283863","rc":[{"batb":[[0,1.05,200],[1,1.04,251.05],[2,1.03,533.33]],"ltp":5.1,"tv":8.0,"id":61044843}]}]}
{"op":"mcm","clk":"11987208103","pt":1724934220849,"mc":[{"id":"1.232283863","rc":[{"batb":[[0,1.06,5],[1,1.05,200],[2,1.04,251.05]],"ltp":5.1,"tv":8.0,"id":61044843}]}]}
{"op":"mcm","clk":"11987208380","pt":1724934224201,"mc":[{"id":"1.232283863","rc":[{"batb":[[0,1.05,200],[1,1.04,251.05],[2,1.03,533.33]],"ltp":5.1,"tv":8.0,"id":61044843}]}]}
{"op":"mcm","clk":"11987208723","pt":1724934228162,"mc":[{"id":"1.232283863","rc":[{"batb":[[0,1.06,5],[1,1.05,200],[2,1.04,251.05]],"ltp":5.1,"tv":8.0,"id":61044843}]}]}
{"op":"mcm","clk":"11987209013","pt":1724934231609,"mc":[{"id":"1.232283863","rc":[{"batb":[[0,1.05,200],[1,1.04,251.05],[2,1.03,533.33]],"ltp":5.1,"tv":8.0,"id":61044843}]}]}
{"op":"mcm","clk":"11987209378","pt":1724934235577,"mc":[{"id":"1.232283863","rc":[{"batb":[[0,1.06,5],[1,1.05,200],[2,1.04,251.05]],"ltp":5.1,"tv":8.0,"id":61044843}]}]}
{"op":"mcm","clk":"11987209671","pt":1724934238975,"mc":[{"id":"1.232283863","rc":[{"batb":[[0,1.05,200],[1,1.04,251.05],[2,1.03,533.33]],"ltp":5.1,"tv":8.0,"id":61044843}]}]}
{"op":"mcm","clk":"11987209908","pt":1724934241917,"mc":[{"id":"1.232283863","rc":[{"batb":[[0,1.06,5],[1,1.05,200],[2,1.04,251.05]],"ltp":5.1,"tv":8.0,"id":61044843}]}]}
{"op":"mcm","clk":"11987210224","pt":1724934245284,"mc":[{"id":"1.232283863","rc":[{"batb":[[0,1.05,200],[1,1.04,251.05],[2,1.03,533.33]],"ltp":5.1,"tv":8.0,"id":61044843}]}]}
{"op":"mcm","clk":"11987210756","pt":1724934252399,"mc":[{"id":"1.232283863","rc":[{"batb":[[0,1.06,5],[1,1.05,200],[2,1.04,251.05]],"ltp":5.1,"tv":8.0,"id":61044843}]}]}
{"op":"mcm","clk":"11987211032","pt":1724934255810,"mc":[{"id":"1.232283863","rc":[{"batb":[[0,1.05,200],[1,1.04,251.05],[2,1.03,533.33]],"ltp":5.1,"tv":8.0,"id":61044843}]}]}
{"op":"mcm","clk":"11987211609","pt":1724934262841,"mc":[{"id":"1.232283863","rc":[{"batb":[[0,1.06,5],[1,1.05,200],[2,1.04,251.05]],"ltp":5.1,"tv":8.0,"id":61044843}]}]}
{"op":"mcm","clk":"11987211882","pt":1724934266240,"mc":[{"id":"1.232283863","rc":[{"batb":[[0,1.05,200],[1,1.04,251.05],[2,1.03,533.33]],"ltp":5.1,"tv":8.0,"id":61044843}]}]}
{"op":"mcm","clk":"11987212605","pt":1724934274932,"mc":[{"id":"1.232283863","rc":[{"batb":[[0,1.06,5],[1,1.05,200],[2,1.04,251.05]],"ltp":5.1,"tv":8.0,"id":61044843}]}]}
{"op":"mcm","clk":"11987212917","pt":1724934278347,"mc":[{"id":"1.232283863","rc":[{"batb":[[0,1.05,200],[1,1.04,251.05],[2,1.03,533.33]],"ltp":5.1,"tv":8.0,"id":61044843}]}]}
{"op":"mcm","clk":"11987213399","pt":1724934283732,"mc":[{"id":"1.232283863","rc":[{"batb":[[0,1.06,5],[1,1.05,200],[2,1.04,251.05]],"ltp":5.1,"tv":8.0,"id":61044843}]}]}
{"op":"mcm","clk":"11987213684","pt":1724934287028,"mc":[{"id":"1.232283863","rc":[{"batb":[[0,1.05,200],[1,1.04,251.05],[2,1.03,533.33]],"ltp":5.1,"tv":8.0,"id":61044843}]}]}
{"op":"mcm","clk":"11987214073","pt":1724934291670,"mc":[{"id":"1.232283863","rc":[{"batb":[[0,1.06,5],[1,1.05,200],[2,1.04,251.05]],"ltp":5.1,"tv":8.0,"id":61044843}]}]}
{"op":"mcm","clk":"11987214337","pt":1724934295037,"mc":[{"id":"1.232283863","rc":[{"batb":[[0,1.05,200],[1,1.04,251.05],[2,1.03,533.33]],"ltp":5.1,"tv":8.0,"id":61044843}]}]}
{"op":"mcm","clk":"11987214573","pt":1724934298344,"mc":[{"id":"1.232283863","rc":[{"batb":[[0,1.06,5],[1,1.05,200],[2,1.04,251.05]],"ltp":5.1,"tv":8.0,"id":61044843}]}]}
{"op":"mcm","clk":"11987214881","pt":1724934301984,"mc":[{"id":"1.232283863","rc":[{"batb":[[0,1.05,200],[1,1.04,251.05],[2,1.03,533.33]],"ltp":5.1,"tv":8.0,"id":61044843}]}]}
{"op":"mcm","clk":"11987215094","pt":1724934304469,"mc":[{"id":"1.232283863","rc":[{"batb":[[0,1.06,5],[1,1.05,200],[2,1.04,251.05]],"ltp":5.1,"tv":8.0,"id":61044843}]}]}
{"op":"mcm","clk":"11987215397","pt":1724934307877,"mc":[{"id":"1.232283863","rc":[{"batb":[[0,1.05,200],[1,1.04,251.05],[2,1.03,533.33]],"ltp":5.1,"tv":8.0,"id":61044843}]}]}
{"op":"mcm","clk":"11987216618","pt":1724934321492,"mc":[{"id":"1.232283863","rc":[{"batb":[[0,1.06,5],[1,1.05,200],[2,1.04,251.05]],"ltp":5.1,"tv":8.0,"id":61044843}]}]}
{"op":"mcm","clk":"11987216872","pt":1724934324995,"mc":[{"id":"1.232283863","rc":[{"batb":[[0,1.05,200],[1,1.04,251.05],[2,1.03,533.33]],"ltp":5.1,"tv":8.0,"id":61044843}]}]}
{"op":"mcm","clk":"11987218054","pt":1724934339510,"mc":[{"id":"1.232283863","rc":[{"batb":[[0,1.06,5],[1,1.05,200],[2,1.04,251.05]],"ltp":5.1,"tv":8.0,"id":61044843}]}]}
{"op":"mcm","clk":"11987218351","pt":1724934342925,"mc":[{"id":"1.232283863","rc":[{"batb":[[0,1.05,200],[1,1.04,251.05],[2,1.03,533.33]],"ltp":5.1,"tv":8.0,"id":61044843}]}]}
{"op":"mcm","clk":"11987219032","pt":1724934351508,"mc":[{"id":"1.232283863","rc":[{"batb":[[0,1.06,5],[1,1.05,200],[2,1.04,251.05]],"ltp":5.1,"tv":8.0,"id":61044843}]}]}
{"op":"mcm","clk":"11987219320","pt":1724934354916,"mc":[{"id":"1.232283863","rc":[{"batb":[[0,1.05,200],[1,1.04,251.05],[2,1.03,533.33]],"ltp":5.1,"tv":8.0,"id":61044843}]}]}
{"op":"mcm","clk":"11987219980","pt":1724934363227,"mc":[{"id":"1.232283863","rc":[{"batb":[[0,1.06,5],[1,1.05,200],[2,1.04,251.05]],"ltp":5.1,"tv":8.0,"id":61044843}]}]}
{"op":"mcm","clk":"11987220280","pt":1724934366644,"mc":[{"id":"1.232283863","rc":[{"batb":[[0,1.05,200],[1,1.04,251.05],[2,1.03,533.33]],"ltp":5.1,"tv":8.0,"id":61044843}]}]}
{"op":"mcm","clk":"11987220530","pt":1724934369339,"mc":[{"id":"1.232283863","rc":[{"batb":[[0,1.06,5],[1,1.05,200],[2,1.04,251.05]],"ltp":5.1,"tv":8.0,"id":61044843}]}]}
{"op":"mcm","clk":"11987220877","pt":1724934372845,"mc":[{"id":"1.232283863","rc":[{"batb":[[0,1.05,200],[1,1.04,251.05],[2,1.03,533.33]],"ltp":5.1,"tv":8.0,"id":61044843}]}]}
{"op":"mcm","clk":"11987221112","pt":1724934375326,"mc":[{"id":"1.232283863","rc":[{"batb":[[0,1.06,5],[1,1.05,200],[2,1.04,251.05]],"ltp":5.1,"tv":8.0,"id":61044843}]}]}
{"op":"mcm","clk":"11987221411","pt":1724934378783,"mc":[{"id":"1.232283863","rc":[{"batb":[[0,1.05,200],[1,1.04,251.05],[2,1.03,533.33]],"ltp":5.1,"tv":8.0,"id":61044843}]}]}
{"op":"mcm","clk":"11987222802","pt":1724934395858,"mc":[{"id":"1.232283863","rc":[{"batb":[[0,1.06,5],[1,1.05,200],[2,1.04,251.05]],"ltp":5.1,"tv":8.0,"id":61044843}]}]}
{"op":"mcm","clk":"11987223122","pt":1724934399365,"mc":[{"id":"1.232283863","rc":[{"batb":[[0,1.05,200],[1,1.04,251.05],[2,1.03,533.33]],"ltp":5.1,"tv":8.0,"id":61044843}]}]}
{"op":"mcm","clk":"11987223799","pt":1724934409081,"mc":[{"id":"1.232283863","rc":[{"batb":[[0,1.06,5],[1,1.05,200],[2,1.04,251.05]],"ltp":5.1,"tv":8.0,"id":61044843}]}]}
{"op":"mcm","clk":"11987224032","pt":1724934412729,"mc":[{"id":"1.232283863","rc":[{"batb":[[0,1.05,200],[1,1.04,251.05],[2,1.03,533.33]],"ltp":5.1,"tv":8.0,"id":61044843}]}]}
{"op":"mcm","clk":"11987224450","pt":1724934419237,"mc":[{"id":"1.232283863","rc":[{"batb":[[0,1.06,5],[1,1.05,200],[2,1.04,251.05]],"ltp":5.1,"tv":8.0,"id":61044843}]}]}
{"op":"mcm","clk":"11987224687","pt":1724934422642,"mc":[{"id":"1.232283863","rc":[{"batb":[[0,1.05,200],[1,1.04,251.05],[2,1.03,533.33]],"ltp":5.1,"tv":8.0,"id":61044843}]}]}
{"op":"mcm","clk":"11987225318","pt":1724934430164,"mc":[{"id":"1.232283863","rc":[{"batb":[[0,1.06,5],[1,1.05,200],[2,1.04,251.05]],"ltp":5.1,"tv":8.0,"id":61044843}]}]}
{"op":"mcm","clk":"11987225574","pt":1724934433391,"mc":[{"id":"1.232283863","rc":[{"batb":[[0,1.05,200],[1,1.04,251.05],[2,1.03,533.33]],"ltp":5.1,"tv":8.0,"id":61044843}]}]}
{"op":"mcm","clk":"11987225971","pt":1724934438801,"mc":[{"id":"1.232283863","rc":[{"batb":[[0,1.06,5],[1,1.05,200],[2,1.04,251.05]],"ltp":5.1,"tv":8.0,"id":61044843}]}]}
{"op":"mcm","clk":"11987226236","pt":1724934442092,"mc":[{"id":"1.232283863","rc":[{"batb":[[0,1.05,200],[1,1.04,251.05],[2,1.03,533.33]],"ltp":5.1,"tv":8.0,"id":61044843}]}]}
{"op":"mcm","clk":"11987226765","pt":1724934449395,"mc":[{"id":"1.232283863","rc":[{"batb":[[0,1.06,5],[1,1.05,200],[2,1.04,251.05]],"ltp":5.1,"tv":8.0,"id":61044843}]}]}
{"op":"mcm","clk":"11987227063","pt":1724934452797,"mc":[{"id":"1.232283863","rc":[{"batb":[[0,1.05,200],[1,1.04,251.05],[2,1.03,533.33]],"ltp":5.1,"tv":8.0,"id":61044843}]}]}
{"op":"mcm","clk":"11987227505","pt":1724934458729,"mc":[{"id":"1.232283863","rc":[{"batb":[[0,1.06,5],[1,1.05,200],[2,1.04,251.05]],"ltp":5.1,"tv":8.0,"id":61044843}]}]}
{"op":"mcm","clk":"11987227766","pt":1724934462015,"mc":[{"id":"1.232283863","rc":[{"batb":[[0,1.05,200],[1,1.04,251.05],[2,1.03,533.33]],"ltp":5.1,"tv":8.0,"id":61044843}]}]}
{"op":"mcm","clk":"11987228167","pt":1724934467416,"mc":[{"id":"1.232283863","rc":[{"batb":[[0,1.06,5],[1,1.05,200],[2,1.04,251.05]],"ltp":5.1,"tv":8.0,"id":61044843}]}]}
{"op":"mcm","clk":"11987228516","pt":1724934470924,"mc":[{"id":"1.232283863","rc":[{"batb":[[0,1.05,200],[1,1.04,251.05],[2,1.03,533.33]],"ltp":5.1,"tv":8.0,"id":61044843}]}]}
{"op":"mcm","clk":"11987228860","pt":1724934475918,"mc":[{"id":"1.232283863","rc":[{"batb":[[0,1.06,5],[1,1.05,200],[2,1.04,251.05]],"ltp":5.1,"tv":8.0,"id":61044843}]}]}
{"op":"mcm","clk":"11987229179","pt":1724934479430,"mc":[{"id":"1.232283863","rc":[{"batb":[[0,1.05,200],[1,1.04,251.05],[2,1.03,533.33]],"ltp":5.1,"tv":8.0,"id":61044843}]}]}
{"op":"mcm","clk":"11987230204","pt":1724934491138,"mc":[{"id":"1.232283863","rc":[{"batb":[[0,1.06,5],[1,1.05,200],[2,1.04,251.05]],"ltp":5.1,"tv":8.0,"id":61044843}]}]}
{"op":"mcm","clk":"11987230539","pt":1724934494540,"mc":[{"id":"1.232283863","rc":[{"batb":[[0,1.05,200],[1,1.04,251.05],[2,1.03,533.33]],"ltp":5.1,"tv":8.0,"id":61044843}]}]}
{"op":"mcm","clk":"11987232503","pt":1724934517072,"mc":[{"id":"1.232283863","rc":[{"batb":[[0,1.06,5],[1,1.05,200],[2,1.04,251.05]],"ltp":5.1,"tv":8.0,"id":61044843}]}]}
{"op":"mcm","clk":"11987232813","pt":1724934520276,"mc":[{"id":"1.232283863","rc":[{"batb":[[0,1.05,200],[1,1.04,251.05],[2,1.03,533.33]],"ltp":5.1,"tv":8.0,"id":61044843}]}]}
{"op":"mcm","clk":"11987233339","pt":1724934526773,"mc":[{"id":"1.232283863","rc":[{"batb":[[0,1.06,5],[1,1.05,200],[2,1.04,251.05]],"ltp":5.1,"tv":8.0,"id":61044843}]}]}
{"op":"mcm","clk":"11987233587","pt":1724934530074,"mc":[{"id":"1.232283863","rc":[{"batb":[[0,1.05,200],[1,1.04,251.05],[2,1.03,533.33]],"ltp":5.1,"tv":8.0,"id":61044843}]}]}
{"op":"mcm","clk":"11987233816","pt":1724934533067,"mc":[{"id":"1.232283863","rc":[{"batb":[[0,1.06,5],[1,1.05,200],[2,1.04,251.05]],"ltp":5.1,"tv":8.0,"id":61044843}]}]}
{"op":"mcm","clk":"11987234109","pt":1724934536575,"mc":[{"id":"1.232283863","rc":[{"batb":[[0,1.05,200],[1,1.04,251.05],[2,1.03,533.33]],"ltp":5.1,"tv":8.0,"id":61044843}]}]}
{"op":"mcm","clk":"11987234956","pt":1724934546173,"mc":[{"id":"1.232283863","rc":[{"batb":[[0,1.06,5],[1,1.05,200],[2,1.04,251.05]],"ltp":5.1,"tv":8.0,"id":61044843}]}]}
{"op":"mcm","clk":"11987235299","pt":1724934549791,"mc":[{"id":"1.232283863","rc":[{"batb":[[0,1.05,200],[1,1.04,251.05],[2,1.03,533.33]],"ltp":5.1,"tv":8.0,"id":61044843}]}]}
{"op":"mcm","clk":"11987236178","pt":1724934560796,"mc":[{"id":"1.232283863","rc":[{"batb":[[0,1.06,5],[1,1.05,200],[2,1.04,251.05]],"ltp":5.1,"tv":8.0,"id":61044843}]}]}
{"op":"mcm","clk":"11987236442","pt":1724934564121,"mc":[{"id":"1.232283863","rc":[{"batb":[[0,1.05,200],[1,1.04,251.05],[2,1.03,533.33]],"ltp":5.1,"tv":8.0,"id":61044843}]}]}
{"op":"mcm","clk":"11987236725","pt":1724934567616,"mc":[{"id":"1.232283863","rc":[{"batb":[[0,1.06,5],[1,1.05,200],[2,1.04,251.05]],"ltp":5.1,"tv":8.0,"id":61044843}]}]}
{"op":"mcm","clk":"11987236983","pt":1724934571315,"mc":[{"id":"1.232283863","rc":[{"batb":[[0,1.05,200],[1,1.04,251.05],[2,1.03,533.33]],"ltp":5.1,"tv":8.0,"id":61044843}]}]}
{"op":"mcm","clk":"11987237769","pt":1724934579394,"mc":[{"id":"1.232283863","rc":[{"batb":[[0,1.06,5],[1,1.05,200],[2,1.04,251.05]],"ltp":5.1,"tv":8.0,"id":61044843}]}]}
{"op":"mcm","clk":"11987238067","pt":1724934582931,"mc":[{"id":"1.232283863","rc":[{"batb":[[0,1.05,200],[1,1.04,251.05],[2,1.03,533.33]],"ltp":5.1,"tv":8.0,"id":61044843}]}]}
{"op":"mcm","clk":"11987238298","pt":1724934585504,"mc":[{"id":"1.232283863","rc":[{"batb":[[0,1.06,5],[1,1.05,200],[2,1.04,251.05]],"ltp":5.1,"tv":8.0,"id":61044843}]}]}
{"op":"mcm","clk":"11987238565","pt":1724934589004,"mc":[{"id":"1.232283863","rc":[{"batb":[[0,1.05,200],[1,1.04,251.05],[2,1.03,533.33]],"ltp":5.1,"tv":8.0,"id":61044843}]}]}
{"op":"mcm","clk":"11987238885","pt":1724934593123,"mc":[{"id":"1.232283863","rc":[{"batb":[[0,1.06,5],[1,1.05,200],[2,1.04,251.05]],"ltp":5.1,"tv":8.0,"id":61044843}]}]}
{"op":"mcm","clk":"11987239129","pt":1724934596515,"mc":[{"id":"1.232283863","rc":[{"batb":[[0,1.05,200],[1,1.04,251.05],[2,1.03,533.33]],"ltp":5.1,"tv":8.0,"id":61044843}]}]}
{"op":"mcm","clk":"11987239315","pt":1724934598949,"mc":[{"id":"1.232283863","rc":[{"batb":[[0,1.06,5],[1,1.05,200],[2,1.04,251.05]],"ltp":5.1,"tv":8.0,"id":61044843}]}]}
{"op":"mcm","clk":"11987239566","pt":1724934602114,"mc":[{"id":"1.232283863","rc":[{"batb":[[0,1.05,200],[1,1.04,251.05],[2,1.03,533.33]],"ltp":5.1,"tv":8.0,"id":61044843}]}]}
{"op":"mcm","clk":"11987239823","pt":1724934604842,"mc":[{"id":"1.232283863","rc":[{"batb":[[0,1.06,5],[1,1.05,200],[2,1.04,251.05]],"ltp":5.1,"tv":8.0,"id":61044843}]}]}
{"op":"mcm","clk":"11987240152","pt":1724934608347,"mc":[{"id":"1.232283863","rc":[{"batb":[[0,1.05,200],[1,1.04,251.05],[2,1.03,533.33]],"ltp":5.1,"tv":8.0,"id":61044843}]}]}
{"op":"mcm","clk":"11987240458","pt":1724934611848,"mc":[{"id":"1.232283863","rc":[{"batb":[[0,1.06,5],[1,1.05,200],[2,1.04,251.05]],"ltp":5.1,"tv":8.0,"id":61044843}]}]}
{"op":"mcm","clk":"11987240785","pt":1724934615147,"mc":[{"id":"1.232283863","rc":[{"batb":[[0,1.05,200],[1,1.04,251.05],[2,1.03,533.33]],"ltp":5.1,"tv":8.0,"id":61044843}]}]}
{"op":"mcm","clk":"11987241028","pt":1724934618037,"mc":[{"id":"1.232283863","rc":[{"batb":[[0,1.06,5],[1,1.05,200],[2,1.04,251.05]],"ltp":5.1,"tv":8.0,"id":61044843}]}]}
{"op":"mcm","clk":"11987241344","pt":1724934621652,"mc":[{"id":"1.232283863","rc":[{"batb":[[0,1.05,200],[1,1.04,251.05],[2,1.03,533.33]],"ltp":5.1,"tv":8.0,"id":61044843}]}]}
{"op":"mcm","clk":"11987241586","pt":1724934624237,"mc":[{"id":"1.232283863","rc":[{"batb":[[0,1.06,5],[1,1.05,200],[2,1.04,251.05]],"ltp":5.1,"tv":8.0,"id":61044843}]}]}
{"op":"mcm","clk":"11987241866","pt":1724934627473,"mc":[{"id":"1.232283863","rc":[{"batb":[[0,1.05,200],[1,1.04,251.05],[2,1.03,533.33]],"ltp":5.1,"tv":8.0,"id":61044843}]}]}
{"op":"mcm","clk":"11987242878","pt":1724934638563,"mc":[{"id":"1.232283863","rc":[{"batb":[[0,1.06,5],[1,1.05,200],[2,1.04,251.05]],"ltp":5.1,"tv":8.0,"id":61044843}]}]}
{"op":"mcm","clk":"11987243205","pt":1724934642066,"mc":[{"id":"1.232283863","rc":[{"batb":[[0,1.05,200],[1,1.04,251.05],[2,1.03,533.33]],"ltp":5.1,"tv":8.0,"id":61044843}]}]}
{"op":"mcm","clk":"11987243502","pt":1724934645684,"mc":[{"id":"1.232283863","rc":[{"batb":[[0,1.06,5],[1,1.05,200],[2,1.04,251.05]],"ltp":5.1,"tv":8.0,"id":61044843}]}]}
{"op":"mcm","clk":"11987243815","pt":1724934648897,"mc":[{"id":"1.232283863","rc":[{"batb":[[0,1.05,200],[1,1.04,251.05],[2,1.03,533.33]],"ltp":5.1,"tv":8.0,"id":61044843}]}]}
{"op":"mcm","clk":"11987244321","pt":1724934654289,"mc":[{"id":"1.232283863","rc":[{"batb":[[0,1.06,5],[1,1.05,200],[2,1.04,251.05]],"ltp":5.1,"tv":8.0,"id":61044843}]}]}
{"op":"mcm","clk":"11987244626","pt":1724934657486,"mc":[{"id":"1.232283863","rc":[{"batb":[[0,1.05,200],[1,1.04,251.05],[2,1.03,533.33]],"ltp":5.1,"tv":8.0,"id":61044843}]}]}
{"op":"mcm","clk":"11987245106","pt":1724934663067,"mc":[{"id":"1.232283863","rc":[{"batb":[[0,1.06,5],[1,1.05,200],[2,1.04,251.05]],"ltp":5.1,"tv":8.0,"id":61044843}]}]}
{"op":"mcm","clk":"11987245403","pt":1724934666568,"mc":[{"id":"1.232283863","rc":[{"batb":[[0,1.05,200],[1,1.04,251.05],[2,1.03,533.33]],"ltp":5.1,"tv":8.0,"id":61044843}]}]}
{"op":"mcm","clk":"11987245652","pt":1724934669620,"mc":[{"id":"1.232283863","rc":[{"batb":[[0,1.06,5],[1,1.05,200],[2,1.04,251.05]],"ltp":5.1,"tv":8.0,"id":61044843}]}]}
{"op":"mcm","clk":"11987245954","pt":1724934673079,"mc":[{"id":"1.232283863","rc":[{"batb":[[0,1.05,200],[1,1.04,251.05],[2,1.03,533.33]],"ltp":5.1,"tv":8.0,"id":61044843}]}]}
{"op":"mcm","clk":"11987246235","pt":1724934676795,"mc":[{"id":"1.232283863","rc":[{"batb":[[0,1.06,5],[1,1.05,200],[2,1.04,251.05]],"ltp":5.1,"tv":8.0,"id":61044843}]}]}
{"op":"mcm","clk":"11987246534","pt":1724934680103,"mc":[{"id":"1.232283863","rc":[{"batb":[[0,1.05,200],[1,1.04,251.05],[2,1.03,533.33]],"ltp":5.1,"tv":8.0,"id":61044843}]}]}
{"op":"mcm","clk":"11987246977","pt":1724934685385,"mc":[{"id":"1.232283863","rc":[{"batb":[[0,1.06,5],[1,1.05,200],[2,1.04,251.05]],"ltp":5.1,"tv":8.0,"id":61044843}]}]}
{"op":"mcm","clk":"11987247238","pt":1724934688729,"mc":[{"id":"1.232283863","rc":[{"batb":[[0,1.05,200],[1,1.04,251.05],[2,1.03,533.33]],"ltp":5.1,"tv":8.0,"id":61044843}]}]}
{"op":"mcm","clk":"11987247460","pt":1724934691210,"mc":[{"id":"1.232283863","rc":[{"batb":[[0,1.06,5],[1,1.05,200],[2,1.04,251.05]],"ltp":5.1,"tv":8.0,"id":61044843}]}]}
{"op":"mcm","clk":"11987247773","pt":1724934694406,"mc":[{"id":"1.232283863","rc":[{"batb":[[0,1.05,200],[1,1.04,251.05],[2,1.03,533.33]],"ltp":5.1,"tv":8.0,"id":61044843}]}]}
{"op":"mcm","clk":"11987247992","pt":1724934696937,"mc":[{"id":"1.232283863","rc":[{"batb":[[0,1.06,5],[1,1.05,200],[2,1.04,251.05]],"ltp":5.1,"tv":8.0,"id":61044843}]}]}
{"op":"mcm","clk":"11987248316","pt":1724934700444,"mc":[{"id":"1.232283863","rc":[{"batb":[[0,1.05,200],[1,1.04,251.05],[2,1.03,533.33]],"ltp":5.1,"tv":8.0,"id":61044843}]}]}
{"op":"mcm","clk":"11987248737","pt":1724934704426,"mc":[{"id":"1.232283863","rc":[{"batb":[[0,1.06,5],[1,1.05,200],[2,1.04,251.05]],"ltp":5.1,"tv":8.0,"id":61044843}]}]}
{"op":"mcm","clk":"11987249034","pt":1724934707987,"mc":[{"id":"1.232283863","rc":[{"batb":[[0,1.05,200],[1,1.04,251.05],[2,1.03,533.33]],"ltp":5.1,"tv":8.0,"id":61044843}]}]}
{"op":"mcm","clk":"11987249265","pt":1724934710318,"mc":[{"id":"1.232283863","rc":[{"batb":[[0,1.06,5],[1,1.05,200],[2,1.04,251.05]],"ltp":5.1,"tv":8.0,"id":61044843}]}]}
{"op":"mcm","clk":"11987249539","pt":1724934713760,"mc":[{"id":"1.232283863","rc":[{"batb":[[0,1.05,200],[1,1.04,251.05],[2,1.03,533.33]],"ltp":5.1,"tv":8.0,"id":61044843}]}]}
{"op":"mcm","clk":"11987249785","pt":1724934716952,"mc":[{"id":"1.232283863","rc":[{"batb":[[0,1.06,5],[1,1.05,200],[2,1.04,251.05]],"ltp":5.1,"tv":8.0,"id":61044843}]}]}
{"op":"mcm","clk":"11987250033","pt":1724934720248,"mc":[{"id":"1.232283863","rc":[{"batb":[[0,1.05,200],[1,1.04,251.05],[2,1.03,533.33]],"ltp":5.1,"tv":8.0,"id":61044843}]}]}
{"op":"mcm","clk":"11987250457","pt":1724934724857,"mc":[{"id":"1.232283863","rc":[{"batb":[[0,1.06,5],[1,1.05,200],[2,1.04,251.05]],"ltp":5.1,"tv":8.0,"id":61044843}]}]}
{"op":"mcm","clk":"11987250720","pt":1724934728162,"mc":[{"id":"1.232283863","rc":[{"batb":[[0,1.05,200],[1,1.04,251.05],[2,1.03,533.33]],"ltp":5.1,"tv":8.0,"id":61044843}]}]}
{"op":"mcm","clk":"11987250997","pt":1724934731570,"mc":[{"id":"1.232283863","rc":[{"batb":[[0,1.06,5],[1,1.05,200],[2,1.04,251.05]],"ltp":5.1,"tv":8.0,"id":61044843}]}]}
{"op":"mcm","clk":"11987251235","pt":1724934734756,"mc":[{"id":"1.232283863","rc":[{"batb":[[0,1.05,200],[1,1.04,251.05],[2,1.03,533.33]],"ltp":5.1,"tv":8.0,"id":61044843}]}]}
{"op":"mcm","clk":"11987251725","pt":1724934739867,"mc":[{"id":"1.232283863","rc":[{"batb":[[0,1.06,5],[1,1.05,200],[2,1.04,251.05]],"ltp":5.1,"tv":8.0,"id":61044843}]}]}
{"op":"mcm","clk":"11987251996","pt":1724934743159,"mc":[{"id":"1.232283863","rc":[{"batb":[[0,1.05,200],[1,1.04,251.05],[2,1.03,533.33]],"ltp":5.1,"tv":8.0,"id":61044843}]}]}
{"op":"mcm","clk":"11987252668","pt":1724934751171,"mc":[{"id":"1.232283863","rc":[{"batb":[[0,1.06,5],[1,1.05,200],[2,1.04,251.05]],"ltp":5.1,"tv":8.0,"id":61044843}]}]}
{"op":"mcm","clk":"11987252929","pt":1724934754479,"mc":[{"id":"1.232283863","rc":[{"batb":[[0,1.05,200],[1,1.04,251.05],[2,1.03,533.33]],"ltp":5.1,"tv":8.0,"id":61044843}]}]}
{"op":"mcm","clk":"11987253162","pt":1724934757209,"mc":[{"id":"1.232283863","rc":[{"batb":[[0,1.06,5],[1,1.05,200],[2,1.04,251.05]],"ltp":5.1,"tv":8.0,"id":61044843}]}]}
{"op":"mcm","clk":"11987253463","pt":1724934760469,"mc":[{"id":"1.232283863","rc":[{"batb":[[0,1.05,200],[1,1.04,251.05],[2,1.03,533.33]],"ltp":5.1,"tv":8.0,"id":61044843}]}]}
{"op":"mcm","clk":"11987253672","pt":1724934763313,"mc":[{"id":"1.232283863","rc":[{"batb":[[0,1.06,5],[1,1.05,200],[2,1.04,251.05]],"ltp":5.1,"tv":8.0,"id":61044843}]}]}
{"op":"mcm","clk":"11987253928","pt":1724934766878,"mc":[{"id":"1.232283863","rc":[{"batb":[[0,1.05,200],[1,1.04,251.05],[2,1.03,533.33]],"ltp":5.1,"tv":8.0,"id":61044843}]}]}
{"op":"mcm","clk":"11987254122","pt":1724934769300,"mc":[{"id":"1.232283863","rc":[{"batb":[[0,1.06,5],[1,1.05,200],[2,1.04,251.05]],"ltp":5.1,"tv":8.0,"id":61044843}]}]}
{"op":"mcm","clk":"11987254432","pt":1724934772618,"mc":[{"id":"1.232283863","rc":[{"batb":[[0,1.05,200],[1,1.04,251.05],[2,1.03,533.33]],"ltp":5.1,"tv":8.0,"id":61044843}]}]}
{"op":"mcm","clk":"11987254763","pt":1724934776505,"mc":[{"id":"1.232283863","rc":[{"batb":[[0,1.06,5],[1,1.05,200],[2,1.04,251.05]],"ltp":5.1,"tv":8.0,"id":61044843}]}]}
{"op":"mcm","clk":"11987255046","pt":1724934779716,"mc":[{"id":"1.232283863","rc":[{"batb":[[0,1.05,200],[1,1.04,251.05],[2,1.03,533.33]],"ltp":5.1,"tv":8.0,"id":61044843}]}]}
{"op":"mcm","clk":"11987255661","pt":1724934786501,"mc":[{"id":"1.232283863","rc":[{"batb":[[0,1.06,5],[1,1.05,200],[2,1.04,251.05]],"ltp":5.1,"tv":8.0,"id":61044843}]}]}
{"op":"mcm","clk":"11987255976","pt":1724934789755,"mc":[{"id":"1.232283863","rc":[{"batb":[[0,1.05,200],[1,1.04,251.05],[2,1.03,533.33]],"ltp":5.1,"tv":8.0,"id":61044843}]}]}
{"op":"mcm","clk":"11987256852","pt":1724934800754,"mc":[{"id":"1.232283863","rc":[{"batb":[[0,1.06,5],[1,1.05,200],[2,1.04,251.05]],"ltp":5.1,"tv":8.0,"id":61044843}]}]}
{"op":"mcm","clk":"11987257122","pt":1724934804050,"mc":[{"id":"1.232283863","rc":[{"batb":[[0,1.05,200],[1,1.04,251.05],[2,1.03,533.33]],"ltp":5.1,"tv":8.0,"id":61044843}]}]}
{"op":"mcm","clk":"11987257918","pt":1724934813827,"mc":[{"id":"1.232283863","rc":[{"batb":[[0,1.06,5],[1,1.05,200],[2,1.04,251.05]],"ltp":5.1,"tv":8.0,"id":61044843}]}]}
{"op":"mcm","clk":"11987258173","pt":1724934817119,"mc":[{"id":"1.232283863","rc":[{"batb":[[0,1.05,200],[1,1.04,251.05],[2,1.03,533.33]],"ltp":5.1,"tv":8.0,"id":61044843}]}]}
{"op":"mcm","clk":"11987258792","pt":1724934824234,"mc":[{"id":"1.232283863","rc":[{"batb":[[0,1.06,5],[1,1.05,200],[2,1.04,251.05]],"ltp":5.1,"tv":8.0,"id":61044843}]}]}
{"op":"mcm","clk":"11987259068","pt":1724934827433,"mc":[{"id":"1.232283863","rc":[{"batb":[[0,1.05,200],[1,1.04,251.05],[2,1.03,533.33]],"ltp":5.1,"tv":8.0,"id":61044843}]}]}
{"op":"mcm","clk":"11987259511","pt":1724934832939,"mc":[{"id":"1.232283863","rc":[{"batb":[[0,1.06,5],[1,1.05,200],[2,1.04,251.05]],"ltp":5.1,"tv":8.0,"id":61044843}]}]}
{"op":"mcm","clk":"11987259800","pt":1724934836384,"mc":[{"id":"1.232283863","rc":[{"batb":[[0,1.05,200],[1,1.04,251.05],[2,1.03,533.33]],"ltp":5.1,"tv":8.0,"id":61044843}]}]}
{"op":"mcm","clk":"11987259963","pt":1724934838654,"mc":[{"id":"1.232283863","rc":[{"batb":[[0,1.06,5],[1,1.05,200],[2,1.04,251.05]],"ltp":5.1,"tv":8.0,"id":61044843}]}]}
{"op":"mcm","clk":"11987260236","pt":1724934841866,"mc":[{"id":"1.232283863","rc":[{"batb":[[0,1.05,200],[1,1.04,251.05],[2,1.03,533.33]],"ltp":5.1,"tv":8.0,"id":61044843}]}]}
{"op":"mcm","clk":"11987260504","pt":1724934844759,"mc":[{"id":"1.232283863","rc":[{"batb":[[0,1.06,5],[1,1.05,200],[2,1.04,251.05]],"ltp":5.1,"tv":8.0,"id":61044843}]}]}
{"op":"mcm","clk":"11987260812","pt":1724934848165,"mc":[{"id":"1.232283863","rc":[{"batb":[[0,1.05,200],[1,1.04,251.05],[2,1.03,533.33]],"ltp":5.1,"tv":8.0,"id":61044843}]}]}
{"op":"mcm","clk":"11987261232","pt":1724934853469,"mc":[{"id":"1.232283863","rc":[{"batb":[[0,1.06,5],[1,1.05,200],[2,1.04,251.05]],"ltp":5.1,"tv":8.0,"id":61044843}]}]}
{"op":"mcm","clk":"11987261561","pt":1724934857289,"mc":[{"id":"1.232283863","rc":[{"batb":[[0,1.05,200],[1,1.04,251.05],[2,1.03,533.33]],"ltp":5.1,"tv":8.0,"id":61044843}]}]}
{"op":"mcm","clk":"11987262166","pt":1724934865069,"mc":[{"id":"1.232283863","rc":[{"batb":[[0,1.06,5],[1,1.05,200],[2,1.04,251.05]],"ltp":5.1,"tv":8.0,"id":61044843}]}]}
{"op":"mcm","clk":"11987262440","pt":1724934868272,"mc":[{"id":"1.232283863","rc":[{"batb":[[0,1.05,200],[1,1.04,251.05],[2,1.03,533.33]],"ltp":5.1,"tv":8.0,"id":61044843}]}]}
{"op":"mcm","clk":"11987262792","pt":1724934872704,"mc":[{"id":"1.232283863","rc":[{"batb":[[0,1.06,5],[1,1.05,200],[2,1.04,251.05]],"ltp":5.1,"tv":8.0,"id":61044843}]}]}
{"op":"mcm","clk":"11987263062","pt":1724934875905,"mc":[{"id":"1.232283863","rc":[{"batb":[[0,1.05,200],[1,1.04,251.05],[2,1.03,533.33]],"ltp":5.1,"tv":8.0,"id":61044843}]}]}
{"op":"mcm","clk":"11987263278","pt":1724934878396,"mc":[{"id":"1.232283863","rc":[{"batb":[[0,1.06,5],[1,1.05,200],[2,1.04,251.05]],"ltp":5.1,"tv":8.0,"id":61044843}]}]}
{"op":"mcm","clk":"11987263521","pt":1724934881591,"mc":[{"id":"1.232283863","rc":[{"batb":[[0,1.05,200],[1,1.04,251.05],[2,1.03,533.33]],"ltp":5.1,"tv":8.0,"id":61044843}]}]}
{"op":"mcm","clk":"11987263794","pt":1724934885302,"mc":[{"id":"1.232283863","rc":[{"batb":[[0,1.06,5],[1,1.05,200],[2,1.04,251.05]],"ltp":5.1,"tv":8.0,"id":61044843}]}]}
{"op":"mcm","clk":"11987264061","pt":1724934888714,"mc":[{"id":"1.232283863","rc":[{"batb":[[0,1.05,200],[1,1.04,251.05],[2,1.03,533.33]],"ltp":5.1,"tv":8.0,"id":61044843}]}]}
{"op":"mcm","clk":"11987264268","pt":1724934891296,"mc":[{"id":"1.232283863","rc":[{"batb":[[0,1.06,5],[1,1.05,200],[2,1.04,251.05]],"ltp":5.1,"tv":8.0,"id":61044843}]}]}
{"op":"mcm","clk":"11987264553","pt":1724934894703,"mc":[{"id":"1.232283863","rc":[{"batb":[[0,1.05,200],[1,1.04,251.05],[2,1.03,533.33]],"ltp":5.1,"tv":8.0,"id":61044843}]}]}
{"op":"mcm","clk":"11987264963","pt":1724934899410,"mc":[{"id":"1.232283863","rc":[{"batb":[[0,1.06,5],[1,1.05,200],[2,1.04,251.05]],"ltp":5.1,"tv":8.0,"id":61044843}]}]}
{"op":"mcm","clk":"11987265251","pt":1724934902835,"mc":[{"id":"1.232283863","rc":[{"batb":[[0,1.05,200],[1,1.04,251.05],[2,1.03,533.33]],"ltp":5.1,"tv":8.0,"id":61044843}]}]}
{"op":"mcm","clk":"11987265491","pt":1724934905645,"mc":[{"id":"1.232283863","rc":[{"batb":[[0,1.06,5],[1,1.05,200],[2,1.04,251.05]],"ltp":5.1,"tv":8.0,"id":61044843}]}]}
{"op":"mcm","clk":"11987265788","pt":1724934908955,"mc":[{"id":"1.232283863","rc":[{"batb":[[0,1.05,200],[1,1.04,251.05],[2,1.03,533.33]],"ltp":5.1,"tv":8.0,"id":61044843}]}]}
{"op":"mcm","clk":"11987266437","pt":1724934917122,"mc":[{"id":"1.232283863","rc":[{"batb":[[0,1.06,5],[1,1.05,200],[2,1.04,251.05]],"ltp":5.1,"tv":8.0,"id":61044843}]}]}
{"op":"mcm","clk":"11987266704","pt":1724934920638,"mc":[{"id":"1.232283863","rc":[{"batb":[[0,1.05,200],[1,1.04,251.05],[2,1.03,533.33]],"ltp":5.1,"tv":8.0,"id":61044843}]}]}
{"op":"mcm","clk":"11987266919","pt":1724934923631,"mc":[{"id":"1.232283863","rc":[{"batb":[[0,1.06,5],[1,1.05,200],[2,1.04,251.05]],"ltp":5.1,"tv":8.0,"id":61044843}]}]}
{"op":"mcm","clk":"11987267169","pt":1724934926930,"mc":[{"id":"1.232283863","rc":[{"batb":[[0,1.05,200],[1,1.04,251.05],[2,1.03,533.33]],"ltp":5.1,"tv":8.0,"id":61044843}]}]}
{"op":"mcm","clk":"11987267638","pt":1724934933124,"mc":[{"id":"1.232283863","rc":[{"batb":[[0,1.06,5],[1,1.05,200],[2,1.04,251.05]],"ltp":5.1,"tv":8.0,"id":61044843}]}]}
{"op":"mcm","clk":"11987267916","pt":1724934936543,"mc":[{"id":"1.232283863","rc":[{"batb":[[0,1.05,200],[1,1.04,251.05],[2,1.03,533.33]],"ltp":5.1,"tv":8.0,"id":61044843}]}]}
{"op":"mcm","clk":"11987269027","pt":1724934950053,"mc":[{"id":"1.232283863","rc":[{"batb":[[0,1.06,5],[1,1.05,200],[2,1.04,251.05]],"ltp":5.1,"tv":8.0,"id":61044843}]}]}
{"op":"mcm","clk":"11987269306","pt":1724934953358,"mc":[{"id":"1.232283863","rc":[{"batb":[[0,1.05,200],[1,1.04,251.05],[2,1.03,533.33]],"ltp":5.1,"tv":8.0,"id":61044843}]}]}
{"op":"mcm","clk":"11987269562","pt":1724934956553,"mc":[{"id":"1.232283863","rc":[{"batb":[[0,1.06,5],[1,1.05,200],[2,1.04,251.05]],"ltp":5.1,"tv":8.0,"id":61044843}]}]}
{"op":"mcm","clk":"11987269819","pt":1724934960164,"mc":[{"id":"1.232283863","rc":[{"batb":[[0,1.05,200],[1,1.04,251.05],[2,1.03,533.33]],"ltp":5.1,"tv":8.0,"id":61044843}]}]}
{"op":"mcm","clk":"11987270467","pt":1724934967270,"mc":[{"id":"1.232283863","rc":[{"batb":[[0,1.06,5],[1,1.05,200],[2,1.04,251.05]],"ltp":5.1,"tv":8.0,"id":61044843}]}]}
{"op":"mcm","clk":"11987270742","pt":1724934970675,"mc":[{"id":"1.232283863","rc":[{"batb":[[0,1.05,200],[1,1.04,251.05],[2,1.03,533.33]],"ltp":5.1,"tv":8.0,"id":61044843}]}]}
{"op":"mcm","clk":"11987271681","pt":1724934982878,"mc":[{"id":"1.232283863","rc":[{"batb":[[0,1.06,5],[1,1.05,200],[2,1.04,251.05]],"ltp":5.1,"tv":8.0,"id":61044843}]}]}
{"op":"mcm","clk":"11987271930","pt":1724934986486,"mc":[{"id":"1.232283863","rc":[{"batb":[[0,1.05,200],[1,1.04,251.05],[2,1.03,533.33]],"ltp":5.1,"tv":8.0,"id":61044843}]}]}
{"op":"mcm","clk":"11987272125","pt":1724934989086,"mc":[{"id":"1.232283863","rc":[{"batb":[[0,1.06,5],[1,1.05,200],[2,1.04,251.05]],"ltp":5.1,"tv":8.0,"id":61044843}]}]}
{"op":"mcm","clk":"11987272395","pt":1724934992577,"mc":[{"id":"1.232283863","rc":[{"batb":[[0,1.05,200],[1,1.04,251.05],[2,1.03,533.33]],"ltp":5.1,"tv":8.0,"id":61044843}]}]}
{"op":"mcm","clk":"11987272548","pt":1724934994795,"mc":[{"id":"1.232283863","rc":[{"batb":[[0,1.06,5],[1,1.05,200],[2,1.04,251.05]],"ltp":5.1,"tv":8.0,"id":61044843}]}]}
{"op":"mcm","clk":"11987272823","pt":1724934998292,"mc":[{"id":"1.232283863","rc":[{"batb":[[0,1.05,200],[1,1.04,251.05],[2,1.03,533.33]],"ltp":5.1,"tv":8.0,"id":61044843}]}]}
{"op":"mcm","clk":"11987273059","pt":1724935000986,"mc":[{"id":"1.232283863","rc":[{"batb":[[0,1.06,5],[1,1.05,200],[2,1.04,251.05]],"ltp":5.1,"tv":8.0,"id":61044843}]}]}
{"op":"mcm","clk":"11987273343","pt":1724935004389,"mc":[{"id":"1.232283863","rc":[{"batb":[[0,1.05,200],[1,1.04,251.05],[2,1.03,533.33]],"ltp":5.1,"tv":8.0,"id":61044843}]}]}
{"op":"mcm","clk":"11987273551","pt":1724935007017,"mc":[{"id":"1.232283863","rc":[{"batb":[[0,1.06,5],[1,1.05,200],[2,1.04,251.05]],"ltp":5.1,"tv":8.0,"id":61044843}]}]}
{"op":"mcm","clk":"11987273794","pt":1724935010324,"mc":[{"id":"1.232283863","rc":[{"batb":[[0,1.05,200],[1,1.04,251.05],[2,1.03,533.33]],"ltp":5.1,"tv":8.0,"id":61044843}]}]}
{"op":"mcm","clk":"11987274033","pt":1724935013216,"mc":[{"id":"1.232283863","rc":[{"batb":[[0,1.06,5],[1,1.05,200],[2,1.04,251.05]],"ltp":5.1,"tv":8.0,"id":61044843}]}]}
{"op":"mcm","clk":"11987274312","pt":1724935016829,"mc":[{"id":"1.232283863","rc":[{"batb":[[0,1.05,200],[1,1.04,251.05],[2,1.03,533.33]],"ltp":5.1,"tv":8.0,"id":61044843}]}]}
{"op":"mcm","clk":"11987274496","pt":1724935019520,"mc":[{"id":"1.232283863","rc":[{"batb":[[0,1.06,5],[1,1.05,200],[2,1.04,251.05]],"ltp":5.1,"tv":8.0,"id":61044843}]}]}
{"op":"mcm","clk":"11987274801","pt":1724935023250,"mc":[{"id":"1.232283863","rc":[{"batb":[[0,1.05,200],[1,1.04,251.05],[2,1.03,533.33]],"ltp":5.1,"tv":8.0,"id":61044843}]}]}
{"op":"mcm","clk":"11987275011","pt":1724935025644,"mc":[{"id":"1.232283863","rc":[{"batb":[[0,1.06,5],[1,1.05,200],[2,1.04,251.05]],"ltp":5.1,"tv":8.0,"id":61044843}]}]}
{"op":"mcm","clk":"11987275294","pt":1724935029136,"mc":[{"id":"1.232283863","rc":[{"batb":[[0,1.05,200],[1,1.04,251.05],[2,1.03,533.33]],"ltp":5.1,"tv":8.0,"id":61044843}]}]}
{"op":"mcm","clk":"11987275603","pt":1724935032747,"mc":[{"id":"1.232283863","rc":[{"batb":[[0,1.06,5],[1,1.05,200],[2,1.04,251.05]],"ltp":5.1,"tv":8.0,"id":61044843}]}]}
{"op":"mcm","clk":"11987275908","pt":1724935036267,"mc":[{"id":"1.232283863","rc":[{"batb":[[0,1.05,200],[1,1.04,251.05],[2,1.03,533.33]],"ltp":5.1,"tv":8.0,"id":61044843}]}]}
{"op":"mcm","clk":"11987276177","pt":1724935039636,"mc":[{"id":"1.232283863","rc":[{"batb":[[0,1.06,5],[1,1.05,200],[2,1.04,251.05]],"ltp":5.1,"tv":8.0,"id":61044843}]}]}
{"op":"mcm","clk":"11987276432","pt":1724935042939,"mc":[{"id":"1.232283863","rc":[{"batb":[[0,1.05,200],[1,1.04,251.05],[2,1.03,533.33]],"ltp":5.1,"tv":8.0,"id":61044843}]}]}
{"op":"mcm","clk":"11987276647","pt":1724935045461,"mc":[{"id":"1.232283863","rc":[{"batb":[[0,1.06,5],[1,1.05,200],[2,1.04,251.05]],"ltp":5.1,"tv":8.0,"id":61044843}]}]}
{"op":"mcm","clk":"11987276914","pt":1724935048863,"mc":[{"id":"1.232283863","rc":[{"batb":[[0,1.05,200],[1,1.04,251.05],[2,1.03,533.33]],"ltp":5.1,"tv":8.0,"id":61044843}]}]}
{"op":"mcm","clk":"11987277636","pt":1724935057389,"mc":[{"id":"1.232283863","rc":[{"batb":[[0,1.06,5],[1,1.05,200],[2,1.04,251.05]],"ltp":5.1,"tv":8.0,"id":61044843}]}]}
{"op":"mcm","clk":"11987277933","pt":1724935060958,"mc":[{"id":"1.232283863","rc":[{"batb":[[0,1.05,200],[1,1.04,251.05],[2,1.03,533.33]],"ltp":5.1,"tv":8.0,"id":61044843}]}]}
{"op":"mcm","clk":"11987278159","pt":1724935064097,"mc":[{"id":"1.232283863","rc":[{"batb":[[0,1.06,5],[1,1.05,200],[2,1.04,251.05]],"ltp":5.1,"tv":8.0,"id":61044843}]}]}
{"op":"mcm","clk":"11987278442","pt":1724935067671,"mc":[{"id":"1.232283863","rc":[{"batb":[[0,1.05,200],[1,1.04,251.05],[2,1.03,533.33]],"ltp":5.1,"tv":8.0,"id":61044843}]}]}
{"op":"mcm","clk":"11987278771","pt":1724935071408,"mc":[{"id":"1.232283863","rc":[{"batb":[[0,1.06,5],[1,1.05,200],[2,1.04,251.05]],"ltp":5.1,"tv":8.0,"id":61044843}]}]}
{"op":"mcm","clk":"11987279065","pt":1724935074776,"mc":[{"id":"1.232283863","rc":[{"batb":[[0,1.05,200],[1,1.04,251.05],[2,1.03,533.33]],"ltp":5.1,"tv":8.0,"id":61044843}]}]}
{"op":"mcm","clk":"11987279453","pt":1724935079102,"mc":[{"id":"1.232283863","rc":[{"batb":[[0,1.06,5],[1,1.05,200],[2,1.04,251.05]],"ltp":5.1,"tv":8.0,"id":61044843}]}]}
{"op":"mcm","clk":"11987279733","pt":1724935082500,"mc":[{"id":"1.232283863","rc":[{"batb":[[0,1.05,200],[1,1.04,251.05],[2,1.03,533.33]],"ltp":5.1,"tv":8.0,"id":61044843}]}]}
{"op":"mcm","clk":"11987280456","pt":1724935090496,"mc":[{"id":"1.232283863","rc":[{"batb":[[0,1.06,5],[1,1.05,200],[2,1.04,251.05]],"ltp":5.1,"tv":8.0,"id":61044843}]}]}
{"op":"mcm","clk":"11987280781","pt":1724935094200,"mc":[{"id":"1.232283863","rc":[{"batb":[[0,1.05,200],[1,1.04,251.05],[2,1.03,533.33]],"ltp":5.1,"tv":8.0,"id":61044843}]}]}
{"op":"mcm","clk":"11987281072","pt":1724935097613,"mc":[{"id":"1.232283863","rc":[{"batb":[[0,1.06,5],[1,1.05,200],[2,1.04,251.05]],"ltp":5.1,"tv":8.0,"id":61044843}]}]}
{"op":"mcm","clk":"11987281340","pt":1724935101080,"mc":[{"id":"1.232283863","rc":[{"batb":[[0,1.05,200],[1,1.04,251.05],[2,1.03,533.33]],"ltp":5.1,"tv":8.0,"id":61044843}]}]}
{"op":"mcm","clk":"11987281659","pt":1724935105320,"mc":[{"id":"1.232283863","rc":[{"batb":[[0,1.06,5],[1,1.05,200],[2,1.04,251.05]],"ltp":5.1,"tv":8.0,"id":61044843}]}]}
{"op":"mcm","clk":"11987281920","pt":1724935108819,"mc":[{"id":"1.232283863","rc":[{"batb":[[0,1.05,200],[1,1.04,251.05],[2,1.03,533.33]],"ltp":5.1,"tv":8.0,"id":61044843}]}]}
{"op":"mcm","clk":"11987282178","pt":1724935112212,"mc":[{"id":"1.232283863","rc":[{"batb":[[0,1.06,5],[1,1.05,200],[2,1.04,251.05]],"ltp":5.1,"tv":8.0,"id":61044843}]}]}
{"op":"mcm","clk":"11987282412","pt":1724935115708,"mc":[{"id":"1.232283863","rc":[{"batb":[[0,1.05,200],[1,1.04,251.05],[2,1.03,533.33]],"ltp":5.1,"tv":8.0,"id":61044843}]}]}
{"op":"mcm","clk":"11987283051","pt":1724935123190,"mc":[{"id":"1.232283863","rc":[{"batb":[[0,1.06,5],[1,1.05,200],[2,1.04,251.05]],"ltp":5.1,"tv":8.0,"id":61044843}]}]}
{"op":"mcm","clk":"11987283288","pt":1724935126532,"mc":[{"id":"1.232283863","rc":[{"batb":[[0,1.05,200],[1,1.04,251.05],[2,1.03,533.33]],"ltp":5.1,"tv":8.0,"id":61044843}]}]}
{"op":"mcm","clk":"11987283494","pt":1724935129008,"mc":[{"id":"1.232283863","rc":[{"batb":[[0,1.06,5],[1,1.05,200],[2,1.04,251.05]],"ltp":5.1,"tv":8.0,"id":61044843}]}]}
{"op":"mcm","clk":"11987283734","pt":1724935132315,"mc":[{"id":"1.232283863","rc":[{"batb":[[0,1.05,200],[1,1.04,251.05],[2,1.03,533.33]],"ltp":5.1,"tv":8.0,"id":61044843}]}]}
{"op":"mcm","clk":"11987283935","pt":1724935135138,"mc":[{"id":"1.232283863","rc":[{"batb":[[0,1.06,5],[1,1.05,200],[2,1.04,251.05]],"ltp":5.1,"tv":8.0,"id":61044843}]}]}
{"op":"mcm","clk":"11987284160","pt":1724935138538,"mc":[{"id":"1.232283863","rc":[{"batb":[[0,1.05,200],[1,1.04,251.05],[2,1.03,533.33]],"ltp":5.1,"tv":8.0,"id":61044843}]}]}
{"op":"mcm","clk":"11987284413","pt":1724935142252,"mc":[{"id":"1.232283863","rc":[{"batb":[[0,1.06,5],[1,1.05,200],[2,1.04,251.05]],"ltp":5.1,"tv":8.0,"id":61044843}]}]}
{"op":"mcm","clk":"11987284648","pt":1724935145653,"mc":[{"id":"1.232283863","rc":[{"batb":[[0,1.05,200],[1,1.04,251.05],[2,1.03,533.33]],"ltp":5.1,"tv":8.0,"id":61044843}]}]}
{"op":"mcm","clk":"11987285994","pt":1724935164468,"mc":[{"id":"1.232283863","rc":[{"batb":[[0,1.06,5],[1,1.05,200],[2,1.04,251.05]],"ltp":5.1,"tv":8.0,"id":61044843}]}]}
{"op":"mcm","clk":"11987286246","pt":1724935167973,"mc":[{"id":"1.232283863","rc":[{"batb":[[0,1.05,200],[1,1.04,251.05],[2,1.03,533.33]],"ltp":5.1,"tv":8.0,"id":61044843}]}]}
{"op":"mcm","clk":"11987286832","pt":1724935176145,"mc":[{"id":"1.232283863","rc":[{"batb":[[0,1.06,5],[1,1.05,200],[2,1.04,251.05]],"ltp":5.1,"tv":8.0,"id":61044843}]}]}
{"op":"mcm","clk":"11987287120","pt":1724935179550,"mc":[{"id":"1.232283863","rc":[{"batb":[[0,1.05,200],[1,1.04,251.05],[2,1.03,533.33]],"ltp":5.1,"tv":8.0,"id":61044843}]}]}
{"op":"mcm","clk":"11987287538","pt":1724935186082,"mc":[{"id":"1.232283863","rc":[{"batb":[[0,1.06,5],[1,1.05,200],[2,1.04,251.05]],"ltp":5.1,"tv":8.0,"id":61044843}]}]}
{"op":"mcm","clk":"11987287805","pt":1724935189556,"mc":[{"id":"1.232283863","rc":[{"batb":[[0,1.05,200],[1,1.04,251.05],[2,1.03,533.33]],"ltp":5.1,"tv":8.0,"id":61044843}]}]}
{"op":"mcm","clk":"11987288277","pt":1724935195958,"mc":[{"id":"1.232283863","rc":[{"batb":[[0,1.06,5],[1,1.05,200],[2,1.04,251.05]],"ltp":5.1,"tv":8.0,"id":61044843}]}]}
{"op":"mcm","clk":"11987288493","pt":1724935199478,"mc":[{"id":"1.232283863","rc":[{"batb":[[0,1.05,200],[1,1.04,251.05],[2,1.03,533.33]],"ltp":5.1,"tv":8.0,"id":61044843}]}]}
{"op":"mcm","clk":"11987289202","pt":1724935208071,"mc":[{"id":"1.232283863","rc":[{"batb":[[0,1.06,5],[1,1.05,200],[2,1.04,251.05]],"ltp":5.1,"tv":8.0,"id":61044843}]}]}
{"op":"mcm","clk":"11987289455","pt":1724935211416,"mc":[{"id":"1.232283863","rc":[{"batb":[[0,1.05,200],[1,1.04,251.05],[2,1.03,533.33]],"ltp":5.1,"tv":8.0,"id":61044843}]}]}
{"op":"mcm","clk":"11987289672","pt":1724935214194,"mc":[{"id":"1.232283863","rc":[{"batb":[[0,1.06,5],[1,1.05,200],[2,1.04,251.05]],"ltp":5.1,"tv":8.0,"id":61044843}]}]}
{"op":"mcm","clk":"11987289887","pt":1724935217585,"mc":[{"id":"1.232283863","rc":[{"batb":[[0,1.05,200],[1,1.04,251.05],[2,1.03,533.33]],"ltp":5.1,"tv":8.0,"id":61044843}]}]}
{"op":"mcm","clk":"11987290423","pt":1724935225598,"mc":[{"id":"1.232283863","rc":[{"batb":[[0,1.06,5],[1,1.05,200],[2,1.04,251.05]],"ltp":5.1,"tv":8.0,"id":61044843}]}]}
{"op":"mcm","clk":"11987290645","pt":1724935229103,"mc":[{"id":"1.232283863","rc":[{"batb":[[0,1.05,200],[1,1.04,251.05],[2,1.03,533.33]],"ltp":5.1,"tv":8.0,"id":61044843}]}]}
{"op":"mcm","clk":"11987290818","pt":1724935231839,"mc":[{"id":"1.232283863","rc":[{"batb":[[0,1.06,5],[1,1.05,200],[2,1.04,251.05]],"ltp":5.1,"tv":8.0,"id":61044843}]}]}
{"op":"mcm","clk":"11987291084","pt":1724935235350,"mc":[{"id":"1.232283863","rc":[{"batb":[[0,1.05,200],[1,1.04,251.05],[2,1.03,533.33]],"ltp":5.1,"tv":8.0,"id":61044843}]}]}
{"op":"mcm","clk":"11987291250","pt":1724935237418,"mc":[{"id":"1.232283863","rc":[{"batb":[[0,1.06,5],[1,1.05,200],[2,1.04,251.05]],"ltp":5.1,"tv":8.0,"id":61044843}]}]}
{"op":"mcm","clk":"11987291534","pt":1724935240855,"mc":[{"id":"1.232283863","rc":[{"batb":[[0,1.05,200],[1,1.04,251.05],[2,1.03,533.33]],"ltp":5.1,"tv":8.0,"id":61044843}]}]}
{"op":"mcm","clk":"11987291946","pt":1724935246631,"mc":[{"id":"1.232283863","rc":[{"batb":[[0,1.06,5],[1,1.05,200],[2,1.04,251.05]],"ltp":5.1,"tv":8.0,"id":61044843}]}]}
{"op":"mcm","clk":"11987292197","pt":1724935250135,"mc":[{"id":"1.232283863","rc":[{"batb":[[0,1.05,200],[1,1.04,251.05],[2,1.03,533.33]],"ltp":5.1,"tv":8.0,"id":61044843}]}]}
{"op":"mcm","clk":"11987292384","pt":1724935253538,"mc":[{"id":"1.232283863","rc":[{"batb":[[0,1.06,5],[1,1.05,200],[2,1.04,251.05]],"ltp":5.1,"tv":8.0,"id":61044843}]}]}
{"op":"mcm","clk":"11987292599","pt":1724935257043,"mc":[{"id":"1.232283863","rc":[{"batb":[[0,1.05,200],[1,1.04,251.05],[2,1.03,533.33]],"ltp":5.1,"tv":8.0,"id":61044843}]}]}
{"op":"mcm","clk":"11987292784","pt":1724935259765,"mc":[{"id":"1.232283863","rc":[{"batb":[[0,1.06,5],[1,1.05,200],[2,1.04,251.05]],"ltp":5.1,"tv":8.0,"id":61044843}]}]}
{"op":"mcm","clk":"11987292975","pt":1724935263067,"mc":[{"id":"1.232283863","rc":[{"batb":[[0,1.05,200],[1,1.04,251.05],[2,1.03,533.33]],"ltp":5.1,"tv":8.0,"id":61044843}]}]}
{"op":"mcm","clk":"11987293412","pt":1724935269168,"mc":[{"id":"1.232283863","rc":[{"batb":[[0,1.06,5],[1,1.05,200],[2,1.04,251.05]],"ltp":5.1,"tv":8.0,"id":61044843}]}]}
{"op":"mcm","clk":"11987293691","pt":1724935272567,"mc":[{"id":"1.232283863","rc":[{"batb":[[0,1.05,200],[1,1.04,251.05],[2,1.03,533.33]],"ltp":5.1,"tv":8.0,"id":61044843}]}]}
{"op":"mcm","clk":"11987294253","pt":1724935280699,"mc":[{"id":"1.232283863","rc":[{"batb":[[0,1.06,5],[1,1.05,200],[2,1.04,251.05]],"ltp":5.1,"tv":8.0,"id":61044843}]}]}
{"op":"mcm","clk":"11987294484","pt":1724935284202,"mc":[{"id":"1.232283863","rc":[{"batb":[[0,1.05,200],[1,1.04,251.05],[2,1.03,533.33]],"ltp":5.1,"tv":8.0,"id":61044843}]}]}
{"op":"mcm","clk":"11987294701","pt":1724935287085,"mc":[{"id":"1.232283863","rc":[{"batb":[[0,1.06,5],[1,1.05,200],[2,1.04,251.05]],"ltp":5.1,"tv":8.0,"id":61044843}]}]}
{"op":"mcm","clk":"11987294923","pt":1724935290493,"mc":[{"id":"1.232283863","rc":[{"batb":[[0,1.05,200],[1,1.04,251.05],[2,1.03,533.33]],"ltp":5.1,"tv":8.0,"id":61044843}]}]}
{"op":"mcm","clk":"11987295288","pt":1724935295394,"mc":[{"id":"1.232283863","rc":[{"batb":[[0,1.06,5],[1,1.05,200],[2,1.04,251.05]],"ltp":5.1,"tv":8.0,"id":61044843}]}]}
{"op":"mcm","clk":"11987295580","pt":1724935299120,"mc":[{"id":"1.232283863","rc":[{"batb":[[0,1.05,200],[1,1.04,251.05],[2,1.03,533.33]],"ltp":5.1,"tv":8.0,"id":61044843}]}]}
{"op":"mcm","clk":"11987295843","pt":1724935302720,"mc":[{"id":"1.232283863","rc":[{"batb":[[0,1.06,5],[1,1.05,200],[2,1.04,251.05]],"ltp":5.1,"tv":8.0,"id":61044843}]}]}
{"op":"mcm","clk":"11987296113","pt":1724935306185,"mc":[{"id":"1.232283863","rc":[{"batb":[[0,1.05,200],[1,1.04,251.05],[2,1.03,533.33]],"ltp":5.1,"tv":8.0,"id":61044843}]}]}
{"op":"mcm","clk":"11987296483","pt":1724935308999,"mc":[{"id":"1.232283863","rc":[{"batb":[[0,1.06,5],[1,1.05,200],[2,1.04,251.05]],"ltp":5.1,"tv":8.0,"id":61044843}]}]}
{"op":"mcm","clk":"11987296897","pt":1724935312519,"mc":[{"id":"1.232283863","rc":[{"batb":[[0,1.05,200],[1,1.04,251.05],[2,1.03,533.33]],"ltp":5.1,"tv":8.0,"id":61044843}]}]}
{"op":"mcm","clk":"11987297133","pt":1724935314808,"mc":[{"id":"1.232283863","rc":[{"batb":[[0,1.06,5],[1,1.05,200],[2,1.04,251.05]],"ltp":5.1,"tv":8.0,"id":61044843}]}]}
{"op":"mcm","clk":"11987297437","pt":1724935318222,"mc":[{"id":"1.232283863","rc":[{"batb":[[0,1.05,200],[1,1.04,251.05],[2,1.03,533.33]],"ltp":5.1,"tv":8.0,"id":61044843}]}]}
{"op":"mcm","clk":"11987297868","pt":1724935323205,"mc":[{"id":"1.232283863","rc":[{"batb":[[0,1.06,5],[1,1.05,200],[2,1.04,251.05]],"ltp":5.1,"tv":8.0,"id":61044843}]}]}
{"op":"mcm","clk":"11987298188","pt":1724935326615,"mc":[{"id":"1.232283863","rc":[{"batb":[[0,1.05,200],[1,1.04,251.05],[2,1.03,533.33]],"ltp":5.1,"tv":8.0,"id":61044843}]}]}
{"op":"mcm","clk":"11987298383","pt":1724935329040,"mc":[{"id":"1.232283863","rc":[{"batb":[[0,1.06,5],[1,1.05,200],[2,1.04,251.05]],"ltp":5.1,"tv":8.0,"id":61044843}]}]}
{"op":"mcm","clk":"11987298670","pt":1724935332608,"mc":[{"id":"1.232283863","rc":[{"batb":[[0,1.05,200],[1,1.04,251.05],[2,1.03,533.33]],"ltp":5.1,"tv":8.0,"id":61044843}]}]}
{"op":"mcm","clk":"11987298961","pt":1724935336019,"mc":[{"id":"1.232283863","rc":[{"batb":[[0,1.06,5],[1,1.05,200],[2,1.04,251.05]],"ltp":5.1,"tv":8.0,"id":61044843}]}]}
{"op":"mcm","clk":"11987299220","pt":1724935339316,"mc":[{"id":"1.232283863","rc":[{"batb":[[0,1.05,200],[1,1.04,251.05],[2,1.03,533.33]],"ltp":5.1,"tv":8.0,"id":61044843}]}]}
{"op":"mcm","clk":"11987299579","pt":1724935343613,"mc":[{"id":"1.232283863","rc":[{"batb":[[0,1.06,5],[1,1.05,200],[2,1.04,251.05]],"ltp":5.1,"tv":8.0,"id":61044843}]}]}
{"op":"mcm","clk":"11987299864","pt":1724935347022,"mc":[{"id":"1.232283863","rc":[{"batb":[[0,1.05,200],[1,1.04,251.05],[2,1.03,533.33]],"ltp":5.1,"tv":8.0,"id":61044843}]}]}
{"op":"mcm","clk":"11987300256","pt":1724935352942,"mc":[{"id":"1.232283863","rc":[{"batb":[[0,1.06,5],[1,1.05,200],[2,1.04,251.05]],"ltp":5.1,"tv":8.0,"id":61044843}]}]}
{"op":"mcm","clk":"11987300491","pt":1724935356352,"mc":[{"id":"1.232283863","rc":[{"batb":[[0,1.05,200],[1,1.04,251.05],[2,1.03,533.33]],"ltp":5.1,"tv":8.0,"id":61044843}]}]}
{"op":"mcm","clk":"11987300652","pt":1724935359240,"mc":[{"id":"1.232283863","rc":[{"batb":[[0,1.06,5],[1,1.05,200],[2,1.04,251.05]],"ltp":5.1,"tv":8.0,"id":61044843}]}]}
{"op":"mcm","clk":"11987300890","pt":1724935362630,"mc":[{"id":"1.232283863","rc":[{"batb":[[0,1.05,200],[1,1.04,251.05],[2,1.03,533.33]],"ltp":5.1,"tv":8.0,"id":61044843}]}]}
{"op":"mcm","clk":"11987301288","pt":1724935367949,"mc":[{"id":"1.232283863","rc":[{"batb":[[0,1.06,5],[1,1.05,200],[2,1.04,251.05]],"ltp":5.1,"tv":8.0,"id":61044843}]}]}
{"op":"mcm","clk":"11987301582","pt":1724935371375,"mc":[{"id":"1.232283863","rc":[{"batb":[[0,1.05,200],[1,1.04,251.05],[2,1.03,533.33]],"ltp":5.1,"tv":8.0,"id":61044843}]}]}
{"op":"mcm","clk":"11987314782","pt":1724935375215,"mc":[{"id":"1.232283863","rc":[{"batb":[[0,1.06,5],[1,1.05,200],[2,1.04,251.05]],"ltp":5.1,"tv":8.0,"id":61044843}]}]}
{"op":"mcm","clk":"11987315094","pt":1724935378887,"mc":[{"id":"1.232283863","rc":[{"batb":[[0,1.05,200],[1,1.04,251.05],[2,1.03,533.33]],"ltp":5.1,"tv":8.0,"id":61044843}]}]}
{"op":"mcm","clk":"11987315918","pt":1724935390887,"mc":[{"id":"1.232283863","rc":[{"batb":[[0,1.06,5],[1,1.05,200],[2,1.04,251.05]],"ltp":5.1,"tv":8.0,"id":61044843}]}]}
{"op":"mcm","clk":"11987316161","pt":1724935394395,"mc":[{"id":"1.232283863","rc":[{"batb":[[0,1.05,200],[1,1.04,251.05],[2,1.03,533.33]],"ltp":5.1,"tv":8.0,"id":61044843}]}]}
{"op":"mcm","clk":"11987316366","pt":1724935397285,"mc":[{"id":"1.232283863","rc":[{"batb":[[0,1.06,5],[1,1.05,200],[2,1.04,251.05]],"ltp":5.1,"tv":8.0,"id":61044843}]}]}
{"op":"mcm","clk":"11987316618","pt":1724935400789,"mc":[{"id":"1.232283863","rc":[{"batb":[[0,1.05,200],[1,1.04,251.05],[2,1.03,533.33]],"ltp":5.1,"tv":8.0,"id":61044843}]}]}
{"op":"mcm","clk":"11987316909","pt":1724935405064,"mc":[{"id":"1.232283863","rc":[{"batb":[[0,1.06,5],[1,1.05,200],[2,1.04,251.05]],"ltp":5.1,"tv":8.0,"id":61044843}]}]}
{"op":"mcm","clk":"11987317159","pt":1724935408815,"mc":[{"id":"1.232283863","rc":[{"batb":[[0,1.05,200],[1,1.04,251.05],[2,1.03,533.33]],"ltp":5.1,"tv":8.0,"id":61044843}]}]}
{"op":"mcm","clk":"11987317323","pt":1724935411284,"mc":[{"id":"1.232283863","rc":[{"batb":[[0,1.06,5],[1,1.05,200],[2,1.04,251.05]],"ltp":5.1,"tv":8.0,"id":61044843}]}]}
{"op":"mcm","clk":"11987317590","pt":1724935414977,"mc":[{"id":"1.232283863","rc":[{"batb":[[0,1.05,200],[1,1.04,251.05],[2,1.03,533.33]],"ltp":5.1,"tv":8.0,"id":61044843}]}]}
{"op":"mcm","clk":"11987317875","pt":1724935418501,"mc":[{"id":"1.232283863","rc":[{"batb":[[0,1.06,5],[1,1.05,200],[2,1.04,251.05]],"ltp":5.1,"tv":8.0,"id":61044843}]}]}
{"op":"mcm","clk":"11987318166","pt":1724935422191,"mc":[{"id":"1.232283863","rc":[{"batb":[[0,1.05,200],[1,1.04,251.05],[2,1.03,533.33]],"ltp":5.1,"tv":8.0,"id":61044843}]}]}
{"op":"mcm","clk":"11987318348","pt":1724935424800,"mc":[{"id":"1.232283863","rc":[{"batb":[[0,1.06,5],[1,1.05,200],[2,1.04,251.05]],"ltp":5.1,"tv":8.0,"id":61044843}]}]}
{"op":"mcm","clk":"11987318566","pt":1724935428444,"mc":[{"id":"1.232283863","rc":[{"batb":[[0,1.05,200],[1,1.04,251.05],[2,1.03,533.33]],"ltp":5.1,"tv":8.0,"id":61044843}]}]}
{"op":"mcm","clk":"11987319119","pt":1724935435807,"mc":[{"id":"1.232283863","rc":[{"batb":[[0,1.06,5],[1,1.05,200],[2,1.04,251.05]],"ltp":5.1,"tv":8.0,"id":61044843}]}]}
{"op":"mcm","clk":"11987319327","pt":1724935439141,"mc":[{"id":"1.232283863","rc":[{"batb":[[0,1.05,200],[1,1.04,251.05],[2,1.03,533.33]],"ltp":5.1,"tv":8.0,"id":61044843}]}]}
{"op":"mcm","clk":"11987319774","pt":1724935444749,"mc":[{"id":"1.232283863","rc":[{"batb":[[0,1.06,5],[1,1.05,200],[2,1.04,251.05]],"ltp":5.1,"tv":8.0,"id":61044843}]}]}
{"op":"mcm","clk":"11987320062","pt":1724935448346,"mc":[{"id":"1.232283863","rc":[{"batb":[[0,1.05,200],[1,1.04,251.05],[2,1.03,533.33]],"ltp":5.1,"tv":8.0,"id":61044843}]}]}
{"op":"mcm","clk":"11987320277","pt":1724935451023,"mc":[{"id":"1.232283863","rc":[{"batb":[[0,1.06,5],[1,1.05,200],[2,1.04,251.05]],"ltp":5.1,"tv":8.0,"id":61044843}]}]}
{"op":"mcm","clk":"11987320563","pt":1724935454532,"mc":[{"id":"1.232283863","rc":[{"batb":[[0,1.05,200],[1,1.04,251.05],[2,1.03,533.33]],"ltp":5.1,"tv":8.0,"id":61044843}]}]}
{"op":"mcm","clk":"11987320802","pt":1724935457836,"mc":[{"id":"1.232283863","rc":[{"batb":[[0,1.06,5],[1,1.05,200],[2,1.04,251.05]],"ltp":5.1,"tv":8.0,"id":61044843}]}]}
{"op":"mcm","clk":"11987321080","pt":1724935461229,"mc":[{"id":"1.232283863","rc":[{"batb":[[0,1.05,200],[1,1.04,251.05],[2,1.03,533.33]],"ltp":5.1,"tv":8.0,"id":61044843}]}]}
{"op":"mcm","clk":"11987321401","pt":1724935465132,"mc":[{"id":"1.232283863","rc":[{"batb":[[0,1.06,5],[1,1.05,200],[2,1.04,251.05]],"ltp":5.1,"tv":8.0,"id":61044843}]}]}
{"op":"mcm","clk":"11987321663","pt":1724935468737,"mc":[{"id":"1.232283863","rc":[{"batb":[[0,1.05,200],[1,1.04,251.05],[2,1.03,533.33]],"ltp":5.1,"tv":8.0,"id":61044843}]}]}
{"op":"mcm","clk":"11987321928","pt":1724935472032,"mc":[{"id":"1.232283863","rc":[{"batb":[[0,1.06,5],[1,1.05,200],[2,1.04,251.05]],"ltp":5.1,"tv":8.0,"id":61044843}]}]}
{"op":"mcm","clk":"11987322178","pt":1724935475339,"mc":[{"id":"1.232283863","rc":[{"batb":[[0,1.05,200],[1,1.04,251.05],[2,1.03,533.33]],"ltp":5.1,"tv":8.0,"id":61044843}]}]}
{"op":"mcm","clk":"11987322388","pt":1724935477857,"mc":[{"id":"1.232283863","rc":[{"batb":[[0,1.06,5],[1,1.05,200],[2,1.04,251.05]],"ltp":5.1,"tv":8.0,"id":61044843}]}]}
{"op":"mcm","clk":"11987322676","pt":1724935481466,"mc":[{"id":"1.232283863","rc":[{"batb":[[0,1.05,200],[1,1.04,251.05],[2,1.03,533.33]],"ltp":5.1,"tv":8.0,"id":61044843}]}]}
{"op":"mcm","clk":"11987322894","pt":1724935483782,"mc":[{"id":"1.232283863","rc":[{"batb":[[0,1.06,5],[1,1.05,200],[2,1.04,251.05]],"ltp":5.1,"tv":8.0,"id":61044843}]}]}
{"op":"mcm","clk":"11987323188","pt":1724935487284,"mc":[{"id":"1.232283863","rc":[{"batb":[[0,1.05,200],[1,1.04,251.05],[2,1.03,533.33]],"ltp":5.1,"tv":8.0,"id":61044843}]}]}
{"op":"mcm","clk":"11987323504","pt":1724935490481,"mc":[{"id":"1.232283863","rc":[{"batb":[[0,1.06,5],[1,1.05,200],[2,1.04,251.05]],"ltp":5.1,"tv":8.0,"id":61044843}]}]}
{"op":"mcm","clk":"11987323838","pt":1724935493998,"mc":[{"id":"1.232283863","rc":[{"batb":[[0,1.05,200],[1,1.04,251.05],[2,1.03,533.33]],"ltp":5.1,"tv":8.0,"id":61044843}]}]}
{"op":"mcm","clk":"11987324101","pt":1724935496374,"mc":[{"id":"1.232283863","rc":[{"batb":[[0,1.06,5],[1,1.05,200],[2,1.04,251.05]],"ltp":5.1,"tv":8.0,"id":61044843}]}]}
{"op":"mcm","clk":"11987324384","pt":1724935500001,"mc":[{"id":"1.232283863","rc":[{"batb":[[0,1.05,200],[1,1.04,251.05],[2,1.03,533.33]],"ltp":5.1,"tv":8.0,"id":61044843}]}]}
{"op":"mcm","clk":"11987324780","pt":1724935503680,"mc":[{"id":"1.232283863","rc":[{"batb":[[0,1.06,5],[1,1.05,200],[2,1.04,251.05]],"ltp":5.1,"tv":8.0,"id":61044843}]}]}
{"op":"mcm","clk":"11987325133","pt":1724935506878,"mc":[{"id":"1.232283863","rc":[{"batb":[[0,1.05,200],[1,1.04,251.05],[2,1.03,533.33]],"ltp":5.1,"tv":8.0,"id":61044843}]}]}
{"op":"mcm","clk":"11987325532","pt":1724935510675,"mc":[{"id":"1.232283863","rc":[{"batb":[[0,1.06,5],[1,1.05,200],[2,1.04,251.05]],"ltp":5.1,"tv":8.0,"id":61044843}]}]}
{"op":"mcm","clk":"11987325807","pt":1724935514013,"mc":[{"id":"1.232283863","rc":[{"batb":[[0,1.05,200],[1,1.04,251.05],[2,1.03,533.33]],"ltp":5.1,"tv":8.0,"id":61044843}]}]}
{"op":"mcm","clk":"11987326023","pt":1724935516895,"mc":[{"id":"1.232283863","rc":[{"batb":[[0,1.06,5],[1,1.05,200],[2,1.04,251.05]],"ltp":5.1,"tv":8.0,"id":61044843}]}]}
{"op":"mcm","clk":"11987326271","pt":1724935520188,"mc":[{"id":"1.232283863","rc":[{"batb":[[0,1.05,200],[1,1.04,251.05],[2,1.03,533.33]],"ltp":5.1,"tv":8.0,"id":61044843}]}]}
{"op":"mcm","clk":"11987326667","pt":1724935524982,"mc":[{"id":"1.232283863","rc":[{"batb":[[0,1.06,5],[1,1.05,200],[2,1.04,251.05]],"ltp":5.1,"tv":8.0,"id":61044843}]}]}
{"op":"mcm","clk":"11987326946","pt":1724935528578,"mc":[{"id":"1.232283863","rc":[{"batb":[[0,1.05,200],[1,1.04,251.05],[2,1.03,533.33]],"ltp":5.1,"tv":8.0,"id":61044843}]}]}
{"op":"mcm","clk":"11987327200","pt":1724935532023,"mc":[{"id":"1.232283863","rc":[{"batb":[[0,1.06,5],[1,1.05,200],[2,1.04,251.05]],"ltp":5.1,"tv":8.0,"id":61044843}]}]}
{"op":"mcm","clk":"11987327495","pt":1724935535523,"mc":[{"id":"1.232283863","rc":[{"batb":[[0,1.05,200],[1,1.04,251.05],[2,1.03,533.33]],"ltp":5.1,"tv":8.0,"id":61044843}]}]}
{"op":"mcm","clk":"11987327822","pt":1724935539129,"mc":[{"id":"1.232283863","rc":[{"batb":[[0,1.06,5],[1,1.05,200],[2,1.04,251.05]],"ltp":5.1,"tv":8.0,"id":61044843}]}]}
{"op":"mcm","clk":"11987328082","pt":1724935542322,"mc":[{"id":"1.232283863","rc":[{"batb":[[0,1.05,200],[1,1.04,251.05],[2,1.03,533.33]],"ltp":5.1,"tv":8.0,"id":61044843}]}]}
{"op":"mcm","clk":"11987329314","pt":1724935558433,"mc":[{"id":"1.232283863","rc":[{"batb":[[0,1.06,5],[1,1.05,200],[2,1.04,251.05]],"ltp":5.1,"tv":8.0,"id":61044843}]}]}
{"op":"mcm","clk":"11987329599","pt":1724935561834,"mc":[{"id":"1.232283863","rc":[{"batb":[[0,1.05,200],[1,1.04,251.05],[2,1.03,533.33]],"ltp":5.1,"tv":8.0,"id":61044843}]}]}
{"op":"mcm","clk":"11987329865","pt":1724935564619,"mc":[{"id":"1.232283863","rc":[{"batb":[[0,1.06,5],[1,1.05,200],[2,1.04,251.05]],"ltp":5.1,"tv":8.0,"id":61044843}]}]}
{"op":"mcm","clk":"11987330191","pt":1724935568226,"mc":[{"id":"1.232283863","rc":[{"batb":[[0,1.05,200],[1,1.04,251.05],[2,1.03,533.33]],"ltp":5.1,"tv":8.0,"id":61044843}]}]}
{"op":"mcm","clk":"11987330510","pt":1724935571471,"mc":[{"id":"1.232283863","rc":[{"batb":[[0,1.06,5],[1,1.05,200],[2,1.04,251.05]],"ltp":5.1,"tv":8.0,"id":61044843}]}]}
{"op":"mcm","clk":"11987330784","pt":1724935574873,"mc":[{"id":"1.232283863","rc":[{"batb":[[0,1.05,200],[1,1.04,251.05],[2,1.03,533.33]],"ltp":5.1,"tv":8.0,"id":61044843}]}]}
{"op":"mcm","clk":"11987331665","pt":1724935585755,"mc":[{"id":"1.232283863","rc":[{"batb":[[0,1.06,5],[1,1.05,200],[2,1.04,251.05]],"ltp":5.1,"tv":8.0,"id":61044843}]}]}
{"op":"mcm","clk":"11987331896","pt":1724935589357,"mc":[{"id":"1.232283863","rc":[{"batb":[[0,1.05,200],[1,1.04,251.05],[2,1.03,533.33]],"ltp":5.1,"tv":8.0,"id":61044843}]}]}
{"op":"mcm","clk":"11987332141","pt":1724935592347,"mc":[{"id":"1.232283863","rc":[{"batb":[[0,1.06,5],[1,1.05,200],[2,1.04,251.05]],"ltp":5.1,"tv":8.0,"id":61044843}]}]}
{"op":"mcm","clk":"11987332455","pt":1724935595971,"mc":[{"id":"1.232283863","rc":[{"batb":[[0,1.05,200],[1,1.04,251.05],[2,1.03,533.33]],"ltp":5.1,"tv":8.0,"id":61044843}]}]}
{"op":"mcm","clk":"11987332957","pt":1724935601284,"mc":[{"id":"1.232283863","rc":[{"batb":[[0,1.06,5],[1,1.05,200],[2,1.04,251.05]],"ltp":5.1,"tv":8.0,"id":61044843}]}]}
{"op":"mcm","clk":"11987333198","pt":1724935604495,"mc":[{"id":"1.232283863","rc":[{"batb":[[0,1.05,200],[1,1.04,251.05],[2,1.03,533.33]],"ltp":5.1,"tv":8.0,"id":61044843}]}]}
{"op":"mcm","clk":"11987333366","pt":1724935607209,"mc":[{"id":"1.232283863","rc":[{"batb":[[0,1.06,5],[1,1.05,200],[2,1.04,251.05]],"ltp":5.1,"tv":8.0,"id":61044843}]}]}
{"op":"mcm","clk":"11987333620","pt":1724935610606,"mc":[{"id":"1.232283863","rc":[{"batb":[[0,1.05,200],[1,1.04,251.05],[2,1.03,533.33]],"ltp":5.1,"tv":8.0,"id":61044843}]}]}
{"op":"mcm","clk":"11987334342","pt":1724935619912,"mc":[{"id":"1.232283863","rc":[{"batb":[[0,1.06,5],[1,1.05,200],[2,1.04,251.05]],"ltp":5.1,"tv":8.0,"id":61044843}]}]}
{"op":"mcm","clk":"11987334686","pt":1724935623719,"mc":[{"id":"1.232283863","rc":[{"batb":[[0,1.05,200],[1,1.04,251.05],[2,1.03,533.33]],"ltp":5.1,"tv":8.0,"id":61044843}]}]}
{"op":"mcm","clk":"11987335165","pt":1724935629490,"mc":[{"id":"1.232283863","rc":[{"batb":[[0,1.06,5],[1,1.05,200],[2,1.04,251.05]],"ltp":5.1,"tv":8.0,"id":61044843}]}]}
{"op":"mcm","clk":"11987335427","pt":1724935633004,"mc":[{"id":"1.232283863","rc":[{"batb":[[0,1.05,200],[1,1.04,251.05],[2,1.03,533.33]],"ltp":5.1,"tv":8.0,"id":61044843}]}]}
{"op":"mcm","clk":"11987335635","pt":1724935635317,"mc":[{"id":"1.232283863","rc":[{"batb":[[0,1.06,5],[1,1.05,200],[2,1.04,251.05]],"ltp":5.1,"tv":8.0,"id":61044843}]}]}
{"op":"mcm","clk":"11987335849","pt":1724935638655,"mc":[{"id":"1.232283863","rc":[{"batb":[[0,1.05,200],[1,1.04,251.05],[2,1.03,533.33]],"ltp":5.1,"tv":8.0,"id":61044843}]}]}
{"op":"mcm","clk":"11987336063","pt":1724935641538,"mc":[{"id":"1.232283863","rc":[{"batb":[[0,1.06,5],[1,1.05,200],[2,1.04,251.05]],"ltp":5.1,"tv":8.0,"id":61044843}]}]}
{"op":"mcm","clk":"11987336329","pt":1724935644931,"mc":[{"id":"1.232283863","rc":[{"batb":[[0,1.05,200],[1,1.04,251.05],[2,1.03,533.33]],"ltp":5.1,"tv":8.0,"id":61044843}]}]}
{"op":"mcm","clk":"11987337642","pt":1724935661239,"mc":[{"id":"1.232283863","rc":[{"batb":[[0,1.06,5],[1,1.05,200],[2,1.04,251.05]],"ltp":5.1,"tv":8.0,"id":61044843}]}]}
{"op":"mcm","clk":"11987337884","pt":1724935664642,"mc":[{"id":"1.232283863","rc":[{"batb":[[0,1.05,200],[1,1.04,251.05],[2,1.03,533.33]],"ltp":5.1,"tv":8.0,"id":61044843}]}]}
{"op":"mcm","clk":"11987338332","pt":1724935671358,"mc":[{"id":"1.232283863","rc":[{"batb":[[0,1.06,5],[1,1.05,200],[2,1.04,251.05]],"ltp":5.1,"tv":8.0,"id":61044843}]}]}
{"op":"mcm","clk":"11987338556","pt":1724935674685,"mc":[{"id":"1.232283863","rc":[{"batb":[[0,1.05,200],[1,1.04,251.05],[2,1.03,533.33]],"ltp":5.1,"tv":8.0,"id":61044843}]}]}
{"op":"mcm","clk":"11987338809","pt":1724935678378,"mc":[{"id":"1.232283863","rc":[{"batb":[[0,1.06,5],[1,1.05,200],[2,1.04,251.05]],"ltp":5.1,"tv":8.0,"id":61044843}]}]}
{"op":"mcm","clk":"11987339098","pt":1724935681779,"mc":[{"id":"1.232283863","rc":[{"batb":[[0,1.05,200],[1,1.04,251.05],[2,1.03,533.33]],"ltp":5.1,"tv":8.0,"id":61044843}]}]}
{"op":"mcm","clk":"11987339807","pt":1724935689983,"mc":[{"id":"1.232283863","rc":[{"batb":[[0,1.06,5],[1,1.05,200],[2,1.04,251.05]],"ltp":5.1,"tv":8.0,"id":61044843}]}]}
{"op":"mcm","clk":"11987340046","pt":1724935693475,"mc":[{"id":"1.232283863","rc":[{"batb":[[0,1.05,200],[1,1.04,251.05],[2,1.03,533.33]],"ltp":5.1,"tv":8.0,"id":61044843}]}]}
{"op":"mcm","clk":"11987341020","pt":1724935706400,"mc":[{"id":"1.232283863","rc":[{"batb":[[0,1.06,5],[1,1.05,200],[2,1.04,251.05]],"ltp":5.1,"tv":8.0,"id":61044843}]}]}
{"op":"mcm","clk":"11987341270","pt":1724935709898,"mc":[{"id":"1.232283863","rc":[{"batb":[[0,1.05,200],[1,1.04,251.05],[2,1.03,533.33]],"ltp":5.1,"tv":8.0,"id":61044843}]}]}
{"op":"mcm","clk":"11987342238","pt":1724935722717,"mc":[{"id":"1.232283863","rc":[{"batb":[[0,1.06,5],[1,1.05,200],[2,1.04,251.05]],"ltp":5.1,"tv":8.0,"id":61044843}]}]}
{"op":"mcm","clk":"11987342476","pt":1724935726215,"mc":[{"id":"1.232283863","rc":[{"batb":[[0,1.05,200],[1,1.04,251.05],[2,1.03,533.33]],"ltp":5.1,"tv":8.0,"id":61044843}]}]}
{"op":"mcm","clk":"11987342739","pt":1724935730026,"mc":[{"id":"1.232283863","rc":[{"batb":[[0,1.06,5],[1,1.05,200],[2,1.04,251.05]],"ltp":5.1,"tv":8.0,"id":61044843}]}]}
{"op":"mcm","clk":"11987343000","pt":1724935733533,"mc":[{"id":"1.232283863","rc":[{"batb":[[0,1.05,200],[1,1.04,251.05],[2,1.03,533.33]],"ltp":5.1,"tv":8.0,"id":61044843}]}]}
{"op":"mcm","clk":"11987343253","pt":1724935736837,"mc":[{"id":"1.232283863","rc":[{"batb":[[0,1.06,5],[1,1.05,200],[2,1.04,251.05]],"ltp":5.1,"tv":8.0,"id":61044843}]}]}
{"op":"mcm","clk":"11987343492","pt":1724935740542,"mc":[{"id":"1.232283863","rc":[{"batb":[[0,1.05,200],[1,1.04,251.05],[2,1.03,533.33]],"ltp":5.1,"tv":8.0,"id":61044843}]}]}
{"op":"mcm","clk":"11987343672","pt":1724935743129,"mc":[{"id":"1.232283863","rc":[{"batb":[[0,1.06,5],[1,1.05,200],[2,1.04,251.05]],"ltp":5.1,"tv":8.0,"id":61044843}]}]}
{"op":"mcm","clk":"11987343948","pt":1724935746641,"mc":[{"id":"1.232283863","rc":[{"batb":[[0,1.05,200],[1,1.04,251.05],[2,1.03,533.33]],"ltp":5.1,"tv":8.0,"id":61044843}]}]}
{"op":"mcm","clk":"11987344168","pt":1724935749422,"mc":[{"id":"1.232283863","rc":[{"batb":[[0,1.06,5],[1,1.05,200],[2,1.04,251.05]],"ltp":5.1,"tv":8.0,"id":61044843}]}]}
{"op":"mcm","clk":"11987344429","pt":1724935752839,"mc":[{"id":"1.232283863","rc":[{"batb":[[0,1.05,200],[1,1.04,251.05],[2,1.03,533.33]],"ltp":5.1,"tv":8.0,"id":61044843}]}]}
{"op":"mcm","clk":"11987344817","pt":1724935757865,"mc":[{"id":"1.232283863","rc":[{"batb":[[0,1.06,5],[1,1.05,200],[2,1.04,251.05]],"ltp":5.1,"tv":8.0,"id":61044843}]}]}
{"op":"mcm","clk":"11987345096","pt":1724935761470,"mc":[{"id":"1.232283863","rc":[{"batb":[[0,1.05,200],[1,1.04,251.05],[2,1.03,533.33]],"ltp":5.1,"tv":8.0,"id":61044843}]}]}
{"op":"mcm","clk":"11987345508","pt":1724935766978,"mc":[{"id":"1.232283863","rc":[{"batb":[[0,1.06,5],[1,1.05,200],[2,1.04,251.05]],"ltp":5.1,"tv":8.0,"id":61044843}]}]}
{"op":"mcm","clk":"11987345773","pt":1724935770474,"mc":[{"id":"1.232283863","rc":[{"batb":[[0,1.05,200],[1,1.04,251.05],[2,1.03,533.33]],"ltp":5.1,"tv":8.0,"id":61044843}]}]}
{"op":"mcm","clk":"11987346008","pt":1724935773474,"mc":[{"id":"1.232283863","rc":[{"batb":[[0,1.06,5],[1,1.05,200],[2,1.04,251.05]],"ltp":5.1,"tv":8.0,"id":61044843}]}]}
{"op":"mcm","clk":"11987346290","pt":1724935777284,"mc":[{"id":"1.232283863","rc":[{"batb":[[0,1.05,200],[1,1.04,251.05],[2,1.03,533.33]],"ltp":5.1,"tv":8.0,"id":61044843}]}]}
{"op":"mcm","clk":"11987346649","pt":1724935781784,"mc":[{"id":"1.232283863","rc":[{"batb":[[0,1.06,5],[1,1.05,200],[2,1.04,251.05]],"ltp":5.1,"tv":8.0,"id":61044843}]}]}
{"op":"mcm","clk":"11987346929","pt":1724935785288,"mc":[{"id":"1.232283863","rc":[{"batb":[[0,1.05,200],[1,1.04,251.05],[2,1.03,533.33]],"ltp":5.1,"tv":8.0,"id":61044843}]}]}
{"op":"mcm","clk":"11987347110","pt":1724935787673,"mc":[{"id":"1.232283863","rc":[{"batb":[[0,1.06,5],[1,1.05,200],[2,1.04,251.05]],"ltp":5.1,"tv":8.0,"id":61044843}]}]}
{"op":"mcm","clk":"11987347354","pt":1724935791206,"mc":[{"id":"1.232283863","rc":[{"batb":[[0,1.05,200],[1,1.04,251.05],[2,1.03,533.33]],"ltp":5.1,"tv":8.0,"id":61044843}]}]}
{"op":"mcm","clk":"11987347699","pt":1724935796008,"mc":[{"id":"1.232283863","rc":[{"batb":[[0,1.06,5],[1,1.05,200],[2,1.04,251.05]],"ltp":5.1,"tv":8.0,"id":61044843}]}]}
{"op":"mcm","clk":"11987347918","pt":1724935799298,"mc":[{"id":"1.232283863","rc":[{"batb":[[0,1.05,200],[1,1.04,251.05],[2,1.03,533.33]],"ltp":5.1,"tv":8.0,"id":61044843}]}]}
{"op":"mcm","clk":"11987348197","pt":1724935803126,"mc":[{"id":"1.232283863","rc":[{"batb":[[0,1.06,5],[1,1.05,200],[2,1.04,251.05]],"ltp":5.1,"tv":8.0,"id":61044843}]}]}
{"op":"mcm","clk":"11987348480","pt":1724935806703,"mc":[{"id":"1.232283863","rc":[{"batb":[[0,1.05,200],[1,1.04,251.05],[2,1.03,533.33]],"ltp":5.1,"tv":8.0,"id":61044843}]}]}
{"op":"mcm","clk":"11987348951","pt":1724935813205,"mc":[{"id":"1.232283863","rc":[{"batb":[[0,1.06,5],[1,1.05,200],[2,1.04,251.05]],"ltp":5.1,"tv":8.0,"id":61044843}]}]}
