{"op":"mcm","clk":"11966341476","pt":1724621740164,"mc":[{"id":"1.232283714","marketDefinition":{"bspMarket":false,"turnInPlayEnabled":true,"persistenceEnabled":true,"marketBaseRate":5.0,"eventId":"33527093","eventTypeId":"4","numberOfWinners":1,"bettingType":"ODDS","marketType":"MATCH_ODDS","marketTime":"2024-08-26T23:00:00.000Z","suspendTime":"2024-08-26T23:00:00.000Z","bspReconciled":false,"complete":true,"inPlay":false,"crossMatching":true,"runnersVoidable":false,"numberOfActiveRunners":2,"betDelay":0,"status":"OPEN","runners":[{"status":"ACTIVE","sortPriority":1,"id":7591770,"name":"Guyana Amazon Warriors"},{"status":"ACTIVE","sortPriority":2,"id":47650821,"name":"Barbados Royals Women"}],"regulators":["MR_INT"],"countryCode":"GB","discountAllowed":false,"timezone":"GMT","openDate":"2024-08-26T23:00:00.000Z","version":6100640819,"name":"Match Odds","eventName":"Guyana Amazon Warriors v Barbados Royals Women"},"rc":[{"batb":[[0,1.03,200],[1,1.02,200],[2,1.01,220]],"ltp":0.0,"tv":0.0,"id":7591770},{"batb":[[0,1.03,200],[1,1.02,200],[2,1.01,220]],"ltp":0.0,"tv":0.0,"id":47650821}]}]}
{"op":"mcm","clk":"11966341660","pt":1724621742553,"mc":[{"id":"1.232283714","marketDefinition":{"bspMarket":false,"turnInPlayEnabled":true,"persistenceEnabled":true,"marketBaseRate":5.0,"eventId":"33527093","eventTypeId":"4","numberOfWinners":1,"bettingType":"ODDS","marketType":"MATCH_ODDS","marketTime":"2024-08-26T23:00:00.000Z","suspendTime":"2024-08-26T23:00:00.000Z","bspReconciled":false,"complete":true,"inPlay":false,"crossMatching":true,"runnersVoidable":false,"numberOfActiveRunners":2,"betDelay":0,"status":"OPEN","runners":[{"status":"ACTIVE","sortPriority":1,"id":7591770,"name":"Guyana Amazon Warriors"},{"status":"ACTIVE","sortPriority":2,"id":47650821,"name":"Barbados Royals Women"}],"regulators":["MR_INT"],"countryCode":"GB","discountAllowed":true,"timezone":"GMT","openDate":"2024-08-26T23:00:00.000Z","version":6100640819,"name":"Match Odds","eventName":"Guyana Amazon Warriors v Barbados Royals Women"}}]}
{"op":"mcm","clk":"11966460413","pt":1724623340796,"mc":[{"id":"1.232283714","rc":[{"batb":[[2,1.01,220.76]],"ltp":0.0,"tv":0.0,"id":7591770},{"batb":[[2,1.01,220.76]],"ltp":0.0,"tv":0.0,"id":47650821}]}]}
{"op":"mcm","clk":"11966966191","pt":1724634996237,"mc":[{"id":"1.232283714","rc":[{"batb":[[2,1.01,480.61]],"ltp":0.0,"tv":0.0,"id":7591770},{"batb":[[2,1.01,480.61]],"ltp":0.0,"tv":0.0,"id":47650821}]}]}
{"op":"mcm","clk":"11967074250","pt":1724638374814,"mc":[{"id":"1.232283714","rc":[{"batb":[[2,1.01,480.8]],"ltp":0.0,"tv":0.0,"id":7591770},{"batb":[[2,1.01,480.8]],"ltp":0.0,"tv":0.0,"id":47650821}]}]}
{"op":"mcm","clk":"11967129198","pt":1724639811511,"mc":[{"id":"1.232283714","rc":[{"batl":[[0,1.04,2.35]],"ltp":0.0,"tv":0.0,"id":47650821}]}]}
{"op":"mcm","clk":"11967129207","pt":1724639811827,"mc":[{"id":"1.232283714","rc":[{"batb":[[0,1.02,200],[1,1.01,480.8],[2,1.01,0]],"ltp":0.0,"tv":0.0,"id":47650821}]}]}
{"op":"mcm","clk":"11967218451","pt":1724643505720,"mc":[{"id":"1.232283714","rc":[{"batb":[[0,1.1,176.28],[1,1.03,200],[2,1.02,200]],"ltp":0.0,"tv":0.0,"id":7591770},{"batb":[[1,1.01,480.83]],"ltp":0.0,"tv":0.0,"id":47650821}]}]}
{"op":"mcm","clk":"11967221567","pt":1724643615759,"mc":[{"id":"1.232283714","rc":[{"batb":[[0,1.03,200],[1,1.02,200],[2,1.01,480.83]],"ltp":0.0,"tv":0.0,"id":7591770}]}]}
{"op":"mcm","clk":"11967224099","pt":1724643731311,"mc":[{"id":"1.232283714","rc":[{"batb":[[0,1.11,4.43],[1,1.02,200],[2,1.01,480.83]],"ltp":0.0,"tv":0.0,"id":47650821}]}]}
{"op":"mcm","clk":"11967224248","pt":1724643742819,"mc":[{"id":"1.232283714","rc":[{"batb":[[0,1.2,6.65],[1,1.03,200],[2,1.02,200]],"ltp":0.0,"tv":0.0,"id":7591770}]}]}
{"op":"mcm","clk":"11967247097","pt":1724644360756,"mc":[{"id":"1.232283714","rc":[{"batb":[[0,1.4,6.58],[1,1.11,4.43],[2,1.02,200]],"ltp":0.0,"tv":0.0,"id":47650821}]}]}
{"op":"mcm","clk":"11967247333","pt":1724644374648,"mc":[{"id":"1.232283714","rc":[{"batl":[[0,6,3.05]],"ltp":0.0,"tv":0.0,"id":47650821}]}]}
{"op":"mcm","clk":"11967247402","pt":1724644379879,"mc":[{"id":"1.232283714","rc":[{"batl":[[0,5.8,3.05]],"ltp":0.0,"tv":0.0,"id":47650821}]}]}
{"op":"mcm","clk":"11967247573","pt":1724644389696,"mc":[{"id":"1.232283714","rc":[{"batl":[[0,5.8,3.98]],"ltp":0.0,"tv":0.0,"id":47650821}]}]}
{"op":"mcm","clk":"11967247859","pt":1724644407707,"mc":[{"id":"1.232283714","rc":[{"batb":[[0,1.26,7.59],[1,1.2,6.65],[2,1.03,200]],"ltp":0.0,"tv":0.0,"id":7591770}]}]}
{"op":"mcm","clk":"11967248093","pt":1724644419804,"mc":[{"id":"1.232283714","rc":[{"batl":[[0,4.9,3.98]],"ltp":0.0,"tv":0.0,"id":47650821}]}]}
{"op":"mcm","clk":"11967248399","pt":1724644438844,"mc":[{"id":"1.232283714","rc":[{"batb":[[0,1.29,7.59]],"ltp":0.0,"tv":0.0,"id":7591770}]}]}
{"op":"mcm","clk":"11967248575","pt":1724644445965,"mc":[{"id":"1.232283714","rc":[{"batl":[[0,4.5,3.98]],"ltp":0.0,"tv":0.0,"id":47650821}]}]}
{"op":"mcm","clk":"11967270603","pt":1724645273956,"mc":[{"id":"1.232283714","rc":[{"batb":[[0,1.29,7.59]],"ltp":0.0,"tv":0.0,"id":7591770},{"batb":[[0,1.4,6.58],[2,1.05,5.19]],"ltp":0.0,"tv":0.0,"id":47650821}]}]}
{"op":"mcm","clk":"11967301347","pt":1724647054142,"mc":[{"id":"1.232283714","rc":[{"batb":[[0,2.24,31],[1,1.29,7.59],[2,1.2,6.65]],"ltp":0.0,"tv":0.0,"id":7591770},{"batb":[[0,1.74,51.95],[1,1.4,6.58],[2,1.11,4.43]],"ltp":0.0,"tv":0.0,"id":47650821}]}]}
{"op":"mcm","clk":"11967367585","pt":1724650121912,"mc":[{"id":"1.232283714","rc":[{"batb":[[0,1.74,52.07]],"ltp":0.0,"tv":0.0,"id":47650821}]}]}
{"op":"mcm","clk":"11967385500","pt":1724650948134,"mc":[{"id":"1.232283714","rc":[{"batb":[[1,1.81,749.94],[2,1.29,7.59]],"ltp":0.0,"tv":0.0,"id":7591770}]}]}
{"op":"mcm","clk":"11967385731","pt":1724650959533,"mc":[{"id":"1.232283714","rc":[{"batb":[[1,1.51,749.94],[2,1.4,6.58]],"ltp":0.0,"tv":0.0,"id":47650821}]}]}
{"op":"mcm","clk":"11967476757","pt":1724654574799,"mc":[{"id":"1.232283714","rc":[{"batb":[[2,1.29,7.59]],"ltp":0.0,"tv":0.0,"id":7591770}]}]}
{"op":"mcm","clk":"11967570859","pt":1724657469590,"mc":[{"id":"1.232283714","rc":[{"batb":[[0,2.26,15.69],[1,2.24,31],[2,1.81,750]],"ltp":0.0,"tv":0.0,"id":7591770},{"batb":[[1,1.51,750]],"ltp":0.0,"tv":0.0,"id":47650821}]}]}
{"op":"mcm","clk":"11967626048","pt":1724659602534,"mc":[{"id":"1.232283714","rc":[{"trd":[[2.26,1.02]],"batb":[[0,2.26,15.18],[2,1.81,750.28]],"ltp":2.26,"tv":1.02,"id":7591770},{"batb":[[1,1.51,750.28],[2,1.4,6.58]],"batl":[[0,4.5,3.98]],"ltp":0.0,"tv":0.0,"id":47650821}],"tv":1.02}]}
{"op":"mcm","clk":"11967626058","pt":1724659602737,"mc":[{"id":"1.232283714","rc":[{"batb":[[0,2.24,31],[1,1.81,750.28],[2,1.29,7.6]],"ltp":2.26,"tv":1.02,"id":7591770}]}]}
{"op":"mcm","clk":"11967674194","pt":1724660728538,"mc":[{"id":"1.232283714","rc":[{"batb":[[0,2.26,15.18],[1,2.24,31],[2,1.81,750.28]],"ltp":2.26,"tv":1.02,"id":7591770}]}]}
{"op":"mcm","clk":"11967713095","pt":1724661887235,"mc":[{"id":"1.232283714","rc":[{"trd":[[1.74,103.76],[1.77,0.24]],"batb":[[0,1.53,56.03],[1,1.52,9],[2,1.51,750.28]],"ltp":1.74,"tv":104.0,"id":47650821}],"tv":105.02}]}
{"op":"mcm","clk":"11967713170","pt":1724661889230,"mc":[{"id":"1.232283714","rc":[{"batb":[[1,1.52,5]],"ltp":1.74,"tv":104.0,"id":47650821}]}]}
{"op":"mcm","clk":"11967713210","pt":1724661890157,"mc":[{"id":"1.232283714","rc":[{"batb":[[1,1.51,750.28],[2,1.4,6.58]],"ltp":1.74,"tv":104.0,"id":47650821}]}]}
{"op":"mcm","clk":"11967713245","pt":1724661891042,"mc":[{"id":"1.232283714","rc":[{"batb":[[0,1.7,54.92],[1,1.53,55.96],[2,1.51,750.28]],"ltp":1.74,"tv":104.0,"id":47650821}]}]}
{"op":"mcm","clk":"11967713293","pt":1724661892176,"mc":[{"id":"1.232283714","rc":[{"batb":[[0,1.71,4],[1,1.7,54.92],[2,1.53,55.96]],"ltp":1.74,"tv":104.0,"id":47650821}]}]}
{"op":"mcm","clk":"11967713330","pt":1724661893357,"mc":[{"id":"1.232283714","rc":[{"batb":[[0,1.72,5],[1,1.71,4],[2,1.7,54.92]],"ltp":1.74,"tv":104.0,"id":47650821}]}]}
{"op":"mcm","clk":"11967713374","pt":1724661894583,"mc":[{"id":"1.232283714","rc":[{"batb":[[1,1.7,54.92],[2,1.53,55.96]],"ltp":1.74,"tv":104.0,"id":47650821}]}]}
{"op":"mcm","clk":"11967713458","pt":1724661896751,"mc":[{"id":"1.232283714","rc":[{"batb":[[0,1.71,4]],"ltp":1.74,"tv":104.0,"id":47650821}]}]}
{"op":"mcm","clk":"11967713541","pt":1724661899068,"mc":[{"id":"1.232283714","rc":[{"batb":[[0,1.72,5]],"ltp":1.74,"tv":104.0,"id":47650821}]}]}
{"op":"mcm","clk":"11967713688","pt":1724661902476,"mc":[{"id":"1.232283714","rc":[{"batb":[[0,1.7,54.92],[1,1.53,55.96],[2,1.51,750.28]],"ltp":1.74,"tv":104.0,"id":47650821}]}]}
{"op":"mcm","clk":"11967713700","pt":1724661902779,"mc":[{"id":"1.232283714","rc":[{"batb":[[0,1.71,4],[1,1.7,54.92]],"ltp":1.74,"tv":104.0,"id":47650821}]}]}
{"op":"mcm","clk":"11967713797","pt":1724661905000,"mc":[{"id":"1.232283714","rc":[{"batb":[[0,1.71,5]],"ltp":1.74,"tv":104.0,"id":47650821}]}]}
{"op":"mcm","clk":"11967713920","pt":1724661908386,"mc":[{"id":"1.232283714","rc":[{"batb":[[0,1.71,4]],"ltp":1.74,"tv":104.0,"id":47650821}]}]}
{"op":"mcm","clk":"11967713989","pt":1724661910769,"mc":[{"id":"1.232283714","rc":[{"batb":[[0,1.72,5]],"ltp":1.74,"tv":104.0,"id":47650821}]}]}
{"op":"mcm","clk":"11967714131","pt":1724661914272,"mc":[{"id":"1.232283714","rc":[{"batb":[[0,1.71,4]],"ltp":1.74,"tv":104.0,"id":47650821}]}]}
{"op":"mcm","clk":"11967714227","pt":1724661916792,"mc":[{"id":"1.232283714","rc":[{"batb":[[0,1.71,5]],"ltp":1.74,"tv":104.0,"id":47650821}]}]}
{"op":"mcm","clk":"11967714362","pt":1724661920085,"mc":[{"id":"1.232283714","rc":[{"batb":[[0,1.72,4]],"ltp":1.74,"tv":104.0,"id":47650821}]}]}
{"op":"mcm","clk":"11967714467","pt":1724661922290,"mc":[{"id":"1.232283714","rc":[{"batb":[[0,1.71,5]],"ltp":1.74,"tv":104.0,"id":47650821}]}]}
{"op":"mcm","clk":"11967714543","pt":1724661924393,"mc":[{"id":"1.232283714","rc":[{"batb":[[0,1.72,4],[1,1.71,5],[2,1.7,54.92]],"ltp":1.74,"tv":104.0,"id":47650821}]}]}
{"op":"mcm","clk":"11967714590","pt":1724661925486,"mc":[{"id":"1.232283714","rc":[{"batb":[[1,1.7,54.92],[2,1.51,750.28]],"ltp":1.74,"tv":104.0,"id":47650821}]}]}
{"op":"mcm","clk":"11967714639","pt":1724661926607,"mc":[{"id":"1.232283714","rc":[{"trd":[[1.72,8]],"batb":[[0,1.7,54.92],[1,1.51,750.28],[2,1.4,6.58]],"batl":[[0,1.72,55],[1,4.5,3.98]],"ltp":1.72,"tv":112.0,"id":47650821}],"tv":113.02}]}
{"op":"mcm","clk":"11967714804","pt":1724661930307,"mc":[{"id":"1.232283714","rc":[{"trd":[[1.7,110]],"batb":[[0,1.71,8.92]],"batl":[[0,4.5,3.98],[1,4.5,0]],"ltp":1.7,"tv":222.0,"id":47650821}],"tv":223.02}]}
{"op":"mcm","clk":"11967714928","pt":1724661933493,"mc":[{"id":"1.232283714","rc":[{"batb":[[0,1.51,750.28],[1,1.4,6.58],[2,1.05,5.19]],"ltp":1.7,"tv":222.0,"id":47650821}]}]}
{"op":"mcm","clk":"11967714938","pt":1724661933695,"mc":[{"id":"1.232283714","rc":[{"batb":[[0,1.53,55.96],[1,1.51,750.28],[2,1.4,6.58]],"ltp":1.7,"tv":222.0,"id":47650821}]}]}
{"op":"mcm","clk":"11967715001","pt":1724661934879,"mc":[{"id":"1.232283714","rc":[{"batb":[[0,1.54,4],[1,1.53,55.96],[2,1.51,750.28]],"ltp":1.7,"tv":222.0,"id":47650821}]}]}
{"op":"mcm","clk":"11967715110","pt":1724661937490,"mc":[{"id":"1.232283714","rc":[{"batb":[[0,1.54,5]],"ltp":1.7,"tv":222.0,"id":47650821}]}]}
{"op":"mcm","clk":"11967715219","pt":1724661939905,"mc":[{"id":"1.232283714","rc":[{"batb":[[0,1.55,4],[1,1.54,5],[2,1.53,55.96]],"ltp":1.7,"tv":222.0,"id":47650821}]}]}
{"op":"mcm","clk":"11967715274","pt":1724661940933,"mc":[{"id":"1.232283714","rc":[{"batb":[[1,1.53,55.96],[2,1.51,750.28]],"ltp":1.7,"tv":222.0,"id":47650821}]}]}
{"op":"mcm","clk":"11967715335","pt":1724661942138,"mc":[{"id":"1.232283714","rc":[{"batb":[[0,1.53,55.96],[1,1.51,750.28],[2,1.4,6.58]],"ltp":1.7,"tv":222.0,"id":47650821}]}]}
{"op":"mcm","clk":"11967715419","pt":1724661943936,"mc":[{"id":"1.232283714","rc":[{"batb":[[0,1.54,5],[1,1.53,55.96],[2,1.51,750.28]],"ltp":1.7,"tv":222.0,"id":47650821}]}]}
{"op":"mcm","clk":"11967715474","pt":1724661945120,"mc":[{"id":"1.232283714","rc":[{"batb":[[0,1.55,4],[1,1.54,5],[2,1.53,55.96]],"ltp":1.7,"tv":222.0,"id":47650821}]}]}
{"op":"mcm","clk":"11967715585","pt":1724661947327,"mc":[{"id":"1.232283714","rc":[{"batb":[[0,1.53,55.96],[1,1.51,750.28],[2,1.4,6.58]],"ltp":1.7,"tv":222.0,"id":47650821}]}]}
{"op":"mcm","clk":"11967715671","pt":1724661949535,"mc":[{"id":"1.232283714","rc":[{"batb":[[0,1.54,9],[1,1.53,55.96],[2,1.51,750.28]],"ltp":1.7,"tv":222.0,"id":47650821}]}]}
{"op":"mcm","clk":"11967715796","pt":1724661951950,"mc":[{"id":"1.232283714","rc":[{"batb":[[0,1.54,5]],"ltp":1.7,"tv":222.0,"id":47650821}]}]}
{"op":"mcm","clk":"11967715835","pt":1724661952824,"mc":[{"id":"1.232283714","rc":[{"batb":[[0,1.53,55.96],[1,1.51,750.28],[2,1.4,6.58]],"ltp":1.7,"tv":222.0,"id":47650821}]}]}
{"op":"mcm","clk":"11967716000","pt":1724661955845,"mc":[{"id":"1.232283714","rc":[{"batb":[[0,1.54,9],[1,1.53,55.96],[2,1.51,750.28]],"ltp":1.7,"tv":222.0,"id":47650821}]}]}
{"op":"mcm","clk":"11967716136","pt":1724661958113,"mc":[{"id":"1.232283714","rc":[{"batb":[[0,1.54,5]],"ltp":1.7,"tv":222.0,"id":47650821}]}]}
{"op":"mcm","clk":"11967716195","pt":1724661959136,"mc":[{"id":"1.232283714","rc":[{"batb":[[0,1.53,55.96],[1,1.51,750.28],[2,1.4,6.58]],"ltp":1.7,"tv":222.0,"id":47650821}]}]}
{"op":"mcm","clk":"11967716296","pt":1724661960935,"mc":[{"id":"1.232283714","rc":[{"batb":[[0,1.54,4],[1,1.53,55.96],[2,1.51,750.28]],"ltp":1.7,"tv":222.0,"id":47650821}]}]}
{"op":"mcm","clk":"11967716394","pt":1724661963255,"mc":[{"id":"1.232283714","rc":[{"batb":[[0,1.55,5]],"ltp":1.7,"tv":222.0,"id":47650821}]}]}
{"op":"mcm","clk":"11967716489","pt":1724661965519,"mc":[{"id":"1.232283714","rc":[{"batb":[[0,1.56,4],[1,1.55,5],[2,1.53,55.96]],"ltp":1.7,"tv":222.0,"id":47650821}]}]}
{"op":"mcm","clk":"11967716504","pt":1724661965721,"mc":[{"id":"1.232283714","rc":[{"batb":[[1,1.53,55.96],[2,1.51,750.28]],"ltp":1.7,"tv":222.0,"id":47650821}]}]}
{"op":"mcm","clk":"11967728063","pt":1724662233772,"mc":[{"id":"1.232283714","rc":[{"batb":[[1,1.51,750.28],[2,1.4,6.58]],"ltp":1.7,"tv":222.0,"id":47650821}]}]}
{"op":"mcm","clk":"11967750518","pt":1724662713468,"mc":[{"id":"1.232283714","rc":[{"batb":[[1,2.18,32.58]],"ltp":2.26,"tv":1.02,"id":7591770}]}]}
{"op":"mcm","clk":"11967765723","pt":1724663041433,"mc":[{"id":"1.232283714","rc":[{"batb":[[2,1.81,750.17]],"ltp":2.26,"tv":1.02,"id":7591770},{"batb":[[1,1.52,17.06],[2,1.51,750.17]],"ltp":1.7,"tv":222.0,"id":47650821}]}]}
{"op":"mcm","clk":"11967779807","pt":1724663336191,"mc":[{"id":"1.232283714","rc":[{"batl":[[0,2.96,16.64]],"ltp":2.26,"tv":1.02,"id":7591770}]}]}
{"op":"mcm","clk":"11967791362","pt":1724663566243,"mc":[{"id":"1.232283714","rc":[{"batb":[[0,2.38,27.85],[1,2.26,15.18]],"ltp":2.26,"tv":1.02,"id":7591770},{"batb":[[0,1.66,58.25],[1,1.56,4],[2,1.52,17.06]],"ltp":1.7,"tv":222.0,"id":47650821}]}]}
{"op":"mcm","clk":"11967791416","pt":1724663567489,"mc":[{"id":"1.232283714","rc":[{"batb":[[2,1.51,750.17]],"ltp":1.7,"tv":222.0,"id":47650821}]}]}
{"op":"mcm","clk":"11967794482","pt":1724663627424,"mc":[{"id":"1.232283714","rc":[{"trd":[[1.66,98]],"batb":[[0,1.66,9.25]],"ltp":1.66,"tv":320.0,"id":47650821}],"tv":321.02}]}
{"op":"mcm","clk":"11967794490","pt":1724663627628,"mc":[{"id":"1.232283714","rc":[{"batb":[[1,1.81,750.17],[2,1.29,7.59]],"ltp":2.26,"tv":1.02,"id":7591770}]}]}
{"op":"mcm","clk":"11967794709","pt":1724663631434,"mc":[{"id":"1.232283714","rc":[{"batb":[[0,1.66,58.25]],"ltp":1.66,"tv":320.0,"id":47650821}]}]}
{"op":"mcm","clk":"11967796045","pt":1724663656503,"mc":[{"id":"1.232283714","rc":[{"trd":[[2.38,27.85]],"batb":[[0,2.18,32.58]],"ltp":2.38,"tv":28.87,"id":7591770},{"trd":[[1.73,38.31]],"batb":[[0,1.78,10.98],[1,1.66,58.25],[2,1.56,4]],"ltp":1.73,"tv":358.31,"id":47650821}],"tv":387.18}]}
{"op":"mcm","clk":"11967796078","pt":1724663656862,"mc":[{"id":"1.232283714","rc":[{"trd":[[1.78,21.5]],"batb":[[0,1.56,4.23],[1,1.51,750.17],[2,1.4,6.58]],"batl":[[0,1.83,37.96],[1,4.5,3.98]],"ltp":1.78,"tv":379.81,"id":47650821}],"tv":408.68}]}
{"op":"mcm","clk":"11967796300","pt":1724663661492,"mc":[{"id":"1.232283714","rc":[{"batb":[[0,2.28,30.03],[1,2.18,32.58],[2,1.81,750.17]],"batl":[[0,2.96,16.58]],"ltp":2.38,"tv":28.87,"id":7591770},{"batb":[[0,1.71,54.37],[1,1.56,4],[2,1.52,16.58]],"ltp":1.78,"tv":379.81,"id":47650821}]}]}
{"op":"mcm","clk":"11967796305","pt":1724663661594,"mc":[{"id":"1.232283714","rc":[{"batb":[[1,1.81,750.17],[2,1.29,7.59]],"ltp":2.38,"tv":28.87,"id":7591770},{"batb":[[0,1.71,54.14]],"ltp":1.78,"tv":379.81,"id":47650821}]}]}
{"op":"mcm","clk":"11967796410","pt":1724663664164,"mc":[{"id":"1.232283714","rc":[{"batb":[[2,1.51,750.17]],"ltp":1.78,"tv":379.81,"id":47650821}]}]}
{"op":"mcm","clk":"11967811703","pt":1724663957125,"mc":[{"id":"1.232283714","rc":[{"batb":[[0,2.28,60.5]],"ltp":2.38,"tv":28.87,"id":7591770},{"batl":[[0,4.5,3.98],[1,4.5,0]],"ltp":1.78,"tv":379.81,"id":47650821}]}]}
{"op":"mcm","clk":"11967814357","pt":1724664007687,"mc":[{"id":"1.232283714","rc":[{"batb":[[0,2.34,28.69],[1,2.28,30.47],[2,1.81,750.17]],"ltp":2.38,"tv":28.87,"id":7591770},{"batb":[[0,1.68,56.53]],"ltp":1.78,"tv":379.81,"id":47650821}]}]}
{"op":"mcm","clk":"11967816383","pt":1724664046445,"mc":[{"id":"1.232283714","rc":[{"batb":[[1,1.81,750.17],[2,1.29,7.59]],"ltp":2.38,"tv":28.87,"id":7591770},{"batl":[[0,1.74,1.5],[1,4.5,3.98]],"ltp":1.78,"tv":379.81,"id":47650821}]}]}
{"op":"mcm","clk":"11967842768","pt":1724664568121,"mc":[{"id":"1.232283714","rc":[{"trd":[[1.68,112]],"batb":[[0,1.56,4.53],[1,1.51,750.17],[2,1.4,6.58]],"ltp":1.68,"tv":491.81,"id":47650821}],"tv":520.68}]}
{"op":"mcm","clk":"11967842836","pt":1724664569660,"mc":[{"id":"1.232283714","rc":[{"batb":[[0,1.64,9.97],[1,1.56,4],[2,1.51,750.17]],"ltp":1.68,"tv":491.81,"id":47650821}]}]}
{"op":"mcm","clk":"11967849480","pt":1724664696001,"mc":[{"id":"1.232283714","rc":[{"trd":[[1.64,8]],"batb":[[0,1.64,5.97]],"ltp":1.64,"tv":499.81,"id":47650821}],"tv":528.68}]}
{"op":"mcm","clk":"11967849678","pt":1724664700094,"mc":[{"id":"1.232283714","rc":[{"batb":[[0,1.64,6.18]],"ltp":1.64,"tv":499.81,"id":47650821}]}]}
{"op":"mcm","clk":"11967850138","pt":1724664708717,"mc":[{"id":"1.232283714","rc":[{"batl":[[0,2.96,16.8]],"ltp":2.38,"tv":28.87,"id":7591770}]}]}
{"op":"mcm","clk":"11967933527","pt":1724665909327,"mc":[{"id":"1.232283714","marketDefinition":{"bspMarket":false,"turnInPlayEnabled":true,"persistenceEnabled":true,"marketBaseRate":5.0,"eventId":"33527093","eventTypeId":"4","numberOfWinners":1,"bettingType":"ODDS","marketType":"MATCH_ODDS","marketTime":"2024-08-26T23:00:00.000Z","suspendTime":"2024-08-26T23:00:00.000Z","bspReconciled":false,"complete":true,"inPlay":false,"crossMatching":true,"runnersVoidable":false,"numberOfActiveRunners":2,"betDelay":0,"status":"SUSPENDED","runners":[{"status":"ACTIVE","sortPriority":1,"id":7591770,"name":"Guyana Amazon Warriors"},{"status":"ACTIVE","sortPriority":2,"id":47650821,"name":"Barbados Royals Women"}],"regulators":["MR_INT"],"countryCode":"GB","discountAllowed":true,"timezone":"GMT","openDate":"2024-08-26T23:00:00.000Z","version":6101154884,"name":"Match Odds","eventName":"Guyana Amazon Warriors v Barbados Royals Women"},"rc":[{"batb":[[0,1.81,750.17],[1,1.29,7.59],[2,1.28,178.57]],"ltp":2.38,"tv":28.87,"id":7591770},{"batb":[[0,1.56,4],[1,1.51,750.17],[2,1.4,6.58]],"ltp":1.64,"tv":499.81,"id":47650821}]}]}
{"op":"mcm","clk":"11967977268","pt":1724666465916,"mc":[{"id":"1.232283714","marketDefinition":{"bspMarket":false,"turnInPlayEnabled":true,"persistenceEnabled":true,"marketBaseRate":5.0,"eventId":"33527093","eventTypeId":"4","numberOfWinners":1,"bettingType":"ODDS","marketType":"MATCH_ODDS","marketTime":"2024-08-26T23:00:00.000Z","suspendTime":"2024-08-26T23:00:00.000Z","bspReconciled":false,"complete":true,"inPlay":false,"crossMatching":false,"runnersVoidable":false,"numberOfActiveRunners":2,"betDelay":0,"status":"SUSPENDED","runners":[{"status":"ACTIVE","sortPriority":1,"id":7591770,"name":"Guyana Amazon Warriors"},{"status":"ACTIVE","sortPriority":2,"id":47650821,"name":"Barbados Royals Women"}],"regulators":["MR_INT"],"countryCode":"GB","discountAllowed":true,"timezone":"GMT","openDate":"2024-08-26T23:00:00.000Z","version":6101167112,"name":"Match Odds","eventName":"Guyana Amazon Warriors v Barbados Royals Women"},"tv":0.0}]}
{"op":"mcm","clk":"11967977338","pt":1724666466918,"mc":[{"id":"1.232283714","marketDefinition":{"bspMarket":false,"turnInPlayEnabled":true,"persistenceEnabled":true,"marketBaseRate":5.0,"eventId":"33527093","eventTypeId":"4","numberOfWinners":1,"bettingType":"ODDS","marketType":"MATCH_ODDS","marketTime":"2024-08-26T23:00:00.000Z","suspendTime":"2024-08-26T23:00:00.000Z","bspReconciled":false,"complete":true,"inPlay":false,"crossMatching":false,"runnersVoidable":false,"numberOfActiveRunners":0,"betDelay":0,"status":"CLOSED","settledTime":"2024-08-26T10:01:05.000Z","runners":[{"status":"REMOVED","sortPriority":1,"removalDate":"2024-08-26T10:01:05.000Z","id":7591770,"name":"Guyana Amazon Warriors"},{"status":"REMOVED","sortPriority":2,"removalDate":"2024-08-26T10:01:05.000Z","id":47650821,"name":"Barbados Royals Women"}],"regulators":["MR_INT"],"countryCode":"GB","discountAllowed":true,"timezone":"GMT","openDate":"2024-08-26T23:00:00.000Z","version":6101167130,"name":"Match Odds","eventName":"Guyana Amazon Warriors v Barbados Royals Women"}}]}
