{"op":"mcm","clk":"11817269021","pt":1723375073188,"mc":[{"id":"1.231699634","marketDefinition":{"bspMarket":false,"turnInPlayEnabled":true,"persistenceEnabled":true,"marketBaseRate":5.0,"eventId":"33486039","eventTypeId":"4","numberOfWinners":1,"bettingType":"ODDS","marketType":"MATCH_ODDS","marketTime":"2024-08-14T10:00:00.000Z","suspendTime":"2024-08-14T10:00:00.000Z","bspReconciled":false,"complete":true,"inPlay":false,"crossMatching":false,"runnersVoidable":false,"numberOfActiveRunners":2,"betDelay":0,"status":"OPEN","runners":[{"status":"ACTIVE","sortPriority":1,"id":424679,"name":"Lancashire"},{"status":"ACTIVE","sortPriority":2,"id":31372,"name":"Worcestershire"}],"regulators":["MR_INT"],"countryCode":"GB","discountAllowed":false,"timezone":"GMT","openDate":"2024-08-14T10:00:00.000Z","version":6069158106,"name":"Match Odds","eventName":"Lancashire v Worcestershire"},"rc":[{"batb":[[0,1.03,200],[1,1.02,200],[2,1.01,220]],"ltp":0.0,"tv":0.0,"id":424679},{"batb":[[0,1.03,200],[1,1.02,200],[2,1.01,220]],"ltp":0.0,"tv":0.0,"id":31372}]}]}
{"op":"mcm","clk":"11817269167","pt":1723375074359,"mc":[{"id":"1.231699634","marketDefinition":{"bspMarket":false,"turnInPlayEnabled":true,"persistenceEnabled":true,"marketBaseRate":5.0,"eventId":"33486039","eventTypeId":"4","numberOfWinners":1,"bettingType":"ODDS","marketType":"MATCH_ODDS","marketTime":"2024-08-14T10:00:00.000Z","suspendTime":"2024-08-14T10:00:00.000Z","bspReconciled":false,"complete":true,"inPlay":false,"crossMatching":false,"runnersVoidable":false,"numberOfActiveRunners":2,"betDelay":0,"status":"OPEN","runners":[{"status":"ACTIVE","sortPriority":1,"id":424679,"name":"Lancashire"},{"status":"ACTIVE","sortPriority":2,"id":31372,"name":"Worcestershire"}],"regulators":["MR_INT"],"countryCode":"GB","discountAllowed":true,"timezone":"GMT","openDate":"2024-08-14T10:00:00.000Z","version":6069158106,"name":"Match Odds","eventName":"Lancashire v Worcestershire"}}]}
{"op":"mcm","clk":"11818446942","pt":1723384861088,"mc":[{"id":"1.231699634","rc":[{"batb":[[2,1.01,480.71]],"ltp":0.0,"tv":0.0,"id":424679}]}]}
{"op":"mcm","clk":"11818446977","pt":1723384861368,"mc":[{"id":"1.231699634","rc":[{"batb":[[2,1.01,480.71]],"ltp":0.0,"tv":0.0,"id":31372}]}]}
{"op":"mcm","clk":"11818852159","pt":1723387405684,"mc":[{"id":"1.231699634","rc":[{"batb":[[2,1.01,488.56]],"ltp":0.0,"tv":0.0,"id":424679},{"batb":[[2,1.01,488.56]],"ltp":0.0,"tv":0.0,"id":31372}]}]}
{"op":"mcm","clk":"11818853622","pt":1723387414828,"mc":[{"id":"1.231699634","marketDefinition":{"bspMarket":false,"turnInPlayEnabled":true,"persistenceEnabled":true,"marketBaseRate":5.0,"eventId":"33486039","eventTypeId":"4","numberOfWinners":1,"bettingType":"ODDS","marketType":"MATCH_ODDS","marketTime":"2024-08-14T10:00:00.000Z","suspendTime":"2024-08-14T10:00:00.000Z","bspReconciled":false,"complete":true,"inPlay":false,"crossMatching":true,"runnersVoidable":false,"numberOfActiveRunners":2,"betDelay":0,"status":"OPEN","runners":[{"status":"ACTIVE","sortPriority":1,"id":424679,"name":"Lancashire"},{"status":"ACTIVE","sortPriority":2,"id":31372,"name":"Worcestershire"}],"regulators":["MR_INT"],"countryCode":"GB","discountAllowed":true,"timezone":"GMT","openDate":"2024-08-14T10:00:00.000Z","version":6069158106,"name":"Match Odds","eventName":"Lancashire v Worcestershire"}}]}
{"op":"mcm","clk":"11818853878","pt":1723387416488,"mc":[{"id":"1.231699634","rc":[{"batb":[[1,1.02,207.85]],"ltp":0.0,"tv":0.0,"id":424679},{"batb":[[1,1.02,207.85]],"ltp":0.0,"tv":0.0,"id":31372}]}]}
{"op":"mcm","clk":"11818855751","pt":1723387429005,"mc":[{"id":"1.231699634","rc":[{"batb":[[1,1.02,247.13]],"ltp":0.0,"tv":0.0,"id":424679},{"batb":[[1,1.02,247.13]],"ltp":0.0,"tv":0.0,"id":31372}]}]}
{"op":"mcm","clk":"11818858325","pt":1723387446422,"mc":[{"id":"1.231699634","rc":[{"batb":[[0,1.03,207.85]],"ltp":0.0,"tv":0.0,"id":424679},{"batb":[[0,1.03,207.85]],"ltp":0.0,"tv":0.0,"id":31372}]}]}
{"op":"mcm","clk":"11818860457","pt":1723387460749,"mc":[{"id":"1.231699634","rc":[{"batb":[[0,1.04,7.85],[1,1.03,207.85],[2,1.02,247.13]],"ltp":0.0,"tv":0.0,"id":424679},{"batb":[[0,1.04,7.85],[1,1.03,207.85],[2,1.02,247.13]],"ltp":0.0,"tv":0.0,"id":31372}]}]}
{"op":"mcm","clk":"11818862691","pt":1723387475382,"mc":[{"id":"1.231699634","rc":[{"batb":[[0,1.05,7.85],[1,1.04,7.85],[2,1.03,207.85]],"ltp":0.0,"tv":0.0,"id":424679},{"batb":[[0,1.05,7.85],[1,1.04,7.85],[2,1.03,207.85]],"ltp":0.0,"tv":0.0,"id":31372}]}]}
{"op":"mcm","clk":"11818864866","pt":1723387489356,"mc":[{"id":"1.231699634","rc":[{"batb":[[0,1.06,7.85],[1,1.05,7.85],[2,1.04,7.85]],"ltp":0.0,"tv":0.0,"id":424679},{"batb":[[0,1.06,7.85],[1,1.05,7.85],[2,1.04,7.85]],"ltp":0.0,"tv":0.0,"id":31372}]}]}
{"op":"mcm","clk":"11818866968","pt":1723387501713,"mc":[{"id":"1.231699634","rc":[{"batb":[[0,1.07,7.85],[1,1.06,7.85],[2,1.05,7.85]],"ltp":0.0,"tv":0.0,"id":424679},{"batb":[[0,1.07,7.85],[1,1.06,7.85],[2,1.05,7.85]],"ltp":0.0,"tv":0.0,"id":31372}]}]}
{"op":"mcm","clk":"11818869723","pt":1723387516292,"mc":[{"id":"1.231699634","rc":[{"batb":[[0,1.08,7.85],[1,1.07,7.85],[2,1.06,7.85]],"ltp":0.0,"tv":0.0,"id":424679},{"batb":[[0,1.08,7.85],[1,1.07,7.85],[2,1.06,7.85]],"ltp":0.0,"tv":0.0,"id":31372}]}]}
{"op":"mcm","clk":"11819520121","pt":1723392490701,"mc":[{"id":"1.231699634","rc":[{"batb":[[0,1.09,95.53],[1,1.08,7.85],[2,1.07,7.85]],"ltp":0.0,"tv":0.0,"id":424679},{"batb":[[0,1.09,95.53],[1,1.08,7.85],[2,1.07,7.85]],"ltp":0.0,"tv":0.0,"id":31372}]}]}
{"op":"mcm","clk":"11819780464","pt":1723394291265,"mc":[{"id":"1.231699634","rc":[{"batb":[[0,1.08,7.85],[1,1.07,7.85],[2,1.06,7.85]],"ltp":0.0,"tv":0.0,"id":424679},{"batb":[[0,1.08,7.85],[1,1.07,7.85],[2,1.06,7.85]],"ltp":0.0,"tv":0.0,"id":31372}]}]}
{"op":"mcm","clk":"11819788540","pt":1723394343446,"mc":[{"id":"1.231699634","rc":[{"batb":[[0,1.09,95.53],[1,1.08,7.85],[2,1.07,7.85]],"ltp":0.0,"tv":0.0,"id":424679},{"batb":[[0,1.09,95.53],[1,1.08,7.85],[2,1.07,7.85]],"ltp":0.0,"tv":0.0,"id":31372}]}]}
{"op":"mcm","clk":"11820064912","pt":1723396144093,"mc":[{"id":"1.231699634","rc":[{"batb":[[0,1.08,7.85],[1,1.07,7.85],[2,1.06,7.85]],"ltp":0.0,"tv":0.0,"id":424679}]}]}
{"op":"mcm","clk":"11820064952","pt":1723396144355,"mc":[{"id":"1.231699634","rc":[{"batb":[[0,1.08,7.85],[1,1.07,7.85],[2,1.06,7.85]],"ltp":0.0,"tv":0.0,"id":31372}]}]}
{"op":"mcm","clk":"11820070870","pt":1723396177918,"mc":[{"id":"1.231699634","rc":[{"batb":[[0,1.09,95.53],[1,1.08,7.85],[2,1.07,7.85]],"ltp":0.0,"tv":0.0,"id":424679},{"batb":[[0,1.09,95.53],[1,1.08,7.85],[2,1.07,7.85]],"ltp":0.0,"tv":0.0,"id":31372}]}]}
{"op":"mcm","clk":"11820331018","pt":1723397762334,"mc":[{"id":"1.231699634","rc":[{"batb":[[0,1.25,100],[1,1.09,95.53],[2,1.08,7.85]],"ltp":0.0,"tv":0.0,"id":424679},{"batb":[[0,1.25,100],[1,1.09,95.53],[2,1.08,7.85]],"ltp":0.0,"tv":0.0,"id":31372}]}]}
{"op":"mcm","clk":"11820366089","pt":1723397978727,"mc":[{"id":"1.231699634","rc":[{"batb":[[1,1.08,7.85],[2,1.07,7.85]],"ltp":0.0,"tv":0.0,"id":424679},{"batb":[[0,1.44,275],[1,1.25,100]],"ltp":0.0,"tv":0.0,"id":31372}]}]}
{"op":"mcm","clk":"11820379913","pt":1723398056365,"mc":[{"id":"1.231699634","rc":[{"batb":[[0,1.26,33.07],[1,1.25,100],[2,1.08,7.85]],"ltp":0.0,"tv":0.0,"id":424679},{"batb":[[0,1.45,19.11],[1,1.44,275],[2,1.25,100]],"ltp":0.0,"tv":0.0,"id":31372}]}]}
{"op":"mcm","clk":"11820419147","pt":1723398222242,"mc":[{"id":"1.231699634","rc":[{"batb":[[1,1.25,100],[2,1.08,7.85]],"ltp":0.0,"tv":0.0,"id":31372}]}]}
{"op":"mcm","clk":"11820419162","pt":1723398222347,"mc":[{"id":"1.231699634","rc":[{"batb":[[0,1.49,275],[1,1.45,19.11],[2,1.25,100]],"ltp":0.0,"tv":0.0,"id":31372}]}]}
{"op":"mcm","clk":"11820463538","pt":1723398497019,"mc":[{"id":"1.231699634","rc":[{"batb":[[0,1.27,6.95],[1,1.26,33.07],[2,1.25,100]],"ltp":0.0,"tv":0.0,"id":424679},{"batb":[[0,1.5,7.05],[1,1.49,275],[2,1.45,19.11]],"ltp":0.0,"tv":0.0,"id":31372}]}]}
{"op":"mcm","clk":"11820497514","pt":1723398755340,"mc":[{"id":"1.231699634","rc":[{"batb":[[1,1.45,19.11],[2,1.25,100]],"ltp":0.0,"tv":0.0,"id":31372}]}]}
{"op":"mcm","clk":"11820497533","pt":1723398755454,"mc":[{"id":"1.231699634","rc":[{"batb":[[0,1.51,275],[1,1.5,7.05],[2,1.45,19.11]],"ltp":0.0,"tv":0.0,"id":31372}]}]}
{"op":"mcm","clk":"11820504121","pt":1723398814374,"mc":[{"id":"1.231699634","rc":[{"batb":[[0,2.42,2.83],[1,1.27,6.95],[2,1.26,33.07]],"ltp":0.0,"tv":0.0,"id":424679},{"batb":[[0,1.65,6.19],[1,1.51,275],[2,1.5,7.05]],"ltp":0.0,"tv":0.0,"id":31372}]}]}
{"op":"mcm","clk":"11820506667","pt":1723398836428,"mc":[{"id":"1.231699634","rc":[{"trd":[[2.42,5.66]],"batb":[[0,1.27,6.95],[1,1.26,33.07],[2,1.25,100]],"batl":[[0,2.42,63.17]],"ltp":2.42,"tv":5.66,"id":424679}],"tv":5.66}]}
{"op":"mcm","clk":"11820507053","pt":1723398839453,"mc":[{"id":"1.231699634","rc":[{"batb":[[0,2.34,3],[1,1.27,6.95],[2,1.26,33.07]],"ltp":2.42,"tv":5.66,"id":424679}]}]}
{"op":"mcm","clk":"11820508468","pt":1723398850239,"mc":[{"id":"1.231699634","rc":[{"trd":[[2.34,6]],"batb":[[0,1.27,6.95],[1,1.26,33.07],[2,1.25,100]],"batl":[[0,2.34,3],[1,2.42,63.17]],"ltp":2.34,"tv":11.66,"id":424679}],"tv":11.66}]}
{"op":"mcm","clk":"11820509013","pt":1723398854435,"mc":[{"id":"1.231699634","rc":[{"batb":[[0,2.26,3.19],[1,1.27,6.95],[2,1.26,33.07]],"ltp":2.34,"tv":11.66,"id":424679}]}]}
{"op":"mcm","clk":"11820509348","pt":1723398857491,"mc":[{"id":"1.231699634","rc":[{"batl":[[0,2.42,63.17],[1,2.42,0]],"ltp":2.34,"tv":11.66,"id":424679}]}]}
{"op":"mcm","clk":"11820511051","pt":1723398869678,"mc":[{"id":"1.231699634","rc":[{"trd":[[2.26,6.38]],"batb":[[0,1.27,6.95],[1,1.26,33.07],[2,1.25,100]],"batl":[[0,2.26,1.81],[1,2.42,63.17]],"ltp":2.26,"tv":18.04,"id":424679}],"tv":18.04}]}
{"op":"mcm","clk":"11820511717","pt":1723398874563,"mc":[{"id":"1.231699634","rc":[{"batb":[[0,2.18,3.41],[1,1.27,6.95],[2,1.26,33.07]],"ltp":2.26,"tv":18.04,"id":424679}]}]}
{"op":"mcm","clk":"11820511956","pt":1723398877069,"mc":[{"id":"1.231699634","rc":[{"batl":[[0,2.42,63.17],[1,2.42,0]],"ltp":2.26,"tv":18.04,"id":424679}]}]}
{"op":"mcm","clk":"11820513026","pt":1723398886491,"mc":[{"id":"1.231699634","rc":[{"trd":[[2.18,6.82]],"batb":[[0,1.27,6.95],[1,1.26,33.07],[2,1.25,100]],"batl":[[0,2.18,3.59],[1,2.42,63.17]],"ltp":2.18,"tv":24.86,"id":424679}],"tv":24.86}]}
{"op":"mcm","clk":"11820513384","pt":1723398889624,"mc":[{"id":"1.231699634","rc":[{"batb":[[0,2.1,2],[1,1.27,6.95],[2,1.26,33.07]],"ltp":2.18,"tv":24.86,"id":424679}]}]}
{"op":"mcm","clk":"11820513481","pt":1723398890396,"mc":[{"id":"1.231699634","rc":[{"batl":[[0,2.42,63.17],[1,2.42,0]],"ltp":2.18,"tv":24.86,"id":424679}]}]}
{"op":"mcm","clk":"11820526464","pt":1723398993376,"mc":[{"id":"1.231699634","rc":[{"batb":[[1,1.5,7.05],[2,1.45,19.11]],"ltp":0.0,"tv":0.0,"id":31372}]}]}
{"op":"mcm","clk":"11820529324","pt":1723399016933,"mc":[{"id":"1.231699634","rc":[{"batb":[[0,1.67,89],[1,1.65,6.19],[2,1.5,7.05]],"ltp":0.0,"tv":0.0,"id":31372}]}]}
{"op":"mcm","clk":"11820653840","pt":1723399857809,"mc":[{"id":"1.231699634","rc":[{"batb":[[2,1.25,100]],"ltp":2.18,"tv":24.86,"id":424679}]}]}
{"op":"mcm","clk":"11820765116","pt":1723400542633,"mc":[{"id":"1.231699634","rc":[{"batb":[[0,1.68,4.37],[1,1.67,89],[2,1.65,6.19]],"ltp":0.0,"tv":0.0,"id":31372}]}]}
{"op":"mcm","clk":"11820777562","pt":1723400620019,"mc":[{"id":"1.231699634","rc":[{"batb":[[1,1.26,6.95]],"ltp":2.18,"tv":24.86,"id":424679}]}]}
{"op":"mcm","clk":"11820908817","pt":1723401442559,"mc":[{"id":"1.231699634","rc":[{"batb":[[0,1.68,93.37],[1,1.65,6.19],[2,1.25,100]],"ltp":0.0,"tv":0.0,"id":31372}]}]}
{"op":"mcm","clk":"11821104526","pt":1723402813900,"mc":[{"id":"1.231699634","rc":[{"batb":[[1,1.25,100],[2,1.08,7.85]],"ltp":2.18,"tv":24.86,"id":424679}]}]}
{"op":"mcm","clk":"11822027036","pt":1723408974832,"mc":[{"id":"1.231699634","rc":[{"batb":[[2,1.08,7.84]],"ltp":2.18,"tv":24.86,"id":424679},{"batb":[[0,1.68,93.36]],"ltp":0.0,"tv":0.0,"id":31372}]}]}
{"op":"mcm","clk":"11822218494","pt":1723411118011,"mc":[{"id":"1.231699634","rc":[{"batb":[[2,1.08,7.83]],"ltp":2.18,"tv":24.86,"id":424679},{"batb":[[0,1.68,93.36]],"ltp":0.0,"tv":0.0,"id":31372}]}]}
{"op":"mcm","clk":"11822377246","pt":1723413635813,"mc":[{"id":"1.231699634","rc":[{"batb":[[2,1.08,7.84]],"ltp":2.18,"tv":24.86,"id":424679},{"batb":[[0,1.68,4.36]],"ltp":0.0,"tv":0.0,"id":31372}]}]}
{"op":"mcm","clk":"11822377318","pt":1723413637926,"mc":[{"id":"1.231699634","rc":[{"batb":[[0,1.65,6.19],[1,1.25,100],[2,1.08,7.84]],"ltp":0.0,"tv":0.0,"id":31372}]}]}
{"op":"mcm","clk":"11822720593","pt":1723419774831,"mc":[{"id":"1.231699634","rc":[{"batb":[[2,1.08,7.84]],"ltp":2.18,"tv":24.86,"id":424679},{"batb":[[2,1.08,7.84]],"ltp":0.0,"tv":0.0,"id":31372}]}]}
{"op":"mcm","clk":"11822934767","pt":1723425174858,"mc":[{"id":"1.231699634","rc":[{"batb":[[2,1.08,7.84]],"ltp":2.18,"tv":24.86,"id":424679},{"batb":[[2,1.08,7.84]],"ltp":0.0,"tv":0.0,"id":31372}]}]}
{"op":"mcm","clk":"11823079284","pt":1723430574852,"mc":[{"id":"1.231699634","rc":[{"batb":[[2,1.08,7.84]],"ltp":2.18,"tv":24.86,"id":424679},{"batb":[[2,1.08,7.84]],"ltp":0.0,"tv":0.0,"id":31372}]}]}
{"op":"mcm","clk":"11823160786","pt":1723435974860,"mc":[{"id":"1.231699634","rc":[{"batb":[[2,1.08,7.84]],"ltp":2.18,"tv":24.86,"id":424679},{"batb":[[2,1.08,7.84]],"ltp":0.0,"tv":0.0,"id":31372}]}]}
{"op":"mcm","clk":"11823280629","pt":1723441374855,"mc":[{"id":"1.231699634","rc":[{"batb":[[2,1.08,7.84]],"ltp":2.18,"tv":24.86,"id":424679},{"batb":[[2,1.08,7.84]],"ltp":0.0,"tv":0.0,"id":31372}]}]}
{"op":"mcm","clk":"11823342487","pt":1723443601519,"mc":[{"id":"1.231699634","rc":[{"batb":[[0,2.52,1.57],[1,2.1,2],[2,1.25,100]],"ltp":2.18,"tv":24.86,"id":424679},{"batb":[[2,1.08,7.83]],"ltp":0.0,"tv":0.0,"id":31372}]}]}
{"op":"mcm","clk":"11823342942","pt":1723443614426,"mc":[{"id":"1.231699634","rc":[{"batb":[[0,2.1,2],[1,1.25,100],[2,1.08,7.83]],"ltp":2.18,"tv":24.86,"id":424679}]}]}
{"op":"mcm","clk":"11823432822","pt":1723446774872,"mc":[{"id":"1.231699634","rc":[{"batb":[[2,1.08,7.83]],"ltp":2.18,"tv":24.86,"id":424679},{"batb":[[2,1.08,7.83]],"ltp":0.0,"tv":0.0,"id":31372}]}]}
{"op":"mcm","clk":"11823864257","pt":1723456101746,"mc":[{"id":"1.231699634","rc":[{"batb":[[0,1.25,100],[1,1.08,7.83],[2,1.07,7.83]],"ltp":2.18,"tv":24.86,"id":424679},{"batb":[[0,1.25,100],[1,1.08,7.83],[2,1.07,7.83]],"ltp":0.0,"tv":0.0,"id":31372}]}]}
{"op":"mcm","clk":"11823864624","pt":1723456102545,"mc":[{"id":"1.231699634","rc":[{"batb":[[0,1.53,152.81],[1,1.25,100],[2,1.08,7.83]],"ltp":2.18,"tv":24.86,"id":424679},{"batb":[[0,1.26,202.27],[1,1.25,100],[2,1.08,7.83]],"ltp":0.0,"tv":0.0,"id":31372}]}]}
{"op":"mcm","clk":"11823868850","pt":1723456172787,"mc":[{"id":"1.231699634","rc":[{"batb":[[0,1.54,15.92],[1,1.53,152.81],[2,1.25,100]],"ltp":2.18,"tv":24.86,"id":424679},{"batb":[[0,1.27,31.85],[1,1.26,202.27],[2,1.25,100]],"ltp":0.0,"tv":0.0,"id":31372}]}]}
{"op":"mcm","clk":"11823909816","pt":1723456903310,"mc":[{"id":"1.231699634","rc":[{"batb":[[0,1.59,146.97],[1,1.54,23.44]],"ltp":2.18,"tv":24.86,"id":424679},{"batb":[[0,1.27,31.87],[1,1.25,100],[2,1.08,7.84]],"ltp":0.0,"tv":0.0,"id":31372}]}]}
{"op":"mcm","clk":"11823909842","pt":1723456903719,"mc":[{"id":"1.231699634","rc":[{"batb":[[1,1.54,15.94]],"ltp":2.18,"tv":24.86,"id":424679},{"batb":[[0,1.29,197.5],[1,1.27,31.87],[2,1.25,100]],"ltp":0.0,"tv":0.0,"id":31372}]}]}
{"op":"mcm","clk":"11823915599","pt":1723456988977,"mc":[{"id":"1.231699634","rc":[{"batb":[[0,1.6,6.29],[1,1.59,146.97],[2,1.54,15.94]],"ltp":2.18,"tv":24.86,"id":424679},{"batb":[[0,1.3,7.34],[1,1.29,197.5],[2,1.27,31.87]],"ltp":0.0,"tv":0.0,"id":31372}]}]}
{"op":"mcm","clk":"11823919875","pt":1723457044335,"mc":[{"id":"1.231699634","rc":[{"batb":[[1,1.54,15.94],[2,1.25,100]],"ltp":2.18,"tv":24.86,"id":424679},{"batb":[[1,1.27,31.87],[2,1.25,100]],"batl":[[0,2.46,80.61]],"ltp":0.0,"tv":0.0,"id":31372}]}]}
{"op":"mcm","clk":"11823919896","pt":1723457044543,"mc":[{"id":"1.231699634","rc":[{"batb":[[0,1.31,194.43],[1,1.3,7.34],[2,1.27,31.87]],"batl":[[0,2.44,95.69],[1,2.46,80.61]],"ltp":0.0,"tv":0.0,"id":31372}]}]}
{"op":"mcm","clk":"11823950444","pt":1723457464760,"mc":[{"id":"1.231699634","rc":[{"batb":[[0,2.42,28.6],[1,1.6,6.29],[2,1.54,15.94]],"ltp":2.18,"tv":24.86,"id":424679},{"batb":[[0,1.65,62.5],[1,1.31,194.43],[2,1.3,7.34]],"ltp":0.0,"tv":0.0,"id":31372}]}]}
{"op":"mcm","clk":"11823992570","pt":1723457975035,"mc":[{"id":"1.231699634","rc":[{"batb":[[2,1.25,100]],"ltp":2.18,"tv":24.86,"id":424679},{"batb":[[1,1.3,7.34],[2,1.25,100]],"batl":[[0,2.46,80.61],[1,2.46,0]],"ltp":0.0,"tv":0.0,"id":31372}]}]}
{"op":"mcm","clk":"11824031231","pt":1723458659127,"mc":[{"id":"1.231699634","rc":[{"batb":[[1,1.25,100],[2,1.08,7.84]],"ltp":2.18,"tv":24.86,"id":424679}]}]}
{"op":"mcm","clk":"11824031253","pt":1723458659431,"mc":[{"id":"1.231699634","rc":[{"batb":[[1,1.25,100],[2,1.08,7.84]],"ltp":0.0,"tv":0.0,"id":31372}]}]}
{"op":"mcm","clk":"11824133427","pt":1723460591674,"mc":[{"id":"1.231699634","rc":[{"trd":[[1.65,4]],"batb":[[0,1.65,60.5]],"batl":[[0,2.46,80.6]],"ltp":1.65,"tv":4.0,"id":31372}],"tv":28.86}]}
{"op":"mcm","clk":"11824133643","pt":1723460594707,"mc":[{"id":"1.231699634","rc":[{"batb":[[0,1.65,62.5]],"ltp":1.65,"tv":4.0,"id":31372}]}]}
{"op":"mcm","clk":"11824347694","pt":1723464133829,"mc":[{"id":"1.231699634","rc":[{"batb":[[2,1.08,7.83]],"ltp":2.18,"tv":24.86,"id":424679},{"batb":[[0,1.66,52.9],[1,1.65,62.5],[2,1.25,100]],"batl":[[0,2.46,80.54]],"ltp":1.65,"tv":4.0,"id":31372}]}]}
{"op":"mcm","clk":"11824348205","pt":1723464140159,"mc":[{"id":"1.231699634","rc":[{"batb":[[0,1.65,62.5],[1,1.25,100],[2,1.08,7.83]],"ltp":1.65,"tv":4.0,"id":31372}]}]}
{"op":"mcm","clk":"11824352331","pt":1723464196311,"mc":[{"id":"1.231699634","rc":[{"trd":[[2.42,62.78]],"batb":[[0,1.25,100.04],[1,1.08,7.83],[2,1.07,7.83]],"ltp":2.42,"tv":81.98,"id":424679}],"tv":85.98}]}
{"op":"mcm","clk":"11824352348","pt":1723464196617,"mc":[{"id":"1.231699634","rc":[{"batb":[[0,2.34,30.31],[1,1.25,100],[2,1.08,7.83]],"ltp":2.42,"tv":81.98,"id":424679},{"batb":[[0,1.66,10],[1,1.65,62.5],[2,1.25,100]],"batl":[[0,2.44,95.13],[1,2.46,80.54]],"ltp":1.65,"tv":4.0,"id":31372}]}]}
{"op":"mcm","clk":"11824352433","pt":1723464197901,"mc":[{"id":"1.231699634","rc":[{"batb":[[0,1.67,12.88],[1,1.66,10],[2,1.65,62.5]],"ltp":1.65,"tv":4.0,"id":31372}]}]}
{"op":"mcm","clk":"11824352549","pt":1723464199903,"mc":[{"id":"1.231699634","rc":[{"batb":[[1,1.65,62.5],[2,1.25,100]],"ltp":1.65,"tv":4.0,"id":31372}]}]}
{"op":"mcm","clk":"11824352864","pt":1723464204619,"mc":[{"id":"1.231699634","rc":[{"batb":[[0,1.68,10],[1,1.67,12.88],[2,1.65,62.5]],"ltp":1.65,"tv":4.0,"id":31372}]}]}
{"op":"mcm","clk":"11824353104","pt":1723464208015,"mc":[{"id":"1.231699634","rc":[{"batb":[[0,1.67,12.88],[1,1.65,62.5],[2,1.25,100]],"batl":[[0,2.46,80.54],[1,2.46,0]],"ltp":1.65,"tv":4.0,"id":31372}]}]}
{"op":"mcm","clk":"11824353324","pt":1723464211507,"mc":[{"id":"1.231699634","rc":[{"batb":[[0,1.68,10],[1,1.67,12.88],[2,1.65,62.5]],"ltp":1.65,"tv":4.0,"id":31372}]}]}
{"op":"mcm","clk":"11824353529","pt":1723464214726,"mc":[{"id":"1.231699634","rc":[{"batb":[[0,1.67,12.88],[1,1.65,62.5],[2,1.25,100]],"ltp":1.65,"tv":4.0,"id":31372}]}]}
{"op":"mcm","clk":"11824353623","pt":1723464216318,"mc":[{"id":"1.231699634","rc":[{"batb":[[0,1.65,62.5],[1,1.25,100],[2,1.08,7.83]],"ltp":1.65,"tv":4.0,"id":31372}]}]}
{"op":"mcm","clk":"11824353676","pt":1723464217232,"mc":[{"id":"1.231699634","rc":[{"batb":[[0,1.68,10],[1,1.65,62.5],[2,1.25,100]],"ltp":1.65,"tv":4.0,"id":31372}]}]}
{"op":"mcm","clk":"11824353880","pt":1723464220926,"mc":[{"id":"1.231699634","rc":[{"batb":[[0,1.65,62.5],[1,1.25,100],[2,1.08,7.83]],"ltp":1.65,"tv":4.0,"id":31372}]}]}
{"op":"mcm","clk":"11824354135","pt":1723464224834,"mc":[{"id":"1.231699634","rc":[{"batb":[[0,1.66,10],[1,1.65,62.5],[2,1.25,100]],"ltp":1.65,"tv":4.0,"id":31372}]}]}
{"op":"mcm","clk":"11824354353","pt":1723464228225,"mc":[{"id":"1.231699634","rc":[{"batb":[[0,1.65,62.5],[1,1.25,100],[2,1.08,7.83]],"ltp":1.65,"tv":4.0,"id":31372}]}]}
{"op":"mcm","clk":"11824354552","pt":1723464231145,"mc":[{"id":"1.231699634","rc":[{"batb":[[0,1.66,10],[1,1.65,62.5],[2,1.25,100]],"ltp":1.65,"tv":4.0,"id":31372}]}]}
{"op":"mcm","clk":"11824354790","pt":1723464234334,"mc":[{"id":"1.231699634","rc":[{"batb":[[0,1.65,62.5],[1,1.25,100],[2,1.08,7.83]],"ltp":1.65,"tv":4.0,"id":31372}]}]}
{"op":"mcm","clk":"11824355284","pt":1723464241043,"mc":[{"id":"1.231699634","rc":[{"batb":[[0,1.66,10],[1,1.65,62.5],[2,1.25,100]],"ltp":1.65,"tv":4.0,"id":31372}]}]}
{"op":"mcm","clk":"11824355563","pt":1723464244641,"mc":[{"id":"1.231699634","rc":[{"batb":[[0,1.65,62.5],[1,1.25,100],[2,1.08,7.83]],"ltp":1.65,"tv":4.0,"id":31372}]}]}
{"op":"mcm","clk":"11824355820","pt":1723464247863,"mc":[{"id":"1.231699634","rc":[{"batb":[[0,1.66,10],[1,1.65,62.5],[2,1.25,100]],"ltp":1.65,"tv":4.0,"id":31372}]}]}
{"op":"mcm","clk":"11824356079","pt":1723464251360,"mc":[{"id":"1.231699634","rc":[{"batb":[[0,1.65,62.5],[1,1.25,100],[2,1.08,7.83]],"ltp":1.65,"tv":4.0,"id":31372}]}]}
{"op":"mcm","clk":"11824356258","pt":1723464254084,"mc":[{"id":"1.231699634","rc":[{"batb":[[0,1.66,10],[1,1.65,62.5],[2,1.25,100]],"ltp":1.65,"tv":4.0,"id":31372}]}]}
{"op":"mcm","clk":"11824356497","pt":1723464257473,"mc":[{"id":"1.231699634","rc":[{"batb":[[0,1.65,62.5],[1,1.25,100],[2,1.08,7.83]],"ltp":1.65,"tv":4.0,"id":31372}]}]}
{"op":"mcm","clk":"11824356940","pt":1723464263888,"mc":[{"id":"1.231699634","rc":[{"batb":[[0,1.66,10],[1,1.65,62.5],[2,1.25,100]],"ltp":1.65,"tv":4.0,"id":31372}]}]}
{"op":"mcm","clk":"11824357213","pt":1723464268200,"mc":[{"id":"1.231699634","rc":[{"batb":[[0,1.65,62.5],[1,1.25,100],[2,1.08,7.83]],"ltp":1.65,"tv":4.0,"id":31372}]}]}
{"op":"mcm","clk":"11824357330","pt":1723464269897,"mc":[{"id":"1.231699634","rc":[{"trd":[[2.34,65.86]],"batb":[[0,1.25,100.38],[1,1.08,7.83],[2,1.07,7.83]],"ltp":2.34,"tv":141.84,"id":424679},{"batl":[[0,2.44,95.13],[1,2.46,80.54]],"ltp":1.65,"tv":4.0,"id":31372}],"tv":145.84}]}
{"op":"mcm","clk":"11824357411","pt":1723464270784,"mc":[{"id":"1.231699634","rc":[{"batb":[[0,1.69,3.29],[1,1.65,62.5],[2,1.25,100]],"ltp":1.65,"tv":4.0,"id":31372}]}]}
{"op":"mcm","clk":"11824357503","pt":1723464271906,"mc":[{"id":"1.231699634","rc":[{"batb":[[0,1.25,100]],"ltp":2.34,"tv":141.84,"id":424679}]}]}
{"op":"mcm","clk":"11824357543","pt":1723464272477,"mc":[{"id":"1.231699634","rc":[{"batb":[[0,1.7,6.74],[1,1.25,100],[2,1.08,7.83]],"ltp":2.34,"tv":141.84,"id":424679},{"batl":[[0,2.42,4.67],[1,2.44,95.13],[2,2.46,80.54]],"ltp":1.65,"tv":4.0,"id":31372}]}]}
{"op":"mcm","clk":"11824358240","pt":1723464282194,"mc":[{"id":"1.231699634","rc":[{"batb":[[0,1.66,10]],"ltp":1.65,"tv":4.0,"id":31372}]}]}
{"op":"mcm","clk":"11824358550","pt":1723464285889,"mc":[{"id":"1.231699634","rc":[{"batb":[[0,1.65,62.5],[1,1.25,100],[2,1.08,7.83]],"batl":[[0,2.4,96.7],[1,2.42,4.67]],"ltp":1.65,"tv":4.0,"id":31372}]}]}
{"op":"mcm","clk":"11824358663","pt":1723464287322,"mc":[{"id":"1.231699634","rc":[{"batb":[[0,1.25,100],[1,1.08,7.83],[2,1.07,7.83]],"ltp":2.34,"tv":141.84,"id":424679},{"batl":[[1,2.46,80.54],[2,2.46,0]],"ltp":1.65,"tv":4.0,"id":31372}]}]}
{"op":"mcm","clk":"11824358726","pt":1723464287994,"mc":[{"id":"1.231699634","rc":[{"batb":[[0,1.66,10],[1,1.65,62.5],[2,1.25,100]],"ltp":1.65,"tv":4.0,"id":31372}]}]}
{"op":"mcm","clk":"11824359079","pt":1723464293125,"mc":[{"id":"1.231699634","rc":[{"batb":[[0,1.65,62.5],[1,1.25,100],[2,1.08,7.83]],"ltp":1.65,"tv":4.0,"id":31372}]}]}
{"op":"mcm","clk":"11824359262","pt":1723464295796,"mc":[{"id":"1.231699634","rc":[{"batb":[[0,1.66,10],[1,1.65,62.5],[2,1.25,100]],"ltp":1.65,"tv":4.0,"id":31372}]}]}
{"op":"mcm","clk":"11824359492","pt":1723464299334,"mc":[{"id":"1.231699634","rc":[{"batb":[[0,1.65,62.5],[1,1.25,100],[2,1.08,7.83]],"ltp":1.65,"tv":4.0,"id":31372}]}]}
{"op":"mcm","clk":"11824359694","pt":1723464301514,"mc":[{"id":"1.231699634","rc":[{"batb":[[0,1.66,10],[1,1.65,62.5],[2,1.25,100]],"ltp":1.65,"tv":4.0,"id":31372}]}]}
{"op":"mcm","clk":"11824360012","pt":1723464305329,"mc":[{"id":"1.231699634","rc":[{"batb":[[0,1.65,62.5],[1,1.25,100],[2,1.08,7.83]],"batl":[[0,2.32,80.54],[1,2.4,96.7]],"ltp":1.65,"tv":4.0,"id":31372}]}]}
{"op":"mcm","clk":"11824360321","pt":1723464309439,"mc":[{"id":"1.231699634","rc":[{"batb":[[0,1.66,10],[1,1.65,62.5],[2,1.25,100]],"ltp":1.65,"tv":4.0,"id":31372}]}]}
{"op":"mcm","clk":"11824360673","pt":1723464314842,"mc":[{"id":"1.231699634","rc":[{"batb":[[0,1.65,62.5],[1,1.25,100],[2,1.08,7.83]],"ltp":1.65,"tv":4.0,"id":31372}]}]}
{"op":"mcm","clk":"11824360866","pt":1723464318244,"mc":[{"id":"1.231699634","rc":[{"batb":[[0,1.66,10],[1,1.65,62.5],[2,1.25,100]],"ltp":1.65,"tv":4.0,"id":31372}]}]}
{"op":"mcm","clk":"11824360898","pt":1723464318654,"mc":[{"id":"1.231699634","rc":[{"batl":[[0,2.3,85.25],[1,2.32,80.54]],"ltp":1.65,"tv":4.0,"id":31372}]}]}
{"op":"mcm","clk":"11824361077","pt":1723464321676,"mc":[{"id":"1.231699634","rc":[{"batb":[[0,1.65,62.5],[1,1.25,100],[2,1.08,7.83]],"ltp":1.65,"tv":4.0,"id":31372}]}]}
{"op":"mcm","clk":"11824361259","pt":1723464324149,"mc":[{"id":"1.231699634","rc":[{"batb":[[0,1.66,10],[1,1.65,62.5],[2,1.25,100]],"ltp":1.65,"tv":4.0,"id":31372}]}]}
{"op":"mcm","clk":"11824361429","pt":1723464327346,"mc":[{"id":"1.231699634","rc":[{"batb":[[0,1.65,62.5],[1,1.25,100],[2,1.08,7.83]],"ltp":1.65,"tv":4.0,"id":31372}]}]}
{"op":"mcm","clk":"11824361665","pt":1723464331454,"mc":[{"id":"1.231699634","rc":[{"batb":[[0,1.66,10],[1,1.65,62.5],[2,1.25,100]],"ltp":1.65,"tv":4.0,"id":31372}]}]}
{"op":"mcm","clk":"11824361915","pt":1723464335058,"mc":[{"id":"1.231699634","rc":[{"batb":[[0,1.65,62.5],[1,1.25,100],[2,1.08,7.83]],"ltp":1.65,"tv":4.0,"id":31372}]}]}
{"op":"mcm","clk":"11824362234","pt":1723464340095,"mc":[{"id":"1.231699634","rc":[{"batb":[[0,1.66,10],[1,1.65,62.5],[2,1.25,100]],"ltp":1.65,"tv":4.0,"id":31372}]}]}
{"op":"mcm","clk":"11824362502","pt":1723464344068,"mc":[{"id":"1.231699634","rc":[{"batb":[[0,1.65,62.5],[1,1.25,100],[2,1.08,7.83]],"ltp":1.65,"tv":4.0,"id":31372}]}]}
{"op":"mcm","clk":"11824362694","pt":1723464346703,"mc":[{"id":"1.231699634","rc":[{"batb":[[0,1.66,10],[1,1.65,62.5],[2,1.25,100]],"ltp":1.65,"tv":4.0,"id":31372}]}]}
{"op":"mcm","clk":"11824362936","pt":1723464350002,"mc":[{"id":"1.231699634","rc":[{"batb":[[0,1.65,62.5],[1,1.25,100],[2,1.08,7.83]],"ltp":1.65,"tv":4.0,"id":31372}]}]}
{"op":"mcm","clk":"11824363129","pt":1723464352776,"mc":[{"id":"1.231699634","rc":[{"batb":[[0,1.66,10],[1,1.65,62.5],[2,1.25,100]],"ltp":1.65,"tv":4.0,"id":31372}]}]}
{"op":"mcm","clk":"11824363356","pt":1723464356375,"mc":[{"id":"1.231699634","rc":[{"batb":[[0,1.65,62.5],[1,1.25,100],[2,1.08,7.83]],"ltp":1.65,"tv":4.0,"id":31372}]}]}
{"op":"mcm","clk":"11824363566","pt":1723464360016,"mc":[{"id":"1.231699634","rc":[{"batb":[[0,1.66,10],[1,1.65,62.5],[2,1.25,100]],"ltp":1.65,"tv":4.0,"id":31372}]}]}
{"op":"mcm","clk":"11824363820","pt":1723464363474,"mc":[{"id":"1.231699634","rc":[{"batb":[[0,1.65,62.5],[1,1.25,100],[2,1.08,7.83]],"ltp":1.65,"tv":4.0,"id":31372}]}]}
{"op":"mcm","clk":"11824363952","pt":1723464365685,"mc":[{"id":"1.231699634","rc":[{"batb":[[0,1.66,10],[1,1.65,62.5],[2,1.25,100]],"ltp":1.65,"tv":4.0,"id":31372}]}]}
{"op":"mcm","clk":"11824364195","pt":1723464368971,"mc":[{"id":"1.231699634","rc":[{"batb":[[0,1.65,62.5],[1,1.25,100],[2,1.08,7.83]],"ltp":1.65,"tv":4.0,"id":31372}]}]}
{"op":"mcm","clk":"11824364428","pt":1723464372100,"mc":[{"id":"1.231699634","rc":[{"batb":[[0,1.66,10],[1,1.65,62.5],[2,1.25,100]],"ltp":1.65,"tv":4.0,"id":31372}]}]}
{"op":"mcm","clk":"11824364792","pt":1723464377599,"mc":[{"id":"1.231699634","rc":[{"batb":[[0,1.65,62.5],[1,1.25,100],[2,1.08,7.83]],"ltp":1.65,"tv":4.0,"id":31372}]}]}
{"op":"mcm","clk":"11824365026","pt":1723464381103,"mc":[{"id":"1.231699634","rc":[{"batb":[[0,1.66,10],[1,1.65,62.5],[2,1.25,100]],"ltp":1.65,"tv":4.0,"id":31372}]}]}
{"op":"mcm","clk":"11824365258","pt":1723464384491,"mc":[{"id":"1.231699634","rc":[{"batb":[[0,1.65,62.5],[1,1.25,100],[2,1.08,7.83]],"ltp":1.65,"tv":4.0,"id":31372}]}]}
{"op":"mcm","clk":"11824365762","pt":1723464391994,"mc":[{"id":"1.231699634","rc":[{"batb":[[0,1.66,10],[1,1.65,62.5],[2,1.25,100]],"ltp":1.65,"tv":4.0,"id":31372}]}]}
{"op":"mcm","clk":"11824366024","pt":1723464396040,"mc":[{"id":"1.231699634","rc":[{"batb":[[0,1.65,62.5],[1,1.25,100],[2,1.08,7.83]],"ltp":1.65,"tv":4.0,"id":31372}]}]}
{"op":"mcm","clk":"11824366214","pt":1723464399040,"mc":[{"id":"1.231699634","rc":[{"batb":[[0,1.66,10],[1,1.65,62.5],[2,1.25,100]],"ltp":1.65,"tv":4.0,"id":31372}]}]}
{"op":"mcm","clk":"11824366427","pt":1723464402538,"mc":[{"id":"1.231699634","rc":[{"batb":[[0,1.65,62.5],[1,1.25,100],[2,1.08,7.83]],"ltp":1.65,"tv":4.0,"id":31372}]}]}
{"op":"mcm","clk":"11824366666","pt":1723464406034,"mc":[{"id":"1.231699634","rc":[{"batb":[[0,1.66,10],[1,1.65,62.5],[2,1.25,100]],"ltp":1.65,"tv":4.0,"id":31372}]}]}
{"op":"mcm","clk":"11824366914","pt":1723464409722,"mc":[{"id":"1.231699634","rc":[{"batb":[[0,1.65,62.5],[1,1.25,100],[2,1.08,7.83]],"ltp":1.65,"tv":4.0,"id":31372}]}]}
{"op":"mcm","clk":"11824367064","pt":1723464411934,"mc":[{"id":"1.231699634","rc":[{"batb":[[0,1.66,10],[1,1.65,62.5],[2,1.25,100]],"ltp":1.65,"tv":4.0,"id":31372}]}]}
{"op":"mcm","clk":"11824367524","pt":1723464418465,"mc":[{"id":"1.231699634","rc":[{"batb":[[0,1.65,62.5],[1,1.25,100],[2,1.08,7.83]],"ltp":1.65,"tv":4.0,"id":31372}]}]}
{"op":"mcm","clk":"11824367750","pt":1723464421447,"mc":[{"id":"1.231699634","rc":[{"batb":[[0,1.67,10],[1,1.65,62.5],[2,1.25,100]],"ltp":1.65,"tv":4.0,"id":31372}]}]}
{"op":"mcm","clk":"11824368194","pt":1723464427750,"mc":[{"id":"1.231699634","rc":[{"batb":[[0,1.65,62.5],[1,1.25,100],[2,1.08,7.83]],"ltp":1.65,"tv":4.0,"id":31372}]}]}
{"op":"mcm","clk":"11824368409","pt":1723464430466,"mc":[{"id":"1.231699634","rc":[{"batb":[[0,1.66,10],[1,1.65,62.5],[2,1.25,100]],"ltp":1.65,"tv":4.0,"id":31372}]}]}
{"op":"mcm","clk":"11824368788","pt":1723464435294,"mc":[{"id":"1.231699634","rc":[{"batb":[[0,1.65,62.5],[1,1.25,100],[2,1.08,7.83]],"ltp":1.65,"tv":4.0,"id":31372}]}]}
{"op":"mcm","clk":"11824369089","pt":1723464439255,"mc":[{"id":"1.231699634","rc":[{"batb":[[0,1.66,10],[1,1.65,62.5],[2,1.25,100]],"ltp":1.65,"tv":4.0,"id":31372}]}]}
{"op":"mcm","clk":"11824369328","pt":1723464442544,"mc":[{"id":"1.231699634","rc":[{"batb":[[0,1.65,62.5],[1,1.25,100],[2,1.08,7.83]],"ltp":1.65,"tv":4.0,"id":31372}]}]}
{"op":"mcm","clk":"11824369537","pt":1723464445631,"mc":[{"id":"1.231699634","rc":[{"batb":[[0,1.66,10],[1,1.65,62.5],[2,1.25,100]],"ltp":1.65,"tv":4.0,"id":31372}]}]}
{"op":"mcm","clk":"11824369799","pt":1723464448969,"mc":[{"id":"1.231699634","rc":[{"batb":[[0,1.65,62.5],[1,1.25,100],[2,1.08,7.83]],"ltp":1.65,"tv":4.0,"id":31372}]}]}
{"op":"mcm","clk":"11824370060","pt":1723464452367,"mc":[{"id":"1.231699634","rc":[{"batb":[[0,1.66,10],[1,1.65,62.5],[2,1.25,100]],"ltp":1.65,"tv":4.0,"id":31372}]}]}
{"op":"mcm","clk":"11824370396","pt":1723464456588,"mc":[{"id":"1.231699634","rc":[{"batb":[[0,1.65,62.5],[1,1.25,100],[2,1.08,7.83]],"ltp":1.65,"tv":4.0,"id":31372}]}]}
{"op":"mcm","clk":"11824370729","pt":1723464461366,"mc":[{"id":"1.231699634","rc":[{"batb":[[0,1.66,10],[1,1.65,62.5],[2,1.25,100]],"ltp":1.65,"tv":4.0,"id":31372}]}]}
{"op":"mcm","clk":"11824371012","pt":1723464464764,"mc":[{"id":"1.231699634","rc":[{"batb":[[0,1.65,62.5],[1,1.25,100],[2,1.08,7.83]],"ltp":1.65,"tv":4.0,"id":31372}]}]}
{"op":"mcm","clk":"11824371431","pt":1723464470982,"mc":[{"id":"1.231699634","rc":[{"batb":[[0,1.66,10],[1,1.65,62.5],[2,1.25,100]],"ltp":1.65,"tv":4.0,"id":31372}]}]}
{"op":"mcm","clk":"11824371655","pt":1723464474271,"mc":[{"id":"1.231699634","rc":[{"batb":[[0,1.65,62.5],[1,1.25,100],[2,1.08,7.83]],"ltp":1.65,"tv":4.0,"id":31372}]}]}
{"op":"mcm","clk":"11824372122","pt":1723464480649,"mc":[{"id":"1.231699634","rc":[{"batb":[[0,1.66,10],[1,1.65,62.5],[2,1.25,100]],"ltp":1.65,"tv":4.0,"id":31372}]}]}
{"op":"mcm","clk":"11824372453","pt":1723464484791,"mc":[{"id":"1.231699634","rc":[{"batb":[[0,1.65,62.5],[1,1.25,100],[2,1.08,7.83]],"ltp":1.65,"tv":4.0,"id":31372}]}]}
{"op":"mcm","clk":"11824372606","pt":1723464487211,"mc":[{"id":"1.231699634","rc":[{"batb":[[0,1.66,10],[1,1.65,62.5],[2,1.25,100]],"ltp":1.65,"tv":4.0,"id":31372}]}]}
{"op":"mcm","clk":"11824372805","pt":1723464490615,"mc":[{"id":"1.231699634","rc":[{"batb":[[0,1.65,62.5],[1,1.25,100],[2,1.08,7.83]],"ltp":1.65,"tv":4.0,"id":31372}]}]}
{"op":"mcm","clk":"11824372990","pt":1723464493190,"mc":[{"id":"1.231699634","rc":[{"batb":[[0,1.66,10],[1,1.65,62.5],[2,1.25,100]],"ltp":1.65,"tv":4.0,"id":31372}]}]}
{"op":"mcm","clk":"11824373330","pt":1723464498217,"mc":[{"id":"1.231699634","rc":[{"batb":[[0,1.65,62.5],[1,1.25,100],[2,1.08,7.83]],"ltp":1.65,"tv":4.0,"id":31372}]}]}
{"op":"mcm","clk":"11824373543","pt":1723464500999,"mc":[{"id":"1.231699634","rc":[{"batb":[[0,1.66,10],[1,1.65,62.5],[2,1.25,100]],"ltp":1.65,"tv":4.0,"id":31372}]}]}
{"op":"mcm","clk":"11824373833","pt":1723464504404,"mc":[{"id":"1.231699634","rc":[{"batb":[[0,1.65,62.5],[1,1.25,100],[2,1.08,7.83]],"ltp":1.65,"tv":4.0,"id":31372}]}]}
{"op":"mcm","clk":"11824374026","pt":1723464507029,"mc":[{"id":"1.231699634","rc":[{"batb":[[0,1.66,10],[1,1.65,62.5],[2,1.25,100]],"ltp":1.65,"tv":4.0,"id":31372}]}]}
{"op":"mcm","clk":"11824374288","pt":1723464510396,"mc":[{"id":"1.231699634","rc":[{"batb":[[0,1.65,62.5],[1,1.25,100],[2,1.08,7.83]],"ltp":1.65,"tv":4.0,"id":31372}]}]}
{"op":"mcm","clk":"11824374515","pt":1723464513294,"mc":[{"id":"1.231699634","rc":[{"batb":[[0,1.66,10],[1,1.65,62.5],[2,1.25,100]],"ltp":1.65,"tv":4.0,"id":31372}]}]}
{"op":"mcm","clk":"11824374775","pt":1723464517415,"mc":[{"id":"1.231699634","rc":[{"batb":[[0,1.65,62.5],[1,1.25,100],[2,1.08,7.83]],"ltp":1.65,"tv":4.0,"id":31372}]}]}
{"op":"mcm","clk":"11824374942","pt":1723464520038,"mc":[{"id":"1.231699634","rc":[{"batb":[[0,1.66,10],[1,1.65,62.5],[2,1.25,100]],"ltp":1.65,"tv":4.0,"id":31372}]}]}
{"op":"mcm","clk":"11824375172","pt":1723464523335,"mc":[{"id":"1.231699634","rc":[{"batb":[[0,1.65,62.5],[1,1.25,100],[2,1.08,7.83]],"ltp":1.65,"tv":4.0,"id":31372}]}]}
{"op":"mcm","clk":"11824375390","pt":1723464526833,"mc":[{"id":"1.231699634","rc":[{"batb":[[0,1.66,10],[1,1.65,62.5],[2,1.25,100]],"ltp":1.65,"tv":4.0,"id":31372}]}]}
{"op":"mcm","clk":"11824375626","pt":1723464530227,"mc":[{"id":"1.231699634","rc":[{"batb":[[0,1.65,62.5],[1,1.25,100],[2,1.08,7.83]],"ltp":1.65,"tv":4.0,"id":31372}]}]}
{"op":"mcm","clk":"11824375811","pt":1723464532511,"mc":[{"id":"1.231699634","rc":[{"batb":[[0,1.66,10],[1,1.65,62.5],[2,1.25,100]],"ltp":1.65,"tv":4.0,"id":31372}]}]}
{"op":"mcm","clk":"11824376091","pt":1723464536212,"mc":[{"id":"1.231699634","rc":[{"batb":[[0,1.65,62.5],[1,1.25,100],[2,1.08,7.83]],"ltp":1.65,"tv":4.0,"id":31372}]}]}
{"op":"mcm","clk":"11824376357","pt":1723464539407,"mc":[{"id":"1.231699634","rc":[{"batb":[[0,1.66,10],[1,1.65,62.5],[2,1.25,100]],"ltp":1.65,"tv":4.0,"id":31372}]}]}
{"op":"mcm","clk":"11824376607","pt":1723464542649,"mc":[{"id":"1.231699634","rc":[{"batb":[[0,1.65,62.5],[1,1.25,100],[2,1.08,7.83]],"ltp":1.65,"tv":4.0,"id":31372}]}]}
{"op":"mcm","clk":"11824376974","pt":1723464547351,"mc":[{"id":"1.231699634","rc":[{"batb":[[0,1.66,10],[1,1.65,62.5],[2,1.25,100]],"ltp":1.65,"tv":4.0,"id":31372}]}]}
{"op":"mcm","clk":"11824377304","pt":1723464552025,"mc":[{"id":"1.231699634","rc":[{"batb":[[0,1.65,62.5],[1,1.25,100],[2,1.08,7.83]],"ltp":1.65,"tv":4.0,"id":31372}]}]}
{"op":"mcm","clk":"11824377564","pt":1723464555931,"mc":[{"id":"1.231699634","rc":[{"batb":[[0,1.66,10],[1,1.65,62.5],[2,1.25,100]],"ltp":1.65,"tv":4.0,"id":31372}]}]}
{"op":"mcm","clk":"11824377836","pt":1723464559431,"mc":[{"id":"1.231699634","rc":[{"batb":[[0,1.65,62.5],[1,1.25,100],[2,1.08,7.83]],"ltp":1.65,"tv":4.0,"id":31372}]}]}
{"op":"mcm","clk":"11824378097","pt":1723464562632,"mc":[{"id":"1.231699634","rc":[{"batb":[[0,1.66,10],[1,1.65,62.5],[2,1.25,100]],"ltp":1.65,"tv":4.0,"id":31372}]}]}
{"op":"mcm","clk":"11824378387","pt":1723464566553,"mc":[{"id":"1.231699634","rc":[{"batb":[[0,1.65,62.5],[1,1.25,100],[2,1.08,7.83]],"ltp":1.65,"tv":4.0,"id":31372}]}]}
{"op":"mcm","clk":"11824378760","pt":1723464570750,"mc":[{"id":"1.231699634","rc":[{"batb":[[0,1.66,10],[1,1.65,62.5],[2,1.25,100]],"ltp":1.65,"tv":4.0,"id":31372}]}]}
{"op":"mcm","clk":"11824379036","pt":1723464574053,"mc":[{"id":"1.231699634","rc":[{"batb":[[0,1.65,62.5],[1,1.25,100],[2,1.08,7.83]],"ltp":1.65,"tv":4.0,"id":31372}]}]}
{"op":"mcm","clk":"11824379385","pt":1723464578793,"mc":[{"id":"1.231699634","rc":[{"batb":[[0,1.66,10],[1,1.65,62.5],[2,1.25,100]],"ltp":1.65,"tv":4.0,"id":31372}]}]}
{"op":"mcm","clk":"11824379659","pt":1723464581988,"mc":[{"id":"1.231699634","rc":[{"batb":[[0,1.65,62.5],[1,1.25,100],[2,1.08,7.83]],"ltp":1.65,"tv":4.0,"id":31372}]}]}
{"op":"mcm","clk":"11824379950","pt":1723464585281,"mc":[{"id":"1.231699634","rc":[{"batb":[[0,1.66,10],[1,1.65,62.5],[2,1.25,100]],"ltp":1.65,"tv":4.0,"id":31372}]}]}
{"op":"mcm","clk":"11824380282","pt":1723464589905,"mc":[{"id":"1.231699634","rc":[{"batb":[[0,1.65,62.5],[1,1.25,100],[2,1.08,7.83]],"ltp":1.65,"tv":4.0,"id":31372}]}]}
{"op":"mcm","clk":"11824380544","pt":1723464593480,"mc":[{"id":"1.231699634","rc":[{"batb":[[0,1.66,10],[1,1.65,62.5],[2,1.25,100]],"ltp":1.65,"tv":4.0,"id":31372}]}]}
{"op":"mcm","clk":"11824380777","pt":1723464596806,"mc":[{"id":"1.231699634","rc":[{"batb":[[0,1.65,62.5],[1,1.25,100],[2,1.08,7.83]],"ltp":1.65,"tv":4.0,"id":31372}]}]}
{"op":"mcm","clk":"11824381587","pt":1723464605618,"mc":[{"id":"1.231699634","rc":[{"batb":[[0,1.66,10],[1,1.65,62.5],[2,1.25,100]],"ltp":1.65,"tv":4.0,"id":31372}]}]}
{"op":"mcm","clk":"11824381913","pt":1723464609403,"mc":[{"id":"1.231699634","rc":[{"batb":[[0,1.65,62.5],[1,1.25,100],[2,1.08,7.83]],"ltp":1.65,"tv":4.0,"id":31372}]}]}
{"op":"mcm","clk":"11824382085","pt":1723464611819,"mc":[{"id":"1.231699634","rc":[{"batb":[[0,1.66,10],[1,1.65,62.5],[2,1.25,100]],"ltp":1.65,"tv":4.0,"id":31372}]}]}
{"op":"mcm","clk":"11824382327","pt":1723464615017,"mc":[{"id":"1.231699634","rc":[{"batb":[[0,1.65,62.5],[1,1.25,100],[2,1.08,7.83]],"ltp":1.65,"tv":4.0,"id":31372}]}]}
{"op":"mcm","clk":"11824382542","pt":1723464617644,"mc":[{"id":"1.231699634","rc":[{"batb":[[0,1.66,10],[1,1.65,62.5],[2,1.25,100]],"ltp":1.65,"tv":4.0,"id":31372}]}]}
{"op":"mcm","clk":"11824382797","pt":1723464621000,"mc":[{"id":"1.231699634","rc":[{"batb":[[0,1.65,62.5],[1,1.25,100],[2,1.08,7.83]],"ltp":1.65,"tv":4.0,"id":31372}]}]}
{"op":"mcm","clk":"11824383149","pt":1723464625728,"mc":[{"id":"1.231699634","rc":[{"batb":[[0,1.66,10],[1,1.65,62.5],[2,1.25,100]],"ltp":1.65,"tv":4.0,"id":31372}]}]}
{"op":"mcm","clk":"11824383510","pt":1723464629106,"mc":[{"id":"1.231699634","rc":[{"batb":[[0,1.65,62.5],[1,1.25,100],[2,1.08,7.83]],"ltp":1.65,"tv":4.0,"id":31372}]}]}
{"op":"mcm","clk":"11824383994","pt":1723464634248,"mc":[{"id":"1.231699634","rc":[{"batb":[[0,1.66,10],[1,1.65,62.5],[2,1.25,100]],"ltp":1.65,"tv":4.0,"id":31372}]}]}
{"op":"mcm","clk":"11824384555","pt":1723464641453,"mc":[{"id":"1.231699634","rc":[{"batb":[[0,1.65,62.5],[1,1.25,100],[2,1.08,7.83]],"ltp":1.65,"tv":4.0,"id":31372}]}]}
{"op":"mcm","clk":"11824384775","pt":1723464644241,"mc":[{"id":"1.231699634","rc":[{"batb":[[0,1.66,10],[1,1.65,62.5],[2,1.25,100]],"ltp":1.65,"tv":4.0,"id":31372}]}]}
{"op":"mcm","clk":"11824385138","pt":1723464648854,"mc":[{"id":"1.231699634","rc":[{"batb":[[0,1.65,62.5],[1,1.25,100],[2,1.08,7.83]],"ltp":1.65,"tv":4.0,"id":31372}]}]}
{"op":"mcm","clk":"11824385298","pt":1723464651628,"mc":[{"id":"1.231699634","rc":[{"batb":[[0,1.66,10],[1,1.65,62.5],[2,1.25,100]],"ltp":1.65,"tv":4.0,"id":31372}]}]}
{"op":"mcm","clk":"11824385631","pt":1723464656143,"mc":[{"id":"1.231699634","rc":[{"batb":[[0,1.65,62.5],[1,1.25,100],[2,1.08,7.83]],"ltp":1.65,"tv":4.0,"id":31372}]}]}
{"op":"mcm","clk":"11824385817","pt":1723464659226,"mc":[{"id":"1.231699634","rc":[{"batb":[[0,1.66,10],[1,1.65,62.5],[2,1.25,100]],"ltp":1.65,"tv":4.0,"id":31372}]}]}
{"op":"mcm","clk":"11824386102","pt":1723464662768,"mc":[{"id":"1.231699634","rc":[{"batb":[[0,1.65,62.5],[1,1.25,100],[2,1.08,7.83]],"ltp":1.65,"tv":4.0,"id":31372}]}]}
{"op":"mcm","clk":"11824386427","pt":1723464666674,"mc":[{"id":"1.231699634","rc":[{"batb":[[0,1.66,10],[1,1.65,62.5],[2,1.25,100]],"ltp":1.65,"tv":4.0,"id":31372}]}]}
{"op":"mcm","clk":"11824386764","pt":1723464671157,"mc":[{"id":"1.231699634","rc":[{"batb":[[0,1.65,62.5],[1,1.25,100],[2,1.08,7.83]],"ltp":1.65,"tv":4.0,"id":31372}]}]}
{"op":"mcm","clk":"11824386912","pt":1723464673372,"mc":[{"id":"1.231699634","rc":[{"batb":[[0,1.66,10],[1,1.65,62.5],[2,1.25,100]],"ltp":1.65,"tv":4.0,"id":31372}]}]}
{"op":"mcm","clk":"11824387235","pt":1723464676981,"mc":[{"id":"1.231699634","rc":[{"batb":[[0,1.65,62.5],[1,1.25,100],[2,1.08,7.83]],"ltp":1.65,"tv":4.0,"id":31372}]}]}
{"op":"mcm","clk":"11824387401","pt":1723464679192,"mc":[{"id":"1.231699634","rc":[{"batb":[[0,1.66,10],[1,1.65,62.5],[2,1.25,100]],"ltp":1.65,"tv":4.0,"id":31372}]}]}
{"op":"mcm","clk":"11824387496","pt":1723464680069,"mc":[{"id":"1.231699634","rc":[{"batl":[[0,2.32,80.54],[1,2.32,0]],"ltp":1.65,"tv":4.0,"id":31372}]}]}
{"op":"mcm","clk":"11824387765","pt":1723464683169,"mc":[{"id":"1.231699634","rc":[{"batb":[[0,1.65,62.5],[1,1.25,100],[2,1.08,7.83]],"ltp":1.65,"tv":4.0,"id":31372}]}]}
{"op":"mcm","clk":"11824388092","pt":1723464687781,"mc":[{"id":"1.231699634","rc":[{"batb":[[0,1.66,10],[1,1.65,62.5],[2,1.25,100]],"ltp":1.65,"tv":4.0,"id":31372}]}]}
{"op":"mcm","clk":"11824388374","pt":1723464691188,"mc":[{"id":"1.231699634","rc":[{"batb":[[0,1.65,62.5],[1,1.25,100],[2,1.08,7.83]],"ltp":1.65,"tv":4.0,"id":31372}]}]}
{"op":"mcm","clk":"11824388638","pt":1723464694578,"mc":[{"id":"1.231699634","rc":[{"batb":[[0,1.66,10],[1,1.65,62.5],[2,1.25,100]],"ltp":1.65,"tv":4.0,"id":31372}]}]}
{"op":"mcm","clk":"11824388923","pt":1723464698276,"mc":[{"id":"1.231699634","rc":[{"batb":[[0,1.65,62.5],[1,1.25,100],[2,1.08,7.83]],"ltp":1.65,"tv":4.0,"id":31372}]}]}
{"op":"mcm","clk":"11824389081","pt":1723464700594,"mc":[{"id":"1.231699634","rc":[{"batb":[[0,1.66,10],[1,1.65,62.5],[2,1.25,100]],"ltp":1.65,"tv":4.0,"id":31372}]}]}
{"op":"mcm","clk":"11824389461","pt":1723464705121,"mc":[{"id":"1.231699634","rc":[{"batb":[[0,1.65,62.5],[1,1.25,100],[2,1.08,7.83]],"ltp":1.65,"tv":4.0,"id":31372}]}]}
{"op":"mcm","clk":"11824389693","pt":1723464707487,"mc":[{"id":"1.231699634","rc":[{"batb":[[0,1.66,10],[1,1.65,62.5],[2,1.25,100]],"ltp":1.65,"tv":4.0,"id":31372}]}]}
{"op":"mcm","clk":"11824389989","pt":1723464710730,"mc":[{"id":"1.231699634","rc":[{"batb":[[0,1.65,62.5],[1,1.25,100],[2,1.08,7.83]],"ltp":1.65,"tv":4.0,"id":31372}]}]}
{"op":"mcm","clk":"11824390314","pt":1723464714524,"mc":[{"id":"1.231699634","rc":[{"batb":[[0,1.66,10],[1,1.65,62.5],[2,1.25,100]],"ltp":1.65,"tv":4.0,"id":31372}]}]}
{"op":"mcm","clk":"11824390557","pt":1723464718120,"mc":[{"id":"1.231699634","rc":[{"batb":[[0,1.65,62.5],[1,1.25,100],[2,1.08,7.83]],"ltp":1.65,"tv":4.0,"id":31372}]}]}
{"op":"mcm","clk":"11824390732","pt":1723464720535,"mc":[{"id":"1.231699634","rc":[{"batb":[[0,1.66,10],[1,1.65,62.5],[2,1.25,100]],"ltp":1.65,"tv":4.0,"id":31372}]}]}
{"op":"mcm","clk":"11824390999","pt":1723464723843,"mc":[{"id":"1.231699634","rc":[{"batb":[[0,1.65,62.5],[1,1.25,100],[2,1.08,7.83]],"ltp":1.65,"tv":4.0,"id":31372}]}]}
{"op":"mcm","clk":"11824391145","pt":1723464726230,"mc":[{"id":"1.231699634","rc":[{"batb":[[0,1.67,10],[1,1.65,62.5],[2,1.25,100]],"ltp":1.65,"tv":4.0,"id":31372}]}]}
{"op":"mcm","clk":"11824391451","pt":1723464730851,"mc":[{"id":"1.231699634","rc":[{"batb":[[0,1.65,62.5],[1,1.25,100],[2,1.08,7.83]],"ltp":1.65,"tv":4.0,"id":31372}]}]}
{"op":"mcm","clk":"11824391661","pt":1723464734053,"mc":[{"id":"1.231699634","rc":[{"batb":[[0,1.66,10],[1,1.65,62.5],[2,1.25,100]],"ltp":1.65,"tv":4.0,"id":31372}]}]}
{"op":"mcm","clk":"11824391874","pt":1723464737438,"mc":[{"id":"1.231699634","rc":[{"batb":[[0,1.65,62.5],[1,1.25,100],[2,1.08,7.83]],"ltp":1.65,"tv":4.0,"id":31372}]}]}
{"op":"mcm","clk":"11824392071","pt":1723464739957,"mc":[{"id":"1.231699634","rc":[{"batb":[[0,1.66,10],[1,1.65,62.5],[2,1.25,100]],"ltp":1.65,"tv":4.0,"id":31372}]}]}
{"op":"mcm","clk":"11824392305","pt":1723464743246,"mc":[{"id":"1.231699634","rc":[{"batb":[[0,1.65,62.5],[1,1.25,100],[2,1.08,7.83]],"ltp":1.65,"tv":4.0,"id":31372}]}]}
{"op":"mcm","clk":"11824392460","pt":1723464745559,"mc":[{"id":"1.231699634","rc":[{"batb":[[0,1.66,10],[1,1.65,62.5],[2,1.25,100]],"ltp":1.65,"tv":4.0,"id":31372}]}]}
{"op":"mcm","clk":"11824392733","pt":1723464748849,"mc":[{"id":"1.231699634","rc":[{"batb":[[0,1.65,62.5],[1,1.25,100],[2,1.08,7.83]],"ltp":1.65,"tv":4.0,"id":31372}]}]}
{"op":"mcm","clk":"11824392913","pt":1723464751361,"mc":[{"id":"1.231699634","rc":[{"batb":[[0,1.66,10],[1,1.65,62.5],[2,1.25,100]],"ltp":1.65,"tv":4.0,"id":31372}]}]}
{"op":"mcm","clk":"11824393191","pt":1723464754680,"mc":[{"id":"1.231699634","rc":[{"batb":[[0,1.65,62.5],[1,1.25,100],[2,1.08,7.83]],"ltp":1.65,"tv":4.0,"id":31372}]}]}
{"op":"mcm","clk":"11824393405","pt":1723464757497,"mc":[{"id":"1.231699634","rc":[{"batb":[[0,1.66,10],[1,1.65,62.5],[2,1.25,100]],"ltp":1.65,"tv":4.0,"id":31372}]}]}
{"op":"mcm","clk":"11824393685","pt":1723464761001,"mc":[{"id":"1.231699634","rc":[{"batb":[[0,1.65,62.5],[1,1.25,100],[2,1.08,7.83]],"ltp":1.65,"tv":4.0,"id":31372}]}]}
{"op":"mcm","clk":"11824393875","pt":1723464763166,"mc":[{"id":"1.231699634","rc":[{"batb":[[0,1.66,10],[1,1.65,62.5],[2,1.25,100]],"ltp":1.65,"tv":4.0,"id":31372}]}]}
{"op":"mcm","clk":"11824394144","pt":1723464766605,"mc":[{"id":"1.231699634","rc":[{"batb":[[0,1.65,62.5],[1,1.25,100],[2,1.08,7.83]],"ltp":1.65,"tv":4.0,"id":31372}]}]}
{"op":"mcm","clk":"11824394375","pt":1723464769382,"mc":[{"id":"1.231699634","rc":[{"batb":[[0,1.66,10],[1,1.65,62.5],[2,1.25,100]],"ltp":1.65,"tv":4.0,"id":31372}]}]}
{"op":"mcm","clk":"11824394600","pt":1723464772818,"mc":[{"id":"1.231699634","rc":[{"batb":[[0,1.65,62.5],[1,1.25,100],[2,1.08,7.83]],"ltp":1.65,"tv":4.0,"id":31372}]}]}
{"op":"mcm","clk":"11824394757","pt":1723464775123,"mc":[{"id":"1.231699634","rc":[{"batb":[[0,1.66,10],[1,1.65,62.5],[2,1.25,100]],"ltp":1.65,"tv":4.0,"id":31372}]}]}
{"op":"mcm","clk":"11824395020","pt":1723464778725,"mc":[{"id":"1.231699634","rc":[{"batb":[[0,1.65,62.5],[1,1.25,100],[2,1.08,7.83]],"ltp":1.65,"tv":4.0,"id":31372}]}]}
{"op":"mcm","clk":"11824395236","pt":1723464781709,"mc":[{"id":"1.231699634","rc":[{"batb":[[0,1.66,10],[1,1.65,62.5],[2,1.25,100]],"ltp":1.65,"tv":4.0,"id":31372}]}]}
{"op":"mcm","clk":"11824395501","pt":1723464785312,"mc":[{"id":"1.231699634","rc":[{"batb":[[0,1.65,62.5],[1,1.25,100],[2,1.08,7.83]],"ltp":1.65,"tv":4.0,"id":31372}]}]}
{"op":"mcm","clk":"11824395750","pt":1723464789269,"mc":[{"id":"1.231699634","rc":[{"batb":[[0,1.66,10],[1,1.65,62.5],[2,1.25,100]],"ltp":1.65,"tv":4.0,"id":31372}]}]}
{"op":"mcm","clk":"11824396036","pt":1723464792820,"mc":[{"id":"1.231699634","rc":[{"batb":[[0,1.65,62.5],[1,1.25,100],[2,1.08,7.83]],"ltp":1.65,"tv":4.0,"id":31372}]}]}
{"op":"mcm","clk":"11824396242","pt":1723464795547,"mc":[{"id":"1.231699634","rc":[{"batb":[[0,1.66,10],[1,1.65,62.5],[2,1.25,100]],"ltp":1.65,"tv":4.0,"id":31372}]}]}
{"op":"mcm","clk":"11824396517","pt":1723464798948,"mc":[{"id":"1.231699634","rc":[{"batb":[[0,1.65,62.5],[1,1.25,100],[2,1.08,7.83]],"ltp":1.65,"tv":4.0,"id":31372}]}]}
{"op":"mcm","clk":"11824396815","pt":1723464802961,"mc":[{"id":"1.231699634","rc":[{"batb":[[0,1.66,10],[1,1.65,62.5],[2,1.25,100]],"ltp":1.65,"tv":4.0,"id":31372}]}]}
{"op":"mcm","clk":"11824397188","pt":1723464807938,"mc":[{"id":"1.231699634","rc":[{"batb":[[0,1.65,62.5],[1,1.25,100],[2,1.08,7.83]],"ltp":1.65,"tv":4.0,"id":31372}]}]}
{"op":"mcm","clk":"11824397355","pt":1723464810245,"mc":[{"id":"1.231699634","rc":[{"batb":[[0,1.66,10],[1,1.65,62.5],[2,1.25,100]],"ltp":1.65,"tv":4.0,"id":31372}]}]}
{"op":"mcm","clk":"11824397622","pt":1723464814099,"mc":[{"id":"1.231699634","rc":[{"batb":[[0,1.65,62.5],[1,1.25,100],[2,1.08,7.83]],"ltp":1.65,"tv":4.0,"id":31372}]}]}
{"op":"mcm","clk":"11824397913","pt":1723464818059,"mc":[{"id":"1.231699634","rc":[{"batb":[[0,1.66,10],[1,1.65,62.5],[2,1.25,100]],"ltp":1.65,"tv":4.0,"id":31372}]}]}
{"op":"mcm","clk":"11824398200","pt":1723464821970,"mc":[{"id":"1.231699634","rc":[{"batb":[[0,1.65,62.5],[1,1.25,100],[2,1.08,7.83]],"ltp":1.65,"tv":4.0,"id":31372}]}]}
{"op":"mcm","clk":"11824398391","pt":1723464824492,"mc":[{"id":"1.231699634","rc":[{"batb":[[0,1.66,10],[1,1.65,62.5],[2,1.25,100]],"ltp":1.65,"tv":4.0,"id":31372}]}]}
{"op":"mcm","clk":"11824398648","pt":1723464827982,"mc":[{"id":"1.231699634","rc":[{"batb":[[0,1.65,62.5],[1,1.25,100],[2,1.08,7.83]],"ltp":1.65,"tv":4.0,"id":31372}]}]}
{"op":"mcm","clk":"11824398913","pt":1723464831996,"mc":[{"id":"1.231699634","rc":[{"batb":[[0,1.66,10],[1,1.65,62.5],[2,1.25,100]],"ltp":1.65,"tv":4.0,"id":31372}]}]}
{"op":"mcm","clk":"11824399178","pt":1723464835496,"mc":[{"id":"1.231699634","rc":[{"batb":[[0,1.65,62.5],[1,1.25,100],[2,1.08,7.83]],"ltp":1.65,"tv":4.0,"id":31372}]}]}
{"op":"mcm","clk":"11824399422","pt":1723464838216,"mc":[{"id":"1.231699634","rc":[{"batb":[[0,1.66,10],[1,1.65,62.5],[2,1.25,100]],"ltp":1.65,"tv":4.0,"id":31372}]}]}
{"op":"mcm","clk":"11824399692","pt":1723464841520,"mc":[{"id":"1.231699634","rc":[{"batb":[[0,1.65,62.5],[1,1.25,100],[2,1.08,7.83]],"ltp":1.65,"tv":4.0,"id":31372}]}]}
{"op":"mcm","clk":"11824399891","pt":1723464843785,"mc":[{"id":"1.231699634","rc":[{"batb":[[0,1.66,10],[1,1.65,62.5],[2,1.25,100]],"ltp":1.65,"tv":4.0,"id":31372}]}]}
{"op":"mcm","clk":"11824400169","pt":1723464847493,"mc":[{"id":"1.231699634","rc":[{"batb":[[0,1.65,62.5],[1,1.25,100],[2,1.08,7.83]],"ltp":1.65,"tv":4.0,"id":31372}]}]}
{"op":"mcm","clk":"11824400347","pt":1723464850015,"mc":[{"id":"1.231699634","rc":[{"batb":[[0,1.66,10],[1,1.65,62.5],[2,1.25,100]],"ltp":1.65,"tv":4.0,"id":31372}]}]}
{"op":"mcm","clk":"11824400592","pt":1723464853617,"mc":[{"id":"1.231699634","rc":[{"batb":[[0,1.65,62.5],[1,1.25,100],[2,1.08,7.83]],"ltp":1.65,"tv":4.0,"id":31372}]}]}
{"op":"mcm","clk":"11824400855","pt":1723464857319,"mc":[{"id":"1.231699634","rc":[{"batb":[[0,1.66,10],[1,1.65,62.5],[2,1.25,100]],"ltp":1.65,"tv":4.0,"id":31372}]}]}
{"op":"mcm","clk":"11824401141","pt":1723464861231,"mc":[{"id":"1.231699634","rc":[{"batb":[[0,1.65,62.5],[1,1.25,100],[2,1.08,7.83]],"ltp":1.65,"tv":4.0,"id":31372}]}]}
{"op":"mcm","clk":"11824401394","pt":1723464864342,"mc":[{"id":"1.231699634","rc":[{"batb":[[0,1.66,10],[1,1.65,62.5],[2,1.25,100]],"ltp":1.65,"tv":4.0,"id":31372}]}]}
{"op":"mcm","clk":"11824401622","pt":1723464867935,"mc":[{"id":"1.231699634","rc":[{"batb":[[0,1.65,62.5],[1,1.25,100],[2,1.08,7.83]],"ltp":1.65,"tv":4.0,"id":31372}]}]}
{"op":"mcm","clk":"11824401775","pt":1723464870455,"mc":[{"id":"1.231699634","rc":[{"batb":[[0,1.66,10],[1,1.65,62.5],[2,1.25,100]],"ltp":1.65,"tv":4.0,"id":31372}]}]}
{"op":"mcm","clk":"11824402042","pt":1723464873956,"mc":[{"id":"1.231699634","rc":[{"batb":[[0,1.65,62.5],[1,1.25,100],[2,1.08,7.83]],"ltp":1.65,"tv":4.0,"id":31372}]}]}
{"op":"mcm","clk":"11824402223","pt":1723464876442,"mc":[{"id":"1.231699634","rc":[{"batb":[[0,1.66,10],[1,1.65,62.5],[2,1.25,100]],"ltp":1.65,"tv":4.0,"id":31372}]}]}
{"op":"mcm","clk":"11824402493","pt":1723464880055,"mc":[{"id":"1.231699634","rc":[{"batb":[[0,1.65,62.5],[1,1.25,100],[2,1.08,7.83]],"ltp":1.65,"tv":4.0,"id":31372}]}]}
{"op":"mcm","clk":"11824402844","pt":1723464883963,"mc":[{"id":"1.231699634","rc":[{"batb":[[0,1.66,10],[1,1.65,62.5],[2,1.25,100]],"ltp":1.65,"tv":4.0,"id":31372}]}]}
{"op":"mcm","clk":"11824403148","pt":1723464888245,"mc":[{"id":"1.231699634","rc":[{"batb":[[0,1.65,62.5],[1,1.25,100],[2,1.08,7.83]],"ltp":1.65,"tv":4.0,"id":31372}]}]}
{"op":"mcm","clk":"11824403475","pt":1723464892685,"mc":[{"id":"1.231699634","rc":[{"batb":[[0,1.66,10],[1,1.65,62.5],[2,1.25,100]],"ltp":1.65,"tv":4.0,"id":31372}]}]}
{"op":"mcm","clk":"11824403805","pt":1723464897363,"mc":[{"id":"1.231699634","rc":[{"batb":[[0,1.65,62.5],[1,1.25,100],[2,1.08,7.83]],"ltp":1.65,"tv":4.0,"id":31372}]}]}
{"op":"mcm","clk":"11824403969","pt":1723464899789,"mc":[{"id":"1.231699634","rc":[{"batb":[[0,1.66,10],[1,1.65,62.5],[2,1.25,100]],"ltp":1.65,"tv":4.0,"id":31372}]}]}
{"op":"mcm","clk":"11824404275","pt":1723464903402,"mc":[{"id":"1.231699634","rc":[{"batb":[[0,1.65,62.5],[1,1.25,100],[2,1.08,7.83]],"ltp":1.65,"tv":4.0,"id":31372}]}]}
{"op":"mcm","clk":"11824404532","pt":1723464906488,"mc":[{"id":"1.231699634","rc":[{"batb":[[0,1.66,10],[1,1.65,62.5],[2,1.25,100]],"ltp":1.65,"tv":4.0,"id":31372}]}]}
{"op":"mcm","clk":"11824404793","pt":1723464909793,"mc":[{"id":"1.231699634","rc":[{"batb":[[0,1.65,62.5],[1,1.25,100],[2,1.08,7.83]],"ltp":1.65,"tv":4.0,"id":31372}]}]}
{"op":"mcm","clk":"11824405166","pt":1723464914076,"mc":[{"id":"1.231699634","rc":[{"batb":[[0,1.66,10],[1,1.65,62.5],[2,1.25,100]],"ltp":1.65,"tv":4.0,"id":31372}]}]}
{"op":"mcm","clk":"11824405493","pt":1723464918399,"mc":[{"id":"1.231699634","rc":[{"batb":[[0,1.65,62.5],[1,1.25,100],[2,1.08,7.83]],"ltp":1.65,"tv":4.0,"id":31372}]}]}
{"op":"mcm","clk":"11824405709","pt":1723464921284,"mc":[{"id":"1.231699634","rc":[{"batb":[[0,1.66,10],[1,1.65,62.5],[2,1.25,100]],"ltp":1.65,"tv":4.0,"id":31372}]}]}
{"op":"mcm","clk":"11824405952","pt":1723464924683,"mc":[{"id":"1.231699634","rc":[{"batb":[[0,1.65,62.5],[1,1.25,100],[2,1.08,7.83]],"ltp":1.65,"tv":4.0,"id":31372}]}]}
{"op":"mcm","clk":"11824406346","pt":1723464929425,"mc":[{"id":"1.231699634","rc":[{"batb":[[0,1.66,10],[1,1.65,62.5],[2,1.25,100]],"ltp":1.65,"tv":4.0,"id":31372}]}]}
{"op":"mcm","clk":"11824406663","pt":1723464933383,"mc":[{"id":"1.231699634","rc":[{"batb":[[0,1.65,62.5],[1,1.25,100],[2,1.08,7.83]],"ltp":1.65,"tv":4.0,"id":31372}]}]}
{"op":"mcm","clk":"11824406821","pt":1723464935693,"mc":[{"id":"1.231699634","rc":[{"batb":[[0,1.66,10],[1,1.65,62.5],[2,1.25,100]],"ltp":1.65,"tv":4.0,"id":31372}]}]}
{"op":"mcm","clk":"11824407054","pt":1723464939093,"mc":[{"id":"1.231699634","rc":[{"batb":[[0,1.65,62.5],[1,1.25,100],[2,1.08,7.83]],"ltp":1.65,"tv":4.0,"id":31372}]}]}
{"op":"mcm","clk":"11824407240","pt":1723464942436,"mc":[{"id":"1.231699634","rc":[{"batb":[[0,1.66,10],[1,1.65,62.5],[2,1.25,100]],"ltp":1.65,"tv":4.0,"id":31372}]}]}
{"op":"mcm","clk":"11824407478","pt":1723464945833,"mc":[{"id":"1.231699634","rc":[{"batb":[[0,1.65,62.5],[1,1.25,100],[2,1.08,7.83]],"ltp":1.65,"tv":4.0,"id":31372}]}]}
{"op":"mcm","clk":"11824407708","pt":1723464948713,"mc":[{"id":"1.231699634","rc":[{"batb":[[0,1.66,10],[1,1.65,62.5],[2,1.25,100]],"ltp":1.65,"tv":4.0,"id":31372}]}]}
{"op":"mcm","clk":"11824408044","pt":1723464953453,"mc":[{"id":"1.231699634","rc":[{"batb":[[0,1.65,62.5],[1,1.25,100],[2,1.08,7.83]],"ltp":1.65,"tv":4.0,"id":31372}]}]}
{"op":"mcm","clk":"11824408275","pt":1723464956444,"mc":[{"id":"1.231699634","rc":[{"batb":[[0,1.66,10],[1,1.65,62.5],[2,1.25,100]],"ltp":1.65,"tv":4.0,"id":31372}]}]}
{"op":"mcm","clk":"11824408562","pt":1723464959949,"mc":[{"id":"1.231699634","rc":[{"batb":[[0,1.65,62.5],[1,1.25,100],[2,1.08,7.83]],"ltp":1.65,"tv":4.0,"id":31372}]}]}
{"op":"mcm","clk":"11824408741","pt":1723464962169,"mc":[{"id":"1.231699634","rc":[{"batb":[[0,1.66,10],[1,1.65,62.5],[2,1.25,100]],"ltp":1.65,"tv":4.0,"id":31372}]}]}
{"op":"mcm","clk":"11824409112","pt":1723464966352,"mc":[{"id":"1.231699634","rc":[{"batb":[[0,1.65,62.5],[1,1.25,100],[2,1.08,7.83]],"ltp":1.65,"tv":4.0,"id":31372}]}]}
{"op":"mcm","clk":"11824409391","pt":1723464969448,"mc":[{"id":"1.231699634","rc":[{"batb":[[0,1.66,10],[1,1.65,62.5],[2,1.25,100]],"ltp":1.65,"tv":4.0,"id":31372}]}]}
{"op":"mcm","clk":"11824409641","pt":1723464972847,"mc":[{"id":"1.231699634","rc":[{"batb":[[0,1.65,62.5],[1,1.25,100],[2,1.08,7.83]],"ltp":1.65,"tv":4.0,"id":31372}]}]}
{"op":"mcm","clk":"11824409893","pt":1723464975840,"mc":[{"id":"1.231699634","rc":[{"batb":[[0,1.66,10],[1,1.65,62.5],[2,1.25,100]],"ltp":1.65,"tv":4.0,"id":31372}]}]}
{"op":"mcm","clk":"11824410147","pt":1723464979182,"mc":[{"id":"1.231699634","rc":[{"batb":[[0,1.65,62.5],[1,1.25,100],[2,1.08,7.83]],"ltp":1.65,"tv":4.0,"id":31372}]}]}
{"op":"mcm","clk":"11824410495","pt":1723464983360,"mc":[{"id":"1.231699634","rc":[{"batb":[[0,1.66,10],[1,1.65,62.5],[2,1.25,100]],"ltp":1.65,"tv":4.0,"id":31372}]}]}
{"op":"mcm","clk":"11824410885","pt":1723464987480,"mc":[{"id":"1.231699634","rc":[{"batb":[[0,1.65,62.5],[1,1.25,100],[2,1.08,7.83]],"ltp":1.65,"tv":4.0,"id":31372}]}]}
{"op":"mcm","clk":"11824411279","pt":1723464991967,"mc":[{"id":"1.231699634","rc":[{"batb":[[0,1.66,10],[1,1.65,62.5],[2,1.25,100]],"ltp":1.65,"tv":4.0,"id":31372}]}]}
{"op":"mcm","clk":"11824411587","pt":1723464995277,"mc":[{"id":"1.231699634","rc":[{"batb":[[0,1.65,62.5],[1,1.25,100],[2,1.08,7.83]],"ltp":1.65,"tv":4.0,"id":31372}]}]}
{"op":"mcm","clk":"11824411763","pt":1723464997696,"mc":[{"id":"1.231699634","rc":[{"batb":[[0,1.67,10],[1,1.65,62.5],[2,1.25,100]],"ltp":1.65,"tv":4.0,"id":31372}]}]}
{"op":"mcm","clk":"11824412098","pt":1723465002189,"mc":[{"id":"1.231699634","rc":[{"batb":[[0,1.65,62.5],[1,1.25,100],[2,1.08,7.83]],"ltp":1.65,"tv":4.0,"id":31372}]}]}
{"op":"mcm","clk":"11824412417","pt":1723465006514,"mc":[{"id":"1.231699634","rc":[{"batb":[[0,1.66,10],[1,1.65,62.5],[2,1.25,100]],"ltp":1.65,"tv":4.0,"id":31372}]}]}
{"op":"mcm","clk":"11824412686","pt":1723465009912,"mc":[{"id":"1.231699634","rc":[{"batb":[[0,1.65,62.5],[1,1.25,100],[2,1.08,7.83]],"ltp":1.65,"tv":4.0,"id":31372}]}]}
{"op":"mcm","clk":"11824412910","pt":1723465012400,"mc":[{"id":"1.231699634","rc":[{"batb":[[0,1.66,10],[1,1.65,62.5],[2,1.25,100]],"ltp":1.65,"tv":4.0,"id":31372}]}]}
{"op":"mcm","clk":"11824413491","pt":1723465019320,"mc":[{"id":"1.231699634","rc":[{"batb":[[0,1.65,62.5],[1,1.25,100],[2,1.08,7.83]],"ltp":1.65,"tv":4.0,"id":31372}]}]}
{"op":"mcm","clk":"11824413700","pt":1723465022016,"mc":[{"id":"1.231699634","rc":[{"batb":[[0,1.67,10],[1,1.65,62.5],[2,1.25,100]],"ltp":1.65,"tv":4.0,"id":31372}]}]}
{"op":"mcm","clk":"11824414173","pt":1723465028219,"mc":[{"id":"1.231699634","rc":[{"batb":[[0,1.65,62.5],[1,1.25,100],[2,1.08,7.83]],"ltp":1.65,"tv":4.0,"id":31372}]}]}
{"op":"mcm","clk":"11824414345","pt":1723465030503,"mc":[{"id":"1.231699634","rc":[{"batb":[[0,1.68,10],[1,1.65,62.5],[2,1.25,100]],"ltp":1.65,"tv":4.0,"id":31372}]}]}
{"op":"mcm","clk":"11824414738","pt":1723465035208,"mc":[{"id":"1.231699634","rc":[{"batb":[[0,1.65,62.5],[1,1.25,100],[2,1.08,7.83]],"ltp":1.65,"tv":4.0,"id":31372}]}]}
{"op":"mcm","clk":"11824414929","pt":1723465037862,"mc":[{"id":"1.231699634","rc":[{"batb":[[0,1.66,10],[1,1.65,62.5],[2,1.25,100]],"ltp":1.65,"tv":4.0,"id":31372}]}]}
{"op":"mcm","clk":"11824415233","pt":1723465041254,"mc":[{"id":"1.231699634","rc":[{"batb":[[0,1.65,62.5],[1,1.25,100],[2,1.08,7.83]],"ltp":1.65,"tv":4.0,"id":31372}]}]}
{"op":"mcm","clk":"11824415419","pt":1723465043694,"mc":[{"id":"1.231699634","rc":[{"batb":[[0,1.66,10],[1,1.65,62.5],[2,1.25,100]],"ltp":1.65,"tv":4.0,"id":31372}]}]}
{"op":"mcm","clk":"11824415680","pt":1723465047068,"mc":[{"id":"1.231699634","rc":[{"batb":[[0,1.65,62.5],[1,1.25,100],[2,1.08,7.83]],"ltp":1.65,"tv":4.0,"id":31372}]}]}
{"op":"mcm","clk":"11824415905","pt":1723465050049,"mc":[{"id":"1.231699634","rc":[{"batb":[[0,1.66,10],[1,1.65,62.5],[2,1.25,100]],"ltp":1.65,"tv":4.0,"id":31372}]}]}
{"op":"mcm","clk":"11824416149","pt":1723465053438,"mc":[{"id":"1.231699634","rc":[{"batb":[[0,1.65,62.5],[1,1.25,100],[2,1.08,7.83]],"ltp":1.65,"tv":4.0,"id":31372}]}]}
{"op":"mcm","clk":"11824416376","pt":1723465056624,"mc":[{"id":"1.231699634","rc":[{"batb":[[0,1.66,10],[1,1.65,62.5],[2,1.25,100]],"ltp":1.65,"tv":4.0,"id":31372}]}]}
{"op":"mcm","clk":"11824416568","pt":1723465059860,"mc":[{"id":"1.231699634","rc":[{"batb":[[0,1.65,62.5],[1,1.25,100],[2,1.08,7.83]],"ltp":1.65,"tv":4.0,"id":31372}]}]}
{"op":"mcm","clk":"11824416717","pt":1723465062220,"mc":[{"id":"1.231699634","rc":[{"batb":[[0,1.66,10],[1,1.65,62.5],[2,1.25,100]],"ltp":1.65,"tv":4.0,"id":31372}]}]}
{"op":"mcm","clk":"11824416995","pt":1723465065747,"mc":[{"id":"1.231699634","rc":[{"batb":[[0,1.65,62.5],[1,1.25,100],[2,1.08,7.83]],"ltp":1.65,"tv":4.0,"id":31372}]}]}
{"op":"mcm","clk":"11824417448","pt":1723465071769,"mc":[{"id":"1.231699634","rc":[{"batb":[[0,1.66,10],[1,1.65,62.5],[2,1.25,100]],"ltp":1.65,"tv":4.0,"id":31372}]}]}
{"op":"mcm","clk":"11824417763","pt":1723465075784,"mc":[{"id":"1.231699634","rc":[{"batb":[[0,1.65,62.5],[1,1.25,100],[2,1.08,7.83]],"ltp":1.65,"tv":4.0,"id":31372}]}]}
{"op":"mcm","clk":"11824417943","pt":1723465078198,"mc":[{"id":"1.231699634","rc":[{"batb":[[0,1.66,10],[1,1.65,62.5],[2,1.25,100]],"ltp":1.65,"tv":4.0,"id":31372}]}]}
{"op":"mcm","clk":"11824418208","pt":1723465081698,"mc":[{"id":"1.231699634","rc":[{"batb":[[0,1.65,62.5],[1,1.25,100],[2,1.08,7.83]],"ltp":1.65,"tv":4.0,"id":31372}]}]}
{"op":"mcm","clk":"11824418376","pt":1723465083965,"mc":[{"id":"1.231699634","rc":[{"batb":[[0,1.66,10],[1,1.65,62.5],[2,1.25,100]],"ltp":1.65,"tv":4.0,"id":31372}]}]}
{"op":"mcm","clk":"11824418612","pt":1723465087303,"mc":[{"id":"1.231699634","rc":[{"batb":[[0,1.65,62.5],[1,1.25,100],[2,1.08,7.83]],"ltp":1.65,"tv":4.0,"id":31372}]}]}
{"op":"mcm","clk":"11824418820","pt":1723465090436,"mc":[{"id":"1.231699634","rc":[{"batb":[[0,1.66,10],[1,1.65,62.5],[2,1.25,100]],"ltp":1.65,"tv":4.0,"id":31372}]}]}
{"op":"mcm","clk":"11824419080","pt":1723465093625,"mc":[{"id":"1.231699634","rc":[{"batb":[[0,1.65,62.5],[1,1.25,100],[2,1.08,7.83]],"ltp":1.65,"tv":4.0,"id":31372}]}]}
{"op":"mcm","clk":"11824419433","pt":1723465098420,"mc":[{"id":"1.231699634","rc":[{"batb":[[0,1.66,10],[1,1.65,62.5],[2,1.25,100]],"ltp":1.65,"tv":4.0,"id":31372}]}]}
{"op":"mcm","clk":"11824419725","pt":1723465102640,"mc":[{"id":"1.231699634","rc":[{"batb":[[0,1.65,62.5],[1,1.25,100],[2,1.08,7.83]],"ltp":1.65,"tv":4.0,"id":31372}]}]}
{"op":"mcm","clk":"11824419974","pt":1723465105632,"mc":[{"id":"1.231699634","rc":[{"batb":[[0,1.66,10],[1,1.65,62.5],[2,1.25,100]],"ltp":1.65,"tv":4.0,"id":31372}]}]}
{"op":"mcm","clk":"11824420245","pt":1723465109029,"mc":[{"id":"1.231699634","rc":[{"batb":[[0,1.65,62.5],[1,1.25,100],[2,1.08,7.83]],"ltp":1.65,"tv":4.0,"id":31372}]}]}
{"op":"mcm","clk":"11824420437","pt":1723465111242,"mc":[{"id":"1.231699634","rc":[{"batb":[[0,1.66,10],[1,1.65,62.5],[2,1.25,100]],"ltp":1.65,"tv":4.0,"id":31372}]}]}
{"op":"mcm","clk":"11824420707","pt":1723465114550,"mc":[{"id":"1.231699634","rc":[{"batb":[[0,1.65,62.5],[1,1.25,100],[2,1.08,7.83]],"ltp":1.65,"tv":4.0,"id":31372}]}]}
{"op":"mcm","clk":"11824420986","pt":1723465118337,"mc":[{"id":"1.231699634","rc":[{"batb":[[0,1.66,10],[1,1.65,62.5],[2,1.25,100]],"ltp":1.65,"tv":4.0,"id":31372}]}]}
{"op":"mcm","clk":"11824421301","pt":1723465122761,"mc":[{"id":"1.231699634","rc":[{"batb":[[0,1.65,62.5],[1,1.25,100],[2,1.08,7.83]],"ltp":1.65,"tv":4.0,"id":31372}]}]}
{"op":"mcm","clk":"11824421473","pt":1723465124966,"mc":[{"id":"1.231699634","rc":[{"batb":[[0,1.66,10],[1,1.65,62.5],[2,1.25,100]],"ltp":1.65,"tv":4.0,"id":31372}]}]}
{"op":"mcm","clk":"11824421696","pt":1723465128358,"mc":[{"id":"1.231699634","rc":[{"batb":[[0,1.65,62.5],[1,1.25,100],[2,1.08,7.83]],"ltp":1.65,"tv":4.0,"id":31372}]}]}
{"op":"mcm","clk":"11824421878","pt":1723465130933,"mc":[{"id":"1.231699634","rc":[{"batb":[[0,1.66,10],[1,1.65,62.5],[2,1.25,100]],"ltp":1.65,"tv":4.0,"id":31372}]}]}
{"op":"mcm","clk":"11824422112","pt":1723465134177,"mc":[{"id":"1.231699634","rc":[{"batb":[[0,1.65,62.5],[1,1.25,100],[2,1.08,7.83]],"ltp":1.65,"tv":4.0,"id":31372}]}]}
{"op":"mcm","clk":"11824422268","pt":1723465136458,"mc":[{"id":"1.231699634","rc":[{"batb":[[0,1.66,10],[1,1.65,62.5],[2,1.25,100]],"ltp":1.65,"tv":4.0,"id":31372}]}]}
{"op":"mcm","clk":"11824422600","pt":1723465140468,"mc":[{"id":"1.231699634","rc":[{"batb":[[0,1.65,62.5],[1,1.25,100],[2,1.08,7.83]],"ltp":1.65,"tv":4.0,"id":31372}]}]}
{"op":"mcm","clk":"11824422911","pt":1723465144073,"mc":[{"id":"1.231699634","rc":[{"batb":[[0,1.66,10],[1,1.65,62.5],[2,1.25,100]],"ltp":1.65,"tv":4.0,"id":31372}]}]}
{"op":"mcm","clk":"11824423163","pt":1723465147368,"mc":[{"id":"1.231699634","rc":[{"batb":[[0,1.65,62.5],[1,1.25,100],[2,1.08,7.83]],"ltp":1.65,"tv":4.0,"id":31372}]}]}
{"op":"mcm","clk":"11824423371","pt":1723465150091,"mc":[{"id":"1.231699634","rc":[{"batb":[[0,1.66,10],[1,1.65,62.5],[2,1.25,100]],"ltp":1.65,"tv":4.0,"id":31372}]}]}
{"op":"mcm","clk":"11824423786","pt":1723465155592,"mc":[{"id":"1.231699634","rc":[{"batb":[[0,1.65,62.5],[1,1.25,100],[2,1.08,7.83]],"ltp":1.65,"tv":4.0,"id":31372}]}]}
{"op":"mcm","clk":"11824423963","pt":1723465158472,"mc":[{"id":"1.231699634","rc":[{"batb":[[0,1.66,10],[1,1.65,62.5],[2,1.25,100]],"ltp":1.65,"tv":4.0,"id":31372}]}]}
{"op":"mcm","clk":"11824424154","pt":1723465161900,"mc":[{"id":"1.231699634","rc":[{"batb":[[0,1.65,62.5],[1,1.25,100],[2,1.08,7.83]],"ltp":1.65,"tv":4.0,"id":31372}]}]}
{"op":"mcm","clk":"11824424444","pt":1723465165903,"mc":[{"id":"1.231699634","rc":[{"batb":[[0,1.66,10],[1,1.65,62.5],[2,1.25,100]],"ltp":1.65,"tv":4.0,"id":31372}]}]}
{"op":"mcm","clk":"11824424718","pt":1723465170413,"mc":[{"id":"1.231699634","rc":[{"batb":[[0,1.65,62.5],[1,1.25,100],[2,1.08,7.83]],"ltp":1.65,"tv":4.0,"id":31372}]}]}
{"op":"mcm","clk":"11824424905","pt":1723465173492,"mc":[{"id":"1.231699634","rc":[{"batb":[[0,1.66,10],[1,1.65,62.5],[2,1.25,100]],"ltp":1.65,"tv":4.0,"id":31372}]}]}
{"op":"mcm","clk":"11824425144","pt":1723465176897,"mc":[{"id":"1.231699634","rc":[{"batb":[[0,1.65,62.5],[1,1.25,100],[2,1.08,7.83]],"ltp":1.65,"tv":4.0,"id":31372}]}]}
{"op":"mcm","clk":"11824425365","pt":1723465180129,"mc":[{"id":"1.231699634","rc":[{"batb":[[0,1.66,10],[1,1.65,62.5],[2,1.25,100]],"ltp":1.65,"tv":4.0,"id":31372}]}]}
{"op":"mcm","clk":"11824425628","pt":1723465184546,"mc":[{"id":"1.231699634","rc":[{"batb":[[0,1.65,62.5],[1,1.25,100],[2,1.08,7.83]],"ltp":1.65,"tv":4.0,"id":31372}]}]}
{"op":"mcm","clk":"11824425798","pt":1723465187014,"mc":[{"id":"1.231699634","rc":[{"batb":[[0,1.66,10],[1,1.65,62.5],[2,1.25,100]],"ltp":1.65,"tv":4.0,"id":31372}]}]}
{"op":"mcm","clk":"11824426039","pt":1723465190911,"mc":[{"id":"1.231699634","rc":[{"batb":[[0,1.65,62.5],[1,1.25,100],[2,1.08,7.83]],"ltp":1.65,"tv":4.0,"id":31372}]}]}
{"op":"mcm","clk":"11824426206","pt":1723465193013,"mc":[{"id":"1.231699634","rc":[{"batb":[[0,1.66,10],[1,1.65,62.5],[2,1.25,100]],"ltp":1.65,"tv":4.0,"id":31372}]}]}
{"op":"mcm","clk":"11824426494","pt":1723465196610,"mc":[{"id":"1.231699634","rc":[{"batb":[[0,1.65,62.5],[1,1.25,100],[2,1.08,7.83]],"ltp":1.65,"tv":4.0,"id":31372}]}]}
{"op":"mcm","clk":"11824426676","pt":1723465199013,"mc":[{"id":"1.231699634","rc":[{"batb":[[0,1.67,10],[1,1.65,62.5],[2,1.25,100]],"ltp":1.65,"tv":4.0,"id":31372}]}]}
{"op":"mcm","clk":"11824427003","pt":1723465203434,"mc":[{"id":"1.231699634","rc":[{"batb":[[0,1.65,62.5],[1,1.25,100],[2,1.08,7.83]],"ltp":1.65,"tv":4.0,"id":31372}]}]}
{"op":"mcm","clk":"11824427175","pt":1723465205745,"mc":[{"id":"1.231699634","rc":[{"batb":[[0,1.66,10],[1,1.65,62.5],[2,1.25,100]],"ltp":1.65,"tv":4.0,"id":31372}]}]}
{"op":"mcm","clk":"11824427410","pt":1723465209346,"mc":[{"id":"1.231699634","rc":[{"batb":[[0,1.65,62.5],[1,1.25,100],[2,1.08,7.83]],"ltp":1.65,"tv":4.0,"id":31372}]}]}
{"op":"mcm","clk":"11824427714","pt":1723465213962,"mc":[{"id":"1.231699634","rc":[{"batb":[[0,1.66,10],[1,1.65,62.5],[2,1.25,100]],"ltp":1.65,"tv":4.0,"id":31372}]}]}
{"op":"mcm","clk":"11824427950","pt":1723465217664,"mc":[{"id":"1.231699634","rc":[{"batb":[[0,1.65,62.5],[1,1.25,100],[2,1.08,7.83]],"ltp":1.65,"tv":4.0,"id":31372}]}]}
{"op":"mcm","clk":"11824428203","pt":1723465221780,"mc":[{"id":"1.231699634","rc":[{"batb":[[0,1.66,10],[1,1.65,62.5],[2,1.25,100]],"ltp":1.65,"tv":4.0,"id":31372}]}]}
{"op":"mcm","clk":"11824428426","pt":1723465225439,"mc":[{"id":"1.231699634","rc":[{"batb":[[0,1.65,62.5],[1,1.25,100],[2,1.08,7.83]],"ltp":1.65,"tv":4.0,"id":31372}]}]}
{"op":"mcm","clk":"11824428643","pt":1723465228774,"mc":[{"id":"1.231699634","rc":[{"batb":[[0,1.66,10],[1,1.65,62.5],[2,1.25,100]],"ltp":1.65,"tv":4.0,"id":31372}]}]}
{"op":"mcm","clk":"11824428926","pt":1723465233756,"mc":[{"id":"1.231699634","rc":[{"batb":[[0,1.65,62.5],[1,1.25,100],[2,1.08,7.83]],"ltp":1.65,"tv":4.0,"id":31372}]}]}
{"op":"mcm","clk":"11824429081","pt":1723465236372,"mc":[{"id":"1.231699634","rc":[{"batb":[[0,1.66,10],[1,1.65,62.5],[2,1.25,100]],"ltp":1.65,"tv":4.0,"id":31372}]}]}
{"op":"mcm","clk":"11824429304","pt":1723465239717,"mc":[{"id":"1.231699634","rc":[{"batb":[[0,1.65,62.5],[1,1.25,100],[2,1.08,7.83]],"ltp":1.65,"tv":4.0,"id":31372}]}]}
{"op":"mcm","clk":"11824429475","pt":1723465242491,"mc":[{"id":"1.231699634","rc":[{"batb":[[0,1.66,10],[1,1.65,62.5],[2,1.25,100]],"ltp":1.65,"tv":4.0,"id":31372}]}]}
{"op":"mcm","clk":"11824429710","pt":1723465245785,"mc":[{"id":"1.231699634","rc":[{"batb":[[0,1.65,62.5],[1,1.25,100],[2,1.08,7.83]],"ltp":1.65,"tv":4.0,"id":31372}]}]}
{"op":"mcm","clk":"11824429912","pt":1723465248870,"mc":[{"id":"1.231699634","rc":[{"batb":[[0,1.66,10],[1,1.65,62.5],[2,1.25,100]],"ltp":1.65,"tv":4.0,"id":31372}]}]}
{"op":"mcm","clk":"11824430087","pt":1723465252201,"mc":[{"id":"1.231699634","rc":[{"batb":[[0,1.65,62.5],[1,1.25,100],[2,1.08,7.83]],"ltp":1.65,"tv":4.0,"id":31372}]}]}
{"op":"mcm","clk":"11824430263","pt":1723465255285,"mc":[{"id":"1.231699634","rc":[{"batb":[[0,1.66,10],[1,1.65,62.5],[2,1.25,100]],"ltp":1.65,"tv":4.0,"id":31372}]}]}
{"op":"mcm","clk":"11824430527","pt":1723465258791,"mc":[{"id":"1.231699634","rc":[{"batb":[[0,1.65,62.5],[1,1.25,100],[2,1.08,7.83]],"ltp":1.65,"tv":4.0,"id":31372}]}]}
{"op":"mcm","clk":"11824430683","pt":1723465260996,"mc":[{"id":"1.231699634","rc":[{"batb":[[0,1.66,10],[1,1.65,62.5],[2,1.25,100]],"ltp":1.65,"tv":4.0,"id":31372}]}]}
{"op":"mcm","clk":"11824430912","pt":1723465264525,"mc":[{"id":"1.231699634","rc":[{"batb":[[0,1.65,62.5],[1,1.25,100],[2,1.08,7.83]],"ltp":1.65,"tv":4.0,"id":31372}]}]}
{"op":"mcm","clk":"11824431157","pt":1723465267918,"mc":[{"id":"1.231699634","rc":[{"batb":[[0,1.66,10],[1,1.65,62.5],[2,1.25,100]],"ltp":1.65,"tv":4.0,"id":31372}]}]}
{"op":"mcm","clk":"11824431343","pt":1723465271103,"mc":[{"id":"1.231699634","rc":[{"batb":[[0,1.65,62.5],[1,1.25,100],[2,1.08,7.83]],"ltp":1.65,"tv":4.0,"id":31372}]}]}
{"op":"mcm","clk":"11824431492","pt":1723465273430,"mc":[{"id":"1.231699634","rc":[{"batb":[[0,1.66,10],[1,1.65,62.5],[2,1.25,100]],"ltp":1.65,"tv":4.0,"id":31372}]}]}
{"op":"mcm","clk":"11824431711","pt":1723465277118,"mc":[{"id":"1.231699634","rc":[{"batb":[[0,1.65,62.5],[1,1.25,100],[2,1.08,7.83]],"ltp":1.65,"tv":4.0,"id":31372}]}]}
{"op":"mcm","clk":"11824431894","pt":1723465280144,"mc":[{"id":"1.231699634","rc":[{"batb":[[0,1.66,10],[1,1.65,62.5],[2,1.25,100]],"ltp":1.65,"tv":4.0,"id":31372}]}]}
{"op":"mcm","clk":"11824432159","pt":1723465284059,"mc":[{"id":"1.231699634","rc":[{"batb":[[0,1.65,62.5],[1,1.25,100],[2,1.08,7.83]],"ltp":1.65,"tv":4.0,"id":31372}]}]}
{"op":"mcm","clk":"11824432329","pt":1723465286529,"mc":[{"id":"1.231699634","rc":[{"batb":[[0,1.66,10],[1,1.65,62.5],[2,1.25,100]],"ltp":1.65,"tv":4.0,"id":31372}]}]}
{"op":"mcm","clk":"11824432536","pt":1723465289921,"mc":[{"id":"1.231699634","rc":[{"batb":[[0,1.65,62.5],[1,1.25,100],[2,1.08,7.83]],"ltp":1.65,"tv":4.0,"id":31372}]}]}
{"op":"mcm","clk":"11824433017","pt":1723465297367,"mc":[{"id":"1.231699634","rc":[{"batb":[[0,1.66,10],[1,1.65,62.5],[2,1.25,100]],"ltp":1.65,"tv":4.0,"id":31372}]}]}
{"op":"mcm","clk":"11824433301","pt":1723465301944,"mc":[{"id":"1.231699634","rc":[{"batb":[[0,1.65,62.5],[1,1.25,100],[2,1.08,7.83]],"ltp":1.65,"tv":4.0,"id":31372}]}]}
{"op":"mcm","clk":"11824433459","pt":1723465304558,"mc":[{"id":"1.231699634","rc":[{"batb":[[0,1.66,10],[1,1.65,62.5],[2,1.25,100]],"ltp":1.65,"tv":4.0,"id":31372}]}]}
{"op":"mcm","clk":"11824433676","pt":1723465307961,"mc":[{"id":"1.231699634","rc":[{"batb":[[0,1.65,62.5],[1,1.25,100],[2,1.08,7.83]],"ltp":1.65,"tv":4.0,"id":31372}]}]}
{"op":"mcm","clk":"11824433882","pt":1723465311240,"mc":[{"id":"1.231699634","rc":[{"batb":[[0,1.66,10],[1,1.65,62.5],[2,1.25,100]],"ltp":1.65,"tv":4.0,"id":31372}]}]}
{"op":"mcm","clk":"11824434085","pt":1723465314566,"mc":[{"id":"1.231699634","rc":[{"batb":[[0,1.65,62.5],[1,1.25,100],[2,1.08,7.83]],"ltp":1.65,"tv":4.0,"id":31372}]}]}
{"op":"mcm","clk":"11824434234","pt":1723465316976,"mc":[{"id":"1.231699634","rc":[{"batb":[[0,1.66,10],[1,1.65,62.5],[2,1.25,100]],"ltp":1.65,"tv":4.0,"id":31372}]}]}
{"op":"mcm","clk":"11824434547","pt":1723465321563,"mc":[{"id":"1.231699634","rc":[{"batb":[[0,1.65,62.5],[1,1.25,100],[2,1.08,7.83]],"ltp":1.65,"tv":4.0,"id":31372}]}]}
{"op":"mcm","clk":"11824434719","pt":1723465324402,"mc":[{"id":"1.231699634","rc":[{"batb":[[0,1.66,10],[1,1.65,62.5],[2,1.25,100]],"ltp":1.65,"tv":4.0,"id":31372}]}]}
{"op":"mcm","clk":"11824434945","pt":1723465327690,"mc":[{"id":"1.231699634","rc":[{"batb":[[0,1.65,62.5],[1,1.25,100],[2,1.08,7.83]],"ltp":1.65,"tv":4.0,"id":31372}]}]}
{"op":"mcm","clk":"11824435209","pt":1723465331599,"mc":[{"id":"1.231699634","rc":[{"batb":[[0,1.66,10],[1,1.65,62.5],[2,1.25,100]],"ltp":1.65,"tv":4.0,"id":31372}]}]}
{"op":"mcm","clk":"11824435464","pt":1723465335609,"mc":[{"id":"1.231699634","rc":[{"batb":[[0,1.65,62.5],[1,1.25,100],[2,1.08,7.83]],"ltp":1.65,"tv":4.0,"id":31372}]}]}
{"op":"mcm","clk":"11824435629","pt":1723465337976,"mc":[{"id":"1.231699634","rc":[{"batb":[[0,1.66,10],[1,1.65,62.5],[2,1.25,100]],"ltp":1.65,"tv":4.0,"id":31372}]}]}
{"op":"mcm","clk":"11824435833","pt":1723465341306,"mc":[{"id":"1.231699634","rc":[{"batb":[[0,1.65,62.5],[1,1.25,100],[2,1.08,7.83]],"ltp":1.65,"tv":4.0,"id":31372}]}]}
{"op":"mcm","clk":"11824436034","pt":1723465344386,"mc":[{"id":"1.231699634","rc":[{"batb":[[0,1.66,10],[1,1.65,62.5],[2,1.25,100]],"ltp":1.65,"tv":4.0,"id":31372}]}]}
{"op":"mcm","clk":"11824436337","pt":1723465349113,"mc":[{"id":"1.231699634","rc":[{"batb":[[0,1.65,62.5],[1,1.25,100],[2,1.08,7.83]],"ltp":1.65,"tv":4.0,"id":31372}]}]}
{"op":"mcm","clk":"11824436527","pt":1723465351327,"mc":[{"id":"1.231699634","rc":[{"batb":[[0,1.66,10],[1,1.65,62.5],[2,1.25,100]],"ltp":1.65,"tv":4.0,"id":31372}]}]}
{"op":"mcm","clk":"11824436745","pt":1723465354708,"mc":[{"id":"1.231699634","rc":[{"batb":[[0,1.65,62.5],[1,1.25,100],[2,1.08,7.83]],"ltp":1.65,"tv":4.0,"id":31372}]}]}
{"op":"mcm","clk":"11824436913","pt":1723465357277,"mc":[{"id":"1.231699634","rc":[{"batb":[[0,1.66,10],[1,1.65,62.5],[2,1.25,100]],"ltp":1.65,"tv":4.0,"id":31372}]}]}
{"op":"mcm","clk":"11824437135","pt":1723465360611,"mc":[{"id":"1.231699634","rc":[{"batb":[[0,1.65,62.5],[1,1.25,100],[2,1.08,7.83]],"ltp":1.65,"tv":4.0,"id":31372}]}]}
{"op":"mcm","clk":"11824437338","pt":1723465363233,"mc":[{"id":"1.231699634","rc":[{"batb":[[0,1.66,10],[1,1.65,62.5],[2,1.25,100]],"ltp":1.65,"tv":4.0,"id":31372}]}]}
{"op":"mcm","clk":"11824437588","pt":1723465367038,"mc":[{"id":"1.231699634","rc":[{"batb":[[0,1.65,62.5],[1,1.25,100],[2,1.08,7.83]],"ltp":1.65,"tv":4.0,"id":31372}]}]}
{"op":"mcm","clk":"11824437779","pt":1723465370216,"mc":[{"id":"1.231699634","rc":[{"batb":[[0,1.66,10],[1,1.65,62.5],[2,1.25,100]],"ltp":1.65,"tv":4.0,"id":31372}]}]}
{"op":"mcm","clk":"11824438023","pt":1723465373508,"mc":[{"id":"1.231699634","rc":[{"batb":[[0,1.65,62.5],[1,1.25,100],[2,1.08,7.83]],"ltp":1.65,"tv":4.0,"id":31372}]}]}
{"op":"mcm","clk":"11824438184","pt":1723465376019,"mc":[{"id":"1.231699634","rc":[{"batb":[[0,1.66,10],[1,1.65,62.5],[2,1.25,100]],"ltp":1.65,"tv":4.0,"id":31372}]}]}
{"op":"mcm","clk":"11824438513","pt":1723465380543,"mc":[{"id":"1.231699634","rc":[{"batb":[[0,1.65,62.5],[1,1.25,100],[2,1.08,7.83]],"ltp":1.65,"tv":4.0,"id":31372}]}]}
{"op":"mcm","clk":"11824438715","pt":1723465383021,"mc":[{"id":"1.231699634","rc":[{"batb":[[0,1.67,10],[1,1.65,62.5],[2,1.25,100]],"ltp":1.65,"tv":4.0,"id":31372}]}]}
{"op":"mcm","clk":"11824439162","pt":1723465389465,"mc":[{"id":"1.231699634","rc":[{"batb":[[0,1.65,62.5],[1,1.25,100],[2,1.08,7.83]],"ltp":1.65,"tv":4.0,"id":31372}]}]}
{"op":"mcm","clk":"11824439582","pt":1723465395430,"mc":[{"id":"1.231699634","rc":[{"batb":[[0,1.66,10],[1,1.65,62.5],[2,1.25,100]],"ltp":1.65,"tv":4.0,"id":31372}]}]}
{"op":"mcm","clk":"11824439919","pt":1723465399757,"mc":[{"id":"1.231699634","rc":[{"batb":[[0,1.65,62.5],[1,1.25,100],[2,1.08,7.83]],"ltp":1.65,"tv":4.0,"id":31372}]}]}
{"op":"mcm","clk":"11824440171","pt":1723465403048,"mc":[{"id":"1.231699634","rc":[{"batb":[[0,1.66,10],[1,1.65,62.5],[2,1.25,100]],"ltp":1.65,"tv":4.0,"id":31372}]}]}
{"op":"mcm","clk":"11824440570","pt":1723465408092,"mc":[{"id":"1.231699634","rc":[{"batb":[[0,1.65,62.5],[1,1.25,100],[2,1.08,7.83]],"ltp":1.65,"tv":4.0,"id":31372}]}]}
{"op":"mcm","clk":"11824440786","pt":1723465411587,"mc":[{"id":"1.231699634","rc":[{"batb":[[0,1.66,10],[1,1.65,62.5],[2,1.25,100]],"ltp":1.65,"tv":4.0,"id":31372}]}]}
{"op":"mcm","clk":"11824441157","pt":1723465416682,"mc":[{"id":"1.231699634","rc":[{"batb":[[0,1.65,62.5],[1,1.25,100],[2,1.08,7.83]],"ltp":1.65,"tv":4.0,"id":31372}]}]}
{"op":"mcm","clk":"11824441649","pt":1723465423581,"mc":[{"id":"1.231699634","rc":[{"batb":[[0,1.66,10],[1,1.65,62.5],[2,1.25,100]],"ltp":1.65,"tv":4.0,"id":31372}]}]}
{"op":"mcm","clk":"11824441947","pt":1723465427892,"mc":[{"id":"1.231699634","rc":[{"batb":[[0,1.65,62.5],[1,1.25,100],[2,1.08,7.83]],"ltp":1.65,"tv":4.0,"id":31372}]}]}
{"op":"mcm","clk":"11824442231","pt":1723465432409,"mc":[{"id":"1.231699634","rc":[{"batb":[[0,1.66,10],[1,1.65,62.5],[2,1.25,100]],"ltp":1.65,"tv":4.0,"id":31372}]}]}
{"op":"mcm","clk":"11824442471","pt":1723465435915,"mc":[{"id":"1.231699634","rc":[{"batb":[[0,1.65,62.5],[1,1.25,100],[2,1.08,7.83]],"ltp":1.65,"tv":4.0,"id":31372}]}]}
{"op":"mcm","clk":"11824442636","pt":1723465438075,"mc":[{"id":"1.231699634","rc":[{"batb":[[0,1.66,10],[1,1.65,62.5],[2,1.25,100]],"ltp":1.65,"tv":4.0,"id":31372}]}]}
{"op":"mcm","clk":"11824442867","pt":1723465441615,"mc":[{"id":"1.231699634","rc":[{"batb":[[0,1.65,62.5],[1,1.25,100],[2,1.08,7.83]],"ltp":1.65,"tv":4.0,"id":31372}]}]}
{"op":"mcm","clk":"11824443157","pt":1723465445426,"mc":[{"id":"1.231699634","rc":[{"batb":[[0,1.66,10],[1,1.65,62.5],[2,1.25,100]],"ltp":1.65,"tv":4.0,"id":31372}]}]}
{"op":"mcm","clk":"11824443492","pt":1723465450112,"mc":[{"id":"1.231699634","rc":[{"batb":[[0,1.65,62.5],[1,1.25,100],[2,1.08,7.83]],"ltp":1.65,"tv":4.0,"id":31372}]}]}
{"op":"mcm","clk":"11824443767","pt":1723465454111,"mc":[{"id":"1.231699634","rc":[{"batb":[[0,1.66,10],[1,1.65,62.5],[2,1.25,100]],"ltp":1.65,"tv":4.0,"id":31372}]}]}
{"op":"mcm","clk":"11824444026","pt":1723465457657,"mc":[{"id":"1.231699634","rc":[{"batb":[[0,1.65,62.5],[1,1.25,100],[2,1.08,7.83]],"ltp":1.65,"tv":4.0,"id":31372}]}]}
{"op":"mcm","clk":"11824444275","pt":1723465461106,"mc":[{"id":"1.231699634","rc":[{"batb":[[0,1.66,10],[1,1.65,62.5],[2,1.25,100]],"ltp":1.65,"tv":4.0,"id":31372}]}]}
{"op":"mcm","clk":"11824444562","pt":1723465465727,"mc":[{"id":"1.231699634","rc":[{"batb":[[0,1.65,62.5],[1,1.25,100],[2,1.08,7.83]],"ltp":1.65,"tv":4.0,"id":31372}]}]}
{"op":"mcm","clk":"11824444768","pt":1723465468911,"mc":[{"id":"1.231699634","rc":[{"batb":[[0,1.66,10],[1,1.65,62.5],[2,1.25,100]],"ltp":1.65,"tv":4.0,"id":31372}]}]}
{"op":"mcm","clk":"11824444995","pt":1723465472360,"mc":[{"id":"1.231699634","rc":[{"batb":[[0,1.65,62.5],[1,1.25,100],[2,1.08,7.83]],"ltp":1.65,"tv":4.0,"id":31372}]}]}
{"op":"mcm","clk":"11824445159","pt":1723465474830,"mc":[{"id":"1.231699634","rc":[{"batb":[[0,1.66,10],[1,1.65,62.5],[2,1.25,100]],"ltp":1.65,"tv":4.0,"id":31372}]}]}
{"op":"mcm","clk":"11824445410","pt":1723465478269,"mc":[{"id":"1.231699634","rc":[{"batb":[[0,1.65,62.5],[1,1.25,100],[2,1.08,7.83]],"ltp":1.65,"tv":4.0,"id":31372}]}]}
{"op":"mcm","clk":"11824445671","pt":1723465482266,"mc":[{"id":"1.231699634","rc":[{"batb":[[0,1.76,5.25],[1,1.25,100],[2,1.08,7.83]],"ltp":2.34,"tv":141.84,"id":424679},{"batb":[[0,1.66,10],[1,1.65,62.5],[2,1.25,100]],"ltp":1.65,"tv":4.0,"id":31372}]}]}
{"op":"mcm","clk":"11824446081","pt":1723465487944,"mc":[{"id":"1.231699634","rc":[{"batb":[[0,1.65,62.5],[1,1.25,100],[2,1.08,7.83]],"ltp":1.65,"tv":4.0,"id":31372}]}]}
{"op":"mcm","clk":"11824446485","pt":1723465493450,"mc":[{"id":"1.231699634","rc":[{"batb":[[0,1.66,10],[1,1.65,62.5],[2,1.25,100]],"ltp":1.65,"tv":4.0,"id":31372}]}]}
{"op":"mcm","clk":"11824446905","pt":1723465499058,"mc":[{"id":"1.231699634","rc":[{"batb":[[0,1.65,62.5],[1,1.25,100],[2,1.08,7.83]],"ltp":1.65,"tv":4.0,"id":31372}]}]}
{"op":"mcm","clk":"11824447072","pt":1723465501584,"mc":[{"id":"1.231699634","rc":[{"batb":[[0,1.66,10],[1,1.65,62.5],[2,1.25,100]],"ltp":1.65,"tv":4.0,"id":31372}]}]}
{"op":"mcm","clk":"11824447362","pt":1723465505440,"mc":[{"id":"1.231699634","rc":[{"batb":[[0,1.65,62.5],[1,1.25,100],[2,1.08,7.83]],"ltp":1.65,"tv":4.0,"id":31372}]}]}
{"op":"mcm","clk":"11824447647","pt":1723465509402,"mc":[{"id":"1.231699634","rc":[{"batb":[[0,1.66,10],[1,1.65,62.5],[2,1.25,100]],"ltp":1.65,"tv":4.0,"id":31372}]}]}
{"op":"mcm","clk":"11824447910","pt":1723465513101,"mc":[{"id":"1.231699634","rc":[{"batb":[[0,1.65,62.5],[1,1.25,100],[2,1.08,7.83]],"ltp":1.65,"tv":4.0,"id":31372}]}]}
{"op":"mcm","clk":"11824448319","pt":1723465518303,"mc":[{"id":"1.231699634","rc":[{"batb":[[0,1.66,10],[1,1.65,62.5],[2,1.25,100]],"ltp":1.65,"tv":4.0,"id":31372}]}]}
{"op":"mcm","clk":"11824448597","pt":1723465522772,"mc":[{"id":"1.231699634","rc":[{"batb":[[0,1.65,62.5],[1,1.25,100],[2,1.08,7.83]],"ltp":1.65,"tv":4.0,"id":31372}]}]}
{"op":"mcm","clk":"11824448967","pt":1723465528274,"mc":[{"id":"1.231699634","rc":[{"batb":[[0,1.66,10],[1,1.65,62.5],[2,1.25,100]],"ltp":1.65,"tv":4.0,"id":31372}]}]}
{"op":"mcm","clk":"11824449166","pt":1723465531511,"mc":[{"id":"1.231699634","rc":[{"batb":[[0,1.65,62.5],[1,1.25,100],[2,1.08,7.83]],"ltp":1.65,"tv":4.0,"id":31372}]}]}
{"op":"mcm","clk":"11824449330","pt":1723465533926,"mc":[{"id":"1.231699634","rc":[{"batb":[[0,1.66,10],[1,1.65,62.5],[2,1.25,100]],"ltp":1.65,"tv":4.0,"id":31372}]}]}
{"op":"mcm","clk":"11824449548","pt":1723465537113,"mc":[{"id":"1.231699634","rc":[{"batb":[[0,1.65,62.5],[1,1.25,100],[2,1.08,7.83]],"ltp":1.65,"tv":4.0,"id":31372}]}]}
{"op":"mcm","clk":"11824450082","pt":1723465545034,"mc":[{"id":"1.231699634","rc":[{"batb":[[0,1.66,10],[1,1.65,62.5],[2,1.25,100]],"ltp":1.65,"tv":4.0,"id":31372}]}]}
{"op":"mcm","clk":"11824450409","pt":1723465549812,"mc":[{"id":"1.231699634","rc":[{"batb":[[0,1.65,62.5],[1,1.25,100],[2,1.08,7.83]],"ltp":1.65,"tv":4.0,"id":31372}]}]}
{"op":"mcm","clk":"11824450820","pt":1723465556327,"mc":[{"id":"1.231699634","rc":[{"batb":[[0,1.66,10],[1,1.65,62.5],[2,1.25,100]],"ltp":1.65,"tv":4.0,"id":31372}]}]}
{"op":"mcm","clk":"11824451191","pt":1723465562128,"mc":[{"id":"1.231699634","rc":[{"batb":[[0,1.65,62.5],[1,1.25,100],[2,1.08,7.83]],"ltp":1.65,"tv":4.0,"id":31372}]}]}
{"op":"mcm","clk":"11824451370","pt":1723465564710,"mc":[{"id":"1.231699634","rc":[{"batb":[[0,1.66,10],[1,1.65,62.5],[2,1.25,100]],"ltp":1.65,"tv":4.0,"id":31372}]}]}
{"op":"mcm","clk":"11824451568","pt":1723465568041,"mc":[{"id":"1.231699634","rc":[{"batb":[[0,1.65,62.5],[1,1.25,100],[2,1.08,7.83]],"ltp":1.65,"tv":4.0,"id":31372}]}]}
{"op":"mcm","clk":"11824451903","pt":1723465572925,"mc":[{"id":"1.231699634","rc":[{"batb":[[0,1.66,10],[1,1.65,62.5],[2,1.25,100]],"ltp":1.65,"tv":4.0,"id":31372}]}]}
{"op":"mcm","clk":"11824452350","pt":1723465579263,"mc":[{"id":"1.231699634","rc":[{"batb":[[0,1.65,62.5],[1,1.25,100],[2,1.08,7.83]],"ltp":1.65,"tv":4.0,"id":31372}]}]}
{"op":"mcm","clk":"11824452520","pt":1723465581726,"mc":[{"id":"1.231699634","rc":[{"batb":[[0,1.67,10],[1,1.65,62.5],[2,1.25,100]],"ltp":1.65,"tv":4.0,"id":31372}]}]}
{"op":"mcm","clk":"11824452898","pt":1723465588358,"mc":[{"id":"1.231699634","rc":[{"batb":[[0,1.65,62.5],[1,1.25,100],[2,1.08,7.83]],"ltp":1.65,"tv":4.0,"id":31372}]}]}
{"op":"mcm","clk":"11824453114","pt":1723465591643,"mc":[{"id":"1.231699634","rc":[{"batb":[[0,1.66,10],[1,1.65,62.5],[2,1.25,100]],"ltp":1.65,"tv":4.0,"id":31372}]}]}
{"op":"mcm","clk":"11824453322","pt":1723465594838,"mc":[{"id":"1.231699634","rc":[{"batb":[[0,1.65,62.5],[1,1.25,100],[2,1.08,7.83]],"ltp":1.65,"tv":4.0,"id":31372}]}]}
{"op":"mcm","clk":"11824453592","pt":1723465598790,"mc":[{"id":"1.231699634","rc":[{"batb":[[0,1.66,10],[1,1.65,62.5],[2,1.25,100]],"ltp":1.65,"tv":4.0,"id":31372}]}]}
{"op":"mcm","clk":"11824453903","pt":1723465603150,"mc":[{"id":"1.231699634","rc":[{"batb":[[0,1.65,62.5],[1,1.25,100],[2,1.08,7.83]],"ltp":1.65,"tv":4.0,"id":31372}]}]}
{"op":"mcm","clk":"11824454141","pt":1723465606382,"mc":[{"id":"1.231699634","rc":[{"batb":[[0,1.66,10],[1,1.65,62.5],[2,1.25,100]],"ltp":1.65,"tv":4.0,"id":31372}]}]}
{"op":"mcm","clk":"11824454373","pt":1723465609679,"mc":[{"id":"1.231699634","rc":[{"batb":[[0,1.65,62.5],[1,1.25,100],[2,1.08,7.83]],"ltp":1.65,"tv":4.0,"id":31372}]}]}
{"op":"mcm","clk":"11824454595","pt":1723465612768,"mc":[{"id":"1.231699634","rc":[{"batb":[[0,1.66,10],[1,1.65,62.5],[2,1.25,100]],"ltp":1.65,"tv":4.0,"id":31372}]}]}
{"op":"mcm","clk":"11824454824","pt":1723465616208,"mc":[{"id":"1.231699634","rc":[{"batb":[[0,1.65,62.5],[1,1.25,100],[2,1.08,7.83]],"ltp":1.65,"tv":4.0,"id":31372}]}]}
{"op":"mcm","clk":"11824455131","pt":1723465620881,"mc":[{"id":"1.231699634","rc":[{"batb":[[0,1.66,10],[1,1.65,62.5],[2,1.25,100]],"ltp":1.65,"tv":4.0,"id":31372}]}]}
{"op":"mcm","clk":"11824455496","pt":1723465624990,"mc":[{"id":"1.231699634","rc":[{"batb":[[0,1.65,62.5],[1,1.25,100],[2,1.08,7.83]],"ltp":1.65,"tv":4.0,"id":31372}]}]}
{"op":"mcm","clk":"11824455732","pt":1723465628584,"mc":[{"id":"1.231699634","rc":[{"batb":[[0,1.66,10],[1,1.65,62.5],[2,1.25,100]],"ltp":1.65,"tv":4.0,"id":31372}]}]}
{"op":"mcm","clk":"11824455975","pt":1723465631930,"mc":[{"id":"1.231699634","rc":[{"batb":[[0,1.65,62.5],[1,1.25,100],[2,1.08,7.83]],"ltp":1.65,"tv":4.0,"id":31372}]}]}
{"op":"mcm","clk":"11824456846","pt":1723465642715,"mc":[{"id":"1.231699634","rc":[{"batb":[[0,1.66,10],[1,1.65,62.5],[2,1.25,100]],"ltp":1.65,"tv":4.0,"id":31372}]}]}
{"op":"mcm","clk":"11824457107","pt":1723465646247,"mc":[{"id":"1.231699634","rc":[{"batb":[[0,1.65,62.5],[1,1.25,100],[2,1.08,7.83]],"ltp":1.65,"tv":4.0,"id":31372}]}]}
{"op":"mcm","clk":"11824457387","pt":1723465649946,"mc":[{"id":"1.231699634","rc":[{"batb":[[0,1.66,10],[1,1.65,62.5],[2,1.25,100]],"ltp":1.65,"tv":4.0,"id":31372}]}]}
{"op":"mcm","clk":"11824457664","pt":1723465653640,"mc":[{"id":"1.231699634","rc":[{"batb":[[0,1.65,62.5],[1,1.25,100],[2,1.08,7.83]],"ltp":1.65,"tv":4.0,"id":31372}]}]}
{"op":"mcm","clk":"11824457961","pt":1723465657452,"mc":[{"id":"1.231699634","rc":[{"batb":[[0,1.66,10],[1,1.65,62.5],[2,1.25,100]],"ltp":1.65,"tv":4.0,"id":31372}]}]}
{"op":"mcm","clk":"11824458178","pt":1723465661147,"mc":[{"id":"1.231699634","rc":[{"batb":[[0,1.65,62.5],[1,1.25,100],[2,1.08,7.83]],"ltp":1.65,"tv":4.0,"id":31372}]}]}
{"op":"mcm","clk":"11824458343","pt":1723465663359,"mc":[{"id":"1.231699634","rc":[{"batb":[[0,1.66,10],[1,1.65,62.5],[2,1.25,100]],"ltp":1.65,"tv":4.0,"id":31372}]}]}
{"op":"mcm","clk":"11824458614","pt":1723465666956,"mc":[{"id":"1.231699634","rc":[{"batb":[[0,1.65,62.5],[1,1.25,100],[2,1.08,7.83]],"ltp":1.65,"tv":4.0,"id":31372}]}]}
{"op":"mcm","clk":"11824458889","pt":1723465670763,"mc":[{"id":"1.231699634","rc":[{"batb":[[0,1.66,10],[1,1.65,62.5],[2,1.25,100]],"ltp":1.65,"tv":4.0,"id":31372}]}]}
{"op":"mcm","clk":"11824459121","pt":1723465674163,"mc":[{"id":"1.231699634","rc":[{"batb":[[0,1.65,62.5],[1,1.25,100],[2,1.08,7.83]],"ltp":1.65,"tv":4.0,"id":31372}]}]}
{"op":"mcm","clk":"11824459289","pt":1723465676784,"mc":[{"id":"1.231699634","rc":[{"batb":[[0,1.66,10],[1,1.65,62.5],[2,1.25,100]],"ltp":1.65,"tv":4.0,"id":31372}]}]}
{"op":"mcm","clk":"11824459527","pt":1723465680177,"mc":[{"id":"1.231699634","rc":[{"batb":[[0,1.65,62.5],[1,1.25,100],[2,1.08,7.83]],"ltp":1.65,"tv":4.0,"id":31372}]}]}
{"op":"mcm","clk":"11824459715","pt":1723465682749,"mc":[{"id":"1.231699634","rc":[{"batb":[[0,1.66,10],[1,1.65,62.5],[2,1.25,100]],"ltp":1.65,"tv":4.0,"id":31372}]}]}
{"op":"mcm","clk":"11824459963","pt":1723465686089,"mc":[{"id":"1.231699634","rc":[{"batb":[[0,1.65,62.5],[1,1.25,100],[2,1.08,7.83]],"ltp":1.65,"tv":4.0,"id":31372}]}]}
{"op":"mcm","clk":"11824460546","pt":1723465693672,"mc":[{"id":"1.231699634","rc":[{"batb":[[0,1.66,10],[1,1.65,62.5],[2,1.25,100]],"ltp":1.65,"tv":4.0,"id":31372}]}]}
{"op":"mcm","clk":"11824460766","pt":1723465697384,"mc":[{"id":"1.231699634","rc":[{"batb":[[0,1.65,62.5],[1,1.25,100],[2,1.08,7.83]],"ltp":1.65,"tv":4.0,"id":31372}]}]}
{"op":"mcm","clk":"11824461105","pt":1723465701776,"mc":[{"id":"1.231699634","rc":[{"batb":[[0,1.66,10],[1,1.65,62.5],[2,1.25,100]],"ltp":1.65,"tv":4.0,"id":31372}]}]}
{"op":"mcm","clk":"11824461375","pt":1723465705279,"mc":[{"id":"1.231699634","rc":[{"batb":[[0,1.65,62.5],[1,1.25,100],[2,1.08,7.83]],"ltp":1.65,"tv":4.0,"id":31372}]}]}
{"op":"mcm","clk":"11824461677","pt":1723465708989,"mc":[{"id":"1.231699634","rc":[{"batb":[[0,1.66,10],[1,1.65,62.5],[2,1.25,100]],"ltp":1.65,"tv":4.0,"id":31372}]}]}
{"op":"mcm","clk":"11824461932","pt":1723465712308,"mc":[{"id":"1.231699634","rc":[{"batb":[[0,1.65,62.5],[1,1.25,100],[2,1.08,7.83]],"ltp":1.65,"tv":4.0,"id":31372}]}]}
{"op":"mcm","clk":"11824462155","pt":1723465715417,"mc":[{"id":"1.231699634","rc":[{"batb":[[0,1.66,10],[1,1.65,62.5],[2,1.25,100]],"ltp":1.65,"tv":4.0,"id":31372}]}]}
{"op":"mcm","clk":"11824462384","pt":1723465718815,"mc":[{"id":"1.231699634","rc":[{"batb":[[0,1.65,62.5],[1,1.25,100],[2,1.08,7.83]],"ltp":1.65,"tv":4.0,"id":31372}]}]}
{"op":"mcm","clk":"11824462865","pt":1723465724697,"mc":[{"id":"1.231699634","rc":[{"batb":[[0,1.66,10],[1,1.65,62.5],[2,1.25,100]],"ltp":1.65,"tv":4.0,"id":31372}]}]}
{"op":"mcm","clk":"11824463186","pt":1723465728926,"mc":[{"id":"1.231699634","rc":[{"batb":[[0,1.65,62.5],[1,1.25,100],[2,1.08,7.83]],"ltp":1.65,"tv":4.0,"id":31372}]}]}
{"op":"mcm","clk":"11824463531","pt":1723465733108,"mc":[{"id":"1.231699634","rc":[{"batb":[[0,1.66,10],[1,1.65,62.5],[2,1.25,100]],"ltp":1.65,"tv":4.0,"id":31372}]}]}
{"op":"mcm","clk":"11824463776","pt":1723465736408,"mc":[{"id":"1.231699634","rc":[{"batb":[[0,1.65,62.5],[1,1.25,100],[2,1.08,7.83]],"ltp":1.65,"tv":4.0,"id":31372}]}]}
{"op":"mcm","clk":"11824464100","pt":1723465740123,"mc":[{"id":"1.231699634","rc":[{"batb":[[0,1.66,10],[1,1.65,62.5],[2,1.25,100]],"ltp":1.65,"tv":4.0,"id":31372}]}]}
{"op":"mcm","clk":"11824464688","pt":1723465746860,"mc":[{"id":"1.231699634","rc":[{"batb":[[0,1.65,62.5],[1,1.25,100],[2,1.08,7.83]],"ltp":1.65,"tv":4.0,"id":31372}]}]}
{"op":"mcm","clk":"11824464857","pt":1723465749018,"mc":[{"id":"1.231699634","rc":[{"batb":[[0,1.67,10],[1,1.65,62.5],[2,1.25,100]],"ltp":1.65,"tv":4.0,"id":31372}]}]}
{"op":"mcm","clk":"11824465391","pt":1723465755874,"mc":[{"id":"1.231699634","rc":[{"batb":[[0,1.65,62.5],[1,1.25,100],[2,1.08,7.83]],"ltp":1.65,"tv":4.0,"id":31372}]}]}
{"op":"mcm","clk":"11824465607","pt":1723465758449,"mc":[{"id":"1.231699634","rc":[{"batb":[[0,1.66,10],[1,1.65,62.5],[2,1.25,100]],"ltp":1.65,"tv":4.0,"id":31372}]}]}
{"op":"mcm","clk":"11824465970","pt":1723465763360,"mc":[{"id":"1.231699634","rc":[{"batb":[[0,1.65,62.5],[1,1.25,100],[2,1.08,7.83]],"ltp":1.65,"tv":4.0,"id":31372}]}]}
{"op":"mcm","clk":"11824466221","pt":1723465766649,"mc":[{"id":"1.231699634","rc":[{"batb":[[0,1.66,10],[1,1.65,62.5],[2,1.25,100]],"ltp":1.65,"tv":4.0,"id":31372}]}]}
{"op":"mcm","clk":"11824466426","pt":1723465769989,"mc":[{"id":"1.231699634","rc":[{"batb":[[0,1.65,62.5],[1,1.25,100],[2,1.08,7.83]],"ltp":1.65,"tv":4.0,"id":31372}]}]}
{"op":"mcm","clk":"11824467189","pt":1723465780688,"mc":[{"id":"1.231699634","rc":[{"batb":[[0,1.66,10],[1,1.65,62.5],[2,1.25,100]],"ltp":1.65,"tv":4.0,"id":31372}]}]}
{"op":"mcm","clk":"11824467756","pt":1723465789579,"mc":[{"id":"1.231699634","rc":[{"batb":[[0,1.65,62.5],[1,1.25,100],[2,1.08,7.83]],"ltp":1.65,"tv":4.0,"id":31372}]}]}
{"op":"mcm","clk":"11824467916","pt":1723465791892,"mc":[{"id":"1.231699634","rc":[{"batb":[[0,1.66,10],[1,1.65,62.5],[2,1.25,100]],"ltp":1.65,"tv":4.0,"id":31372}]}]}
{"op":"mcm","clk":"11824468353","pt":1723465797288,"mc":[{"id":"1.231699634","rc":[{"batb":[[0,1.65,62.5],[1,1.25,100],[2,1.08,7.83]],"ltp":1.65,"tv":4.0,"id":31372}]}]}
{"op":"mcm","clk":"11824468672","pt":1723465801069,"mc":[{"id":"1.231699634","rc":[{"batb":[[0,1.66,10],[1,1.65,62.5],[2,1.25,100]],"ltp":1.65,"tv":4.0,"id":31372}]}]}
{"op":"mcm","clk":"11824469186","pt":1723465807012,"mc":[{"id":"1.231699634","rc":[{"batb":[[0,1.65,62.5],[1,1.25,100],[2,1.08,7.83]],"ltp":1.65,"tv":4.0,"id":31372}]}]}
{"op":"mcm","clk":"11824469376","pt":1723465809437,"mc":[{"id":"1.231699634","rc":[{"batb":[[0,1.66,10],[1,1.65,62.5],[2,1.25,100]],"ltp":1.65,"tv":4.0,"id":31372}]}]}
{"op":"mcm","clk":"11824469639","pt":1723465812894,"mc":[{"id":"1.231699634","rc":[{"batb":[[0,1.65,62.5],[1,1.25,100],[2,1.08,7.83]],"ltp":1.65,"tv":4.0,"id":31372}]}]}
{"op":"mcm","clk":"11824469822","pt":1723465815162,"mc":[{"id":"1.231699634","rc":[{"batb":[[0,1.66,10],[1,1.65,62.5],[2,1.25,100]],"ltp":1.65,"tv":4.0,"id":31372}]}]}
{"op":"mcm","clk":"11824470063","pt":1723465818467,"mc":[{"id":"1.231699634","rc":[{"batb":[[0,1.65,62.5],[1,1.25,100],[2,1.08,7.83]],"ltp":1.65,"tv":4.0,"id":31372}]}]}
{"op":"mcm","clk":"11824470512","pt":1723465823573,"mc":[{"id":"1.231699634","rc":[{"batb":[[0,1.66,10],[1,1.65,62.5],[2,1.25,100]],"ltp":1.65,"tv":4.0,"id":31372}]}]}
{"op":"mcm","clk":"11824470797","pt":1723465826874,"mc":[{"id":"1.231699634","rc":[{"batb":[[0,1.65,62.5],[1,1.25,100],[2,1.08,7.83]],"ltp":1.65,"tv":4.0,"id":31372}]}]}
{"op":"mcm","clk":"11824471034","pt":1723465829202,"mc":[{"id":"1.231699634","rc":[{"batb":[[0,1.67,10],[1,1.65,62.5],[2,1.25,100]],"ltp":1.65,"tv":4.0,"id":31372}]}]}
{"op":"mcm","clk":"11824471543","pt":1723465834463,"mc":[{"id":"1.231699634","rc":[{"batb":[[0,1.65,62.5],[1,1.25,100],[2,1.08,7.83]],"ltp":1.65,"tv":4.0,"id":31372}]}]}
{"op":"mcm","clk":"11824471861","pt":1723465838090,"mc":[{"id":"1.231699634","rc":[{"batb":[[0,1.66,10],[1,1.65,62.5],[2,1.25,100]],"ltp":1.65,"tv":4.0,"id":31372}]}]}
{"op":"mcm","clk":"11824472340","pt":1723465843097,"mc":[{"id":"1.231699634","rc":[{"batb":[[0,1.65,62.5],[1,1.25,100],[2,1.08,7.83]],"ltp":1.65,"tv":4.0,"id":31372}]}]}
{"op":"mcm","clk":"11824472513","pt":1723465845513,"mc":[{"id":"1.231699634","rc":[{"batb":[[0,1.66,10],[1,1.65,62.5],[2,1.25,100]],"ltp":1.65,"tv":4.0,"id":31372}]}]}
{"op":"mcm","clk":"11824472785","pt":1723465849109,"mc":[{"id":"1.231699634","rc":[{"batb":[[0,1.65,62.5],[1,1.25,100],[2,1.08,7.83]],"ltp":1.65,"tv":4.0,"id":31372}]}]}
{"op":"mcm","clk":"11824472952","pt":1723465851278,"mc":[{"id":"1.231699634","rc":[{"batb":[[0,1.66,10],[1,1.65,62.5],[2,1.25,100]],"ltp":1.65,"tv":4.0,"id":31372}]}]}
{"op":"mcm","clk":"11824473209","pt":1723465854483,"mc":[{"id":"1.231699634","rc":[{"batb":[[0,1.65,62.5],[1,1.25,100],[2,1.08,7.83]],"ltp":1.65,"tv":4.0,"id":31372}]}]}
{"op":"mcm","clk":"11824473429","pt":1723465857207,"mc":[{"id":"1.231699634","rc":[{"batb":[[0,1.66,10],[1,1.65,62.5],[2,1.25,100]],"ltp":1.65,"tv":4.0,"id":31372}]}]}
{"op":"mcm","clk":"11824473681","pt":1723465860396,"mc":[{"id":"1.231699634","rc":[{"batb":[[0,1.65,62.5],[1,1.25,100],[2,1.08,7.83]],"ltp":1.65,"tv":4.0,"id":31372}]}]}
{"op":"mcm","clk":"11824473979","pt":1723465863399,"mc":[{"id":"1.231699634","rc":[{"batb":[[0,1.66,10],[1,1.65,62.5],[2,1.25,100]],"ltp":1.65,"tv":4.0,"id":31372}]}]}
{"op":"mcm","clk":"11824474335","pt":1723465867520,"mc":[{"id":"1.231699634","rc":[{"batb":[[0,1.65,62.5],[1,1.25,100],[2,1.08,7.83]],"ltp":1.65,"tv":4.0,"id":31372}]}]}
{"op":"mcm","clk":"11824474533","pt":1723465869791,"mc":[{"id":"1.231699634","rc":[{"batb":[[0,1.66,10],[1,1.65,62.5],[2,1.25,100]],"ltp":1.65,"tv":4.0,"id":31372}]}]}
{"op":"mcm","clk":"11824474794","pt":1723465873090,"mc":[{"id":"1.231699634","rc":[{"batb":[[0,1.65,62.5],[1,1.25,100],[2,1.08,7.83]],"ltp":1.65,"tv":4.0,"id":31372}]}]}
{"op":"mcm","clk":"11824475002","pt":1723465875400,"mc":[{"id":"1.231699634","rc":[{"batb":[[0,1.66,10],[1,1.65,62.5],[2,1.25,100]],"ltp":1.65,"tv":4.0,"id":31372}]}]}
{"op":"mcm","clk":"11824475239","pt":1723465878611,"mc":[{"id":"1.231699634","rc":[{"batb":[[0,1.65,62.5],[1,1.25,100],[2,1.08,7.83]],"ltp":1.65,"tv":4.0,"id":31372}]}]}
{"op":"mcm","clk":"11824475422","pt":1723465881024,"mc":[{"id":"1.231699634","rc":[{"batb":[[0,1.66,10],[1,1.65,62.5],[2,1.25,100]],"ltp":1.65,"tv":4.0,"id":31372}]}]}
{"op":"mcm","clk":"11824475771","pt":1723465885509,"mc":[{"id":"1.231699634","rc":[{"batb":[[0,1.65,62.5],[1,1.25,100],[2,1.08,7.83]],"ltp":1.65,"tv":4.0,"id":31372}]}]}
{"op":"mcm","clk":"11824475998","pt":1723465888543,"mc":[{"id":"1.231699634","rc":[{"batb":[[0,1.66,10],[1,1.65,62.5],[2,1.25,100]],"ltp":1.65,"tv":4.0,"id":31372}]}]}
{"op":"mcm","clk":"11824476254","pt":1723465891825,"mc":[{"id":"1.231699634","rc":[{"batb":[[0,1.65,62.5],[1,1.25,100],[2,1.08,7.83]],"ltp":1.65,"tv":4.0,"id":31372}]}]}
{"op":"mcm","clk":"11824476525","pt":1723465895223,"mc":[{"id":"1.231699634","rc":[{"batb":[[0,1.66,10],[1,1.65,62.5],[2,1.25,100]],"ltp":1.65,"tv":4.0,"id":31372}]}]}
{"op":"mcm","clk":"11824476771","pt":1723465898764,"mc":[{"id":"1.231699634","rc":[{"batb":[[0,1.65,62.5],[1,1.25,100],[2,1.08,7.83]],"ltp":1.65,"tv":4.0,"id":31372}]}]}
{"op":"mcm","clk":"11824476951","pt":1723465901133,"mc":[{"id":"1.231699634","rc":[{"batb":[[0,1.66,10],[1,1.65,62.5],[2,1.25,100]],"ltp":1.65,"tv":4.0,"id":31372}]}]}
{"op":"mcm","clk":"11824477255","pt":1723465904374,"mc":[{"id":"1.231699634","rc":[{"batb":[[0,1.65,62.5],[1,1.25,100],[2,1.08,7.83]],"ltp":1.65,"tv":4.0,"id":31372}]}]}
{"op":"mcm","clk":"11824477529","pt":1723465907271,"mc":[{"id":"1.231699634","rc":[{"batb":[[0,1.66,10],[1,1.65,62.5],[2,1.25,100]],"ltp":1.65,"tv":4.0,"id":31372}]}]}
{"op":"mcm","clk":"11824477894","pt":1723465911768,"mc":[{"id":"1.231699634","rc":[{"batb":[[0,1.65,62.5],[1,1.25,100],[2,1.08,7.83]],"ltp":1.65,"tv":4.0,"id":31372}]}]}
{"op":"mcm","clk":"11824478109","pt":1723465914597,"mc":[{"id":"1.231699634","rc":[{"batb":[[0,1.66,10],[1,1.65,62.5],[2,1.25,100]],"ltp":1.65,"tv":4.0,"id":31372}]}]}
{"op":"mcm","clk":"11824478380","pt":1723465917997,"mc":[{"id":"1.231699634","rc":[{"batb":[[0,1.65,62.5],[1,1.25,100],[2,1.08,7.83]],"ltp":1.65,"tv":4.0,"id":31372}]}]}
{"op":"mcm","clk":"11824478607","pt":1723465920809,"mc":[{"id":"1.231699634","rc":[{"batb":[[0,1.66,10],[1,1.65,62.5],[2,1.25,100]],"ltp":1.65,"tv":4.0,"id":31372}]}]}
{"op":"mcm","clk":"11824478871","pt":1723465924391,"mc":[{"id":"1.231699634","rc":[{"batb":[[0,1.65,62.5],[1,1.25,100],[2,1.08,7.83]],"ltp":1.65,"tv":4.0,"id":31372}]}]}
{"op":"mcm","clk":"11824479528","pt":1723465932407,"mc":[{"id":"1.231699634","rc":[{"batb":[[0,1.66,10],[1,1.65,62.5],[2,1.25,100]],"ltp":1.65,"tv":4.0,"id":31372}]}]}
{"op":"mcm","clk":"11824479865","pt":1723465936414,"mc":[{"id":"1.231699634","rc":[{"batb":[[0,1.65,62.5],[1,1.25,100],[2,1.08,7.83]],"ltp":1.65,"tv":4.0,"id":31372}]}]}
{"op":"mcm","clk":"11824480490","pt":1723465944187,"mc":[{"id":"1.231699634","rc":[{"batb":[[0,1.66,10],[1,1.65,62.5],[2,1.25,100]],"ltp":1.65,"tv":4.0,"id":31372}]}]}
{"op":"mcm","clk":"11824480829","pt":1723465948409,"mc":[{"id":"1.231699634","rc":[{"batb":[[0,1.65,62.5],[1,1.25,100],[2,1.08,7.83]],"ltp":1.65,"tv":4.0,"id":31372}]}]}
{"op":"mcm","clk":"11824481275","pt":1723465953146,"mc":[{"id":"1.231699634","rc":[{"batb":[[0,1.66,10],[1,1.65,62.5],[2,1.25,100]],"ltp":1.65,"tv":4.0,"id":31372}]}]}
{"op":"mcm","clk":"11824481610","pt":1723465956629,"mc":[{"id":"1.231699634","rc":[{"batb":[[0,1.65,62.5],[1,1.25,100],[2,1.08,7.83]],"ltp":1.65,"tv":4.0,"id":31372}]}]}
{"op":"mcm","clk":"11824481868","pt":1723465959826,"mc":[{"id":"1.231699634","rc":[{"batb":[[0,1.66,10],[1,1.65,62.5],[2,1.25,100]],"ltp":1.65,"tv":4.0,"id":31372}]}]}
{"op":"mcm","clk":"11824482185","pt":1723465963216,"mc":[{"id":"1.231699634","rc":[{"batb":[[0,1.65,62.5],[1,1.25,100],[2,1.08,7.83]],"ltp":1.65,"tv":4.0,"id":31372}]}]}
{"op":"mcm","clk":"11824482381","pt":1723465965434,"mc":[{"id":"1.231699634","rc":[{"batb":[[0,1.66,10],[1,1.65,62.5],[2,1.25,100]],"ltp":1.65,"tv":4.0,"id":31372}]}]}
{"op":"mcm","clk":"11824482925","pt":1723465971831,"mc":[{"id":"1.231699634","rc":[{"batb":[[0,1.65,62.5],[1,1.25,100],[2,1.08,7.83]],"ltp":1.65,"tv":4.0,"id":31372}]}]}
{"op":"mcm","clk":"11824483150","pt":1723465974349,"mc":[{"id":"1.231699634","rc":[{"batb":[[0,1.67,10],[1,1.65,62.5],[2,1.25,100]],"ltp":1.65,"tv":4.0,"id":31372}]}]}
{"op":"mcm","clk":"11824483598","pt":1723465979955,"mc":[{"id":"1.231699634","rc":[{"batb":[[0,1.65,62.5],[1,1.25,100],[2,1.08,7.83]],"ltp":1.65,"tv":4.0,"id":31372}]}]}
{"op":"mcm","clk":"11824483904","pt":1723465983770,"mc":[{"id":"1.231699634","rc":[{"batb":[[0,1.66,10],[1,1.65,62.5],[2,1.25,100]],"ltp":1.65,"tv":4.0,"id":31372}]}]}
{"op":"mcm","clk":"11824484194","pt":1723465987062,"mc":[{"id":"1.231699634","rc":[{"batb":[[0,1.65,62.5],[1,1.25,100],[2,1.08,7.83]],"ltp":1.65,"tv":4.0,"id":31372}]}]}
{"op":"mcm","clk":"11824484445","pt":1723465989945,"mc":[{"id":"1.231699634","rc":[{"batb":[[0,1.66,10],[1,1.65,62.5],[2,1.25,100]],"ltp":1.65,"tv":4.0,"id":31372}]}]}
{"op":"mcm","clk":"11824484793","pt":1723465993978,"mc":[{"id":"1.231699634","rc":[{"batb":[[0,1.65,62.5],[1,1.25,100],[2,1.08,7.83]],"ltp":1.65,"tv":4.0,"id":31372}]}]}
{"op":"mcm","clk":"11824485141","pt":1723465998069,"mc":[{"id":"1.231699634","rc":[{"batb":[[0,1.66,10],[1,1.65,62.5],[2,1.25,100]],"ltp":1.65,"tv":4.0,"id":31372}]}]}
{"op":"mcm","clk":"11824485431","pt":1723466001360,"mc":[{"id":"1.231699634","rc":[{"batb":[[0,1.65,62.5],[1,1.25,100],[2,1.08,7.83]],"ltp":1.65,"tv":4.0,"id":31372}]}]}
{"op":"mcm","clk":"11824485741","pt":1723466004950,"mc":[{"id":"1.231699634","rc":[{"batb":[[0,1.66,10],[1,1.65,62.5],[2,1.25,100]],"ltp":1.65,"tv":4.0,"id":31372}]}]}
{"op":"mcm","clk":"11824486079","pt":1723466008681,"mc":[{"id":"1.231699634","rc":[{"batb":[[0,1.65,62.5],[1,1.25,100],[2,1.08,7.83]],"ltp":1.65,"tv":4.0,"id":31372}]}]}
{"op":"mcm","clk":"11824486328","pt":1723466011467,"mc":[{"id":"1.231699634","rc":[{"batb":[[0,1.66,10],[1,1.65,62.5],[2,1.25,100]],"ltp":1.65,"tv":4.0,"id":31372}]}]}
{"op":"mcm","clk":"11824486732","pt":1723466016480,"mc":[{"id":"1.231699634","rc":[{"batb":[[0,1.65,62.5],[1,1.25,100],[2,1.08,7.83]],"ltp":1.65,"tv":4.0,"id":31372}]}]}
{"op":"mcm","clk":"11824487172","pt":1723466021791,"mc":[{"id":"1.231699634","rc":[{"batb":[[0,1.66,10],[1,1.65,62.5],[2,1.25,100]],"ltp":1.65,"tv":4.0,"id":31372}]}]}
{"op":"mcm","clk":"11824487561","pt":1723466026058,"mc":[{"id":"1.231699634","rc":[{"batb":[[0,1.65,62.5],[1,1.25,100],[2,1.08,7.83]],"ltp":1.65,"tv":4.0,"id":31372}]}]}
{"op":"mcm","clk":"11824487958","pt":1723466031350,"mc":[{"id":"1.231699634","rc":[{"batb":[[0,1.66,10],[1,1.65,62.5],[2,1.25,100]],"ltp":1.65,"tv":4.0,"id":31372}]}]}
{"op":"mcm","clk":"11824488187","pt":1723466034692,"mc":[{"id":"1.231699634","rc":[{"batb":[[0,1.65,62.5],[1,1.25,100],[2,1.08,7.83]],"ltp":1.65,"tv":4.0,"id":31372}]}]}
{"op":"mcm","clk":"11824488832","pt":1723466042417,"mc":[{"id":"1.231699634","rc":[{"batb":[[0,1.66,10],[1,1.65,62.5],[2,1.25,100]],"ltp":1.65,"tv":4.0,"id":31372}]}]}
{"op":"mcm","clk":"11824489337","pt":1723466047202,"mc":[{"id":"1.231699634","rc":[{"batb":[[0,1.65,62.5],[1,1.25,100],[2,1.08,7.83]],"ltp":1.65,"tv":4.0,"id":31372}]}]}
{"op":"mcm","clk":"11824489565","pt":1723466050404,"mc":[{"id":"1.231699634","rc":[{"batb":[[0,1.66,10],[1,1.65,62.5],[2,1.25,100]],"ltp":1.65,"tv":4.0,"id":31372}]}]}
{"op":"mcm","clk":"11824489880","pt":1723466053810,"mc":[{"id":"1.231699634","rc":[{"batb":[[0,1.65,62.5],[1,1.25,100],[2,1.08,7.83]],"ltp":1.65,"tv":4.0,"id":31372}]}]}
{"op":"mcm","clk":"11824490119","pt":1723466056290,"mc":[{"id":"1.231699634","rc":[{"batb":[[0,1.66,10],[1,1.65,62.5],[2,1.25,100]],"ltp":1.65,"tv":4.0,"id":31372}]}]}
{"op":"mcm","clk":"11824490394","pt":1723466059798,"mc":[{"id":"1.231699634","rc":[{"batb":[[0,1.65,62.5],[1,1.25,100],[2,1.08,7.83]],"ltp":1.65,"tv":4.0,"id":31372}]}]}
{"op":"mcm","clk":"11824490823","pt":1723466065099,"mc":[{"id":"1.231699634","rc":[{"batb":[[0,1.66,10],[1,1.65,62.5],[2,1.25,100]],"ltp":1.65,"tv":4.0,"id":31372}]}]}
{"op":"mcm","clk":"11824491204","pt":1723466069489,"mc":[{"id":"1.231699634","rc":[{"batb":[[0,1.65,62.5],[1,1.25,100],[2,1.08,7.83]],"ltp":1.65,"tv":4.0,"id":31372}]}]}
{"op":"mcm","clk":"11824491413","pt":1723466072615,"mc":[{"id":"1.231699634","rc":[{"batb":[[0,1.66,10],[1,1.65,62.5],[2,1.25,100]],"ltp":1.65,"tv":4.0,"id":31372}]}]}
{"op":"mcm","clk":"11824491721","pt":1723466076113,"mc":[{"id":"1.231699634","rc":[{"batb":[[0,1.65,62.5],[1,1.25,100],[2,1.08,7.83]],"ltp":1.65,"tv":4.0,"id":31372}]}]}
{"op":"mcm","clk":"11824492109","pt":1723466080792,"mc":[{"id":"1.231699634","rc":[{"batb":[[0,1.66,10],[1,1.65,62.5],[2,1.25,100]],"ltp":1.65,"tv":4.0,"id":31372}]}]}
{"op":"mcm","clk":"11824492514","pt":1723466085533,"mc":[{"id":"1.231699634","rc":[{"batb":[[0,1.65,62.5],[1,1.25,100],[2,1.08,7.83]],"ltp":1.65,"tv":4.0,"id":31372}]}]}
{"op":"mcm","clk":"11824493010","pt":1723466091039,"mc":[{"id":"1.231699634","rc":[{"batb":[[0,1.66,10],[1,1.65,62.5],[2,1.25,100]],"ltp":1.65,"tv":4.0,"id":31372}]}]}
{"op":"mcm","clk":"11824493487","pt":1723466096543,"mc":[{"id":"1.231699634","rc":[{"batb":[[0,1.65,62.5],[1,1.25,100],[2,1.08,7.83]],"ltp":1.65,"tv":4.0,"id":31372}]}]}
{"op":"mcm","clk":"11824493812","pt":1723466100418,"mc":[{"id":"1.231699634","rc":[{"batb":[[0,1.66,10],[1,1.65,62.5],[2,1.25,100]],"ltp":1.65,"tv":4.0,"id":31372}]}]}
{"op":"mcm","clk":"11824494289","pt":1723466105760,"mc":[{"id":"1.231699634","rc":[{"batb":[[0,1.65,62.5],[1,1.25,100],[2,1.08,7.83]],"ltp":1.65,"tv":4.0,"id":31372}]}]}
{"op":"mcm","clk":"11824494808","pt":1723466111951,"mc":[{"id":"1.231699634","rc":[{"batb":[[0,1.66,10],[1,1.65,62.5],[2,1.25,100]],"ltp":1.65,"tv":4.0,"id":31372}]}]}
{"op":"mcm","clk":"11824495286","pt":1723466116961,"mc":[{"id":"1.231699634","rc":[{"batb":[[0,1.65,62.5],[1,1.25,100],[2,1.08,7.83]],"ltp":1.65,"tv":4.0,"id":31372}]}]}
{"op":"mcm","clk":"11824495631","pt":1723466120572,"mc":[{"id":"1.231699634","rc":[{"batb":[[0,1.66,10],[1,1.65,62.5],[2,1.25,100]],"ltp":1.65,"tv":4.0,"id":31372}]}]}
{"op":"mcm","clk":"11824495904","pt":1723466123879,"mc":[{"id":"1.231699634","rc":[{"batb":[[0,1.65,62.5],[1,1.25,100],[2,1.08,7.83]],"ltp":1.65,"tv":4.0,"id":31372}]}]}
{"op":"mcm","clk":"11824496259","pt":1723466127854,"mc":[{"id":"1.231699634","rc":[{"batb":[[0,1.66,10],[1,1.65,62.5],[2,1.25,100]],"ltp":1.65,"tv":4.0,"id":31372}]}]}
{"op":"mcm","clk":"11824496630","pt":1723466132059,"mc":[{"id":"1.231699634","rc":[{"batb":[[0,1.65,62.5],[1,1.25,100],[2,1.08,7.83]],"ltp":1.65,"tv":4.0,"id":31372}]}]}
{"op":"mcm","clk":"11824497253","pt":1723466139669,"mc":[{"id":"1.231699634","rc":[{"batb":[[0,1.66,10],[1,1.65,62.5],[2,1.25,100]],"ltp":1.65,"tv":4.0,"id":31372}]}]}
{"op":"mcm","clk":"11824497724","pt":1723466144675,"mc":[{"id":"1.231699634","rc":[{"batb":[[0,1.65,62.5],[1,1.25,100],[2,1.08,7.83]],"ltp":1.65,"tv":4.0,"id":31372}]}]}
{"op":"mcm","clk":"11824497933","pt":1723466147761,"mc":[{"id":"1.231699634","rc":[{"batb":[[0,1.66,10],[1,1.65,62.5],[2,1.25,100]],"ltp":1.65,"tv":4.0,"id":31372}]}]}
{"op":"mcm","clk":"11824498193","pt":1723466151278,"mc":[{"id":"1.231699634","rc":[{"batb":[[0,1.65,62.5],[1,1.25,100],[2,1.08,7.83]],"ltp":1.65,"tv":4.0,"id":31372}]}]}
{"op":"mcm","clk":"11824498469","pt":1723466154582,"mc":[{"id":"1.231699634","rc":[{"batb":[[0,1.66,10],[1,1.65,62.5],[2,1.25,100]],"ltp":1.65,"tv":4.0,"id":31372}]}]}
{"op":"mcm","clk":"11824499132","pt":1723466162028,"mc":[{"id":"1.231699634","rc":[{"batb":[[0,1.65,62.5],[1,1.25,100],[2,1.08,7.83]],"ltp":1.65,"tv":4.0,"id":31372}]}]}
{"op":"mcm","clk":"11824499475","pt":1723466166523,"mc":[{"id":"1.231699634","rc":[{"batb":[[0,1.66,10],[1,1.65,62.5],[2,1.25,100]],"ltp":1.65,"tv":4.0,"id":31372}]}]}
{"op":"mcm","clk":"11824499922","pt":1723466171810,"mc":[{"id":"1.231699634","rc":[{"batb":[[0,1.65,62.5],[1,1.25,100],[2,1.08,7.83]],"ltp":1.65,"tv":4.0,"id":31372}]}]}
{"op":"mcm","clk":"11824500574","pt":1723466179505,"mc":[{"id":"1.231699634","rc":[{"batb":[[0,1.66,10],[1,1.65,62.5],[2,1.25,100]],"ltp":1.65,"tv":4.0,"id":31372}]}]}
{"op":"mcm","clk":"11824500852","pt":1723466182817,"mc":[{"id":"1.231699634","rc":[{"batb":[[0,1.65,62.5],[1,1.25,100],[2,1.08,7.83]],"ltp":1.65,"tv":4.0,"id":31372}]}]}
{"op":"mcm","clk":"11824501201","pt":1723466187747,"mc":[{"id":"1.231699634","rc":[{"batb":[[0,1.66,10],[1,1.65,62.5],[2,1.25,100]],"ltp":1.65,"tv":4.0,"id":31372}]}]}
{"op":"mcm","clk":"11824501436","pt":1723466191246,"mc":[{"id":"1.231699634","rc":[{"batb":[[0,1.65,62.5],[1,1.25,100],[2,1.08,7.83]],"ltp":1.65,"tv":4.0,"id":31372}]}]}
{"op":"mcm","clk":"11824501590","pt":1723466193610,"mc":[{"id":"1.231699634","rc":[{"batb":[[0,1.66,10],[1,1.65,62.5],[2,1.25,100]],"ltp":1.65,"tv":4.0,"id":31372}]}]}
{"op":"mcm","clk":"11824501801","pt":1723466197047,"mc":[{"id":"1.231699634","rc":[{"batb":[[0,1.65,62.5],[1,1.25,100],[2,1.08,7.83]],"ltp":1.65,"tv":4.0,"id":31372}]}]}
{"op":"mcm","clk":"11824501949","pt":1723466199518,"mc":[{"id":"1.231699634","rc":[{"batb":[[0,1.66,10],[1,1.65,62.5],[2,1.25,100]],"ltp":1.65,"tv":4.0,"id":31372}]}]}
{"op":"mcm","clk":"11824502196","pt":1723466202960,"mc":[{"id":"1.231699634","rc":[{"batb":[[0,1.65,62.5],[1,1.25,100],[2,1.08,7.83]],"ltp":1.65,"tv":4.0,"id":31372}]}]}
{"op":"mcm","clk":"11824502374","pt":1723466205422,"mc":[{"id":"1.231699634","rc":[{"batb":[[0,1.66,10],[1,1.65,62.5],[2,1.25,100]],"ltp":1.65,"tv":4.0,"id":31372}]}]}
{"op":"mcm","clk":"11824502681","pt":1723466210056,"mc":[{"id":"1.231699634","rc":[{"batb":[[0,1.65,62.5],[1,1.25,100],[2,1.08,7.83]],"ltp":1.65,"tv":4.0,"id":31372}]}]}
{"op":"mcm","clk":"11824502895","pt":1723466213248,"mc":[{"id":"1.231699634","rc":[{"batb":[[0,1.66,10],[1,1.65,62.5],[2,1.25,100]],"ltp":1.65,"tv":4.0,"id":31372}]}]}
{"op":"mcm","clk":"11824503155","pt":1723466216541,"mc":[{"id":"1.231699634","rc":[{"batb":[[0,1.65,62.5],[1,1.25,100],[2,1.08,7.83]],"ltp":1.65,"tv":4.0,"id":31372}]}]}
{"op":"mcm","clk":"11824503324","pt":1723466219481,"mc":[{"id":"1.231699634","rc":[{"batb":[[0,1.66,10],[1,1.65,62.5],[2,1.25,100]],"ltp":1.65,"tv":4.0,"id":31372}]}]}
{"op":"mcm","clk":"11824503675","pt":1723466223091,"mc":[{"id":"1.231699634","rc":[{"batb":[[0,1.65,62.5],[1,1.25,100],[2,1.08,7.83]],"ltp":1.65,"tv":4.0,"id":31372}]}]}
{"op":"mcm","clk":"11824504049","pt":1723466228384,"mc":[{"id":"1.231699634","rc":[{"batb":[[0,1.66,10],[1,1.65,62.5],[2,1.25,100]],"ltp":1.65,"tv":4.0,"id":31372}]}]}
{"op":"mcm","clk":"11824504473","pt":1723466234296,"mc":[{"id":"1.231699634","rc":[{"batb":[[0,1.65,62.5],[1,1.25,100],[2,1.08,7.83]],"ltp":1.65,"tv":4.0,"id":31372}]}]}
{"op":"mcm","clk":"11824504703","pt":1723466237585,"mc":[{"id":"1.231699634","rc":[{"batb":[[0,1.66,10],[1,1.65,62.5],[2,1.25,100]],"ltp":1.65,"tv":4.0,"id":31372}]}]}
{"op":"mcm","clk":"11824505040","pt":1723466242405,"mc":[{"id":"1.231699634","rc":[{"batb":[[0,1.65,62.5],[1,1.25,100],[2,1.08,7.83]],"ltp":1.65,"tv":4.0,"id":31372}]}]}
{"op":"mcm","clk":"11824505222","pt":1723466245075,"mc":[{"id":"1.231699634","rc":[{"batb":[[0,1.66,10],[1,1.65,62.5],[2,1.25,100]],"ltp":1.65,"tv":4.0,"id":31372}]}]}
{"op":"mcm","clk":"11824505430","pt":1723466248985,"mc":[{"id":"1.231699634","rc":[{"batb":[[0,1.65,62.5],[1,1.25,100],[2,1.08,7.83]],"ltp":1.65,"tv":4.0,"id":31372}]}]}
{"op":"mcm","clk":"11824505639","pt":1723466252784,"mc":[{"id":"1.231699634","rc":[{"batb":[[0,1.66,10],[1,1.65,62.5],[2,1.25,100]],"ltp":1.65,"tv":4.0,"id":31372}]}]}
{"op":"mcm","clk":"11824505886","pt":1723466256272,"mc":[{"id":"1.231699634","rc":[{"batb":[[0,1.65,62.5],[1,1.25,100],[2,1.08,7.83]],"ltp":1.65,"tv":4.0,"id":31372}]}]}
{"op":"mcm","clk":"11824557382","pt":1723467044572,"mc":[{"id":"1.231699634","rc":[{"batb":[[1,1.08,7.83],[2,1.07,7.83]],"ltp":2.34,"tv":141.84,"id":424679},{"batb":[[1,1.08,7.83],[2,1.07,7.83]],"ltp":1.65,"tv":4.0,"id":31372}]}]}
{"op":"mcm","clk":"11824579251","pt":1723467389136,"mc":[{"id":"1.231699634","rc":[{"batb":[[1,1.3,1166.67],[2,1.08,7.83]],"ltp":2.34,"tv":141.84,"id":424679},{"batb":[[1,1.3,1166.67],[2,1.08,7.83]],"ltp":1.65,"tv":4.0,"id":31372}]}]}
{"op":"mcm","clk":"11824583621","pt":1723467458329,"mc":[{"id":"1.231699634","rc":[{"batb":[[1,1.08,7.83],[2,1.07,7.83]],"ltp":2.34,"tv":141.84,"id":424679},{"batb":[[1,1.08,7.83],[2,1.07,7.83]],"ltp":1.65,"tv":4.0,"id":31372}]}]}
{"op":"mcm","clk":"11824585291","pt":1723467486334,"mc":[{"id":"1.231699634","rc":[{"batb":[[1,1.25,100],[2,1.08,7.83]],"ltp":2.34,"tv":141.84,"id":424679},{"batb":[[1,1.25,100],[2,1.08,7.83]],"ltp":1.65,"tv":4.0,"id":31372}]}]}
{"op":"mcm","clk":"11824593387","pt":1723467608898,"mc":[{"id":"1.231699634","rc":[{"batb":[[2,1.08,7.83]],"ltp":2.34,"tv":141.84,"id":424679},{"batb":[[0,1.66,10],[1,1.65,62.5],[2,1.25,100]],"batl":[[0,2.32,80.6]],"ltp":1.65,"tv":4.0,"id":31372}]}]}
{"op":"mcm","clk":"11824593685","pt":1723467613310,"mc":[{"id":"1.231699634","rc":[{"batb":[[0,1.65,62.5],[1,1.25,100],[2,1.08,7.83]],"ltp":1.65,"tv":4.0,"id":31372}]}]}
{"op":"mcm","clk":"11824593983","pt":1723467617635,"mc":[{"id":"1.231699634","rc":[{"batb":[[0,1.66,10],[1,1.65,62.5],[2,1.25,100]],"ltp":1.65,"tv":4.0,"id":31372}]}]}
{"op":"mcm","clk":"11824594236","pt":1723467621123,"mc":[{"id":"1.231699634","rc":[{"batb":[[0,1.65,62.5],[1,1.25,100],[2,1.08,7.83]],"ltp":1.65,"tv":4.0,"id":31372}]}]}
{"op":"mcm","clk":"11824594709","pt":1723467628005,"mc":[{"id":"1.231699634","rc":[{"batb":[[0,1.66,10],[1,1.65,62.5],[2,1.25,100]],"ltp":1.65,"tv":4.0,"id":31372}]}]}
{"op":"mcm","clk":"11824594935","pt":1723467631638,"mc":[{"id":"1.231699634","rc":[{"batb":[[0,1.65,62.5],[1,1.25,100],[2,1.08,7.83]],"ltp":1.65,"tv":4.0,"id":31372}]}]}
{"op":"mcm","clk":"11824595122","pt":1723467634535,"mc":[{"id":"1.231699634","rc":[{"batb":[[0,1.66,10],[1,1.65,62.5],[2,1.25,100]],"ltp":1.65,"tv":4.0,"id":31372}]}]}
{"op":"mcm","clk":"11824595381","pt":1723467637821,"mc":[{"id":"1.231699634","rc":[{"batb":[[0,1.65,62.5],[1,1.25,100],[2,1.08,7.83]],"ltp":1.65,"tv":4.0,"id":31372}]}]}
{"op":"mcm","clk":"11824595693","pt":1723467641749,"mc":[{"id":"1.231699634","rc":[{"batb":[[0,1.66,10],[1,1.65,62.5],[2,1.25,100]],"ltp":1.65,"tv":4.0,"id":31372}]}]}
{"op":"mcm","clk":"11824595925","pt":1723467645958,"mc":[{"id":"1.231699634","rc":[{"batb":[[0,1.65,62.5],[1,1.25,100],[2,1.08,7.83]],"ltp":1.65,"tv":4.0,"id":31372}]}]}
{"op":"mcm","clk":"11824596875","pt":1723467660410,"mc":[{"id":"1.231699634","rc":[{"batb":[[0,1.66,10],[1,1.65,62.5],[2,1.25,100]],"ltp":1.65,"tv":4.0,"id":31372}]}]}
{"op":"mcm","clk":"11824597110","pt":1723467663705,"mc":[{"id":"1.231699634","rc":[{"batb":[[0,1.65,62.5],[1,1.25,100],[2,1.08,7.83]],"ltp":1.65,"tv":4.0,"id":31372}]}]}
{"op":"mcm","clk":"11824597697","pt":1723467672731,"mc":[{"id":"1.231699634","rc":[{"batb":[[0,1.66,10],[1,1.65,62.5],[2,1.25,100]],"ltp":1.65,"tv":4.0,"id":31372}]}]}
{"op":"mcm","clk":"11824597891","pt":1723467676019,"mc":[{"id":"1.231699634","rc":[{"batb":[[0,1.65,62.5],[1,1.25,100],[2,1.08,7.83]],"ltp":1.65,"tv":4.0,"id":31372}]}]}
{"op":"mcm","clk":"11824598354","pt":1723467683276,"mc":[{"id":"1.231699634","rc":[{"batb":[[0,1.66,10],[1,1.65,62.5],[2,1.25,100]],"ltp":1.65,"tv":4.0,"id":31372}]}]}
{"op":"mcm","clk":"11824598697","pt":1723467687952,"mc":[{"id":"1.231699634","rc":[{"batb":[[0,1.65,62.5],[1,1.25,100],[2,1.08,7.83]],"ltp":1.65,"tv":4.0,"id":31372}]}]}
{"op":"mcm","clk":"11824599095","pt":1723467694373,"mc":[{"id":"1.231699634","rc":[{"batb":[[0,1.66,10],[1,1.65,62.5],[2,1.25,100]],"ltp":1.65,"tv":4.0,"id":31372}]}]}
{"op":"mcm","clk":"11824599332","pt":1723467697866,"mc":[{"id":"1.231699634","rc":[{"batb":[[0,1.65,62.5],[1,1.25,100],[2,1.08,7.83]],"ltp":1.65,"tv":4.0,"id":31372}]}]}
{"op":"mcm","clk":"11824599561","pt":1723467701973,"mc":[{"id":"1.231699634","rc":[{"batb":[[0,1.66,10],[1,1.65,62.5],[2,1.25,100]],"ltp":1.65,"tv":4.0,"id":31372}]}]}
{"op":"mcm","clk":"11824599829","pt":1723467706482,"mc":[{"id":"1.231699634","rc":[{"batb":[[0,1.65,62.5],[1,1.25,100],[2,1.08,7.83]],"ltp":1.65,"tv":4.0,"id":31372}]}]}
{"op":"mcm","clk":"11824600187","pt":1723467713202,"mc":[{"id":"1.231699634","rc":[{"batb":[[0,1.66,10],[1,1.65,62.5],[2,1.25,100]],"ltp":1.65,"tv":4.0,"id":31372}]}]}
{"op":"mcm","clk":"11824600443","pt":1723467717612,"mc":[{"id":"1.231699634","rc":[{"batb":[[0,1.65,62.5],[1,1.25,100],[2,1.08,7.83]],"ltp":1.65,"tv":4.0,"id":31372}]}]}
{"op":"mcm","clk":"11824600580","pt":1723467719973,"mc":[{"id":"1.231699634","rc":[{"batb":[[0,1.66,10],[1,1.65,62.5],[2,1.25,100]],"ltp":1.65,"tv":4.0,"id":31372}]}]}
{"op":"mcm","clk":"11824600759","pt":1723467723513,"mc":[{"id":"1.231699634","rc":[{"batb":[[0,1.65,62.5],[1,1.25,100],[2,1.08,7.83]],"ltp":1.65,"tv":4.0,"id":31372}]}]}
{"op":"mcm","clk":"11824601483","pt":1723467735007,"mc":[{"id":"1.231699634","rc":[{"batb":[[0,1.66,10],[1,1.65,62.5],[2,1.25,100]],"ltp":1.65,"tv":4.0,"id":31372}]}]}
{"op":"mcm","clk":"11824601688","pt":1723467738597,"mc":[{"id":"1.231699634","rc":[{"batb":[[0,1.65,62.5],[1,1.25,100],[2,1.08,7.83]],"ltp":1.65,"tv":4.0,"id":31372}]}]}
{"op":"mcm","clk":"11824601920","pt":1723467742392,"mc":[{"id":"1.231699634","rc":[{"batb":[[0,1.66,10],[1,1.65,62.5],[2,1.25,100]],"ltp":1.65,"tv":4.0,"id":31372}]}]}
{"op":"mcm","clk":"11824602132","pt":1723467745833,"mc":[{"id":"1.231699634","rc":[{"batb":[[0,1.65,62.5],[1,1.25,100],[2,1.08,7.83]],"ltp":1.65,"tv":4.0,"id":31372}]}]}
{"op":"mcm","clk":"11824602336","pt":1723467749528,"mc":[{"id":"1.231699634","rc":[{"batb":[[0,1.66,10],[1,1.65,62.5],[2,1.25,100]],"ltp":1.65,"tv":4.0,"id":31372}]}]}
{"op":"mcm","clk":"11824602598","pt":1723467753435,"mc":[{"id":"1.231699634","rc":[{"batb":[[0,1.65,62.5],[1,1.25,100],[2,1.08,7.83]],"ltp":1.65,"tv":4.0,"id":31372}]}]}
{"op":"mcm","clk":"11824602750","pt":1723467756052,"mc":[{"id":"1.231699634","rc":[{"batb":[[0,1.66,10],[1,1.65,62.5],[2,1.25,100]],"ltp":1.65,"tv":4.0,"id":31372}]}]}
{"op":"mcm","clk":"11824602961","pt":1723467759240,"mc":[{"id":"1.231699634","rc":[{"batb":[[0,1.65,62.5],[1,1.25,100],[2,1.08,7.83]],"ltp":1.65,"tv":4.0,"id":31372}]}]}
{"op":"mcm","clk":"11824603199","pt":1723467762729,"mc":[{"id":"1.231699634","rc":[{"batb":[[0,1.66,10],[1,1.65,62.5],[2,1.25,100]],"ltp":1.65,"tv":4.0,"id":31372}]}]}
{"op":"mcm","clk":"11824603378","pt":1723467766057,"mc":[{"id":"1.231699634","rc":[{"batb":[[0,1.65,62.5],[1,1.25,100],[2,1.08,7.83]],"ltp":1.65,"tv":4.0,"id":31372}]}]}
{"op":"mcm","clk":"11824603537","pt":1723467768627,"mc":[{"id":"1.231699634","rc":[{"batb":[[0,1.66,10],[1,1.65,62.5],[2,1.25,100]],"ltp":1.65,"tv":4.0,"id":31372}]}]}
{"op":"mcm","clk":"11824603778","pt":1723467772270,"mc":[{"id":"1.231699634","rc":[{"batb":[[0,1.65,62.5],[1,1.25,100],[2,1.08,7.83]],"ltp":1.65,"tv":4.0,"id":31372}]}]}
{"op":"mcm","clk":"11824603974","pt":1723467775041,"mc":[{"id":"1.231699634","rc":[{"batb":[[0,1.66,10],[1,1.65,62.5],[2,1.25,100]],"ltp":1.65,"tv":4.0,"id":31372}]}]}
{"op":"mcm","clk":"11824604258","pt":1723467778949,"mc":[{"id":"1.231699634","rc":[{"batb":[[0,1.65,62.5],[1,1.25,100],[2,1.08,7.83]],"ltp":1.65,"tv":4.0,"id":31372}]}]}
{"op":"mcm","clk":"11824604865","pt":1723467787884,"mc":[{"id":"1.231699634","rc":[{"batb":[[0,1.66,10],[1,1.65,62.5],[2,1.25,100]],"ltp":1.65,"tv":4.0,"id":31372}]}]}
{"op":"mcm","clk":"11824605107","pt":1723467791270,"mc":[{"id":"1.231699634","rc":[{"batb":[[0,1.65,62.5],[1,1.25,100],[2,1.08,7.83]],"ltp":1.65,"tv":4.0,"id":31372}]}]}
{"op":"mcm","clk":"11824605516","pt":1723467798269,"mc":[{"id":"1.231699634","rc":[{"batb":[[0,1.66,10],[1,1.65,62.5],[2,1.25,100]],"ltp":1.65,"tv":4.0,"id":31372}]}]}
{"op":"mcm","clk":"11824605747","pt":1723467801980,"mc":[{"id":"1.231699634","rc":[{"batb":[[0,1.65,62.5],[1,1.25,100],[2,1.08,7.83]],"ltp":1.65,"tv":4.0,"id":31372}]}]}
{"op":"mcm","clk":"11824607184","pt":1723467825008,"mc":[{"id":"1.231699634","rc":[{"batb":[[0,1.66,10],[1,1.65,62.5],[2,1.25,100]],"ltp":1.65,"tv":4.0,"id":31372}]}]}
{"op":"mcm","clk":"11824607385","pt":1723467828405,"mc":[{"id":"1.231699634","rc":[{"batb":[[0,1.65,62.5],[1,1.25,100],[2,1.08,7.83]],"ltp":1.65,"tv":4.0,"id":31372}]}]}
{"op":"mcm","clk":"11824607778","pt":1723467835017,"mc":[{"id":"1.231699634","rc":[{"batb":[[0,1.66,10],[1,1.65,62.5],[2,1.25,100]],"ltp":1.65,"tv":4.0,"id":31372}]}]}
{"op":"mcm","clk":"11824608035","pt":1723467838512,"mc":[{"id":"1.231699634","rc":[{"batb":[[0,1.65,62.5],[1,1.25,100],[2,1.08,7.83]],"ltp":1.65,"tv":4.0,"id":31372}]}]}
{"op":"mcm","clk":"11824608262","pt":1723467842145,"mc":[{"id":"1.231699634","rc":[{"batb":[[0,1.66,10],[1,1.65,62.5],[2,1.25,100]],"ltp":1.65,"tv":4.0,"id":31372}]}]}
{"op":"mcm","clk":"11824608460","pt":1723467845644,"mc":[{"id":"1.231699634","rc":[{"batb":[[0,1.65,62.5],[1,1.25,100],[2,1.08,7.83]],"ltp":1.65,"tv":4.0,"id":31372}]}]}
{"op":"mcm","clk":"11824608767","pt":1723467849542,"mc":[{"id":"1.231699634","rc":[{"batb":[[0,1.66,10],[1,1.65,62.5],[2,1.25,100]],"ltp":1.65,"tv":4.0,"id":31372}]}]}
{"op":"mcm","clk":"11824609061","pt":1723467854155,"mc":[{"id":"1.231699634","rc":[{"batb":[[0,1.65,62.5],[1,1.25,100],[2,1.08,7.83]],"ltp":1.65,"tv":4.0,"id":31372}]}]}
{"op":"mcm","clk":"11824609333","pt":1723467859034,"mc":[{"id":"1.231699634","rc":[{"batb":[[0,1.66,10],[1,1.65,62.5],[2,1.25,100]],"ltp":1.65,"tv":4.0,"id":31372}]}]}
{"op":"mcm","clk":"11824609535","pt":1723467862572,"mc":[{"id":"1.231699634","rc":[{"batb":[[0,1.65,62.5],[1,1.25,100],[2,1.08,7.83]],"ltp":1.65,"tv":4.0,"id":31372}]}]}
{"op":"mcm","clk":"11824610358","pt":1723467875074,"mc":[{"id":"1.231699634","rc":[{"batb":[[0,1.66,10],[1,1.65,62.5],[2,1.25,100]],"ltp":1.65,"tv":4.0,"id":31372}]}]}
{"op":"mcm","clk":"11824610772","pt":1723467880681,"mc":[{"id":"1.231699634","rc":[{"batb":[[0,1.65,62.5],[1,1.25,100],[2,1.08,7.83]],"ltp":1.65,"tv":4.0,"id":31372}]}]}
{"op":"mcm","clk":"11824611021","pt":1723467884574,"mc":[{"id":"1.231699634","rc":[{"batb":[[0,1.66,10],[1,1.65,62.5],[2,1.25,100]],"ltp":1.65,"tv":4.0,"id":31372}]}]}
{"op":"mcm","clk":"11824611345","pt":1723467890167,"mc":[{"id":"1.231699634","rc":[{"batb":[[0,1.65,62.5],[1,1.25,100],[2,1.08,7.83]],"ltp":1.65,"tv":4.0,"id":31372}]}]}
{"op":"mcm","clk":"11824611878","pt":1723467898184,"mc":[{"id":"1.231699634","rc":[{"batb":[[0,1.66,10],[1,1.65,62.5],[2,1.25,100]],"ltp":1.65,"tv":4.0,"id":31372}]}]}
{"op":"mcm","clk":"11824612081","pt":1723467901587,"mc":[{"id":"1.231699634","rc":[{"batb":[[0,1.65,62.5],[1,1.25,100],[2,1.08,7.83]],"ltp":1.65,"tv":4.0,"id":31372}]}]}
{"op":"mcm","clk":"11824612671","pt":1723467909311,"mc":[{"id":"1.231699634","rc":[{"batb":[[0,1.66,10],[1,1.65,62.5],[2,1.25,100]],"ltp":1.65,"tv":4.0,"id":31372}]}]}
{"op":"mcm","clk":"11824613011","pt":1723467914085,"mc":[{"id":"1.231699634","rc":[{"batb":[[0,1.65,62.5],[1,1.25,100],[2,1.08,7.83]],"ltp":1.65,"tv":4.0,"id":31372}]}]}
{"op":"mcm","clk":"11824613239","pt":1723467917991,"mc":[{"id":"1.231699634","rc":[{"batb":[[0,1.66,10],[1,1.65,62.5],[2,1.25,100]],"ltp":1.65,"tv":4.0,"id":31372}]}]}
{"op":"mcm","clk":"11824613433","pt":1723467921427,"mc":[{"id":"1.231699634","rc":[{"batb":[[0,1.65,62.5],[1,1.25,100],[2,1.08,7.83]],"ltp":1.65,"tv":4.0,"id":31372}]}]}
{"op":"mcm","clk":"11824613942","pt":1723467928745,"mc":[{"id":"1.231699634","rc":[{"batb":[[0,1.66,10],[1,1.65,62.5],[2,1.25,100]],"ltp":1.65,"tv":4.0,"id":31372}]}]}
{"op":"mcm","clk":"11824614223","pt":1723467933657,"mc":[{"id":"1.231699634","rc":[{"batb":[[0,1.65,62.5],[1,1.25,100],[2,1.08,7.83]],"ltp":1.65,"tv":4.0,"id":31372}]}]}
{"op":"mcm","clk":"11824614811","pt":1723467943754,"mc":[{"id":"1.231699634","rc":[{"batb":[[0,1.66,10],[1,1.65,62.5],[2,1.25,100]],"ltp":1.65,"tv":4.0,"id":31372}]}]}
{"op":"mcm","clk":"11824615091","pt":1723467948349,"mc":[{"id":"1.231699634","rc":[{"batb":[[0,1.65,62.5],[1,1.25,100],[2,1.08,7.83]],"ltp":1.65,"tv":4.0,"id":31372}]}]}
{"op":"mcm","clk":"11824615350","pt":1723467953167,"mc":[{"id":"1.231699634","rc":[{"batb":[[0,1.66,10],[1,1.65,62.5],[2,1.25,100]],"ltp":1.65,"tv":4.0,"id":31372}]}]}
{"op":"mcm","clk":"11824615522","pt":1723467956664,"mc":[{"id":"1.231699634","rc":[{"batb":[[0,1.65,62.5],[1,1.25,100],[2,1.08,7.83]],"ltp":1.65,"tv":4.0,"id":31372}]}]}
{"op":"mcm","clk":"11824615691","pt":1723467960046,"mc":[{"id":"1.231699634","rc":[{"batb":[[0,1.66,10],[1,1.65,62.5],[2,1.25,100]],"ltp":1.65,"tv":4.0,"id":31372}]}]}
{"op":"mcm","clk":"11824615911","pt":1723467963545,"mc":[{"id":"1.231699634","rc":[{"batb":[[0,1.65,62.5],[1,1.25,100],[2,1.08,7.83]],"ltp":1.65,"tv":4.0,"id":31372}]}]}
{"op":"mcm","clk":"11824616120","pt":1723467966983,"mc":[{"id":"1.231699634","rc":[{"batb":[[0,1.66,10],[1,1.65,62.5],[2,1.25,100]],"ltp":1.65,"tv":4.0,"id":31372}]}]}
{"op":"mcm","clk":"11824616294","pt":1723467970373,"mc":[{"id":"1.231699634","rc":[{"batb":[[0,1.65,62.5],[1,1.25,100],[2,1.08,7.83]],"ltp":1.65,"tv":4.0,"id":31372}]}]}
{"op":"mcm","clk":"11824616572","pt":1723467975266,"mc":[{"id":"1.231699634","rc":[{"batb":[[0,1.66,10],[1,1.65,62.5],[2,1.25,100]],"ltp":1.65,"tv":4.0,"id":31372}]}]}
{"op":"mcm","clk":"11824616760","pt":1723467978559,"mc":[{"id":"1.231699634","rc":[{"batb":[[0,1.65,62.5],[1,1.25,100],[2,1.08,7.83]],"ltp":1.65,"tv":4.0,"id":31372}]}]}
{"op":"mcm","clk":"11824616956","pt":1723467981796,"mc":[{"id":"1.231699634","rc":[{"batb":[[0,1.66,10],[1,1.65,62.5],[2,1.25,100]],"ltp":1.65,"tv":4.0,"id":31372}]}]}
{"op":"mcm","clk":"11824617194","pt":1723467984981,"mc":[{"id":"1.231699634","rc":[{"batb":[[0,1.65,62.5],[1,1.25,100],[2,1.08,7.83]],"ltp":1.65,"tv":4.0,"id":31372}]}]}
{"op":"mcm","clk":"11824617337","pt":1723467987292,"mc":[{"id":"1.231699634","rc":[{"batb":[[0,1.66,10],[1,1.65,62.5],[2,1.25,100]],"ltp":1.65,"tv":4.0,"id":31372}]}]}
{"op":"mcm","clk":"11824617537","pt":1723467990689,"mc":[{"id":"1.231699634","rc":[{"batb":[[0,1.65,62.5],[1,1.25,100],[2,1.08,7.83]],"ltp":1.65,"tv":4.0,"id":31372}]}]}
{"op":"mcm","clk":"11824617740","pt":1723467993979,"mc":[{"id":"1.231699634","rc":[{"batb":[[0,1.66,10],[1,1.65,62.5],[2,1.25,100]],"ltp":1.65,"tv":4.0,"id":31372}]}]}
{"op":"mcm","clk":"11824617922","pt":1723467997210,"mc":[{"id":"1.231699634","rc":[{"batb":[[0,1.65,62.5],[1,1.25,100],[2,1.08,7.83]],"ltp":1.65,"tv":4.0,"id":31372}]}]}
{"op":"mcm","clk":"11824618320","pt":1723468002973,"mc":[{"id":"1.231699634","rc":[{"batb":[[0,1.66,10],[1,1.65,62.5],[2,1.25,100]],"ltp":1.65,"tv":4.0,"id":31372}]}]}
{"op":"mcm","clk":"11824618683","pt":1723468007823,"mc":[{"id":"1.231699634","rc":[{"batb":[[0,1.65,62.5],[1,1.25,100],[2,1.08,7.83]],"ltp":1.65,"tv":4.0,"id":31372}]}]}
{"op":"mcm","clk":"11824618910","pt":1723468011422,"mc":[{"id":"1.231699634","rc":[{"batb":[[0,1.66,10],[1,1.65,62.5],[2,1.25,100]],"ltp":1.65,"tv":4.0,"id":31372}]}]}
{"op":"mcm","clk":"11824619133","pt":1723468014707,"mc":[{"id":"1.231699634","rc":[{"batb":[[0,1.65,62.5],[1,1.25,100],[2,1.08,7.83]],"ltp":1.65,"tv":4.0,"id":31372}]}]}
{"op":"mcm","clk":"11824619552","pt":1723468020923,"mc":[{"id":"1.231699634","rc":[{"batb":[[0,1.66,10],[1,1.65,62.5],[2,1.25,100]],"ltp":1.65,"tv":4.0,"id":31372}]}]}
{"op":"mcm","clk":"11824619783","pt":1723468024520,"mc":[{"id":"1.231699634","rc":[{"batb":[[0,1.65,62.5],[1,1.25,100],[2,1.08,7.83]],"ltp":1.65,"tv":4.0,"id":31372}]}]}
{"op":"mcm","clk":"11824620593","pt":1723468035337,"mc":[{"id":"1.231699634","rc":[{"batb":[[0,1.66,10],[1,1.65,62.5],[2,1.25,100]],"ltp":1.65,"tv":4.0,"id":31372}]}]}
{"op":"mcm","clk":"11824620833","pt":1723468038737,"mc":[{"id":"1.231699634","rc":[{"batb":[[0,1.65,62.5],[1,1.25,100],[2,1.08,7.83]],"ltp":1.65,"tv":4.0,"id":31372}]}]}
{"op":"mcm","clk":"11824621177","pt":1723468044346,"mc":[{"id":"1.231699634","rc":[{"batb":[[0,1.66,10],[1,1.65,62.5],[2,1.25,100]],"ltp":1.65,"tv":4.0,"id":31372}]}]}
{"op":"mcm","clk":"11824621389","pt":1723468047647,"mc":[{"id":"1.231699634","rc":[{"batb":[[0,1.65,62.5],[1,1.25,100],[2,1.08,7.83]],"ltp":1.65,"tv":4.0,"id":31372}]}]}
{"op":"mcm","clk":"11824621581","pt":1723468050275,"mc":[{"id":"1.231699634","rc":[{"batb":[[0,1.66,10],[1,1.65,62.5],[2,1.25,100]],"ltp":1.65,"tv":4.0,"id":31372}]}]}
{"op":"mcm","clk":"11824621818","pt":1723468053782,"mc":[{"id":"1.231699634","rc":[{"batb":[[0,1.65,62.5],[1,1.25,100],[2,1.08,7.83]],"ltp":1.65,"tv":4.0,"id":31372}]}]}
{"op":"mcm","clk":"11824622033","pt":1723468057180,"mc":[{"id":"1.231699634","rc":[{"batb":[[0,1.66,10],[1,1.65,62.5],[2,1.25,100]],"ltp":1.65,"tv":4.0,"id":31372}]}]}
{"op":"mcm","clk":"11824622268","pt":1723468060637,"mc":[{"id":"1.231699634","rc":[{"batb":[[0,1.65,62.5],[1,1.25,100],[2,1.08,7.83]],"ltp":1.65,"tv":4.0,"id":31372}]}]}
{"op":"mcm","clk":"11824623090","pt":1723468072174,"mc":[{"id":"1.231699634","rc":[{"batb":[[0,1.66,10],[1,1.65,62.5],[2,1.25,100]],"ltp":1.65,"tv":4.0,"id":31372}]}]}
{"op":"mcm","clk":"11824623551","pt":1723468078094,"mc":[{"id":"1.231699634","rc":[{"batb":[[0,1.65,62.5],[1,1.25,100],[2,1.08,7.83]],"ltp":1.65,"tv":4.0,"id":31372}]}]}
{"op":"mcm","clk":"11824623805","pt":1723468081303,"mc":[{"id":"1.231699634","rc":[{"batb":[[0,1.66,10],[1,1.65,62.5],[2,1.25,100]],"ltp":1.65,"tv":4.0,"id":31372}]}]}
{"op":"mcm","clk":"11824624229","pt":1723468086890,"mc":[{"id":"1.231699634","rc":[{"batb":[[0,1.65,62.5],[1,1.25,100],[2,1.08,7.83]],"ltp":1.65,"tv":4.0,"id":31372}]}]}
{"op":"mcm","clk":"11824624611","pt":1723468091201,"mc":[{"id":"1.231699634","rc":[{"batb":[[0,1.66,10],[1,1.65,62.5],[2,1.25,100]],"ltp":1.65,"tv":4.0,"id":31372}]}]}
{"op":"mcm","clk":"11824624850","pt":1723468094519,"mc":[{"id":"1.231699634","rc":[{"batb":[[0,1.65,62.5],[1,1.25,100],[2,1.08,7.83]],"ltp":1.65,"tv":4.0,"id":31372}]}]}
{"op":"mcm","clk":"11824625128","pt":1723468098303,"mc":[{"id":"1.231699634","rc":[{"batb":[[0,1.66,10],[1,1.65,62.5],[2,1.25,100]],"ltp":1.65,"tv":4.0,"id":31372}]}]}
{"op":"mcm","clk":"11824625361","pt":1723468101717,"mc":[{"id":"1.231699634","rc":[{"batb":[[0,1.65,62.5],[1,1.25,100],[2,1.08,7.83]],"ltp":1.65,"tv":4.0,"id":31372}]}]}
{"op":"mcm","clk":"11824625754","pt":1723468106933,"mc":[{"id":"1.231699634","rc":[{"batb":[[0,1.66,10],[1,1.65,62.5],[2,1.25,100]],"ltp":1.65,"tv":4.0,"id":31372}]}]}
{"op":"mcm","clk":"11824626068","pt":1723468110906,"mc":[{"id":"1.231699634","rc":[{"batb":[[0,1.65,62.5],[1,1.25,100],[2,1.08,7.83]],"ltp":1.65,"tv":4.0,"id":31372}]}]}
{"op":"mcm","clk":"11824626837","pt":1723468122018,"mc":[{"id":"1.231699634","rc":[{"batb":[[0,1.66,10],[1,1.65,62.5],[2,1.25,100]],"ltp":1.65,"tv":4.0,"id":31372}]}]}
{"op":"mcm","clk":"11824627127","pt":1723468125435,"mc":[{"id":"1.231699634","rc":[{"batb":[[0,1.65,62.5],[1,1.25,100],[2,1.08,7.83]],"ltp":1.65,"tv":4.0,"id":31372}]}]}
{"op":"mcm","clk":"11824627423","pt":1723468129167,"mc":[{"id":"1.231699634","rc":[{"batb":[[0,1.66,10],[1,1.65,62.5],[2,1.25,100]],"ltp":1.65,"tv":4.0,"id":31372}]}]}
{"op":"mcm","clk":"11824627758","pt":1723468133155,"mc":[{"id":"1.231699634","rc":[{"batb":[[0,1.65,62.5],[1,1.25,100],[2,1.08,7.83]],"ltp":1.65,"tv":4.0,"id":31372}]}]}
{"op":"mcm","clk":"11824628070","pt":1723468137741,"mc":[{"id":"1.231699634","rc":[{"batb":[[0,1.66,10],[1,1.65,62.5],[2,1.25,100]],"ltp":1.65,"tv":4.0,"id":31372}]}]}
{"op":"mcm","clk":"11824628327","pt":1723468141173,"mc":[{"id":"1.231699634","rc":[{"batb":[[0,1.65,62.5],[1,1.25,100],[2,1.08,7.83]],"ltp":1.65,"tv":4.0,"id":31372}]}]}
{"op":"mcm","clk":"11824628727","pt":1723468146492,"mc":[{"id":"1.231699634","rc":[{"batb":[[0,1.66,10],[1,1.65,62.5],[2,1.25,100]],"ltp":1.65,"tv":4.0,"id":31372}]}]}
{"op":"mcm","clk":"11824628948","pt":1723468149755,"mc":[{"id":"1.231699634","rc":[{"batb":[[0,1.65,62.5],[1,1.25,100],[2,1.08,7.83]],"ltp":1.65,"tv":4.0,"id":31372}]}]}
{"op":"mcm","clk":"11824629218","pt":1723468154114,"mc":[{"id":"1.231699634","rc":[{"batb":[[0,1.66,10],[1,1.65,62.5],[2,1.25,100]],"ltp":1.65,"tv":4.0,"id":31372}]}]}
{"op":"mcm","clk":"11824629429","pt":1723468157401,"mc":[{"id":"1.231699634","rc":[{"batb":[[0,1.65,62.5],[1,1.25,100],[2,1.08,7.83]],"ltp":1.65,"tv":4.0,"id":31372}]}]}
{"op":"mcm","clk":"11824629827","pt":1723468163372,"mc":[{"id":"1.231699634","rc":[{"batb":[[0,1.66,10],[1,1.65,62.5],[2,1.25,100]],"ltp":1.65,"tv":4.0,"id":31372}]}]}
{"op":"mcm","clk":"11824630070","pt":1723468166770,"mc":[{"id":"1.231699634","rc":[{"batb":[[0,1.65,62.5],[1,1.25,100],[2,1.08,7.83]],"ltp":1.65,"tv":4.0,"id":31372}]}]}
{"op":"mcm","clk":"11824630514","pt":1723468173328,"mc":[{"id":"1.231699634","rc":[{"batb":[[0,1.66,10],[1,1.65,62.5],[2,1.25,100]],"ltp":1.65,"tv":4.0,"id":31372}]}]}
{"op":"mcm","clk":"11824630748","pt":1723468176796,"mc":[{"id":"1.231699634","rc":[{"batb":[[0,1.65,62.5],[1,1.25,100],[2,1.08,7.83]],"ltp":1.65,"tv":4.0,"id":31372}]}]}
{"op":"mcm","clk":"11824631252","pt":1723468184295,"mc":[{"id":"1.231699634","rc":[{"batb":[[0,1.66,10],[1,1.65,62.5],[2,1.25,100]],"ltp":1.65,"tv":4.0,"id":31372}]}]}
{"op":"mcm","clk":"11824631477","pt":1723468187905,"mc":[{"id":"1.231699634","rc":[{"batb":[[0,1.65,62.5],[1,1.25,100],[2,1.08,7.83]],"ltp":1.65,"tv":4.0,"id":31372}]}]}
{"op":"mcm","clk":"11824631659","pt":1723468190696,"mc":[{"id":"1.231699634","rc":[{"batb":[[0,1.66,10],[1,1.65,62.5],[2,1.25,100]],"ltp":1.65,"tv":4.0,"id":31372}]}]}
{"op":"mcm","clk":"11824631898","pt":1723468194113,"mc":[{"id":"1.231699634","rc":[{"batb":[[0,1.65,62.5],[1,1.25,100],[2,1.08,7.83]],"ltp":1.65,"tv":4.0,"id":31372}]}]}
{"op":"mcm","clk":"11824632065","pt":1723468196907,"mc":[{"id":"1.231699634","rc":[{"batb":[[0,1.66,10],[1,1.65,62.5],[2,1.25,100]],"ltp":1.65,"tv":4.0,"id":31372}]}]}
{"op":"mcm","clk":"11824632283","pt":1723468200216,"mc":[{"id":"1.231699634","rc":[{"batb":[[0,1.65,62.5],[1,1.25,100],[2,1.08,7.83]],"ltp":1.65,"tv":4.0,"id":31372}]}]}
{"op":"mcm","clk":"11824632695","pt":1723468205847,"mc":[{"id":"1.231699634","rc":[{"batb":[[0,1.66,10],[1,1.65,62.5],[2,1.25,100]],"ltp":1.65,"tv":4.0,"id":31372}]}]}
{"op":"mcm","clk":"11824632931","pt":1723468209253,"mc":[{"id":"1.231699634","rc":[{"batb":[[0,1.65,62.5],[1,1.25,100],[2,1.08,7.83]],"ltp":1.65,"tv":4.0,"id":31372}]}]}
{"op":"mcm","clk":"11824633171","pt":1723468212245,"mc":[{"id":"1.231699634","rc":[{"batb":[[0,1.66,10],[1,1.65,62.5],[2,1.25,100]],"ltp":1.65,"tv":4.0,"id":31372}]}]}
{"op":"mcm","clk":"11824633397","pt":1723468215746,"mc":[{"id":"1.231699634","rc":[{"batb":[[0,1.65,62.5],[1,1.25,100],[2,1.08,7.83]],"ltp":1.65,"tv":4.0,"id":31372}]}]}
{"op":"mcm","clk":"11824633561","pt":1723468217960,"mc":[{"id":"1.231699634","rc":[{"batb":[[0,1.66,10],[1,1.65,62.5],[2,1.25,100]],"ltp":1.65,"tv":4.0,"id":31372}]}]}
{"op":"mcm","clk":"11824633785","pt":1723468221158,"mc":[{"id":"1.231699634","rc":[{"batb":[[0,1.65,62.5],[1,1.25,100],[2,1.08,7.83]],"ltp":1.65,"tv":4.0,"id":31372}]}]}
{"op":"mcm","clk":"11824633968","pt":1723468223541,"mc":[{"id":"1.231699634","rc":[{"batb":[[0,1.66,10],[1,1.65,62.5],[2,1.25,100]],"ltp":1.65,"tv":4.0,"id":31372}]}]}
{"op":"mcm","clk":"11824634182","pt":1723468226837,"mc":[{"id":"1.231699634","rc":[{"batb":[[0,1.65,62.5],[1,1.25,100],[2,1.08,7.83]],"ltp":1.65,"tv":4.0,"id":31372}]}]}
{"op":"mcm","clk":"11824634338","pt":1723468229251,"mc":[{"id":"1.231699634","rc":[{"batb":[[0,1.66,10],[1,1.65,62.5],[2,1.25,100]],"ltp":1.65,"tv":4.0,"id":31372}]}]}
{"op":"mcm","clk":"11824634563","pt":1723468232553,"mc":[{"id":"1.231699634","rc":[{"batb":[[0,1.65,62.5],[1,1.25,100],[2,1.08,7.83]],"ltp":1.65,"tv":4.0,"id":31372}]}]}
{"op":"mcm","clk":"11824634779","pt":1723468235383,"mc":[{"id":"1.231699634","rc":[{"batb":[[0,1.66,10],[1,1.65,62.5],[2,1.25,100]],"ltp":1.65,"tv":4.0,"id":31372}]}]}
{"op":"mcm","clk":"11824635115","pt":1723468240389,"mc":[{"id":"1.231699634","rc":[{"batb":[[0,1.65,62.5],[1,1.25,100],[2,1.08,7.83]],"ltp":1.65,"tv":4.0,"id":31372}]}]}
{"op":"mcm","clk":"11824635481","pt":1723468244976,"mc":[{"id":"1.231699634","rc":[{"batb":[[0,1.66,10],[1,1.65,62.5],[2,1.25,100]],"ltp":1.65,"tv":4.0,"id":31372}]}]}
{"op":"mcm","clk":"11824635766","pt":1723468248988,"mc":[{"id":"1.231699634","rc":[{"batb":[[0,1.65,62.5],[1,1.25,100],[2,1.08,7.83]],"ltp":1.65,"tv":4.0,"id":31372}]}]}
{"op":"mcm","clk":"11824635953","pt":1723468251576,"mc":[{"id":"1.231699634","rc":[{"batb":[[0,1.66,10],[1,1.65,62.5],[2,1.25,100]],"ltp":1.65,"tv":4.0,"id":31372}]}]}
{"op":"mcm","clk":"11824636208","pt":1723468254991,"mc":[{"id":"1.231699634","rc":[{"batb":[[0,1.65,62.5],[1,1.25,100],[2,1.08,7.83]],"ltp":1.65,"tv":4.0,"id":31372}]}]}
{"op":"mcm","clk":"11824636575","pt":1723468259891,"mc":[{"id":"1.231699634","rc":[{"batb":[[0,1.66,10],[1,1.65,62.5],[2,1.25,100]],"ltp":1.65,"tv":4.0,"id":31372}]}]}
{"op":"mcm","clk":"11824636817","pt":1723468263092,"mc":[{"id":"1.231699634","rc":[{"batb":[[0,1.65,62.5],[1,1.25,100],[2,1.08,7.83]],"ltp":1.65,"tv":4.0,"id":31372}]}]}
{"op":"mcm","clk":"11824637045","pt":1723468265819,"mc":[{"id":"1.231699634","rc":[{"batb":[[0,1.66,10],[1,1.65,62.5],[2,1.25,100]],"ltp":1.65,"tv":4.0,"id":31372}]}]}
{"op":"mcm","clk":"11824637281","pt":1723468269325,"mc":[{"id":"1.231699634","rc":[{"batb":[[0,1.65,62.5],[1,1.25,100],[2,1.08,7.83]],"ltp":1.65,"tv":4.0,"id":31372}]}]}
{"op":"mcm","clk":"11824637494","pt":1723468272510,"mc":[{"id":"1.231699634","rc":[{"batb":[[0,1.66,10],[1,1.65,62.5],[2,1.25,100]],"ltp":1.65,"tv":4.0,"id":31372}]}]}
{"op":"mcm","clk":"11824637711","pt":1723468275862,"mc":[{"id":"1.231699634","rc":[{"batb":[[0,1.65,62.5],[1,1.25,100],[2,1.08,7.83]],"ltp":1.65,"tv":4.0,"id":31372}]}]}
{"op":"mcm","clk":"11824637982","pt":1723468279922,"mc":[{"id":"1.231699634","rc":[{"batb":[[0,1.66,10],[1,1.65,62.5],[2,1.25,100]],"ltp":1.65,"tv":4.0,"id":31372}]}]}
{"op":"mcm","clk":"11824638192","pt":1723468283111,"mc":[{"id":"1.231699634","rc":[{"batb":[[0,1.65,62.5],[1,1.25,100],[2,1.08,7.83]],"ltp":1.65,"tv":4.0,"id":31372}]}]}
{"op":"mcm","clk":"11824638491","pt":1723468287637,"mc":[{"id":"1.231699634","rc":[{"batb":[[0,1.66,10],[1,1.65,62.5],[2,1.25,100]],"ltp":1.65,"tv":4.0,"id":31372}]}]}
{"op":"mcm","clk":"11824638695","pt":1723468290918,"mc":[{"id":"1.231699634","rc":[{"batb":[[0,1.65,62.5],[1,1.25,100],[2,1.08,7.83]],"ltp":1.65,"tv":4.0,"id":31372}]}]}
{"op":"mcm","clk":"11824638884","pt":1723468293616,"mc":[{"id":"1.231699634","rc":[{"batb":[[0,1.66,10],[1,1.65,62.5],[2,1.25,100]],"ltp":1.65,"tv":4.0,"id":31372}]}]}
{"op":"mcm","clk":"11824639113","pt":1723468297156,"mc":[{"id":"1.231699634","rc":[{"batb":[[0,1.65,62.5],[1,1.25,100],[2,1.08,7.83]],"ltp":1.65,"tv":4.0,"id":31372}]}]}
{"op":"mcm","clk":"11824639398","pt":1723468301688,"mc":[{"id":"1.231699634","rc":[{"batb":[[0,1.66,10],[1,1.65,62.5],[2,1.25,100]],"ltp":1.65,"tv":4.0,"id":31372}]}]}
{"op":"mcm","clk":"11824639573","pt":1723468305167,"mc":[{"id":"1.231699634","rc":[{"batb":[[0,1.65,62.5],[1,1.25,100],[2,1.08,7.83]],"ltp":1.65,"tv":4.0,"id":31372}]}]}
{"op":"mcm","clk":"11824639882","pt":1723468309840,"mc":[{"id":"1.231699634","rc":[{"batb":[[0,1.66,10],[1,1.65,62.5],[2,1.25,100]],"ltp":1.65,"tv":4.0,"id":31372}]}]}
{"op":"mcm","clk":"11824640106","pt":1723468313361,"mc":[{"id":"1.231699634","rc":[{"batb":[[0,1.65,62.5],[1,1.25,100],[2,1.08,7.83]],"ltp":1.65,"tv":4.0,"id":31372}]}]}
{"op":"mcm","clk":"11824640278","pt":1723468316028,"mc":[{"id":"1.231699634","rc":[{"batb":[[0,1.66,10],[1,1.65,62.5],[2,1.25,100]],"ltp":1.65,"tv":4.0,"id":31372}]}]}
{"op":"mcm","clk":"11824640441","pt":1723468319367,"mc":[{"id":"1.231699634","rc":[{"batb":[[0,1.65,62.5],[1,1.25,100],[2,1.08,7.83]],"ltp":1.65,"tv":4.0,"id":31372}]}]}
{"op":"mcm","clk":"11824640701","pt":1723468324148,"mc":[{"id":"1.231699634","rc":[{"batb":[[0,1.66,10],[1,1.65,62.5],[2,1.25,100]],"ltp":1.65,"tv":4.0,"id":31372}]}]}
{"op":"mcm","clk":"11824640953","pt":1723468328585,"mc":[{"id":"1.231699634","rc":[{"batb":[[0,1.65,62.5],[1,1.25,100],[2,1.08,7.83]],"ltp":1.65,"tv":4.0,"id":31372}]}]}
{"op":"mcm","clk":"11824641262","pt":1723468334298,"mc":[{"id":"1.231699634","rc":[{"batb":[[0,1.66,10],[1,1.65,62.5],[2,1.25,100]],"ltp":1.65,"tv":4.0,"id":31372}]}]}
{"op":"mcm","clk":"11824641414","pt":1723468337592,"mc":[{"id":"1.231699634","rc":[{"batb":[[0,1.65,62.5],[1,1.25,100],[2,1.08,7.83]],"ltp":1.65,"tv":4.0,"id":31372}]}]}
{"op":"mcm","clk":"11824641596","pt":1723468340785,"mc":[{"id":"1.231699634","rc":[{"batb":[[0,1.66,10],[1,1.65,62.5],[2,1.25,100]],"ltp":1.65,"tv":4.0,"id":31372}]}]}
{"op":"mcm","clk":"11824641781","pt":1723468344174,"mc":[{"id":"1.231699634","rc":[{"batb":[[0,1.65,62.5],[1,1.25,100],[2,1.08,7.83]],"ltp":1.65,"tv":4.0,"id":31372}]}]}
{"op":"mcm","clk":"11824641949","pt":1723468347407,"mc":[{"id":"1.231699634","rc":[{"batb":[[0,1.66,10],[1,1.65,62.5],[2,1.25,100]],"ltp":1.65,"tv":4.0,"id":31372}]}]}
{"op":"mcm","clk":"11824642140","pt":1723468350607,"mc":[{"id":"1.231699634","rc":[{"batb":[[0,1.65,62.5],[1,1.25,100],[2,1.08,7.83]],"ltp":1.65,"tv":4.0,"id":31372}]}]}
{"op":"mcm","clk":"11824642281","pt":1723468353112,"mc":[{"id":"1.231699634","rc":[{"batb":[[0,1.66,10],[1,1.65,62.5],[2,1.25,100]],"ltp":1.65,"tv":4.0,"id":31372}]}]}
{"op":"mcm","clk":"11824642451","pt":1723468356407,"mc":[{"id":"1.231699634","rc":[{"batb":[[0,1.65,62.5],[1,1.25,100],[2,1.08,7.83]],"ltp":1.65,"tv":4.0,"id":31372}]}]}
{"op":"mcm","clk":"11824642864","pt":1723468363502,"mc":[{"id":"1.231699634","rc":[{"batb":[[0,1.66,10],[1,1.65,62.5],[2,1.25,100]],"ltp":1.65,"tv":4.0,"id":31372}]}]}
{"op":"mcm","clk":"11824643070","pt":1723468366792,"mc":[{"id":"1.231699634","rc":[{"batb":[[0,1.65,62.5],[1,1.25,100],[2,1.08,7.83]],"ltp":1.65,"tv":4.0,"id":31372}]}]}
{"op":"mcm","clk":"11824643193","pt":1723468369204,"mc":[{"id":"1.231699634","rc":[{"batb":[[0,1.66,10],[1,1.65,62.5],[2,1.25,100]],"ltp":1.65,"tv":4.0,"id":31372}]}]}
{"op":"mcm","clk":"11824643368","pt":1723468372428,"mc":[{"id":"1.231699634","rc":[{"batb":[[0,1.65,62.5],[1,1.25,100],[2,1.08,7.83]],"ltp":1.65,"tv":4.0,"id":31372}]}]}
{"op":"mcm","clk":"11824652040","pt":1723468380131,"mc":[{"id":"1.231699634","rc":[{"batb":[[0,1.66,10],[1,1.65,62.5],[2,1.25,100]],"ltp":1.65,"tv":4.0,"id":31372}]}]}
{"op":"mcm","clk":"11824652263","pt":1723468383630,"mc":[{"id":"1.231699634","rc":[{"batb":[[0,1.65,62.5],[1,1.25,100],[2,1.08,7.83]],"ltp":1.65,"tv":4.0,"id":31372}]}]}
{"op":"mcm","clk":"11824652696","pt":1723468389453,"mc":[{"id":"1.231699634","rc":[{"batb":[[0,1.66,10],[1,1.65,62.5],[2,1.25,100]],"ltp":1.65,"tv":4.0,"id":31372}]}]}
{"op":"mcm","clk":"11824653017","pt":1723468394129,"mc":[{"id":"1.231699634","rc":[{"batb":[[0,1.65,62.5],[1,1.25,100],[2,1.08,7.83]],"ltp":1.65,"tv":4.0,"id":31372}]}]}
{"op":"mcm","clk":"11824653182","pt":1723468396349,"mc":[{"id":"1.231699634","rc":[{"batb":[[0,1.66,10],[1,1.65,62.5],[2,1.25,100]],"ltp":1.65,"tv":4.0,"id":31372}]}]}
{"op":"mcm","clk":"11824653391","pt":1723468399840,"mc":[{"id":"1.231699634","rc":[{"batb":[[0,1.65,62.5],[1,1.25,100],[2,1.08,7.83]],"ltp":1.65,"tv":4.0,"id":31372}]}]}
{"op":"mcm","clk":"11824653911","pt":1723468407845,"mc":[{"id":"1.231699634","rc":[{"batb":[[0,1.66,10],[1,1.65,62.5],[2,1.25,100]],"ltp":1.65,"tv":4.0,"id":31372}]}]}
{"op":"mcm","clk":"11824654283","pt":1723468411189,"mc":[{"id":"1.231699634","rc":[{"batb":[[0,1.65,62.5],[1,1.25,100],[2,1.08,7.83]],"ltp":1.65,"tv":4.0,"id":31372}]}]}
{"op":"mcm","clk":"11824655103","pt":1723468421495,"mc":[{"id":"1.231699634","rc":[{"batb":[[0,1.66,10],[1,1.65,62.5],[2,1.25,100]],"ltp":1.65,"tv":4.0,"id":31372}]}]}
{"op":"mcm","clk":"11824655371","pt":1723468425103,"mc":[{"id":"1.231699634","rc":[{"batb":[[0,1.65,62.5],[1,1.25,100],[2,1.08,7.83]],"ltp":1.65,"tv":4.0,"id":31372}]}]}
{"op":"mcm","clk":"11824655532","pt":1723468427930,"mc":[{"id":"1.231699634","rc":[{"batb":[[0,1.66,10],[1,1.65,62.5],[2,1.25,100]],"ltp":1.65,"tv":4.0,"id":31372}]}]}
{"op":"mcm","clk":"11824655716","pt":1723468431224,"mc":[{"id":"1.231699634","rc":[{"batb":[[0,1.65,62.5],[1,1.25,100],[2,1.08,7.83]],"ltp":1.65,"tv":4.0,"id":31372}]}]}
{"op":"mcm","clk":"11824655951","pt":1723468434494,"mc":[{"id":"1.231699634","rc":[{"batb":[[0,1.66,10],[1,1.65,62.5],[2,1.25,100]],"ltp":1.65,"tv":4.0,"id":31372}]}]}
{"op":"mcm","clk":"11824656151","pt":1723468437839,"mc":[{"id":"1.231699634","rc":[{"batb":[[0,1.65,62.5],[1,1.25,100],[2,1.08,7.83]],"ltp":1.65,"tv":4.0,"id":31372}]}]}
{"op":"mcm","clk":"11824656343","pt":1723468440102,"mc":[{"id":"1.231699634","rc":[{"batb":[[0,1.66,10],[1,1.65,62.5],[2,1.25,100]],"ltp":1.65,"tv":4.0,"id":31372}]}]}
{"op":"mcm","clk":"11824656575","pt":1723468443548,"mc":[{"id":"1.231699634","rc":[{"batb":[[0,1.65,62.5],[1,1.25,100],[2,1.08,7.83]],"ltp":1.65,"tv":4.0,"id":31372}]}]}
{"op":"mcm","clk":"11824656753","pt":1723468445913,"mc":[{"id":"1.231699634","rc":[{"batb":[[0,1.66,10],[1,1.65,62.5],[2,1.25,100]],"ltp":1.65,"tv":4.0,"id":31372}]}]}
{"op":"mcm","clk":"11824657078","pt":1723468450432,"mc":[{"id":"1.231699634","rc":[{"batb":[[0,1.65,62.5],[1,1.25,100],[2,1.08,7.83]],"ltp":1.65,"tv":4.0,"id":31372}]}]}
{"op":"mcm","clk":"11824657346","pt":1723468454029,"mc":[{"id":"1.231699634","rc":[{"batb":[[0,1.66,10],[1,1.65,62.5],[2,1.25,100]],"ltp":1.65,"tv":4.0,"id":31372}]}]}
{"op":"mcm","clk":"11824657583","pt":1723468457420,"mc":[{"id":"1.231699634","rc":[{"batb":[[0,1.65,62.5],[1,1.25,100],[2,1.08,7.83]],"ltp":1.65,"tv":4.0,"id":31372}]}]}
{"op":"mcm","clk":"11824657948","pt":1723468462757,"mc":[{"id":"1.231699634","rc":[{"batb":[[0,1.66,10],[1,1.65,62.5],[2,1.25,100]],"ltp":1.65,"tv":4.0,"id":31372}]}]}
{"op":"mcm","clk":"11824658178","pt":1723468466345,"mc":[{"id":"1.231699634","rc":[{"batb":[[0,1.65,62.5],[1,1.25,100],[2,1.08,7.83]],"ltp":1.65,"tv":4.0,"id":31372}]}]}
{"op":"mcm","clk":"11824658458","pt":1723468470454,"mc":[{"id":"1.231699634","rc":[{"batb":[[0,1.66,10],[1,1.65,62.5],[2,1.25,100]],"ltp":1.65,"tv":4.0,"id":31372}]}]}
{"op":"mcm","clk":"11824658704","pt":1723468473741,"mc":[{"id":"1.231699634","rc":[{"batb":[[0,1.65,62.5],[1,1.25,100],[2,1.08,7.83]],"ltp":1.65,"tv":4.0,"id":31372}]}]}
{"op":"mcm","clk":"11824658880","pt":1723468476670,"mc":[{"id":"1.231699634","rc":[{"batb":[[0,1.66,10],[1,1.65,62.5],[2,1.25,100]],"ltp":1.65,"tv":4.0,"id":31372}]}]}
{"op":"mcm","clk":"11824659137","pt":1723468481434,"mc":[{"id":"1.231699634","rc":[{"batb":[[0,1.65,62.5],[1,1.25,100],[2,1.08,7.83]],"ltp":1.65,"tv":4.0,"id":31372}]}]}
{"op":"mcm","clk":"11824659496","pt":1723468487079,"mc":[{"id":"1.231699634","rc":[{"batb":[[0,1.66,10],[1,1.65,62.5],[2,1.25,100]],"ltp":1.65,"tv":4.0,"id":31372}]}]}
{"op":"mcm","clk":"11824659700","pt":1723468490384,"mc":[{"id":"1.231699634","rc":[{"batb":[[0,1.65,62.5],[1,1.25,100],[2,1.08,7.83]],"ltp":1.65,"tv":4.0,"id":31372}]}]}
{"op":"mcm","clk":"11824659831","pt":1723468492895,"mc":[{"id":"1.231699634","rc":[{"batb":[[0,1.66,10],[1,1.65,62.5],[2,1.25,100]],"ltp":1.65,"tv":4.0,"id":31372}]}]}
{"op":"mcm","clk":"11824660010","pt":1723468496179,"mc":[{"id":"1.231699634","rc":[{"batb":[[0,1.65,62.5],[1,1.25,100],[2,1.08,7.83]],"ltp":1.65,"tv":4.0,"id":31372}]}]}
{"op":"mcm","clk":"11824660176","pt":1723468499570,"mc":[{"id":"1.231699634","rc":[{"batb":[[0,1.66,10],[1,1.65,62.5],[2,1.25,100]],"ltp":1.65,"tv":4.0,"id":31372}]}]}
{"op":"mcm","clk":"11824660430","pt":1723468502989,"mc":[{"id":"1.231699634","rc":[{"batb":[[0,1.65,62.5],[1,1.25,100],[2,1.08,7.83]],"ltp":1.65,"tv":4.0,"id":31372}]}]}
{"op":"mcm","clk":"11824660627","pt":1723468505735,"mc":[{"id":"1.231699634","rc":[{"batb":[[0,1.66,10],[1,1.65,62.5],[2,1.25,100]],"ltp":1.65,"tv":4.0,"id":31372}]}]}
{"op":"mcm","clk":"11824660903","pt":1723468510091,"mc":[{"id":"1.231699634","rc":[{"batb":[[0,1.65,62.5],[1,1.25,100],[2,1.08,7.83]],"ltp":1.65,"tv":4.0,"id":31372}]}]}
{"op":"mcm","clk":"11824661092","pt":1723468512519,"mc":[{"id":"1.231699634","rc":[{"batb":[[0,1.66,10],[1,1.65,62.5],[2,1.25,100]],"ltp":1.65,"tv":4.0,"id":31372}]}]}
{"op":"mcm","clk":"11824661284","pt":1723468515707,"mc":[{"id":"1.231699634","rc":[{"batb":[[0,1.65,62.5],[1,1.25,100],[2,1.08,7.83]],"ltp":1.65,"tv":4.0,"id":31372}]}]}
{"op":"mcm","clk":"11824661524","pt":1723468519818,"mc":[{"id":"1.231699634","rc":[{"batb":[[0,1.66,10],[1,1.65,62.5],[2,1.25,100]],"ltp":1.65,"tv":4.0,"id":31372}]}]}
{"op":"mcm","clk":"11824661753","pt":1723468523222,"mc":[{"id":"1.231699634","rc":[{"batb":[[0,1.65,62.5],[1,1.25,100],[2,1.08,7.83]],"ltp":1.65,"tv":4.0,"id":31372}]}]}
{"op":"mcm","clk":"11824661942","pt":1723468525501,"mc":[{"id":"1.231699634","rc":[{"batb":[[0,1.66,10],[1,1.65,62.5],[2,1.25,100]],"ltp":1.65,"tv":4.0,"id":31372}]}]}
{"op":"mcm","clk":"11824662554","pt":1723468533317,"mc":[{"id":"1.231699634","rc":[{"batb":[[0,1.65,62.5],[1,1.25,100],[2,1.08,7.83]],"ltp":1.65,"tv":4.0,"id":31372}]}]}
{"op":"mcm","clk":"11824662846","pt":1723468537047,"mc":[{"id":"1.231699634","rc":[{"batb":[[0,1.66,10],[1,1.65,62.5],[2,1.25,100]],"ltp":1.65,"tv":4.0,"id":31372}]}]}
{"op":"mcm","clk":"11824663206","pt":1723468542536,"mc":[{"id":"1.231699634","rc":[{"batb":[[0,1.65,62.5],[1,1.25,100],[2,1.08,7.83]],"ltp":1.65,"tv":4.0,"id":31372}]}]}
{"op":"mcm","clk":"11824663633","pt":1723468549258,"mc":[{"id":"1.231699634","rc":[{"batb":[[0,1.66,10],[1,1.65,62.5],[2,1.25,100]],"ltp":1.65,"tv":4.0,"id":31372}]}]}
{"op":"mcm","clk":"11824663843","pt":1723468552834,"mc":[{"id":"1.231699634","rc":[{"batb":[[0,1.65,62.5],[1,1.25,100],[2,1.08,7.83]],"ltp":1.65,"tv":4.0,"id":31372}]}]}
{"op":"mcm","clk":"11824665033","pt":1723468570874,"mc":[{"id":"1.231699634","rc":[{"batb":[[0,1.66,10],[1,1.65,62.5],[2,1.25,100]],"ltp":1.65,"tv":4.0,"id":31372}]}]}
{"op":"mcm","clk":"11824665259","pt":1723468574369,"mc":[{"id":"1.231699634","rc":[{"batb":[[0,1.65,62.5],[1,1.25,100],[2,1.08,7.83]],"ltp":1.65,"tv":4.0,"id":31372}]}]}
{"op":"mcm","clk":"11824665470","pt":1723468577579,"mc":[{"id":"1.231699634","rc":[{"batb":[[0,1.66,10],[1,1.65,62.5],[2,1.25,100]],"ltp":1.65,"tv":4.0,"id":31372}]}]}
{"op":"mcm","clk":"11824665690","pt":1723468581007,"mc":[{"id":"1.231699634","rc":[{"batb":[[0,1.65,62.5],[1,1.25,100],[2,1.08,7.83]],"ltp":1.65,"tv":4.0,"id":31372}]}]}
{"op":"mcm","clk":"11824665813","pt":1723468583286,"mc":[{"id":"1.231699634","rc":[{"batb":[[0,1.66,10],[1,1.65,62.5],[2,1.25,100]],"ltp":1.65,"tv":4.0,"id":31372}]}]}
{"op":"mcm","clk":"11824665977","pt":1723468586582,"mc":[{"id":"1.231699634","rc":[{"batb":[[0,1.65,62.5],[1,1.25,100],[2,1.08,7.83]],"ltp":1.65,"tv":4.0,"id":31372}]}]}
{"op":"mcm","clk":"11824666205","pt":1723468590796,"mc":[{"id":"1.231699634","rc":[{"batb":[[0,1.66,10],[1,1.65,62.5],[2,1.25,100]],"ltp":1.65,"tv":4.0,"id":31372}]}]}
{"op":"mcm","clk":"11824666416","pt":1723468594405,"mc":[{"id":"1.231699634","rc":[{"batb":[[0,1.65,62.5],[1,1.25,100],[2,1.08,7.83]],"ltp":1.65,"tv":4.0,"id":31372}]}]}
{"op":"mcm","clk":"11824666668","pt":1723468598419,"mc":[{"id":"1.231699634","rc":[{"batb":[[0,1.66,10],[1,1.65,62.5],[2,1.25,100]],"ltp":1.65,"tv":4.0,"id":31372}]}]}
{"op":"mcm","clk":"11824666897","pt":1723468601814,"mc":[{"id":"1.231699634","rc":[{"batb":[[0,1.65,62.5],[1,1.25,100],[2,1.08,7.83]],"ltp":1.65,"tv":4.0,"id":31372}]}]}
{"op":"mcm","clk":"11824667080","pt":1723468604097,"mc":[{"id":"1.231699634","rc":[{"batb":[[0,1.66,10],[1,1.65,62.5],[2,1.25,100]],"ltp":1.65,"tv":4.0,"id":31372}]}]}
{"op":"mcm","clk":"11824667402","pt":1723468607683,"mc":[{"id":"1.231699634","rc":[{"batb":[[0,1.65,62.5],[1,1.25,100],[2,1.08,7.83]],"ltp":1.65,"tv":4.0,"id":31372}]}]}
{"op":"mcm","clk":"11824667624","pt":1723468610815,"mc":[{"id":"1.231699634","rc":[{"batb":[[0,1.66,10],[1,1.65,62.5],[2,1.25,100]],"ltp":1.65,"tv":4.0,"id":31372}]}]}
{"op":"mcm","clk":"11824668013","pt":1723468616438,"mc":[{"id":"1.231699634","rc":[{"batb":[[0,1.65,62.5],[1,1.25,100],[2,1.08,7.83]],"ltp":1.65,"tv":4.0,"id":31372}]}]}
{"op":"mcm","clk":"11824668662","pt":1723468626656,"mc":[{"id":"1.231699634","rc":[{"batb":[[0,1.66,10],[1,1.65,62.5],[2,1.25,100]],"ltp":1.65,"tv":4.0,"id":31372}]}]}
{"op":"mcm","clk":"11824668856","pt":1723468630147,"mc":[{"id":"1.231699634","rc":[{"batb":[[0,1.65,62.5],[1,1.25,100],[2,1.08,7.83]],"ltp":1.65,"tv":4.0,"id":31372}]}]}
{"op":"mcm","clk":"11824669315","pt":1723468636930,"mc":[{"id":"1.231699634","rc":[{"batb":[[0,1.66,10],[1,1.65,62.5],[2,1.25,100]],"ltp":1.65,"tv":4.0,"id":31372}]}]}
{"op":"mcm","clk":"11824669502","pt":1723468640265,"mc":[{"id":"1.231699634","rc":[{"batb":[[0,1.65,62.5],[1,1.25,100],[2,1.08,7.83]],"ltp":1.65,"tv":4.0,"id":31372}]}]}
{"op":"mcm","clk":"11824669564","pt":1723468641147,"mc":[{"id":"1.231699634","rc":[{"batl":[[0,2.32,81.56]],"ltp":1.65,"tv":4.0,"id":31372}]}]}
{"op":"mcm","clk":"11824669804","pt":1723468645480,"mc":[{"id":"1.231699634","rc":[{"batb":[[0,1.66,10],[1,1.65,62.5],[2,1.25,100]],"ltp":1.65,"tv":4.0,"id":31372}]}]}
{"op":"mcm","clk":"11824670023","pt":1723468649069,"mc":[{"id":"1.231699634","rc":[{"batb":[[0,1.65,62.5],[1,1.25,100],[2,1.08,7.83]],"ltp":1.65,"tv":4.0,"id":31372}]}]}
{"op":"mcm","clk":"11824670137","pt":1723468651182,"mc":[{"id":"1.231699634","rc":[{"batl":[[0,2.4,0.96]],"ltp":2.34,"tv":141.84,"id":424679}]}]}
{"op":"mcm","clk":"11824670152","pt":1723468651389,"mc":[{"id":"1.231699634","rc":[{"batb":[[0,1.77,10],[1,1.76,5.24],[2,1.25,100]],"ltp":2.34,"tv":141.84,"id":424679},{"batb":[[0,1.66,10],[1,1.65,62.5],[2,1.25,100]],"ltp":1.65,"tv":4.0,"id":31372}]}]}
{"op":"mcm","clk":"11824670299","pt":1723468653654,"mc":[{"id":"1.231699634","rc":[{"batb":[[1,1.25,100],[2,1.08,7.83]],"ltp":2.34,"tv":141.84,"id":424679}]}]}
{"op":"mcm","clk":"11824670373","pt":1723468654777,"mc":[{"id":"1.231699634","rc":[{"batb":[[0,1.25,100],[1,1.08,7.83],[2,1.07,7.83]],"ltp":2.34,"tv":141.84,"id":424679},{"batb":[[0,1.65,62.5],[1,1.25,100],[2,1.08,7.83]],"ltp":1.65,"tv":4.0,"id":31372}]}]}
{"op":"mcm","clk":"11824670418","pt":1723468655549,"mc":[{"id":"1.231699634","rc":[{"batb":[[0,1.76,5.3],[1,1.25,100],[2,1.08,7.83]],"ltp":2.34,"tv":141.84,"id":424679}]}]}
{"op":"mcm","clk":"11824670952","pt":1723468664980,"mc":[{"id":"1.231699634","rc":[{"batb":[[0,1.77,10],[1,1.76,5.3],[2,1.25,100]],"ltp":2.34,"tv":141.84,"id":424679},{"batb":[[0,1.66,10],[1,1.65,62.5],[2,1.25,100]],"ltp":1.65,"tv":4.0,"id":31372}]}]}
{"op":"mcm","clk":"11824670995","pt":1723468665595,"mc":[{"id":"1.231699634","rc":[{"batb":[[1,1.25,100],[2,1.08,7.83]],"ltp":2.34,"tv":141.84,"id":424679}]}]}
{"op":"mcm","clk":"11824671233","pt":1723468668879,"mc":[{"id":"1.231699634","rc":[{"batb":[[0,1.25,100],[1,1.08,7.83],[2,1.07,7.83]],"ltp":2.34,"tv":141.84,"id":424679},{"batb":[[0,1.65,62.5],[1,1.25,100],[2,1.08,7.83]],"ltp":1.65,"tv":4.0,"id":31372}]}]}
{"op":"mcm","clk":"11824671669","pt":1723468675198,"mc":[{"id":"1.231699634","rc":[{"batl":[[0,2.52,4.05]],"ltp":2.34,"tv":141.84,"id":424679}]}]}
{"op":"mcm","clk":"11824671696","pt":1723468675505,"mc":[{"id":"1.231699634","rc":[{"batb":[[0,1.26,10],[1,1.25,100],[2,1.08,7.83]],"ltp":2.34,"tv":141.84,"id":424679},{"batb":[[0,1.66,10],[1,1.65,62.5],[2,1.25,100]],"ltp":1.65,"tv":4.0,"id":31372}]}]}
{"op":"mcm","clk":"11824671941","pt":1723468679103,"mc":[{"id":"1.231699634","rc":[{"batb":[[0,1.25,100],[1,1.08,7.83],[2,1.07,7.83]],"ltp":2.34,"tv":141.84,"id":424679},{"batb":[[0,1.65,62.5],[1,1.25,100],[2,1.08,7.83]],"ltp":1.65,"tv":4.0,"id":31372}]}]}
{"op":"mcm","clk":"11824672361","pt":1723468684664,"mc":[{"id":"1.231699634","rc":[{"batb":[[0,1.26,10],[1,1.25,100],[2,1.08,7.83]],"ltp":2.34,"tv":141.84,"id":424679},{"batb":[[0,1.66,10],[1,1.65,62.5],[2,1.25,100]],"ltp":1.65,"tv":4.0,"id":31372}]}]}
{"op":"mcm","clk":"11824672560","pt":1723468687587,"mc":[{"id":"1.231699634","rc":[{"batl":[[0,2.3,27.46],[1,2.32,80.6]],"ltp":1.65,"tv":4.0,"id":31372}]}]}
{"op":"mcm","clk":"11824672662","pt":1723468689078,"mc":[{"id":"1.231699634","rc":[{"batb":[[0,1.25,100],[1,1.08,7.83],[2,1.07,7.83]],"ltp":2.34,"tv":141.84,"id":424679},{"batb":[[0,1.67,47.49]],"ltp":1.65,"tv":4.0,"id":31372}]}]}
{"op":"mcm","clk":"11824672884","pt":1723468691874,"mc":[{"id":"1.231699634","rc":[{"batb":[[0,1.26,10],[1,1.25,100],[2,1.08,7.83]],"ltp":2.34,"tv":141.84,"id":424679},{"batb":[[0,1.68,10],[1,1.67,47.49],[2,1.65,62.5]],"ltp":1.65,"tv":4.0,"id":31372}]}]}
{"op":"mcm","clk":"11824673085","pt":1723468695227,"mc":[{"id":"1.231699634","rc":[{"batb":[[0,1.25,100],[1,1.08,7.83],[2,1.07,7.83]],"ltp":2.34,"tv":141.84,"id":424679},{"batb":[[0,1.67,47.49],[1,1.65,62.5],[2,1.25,100]],"ltp":1.65,"tv":4.0,"id":31372}]}]}
{"op":"mcm","clk":"11824673577","pt":1723468702211,"mc":[{"id":"1.231699634","rc":[{"batl":[[0,2.4,0.96]],"ltp":2.34,"tv":141.84,"id":424679}]}]}
{"op":"mcm","clk":"11824673621","pt":1723468702625,"mc":[{"id":"1.231699634","rc":[{"batb":[[0,1.26,10],[1,1.25,100],[2,1.08,7.83]],"batl":[[0,2.48,4.05]],"ltp":2.34,"tv":141.84,"id":424679},{"batb":[[0,1.68,10],[1,1.67,47.49],[2,1.65,62.5]],"ltp":1.65,"tv":4.0,"id":31372}]}]}
{"op":"mcm","clk":"11824673919","pt":1723468706890,"mc":[{"id":"1.231699634","rc":[{"batb":[[0,1.25,100],[1,1.08,7.83],[2,1.07,7.83]],"ltp":2.34,"tv":141.84,"id":424679},{"batb":[[0,1.67,47.49],[1,1.65,62.5],[2,1.25,100]],"ltp":1.65,"tv":4.0,"id":31372}]}]}
{"op":"mcm","clk":"11824674175","pt":1723468710389,"mc":[{"id":"1.231699634","rc":[{"batb":[[0,1.26,10],[1,1.25,100],[2,1.08,7.83]],"ltp":2.34,"tv":141.84,"id":424679},{"batb":[[0,1.68,10],[1,1.67,47.49],[2,1.65,62.5]],"ltp":1.65,"tv":4.0,"id":31372}]}]}
{"op":"mcm","clk":"11824674495","pt":1723468714293,"mc":[{"id":"1.231699634","rc":[{"batb":[[0,1.25,100],[1,1.08,7.83],[2,1.07,7.83]],"batl":[[0,2.46,33.2],[1,2.48,3.1]],"ltp":2.34,"tv":141.84,"id":424679},{"batb":[[0,1.65,62.5],[1,1.25,100],[2,1.08,7.83]],"ltp":1.65,"tv":4.0,"id":31372}]}]}
{"op":"mcm","clk":"11824675016","pt":1723468720827,"mc":[{"id":"1.231699634","rc":[{"batb":[[0,1.26,10],[1,1.25,100],[2,1.08,7.83]],"ltp":2.34,"tv":141.84,"id":424679},{"batb":[[0,1.66,10],[1,1.65,62.5],[2,1.25,100]],"ltp":1.65,"tv":4.0,"id":31372}]}]}
{"op":"mcm","clk":"11824675295","pt":1723468724120,"mc":[{"id":"1.231699634","rc":[{"batb":[[0,1.25,100],[1,1.08,7.83],[2,1.07,7.83]],"ltp":2.34,"tv":141.84,"id":424679},{"batb":[[0,1.65,62.5],[1,1.25,100],[2,1.08,7.83]],"ltp":1.65,"tv":4.0,"id":31372}]}]}
{"op":"mcm","clk":"11824675561","pt":1723468728229,"mc":[{"id":"1.231699634","rc":[{"batb":[[0,1.26,10],[1,1.25,100],[2,1.08,7.83]],"ltp":2.34,"tv":141.84,"id":424679},{"batb":[[0,1.66,10],[1,1.65,62.5],[2,1.25,100]],"ltp":1.65,"tv":4.0,"id":31372}]}]}
{"op":"mcm","clk":"11824675797","pt":1723468731930,"mc":[{"id":"1.231699634","rc":[{"batb":[[0,1.25,100],[1,1.08,7.83],[2,1.07,7.83]],"ltp":2.34,"tv":141.84,"id":424679},{"batb":[[0,1.65,62.5],[1,1.25,100],[2,1.08,7.83]],"ltp":1.65,"tv":4.0,"id":31372}]}]}
{"op":"mcm","clk":"11824676081","pt":1723468736348,"mc":[{"id":"1.231699634","rc":[{"batb":[[0,1.26,10],[1,1.25,100],[2,1.08,7.83]],"ltp":2.34,"tv":141.84,"id":424679},{"batb":[[0,1.66,10],[1,1.65,62.5],[2,1.25,100]],"ltp":1.65,"tv":4.0,"id":31372}]}]}
{"op":"mcm","clk":"11824676344","pt":1723468739845,"mc":[{"id":"1.231699634","rc":[{"batb":[[0,1.25,100],[1,1.08,7.83],[2,1.07,7.83]],"ltp":2.34,"tv":141.84,"id":424679},{"batb":[[0,1.65,62.5],[1,1.25,100],[2,1.08,7.83]],"ltp":1.65,"tv":4.0,"id":31372}]}]}
{"op":"mcm","clk":"11824676523","pt":1723468742057,"mc":[{"id":"1.231699634","rc":[{"batb":[[0,1.26,10],[1,1.25,100],[2,1.08,7.83]],"ltp":2.34,"tv":141.84,"id":424679},{"batb":[[0,1.66,10],[1,1.65,62.5],[2,1.25,100]],"ltp":1.65,"tv":4.0,"id":31372}]}]}
{"op":"mcm","clk":"11824676849","pt":1723468746165,"mc":[{"id":"1.231699634","rc":[{"batb":[[0,1.25,100],[1,1.08,7.83],[2,1.07,7.83]],"ltp":2.34,"tv":141.84,"id":424679},{"batb":[[0,1.65,62.5],[1,1.25,100],[2,1.08,7.83]],"ltp":1.65,"tv":4.0,"id":31372}]}]}
{"op":"mcm","clk":"11824677258","pt":1723468752171,"mc":[{"id":"1.231699634","rc":[{"batb":[[0,1.26,10],[1,1.25,100],[2,1.08,7.83]],"batl":[[1,2.48,0]],"ltp":2.34,"tv":141.84,"id":424679},{"batb":[[0,1.66,10],[1,1.65,62.5],[2,1.25,100]],"ltp":1.65,"tv":4.0,"id":31372}]}]}
{"op":"mcm","clk":"11824677509","pt":1723468755263,"mc":[{"id":"1.231699634","rc":[{"batb":[[0,1.78,6.03]],"ltp":2.34,"tv":141.84,"id":424679},{"batb":[[0,1.69,7.78]],"ltp":1.65,"tv":4.0,"id":31372}]}]}
{"op":"mcm","clk":"11824677865","pt":1723468759373,"mc":[{"id":"1.231699634","rc":[{"batb":[[0,1.79,10],[1,1.78,6.03],[2,1.25,100]],"ltp":2.34,"tv":141.84,"id":424679},{"batb":[[0,1.7,10],[1,1.69,7.78],[2,1.65,62.5]],"ltp":1.65,"tv":4.0,"id":31372}]}]}
{"op":"mcm","clk":"11824678290","pt":1723468764259,"mc":[{"id":"1.231699634","rc":[{"batb":[[0,1.78,6.03],[1,1.25,100],[2,1.08,7.83]],"ltp":2.34,"tv":141.84,"id":424679}]}]}
{"op":"mcm","clk":"11824678300","pt":1723468764360,"mc":[{"id":"1.231699634","rc":[{"batb":[[0,1.69,7.78],[1,1.65,62.5],[2,1.25,100]],"ltp":1.65,"tv":4.0,"id":31372}]}]}
{"op":"mcm","clk":"11824678635","pt":1723468769147,"mc":[{"id":"1.231699634","rc":[{"batb":[[0,1.79,10],[1,1.78,6.03],[2,1.25,100]],"ltp":2.34,"tv":141.84,"id":424679},{"batb":[[0,1.7,10],[1,1.69,7.78],[2,1.65,62.5]],"ltp":1.65,"tv":4.0,"id":31372}]}]}
{"op":"mcm","clk":"11824678665","pt":1723468769456,"mc":[{"id":"1.231699634","rc":[{"batb":[[0,1.8,33.87],[1,1.79,10],[2,1.78,6.03]],"batl":[[0,2.4,0.96]],"ltp":2.34,"tv":141.84,"id":424679},{"batb":[[0,1.71,46.38],[1,1.7,10],[2,1.69,7.78]],"batl":[[0,2.32,81.56],[1,2.32,0]],"ltp":1.65,"tv":4.0,"id":31372}]}]}
{"op":"mcm","clk":"11824678894","pt":1723468772690,"mc":[{"id":"1.231699634","rc":[{"batb":[[1,1.78,6.03],[2,1.25,100]],"ltp":2.34,"tv":141.84,"id":424679},{"batb":[[1,1.69,7.78],[2,1.65,62.5]],"ltp":1.65,"tv":4.0,"id":31372}]}]}
{"op":"mcm","clk":"11824679105","pt":1723468775464,"mc":[{"id":"1.231699634","rc":[{"batb":[[0,1.81,10],[1,1.8,33.87],[2,1.78,6.03]],"ltp":2.34,"tv":141.84,"id":424679},{"batb":[[0,1.72,10],[1,1.71,46.38],[2,1.69,7.78]],"ltp":1.65,"tv":4.0,"id":31372}]}]}
{"op":"mcm","clk":"11824679372","pt":1723468778861,"mc":[{"id":"1.231699634","rc":[{"batb":[[0,1.8,33.87],[1,1.78,6.03],[2,1.25,100]],"ltp":2.34,"tv":141.84,"id":424679},{"batb":[[0,1.71,46.38],[1,1.69,7.78],[2,1.65,62.5]],"ltp":1.65,"tv":4.0,"id":31372}]}]}
{"op":"mcm","clk":"11824680277","pt":1723468789807,"mc":[{"id":"1.231699634","rc":[{"batb":[[0,1.81,10],[1,1.8,33.87],[2,1.78,6.03]],"ltp":2.34,"tv":141.84,"id":424679},{"batb":[[0,1.73,45.84],[1,1.72,10],[2,1.69,7.78]],"ltp":1.65,"tv":4.0,"id":31372}]}]}
{"op":"mcm","clk":"11824680624","pt":1723468794282,"mc":[{"id":"1.231699634","rc":[{"batb":[[0,1.8,33.87],[1,1.78,6.03],[2,1.25,100]],"ltp":2.34,"tv":141.84,"id":424679},{"batb":[[1,1.69,7.78],[2,1.65,62.5]],"ltp":1.65,"tv":4.0,"id":31372}]}]}
{"op":"mcm","clk":"11824681303","pt":1723468804106,"mc":[{"id":"1.231699634","rc":[{"batb":[[0,1.81,10],[1,1.8,33.87],[2,1.78,6.03]],"ltp":2.34,"tv":141.84,"id":424679},{"batb":[[0,1.74,10],[1,1.73,45.84],[2,1.69,7.78]],"ltp":1.65,"tv":4.0,"id":31372}]}]}
{"op":"mcm","clk":"11824681574","pt":1723468807305,"mc":[{"id":"1.231699634","rc":[{"batb":[[0,1.8,33.87],[1,1.78,6.03],[2,1.25,100]],"ltp":2.34,"tv":141.84,"id":424679},{"batb":[[0,1.73,45.84],[1,1.69,7.78],[2,1.65,62.5]],"ltp":1.65,"tv":4.0,"id":31372}]}]}
{"op":"mcm","clk":"11824682230","pt":1723468816113,"mc":[{"id":"1.231699634","rc":[{"batb":[[0,1.81,10],[1,1.8,33.87],[2,1.78,6.03]],"ltp":2.34,"tv":141.84,"id":424679},{"batb":[[0,1.74,10],[1,1.73,45.84],[2,1.69,7.78]],"ltp":1.65,"tv":4.0,"id":31372}]}]}
{"op":"mcm","clk":"11824682552","pt":1723468820442,"mc":[{"id":"1.231699634","rc":[{"batb":[[0,1.8,33.87],[1,1.78,6.03],[2,1.25,100]],"ltp":2.34,"tv":141.84,"id":424679},{"batb":[[0,1.73,45.84],[1,1.69,7.78],[2,1.65,62.5]],"ltp":1.65,"tv":4.0,"id":31372}]}]}
{"op":"mcm","clk":"11824682728","pt":1723468823109,"mc":[{"id":"1.231699634","rc":[{"batb":[[0,1.81,10],[1,1.8,33.87],[2,1.78,6.03]],"ltp":2.34,"tv":141.84,"id":424679},{"batb":[[0,1.74,10],[1,1.73,45.84],[2,1.69,7.78]],"ltp":1.65,"tv":4.0,"id":31372}]}]}
{"op":"mcm","clk":"11824682966","pt":1723468826759,"mc":[{"id":"1.231699634","rc":[{"batb":[[0,1.8,33.87],[1,1.78,6.03],[2,1.25,100]],"ltp":2.34,"tv":141.84,"id":424679},{"batb":[[0,1.73,45.84],[1,1.69,7.78],[2,1.65,62.5]],"ltp":1.65,"tv":4.0,"id":31372}]}]}
{"op":"mcm","clk":"11824684557","pt":1723468850163,"mc":[{"id":"1.231699634","rc":[{"batl":[[0,2.32,80.6]],"ltp":1.65,"tv":4.0,"id":31372}]}]}
{"op":"mcm","clk":"11824684571","pt":1723468850366,"mc":[{"id":"1.231699634","rc":[{"batb":[[0,1.81,10],[1,1.8,33.87],[2,1.78,6.03]],"ltp":2.34,"tv":141.84,"id":424679},{"batb":[[0,1.74,10],[1,1.73,45.84],[2,1.69,7.78]],"ltp":1.65,"tv":4.0,"id":31372}]}]}
{"op":"mcm","clk":"11824684804","pt":1723468853781,"mc":[{"id":"1.231699634","rc":[{"batb":[[0,1.8,33.87],[1,1.78,6.03],[2,1.25,100]],"ltp":2.34,"tv":141.84,"id":424679},{"batb":[[0,1.73,45.84],[1,1.69,7.78],[2,1.65,62.5]],"ltp":1.65,"tv":4.0,"id":31372}]}]}
{"op":"mcm","clk":"11824685108","pt":1723468858062,"mc":[{"id":"1.231699634","rc":[{"batb":[[0,1.74,10],[1,1.73,45.84],[2,1.69,7.78]],"ltp":1.65,"tv":4.0,"id":31372}]}]}
{"op":"mcm","clk":"11824685327","pt":1723468861375,"mc":[{"id":"1.231699634","rc":[{"batb":[[0,1.73,45.84],[1,1.69,7.78],[2,1.65,62.5]],"ltp":1.65,"tv":4.0,"id":31372}]}]}
{"op":"mcm","clk":"11824685796","pt":1723468868974,"mc":[{"id":"1.231699634","rc":[{"batb":[[0,1.74,10],[1,1.73,45.84],[2,1.69,7.78]],"ltp":1.65,"tv":4.0,"id":31372}]}]}
{"op":"mcm","clk":"11824686001","pt":1723468872468,"mc":[{"id":"1.231699634","rc":[{"batb":[[0,1.73,45.84],[1,1.69,7.78],[2,1.65,62.5]],"ltp":1.65,"tv":4.0,"id":31372}]}]}
{"op":"mcm","clk":"11824686499","pt":1723468880215,"mc":[{"id":"1.231699634","rc":[{"batb":[[0,1.74,10],[1,1.73,45.84],[2,1.69,7.78]],"ltp":1.65,"tv":4.0,"id":31372}]}]}
{"op":"mcm","clk":"11824686758","pt":1723468883915,"mc":[{"id":"1.231699634","rc":[{"batb":[[0,1.73,45.84],[1,1.69,7.78],[2,1.65,62.5]],"ltp":1.65,"tv":4.0,"id":31372}]}]}
{"op":"mcm","clk":"11824687961","pt":1723468900222,"mc":[{"id":"1.231699634","rc":[{"batb":[[0,1.74,10],[1,1.73,45.84],[2,1.69,7.78]],"ltp":1.65,"tv":4.0,"id":31372}]}]}
{"op":"mcm","clk":"11824688238","pt":1723468903623,"mc":[{"id":"1.231699634","rc":[{"batb":[[0,1.73,45.84],[1,1.69,7.78],[2,1.65,62.5]],"ltp":1.65,"tv":4.0,"id":31372}]}]}
{"op":"mcm","clk":"11824688619","pt":1723468909138,"mc":[{"id":"1.231699634","rc":[{"batb":[[0,1.74,10],[1,1.73,45.84],[2,1.69,7.78]],"ltp":1.65,"tv":4.0,"id":31372}]}]}
{"op":"mcm","clk":"11824688877","pt":1723468912644,"mc":[{"id":"1.231699634","rc":[{"batb":[[0,1.73,45.84],[1,1.69,7.78],[2,1.65,62.5]],"ltp":1.65,"tv":4.0,"id":31372}]}]}
{"op":"mcm","clk":"11824689349","pt":1723468918824,"mc":[{"id":"1.231699634","rc":[{"batb":[[0,1.74,10],[1,1.73,45.84],[2,1.69,7.78]],"ltp":1.65,"tv":4.0,"id":31372}]}]}
{"op":"mcm","clk":"11824689691","pt":1723468923667,"mc":[{"id":"1.231699634","rc":[{"batb":[[0,1.73,45.84],[1,1.69,7.78],[2,1.65,62.5]],"ltp":1.65,"tv":4.0,"id":31372}]}]}
{"op":"mcm","clk":"11824689871","pt":1723468926652,"mc":[{"id":"1.231699634","rc":[{"batb":[[0,1.74,10],[1,1.73,45.84],[2,1.69,7.78]],"ltp":1.65,"tv":4.0,"id":31372}]}]}
{"op":"mcm","clk":"11824690094","pt":1723468930353,"mc":[{"id":"1.231699634","rc":[{"batb":[[0,1.73,45.84],[1,1.69,7.78],[2,1.65,62.5]],"ltp":1.65,"tv":4.0,"id":31372}]}]}
{"op":"mcm","clk":"11824690497","pt":1723468936172,"mc":[{"id":"1.231699634","rc":[{"batb":[[0,1.74,10],[1,1.73,45.84],[2,1.69,7.78]],"ltp":1.65,"tv":4.0,"id":31372}]}]}
{"op":"mcm","clk":"11824690743","pt":1723468939462,"mc":[{"id":"1.231699634","rc":[{"batb":[[0,1.73,45.84],[1,1.69,7.78],[2,1.65,62.5]],"ltp":1.65,"tv":4.0,"id":31372}]}]}
{"op":"mcm","clk":"11824691582","pt":1723468952361,"mc":[{"id":"1.231699634","rc":[{"batb":[[0,1.74,10],[1,1.73,45.84],[2,1.69,7.78]],"ltp":1.65,"tv":4.0,"id":31372}]}]}
{"op":"mcm","clk":"11824691801","pt":1723468955803,"mc":[{"id":"1.231699634","rc":[{"batb":[[0,1.73,45.84],[1,1.69,7.78],[2,1.65,62.5]],"ltp":1.65,"tv":4.0,"id":31372}]}]}
{"op":"mcm","clk":"11824691978","pt":1723468958797,"mc":[{"id":"1.231699634","rc":[{"batb":[[0,1.74,10],[1,1.73,45.84],[2,1.69,7.78]],"ltp":1.65,"tv":4.0,"id":31372}]}]}
{"op":"mcm","clk":"11824692147","pt":1723468962401,"mc":[{"id":"1.231699634","rc":[{"batb":[[0,1.73,45.84],[1,1.69,7.78],[2,1.65,62.5]],"ltp":1.65,"tv":4.0,"id":31372}]}]}
{"op":"mcm","clk":"11824692433","pt":1723468966008,"mc":[{"id":"1.231699634","rc":[{"batb":[[0,1.74,10],[1,1.73,45.84],[2,1.69,7.78]],"ltp":1.65,"tv":4.0,"id":31372}]}]}
{"op":"mcm","clk":"11824692725","pt":1723468969412,"mc":[{"id":"1.231699634","rc":[{"batb":[[0,1.73,45.84],[1,1.69,7.78],[2,1.65,62.5]],"ltp":1.65,"tv":4.0,"id":31372}]}]}
{"op":"mcm","clk":"11824692866","pt":1723468971580,"mc":[{"id":"1.231699634","rc":[{"batb":[[0,1.74,10],[1,1.73,45.84],[2,1.69,7.78]],"ltp":1.65,"tv":4.0,"id":31372}]}]}
{"op":"mcm","clk":"11824693135","pt":1723468976276,"mc":[{"id":"1.231699634","rc":[{"batb":[[0,1.73,45.84],[1,1.69,7.78],[2,1.65,62.5]],"ltp":1.65,"tv":4.0,"id":31372}]}]}
{"op":"mcm","clk":"11824693687","pt":1723468983028,"mc":[{"id":"1.231699634","rc":[{"batb":[[0,1.74,10],[1,1.73,45.84],[2,1.69,7.78]],"ltp":1.65,"tv":4.0,"id":31372}]}]}
{"op":"mcm","clk":"11824693985","pt":1723468986435,"mc":[{"id":"1.231699634","rc":[{"batb":[[0,1.73,45.84],[1,1.69,7.78],[2,1.65,62.5]],"ltp":1.65,"tv":4.0,"id":31372}]}]}
{"op":"mcm","clk":"11824694363","pt":1723468991539,"mc":[{"id":"1.231699634","rc":[{"batb":[[0,1.74,10],[1,1.73,45.84],[2,1.69,7.78]],"ltp":1.65,"tv":4.0,"id":31372}]}]}
{"op":"mcm","clk":"11824694617","pt":1723468995343,"mc":[{"id":"1.231699634","rc":[{"batb":[[0,1.73,45.84],[1,1.69,7.78],[2,1.65,62.5]],"ltp":1.65,"tv":4.0,"id":31372}]}]}
{"op":"mcm","clk":"11824695548","pt":1723469009626,"mc":[{"id":"1.231699634","rc":[{"batb":[[0,1.74,10],[1,1.73,45.84],[2,1.69,7.78]],"ltp":1.65,"tv":4.0,"id":31372}]}]}
{"op":"mcm","clk":"11824695727","pt":1723469013068,"mc":[{"id":"1.231699634","rc":[{"batb":[[0,1.73,45.84],[1,1.69,7.78],[2,1.65,62.5]],"ltp":1.65,"tv":4.0,"id":31372}]}]}
{"op":"mcm","clk":"11824696781","pt":1723469028274,"mc":[{"id":"1.231699634","rc":[{"batb":[[0,1.74,10],[1,1.73,45.84],[2,1.69,7.78]],"ltp":1.65,"tv":4.0,"id":31372}]}]}
{"op":"mcm","clk":"11824697178","pt":1723469031748,"mc":[{"id":"1.231699634","rc":[{"batb":[[0,1.73,45.84],[1,1.69,7.78],[2,1.65,62.5]],"ltp":1.65,"tv":4.0,"id":31372}]}]}
{"op":"mcm","clk":"11824697699","pt":1723469036143,"mc":[{"id":"1.231699634","rc":[{"batb":[[0,1.74,10],[1,1.73,45.84],[2,1.69,7.78]],"ltp":1.65,"tv":4.0,"id":31372}]}]}
{"op":"mcm","clk":"11824697966","pt":1723469039954,"mc":[{"id":"1.231699634","rc":[{"batb":[[0,1.73,45.84],[1,1.69,7.78],[2,1.65,62.5]],"ltp":1.65,"tv":4.0,"id":31372}]}]}
{"op":"mcm","clk":"11824699244","pt":1723469056349,"mc":[{"id":"1.231699634","rc":[{"batb":[[0,1.74,10],[1,1.73,45.84],[2,1.69,7.78]],"ltp":1.65,"tv":4.0,"id":31372}]}]}
{"op":"mcm","clk":"11824699522","pt":1723469059745,"mc":[{"id":"1.231699634","rc":[{"batb":[[0,1.73,45.84],[1,1.69,7.78],[2,1.65,62.5]],"ltp":1.65,"tv":4.0,"id":31372}]}]}
{"op":"mcm","clk":"11824699881","pt":1723469064388,"mc":[{"id":"1.231699634","rc":[{"batb":[[0,1.74,10],[1,1.73,45.84],[2,1.69,7.78]],"ltp":1.65,"tv":4.0,"id":31372}]}]}
{"op":"mcm","clk":"11824700193","pt":1723469068446,"mc":[{"id":"1.231699634","rc":[{"batb":[[0,1.73,45.84],[1,1.69,7.78],[2,1.65,62.5]],"ltp":1.65,"tv":4.0,"id":31372}]}]}
{"op":"mcm","clk":"11824700440","pt":1723469071893,"mc":[{"id":"1.231699634","rc":[{"batb":[[0,1.74,10],[1,1.73,45.84],[2,1.69,7.78]],"ltp":1.65,"tv":4.0,"id":31372}]}]}
{"op":"mcm","clk":"11824700687","pt":1723469075081,"mc":[{"id":"1.231699634","rc":[{"batb":[[0,1.73,45.84],[1,1.69,7.78],[2,1.65,62.5]],"ltp":1.65,"tv":4.0,"id":31372}]}]}
{"op":"mcm","clk":"11824701045","pt":1723469078892,"mc":[{"id":"1.231699634","rc":[{"batb":[[0,1.74,10],[1,1.73,45.84],[2,1.69,7.78]],"ltp":1.65,"tv":4.0,"id":31372}]}]}
{"op":"mcm","clk":"11824701440","pt":1723469083690,"mc":[{"id":"1.231699634","rc":[{"batb":[[0,1.73,45.84],[1,1.69,7.78],[2,1.65,62.5]],"ltp":1.65,"tv":4.0,"id":31372}]}]}
{"op":"mcm","clk":"11824701950","pt":1723469089714,"mc":[{"id":"1.231699634","rc":[{"batb":[[0,1.74,10],[1,1.73,45.84],[2,1.69,7.78]],"ltp":1.65,"tv":4.0,"id":31372}]}]}
{"op":"mcm","clk":"11824702403","pt":1723469094920,"mc":[{"id":"1.231699634","rc":[{"batb":[[0,1.73,45.84],[1,1.69,7.78],[2,1.65,62.5]],"ltp":1.65,"tv":4.0,"id":31372}]}]}
{"op":"mcm","clk":"11824702594","pt":1723469097501,"mc":[{"id":"1.231699634","rc":[{"batb":[[0,1.74,10],[1,1.73,45.84],[2,1.69,7.78]],"ltp":1.65,"tv":4.0,"id":31372}]}]}
{"op":"mcm","clk":"11824702841","pt":1723469101312,"mc":[{"id":"1.231699634","rc":[{"batb":[[0,1.73,45.84],[1,1.69,7.78],[2,1.65,62.5]],"ltp":1.65,"tv":4.0,"id":31372}]}]}
{"op":"mcm","clk":"11824703034","pt":1723469103791,"mc":[{"id":"1.231699634","rc":[{"batb":[[0,1.74,10],[1,1.73,45.84],[2,1.69,7.78]],"ltp":1.65,"tv":4.0,"id":31372}]}]}
{"op":"mcm","clk":"11824703314","pt":1723469107090,"mc":[{"id":"1.231699634","rc":[{"batb":[[0,1.73,45.84],[1,1.69,7.78],[2,1.65,62.5]],"ltp":1.65,"tv":4.0,"id":31372}]}]}
{"op":"mcm","clk":"11824703497","pt":1723469109407,"mc":[{"id":"1.231699634","rc":[{"batb":[[0,1.74,10],[1,1.73,45.84],[2,1.69,7.78]],"ltp":1.65,"tv":4.0,"id":31372}]}]}
{"op":"mcm","clk":"11824703871","pt":1723469113892,"mc":[{"id":"1.231699634","rc":[{"batb":[[0,1.73,45.84],[1,1.69,7.78],[2,1.65,62.5]],"ltp":1.65,"tv":4.0,"id":31372}]}]}
{"op":"mcm","clk":"11824704023","pt":1723469116306,"mc":[{"id":"1.231699634","rc":[{"batb":[[0,1.74,10],[1,1.73,45.84],[2,1.69,7.78]],"ltp":1.65,"tv":4.0,"id":31372}]}]}
{"op":"mcm","clk":"11824704256","pt":1723469119608,"mc":[{"id":"1.231699634","rc":[{"batb":[[0,1.73,45.84],[1,1.69,7.78],[2,1.65,62.5]],"ltp":1.65,"tv":4.0,"id":31372}]}]}
{"op":"mcm","clk":"11824704616","pt":1723469124439,"mc":[{"id":"1.231699634","rc":[{"batb":[[0,1.74,10],[1,1.73,45.84],[2,1.69,7.78]],"ltp":1.65,"tv":4.0,"id":31372}]}]}
{"op":"mcm","clk":"11824704859","pt":1723469127735,"mc":[{"id":"1.231699634","rc":[{"batb":[[0,1.73,45.84],[1,1.69,7.78],[2,1.65,62.5]],"ltp":1.65,"tv":4.0,"id":31372}]}]}
{"op":"mcm","clk":"11824705019","pt":1723469129949,"mc":[{"id":"1.231699634","rc":[{"batb":[[0,1.75,10],[1,1.73,45.84],[2,1.69,7.78]],"ltp":1.65,"tv":4.0,"id":31372}]}]}
{"op":"mcm","clk":"11824705326","pt":1723469134368,"mc":[{"id":"1.231699634","rc":[{"batb":[[0,1.73,45.84],[1,1.69,7.78],[2,1.65,62.5]],"ltp":1.65,"tv":4.0,"id":31372}]}]}
{"op":"mcm","clk":"11824705513","pt":1723469137164,"mc":[{"id":"1.231699634","rc":[{"batb":[[0,1.74,10],[1,1.73,45.84],[2,1.69,7.78]],"ltp":1.65,"tv":4.0,"id":31372}]}]}
{"op":"mcm","clk":"11824705760","pt":1723469140766,"mc":[{"id":"1.231699634","rc":[{"batb":[[0,1.73,45.84],[1,1.69,7.78],[2,1.65,62.5]],"ltp":1.65,"tv":4.0,"id":31372}]}]}
{"op":"mcm","clk":"11824706072","pt":1723469144983,"mc":[{"id":"1.231699634","rc":[{"batb":[[0,1.69,7.78],[1,1.65,62.5],[2,1.25,100]],"ltp":1.65,"tv":4.0,"id":31372}]}]}
{"op":"mcm","clk":"11824706174","pt":1723469146471,"mc":[{"id":"1.231699634","rc":[{"batb":[[0,1.7,10],[1,1.69,7.78],[2,1.65,62.5]],"ltp":1.65,"tv":4.0,"id":31372}]}]}
{"op":"mcm","clk":"11824706457","pt":1723469150374,"mc":[{"id":"1.231699634","rc":[{"batb":[[0,1.69,7.78],[1,1.65,62.5],[2,1.25,100]],"ltp":1.65,"tv":4.0,"id":31372}]}]}
{"op":"mcm","clk":"11824706892","pt":1723469157367,"mc":[{"id":"1.231699634","rc":[{"batb":[[0,1.7,10],[1,1.69,7.78],[2,1.65,62.5]],"ltp":1.65,"tv":4.0,"id":31372}]}]}
{"op":"mcm","clk":"11824707249","pt":1723469162462,"mc":[{"id":"1.231699634","rc":[{"batb":[[0,1.69,7.78],[1,1.65,62.5],[2,1.25,100]],"ltp":1.65,"tv":4.0,"id":31372}]}]}
{"op":"mcm","clk":"11824707620","pt":1723469168211,"mc":[{"id":"1.231699634","rc":[{"batb":[[0,1.7,10],[1,1.69,7.78],[2,1.65,62.5]],"ltp":1.65,"tv":4.0,"id":31372}]}]}
{"op":"mcm","clk":"11824707885","pt":1723469172678,"mc":[{"id":"1.231699634","rc":[{"batb":[[0,1.69,7.78],[1,1.65,62.5],[2,1.25,100]],"ltp":1.65,"tv":4.0,"id":31372}]}]}
{"op":"mcm","clk":"11824708348","pt":1723469179401,"mc":[{"id":"1.231699634","rc":[{"batb":[[0,1.7,10],[1,1.69,7.78],[2,1.65,62.5]],"ltp":1.65,"tv":4.0,"id":31372}]}]}
{"op":"mcm","clk":"11824708592","pt":1723469182680,"mc":[{"id":"1.231699634","rc":[{"batb":[[0,1.69,7.78],[1,1.65,62.5],[2,1.25,100]],"ltp":1.65,"tv":4.0,"id":31372}]}]}
{"op":"mcm","clk":"11824709294","pt":1723469193113,"mc":[{"id":"1.231699634","rc":[{"batb":[[0,1.7,10],[1,1.69,7.78],[2,1.65,62.5]],"ltp":1.65,"tv":4.0,"id":31372}]}]}
{"op":"mcm","clk":"11824709510","pt":1723469196405,"mc":[{"id":"1.231699634","rc":[{"batb":[[0,1.69,7.78],[1,1.65,62.5],[2,1.25,100]],"ltp":1.65,"tv":4.0,"id":31372}]}]}
{"op":"mcm","clk":"11824709989","pt":1723469203338,"mc":[{"id":"1.231699634","rc":[{"batb":[[0,1.7,10],[1,1.69,7.78],[2,1.65,62.5]],"ltp":1.65,"tv":4.0,"id":31372}]}]}
{"op":"mcm","clk":"11824710416","pt":1723469208948,"mc":[{"id":"1.231699634","rc":[{"batb":[[0,1.69,7.78],[1,1.65,62.5],[2,1.25,100]],"ltp":1.65,"tv":4.0,"id":31372}]}]}
{"op":"mcm","clk":"11824710675","pt":1723469212539,"mc":[{"id":"1.231699634","rc":[{"batb":[[0,1.7,10],[1,1.69,7.78],[2,1.65,62.5]],"ltp":1.65,"tv":4.0,"id":31372}]}]}
{"op":"mcm","clk":"11824711017","pt":1723469217648,"mc":[{"id":"1.231699634","rc":[{"batb":[[0,1.69,7.78],[1,1.65,62.5],[2,1.25,100]],"ltp":1.65,"tv":4.0,"id":31372}]}]}
{"op":"mcm","clk":"11824711338","pt":1723469222255,"mc":[{"id":"1.231699634","rc":[{"batb":[[0,1.7,10],[1,1.69,7.78],[2,1.65,62.5]],"ltp":1.65,"tv":4.0,"id":31372}]}]}
{"op":"mcm","clk":"11824711575","pt":1723469225756,"mc":[{"id":"1.231699634","rc":[{"batb":[[0,1.69,7.78],[1,1.65,62.5],[2,1.25,100]],"ltp":1.65,"tv":4.0,"id":31372}]}]}
{"op":"mcm","clk":"11824711807","pt":1723469229094,"mc":[{"id":"1.231699634","rc":[{"batb":[[0,1.7,10],[1,1.69,7.78],[2,1.65,62.5]],"ltp":1.65,"tv":4.0,"id":31372}]}]}
{"op":"mcm","clk":"11824712150","pt":1723469233471,"mc":[{"id":"1.231699634","rc":[{"batb":[[0,1.69,7.78],[1,1.65,62.5],[2,1.25,100]],"ltp":1.65,"tv":4.0,"id":31372}]}]}
{"op":"mcm","clk":"11824712379","pt":1723469236965,"mc":[{"id":"1.231699634","rc":[{"batb":[[0,1.7,10],[1,1.69,7.78],[2,1.65,62.5]],"ltp":1.65,"tv":4.0,"id":31372}]}]}
{"op":"mcm","clk":"11824712671","pt":1723469241082,"mc":[{"id":"1.231699634","rc":[{"batb":[[0,1.69,7.78],[1,1.65,62.5],[2,1.25,100]],"ltp":1.65,"tv":4.0,"id":31372}]}]}
{"op":"mcm","clk":"11824713038","pt":1723469246266,"mc":[{"id":"1.231699634","rc":[{"batb":[[0,1.7,10],[1,1.69,7.78],[2,1.65,62.5]],"ltp":1.65,"tv":4.0,"id":31372}]}]}
{"op":"mcm","clk":"11824713251","pt":1723469249684,"mc":[{"id":"1.231699634","rc":[{"batb":[[0,1.69,7.78],[1,1.65,62.5],[2,1.25,100]],"ltp":1.65,"tv":4.0,"id":31372}]}]}
{"op":"mcm","clk":"11824713421","pt":1723469252201,"mc":[{"id":"1.231699634","rc":[{"batb":[[0,1.7,10],[1,1.69,7.78],[2,1.65,62.5]],"ltp":1.65,"tv":4.0,"id":31372}]}]}
{"op":"mcm","clk":"11824713635","pt":1723469255689,"mc":[{"id":"1.231699634","rc":[{"batb":[[0,1.69,7.78],[1,1.65,62.5],[2,1.25,100]],"ltp":1.65,"tv":4.0,"id":31372}]}]}
{"op":"mcm","clk":"11824713922","pt":1723469260314,"mc":[{"id":"1.231699634","rc":[{"batb":[[0,1.7,10],[1,1.69,7.78],[2,1.65,62.5]],"ltp":1.65,"tv":4.0,"id":31372}]}]}
{"op":"mcm","clk":"11824714214","pt":1723469264055,"mc":[{"id":"1.231699634","rc":[{"batb":[[0,1.69,7.78],[1,1.65,62.5],[2,1.25,100]],"ltp":1.65,"tv":4.0,"id":31372}]}]}
{"op":"mcm","clk":"11824714388","pt":1723469267037,"mc":[{"id":"1.231699634","rc":[{"batb":[[0,1.7,10],[1,1.69,7.78],[2,1.65,62.5]],"ltp":1.65,"tv":4.0,"id":31372}]}]}
{"op":"mcm","clk":"11824714610","pt":1723469270641,"mc":[{"id":"1.231699634","rc":[{"batb":[[0,1.69,7.78],[1,1.65,62.5],[2,1.25,100]],"ltp":1.65,"tv":4.0,"id":31372}]}]}
{"op":"mcm","clk":"11824714783","pt":1723469273463,"mc":[{"id":"1.231699634","rc":[{"batb":[[0,1.7,10],[1,1.69,7.78],[2,1.65,62.5]],"ltp":1.65,"tv":4.0,"id":31372}]}]}
{"op":"mcm","clk":"11824715021","pt":1723469276957,"mc":[{"id":"1.231699634","rc":[{"batb":[[0,1.69,7.78],[1,1.65,62.5],[2,1.25,100]],"ltp":1.65,"tv":4.0,"id":31372}]}]}
{"op":"mcm","clk":"11824715234","pt":1723469279881,"mc":[{"id":"1.231699634","rc":[{"batb":[[0,1.7,10],[1,1.69,7.78],[2,1.65,62.5]],"ltp":1.65,"tv":4.0,"id":31372}]}]}
{"op":"mcm","clk":"11824715514","pt":1723469283287,"mc":[{"id":"1.231699634","rc":[{"batb":[[0,1.69,7.78],[1,1.65,62.5],[2,1.25,100]],"ltp":1.65,"tv":4.0,"id":31372}]}]}
{"op":"mcm","clk":"11824715738","pt":1723469285553,"mc":[{"id":"1.231699634","rc":[{"batb":[[0,1.7,10],[1,1.69,7.78],[2,1.65,62.5]],"ltp":1.65,"tv":4.0,"id":31372}]}]}
{"op":"mcm","clk":"11824716009","pt":1723469288854,"mc":[{"id":"1.231699634","rc":[{"batb":[[0,1.69,7.78],[1,1.65,62.5],[2,1.25,100]],"ltp":1.65,"tv":4.0,"id":31372}]}]}
{"op":"mcm","clk":"11824716235","pt":1723469291672,"mc":[{"id":"1.231699634","rc":[{"batb":[[0,1.7,10],[1,1.69,7.78],[2,1.65,62.5]],"ltp":1.65,"tv":4.0,"id":31372}]}]}
{"op":"mcm","clk":"11824716526","pt":1723469294867,"mc":[{"id":"1.231699634","rc":[{"batb":[[0,1.69,7.78],[1,1.65,62.5],[2,1.25,100]],"ltp":1.65,"tv":4.0,"id":31372}]}]}
{"op":"mcm","clk":"11824716904","pt":1723469299368,"mc":[{"id":"1.231699634","rc":[{"batb":[[0,1.7,10],[1,1.69,7.78],[2,1.65,62.5]],"ltp":1.65,"tv":4.0,"id":31372}]}]}
{"op":"mcm","clk":"11824717209","pt":1723469302891,"mc":[{"id":"1.231699634","rc":[{"batb":[[0,1.69,7.78],[1,1.65,62.5],[2,1.25,100]],"ltp":1.65,"tv":4.0,"id":31372}]}]}
{"op":"mcm","clk":"11824717481","pt":1723469306102,"mc":[{"id":"1.231699634","rc":[{"batb":[[0,1.7,10],[1,1.69,7.78],[2,1.65,62.5]],"ltp":1.65,"tv":4.0,"id":31372}]}]}
{"op":"mcm","clk":"11824717778","pt":1723469309502,"mc":[{"id":"1.231699634","rc":[{"batb":[[0,1.69,7.78],[1,1.65,62.5],[2,1.25,100]],"ltp":1.65,"tv":4.0,"id":31372}]}]}
{"op":"mcm","clk":"11824718003","pt":1723469312280,"mc":[{"id":"1.231699634","rc":[{"batb":[[0,1.7,10],[1,1.69,7.78],[2,1.65,62.5]],"ltp":1.65,"tv":4.0,"id":31372}]}]}
{"op":"mcm","clk":"11824718435","pt":1723469317787,"mc":[{"id":"1.231699634","rc":[{"batb":[[0,1.69,7.78],[1,1.65,62.5],[2,1.25,100]],"ltp":1.65,"tv":4.0,"id":31372}]}]}
{"op":"mcm","clk":"11824718667","pt":1723469320819,"mc":[{"id":"1.231699634","rc":[{"batb":[[0,1.71,10],[1,1.69,7.78],[2,1.65,62.5]],"ltp":1.65,"tv":4.0,"id":31372}]}]}
{"op":"mcm","clk":"11824719089","pt":1723469326627,"mc":[{"id":"1.231699634","rc":[{"batb":[[0,1.69,7.78],[1,1.65,62.5],[2,1.25,100]],"ltp":1.65,"tv":4.0,"id":31372}]}]}
{"op":"mcm","clk":"11824719950","pt":1723469338339,"mc":[{"id":"1.231699634","rc":[{"batb":[[0,1.7,10],[1,1.69,7.78],[2,1.65,62.5]],"ltp":1.65,"tv":4.0,"id":31372}]}]}
{"op":"mcm","clk":"11824720239","pt":1723469342318,"mc":[{"id":"1.231699634","rc":[{"batb":[[0,1.69,7.78],[1,1.65,62.5],[2,1.25,100]],"ltp":1.65,"tv":4.0,"id":31372}]}]}
{"op":"mcm","clk":"11824720430","pt":1723469345729,"mc":[{"id":"1.231699634","rc":[{"batb":[[0,1.7,10],[1,1.69,7.78],[2,1.65,62.5]],"ltp":1.65,"tv":4.0,"id":31372}]}]}
{"op":"mcm","clk":"11824720698","pt":1723469349332,"mc":[{"id":"1.231699634","rc":[{"batb":[[0,1.69,7.78],[1,1.65,62.5],[2,1.25,100]],"ltp":1.65,"tv":4.0,"id":31372}]}]}
{"op":"mcm","clk":"11824720875","pt":1723469352019,"mc":[{"id":"1.231699634","rc":[{"batb":[[0,1.7,10],[1,1.69,7.78],[2,1.65,62.5]],"ltp":1.65,"tv":4.0,"id":31372}]}]}
{"op":"mcm","clk":"11824721216","pt":1723469356455,"mc":[{"id":"1.231699634","rc":[{"batb":[[0,1.69,7.78],[1,1.65,62.5],[2,1.25,100]],"ltp":1.65,"tv":4.0,"id":31372}]}]}
{"op":"mcm","clk":"11824721699","pt":1723469362331,"mc":[{"id":"1.231699634","rc":[{"batb":[[0,1.7,10],[1,1.69,7.78],[2,1.65,62.5]],"ltp":1.65,"tv":4.0,"id":31372}]}]}
{"op":"mcm","clk":"11824722159","pt":1723469369270,"mc":[{"id":"1.231699634","rc":[{"batb":[[0,1.69,7.78],[1,1.65,62.5],[2,1.25,100]],"ltp":1.65,"tv":4.0,"id":31372}]}]}
{"op":"mcm","clk":"11824723369","pt":1723469381293,"mc":[{"id":"1.231699634","rc":[{"batb":[[0,1.7,10],[1,1.69,7.78],[2,1.65,62.5]],"ltp":1.65,"tv":4.0,"id":31372}]}]}
{"op":"mcm","clk":"11824723685","pt":1723469385800,"mc":[{"id":"1.231699634","rc":[{"batb":[[0,1.69,7.78],[1,1.65,62.5],[2,1.25,100]],"ltp":1.65,"tv":4.0,"id":31372}]}]}
{"op":"mcm","clk":"11824724077","pt":1723469391900,"mc":[{"id":"1.231699634","rc":[{"batb":[[0,1.7,10],[1,1.69,7.78],[2,1.65,62.5]],"ltp":1.65,"tv":4.0,"id":31372}]}]}
{"op":"mcm","clk":"11824724318","pt":1723469395723,"mc":[{"id":"1.231699634","rc":[{"batb":[[0,1.69,7.78],[1,1.65,62.5],[2,1.25,100]],"ltp":1.65,"tv":4.0,"id":31372}]}]}
{"op":"mcm","clk":"11824724621","pt":1723469400608,"mc":[{"id":"1.231699634","rc":[{"batb":[[0,1.7,10],[1,1.69,7.78],[2,1.65,62.5]],"ltp":1.65,"tv":4.0,"id":31372}]}]}
{"op":"mcm","clk":"11824724905","pt":1723469404110,"mc":[{"id":"1.231699634","rc":[{"batb":[[0,1.69,7.78],[1,1.65,62.5],[2,1.25,100]],"ltp":1.65,"tv":4.0,"id":31372}]}]}
{"op":"mcm","clk":"11824725182","pt":1723469408536,"mc":[{"id":"1.231699634","rc":[{"batb":[[0,1.7,10],[1,1.69,7.78],[2,1.65,62.5]],"ltp":1.65,"tv":4.0,"id":31372}]}]}
{"op":"mcm","clk":"11824725413","pt":1723469412032,"mc":[{"id":"1.231699634","rc":[{"batb":[[0,1.69,7.78],[1,1.65,62.5],[2,1.25,100]],"ltp":1.65,"tv":4.0,"id":31372}]}]}
{"op":"mcm","clk":"11824725568","pt":1723469414245,"mc":[{"id":"1.231699634","rc":[{"batb":[[0,1.7,10],[1,1.69,7.78],[2,1.65,62.5]],"ltp":1.65,"tv":4.0,"id":31372}]}]}
{"op":"mcm","clk":"11824725798","pt":1723469417644,"mc":[{"id":"1.231699634","rc":[{"batb":[[0,1.69,7.78],[1,1.65,62.5],[2,1.25,100]],"ltp":1.65,"tv":4.0,"id":31372}]}]}
{"op":"mcm","clk":"11824726044","pt":1723469420831,"mc":[{"id":"1.231699634","rc":[{"batb":[[0,1.7,10],[1,1.69,7.78],[2,1.65,62.5]],"ltp":1.65,"tv":4.0,"id":31372}]}]}
{"op":"mcm","clk":"11824726388","pt":1723469425763,"mc":[{"id":"1.231699634","rc":[{"batb":[[0,1.69,7.78],[1,1.65,62.5],[2,1.25,100]],"ltp":1.65,"tv":4.0,"id":31372}]}]}
{"op":"mcm","clk":"11824727364","pt":1723469438151,"mc":[{"id":"1.231699634","rc":[{"batb":[[0,1.7,10],[1,1.69,7.78],[2,1.65,62.5]],"ltp":1.65,"tv":4.0,"id":31372}]}]}
{"op":"mcm","clk":"11824727587","pt":1723469442154,"mc":[{"id":"1.231699634","rc":[{"batb":[[0,1.69,7.78],[1,1.65,62.5],[2,1.25,100]],"ltp":1.65,"tv":4.0,"id":31372}]}]}
{"op":"mcm","clk":"11824728117","pt":1723469449407,"mc":[{"id":"1.231699634","rc":[{"batb":[[0,1.7,10],[1,1.69,7.78],[2,1.65,62.5]],"ltp":1.65,"tv":4.0,"id":31372}]}]}
{"op":"mcm","clk":"11824728515","pt":1723469454202,"mc":[{"id":"1.231699634","rc":[{"batb":[[0,1.69,7.78],[1,1.65,62.5],[2,1.25,100]],"ltp":1.65,"tv":4.0,"id":31372}]}]}
{"op":"mcm","clk":"11824729454","pt":1723469463709,"mc":[{"id":"1.231699634","rc":[{"batb":[[0,1.7,10],[1,1.69,7.78],[2,1.65,62.5]],"ltp":1.65,"tv":4.0,"id":31372}]}]}
{"op":"mcm","clk":"11824730142","pt":1723469471831,"mc":[{"id":"1.231699634","rc":[{"batb":[[0,1.69,7.78],[1,1.65,62.5],[2,1.25,100]],"ltp":1.65,"tv":4.0,"id":31372}]}]}
{"op":"mcm","clk":"11824730377","pt":1723469474608,"mc":[{"id":"1.231699634","rc":[{"batb":[[0,1.7,10],[1,1.69,7.78],[2,1.65,62.5]],"ltp":1.65,"tv":4.0,"id":31372}]}]}
{"op":"mcm","clk":"11824730736","pt":1723469479290,"mc":[{"id":"1.231699634","rc":[{"batb":[[0,1.69,7.78],[1,1.65,62.5],[2,1.25,100]],"ltp":1.65,"tv":4.0,"id":31372}]}]}
{"op":"mcm","clk":"11824731165","pt":1723469484900,"mc":[{"id":"1.231699634","rc":[{"batb":[[0,1.7,10],[1,1.69,7.78],[2,1.65,62.5]],"ltp":1.65,"tv":4.0,"id":31372}]}]}
{"op":"mcm","clk":"11824731480","pt":1723469489321,"mc":[{"id":"1.231699634","rc":[{"batb":[[0,1.69,7.78],[1,1.65,62.5],[2,1.25,100]],"ltp":1.65,"tv":4.0,"id":31372}]}]}
{"op":"mcm","clk":"11824731683","pt":1723469492348,"mc":[{"id":"1.231699634","rc":[{"batb":[[0,1.7,10],[1,1.69,7.78],[2,1.65,62.5]],"ltp":1.65,"tv":4.0,"id":31372}]}]}
{"op":"mcm","clk":"11824731918","pt":1723469495734,"mc":[{"id":"1.231699634","rc":[{"batb":[[0,1.69,7.78],[1,1.65,62.5],[2,1.25,100]],"ltp":1.65,"tv":4.0,"id":31372}]}]}
{"op":"mcm","clk":"11824732248","pt":1723469500768,"mc":[{"id":"1.231699634","rc":[{"batb":[[0,1.7,10],[1,1.69,7.78],[2,1.65,62.5]],"ltp":1.65,"tv":4.0,"id":31372}]}]}
{"op":"mcm","clk":"11824732637","pt":1723469506436,"mc":[{"id":"1.231699634","rc":[{"batb":[[0,1.69,7.78],[1,1.65,62.5],[2,1.25,100]],"ltp":1.65,"tv":4.0,"id":31372}]}]}
{"op":"mcm","clk":"11824732839","pt":1723469509737,"mc":[{"id":"1.231699634","rc":[{"batb":[[0,1.7,10],[1,1.69,7.78],[2,1.65,62.5]],"ltp":1.65,"tv":4.0,"id":31372}]}]}
{"op":"mcm","clk":"11824733143","pt":1723469513251,"mc":[{"id":"1.231699634","rc":[{"batb":[[0,1.69,7.78],[1,1.65,62.5],[2,1.25,100]],"ltp":1.65,"tv":4.0,"id":31372}]}]}
{"op":"mcm","clk":"11824733316","pt":1723469515568,"mc":[{"id":"1.231699634","rc":[{"batb":[[0,1.7,10],[1,1.69,7.78],[2,1.65,62.5]],"ltp":1.65,"tv":4.0,"id":31372}]}]}
{"op":"mcm","clk":"11824733657","pt":1723469520146,"mc":[{"id":"1.231699634","rc":[{"batb":[[0,1.69,7.78],[1,1.65,62.5],[2,1.25,100]],"ltp":1.65,"tv":4.0,"id":31372}]}]}
{"op":"mcm","clk":"11824733850","pt":1723469522984,"mc":[{"id":"1.231699634","rc":[{"batb":[[0,1.7,10],[1,1.69,7.78],[2,1.65,62.5]],"ltp":1.65,"tv":4.0,"id":31372}]}]}
{"op":"mcm","clk":"11824734106","pt":1723469526542,"mc":[{"id":"1.231699634","rc":[{"batb":[[0,1.69,7.78],[1,1.65,62.5],[2,1.25,100]],"ltp":1.65,"tv":4.0,"id":31372}]}]}
{"op":"mcm","clk":"11824734683","pt":1723469534371,"mc":[{"id":"1.231699634","rc":[{"batb":[[0,1.7,10],[1,1.69,7.78],[2,1.65,62.5]],"ltp":1.65,"tv":4.0,"id":31372}]}]}
{"op":"mcm","clk":"11824734998","pt":1723469538295,"mc":[{"id":"1.231699634","rc":[{"batb":[[0,1.69,7.78],[1,1.65,62.5],[2,1.25,100]],"ltp":1.65,"tv":4.0,"id":31372}]}]}
{"op":"mcm","clk":"11824735341","pt":1723469542673,"mc":[{"id":"1.231699634","rc":[{"batb":[[0,1.7,10],[1,1.69,7.78],[2,1.65,62.5]],"ltp":1.65,"tv":4.0,"id":31372}]}]}
{"op":"mcm","clk":"11824735688","pt":1723469546393,"mc":[{"id":"1.231699634","rc":[{"batb":[[0,1.69,7.78],[1,1.65,62.5],[2,1.25,100]],"ltp":1.65,"tv":4.0,"id":31372}]}]}
{"op":"mcm","clk":"11824735948","pt":1723469549791,"mc":[{"id":"1.231699634","rc":[{"batb":[[0,1.7,10],[1,1.69,7.78],[2,1.65,62.5]],"ltp":1.65,"tv":4.0,"id":31372}]}]}
{"op":"mcm","clk":"11824736198","pt":1723469553511,"mc":[{"id":"1.231699634","rc":[{"batb":[[0,1.69,7.78],[1,1.65,62.5],[2,1.25,100]],"ltp":1.65,"tv":4.0,"id":31372}]}]}
{"op":"mcm","clk":"11824736865","pt":1723469562889,"mc":[{"id":"1.231699634","rc":[{"batb":[[0,1.7,10],[1,1.69,7.78],[2,1.65,62.5]],"ltp":1.65,"tv":4.0,"id":31372}]}]}
{"op":"mcm","clk":"11824737204","pt":1723469567531,"mc":[{"id":"1.231699634","rc":[{"batb":[[0,1.69,7.78],[1,1.65,62.5],[2,1.25,100]],"ltp":1.65,"tv":4.0,"id":31372}]}]}
{"op":"mcm","clk":"11824737733","pt":1723469574295,"mc":[{"id":"1.231699634","rc":[{"batb":[[0,1.7,10],[1,1.69,7.78],[2,1.65,62.5]],"ltp":1.65,"tv":4.0,"id":31372}]}]}
{"op":"mcm","clk":"11824737987","pt":1723469577703,"mc":[{"id":"1.231699634","rc":[{"batb":[[0,1.69,7.78],[1,1.65,62.5],[2,1.25,100]],"ltp":1.65,"tv":4.0,"id":31372}]}]}
{"op":"mcm","clk":"11824738394","pt":1723469583738,"mc":[{"id":"1.231699634","rc":[{"batb":[[0,1.7,10],[1,1.69,7.78],[2,1.65,62.5]],"ltp":1.65,"tv":4.0,"id":31372}]}]}
{"op":"mcm","clk":"11824738648","pt":1723469587552,"mc":[{"id":"1.231699634","rc":[{"batb":[[0,1.69,7.78],[1,1.65,62.5],[2,1.25,100]],"ltp":1.65,"tv":4.0,"id":31372}]}]}
{"op":"mcm","clk":"11824738981","pt":1723469592238,"mc":[{"id":"1.231699634","rc":[{"batb":[[0,1.7,10],[1,1.69,7.78],[2,1.65,62.5]],"ltp":1.65,"tv":4.0,"id":31372}]}]}
{"op":"mcm","clk":"11824739198","pt":1723469595614,"mc":[{"id":"1.231699634","rc":[{"batb":[[0,1.69,7.78],[1,1.65,62.5],[2,1.25,100]],"ltp":1.65,"tv":4.0,"id":31372}]}]}
{"op":"mcm","clk":"11824739411","pt":1723469599218,"mc":[{"id":"1.231699634","rc":[{"batb":[[0,1.7,10],[1,1.69,7.78],[2,1.65,62.5]],"ltp":1.65,"tv":4.0,"id":31372}]}]}
{"op":"mcm","clk":"11824739685","pt":1723469602923,"mc":[{"id":"1.231699634","rc":[{"batb":[[0,1.69,7.78],[1,1.65,62.5],[2,1.25,100]],"ltp":1.65,"tv":4.0,"id":31372}]}]}
{"op":"mcm","clk":"11824740667","pt":1723469617271,"mc":[{"id":"1.231699634","rc":[{"batb":[[0,1.7,10],[1,1.69,7.78],[2,1.65,62.5]],"ltp":1.65,"tv":4.0,"id":31372}]}]}
{"op":"mcm","clk":"11824740882","pt":1723469620662,"mc":[{"id":"1.231699634","rc":[{"batb":[[0,1.69,7.78],[1,1.65,62.5],[2,1.25,100]],"ltp":1.65,"tv":4.0,"id":31372}]}]}
{"op":"mcm","clk":"11824741066","pt":1723469623283,"mc":[{"id":"1.231699634","rc":[{"batb":[[0,1.7,10],[1,1.69,7.78],[2,1.65,62.5]],"ltp":1.65,"tv":4.0,"id":31372}]}]}
{"op":"mcm","clk":"11824741340","pt":1723469627846,"mc":[{"id":"1.231699634","rc":[{"batb":[[0,1.69,7.78],[1,1.65,62.5],[2,1.25,100]],"ltp":1.65,"tv":4.0,"id":31372}]}]}
{"op":"mcm","clk":"11824741775","pt":1723469634568,"mc":[{"id":"1.231699634","rc":[{"batb":[[0,1.7,10],[1,1.69,7.78],[2,1.65,62.5]],"ltp":1.65,"tv":4.0,"id":31372}]}]}
{"op":"mcm","clk":"11824742003","pt":1723469638055,"mc":[{"id":"1.231699634","rc":[{"batb":[[0,1.69,7.78],[1,1.65,62.5],[2,1.25,100]],"ltp":1.65,"tv":4.0,"id":31372}]}]}
{"op":"mcm","clk":"11824742152","pt":1723469640772,"mc":[{"id":"1.231699634","rc":[{"batb":[[0,1.7,10],[1,1.69,7.78],[2,1.65,62.5]],"ltp":1.65,"tv":4.0,"id":31372}]}]}
{"op":"mcm","clk":"11824742517","pt":1723469645755,"mc":[{"id":"1.231699634","rc":[{"batb":[[0,1.69,7.78],[1,1.65,62.5],[2,1.25,100]],"ltp":1.65,"tv":4.0,"id":31372}]}]}
{"op":"mcm","clk":"11824743486","pt":1723469659165,"mc":[{"id":"1.231699634","rc":[{"batb":[[0,1.7,10],[1,1.69,7.78],[2,1.65,62.5]],"ltp":1.65,"tv":4.0,"id":31372}]}]}
{"op":"mcm","clk":"11824743833","pt":1723469664661,"mc":[{"id":"1.231699634","rc":[{"batb":[[0,1.69,7.78],[1,1.65,62.5],[2,1.25,100]],"ltp":1.65,"tv":4.0,"id":31372}]}]}
{"op":"mcm","clk":"11824745045","pt":1723469683393,"mc":[{"id":"1.231699634","rc":[{"batb":[[0,1.7,10],[1,1.69,7.78],[2,1.65,62.5]],"ltp":1.65,"tv":4.0,"id":31372}]}]}
{"op":"mcm","clk":"11824745292","pt":1723469686983,"mc":[{"id":"1.231699634","rc":[{"batb":[[0,1.69,7.78],[1,1.65,62.5],[2,1.25,100]],"ltp":1.65,"tv":4.0,"id":31372}]}]}
{"op":"mcm","clk":"11824746366","pt":1723469702928,"mc":[{"id":"1.231699634","rc":[{"batb":[[0,1.7,10],[1,1.69,7.78],[2,1.65,62.5]],"ltp":1.65,"tv":4.0,"id":31372}]}]}
{"op":"mcm","clk":"11824746662","pt":1723469707504,"mc":[{"id":"1.231699634","rc":[{"batb":[[0,1.69,7.78],[1,1.65,62.5],[2,1.25,100]],"ltp":1.65,"tv":4.0,"id":31372}]}]}
{"op":"mcm","clk":"11824746944","pt":1723469711927,"mc":[{"id":"1.231699634","rc":[{"batb":[[0,1.7,10],[1,1.69,7.78],[2,1.65,62.5]],"ltp":1.65,"tv":4.0,"id":31372}]}]}
{"op":"mcm","clk":"11824747189","pt":1723469715305,"mc":[{"id":"1.231699634","rc":[{"batb":[[2,1.65,122.1]],"ltp":1.65,"tv":4.0,"id":31372}]}]}
{"op":"mcm","clk":"11824747220","pt":1723469715722,"mc":[{"id":"1.231699634","rc":[{"batb":[[0,1.69,7.78],[1,1.65,59.6],[2,1.25,100]],"ltp":1.65,"tv":4.0,"id":31372}]}]}
{"op":"mcm","clk":"11824747543","pt":1723469720517,"mc":[{"id":"1.231699634","rc":[{"batb":[[0,1.7,10],[1,1.69,7.78],[2,1.65,59.6]],"ltp":1.65,"tv":4.0,"id":31372}]}]}
{"op":"mcm","clk":"11824747968","pt":1723469723826,"mc":[{"id":"1.231699634","rc":[{"batb":[[0,1.69,7.78],[1,1.65,59.6],[2,1.25,100]],"ltp":1.65,"tv":4.0,"id":31372}]}]}
{"op":"mcm","clk":"11824748322","pt":1723469728931,"mc":[{"id":"1.231699634","rc":[{"batb":[[0,1.7,10],[1,1.69,7.78],[2,1.65,59.6]],"ltp":1.65,"tv":4.0,"id":31372}]}]}
{"op":"mcm","clk":"11824748559","pt":1723469732673,"mc":[{"id":"1.231699634","rc":[{"batb":[[0,1.69,7.78],[1,1.65,59.6],[2,1.25,100]],"ltp":1.65,"tv":4.0,"id":31372}]}]}
{"op":"mcm","clk":"11824748674","pt":1723469734813,"mc":[{"id":"1.231699634","rc":[{"batb":[[0,1.7,10],[1,1.69,7.78],[2,1.65,59.6]],"ltp":1.65,"tv":4.0,"id":31372}]}]}
{"op":"mcm","clk":"11824748914","pt":1723469739240,"mc":[{"id":"1.231699634","rc":[{"batb":[[0,1.69,7.78],[1,1.65,59.6],[2,1.25,100]],"ltp":1.65,"tv":4.0,"id":31372}]}]}
{"op":"mcm","clk":"11824749058","pt":1723469742128,"mc":[{"id":"1.231699634","rc":[{"batb":[[0,1.7,10],[1,1.69,7.78],[2,1.65,59.6]],"ltp":1.65,"tv":4.0,"id":31372}]}]}
{"op":"mcm","clk":"11824749256","pt":1723469745748,"mc":[{"id":"1.231699634","rc":[{"batb":[[0,1.69,7.78],[1,1.65,59.6],[2,1.25,100]],"ltp":1.65,"tv":4.0,"id":31372}]}]}
{"op":"mcm","clk":"11824749548","pt":1723469751149,"mc":[{"id":"1.231699634","rc":[{"batb":[[0,1.7,10],[1,1.69,7.78],[2,1.65,59.6]],"ltp":1.65,"tv":4.0,"id":31372}]}]}
{"op":"mcm","clk":"11824749725","pt":1723469754440,"mc":[{"id":"1.231699634","rc":[{"batb":[[0,1.69,7.78],[1,1.65,59.6],[2,1.25,100]],"ltp":1.65,"tv":4.0,"id":31372}]}]}
{"op":"mcm","clk":"11824750466","pt":1723469766265,"mc":[{"id":"1.231699634","rc":[{"batb":[[0,1.7,10],[1,1.69,7.78],[2,1.65,59.6]],"ltp":1.65,"tv":4.0,"id":31372}]}]}
{"op":"mcm","clk":"11824750708","pt":1723469770083,"mc":[{"id":"1.231699634","rc":[{"batb":[[0,1.69,7.78],[1,1.65,59.6],[2,1.25,100]],"ltp":1.65,"tv":4.0,"id":31372}]}]}
{"op":"mcm","clk":"11824751243","pt":1723469778484,"mc":[{"id":"1.231699634","rc":[{"batb":[[0,1.7,10],[1,1.69,7.78],[2,1.65,59.6]],"ltp":1.65,"tv":4.0,"id":31372}]}]}
{"op":"mcm","clk":"11824751553","pt":1723469783181,"mc":[{"id":"1.231699634","rc":[{"batb":[[0,1.69,7.78],[1,1.65,59.6],[2,1.25,100]],"ltp":1.65,"tv":4.0,"id":31372}]}]}
{"op":"mcm","clk":"11824752097","pt":1723469791642,"mc":[{"id":"1.231699634","rc":[{"batb":[[0,1.7,10],[1,1.69,7.78],[2,1.65,59.6]],"ltp":1.65,"tv":4.0,"id":31372}]}]}
{"op":"mcm","clk":"11824752372","pt":1723469795046,"mc":[{"id":"1.231699634","rc":[{"batb":[[0,1.69,7.78],[1,1.65,59.6],[2,1.25,100]],"ltp":1.65,"tv":4.0,"id":31372}]}]}
{"op":"mcm","clk":"11824756089","pt":1723469844291,"mc":[{"id":"1.231699634","rc":[{"batb":[[0,1.7,10],[1,1.69,7.78],[2,1.65,59.6]],"ltp":1.65,"tv":4.0,"id":31372}]}]}
{"op":"mcm","clk":"11824756336","pt":1723469847613,"mc":[{"id":"1.231699634","rc":[{"batb":[[0,1.69,7.78],[1,1.65,59.6],[2,1.25,100]],"ltp":1.65,"tv":4.0,"id":31372}]}]}
{"op":"mcm","clk":"11824759054","pt":1723469885529,"mc":[{"id":"1.231699634","rc":[{"batb":[[0,1.7,10],[1,1.69,7.78],[2,1.65,59.6]],"ltp":1.65,"tv":4.0,"id":31372}]}]}
{"op":"mcm","clk":"11824759356","pt":1723469889749,"mc":[{"id":"1.231699634","rc":[{"batb":[[0,1.69,7.78],[1,1.65,59.6],[2,1.25,100]],"ltp":1.65,"tv":4.0,"id":31372}]}]}
{"op":"mcm","clk":"11824759810","pt":1723469895426,"mc":[{"id":"1.231699634","rc":[{"batb":[[0,1.7,10],[1,1.69,7.78],[2,1.65,59.6]],"ltp":1.65,"tv":4.0,"id":31372}]}]}
{"op":"mcm","clk":"11824760076","pt":1723469899046,"mc":[{"id":"1.231699634","rc":[{"batb":[[0,1.69,7.78],[1,1.65,59.6],[2,1.25,100]],"ltp":1.65,"tv":4.0,"id":31372}]}]}
{"op":"mcm","clk":"11824760643","pt":1723469906424,"mc":[{"id":"1.231699634","rc":[{"batb":[[0,1.7,10],[1,1.69,7.78],[2,1.65,59.6]],"ltp":1.65,"tv":4.0,"id":31372}]}]}
{"op":"mcm","clk":"11824760867","pt":1723469909841,"mc":[{"id":"1.231699634","rc":[{"batb":[[0,1.69,7.78],[1,1.65,59.6],[2,1.25,100]],"ltp":1.65,"tv":4.0,"id":31372}]}]}
{"op":"mcm","clk":"11824761979","pt":1723469924679,"mc":[{"id":"1.231699634","rc":[{"batb":[[0,1.7,10],[1,1.69,7.78],[2,1.65,59.6]],"ltp":1.65,"tv":4.0,"id":31372}]}]}
{"op":"mcm","clk":"11824762232","pt":1723469928054,"mc":[{"id":"1.231699634","rc":[{"batb":[[0,1.69,7.78],[1,1.65,59.6],[2,1.25,100]],"ltp":1.65,"tv":4.0,"id":31372}]}]}
{"op":"mcm","clk":"11824764342","pt":1723469955139,"mc":[{"id":"1.231699634","rc":[{"batb":[[0,1.7,10],[1,1.69,7.78],[2,1.65,59.6]],"ltp":1.65,"tv":4.0,"id":31372}]}]}
{"op":"mcm","clk":"11824764612","pt":1723469958806,"mc":[{"id":"1.231699634","rc":[{"batb":[[0,1.69,7.78],[1,1.65,59.6],[2,1.25,100]],"ltp":1.65,"tv":4.0,"id":31372}]}]}
{"op":"mcm","clk":"11824765610","pt":1723469970624,"mc":[{"id":"1.231699634","rc":[{"batb":[[0,1.7,10],[1,1.69,7.78],[2,1.65,59.6]],"ltp":1.65,"tv":4.0,"id":31372}]}]}
{"op":"mcm","clk":"11824765948","pt":1723469975322,"mc":[{"id":"1.231699634","rc":[{"batb":[[0,1.69,7.78],[1,1.65,59.6],[2,1.25,100]],"ltp":1.65,"tv":4.0,"id":31372}]}]}
