{"op":"mcm","clk":"11829161865","pt":1723376252028,"mc":[{"id":"1.231699683","marketDefinition":{"bspMarket":false,"turnInPlayEnabled":true,"persistenceEnabled":true,"marketBaseRate":5.0,"eventId":"33486073","eventTypeId":"4","numberOfWinners":1,"bettingType":"ODDS","marketType":"MATCH_ODDS","marketTime":"2024-08-14T10:00:00.000Z","suspendTime":"2024-08-14T10:00:00.000Z","bspReconciled":false,"complete":true,"inPlay":false,"crossMatching":false,"runnersVoidable":false,"numberOfActiveRunners":2,"betDelay":0,"status":"OPEN","runners":[{"status":"ACTIVE","sortPriority":1,"id":2120,"name":"Warwickshire"},{"status":"ACTIVE","sortPriority":2,"id":2780,"name":"Nottinghamshire"}],"regulators":["MR_INT"],"countryCode":"GB","discountAllowed":false,"timezone":"GMT","openDate":"2024-08-14T10:00:00.000Z","version":6069213938,"name":"Match Odds","eventName":"Warwickshire v Nottinghamshire"},"rc":[{"batb":[[0,1.03,200],[1,1.02,200],[2,1.01,220]],"ltp":0.0,"tv":0.0,"id":2780},{"batb":[[0,1.03,200],[1,1.02,200],[2,1.01,220]],"ltp":0.0,"tv":0.0,"id":2120}]}]}
{"op":"mcm","clk":"11829162066","pt":1723376253156,"mc":[{"id":"1.231699683","marketDefinition":{"bspMarket":false,"turnInPlayEnabled":true,"persistenceEnabled":true,"marketBaseRate":5.0,"eventId":"33486073","eventTypeId":"4","numberOfWinners":1,"bettingType":"ODDS","marketType":"MATCH_ODDS","marketTime":"2024-08-14T10:00:00.000Z","suspendTime":"2024-08-14T10:00:00.000Z","bspReconciled":false,"complete":true,"inPlay":false,"crossMatching":false,"runnersVoidable":false,"numberOfActiveRunners":2,"betDelay":0,"status":"OPEN","runners":[{"status":"ACTIVE","sortPriority":1,"id":2120,"name":"Warwickshire"},{"status":"ACTIVE","sortPriority":2,"id":2780,"name":"Nottinghamshire"}],"regulators":["MR_INT"],"countryCode":"GB","discountAllowed":true,"timezone":"GMT","openDate":"2024-08-14T10:00:00.000Z","version":6069213938,"name":"Match Odds","eventName":"Warwickshire v Nottinghamshire"}}]}
{"op":"mcm","clk":"11830662930","pt":1723384888994,"mc":[{"id":"1.231699683","rc":[{"batb":[[2,1.01,480.71]],"ltp":0.0,"tv":0.0,"id":2780},{"batb":[[2,1.01,480.71]],"ltp":0.0,"tv":0.0,"id":2120}]}]}
{"op":"mcm","clk":"11831382895","pt":1723389042472,"mc":[{"id":"1.231699683","rc":[{"batb":[[2,1.01,488.56]],"ltp":0.0,"tv":0.0,"id":2780},{"batb":[[2,1.01,488.56]],"ltp":0.0,"tv":0.0,"id":2120}]}]}
{"op":"mcm","clk":"11831385152","pt":1723389053660,"mc":[{"id":"1.231699683","rc":[{"batb":[[1,1.02,207.85]],"ltp":0.0,"tv":0.0,"id":2780},{"batb":[[1,1.02,207.85]],"ltp":0.0,"tv":0.0,"id":2120}]}]}
{"op":"mcm","clk":"11831387375","pt":1723389064318,"mc":[{"id":"1.231699683","marketDefinition":{"bspMarket":false,"turnInPlayEnabled":true,"persistenceEnabled":true,"marketBaseRate":5.0,"eventId":"33486073","eventTypeId":"4","numberOfWinners":1,"bettingType":"ODDS","marketType":"MATCH_ODDS","marketTime":"2024-08-14T10:00:00.000Z","suspendTime":"2024-08-14T10:00:00.000Z","bspReconciled":false,"complete":true,"inPlay":false,"crossMatching":true,"runnersVoidable":false,"numberOfActiveRunners":2,"betDelay":0,"status":"OPEN","runners":[{"status":"ACTIVE","sortPriority":1,"id":2120,"name":"Warwickshire"},{"status":"ACTIVE","sortPriority":2,"id":2780,"name":"Nottinghamshire"}],"regulators":["MR_INT"],"countryCode":"GB","discountAllowed":true,"timezone":"GMT","openDate":"2024-08-14T10:00:00.000Z","version":6069213938,"name":"Match Odds","eventName":"Warwickshire v Nottinghamshire"}}]}
{"op":"mcm","clk":"11831388133","pt":1723389068308,"mc":[{"id":"1.231699683","rc":[{"batb":[[1,1.02,247.13]],"ltp":0.0,"tv":0.0,"id":2780},{"batb":[[1,1.02,247.13]],"ltp":0.0,"tv":0.0,"id":2120}]}]}
{"op":"mcm","clk":"11831391445","pt":1723389084524,"mc":[{"id":"1.231699683","rc":[{"batb":[[0,1.03,207.85]],"ltp":0.0,"tv":0.0,"id":2780},{"batb":[[0,1.03,207.85]],"ltp":0.0,"tv":0.0,"id":2120}]}]}
{"op":"mcm","clk":"11831394088","pt":1723389097820,"mc":[{"id":"1.231699683","rc":[{"batb":[[0,1.04,7.85],[1,1.03,207.85],[2,1.02,247.13]],"ltp":0.0,"tv":0.0,"id":2780},{"batb":[[0,1.04,7.85],[1,1.03,207.85],[2,1.02,247.13]],"ltp":0.0,"tv":0.0,"id":2120}]}]}
{"op":"mcm","clk":"11831396506","pt":1723389110226,"mc":[{"id":"1.231699683","rc":[{"batb":[[0,1.05,7.85],[1,1.04,7.85],[2,1.03,207.85]],"ltp":0.0,"tv":0.0,"id":2780},{"batb":[[0,1.05,7.85],[1,1.04,7.85],[2,1.03,207.85]],"ltp":0.0,"tv":0.0,"id":2120}]}]}
{"op":"mcm","clk":"11831398936","pt":1723389122850,"mc":[{"id":"1.231699683","rc":[{"batb":[[0,1.06,7.85],[1,1.05,7.85],[2,1.04,7.85]],"ltp":0.0,"tv":0.0,"id":2780},{"batb":[[0,1.06,7.85],[1,1.05,7.85],[2,1.04,7.85]],"ltp":0.0,"tv":0.0,"id":2120}]}]}
{"op":"mcm","clk":"11831401231","pt":1723389135379,"mc":[{"id":"1.231699683","rc":[{"batb":[[0,1.07,7.85],[1,1.06,7.85],[2,1.05,7.85]],"ltp":0.0,"tv":0.0,"id":2780},{"batb":[[0,1.07,7.85],[1,1.06,7.85],[2,1.05,7.85]],"ltp":0.0,"tv":0.0,"id":2120}]}]}
{"op":"mcm","clk":"11831403785","pt":1723389147997,"mc":[{"id":"1.231699683","rc":[{"batb":[[0,1.08,7.85],[1,1.07,7.85],[2,1.06,7.85]],"ltp":0.0,"tv":0.0,"id":2780},{"batb":[[0,1.08,7.85],[1,1.07,7.85],[2,1.06,7.85]],"ltp":0.0,"tv":0.0,"id":2120}]}]}
{"op":"mcm","clk":"11832013716","pt":1723392491106,"mc":[{"id":"1.231699683","rc":[{"batb":[[0,1.09,95.53],[1,1.08,7.85],[2,1.07,7.85]],"ltp":0.0,"tv":0.0,"id":2780},{"batb":[[0,1.09,95.53],[1,1.08,7.85],[2,1.07,7.85]],"ltp":0.0,"tv":0.0,"id":2120}]}]}
{"op":"mcm","clk":"11832317523","pt":1723394293056,"mc":[{"id":"1.231699683","rc":[{"batb":[[0,1.08,7.85],[1,1.07,7.85],[2,1.06,7.85]],"ltp":0.0,"tv":0.0,"id":2780}]}]}
{"op":"mcm","clk":"11832317586","pt":1723394293432,"mc":[{"id":"1.231699683","rc":[{"batb":[[0,1.08,7.85],[1,1.07,7.85],[2,1.06,7.85]],"ltp":0.0,"tv":0.0,"id":2120}]}]}
{"op":"mcm","clk":"11832326587","pt":1723394344027,"mc":[{"id":"1.231699683","rc":[{"batb":[[0,1.09,95.53],[1,1.08,7.85],[2,1.07,7.85]],"ltp":0.0,"tv":0.0,"id":2780},{"batb":[[0,1.09,95.53],[1,1.08,7.85],[2,1.07,7.85]],"ltp":0.0,"tv":0.0,"id":2120}]}]}
{"op":"mcm","clk":"11832607998","pt":1723396146930,"mc":[{"id":"1.231699683","rc":[{"batb":[[0,1.08,7.85],[1,1.07,7.85],[2,1.06,7.85]],"ltp":0.0,"tv":0.0,"id":2780},{"batb":[[0,1.08,7.85],[1,1.07,7.85],[2,1.06,7.85]],"ltp":0.0,"tv":0.0,"id":2120}]}]}
{"op":"mcm","clk":"11832612720","pt":1723396178561,"mc":[{"id":"1.231699683","rc":[{"batb":[[0,1.09,95.53],[1,1.08,7.85],[2,1.07,7.85]],"ltp":0.0,"tv":0.0,"id":2780},{"batb":[[0,1.09,95.53],[1,1.08,7.85],[2,1.07,7.85]],"ltp":0.0,"tv":0.0,"id":2120}]}]}
{"op":"mcm","clk":"11832834783","pt":1723397762297,"mc":[{"id":"1.231699683","rc":[{"batb":[[0,1.25,100],[1,1.09,95.53],[2,1.08,7.85]],"ltp":0.0,"tv":0.0,"id":2780},{"batb":[[0,1.25,100],[1,1.09,95.53],[2,1.08,7.85]],"ltp":0.0,"tv":0.0,"id":2120}]}]}
{"op":"mcm","clk":"11832864150","pt":1723397980500,"mc":[{"id":"1.231699683","rc":[{"batb":[[1,1.08,7.85],[2,1.07,7.85]],"ltp":0.0,"tv":0.0,"id":2780},{"batb":[[1,1.08,7.85],[2,1.07,7.85]],"ltp":0.0,"tv":0.0,"id":2120}]}]}
{"op":"mcm","clk":"11832875388","pt":1723398056999,"mc":[{"id":"1.231699683","rc":[{"batb":[[0,1.26,33.07],[1,1.25,100],[2,1.08,7.85]],"ltp":0.0,"tv":0.0,"id":2780},{"batb":[[0,1.26,33.07],[1,1.25,100],[2,1.08,7.85]],"ltp":0.0,"tv":0.0,"id":2120}]}]}
{"op":"mcm","clk":"11832939253","pt":1723398496916,"mc":[{"id":"1.231699683","rc":[{"batb":[[0,1.27,6.51],[1,1.26,33.07],[2,1.25,100]],"ltp":0.0,"tv":0.0,"id":2120}]}]}
{"op":"mcm","clk":"11832939296","pt":1723398497226,"mc":[{"id":"1.231699683","rc":[{"batb":[[0,1.27,7.77],[1,1.26,33.07],[2,1.25,100]],"ltp":0.0,"tv":0.0,"id":2780}]}]}
{"op":"mcm","clk":"11832983239","pt":1723398814319,"mc":[{"id":"1.231699683","rc":[{"batb":[[0,2.26,3.19],[1,1.27,7.77],[2,1.26,33.07]],"ltp":0.0,"tv":0.0,"id":2780},{"batb":[[0,1.73,5.51],[1,1.27,6.51],[2,1.26,33.07]],"ltp":0.0,"tv":0.0,"id":2120}]}]}
{"op":"mcm","clk":"11833141291","pt":1723399857438,"mc":[{"id":"1.231699683","rc":[{"batb":[[2,1.25,100]],"ltp":0.0,"tv":0.0,"id":2780},{"batb":[[2,1.25,100]],"ltp":0.0,"tv":0.0,"id":2120}]}]}
{"op":"mcm","clk":"11833276654","pt":1723400619859,"mc":[{"id":"1.231699683","rc":[{"batb":[[1,1.25,100],[2,1.08,7.85]],"ltp":0.0,"tv":0.0,"id":2120}]}]}
{"op":"mcm","clk":"11833276703","pt":1723400620175,"mc":[{"id":"1.231699683","rc":[{"batb":[[1,1.25,100],[2,1.08,7.85]],"ltp":0.0,"tv":0.0,"id":2780}]}]}
{"op":"mcm","clk":"11834738702","pt":1723410774824,"mc":[{"id":"1.231699683","rc":[{"batb":[[2,1.08,7.83]],"ltp":0.0,"tv":0.0,"id":2780},{"batb":[[2,1.08,7.83]],"ltp":0.0,"tv":0.0,"id":2120}]}]}
{"op":"mcm","clk":"11835082033","pt":1723416174835,"mc":[{"id":"1.231699683","rc":[{"batb":[[2,1.08,7.84]],"ltp":0.0,"tv":0.0,"id":2780},{"batb":[[2,1.08,7.84]],"ltp":0.0,"tv":0.0,"id":2120}]}]}
{"op":"mcm","clk":"11835383989","pt":1723421574845,"mc":[{"id":"1.231699683","rc":[{"batb":[[2,1.08,7.84]],"ltp":0.0,"tv":0.0,"id":2780},{"batb":[[2,1.08,7.84]],"ltp":0.0,"tv":0.0,"id":2120}]}]}
{"op":"mcm","clk":"11835591412","pt":1723426974847,"mc":[{"id":"1.231699683","rc":[{"batb":[[2,1.08,7.84]],"ltp":0.0,"tv":0.0,"id":2780},{"batb":[[2,1.08,7.84]],"ltp":0.0,"tv":0.0,"id":2120}]}]}
{"op":"mcm","clk":"11835765929","pt":1723432374844,"mc":[{"id":"1.231699683","rc":[{"batb":[[2,1.08,7.84]],"ltp":0.0,"tv":0.0,"id":2780},{"batb":[[2,1.08,7.84]],"ltp":0.0,"tv":0.0,"id":2120}]}]}
{"op":"mcm","clk":"11835944393","pt":1723437774831,"mc":[{"id":"1.231699683","rc":[{"batb":[[2,1.08,7.84]],"ltp":0.0,"tv":0.0,"id":2780},{"batb":[[2,1.08,7.84]],"ltp":0.0,"tv":0.0,"id":2120}]}]}
{"op":"mcm","clk":"11836105136","pt":1723443174824,"mc":[{"id":"1.231699683","rc":[{"batb":[[2,1.08,7.83]],"ltp":0.0,"tv":0.0,"id":2780},{"batb":[[2,1.08,7.83]],"ltp":0.0,"tv":0.0,"id":2120}]}]}
{"op":"mcm","clk":"11836279716","pt":1723448574836,"mc":[{"id":"1.231699683","rc":[{"batb":[[2,1.08,7.83]],"ltp":0.0,"tv":0.0,"id":2780},{"batb":[[2,1.08,7.83]],"ltp":0.0,"tv":0.0,"id":2120}]}]}
{"op":"mcm","clk":"11836433699","pt":1723453974833,"mc":[{"id":"1.231699683","rc":[{"batb":[[2,1.08,7.83]],"ltp":0.0,"tv":0.0,"id":2780},{"batb":[[2,1.08,7.83]],"ltp":0.0,"tv":0.0,"id":2120}]}]}
{"op":"mcm","clk":"11836494148","pt":1723456102014,"mc":[{"id":"1.231699683","rc":[{"batb":[[0,1.53,155.56]],"ltp":0.0,"tv":0.0,"id":2780},{"batb":[[0,1.26,189.55]],"ltp":0.0,"tv":0.0,"id":2120}]}]}
{"op":"mcm","clk":"11836496450","pt":1723456173400,"mc":[{"id":"1.231699683","rc":[{"batb":[[0,1.54,15.92],[1,1.53,155.56],[2,1.25,100]],"ltp":0.0,"tv":0.0,"id":2780},{"batb":[[0,1.27,31.85],[1,1.26,189.55],[2,1.25,100]],"ltp":0.0,"tv":0.0,"id":2120}]}]}
{"op":"mcm","clk":"11836526356","pt":1723456989078,"mc":[{"id":"1.231699683","rc":[{"batb":[[0,1.58,150.57],[1,1.54,23.62]],"ltp":0.0,"tv":0.0,"id":2780},{"batb":[[0,1.3,183.62],[1,1.28,6.5],[2,1.27,31.87]],"ltp":0.0,"tv":0.0,"id":2120}]}]}
{"op":"mcm","clk":"11836535108","pt":1723457233083,"mc":[{"id":"1.231699683","rc":[{"batb":[[0,1.54,23.62],[1,1.25,100],[2,1.08,7.84]],"ltp":0.0,"tv":0.0,"id":2780}]}]}
{"op":"mcm","clk":"11836535114","pt":1723457233185,"mc":[{"id":"1.231699683","rc":[{"batb":[[0,1.59,147.39],[1,1.54,23.62],[2,1.25,100]],"ltp":0.0,"tv":0.0,"id":2780}]}]}
{"op":"mcm","clk":"11836535313","pt":1723457235928,"mc":[{"id":"1.231699683","rc":[{"batb":[[0,1.65,146.29]],"ltp":0.0,"tv":0.0,"id":2780}]}]}
{"op":"mcm","clk":"11836544306","pt":1723457464706,"mc":[{"id":"1.231699683","rc":[{"batb":[[0,2.26,32.24],[1,1.65,146.29],[2,1.54,23.62]],"ltp":0.0,"tv":0.0,"id":2780},{"batb":[[0,1.73,55.65],[1,1.3,183.62],[2,1.28,6.5]],"ltp":0.0,"tv":0.0,"id":2120}]}]}
{"op":"mcm","clk":"11836563520","pt":1723457973960,"mc":[{"id":"1.231699683","rc":[{"batb":[[1,1.54,7.68],[2,1.25,100]],"ltp":0.0,"tv":0.0,"id":2780},{"batb":[[1,1.28,6.5],[2,1.25,100]],"ltp":0.0,"tv":0.0,"id":2120}]}]}
{"op":"mcm","clk":"11836584437","pt":1723458649911,"mc":[{"id":"1.231699683","rc":[{"batb":[[1,1.25,100],[2,1.08,7.84]],"ltp":0.0,"tv":0.0,"id":2120}]}]}
{"op":"mcm","clk":"11836584454","pt":1723458650268,"mc":[{"id":"1.231699683","rc":[{"batb":[[1,1.25,100],[2,1.08,7.84]],"ltp":0.0,"tv":0.0,"id":2780}]}]}
{"op":"mcm","clk":"11836668604","pt":1723460678020,"mc":[{"id":"1.231699683","rc":[{"trd":[[1.73,4]],"batb":[[0,1.73,53.65]],"ltp":1.73,"tv":4.0,"id":2120}],"tv":4.0}]}
{"op":"mcm","clk":"11836668655","pt":1723460679905,"mc":[{"id":"1.231699683","rc":[{"batb":[[0,1.73,55.65]],"ltp":1.73,"tv":4.0,"id":2120}]}]}
{"op":"mcm","clk":"11836794082","pt":1723464774834,"mc":[{"id":"1.231699683","rc":[{"batb":[[2,1.08,7.83]],"ltp":0.0,"tv":0.0,"id":2780},{"batb":[[2,1.08,7.83]],"ltp":1.73,"tv":4.0,"id":2120}]}]}
{"op":"mcm","clk":"11836866417","pt":1723467044011,"mc":[{"id":"1.231699683","rc":[{"batb":[[1,1.08,7.83],[2,1.07,7.83]],"ltp":0.0,"tv":0.0,"id":2780},{"batb":[[1,1.08,7.83],[2,1.07,7.83]],"ltp":1.73,"tv":4.0,"id":2120}]}]}
{"op":"mcm","clk":"11836876261","pt":1723467389451,"mc":[{"id":"1.231699683","rc":[{"batb":[[1,1.3,1166.67],[2,1.08,7.83]],"ltp":0.0,"tv":0.0,"id":2780},{"batb":[[1,1.3,1166.67],[2,1.08,7.83]],"ltp":1.73,"tv":4.0,"id":2120}]}]}
{"op":"mcm","clk":"11836878086","pt":1723467458079,"mc":[{"id":"1.231699683","rc":[{"batb":[[1,1.08,7.83],[2,1.07,7.83]],"ltp":0.0,"tv":0.0,"id":2780},{"batb":[[1,1.08,7.83],[2,1.07,7.83]],"ltp":1.73,"tv":4.0,"id":2120}]}]}
{"op":"mcm","clk":"11836878803","pt":1723467485715,"mc":[{"id":"1.231699683","rc":[{"batb":[[1,1.25,100],[2,1.08,7.83]],"ltp":0.0,"tv":0.0,"id":2780},{"batb":[[1,1.25,100],[2,1.08,7.83]],"ltp":1.73,"tv":4.0,"id":2120}]}]}
{"op":"mcm","clk":"11836902480","pt":1723468384033,"mc":[{"id":"1.231699683","rc":[{"batb":[[2,1.08,7.83]],"ltp":0.0,"tv":0.0,"id":2780},{"trd":[[1.73,114]],"batb":[[0,1.28,190.62],[2,1.08,7.83]],"ltp":1.73,"tv":114.0,"id":2120}],"tv":114.0}]}
{"op":"mcm","clk":"11836902527","pt":1723468385532,"mc":[{"id":"1.231699683","rc":[{"batb":[[0,1.69,58.87],[1,1.28,189.97],[2,1.25,100]],"ltp":1.73,"tv":114.0,"id":2120}]}]}
{"op":"mcm","clk":"11836910877","pt":1723468672072,"mc":[{"id":"1.231699683","rc":[{"trd":[[1.69,116]],"batb":[[0,1.65,62.5]],"ltp":1.69,"tv":230.0,"id":2120}],"tv":230.0}]}
{"op":"mcm","clk":"11836914428","pt":1723468773978,"mc":[{"id":"1.231699683","rc":[{"batl":[[0,1.75,175]],"ltp":1.69,"tv":230.0,"id":2120}]}]}
{"op":"mcm","clk":"11836914431","pt":1723468774182,"mc":[{"id":"1.231699683","rc":[{"batb":[[1,1.25,100],[2,1.08,7.83]],"ltp":1.69,"tv":230.0,"id":2120}]}]}
{"op":"mcm","clk":"11836914640","pt":1723468780195,"mc":[{"id":"1.231699683","rc":[{"batl":[[0,1.75,200]],"ltp":1.69,"tv":230.0,"id":2120}]}]}
{"op":"mcm","clk":"11836939002","pt":1723469500873,"mc":[{"id":"1.231699683","rc":[{"batl":[[0,1.74,9.82],[1,1.75,200]],"ltp":1.69,"tv":230.0,"id":2120}]}]}
{"op":"mcm","clk":"11836946141","pt":1723469715459,"mc":[{"id":"1.231699683","rc":[{"batb":[[0,2.26,30.75]],"ltp":0.0,"tv":0.0,"id":2780},{"batb":[[0,1.65,59.6]],"ltp":1.69,"tv":230.0,"id":2120}]}]}
{"op":"mcm","clk":"11836960424","pt":1723470162492,"mc":[{"id":"1.231699683","rc":[{"batb":[[0,2.34,7.77],[1,2.26,30.75],[2,1.25,100]],"ltp":0.0,"tv":0.0,"id":2780}]}]}
{"op":"mcm","clk":"11837161119","pt":1723475574834,"mc":[{"id":"1.231699683","rc":[{"batb":[[0,2.34,7.76]],"ltp":0.0,"tv":0.0,"id":2780},{"batb":[[2,1.08,7.82]],"batl":[[0,1.74,9.81]],"ltp":1.69,"tv":230.0,"id":2120}]}]}
{"op":"mcm","clk":"11837185191","pt":1723476035047,"mc":[{"id":"1.231699683","rc":[{"batb":[[0,2.26,30.75],[1,1.25,100],[2,1.08,7.82]],"ltp":0.0,"tv":0.0,"id":2780},{"batl":[[0,1.73,200],[1,1.75,0]],"ltp":1.69,"tv":230.0,"id":2120}]}]}
{"op":"mcm","clk":"11837216742","pt":1723476762428,"mc":[{"id":"1.231699683","rc":[{"batl":[[0,1.72,9.82],[1,1.73,200]],"ltp":1.69,"tv":230.0,"id":2120}]}]}
{"op":"mcm","clk":"11837244000","pt":1723477416076,"mc":[{"id":"1.231699683","rc":[{"batb":[[0,2.38,7.55],[1,2.26,30.75],[2,1.25,100]],"ltp":0.0,"tv":0.0,"id":2780}]}]}
{"op":"mcm","clk":"11837425078","pt":1723480974827,"mc":[{"id":"1.231699683","rc":[{"batb":[[0,2.38,7.55]],"ltp":0.0,"tv":0.0,"id":2780},{"batb":[[2,1.08,7.83]],"batl":[[0,1.72,9.83]],"ltp":1.69,"tv":230.0,"id":2120}]}]}
{"op":"mcm","clk":"11837808379","pt":1723486374822,"mc":[{"id":"1.231699683","rc":[{"batb":[[0,2.38,7.56]],"ltp":0.0,"tv":0.0,"id":2780},{"batb":[[2,1.08,7.83]],"batl":[[0,1.72,9.84]],"ltp":1.69,"tv":230.0,"id":2120}]}]}
{"op":"mcm","clk":"11837908432","pt":1723487342908,"mc":[{"id":"1.231699683","rc":[{"batb":[[1,2.34,28.91]],"ltp":0.0,"tv":0.0,"id":2780},{"batb":[[0,1.68,56.97]],"ltp":1.69,"tv":230.0,"id":2120}]}]}
{"op":"mcm","clk":"11838260207","pt":1723491774817,"mc":[{"id":"1.231699683","rc":[{"batb":[[0,2.38,7.56]],"ltp":0.0,"tv":0.0,"id":2780},{"batb":[[2,1.08,7.83]],"batl":[[0,1.72,9.83]],"ltp":1.69,"tv":230.0,"id":2120}]}]}
{"op":"mcm","clk":"11838371435","pt":1723493946657,"mc":[{"id":"1.231699683","rc":[{"batb":[[0,2.38,7.56]],"ltp":0.0,"tv":0.0,"id":2780},{"trd":[[1.68,112]],"batb":[[0,1.26,197.94]],"batl":[[0,1.72,9.84]],"ltp":1.68,"tv":342.0,"id":2120}],"tv":342.0}]}
{"op":"mcm","clk":"11838371563","pt":1723493950144,"mc":[{"id":"1.231699683","rc":[{"batb":[[0,1.64,60.53],[1,1.26,196.97],[2,1.25,100]],"ltp":1.68,"tv":342.0,"id":2120}]}]}
{"op":"mcm","clk":"11838484974","pt":1723497097752,"mc":[{"id":"1.231699683","rc":[{"batb":[[0,2.38,7.56]],"ltp":0.0,"tv":0.0,"id":2780},{"trd":[[1.64,62]],"batb":[[0,1.64,29.53],[1,1.25,100],[2,1.08,7.83]],"batl":[[0,1.72,9.84]],"ltp":1.64,"tv":404.0,"id":2120}],"tv":404.0}]}
{"op":"mcm","clk":"11838485063","pt":1723497100568,"mc":[{"id":"1.231699683","rc":[{"batb":[[0,1.64,34.2]],"ltp":1.64,"tv":404.0,"id":2120}]}]}
{"op":"mcm","clk":"11838728823","pt":1723502574821,"mc":[{"id":"1.231699683","rc":[{"batb":[[0,2.38,7.56]],"ltp":0.0,"tv":0.0,"id":2780},{"batb":[[2,1.08,7.83]],"batl":[[0,1.72,9.84]],"ltp":1.64,"tv":404.0,"id":2120}]}]}
{"op":"mcm","clk":"11839065193","pt":1723507974890,"mc":[{"id":"1.231699683","rc":[{"batb":[[0,2.38,7.56]],"ltp":0.0,"tv":0.0,"id":2780},{"batb":[[2,1.08,7.83]],"batl":[[0,1.72,9.84]],"ltp":1.64,"tv":404.0,"id":2120}]}]}
{"op":"mcm","clk":"11839269741","pt":1723513374881,"mc":[{"id":"1.231699683","rc":[{"batb":[[0,2.38,7.56]],"ltp":0.0,"tv":0.0,"id":2780},{"batb":[[2,1.08,7.83]],"batl":[[0,1.72,9.84]],"ltp":1.64,"tv":404.0,"id":2120}]}]}
{"op":"mcm","clk":"11839446392","pt":1723518774893,"mc":[{"id":"1.231699683","rc":[{"batb":[[2,1.08,7.83]],"ltp":1.64,"tv":404.0,"id":2120}]}]}
{"op":"mcm","clk":"11839591349","pt":1723524174890,"mc":[{"id":"1.231699683","rc":[{"batb":[[2,1.08,7.83]],"ltp":1.64,"tv":404.0,"id":2120}]}]}
{"op":"mcm","clk":"11839783477","pt":1723529574888,"mc":[{"id":"1.231699683","rc":[{"batb":[[0,2.38,7.56]],"ltp":0.0,"tv":0.0,"id":2780},{"batb":[[2,1.08,7.83]],"batl":[[0,1.72,9.84]],"ltp":1.64,"tv":404.0,"id":2120}]}]}
{"op":"mcm","clk":"11839841720","pt":1723531095464,"mc":[{"id":"1.231699683","rc":[{"trd":[[2.38,4.3]],"batb":[[0,2.38,5.41]],"ltp":2.38,"tv":4.29,"id":2780}],"tv":408.29}]}
{"op":"mcm","clk":"11839950182","pt":1723534974853,"mc":[{"id":"1.231699683","rc":[{"trd":[[2.38,4.29]],"batb":[[0,2.38,5.4]],"ltp":2.38,"tv":4.29,"id":2780},{"batb":[[2,1.08,7.81]],"batl":[[0,1.72,9.81]],"ltp":1.64,"tv":404.0,"id":2120}],"tv":408.29}]}
{"op":"mcm","clk":"11840125814","pt":1723540374835,"mc":[{"id":"1.231699683","rc":[{"trd":[[2.38,4.29]],"batb":[[0,2.38,5.39]],"ltp":2.38,"tv":4.29,"id":2780},{"batb":[[2,1.08,7.81]],"batl":[[0,1.72,9.81]],"ltp":1.64,"tv":404.0,"id":2120}],"tv":408.29}]}
{"op":"mcm","clk":"11840396006","pt":1723545774828,"mc":[{"id":"1.231699683","rc":[{"batb":[[2,1.08,7.82]],"batl":[[0,1.72,9.81]],"ltp":1.64,"tv":404.0,"id":2120}]}]}
{"op":"mcm","clk":"11840436345","pt":1723546450515,"mc":[{"id":"1.231699683","rc":[{"batl":[[0,2.58,1]],"ltp":2.38,"tv":4.29,"id":2780}]}]}
{"op":"mcm","clk":"11840453361","pt":1723546802515,"mc":[{"id":"1.231699683","rc":[{"batb":[[0,2.4,10],[1,2.38,5.39],[2,2.34,28.91]],"ltp":2.38,"tv":4.29,"id":2780}]}]}
{"op":"mcm","clk":"11840453617","pt":1723546806105,"mc":[{"id":"1.231699683","rc":[{"trd":[[2.38,4.29]],"batb":[[0,2.38,5.4],[1,2.34,28.91],[2,1.25,100]],"ltp":2.38,"tv":4.29,"id":2780},{"batb":[[2,1.08,7.82]],"batl":[[0,1.72,9.82]],"ltp":1.64,"tv":404.0,"id":2120}],"tv":408.29}]}
{"op":"mcm","clk":"11840453762","pt":1723546808326,"mc":[{"id":"1.231699683","rc":[{"batb":[[0,2.4,10],[1,2.38,5.4],[2,2.34,28.91]],"ltp":2.38,"tv":4.29,"id":2780}]}]}
{"op":"mcm","clk":"11840453990","pt":1723546811801,"mc":[{"id":"1.231699683","rc":[{"batb":[[0,2.38,5.4],[1,2.34,28.91],[2,1.25,100]],"ltp":2.38,"tv":4.29,"id":2780}]}]}
{"op":"mcm","clk":"11840454205","pt":1723546815228,"mc":[{"id":"1.231699683","rc":[{"batb":[[0,2.4,10],[1,2.38,5.4],[2,2.34,28.91]],"ltp":2.38,"tv":4.29,"id":2780}]}]}
{"op":"mcm","clk":"11840454429","pt":1723546818527,"mc":[{"id":"1.231699683","rc":[{"batb":[[0,2.38,5.4],[1,2.34,28.91],[2,1.25,100]],"ltp":2.38,"tv":4.29,"id":2780}]}]}
{"op":"mcm","clk":"11840454812","pt":1723546824623,"mc":[{"id":"1.231699683","rc":[{"batb":[[0,2.4,10],[1,2.38,5.4],[2,2.34,28.91]],"ltp":2.38,"tv":4.29,"id":2780}]}]}
{"op":"mcm","clk":"11840455020","pt":1723546828039,"mc":[{"id":"1.231699683","rc":[{"batb":[[0,2.38,5.4],[1,2.34,28.91],[2,1.25,100]],"ltp":2.38,"tv":4.29,"id":2780}]}]}
{"op":"mcm","clk":"11840455368","pt":1723546833259,"mc":[{"id":"1.231699683","rc":[{"batb":[[0,2.4,10],[1,2.38,5.4],[2,2.34,28.91]],"ltp":2.38,"tv":4.29,"id":2780}]}]}
{"op":"mcm","clk":"11840455671","pt":1723546837035,"mc":[{"id":"1.231699683","rc":[{"batb":[[0,2.38,5.4],[1,2.34,28.91],[2,1.25,100]],"ltp":2.38,"tv":4.29,"id":2780}]}]}
{"op":"mcm","clk":"11840456029","pt":1723546842373,"mc":[{"id":"1.231699683","rc":[{"batb":[[0,2.4,10],[1,2.38,5.4],[2,2.34,28.91]],"ltp":2.38,"tv":4.29,"id":2780}]}]}
{"op":"mcm","clk":"11840456210","pt":1723546845633,"mc":[{"id":"1.231699683","rc":[{"batb":[[0,2.38,5.4],[1,2.34,28.91],[2,1.25,100]],"ltp":2.38,"tv":4.29,"id":2780}]}]}
{"op":"mcm","clk":"11840456500","pt":1723546849462,"mc":[{"id":"1.231699683","rc":[{"batb":[[0,2.4,10],[1,2.38,5.4],[2,2.34,28.91]],"ltp":2.38,"tv":4.29,"id":2780}]}]}
{"op":"mcm","clk":"11840456690","pt":1723546852977,"mc":[{"id":"1.231699683","rc":[{"batb":[[0,2.38,5.4],[1,2.34,28.91],[2,1.25,100]],"ltp":2.38,"tv":4.29,"id":2780}]}]}
{"op":"mcm","clk":"11840456891","pt":1723546856543,"mc":[{"id":"1.231699683","rc":[{"batb":[[0,2.4,10],[1,2.38,5.4],[2,2.34,28.91]],"ltp":2.38,"tv":4.29,"id":2780}]}]}
{"op":"mcm","clk":"11840457080","pt":1723546859861,"mc":[{"id":"1.231699683","rc":[{"batb":[[0,2.38,5.4],[1,2.34,28.91],[2,1.25,100]],"ltp":2.38,"tv":4.29,"id":2780}]}]}
{"op":"mcm","clk":"11840457393","pt":1723546865280,"mc":[{"id":"1.231699683","rc":[{"batb":[[0,2.4,10],[1,2.38,5.4],[2,2.34,28.91]],"ltp":2.38,"tv":4.29,"id":2780}]}]}
{"op":"mcm","clk":"11840457578","pt":1723546868584,"mc":[{"id":"1.231699683","rc":[{"batb":[[0,2.38,5.4],[1,2.34,28.91],[2,1.25,100]],"ltp":2.38,"tv":4.29,"id":2780}]}]}
{"op":"mcm","clk":"11840457801","pt":1723546872975,"mc":[{"id":"1.231699683","rc":[{"batb":[[0,2.4,10],[1,2.38,5.4],[2,2.34,28.91]],"ltp":2.38,"tv":4.29,"id":2780}]}]}
{"op":"mcm","clk":"11840457953","pt":1723546876266,"mc":[{"id":"1.231699683","rc":[{"batb":[[0,2.38,5.4],[1,2.34,28.91],[2,1.25,100]],"ltp":2.38,"tv":4.29,"id":2780}]}]}
{"op":"mcm","clk":"11840458378","pt":1723546884589,"mc":[{"id":"1.231699683","rc":[{"batb":[[0,2.4,10],[1,2.38,5.4],[2,2.34,28.91]],"ltp":2.38,"tv":4.29,"id":2780}]}]}
{"op":"mcm","clk":"11840458532","pt":1723546887885,"mc":[{"id":"1.231699683","rc":[{"batb":[[0,2.38,5.4],[1,2.34,28.91],[2,1.25,100]],"ltp":2.38,"tv":4.29,"id":2780}]}]}
{"op":"mcm","clk":"11840458855","pt":1723546894577,"mc":[{"id":"1.231699683","rc":[{"batb":[[0,2.4,10],[1,2.38,5.4],[2,2.34,28.91]],"ltp":2.38,"tv":4.29,"id":2780}]}]}
{"op":"mcm","clk":"11840459006","pt":1723546897918,"mc":[{"id":"1.231699683","rc":[{"batb":[[0,2.38,5.4],[1,2.34,28.91],[2,1.25,100]],"ltp":2.38,"tv":4.29,"id":2780}]}]}
{"op":"mcm","clk":"11840459104","pt":1723546900188,"mc":[{"id":"1.231699683","rc":[{"batb":[[0,2.4,10],[1,2.38,5.4],[2,2.34,28.91]],"ltp":2.38,"tv":4.29,"id":2780}]}]}
{"op":"mcm","clk":"11840459224","pt":1723546903529,"mc":[{"id":"1.231699683","rc":[{"batb":[[0,2.38,5.4],[1,2.34,28.91],[2,1.25,100]],"ltp":2.38,"tv":4.29,"id":2780}]}]}
{"op":"mcm","clk":"11840459399","pt":1723546907737,"mc":[{"id":"1.231699683","rc":[{"batb":[[0,2.4,10],[1,2.38,5.4],[2,2.34,28.91]],"ltp":2.38,"tv":4.29,"id":2780}]}]}
{"op":"mcm","clk":"11840459525","pt":1723546911122,"mc":[{"id":"1.231699683","rc":[{"batb":[[0,2.38,5.4],[1,2.34,28.91],[2,1.25,100]],"ltp":2.38,"tv":4.29,"id":2780}]}]}
{"op":"mcm","clk":"11840459634","pt":1723546913942,"mc":[{"id":"1.231699683","rc":[{"batb":[[0,2.4,10],[1,2.38,5.4],[2,2.34,28.91]],"ltp":2.38,"tv":4.29,"id":2780}]}]}
{"op":"mcm","clk":"11840459801","pt":1723546917449,"mc":[{"id":"1.231699683","rc":[{"batb":[[0,2.38,5.4],[1,2.34,28.91],[2,1.25,100]],"ltp":2.38,"tv":4.29,"id":2780}]}]}
{"op":"mcm","clk":"11840459968","pt":1723546921818,"mc":[{"id":"1.231699683","rc":[{"batb":[[0,2.4,10],[1,2.38,5.4],[2,2.34,28.91]],"ltp":2.38,"tv":4.29,"id":2780}]}]}
{"op":"mcm","clk":"11840460160","pt":1723546926238,"mc":[{"id":"1.231699683","rc":[{"batb":[[0,2.38,5.4],[1,2.34,28.91],[2,1.25,100]],"ltp":2.38,"tv":4.29,"id":2780}]}]}
{"op":"mcm","clk":"11840460368","pt":1723546931837,"mc":[{"id":"1.231699683","rc":[{"batb":[[0,2.4,10],[1,2.38,5.4],[2,2.34,28.91]],"ltp":2.38,"tv":4.29,"id":2780}]}]}
{"op":"mcm","clk":"11840460505","pt":1723546935431,"mc":[{"id":"1.231699683","rc":[{"batb":[[0,2.38,5.4],[1,2.34,28.91],[2,1.25,100]],"ltp":2.38,"tv":4.29,"id":2780}]}]}
{"op":"mcm","clk":"11840460768","pt":1723546942979,"mc":[{"id":"1.231699683","rc":[{"batb":[[0,2.4,10],[1,2.38,5.4],[2,2.34,28.91]],"ltp":2.38,"tv":4.29,"id":2780}]}]}
{"op":"mcm","clk":"11840460930","pt":1723546946571,"mc":[{"id":"1.231699683","rc":[{"batb":[[0,2.38,5.4],[1,2.34,28.91],[2,1.25,100]],"ltp":2.38,"tv":4.29,"id":2780}]}]}
{"op":"mcm","clk":"11840461378","pt":1723546957171,"mc":[{"id":"1.231699683","rc":[{"batb":[[0,2.4,10],[1,2.38,5.4],[2,2.34,28.91]],"ltp":2.38,"tv":4.29,"id":2780}]}]}
{"op":"mcm","clk":"11840461517","pt":1723546960667,"mc":[{"id":"1.231699683","rc":[{"batb":[[0,2.38,5.4],[1,2.34,28.91],[2,1.25,100]],"ltp":2.38,"tv":4.29,"id":2780}]}]}
{"op":"mcm","clk":"11840461764","pt":1723546966796,"mc":[{"id":"1.231699683","rc":[{"batb":[[0,2.4,10],[1,2.38,5.4],[2,2.34,28.91]],"ltp":2.38,"tv":4.29,"id":2780}]}]}
{"op":"mcm","clk":"11840461898","pt":1723546970095,"mc":[{"id":"1.231699683","rc":[{"batb":[[0,2.38,5.4],[1,2.34,28.91],[2,1.25,100]],"ltp":2.38,"tv":4.29,"id":2780}]}]}
{"op":"mcm","clk":"11840462142","pt":1723546976210,"mc":[{"id":"1.231699683","rc":[{"batb":[[0,2.4,10],[1,2.38,5.4],[2,2.34,28.91]],"ltp":2.38,"tv":4.29,"id":2780}]}]}
{"op":"mcm","clk":"11840462305","pt":1723546979739,"mc":[{"id":"1.231699683","rc":[{"batb":[[0,2.38,5.4],[1,2.34,28.91],[2,1.25,100]],"ltp":2.38,"tv":4.29,"id":2780}]}]}
{"op":"mcm","clk":"11840462447","pt":1723546982212,"mc":[{"id":"1.231699683","rc":[{"batb":[[0,2.4,10],[1,2.38,5.4],[2,2.34,28.91]],"ltp":2.38,"tv":4.29,"id":2780}]}]}
{"op":"mcm","clk":"11840462654","pt":1723546986012,"mc":[{"id":"1.231699683","rc":[{"batb":[[0,2.38,5.4],[1,2.34,28.91],[2,1.25,100]],"ltp":2.38,"tv":4.29,"id":2780}]}]}
{"op":"mcm","clk":"11840462770","pt":1723546988730,"mc":[{"id":"1.231699683","rc":[{"batb":[[0,2.4,10],[1,2.38,5.4],[2,2.34,28.91]],"ltp":2.38,"tv":4.29,"id":2780}]}]}
{"op":"mcm","clk":"11840462889","pt":1723546992018,"mc":[{"id":"1.231699683","rc":[{"batb":[[0,2.38,5.4],[1,2.34,28.91],[2,1.25,100]],"ltp":2.38,"tv":4.29,"id":2780}]}]}
{"op":"mcm","clk":"11840463447","pt":1723547000590,"mc":[{"id":"1.231699683","rc":[{"batb":[[0,2.4,10],[1,2.38,5.4],[2,2.34,28.91]],"ltp":2.38,"tv":4.29,"id":2780}]}]}
{"op":"mcm","clk":"11840463603","pt":1723547004184,"mc":[{"id":"1.231699683","rc":[{"batb":[[0,2.38,5.4],[1,2.34,28.91],[2,1.25,100]],"ltp":2.38,"tv":4.29,"id":2780}]}]}
{"op":"mcm","clk":"11840463754","pt":1723547007180,"mc":[{"id":"1.231699683","rc":[{"batb":[[0,2.4,10],[1,2.38,5.4],[2,2.34,28.91]],"ltp":2.38,"tv":4.29,"id":2780}]}]}
{"op":"mcm","clk":"11840463931","pt":1723547010783,"mc":[{"id":"1.231699683","rc":[{"batb":[[0,2.38,5.4],[1,2.34,28.91],[2,1.25,100]],"ltp":2.38,"tv":4.29,"id":2780}]}]}
{"op":"mcm","clk":"11840464161","pt":1723547016129,"mc":[{"id":"1.231699683","rc":[{"batb":[[0,2.4,10],[1,2.38,5.4],[2,2.34,28.91]],"ltp":2.38,"tv":4.29,"id":2780}]}]}
{"op":"mcm","clk":"11840464276","pt":1723547019522,"mc":[{"id":"1.231699683","rc":[{"batb":[[0,2.38,5.4],[1,2.34,28.91],[2,1.25,100]],"ltp":2.38,"tv":4.29,"id":2780}]}]}
{"op":"mcm","clk":"11840464613","pt":1723547026332,"mc":[{"id":"1.231699683","rc":[{"batb":[[0,2.4,10],[1,2.38,5.4],[2,2.34,28.91]],"ltp":2.38,"tv":4.29,"id":2780}]}]}
{"op":"mcm","clk":"11840464760","pt":1723547029929,"mc":[{"id":"1.231699683","rc":[{"batb":[[0,2.38,5.4],[1,2.34,28.91],[2,1.25,100]],"ltp":2.38,"tv":4.29,"id":2780}]}]}
{"op":"mcm","clk":"11840465007","pt":1723547036317,"mc":[{"id":"1.231699683","rc":[{"batb":[[0,2.4,10],[1,2.38,5.4],[2,2.34,28.91]],"ltp":2.38,"tv":4.29,"id":2780}]}]}
{"op":"mcm","clk":"11840465157","pt":1723547039615,"mc":[{"id":"1.231699683","rc":[{"batb":[[0,2.38,5.4],[1,2.34,28.91],[2,1.25,100]],"ltp":2.38,"tv":4.29,"id":2780}]}]}
{"op":"mcm","clk":"11840465310","pt":1723547042966,"mc":[{"id":"1.231699683","rc":[{"batb":[[0,2.4,10],[1,2.38,5.4],[2,2.34,28.91]],"ltp":2.38,"tv":4.29,"id":2780}]}]}
{"op":"mcm","clk":"11840465459","pt":1723547046372,"mc":[{"id":"1.231699683","rc":[{"batb":[[0,2.38,5.4],[1,2.34,28.91],[2,1.25,100]],"ltp":2.38,"tv":4.29,"id":2780}]}]}
{"op":"mcm","clk":"11840465578","pt":1723547049369,"mc":[{"id":"1.231699683","rc":[{"batb":[[0,2.4,10],[1,2.38,5.4],[2,2.34,28.91]],"ltp":2.38,"tv":4.29,"id":2780}]}]}
{"op":"mcm","clk":"11840465714","pt":1723547052872,"mc":[{"id":"1.231699683","rc":[{"batb":[[0,2.38,5.4],[1,2.34,28.91],[2,1.25,100]],"ltp":2.38,"tv":4.29,"id":2780}]}]}
{"op":"mcm","clk":"11840465886","pt":1723547056428,"mc":[{"id":"1.231699683","rc":[{"batb":[[0,2.4,10],[1,2.38,5.4],[2,2.34,28.91]],"ltp":2.38,"tv":4.29,"id":2780}]}]}
{"op":"mcm","clk":"11840466036","pt":1723547059832,"mc":[{"id":"1.231699683","rc":[{"batb":[[0,2.38,5.4],[1,2.34,28.91],[2,1.25,100]],"ltp":2.38,"tv":4.29,"id":2780}]}]}
{"op":"mcm","clk":"11840466153","pt":1723547062364,"mc":[{"id":"1.231699683","rc":[{"batb":[[0,2.4,10],[1,2.38,5.4],[2,2.34,28.91]],"ltp":2.38,"tv":4.29,"id":2780}]}]}
{"op":"mcm","clk":"11840466329","pt":1723547065763,"mc":[{"id":"1.231699683","rc":[{"batb":[[0,2.38,5.4],[1,2.34,28.91],[2,1.25,100]],"ltp":2.38,"tv":4.29,"id":2780}]}]}
{"op":"mcm","clk":"11840466478","pt":1723547068748,"mc":[{"id":"1.231699683","rc":[{"batb":[[0,2.4,10],[1,2.38,5.4],[2,2.34,28.91]],"ltp":2.38,"tv":4.29,"id":2780}]}]}
{"op":"mcm","clk":"11840466632","pt":1723547072153,"mc":[{"id":"1.231699683","rc":[{"batb":[[0,2.38,5.4],[1,2.34,28.91],[2,1.25,100]],"ltp":2.38,"tv":4.29,"id":2780}]}]}
{"op":"mcm","clk":"11840466792","pt":1723547075452,"mc":[{"id":"1.231699683","rc":[{"batb":[[0,2.4,10],[1,2.38,5.4],[2,2.34,28.91]],"ltp":2.38,"tv":4.29,"id":2780}]}]}
{"op":"mcm","clk":"11840466942","pt":1723547078957,"mc":[{"id":"1.231699683","rc":[{"batb":[[0,2.38,5.4],[1,2.34,28.91],[2,1.25,100]],"ltp":2.38,"tv":4.29,"id":2780}]}]}
{"op":"mcm","clk":"11840467128","pt":1723547083363,"mc":[{"id":"1.231699683","rc":[{"batb":[[0,2.4,10],[1,2.38,5.4],[2,2.34,28.91]],"ltp":2.38,"tv":4.29,"id":2780}]}]}
{"op":"mcm","clk":"11840467292","pt":1723547086877,"mc":[{"id":"1.231699683","rc":[{"batb":[[0,2.38,5.4],[1,2.34,28.91],[2,1.25,100]],"ltp":2.38,"tv":4.29,"id":2780}]}]}
{"op":"mcm","clk":"11840467599","pt":1723547093389,"mc":[{"id":"1.231699683","rc":[{"batb":[[0,2.4,10],[1,2.38,5.4],[2,2.34,28.91]],"ltp":2.38,"tv":4.29,"id":2780}]}]}
{"op":"mcm","clk":"11840467758","pt":1723547096691,"mc":[{"id":"1.231699683","rc":[{"batb":[[0,2.38,5.4],[1,2.34,28.91],[2,1.25,100]],"ltp":2.38,"tv":4.29,"id":2780}]}]}
{"op":"mcm","clk":"11840468028","pt":1723547102893,"mc":[{"id":"1.231699683","rc":[{"batb":[[0,2.4,10],[1,2.38,5.4],[2,2.34,28.91]],"ltp":2.38,"tv":4.29,"id":2780}]}]}
{"op":"mcm","clk":"11840468191","pt":1723547106188,"mc":[{"id":"1.231699683","rc":[{"batb":[[0,2.38,5.4],[1,2.34,28.91],[2,1.25,100]],"ltp":2.38,"tv":4.29,"id":2780}]}]}
{"op":"mcm","clk":"11840468455","pt":1723547111784,"mc":[{"id":"1.231699683","rc":[{"batb":[[0,2.4,10],[1,2.38,5.4],[2,2.34,28.91]],"ltp":2.38,"tv":4.29,"id":2780}]}]}
{"op":"mcm","clk":"11840468648","pt":1723547115438,"mc":[{"id":"1.231699683","rc":[{"batb":[[0,2.38,5.4],[1,2.34,28.91],[2,1.25,100]],"ltp":2.38,"tv":4.29,"id":2780}]}]}
{"op":"mcm","clk":"11840468777","pt":1723547117710,"mc":[{"id":"1.231699683","rc":[{"batb":[[0,2.4,10],[1,2.38,5.4],[2,2.34,28.91]],"ltp":2.38,"tv":4.29,"id":2780}]}]}
{"op":"mcm","clk":"11840468971","pt":1723547121004,"mc":[{"id":"1.231699683","rc":[{"batb":[[0,2.38,5.4],[1,2.34,28.91],[2,1.25,100]],"ltp":2.38,"tv":4.29,"id":2780}]}]}
{"op":"mcm","clk":"11840469100","pt":1723547123407,"mc":[{"id":"1.231699683","rc":[{"batb":[[0,2.4,10],[1,2.38,5.4],[2,2.34,28.91]],"ltp":2.38,"tv":4.29,"id":2780}]}]}
{"op":"mcm","clk":"11840469275","pt":1723547126915,"mc":[{"id":"1.231699683","rc":[{"batb":[[0,2.38,5.4],[1,2.34,28.91],[2,1.25,100]],"ltp":2.38,"tv":4.29,"id":2780}]}]}
{"op":"mcm","clk":"11840469394","pt":1723547129643,"mc":[{"id":"1.231699683","rc":[{"batb":[[0,2.4,10],[1,2.38,5.4],[2,2.34,28.91]],"ltp":2.38,"tv":4.29,"id":2780}]}]}
{"op":"mcm","clk":"11840469545","pt":1723547133029,"mc":[{"id":"1.231699683","rc":[{"batb":[[0,2.38,5.4],[1,2.34,28.91],[2,1.25,100]],"ltp":2.38,"tv":4.29,"id":2780}]}]}
{"op":"mcm","clk":"11840469759","pt":1723547136632,"mc":[{"id":"1.231699683","rc":[{"batb":[[0,2.4,10],[1,2.38,5.4],[2,2.34,28.91]],"ltp":2.38,"tv":4.29,"id":2780}]}]}
{"op":"mcm","clk":"11840469950","pt":1723547140169,"mc":[{"id":"1.231699683","rc":[{"batb":[[0,2.38,5.4],[1,2.34,28.91],[2,1.25,100]],"ltp":2.38,"tv":4.29,"id":2780}]}]}
{"op":"mcm","clk":"11840470133","pt":1723547143762,"mc":[{"id":"1.231699683","rc":[{"batb":[[0,2.4,10],[1,2.38,5.4],[2,2.34,28.91]],"ltp":2.38,"tv":4.29,"id":2780}]}]}
{"op":"mcm","clk":"11840470296","pt":1723547146947,"mc":[{"id":"1.231699683","rc":[{"batb":[[0,2.38,5.4],[1,2.34,28.91],[2,1.25,100]],"ltp":2.38,"tv":4.29,"id":2780}]}]}
{"op":"mcm","clk":"11840470384","pt":1723547149359,"mc":[{"id":"1.231699683","rc":[{"batb":[[0,2.4,10],[1,2.38,5.4],[2,2.34,28.91]],"ltp":2.38,"tv":4.29,"id":2780}]}]}
{"op":"mcm","clk":"11840470526","pt":1723547152748,"mc":[{"id":"1.231699683","rc":[{"batb":[[0,2.38,5.4],[1,2.34,28.91],[2,1.25,100]],"ltp":2.38,"tv":4.29,"id":2780}]}]}
{"op":"mcm","clk":"11840470633","pt":1723547155486,"mc":[{"id":"1.231699683","rc":[{"batb":[[0,2.4,10],[1,2.38,5.4],[2,2.34,28.91]],"ltp":2.38,"tv":4.29,"id":2780}]}]}
{"op":"mcm","clk":"11840470796","pt":1723547158885,"mc":[{"id":"1.231699683","rc":[{"batb":[[0,2.38,5.4],[1,2.34,28.91],[2,1.25,100]],"ltp":2.38,"tv":4.29,"id":2780}]}]}
{"op":"mcm","clk":"11840470900","pt":1723547161210,"mc":[{"id":"1.231699683","rc":[{"batb":[[0,2.4,10],[1,2.38,5.4],[2,2.34,28.91]],"ltp":2.38,"tv":4.29,"id":2780}]}]}
{"op":"mcm","clk":"11840471060","pt":1723547164596,"mc":[{"id":"1.231699683","rc":[{"batb":[[0,2.38,5.4],[1,2.34,28.91],[2,1.25,100]],"ltp":2.38,"tv":4.29,"id":2780}]}]}
{"op":"mcm","clk":"11840471287","pt":1723547168710,"mc":[{"id":"1.231699683","rc":[{"batb":[[0,2.4,10],[1,2.38,5.4],[2,2.34,28.91]],"ltp":2.38,"tv":4.29,"id":2780}]}]}
{"op":"mcm","clk":"11840471429","pt":1723547172106,"mc":[{"id":"1.231699683","rc":[{"batb":[[0,2.38,5.4],[1,2.34,28.91],[2,1.25,100]],"ltp":2.38,"tv":4.29,"id":2780}]}]}
{"op":"mcm","clk":"11840471527","pt":1723547174414,"mc":[{"id":"1.231699683","rc":[{"batb":[[0,2.4,10],[1,2.38,5.4],[2,2.34,28.91]],"ltp":2.38,"tv":4.29,"id":2780}]}]}
{"op":"mcm","clk":"11840471678","pt":1723547177804,"mc":[{"id":"1.231699683","rc":[{"batb":[[0,2.38,5.4],[1,2.34,28.91],[2,1.25,100]],"ltp":2.38,"tv":4.29,"id":2780}]}]}
{"op":"mcm","clk":"11840471830","pt":1723547181407,"mc":[{"id":"1.231699683","rc":[{"batb":[[0,2.4,10],[1,2.38,5.4],[2,2.34,28.91]],"ltp":2.38,"tv":4.29,"id":2780}]}]}
{"op":"mcm","clk":"11840471966","pt":1723547185097,"mc":[{"id":"1.231699683","rc":[{"batb":[[0,2.38,5.4],[1,2.34,28.91],[2,1.25,100]],"ltp":2.38,"tv":4.29,"id":2780}]}]}
{"op":"mcm","clk":"11840472080","pt":1723547187815,"mc":[{"id":"1.231699683","rc":[{"batb":[[0,2.4,10],[1,2.38,5.4],[2,2.34,28.91]],"ltp":2.38,"tv":4.29,"id":2780}]}]}
{"op":"mcm","clk":"11840472246","pt":1723547191217,"mc":[{"id":"1.231699683","rc":[{"batb":[[0,2.38,5.4],[1,2.34,28.91],[2,1.25,100]],"ltp":2.38,"tv":4.29,"id":2780}]}]}
{"op":"mcm","clk":"11840472419","pt":1723547194401,"mc":[{"id":"1.231699683","rc":[{"batb":[[0,2.4,10],[1,2.38,5.4],[2,2.34,28.91]],"ltp":2.38,"tv":4.29,"id":2780}]}]}
{"op":"mcm","clk":"11840472590","pt":1723547197901,"mc":[{"id":"1.231699683","rc":[{"batb":[[0,2.38,5.4],[1,2.34,28.91],[2,1.25,100]],"ltp":2.38,"tv":4.29,"id":2780}]}]}
{"op":"mcm","clk":"11840472799","pt":1723547202347,"mc":[{"id":"1.231699683","rc":[{"batb":[[0,2.4,10],[1,2.38,5.4],[2,2.34,28.91]],"ltp":2.38,"tv":4.29,"id":2780}]}]}
{"op":"mcm","clk":"11840472973","pt":1723547205719,"mc":[{"id":"1.231699683","rc":[{"batb":[[0,2.38,5.4],[1,2.34,28.91],[2,1.25,100]],"ltp":2.38,"tv":4.29,"id":2780}]}]}
{"op":"mcm","clk":"11840473106","pt":1723547208606,"mc":[{"id":"1.231699683","rc":[{"batb":[[0,2.4,10],[1,2.38,5.4],[2,2.34,28.91]],"ltp":2.38,"tv":4.29,"id":2780}]}]}
{"op":"mcm","clk":"11840473244","pt":1723547212055,"mc":[{"id":"1.231699683","rc":[{"batb":[[0,2.38,5.4],[1,2.34,28.91],[2,1.25,100]],"ltp":2.38,"tv":4.29,"id":2780}]}]}
{"op":"mcm","clk":"11840473344","pt":1723547214716,"mc":[{"id":"1.231699683","rc":[{"batb":[[0,2.4,10],[1,2.38,5.4],[2,2.34,28.91]],"ltp":2.38,"tv":4.29,"id":2780}]}]}
{"op":"mcm","clk":"11840473528","pt":1723547218328,"mc":[{"id":"1.231699683","rc":[{"batb":[[0,2.38,5.4],[1,2.34,28.91],[2,1.25,100]],"ltp":2.38,"tv":4.29,"id":2780}]}]}
{"op":"mcm","clk":"11840473777","pt":1723547222521,"mc":[{"id":"1.231699683","rc":[{"batb":[[0,2.4,10],[1,2.38,5.4],[2,2.34,28.91]],"ltp":2.38,"tv":4.29,"id":2780}]}]}
{"op":"mcm","clk":"11840473995","pt":1723547225930,"mc":[{"id":"1.231699683","rc":[{"batb":[[0,2.38,5.4],[1,2.34,28.91],[2,1.25,100]],"ltp":2.38,"tv":4.29,"id":2780}]}]}
{"op":"mcm","clk":"11840474131","pt":1723547228357,"mc":[{"id":"1.231699683","rc":[{"batb":[[0,2.4,10],[1,2.38,5.4],[2,2.34,28.91]],"ltp":2.38,"tv":4.29,"id":2780}]}]}
{"op":"mcm","clk":"11840474310","pt":1723547231761,"mc":[{"id":"1.231699683","rc":[{"batb":[[0,2.38,5.4],[1,2.34,28.91],[2,1.25,100]],"ltp":2.38,"tv":4.29,"id":2780}]}]}
{"op":"mcm","clk":"11840474473","pt":1723547234644,"mc":[{"id":"1.231699683","rc":[{"batb":[[0,2.4,10],[1,2.38,5.4],[2,2.34,28.91]],"ltp":2.38,"tv":4.29,"id":2780}]}]}
{"op":"mcm","clk":"11840474657","pt":1723547237942,"mc":[{"id":"1.231699683","rc":[{"batb":[[0,2.38,5.4],[1,2.34,28.91],[2,1.25,100]],"ltp":2.38,"tv":4.29,"id":2780}]}]}
{"op":"mcm","clk":"11840474829","pt":1723547241188,"mc":[{"id":"1.231699683","rc":[{"batb":[[0,2.4,10],[1,2.38,5.4],[2,2.34,28.91]],"ltp":2.38,"tv":4.29,"id":2780}]}]}
{"op":"mcm","clk":"11840475028","pt":1723547244954,"mc":[{"id":"1.231699683","rc":[{"batb":[[0,2.38,5.4],[1,2.34,28.91],[2,1.25,100]],"ltp":2.38,"tv":4.29,"id":2780}]}]}
{"op":"mcm","clk":"11840475186","pt":1723547247480,"mc":[{"id":"1.231699683","rc":[{"batb":[[0,2.4,10],[1,2.38,5.4],[2,2.34,28.91]],"ltp":2.38,"tv":4.29,"id":2780}]}]}
{"op":"mcm","clk":"11840475377","pt":1723547250883,"mc":[{"id":"1.231699683","rc":[{"batb":[[0,2.38,5.4],[1,2.34,28.91],[2,1.25,100]],"ltp":2.38,"tv":4.29,"id":2780}]}]}
{"op":"mcm","clk":"11840475536","pt":1723547253361,"mc":[{"id":"1.231699683","rc":[{"batb":[[0,2.4,10],[1,2.38,5.4],[2,2.34,28.91]],"ltp":2.38,"tv":4.29,"id":2780}]}]}
{"op":"mcm","clk":"11840475726","pt":1723547256768,"mc":[{"id":"1.231699683","rc":[{"batb":[[0,2.38,5.4],[1,2.34,28.91],[2,1.25,100]],"ltp":2.38,"tv":4.29,"id":2780}]}]}
{"op":"mcm","clk":"11840476064","pt":1723547263112,"mc":[{"id":"1.231699683","rc":[{"batb":[[0,2.4,10],[1,2.38,5.4],[2,2.34,28.91]],"ltp":2.38,"tv":4.29,"id":2780}]}]}
{"op":"mcm","clk":"11840476257","pt":1723547266401,"mc":[{"id":"1.231699683","rc":[{"batb":[[0,2.38,5.4],[1,2.34,28.91],[2,1.25,100]],"ltp":2.38,"tv":4.29,"id":2780}]}]}
{"op":"mcm","clk":"11840476405","pt":1723547268822,"mc":[{"id":"1.231699683","rc":[{"batb":[[0,2.4,10],[1,2.38,5.4],[2,2.34,28.91]],"ltp":2.38,"tv":4.29,"id":2780}]}]}
{"op":"mcm","clk":"11840476601","pt":1723547272080,"mc":[{"id":"1.231699683","rc":[{"batb":[[0,2.38,5.4],[1,2.34,28.91],[2,1.25,100]],"ltp":2.38,"tv":4.29,"id":2780}]}]}
{"op":"mcm","clk":"11840477173","pt":1723547282198,"mc":[{"id":"1.231699683","rc":[{"batb":[[0,2.4,10],[1,2.38,5.4],[2,2.34,28.91]],"ltp":2.38,"tv":4.29,"id":2780}]}]}
{"op":"mcm","clk":"11840477383","pt":1723547285412,"mc":[{"id":"1.231699683","rc":[{"batb":[[0,2.38,5.4],[1,2.34,28.91],[2,1.25,100]],"ltp":2.38,"tv":4.29,"id":2780}]}]}
{"op":"mcm","clk":"11840477518","pt":1723547287735,"mc":[{"id":"1.231699683","rc":[{"batb":[[0,2.4,10],[1,2.38,5.4],[2,2.34,28.91]],"ltp":2.38,"tv":4.29,"id":2780}]}]}
{"op":"mcm","clk":"11840477724","pt":1723547291135,"mc":[{"id":"1.231699683","rc":[{"batb":[[0,2.38,5.4],[1,2.34,28.91],[2,1.25,100]],"ltp":2.38,"tv":4.29,"id":2780}]}]}
{"op":"mcm","clk":"11840478114","pt":1723547297647,"mc":[{"id":"1.231699683","rc":[{"batb":[[0,2.4,10],[1,2.38,5.4],[2,2.34,28.91]],"ltp":2.38,"tv":4.29,"id":2780}]}]}
{"op":"mcm","clk":"11840478310","pt":1723547301047,"mc":[{"id":"1.231699683","rc":[{"batb":[[0,2.38,5.4],[1,2.34,28.91],[2,1.25,100]],"ltp":2.38,"tv":4.29,"id":2780}]}]}
{"op":"mcm","clk":"11840478462","pt":1723547303543,"mc":[{"id":"1.231699683","rc":[{"batb":[[0,2.4,10],[1,2.38,5.4],[2,2.34,28.91]],"ltp":2.38,"tv":4.29,"id":2780}]}]}
{"op":"mcm","clk":"11840478677","pt":1723547307154,"mc":[{"id":"1.231699683","rc":[{"batb":[[0,2.38,5.4],[1,2.34,28.91],[2,1.25,100]],"ltp":2.38,"tv":4.29,"id":2780}]}]}
{"op":"mcm","clk":"11840478837","pt":1723547309541,"mc":[{"id":"1.231699683","rc":[{"batb":[[0,2.4,10],[1,2.38,5.4],[2,2.34,28.91]],"ltp":2.38,"tv":4.29,"id":2780}]}]}
{"op":"mcm","clk":"11840479052","pt":1723547312851,"mc":[{"id":"1.231699683","rc":[{"batb":[[0,2.38,5.4],[1,2.34,28.91],[2,1.25,100]],"ltp":2.38,"tv":4.29,"id":2780}]}]}
{"op":"mcm","clk":"11840479385","pt":1723547317163,"mc":[{"id":"1.231699683","rc":[{"batb":[[0,2.4,10],[1,2.38,5.4],[2,2.34,28.91]],"ltp":2.38,"tv":4.29,"id":2780}]}]}
{"op":"mcm","clk":"11840479592","pt":1723547321039,"mc":[{"id":"1.231699683","rc":[{"batb":[[0,2.38,5.4],[1,2.34,28.91],[2,1.25,100]],"ltp":2.38,"tv":4.29,"id":2780}]}]}
{"op":"mcm","clk":"11840479766","pt":1723547324481,"mc":[{"id":"1.231699683","rc":[{"batb":[[0,2.4,10],[1,2.38,5.4],[2,2.34,28.91]],"ltp":2.38,"tv":4.29,"id":2780}]}]}
{"op":"mcm","clk":"11840479969","pt":1723547327880,"mc":[{"id":"1.231699683","rc":[{"batb":[[0,2.38,5.4],[1,2.34,28.91],[2,1.25,100]],"ltp":2.38,"tv":4.29,"id":2780}]}]}
{"op":"mcm","clk":"11840480122","pt":1723547330558,"mc":[{"id":"1.231699683","rc":[{"batb":[[0,2.4,10],[1,2.38,5.4],[2,2.34,28.91]],"ltp":2.38,"tv":4.29,"id":2780}]}]}
{"op":"mcm","clk":"11840480315","pt":1723547333960,"mc":[{"id":"1.231699683","rc":[{"batb":[[0,2.38,5.4],[1,2.34,28.91],[2,1.25,100]],"ltp":2.38,"tv":4.29,"id":2780}]}]}
{"op":"mcm","clk":"11840480422","pt":1723547336190,"mc":[{"id":"1.231699683","rc":[{"batb":[[0,2.4,10],[1,2.38,5.4],[2,2.34,28.91]],"ltp":2.38,"tv":4.29,"id":2780}]}]}
{"op":"mcm","clk":"11840480615","pt":1723547339796,"mc":[{"id":"1.231699683","rc":[{"batb":[[0,2.38,5.4],[1,2.34,28.91],[2,1.25,100]],"ltp":2.38,"tv":4.29,"id":2780}]}]}
{"op":"mcm","clk":"11840480780","pt":1723547342172,"mc":[{"id":"1.231699683","rc":[{"batb":[[0,2.4,10],[1,2.38,5.4],[2,2.34,28.91]],"ltp":2.38,"tv":4.29,"id":2780}]}]}
{"op":"mcm","clk":"11840480996","pt":1723547345695,"mc":[{"id":"1.231699683","rc":[{"batb":[[0,2.38,5.4],[1,2.34,28.91],[2,1.25,100]],"ltp":2.38,"tv":4.29,"id":2780}]}]}
{"op":"mcm","clk":"11840481174","pt":1723547348268,"mc":[{"id":"1.231699683","rc":[{"batb":[[0,2.4,10],[1,2.38,5.4],[2,2.34,28.91]],"ltp":2.38,"tv":4.29,"id":2780}]}]}
{"op":"mcm","clk":"11840481384","pt":1723547351568,"mc":[{"id":"1.231699683","rc":[{"batb":[[0,2.38,5.4],[1,2.34,28.91],[2,1.25,100]],"ltp":2.38,"tv":4.29,"id":2780}]}]}
{"op":"mcm","clk":"11840481531","pt":1723547354195,"mc":[{"id":"1.231699683","rc":[{"batb":[[0,2.4,10],[1,2.38,5.4],[2,2.34,28.91]],"ltp":2.38,"tv":4.29,"id":2780}]}]}
{"op":"mcm","clk":"11840481718","pt":1723547357694,"mc":[{"id":"1.231699683","rc":[{"batb":[[0,2.38,5.4],[1,2.34,28.91],[2,1.25,100]],"ltp":2.38,"tv":4.29,"id":2780}]}]}
{"op":"mcm","clk":"11840481946","pt":1723547362223,"mc":[{"id":"1.231699683","rc":[{"batb":[[0,2.4,10],[1,2.38,5.4],[2,2.34,28.91]],"ltp":2.38,"tv":4.29,"id":2780}]}]}
{"op":"mcm","clk":"11840482129","pt":1723547365525,"mc":[{"id":"1.231699683","rc":[{"batb":[[0,2.38,5.4],[1,2.34,28.91],[2,1.25,100]],"ltp":2.38,"tv":4.29,"id":2780}]}]}
{"op":"mcm","clk":"11840482294","pt":1723547368306,"mc":[{"id":"1.231699683","rc":[{"batb":[[0,2.4,10],[1,2.38,5.4],[2,2.34,28.91]],"ltp":2.38,"tv":4.29,"id":2780}]}]}
{"op":"mcm","clk":"11840482466","pt":1723547371703,"mc":[{"id":"1.231699683","rc":[{"batb":[[0,2.38,5.4],[1,2.34,28.91],[2,1.25,100]],"ltp":2.38,"tv":4.29,"id":2780}]}]}
{"op":"mcm","clk":"11840482657","pt":1723547374598,"mc":[{"id":"1.231699683","rc":[{"batb":[[0,2.4,10],[1,2.38,5.4],[2,2.34,28.91]],"ltp":2.38,"tv":4.29,"id":2780}]}]}
{"op":"mcm","clk":"11840482874","pt":1723547377909,"mc":[{"id":"1.231699683","rc":[{"batb":[[0,2.38,5.4],[1,2.34,28.91],[2,1.25,100]],"ltp":2.38,"tv":4.29,"id":2780}]}]}
{"op":"mcm","clk":"11840483042","pt":1723547380538,"mc":[{"id":"1.231699683","rc":[{"batb":[[0,2.4,10],[1,2.38,5.4],[2,2.34,28.91]],"ltp":2.38,"tv":4.29,"id":2780}]}]}
{"op":"mcm","clk":"11840483245","pt":1723547383932,"mc":[{"id":"1.231699683","rc":[{"batb":[[0,2.38,5.4],[1,2.34,28.91],[2,1.25,100]],"ltp":2.38,"tv":4.29,"id":2780}]}]}
{"op":"mcm","clk":"11840483528","pt":1723547388719,"mc":[{"id":"1.231699683","rc":[{"batb":[[0,2.4,10],[1,2.38,5.4],[2,2.34,28.91]],"ltp":2.38,"tv":4.29,"id":2780}]}]}
{"op":"mcm","clk":"11840483731","pt":1723547392123,"mc":[{"id":"1.231699683","rc":[{"batb":[[0,2.38,5.4],[1,2.34,28.91],[2,1.25,100]],"ltp":2.38,"tv":4.29,"id":2780}]}]}
{"op":"mcm","clk":"11840484029","pt":1723547397840,"mc":[{"id":"1.231699683","rc":[{"batb":[[0,2.4,10],[1,2.38,5.4],[2,2.34,28.91]],"ltp":2.38,"tv":4.29,"id":2780}]}]}
{"op":"mcm","clk":"11840484241","pt":1723547401236,"mc":[{"id":"1.231699683","rc":[{"batb":[[0,2.38,5.4],[1,2.34,28.91],[2,1.25,100]],"ltp":2.38,"tv":4.29,"id":2780}]}]}
{"op":"mcm","clk":"11840484462","pt":1723547404640,"mc":[{"id":"1.231699683","rc":[{"batb":[[0,2.4,10],[1,2.38,5.4],[2,2.34,28.91]],"ltp":2.38,"tv":4.29,"id":2780}]}]}
{"op":"mcm","clk":"11840484692","pt":1723547408146,"mc":[{"id":"1.231699683","rc":[{"batb":[[0,2.38,5.4],[1,2.34,28.91],[2,1.25,100]],"ltp":2.38,"tv":4.29,"id":2780}]}]}
{"op":"mcm","clk":"11840485054","pt":1723547414258,"mc":[{"id":"1.231699683","rc":[{"batb":[[0,2.4,10],[1,2.38,5.4],[2,2.34,28.91]],"ltp":2.38,"tv":4.29,"id":2780}]}]}
{"op":"mcm","clk":"11840485263","pt":1723547417655,"mc":[{"id":"1.231699683","rc":[{"batb":[[0,2.38,5.4],[1,2.34,28.91],[2,1.25,100]],"ltp":2.38,"tv":4.29,"id":2780}]}]}
{"op":"mcm","clk":"11840485438","pt":1723547420477,"mc":[{"id":"1.231699683","rc":[{"batb":[[0,2.4,10],[1,2.38,5.4],[2,2.34,28.91]],"ltp":2.38,"tv":4.29,"id":2780}]}]}
{"op":"mcm","clk":"11840485635","pt":1723547424069,"mc":[{"id":"1.231699683","rc":[{"batb":[[0,2.38,5.4],[1,2.34,28.91],[2,1.25,100]],"ltp":2.38,"tv":4.29,"id":2780}]}]}
{"op":"mcm","clk":"11840485989","pt":1723547430703,"mc":[{"id":"1.231699683","rc":[{"batb":[[0,2.4,10],[1,2.38,5.4],[2,2.34,28.91]],"ltp":2.38,"tv":4.29,"id":2780}]}]}
{"op":"mcm","clk":"11840486185","pt":1723547434157,"mc":[{"id":"1.231699683","rc":[{"batb":[[0,2.38,5.4],[1,2.34,28.91],[2,1.25,100]],"ltp":2.38,"tv":4.29,"id":2780}]}]}
{"op":"mcm","clk":"11840486394","pt":1723547437804,"mc":[{"id":"1.231699683","rc":[{"batb":[[0,2.4,10],[1,2.38,5.4],[2,2.34,28.91]],"ltp":2.38,"tv":4.29,"id":2780}]}]}
{"op":"mcm","clk":"11840486593","pt":1723547441212,"mc":[{"id":"1.231699683","rc":[{"batb":[[0,2.38,5.4],[1,2.34,28.91],[2,1.25,100]],"ltp":2.38,"tv":4.29,"id":2780}]}]}
{"op":"mcm","clk":"11840486837","pt":1723547445803,"mc":[{"id":"1.231699683","rc":[{"batb":[[0,2.4,10],[1,2.38,5.4],[2,2.34,28.91]],"ltp":2.38,"tv":4.29,"id":2780}]}]}
{"op":"mcm","clk":"11840487015","pt":1723547449106,"mc":[{"id":"1.231699683","rc":[{"batb":[[0,2.38,5.4],[1,2.34,28.91],[2,1.25,100]],"ltp":2.38,"tv":4.29,"id":2780}]}]}
{"op":"mcm","clk":"11840487239","pt":1723547452922,"mc":[{"id":"1.231699683","rc":[{"batb":[[0,2.4,10],[1,2.38,5.4],[2,2.34,28.91]],"ltp":2.38,"tv":4.29,"id":2780}]}]}
{"op":"mcm","clk":"11840487415","pt":1723547456322,"mc":[{"id":"1.231699683","rc":[{"batb":[[0,2.38,5.4],[1,2.34,28.91],[2,1.25,100]],"ltp":2.38,"tv":4.29,"id":2780}]}]}
{"op":"mcm","clk":"11840487596","pt":1723547459326,"mc":[{"id":"1.231699683","rc":[{"batb":[[0,2.4,10],[1,2.38,5.4],[2,2.34,28.91]],"ltp":2.38,"tv":4.29,"id":2780}]}]}
{"op":"mcm","clk":"11840487817","pt":1723547462690,"mc":[{"id":"1.231699683","rc":[{"batb":[[0,2.38,5.4],[1,2.34,28.91],[2,1.25,100]],"ltp":2.38,"tv":4.29,"id":2780}]}]}
{"op":"mcm","clk":"11840488005","pt":1723547465636,"mc":[{"id":"1.231699683","rc":[{"batb":[[0,2.4,10],[1,2.38,5.4],[2,2.34,28.91]],"ltp":2.38,"tv":4.29,"id":2780}]}]}
{"op":"mcm","clk":"11840488221","pt":1723547469037,"mc":[{"id":"1.231699683","rc":[{"batb":[[0,2.38,5.4],[1,2.34,28.91],[2,1.25,100]],"ltp":2.38,"tv":4.29,"id":2780}]}]}
{"op":"mcm","clk":"11840488391","pt":1723547472338,"mc":[{"id":"1.231699683","rc":[{"batb":[[0,2.4,10],[1,2.38,5.4],[2,2.34,28.91]],"ltp":2.38,"tv":4.29,"id":2780}]}]}
{"op":"mcm","clk":"11840488584","pt":1723547475835,"mc":[{"id":"1.231699683","rc":[{"batb":[[0,2.38,5.4],[1,2.34,28.91],[2,1.25,100]],"ltp":2.38,"tv":4.29,"id":2780}]}]}
{"op":"mcm","clk":"11840488783","pt":1723547479448,"mc":[{"id":"1.231699683","rc":[{"batb":[[0,2.4,10],[1,2.38,5.4],[2,2.34,28.91]],"ltp":2.38,"tv":4.29,"id":2780}]}]}
{"op":"mcm","clk":"11840488957","pt":1723547482744,"mc":[{"id":"1.231699683","rc":[{"batb":[[0,2.38,5.4],[1,2.34,28.91],[2,1.25,100]],"ltp":2.38,"tv":4.29,"id":2780}]}]}
{"op":"mcm","clk":"11840489118","pt":1723547485219,"mc":[{"id":"1.231699683","rc":[{"batb":[[0,2.4,10],[1,2.38,5.4],[2,2.34,28.91]],"ltp":2.38,"tv":4.29,"id":2780}]}]}
{"op":"mcm","clk":"11840489318","pt":1723547488767,"mc":[{"id":"1.231699683","rc":[{"batb":[[0,2.38,5.4],[1,2.34,28.91],[2,1.25,100]],"ltp":2.38,"tv":4.29,"id":2780}]}]}
{"op":"mcm","clk":"11840489457","pt":1723547491045,"mc":[{"id":"1.231699683","rc":[{"batb":[[0,2.4,10],[1,2.38,5.4],[2,2.34,28.91]],"ltp":2.38,"tv":4.29,"id":2780}]}]}
{"op":"mcm","clk":"11840489659","pt":1723547494456,"mc":[{"id":"1.231699683","rc":[{"batb":[[0,2.38,5.4],[1,2.34,28.91],[2,1.25,100]],"ltp":2.38,"tv":4.29,"id":2780}]}]}
{"op":"mcm","clk":"11840489831","pt":1723547497345,"mc":[{"id":"1.231699683","rc":[{"batb":[[0,2.4,10],[1,2.38,5.4],[2,2.34,28.91]],"ltp":2.38,"tv":4.29,"id":2780}]}]}
{"op":"mcm","clk":"11840490017","pt":1723547500656,"mc":[{"id":"1.231699683","rc":[{"batb":[[0,2.38,5.4],[1,2.34,28.91],[2,1.25,100]],"ltp":2.38,"tv":4.29,"id":2780}]}]}
{"op":"mcm","clk":"11840490148","pt":1723547502963,"mc":[{"id":"1.231699683","rc":[{"batb":[[0,2.4,10],[1,2.38,5.4],[2,2.34,28.91]],"ltp":2.38,"tv":4.29,"id":2780}]}]}
{"op":"mcm","clk":"11840490333","pt":1723547506352,"mc":[{"id":"1.231699683","rc":[{"batb":[[0,2.38,5.4],[1,2.34,28.91],[2,1.25,100]],"ltp":2.38,"tv":4.29,"id":2780}]}]}
{"op":"mcm","clk":"11840490506","pt":1723547509485,"mc":[{"id":"1.231699683","rc":[{"batb":[[0,2.4,10],[1,2.38,5.4],[2,2.34,28.91]],"ltp":2.38,"tv":4.29,"id":2780}]}]}
{"op":"mcm","clk":"11840490745","pt":1723547512886,"mc":[{"id":"1.231699683","rc":[{"batb":[[0,2.38,5.4],[1,2.34,28.91],[2,1.25,100]],"ltp":2.38,"tv":4.29,"id":2780}]}]}
{"op":"mcm","clk":"11840490986","pt":1723547516257,"mc":[{"id":"1.231699683","rc":[{"batb":[[0,2.4,10],[1,2.38,5.4],[2,2.34,28.91]],"ltp":2.38,"tv":4.29,"id":2780}]}]}
{"op":"mcm","clk":"11840491203","pt":1723547519806,"mc":[{"id":"1.231699683","rc":[{"batb":[[0,2.38,5.4],[1,2.34,28.91],[2,1.25,100]],"ltp":2.38,"tv":4.29,"id":2780}]}]}
{"op":"mcm","clk":"11840491466","pt":1723547524592,"mc":[{"id":"1.231699683","rc":[{"batb":[[0,2.4,10],[1,2.38,5.4],[2,2.34,28.91]],"ltp":2.38,"tv":4.29,"id":2780}]}]}
{"op":"mcm","clk":"11840491657","pt":1723547527992,"mc":[{"id":"1.231699683","rc":[{"batb":[[0,2.38,5.4],[1,2.34,28.91],[2,1.25,100]],"ltp":2.38,"tv":4.29,"id":2780}]}]}
{"op":"mcm","clk":"11840491861","pt":1723547530987,"mc":[{"id":"1.231699683","rc":[{"batb":[[0,2.4,10],[1,2.38,5.4],[2,2.34,28.91]],"ltp":2.38,"tv":4.29,"id":2780}]}]}
{"op":"mcm","clk":"11840492067","pt":1723547534327,"mc":[{"id":"1.231699683","rc":[{"batb":[[0,2.38,5.4],[1,2.34,28.91],[2,1.25,100]],"ltp":2.38,"tv":4.29,"id":2780}]}]}
{"op":"mcm","clk":"11840492230","pt":1723547537115,"mc":[{"id":"1.231699683","rc":[{"batb":[[0,2.4,10],[1,2.38,5.4],[2,2.34,28.91]],"ltp":2.38,"tv":4.29,"id":2780}]}]}
{"op":"mcm","clk":"11840492467","pt":1723547540725,"mc":[{"id":"1.231699683","rc":[{"batb":[[0,2.38,5.4],[1,2.34,28.91],[2,1.25,100]],"ltp":2.38,"tv":4.29,"id":2780}]}]}
{"op":"mcm","clk":"11840492649","pt":1723547544625,"mc":[{"id":"1.231699683","rc":[{"batb":[[0,2.4,10],[1,2.38,5.4],[2,2.34,28.91]],"ltp":2.38,"tv":4.29,"id":2780}]}]}
{"op":"mcm","clk":"11840492825","pt":1723547548126,"mc":[{"id":"1.231699683","rc":[{"batb":[[0,2.38,5.4],[1,2.34,28.91],[2,1.25,100]],"ltp":2.38,"tv":4.29,"id":2780}]}]}
{"op":"mcm","clk":"11840493034","pt":1723547551623,"mc":[{"id":"1.231699683","rc":[{"batb":[[0,2.4,10],[1,2.38,5.4],[2,2.34,28.91]],"ltp":2.38,"tv":4.29,"id":2780}]}]}
{"op":"mcm","clk":"11840493292","pt":1723547556500,"mc":[{"id":"1.231699683","rc":[{"batb":[[0,2.38,5.4],[1,2.34,28.91],[2,1.25,100]],"ltp":2.38,"tv":4.29,"id":2780}]}]}
{"op":"mcm","clk":"11840493710","pt":1723547564821,"mc":[{"id":"1.231699683","rc":[{"batb":[[0,2.4,10],[1,2.38,5.4],[2,2.34,28.91]],"ltp":2.38,"tv":4.29,"id":2780}]}]}
{"op":"mcm","clk":"11840493905","pt":1723547568535,"mc":[{"id":"1.231699683","rc":[{"batb":[[0,2.38,5.4],[1,2.34,28.91],[2,1.25,100]],"ltp":2.38,"tv":4.29,"id":2780}]}]}
{"op":"mcm","clk":"11840494212","pt":1723547574029,"mc":[{"id":"1.231699683","rc":[{"batb":[[0,2.4,10],[1,2.38,5.4],[2,2.34,28.91]],"ltp":2.38,"tv":4.29,"id":2780}]}]}
{"op":"mcm","clk":"11840494364","pt":1723547577441,"mc":[{"id":"1.231699683","rc":[{"batb":[[0,2.38,5.4],[1,2.34,28.91],[2,1.25,100]],"ltp":2.38,"tv":4.29,"id":2780}]}]}
{"op":"mcm","clk":"11840494454","pt":1723547579650,"mc":[{"id":"1.231699683","rc":[{"batb":[[0,2.4,10],[1,2.38,5.4],[2,2.34,28.91]],"ltp":2.38,"tv":4.29,"id":2780}]}]}
{"op":"mcm","clk":"11840494669","pt":1723547583061,"mc":[{"id":"1.231699683","rc":[{"batb":[[0,2.38,5.4],[1,2.34,28.91],[2,1.25,100]],"ltp":2.38,"tv":4.29,"id":2780}]}]}
{"op":"mcm","clk":"11840494814","pt":1723547585529,"mc":[{"id":"1.231699683","rc":[{"batb":[[0,2.4,10],[1,2.38,5.4],[2,2.34,28.91]],"ltp":2.38,"tv":4.29,"id":2780}]}]}
{"op":"mcm","clk":"11840494998","pt":1723547588827,"mc":[{"id":"1.231699683","rc":[{"batb":[[0,2.38,5.4],[1,2.34,28.91],[2,1.25,100]],"ltp":2.38,"tv":4.29,"id":2780}]}]}
{"op":"mcm","clk":"11840495264","pt":1723547594166,"mc":[{"id":"1.231699683","rc":[{"batb":[[0,2.4,10],[1,2.38,5.4],[2,2.34,28.91]],"ltp":2.38,"tv":4.29,"id":2780}]}]}
{"op":"mcm","clk":"11840495457","pt":1723547597670,"mc":[{"id":"1.231699683","rc":[{"batb":[[0,2.38,5.4],[1,2.34,28.91],[2,1.25,100]],"ltp":2.38,"tv":4.29,"id":2780}]}]}
{"op":"mcm","clk":"11840495613","pt":1723547600351,"mc":[{"id":"1.231699683","rc":[{"batb":[[0,2.4,10],[1,2.38,5.4],[2,2.34,28.91]],"ltp":2.38,"tv":4.29,"id":2780}]}]}
{"op":"mcm","clk":"11840495844","pt":1723547603648,"mc":[{"id":"1.231699683","rc":[{"batb":[[0,2.38,5.4],[1,2.34,28.91],[2,1.25,100]],"ltp":2.38,"tv":4.29,"id":2780}]}]}
{"op":"mcm","clk":"11840495994","pt":1723547606173,"mc":[{"id":"1.231699683","rc":[{"batb":[[0,2.4,10],[1,2.38,5.4],[2,2.34,28.91]],"ltp":2.38,"tv":4.29,"id":2780}]}]}
{"op":"mcm","clk":"11840496172","pt":1723547609461,"mc":[{"id":"1.231699683","rc":[{"batb":[[0,2.38,5.4],[1,2.34,28.91],[2,1.25,100]],"ltp":2.38,"tv":4.29,"id":2780}]}]}
{"op":"mcm","clk":"11840496514","pt":1723547615274,"mc":[{"id":"1.231699683","rc":[{"batb":[[0,2.4,10],[1,2.38,5.4],[2,2.34,28.91]],"ltp":2.38,"tv":4.29,"id":2780}]}]}
{"op":"mcm","clk":"11840496710","pt":1723547618578,"mc":[{"id":"1.231699683","rc":[{"batb":[[0,2.38,5.4],[1,2.34,28.91],[2,1.25,100]],"ltp":2.38,"tv":4.29,"id":2780}]}]}
{"op":"mcm","clk":"11840496927","pt":1723547622384,"mc":[{"id":"1.231699683","rc":[{"batb":[[0,2.4,10],[1,2.38,5.4],[2,2.34,28.91]],"ltp":2.38,"tv":4.29,"id":2780}]}]}
{"op":"mcm","clk":"11840497084","pt":1723547625674,"mc":[{"id":"1.231699683","rc":[{"batb":[[0,2.38,5.4],[1,2.34,28.91],[2,1.25,100]],"ltp":2.38,"tv":4.29,"id":2780}]}]}
{"op":"mcm","clk":"11840497242","pt":1723547628561,"mc":[{"id":"1.231699683","rc":[{"batb":[[0,2.4,10],[1,2.38,5.4],[2,2.34,28.91]],"ltp":2.38,"tv":4.29,"id":2780}]}]}
{"op":"mcm","clk":"11840497448","pt":1723547632179,"mc":[{"id":"1.231699683","rc":[{"batb":[[0,2.38,5.4],[1,2.34,28.91],[2,1.25,100]],"ltp":2.38,"tv":4.29,"id":2780}]}]}
{"op":"mcm","clk":"11840497684","pt":1723547636200,"mc":[{"id":"1.231699683","rc":[{"batb":[[0,2.4,10],[1,2.38,5.4],[2,2.34,28.91]],"ltp":2.38,"tv":4.29,"id":2780}]}]}
{"op":"mcm","clk":"11840497915","pt":1723547639670,"mc":[{"id":"1.231699683","rc":[{"batb":[[0,2.38,5.4],[1,2.34,28.91],[2,1.25,100]],"ltp":2.38,"tv":4.29,"id":2780}]}]}
{"op":"mcm","clk":"11840498167","pt":1723547644117,"mc":[{"id":"1.231699683","rc":[{"batb":[[0,2.4,10],[1,2.38,5.4],[2,2.34,28.91]],"ltp":2.38,"tv":4.29,"id":2780}]}]}
{"op":"mcm","clk":"11840498365","pt":1723547647417,"mc":[{"id":"1.231699683","rc":[{"batb":[[0,2.38,5.4],[1,2.34,28.91],[2,1.25,100]],"ltp":2.38,"tv":4.29,"id":2780}]}]}
{"op":"mcm","clk":"11840498548","pt":1723547650412,"mc":[{"id":"1.231699683","rc":[{"batb":[[0,2.4,10],[1,2.38,5.4],[2,2.34,28.91]],"ltp":2.38,"tv":4.29,"id":2780}]}]}
{"op":"mcm","clk":"11840498763","pt":1723547653919,"mc":[{"id":"1.231699683","rc":[{"batb":[[0,2.38,5.4],[1,2.34,28.91],[2,1.25,100]],"ltp":2.38,"tv":4.29,"id":2780}]}]}
{"op":"mcm","clk":"11840498880","pt":1723547656088,"mc":[{"id":"1.231699683","rc":[{"batb":[[0,2.4,10],[1,2.38,5.4],[2,2.34,28.91]],"ltp":2.38,"tv":4.29,"id":2780}]}]}
{"op":"mcm","clk":"11840499080","pt":1723547659391,"mc":[{"id":"1.231699683","rc":[{"batb":[[0,2.38,5.4],[1,2.34,28.91],[2,1.25,100]],"ltp":2.38,"tv":4.29,"id":2780}]}]}
{"op":"mcm","clk":"11840499273","pt":1723547662687,"mc":[{"id":"1.231699683","rc":[{"batb":[[0,2.4,10],[1,2.38,5.4],[2,2.34,28.91]],"ltp":2.38,"tv":4.29,"id":2780}]}]}
{"op":"mcm","clk":"11840499477","pt":1723547665934,"mc":[{"id":"1.231699683","rc":[{"batb":[[0,2.38,5.4],[1,2.34,28.91],[2,1.25,100]],"ltp":2.38,"tv":4.29,"id":2780}]}]}
{"op":"mcm","clk":"11840499773","pt":1723547670415,"mc":[{"id":"1.231699683","rc":[{"batb":[[0,2.4,10],[1,2.38,5.4],[2,2.34,28.91]],"ltp":2.38,"tv":4.29,"id":2780}]}]}
{"op":"mcm","clk":"11840500012","pt":1723547673843,"mc":[{"id":"1.231699683","rc":[{"batb":[[0,2.38,5.4],[1,2.34,28.91],[2,1.25,100]],"ltp":2.38,"tv":4.29,"id":2780}]}]}
{"op":"mcm","clk":"11840500200","pt":1723547676842,"mc":[{"id":"1.231699683","rc":[{"batb":[[0,2.4,10],[1,2.38,5.4],[2,2.34,28.91]],"ltp":2.38,"tv":4.29,"id":2780}]}]}
{"op":"mcm","clk":"11840500413","pt":1723547680208,"mc":[{"id":"1.231699683","rc":[{"batb":[[0,2.38,5.4],[1,2.34,28.91],[2,1.25,100]],"ltp":2.38,"tv":4.29,"id":2780}]}]}
{"op":"mcm","clk":"11840500566","pt":1723547682434,"mc":[{"id":"1.231699683","rc":[{"batb":[[0,2.4,10],[1,2.38,5.4],[2,2.34,28.91]],"ltp":2.38,"tv":4.29,"id":2780}]}]}
{"op":"mcm","clk":"11840500768","pt":1723547685621,"mc":[{"id":"1.231699683","rc":[{"batb":[[0,2.38,5.4],[1,2.34,28.91],[2,1.25,100]],"ltp":2.38,"tv":4.29,"id":2780}]}]}
{"op":"mcm","clk":"11840501000","pt":1723547689533,"mc":[{"id":"1.231699683","rc":[{"batb":[[0,2.4,10],[1,2.38,5.4],[2,2.34,28.91]],"ltp":2.38,"tv":4.29,"id":2780}]}]}
{"op":"mcm","clk":"11840501215","pt":1723547692928,"mc":[{"id":"1.231699683","rc":[{"batb":[[0,2.38,5.4],[1,2.34,28.91],[2,1.25,100]],"ltp":2.38,"tv":4.29,"id":2780}]}]}
{"op":"mcm","clk":"11840501371","pt":1723547695345,"mc":[{"id":"1.231699683","rc":[{"batb":[[0,2.4,10],[1,2.38,5.4],[2,2.34,28.91]],"ltp":2.38,"tv":4.29,"id":2780}]}]}
{"op":"mcm","clk":"11840501558","pt":1723547698733,"mc":[{"id":"1.231699683","rc":[{"batb":[[0,2.38,5.4],[1,2.34,28.91],[2,1.25,100]],"ltp":2.38,"tv":4.29,"id":2780}]}]}
{"op":"mcm","clk":"11840501773","pt":1723547702178,"mc":[{"id":"1.231699683","rc":[{"batb":[[0,2.4,10],[1,2.38,5.4],[2,2.34,28.91]],"ltp":2.38,"tv":4.29,"id":2780}]}]}
{"op":"mcm","clk":"11840502006","pt":1723547705733,"mc":[{"id":"1.231699683","rc":[{"batb":[[0,2.38,5.4],[1,2.34,28.91],[2,1.25,100]],"ltp":2.38,"tv":4.29,"id":2780}]}]}
{"op":"mcm","clk":"11840502235","pt":1723547709439,"mc":[{"id":"1.231699683","rc":[{"batb":[[0,2.4,10],[1,2.38,5.4],[2,2.34,28.91]],"ltp":2.38,"tv":4.29,"id":2780}]}]}
{"op":"mcm","clk":"11840502424","pt":1723547712839,"mc":[{"id":"1.231699683","rc":[{"batb":[[0,2.38,5.4],[1,2.34,28.91],[2,1.25,100]],"ltp":2.38,"tv":4.29,"id":2780}]}]}
{"op":"mcm","clk":"11840502568","pt":1723547715871,"mc":[{"id":"1.231699683","rc":[{"batb":[[0,2.4,10],[1,2.38,5.4],[2,2.34,28.91]],"ltp":2.38,"tv":4.29,"id":2780}]}]}
{"op":"mcm","clk":"11840502751","pt":1723547719261,"mc":[{"id":"1.231699683","rc":[{"batb":[[0,2.38,5.4],[1,2.34,28.91],[2,1.25,100]],"ltp":2.38,"tv":4.29,"id":2780}]}]}
{"op":"mcm","clk":"11840502975","pt":1723547722651,"mc":[{"id":"1.231699683","rc":[{"batb":[[0,2.4,10],[1,2.38,5.4],[2,2.34,28.91]],"ltp":2.38,"tv":4.29,"id":2780}]}]}
{"op":"mcm","clk":"11840503162","pt":1723547725989,"mc":[{"id":"1.231699683","rc":[{"batb":[[0,2.38,5.4],[1,2.34,28.91],[2,1.25,100]],"ltp":2.38,"tv":4.29,"id":2780}]}]}
{"op":"mcm","clk":"11840503459","pt":1723547731368,"mc":[{"id":"1.231699683","rc":[{"batb":[[0,2.4,10],[1,2.38,5.4],[2,2.34,28.91]],"ltp":2.38,"tv":4.29,"id":2780}]}]}
{"op":"mcm","clk":"11840503779","pt":1723547736981,"mc":[{"id":"1.231699683","rc":[{"batb":[[0,2.38,5.4],[1,2.34,28.91],[2,1.25,100]],"ltp":2.38,"tv":4.29,"id":2780}]}]}
{"op":"mcm","clk":"11840504006","pt":1723547740791,"mc":[{"id":"1.231699683","rc":[{"batb":[[0,2.4,10],[1,2.38,5.4],[2,2.34,28.91]],"ltp":2.38,"tv":4.29,"id":2780}]}]}
{"op":"mcm","clk":"11840504194","pt":1723547744314,"mc":[{"id":"1.231699683","rc":[{"batb":[[0,2.38,5.4],[1,2.34,28.91],[2,1.25,100]],"ltp":2.38,"tv":4.29,"id":2780}]}]}
{"op":"mcm","clk":"11840504460","pt":1723547749601,"mc":[{"id":"1.231699683","rc":[{"batb":[[0,2.4,10],[1,2.38,5.4],[2,2.34,28.91]],"ltp":2.38,"tv":4.29,"id":2780}]}]}
{"op":"mcm","clk":"11840504641","pt":1723547753090,"mc":[{"id":"1.231699683","rc":[{"batb":[[0,2.38,5.4],[1,2.34,28.91],[2,1.25,100]],"ltp":2.38,"tv":4.29,"id":2780}]}]}
{"op":"mcm","clk":"11840504775","pt":1723547755504,"mc":[{"id":"1.231699683","rc":[{"batb":[[0,2.4,10],[1,2.38,5.4],[2,2.34,28.91]],"ltp":2.38,"tv":4.29,"id":2780}]}]}
{"op":"mcm","clk":"11840504960","pt":1723547759092,"mc":[{"id":"1.231699683","rc":[{"batb":[[0,2.38,5.4],[1,2.34,28.91],[2,1.25,100]],"ltp":2.38,"tv":4.29,"id":2780}]}]}
{"op":"mcm","clk":"11840505165","pt":1723547762304,"mc":[{"id":"1.231699683","rc":[{"batb":[[0,2.4,10],[1,2.38,5.4],[2,2.34,28.91]],"ltp":2.38,"tv":4.29,"id":2780}]}]}
{"op":"mcm","clk":"11840505326","pt":1723547765513,"mc":[{"id":"1.231699683","rc":[{"batb":[[0,2.38,5.4],[1,2.34,28.91],[2,1.25,100]],"ltp":2.38,"tv":4.29,"id":2780}]}]}
{"op":"mcm","clk":"11840505503","pt":1723547769013,"mc":[{"id":"1.231699683","rc":[{"batb":[[0,2.4,10],[1,2.38,5.4],[2,2.34,28.91]],"ltp":2.38,"tv":4.29,"id":2780}]}]}
{"op":"mcm","clk":"11840505741","pt":1723547773436,"mc":[{"id":"1.231699683","rc":[{"batb":[[0,2.38,5.4],[1,2.34,28.91],[2,1.25,100]],"ltp":2.38,"tv":4.29,"id":2780}]}]}
{"op":"mcm","clk":"11840505920","pt":1723547776833,"mc":[{"id":"1.231699683","rc":[{"batb":[[0,2.4,10],[1,2.38,5.4],[2,2.34,28.91]],"ltp":2.38,"tv":4.29,"id":2780}]}]}
{"op":"mcm","clk":"11840506139","pt":1723547780336,"mc":[{"id":"1.231699683","rc":[{"batb":[[0,2.38,5.4],[1,2.34,28.91],[2,1.25,100]],"ltp":2.38,"tv":4.29,"id":2780}]}]}
{"op":"mcm","clk":"11840506249","pt":1723547782809,"mc":[{"id":"1.231699683","rc":[{"batb":[[0,2.4,10],[1,2.38,5.4],[2,2.34,28.91]],"ltp":2.38,"tv":4.29,"id":2780}]}]}
{"op":"mcm","clk":"11840506444","pt":1723547786418,"mc":[{"id":"1.231699683","rc":[{"batb":[[0,2.38,5.4],[1,2.34,28.91],[2,1.25,100]],"ltp":2.38,"tv":4.29,"id":2780}]}]}
{"op":"mcm","clk":"11840506616","pt":1723547790220,"mc":[{"id":"1.231699683","rc":[{"batb":[[0,2.4,10],[1,2.38,5.4],[2,2.34,28.91]],"ltp":2.38,"tv":4.29,"id":2780}]}]}
{"op":"mcm","clk":"11840506791","pt":1723547793724,"mc":[{"id":"1.231699683","rc":[{"batb":[[0,2.38,5.4],[1,2.34,28.91],[2,1.25,100]],"ltp":2.38,"tv":4.29,"id":2780}]}]}
{"op":"mcm","clk":"11840506944","pt":1723547796755,"mc":[{"id":"1.231699683","rc":[{"batb":[[0,2.4,10],[1,2.38,5.4],[2,2.34,28.91]],"ltp":2.38,"tv":4.29,"id":2780}]}]}
{"op":"mcm","clk":"11840507138","pt":1723547800233,"mc":[{"id":"1.231699683","rc":[{"batb":[[0,2.38,5.4],[1,2.34,28.91],[2,1.25,100]],"ltp":2.38,"tv":4.29,"id":2780}]}]}
{"op":"mcm","clk":"11840507288","pt":1723547802651,"mc":[{"id":"1.231699683","rc":[{"batb":[[0,2.4,10],[1,2.38,5.4],[2,2.34,28.91]],"ltp":2.38,"tv":4.29,"id":2780}]}]}
{"op":"mcm","clk":"11840507483","pt":1723547806051,"mc":[{"id":"1.231699683","rc":[{"batb":[[0,2.38,5.4],[1,2.34,28.91],[2,1.25,100]],"ltp":2.38,"tv":4.29,"id":2780}]}]}
{"op":"mcm","clk":"11840507615","pt":1723547808358,"mc":[{"id":"1.231699683","rc":[{"batb":[[0,2.4,10],[1,2.38,5.4],[2,2.34,28.91]],"ltp":2.38,"tv":4.29,"id":2780}]}]}
{"op":"mcm","clk":"11840507800","pt":1723547811865,"mc":[{"id":"1.231699683","rc":[{"batb":[[0,2.38,5.4],[1,2.34,28.91],[2,1.25,100]],"ltp":2.38,"tv":4.29,"id":2780}]}]}
{"op":"mcm","clk":"11840507894","pt":1723547813567,"mc":[{"id":"1.231699683","rc":[{"batl":[[0,1.7,200],[1,1.72,9.82]],"ltp":1.64,"tv":404.0,"id":2120}]}]}
{"op":"mcm","clk":"11840507996","pt":1723547815679,"mc":[{"id":"1.231699683","rc":[{"batb":[[0,2.36,10]],"ltp":2.38,"tv":4.29,"id":2780},{"batl":[[1,1.72,0]],"ltp":1.64,"tv":404.0,"id":2120}]}]}
{"op":"mcm","clk":"11840508106","pt":1723547817951,"mc":[{"id":"1.231699683","rc":[{"batl":[[0,2.56,1.99],[1,2.58,1]],"ltp":2.38,"tv":4.29,"id":2780}]}]}
{"op":"mcm","clk":"11840508197","pt":1723547819344,"mc":[{"id":"1.231699683","rc":[{"batb":[[0,2.34,28.91],[1,1.25,100],[2,1.08,7.82]],"ltp":2.38,"tv":4.29,"id":2780}]}]}
{"op":"mcm","clk":"11840508464","pt":1723547824246,"mc":[{"id":"1.231699683","rc":[{"batb":[[0,2.36,10],[1,2.34,28.91],[2,1.25,100]],"ltp":2.38,"tv":4.29,"id":2780}]}]}
{"op":"mcm","clk":"11840508653","pt":1723547827553,"mc":[{"id":"1.231699683","rc":[{"batb":[[0,2.34,28.91],[1,1.25,100],[2,1.08,7.82]],"ltp":2.38,"tv":4.29,"id":2780}]}]}
{"op":"mcm","clk":"11840508838","pt":1723547830784,"mc":[{"id":"1.231699683","rc":[{"batb":[[0,2.36,10],[1,2.34,28.91],[2,1.25,100]],"ltp":2.38,"tv":4.29,"id":2780}]}]}
{"op":"mcm","clk":"11840509025","pt":1723547834182,"mc":[{"id":"1.231699683","rc":[{"batb":[[0,2.34,28.91],[1,1.25,100],[2,1.08,7.82]],"ltp":2.38,"tv":4.29,"id":2780}]}]}
{"op":"mcm","clk":"11840509687","pt":1723547845997,"mc":[{"id":"1.231699683","rc":[{"batb":[[0,2.36,10],[1,2.34,28.91],[2,1.25,100]],"ltp":2.38,"tv":4.29,"id":2780}]}]}
{"op":"mcm","clk":"11840509878","pt":1723547849295,"mc":[{"id":"1.231699683","rc":[{"batb":[[0,2.34,28.91],[1,1.25,100],[2,1.08,7.82]],"ltp":2.38,"tv":4.29,"id":2780}]}]}
{"op":"mcm","clk":"11840510002","pt":1723547851775,"mc":[{"id":"1.231699683","rc":[{"batb":[[0,2.36,10],[1,2.34,28.91],[2,1.25,100]],"ltp":2.38,"tv":4.29,"id":2780}]}]}
{"op":"mcm","clk":"11840510199","pt":1723547855297,"mc":[{"id":"1.231699683","rc":[{"batb":[[0,2.34,28.91],[1,1.25,100],[2,1.08,7.82]],"ltp":2.38,"tv":4.29,"id":2780}]}]}
{"op":"mcm","clk":"11840510483","pt":1723547860101,"mc":[{"id":"1.231699683","rc":[{"batb":[[0,2.36,10],[1,2.34,28.91],[2,1.25,100]],"ltp":2.38,"tv":4.29,"id":2780}]}]}
{"op":"mcm","clk":"11840510707","pt":1723547863912,"mc":[{"id":"1.231699683","rc":[{"batb":[[0,2.34,28.91],[1,1.25,100],[2,1.08,7.82]],"ltp":2.38,"tv":4.29,"id":2780}]}]}
{"op":"mcm","clk":"11840510882","pt":1723547866954,"mc":[{"id":"1.231699683","rc":[{"batb":[[0,2.36,10],[1,2.34,28.91],[2,1.25,100]],"ltp":2.38,"tv":4.29,"id":2780}]}]}
{"op":"mcm","clk":"11840511061","pt":1723547870346,"mc":[{"id":"1.231699683","rc":[{"batb":[[0,2.34,28.91],[1,1.25,100],[2,1.08,7.82]],"ltp":2.38,"tv":4.29,"id":2780}]}]}
{"op":"mcm","clk":"11840511376","pt":1723547876152,"mc":[{"id":"1.231699683","rc":[{"batb":[[0,2.36,10],[1,2.34,28.91],[2,1.25,100]],"ltp":2.38,"tv":4.29,"id":2780}]}]}
{"op":"mcm","clk":"11840511565","pt":1723547879655,"mc":[{"id":"1.231699683","rc":[{"batb":[[0,2.34,28.91],[1,1.25,100],[2,1.08,7.82]],"ltp":2.38,"tv":4.29,"id":2780}]}]}
{"op":"mcm","clk":"11840511753","pt":1723547882342,"mc":[{"id":"1.231699683","rc":[{"batb":[[0,2.36,10],[1,2.34,28.91],[2,1.25,100]],"ltp":2.38,"tv":4.29,"id":2780}]}]}
{"op":"mcm","clk":"11840511963","pt":1723547885842,"mc":[{"id":"1.231699683","rc":[{"batb":[[0,2.34,28.91],[1,1.25,100],[2,1.08,7.82]],"ltp":2.38,"tv":4.29,"id":2780}]}]}
{"op":"mcm","clk":"11840512128","pt":1723547888774,"mc":[{"id":"1.231699683","rc":[{"batb":[[0,2.36,10],[1,2.34,28.91],[2,1.25,100]],"ltp":2.38,"tv":4.29,"id":2780}]}]}
{"op":"mcm","clk":"11840512315","pt":1723547892066,"mc":[{"id":"1.231699683","rc":[{"batb":[[0,2.34,28.91],[1,1.25,100],[2,1.08,7.82]],"ltp":2.38,"tv":4.29,"id":2780}]}]}
{"op":"mcm","clk":"11840512441","pt":1723547894587,"mc":[{"id":"1.231699683","rc":[{"batb":[[0,2.36,10],[1,2.34,28.91],[2,1.25,100]],"ltp":2.38,"tv":4.29,"id":2780}]}]}
{"op":"mcm","clk":"11840512657","pt":1723547898293,"mc":[{"id":"1.231699683","rc":[{"batb":[[0,2.34,28.91],[1,1.25,100],[2,1.08,7.82]],"ltp":2.38,"tv":4.29,"id":2780}]}]}
{"op":"mcm","clk":"11840512894","pt":1723547902101,"mc":[{"id":"1.231699683","rc":[{"batb":[[0,2.36,10],[1,2.34,28.91],[2,1.25,100]],"ltp":2.38,"tv":4.29,"id":2780}]}]}
{"op":"mcm","clk":"11840513103","pt":1723547905495,"mc":[{"id":"1.231699683","rc":[{"batb":[[0,2.34,28.91],[1,1.25,100],[2,1.08,7.82]],"ltp":2.38,"tv":4.29,"id":2780}]}]}
{"op":"mcm","clk":"11840513504","pt":1723547912079,"mc":[{"id":"1.231699683","rc":[{"batb":[[0,2.36,10],[1,2.34,28.91],[2,1.25,100]],"ltp":2.38,"tv":4.29,"id":2780}]}]}
{"op":"mcm","clk":"11840513689","pt":1723547915500,"mc":[{"id":"1.231699683","rc":[{"batb":[[0,2.34,28.91],[1,1.25,100],[2,1.08,7.82]],"ltp":2.38,"tv":4.29,"id":2780}]}]}
{"op":"mcm","clk":"11840513912","pt":1723547919878,"mc":[{"id":"1.231699683","rc":[{"batb":[[0,2.36,10],[1,2.34,28.91],[2,1.25,100]],"ltp":2.38,"tv":4.29,"id":2780}]}]}
{"op":"mcm","clk":"11840514131","pt":1723547923496,"mc":[{"id":"1.231699683","rc":[{"batb":[[0,2.34,28.91],[1,1.25,100],[2,1.08,7.82]],"ltp":2.38,"tv":4.29,"id":2780}]}]}
{"op":"mcm","clk":"11840514380","pt":1723547928415,"mc":[{"id":"1.231699683","rc":[{"batb":[[0,2.36,10],[1,2.34,28.91],[2,1.25,100]],"ltp":2.38,"tv":4.29,"id":2780}]}]}
{"op":"mcm","clk":"11840514552","pt":1723547931908,"mc":[{"id":"1.231699683","rc":[{"batb":[[0,2.34,28.91],[1,1.25,100],[2,1.08,7.82]],"ltp":2.38,"tv":4.29,"id":2780}]}]}
{"op":"mcm","clk":"11840514732","pt":1723547934505,"mc":[{"id":"1.231699683","rc":[{"batb":[[0,2.36,10],[1,2.34,28.91],[2,1.25,100]],"ltp":2.38,"tv":4.29,"id":2780}]}]}
{"op":"mcm","clk":"11840514903","pt":1723547938035,"mc":[{"id":"1.231699683","rc":[{"batb":[[0,2.34,28.91],[1,1.25,100],[2,1.08,7.82]],"ltp":2.38,"tv":4.29,"id":2780}]}]}
{"op":"mcm","clk":"11840515075","pt":1723547941115,"mc":[{"id":"1.231699683","rc":[{"batb":[[0,2.36,10],[1,2.34,28.91],[2,1.25,100]],"ltp":2.38,"tv":4.29,"id":2780}]}]}
{"op":"mcm","clk":"11840515300","pt":1723547944724,"mc":[{"id":"1.231699683","rc":[{"batb":[[0,2.34,28.91],[1,1.25,100],[2,1.08,7.82]],"ltp":2.38,"tv":4.29,"id":2780}]}]}
{"op":"mcm","clk":"11840515642","pt":1723547950805,"mc":[{"id":"1.231699683","rc":[{"batb":[[0,2.36,10],[1,2.34,28.91],[2,1.25,100]],"ltp":2.38,"tv":4.29,"id":2780}]}]}
{"op":"mcm","clk":"11840515845","pt":1723547954350,"mc":[{"id":"1.231699683","rc":[{"batb":[[0,2.34,28.91],[1,1.25,100],[2,1.08,7.82]],"ltp":2.38,"tv":4.29,"id":2780}]}]}
{"op":"mcm","clk":"11840515945","pt":1723547956722,"mc":[{"id":"1.231699683","rc":[{"batb":[[0,2.36,10],[1,2.34,28.91],[2,1.25,100]],"ltp":2.38,"tv":4.29,"id":2780}]}]}
{"op":"mcm","clk":"11840516173","pt":1723547961034,"mc":[{"id":"1.231699683","rc":[{"batb":[[0,2.34,28.91],[1,1.25,100],[2,1.08,7.82]],"ltp":2.38,"tv":4.29,"id":2780}]}]}
{"op":"mcm","clk":"11840516310","pt":1723547963552,"mc":[{"id":"1.231699683","rc":[{"batb":[[0,2.36,10],[1,2.34,28.91],[2,1.25,100]],"ltp":2.38,"tv":4.29,"id":2780}]}]}
{"op":"mcm","clk":"11840516489","pt":1723547967055,"mc":[{"id":"1.231699683","rc":[{"batb":[[0,2.34,28.91],[1,1.25,100],[2,1.08,7.82]],"ltp":2.38,"tv":4.29,"id":2780}]}]}
{"op":"mcm","clk":"11840516628","pt":1723547969867,"mc":[{"id":"1.231699683","rc":[{"batb":[[0,2.36,10],[1,2.34,28.91],[2,1.25,100]],"ltp":2.38,"tv":4.29,"id":2780}]}]}
{"op":"mcm","clk":"11840516793","pt":1723547973262,"mc":[{"id":"1.231699683","rc":[{"batb":[[0,2.34,28.91],[1,1.25,100],[2,1.08,7.82]],"ltp":2.38,"tv":4.29,"id":2780}]}]}
{"op":"mcm","clk":"11840517003","pt":1723547977277,"mc":[{"id":"1.231699683","rc":[{"batb":[[0,2.36,10],[1,2.34,28.91],[2,1.25,100]],"ltp":2.38,"tv":4.29,"id":2780}]}]}
{"op":"mcm","clk":"11840517209","pt":1723547980544,"mc":[{"id":"1.231699683","rc":[{"batb":[[0,2.34,28.91],[1,1.25,100],[2,1.08,7.82]],"ltp":2.38,"tv":4.29,"id":2780}]}]}
{"op":"mcm","clk":"11840517485","pt":1723547986049,"mc":[{"id":"1.231699683","rc":[{"batb":[[0,2.36,10],[1,2.34,28.91],[2,1.25,100]],"ltp":2.38,"tv":4.29,"id":2780}]}]}
{"op":"mcm","clk":"11840517663","pt":1723547989386,"mc":[{"id":"1.231699683","rc":[{"batb":[[0,2.34,28.91],[1,1.25,100],[2,1.08,7.82]],"ltp":2.38,"tv":4.29,"id":2780}]}]}
{"op":"mcm","clk":"11840517790","pt":1723547992065,"mc":[{"id":"1.231699683","rc":[{"batb":[[0,2.36,10],[1,2.34,28.91],[2,1.25,100]],"ltp":2.38,"tv":4.29,"id":2780}]}]}
{"op":"mcm","clk":"11840517963","pt":1723547995300,"mc":[{"id":"1.231699683","rc":[{"batb":[[0,2.34,28.91],[1,1.25,100],[2,1.08,7.82]],"ltp":2.38,"tv":4.29,"id":2780}]}]}
{"op":"mcm","clk":"11840518080","pt":1723547997868,"mc":[{"id":"1.231699683","rc":[{"batb":[[0,2.36,10],[1,2.34,28.91],[2,1.25,100]],"ltp":2.38,"tv":4.29,"id":2780}]}]}
{"op":"mcm","clk":"11840518269","pt":1723548001177,"mc":[{"id":"1.231699683","rc":[{"batb":[[0,2.34,28.91],[1,1.25,100],[2,1.08,7.82]],"ltp":2.38,"tv":4.29,"id":2780}]}]}
{"op":"mcm","clk":"11840518574","pt":1723548006494,"mc":[{"id":"1.231699683","rc":[{"batb":[[0,2.36,10],[1,2.34,28.91],[2,1.25,100]],"ltp":2.38,"tv":4.29,"id":2780}]}]}
{"op":"mcm","clk":"11840518812","pt":1723548010620,"mc":[{"id":"1.231699683","rc":[{"batb":[[0,2.34,28.91],[1,1.25,100],[2,1.08,7.82]],"ltp":2.38,"tv":4.29,"id":2780}]}]}
{"op":"mcm","clk":"11840519011","pt":1723548014119,"mc":[{"id":"1.231699683","rc":[{"batb":[[0,2.36,10],[1,2.34,28.91],[2,1.25,100]],"ltp":2.38,"tv":4.29,"id":2780}]}]}
{"op":"mcm","clk":"11840519199","pt":1723548017715,"mc":[{"id":"1.231699683","rc":[{"batb":[[0,2.34,28.91],[1,1.25,100],[2,1.08,7.82]],"ltp":2.38,"tv":4.29,"id":2780}]}]}
{"op":"mcm","clk":"11840519442","pt":1723548022707,"mc":[{"id":"1.231699683","rc":[{"batb":[[0,2.36,10],[1,2.34,28.91],[2,1.25,100]],"ltp":2.38,"tv":4.29,"id":2780}]}]}
{"op":"mcm","clk":"11840519639","pt":1723548026010,"mc":[{"id":"1.231699683","rc":[{"batb":[[0,2.34,28.91],[1,1.25,100],[2,1.08,7.82]],"ltp":2.38,"tv":4.29,"id":2780}]}]}
{"op":"mcm","clk":"11840520009","pt":1723548032916,"mc":[{"id":"1.231699683","rc":[{"batb":[[0,2.36,10],[1,2.34,28.91],[2,1.25,100]],"ltp":2.38,"tv":4.29,"id":2780}]}]}
{"op":"mcm","clk":"11840520203","pt":1723548036311,"mc":[{"id":"1.231699683","rc":[{"batb":[[0,2.34,28.91],[1,1.25,100],[2,1.08,7.82]],"ltp":2.38,"tv":4.29,"id":2780}]}]}
{"op":"mcm","clk":"11840520490","pt":1723548041549,"mc":[{"id":"1.231699683","rc":[{"batb":[[0,2.36,10],[1,2.34,28.91],[2,1.25,100]],"ltp":2.38,"tv":4.29,"id":2780}]}]}
{"op":"mcm","clk":"11840520719","pt":1723548045622,"mc":[{"id":"1.231699683","rc":[{"batb":[[0,2.34,28.91],[1,1.25,100],[2,1.08,7.82]],"ltp":2.38,"tv":4.29,"id":2780}]}]}
{"op":"mcm","clk":"11840521058","pt":1723548051645,"mc":[{"id":"1.231699683","rc":[{"batb":[[0,2.36,10],[1,2.34,28.91],[2,1.25,100]],"ltp":2.38,"tv":4.29,"id":2780}]}]}
{"op":"mcm","clk":"11840521278","pt":1723548055047,"mc":[{"id":"1.231699683","rc":[{"batb":[[0,2.34,28.91],[1,1.25,100],[2,1.08,7.82]],"ltp":2.38,"tv":4.29,"id":2780}]}]}
{"op":"mcm","clk":"11840521447","pt":1723548057680,"mc":[{"id":"1.231699683","rc":[{"batb":[[0,2.36,10],[1,2.34,28.91],[2,1.25,100]],"ltp":2.38,"tv":4.29,"id":2780}]}]}
{"op":"mcm","clk":"11840521669","pt":1723548061251,"mc":[{"id":"1.231699683","rc":[{"batb":[[0,2.34,28.91],[1,1.25,100],[2,1.08,7.82]],"ltp":2.38,"tv":4.29,"id":2780}]}]}
{"op":"mcm","clk":"11840521900","pt":1723548065067,"mc":[{"id":"1.231699683","rc":[{"batb":[[0,2.36,10],[1,2.34,28.91],[2,1.25,100]],"ltp":2.38,"tv":4.29,"id":2780}]}]}
{"op":"mcm","clk":"11840522106","pt":1723548068472,"mc":[{"id":"1.231699683","rc":[{"batb":[[0,2.34,28.91],[1,1.25,100],[2,1.08,7.82]],"ltp":2.38,"tv":4.29,"id":2780}]}]}
{"op":"mcm","clk":"11840522287","pt":1723548071278,"mc":[{"id":"1.231699683","rc":[{"batb":[[0,2.36,10],[1,2.34,28.91],[2,1.25,100]],"ltp":2.38,"tv":4.29,"id":2780}]}]}
{"op":"mcm","clk":"11840522486","pt":1723548074689,"mc":[{"id":"1.231699683","rc":[{"batb":[[0,2.34,28.91],[1,1.25,100],[2,1.08,7.82]],"ltp":2.38,"tv":4.29,"id":2780}]}]}
{"op":"mcm","clk":"11840522731","pt":1723548078870,"mc":[{"id":"1.231699683","rc":[{"batb":[[0,2.36,10],[1,2.34,28.91],[2,1.25,100]],"ltp":2.38,"tv":4.29,"id":2780}]}]}
{"op":"mcm","clk":"11840522919","pt":1723548082203,"mc":[{"id":"1.231699683","rc":[{"batb":[[0,2.34,28.91],[1,1.25,100],[2,1.08,7.82]],"ltp":2.38,"tv":4.29,"id":2780}]}]}
{"op":"mcm","clk":"11840523186","pt":1723548087418,"mc":[{"id":"1.231699683","rc":[{"batb":[[0,2.36,10],[1,2.34,28.91],[2,1.25,100]],"ltp":2.38,"tv":4.29,"id":2780}]}]}
{"op":"mcm","clk":"11840523400","pt":1723548090916,"mc":[{"id":"1.231699683","rc":[{"batb":[[0,2.34,28.91],[1,1.25,100],[2,1.08,7.82]],"ltp":2.38,"tv":4.29,"id":2780}]}]}
{"op":"mcm","clk":"11840523644","pt":1723548095212,"mc":[{"id":"1.231699683","rc":[{"batb":[[0,2.36,10],[1,2.34,28.91],[2,1.25,100]],"ltp":2.38,"tv":4.29,"id":2780}]}]}
{"op":"mcm","clk":"11840523835","pt":1723548098617,"mc":[{"id":"1.231699683","rc":[{"batb":[[0,2.34,28.91],[1,1.25,100],[2,1.08,7.82]],"ltp":2.38,"tv":4.29,"id":2780}]}]}
{"op":"mcm","clk":"11840524068","pt":1723548102018,"mc":[{"id":"1.231699683","rc":[{"batb":[[0,2.36,10],[1,2.34,28.91],[2,1.25,100]],"ltp":2.38,"tv":4.29,"id":2780}]}]}
{"op":"mcm","clk":"11840524240","pt":1723548105529,"mc":[{"id":"1.231699683","rc":[{"batb":[[0,2.34,28.91],[1,1.25,100],[2,1.08,7.82]],"ltp":2.38,"tv":4.29,"id":2780}]}]}
{"op":"mcm","clk":"11840524427","pt":1723548108731,"mc":[{"id":"1.231699683","rc":[{"batb":[[0,2.36,10],[1,2.34,28.91],[2,1.25,100]],"ltp":2.38,"tv":4.29,"id":2780}]}]}
{"op":"mcm","clk":"11840524593","pt":1723548111921,"mc":[{"id":"1.231699683","rc":[{"batb":[[0,2.34,28.91],[1,1.25,100],[2,1.08,7.82]],"ltp":2.38,"tv":4.29,"id":2780}]}]}
{"op":"mcm","clk":"11840524795","pt":1723548115327,"mc":[{"id":"1.231699683","rc":[{"batb":[[0,2.36,10],[1,2.34,28.91],[2,1.25,100]],"ltp":2.38,"tv":4.29,"id":2780}]}]}
{"op":"mcm","clk":"11840524968","pt":1723548118630,"mc":[{"id":"1.231699683","rc":[{"batb":[[0,2.34,28.91],[1,1.25,100],[2,1.08,7.82]],"ltp":2.38,"tv":4.29,"id":2780}]}]}
{"op":"mcm","clk":"11840525109","pt":1723548121051,"mc":[{"id":"1.231699683","rc":[{"batb":[[0,2.36,10],[1,2.34,28.91],[2,1.25,100]],"ltp":2.38,"tv":4.29,"id":2780}]}]}
{"op":"mcm","clk":"11840525318","pt":1723548124559,"mc":[{"id":"1.231699683","rc":[{"batb":[[0,2.34,28.91],[1,1.25,100],[2,1.08,7.82]],"ltp":2.38,"tv":4.29,"id":2780}]}]}
{"op":"mcm","clk":"11840525532","pt":1723548128471,"mc":[{"id":"1.231699683","rc":[{"batb":[[0,2.36,10],[1,2.34,28.91],[2,1.25,100]],"ltp":2.38,"tv":4.29,"id":2780}]}]}
{"op":"mcm","clk":"11840525762","pt":1723548132278,"mc":[{"id":"1.231699683","rc":[{"batb":[[0,2.34,28.91],[1,1.25,100],[2,1.08,7.82]],"ltp":2.38,"tv":4.29,"id":2780}]}]}
{"op":"mcm","clk":"11840525966","pt":1723548135473,"mc":[{"id":"1.231699683","rc":[{"batb":[[0,2.36,10],[1,2.34,28.91],[2,1.25,100]],"ltp":2.38,"tv":4.29,"id":2780}]}]}
{"op":"mcm","clk":"11840526149","pt":1723548138972,"mc":[{"id":"1.231699683","rc":[{"batb":[[0,2.34,28.91],[1,1.25,100],[2,1.08,7.82]],"ltp":2.38,"tv":4.29,"id":2780}]}]}
{"op":"mcm","clk":"11840526306","pt":1723548141596,"mc":[{"id":"1.231699683","rc":[{"batb":[[0,2.36,10],[1,2.34,28.91],[2,1.25,100]],"ltp":2.38,"tv":4.29,"id":2780}]}]}
{"op":"mcm","clk":"11840526593","pt":1723548146962,"mc":[{"id":"1.231699683","rc":[{"batb":[[0,2.34,28.91],[1,1.25,100],[2,1.08,7.82]],"ltp":2.38,"tv":4.29,"id":2780}]}]}
{"op":"mcm","clk":"11840526748","pt":1723548149486,"mc":[{"id":"1.231699683","rc":[{"batb":[[0,2.36,10],[1,2.34,28.91],[2,1.25,100]],"ltp":2.38,"tv":4.29,"id":2780}]}]}
{"op":"mcm","clk":"11840526945","pt":1723548153081,"mc":[{"id":"1.231699683","rc":[{"batb":[[0,2.34,28.91],[1,1.25,100],[2,1.08,7.82]],"ltp":2.38,"tv":4.29,"id":2780}]}]}
{"op":"mcm","clk":"11840527088","pt":1723548155603,"mc":[{"id":"1.231699683","rc":[{"batb":[[0,2.36,10],[1,2.34,28.91],[2,1.25,100]],"ltp":2.38,"tv":4.29,"id":2780}]}]}
{"op":"mcm","clk":"11840527284","pt":1723548159122,"mc":[{"id":"1.231699683","rc":[{"batb":[[0,2.34,28.91],[1,1.25,100],[2,1.08,7.82]],"ltp":2.38,"tv":4.29,"id":2780}]}]}
{"op":"mcm","clk":"11840527422","pt":1723548161492,"mc":[{"id":"1.231699683","rc":[{"batb":[[0,2.36,10],[1,2.34,28.91],[2,1.25,100]],"ltp":2.38,"tv":4.29,"id":2780}]}]}
{"op":"mcm","clk":"11840527593","pt":1723548164985,"mc":[{"id":"1.231699683","rc":[{"batb":[[0,2.34,28.91],[1,1.25,100],[2,1.08,7.82]],"ltp":2.38,"tv":4.29,"id":2780}]}]}
{"op":"mcm","clk":"11840527734","pt":1723548167507,"mc":[{"id":"1.231699683","rc":[{"batb":[[0,2.36,10],[1,2.34,28.91],[2,1.25,100]],"ltp":2.38,"tv":4.29,"id":2780}]}]}
{"op":"mcm","clk":"11840527903","pt":1723548171145,"mc":[{"id":"1.231699683","rc":[{"batb":[[0,2.34,28.91],[1,1.25,100],[2,1.08,7.82]],"ltp":2.38,"tv":4.29,"id":2780}]}]}
{"op":"mcm","clk":"11840528006","pt":1723548173617,"mc":[{"id":"1.231699683","rc":[{"batb":[[0,2.36,10],[1,2.34,28.91],[2,1.25,100]],"ltp":2.38,"tv":4.29,"id":2780}]}]}
{"op":"mcm","clk":"11840528183","pt":1723548177151,"mc":[{"id":"1.231699683","rc":[{"batb":[[0,2.34,28.91],[1,1.25,100],[2,1.08,7.82]],"ltp":2.38,"tv":4.29,"id":2780}]}]}
{"op":"mcm","clk":"11840528427","pt":1723548181524,"mc":[{"id":"1.231699683","rc":[{"batb":[[0,2.36,10],[1,2.34,28.91],[2,1.25,100]],"ltp":2.38,"tv":4.29,"id":2780}]}]}
{"op":"mcm","clk":"11840528630","pt":1723548185021,"mc":[{"id":"1.231699683","rc":[{"batb":[[0,2.34,28.91],[1,1.25,100],[2,1.08,7.82]],"ltp":2.38,"tv":4.29,"id":2780}]}]}
{"op":"mcm","clk":"11840528806","pt":1723548188625,"mc":[{"id":"1.231699683","rc":[{"batb":[[0,2.36,10],[1,2.34,28.91],[2,1.25,100]],"ltp":2.38,"tv":4.29,"id":2780}]}]}
{"op":"mcm","clk":"11840528978","pt":1723548192162,"mc":[{"id":"1.231699683","rc":[{"batb":[[0,2.34,28.91],[1,1.25,100],[2,1.08,7.82]],"ltp":2.38,"tv":4.29,"id":2780}]}]}
{"op":"mcm","clk":"11840529119","pt":1723548195044,"mc":[{"id":"1.231699683","rc":[{"batb":[[0,2.36,10],[1,2.34,28.91],[2,1.25,100]],"ltp":2.38,"tv":4.29,"id":2780}]}]}
{"op":"mcm","clk":"11840529297","pt":1723548198542,"mc":[{"id":"1.231699683","rc":[{"batb":[[0,2.34,28.91],[1,1.25,100],[2,1.08,7.82]],"ltp":2.38,"tv":4.29,"id":2780}]}]}
{"op":"mcm","clk":"11840529399","pt":1723548200644,"mc":[{"id":"1.231699683","rc":[{"batb":[[0,2.36,10],[1,2.34,28.91],[2,1.25,100]],"ltp":2.38,"tv":4.29,"id":2780}]}]}
{"op":"mcm","clk":"11840529535","pt":1723548203877,"mc":[{"id":"1.231699683","rc":[{"batb":[[0,2.34,28.91],[1,1.25,100],[2,1.08,7.82]],"ltp":2.38,"tv":4.29,"id":2780}]}]}
{"op":"mcm","clk":"11840529691","pt":1723548207156,"mc":[{"id":"1.231699683","rc":[{"batb":[[0,2.36,10],[1,2.34,28.91],[2,1.25,100]],"ltp":2.38,"tv":4.29,"id":2780}]}]}
{"op":"mcm","clk":"11840529892","pt":1723548210552,"mc":[{"id":"1.231699683","rc":[{"batb":[[0,2.34,28.91],[1,1.25,100],[2,1.08,7.82]],"ltp":2.38,"tv":4.29,"id":2780}]}]}
{"op":"mcm","clk":"11840530011","pt":1723548213069,"mc":[{"id":"1.231699683","rc":[{"batb":[[0,2.36,10],[1,2.34,28.91],[2,1.25,100]],"ltp":2.38,"tv":4.29,"id":2780}]}]}
{"op":"mcm","clk":"11840530173","pt":1723548216567,"mc":[{"id":"1.231699683","rc":[{"batb":[[0,2.34,28.91],[1,1.25,100],[2,1.08,7.82]],"ltp":2.38,"tv":4.29,"id":2780}]}]}
{"op":"mcm","clk":"11840530280","pt":1723548218780,"mc":[{"id":"1.231699683","rc":[{"batb":[[0,2.36,10],[1,2.34,28.91],[2,1.25,100]],"ltp":2.38,"tv":4.29,"id":2780}]}]}
{"op":"mcm","clk":"11840530441","pt":1723548222178,"mc":[{"id":"1.231699683","rc":[{"batb":[[0,2.34,28.91],[1,1.25,100],[2,1.08,7.82]],"ltp":2.38,"tv":4.29,"id":2780}]}]}
{"op":"mcm","clk":"11840530563","pt":1723548224797,"mc":[{"id":"1.231699683","rc":[{"batb":[[0,2.36,10],[1,2.34,28.91],[2,1.25,100]],"ltp":2.38,"tv":4.29,"id":2780}]}]}
{"op":"mcm","clk":"11840530758","pt":1723548228407,"mc":[{"id":"1.231699683","rc":[{"batb":[[0,2.34,28.91],[1,1.25,100],[2,1.08,7.82]],"ltp":2.38,"tv":4.29,"id":2780}]}]}
{"op":"mcm","clk":"11840530931","pt":1723548232275,"mc":[{"id":"1.231699683","rc":[{"batb":[[0,2.36,10],[1,2.34,28.91],[2,1.25,100]],"ltp":2.38,"tv":4.29,"id":2780}]}]}
{"op":"mcm","clk":"11840531094","pt":1723548235814,"mc":[{"id":"1.231699683","rc":[{"batb":[[0,2.34,28.91],[1,1.25,100],[2,1.08,7.82]],"ltp":2.38,"tv":4.29,"id":2780}]}]}
{"op":"mcm","clk":"11840531278","pt":1723548239715,"mc":[{"id":"1.231699683","rc":[{"batb":[[0,2.36,10],[1,2.34,28.91],[2,1.25,100]],"ltp":2.38,"tv":4.29,"id":2780}]}]}
{"op":"mcm","clk":"11840531518","pt":1723548243396,"mc":[{"id":"1.231699683","rc":[{"batb":[[0,2.34,28.91],[1,1.25,100],[2,1.08,7.82]],"ltp":2.38,"tv":4.29,"id":2780}]}]}
{"op":"mcm","clk":"11840531694","pt":1723548246298,"mc":[{"id":"1.231699683","rc":[{"batb":[[0,2.36,10],[1,2.34,28.91],[2,1.25,100]],"ltp":2.38,"tv":4.29,"id":2780}]}]}
{"op":"mcm","clk":"11840531904","pt":1723548249802,"mc":[{"id":"1.231699683","rc":[{"batb":[[0,2.34,28.91],[1,1.25,100],[2,1.08,7.82]],"ltp":2.38,"tv":4.29,"id":2780}]}]}
{"op":"mcm","clk":"11840532026","pt":1723548252116,"mc":[{"id":"1.231699683","rc":[{"batb":[[0,2.36,10],[1,2.34,28.91],[2,1.25,100]],"ltp":2.38,"tv":4.29,"id":2780}]}]}
{"op":"mcm","clk":"11840532226","pt":1723548255733,"mc":[{"id":"1.231699683","rc":[{"batb":[[0,2.34,28.91],[1,1.25,100],[2,1.08,7.82]],"ltp":2.38,"tv":4.29,"id":2780}]}]}
{"op":"mcm","clk":"11840532376","pt":1723548258310,"mc":[{"id":"1.231699683","rc":[{"batb":[[0,2.36,10],[1,2.34,28.91],[2,1.25,100]],"ltp":2.38,"tv":4.29,"id":2780}]}]}
{"op":"mcm","clk":"11840532555","pt":1723548261613,"mc":[{"id":"1.231699683","rc":[{"batb":[[0,2.34,28.91],[1,1.25,100],[2,1.08,7.82]],"ltp":2.38,"tv":4.29,"id":2780}]}]}
{"op":"mcm","clk":"11840532692","pt":1723548264125,"mc":[{"id":"1.231699683","rc":[{"batb":[[0,2.36,10],[1,2.34,28.91],[2,1.25,100]],"ltp":2.38,"tv":4.29,"id":2780}]}]}
{"op":"mcm","clk":"11840532874","pt":1723548267519,"mc":[{"id":"1.231699683","rc":[{"batb":[[0,2.34,28.91],[1,1.25,100],[2,1.08,7.82]],"ltp":2.38,"tv":4.29,"id":2780}]}]}
{"op":"mcm","clk":"11840533008","pt":1723548269823,"mc":[{"id":"1.231699683","rc":[{"batb":[[0,2.36,10],[1,2.34,28.91],[2,1.25,100]],"ltp":2.38,"tv":4.29,"id":2780}]}]}
{"op":"mcm","clk":"11840533183","pt":1723548273122,"mc":[{"id":"1.231699683","rc":[{"batb":[[0,2.34,28.91],[1,1.25,100],[2,1.08,7.82]],"ltp":2.38,"tv":4.29,"id":2780}]}]}
{"op":"mcm","clk":"11840533322","pt":1723548275437,"mc":[{"id":"1.231699683","rc":[{"batb":[[0,2.36,10],[1,2.34,28.91],[2,1.25,100]],"ltp":2.38,"tv":4.29,"id":2780}]}]}
{"op":"mcm","clk":"11840533519","pt":1723548278842,"mc":[{"id":"1.231699683","rc":[{"batb":[[0,2.34,28.91],[1,1.25,100],[2,1.08,7.82]],"ltp":2.38,"tv":4.29,"id":2780}]}]}
{"op":"mcm","clk":"11840533738","pt":1723548282346,"mc":[{"id":"1.231699683","rc":[{"batb":[[0,2.36,10],[1,2.34,28.91],[2,1.25,100]],"ltp":2.38,"tv":4.29,"id":2780}]}]}
{"op":"mcm","clk":"11840533904","pt":1723548285643,"mc":[{"id":"1.231699683","rc":[{"batb":[[0,2.34,28.91],[1,1.25,100],[2,1.08,7.82]],"ltp":2.38,"tv":4.29,"id":2780}]}]}
{"op":"mcm","clk":"11840534239","pt":1723548291457,"mc":[{"id":"1.231699683","rc":[{"batb":[[0,2.36,10],[1,2.34,28.91],[2,1.25,100]],"ltp":2.38,"tv":4.29,"id":2780}]}]}
{"op":"mcm","clk":"11840534424","pt":1723548294927,"mc":[{"id":"1.231699683","rc":[{"batb":[[0,2.34,28.91],[1,1.25,100],[2,1.08,7.82]],"ltp":2.38,"tv":4.29,"id":2780}]}]}
{"op":"mcm","clk":"11840534624","pt":1723548298854,"mc":[{"id":"1.231699683","rc":[{"batb":[[0,2.36,10],[1,2.34,28.91],[2,1.25,100]],"ltp":2.38,"tv":4.29,"id":2780}]}]}
{"op":"mcm","clk":"11840534827","pt":1723548302082,"mc":[{"id":"1.231699683","rc":[{"batb":[[0,2.34,28.91],[1,1.25,100],[2,1.08,7.82]],"ltp":2.38,"tv":4.29,"id":2780}]}]}
{"op":"mcm","clk":"11840535126","pt":1723548307090,"mc":[{"id":"1.231699683","rc":[{"batb":[[0,2.36,10],[1,2.34,28.91],[2,1.25,100]],"ltp":2.38,"tv":4.29,"id":2780}]}]}
{"op":"mcm","clk":"11840535286","pt":1723548310361,"mc":[{"id":"1.231699683","rc":[{"batb":[[0,2.34,28.91],[1,1.25,100],[2,1.08,7.82]],"ltp":2.38,"tv":4.29,"id":2780}]}]}
{"op":"mcm","clk":"11840535486","pt":1723548314184,"mc":[{"id":"1.231699683","rc":[{"batb":[[0,2.36,10],[1,2.34,28.91],[2,1.25,100]],"ltp":2.38,"tv":4.29,"id":2780}]}]}
{"op":"mcm","clk":"11840535663","pt":1723548317389,"mc":[{"id":"1.231699683","rc":[{"batb":[[0,2.34,28.91],[1,1.25,100],[2,1.08,7.82]],"ltp":2.38,"tv":4.29,"id":2780}]}]}
{"op":"mcm","clk":"11840535953","pt":1723548322876,"mc":[{"id":"1.231699683","rc":[{"batb":[[0,2.36,10],[1,2.34,28.91],[2,1.25,100]],"ltp":2.38,"tv":4.29,"id":2780}]}]}
{"op":"mcm","clk":"11840536145","pt":1723548326388,"mc":[{"id":"1.231699683","rc":[{"batb":[[0,2.34,28.91],[1,1.25,100],[2,1.08,7.82]],"ltp":2.38,"tv":4.29,"id":2780}]}]}
{"op":"mcm","clk":"11840536750","pt":1723548335792,"mc":[{"id":"1.231699683","rc":[{"batb":[[0,2.36,10],[1,2.34,28.91],[2,1.25,100]],"ltp":2.38,"tv":4.29,"id":2780}]}]}
{"op":"mcm","clk":"11840536951","pt":1723548339194,"mc":[{"id":"1.231699683","rc":[{"batb":[[0,2.34,28.91],[1,1.25,100],[2,1.08,7.82]],"ltp":2.38,"tv":4.29,"id":2780}]}]}
{"op":"mcm","clk":"11840537143","pt":1723548342593,"mc":[{"id":"1.231699683","rc":[{"batb":[[0,2.36,10],[1,2.34,28.91],[2,1.25,100]],"ltp":2.38,"tv":4.29,"id":2780}]}]}
{"op":"mcm","clk":"11840537305","pt":1723548345985,"mc":[{"id":"1.231699683","rc":[{"batb":[[0,2.34,28.91],[1,1.25,100],[2,1.08,7.82]],"ltp":2.38,"tv":4.29,"id":2780}]}]}
{"op":"mcm","clk":"11840537560","pt":1723548349905,"mc":[{"id":"1.231699683","rc":[{"batb":[[0,2.36,10],[1,2.34,28.91],[2,1.25,100]],"ltp":2.38,"tv":4.29,"id":2780}]}]}
{"op":"mcm","clk":"11840537746","pt":1723548353301,"mc":[{"id":"1.231699683","rc":[{"batb":[[0,2.34,28.91],[1,1.25,100],[2,1.08,7.82]],"ltp":2.38,"tv":4.29,"id":2780}]}]}
{"op":"mcm","clk":"11840537879","pt":1723548355618,"mc":[{"id":"1.231699683","rc":[{"batb":[[0,2.36,10],[1,2.34,28.91],[2,1.25,100]],"ltp":2.38,"tv":4.29,"id":2780}]}]}
{"op":"mcm","clk":"11840538054","pt":1723548359020,"mc":[{"id":"1.231699683","rc":[{"batb":[[0,2.34,28.91],[1,1.25,100],[2,1.08,7.82]],"ltp":2.38,"tv":4.29,"id":2780}]}]}
{"op":"mcm","clk":"11840538320","pt":1723548363711,"mc":[{"id":"1.231699683","rc":[{"batb":[[0,2.36,10],[1,2.34,28.91],[2,1.25,100]],"ltp":2.38,"tv":4.29,"id":2780}]}]}
{"op":"mcm","clk":"11840538498","pt":1723548367718,"mc":[{"id":"1.231699683","rc":[{"batb":[[0,2.34,28.91],[1,1.25,100],[2,1.08,7.82]],"ltp":2.38,"tv":4.29,"id":2780}]}]}
{"op":"mcm","clk":"11840538813","pt":1723548373328,"mc":[{"id":"1.231699683","rc":[{"batb":[[0,2.36,10],[1,2.34,28.91],[2,1.25,100]],"ltp":2.38,"tv":4.29,"id":2780}]}]}
{"op":"mcm","clk":"11840538982","pt":1723548376559,"mc":[{"id":"1.231699683","rc":[{"batb":[[0,2.34,28.91],[1,1.25,100],[2,1.08,7.82]],"ltp":2.38,"tv":4.29,"id":2780}]}]}
{"op":"mcm","clk":"11840539198","pt":1723548380771,"mc":[{"id":"1.231699683","rc":[{"batb":[[0,2.36,10],[1,2.34,28.91],[2,1.25,100]],"ltp":2.38,"tv":4.29,"id":2780}]}]}
{"op":"mcm","clk":"11840539369","pt":1723548384159,"mc":[{"id":"1.231699683","rc":[{"batb":[[0,2.34,28.91],[1,1.25,100],[2,1.08,7.82]],"ltp":2.38,"tv":4.29,"id":2780}]}]}
{"op":"mcm","clk":"11840539535","pt":1723548387147,"mc":[{"id":"1.231699683","rc":[{"batb":[[0,2.36,10],[1,2.34,28.91],[2,1.25,100]],"ltp":2.38,"tv":4.29,"id":2780}]}]}
{"op":"mcm","clk":"11840539684","pt":1723548390449,"mc":[{"id":"1.231699683","rc":[{"batb":[[0,2.34,28.91],[1,1.25,100],[2,1.08,7.82]],"ltp":2.38,"tv":4.29,"id":2780}]}]}
{"op":"mcm","clk":"11840540040","pt":1723548398291,"mc":[{"id":"1.231699683","rc":[{"batb":[[0,2.36,10],[1,2.34,28.91],[2,1.25,100]],"ltp":2.38,"tv":4.29,"id":2780}]}]}
{"op":"mcm","clk":"11840540191","pt":1723548401780,"mc":[{"id":"1.231699683","rc":[{"batb":[[0,2.34,28.91],[1,1.25,100],[2,1.08,7.82]],"ltp":2.38,"tv":4.29,"id":2780}]}]}
{"op":"mcm","clk":"11840540356","pt":1723548405693,"mc":[{"id":"1.231699683","rc":[{"batb":[[0,2.36,10],[1,2.34,28.91],[2,1.25,100]],"ltp":2.38,"tv":4.29,"id":2780}]}]}
{"op":"mcm","clk":"11840540502","pt":1723548409185,"mc":[{"id":"1.231699683","rc":[{"batb":[[0,2.34,28.91],[1,1.25,100],[2,1.08,7.82]],"ltp":2.38,"tv":4.29,"id":2780}]}]}
{"op":"mcm","clk":"11840540663","pt":1723548412676,"mc":[{"id":"1.231699683","rc":[{"batb":[[0,2.36,10],[1,2.34,28.91],[2,1.25,100]],"ltp":2.38,"tv":4.29,"id":2780}]}]}
{"op":"mcm","clk":"11840540822","pt":1723548416216,"mc":[{"id":"1.231699683","rc":[{"batb":[[0,2.34,28.91],[1,1.25,100],[2,1.08,7.82]],"ltp":2.38,"tv":4.29,"id":2780}]}]}
{"op":"mcm","clk":"11840540918","pt":1723548418316,"mc":[{"id":"1.231699683","rc":[{"batb":[[0,2.36,10],[1,2.34,28.91],[2,1.25,100]],"ltp":2.38,"tv":4.29,"id":2780}]}]}
{"op":"mcm","clk":"11840541106","pt":1723548421720,"mc":[{"id":"1.231699683","rc":[{"batb":[[0,2.34,28.91],[1,1.25,100],[2,1.08,7.82]],"ltp":2.38,"tv":4.29,"id":2780}]}]}
{"op":"mcm","clk":"11840541321","pt":1723548425636,"mc":[{"id":"1.231699683","rc":[{"batb":[[0,2.36,10],[1,2.34,28.91],[2,1.25,100]],"ltp":2.38,"tv":4.29,"id":2780}]}]}
{"op":"mcm","clk":"11840541486","pt":1723548429138,"mc":[{"id":"1.231699683","rc":[{"batb":[[0,2.34,28.91],[1,1.25,100],[2,1.08,7.82]],"ltp":2.38,"tv":4.29,"id":2780}]}]}
{"op":"mcm","clk":"11840541706","pt":1723548433925,"mc":[{"id":"1.231699683","rc":[{"batb":[[0,2.36,10],[1,2.34,28.91],[2,1.25,100]],"ltp":2.38,"tv":4.29,"id":2780}]}]}
{"op":"mcm","clk":"11840541876","pt":1723548437316,"mc":[{"id":"1.231699683","rc":[{"batb":[[0,2.34,28.91],[1,1.25,100],[2,1.08,7.82]],"ltp":2.38,"tv":4.29,"id":2780}]}]}
{"op":"mcm","clk":"11840542006","pt":1723548440753,"mc":[{"id":"1.231699683","rc":[{"batb":[[0,2.36,10],[1,2.34,28.91],[2,1.25,100]],"ltp":2.38,"tv":4.29,"id":2780}]}]}
{"op":"mcm","clk":"11840542162","pt":1723548444256,"mc":[{"id":"1.231699683","rc":[{"batb":[[0,2.34,28.91],[1,1.25,100],[2,1.08,7.82]],"ltp":2.38,"tv":4.29,"id":2780}]}]}
{"op":"mcm","clk":"11840542341","pt":1723548448260,"mc":[{"id":"1.231699683","rc":[{"batb":[[0,2.36,10],[1,2.34,28.91],[2,1.25,100]],"ltp":2.38,"tv":4.29,"id":2780}]}]}
{"op":"mcm","clk":"11840542509","pt":1723548451655,"mc":[{"id":"1.231699683","rc":[{"batb":[[0,2.34,28.91],[1,1.25,100],[2,1.08,7.82]],"ltp":2.38,"tv":4.29,"id":2780}]}]}
{"op":"mcm","clk":"11840542745","pt":1723548458072,"mc":[{"id":"1.231699683","rc":[{"batb":[[0,2.36,10],[1,2.34,28.91],[2,1.25,100]],"ltp":2.38,"tv":4.29,"id":2780}]}]}
{"op":"mcm","clk":"11840542914","pt":1723548461563,"mc":[{"id":"1.231699683","rc":[{"batb":[[0,2.34,28.91],[1,1.25,100],[2,1.08,7.82]],"ltp":2.38,"tv":4.29,"id":2780}]}]}
{"op":"mcm","clk":"11840543065","pt":1723548465163,"mc":[{"id":"1.231699683","rc":[{"batb":[[0,2.36,10],[1,2.34,28.91],[2,1.25,100]],"ltp":2.38,"tv":4.29,"id":2780}]}]}
{"op":"mcm","clk":"11840543238","pt":1723548468771,"mc":[{"id":"1.231699683","rc":[{"batb":[[0,2.34,28.91],[1,1.25,100],[2,1.08,7.82]],"ltp":2.38,"tv":4.29,"id":2780}]}]}
{"op":"mcm","clk":"11840543512","pt":1723548474678,"mc":[{"id":"1.231699683","rc":[{"batb":[[0,2.36,10],[1,2.34,28.91],[2,1.25,100]],"ltp":2.38,"tv":4.29,"id":2780}]}]}
{"op":"mcm","clk":"11840543697","pt":1723548478284,"mc":[{"id":"1.231699683","rc":[{"batb":[[0,2.34,28.91],[1,1.25,100],[2,1.08,7.82]],"ltp":2.38,"tv":4.29,"id":2780}]}]}
{"op":"mcm","clk":"11840544215","pt":1723548487794,"mc":[{"id":"1.231699683","rc":[{"batb":[[0,2.36,10],[1,2.34,28.91],[2,1.25,100]],"ltp":2.38,"tv":4.29,"id":2780}]}]}
{"op":"mcm","clk":"11840544431","pt":1723548491515,"mc":[{"id":"1.231699683","rc":[{"batb":[[0,2.34,28.91],[1,1.25,100],[2,1.08,7.82]],"ltp":2.38,"tv":4.29,"id":2780}]}]}
{"op":"mcm","clk":"11840544528","pt":1723548493796,"mc":[{"id":"1.231699683","rc":[{"batb":[[0,2.36,10],[1,2.34,28.91],[2,1.25,100]],"ltp":2.38,"tv":4.29,"id":2780}]}]}
{"op":"mcm","clk":"11840544714","pt":1723548497197,"mc":[{"id":"1.231699683","rc":[{"batb":[[0,2.34,28.91],[1,1.25,100],[2,1.08,7.82]],"ltp":2.38,"tv":4.29,"id":2780}]}]}
{"op":"mcm","clk":"11840544844","pt":1723548499820,"mc":[{"id":"1.231699683","rc":[{"batb":[[0,2.36,10],[1,2.34,28.91],[2,1.25,100]],"ltp":2.38,"tv":4.29,"id":2780}]}]}
{"op":"mcm","clk":"11840545008","pt":1723548503525,"mc":[{"id":"1.231699683","rc":[{"batb":[[0,2.34,28.91],[1,1.25,100],[2,1.08,7.82]],"ltp":2.38,"tv":4.29,"id":2780}]}]}
{"op":"mcm","clk":"11840545308","pt":1723548509493,"mc":[{"id":"1.231699683","rc":[{"batb":[[0,2.36,10],[1,2.34,28.91],[2,1.25,100]],"ltp":2.38,"tv":4.29,"id":2780}]}]}
{"op":"mcm","clk":"11840545505","pt":1723548513406,"mc":[{"id":"1.231699683","rc":[{"batb":[[0,2.34,28.91],[1,1.25,100],[2,1.08,7.82]],"ltp":2.38,"tv":4.29,"id":2780}]}]}
{"op":"mcm","clk":"11840545628","pt":1723548515924,"mc":[{"id":"1.231699683","rc":[{"batb":[[0,2.36,10],[1,2.34,28.91],[2,1.25,100]],"ltp":2.38,"tv":4.29,"id":2780}]}]}
{"op":"mcm","clk":"11840545853","pt":1723548519912,"mc":[{"id":"1.231699683","rc":[{"batb":[[0,2.34,28.91],[1,1.25,100],[2,1.08,7.82]],"ltp":2.38,"tv":4.29,"id":2780}]}]}
{"op":"mcm","clk":"11840546062","pt":1723548523720,"mc":[{"id":"1.231699683","rc":[{"batb":[[0,2.36,10],[1,2.34,28.91],[2,1.25,100]],"ltp":2.38,"tv":4.29,"id":2780}]}]}
{"op":"mcm","clk":"11840546223","pt":1723548527051,"mc":[{"id":"1.231699683","rc":[{"batb":[[0,2.34,28.91],[1,1.25,100],[2,1.08,7.82]],"ltp":2.38,"tv":4.29,"id":2780}]}]}
{"op":"mcm","clk":"11840546407","pt":1723548530338,"mc":[{"id":"1.231699683","rc":[{"batb":[[0,2.36,10],[1,2.34,28.91],[2,1.25,100]],"ltp":2.38,"tv":4.29,"id":2780}]}]}
{"op":"mcm","clk":"11840546604","pt":1723548534147,"mc":[{"id":"1.231699683","rc":[{"batb":[[0,2.34,28.91],[1,1.25,100],[2,1.08,7.82]],"ltp":2.38,"tv":4.29,"id":2780}]}]}
{"op":"mcm","clk":"11840546740","pt":1723548536554,"mc":[{"id":"1.231699683","rc":[{"batb":[[0,2.36,10],[1,2.34,28.91],[2,1.25,100]],"ltp":2.38,"tv":4.29,"id":2780},{"batl":[[0,1.69,9.82],[1,1.7,200]],"ltp":1.64,"tv":404.0,"id":2120}]}]}
{"op":"mcm","clk":"11840546912","pt":1723548539737,"mc":[{"id":"1.231699683","rc":[{"batb":[[0,2.34,28.91],[1,1.25,100],[2,1.08,7.82]],"ltp":2.38,"tv":4.29,"id":2780}]}]}
{"op":"mcm","clk":"11840547199","pt":1723548544983,"mc":[{"id":"1.231699683","rc":[{"batb":[[0,2.36,10],[1,2.34,28.91],[2,1.25,100]],"ltp":2.38,"tv":4.29,"id":2780}]}]}
{"op":"mcm","clk":"11840547377","pt":1723548548386,"mc":[{"id":"1.231699683","rc":[{"batb":[[0,2.34,28.91],[1,1.25,100],[2,1.08,7.82]],"ltp":2.38,"tv":4.29,"id":2780}]}]}
{"op":"mcm","clk":"11840547702","pt":1723548553779,"mc":[{"id":"1.231699683","rc":[{"batb":[[0,2.36,10],[1,2.34,28.91],[2,1.25,100]],"ltp":2.38,"tv":4.29,"id":2780}]}]}
{"op":"mcm","clk":"11840547921","pt":1723548557274,"mc":[{"id":"1.231699683","rc":[{"batb":[[0,2.34,28.91],[1,1.25,100],[2,1.08,7.82]],"ltp":2.38,"tv":4.29,"id":2780}]}]}
{"op":"mcm","clk":"11840548133","pt":1723548561577,"mc":[{"id":"1.231699683","rc":[{"batb":[[0,2.36,10],[1,2.34,28.91],[2,1.25,100]],"ltp":2.38,"tv":4.29,"id":2780}]}]}
{"op":"mcm","clk":"11840548284","pt":1723548564965,"mc":[{"id":"1.231699683","rc":[{"batb":[[0,2.34,28.91],[1,1.25,100],[2,1.08,7.82]],"ltp":2.38,"tv":4.29,"id":2780}]}]}
{"op":"mcm","clk":"11840548423","pt":1723548568194,"mc":[{"id":"1.231699683","rc":[{"batb":[[0,2.36,10],[1,2.34,28.91],[2,1.25,100]],"ltp":2.38,"tv":4.29,"id":2780}]}]}
{"op":"mcm","clk":"11840548605","pt":1723548571696,"mc":[{"id":"1.231699683","rc":[{"batb":[[0,2.34,28.91],[1,1.25,100],[2,1.08,7.82]],"ltp":2.38,"tv":4.29,"id":2780}]}]}
{"op":"mcm","clk":"11840548949","pt":1723548578312,"mc":[{"id":"1.231699683","rc":[{"batb":[[0,2.36,10],[1,2.34,28.91],[2,1.25,100]],"ltp":2.38,"tv":4.29,"id":2780}]}]}
{"op":"mcm","clk":"11840549141","pt":1723548581817,"mc":[{"id":"1.231699683","rc":[{"batb":[[0,2.34,28.91],[1,1.25,100],[2,1.08,7.82]],"ltp":2.38,"tv":4.29,"id":2780}]}]}
{"op":"mcm","clk":"11840549633","pt":1723548592394,"mc":[{"id":"1.231699683","rc":[{"batb":[[0,2.36,10],[1,2.34,28.91],[2,1.25,100]],"ltp":2.38,"tv":4.29,"id":2780}]}]}
{"op":"mcm","clk":"11840549809","pt":1723548595891,"mc":[{"id":"1.231699683","rc":[{"batb":[[0,2.34,28.91],[1,1.25,100],[2,1.08,7.82]],"ltp":2.38,"tv":4.29,"id":2780}]}]}
{"op":"mcm","clk":"11840549964","pt":1723548599630,"mc":[{"id":"1.231699683","rc":[{"batb":[[0,2.36,10],[1,2.34,28.91],[2,1.25,100]],"ltp":2.38,"tv":4.29,"id":2780}]}]}
{"op":"mcm","clk":"11840550203","pt":1723548603207,"mc":[{"id":"1.231699683","rc":[{"batb":[[0,2.34,28.91],[1,1.25,100],[2,1.08,7.82]],"ltp":2.38,"tv":4.29,"id":2780}]}]}
{"op":"mcm","clk":"11840550352","pt":1723548605522,"mc":[{"id":"1.231699683","rc":[{"batb":[[0,2.36,10],[1,2.34,28.91],[2,1.25,100]],"ltp":2.38,"tv":4.29,"id":2780}]}]}
{"op":"mcm","clk":"11840550589","pt":1723548609020,"mc":[{"id":"1.231699683","rc":[{"batb":[[0,2.34,28.91],[1,1.25,100],[2,1.08,7.82]],"ltp":2.38,"tv":4.29,"id":2780}]}]}
{"op":"mcm","clk":"11840550706","pt":1723548611431,"mc":[{"id":"1.231699683","rc":[{"batb":[[0,2.36,10],[1,2.34,28.91],[2,1.25,100]],"ltp":2.38,"tv":4.29,"id":2780}]}]}
{"op":"mcm","clk":"11840550981","pt":1723548615045,"mc":[{"id":"1.231699683","rc":[{"batb":[[0,2.34,28.91],[1,1.25,100],[2,1.08,7.82]],"ltp":2.38,"tv":4.29,"id":2780}]}]}
{"op":"mcm","clk":"11840551705","pt":1723548627237,"mc":[{"id":"1.231699683","rc":[{"batb":[[0,2.36,10],[1,2.34,28.91],[2,1.25,100]],"ltp":2.38,"tv":4.29,"id":2780}]}]}
{"op":"mcm","clk":"11840551899","pt":1723548631027,"mc":[{"id":"1.231699683","rc":[{"batb":[[0,2.34,28.91],[1,1.25,100],[2,1.08,7.82]],"ltp":2.38,"tv":4.29,"id":2780}]}]}
{"op":"mcm","clk":"11840552231","pt":1723548636129,"mc":[{"id":"1.231699683","rc":[{"batb":[[0,2.36,10],[1,2.34,28.91],[2,1.25,100]],"ltp":2.38,"tv":4.29,"id":2780}]}]}
{"op":"mcm","clk":"11840552441","pt":1723548639776,"mc":[{"id":"1.231699683","rc":[{"batb":[[0,2.34,28.91],[1,1.25,100],[2,1.08,7.82]],"ltp":2.38,"tv":4.29,"id":2780}]}]}
{"op":"mcm","clk":"11840553127","pt":1723548651360,"mc":[{"id":"1.231699683","rc":[{"batb":[[0,2.36,10],[1,2.34,28.91],[2,1.25,100]],"ltp":2.38,"tv":4.29,"id":2780}]}]}
{"op":"mcm","clk":"11840553301","pt":1723548654895,"mc":[{"id":"1.231699683","rc":[{"batb":[[0,2.34,28.91],[1,1.25,100],[2,1.08,7.82]],"ltp":2.38,"tv":4.29,"id":2780}]}]}
{"op":"mcm","clk":"11840553575","pt":1723548659475,"mc":[{"id":"1.231699683","rc":[{"batb":[[0,2.36,10],[1,2.34,28.91],[2,1.25,100]],"ltp":2.38,"tv":4.29,"id":2780}]}]}
{"op":"mcm","clk":"11840553768","pt":1723548662675,"mc":[{"id":"1.231699683","rc":[{"batb":[[0,2.34,28.91],[1,1.25,100],[2,1.08,7.82]],"ltp":2.38,"tv":4.29,"id":2780}]}]}
{"op":"mcm","clk":"11840553913","pt":1723548665298,"mc":[{"id":"1.231699683","rc":[{"batb":[[0,2.36,10],[1,2.34,28.91],[2,1.25,100]],"ltp":2.38,"tv":4.29,"id":2780}]}]}
{"op":"mcm","clk":"11840554130","pt":1723548668692,"mc":[{"id":"1.231699683","rc":[{"batb":[[0,2.34,28.91],[1,1.25,100],[2,1.08,7.82]],"ltp":2.38,"tv":4.29,"id":2780}]}]}
{"op":"mcm","clk":"11840554451","pt":1723548673922,"mc":[{"id":"1.231699683","rc":[{"batb":[[0,2.36,10],[1,2.34,28.91],[2,1.25,100]],"ltp":2.38,"tv":4.29,"id":2780}]}]}
{"op":"mcm","clk":"11840554668","pt":1723548677675,"mc":[{"id":"1.231699683","rc":[{"batb":[[0,2.34,28.91],[1,1.25,100],[2,1.08,7.82]],"ltp":2.38,"tv":4.29,"id":2780}]}]}
{"op":"mcm","clk":"11840554995","pt":1723548682914,"mc":[{"id":"1.231699683","rc":[{"batb":[[0,2.36,10],[1,2.34,28.91],[2,1.25,100]],"ltp":2.38,"tv":4.29,"id":2780}]}]}
{"op":"mcm","clk":"11840555177","pt":1723548686094,"mc":[{"id":"1.231699683","rc":[{"batb":[[0,2.34,28.91],[1,1.25,100],[2,1.08,7.82]],"ltp":2.38,"tv":4.29,"id":2780}]}]}
{"op":"mcm","clk":"11840555413","pt":1723548689912,"mc":[{"id":"1.231699683","rc":[{"batb":[[0,2.36,10],[1,2.34,28.91],[2,1.25,100]],"ltp":2.38,"tv":4.29,"id":2780}]}]}
{"op":"mcm","clk":"11840555650","pt":1723548693914,"mc":[{"id":"1.231699683","rc":[{"batb":[[0,2.34,28.91],[1,1.25,100],[2,1.08,7.82]],"ltp":2.38,"tv":4.29,"id":2780}]}]}
{"op":"mcm","clk":"11840556195","pt":1723548702304,"mc":[{"id":"1.231699683","rc":[{"batb":[[0,2.36,10],[1,2.34,28.91],[2,1.25,100]],"ltp":2.38,"tv":4.29,"id":2780}]}]}
{"op":"mcm","clk":"11840556412","pt":1723548705692,"mc":[{"id":"1.231699683","rc":[{"batb":[[0,2.34,28.91],[1,1.25,100],[2,1.08,7.82]],"ltp":2.38,"tv":4.29,"id":2780}]}]}
{"op":"mcm","clk":"11840557394","pt":1723548722131,"mc":[{"id":"1.231699683","rc":[{"batb":[[0,2.36,10],[1,2.34,28.91],[2,1.25,100]],"ltp":2.38,"tv":4.29,"id":2780}]}]}
{"op":"mcm","clk":"11840557599","pt":1723548725635,"mc":[{"id":"1.231699683","rc":[{"batb":[[0,2.34,28.91],[1,1.25,100],[2,1.08,7.82]],"ltp":2.38,"tv":4.29,"id":2780}]}]}
{"op":"mcm","clk":"11840557754","pt":1723548728560,"mc":[{"id":"1.231699683","rc":[{"batb":[[0,2.36,10],[1,2.34,28.91],[2,1.25,100]],"ltp":2.38,"tv":4.29,"id":2780}]}]}
{"op":"mcm","clk":"11840557932","pt":1723548731949,"mc":[{"id":"1.231699683","rc":[{"batb":[[0,2.34,28.91],[1,1.25,100],[2,1.08,7.82]],"ltp":2.38,"tv":4.29,"id":2780}]}]}
{"op":"mcm","clk":"11840558378","pt":1723548740667,"mc":[{"id":"1.231699683","rc":[{"batb":[[0,2.36,10],[1,2.34,28.91],[2,1.25,100]],"ltp":2.38,"tv":4.29,"id":2780}]}]}
{"op":"mcm","clk":"11840558557","pt":1723548744054,"mc":[{"id":"1.231699683","rc":[{"batb":[[0,2.34,28.91],[1,1.25,100],[2,1.08,7.82]],"ltp":2.38,"tv":4.29,"id":2780}]}]}
{"op":"mcm","clk":"11840558660","pt":1723548746270,"mc":[{"id":"1.231699683","rc":[{"batb":[[0,2.36,10],[1,2.34,28.91],[2,1.25,100]],"ltp":2.38,"tv":4.29,"id":2780}]}]}
{"op":"mcm","clk":"11840558858","pt":1723548749759,"mc":[{"id":"1.231699683","rc":[{"batb":[[0,2.34,28.91],[1,1.25,100],[2,1.08,7.82]],"ltp":2.38,"tv":4.29,"id":2780}]}]}
{"op":"mcm","clk":"11840559153","pt":1723548754657,"mc":[{"id":"1.231699683","rc":[{"batb":[[0,2.36,10],[1,2.34,28.91],[2,1.25,100]],"ltp":2.38,"tv":4.29,"id":2780}]}]}
{"op":"mcm","clk":"11840559351","pt":1723548758060,"mc":[{"id":"1.231699683","rc":[{"batb":[[0,2.34,28.91],[1,1.25,100],[2,1.08,7.82]],"ltp":2.38,"tv":4.29,"id":2780}]}]}
{"op":"mcm","clk":"11840559551","pt":1723548761667,"mc":[{"id":"1.231699683","rc":[{"batb":[[0,2.36,10],[1,2.34,28.91],[2,1.25,100]],"ltp":2.38,"tv":4.29,"id":2780}]}]}
{"op":"mcm","clk":"11840559745","pt":1723548765051,"mc":[{"id":"1.231699683","rc":[{"batb":[[0,2.34,28.91],[1,1.25,100],[2,1.08,7.82]],"ltp":2.38,"tv":4.29,"id":2780}]}]}
{"op":"mcm","clk":"11840559945","pt":1723548768489,"mc":[{"id":"1.231699683","rc":[{"batb":[[0,2.36,10],[1,2.34,28.91],[2,1.25,100]],"ltp":2.38,"tv":4.29,"id":2780}]}]}
{"op":"mcm","clk":"11840560170","pt":1723548771789,"mc":[{"id":"1.231699683","rc":[{"batb":[[0,2.34,28.91],[1,1.25,100],[2,1.08,7.82]],"ltp":2.38,"tv":4.29,"id":2780}]}]}
{"op":"mcm","clk":"11840560645","pt":1723548778551,"mc":[{"id":"1.231699683","rc":[{"batb":[[0,2.36,10],[1,2.34,28.91],[2,1.25,100]],"ltp":2.38,"tv":4.29,"id":2780}]}]}
{"op":"mcm","clk":"11840560842","pt":1723548782066,"mc":[{"id":"1.231699683","rc":[{"batb":[[0,2.34,28.91],[1,1.25,100],[2,1.08,7.82]],"ltp":2.38,"tv":4.29,"id":2780}]}]}
{"op":"mcm","clk":"11840561597","pt":1723548794294,"mc":[{"id":"1.231699683","rc":[{"batb":[[0,2.36,10],[1,2.34,28.91],[2,1.25,100]],"ltp":2.38,"tv":4.29,"id":2780}]}]}
{"op":"mcm","clk":"11840561786","pt":1723548797589,"mc":[{"id":"1.231699683","rc":[{"batb":[[0,2.34,28.91],[1,1.25,100],[2,1.08,7.82]],"ltp":2.38,"tv":4.29,"id":2780}]}]}
{"op":"mcm","clk":"11840561983","pt":1723548801196,"mc":[{"id":"1.231699683","rc":[{"batb":[[0,2.36,10],[1,2.34,28.91],[2,1.25,100]],"ltp":2.38,"tv":4.29,"id":2780}]}]}
{"op":"mcm","clk":"11840562138","pt":1723548804697,"mc":[{"id":"1.231699683","rc":[{"batb":[[0,2.34,28.91],[1,1.25,100],[2,1.08,7.82]],"ltp":2.38,"tv":4.29,"id":2780}]}]}
{"op":"mcm","clk":"11840562250","pt":1723548807013,"mc":[{"id":"1.231699683","rc":[{"batb":[[0,2.36,10],[1,2.34,28.91],[2,1.25,100]],"ltp":2.38,"tv":4.29,"id":2780}]}]}
{"op":"mcm","clk":"11840562435","pt":1723548810411,"mc":[{"id":"1.231699683","rc":[{"batb":[[0,2.34,28.91],[1,1.25,100],[2,1.08,7.82]],"ltp":2.38,"tv":4.29,"id":2780}]}]}
{"op":"mcm","clk":"11840562681","pt":1723548814641,"mc":[{"id":"1.231699683","rc":[{"batb":[[0,2.36,10],[1,2.34,28.91],[2,1.25,100]],"ltp":2.38,"tv":4.29,"id":2780}]}]}
{"op":"mcm","clk":"11840562895","pt":1723548818011,"mc":[{"id":"1.231699683","rc":[{"batb":[[0,2.34,28.91],[1,1.25,100],[2,1.08,7.82]],"ltp":2.38,"tv":4.29,"id":2780}]}]}
{"op":"mcm","clk":"11840563309","pt":1723548824348,"mc":[{"id":"1.231699683","rc":[{"batb":[[0,2.36,10],[1,2.34,28.91],[2,1.25,100]],"ltp":2.38,"tv":4.29,"id":2780}]}]}
{"op":"mcm","clk":"11840563544","pt":1723548827812,"mc":[{"id":"1.231699683","rc":[{"batb":[[0,2.34,28.91],[1,1.25,100],[2,1.08,7.82]],"ltp":2.38,"tv":4.29,"id":2780}]}]}
{"op":"mcm","clk":"11840563840","pt":1723548832725,"mc":[{"id":"1.231699683","rc":[{"batb":[[0,2.36,10],[1,2.34,28.91],[2,1.25,100]],"ltp":2.38,"tv":4.29,"id":2780}]}]}
{"op":"mcm","clk":"11840564043","pt":1723548836125,"mc":[{"id":"1.231699683","rc":[{"batb":[[0,2.34,28.91],[1,1.25,100],[2,1.08,7.82]],"ltp":2.38,"tv":4.29,"id":2780}]}]}
{"op":"mcm","clk":"11840564296","pt":1723548839752,"mc":[{"id":"1.231699683","rc":[{"batb":[[0,2.36,10],[1,2.34,28.91],[2,1.25,100]],"ltp":2.38,"tv":4.29,"id":2780}]}]}
{"op":"mcm","clk":"11840564540","pt":1723548843167,"mc":[{"id":"1.231699683","rc":[{"batb":[[0,2.34,28.91],[1,1.25,100],[2,1.08,7.82]],"ltp":2.38,"tv":4.29,"id":2780}]}]}
{"op":"mcm","clk":"11840564754","pt":1723548847241,"mc":[{"id":"1.231699683","rc":[{"batb":[[0,2.36,10],[1,2.34,28.91],[2,1.25,100]],"ltp":2.38,"tv":4.29,"id":2780}]}]}
{"op":"mcm","clk":"11840564922","pt":1723548850882,"mc":[{"id":"1.231699683","rc":[{"batb":[[0,2.34,28.91],[1,1.25,100],[2,1.08,7.82]],"ltp":2.38,"tv":4.29,"id":2780}]}]}
{"op":"mcm","clk":"11840565133","pt":1723548854247,"mc":[{"id":"1.231699683","rc":[{"batb":[[0,2.36,10],[1,2.34,28.91],[2,1.25,100]],"ltp":2.38,"tv":4.29,"id":2780}]}]}
{"op":"mcm","clk":"11840565312","pt":1723548857688,"mc":[{"id":"1.231699683","rc":[{"batb":[[0,2.34,28.91],[1,1.25,100],[2,1.08,7.82]],"ltp":2.38,"tv":4.29,"id":2780}]}]}
{"op":"mcm","clk":"11840565496","pt":1723548860987,"mc":[{"id":"1.231699683","rc":[{"batb":[[0,2.36,10],[1,2.34,28.91],[2,1.25,100]],"ltp":2.38,"tv":4.29,"id":2780}]}]}
{"op":"mcm","clk":"11840565700","pt":1723548864582,"mc":[{"id":"1.231699683","rc":[{"batb":[[0,2.34,28.91],[1,1.25,100],[2,1.08,7.82]],"ltp":2.38,"tv":4.29,"id":2780}]}]}
{"op":"mcm","clk":"11840565863","pt":1723548867865,"mc":[{"id":"1.231699683","rc":[{"batb":[[0,2.36,10],[1,2.34,28.91],[2,1.25,100]],"ltp":2.38,"tv":4.29,"id":2780}]}]}
{"op":"mcm","clk":"11840566066","pt":1723548871370,"mc":[{"id":"1.231699683","rc":[{"batb":[[0,2.34,28.91],[1,1.25,100],[2,1.08,7.82]],"ltp":2.38,"tv":4.29,"id":2780}]}]}
{"op":"mcm","clk":"11840566304","pt":1723548875175,"mc":[{"id":"1.231699683","rc":[{"batb":[[0,2.36,10],[1,2.34,28.91],[2,1.25,100]],"ltp":2.38,"tv":4.29,"id":2780}]}]}
{"op":"mcm","clk":"11840566491","pt":1723548878676,"mc":[{"id":"1.231699683","rc":[{"batb":[[0,2.34,28.91],[1,1.25,100],[2,1.08,7.82]],"ltp":2.38,"tv":4.29,"id":2780}]}]}
{"op":"mcm","clk":"11840566632","pt":1723548880896,"mc":[{"id":"1.231699683","rc":[{"batb":[[0,2.36,10],[1,2.34,28.91],[2,1.25,100]],"ltp":2.38,"tv":4.29,"id":2780}]}]}
{"op":"mcm","clk":"11840566829","pt":1723548884302,"mc":[{"id":"1.231699683","rc":[{"batb":[[0,2.34,28.91],[1,1.25,100],[2,1.08,7.82]],"ltp":2.38,"tv":4.29,"id":2780}]}]}
{"op":"mcm","clk":"11840566977","pt":1723548886927,"mc":[{"id":"1.231699683","rc":[{"batb":[[0,2.36,10],[1,2.34,28.91],[2,1.25,100]],"ltp":2.38,"tv":4.29,"id":2780}]}]}
{"op":"mcm","clk":"11840567178","pt":1723548890381,"mc":[{"id":"1.231699683","rc":[{"batb":[[0,2.34,28.91],[1,1.25,100],[2,1.08,7.82]],"ltp":2.38,"tv":4.29,"id":2780}]}]}
{"op":"mcm","clk":"11840567515","pt":1723548896319,"mc":[{"id":"1.231699683","rc":[{"batb":[[0,2.36,10],[1,2.34,28.91],[2,1.25,100]],"ltp":2.38,"tv":4.29,"id":2780}]}]}
{"op":"mcm","clk":"11840567701","pt":1723548899833,"mc":[{"id":"1.231699683","rc":[{"batb":[[0,2.34,28.91],[1,1.25,100],[2,1.08,7.82]],"ltp":2.38,"tv":4.29,"id":2780}]}]}
{"op":"mcm","clk":"11840567883","pt":1723548902832,"mc":[{"id":"1.231699683","rc":[{"batb":[[0,2.36,10],[1,2.34,28.91],[2,1.25,100]],"ltp":2.38,"tv":4.29,"id":2780}]}]}
{"op":"mcm","clk":"11840568101","pt":1723548906503,"mc":[{"id":"1.231699683","rc":[{"batb":[[0,2.34,28.91],[1,1.25,100],[2,1.08,7.82]],"ltp":2.38,"tv":4.29,"id":2780}]}]}
{"op":"mcm","clk":"11840568384","pt":1723548911205,"mc":[{"id":"1.231699683","rc":[{"batb":[[0,2.36,10],[1,2.34,28.91],[2,1.25,100]],"ltp":2.38,"tv":4.29,"id":2780}]}]}
{"op":"mcm","clk":"11840568576","pt":1723548914523,"mc":[{"id":"1.231699683","rc":[{"batb":[[0,2.34,28.91],[1,1.25,100],[2,1.08,7.82]],"ltp":2.38,"tv":4.29,"id":2780}]}]}
{"op":"mcm","clk":"11840568770","pt":1723548917618,"mc":[{"id":"1.231699683","rc":[{"batb":[[0,2.36,10],[1,2.34,28.91],[2,1.25,100]],"ltp":2.38,"tv":4.29,"id":2780}]}]}
{"op":"mcm","clk":"11840568906","pt":1723548921010,"mc":[{"id":"1.231699683","rc":[{"batb":[[0,2.34,28.91],[1,1.25,100],[2,1.08,7.82]],"ltp":2.38,"tv":4.29,"id":2780}]}]}
{"op":"mcm","clk":"11840569151","pt":1723548925330,"mc":[{"id":"1.231699683","rc":[{"batb":[[0,2.36,10],[1,2.34,28.91],[2,1.25,100]],"ltp":2.38,"tv":4.29,"id":2780}]}]}
{"op":"mcm","clk":"11840569353","pt":1723548928739,"mc":[{"id":"1.231699683","rc":[{"batb":[[0,2.34,28.91],[1,1.25,100],[2,1.08,7.82]],"ltp":2.38,"tv":4.29,"id":2780}]}]}
{"op":"mcm","clk":"11840569678","pt":1723548934876,"mc":[{"id":"1.231699683","rc":[{"batb":[[0,2.36,10],[1,2.34,28.91],[2,1.25,100]],"ltp":2.38,"tv":4.29,"id":2780}]}]}
{"op":"mcm","clk":"11840569888","pt":1723548938238,"mc":[{"id":"1.231699683","rc":[{"batb":[[0,2.34,28.91],[1,1.25,100],[2,1.08,7.82]],"ltp":2.38,"tv":4.29,"id":2780}]}]}
{"op":"mcm","clk":"11840570061","pt":1723548941474,"mc":[{"id":"1.231699683","rc":[{"batb":[[0,2.36,10],[1,2.34,28.91],[2,1.25,100]],"ltp":2.38,"tv":4.29,"id":2780}]}]}
{"op":"mcm","clk":"11840570276","pt":1723548945384,"mc":[{"id":"1.231699683","rc":[{"batb":[[0,2.34,28.91],[1,1.25,100],[2,1.08,7.82]],"ltp":2.38,"tv":4.29,"id":2780}]}]}
{"op":"mcm","clk":"11840570462","pt":1723548948575,"mc":[{"id":"1.231699683","rc":[{"batb":[[0,2.36,10],[1,2.34,28.91],[2,1.25,100]],"ltp":2.38,"tv":4.29,"id":2780}]}]}
{"op":"mcm","clk":"11840570631","pt":1723548952061,"mc":[{"id":"1.231699683","rc":[{"batb":[[0,2.34,28.91],[1,1.25,100],[2,1.08,7.82]],"ltp":2.38,"tv":4.29,"id":2780}]}]}
{"op":"mcm","clk":"11840570818","pt":1723548955290,"mc":[{"id":"1.231699683","rc":[{"batb":[[0,2.36,10],[1,2.34,28.91],[2,1.25,100]],"ltp":2.38,"tv":4.29,"id":2780}]}]}
{"op":"mcm","clk":"11840571003","pt":1723548958471,"mc":[{"id":"1.231699683","rc":[{"batb":[[0,2.34,28.91],[1,1.25,100],[2,1.08,7.82]],"ltp":2.38,"tv":4.29,"id":2780}]}]}
{"op":"mcm","clk":"11840571289","pt":1723548961702,"mc":[{"id":"1.231699683","rc":[{"batb":[[0,2.36,10],[1,2.34,28.91],[2,1.25,100]],"ltp":2.38,"tv":4.29,"id":2780}]}]}
{"op":"mcm","clk":"11840571548","pt":1723548965306,"mc":[{"id":"1.231699683","rc":[{"batb":[[0,2.34,28.91],[1,1.25,100],[2,1.08,7.82]],"ltp":2.38,"tv":4.29,"id":2780}]}]}
{"op":"mcm","clk":"11840571729","pt":1723548967825,"mc":[{"id":"1.231699683","rc":[{"batb":[[0,2.36,10],[1,2.34,28.91],[2,1.25,100]],"ltp":2.38,"tv":4.29,"id":2780}]}]}
{"op":"mcm","clk":"11840571946","pt":1723548971234,"mc":[{"id":"1.231699683","rc":[{"batb":[[0,2.34,28.91],[1,1.25,100],[2,1.08,7.82]],"ltp":2.38,"tv":4.29,"id":2780}]}]}
{"op":"mcm","clk":"11840572127","pt":1723548974429,"mc":[{"id":"1.231699683","rc":[{"batb":[[0,2.36,10],[1,2.34,28.91],[2,1.25,100]],"ltp":2.38,"tv":4.29,"id":2780}]}]}
{"op":"mcm","clk":"11840572320","pt":1723548977830,"mc":[{"id":"1.231699683","rc":[{"batb":[[0,2.34,28.91],[1,1.25,100],[2,1.08,7.82]],"ltp":2.38,"tv":4.29,"id":2780}]}]}
{"op":"mcm","clk":"11840572527","pt":1723548981839,"mc":[{"id":"1.231699683","rc":[{"batb":[[0,2.36,10],[1,2.34,28.91],[2,1.25,100]],"ltp":2.38,"tv":4.29,"id":2780}]}]}
{"op":"mcm","clk":"11840572710","pt":1723548985256,"mc":[{"id":"1.231699683","rc":[{"batb":[[0,2.34,28.91],[1,1.25,100],[2,1.08,7.82]],"ltp":2.38,"tv":4.29,"id":2780}]}]}
{"op":"mcm","clk":"11840572830","pt":1723548987534,"mc":[{"id":"1.231699683","rc":[{"batb":[[0,2.36,10],[1,2.34,28.91],[2,1.25,100]],"ltp":2.38,"tv":4.29,"id":2780}]}]}
{"op":"mcm","clk":"11840572984","pt":1723548990826,"mc":[{"id":"1.231699683","rc":[{"batb":[[0,2.34,28.91],[1,1.25,100],[2,1.08,7.82]],"ltp":2.38,"tv":4.29,"id":2780}]}]}
{"op":"mcm","clk":"11840573174","pt":1723548993972,"mc":[{"id":"1.231699683","rc":[{"batb":[[0,2.36,10],[1,2.34,28.91],[2,1.25,100]],"ltp":2.38,"tv":4.29,"id":2780}]}]}
{"op":"mcm","clk":"11840573343","pt":1723548997328,"mc":[{"id":"1.231699683","rc":[{"batb":[[0,2.34,28.91],[1,1.25,100],[2,1.08,7.82]],"ltp":2.38,"tv":4.29,"id":2780}]}]}
{"op":"mcm","clk":"11840573520","pt":1723548999956,"mc":[{"id":"1.231699683","rc":[{"batb":[[0,2.36,10],[1,2.34,28.91],[2,1.25,100]],"ltp":2.38,"tv":4.29,"id":2780}]}]}
{"op":"mcm","clk":"11840573694","pt":1723549003458,"mc":[{"id":"1.231699683","rc":[{"batb":[[0,2.34,28.91],[1,1.25,100],[2,1.08,7.82]],"ltp":2.38,"tv":4.29,"id":2780}]}]}
{"op":"mcm","clk":"11840573880","pt":1723549006762,"mc":[{"id":"1.231699683","rc":[{"batb":[[0,2.36,10],[1,2.34,28.91],[2,1.25,100]],"ltp":2.38,"tv":4.29,"id":2780}]}]}
{"op":"mcm","clk":"11840574085","pt":1723549010246,"mc":[{"id":"1.231699683","rc":[{"batb":[[0,2.34,28.91],[1,1.25,100],[2,1.08,7.82]],"ltp":2.38,"tv":4.29,"id":2780}]}]}
{"op":"mcm","clk":"11840574216","pt":1723549012662,"mc":[{"id":"1.231699683","rc":[{"batb":[[0,2.36,10],[1,2.34,28.91],[2,1.25,100]],"ltp":2.38,"tv":4.29,"id":2780}]}]}
{"op":"mcm","clk":"11840574436","pt":1723549016060,"mc":[{"id":"1.231699683","rc":[{"batb":[[0,2.34,28.91],[1,1.25,100],[2,1.08,7.82]],"ltp":2.38,"tv":4.29,"id":2780}]}]}
{"op":"mcm","clk":"11840574677","pt":1723549020178,"mc":[{"id":"1.231699683","rc":[{"batb":[[0,2.36,10],[1,2.34,28.91],[2,1.25,100]],"ltp":2.38,"tv":4.29,"id":2780}]}]}
{"op":"mcm","clk":"11840574880","pt":1723549023593,"mc":[{"id":"1.231699683","rc":[{"batb":[[0,2.34,28.91],[1,1.25,100],[2,1.08,7.82]],"ltp":2.38,"tv":4.29,"id":2780}]}]}
{"op":"mcm","clk":"11840575027","pt":1723549026168,"mc":[{"id":"1.231699683","rc":[{"batb":[[0,2.36,10],[1,2.34,28.91],[2,1.25,100]],"ltp":2.38,"tv":4.29,"id":2780}]}]}
{"op":"mcm","clk":"11840575224","pt":1723549029472,"mc":[{"id":"1.231699683","rc":[{"batb":[[0,2.34,28.91],[1,1.25,100],[2,1.08,7.82]],"ltp":2.38,"tv":4.29,"id":2780}]}]}
{"op":"mcm","clk":"11840575381","pt":1723549032200,"mc":[{"id":"1.231699683","rc":[{"batb":[[0,2.36,10],[1,2.34,28.91],[2,1.25,100]],"ltp":2.38,"tv":4.29,"id":2780}]}]}
{"op":"mcm","clk":"11840575594","pt":1723549035704,"mc":[{"id":"1.231699683","rc":[{"batb":[[0,2.34,28.91],[1,1.25,100],[2,1.08,7.82]],"ltp":2.38,"tv":4.29,"id":2780}]}]}
{"op":"mcm","clk":"11840575756","pt":1723549038426,"mc":[{"id":"1.231699683","rc":[{"batb":[[0,2.36,10],[1,2.34,28.91],[2,1.25,100]],"ltp":2.38,"tv":4.29,"id":2780}]}]}
{"op":"mcm","clk":"11840575944","pt":1723549041710,"mc":[{"id":"1.231699683","rc":[{"batb":[[0,2.34,28.91],[1,1.25,100],[2,1.08,7.82]],"ltp":2.38,"tv":4.29,"id":2780}]}]}
{"op":"mcm","clk":"11840576150","pt":1723549045012,"mc":[{"id":"1.231699683","rc":[{"batb":[[0,2.36,10],[1,2.34,28.91],[2,1.25,100]],"ltp":2.38,"tv":4.29,"id":2780}]}]}
{"op":"mcm","clk":"11840576360","pt":1723549048718,"mc":[{"id":"1.231699683","rc":[{"batb":[[0,2.34,28.91],[1,1.25,100],[2,1.08,7.82]],"ltp":2.38,"tv":4.29,"id":2780}]}]}
{"op":"mcm","clk":"11840576558","pt":1723549052021,"mc":[{"id":"1.231699683","rc":[{"batb":[[0,2.36,10],[1,2.34,28.91],[2,1.25,100]],"ltp":2.38,"tv":4.29,"id":2780}]}]}
{"op":"mcm","clk":"11840576785","pt":1723549055424,"mc":[{"id":"1.231699683","rc":[{"batb":[[0,2.34,28.91],[1,1.25,100],[2,1.08,7.82]],"ltp":2.38,"tv":4.29,"id":2780}]}]}
{"op":"mcm","clk":"11840577023","pt":1723549058934,"mc":[{"id":"1.231699683","rc":[{"batb":[[0,2.36,10],[1,2.34,28.91],[2,1.25,100]],"ltp":2.38,"tv":4.29,"id":2780}]}]}
{"op":"mcm","clk":"11840577282","pt":1723549062405,"mc":[{"id":"1.231699683","rc":[{"batb":[[0,2.34,28.91],[1,1.25,100],[2,1.08,7.82]],"ltp":2.38,"tv":4.29,"id":2780}]}]}
{"op":"mcm","clk":"11840577410","pt":1723549064821,"mc":[{"id":"1.231699683","rc":[{"batb":[[0,2.36,10],[1,2.34,28.91],[2,1.25,100]],"ltp":2.38,"tv":4.29,"id":2780}]}]}
{"op":"mcm","clk":"11840577642","pt":1723549068227,"mc":[{"id":"1.231699683","rc":[{"batb":[[0,2.34,28.91],[1,1.25,100],[2,1.08,7.82]],"ltp":2.38,"tv":4.29,"id":2780}]}]}
{"op":"mcm","clk":"11840577865","pt":1723549071948,"mc":[{"id":"1.231699683","rc":[{"batb":[[0,2.36,10],[1,2.34,28.91],[2,1.25,100]],"ltp":2.38,"tv":4.29,"id":2780}]}]}
{"op":"mcm","clk":"11840578073","pt":1723549075253,"mc":[{"id":"1.231699683","rc":[{"batb":[[0,2.34,28.91],[1,1.25,100],[2,1.08,7.82]],"ltp":2.38,"tv":4.29,"id":2780}]}]}
{"op":"mcm","clk":"11840578318","pt":1723549078929,"mc":[{"id":"1.231699683","rc":[{"batb":[[0,2.36,10],[1,2.34,28.91],[2,1.25,100]],"ltp":2.38,"tv":4.29,"id":2780}]}]}
{"op":"mcm","clk":"11840578527","pt":1723549082241,"mc":[{"id":"1.231699683","rc":[{"batb":[[0,2.34,28.91],[1,1.25,100],[2,1.08,7.82]],"ltp":2.38,"tv":4.29,"id":2780}]}]}
{"op":"mcm","clk":"11840578870","pt":1723549087679,"mc":[{"id":"1.231699683","rc":[{"batb":[[0,2.36,10],[1,2.34,28.91],[2,1.25,100]],"ltp":2.38,"tv":4.29,"id":2780}]}]}
{"op":"mcm","clk":"11840579082","pt":1723549091344,"mc":[{"id":"1.231699683","rc":[{"batb":[[0,2.34,28.91],[1,1.25,100],[2,1.08,7.82]],"ltp":2.38,"tv":4.29,"id":2780}]}]}
{"op":"mcm","clk":"11840579256","pt":1723549094033,"mc":[{"id":"1.231699683","rc":[{"batb":[[0,2.36,10],[1,2.34,28.91],[2,1.25,100]],"ltp":2.38,"tv":4.29,"id":2780}]}]}
{"op":"mcm","clk":"11840579485","pt":1723549097587,"mc":[{"id":"1.231699683","rc":[{"batb":[[0,2.34,28.91],[1,1.25,100],[2,1.08,7.82]],"ltp":2.38,"tv":4.29,"id":2780}]}]}
{"op":"mcm","clk":"11840579672","pt":1723549100786,"mc":[{"id":"1.231699683","rc":[{"batb":[[0,2.36,10],[1,2.34,28.91],[2,1.25,100]],"ltp":2.38,"tv":4.29,"id":2780}]}]}
{"op":"mcm","clk":"11840579855","pt":1723549104089,"mc":[{"id":"1.231699683","rc":[{"batb":[[0,2.34,28.91],[1,1.25,100],[2,1.08,7.82]],"ltp":2.38,"tv":4.29,"id":2780}]}]}
{"op":"mcm","clk":"11840580062","pt":1723549107591,"mc":[{"id":"1.231699683","rc":[{"batb":[[0,2.36,10],[1,2.34,28.91],[2,1.25,100]],"ltp":2.38,"tv":4.29,"id":2780}]}]}
{"op":"mcm","clk":"11840580298","pt":1723549111083,"mc":[{"id":"1.231699683","rc":[{"batb":[[0,2.34,28.91],[1,1.25,100],[2,1.08,7.82]],"ltp":2.38,"tv":4.29,"id":2780}]}]}
{"op":"mcm","clk":"11840580528","pt":1723549114374,"mc":[{"id":"1.231699683","rc":[{"batb":[[0,2.36,10],[1,2.34,28.91],[2,1.25,100]],"ltp":2.38,"tv":4.29,"id":2780}]}]}
{"op":"mcm","clk":"11840580805","pt":1723549118569,"mc":[{"id":"1.231699683","rc":[{"batb":[[0,2.34,28.91],[1,1.25,100],[2,1.08,7.82]],"ltp":2.38,"tv":4.29,"id":2780}]}]}
{"op":"mcm","clk":"11840580952","pt":1723549120999,"mc":[{"id":"1.231699683","rc":[{"batb":[[0,2.36,10],[1,2.34,28.91],[2,1.25,100]],"ltp":2.38,"tv":4.29,"id":2780}]}]}
{"op":"mcm","clk":"11840581172","pt":1723549124415,"mc":[{"id":"1.231699683","rc":[{"batb":[[0,2.34,28.91],[1,1.25,100],[2,1.08,7.82]],"ltp":2.38,"tv":4.29,"id":2780}]}]}
{"op":"mcm","clk":"11840581566","pt":1723549130891,"mc":[{"id":"1.231699683","rc":[{"batb":[[0,2.36,10],[1,2.34,28.91],[2,1.25,100]],"ltp":2.38,"tv":4.29,"id":2780}]}]}
{"op":"mcm","clk":"11840581775","pt":1723549134339,"mc":[{"id":"1.231699683","rc":[{"batb":[[0,2.34,28.91],[1,1.25,100],[2,1.08,7.82]],"ltp":2.38,"tv":4.29,"id":2780}]}]}
{"op":"mcm","clk":"11840582092","pt":1723549139218,"mc":[{"id":"1.231699683","rc":[{"batb":[[0,2.36,10],[1,2.34,28.91],[2,1.25,100]],"ltp":2.38,"tv":4.29,"id":2780}]}]}
{"op":"mcm","clk":"11840582284","pt":1723549142513,"mc":[{"id":"1.231699683","rc":[{"batb":[[0,2.34,28.91],[1,1.25,100],[2,1.08,7.82]],"ltp":2.38,"tv":4.29,"id":2780}]}]}
{"op":"mcm","clk":"11840582565","pt":1723549147136,"mc":[{"id":"1.231699683","rc":[{"batb":[[0,2.36,10],[1,2.34,28.91],[2,1.25,100]],"ltp":2.38,"tv":4.29,"id":2780}]}]}
{"op":"mcm","clk":"11840582767","pt":1723549150626,"mc":[{"id":"1.231699683","rc":[{"batb":[[0,2.34,28.91],[1,1.25,100],[2,1.08,7.82]],"ltp":2.38,"tv":4.29,"id":2780}]}]}
{"op":"mcm","clk":"11840582898","pt":1723549152949,"mc":[{"id":"1.231699683","rc":[{"batb":[[0,2.36,10],[1,2.34,28.91],[2,1.25,100]],"ltp":2.38,"tv":4.29,"id":2780}]}]}
{"op":"mcm","clk":"11840583084","pt":1723549156235,"mc":[{"id":"1.231699683","rc":[{"batb":[[0,2.34,28.91],[1,1.25,100],[2,1.08,7.82]],"ltp":2.38,"tv":4.29,"id":2780}]}]}
{"op":"mcm","clk":"11840658673","pt":1723550401821,"mc":[{"id":"1.231699683","rc":[{"batb":[[0,2.36,10],[1,2.34,28.91],[2,1.25,100]],"ltp":2.38,"tv":4.29,"id":2780}]}]}
{"op":"mcm","clk":"11840658936","pt":1723550405135,"mc":[{"id":"1.231699683","rc":[{"batb":[[0,2.34,28.91],[1,1.25,100],[2,1.08,7.82]],"ltp":2.38,"tv":4.29,"id":2780},{"batb":[[2,1.08,7.82]],"batl":[[0,1.69,9.82]],"ltp":1.64,"tv":404.0,"id":2120}]}]}
{"op":"mcm","clk":"11840659139","pt":1723550407920,"mc":[{"id":"1.231699683","rc":[{"batb":[[0,2.36,10],[1,2.34,28.91],[2,1.25,100]],"ltp":2.38,"tv":4.29,"id":2780}]}]}
{"op":"mcm","clk":"11840659396","pt":1723550411640,"mc":[{"id":"1.231699683","rc":[{"batb":[[0,2.34,28.91],[1,1.25,100],[2,1.08,7.82]],"ltp":2.38,"tv":4.29,"id":2780}]}]}
{"op":"mcm","clk":"11840659833","pt":1723550419530,"mc":[{"id":"1.231699683","rc":[{"batb":[[0,2.36,10],[1,2.34,28.91],[2,1.25,100]],"ltp":2.38,"tv":4.29,"id":2780}]}]}
{"op":"mcm","clk":"11840660054","pt":1723550423141,"mc":[{"id":"1.231699683","rc":[{"batb":[[0,2.34,28.91],[1,1.25,100],[2,1.08,7.82]],"ltp":2.38,"tv":4.29,"id":2780}]}]}
{"op":"mcm","clk":"11840660223","pt":1723550425735,"mc":[{"id":"1.231699683","rc":[{"batb":[[0,2.36,10],[1,2.34,28.91],[2,1.25,100]],"ltp":2.38,"tv":4.29,"id":2780}]}]}
{"op":"mcm","clk":"11840660450","pt":1723550429044,"mc":[{"id":"1.231699683","rc":[{"batb":[[0,2.34,28.91],[1,1.25,100],[2,1.08,7.82]],"ltp":2.38,"tv":4.29,"id":2780}]}]}
{"op":"mcm","clk":"11840660777","pt":1723550433734,"mc":[{"id":"1.231699683","rc":[{"batb":[[0,2.36,10],[1,2.34,28.91],[2,1.25,100]],"ltp":2.38,"tv":4.29,"id":2780}]}]}
{"op":"mcm","clk":"11840661026","pt":1723550437353,"mc":[{"id":"1.231699683","rc":[{"batb":[[0,2.34,28.91],[1,1.25,100],[2,1.08,7.82]],"ltp":2.38,"tv":4.29,"id":2780}]}]}
{"op":"mcm","clk":"11840661237","pt":1723550440052,"mc":[{"id":"1.231699683","rc":[{"batb":[[0,2.36,10],[1,2.34,28.91],[2,1.25,100]],"ltp":2.38,"tv":4.29,"id":2780}]}]}
{"op":"mcm","clk":"11840661419","pt":1723550443231,"mc":[{"id":"1.231699683","rc":[{"batb":[[0,2.34,28.91],[1,1.25,100],[2,1.08,7.82]],"ltp":2.38,"tv":4.29,"id":2780}]}]}
{"op":"mcm","clk":"11840661637","pt":1723550446436,"mc":[{"id":"1.231699683","rc":[{"batb":[[0,2.36,10],[1,2.34,28.91],[2,1.25,100]],"ltp":2.38,"tv":4.29,"id":2780}]}]}
{"op":"mcm","clk":"11840661905","pt":1723550449974,"mc":[{"id":"1.231699683","rc":[{"batb":[[0,2.34,28.91],[1,1.25,100],[2,1.08,7.82]],"ltp":2.38,"tv":4.29,"id":2780}]}]}
{"op":"mcm","clk":"11840662047","pt":1723550452256,"mc":[{"id":"1.231699683","rc":[{"batb":[[0,2.36,10],[1,2.34,28.91],[2,1.25,100]],"ltp":2.38,"tv":4.29,"id":2780}]}]}
{"op":"mcm","clk":"11840662248","pt":1723550455745,"mc":[{"id":"1.231699683","rc":[{"batb":[[0,2.34,28.91],[1,1.25,100],[2,1.08,7.82]],"ltp":2.38,"tv":4.29,"id":2780}]}]}
{"op":"mcm","clk":"11840662580","pt":1723550460779,"mc":[{"id":"1.231699683","rc":[{"batb":[[0,2.36,10],[1,2.34,28.91],[2,1.25,100]],"ltp":2.38,"tv":4.29,"id":2780}]}]}
{"op":"mcm","clk":"11840662841","pt":1723550464277,"mc":[{"id":"1.231699683","rc":[{"batb":[[0,2.34,28.91],[1,1.25,100],[2,1.08,7.82]],"ltp":2.38,"tv":4.29,"id":2780}]}]}
{"op":"mcm","clk":"11840663023","pt":1723550466692,"mc":[{"id":"1.231699683","rc":[{"batb":[[0,2.36,10],[1,2.34,28.91],[2,1.25,100]],"ltp":2.38,"tv":4.29,"id":2780}]}]}
{"op":"mcm","clk":"11840663277","pt":1723550470182,"mc":[{"id":"1.231699683","rc":[{"batb":[[0,2.34,28.91],[1,1.25,100],[2,1.08,7.82]],"ltp":2.38,"tv":4.29,"id":2780}]}]}
{"op":"mcm","clk":"11840663437","pt":1723550472710,"mc":[{"id":"1.231699683","rc":[{"batb":[[0,2.36,10],[1,2.34,28.91],[2,1.25,100]],"ltp":2.38,"tv":4.29,"id":2780}]}]}
{"op":"mcm","clk":"11840663699","pt":1723550476101,"mc":[{"id":"1.231699683","rc":[{"batb":[[0,2.34,28.91],[1,1.25,100],[2,1.08,7.82]],"ltp":2.38,"tv":4.29,"id":2780}]}]}
{"op":"mcm","clk":"11840663914","pt":1723550479490,"mc":[{"id":"1.231699683","rc":[{"batb":[[0,2.36,10],[1,2.34,28.91],[2,1.25,100]],"ltp":2.38,"tv":4.29,"id":2780}]}]}
{"op":"mcm","clk":"11840664165","pt":1723550483090,"mc":[{"id":"1.231699683","rc":[{"batb":[[0,2.34,28.91],[1,1.25,100],[2,1.08,7.82]],"ltp":2.38,"tv":4.29,"id":2780}]}]}
{"op":"mcm","clk":"11840664381","pt":1723550486110,"mc":[{"id":"1.231699683","rc":[{"batb":[[0,2.36,10],[1,2.34,28.91],[2,1.25,100]],"ltp":2.38,"tv":4.29,"id":2780}]}]}
{"op":"mcm","clk":"11840664636","pt":1723550489504,"mc":[{"id":"1.231699683","rc":[{"batb":[[0,2.34,28.91],[1,1.25,100],[2,1.08,7.82]],"ltp":2.38,"tv":4.29,"id":2780}]}]}
{"op":"mcm","clk":"11840664826","pt":1723550491920,"mc":[{"id":"1.231699683","rc":[{"batb":[[0,2.36,10],[1,2.34,28.91],[2,1.25,100]],"ltp":2.38,"tv":4.29,"id":2780}]}]}
{"op":"mcm","clk":"11840665079","pt":1723550495222,"mc":[{"id":"1.231699683","rc":[{"batb":[[0,2.34,28.91],[1,1.25,100],[2,1.08,7.82]],"ltp":2.38,"tv":4.29,"id":2780}]}]}
{"op":"mcm","clk":"11840665446","pt":1723550499647,"mc":[{"id":"1.231699683","rc":[{"batb":[[0,2.36,10],[1,2.34,28.91],[2,1.25,100]],"ltp":2.38,"tv":4.29,"id":2780}]}]}
{"op":"mcm","clk":"11840665682","pt":1723550503099,"mc":[{"id":"1.231699683","rc":[{"batb":[[0,2.34,28.91],[1,1.25,100],[2,1.08,7.82]],"ltp":2.38,"tv":4.29,"id":2780}]}]}
{"op":"mcm","clk":"11840665872","pt":1723550505251,"mc":[{"id":"1.231699683","rc":[{"batb":[[0,2.36,10],[1,2.34,28.91],[2,1.25,100]],"ltp":2.38,"tv":4.29,"id":2780}]}]}
{"op":"mcm","clk":"11840666124","pt":1723550508638,"mc":[{"id":"1.231699683","rc":[{"batb":[[0,2.34,28.91],[1,1.25,100],[2,1.08,7.82]],"ltp":2.38,"tv":4.29,"id":2780}]}]}
{"op":"mcm","clk":"11840666342","pt":1723550511418,"mc":[{"id":"1.231699683","rc":[{"batb":[[0,2.36,10],[1,2.34,28.91],[2,1.25,100]],"ltp":2.38,"tv":4.29,"id":2780}]}]}
{"op":"mcm","clk":"11840666575","pt":1723550514655,"mc":[{"id":"1.231699683","rc":[{"batb":[[0,2.34,28.91],[1,1.25,100],[2,1.08,7.82]],"ltp":2.38,"tv":4.29,"id":2780}]}]}
{"op":"mcm","clk":"11840667046","pt":1723550520747,"mc":[{"id":"1.231699683","rc":[{"batb":[[0,2.36,10],[1,2.34,28.91],[2,1.25,100]],"ltp":2.38,"tv":4.29,"id":2780}]}]}
{"op":"mcm","clk":"11840667321","pt":1723550524262,"mc":[{"id":"1.231699683","rc":[{"batb":[[0,2.34,28.91],[1,1.25,100],[2,1.08,7.82]],"ltp":2.38,"tv":4.29,"id":2780}]}]}
{"op":"mcm","clk":"11840667939","pt":1723550531447,"mc":[{"id":"1.231699683","rc":[{"batb":[[0,2.36,10],[1,2.34,28.91],[2,1.25,100]],"ltp":2.38,"tv":4.29,"id":2780}]}]}
{"op":"mcm","clk":"11840668233","pt":1723550534958,"mc":[{"id":"1.231699683","rc":[{"batb":[[0,2.34,28.91],[1,1.25,100],[2,1.08,7.82]],"ltp":2.38,"tv":4.29,"id":2780}]}]}
{"op":"mcm","clk":"11840668746","pt":1723550541963,"mc":[{"id":"1.231699683","rc":[{"batb":[[0,2.36,10],[1,2.34,28.91],[2,1.25,100]],"ltp":2.38,"tv":4.29,"id":2780}]}]}
{"op":"mcm","clk":"11840668978","pt":1723550545265,"mc":[{"id":"1.231699683","rc":[{"batb":[[0,2.34,28.91],[1,1.25,100],[2,1.08,7.82]],"ltp":2.38,"tv":4.29,"id":2780}]}]}
{"op":"mcm","clk":"11840670301","pt":1723550562300,"mc":[{"id":"1.231699683","rc":[{"batb":[[0,2.36,10],[1,2.34,28.91],[2,1.25,100]],"ltp":2.38,"tv":4.29,"id":2780}]}]}
{"op":"mcm","clk":"11840670565","pt":1723550565710,"mc":[{"id":"1.231699683","rc":[{"batb":[[0,2.34,28.91],[1,1.25,100],[2,1.08,7.82]],"ltp":2.38,"tv":4.29,"id":2780}]}]}
{"op":"mcm","clk":"11840670778","pt":1723550568798,"mc":[{"id":"1.231699683","rc":[{"batb":[[0,2.36,10],[1,2.34,28.91],[2,1.25,100]],"ltp":2.38,"tv":4.29,"id":2780}]}]}
{"op":"mcm","clk":"11840671029","pt":1723550572007,"mc":[{"id":"1.231699683","rc":[{"batb":[[0,2.34,28.91],[1,1.25,100],[2,1.08,7.82]],"ltp":2.38,"tv":4.29,"id":2780}]}]}
{"op":"mcm","clk":"11840671331","pt":1723550575788,"mc":[{"id":"1.231699683","rc":[{"batb":[[0,2.36,10],[1,2.34,28.91],[2,1.25,100]],"ltp":2.38,"tv":4.29,"id":2780}]}]}
{"op":"mcm","clk":"11840671610","pt":1723550579012,"mc":[{"id":"1.231699683","rc":[{"batb":[[0,2.34,28.91],[1,1.25,100],[2,1.08,7.82]],"ltp":2.38,"tv":4.29,"id":2780}]}]}
{"op":"mcm","clk":"11840671995","pt":1723550583321,"mc":[{"id":"1.231699683","rc":[{"batb":[[0,2.36,10],[1,2.34,28.91],[2,1.25,100]],"ltp":2.38,"tv":4.29,"id":2780}]}]}
{"op":"mcm","clk":"11840672299","pt":1723550586683,"mc":[{"id":"1.231699683","rc":[{"batb":[[0,2.34,28.91],[1,1.25,100],[2,1.08,7.82]],"ltp":2.38,"tv":4.29,"id":2780}]}]}
{"op":"mcm","clk":"11840672785","pt":1723550593017,"mc":[{"id":"1.231699683","rc":[{"batb":[[0,2.36,10],[1,2.34,28.91],[2,1.25,100]],"ltp":2.38,"tv":4.29,"id":2780}]}]}
{"op":"mcm","clk":"11840673028","pt":1723550596210,"mc":[{"id":"1.231699683","rc":[{"batb":[[0,2.34,28.91],[1,1.25,100],[2,1.08,7.82]],"ltp":2.38,"tv":4.29,"id":2780}]}]}
{"op":"mcm","clk":"11840673393","pt":1723550600632,"mc":[{"id":"1.231699683","rc":[{"batb":[[0,2.36,10],[1,2.34,28.91],[2,1.25,100]],"ltp":2.38,"tv":4.29,"id":2780}]}]}
{"op":"mcm","clk":"11840673640","pt":1723550604015,"mc":[{"id":"1.231699683","rc":[{"batb":[[0,2.34,28.91],[1,1.25,100],[2,1.08,7.82]],"ltp":2.38,"tv":4.29,"id":2780}]}]}
{"op":"mcm","clk":"11840673877","pt":1723550607150,"mc":[{"id":"1.231699683","rc":[{"batb":[[0,2.36,10],[1,2.34,28.91],[2,1.25,100]],"ltp":2.38,"tv":4.29,"id":2780}]}]}
{"op":"mcm","clk":"11840674165","pt":1723550610745,"mc":[{"id":"1.231699683","rc":[{"batb":[[0,2.34,28.91],[1,1.25,100],[2,1.08,7.82]],"ltp":2.38,"tv":4.29,"id":2780}]}]}
{"op":"mcm","clk":"11840674417","pt":1723550614437,"mc":[{"id":"1.231699683","rc":[{"batb":[[0,2.36,10],[1,2.34,28.91],[2,1.25,100]],"ltp":2.38,"tv":4.29,"id":2780}]}]}
{"op":"mcm","clk":"11840674649","pt":1723550617978,"mc":[{"id":"1.231699683","rc":[{"batb":[[0,2.34,28.91],[1,1.25,100],[2,1.08,7.82]],"ltp":2.38,"tv":4.29,"id":2780}]}]}
{"op":"mcm","clk":"11840675009","pt":1723550623174,"mc":[{"id":"1.231699683","rc":[{"batb":[[0,2.36,10],[1,2.34,28.91],[2,1.25,100]],"ltp":2.38,"tv":4.29,"id":2780}]}]}
{"op":"mcm","clk":"11840675221","pt":1723550626467,"mc":[{"id":"1.231699683","rc":[{"batb":[[0,2.34,28.91],[1,1.25,100],[2,1.08,7.82]],"ltp":2.38,"tv":4.29,"id":2780}]}]}
{"op":"mcm","clk":"11840675686","pt":1723550633082,"mc":[{"id":"1.231699683","rc":[{"batb":[[0,2.36,10],[1,2.34,28.91],[2,1.25,100]],"ltp":2.38,"tv":4.29,"id":2780}]}]}
{"op":"mcm","clk":"11840675934","pt":1723550636806,"mc":[{"id":"1.231699683","rc":[{"batb":[[0,2.34,28.91],[1,1.25,100],[2,1.08,7.82]],"ltp":2.38,"tv":4.29,"id":2780}]}]}
{"op":"mcm","clk":"11840676141","pt":1723550639887,"mc":[{"id":"1.231699683","rc":[{"batb":[[0,2.36,10],[1,2.34,28.91],[2,1.25,100]],"ltp":2.38,"tv":4.29,"id":2780}]}]}
{"op":"mcm","clk":"11840676375","pt":1723550643292,"mc":[{"id":"1.231699683","rc":[{"batb":[[0,2.34,28.91],[1,1.25,100],[2,1.08,7.82]],"ltp":2.38,"tv":4.29,"id":2780}]}]}
{"op":"mcm","clk":"11840676620","pt":1723550646687,"mc":[{"id":"1.231699683","rc":[{"batb":[[0,2.36,10],[1,2.34,28.91],[2,1.25,100]],"ltp":2.38,"tv":4.29,"id":2780}]}]}
{"op":"mcm","clk":"11840676873","pt":1723550650291,"mc":[{"id":"1.231699683","rc":[{"batb":[[0,2.34,28.91],[1,1.25,100],[2,1.08,7.82]],"ltp":2.38,"tv":4.29,"id":2780}]}]}
{"op":"mcm","clk":"11840677102","pt":1723550653323,"mc":[{"id":"1.231699683","rc":[{"batb":[[0,2.36,10],[1,2.34,28.91],[2,1.25,100]],"ltp":2.38,"tv":4.29,"id":2780}]}]}
{"op":"mcm","clk":"11840677348","pt":1723550656823,"mc":[{"id":"1.231699683","rc":[{"batb":[[0,2.34,28.91],[1,1.25,100],[2,1.08,7.82]],"ltp":2.38,"tv":4.29,"id":2780}]}]}
{"op":"mcm","clk":"11840677648","pt":1723550661598,"mc":[{"id":"1.231699683","rc":[{"batb":[[0,2.36,10],[1,2.34,28.91],[2,1.25,100]],"ltp":2.38,"tv":4.29,"id":2780}]}]}
{"op":"mcm","clk":"11840677845","pt":1723550664939,"mc":[{"id":"1.231699683","rc":[{"batb":[[0,2.34,28.91],[1,1.25,100],[2,1.08,7.82]],"ltp":2.38,"tv":4.29,"id":2780}]}]}
{"op":"mcm","clk":"11840678630","pt":1723550675645,"mc":[{"id":"1.231699683","rc":[{"batb":[[0,2.36,10],[1,2.34,28.91],[2,1.25,100]],"ltp":2.38,"tv":4.29,"id":2780}]}]}
{"op":"mcm","clk":"11840678896","pt":1723550678938,"mc":[{"id":"1.231699683","rc":[{"batb":[[0,2.34,28.91],[1,1.25,100],[2,1.08,7.82]],"ltp":2.38,"tv":4.29,"id":2780}]}]}
{"op":"mcm","clk":"11840679369","pt":1723550685328,"mc":[{"id":"1.231699683","rc":[{"batb":[[0,2.36,10],[1,2.34,28.91],[2,1.25,100]],"ltp":2.38,"tv":4.29,"id":2780}]}]}
{"op":"mcm","clk":"11840679619","pt":1723550688721,"mc":[{"id":"1.231699683","rc":[{"batb":[[0,2.34,28.91],[1,1.25,100],[2,1.08,7.82]],"ltp":2.38,"tv":4.29,"id":2780}]}]}
{"op":"mcm","clk":"11840679898","pt":1723550692474,"mc":[{"id":"1.231699683","rc":[{"batb":[[0,2.36,10],[1,2.34,28.91],[2,1.25,100]],"ltp":2.38,"tv":4.29,"id":2780}]}]}
{"op":"mcm","clk":"11840680168","pt":1723550695970,"mc":[{"id":"1.231699683","rc":[{"batb":[[0,2.34,28.91],[1,1.25,100],[2,1.08,7.82]],"ltp":2.38,"tv":4.29,"id":2780}]}]}
{"op":"mcm","clk":"11840680341","pt":1723550698542,"mc":[{"id":"1.231699683","rc":[{"batb":[[0,2.36,10],[1,2.34,28.91],[2,1.25,100]],"ltp":2.38,"tv":4.29,"id":2780}]}]}
{"op":"mcm","clk":"11840680728","pt":1723550702282,"mc":[{"id":"1.231699683","rc":[{"batb":[[0,2.34,28.91],[1,1.25,100],[2,1.08,7.82]],"ltp":2.38,"tv":4.29,"id":2780}]}]}
{"op":"mcm","clk":"11840680920","pt":1723550704808,"mc":[{"id":"1.231699683","rc":[{"batb":[[0,2.36,10],[1,2.34,28.91],[2,1.25,100]],"ltp":2.38,"tv":4.29,"id":2780}]}]}
{"op":"mcm","clk":"11840681173","pt":1723550708223,"mc":[{"id":"1.231699683","rc":[{"batb":[[0,2.34,28.91],[1,1.25,100],[2,1.08,7.82]],"ltp":2.38,"tv":4.29,"id":2780}]}]}
{"op":"mcm","clk":"11840681504","pt":1723550712929,"mc":[{"id":"1.231699683","rc":[{"batb":[[0,2.36,10],[1,2.34,28.91],[2,1.25,100]],"ltp":2.38,"tv":4.29,"id":2780}]}]}
{"op":"mcm","clk":"11840681832","pt":1723550717106,"mc":[{"id":"1.231699683","rc":[{"batb":[[0,2.34,28.91],[1,1.25,100],[2,1.08,7.82]],"ltp":2.38,"tv":4.29,"id":2780}]}]}
{"op":"mcm","clk":"11840682416","pt":1723550725820,"mc":[{"id":"1.231699683","rc":[{"batb":[[0,2.36,10],[1,2.34,28.91],[2,1.25,100]],"ltp":2.38,"tv":4.29,"id":2780}]}]}
{"op":"mcm","clk":"11840682692","pt":1723550729523,"mc":[{"id":"1.231699683","rc":[{"batb":[[0,2.34,28.91],[1,1.25,100],[2,1.08,7.82]],"ltp":2.38,"tv":4.29,"id":2780}]}]}
{"op":"mcm","clk":"11840682906","pt":1723550732450,"mc":[{"id":"1.231699683","rc":[{"batb":[[0,2.36,10],[1,2.34,28.91],[2,1.25,100]],"ltp":2.38,"tv":4.29,"id":2780}]}]}
{"op":"mcm","clk":"11840683168","pt":1723550736057,"mc":[{"id":"1.231699683","rc":[{"batb":[[0,2.34,28.91],[1,1.25,100],[2,1.08,7.82]],"ltp":2.38,"tv":4.29,"id":2780}]}]}
{"op":"mcm","clk":"11840683340","pt":1723550738328,"mc":[{"id":"1.231699683","rc":[{"batb":[[0,2.36,10],[1,2.34,28.91],[2,1.25,100]],"ltp":2.38,"tv":4.29,"id":2780}]}]}
{"op":"mcm","clk":"11840683569","pt":1723550741838,"mc":[{"id":"1.231699683","rc":[{"batb":[[0,2.34,28.91],[1,1.25,100],[2,1.08,7.82]],"ltp":2.38,"tv":4.29,"id":2780}]}]}
{"op":"mcm","clk":"11840684179","pt":1723550751066,"mc":[{"id":"1.231699683","rc":[{"batb":[[0,2.36,10],[1,2.34,28.91],[2,1.25,100]],"ltp":2.38,"tv":4.29,"id":2780}]}]}
{"op":"mcm","clk":"11840684388","pt":1723550754561,"mc":[{"id":"1.231699683","rc":[{"batb":[[0,2.34,28.91],[1,1.25,100],[2,1.08,7.82]],"ltp":2.38,"tv":4.29,"id":2780}]}]}
{"op":"mcm","clk":"11840684942","pt":1723550761362,"mc":[{"id":"1.231699683","rc":[{"batb":[[0,2.36,10],[1,2.34,28.91],[2,1.25,100]],"ltp":2.38,"tv":4.29,"id":2780}]}]}
{"op":"mcm","clk":"11840685240","pt":1723550765185,"mc":[{"id":"1.231699683","rc":[{"batb":[[0,2.34,28.91],[1,1.25,100],[2,1.08,7.82]],"ltp":2.38,"tv":4.29,"id":2780}]}]}
{"op":"mcm","clk":"11840685715","pt":1723550770696,"mc":[{"id":"1.231699683","rc":[{"batb":[[0,2.36,10],[1,2.34,28.91],[2,1.25,100]],"ltp":2.38,"tv":4.29,"id":2780}]}]}
{"op":"mcm","clk":"11840686002","pt":1723550774158,"mc":[{"id":"1.231699683","rc":[{"batb":[[0,2.34,28.91],[1,1.25,100],[2,1.08,7.82]],"ltp":2.38,"tv":4.29,"id":2780}]}]}
{"op":"mcm","clk":"11840686211","pt":1723550777202,"mc":[{"id":"1.231699683","rc":[{"batb":[[0,2.36,10],[1,2.34,28.91],[2,1.25,100]],"ltp":2.38,"tv":4.29,"id":2780}]}]}
{"op":"mcm","clk":"11840686447","pt":1723550780409,"mc":[{"id":"1.231699683","rc":[{"batb":[[0,2.34,28.91],[1,1.25,100],[2,1.08,7.82]],"ltp":2.38,"tv":4.29,"id":2780}]}]}
{"op":"mcm","clk":"11840686636","pt":1723550782886,"mc":[{"id":"1.231699683","rc":[{"batb":[[0,2.36,10],[1,2.34,28.91],[2,1.25,100]],"ltp":2.38,"tv":4.29,"id":2780}]}]}
{"op":"mcm","clk":"11840686885","pt":1723550786704,"mc":[{"id":"1.231699683","rc":[{"batb":[[0,2.34,28.91],[1,1.25,100],[2,1.08,7.82]],"ltp":2.38,"tv":4.29,"id":2780}]}]}
{"op":"mcm","clk":"11840687407","pt":1723550793814,"mc":[{"id":"1.231699683","rc":[{"batb":[[0,2.36,10],[1,2.34,28.91],[2,1.25,100]],"ltp":2.38,"tv":4.29,"id":2780}]}]}
{"op":"mcm","clk":"11840687662","pt":1723550797117,"mc":[{"id":"1.231699683","rc":[{"batb":[[0,2.34,28.91],[1,1.25,100],[2,1.08,7.82]],"ltp":2.38,"tv":4.29,"id":2780}]}]}
{"op":"mcm","clk":"11840688220","pt":1723550804506,"mc":[{"id":"1.231699683","rc":[{"batb":[[0,2.36,10],[1,2.34,28.91],[2,1.25,100]],"ltp":2.38,"tv":4.29,"id":2780}]}]}
{"op":"mcm","clk":"11840688500","pt":1723550808124,"mc":[{"id":"1.231699683","rc":[{"batb":[[0,2.34,28.91],[1,1.25,100],[2,1.08,7.82]],"ltp":2.38,"tv":4.29,"id":2780}]}]}
{"op":"mcm","clk":"11840688726","pt":1723550811236,"mc":[{"id":"1.231699683","rc":[{"batb":[[0,2.36,10],[1,2.34,28.91],[2,1.25,100]],"ltp":2.38,"tv":4.29,"id":2780}]}]}
{"op":"mcm","clk":"11840689074","pt":1723550815828,"mc":[{"id":"1.231699683","rc":[{"batb":[[0,2.34,28.91],[1,1.25,100],[2,1.08,7.82]],"ltp":2.38,"tv":4.29,"id":2780}]}]}
{"op":"mcm","clk":"11840689238","pt":1723550818152,"mc":[{"id":"1.231699683","rc":[{"batb":[[0,2.36,10],[1,2.34,28.91],[2,1.25,100]],"ltp":2.38,"tv":4.29,"id":2780}]}]}
{"op":"mcm","clk":"11840689526","pt":1723550821355,"mc":[{"id":"1.231699683","rc":[{"batb":[[0,2.34,28.91],[1,1.25,100],[2,1.08,7.82]],"ltp":2.38,"tv":4.29,"id":2780}]}]}
{"op":"mcm","clk":"11840689718","pt":1723550823631,"mc":[{"id":"1.231699683","rc":[{"batb":[[0,2.36,10],[1,2.34,28.91],[2,1.25,100]],"ltp":2.38,"tv":4.29,"id":2780}]}]}
{"op":"mcm","clk":"11840689983","pt":1723550826851,"mc":[{"id":"1.231699683","rc":[{"batb":[[0,2.34,28.91],[1,1.25,100],[2,1.08,7.82]],"ltp":2.38,"tv":4.29,"id":2780}]}]}
{"op":"mcm","clk":"11840690181","pt":1723550829130,"mc":[{"id":"1.231699683","rc":[{"batb":[[0,2.36,10],[1,2.34,28.91],[2,1.25,100]],"ltp":2.38,"tv":4.29,"id":2780}]}]}
{"op":"mcm","clk":"11840690472","pt":1723550832759,"mc":[{"id":"1.231699683","rc":[{"batb":[[0,2.34,28.91],[1,1.25,100],[2,1.08,7.82]],"ltp":2.38,"tv":4.29,"id":2780}]}]}
{"op":"mcm","clk":"11840690743","pt":1723550836181,"mc":[{"id":"1.231699683","rc":[{"batb":[[0,2.36,10],[1,2.34,28.91],[2,1.25,100]],"ltp":2.38,"tv":4.29,"id":2780}]}]}
{"op":"mcm","clk":"11840690993","pt":1723550839385,"mc":[{"id":"1.231699683","rc":[{"batb":[[0,2.34,28.91],[1,1.25,100],[2,1.08,7.82]],"ltp":2.38,"tv":4.29,"id":2780}]}]}
{"op":"mcm","clk":"11840691175","pt":1723550841765,"mc":[{"id":"1.231699683","rc":[{"batb":[[0,2.36,10],[1,2.34,28.91],[2,1.25,100]],"ltp":2.38,"tv":4.29,"id":2780}]}]}
{"op":"mcm","clk":"11840691428","pt":1723550845076,"mc":[{"id":"1.231699683","rc":[{"batb":[[0,2.34,28.91],[1,1.25,100],[2,1.08,7.82]],"ltp":2.38,"tv":4.29,"id":2780}]}]}
{"op":"mcm","clk":"11840692180","pt":1723550854005,"mc":[{"id":"1.231699683","rc":[{"batb":[[0,2.36,10],[1,2.34,28.91],[2,1.25,100]],"ltp":2.38,"tv":4.29,"id":2780}]}]}
{"op":"mcm","clk":"11840692441","pt":1723550857308,"mc":[{"id":"1.231699683","rc":[{"batb":[[0,2.34,28.91],[1,1.25,100],[2,1.08,7.82]],"ltp":2.38,"tv":4.29,"id":2780}]}]}
{"op":"mcm","clk":"11840693058","pt":1723550865293,"mc":[{"id":"1.231699683","rc":[{"batb":[[0,2.36,10],[1,2.34,28.91],[2,1.25,100]],"ltp":2.38,"tv":4.29,"id":2780}]}]}
{"op":"mcm","clk":"11840693295","pt":1723550868595,"mc":[{"id":"1.231699683","rc":[{"batb":[[0,2.34,28.91],[1,1.25,100],[2,1.08,7.82]],"ltp":2.38,"tv":4.29,"id":2780}]}]}
{"op":"mcm","clk":"11840693583","pt":1723550872821,"mc":[{"id":"1.231699683","rc":[{"batb":[[0,2.36,10],[1,2.34,28.91],[2,1.25,100]],"ltp":2.38,"tv":4.29,"id":2780}]}]}
{"op":"mcm","clk":"11840693791","pt":1723550876332,"mc":[{"id":"1.231699683","rc":[{"batb":[[0,2.34,28.91],[1,1.25,100],[2,1.08,7.82]],"ltp":2.38,"tv":4.29,"id":2780}]}]}
{"op":"mcm","clk":"11840694018","pt":1723550879647,"mc":[{"id":"1.231699683","rc":[{"batb":[[0,2.36,10],[1,2.34,28.91],[2,1.25,100]],"ltp":2.38,"tv":4.29,"id":2780}]}]}
{"op":"mcm","clk":"11840694268","pt":1723550883226,"mc":[{"id":"1.231699683","rc":[{"batb":[[0,2.34,28.91],[1,1.25,100],[2,1.08,7.82]],"ltp":2.38,"tv":4.29,"id":2780}]}]}
{"op":"mcm","clk":"11840694420","pt":1723550885541,"mc":[{"id":"1.231699683","rc":[{"batb":[[0,2.36,10],[1,2.34,28.91],[2,1.25,100]],"ltp":2.38,"tv":4.29,"id":2780}]}]}
{"op":"mcm","clk":"11840694654","pt":1723550889002,"mc":[{"id":"1.231699683","rc":[{"batb":[[0,2.34,28.91],[1,1.25,100],[2,1.08,7.82]],"ltp":2.38,"tv":4.29,"id":2780}]}]}
{"op":"mcm","clk":"11840695029","pt":1723550894966,"mc":[{"id":"1.231699683","rc":[{"batb":[[0,2.36,10],[1,2.34,28.91],[2,1.25,100]],"ltp":2.38,"tv":4.29,"id":2780}]}]}
{"op":"mcm","clk":"11840695266","pt":1723550898360,"mc":[{"id":"1.231699683","rc":[{"batb":[[0,2.34,28.91],[1,1.25,100],[2,1.08,7.82]],"ltp":2.38,"tv":4.29,"id":2780}]}]}
{"op":"mcm","clk":"11840695857","pt":1723550909051,"mc":[{"id":"1.231699683","rc":[{"batb":[[0,2.36,10],[1,2.34,28.91],[2,1.25,100]],"ltp":2.38,"tv":4.29,"id":2780}]}]}
{"op":"mcm","clk":"11840696060","pt":1723550912648,"mc":[{"id":"1.231699683","rc":[{"batb":[[0,2.34,28.91],[1,1.25,100],[2,1.08,7.82]],"ltp":2.38,"tv":4.29,"id":2780}]}]}
{"op":"mcm","clk":"11840696456","pt":1723550918976,"mc":[{"id":"1.231699683","rc":[{"batb":[[0,2.36,10],[1,2.34,28.91],[2,1.25,100]],"ltp":2.38,"tv":4.29,"id":2780}]}]}
{"op":"mcm","clk":"11840696690","pt":1723550922793,"mc":[{"id":"1.231699683","rc":[{"batb":[[0,2.34,28.91],[1,1.25,100],[2,1.08,7.82]],"ltp":2.38,"tv":4.29,"id":2780}]}]}
{"op":"mcm","clk":"11840697062","pt":1723550929159,"mc":[{"id":"1.231699683","rc":[{"batb":[[0,2.36,10],[1,2.34,28.91],[2,1.25,100]],"ltp":2.38,"tv":4.29,"id":2780}]}]}
{"op":"mcm","clk":"11840697262","pt":1723550932608,"mc":[{"id":"1.231699683","rc":[{"batb":[[0,2.34,28.91],[1,1.25,100],[2,1.08,7.82]],"ltp":2.38,"tv":4.29,"id":2780}]}]}
{"op":"mcm","clk":"11840697388","pt":1723550935083,"mc":[{"id":"1.231699683","rc":[{"batb":[[0,2.36,10],[1,2.34,28.91],[2,1.25,100]],"ltp":2.38,"tv":4.29,"id":2780}]}]}
{"op":"mcm","clk":"11840697569","pt":1723550938375,"mc":[{"id":"1.231699683","rc":[{"batb":[[0,2.34,28.91],[1,1.25,100],[2,1.08,7.82]],"ltp":2.38,"tv":4.29,"id":2780}]}]}
{"op":"mcm","clk":"11840698081","pt":1723550945902,"mc":[{"id":"1.231699683","rc":[{"batb":[[0,2.36,10],[1,2.34,28.91],[2,1.25,100]],"ltp":2.38,"tv":4.29,"id":2780}]}]}
{"op":"mcm","clk":"11840698306","pt":1723550949091,"mc":[{"id":"1.231699683","rc":[{"batb":[[0,2.34,28.91],[1,1.25,100],[2,1.08,7.82]],"ltp":2.38,"tv":4.29,"id":2780}]}]}
{"op":"mcm","clk":"11840699507","pt":1723550966919,"mc":[{"id":"1.231699683","rc":[{"batb":[[0,2.36,10],[1,2.34,28.91],[2,1.25,100]],"ltp":2.38,"tv":4.29,"id":2780}]}]}
{"op":"mcm","clk":"11840699713","pt":1723550970317,"mc":[{"id":"1.231699683","rc":[{"batb":[[0,2.34,28.91],[1,1.25,100],[2,1.08,7.82]],"ltp":2.38,"tv":4.29,"id":2780}]}]}
{"op":"mcm","clk":"11840699899","pt":1723550973617,"mc":[{"id":"1.231699683","rc":[{"batb":[[0,2.36,10],[1,2.34,28.91],[2,1.25,100]],"ltp":2.38,"tv":4.29,"id":2780}]}]}
{"op":"mcm","clk":"11840700124","pt":1723550977238,"mc":[{"id":"1.231699683","rc":[{"batb":[[0,2.34,28.91],[1,1.25,100],[2,1.08,7.82]],"ltp":2.38,"tv":4.29,"id":2780}]}]}
{"op":"mcm","clk":"11840700612","pt":1723550985960,"mc":[{"id":"1.231699683","rc":[{"batb":[[0,2.36,10],[1,2.34,28.91],[2,1.25,100]],"ltp":2.38,"tv":4.29,"id":2780}]}]}
{"op":"mcm","clk":"11840700815","pt":1723550989376,"mc":[{"id":"1.231699683","rc":[{"batb":[[0,2.34,28.91],[1,1.25,100],[2,1.08,7.82]],"ltp":2.38,"tv":4.29,"id":2780}]}]}
{"op":"mcm","clk":"11840701346","pt":1723550998777,"mc":[{"id":"1.231699683","rc":[{"batb":[[0,2.36,10],[1,2.34,28.91],[2,1.25,100]],"ltp":2.38,"tv":4.29,"id":2780}]}]}
{"op":"mcm","clk":"11840701550","pt":1723551002347,"mc":[{"id":"1.231699683","rc":[{"batb":[[0,2.34,28.91],[1,1.25,100],[2,1.08,7.82]],"ltp":2.38,"tv":4.29,"id":2780}]}]}
{"op":"mcm","clk":"11840702250","pt":1723551012556,"mc":[{"id":"1.231699683","rc":[{"batb":[[0,2.36,10],[1,2.34,28.91],[2,1.25,100]],"ltp":2.38,"tv":4.29,"id":2780}]}]}
{"op":"mcm","clk":"11840702470","pt":1723551016071,"mc":[{"id":"1.231699683","rc":[{"batb":[[0,2.34,28.91],[1,1.25,100],[2,1.08,7.82]],"ltp":2.38,"tv":4.29,"id":2780}]}]}
{"op":"mcm","clk":"11840703584","pt":1723551033515,"mc":[{"id":"1.231699683","rc":[{"batb":[[0,2.36,10],[1,2.34,28.91],[2,1.25,100]],"ltp":2.38,"tv":4.29,"id":2780}]}]}
{"op":"mcm","clk":"11840703816","pt":1723551036911,"mc":[{"id":"1.231699683","rc":[{"batb":[[0,2.34,28.91],[1,1.25,100],[2,1.08,7.82]],"ltp":2.38,"tv":4.29,"id":2780}]}]}
{"op":"mcm","clk":"11840704127","pt":1723551041094,"mc":[{"id":"1.231699683","rc":[{"batb":[[0,2.36,10],[1,2.34,28.91],[2,1.25,100]],"ltp":2.38,"tv":4.29,"id":2780}]}]}
{"op":"mcm","clk":"11840704389","pt":1723551044701,"mc":[{"id":"1.231699683","rc":[{"batb":[[0,2.34,28.91],[1,1.25,100],[2,1.08,7.82]],"ltp":2.38,"tv":4.29,"id":2780}]}]}
{"op":"mcm","clk":"11840705034","pt":1723551054125,"mc":[{"id":"1.231699683","rc":[{"batb":[[0,2.36,10],[1,2.34,28.91],[2,1.25,100]],"ltp":2.38,"tv":4.29,"id":2780}]}]}
{"op":"mcm","clk":"11840705233","pt":1723551057716,"mc":[{"id":"1.231699683","rc":[{"batb":[[0,2.34,28.91],[1,1.25,100],[2,1.08,7.82]],"ltp":2.38,"tv":4.29,"id":2780}]}]}
{"op":"mcm","clk":"11840705431","pt":1723551060851,"mc":[{"id":"1.231699683","rc":[{"batb":[[0,2.36,10],[1,2.34,28.91],[2,1.25,100]],"ltp":2.38,"tv":4.29,"id":2780}]}]}
{"op":"mcm","clk":"11840705722","pt":1723551064457,"mc":[{"id":"1.231699683","rc":[{"batb":[[0,2.34,28.91],[1,1.25,100],[2,1.08,7.82]],"ltp":2.38,"tv":4.29,"id":2780}]}]}
{"op":"mcm","clk":"11840706088","pt":1723551069031,"mc":[{"id":"1.231699683","rc":[{"batb":[[0,2.36,10],[1,2.34,28.91],[2,1.25,100]],"ltp":2.38,"tv":4.29,"id":2780}]}]}
{"op":"mcm","clk":"11840706355","pt":1723551072431,"mc":[{"id":"1.231699683","rc":[{"batb":[[0,2.34,28.91],[1,1.25,100],[2,1.08,7.82]],"ltp":2.38,"tv":4.29,"id":2780}]}]}
{"op":"mcm","clk":"11840706945","pt":1723551080980,"mc":[{"id":"1.231699683","rc":[{"batb":[[0,2.36,10],[1,2.34,28.91],[2,1.25,100]],"ltp":2.38,"tv":4.29,"id":2780}]}]}
{"op":"mcm","clk":"11840707155","pt":1723551084374,"mc":[{"id":"1.231699683","rc":[{"batb":[[0,2.34,28.91],[1,1.25,100],[2,1.08,7.82]],"ltp":2.38,"tv":4.29,"id":2780}]}]}
{"op":"mcm","clk":"11840707620","pt":1723551093168,"mc":[{"id":"1.231699683","rc":[{"batb":[[0,2.36,10],[1,2.34,28.91],[2,1.25,100]],"ltp":2.38,"tv":4.29,"id":2780}]}]}
{"op":"mcm","clk":"11840707833","pt":1723551096414,"mc":[{"id":"1.231699683","rc":[{"batb":[[0,2.34,28.91],[1,1.25,100],[2,1.08,7.82]],"ltp":2.38,"tv":4.29,"id":2780}]}]}
{"op":"mcm","clk":"11840708052","pt":1723551099294,"mc":[{"id":"1.231699683","rc":[{"batb":[[0,2.36,10],[1,2.34,28.91],[2,1.25,100]],"ltp":2.38,"tv":4.29,"id":2780}]}]}
{"op":"mcm","clk":"11840708280","pt":1723551102787,"mc":[{"id":"1.231699683","rc":[{"batb":[[0,2.34,28.91],[1,1.25,100],[2,1.08,7.82]],"ltp":2.38,"tv":4.29,"id":2780}]}]}
{"op":"mcm","clk":"11840708463","pt":1723551105305,"mc":[{"id":"1.231699683","rc":[{"batb":[[0,2.36,10],[1,2.34,28.91],[2,1.25,100]],"ltp":2.38,"tv":4.29,"id":2780}]}]}
{"op":"mcm","clk":"11840708677","pt":1723551108602,"mc":[{"id":"1.231699683","rc":[{"batb":[[0,2.34,28.91],[1,1.25,100],[2,1.08,7.82]],"ltp":2.38,"tv":4.29,"id":2780}]}]}
{"op":"mcm","clk":"11840709070","pt":1723551115040,"mc":[{"id":"1.231699683","rc":[{"batb":[[0,2.36,10],[1,2.34,28.91],[2,1.25,100]],"ltp":2.38,"tv":4.29,"id":2780}]}]}
{"op":"mcm","clk":"11840709260","pt":1723551118335,"mc":[{"id":"1.231699683","rc":[{"batb":[[0,2.34,28.91],[1,1.25,100],[2,1.08,7.82]],"ltp":2.38,"tv":4.29,"id":2780}]}]}
{"op":"mcm","clk":"11840709438","pt":1723551120960,"mc":[{"id":"1.231699683","rc":[{"batb":[[0,2.36,10],[1,2.34,28.91],[2,1.25,100]],"ltp":2.38,"tv":4.29,"id":2780}]}]}
{"op":"mcm","clk":"11840709672","pt":1723551124264,"mc":[{"id":"1.231699683","rc":[{"batb":[[0,2.34,28.91],[1,1.25,100],[2,1.08,7.82]],"ltp":2.38,"tv":4.29,"id":2780}]}]}
{"op":"mcm","clk":"11840710100","pt":1723551130355,"mc":[{"id":"1.231699683","rc":[{"batb":[[0,2.36,10],[1,2.34,28.91],[2,1.25,100]],"ltp":2.38,"tv":4.29,"id":2780}]}]}
{"op":"mcm","clk":"11840710326","pt":1723551133647,"mc":[{"id":"1.231699683","rc":[{"batb":[[0,2.34,28.91],[1,1.25,100],[2,1.08,7.82]],"ltp":2.38,"tv":4.29,"id":2780}]}]}
{"op":"mcm","clk":"11840710546","pt":1723551137253,"mc":[{"id":"1.231699683","rc":[{"batb":[[0,2.36,10],[1,2.34,28.91],[2,1.25,100]],"ltp":2.38,"tv":4.29,"id":2780}]}]}
{"op":"mcm","clk":"11840710799","pt":1723551140799,"mc":[{"id":"1.231699683","rc":[{"batb":[[0,2.34,28.91],[1,1.25,100],[2,1.08,7.82]],"ltp":2.38,"tv":4.29,"id":2780}]}]}
{"op":"mcm","clk":"11840711028","pt":1723551144002,"mc":[{"id":"1.231699683","rc":[{"batb":[[0,2.36,10],[1,2.34,28.91],[2,1.25,100]],"ltp":2.38,"tv":4.29,"id":2780}]}]}
{"op":"mcm","clk":"11840711228","pt":1723551147395,"mc":[{"id":"1.231699683","rc":[{"batb":[[0,2.34,28.91],[1,1.25,100],[2,1.08,7.82]],"ltp":2.38,"tv":4.29,"id":2780}]}]}
{"op":"mcm","clk":"11840711574","pt":1723551152704,"mc":[{"id":"1.231699683","rc":[{"batb":[[0,2.36,10],[1,2.34,28.91],[2,1.25,100]],"ltp":2.38,"tv":4.29,"id":2780}]}]}
{"op":"mcm","clk":"11840711810","pt":1723551156311,"mc":[{"id":"1.231699683","rc":[{"batb":[[0,2.34,28.91],[1,1.25,100],[2,1.08,7.82]],"ltp":2.38,"tv":4.29,"id":2780}]}]}
{"op":"mcm","clk":"11840712039","pt":1723551159401,"mc":[{"id":"1.231699683","rc":[{"batb":[[0,2.36,10],[1,2.34,28.91],[2,1.25,100]],"ltp":2.38,"tv":4.29,"id":2780}]}]}
{"op":"mcm","clk":"11840712273","pt":1723551163006,"mc":[{"id":"1.231699683","rc":[{"batb":[[0,2.34,28.91],[1,1.25,100],[2,1.08,7.82]],"ltp":2.38,"tv":4.29,"id":2780}]}]}
{"op":"mcm","clk":"11840712475","pt":1723551165923,"mc":[{"id":"1.231699683","rc":[{"batb":[[0,2.36,10],[1,2.34,28.91],[2,1.25,100]],"ltp":2.38,"tv":4.29,"id":2780}]}]}
{"op":"mcm","clk":"11840712723","pt":1723551169530,"mc":[{"id":"1.231699683","rc":[{"batb":[[0,2.34,28.91],[1,1.25,100],[2,1.08,7.82]],"ltp":2.38,"tv":4.29,"id":2780}]}]}
{"op":"mcm","clk":"11840712926","pt":1723551172616,"mc":[{"id":"1.231699683","rc":[{"batb":[[0,2.36,10],[1,2.34,28.91],[2,1.25,100]],"ltp":2.38,"tv":4.29,"id":2780}]}]}
{"op":"mcm","clk":"11840720292","pt":1723551176131,"mc":[{"id":"1.231699683","rc":[{"batb":[[0,2.34,28.91],[1,1.25,100],[2,1.08,7.82]],"ltp":2.38,"tv":4.29,"id":2780}]}]}
{"op":"mcm","clk":"11840720604","pt":1723551180304,"mc":[{"id":"1.231699683","rc":[{"batb":[[0,2.36,10],[1,2.34,28.91],[2,1.25,100]],"ltp":2.38,"tv":4.29,"id":2780}]}]}
{"op":"mcm","clk":"11840720865","pt":1723551183940,"mc":[{"id":"1.231699683","rc":[{"batb":[[0,2.34,28.91],[1,1.25,100],[2,1.08,7.82]],"ltp":2.38,"tv":4.29,"id":2780}]}]}
{"op":"mcm","clk":"11840721050","pt":1723551186716,"mc":[{"id":"1.231699683","rc":[{"batb":[[0,2.36,10],[1,2.34,28.91],[2,1.25,100]],"ltp":2.38,"tv":4.29,"id":2780}]}]}
{"op":"mcm","clk":"11840721285","pt":1723551190334,"mc":[{"id":"1.231699683","rc":[{"batb":[[0,2.34,28.91],[1,1.25,100],[2,1.08,7.82]],"ltp":2.38,"tv":4.29,"id":2780}]}]}
{"op":"mcm","clk":"11840721653","pt":1723551195240,"mc":[{"id":"1.231699683","rc":[{"batb":[[0,2.36,10],[1,2.34,28.91],[2,1.25,100]],"ltp":2.38,"tv":4.29,"id":2780}]}]}
{"op":"mcm","clk":"11840721857","pt":1723551198432,"mc":[{"id":"1.231699683","rc":[{"batb":[[0,2.34,28.91],[1,1.25,100],[2,1.08,7.82]],"ltp":2.38,"tv":4.29,"id":2780}]}]}
{"op":"mcm","clk":"11840722020","pt":1723551200857,"mc":[{"id":"1.231699683","rc":[{"batb":[[0,2.36,10],[1,2.34,28.91],[2,1.25,100]],"ltp":2.38,"tv":4.29,"id":2780}]}]}
{"op":"mcm","clk":"11840722252","pt":1723551204165,"mc":[{"id":"1.231699683","rc":[{"batb":[[0,2.34,28.91],[1,1.25,100],[2,1.08,7.82]],"ltp":2.38,"tv":4.29,"id":2780}]}]}
{"op":"mcm","clk":"11840723051","pt":1723551216038,"mc":[{"id":"1.231699683","rc":[{"batb":[[0,2.36,10],[1,2.34,28.91],[2,1.25,100]],"ltp":2.38,"tv":4.29,"id":2780}]}]}
{"op":"mcm","clk":"11840723321","pt":1723551219519,"mc":[{"id":"1.231699683","rc":[{"batb":[[0,2.34,28.91],[1,1.25,100],[2,1.08,7.82]],"ltp":2.38,"tv":4.29,"id":2780}]}]}
{"op":"mcm","clk":"11840723545","pt":1723551222515,"mc":[{"id":"1.231699683","rc":[{"batb":[[0,2.36,10],[1,2.34,28.91],[2,1.25,100]],"ltp":2.38,"tv":4.29,"id":2780}]}]}
{"op":"mcm","clk":"11840723808","pt":1723551226037,"mc":[{"id":"1.231699683","rc":[{"batb":[[0,2.34,28.91],[1,1.25,100],[2,1.08,7.82]],"ltp":2.38,"tv":4.29,"id":2780}]}]}
{"op":"mcm","clk":"11840724133","pt":1723551230413,"mc":[{"id":"1.231699683","rc":[{"batb":[[0,2.36,10],[1,2.34,28.91],[2,1.25,100]],"ltp":2.38,"tv":4.29,"id":2780}]}]}
{"op":"mcm","clk":"11840724379","pt":1723551233958,"mc":[{"id":"1.231699683","rc":[{"batb":[[0,2.34,28.91],[1,1.25,100],[2,1.08,7.82]],"ltp":2.38,"tv":4.29,"id":2780}]}]}
{"op":"mcm","clk":"11840724600","pt":1723551237354,"mc":[{"id":"1.231699683","rc":[{"batb":[[0,2.36,10],[1,2.34,28.91],[2,1.25,100]],"ltp":2.38,"tv":4.29,"id":2780}]}]}
{"op":"mcm","clk":"11840724866","pt":1723551240656,"mc":[{"id":"1.231699683","rc":[{"batb":[[0,2.34,28.91],[1,1.25,100],[2,1.08,7.82]],"ltp":2.38,"tv":4.29,"id":2780}]}]}
{"op":"mcm","clk":"11840725057","pt":1723551243078,"mc":[{"id":"1.231699683","rc":[{"batb":[[0,2.36,10],[1,2.34,28.91],[2,1.25,100]],"ltp":2.38,"tv":4.29,"id":2780}]}]}
{"op":"mcm","clk":"11840725312","pt":1723551246447,"mc":[{"id":"1.231699683","rc":[{"batb":[[0,2.34,28.91],[1,1.25,100],[2,1.08,7.82]],"ltp":2.38,"tv":4.29,"id":2780}]}]}
{"op":"mcm","clk":"11840725670","pt":1723551251086,"mc":[{"id":"1.231699683","rc":[{"batb":[[0,2.36,10],[1,2.34,28.91],[2,1.25,100]],"ltp":2.38,"tv":4.29,"id":2780}]}]}
{"op":"mcm","clk":"11840725919","pt":1723551254264,"mc":[{"id":"1.231699683","rc":[{"batb":[[0,2.34,28.91],[1,1.25,100],[2,1.08,7.82]],"ltp":2.38,"tv":4.29,"id":2780}]}]}
{"op":"mcm","clk":"11840726908","pt":1723551267407,"mc":[{"id":"1.231699683","rc":[{"batb":[[0,2.36,10],[1,2.34,28.91],[2,1.25,100]],"ltp":2.38,"tv":4.29,"id":2780}]}]}
{"op":"mcm","clk":"11840727165","pt":1723551270811,"mc":[{"id":"1.231699683","rc":[{"batb":[[0,2.34,28.91],[1,1.25,100],[2,1.08,7.82]],"ltp":2.38,"tv":4.29,"id":2780}]}]}
{"op":"mcm","clk":"11840728569","pt":1723551288740,"mc":[{"id":"1.231699683","rc":[{"batb":[[0,2.36,10],[1,2.34,28.91],[2,1.25,100]],"ltp":2.38,"tv":4.29,"id":2780}]}]}
{"op":"mcm","clk":"11840728863","pt":1723551292106,"mc":[{"id":"1.231699683","rc":[{"batb":[[0,2.34,28.91],[1,1.25,100],[2,1.08,7.82]],"ltp":2.38,"tv":4.29,"id":2780}]}]}
{"op":"mcm","clk":"11840729506","pt":1723551300517,"mc":[{"id":"1.231699683","rc":[{"batb":[[0,2.36,10],[1,2.34,28.91],[2,1.25,100]],"ltp":2.38,"tv":4.29,"id":2780}]}]}
{"op":"mcm","clk":"11840729807","pt":1723551304244,"mc":[{"id":"1.231699683","rc":[{"batb":[[0,2.34,28.91],[1,1.25,100],[2,1.08,7.82]],"ltp":2.38,"tv":4.29,"id":2780}]}]}
{"op":"mcm","clk":"11840730758","pt":1723551314942,"mc":[{"id":"1.231699683","rc":[{"batb":[[0,2.36,10],[1,2.34,28.91],[2,1.25,100]],"ltp":2.38,"tv":4.29,"id":2780}]}]}
{"op":"mcm","clk":"11840731042","pt":1723551318554,"mc":[{"id":"1.231699683","rc":[{"batb":[[0,2.34,28.91],[1,1.25,100],[2,1.08,7.82]],"ltp":2.38,"tv":4.29,"id":2780}]}]}
{"op":"mcm","clk":"11840731285","pt":1723551321853,"mc":[{"id":"1.231699683","rc":[{"batb":[[0,2.36,10],[1,2.34,28.91],[2,1.25,100]],"ltp":2.38,"tv":4.29,"id":2780}]}]}
{"op":"mcm","clk":"11840731533","pt":1723551325355,"mc":[{"id":"1.231699683","rc":[{"batb":[[0,2.34,28.91],[1,1.25,100],[2,1.08,7.82]],"ltp":2.38,"tv":4.29,"id":2780}]}]}
{"op":"mcm","clk":"11840731763","pt":1723551328246,"mc":[{"id":"1.231699683","rc":[{"batb":[[0,2.36,10],[1,2.34,28.91],[2,1.25,100]],"ltp":2.38,"tv":4.29,"id":2780}]}]}
{"op":"mcm","clk":"11840732076","pt":1723551331950,"mc":[{"id":"1.231699683","rc":[{"batb":[[0,2.34,28.91],[1,1.25,100],[2,1.08,7.82]],"ltp":2.38,"tv":4.29,"id":2780}]}]}
{"op":"mcm","clk":"11840733313","pt":1723551348878,"mc":[{"id":"1.231699683","rc":[{"batb":[[0,2.36,10],[1,2.34,28.91],[2,1.25,100]],"ltp":2.38,"tv":4.29,"id":2780}]}]}
{"op":"mcm","clk":"11840733596","pt":1723551352070,"mc":[{"id":"1.231699683","rc":[{"batb":[[0,2.34,28.91],[1,1.25,100],[2,1.08,7.82]],"ltp":2.38,"tv":4.29,"id":2780}]}]}
{"op":"mcm","clk":"11840733980","pt":1723551356899,"mc":[{"id":"1.231699683","rc":[{"batb":[[0,2.36,10],[1,2.34,28.91],[2,1.25,100]],"ltp":2.38,"tv":4.29,"id":2780}]}]}
{"op":"mcm","clk":"11840734264","pt":1723551360514,"mc":[{"id":"1.231699683","rc":[{"batb":[[0,2.34,28.91],[1,1.25,100],[2,1.08,7.82]],"ltp":2.38,"tv":4.29,"id":2780}]}]}
{"op":"mcm","clk":"11840734488","pt":1723551363206,"mc":[{"id":"1.231699683","rc":[{"batb":[[0,2.36,10],[1,2.34,28.91],[2,1.25,100]],"ltp":2.38,"tv":4.29,"id":2780}]}]}
{"op":"mcm","clk":"11840734763","pt":1723551366714,"mc":[{"id":"1.231699683","rc":[{"batb":[[0,2.34,28.91],[1,1.25,100],[2,1.08,7.82]],"ltp":2.38,"tv":4.29,"id":2780}]}]}
{"op":"mcm","clk":"11840734992","pt":1723551369401,"mc":[{"id":"1.231699683","rc":[{"batb":[[0,2.36,10],[1,2.34,28.91],[2,1.25,100]],"ltp":2.38,"tv":4.29,"id":2780}]}]}
{"op":"mcm","clk":"11840735318","pt":1723551373021,"mc":[{"id":"1.231699683","rc":[{"batb":[[0,2.34,28.91],[1,1.25,100],[2,1.08,7.82]],"ltp":2.38,"tv":4.29,"id":2780}]}]}
{"op":"mcm","clk":"11840735588","pt":1723551375823,"mc":[{"id":"1.231699683","rc":[{"batb":[[0,2.36,10],[1,2.34,28.91],[2,1.25,100]],"ltp":2.38,"tv":4.29,"id":2780}]}]}
{"op":"mcm","clk":"11840735861","pt":1723551379230,"mc":[{"id":"1.231699683","rc":[{"batb":[[0,2.34,28.91],[1,1.25,100],[2,1.08,7.82]],"ltp":2.38,"tv":4.29,"id":2780}]}]}
{"op":"mcm","clk":"11840736627","pt":1723551388613,"mc":[{"id":"1.231699683","rc":[{"batb":[[0,2.36,10],[1,2.34,28.91],[2,1.25,100]],"ltp":2.38,"tv":4.29,"id":2780}]}]}
{"op":"mcm","clk":"11840736957","pt":1723551392013,"mc":[{"id":"1.231699683","rc":[{"batb":[[0,2.34,28.91],[1,1.25,100],[2,1.08,7.82]],"ltp":2.38,"tv":4.29,"id":2780}]}]}
{"op":"mcm","clk":"11840737175","pt":1723551394721,"mc":[{"id":"1.231699683","rc":[{"batb":[[0,2.36,10],[1,2.34,28.91],[2,1.25,100]],"ltp":2.38,"tv":4.29,"id":2780}]}]}
{"op":"mcm","clk":"11840737481","pt":1723551398228,"mc":[{"id":"1.231699683","rc":[{"batb":[[0,2.34,28.91],[1,1.25,100],[2,1.08,7.82]],"ltp":2.38,"tv":4.29,"id":2780}]}]}
{"op":"mcm","clk":"11840738309","pt":1723551408033,"mc":[{"id":"1.231699683","rc":[{"batb":[[0,2.36,10],[1,2.34,28.91],[2,1.25,100]],"ltp":2.38,"tv":4.29,"id":2780}]}]}
{"op":"mcm","clk":"11840738600","pt":1723551411647,"mc":[{"id":"1.231699683","rc":[{"batb":[[0,2.34,28.91],[1,1.25,100],[2,1.08,7.82]],"ltp":2.38,"tv":4.29,"id":2780}]}]}
{"op":"mcm","clk":"11840738926","pt":1723551415838,"mc":[{"id":"1.231699683","rc":[{"batb":[[0,2.36,10],[1,2.34,28.91],[2,1.25,100]],"ltp":2.38,"tv":4.29,"id":2780}]}]}
{"op":"mcm","clk":"11840739237","pt":1723551419157,"mc":[{"id":"1.231699683","rc":[{"batb":[[0,2.34,28.91],[1,1.25,100],[2,1.08,7.82]],"ltp":2.38,"tv":4.29,"id":2780}]}]}
{"op":"mcm","clk":"11840739424","pt":1723551421448,"mc":[{"id":"1.231699683","rc":[{"batb":[[0,2.36,10],[1,2.34,28.91],[2,1.25,100]],"ltp":2.38,"tv":4.29,"id":2780}]}]}
{"op":"mcm","clk":"11840739686","pt":1723551424948,"mc":[{"id":"1.231699683","rc":[{"batb":[[0,2.34,28.91],[1,1.25,100],[2,1.08,7.82]],"ltp":2.38,"tv":4.29,"id":2780}]}]}
{"op":"mcm","clk":"11840739883","pt":1723551427472,"mc":[{"id":"1.231699683","rc":[{"batb":[[0,2.36,10],[1,2.34,28.91],[2,1.25,100]],"ltp":2.38,"tv":4.29,"id":2780}]}]}
{"op":"mcm","clk":"11840740131","pt":1723551430989,"mc":[{"id":"1.231699683","rc":[{"batb":[[0,2.34,28.91],[1,1.25,100],[2,1.08,7.82]],"ltp":2.38,"tv":4.29,"id":2780}]}]}
{"op":"mcm","clk":"11840740448","pt":1723551434677,"mc":[{"id":"1.231699683","rc":[{"batb":[[0,2.36,10],[1,2.34,28.91],[2,1.25,100]],"ltp":2.38,"tv":4.29,"id":2780}]}]}
{"op":"mcm","clk":"11840740758","pt":1723551438348,"mc":[{"id":"1.231699683","rc":[{"batb":[[0,2.34,28.91],[1,1.25,100],[2,1.08,7.82]],"ltp":2.38,"tv":4.29,"id":2780}]}]}
{"op":"mcm","clk":"11840741182","pt":1723551444960,"mc":[{"id":"1.231699683","rc":[{"batb":[[0,2.36,10],[1,2.34,28.91],[2,1.25,100]],"ltp":2.38,"tv":4.29,"id":2780}]}]}
{"op":"mcm","clk":"11840741462","pt":1723551449486,"mc":[{"id":"1.231699683","rc":[{"batb":[[0,2.34,28.91],[1,1.25,100],[2,1.08,7.82]],"ltp":2.38,"tv":4.29,"id":2780}]}]}
{"op":"mcm","clk":"11840741937","pt":1723551457569,"mc":[{"id":"1.231699683","rc":[{"batb":[[0,2.36,10],[1,2.34,28.91],[2,1.25,100]],"ltp":2.38,"tv":4.29,"id":2780}]}]}
{"op":"mcm","clk":"11840742141","pt":1723551460800,"mc":[{"id":"1.231699683","rc":[{"batb":[[0,2.34,28.91],[1,1.25,100],[2,1.08,7.82]],"ltp":2.38,"tv":4.29,"id":2780}]}]}
{"op":"mcm","clk":"11840742295","pt":1723551463479,"mc":[{"id":"1.231699683","rc":[{"batb":[[0,2.36,10],[1,2.34,28.91],[2,1.25,100]],"ltp":2.38,"tv":4.29,"id":2780}]}]}
{"op":"mcm","clk":"11840742493","pt":1723551466791,"mc":[{"id":"1.231699683","rc":[{"batb":[[0,2.34,28.91],[1,1.25,100],[2,1.08,7.82]],"ltp":2.38,"tv":4.29,"id":2780}]}]}
{"op":"mcm","clk":"11840742994","pt":1723551474118,"mc":[{"id":"1.231699683","rc":[{"batb":[[0,2.36,10],[1,2.34,28.91],[2,1.25,100]],"ltp":2.38,"tv":4.29,"id":2780}]}]}
{"op":"mcm","clk":"11840743215","pt":1723551477696,"mc":[{"id":"1.231699683","rc":[{"batb":[[0,2.34,28.91],[1,1.25,100],[2,1.08,7.82]],"ltp":2.38,"tv":4.29,"id":2780}]}]}
{"op":"mcm","clk":"11840743454","pt":1723551481148,"mc":[{"id":"1.231699683","rc":[{"batb":[[0,2.36,10],[1,2.34,28.91],[2,1.25,100]],"ltp":2.38,"tv":4.29,"id":2780}]}]}
{"op":"mcm","clk":"11840743687","pt":1723551484317,"mc":[{"id":"1.231699683","rc":[{"batb":[[0,2.34,28.91],[1,1.25,100],[2,1.08,7.82]],"ltp":2.38,"tv":4.29,"id":2780}]}]}
{"op":"mcm","clk":"11840743941","pt":1723551488232,"mc":[{"id":"1.231699683","rc":[{"batb":[[0,2.36,10],[1,2.34,28.91],[2,1.25,100]],"ltp":2.38,"tv":4.29,"id":2780}]}]}
{"op":"mcm","clk":"11840744161","pt":1723551491424,"mc":[{"id":"1.231699683","rc":[{"batb":[[0,2.34,28.91],[1,1.25,100],[2,1.08,7.82]],"ltp":2.38,"tv":4.29,"id":2780}]}]}
{"op":"mcm","clk":"11840744534","pt":1723551496346,"mc":[{"id":"1.231699683","rc":[{"batb":[[0,2.36,10],[1,2.34,28.91],[2,1.25,100]],"ltp":2.38,"tv":4.29,"id":2780}]}]}
{"op":"mcm","clk":"11840744785","pt":1723551499651,"mc":[{"id":"1.231699683","rc":[{"batb":[[0,2.34,28.91],[1,1.25,100],[2,1.08,7.82]],"ltp":2.38,"tv":4.29,"id":2780}]}]}
{"op":"mcm","clk":"11840745333","pt":1723551507136,"mc":[{"id":"1.231699683","rc":[{"batb":[[0,2.36,10],[1,2.34,28.91],[2,1.25,100]],"ltp":2.38,"tv":4.29,"id":2780}]}]}
{"op":"mcm","clk":"11840745599","pt":1723551510555,"mc":[{"id":"1.231699683","rc":[{"batb":[[0,2.34,28.91],[1,1.25,100],[2,1.08,7.82]],"ltp":2.38,"tv":4.29,"id":2780}]}]}
{"op":"mcm","clk":"11840745863","pt":1723551513864,"mc":[{"id":"1.231699683","rc":[{"batb":[[0,2.36,10],[1,2.34,28.91],[2,1.25,100]],"ltp":2.38,"tv":4.29,"id":2780}]}]}
{"op":"mcm","clk":"11840746115","pt":1723551517280,"mc":[{"id":"1.231699683","rc":[{"batb":[[0,2.34,28.91],[1,1.25,100],[2,1.08,7.82]],"ltp":2.38,"tv":4.29,"id":2780}]}]}
{"op":"mcm","clk":"11840746408","pt":1723551521472,"mc":[{"id":"1.231699683","rc":[{"batb":[[0,2.36,10],[1,2.34,28.91],[2,1.25,100]],"ltp":2.38,"tv":4.29,"id":2780}]}]}
{"op":"mcm","clk":"11840746634","pt":1723551524868,"mc":[{"id":"1.231699683","rc":[{"batb":[[0,2.34,28.91],[1,1.25,100],[2,1.08,7.82]],"ltp":2.38,"tv":4.29,"id":2780}]}]}
{"op":"mcm","clk":"11840746846","pt":1723551528172,"mc":[{"id":"1.231699683","rc":[{"batb":[[0,2.36,10],[1,2.34,28.91],[2,1.25,100]],"ltp":2.38,"tv":4.29,"id":2780}]}]}
{"op":"mcm","clk":"11840747061","pt":1723551531475,"mc":[{"id":"1.231699683","rc":[{"batb":[[0,2.34,28.91],[1,1.25,100],[2,1.08,7.82]],"ltp":2.38,"tv":4.29,"id":2780}]}]}
{"op":"mcm","clk":"11840747601","pt":1723551539080,"mc":[{"id":"1.231699683","rc":[{"batb":[[0,2.36,10],[1,2.34,28.91],[2,1.25,100]],"ltp":2.38,"tv":4.29,"id":2780}]}]}
{"op":"mcm","clk":"11840747818","pt":1723551542493,"mc":[{"id":"1.231699683","rc":[{"batb":[[0,2.34,28.91],[1,1.25,100],[2,1.08,7.82]],"ltp":2.38,"tv":4.29,"id":2780}]}]}
{"op":"mcm","clk":"11840748111","pt":1723551547295,"mc":[{"id":"1.231699683","rc":[{"batb":[[0,2.36,10],[1,2.34,28.91],[2,1.25,100]],"ltp":2.38,"tv":4.29,"id":2780}]}]}
{"op":"mcm","clk":"11840748349","pt":1723551550804,"mc":[{"id":"1.231699683","rc":[{"batb":[[0,2.34,28.91],[1,1.25,100],[2,1.08,7.82]],"ltp":2.38,"tv":4.29,"id":2780}]}]}
{"op":"mcm","clk":"11840748517","pt":1723551553192,"mc":[{"id":"1.231699683","rc":[{"batb":[[0,2.36,10],[1,2.34,28.91],[2,1.25,100]],"ltp":2.38,"tv":4.29,"id":2780}]}]}
{"op":"mcm","clk":"11840748705","pt":1723551556495,"mc":[{"id":"1.231699683","rc":[{"batb":[[0,2.34,28.91],[1,1.25,100],[2,1.08,7.82]],"ltp":2.38,"tv":4.29,"id":2780}]}]}
{"op":"mcm","clk":"11840748803","pt":1723551558603,"mc":[{"id":"1.231699683","rc":[{"batb":[[0,2.36,10],[1,2.34,28.91],[2,1.25,100]],"ltp":2.38,"tv":4.29,"id":2780}]}]}
{"op":"mcm","clk":"11840748956","pt":1723551562111,"mc":[{"id":"1.231699683","rc":[{"batb":[[0,2.34,28.91],[1,1.25,100],[2,1.08,7.82]],"ltp":2.38,"tv":4.29,"id":2780}]}]}
{"op":"mcm","clk":"11840749198","pt":1723551567209,"mc":[{"id":"1.231699683","rc":[{"batb":[[0,2.36,10],[1,2.34,28.91],[2,1.25,100]],"ltp":2.38,"tv":4.29,"id":2780}]}]}
{"op":"mcm","clk":"11840749400","pt":1723551570713,"mc":[{"id":"1.231699683","rc":[{"batb":[[0,2.34,28.91],[1,1.25,100],[2,1.08,7.82]],"ltp":2.38,"tv":4.29,"id":2780}]}]}
{"op":"mcm","clk":"11840749598","pt":1723551573817,"mc":[{"id":"1.231699683","rc":[{"batb":[[0,2.36,10],[1,2.34,28.91],[2,1.25,100]],"ltp":2.38,"tv":4.29,"id":2780}]}]}
{"op":"mcm","clk":"11840749801","pt":1723551577214,"mc":[{"id":"1.231699683","rc":[{"batb":[[0,2.34,28.91],[1,1.25,100],[2,1.08,7.82]],"ltp":2.38,"tv":4.29,"id":2780}]}]}
{"op":"mcm","clk":"11840750029","pt":1723551581641,"mc":[{"id":"1.231699683","rc":[{"batb":[[0,2.36,10],[1,2.34,28.91],[2,1.25,100]],"ltp":2.38,"tv":4.29,"id":2780}]}]}
{"op":"mcm","clk":"11840750235","pt":1723551584947,"mc":[{"id":"1.231699683","rc":[{"batb":[[0,2.34,28.91],[1,1.25,100],[2,1.08,7.82]],"ltp":2.38,"tv":4.29,"id":2780}]}]}
{"op":"mcm","clk":"11840750497","pt":1723551589650,"mc":[{"id":"1.231699683","rc":[{"batb":[[0,2.36,10],[1,2.34,28.91],[2,1.25,100]],"ltp":2.38,"tv":4.29,"id":2780}]}]}
{"op":"mcm","clk":"11840750696","pt":1723551593063,"mc":[{"id":"1.231699683","rc":[{"batb":[[0,2.34,28.91],[1,1.25,100],[2,1.08,7.82]],"ltp":2.38,"tv":4.29,"id":2780}]}]}
{"op":"mcm","clk":"11840750866","pt":1723551595844,"mc":[{"id":"1.231699683","rc":[{"batb":[[0,2.36,10],[1,2.34,28.91],[2,1.25,100]],"ltp":2.38,"tv":4.29,"id":2780}]}]}
{"op":"mcm","clk":"11840751066","pt":1723551599146,"mc":[{"id":"1.231699683","rc":[{"batb":[[0,2.34,28.91],[1,1.25,100],[2,1.08,7.82]],"ltp":2.38,"tv":4.29,"id":2780}]}]}
{"op":"mcm","clk":"11840751405","pt":1723551605350,"mc":[{"id":"1.231699683","rc":[{"batb":[[0,2.36,10],[1,2.34,28.91],[2,1.25,100]],"ltp":2.38,"tv":4.29,"id":2780}]}]}
{"op":"mcm","clk":"11840751604","pt":1723551608853,"mc":[{"id":"1.231699683","rc":[{"batb":[[0,2.34,28.91],[1,1.25,100],[2,1.08,7.82]],"ltp":2.38,"tv":4.29,"id":2780}]}]}
{"op":"mcm","clk":"11840752283","pt":1723551620756,"mc":[{"id":"1.231699683","rc":[{"batb":[[0,2.36,10],[1,2.34,28.91],[2,1.25,100]],"ltp":2.38,"tv":4.29,"id":2780}]}]}
{"op":"mcm","clk":"11840752456","pt":1723551624367,"mc":[{"id":"1.231699683","rc":[{"batb":[[0,2.34,28.91],[1,1.25,100],[2,1.08,7.82]],"ltp":2.38,"tv":4.29,"id":2780}]}]}
{"op":"mcm","clk":"11840752601","pt":1723551627475,"mc":[{"id":"1.231699683","rc":[{"batb":[[0,2.36,10],[1,2.34,28.91],[2,1.25,100]],"ltp":2.38,"tv":4.29,"id":2780}]}]}
{"op":"mcm","clk":"11840752802","pt":1723551630792,"mc":[{"id":"1.231699683","rc":[{"batb":[[0,2.34,28.91],[1,1.25,100],[2,1.08,7.82]],"ltp":2.38,"tv":4.29,"id":2780}]}]}
{"op":"mcm","clk":"11840753009","pt":1723551633896,"mc":[{"id":"1.231699683","rc":[{"batb":[[0,2.36,10],[1,2.34,28.91],[2,1.25,100]],"ltp":2.38,"tv":4.29,"id":2780}]}]}
{"op":"mcm","clk":"11840753196","pt":1723551637614,"mc":[{"id":"1.231699683","rc":[{"batb":[[0,2.34,28.91],[1,1.25,100],[2,1.08,7.82]],"ltp":2.38,"tv":4.29,"id":2780}]}]}
{"op":"mcm","clk":"11840753483","pt":1723551642882,"mc":[{"id":"1.231699683","rc":[{"batb":[[0,2.36,10],[1,2.34,28.91],[2,1.25,100]],"ltp":2.38,"tv":4.29,"id":2780}]}]}
{"op":"mcm","clk":"11840753693","pt":1723551646490,"mc":[{"id":"1.231699683","rc":[{"batb":[[0,2.34,28.91],[1,1.25,100],[2,1.08,7.82]],"ltp":2.38,"tv":4.29,"id":2780}]}]}
{"op":"mcm","clk":"11840754270","pt":1723551658100,"mc":[{"id":"1.231699683","rc":[{"batb":[[0,2.36,10],[1,2.34,28.91],[2,1.25,100]],"ltp":2.38,"tv":4.29,"id":2780}]}]}
{"op":"mcm","clk":"11840754488","pt":1723551661809,"mc":[{"id":"1.231699683","rc":[{"batb":[[0,2.34,28.91],[1,1.25,100],[2,1.08,7.82]],"ltp":2.38,"tv":4.29,"id":2780}]}]}
{"op":"mcm","clk":"11840754804","pt":1723551667012,"mc":[{"id":"1.231699683","rc":[{"batb":[[0,2.36,10],[1,2.34,28.91],[2,1.25,100]],"ltp":2.38,"tv":4.29,"id":2780}]}]}
{"op":"mcm","clk":"11840754972","pt":1723551670604,"mc":[{"id":"1.231699683","rc":[{"batb":[[0,2.34,28.91],[1,1.25,100],[2,1.08,7.82]],"ltp":2.38,"tv":4.29,"id":2780}]}]}
{"op":"mcm","clk":"11840755136","pt":1723551673838,"mc":[{"id":"1.231699683","rc":[{"batb":[[0,2.36,10],[1,2.34,28.91],[2,1.25,100]],"ltp":2.38,"tv":4.29,"id":2780}]}]}
{"op":"mcm","clk":"11840755367","pt":1723551677437,"mc":[{"id":"1.231699683","rc":[{"batb":[[0,2.34,28.91],[1,1.25,100],[2,1.08,7.82]],"ltp":2.38,"tv":4.29,"id":2780}]}]}
{"op":"mcm","clk":"11840756014","pt":1723551689464,"mc":[{"id":"1.231699683","rc":[{"batb":[[0,2.36,10],[1,2.34,28.91],[2,1.25,100]],"ltp":2.38,"tv":4.29,"id":2780}]}]}
{"op":"mcm","clk":"11840756203","pt":1723551692964,"mc":[{"id":"1.231699683","rc":[{"batb":[[0,2.34,28.91],[1,1.25,100],[2,1.08,7.82]],"ltp":2.38,"tv":4.29,"id":2780}]}]}
{"op":"mcm","clk":"11840756401","pt":1723551696777,"mc":[{"id":"1.231699683","rc":[{"batb":[[0,2.36,10],[1,2.34,28.91],[2,1.25,100]],"ltp":2.38,"tv":4.29,"id":2780}]}]}
{"op":"mcm","clk":"11840756591","pt":1723551700156,"mc":[{"id":"1.231699683","rc":[{"batb":[[0,2.34,28.91],[1,1.25,100],[2,1.08,7.82]],"ltp":2.38,"tv":4.29,"id":2780}]}]}
{"op":"mcm","clk":"11840756825","pt":1723551704685,"mc":[{"id":"1.231699683","rc":[{"batb":[[0,2.36,10],[1,2.34,28.91],[2,1.25,100]],"ltp":2.38,"tv":4.29,"id":2780}]}]}
{"op":"mcm","clk":"11840756986","pt":1723551708080,"mc":[{"id":"1.231699683","rc":[{"batb":[[0,2.34,28.91],[1,1.25,100],[2,1.08,7.82]],"ltp":2.38,"tv":4.29,"id":2780}]}]}
{"op":"mcm","clk":"11840757528","pt":1723551719195,"mc":[{"id":"1.231699683","rc":[{"batb":[[0,2.36,10],[1,2.34,28.91],[2,1.25,100]],"ltp":2.38,"tv":4.29,"id":2780}]}]}
{"op":"mcm","clk":"11840757774","pt":1723551722853,"mc":[{"id":"1.231699683","rc":[{"batb":[[0,2.34,28.91],[1,1.25,100],[2,1.08,7.82]],"ltp":2.38,"tv":4.29,"id":2780}]}]}
{"op":"mcm","clk":"11840758381","pt":1723551728038,"mc":[{"id":"1.231699683","rc":[{"batb":[[0,2.36,10],[1,2.34,28.91],[2,1.25,100]],"ltp":2.38,"tv":4.29,"id":2780}]}]}
{"op":"mcm","clk":"11840758742","pt":1723551731352,"mc":[{"id":"1.231699683","rc":[{"batb":[[0,2.34,28.91],[1,1.25,100],[2,1.08,7.82]],"ltp":2.38,"tv":4.29,"id":2780}]}]}
{"op":"mcm","clk":"11840759388","pt":1723551737123,"mc":[{"id":"1.231699683","rc":[{"batb":[[0,2.36,10],[1,2.34,28.91],[2,1.25,100]],"ltp":2.38,"tv":4.29,"id":2780}]}]}
{"op":"mcm","clk":"11840759717","pt":1723551740437,"mc":[{"id":"1.231699683","rc":[{"batb":[[0,2.34,28.91],[1,1.25,100],[2,1.08,7.82]],"ltp":2.38,"tv":4.29,"id":2780}]}]}
{"op":"mcm","clk":"11840760227","pt":1723551746131,"mc":[{"id":"1.231699683","rc":[{"batb":[[0,2.36,10],[1,2.34,28.91],[2,1.25,100]],"ltp":2.38,"tv":4.29,"id":2780}]}]}
{"op":"mcm","clk":"11840760482","pt":1723551749611,"mc":[{"id":"1.231699683","rc":[{"batb":[[0,2.34,28.91],[1,1.25,100],[2,1.08,7.82]],"ltp":2.38,"tv":4.29,"id":2780}]}]}
{"op":"mcm","clk":"11840760992","pt":1723551754156,"mc":[{"id":"1.231699683","rc":[{"batb":[[0,2.36,10],[1,2.34,28.91],[2,1.25,100]],"ltp":2.38,"tv":4.29,"id":2780}]}]}
{"op":"mcm","clk":"11840761390","pt":1723551757671,"mc":[{"id":"1.231699683","rc":[{"batb":[[0,2.34,28.91],[1,1.25,100],[2,1.08,7.82]],"ltp":2.38,"tv":4.29,"id":2780}]}]}
{"op":"mcm","clk":"11840761663","pt":1723551760474,"mc":[{"id":"1.231699683","rc":[{"batb":[[0,2.36,10],[1,2.34,28.91],[2,1.25,100]],"ltp":2.38,"tv":4.29,"id":2780}]}]}
{"op":"mcm","clk":"11840762062","pt":1723551764361,"mc":[{"id":"1.231699683","rc":[{"batb":[[0,2.34,28.91],[1,1.25,100],[2,1.08,7.82]],"ltp":2.38,"tv":4.29,"id":2780}]}]}
{"op":"mcm","clk":"11840762744","pt":1723551771976,"mc":[{"id":"1.231699683","rc":[{"batb":[[0,2.36,10],[1,2.34,28.91],[2,1.25,100]],"ltp":2.38,"tv":4.29,"id":2780}]}]}
{"op":"mcm","clk":"11840762972","pt":1723551775274,"mc":[{"id":"1.231699683","rc":[{"batb":[[0,2.34,28.91],[1,1.25,100],[2,1.08,7.82]],"ltp":2.38,"tv":4.29,"id":2780}]}]}
{"op":"mcm","clk":"11840763215","pt":1723551779192,"mc":[{"id":"1.231699683","rc":[{"batb":[[0,2.36,10],[1,2.34,28.91],[2,1.25,100]],"ltp":2.38,"tv":4.29,"id":2780}]}]}
{"op":"mcm","clk":"11840763523","pt":1723551783393,"mc":[{"id":"1.231699683","rc":[{"batb":[[0,2.34,28.91],[1,1.25,100],[2,1.08,7.82]],"ltp":2.38,"tv":4.29,"id":2780}]}]}
{"op":"mcm","clk":"11840763877","pt":1723551788511,"mc":[{"id":"1.231699683","rc":[{"batb":[[0,2.36,10],[1,2.34,28.91],[2,1.25,100]],"ltp":2.38,"tv":4.29,"id":2780}]}]}
{"op":"mcm","clk":"11840764124","pt":1723551791923,"mc":[{"id":"1.231699683","rc":[{"batb":[[0,2.34,28.91],[1,1.25,100],[2,1.08,7.82]],"ltp":2.38,"tv":4.29,"id":2780}]}]}
{"op":"mcm","clk":"11840764393","pt":1723551796005,"mc":[{"id":"1.231699683","rc":[{"batb":[[0,2.36,10],[1,2.34,28.91],[2,1.25,100]],"ltp":2.38,"tv":4.29,"id":2780}]}]}
{"op":"mcm","clk":"11840764596","pt":1723551799307,"mc":[{"id":"1.231699683","rc":[{"batb":[[0,2.34,28.91],[1,1.25,100],[2,1.08,7.82]],"ltp":2.38,"tv":4.29,"id":2780}]}]}
{"op":"mcm","clk":"11840765308","pt":1723551810242,"mc":[{"id":"1.231699683","rc":[{"batb":[[0,2.36,10],[1,2.34,28.91],[2,1.25,100]],"ltp":2.38,"tv":4.29,"id":2780}]}]}
{"op":"mcm","clk":"11840765498","pt":1723551813725,"mc":[{"id":"1.231699683","rc":[{"batb":[[0,2.34,28.91],[1,1.25,100],[2,1.08,7.82]],"ltp":2.38,"tv":4.29,"id":2780}]}]}
{"op":"mcm","clk":"11840765888","pt":1723551819443,"mc":[{"id":"1.231699683","rc":[{"batb":[[0,2.36,10],[1,2.34,28.91],[2,1.25,100]],"ltp":2.38,"tv":4.29,"id":2780}]}]}
{"op":"mcm","clk":"11840766089","pt":1723551822832,"mc":[{"id":"1.231699683","rc":[{"batb":[[0,2.34,28.91],[1,1.25,100],[2,1.08,7.82]],"ltp":2.38,"tv":4.29,"id":2780}]}]}
{"op":"mcm","clk":"11840766296","pt":1723551825720,"mc":[{"id":"1.231699683","rc":[{"batb":[[0,2.36,10],[1,2.34,28.91],[2,1.25,100]],"ltp":2.38,"tv":4.29,"id":2780}]}]}
{"op":"mcm","clk":"11840766516","pt":1723551829154,"mc":[{"id":"1.231699683","rc":[{"batb":[[0,2.34,28.91],[1,1.25,100],[2,1.08,7.82]],"ltp":2.38,"tv":4.29,"id":2780}]}]}
{"op":"mcm","clk":"11840766765","pt":1723551833232,"mc":[{"id":"1.231699683","rc":[{"batb":[[0,2.36,10],[1,2.34,28.91],[2,1.25,100]],"ltp":2.38,"tv":4.29,"id":2780}]}]}
{"op":"mcm","clk":"11840766971","pt":1723551836724,"mc":[{"id":"1.231699683","rc":[{"batb":[[0,2.34,28.91],[1,1.25,100],[2,1.08,7.82]],"ltp":2.38,"tv":4.29,"id":2780}]}]}
{"op":"mcm","clk":"11840767121","pt":1723551839032,"mc":[{"id":"1.231699683","rc":[{"batb":[[0,2.36,10],[1,2.34,28.91],[2,1.25,100]],"ltp":2.38,"tv":4.29,"id":2780}]}]}
{"op":"mcm","clk":"11840767365","pt":1723551842445,"mc":[{"id":"1.231699683","rc":[{"batb":[[0,2.34,28.91],[1,1.25,100],[2,1.08,7.82]],"ltp":2.38,"tv":4.29,"id":2780}]}]}
{"op":"mcm","clk":"11840768423","pt":1723551859249,"mc":[{"id":"1.231699683","rc":[{"batb":[[0,2.36,10],[1,2.34,28.91],[2,1.25,100]],"ltp":2.38,"tv":4.29,"id":2780}]}]}
{"op":"mcm","clk":"11840768655","pt":1723551862751,"mc":[{"id":"1.231699683","rc":[{"batb":[[0,2.34,28.91],[1,1.25,100],[2,1.08,7.82]],"ltp":2.38,"tv":4.29,"id":2780}]}]}
{"op":"mcm","clk":"11840769041","pt":1723551868153,"mc":[{"id":"1.231699683","rc":[{"batb":[[0,2.36,10],[1,2.34,28.91],[2,1.25,100]],"ltp":2.38,"tv":4.29,"id":2780}]}]}
{"op":"mcm","clk":"11840769306","pt":1723551872591,"mc":[{"id":"1.231699683","rc":[{"batb":[[0,2.34,28.91],[1,1.25,100],[2,1.08,7.82]],"ltp":2.38,"tv":4.29,"id":2780}]}]}
{"op":"mcm","clk":"11840769506","pt":1723551875886,"mc":[{"id":"1.231699683","rc":[{"batb":[[0,2.36,10],[1,2.34,28.91],[2,1.25,100]],"ltp":2.38,"tv":4.29,"id":2780}]}]}
{"op":"mcm","clk":"11840769740","pt":1723551879279,"mc":[{"id":"1.231699683","rc":[{"batb":[[0,2.34,28.91],[1,1.25,100],[2,1.08,7.82]],"ltp":2.38,"tv":4.29,"id":2780}]}]}
{"op":"mcm","clk":"11840770054","pt":1723551884471,"mc":[{"id":"1.231699683","rc":[{"batb":[[0,2.36,10],[1,2.34,28.91],[2,1.25,100]],"ltp":2.38,"tv":4.29,"id":2780}]}]}
{"op":"mcm","clk":"11840770240","pt":1723551887907,"mc":[{"id":"1.231699683","rc":[{"batb":[[0,2.34,28.91],[1,1.25,100],[2,1.08,7.82]],"ltp":2.38,"tv":4.29,"id":2780}]}]}
{"op":"mcm","clk":"11840770753","pt":1723551896399,"mc":[{"id":"1.231699683","rc":[{"batb":[[0,2.36,10],[1,2.34,28.91],[2,1.25,100]],"ltp":2.38,"tv":4.29,"id":2780}]}]}
{"op":"mcm","clk":"11840770983","pt":1723551900101,"mc":[{"id":"1.231699683","rc":[{"batb":[[0,2.34,28.91],[1,1.25,100],[2,1.08,7.82]],"ltp":2.38,"tv":4.29,"id":2780}]}]}
{"op":"mcm","clk":"11840771377","pt":1723551905720,"mc":[{"id":"1.231699683","rc":[{"batb":[[0,2.36,10],[1,2.34,28.91],[2,1.25,100]],"ltp":2.38,"tv":4.29,"id":2780}]}]}
{"op":"mcm","clk":"11840771609","pt":1723551909122,"mc":[{"id":"1.231699683","rc":[{"batb":[[0,2.34,28.91],[1,1.25,100],[2,1.08,7.82]],"ltp":2.38,"tv":4.29,"id":2780}]}]}
{"op":"mcm","clk":"11840772279","pt":1723551921157,"mc":[{"id":"1.231699683","rc":[{"batb":[[0,2.36,10],[1,2.34,28.91],[2,1.25,100]],"ltp":2.38,"tv":4.29,"id":2780}]}]}
{"op":"mcm","clk":"11840772502","pt":1723551924757,"mc":[{"id":"1.231699683","rc":[{"batb":[[0,2.34,28.91],[1,1.25,100],[2,1.08,7.82]],"ltp":2.38,"tv":4.29,"id":2780}]}]}
{"op":"mcm","clk":"11840772807","pt":1723551929534,"mc":[{"id":"1.231699683","rc":[{"batb":[[0,2.36,10],[1,2.34,28.91],[2,1.25,100]],"ltp":2.38,"tv":4.29,"id":2780}]}]}
{"op":"mcm","clk":"11840773015","pt":1723551933084,"mc":[{"id":"1.231699683","rc":[{"batb":[[0,2.34,28.91],[1,1.25,100],[2,1.08,7.82]],"ltp":2.38,"tv":4.29,"id":2780}]}]}
{"op":"mcm","clk":"11840773216","pt":1723551936273,"mc":[{"id":"1.231699683","rc":[{"batb":[[0,2.36,10],[1,2.34,28.91],[2,1.25,100]],"ltp":2.38,"tv":4.29,"id":2780}]}]}
{"op":"mcm","clk":"11840773434","pt":1723551939779,"mc":[{"id":"1.231699683","rc":[{"batb":[[0,2.34,28.91],[1,1.25,100],[2,1.08,7.82]],"ltp":2.38,"tv":4.29,"id":2780}]}]}
{"op":"mcm","clk":"11840773690","pt":1723551944002,"mc":[{"id":"1.231699683","rc":[{"batb":[[0,2.36,10],[1,2.34,28.91],[2,1.25,100]],"ltp":2.38,"tv":4.29,"id":2780}]}]}
{"op":"mcm","clk":"11840773920","pt":1723551947505,"mc":[{"id":"1.231699683","rc":[{"batb":[[0,2.34,28.91],[1,1.25,100],[2,1.08,7.82]],"ltp":2.38,"tv":4.29,"id":2780}]}]}
{"op":"mcm","clk":"11840774087","pt":1723551950077,"mc":[{"id":"1.231699683","rc":[{"batb":[[0,2.36,10],[1,2.34,28.91],[2,1.25,100]],"ltp":2.38,"tv":4.29,"id":2780}]}]}
{"op":"mcm","clk":"11840774276","pt":1723551953519,"mc":[{"id":"1.231699683","rc":[{"batb":[[0,2.34,28.91],[1,1.25,100],[2,1.08,7.82]],"ltp":2.38,"tv":4.29,"id":2780}]}]}
{"op":"mcm","clk":"11840774575","pt":1723551958919,"mc":[{"id":"1.231699683","rc":[{"batb":[[0,2.36,10],[1,2.34,28.91],[2,1.25,100]],"ltp":2.38,"tv":4.29,"id":2780}]}]}
{"op":"mcm","clk":"11840774777","pt":1723551962587,"mc":[{"id":"1.231699683","rc":[{"batb":[[0,2.34,28.91],[1,1.25,100],[2,1.08,7.82]],"ltp":2.38,"tv":4.29,"id":2780}]}]}
{"op":"mcm","clk":"11840774935","pt":1723551965007,"mc":[{"id":"1.231699683","rc":[{"batb":[[0,2.36,10],[1,2.34,28.91],[2,1.25,100]],"ltp":2.38,"tv":4.29,"id":2780}]}]}
{"op":"mcm","clk":"11840775145","pt":1723551968204,"mc":[{"id":"1.231699683","rc":[{"batb":[[0,2.34,28.91],[1,1.25,100],[2,1.08,7.82]],"ltp":2.38,"tv":4.29,"id":2780}]}]}
{"op":"mcm","clk":"11840775492","pt":1723551974123,"mc":[{"id":"1.231699683","rc":[{"batb":[[0,2.36,10],[1,2.34,28.91],[2,1.25,100]],"ltp":2.38,"tv":4.29,"id":2780}]}]}
{"op":"mcm","clk":"11840775672","pt":1723551977922,"mc":[{"id":"1.231699683","rc":[{"batb":[[0,2.34,28.91],[1,1.25,100],[2,1.08,7.82]],"ltp":2.38,"tv":4.29,"id":2780}]}]}
{"op":"mcm","clk":"11840776031","pt":1723551984230,"mc":[{"id":"1.231699683","rc":[{"batb":[[0,2.36,10],[1,2.34,28.91],[2,1.25,100]],"ltp":2.38,"tv":4.29,"id":2780}]}]}
{"op":"mcm","clk":"11840776232","pt":1723551987638,"mc":[{"id":"1.231699683","rc":[{"batb":[[0,2.34,28.91],[1,1.25,100],[2,1.08,7.82]],"ltp":2.38,"tv":4.29,"id":2780}]}]}
{"op":"mcm","clk":"11840776396","pt":1723551990159,"mc":[{"id":"1.231699683","rc":[{"batb":[[0,2.36,10],[1,2.34,28.91],[2,1.25,100]],"ltp":2.38,"tv":4.29,"id":2780}]}]}
{"op":"mcm","clk":"11840776603","pt":1723551994057,"mc":[{"id":"1.231699683","rc":[{"batb":[[0,2.34,28.91],[1,1.25,100],[2,1.08,7.82]],"ltp":2.38,"tv":4.29,"id":2780}]}]}
{"op":"mcm","clk":"11840777027","pt":1723552001556,"mc":[{"id":"1.231699683","rc":[{"batb":[[0,2.36,10],[1,2.34,28.91],[2,1.25,100]],"ltp":2.38,"tv":4.29,"id":2780}]}]}
{"op":"mcm","clk":"11840777220","pt":1723552005158,"mc":[{"id":"1.231699683","rc":[{"batb":[[0,2.34,28.91],[1,1.25,100],[2,1.08,7.82]],"ltp":2.38,"tv":4.29,"id":2780}]}]}
{"op":"mcm","clk":"11840777407","pt":1723552008441,"mc":[{"id":"1.231699683","rc":[{"batb":[[0,2.36,10],[1,2.34,28.91],[2,1.25,100]],"ltp":2.38,"tv":4.29,"id":2780}]}]}
{"op":"mcm","clk":"11840777587","pt":1723552011828,"mc":[{"id":"1.231699683","rc":[{"batb":[[0,2.34,28.91],[1,1.25,100],[2,1.08,7.82]],"ltp":2.38,"tv":4.29,"id":2780}]}]}
{"op":"mcm","clk":"11840777773","pt":1723552015565,"mc":[{"id":"1.231699683","rc":[{"batb":[[0,2.36,10],[1,2.34,28.91],[2,1.25,100]],"ltp":2.38,"tv":4.29,"id":2780}]}]}
{"op":"mcm","clk":"11840777963","pt":1723552019355,"mc":[{"id":"1.231699683","rc":[{"batb":[[0,2.34,28.91],[1,1.25,100],[2,1.08,7.82]],"ltp":2.38,"tv":4.29,"id":2780}]}]}
{"op":"mcm","clk":"11840778248","pt":1723552024798,"mc":[{"id":"1.231699683","rc":[{"batb":[[0,2.36,10],[1,2.34,28.91],[2,1.25,100]],"ltp":2.38,"tv":4.29,"id":2780}]}]}
{"op":"mcm","clk":"11840778453","pt":1723552028184,"mc":[{"id":"1.231699683","rc":[{"batb":[[0,2.34,28.91],[1,1.25,100],[2,1.08,7.82]],"ltp":2.38,"tv":4.29,"id":2780}]}]}
{"op":"mcm","clk":"11840778590","pt":1723552030960,"mc":[{"id":"1.231699683","rc":[{"batb":[[0,2.36,10],[1,2.34,28.91],[2,1.25,100]],"ltp":2.38,"tv":4.29,"id":2780}]}]}
{"op":"mcm","clk":"11840778826","pt":1723552034704,"mc":[{"id":"1.231699683","rc":[{"batb":[[0,2.34,28.91],[1,1.25,100],[2,1.08,7.82]],"ltp":2.38,"tv":4.29,"id":2780}]}]}
{"op":"mcm","clk":"11840779240","pt":1723552043186,"mc":[{"id":"1.231699683","rc":[{"batb":[[0,2.36,10],[1,2.34,28.91],[2,1.25,100]],"ltp":2.38,"tv":4.29,"id":2780}]}]}
{"op":"mcm","clk":"11840779466","pt":1723552046581,"mc":[{"id":"1.231699683","rc":[{"batb":[[0,2.34,28.91],[1,1.25,100],[2,1.08,7.82]],"ltp":2.38,"tv":4.29,"id":2780}]}]}
{"op":"mcm","clk":"11840780136","pt":1723552058302,"mc":[{"id":"1.231699683","rc":[{"batb":[[0,2.36,10],[1,2.34,28.91],[2,1.25,100]],"ltp":2.38,"tv":4.29,"id":2780}]}]}
{"op":"mcm","clk":"11840780318","pt":1723552061598,"mc":[{"id":"1.231699683","rc":[{"batb":[[0,2.34,28.91],[1,1.25,100],[2,1.08,7.82]],"ltp":2.38,"tv":4.29,"id":2780}]}]}
{"op":"mcm","clk":"11840780469","pt":1723552064322,"mc":[{"id":"1.231699683","rc":[{"batb":[[0,2.36,10],[1,2.34,28.91],[2,1.25,100]],"ltp":2.38,"tv":4.29,"id":2780}]}]}
{"op":"mcm","clk":"11840780641","pt":1723552067724,"mc":[{"id":"1.231699683","rc":[{"batb":[[0,2.34,28.91],[1,1.25,100],[2,1.08,7.82]],"ltp":2.38,"tv":4.29,"id":2780}]}]}
{"op":"mcm","clk":"11840781048","pt":1723552075227,"mc":[{"id":"1.231699683","rc":[{"batb":[[0,2.36,10],[1,2.34,28.91],[2,1.25,100]],"ltp":2.38,"tv":4.29,"id":2780}]}]}
{"op":"mcm","clk":"11840781276","pt":1723552078928,"mc":[{"id":"1.231699683","rc":[{"batb":[[0,2.34,28.91],[1,1.25,100],[2,1.08,7.82]],"ltp":2.38,"tv":4.29,"id":2780}]}]}
{"op":"mcm","clk":"11840781640","pt":1723552084573,"mc":[{"id":"1.231699683","rc":[{"batb":[[0,2.36,10],[1,2.34,28.91],[2,1.25,100]],"ltp":2.38,"tv":4.29,"id":2780}]}]}
{"op":"mcm","clk":"11840781868","pt":1723552087924,"mc":[{"id":"1.231699683","rc":[{"batb":[[0,2.34,28.91],[1,1.25,100],[2,1.08,7.82]],"ltp":2.38,"tv":4.29,"id":2780}]}]}
{"op":"mcm","clk":"11840782054","pt":1723552090555,"mc":[{"id":"1.231699683","rc":[{"batb":[[0,2.36,10],[1,2.34,28.91],[2,1.25,100]],"ltp":2.38,"tv":4.29,"id":2780}]}]}
{"op":"mcm","clk":"11840782250","pt":1723552093957,"mc":[{"id":"1.231699683","rc":[{"batb":[[0,2.34,28.91],[1,1.25,100],[2,1.08,7.82]],"ltp":2.38,"tv":4.29,"id":2780}]}]}
{"op":"mcm","clk":"11840782446","pt":1723552097395,"mc":[{"id":"1.231699683","rc":[{"batb":[[0,2.36,10],[1,2.34,28.91],[2,1.25,100]],"ltp":2.38,"tv":4.29,"id":2780}]}]}
{"op":"mcm","clk":"11840782653","pt":1723552100846,"mc":[{"id":"1.231699683","rc":[{"batb":[[0,2.34,28.91],[1,1.25,100],[2,1.08,7.82]],"ltp":2.38,"tv":4.29,"id":2780}]}]}
{"op":"mcm","clk":"11840783055","pt":1723552107376,"mc":[{"id":"1.231699683","rc":[{"batb":[[0,2.36,10],[1,2.34,28.91],[2,1.25,100]],"ltp":2.38,"tv":4.29,"id":2780}]}]}
{"op":"mcm","clk":"11840783280","pt":1723552110873,"mc":[{"id":"1.231699683","rc":[{"batb":[[0,2.34,28.91],[1,1.25,100],[2,1.08,7.82]],"ltp":2.38,"tv":4.29,"id":2780}]}]}
{"op":"mcm","clk":"11840783505","pt":1723552114378,"mc":[{"id":"1.231699683","rc":[{"batb":[[0,2.36,10],[1,2.34,28.91],[2,1.25,100]],"ltp":2.38,"tv":4.29,"id":2780}]}]}
{"op":"mcm","clk":"11840783735","pt":1723552117985,"mc":[{"id":"1.231699683","rc":[{"batb":[[0,2.34,28.91],[1,1.25,100],[2,1.08,7.82]],"ltp":2.38,"tv":4.29,"id":2780}]}]}
{"op":"mcm","clk":"11840783867","pt":1723552120205,"mc":[{"id":"1.231699683","rc":[{"batb":[[0,2.36,10],[1,2.34,28.91],[2,1.25,100]],"ltp":2.38,"tv":4.29,"id":2780}]}]}
{"op":"mcm","clk":"11840784145","pt":1723552123722,"mc":[{"id":"1.231699683","rc":[{"batb":[[0,2.34,28.91],[1,1.25,100],[2,1.08,7.82]],"ltp":2.38,"tv":4.29,"id":2780}]}]}
{"op":"mcm","clk":"11840784303","pt":1723552125888,"mc":[{"id":"1.231699683","rc":[{"batb":[[0,2.36,10],[1,2.34,28.91],[2,1.25,100]],"ltp":2.38,"tv":4.29,"id":2780}]}]}
{"op":"mcm","clk":"11840784509","pt":1723552129229,"mc":[{"id":"1.231699683","rc":[{"batb":[[0,2.34,28.91],[1,1.25,100],[2,1.08,7.82]],"ltp":2.38,"tv":4.29,"id":2780}]}]}
{"op":"mcm","clk":"11840784658","pt":1723552131394,"mc":[{"id":"1.231699683","rc":[{"batb":[[0,2.36,10],[1,2.34,28.91],[2,1.25,100]],"ltp":2.38,"tv":4.29,"id":2780}]}]}
{"op":"mcm","clk":"11840784852","pt":1723552134637,"mc":[{"id":"1.231699683","rc":[{"batb":[[0,2.34,28.91],[1,1.25,100],[2,1.08,7.82]],"ltp":2.38,"tv":4.29,"id":2780}]}]}
{"op":"mcm","clk":"11840784973","pt":1723552137006,"mc":[{"id":"1.231699683","rc":[{"batb":[[0,2.36,10],[1,2.34,28.91],[2,1.25,100]],"ltp":2.38,"tv":4.29,"id":2780}]}]}
{"op":"mcm","clk":"11840785170","pt":1723552140427,"mc":[{"id":"1.231699683","rc":[{"batb":[[0,2.34,28.91],[1,1.25,100],[2,1.08,7.82]],"ltp":2.38,"tv":4.29,"id":2780}]}]}
{"op":"mcm","clk":"11840785993","pt":1723552152446,"mc":[{"id":"1.231699683","rc":[{"batb":[[0,2.36,10],[1,2.34,28.91],[2,1.25,100]],"ltp":2.38,"tv":4.29,"id":2780}]}]}
{"op":"mcm","clk":"11840786178","pt":1723552155745,"mc":[{"id":"1.231699683","rc":[{"batb":[[0,2.34,28.91],[1,1.25,100],[2,1.08,7.82]],"ltp":2.38,"tv":4.29,"id":2780}]}]}
{"op":"mcm","clk":"11840786518","pt":1723552161573,"mc":[{"id":"1.231699683","rc":[{"batb":[[0,2.36,10],[1,2.34,28.91],[2,1.25,100]],"ltp":2.38,"tv":4.29,"id":2780}]}]}
{"op":"mcm","clk":"11840786742","pt":1723552165077,"mc":[{"id":"1.231699683","rc":[{"batb":[[0,2.34,28.91],[1,1.25,100],[2,1.08,7.82]],"ltp":2.38,"tv":4.29,"id":2780}]}]}
{"op":"mcm","clk":"11840786918","pt":1723552167764,"mc":[{"id":"1.231699683","rc":[{"batb":[[0,2.36,10],[1,2.34,28.91],[2,1.25,100]],"ltp":2.38,"tv":4.29,"id":2780}]}]}
{"op":"mcm","clk":"11840787147","pt":1723552171167,"mc":[{"id":"1.231699683","rc":[{"batb":[[0,2.34,28.91],[1,1.25,100],[2,1.08,7.82]],"ltp":2.38,"tv":4.29,"id":2780}]}]}
{"op":"mcm","clk":"11840787553","pt":1723552176891,"mc":[{"id":"1.231699683","rc":[{"batb":[[0,2.36,10],[1,2.34,28.91],[2,1.25,100]],"ltp":2.38,"tv":4.29,"id":2780}]}]}
{"op":"mcm","clk":"11840787824","pt":1723552180553,"mc":[{"id":"1.231699683","rc":[{"batb":[[0,2.34,28.91],[1,1.25,100],[2,1.08,7.82]],"ltp":2.38,"tv":4.29,"id":2780}]}]}
{"op":"mcm","clk":"11840787989","pt":1723552182880,"mc":[{"id":"1.231699683","rc":[{"batb":[[0,2.36,10],[1,2.34,28.91],[2,1.25,100]],"ltp":2.38,"tv":4.29,"id":2780}]}]}
{"op":"mcm","clk":"11840788213","pt":1723552186278,"mc":[{"id":"1.231699683","rc":[{"batb":[[0,2.34,28.91],[1,1.25,100],[2,1.08,7.82]],"ltp":2.38,"tv":4.29,"id":2780}]}]}
{"op":"mcm","clk":"11840788397","pt":1723552190212,"mc":[{"id":"1.231699683","rc":[{"batb":[[0,2.36,10],[1,2.34,28.91],[2,1.25,100]],"ltp":2.38,"tv":4.29,"id":2780}]}]}
{"op":"mcm","clk":"11840788576","pt":1723552193604,"mc":[{"id":"1.231699683","rc":[{"batb":[[0,2.34,28.91],[1,1.25,100],[2,1.08,7.82]],"ltp":2.38,"tv":4.29,"id":2780}]}]}
{"op":"mcm","clk":"11840788777","pt":1723552197412,"mc":[{"id":"1.231699683","rc":[{"batb":[[0,2.36,10],[1,2.34,28.91],[2,1.25,100]],"ltp":2.38,"tv":4.29,"id":2780}]}]}
{"op":"mcm","clk":"11840789036","pt":1723552201020,"mc":[{"id":"1.231699683","rc":[{"batb":[[0,2.34,28.91],[1,1.25,100],[2,1.08,7.82]],"ltp":2.38,"tv":4.29,"id":2780}]}]}
{"op":"mcm","clk":"11840789209","pt":1723552204017,"mc":[{"id":"1.231699683","rc":[{"batb":[[0,2.36,10],[1,2.34,28.91],[2,1.25,100]],"ltp":2.38,"tv":4.29,"id":2780}]}]}
{"op":"mcm","clk":"11840789459","pt":1723552207907,"mc":[{"id":"1.231699683","rc":[{"batb":[[0,2.34,28.91],[1,1.25,100],[2,1.08,7.82]],"ltp":2.38,"tv":4.29,"id":2780}]}]}
{"op":"mcm","clk":"11840789633","pt":1723552210428,"mc":[{"id":"1.231699683","rc":[{"batb":[[0,2.36,10],[1,2.34,28.91],[2,1.25,100]],"ltp":2.38,"tv":4.29,"id":2780}]}]}
{"op":"mcm","clk":"11840789870","pt":1723552213829,"mc":[{"id":"1.231699683","rc":[{"batb":[[0,2.34,28.91],[1,1.25,100],[2,1.08,7.82]],"ltp":2.38,"tv":4.29,"id":2780}]}]}
{"op":"mcm","clk":"11840790448","pt":1723552222549,"mc":[{"id":"1.231699683","rc":[{"batb":[[0,2.36,10],[1,2.34,28.91],[2,1.25,100]],"ltp":2.38,"tv":4.29,"id":2780}]}]}
{"op":"mcm","clk":"11840790881","pt":1723552229041,"mc":[{"id":"1.231699683","rc":[{"batb":[[0,2.34,28.91],[1,1.25,100],[2,1.08,7.82]],"ltp":2.38,"tv":4.29,"id":2780}]}]}
{"op":"mcm","clk":"11840791098","pt":1723552231731,"mc":[{"id":"1.231699683","rc":[{"batb":[[0,2.38,10],[1,2.34,28.91],[2,1.25,100]],"ltp":2.38,"tv":4.29,"id":2780}]}]}
{"op":"mcm","clk":"11840791513","pt":1723552238075,"mc":[{"id":"1.231699683","rc":[{"batb":[[0,2.34,28.91],[1,1.25,100],[2,1.08,7.82]],"ltp":2.38,"tv":4.29,"id":2780}]}]}
{"op":"mcm","clk":"11840791713","pt":1723552241361,"mc":[{"id":"1.231699683","rc":[{"batb":[[0,2.36,10],[1,2.34,28.91],[2,1.25,100]],"ltp":2.38,"tv":4.29,"id":2780}]}]}
{"op":"mcm","clk":"11840791926","pt":1723552244778,"mc":[{"id":"1.231699683","rc":[{"batb":[[0,2.34,28.91],[1,1.25,100],[2,1.08,7.82]],"ltp":2.38,"tv":4.29,"id":2780}]}]}
{"op":"mcm","clk":"11840792195","pt":1723552248755,"mc":[{"id":"1.231699683","rc":[{"batb":[[0,2.36,10],[1,2.34,28.91],[2,1.25,100]],"ltp":2.38,"tv":4.29,"id":2780}]}]}
{"op":"mcm","clk":"11840792427","pt":1723552252362,"mc":[{"id":"1.231699683","rc":[{"batb":[[0,2.34,28.91],[1,1.25,100],[2,1.08,7.82]],"ltp":2.38,"tv":4.29,"id":2780}]}]}
{"op":"mcm","clk":"11840792688","pt":1723552256579,"mc":[{"id":"1.231699683","rc":[{"batb":[[0,2.36,10],[1,2.34,28.91],[2,1.25,100]],"ltp":2.38,"tv":4.29,"id":2780}]}]}
{"op":"mcm","clk":"11840792897","pt":1723552259980,"mc":[{"id":"1.231699683","rc":[{"batb":[[0,2.34,28.91],[1,1.25,100],[2,1.08,7.82]],"ltp":2.38,"tv":4.29,"id":2780}]}]}
{"op":"mcm","clk":"11840793084","pt":1723552262984,"mc":[{"id":"1.231699683","rc":[{"batb":[[0,2.36,10],[1,2.34,28.91],[2,1.25,100]],"ltp":2.38,"tv":4.29,"id":2780}]}]}
{"op":"mcm","clk":"11840793307","pt":1723552266387,"mc":[{"id":"1.231699683","rc":[{"batb":[[0,2.34,28.91],[1,1.25,100],[2,1.08,7.82]],"ltp":2.38,"tv":4.29,"id":2780}]}]}
{"op":"mcm","clk":"11840793811","pt":1723552273921,"mc":[{"id":"1.231699683","rc":[{"batb":[[0,2.36,10],[1,2.34,28.91],[2,1.25,100]],"ltp":2.38,"tv":4.29,"id":2780}]}]}
{"op":"mcm","clk":"11840794088","pt":1723552277322,"mc":[{"id":"1.231699683","rc":[{"batb":[[0,2.34,28.91],[1,1.25,100],[2,1.08,7.82]],"ltp":2.38,"tv":4.29,"id":2780}]}]}
{"op":"mcm","clk":"11840794476","pt":1723552283508,"mc":[{"id":"1.231699683","rc":[{"batb":[[0,2.36,10],[1,2.34,28.91],[2,1.25,100]],"ltp":2.38,"tv":4.29,"id":2780}]}]}
{"op":"mcm","clk":"11840794689","pt":1723552286705,"mc":[{"id":"1.231699683","rc":[{"batb":[[0,2.34,28.91],[1,1.25,100],[2,1.08,7.82]],"ltp":2.38,"tv":4.29,"id":2780}]}]}
{"op":"mcm","clk":"11840794890","pt":1723552289801,"mc":[{"id":"1.231699683","rc":[{"batb":[[0,2.36,10],[1,2.34,28.91],[2,1.25,100]],"ltp":2.38,"tv":4.29,"id":2780}]}]}
