{"op":"mcm","clk":"11832897406","pt":1723100839324,"mc":[{"id":"1.231581347","marketDefinition":{"bspMarket":false,"turnInPlayEnabled":true,"persistenceEnabled":true,"marketBaseRate":5.0,"eventId":"33477608","eventTypeId":"4","numberOfWinners":1,"bettingType":"ODDS","marketType":"MATCH_ODDS","marketTime":"2024-08-09T09:00:00.000Z","suspendTime":"2024-08-09T09:00:00.000Z","bspReconciled":false,"complete":true,"inPlay":false,"crossMatching":false,"runnersVoidable":false,"numberOfActiveRunners":2,"betDelay":0,"status":"OPEN","runners":[{"status":"ACTIVE","sortPriority":1,"id":25686043,"name":"Netherlands Women"},{"status":"ACTIVE","sortPriority":2,"id":12474498,"name":"Papua New Guinea Women"}],"regulators":["MR_INT"],"countryCode":"GB","discountAllowed":false,"timezone":"GMT","openDate":"2024-08-09T09:00:00.000Z","version":6061671544,"name":"Match Odds","eventName":"Netherlands Women v Papua New Guinea Women"},"rc":[{"batb":[[0,1.03,200],[1,1.02,200],[2,1.01,220]],"ltp":0.0,"tv":0.0,"id":25686043},{"batb":[[0,1.03,200],[1,1.02,200],[2,1.01,220]],"ltp":0.0,"tv":0.0,"id":12474498}]}]}
{"op":"mcm","clk":"11832897461","pt":1723100840991,"mc":[{"id":"1.231581347","marketDefinition":{"bspMarket":false,"turnInPlayEnabled":true,"persistenceEnabled":true,"marketBaseRate":5.0,"eventId":"33477608","eventTypeId":"4","numberOfWinners":1,"bettingType":"ODDS","marketType":"MATCH_ODDS","marketTime":"2024-08-09T09:00:00.000Z","suspendTime":"2024-08-09T09:00:00.000Z","bspReconciled":false,"complete":true,"inPlay":false,"crossMatching":false,"runnersVoidable":false,"numberOfActiveRunners":2,"betDelay":0,"status":"OPEN","runners":[{"status":"ACTIVE","sortPriority":1,"id":25686043,"name":"Netherlands Women"},{"status":"ACTIVE","sortPriority":2,"id":12474498,"name":"Papua New Guinea Women"}],"regulators":["MR_INT"],"countryCode":"GB","discountAllowed":true,"timezone":"GMT","openDate":"2024-08-09T09:00:00.000Z","version":6061671544,"name":"Match Odds","eventName":"Netherlands Women v Papua New Guinea Women"}}]}
{"op":"mcm","clk":"11832900246","pt":1723100925921,"mc":[{"id":"1.231581347","rc":[{"batb":[[0,1.04,1641.56],[1,1.03,2372.68],[2,1.02,3408.23]],"ltp":0.0,"tv":0.0,"id":25686043},{"batb":[[2,1.01,6447.94]],"ltp":0.0,"tv":0.0,"id":12474498}]}]}
{"op":"mcm","clk":"11832900258","pt":1723100926227,"mc":[{"id":"1.231581347","rc":[{"batb":[[0,1.04,1641.56],[1,1.03,2372.68],[2,1.02,3408.23]],"ltp":0.0,"tv":0.0,"id":12474498}]}]}
{"op":"mcm","clk":"11833000647","pt":1723104774756,"mc":[{"id":"1.231581347","rc":[{"batb":[[0,1.04,1642.55],[1,1.03,2373.99],[2,1.02,3410.16]],"ltp":0.0,"tv":0.0,"id":25686043},{"batb":[[0,1.04,1642.55],[1,1.03,2373.99],[2,1.02,3410.16]],"ltp":0.0,"tv":0.0,"id":12474498}]}]}
{"op":"mcm","clk":"11833106646","pt":1723107922317,"mc":[{"id":"1.231581347","rc":[{"batb":[[0,1.05,500],[1,1.04,1642.41],[2,1.03,2373.8]],"ltp":0.0,"tv":0.0,"id":25686043},{"batb":[[0,1.04,1642.41],[1,1.03,2373.8],[2,1.02,3409.89]],"ltp":0.0,"tv":0.0,"id":12474498}]}]}
{"op":"mcm","clk":"11833106675","pt":1723107923704,"mc":[{"id":"1.231581347","rc":[{"batb":[[0,1.07,357.14],[1,1.06,416.67],[2,1.05,500]],"ltp":0.0,"tv":0.0,"id":25686043}]}]}
{"op":"mcm","clk":"11833106698","pt":1723107924529,"mc":[{"id":"1.231581347","rc":[{"batb":[[0,1.08,312.5],[1,1.07,357.14],[2,1.06,416.67]],"ltp":0.0,"tv":0.0,"id":25686043}]}]}
{"op":"mcm","clk":"11833106852","pt":1723107931743,"mc":[{"id":"1.231581347","rc":[{"batb":[[0,1.08,312.5],[1,1.04,1642.41],[2,1.03,2373.8]],"ltp":0.0,"tv":0.0,"id":12474498}]}]}
{"op":"mcm","clk":"11833106868","pt":1723107932720,"mc":[{"id":"1.231581347","rc":[{"batb":[[0,1.13,192.31],[1,1.08,312.5],[2,1.04,1642.41]],"ltp":0.0,"tv":0.0,"id":12474498}]}]}
{"op":"mcm","clk":"11833106893","pt":1723107933746,"mc":[{"id":"1.231581347","rc":[{"batb":[[0,1.18,138.89],[1,1.13,192.31],[2,1.08,312.5]],"ltp":0.0,"tv":0.0,"id":12474498}]}]}
{"op":"mcm","clk":"11833106942","pt":1723107935770,"mc":[{"id":"1.231581347","rc":[{"batb":[[0,1.23,108.7],[1,1.18,138.89],[2,1.13,192.31]],"ltp":0.0,"tv":0.0,"id":12474498}]}]}
{"op":"mcm","clk":"11833107008","pt":1723107938792,"mc":[{"id":"1.231581347","marketDefinition":{"bspMarket":false,"turnInPlayEnabled":true,"persistenceEnabled":true,"marketBaseRate":5.0,"eventId":"33477608","eventTypeId":"4","numberOfWinners":1,"bettingType":"ODDS","marketType":"MATCH_ODDS","marketTime":"2024-08-09T09:00:00.000Z","suspendTime":"2024-08-09T09:00:00.000Z","bspReconciled":false,"complete":true,"inPlay":false,"crossMatching":true,"runnersVoidable":false,"numberOfActiveRunners":2,"betDelay":0,"status":"OPEN","runners":[{"status":"ACTIVE","sortPriority":1,"id":25686043,"name":"Netherlands Women"},{"status":"ACTIVE","sortPriority":2,"id":12474498,"name":"Papua New Guinea Women"}],"regulators":["MR_INT"],"countryCode":"GB","discountAllowed":true,"timezone":"GMT","openDate":"2024-08-09T09:00:00.000Z","version":6061671544,"name":"Match Odds","eventName":"Netherlands Women v Papua New Guinea Women"}}]}
{"op":"mcm","clk":"11833131681","pt":1723108616398,"mc":[{"id":"1.231581347","rc":[{"batb":[[0,1.24,7.65],[1,1.23,108.7],[2,1.18,138.89]],"ltp":0.0,"tv":0.0,"id":12474498}]}]}
{"op":"mcm","clk":"11833519097","pt":1723115574756,"mc":[{"id":"1.231581347","rc":[{"batb":[[0,1.24,7.65]],"ltp":0.0,"tv":0.0,"id":12474498}]}]}
{"op":"mcm","clk":"11833836124","pt":1723120974756,"mc":[{"id":"1.231581347","rc":[{"batb":[[0,1.24,7.65]],"ltp":0.0,"tv":0.0,"id":12474498}]}]}
{"op":"mcm","clk":"11834124487","pt":1723126374756,"mc":[{"id":"1.231581347","rc":[{"batb":[[0,1.24,7.64]],"ltp":0.0,"tv":0.0,"id":12474498}]}]}
{"op":"mcm","clk":"11834508378","pt":1723131774756,"mc":[{"id":"1.231581347","rc":[{"batb":[[0,1.24,7.64]],"ltp":0.0,"tv":0.0,"id":12474498}]}]}
{"op":"mcm","clk":"11834566944","pt":1723132321020,"mc":[{"id":"1.231581347","rc":[{"batb":[[0,1.33,75.76],[1,1.24,7.64],[2,1.23,108.7]],"ltp":0.0,"tv":0.0,"id":12474498}]}]}
{"op":"mcm","clk":"11834567102","pt":1723132322803,"mc":[{"id":"1.231581347","rc":[{"batb":[[0,1.43,58.14],[1,1.33,75.76],[2,1.24,7.64]],"ltp":0.0,"tv":0.0,"id":12474498}]}]}
{"op":"mcm","clk":"11834567252","pt":1723132324498,"mc":[{"id":"1.231581347","rc":[{"batb":[[0,1.53,47.17],[1,1.43,58.14],[2,1.33,75.76]],"ltp":0.0,"tv":0.0,"id":12474498}]}]}
{"op":"mcm","clk":"11834567488","pt":1723132327000,"mc":[{"id":"1.231581347","rc":[{"batb":[[0,1.63,39.68],[1,1.53,47.17],[2,1.43,58.14]],"ltp":0.0,"tv":0.0,"id":12474498}]}]}
{"op":"mcm","clk":"11834581095","pt":1723132505717,"mc":[{"id":"1.231581347","rc":[{"batb":[[0,1.1,250],[1,1.08,312.5],[2,1.07,357.14]],"ltp":0.0,"tv":0.0,"id":25686043}]}]}
{"op":"mcm","clk":"11834581216","pt":1723132507240,"mc":[{"id":"1.231581347","rc":[{"batb":[[0,1.12,208.33],[1,1.1,250],[2,1.08,312.5]],"ltp":0.0,"tv":0.0,"id":25686043}]}]}
{"op":"mcm","clk":"11834581712","pt":1723132513138,"mc":[{"id":"1.231581347","rc":[{"batb":[[0,1.73,34.25],[1,1.63,39.68],[2,1.53,47.17]],"ltp":0.0,"tv":0.0,"id":12474498}]}]}
{"op":"mcm","clk":"11834581890","pt":1723132514649,"mc":[{"id":"1.231581347","rc":[{"batb":[[0,1.83,30.12],[1,1.73,34.25],[2,1.63,39.68]],"ltp":0.0,"tv":0.0,"id":12474498}]}]}
{"op":"mcm","clk":"11834596011","pt":1723132690286,"mc":[{"id":"1.231581347","rc":[{"batb":[[0,2.9,5.56],[1,1.83,30.12],[2,1.73,34.25]],"ltp":0.0,"tv":0.0,"id":12474498}]}]}
{"op":"mcm","clk":"11834610428","pt":1723132865296,"mc":[{"id":"1.231581347","rc":[{"batb":[[0,1.21,45.47],[1,1.12,208.33],[2,1.1,250]],"ltp":0.0,"tv":0.0,"id":25686043},{"batb":[[0,2.9,5.55]],"ltp":0.0,"tv":0.0,"id":12474498}]}]}
{"op":"mcm","clk":"11834611481","pt":1723132877204,"mc":[{"id":"1.231581347","rc":[{"batb":[[0,1.39,11.58],[1,1.21,45.47],[2,1.12,208.33]],"ltp":0.0,"tv":0.0,"id":25686043}]}]}
{"op":"mcm","clk":"11834613130","pt":1723132895848,"mc":[{"id":"1.231581347","rc":[{"batb":[[0,1.39,51.07],[1,1.12,208.33],[2,1.1,250]],"ltp":0.0,"tv":0.0,"id":25686043},{"batb":[[0,2.96,5.45]],"ltp":0.0,"tv":0.0,"id":12474498}]}]}
{"op":"mcm","clk":"11834614912","pt":1723132917607,"mc":[{"id":"1.231581347","rc":[{"batb":[[0,1.39,39.49],[1,1.37,11.73],[2,1.12,208.33]],"ltp":0.0,"tv":0.0,"id":25686043}]}]}
{"op":"mcm","clk":"11834638407","pt":1723133163580,"mc":[{"id":"1.231581347","rc":[{"batb":[[0,1.44,86.16],[1,1.39,39.49],[2,1.37,11.73]],"ltp":0.0,"tv":0.0,"id":25686043},{"batb":[[0,2.98,19.14],[1,2.96,5.45],[2,1.83,30.12]],"ltp":0.0,"tv":0.0,"id":12474498}]}]}
{"op":"mcm","clk":"11834666584","pt":1723133475754,"mc":[{"id":"1.231581347","rc":[{"batb":[[1,1.37,11.73],[2,1.12,208.33]],"ltp":0.0,"tv":0.0,"id":25686043}]}]}
{"op":"mcm","clk":"11834936680","pt":1723135797064,"mc":[{"id":"1.231581347","rc":[{"batb":[[1,1.12,208.33],[2,1.1,250]],"ltp":0.0,"tv":0.0,"id":25686043},{"batb":[[1,1.83,30.12],[2,1.73,34.25]],"ltp":0.0,"tv":0.0,"id":12474498}]}]}
{"op":"mcm","clk":"11835003193","pt":1723136313701,"mc":[{"id":"1.231581347","rc":[{"batl":[[0,1.79,392.4]],"ltp":0.0,"tv":0.0,"id":25686043}]}]}
{"op":"mcm","clk":"11835112164","pt":1723137076089,"mc":[{"id":"1.231581347","rc":[{"batl":[[0,1.5,30],[1,1.79,392.43]],"ltp":0.0,"tv":0.0,"id":25686043}]}]}
{"op":"mcm","clk":"11835203373","pt":1723137627586,"mc":[{"id":"1.231581347","rc":[{"trd":[[1.44,172.32]],"batb":[[0,1.22,179.99]],"batl":[[0,1.44,4.95],[1,1.5,30],[2,1.79,392.43]],"ltp":1.44,"tv":172.32,"id":25686043}],"tv":172.32}]}
{"op":"mcm","clk":"11835203916","pt":1723137631271,"mc":[{"id":"1.231581347","rc":[{"batb":[[0,1.4,94.78],[1,1.22,179.99],[2,1.12,208.33]],"ltp":1.44,"tv":172.32,"id":25686043}]}]}
{"op":"mcm","clk":"11835204391","pt":1723137634492,"mc":[{"id":"1.231581347","rc":[{"batl":[[0,1.5,30],[1,1.79,392.43],[2,1.79,0]],"ltp":1.44,"tv":172.32,"id":25686043}]}]}
{"op":"mcm","clk":"11835213813","pt":1723137699982,"mc":[{"id":"1.231581347","rc":[{"batb":[[1,1.37,11.73]],"ltp":1.44,"tv":172.32,"id":25686043},{"batb":[[0,2.98,24.53]],"ltp":0.0,"tv":0.0,"id":12474498}]}]}
{"op":"mcm","clk":"11835218228","pt":1723137730226,"mc":[{"id":"1.231581347","rc":[{"batb":[[1,1.12,208.33],[2,1.1,250]],"ltp":1.44,"tv":172.32,"id":25686043},{"batb":[[0,2.98,19.14]],"ltp":0.0,"tv":0.0,"id":12474498}]}]}
{"op":"mcm","clk":"11835244045","pt":1723137917510,"mc":[{"id":"1.231581347","rc":[{"trd":[[1.4,0.14]],"batb":[[0,1.4,94.71]],"ltp":1.4,"tv":172.46,"id":25686043}],"tv":172.46}]}
{"op":"mcm","clk":"11835244724","pt":1723137922410,"mc":[{"id":"1.231581347","rc":[{"batb":[[0,1.4,94.78]],"ltp":1.4,"tv":172.46,"id":25686043}]}]}
{"op":"mcm","clk":"11835278520","pt":1723138155763,"mc":[{"id":"1.231581347","rc":[{"batl":[[0,1.49,50],[1,1.5,30],[2,1.79,392.43]],"ltp":1.4,"tv":172.46,"id":25686043}]}]}
{"op":"mcm","clk":"11835283115","pt":1723138187874,"mc":[{"id":"1.231581347","rc":[{"trd":[[1.4,20.14]],"batb":[[0,1.4,84.78]],"ltp":1.4,"tv":192.46,"id":25686043}],"tv":192.46}]}
{"op":"mcm","clk":"11835283213","pt":1723138188496,"mc":[{"id":"1.231581347","rc":[{"batb":[[0,1.4,94.78]],"ltp":1.4,"tv":192.46,"id":25686043}]}]}
{"op":"mcm","clk":"11835298982","pt":1723138288914,"mc":[{"id":"1.231581347","rc":[{"trd":[[1.4,40.14]],"ltp":1.4,"tv":212.46,"id":25686043}],"tv":212.46}]}
{"op":"mcm","clk":"11835314568","pt":1723138388816,"mc":[{"id":"1.231581347","rc":[{"batb":[[0,1.41,4.66],[1,1.4,94.78],[2,1.12,208.33]],"ltp":1.4,"tv":212.46,"id":25686043}]}]}
{"op":"mcm","clk":"11835690457","pt":1723140730606,"mc":[{"id":"1.231581347","rc":[{"trd":[[1.44,172.29]],"batb":[[2,1.2,20]],"batl":[[2,1.79,392.34]],"ltp":1.4,"tv":212.42,"id":25686043}],"tv":212.42}]}
{"op":"mcm","clk":"11836101229","pt":1723142968110,"mc":[{"id":"1.231581347","rc":[{"batb":[[2,1.37,11.73]],"ltp":1.4,"tv":212.42,"id":25686043},{"batb":[[0,2.98,24.53]],"ltp":0.0,"tv":0.0,"id":12474498}]}]}
{"op":"mcm","clk":"11836374806","pt":1723145031079,"mc":[{"id":"1.231581347","rc":[{"trd":[[1.44,172.25]],"batb":[[2,1.2,20]],"batl":[[2,1.79,392.19]],"ltp":1.4,"tv":212.38,"id":25686043},{"batb":[[0,2.98,19.14]],"ltp":0.0,"tv":0.0,"id":12474498}],"tv":212.38}]}
{"op":"mcm","clk":"11836464863","pt":1723145721891,"mc":[{"id":"1.231581347","rc":[{"batb":[[1,1.4,148.78]],"ltp":1.4,"tv":212.38,"id":25686043}]}]}
{"op":"mcm","clk":"11836465976","pt":1723145730403,"mc":[{"id":"1.231581347","rc":[{"batl":[[1,1.5,51.6]],"ltp":1.4,"tv":212.38,"id":25686043}]}]}
{"op":"mcm","clk":"11836581142","pt":1723146722544,"mc":[{"id":"1.231581347","rc":[{"batb":[[2,1.37,11.73]],"ltp":1.4,"tv":212.38,"id":25686043},{"batb":[[0,2.98,24.53]],"ltp":0.0,"tv":0.0,"id":12474498}]}]}
{"op":"mcm","clk":"11836635370","pt":1723147274170,"mc":[{"id":"1.231581347","rc":[{"trd":[[1.44,172.27]],"batb":[[0,1.41,4.66],[2,1.2,20]],"batl":[[2,1.79,392.31]],"ltp":1.4,"tv":212.41,"id":25686043},{"batb":[[0,2.98,19.14]],"ltp":0.0,"tv":0.0,"id":12474498}],"tv":212.41}]}
{"op":"mcm","clk":"11836657984","pt":1723147526531,"mc":[{"id":"1.231581347","rc":[{"batb":[[0,1.43,300],[1,1.41,4.66],[2,1.4,148.78]],"ltp":1.4,"tv":212.41,"id":25686043}]}]}
{"op":"mcm","clk":"11836658096","pt":1723147528032,"mc":[{"id":"1.231581347","rc":[{"batb":[[1,1.4,148.78],[2,1.2,20]],"ltp":1.4,"tv":212.41,"id":25686043}]}]}
{"op":"mcm","clk":"11836721083","pt":1723148349862,"mc":[{"id":"1.231581347","rc":[{"batb":[[0,1.44,14.73],[1,1.43,300],[2,1.4,148.78]],"ltp":1.4,"tv":212.41,"id":25686043}]}]}
{"op":"mcm","clk":"11836749598","pt":1723148886020,"mc":[{"id":"1.231581347","rc":[{"batl":[[0,3.3,6.6]],"ltp":0.0,"tv":0.0,"id":12474498}]}]}
{"op":"mcm","clk":"11836764879","pt":1723149232342,"mc":[{"id":"1.231581347","rc":[{"batb":[[1,2.84,12.54],[2,1.83,30.12]],"ltp":0.0,"tv":0.0,"id":12474498}]}]}
{"op":"mcm","clk":"11836765907","pt":1723149256654,"mc":[{"id":"1.231581347","rc":[{"batb":[[2,2.62,16.72]],"ltp":0.0,"tv":0.0,"id":12474498}]}]}
{"op":"mcm","clk":"11836826331","pt":1723150945539,"mc":[{"id":"1.231581347","rc":[{"trd":[[1.44,172.24]],"batl":[[0,1.49,360.27],[2,1.79,392.19]],"ltp":1.4,"tv":212.38,"id":25686043},{"batb":[[1,2.84,12.54],[2,2.62,16.71]],"ltp":0.0,"tv":0.0,"id":12474498}],"tv":212.38}]}
{"op":"mcm","clk":"11836832035","pt":1723151130517,"mc":[{"id":"1.231581347","rc":[{"trd":[[1.44,194.51]],"batb":[[0,1.44,3.6]],"ltp":1.44,"tv":234.64,"id":25686043}],"tv":234.64}]}
{"op":"mcm","clk":"11836848676","pt":1723151708483,"mc":[{"id":"1.231581347","rc":[{"batl":[[0,1.48,17.34],[1,1.49,360.27],[2,1.5,51.6]],"ltp":1.44,"tv":234.64,"id":25686043}]}]}
{"op":"mcm","clk":"11836863961","pt":1723152308293,"mc":[{"id":"1.231581347","rc":[{"batb":[[0,3.05,8.69],[1,2.98,19.14],[2,2.84,12.54]],"ltp":0.0,"tv":0.0,"id":12474498}]}]}
{"op":"mcm","clk":"11836938799","pt":1723154008712,"mc":[{"id":"1.231581347","rc":[{"batl":[[0,1.47,1],[1,1.48,17.34],[2,1.49,360.27]],"ltp":1.44,"tv":234.64,"id":25686043}]}]}
{"op":"mcm","clk":"11837110716","pt":1723158710980,"mc":[{"id":"1.231581347","rc":[{"trd":[[1.44,194.57]],"batb":[[0,1.44,3.6]],"batl":[[1,1.48,17.35],[2,1.49,360.25]],"ltp":1.44,"tv":234.7,"id":25686043},{"batb":[[0,3.15,17.63],[1,3.05,8.7],[2,2.84,12.54]],"batl":[[0,3.3,6.61]],"ltp":0.0,"tv":0.0,"id":12474498}],"tv":234.7}]}
{"op":"mcm","clk":"11837110827","pt":1723158712940,"mc":[{"id":"1.231581347","rc":[{"batl":[[1,1.49,360.25],[2,1.5,51.6]],"ltp":1.44,"tv":234.7,"id":25686043},{"batb":[[1,2.84,12.54],[2,2.62,16.72]],"ltp":0.0,"tv":0.0,"id":12474498}]}]}
{"op":"mcm","clk":"11837152887","pt":1723159361031,"mc":[{"id":"1.231581347","rc":[{"batl":[[0,1.46,100],[1,1.47,1],[2,1.49,360.25]],"ltp":1.44,"tv":234.7,"id":25686043}]}]}
{"op":"mcm","clk":"11837181006","pt":1723160108371,"mc":[{"id":"1.231581347","rc":[{"batl":[[0,1.45,4.91],[1,1.46,100],[2,1.47,1]],"ltp":1.44,"tv":234.7,"id":25686043}]}]}
{"op":"mcm","clk":"11837243095","pt":1723161747819,"mc":[{"id":"1.231581347","rc":[{"trd":[[1.44,194.53],[1.45,1.61]],"batb":[[0,1.44,3.6]],"batl":[[0,1.45,3.3]],"ltp":1.45,"tv":236.28,"id":25686043},{"trd":[[3.2,0.73]],"batb":[[0,3.2,4],[1,3.15,17.63],[2,2.84,12.54]],"batl":[[0,3.3,6.6]],"ltp":3.2,"tv":0.72,"id":12474498}],"tv":237.0}]}
{"op":"mcm","clk":"11837243193","pt":1723161750230,"mc":[{"id":"1.231581347","rc":[{"batb":[[0,3.15,17.63],[1,2.84,12.54],[2,2.62,16.72]],"ltp":3.2,"tv":0.72,"id":12474498}]}]}
{"op":"mcm","clk":"11837243444","pt":1723161756947,"mc":[{"id":"1.231581347","rc":[{"batb":[[0,3.2,4],[1,3.15,17.63],[2,2.84,12.54]],"ltp":3.2,"tv":0.72,"id":12474498}]}]}
{"op":"mcm","clk":"11837243540","pt":1723161759514,"mc":[{"id":"1.231581347","rc":[{"batb":[[0,3.15,17.63],[1,2.84,12.54],[2,2.62,16.72]],"ltp":3.2,"tv":0.72,"id":12474498}]}]}
{"op":"mcm","clk":"11837243667","pt":1723161762949,"mc":[{"id":"1.231581347","rc":[{"batb":[[0,3.2,4],[1,3.15,17.63],[2,2.84,12.54]],"ltp":3.2,"tv":0.72,"id":12474498}]}]}
{"op":"mcm","clk":"11837243752","pt":1723161765256,"mc":[{"id":"1.231581347","rc":[{"batb":[[0,3.15,17.63],[1,2.84,12.54],[2,2.62,16.72]],"ltp":3.2,"tv":0.72,"id":12474498}]}]}
{"op":"mcm","clk":"11837243852","pt":1723161767541,"mc":[{"id":"1.231581347","rc":[{"batb":[[0,3.2,4],[1,3.15,17.63],[2,2.84,12.54]],"ltp":3.2,"tv":0.72,"id":12474498}]}]}
{"op":"mcm","clk":"11837243940","pt":1723161769853,"mc":[{"id":"1.231581347","rc":[{"batb":[[0,3.15,17.63],[1,2.84,12.54],[2,2.62,16.72]],"ltp":3.2,"tv":0.72,"id":12474498}]}]}
{"op":"mcm","clk":"11837244038","pt":1723161772058,"mc":[{"id":"1.231581347","rc":[{"batb":[[0,3.2,4],[1,3.15,17.63],[2,2.84,12.54]],"ltp":3.2,"tv":0.72,"id":12474498}]}]}
{"op":"mcm","clk":"11837244115","pt":1723161774261,"mc":[{"id":"1.231581347","rc":[{"batb":[[0,3.15,17.63],[1,2.84,12.54],[2,2.62,16.72]],"ltp":3.2,"tv":0.72,"id":12474498}]}]}
{"op":"mcm","clk":"11837244223","pt":1723161777086,"mc":[{"id":"1.231581347","rc":[{"batb":[[0,3.2,4],[1,3.15,17.63],[2,2.84,12.54]],"ltp":3.2,"tv":0.72,"id":12474498}]}]}
{"op":"mcm","clk":"11837244367","pt":1723161779370,"mc":[{"id":"1.231581347","rc":[{"batb":[[0,3.15,17.63],[1,2.84,12.54],[2,2.62,16.72]],"ltp":3.2,"tv":0.72,"id":12474498}]}]}
{"op":"mcm","clk":"11837244533","pt":1723161782577,"mc":[{"id":"1.231581347","rc":[{"batb":[[0,3.2,4],[1,3.15,17.63],[2,2.84,12.54]],"ltp":3.2,"tv":0.72,"id":12474498}]}]}
{"op":"mcm","clk":"11837244654","pt":1723161784946,"mc":[{"id":"1.231581347","rc":[{"batb":[[0,3.15,17.63],[1,2.84,12.54],[2,2.62,16.72]],"ltp":3.2,"tv":0.72,"id":12474498}]}]}
{"op":"mcm","clk":"11837244811","pt":1723161788385,"mc":[{"id":"1.231581347","rc":[{"batb":[[0,3.2,4],[1,3.15,17.63],[2,2.84,12.54]],"ltp":3.2,"tv":0.72,"id":12474498}]}]}
{"op":"mcm","clk":"11837244929","pt":1723161790803,"mc":[{"id":"1.231581347","rc":[{"batb":[[0,3.15,17.63],[1,2.84,12.54],[2,2.62,16.72]],"ltp":3.2,"tv":0.72,"id":12474498}]}]}
{"op":"mcm","clk":"11837244999","pt":1723161793057,"mc":[{"id":"1.231581347","rc":[{"batb":[[0,3.2,4],[1,3.15,17.63],[2,2.84,12.54]],"ltp":3.2,"tv":0.72,"id":12474498}]}]}
{"op":"mcm","clk":"11837245122","pt":1723161795411,"mc":[{"id":"1.231581347","rc":[{"batb":[[0,3.15,17.63],[1,2.84,12.54],[2,2.62,16.72]],"ltp":3.2,"tv":0.72,"id":12474498}]}]}
{"op":"mcm","clk":"11837245364","pt":1723161799570,"mc":[{"id":"1.231581347","rc":[{"batb":[[0,3.2,4],[1,3.15,17.63],[2,2.84,12.54]],"ltp":3.2,"tv":0.72,"id":12474498}]}]}
{"op":"mcm","clk":"11837245448","pt":1723161801889,"mc":[{"id":"1.231581347","rc":[{"batb":[[0,3.15,17.63],[1,2.84,12.54],[2,2.62,16.72]],"ltp":3.2,"tv":0.72,"id":12474498}]}]}
{"op":"mcm","clk":"11837245705","pt":1723161806517,"mc":[{"id":"1.231581347","rc":[{"batb":[[0,3.2,4],[1,3.15,17.63],[2,2.84,12.54]],"ltp":3.2,"tv":0.72,"id":12474498}]}]}
{"op":"mcm","clk":"11837245837","pt":1723161808922,"mc":[{"id":"1.231581347","rc":[{"batb":[[0,3.15,17.63],[1,2.84,12.54],[2,2.62,16.72]],"ltp":3.2,"tv":0.72,"id":12474498}]}]}
{"op":"mcm","clk":"11837245944","pt":1723161811330,"mc":[{"id":"1.231581347","rc":[{"batb":[[0,3.2,4],[1,3.15,17.63],[2,2.84,12.54]],"ltp":3.2,"tv":0.72,"id":12474498}]}]}
{"op":"mcm","clk":"11837246020","pt":1723161813691,"mc":[{"id":"1.231581347","rc":[{"batb":[[0,3.15,17.63],[1,2.84,12.54],[2,2.62,16.72]],"ltp":3.2,"tv":0.72,"id":12474498}]}]}
{"op":"mcm","clk":"11837246153","pt":1723161816919,"mc":[{"id":"1.231581347","rc":[{"batb":[[0,3.2,4],[1,3.15,17.63],[2,2.84,12.54]],"ltp":3.2,"tv":0.72,"id":12474498}]}]}
{"op":"mcm","clk":"11837246253","pt":1723161819228,"mc":[{"id":"1.231581347","rc":[{"batb":[[0,3.15,17.63],[1,2.84,12.54],[2,2.62,16.72]],"ltp":3.2,"tv":0.72,"id":12474498}]}]}
{"op":"mcm","clk":"11837246315","pt":1723161821634,"mc":[{"id":"1.231581347","rc":[{"batb":[[0,3.2,4],[1,3.15,17.63],[2,2.84,12.54]],"ltp":3.2,"tv":0.72,"id":12474498}]}]}
{"op":"mcm","clk":"11837246396","pt":1723161823839,"mc":[{"id":"1.231581347","rc":[{"batb":[[0,3.15,17.63],[1,2.84,12.54],[2,2.62,16.72]],"ltp":3.2,"tv":0.72,"id":12474498}]}]}
{"op":"mcm","clk":"11837246490","pt":1723161826249,"mc":[{"id":"1.231581347","rc":[{"batb":[[0,3.2,4],[1,3.15,17.63],[2,2.84,12.54]],"ltp":3.2,"tv":0.72,"id":12474498}]}]}
{"op":"mcm","clk":"11837246605","pt":1723161828516,"mc":[{"id":"1.231581347","rc":[{"batb":[[0,3.15,17.63],[1,2.84,12.54],[2,2.62,16.72]],"ltp":3.2,"tv":0.72,"id":12474498}]}]}
{"op":"mcm","clk":"11837246808","pt":1723161834426,"mc":[{"id":"1.231581347","rc":[{"batb":[[0,3.2,4],[1,3.15,17.63],[2,2.84,12.54]],"ltp":3.2,"tv":0.72,"id":12474498}]}]}
{"op":"mcm","clk":"11837246902","pt":1723161836732,"mc":[{"id":"1.231581347","rc":[{"batb":[[0,3.15,17.63],[1,2.84,12.54],[2,2.62,16.72]],"ltp":3.2,"tv":0.72,"id":12474498}]}]}
{"op":"mcm","clk":"11837246989","pt":1723161839250,"mc":[{"id":"1.231581347","rc":[{"batb":[[0,3.2,4],[1,3.15,17.63],[2,2.84,12.54]],"ltp":3.2,"tv":0.72,"id":12474498}]}]}
{"op":"mcm","clk":"11837247074","pt":1723161841561,"mc":[{"id":"1.231581347","rc":[{"batb":[[0,3.15,17.63],[1,2.84,12.54],[2,2.62,16.72]],"ltp":3.2,"tv":0.72,"id":12474498}]}]}
{"op":"mcm","clk":"11837247220","pt":1723161845260,"mc":[{"id":"1.231581347","rc":[{"batb":[[0,3.2,4],[1,3.15,17.63],[2,2.84,12.54]],"ltp":3.2,"tv":0.72,"id":12474498}]}]}
{"op":"mcm","clk":"11837247336","pt":1723161847591,"mc":[{"id":"1.231581347","rc":[{"batb":[[0,3.15,17.63],[1,2.84,12.54],[2,2.62,16.72]],"ltp":3.2,"tv":0.72,"id":12474498}]}]}
{"op":"mcm","clk":"11837247549","pt":1723161851081,"mc":[{"id":"1.231581347","rc":[{"batb":[[0,3.2,4],[1,3.15,17.63],[2,2.84,12.54]],"ltp":3.2,"tv":0.72,"id":12474498}]}]}
{"op":"mcm","clk":"11837247663","pt":1723161853283,"mc":[{"id":"1.231581347","rc":[{"batb":[[0,3.15,17.63],[1,2.84,12.54],[2,2.62,16.72]],"ltp":3.2,"tv":0.72,"id":12474498}]}]}
{"op":"mcm","clk":"11837247819","pt":1723161856570,"mc":[{"id":"1.231581347","rc":[{"batb":[[0,3.2,4],[1,3.15,17.63],[2,2.84,12.54]],"ltp":3.2,"tv":0.72,"id":12474498}]}]}
{"op":"mcm","clk":"11837247920","pt":1723161858876,"mc":[{"id":"1.231581347","rc":[{"batb":[[0,3.15,17.63],[1,2.84,12.54],[2,2.62,16.72]],"ltp":3.2,"tv":0.72,"id":12474498}]}]}
{"op":"mcm","clk":"11837248062","pt":1723161862474,"mc":[{"id":"1.231581347","rc":[{"batb":[[0,3.2,4],[1,3.15,17.63],[2,2.84,12.54]],"ltp":3.2,"tv":0.72,"id":12474498}]}]}
{"op":"mcm","clk":"11837248144","pt":1723161864787,"mc":[{"id":"1.231581347","rc":[{"batb":[[0,3.15,17.63],[1,2.84,12.54],[2,2.62,16.72]],"ltp":3.2,"tv":0.72,"id":12474498}]}]}
{"op":"mcm","clk":"11837248246","pt":1723161867103,"mc":[{"id":"1.231581347","rc":[{"batb":[[0,3.2,4],[1,3.15,17.63],[2,2.84,12.54]],"ltp":3.2,"tv":0.72,"id":12474498}]}]}
{"op":"mcm","clk":"11837248350","pt":1723161869386,"mc":[{"id":"1.231581347","rc":[{"batb":[[0,3.15,17.63],[1,2.84,12.54],[2,2.62,16.72]],"ltp":3.2,"tv":0.72,"id":12474498}]}]}
{"op":"mcm","clk":"11837248590","pt":1723161874169,"mc":[{"id":"1.231581347","rc":[{"batb":[[0,3.2,4],[1,3.15,17.63],[2,2.84,12.54]],"ltp":3.2,"tv":0.72,"id":12474498}]}]}
{"op":"mcm","clk":"11837248682","pt":1723161876585,"mc":[{"id":"1.231581347","rc":[{"batb":[[0,3.15,17.63],[1,2.84,12.54],[2,2.62,16.72]],"ltp":3.2,"tv":0.72,"id":12474498}]}]}
{"op":"mcm","clk":"11837248842","pt":1723161880283,"mc":[{"id":"1.231581347","rc":[{"batb":[[0,3.2,4],[1,3.15,17.63],[2,2.84,12.54]],"ltp":3.2,"tv":0.72,"id":12474498}]}]}
{"op":"mcm","clk":"11837248954","pt":1723161882794,"mc":[{"id":"1.231581347","rc":[{"batb":[[0,3.15,17.63],[1,2.84,12.54],[2,2.62,16.72]],"ltp":3.2,"tv":0.72,"id":12474498}]}]}
{"op":"mcm","clk":"11837249047","pt":1723161885006,"mc":[{"id":"1.231581347","rc":[{"batb":[[0,3.2,4],[1,3.15,17.63],[2,2.84,12.54]],"ltp":3.2,"tv":0.72,"id":12474498}]}]}
{"op":"mcm","clk":"11837249163","pt":1723161887425,"mc":[{"id":"1.231581347","rc":[{"batb":[[0,3.15,17.63],[1,2.84,12.54],[2,2.62,16.72]],"ltp":3.2,"tv":0.72,"id":12474498}]}]}
{"op":"mcm","clk":"11837249281","pt":1723161889789,"mc":[{"id":"1.231581347","rc":[{"batb":[[0,3.2,4],[1,3.15,17.63],[2,2.84,12.54]],"ltp":3.2,"tv":0.72,"id":12474498}]}]}
{"op":"mcm","clk":"11837249368","pt":1723161892099,"mc":[{"id":"1.231581347","rc":[{"batb":[[0,3.15,17.63],[1,2.84,12.54],[2,2.62,16.72]],"ltp":3.2,"tv":0.72,"id":12474498}]}]}
{"op":"mcm","clk":"11837249489","pt":1723161894510,"mc":[{"id":"1.231581347","rc":[{"batb":[[0,3.2,4],[1,3.15,17.63],[2,2.84,12.54]],"ltp":3.2,"tv":0.72,"id":12474498}]}]}
{"op":"mcm","clk":"11837249582","pt":1723161896719,"mc":[{"id":"1.231581347","rc":[{"batb":[[0,3.15,17.63],[1,2.84,12.54],[2,2.62,16.72]],"ltp":3.2,"tv":0.72,"id":12474498}]}]}
{"op":"mcm","clk":"11837249702","pt":1723161899340,"mc":[{"id":"1.231581347","rc":[{"batb":[[0,3.2,4],[1,3.15,17.63],[2,2.84,12.54]],"ltp":3.2,"tv":0.72,"id":12474498}]}]}
{"op":"mcm","clk":"11837249811","pt":1723161901711,"mc":[{"id":"1.231581347","rc":[{"batb":[[0,3.15,17.63],[1,2.84,12.54],[2,2.62,16.72]],"ltp":3.2,"tv":0.72,"id":12474498}]}]}
{"op":"mcm","clk":"11837249916","pt":1723161904134,"mc":[{"id":"1.231581347","rc":[{"batb":[[0,3.2,4],[1,3.15,17.63],[2,2.84,12.54]],"ltp":3.2,"tv":0.72,"id":12474498}]}]}
{"op":"mcm","clk":"11837250016","pt":1723161906446,"mc":[{"id":"1.231581347","rc":[{"batb":[[0,3.15,17.63],[1,2.84,12.54],[2,2.62,16.72]],"ltp":3.2,"tv":0.72,"id":12474498}]}]}
{"op":"mcm","clk":"11837250164","pt":1723161910145,"mc":[{"id":"1.231581347","rc":[{"batb":[[0,3.2,4],[1,3.15,17.63],[2,2.84,12.54]],"ltp":3.2,"tv":0.72,"id":12474498}]}]}
{"op":"mcm","clk":"11837250247","pt":1723161912458,"mc":[{"id":"1.231581347","rc":[{"batb":[[0,3.15,17.63],[1,2.84,12.54],[2,2.62,16.72]],"ltp":3.2,"tv":0.72,"id":12474498}]}]}
{"op":"mcm","clk":"11837250422","pt":1723161916268,"mc":[{"id":"1.231581347","rc":[{"batb":[[0,3.2,4],[1,3.15,17.63],[2,2.84,12.54]],"ltp":3.2,"tv":0.72,"id":12474498}]}]}
{"op":"mcm","clk":"11837250534","pt":1723161918838,"mc":[{"id":"1.231581347","rc":[{"batb":[[0,3.15,17.63],[1,2.84,12.54],[2,2.62,16.72]],"ltp":3.2,"tv":0.72,"id":12474498}]}]}
{"op":"mcm","clk":"11837250669","pt":1723161921771,"mc":[{"id":"1.231581347","rc":[{"batb":[[0,3.2,4],[1,3.15,17.63],[2,2.84,12.54]],"ltp":3.2,"tv":0.72,"id":12474498}]}]}
{"op":"mcm","clk":"11837250804","pt":1723161924346,"mc":[{"id":"1.231581347","rc":[{"batb":[[0,3.15,17.63],[1,2.84,12.54],[2,2.62,16.72]],"ltp":3.2,"tv":0.72,"id":12474498}]}]}
{"op":"mcm","clk":"11837251001","pt":1723161928589,"mc":[{"id":"1.231581347","rc":[{"batb":[[0,3.2,4],[1,3.15,17.63],[2,2.84,12.54]],"ltp":3.2,"tv":0.72,"id":12474498}]}]}
{"op":"mcm","clk":"11837251079","pt":1723161930855,"mc":[{"id":"1.231581347","rc":[{"batb":[[0,3.15,17.63],[1,2.84,12.54],[2,2.62,16.72]],"ltp":3.2,"tv":0.72,"id":12474498}]}]}
{"op":"mcm","clk":"11837251184","pt":1723161933375,"mc":[{"id":"1.231581347","rc":[{"batb":[[0,3.2,4],[1,3.15,17.63],[2,2.84,12.54]],"ltp":3.2,"tv":0.72,"id":12474498}]}]}
{"op":"mcm","clk":"11837251273","pt":1723161935798,"mc":[{"id":"1.231581347","rc":[{"batb":[[0,3.15,17.63],[1,2.84,12.54],[2,2.62,16.72]],"ltp":3.2,"tv":0.72,"id":12474498}]}]}
{"op":"mcm","clk":"11837251415","pt":1723161939301,"mc":[{"id":"1.231581347","rc":[{"batb":[[0,3.2,4],[1,3.15,17.63],[2,2.84,12.54]],"ltp":3.2,"tv":0.72,"id":12474498}]}]}
{"op":"mcm","clk":"11837251511","pt":1723161941667,"mc":[{"id":"1.231581347","rc":[{"batb":[[0,3.15,17.63],[1,2.84,12.54],[2,2.62,16.72]],"ltp":3.2,"tv":0.72,"id":12474498}]}]}
{"op":"mcm","clk":"11837251666","pt":1723161945265,"mc":[{"id":"1.231581347","rc":[{"batb":[[0,3.2,4],[1,3.15,17.63],[2,2.84,12.54]],"ltp":3.2,"tv":0.72,"id":12474498}]}]}
{"op":"mcm","clk":"11837251763","pt":1723161947576,"mc":[{"id":"1.231581347","rc":[{"batb":[[0,3.15,17.63],[1,2.84,12.54],[2,2.62,16.72]],"ltp":3.2,"tv":0.72,"id":12474498}]}]}
{"op":"mcm","clk":"11837251984","pt":1723161952405,"mc":[{"id":"1.231581347","rc":[{"batb":[[0,3.2,4],[1,3.15,17.63],[2,2.84,12.54]],"ltp":3.2,"tv":0.72,"id":12474498}]}]}
{"op":"mcm","clk":"11837252066","pt":1723161954717,"mc":[{"id":"1.231581347","rc":[{"batb":[[0,3.15,17.63],[1,2.84,12.54],[2,2.62,16.72]],"ltp":3.2,"tv":0.72,"id":12474498}]}]}
{"op":"mcm","clk":"11837252219","pt":1723161958320,"mc":[{"id":"1.231581347","rc":[{"batb":[[0,3.2,4],[1,3.15,17.63],[2,2.84,12.54]],"ltp":3.2,"tv":0.72,"id":12474498}]}]}
{"op":"mcm","clk":"11837252333","pt":1723161960633,"mc":[{"id":"1.231581347","rc":[{"batb":[[0,3.15,17.63],[1,2.84,12.54],[2,2.62,16.72]],"ltp":3.2,"tv":0.72,"id":12474498}]}]}
{"op":"mcm","clk":"11837252418","pt":1723161963109,"mc":[{"id":"1.231581347","rc":[{"batb":[[0,3.2,4],[1,3.15,17.63],[2,2.84,12.54]],"ltp":3.2,"tv":0.72,"id":12474498}]}]}
{"op":"mcm","clk":"11837252511","pt":1723161965417,"mc":[{"id":"1.231581347","rc":[{"batb":[[0,3.15,17.63],[1,2.84,12.54],[2,2.62,16.72]],"ltp":3.2,"tv":0.72,"id":12474498}]}]}
{"op":"mcm","clk":"11837252808","pt":1723161972618,"mc":[{"id":"1.231581347","rc":[{"batb":[[0,3.2,4],[1,3.15,17.63],[2,2.84,12.54]],"ltp":3.2,"tv":0.72,"id":12474498}]}]}
{"op":"mcm","clk":"11837252895","pt":1723161975030,"mc":[{"id":"1.231581347","rc":[{"batb":[[0,3.15,17.63],[1,2.84,12.54],[2,2.62,16.72]],"ltp":3.2,"tv":0.72,"id":12474498}]}]}
{"op":"mcm","clk":"11837253001","pt":1723161977346,"mc":[{"id":"1.231581347","rc":[{"batb":[[0,3.2,4],[1,3.15,17.63],[2,2.84,12.54]],"ltp":3.2,"tv":0.72,"id":12474498}]}]}
{"op":"mcm","clk":"11837253080","pt":1723161979758,"mc":[{"id":"1.231581347","rc":[{"batb":[[0,3.15,17.63],[1,2.84,12.54],[2,2.62,16.72]],"ltp":3.2,"tv":0.72,"id":12474498}]}]}
{"op":"mcm","clk":"11837253181","pt":1723161983244,"mc":[{"id":"1.231581347","rc":[{"batb":[[0,3.2,4],[1,3.15,17.63],[2,2.84,12.54]],"ltp":3.2,"tv":0.72,"id":12474498}]}]}
{"op":"mcm","clk":"11837253256","pt":1723161985651,"mc":[{"id":"1.231581347","rc":[{"batb":[[0,3.15,17.63],[1,2.84,12.54],[2,2.62,16.72]],"ltp":3.2,"tv":0.72,"id":12474498}]}]}
{"op":"mcm","clk":"11837253333","pt":1723161987864,"mc":[{"id":"1.231581347","rc":[{"batb":[[0,3.2,4],[1,3.15,17.63],[2,2.84,12.54]],"ltp":3.2,"tv":0.72,"id":12474498}]}]}
{"op":"mcm","clk":"11837253401","pt":1723161990079,"mc":[{"id":"1.231581347","rc":[{"batb":[[0,3.15,17.63],[1,2.84,12.54],[2,2.62,16.72]],"ltp":3.2,"tv":0.72,"id":12474498}]}]}
{"op":"mcm","clk":"11837253510","pt":1723161993879,"mc":[{"id":"1.231581347","rc":[{"batb":[[0,3.2,4],[1,3.15,17.63],[2,2.84,12.54]],"ltp":3.2,"tv":0.72,"id":12474498}]}]}
{"op":"mcm","clk":"11837253598","pt":1723161996144,"mc":[{"id":"1.231581347","rc":[{"batb":[[0,3.15,17.63],[1,2.84,12.54],[2,2.62,16.72]],"ltp":3.2,"tv":0.72,"id":12474498}]}]}
{"op":"mcm","clk":"11837253831","pt":1723162003486,"mc":[{"id":"1.231581347","rc":[{"batb":[[0,3.2,4],[1,3.15,17.63],[2,2.84,12.54]],"ltp":3.2,"tv":0.72,"id":12474498}]}]}
{"op":"mcm","clk":"11837253900","pt":1723162005905,"mc":[{"id":"1.231581347","rc":[{"batb":[[0,3.15,17.63],[1,2.84,12.54],[2,2.62,16.72]],"ltp":3.2,"tv":0.72,"id":12474498}]}]}
{"op":"mcm","clk":"11837253984","pt":1723162008267,"mc":[{"id":"1.231581347","rc":[{"batb":[[0,3.2,4],[1,3.15,17.63],[2,2.84,12.54]],"ltp":3.2,"tv":0.72,"id":12474498}]}]}
{"op":"mcm","clk":"11837254066","pt":1723162010781,"mc":[{"id":"1.231581347","rc":[{"batb":[[0,3.15,17.63],[1,2.84,12.54],[2,2.62,16.72]],"ltp":3.2,"tv":0.72,"id":12474498}]}]}
{"op":"mcm","clk":"11837254201","pt":1723162014072,"mc":[{"id":"1.231581347","rc":[{"batb":[[0,3.2,4],[1,3.15,17.63],[2,2.84,12.54]],"ltp":3.2,"tv":0.72,"id":12474498}]}]}
{"op":"mcm","clk":"11837254279","pt":1723162016285,"mc":[{"id":"1.231581347","rc":[{"batb":[[0,3.15,17.63],[1,2.84,12.54],[2,2.62,16.72]],"ltp":3.2,"tv":0.72,"id":12474498}]}]}
{"op":"mcm","clk":"11837254413","pt":1723162019979,"mc":[{"id":"1.231581347","rc":[{"batb":[[0,3.2,4],[1,3.15,17.63],[2,2.84,12.54]],"ltp":3.2,"tv":0.72,"id":12474498}]}]}
{"op":"mcm","clk":"11837254518","pt":1723162022401,"mc":[{"id":"1.231581347","rc":[{"batb":[[0,3.15,17.63],[1,2.84,12.54],[2,2.62,16.72]],"ltp":3.2,"tv":0.72,"id":12474498}]}]}
{"op":"mcm","clk":"11837254671","pt":1723162026105,"mc":[{"id":"1.231581347","rc":[{"batb":[[0,3.2,4],[1,3.15,17.63],[2,2.84,12.54]],"ltp":3.2,"tv":0.72,"id":12474498}]}]}
{"op":"mcm","clk":"11837254756","pt":1723162028519,"mc":[{"id":"1.231581347","rc":[{"batb":[[0,3.15,17.63],[1,2.84,12.54],[2,2.62,16.72]],"ltp":3.2,"tv":0.72,"id":12474498}]}]}
{"op":"mcm","clk":"11837254846","pt":1723162030991,"mc":[{"id":"1.231581347","rc":[{"batb":[[0,3.2,4],[1,3.15,17.63],[2,2.84,12.54]],"ltp":3.2,"tv":0.72,"id":12474498}]}]}
{"op":"mcm","clk":"11837254924","pt":1723162033407,"mc":[{"id":"1.231581347","rc":[{"batb":[[0,3.15,17.63],[1,2.84,12.54],[2,2.62,16.72]],"ltp":3.2,"tv":0.72,"id":12474498}]}]}
{"op":"mcm","clk":"11837255049","pt":1723162036997,"mc":[{"id":"1.231581347","rc":[{"batb":[[0,3.2,4],[1,3.15,17.63],[2,2.84,12.54]],"ltp":3.2,"tv":0.72,"id":12474498}]}]}
{"op":"mcm","clk":"11837255152","pt":1723162039622,"mc":[{"id":"1.231581347","rc":[{"batb":[[0,3.15,17.63],[1,2.84,12.54],[2,2.62,16.72]],"ltp":3.2,"tv":0.72,"id":12474498}]}]}
{"op":"mcm","clk":"11837255257","pt":1723162042905,"mc":[{"id":"1.231581347","rc":[{"batb":[[0,3.2,4],[1,3.15,17.63],[2,2.84,12.54]],"ltp":3.2,"tv":0.72,"id":12474498}]}]}
{"op":"mcm","clk":"11837255321","pt":1723162045525,"mc":[{"id":"1.231581347","rc":[{"batb":[[0,3.15,17.63],[1,2.84,12.54],[2,2.62,16.72]],"ltp":3.2,"tv":0.72,"id":12474498}]}]}
{"op":"mcm","clk":"11837255404","pt":1723162048752,"mc":[{"id":"1.231581347","rc":[{"batb":[[0,3.2,4],[1,3.15,17.63],[2,2.84,12.54]],"ltp":3.2,"tv":0.72,"id":12474498}]}]}
{"op":"mcm","clk":"11837255476","pt":1723162051016,"mc":[{"id":"1.231581347","rc":[{"batb":[[0,3.15,17.63],[1,2.84,12.54],[2,2.62,16.72]],"ltp":3.2,"tv":0.72,"id":12474498}]}]}
{"op":"mcm","clk":"11837255552","pt":1723162053243,"mc":[{"id":"1.231581347","rc":[{"batb":[[0,3.2,4],[1,3.15,17.63],[2,2.84,12.54]],"ltp":3.2,"tv":0.72,"id":12474498}]}]}
{"op":"mcm","clk":"11837255644","pt":1723162055658,"mc":[{"id":"1.231581347","rc":[{"batb":[[0,3.15,17.63],[1,2.84,12.54],[2,2.62,16.72]],"ltp":3.2,"tv":0.72,"id":12474498}]}]}
{"op":"mcm","clk":"11837255799","pt":1723162060435,"mc":[{"id":"1.231581347","rc":[{"batb":[[0,3.2,4],[1,3.15,17.63],[2,2.84,12.54]],"ltp":3.2,"tv":0.72,"id":12474498}]}]}
{"op":"mcm","clk":"11837255882","pt":1723162062745,"mc":[{"id":"1.231581347","rc":[{"batb":[[0,3.15,17.63],[1,2.84,12.54],[2,2.62,16.72]],"ltp":3.2,"tv":0.72,"id":12474498}]}]}
{"op":"mcm","clk":"11837256055","pt":1723162067673,"mc":[{"id":"1.231581347","rc":[{"batb":[[0,3.2,4],[1,3.15,17.63],[2,2.84,12.54]],"ltp":3.2,"tv":0.72,"id":12474498}]}]}
{"op":"mcm","clk":"11837256137","pt":1723162069932,"mc":[{"id":"1.231581347","rc":[{"batb":[[0,3.15,17.63],[1,2.84,12.54],[2,2.62,16.72]],"ltp":3.2,"tv":0.72,"id":12474498}]}]}
{"op":"mcm","clk":"11837256267","pt":1723162073578,"mc":[{"id":"1.231581347","rc":[{"batb":[[0,3.2,4],[1,3.15,17.63],[2,2.84,12.54]],"ltp":3.2,"tv":0.72,"id":12474498}]}]}
{"op":"mcm","clk":"11837256344","pt":1723162076038,"mc":[{"id":"1.231581347","rc":[{"batb":[[0,3.15,17.63],[1,2.84,12.54],[2,2.62,16.72]],"ltp":3.2,"tv":0.72,"id":12474498}]}]}
{"op":"mcm","clk":"11837256477","pt":1723162079576,"mc":[{"id":"1.231581347","rc":[{"batb":[[0,3.2,4],[1,3.15,17.63],[2,2.84,12.54]],"ltp":3.2,"tv":0.72,"id":12474498}]}]}
{"op":"mcm","clk":"11837256578","pt":1723162081991,"mc":[{"id":"1.231581347","rc":[{"batb":[[0,3.15,17.63],[1,2.84,12.54],[2,2.62,16.72]],"ltp":3.2,"tv":0.72,"id":12474498}]}]}
{"op":"mcm","clk":"11837256658","pt":1723162084259,"mc":[{"id":"1.231581347","rc":[{"batb":[[0,3.2,4],[1,3.15,17.63],[2,2.84,12.54]],"ltp":3.2,"tv":0.72,"id":12474498}]}]}
{"op":"mcm","clk":"11837256733","pt":1723162086464,"mc":[{"id":"1.231581347","rc":[{"batb":[[0,3.15,17.63],[1,2.84,12.54],[2,2.62,16.72]],"ltp":3.2,"tv":0.72,"id":12474498}]}]}
{"op":"mcm","clk":"11837256938","pt":1723162093696,"mc":[{"id":"1.231581347","rc":[{"batb":[[0,3.2,4],[1,3.15,17.63],[2,2.84,12.54]],"ltp":3.2,"tv":0.72,"id":12474498}]}]}
{"op":"mcm","clk":"11837257008","pt":1723162096007,"mc":[{"id":"1.231581347","rc":[{"batb":[[0,3.15,17.63],[1,2.84,12.54],[2,2.62,16.72]],"ltp":3.2,"tv":0.72,"id":12474498}]}]}
{"op":"mcm","clk":"11837257076","pt":1723162098673,"mc":[{"id":"1.231581347","rc":[{"batb":[[0,3.2,4],[1,3.15,17.63],[2,2.84,12.54]],"ltp":3.2,"tv":0.72,"id":12474498}]}]}
{"op":"mcm","clk":"11837257134","pt":1723162100881,"mc":[{"id":"1.231581347","rc":[{"batb":[[0,3.15,17.63],[1,2.84,12.54],[2,2.62,16.72]],"ltp":3.2,"tv":0.72,"id":12474498}]}]}
{"op":"mcm","clk":"11837257241","pt":1723162104176,"mc":[{"id":"1.231581347","rc":[{"batb":[[0,3.2,4],[1,3.15,17.63],[2,2.84,12.54]],"ltp":3.2,"tv":0.72,"id":12474498}]}]}
{"op":"mcm","clk":"11837257333","pt":1723162106491,"mc":[{"id":"1.231581347","rc":[{"batb":[[0,3.15,17.63],[1,2.84,12.54],[2,2.62,16.72]],"ltp":3.2,"tv":0.72,"id":12474498}]}]}
{"op":"mcm","clk":"11837257419","pt":1723162109004,"mc":[{"id":"1.231581347","rc":[{"batb":[[0,3.2,4],[1,3.15,17.63],[2,2.84,12.54]],"ltp":3.2,"tv":0.72,"id":12474498}]}]}
{"op":"mcm","clk":"11837257513","pt":1723162111416,"mc":[{"id":"1.231581347","rc":[{"batb":[[0,3.15,17.63],[1,2.84,12.54],[2,2.62,16.72]],"ltp":3.2,"tv":0.72,"id":12474498}]}]}
{"op":"mcm","clk":"11837257672","pt":1723162115008,"mc":[{"id":"1.231581347","rc":[{"batb":[[0,3.2,4],[1,3.15,17.63],[2,2.84,12.54]],"ltp":3.2,"tv":0.72,"id":12474498}]}]}
{"op":"mcm","clk":"11837257769","pt":1723162117522,"mc":[{"id":"1.231581347","rc":[{"batb":[[0,3.15,17.63],[1,2.84,12.54],[2,2.62,16.72]],"ltp":3.2,"tv":0.72,"id":12474498}]}]}
{"op":"mcm","clk":"11837257848","pt":1723162119938,"mc":[{"id":"1.231581347","rc":[{"batb":[[0,3.2,4],[1,3.15,17.63],[2,2.84,12.54]],"ltp":3.2,"tv":0.72,"id":12474498}]}]}
{"op":"mcm","clk":"11837257914","pt":1723162122120,"mc":[{"id":"1.231581347","rc":[{"batb":[[0,3.15,17.63],[1,2.84,12.54],[2,2.62,16.72]],"ltp":3.2,"tv":0.72,"id":12474498}]}]}
{"op":"mcm","clk":"11837257999","pt":1723162124725,"mc":[{"id":"1.231581347","rc":[{"batb":[[0,3.2,4],[1,3.15,17.63],[2,2.84,12.54]],"ltp":3.2,"tv":0.72,"id":12474498}]}]}
{"op":"mcm","clk":"11837258073","pt":1723162127038,"mc":[{"id":"1.231581347","rc":[{"batb":[[0,3.15,17.63],[1,2.84,12.54],[2,2.62,16.72]],"ltp":3.2,"tv":0.72,"id":12474498}]}]}
{"op":"mcm","clk":"11837258173","pt":1723162129449,"mc":[{"id":"1.231581347","rc":[{"batb":[[0,3.2,4],[1,3.15,17.63],[2,2.84,12.54]],"ltp":3.2,"tv":0.72,"id":12474498}]}]}
{"op":"mcm","clk":"11837258260","pt":1723162131816,"mc":[{"id":"1.231581347","rc":[{"batb":[[0,3.15,17.63],[1,2.84,12.54],[2,2.62,16.72]],"ltp":3.2,"tv":0.72,"id":12474498}]}]}
{"op":"mcm","clk":"11837258361","pt":1723162134336,"mc":[{"id":"1.231581347","rc":[{"batb":[[0,3.2,4],[1,3.15,17.63],[2,2.84,12.54]],"ltp":3.2,"tv":0.72,"id":12474498}]}]}
{"op":"mcm","clk":"11837258465","pt":1723162136655,"mc":[{"id":"1.231581347","rc":[{"batb":[[0,3.15,17.63],[1,2.84,12.54],[2,2.62,16.72]],"ltp":3.2,"tv":0.72,"id":12474498}]}]}
{"op":"mcm","clk":"11837258617","pt":1723162140357,"mc":[{"id":"1.231581347","rc":[{"batb":[[0,3.2,4],[1,3.15,17.63],[2,2.84,12.54]],"ltp":3.2,"tv":0.72,"id":12474498}]}]}
{"op":"mcm","clk":"11837258715","pt":1723162142831,"mc":[{"id":"1.231581347","rc":[{"batb":[[0,3.15,17.63],[1,2.84,12.54],[2,2.62,16.72]],"ltp":3.2,"tv":0.72,"id":12474498}]}]}
{"op":"mcm","clk":"11837258864","pt":1723162146270,"mc":[{"id":"1.231581347","rc":[{"batb":[[0,3.2,4],[1,3.15,17.63],[2,2.84,12.54]],"ltp":3.2,"tv":0.72,"id":12474498}]}]}
{"op":"mcm","clk":"11837258969","pt":1723162148479,"mc":[{"id":"1.231581347","rc":[{"batb":[[0,3.15,17.63],[1,2.84,12.54],[2,2.62,16.72]],"ltp":3.2,"tv":0.72,"id":12474498}]}]}
{"op":"mcm","clk":"11837259084","pt":1723162150847,"mc":[{"id":"1.231581347","rc":[{"batb":[[0,3.2,4],[1,3.15,17.63],[2,2.84,12.54]],"ltp":3.2,"tv":0.72,"id":12474498}]}]}
{"op":"mcm","clk":"11837259202","pt":1723162153162,"mc":[{"id":"1.231581347","rc":[{"batb":[[0,3.15,17.63],[1,2.84,12.54],[2,2.62,16.72]],"ltp":3.2,"tv":0.72,"id":12474498}]}]}
{"op":"mcm","clk":"11837259405","pt":1723162157065,"mc":[{"id":"1.231581347","rc":[{"batb":[[0,3.2,4],[1,3.15,17.63],[2,2.84,12.54]],"ltp":3.2,"tv":0.72,"id":12474498}]}]}
{"op":"mcm","clk":"11837259504","pt":1723162159377,"mc":[{"id":"1.231581347","rc":[{"batb":[[0,3.15,17.63],[1,2.84,12.54],[2,2.62,16.72]],"ltp":3.2,"tv":0.72,"id":12474498}]}]}
{"op":"mcm","clk":"11837259765","pt":1723162165361,"mc":[{"id":"1.231581347","rc":[{"batb":[[0,3.2,4],[1,3.15,17.63],[2,2.84,12.54]],"ltp":3.2,"tv":0.72,"id":12474498}]}]}
{"op":"mcm","clk":"11837259851","pt":1723162167772,"mc":[{"id":"1.231581347","rc":[{"batb":[[0,3.15,17.63],[1,2.84,12.54],[2,2.62,16.72]],"ltp":3.2,"tv":0.72,"id":12474498}]}]}
{"op":"mcm","clk":"11837260010","pt":1723162171368,"mc":[{"id":"1.231581347","rc":[{"batb":[[0,3.2,4],[1,3.15,17.63],[2,2.84,12.54]],"ltp":3.2,"tv":0.72,"id":12474498}]}]}
{"op":"mcm","clk":"11837260135","pt":1723162173788,"mc":[{"id":"1.231581347","rc":[{"batb":[[0,3.15,17.63],[1,2.84,12.54],[2,2.62,16.72]],"ltp":3.2,"tv":0.72,"id":12474498}]}]}
{"op":"mcm","clk":"11837260255","pt":1723162176167,"mc":[{"id":"1.231581347","rc":[{"batb":[[0,3.2,4],[1,3.15,17.63],[2,2.84,12.54]],"ltp":3.2,"tv":0.72,"id":12474498}]}]}
{"op":"mcm","clk":"11837260335","pt":1723162178277,"mc":[{"id":"1.231581347","rc":[{"batb":[[0,3.15,17.63],[1,2.84,12.54],[2,2.62,16.72]],"ltp":3.2,"tv":0.72,"id":12474498}]}]}
{"op":"mcm","clk":"11837260502","pt":1723162181672,"mc":[{"id":"1.231581347","rc":[{"batb":[[0,3.2,4],[1,3.15,17.63],[2,2.84,12.54]],"ltp":3.2,"tv":0.72,"id":12474498}]}]}
{"op":"mcm","clk":"11837260610","pt":1723162184083,"mc":[{"id":"1.231581347","rc":[{"batb":[[0,3.15,17.63],[1,2.84,12.54],[2,2.62,16.72]],"ltp":3.2,"tv":0.72,"id":12474498}]}]}
{"op":"mcm","clk":"11837260753","pt":1723162187480,"mc":[{"id":"1.231581347","rc":[{"batb":[[0,3.2,4],[1,3.15,17.63],[2,2.84,12.54]],"ltp":3.2,"tv":0.72,"id":12474498}]}]}
{"op":"mcm","clk":"11837260866","pt":1723162189686,"mc":[{"id":"1.231581347","rc":[{"batb":[[0,3.15,17.63],[1,2.84,12.54],[2,2.62,16.72]],"ltp":3.2,"tv":0.72,"id":12474498}]}]}
{"op":"mcm","clk":"11837260983","pt":1723162192312,"mc":[{"id":"1.231581347","rc":[{"batb":[[0,3.2,4],[1,3.15,17.63],[2,2.84,12.54]],"ltp":3.2,"tv":0.72,"id":12474498}]}]}
{"op":"mcm","clk":"11837261108","pt":1723162194726,"mc":[{"id":"1.231581347","rc":[{"batb":[[0,3.15,17.63],[1,2.84,12.54],[2,2.62,16.72]],"ltp":3.2,"tv":0.72,"id":12474498}]}]}
{"op":"mcm","clk":"11837261200","pt":1723162196889,"mc":[{"id":"1.231581347","rc":[{"batb":[[0,3.2,4],[1,3.15,17.63],[2,2.84,12.54]],"ltp":3.2,"tv":0.72,"id":12474498}]}]}
{"op":"mcm","clk":"11837261282","pt":1723162199197,"mc":[{"id":"1.231581347","rc":[{"batb":[[0,3.15,17.63],[1,2.84,12.54],[2,2.62,16.72]],"ltp":3.2,"tv":0.72,"id":12474498}]}]}
{"op":"mcm","clk":"11837261394","pt":1723162201823,"mc":[{"id":"1.231581347","rc":[{"batb":[[0,3.2,4],[1,3.15,17.63],[2,2.84,12.54]],"ltp":3.2,"tv":0.72,"id":12474498}]}]}
{"op":"mcm","clk":"11837261511","pt":1723162204135,"mc":[{"id":"1.231581347","rc":[{"batb":[[0,3.15,17.63],[1,2.84,12.54],[2,2.62,16.72]],"ltp":3.2,"tv":0.72,"id":12474498}]}]}
{"op":"mcm","clk":"11837261613","pt":1723162206602,"mc":[{"id":"1.231581347","rc":[{"batb":[[0,3.2,4],[1,3.15,17.63],[2,2.84,12.54]],"ltp":3.2,"tv":0.72,"id":12474498}]}]}
{"op":"mcm","clk":"11837261748","pt":1723162208914,"mc":[{"id":"1.231581347","rc":[{"batb":[[0,3.15,17.63],[1,2.84,12.54],[2,2.62,16.72]],"ltp":3.2,"tv":0.72,"id":12474498}]}]}
{"op":"mcm","clk":"11837261858","pt":1723162211435,"mc":[{"id":"1.231581347","rc":[{"batb":[[0,3.2,4],[1,3.15,17.63],[2,2.84,12.54]],"ltp":3.2,"tv":0.72,"id":12474498}]}]}
{"op":"mcm","clk":"11837261980","pt":1723162213748,"mc":[{"id":"1.231581347","rc":[{"batb":[[0,3.15,17.63],[1,2.84,12.54],[2,2.62,16.72]],"ltp":3.2,"tv":0.72,"id":12474498}]}]}
{"op":"mcm","clk":"11837262114","pt":1723162216415,"mc":[{"id":"1.231581347","rc":[{"batb":[[0,3.2,4],[1,3.15,17.63],[2,2.84,12.54]],"ltp":3.2,"tv":0.72,"id":12474498}]}]}
{"op":"mcm","clk":"11837262226","pt":1723162218621,"mc":[{"id":"1.231581347","rc":[{"batb":[[0,3.15,17.63],[1,2.84,12.54],[2,2.62,16.72]],"ltp":3.2,"tv":0.72,"id":12474498}]}]}
{"op":"mcm","clk":"11837262344","pt":1723162221028,"mc":[{"id":"1.231581347","rc":[{"batb":[[0,3.2,4],[1,3.15,17.63],[2,2.84,12.54]],"ltp":3.2,"tv":0.72,"id":12474498}]}]}
{"op":"mcm","clk":"11837262430","pt":1723162223259,"mc":[{"id":"1.231581347","rc":[{"batb":[[0,3.15,17.63],[1,2.84,12.54],[2,2.62,16.72]],"ltp":3.2,"tv":0.72,"id":12474498}]}]}
{"op":"mcm","clk":"11837262588","pt":1723162226952,"mc":[{"id":"1.231581347","rc":[{"batb":[[0,3.2,4],[1,3.15,17.63],[2,2.84,12.54]],"ltp":3.2,"tv":0.72,"id":12474498}]}]}
{"op":"mcm","clk":"11837262667","pt":1723162229366,"mc":[{"id":"1.231581347","rc":[{"batb":[[0,3.15,17.63],[1,2.84,12.54],[2,2.62,16.72]],"ltp":3.2,"tv":0.72,"id":12474498}]}]}
{"op":"mcm","clk":"11837262934","pt":1723162235638,"mc":[{"id":"1.231581347","rc":[{"batb":[[0,3.2,4],[1,3.15,17.63],[2,2.84,12.54]],"ltp":3.2,"tv":0.72,"id":12474498}]}]}
{"op":"mcm","clk":"11837263024","pt":1723162237954,"mc":[{"id":"1.231581347","rc":[{"batb":[[0,3.15,17.63],[1,2.84,12.54],[2,2.62,16.72]],"ltp":3.2,"tv":0.72,"id":12474498}]}]}
{"op":"mcm","clk":"11837263213","pt":1723162241861,"mc":[{"id":"1.231581347","rc":[{"batb":[[0,3.2,4],[1,3.15,17.63],[2,2.84,12.54]],"ltp":3.2,"tv":0.72,"id":12474498}]}]}
{"op":"mcm","clk":"11837263296","pt":1723162244170,"mc":[{"id":"1.231581347","rc":[{"batb":[[0,3.15,17.63],[1,2.84,12.54],[2,2.62,16.72]],"ltp":3.2,"tv":0.72,"id":12474498}]}]}
{"op":"mcm","clk":"11837263421","pt":1723162247763,"mc":[{"id":"1.231581347","rc":[{"batb":[[0,3.2,4],[1,3.15,17.63],[2,2.84,12.54]],"ltp":3.2,"tv":0.72,"id":12474498}]}]}
{"op":"mcm","clk":"11837263504","pt":1723162250174,"mc":[{"id":"1.231581347","rc":[{"batb":[[0,3.15,17.63],[1,2.84,12.54],[2,2.62,16.72]],"ltp":3.2,"tv":0.72,"id":12474498}]}]}
{"op":"mcm","clk":"11837263599","pt":1723162252592,"mc":[{"id":"1.231581347","rc":[{"batb":[[0,3.2,4],[1,3.15,17.63],[2,2.84,12.54]],"ltp":3.2,"tv":0.72,"id":12474498}]}]}
{"op":"mcm","clk":"11837263682","pt":1723162254799,"mc":[{"id":"1.231581347","rc":[{"batb":[[0,3.15,17.63],[1,2.84,12.54],[2,2.62,16.72]],"ltp":3.2,"tv":0.72,"id":12474498}]}]}
{"op":"mcm","clk":"11837263787","pt":1723162257270,"mc":[{"id":"1.231581347","rc":[{"batb":[[0,3.2,4],[1,3.15,17.63],[2,2.84,12.54]],"ltp":3.2,"tv":0.72,"id":12474498}]}]}
{"op":"mcm","clk":"11837263895","pt":1723162259586,"mc":[{"id":"1.231581347","rc":[{"batb":[[0,3.15,17.63],[1,2.84,12.54],[2,2.62,16.72]],"ltp":3.2,"tv":0.72,"id":12474498}]}]}
{"op":"mcm","clk":"11837264005","pt":1723162262103,"mc":[{"id":"1.231581347","rc":[{"batb":[[0,3.2,4],[1,3.15,17.63],[2,2.84,12.54]],"ltp":3.2,"tv":0.72,"id":12474498}]}]}
{"op":"mcm","clk":"11837264111","pt":1723162264314,"mc":[{"id":"1.231581347","rc":[{"batb":[[0,3.15,17.63],[1,2.84,12.54],[2,2.62,16.72]],"ltp":3.2,"tv":0.72,"id":12474498}]}]}
{"op":"mcm","clk":"11837264244","pt":1723162266985,"mc":[{"id":"1.231581347","rc":[{"batb":[[0,3.2,4],[1,3.15,17.63],[2,2.84,12.54]],"ltp":3.2,"tv":0.72,"id":12474498}]}]}
{"op":"mcm","clk":"11837264350","pt":1723162269194,"mc":[{"id":"1.231581347","rc":[{"batb":[[0,3.15,17.63],[1,2.84,12.54],[2,2.62,16.72]],"ltp":3.2,"tv":0.72,"id":12474498}]}]}
{"op":"mcm","clk":"11837264510","pt":1723162272998,"mc":[{"id":"1.231581347","rc":[{"batb":[[0,3.2,4],[1,3.15,17.63],[2,2.84,12.54]],"ltp":3.2,"tv":0.72,"id":12474498}]}]}
{"op":"mcm","clk":"11837264611","pt":1723162275412,"mc":[{"id":"1.231581347","rc":[{"batb":[[0,3.15,17.63],[1,2.84,12.54],[2,2.62,16.72]],"ltp":3.2,"tv":0.72,"id":12474498}]}]}
{"op":"mcm","clk":"11837264768","pt":1723162278811,"mc":[{"id":"1.231581347","rc":[{"batb":[[0,3.2,4],[1,3.15,17.63],[2,2.84,12.54]],"ltp":3.2,"tv":0.72,"id":12474498}]}]}
{"op":"mcm","clk":"11837264870","pt":1723162281119,"mc":[{"id":"1.231581347","rc":[{"batb":[[0,3.15,17.63],[1,2.84,12.54],[2,2.62,16.72]],"ltp":3.2,"tv":0.72,"id":12474498}]}]}
{"op":"mcm","clk":"11837264983","pt":1723162283388,"mc":[{"id":"1.231581347","rc":[{"batb":[[0,3.2,4],[1,3.15,17.63],[2,2.84,12.54]],"ltp":3.2,"tv":0.72,"id":12474498}]}]}
{"op":"mcm","clk":"11837265086","pt":1723162285694,"mc":[{"id":"1.231581347","rc":[{"batb":[[0,3.15,17.63],[1,2.84,12.54],[2,2.62,16.72]],"ltp":3.2,"tv":0.72,"id":12474498}]}]}
{"op":"mcm","clk":"11837265200","pt":1723162288316,"mc":[{"id":"1.231581347","rc":[{"batb":[[0,3.2,4],[1,3.15,17.63],[2,2.84,12.54]],"ltp":3.2,"tv":0.72,"id":12474498}]}]}
{"op":"mcm","clk":"11837265307","pt":1723162290728,"mc":[{"id":"1.231581347","rc":[{"batb":[[0,3.15,17.63],[1,2.84,12.54],[2,2.62,16.72]],"ltp":3.2,"tv":0.72,"id":12474498}]}]}
{"op":"mcm","clk":"11837265423","pt":1723162293343,"mc":[{"id":"1.231581347","rc":[{"batb":[[0,3.2,4],[1,3.15,17.63],[2,2.84,12.54]],"ltp":3.2,"tv":0.72,"id":12474498}]}]}
{"op":"mcm","clk":"11837265525","pt":1723162296019,"mc":[{"id":"1.231581347","rc":[{"batb":[[0,3.15,17.63],[1,2.84,12.54],[2,2.62,16.72]],"ltp":3.2,"tv":0.72,"id":12474498}]}]}
{"op":"mcm","clk":"11837265622","pt":1723162298330,"mc":[{"id":"1.231581347","rc":[{"batb":[[0,3.2,4],[1,3.15,17.63],[2,2.84,12.54]],"ltp":3.2,"tv":0.72,"id":12474498}]}]}
{"op":"mcm","clk":"11837265723","pt":1723162300848,"mc":[{"id":"1.231581347","rc":[{"batb":[[0,3.15,17.63],[1,2.84,12.54],[2,2.62,16.72]],"ltp":3.2,"tv":0.72,"id":12474498}]}]}
{"op":"mcm","clk":"11837265840","pt":1723162303219,"mc":[{"id":"1.231581347","rc":[{"batb":[[0,3.2,4],[1,3.15,17.63],[2,2.84,12.54]],"ltp":3.2,"tv":0.72,"id":12474498}]}]}
{"op":"mcm","clk":"11837265932","pt":1723162305528,"mc":[{"id":"1.231581347","rc":[{"batb":[[0,3.15,17.63],[1,2.84,12.54],[2,2.62,16.72]],"ltp":3.2,"tv":0.72,"id":12474498}]}]}
{"op":"mcm","clk":"11837266114","pt":1723162309330,"mc":[{"id":"1.231581347","rc":[{"batb":[[0,3.2,4],[1,3.15,17.63],[2,2.84,12.54]],"ltp":3.2,"tv":0.72,"id":12474498}]}]}
{"op":"mcm","clk":"11837266235","pt":1723162311746,"mc":[{"id":"1.231581347","rc":[{"batb":[[0,3.15,17.63],[1,2.84,12.54],[2,2.62,16.72]],"ltp":3.2,"tv":0.72,"id":12474498}]}]}
{"op":"mcm","clk":"11837266505","pt":1723162317770,"mc":[{"id":"1.231581347","rc":[{"batb":[[0,3.2,4],[1,3.15,17.63],[2,2.84,12.54]],"ltp":3.2,"tv":0.72,"id":12474498}]}]}
{"op":"mcm","clk":"11837266619","pt":1723162320240,"mc":[{"id":"1.231581347","rc":[{"batb":[[0,3.15,17.63],[1,2.84,12.54],[2,2.62,16.72]],"ltp":3.2,"tv":0.72,"id":12474498}]}]}
{"op":"mcm","clk":"11837266786","pt":1723162323750,"mc":[{"id":"1.231581347","rc":[{"batb":[[0,3.2,4],[1,3.15,17.63],[2,2.84,12.54]],"ltp":3.2,"tv":0.72,"id":12474498}]}]}
{"op":"mcm","clk":"11837266902","pt":1723162326066,"mc":[{"id":"1.231581347","rc":[{"batb":[[0,3.15,17.63],[1,2.84,12.54],[2,2.62,16.72]],"ltp":3.2,"tv":0.72,"id":12474498}]}]}
{"op":"mcm","clk":"11837267029","pt":1723162328369,"mc":[{"id":"1.231581347","rc":[{"batb":[[0,3.2,4],[1,3.15,17.63],[2,2.84,12.54]],"ltp":3.2,"tv":0.72,"id":12474498}]}]}
{"op":"mcm","clk":"11837267174","pt":1723162330892,"mc":[{"id":"1.231581347","rc":[{"batb":[[0,3.15,17.63],[1,2.84,12.54],[2,2.62,16.72]],"ltp":3.2,"tv":0.72,"id":12474498}]}]}
{"op":"mcm","clk":"11837267383","pt":1723162335266,"mc":[{"id":"1.231581347","rc":[{"batb":[[0,3.2,4],[1,3.15,17.63],[2,2.84,12.54]],"ltp":3.2,"tv":0.72,"id":12474498}]}]}
{"op":"mcm","clk":"11837267495","pt":1723162337472,"mc":[{"id":"1.231581347","rc":[{"batb":[[0,3.15,17.63],[1,2.84,12.54],[2,2.62,16.72]],"ltp":3.2,"tv":0.72,"id":12474498}]}]}
{"op":"mcm","clk":"11837267622","pt":1723162339956,"mc":[{"id":"1.231581347","rc":[{"batb":[[0,3.2,4],[1,3.15,17.63],[2,2.84,12.54]],"ltp":3.2,"tv":0.72,"id":12474498}]}]}
{"op":"mcm","clk":"11837267736","pt":1723162342168,"mc":[{"id":"1.231581347","rc":[{"batb":[[0,3.15,17.63],[1,2.84,12.54],[2,2.62,16.72]],"ltp":3.2,"tv":0.72,"id":12474498}]}]}
{"op":"mcm","clk":"11837267875","pt":1723162344690,"mc":[{"id":"1.231581347","rc":[{"batb":[[0,3.2,4],[1,3.15,17.63],[2,2.84,12.54]],"ltp":3.2,"tv":0.72,"id":12474498}]}]}
{"op":"mcm","clk":"11837268010","pt":1723162347103,"mc":[{"id":"1.231581347","rc":[{"batb":[[0,3.15,17.63],[1,2.84,12.54],[2,2.62,16.72]],"ltp":3.2,"tv":0.72,"id":12474498}]}]}
{"op":"mcm","clk":"11837268141","pt":1723162349410,"mc":[{"id":"1.231581347","rc":[{"batb":[[0,3.2,4],[1,3.15,17.63],[2,2.84,12.54]],"ltp":3.2,"tv":0.72,"id":12474498}]}]}
{"op":"mcm","clk":"11837268283","pt":1723162351799,"mc":[{"id":"1.231581347","rc":[{"batb":[[0,3.15,17.63],[1,2.84,12.54],[2,2.62,16.72]],"ltp":3.2,"tv":0.72,"id":12474498}]}]}
{"op":"mcm","clk":"11837268495","pt":1723162355194,"mc":[{"id":"1.231581347","rc":[{"batb":[[0,3.2,4],[1,3.15,17.63],[2,2.84,12.54]],"ltp":3.2,"tv":0.72,"id":12474498}]}]}
{"op":"mcm","clk":"11837268605","pt":1723162357607,"mc":[{"id":"1.231581347","rc":[{"batb":[[0,3.15,17.63],[1,2.84,12.54],[2,2.62,16.72]],"ltp":3.2,"tv":0.72,"id":12474498}]}]}
{"op":"mcm","clk":"11837268762","pt":1723162361315,"mc":[{"id":"1.231581347","rc":[{"batb":[[0,3.2,4],[1,3.15,17.63],[2,2.84,12.54]],"ltp":3.2,"tv":0.72,"id":12474498}]}]}
{"op":"mcm","clk":"11837268870","pt":1723162363527,"mc":[{"id":"1.231581347","rc":[{"batb":[[0,3.15,17.63],[1,2.84,12.54],[2,2.62,16.72]],"ltp":3.2,"tv":0.72,"id":12474498}]}]}
{"op":"mcm","clk":"11837269038","pt":1723162367030,"mc":[{"id":"1.231581347","rc":[{"batb":[[0,3.2,4],[1,3.15,17.63],[2,2.84,12.54]],"ltp":3.2,"tv":0.72,"id":12474498}]}]}
{"op":"mcm","clk":"11837269152","pt":1723162369497,"mc":[{"id":"1.231581347","rc":[{"batb":[[0,3.15,17.63],[1,2.84,12.54],[2,2.62,16.72]],"ltp":3.2,"tv":0.72,"id":12474498}]}]}
{"op":"mcm","clk":"11837269285","pt":1723162373138,"mc":[{"id":"1.231581347","rc":[{"batb":[[0,3.2,4],[1,3.15,17.63],[2,2.84,12.54]],"ltp":3.2,"tv":0.72,"id":12474498}]}]}
{"op":"mcm","clk":"11837269360","pt":1723162375519,"mc":[{"id":"1.231581347","rc":[{"batb":[[0,3.15,17.63],[1,2.84,12.54],[2,2.62,16.72]],"ltp":3.2,"tv":0.72,"id":12474498}]}]}
{"op":"mcm","clk":"11837269555","pt":1723162379700,"mc":[{"id":"1.231581347","rc":[{"batb":[[0,3.2,4],[1,3.15,17.63],[2,2.84,12.54]],"ltp":3.2,"tv":0.72,"id":12474498}]}]}
{"op":"mcm","clk":"11837269714","pt":1723162382142,"mc":[{"id":"1.231581347","rc":[{"batb":[[0,3.15,17.63],[1,2.84,12.54],[2,2.62,16.72]],"ltp":3.2,"tv":0.72,"id":12474498}]}]}
{"op":"mcm","clk":"11837269876","pt":1723162385231,"mc":[{"id":"1.231581347","rc":[{"batb":[[0,3.2,4],[1,3.15,17.63],[2,2.84,12.54]],"ltp":3.2,"tv":0.72,"id":12474498}]}]}
{"op":"mcm","clk":"11837270024","pt":1723162387448,"mc":[{"id":"1.231581347","rc":[{"batb":[[0,3.15,17.63],[1,2.84,12.54],[2,2.62,16.72]],"ltp":3.2,"tv":0.72,"id":12474498}]}]}
{"op":"mcm","clk":"11837270282","pt":1723162392627,"mc":[{"id":"1.231581347","rc":[{"batb":[[0,3.2,4],[1,3.15,17.63],[2,2.84,12.54]],"ltp":3.2,"tv":0.72,"id":12474498}]}]}
{"op":"mcm","clk":"11837270384","pt":1723162394934,"mc":[{"id":"1.231581347","rc":[{"batb":[[0,3.15,17.63],[1,2.84,12.54],[2,2.62,16.72]],"ltp":3.2,"tv":0.72,"id":12474498}]}]}
{"op":"mcm","clk":"11837270601","pt":1723162399457,"mc":[{"id":"1.231581347","rc":[{"batb":[[0,3.2,4],[1,3.15,17.63],[2,2.84,12.54]],"ltp":3.2,"tv":0.72,"id":12474498}]}]}
{"op":"mcm","clk":"11837270726","pt":1723162401926,"mc":[{"id":"1.231581347","rc":[{"batb":[[0,3.15,17.63],[1,2.84,12.54],[2,2.62,16.72]],"ltp":3.2,"tv":0.72,"id":12474498}]}]}
{"op":"mcm","clk":"11837270825","pt":1723162404239,"mc":[{"id":"1.231581347","rc":[{"batb":[[0,3.2,4],[1,3.15,17.63],[2,2.84,12.54]],"ltp":3.2,"tv":0.72,"id":12474498}]}]}
{"op":"mcm","clk":"11837270927","pt":1723162406447,"mc":[{"id":"1.231581347","rc":[{"batb":[[0,3.15,17.63],[1,2.84,12.54],[2,2.62,16.72]],"ltp":3.2,"tv":0.72,"id":12474498}]}]}
{"op":"mcm","clk":"11837271093","pt":1723162410343,"mc":[{"id":"1.231581347","rc":[{"batb":[[0,3.2,4],[1,3.15,17.63],[2,2.84,12.54]],"ltp":3.2,"tv":0.72,"id":12474498}]}]}
{"op":"mcm","clk":"11837271192","pt":1723162412759,"mc":[{"id":"1.231581347","rc":[{"batb":[[0,3.15,17.63],[1,2.84,12.54],[2,2.62,16.72]],"ltp":3.2,"tv":0.72,"id":12474498}]}]}
{"op":"mcm","clk":"11837271346","pt":1723162416252,"mc":[{"id":"1.231581347","rc":[{"batb":[[0,3.2,4],[1,3.15,17.63],[2,2.84,12.54]],"ltp":3.2,"tv":0.72,"id":12474498}]}]}
{"op":"mcm","clk":"11837271469","pt":1723162418458,"mc":[{"id":"1.231581347","rc":[{"batb":[[0,3.15,17.63],[1,2.84,12.54],[2,2.62,16.72]],"ltp":3.2,"tv":0.72,"id":12474498}]}]}
{"op":"mcm","clk":"11837271592","pt":1723162421181,"mc":[{"id":"1.231581347","rc":[{"batb":[[0,3.2,4],[1,3.15,17.63],[2,2.84,12.54]],"ltp":3.2,"tv":0.72,"id":12474498}]}]}
{"op":"mcm","clk":"11837271708","pt":1723162423594,"mc":[{"id":"1.231581347","rc":[{"batb":[[0,3.15,17.63],[1,2.84,12.54],[2,2.62,16.72]],"ltp":3.2,"tv":0.72,"id":12474498}]}]}
{"op":"mcm","clk":"11837271816","pt":1723162425957,"mc":[{"id":"1.231581347","rc":[{"batb":[[0,3.2,4],[1,3.15,17.63],[2,2.84,12.54]],"ltp":3.2,"tv":0.72,"id":12474498}]}]}
{"op":"mcm","clk":"11837271930","pt":1723162428371,"mc":[{"id":"1.231581347","rc":[{"batb":[[0,3.15,17.63],[1,2.84,12.54],[2,2.62,16.72]],"ltp":3.2,"tv":0.72,"id":12474498}]}]}
{"op":"mcm","clk":"11837272039","pt":1723162430683,"mc":[{"id":"1.231581347","rc":[{"batb":[[0,3.2,4],[1,3.15,17.63],[2,2.84,12.54]],"ltp":3.2,"tv":0.72,"id":12474498}]}]}
{"op":"mcm","clk":"11837272154","pt":1723162433091,"mc":[{"id":"1.231581347","rc":[{"batb":[[0,3.15,17.63],[1,2.84,12.54],[2,2.62,16.72]],"ltp":3.2,"tv":0.72,"id":12474498}]}]}
{"op":"mcm","clk":"11837272272","pt":1723162435601,"mc":[{"id":"1.231581347","rc":[{"batb":[[0,3.2,4],[1,3.15,17.63],[2,2.84,12.54]],"ltp":3.2,"tv":0.72,"id":12474498}]}]}
{"op":"mcm","clk":"11837272381","pt":1723162438008,"mc":[{"id":"1.231581347","rc":[{"batb":[[0,3.15,17.63],[1,2.84,12.54],[2,2.62,16.72]],"ltp":3.2,"tv":0.72,"id":12474498}]}]}
{"op":"mcm","clk":"11837272479","pt":1723162440417,"mc":[{"id":"1.231581347","rc":[{"batb":[[0,3.2,4],[1,3.15,17.63],[2,2.84,12.54]],"ltp":3.2,"tv":0.72,"id":12474498}]}]}
{"op":"mcm","clk":"11837272593","pt":1723162442891,"mc":[{"id":"1.231581347","rc":[{"batb":[[0,3.15,17.63],[1,2.84,12.54],[2,2.62,16.72]],"ltp":3.2,"tv":0.72,"id":12474498}]}]}
{"op":"mcm","clk":"11837272724","pt":1723162445201,"mc":[{"id":"1.231581347","rc":[{"batb":[[0,3.2,4],[1,3.15,17.63],[2,2.84,12.54]],"ltp":3.2,"tv":0.72,"id":12474498}]}]}
{"op":"mcm","clk":"11837272839","pt":1723162447717,"mc":[{"id":"1.231581347","rc":[{"batb":[[0,3.15,17.63],[1,2.84,12.54],[2,2.62,16.72]],"ltp":3.2,"tv":0.72,"id":12474498}]}]}
{"op":"mcm","clk":"11837273001","pt":1723162451214,"mc":[{"id":"1.231581347","rc":[{"batb":[[0,3.2,4],[1,3.15,17.63],[2,2.84,12.54]],"ltp":3.2,"tv":0.72,"id":12474498}]}]}
{"op":"mcm","clk":"11837273092","pt":1723162453531,"mc":[{"id":"1.231581347","rc":[{"batb":[[0,3.15,17.63],[1,2.84,12.54],[2,2.62,16.72]],"ltp":3.2,"tv":0.72,"id":12474498}]}]}
{"op":"mcm","clk":"11837273276","pt":1723162457528,"mc":[{"id":"1.231581347","rc":[{"batb":[[0,3.2,4],[1,3.15,17.63],[2,2.84,12.54]],"ltp":3.2,"tv":0.72,"id":12474498}]}]}
{"op":"mcm","clk":"11837273406","pt":1723162459948,"mc":[{"id":"1.231581347","rc":[{"batb":[[0,3.15,17.63],[1,2.84,12.54],[2,2.62,16.72]],"ltp":3.2,"tv":0.72,"id":12474498}]}]}
{"op":"mcm","clk":"11837273573","pt":1723162463345,"mc":[{"id":"1.231581347","rc":[{"batb":[[0,3.2,4],[1,3.15,17.63],[2,2.84,12.54]],"ltp":3.2,"tv":0.72,"id":12474498}]}]}
{"op":"mcm","clk":"11837273704","pt":1723162465757,"mc":[{"id":"1.231581347","rc":[{"batb":[[0,3.15,17.63],[1,2.84,12.54],[2,2.62,16.72]],"ltp":3.2,"tv":0.72,"id":12474498}]}]}
{"op":"mcm","clk":"11837273829","pt":1723162468121,"mc":[{"id":"1.231581347","rc":[{"batb":[[0,3.2,4],[1,3.15,17.63],[2,2.84,12.54]],"ltp":3.2,"tv":0.72,"id":12474498}]}]}
{"op":"mcm","clk":"11837273938","pt":1723162470335,"mc":[{"id":"1.231581347","rc":[{"batb":[[0,3.15,17.63],[1,2.84,12.54],[2,2.62,16.72]],"ltp":3.2,"tv":0.72,"id":12474498}]}]}
{"op":"mcm","clk":"11837274174","pt":1723162475328,"mc":[{"id":"1.231581347","rc":[{"batb":[[0,3.2,4],[1,3.15,17.63],[2,2.84,12.54]],"ltp":3.2,"tv":0.72,"id":12474498}]}]}
{"op":"mcm","clk":"11837274301","pt":1723162477850,"mc":[{"id":"1.231581347","rc":[{"batb":[[0,3.15,17.63],[1,2.84,12.54],[2,2.62,16.72]],"ltp":3.2,"tv":0.72,"id":12474498}]}]}
{"op":"mcm","clk":"11837274469","pt":1723162481344,"mc":[{"id":"1.231581347","rc":[{"batb":[[0,3.2,4],[1,3.15,17.63],[2,2.84,12.54]],"ltp":3.2,"tv":0.72,"id":12474498}]}]}
{"op":"mcm","clk":"11837274572","pt":1723162483657,"mc":[{"id":"1.231581347","rc":[{"batb":[[0,3.15,17.63],[1,2.84,12.54],[2,2.62,16.72]],"ltp":3.2,"tv":0.72,"id":12474498}]}]}
{"op":"mcm","clk":"11837274716","pt":1723162487458,"mc":[{"id":"1.231581347","rc":[{"batb":[[0,3.2,4],[1,3.15,17.63],[2,2.84,12.54]],"ltp":3.2,"tv":0.72,"id":12474498}]}]}
{"op":"mcm","clk":"11837274839","pt":1723162489871,"mc":[{"id":"1.231581347","rc":[{"batb":[[0,3.15,17.63],[1,2.84,12.54],[2,2.62,16.72]],"ltp":3.2,"tv":0.72,"id":12474498}]}]}
{"op":"mcm","clk":"11837275184","pt":1723162496957,"mc":[{"id":"1.231581347","rc":[{"batb":[[0,3.2,4],[1,3.15,17.63],[2,2.84,12.54]],"ltp":3.2,"tv":0.72,"id":12474498}]}]}
{"op":"mcm","clk":"11837275284","pt":1723162499474,"mc":[{"id":"1.231581347","rc":[{"batb":[[0,3.15,17.63],[1,2.84,12.54],[2,2.62,16.72]],"ltp":3.2,"tv":0.72,"id":12474498}]}]}
{"op":"mcm","clk":"11837275410","pt":1723162501850,"mc":[{"id":"1.231581347","rc":[{"batb":[[0,3.2,4],[1,3.15,17.63],[2,2.84,12.54]],"ltp":3.2,"tv":0.72,"id":12474498}]}]}
{"op":"mcm","clk":"11837275508","pt":1723162504173,"mc":[{"id":"1.231581347","rc":[{"batb":[[0,3.15,17.63],[1,2.84,12.54],[2,2.62,16.72]],"ltp":3.2,"tv":0.72,"id":12474498}]}]}
{"op":"mcm","clk":"11837275627","pt":1723162506454,"mc":[{"id":"1.231581347","rc":[{"batb":[[0,3.2,4],[1,3.15,17.63],[2,2.84,12.54]],"ltp":3.2,"tv":0.72,"id":12474498}]}]}
{"op":"mcm","clk":"11837275738","pt":1723162508776,"mc":[{"id":"1.231581347","rc":[{"batb":[[0,3.15,17.63],[1,2.84,12.54],[2,2.62,16.72]],"ltp":3.2,"tv":0.72,"id":12474498}]}]}
{"op":"mcm","clk":"11837275865","pt":1723162511249,"mc":[{"id":"1.231581347","rc":[{"batb":[[0,3.2,4],[1,3.15,17.63],[2,2.84,12.54]],"ltp":3.2,"tv":0.72,"id":12474498}]}]}
{"op":"mcm","clk":"11837275967","pt":1723162513674,"mc":[{"id":"1.231581347","rc":[{"batb":[[0,3.15,17.63],[1,2.84,12.54],[2,2.62,16.72]],"ltp":3.2,"tv":0.72,"id":12474498}]}]}
{"op":"mcm","clk":"11837276065","pt":1723162516197,"mc":[{"id":"1.231581347","rc":[{"batb":[[0,3.2,4],[1,3.15,17.63],[2,2.84,12.54]],"ltp":3.2,"tv":0.72,"id":12474498}]}]}
{"op":"mcm","clk":"11837276155","pt":1723162518556,"mc":[{"id":"1.231581347","rc":[{"batb":[[0,3.15,17.63],[1,2.84,12.54],[2,2.62,16.72]],"ltp":3.2,"tv":0.72,"id":12474498}]}]}
{"op":"mcm","clk":"11837276247","pt":1723162520867,"mc":[{"id":"1.231581347","rc":[{"batb":[[0,3.2,4],[1,3.15,17.63],[2,2.84,12.54]],"ltp":3.2,"tv":0.72,"id":12474498}]}]}
{"op":"mcm","clk":"11837276338","pt":1723162523182,"mc":[{"id":"1.231581347","rc":[{"batb":[[0,3.15,17.63],[1,2.84,12.54],[2,2.62,16.72]],"ltp":3.2,"tv":0.72,"id":12474498}]}]}
{"op":"mcm","clk":"11837276448","pt":1723162525598,"mc":[{"id":"1.231581347","rc":[{"batb":[[0,3.2,4],[1,3.15,17.63],[2,2.84,12.54]],"ltp":3.2,"tv":0.72,"id":12474498}]}]}
{"op":"mcm","clk":"11837276549","pt":1723162527807,"mc":[{"id":"1.231581347","rc":[{"batb":[[0,3.15,17.63],[1,2.84,12.54],[2,2.62,16.72]],"ltp":3.2,"tv":0.72,"id":12474498}]}]}
{"op":"mcm","clk":"11837276673","pt":1723162530478,"mc":[{"id":"1.231581347","rc":[{"batb":[[0,3.2,4],[1,3.15,17.63],[2,2.84,12.54]],"ltp":3.2,"tv":0.72,"id":12474498}]}]}
{"op":"mcm","clk":"11837276788","pt":1723162532892,"mc":[{"id":"1.231581347","rc":[{"batb":[[0,3.15,17.63],[1,2.84,12.54],[2,2.62,16.72]],"ltp":3.2,"tv":0.72,"id":12474498}]}]}
{"op":"mcm","clk":"11837276882","pt":1723162535101,"mc":[{"id":"1.231581347","rc":[{"batb":[[0,3.2,4],[1,3.15,17.63],[2,2.84,12.54]],"ltp":3.2,"tv":0.72,"id":12474498}]}]}
{"op":"mcm","clk":"11837277007","pt":1723162537518,"mc":[{"id":"1.231581347","rc":[{"batb":[[0,3.15,17.63],[1,2.84,12.54],[2,2.62,16.72]],"ltp":3.2,"tv":0.72,"id":12474498}]}]}
{"op":"mcm","clk":"11837277167","pt":1723162541017,"mc":[{"id":"1.231581347","rc":[{"batb":[[0,3.2,4],[1,3.15,17.63],[2,2.84,12.54]],"ltp":3.2,"tv":0.72,"id":12474498}]}]}
{"op":"mcm","clk":"11837277267","pt":1723162543323,"mc":[{"id":"1.231581347","rc":[{"batb":[[0,3.15,17.63],[1,2.84,12.54],[2,2.62,16.72]],"ltp":3.2,"tv":0.72,"id":12474498}]}]}
{"op":"mcm","clk":"11837277451","pt":1723162545696,"mc":[{"id":"1.231581347","rc":[{"batb":[[0,3.2,4],[1,3.15,17.63],[2,2.84,12.54]],"ltp":3.2,"tv":0.72,"id":12474498}]}]}
{"op":"mcm","clk":"11837277635","pt":1723162548011,"mc":[{"id":"1.231581347","rc":[{"batb":[[0,3.15,17.63],[1,2.84,12.54],[2,2.62,16.72]],"ltp":3.2,"tv":0.72,"id":12474498}]}]}
{"op":"mcm","clk":"11837277937","pt":1723162551925,"mc":[{"id":"1.231581347","rc":[{"batb":[[0,3.2,4],[1,3.15,17.63],[2,2.84,12.54]],"ltp":3.2,"tv":0.72,"id":12474498}]}]}
{"op":"mcm","clk":"11837278092","pt":1723162554194,"mc":[{"id":"1.231581347","rc":[{"batb":[[0,3.15,17.63],[1,2.84,12.54],[2,2.62,16.72]],"ltp":3.2,"tv":0.72,"id":12474498}]}]}
{"op":"mcm","clk":"11837278191","pt":1723162556505,"mc":[{"id":"1.231581347","rc":[{"batb":[[0,3.2,4],[1,3.15,17.63],[2,2.84,12.54]],"ltp":3.2,"tv":0.72,"id":12474498}]}]}
{"op":"mcm","clk":"11837278308","pt":1723162558922,"mc":[{"id":"1.231581347","rc":[{"batb":[[0,3.15,17.63],[1,2.84,12.54],[2,2.62,16.72]],"ltp":3.2,"tv":0.72,"id":12474498}]}]}
{"op":"mcm","clk":"11837278416","pt":1723162561338,"mc":[{"id":"1.231581347","rc":[{"batb":[[0,3.2,4],[1,3.15,17.63],[2,2.84,12.54]],"ltp":3.2,"tv":0.72,"id":12474498}]}]}
{"op":"mcm","clk":"11837278541","pt":1723162563836,"mc":[{"id":"1.231581347","rc":[{"batb":[[0,3.15,17.63],[1,2.84,12.54],[2,2.62,16.72]],"ltp":3.2,"tv":0.72,"id":12474498}]}]}
{"op":"mcm","clk":"11837278693","pt":1723162567130,"mc":[{"id":"1.231581347","rc":[{"batb":[[0,3.2,4],[1,3.15,17.63],[2,2.84,12.54]],"ltp":3.2,"tv":0.72,"id":12474498}]}]}
{"op":"mcm","clk":"11837278818","pt":1723162569608,"mc":[{"id":"1.231581347","rc":[{"batb":[[0,3.15,17.63],[1,2.84,12.54],[2,2.62,16.72]],"ltp":3.2,"tv":0.72,"id":12474498}]}]}
{"op":"mcm","clk":"11837278921","pt":1723162572126,"mc":[{"id":"1.231581347","rc":[{"batb":[[0,3.2,4],[1,3.15,17.63],[2,2.84,12.54]],"ltp":3.2,"tv":0.72,"id":12474498}]}]}
{"op":"mcm","clk":"11837279015","pt":1723162574436,"mc":[{"id":"1.231581347","rc":[{"batb":[[0,3.15,17.63],[1,2.84,12.54],[2,2.62,16.72]],"ltp":3.2,"tv":0.72,"id":12474498}]}]}
{"op":"mcm","clk":"11837279095","pt":1723162576849,"mc":[{"id":"1.231581347","rc":[{"batb":[[0,3.2,4],[1,3.15,17.63],[2,2.84,12.54]],"ltp":3.2,"tv":0.72,"id":12474498}]}]}
{"op":"mcm","clk":"11837279184","pt":1723162579152,"mc":[{"id":"1.231581347","rc":[{"batb":[[0,3.15,17.63],[1,2.84,12.54],[2,2.62,16.72]],"ltp":3.2,"tv":0.72,"id":12474498}]}]}
{"op":"mcm","clk":"11837279281","pt":1723162581664,"mc":[{"id":"1.231581347","rc":[{"batb":[[0,3.2,4],[1,3.15,17.63],[2,2.84,12.54]],"ltp":3.2,"tv":0.72,"id":12474498}]}]}
{"op":"mcm","clk":"11837279381","pt":1723162584027,"mc":[{"id":"1.231581347","rc":[{"batb":[[0,3.15,17.63],[1,2.84,12.54],[2,2.62,16.72]],"ltp":3.2,"tv":0.72,"id":12474498}]}]}
{"op":"mcm","clk":"11837279550","pt":1723162587942,"mc":[{"id":"1.231581347","rc":[{"batb":[[0,3.2,4],[1,3.15,17.63],[2,2.84,12.54]],"ltp":3.2,"tv":0.72,"id":12474498}]}]}
{"op":"mcm","clk":"11837279632","pt":1723162590250,"mc":[{"id":"1.231581347","rc":[{"batb":[[0,3.15,17.63],[1,2.84,12.54],[2,2.62,16.72]],"ltp":3.2,"tv":0.72,"id":12474498}]}]}
{"op":"mcm","clk":"11837279840","pt":1723162594369,"mc":[{"id":"1.231581347","rc":[{"batb":[[0,3.2,4],[1,3.15,17.63],[2,2.84,12.54]],"ltp":3.2,"tv":0.72,"id":12474498}]}]}
{"op":"mcm","clk":"11837279972","pt":1723162596736,"mc":[{"id":"1.231581347","rc":[{"batb":[[0,3.15,17.63],[1,2.84,12.54],[2,2.62,16.72]],"ltp":3.2,"tv":0.72,"id":12474498}]}]}
{"op":"mcm","clk":"11837280145","pt":1723162599568,"mc":[{"id":"1.231581347","rc":[{"batb":[[0,3.2,4],[1,3.15,17.63],[2,2.84,12.54]],"ltp":3.2,"tv":0.72,"id":12474498}]}]}
{"op":"mcm","clk":"11837280239","pt":1723162602082,"mc":[{"id":"1.231581347","rc":[{"batb":[[0,3.15,17.63],[1,2.84,12.54],[2,2.62,16.72]],"ltp":3.2,"tv":0.72,"id":12474498}]}]}
{"op":"mcm","clk":"11837280422","pt":1723162606660,"mc":[{"id":"1.231581347","rc":[{"batb":[[0,3.2,4],[1,3.15,17.63],[2,2.84,12.54]],"ltp":3.2,"tv":0.72,"id":12474498}]}]}
{"op":"mcm","clk":"11837280527","pt":1723162609080,"mc":[{"id":"1.231581347","rc":[{"batb":[[0,3.15,17.63],[1,2.84,12.54],[2,2.62,16.72]],"ltp":3.2,"tv":0.72,"id":12474498}]}]}
{"op":"mcm","clk":"11837280639","pt":1723162611659,"mc":[{"id":"1.231581347","rc":[{"batb":[[0,3.2,4],[1,3.15,17.63],[2,2.84,12.54]],"ltp":3.2,"tv":0.72,"id":12474498}]}]}
{"op":"mcm","clk":"11837280728","pt":1723162613872,"mc":[{"id":"1.231581347","rc":[{"batb":[[0,3.15,17.63],[1,2.84,12.54],[2,2.62,16.72]],"ltp":3.2,"tv":0.72,"id":12474498}]}]}
{"op":"mcm","clk":"11837280870","pt":1723162617471,"mc":[{"id":"1.231581347","rc":[{"batb":[[0,3.2,4],[1,3.15,17.63],[2,2.84,12.54]],"ltp":3.2,"tv":0.72,"id":12474498}]}]}
{"op":"mcm","clk":"11837280994","pt":1723162619796,"mc":[{"id":"1.231581347","rc":[{"batb":[[0,3.15,17.63],[1,2.84,12.54],[2,2.62,16.72]],"ltp":3.2,"tv":0.72,"id":12474498}]}]}
{"op":"mcm","clk":"11837281308","pt":1723162625996,"mc":[{"id":"1.231581347","rc":[{"batb":[[0,3.2,4],[1,3.15,17.63],[2,2.84,12.54]],"ltp":3.2,"tv":0.72,"id":12474498}]}]}
{"op":"mcm","clk":"11837281416","pt":1723162628309,"mc":[{"id":"1.231581347","rc":[{"batb":[[0,3.15,17.63],[1,2.84,12.54],[2,2.62,16.72]],"ltp":3.2,"tv":0.72,"id":12474498}]}]}
{"op":"mcm","clk":"11837281542","pt":1723162630602,"mc":[{"id":"1.231581347","rc":[{"batb":[[0,3.2,4],[1,3.15,17.63],[2,2.84,12.54]],"ltp":3.2,"tv":0.72,"id":12474498}]}]}
{"op":"mcm","clk":"11837281666","pt":1723162632917,"mc":[{"id":"1.231581347","rc":[{"batb":[[0,3.15,17.63],[1,2.84,12.54],[2,2.62,16.72]],"ltp":3.2,"tv":0.72,"id":12474498}]}]}
{"op":"mcm","clk":"11837281788","pt":1723162636004,"mc":[{"id":"1.231581347","rc":[{"batb":[[0,3.2,4],[1,3.15,17.63],[2,2.84,12.54]],"ltp":3.2,"tv":0.72,"id":12474498}]}]}
{"op":"mcm","clk":"11837281906","pt":1723162638421,"mc":[{"id":"1.231581347","rc":[{"batb":[[0,3.15,17.63],[1,2.84,12.54],[2,2.62,16.72]],"ltp":3.2,"tv":0.72,"id":12474498}]}]}
{"op":"mcm","clk":"11837282010","pt":1723162641139,"mc":[{"id":"1.231581347","rc":[{"batb":[[0,3.2,4],[1,3.15,17.63],[2,2.84,12.54]],"ltp":3.2,"tv":0.72,"id":12474498}]}]}
{"op":"mcm","clk":"11837282104","pt":1723162643506,"mc":[{"id":"1.231581347","rc":[{"batb":[[0,3.15,17.63],[1,2.84,12.54],[2,2.62,16.72]],"ltp":3.2,"tv":0.72,"id":12474498}]}]}
{"op":"mcm","clk":"11837282210","pt":1723162646033,"mc":[{"id":"1.231581347","rc":[{"batb":[[0,3.2,4],[1,3.15,17.63],[2,2.84,12.54]],"ltp":3.2,"tv":0.72,"id":12474498}]}]}
{"op":"mcm","clk":"11837282284","pt":1723162648550,"mc":[{"id":"1.231581347","rc":[{"batb":[[0,3.15,17.63],[1,2.84,12.54],[2,2.62,16.72]],"ltp":3.2,"tv":0.72,"id":12474498}]}]}
{"op":"mcm","clk":"11837282436","pt":1723162652153,"mc":[{"id":"1.231581347","rc":[{"batb":[[0,3.2,4],[1,3.15,17.63],[2,2.84,12.54]],"ltp":3.2,"tv":0.72,"id":12474498}]}]}
{"op":"mcm","clk":"11837282540","pt":1723162654527,"mc":[{"id":"1.231581347","rc":[{"batb":[[0,3.15,17.63],[1,2.84,12.54],[2,2.62,16.72]],"ltp":3.2,"tv":0.72,"id":12474498}]}]}
{"op":"mcm","clk":"11837282652","pt":1723162656844,"mc":[{"id":"1.231581347","rc":[{"batb":[[0,3.2,4],[1,3.15,17.63],[2,2.84,12.54]],"ltp":3.2,"tv":0.72,"id":12474498}]}]}
{"op":"mcm","clk":"11837282760","pt":1723162659241,"mc":[{"id":"1.231581347","rc":[{"batb":[[0,3.15,17.63],[1,2.84,12.54],[2,2.62,16.72]],"ltp":3.2,"tv":0.72,"id":12474498}]}]}
{"op":"mcm","clk":"11837282873","pt":1723162662737,"mc":[{"id":"1.231581347","rc":[{"batb":[[0,3.2,4],[1,3.15,17.63],[2,2.84,12.54]],"ltp":3.2,"tv":0.72,"id":12474498}]}]}
{"op":"mcm","clk":"11837282939","pt":1723162665159,"mc":[{"id":"1.231581347","rc":[{"batb":[[0,3.15,17.63],[1,2.84,12.54],[2,2.62,16.72]],"ltp":3.2,"tv":0.72,"id":12474498}]}]}
{"op":"mcm","clk":"11837283064","pt":1723162668954,"mc":[{"id":"1.231581347","rc":[{"batb":[[0,3.2,4],[1,3.15,17.63],[2,2.84,12.54]],"ltp":3.2,"tv":0.72,"id":12474498}]}]}
{"op":"mcm","clk":"11837283144","pt":1723162671474,"mc":[{"id":"1.231581347","rc":[{"batb":[[0,3.15,17.63],[1,2.84,12.54],[2,2.62,16.72]],"ltp":3.2,"tv":0.72,"id":12474498}]}]}
{"op":"mcm","clk":"11837283229","pt":1723162674959,"mc":[{"id":"1.231581347","rc":[{"batb":[[0,3.2,4],[1,3.15,17.63],[2,2.84,12.54]],"ltp":3.2,"tv":0.72,"id":12474498}]}]}
{"op":"mcm","clk":"11837283285","pt":1723162677163,"mc":[{"id":"1.231581347","rc":[{"batb":[[0,3.15,17.63],[1,2.84,12.54],[2,2.62,16.72]],"ltp":3.2,"tv":0.72,"id":12474498}]}]}
{"op":"mcm","clk":"11837283372","pt":1723162679477,"mc":[{"id":"1.231581347","rc":[{"batb":[[0,3.2,4],[1,3.15,17.63],[2,2.84,12.54]],"ltp":3.2,"tv":0.72,"id":12474498}]}]}
{"op":"mcm","clk":"11837283438","pt":1723162681740,"mc":[{"id":"1.231581347","rc":[{"batb":[[0,3.15,17.63],[1,2.84,12.54],[2,2.62,16.72]],"ltp":3.2,"tv":0.72,"id":12474498}]}]}
{"op":"mcm","clk":"11837283639","pt":1723162688067,"mc":[{"id":"1.231581347","rc":[{"batb":[[0,3.2,4],[1,3.15,17.63],[2,2.84,12.54]],"ltp":3.2,"tv":0.72,"id":12474498}]}]}
{"op":"mcm","clk":"11837283720","pt":1723162690384,"mc":[{"id":"1.231581347","rc":[{"batb":[[0,3.15,17.63],[1,2.84,12.54],[2,2.62,16.72]],"ltp":3.2,"tv":0.72,"id":12474498}]}]}
{"op":"mcm","clk":"11837283919","pt":1723162696393,"mc":[{"id":"1.231581347","rc":[{"batb":[[0,3.2,4],[1,3.15,17.63],[2,2.84,12.54]],"ltp":3.2,"tv":0.72,"id":12474498}]}]}
{"op":"mcm","clk":"11837283995","pt":1723162698909,"mc":[{"id":"1.231581347","rc":[{"batb":[[0,3.15,17.63],[1,2.84,12.54],[2,2.62,16.72]],"ltp":3.2,"tv":0.72,"id":12474498}]}]}
{"op":"mcm","clk":"11837284074","pt":1723162701178,"mc":[{"id":"1.231581347","rc":[{"batb":[[0,3.2,4],[1,3.15,17.63],[2,2.84,12.54]],"ltp":3.2,"tv":0.72,"id":12474498}]}]}
{"op":"mcm","clk":"11837284145","pt":1723162703589,"mc":[{"id":"1.231581347","rc":[{"batb":[[0,3.15,17.63],[1,2.84,12.54],[2,2.62,16.72]],"ltp":3.2,"tv":0.72,"id":12474498}]}]}
{"op":"mcm","clk":"11837284224","pt":1723162706013,"mc":[{"id":"1.231581347","rc":[{"batb":[[0,3.2,4],[1,3.15,17.63],[2,2.84,12.54]],"ltp":3.2,"tv":0.72,"id":12474498}]}]}
{"op":"mcm","clk":"11837284296","pt":1723162708563,"mc":[{"id":"1.231581347","rc":[{"batb":[[0,3.15,17.63],[1,2.84,12.54],[2,2.62,16.72]],"ltp":3.2,"tv":0.72,"id":12474498}]}]}
{"op":"mcm","clk":"11837284364","pt":1723162711026,"mc":[{"id":"1.231581347","rc":[{"batb":[[0,3.2,4],[1,3.15,17.63],[2,2.84,12.54]],"ltp":3.2,"tv":0.72,"id":12474498}]}]}
{"op":"mcm","clk":"11837284442","pt":1723162713492,"mc":[{"id":"1.231581347","rc":[{"batb":[[0,3.15,17.63],[1,2.84,12.54],[2,2.62,16.72]],"ltp":3.2,"tv":0.72,"id":12474498}]}]}
{"op":"mcm","clk":"11837284504","pt":1723162715800,"mc":[{"id":"1.231581347","rc":[{"batb":[[0,3.2,4],[1,3.15,17.63],[2,2.84,12.54]],"ltp":3.2,"tv":0.72,"id":12474498}]}]}
{"op":"mcm","clk":"11837284578","pt":1723162718316,"mc":[{"id":"1.231581347","rc":[{"batb":[[0,3.15,17.63],[1,2.84,12.54],[2,2.62,16.72]],"ltp":3.2,"tv":0.72,"id":12474498}]}]}
{"op":"mcm","clk":"11837284677","pt":1723162721911,"mc":[{"id":"1.231581347","rc":[{"batb":[[0,3.2,4],[1,3.15,17.63],[2,2.84,12.54]],"ltp":3.2,"tv":0.72,"id":12474498}]}]}
{"op":"mcm","clk":"11837284737","pt":1723162724271,"mc":[{"id":"1.231581347","rc":[{"batb":[[0,3.15,17.63],[1,2.84,12.54],[2,2.62,16.72]],"ltp":3.2,"tv":0.72,"id":12474498}]}]}
{"op":"mcm","clk":"11837284882","pt":1723162728741,"mc":[{"id":"1.231581347","rc":[{"batb":[[0,3.2,4],[1,3.15,17.63],[2,2.84,12.54]],"ltp":3.2,"tv":0.72,"id":12474498}]}]}
{"op":"mcm","clk":"11837284947","pt":1723162731154,"mc":[{"id":"1.231581347","rc":[{"batb":[[0,3.15,17.63],[1,2.84,12.54],[2,2.62,16.72]],"ltp":3.2,"tv":0.72,"id":12474498}]}]}
{"op":"mcm","clk":"11837285017","pt":1723162733420,"mc":[{"id":"1.231581347","rc":[{"batb":[[0,3.2,4],[1,3.15,17.63],[2,2.84,12.54]],"ltp":3.2,"tv":0.72,"id":12474498}]}]}
{"op":"mcm","clk":"11837285085","pt":1723162735934,"mc":[{"id":"1.231581347","rc":[{"batb":[[0,3.15,17.63],[1,2.84,12.54],[2,2.62,16.72]],"ltp":3.2,"tv":0.72,"id":12474498}]}]}
{"op":"mcm","clk":"11837285175","pt":1723162739626,"mc":[{"id":"1.231581347","rc":[{"batb":[[0,3.2,4],[1,3.15,17.63],[2,2.84,12.54]],"ltp":3.2,"tv":0.72,"id":12474498}]}]}
{"op":"mcm","clk":"11837285245","pt":1723162742045,"mc":[{"id":"1.231581347","rc":[{"batb":[[0,3.15,17.63],[1,2.84,12.54],[2,2.62,16.72]],"ltp":3.2,"tv":0.72,"id":12474498}]}]}
{"op":"mcm","clk":"11837285446","pt":1723162748056,"mc":[{"id":"1.231581347","rc":[{"batb":[[0,3.2,4],[1,3.15,17.63],[2,2.84,12.54]],"ltp":3.2,"tv":0.72,"id":12474498}]}]}
{"op":"mcm","clk":"11837285532","pt":1723162750626,"mc":[{"id":"1.231581347","rc":[{"batb":[[0,3.15,17.63],[1,2.84,12.54],[2,2.62,16.72]],"ltp":3.2,"tv":0.72,"id":12474498}]}]}
{"op":"mcm","clk":"11837285642","pt":1723162753856,"mc":[{"id":"1.231581347","rc":[{"batb":[[0,3.2,4],[1,3.15,17.63],[2,2.84,12.54]],"ltp":3.2,"tv":0.72,"id":12474498}]}]}
{"op":"mcm","clk":"11837285725","pt":1723162756374,"mc":[{"id":"1.231581347","rc":[{"batb":[[0,3.15,17.63],[1,2.84,12.54],[2,2.62,16.72]],"ltp":3.2,"tv":0.72,"id":12474498}]}]}
{"op":"mcm","clk":"11837285922","pt":1723162760942,"mc":[{"id":"1.231581347","rc":[{"batb":[[0,3.2,4],[1,3.15,17.63],[2,2.84,12.54]],"ltp":3.2,"tv":0.72,"id":12474498}]}]}
{"op":"mcm","clk":"11837286017","pt":1723162763372,"mc":[{"id":"1.231581347","rc":[{"batb":[[0,3.15,17.63],[1,2.84,12.54],[2,2.62,16.72]],"ltp":3.2,"tv":0.72,"id":12474498}]}]}
{"op":"mcm","clk":"11837286128","pt":1723162767069,"mc":[{"id":"1.231581347","rc":[{"batb":[[0,3.2,4],[1,3.15,17.63],[2,2.84,12.54]],"ltp":3.2,"tv":0.72,"id":12474498}]}]}
{"op":"mcm","clk":"11837286201","pt":1723162769686,"mc":[{"id":"1.231581347","rc":[{"batb":[[0,3.15,17.63],[1,2.84,12.54],[2,2.62,16.72]],"ltp":3.2,"tv":0.72,"id":12474498}]}]}
{"op":"mcm","clk":"11837286287","pt":1723162772872,"mc":[{"id":"1.231581347","rc":[{"batb":[[0,3.2,4],[1,3.15,17.63],[2,2.84,12.54]],"ltp":3.2,"tv":0.72,"id":12474498}]}]}
{"op":"mcm","clk":"11837286359","pt":1723162775288,"mc":[{"id":"1.231581347","rc":[{"batb":[[0,3.15,17.63],[1,2.84,12.54],[2,2.62,16.72]],"ltp":3.2,"tv":0.72,"id":12474498}]}]}
{"op":"mcm","clk":"11837286458","pt":1723162778774,"mc":[{"id":"1.231581347","rc":[{"batb":[[0,3.2,4],[1,3.15,17.63],[2,2.84,12.54]],"ltp":3.2,"tv":0.72,"id":12474498}]}]}
{"op":"mcm","clk":"11837286534","pt":1723162781292,"mc":[{"id":"1.231581347","rc":[{"batb":[[0,3.15,17.63],[1,2.84,12.54],[2,2.62,16.72]],"ltp":3.2,"tv":0.72,"id":12474498}]}]}
{"op":"mcm","clk":"11837286589","pt":1723162783500,"mc":[{"id":"1.231581347","rc":[{"batb":[[0,3.2,4],[1,3.15,17.63],[2,2.84,12.54]],"ltp":3.2,"tv":0.72,"id":12474498}]}]}
{"op":"mcm","clk":"11837286673","pt":1723162785863,"mc":[{"id":"1.231581347","rc":[{"batb":[[0,3.15,17.63],[1,2.84,12.54],[2,2.62,16.72]],"ltp":3.2,"tv":0.72,"id":12474498}]}]}
{"op":"mcm","clk":"11837286788","pt":1723162789866,"mc":[{"id":"1.231581347","rc":[{"batb":[[0,3.2,4],[1,3.15,17.63],[2,2.84,12.54]],"ltp":3.2,"tv":0.72,"id":12474498}]}]}
{"op":"mcm","clk":"11837286871","pt":1723162792181,"mc":[{"id":"1.231581347","rc":[{"batb":[[0,3.15,17.63],[1,2.84,12.54],[2,2.62,16.72]],"ltp":3.2,"tv":0.72,"id":12474498}]}]}
{"op":"mcm","clk":"11837286956","pt":1723162794590,"mc":[{"id":"1.231581347","rc":[{"batb":[[0,3.2,4],[1,3.15,17.63],[2,2.84,12.54]],"ltp":3.2,"tv":0.72,"id":12474498}]}]}
{"op":"mcm","clk":"11837287038","pt":1723162797108,"mc":[{"id":"1.231581347","rc":[{"batb":[[0,3.15,17.63],[1,2.84,12.54],[2,2.62,16.72]],"ltp":3.2,"tv":0.72,"id":12474498}]}]}
{"op":"mcm","clk":"11837287110","pt":1723162799778,"mc":[{"id":"1.231581347","rc":[{"batb":[[0,3.2,4],[1,3.15,17.63],[2,2.84,12.54]],"ltp":3.2,"tv":0.72,"id":12474498}]}]}
{"op":"mcm","clk":"11837287205","pt":1723162802194,"mc":[{"id":"1.231581347","rc":[{"batb":[[0,3.15,17.63],[1,2.84,12.54],[2,2.62,16.72]],"ltp":3.2,"tv":0.72,"id":12474498}]}]}
{"op":"mcm","clk":"11837287293","pt":1723162804609,"mc":[{"id":"1.231581347","rc":[{"batb":[[0,3.2,4],[1,3.15,17.63],[2,2.84,12.54]],"ltp":3.2,"tv":0.72,"id":12474498}]}]}
{"op":"mcm","clk":"11837287400","pt":1723162807125,"mc":[{"id":"1.231581347","rc":[{"batb":[[0,3.15,17.63],[1,2.84,12.54],[2,2.62,16.72]],"ltp":3.2,"tv":0.72,"id":12474498}]}]}
{"op":"mcm","clk":"11837287614","pt":1723162812319,"mc":[{"id":"1.231581347","rc":[{"batb":[[0,3.2,4],[1,3.15,17.63],[2,2.84,12.54]],"ltp":3.2,"tv":0.72,"id":12474498}]}]}
{"op":"mcm","clk":"11837287711","pt":1723162814524,"mc":[{"id":"1.231581347","rc":[{"batb":[[0,3.15,17.63],[1,2.84,12.54],[2,2.62,16.72]],"ltp":3.2,"tv":0.72,"id":12474498}]}]}
{"op":"mcm","clk":"11837287810","pt":1723162816939,"mc":[{"id":"1.231581347","rc":[{"batb":[[0,3.2,4],[1,3.15,17.63],[2,2.84,12.54]],"ltp":3.2,"tv":0.72,"id":12474498}]}]}
{"op":"mcm","clk":"11837287902","pt":1723162819198,"mc":[{"id":"1.231581347","rc":[{"batb":[[0,3.15,17.63],[1,2.84,12.54],[2,2.62,16.72]],"ltp":3.2,"tv":0.72,"id":12474498}]}]}
{"op":"mcm","clk":"11837288005","pt":1723162821715,"mc":[{"id":"1.231581347","rc":[{"batb":[[0,3.2,4],[1,3.15,17.63],[2,2.84,12.54]],"ltp":3.2,"tv":0.72,"id":12474498}]}]}
{"op":"mcm","clk":"11837288073","pt":1723162824025,"mc":[{"id":"1.231581347","rc":[{"batb":[[0,3.15,17.63],[1,2.84,12.54],[2,2.62,16.72]],"ltp":3.2,"tv":0.72,"id":12474498}]}]}
{"op":"mcm","clk":"11837288250","pt":1723162828854,"mc":[{"id":"1.231581347","rc":[{"batb":[[0,3.2,4],[1,3.15,17.63],[2,2.84,12.54]],"ltp":3.2,"tv":0.72,"id":12474498}]}]}
{"op":"mcm","clk":"11837288357","pt":1723162831417,"mc":[{"id":"1.231581347","rc":[{"batb":[[0,3.15,17.63],[1,2.84,12.54],[2,2.62,16.72]],"ltp":3.2,"tv":0.72,"id":12474498}]}]}
{"op":"mcm","clk":"11837288441","pt":1723162833627,"mc":[{"id":"1.231581347","rc":[{"batb":[[0,3.2,4],[1,3.15,17.63],[2,2.84,12.54]],"ltp":3.2,"tv":0.72,"id":12474498}]}]}
{"op":"mcm","clk":"11837288530","pt":1723162835838,"mc":[{"id":"1.231581347","rc":[{"batb":[[0,3.15,17.63],[1,2.84,12.54],[2,2.62,16.72]],"ltp":3.2,"tv":0.72,"id":12474498}]}]}
{"op":"mcm","clk":"11837288662","pt":1723162838662,"mc":[{"id":"1.231581347","rc":[{"batb":[[0,3.2,4],[1,3.15,17.63],[2,2.84,12.54]],"ltp":3.2,"tv":0.72,"id":12474498}]}]}
{"op":"mcm","clk":"11837288757","pt":1723162840971,"mc":[{"id":"1.231581347","rc":[{"batb":[[0,3.15,17.63],[1,2.84,12.54],[2,2.62,16.72]],"ltp":3.2,"tv":0.72,"id":12474498}]}]}
{"op":"mcm","clk":"11837288836","pt":1723162843379,"mc":[{"id":"1.231581347","rc":[{"batb":[[0,3.2,4],[1,3.15,17.63],[2,2.84,12.54]],"ltp":3.2,"tv":0.72,"id":12474498}]}]}
{"op":"mcm","clk":"11837288917","pt":1723162845848,"mc":[{"id":"1.231581347","rc":[{"batb":[[0,3.15,17.63],[1,2.84,12.54],[2,2.62,16.72]],"ltp":3.2,"tv":0.72,"id":12474498}]}]}
{"op":"mcm","clk":"11837289015","pt":1723162849093,"mc":[{"id":"1.231581347","rc":[{"batb":[[0,3.2,4],[1,3.15,17.63],[2,2.84,12.54]],"ltp":3.2,"tv":0.72,"id":12474498}]}]}
{"op":"mcm","clk":"11837289086","pt":1723162851487,"mc":[{"id":"1.231581347","rc":[{"batb":[[0,3.15,17.63],[1,2.84,12.54],[2,2.62,16.72]],"ltp":3.2,"tv":0.72,"id":12474498}]}]}
{"op":"mcm","clk":"11837289181","pt":1723162854055,"mc":[{"id":"1.231581347","rc":[{"batb":[[0,3.2,4],[1,3.15,17.63],[2,2.84,12.54]],"ltp":3.2,"tv":0.72,"id":12474498}]}]}
{"op":"mcm","clk":"11837289274","pt":1723162856364,"mc":[{"id":"1.231581347","rc":[{"batb":[[0,3.15,17.63],[1,2.84,12.54],[2,2.62,16.72]],"ltp":3.2,"tv":0.72,"id":12474498}]}]}
{"op":"mcm","clk":"11837289347","pt":1723162858782,"mc":[{"id":"1.231581347","rc":[{"batb":[[0,3.2,4],[1,3.15,17.63],[2,2.84,12.54]],"ltp":3.2,"tv":0.72,"id":12474498}]}]}
{"op":"mcm","clk":"11837289423","pt":1723162861092,"mc":[{"id":"1.231581347","rc":[{"batb":[[0,3.15,17.63],[1,2.84,12.54],[2,2.62,16.72]],"ltp":3.2,"tv":0.72,"id":12474498}]}]}
{"op":"mcm","clk":"11837289511","pt":1723162863465,"mc":[{"id":"1.231581347","rc":[{"batb":[[0,3.2,4],[1,3.15,17.63],[2,2.84,12.54]],"ltp":3.2,"tv":0.72,"id":12474498}]}]}
{"op":"mcm","clk":"11837289602","pt":1723162865979,"mc":[{"id":"1.231581347","rc":[{"batb":[[0,3.15,17.63],[1,2.84,12.54],[2,2.62,16.72]],"ltp":3.2,"tv":0.72,"id":12474498}]}]}
{"op":"mcm","clk":"11837289697","pt":1723162868188,"mc":[{"id":"1.231581347","rc":[{"batb":[[0,3.2,4],[1,3.15,17.63],[2,2.84,12.54]],"ltp":3.2,"tv":0.72,"id":12474498}]}]}
{"op":"mcm","clk":"11837289825","pt":1723162870913,"mc":[{"id":"1.231581347","rc":[{"batb":[[0,3.15,17.63],[1,2.84,12.54],[2,2.62,16.72]],"ltp":3.2,"tv":0.72,"id":12474498}]}]}
{"op":"mcm","clk":"11837289952","pt":1723162874103,"mc":[{"id":"1.231581347","rc":[{"batb":[[0,3.2,4],[1,3.15,17.63],[2,2.84,12.54]],"ltp":3.2,"tv":0.72,"id":12474498}]}]}
{"op":"mcm","clk":"11837290068","pt":1723162876516,"mc":[{"id":"1.231581347","rc":[{"batb":[[0,3.15,17.63],[1,2.84,12.54],[2,2.62,16.72]],"ltp":3.2,"tv":0.72,"id":12474498}]}]}
{"op":"mcm","clk":"11837290233","pt":1723162880115,"mc":[{"id":"1.231581347","rc":[{"batb":[[0,3.2,4],[1,3.15,17.63],[2,2.84,12.54]],"ltp":3.2,"tv":0.72,"id":12474498}]}]}
{"op":"mcm","clk":"11837290320","pt":1723162882632,"mc":[{"id":"1.231581347","rc":[{"batb":[[0,3.15,17.63],[1,2.84,12.54],[2,2.62,16.72]],"ltp":3.2,"tv":0.72,"id":12474498}]}]}
{"op":"mcm","clk":"11837290470","pt":1723162885997,"mc":[{"id":"1.231581347","rc":[{"batb":[[0,3.2,4],[1,3.15,17.63],[2,2.84,12.54]],"ltp":3.2,"tv":0.72,"id":12474498}]}]}
{"op":"mcm","clk":"11837290571","pt":1723162888521,"mc":[{"id":"1.231581347","rc":[{"batb":[[0,3.15,17.63],[1,2.84,12.54],[2,2.62,16.72]],"ltp":3.2,"tv":0.72,"id":12474498}]}]}
{"op":"mcm","clk":"11837290709","pt":1723162891809,"mc":[{"id":"1.231581347","rc":[{"batb":[[0,3.2,4],[1,3.15,17.63],[2,2.84,12.54]],"ltp":3.2,"tv":0.72,"id":12474498}]}]}
{"op":"mcm","clk":"11837290808","pt":1723162894221,"mc":[{"id":"1.231581347","rc":[{"batb":[[0,3.15,17.63],[1,2.84,12.54],[2,2.62,16.72]],"ltp":3.2,"tv":0.72,"id":12474498}]}]}
{"op":"mcm","clk":"11837290940","pt":1723162896742,"mc":[{"id":"1.231581347","rc":[{"batb":[[0,3.2,4],[1,3.15,17.63],[2,2.84,12.54]],"ltp":3.2,"tv":0.72,"id":12474498}]}]}
{"op":"mcm","clk":"11837291057","pt":1723162899308,"mc":[{"id":"1.231581347","rc":[{"batb":[[0,3.15,17.63],[1,2.84,12.54],[2,2.62,16.72]],"ltp":3.2,"tv":0.72,"id":12474498}]}]}
{"op":"mcm","clk":"11837291216","pt":1723162902750,"mc":[{"id":"1.231581347","rc":[{"batb":[[0,3.2,4],[1,3.15,17.63],[2,2.84,12.54]],"ltp":3.2,"tv":0.72,"id":12474498}]}]}
{"op":"mcm","clk":"11837291305","pt":1723162905522,"mc":[{"id":"1.231581347","rc":[{"batb":[[0,3.15,17.63],[1,2.84,12.54],[2,2.62,16.72]],"ltp":3.2,"tv":0.72,"id":12474498}]}]}
{"op":"mcm","clk":"11837291444","pt":1723162908962,"mc":[{"id":"1.231581347","rc":[{"batb":[[0,3.2,4],[1,3.15,17.63],[2,2.84,12.54]],"ltp":3.2,"tv":0.72,"id":12474498}]}]}
{"op":"mcm","clk":"11837291545","pt":1723162911630,"mc":[{"id":"1.231581347","rc":[{"batb":[[0,3.15,17.63],[1,2.84,12.54],[2,2.62,16.72]],"ltp":3.2,"tv":0.72,"id":12474498}]}]}
{"op":"mcm","clk":"11837291656","pt":1723162914859,"mc":[{"id":"1.231581347","rc":[{"batb":[[0,3.2,4],[1,3.15,17.63],[2,2.84,12.54]],"ltp":3.2,"tv":0.72,"id":12474498}]}]}
{"op":"mcm","clk":"11837291746","pt":1723162917270,"mc":[{"id":"1.231581347","rc":[{"batb":[[0,3.15,17.63],[1,2.84,12.54],[2,2.62,16.72]],"ltp":3.2,"tv":0.72,"id":12474498}]}]}
{"op":"mcm","clk":"11837291829","pt":1723162919678,"mc":[{"id":"1.231581347","rc":[{"batb":[[0,3.2,4],[1,3.15,17.63],[2,2.84,12.54]],"ltp":3.2,"tv":0.72,"id":12474498}]}]}
{"op":"mcm","clk":"11837291909","pt":1723162921942,"mc":[{"id":"1.231581347","rc":[{"batb":[[0,3.15,17.63],[1,2.84,12.54],[2,2.62,16.72]],"ltp":3.2,"tv":0.72,"id":12474498}]}]}
{"op":"mcm","clk":"11837292148","pt":1723162926869,"mc":[{"id":"1.231581347","rc":[{"batb":[[0,3.2,4],[1,3.15,17.63],[2,2.84,12.54]],"ltp":3.2,"tv":0.72,"id":12474498}]}]}
{"op":"mcm","clk":"11837292228","pt":1723162929283,"mc":[{"id":"1.231581347","rc":[{"batb":[[0,3.15,17.63],[1,2.84,12.54],[2,2.62,16.72]],"ltp":3.2,"tv":0.72,"id":12474498}]}]}
{"op":"mcm","clk":"11837292345","pt":1723162932774,"mc":[{"id":"1.231581347","rc":[{"batb":[[0,3.2,4],[1,3.15,17.63],[2,2.84,12.54]],"ltp":3.2,"tv":0.72,"id":12474498}]}]}
{"op":"mcm","clk":"11837292421","pt":1723162935189,"mc":[{"id":"1.231581347","rc":[{"batb":[[0,3.15,17.63],[1,2.84,12.54],[2,2.62,16.72]],"ltp":3.2,"tv":0.72,"id":12474498}]}]}
{"op":"mcm","clk":"11837292537","pt":1723162938885,"mc":[{"id":"1.231581347","rc":[{"batb":[[0,3.2,4],[1,3.15,17.63],[2,2.84,12.54]],"ltp":3.2,"tv":0.72,"id":12474498}]}]}
{"op":"mcm","clk":"11837292607","pt":1723162941303,"mc":[{"id":"1.231581347","rc":[{"batb":[[0,3.15,17.63],[1,2.84,12.54],[2,2.62,16.72]],"ltp":3.2,"tv":0.72,"id":12474498}]}]}
{"op":"mcm","clk":"11837292770","pt":1723162945972,"mc":[{"id":"1.231581347","rc":[{"batb":[[0,3.2,4],[1,3.15,17.63],[2,2.84,12.54]],"ltp":3.2,"tv":0.72,"id":12474498}]}]}
{"op":"mcm","clk":"11837292851","pt":1723162948385,"mc":[{"id":"1.231581347","rc":[{"batb":[[0,3.15,17.63],[1,2.84,12.54],[2,2.62,16.72]],"ltp":3.2,"tv":0.72,"id":12474498}]}]}
{"op":"mcm","clk":"11837292955","pt":1723162951777,"mc":[{"id":"1.231581347","rc":[{"batb":[[0,3.2,4],[1,3.15,17.63],[2,2.84,12.54]],"ltp":3.2,"tv":0.72,"id":12474498}]}]}
{"op":"mcm","clk":"11837293044","pt":1723162954496,"mc":[{"id":"1.231581347","rc":[{"batb":[[0,3.15,17.63],[1,2.84,12.54],[2,2.62,16.72]],"ltp":3.2,"tv":0.72,"id":12474498}]}]}
{"op":"mcm","clk":"11837293124","pt":1723162956706,"mc":[{"id":"1.231581347","rc":[{"batb":[[0,3.2,4],[1,3.15,17.63],[2,2.84,12.54]],"ltp":3.2,"tv":0.72,"id":12474498}]}]}
{"op":"mcm","clk":"11837293201","pt":1723162958911,"mc":[{"id":"1.231581347","rc":[{"batb":[[0,3.15,17.63],[1,2.84,12.54],[2,2.62,16.72]],"ltp":3.2,"tv":0.72,"id":12474498}]}]}
{"op":"mcm","clk":"11837293362","pt":1723162963232,"mc":[{"id":"1.231581347","rc":[{"batb":[[0,3.2,4],[1,3.15,17.63],[2,2.84,12.54]],"ltp":3.2,"tv":0.72,"id":12474498}]}]}
{"op":"mcm","clk":"11837293446","pt":1723162965594,"mc":[{"id":"1.231581347","rc":[{"batb":[[0,3.15,17.63],[1,2.84,12.54],[2,2.62,16.72]],"ltp":3.2,"tv":0.72,"id":12474498}]}]}
{"op":"mcm","clk":"11837293577","pt":1723162968929,"mc":[{"id":"1.231581347","rc":[{"batb":[[0,3.2,4],[1,3.15,17.63],[2,2.84,12.54]],"ltp":3.2,"tv":0.72,"id":12474498}]}]}
{"op":"mcm","clk":"11837293671","pt":1723162971294,"mc":[{"id":"1.231581347","rc":[{"batb":[[0,3.15,17.63],[1,2.84,12.54],[2,2.62,16.72]],"ltp":3.2,"tv":0.72,"id":12474498}]}]}
{"op":"mcm","clk":"11837293784","pt":1723162974932,"mc":[{"id":"1.231581347","rc":[{"batb":[[0,3.2,4],[1,3.15,17.63],[2,2.84,12.54]],"ltp":3.2,"tv":0.72,"id":12474498}]}]}
{"op":"mcm","clk":"11837293876","pt":1723162977243,"mc":[{"id":"1.231581347","rc":[{"batb":[[0,3.15,17.63],[1,2.84,12.54],[2,2.62,16.72]],"ltp":3.2,"tv":0.72,"id":12474498}]}]}
{"op":"mcm","clk":"11837293981","pt":1723162979615,"mc":[{"id":"1.231581347","rc":[{"batb":[[0,3.2,4],[1,3.15,17.63],[2,2.84,12.54]],"ltp":3.2,"tv":0.72,"id":12474498}]}]}
{"op":"mcm","clk":"11837294123","pt":1723162982209,"mc":[{"id":"1.231581347","rc":[{"batb":[[0,3.15,17.63],[1,2.84,12.54],[2,2.62,16.72]],"ltp":3.2,"tv":0.72,"id":12474498}]}]}
{"op":"mcm","clk":"11837294254","pt":1723162985146,"mc":[{"id":"1.231581347","rc":[{"batb":[[0,3.2,4],[1,3.15,17.63],[2,2.84,12.54]],"ltp":3.2,"tv":0.72,"id":12474498}]}]}
{"op":"mcm","clk":"11837294375","pt":1723162987668,"mc":[{"id":"1.231581347","rc":[{"batb":[[0,3.15,17.63],[1,2.84,12.54],[2,2.62,16.72]],"ltp":3.2,"tv":0.72,"id":12474498}]}]}
{"op":"mcm","clk":"11837294551","pt":1723162991434,"mc":[{"id":"1.231581347","rc":[{"batb":[[0,3.2,4],[1,3.15,17.63],[2,2.84,12.54]],"ltp":3.2,"tv":0.72,"id":12474498}]}]}
{"op":"mcm","clk":"11837294652","pt":1723162993741,"mc":[{"id":"1.231581347","rc":[{"batb":[[0,3.15,17.63],[1,2.84,12.54],[2,2.62,16.72]],"ltp":3.2,"tv":0.72,"id":12474498}]}]}
{"op":"mcm","clk":"11837294754","pt":1723162996261,"mc":[{"id":"1.231581347","rc":[{"batb":[[0,3.2,4],[1,3.15,17.63],[2,2.84,12.54]],"ltp":3.2,"tv":0.72,"id":12474498}]}]}
{"op":"mcm","clk":"11837294873","pt":1723162998728,"mc":[{"id":"1.231581347","rc":[{"batb":[[0,3.15,17.63],[1,2.84,12.54],[2,2.62,16.72]],"ltp":3.2,"tv":0.72,"id":12474498}]}]}
{"op":"mcm","clk":"11837295035","pt":1723163002059,"mc":[{"id":"1.231581347","rc":[{"batb":[[0,3.2,4],[1,3.15,17.63],[2,2.84,12.54]],"ltp":3.2,"tv":0.72,"id":12474498}]}]}
{"op":"mcm","clk":"11837295151","pt":1723163004377,"mc":[{"id":"1.231581347","rc":[{"batb":[[0,3.15,17.63],[1,2.84,12.54],[2,2.62,16.72]],"ltp":3.2,"tv":0.72,"id":12474498}]}]}
{"op":"mcm","clk":"11837295269","pt":1723163006947,"mc":[{"id":"1.231581347","rc":[{"batb":[[0,3.2,4],[1,3.15,17.63],[2,2.84,12.54]],"ltp":3.2,"tv":0.72,"id":12474498}]}]}
{"op":"mcm","clk":"11837295372","pt":1723163009360,"mc":[{"id":"1.231581347","rc":[{"batb":[[0,3.15,17.63],[1,2.84,12.54],[2,2.62,16.72]],"ltp":3.2,"tv":0.72,"id":12474498}]}]}
{"op":"mcm","clk":"11837295456","pt":1723163011569,"mc":[{"id":"1.231581347","rc":[{"batb":[[0,3.2,4],[1,3.15,17.63],[2,2.84,12.54]],"ltp":3.2,"tv":0.72,"id":12474498}]}]}
{"op":"mcm","clk":"11837295539","pt":1723163013874,"mc":[{"id":"1.231581347","rc":[{"batb":[[0,3.15,17.63],[1,2.84,12.54],[2,2.62,16.72]],"ltp":3.2,"tv":0.72,"id":12474498}]}]}
{"op":"mcm","clk":"11837295643","pt":1723163016286,"mc":[{"id":"1.231581347","rc":[{"batb":[[0,3.2,4],[1,3.15,17.63],[2,2.84,12.54]],"ltp":3.2,"tv":0.72,"id":12474498}]}]}
{"op":"mcm","clk":"11837295764","pt":1723163018651,"mc":[{"id":"1.231581347","rc":[{"batb":[[0,3.15,17.63],[1,2.84,12.54],[2,2.62,16.72]],"ltp":3.2,"tv":0.72,"id":12474498}]}]}
{"op":"mcm","clk":"11837295973","pt":1723163023580,"mc":[{"id":"1.231581347","rc":[{"batb":[[0,3.2,4],[1,3.15,17.63],[2,2.84,12.54]],"ltp":3.2,"tv":0.72,"id":12474498}]}]}
{"op":"mcm","clk":"11837296101","pt":1723163026003,"mc":[{"id":"1.231581347","rc":[{"batb":[[0,3.15,17.63],[1,2.84,12.54],[2,2.62,16.72]],"ltp":3.2,"tv":0.72,"id":12474498}]}]}
{"op":"mcm","clk":"11837296302","pt":1723163029605,"mc":[{"id":"1.231581347","rc":[{"batb":[[0,3.2,4],[1,3.15,17.63],[2,2.84,12.54]],"ltp":3.2,"tv":0.72,"id":12474498}]}]}
{"op":"mcm","clk":"11837296453","pt":1723163032279,"mc":[{"id":"1.231581347","rc":[{"batb":[[0,3.15,17.63],[1,2.84,12.54],[2,2.62,16.72]],"ltp":3.2,"tv":0.72,"id":12474498}]}]}
{"op":"mcm","clk":"11837296600","pt":1723163035511,"mc":[{"id":"1.231581347","rc":[{"batb":[[0,3.2,4],[1,3.15,17.63],[2,2.84,12.54]],"ltp":3.2,"tv":0.72,"id":12474498}]}]}
{"op":"mcm","clk":"11837296717","pt":1723163038080,"mc":[{"id":"1.231581347","rc":[{"batb":[[0,3.15,17.63],[1,2.84,12.54],[2,2.62,16.72]],"ltp":3.2,"tv":0.72,"id":12474498}]}]}
{"op":"mcm","clk":"11837296890","pt":1723163041373,"mc":[{"id":"1.231581347","rc":[{"batb":[[0,3.2,4],[1,3.15,17.63],[2,2.84,12.54]],"ltp":3.2,"tv":0.72,"id":12474498}]}]}
{"op":"mcm","clk":"11837297007","pt":1723163043890,"mc":[{"id":"1.231581347","rc":[{"batb":[[0,3.15,17.63],[1,2.84,12.54],[2,2.62,16.72]],"ltp":3.2,"tv":0.72,"id":12474498}]}]}
{"op":"mcm","clk":"11837297150","pt":1723163047295,"mc":[{"id":"1.231581347","rc":[{"batb":[[0,3.2,4],[1,3.15,17.63],[2,2.84,12.54]],"ltp":3.2,"tv":0.72,"id":12474498}]}]}
{"op":"mcm","clk":"11837297286","pt":1723163050074,"mc":[{"id":"1.231581347","rc":[{"batb":[[0,3.15,17.63],[1,2.84,12.54],[2,2.62,16.72]],"ltp":3.2,"tv":0.72,"id":12474498}]}]}
{"op":"mcm","clk":"11837297414","pt":1723163052795,"mc":[{"id":"1.231581347","rc":[{"batb":[[0,3.2,4],[1,3.15,17.63],[2,2.84,12.54]],"ltp":3.2,"tv":0.72,"id":12474498}]}]}
{"op":"mcm","clk":"11837297502","pt":1723163055211,"mc":[{"id":"1.231581347","rc":[{"batb":[[0,3.15,17.63],[1,2.84,12.54],[2,2.62,16.72]],"ltp":3.2,"tv":0.72,"id":12474498}]}]}
{"op":"mcm","clk":"11837297722","pt":1723163060007,"mc":[{"id":"1.231581347","rc":[{"batb":[[0,3.2,4],[1,3.15,17.63],[2,2.84,12.54]],"ltp":3.2,"tv":0.72,"id":12474498}]}]}
{"op":"mcm","clk":"11837297839","pt":1723163062323,"mc":[{"id":"1.231581347","rc":[{"batb":[[0,3.15,17.63],[1,2.84,12.54],[2,2.62,16.72]],"ltp":3.2,"tv":0.72,"id":12474498}]}]}
{"op":"mcm","clk":"11837297938","pt":1723163064600,"mc":[{"id":"1.231581347","rc":[{"batb":[[0,3.2,4],[1,3.15,17.63],[2,2.84,12.54]],"ltp":3.2,"tv":0.72,"id":12474498}]}]}
{"op":"mcm","clk":"11837298051","pt":1723163066910,"mc":[{"id":"1.231581347","rc":[{"batb":[[0,3.15,17.63],[1,2.84,12.54],[2,2.62,16.72]],"ltp":3.2,"tv":0.72,"id":12474498}]}]}
{"op":"mcm","clk":"11837298253","pt":1723163071416,"mc":[{"id":"1.231581347","rc":[{"batb":[[0,3.2,4],[1,3.15,17.63],[2,2.84,12.54]],"ltp":3.2,"tv":0.72,"id":12474498}]}]}
{"op":"mcm","clk":"11837298360","pt":1723163073837,"mc":[{"id":"1.231581347","rc":[{"batb":[[0,3.15,17.63],[1,2.84,12.54],[2,2.62,16.72]],"ltp":3.2,"tv":0.72,"id":12474498}]}]}
{"op":"mcm","clk":"11837298546","pt":1723163078462,"mc":[{"id":"1.231581347","rc":[{"batb":[[0,3.2,4],[1,3.15,17.63],[2,2.84,12.54]],"ltp":3.2,"tv":0.72,"id":12474498}]}]}
{"op":"mcm","clk":"11837298651","pt":1723163080832,"mc":[{"id":"1.231581347","rc":[{"batb":[[0,3.15,17.63],[1,2.84,12.54],[2,2.62,16.72]],"ltp":3.2,"tv":0.72,"id":12474498}]}]}
{"op":"mcm","clk":"11837298793","pt":1723163084427,"mc":[{"id":"1.231581347","rc":[{"batb":[[0,3.2,4],[1,3.15,17.63],[2,2.84,12.54]],"ltp":3.2,"tv":0.72,"id":12474498}]}]}
{"op":"mcm","clk":"11837298884","pt":1723163086944,"mc":[{"id":"1.231581347","rc":[{"batb":[[0,3.15,17.63],[1,2.84,12.54],[2,2.62,16.72]],"ltp":3.2,"tv":0.72,"id":12474498}]}]}
{"op":"mcm","clk":"11837299017","pt":1723163090334,"mc":[{"id":"1.231581347","rc":[{"batb":[[0,3.2,4],[1,3.15,17.63],[2,2.84,12.54]],"ltp":3.2,"tv":0.72,"id":12474498}]}]}
{"op":"mcm","clk":"11837299097","pt":1723163092755,"mc":[{"id":"1.231581347","rc":[{"batb":[[0,3.15,17.63],[1,2.84,12.54],[2,2.62,16.72]],"ltp":3.2,"tv":0.72,"id":12474498}]}]}
{"op":"mcm","clk":"11837299227","pt":1723163096262,"mc":[{"id":"1.231581347","rc":[{"batb":[[0,3.2,4],[1,3.15,17.63],[2,2.84,12.54]],"ltp":3.2,"tv":0.72,"id":12474498}]}]}
{"op":"mcm","clk":"11837299333","pt":1723163098773,"mc":[{"id":"1.231581347","rc":[{"batb":[[0,3.15,17.63],[1,2.84,12.54],[2,2.62,16.72]],"ltp":3.2,"tv":0.72,"id":12474498}]}]}
{"op":"mcm","clk":"11837299423","pt":1723163100942,"mc":[{"id":"1.231581347","rc":[{"batb":[[0,3.2,4],[1,3.15,17.63],[2,2.84,12.54]],"ltp":3.2,"tv":0.72,"id":12474498}]}]}
{"op":"mcm","clk":"11837299512","pt":1723163103372,"mc":[{"id":"1.231581347","rc":[{"batb":[[0,3.15,17.63],[1,2.84,12.54],[2,2.62,16.72]],"ltp":3.2,"tv":0.72,"id":12474498}]}]}
{"op":"mcm","clk":"11837299664","pt":1723163106974,"mc":[{"id":"1.231581347","rc":[{"batb":[[0,3.2,4],[1,3.15,17.63],[2,2.84,12.54]],"ltp":3.2,"tv":0.72,"id":12474498}]}]}
{"op":"mcm","clk":"11837299760","pt":1723163109451,"mc":[{"id":"1.231581347","rc":[{"batb":[[0,3.15,17.63],[1,2.84,12.54],[2,2.62,16.72]],"ltp":3.2,"tv":0.72,"id":12474498}]}]}
{"op":"mcm","clk":"11837299869","pt":1723163111773,"mc":[{"id":"1.231581347","rc":[{"batb":[[0,3.2,4],[1,3.15,17.63],[2,2.84,12.54]],"ltp":3.2,"tv":0.72,"id":12474498}]}]}
{"op":"mcm","clk":"11837299980","pt":1723163114290,"mc":[{"id":"1.231581347","rc":[{"batb":[[0,3.15,17.63],[1,2.84,12.54],[2,2.62,16.72]],"ltp":3.2,"tv":0.72,"id":12474498}]}]}
{"op":"mcm","clk":"11837300112","pt":1723163117592,"mc":[{"id":"1.231581347","rc":[{"batb":[[0,3.2,4],[1,3.15,17.63],[2,2.84,12.54]],"ltp":3.2,"tv":0.72,"id":12474498}]}]}
{"op":"mcm","clk":"11837300217","pt":1723163119960,"mc":[{"id":"1.231581347","rc":[{"batb":[[0,3.15,17.63],[1,2.84,12.54],[2,2.62,16.72]],"ltp":3.2,"tv":0.72,"id":12474498}]}]}
{"op":"mcm","clk":"11837300354","pt":1723163122388,"mc":[{"id":"1.231581347","rc":[{"batb":[[0,3.2,4],[1,3.15,17.63],[2,2.84,12.54]],"ltp":3.2,"tv":0.72,"id":12474498}]}]}
{"op":"mcm","clk":"11837300464","pt":1723163124898,"mc":[{"id":"1.231581347","rc":[{"batb":[[0,3.15,17.63],[1,2.84,12.54],[2,2.62,16.72]],"ltp":3.2,"tv":0.72,"id":12474498}]}]}
{"op":"mcm","clk":"11837300569","pt":1723163127415,"mc":[{"id":"1.231581347","rc":[{"batb":[[0,3.2,4],[1,3.15,17.63],[2,2.84,12.54]],"ltp":3.2,"tv":0.72,"id":12474498}]}]}
{"op":"mcm","clk":"11837300679","pt":1723163129580,"mc":[{"id":"1.231581347","rc":[{"batb":[[0,3.15,17.63],[1,2.84,12.54],[2,2.62,16.72]],"ltp":3.2,"tv":0.72,"id":12474498}]}]}
{"op":"mcm","clk":"11837300797","pt":1723163132401,"mc":[{"id":"1.231581347","rc":[{"batb":[[0,3.2,4],[1,3.15,17.63],[2,2.84,12.54]],"ltp":3.2,"tv":0.72,"id":12474498}]}]}
{"op":"mcm","clk":"11837301256","pt":1723163134969,"mc":[{"id":"1.231581347","rc":[{"batb":[[0,3.15,17.63],[1,2.84,12.54],[2,2.62,16.72]],"ltp":3.2,"tv":0.72,"id":12474498}]}]}
{"op":"mcm","clk":"11837301528","pt":1723163138144,"mc":[{"id":"1.231581347","rc":[{"batb":[[0,3.2,4],[1,3.15,17.63],[2,2.84,12.54]],"ltp":3.2,"tv":0.72,"id":12474498}]}]}
{"op":"mcm","clk":"11837301629","pt":1723163140316,"mc":[{"id":"1.231581347","rc":[{"batb":[[0,3.15,17.63],[1,2.84,12.54],[2,2.62,16.72]],"ltp":3.2,"tv":0.72,"id":12474498}]}]}
{"op":"mcm","clk":"11837301768","pt":1723163142939,"mc":[{"id":"1.231581347","rc":[{"batb":[[0,3.2,4],[1,3.15,17.63],[2,2.84,12.54]],"ltp":3.2,"tv":0.72,"id":12474498}]}]}
{"op":"mcm","clk":"11837301870","pt":1723163145253,"mc":[{"id":"1.231581347","rc":[{"batb":[[0,3.15,17.63],[1,2.84,12.54],[2,2.62,16.72]],"ltp":3.2,"tv":0.72,"id":12474498}]}]}
{"op":"mcm","clk":"11837301983","pt":1723163147928,"mc":[{"id":"1.231581347","rc":[{"batb":[[0,3.2,4],[1,3.15,17.63],[2,2.84,12.54]],"ltp":3.2,"tv":0.72,"id":12474498}]}]}
{"op":"mcm","clk":"11837302074","pt":1723163150340,"mc":[{"id":"1.231581347","rc":[{"batb":[[0,3.15,17.63],[1,2.84,12.54],[2,2.62,16.72]],"ltp":3.2,"tv":0.72,"id":12474498}]}]}
{"op":"mcm","clk":"11837302224","pt":1723163153933,"mc":[{"id":"1.231581347","rc":[{"batb":[[0,3.2,4],[1,3.15,17.63],[2,2.84,12.54]],"ltp":3.2,"tv":0.72,"id":12474498}]}]}
{"op":"mcm","clk":"11837302326","pt":1723163156347,"mc":[{"id":"1.231581347","rc":[{"batb":[[0,3.15,17.63],[1,2.84,12.54],[2,2.62,16.72]],"ltp":3.2,"tv":0.72,"id":12474498}]}]}
{"op":"mcm","clk":"11837302603","pt":1723163162565,"mc":[{"id":"1.231581347","rc":[{"batb":[[0,3.2,4],[1,3.15,17.63],[2,2.84,12.54]],"ltp":3.2,"tv":0.72,"id":12474498}]}]}
{"op":"mcm","clk":"11837302686","pt":1723163164871,"mc":[{"id":"1.231581347","rc":[{"batb":[[0,3.15,17.63],[1,2.84,12.54],[2,2.62,16.72]],"ltp":3.2,"tv":0.72,"id":12474498}]}]}
{"op":"mcm","clk":"11837302862","pt":1723163168471,"mc":[{"id":"1.231581347","rc":[{"batb":[[0,3.2,4],[1,3.15,17.63],[2,2.84,12.54]],"ltp":3.2,"tv":0.72,"id":12474498}]}]}
{"op":"mcm","clk":"11837302981","pt":1723163170786,"mc":[{"id":"1.231581347","rc":[{"batb":[[0,3.15,17.63],[1,2.84,12.54],[2,2.62,16.72]],"ltp":3.2,"tv":0.72,"id":12474498}]}]}
{"op":"mcm","clk":"11837303074","pt":1723163173254,"mc":[{"id":"1.231581347","rc":[{"batb":[[0,3.2,4],[1,3.15,17.63],[2,2.84,12.54]],"ltp":3.2,"tv":0.72,"id":12474498}]}]}
{"op":"mcm","clk":"11837303178","pt":1723163175573,"mc":[{"id":"1.231581347","rc":[{"batb":[[0,3.15,17.63],[1,2.84,12.54],[2,2.62,16.72]],"ltp":3.2,"tv":0.72,"id":12474498}]}]}
{"op":"mcm","clk":"11837303459","pt":1723163181867,"mc":[{"id":"1.231581347","rc":[{"batb":[[0,3.2,4],[1,3.15,17.63],[2,2.84,12.54]],"ltp":3.2,"tv":0.72,"id":12474498}]}]}
{"op":"mcm","clk":"11837303584","pt":1723163184275,"mc":[{"id":"1.231581347","rc":[{"batb":[[0,3.15,17.63],[1,2.84,12.54],[2,2.62,16.72]],"ltp":3.2,"tv":0.72,"id":12474498}]}]}
{"op":"mcm","clk":"11837303774","pt":1723163187988,"mc":[{"id":"1.231581347","rc":[{"batb":[[0,3.2,4],[1,3.15,17.63],[2,2.84,12.54]],"ltp":3.2,"tv":0.72,"id":12474498}]}]}
{"op":"mcm","clk":"11837303881","pt":1723163190509,"mc":[{"id":"1.231581347","rc":[{"batb":[[0,3.15,17.63],[1,2.84,12.54],[2,2.62,16.72]],"ltp":3.2,"tv":0.72,"id":12474498}]}]}
{"op":"mcm","clk":"11837304029","pt":1723163194012,"mc":[{"id":"1.231581347","rc":[{"batb":[[0,3.2,4],[1,3.15,17.63],[2,2.84,12.54]],"ltp":3.2,"tv":0.72,"id":12474498}]}]}
{"op":"mcm","clk":"11837304140","pt":1723163196482,"mc":[{"id":"1.231581347","rc":[{"batb":[[0,3.15,17.63],[1,2.84,12.54],[2,2.62,16.72]],"ltp":3.2,"tv":0.72,"id":12474498}]}]}
{"op":"mcm","clk":"11837304252","pt":1723163198697,"mc":[{"id":"1.231581347","rc":[{"batb":[[0,3.2,4],[1,3.15,17.63],[2,2.84,12.54]],"ltp":3.2,"tv":0.72,"id":12474498}]}]}
{"op":"mcm","clk":"11837304359","pt":1723163200905,"mc":[{"id":"1.231581347","rc":[{"batb":[[0,3.15,17.63],[1,2.84,12.54],[2,2.62,16.72]],"ltp":3.2,"tv":0.72,"id":12474498}]}]}
{"op":"mcm","clk":"11837304482","pt":1723163203795,"mc":[{"id":"1.231581347","rc":[{"batb":[[0,3.2,4],[1,3.15,17.63],[2,2.84,12.54]],"ltp":3.2,"tv":0.72,"id":12474498}]}]}
{"op":"mcm","clk":"11837304584","pt":1723163206318,"mc":[{"id":"1.231581347","rc":[{"batb":[[0,3.15,17.63],[1,2.84,12.54],[2,2.62,16.72]],"ltp":3.2,"tv":0.72,"id":12474498}]}]}
{"op":"mcm","clk":"11837308035","pt":1723163285737,"mc":[{"id":"1.231581347","rc":[{"trd":[[1.44,197.19]],"batb":[[0,1.44,2.27]],"ltp":1.44,"tv":238.93,"id":25686043}],"tv":239.66}]}
{"op":"mcm","clk":"11837346483","pt":1723164147548,"mc":[{"id":"1.231581347","rc":[{"trd":[[1.43,615.23],[1.44,201.72]],"batb":[[0,1.4,148.78],[1,1.36,37.62],[2,1.29,54.34]],"batl":[[0,1.43,3302.31],[1,1.45,3.3],[2,1.46,100]],"ltp":1.43,"tv":858.7,"id":25686043},{"trd":[[3.3,6.6]],"ltp":3.3,"tv":7.33,"id":12474498}],"tv":866.03}]}
{"op":"mcm","clk":"11837346573","pt":1723164149982,"mc":[{"id":"1.231581347","rc":[{"batl":[[0,1.42,13.29],[1,1.43,3302.31]],"ltp":1.43,"tv":858.7,"id":25686043},{"batb":[[0,3.3,6.6],[1,3.15,17.63],[2,2.84,12.54]],"ltp":3.3,"tv":7.33,"id":12474498}]}]}
{"op":"mcm","clk":"11837365841","pt":1723164308512,"mc":[{"id":"1.231581347","rc":[{"trd":[[1.4,40.28]],"batb":[[0,1.4,148.71]],"ltp":1.4,"tv":858.84,"id":25686043}],"tv":866.17}]}
{"op":"mcm","clk":"11837365910","pt":1723164309948,"mc":[{"id":"1.231581347","rc":[{"batb":[[0,1.4,148.78]],"ltp":1.4,"tv":858.84,"id":25686043}]}]}
{"op":"mcm","clk":"11837371440","pt":1723164450255,"mc":[{"id":"1.231581347","rc":[{"batl":[[0,1.42,30.08]],"ltp":1.4,"tv":858.84,"id":25686043}]}]}
{"op":"mcm","clk":"11837391333","pt":1723164930910,"mc":[{"id":"1.231581347","rc":[{"batb":[[0,3.35,7.33],[1,3.3,6.6],[2,3.15,17.63]],"ltp":3.3,"tv":7.33,"id":12474498}]}]}
{"op":"mcm","clk":"11837392825","pt":1723164972689,"mc":[{"id":"1.231581347","rc":[{"trd":[[1.4,51.2]],"batb":[[0,1.4,143.32]],"ltp":1.4,"tv":869.77,"id":25686043}],"tv":877.1}]}
{"op":"mcm","clk":"11837414196","pt":1723165510110,"mc":[{"id":"1.231581347","rc":[{"trd":[[1.4,51.35],[1.43,615.07],[1.44,201.78]],"batb":[[0,1.4,143.25],[1,1.36,37.64],[2,1.29,54.37]],"batl":[[0,1.42,30.09],[1,1.43,3300.6]],"ltp":1.4,"tv":869.8,"id":25686043},{"trd":[[3.3,6.6]],"batb":[[0,3.35,7.33],[1,3.3,6.6]],"ltp":3.3,"tv":7.33,"id":12474498}],"tv":877.13}]}
{"op":"mcm","clk":"11837483334","pt":1723167031752,"mc":[{"id":"1.231581347","rc":[{"batl":[[0,3.45,4.3]],"ltp":3.3,"tv":7.33,"id":12474498}]}]}
{"op":"mcm","clk":"11837513536","pt":1723167857450,"mc":[{"id":"1.231581347","rc":[{"trd":[[1.4,141.35]],"batb":[[0,1.4,98.25]],"ltp":1.4,"tv":959.8,"id":25686043}],"tv":967.13}]}
{"op":"mcm","clk":"11837513833","pt":1723167866672,"mc":[{"id":"1.231581347","rc":[{"batl":[[1,1.43,3390.6]],"ltp":1.4,"tv":959.8,"id":25686043}]}]}
{"op":"mcm","clk":"11837515173","pt":1723167909789,"mc":[{"id":"1.231581347","rc":[{"trd":[[1.4,141.49]],"batb":[[0,1.4,98.18]],"ltp":1.4,"tv":959.94,"id":25686043}],"tv":967.27}]}
{"op":"mcm","clk":"11837515763","pt":1723167927807,"mc":[{"id":"1.231581347","rc":[{"batl":[[2,1.46,363.66]],"ltp":1.4,"tv":959.94,"id":25686043}]}]}
{"op":"mcm","clk":"11837536823","pt":1723168543610,"mc":[{"id":"1.231581347","rc":[{"trd":[[1.4,161.17]],"batb":[[0,1.4,94.78]],"ltp":1.4,"tv":979.62,"id":25686043}],"tv":986.95}]}
{"op":"mcm","clk":"11837550213","pt":1723168911373,"mc":[{"id":"1.231581347","rc":[{"trd":[[1.4,185.45],[1.43,615.12],[1.44,201.67]],"batb":[[0,1.4,82.63],[1,1.36,37.59],[2,1.29,54.3]],"batl":[[0,1.42,30.08],[1,1.43,3391.12]],"ltp":1.4,"tv":1003.84,"id":25686043},{"trd":[[3.3,6.6]],"batb":[[0,3.35,7.33],[1,3.3,6.6]],"ltp":3.3,"tv":7.33,"id":12474498}],"tv":1011.17}]}
{"op":"mcm","clk":"11837550380","pt":1723168915288,"mc":[{"id":"1.231581347","rc":[{"batb":[[0,1.4,94.78]],"ltp":1.4,"tv":1003.84,"id":25686043}]}]}
{"op":"mcm","clk":"11837554738","pt":1723169016729,"mc":[{"id":"1.231581347","rc":[{"trd":[[1.4,190.91]],"batb":[[0,1.4,92.05]],"ltp":1.4,"tv":1009.3,"id":25686043}],"tv":1016.63}]}
{"op":"mcm","clk":"11837554893","pt":1723169020641,"mc":[{"id":"1.231581347","rc":[{"batb":[[0,1.4,94.78]],"ltp":1.4,"tv":1009.3,"id":25686043}]}]}
{"op":"mcm","clk":"11837585671","pt":1723169597320,"mc":[{"id":"1.231581347","rc":[{"trd":[[1.4,191.09]],"batb":[[0,1.4,94.69]],"ltp":1.4,"tv":1009.48,"id":25686043}],"tv":1016.81}]}
{"op":"mcm","clk":"11837585709","pt":1723169598195,"mc":[{"id":"1.231581347","rc":[{"batb":[[0,1.4,94.78]],"ltp":1.4,"tv":1009.48,"id":25686043}]}]}
{"op":"mcm","clk":"11837585751","pt":1723169599683,"mc":[{"id":"1.231581347","rc":[{"trd":[[1.42,0.18]],"batl":[[0,1.42,29.99]],"ltp":1.42,"tv":1009.66,"id":25686043}],"tv":1016.99}]}
{"op":"mcm","clk":"11837610782","pt":1723170309196,"mc":[{"id":"1.231581347","rc":[{"trd":[[1.4,191.23]],"batb":[[0,1.4,94.71]],"ltp":1.4,"tv":1009.8,"id":25686043}],"tv":1017.13}]}
{"op":"mcm","clk":"11837610870","pt":1723170311678,"mc":[{"id":"1.231581347","rc":[{"batb":[[0,1.4,94.78]],"ltp":1.4,"tv":1009.8,"id":25686043}]}]}
{"op":"mcm","clk":"11837613879","pt":1723170419847,"mc":[{"id":"1.231581347","rc":[{"trd":[[1.4,227.23]],"batb":[[0,1.4,76.78]],"ltp":1.4,"tv":1045.8,"id":25686043}],"tv":1053.13}]}
{"op":"mcm","clk":"11837613968","pt":1723170422323,"mc":[{"id":"1.231581347","rc":[{"batb":[[0,1.4,94.78]],"ltp":1.4,"tv":1045.8,"id":25686043}]}]}
{"op":"mcm","clk":"11837620230","pt":1723170608321,"mc":[{"id":"1.231581347","rc":[{"trd":[[1.4,233.05]],"batb":[[0,1.4,91.87]],"ltp":1.4,"tv":1051.63,"id":25686043}],"tv":1058.96}]}
{"op":"mcm","clk":"11837620457","pt":1723170613247,"mc":[{"id":"1.231581347","rc":[{"batb":[[0,1.4,94.78]],"ltp":1.4,"tv":1051.63,"id":25686043}]}]}
{"op":"mcm","clk":"11837634590","pt":1723170941486,"mc":[{"id":"1.231581347","rc":[{"trd":[[1.4,243.05]],"batb":[[0,1.4,89.78]],"ltp":1.4,"tv":1061.63,"id":25686043}],"tv":1068.96}]}
{"op":"mcm","clk":"11837634768","pt":1723170945085,"mc":[{"id":"1.231581347","rc":[{"batb":[[0,1.4,94.78]],"ltp":1.4,"tv":1061.63,"id":25686043}]}]}
{"op":"mcm","clk":"11837670780","pt":1723172019586,"mc":[{"id":"1.231581347","rc":[{"trd":[[1.4,244.87]],"ltp":1.4,"tv":1063.45,"id":25686043}],"tv":1070.78}]}
{"op":"mcm","clk":"11837672169","pt":1723172060818,"mc":[{"id":"1.231581347","rc":[{"trd":[[1.4,249.37]],"batb":[[0,1.4,90.28]],"ltp":1.4,"tv":1067.95,"id":25686043},{"trd":[[3.5,1.8]],"ltp":3.5,"tv":9.13,"id":12474498}],"tv":1077.08}]}
{"op":"mcm","clk":"11837672338","pt":1723172064820,"mc":[{"id":"1.231581347","rc":[{"batb":[[0,1.4,94.78]],"ltp":1.4,"tv":1067.95,"id":25686043}]}]}
{"op":"mcm","clk":"11837676518","pt":1723172213409,"mc":[{"id":"1.231581347","rc":[{"batb":[[1,1.29,54.3],[2,1.2,20.09]],"ltp":1.4,"tv":1067.95,"id":25686043}]}]}
{"op":"mcm","clk":"11837676585","pt":1723172215421,"mc":[{"id":"1.231581347","rc":[{"batb":[[1,1.2,20.09],[2,1.15,1284.47]],"ltp":1.4,"tv":1067.95,"id":25686043}]}]}
{"op":"mcm","clk":"11837696146","pt":1723172710509,"mc":[{"id":"1.231581347","rc":[{"trd":[[1.4,249.5],[1.43,615.4],[1.44,201.64]],"batb":[[0,1.4,94.71],[2,1.15,1284.58]],"batl":[[0,1.42,29.99],[1,1.43,3394.02]],"ltp":1.4,"tv":1068.32,"id":25686043}],"tv":1077.45}]}
{"op":"mcm","clk":"11837696287","pt":1723172712808,"mc":[{"id":"1.231581347","rc":[{"batb":[[0,1.4,94.78]],"ltp":1.4,"tv":1068.32,"id":25686043}]}]}
{"op":"mcm","clk":"11837706524","pt":1723172914548,"mc":[{"id":"1.231581347","rc":[{"batb":[[0,1.41,10],[1,1.4,94.78],[2,1.2,20.09]],"ltp":1.4,"tv":1068.32,"id":25686043}]}]}
{"op":"mcm","clk":"11837706729","pt":1723172918651,"mc":[{"id":"1.231581347","rc":[{"batb":[[1,1.2,20.09],[2,1.15,1284.58]],"ltp":1.4,"tv":1068.32,"id":25686043},{"batb":[[2,1.88,171.53]],"ltp":3.5,"tv":9.13,"id":12474498}]}]}
{"op":"mcm","clk":"11837725370","pt":1723173314896,"mc":[{"id":"1.231581347","rc":[{"trd":[[1.41,13.5]],"batb":[[0,1.41,3.25]],"ltp":1.41,"tv":1081.82,"id":25686043}],"tv":1090.95}]}
{"op":"mcm","clk":"11837725404","pt":1723173315466,"mc":[{"id":"1.231581347","rc":[{"batb":[[1,1.4,94.78],[2,1.2,20.09]],"ltp":1.41,"tv":1081.82,"id":25686043},{"batb":[[2,3.15,17.63]],"ltp":3.5,"tv":9.13,"id":12474498}]}]}
{"op":"mcm","clk":"11837749483","pt":1723173844301,"mc":[{"id":"1.231581347","rc":[{"batl":[[0,1.42,39.09]],"ltp":1.41,"tv":1081.82,"id":25686043}]}]}
{"op":"mcm","clk":"11837793180","pt":1723174954994,"mc":[{"id":"1.231581347","rc":[{"batl":[[0,1.42,151.59]],"ltp":1.41,"tv":1081.82,"id":25686043}]}]}
{"op":"mcm","clk":"11837793223","pt":1723174956379,"mc":[{"id":"1.231581347","rc":[{"batl":[[0,1.42,138.39]],"ltp":1.41,"tv":1081.82,"id":25686043},{"batb":[[1,3.15,17.63],[2,1.88,171.53]],"ltp":3.5,"tv":9.13,"id":12474498}]}]}
{"op":"mcm","clk":"11837793491","pt":1723174964177,"mc":[{"id":"1.231581347","rc":[{"trd":[[1.41,20]],"batb":[[0,1.4,94.78],[1,1.2,20.09],[2,1.15,1284.58]],"batl":[[0,1.41,109.25],[1,1.42,138.39],[2,1.43,3394.02]],"ltp":1.41,"tv":1088.32,"id":25686043}],"tv":1097.45}]}
{"op":"mcm","clk":"11837793563","pt":1723174965974,"mc":[{"id":"1.231581347","rc":[{"batl":[[0,1.41,123.44],[1,1.42,121.6]],"ltp":1.41,"tv":1088.32,"id":25686043},{"batb":[[0,3.45,6.31]],"ltp":3.5,"tv":9.13,"id":12474498}]}]}
{"op":"mcm","clk":"11837793988","pt":1723174974772,"mc":[{"id":"1.231581347","rc":[{"trd":[[1.4,252.2]],"batb":[[0,1.4,93.43]],"ltp":1.4,"tv":1091.02,"id":25686043}],"tv":1100.15}]}
{"op":"mcm","clk":"11837807157","pt":1723174978275,"mc":[{"id":"1.231581347","rc":[{"batb":[[0,1.4,94.78]],"ltp":1.4,"tv":1091.02,"id":25686043}]}]}
{"op":"mcm","clk":"11837834112","pt":1723175537806,"mc":[{"id":"1.231581347","rc":[{"batb":[[1,1.25,63.99],[2,1.2,20]],"ltp":1.4,"tv":1091.02,"id":25686043}]}]}
{"op":"mcm","clk":"11837850731","pt":1723176064375,"mc":[{"id":"1.231581347","rc":[{"trd":[[1.4,252.19],[1.44,201.62]],"batl":[[0,1.41,123.44]],"ltp":1.4,"tv":1091.0,"id":25686043},{"trd":[[3.3,6.6],[3.45,4.51]],"batb":[[0,3.45,4.06],[2,1.88,171.48]],"ltp":3.45,"tv":13.63,"id":12474498}],"tv":1104.64}]}
{"op":"mcm","clk":"11837891869","pt":1723177053058,"mc":[{"id":"1.231581347","rc":[{"trd":[[1.4,264.47]],"batb":[[0,1.4,88.64]],"ltp":1.4,"tv":1103.28,"id":25686043}],"tv":1116.92}]}
{"op":"mcm","clk":"11837891968","pt":1723177055262,"mc":[{"id":"1.231581347","rc":[{"batb":[[0,1.4,94.78]],"ltp":1.4,"tv":1103.28,"id":25686043}]}]}
{"op":"mcm","clk":"11837901457","pt":1723177298485,"mc":[{"id":"1.231581347","rc":[{"trd":[[1.4,454.03]],"batb":[[0,1.25,63.99],[1,1.2,20],[2,1.15,1284.14]],"batl":[[0,1.4,17.72],[1,1.41,123.44],[2,1.42,121.59]],"ltp":1.4,"tv":1292.84,"id":25686043}],"tv":1306.48}]}
{"op":"mcm","clk":"11837901564","pt":1723177300754,"mc":[{"id":"1.231581347","rc":[{"trd":[[1.39,26.64]],"batl":[[0,1.4,17.88],[1,1.41,110.15]],"ltp":1.39,"tv":1319.48,"id":25686043}],"tv":1333.12}]}
{"op":"mcm","clk":"11837901605","pt":1723177301677,"mc":[{"id":"1.231581347","rc":[{"trd":[[1.39,26.96],[1.4,467.13]],"batb":[[0,1.36,273.49],[1,1.25,63.99],[2,1.2,20]],"batl":[[0,1.4,4.62]],"ltp":1.4,"tv":1332.9,"id":25686043},{"trd":[[3.5,7.04]],"ltp":3.5,"tv":18.87,"id":12474498}],"tv":1351.78}]}
{"op":"mcm","clk":"11837902464","pt":1723177322398,"mc":[{"id":"1.231581347","rc":[{"trd":[[1.4,468.26]],"batl":[[0,1.4,3.49]],"ltp":1.4,"tv":1334.03,"id":25686043},{"trd":[[3.5,7.49]],"ltp":3.5,"tv":19.32,"id":12474498}],"tv":1353.36}]}
{"op":"mcm","clk":"11837902742","pt":1723177328505,"mc":[{"id":"1.231581347","rc":[{"batb":[[0,1.37,112.5],[1,1.36,273.49],[2,1.25,63.99]],"ltp":1.4,"tv":1334.03,"id":25686043}]}]}
{"op":"mcm","clk":"11837902941","pt":1723177333019,"mc":[{"id":"1.231581347","rc":[{"batl":[[0,1.4,12.77]],"ltp":1.4,"tv":1334.03,"id":25686043}]}]}
{"op":"mcm","clk":"11837910144","pt":1723177509531,"mc":[{"id":"1.231581347","rc":[{"trd":[[1.4,468.4]],"batb":[[1,1.36,105.31]],"batl":[[0,1.4,12.7]],"ltp":1.4,"tv":1334.17,"id":25686043}],"tv":1353.5}]}
{"op":"mcm","clk":"11837912564","pt":1723177567112,"mc":[{"id":"1.231581347","rc":[{"trd":[[1.37,0.12]],"batb":[[0,1.37,112.44]],"ltp":1.37,"tv":1334.3,"id":25686043}],"tv":1353.62}]}
{"op":"mcm","clk":"11837913136","pt":1723177584141,"mc":[{"id":"1.231581347","rc":[{"trd":[[1.4,468.43]],"batl":[[0,1.4,12.67]],"ltp":1.4,"tv":1334.33,"id":25686043},{"trd":[[3.5,7.5]],"ltp":3.5,"tv":19.33,"id":12474498}],"tv":1353.66}]}
{"op":"mcm","clk":"11837913810","pt":1723177603866,"mc":[{"id":"1.231581347","rc":[{"trd":[[1.4,468.46]],"batl":[[0,1.4,12.64]],"ltp":1.4,"tv":1334.36,"id":25686043},{"trd":[[3.5,7.51]],"ltp":3.5,"tv":19.34,"id":12474498}],"tv":1353.7}]}
{"op":"mcm","clk":"11837923675","pt":1723177879773,"mc":[{"id":"1.231581347","rc":[{"trd":[[1.37,0.22]],"batb":[[0,1.37,112.39]],"ltp":1.37,"tv":1334.46,"id":25686043}],"tv":1353.8}]}
{"op":"mcm","clk":"11837928390","pt":1723177995341,"mc":[{"id":"1.231581347","rc":[{"batl":[[0,1.4,21.9]],"ltp":1.37,"tv":1334.46,"id":25686043}]}]}
{"op":"mcm","clk":"11837928820","pt":1723178006072,"mc":[{"id":"1.231581347","rc":[{"batl":[[0,1.39,45.08],[1,1.4,21.9],[2,1.41,110.15]],"ltp":1.37,"tv":1334.46,"id":25686043}]}]}
{"op":"mcm","clk":"11837928919","pt":1723178008372,"mc":[{"id":"1.231581347","rc":[{"batl":[[1,1.4,12.62]],"ltp":1.37,"tv":1334.46,"id":25686043},{"batb":[[0,3.6,3.9]],"ltp":3.5,"tv":19.34,"id":12474498}]}]}
{"op":"mcm","clk":"11837929611","pt":1723178027849,"mc":[{"id":"1.231581347","rc":[{"batb":[[0,1.37,67.31]],"ltp":1.37,"tv":1334.46,"id":25686043}]}]}
{"op":"mcm","clk":"11837929833","pt":1723178033953,"mc":[{"id":"1.231581347","rc":[{"batl":[[0,1.4,12.62],[1,1.41,110.15],[2,1.42,121.59]],"ltp":1.37,"tv":1334.46,"id":25686043},{"batb":[[0,3.15,17.63],[1,1.88,171.48],[2,1.87,171.22]],"ltp":3.5,"tv":19.34,"id":12474498}]}]}
{"op":"mcm","clk":"11837929837","pt":1723178034055,"mc":[{"id":"1.231581347","rc":[{"batb":[[0,3.45,4.06],[1,3.15,17.63],[2,1.88,171.48]],"ltp":3.5,"tv":19.34,"id":12474498}]}]}
{"op":"mcm","clk":"11837948322","pt":1723178470666,"mc":[{"id":"1.231581347","rc":[{"trd":[[1.37,0.3]],"batb":[[0,1.37,67.27]],"ltp":1.37,"tv":1334.54,"id":25686043}],"tv":1353.88}]}
{"op":"mcm","clk":"11837957696","pt":1723178709671,"mc":[{"id":"1.231581347","rc":[{"trd":[[1.4,468.6]],"batl":[[0,1.4,12.55]],"ltp":1.4,"tv":1334.68,"id":25686043}],"tv":1354.02}]}
{"op":"mcm","clk":"11838007294","pt":1723179909436,"mc":[{"id":"1.231581347","rc":[{"trd":[[1.39,26.97],[1.4,468.77],[1.43,615.06],[1.44,201.7]],"batl":[[0,1.4,12.48],[2,1.42,121.6]],"ltp":1.4,"tv":1334.59,"id":25686043},{"trd":[[3.3,6.6],[3.45,4.51],[3.5,7.51]],"batb":[[0,3.45,4.06],[2,1.88,171.56]],"ltp":3.5,"tv":19.34,"id":12474498}],"tv":1353.94}]}
{"op":"mcm","clk":"11838012139","pt":1723180044361,"mc":[{"id":"1.231581347","rc":[{"batb":[[0,1.37,169.73],[1,1.25,63.99],[2,1.2,20]],"ltp":1.4,"tv":1334.59,"id":25686043},{"batb":[[1,3.35,16.13]],"ltp":3.5,"tv":19.34,"id":12474498}]}]}
{"op":"mcm","clk":"11838040424","pt":1723180435347,"mc":[{"id":"1.231581347","rc":[{"batb":[[0,3.5,14],[1,3.45,4.06],[2,3.35,16.13]],"batl":[[0,3.7,4.66]],"ltp":3.5,"tv":19.34,"id":12474498}]}]}
{"op":"mcm","clk":"11838040476","pt":1723180436982,"mc":[{"id":"1.231581347","rc":[{"batb":[[0,3.55,3.95],[1,3.5,14]],"ltp":3.5,"tv":19.34,"id":12474498}]}]}
{"op":"mcm","clk":"11838040494","pt":1723180437855,"mc":[{"id":"1.231581347","rc":[{"batb":[[1,3.5,10]],"ltp":3.5,"tv":19.34,"id":12474498}]}]}
{"op":"mcm","clk":"11838040510","pt":1723180438682,"mc":[{"id":"1.231581347","rc":[{"batb":[[1,3.35,16.13],[2,1.88,171.56]],"ltp":3.5,"tv":19.34,"id":12474498}]}]}
{"op":"mcm","clk":"11838040547","pt":1723180439555,"mc":[{"id":"1.231581347","rc":[{"batb":[[0,3.45,4.06]],"ltp":3.5,"tv":19.34,"id":12474498}]}]}
{"op":"mcm","clk":"11838040620","pt":1723180441096,"mc":[{"id":"1.231581347","rc":[{"batb":[[0,3.5,14],[1,3.45,4.06],[2,3.35,16.13]],"ltp":3.5,"tv":19.34,"id":12474498}]}]}
{"op":"mcm","clk":"11838040652","pt":1723180442069,"mc":[{"id":"1.231581347","rc":[{"batb":[[1,3.35,16.13],[2,1.88,171.56]],"ltp":3.5,"tv":19.34,"id":12474498}]}]}
{"op":"mcm","clk":"11838040704","pt":1723180443761,"mc":[{"id":"1.231581347","rc":[{"batb":[[0,3.5,10]],"ltp":3.5,"tv":19.34,"id":12474498}]}]}
{"op":"mcm","clk":"11838040731","pt":1723180444485,"mc":[{"id":"1.231581347","rc":[{"batb":[[0,3.35,16.13],[1,1.88,171.56],[2,1.87,171.31]],"ltp":3.5,"tv":19.34,"id":12474498}]}]}
{"op":"mcm","clk":"11838040801","pt":1723180446088,"mc":[{"id":"1.231581347","rc":[{"batb":[[0,3.4,4],[1,3.35,16.13],[2,1.88,171.56]],"ltp":3.5,"tv":19.34,"id":12474498}]}]}
{"op":"mcm","clk":"11838040946","pt":1723180448466,"mc":[{"id":"1.231581347","rc":[{"batb":[[0,3.4,10]],"ltp":3.5,"tv":19.34,"id":12474498}]}]}
{"op":"mcm","clk":"11838041091","pt":1723180451904,"mc":[{"id":"1.231581347","rc":[{"batb":[[0,3.45,4]],"ltp":3.5,"tv":19.34,"id":12474498}]}]}
{"op":"mcm","clk":"11838041173","pt":1723180454313,"mc":[{"id":"1.231581347","rc":[{"batb":[[0,3.4,10]],"ltp":3.5,"tv":19.34,"id":12474498}]}]}
{"op":"mcm","clk":"11838041332","pt":1723180457814,"mc":[{"id":"1.231581347","rc":[{"batb":[[0,3.45,4]],"ltp":3.5,"tv":19.34,"id":12474498}]}]}
{"op":"mcm","clk":"11838041407","pt":1723180460100,"mc":[{"id":"1.231581347","rc":[{"batb":[[0,3.4,10]],"ltp":3.5,"tv":19.34,"id":12474498}]}]}
{"op":"mcm","clk":"11838041527","pt":1723180463525,"mc":[{"id":"1.231581347","rc":[{"batb":[[0,3.45,4]],"ltp":3.5,"tv":19.34,"id":12474498}]}]}
{"op":"mcm","clk":"11838041604","pt":1723180465990,"mc":[{"id":"1.231581347","rc":[{"batb":[[0,3.4,10]],"ltp":3.5,"tv":19.34,"id":12474498}]}]}
{"op":"mcm","clk":"11838041730","pt":1723180469525,"mc":[{"id":"1.231581347","rc":[{"batb":[[0,3.45,4]],"ltp":3.5,"tv":19.34,"id":12474498}]}]}
{"op":"mcm","clk":"11838041801","pt":1723180471827,"mc":[{"id":"1.231581347","rc":[{"batb":[[0,3.4,10]],"ltp":3.5,"tv":19.34,"id":12474498}]}]}
{"op":"mcm","clk":"11838041869","pt":1723180473935,"mc":[{"id":"1.231581347","rc":[{"batb":[[0,3.45,4],[1,3.4,10],[2,3.35,16.13]],"ltp":3.5,"tv":19.34,"id":12474498}]}]}
{"op":"mcm","clk":"11838041908","pt":1723180475108,"mc":[{"id":"1.231581347","rc":[{"batb":[[1,3.35,16.13],[2,1.88,171.56]],"ltp":3.5,"tv":19.34,"id":12474498}]}]}
{"op":"mcm","clk":"11838041947","pt":1723180476439,"mc":[{"id":"1.231581347","rc":[{"batb":[[0,3.35,16.13],[1,1.88,171.56],[2,1.87,171.31]],"ltp":3.5,"tv":19.34,"id":12474498}]}]}
{"op":"mcm","clk":"11838042033","pt":1723180478639,"mc":[{"id":"1.231581347","rc":[{"batb":[[0,3.45,4],[1,3.4,10],[2,3.35,16.13]],"ltp":3.5,"tv":19.34,"id":12474498}]}]}
{"op":"mcm","clk":"11838042101","pt":1723180480943,"mc":[{"id":"1.231581347","rc":[{"batb":[[0,3.4,10],[1,3.35,16.13],[2,1.88,171.56]],"ltp":3.5,"tv":19.34,"id":12474498}]}]}
{"op":"mcm","clk":"11838042134","pt":1723180481716,"mc":[{"id":"1.231581347","rc":[{"batb":[[0,3.35,16.13],[1,1.88,171.56],[2,1.87,171.31]],"ltp":3.5,"tv":19.34,"id":12474498}]}]}
{"op":"mcm","clk":"11838042204","pt":1723180483914,"mc":[{"id":"1.231581347","rc":[{"batb":[[0,3.45,10],[1,3.4,4],[2,3.35,16.13]],"ltp":3.5,"tv":19.34,"id":12474498}]}]}
{"op":"mcm","clk":"11838042270","pt":1723180486012,"mc":[{"id":"1.231581347","rc":[{"batb":[[1,3.35,16.13],[2,1.88,171.56]],"ltp":3.5,"tv":19.34,"id":12474498}]}]}
{"op":"mcm","clk":"11838042305","pt":1723180487041,"mc":[{"id":"1.231581347","rc":[{"batb":[[0,3.35,16.13],[1,1.88,171.56],[2,1.87,171.31]],"ltp":3.5,"tv":19.34,"id":12474498}]}]}
{"op":"mcm","clk":"11838042339","pt":1723180488322,"mc":[{"id":"1.231581347","rc":[{"batb":[[0,3.4,4],[1,3.35,16.13],[2,1.88,171.56]],"ltp":3.5,"tv":19.34,"id":12474498}]}]}
{"op":"mcm","clk":"11838042386","pt":1723180489446,"mc":[{"id":"1.231581347","rc":[{"batb":[[0,3.45,10],[1,3.4,4],[2,3.35,16.13]],"ltp":3.5,"tv":19.34,"id":12474498}]}]}
{"op":"mcm","clk":"11838042447","pt":1723180491137,"mc":[{"id":"1.231581347","rc":[{"batb":[[1,3.35,16.13],[2,1.88,171.56]],"ltp":3.5,"tv":19.34,"id":12474498}]}]}
{"op":"mcm","clk":"11838042499","pt":1723180492724,"mc":[{"id":"1.231581347","rc":[{"batb":[[0,3.35,16.13],[1,1.88,171.56],[2,1.87,171.31]],"ltp":3.5,"tv":19.34,"id":12474498}]}]}
{"op":"mcm","clk":"11838042537","pt":1723180494051,"mc":[{"id":"1.231581347","rc":[{"batb":[[0,3.4,4],[1,3.35,16.13],[2,1.88,171.56]],"ltp":3.5,"tv":19.34,"id":12474498}]}]}
{"op":"mcm","clk":"11838042568","pt":1723180495229,"mc":[{"id":"1.231581347","rc":[{"batb":[[0,3.45,10],[1,3.4,4],[2,3.35,16.13]],"ltp":3.5,"tv":19.34,"id":12474498}]}]}
{"op":"mcm","clk":"11838042604","pt":1723180496557,"mc":[{"id":"1.231581347","rc":[{"batb":[[1,3.35,16.13],[2,1.88,171.56]],"ltp":3.5,"tv":19.34,"id":12474498}]}]}
{"op":"mcm","clk":"11838042667","pt":1723180498757,"mc":[{"id":"1.231581347","rc":[{"batb":[[0,3.4,4]],"ltp":3.5,"tv":19.34,"id":12474498}]}]}
{"op":"mcm","clk":"11838042756","pt":1723180501168,"mc":[{"id":"1.231581347","rc":[{"batb":[[0,3.45,10]],"ltp":3.5,"tv":19.34,"id":12474498}]}]}
{"op":"mcm","clk":"11838042887","pt":1723180504734,"mc":[{"id":"1.231581347","rc":[{"batb":[[0,3.4,4]],"ltp":3.5,"tv":19.34,"id":12474498}]}]}
{"op":"mcm","clk":"11838042974","pt":1723180507250,"mc":[{"id":"1.231581347","rc":[{"batb":[[0,3.45,10]],"ltp":3.5,"tv":19.34,"id":12474498}]}]}
{"op":"mcm","clk":"11838043108","pt":1723180510851,"mc":[{"id":"1.231581347","rc":[{"batb":[[0,3.4,4]],"ltp":3.5,"tv":19.34,"id":12474498}]}]}
{"op":"mcm","clk":"11838043228","pt":1723180513370,"mc":[{"id":"1.231581347","rc":[{"batb":[[0,3.45,10]],"ltp":3.5,"tv":19.34,"id":12474498}]}]}
{"op":"mcm","clk":"11838043377","pt":1723180517290,"mc":[{"id":"1.231581347","rc":[{"batb":[[0,3.4,4]],"ltp":3.5,"tv":19.34,"id":12474498}]}]}
{"op":"mcm","clk":"11838043469","pt":1723180519651,"mc":[{"id":"1.231581347","rc":[{"batb":[[0,3.45,10]],"ltp":3.5,"tv":19.34,"id":12474498}]}]}
{"op":"mcm","clk":"11838043584","pt":1723180523082,"mc":[{"id":"1.231581347","rc":[{"batb":[[0,3.5,4]],"ltp":3.5,"tv":19.34,"id":12474498}]}]}
{"op":"mcm","clk":"11838043645","pt":1723180525793,"mc":[{"id":"1.231581347","rc":[{"batb":[[0,3.4,10]],"ltp":3.5,"tv":19.34,"id":12474498}]}]}
{"op":"mcm","clk":"11838043726","pt":1723180527891,"mc":[{"id":"1.231581347","rc":[{"batb":[[0,3.45,4],[1,3.4,10],[2,3.35,16.13]],"ltp":3.5,"tv":19.34,"id":12474498}]}]}
{"op":"mcm","clk":"11838043783","pt":1723180529274,"mc":[{"id":"1.231581347","rc":[{"batb":[[1,3.35,16.13],[2,1.88,171.56]],"ltp":3.5,"tv":19.34,"id":12474498}]}]}
{"op":"mcm","clk":"11838043807","pt":1723180530298,"mc":[{"id":"1.231581347","rc":[{"batb":[[0,3.35,16.13],[1,1.88,171.56],[2,1.87,171.31]],"ltp":3.5,"tv":19.34,"id":12474498}]}]}
{"op":"mcm","clk":"11838043851","pt":1723180531589,"mc":[{"id":"1.231581347","rc":[{"batb":[[0,3.4,10],[1,3.35,16.13],[2,1.88,171.56]],"ltp":3.5,"tv":19.34,"id":12474498}]}]}
{"op":"mcm","clk":"11838043892","pt":1723180532771,"mc":[{"id":"1.231581347","rc":[{"batb":[[0,3.45,4],[1,3.4,10],[2,3.35,16.13]],"ltp":3.5,"tv":19.34,"id":12474498}]}]}
{"op":"mcm","clk":"11838043952","pt":1723180535078,"mc":[{"id":"1.231581347","rc":[{"batb":[[0,3.35,16.13],[1,1.88,171.56],[2,1.87,171.31]],"ltp":3.5,"tv":19.34,"id":12474498}]}]}
{"op":"mcm","clk":"11838044018","pt":1723180537588,"mc":[{"id":"1.231581347","rc":[{"batb":[[0,3.4,14],[1,3.35,16.13],[2,1.88,171.56]],"ltp":3.5,"tv":19.34,"id":12474498}]}]}
{"op":"mcm","clk":"11838044085","pt":1723180540197,"mc":[{"id":"1.231581347","rc":[{"batb":[[0,3.4,10]],"ltp":3.5,"tv":19.34,"id":12474498}]}]}
{"op":"mcm","clk":"11838044107","pt":1723180541180,"mc":[{"id":"1.231581347","rc":[{"batb":[[0,3.35,16.13],[1,1.88,171.56],[2,1.87,171.31]],"ltp":3.5,"tv":19.34,"id":12474498}]}]}
{"op":"mcm","clk":"11838044193","pt":1723180542813,"mc":[{"id":"1.231581347","rc":[{"batb":[[0,3.4,4],[1,3.35,16.13],[2,1.88,171.56]],"ltp":3.5,"tv":19.34,"id":12474498}]}]}
{"op":"mcm","clk":"11838044241","pt":1723180544096,"mc":[{"id":"1.231581347","rc":[{"batb":[[0,3.45,10],[1,3.4,4],[2,3.35,16.13]],"ltp":3.5,"tv":19.34,"id":12474498}]}]}
{"op":"mcm","clk":"11838044266","pt":1723180545324,"mc":[{"id":"1.231581347","rc":[{"batb":[[1,3.35,16.13],[2,1.88,171.56]],"ltp":3.5,"tv":19.34,"id":12474498}]}]}
{"op":"mcm","clk":"11838044367","pt":1723180547801,"mc":[{"id":"1.231581347","rc":[{"batb":[[0,3.35,16.13],[1,1.88,171.56],[2,1.87,171.31]],"ltp":3.5,"tv":19.34,"id":12474498}]}]}
{"op":"mcm","clk":"11838044372","pt":1723180548215,"mc":[{"id":"1.231581347","rc":[{"batb":[[0,3.4,4],[1,3.35,16.13],[2,1.88,171.56]],"ltp":3.5,"tv":19.34,"id":12474498}]}]}
{"op":"mcm","clk":"11838044449","pt":1723180550534,"mc":[{"id":"1.231581347","rc":[{"batb":[[0,3.45,10]],"ltp":3.5,"tv":19.34,"id":12474498}]}]}
{"op":"mcm","clk":"11838044549","pt":1723180553911,"mc":[{"id":"1.231581347","rc":[{"batb":[[0,3.4,4]],"ltp":3.5,"tv":19.34,"id":12474498}]}]}
{"op":"mcm","clk":"11838044617","pt":1723180556326,"mc":[{"id":"1.231581347","rc":[{"batb":[[0,3.4,10]],"ltp":3.5,"tv":19.34,"id":12474498}]}]}
{"op":"mcm","clk":"11838044713","pt":1723180558895,"mc":[{"id":"1.231581347","rc":[{"batb":[[0,3.45,4],[1,3.4,10],[2,3.35,16.13]],"ltp":3.5,"tv":19.34,"id":12474498}]}]}
{"op":"mcm","clk":"11838044741","pt":1723180559509,"mc":[{"id":"1.231581347","rc":[{"batb":[[1,3.35,16.13],[2,1.88,171.56]],"ltp":3.5,"tv":19.34,"id":12474498}]}]}
{"op":"mcm","clk":"11838044816","pt":1723180561725,"mc":[{"id":"1.231581347","rc":[{"batb":[[0,3.35,16.13],[1,1.88,171.56],[2,1.87,171.31]],"ltp":3.5,"tv":19.34,"id":12474498}]}]}
{"op":"mcm","clk":"11838044843","pt":1723180562343,"mc":[{"id":"1.231581347","rc":[{"batb":[[0,3.4,10],[1,3.35,16.13],[2,1.88,171.56]],"ltp":3.5,"tv":19.34,"id":12474498}]}]}
{"op":"mcm","clk":"11838044983","pt":1723180565934,"mc":[{"id":"1.231581347","rc":[{"batb":[[0,3.45,4]],"ltp":3.5,"tv":19.34,"id":12474498}]}]}
{"op":"mcm","clk":"11838045071","pt":1723180567936,"mc":[{"id":"1.231581347","rc":[{"batb":[[0,3.35,16.13],[1,1.88,171.56],[2,1.87,171.31]],"ltp":3.5,"tv":19.34,"id":12474498}]}]}
{"op":"mcm","clk":"11838045078","pt":1723180568140,"mc":[{"id":"1.231581347","rc":[{"batb":[[0,3.4,10],[1,3.35,16.13],[2,1.88,171.56]],"ltp":3.5,"tv":19.34,"id":12474498}]}]}
{"op":"mcm","clk":"11838045157","pt":1723180570351,"mc":[{"id":"1.231581347","rc":[{"batb":[[0,3.45,4],[1,3.4,10],[2,3.35,16.13]],"ltp":3.5,"tv":19.34,"id":12474498}]}]}
{"op":"mcm","clk":"11838045201","pt":1723180571428,"mc":[{"id":"1.231581347","rc":[{"batb":[[1,3.35,16.13],[2,1.88,171.56]],"ltp":3.5,"tv":19.34,"id":12474498}]}]}
{"op":"mcm","clk":"11838045264","pt":1723180572815,"mc":[{"id":"1.231581347","rc":[{"batb":[[0,3.35,16.13],[1,1.88,171.56],[2,1.87,171.31]],"ltp":3.5,"tv":19.34,"id":12474498}]}]}
{"op":"mcm","clk":"11838045327","pt":1723180574857,"mc":[{"id":"1.231581347","rc":[{"batb":[[0,3.4,10],[1,3.35,16.13],[2,1.88,171.56]],"ltp":3.5,"tv":19.34,"id":12474498}]}]}
{"op":"mcm","clk":"11838045335","pt":1723180575165,"mc":[{"id":"1.231581347","rc":[{"batb":[[0,3.45,4],[1,3.4,10],[2,3.35,16.13]],"ltp":3.5,"tv":19.34,"id":12474498}]}]}
{"op":"mcm","clk":"11838045389","pt":1723180576650,"mc":[{"id":"1.231581347","rc":[{"batb":[[0,3.45,8.06]],"ltp":3.5,"tv":19.34,"id":12474498}]}]}
{"op":"mcm","clk":"11838045434","pt":1723180577626,"mc":[{"id":"1.231581347","rc":[{"batb":[[0,3.45,4.06]],"ltp":3.5,"tv":19.34,"id":12474498}]}]}
{"op":"mcm","clk":"11838045457","pt":1723180578444,"mc":[{"id":"1.231581347","rc":[{"batb":[[1,3.35,16.13],[2,1.88,171.56]],"ltp":3.5,"tv":19.34,"id":12474498}]}]}
{"op":"mcm","clk":"11838045552","pt":1723180581063,"mc":[{"id":"1.231581347","rc":[{"batb":[[0,3.5,14],[1,3.45,4.06],[2,3.35,16.13]],"ltp":3.5,"tv":19.34,"id":12474498}]}]}
{"op":"mcm","clk":"11838045638","pt":1723180582656,"mc":[{"id":"1.231581347","rc":[{"batb":[[0,3.55,3.95],[1,3.5,14]],"ltp":3.5,"tv":19.34,"id":12474498}]}]}
{"op":"mcm","clk":"11838045719","pt":1723180584859,"mc":[{"id":"1.231581347","rc":[{"batb":[[1,3.35,16.13],[2,1.88,171.56]],"ltp":3.5,"tv":19.34,"id":12474498}]}]}
{"op":"mcm","clk":"11838045737","pt":1723180585371,"mc":[{"id":"1.231581347","rc":[{"batb":[[0,3.35,16.13],[1,1.88,171.56],[2,1.87,171.31]],"ltp":3.5,"tv":19.34,"id":12474498}]}]}
{"op":"mcm","clk":"11838045787","pt":1723180586655,"mc":[{"id":"1.231581347","rc":[{"batb":[[0,3.4,4],[1,3.35,16.13],[2,1.88,171.56]],"ltp":3.5,"tv":19.34,"id":12474498}]}]}
{"op":"mcm","clk":"11838045869","pt":1723180589268,"mc":[{"id":"1.231581347","rc":[{"batb":[[0,3.4,10]],"ltp":3.5,"tv":19.34,"id":12474498}]}]}
{"op":"mcm","clk":"11838045947","pt":1723180591584,"mc":[{"id":"1.231581347","rc":[{"batb":[[0,3.45,4],[1,3.4,10],[2,3.35,16.13]],"ltp":3.5,"tv":19.34,"id":12474498}]}]}
{"op":"mcm","clk":"11838045975","pt":1723180592566,"mc":[{"id":"1.231581347","rc":[{"batb":[[1,3.35,16.13],[2,1.88,171.56]],"ltp":3.5,"tv":19.34,"id":12474498}]}]}
{"op":"mcm","clk":"11838046027","pt":1723180594166,"mc":[{"id":"1.231581347","rc":[{"batb":[[0,3.35,16.13],[1,1.88,171.56],[2,1.87,171.31]],"ltp":3.5,"tv":19.34,"id":12474498}]}]}
{"op":"mcm","clk":"11838046122","pt":1723180597064,"mc":[{"id":"1.231581347","rc":[{"batb":[[0,3.4,14],[1,3.35,16.13],[2,1.88,171.56]],"ltp":3.5,"tv":19.34,"id":12474498}]}]}
{"op":"mcm","clk":"11838046195","pt":1723180599373,"mc":[{"id":"1.231581347","rc":[{"batb":[[0,3.4,10]],"ltp":3.5,"tv":19.34,"id":12474498}]}]}
{"op":"mcm","clk":"11838046236","pt":1723180600351,"mc":[{"id":"1.231581347","rc":[{"batb":[[0,3.35,16.13],[1,1.88,171.56],[2,1.87,171.31]],"ltp":3.5,"tv":19.34,"id":12474498}]}]}
{"op":"mcm","clk":"11838046333","pt":1723180602964,"mc":[{"id":"1.231581347","rc":[{"batb":[[0,3.45,10],[1,3.4,4],[2,3.35,16.13]],"ltp":3.5,"tv":19.34,"id":12474498}]}]}
{"op":"mcm","clk":"11838046409","pt":1723180605173,"mc":[{"id":"1.231581347","rc":[{"batb":[[1,3.35,16.13],[2,1.88,171.56]],"ltp":3.5,"tv":19.34,"id":12474498}]}]}
{"op":"mcm","clk":"11838046450","pt":1723180606559,"mc":[{"id":"1.231581347","rc":[{"batb":[[0,3.35,16.13],[1,1.88,171.56],[2,1.87,171.31]],"ltp":3.5,"tv":19.34,"id":12474498}]}]}
{"op":"mcm","clk":"11838046552","pt":1723180609697,"mc":[{"id":"1.231581347","rc":[{"batb":[[0,3.4,14],[1,3.35,16.13],[2,1.88,171.56]],"ltp":3.5,"tv":19.34,"id":12474498}]}]}
{"op":"mcm","clk":"11838046644","pt":1723180612171,"mc":[{"id":"1.231581347","rc":[{"batb":[[0,3.4,10]],"ltp":3.5,"tv":19.34,"id":12474498}]}]}
{"op":"mcm","clk":"11838046684","pt":1723180613198,"mc":[{"id":"1.231581347","rc":[{"batb":[[0,3.35,16.13],[1,1.88,171.56],[2,1.87,171.31]],"ltp":3.5,"tv":19.34,"id":12474498}]}]}
{"op":"mcm","clk":"11838046758","pt":1723180615716,"mc":[{"id":"1.231581347","rc":[{"batb":[[0,3.4,14],[1,3.35,16.13],[2,1.88,171.56]],"ltp":3.5,"tv":19.34,"id":12474498}]}]}
{"op":"mcm","clk":"11838046837","pt":1723180618019,"mc":[{"id":"1.231581347","rc":[{"batb":[[0,3.4,10]],"ltp":3.5,"tv":19.34,"id":12474498}]}]}
{"op":"mcm","clk":"11838046866","pt":1723180619094,"mc":[{"id":"1.231581347","rc":[{"batb":[[0,3.35,16.13],[1,1.88,171.56],[2,1.87,171.31]],"ltp":3.5,"tv":19.34,"id":12474498}]}]}
{"op":"mcm","clk":"11838046891","pt":1723180620321,"mc":[{"id":"1.231581347","rc":[{"batb":[[0,3.4,4],[1,3.35,16.13],[2,1.88,171.56]],"ltp":3.5,"tv":19.34,"id":12474498}]}]}
{"op":"mcm","clk":"11838046976","pt":1723180621914,"mc":[{"id":"1.231581347","rc":[{"batb":[[0,3.45,10],[1,3.4,4],[2,3.35,16.13]],"ltp":3.5,"tv":19.34,"id":12474498}]}]}
{"op":"mcm","clk":"11838047015","pt":1723180622685,"mc":[{"id":"1.231581347","rc":[{"batb":[[1,3.35,16.13],[2,1.88,171.56]],"ltp":3.5,"tv":19.34,"id":12474498}]}]}
{"op":"mcm","clk":"11838047124","pt":1723180625409,"mc":[{"id":"1.231581347","rc":[{"batb":[[0,3.4,4]],"ltp":3.5,"tv":19.34,"id":12474498}]}]}
{"op":"mcm","clk":"11838047263","pt":1723180628340,"mc":[{"id":"1.231581347","rc":[{"batb":[[0,3.4,10]],"ltp":3.5,"tv":19.34,"id":12474498}]}]}
{"op":"mcm","clk":"11838047395","pt":1723180631728,"mc":[{"id":"1.231581347","rc":[{"batb":[[0,3.45,4]],"ltp":3.5,"tv":19.34,"id":12474498}]}]}
{"op":"mcm","clk":"11838047483","pt":1723180633630,"mc":[{"id":"1.231581347","rc":[{"batb":[[0,3.35,16.13],[1,1.88,171.56],[2,1.87,171.31]],"ltp":3.5,"tv":19.34,"id":12474498}]}]}
{"op":"mcm","clk":"11838047546","pt":1723180635122,"mc":[{"id":"1.231581347","rc":[{"batb":[[0,3.4,10],[1,3.35,16.13],[2,1.88,171.56]],"ltp":3.5,"tv":19.34,"id":12474498}]}]}
{"op":"mcm","clk":"11838047600","pt":1723180636512,"mc":[{"id":"1.231581347","rc":[{"batb":[[0,3.45,4],[1,3.4,10],[2,3.35,16.13]],"ltp":3.5,"tv":19.34,"id":12474498}]}]}
{"op":"mcm","clk":"11838047682","pt":1723180638725,"mc":[{"id":"1.231581347","rc":[{"batb":[[1,3.35,16.13],[2,1.88,171.56]],"ltp":3.5,"tv":19.34,"id":12474498}]}]}
{"op":"mcm","clk":"11838047696","pt":1723180639031,"mc":[{"id":"1.231581347","rc":[{"batb":[[0,3.35,16.13],[1,1.88,171.56],[2,1.87,171.31]],"ltp":3.5,"tv":19.34,"id":12474498}]}]}
{"op":"mcm","clk":"11838047783","pt":1723180641448,"mc":[{"id":"1.231581347","rc":[{"batb":[[0,3.4,14],[1,3.35,16.13],[2,1.88,171.56]],"ltp":3.5,"tv":19.34,"id":12474498}]}]}
{"op":"mcm","clk":"11838047893","pt":1723180643755,"mc":[{"id":"1.231581347","rc":[{"batb":[[0,3.4,10]],"ltp":3.5,"tv":19.34,"id":12474498}]}]}
{"op":"mcm","clk":"11838047939","pt":1723180644833,"mc":[{"id":"1.231581347","rc":[{"batb":[[0,3.35,16.13],[1,1.88,171.56],[2,1.87,171.31]],"ltp":3.5,"tv":19.34,"id":12474498}]}]}
{"op":"mcm","clk":"11838047990","pt":1723180646165,"mc":[{"id":"1.231581347","rc":[{"batb":[[0,3.4,4],[1,3.35,16.13],[2,1.88,171.56]],"ltp":3.5,"tv":19.34,"id":12474498}]}]}
{"op":"mcm","clk":"11838048105","pt":1723180648632,"mc":[{"id":"1.231581347","rc":[{"batb":[[0,3.45,10]],"ltp":3.5,"tv":19.34,"id":12474498}]}]}
{"op":"mcm","clk":"11838048254","pt":1723180652435,"mc":[{"id":"1.231581347","rc":[{"batb":[[0,3.4,4]],"ltp":3.5,"tv":19.34,"id":12474498}]}]}
{"op":"mcm","clk":"11838048343","pt":1723180654845,"mc":[{"id":"1.231581347","rc":[{"batb":[[0,3.45,10]],"ltp":3.5,"tv":19.34,"id":12474498}]}]}
{"op":"mcm","clk":"11838048460","pt":1723180658952,"mc":[{"id":"1.231581347","rc":[{"batb":[[0,3.35,16.13],[1,1.88,171.56],[2,1.87,171.31]],"ltp":3.5,"tv":19.34,"id":12474498}]}]}
{"op":"mcm","clk":"11838048468","pt":1723180659053,"mc":[{"id":"1.231581347","rc":[{"batb":[[0,3.5,4],[1,3.35,16.13],[2,1.88,171.56]],"ltp":3.5,"tv":19.34,"id":12474498}]}]}
{"op":"mcm","clk":"11838048550","pt":1723180661973,"mc":[{"id":"1.231581347","rc":[{"batb":[[0,3.35,16.13],[1,1.88,171.56],[2,1.87,171.31]],"ltp":3.5,"tv":19.34,"id":12474498}]}]}
{"op":"mcm","clk":"11838048558","pt":1723180662279,"mc":[{"id":"1.231581347","rc":[{"batb":[[0,3.4,10],[1,3.35,16.13],[2,1.88,171.56]],"ltp":3.5,"tv":19.34,"id":12474498}]}]}
{"op":"mcm","clk":"11838048723","pt":1723180665680,"mc":[{"id":"1.231581347","rc":[{"batb":[[0,3.4,4]],"ltp":3.5,"tv":19.34,"id":12474498}]}]}
{"op":"mcm","clk":"11838048825","pt":1723180667954,"mc":[{"id":"1.231581347","rc":[{"batb":[[0,3.35,16.13],[1,1.88,171.56],[2,1.87,171.31]],"ltp":3.5,"tv":19.34,"id":12474498}]}]}
{"op":"mcm","clk":"11838048835","pt":1723180668261,"mc":[{"id":"1.231581347","rc":[{"batb":[[0,3.4,10],[1,3.35,16.13],[2,1.88,171.56]],"ltp":3.5,"tv":19.34,"id":12474498}]}]}
{"op":"mcm","clk":"11838048889","pt":1723180670465,"mc":[{"id":"1.231581347","rc":[{"batb":[[0,3.45,4],[1,3.4,10],[2,3.35,16.13]],"ltp":3.5,"tv":19.34,"id":12474498}]}]}
{"op":"mcm","clk":"11838048932","pt":1723180671693,"mc":[{"id":"1.231581347","rc":[{"batb":[[1,3.35,16.13],[2,1.88,171.56]],"ltp":3.5,"tv":19.34,"id":12474498}]}]}
{"op":"mcm","clk":"11838048974","pt":1723180672770,"mc":[{"id":"1.231581347","rc":[{"batb":[[0,3.35,16.13],[1,1.88,171.56],[2,1.87,171.31]],"ltp":3.5,"tv":19.34,"id":12474498}]}]}
{"op":"mcm","clk":"11838049066","pt":1723180675284,"mc":[{"id":"1.231581347","rc":[{"batb":[[0,3.4,14],[1,3.35,16.13],[2,1.88,171.56]],"ltp":3.5,"tv":19.34,"id":12474498}]}]}
{"op":"mcm","clk":"11838049152","pt":1723180677694,"mc":[{"id":"1.231581347","rc":[{"batb":[[0,3.4,10]],"ltp":3.5,"tv":19.34,"id":12474498}]}]}
{"op":"mcm","clk":"11838049188","pt":1723180678465,"mc":[{"id":"1.231581347","rc":[{"batb":[[0,3.35,16.13],[1,1.88,171.56],[2,1.87,171.31]],"ltp":3.5,"tv":19.34,"id":12474498}]}]}
{"op":"mcm","clk":"11838049289","pt":1723180680871,"mc":[{"id":"1.231581347","rc":[{"batb":[[0,3.4,14],[1,3.35,16.13],[2,1.88,171.56]],"ltp":3.5,"tv":19.34,"id":12474498}]}]}
{"op":"mcm","clk":"11838049403","pt":1723180683285,"mc":[{"id":"1.231581347","rc":[{"batb":[[0,3.4,10]],"ltp":3.5,"tv":19.34,"id":12474498}]}]}
{"op":"mcm","clk":"11838049431","pt":1723180684215,"mc":[{"id":"1.231581347","rc":[{"batb":[[0,3.35,16.13],[1,1.88,171.56],[2,1.87,171.31]],"ltp":3.5,"tv":19.34,"id":12474498}]}]}
{"op":"mcm","clk":"11838049486","pt":1723180685497,"mc":[{"id":"1.231581347","rc":[{"batb":[[0,3.4,4],[1,3.35,16.13],[2,1.88,171.56]],"ltp":3.5,"tv":19.34,"id":12474498}]}]}
{"op":"mcm","clk":"11838049539","pt":1723180686570,"mc":[{"id":"1.231581347","rc":[{"batb":[[0,3.45,10],[1,3.4,4],[2,3.35,16.13]],"ltp":3.5,"tv":19.34,"id":12474498}]}]}
{"op":"mcm","clk":"11838049595","pt":1723180687899,"mc":[{"id":"1.231581347","rc":[{"batb":[[1,3.35,16.13],[2,1.88,171.56]],"ltp":3.5,"tv":19.34,"id":12474498}]}]}
{"op":"mcm","clk":"11838049668","pt":1723180690202,"mc":[{"id":"1.231581347","rc":[{"batb":[[0,3.4,4]],"ltp":3.5,"tv":19.34,"id":12474498}]}]}
{"op":"mcm","clk":"11838049749","pt":1723180692516,"mc":[{"id":"1.231581347","rc":[{"batb":[[0,3.4,10]],"ltp":3.5,"tv":19.34,"id":12474498}]}]}
{"op":"mcm","clk":"11838049870","pt":1723180696201,"mc":[{"id":"1.231581347","rc":[{"batb":[[0,3.45,4]],"ltp":3.5,"tv":19.34,"id":12474498}]}]}
{"op":"mcm","clk":"11838049968","pt":1723180698809,"mc":[{"id":"1.231581347","rc":[{"batb":[[0,3.35,16.13],[1,1.88,171.56],[2,1.87,171.31]],"ltp":3.5,"tv":19.34,"id":12474498}]}]}
{"op":"mcm","clk":"11838049980","pt":1723180699114,"mc":[{"id":"1.231581347","rc":[{"batb":[[0,3.4,10],[1,3.35,16.13],[2,1.88,171.56]],"ltp":3.5,"tv":19.34,"id":12474498}]}]}
{"op":"mcm","clk":"11838050103","pt":1723180702594,"mc":[{"id":"1.231581347","rc":[{"batb":[[0,3.4,4]],"ltp":3.5,"tv":19.34,"id":12474498}]}]}
{"op":"mcm","clk":"11838050198","pt":1723180705413,"mc":[{"id":"1.231581347","rc":[{"batb":[[0,3.4,10]],"ltp":3.5,"tv":19.34,"id":12474498}]}]}
{"op":"mcm","clk":"11838050317","pt":1723180708742,"mc":[{"id":"1.231581347","rc":[{"batb":[[0,3.35,16.13],[1,1.88,171.56],[2,1.87,171.31]],"ltp":3.5,"tv":19.34,"id":12474498}]}]}
{"op":"mcm","clk":"11838050327","pt":1723180709048,"mc":[{"id":"1.231581347","rc":[{"batb":[[0,3.4,4],[1,3.35,16.13],[2,1.88,171.56]],"ltp":3.5,"tv":19.34,"id":12474498}]}]}
{"op":"mcm","clk":"11838050414","pt":1723180711350,"mc":[{"id":"1.231581347","rc":[{"batb":[[0,3.45,10]],"ltp":3.5,"tv":19.34,"id":12474498}]}]}
{"op":"mcm","clk":"11838050484","pt":1723180713757,"mc":[{"id":"1.231581347","rc":[{"batb":[[0,3.5,4],[1,3.45,10],[2,3.35,16.13]],"ltp":3.5,"tv":19.34,"id":12474498}]}]}
{"op":"mcm","clk":"11838050507","pt":1723180714731,"mc":[{"id":"1.231581347","rc":[{"batb":[[0,3.5,8.01]],"ltp":3.5,"tv":19.34,"id":12474498}]}]}
{"op":"mcm","clk":"11838050516","pt":1723180715064,"mc":[{"id":"1.231581347","rc":[{"batb":[[1,3.35,16.13],[2,1.88,171.56]],"ltp":3.5,"tv":19.34,"id":12474498}]}]}
{"op":"mcm","clk":"11838050554","pt":1723180716117,"mc":[{"id":"1.231581347","rc":[{"batb":[[0,3.5,4.01]],"ltp":3.5,"tv":19.34,"id":12474498}]}]}
{"op":"mcm","clk":"11838050609","pt":1723180717357,"mc":[{"id":"1.231581347","rc":[{"batb":[[0,3.5,10],[1,3.45,4.06],[2,3.35,16.13]],"ltp":3.5,"tv":19.34,"id":12474498}]}]}
{"op":"mcm","clk":"11838050681","pt":1723180719053,"mc":[{"id":"1.231581347","rc":[{"batb":[[0,3.55,4],[1,3.5,10],[2,3.45,4.06]],"ltp":3.5,"tv":19.34,"id":12474498}]}]}
{"op":"mcm","clk":"11838050737","pt":1723180720741,"mc":[{"id":"1.231581347","rc":[{"batb":[[1,3.35,16.13],[2,1.88,171.56]],"ltp":3.5,"tv":19.34,"id":12474498}]}]}
{"op":"mcm","clk":"11838050781","pt":1723180721717,"mc":[{"id":"1.231581347","rc":[{"batb":[[0,3.35,16.13],[1,1.88,171.56],[2,1.87,171.31]],"ltp":3.5,"tv":19.34,"id":12474498}]}]}
{"op":"mcm","clk":"11838050863","pt":1723180724051,"mc":[{"id":"1.231581347","rc":[{"batb":[[0,3.4,14],[1,3.35,16.13],[2,1.88,171.56]],"ltp":3.5,"tv":19.34,"id":12474498}]}]}
{"op":"mcm","clk":"11838050963","pt":1723180726731,"mc":[{"id":"1.231581347","rc":[{"batb":[[0,3.4,10]],"ltp":3.5,"tv":19.34,"id":12474498}]}]}
{"op":"mcm","clk":"11838050994","pt":1723180727764,"mc":[{"id":"1.231581347","rc":[{"batb":[[0,3.35,16.13],[1,1.88,171.56],[2,1.87,171.31]],"ltp":3.5,"tv":19.34,"id":12474498}]}]}
{"op":"mcm","clk":"11838051032","pt":1723180728943,"mc":[{"id":"1.231581347","rc":[{"batb":[[0,3.4,4],[1,3.35,16.13],[2,1.88,171.56]],"ltp":3.5,"tv":19.34,"id":12474498}]}]}
{"op":"mcm","clk":"11838051081","pt":1723180730272,"mc":[{"id":"1.231581347","rc":[{"batb":[[0,3.45,10],[1,3.4,4],[2,3.35,16.13]],"ltp":3.5,"tv":19.34,"id":12474498}]}]}
{"op":"mcm","clk":"11838051135","pt":1723180731763,"mc":[{"id":"1.231581347","rc":[{"batb":[[1,3.35,16.13],[2,1.88,171.56]],"ltp":3.5,"tv":19.34,"id":12474498}]}]}
{"op":"mcm","clk":"11838051204","pt":1723180733446,"mc":[{"id":"1.231581347","rc":[{"batb":[[0,3.35,16.13],[1,1.88,171.56],[2,1.87,171.31]],"ltp":3.5,"tv":19.34,"id":12474498}]}]}
{"op":"mcm","clk":"11838051319","pt":1723180736365,"mc":[{"id":"1.231581347","rc":[{"batb":[[0,3.4,14],[1,3.35,16.13],[2,1.88,171.56]],"ltp":3.5,"tv":19.34,"id":12474498}]}]}
{"op":"mcm","clk":"11838051406","pt":1723180738868,"mc":[{"id":"1.231581347","rc":[{"batb":[[0,3.4,10]],"ltp":3.5,"tv":19.34,"id":12474498}]}]}
{"op":"mcm","clk":"11838051433","pt":1723180739888,"mc":[{"id":"1.231581347","rc":[{"batb":[[0,3.35,16.13],[1,1.88,171.56],[2,1.87,171.31]],"ltp":3.5,"tv":19.34,"id":12474498}]}]}
{"op":"mcm","clk":"11838051649","pt":1723180745000,"mc":[{"id":"1.231581347","rc":[{"batb":[[0,3.4,14],[1,3.35,16.13],[2,1.88,171.56]],"ltp":3.5,"tv":19.34,"id":12474498}]}]}
{"op":"mcm","clk":"11838051730","pt":1723180747307,"mc":[{"id":"1.231581347","rc":[{"batb":[[0,3.4,10]],"ltp":3.5,"tv":19.34,"id":12474498}]}]}
{"op":"mcm","clk":"11838051765","pt":1723180748285,"mc":[{"id":"1.231581347","rc":[{"batb":[[0,3.35,16.13],[1,1.88,171.56],[2,1.87,171.31]],"ltp":3.5,"tv":19.34,"id":12474498}]}]}
{"op":"mcm","clk":"11838051819","pt":1723180749660,"mc":[{"id":"1.231581347","rc":[{"batb":[[0,3.4,4],[1,3.35,16.13],[2,1.88,171.56]],"ltp":3.5,"tv":19.34,"id":12474498}]}]}
{"op":"mcm","clk":"11838051873","pt":1723180751000,"mc":[{"id":"1.231581347","rc":[{"batb":[[0,3.45,10],[1,3.4,4],[2,3.35,16.13]],"ltp":3.5,"tv":19.34,"id":12474498}]}]}
{"op":"mcm","clk":"11838051934","pt":1723180752086,"mc":[{"id":"1.231581347","rc":[{"batb":[[1,3.35,16.13],[2,1.88,171.56]],"ltp":3.5,"tv":19.34,"id":12474498}]}]}
{"op":"mcm","clk":"11838052025","pt":1723180754694,"mc":[{"id":"1.231581347","rc":[{"batb":[[0,3.4,4]],"ltp":3.5,"tv":19.34,"id":12474498}]}]}
{"op":"mcm","clk":"11838052131","pt":1723180757203,"mc":[{"id":"1.231581347","rc":[{"batb":[[0,3.45,10]],"ltp":3.5,"tv":19.34,"id":12474498}]}]}
{"op":"mcm","clk":"11838052243","pt":1723180760628,"mc":[{"id":"1.231581347","rc":[{"batb":[[0,3.5,4]],"ltp":3.5,"tv":19.34,"id":12474498}]}]}
{"op":"mcm","clk":"11838052352","pt":1723180763304,"mc":[{"id":"1.231581347","rc":[{"batb":[[0,3.4,10]],"ltp":3.5,"tv":19.34,"id":12474498}]}]}
{"op":"mcm","clk":"11838052468","pt":1723180766684,"mc":[{"id":"1.231581347","rc":[{"batb":[[0,3.4,4]],"ltp":3.5,"tv":19.34,"id":12474498}]}]}
{"op":"mcm","clk":"11838052544","pt":1723180769301,"mc":[{"id":"1.231581347","rc":[{"batb":[[0,3.4,10]],"ltp":3.5,"tv":19.34,"id":12474498}]}]}
{"op":"mcm","clk":"11838052626","pt":1723180772837,"mc":[{"id":"1.231581347","rc":[{"batb":[[0,3.35,16.13],[1,1.88,171.56],[2,1.87,171.31]],"ltp":3.5,"tv":19.34,"id":12474498}]}]}
{"op":"mcm","clk":"11838052632","pt":1723180773043,"mc":[{"id":"1.231581347","rc":[{"batb":[[0,3.4,4],[1,3.35,16.13],[2,1.88,171.56]],"ltp":3.5,"tv":19.34,"id":12474498}]}]}
{"op":"mcm","clk":"11838052689","pt":1723180775419,"mc":[{"id":"1.231581347","rc":[{"batb":[[0,3.4,10]],"ltp":3.5,"tv":19.34,"id":12474498}]}]}
{"op":"mcm","clk":"11838052829","pt":1723180778730,"mc":[{"id":"1.231581347","rc":[{"batb":[[0,3.45,4]],"ltp":3.5,"tv":19.34,"id":12474498}]}]}
{"op":"mcm","clk":"11838052902","pt":1723180780539,"mc":[{"id":"1.231581347","rc":[{"batb":[[0,3.35,16.13],[1,1.88,171.56],[2,1.87,171.31]],"ltp":3.5,"tv":19.34,"id":12474498}]}]}
{"op":"mcm","clk":"11838052958","pt":1723180781727,"mc":[{"id":"1.231581347","rc":[{"batb":[[0,3.4,10],[1,3.35,16.13],[2,1.88,171.56]],"ltp":3.5,"tv":19.34,"id":12474498}]}]}
{"op":"mcm","clk":"11838053013","pt":1723180782956,"mc":[{"id":"1.231581347","rc":[{"batb":[[0,3.45,4],[1,3.4,10],[2,3.35,16.13]],"ltp":3.5,"tv":19.34,"id":12474498}]}]}
{"op":"mcm","clk":"11838053103","pt":1723180785429,"mc":[{"id":"1.231581347","rc":[{"batb":[[0,3.35,16.13],[1,1.88,171.56],[2,1.87,171.31]],"ltp":3.5,"tv":19.34,"id":12474498}]}]}
{"op":"mcm","clk":"11838053186","pt":1723180787947,"mc":[{"id":"1.231581347","rc":[{"batb":[[0,3.4,14],[1,3.35,16.13],[2,1.88,171.56]],"ltp":3.5,"tv":19.34,"id":12474498}]}]}
{"op":"mcm","clk":"11838053279","pt":1723180790363,"mc":[{"id":"1.231581347","rc":[{"batb":[[0,3.4,10]],"ltp":3.5,"tv":19.34,"id":12474498}]}]}
{"op":"mcm","clk":"11838053312","pt":1723180791348,"mc":[{"id":"1.231581347","rc":[{"batb":[[0,3.35,16.13],[1,1.88,171.56],[2,1.87,171.31]],"ltp":3.5,"tv":19.34,"id":12474498}]}]}
{"op":"mcm","clk":"11838053515","pt":1723180796389,"mc":[{"id":"1.231581347","rc":[{"batb":[[0,3.4,14],[1,3.35,16.13],[2,1.88,171.56]],"ltp":3.5,"tv":19.34,"id":12474498}]}]}
{"op":"mcm","clk":"11838053612","pt":1723180798867,"mc":[{"id":"1.231581347","rc":[{"batb":[[0,3.4,10]],"ltp":3.5,"tv":19.34,"id":12474498}]}]}
{"op":"mcm","clk":"11838053652","pt":1723180799991,"mc":[{"id":"1.231581347","rc":[{"batb":[[0,3.35,16.13],[1,1.88,171.56],[2,1.87,171.31]],"ltp":3.5,"tv":19.34,"id":12474498}]}]}
{"op":"mcm","clk":"11838053688","pt":1723180801193,"mc":[{"id":"1.231581347","rc":[{"batb":[[0,3.4,4],[1,3.35,16.13],[2,1.88,171.56]],"ltp":3.5,"tv":19.34,"id":12474498}]}]}
{"op":"mcm","clk":"11838053768","pt":1723180802692,"mc":[{"id":"1.231581347","rc":[{"batb":[[0,3.45,10],[1,3.4,4],[2,3.35,16.13]],"ltp":3.5,"tv":19.34,"id":12474498}]}]}
{"op":"mcm","clk":"11838053803","pt":1723180803675,"mc":[{"id":"1.231581347","rc":[{"batb":[[1,3.35,16.13],[2,1.88,171.56]],"ltp":3.5,"tv":19.34,"id":12474498}]}]}
{"op":"mcm","clk":"11838053901","pt":1723180805990,"mc":[{"id":"1.231581347","rc":[{"batb":[[0,3.35,16.13],[1,1.88,171.56],[2,1.87,171.31]],"ltp":3.5,"tv":19.34,"id":12474498}]}]}
{"op":"mcm","clk":"11838053912","pt":1723180806198,"mc":[{"id":"1.231581347","rc":[{"batb":[[0,3.5,4],[1,3.35,16.13],[2,1.88,171.56]],"ltp":3.5,"tv":19.34,"id":12474498}]}]}
{"op":"mcm","clk":"11838054030","pt":1723180808766,"mc":[{"id":"1.231581347","rc":[{"batb":[[0,3.4,10]],"ltp":3.5,"tv":19.34,"id":12474498}]}]}
{"op":"mcm","clk":"11838054141","pt":1723180811491,"mc":[{"id":"1.231581347","rc":[{"batb":[[0,3.45,4],[1,3.4,10],[2,3.35,16.13]],"ltp":3.5,"tv":19.34,"id":12474498}]}]}
{"op":"mcm","clk":"11838054163","pt":1723180812106,"mc":[{"id":"1.231581347","rc":[{"batb":[[1,3.35,16.13],[2,1.88,171.56]],"ltp":3.5,"tv":19.34,"id":12474498}]}]}
{"op":"mcm","clk":"11838054238","pt":1723180814003,"mc":[{"id":"1.231581347","rc":[{"batb":[[0,3.35,16.13],[1,1.88,171.56],[2,1.87,171.31]],"ltp":3.5,"tv":19.34,"id":12474498}]}]}
{"op":"mcm","clk":"11838054333","pt":1723180817195,"mc":[{"id":"1.231581347","rc":[{"batb":[[0,3.4,14],[1,3.35,16.13],[2,1.88,171.56]],"ltp":3.5,"tv":19.34,"id":12474498}]}]}
{"op":"mcm","clk":"11838054427","pt":1723180819708,"mc":[{"id":"1.231581347","rc":[{"batb":[[0,3.4,10]],"ltp":3.5,"tv":19.34,"id":12474498}]}]}
{"op":"mcm","clk":"11838054457","pt":1723180820688,"mc":[{"id":"1.231581347","rc":[{"batb":[[0,3.35,16.13],[1,1.88,171.56],[2,1.87,171.31]],"ltp":3.5,"tv":19.34,"id":12474498}]}]}
{"op":"mcm","clk":"11838054503","pt":1723180822020,"mc":[{"id":"1.231581347","rc":[{"batb":[[0,3.4,4],[1,3.35,16.13],[2,1.88,171.56]],"ltp":3.5,"tv":19.34,"id":12474498}]}]}
{"op":"mcm","clk":"11838054605","pt":1723180824504,"mc":[{"id":"1.231581347","rc":[{"batb":[[0,3.45,10]],"ltp":3.5,"tv":19.34,"id":12474498}]}]}
{"op":"mcm","clk":"11838054734","pt":1723180827599,"mc":[{"id":"1.231581347","rc":[{"batb":[[0,3.4,4]],"ltp":3.5,"tv":19.34,"id":12474498}]}]}
{"op":"mcm","clk":"11838054824","pt":1723180830333,"mc":[{"id":"1.231581347","rc":[{"batb":[[0,3.4,10]],"ltp":3.5,"tv":19.34,"id":12474498}]}]}
{"op":"mcm","clk":"11838054918","pt":1723180832913,"mc":[{"id":"1.231581347","rc":[{"batb":[[0,3.45,4],[1,3.4,10],[2,3.35,16.13]],"ltp":3.5,"tv":19.34,"id":12474498}]}]}
{"op":"mcm","clk":"11838054953","pt":1723180833725,"mc":[{"id":"1.231581347","rc":[{"batb":[[1,3.35,16.13],[2,1.88,171.56]],"ltp":3.5,"tv":19.34,"id":12474498}]}]}
{"op":"mcm","clk":"11838055005","pt":1723180835414,"mc":[{"id":"1.231581347","rc":[{"batb":[[0,3.35,16.13],[1,1.88,171.56],[2,1.87,171.31]],"ltp":3.5,"tv":19.34,"id":12474498}]}]}
{"op":"mcm","clk":"11838055179","pt":1723180839524,"mc":[{"id":"1.231581347","rc":[{"batb":[[0,3.4,14],[1,3.35,16.13],[2,1.88,171.56]],"ltp":3.5,"tv":19.34,"id":12474498}]}]}
{"op":"mcm","clk":"11838055260","pt":1723180841936,"mc":[{"id":"1.231581347","rc":[{"batb":[[0,3.45,4.86],[1,3.4,10],[2,3.35,16.13]],"ltp":3.5,"tv":19.34,"id":12474498}]}]}
{"op":"mcm","clk":"11838055296","pt":1723180842914,"mc":[{"id":"1.231581347","rc":[{"batb":[[1,3.35,16.13],[2,1.88,171.56]],"ltp":3.5,"tv":19.34,"id":12474498}]}]}
{"op":"mcm","clk":"11838055317","pt":1723180843530,"mc":[{"id":"1.231581347","rc":[{"batb":[[0,3.35,16.13],[1,1.88,171.56],[2,1.87,171.31]],"ltp":3.5,"tv":19.34,"id":12474498}]}]}
{"op":"mcm","clk":"11838055366","pt":1723180845223,"mc":[{"id":"1.231581347","rc":[{"batb":[[0,3.4,14],[1,3.35,16.13],[2,1.88,171.56]],"ltp":3.5,"tv":19.34,"id":12474498}]}]}
{"op":"mcm","clk":"11838055480","pt":1723180847859,"mc":[{"id":"1.231581347","rc":[{"batb":[[0,3.4,10]],"ltp":3.5,"tv":19.34,"id":12474498}]}]}
{"op":"mcm","clk":"11838055514","pt":1723180848728,"mc":[{"id":"1.231581347","rc":[{"batb":[[0,3.35,16.13],[1,1.88,171.56],[2,1.87,171.31]],"ltp":3.5,"tv":19.34,"id":12474498}]}]}
{"op":"mcm","clk":"11838055567","pt":1723180850423,"mc":[{"id":"1.231581347","rc":[{"batb":[[0,3.4,4],[1,3.35,16.13],[2,1.88,171.56]],"ltp":3.5,"tv":19.34,"id":12474498}]}]}
{"op":"mcm","clk":"11838055653","pt":1723180852632,"mc":[{"id":"1.231581347","rc":[{"batb":[[0,3.45,10]],"ltp":3.5,"tv":19.34,"id":12474498}]}]}
{"op":"mcm","clk":"11838055761","pt":1723180855355,"mc":[{"id":"1.231581347","rc":[{"batb":[[0,3.5,4]],"ltp":3.5,"tv":19.34,"id":12474498}]}]}
{"op":"mcm","clk":"11838055852","pt":1723180857867,"mc":[{"id":"1.231581347","rc":[{"batb":[[0,3.35,16.13],[1,1.88,171.56],[2,1.87,171.31]],"ltp":3.5,"tv":19.34,"id":12474498}]}]}
{"op":"mcm","clk":"11838055868","pt":1723180858280,"mc":[{"id":"1.231581347","rc":[{"batb":[[0,3.4,10],[1,3.35,16.13],[2,1.88,171.56]],"ltp":3.5,"tv":19.34,"id":12474498}]}]}
{"op":"mcm","clk":"11838055942","pt":1723180860448,"mc":[{"id":"1.231581347","rc":[{"batb":[[0,3.5,4],[1,3.45,4.06],[2,3.4,10]],"ltp":3.5,"tv":19.34,"id":12474498}]}]}
{"op":"mcm","clk":"11838055985","pt":1723180861680,"mc":[{"id":"1.231581347","rc":[{"batb":[[2,3.35,16.13]],"ltp":3.5,"tv":19.34,"id":12474498}]}]}
{"op":"mcm","clk":"11838056026","pt":1723180862864,"mc":[{"id":"1.231581347","rc":[{"batb":[[0,3.45,4.06],[1,3.35,16.13],[2,1.88,171.56]],"ltp":3.5,"tv":19.34,"id":12474498}]}]}
{"op":"mcm","clk":"11838056113","pt":1723180865684,"mc":[{"id":"1.231581347","rc":[{"batb":[[0,3.5,14],[1,3.45,4.06],[2,3.35,16.13]],"ltp":3.5,"tv":19.34,"id":12474498}]}]}
{"op":"mcm","clk":"11838056201","pt":1723180867792,"mc":[{"id":"1.231581347","rc":[{"batb":[[0,3.55,3.95],[1,3.5,14]],"ltp":3.5,"tv":19.34,"id":12474498}]}]}
{"op":"mcm","clk":"11838056227","pt":1723180868257,"mc":[{"id":"1.231581347","rc":[{"batb":[[1,3.5,10]],"ltp":3.5,"tv":19.34,"id":12474498}]}]}
{"op":"mcm","clk":"11838056263","pt":1723180869075,"mc":[{"id":"1.231581347","rc":[{"batb":[[1,3.35,16.13],[2,1.88,171.56]],"ltp":3.5,"tv":19.34,"id":12474498}]}]}
{"op":"mcm","clk":"11838056337","pt":1723180870676,"mc":[{"id":"1.231581347","rc":[{"batb":[[0,3.6,4],[1,3.55,3.95],[2,3.35,16.13]],"ltp":3.5,"tv":19.34,"id":12474498}]}]}
{"op":"mcm","clk":"11838056408","pt":1723180872266,"mc":[{"id":"1.231581347","rc":[{"batb":[[1,3.35,16.13],[2,1.88,171.56]],"ltp":3.5,"tv":19.34,"id":12474498}]}]}
{"op":"mcm","clk":"11838056460","pt":1723180873599,"mc":[{"id":"1.231581347","rc":[{"batb":[[0,3.4,10]],"ltp":3.5,"tv":19.34,"id":12474498}]}]}
{"op":"mcm","clk":"11838056523","pt":1723180875595,"mc":[{"id":"1.231581347","rc":[{"batb":[[0,3.45,4],[1,3.4,10],[2,3.35,16.13]],"ltp":3.5,"tv":19.34,"id":12474498}]}]}
{"op":"mcm","clk":"11838056607","pt":1723180877961,"mc":[{"id":"1.231581347","rc":[{"batb":[[0,3.35,16.13],[1,1.88,171.56],[2,1.87,171.31]],"ltp":3.5,"tv":19.34,"id":12474498}]}]}
{"op":"mcm","clk":"11838056678","pt":1723180879703,"mc":[{"id":"1.231581347","rc":[{"batb":[[0,3.4,10],[1,3.35,16.13],[2,1.88,171.56]],"ltp":3.5,"tv":19.34,"id":12474498}]}]}
{"op":"mcm","clk":"11838056746","pt":1723180881499,"mc":[{"id":"1.231581347","rc":[{"batb":[[0,3.45,4],[1,3.4,10],[2,3.35,16.13]],"ltp":3.5,"tv":19.34,"id":12474498}]}]}
{"op":"mcm","clk":"11838056851","pt":1723180883912,"mc":[{"id":"1.231581347","rc":[{"batb":[[0,3.35,16.13],[1,1.88,171.56],[2,1.87,171.31]],"ltp":3.5,"tv":19.34,"id":12474498}]}]}
{"op":"mcm","clk":"11838056911","pt":1723180885296,"mc":[{"id":"1.231581347","rc":[{"batb":[[0,3.4,10],[1,3.35,16.13],[2,1.88,171.56]],"ltp":3.5,"tv":19.34,"id":12474498}]}]}
{"op":"mcm","clk":"11838056991","pt":1723180887498,"mc":[{"id":"1.231581347","rc":[{"batb":[[0,3.45,4],[1,3.4,10],[2,3.35,16.13]],"ltp":3.5,"tv":19.34,"id":12474498}]}]}
{"op":"mcm","clk":"11838057031","pt":1723180888580,"mc":[{"id":"1.231581347","rc":[{"batb":[[1,3.35,16.13],[2,1.88,171.56]],"ltp":3.5,"tv":19.34,"id":12474498}]}]}
{"op":"mcm","clk":"11838057082","pt":1723180890113,"mc":[{"id":"1.231581347","rc":[{"batb":[[0,3.35,16.13],[1,1.88,171.56],[2,1.87,171.31]],"ltp":3.5,"tv":19.34,"id":12474498}]}]}
{"op":"mcm","clk":"11838057289","pt":1723180894997,"mc":[{"id":"1.231581347","rc":[{"batb":[[0,3.4,14],[1,3.35,16.13],[2,1.88,171.56]],"ltp":3.5,"tv":19.34,"id":12474498}]}]}
{"op":"mcm","clk":"11838057345","pt":1723180896591,"mc":[{"id":"1.231581347","rc":[{"batb":[[0,3.45,4.86],[1,3.4,14],[2,3.35,16.13]],"ltp":3.5,"tv":19.34,"id":12474498}]}]}
{"op":"mcm","clk":"11838057379","pt":1723180897203,"mc":[{"id":"1.231581347","rc":[{"batb":[[1,3.4,10]],"ltp":3.5,"tv":19.34,"id":12474498}]}]}
{"op":"mcm","clk":"11838057423","pt":1723180898332,"mc":[{"id":"1.231581347","rc":[{"batb":[[1,3.35,16.13],[2,1.88,171.56]],"ltp":3.5,"tv":19.34,"id":12474498}]}]}
{"op":"mcm","clk":"11838057480","pt":1723180899722,"mc":[{"id":"1.231581347","rc":[{"batb":[[0,3.35,16.13],[1,1.88,171.56],[2,1.87,171.31]],"ltp":3.5,"tv":19.34,"id":12474498}]}]}
{"op":"mcm","clk":"11838057495","pt":1723180900029,"mc":[{"id":"1.231581347","rc":[{"batb":[[0,3.4,4],[1,3.35,16.13],[2,1.88,171.56]],"ltp":3.5,"tv":19.34,"id":12474498}]}]}
{"op":"mcm","clk":"11838057594","pt":1723180902901,"mc":[{"id":"1.231581347","rc":[{"batb":[[0,3.4,10]],"ltp":3.5,"tv":19.34,"id":12474498}]}]}
{"op":"mcm","clk":"11838057658","pt":1723180904900,"mc":[{"id":"1.231581347","rc":[{"batb":[[0,3.45,4],[1,3.4,10],[2,3.35,16.13]],"ltp":3.5,"tv":19.34,"id":12474498}]}]}
{"op":"mcm","clk":"11838057704","pt":1723180906533,"mc":[{"id":"1.231581347","rc":[{"batb":[[1,3.35,16.13],[2,1.88,171.56]],"ltp":3.5,"tv":19.34,"id":12474498}]}]}
{"op":"mcm","clk":"11838057728","pt":1723180907402,"mc":[{"id":"1.231581347","rc":[{"batb":[[0,3.35,16.13],[1,1.88,171.56],[2,1.87,171.31]],"ltp":3.5,"tv":19.34,"id":12474498}]}]}
{"op":"mcm","clk":"11838057812","pt":1723180909705,"mc":[{"id":"1.231581347","rc":[{"batb":[[0,3.4,14],[1,3.35,16.13],[2,1.88,171.56]],"ltp":3.5,"tv":19.34,"id":12474498}]}]}
{"op":"mcm","clk":"11838057905","pt":1723180912208,"mc":[{"id":"1.231581347","rc":[{"batb":[[0,3.4,10]],"ltp":3.5,"tv":19.34,"id":12474498}]}]}
{"op":"mcm","clk":"11838057945","pt":1723180913228,"mc":[{"id":"1.231581347","rc":[{"batb":[[0,3.35,16.13],[1,1.88,171.56],[2,1.87,171.31]],"ltp":3.5,"tv":19.34,"id":12474498}]}]}
{"op":"mcm","clk":"11838058044","pt":1723180915832,"mc":[{"id":"1.231581347","rc":[{"batb":[[0,3.4,14],[1,3.35,16.13],[2,1.88,171.56]],"ltp":3.5,"tv":19.34,"id":12474498}]}]}
{"op":"mcm","clk":"11838058131","pt":1723180918437,"mc":[{"id":"1.231581347","rc":[{"batb":[[0,3.4,10]],"ltp":3.5,"tv":19.34,"id":12474498}]}]}
{"op":"mcm","clk":"11838058169","pt":1723180919414,"mc":[{"id":"1.231581347","rc":[{"batb":[[0,3.35,16.13],[1,1.88,171.56],[2,1.87,171.31]],"ltp":3.5,"tv":19.34,"id":12474498}]}]}
{"op":"mcm","clk":"11838058365","pt":1723180923721,"mc":[{"id":"1.231581347","rc":[{"batb":[[0,3.4,14],[1,3.35,16.13],[2,1.88,171.56]],"ltp":3.5,"tv":19.34,"id":12474498}]}]}
{"op":"mcm","clk":"11838058461","pt":1723180926444,"mc":[{"id":"1.231581347","rc":[{"batb":[[0,3.4,10]],"ltp":3.5,"tv":19.34,"id":12474498}]}]}
{"op":"mcm","clk":"11838058494","pt":1723180927153,"mc":[{"id":"1.231581347","rc":[{"batb":[[0,3.35,16.13],[1,1.88,171.56],[2,1.87,171.31]],"ltp":3.5,"tv":19.34,"id":12474498}]}]}
{"op":"mcm","clk":"11838058575","pt":1723180928740,"mc":[{"id":"1.231581347","rc":[{"batb":[[0,3.4,4],[1,3.35,16.13],[2,1.88,171.56]],"ltp":3.5,"tv":19.34,"id":12474498}]}]}
{"op":"mcm","clk":"11838058633","pt":1723180930131,"mc":[{"id":"1.231581347","rc":[{"batb":[[0,3.45,10],[1,3.4,4],[2,3.35,16.13]],"ltp":3.5,"tv":19.34,"id":12474498}]}]}
{"op":"mcm","clk":"11838058680","pt":1723180931257,"mc":[{"id":"1.231581347","rc":[{"batb":[[1,3.35,16.13],[2,1.88,171.56]],"ltp":3.5,"tv":19.34,"id":12474498}]}]}
{"op":"mcm","clk":"11838058799","pt":1723180933670,"mc":[{"id":"1.231581347","rc":[{"batb":[[0,3.5,4]],"ltp":3.5,"tv":19.34,"id":12474498}]}]}
{"op":"mcm","clk":"11838058909","pt":1723180936855,"mc":[{"id":"1.231581347","rc":[{"batb":[[0,3.4,10]],"ltp":3.5,"tv":19.34,"id":12474498}]}]}
{"op":"mcm","clk":"11838059013","pt":1723180939371,"mc":[{"id":"1.231581347","rc":[{"batb":[[0,3.45,4],[1,3.4,10],[2,3.35,16.13]],"ltp":3.5,"tv":19.34,"id":12474498}]}]}
{"op":"mcm","clk":"11838059048","pt":1723180940341,"mc":[{"id":"1.231581347","rc":[{"batb":[[1,3.35,16.13],[2,1.88,171.56]],"ltp":3.5,"tv":19.34,"id":12474498}]}]}
{"op":"mcm","clk":"11838059087","pt":1723180941775,"mc":[{"id":"1.231581347","rc":[{"batb":[[0,3.35,16.13],[1,1.88,171.56],[2,1.87,171.31]],"ltp":3.5,"tv":19.34,"id":12474498}]}]}
{"op":"mcm","clk":"11838059183","pt":1723180944382,"mc":[{"id":"1.231581347","rc":[{"batb":[[0,3.4,14],[1,3.35,16.13],[2,1.88,171.56]],"ltp":3.5,"tv":19.34,"id":12474498}]}]}
{"op":"mcm","clk":"11838059291","pt":1723180946850,"mc":[{"id":"1.231581347","rc":[{"batb":[[0,3.4,10]],"ltp":3.5,"tv":19.34,"id":12474498}]}]}
{"op":"mcm","clk":"11838059323","pt":1723180947664,"mc":[{"id":"1.231581347","rc":[{"batb":[[0,3.45,4.86]],"ltp":3.5,"tv":19.34,"id":12474498}]}]}
{"op":"mcm","clk":"11838059365","pt":1723180949098,"mc":[{"id":"1.231581347","rc":[{"batb":[[0,3.5,4]],"ltp":3.5,"tv":19.34,"id":12474498}]}]}
{"op":"mcm","clk":"11838059452","pt":1723180951667,"mc":[{"id":"1.231581347","rc":[{"batb":[[0,3.4,10]],"ltp":3.5,"tv":19.34,"id":12474498}]}]}
{"op":"mcm","clk":"11838059538","pt":1723180953871,"mc":[{"id":"1.231581347","rc":[{"batb":[[0,3.45,4],[1,3.4,10],[2,3.35,16.13]],"ltp":3.5,"tv":19.34,"id":12474498}]}]}
{"op":"mcm","clk":"11838059570","pt":1723180954957,"mc":[{"id":"1.231581347","rc":[{"batb":[[1,3.35,16.13],[2,1.88,171.56]],"ltp":3.5,"tv":19.34,"id":12474498}]}]}
{"op":"mcm","clk":"11838059603","pt":1723180956288,"mc":[{"id":"1.231581347","rc":[{"batb":[[0,3.35,16.13],[1,1.88,171.56],[2,1.87,171.31]],"ltp":3.5,"tv":19.34,"id":12474498}]}]}
{"op":"mcm","clk":"11838059638","pt":1723180957472,"mc":[{"id":"1.231581347","rc":[{"batb":[[0,3.4,10],[1,3.35,16.13],[2,1.88,171.56]],"ltp":3.5,"tv":19.34,"id":12474498}]}]}
{"op":"mcm","clk":"11838059682","pt":1723180958694,"mc":[{"id":"1.231581347","rc":[{"batb":[[0,3.45,4],[1,3.4,10],[2,3.35,16.13]],"ltp":3.5,"tv":19.34,"id":12474498}]}]}
{"op":"mcm","clk":"11838059764","pt":1723180960805,"mc":[{"id":"1.231581347","rc":[{"batb":[[1,3.35,16.13],[2,1.88,171.56]],"ltp":3.5,"tv":19.34,"id":12474498}]}]}
{"op":"mcm","clk":"11838059776","pt":1723180961011,"mc":[{"id":"1.231581347","rc":[{"batb":[[0,3.35,16.13],[1,1.88,171.56],[2,1.87,171.31]],"ltp":3.5,"tv":19.34,"id":12474498}]}]}
{"op":"mcm","clk":"11838059885","pt":1723180963593,"mc":[{"id":"1.231581347","rc":[{"batb":[[0,3.4,14],[1,3.35,16.13],[2,1.88,171.56]],"ltp":3.5,"tv":19.34,"id":12474498}]}]}
{"op":"mcm","clk":"11838059941","pt":1723180965896,"mc":[{"id":"1.231581347","rc":[{"batb":[[0,3.4,10]],"ltp":3.5,"tv":19.34,"id":12474498}]}]}
{"op":"mcm","clk":"11838059974","pt":1723180967123,"mc":[{"id":"1.231581347","rc":[{"batb":[[0,3.35,16.13],[1,1.88,171.56],[2,1.87,171.31]],"ltp":3.5,"tv":19.34,"id":12474498}]}]}
{"op":"mcm","clk":"11838060016","pt":1723180968405,"mc":[{"id":"1.231581347","rc":[{"batb":[[0,3.4,4],[1,3.35,16.13],[2,1.88,171.56]],"ltp":3.5,"tv":19.34,"id":12474498}]}]}
{"op":"mcm","clk":"11838060096","pt":1723180970910,"mc":[{"id":"1.231581347","rc":[{"batb":[[0,3.45,10]],"ltp":3.5,"tv":19.34,"id":12474498}]}]}
{"op":"mcm","clk":"11838060185","pt":1723180974289,"mc":[{"id":"1.231581347","rc":[{"batb":[[0,3.5,4]],"ltp":3.5,"tv":19.34,"id":12474498}]}]}
{"op":"mcm","clk":"11838060252","pt":1723180976597,"mc":[{"id":"1.231581347","rc":[{"batb":[[0,3.35,16.13],[1,1.88,171.56],[2,1.87,171.31]],"ltp":3.5,"tv":19.34,"id":12474498}]}]}
{"op":"mcm","clk":"11838060273","pt":1723180977110,"mc":[{"id":"1.231581347","rc":[{"batb":[[0,3.4,10],[1,3.35,16.13],[2,1.88,171.56]],"ltp":3.5,"tv":19.34,"id":12474498}]}]}
{"op":"mcm","clk":"11838060391","pt":1723180980704,"mc":[{"id":"1.231581347","rc":[{"batb":[[0,3.45,4]],"ltp":3.5,"tv":19.34,"id":12474498}]}]}
{"op":"mcm","clk":"11838060456","pt":1723180982507,"mc":[{"id":"1.231581347","rc":[{"batb":[[0,3.35,16.13],[1,1.88,171.56],[2,1.87,171.31]],"ltp":3.5,"tv":19.34,"id":12474498}]}]}
{"op":"mcm","clk":"11838060513","pt":1723180984816,"mc":[{"id":"1.231581347","rc":[{"batb":[[0,3.4,14],[1,3.35,16.13],[2,1.88,171.56]],"ltp":3.5,"tv":19.34,"id":12474498}]}]}
{"op":"mcm","clk":"11838060563","pt":1723180987125,"mc":[{"id":"1.231581347","rc":[{"batb":[[0,3.4,10]],"ltp":3.5,"tv":19.34,"id":12474498}]}]}
{"op":"mcm","clk":"11838060613","pt":1723180988149,"mc":[{"id":"1.231581347","rc":[{"batb":[[0,3.35,16.13],[1,1.88,171.56],[2,1.87,171.31]],"ltp":3.5,"tv":19.34,"id":12474498}]}]}
{"op":"mcm","clk":"11838060658","pt":1723180989333,"mc":[{"id":"1.231581347","rc":[{"batb":[[0,3.4,4],[1,3.35,16.13],[2,1.88,171.56]],"ltp":3.5,"tv":19.34,"id":12474498}]}]}
{"op":"mcm","clk":"11838060753","pt":1723180991845,"mc":[{"id":"1.231581347","rc":[{"batb":[[0,3.35,16.13],[1,1.88,171.56],[2,1.87,171.31]],"ltp":3.5,"tv":19.34,"id":12474498}]}]}
{"op":"mcm","clk":"11838060766","pt":1723180992256,"mc":[{"id":"1.231581347","rc":[{"batb":[[0,3.4,10],[1,3.35,16.13],[2,1.88,171.56]],"ltp":3.5,"tv":19.34,"id":12474498}]}]}
{"op":"mcm","clk":"11838060855","pt":1723180994935,"mc":[{"id":"1.231581347","rc":[{"batb":[[0,3.45,4],[1,3.4,10],[2,3.35,16.13]],"ltp":3.5,"tv":19.34,"id":12474498}]}]}
{"op":"mcm","clk":"11838060873","pt":1723180995540,"mc":[{"id":"1.231581347","rc":[{"batb":[[1,3.35,16.13],[2,1.88,171.56]],"ltp":3.5,"tv":19.34,"id":12474498}]}]}
{"op":"mcm","clk":"11838060951","pt":1723180997761,"mc":[{"id":"1.231581347","rc":[{"batb":[[0,3.4,10]],"ltp":3.5,"tv":19.34,"id":12474498}]}]}
{"op":"mcm","clk":"11838061010","pt":1723180999631,"mc":[{"id":"1.231581347","rc":[{"batb":[[0,3.5,4],[1,3.45,4.56],[2,3.4,10]],"ltp":3.5,"tv":19.34,"id":12474498}]}]}
{"op":"mcm","clk":"11838061070","pt":1723181001739,"mc":[{"id":"1.231581347","rc":[{"batb":[[1,3.45,8.62],[2,3.35,16.13]],"ltp":3.5,"tv":19.34,"id":12474498}]}]}
{"op":"mcm","clk":"11838061081","pt":1723181002050,"mc":[{"id":"1.231581347","rc":[{"batb":[[0,3.45,4.06],[1,3.35,16.13],[2,1.88,171.56]],"ltp":3.5,"tv":19.34,"id":12474498}]}]}
{"op":"mcm","clk":"11838061229","pt":1723181005851,"mc":[{"id":"1.231581347","rc":[{"batb":[[0,3.5,14],[1,3.45,4.06],[2,3.35,16.13]],"ltp":3.5,"tv":19.34,"id":12474498}]}]}
{"op":"mcm","clk":"11838061329","pt":1723181008469,"mc":[{"id":"1.231581347","rc":[{"batb":[[0,3.5,10],[1,3.35,16.13],[2,1.88,171.56]],"ltp":3.5,"tv":19.34,"id":12474498}]}]}
{"op":"mcm","clk":"11838061369","pt":1723181009251,"mc":[{"id":"1.231581347","rc":[{"batb":[[0,3.35,16.13],[1,1.88,171.56],[2,1.87,171.31]],"ltp":3.5,"tv":19.34,"id":12474498}]}]}
{"op":"mcm","clk":"11838061495","pt":1723181013358,"mc":[{"id":"1.231581347","rc":[{"batb":[[0,3.4,14],[1,3.35,16.13],[2,1.88,171.56]],"ltp":3.5,"tv":19.34,"id":12474498}]}]}
{"op":"mcm","clk":"11838061573","pt":1723181015978,"mc":[{"id":"1.231581347","rc":[{"batb":[[0,3.4,10]],"ltp":3.5,"tv":19.34,"id":12474498}]}]}
{"op":"mcm","clk":"11838061611","pt":1723181016963,"mc":[{"id":"1.231581347","rc":[{"batb":[[0,3.35,16.13],[1,1.88,171.56],[2,1.87,171.31]],"ltp":3.5,"tv":19.34,"id":12474498}]}]}
{"op":"mcm","clk":"11838061627","pt":1723181017371,"mc":[{"id":"1.231581347","rc":[{"trd":[[1.4,469.24]],"batl":[[0,1.4,12.01]],"ltp":1.4,"tv":1335.06,"id":25686043},{"trd":[[3.5,7.69]],"ltp":3.5,"tv":19.53,"id":12474498}],"tv":1354.6}]}
{"op":"mcm","clk":"11838061678","pt":1723181018564,"mc":[{"id":"1.231581347","rc":[{"batb":[[0,3.4,4],[1,3.35,16.13],[2,1.88,171.56]],"ltp":3.5,"tv":19.53,"id":12474498}]}]}
{"op":"mcm","clk":"11838061719","pt":1723181019899,"mc":[{"id":"1.231581347","rc":[{"trd":[[1.37,45.12]],"batb":[[0,1.37,147.32]],"ltp":1.37,"tv":1379.88,"id":25686043}],"tv":1399.42}]}
{"op":"mcm","clk":"11838061758","pt":1723181020980,"mc":[{"id":"1.231581347","rc":[{"batb":[[0,3.45,10]],"ltp":3.5,"tv":19.53,"id":12474498}]}]}
{"op":"mcm","clk":"11838061837","pt":1723181023397,"mc":[{"id":"1.231581347","rc":[{"batb":[[0,3.4,4]],"ltp":3.5,"tv":19.53,"id":12474498}]}]}
{"op":"mcm","clk":"11838061914","pt":1723181025868,"mc":[{"id":"1.231581347","rc":[{"batb":[[0,3.4,10]],"ltp":3.5,"tv":19.53,"id":12474498}]}]}
{"op":"mcm","clk":"11838062025","pt":1723181029310,"mc":[{"id":"1.231581347","rc":[{"batb":[[0,3.4,4]],"ltp":3.5,"tv":19.53,"id":12474498}]}]}
{"op":"mcm","clk":"11838062148","pt":1723181031889,"mc":[{"id":"1.231581347","rc":[{"batb":[[0,3.4,10]],"ltp":3.5,"tv":19.53,"id":12474498}]}]}
{"op":"mcm","clk":"11838062302","pt":1723181035389,"mc":[{"id":"1.231581347","rc":[{"batb":[[0,3.4,4]],"ltp":3.5,"tv":19.53,"id":12474498}]}]}
{"op":"mcm","clk":"11838062392","pt":1723181037714,"mc":[{"id":"1.231581347","rc":[{"batb":[[0,3.45,10]],"ltp":3.5,"tv":19.53,"id":12474498}]}]}
{"op":"mcm","clk":"11838062508","pt":1723181041325,"mc":[{"id":"1.231581347","rc":[{"batb":[[0,3.4,4]],"ltp":3.5,"tv":19.53,"id":12474498}]}]}
{"op":"mcm","clk":"11838062582","pt":1723181043810,"mc":[{"id":"1.231581347","rc":[{"batb":[[0,3.45,10]],"ltp":3.5,"tv":19.53,"id":12474498}]}]}
{"op":"mcm","clk":"11838062736","pt":1723181047940,"mc":[{"id":"1.231581347","rc":[{"batb":[[0,3.4,4]],"ltp":3.5,"tv":19.53,"id":12474498}]}]}
{"op":"mcm","clk":"11838062834","pt":1723181049747,"mc":[{"id":"1.231581347","rc":[{"batb":[[0,3.45,10],[1,3.4,4],[2,3.35,16.13]],"ltp":3.5,"tv":19.53,"id":12474498}]}]}
{"op":"mcm","clk":"11838062872","pt":1723181050415,"mc":[{"id":"1.231581347","rc":[{"batb":[[1,3.35,16.13],[2,1.88,171.56]],"ltp":3.5,"tv":19.53,"id":12474498}]}]}
{"op":"mcm","clk":"11838062999","pt":1723181053337,"mc":[{"id":"1.231581347","rc":[{"batb":[[0,3.4,4]],"ltp":3.5,"tv":19.53,"id":12474498}]}]}
{"op":"mcm","clk":"11838063093","pt":1723181055812,"mc":[{"id":"1.231581347","rc":[{"batb":[[0,3.45,10]],"ltp":3.5,"tv":19.53,"id":12474498}]}]}
{"op":"mcm","clk":"11838063214","pt":1723181059150,"mc":[{"id":"1.231581347","rc":[{"batb":[[0,3.35,16.13],[1,1.88,171.56],[2,1.87,171.31]],"ltp":3.5,"tv":19.53,"id":12474498}]}]}
{"op":"mcm","clk":"11838063326","pt":1723181061618,"mc":[{"id":"1.231581347","rc":[{"batb":[[0,3.5,4],[1,3.35,16.13],[2,1.88,171.56]],"ltp":3.5,"tv":19.53,"id":12474498}]}]}
{"op":"mcm","clk":"11838063476","pt":1723181064651,"mc":[{"id":"1.231581347","rc":[{"batb":[[0,3.4,10]],"ltp":3.5,"tv":19.53,"id":12474498}]}]}
{"op":"mcm","clk":"11838063523","pt":1723181065838,"mc":[{"id":"1.231581347","rc":[{"batb":[[0,3.45,4.54],[1,3.4,10],[2,3.35,16.13]],"ltp":3.5,"tv":19.53,"id":12474498}]}]}
{"op":"mcm","clk":"11838063629","pt":1723181067957,"mc":[{"id":"1.231581347","rc":[{"batb":[[0,3.35,16.13],[1,1.88,171.56],[2,1.87,171.31]],"ltp":3.5,"tv":19.53,"id":12474498}]}]}
{"op":"mcm","clk":"11838063649","pt":1723181068322,"mc":[{"id":"1.231581347","rc":[{"trd":[[1.37,48.4]],"batb":[[0,1.37,145.68]],"ltp":1.37,"tv":1383.16,"id":25686043},{"batb":[[0,3.4,4],[1,3.35,16.13],[2,1.88,171.56]],"ltp":3.5,"tv":19.53,"id":12474498}],"tv":1402.7}]}
{"op":"mcm","clk":"11838063730","pt":1723181070802,"mc":[{"id":"1.231581347","rc":[{"batb":[[0,3.45,10]],"ltp":3.5,"tv":19.53,"id":12474498}]}]}
{"op":"mcm","clk":"11838063883","pt":1723181074379,"mc":[{"id":"1.231581347","rc":[{"batb":[[0,3.4,4]],"ltp":3.5,"tv":19.53,"id":12474498}]}]}
{"op":"mcm","clk":"11838063981","pt":1723181076657,"mc":[{"id":"1.231581347","rc":[{"batb":[[0,3.35,16.13],[1,1.88,171.56],[2,1.87,171.31]],"ltp":3.5,"tv":19.53,"id":12474498}]}]}
{"op":"mcm","clk":"11838064021","pt":1723181077174,"mc":[{"id":"1.231581347","rc":[{"batb":[[0,3.4,10],[1,3.35,16.13],[2,1.88,171.56]],"ltp":3.5,"tv":19.53,"id":12474498}]}]}
{"op":"mcm","clk":"11838064194","pt":1723181080883,"mc":[{"id":"1.231581347","rc":[{"batb":[[0,3.45,4]],"ltp":3.5,"tv":19.53,"id":12474498}]}]}
{"op":"mcm","clk":"11838064308","pt":1723181083253,"mc":[{"id":"1.231581347","rc":[{"batb":[[0,3.5,10]],"ltp":3.5,"tv":19.53,"id":12474498}]}]}
{"op":"mcm","clk":"11838064449","pt":1723181086591,"mc":[{"id":"1.231581347","rc":[{"batb":[[0,3.55,7.95]],"ltp":3.5,"tv":19.53,"id":12474498}]}]}
{"op":"mcm","clk":"11838064515","pt":1723181088589,"mc":[{"id":"1.231581347","rc":[{"batb":[[0,3.55,3.95]],"ltp":3.5,"tv":19.53,"id":12474498}]}]}
{"op":"mcm","clk":"11838064553","pt":1723181089366,"mc":[{"id":"1.231581347","rc":[{"batb":[[0,3.4,10]],"ltp":3.5,"tv":19.53,"id":12474498}]}]}
{"op":"mcm","clk":"11838064685","pt":1723181091775,"mc":[{"id":"1.231581347","rc":[{"batb":[[0,3.45,4],[1,3.4,10],[2,3.35,16.13]],"ltp":3.5,"tv":19.53,"id":12474498}]}]}
{"op":"mcm","clk":"11838064732","pt":1723181092592,"mc":[{"id":"1.231581347","rc":[{"batb":[[1,3.35,16.13],[2,1.88,171.56]],"ltp":3.5,"tv":19.53,"id":12474498}]}]}
{"op":"mcm","clk":"11838064785","pt":1723181094078,"mc":[{"id":"1.231581347","rc":[{"batb":[[0,3.35,16.13],[1,1.88,171.56],[2,1.87,171.31]],"ltp":3.5,"tv":19.53,"id":12474498}]}]}
{"op":"mcm","clk":"11838064881","pt":1723181096793,"mc":[{"id":"1.231581347","rc":[{"batb":[[0,3.4,14],[1,3.35,16.13],[2,1.88,171.56]],"ltp":3.5,"tv":19.53,"id":12474498}]}]}
{"op":"mcm","clk":"11838064959","pt":1723181099098,"mc":[{"id":"1.231581347","rc":[{"batb":[[0,3.4,10]],"ltp":3.5,"tv":19.53,"id":12474498}]}]}
{"op":"mcm","clk":"11838064993","pt":1723181100121,"mc":[{"id":"1.231581347","rc":[{"batb":[[0,3.35,16.13],[1,1.88,171.56],[2,1.87,171.31]],"ltp":3.5,"tv":19.53,"id":12474498}]}]}
{"op":"mcm","clk":"11838065098","pt":1723181102588,"mc":[{"id":"1.231581347","rc":[{"batb":[[0,3.4,14],[1,3.35,16.13],[2,1.88,171.56]],"ltp":3.5,"tv":19.53,"id":12474498}]}]}
{"op":"mcm","clk":"11838065242","pt":1723181105789,"mc":[{"id":"1.231581347","rc":[{"batb":[[0,3.35,16.13],[1,1.88,171.56],[2,1.87,171.31]],"ltp":3.5,"tv":19.53,"id":12474498}]}]}
{"op":"mcm","clk":"11838065408","pt":1723181108514,"mc":[{"id":"1.231581347","rc":[{"trd":[[1.4,469.38]],"batl":[[0,1.4,11.94]],"ltp":1.4,"tv":1383.3,"id":25686043},{"batb":[[0,3.4,14],[1,3.35,16.13],[2,1.88,171.56]],"ltp":3.5,"tv":19.53,"id":12474498}],"tv":1402.84}]}
{"op":"mcm","clk":"11838065548","pt":1723181110726,"mc":[{"id":"1.231581347","rc":[{"batb":[[0,3.4,10]],"ltp":3.5,"tv":19.53,"id":12474498}]}]}
{"op":"mcm","clk":"11838065599","pt":1723181111707,"mc":[{"id":"1.231581347","rc":[{"batb":[[0,3.35,16.13],[1,1.88,171.56],[2,1.87,171.31]],"ltp":3.5,"tv":19.53,"id":12474498}]}]}
{"op":"mcm","clk":"11838065720","pt":1723181114322,"mc":[{"id":"1.231581347","rc":[{"batb":[[0,3.4,14],[1,3.35,16.13],[2,1.88,171.56]],"ltp":3.5,"tv":19.53,"id":12474498}]}]}
{"op":"mcm","clk":"11838065840","pt":1723181116932,"mc":[{"id":"1.231581347","rc":[{"batb":[[0,3.4,10]],"ltp":3.5,"tv":19.53,"id":12474498}]}]}
{"op":"mcm","clk":"11838065875","pt":1723181117907,"mc":[{"id":"1.231581347","rc":[{"batb":[[0,3.45,4.54],[1,3.4,10],[2,3.35,16.13]],"ltp":3.5,"tv":19.53,"id":12474498}]}]}
{"op":"mcm","clk":"11838065884","pt":1723181118164,"mc":[{"id":"1.231581347","rc":[{"batb":[[1,3.35,16.13],[2,1.88,171.56]],"ltp":3.5,"tv":19.53,"id":12474498}]}]}
{"op":"mcm","clk":"11838065987","pt":1723181120626,"mc":[{"id":"1.231581347","rc":[{"batb":[[0,3.5,4]],"ltp":3.5,"tv":19.53,"id":12474498}]}]}
{"op":"mcm","clk":"11838066097","pt":1723181122733,"mc":[{"id":"1.231581347","rc":[{"batb":[[0,3.4,10]],"ltp":3.5,"tv":19.53,"id":12474498}]}]}
{"op":"mcm","clk":"11838066173","pt":1723181124832,"mc":[{"id":"1.231581347","rc":[{"batb":[[0,3.45,4],[1,3.4,10],[2,3.35,16.13]],"ltp":3.5,"tv":19.53,"id":12474498}]}]}
{"op":"mcm","clk":"11838066274","pt":1723181126228,"mc":[{"id":"1.231581347","rc":[{"batb":[[1,3.35,16.13],[2,1.88,171.56]],"ltp":3.5,"tv":19.53,"id":12474498}]}]}
{"op":"mcm","clk":"11838066346","pt":1723181127152,"mc":[{"id":"1.231581347","rc":[{"batb":[[0,3.35,16.13],[1,1.88,171.56],[2,1.87,171.31]],"ltp":3.5,"tv":19.53,"id":12474498}]}]}
{"op":"mcm","clk":"11838066422","pt":1723181128536,"mc":[{"id":"1.231581347","rc":[{"batb":[[0,3.4,10],[1,3.35,16.13],[2,1.88,171.56]],"ltp":3.5,"tv":19.53,"id":12474498}]}]}
{"op":"mcm","clk":"11838066639","pt":1723181131928,"mc":[{"id":"1.231581347","rc":[{"batb":[[0,3.45,4]],"ltp":3.5,"tv":19.53,"id":12474498}]}]}
{"op":"mcm","clk":"11838066739","pt":1723181133785,"mc":[{"id":"1.231581347","rc":[{"batb":[[0,3.35,16.13],[1,1.88,171.56],[2,1.87,171.31]],"ltp":3.5,"tv":19.53,"id":12474498}]}]}
{"op":"mcm","clk":"11838066786","pt":1723181134963,"mc":[{"id":"1.231581347","rc":[{"batb":[[0,3.4,10],[1,3.35,16.13],[2,1.88,171.56]],"ltp":3.5,"tv":19.53,"id":12474498}]}]}
{"op":"mcm","clk":"11838066944","pt":1723181138560,"mc":[{"id":"1.231581347","rc":[{"batb":[[0,3.4,4]],"ltp":3.5,"tv":19.53,"id":12474498}]}]}
{"op":"mcm","clk":"11838067046","pt":1723181140866,"mc":[{"id":"1.231581347","rc":[{"batb":[[0,3.45,10]],"ltp":3.5,"tv":19.53,"id":12474498}]}]}
{"op":"mcm","clk":"11838067188","pt":1723181143750,"mc":[{"id":"1.231581347","rc":[{"batb":[[0,3.5,4],[1,3.45,14.06],[2,3.35,16.13]],"ltp":3.5,"tv":19.53,"id":12474498}]}]}
{"op":"mcm","clk":"11838067198","pt":1723181144057,"mc":[{"id":"1.231581347","rc":[{"batb":[[1,3.45,4.06]],"ltp":3.5,"tv":19.53,"id":12474498}]}]}
{"op":"mcm","clk":"11838067254","pt":1723181146059,"mc":[{"id":"1.231581347","rc":[{"batb":[[0,3.45,4.06],[1,3.35,16.13],[2,1.88,171.56]],"ltp":3.5,"tv":19.53,"id":12474498}]}]}
{"op":"mcm","clk":"11838067305","pt":1723181147348,"mc":[{"id":"1.231581347","rc":[{"batb":[[0,3.5,10],[1,3.45,4.06],[2,3.35,16.13]],"ltp":3.5,"tv":19.53,"id":12474498}]}]}
{"op":"mcm","clk":"11838067345","pt":1723181148576,"mc":[{"id":"1.231581347","rc":[{"batb":[[0,3.55,4],[1,3.5,10],[2,3.45,4.06]],"ltp":3.5,"tv":19.53,"id":12474498}]}]}
{"op":"mcm","clk":"11838067446","pt":1723181151094,"mc":[{"id":"1.231581347","rc":[{"batb":[[0,3.45,4.06],[1,3.35,16.13],[2,1.88,171.56]],"ltp":3.5,"tv":19.53,"id":12474498}]}]}
{"op":"mcm","clk":"11838067585","pt":1723181154690,"mc":[{"id":"1.231581347","rc":[{"batb":[[0,3.5,14],[1,3.45,4.06],[2,3.35,16.13]],"ltp":3.5,"tv":19.53,"id":12474498}]}]}
{"op":"mcm","clk":"11838067614","pt":1723181155778,"mc":[{"id":"1.231581347","rc":[{"batb":[[1,3.35,16.13],[2,1.88,171.56]],"ltp":3.5,"tv":19.53,"id":12474498}]}]}
{"op":"mcm","clk":"11838067652","pt":1723181157000,"mc":[{"id":"1.231581347","rc":[{"batb":[[0,3.5,10]],"ltp":3.5,"tv":19.53,"id":12474498}]}]}
{"op":"mcm","clk":"11838067705","pt":1723181158075,"mc":[{"id":"1.231581347","rc":[{"batb":[[0,3.35,16.13],[1,1.88,171.56],[2,1.87,171.31]],"ltp":3.5,"tv":19.53,"id":12474498}]}]}
{"op":"mcm","clk":"11838067748","pt":1723181159309,"mc":[{"id":"1.231581347","rc":[{"batb":[[0,3.4,4],[1,3.35,16.13],[2,1.88,171.56]],"ltp":3.5,"tv":19.53,"id":12474498}]}]}
{"op":"mcm","clk":"11838067786","pt":1723181160487,"mc":[{"id":"1.231581347","rc":[{"batb":[[0,3.45,10],[1,3.4,4],[2,3.35,16.13]],"ltp":3.5,"tv":19.53,"id":12474498}]}]}
{"op":"mcm","clk":"11838067858","pt":1723181161722,"mc":[{"id":"1.231581347","rc":[{"batb":[[1,3.35,16.13],[2,1.88,171.56]],"ltp":3.5,"tv":19.53,"id":12474498}]}]}
{"op":"mcm","clk":"11838067964","pt":1723181163886,"mc":[{"id":"1.231581347","rc":[{"batb":[[0,3.4,4]],"ltp":3.5,"tv":19.53,"id":12474498}]}]}
{"op":"mcm","clk":"11838068074","pt":1723181166523,"mc":[{"id":"1.231581347","rc":[{"batb":[[0,3.45,10]],"ltp":3.5,"tv":19.53,"id":12474498}]}]}
{"op":"mcm","clk":"11838068264","pt":1723181169890,"mc":[{"id":"1.231581347","rc":[{"batb":[[0,3.35,16.13],[1,1.88,171.56],[2,1.87,171.31]],"ltp":3.5,"tv":19.53,"id":12474498}]}]}
{"op":"mcm","clk":"11838068274","pt":1723181170091,"mc":[{"id":"1.231581347","rc":[{"batb":[[0,3.4,4],[1,3.35,16.13],[2,1.88,171.56]],"ltp":3.5,"tv":19.53,"id":12474498}]}]}
{"op":"mcm","clk":"11838068409","pt":1723181172614,"mc":[{"id":"1.231581347","rc":[{"batb":[[0,3.4,10]],"ltp":3.5,"tv":19.53,"id":12474498}]}]}
{"op":"mcm","clk":"11838068503","pt":1723181174929,"mc":[{"id":"1.231581347","rc":[{"batb":[[0,3.5,4],[1,3.45,4.54],[2,3.4,10]],"ltp":3.5,"tv":19.53,"id":12474498}]}]}
{"op":"mcm","clk":"11838068559","pt":1723181176120,"mc":[{"id":"1.231581347","rc":[{"batb":[[2,3.35,16.13]],"ltp":3.5,"tv":19.53,"id":12474498}]}]}
{"op":"mcm","clk":"11838068626","pt":1723181177615,"mc":[{"id":"1.231581347","rc":[{"batb":[[0,3.35,16.13],[1,1.88,171.56],[2,1.87,171.31]],"ltp":3.5,"tv":19.53,"id":12474498}]}]}
{"op":"mcm","clk":"11838068790","pt":1723181181216,"mc":[{"id":"1.231581347","rc":[{"batb":[[0,3.4,14],[1,3.35,16.13],[2,1.88,171.56]],"ltp":3.5,"tv":19.53,"id":12474498}]}]}
{"op":"mcm","clk":"11838068949","pt":1723181184849,"mc":[{"id":"1.231581347","rc":[{"batb":[[0,3.35,16.13],[1,1.88,171.56],[2,1.87,171.31]],"ltp":3.5,"tv":19.53,"id":12474498}]}]}
{"op":"mcm","clk":"11838069168","pt":1723181189520,"mc":[{"id":"1.231581347","rc":[{"batb":[[0,3.4,14],[1,3.35,16.13],[2,1.88,171.56]],"ltp":3.5,"tv":19.53,"id":12474498}]}]}
{"op":"mcm","clk":"11838069255","pt":1723181191830,"mc":[{"id":"1.231581347","rc":[{"batb":[[0,3.4,10]],"ltp":3.5,"tv":19.53,"id":12474498}]}]}
{"op":"mcm","clk":"11838069285","pt":1723181192755,"mc":[{"id":"1.231581347","rc":[{"batb":[[0,3.35,16.13],[1,1.88,171.56],[2,1.87,171.31]],"ltp":3.5,"tv":19.53,"id":12474498}]}]}
{"op":"mcm","clk":"11838072544","pt":1723181288253,"mc":[{"id":"1.231581347","rc":[{"batb":[[0,3.45,4.06],[1,3.35,16.13],[2,1.88,171.56]],"ltp":3.5,"tv":19.53,"id":12474498}]}]}
{"op":"mcm","clk":"11838073015","pt":1723181300079,"mc":[{"id":"1.231581347","rc":[{"batl":[[0,1.39,45],[1,1.4,11.94],[2,1.41,110.15]],"ltp":1.4,"tv":1383.3,"id":25686043}]}]}
{"op":"mcm","clk":"11838073086","pt":1723181301881,"mc":[{"id":"1.231581347","rc":[{"batb":[[0,3.6,3.9]],"ltp":3.5,"tv":19.53,"id":12474498}]}]}
{"op":"mcm","clk":"11838076141","pt":1723181383984,"mc":[{"id":"1.231581347","rc":[{"trd":[[3.6,0.04]],"batb":[[0,3.6,3.88]],"ltp":3.6,"tv":19.57,"id":12474498}],"tv":1402.87}]}
{"op":"mcm","clk":"11838080834","pt":1723181494535,"mc":[{"id":"1.231581347","rc":[{"batl":[[0,1.38,9.26],[1,1.39,45],[2,1.4,2.68]],"ltp":1.4,"tv":1383.3,"id":25686043}]}]}
{"op":"mcm","clk":"11838083541","pt":1723181549722,"mc":[{"id":"1.231581347","rc":[{"trd":[[1.38,9.26]],"batl":[[0,1.39,45],[1,1.4,2.68],[2,1.41,110.15]],"ltp":1.38,"tv":1392.57,"id":25686043},{"trd":[[3.6,11.35]],"batb":[[0,3.35,16.13],[1,1.88,171.56],[2,1.87,171.31]],"batl":[[0,3.6,357.15],[1,3.7,4.66]],"ltp":3.6,"tv":30.88,"id":12474498}],"tv":1423.45}]}
{"op":"mcm","clk":"11838083632","pt":1723181551993,"mc":[{"id":"1.231581347","rc":[{"batl":[[1,3.7,0]],"ltp":3.6,"tv":30.88,"id":12474498}]}]}
{"op":"mcm","clk":"11838084355","pt":1723181567315,"mc":[{"id":"1.231581347","rc":[{"trd":[[1.39,71.97]],"batl":[[0,1.4,2.68],[1,1.41,110.15],[2,1.42,121.6]],"ltp":1.39,"tv":1437.57,"id":25686043},{"trd":[[3.55,17.62]],"batl":[[0,3.55,339.53]],"ltp":3.55,"tv":48.5,"id":12474498}],"tv":1486.07}]}
{"op":"mcm","clk":"11838085045","pt":1723181580335,"mc":[{"id":"1.231581347","rc":[{"trd":[[1.4,472.06]],"batl":[[0,1.41,110.15],[1,1.42,121.6],[2,1.43,3390.43]],"ltp":1.4,"tv":1440.25,"id":25686043},{"trd":[[3.5,8.76]],"batl":[[0,3.5,338.46]],"ltp":3.5,"tv":49.57,"id":12474498}],"tv":1489.82}]}
{"op":"mcm","clk":"11838085674","pt":1723181592363,"mc":[{"id":"1.231581347","rc":[{"trd":[[1.41,130.15]],"batl":[[0,1.42,121.6],[1,1.43,3390.43],[2,1.46,363.66]],"ltp":1.41,"tv":1550.4,"id":25686043},{"trd":[[3.4,45.68]],"batl":[[0,3.4,292.78]],"ltp":3.4,"tv":95.25,"id":12474498}],"tv":1645.65}]}
{"op":"mcm","clk":"11838086400","pt":1723181605377,"mc":[{"id":"1.231581347","rc":[{"trd":[[1.42,121.79]],"batl":[[0,1.43,3390.43],[1,1.46,363.66],[2,1.47,1]],"ltp":1.42,"tv":1672.0,"id":25686043},{"trd":[[3.35,83.8]],"batb":[[0,1.88,171.56],[1,1.87,171.31],[2,1.86,171.31]],"batl":[[0,3.35,225.1]],"ltp":3.35,"tv":179.05,"id":12474498}],"tv":1851.05}]}
{"op":"mcm","clk":"11838086530","pt":1723181607073,"mc":[{"id":"1.231581347","rc":[{"batb":[[0,3.15,17.63],[1,1.88,171.56],[2,1.87,171.31]],"ltp":3.35,"tv":179.05,"id":12474498}]}]}
{"op":"mcm","clk":"11838088012","pt":1723181629489,"mc":[{"id":"1.231581347","rc":[{"batl":[[0,1.42,45],[1,1.43,3390.43],[2,1.46,363.66]],"ltp":1.42,"tv":1672.0,"id":25686043}]}]}
{"op":"mcm","clk":"11838088043","pt":1723181630404,"mc":[{"id":"1.231581347","rc":[{"trd":[[1.42,166.79],[1.43,1090.51]],"batl":[[0,1.43,2914.98],[1,1.46,363.66],[2,1.47,1]],"ltp":1.43,"tv":2192.45,"id":25686043},{"trd":[[3.3,212.63],[3.35,102.88]],"ltp":3.3,"tv":404.16,"id":12474498}],"tv":2596.62}]}
{"op":"mcm","clk":"11838088693","pt":1723181645109,"mc":[{"id":"1.231581347","rc":[{"batl":[[0,1.42,112.5],[1,1.43,2914.98],[2,1.46,363.66]],"ltp":1.43,"tv":2192.45,"id":25686043}]}]}
{"op":"mcm","clk":"11838089587","pt":1723181661022,"mc":[{"id":"1.231581347","rc":[{"batb":[[0,1.38,90],[1,1.37,145.68],[2,1.25,63.99]],"ltp":1.43,"tv":2192.45,"id":25686043}]}]}
{"op":"mcm","clk":"11838090222","pt":1723181677067,"mc":[{"id":"1.231581347","rc":[{"batl":[[0,1.41,8.45],[1,1.42,112.5],[2,1.43,2914.98]],"ltp":1.43,"tv":2192.45,"id":25686043}]}]}
{"op":"mcm","clk":"11838092751","pt":1723181734924,"mc":[{"id":"1.231581347","rc":[{"batl":[[1,1.43,2914.98],[2,1.46,363.66]],"ltp":1.43,"tv":2192.45,"id":25686043}]}]}
{"op":"mcm","clk":"11838092852","pt":1723181736930,"mc":[{"id":"1.231581347","rc":[{"batl":[[0,1.43,2914.98],[1,1.46,363.66],[2,1.47,1]],"ltp":1.43,"tv":2192.45,"id":25686043}]}]}
{"op":"mcm","clk":"11838094243","pt":1723181767392,"mc":[{"id":"1.231581347","rc":[{"batl":[[0,1.42,17.13],[1,1.43,2914.98],[2,1.46,363.66]],"ltp":1.43,"tv":2192.45,"id":25686043}]}]}
{"op":"mcm","clk":"11838094750","pt":1723181779693,"mc":[{"id":"1.231581347","rc":[{"batl":[[0,1.41,1.71],[1,1.42,17.13],[2,1.43,2914.98]],"ltp":1.43,"tv":2192.45,"id":25686043}]}]}
{"op":"mcm","clk":"11838098443","pt":1723181890108,"mc":[{"id":"1.231581347","rc":[{"batb":[[0,3.35,7.45],[1,3.15,17.63],[2,1.88,171.56]],"ltp":3.3,"tv":404.16,"id":12474498}]}]}
{"op":"mcm","clk":"11838136152","pt":1723182961746,"mc":[{"id":"1.231581347","rc":[{"batb":[[0,3.4,2],[1,3.35,7.45],[2,3.15,17.63]],"ltp":3.3,"tv":404.16,"id":12474498}]}]}
{"op":"mcm","clk":"11838139756","pt":1723183043359,"mc":[{"id":"1.231581347","rc":[{"trd":[[1.38,16.09]],"batb":[[0,1.38,83.17]],"ltp":1.38,"tv":2199.28,"id":25686043},{"trd":[[3.65,2.58]],"ltp":3.65,"tv":406.74,"id":12474498}],"tv":2606.03}]}
{"op":"mcm","clk":"11838151658","pt":1723183308123,"mc":[{"id":"1.231581347","rc":[{"trd":[[1.38,102.93],[1.39,71.96],[1.4,472.05],[1.42,166.78],[1.43,1090.67],[1.44,201.66]],"batb":[[0,1.38,39.75]],"batl":[[1,1.42,17.12],[2,1.43,2915.56]],"ltp":1.38,"tv":2286.22,"id":25686043},{"trd":[[3.3,212.56],[3.35,102.85],[3.4,45.66],[3.45,4.51],[3.55,17.61],[3.6,11.34]],"batb":[[1,3.35,7.45]],"ltp":3.65,"tv":406.62,"id":12474498}],"tv":2692.84}]}
{"op":"mcm","clk":"11838154756","pt":1723183376708,"mc":[{"id":"1.231581347","rc":[{"batl":[[0,1.41,31.71]],"ltp":1.38,"tv":2286.22,"id":25686043}]}]}
{"op":"mcm","clk":"11838155577","pt":1723183394357,"mc":[{"id":"1.231581347","rc":[{"batl":[[0,1.4,30],[1,1.41,1.71],[2,1.42,17.12]],"ltp":1.38,"tv":2286.22,"id":25686043}]}]}
{"op":"mcm","clk":"11838155635","pt":1723183395848,"mc":[{"id":"1.231581347","rc":[{"batl":[[2,1.43,2915.56]],"ltp":1.38,"tv":2286.22,"id":25686043},{"batb":[[1,3.15,17.63],[2,1.88,171.49]],"ltp":3.65,"tv":406.62,"id":12474498}]}]}
{"op":"mcm","clk":"11838160634","pt":1723183509116,"mc":[{"id":"1.231581347","rc":[{"trd":[[1.4,472.19]],"batl":[[0,1.4,29.93]],"ltp":1.4,"tv":2286.36,"id":25686043}],"tv":2692.98}]}
{"op":"mcm","clk":"11838163249","pt":1723183566892,"mc":[{"id":"1.231581347","rc":[{"batb":[[0,1.39,2.53],[1,1.38,39.75],[2,1.37,145.68]],"ltp":1.4,"tv":2286.36,"id":25686043}]}]}
{"op":"mcm","clk":"11838164986","pt":1723183604252,"mc":[{"id":"1.231581347","rc":[{"batl":[[0,1.4,97.43]],"ltp":1.4,"tv":2286.36,"id":25686043}]}]}
{"op":"mcm","clk":"11838165565","pt":1723183618626,"mc":[{"id":"1.231581347","rc":[{"batl":[[0,1.4,29.93]],"ltp":1.4,"tv":2286.36,"id":25686043}]}]}
{"op":"mcm","clk":"11838166103","pt":1723183631249,"mc":[{"id":"1.231581347","rc":[{"trd":[[1.4,483.44]],"batl":[[0,1.4,18.68]],"ltp":1.4,"tv":2297.61,"id":25686043},{"trd":[[3.5,13.26]],"ltp":3.5,"tv":411.12,"id":12474498}],"tv":2708.73}]}
{"op":"mcm","clk":"11838171039","pt":1723183753928,"mc":[{"id":"1.231581347","rc":[{"trd":[[1.4,492.55]],"batl":[[0,1.4,9.57]],"ltp":1.4,"tv":2306.72,"id":25686043},{"trd":[[3.5,16.91]],"batb":[[1,3.35,7.45],[2,3.15,17.63]],"ltp":3.5,"tv":414.76,"id":12474498}],"tv":2721.49}]}
{"op":"mcm","clk":"11838174022","pt":1723183829402,"mc":[{"id":"1.231581347","rc":[{"trd":[[1.39,77.02]],"batb":[[0,1.38,39.75],[1,1.37,145.68],[2,1.25,63.99]],"batl":[[0,1.39,13.54],[1,1.4,9.57],[2,1.41,1.71]],"ltp":1.39,"tv":2311.78,"id":25686043}],"tv":2726.55}]}
{"op":"mcm","clk":"11838174097","pt":1723183831605,"mc":[{"id":"1.231581347","rc":[{"batb":[[1,3.15,17.63],[2,1.88,171.49]],"ltp":3.5,"tv":414.76,"id":12474498}]}]}
{"op":"mcm","clk":"11838174445","pt":1723183840425,"mc":[{"id":"1.231581347","rc":[{"batl":[[0,1.4,9.57],[1,1.41,1.71],[2,1.43,2915.56]],"ltp":1.39,"tv":2311.78,"id":25686043}]}]}
{"op":"mcm","clk":"11838174473","pt":1723183841095,"mc":[{"id":"1.231581347","rc":[{"batb":[[1,3.35,7.45],[2,3.15,17.63]],"ltp":3.5,"tv":414.76,"id":12474498}]}]}
{"op":"mcm","clk":"11838191418","pt":1723184226915,"mc":[{"id":"1.231581347","rc":[{"batb":[[0,1.38,152.25]],"ltp":1.39,"tv":2311.78,"id":25686043}]}]}
{"op":"mcm","clk":"11838199922","pt":1723184501126,"mc":[{"id":"1.231581347","rc":[{"batb":[[0,3.45,4],[1,3.4,2],[2,3.35,7.45]],"batl":[[0,3.6,4.32]],"ltp":3.5,"tv":414.76,"id":12474498}]}]}
{"op":"mcm","clk":"11838199989","pt":1723184503345,"mc":[{"id":"1.231581347","rc":[{"batb":[[0,3.4,2],[1,3.15,17.63],[2,1.88,171.49]],"ltp":3.5,"tv":414.76,"id":12474498}]}]}
{"op":"mcm","clk":"11838200093","pt":1723184505944,"mc":[{"id":"1.231581347","rc":[{"batb":[[1,3.35,7.45],[2,3.15,17.63]],"ltp":3.5,"tv":414.76,"id":12474498}]}]}
{"op":"mcm","clk":"11838200096","pt":1723184506047,"mc":[{"id":"1.231581347","rc":[{"batb":[[0,3.45,4],[1,3.4,2],[2,3.35,7.45]],"ltp":3.5,"tv":414.76,"id":12474498}]}]}
{"op":"mcm","clk":"11838200177","pt":1723184508554,"mc":[{"id":"1.231581347","rc":[{"batb":[[0,3.4,2],[1,3.15,17.63],[2,1.88,171.49]],"ltp":3.5,"tv":414.76,"id":12474498}]}]}
{"op":"mcm","clk":"11838200270","pt":1723184512132,"mc":[{"id":"1.231581347","rc":[{"batb":[[0,3.45,4],[1,3.4,2],[2,3.15,17.63]],"ltp":3.5,"tv":414.76,"id":12474498}]}]}
{"op":"mcm","clk":"11838200374","pt":1723184514533,"mc":[{"id":"1.231581347","rc":[{"batb":[[0,3.4,2],[1,3.15,17.63],[2,1.88,171.49]],"ltp":3.5,"tv":414.76,"id":12474498}]}]}
{"op":"mcm","clk":"11838200443","pt":1723184516738,"mc":[{"id":"1.231581347","rc":[{"batb":[[0,3.45,4],[1,3.4,2],[2,3.15,17.63]],"ltp":3.5,"tv":414.76,"id":12474498}]}]}
{"op":"mcm","clk":"11838200540","pt":1723184519348,"mc":[{"id":"1.231581347","rc":[{"batb":[[0,3.4,2],[1,3.15,17.63],[2,1.88,171.49]],"ltp":3.5,"tv":414.76,"id":12474498}]}]}
{"op":"mcm","clk":"11838200767","pt":1723184526241,"mc":[{"id":"1.231581347","rc":[{"batb":[[0,3.45,4],[1,3.4,2],[2,3.15,17.63]],"ltp":3.5,"tv":414.76,"id":12474498}]}]}
{"op":"mcm","clk":"11838200857","pt":1723184528567,"mc":[{"id":"1.231581347","rc":[{"batb":[[0,3.4,2],[1,3.15,17.63],[2,1.88,171.49]],"ltp":3.5,"tv":414.76,"id":12474498}]}]}
{"op":"mcm","clk":"11838201007","pt":1723184532058,"mc":[{"id":"1.231581347","rc":[{"batb":[[0,3.45,4],[1,3.4,2],[2,3.15,17.63]],"ltp":3.5,"tv":414.76,"id":12474498}]}]}
{"op":"mcm","clk":"11838201124","pt":1723184534353,"mc":[{"id":"1.231581347","rc":[{"batb":[[0,3.4,2],[1,3.15,17.63],[2,1.88,171.49]],"ltp":3.5,"tv":414.76,"id":12474498}]}]}
{"op":"mcm","clk":"11838201188","pt":1723184536573,"mc":[{"id":"1.231581347","rc":[{"batb":[[0,3.45,4],[1,3.4,2],[2,3.15,17.63]],"ltp":3.5,"tv":414.76,"id":12474498}]}]}
{"op":"mcm","clk":"11838201262","pt":1723184538893,"mc":[{"id":"1.231581347","rc":[{"batb":[[0,3.4,2],[1,3.15,17.63],[2,1.88,171.49]],"ltp":3.5,"tv":414.76,"id":12474498}]}]}
{"op":"mcm","clk":"11838201368","pt":1723184542179,"mc":[{"id":"1.231581347","rc":[{"batb":[[0,3.45,4],[1,3.4,2],[2,3.15,17.63]],"ltp":3.5,"tv":414.76,"id":12474498}]}]}
{"op":"mcm","clk":"11838201498","pt":1723184544382,"mc":[{"id":"1.231581347","rc":[{"batb":[[0,3.4,2],[1,3.15,17.63],[2,1.88,171.49]],"ltp":3.5,"tv":414.76,"id":12474498}]}]}
{"op":"mcm","clk":"11838201631","pt":1723184547965,"mc":[{"id":"1.231581347","rc":[{"batb":[[0,3.45,4],[1,3.4,2],[2,3.15,17.63]],"ltp":3.5,"tv":414.76,"id":12474498}]}]}
{"op":"mcm","clk":"11838201715","pt":1723184550280,"mc":[{"id":"1.231581347","rc":[{"batb":[[0,3.4,2],[1,3.15,17.63],[2,1.88,171.49]],"ltp":3.5,"tv":414.76,"id":12474498}]}]}
{"op":"mcm","clk":"11838201855","pt":1723184554279,"mc":[{"id":"1.231581347","rc":[{"batb":[[0,3.45,4],[1,3.4,2],[2,3.15,17.63]],"ltp":3.5,"tv":414.76,"id":12474498}]}]}
{"op":"mcm","clk":"11838201950","pt":1723184556896,"mc":[{"id":"1.231581347","rc":[{"batb":[[0,3.4,2],[1,3.15,17.63],[2,1.88,171.49]],"ltp":3.5,"tv":414.76,"id":12474498}]}]}
{"op":"mcm","clk":"11838202085","pt":1723184560188,"mc":[{"id":"1.231581347","rc":[{"batb":[[0,3.45,4],[1,3.4,2],[2,3.15,17.63]],"ltp":3.5,"tv":414.76,"id":12474498}]}]}
{"op":"mcm","clk":"11838202192","pt":1723184562804,"mc":[{"id":"1.231581347","rc":[{"batb":[[0,3.4,2],[1,3.15,17.63],[2,1.88,171.49]],"ltp":3.5,"tv":414.76,"id":12474498}]}]}
{"op":"mcm","clk":"11838202238","pt":1723184564092,"mc":[{"id":"1.231581347","rc":[{"batb":[[1,3.35,7.45],[2,3.15,17.63]],"ltp":3.5,"tv":414.76,"id":12474498}]}]}
{"op":"mcm","clk":"11838202302","pt":1723184566097,"mc":[{"id":"1.231581347","rc":[{"batb":[[0,3.45,4],[1,3.4,2],[2,3.35,7.45]],"ltp":3.5,"tv":414.76,"id":12474498}]}]}
{"op":"mcm","clk":"11838202358","pt":1723184568304,"mc":[{"id":"1.231581347","rc":[{"batb":[[2,3.15,17.63]],"ltp":3.5,"tv":414.76,"id":12474498}]}]}
{"op":"mcm","clk":"11838202386","pt":1723184569124,"mc":[{"id":"1.231581347","rc":[{"batb":[[0,3.4,2],[1,3.15,17.63],[2,1.88,171.49]],"ltp":3.5,"tv":414.76,"id":12474498}]}]}
{"op":"mcm","clk":"11838202577","pt":1723184573230,"mc":[{"id":"1.231581347","rc":[{"batb":[[0,3.45,4],[1,3.4,2],[2,3.15,17.63]],"ltp":3.5,"tv":414.76,"id":12474498}]}]}
{"op":"mcm","clk":"11838202693","pt":1723184575906,"mc":[{"id":"1.231581347","rc":[{"batb":[[0,3.4,2],[1,3.15,17.63],[2,1.88,171.49]],"ltp":3.5,"tv":414.76,"id":12474498}]}]}
{"op":"mcm","clk":"11838202839","pt":1723184580318,"mc":[{"id":"1.231581347","rc":[{"batb":[[0,3.45,4],[1,3.4,2],[2,3.15,17.63]],"ltp":3.5,"tv":414.76,"id":12474498}]}]}
{"op":"mcm","clk":"11838202927","pt":1723184582803,"mc":[{"id":"1.231581347","rc":[{"batb":[[0,3.4,2],[1,3.15,17.63],[2,1.88,171.49]],"ltp":3.5,"tv":414.76,"id":12474498}]}]}
{"op":"mcm","clk":"11838203093","pt":1723184587027,"mc":[{"id":"1.231581347","rc":[{"batb":[[0,3.45,4],[1,3.4,2],[2,3.15,17.63]],"ltp":3.5,"tv":414.76,"id":12474498}]}]}
{"op":"mcm","clk":"11838203232","pt":1723184589505,"mc":[{"id":"1.231581347","rc":[{"batb":[[0,3.4,2],[1,3.15,17.63],[2,1.88,171.49]],"ltp":3.5,"tv":414.76,"id":12474498}]}]}
{"op":"mcm","clk":"11838203390","pt":1723184592636,"mc":[{"id":"1.231581347","rc":[{"batb":[[0,3.45,4],[1,3.4,2],[2,3.15,17.63]],"ltp":3.5,"tv":414.76,"id":12474498}]}]}
{"op":"mcm","clk":"11838203468","pt":1723184595006,"mc":[{"id":"1.231581347","rc":[{"batb":[[0,3.4,2],[1,3.15,17.63],[2,1.88,171.49]],"ltp":3.5,"tv":414.76,"id":12474498}]}]}
{"op":"mcm","clk":"11838203563","pt":1723184597629,"mc":[{"id":"1.231581347","rc":[{"batb":[[0,3.45,4],[1,3.4,2],[2,3.15,17.63]],"ltp":3.5,"tv":414.76,"id":12474498}]}]}
{"op":"mcm","clk":"11838203637","pt":1723184600033,"mc":[{"id":"1.231581347","rc":[{"batb":[[0,3.4,2],[1,3.15,17.63],[2,1.88,171.49]],"ltp":3.5,"tv":414.76,"id":12474498}]}]}
{"op":"mcm","clk":"11838203732","pt":1723184602655,"mc":[{"id":"1.231581347","rc":[{"batb":[[0,3.45,4],[1,3.4,2],[2,3.15,17.63]],"ltp":3.5,"tv":414.76,"id":12474498}]}]}
{"op":"mcm","clk":"11838203823","pt":1723184605424,"mc":[{"id":"1.231581347","rc":[{"batb":[[0,3.4,2],[1,3.15,17.63],[2,1.88,171.49]],"ltp":3.5,"tv":414.76,"id":12474498}]}]}
{"op":"mcm","clk":"11838203954","pt":1723184609066,"mc":[{"id":"1.231581347","rc":[{"batb":[[0,3.45,4],[1,3.4,2],[2,3.15,17.63]],"ltp":3.5,"tv":414.76,"id":12474498}]}]}
{"op":"mcm","clk":"11838204049","pt":1723184611654,"mc":[{"id":"1.231581347","rc":[{"batb":[[0,3.4,2],[1,3.15,17.63],[2,1.88,171.49]],"ltp":3.5,"tv":414.76,"id":12474498}]}]}
{"op":"mcm","clk":"11838204116","pt":1723184614328,"mc":[{"id":"1.231581347","rc":[{"batb":[[0,3.45,4],[1,3.4,2],[2,3.15,17.63]],"ltp":3.5,"tv":414.76,"id":12474498}]}]}
{"op":"mcm","clk":"11838204188","pt":1723184616743,"mc":[{"id":"1.231581347","rc":[{"batb":[[0,3.4,2],[1,3.15,17.63],[2,1.88,171.49]],"ltp":3.5,"tv":414.76,"id":12474498}]}]}
{"op":"mcm","clk":"11838204279","pt":1723184619053,"mc":[{"id":"1.231581347","rc":[{"batb":[[0,3.45,4],[1,3.4,2],[2,3.15,17.63]],"ltp":3.5,"tv":414.76,"id":12474498}]}]}
