{"op":"mcm","clk":"11789427353","pt":1723022148074,"mc":[{"id":"1.231540926","marketDefinition":{"bspMarket":false,"turnInPlayEnabled":true,"persistenceEnabled":true,"marketBaseRate":5.0,"eventId":"33474954","eventTypeId":"4","numberOfWinners":1,"bettingType":"ODDS","marketType":"MATCH_ODDS","marketTime":"2024-08-09T20:00:00.000Z","suspendTime":"2024-08-09T20:00:00.000Z","bspReconciled":false,"complete":true,"inPlay":false,"crossMatching":true,"runnersVoidable":false,"numberOfActiveRunners":2,"betDelay":0,"status":"OPEN","runners":[{"status":"ACTIVE","sortPriority":1,"id":71847983,"name":"Mississauga Bangla Tigers"},{"status":"ACTIVE","sortPriority":2,"id":19144236,"name":"Toronto Nationals"}],"regulators":["MR_INT"],"countryCode":"GB","discountAllowed":false,"timezone":"GMT","openDate":"2024-08-09T20:00:00.000Z","version":6060473688,"name":"Match Odds","eventName":"Mississauga Bangla Tigers v Toronto Nationals"},"rc":[{"batb":[[0,1.03,200],[1,1.02,200],[2,1.01,220]],"ltp":0.0,"tv":0.0,"id":71847983},{"batb":[[0,1.03,200],[1,1.02,200],[2,1.01,220]],"ltp":0.0,"tv":0.0,"id":19144236}]}]}
{"op":"mcm","clk":"11789427427","pt":1723022149179,"mc":[{"id":"1.231540926","marketDefinition":{"bspMarket":false,"turnInPlayEnabled":true,"persistenceEnabled":true,"marketBaseRate":5.0,"eventId":"33474954","eventTypeId":"4","numberOfWinners":1,"bettingType":"ODDS","marketType":"MATCH_ODDS","marketTime":"2024-08-09T20:00:00.000Z","suspendTime":"2024-08-09T20:00:00.000Z","bspReconciled":false,"complete":true,"inPlay":false,"crossMatching":true,"runnersVoidable":false,"numberOfActiveRunners":2,"betDelay":0,"status":"OPEN","runners":[{"status":"ACTIVE","sortPriority":1,"id":71847983,"name":"Mississauga Bangla Tigers"},{"status":"ACTIVE","sortPriority":2,"id":19144236,"name":"Toronto Nationals"}],"regulators":["MR_INT"],"countryCode":"GB","discountAllowed":true,"timezone":"GMT","openDate":"2024-08-09T20:00:00.000Z","version":6060473688,"name":"Match Odds","eventName":"Mississauga Bangla Tigers v Toronto Nationals"}}]}
{"op":"mcm","clk":"11789433542","pt":1723022240042,"mc":[{"id":"1.231540926","rc":[{"batb":[[2,1.01,6439.38]],"ltp":0.0,"tv":0.0,"id":71847983}]}]}
{"op":"mcm","clk":"11789433604","pt":1723022241073,"mc":[{"id":"1.231540926","rc":[{"batb":[[0,1.04,1639.3],[1,1.03,2369.69],[2,1.02,3403.82]],"ltp":0.0,"tv":0.0,"id":71847983},{"batb":[[0,1.03,2369.69],[1,1.02,3403.82],[2,1.01,6439.38]],"ltp":0.0,"tv":0.0,"id":19144236}]}]}
{"op":"mcm","clk":"11789433624","pt":1723022241278,"mc":[{"id":"1.231540926","rc":[{"batb":[[0,1.04,1639.3],[1,1.03,2369.69],[2,1.02,3403.82]],"ltp":0.0,"tv":0.0,"id":19144236}]}]}
{"op":"mcm","clk":"11789517051","pt":1723023467886,"mc":[{"id":"1.231540926","rc":[{"batb":[[0,1.05,100],[1,1.04,1639.3],[2,1.03,2369.69]],"ltp":0.0,"tv":0.0,"id":71847983},{"batb":[[0,1.05,100],[1,1.04,1639.3],[2,1.03,2369.69]],"ltp":0.0,"tv":0.0,"id":19144236}]}]}
{"op":"mcm","clk":"11789666558","pt":1723025574921,"mc":[{"id":"1.231540926","rc":[{"batb":[[1,1.04,1637.47],[2,1.03,2367.27]],"ltp":0.0,"tv":0.0,"id":71847983},{"batb":[[1,1.04,1637.47],[2,1.03,2367.27]],"ltp":0.0,"tv":0.0,"id":19144236}]}]}
{"op":"mcm","clk":"11789806451","pt":1723027307625,"mc":[{"id":"1.231540926","rc":[{"batb":[[2,1.03,2368.05]],"ltp":0.0,"tv":0.0,"id":71847983},{"batb":[[2,1.03,2368.05]],"ltp":0.0,"tv":0.0,"id":19144236}]}]}
{"op":"mcm","clk":"11789823083","pt":1723027522636,"mc":[{"id":"1.231540926","rc":[{"batb":[[0,1.1,20],[1,1.05,100],[2,1.04,1637.47]],"ltp":0.0,"tv":0.0,"id":71847983},{"batb":[[0,1.09,40],[1,1.05,100],[2,1.04,1637.47]],"ltp":0.0,"tv":0.0,"id":19144236}]}]}
{"op":"mcm","clk":"11790022063","pt":1723030272893,"mc":[{"id":"1.231540926","rc":[{"batb":[[0,1.11,20],[1,1.1,20],[2,1.05,100]],"ltp":0.0,"tv":0.0,"id":71847983},{"batb":[[0,1.11,20],[1,1.09,40],[2,1.05,100]],"ltp":0.0,"tv":0.0,"id":19144236}]}]}
{"op":"mcm","clk":"11790491100","pt":1723037792702,"mc":[{"id":"1.231540926","rc":[{"batb":[[0,1.5,50.9],[1,1.11,20],[2,1.09,40]],"ltp":0.0,"tv":0.0,"id":19144236}]}]}
{"op":"mcm","clk":"11790491764","pt":1723037804793,"mc":[{"id":"1.231540926","rc":[{"batb":[[0,1.5,50.9],[1,1.11,20],[2,1.1,20]],"ltp":0.0,"tv":0.0,"id":71847983}]}]}
{"op":"mcm","clk":"11790492395","pt":1723037816929,"mc":[{"id":"1.231540926","rc":[{"trd":[[1.5,81.81]],"batb":[[0,1.5,9.99]],"ltp":1.5,"tv":81.8,"id":19144236}],"tv":81.8}]}
{"op":"mcm","clk":"11790492823","pt":1723037824041,"mc":[{"id":"1.231540926","rc":[{"trd":[[1.5,81.81]],"batb":[[0,1.5,9.99]],"ltp":1.5,"tv":81.8,"id":71847983}],"tv":163.61}]}
{"op":"mcm","clk":"11790493610","pt":1723037839166,"mc":[{"id":"1.231540926","rc":[{"batb":[[0,1.5,45.33]],"ltp":1.5,"tv":81.8,"id":19144236}]}]}
{"op":"mcm","clk":"11790494284","pt":1723037852651,"mc":[{"id":"1.231540926","rc":[{"batb":[[0,1.5,45.33]],"ltp":1.5,"tv":81.8,"id":71847983}]}]}
{"op":"mcm","clk":"11790494829","pt":1723037862964,"mc":[{"id":"1.231540926","rc":[{"trd":[[1.5,122.71]],"batb":[[0,1.5,24.88]],"ltp":1.5,"tv":122.71,"id":19144236}],"tv":204.52}]}
{"op":"mcm","clk":"11790495142","pt":1723037869975,"mc":[{"id":"1.231540926","rc":[{"trd":[[1.5,122.71]],"batb":[[0,1.5,24.88]],"ltp":1.5,"tv":122.71,"id":71847983}],"tv":245.42}]}
{"op":"mcm","clk":"11790495664","pt":1723037879975,"mc":[{"id":"1.231540926","rc":[{"trd":[[1.5,143.17]],"batb":[[0,1.5,14.66]],"ltp":1.5,"tv":143.16,"id":19144236}],"tv":265.87}]}
{"op":"mcm","clk":"11790496125","pt":1723037888018,"mc":[{"id":"1.231540926","rc":[{"trd":[[1.5,143.17]],"batb":[[0,1.5,14.66]],"ltp":1.5,"tv":143.16,"id":71847983}],"tv":286.33}]}
{"op":"mcm","clk":"11790497212","pt":1723037908017,"mc":[{"id":"1.231540926","rc":[{"trd":[[1.5,153.39]],"batb":[[0,1.5,9.54]],"ltp":1.5,"tv":153.39,"id":19144236}],"tv":296.55}]}
{"op":"mcm","clk":"11790497675","pt":1723037916232,"mc":[{"id":"1.231540926","rc":[{"trd":[[1.5,153.39]],"batb":[[0,1.5,9.54]],"ltp":1.5,"tv":153.39,"id":71847983}],"tv":306.78}]}
{"op":"mcm","clk":"11790498155","pt":1723037924953,"mc":[{"id":"1.231540926","rc":[{"trd":[[1.5,158.5]],"batb":[[0,1.5,6.99]],"ltp":1.5,"tv":158.5,"id":71847983}],"tv":311.89}]}
{"op":"mcm","clk":"11790498567","pt":1723037932276,"mc":[{"id":"1.231540926","rc":[{"trd":[[1.5,158.5]],"batb":[[0,1.5,6.99]],"ltp":1.5,"tv":158.5,"id":19144236}],"tv":317.0}]}
{"op":"mcm","clk":"11790501283","pt":1723037975554,"mc":[{"id":"1.231540926","rc":[{"batb":[[0,1.11,20],[1,1.1,20],[2,1.05,100]],"ltp":1.5,"tv":158.5,"id":71847983}]}]}
{"op":"mcm","clk":"11790501456","pt":1723037978751,"mc":[{"id":"1.231540926","rc":[{"batb":[[0,1.11,20],[1,1.09,40],[2,1.05,100]],"ltp":1.5,"tv":158.5,"id":19144236}]}]}
{"op":"mcm","clk":"11790605349","pt":1723039808681,"mc":[{"id":"1.231540926","rc":[{"trd":[[1.5,158.57]],"batb":[[0,1.12,71.91],[1,1.11,20],[2,1.1,20]],"ltp":1.5,"tv":158.56,"id":71847983},{"trd":[[1.5,158.57]],"batb":[[0,1.12,71.91],[1,1.11,20],[2,1.09,40]],"ltp":1.5,"tv":158.56,"id":19144236}],"tv":317.13}]}
{"op":"mcm","clk":"11790616604","pt":1723039979074,"mc":[{"id":"1.231540926","rc":[{"batb":[[0,1.13,20],[1,1.12,71.91]],"ltp":1.5,"tv":158.56,"id":71847983},{"batb":[[0,1.13,20],[1,1.12,71.91]],"ltp":1.5,"tv":158.56,"id":19144236}]}]}
{"op":"mcm","clk":"11790728341","pt":1723041609736,"mc":[{"id":"1.231540926","rc":[{"batb":[[1,1.1,20],[2,1.05,100]],"ltp":1.5,"tv":158.56,"id":71847983},{"batb":[[1,1.09,40],[2,1.05,100]],"ltp":1.5,"tv":158.56,"id":19144236}]}]}
{"op":"mcm","clk":"11790733452","pt":1723041665596,"mc":[{"id":"1.231540926","rc":[{"batb":[[0,1.14,61.63],[1,1.13,20],[2,1.1,20]],"ltp":1.5,"tv":158.56,"id":71847983},{"batb":[[0,1.14,61.63],[1,1.13,20],[2,1.09,40]],"ltp":1.5,"tv":158.56,"id":19144236}]}]}
{"op":"mcm","clk":"11790759345","pt":1723041859100,"mc":[{"id":"1.231540926","rc":[{"batb":[[1,1.1,20],[2,1.05,100]],"ltp":1.5,"tv":158.56,"id":71847983},{"batb":[[1,1.09,40],[2,1.05,100]],"ltp":1.5,"tv":158.56,"id":19144236}]}]}
{"op":"mcm","clk":"11790759356","pt":1723041859202,"mc":[{"id":"1.231540926","rc":[{"batb":[[0,1.15,20],[1,1.14,61.63],[2,1.1,20]],"ltp":1.5,"tv":158.56,"id":71847983},{"batb":[[0,1.15,20],[1,1.14,61.63],[2,1.09,40]],"ltp":1.5,"tv":158.56,"id":19144236}]}]}
{"op":"mcm","clk":"11790911561","pt":1723043468425,"mc":[{"id":"1.231540926","rc":[{"trd":[[1.5,158.47]],"batb":[[1,1.1,20],[2,1.05,100]],"ltp":1.5,"tv":158.46,"id":71847983},{"trd":[[1.5,158.47]],"batb":[[1,1.09,40],[2,1.05,100]],"ltp":1.5,"tv":158.46,"id":19144236}],"tv":316.93}]}
{"op":"mcm","clk":"11790915941","pt":1723043514419,"mc":[{"id":"1.231540926","rc":[{"batb":[[0,1.16,53.98],[1,1.15,20],[2,1.1,20]],"ltp":1.5,"tv":158.46,"id":71847983},{"batb":[[0,1.16,53.98],[1,1.15,20],[2,1.09,40]],"ltp":1.5,"tv":158.46,"id":19144236}]}]}
{"op":"mcm","clk":"11790951998","pt":1723043875342,"mc":[{"id":"1.231540926","rc":[{"batb":[[0,1.17,20],[1,1.16,53.98]],"ltp":1.5,"tv":158.46,"id":71847983},{"batb":[[0,1.17,20],[1,1.16,53.98]],"ltp":1.5,"tv":158.46,"id":19144236}]}]}
{"op":"mcm","clk":"11791093301","pt":1723045315858,"mc":[{"id":"1.231540926","rc":[{"batb":[[1,1.1,20],[2,1.05,100]],"ltp":1.5,"tv":158.46,"id":71847983},{"batb":[[1,1.09,40],[2,1.05,100]],"ltp":1.5,"tv":158.46,"id":19144236}]}]}
{"op":"mcm","clk":"11791098564","pt":1723045361282,"mc":[{"id":"1.231540926","rc":[{"batb":[[0,1.18,47.98],[1,1.17,20],[2,1.1,20]],"ltp":1.5,"tv":158.46,"id":71847983},{"batb":[[0,1.18,47.98],[1,1.17,20],[2,1.09,40]],"ltp":1.5,"tv":158.46,"id":19144236}]}]}
{"op":"mcm","clk":"11791149251","pt":1723045922417,"mc":[{"id":"1.231540926","rc":[{"batb":[[0,1.19,20],[1,1.18,47.98]],"ltp":1.5,"tv":158.46,"id":71847983},{"batb":[[0,1.19,20],[1,1.18,47.98]],"ltp":1.5,"tv":158.46,"id":19144236}]}]}
{"op":"mcm","clk":"11791223750","pt":1723046754153,"mc":[{"id":"1.231540926","rc":[{"trd":[[1.5,158.55]],"batb":[[0,1.25,100],[1,1.19,20],[2,1.18,47.97]],"ltp":1.5,"tv":158.55,"id":71847983},{"trd":[[1.5,158.55]],"batb":[[0,1.25,100],[1,1.19,20],[2,1.18,47.97]],"ltp":1.5,"tv":158.55,"id":19144236}],"tv":317.1}]}
{"op":"mcm","clk":"11791253064","pt":1723047085167,"mc":[{"id":"1.231540926","rc":[{"batb":[[0,1.26,10],[1,1.25,100],[2,1.19,20]],"ltp":1.5,"tv":158.55,"id":71847983},{"batb":[[0,1.26,10],[1,1.25,100],[2,1.19,20]],"ltp":1.5,"tv":158.55,"id":19144236}]}]}
{"op":"mcm","clk":"11791273188","pt":1723047201912,"mc":[{"id":"1.231540926","rc":[{"batb":[[0,1.27,31.98],[1,1.26,10],[2,1.25,100]],"ltp":1.5,"tv":158.55,"id":71847983},{"batb":[[0,1.27,31.98],[1,1.26,10],[2,1.25,100]],"ltp":1.5,"tv":158.55,"id":19144236}]}]}
{"op":"mcm","clk":"11791293439","pt":1723047389895,"mc":[{"id":"1.231540926","rc":[{"batl":[[0,1.35,0.7]],"ltp":1.5,"tv":158.55,"id":71847983}]}]}
{"op":"mcm","clk":"11791296416","pt":1723047416834,"mc":[{"id":"1.231540926","rc":[{"batl":[[0,1.35,1.05]],"ltp":1.5,"tv":158.55,"id":71847983}]}]}
{"op":"mcm","clk":"11791300155","pt":1723047449299,"mc":[{"id":"1.231540926","rc":[{"trd":[[1.35,2.11]],"batb":[[0,1.35,2.6],[1,1.27,31.98],[2,1.26,10]],"ltp":1.35,"tv":160.66,"id":71847983}],"tv":319.21}]}
{"op":"mcm","clk":"11791300598","pt":1723047453057,"mc":[{"id":"1.231540926","rc":[{"batb":[[0,1.27,31.98],[1,1.26,10],[2,1.25,100]],"ltp":1.35,"tv":160.66,"id":71847983}]}]}
{"op":"mcm","clk":"11791301723","pt":1723047462500,"mc":[{"id":"1.231540926","rc":[{"batb":[[0,1.28,14],[1,1.27,31.98],[2,1.26,10]],"batl":[[0,3,1.05]],"ltp":1.35,"tv":160.66,"id":71847983}]}]}
{"op":"mcm","clk":"11791301992","pt":1723047464899,"mc":[{"id":"1.231540926","rc":[{"batb":[[0,1.28,10]],"ltp":1.35,"tv":160.66,"id":71847983}]}]}
{"op":"mcm","clk":"11791302094","pt":1723047465694,"mc":[{"id":"1.231540926","rc":[{"batb":[[0,1.27,31.98],[1,1.26,10],[2,1.25,100]],"ltp":1.35,"tv":160.66,"id":71847983}]}]}
{"op":"mcm","clk":"11791306375","pt":1723047506526,"mc":[{"id":"1.231540926","rc":[{"batb":[[0,1.28,14],[1,1.27,31.98],[2,1.26,10]],"batl":[[0,3,1.19]],"ltp":1.35,"tv":160.66,"id":71847983}]}]}
{"op":"mcm","clk":"11791306615","pt":1723047508612,"mc":[{"id":"1.231540926","rc":[{"batb":[[0,1.28,10]],"ltp":1.35,"tv":160.66,"id":71847983}]}]}
{"op":"mcm","clk":"11791306770","pt":1723047509815,"mc":[{"id":"1.231540926","rc":[{"batb":[[0,1.27,31.98],[1,1.26,10],[2,1.25,100]],"ltp":1.35,"tv":160.66,"id":71847983}]}]}
{"op":"mcm","clk":"11791307088","pt":1723047512522,"mc":[{"id":"1.231540926","rc":[{"batb":[[0,1.28,14],[1,1.27,31.98],[2,1.26,10]],"batl":[[0,3,1.05]],"ltp":1.35,"tv":160.66,"id":71847983}]}]}
{"op":"mcm","clk":"11791307298","pt":1723047514708,"mc":[{"id":"1.231540926","rc":[{"batb":[[0,1.28,10]],"ltp":1.35,"tv":160.66,"id":71847983}]}]}
{"op":"mcm","clk":"11791307401","pt":1723047515711,"mc":[{"id":"1.231540926","rc":[{"batb":[[0,1.27,31.98],[1,1.26,10],[2,1.25,100]],"ltp":1.35,"tv":160.66,"id":71847983}]}]}
{"op":"mcm","clk":"11791308375","pt":1723047525337,"mc":[{"id":"1.231540926","rc":[{"batb":[[0,1.28,14],[1,1.27,31.98],[2,1.26,10]],"batl":[[0,3,2.46]],"ltp":1.35,"tv":160.66,"id":71847983}]}]}
{"op":"mcm","clk":"11791308662","pt":1723047527745,"mc":[{"id":"1.231540926","rc":[{"batb":[[0,1.28,10]],"ltp":1.35,"tv":160.66,"id":71847983}]}]}
{"op":"mcm","clk":"11791308775","pt":1723047528641,"mc":[{"id":"1.231540926","rc":[{"batb":[[0,1.27,31.98],[1,1.26,10],[2,1.25,100]],"ltp":1.35,"tv":160.66,"id":71847983}]}]}
{"op":"mcm","clk":"11791311468","pt":1723047555396,"mc":[{"id":"1.231540926","rc":[{"batb":[[0,1.28,14],[1,1.27,31.98],[2,1.26,10]],"batl":[[0,3,1.05]],"ltp":1.35,"tv":160.66,"id":71847983}]}]}
{"op":"mcm","clk":"11791311725","pt":1723047557701,"mc":[{"id":"1.231540926","rc":[{"batb":[[0,1.28,10]],"ltp":1.35,"tv":160.66,"id":71847983}]}]}
{"op":"mcm","clk":"11791311850","pt":1723047558787,"mc":[{"id":"1.231540926","rc":[{"batb":[[0,1.27,31.98],[1,1.26,10],[2,1.25,100]],"ltp":1.35,"tv":160.66,"id":71847983}]}]}
{"op":"mcm","clk":"11791314649","pt":1723047585770,"mc":[{"id":"1.231540926","rc":[{"batb":[[0,1.28,14],[1,1.27,31.98],[2,1.26,10]],"ltp":1.35,"tv":160.66,"id":71847983}]}]}
{"op":"mcm","clk":"11791314887","pt":1723047587841,"mc":[{"id":"1.231540926","rc":[{"batb":[[0,1.28,10]],"ltp":1.35,"tv":160.66,"id":71847983}]}]}
{"op":"mcm","clk":"11791315016","pt":1723047588820,"mc":[{"id":"1.231540926","rc":[{"batb":[[0,1.27,31.98],[1,1.26,10],[2,1.25,100]],"ltp":1.35,"tv":160.66,"id":71847983}]}]}
{"op":"mcm","clk":"11791336064","pt":1723047795136,"mc":[{"id":"1.231540926","rc":[{"batb":[[0,1.28,24],[1,1.27,31.98]],"ltp":1.35,"tv":160.66,"id":71847983}]}]}
{"op":"mcm","clk":"11791336260","pt":1723047797219,"mc":[{"id":"1.231540926","rc":[{"batb":[[0,1.28,20]],"ltp":1.35,"tv":160.66,"id":71847983}]}]}
{"op":"mcm","clk":"11791336382","pt":1723047798526,"mc":[{"id":"1.231540926","rc":[{"batb":[[0,1.28,10]],"ltp":1.35,"tv":160.66,"id":71847983}]}]}
{"op":"mcm","clk":"11791338255","pt":1723047817526,"mc":[{"id":"1.231540926","rc":[{"batb":[[0,1.29,14],[1,1.28,10],[2,1.27,31.98]],"ltp":1.35,"tv":160.66,"id":71847983}]}]}
{"op":"mcm","clk":"11791338491","pt":1723047819564,"mc":[{"id":"1.231540926","rc":[{"batb":[[0,1.29,10]],"ltp":1.35,"tv":160.66,"id":71847983}]}]}
{"op":"mcm","clk":"11791338572","pt":1723047820451,"mc":[{"id":"1.231540926","rc":[{"batb":[[0,1.28,10],[1,1.27,31.98],[2,1.25,100]],"ltp":1.35,"tv":160.66,"id":71847983}]}]}
{"op":"mcm","clk":"11791342336","pt":1723047869245,"mc":[{"id":"1.231540926","rc":[{"batb":[[0,1.29,14],[1,1.28,10],[2,1.27,31.98]],"ltp":1.35,"tv":160.66,"id":71847983}]}]}
{"op":"mcm","clk":"11791342525","pt":1723047872009,"mc":[{"id":"1.231540926","rc":[{"batb":[[0,1.29,10]],"ltp":1.35,"tv":160.66,"id":71847983}]}]}
{"op":"mcm","clk":"11791342603","pt":1723047872912,"mc":[{"id":"1.231540926","rc":[{"batb":[[0,1.28,10],[1,1.27,31.98],[2,1.25,100]],"ltp":1.35,"tv":160.66,"id":71847983}]}]}
{"op":"mcm","clk":"11791342998","pt":1723047878410,"mc":[{"id":"1.231540926","rc":[{"batb":[[0,1.29,14],[1,1.28,10],[2,1.27,31.98]],"ltp":1.35,"tv":160.66,"id":71847983}]}]}
{"op":"mcm","clk":"11791343154","pt":1723047880747,"mc":[{"id":"1.231540926","rc":[{"batb":[[0,1.29,10]],"ltp":1.35,"tv":160.66,"id":71847983}]}]}
{"op":"mcm","clk":"11791343247","pt":1723047881838,"mc":[{"id":"1.231540926","rc":[{"batb":[[0,1.28,10],[1,1.27,31.98],[2,1.25,100]],"ltp":1.35,"tv":160.66,"id":71847983}]}]}
{"op":"mcm","clk":"11791349005","pt":1723047949121,"mc":[{"id":"1.231540926","rc":[{"trd":[[3,0.04]],"batl":[[0,3,1.02]],"ltp":3.0,"tv":160.69,"id":71847983},{"trd":[[1.5,158.62]],"ltp":1.5,"tv":158.62,"id":19144236}],"tv":319.31}]}
{"op":"mcm","clk":"11791349048","pt":1723047949330,"mc":[{"id":"1.231540926","rc":[{"batb":[[0,1.29,14],[1,1.28,10],[2,1.27,31.98]],"ltp":3.0,"tv":160.69,"id":71847983}]}]}
{"op":"mcm","clk":"11791349266","pt":1723047951810,"mc":[{"id":"1.231540926","rc":[{"batb":[[0,1.29,10]],"ltp":3.0,"tv":160.69,"id":71847983}]}]}
{"op":"mcm","clk":"11791349352","pt":1723047952847,"mc":[{"id":"1.231540926","rc":[{"batb":[[0,1.28,10],[1,1.27,31.98],[2,1.25,100]],"ltp":3.0,"tv":160.69,"id":71847983}]}]}
{"op":"mcm","clk":"11791349642","pt":1723047956012,"mc":[{"id":"1.231540926","rc":[{"batb":[[0,1.29,14],[1,1.28,10],[2,1.27,31.98]],"ltp":3.0,"tv":160.69,"id":71847983}]}]}
{"op":"mcm","clk":"11791349866","pt":1723047958445,"mc":[{"id":"1.231540926","rc":[{"batb":[[0,1.29,10]],"ltp":3.0,"tv":160.69,"id":71847983}]}]}
{"op":"mcm","clk":"11791349936","pt":1723047959430,"mc":[{"id":"1.231540926","rc":[{"batb":[[0,1.28,10],[1,1.27,31.98],[2,1.25,100]],"ltp":3.0,"tv":160.69,"id":71847983}]}]}
{"op":"mcm","clk":"11791353492","pt":1723048004823,"mc":[{"id":"1.231540926","rc":[{"batb":[[0,1.29,14],[1,1.28,16.72],[2,1.27,31.98]],"ltp":3.0,"tv":160.69,"id":71847983},{"batb":[[0,1.28,7.71],[1,1.27,31.98],[2,1.26,10]],"ltp":1.5,"tv":158.62,"id":19144236}]}]}
{"op":"mcm","clk":"11791353639","pt":1723048007004,"mc":[{"id":"1.231540926","rc":[{"batb":[[0,1.29,10]],"ltp":3.0,"tv":160.69,"id":71847983}]}]}
{"op":"mcm","clk":"11791353699","pt":1723048007888,"mc":[{"id":"1.231540926","rc":[{"batb":[[0,1.28,16.72],[1,1.27,31.98],[2,1.25,100]],"ltp":3.0,"tv":160.69,"id":71847983}]}]}
{"op":"mcm","clk":"11791355941","pt":1723048036436,"mc":[{"id":"1.231540926","rc":[{"batb":[[0,1.29,14],[1,1.28,16.72],[2,1.27,31.98]],"ltp":3.0,"tv":160.69,"id":71847983}]}]}
{"op":"mcm","clk":"11791356110","pt":1723048038619,"mc":[{"id":"1.231540926","rc":[{"batb":[[0,1.29,10]],"ltp":3.0,"tv":160.69,"id":71847983}]}]}
{"op":"mcm","clk":"11791356192","pt":1723048039759,"mc":[{"id":"1.231540926","rc":[{"batb":[[0,1.28,16.72],[1,1.27,31.98],[2,1.25,100]],"ltp":3.0,"tv":160.69,"id":71847983}]}]}
{"op":"mcm","clk":"11791356947","pt":1723048050139,"mc":[{"id":"1.231540926","rc":[{"batb":[[0,1.29,14],[1,1.28,16.72],[2,1.27,31.98]],"ltp":3.0,"tv":160.69,"id":71847983}]}]}
{"op":"mcm","clk":"11791357124","pt":1723048052670,"mc":[{"id":"1.231540926","rc":[{"batb":[[0,1.29,10]],"ltp":3.0,"tv":160.69,"id":71847983}]}]}
{"op":"mcm","clk":"11791357203","pt":1723048053665,"mc":[{"id":"1.231540926","rc":[{"batb":[[0,1.28,16.72],[1,1.27,31.98],[2,1.25,100]],"ltp":3.0,"tv":160.69,"id":71847983}]}]}
{"op":"mcm","clk":"11791358563","pt":1723048071861,"mc":[{"id":"1.231540926","rc":[{"batb":[[0,1.29,14],[1,1.28,16.72],[2,1.27,31.98]],"ltp":3.0,"tv":160.69,"id":71847983}]}]}
{"op":"mcm","clk":"11791358719","pt":1723048074180,"mc":[{"id":"1.231540926","rc":[{"batb":[[0,1.29,10]],"ltp":3.0,"tv":160.69,"id":71847983}]}]}
{"op":"mcm","clk":"11791358786","pt":1723048075168,"mc":[{"id":"1.231540926","rc":[{"batb":[[0,1.28,16.72],[1,1.27,31.98],[2,1.25,100]],"ltp":3.0,"tv":160.69,"id":71847983}]}]}
{"op":"mcm","clk":"11791360509","pt":1723048096889,"mc":[{"id":"1.231540926","rc":[{"batb":[[0,1.29,14],[1,1.28,16.72],[2,1.27,31.98]],"ltp":3.0,"tv":160.69,"id":71847983}]}]}
{"op":"mcm","clk":"11791360746","pt":1723048100110,"mc":[{"id":"1.231540926","rc":[{"batb":[[0,1.28,16.72],[1,1.27,31.98],[2,1.25,100]],"ltp":3.0,"tv":160.69,"id":71847983}]}]}
{"op":"mcm","clk":"11791361901","pt":1723048115648,"mc":[{"id":"1.231540926","rc":[{"batb":[[0,1.29,14],[1,1.28,16.72],[2,1.27,31.98]],"ltp":3.0,"tv":160.69,"id":71847983}]}]}
{"op":"mcm","clk":"11791362101","pt":1723048118143,"mc":[{"id":"1.231540926","rc":[{"batb":[[0,1.29,10]],"ltp":3.0,"tv":160.69,"id":71847983}]}]}
{"op":"mcm","clk":"11791362185","pt":1723048119173,"mc":[{"id":"1.231540926","rc":[{"batb":[[0,1.28,16.72],[1,1.27,31.98],[2,1.25,100]],"ltp":3.0,"tv":160.69,"id":71847983}]}]}
{"op":"mcm","clk":"11791362996","pt":1723048129244,"mc":[{"id":"1.231540926","rc":[{"batb":[[0,1.29,14],[1,1.28,16.72],[2,1.27,31.98]],"ltp":3.0,"tv":160.69,"id":71847983}]}]}
{"op":"mcm","clk":"11791363180","pt":1723048131679,"mc":[{"id":"1.231540926","rc":[{"batb":[[0,1.29,10]],"ltp":3.0,"tv":160.69,"id":71847983}]}]}
{"op":"mcm","clk":"11791363248","pt":1723048132558,"mc":[{"id":"1.231540926","rc":[{"batb":[[0,1.28,16.72],[1,1.27,31.98],[2,1.25,100]],"ltp":3.0,"tv":160.69,"id":71847983}]}]}
{"op":"mcm","clk":"11791364336","pt":1723048145981,"mc":[{"id":"1.231540926","rc":[{"batb":[[0,1.29,14],[1,1.28,16.72],[2,1.27,31.98]],"ltp":3.0,"tv":160.69,"id":71847983}]}]}
{"op":"mcm","clk":"11791364564","pt":1723048148287,"mc":[{"id":"1.231540926","rc":[{"batb":[[0,1.29,10]],"ltp":3.0,"tv":160.69,"id":71847983}]}]}
{"op":"mcm","clk":"11791364666","pt":1723048149375,"mc":[{"id":"1.231540926","rc":[{"batb":[[0,1.28,16.72],[1,1.27,31.98],[2,1.25,100]],"ltp":3.0,"tv":160.69,"id":71847983}]}]}
{"op":"mcm","clk":"11791378800","pt":1723048297525,"mc":[{"id":"1.231540926","rc":[{"batb":[[0,1.29,14],[1,1.28,16.72],[2,1.27,31.98]],"ltp":3.0,"tv":160.69,"id":71847983}]}]}
{"op":"mcm","clk":"11791379070","pt":1723048300356,"mc":[{"id":"1.231540926","rc":[{"batb":[[0,1.29,10]],"ltp":3.0,"tv":160.69,"id":71847983}]}]}
{"op":"mcm","clk":"11791379188","pt":1723048301437,"mc":[{"id":"1.231540926","rc":[{"batb":[[0,1.28,16.72],[1,1.27,31.98],[2,1.25,100]],"ltp":3.0,"tv":160.69,"id":71847983}]}]}
{"op":"mcm","clk":"11791389786","pt":1723048407282,"mc":[{"id":"1.231540926","rc":[{"batb":[[0,1.29,14],[1,1.28,16.72],[2,1.27,31.98]],"ltp":3.0,"tv":160.69,"id":71847983}]}]}
{"op":"mcm","clk":"11791390065","pt":1723048409452,"mc":[{"id":"1.231540926","rc":[{"batb":[[0,1.29,10]],"ltp":3.0,"tv":160.69,"id":71847983}]}]}
{"op":"mcm","clk":"11791390208","pt":1723048410588,"mc":[{"id":"1.231540926","rc":[{"batb":[[0,1.28,16.72],[1,1.27,31.98],[2,1.25,100]],"ltp":3.0,"tv":160.69,"id":71847983}]}]}
{"op":"mcm","clk":"11791396878","pt":1723048470658,"mc":[{"id":"1.231540926","rc":[{"batb":[[0,1.29,14],[1,1.28,16.72],[2,1.27,31.98]],"ltp":3.0,"tv":160.69,"id":71847983}]}]}
{"op":"mcm","clk":"11791397094","pt":1723048472937,"mc":[{"id":"1.231540926","rc":[{"batb":[[0,1.29,10]],"ltp":3.0,"tv":160.69,"id":71847983}]}]}
{"op":"mcm","clk":"11791397195","pt":1723048474073,"mc":[{"id":"1.231540926","rc":[{"batb":[[0,1.28,16.72],[1,1.27,31.98],[2,1.25,100]],"ltp":3.0,"tv":160.69,"id":71847983}]}]}
{"op":"mcm","clk":"11791398852","pt":1723048490366,"mc":[{"id":"1.231540926","rc":[{"batb":[[0,1.29,14],[1,1.28,16.72],[2,1.27,31.98]],"ltp":3.0,"tv":160.69,"id":71847983}]}]}
{"op":"mcm","clk":"11791399080","pt":1723048492559,"mc":[{"id":"1.231540926","rc":[{"batb":[[0,1.29,10]],"ltp":3.0,"tv":160.69,"id":71847983}]}]}
{"op":"mcm","clk":"11791399201","pt":1723048493800,"mc":[{"id":"1.231540926","rc":[{"batb":[[0,1.28,16.72],[1,1.27,31.98],[2,1.25,100]],"ltp":3.0,"tv":160.69,"id":71847983}]}]}
{"op":"mcm","clk":"11791412236","pt":1723048620188,"mc":[{"id":"1.231540926","rc":[{"batb":[[0,1.29,14],[1,1.28,16.72],[2,1.27,31.98]],"ltp":3.0,"tv":160.69,"id":71847983}]}]}
{"op":"mcm","clk":"11791412478","pt":1723048622703,"mc":[{"id":"1.231540926","rc":[{"batb":[[0,1.29,10]],"ltp":3.0,"tv":160.69,"id":71847983}]}]}
{"op":"mcm","clk":"11791412554","pt":1723048623477,"mc":[{"id":"1.231540926","rc":[{"batb":[[0,1.28,16.72],[1,1.27,31.98],[2,1.25,100]],"ltp":3.0,"tv":160.69,"id":71847983}]}]}
{"op":"mcm","clk":"11791412957","pt":1723048627175,"mc":[{"id":"1.231540926","rc":[{"batb":[[0,1.29,14],[1,1.28,16.72],[2,1.27,31.98]],"ltp":3.0,"tv":160.69,"id":71847983}]}]}
{"op":"mcm","clk":"11791413211","pt":1723048629678,"mc":[{"id":"1.231540926","rc":[{"batb":[[0,1.29,10]],"ltp":3.0,"tv":160.69,"id":71847983}]}]}
{"op":"mcm","clk":"11791413314","pt":1723048630605,"mc":[{"id":"1.231540926","rc":[{"batb":[[0,1.28,16.72],[1,1.27,31.98],[2,1.25,100]],"ltp":3.0,"tv":160.69,"id":71847983}]}]}
{"op":"mcm","clk":"11791417152","pt":1723048666899,"mc":[{"id":"1.231540926","rc":[{"batb":[[0,1.29,14],[1,1.28,16.72],[2,1.27,31.98]],"ltp":3.0,"tv":160.69,"id":71847983}]}]}
{"op":"mcm","clk":"11791417429","pt":1723048669344,"mc":[{"id":"1.231540926","rc":[{"batb":[[0,1.29,10]],"ltp":3.0,"tv":160.69,"id":71847983}]}]}
{"op":"mcm","clk":"11791417542","pt":1723048670328,"mc":[{"id":"1.231540926","rc":[{"batb":[[0,1.28,16.72],[1,1.27,31.98],[2,1.25,100]],"ltp":3.0,"tv":160.69,"id":71847983}]}]}
{"op":"mcm","clk":"11791418584","pt":1723048679977,"mc":[{"id":"1.231540926","rc":[{"batb":[[0,1.29,14],[1,1.28,16.72],[2,1.27,31.98]],"ltp":3.0,"tv":160.69,"id":71847983}]}]}
{"op":"mcm","clk":"11791418834","pt":1723048682151,"mc":[{"id":"1.231540926","rc":[{"batb":[[0,1.29,10]],"ltp":3.0,"tv":160.69,"id":71847983}]}]}
{"op":"mcm","clk":"11791418939","pt":1723048683159,"mc":[{"id":"1.231540926","rc":[{"batb":[[0,1.28,16.72],[1,1.27,31.98],[2,1.25,100]],"ltp":3.0,"tv":160.69,"id":71847983}]}]}
{"op":"mcm","clk":"11791420795","pt":1723048699994,"mc":[{"id":"1.231540926","rc":[{"batb":[[0,1.29,14],[1,1.28,16.72],[2,1.27,31.98]],"ltp":3.0,"tv":160.69,"id":71847983}]}]}
{"op":"mcm","clk":"11791421039","pt":1723048702300,"mc":[{"id":"1.231540926","rc":[{"batb":[[0,1.29,10]],"ltp":3.0,"tv":160.69,"id":71847983}]}]}
{"op":"mcm","clk":"11791421161","pt":1723048703399,"mc":[{"id":"1.231540926","rc":[{"batb":[[0,1.28,16.72],[1,1.27,31.98],[2,1.25,100]],"ltp":3.0,"tv":160.69,"id":71847983}]}]}
{"op":"mcm","clk":"11791421991","pt":1723048710583,"mc":[{"id":"1.231540926","rc":[{"batb":[[0,1.29,14],[1,1.28,16.72],[2,1.27,31.98]],"ltp":3.0,"tv":160.69,"id":71847983}]}]}
{"op":"mcm","clk":"11791422251","pt":1723048712894,"mc":[{"id":"1.231540926","rc":[{"batb":[[0,1.29,10]],"ltp":3.0,"tv":160.69,"id":71847983}]}]}
{"op":"mcm","clk":"11791422379","pt":1723048713996,"mc":[{"id":"1.231540926","rc":[{"batb":[[0,1.28,16.72],[1,1.27,31.98],[2,1.25,100]],"ltp":3.0,"tv":160.69,"id":71847983}]}]}
{"op":"mcm","clk":"11791425167","pt":1723048740510,"mc":[{"id":"1.231540926","rc":[{"batb":[[0,1.29,14],[1,1.28,16.72],[2,1.27,31.98]],"ltp":3.0,"tv":160.69,"id":71847983}]}]}
{"op":"mcm","clk":"11791425432","pt":1723048742827,"mc":[{"id":"1.231540926","rc":[{"batb":[[0,1.29,10]],"ltp":3.0,"tv":160.69,"id":71847983}]}]}
{"op":"mcm","clk":"11791425542","pt":1723048743920,"mc":[{"id":"1.231540926","rc":[{"batb":[[0,1.28,16.72],[1,1.27,31.98],[2,1.25,100]],"ltp":3.0,"tv":160.69,"id":71847983}]}]}
{"op":"mcm","clk":"11791427573","pt":1723048763655,"mc":[{"id":"1.231540926","rc":[{"batb":[[0,1.29,14],[1,1.28,16.72],[2,1.27,31.98]],"ltp":3.0,"tv":160.69,"id":71847983}]}]}
{"op":"mcm","clk":"11791427760","pt":1723048766143,"mc":[{"id":"1.231540926","rc":[{"batb":[[0,1.29,10]],"ltp":3.0,"tv":160.69,"id":71847983}]}]}
{"op":"mcm","clk":"11791427824","pt":1723048767079,"mc":[{"id":"1.231540926","rc":[{"batb":[[0,1.28,16.72],[1,1.27,31.98],[2,1.25,100]],"ltp":3.0,"tv":160.69,"id":71847983}]}]}
{"op":"mcm","clk":"11791427930","pt":1723048768469,"mc":[{"id":"1.231540926","rc":[{"batb":[[0,1.29,4],[1,1.28,16.72],[2,1.27,31.98]],"ltp":3.0,"tv":160.69,"id":71847983}]}]}
{"op":"mcm","clk":"11791428138","pt":1723048770969,"mc":[{"id":"1.231540926","rc":[{"batb":[[0,1.29,10]],"ltp":3.0,"tv":160.69,"id":71847983}]}]}
{"op":"mcm","clk":"11791428422","pt":1723048774466,"mc":[{"id":"1.231540926","rc":[{"batb":[[0,1.29,4]],"ltp":3.0,"tv":160.69,"id":71847983}]}]}
{"op":"mcm","clk":"11791428652","pt":1723048776865,"mc":[{"id":"1.231540926","rc":[{"batb":[[0,1.29,10]],"ltp":3.0,"tv":160.69,"id":71847983}]}]}
{"op":"mcm","clk":"11791428987","pt":1723048780390,"mc":[{"id":"1.231540926","rc":[{"batb":[[0,1.29,4]],"ltp":3.0,"tv":160.69,"id":71847983}]}]}
{"op":"mcm","clk":"11791429221","pt":1723048782888,"mc":[{"id":"1.231540926","rc":[{"batb":[[0,1.29,10]],"ltp":3.0,"tv":160.69,"id":71847983}]}]}
{"op":"mcm","clk":"11791429511","pt":1723048786075,"mc":[{"id":"1.231540926","rc":[{"batb":[[0,1.28,16.72],[1,1.27,31.98],[2,1.25,100]],"ltp":3.0,"tv":160.69,"id":71847983}]}]}
{"op":"mcm","clk":"11791429522","pt":1723048786181,"mc":[{"id":"1.231540926","rc":[{"batb":[[0,1.29,4],[1,1.28,16.72],[2,1.27,31.98]],"ltp":3.0,"tv":160.69,"id":71847983}]}]}
{"op":"mcm","clk":"11791429781","pt":1723048788786,"mc":[{"id":"1.231540926","rc":[{"batb":[[0,1.29,10]],"ltp":3.0,"tv":160.69,"id":71847983}]}]}
{"op":"mcm","clk":"11791430066","pt":1723048792004,"mc":[{"id":"1.231540926","rc":[{"batb":[[0,1.28,16.72],[1,1.27,31.98],[2,1.25,100]],"ltp":3.0,"tv":160.69,"id":71847983}]}]}
{"op":"mcm","clk":"11791430089","pt":1723048792178,"mc":[{"id":"1.231540926","rc":[{"batb":[[0,1.29,4],[1,1.28,16.72],[2,1.27,31.98]],"ltp":3.0,"tv":160.69,"id":71847983}]}]}
{"op":"mcm","clk":"11791430294","pt":1723048794603,"mc":[{"id":"1.231540926","rc":[{"batb":[[0,1.29,10]],"ltp":3.0,"tv":160.69,"id":71847983}]}]}
{"op":"mcm","clk":"11791430636","pt":1723048798101,"mc":[{"id":"1.231540926","rc":[{"batb":[[0,1.29,4]],"ltp":3.0,"tv":160.69,"id":71847983}]}]}
{"op":"mcm","clk":"11791430832","pt":1723048800493,"mc":[{"id":"1.231540926","rc":[{"batb":[[0,1.29,10]],"ltp":3.0,"tv":160.69,"id":71847983}]}]}
{"op":"mcm","clk":"11791431214","pt":1723048804013,"mc":[{"id":"1.231540926","rc":[{"batb":[[0,1.29,4]],"ltp":3.0,"tv":160.69,"id":71847983}]}]}
{"op":"mcm","clk":"11791431434","pt":1723048806524,"mc":[{"id":"1.231540926","rc":[{"batb":[[0,1.29,10]],"ltp":3.0,"tv":160.69,"id":71847983}]}]}
{"op":"mcm","clk":"11791431761","pt":1723048809925,"mc":[{"id":"1.231540926","rc":[{"batb":[[0,1.29,4]],"ltp":3.0,"tv":160.69,"id":71847983}]}]}
{"op":"mcm","clk":"11791431969","pt":1723048812117,"mc":[{"id":"1.231540926","rc":[{"batb":[[0,1.3,10],[1,1.29,4],[2,1.28,16.72]],"ltp":3.0,"tv":160.69,"id":71847983}]}]}
{"op":"mcm","clk":"11791431986","pt":1723048812322,"mc":[{"id":"1.231540926","rc":[{"batb":[[1,1.28,16.72],[2,1.27,31.98]],"ltp":3.0,"tv":160.69,"id":71847983}]}]}
{"op":"mcm","clk":"11791432256","pt":1723048815517,"mc":[{"id":"1.231540926","rc":[{"batb":[[0,1.29,4]],"ltp":3.0,"tv":160.69,"id":71847983}]}]}
{"op":"mcm","clk":"11791432467","pt":1723048817919,"mc":[{"id":"1.231540926","rc":[{"batb":[[0,1.29,10]],"ltp":3.0,"tv":160.69,"id":71847983}]}]}
{"op":"mcm","clk":"11791432784","pt":1723048821423,"mc":[{"id":"1.231540926","rc":[{"batb":[[0,1.29,4]],"ltp":3.0,"tv":160.69,"id":71847983}]}]}
{"op":"mcm","clk":"11791432996","pt":1723048823821,"mc":[{"id":"1.231540926","rc":[{"batb":[[0,1.29,10]],"ltp":3.0,"tv":160.69,"id":71847983}]}]}
{"op":"mcm","clk":"11791433301","pt":1723048827145,"mc":[{"id":"1.231540926","rc":[{"batb":[[0,1.29,4]],"ltp":3.0,"tv":160.69,"id":71847983}]}]}
{"op":"mcm","clk":"11791433548","pt":1723048829542,"mc":[{"id":"1.231540926","rc":[{"batb":[[0,1.29,10]],"ltp":3.0,"tv":160.69,"id":71847983}]}]}
{"op":"mcm","clk":"11791433892","pt":1723048832966,"mc":[{"id":"1.231540926","rc":[{"batb":[[0,1.29,4]],"ltp":3.0,"tv":160.69,"id":71847983}]}]}
{"op":"mcm","clk":"11791434128","pt":1723048835465,"mc":[{"id":"1.231540926","rc":[{"batb":[[0,1.29,10]],"ltp":3.0,"tv":160.69,"id":71847983}]}]}
{"op":"mcm","clk":"11791434429","pt":1723048838857,"mc":[{"id":"1.231540926","rc":[{"batb":[[0,1.29,4]],"ltp":3.0,"tv":160.69,"id":71847983}]}]}
{"op":"mcm","clk":"11791434676","pt":1723048841355,"mc":[{"id":"1.231540926","rc":[{"batb":[[0,1.29,10]],"ltp":3.0,"tv":160.69,"id":71847983}]}]}
{"op":"mcm","clk":"11791434982","pt":1723048844784,"mc":[{"id":"1.231540926","rc":[{"batb":[[0,1.29,4]],"ltp":3.0,"tv":160.69,"id":71847983}]}]}
{"op":"mcm","clk":"11791435242","pt":1723048847073,"mc":[{"id":"1.231540926","rc":[{"batb":[[0,1.28,16.72],[1,1.27,31.98],[2,1.25,100]],"ltp":3.0,"tv":160.69,"id":71847983}]}]}
{"op":"mcm","clk":"11791435255","pt":1723048847173,"mc":[{"id":"1.231540926","rc":[{"batb":[[0,1.29,10],[1,1.28,16.72],[2,1.27,31.98]],"ltp":3.0,"tv":160.69,"id":71847983}]}]}
{"op":"mcm","clk":"11791435480","pt":1723048849671,"mc":[{"id":"1.231540926","rc":[{"batb":[[0,1.3,4],[1,1.29,10],[2,1.28,16.72]],"ltp":3.0,"tv":160.69,"id":71847983}]}]}
{"op":"mcm","clk":"11791435550","pt":1723048850469,"mc":[{"id":"1.231540926","rc":[{"batb":[[1,1.28,16.72],[2,1.27,31.98]],"ltp":3.0,"tv":160.69,"id":71847983}]}]}
{"op":"mcm","clk":"11791435689","pt":1723048851874,"mc":[{"id":"1.231540926","rc":[{"batb":[[0,1.28,16.72],[1,1.27,31.98],[2,1.25,100]],"ltp":3.0,"tv":160.69,"id":71847983}]}]}
{"op":"mcm","clk":"11791438843","pt":1723048886629,"mc":[{"id":"1.231540926","rc":[{"batb":[[0,1.29,14],[1,1.28,16.72],[2,1.27,31.98]],"ltp":3.0,"tv":160.69,"id":71847983}]}]}
{"op":"mcm","clk":"11791439061","pt":1723048889132,"mc":[{"id":"1.231540926","rc":[{"batb":[[0,1.29,10]],"ltp":3.0,"tv":160.69,"id":71847983}]}]}
{"op":"mcm","clk":"11791439128","pt":1723048890017,"mc":[{"id":"1.231540926","rc":[{"batb":[[0,1.28,16.72],[1,1.27,31.98],[2,1.25,100]],"ltp":3.0,"tv":160.69,"id":71847983}]}]}
{"op":"mcm","clk":"11791439249","pt":1723048891519,"mc":[{"id":"1.231540926","rc":[{"batb":[[0,1.29,4],[1,1.28,16.72],[2,1.27,31.98]],"ltp":3.0,"tv":160.69,"id":71847983}]}]}
{"op":"mcm","clk":"11791439464","pt":1723048893912,"mc":[{"id":"1.231540926","rc":[{"batb":[[0,1.28,16.72],[1,1.27,31.98],[2,1.25,100]],"ltp":3.0,"tv":160.69,"id":71847983}]}]}
{"op":"mcm","clk":"11791439510","pt":1723048894427,"mc":[{"id":"1.231540926","rc":[{"batb":[[0,1.29,10],[1,1.28,16.72],[2,1.27,31.98]],"ltp":3.0,"tv":160.69,"id":71847983}]}]}
{"op":"mcm","clk":"11791439785","pt":1723048898120,"mc":[{"id":"1.231540926","rc":[{"batb":[[0,1.29,4]],"ltp":3.0,"tv":160.69,"id":71847983}]}]}
{"op":"mcm","clk":"11791439994","pt":1723048900852,"mc":[{"id":"1.231540926","rc":[{"batb":[[0,1.29,10]],"ltp":3.0,"tv":160.69,"id":71847983}]}]}
{"op":"mcm","clk":"11791440260","pt":1723048904123,"mc":[{"id":"1.231540926","rc":[{"batb":[[0,1.28,16.72],[1,1.27,31.98],[2,1.25,100]],"ltp":3.0,"tv":160.69,"id":71847983}]}]}
{"op":"mcm","clk":"11791440272","pt":1723048904235,"mc":[{"id":"1.231540926","rc":[{"batb":[[0,1.29,4],[1,1.28,16.72],[2,1.27,31.98]],"ltp":3.0,"tv":160.69,"id":71847983}]}]}
{"op":"mcm","clk":"11791440455","pt":1723048906449,"mc":[{"id":"1.231540926","rc":[{"batb":[[0,1.29,10]],"ltp":3.0,"tv":160.69,"id":71847983}]}]}
{"op":"mcm","clk":"11791440764","pt":1723048909736,"mc":[{"id":"1.231540926","rc":[{"batb":[[0,1.29,4]],"ltp":3.0,"tv":160.69,"id":71847983}]}]}
{"op":"mcm","clk":"11791440912","pt":1723048912061,"mc":[{"id":"1.231540926","rc":[{"batb":[[0,1.28,16.72],[1,1.27,31.98],[2,1.25,100]],"ltp":3.0,"tv":160.69,"id":71847983}]}]}
{"op":"mcm","clk":"11791440919","pt":1723048912166,"mc":[{"id":"1.231540926","rc":[{"batb":[[0,1.29,10],[1,1.28,16.72],[2,1.27,31.98]],"ltp":3.0,"tv":160.69,"id":71847983}]}]}
{"op":"mcm","clk":"11791441143","pt":1723048915646,"mc":[{"id":"1.231540926","rc":[{"batb":[[0,1.29,4]],"ltp":3.0,"tv":160.69,"id":71847983}]}]}
{"op":"mcm","clk":"11791441322","pt":1723048918144,"mc":[{"id":"1.231540926","rc":[{"batb":[[0,1.29,10]],"ltp":3.0,"tv":160.69,"id":71847983}]}]}
{"op":"mcm","clk":"11791441618","pt":1723048921355,"mc":[{"id":"1.231540926","rc":[{"batb":[[0,1.29,4]],"ltp":3.0,"tv":160.69,"id":71847983}]}]}
{"op":"mcm","clk":"11791441815","pt":1723048923750,"mc":[{"id":"1.231540926","rc":[{"batb":[[0,1.29,10]],"ltp":3.0,"tv":160.69,"id":71847983}]}]}
{"op":"mcm","clk":"11791442155","pt":1723048927561,"mc":[{"id":"1.231540926","rc":[{"batb":[[0,1.29,4]],"ltp":3.0,"tv":160.69,"id":71847983}]}]}
{"op":"mcm","clk":"11791442341","pt":1723048929859,"mc":[{"id":"1.231540926","rc":[{"batb":[[0,1.28,16.72],[1,1.27,31.98],[2,1.25,100]],"ltp":3.0,"tv":160.69,"id":71847983}]}]}
{"op":"mcm","clk":"11791442371","pt":1723048930265,"mc":[{"id":"1.231540926","rc":[{"batb":[[0,1.29,10],[1,1.28,16.72],[2,1.27,31.98]],"ltp":3.0,"tv":160.69,"id":71847983}]}]}
{"op":"mcm","clk":"11791442690","pt":1723048933859,"mc":[{"id":"1.231540926","rc":[{"batb":[[0,1.29,4]],"ltp":3.0,"tv":160.69,"id":71847983}]}]}
{"op":"mcm","clk":"11791442893","pt":1723048936299,"mc":[{"id":"1.231540926","rc":[{"batb":[[0,1.29,10]],"ltp":3.0,"tv":160.69,"id":71847983}]}]}
{"op":"mcm","clk":"11791443162","pt":1723048939671,"mc":[{"id":"1.231540926","rc":[{"batb":[[0,1.29,4]],"ltp":3.0,"tv":160.69,"id":71847983}]}]}
{"op":"mcm","clk":"11791443352","pt":1723048942010,"mc":[{"id":"1.231540926","rc":[{"batb":[[0,1.28,16.72],[1,1.27,31.98],[2,1.25,100]],"ltp":3.0,"tv":160.69,"id":71847983}]}]}
{"op":"mcm","clk":"11791443377","pt":1723048942171,"mc":[{"id":"1.231540926","rc":[{"batb":[[0,1.29,10],[1,1.28,16.72],[2,1.27,31.98]],"ltp":3.0,"tv":160.69,"id":71847983}]}]}
{"op":"mcm","clk":"11791443701","pt":1723048945900,"mc":[{"id":"1.231540926","rc":[{"batb":[[0,1.29,4]],"ltp":3.0,"tv":160.69,"id":71847983}]}]}
{"op":"mcm","clk":"11791443897","pt":1723048948091,"mc":[{"id":"1.231540926","rc":[{"batb":[[0,1.28,16.72],[1,1.27,31.98],[2,1.25,100]],"ltp":3.0,"tv":160.69,"id":71847983}]}]}
{"op":"mcm","clk":"11791443914","pt":1723048948287,"mc":[{"id":"1.231540926","rc":[{"batb":[[0,1.29,10],[1,1.28,16.72],[2,1.27,31.98]],"ltp":3.0,"tv":160.69,"id":71847983}]}]}
{"op":"mcm","clk":"11791444210","pt":1723048951611,"mc":[{"id":"1.231540926","rc":[{"batb":[[0,1.29,4]],"ltp":3.0,"tv":160.69,"id":71847983}]}]}
{"op":"mcm","clk":"11791444425","pt":1723048953909,"mc":[{"id":"1.231540926","rc":[{"batb":[[0,1.29,10]],"ltp":3.0,"tv":160.69,"id":71847983}]}]}
{"op":"mcm","clk":"11791444700","pt":1723048957104,"mc":[{"id":"1.231540926","rc":[{"batb":[[0,1.3,4]],"ltp":3.0,"tv":160.69,"id":71847983}]}]}
{"op":"mcm","clk":"11791444886","pt":1723048959298,"mc":[{"id":"1.231540926","rc":[{"batb":[[0,1.29,10]],"ltp":3.0,"tv":160.69,"id":71847983}]}]}
{"op":"mcm","clk":"11791445173","pt":1723048962811,"mc":[{"id":"1.231540926","rc":[{"batb":[[0,1.29,4]],"ltp":3.0,"tv":160.69,"id":71847983}]}]}
{"op":"mcm","clk":"11791445393","pt":1723048965004,"mc":[{"id":"1.231540926","rc":[{"batb":[[0,1.28,16.72],[1,1.27,31.98],[2,1.25,100]],"ltp":3.0,"tv":160.69,"id":71847983}]}]}
{"op":"mcm","clk":"11791445411","pt":1723048965210,"mc":[{"id":"1.231540926","rc":[{"batb":[[0,1.29,10],[1,1.28,16.72],[2,1.27,31.98]],"ltp":3.0,"tv":160.69,"id":71847983}]}]}
{"op":"mcm","clk":"11791445760","pt":1723048968743,"mc":[{"id":"1.231540926","rc":[{"batb":[[0,1.29,4]],"ltp":3.0,"tv":160.69,"id":71847983}]}]}
{"op":"mcm","clk":"11791445936","pt":1723048971035,"mc":[{"id":"1.231540926","rc":[{"batb":[[0,1.28,16.72],[1,1.27,31.98],[2,1.25,100]],"ltp":3.0,"tv":160.69,"id":71847983}]}]}
{"op":"mcm","clk":"11791445960","pt":1723048971241,"mc":[{"id":"1.231540926","rc":[{"batb":[[0,1.29,10],[1,1.28,16.72],[2,1.27,31.98]],"ltp":3.0,"tv":160.69,"id":71847983}]}]}
{"op":"mcm","clk":"11791446284","pt":1723048974745,"mc":[{"id":"1.231540926","rc":[{"batb":[[0,1.29,4]],"ltp":3.0,"tv":160.69,"id":71847983}]}]}
{"op":"mcm","clk":"11791446509","pt":1723048977111,"mc":[{"id":"1.231540926","rc":[{"batb":[[0,1.28,16.72],[1,1.27,31.98],[2,1.25,100]],"ltp":3.0,"tv":160.69,"id":71847983}]}]}
{"op":"mcm","clk":"11791446515","pt":1723048977212,"mc":[{"id":"1.231540926","rc":[{"batb":[[0,1.29,10],[1,1.28,16.72],[2,1.27,31.98]],"ltp":3.0,"tv":160.69,"id":71847983}]}]}
{"op":"mcm","clk":"11791446728","pt":1723048979828,"mc":[{"id":"1.231540926","rc":[{"batb":[[0,1.3,4],[1,1.29,10],[2,1.28,16.72]],"ltp":3.0,"tv":160.69,"id":71847983}]}]}
{"op":"mcm","clk":"11791446774","pt":1723048980439,"mc":[{"id":"1.231540926","rc":[{"batb":[[1,1.28,16.72],[2,1.27,31.98]],"ltp":3.0,"tv":160.69,"id":71847983}]}]}
{"op":"mcm","clk":"11791446916","pt":1723048982230,"mc":[{"id":"1.231540926","rc":[{"batb":[[0,1.28,16.72],[1,1.27,31.98],[2,1.25,100]],"ltp":3.0,"tv":160.69,"id":71847983}]}]}
{"op":"mcm","clk":"11791447300","pt":1723048987260,"mc":[{"id":"1.231540926","rc":[{"batb":[[0,1.29,14],[1,1.28,16.72],[2,1.27,31.98]],"ltp":3.0,"tv":160.69,"id":71847983}]}]}
{"op":"mcm","clk":"11791447492","pt":1723048989637,"mc":[{"id":"1.231540926","rc":[{"batb":[[0,1.29,10]],"ltp":3.0,"tv":160.69,"id":71847983}]}]}
{"op":"mcm","clk":"11791447552","pt":1723048990429,"mc":[{"id":"1.231540926","rc":[{"batb":[[0,1.28,16.72],[1,1.27,31.98],[2,1.25,100]],"ltp":3.0,"tv":160.69,"id":71847983}]}]}
{"op":"mcm","clk":"11791448468","pt":1723049002845,"mc":[{"id":"1.231540926","rc":[{"batb":[[0,1.29,14],[1,1.28,16.72]],"ltp":3.0,"tv":160.69,"id":71847983},{"batb":[[1,1.26,10],[2,1.25,100]],"ltp":1.5,"tv":158.62,"id":19144236}]}]}
{"op":"mcm","clk":"11791448632","pt":1723049005083,"mc":[{"id":"1.231540926","rc":[{"batb":[[0,1.29,10]],"ltp":3.0,"tv":160.69,"id":71847983}]}]}
{"op":"mcm","clk":"11791448723","pt":1723049006042,"mc":[{"id":"1.231540926","rc":[{"batb":[[0,1.28,16.72],[1,1.25,100],[2,1.19,20]],"ltp":3.0,"tv":160.69,"id":71847983}]}]}
{"op":"mcm","clk":"11791448998","pt":1723049009472,"mc":[{"id":"1.231540926","rc":[{"batb":[[0,1.29,14],[1,1.28,16.72],[2,1.25,100]],"ltp":3.0,"tv":160.69,"id":71847983}]}]}
{"op":"mcm","clk":"11791449185","pt":1723049011752,"mc":[{"id":"1.231540926","rc":[{"batb":[[0,1.29,10]],"ltp":3.0,"tv":160.69,"id":71847983}]}]}
{"op":"mcm","clk":"11791449260","pt":1723049012764,"mc":[{"id":"1.231540926","rc":[{"batb":[[0,1.28,16.72],[1,1.25,100],[2,1.19,20]],"ltp":3.0,"tv":160.69,"id":71847983}]}]}
{"op":"mcm","clk":"11791449738","pt":1723049019361,"mc":[{"id":"1.231540926","rc":[{"batb":[[0,1.3,14],[1,1.29,29.78],[2,1.28,16.72]],"ltp":3.0,"tv":160.69,"id":71847983},{"batb":[[0,1.51,16.93],[1,1.28,7.71],[2,1.26,10]],"ltp":1.5,"tv":158.62,"id":19144236}]}]}
{"op":"mcm","clk":"11791449920","pt":1723049021776,"mc":[{"id":"1.231540926","rc":[{"batb":[[0,1.3,10]],"ltp":3.0,"tv":160.69,"id":71847983}]}]}
{"op":"mcm","clk":"11791449988","pt":1723049022660,"mc":[{"id":"1.231540926","rc":[{"batb":[[0,1.29,29.78],[1,1.28,16.72],[2,1.25,100]],"ltp":3.0,"tv":160.69,"id":71847983}]}]}
{"op":"mcm","clk":"11791450739","pt":1723049033176,"mc":[{"id":"1.231540926","rc":[{"batb":[[0,1.3,14],[1,1.29,29.78],[2,1.28,16.72]],"ltp":3.0,"tv":160.69,"id":71847983}]}]}
{"op":"mcm","clk":"11791450905","pt":1723049035501,"mc":[{"id":"1.231540926","rc":[{"batb":[[0,1.3,10]],"ltp":3.0,"tv":160.69,"id":71847983}]}]}
{"op":"mcm","clk":"11791451009","pt":1723049036711,"mc":[{"id":"1.231540926","rc":[{"batb":[[0,1.29,29.78],[1,1.28,16.72],[2,1.25,100]],"ltp":3.0,"tv":160.69,"id":71847983}]}]}
{"op":"mcm","clk":"11791452124","pt":1723049049327,"mc":[{"id":"1.231540926","rc":[{"batb":[[0,1.3,14],[1,1.29,29.78],[2,1.28,16.72]],"ltp":3.0,"tv":160.69,"id":71847983}]}]}
{"op":"mcm","clk":"11791452303","pt":1723049051595,"mc":[{"id":"1.231540926","rc":[{"batb":[[0,1.3,10]],"ltp":3.0,"tv":160.69,"id":71847983}]}]}
{"op":"mcm","clk":"11791452368","pt":1723049052624,"mc":[{"id":"1.231540926","rc":[{"batb":[[0,1.29,29.78],[1,1.28,16.72],[2,1.25,100]],"ltp":3.0,"tv":160.69,"id":71847983}]}]}
{"op":"mcm","clk":"11791459921","pt":1723049142982,"mc":[{"id":"1.231540926","rc":[{"batb":[[0,1.3,14],[1,1.29,29.78],[2,1.28,16.72]],"ltp":3.0,"tv":160.69,"id":71847983}]}]}
{"op":"mcm","clk":"11791460146","pt":1723049145415,"mc":[{"id":"1.231540926","rc":[{"batb":[[0,1.3,10]],"ltp":3.0,"tv":160.69,"id":71847983}]}]}
{"op":"mcm","clk":"11791460225","pt":1723049146198,"mc":[{"id":"1.231540926","rc":[{"batb":[[0,1.29,29.78],[1,1.28,16.72],[2,1.25,100]],"ltp":3.0,"tv":160.69,"id":71847983}]}]}
{"op":"mcm","clk":"11791460945","pt":1723049153901,"mc":[{"id":"1.231540926","rc":[{"batb":[[0,1.3,14],[1,1.29,29.78],[2,1.28,16.72]],"ltp":3.0,"tv":160.69,"id":71847983}]}]}
{"op":"mcm","clk":"11791461116","pt":1723049156102,"mc":[{"id":"1.231540926","rc":[{"batb":[[0,1.3,10]],"ltp":3.0,"tv":160.69,"id":71847983}]}]}
{"op":"mcm","clk":"11791461210","pt":1723049157288,"mc":[{"id":"1.231540926","rc":[{"batb":[[0,1.29,29.78],[1,1.28,16.72],[2,1.25,100]],"ltp":3.0,"tv":160.69,"id":71847983}]}]}
{"op":"mcm","clk":"11791462327","pt":1723049170105,"mc":[{"id":"1.231540926","rc":[{"batb":[[0,1.3,10],[1,1.29,29.78],[2,1.28,16.72]],"ltp":3.0,"tv":160.69,"id":71847983}]}]}
{"op":"mcm","clk":"11791462342","pt":1723049170209,"mc":[{"id":"1.231540926","rc":[{"batb":[[0,1.3,14]],"ltp":3.0,"tv":160.69,"id":71847983}]}]}
{"op":"mcm","clk":"11791462565","pt":1723049172916,"mc":[{"id":"1.231540926","rc":[{"batb":[[0,1.3,10]],"ltp":3.0,"tv":160.69,"id":71847983}]}]}
{"op":"mcm","clk":"11791462595","pt":1723049173434,"mc":[{"id":"1.231540926","rc":[{"batb":[[0,1.29,29.78],[1,1.28,16.72],[2,1.25,100]],"ltp":3.0,"tv":160.69,"id":71847983}]}]}
{"op":"mcm","clk":"11791496051","pt":1723049518665,"mc":[{"id":"1.231540926","rc":[{"batb":[[0,1.3,6.72],[1,1.29,29.78],[2,1.28,10]],"ltp":3.0,"tv":160.69,"id":71847983},{"batb":[[1,1.26,17.71],[2,1.25,100]],"ltp":1.5,"tv":158.62,"id":19144236}]}]}
{"op":"mcm","clk":"11791549718","pt":1723050028144,"mc":[{"id":"1.231540926","rc":[{"trd":[[1.35,2.11],[1.5,158.67]],"batb":[[0,1.31,14],[1,1.3,6.73],[2,1.29,29.79]],"batl":[[0,3,1.02]],"ltp":3.0,"tv":160.8,"id":71847983},{"trd":[[1.5,158.74]],"batb":[[0,1.51,16.94],[1,1.26,17.72]],"ltp":1.5,"tv":158.73,"id":19144236}],"tv":319.54}]}
{"op":"mcm","clk":"11791550019","pt":1723050030549,"mc":[{"id":"1.231540926","rc":[{"batb":[[0,1.31,10]],"ltp":3.0,"tv":160.8,"id":71847983}]}]}
{"op":"mcm","clk":"11791550141","pt":1723050031433,"mc":[{"id":"1.231540926","rc":[{"batb":[[0,1.3,6.73],[1,1.29,29.79],[2,1.28,10]],"ltp":3.0,"tv":160.8,"id":71847983}]}]}
{"op":"mcm","clk":"11791553540","pt":1723050059345,"mc":[{"id":"1.231540926","rc":[{"batb":[[0,1.31,14],[1,1.3,6.73],[2,1.29,29.79]],"ltp":3.0,"tv":160.8,"id":71847983}]}]}
{"op":"mcm","clk":"11791553821","pt":1723050061552,"mc":[{"id":"1.231540926","rc":[{"batb":[[0,1.31,10]],"ltp":3.0,"tv":160.8,"id":71847983}]}]}
{"op":"mcm","clk":"11791553963","pt":1723050062650,"mc":[{"id":"1.231540926","rc":[{"batb":[[0,1.3,6.73],[1,1.29,29.79],[2,1.28,10]],"ltp":3.0,"tv":160.8,"id":71847983}]}]}
{"op":"mcm","clk":"11791554199","pt":1723050064476,"mc":[{"id":"1.231540926","rc":[{"batb":[[0,1.31,4],[1,1.3,6.73],[2,1.29,29.79]],"ltp":3.0,"tv":160.8,"id":71847983}]}]}
{"op":"mcm","clk":"11791554489","pt":1723050066884,"mc":[{"id":"1.231540926","rc":[{"batb":[[0,1.31,10]],"ltp":3.0,"tv":160.8,"id":71847983}]}]}
{"op":"mcm","clk":"11791554895","pt":1723050070073,"mc":[{"id":"1.231540926","rc":[{"batb":[[0,1.3,6.73],[1,1.29,29.79],[2,1.28,10]],"ltp":3.0,"tv":160.8,"id":71847983}]}]}
{"op":"mcm","clk":"11791554909","pt":1723050070173,"mc":[{"id":"1.231540926","rc":[{"batb":[[0,1.31,4],[1,1.3,6.73],[2,1.29,29.79]],"ltp":3.0,"tv":160.8,"id":71847983}]}]}
{"op":"mcm","clk":"11791555219","pt":1723050072678,"mc":[{"id":"1.231540926","rc":[{"batb":[[0,1.31,10]],"ltp":3.0,"tv":160.8,"id":71847983}]}]}
{"op":"mcm","clk":"11791555618","pt":1723050075870,"mc":[{"id":"1.231540926","rc":[{"batb":[[0,1.3,6.73],[1,1.29,29.79],[2,1.28,10]],"ltp":3.0,"tv":160.8,"id":71847983}]}]}
{"op":"mcm","clk":"11791555656","pt":1723050076175,"mc":[{"id":"1.231540926","rc":[{"batb":[[0,1.31,4],[1,1.3,6.73],[2,1.29,29.79]],"ltp":3.0,"tv":160.8,"id":71847983}]}]}
{"op":"mcm","clk":"11791555961","pt":1723050078592,"mc":[{"id":"1.231540926","rc":[{"batb":[[0,1.31,10]],"ltp":3.0,"tv":160.8,"id":71847983}]}]}
{"op":"mcm","clk":"11791556404","pt":1723050081994,"mc":[{"id":"1.231540926","rc":[{"batb":[[0,1.31,4]],"ltp":3.0,"tv":160.8,"id":71847983}]}]}
{"op":"mcm","clk":"11791556705","pt":1723050084606,"mc":[{"id":"1.231540926","rc":[{"batb":[[0,1.31,10]],"ltp":3.0,"tv":160.8,"id":71847983}]}]}
{"op":"mcm","clk":"11791557080","pt":1723050087995,"mc":[{"id":"1.231540926","rc":[{"batb":[[0,1.32,4]],"ltp":3.0,"tv":160.8,"id":71847983}]}]}
{"op":"mcm","clk":"11791557358","pt":1723050090502,"mc":[{"id":"1.231540926","rc":[{"batb":[[0,1.31,10]],"ltp":3.0,"tv":160.8,"id":71847983}]}]}
{"op":"mcm","clk":"11791557779","pt":1723050094098,"mc":[{"id":"1.231540926","rc":[{"batb":[[0,1.31,4]],"ltp":3.0,"tv":160.8,"id":71847983}]}]}
{"op":"mcm","clk":"11791558108","pt":1723050096717,"mc":[{"id":"1.231540926","rc":[{"batb":[[0,1.31,10]],"ltp":3.0,"tv":160.8,"id":71847983}]}]}
{"op":"mcm","clk":"11791558324","pt":1723050098801,"mc":[{"id":"1.231540926","rc":[{"batb":[[0,1.32,4],[1,1.31,10],[2,1.3,6.73]],"ltp":3.0,"tv":160.8,"id":71847983}]}]}
{"op":"mcm","clk":"11791558460","pt":1723050099903,"mc":[{"id":"1.231540926","rc":[{"batb":[[1,1.3,6.73],[2,1.29,29.79]],"ltp":3.0,"tv":160.8,"id":71847983}]}]}
{"op":"mcm","clk":"11791558596","pt":1723050101021,"mc":[{"id":"1.231540926","rc":[{"batb":[[0,1.3,6.73],[1,1.29,29.79],[2,1.28,10]],"ltp":3.0,"tv":160.8,"id":71847983}]}]}
{"op":"mcm","clk":"11791559429","pt":1723050108124,"mc":[{"id":"1.231540926","rc":[{"batb":[[0,1.31,14],[1,1.3,6.73],[2,1.29,29.79]],"ltp":3.0,"tv":160.8,"id":71847983}]}]}
{"op":"mcm","clk":"11791559737","pt":1723050110528,"mc":[{"id":"1.231540926","rc":[{"batb":[[0,1.31,10]],"ltp":3.0,"tv":160.8,"id":71847983}]}]}
{"op":"mcm","clk":"11791559853","pt":1723050111525,"mc":[{"id":"1.231540926","rc":[{"batb":[[0,1.3,6.73],[1,1.29,29.79],[2,1.28,10]],"ltp":3.0,"tv":160.8,"id":71847983}]}]}
{"op":"mcm","clk":"11791560130","pt":1723050113807,"mc":[{"id":"1.231540926","rc":[{"batb":[[0,1.31,14],[1,1.3,6.73],[2,1.29,29.79]],"ltp":3.0,"tv":160.8,"id":71847983}]}]}
{"op":"mcm","clk":"11791560420","pt":1723050116061,"mc":[{"id":"1.231540926","rc":[{"batb":[[0,1.31,10]],"ltp":3.0,"tv":160.8,"id":71847983}]}]}
{"op":"mcm","clk":"11791560573","pt":1723050117031,"mc":[{"id":"1.231540926","rc":[{"batb":[[0,1.3,6.73],[1,1.29,29.79],[2,1.28,10]],"ltp":3.0,"tv":160.8,"id":71847983}]}]}
{"op":"mcm","clk":"11791561333","pt":1723050123619,"mc":[{"id":"1.231540926","rc":[{"batb":[[0,1.31,14],[1,1.3,6.73],[2,1.29,29.79]],"ltp":3.0,"tv":160.8,"id":71847983}]}]}
{"op":"mcm","clk":"11791561651","pt":1723050126009,"mc":[{"id":"1.231540926","rc":[{"batb":[[0,1.31,10]],"ltp":3.0,"tv":160.8,"id":71847983}]}]}
{"op":"mcm","clk":"11791561774","pt":1723050127003,"mc":[{"id":"1.231540926","rc":[{"batb":[[0,1.3,6.73],[1,1.29,29.79],[2,1.28,10]],"ltp":3.0,"tv":160.8,"id":71847983}]}]}
{"op":"mcm","clk":"11791562802","pt":1723050135911,"mc":[{"id":"1.231540926","rc":[{"batb":[[0,1.31,14],[1,1.3,6.73],[2,1.29,29.79]],"ltp":3.0,"tv":160.8,"id":71847983}]}]}
{"op":"mcm","clk":"11791563196","pt":1723050139125,"mc":[{"id":"1.231540926","rc":[{"batb":[[0,1.3,6.73],[1,1.29,29.79],[2,1.28,10]],"ltp":3.0,"tv":160.8,"id":71847983}]}]}
{"op":"mcm","clk":"11791564584","pt":1723050149615,"mc":[{"id":"1.231540926","rc":[{"batb":[[0,1.31,14],[1,1.3,6.73],[2,1.29,29.79]],"ltp":3.0,"tv":160.8,"id":71847983}]}]}
{"op":"mcm","clk":"11791564914","pt":1723050152013,"mc":[{"id":"1.231540926","rc":[{"batb":[[0,1.31,10]],"ltp":3.0,"tv":160.8,"id":71847983}]}]}
{"op":"mcm","clk":"11791565042","pt":1723050153074,"mc":[{"id":"1.231540926","rc":[{"batb":[[0,1.3,6.73],[1,1.29,29.79],[2,1.28,10]],"ltp":3.0,"tv":160.8,"id":71847983}]}]}
{"op":"mcm","clk":"11791565995","pt":1723050160356,"mc":[{"id":"1.231540926","rc":[{"batb":[[0,1.31,14],[1,1.3,6.73],[2,1.29,29.79]],"ltp":3.0,"tv":160.8,"id":71847983}]}]}
{"op":"mcm","clk":"11791566279","pt":1723050162562,"mc":[{"id":"1.231540926","rc":[{"batb":[[0,1.31,10]],"ltp":3.0,"tv":160.8,"id":71847983}]}]}
{"op":"mcm","clk":"11791566461","pt":1723050163668,"mc":[{"id":"1.231540926","rc":[{"batb":[[0,1.3,6.73],[1,1.29,29.79],[2,1.28,10]],"ltp":3.0,"tv":160.8,"id":71847983}]}]}
{"op":"mcm","clk":"11791566981","pt":1723050167989,"mc":[{"id":"1.231540926","rc":[{"batb":[[0,1.31,14],[1,1.3,6.73],[2,1.29,29.79]],"ltp":3.0,"tv":160.8,"id":71847983}]}]}
{"op":"mcm","clk":"11791567242","pt":1723050170293,"mc":[{"id":"1.231540926","rc":[{"batb":[[0,1.31,10]],"ltp":3.0,"tv":160.8,"id":71847983}]}]}
{"op":"mcm","clk":"11791567366","pt":1723050171290,"mc":[{"id":"1.231540926","rc":[{"batb":[[0,1.3,6.73],[1,1.29,29.79],[2,1.28,10]],"ltp":3.0,"tv":160.8,"id":71847983}]}]}
{"op":"mcm","clk":"11791574348","pt":1723050228143,"mc":[{"id":"1.231540926","rc":[{"batb":[[0,1.31,14],[1,1.3,6.73],[2,1.29,29.79]],"ltp":3.0,"tv":160.8,"id":71847983}]}]}
{"op":"mcm","clk":"11791574665","pt":1723050230737,"mc":[{"id":"1.231540926","rc":[{"batb":[[0,1.31,10]],"ltp":3.0,"tv":160.8,"id":71847983}]}]}
{"op":"mcm","clk":"11791574800","pt":1723050231842,"mc":[{"id":"1.231540926","rc":[{"batb":[[0,1.3,6.73],[1,1.29,29.79],[2,1.28,10]],"ltp":3.0,"tv":160.8,"id":71847983}]}]}
{"op":"mcm","clk":"11791577890","pt":1723050255951,"mc":[{"id":"1.231540926","rc":[{"batb":[[0,1.31,14],[1,1.3,6.73],[2,1.29,29.79]],"ltp":3.0,"tv":160.8,"id":71847983}]}]}
{"op":"mcm","clk":"11791578194","pt":1723050258189,"mc":[{"id":"1.231540926","rc":[{"batb":[[0,1.31,10]],"ltp":3.0,"tv":160.8,"id":71847983}]}]}
{"op":"mcm","clk":"11791578372","pt":1723050259459,"mc":[{"id":"1.231540926","rc":[{"batb":[[0,1.3,6.73],[1,1.29,29.79],[2,1.28,10]],"ltp":3.0,"tv":160.8,"id":71847983}]}]}
{"op":"mcm","clk":"11791583590","pt":1723050299729,"mc":[{"id":"1.231540926","rc":[{"batb":[[0,1.31,14],[1,1.3,6.73],[2,1.29,29.79]],"ltp":3.0,"tv":160.8,"id":71847983}]}]}
{"op":"mcm","clk":"11791583855","pt":1723050301896,"mc":[{"id":"1.231540926","rc":[{"batb":[[0,1.31,10]],"ltp":3.0,"tv":160.8,"id":71847983}]}]}
{"op":"mcm","clk":"11791584017","pt":1723050303112,"mc":[{"id":"1.231540926","rc":[{"batb":[[0,1.3,6.73],[1,1.29,29.79],[2,1.28,10]],"ltp":3.0,"tv":160.8,"id":71847983}]}]}
{"op":"mcm","clk":"11791589900","pt":1723050348152,"mc":[{"id":"1.231540926","rc":[{"batb":[[0,1.31,14],[1,1.3,6.73],[2,1.29,29.79]],"ltp":3.0,"tv":160.8,"id":71847983}]}]}
{"op":"mcm","clk":"11791590243","pt":1723050350659,"mc":[{"id":"1.231540926","rc":[{"batb":[[0,1.31,10]],"ltp":3.0,"tv":160.8,"id":71847983}]}]}
{"op":"mcm","clk":"11791590369","pt":1723050351552,"mc":[{"id":"1.231540926","rc":[{"batb":[[0,1.3,6.73],[1,1.29,29.79],[2,1.28,10]],"ltp":3.0,"tv":160.8,"id":71847983}]}]}
{"op":"mcm","clk":"11791606815","pt":1723050476417,"mc":[{"id":"1.231540926","rc":[{"batb":[[0,1.31,14],[1,1.3,6.73],[2,1.29,29.79]],"ltp":3.0,"tv":160.8,"id":71847983}]}]}
{"op":"mcm","clk":"11791607106","pt":1723050478618,"mc":[{"id":"1.231540926","rc":[{"batb":[[0,1.31,10]],"ltp":3.0,"tv":160.8,"id":71847983}]}]}
{"op":"mcm","clk":"11791607276","pt":1723050479786,"mc":[{"id":"1.231540926","rc":[{"batb":[[0,1.3,6.73],[1,1.29,29.79],[2,1.28,10]],"ltp":3.0,"tv":160.8,"id":71847983}]}]}
{"op":"mcm","clk":"11791608242","pt":1723050486907,"mc":[{"id":"1.231540926","rc":[{"batb":[[0,1.31,14],[1,1.3,6.73],[2,1.29,29.79]],"ltp":3.0,"tv":160.8,"id":71847983}]}]}
{"op":"mcm","clk":"11791608523","pt":1723050489115,"mc":[{"id":"1.231540926","rc":[{"batb":[[0,1.31,10]],"ltp":3.0,"tv":160.8,"id":71847983}]}]}
{"op":"mcm","clk":"11791608664","pt":1723050490316,"mc":[{"id":"1.231540926","rc":[{"batb":[[0,1.3,6.73],[1,1.29,29.79],[2,1.28,10]],"ltp":3.0,"tv":160.8,"id":71847983}]}]}
{"op":"mcm","clk":"11791617399","pt":1723050554906,"mc":[{"id":"1.231540926","rc":[{"batb":[[0,1.31,14],[1,1.3,6.73],[2,1.29,29.79]],"ltp":3.0,"tv":160.8,"id":71847983}]}]}
{"op":"mcm","clk":"11791617689","pt":1723050557110,"mc":[{"id":"1.231540926","rc":[{"batb":[[0,1.31,10]],"ltp":3.0,"tv":160.8,"id":71847983}]}]}
{"op":"mcm","clk":"11791617859","pt":1723050558305,"mc":[{"id":"1.231540926","rc":[{"batb":[[0,1.3,6.73],[1,1.29,29.79],[2,1.28,10]],"ltp":3.0,"tv":160.8,"id":71847983}]}]}
{"op":"mcm","clk":"11791619890","pt":1723050573813,"mc":[{"id":"1.231540926","rc":[{"batb":[[0,1.31,14],[1,1.3,6.73],[2,1.29,29.79]],"ltp":3.0,"tv":160.8,"id":71847983}]}]}
{"op":"mcm","clk":"11791620320","pt":1723050577123,"mc":[{"id":"1.231540926","rc":[{"batb":[[0,1.3,6.73],[1,1.29,29.79],[2,1.28,10]],"ltp":3.0,"tv":160.8,"id":71847983}]}]}
{"op":"mcm","clk":"11791620789","pt":1723050580612,"mc":[{"id":"1.231540926","rc":[{"batb":[[0,1.31,14],[1,1.3,6.73],[2,1.29,29.79]],"ltp":3.0,"tv":160.8,"id":71847983}]}]}
{"op":"mcm","clk":"11791621073","pt":1723050582820,"mc":[{"id":"1.231540926","rc":[{"batb":[[0,1.31,10]],"ltp":3.0,"tv":160.8,"id":71847983}]}]}
{"op":"mcm","clk":"11791621196","pt":1723050583822,"mc":[{"id":"1.231540926","rc":[{"batb":[[0,1.3,6.73],[1,1.29,29.79],[2,1.28,10]],"ltp":3.0,"tv":160.8,"id":71847983}]}]}
{"op":"mcm","clk":"11791624393","pt":1723050609054,"mc":[{"id":"1.231540926","rc":[{"batb":[[0,1.31,14],[1,1.3,6.73],[2,1.29,29.79]],"ltp":3.0,"tv":160.8,"id":71847983}]}]}
{"op":"mcm","clk":"11791624697","pt":1723050611249,"mc":[{"id":"1.231540926","rc":[{"batb":[[0,1.31,10]],"ltp":3.0,"tv":160.8,"id":71847983}]}]}
{"op":"mcm","clk":"11791624837","pt":1723050612261,"mc":[{"id":"1.231540926","rc":[{"batb":[[0,1.3,6.73],[1,1.29,29.79],[2,1.28,10]],"ltp":3.0,"tv":160.8,"id":71847983}]}]}
{"op":"mcm","clk":"11791626738","pt":1723050625769,"mc":[{"id":"1.231540926","rc":[{"batb":[[0,1.31,14],[1,1.3,6.73],[2,1.29,29.79]],"ltp":3.0,"tv":160.8,"id":71847983}]}]}
{"op":"mcm","clk":"11791627102","pt":1723050628286,"mc":[{"id":"1.231540926","rc":[{"batb":[[0,1.31,10]],"ltp":3.0,"tv":160.8,"id":71847983}]}]}
{"op":"mcm","clk":"11791627232","pt":1723050629279,"mc":[{"id":"1.231540926","rc":[{"batb":[[0,1.3,6.73],[1,1.29,29.79],[2,1.28,10]],"ltp":3.0,"tv":160.8,"id":71847983}]}]}
{"op":"mcm","clk":"11791629377","pt":1723050644343,"mc":[{"id":"1.231540926","rc":[{"batb":[[0,1.31,14],[1,1.3,6.73],[2,1.29,29.79]],"ltp":3.0,"tv":160.8,"id":71847983}]}]}
{"op":"mcm","clk":"11791629679","pt":1723050646587,"mc":[{"id":"1.231540926","rc":[{"batb":[[0,1.31,10]],"ltp":3.0,"tv":160.8,"id":71847983}]}]}
{"op":"mcm","clk":"11791629836","pt":1723050647686,"mc":[{"id":"1.231540926","rc":[{"batb":[[0,1.3,6.73],[1,1.29,29.79],[2,1.28,10]],"ltp":3.0,"tv":160.8,"id":71847983}]}]}
{"op":"mcm","clk":"11791630731","pt":1723050653888,"mc":[{"id":"1.231540926","rc":[{"batb":[[0,1.31,14],[1,1.3,6.73],[2,1.29,29.79]],"ltp":3.0,"tv":160.8,"id":71847983}]}]}
{"op":"mcm","clk":"11791631014","pt":1723050656189,"mc":[{"id":"1.231540926","rc":[{"batb":[[0,1.31,10]],"ltp":3.0,"tv":160.8,"id":71847983}]}]}
{"op":"mcm","clk":"11791631157","pt":1723050657178,"mc":[{"id":"1.231540926","rc":[{"batb":[[0,1.3,6.73],[1,1.29,29.79],[2,1.28,10]],"ltp":3.0,"tv":160.8,"id":71847983}]}]}
{"op":"mcm","clk":"11791632170","pt":1723050664527,"mc":[{"id":"1.231540926","rc":[{"batb":[[0,1.31,14],[1,1.3,6.73],[2,1.29,29.79]],"ltp":3.0,"tv":160.8,"id":71847983}]}]}
{"op":"mcm","clk":"11791632457","pt":1723050666888,"mc":[{"id":"1.231540926","rc":[{"batb":[[0,1.31,10]],"ltp":3.0,"tv":160.8,"id":71847983}]}]}
{"op":"mcm","clk":"11791632587","pt":1723050668027,"mc":[{"id":"1.231540926","rc":[{"batb":[[0,1.3,6.73],[1,1.29,29.79],[2,1.28,10]],"ltp":3.0,"tv":160.8,"id":71847983}]}]}
{"op":"mcm","clk":"11791634161","pt":1723050679964,"mc":[{"id":"1.231540926","rc":[{"batb":[[0,1.31,14],[1,1.3,6.73],[2,1.29,29.79]],"ltp":3.0,"tv":160.8,"id":71847983}]}]}
{"op":"mcm","clk":"11791634592","pt":1723050683146,"mc":[{"id":"1.231540926","rc":[{"batb":[[0,1.3,6.73],[1,1.29,29.79],[2,1.28,10]],"ltp":3.0,"tv":160.8,"id":71847983}]}]}
{"op":"mcm","clk":"11791636291","pt":1723050695963,"mc":[{"id":"1.231540926","rc":[{"batb":[[0,1.31,14],[1,1.3,6.73],[2,1.29,29.79]],"ltp":3.0,"tv":160.8,"id":71847983}]}]}
{"op":"mcm","clk":"11791636680","pt":1723050699139,"mc":[{"id":"1.231540926","rc":[{"batb":[[0,1.3,6.73],[1,1.29,29.79],[2,1.28,10]],"ltp":3.0,"tv":160.8,"id":71847983}]}]}
{"op":"mcm","clk":"11791651900","pt":1723050820155,"mc":[{"id":"1.231540926","rc":[{"batb":[[0,1.26,17.72],[1,1.25,100],[2,1.19,20]],"ltp":1.5,"tv":158.73,"id":19144236}]}]}
{"op":"mcm","clk":"11791651926","pt":1723050820363,"mc":[{"id":"1.231540926","rc":[{"batb":[[0,1.31,14],[1,1.3,6.73]],"ltp":3.0,"tv":160.8,"id":71847983}]}]}
{"op":"mcm","clk":"11791652183","pt":1723050822560,"mc":[{"id":"1.231540926","rc":[{"batb":[[0,1.31,10]],"ltp":3.0,"tv":160.8,"id":71847983}]}]}
{"op":"mcm","clk":"11791652321","pt":1723050823554,"mc":[{"id":"1.231540926","rc":[{"batb":[[0,1.3,6.73],[1,1.28,10],[2,1.25,100]],"ltp":3.0,"tv":160.8,"id":71847983}]}]}
{"op":"mcm","clk":"11791655002","pt":1723050843175,"mc":[{"id":"1.231540926","rc":[{"batb":[[0,1.31,14],[1,1.3,6.73],[2,1.28,10]],"ltp":3.0,"tv":160.8,"id":71847983}]}]}
{"op":"mcm","clk":"11791655369","pt":1723050845657,"mc":[{"id":"1.231540926","rc":[{"batb":[[0,1.31,10]],"ltp":3.0,"tv":160.8,"id":71847983}]}]}
{"op":"mcm","clk":"11791655479","pt":1723050846497,"mc":[{"id":"1.231540926","rc":[{"batb":[[0,1.3,6.73],[1,1.28,10],[2,1.25,100]],"ltp":3.0,"tv":160.8,"id":71847983}]}]}
{"op":"mcm","clk":"11791655806","pt":1723050849076,"mc":[{"id":"1.231540926","rc":[{"batb":[[0,1.31,14],[1,1.3,6.73],[2,1.28,10]],"ltp":3.0,"tv":160.8,"id":71847983}]}]}
{"op":"mcm","clk":"11791656111","pt":1723050851288,"mc":[{"id":"1.231540926","rc":[{"batb":[[0,1.31,10]],"ltp":3.0,"tv":160.8,"id":71847983}]}]}
{"op":"mcm","clk":"11791656237","pt":1723050852178,"mc":[{"id":"1.231540926","rc":[{"batb":[[0,1.3,6.73],[1,1.28,10],[2,1.25,100]],"ltp":3.0,"tv":160.8,"id":71847983}]}]}
{"op":"mcm","clk":"11791669356","pt":1723050953387,"mc":[{"id":"1.231540926","rc":[{"batb":[[0,1.32,14],[1,1.31,27.87],[2,1.3,6.73]],"ltp":3.0,"tv":160.8,"id":71847983},{"batb":[[0,1.51,16.94],[1,1.26,17.72],[2,1.25,100]],"ltp":1.5,"tv":158.73,"id":19144236}]}]}
{"op":"mcm","clk":"11791669659","pt":1723050955719,"mc":[{"id":"1.231540926","rc":[{"batb":[[0,1.32,10]],"ltp":3.0,"tv":160.8,"id":71847983}]}]}
{"op":"mcm","clk":"11791669780","pt":1723050956609,"mc":[{"id":"1.231540926","rc":[{"batb":[[0,1.31,27.87],[1,1.3,6.73],[2,1.28,10]],"ltp":3.0,"tv":160.8,"id":71847983}]}]}
{"op":"mcm","clk":"11791672698","pt":1723050979010,"mc":[{"id":"1.231540926","rc":[{"batb":[[0,1.32,14],[1,1.31,27.87],[2,1.3,6.73]],"ltp":3.0,"tv":160.8,"id":71847983}]}]}
{"op":"mcm","clk":"11791673002","pt":1723050981355,"mc":[{"id":"1.231540926","rc":[{"batb":[[0,1.32,10]],"ltp":3.0,"tv":160.8,"id":71847983}]}]}
{"op":"mcm","clk":"11791673164","pt":1723050982453,"mc":[{"id":"1.231540926","rc":[{"batb":[[0,1.31,27.87],[1,1.3,6.73],[2,1.28,10]],"ltp":3.0,"tv":160.8,"id":71847983}]}]}
{"op":"mcm","clk":"11791682013","pt":1723051049998,"mc":[{"id":"1.231540926","rc":[{"batb":[[0,1.32,20.73],[1,1.31,27.87]],"ltp":3.0,"tv":160.8,"id":71847983},{"batb":[[1,1.26,10]],"ltp":1.5,"tv":158.73,"id":19144236}]}]}
{"op":"mcm","clk":"11791682292","pt":1723051052089,"mc":[{"id":"1.231540926","rc":[{"batb":[[0,1.32,16.73]],"ltp":3.0,"tv":160.8,"id":71847983}]}]}
{"op":"mcm","clk":"11791682441","pt":1723051053125,"mc":[{"id":"1.231540926","rc":[{"batb":[[0,1.32,6.73]],"ltp":3.0,"tv":160.8,"id":71847983}]}]}
{"op":"mcm","clk":"11791693686","pt":1723051131788,"mc":[{"id":"1.231540926","rc":[{"batb":[[0,1.33,14],[1,1.32,6.73],[2,1.31,27.87]],"ltp":3.0,"tv":160.8,"id":71847983}]}]}
{"op":"mcm","clk":"11791694139","pt":1723051135085,"mc":[{"id":"1.231540926","rc":[{"batb":[[0,1.32,6.73],[1,1.31,27.87],[2,1.28,10]],"ltp":3.0,"tv":160.8,"id":71847983}]}]}
{"op":"mcm","clk":"11791702456","pt":1723051193445,"mc":[{"id":"1.231540926","rc":[{"batb":[[0,1.33,14],[1,1.32,6.73],[2,1.31,27.87]],"ltp":3.0,"tv":160.8,"id":71847983}]}]}
{"op":"mcm","clk":"11791702865","pt":1723051196060,"mc":[{"id":"1.231540926","rc":[{"batb":[[0,1.33,10]],"ltp":3.0,"tv":160.8,"id":71847983}]}]}
{"op":"mcm","clk":"11791702962","pt":1723051196745,"mc":[{"id":"1.231540926","rc":[{"batb":[[0,1.32,6.73],[1,1.31,27.87],[2,1.28,10]],"ltp":3.0,"tv":160.8,"id":71847983}]}]}
{"op":"mcm","clk":"11791708500","pt":1723051238385,"mc":[{"id":"1.231540926","rc":[{"batb":[[0,1.33,14],[1,1.32,6.73],[2,1.31,27.87]],"ltp":3.0,"tv":160.8,"id":71847983}]}]}
{"op":"mcm","clk":"11791708803","pt":1723051240612,"mc":[{"id":"1.231540926","rc":[{"batb":[[0,1.33,10]],"ltp":3.0,"tv":160.8,"id":71847983}]}]}
{"op":"mcm","clk":"11791708969","pt":1723051241711,"mc":[{"id":"1.231540926","rc":[{"batb":[[0,1.32,6.73],[1,1.31,27.87],[2,1.28,10]],"ltp":3.0,"tv":160.8,"id":71847983}]}]}
{"op":"mcm","clk":"11791713041","pt":1723051271111,"mc":[{"id":"1.231540926","rc":[{"batb":[[0,1.33,14],[1,1.32,6.73],[2,1.31,27.87]],"ltp":3.0,"tv":160.8,"id":71847983}]}]}
{"op":"mcm","clk":"11791713323","pt":1723051273355,"mc":[{"id":"1.231540926","rc":[{"batb":[[0,1.33,10]],"ltp":3.0,"tv":160.8,"id":71847983}]}]}
{"op":"mcm","clk":"11791713484","pt":1723051274454,"mc":[{"id":"1.231540926","rc":[{"batb":[[0,1.32,6.73],[1,1.31,27.87],[2,1.28,10]],"ltp":3.0,"tv":160.8,"id":71847983}]}]}
{"op":"mcm","clk":"11791717848","pt":1723051303554,"mc":[{"id":"1.231540926","rc":[{"batb":[[0,1.33,14],[1,1.32,6.73],[2,1.31,27.87]],"ltp":3.0,"tv":160.8,"id":71847983}]}]}
{"op":"mcm","clk":"11791718190","pt":1723051305956,"mc":[{"id":"1.231540926","rc":[{"batb":[[0,1.33,10]],"ltp":3.0,"tv":160.8,"id":71847983}]}]}
{"op":"mcm","clk":"11791718304","pt":1723051306846,"mc":[{"id":"1.231540926","rc":[{"batb":[[0,1.32,6.73],[1,1.31,27.87],[2,1.28,10]],"ltp":3.0,"tv":160.8,"id":71847983}]}]}
{"op":"mcm","clk":"11791720611","pt":1723051323680,"mc":[{"id":"1.231540926","rc":[{"batb":[[0,1.33,14],[1,1.32,6.73],[2,1.31,27.87]],"ltp":3.0,"tv":160.8,"id":71847983}]}]}
{"op":"mcm","clk":"11791720963","pt":1723051325975,"mc":[{"id":"1.231540926","rc":[{"batb":[[0,1.33,10]],"ltp":3.0,"tv":160.8,"id":71847983}]}]}
{"op":"mcm","clk":"11791721100","pt":1723051326964,"mc":[{"id":"1.231540926","rc":[{"batb":[[0,1.32,6.73],[1,1.31,27.87],[2,1.28,10]],"ltp":3.0,"tv":160.8,"id":71847983}]}]}
{"op":"mcm","clk":"11791722196","pt":1723051335088,"mc":[{"id":"1.231540926","rc":[{"batb":[[0,1.33,14],[1,1.32,6.73],[2,1.31,27.87]],"ltp":3.0,"tv":160.8,"id":71847983}]}]}
{"op":"mcm","clk":"11791722480","pt":1723051337399,"mc":[{"id":"1.231540926","rc":[{"batb":[[0,1.33,10]],"ltp":3.0,"tv":160.8,"id":71847983}]}]}
{"op":"mcm","clk":"11791722655","pt":1723051338490,"mc":[{"id":"1.231540926","rc":[{"batb":[[0,1.32,6.73],[1,1.31,27.87],[2,1.28,10]],"ltp":3.0,"tv":160.8,"id":71847983}]}]}
{"op":"mcm","clk":"11791725784","pt":1723051359813,"mc":[{"id":"1.231540926","rc":[{"batb":[[0,1.33,14],[1,1.32,6.73],[2,1.31,27.87]],"ltp":3.0,"tv":160.8,"id":71847983}]}]}
{"op":"mcm","clk":"11791726120","pt":1723051362015,"mc":[{"id":"1.231540926","rc":[{"batb":[[0,1.33,10]],"ltp":3.0,"tv":160.8,"id":71847983}]}]}
{"op":"mcm","clk":"11791726287","pt":1723051363101,"mc":[{"id":"1.231540926","rc":[{"batb":[[0,1.32,6.73],[1,1.31,27.87],[2,1.28,10]],"ltp":3.0,"tv":160.8,"id":71847983}]}]}
{"op":"mcm","clk":"11791726640","pt":1723051365395,"mc":[{"id":"1.231540926","rc":[{"batb":[[0,1.34,10],[1,1.33,4],[2,1.32,6.73]],"ltp":3.0,"tv":160.8,"id":71847983}]}]}
{"op":"mcm","clk":"11791726944","pt":1723051367432,"mc":[{"id":"1.231540926","rc":[{"batb":[[1,1.32,6.73],[2,1.31,27.87]],"ltp":3.0,"tv":160.8,"id":71847983}]}]}
{"op":"mcm","clk":"11791727131","pt":1723051368593,"mc":[{"id":"1.231540926","rc":[{"batb":[[0,1.32,6.73],[1,1.31,27.87],[2,1.28,10]],"ltp":3.0,"tv":160.8,"id":71847983}]}]}
{"op":"mcm","clk":"11791728317","pt":1723051377134,"mc":[{"id":"1.231540926","rc":[{"batb":[[0,1.33,14],[1,1.32,6.73],[2,1.31,27.87]],"ltp":3.0,"tv":160.8,"id":71847983}]}]}
{"op":"mcm","clk":"11791728623","pt":1723051379436,"mc":[{"id":"1.231540926","rc":[{"batb":[[0,1.33,10]],"ltp":3.0,"tv":160.8,"id":71847983}]}]}
{"op":"mcm","clk":"11791728748","pt":1723051380326,"mc":[{"id":"1.231540926","rc":[{"batb":[[0,1.32,6.73],[1,1.31,27.87],[2,1.28,10]],"ltp":3.0,"tv":160.8,"id":71847983}]}]}
{"op":"mcm","clk":"11791730522","pt":1723051392664,"mc":[{"id":"1.231540926","rc":[{"batb":[[0,1.33,14],[1,1.32,6.73],[2,1.31,27.87]],"ltp":3.0,"tv":160.8,"id":71847983}]}]}
{"op":"mcm","clk":"11791730863","pt":1723051395128,"mc":[{"id":"1.231540926","rc":[{"batb":[[0,1.33,10]],"ltp":3.0,"tv":160.8,"id":71847983}]}]}
{"op":"mcm","clk":"11791730986","pt":1723051395957,"mc":[{"id":"1.231540926","rc":[{"batb":[[0,1.32,6.73],[1,1.31,27.87],[2,1.28,10]],"ltp":3.0,"tv":160.8,"id":71847983}]}]}
{"op":"mcm","clk":"11791731266","pt":1723051397786,"mc":[{"id":"1.231540926","rc":[{"batb":[[0,1.33,4],[1,1.32,6.73],[2,1.31,27.87]],"ltp":3.0,"tv":160.8,"id":71847983}]}]}
{"op":"mcm","clk":"11791731620","pt":1723051400088,"mc":[{"id":"1.231540926","rc":[{"batb":[[0,1.32,6.73],[1,1.31,27.87],[2,1.28,10]],"ltp":3.0,"tv":160.8,"id":71847983}]}]}
{"op":"mcm","clk":"11791731650","pt":1723051400295,"mc":[{"id":"1.231540926","rc":[{"batb":[[0,1.33,10],[1,1.32,6.73],[2,1.31,27.87]],"ltp":3.0,"tv":160.8,"id":71847983}]}]}
{"op":"mcm","clk":"11791732141","pt":1723051403864,"mc":[{"id":"1.231540926","rc":[{"batb":[[0,1.33,4]],"ltp":3.0,"tv":160.8,"id":71847983}]}]}
{"op":"mcm","clk":"11791732531","pt":1723051406472,"mc":[{"id":"1.231540926","rc":[{"batb":[[0,1.33,10]],"ltp":3.0,"tv":160.8,"id":71847983}]}]}
{"op":"mcm","clk":"11791733103","pt":1723051410171,"mc":[{"id":"1.231540926","rc":[{"batb":[[0,1.34,4]],"ltp":3.0,"tv":160.8,"id":71847983}]}]}
{"op":"mcm","clk":"11791733477","pt":1723051412876,"mc":[{"id":"1.231540926","rc":[{"batb":[[0,1.33,10]],"ltp":3.0,"tv":160.8,"id":71847983}]}]}
{"op":"mcm","clk":"11791733972","pt":1723051416275,"mc":[{"id":"1.231540926","rc":[{"batb":[[0,1.34,4]],"ltp":3.0,"tv":160.8,"id":71847983}]}]}
{"op":"mcm","clk":"11791734343","pt":1723051418885,"mc":[{"id":"1.231540926","rc":[{"batb":[[0,1.33,10]],"ltp":3.0,"tv":160.8,"id":71847983}]}]}
{"op":"mcm","clk":"11791734792","pt":1723051422124,"mc":[{"id":"1.231540926","rc":[{"batb":[[0,1.32,6.73],[1,1.31,27.87],[2,1.28,10]],"ltp":3.0,"tv":160.8,"id":71847983}]}]}
{"op":"mcm","clk":"11791734807","pt":1723051422186,"mc":[{"id":"1.231540926","rc":[{"batb":[[0,1.33,4],[1,1.32,6.73],[2,1.31,27.87]],"ltp":3.0,"tv":160.8,"id":71847983}]}]}
{"op":"mcm","clk":"11791735182","pt":1723051424796,"mc":[{"id":"1.231540926","rc":[{"batb":[[0,1.33,10]],"ltp":3.0,"tv":160.8,"id":71847983}]}]}
{"op":"mcm","clk":"11791735685","pt":1723051428410,"mc":[{"id":"1.231540926","rc":[{"batb":[[0,1.33,4]],"ltp":3.0,"tv":160.8,"id":71847983}]}]}
{"op":"mcm","clk":"11791736088","pt":1723051431498,"mc":[{"id":"1.231540926","rc":[{"batb":[[0,1.33,10]],"ltp":3.0,"tv":160.8,"id":71847983}]}]}
{"op":"mcm","clk":"11791736561","pt":1723051434995,"mc":[{"id":"1.231540926","rc":[{"batb":[[0,1.33,4]],"ltp":3.0,"tv":160.8,"id":71847983}]}]}
{"op":"mcm","clk":"11791736916","pt":1723051437606,"mc":[{"id":"1.231540926","rc":[{"batb":[[0,1.33,10]],"ltp":3.0,"tv":160.8,"id":71847983}]}]}
{"op":"mcm","clk":"11791737369","pt":1723051440901,"mc":[{"id":"1.231540926","rc":[{"batb":[[0,1.33,4]],"ltp":3.0,"tv":160.8,"id":71847983}]}]}
{"op":"mcm","clk":"11791737700","pt":1723051443106,"mc":[{"id":"1.231540926","rc":[{"batb":[[0,1.32,6.73],[1,1.31,27.87],[2,1.28,10]],"ltp":3.0,"tv":160.8,"id":71847983}]}]}
{"op":"mcm","clk":"11791737731","pt":1723051443309,"mc":[{"id":"1.231540926","rc":[{"batb":[[0,1.33,10],[1,1.32,6.73],[2,1.31,27.87]],"ltp":3.0,"tv":160.8,"id":71847983}]}]}
{"op":"mcm","clk":"11791738181","pt":1723051446717,"mc":[{"id":"1.231540926","rc":[{"batb":[[0,1.33,4]],"ltp":3.0,"tv":160.8,"id":71847983}]}]}
{"op":"mcm","clk":"11791738513","pt":1723051449014,"mc":[{"id":"1.231540926","rc":[{"batb":[[0,1.33,10]],"ltp":3.0,"tv":160.8,"id":71847983}]}]}
{"op":"mcm","clk":"11791738986","pt":1723051452609,"mc":[{"id":"1.231540926","rc":[{"batb":[[0,1.33,4]],"ltp":3.0,"tv":160.8,"id":71847983}]}]}
{"op":"mcm","clk":"11791739298","pt":1723051455120,"mc":[{"id":"1.231540926","rc":[{"batb":[[0,1.33,10]],"ltp":3.0,"tv":160.8,"id":71847983}]}]}
{"op":"mcm","clk":"11791739765","pt":1723051458522,"mc":[{"id":"1.231540926","rc":[{"batb":[[0,1.33,4]],"ltp":3.0,"tv":160.8,"id":71847983}]}]}
{"op":"mcm","clk":"11791740150","pt":1723051461133,"mc":[{"id":"1.231540926","rc":[{"batb":[[0,1.32,6.73],[1,1.31,27.87],[2,1.28,10]],"ltp":3.0,"tv":160.8,"id":71847983}]}]}
{"op":"mcm","clk":"11791740179","pt":1723051461296,"mc":[{"id":"1.231540926","rc":[{"batb":[[0,1.33,10],[1,1.32,6.73],[2,1.31,27.87]],"ltp":3.0,"tv":160.8,"id":71847983}]}]}
{"op":"mcm","clk":"11791740734","pt":1723051465015,"mc":[{"id":"1.231540926","rc":[{"batb":[[0,1.33,4]],"ltp":3.0,"tv":160.8,"id":71847983}]}]}
{"op":"mcm","clk":"11791741102","pt":1723051467724,"mc":[{"id":"1.231540926","rc":[{"batb":[[0,1.33,10]],"ltp":3.0,"tv":160.8,"id":71847983}]}]}
{"op":"mcm","clk":"11791741564","pt":1723051471137,"mc":[{"id":"1.231540926","rc":[{"batb":[[0,1.33,4]],"ltp":3.0,"tv":160.8,"id":71847983}]}]}
{"op":"mcm","clk":"11791741911","pt":1723051473528,"mc":[{"id":"1.231540926","rc":[{"batb":[[0,1.33,10]],"ltp":3.0,"tv":160.8,"id":71847983}]}]}
{"op":"mcm","clk":"11791742417","pt":1723051477148,"mc":[{"id":"1.231540926","rc":[{"batb":[[0,1.33,4]],"ltp":3.0,"tv":160.8,"id":71847983}]}]}
{"op":"mcm","clk":"11791742747","pt":1723051479544,"mc":[{"id":"1.231540926","rc":[{"batb":[[0,1.33,10]],"ltp":3.0,"tv":160.8,"id":71847983}]}]}
{"op":"mcm","clk":"11791743239","pt":1723051483055,"mc":[{"id":"1.231540926","rc":[{"batb":[[0,1.32,6.73],[1,1.31,27.87],[2,1.28,10]],"ltp":3.0,"tv":160.8,"id":71847983}]}]}
{"op":"mcm","clk":"11791743278","pt":1723051483232,"mc":[{"id":"1.231540926","rc":[{"batb":[[0,1.33,4],[1,1.32,6.73],[2,1.31,27.87]],"ltp":3.0,"tv":160.8,"id":71847983}]}]}
{"op":"mcm","clk":"11791743656","pt":1723051485537,"mc":[{"id":"1.231540926","rc":[{"batb":[[0,1.33,10]],"ltp":3.0,"tv":160.8,"id":71847983}]}]}
{"op":"mcm","clk":"11791744194","pt":1723051488936,"mc":[{"id":"1.231540926","rc":[{"batb":[[0,1.33,4]],"ltp":3.0,"tv":160.8,"id":71847983}]}]}
{"op":"mcm","clk":"11791744589","pt":1723051491571,"mc":[{"id":"1.231540926","rc":[{"batb":[[0,1.33,10]],"ltp":3.0,"tv":160.8,"id":71847983}]}]}
{"op":"mcm","clk":"11791745078","pt":1723051494763,"mc":[{"id":"1.231540926","rc":[{"batb":[[0,1.34,4]],"ltp":3.0,"tv":160.8,"id":71847983}]}]}
{"op":"mcm","clk":"11791745422","pt":1723051496963,"mc":[{"id":"1.231540926","rc":[{"batb":[[0,1.32,6.73],[1,1.31,27.87],[2,1.28,10]],"ltp":3.0,"tv":160.8,"id":71847983}]}]}
{"op":"mcm","clk":"11791745451","pt":1723051497168,"mc":[{"id":"1.231540926","rc":[{"batb":[[0,1.33,10],[1,1.32,6.73],[2,1.31,27.87]],"ltp":3.0,"tv":160.8,"id":71847983}]}]}
{"op":"mcm","clk":"11791745939","pt":1723051500373,"mc":[{"id":"1.231540926","rc":[{"batb":[[0,1.34,4]],"ltp":3.0,"tv":160.8,"id":71847983}]}]}
{"op":"mcm","clk":"11791746320","pt":1723051502699,"mc":[{"id":"1.231540926","rc":[{"batb":[[0,1.33,10]],"ltp":3.0,"tv":160.8,"id":71847983}]}]}
{"op":"mcm","clk":"11791746889","pt":1723051506081,"mc":[{"id":"1.231540926","rc":[{"batb":[[0,1.34,4]],"ltp":3.0,"tv":160.8,"id":71847983}]}]}
{"op":"mcm","clk":"11791747238","pt":1723051508076,"mc":[{"id":"1.231540926","rc":[{"batb":[[0,1.32,6.73],[1,1.31,27.87],[2,1.28,10]],"ltp":3.0,"tv":160.8,"id":71847983}]}]}
{"op":"mcm","clk":"11791747852","pt":1723051511698,"mc":[{"id":"1.231540926","rc":[{"batb":[[0,1.33,14],[1,1.32,6.73],[2,1.31,27.87]],"ltp":3.0,"tv":160.8,"id":71847983}]}]}
{"op":"mcm","clk":"11791748328","pt":1723051514899,"mc":[{"id":"1.231540926","rc":[{"batb":[[0,1.32,6.73],[1,1.31,27.87],[2,1.28,10]],"ltp":3.0,"tv":160.8,"id":71847983}]}]}
{"op":"mcm","clk":"11791751344","pt":1723051534311,"mc":[{"id":"1.231540926","rc":[{"batb":[[0,1.33,14],[1,1.32,6.73],[2,1.31,27.87]],"ltp":3.0,"tv":160.8,"id":71847983}]}]}
{"op":"mcm","clk":"11791751661","pt":1723051536630,"mc":[{"id":"1.231540926","rc":[{"batb":[[0,1.33,10]],"ltp":3.0,"tv":160.8,"id":71847983}]}]}
{"op":"mcm","clk":"11791751839","pt":1723051537714,"mc":[{"id":"1.231540926","rc":[{"batb":[[0,1.32,6.73],[1,1.31,27.87],[2,1.28,10]],"ltp":3.0,"tv":160.8,"id":71847983}]}]}
{"op":"mcm","clk":"11791752416","pt":1723051541599,"mc":[{"id":"1.231540926","rc":[{"batb":[[0,1.33,14],[1,1.32,6.73],[2,1.31,27.87]],"ltp":3.0,"tv":160.8,"id":71847983}]}]}
{"op":"mcm","clk":"11791752766","pt":1723051544002,"mc":[{"id":"1.231540926","rc":[{"batb":[[0,1.33,10]],"ltp":3.0,"tv":160.8,"id":71847983}]}]}
{"op":"mcm","clk":"11791752905","pt":1723051544900,"mc":[{"id":"1.231540926","rc":[{"batb":[[0,1.32,6.73],[1,1.31,27.87],[2,1.28,10]],"ltp":3.0,"tv":160.8,"id":71847983}]}]}
{"op":"mcm","clk":"11791761768","pt":1723051606475,"mc":[{"id":"1.231540926","rc":[{"batb":[[0,1.33,14],[1,1.32,6.73],[2,1.31,27.87]],"ltp":3.0,"tv":160.8,"id":71847983}]}]}
{"op":"mcm","clk":"11791762111","pt":1723051608773,"mc":[{"id":"1.231540926","rc":[{"batb":[[0,1.33,10]],"ltp":3.0,"tv":160.8,"id":71847983}]}]}
{"op":"mcm","clk":"11791762250","pt":1723051609765,"mc":[{"id":"1.231540926","rc":[{"batb":[[0,1.32,6.73],[1,1.31,27.87],[2,1.28,10]],"ltp":3.0,"tv":160.8,"id":71847983}]}]}
{"op":"mcm","clk":"11791772049","pt":1723051672409,"mc":[{"id":"1.231540926","rc":[{"batb":[[0,1.33,14],[1,1.32,6.73],[2,1.31,27.87]],"ltp":3.0,"tv":160.8,"id":71847983}]}]}
{"op":"mcm","clk":"11791772416","pt":1723051674708,"mc":[{"id":"1.231540926","rc":[{"batb":[[0,1.33,10]],"ltp":3.0,"tv":160.8,"id":71847983}]}]}
{"op":"mcm","clk":"11791772603","pt":1723051675905,"mc":[{"id":"1.231540926","rc":[{"batb":[[0,1.32,6.73],[1,1.31,27.87],[2,1.28,10]],"ltp":3.0,"tv":160.8,"id":71847983}]}]}
{"op":"mcm","clk":"11791779191","pt":1723051715955,"mc":[{"id":"1.231540926","rc":[{"batb":[[0,1.33,14],[1,1.32,6.73],[2,1.31,27.87]],"ltp":3.0,"tv":160.8,"id":71847983}]}]}
{"op":"mcm","clk":"11791779562","pt":1723051718466,"mc":[{"id":"1.231540926","rc":[{"batb":[[0,1.33,10]],"ltp":3.0,"tv":160.8,"id":71847983}]}]}
{"op":"mcm","clk":"11791779711","pt":1723051719456,"mc":[{"id":"1.231540926","rc":[{"batb":[[0,1.32,6.73],[1,1.31,27.87],[2,1.28,10]],"ltp":3.0,"tv":160.8,"id":71847983}]}]}
{"op":"mcm","clk":"11791783033","pt":1723051741194,"mc":[{"id":"1.231540926","rc":[{"batb":[[0,1.33,14],[1,1.32,6.73],[2,1.31,27.87]],"ltp":3.0,"tv":160.8,"id":71847983}]}]}
{"op":"mcm","clk":"11791783420","pt":1723051743463,"mc":[{"id":"1.231540926","rc":[{"batb":[[0,1.33,10]],"ltp":3.0,"tv":160.8,"id":71847983}]}]}
{"op":"mcm","clk":"11791783594","pt":1723051744506,"mc":[{"id":"1.231540926","rc":[{"batb":[[0,1.32,6.73],[1,1.31,27.87],[2,1.28,10]],"ltp":3.0,"tv":160.8,"id":71847983}]}]}
{"op":"mcm","clk":"11791792324","pt":1723051804378,"mc":[{"id":"1.231540926","rc":[{"batb":[[0,1.33,14],[1,1.32,6.73],[2,1.31,27.87]],"ltp":3.0,"tv":160.8,"id":71847983}]}]}
{"op":"mcm","clk":"11791792707","pt":1723051806665,"mc":[{"id":"1.231540926","rc":[{"batb":[[0,1.33,10]],"ltp":3.0,"tv":160.8,"id":71847983}]}]}
{"op":"mcm","clk":"11791792843","pt":1723051807570,"mc":[{"id":"1.231540926","rc":[{"batb":[[0,1.32,6.73],[1,1.31,27.87],[2,1.28,10]],"ltp":3.0,"tv":160.8,"id":71847983}]}]}
{"op":"mcm","clk":"11791793035","pt":1723051808862,"mc":[{"id":"1.231540926","rc":[{"batb":[[0,1.33,4],[1,1.32,6.73],[2,1.31,27.87]],"ltp":3.0,"tv":160.8,"id":71847983}]}]}
{"op":"mcm","clk":"11791793409","pt":1723051811277,"mc":[{"id":"1.231540926","rc":[{"batb":[[0,1.34,10]],"ltp":3.0,"tv":160.8,"id":71847983}]}]}
{"op":"mcm","clk":"11791793977","pt":1723051814858,"mc":[{"id":"1.231540926","rc":[{"batb":[[0,1.33,4]],"ltp":3.0,"tv":160.8,"id":71847983}]}]}
{"op":"mcm","clk":"11791794344","pt":1723051816970,"mc":[{"id":"1.231540926","rc":[{"batb":[[0,1.34,10],[1,1.33,4],[2,1.32,6.73]],"ltp":3.0,"tv":160.8,"id":71847983}]}]}
{"op":"mcm","clk":"11791794381","pt":1723051817179,"mc":[{"id":"1.231540926","rc":[{"batb":[[1,1.32,6.73],[2,1.31,27.87]],"ltp":3.0,"tv":160.8,"id":71847983}]}]}
{"op":"mcm","clk":"11791794781","pt":1723051819765,"mc":[{"id":"1.231540926","rc":[{"batb":[[0,1.35,4],[1,1.34,10],[2,1.32,6.73]],"ltp":3.0,"tv":160.8,"id":71847983}]}]}
{"op":"mcm","clk":"11791794883","pt":1723051820420,"mc":[{"id":"1.231540926","rc":[{"batb":[[1,1.32,6.73],[2,1.31,27.87]],"ltp":3.0,"tv":160.8,"id":71847983}]}]}
{"op":"mcm","clk":"11791795152","pt":1723051821974,"mc":[{"id":"1.231540926","rc":[{"batb":[[0,1.32,6.73],[1,1.31,27.87],[2,1.28,10]],"ltp":3.0,"tv":160.8,"id":71847983}]}]}
{"op":"mcm","clk":"11791795651","pt":1723051825598,"mc":[{"id":"1.231540926","rc":[{"batb":[[0,1.33,14],[1,1.32,6.73],[2,1.31,27.87]],"ltp":3.0,"tv":160.8,"id":71847983}]}]}
{"op":"mcm","clk":"11791796011","pt":1723051827867,"mc":[{"id":"1.231540926","rc":[{"batb":[[0,1.33,10]],"ltp":3.0,"tv":160.8,"id":71847983}]}]}
{"op":"mcm","clk":"11791796168","pt":1723051828868,"mc":[{"id":"1.231540926","rc":[{"batb":[[0,1.32,6.73],[1,1.31,27.87],[2,1.28,10]],"ltp":3.0,"tv":160.8,"id":71847983}]}]}
{"op":"mcm","clk":"11791861598","pt":1723052244489,"mc":[{"id":"1.231540926","rc":[{"batb":[[0,1.33,14],[1,1.32,6.73],[2,1.31,27.87]],"ltp":3.0,"tv":160.8,"id":71847983}]}]}
{"op":"mcm","clk":"11791862003","pt":1723052247301,"mc":[{"id":"1.231540926","rc":[{"batb":[[0,1.33,10]],"ltp":3.0,"tv":160.8,"id":71847983}]}]}
{"op":"mcm","clk":"11791862151","pt":1723052248295,"mc":[{"id":"1.231540926","rc":[{"batb":[[0,1.32,6.73],[1,1.31,27.87],[2,1.28,10]],"ltp":3.0,"tv":160.8,"id":71847983}]}]}
{"op":"mcm","clk":"11791949150","pt":1723052754628,"mc":[{"id":"1.231540926","rc":[{"batb":[[0,1.33,14],[1,1.32,6.73]],"ltp":3.0,"tv":160.8,"id":71847983},{"batb":[[0,1.26,10],[1,1.25,100],[2,1.19,20]],"ltp":1.5,"tv":158.73,"id":19144236}]}]}
{"op":"mcm","clk":"11791949529","pt":1723052756827,"mc":[{"id":"1.231540926","rc":[{"batb":[[0,1.33,10]],"ltp":3.0,"tv":160.8,"id":71847983}]}]}
{"op":"mcm","clk":"11791949687","pt":1723052757725,"mc":[{"id":"1.231540926","rc":[{"batb":[[0,1.32,6.73],[1,1.28,10],[2,1.25,100]],"ltp":3.0,"tv":160.8,"id":71847983}]}]}
{"op":"mcm","clk":"11791972967","pt":1723052919307,"mc":[{"id":"1.231540926","rc":[{"batb":[[0,1.33,26.18],[1,1.32,6.73],[2,1.28,10]],"ltp":3.0,"tv":160.8,"id":71847983},{"batb":[[0,1.51,16.94],[1,1.26,10],[2,1.25,100]],"ltp":1.5,"tv":158.73,"id":19144236}]}]}
{"op":"mcm","clk":"11792114918","pt":1723053917773,"mc":[{"id":"1.231540926","rc":[{"trd":[[1.35,2.11],[1.5,158.82]],"batb":[[0,1.34,14],[1,1.33,26.2],[2,1.32,6.73]],"ltp":3.0,"tv":160.96,"id":71847983},{"trd":[[1.5,158.89]],"batb":[[0,1.51,16.95]],"ltp":1.5,"tv":158.89,"id":19144236}],"tv":319.85}]}
{"op":"mcm","clk":"11792115246","pt":1723053919980,"mc":[{"id":"1.231540926","rc":[{"batb":[[0,1.34,10]],"ltp":3.0,"tv":160.96,"id":71847983}]}]}
{"op":"mcm","clk":"11792115431","pt":1723053921085,"mc":[{"id":"1.231540926","rc":[{"batb":[[0,1.33,26.2],[1,1.32,6.73],[2,1.28,10]],"ltp":3.0,"tv":160.96,"id":71847983}]}]}
{"op":"mcm","clk":"11792146012","pt":1723054090099,"mc":[{"id":"1.231540926","rc":[{"batb":[[0,1.34,20.73],[1,1.33,26.2]],"ltp":3.0,"tv":160.96,"id":71847983}]}]}
{"op":"mcm","clk":"11792146414","pt":1723054092273,"mc":[{"id":"1.231540926","rc":[{"batb":[[0,1.34,16.73]],"ltp":3.0,"tv":160.96,"id":71847983}]}]}
{"op":"mcm","clk":"11792146625","pt":1723054093265,"mc":[{"id":"1.231540926","rc":[{"batb":[[0,1.34,6.73]],"ltp":3.0,"tv":160.96,"id":71847983}]}]}
{"op":"mcm","clk":"11792158414","pt":1723054156262,"mc":[{"id":"1.231540926","rc":[{"batb":[[0,1.35,14],[1,1.34,6.73],[2,1.33,26.2]],"ltp":3.0,"tv":160.96,"id":71847983}]}]}
{"op":"mcm","clk":"11792158950","pt":1723054158961,"mc":[{"id":"1.231540926","rc":[{"batb":[[0,1.35,10]],"ltp":3.0,"tv":160.96,"id":71847983}]}]}
{"op":"mcm","clk":"11792159154","pt":1723054159966,"mc":[{"id":"1.231540926","rc":[{"batb":[[0,1.34,6.73],[1,1.33,26.2],[2,1.28,10]],"ltp":3.0,"tv":160.96,"id":71847983}]}]}
{"op":"mcm","clk":"11792256141","pt":1723054719735,"mc":[{"id":"1.231540926","rc":[{"batb":[[0,1.35,14],[1,1.34,6.73]],"ltp":3.0,"tv":160.96,"id":71847983},{"batb":[[0,1.26,10],[1,1.25,100],[2,1.19,20]],"ltp":1.5,"tv":158.89,"id":19144236}]}]}
{"op":"mcm","clk":"11792256604","pt":1723054722101,"mc":[{"id":"1.231540926","rc":[{"batb":[[0,1.35,10]],"ltp":3.0,"tv":160.96,"id":71847983}]}]}
{"op":"mcm","clk":"11792256789","pt":1723054723115,"mc":[{"id":"1.231540926","rc":[{"batb":[[0,1.34,6.73],[1,1.28,10],[2,1.25,100]],"ltp":3.0,"tv":160.96,"id":71847983}]}]}
{"op":"mcm","clk":"11792262689","pt":1723054759041,"mc":[{"id":"1.231540926","rc":[{"batb":[[0,1.35,14],[1,1.34,6.73],[2,1.28,10]],"ltp":3.0,"tv":160.96,"id":71847983}]}]}
{"op":"mcm","clk":"11792263098","pt":1723054761657,"mc":[{"id":"1.231540926","rc":[{"batb":[[0,1.35,10]],"ltp":3.0,"tv":160.96,"id":71847983}]}]}
{"op":"mcm","clk":"11792263234","pt":1723054762554,"mc":[{"id":"1.231540926","rc":[{"batb":[[0,1.34,6.73],[1,1.28,10],[2,1.25,100]],"ltp":3.0,"tv":160.96,"id":71847983}]}]}
{"op":"mcm","clk":"11792279909","pt":1723054863861,"mc":[{"id":"1.231540926","rc":[{"batb":[[0,1.36,14],[1,1.35,24.71],[2,1.34,6.73]],"ltp":3.0,"tv":160.96,"id":71847983},{"batb":[[0,1.51,16.95],[1,1.26,10],[2,1.25,100]],"ltp":1.5,"tv":158.89,"id":19144236}]}]}
{"op":"mcm","clk":"11792280329","pt":1723054866296,"mc":[{"id":"1.231540926","rc":[{"batb":[[0,1.36,10]],"ltp":3.0,"tv":160.96,"id":71847983}]}]}
{"op":"mcm","clk":"11792280480","pt":1723054867223,"mc":[{"id":"1.231540926","rc":[{"batb":[[0,1.35,24.71],[1,1.34,6.73],[2,1.28,10]],"ltp":3.0,"tv":160.96,"id":71847983}]}]}
{"op":"mcm","clk":"11792382967","pt":1723055492242,"mc":[{"id":"1.231540926","rc":[{"batb":[[0,1.36,14],[1,1.35,24.71],[2,1.34,6.73]],"ltp":3.0,"tv":160.96,"id":71847983}]}]}
{"op":"mcm","clk":"11792383396","pt":1723055495363,"mc":[{"id":"1.231540926","rc":[{"batb":[[0,1.36,10]],"ltp":3.0,"tv":160.96,"id":71847983}]}]}
{"op":"mcm","clk":"11792383537","pt":1723055496362,"mc":[{"id":"1.231540926","rc":[{"batb":[[0,1.35,24.71],[1,1.34,6.73],[2,1.28,10]],"ltp":3.0,"tv":160.96,"id":71847983}]}]}
{"op":"mcm","clk":"11792399240","pt":1723055603102,"mc":[{"id":"1.231540926","rc":[{"batb":[[0,1.36,14],[1,1.35,24.71]],"ltp":3.0,"tv":160.96,"id":71847983}]}]}
{"op":"mcm","clk":"11792399581","pt":1723055605301,"mc":[{"id":"1.231540926","rc":[{"batb":[[0,1.36,10]],"ltp":3.0,"tv":160.96,"id":71847983}]}]}
{"op":"mcm","clk":"11792399736","pt":1723055606300,"mc":[{"id":"1.231540926","rc":[{"batb":[[0,1.35,24.71],[1,1.28,10],[2,1.26,6.73]],"ltp":3.0,"tv":160.96,"id":71847983}]}]}
{"op":"mcm","clk":"11792433987","pt":1723055821788,"mc":[{"id":"1.231540926","rc":[{"batb":[[0,1.36,14],[1,1.35,24.71],[2,1.28,10]],"ltp":3.0,"tv":160.96,"id":71847983}]}]}
{"op":"mcm","clk":"11792434364","pt":1723055824101,"mc":[{"id":"1.231540926","rc":[{"batb":[[0,1.36,10]],"ltp":3.0,"tv":160.96,"id":71847983}]}]}
{"op":"mcm","clk":"11792434527","pt":1723055825105,"mc":[{"id":"1.231540926","rc":[{"batb":[[0,1.35,24.71],[1,1.28,10],[2,1.26,6.73]],"ltp":3.0,"tv":160.96,"id":71847983}]}]}
{"op":"mcm","clk":"11792434862","pt":1723055826884,"mc":[{"id":"1.231540926","rc":[{"batb":[[0,1.36,4],[1,1.35,24.71],[2,1.28,10]],"ltp":3.0,"tv":160.96,"id":71847983}]}]}
{"op":"mcm","clk":"11792435265","pt":1723055829509,"mc":[{"id":"1.231540926","rc":[{"batb":[[0,1.36,10]],"ltp":3.0,"tv":160.96,"id":71847983}]}]}
{"op":"mcm","clk":"11792435822","pt":1723055832930,"mc":[{"id":"1.231540926","rc":[{"batb":[[0,1.36,4]],"ltp":3.0,"tv":160.96,"id":71847983}]}]}
{"op":"mcm","clk":"11792436344","pt":1723055836143,"mc":[{"id":"1.231540926","rc":[{"batb":[[0,1.36,10]],"ltp":3.0,"tv":160.96,"id":71847983}]}]}
{"op":"mcm","clk":"11792436897","pt":1723055839707,"mc":[{"id":"1.231540926","rc":[{"batb":[[0,1.36,4]],"ltp":3.0,"tv":160.96,"id":71847983}]}]}
{"op":"mcm","clk":"11792437254","pt":1723055842120,"mc":[{"id":"1.231540926","rc":[{"batb":[[0,1.35,24.71],[1,1.28,10],[2,1.26,6.73]],"ltp":3.0,"tv":160.96,"id":71847983}]}]}
{"op":"mcm","clk":"11792437278","pt":1723055842225,"mc":[{"id":"1.231540926","rc":[{"batb":[[0,1.36,10],[1,1.35,24.71],[2,1.28,10]],"ltp":3.0,"tv":160.96,"id":71847983}]}]}
{"op":"mcm","clk":"11792437895","pt":1723055845845,"mc":[{"id":"1.231540926","rc":[{"batb":[[0,1.36,4]],"ltp":3.0,"tv":160.96,"id":71847983}]}]}
{"op":"mcm","clk":"11792438235","pt":1723055848143,"mc":[{"id":"1.231540926","rc":[{"batb":[[0,1.36,10]],"ltp":3.0,"tv":160.96,"id":71847983}]}]}
{"op":"mcm","clk":"11792438883","pt":1723055851941,"mc":[{"id":"1.231540926","rc":[{"batb":[[0,1.36,4]],"ltp":3.0,"tv":160.96,"id":71847983}]}]}
{"op":"mcm","clk":"11792439321","pt":1723055854622,"mc":[{"id":"1.231540926","rc":[{"batb":[[0,1.36,10]],"ltp":3.0,"tv":160.96,"id":71847983}]}]}
{"op":"mcm","clk":"11792439856","pt":1723055858053,"mc":[{"id":"1.231540926","rc":[{"batb":[[0,1.36,4]],"ltp":3.0,"tv":160.96,"id":71847983}]}]}
{"op":"mcm","clk":"11792440237","pt":1723055860625,"mc":[{"id":"1.231540926","rc":[{"batb":[[0,1.36,10]],"ltp":3.0,"tv":160.96,"id":71847983}]}]}
{"op":"mcm","clk":"11792440728","pt":1723055863924,"mc":[{"id":"1.231540926","rc":[{"batb":[[0,1.36,4]],"ltp":3.0,"tv":160.96,"id":71847983}]}]}
{"op":"mcm","clk":"11792441098","pt":1723055866560,"mc":[{"id":"1.231540926","rc":[{"batb":[[0,1.36,10]],"ltp":3.0,"tv":160.96,"id":71847983}]}]}
{"op":"mcm","clk":"11792441644","pt":1723055869953,"mc":[{"id":"1.231540926","rc":[{"batb":[[0,1.36,4]],"ltp":3.0,"tv":160.96,"id":71847983}]}]}
{"op":"mcm","clk":"11792442025","pt":1723055872157,"mc":[{"id":"1.231540926","rc":[{"batb":[[0,1.35,24.71],[1,1.28,10],[2,1.26,6.73]],"ltp":3.0,"tv":160.96,"id":71847983}]}]}
{"op":"mcm","clk":"11792442064","pt":1723055872364,"mc":[{"id":"1.231540926","rc":[{"batb":[[0,1.36,10],[1,1.35,24.71],[2,1.28,10]],"ltp":3.0,"tv":160.96,"id":71847983}]}]}
{"op":"mcm","clk":"11792442655","pt":1723055875854,"mc":[{"id":"1.231540926","rc":[{"batb":[[0,1.36,4]],"ltp":3.0,"tv":160.96,"id":71847983}]}]}
{"op":"mcm","clk":"11792442993","pt":1723055878157,"mc":[{"id":"1.231540926","rc":[{"batb":[[0,1.36,10]],"ltp":3.0,"tv":160.96,"id":71847983}]}]}
{"op":"mcm","clk":"11792443652","pt":1723055881950,"mc":[{"id":"1.231540926","rc":[{"batb":[[0,1.36,4]],"ltp":3.0,"tv":160.96,"id":71847983}]}]}
{"op":"mcm","clk":"11792444015","pt":1723055884359,"mc":[{"id":"1.231540926","rc":[{"batb":[[0,1.36,10]],"ltp":3.0,"tv":160.96,"id":71847983}]}]}
{"op":"mcm","clk":"11792444606","pt":1723055887847,"mc":[{"id":"1.231540926","rc":[{"batb":[[0,1.36,4]],"ltp":3.0,"tv":160.96,"id":71847983}]}]}
{"op":"mcm","clk":"11792445011","pt":1723055890472,"mc":[{"id":"1.231540926","rc":[{"batb":[[0,1.36,10]],"ltp":3.0,"tv":160.96,"id":71847983}]}]}
{"op":"mcm","clk":"11792445590","pt":1723055893856,"mc":[{"id":"1.231540926","rc":[{"batb":[[0,1.36,4]],"ltp":3.0,"tv":160.96,"id":71847983}]}]}
{"op":"mcm","clk":"11792446019","pt":1723055896602,"mc":[{"id":"1.231540926","rc":[{"batb":[[0,1.36,10]],"ltp":3.0,"tv":160.96,"id":71847983}]}]}
{"op":"mcm","clk":"11792446631","pt":1723055900057,"mc":[{"id":"1.231540926","rc":[{"batb":[[0,1.36,4]],"ltp":3.0,"tv":160.96,"id":71847983}]}]}
{"op":"mcm","clk":"11792447072","pt":1723055902759,"mc":[{"id":"1.231540926","rc":[{"batb":[[0,1.36,10]],"ltp":3.0,"tv":160.96,"id":71847983}]}]}
{"op":"mcm","clk":"11792447669","pt":1723055906375,"mc":[{"id":"1.231540926","rc":[{"batb":[[0,1.36,4]],"ltp":3.0,"tv":160.96,"id":71847983}]}]}
{"op":"mcm","clk":"11792448110","pt":1723055909065,"mc":[{"id":"1.231540926","rc":[{"batb":[[0,1.36,10]],"ltp":3.0,"tv":160.96,"id":71847983}]}]}
{"op":"mcm","clk":"11792448662","pt":1723055912483,"mc":[{"id":"1.231540926","rc":[{"batb":[[0,1.36,4]],"ltp":3.0,"tv":160.96,"id":71847983}]}]}
{"op":"mcm","clk":"11792449057","pt":1723055914897,"mc":[{"id":"1.231540926","rc":[{"batb":[[0,1.36,10]],"ltp":3.0,"tv":160.96,"id":71847983}]}]}
{"op":"mcm","clk":"11792449675","pt":1723055918681,"mc":[{"id":"1.231540926","rc":[{"batb":[[0,1.36,4]],"ltp":3.0,"tv":160.96,"id":71847983}]}]}
{"op":"mcm","clk":"11792450030","pt":1723055921095,"mc":[{"id":"1.231540926","rc":[{"batb":[[0,1.35,24.71],[1,1.28,10],[2,1.26,6.73]],"ltp":3.0,"tv":160.96,"id":71847983}]}]}
{"op":"mcm","clk":"11792450082","pt":1723055921407,"mc":[{"id":"1.231540926","rc":[{"batb":[[0,1.36,10],[1,1.35,24.71],[2,1.28,10]],"ltp":3.0,"tv":160.96,"id":71847983}]}]}
{"op":"mcm","clk":"11792450677","pt":1723055925080,"mc":[{"id":"1.231540926","rc":[{"batb":[[0,1.35,24.71],[1,1.28,10],[2,1.26,6.73]],"ltp":3.0,"tv":160.96,"id":71847983}]}]}
{"op":"mcm","clk":"11792450711","pt":1723055925287,"mc":[{"id":"1.231540926","rc":[{"batb":[[0,1.36,4],[1,1.35,24.71],[2,1.28,10]],"ltp":3.0,"tv":160.96,"id":71847983}]}]}
{"op":"mcm","clk":"11792451088","pt":1723055927700,"mc":[{"id":"1.231540926","rc":[{"batb":[[0,1.36,10]],"ltp":3.0,"tv":160.96,"id":71847983}]}]}
{"op":"mcm","clk":"11792451606","pt":1723055931083,"mc":[{"id":"1.231540926","rc":[{"batb":[[0,1.35,24.71],[1,1.28,10],[2,1.26,6.73]],"ltp":3.0,"tv":160.96,"id":71847983}]}]}
{"op":"mcm","clk":"11792451639","pt":1723055931297,"mc":[{"id":"1.231540926","rc":[{"batb":[[0,1.36,4],[1,1.35,24.71],[2,1.28,10]],"ltp":3.0,"tv":160.96,"id":71847983}]}]}
{"op":"mcm","clk":"11792452158","pt":1723055934399,"mc":[{"id":"1.231540926","rc":[{"batb":[[0,1.36,10]],"ltp":3.0,"tv":160.96,"id":71847983}]}]}
{"op":"mcm","clk":"11792452676","pt":1723055937809,"mc":[{"id":"1.231540926","rc":[{"batb":[[0,1.36,4]],"ltp":3.0,"tv":160.96,"id":71847983}]}]}
{"op":"mcm","clk":"11792453039","pt":1723055940007,"mc":[{"id":"1.231540926","rc":[{"batb":[[0,1.35,24.71],[1,1.28,10],[2,1.26,6.73]],"ltp":3.0,"tv":160.96,"id":71847983}]}]}
{"op":"mcm","clk":"11792453075","pt":1723055940219,"mc":[{"id":"1.231540926","rc":[{"batb":[[0,1.36,10],[1,1.35,24.71],[2,1.28,10]],"ltp":3.0,"tv":160.96,"id":71847983}]}]}
{"op":"mcm","clk":"11792453744","pt":1723055944020,"mc":[{"id":"1.231540926","rc":[{"batb":[[0,1.35,24.71],[1,1.28,10],[2,1.26,6.73]],"ltp":3.0,"tv":160.96,"id":71847983}]}]}
{"op":"mcm","clk":"11792453781","pt":1723055944250,"mc":[{"id":"1.231540926","rc":[{"batb":[[0,1.36,4],[1,1.35,24.71],[2,1.28,10]],"ltp":3.0,"tv":160.96,"id":71847983}]}]}
{"op":"mcm","clk":"11792454220","pt":1723055946724,"mc":[{"id":"1.231540926","rc":[{"batb":[[0,1.36,10]],"ltp":3.0,"tv":160.96,"id":71847983}]}]}
{"op":"mcm","clk":"11792454777","pt":1723055950140,"mc":[{"id":"1.231540926","rc":[{"batb":[[0,1.36,4]],"ltp":3.0,"tv":160.96,"id":71847983}]}]}
{"op":"mcm","clk":"11792455187","pt":1723055952509,"mc":[{"id":"1.231540926","rc":[{"batb":[[0,1.36,10]],"ltp":3.0,"tv":160.96,"id":71847983}]}]}
{"op":"mcm","clk":"11792455798","pt":1723055955938,"mc":[{"id":"1.231540926","rc":[{"batb":[[0,1.36,4]],"ltp":3.0,"tv":160.96,"id":71847983}]}]}
{"op":"mcm","clk":"11792456184","pt":1723055958137,"mc":[{"id":"1.231540926","rc":[{"batb":[[0,1.35,24.71],[1,1.28,10],[2,1.26,6.73]],"ltp":3.0,"tv":160.96,"id":71847983}]}]}
{"op":"mcm","clk":"11792456227","pt":1723055958347,"mc":[{"id":"1.231540926","rc":[{"batb":[[0,1.36,10],[1,1.35,24.71],[2,1.28,10]],"ltp":3.0,"tv":160.96,"id":71847983}]}]}
{"op":"mcm","clk":"11792456844","pt":1723055961723,"mc":[{"id":"1.231540926","rc":[{"batb":[[0,1.36,4]],"ltp":3.0,"tv":160.96,"id":71847983}]}]}
{"op":"mcm","clk":"11792457270","pt":1723055964152,"mc":[{"id":"1.231540926","rc":[{"batb":[[0,1.36,10]],"ltp":3.0,"tv":160.96,"id":71847983}]}]}
{"op":"mcm","clk":"11792457860","pt":1723055967517,"mc":[{"id":"1.231540926","rc":[{"batb":[[0,1.36,4]],"ltp":3.0,"tv":160.96,"id":71847983}]}]}
{"op":"mcm","clk":"11792458296","pt":1723055970037,"mc":[{"id":"1.231540926","rc":[{"batb":[[0,1.36,10]],"ltp":3.0,"tv":160.96,"id":71847983}]}]}
{"op":"mcm","clk":"11792458862","pt":1723055973363,"mc":[{"id":"1.231540926","rc":[{"batb":[[0,1.36,4]],"ltp":3.0,"tv":160.96,"id":71847983}]}]}
{"op":"mcm","clk":"11792459281","pt":1723055975854,"mc":[{"id":"1.231540926","rc":[{"batb":[[0,1.36,10]],"ltp":3.0,"tv":160.96,"id":71847983}]}]}
{"op":"mcm","clk":"11792459854","pt":1723055979361,"mc":[{"id":"1.231540926","rc":[{"batb":[[0,1.36,4]],"ltp":3.0,"tv":160.96,"id":71847983}]}]}
{"op":"mcm","clk":"11792460286","pt":1723055981846,"mc":[{"id":"1.231540926","rc":[{"batb":[[0,1.36,10]],"ltp":3.0,"tv":160.96,"id":71847983}]}]}
{"op":"mcm","clk":"11792460848","pt":1723055985157,"mc":[{"id":"1.231540926","rc":[{"batb":[[0,1.35,24.71],[1,1.28,10],[2,1.26,6.73]],"ltp":3.0,"tv":160.96,"id":71847983}]}]}
{"op":"mcm","clk":"11792460939","pt":1723055985633,"mc":[{"id":"1.231540926","rc":[{"batb":[[0,1.36,4],[1,1.35,24.71],[2,1.28,10]],"ltp":3.0,"tv":160.96,"id":71847983}]}]}
{"op":"mcm","clk":"11792461333","pt":1723055987859,"mc":[{"id":"1.231540926","rc":[{"batb":[[0,1.35,24.71],[1,1.28,10],[2,1.26,6.73]],"ltp":3.0,"tv":160.96,"id":71847983}]}]}
{"op":"mcm","clk":"11792461423","pt":1723055988271,"mc":[{"id":"1.231540926","rc":[{"batb":[[0,1.36,10],[1,1.35,24.71],[2,1.28,10]],"ltp":3.0,"tv":160.96,"id":71847983}]}]}
{"op":"mcm","clk":"11792462025","pt":1723055991843,"mc":[{"id":"1.231540926","rc":[{"batb":[[0,1.36,4]],"ltp":3.0,"tv":160.96,"id":71847983}]}]}
{"op":"mcm","clk":"11792462388","pt":1723055994048,"mc":[{"id":"1.231540926","rc":[{"batb":[[0,1.35,24.71],[1,1.28,10],[2,1.26,6.73]],"ltp":3.0,"tv":160.96,"id":71847983}]}]}
{"op":"mcm","clk":"11792462515","pt":1723055994778,"mc":[{"id":"1.231540926","rc":[{"batb":[[0,1.36,10],[1,1.35,24.71],[2,1.28,10]],"ltp":3.0,"tv":160.96,"id":71847983}]}]}
{"op":"mcm","clk":"11792463063","pt":1723055998082,"mc":[{"id":"1.231540926","rc":[{"batb":[[0,1.36,4]],"ltp":3.0,"tv":160.96,"id":71847983}]}]}
{"op":"mcm","clk":"11792463482","pt":1723056000566,"mc":[{"id":"1.231540926","rc":[{"batb":[[0,1.36,10]],"ltp":3.0,"tv":160.96,"id":71847983}]}]}
{"op":"mcm","clk":"11792464077","pt":1723056003974,"mc":[{"id":"1.231540926","rc":[{"batb":[[0,1.36,4]],"ltp":3.0,"tv":160.96,"id":71847983}]}]}
{"op":"mcm","clk":"11792464546","pt":1723056006483,"mc":[{"id":"1.231540926","rc":[{"batb":[[0,1.36,10]],"ltp":3.0,"tv":160.96,"id":71847983}]}]}
{"op":"mcm","clk":"11792465253","pt":1723056010152,"mc":[{"id":"1.231540926","rc":[{"batb":[[0,1.36,4]],"ltp":3.0,"tv":160.96,"id":71847983}]}]}
{"op":"mcm","clk":"11792465762","pt":1723056012806,"mc":[{"id":"1.231540926","rc":[{"batb":[[0,1.36,10]],"ltp":3.0,"tv":160.96,"id":71847983}]}]}
{"op":"mcm","clk":"11792466383","pt":1723056016058,"mc":[{"id":"1.231540926","rc":[{"batb":[[0,1.35,24.71],[1,1.28,10],[2,1.26,6.73]],"ltp":3.0,"tv":160.96,"id":71847983}]}]}
{"op":"mcm","clk":"11792466408","pt":1723056016164,"mc":[{"id":"1.231540926","rc":[{"batb":[[0,1.36,4],[1,1.35,24.71],[2,1.28,10]],"ltp":3.0,"tv":160.96,"id":71847983}]}]}
{"op":"mcm","clk":"11792466879","pt":1723056018590,"mc":[{"id":"1.231540926","rc":[{"batb":[[0,1.36,10]],"ltp":3.0,"tv":160.96,"id":71847983}]}]}
{"op":"mcm","clk":"11792467492","pt":1723056022005,"mc":[{"id":"1.231540926","rc":[{"batb":[[0,1.36,4]],"ltp":3.0,"tv":160.96,"id":71847983}]}]}
{"op":"mcm","clk":"11792467978","pt":1723056024779,"mc":[{"id":"1.231540926","rc":[{"batb":[[0,1.36,10]],"ltp":3.0,"tv":160.96,"id":71847983}]}]}
{"op":"mcm","clk":"11792468555","pt":1723056027969,"mc":[{"id":"1.231540926","rc":[{"batb":[[0,1.35,24.71],[1,1.28,10],[2,1.26,6.73]],"ltp":3.0,"tv":160.96,"id":71847983}]}]}
{"op":"mcm","clk":"11792468584","pt":1723056028179,"mc":[{"id":"1.231540926","rc":[{"batb":[[0,1.36,4],[1,1.35,24.71],[2,1.28,10]],"ltp":3.0,"tv":160.96,"id":71847983}]}]}
{"op":"mcm","clk":"11792469024","pt":1723056030620,"mc":[{"id":"1.231540926","rc":[{"batb":[[0,1.36,10]],"ltp":3.0,"tv":160.96,"id":71847983}]}]}
{"op":"mcm","clk":"11792469607","pt":1723056033893,"mc":[{"id":"1.231540926","rc":[{"batb":[[0,1.36,4]],"ltp":3.0,"tv":160.96,"id":71847983}]}]}
{"op":"mcm","clk":"11792470053","pt":1723056036590,"mc":[{"id":"1.231540926","rc":[{"batb":[[0,1.36,10]],"ltp":3.0,"tv":160.96,"id":71847983}]}]}
{"op":"mcm","clk":"11792470589","pt":1723056039926,"mc":[{"id":"1.231540926","rc":[{"batb":[[0,1.35,24.71],[1,1.28,10],[2,1.26,6.73]],"ltp":3.0,"tv":160.96,"id":71847983}]}]}
{"op":"mcm","clk":"11792470631","pt":1723056040191,"mc":[{"id":"1.231540926","rc":[{"batb":[[0,1.36,4],[1,1.35,24.71],[2,1.28,10]],"ltp":3.0,"tv":160.96,"id":71847983}]}]}
{"op":"mcm","clk":"11792471051","pt":1723056042931,"mc":[{"id":"1.231540926","rc":[{"batb":[[0,1.36,10]],"ltp":3.0,"tv":160.96,"id":71847983}]}]}
{"op":"mcm","clk":"11792471733","pt":1723056046823,"mc":[{"id":"1.231540926","rc":[{"batb":[[0,1.36,4]],"ltp":3.0,"tv":160.96,"id":71847983}]}]}
{"op":"mcm","clk":"11792472225","pt":1723056049715,"mc":[{"id":"1.231540926","rc":[{"batb":[[0,1.36,10]],"ltp":3.0,"tv":160.96,"id":71847983}]}]}
{"op":"mcm","clk":"11792472797","pt":1723056053026,"mc":[{"id":"1.231540926","rc":[{"batb":[[0,1.36,4]],"ltp":3.0,"tv":160.96,"id":71847983}]}]}
{"op":"mcm","clk":"11792473184","pt":1723056055397,"mc":[{"id":"1.231540926","rc":[{"batb":[[0,1.36,10]],"ltp":3.0,"tv":160.96,"id":71847983}]}]}
{"op":"mcm","clk":"11792473774","pt":1723056058714,"mc":[{"id":"1.231540926","rc":[{"batb":[[0,1.36,4]],"ltp":3.0,"tv":160.96,"id":71847983}]}]}
{"op":"mcm","clk":"11792474116","pt":1723056060946,"mc":[{"id":"1.231540926","rc":[{"batb":[[0,1.35,24.71],[1,1.28,10],[2,1.26,6.73]],"ltp":3.0,"tv":160.96,"id":71847983}]}]}
{"op":"mcm","clk":"11792474172","pt":1723056061213,"mc":[{"id":"1.231540926","rc":[{"batb":[[0,1.36,10],[1,1.35,24.71],[2,1.28,10]],"ltp":3.0,"tv":160.96,"id":71847983}]}]}
{"op":"mcm","clk":"11792474788","pt":1723056064542,"mc":[{"id":"1.231540926","rc":[{"batb":[[0,1.36,4]],"ltp":3.0,"tv":160.96,"id":71847983}]}]}
{"op":"mcm","clk":"11792475240","pt":1723056067132,"mc":[{"id":"1.231540926","rc":[{"batb":[[0,1.36,10]],"ltp":3.0,"tv":160.96,"id":71847983}]}]}
{"op":"mcm","clk":"11792475859","pt":1723056070655,"mc":[{"id":"1.231540926","rc":[{"batb":[[0,1.36,4]],"ltp":3.0,"tv":160.96,"id":71847983}]}]}
{"op":"mcm","clk":"11792476305","pt":1723056073122,"mc":[{"id":"1.231540926","rc":[{"batb":[[0,1.36,10]],"ltp":3.0,"tv":160.96,"id":71847983}]}]}
{"op":"mcm","clk":"11792476916","pt":1723056076525,"mc":[{"id":"1.231540926","rc":[{"batb":[[0,1.36,4]],"ltp":3.0,"tv":160.96,"id":71847983}]}]}
{"op":"mcm","clk":"11792477338","pt":1723056079042,"mc":[{"id":"1.231540926","rc":[{"batb":[[0,1.36,10]],"ltp":3.0,"tv":160.96,"id":71847983}]}]}
{"op":"mcm","clk":"11792477985","pt":1723056082452,"mc":[{"id":"1.231540926","rc":[{"batb":[[0,1.36,4]],"ltp":3.0,"tv":160.96,"id":71847983}]}]}
{"op":"mcm","clk":"11792478430","pt":1723056084868,"mc":[{"id":"1.231540926","rc":[{"batb":[[0,1.36,10]],"ltp":3.0,"tv":160.96,"id":71847983}]}]}
{"op":"mcm","clk":"11792479156","pt":1723056088485,"mc":[{"id":"1.231540926","rc":[{"batb":[[0,1.36,4]],"ltp":3.0,"tv":160.96,"id":71847983}]}]}
{"op":"mcm","clk":"11792479593","pt":1723056090954,"mc":[{"id":"1.231540926","rc":[{"batb":[[0,1.36,10]],"ltp":3.0,"tv":160.96,"id":71847983}]}]}
{"op":"mcm","clk":"11792480222","pt":1723056094376,"mc":[{"id":"1.231540926","rc":[{"batb":[[0,1.36,4]],"ltp":3.0,"tv":160.96,"id":71847983}]}]}
{"op":"mcm","clk":"11792480667","pt":1723056096895,"mc":[{"id":"1.231540926","rc":[{"batb":[[0,1.36,10]],"ltp":3.0,"tv":160.96,"id":71847983}]}]}
{"op":"mcm","clk":"11792481281","pt":1723056100095,"mc":[{"id":"1.231540926","rc":[{"batb":[[0,1.35,24.71],[1,1.28,10],[2,1.26,6.73]],"ltp":3.0,"tv":160.96,"id":71847983}]}]}
{"op":"mcm","clk":"11792481319","pt":1723056100307,"mc":[{"id":"1.231540926","rc":[{"batb":[[0,1.36,4],[1,1.35,24.71],[2,1.28,10]],"ltp":3.0,"tv":160.96,"id":71847983}]}]}
{"op":"mcm","clk":"11792481816","pt":1723056102793,"mc":[{"id":"1.231540926","rc":[{"batb":[[0,1.36,10]],"ltp":3.0,"tv":160.96,"id":71847983}]}]}
{"op":"mcm","clk":"11792482503","pt":1723056106315,"mc":[{"id":"1.231540926","rc":[{"batb":[[0,1.36,4]],"ltp":3.0,"tv":160.96,"id":71847983}]}]}
{"op":"mcm","clk":"11792483021","pt":1723056109098,"mc":[{"id":"1.231540926","rc":[{"batb":[[0,1.36,10]],"ltp":3.0,"tv":160.96,"id":71847983}]}]}
{"op":"mcm","clk":"11792483603","pt":1723056112509,"mc":[{"id":"1.231540926","rc":[{"batb":[[0,1.36,4]],"ltp":3.0,"tv":160.96,"id":71847983}]}]}
{"op":"mcm","clk":"11792484050","pt":1723056115157,"mc":[{"id":"1.231540926","rc":[{"batb":[[0,1.36,10]],"ltp":3.0,"tv":160.96,"id":71847983}]}]}
{"op":"mcm","clk":"11792484629","pt":1723056118658,"mc":[{"id":"1.231540926","rc":[{"batb":[[0,1.36,4]],"ltp":3.0,"tv":160.96,"id":71847983}]}]}
{"op":"mcm","clk":"11792485135","pt":1723056121642,"mc":[{"id":"1.231540926","rc":[{"batb":[[0,1.36,10]],"ltp":3.0,"tv":160.96,"id":71847983}]}]}
{"op":"mcm","clk":"11792485727","pt":1723056125045,"mc":[{"id":"1.231540926","rc":[{"batb":[[0,1.36,4]],"ltp":3.0,"tv":160.96,"id":71847983}]}]}
{"op":"mcm","clk":"11792486209","pt":1723056127546,"mc":[{"id":"1.231540926","rc":[{"batb":[[0,1.36,10]],"ltp":3.0,"tv":160.96,"id":71847983}]}]}
{"op":"mcm","clk":"11792486752","pt":1723056130949,"mc":[{"id":"1.231540926","rc":[{"batb":[[0,1.35,24.71],[1,1.28,10],[2,1.26,6.73]],"ltp":3.0,"tv":160.96,"id":71847983}]}]}
{"op":"mcm","clk":"11792486789","pt":1723056131205,"mc":[{"id":"1.231540926","rc":[{"batb":[[0,1.36,4],[1,1.35,24.71],[2,1.28,10]],"ltp":3.0,"tv":160.96,"id":71847983}]}]}
{"op":"mcm","clk":"11792487199","pt":1723056133957,"mc":[{"id":"1.231540926","rc":[{"batb":[[0,1.36,10]],"ltp":3.0,"tv":160.96,"id":71847983}]}]}
{"op":"mcm","clk":"11792487748","pt":1723056137652,"mc":[{"id":"1.231540926","rc":[{"batb":[[0,1.36,4]],"ltp":3.0,"tv":160.96,"id":71847983}]}]}
{"op":"mcm","clk":"11792488095","pt":1723056140111,"mc":[{"id":"1.231540926","rc":[{"batb":[[0,1.36,10]],"ltp":3.0,"tv":160.96,"id":71847983}]}]}
{"op":"mcm","clk":"11792488686","pt":1723056143885,"mc":[{"id":"1.231540926","rc":[{"batb":[[0,1.36,4]],"ltp":3.0,"tv":160.96,"id":71847983}]}]}
{"op":"mcm","clk":"11792489061","pt":1723056146375,"mc":[{"id":"1.231540926","rc":[{"batb":[[0,1.36,10]],"ltp":3.0,"tv":160.96,"id":71847983}]}]}
{"op":"mcm","clk":"11792489564","pt":1723056149610,"mc":[{"id":"1.231540926","rc":[{"batb":[[0,1.35,24.71],[1,1.28,10],[2,1.26,6.73]],"ltp":3.0,"tv":160.96,"id":71847983}]}]}
{"op":"mcm","clk":"11792489643","pt":1723056150184,"mc":[{"id":"1.231540926","rc":[{"batb":[[0,1.36,4],[1,1.35,24.71],[2,1.28,10]],"ltp":3.0,"tv":160.96,"id":71847983}]}]}
{"op":"mcm","clk":"11792490079","pt":1723056152781,"mc":[{"id":"1.231540926","rc":[{"batb":[[0,1.36,10]],"ltp":3.0,"tv":160.96,"id":71847983}]}]}
{"op":"mcm","clk":"11792490636","pt":1723056156285,"mc":[{"id":"1.231540926","rc":[{"batb":[[0,1.36,4]],"ltp":3.0,"tv":160.96,"id":71847983}]}]}
{"op":"mcm","clk":"11792491138","pt":1723056159007,"mc":[{"id":"1.231540926","rc":[{"batb":[[0,1.36,10]],"ltp":3.0,"tv":160.96,"id":71847983}]}]}
{"op":"mcm","clk":"11792491744","pt":1723056162738,"mc":[{"id":"1.231540926","rc":[{"batb":[[0,1.36,4]],"ltp":3.0,"tv":160.96,"id":71847983}]}]}
{"op":"mcm","clk":"11792492110","pt":1723056165104,"mc":[{"id":"1.231540926","rc":[{"batb":[[0,1.35,24.71],[1,1.28,10],[2,1.26,6.73]],"ltp":3.0,"tv":160.96,"id":71847983}]}]}
{"op":"mcm","clk":"11792492125","pt":1723056165203,"mc":[{"id":"1.231540926","rc":[{"batb":[[0,1.36,10],[1,1.35,24.71],[2,1.28,10]],"ltp":3.0,"tv":160.96,"id":71847983}]}]}
{"op":"mcm","clk":"11792492518","pt":1723056167714,"mc":[{"id":"1.231540926","rc":[{"batb":[[0,1.37,4],[1,1.36,10],[2,1.35,24.71]],"ltp":3.0,"tv":160.96,"id":71847983}]}]}
{"op":"mcm","clk":"11792492649","pt":1723056168399,"mc":[{"id":"1.231540926","rc":[{"batb":[[1,1.35,24.71],[2,1.28,10]],"ltp":3.0,"tv":160.96,"id":71847983}]}]}
{"op":"mcm","clk":"11792492941","pt":1723056170191,"mc":[{"id":"1.231540926","rc":[{"batb":[[0,1.35,24.71],[1,1.28,10],[2,1.26,6.73]],"ltp":3.0,"tv":160.96,"id":71847983}]}]}
{"op":"mcm","clk":"11792538017","pt":1723056471121,"mc":[{"id":"1.231540926","rc":[{"batb":[[0,1.36,14],[1,1.35,24.71],[2,1.28,10]],"ltp":3.0,"tv":160.96,"id":71847983}]}]}
{"op":"mcm","clk":"11792538354","pt":1723056473434,"mc":[{"id":"1.231540926","rc":[{"batb":[[0,1.36,10]],"ltp":3.0,"tv":160.96,"id":71847983}]}]}
{"op":"mcm","clk":"11792538500","pt":1723056474422,"mc":[{"id":"1.231540926","rc":[{"batb":[[0,1.35,24.71],[1,1.28,10],[2,1.26,6.73]],"ltp":3.0,"tv":160.96,"id":71847983}]}]}
{"op":"mcm","clk":"11792555034","pt":1723056596878,"mc":[{"id":"1.231540926","rc":[{"batb":[[0,1.36,14],[1,1.35,24.71],[2,1.28,10]],"ltp":3.0,"tv":160.96,"id":71847983}]}]}
{"op":"mcm","clk":"11792555376","pt":1723056599376,"mc":[{"id":"1.231540926","rc":[{"batb":[[0,1.36,10]],"ltp":3.0,"tv":160.96,"id":71847983}]}]}
{"op":"mcm","clk":"11792555481","pt":1723056600162,"mc":[{"id":"1.231540926","rc":[{"batb":[[0,1.35,24.71],[1,1.28,10],[2,1.26,6.73]],"ltp":3.0,"tv":160.96,"id":71847983}]}]}
{"op":"mcm","clk":"11792561463","pt":1723056643924,"mc":[{"id":"1.231540926","rc":[{"batb":[[0,1.36,14],[1,1.35,24.71],[2,1.28,10]],"ltp":3.0,"tv":160.96,"id":71847983}]}]}
{"op":"mcm","clk":"11792561805","pt":1723056646249,"mc":[{"id":"1.231540926","rc":[{"batb":[[0,1.36,10]],"ltp":3.0,"tv":160.96,"id":71847983}]}]}
{"op":"mcm","clk":"11792561948","pt":1723056647423,"mc":[{"id":"1.231540926","rc":[{"batb":[[0,1.35,24.71],[1,1.28,10],[2,1.26,6.73]],"ltp":3.0,"tv":160.96,"id":71847983}]}]}
{"op":"mcm","clk":"11792564071","pt":1723056663837,"mc":[{"id":"1.231540926","rc":[{"batb":[[0,1.29,14]],"ltp":3.0,"tv":160.96,"id":71847983},{"batb":[[0,1.26,10],[1,1.25,100],[2,1.19,20]],"ltp":1.5,"tv":158.89,"id":19144236}]}]}
{"op":"mcm","clk":"11792564358","pt":1723056666136,"mc":[{"id":"1.231540926","rc":[{"batb":[[0,1.29,10]],"ltp":3.0,"tv":160.96,"id":71847983}]}]}
{"op":"mcm","clk":"11792564469","pt":1723056667127,"mc":[{"id":"1.231540926","rc":[{"batb":[[0,1.28,10],[1,1.26,6.73],[2,1.25,100]],"ltp":3.0,"tv":160.96,"id":71847983}]}]}
{"op":"mcm","clk":"11792578704","pt":1723056788642,"mc":[{"id":"1.231540926","rc":[{"batb":[[0,1.29,29.82],[1,1.28,10],[2,1.26,6.73]],"ltp":3.0,"tv":160.96,"id":71847983},{"batb":[[0,1.51,16.95],[1,1.26,10],[2,1.25,100]],"ltp":1.5,"tv":158.89,"id":19144236}]}]}
{"op":"mcm","clk":"11792616103","pt":1723057119328,"mc":[{"id":"1.231540926","rc":[{"batb":[[0,1.3,6.73],[1,1.29,29.82],[2,1.28,10]],"ltp":3.0,"tv":160.96,"id":71847983}]}]}
{"op":"mcm","clk":"11792655797","pt":1723057497879,"mc":[{"id":"1.231540926","rc":[{"trd":[[1.3,0.14],[1.5,158.95]],"batb":[[0,1.31,14],[1,1.3,6.67],[2,1.29,29.83]],"batl":[[0,3,1.02]],"ltp":1.3,"tv":161.22,"id":71847983},{"trd":[[1.5,159.02]],"batb":[[0,1.51,16.96]],"ltp":1.5,"tv":159.01,"id":19144236}],"tv":320.24}]}
{"op":"mcm","clk":"11792656161","pt":1723057501093,"mc":[{"id":"1.231540926","rc":[{"batb":[[0,1.3,6.67],[1,1.29,29.83],[2,1.28,10]],"ltp":1.3,"tv":161.22,"id":71847983}]}]}
{"op":"mcm","clk":"11792662630","pt":1723057553154,"mc":[{"id":"1.231540926","rc":[{"batb":[[0,1.31,14],[1,1.3,6.67],[2,1.29,29.83]],"ltp":1.3,"tv":161.22,"id":71847983}]}]}
{"op":"mcm","clk":"11792663010","pt":1723057556261,"mc":[{"id":"1.231540926","rc":[{"batb":[[0,1.31,10]],"ltp":1.3,"tv":161.22,"id":71847983}]}]}
{"op":"mcm","clk":"11792663137","pt":1723057557263,"mc":[{"id":"1.231540926","rc":[{"batb":[[0,1.3,6.67],[1,1.29,29.83],[2,1.28,10]],"ltp":1.3,"tv":161.22,"id":71847983}]}]}
{"op":"mcm","clk":"11792744713","pt":1723058143298,"mc":[{"id":"1.231540926","rc":[{"batb":[[0,1.31,14],[1,1.3,6.67],[2,1.29,29.83]],"ltp":1.3,"tv":161.22,"id":71847983}]}]}
{"op":"mcm","clk":"11792745159","pt":1723058146770,"mc":[{"id":"1.231540926","rc":[{"batb":[[0,1.31,10]],"ltp":1.3,"tv":161.22,"id":71847983}]}]}
{"op":"mcm","clk":"11792745305","pt":1723058147760,"mc":[{"id":"1.231540926","rc":[{"batb":[[0,1.3,6.67],[1,1.29,29.83],[2,1.28,10]],"ltp":1.3,"tv":161.22,"id":71847983}]}]}
{"op":"mcm","clk":"11792791455","pt":1723058589096,"mc":[{"id":"1.231540926","rc":[{"batb":[[1,1.28,10],[2,1.25,100]],"ltp":1.3,"tv":161.22,"id":71847983},{"batb":[[0,1.26,10],[1,1.25,100],[2,1.19,20]],"ltp":1.5,"tv":159.01,"id":19144236}]}]}
{"op":"mcm","clk":"11792791477","pt":1723058589413,"mc":[{"id":"1.231540926","rc":[{"batb":[[0,1.31,14],[1,1.3,6.67],[2,1.28,10]],"ltp":1.3,"tv":161.22,"id":71847983}]}]}
{"op":"mcm","clk":"11792791713","pt":1723058591718,"mc":[{"id":"1.231540926","rc":[{"batb":[[0,1.31,10]],"ltp":1.3,"tv":161.22,"id":71847983}]}]}
{"op":"mcm","clk":"11792791815","pt":1723058592819,"mc":[{"id":"1.231540926","rc":[{"batb":[[0,1.3,6.67],[1,1.28,10],[2,1.25,100]],"ltp":1.3,"tv":161.22,"id":71847983}]}]}
{"op":"mcm","clk":"11792798536","pt":1723058663896,"mc":[{"id":"1.231540926","rc":[{"batb":[[0,1.29,14],[2,1.26,6.67]],"ltp":1.3,"tv":161.22,"id":71847983}]}]}
{"op":"mcm","clk":"11792798775","pt":1723058666291,"mc":[{"id":"1.231540926","rc":[{"batb":[[0,1.29,10]],"ltp":1.3,"tv":161.22,"id":71847983}]}]}
{"op":"mcm","clk":"11792798872","pt":1723058667181,"mc":[{"id":"1.231540926","rc":[{"batb":[[0,1.28,10],[1,1.26,6.67],[2,1.25,100]],"ltp":1.3,"tv":161.22,"id":71847983}]}]}
{"op":"mcm","clk":"11792800301","pt":1723058682085,"mc":[{"id":"1.231540926","rc":[{"batb":[[0,1.29,29.83],[1,1.28,10],[2,1.26,6.67]],"ltp":1.3,"tv":161.22,"id":71847983},{"batb":[[0,1.51,16.96],[1,1.26,10],[2,1.25,100]],"ltp":1.5,"tv":159.01,"id":19144236}]}]}
{"op":"mcm","clk":"11792800325","pt":1723058682294,"mc":[{"id":"1.231540926","rc":[{"batb":[[0,1.3,14],[1,1.29,29.83],[2,1.28,10]],"ltp":1.3,"tv":161.22,"id":71847983}]}]}
{"op":"mcm","clk":"11792800540","pt":1723058684987,"mc":[{"id":"1.231540926","rc":[{"batb":[[0,1.3,10]],"ltp":1.3,"tv":161.22,"id":71847983}]}]}
{"op":"mcm","clk":"11792800629","pt":1723058685918,"mc":[{"id":"1.231540926","rc":[{"batb":[[0,1.29,29.83],[1,1.28,10],[2,1.26,6.67]],"ltp":1.3,"tv":161.22,"id":71847983}]}]}
{"op":"mcm","clk":"11792863657","pt":1723059351785,"mc":[{"id":"1.231540926","rc":[{"batb":[[0,1.3,14],[1,1.29,29.83],[2,1.28,10]],"ltp":1.3,"tv":161.22,"id":71847983}]}]}
{"op":"mcm","clk":"11792863882","pt":1723059354381,"mc":[{"id":"1.231540926","rc":[{"batb":[[0,1.3,10]],"ltp":1.3,"tv":161.22,"id":71847983}]}]}
{"op":"mcm","clk":"11792863972","pt":1723059355516,"mc":[{"id":"1.231540926","rc":[{"batb":[[0,1.29,29.83],[1,1.28,10],[2,1.26,6.67]],"ltp":1.3,"tv":161.22,"id":71847983}]}]}
{"op":"mcm","clk":"11792872046","pt":1723059443999,"mc":[{"id":"1.231540926","rc":[{"batb":[[0,1.3,20.67],[1,1.29,29.83],[2,1.28,10]],"ltp":1.3,"tv":161.22,"id":71847983}]}]}
{"op":"mcm","clk":"11792872249","pt":1723059446180,"mc":[{"id":"1.231540926","rc":[{"batb":[[0,1.3,16.67]],"ltp":1.3,"tv":161.22,"id":71847983}]}]}
{"op":"mcm","clk":"11792872331","pt":1723059447170,"mc":[{"id":"1.231540926","rc":[{"batb":[[0,1.3,6.67]],"ltp":1.3,"tv":161.22,"id":71847983}]}]}
{"op":"mcm","clk":"11792887043","pt":1723059603048,"mc":[{"id":"1.231540926","rc":[{"batb":[[0,1.31,14],[1,1.3,6.67],[2,1.29,29.83]],"ltp":1.3,"tv":161.22,"id":71847983}]}]}
{"op":"mcm","clk":"11792887353","pt":1723059606026,"mc":[{"id":"1.231540926","rc":[{"batb":[[0,1.31,10]],"ltp":1.3,"tv":161.22,"id":71847983}]}]}
{"op":"mcm","clk":"11792887462","pt":1723059607164,"mc":[{"id":"1.231540926","rc":[{"batb":[[0,1.3,6.67],[1,1.29,29.83],[2,1.28,10]],"ltp":1.3,"tv":161.22,"id":71847983}]}]}
{"op":"mcm","clk":"11792903787","pt":1723059775086,"mc":[{"id":"1.231540926","rc":[{"batb":[[0,1.31,24],[1,1.3,6.67],[2,1.29,29.83]],"ltp":1.3,"tv":161.22,"id":71847983}]}]}
{"op":"mcm","clk":"11792904149","pt":1723059778050,"mc":[{"id":"1.231540926","rc":[{"batb":[[0,1.31,10]],"ltp":1.3,"tv":161.22,"id":71847983}]}]}
{"op":"mcm","clk":"11792940714","pt":1723060161877,"mc":[{"id":"1.231540926","rc":[{"batl":[[0,1.38,2.8],[1,3,1.02]],"ltp":1.3,"tv":161.22,"id":71847983}]}]}
{"op":"mcm","clk":"11792941970","pt":1723060174355,"mc":[{"id":"1.231540926","rc":[{"batb":[[0,1.32,14],[1,1.31,10],[2,1.3,6.67]],"batl":[[0,3,1.02],[1,3,0]],"ltp":1.3,"tv":161.22,"id":71847983}]}]}
{"op":"mcm","clk":"11792942165","pt":1723060176783,"mc":[{"id":"1.231540926","rc":[{"batb":[[0,1.32,10]],"ltp":1.3,"tv":161.22,"id":71847983}]}]}
{"op":"mcm","clk":"11792942263","pt":1723060177765,"mc":[{"id":"1.231540926","rc":[{"batb":[[0,1.31,10],[1,1.3,6.67],[2,1.29,29.83]],"ltp":1.3,"tv":161.22,"id":71847983}]}]}
{"op":"mcm","clk":"11792943510","pt":1723060190969,"mc":[{"id":"1.231540926","rc":[{"batl":[[0,1.41,2.8],[1,3,1.02]],"ltp":1.3,"tv":161.22,"id":71847983}]}]}
{"op":"mcm","clk":"11792944509","pt":1723060202068,"mc":[{"id":"1.231540926","rc":[{"batl":[[0,3,1.02],[1,3,0]],"ltp":1.3,"tv":161.22,"id":71847983}]}]}
{"op":"mcm","clk":"11792944520","pt":1723060202170,"mc":[{"id":"1.231540926","rc":[{"batb":[[0,1.32,14],[1,1.31,10],[2,1.3,6.67]],"ltp":1.3,"tv":161.22,"id":71847983}]}]}
{"op":"mcm","clk":"11792944743","pt":1723060204364,"mc":[{"id":"1.231540926","rc":[{"batb":[[0,1.32,10]],"ltp":1.3,"tv":161.22,"id":71847983}]}]}
{"op":"mcm","clk":"11792944852","pt":1723060205565,"mc":[{"id":"1.231540926","rc":[{"batb":[[0,1.31,10],[1,1.3,6.67],[2,1.29,29.83]],"ltp":1.3,"tv":161.22,"id":71847983}]}]}
{"op":"mcm","clk":"11792946443","pt":1723060222891,"mc":[{"id":"1.231540926","rc":[{"batl":[[0,1.41,2.8],[1,3,1.02]],"ltp":1.3,"tv":161.22,"id":71847983}]}]}
{"op":"mcm","clk":"11792950007","pt":1723060260894,"mc":[{"id":"1.231540926","rc":[{"batb":[[0,1.51,259.67],[1,1.32,14],[2,1.31,10]],"batl":[[0,3,1.02],[1,3,0]],"ltp":1.3,"tv":161.22,"id":71847983}]}]}
{"op":"mcm","clk":"11792950211","pt":1723060262810,"mc":[{"id":"1.231540926","rc":[{"batb":[[1,1.32,10]],"ltp":1.3,"tv":161.22,"id":71847983}]}]}
{"op":"mcm","clk":"11792950324","pt":1723060263846,"mc":[{"id":"1.231540926","rc":[{"batb":[[0,1.31,10],[1,1.3,6.67],[2,1.29,29.83]],"ltp":1.3,"tv":161.22,"id":71847983}]}]}
{"op":"mcm","clk":"11792951909","pt":1723060279622,"mc":[{"id":"1.231540926","rc":[{"batb":[[0,1.32,14],[1,1.31,10],[2,1.3,6.67]],"ltp":1.3,"tv":161.22,"id":71847983}]}]}
{"op":"mcm","clk":"11792952208","pt":1723060282836,"mc":[{"id":"1.231540926","rc":[{"batb":[[0,1.32,10]],"ltp":1.3,"tv":161.22,"id":71847983}]}]}
{"op":"mcm","clk":"11792952315","pt":1723060283823,"mc":[{"id":"1.231540926","rc":[{"batb":[[0,1.31,10],[1,1.3,6.67],[2,1.29,29.83]],"ltp":1.3,"tv":161.22,"id":71847983}]}]}
{"op":"mcm","clk":"11792954553","pt":1723060303965,"mc":[{"id":"1.231540926","rc":[{"batb":[[0,1.32,14],[1,1.31,10],[2,1.3,6.67]],"ltp":1.3,"tv":161.22,"id":71847983},{"batl":[[0,1.58,1.4]],"ltp":1.5,"tv":159.01,"id":19144236}]}]}
{"op":"mcm","clk":"11792954765","pt":1723060306180,"mc":[{"id":"1.231540926","rc":[{"batb":[[0,1.32,10]],"ltp":1.3,"tv":161.22,"id":71847983}]}]}
{"op":"mcm","clk":"11792954883","pt":1723060307173,"mc":[{"id":"1.231540926","rc":[{"batb":[[0,1.31,10],[1,1.3,6.67],[2,1.29,29.83]],"ltp":1.3,"tv":161.22,"id":71847983}]}]}
{"op":"mcm","clk":"11792955237","pt":1723060310963,"mc":[{"id":"1.231540926","rc":[{"batb":[[0,1.32,14],[1,1.31,10],[2,1.3,6.67]],"ltp":1.3,"tv":161.22,"id":71847983}]}]}
{"op":"mcm","clk":"11792955468","pt":1723060313264,"mc":[{"id":"1.231540926","rc":[{"batb":[[0,1.32,10]],"ltp":1.3,"tv":161.22,"id":71847983}]}]}
{"op":"mcm","clk":"11792955571","pt":1723060314261,"mc":[{"id":"1.231540926","rc":[{"batb":[[0,1.31,10],[1,1.3,6.67],[2,1.29,29.83]],"ltp":1.3,"tv":161.22,"id":71847983}]}]}
{"op":"mcm","clk":"11792957427","pt":1723060336578,"mc":[{"id":"1.231540926","rc":[{"batb":[[0,1.32,14],[1,1.31,10],[2,1.3,6.67]],"ltp":1.3,"tv":161.22,"id":71847983},{"batl":[[0,1.59,2.8]],"ltp":1.5,"tv":159.01,"id":19144236}]}]}
{"op":"mcm","clk":"11792957635","pt":1723060339084,"mc":[{"id":"1.231540926","rc":[{"batb":[[0,1.32,10]],"ltp":1.3,"tv":161.22,"id":71847983}]}]}
{"op":"mcm","clk":"11792957699","pt":1723060339905,"mc":[{"id":"1.231540926","rc":[{"batb":[[0,1.31,10],[1,1.3,6.67],[2,1.29,29.83]],"ltp":1.3,"tv":161.22,"id":71847983}]}]}
{"op":"mcm","clk":"11792959236","pt":1723060359099,"mc":[{"id":"1.231540926","rc":[{"trd":[[2.68,1.56]],"ltp":2.68,"tv":162.78,"id":71847983},{"trd":[[1.59,2.63]],"batl":[[0,1.59,0.17]],"ltp":1.59,"tv":161.64,"id":19144236}],"tv":324.43}]}
{"op":"mcm","clk":"11792959259","pt":1723060359413,"mc":[{"id":"1.231540926","rc":[{"batb":[[0,1.32,14],[1,1.31,10],[2,1.3,6.67]],"ltp":2.68,"tv":162.78,"id":71847983}]}]}
{"op":"mcm","clk":"11792959462","pt":1723060361898,"mc":[{"id":"1.231540926","rc":[{"batb":[[0,1.32,10]],"ltp":2.68,"tv":162.78,"id":71847983}]}]}
{"op":"mcm","clk":"11792959526","pt":1723060362723,"mc":[{"id":"1.231540926","rc":[{"batb":[[0,1.31,10],[1,1.3,6.67],[2,1.29,29.83]],"ltp":2.68,"tv":162.78,"id":71847983}]}]}
{"op":"mcm","clk":"11792960907","pt":1723060380649,"mc":[{"id":"1.231540926","rc":[{"trd":[[1.31,3.08]],"batb":[[0,1.32,14],[1,1.31,8.46],[2,1.3,6.67]],"ltp":1.31,"tv":165.87,"id":71847983}],"tv":327.51}]}
{"op":"mcm","clk":"11792961133","pt":1723060383127,"mc":[{"id":"1.231540926","rc":[{"batb":[[0,1.32,10]],"ltp":1.31,"tv":165.87,"id":71847983}]}]}
{"op":"mcm","clk":"11792961210","pt":1723060383924,"mc":[{"id":"1.231540926","rc":[{"batb":[[0,1.31,8.46],[1,1.3,6.67],[2,1.29,29.83]],"ltp":1.31,"tv":165.87,"id":71847983}]}]}
{"op":"mcm","clk":"11792964415","pt":1723060419669,"mc":[{"id":"1.231540926","rc":[{"batb":[[0,1.71,14],[1,1.7,259.67],[2,1.31,8.46]],"ltp":1.31,"tv":165.87,"id":71847983}]}]}
{"op":"mcm","clk":"11792964630","pt":1723060421873,"mc":[{"id":"1.231540926","rc":[{"batb":[[0,1.71,10]],"ltp":1.31,"tv":165.87,"id":71847983}]}]}
{"op":"mcm","clk":"11792964746","pt":1723060423072,"mc":[{"id":"1.231540926","rc":[{"batb":[[0,1.7,259.67],[1,1.31,8.46],[2,1.3,6.67]],"ltp":1.31,"tv":165.87,"id":71847983}]}]}
{"op":"mcm","clk":"11792965904","pt":1723060435892,"mc":[{"id":"1.231540926","rc":[{"trd":[[1.7,2.54]],"batb":[[0,1.71,14],[1,1.7,258.4],[2,1.31,8.46]],"ltp":1.7,"tv":168.41,"id":71847983}],"tv":330.05}]}
{"op":"mcm","clk":"11792966009","pt":1723060437098,"mc":[{"id":"1.231540926","rc":[{"batb":[[0,1.7,259.67],[1,1.51,16.96],[2,1.26,10]],"ltp":1.59,"tv":161.64,"id":19144236}]}]}
{"op":"mcm","clk":"11792966094","pt":1723060438084,"mc":[{"id":"1.231540926","rc":[{"batb":[[0,1.71,10]],"ltp":1.7,"tv":168.41,"id":71847983}]}]}
{"op":"mcm","clk":"11792966185","pt":1723060439116,"mc":[{"id":"1.231540926","rc":[{"batb":[[0,1.7,258.4],[1,1.31,8.46],[2,1.3,6.67]],"ltp":1.7,"tv":168.41,"id":71847983}]}]}
{"op":"mcm","clk":"11792969081","pt":1723060474335,"mc":[{"id":"1.231540926","rc":[{"batb":[[0,1.32,14]],"ltp":1.7,"tv":168.41,"id":71847983},{"batb":[[0,1.51,16.96],[1,1.26,10],[2,1.25,100]],"ltp":1.59,"tv":161.64,"id":19144236}]}]}
{"op":"mcm","clk":"11792969233","pt":1723060476629,"mc":[{"id":"1.231540926","rc":[{"batb":[[0,1.32,10]],"ltp":1.7,"tv":168.41,"id":71847983}]}]}
{"op":"mcm","clk":"11792969316","pt":1723060477726,"mc":[{"id":"1.231540926","rc":[{"batb":[[0,1.31,8.46],[1,1.3,6.67],[2,1.29,29.83]],"ltp":1.7,"tv":168.41,"id":71847983}]}]}
{"op":"mcm","clk":"11792969680","pt":1723060482615,"mc":[{"id":"1.231540926","rc":[{"batb":[[0,1.32,14],[1,1.31,8.46],[2,1.3,6.67]],"ltp":1.7,"tv":168.41,"id":71847983},{"batb":[[0,1.26,10],[1,1.25,100],[2,1.19,20]],"ltp":1.59,"tv":161.64,"id":19144236}]}]}
{"op":"mcm","clk":"11792969846","pt":1723060485055,"mc":[{"id":"1.231540926","rc":[{"batb":[[0,1.32,10]],"ltp":1.7,"tv":168.41,"id":71847983}]}]}
{"op":"mcm","clk":"11792969904","pt":1723060486045,"mc":[{"id":"1.231540926","rc":[{"batb":[[0,1.31,8.46],[1,1.3,6.67],[2,1.25,100]],"ltp":1.7,"tv":168.41,"id":71847983}]}]}
{"op":"mcm","clk":"11792971518","pt":1723060507489,"mc":[{"id":"1.231540926","rc":[{"batl":[[0,1.41,2.8],[1,3,1.02]],"ltp":1.7,"tv":168.41,"id":71847983}]}]}
{"op":"mcm","clk":"11792972112","pt":1723060516375,"mc":[{"id":"1.231540926","rc":[{"trd":[[1.41,5.6]],"batb":[[0,1.41,2.39],[1,1.31,8.46],[2,1.3,6.67]],"batl":[[0,3,1.02],[1,3,0]],"ltp":1.41,"tv":174.01,"id":71847983}],"tv":335.65}]}
{"op":"mcm","clk":"11792972496","pt":1723060522678,"mc":[{"id":"1.231540926","rc":[{"batb":[[0,1.31,8.46],[1,1.3,6.67],[2,1.25,100]],"ltp":1.41,"tv":174.01,"id":71847983}]}]}
{"op":"mcm","clk":"11792973063","pt":1723060531285,"mc":[{"id":"1.231540926","rc":[{"batb":[[0,1.41,8.82],[1,1.31,8.46],[2,1.3,6.67]],"ltp":1.41,"tv":174.01,"id":71847983}]}]}
{"op":"mcm","clk":"11792977435","pt":1723060593732,"mc":[{"id":"1.231540926","rc":[{"batb":[[0,1.41,17.68]],"ltp":1.41,"tv":174.01,"id":71847983}]}]}
{"op":"mcm","clk":"11792978152","pt":1723060604359,"mc":[{"id":"1.231540926","rc":[{"batb":[[0,1.42,20.6],[1,1.41,17.68],[2,1.31,8.46]],"ltp":1.41,"tv":174.01,"id":71847983},{"batb":[[0,1.51,16.96],[1,1.26,10],[2,1.25,100]],"ltp":1.59,"tv":161.64,"id":19144236}]}]}
{"op":"mcm","clk":"11792978314","pt":1723060607545,"mc":[{"id":"1.231540926","rc":[{"trd":[[1.51,2.8]],"batb":[[0,1.51,15.56]],"ltp":1.51,"tv":164.44,"id":19144236}],"tv":338.46}]}
{"op":"mcm","clk":"11792979164","pt":1723060620480,"mc":[{"id":"1.231540926","rc":[{"trd":[[1.51,4.2]],"batb":[[0,1.51,14.86]],"ltp":1.51,"tv":165.84,"id":19144236}],"tv":339.86}]}
{"op":"mcm","clk":"11792980157","pt":1723060636082,"mc":[{"id":"1.231540926","rc":[{"batl":[[0,1.57,2.52],[1,3,1.02]],"ltp":1.41,"tv":174.01,"id":71847983}]}]}
{"op":"mcm","clk":"11792980467","pt":1723060640486,"mc":[{"id":"1.231540926","rc":[{"batb":[[0,1.43,17.41],[1,1.42,20.6]],"ltp":1.41,"tv":174.01,"id":71847983}]}]}
{"op":"mcm","clk":"11792981000","pt":1723060648054,"mc":[{"id":"1.231540926","rc":[{"batl":[[0,3,1.02],[1,3,0]],"ltp":1.41,"tv":174.01,"id":71847983}]}]}
{"op":"mcm","clk":"11792984761","pt":1723060701825,"mc":[{"id":"1.231540926","rc":[{"batl":[[0,1.6,2.52],[1,3,1.02]],"ltp":1.41,"tv":174.01,"id":71847983}]}]}
{"op":"mcm","clk":"11792985732","pt":1723060715851,"mc":[{"id":"1.231540926","rc":[{"batl":[[0,3,1.02],[1,3,0]],"ltp":1.41,"tv":174.01,"id":71847983}]}]}
{"op":"mcm","clk":"11792998495","pt":1723060900139,"mc":[{"id":"1.231540926","rc":[{"trd":[[1.5,158.91]],"batb":[[0,1.44,14],[1,1.43,17.41],[2,1.42,20.6]],"ltp":1.41,"tv":173.97,"id":71847983},{"trd":[[1.5,158.98]],"batb":[[0,1.51,14.86]],"ltp":1.51,"tv":165.8,"id":19144236}],"tv":339.78}]}
{"op":"mcm","clk":"11792998639","pt":1723060902418,"mc":[{"id":"1.231540926","rc":[{"batb":[[0,1.44,10]],"ltp":1.41,"tv":173.97,"id":71847983}]}]}
{"op":"mcm","clk":"11792998705","pt":1723060903346,"mc":[{"id":"1.231540926","rc":[{"batb":[[0,1.43,17.41],[1,1.42,20.6],[2,1.31,8.46]],"ltp":1.41,"tv":173.97,"id":71847983}]}]}
{"op":"mcm","clk":"11792999993","pt":1723060923835,"mc":[{"id":"1.231540926","rc":[{"batb":[[0,1.44,14],[1,1.43,17.41],[2,1.42,20.6]],"ltp":1.41,"tv":173.97,"id":71847983}]}]}
{"op":"mcm","clk":"11793000200","pt":1723060926942,"mc":[{"id":"1.231540926","rc":[{"batb":[[0,1.44,10]],"ltp":1.41,"tv":173.97,"id":71847983}]}]}
{"op":"mcm","clk":"11793000248","pt":1723060927823,"mc":[{"id":"1.231540926","rc":[{"batb":[[0,1.43,17.41],[1,1.42,20.6],[2,1.31,8.46]],"ltp":1.41,"tv":173.97,"id":71847983}]}]}
{"op":"mcm","clk":"11793004573","pt":1723061004800,"mc":[{"id":"1.231540926","rc":[{"batb":[[0,1.44,14],[1,1.43,17.41],[2,1.42,20.6]],"ltp":1.41,"tv":173.97,"id":71847983}]}]}
{"op":"mcm","clk":"11793004687","pt":1723061007128,"mc":[{"id":"1.231540926","rc":[{"batb":[[0,1.44,10]],"ltp":1.41,"tv":173.97,"id":71847983}]}]}
{"op":"mcm","clk":"11793004735","pt":1723061008011,"mc":[{"id":"1.231540926","rc":[{"batb":[[0,1.43,17.41],[1,1.42,20.6],[2,1.31,8.46]],"ltp":1.41,"tv":173.97,"id":71847983}]}]}
{"op":"mcm","clk":"11793039278","pt":1723061608428,"mc":[{"id":"1.231540926","rc":[{"batb":[[0,1.44,14],[1,1.43,17.41],[2,1.42,20.6]],"ltp":1.41,"tv":173.97,"id":71847983}]}]}
{"op":"mcm","clk":"11793039489","pt":1723061612146,"mc":[{"id":"1.231540926","rc":[{"batb":[[0,1.43,17.41],[1,1.42,20.6],[2,1.31,8.46]],"ltp":1.41,"tv":173.97,"id":71847983}]}]}
{"op":"mcm","clk":"11793058188","pt":1723061978130,"mc":[{"id":"1.231540926","rc":[{"batb":[[0,1.44,14],[1,1.43,17.41],[2,1.42,20.6]],"ltp":1.41,"tv":173.97,"id":71847983}]}]}
{"op":"mcm","clk":"11793058334","pt":1723061980657,"mc":[{"id":"1.231540926","rc":[{"batb":[[0,1.44,10]],"ltp":1.41,"tv":173.97,"id":71847983}]}]}
{"op":"mcm","clk":"11793058399","pt":1723061981635,"mc":[{"id":"1.231540926","rc":[{"batb":[[0,1.43,17.41],[1,1.42,20.6],[2,1.31,8.46]],"ltp":1.41,"tv":173.97,"id":71847983}]}]}
{"op":"mcm","clk":"11793059688","pt":1723062004849,"mc":[{"id":"1.231540926","rc":[{"batb":[[0,1.44,14],[1,1.43,17.41],[2,1.42,20.6]],"ltp":1.41,"tv":173.97,"id":71847983}]}]}
{"op":"mcm","clk":"11793059799","pt":1723062007165,"mc":[{"id":"1.231540926","rc":[{"batb":[[0,1.44,10]],"ltp":1.41,"tv":173.97,"id":71847983}]}]}
{"op":"mcm","clk":"11793059854","pt":1723062008190,"mc":[{"id":"1.231540926","rc":[{"batb":[[0,1.43,17.41],[1,1.42,20.6],[2,1.31,8.46]],"ltp":1.41,"tv":173.97,"id":71847983}]}]}
{"op":"mcm","clk":"11793061170","pt":1723062033387,"mc":[{"id":"1.231540926","rc":[{"batb":[[0,1.44,14],[1,1.43,17.41],[2,1.42,20.6]],"ltp":1.41,"tv":173.97,"id":71847983}]}]}
{"op":"mcm","clk":"11793061323","pt":1723062035968,"mc":[{"id":"1.231540926","rc":[{"batb":[[0,1.44,10]],"ltp":1.41,"tv":173.97,"id":71847983}]}]}
{"op":"mcm","clk":"11793061380","pt":1723062037110,"mc":[{"id":"1.231540926","rc":[{"batb":[[0,1.43,17.41],[1,1.42,20.6],[2,1.31,8.46]],"ltp":1.41,"tv":173.97,"id":71847983}]}]}
{"op":"mcm","clk":"11793061465","pt":1723062038804,"mc":[{"id":"1.231540926","rc":[{"batb":[[0,1.44,4],[1,1.43,17.41],[2,1.42,20.6]],"ltp":1.41,"tv":173.97,"id":71847983}]}]}
{"op":"mcm","clk":"11793061590","pt":1723062041281,"mc":[{"id":"1.231540926","rc":[{"batb":[[0,1.44,10]],"ltp":1.41,"tv":173.97,"id":71847983}]}]}
{"op":"mcm","clk":"11793061764","pt":1723062044888,"mc":[{"id":"1.231540926","rc":[{"batb":[[0,1.44,4]],"ltp":1.41,"tv":173.97,"id":71847983}]}]}
{"op":"mcm","clk":"11793061886","pt":1723062047111,"mc":[{"id":"1.231540926","rc":[{"batb":[[0,1.45,10]],"ltp":1.41,"tv":173.97,"id":71847983}]}]}
{"op":"mcm","clk":"11793062052","pt":1723062050509,"mc":[{"id":"1.231540926","rc":[{"batb":[[0,1.44,4]],"ltp":1.41,"tv":173.97,"id":71847983}]}]}
{"op":"mcm","clk":"11793062176","pt":1723062052825,"mc":[{"id":"1.231540926","rc":[{"batb":[[0,1.45,10]],"ltp":1.41,"tv":173.97,"id":71847983}]}]}
{"op":"mcm","clk":"11793062318","pt":1723062056116,"mc":[{"id":"1.231540926","rc":[{"batb":[[0,1.43,17.41],[1,1.42,20.6],[2,1.31,8.46]],"ltp":1.41,"tv":173.97,"id":71847983}]}]}
{"op":"mcm","clk":"11793062335","pt":1723062056324,"mc":[{"id":"1.231540926","rc":[{"batb":[[0,1.44,4],[1,1.43,17.41],[2,1.42,20.6]],"ltp":1.41,"tv":173.97,"id":71847983}]}]}
{"op":"mcm","clk":"11793062439","pt":1723062058794,"mc":[{"id":"1.231540926","rc":[{"batb":[[0,1.44,10]],"ltp":1.41,"tv":173.97,"id":71847983}]}]}
{"op":"mcm","clk":"11793062590","pt":1723062062105,"mc":[{"id":"1.231540926","rc":[{"batb":[[0,1.43,17.41],[1,1.42,20.6],[2,1.31,8.46]],"ltp":1.41,"tv":173.97,"id":71847983}]}]}
{"op":"mcm","clk":"11793062608","pt":1723062062311,"mc":[{"id":"1.231540926","rc":[{"batb":[[0,1.44,4],[1,1.43,17.41],[2,1.42,20.6]],"ltp":1.41,"tv":173.97,"id":71847983}]}]}
{"op":"mcm","clk":"11793062794","pt":1723062065608,"mc":[{"id":"1.231540926","rc":[{"batb":[[0,1.44,10]],"ltp":1.41,"tv":173.97,"id":71847983}]}]}
{"op":"mcm","clk":"11793062963","pt":1723062068908,"mc":[{"id":"1.231540926","rc":[{"batb":[[0,1.43,17.41],[1,1.42,20.6],[2,1.31,8.46]],"ltp":1.41,"tv":173.97,"id":71847983}]}]}
{"op":"mcm","clk":"11793062991","pt":1723062069425,"mc":[{"id":"1.231540926","rc":[{"batb":[[0,1.44,4],[1,1.43,17.41],[2,1.42,20.6]],"ltp":1.41,"tv":173.97,"id":71847983}]}]}
{"op":"mcm","clk":"11793063092","pt":1723062071843,"mc":[{"id":"1.231540926","rc":[{"batb":[[0,1.44,10]],"ltp":1.41,"tv":173.97,"id":71847983}]}]}
{"op":"mcm","clk":"11793063228","pt":1723062075262,"mc":[{"id":"1.231540926","rc":[{"batb":[[0,1.44,4]],"ltp":1.41,"tv":173.97,"id":71847983}]}]}
{"op":"mcm","clk":"11793063303","pt":1723062077468,"mc":[{"id":"1.231540926","rc":[{"batb":[[0,1.43,17.41],[1,1.42,20.6],[2,1.31,8.46]],"ltp":1.41,"tv":173.97,"id":71847983}]}]}
{"op":"mcm","clk":"11793063355","pt":1723062078967,"mc":[{"id":"1.231540926","rc":[{"batb":[[0,1.44,10],[1,1.43,17.41],[2,1.42,20.6]],"ltp":1.41,"tv":173.97,"id":71847983}]}]}
{"op":"mcm","clk":"11793063434","pt":1723062080362,"mc":[{"id":"1.231540926","rc":[{"batb":[[0,1.45,4],[1,1.44,10],[2,1.43,17.41]],"ltp":1.41,"tv":173.97,"id":71847983}]}]}
{"op":"mcm","clk":"11793063549","pt":1723062082643,"mc":[{"id":"1.231540926","rc":[{"batb":[[0,1.43,17.41],[1,1.42,20.6],[2,1.31,8.46]],"ltp":1.41,"tv":173.97,"id":71847983}]}]}
{"op":"mcm","clk":"11793063689","pt":1723062085370,"mc":[{"id":"1.231540926","rc":[{"batb":[[0,1.44,14],[1,1.43,17.41],[2,1.42,20.6]],"ltp":1.41,"tv":173.97,"id":71847983}]}]}
{"op":"mcm","clk":"11793063781","pt":1723062087597,"mc":[{"id":"1.231540926","rc":[{"batb":[[0,1.44,10]],"ltp":1.41,"tv":173.97,"id":71847983}]}]}
{"op":"mcm","clk":"11793063835","pt":1723062088433,"mc":[{"id":"1.231540926","rc":[{"batb":[[0,1.43,17.41],[1,1.42,20.6],[2,1.31,8.46]],"ltp":1.41,"tv":173.97,"id":71847983}]}]}
{"op":"mcm","clk":"11793064095","pt":1723062092586,"mc":[{"id":"1.231540926","rc":[{"batb":[[0,1.44,14],[1,1.43,17.41],[2,1.42,20.6]],"ltp":1.41,"tv":173.97,"id":71847983}]}]}
{"op":"mcm","clk":"11793064255","pt":1723062095675,"mc":[{"id":"1.231540926","rc":[{"batb":[[0,1.44,10]],"ltp":1.41,"tv":173.97,"id":71847983}]}]}
{"op":"mcm","clk":"11793064326","pt":1723062096607,"mc":[{"id":"1.231540926","rc":[{"batb":[[0,1.43,17.41],[1,1.42,20.6],[2,1.31,8.46]],"ltp":1.41,"tv":173.97,"id":71847983}]}]}
{"op":"mcm","clk":"11793064419","pt":1723062098066,"mc":[{"id":"1.231540926","rc":[{"batb":[[0,1.44,4],[1,1.43,17.41],[2,1.42,20.6]],"ltp":1.41,"tv":173.97,"id":71847983},{"batb":[[0,1.52,3],[1,1.51,14.86],[2,1.26,10]],"ltp":1.51,"tv":165.8,"id":19144236}]}]}
{"op":"mcm","clk":"11793064501","pt":1723062099294,"mc":[{"id":"1.231540926","rc":[{"batb":[[0,1.45,10],[1,1.44,4],[2,1.43,17.41]],"ltp":1.41,"tv":173.97,"id":71847983}]}]}
{"op":"mcm","clk":"11793064564","pt":1723062100575,"mc":[{"id":"1.231540926","rc":[{"batb":[[1,1.43,17.41],[2,1.42,20.6]],"ltp":1.41,"tv":173.97,"id":71847983}]}]}
{"op":"mcm","clk":"11793064688","pt":1723062102872,"mc":[{"id":"1.231540926","rc":[{"batb":[[0,1.43,17.41],[1,1.42,20.6],[2,1.31,8.46]],"ltp":1.41,"tv":173.97,"id":71847983}]}]}
{"op":"mcm","clk":"11793064716","pt":1723062103183,"mc":[{"id":"1.231540926","rc":[{"batb":[[0,1.44,4],[1,1.43,17.41],[2,1.42,20.6]],"ltp":1.41,"tv":173.97,"id":71847983}]}]}
{"op":"mcm","clk":"11793064852","pt":1723062105793,"mc":[{"id":"1.231540926","rc":[{"batb":[[0,1.44,10]],"ltp":1.41,"tv":173.97,"id":71847983}]}]}
{"op":"mcm","clk":"11793065022","pt":1723062109056,"mc":[{"id":"1.231540926","rc":[{"batb":[[0,1.45,4]],"ltp":1.41,"tv":173.97,"id":71847983}]}]}
{"op":"mcm","clk":"11793065101","pt":1723062110451,"mc":[{"id":"1.231540926","rc":[{"batb":[[0,1.43,17.41],[1,1.42,20.6],[2,1.31,8.46]],"ltp":1.41,"tv":173.97,"id":71847983}]}]}
{"op":"mcm","clk":"11793065185","pt":1723062112260,"mc":[{"id":"1.231540926","rc":[{"batb":[[0,1.44,10],[1,1.43,17.41],[2,1.42,20.6]],"ltp":1.41,"tv":173.97,"id":71847983}]}]}
{"op":"mcm","clk":"11793065256","pt":1723062113497,"mc":[{"id":"1.231540926","rc":[{"batb":[[0,1.45,4],[1,1.44,10],[2,1.43,17.41]],"ltp":1.41,"tv":173.97,"id":71847983}]}]}
{"op":"mcm","clk":"11793065385","pt":1723062115992,"mc":[{"id":"1.231540926","rc":[{"batb":[[0,1.43,17.41],[1,1.42,20.6],[2,1.31,8.46]],"ltp":1.41,"tv":173.97,"id":71847983}]}]}
{"op":"mcm","clk":"11793065505","pt":1723062118161,"mc":[{"id":"1.231540926","rc":[{"batb":[[0,1.44,14],[1,1.43,17.41],[2,1.42,20.6]],"ltp":1.41,"tv":173.97,"id":71847983}]}]}
{"op":"mcm","clk":"11793065657","pt":1723062120581,"mc":[{"id":"1.231540926","rc":[{"batb":[[0,1.44,10]],"ltp":1.41,"tv":173.97,"id":71847983}]}]}
{"op":"mcm","clk":"11793065726","pt":1723062121463,"mc":[{"id":"1.231540926","rc":[{"batb":[[0,1.43,17.41],[1,1.42,20.6],[2,1.31,8.46]],"ltp":1.41,"tv":173.97,"id":71847983}]}]}
{"op":"mcm","clk":"11793065881","pt":1723062124275,"mc":[{"id":"1.231540926","rc":[{"batb":[[0,1.44,14],[1,1.43,17.41],[2,1.42,20.6]],"ltp":1.41,"tv":173.97,"id":71847983}]}]}
{"op":"mcm","clk":"11793066000","pt":1723062126495,"mc":[{"id":"1.231540926","rc":[{"batb":[[0,1.44,10]],"ltp":1.41,"tv":173.97,"id":71847983}]}]}
{"op":"mcm","clk":"11793066075","pt":1723062127684,"mc":[{"id":"1.231540926","rc":[{"batb":[[0,1.43,17.41],[1,1.42,20.6],[2,1.31,8.46]],"ltp":1.41,"tv":173.97,"id":71847983}]}]}
{"op":"mcm","clk":"11793066141","pt":1723062128875,"mc":[{"id":"1.231540926","rc":[{"batb":[[0,1.44,4],[1,1.43,17.41],[2,1.42,20.6]],"ltp":1.41,"tv":173.97,"id":71847983}]}]}
{"op":"mcm","clk":"11793066251","pt":1723062131092,"mc":[{"id":"1.231540926","rc":[{"batb":[[0,1.45,10]],"ltp":1.41,"tv":173.97,"id":71847983}]}]}
{"op":"mcm","clk":"11793066408","pt":1723062133575,"mc":[{"id":"1.231540926","rc":[{"batb":[[0,1.46,4],[1,1.45,10],[2,1.43,17.41]],"ltp":1.41,"tv":173.97,"id":71847983}]}]}
{"op":"mcm","clk":"11793066438","pt":1723062134291,"mc":[{"id":"1.231540926","rc":[{"batb":[[1,1.43,17.41],[2,1.42,20.6]],"ltp":1.41,"tv":173.97,"id":71847983}]}]}
{"op":"mcm","clk":"11793066512","pt":1723062135888,"mc":[{"id":"1.231540926","rc":[{"batb":[[0,1.43,17.41],[1,1.42,20.6],[2,1.31,8.46]],"ltp":1.41,"tv":173.97,"id":71847983}]}]}
{"op":"mcm","clk":"11793066557","pt":1723062137123,"mc":[{"id":"1.231540926","rc":[{"batb":[[0,1.44,10],[1,1.43,17.41],[2,1.42,20.6]],"ltp":1.41,"tv":173.97,"id":71847983}]}]}
{"op":"mcm","clk":"11793066627","pt":1723062138310,"mc":[{"id":"1.231540926","rc":[{"batb":[[0,1.45,4],[1,1.44,10],[2,1.43,17.41]],"ltp":1.41,"tv":173.97,"id":71847983}]}]}
{"op":"mcm","clk":"11793066785","pt":1723062140893,"mc":[{"id":"1.231540926","rc":[{"batb":[[0,1.43,17.41],[1,1.42,20.6],[2,1.31,8.46]],"ltp":1.41,"tv":173.97,"id":71847983}]}]}
{"op":"mcm","clk":"11793066976","pt":1723062143528,"mc":[{"id":"1.231540926","rc":[{"batb":[[0,1.44,14],[1,1.43,17.41],[2,1.42,20.6]],"ltp":1.41,"tv":173.97,"id":71847983}]}]}
{"op":"mcm","clk":"11793067083","pt":1723062145817,"mc":[{"id":"1.231540926","rc":[{"batb":[[0,1.44,10]],"ltp":1.41,"tv":173.97,"id":71847983}]}]}
{"op":"mcm","clk":"11793067135","pt":1723062146728,"mc":[{"id":"1.231540926","rc":[{"batb":[[0,1.43,17.41],[1,1.42,20.6],[2,1.31,8.46]],"ltp":1.41,"tv":173.97,"id":71847983}]}]}
{"op":"mcm","clk":"11793067331","pt":1723062150431,"mc":[{"id":"1.231540926","rc":[{"batb":[[0,1.44,14],[1,1.43,17.41],[2,1.42,20.6]],"ltp":1.41,"tv":173.97,"id":71847983}]}]}
{"op":"mcm","clk":"11793067444","pt":1723062152746,"mc":[{"id":"1.231540926","rc":[{"batb":[[0,1.44,10]],"ltp":1.41,"tv":173.97,"id":71847983}]}]}
{"op":"mcm","clk":"11793067504","pt":1723062153832,"mc":[{"id":"1.231540926","rc":[{"batb":[[0,1.43,17.41],[1,1.42,20.6],[2,1.31,8.46]],"ltp":1.41,"tv":173.97,"id":71847983}]}]}
{"op":"mcm","clk":"11793067636","pt":1723062156713,"mc":[{"id":"1.231540926","rc":[{"batb":[[0,1.44,14],[1,1.43,17.41],[2,1.42,20.6]],"ltp":1.41,"tv":173.97,"id":71847983}]}]}
{"op":"mcm","clk":"11793067789","pt":1723062159957,"mc":[{"id":"1.231540926","rc":[{"batb":[[0,1.43,17.41],[1,1.42,20.6],[2,1.31,8.46]],"ltp":1.41,"tv":173.97,"id":71847983}]}]}
{"op":"mcm","clk":"11793067911","pt":1723062162944,"mc":[{"id":"1.231540926","rc":[{"batb":[[0,1.44,14],[1,1.43,17.41],[2,1.42,20.6]],"ltp":1.41,"tv":173.97,"id":71847983}]}]}
{"op":"mcm","clk":"11793068005","pt":1723062165321,"mc":[{"id":"1.231540926","rc":[{"batb":[[0,1.44,10]],"ltp":1.41,"tv":173.97,"id":71847983}]}]}
{"op":"mcm","clk":"11793068039","pt":1723062166450,"mc":[{"id":"1.231540926","rc":[{"batb":[[0,1.43,17.41],[1,1.42,20.6],[2,1.31,8.46]],"ltp":1.41,"tv":173.97,"id":71847983}]}]}
{"op":"mcm","clk":"11793068156","pt":1723062169024,"mc":[{"id":"1.231540926","rc":[{"batb":[[0,1.44,14],[1,1.43,17.41],[2,1.42,20.6]],"ltp":1.41,"tv":173.97,"id":71847983}]}]}
{"op":"mcm","clk":"11793068289","pt":1723062171446,"mc":[{"id":"1.231540926","rc":[{"batb":[[0,1.44,10]],"ltp":1.41,"tv":173.97,"id":71847983}]}]}
{"op":"mcm","clk":"11793068440","pt":1723062174740,"mc":[{"id":"1.231540926","rc":[{"batb":[[0,1.45,4]],"ltp":1.41,"tv":173.97,"id":71847983}]}]}
{"op":"mcm","clk":"11793068533","pt":1723062176957,"mc":[{"id":"1.231540926","rc":[{"batb":[[0,1.46,10],[1,1.45,4],[2,1.43,17.41]],"ltp":1.41,"tv":173.97,"id":71847983}]}]}
{"op":"mcm","clk":"11793068564","pt":1723062177670,"mc":[{"id":"1.231540926","rc":[{"batb":[[1,1.43,17.41],[2,1.42,20.6]],"ltp":1.41,"tv":173.97,"id":71847983}]}]}
{"op":"mcm","clk":"11793068724","pt":1723062180771,"mc":[{"id":"1.231540926","rc":[{"batb":[[0,1.44,4]],"ltp":1.41,"tv":173.97,"id":71847983}]}]}
{"op":"mcm","clk":"11793068838","pt":1723062183053,"mc":[{"id":"1.231540926","rc":[{"batb":[[0,1.43,17.41],[1,1.42,20.6],[2,1.31,8.46]],"ltp":1.41,"tv":173.97,"id":71847983}]}]}
{"op":"mcm","clk":"11793068852","pt":1723062183361,"mc":[{"id":"1.231540926","rc":[{"batb":[[0,1.45,10],[1,1.43,17.41],[2,1.42,20.6]],"ltp":1.41,"tv":173.97,"id":71847983}]}]}
{"op":"mcm","clk":"11793069015","pt":1723062185988,"mc":[{"id":"1.231540926","rc":[{"batb":[[0,1.46,4],[1,1.45,10],[2,1.43,17.41]],"ltp":1.41,"tv":173.97,"id":71847983}]}]}
{"op":"mcm","clk":"11793069048","pt":1723062186662,"mc":[{"id":"1.231540926","rc":[{"batb":[[1,1.43,17.41],[2,1.42,20.6]],"ltp":1.41,"tv":173.97,"id":71847983}]}]}
{"op":"mcm","clk":"11793069109","pt":1723062188362,"mc":[{"id":"1.231540926","rc":[{"batb":[[0,1.43,17.41],[1,1.42,20.6],[2,1.31,8.46]],"ltp":1.41,"tv":173.97,"id":71847983}]}]}
{"op":"mcm","clk":"11793069156","pt":1723062189441,"mc":[{"id":"1.231540926","rc":[{"batb":[[0,1.44,10],[1,1.43,17.41],[2,1.42,20.6]],"ltp":1.41,"tv":173.97,"id":71847983}]}]}
{"op":"mcm","clk":"11793069254","pt":1723062191657,"mc":[{"id":"1.231540926","rc":[{"batb":[[0,1.45,4],[1,1.44,10],[2,1.43,17.41]],"ltp":1.41,"tv":173.97,"id":71847983}]}]}
{"op":"mcm","clk":"11793069323","pt":1723062192894,"mc":[{"id":"1.231540926","rc":[{"batb":[[1,1.43,17.41],[2,1.42,20.6]],"ltp":1.41,"tv":173.97,"id":71847983}]}]}
{"op":"mcm","clk":"11793069358","pt":1723062193969,"mc":[{"id":"1.231540926","rc":[{"batb":[[0,1.43,17.41],[1,1.42,20.6],[2,1.31,8.46]],"ltp":1.41,"tv":173.97,"id":71847983}]}]}
{"op":"mcm","clk":"11793069417","pt":1723062195154,"mc":[{"id":"1.231540926","rc":[{"batb":[[0,1.44,10],[1,1.43,17.41],[2,1.42,20.6]],"ltp":1.41,"tv":173.97,"id":71847983}]}]}
{"op":"mcm","clk":"11793069479","pt":1723062196545,"mc":[{"id":"1.231540926","rc":[{"batb":[[0,1.45,4],[1,1.44,10],[2,1.43,17.41]],"ltp":1.41,"tv":173.97,"id":71847983}]}]}
{"op":"mcm","clk":"11793069590","pt":1723062198878,"mc":[{"id":"1.231540926","rc":[{"batb":[[0,1.43,17.41],[1,1.42,20.6],[2,1.31,8.46]],"ltp":1.41,"tv":173.97,"id":71847983}]}]}
{"op":"mcm","clk":"11793069708","pt":1723062201186,"mc":[{"id":"1.231540926","rc":[{"batb":[[0,1.44,14],[1,1.43,17.41],[2,1.42,20.6]],"ltp":1.41,"tv":173.97,"id":71847983}]}]}
{"op":"mcm","clk":"11793069911","pt":1723062205871,"mc":[{"id":"1.231540926","rc":[{"batb":[[0,1.45,4]],"ltp":1.41,"tv":173.97,"id":71847983}]}]}
{"op":"mcm","clk":"11793069974","pt":1723062207206,"mc":[{"id":"1.231540926","rc":[{"batb":[[0,1.46,10],[1,1.45,4],[2,1.43,17.41]],"ltp":1.41,"tv":173.97,"id":71847983}]}]}
{"op":"mcm","clk":"11793070034","pt":1723062208394,"mc":[{"id":"1.231540926","rc":[{"batb":[[1,1.43,17.41],[2,1.42,20.6]],"ltp":1.41,"tv":173.97,"id":71847983}]}]}
{"op":"mcm","clk":"11793070147","pt":1723062210709,"mc":[{"id":"1.231540926","rc":[{"batb":[[0,1.44,4]],"ltp":1.41,"tv":173.97,"id":71847983}]}]}
{"op":"mcm","clk":"11793070301","pt":1723062213598,"mc":[{"id":"1.231540926","rc":[{"batb":[[0,1.44,10]],"ltp":1.41,"tv":173.97,"id":71847983}]}]}
{"op":"mcm","clk":"11793070424","pt":1723062215713,"mc":[{"id":"1.231540926","rc":[{"batb":[[0,1.45,4],[1,1.44,10],[2,1.43,17.41]],"ltp":1.41,"tv":173.97,"id":71847983}]}]}
{"op":"mcm","clk":"11793070469","pt":1723062216798,"mc":[{"id":"1.231540926","rc":[{"batb":[[1,1.43,17.41],[2,1.42,20.6]],"ltp":1.41,"tv":173.97,"id":71847983}]}]}
{"op":"mcm","clk":"11793070526","pt":1723062218288,"mc":[{"id":"1.231540926","rc":[{"batb":[[0,1.43,17.41],[1,1.42,20.6],[2,1.31,8.46]],"ltp":1.41,"tv":173.97,"id":71847983}]}]}
{"op":"mcm","clk":"11793070621","pt":1723062220395,"mc":[{"id":"1.231540926","rc":[{"batb":[[0,1.44,14],[1,1.43,17.41],[2,1.42,20.6]],"ltp":1.41,"tv":173.97,"id":71847983}]}]}
{"op":"mcm","clk":"11793070716","pt":1723062222808,"mc":[{"id":"1.231540926","rc":[{"batb":[[0,1.44,10]],"ltp":1.41,"tv":173.97,"id":71847983}]}]}
{"op":"mcm","clk":"11793070769","pt":1723062223829,"mc":[{"id":"1.231540926","rc":[{"batb":[[0,1.43,17.41],[1,1.42,20.6],[2,1.31,8.46]],"ltp":1.41,"tv":173.97,"id":71847983}]}]}
{"op":"mcm","clk":"11793070885","pt":1723062226509,"mc":[{"id":"1.231540926","rc":[{"batb":[[0,1.44,14],[1,1.43,17.41],[2,1.42,20.6]],"ltp":1.41,"tv":173.97,"id":71847983}]}]}
{"op":"mcm","clk":"11793070979","pt":1723062228812,"mc":[{"id":"1.231540926","rc":[{"batb":[[0,1.44,10]],"ltp":1.41,"tv":173.97,"id":71847983}]}]}
{"op":"mcm","clk":"11793071026","pt":1723062229689,"mc":[{"id":"1.231540926","rc":[{"batb":[[0,1.43,17.41],[1,1.42,20.6],[2,1.31,8.46]],"ltp":1.41,"tv":173.97,"id":71847983}]}]}
{"op":"mcm","clk":"11793071154","pt":1723062232514,"mc":[{"id":"1.231540926","rc":[{"batb":[[0,1.44,14],[1,1.43,17.41],[2,1.42,20.6]],"ltp":1.41,"tv":173.97,"id":71847983}]}]}
{"op":"mcm","clk":"11793071251","pt":1723062234930,"mc":[{"id":"1.231540926","rc":[{"batb":[[0,1.44,10]],"ltp":1.41,"tv":173.97,"id":71847983}]}]}
{"op":"mcm","clk":"11793071289","pt":1723062235700,"mc":[{"id":"1.231540926","rc":[{"batb":[[0,1.43,17.41],[1,1.42,20.6],[2,1.31,8.46]],"ltp":1.41,"tv":173.97,"id":71847983}]}]}
{"op":"mcm","clk":"11793071409","pt":1723062238423,"mc":[{"id":"1.231540926","rc":[{"batb":[[0,1.44,14],[1,1.43,17.41],[2,1.42,20.6]],"ltp":1.41,"tv":173.97,"id":71847983}]}]}
{"op":"mcm","clk":"11793071503","pt":1723062240631,"mc":[{"id":"1.231540926","rc":[{"batb":[[0,1.44,10]],"ltp":1.41,"tv":173.97,"id":71847983}]}]}
{"op":"mcm","clk":"11793071537","pt":1723062241616,"mc":[{"id":"1.231540926","rc":[{"batb":[[0,1.43,17.41],[1,1.42,20.6],[2,1.31,8.46]],"ltp":1.41,"tv":173.97,"id":71847983}]}]}
{"op":"mcm","clk":"11793071580","pt":1723062242793,"mc":[{"id":"1.231540926","rc":[{"batb":[[0,1.44,4],[1,1.43,17.41],[2,1.42,20.6]],"ltp":1.41,"tv":173.97,"id":71847983}]}]}
{"op":"mcm","clk":"11793071700","pt":1723062245105,"mc":[{"id":"1.231540926","rc":[{"batb":[[0,1.44,10]],"ltp":1.41,"tv":173.97,"id":71847983}]}]}
{"op":"mcm","clk":"11793071835","pt":1723062248301,"mc":[{"id":"1.231540926","rc":[{"batb":[[0,1.45,4]],"ltp":1.41,"tv":173.97,"id":71847983}]}]}
{"op":"mcm","clk":"11793071947","pt":1723062250929,"mc":[{"id":"1.231540926","rc":[{"batb":[[0,1.44,10]],"ltp":1.41,"tv":173.97,"id":71847983}]}]}
{"op":"mcm","clk":"11793072028","pt":1723062253031,"mc":[{"id":"1.231540926","rc":[{"batb":[[0,1.45,4],[1,1.44,10],[2,1.43,17.41]],"ltp":1.41,"tv":173.97,"id":71847983}]}]}
{"op":"mcm","clk":"11793072067","pt":1723062254109,"mc":[{"id":"1.231540926","rc":[{"batb":[[1,1.43,17.41],[2,1.42,20.6]],"ltp":1.41,"tv":173.97,"id":71847983}]}]}
{"op":"mcm","clk":"11793072108","pt":1723062255341,"mc":[{"id":"1.231540926","rc":[{"batb":[[0,1.43,17.41],[1,1.42,20.6],[2,1.31,8.46]],"ltp":1.41,"tv":173.97,"id":71847983}]}]}
{"op":"mcm","clk":"11793072247","pt":1723062258336,"mc":[{"id":"1.231540926","rc":[{"batb":[[0,1.44,14],[1,1.43,17.41],[2,1.42,20.6]],"ltp":1.41,"tv":173.97,"id":71847983}]}]}
{"op":"mcm","clk":"11793072377","pt":1723062260610,"mc":[{"id":"1.231540926","rc":[{"batb":[[0,1.44,10]],"ltp":1.41,"tv":173.97,"id":71847983}]}]}
{"op":"mcm","clk":"11793072435","pt":1723062261537,"mc":[{"id":"1.231540926","rc":[{"batb":[[0,1.43,17.41],[1,1.42,20.6],[2,1.31,8.46]],"ltp":1.41,"tv":173.97,"id":71847983}]}]}
{"op":"mcm","clk":"11793072490","pt":1723062262828,"mc":[{"id":"1.231540926","rc":[{"batb":[[0,1.44,4],[1,1.43,17.41],[2,1.42,20.6]],"ltp":1.41,"tv":173.97,"id":71847983}]}]}
{"op":"mcm","clk":"11793072614","pt":1723062265451,"mc":[{"id":"1.231540926","rc":[{"batb":[[0,1.44,10]],"ltp":1.41,"tv":173.97,"id":71847983}]}]}
{"op":"mcm","clk":"11793072747","pt":1723062268640,"mc":[{"id":"1.231540926","rc":[{"batb":[[0,1.45,4]],"ltp":1.41,"tv":173.97,"id":71847983}]}]}
{"op":"mcm","clk":"11793072844","pt":1723062271059,"mc":[{"id":"1.231540926","rc":[{"batb":[[0,1.43,17.41],[1,1.42,20.6],[2,1.31,8.46]],"ltp":1.41,"tv":173.97,"id":71847983}]}]}
{"op":"mcm","clk":"11793072853","pt":1723062271264,"mc":[{"id":"1.231540926","rc":[{"batb":[[0,1.44,10],[1,1.43,17.41],[2,1.42,20.6]],"ltp":1.41,"tv":173.97,"id":71847983}]}]}
{"op":"mcm","clk":"11793072971","pt":1723062273530,"mc":[{"id":"1.231540926","rc":[{"batb":[[0,1.45,4],[1,1.44,10],[2,1.43,17.41]],"ltp":1.41,"tv":173.97,"id":71847983}]}]}
{"op":"mcm","clk":"11793073028","pt":1723062274559,"mc":[{"id":"1.231540926","rc":[{"batb":[[1,1.43,17.41],[2,1.42,20.6]],"ltp":1.41,"tv":173.97,"id":71847983}]}]}
{"op":"mcm","clk":"11793073101","pt":1723062275945,"mc":[{"id":"1.231540926","rc":[{"batb":[[0,1.43,17.41],[1,1.42,20.6],[2,1.31,8.46]],"ltp":1.41,"tv":173.97,"id":71847983}]}]}
{"op":"mcm","clk":"11793073205","pt":1723062278668,"mc":[{"id":"1.231540926","rc":[{"batb":[[0,1.44,14],[1,1.43,17.41],[2,1.42,20.6]],"ltp":1.41,"tv":173.97,"id":71847983}]}]}
{"op":"mcm","clk":"11793073309","pt":1723062280845,"mc":[{"id":"1.231540926","rc":[{"batb":[[0,1.44,10]],"ltp":1.41,"tv":173.97,"id":71847983}]}]}
{"op":"mcm","clk":"11793073353","pt":1723062281871,"mc":[{"id":"1.231540926","rc":[{"batb":[[0,1.43,17.41],[1,1.42,20.6],[2,1.31,8.46]],"ltp":1.41,"tv":173.97,"id":71847983}]}]}
{"op":"mcm","clk":"11793073391","pt":1723062282951,"mc":[{"id":"1.231540926","rc":[{"batb":[[0,1.44,4],[1,1.43,17.41],[2,1.42,20.6]],"ltp":1.41,"tv":173.97,"id":71847983}]}]}
{"op":"mcm","clk":"11793073460","pt":1723062284139,"mc":[{"id":"1.231540926","rc":[{"batb":[[0,1.45,10],[1,1.44,4],[2,1.43,17.41]],"ltp":1.41,"tv":173.97,"id":71847983}]}]}
{"op":"mcm","clk":"11793073518","pt":1723062285267,"mc":[{"id":"1.231540926","rc":[{"batb":[[1,1.43,17.41],[2,1.42,20.6]],"ltp":1.41,"tv":173.97,"id":71847983}]}]}
{"op":"mcm","clk":"11793073610","pt":1723062287634,"mc":[{"id":"1.231540926","rc":[{"batb":[[0,1.46,4]],"ltp":1.41,"tv":173.97,"id":71847983}]}]}
{"op":"mcm","clk":"11793073722","pt":1723062289950,"mc":[{"id":"1.231540926","rc":[{"batb":[[0,1.44,10]],"ltp":1.41,"tv":173.97,"id":71847983}]}]}
{"op":"mcm","clk":"11793073877","pt":1723062293457,"mc":[{"id":"1.231540926","rc":[{"batb":[[0,1.44,4]],"ltp":1.41,"tv":173.97,"id":71847983}]}]}
{"op":"mcm","clk":"11793073987","pt":1723062295872,"mc":[{"id":"1.231540926","rc":[{"batb":[[0,1.44,10]],"ltp":1.41,"tv":173.97,"id":71847983}]}]}
{"op":"mcm","clk":"11793074149","pt":1723062299062,"mc":[{"id":"1.231540926","rc":[{"batb":[[0,1.43,17.41],[1,1.42,20.6],[2,1.31,8.46]],"ltp":1.41,"tv":173.97,"id":71847983}]}]}
{"op":"mcm","clk":"11793074154","pt":1723062299169,"mc":[{"id":"1.231540926","rc":[{"batb":[[0,1.44,4],[1,1.43,17.41],[2,1.42,20.6]],"ltp":1.41,"tv":173.97,"id":71847983}]}]}
{"op":"mcm","clk":"11793074251","pt":1723062301580,"mc":[{"id":"1.231540926","rc":[{"batb":[[0,1.44,10]],"ltp":1.41,"tv":173.97,"id":71847983}]}]}
{"op":"mcm","clk":"11793074394","pt":1723062304882,"mc":[{"id":"1.231540926","rc":[{"batb":[[0,1.45,4]],"ltp":1.41,"tv":173.97,"id":71847983}]}]}
{"op":"mcm","clk":"11793074463","pt":1723062306580,"mc":[{"id":"1.231540926","rc":[{"batb":[[0,1.43,17.41],[1,1.42,20.6],[2,1.31,8.46]],"ltp":1.41,"tv":173.97,"id":71847983}]}]}
{"op":"mcm","clk":"11793074504","pt":1723062307662,"mc":[{"id":"1.231540926","rc":[{"batb":[[0,1.44,10],[1,1.43,17.41],[2,1.42,20.6]],"ltp":1.41,"tv":173.97,"id":71847983}]}]}
{"op":"mcm","clk":"11793074573","pt":1723062309406,"mc":[{"id":"1.231540926","rc":[{"batb":[[0,1.45,4],[1,1.44,10],[2,1.43,17.41]],"ltp":1.41,"tv":173.97,"id":71847983}]}]}
{"op":"mcm","clk":"11793074631","pt":1723062311001,"mc":[{"id":"1.231540926","rc":[{"batb":[[1,1.43,17.41],[2,1.42,20.6]],"ltp":1.41,"tv":173.97,"id":71847983}]}]}
{"op":"mcm","clk":"11793074654","pt":1723062311672,"mc":[{"id":"1.231540926","rc":[{"batb":[[0,1.43,17.41],[1,1.42,20.6],[2,1.31,8.46]],"ltp":1.41,"tv":173.97,"id":71847983}]}]}
{"op":"mcm","clk":"11793074746","pt":1723062313894,"mc":[{"id":"1.231540926","rc":[{"batb":[[0,1.44,14],[1,1.43,17.41],[2,1.42,20.6]],"ltp":1.41,"tv":173.97,"id":71847983}]}]}
{"op":"mcm","clk":"11793074839","pt":1723062316267,"mc":[{"id":"1.231540926","rc":[{"batb":[[0,1.44,10]],"ltp":1.41,"tv":173.97,"id":71847983}]}]}
{"op":"mcm","clk":"11793074872","pt":1723062317192,"mc":[{"id":"1.231540926","rc":[{"batb":[[0,1.43,17.41],[1,1.42,20.6],[2,1.31,8.46]],"ltp":1.41,"tv":173.97,"id":71847983}]}]}
{"op":"mcm","clk":"11793074938","pt":1723062318687,"mc":[{"id":"1.231540926","rc":[{"batb":[[0,1.44,4],[1,1.43,17.41],[2,1.42,20.6]],"ltp":1.41,"tv":173.97,"id":71847983}]}]}
{"op":"mcm","clk":"11793074983","pt":1723062319916,"mc":[{"id":"1.231540926","rc":[{"batb":[[0,1.45,10],[1,1.44,4],[2,1.43,17.41]],"ltp":1.41,"tv":173.97,"id":71847983}]}]}
{"op":"mcm","clk":"11793075025","pt":1723062321000,"mc":[{"id":"1.231540926","rc":[{"batb":[[1,1.43,17.41],[2,1.42,20.6]],"ltp":1.41,"tv":173.97,"id":71847983}]}]}
{"op":"mcm","clk":"11793075131","pt":1723062324000,"mc":[{"id":"1.231540926","rc":[{"batb":[[0,1.44,4]],"ltp":1.41,"tv":173.97,"id":71847983}]}]}
{"op":"mcm","clk":"11793075234","pt":1723062326402,"mc":[{"id":"1.231540926","rc":[{"batb":[[0,1.45,10]],"ltp":1.41,"tv":173.97,"id":71847983}]}]}
{"op":"mcm","clk":"11793075323","pt":1723062328713,"mc":[{"id":"1.231540926","rc":[{"batb":[[0,1.46,4],[1,1.45,10],[2,1.43,17.41]],"ltp":1.41,"tv":173.97,"id":71847983}]}]}
{"op":"mcm","clk":"11793075360","pt":1723062329918,"mc":[{"id":"1.231540926","rc":[{"batb":[[1,1.43,17.41],[2,1.42,20.6]],"ltp":1.41,"tv":173.97,"id":71847983}]}]}
{"op":"mcm","clk":"11793075411","pt":1723062330931,"mc":[{"id":"1.231540926","rc":[{"batb":[[0,1.43,17.41],[1,1.42,20.6],[2,1.31,8.46]],"ltp":1.41,"tv":173.97,"id":71847983}]}]}
{"op":"mcm","clk":"11793075478","pt":1723062332322,"mc":[{"id":"1.231540926","rc":[{"batb":[[0,1.44,10],[1,1.43,17.41],[2,1.42,20.6]],"ltp":1.41,"tv":173.97,"id":71847983}]}]}
{"op":"mcm","clk":"11793075557","pt":1723062334425,"mc":[{"id":"1.231540926","rc":[{"batb":[[0,1.45,4],[1,1.44,10],[2,1.43,17.41]],"ltp":1.41,"tv":173.97,"id":71847983}]}]}
{"op":"mcm","clk":"11793075621","pt":1723062335823,"mc":[{"id":"1.231540926","rc":[{"batb":[[1,1.43,17.41],[2,1.42,20.6]],"ltp":1.41,"tv":173.97,"id":71847983}]}]}
{"op":"mcm","clk":"11793075668","pt":1723062336902,"mc":[{"id":"1.231540926","rc":[{"batb":[[0,1.43,17.41],[1,1.42,20.6],[2,1.31,8.46]],"ltp":1.41,"tv":173.97,"id":71847983}]}]}
{"op":"mcm","clk":"11793075760","pt":1723062338647,"mc":[{"id":"1.231540926","rc":[{"batb":[[0,1.44,10],[1,1.43,17.41],[2,1.42,20.6]],"ltp":1.41,"tv":173.97,"id":71847983}]}]}
{"op":"mcm","clk":"11793075820","pt":1723062340139,"mc":[{"id":"1.231540926","rc":[{"batb":[[0,1.45,4],[1,1.44,10],[2,1.43,17.41]],"ltp":1.41,"tv":173.97,"id":71847983}]}]}
{"op":"mcm","clk":"11793075889","pt":1723062342044,"mc":[{"id":"1.231540926","rc":[{"batb":[[1,1.43,17.41],[2,1.42,20.6]],"ltp":1.41,"tv":173.97,"id":71847983}]}]}
{"op":"mcm","clk":"11793075903","pt":1723062342407,"mc":[{"id":"1.231540926","rc":[{"batb":[[0,1.43,17.41],[1,1.42,20.6],[2,1.31,8.46]],"ltp":1.41,"tv":173.97,"id":71847983}]}]}
{"op":"mcm","clk":"11793075991","pt":1723062344722,"mc":[{"id":"1.231540926","rc":[{"batb":[[0,1.44,14],[1,1.43,17.41],[2,1.42,20.6]],"ltp":1.41,"tv":173.97,"id":71847983}]}]}
{"op":"mcm","clk":"11793076111","pt":1723062347047,"mc":[{"id":"1.231540926","rc":[{"batb":[[0,1.44,10]],"ltp":1.41,"tv":173.97,"id":71847983}]}]}
{"op":"mcm","clk":"11793076159","pt":1723062348126,"mc":[{"id":"1.231540926","rc":[{"batb":[[0,1.43,17.41],[1,1.42,20.6],[2,1.31,8.46]],"ltp":1.41,"tv":173.97,"id":71847983}]}]}
{"op":"mcm","clk":"11793076222","pt":1723062349522,"mc":[{"id":"1.231540926","rc":[{"batb":[[0,1.44,4],[1,1.43,17.41],[2,1.42,20.6]],"ltp":1.41,"tv":173.97,"id":71847983}]}]}
{"op":"mcm","clk":"11793076329","pt":1723062351934,"mc":[{"id":"1.231540926","rc":[{"batb":[[0,1.45,10]],"ltp":1.41,"tv":173.97,"id":71847983}]}]}
{"op":"mcm","clk":"11793076420","pt":1723062354553,"mc":[{"id":"1.231540926","rc":[{"batb":[[0,1.46,4],[1,1.45,10],[2,1.43,17.41]],"ltp":1.41,"tv":173.97,"id":71847983}]}]}
{"op":"mcm","clk":"11793076438","pt":1723062355169,"mc":[{"id":"1.231540926","rc":[{"batb":[[1,1.43,17.41],[2,1.42,20.6]],"ltp":1.41,"tv":173.97,"id":71847983}]}]}
{"op":"mcm","clk":"11793076546","pt":1723062357024,"mc":[{"id":"1.231540926","rc":[{"batb":[[0,1.43,17.41],[1,1.42,20.6],[2,1.31,8.46]],"ltp":1.41,"tv":173.97,"id":71847983}]}]}
{"op":"mcm","clk":"11793076607","pt":1723062358257,"mc":[{"id":"1.231540926","rc":[{"batb":[[0,1.44,10],[1,1.43,17.41],[2,1.42,20.6]],"ltp":1.41,"tv":173.97,"id":71847983}]}]}
{"op":"mcm","clk":"11793076674","pt":1723062359537,"mc":[{"id":"1.231540926","rc":[{"batb":[[0,1.45,4],[1,1.44,10],[2,1.43,17.41]],"ltp":1.41,"tv":173.97,"id":71847983}]}]}
{"op":"mcm","clk":"11793076783","pt":1723062361860,"mc":[{"id":"1.231540926","rc":[{"batb":[[0,1.43,17.41],[1,1.42,20.6],[2,1.31,8.46]],"ltp":1.41,"tv":173.97,"id":71847983}]}]}
{"op":"mcm","clk":"11793076865","pt":1723062363866,"mc":[{"id":"1.231540926","rc":[{"batb":[[0,1.44,10],[1,1.43,17.41],[2,1.42,20.6]],"ltp":1.41,"tv":173.97,"id":71847983}]}]}
{"op":"mcm","clk":"11793076880","pt":1723062364177,"mc":[{"id":"1.231540926","rc":[{"batb":[[0,1.45,4],[1,1.44,10],[2,1.43,17.41]],"ltp":1.41,"tv":173.97,"id":71847983}]}]}
{"op":"mcm","clk":"11793076988","pt":1723062367057,"mc":[{"id":"1.231540926","rc":[{"batb":[[0,1.43,17.41],[1,1.42,20.6],[2,1.31,8.46]],"ltp":1.41,"tv":173.97,"id":71847983}]}]}
{"op":"mcm","clk":"11793077109","pt":1723062370039,"mc":[{"id":"1.231540926","rc":[{"batb":[[0,1.44,14],[1,1.43,17.41],[2,1.42,20.6]],"ltp":1.41,"tv":173.97,"id":71847983}]}]}
{"op":"mcm","clk":"11793077234","pt":1723062372562,"mc":[{"id":"1.231540926","rc":[{"batb":[[0,1.44,10]],"ltp":1.41,"tv":173.97,"id":71847983}]}]}
{"op":"mcm","clk":"11793077260","pt":1723062373383,"mc":[{"id":"1.231540926","rc":[{"batb":[[0,1.43,17.41],[1,1.42,20.6],[2,1.31,8.46]],"ltp":1.41,"tv":173.97,"id":71847983}]}]}
{"op":"mcm","clk":"11793077320","pt":1723062374773,"mc":[{"id":"1.231540926","rc":[{"batb":[[0,1.44,4],[1,1.43,17.41],[2,1.42,20.6]],"ltp":1.41,"tv":173.97,"id":71847983}]}]}
{"op":"mcm","clk":"11793077395","pt":1723062376060,"mc":[{"id":"1.231540926","rc":[{"batb":[[0,1.45,10],[1,1.44,4],[2,1.43,17.41]],"ltp":1.41,"tv":173.97,"id":71847983}]}]}
{"op":"mcm","clk":"11793077429","pt":1723062377059,"mc":[{"id":"1.231540926","rc":[{"batb":[[1,1.43,17.41],[2,1.42,20.6]],"ltp":1.41,"tv":173.97,"id":71847983}]}]}
{"op":"mcm","clk":"11793077533","pt":1723062379664,"mc":[{"id":"1.231540926","rc":[{"batb":[[0,1.44,4]],"ltp":1.41,"tv":173.97,"id":71847983}]}]}
{"op":"mcm","clk":"11793077627","pt":1723062382084,"mc":[{"id":"1.231540926","rc":[{"batb":[[0,1.45,10]],"ltp":1.41,"tv":173.97,"id":71847983}]}]}
{"op":"mcm","clk":"11793077739","pt":1723062385080,"mc":[{"id":"1.231540926","rc":[{"batb":[[0,1.46,4]],"ltp":1.41,"tv":173.97,"id":71847983}]}]}
{"op":"mcm","clk":"11793077790","pt":1723062386680,"mc":[{"id":"1.231540926","rc":[{"batb":[[0,1.43,17.41],[1,1.42,20.6],[2,1.31,8.46]],"ltp":1.41,"tv":173.97,"id":71847983}]}]}
{"op":"mcm","clk":"11793077906","pt":1723062389194,"mc":[{"id":"1.231540926","rc":[{"batb":[[0,1.44,14],[1,1.43,17.41],[2,1.42,20.6]],"ltp":1.41,"tv":173.97,"id":71847983}]}]}
{"op":"mcm","clk":"11793078011","pt":1723062391775,"mc":[{"id":"1.231540926","rc":[{"batb":[[0,1.44,10]],"ltp":1.41,"tv":173.97,"id":71847983}]}]}
{"op":"mcm","clk":"11793078053","pt":1723062392703,"mc":[{"id":"1.231540926","rc":[{"batb":[[0,1.43,17.41],[1,1.42,20.6],[2,1.31,8.46]],"ltp":1.41,"tv":173.97,"id":71847983}]}]}
{"op":"mcm","clk":"11793078161","pt":1723062395167,"mc":[{"id":"1.231540926","rc":[{"batb":[[0,1.44,14],[1,1.43,17.41],[2,1.42,20.6]],"ltp":1.41,"tv":173.97,"id":71847983}]}]}
{"op":"mcm","clk":"11793078250","pt":1723062397482,"mc":[{"id":"1.231540926","rc":[{"batb":[[0,1.44,10]],"ltp":1.41,"tv":173.97,"id":71847983}]}]}
{"op":"mcm","clk":"11793078288","pt":1723062398660,"mc":[{"id":"1.231540926","rc":[{"batb":[[0,1.43,17.41],[1,1.42,20.6],[2,1.31,8.46]],"ltp":1.41,"tv":173.97,"id":71847983}]}]}
{"op":"mcm","clk":"11793078390","pt":1723062401187,"mc":[{"id":"1.231540926","rc":[{"batb":[[0,1.44,14],[1,1.43,17.41],[2,1.42,20.6]],"ltp":1.41,"tv":173.97,"id":71847983}]}]}
{"op":"mcm","clk":"11793078511","pt":1723062403702,"mc":[{"id":"1.231540926","rc":[{"batb":[[0,1.44,10]],"ltp":1.41,"tv":173.97,"id":71847983}]}]}
{"op":"mcm","clk":"11793078573","pt":1723062404675,"mc":[{"id":"1.231540926","rc":[{"batb":[[0,1.43,17.41],[1,1.31,8.46],[2,1.26,6.67]],"ltp":1.41,"tv":173.97,"id":71847983},{"batb":[[1,1.26,10],[2,1.25,100]],"ltp":1.51,"tv":165.8,"id":19144236}]}]}
{"op":"mcm","clk":"11793078801","pt":1723062409303,"mc":[{"id":"1.231540926","rc":[{"batb":[[0,1.44,14],[1,1.43,17.41],[2,1.31,8.46]],"ltp":1.41,"tv":173.97,"id":71847983}]}]}
{"op":"mcm","clk":"11793078906","pt":1723062411775,"mc":[{"id":"1.231540926","rc":[{"batb":[[0,1.44,10]],"ltp":1.41,"tv":173.97,"id":71847983}]}]}
{"op":"mcm","clk":"11793078935","pt":1723062412695,"mc":[{"id":"1.231540926","rc":[{"batb":[[0,1.43,17.41],[1,1.31,8.46],[2,1.26,6.67]],"ltp":1.41,"tv":173.97,"id":71847983}]}]}
{"op":"mcm","clk":"11793079030","pt":1723062414909,"mc":[{"id":"1.231540926","rc":[{"batb":[[0,1.44,14],[1,1.43,17.41],[2,1.31,8.46]],"ltp":1.41,"tv":173.97,"id":71847983}]}]}
{"op":"mcm","clk":"11793079139","pt":1723062417389,"mc":[{"id":"1.231540926","rc":[{"batb":[[0,1.44,10]],"ltp":1.41,"tv":173.97,"id":71847983}]}]}
{"op":"mcm","clk":"11793079195","pt":1723062418413,"mc":[{"id":"1.231540926","rc":[{"batb":[[0,1.43,17.41],[1,1.31,8.46],[2,1.26,6.67]],"ltp":1.41,"tv":173.97,"id":71847983}]}]}
{"op":"mcm","clk":"11793079270","pt":1723062420111,"mc":[{"id":"1.231540926","rc":[{"batb":[[0,1.44,4],[1,1.43,17.41],[2,1.31,8.46]],"ltp":1.41,"tv":173.97,"id":71847983}]}]}
{"op":"mcm","clk":"11793079325","pt":1723062421212,"mc":[{"id":"1.231540926","rc":[{"batb":[[0,1.45,10],[1,1.44,4],[2,1.43,17.41]],"ltp":1.41,"tv":173.97,"id":71847983}]}]}
{"op":"mcm","clk":"11793079370","pt":1723062422433,"mc":[{"id":"1.231540926","rc":[{"batb":[[1,1.43,17.41],[2,1.31,8.46]],"ltp":1.41,"tv":173.97,"id":71847983}]}]}
{"op":"mcm","clk":"11793079482","pt":1723062424711,"mc":[{"id":"1.231540926","rc":[{"batb":[[0,1.44,4]],"ltp":1.41,"tv":173.97,"id":71847983}]}]}
{"op":"mcm","clk":"11793079575","pt":1723062426926,"mc":[{"id":"1.231540926","rc":[{"batb":[[0,1.43,17.41],[1,1.31,8.46],[2,1.26,6.67]],"ltp":1.41,"tv":173.97,"id":71847983}]}]}
{"op":"mcm","clk":"11793079592","pt":1723062427230,"mc":[{"id":"1.231540926","rc":[{"batb":[[0,1.44,10],[1,1.43,17.41],[2,1.31,8.46]],"ltp":1.41,"tv":173.97,"id":71847983}]}]}
{"op":"mcm","clk":"11793079773","pt":1723062430428,"mc":[{"id":"1.231540926","rc":[{"batb":[[0,1.45,4]],"ltp":1.41,"tv":173.97,"id":71847983}]}]}
{"op":"mcm","clk":"11793079876","pt":1723062432745,"mc":[{"id":"1.231540926","rc":[{"batb":[[0,1.44,10]],"ltp":1.41,"tv":173.97,"id":71847983}]}]}
{"op":"mcm","clk":"11793079988","pt":1723062435006,"mc":[{"id":"1.231540926","rc":[{"batb":[[0,1.45,4],[1,1.44,10],[2,1.43,17.41]],"ltp":1.41,"tv":173.97,"id":71847983}]}]}
{"op":"mcm","clk":"11793080045","pt":1723062436135,"mc":[{"id":"1.231540926","rc":[{"batb":[[1,1.43,17.41],[2,1.31,8.46]],"ltp":1.41,"tv":173.97,"id":71847983}]}]}
{"op":"mcm","clk":"11793080098","pt":1723062437334,"mc":[{"id":"1.231540926","rc":[{"batb":[[0,1.43,17.41],[1,1.31,8.46],[2,1.26,6.67]],"ltp":1.41,"tv":173.97,"id":71847983}]}]}
{"op":"mcm","clk":"11793080155","pt":1723062438553,"mc":[{"id":"1.231540926","rc":[{"batb":[[0,1.44,10],[1,1.43,17.41],[2,1.31,8.46]],"ltp":1.41,"tv":173.97,"id":71847983}]}]}
{"op":"mcm","clk":"11793080256","pt":1723062439845,"mc":[{"id":"1.231540926","rc":[{"batb":[[0,1.45,4],[1,1.44,10],[2,1.43,17.41]],"ltp":1.41,"tv":173.97,"id":71847983}]}]}
{"op":"mcm","clk":"11793080385","pt":1723062442056,"mc":[{"id":"1.231540926","rc":[{"batb":[[0,1.43,17.41],[1,1.31,8.46],[2,1.26,6.67]],"ltp":1.41,"tv":173.97,"id":71847983}]}]}
{"op":"mcm","clk":"11793080616","pt":1723062446872,"mc":[{"id":"1.231540926","rc":[{"batb":[[0,1.44,14],[1,1.43,17.41],[2,1.31,8.46]],"ltp":1.41,"tv":173.97,"id":71847983}]}]}
{"op":"mcm","clk":"11793080768","pt":1723062449340,"mc":[{"id":"1.231540926","rc":[{"batb":[[0,1.44,10]],"ltp":1.41,"tv":173.97,"id":71847983}]}]}
{"op":"mcm","clk":"11793080804","pt":1723062450160,"mc":[{"id":"1.231540926","rc":[{"batb":[[0,1.43,17.41],[1,1.31,8.46],[2,1.26,6.67]],"ltp":1.41,"tv":173.97,"id":71847983}]}]}
{"op":"mcm","clk":"11793080870","pt":1723062451668,"mc":[{"id":"1.231540926","rc":[{"batb":[[0,1.44,4],[1,1.43,17.41],[2,1.31,8.46]],"ltp":1.41,"tv":173.97,"id":71847983}]}]}
{"op":"mcm","clk":"11793080929","pt":1723062452865,"mc":[{"id":"1.231540926","rc":[{"batb":[[0,1.45,10],[1,1.44,4],[2,1.43,17.41]],"ltp":1.41,"tv":173.97,"id":71847983}]}]}
{"op":"mcm","clk":"11793081014","pt":1723062454369,"mc":[{"id":"1.231540926","rc":[{"batb":[[1,1.43,17.41],[2,1.31,8.46]],"ltp":1.41,"tv":173.97,"id":71847983}]}]}
{"op":"mcm","clk":"11793081121","pt":1723062456160,"mc":[{"id":"1.231540926","rc":[{"batb":[[0,1.43,17.41],[1,1.31,8.46],[2,1.26,6.67]],"ltp":1.41,"tv":173.97,"id":71847983}]}]}
{"op":"mcm","clk":"11793081204","pt":1723062457551,"mc":[{"id":"1.231540926","rc":[{"batb":[[0,1.44,4],[1,1.43,17.41],[2,1.31,8.46]],"ltp":1.41,"tv":173.97,"id":71847983}]}]}
{"op":"mcm","clk":"11793081274","pt":1723062458851,"mc":[{"id":"1.231540926","rc":[{"batb":[[0,1.45,10],[1,1.44,4],[2,1.43,17.41]],"ltp":1.41,"tv":173.97,"id":71847983}]}]}
{"op":"mcm","clk":"11793081326","pt":1723062459869,"mc":[{"id":"1.231540926","rc":[{"batb":[[1,1.43,17.41],[2,1.31,8.46]],"ltp":1.41,"tv":173.97,"id":71847983}]}]}
{"op":"mcm","clk":"11793081429","pt":1723062462438,"mc":[{"id":"1.231540926","rc":[{"batb":[[0,1.46,4]],"ltp":1.41,"tv":173.97,"id":71847983}]}]}
{"op":"mcm","clk":"11793081545","pt":1723062464862,"mc":[{"id":"1.231540926","rc":[{"batb":[[0,1.43,17.41],[1,1.31,8.46],[2,1.26,6.67]],"ltp":1.41,"tv":173.97,"id":71847983}]}]}
{"op":"mcm","clk":"11793081559","pt":1723062465174,"mc":[{"id":"1.231540926","rc":[{"batb":[[0,1.44,10],[1,1.43,17.41],[2,1.31,8.46]],"ltp":1.41,"tv":173.97,"id":71847983}]}]}
{"op":"mcm","clk":"11793081672","pt":1723062467449,"mc":[{"id":"1.231540926","rc":[{"batb":[[0,1.45,4],[1,1.44,10],[2,1.43,17.41]],"ltp":1.41,"tv":173.97,"id":71847983}]}]}
{"op":"mcm","clk":"11793081723","pt":1723062468479,"mc":[{"id":"1.231540926","rc":[{"batb":[[1,1.43,17.41],[2,1.31,8.46]],"ltp":1.41,"tv":173.97,"id":71847983}]}]}
{"op":"mcm","clk":"11793081783","pt":1723062469795,"mc":[{"id":"1.231540926","rc":[{"batb":[[0,1.43,17.41],[1,1.31,8.46],[2,1.26,6.67]],"ltp":1.41,"tv":173.97,"id":71847983}]}]}
{"op":"mcm","clk":"11793081852","pt":1723062471076,"mc":[{"id":"1.231540926","rc":[{"batb":[[0,1.44,10],[1,1.43,17.41],[2,1.31,8.46]],"ltp":1.41,"tv":173.97,"id":71847983}]}]}
{"op":"mcm","clk":"11793081957","pt":1723062473192,"mc":[{"id":"1.231540926","rc":[{"batb":[[0,1.45,4],[1,1.44,10],[2,1.43,17.41]],"ltp":1.41,"tv":173.97,"id":71847983}]}]}
{"op":"mcm","clk":"11793082016","pt":1723062474277,"mc":[{"id":"1.231540926","rc":[{"batb":[[1,1.43,17.41],[2,1.31,8.46]],"ltp":1.41,"tv":173.97,"id":71847983}]}]}
{"op":"mcm","clk":"11793082071","pt":1723062475571,"mc":[{"id":"1.231540926","rc":[{"batb":[[0,1.43,17.41],[1,1.31,8.46],[2,1.26,6.67]],"ltp":1.41,"tv":173.97,"id":71847983}]}]}
{"op":"mcm","clk":"11793082176","pt":1723062477882,"mc":[{"id":"1.231540926","rc":[{"batb":[[0,1.44,14],[1,1.43,17.41],[2,1.31,8.46]],"ltp":1.41,"tv":173.97,"id":71847983}]}]}
{"op":"mcm","clk":"11793082308","pt":1723062481087,"mc":[{"id":"1.231540926","rc":[{"batb":[[0,1.43,17.41],[1,1.31,8.46],[2,1.26,6.67]],"ltp":1.41,"tv":173.97,"id":71847983}]}]}
{"op":"mcm","clk":"11793082436","pt":1723062483785,"mc":[{"id":"1.231540926","rc":[{"batb":[[0,1.44,14],[1,1.43,17.41],[2,1.31,8.46]],"ltp":1.41,"tv":173.97,"id":71847983}]}]}
{"op":"mcm","clk":"11793082571","pt":1723062486322,"mc":[{"id":"1.231540926","rc":[{"batb":[[0,1.44,10]],"ltp":1.41,"tv":173.97,"id":71847983}]}]}
{"op":"mcm","clk":"11793082615","pt":1723062487200,"mc":[{"id":"1.231540926","rc":[{"batb":[[0,1.43,17.41],[1,1.31,8.46],[2,1.26,6.67]],"ltp":1.41,"tv":173.97,"id":71847983}]}]}
{"op":"mcm","clk":"11793082683","pt":1723062488381,"mc":[{"id":"1.231540926","rc":[{"batb":[[0,1.44,4],[1,1.43,17.41],[2,1.31,8.46]],"ltp":1.41,"tv":173.97,"id":71847983}]}]}
{"op":"mcm","clk":"11793082808","pt":1723062490806,"mc":[{"id":"1.231540926","rc":[{"batb":[[0,1.45,10]],"ltp":1.41,"tv":173.97,"id":71847983}]}]}
{"op":"mcm","clk":"11793082963","pt":1723062493793,"mc":[{"id":"1.231540926","rc":[{"batb":[[0,1.46,4]],"ltp":1.41,"tv":173.97,"id":71847983}]}]}
{"op":"mcm","clk":"11793083086","pt":1723062496004,"mc":[{"id":"1.231540926","rc":[{"batb":[[0,1.44,10]],"ltp":1.41,"tv":173.97,"id":71847983}]}]}
{"op":"mcm","clk":"11793083240","pt":1723062498179,"mc":[{"id":"1.231540926","rc":[{"batb":[[0,1.45,4],[1,1.44,10],[2,1.43,17.41]],"ltp":1.41,"tv":173.97,"id":71847983}]}]}
{"op":"mcm","clk":"11793083299","pt":1723062499211,"mc":[{"id":"1.231540926","rc":[{"batb":[[1,1.43,17.41],[2,1.31,8.46]],"ltp":1.41,"tv":173.97,"id":71847983}]}]}
{"op":"mcm","clk":"11793083372","pt":1723062500702,"mc":[{"id":"1.231540926","rc":[{"batb":[[0,1.43,17.41],[1,1.31,8.46],[2,1.26,6.67]],"ltp":1.41,"tv":173.97,"id":71847983}]}]}
{"op":"mcm","clk":"11793083532","pt":1723062503586,"mc":[{"id":"1.231540926","rc":[{"batb":[[0,1.44,14],[1,1.43,17.41],[2,1.31,8.46]],"ltp":1.41,"tv":173.97,"id":71847983}]}]}
{"op":"mcm","clk":"11793083609","pt":1723062506046,"mc":[{"id":"1.231540926","rc":[{"batb":[[0,1.44,10]],"ltp":1.41,"tv":173.97,"id":71847983}]}]}
{"op":"mcm","clk":"11793083651","pt":1723062507125,"mc":[{"id":"1.231540926","rc":[{"batb":[[0,1.43,17.41],[1,1.31,8.46],[2,1.26,6.67]],"ltp":1.41,"tv":173.97,"id":71847983}]}]}
{"op":"mcm","clk":"11793083747","pt":1723062510210,"mc":[{"id":"1.231540926","rc":[{"batb":[[0,1.44,14],[1,1.43,17.41],[2,1.31,8.46]],"ltp":1.41,"tv":173.97,"id":71847983}]}]}
{"op":"mcm","clk":"11793083841","pt":1723062512726,"mc":[{"id":"1.231540926","rc":[{"batb":[[0,1.44,10]],"ltp":1.41,"tv":173.97,"id":71847983}]}]}
{"op":"mcm","clk":"11793083891","pt":1723062513654,"mc":[{"id":"1.231540926","rc":[{"batb":[[0,1.43,17.41],[1,1.31,8.46],[2,1.26,6.67]],"ltp":1.41,"tv":173.97,"id":71847983}]}]}
{"op":"mcm","clk":"11793084018","pt":1723062516630,"mc":[{"id":"1.231540926","rc":[{"batb":[[0,1.44,14],[1,1.43,17.41],[2,1.31,8.46]],"ltp":1.41,"tv":173.97,"id":71847983}]}]}
{"op":"mcm","clk":"11793084108","pt":1723062518945,"mc":[{"id":"1.231540926","rc":[{"batb":[[0,1.44,10]],"ltp":1.41,"tv":173.97,"id":71847983}]}]}
{"op":"mcm","clk":"11793084141","pt":1723062519815,"mc":[{"id":"1.231540926","rc":[{"batb":[[0,1.43,17.41],[1,1.31,8.46],[2,1.25,100]],"ltp":1.41,"tv":173.97,"id":71847983}]}]}
{"op":"mcm","clk":"11793084298","pt":1723062523816,"mc":[{"id":"1.231540926","rc":[{"batb":[[0,1.44,14],[1,1.43,17.41],[2,1.31,8.46]],"ltp":1.41,"tv":173.97,"id":71847983}]}]}
{"op":"mcm","clk":"11793084370","pt":1723062526325,"mc":[{"id":"1.231540926","rc":[{"batb":[[0,1.44,10]],"ltp":1.41,"tv":173.97,"id":71847983}]}]}
{"op":"mcm","clk":"11793084398","pt":1723062527455,"mc":[{"id":"1.231540926","rc":[{"batb":[[0,1.43,17.41],[1,1.31,8.46],[2,1.25,100]],"ltp":1.41,"tv":173.97,"id":71847983}]}]}
{"op":"mcm","clk":"11793084466","pt":1723062529157,"mc":[{"id":"1.231540926","rc":[{"batb":[[0,1.44,4],[1,1.43,17.41],[2,1.31,8.46]],"ltp":1.41,"tv":173.97,"id":71847983}]}]}
{"op":"mcm","clk":"11793084492","pt":1723062529728,"mc":[{"id":"1.231540926","rc":[{"batb":[[0,1.45,10],[1,1.44,4],[2,1.43,17.41]],"ltp":1.41,"tv":173.97,"id":71847983}]}]}
{"op":"mcm","clk":"11793084573","pt":1723062531932,"mc":[{"id":"1.231540926","rc":[{"batb":[[1,1.43,17.41],[2,1.31,8.46]],"ltp":1.41,"tv":173.97,"id":71847983}]}]}
{"op":"mcm","clk":"11793084613","pt":1723062533062,"mc":[{"id":"1.231540926","rc":[{"batb":[[0,1.43,17.41],[1,1.31,8.46],[2,1.25,100]],"ltp":1.41,"tv":173.97,"id":71847983}]}]}
{"op":"mcm","clk":"11793084642","pt":1723062533628,"mc":[{"id":"1.231540926","rc":[{"batb":[[0,1.44,19.66],[1,1.43,17.41],[2,1.31,8.46]],"ltp":1.41,"tv":173.97,"id":71847983}]}]}
{"op":"mcm","clk":"11793084718","pt":1723062535737,"mc":[{"id":"1.231540926","rc":[{"batb":[[0,1.45,14],[1,1.44,19.66],[2,1.43,17.41]],"ltp":1.41,"tv":173.97,"id":71847983}]}]}
{"op":"mcm","clk":"11793084787","pt":1723062538148,"mc":[{"id":"1.231540926","rc":[{"batb":[[0,1.45,10]],"ltp":1.41,"tv":173.97,"id":71847983}]}]}
{"op":"mcm","clk":"11793084829","pt":1723062539270,"mc":[{"id":"1.231540926","rc":[{"batb":[[0,1.44,19.66],[1,1.43,17.41],[2,1.31,8.46]],"ltp":1.41,"tv":173.97,"id":71847983}]}]}
{"op":"mcm","clk":"11793084957","pt":1723062542459,"mc":[{"id":"1.231540926","rc":[{"batb":[[0,1.45,14],[1,1.44,19.66],[2,1.43,17.41]],"ltp":1.41,"tv":173.97,"id":71847983}]}]}
{"op":"mcm","clk":"11793085054","pt":1723062544845,"mc":[{"id":"1.231540926","rc":[{"batb":[[0,1.45,10]],"ltp":1.41,"tv":173.97,"id":71847983}]}]}
{"op":"mcm","clk":"11793085093","pt":1723062545874,"mc":[{"id":"1.231540926","rc":[{"batb":[[0,1.44,19.66],[1,1.43,17.41],[2,1.31,8.46]],"ltp":1.41,"tv":173.97,"id":71847983}]}]}
{"op":"mcm","clk":"11793085195","pt":1723062548040,"mc":[{"id":"1.231540926","rc":[{"batb":[[0,1.45,14],[1,1.44,19.66],[2,1.43,17.41]],"ltp":1.41,"tv":173.97,"id":71847983}]}]}
{"op":"mcm","clk":"11793085307","pt":1723062550562,"mc":[{"id":"1.231540926","rc":[{"batb":[[0,1.45,10]],"ltp":1.41,"tv":173.97,"id":71847983}]}]}
{"op":"mcm","clk":"11793085337","pt":1723062551638,"mc":[{"id":"1.231540926","rc":[{"batb":[[0,1.44,19.66],[1,1.43,17.41],[2,1.31,8.46]],"ltp":1.41,"tv":173.97,"id":71847983}]}]}
{"op":"mcm","clk":"11793085397","pt":1723062553078,"mc":[{"id":"1.231540926","rc":[{"batb":[[0,1.45,4],[1,1.44,19.66],[2,1.43,17.41]],"ltp":1.41,"tv":173.97,"id":71847983}]}]}
{"op":"mcm","clk":"11793085436","pt":1723062554359,"mc":[{"id":"1.231540926","rc":[{"batb":[[0,1.46,10],[1,1.45,4],[2,1.44,19.66]],"ltp":1.41,"tv":173.97,"id":71847983}]}]}
{"op":"mcm","clk":"11793085466","pt":1723062555385,"mc":[{"id":"1.231540926","rc":[{"batb":[[1,1.44,19.66],[2,1.43,17.41]],"ltp":1.41,"tv":173.97,"id":71847983}]}]}
{"op":"mcm","clk":"11793085560","pt":1723062557749,"mc":[{"id":"1.231540926","rc":[{"batb":[[0,1.45,4]],"ltp":1.41,"tv":173.97,"id":71847983}]}]}
{"op":"mcm","clk":"11793085645","pt":1723062560059,"mc":[{"id":"1.231540926","rc":[{"batb":[[0,1.44,19.66],[1,1.43,17.41],[2,1.31,8.46]],"ltp":1.41,"tv":173.97,"id":71847983}]}]}
{"op":"mcm","clk":"11793085655","pt":1723062560260,"mc":[{"id":"1.231540926","rc":[{"batb":[[0,1.45,10],[1,1.44,19.66],[2,1.43,17.41]],"ltp":1.41,"tv":173.97,"id":71847983}]}]}
{"op":"mcm","clk":"11793085758","pt":1723062563091,"mc":[{"id":"1.231540926","rc":[{"batb":[[0,1.46,4],[1,1.45,10],[2,1.44,19.66]],"ltp":1.41,"tv":173.97,"id":71847983}]}]}
{"op":"mcm","clk":"11793085777","pt":1723062563557,"mc":[{"id":"1.231540926","rc":[{"batb":[[1,1.44,19.66],[2,1.43,17.41]],"ltp":1.41,"tv":173.97,"id":71847983}]}]}
{"op":"mcm","clk":"11793085839","pt":1723062565257,"mc":[{"id":"1.231540926","rc":[{"batb":[[0,1.44,19.66],[1,1.43,17.41],[2,1.31,8.46]],"ltp":1.41,"tv":173.97,"id":71847983}]}]}
{"op":"mcm","clk":"11793085893","pt":1723062566491,"mc":[{"id":"1.231540926","rc":[{"batb":[[0,1.45,10],[1,1.44,19.66],[2,1.43,17.41]],"ltp":1.41,"tv":173.97,"id":71847983}]}]}
{"op":"mcm","clk":"11793085978","pt":1723062568294,"mc":[{"id":"1.231540926","rc":[{"batb":[[0,1.46,4],[1,1.45,10],[2,1.44,19.66]],"ltp":1.41,"tv":173.97,"id":71847983}]}]}
{"op":"mcm","clk":"11793086033","pt":1723062569581,"mc":[{"id":"1.231540926","rc":[{"batb":[[1,1.44,19.66],[2,1.43,17.41]],"ltp":1.41,"tv":173.97,"id":71847983}]}]}
{"op":"mcm","clk":"11793086113","pt":1723062571278,"mc":[{"id":"1.231540926","rc":[{"batb":[[0,1.44,19.66],[1,1.43,17.41],[2,1.31,8.46]],"ltp":1.41,"tv":173.97,"id":71847983}]}]}
{"op":"mcm","clk":"11793086205","pt":1723062573484,"mc":[{"id":"1.231540926","rc":[{"batb":[[0,1.46,4],[1,1.45,10],[2,1.44,19.66]],"ltp":1.41,"tv":173.97,"id":71847983}]}]}
{"op":"mcm","clk":"11793086355","pt":1723062576682,"mc":[{"id":"1.231540926","rc":[{"batb":[[0,1.44,19.66],[1,1.43,17.41],[2,1.31,8.46]],"ltp":1.41,"tv":173.97,"id":71847983}]}]}
{"op":"mcm","clk":"11793086491","pt":1723062579608,"mc":[{"id":"1.231540926","rc":[{"batb":[[0,1.45,14],[1,1.44,19.66],[2,1.43,17.41]],"ltp":1.41,"tv":173.97,"id":71847983}]}]}
{"op":"mcm","clk":"11793086560","pt":1723062582072,"mc":[{"id":"1.231540926","rc":[{"batb":[[0,1.45,10]],"ltp":1.41,"tv":173.97,"id":71847983}]}]}
{"op":"mcm","clk":"11793086591","pt":1723062582894,"mc":[{"id":"1.231540926","rc":[{"batb":[[0,1.44,19.66],[1,1.43,17.41],[2,1.31,8.46]],"ltp":1.41,"tv":173.97,"id":71847983}]}]}
{"op":"mcm","clk":"11793086631","pt":1723062584382,"mc":[{"id":"1.231540926","rc":[{"batb":[[0,1.45,4],[1,1.44,19.66],[2,1.43,17.41]],"ltp":1.41,"tv":173.97,"id":71847983}]}]}
{"op":"mcm","clk":"11793086682","pt":1723062585770,"mc":[{"id":"1.231540926","rc":[{"batb":[[0,1.46,10],[1,1.45,4],[2,1.44,19.66]],"ltp":1.41,"tv":173.97,"id":71847983}]}]}
{"op":"mcm","clk":"11793086715","pt":1723062586671,"mc":[{"id":"1.231540926","rc":[{"batb":[[1,1.44,19.66],[2,1.43,17.41]],"ltp":1.41,"tv":173.97,"id":71847983}]}]}
{"op":"mcm","clk":"11793086814","pt":1723062589088,"mc":[{"id":"1.231540926","rc":[{"batb":[[0,1.44,19.66],[1,1.43,17.41],[2,1.31,8.46]],"ltp":1.41,"tv":173.97,"id":71847983}]}]}
{"op":"mcm","clk":"11793086837","pt":1723062589499,"mc":[{"id":"1.231540926","rc":[{"batb":[[0,1.45,4],[1,1.44,19.66],[2,1.43,17.41]],"ltp":1.41,"tv":173.97,"id":71847983}]}]}
{"op":"mcm","clk":"11793086930","pt":1723062592012,"mc":[{"id":"1.231540926","rc":[{"batb":[[0,1.46,10]],"ltp":1.41,"tv":173.97,"id":71847983}]}]}
{"op":"mcm","clk":"11793087016","pt":1723062594680,"mc":[{"id":"1.231540926","rc":[{"batb":[[0,1.47,4],[1,1.46,10],[2,1.44,19.66]],"ltp":1.41,"tv":173.97,"id":71847983}]}]}
{"op":"mcm","clk":"11793087036","pt":1723062595401,"mc":[{"id":"1.231540926","rc":[{"batb":[[1,1.44,19.66],[2,1.43,17.41]],"ltp":1.41,"tv":173.97,"id":71847983}]}]}
{"op":"mcm","clk":"11793087077","pt":1723062596895,"mc":[{"id":"1.231540926","rc":[{"batb":[[0,1.44,19.66],[1,1.43,17.41],[2,1.31,8.46]],"ltp":1.41,"tv":173.97,"id":71847983}]}]}
{"op":"mcm","clk":"11793087159","pt":1723062599109,"mc":[{"id":"1.231540926","rc":[{"batb":[[0,1.45,14],[1,1.44,19.66],[2,1.43,17.41]],"ltp":1.41,"tv":173.97,"id":71847983}]}]}
{"op":"mcm","clk":"11793087250","pt":1723062601530,"mc":[{"id":"1.231540926","rc":[{"batb":[[0,1.45,10]],"ltp":1.41,"tv":173.97,"id":71847983}]}]}
{"op":"mcm","clk":"11793087289","pt":1723062602513,"mc":[{"id":"1.231540926","rc":[{"batb":[[0,1.44,19.66],[1,1.43,17.41],[2,1.31,8.46]],"ltp":1.41,"tv":173.97,"id":71847983}]}]}
{"op":"mcm","clk":"11793087382","pt":1723062604724,"mc":[{"id":"1.231540926","rc":[{"batb":[[0,1.46,10],[1,1.45,4],[2,1.44,19.66]],"ltp":1.41,"tv":173.97,"id":71847983}]}]}
{"op":"mcm","clk":"11793087486","pt":1723062607093,"mc":[{"id":"1.231540926","rc":[{"batb":[[1,1.44,19.66],[2,1.43,17.41]],"ltp":1.41,"tv":173.97,"id":71847983}]}]}
{"op":"mcm","clk":"11793087533","pt":1723062608120,"mc":[{"id":"1.231540926","rc":[{"batb":[[0,1.44,19.66],[1,1.43,17.41],[2,1.31,8.46]],"ltp":1.41,"tv":173.97,"id":71847983}]}]}
{"op":"mcm","clk":"11793087612","pt":1723062609823,"mc":[{"id":"1.231540926","rc":[{"batl":[[0,1.54,2.8],[1,3,1.02]],"ltp":1.41,"tv":173.97,"id":71847983}]}]}
{"op":"mcm","clk":"11793087996","pt":1723062619757,"mc":[{"id":"1.231540926","rc":[{"batb":[[0,1.45,14],[1,1.44,19.66],[2,1.43,17.41]],"batl":[[0,3,1.02],[1,3,0]],"ltp":1.41,"tv":173.97,"id":71847983}]}]}
{"op":"mcm","clk":"11793088091","pt":1723062622124,"mc":[{"id":"1.231540926","rc":[{"batb":[[0,1.45,10]],"ltp":1.41,"tv":173.97,"id":71847983}]}]}
{"op":"mcm","clk":"11793088124","pt":1723062622951,"mc":[{"id":"1.231540926","rc":[{"batb":[[0,1.44,19.66],[1,1.43,17.41],[2,1.31,8.46]],"ltp":1.41,"tv":173.97,"id":71847983}]}]}
{"op":"mcm","clk":"11793088257","pt":1723062626850,"mc":[{"id":"1.231540926","rc":[{"batb":[[0,1.45,14],[1,1.44,19.66],[2,1.43,17.41]],"ltp":1.41,"tv":173.97,"id":71847983}]}]}
{"op":"mcm","clk":"11793088329","pt":1723062629057,"mc":[{"id":"1.231540926","rc":[{"batb":[[0,1.45,10]],"ltp":1.41,"tv":173.97,"id":71847983}]}]}
{"op":"mcm","clk":"11793088368","pt":1723062630243,"mc":[{"id":"1.231540926","rc":[{"batb":[[0,1.44,19.66],[1,1.43,17.41],[2,1.31,8.46]],"ltp":1.41,"tv":173.97,"id":71847983}]}]}
{"op":"mcm","clk":"11793088446","pt":1723062631942,"mc":[{"id":"1.231540926","rc":[{"batb":[[0,1.45,4],[1,1.44,19.66],[2,1.43,17.41]],"ltp":1.41,"tv":173.97,"id":71847983}]}]}
{"op":"mcm","clk":"11793088490","pt":1723062633230,"mc":[{"id":"1.231540926","rc":[{"batb":[[0,1.46,10],[1,1.45,4],[2,1.44,19.66]],"ltp":1.41,"tv":173.97,"id":71847983}]}]}
{"op":"mcm","clk":"11793088527","pt":1723062634260,"mc":[{"id":"1.231540926","rc":[{"batb":[[1,1.44,19.66],[2,1.43,17.41]],"ltp":1.41,"tv":173.97,"id":71847983}]}]}
{"op":"mcm","clk":"11793088621","pt":1723062636728,"mc":[{"id":"1.231540926","rc":[{"batb":[[0,1.47,4]],"ltp":1.41,"tv":173.97,"id":71847983}]}]}
{"op":"mcm","clk":"11793088723","pt":1723062638838,"mc":[{"id":"1.231540926","rc":[{"batb":[[0,1.44,19.66],[1,1.43,17.41],[2,1.31,8.46]],"batl":[[0,1.53,2.8],[1,3,1.02]],"ltp":1.41,"tv":173.97,"id":71847983}]}]}
{"op":"mcm","clk":"11793090069","pt":1723062672583,"mc":[{"id":"1.231540926","rc":[{"batb":[[0,1.45,14],[1,1.44,19.66],[2,1.43,17.41]],"batl":[[0,3,1.02],[1,3,0]],"ltp":1.41,"tv":173.97,"id":71847983}]}]}
{"op":"mcm","clk":"11793090151","pt":1723062674789,"mc":[{"id":"1.231540926","rc":[{"batb":[[0,1.45,10]],"ltp":1.41,"tv":173.97,"id":71847983}]}]}
{"op":"mcm","clk":"11793090196","pt":1723062675817,"mc":[{"id":"1.231540926","rc":[{"batb":[[0,1.44,19.66],[1,1.43,17.41],[2,1.31,8.46]],"ltp":1.41,"tv":173.97,"id":71847983}]}]}
{"op":"mcm","clk":"11793090253","pt":1723062677002,"mc":[{"id":"1.231540926","rc":[{"batb":[[0,1.45,4],[1,1.44,19.66],[2,1.43,17.41]],"ltp":1.41,"tv":173.97,"id":71847983}]}]}
{"op":"mcm","clk":"11793090297","pt":1723062678390,"mc":[{"id":"1.231540926","rc":[{"batb":[[0,1.46,10],[1,1.45,4],[2,1.44,19.66]],"ltp":1.41,"tv":173.97,"id":71847983}]}]}
{"op":"mcm","clk":"11793090326","pt":1723062679316,"mc":[{"id":"1.231540926","rc":[{"batb":[[1,1.44,19.66],[2,1.43,17.41]],"ltp":1.41,"tv":173.97,"id":71847983}]}]}
{"op":"mcm","clk":"11793090475","pt":1723062683118,"mc":[{"id":"1.231540926","rc":[{"batb":[[0,1.47,4]],"ltp":1.41,"tv":173.97,"id":71847983}]}]}
{"op":"mcm","clk":"11793090594","pt":1723062685903,"mc":[{"id":"1.231540926","rc":[{"batb":[[0,1.45,10]],"ltp":1.41,"tv":173.97,"id":71847983}]}]}
{"op":"mcm","clk":"11793090712","pt":1723062689344,"mc":[{"id":"1.231540926","rc":[{"batb":[[0,1.46,4]],"ltp":1.41,"tv":173.97,"id":71847983}]}]}
{"op":"mcm","clk":"11793090832","pt":1723062692119,"mc":[{"id":"1.231540926","rc":[{"batb":[[0,1.45,10]],"ltp":1.41,"tv":173.97,"id":71847983}]}]}
{"op":"mcm","clk":"11793090921","pt":1723062694130,"mc":[{"id":"1.231540926","rc":[{"batb":[[0,1.46,4],[1,1.45,10],[2,1.44,19.66]],"ltp":1.41,"tv":173.97,"id":71847983}]}]}
{"op":"mcm","clk":"11793090963","pt":1723062695310,"mc":[{"id":"1.231540926","rc":[{"batb":[[1,1.44,19.66],[2,1.43,17.41]],"ltp":1.41,"tv":173.97,"id":71847983}]}]}
{"op":"mcm","clk":"11793091000","pt":1723062696648,"mc":[{"id":"1.231540926","rc":[{"batb":[[0,1.44,19.66],[1,1.43,17.41],[2,1.31,8.46]],"ltp":1.41,"tv":173.97,"id":71847983}]}]}
{"op":"mcm","clk":"11793091072","pt":1723062699318,"mc":[{"id":"1.231540926","rc":[{"batb":[[0,1.45,14],[1,1.44,19.66],[2,1.43,17.41]],"ltp":1.41,"tv":173.97,"id":71847983}]}]}
{"op":"mcm","clk":"11793091170","pt":1723062701831,"mc":[{"id":"1.231540926","rc":[{"batb":[[0,1.45,10]],"ltp":1.41,"tv":173.97,"id":71847983}]}]}
{"op":"mcm","clk":"11793091198","pt":1723062702653,"mc":[{"id":"1.231540926","rc":[{"batb":[[0,1.44,19.66],[1,1.43,17.41],[2,1.31,8.46]],"ltp":1.41,"tv":173.97,"id":71847983}]}]}
{"op":"mcm","clk":"11793091320","pt":1723062705635,"mc":[{"id":"1.231540926","rc":[{"batb":[[0,1.45,14],[1,1.44,19.66],[2,1.43,17.41]],"ltp":1.41,"tv":173.97,"id":71847983}]}]}
{"op":"mcm","clk":"11793091391","pt":1723062707950,"mc":[{"id":"1.231540926","rc":[{"batb":[[0,1.45,10]],"ltp":1.41,"tv":173.97,"id":71847983}]}]}
{"op":"mcm","clk":"11793091429","pt":1723062708931,"mc":[{"id":"1.231540926","rc":[{"batb":[[0,1.44,19.66],[1,1.43,17.41],[2,1.31,8.46]],"ltp":1.41,"tv":173.97,"id":71847983}]}]}
{"op":"mcm","clk":"11793091476","pt":1723062710220,"mc":[{"id":"1.231540926","rc":[{"batb":[[0,1.45,4],[1,1.44,19.66],[2,1.43,17.41]],"ltp":1.41,"tv":173.97,"id":71847983}]}]}
{"op":"mcm","clk":"11793091563","pt":1723062712738,"mc":[{"id":"1.231540926","rc":[{"batb":[[0,1.45,10]],"ltp":1.41,"tv":173.97,"id":71847983}]}]}
{"op":"mcm","clk":"11793091658","pt":1723062716135,"mc":[{"id":"1.231540926","rc":[{"batb":[[0,1.46,4]],"ltp":1.41,"tv":173.97,"id":71847983}]}]}
{"op":"mcm","clk":"11793091722","pt":1723062718145,"mc":[{"id":"1.231540926","rc":[{"batb":[[0,1.44,19.66],[1,1.43,17.41],[2,1.31,8.46]],"ltp":1.41,"tv":173.97,"id":71847983}]}]}
{"op":"mcm","clk":"11793091731","pt":1723062718450,"mc":[{"id":"1.231540926","rc":[{"batb":[[0,1.45,10],[1,1.44,19.66],[2,1.43,17.41]],"ltp":1.41,"tv":173.97,"id":71847983}]}]}
{"op":"mcm","clk":"11793091899","pt":1723062721952,"mc":[{"id":"1.231540926","rc":[{"batb":[[0,1.46,4]],"ltp":1.41,"tv":173.97,"id":71847983}]}]}
{"op":"mcm","clk":"11793091993","pt":1723062723558,"mc":[{"id":"1.231540926","rc":[{"batb":[[0,1.44,19.66],[1,1.43,17.41],[2,1.31,8.46]],"ltp":1.41,"tv":173.97,"id":71847983}]}]}
{"op":"mcm","clk":"11793092071","pt":1723062725046,"mc":[{"id":"1.231540926","rc":[{"batb":[[0,1.45,10],[1,1.44,19.66],[2,1.43,17.41]],"ltp":1.41,"tv":173.97,"id":71847983}]}]}
{"op":"mcm","clk":"11793092126","pt":1723062726282,"mc":[{"id":"1.231540926","rc":[{"batb":[[0,1.46,4],[1,1.45,10],[2,1.44,19.66]],"ltp":1.41,"tv":173.97,"id":71847983}]}]}
{"op":"mcm","clk":"11793092221","pt":1723062728546,"mc":[{"id":"1.231540926","rc":[{"batb":[[0,1.44,19.66],[1,1.43,17.41],[2,1.31,8.46]],"ltp":1.41,"tv":173.97,"id":71847983}]}]}
{"op":"mcm","clk":"11793092364","pt":1723062731994,"mc":[{"id":"1.231540926","rc":[{"batb":[[0,1.45,14],[1,1.44,19.66],[2,1.43,17.41]],"ltp":1.41,"tv":173.97,"id":71847983}]}]}
{"op":"mcm","clk":"11793092459","pt":1723062734567,"mc":[{"id":"1.231540926","rc":[{"batb":[[0,1.45,10]],"ltp":1.41,"tv":173.97,"id":71847983}]}]}
{"op":"mcm","clk":"11793092500","pt":1723062735755,"mc":[{"id":"1.231540926","rc":[{"batb":[[0,1.44,19.66],[1,1.43,17.41],[2,1.31,8.46]],"ltp":1.41,"tv":173.97,"id":71847983}]}]}
{"op":"mcm","clk":"11793092582","pt":1723062738174,"mc":[{"id":"1.231540926","rc":[{"batb":[[0,1.45,14],[1,1.44,19.66],[2,1.43,17.41]],"ltp":1.41,"tv":173.97,"id":71847983}]}]}
{"op":"mcm","clk":"11793092692","pt":1723062740595,"mc":[{"id":"1.231540926","rc":[{"batb":[[0,1.45,10]],"ltp":1.41,"tv":173.97,"id":71847983}]}]}
{"op":"mcm","clk":"11793092734","pt":1723062741579,"mc":[{"id":"1.231540926","rc":[{"batb":[[0,1.44,19.66],[1,1.43,17.41],[2,1.31,8.46]],"ltp":1.41,"tv":173.97,"id":71847983}]}]}
{"op":"mcm","clk":"11793092838","pt":1723062744409,"mc":[{"id":"1.231540926","rc":[{"batb":[[0,1.45,14],[1,1.44,19.66],[2,1.43,17.41]],"ltp":1.41,"tv":173.97,"id":71847983}]}]}
{"op":"mcm","clk":"11793092938","pt":1723062746671,"mc":[{"id":"1.231540926","rc":[{"batb":[[0,1.45,10]],"ltp":1.41,"tv":173.97,"id":71847983}]}]}
{"op":"mcm","clk":"11793093007","pt":1723062748061,"mc":[{"id":"1.231540926","rc":[{"batb":[[0,1.44,19.66],[1,1.43,17.41],[2,1.31,8.46]],"ltp":1.41,"tv":173.97,"id":71847983}]}]}
{"op":"mcm","clk":"11793093090","pt":1723062750577,"mc":[{"id":"1.231540926","rc":[{"batb":[[0,1.45,14],[1,1.44,19.66],[2,1.43,17.41]],"ltp":1.41,"tv":173.97,"id":71847983}]}]}
{"op":"mcm","clk":"11793093223","pt":1723062753611,"mc":[{"id":"1.231540926","rc":[{"batb":[[0,1.45,10]],"ltp":1.41,"tv":173.97,"id":71847983}]}]}
{"op":"mcm","clk":"11793093268","pt":1723062754595,"mc":[{"id":"1.231540926","rc":[{"batb":[[0,1.44,19.66],[1,1.43,17.41],[2,1.31,8.46]],"ltp":1.41,"tv":173.97,"id":71847983}]}]}
{"op":"mcm","clk":"11793093360","pt":1723062756510,"mc":[{"id":"1.231540926","rc":[{"batb":[[0,1.45,4],[1,1.44,19.66],[2,1.43,17.41]],"ltp":1.41,"tv":173.97,"id":71847983}]}]}
{"op":"mcm","clk":"11793093438","pt":1723062757797,"mc":[{"id":"1.231540926","rc":[{"batb":[[0,1.46,10],[1,1.45,4],[2,1.44,19.66]],"ltp":1.41,"tv":173.97,"id":71847983}]}]}
{"op":"mcm","clk":"11793093488","pt":1723062758775,"mc":[{"id":"1.231540926","rc":[{"batb":[[1,1.44,19.66],[2,1.43,17.41]],"ltp":1.41,"tv":173.97,"id":71847983}]}]}
{"op":"mcm","clk":"11793093587","pt":1723062761495,"mc":[{"id":"1.231540926","rc":[{"batb":[[0,1.45,4]],"ltp":1.41,"tv":173.97,"id":71847983}]}]}
{"op":"mcm","clk":"11793093679","pt":1723062763917,"mc":[{"id":"1.231540926","rc":[{"batb":[[0,1.45,10]],"ltp":1.41,"tv":173.97,"id":71847983}]}]}
{"op":"mcm","clk":"11793093771","pt":1723062766490,"mc":[{"id":"1.231540926","rc":[{"batb":[[0,1.46,4],[1,1.45,10],[2,1.44,19.66]],"ltp":1.41,"tv":173.97,"id":71847983}]}]}
{"op":"mcm","clk":"11793093791","pt":1723062767207,"mc":[{"id":"1.231540926","rc":[{"batb":[[1,1.44,19.66],[2,1.43,17.41]],"ltp":1.41,"tv":173.97,"id":71847983}]}]}
{"op":"mcm","clk":"11793093843","pt":1723062768723,"mc":[{"id":"1.231540926","rc":[{"batb":[[0,1.44,19.66],[1,1.43,17.41],[2,1.31,8.46]],"ltp":1.41,"tv":173.97,"id":71847983}]}]}
{"op":"mcm","clk":"11793093890","pt":1723062770004,"mc":[{"id":"1.231540926","rc":[{"batb":[[0,1.45,10],[1,1.44,19.66],[2,1.43,17.41]],"ltp":1.41,"tv":173.97,"id":71847983}]}]}
{"op":"mcm","clk":"11793093969","pt":1723062771906,"mc":[{"id":"1.231540926","rc":[{"batb":[[0,1.46,4],[1,1.45,10],[2,1.44,19.66]],"ltp":1.41,"tv":173.97,"id":71847983}]}]}
{"op":"mcm","clk":"11793094023","pt":1723062773295,"mc":[{"id":"1.231540926","rc":[{"batb":[[1,1.44,19.66],[2,1.43,17.41]],"ltp":1.41,"tv":173.97,"id":71847983}]}]}
{"op":"mcm","clk":"11793094054","pt":1723062774319,"mc":[{"id":"1.231540926","rc":[{"batb":[[0,1.44,19.66],[1,1.43,17.41],[2,1.31,8.46]],"ltp":1.41,"tv":173.97,"id":71847983}]}]}
{"op":"mcm","clk":"11793094166","pt":1723062777302,"mc":[{"id":"1.231540926","rc":[{"batb":[[0,1.45,14],[1,1.44,19.66],[2,1.43,17.41]],"ltp":1.41,"tv":173.97,"id":71847983}]}]}
{"op":"mcm","clk":"11793094279","pt":1723062779617,"mc":[{"id":"1.231540926","rc":[{"batb":[[0,1.45,10]],"ltp":1.41,"tv":173.97,"id":71847983}]}]}
{"op":"mcm","clk":"11793094316","pt":1723062780436,"mc":[{"id":"1.231540926","rc":[{"batb":[[0,1.44,19.66],[1,1.43,17.41],[2,1.31,8.46]],"ltp":1.41,"tv":173.97,"id":71847983}]}]}
{"op":"mcm","clk":"11793094430","pt":1723062783328,"mc":[{"id":"1.231540926","rc":[{"batb":[[0,1.45,14],[1,1.44,19.66],[2,1.43,17.41]],"ltp":1.41,"tv":173.97,"id":71847983}]}]}
{"op":"mcm","clk":"11793094544","pt":1723062785645,"mc":[{"id":"1.231540926","rc":[{"batb":[[0,1.45,10]],"ltp":1.41,"tv":173.97,"id":71847983}]}]}
{"op":"mcm","clk":"11793094579","pt":1723062786519,"mc":[{"id":"1.231540926","rc":[{"batb":[[0,1.44,19.66],[1,1.43,17.41],[2,1.31,8.46]],"ltp":1.41,"tv":173.97,"id":71847983}]}]}
{"op":"mcm","clk":"11793094681","pt":1723062789150,"mc":[{"id":"1.231540926","rc":[{"batb":[[0,1.45,4],[1,1.44,19.66],[2,1.43,17.41]],"ltp":1.41,"tv":173.97,"id":71847983}]}]}
{"op":"mcm","clk":"11793094688","pt":1723062789253,"mc":[{"id":"1.231540926","rc":[{"batb":[[0,1.45,14]],"ltp":1.41,"tv":173.97,"id":71847983}]}]}
{"op":"mcm","clk":"11793094806","pt":1723062791430,"mc":[{"id":"1.231540926","rc":[{"batb":[[0,1.45,10]],"ltp":1.41,"tv":173.97,"id":71847983}]}]}
{"op":"mcm","clk":"11793094847","pt":1723062792527,"mc":[{"id":"1.231540926","rc":[{"batb":[[0,1.44,19.66],[1,1.43,17.41],[2,1.31,8.46]],"ltp":1.41,"tv":173.97,"id":71847983}]}]}
{"op":"mcm","clk":"11793094871","pt":1723062793656,"mc":[{"id":"1.231540926","rc":[{"batb":[[0,1.45,4],[1,1.44,19.66],[2,1.43,17.41]],"ltp":1.41,"tv":173.97,"id":71847983}]}]}
{"op":"mcm","clk":"11793094941","pt":1723062795859,"mc":[{"id":"1.231540926","rc":[{"batb":[[0,1.46,10]],"ltp":1.41,"tv":173.97,"id":71847983}]}]}
{"op":"mcm","clk":"11793095109","pt":1723062799157,"mc":[{"id":"1.231540926","rc":[{"batb":[[0,1.47,4]],"ltp":1.41,"tv":173.97,"id":71847983}]}]}
{"op":"mcm","clk":"11793095212","pt":1723062800857,"mc":[{"id":"1.231540926","rc":[{"batb":[[0,1.44,19.66],[1,1.43,17.41],[2,1.31,8.46]],"ltp":1.41,"tv":173.97,"id":71847983}]}]}
{"op":"mcm","clk":"11793095288","pt":1723062802142,"mc":[{"id":"1.231540926","rc":[{"batb":[[0,1.45,10],[1,1.44,19.66],[2,1.43,17.41]],"ltp":1.41,"tv":173.97,"id":71847983}]}]}
{"op":"mcm","clk":"11793095405","pt":1723062804564,"mc":[{"id":"1.231540926","rc":[{"batb":[[0,1.46,4],[1,1.45,10],[2,1.44,19.66]],"ltp":1.41,"tv":173.97,"id":71847983}]}]}
{"op":"mcm","clk":"11793095432","pt":1723062805333,"mc":[{"id":"1.231540926","rc":[{"batb":[[1,1.44,19.66],[2,1.43,17.41]],"ltp":1.41,"tv":173.97,"id":71847983}]}]}
{"op":"mcm","clk":"11793095541","pt":1723062807746,"mc":[{"id":"1.231540926","rc":[{"batb":[[0,1.45,10]],"ltp":1.41,"tv":173.97,"id":71847983}]}]}
{"op":"mcm","clk":"11793095654","pt":1723062809964,"mc":[{"id":"1.231540926","rc":[{"batb":[[0,1.46,4],[1,1.45,10],[2,1.44,19.66]],"ltp":1.41,"tv":173.97,"id":71847983}]}]}
{"op":"mcm","clk":"11793095721","pt":1723062811250,"mc":[{"id":"1.231540926","rc":[{"batb":[[1,1.44,19.66],[2,1.43,17.41]],"ltp":1.41,"tv":173.97,"id":71847983}]}]}
{"op":"mcm","clk":"11793095782","pt":1723062812536,"mc":[{"id":"1.231540926","rc":[{"batb":[[0,1.44,19.66],[1,1.43,17.41],[2,1.31,8.46]],"ltp":1.41,"tv":173.97,"id":71847983}]}]}
{"op":"mcm","clk":"11793095890","pt":1723062814951,"mc":[{"id":"1.231540926","rc":[{"batb":[[0,1.45,14],[1,1.44,19.66],[2,1.43,17.41]],"ltp":1.41,"tv":173.97,"id":71847983}]}]}
{"op":"mcm","clk":"11793095988","pt":1723062817167,"mc":[{"id":"1.231540926","rc":[{"batb":[[0,1.45,10]],"ltp":1.41,"tv":173.97,"id":71847983}]}]}
{"op":"mcm","clk":"11793096044","pt":1723062818453,"mc":[{"id":"1.231540926","rc":[{"batb":[[0,1.44,19.66],[1,1.43,17.41],[2,1.31,8.46]],"ltp":1.41,"tv":173.97,"id":71847983}]}]}
{"op":"mcm","clk":"11793096107","pt":1723062820150,"mc":[{"id":"1.231540926","rc":[{"batb":[[0,1.46,8.46],[1,1.45,4],[2,1.44,19.66]],"ltp":1.41,"tv":173.97,"id":71847983}]}]}
{"op":"mcm","clk":"11793096187","pt":1723062822151,"mc":[{"id":"1.231540926","rc":[{"batb":[[0,1.47,10],[1,1.46,8.46],[2,1.45,4]],"ltp":1.41,"tv":173.97,"id":71847983}]}]}
{"op":"mcm","clk":"11793096206","pt":1723062822666,"mc":[{"id":"1.231540926","rc":[{"batb":[[2,1.44,19.66]],"ltp":1.41,"tv":173.97,"id":71847983}]}]}
{"op":"mcm","clk":"11793096312","pt":1723062825654,"mc":[{"id":"1.231540926","rc":[{"batb":[[0,1.47,4]],"ltp":1.41,"tv":173.97,"id":71847983}]}]}
{"op":"mcm","clk":"11793096410","pt":1723062827867,"mc":[{"id":"1.231540926","rc":[{"batb":[[0,1.46,8.46],[1,1.44,19.66],[2,1.43,17.41]],"ltp":1.41,"tv":173.97,"id":71847983}]}]}
{"op":"mcm","clk":"11793096457","pt":1723062829095,"mc":[{"id":"1.231540926","rc":[{"batb":[[0,1.47,10],[1,1.46,8.46],[2,1.44,19.66]],"ltp":1.41,"tv":173.97,"id":71847983},{"batb":[[0,1.26,10],[1,1.25,100],[2,1.19,20]],"ltp":1.51,"tv":165.8,"id":19144236}]}]}
{"op":"mcm","clk":"11793096485","pt":1723062830180,"mc":[{"id":"1.231540926","rc":[{"batb":[[0,1.48,4],[1,1.47,10],[2,1.46,8.46]],"ltp":1.41,"tv":173.97,"id":71847983}]}]}
{"op":"mcm","clk":"11793096527","pt":1723062831466,"mc":[{"id":"1.231540926","rc":[{"batb":[[1,1.46,8.46],[2,1.44,19.66]],"ltp":1.41,"tv":173.97,"id":71847983}]}]}
{"op":"mcm","clk":"11793096574","pt":1723062832593,"mc":[{"id":"1.231540926","rc":[{"batb":[[0,1.46,8.46],[1,1.44,19.66],[2,1.43,17.41]],"ltp":1.41,"tv":173.97,"id":71847983}]}]}
{"op":"mcm","clk":"11793096653","pt":1723062833679,"mc":[{"id":"1.231540926","rc":[{"batb":[[0,1.47,10],[1,1.46,8.46],[2,1.44,19.66]],"ltp":1.41,"tv":173.97,"id":71847983}]}]}
{"op":"mcm","clk":"11793096694","pt":1723062834504,"mc":[{"id":"1.231540926","rc":[{"batb":[[0,1.51,10],[1,1.26,10],[2,1.25,100]],"ltp":1.51,"tv":165.8,"id":19144236}]}]}
{"op":"mcm","clk":"11793096739","pt":1723062836095,"mc":[{"id":"1.231540926","rc":[{"batb":[[0,1.48,4],[1,1.47,10],[2,1.46,8.46]],"ltp":1.41,"tv":173.97,"id":71847983}]}]}
{"op":"mcm","clk":"11793096766","pt":1723062836869,"mc":[{"id":"1.231540926","rc":[{"batb":[[1,1.46,8.46],[2,1.44,19.66]],"ltp":1.41,"tv":173.97,"id":71847983}]}]}
{"op":"mcm","clk":"11793096835","pt":1723062838674,"mc":[{"id":"1.231540926","rc":[{"batb":[[0,1.46,8.46],[1,1.44,19.66],[2,1.43,17.41]],"ltp":1.41,"tv":173.97,"id":71847983}]}]}
{"op":"mcm","clk":"11793096912","pt":1723062840984,"mc":[{"id":"1.231540926","rc":[{"batb":[[0,1.47,14],[1,1.46,8.46],[2,1.44,19.66]],"ltp":1.41,"tv":173.97,"id":71847983}]}]}
{"op":"mcm","clk":"11793097004","pt":1723062843203,"mc":[{"id":"1.231540926","rc":[{"batb":[[0,1.47,10]],"ltp":1.41,"tv":173.97,"id":71847983}]}]}
{"op":"mcm","clk":"11793097051","pt":1723062844392,"mc":[{"id":"1.231540926","rc":[{"batb":[[0,1.46,8.46],[1,1.44,19.66],[2,1.43,17.41]],"ltp":1.41,"tv":173.97,"id":71847983}]}]}
{"op":"mcm","clk":"11793097099","pt":1723062845521,"mc":[{"id":"1.231540926","rc":[{"batb":[[0,1.47,4],[1,1.46,8.46],[2,1.44,19.66]],"ltp":1.41,"tv":173.97,"id":71847983}]}]}
{"op":"mcm","clk":"11793097166","pt":1723062847785,"mc":[{"id":"1.231540926","rc":[{"batb":[[0,1.48,10]],"ltp":1.41,"tv":173.97,"id":71847983}]}]}
{"op":"mcm","clk":"11793097259","pt":1723062850819,"mc":[{"id":"1.231540926","rc":[{"batb":[[0,1.46,8.46],[1,1.44,19.66],[2,1.43,17.41]],"ltp":1.41,"tv":173.97,"id":71847983}]}]}
{"op":"mcm","clk":"11793097280","pt":1723062851282,"mc":[{"id":"1.231540926","rc":[{"batb":[[0,1.47,4],[1,1.46,8.46],[2,1.44,19.66]],"ltp":1.41,"tv":173.97,"id":71847983}]}]}
{"op":"mcm","clk":"11793097388","pt":1723062853802,"mc":[{"id":"1.231540926","rc":[{"batb":[[0,1.48,10]],"ltp":1.41,"tv":173.97,"id":71847983}]}]}
{"op":"mcm","clk":"11793097522","pt":1723062856888,"mc":[{"id":"1.231540926","rc":[{"batb":[[0,1.46,8.46],[1,1.44,19.66],[2,1.43,17.41]],"ltp":1.41,"tv":173.97,"id":71847983}]}]}
{"op":"mcm","clk":"11793097534","pt":1723062857312,"mc":[{"id":"1.231540926","rc":[{"batb":[[0,1.49,4],[1,1.46,8.46],[2,1.44,19.66]],"ltp":1.41,"tv":173.97,"id":71847983}]}]}
{"op":"mcm","clk":"11793097734","pt":1723062859931,"mc":[{"id":"1.231540926","rc":[{"batb":[[0,1.47,10]],"ltp":1.41,"tv":173.97,"id":71847983}]}]}
{"op":"mcm","clk":"11793097873","pt":1723062863122,"mc":[{"id":"1.231540926","rc":[{"batb":[[0,1.48,4]],"ltp":1.41,"tv":173.97,"id":71847983}]}]}
{"op":"mcm","clk":"11793097928","pt":1723062864616,"mc":[{"id":"1.231540926","rc":[{"batb":[[0,1.46,8.46],[1,1.44,19.66],[2,1.43,17.41]],"ltp":1.41,"tv":173.97,"id":71847983}]}]}
{"op":"mcm","clk":"11793098024","pt":1723062867443,"mc":[{"id":"1.231540926","rc":[{"batb":[[0,1.47,14],[1,1.46,8.46],[2,1.44,19.66]],"ltp":1.41,"tv":173.97,"id":71847983}]}]}
{"op":"mcm","clk":"11793098159","pt":1723062869815,"mc":[{"id":"1.231540926","rc":[{"batb":[[0,1.47,10]],"ltp":1.41,"tv":173.97,"id":71847983}]}]}
{"op":"mcm","clk":"11793098218","pt":1723062870841,"mc":[{"id":"1.231540926","rc":[{"batb":[[0,1.46,8.46],[1,1.44,19.66],[2,1.43,17.41]],"ltp":1.41,"tv":173.97,"id":71847983}]}]}
{"op":"mcm","clk":"11793098276","pt":1723062872132,"mc":[{"id":"1.231540926","rc":[{"batb":[[0,1.47,4],[1,1.46,8.46],[2,1.44,19.66]],"ltp":1.41,"tv":173.97,"id":71847983}]}]}
{"op":"mcm","clk":"11793098310","pt":1723062873253,"mc":[{"id":"1.231540926","rc":[{"batb":[[0,1.48,10],[1,1.47,4],[2,1.46,8.46]],"ltp":1.41,"tv":173.97,"id":71847983}]}]}
{"op":"mcm","clk":"11793098372","pt":1723062874540,"mc":[{"id":"1.231540926","rc":[{"batb":[[1,1.46,8.46],[2,1.44,19.66]],"ltp":1.41,"tv":173.97,"id":71847983}]}]}
{"op":"mcm","clk":"11793098479","pt":1723062876550,"mc":[{"id":"1.231540926","rc":[{"batb":[[0,1.46,8.46],[1,1.44,19.66],[2,1.43,17.41]],"ltp":1.41,"tv":173.97,"id":71847983}]}]}
{"op":"mcm","clk":"11793098546","pt":1723062877942,"mc":[{"id":"1.231540926","rc":[{"batb":[[0,1.47,4],[1,1.46,8.46],[2,1.44,19.66]],"ltp":1.41,"tv":173.97,"id":71847983}]}]}
