{"op":"mcm","clk":"11952311736","pt":1725017731094,"mc":[{"id":"1.232462894","marketDefinition":{"bspMarket":false,"turnInPlayEnabled":true,"persistenceEnabled":true,"marketBaseRate":5.0,"eventId":"33540261","eventTypeId":"4","numberOfWinners":1,"bettingType":"ODDS","marketType":"MATCH_ODDS","marketTime":"2024-08-31T05:45:00.000Z","suspendTime":"2024-08-31T05:45:00.000Z","bspReconciled":false,"complete":true,"inPlay":false,"crossMatching":false,"runnersVoidable":false,"numberOfActiveRunners":2,"betDelay":0,"status":"OPEN","runners":[{"status":"ACTIVE","sortPriority":1,"id":247649,"name":"Hong Kong"},{"status":"ACTIVE","sortPriority":2,"id":61044843,"name":"Mongolia"}],"regulators":["MR_INT"],"countryCode":"GB","discountAllowed":false,"timezone":"GMT","openDate":"2024-08-31T05:45:00.000Z","version":6107669610,"name":"Match Odds","eventName":"Hong Kong v Mongolia"},"rc":[{"batb":[[0,1.01,20]],"ltp":0.0,"tv":0.0,"id":247649},{"batb":[[0,1.01,20]],"ltp":0.0,"tv":0.0,"id":61044843}]}]}
{"op":"mcm","clk":"11952311747","pt":1725017731246,"mc":[{"id":"1.232462894","rc":[{"batb":[[0,1.03,200],[1,1.02,200],[2,1.01,220]],"ltp":0.0,"tv":0.0,"id":247649},{"batb":[[0,1.03,200],[1,1.02,200],[2,1.01,220]],"ltp":0.0,"tv":0.0,"id":61044843}]}]}
{"op":"mcm","clk":"11952311927","pt":1725017734219,"mc":[{"id":"1.232462894","marketDefinition":{"bspMarket":false,"turnInPlayEnabled":true,"persistenceEnabled":true,"marketBaseRate":5.0,"eventId":"33540261","eventTypeId":"4","numberOfWinners":1,"bettingType":"ODDS","marketType":"MATCH_ODDS","marketTime":"2024-08-31T05:45:00.000Z","suspendTime":"2024-08-31T05:45:00.000Z","bspReconciled":false,"complete":true,"inPlay":false,"crossMatching":false,"runnersVoidable":false,"numberOfActiveRunners":2,"betDelay":0,"status":"OPEN","runners":[{"status":"ACTIVE","sortPriority":1,"id":247649,"name":"Hong Kong"},{"status":"ACTIVE","sortPriority":2,"id":61044843,"name":"Mongolia"}],"regulators":["MR_INT"],"countryCode":"GB","discountAllowed":true,"timezone":"GMT","openDate":"2024-08-31T05:45:00.000Z","version":6107669610,"name":"Match Odds","eventName":"Hong Kong v Mongolia"}}]}
{"op":"mcm","clk":"11952361642","pt":1725018216391,"mc":[{"id":"1.232462894","rc":[{"batb":[[0,5.2,14],[1,1.03,200],[2,1.02,200]],"ltp":0.0,"tv":0.0,"id":61044843}]}]}
{"op":"mcm","clk":"11952371089","pt":1725018347075,"mc":[{"id":"1.232462894","rc":[{"batl":[[0,2,70]],"ltp":0.0,"tv":0.0,"id":247649}]}]}
{"op":"mcm","clk":"11952372817","pt":1725018370192,"mc":[{"id":"1.232462894","marketDefinition":{"bspMarket":false,"turnInPlayEnabled":true,"persistenceEnabled":true,"marketBaseRate":5.0,"eventId":"33540261","eventTypeId":"4","numberOfWinners":1,"bettingType":"ODDS","marketType":"MATCH_ODDS","marketTime":"2024-08-31T05:45:00.000Z","suspendTime":"2024-08-31T05:45:00.000Z","bspReconciled":false,"complete":true,"inPlay":false,"crossMatching":true,"runnersVoidable":false,"numberOfActiveRunners":2,"betDelay":0,"status":"OPEN","runners":[{"status":"ACTIVE","sortPriority":1,"id":247649,"name":"Hong Kong"},{"status":"ACTIVE","sortPriority":2,"id":61044843,"name":"Mongolia"}],"regulators":["MR_INT"],"countryCode":"GB","discountAllowed":true,"timezone":"GMT","openDate":"2024-08-31T05:45:00.000Z","version":6107669610,"name":"Match Odds","eventName":"Hong Kong v Mongolia"}}]}
{"op":"mcm","clk":"11952427572","pt":1725019119205,"mc":[{"id":"1.232462894","rc":[{"batl":[[0,1.18,55.38],[1,2,70]],"ltp":0.0,"tv":0.0,"id":247649}]}]}
{"op":"mcm","clk":"11952453149","pt":1725019500523,"mc":[{"id":"1.232462894","rc":[{"trd":[[1.03,400]],"batb":[[0,1.01,220],[1,1.02,0],[2,1.01,0]],"batl":[[0,1.03,226.67],[1,1.04,198.08],[2,1.18,55.38]],"ltp":1.03,"tv":400.0,"id":247649}],"tv":400.0}]}
{"op":"mcm","clk":"11952453640","pt":1725019506753,"mc":[{"id":"1.232462894","rc":[{"batl":[[0,1.03,424.75],[1,1.04,426.67]],"ltp":1.03,"tv":400.0,"id":247649}]}]}
{"op":"mcm","clk":"11952455891","pt":1725019537899,"mc":[{"id":"1.232462894","rc":[{"batl":[[0,1.03,198.08],[1,1.18,55.38],[2,2,70]],"ltp":1.03,"tv":400.0,"id":247649}]}]}
{"op":"mcm","clk":"11952461927","pt":1725019622001,"mc":[{"id":"1.232462894","rc":[{"batb":[[0,1.02,7.59],[1,1.01,220]],"ltp":1.03,"tv":400.0,"id":247649}]}]}
{"op":"mcm","clk":"11952466375","pt":1725019686669,"mc":[{"id":"1.232462894","rc":[{"batb":[[0,1.01,220],[1,1.01,0]],"ltp":1.03,"tv":400.0,"id":247649}]}]}
{"op":"mcm","clk":"11952469580","pt":1725019732206,"mc":[{"id":"1.232462894","rc":[{"batl":[[0,1.02,1792],[1,1.03,198.08],[2,1.18,55.38]],"ltp":1.03,"tv":400.0,"id":247649}]}]}
{"op":"mcm","clk":"11952469604","pt":1725019732519,"mc":[{"id":"1.232462894","rc":[{"batb":[[0,1.01,20]],"ltp":1.03,"tv":400.0,"id":247649}]}]}
{"op":"mcm","clk":"11952664105","pt":1725022167652,"mc":[{"id":"1.232462894","rc":[{"trd":[[1.01,40]],"batl":[[0,1.01,753.67],[1,1.02,1792],[2,1.03,198.08]],"ltp":1.01,"tv":440.0,"id":247649}],"tv":440.0}]}
{"op":"mcm","clk":"11952664336","pt":1725022169936,"mc":[{"id":"1.232462894","rc":[{"batl":[[1,1.02,2565.67]],"ltp":1.01,"tv":440.0,"id":247649}]}]}
{"op":"mcm","clk":"11952779408","pt":1725023575285,"mc":[{"id":"1.232462894","rc":[{"trd":[[1.01,40]],"batl":[[0,1.01,753.48],[1,1.02,2565.47]],"ltp":1.01,"tv":439.99,"id":247649}],"tv":439.99}]}
{"op":"mcm","clk":"11953066743","pt":1725027955391,"mc":[{"id":"1.232462894","rc":[{"trd":[[1.01,40.01]],"batl":[[0,1.01,753.79],[1,1.02,2565.79]],"ltp":1.01,"tv":440.0,"id":247649}],"tv":440.0}]}
{"op":"mcm","clk":"11953364198","pt":1725031904976,"mc":[{"id":"1.232462894","rc":[{"trd":[[1.01,42.18]],"batl":[[0,1.01,753.37],[1,1.02,2566.47]],"ltp":1.01,"tv":442.18,"id":247649},{"batb":[[1,1.04,1.05],[2,1.03,200]],"ltp":0.0,"tv":0.0,"id":61044843}],"tv":442.18}]}
{"op":"mcm","clk":"11953634456","pt":1725034375373,"mc":[{"id":"1.232462894","rc":[{"trd":[[1.01,42.14]],"batl":[[0,1.01,751.7],[1,1.02,2564.76]],"ltp":1.01,"tv":442.13,"id":247649}],"tv":442.13}]}
{"op":"mcm","clk":"11954200954","pt":1725038064893,"mc":[{"id":"1.232462894","rc":[{"trd":[[1.01,42.13]],"batl":[[0,1.01,751.66],[1,1.02,2564.72]],"ltp":1.01,"tv":442.13,"id":247649}],"tv":442.13}]}
{"op":"mcm","clk":"11954730299","pt":1725040685324,"mc":[{"id":"1.232462894","rc":[{"batl":[[0,1.01,2554.67]],"ltp":1.01,"tv":442.13,"id":247649}]}]}
{"op":"mcm","clk":"11954856149","pt":1725041370817,"mc":[{"id":"1.232462894","rc":[{"trd":[[1.01,42.14]],"batl":[[0,1.01,2555.99],[1,1.02,2565.12]],"ltp":1.01,"tv":442.14,"id":247649},{"batb":[[1,2.2,140.9],[2,1.04,1.05]],"ltp":0.0,"tv":0.0,"id":61044843}],"tv":442.14}]}
{"op":"mcm","clk":"11955060774","pt":1725042393852,"mc":[{"id":"1.232462894","rc":[{"trd":[[1.01,46.14]],"batl":[[0,1.01,2553.99]],"ltp":1.01,"tv":446.14,"id":247649}],"tv":446.14}]}
{"op":"mcm","clk":"11955062869","pt":1725042405165,"mc":[{"id":"1.232462894","rc":[{"batb":[[2,1.46,2]],"ltp":0.0,"tv":0.0,"id":61044843}]}]}
{"op":"mcm","clk":"11955546578","pt":1725044978669,"mc":[{"id":"1.232462894","rc":[{"trd":[[1.01,63.67]],"batl":[[0,1.01,2537.79],[1,1.02,2565.51]],"ltp":1.01,"tv":463.67,"id":247649},{"trd":[[100,0.18]],"batb":[[1,2.2,140.97]],"ltp":100.0,"tv":0.17,"id":61044843}],"tv":463.85}]}
{"op":"mcm","clk":"11955792768","pt":1725046384130,"mc":[{"id":"1.232462894","rc":[{"batl":[[0,1.01,4342.66]],"ltp":1.01,"tv":463.67,"id":247649}]}]}
{"op":"mcm","clk":"11956010334","pt":1725048246100,"mc":[{"id":"1.232462894","rc":[{"trd":[[1.01,400.33]],"batl":[[0,1.01,4172.08],[1,1.02,2565.12]],"ltp":1.01,"tv":800.32,"id":247649},{"batb":[[1,2.2,140.88]],"ltp":100.0,"tv":0.17,"id":61044843}],"tv":800.5}]}
{"op":"mcm","clk":"11956019085","pt":1725048343161,"mc":[{"id":"1.232462894","rc":[{"batb":[[1,2.34,168.34],[2,2.3,168.34]],"ltp":100.0,"tv":0.17,"id":61044843}]}]}
{"op":"mcm","clk":"11956235850","pt":1725050826523,"mc":[{"id":"1.232462894","rc":[{"trd":[[1.01,451.36]],"batl":[[0,1.01,4121.05]],"ltp":1.01,"tv":851.35,"id":247649},{"trd":[[100,0.69]],"ltp":100.0,"tv":0.69,"id":61044843}],"tv":852.05}]}
{"op":"mcm","clk":"11956242261","pt":1725050934943,"mc":[{"id":"1.232462894","rc":[{"trd":[[1.01,961.67]],"batl":[[0,1.01,3610.74]],"ltp":1.01,"tv":1361.66,"id":247649},{"trd":[[100,5.85]],"ltp":100.0,"tv":5.84,"id":61044843}],"tv":1367.51}]}
{"op":"mcm","clk":"11956377003","pt":1725053934506,"mc":[{"id":"1.232462894","rc":[{"trd":[[1.01,969.15]],"batl":[[0,1.01,3606.37],[1,1.02,2565]],"ltp":1.01,"tv":1369.15,"id":247649},{"batb":[[1,2.34,168.32],[2,2.3,168.32]],"ltp":100.0,"tv":5.84,"id":61044843}],"tv":1374.99}]}
{"op":"mcm","clk":"11956479440","pt":1725055975258,"mc":[{"id":"1.232462894","rc":[{"trd":[[1.01,969.2]],"batl":[[0,1.01,3606],[1,1.02,2564.92]],"ltp":1.01,"tv":1369.19,"id":247649},{"batb":[[1,2.34,168.45],[2,2.3,168.45]],"ltp":100.0,"tv":5.84,"id":61044843}],"tv":1375.04}]}
{"op":"mcm","clk":"11956510591","pt":1725056731350,"mc":[{"id":"1.232462894","rc":[{"trd":[[1.01,1136.74]],"batl":[[0,1.01,3522.23]],"ltp":1.01,"tv":1536.73,"id":247649}],"tv":1542.58}]}
{"op":"mcm","clk":"11956737762","pt":1725061684632,"mc":[{"id":"1.232462894","rc":[{"trd":[[1.01,1334.76]],"batl":[[0,1.01,3324.21]],"ltp":1.01,"tv":1734.75,"id":247649},{"trd":[[100,7.84]],"ltp":100.0,"tv":7.84,"id":61044843}],"tv":1742.6}]}
{"op":"mcm","clk":"11956951732","pt":1725065866195,"mc":[{"id":"1.232462894","rc":[{"trd":[[1.01,1376.34]],"batl":[[0,1.01,3282.63]],"ltp":1.01,"tv":1776.34,"id":247649},{"trd":[[100,8.26]],"ltp":100.0,"tv":8.26,"id":61044843}],"tv":1784.6}]}
{"op":"mcm","clk":"11956979148","pt":1725066375613,"mc":[{"id":"1.232462894","rc":[{"trd":[[1.01,1383.84]],"batl":[[0,1.01,3278.48],[1,1.02,2564.84]],"ltp":1.01,"tv":1783.84,"id":247649}],"tv":1792.1}]}
{"op":"mcm","clk":"11956986486","pt":1725066501017,"mc":[{"id":"1.232462894","rc":[{"batl":[[0,1000,0.84]],"ltp":100.0,"tv":8.26,"id":61044843}]}]}
{"op":"mcm","clk":"11956999635","pt":1725066745069,"mc":[{"id":"1.232462894","rc":[{"batl":[[0,1.01,3536.1]],"ltp":1.01,"tv":1783.84,"id":247649}]}]}
{"op":"mcm","clk":"11957056880","pt":1725067441856,"mc":[{"id":"1.232462894","rc":[{"batb":[[1,3.95,3.61],[2,2.34,168.45]],"batl":[[0,630,1.55],[1,1000,0.84]],"ltp":100.0,"tv":8.26,"id":61044843}]}]}
{"op":"mcm","clk":"11957057348","pt":1725067449176,"mc":[{"id":"1.232462894","rc":[{"batb":[[0,5.2,17.61],[1,2.34,168.45],[2,2.3,168.45]],"ltp":100.0,"tv":8.26,"id":61044843}]}]}
{"op":"mcm","clk":"11957078146","pt":1725067801606,"mc":[{"id":"1.232462894","rc":[{"batb":[[1,2.48,42.11],[2,2.34,168.45]],"ltp":100.0,"tv":8.26,"id":61044843}]}]}
{"op":"mcm","clk":"11957078275","pt":1725067804099,"mc":[{"id":"1.232462894","rc":[{"batb":[[2,2.3,168.45]],"ltp":100.0,"tv":8.26,"id":61044843}]}]}
{"op":"mcm","clk":"11957078335","pt":1725067805177,"mc":[{"id":"1.232462894","rc":[{"batb":[[2,2.38,42.11]],"ltp":100.0,"tv":8.26,"id":61044843}]}]}
{"op":"mcm","clk":"11957078412","pt":1725067806424,"mc":[{"id":"1.232462894","rc":[{"batb":[[1,2.72,42.11],[2,2.48,42.11]],"ltp":100.0,"tv":8.26,"id":61044843}]}]}
{"op":"mcm","clk":"11957106918","pt":1725068303458,"mc":[{"id":"1.232462894","rc":[{"batb":[[1,2.2,140.88],[2,1.46,2]],"ltp":100.0,"tv":8.26,"id":61044843}]}]}
{"op":"mcm","clk":"11957110890","pt":1725068371649,"mc":[{"id":"1.232462894","rc":[{"trd":[[1.01,1559.06]],"batl":[[0,1.01,3360.88]],"ltp":1.01,"tv":1959.05,"id":247649},{"trd":[[100,10.03]],"ltp":100.0,"tv":10.03,"id":61044843}],"tv":1969.08}]}
{"op":"mcm","clk":"11957132232","pt":1725068687925,"mc":[{"id":"1.232462894","rc":[{"batl":[[0,400,2.09],[1,630,1.55],[2,1000,0.84]],"ltp":100.0,"tv":10.03,"id":61044843}]}]}
{"op":"mcm","clk":"11957133444","pt":1725068709325,"mc":[{"id":"1.232462894","rc":[{"batl":[[2,1000,1.68]],"ltp":100.0,"tv":10.03,"id":61044843}]}]}
{"op":"mcm","clk":"11957133732","pt":1725068714227,"mc":[{"id":"1.232462894","rc":[{"batl":[[2,790,0.84]],"ltp":100.0,"tv":10.03,"id":61044843}]}]}
{"op":"mcm","clk":"11957142363","pt":1725068877651,"mc":[{"id":"1.232462894","rc":[{"batl":[[2,790,0]],"ltp":100.0,"tv":10.03,"id":61044843}]}]}
{"op":"mcm","clk":"11957142987","pt":1725068891284,"mc":[{"id":"1.232462894","rc":[{"batl":[[2,840,0.84]],"ltp":100.0,"tv":10.03,"id":61044843}]}]}
{"op":"mcm","clk":"11957173796","pt":1725069526926,"mc":[{"id":"1.232462894","rc":[{"batl":[[0,400,2.93]],"ltp":100.0,"tv":10.03,"id":61044843}]}]}
{"op":"mcm","clk":"11957207183","pt":1725070172186,"mc":[{"id":"1.232462894","rc":[{"batl":[[0,630,2.39],[1,840,0.84],[2,840,0]],"ltp":100.0,"tv":10.03,"id":61044843}]}]}
{"op":"mcm","clk":"11957210528","pt":1725070226776,"mc":[{"id":"1.232462894","rc":[{"batl":[[0,550,9.22],[1,630,1.55],[2,840,0.84]],"ltp":100.0,"tv":10.03,"id":61044843}]}]}
{"op":"mcm","clk":"11957210602","pt":1725070227904,"mc":[{"id":"1.232462894","rc":[{"batl":[[0,550,10.77],[1,840,0.84],[2,840,0]],"ltp":100.0,"tv":10.03,"id":61044843}]}]}
{"op":"mcm","clk":"11957234352","pt":1725070649096,"mc":[{"id":"1.232462894","rc":[{"batl":[[0,550,2.39]],"ltp":100.0,"tv":10.03,"id":61044843}]}]}
{"op":"mcm","clk":"11957273726","pt":1725071399146,"mc":[{"id":"1.232462894","rc":[{"trd":[[1.01,1642.83]],"batl":[[0,1.01,3319]],"ltp":1.01,"tv":2042.83,"id":247649}],"tv":2052.86}]}
{"op":"mcm","clk":"11957354848","pt":1725072631662,"mc":[{"id":"1.232462894","rc":[{"trd":[[1.01,1713.63]],"batl":[[0,1.01,3283.6]],"ltp":1.01,"tv":2113.63,"id":247649}],"tv":2123.66}]}
{"op":"mcm","clk":"11957357037","pt":1725072677155,"mc":[{"id":"1.232462894","rc":[{"batl":[[0,540,1.68]],"ltp":100.0,"tv":10.03,"id":61044843}]}]}
{"op":"mcm","clk":"11957357041","pt":1725072677255,"mc":[{"id":"1.232462894","rc":[{"batl":[[0,540,3.23]],"ltp":100.0,"tv":10.03,"id":61044843}]}]}
{"op":"mcm","clk":"11957357274","pt":1725072682341,"mc":[{"id":"1.232462894","rc":[{"batl":[[1,840,0]],"ltp":100.0,"tv":10.03,"id":61044843}]}]}
{"op":"mcm","clk":"11957357978","pt":1725072699366,"mc":[{"id":"1.232462894","rc":[{"batl":[[1,1000,0.84]],"ltp":100.0,"tv":10.03,"id":61044843}]}]}
{"op":"mcm","clk":"11957395994","pt":1725073627664,"mc":[{"id":"1.232462894","rc":[{"batl":[[0,530,2.39],[1,1000,1.68]],"ltp":100.0,"tv":10.03,"id":61044843}]}]}
{"op":"mcm","clk":"11957396296","pt":1725073635047,"mc":[{"id":"1.232462894","rc":[{"batl":[[0,520,2.39]],"ltp":100.0,"tv":10.03,"id":61044843}]}]}
{"op":"mcm","clk":"11957403222","pt":1725073782659,"mc":[{"id":"1.232462894","rc":[{"trd":[[1.01,1755.22]],"batl":[[0,1.01,3242.01]],"ltp":1.01,"tv":2155.21,"id":247649},{"trd":[[100,10.45]],"ltp":100.0,"tv":10.45,"id":61044843}],"tv":2165.67}]}
{"op":"mcm","clk":"11957451032","pt":1725074869520,"mc":[{"id":"1.232462894","rc":[{"trd":[[1.01,1797.1]],"batl":[[0,1.01,3221.07]],"ltp":1.01,"tv":2197.09,"id":247649}],"tv":2207.55}]}
{"op":"mcm","clk":"11957456894","pt":1725075037738,"mc":[{"id":"1.232462894","rc":[{"trd":[[1.01,1838.97]],"batl":[[0,1.01,3200.13]],"ltp":1.01,"tv":2238.97,"id":247649}],"tv":2249.42}]}
{"op":"mcm","clk":"11957484198","pt":1725075693687,"mc":[{"id":"1.232462894","rc":[{"trd":[[1.01,1847.77]],"batl":[[0,1.01,3191.33]],"ltp":1.01,"tv":2247.77,"id":247649},{"trd":[[100,10.54]],"ltp":100.0,"tv":10.54,"id":61044843}],"tv":2258.31}]}
{"op":"mcm","clk":"11957485109","pt":1725075711707,"mc":[{"id":"1.232462894","rc":[{"trd":[[1.01,1856.58]],"batl":[[0,1.01,3182.53]],"ltp":1.01,"tv":2256.57,"id":247649},{"trd":[[100,10.63]],"ltp":100.0,"tv":10.63,"id":61044843}],"tv":2267.2}]}
{"op":"mcm","clk":"11957492513","pt":1725075882513,"mc":[{"id":"1.232462894","rc":[{"trd":[[1.01,2023.92]],"batl":[[0,1.01,3098.86]],"ltp":1.01,"tv":2423.91,"id":247649}],"tv":2434.54}]}
{"op":"mcm","clk":"11957496518","pt":1725075965936,"mc":[{"id":"1.232462894","rc":[{"trd":[[1.01,2274.94]],"batl":[[0,1.01,2973.35]],"ltp":1.01,"tv":2674.93,"id":247649}],"tv":2685.56}]}
{"op":"mcm","clk":"11957497649","pt":1725075989981,"mc":[{"id":"1.232462894","rc":[{"trd":[[1.01,2358.62]],"batl":[[0,1.01,2931.51]],"ltp":1.01,"tv":2758.61,"id":247649}],"tv":2769.24}]}
{"op":"mcm","clk":"11957498097","pt":1725076001378,"mc":[{"id":"1.232462894","rc":[{"trd":[[1.01,2400.46]],"batl":[[0,1.01,2910.59]],"ltp":1.01,"tv":2800.45,"id":247649}],"tv":2811.08}]}
{"op":"mcm","clk":"11957498794","pt":1725076017569,"mc":[{"id":"1.232462894","rc":[{"trd":[[1.01,2408.83]],"batl":[[0,1.01,2906.4]],"ltp":1.01,"tv":2808.83,"id":247649}],"tv":2819.46}]}
{"op":"mcm","clk":"11957499065","pt":1725076023767,"mc":[{"id":"1.232462894","rc":[{"trd":[[1.01,2425.58]],"batl":[[0,1.01,2898.03]],"ltp":1.01,"tv":2825.57,"id":247649}],"tv":2836.2}]}
{"op":"mcm","clk":"11957528900","pt":1725076571097,"mc":[{"id":"1.232462894","rc":[{"trd":[[1.01,2466.17]],"batl":[[0,1.01,2857.44]],"ltp":1.01,"tv":2866.17,"id":247649},{"trd":[[100,11.04]],"ltp":100.0,"tv":11.04,"id":61044843}],"tv":2877.21}]}
{"op":"mcm","clk":"11957536727","pt":1725076731616,"mc":[{"id":"1.232462894","rc":[{"trd":[[1.01,2480.33]],"batl":[[0,1.01,2850.36]],"ltp":1.01,"tv":2880.33,"id":247649}],"tv":2891.37}]}
{"op":"mcm","clk":"11957537211","pt":1725076740652,"mc":[{"id":"1.232462894","rc":[{"trd":[[1.01,2655.54]],"batl":[[0,1.01,2675.15]],"ltp":1.01,"tv":3055.54,"id":247649},{"trd":[[100,12.81]],"ltp":100.0,"tv":12.81,"id":61044843}],"tv":3068.35}]}
{"op":"mcm","clk":"11957548494","pt":1725076875658,"mc":[{"id":"1.232462894","rc":[{"trd":[[1.01,2671.69]],"batl":[[0,1.01,2659]],"ltp":1.01,"tv":3071.69,"id":247649},{"trd":[[100,12.97]],"ltp":100.0,"tv":12.97,"id":61044843}],"tv":3084.66}]}
{"op":"mcm","clk":"11957558323","pt":1725077041696,"mc":[{"id":"1.232462894","rc":[{"trd":[[1.01,2680.49]],"batl":[[0,1.01,2650.2]],"ltp":1.01,"tv":3080.49,"id":247649},{"trd":[[100,13.06]],"ltp":100.0,"tv":13.06,"id":61044843}],"tv":3093.55}]}
{"op":"mcm","clk":"11957566886","pt":1725077212618,"mc":[{"id":"1.232462894","rc":[{"trd":[[1.01,2689.29]],"batl":[[0,1.01,2641.4]],"ltp":1.01,"tv":3089.29,"id":247649},{"trd":[[100,13.15]],"ltp":100.0,"tv":13.15,"id":61044843}],"tv":3102.44}]}
{"op":"mcm","clk":"11957605754","pt":1725077680665,"mc":[{"id":"1.232462894","rc":[{"trd":[[1.01,2691.41]],"batl":[[0,1.01,2640.34]],"ltp":1.01,"tv":3091.41,"id":247649}],"tv":3104.56}]}
{"op":"mcm","clk":"11957607582","pt":1725077716671,"mc":[{"id":"1.232462894","rc":[{"trd":[[1.01,2694.95]],"batl":[[0,1.01,2638.57]],"ltp":1.01,"tv":3094.95,"id":247649}],"tv":3108.1}]}
{"op":"mcm","clk":"11957608651","pt":1725077739701,"mc":[{"id":"1.232462894","rc":[{"trd":[[1.01,2701.32]],"batl":[[0,1.01,2635.39]],"ltp":1.01,"tv":3101.31,"id":247649}],"tv":3114.47}]}
{"op":"mcm","clk":"11957609138","pt":1725077750682,"mc":[{"id":"1.232462894","rc":[{"trd":[[1.01,2703.44]],"batl":[[0,1.01,2634.32]],"ltp":1.01,"tv":3103.44,"id":247649}],"tv":3116.59}]}
{"op":"mcm","clk":"11957611077","pt":1725077788728,"mc":[{"id":"1.232462894","rc":[{"trd":[[1.01,2710.52]],"batl":[[0,1.01,2630.78]],"ltp":1.01,"tv":3110.52,"id":247649}],"tv":3123.67}]}
{"op":"mcm","clk":"11957643939","pt":1725078416618,"mc":[{"id":"1.232462894","rc":[{"batl":[[0,520,3.23]],"ltp":100.0,"tv":13.15,"id":61044843}]}]}
{"op":"mcm","clk":"11957644000","pt":1725078418011,"mc":[{"id":"1.232462894","rc":[{"batl":[[0,500,2.39],[1,540,1.68],[2,1000,0.84]],"ltp":100.0,"tv":13.15,"id":61044843}]}]}
{"op":"mcm","clk":"11957647923","pt":1725078495281,"mc":[{"id":"1.232462894","rc":[{"trd":[[1.01,2727.28]],"batl":[[0,1.01,2622.41]],"ltp":1.01,"tv":3127.28,"id":247649}],"tv":3140.43}]}
{"op":"mcm","clk":"11957663391","pt":1725078842387,"mc":[{"id":"1.232462894","rc":[{"batl":[[1,1.02,10293.21]],"ltp":1.01,"tv":3127.28,"id":247649}]}]}
{"op":"mcm","clk":"11957663478","pt":1725078844800,"mc":[{"id":"1.232462894","rc":[{"batl":[[0,1.01,10350.78]],"ltp":1.01,"tv":3127.28,"id":247649}]}]}
{"op":"mcm","clk":"11957667829","pt":1725078943638,"mc":[{"id":"1.232462894","rc":[{"batl":[[0,500,2.47]],"ltp":100.0,"tv":13.15,"id":61044843}]}]}
{"op":"mcm","clk":"11957672211","pt":1725079054773,"mc":[{"id":"1.232462894","rc":[{"trd":[[1.01,2797.39]],"batl":[[0,1.01,10280.67]],"ltp":1.01,"tv":3197.38,"id":247649},{"trd":[[100,13.86]],"ltp":100.0,"tv":13.86,"id":61044843}],"tv":3211.24}]}
{"op":"mcm","clk":"11957673675","pt":1725079078684,"mc":[{"id":"1.232462894","rc":[{"batl":[[2,1.03,222.86]],"ltp":1.01,"tv":3197.38,"id":247649}]}]}
{"op":"mcm","clk":"11957677181","pt":1725079141444,"mc":[{"id":"1.232462894","rc":[{"batl":[[0,500,3.32],[1,1000,1.68],[2,1000,0]],"ltp":100.0,"tv":13.86,"id":61044843}]}]}
{"op":"mcm","clk":"11957677360","pt":1725079142934,"mc":[{"id":"1.232462894","rc":[{"batl":[[0,490,2.48],[1,540,1.68],[2,1000,0.84]],"ltp":100.0,"tv":13.86,"id":61044843}]}]}
{"op":"mcm","clk":"11957682844","pt":1725079281457,"mc":[{"id":"1.232462894","rc":[{"trd":[[1.01,3490.46]],"batl":[[0,1.01,9587.6]],"ltp":1.01,"tv":3890.45,"id":247649},{"trd":[[100,20.86]],"ltp":100.0,"tv":20.86,"id":61044843}],"tv":3911.31}]}
{"op":"mcm","clk":"11957693543","pt":1725079567266,"mc":[{"id":"1.232462894","rc":[{"batb":[[1,1.46,2],[2,1.04,1.05]],"ltp":100.0,"tv":20.86,"id":61044843}]}]}
{"op":"mcm","clk":"11957694103","pt":1725079581685,"mc":[{"id":"1.232462894","rc":[{"batb":[[1,2.2,329.5],[2,1.46,2]],"ltp":100.0,"tv":20.86,"id":61044843}]}]}
{"op":"mcm","clk":"11957717398","pt":1725080117667,"mc":[{"id":"1.232462894","rc":[{"trd":[[1.01,3512.41]],"batl":[[0,1.01,9565.66]],"ltp":1.01,"tv":3912.4,"id":247649},{"trd":[[100,21.08]],"ltp":100.0,"tv":21.08,"id":61044843}],"tv":3933.48}]}
{"op":"mcm","clk":"11957717968","pt":1725080130658,"mc":[{"id":"1.232462894","rc":[{"trd":[[1.01,3534.35]],"batl":[[0,1.01,9543.71]],"ltp":1.01,"tv":3934.35,"id":247649},{"trd":[[100,21.3]],"ltp":100.0,"tv":21.3,"id":61044843}],"tv":3955.65}]}
{"op":"mcm","clk":"11957720396","pt":1725080179046,"mc":[{"id":"1.232462894","rc":[{"trd":[[1.01,3618.13]],"batl":[[0,1.01,9501.82]],"ltp":1.01,"tv":4018.13,"id":247649}],"tv":4039.43}]}
{"op":"mcm","clk":"11957740060","pt":1725080604713,"mc":[{"id":"1.232462894","rc":[{"trd":[[1.01,3621.02]],"batl":[[0,1.01,9500.38]],"ltp":1.01,"tv":4021.01,"id":247649}],"tv":4042.32}]}
{"op":"mcm","clk":"11957745060","pt":1725080741668,"mc":[{"id":"1.232462894","rc":[{"batl":[[0,400,16.53],[1,490,2.39],[2,540,1.68]],"ltp":100.0,"tv":21.3,"id":61044843}]}]}
{"op":"mcm","clk":"11957746744","pt":1725080798240,"mc":[{"id":"1.232462894","rc":[{"trd":[[1.01,4457.78]],"batl":[[0,1.01,9082]],"ltp":1.01,"tv":4857.77,"id":247649}],"tv":4879.08}]}
{"op":"mcm","clk":"11957749758","pt":1725080889881,"mc":[{"id":"1.232462894","rc":[{"batl":[[0,400,17.37],[1,490,1.55]],"ltp":100.0,"tv":21.3,"id":61044843}]}]}
{"op":"mcm","clk":"11957749863","pt":1725080892766,"mc":[{"id":"1.232462894","rc":[{"batl":[[0,1.01,9084.95]],"ltp":1.01,"tv":4857.77,"id":247649}]}]}
{"op":"mcm","clk":"11957750000","pt":1725080896977,"mc":[{"id":"1.232462894","rc":[{"trd":[[1.01,4458.17]],"batl":[[0,1.01,9084.76]],"ltp":1.01,"tv":4858.16,"id":247649}],"tv":4879.47}]}
{"op":"mcm","clk":"11957750217","pt":1725080903393,"mc":[{"id":"1.232462894","rc":[{"trd":[[1.01,4458.56]],"batl":[[0,1.01,9084.56]],"ltp":1.01,"tv":4858.55,"id":247649}],"tv":4879.86}]}
{"op":"mcm","clk":"11957753916","pt":1725081014713,"mc":[{"id":"1.232462894","rc":[{"trd":[[1.01,4467.36]],"batl":[[0,1.01,9075.76]],"ltp":1.01,"tv":4867.35,"id":247649},{"trd":[[100,21.39]],"ltp":100.0,"tv":21.39,"id":61044843}],"tv":4888.75}]}
{"op":"mcm","clk":"11957758983","pt":1725081134659,"mc":[{"id":"1.232462894","rc":[{"trd":[[1.01,4476.16]],"batl":[[0,1.01,9066.96]],"ltp":1.01,"tv":4876.15,"id":247649},{"trd":[[100,21.48]],"ltp":100.0,"tv":21.48,"id":61044843}],"tv":4897.64}]}
{"op":"mcm","clk":"11957759399","pt":1725081142661,"mc":[{"id":"1.232462894","rc":[{"batb":[[0,5.2,14]],"batl":[[1,540,1.68],[2,1000,0.84]],"ltp":100.0,"tv":21.48,"id":61044843}]}]}
{"op":"mcm","clk":"11957760678","pt":1725081172698,"mc":[{"id":"1.232462894","rc":[{"trd":[[1.01,4511.16]],"batl":[[0,1.01,9031.96]],"ltp":1.01,"tv":4911.16,"id":247649},{"trd":[[100,21.83]],"ltp":100.0,"tv":21.83,"id":61044843}],"tv":4932.99}]}
{"op":"mcm","clk":"11957763229","pt":1725081242091,"mc":[{"id":"1.232462894","rc":[{"batl":[[0,400,16.53]],"ltp":100.0,"tv":21.83,"id":61044843}]}]}
{"op":"mcm","clk":"11957763641","pt":1725081254518,"mc":[{"id":"1.232462894","rc":[{"batl":[[0,400,17.37]],"ltp":100.0,"tv":21.83,"id":61044843}]}]}
{"op":"mcm","clk":"11957770419","pt":1725081397405,"mc":[{"id":"1.232462894","rc":[{"batl":[[0,220,4.19],[1,400,17.37],[2,540,1.68]],"ltp":100.0,"tv":21.83,"id":61044843}]}]}
{"op":"mcm","clk":"11957770561","pt":1725081401678,"mc":[{"id":"1.232462894","rc":[{"batl":[[0,1.01,9183.98]],"ltp":1.01,"tv":4911.16,"id":247649}]}]}
{"op":"mcm","clk":"11957771895","pt":1725081424132,"mc":[{"id":"1.232462894","rc":[{"batb":[[1,3.95,3.61],[2,2.2,329.5]],"batl":[[1,380,1.55],[2,400,17.37]],"ltp":100.0,"tv":21.83,"id":61044843}]}]}
{"op":"mcm","clk":"11957772316","pt":1725081431326,"mc":[{"id":"1.232462894","rc":[{"batb":[[0,5.2,17.61],[1,2.2,329.5],[2,1.46,2]],"ltp":100.0,"tv":21.83,"id":61044843}]}]}
{"op":"mcm","clk":"11957776299","pt":1725081502034,"mc":[{"id":"1.232462894","rc":[{"trd":[[1.01,4519.54]],"batl":[[0,1.01,9179.79]],"ltp":1.01,"tv":4919.54,"id":247649}],"tv":4941.37}]}
{"op":"mcm","clk":"11957777764","pt":1725081527570,"mc":[{"id":"1.232462894","rc":[{"trd":[[1.01,4602.71]],"batl":[[0,1.01,9096.62]],"ltp":1.01,"tv":5002.71,"id":247649},{"trd":[[100,22.67]],"ltp":100.0,"tv":22.67,"id":61044843}],"tv":5025.38}]}
{"op":"mcm","clk":"11957777971","pt":1725081531664,"mc":[{"id":"1.232462894","rc":[{"trd":[[1.01,4638.12]],"batl":[[0,1.01,9078.92]],"ltp":1.01,"tv":5038.11,"id":247649}],"tv":5060.79}]}
{"op":"mcm","clk":"11957778440","pt":1725081542673,"mc":[{"id":"1.232462894","rc":[{"batl":[[0,220,4.29]],"ltp":100.0,"tv":22.67,"id":61044843}]}]}
{"op":"mcm","clk":"11957778625","pt":1725081547120,"mc":[{"id":"1.232462894","rc":[{"batl":[[0,200,8.38],[1,220,4.29],[2,380,1.55]],"ltp":100.0,"tv":22.67,"id":61044843}]}]}
{"op":"mcm","clk":"11957780816","pt":1725081600751,"mc":[{"id":"1.232462894","rc":[{"batl":[[0,200,8.48],[1,220,4.19]],"ltp":100.0,"tv":22.67,"id":61044843}]}]}
{"op":"mcm","clk":"11957781485","pt":1725081617978,"mc":[{"id":"1.232462894","rc":[{"batl":[[0,160,8.38],[1,200,8.48],[2,220,4.19]],"ltp":100.0,"tv":22.67,"id":61044843}]}]}
{"op":"mcm","clk":"11957781686","pt":1725081622717,"mc":[{"id":"1.232462894","rc":[{"batl":[[1,220,4.29],[2,380,1.55]],"ltp":100.0,"tv":22.67,"id":61044843}]}]}
{"op":"mcm","clk":"11957782145","pt":1725081634129,"mc":[{"id":"1.232462894","rc":[{"trd":[[1.01,4647.79]],"batl":[[0,1.01,9069.25]],"ltp":1.01,"tv":5047.78,"id":247649},{"trd":[[100,22.77]],"ltp":100.0,"tv":22.77,"id":61044843}],"tv":5070.56}]}
{"op":"mcm","clk":"11957782563","pt":1725081643814,"mc":[{"id":"1.232462894","rc":[{"trd":[[1.01,4834.5]],"batl":[[0,1.01,8971.06]],"ltp":1.01,"tv":5234.5,"id":247649},{"trd":[[100,22.87]],"ltp":100.0,"tv":22.87,"id":61044843}],"tv":5257.37}]}
{"op":"mcm","clk":"11957782614","pt":1725081645146,"mc":[{"id":"1.232462894","rc":[{"batl":[[0,160,8.48]],"ltp":100.0,"tv":22.87,"id":61044843}]}]}
{"op":"mcm","clk":"11957782923","pt":1725081654044,"mc":[{"id":"1.232462894","rc":[{"trd":[[1.01,4853.84]],"batl":[[0,1.01,8951.71]],"ltp":1.01,"tv":5253.84,"id":247649},{"trd":[[100,23.07]],"ltp":100.0,"tv":23.06,"id":61044843}],"tv":5276.91}]}
{"op":"mcm","clk":"11957782990","pt":1725081655940,"mc":[{"id":"1.232462894","rc":[{"batl":[[0,220,4.39],[1,380,1.55],[2,400,17.37]],"ltp":100.0,"tv":23.06,"id":61044843}]}]}
{"op":"mcm","clk":"11957783406","pt":1725081665469,"mc":[{"id":"1.232462894","rc":[{"batl":[[0,220,4.49]],"ltp":100.0,"tv":23.06,"id":61044843}]}]}
{"op":"mcm","clk":"11957785536","pt":1725081707404,"mc":[{"id":"1.232462894","rc":[{"batl":[[0,220,4.58]],"ltp":100.0,"tv":23.06,"id":61044843}]}]}
{"op":"mcm","clk":"11957786270","pt":1725081723840,"mc":[{"id":"1.232462894","rc":[{"trd":[[1.01,4863.52]],"batl":[[0,1.01,8942.04]],"ltp":1.01,"tv":5263.51,"id":247649},{"trd":[[100,23.16]],"ltp":100.0,"tv":23.16,"id":61044843}],"tv":5286.67}]}
{"op":"mcm","clk":"11957787411","pt":1725081751159,"mc":[{"id":"1.232462894","rc":[{"trd":[[1.01,4873.19]],"batl":[[0,1.01,8932.37]],"ltp":1.01,"tv":5273.18,"id":247649},{"trd":[[100,23.26]],"ltp":100.0,"tv":23.26,"id":61044843}],"tv":5296.44}]}
{"op":"mcm","clk":"11957787453","pt":1725081752496,"mc":[{"id":"1.232462894","rc":[{"trd":[[1.01,4882.86]],"batl":[[0,1.01,8922.7]],"ltp":1.01,"tv":5282.85,"id":247649},{"trd":[[100,23.36]],"ltp":100.0,"tv":23.35,"id":61044843}],"tv":5306.21}]}
{"op":"mcm","clk":"11957787647","pt":1725081757081,"mc":[{"id":"1.232462894","rc":[{"trd":[[1.01,4886.51]],"batl":[[0,1.01,8920.88]],"ltp":1.01,"tv":5286.5,"id":247649}],"tv":5309.86}]}
{"op":"mcm","clk":"11957788172","pt":1725081769112,"mc":[{"id":"1.232462894","rc":[{"trd":[[1.01,4904.59]],"batl":[[0,1.01,8902.79]],"ltp":1.01,"tv":5304.59,"id":247649},{"trd":[[100,23.54]],"ltp":100.0,"tv":23.54,"id":61044843}],"tv":5328.13}]}
{"op":"mcm","clk":"11957788208","pt":1725081770091,"mc":[{"id":"1.232462894","rc":[{"trd":[[1.01,4908.24]],"batl":[[0,1.01,8900.97]],"ltp":1.01,"tv":5308.24,"id":247649}],"tv":5331.78}]}
{"op":"mcm","clk":"11957789595","pt":1725081805060,"mc":[{"id":"1.232462894","rc":[{"trd":[[1.01,4908.6]],"batl":[[0,1.01,8900.79]],"ltp":1.01,"tv":5308.6,"id":247649}],"tv":5332.14}]}
{"op":"mcm","clk":"11957789792","pt":1725081810359,"mc":[{"id":"1.232462894","rc":[{"trd":[[1.01,4908.97]],"batl":[[0,1.01,8900.61]],"ltp":1.01,"tv":5308.96,"id":247649}],"tv":5332.5}]}
{"op":"mcm","clk":"11957790117","pt":1725081818440,"mc":[{"id":"1.232462894","rc":[{"trd":[[1.01,4912.25]],"batl":[[0,1.01,8898.97]],"ltp":1.01,"tv":5312.25,"id":247649}],"tv":5335.79}]}
{"op":"mcm","clk":"11957790660","pt":1725081831387,"mc":[{"id":"1.232462894","rc":[{"trd":[[1.01,4912.99]],"batl":[[0,1.01,8898.6]],"ltp":1.01,"tv":5312.98,"id":247649}],"tv":5336.52}]}
{"op":"mcm","clk":"11957791197","pt":1725081844204,"mc":[{"id":"1.232462894","rc":[{"trd":[[1.01,4922.66]],"batl":[[0,1.01,8888.93]],"ltp":1.01,"tv":5322.65,"id":247649},{"trd":[[100,23.64]],"ltp":100.0,"tv":23.63,"id":61044843}],"tv":5346.29}]}
{"op":"mcm","clk":"11957791266","pt":1725081846304,"mc":[{"id":"1.232462894","rc":[{"trd":[[1.01,4923.75]],"batl":[[0,1.01,8888.38]],"ltp":1.01,"tv":5323.75,"id":247649}],"tv":5347.38}]}
{"op":"mcm","clk":"11957791946","pt":1725081862320,"mc":[{"id":"1.232462894","rc":[{"trd":[[1.01,4933.42]],"batl":[[0,1.01,8878.71]],"ltp":1.01,"tv":5333.42,"id":247649},{"trd":[[100,23.74]],"ltp":100.0,"tv":23.73,"id":61044843}],"tv":5357.15}]}
{"op":"mcm","clk":"11957792092","pt":1725081865823,"mc":[{"id":"1.232462894","rc":[{"trd":[[1.01,4937.07]],"batl":[[0,1.01,8876.89]],"ltp":1.01,"tv":5337.07,"id":247649}],"tv":5360.8}]}
{"op":"mcm","clk":"11957792193","pt":1725081868804,"mc":[{"id":"1.232462894","rc":[{"trd":[[1.01,4946.74]],"batl":[[0,1.01,8867.22]],"ltp":1.01,"tv":5346.74,"id":247649},{"trd":[[100,23.83]],"ltp":100.0,"tv":23.83,"id":61044843}],"tv":5370.57}]}
{"op":"mcm","clk":"11957792364","pt":1725081874247,"mc":[{"id":"1.232462894","rc":[{"trd":[[1.01,4948.57]],"batl":[[0,1.01,8866.3]],"ltp":1.01,"tv":5348.56,"id":247649}],"tv":5372.4}]}
{"op":"mcm","clk":"11957792746","pt":1725081884820,"mc":[{"id":"1.232462894","rc":[{"trd":[[1.01,5032.35]],"batl":[[0,1.01,8824.42]],"ltp":1.01,"tv":5432.34,"id":247649}],"tv":5456.17}]}
{"op":"mcm","clk":"11957793006","pt":1725081891035,"mc":[{"id":"1.232462894","rc":[{"trd":[[1.01,5032.54]],"batl":[[0,1.01,8824.32]],"ltp":1.01,"tv":5432.54,"id":247649}],"tv":5456.37}]}
{"op":"mcm","clk":"11957794024","pt":1725081914289,"mc":[{"id":"1.232462894","rc":[{"trd":[[1.01,5042.21]],"batl":[[0,1.01,8814.65]],"ltp":1.01,"tv":5442.21,"id":247649},{"trd":[[100,23.93]],"ltp":100.0,"tv":23.93,"id":61044843}],"tv":5466.14}]}
{"op":"mcm","clk":"11957795179","pt":1725081940720,"mc":[{"id":"1.232462894","rc":[{"batl":[[0,220,4.49]],"ltp":100.0,"tv":23.93,"id":61044843}]}]}
{"op":"mcm","clk":"11957795762","pt":1725081951632,"mc":[{"id":"1.232462894","rc":[{"trd":[[1.01,5061.55]],"batl":[[0,1.01,8795.31]],"ltp":1.01,"tv":5461.55,"id":247649},{"trd":[[100,24.13]],"ltp":100.0,"tv":24.12,"id":61044843}],"tv":5485.68}]}
{"op":"mcm","clk":"11957795804","pt":1725081952716,"mc":[{"id":"1.232462894","rc":[{"batl":[[0,220,4.58]],"ltp":100.0,"tv":24.12,"id":61044843}]}]}
{"op":"mcm","clk":"11957795958","pt":1725081955943,"mc":[{"id":"1.232462894","rc":[{"trd":[[1.01,5063.38]],"batl":[[0,1.01,8794.39]],"ltp":1.01,"tv":5463.37,"id":247649}],"tv":5487.5}]}
{"op":"mcm","clk":"11957796729","pt":1725081974584,"mc":[{"id":"1.232462894","rc":[{"trd":[[1.01,5073.05]],"batl":[[0,1.01,8784.72]],"ltp":1.01,"tv":5473.04,"id":247649},{"trd":[[100,24.22]],"ltp":100.0,"tv":24.22,"id":61044843}],"tv":5497.27}]}
{"op":"mcm","clk":"11957797254","pt":1725081986592,"mc":[{"id":"1.232462894","rc":[{"trd":[[1.01,5082.72]],"batl":[[0,1.01,8775.05]],"ltp":1.01,"tv":5482.71,"id":247649},{"trd":[[100,24.32]],"ltp":100.0,"tv":24.32,"id":61044843}],"tv":5507.04}]}
{"op":"mcm","clk":"11957799351","pt":1725082032057,"mc":[{"id":"1.232462894","rc":[{"trd":[[1.01,5084.54]],"batl":[[0,1.01,8774.14]],"ltp":1.01,"tv":5484.54,"id":247649}],"tv":5508.86}]}
{"op":"mcm","clk":"11957800363","pt":1725082055659,"mc":[{"id":"1.232462894","rc":[{"trd":[[1.01,5106.2]],"batl":[[0,1.01,8752.48]],"ltp":1.01,"tv":5506.2,"id":247649},{"trd":[[100,24.54]],"ltp":100.0,"tv":24.54,"id":61044843}],"tv":5530.74}]}
{"op":"mcm","clk":"11957800842","pt":1725082067186,"mc":[{"id":"1.232462894","rc":[{"trd":[[1.01,5115.88]],"batl":[[0,1.01,8742.81]],"ltp":1.01,"tv":5515.87,"id":247649},{"trd":[[100,24.64]],"ltp":100.0,"tv":24.63,"id":61044843}],"tv":5540.51}]}
{"op":"mcm","clk":"11957801152","pt":1725082074198,"mc":[{"id":"1.232462894","rc":[{"trd":[[1.01,5125.55]],"batl":[[0,1.01,8733.14]],"ltp":1.01,"tv":5525.54,"id":247649},{"trd":[[100,24.74]],"ltp":100.0,"tv":24.73,"id":61044843}],"tv":5550.28}]}
{"op":"mcm","clk":"11957801626","pt":1725082083695,"mc":[{"id":"1.232462894","rc":[{"trd":[[1.01,5141.69]],"batl":[[0,1.01,8716.99]],"ltp":1.01,"tv":5541.69,"id":247649},{"trd":[[100,24.9]],"ltp":100.0,"tv":24.89,"id":61044843}],"tv":5566.59}]}
{"op":"mcm","clk":"11957801937","pt":1725082088804,"mc":[{"id":"1.232462894","rc":[{"trd":[[1.01,5159.78]],"batl":[[0,1.01,8698.91]],"ltp":1.01,"tv":5559.77,"id":247649},{"trd":[[100,25.08]],"ltp":100.0,"tv":25.08,"id":61044843}],"tv":5584.86}]}
{"op":"mcm","clk":"11957803577","pt":1725082122936,"mc":[{"id":"1.232462894","rc":[{"trd":[[1.01,5169.45]],"batl":[[0,1.01,8689.24]],"ltp":1.01,"tv":5569.44,"id":247649},{"trd":[[100,25.18]],"ltp":100.0,"tv":25.18,"id":61044843}],"tv":5594.62}]}
{"op":"mcm","clk":"11957803596","pt":1725082123344,"mc":[{"id":"1.232462894","rc":[{"trd":[[1.01,5179.12]],"batl":[[0,1.01,8679.57]],"ltp":1.01,"tv":5579.11,"id":247649},{"trd":[[100,25.28]],"ltp":100.0,"tv":25.27,"id":61044843}],"tv":5604.39}]}
{"op":"mcm","clk":"11957804013","pt":1725082132348,"mc":[{"id":"1.232462894","rc":[{"trd":[[1.01,5182.77]],"batl":[[0,1.01,8677.74]],"ltp":1.01,"tv":5582.76,"id":247649}],"tv":5608.04}]}
{"op":"mcm","clk":"11957804311","pt":1725082139486,"mc":[{"id":"1.232462894","rc":[{"trd":[[1.01,5265.94]],"batl":[[0,1.01,8594.58]],"ltp":1.01,"tv":5665.93,"id":247649},{"trd":[[100,26.12]],"ltp":100.0,"tv":26.11,"id":61044843}],"tv":5692.05}]}
{"op":"mcm","clk":"11957804491","pt":1725082142804,"mc":[{"id":"1.232462894","rc":[{"trd":[[1.01,5269.59]],"batl":[[0,1.01,8592.75]],"ltp":1.01,"tv":5669.58,"id":247649}],"tv":5695.7}]}
{"op":"mcm","clk":"11957804942","pt":1725082151462,"mc":[{"id":"1.232462894","rc":[{"trd":[[1.01,5273.24]],"batl":[[0,1.01,8590.93]],"ltp":1.01,"tv":5673.23,"id":247649}],"tv":5699.35}]}
{"op":"mcm","clk":"11957805098","pt":1725082154761,"mc":[{"id":"1.232462894","rc":[{"trd":[[1.01,5282.04]],"batl":[[0,1.01,8582.13]],"ltp":1.01,"tv":5682.03,"id":247649},{"trd":[[100,26.21]],"ltp":100.0,"tv":26.2,"id":61044843}],"tv":5708.24}]}
{"op":"mcm","clk":"11957805405","pt":1725082160694,"mc":[{"id":"1.232462894","rc":[{"trd":[[1.01,5285.69]],"batl":[[0,1.01,8580.3]],"ltp":1.01,"tv":5685.68,"id":247649}],"tv":5711.89}]}
{"op":"mcm","clk":"11957805585","pt":1725082164404,"mc":[{"id":"1.232462894","rc":[{"trd":[[1.01,5295.36]],"batl":[[0,1.01,8570.63]],"ltp":1.01,"tv":5695.35,"id":247649},{"trd":[[100,26.3]],"ltp":100.0,"tv":26.3,"id":61044843}],"tv":5721.66}]}
{"op":"mcm","clk":"11957805957","pt":1725082172185,"mc":[{"id":"1.232462894","rc":[{"trd":[[1.01,5299.01]],"batl":[[0,1.01,8568.81]],"ltp":1.01,"tv":5699.0,"id":247649}],"tv":5725.31}]}
{"op":"mcm","clk":"11957807564","pt":1725082205923,"mc":[{"id":"1.232462894","rc":[{"trd":[[1.01,5466.55]],"batl":[[0,1.01,8485.04]],"ltp":1.01,"tv":5866.54,"id":247649}],"tv":5892.85}]}
{"op":"mcm","clk":"11957809243","pt":1725082235866,"mc":[{"id":"1.232462894","rc":[{"trd":[[1.01,5483.31]],"batl":[[0,1.01,8476.66]],"ltp":1.01,"tv":5883.3,"id":247649}],"tv":5909.61}]}
{"op":"mcm","clk":"11957809529","pt":1725082241962,"mc":[{"id":"1.232462894","rc":[{"trd":[[1.01,5484.84]],"batl":[[0,1.01,8475.89]],"ltp":1.01,"tv":5884.84,"id":247649}],"tv":5911.14}]}
{"op":"mcm","clk":"11957809783","pt":1725082246761,"mc":[{"id":"1.232462894","rc":[{"trd":[[1.01,5494.51]],"batl":[[0,1.01,8466.22]],"ltp":1.01,"tv":5894.51,"id":247649},{"trd":[[100,26.4]],"ltp":100.0,"tv":26.4,"id":61044843}],"tv":5920.91}]}
{"op":"mcm","clk":"11957810871","pt":1725082268022,"mc":[{"id":"1.232462894","rc":[{"trd":[[1.01,5496.34]],"batl":[[0,1.01,8465.31]],"ltp":1.01,"tv":5896.33,"id":247649}],"tv":5922.73}]}
{"op":"mcm","clk":"11957810956","pt":1725082269622,"mc":[{"id":"1.232462894","rc":[{"trd":[[1.01,5518]],"batl":[[0,1.01,8443.65]],"ltp":1.01,"tv":5917.99,"id":247649},{"trd":[[100,26.62]],"ltp":100.0,"tv":26.62,"id":61044843}],"tv":5944.61}]}
{"op":"mcm","clk":"11957811180","pt":1725082273802,"mc":[{"id":"1.232462894","rc":[{"trd":[[1.01,5519.82]],"batl":[[0,1.01,8442.74]],"ltp":1.01,"tv":5919.82,"id":247649}],"tv":5946.44}]}
{"op":"mcm","clk":"11957811285","pt":1725082276012,"mc":[{"id":"1.232462894","rc":[{"trd":[[1.01,5525.3]],"batl":[[0,1.01,8440]],"ltp":1.01,"tv":5925.29,"id":247649}],"tv":5951.91}]}
{"op":"mcm","clk":"11957812099","pt":1725082291701,"mc":[{"id":"1.232462894","rc":[{"trd":[[1.01,5528.95]],"batl":[[0,1.01,8438.18]],"ltp":1.01,"tv":5928.94,"id":247649}],"tv":5955.56}]}
{"op":"mcm","clk":"11957812772","pt":1725082304553,"mc":[{"id":"1.232462894","rc":[{"trd":[[1.01,5532.6]],"batl":[[0,1.01,8436.35]],"ltp":1.01,"tv":5932.59,"id":247649}],"tv":5959.21}]}
{"op":"mcm","clk":"11957813184","pt":1725082312161,"mc":[{"id":"1.232462894","rc":[{"batl":[[0,380,1.94],[1,400,17.37],[2,540,1.68]],"ltp":100.0,"tv":26.62,"id":61044843}]}]}
{"op":"mcm","clk":"11957813477","pt":1725082318172,"mc":[{"id":"1.232462894","rc":[{"batl":[[0,380,1.84]],"ltp":100.0,"tv":26.62,"id":61044843}]}]}
{"op":"mcm","clk":"11957813588","pt":1725082320358,"mc":[{"id":"1.232462894","rc":[{"trd":[[110,0.2]],"batb":[[0,5.2,18.51]],"batl":[[0,380,1.74]],"ltp":110.0,"tv":26.81,"id":61044843}],"tv":5959.41}]}
{"op":"mcm","clk":"11957813696","pt":1725082322256,"mc":[{"id":"1.232462894","rc":[{"trd":[[1.01,5549.36]],"batl":[[0,1.01,8427.98]],"ltp":1.01,"tv":5949.35,"id":247649}],"tv":5976.17}]}
{"op":"mcm","clk":"11957814544","pt":1725082338898,"mc":[{"id":"1.232462894","rc":[{"trd":[[120,0.2]],"batb":[[0,5.2,18.41]],"ltp":120.0,"tv":27.01,"id":61044843}],"tv":5976.37}]}
{"op":"mcm","clk":"11957814711","pt":1725082341988,"mc":[{"id":"1.232462894","rc":[{"trd":[[1.01,5557.73]],"batl":[[0,1.01,8423.79]],"ltp":1.01,"tv":5957.73,"id":247649}],"tv":5984.75}]}
{"op":"mcm","clk":"11957815307","pt":1725082354594,"mc":[{"id":"1.232462894","rc":[{"trd":[[130,0.2]],"batb":[[0,5.2,18.31]],"ltp":130.0,"tv":27.21,"id":61044843}],"tv":5984.94}]}
{"op":"mcm","clk":"11957815399","pt":1725082356191,"mc":[{"id":"1.232462894","rc":[{"batb":[[0,5.3,5.7],[1,5.2,14],[2,2.2,329.5]],"ltp":130.0,"tv":27.21,"id":61044843}]}]}
{"op":"mcm","clk":"11957815405","pt":1725082356303,"mc":[{"id":"1.232462894","rc":[{"batb":[[0,5.3,9.31]],"ltp":130.0,"tv":27.21,"id":61044843}]}]}
{"op":"mcm","clk":"11957815540","pt":1725082358871,"mc":[{"id":"1.232462894","rc":[{"batb":[[0,5.3,4.31]],"ltp":130.0,"tv":27.21,"id":61044843}]}]}
{"op":"mcm","clk":"11957815758","pt":1725082363320,"mc":[{"id":"1.232462894","rc":[{"batb":[[0,5.4,5.7],[1,5.3,3.61],[2,5.2,14]],"ltp":130.0,"tv":27.21,"id":61044843}]}]}
{"op":"mcm","clk":"11957815846","pt":1725082364805,"mc":[{"id":"1.232462894","rc":[{"batb":[[0,5.4,9.31],[1,5.2,14],[2,2.2,329.5]],"ltp":130.0,"tv":27.21,"id":61044843}]}]}
{"op":"mcm","clk":"11957815942","pt":1725082366708,"mc":[{"id":"1.232462894","rc":[{"batb":[[0,5.4,4.31]],"ltp":130.0,"tv":27.21,"id":61044843}]}]}
{"op":"mcm","clk":"11957816081","pt":1725082369802,"mc":[{"id":"1.232462894","rc":[{"batb":[[0,5.5,9.31]],"ltp":130.0,"tv":27.21,"id":61044843}]}]}
{"op":"mcm","clk":"11957816224","pt":1725082372584,"mc":[{"id":"1.232462894","rc":[{"batb":[[0,5.5,4.31]],"ltp":130.0,"tv":27.21,"id":61044843}]}]}
{"op":"mcm","clk":"11957816369","pt":1725082375598,"mc":[{"id":"1.232462894","rc":[{"batb":[[0,5.6,5.7],[1,5.5,3.61],[2,5.2,14]],"ltp":130.0,"tv":27.21,"id":61044843}]}]}
{"op":"mcm","clk":"11957816519","pt":1725082378989,"mc":[{"id":"1.232462894","rc":[{"batb":[[0,5.5,4.31],[1,5.2,14],[2,2.2,329.5]],"ltp":130.0,"tv":27.21,"id":61044843}]}]}
{"op":"mcm","clk":"11957816759","pt":1725082383208,"mc":[{"id":"1.232462894","rc":[{"trd":[[1.01,5558.32]],"batl":[[0,1.01,8423.49]],"ltp":1.01,"tv":5958.32,"id":247649},{"batb":[[0,5.6,5.7],[1,5.5,3.61],[2,5.2,14]],"ltp":130.0,"tv":27.21,"id":61044843}],"tv":5985.53}]}
{"op":"mcm","clk":"11957816922","pt":1725082385934,"mc":[{"id":"1.232462894","rc":[{"batb":[[0,5.5,4.31],[1,5.2,14],[2,2.2,329.5]],"ltp":130.0,"tv":27.21,"id":61044843}]}]}
{"op":"mcm","clk":"11957817068","pt":1725082388404,"mc":[{"id":"1.232462894","rc":[{"batb":[[0,5.6,5.7],[1,5.5,3.61],[2,5.2,14]],"ltp":130.0,"tv":27.21,"id":61044843}]}]}
{"op":"mcm","clk":"11957817244","pt":1725082391826,"mc":[{"id":"1.232462894","rc":[{"batb":[[0,5.5,4.31],[1,5.2,14],[2,2.2,329.5]],"ltp":130.0,"tv":27.21,"id":61044843}]}]}
{"op":"mcm","clk":"11957817541","pt":1725082397519,"mc":[{"id":"1.232462894","rc":[{"batb":[[0,5.6,5.7],[1,5.5,3.61],[2,5.2,14]],"ltp":130.0,"tv":27.21,"id":61044843}]}]}
{"op":"mcm","clk":"11957817581","pt":1725082398541,"mc":[{"id":"1.232462894","rc":[{"batb":[[0,5.7,5.63],[1,5.6,5],[2,5.5,3.61]],"ltp":130.0,"tv":27.21,"id":61044843}]}]}
{"op":"mcm","clk":"11957817674","pt":1725082400847,"mc":[{"id":"1.232462894","rc":[{"batb":[[1,5.5,3.61],[2,5.2,14]],"ltp":130.0,"tv":27.21,"id":61044843}]}]}
{"op":"mcm","clk":"11957818003","pt":1725082408132,"mc":[{"id":"1.232462894","rc":[{"batb":[[0,5.8,5.7],[1,5.7,4.93],[2,5.5,3.61]],"ltp":130.0,"tv":27.21,"id":61044843}]}]}
{"op":"mcm","clk":"11957818172","pt":1725082411529,"mc":[{"id":"1.232462894","rc":[{"batb":[[0,5.7,5.63],[1,5.5,3.61],[2,5.2,14]],"ltp":130.0,"tv":27.21,"id":61044843}]}]}
{"op":"mcm","clk":"11957818404","pt":1725082416153,"mc":[{"id":"1.232462894","rc":[{"trd":[[1.01,5566.7]],"batl":[[0,1.01,8419.31]],"ltp":1.01,"tv":5966.69,"id":247649}],"tv":5993.91}]}
{"op":"mcm","clk":"11957818414","pt":1725082416257,"mc":[{"id":"1.232462894","rc":[{"batb":[[0,5.8,5.7],[1,5.7,4.93],[2,5.5,3.61]],"ltp":130.0,"tv":27.21,"id":61044843}]}]}
{"op":"mcm","clk":"11957818497","pt":1725082417745,"mc":[{"id":"1.232462894","rc":[{"batb":[[0,5.9,5.45],[1,5.8,5],[2,5.7,4.93]],"ltp":130.0,"tv":27.21,"id":61044843}]}]}
{"op":"mcm","clk":"11957818594","pt":1725082419442,"mc":[{"id":"1.232462894","rc":[{"batb":[[1,5.7,4.93],[2,5.5,3.61]],"ltp":130.0,"tv":27.21,"id":61044843}]}]}
{"op":"mcm","clk":"11957818676","pt":1725082420824,"mc":[{"id":"1.232462894","rc":[{"trd":[[160,0.2]],"batb":[[0,5.9,5.35]],"ltp":160.0,"tv":27.41,"id":61044843}],"tv":5994.11}]}
{"op":"mcm","clk":"11957818851","pt":1725082424457,"mc":[{"id":"1.232462894","rc":[{"batb":[[0,6,5.6],[1,5.9,4.75],[2,5.7,4.93]],"ltp":160.0,"tv":27.41,"id":61044843}]}]}
{"op":"mcm","clk":"11957819007","pt":1725082427842,"mc":[{"id":"1.232462894","rc":[{"batb":[[0,5.9,5.35],[1,5.7,4.93],[2,5.5,3.61]],"ltp":160.0,"tv":27.41,"id":61044843}]}]}
{"op":"mcm","clk":"11957819114","pt":1725082430151,"mc":[{"id":"1.232462894","rc":[{"trd":[[1.01,5650.48]],"batl":[[0,1.01,8377.42]],"ltp":1.01,"tv":6050.47,"id":247649}],"tv":6077.88}]}
{"op":"mcm","clk":"11957819119","pt":1725082430256,"mc":[{"id":"1.232462894","rc":[{"trd":[[1.01,5650.67]],"batl":[[0,1.01,8377.32]],"ltp":1.01,"tv":6050.67,"id":247649},{"batb":[[0,6,5.6],[1,5.9,4.75],[2,5.7,4.93]],"ltp":160.0,"tv":27.41,"id":61044843}],"tv":6078.08}]}
{"op":"mcm","clk":"11957819184","pt":1725082431581,"mc":[{"id":"1.232462894","rc":[{"trd":[[160,0.4]],"batb":[[0,6,5.5]],"ltp":160.0,"tv":27.6,"id":61044843}],"tv":6078.28}]}
{"op":"mcm","clk":"11957819307","pt":1725082434173,"mc":[{"id":"1.232462894","rc":[{"trd":[[160,0.59]],"batb":[[0,5.9,5.15],[1,5.7,4.93],[2,5.6,5.06]],"ltp":160.0,"tv":27.8,"id":61044843}],"tv":6078.47}]}
{"op":"mcm","clk":"11957819313","pt":1725082434271,"mc":[{"id":"1.232462894","rc":[{"batb":[[0,5.6,5.46],[1,5.5,3.61],[2,5.2,14]],"ltp":160.0,"tv":27.8,"id":61044843}]}]}
{"op":"mcm","clk":"11957819415","pt":1725082436070,"mc":[{"id":"1.232462894","rc":[{"batb":[[0,5.7,5.4],[1,5.6,5.06],[2,5.5,3.61]],"ltp":160.0,"tv":27.8,"id":61044843}]}]}
{"op":"mcm","clk":"11957819597","pt":1725082439761,"mc":[{"id":"1.232462894","rc":[{"trd":[[1.01,5650.87]],"batl":[[0,1.01,8377.22]],"ltp":1.01,"tv":6050.86,"id":247649},{"batb":[[0,5.6,5.46],[1,5.5,3.61],[2,5.2,14]],"ltp":160.0,"tv":27.8,"id":61044843}],"tv":6078.67}]}
{"op":"mcm","clk":"11957819714","pt":1725082442260,"mc":[{"id":"1.232462894","rc":[{"batb":[[0,5.7,5.4],[1,5.6,5.06],[2,5.5,3.61]],"ltp":160.0,"tv":27.8,"id":61044843}]}]}
{"op":"mcm","clk":"11957819909","pt":1725082445650,"mc":[{"id":"1.232462894","rc":[{"batb":[[0,5.6,5.46],[1,5.5,3.61],[2,5.2,14]],"ltp":160.0,"tv":27.8,"id":61044843}]}]}
{"op":"mcm","clk":"11957820034","pt":1725082448476,"mc":[{"id":"1.232462894","rc":[{"batb":[[0,5.7,5.4],[1,5.6,5.06],[2,5.5,3.61]],"ltp":160.0,"tv":27.8,"id":61044843}]}]}
{"op":"mcm","clk":"11957820215","pt":1725082451760,"mc":[{"id":"1.232462894","rc":[{"batb":[[0,5.6,5.46],[1,5.5,3.61],[2,5.2,14]],"ltp":160.0,"tv":27.8,"id":61044843}]}]}
{"op":"mcm","clk":"11957820470","pt":1725082457593,"mc":[{"id":"1.232462894","rc":[{"batb":[[0,5.7,5.4],[1,5.6,5.06],[2,5.5,3.61]],"ltp":160.0,"tv":27.8,"id":61044843}]}]}
{"op":"mcm","clk":"11957820612","pt":1725082460868,"mc":[{"id":"1.232462894","rc":[{"batb":[[0,5.6,5.46],[1,5.5,3.61],[2,5.2,14]],"ltp":160.0,"tv":27.8,"id":61044843}]}]}
{"op":"mcm","clk":"11957820797","pt":1725082463700,"mc":[{"id":"1.232462894","rc":[{"trd":[[190,0.2]],"batb":[[0,5.7,5.3],[1,5.6,5.06],[2,5.5,3.61]],"batl":[[0,380,1.64]],"ltp":190.0,"tv":28.0,"id":61044843}],"tv":6078.87}]}
{"op":"mcm","clk":"11957821006","pt":1725082467188,"mc":[{"id":"1.232462894","rc":[{"batb":[[0,5.6,5.36],[1,5.5,3.61],[2,5.2,14]],"ltp":190.0,"tv":28.0,"id":61044843}]}]}
{"op":"mcm","clk":"11957821027","pt":1725082467599,"mc":[{"id":"1.232462894","rc":[{"trd":[[1.01,5651.23]],"batl":[[0,1.01,8377.04]],"ltp":1.01,"tv":6051.23,"id":247649}],"tv":6079.23}]}
{"op":"mcm","clk":"11957821233","pt":1725082471765,"mc":[{"id":"1.232462894","rc":[{"trd":[[190,0.52]],"batb":[[0,5.7,5.14],[1,5.6,5.06],[2,5.5,3.61]],"ltp":190.0,"tv":28.33,"id":61044843}],"tv":6079.56}]}
{"op":"mcm","clk":"11957821396","pt":1725082475095,"mc":[{"id":"1.232462894","rc":[{"batb":[[0,5.6,5.2],[1,5.5,3.61],[2,5.2,14]],"ltp":190.0,"tv":28.33,"id":61044843}]}]}
{"op":"mcm","clk":"11957821428","pt":1725082475914,"mc":[{"id":"1.232462894","rc":[{"trd":[[190,0.72]],"batb":[[0,5.6,5.1]],"ltp":190.0,"tv":28.52,"id":61044843}],"tv":6079.75}]}
{"op":"mcm","clk":"11957821486","pt":1725082477001,"mc":[{"id":"1.232462894","rc":[{"trd":[[1.01,5663.22]],"batl":[[0,1.01,8365.05]],"ltp":1.01,"tv":6063.22,"id":247649},{"trd":[[100,26.74],[190,0.8]],"batb":[[0,5.6,5.06]],"ltp":100.0,"tv":28.72,"id":61044843}],"tv":6091.95}]}
{"op":"mcm","clk":"11957821537","pt":1725082478180,"mc":[{"id":"1.232462894","rc":[{"batb":[[0,5.7,5],[1,5.6,5.06],[2,5.5,3.61]],"ltp":100.0,"tv":28.72,"id":61044843}]}]}
{"op":"mcm","clk":"11957821542","pt":1725082478278,"mc":[{"id":"1.232462894","rc":[{"batb":[[0,5.8,4.86],[1,5.7,5],[2,5.6,5.06]],"ltp":100.0,"tv":28.72,"id":61044843}]}]}
{"op":"mcm","clk":"11957821748","pt":1725082481620,"mc":[{"id":"1.232462894","rc":[{"batb":[[0,5.6,5.06],[1,5.5,3.61],[2,5.2,14]],"ltp":100.0,"tv":28.72,"id":61044843}]}]}
{"op":"mcm","clk":"11957821929","pt":1725082485206,"mc":[{"id":"1.232462894","rc":[{"batb":[[0,5.7,5],[1,5.6,5.06],[2,5.5,3.61]],"ltp":100.0,"tv":28.72,"id":61044843}]}]}
{"op":"mcm","clk":"11957821994","pt":1725082486185,"mc":[{"id":"1.232462894","rc":[{"batb":[[0,5.8,4.85],[1,5.7,5],[2,5.6,5.06]],"ltp":100.0,"tv":28.72,"id":61044843}]}]}
{"op":"mcm","clk":"11957822013","pt":1725082486488,"mc":[{"id":"1.232462894","rc":[{"batb":[[2,5.5,3.61]],"ltp":100.0,"tv":28.72,"id":61044843}]}]}
{"op":"mcm","clk":"11957822131","pt":1725082488900,"mc":[{"id":"1.232462894","rc":[{"batb":[[0,5.6,5.02],[1,5.5,3.61],[2,5.2,14]],"ltp":100.0,"tv":28.72,"id":61044843}]}]}
{"op":"mcm","clk":"11957822200","pt":1725082490296,"mc":[{"id":"1.232462894","rc":[{"trd":[[1.01,6499.98]],"batl":[[0,1.01,7946.67]],"ltp":1.01,"tv":6899.98,"id":247649}],"tv":6928.71}]}
{"op":"mcm","clk":"11957822253","pt":1725082491690,"mc":[{"id":"1.232462894","rc":[{"trd":[[1.01,6675.29]],"batl":[[0,1.01,7771.36]],"ltp":1.01,"tv":7075.29,"id":247649},{"trd":[[100,28.51]],"batb":[[0,5.8,5.51],[1,5.7,5],[2,5.6,5.02]],"ltp":100.0,"tv":30.49,"id":61044843}],"tv":7105.79}]}
{"op":"mcm","clk":"11957822348","pt":1725082494111,"mc":[{"id":"1.232462894","rc":[{"batl":[[0,300,2.19],[1,380,1.55],[2,400,17.37]],"ltp":100.0,"tv":30.49,"id":61044843}]}]}
{"op":"mcm","clk":"11957822410","pt":1725082495197,"mc":[{"id":"1.232462894","rc":[{"batb":[[0,5.6,5.02],[1,5.5,3.61],[2,5.2,14]],"ltp":100.0,"tv":30.49,"id":61044843}]}]}
{"op":"mcm","clk":"11957822427","pt":1725082495500,"mc":[{"id":"1.232462894","rc":[{"trd":[[1.01,6675.49]],"batl":[[0,1.01,7771.26]],"ltp":1.01,"tv":7075.49,"id":247649}],"tv":7105.99}]}
{"op":"mcm","clk":"11957822615","pt":1725082499101,"mc":[{"id":"1.232462894","rc":[{"batb":[[0,5.8,5.65],[1,5.7,5],[2,5.6,5.02]],"ltp":100.0,"tv":30.49,"id":61044843}]}]}
{"op":"mcm","clk":"11957822762","pt":1725082502509,"mc":[{"id":"1.232462894","rc":[{"trd":[[1.01,6685.16]],"batl":[[0,1.01,7761.59]],"ltp":1.01,"tv":7085.16,"id":247649},{"trd":[[100,28.61]],"batb":[[0,5.6,5.02],[1,5.5,3.61],[2,5.2,14]],"ltp":100.0,"tv":30.59,"id":61044843}],"tv":7115.75}]}
{"op":"mcm","clk":"11957822892","pt":1725082504925,"mc":[{"id":"1.232462894","rc":[{"batb":[[0,5.8,5.65],[1,5.7,5],[2,5.6,5.02]],"ltp":100.0,"tv":30.59,"id":61044843}]}]}
{"op":"mcm","clk":"11957823034","pt":1725082508115,"mc":[{"id":"1.232462894","rc":[{"batb":[[1,5.6,5.02],[2,5.5,3.61]],"ltp":100.0,"tv":30.59,"id":61044843}]}]}
{"op":"mcm","clk":"11957823047","pt":1725082508315,"mc":[{"id":"1.232462894","rc":[{"batb":[[0,5.6,5.02],[1,5.5,3.61],[2,5.2,14]],"ltp":100.0,"tv":30.59,"id":61044843}]}]}
{"op":"mcm","clk":"11957823443","pt":1725082515938,"mc":[{"id":"1.232462894","rc":[{"trd":[[1.01,6686.08]],"batl":[[0,1.01,7761.13]],"ltp":1.01,"tv":7086.07,"id":247649},{"batb":[[0,5.8,5.64],[1,5.7,5],[2,5.6,5.02]],"ltp":100.0,"tv":30.59,"id":61044843}],"tv":7116.67}]}
{"op":"mcm","clk":"11957823612","pt":1725082519034,"mc":[{"id":"1.232462894","rc":[{"batb":[[1,5.6,5.02],[2,5.5,3.61]],"ltp":100.0,"tv":30.59,"id":61044843}]}]}
{"op":"mcm","clk":"11957823621","pt":1725082519239,"mc":[{"id":"1.232462894","rc":[{"batb":[[0,5.6,5.02],[1,5.5,3.61],[2,5.2,14]],"ltp":100.0,"tv":30.59,"id":61044843}]}]}
{"op":"mcm","clk":"11957823920","pt":1725082525346,"mc":[{"id":"1.232462894","rc":[{"batb":[[0,5.8,5.63],[1,5.7,5],[2,5.6,5.02]],"ltp":100.0,"tv":30.59,"id":61044843}]}]}
{"op":"mcm","clk":"11957824074","pt":1725082528629,"mc":[{"id":"1.232462894","rc":[{"batb":[[0,5.6,5.02],[1,5.5,3.61],[2,5.2,14]],"ltp":100.0,"tv":30.59,"id":61044843}]}]}
{"op":"mcm","clk":"11957824186","pt":1725082531150,"mc":[{"id":"1.232462894","rc":[{"batb":[[0,6,5.43],[1,5.9,5.53],[2,5.8,5.62]],"ltp":100.0,"tv":30.59,"id":61044843}]}]}
{"op":"mcm","clk":"11957824192","pt":1725082531355,"mc":[{"id":"1.232462894","rc":[{"batb":[[0,5.8,5.62],[1,5.7,5],[2,5.6,5.02]],"ltp":100.0,"tv":30.59,"id":61044843}]}]}
{"op":"mcm","clk":"11957824289","pt":1725082534126,"mc":[{"id":"1.232462894","rc":[{"batb":[[1,5.6,5.02],[2,5.5,3.61]],"ltp":100.0,"tv":30.59,"id":61044843}]}]}
{"op":"mcm","clk":"11957824299","pt":1725082534333,"mc":[{"id":"1.232462894","rc":[{"batb":[[0,5.6,5.02],[1,5.5,3.61],[2,5.2,14]],"ltp":100.0,"tv":30.59,"id":61044843}]}]}
{"op":"mcm","clk":"11957824440","pt":1725082537155,"mc":[{"id":"1.232462894","rc":[{"trd":[[1.01,6689.73]],"batl":[[0,1.01,7759.31]],"ltp":1.01,"tv":7089.72,"id":247649},{"batb":[[0,5.9,5.52],[1,5.8,5.62],[2,5.7,5]],"ltp":100.0,"tv":30.59,"id":61044843}],"tv":7120.32}]}
{"op":"mcm","clk":"11957824453","pt":1725082537471,"mc":[{"id":"1.232462894","rc":[{"batb":[[0,5.8,5.62],[1,5.7,5],[2,5.6,5.02]],"ltp":100.0,"tv":30.59,"id":61044843}]}]}
{"op":"mcm","clk":"11957824626","pt":1725082540453,"mc":[{"id":"1.232462894","rc":[{"trd":[[1.01,6693.38]],"batl":[[0,1.01,7757.48]],"ltp":1.01,"tv":7093.37,"id":247649},{"batb":[[0,5.6,5.02],[1,5.5,3.61],[2,5.2,14]],"ltp":100.0,"tv":30.59,"id":61044843}],"tv":7123.97}]}
{"op":"mcm","clk":"11957824858","pt":1725082544968,"mc":[{"id":"1.232462894","rc":[{"batb":[[0,5.8,5.61],[1,5.7,5],[2,5.6,5.02]],"ltp":100.0,"tv":30.59,"id":61044843}]}]}
{"op":"mcm","clk":"11957824911","pt":1725082546252,"mc":[{"id":"1.232462894","rc":[{"trd":[[1.01,6697.03]],"batl":[[0,1.01,7755.66]],"ltp":1.01,"tv":7097.02,"id":247649}],"tv":7127.62}]}
{"op":"mcm","clk":"11957825021","pt":1725082548461,"mc":[{"id":"1.232462894","rc":[{"batb":[[0,5.6,5.02],[1,5.5,3.61],[2,5.2,14]],"ltp":100.0,"tv":30.59,"id":61044843}]}]}
{"op":"mcm","clk":"11957825137","pt":1725082550977,"mc":[{"id":"1.232462894","rc":[{"trd":[[1.01,6716.37]],"batl":[[0,1.01,7736.32]],"ltp":1.01,"tv":7116.36,"id":247649},{"trd":[[100,28.81]],"batb":[[0,5.8,5.62],[1,5.7,5],[2,5.6,5.02]],"ltp":100.0,"tv":30.79,"id":61044843}],"tv":7147.16}]}
{"op":"mcm","clk":"11957825150","pt":1725082551284,"mc":[{"id":"1.232462894","rc":[{"trd":[[1.01,6726.04]],"batl":[[0,1.01,7726.65]],"ltp":1.01,"tv":7126.03,"id":247649},{"trd":[[100,28.9]],"ltp":100.0,"tv":30.89,"id":61044843}],"tv":7156.93}]}
{"op":"mcm","clk":"11957825337","pt":1725082554472,"mc":[{"id":"1.232462894","rc":[{"batb":[[0,5.6,5.02],[1,5.5,3.61],[2,5.2,14]],"ltp":100.0,"tv":30.89,"id":61044843}]}]}
{"op":"mcm","clk":"11957825413","pt":1725082555856,"mc":[{"id":"1.232462894","rc":[{"trd":[[1.01,6809.82]],"batl":[[0,1.01,7684.76]],"ltp":1.01,"tv":7209.81,"id":247649}],"tv":7240.7}]}
{"op":"mcm","clk":"11957825499","pt":1725082557962,"mc":[{"id":"1.232462894","rc":[{"trd":[[1.01,6823.14]],"batl":[[0,1.01,7673.27]],"ltp":1.01,"tv":7223.13,"id":247649},{"trd":[[100,29]],"batb":[[0,5.8,5.7],[1,5.7,5],[2,5.6,5.02]],"ltp":100.0,"tv":30.98,"id":61044843}],"tv":7254.12}]}
{"op":"mcm","clk":"11957825572","pt":1725082559668,"mc":[{"id":"1.232462894","rc":[{"trd":[[1.01,6832.81]],"batl":[[0,1.01,7663.59]],"ltp":1.01,"tv":7232.8,"id":247649},{"trd":[[100,29.1]],"ltp":100.0,"tv":31.08,"id":61044843}],"tv":7263.89}]}
{"op":"mcm","clk":"11957825646","pt":1725082561200,"mc":[{"id":"1.232462894","rc":[{"batb":[[0,5.6,5.02],[1,5.5,3.61],[2,5.2,14]],"ltp":100.0,"tv":31.08,"id":61044843}]}]}
{"op":"mcm","clk":"11957825995","pt":1725082567517,"mc":[{"id":"1.232462894","rc":[{"trd":[[1.01,6836.46]],"batl":[[0,1.01,7661.77]],"ltp":1.01,"tv":7236.45,"id":247649},{"batb":[[0,5.8,5.7],[1,5.7,5],[2,5.6,5.02]],"ltp":100.0,"tv":31.08,"id":61044843}],"tv":7267.54}]}
{"op":"mcm","clk":"11957826165","pt":1725082571114,"mc":[{"id":"1.232462894","rc":[{"batb":[[0,5.6,5.02],[1,5.5,3.61],[2,5.2,14]],"ltp":100.0,"tv":31.08,"id":61044843}]}]}
{"op":"mcm","clk":"11957826355","pt":1725082575120,"mc":[{"id":"1.232462894","rc":[{"batb":[[0,5.7,5],[1,5.6,5.02],[2,5.5,3.61]],"ltp":100.0,"tv":31.08,"id":61044843}]}]}
{"op":"mcm","clk":"11957826410","pt":1725082576196,"mc":[{"id":"1.232462894","rc":[{"trd":[[1.01,6840.11]],"batl":[[0,1.01,7659.95]],"ltp":1.01,"tv":7240.1,"id":247649},{"batb":[[0,5.8,5.7],[1,5.7,5],[2,5.6,5.02]],"ltp":100.0,"tv":31.08,"id":61044843}],"tv":7271.19}]}
{"op":"mcm","clk":"11957826512","pt":1725082578704,"mc":[{"id":"1.232462894","rc":[{"batb":[[0,5.6,5.02],[1,5.5,3.61],[2,5.2,14]],"ltp":100.0,"tv":31.08,"id":61044843}]}]}
{"op":"mcm","clk":"11957826628","pt":1725082582117,"mc":[{"id":"1.232462894","rc":[{"batb":[[0,5.8,5.69],[1,5.7,5],[2,5.6,5.02]],"ltp":100.0,"tv":31.08,"id":61044843}]}]}
{"op":"mcm","clk":"11957826717","pt":1725082583610,"mc":[{"id":"1.232462894","rc":[{"trd":[[1.01,6849.78]],"batl":[[0,1.01,7650.28]],"ltp":1.01,"tv":7249.78,"id":247649},{"trd":[[100,29.2]],"ltp":100.0,"tv":31.18,"id":61044843}],"tv":7280.96}]}
{"op":"mcm","clk":"11957826777","pt":1725082584940,"mc":[{"id":"1.232462894","rc":[{"batb":[[0,5.6,5.02],[1,5.5,3.61],[2,5.2,14]],"ltp":100.0,"tv":31.18,"id":61044843}]}]}
{"op":"mcm","clk":"11957826871","pt":1725082587208,"mc":[{"id":"1.232462894","rc":[{"batb":[[0,5.8,5.7],[1,5.7,5],[2,5.6,5.02]],"ltp":100.0,"tv":31.18,"id":61044843}]}]}
{"op":"mcm","clk":"11957827003","pt":1725082590743,"mc":[{"id":"1.232462894","rc":[{"batb":[[0,5.6,5.02],[1,5.5,3.61],[2,5.2,14]],"ltp":100.0,"tv":31.18,"id":61044843}]}]}
{"op":"mcm","clk":"11957827130","pt":1725082594135,"mc":[{"id":"1.232462894","rc":[{"batb":[[0,5.7,5],[1,5.6,5.02],[2,5.5,3.61]],"ltp":100.0,"tv":31.18,"id":61044843}]}]}
{"op":"mcm","clk":"11957827159","pt":1725082594646,"mc":[{"id":"1.232462894","rc":[{"batb":[[0,5.8,5.69],[1,5.7,5],[2,5.6,5.02]],"ltp":100.0,"tv":31.18,"id":61044843}]}]}
{"op":"mcm","clk":"11957827283","pt":1725082597730,"mc":[{"id":"1.232462894","rc":[{"batb":[[0,5.6,5.02],[1,5.5,3.61],[2,5.2,14]],"ltp":100.0,"tv":31.18,"id":61044843}]}]}
{"op":"mcm","clk":"11957827457","pt":1725082602046,"mc":[{"id":"1.232462894","rc":[{"batb":[[0,5.8,5.68],[1,5.7,5],[2,5.6,5.02]],"ltp":100.0,"tv":31.18,"id":61044843}]}]}
{"op":"mcm","clk":"11957827626","pt":1725082605638,"mc":[{"id":"1.232462894","rc":[{"batb":[[0,5.6,5.02],[1,5.5,3.61],[2,5.2,14]],"ltp":100.0,"tv":31.18,"id":61044843}]}]}
{"op":"mcm","clk":"11957827720","pt":1725082608150,"mc":[{"id":"1.232462894","rc":[{"batb":[[0,5.8,5.67],[1,5.7,5],[2,5.6,5.02]],"ltp":100.0,"tv":31.18,"id":61044843}]}]}
{"op":"mcm","clk":"11957827859","pt":1725082611841,"mc":[{"id":"1.232462894","rc":[{"batb":[[0,5.6,5.02],[1,5.5,3.61],[2,5.2,14]],"ltp":100.0,"tv":31.18,"id":61044843}]}]}
{"op":"mcm","clk":"11957827907","pt":1725082612859,"mc":[{"id":"1.232462894","rc":[{"trd":[[1.01,6859.45]],"batl":[[0,1.01,7640.61]],"ltp":1.01,"tv":7259.45,"id":247649},{"trd":[[100,29.29]],"ltp":100.0,"tv":31.28,"id":61044843}],"tv":7290.73}]}
{"op":"mcm","clk":"11957827961","pt":1725082614145,"mc":[{"id":"1.232462894","rc":[{"batb":[[0,5.9,5.58],[1,5.8,5.68],[2,5.7,5]],"ltp":100.0,"tv":31.28,"id":61044843}]}]}
{"op":"mcm","clk":"11957827968","pt":1725082614345,"mc":[{"id":"1.232462894","rc":[{"batb":[[0,5.8,5.68],[1,5.7,5],[2,5.6,5.02]],"ltp":100.0,"tv":31.28,"id":61044843}]}]}
{"op":"mcm","clk":"11957828104","pt":1725082617533,"mc":[{"id":"1.232462894","rc":[{"batb":[[0,5.6,5.02],[1,5.5,3.61],[2,5.2,14]],"ltp":100.0,"tv":31.28,"id":61044843}]}]}
{"op":"mcm","clk":"11957828345","pt":1725082623959,"mc":[{"id":"1.232462894","rc":[{"batb":[[0,5.8,5.67],[1,5.7,5],[2,5.6,5.02]],"ltp":100.0,"tv":31.28,"id":61044843}]}]}
{"op":"mcm","clk":"11957828470","pt":1725082627086,"mc":[{"id":"1.232462894","rc":[{"batb":[[1,5.6,5.02],[2,5.5,3.61]],"ltp":100.0,"tv":31.28,"id":61044843}]}]}
{"op":"mcm","clk":"11957828481","pt":1725082627291,"mc":[{"id":"1.232462894","rc":[{"batb":[[0,5.6,5.02],[1,5.5,3.61],[2,5.2,14]],"ltp":100.0,"tv":31.28,"id":61044843}]}]}
{"op":"mcm","clk":"11957828619","pt":1725082630684,"mc":[{"id":"1.232462894","rc":[{"batb":[[0,5.8,5.66],[1,5.7,5],[2,5.6,5.02]],"ltp":100.0,"tv":31.28,"id":61044843}]}]}
{"op":"mcm","clk":"11957828748","pt":1725082633968,"mc":[{"id":"1.232462894","rc":[{"batb":[[0,5.6,5.02],[1,5.5,3.61],[2,5.2,14]],"ltp":100.0,"tv":31.28,"id":61044843}]}]}
{"op":"mcm","clk":"11957828913","pt":1725082637771,"mc":[{"id":"1.232462894","rc":[{"batb":[[0,5.8,5.65],[1,5.7,5],[2,5.6,5.02]],"ltp":100.0,"tv":31.28,"id":61044843}]}]}
{"op":"mcm","clk":"11957829013","pt":1725082639975,"mc":[{"id":"1.232462894","rc":[{"trd":[[1.01,6861.28]],"batl":[[0,1.01,7639.69]],"ltp":1.01,"tv":7261.27,"id":247649}],"tv":7292.55}]}
{"op":"mcm","clk":"11957829069","pt":1725082640995,"mc":[{"id":"1.232462894","rc":[{"batb":[[0,5.6,5.02],[1,5.5,3.61],[2,5.2,14]],"ltp":100.0,"tv":31.28,"id":61044843}]}]}
{"op":"mcm","clk":"11957829157","pt":1725082643206,"mc":[{"id":"1.232462894","rc":[{"batb":[[0,5.7,5],[1,5.6,5.02],[2,5.5,3.61]],"ltp":100.0,"tv":31.28,"id":61044843}]}]}
{"op":"mcm","clk":"11957829168","pt":1725082643408,"mc":[{"id":"1.232462894","rc":[{"batb":[[0,5.8,5.65],[1,5.7,5],[2,5.6,5.02]],"ltp":100.0,"tv":31.28,"id":61044843}]}]}
{"op":"mcm","clk":"11957829281","pt":1725082645871,"mc":[{"id":"1.232462894","rc":[{"trd":[[1.01,6902.07]],"batl":[[0,1.01,7599]],"ltp":1.01,"tv":7302.06,"id":247649},{"trd":[[100,29.7]],"ltp":100.0,"tv":31.69,"id":61044843}],"tv":7333.75}]}
{"op":"mcm","clk":"11957829321","pt":1725082646794,"mc":[{"id":"1.232462894","rc":[{"batb":[[0,5.6,5.02],[1,5.5,3.61],[2,5.2,14]],"ltp":100.0,"tv":31.69,"id":61044843}]}]}
{"op":"mcm","clk":"11957829455","pt":1725082649772,"mc":[{"id":"1.232462894","rc":[{"trd":[[1.01,6911.74]],"batl":[[0,1.01,7589.33]],"ltp":1.01,"tv":7311.73,"id":247649},{"trd":[[100,29.8]],"batb":[[0,5.8,5.68],[1,5.7,5],[2,5.6,5.02]],"ltp":100.0,"tv":31.78,"id":61044843}],"tv":7343.52}]}
{"op":"mcm","clk":"11957829610","pt":1725082653019,"mc":[{"id":"1.232462894","rc":[{"batb":[[0,5.6,5.02],[1,5.5,3.61],[2,5.2,14]],"ltp":100.0,"tv":31.78,"id":61044843}]}]}
{"op":"mcm","clk":"11957829729","pt":1725082655189,"mc":[{"id":"1.232462894","rc":[{"trd":[[1.01,6912.26]],"batl":[[0,1.01,7589.07]],"ltp":1.01,"tv":7312.26,"id":247649},{"batb":[[0,5.9,5.58],[1,5.8,5.68],[2,5.7,5]],"ltp":100.0,"tv":31.78,"id":61044843}],"tv":7344.05}]}
{"op":"mcm","clk":"11957829735","pt":1725082655389,"mc":[{"id":"1.232462894","rc":[{"batb":[[0,5.7,5],[1,5.5,3.61],[2,5.2,14]],"ltp":100.0,"tv":31.78,"id":61044843}]}]}
{"op":"mcm","clk":"11957829867","pt":1725082658290,"mc":[{"id":"1.232462894","rc":[{"batb":[[0,5.5,3.61],[1,5.2,14],[2,2.2,329.5]],"ltp":100.0,"tv":31.78,"id":61044843}]}]}
{"op":"mcm","clk":"11957829991","pt":1725082660806,"mc":[{"id":"1.232462894","rc":[{"batb":[[0,5.6,5],[1,5.5,3.61],[2,5.2,14]],"ltp":100.0,"tv":31.78,"id":61044843}]}]}
{"op":"mcm","clk":"11957830177","pt":1725082664218,"mc":[{"id":"1.232462894","rc":[{"batb":[[0,5.5,3.61],[1,5.2,14],[2,2.2,329.5]],"ltp":100.0,"tv":31.78,"id":61044843}]}]}
{"op":"mcm","clk":"11957830327","pt":1725082667812,"mc":[{"id":"1.232462894","rc":[{"batb":[[0,5.6,5],[1,5.5,3.61],[2,5.2,14]],"ltp":100.0,"tv":31.78,"id":61044843}]}]}
{"op":"mcm","clk":"11957830429","pt":1725082671044,"mc":[{"id":"1.232462894","rc":[{"batb":[[0,5.5,3.61],[1,5.2,14],[2,2.2,329.5]],"ltp":100.0,"tv":31.78,"id":61044843}]}]}
{"op":"mcm","clk":"11957830600","pt":1725082677008,"mc":[{"id":"1.232462894","rc":[{"batb":[[0,5.6,5],[1,5.5,3.61],[2,5.2,14]],"ltp":100.0,"tv":31.78,"id":61044843}]}]}
{"op":"mcm","clk":"11957830697","pt":1725082680537,"mc":[{"id":"1.232462894","rc":[{"batb":[[0,5.5,3.61],[1,5.2,14],[2,2.2,329.5]],"ltp":100.0,"tv":31.78,"id":61044843}]}]}
{"op":"mcm","clk":"11957830935","pt":1725082687420,"mc":[{"id":"1.232462894","rc":[{"batb":[[0,5.6,5],[1,5.5,3.61],[2,5.2,14]],"ltp":100.0,"tv":31.78,"id":61044843}]}]}
{"op":"mcm","clk":"11957831068","pt":1725082690659,"mc":[{"id":"1.232462894","rc":[{"batb":[[0,5.5,3.61],[1,5.2,14],[2,2.2,329.5]],"ltp":100.0,"tv":31.78,"id":61044843}]}]}
{"op":"mcm","clk":"11957831195","pt":1725082693836,"mc":[{"id":"1.232462894","rc":[{"batb":[[0,5.6,5],[1,5.5,3.61],[2,5.2,14]],"batl":[[2,400,16.53]],"ltp":100.0,"tv":31.78,"id":61044843}]}]}
{"op":"mcm","clk":"11957831279","pt":1725082697220,"mc":[{"id":"1.232462894","rc":[{"batb":[[0,5.5,3.61],[1,5.2,14],[2,2.2,329.5]],"ltp":100.0,"tv":31.78,"id":61044843}]}]}
{"op":"mcm","clk":"11957831375","pt":1725082700350,"mc":[{"id":"1.232462894","rc":[{"trd":[[1.01,6996.04]],"batl":[[0,1.01,7547.18]],"ltp":1.01,"tv":7396.04,"id":247649},{"batb":[[0,5.6,5],[1,5.5,3.61],[2,5.2,14]],"ltp":100.0,"tv":31.78,"id":61044843}],"tv":7427.83}]}
{"op":"mcm","clk":"11957831471","pt":1725082703758,"mc":[{"id":"1.232462894","rc":[{"batb":[[0,5.5,3.61],[1,5.2,14],[2,2.2,329.5]],"ltp":100.0,"tv":31.78,"id":61044843}]}]}
{"op":"mcm","clk":"11957831534","pt":1725082705442,"mc":[{"id":"1.232462894","rc":[{"batl":[[0,300,3.03]],"ltp":100.0,"tv":31.78,"id":61044843}]}]}
{"op":"mcm","clk":"11957831641","pt":1725082708678,"mc":[{"id":"1.232462894","rc":[{"batb":[[0,5.6,5],[1,5.5,3.61],[2,5.2,14]],"ltp":100.0,"tv":31.78,"id":61044843}]}]}
{"op":"mcm","clk":"11957831714","pt":1725082711963,"mc":[{"id":"1.232462894","rc":[{"batb":[[0,5.5,3.61],[1,5.2,14],[2,2.2,329.5]],"ltp":100.0,"tv":31.78,"id":61044843}]}]}
{"op":"mcm","clk":"11957831917","pt":1725082717781,"mc":[{"id":"1.232462894","rc":[{"batb":[[0,5.6,5],[1,5.5,3.61],[2,5.2,14]],"ltp":100.0,"tv":31.78,"id":61044843}]}]}
{"op":"mcm","clk":"11957832022","pt":1725082721169,"mc":[{"id":"1.232462894","rc":[{"batb":[[0,5.5,3.61],[1,5.2,14],[2,2.2,329.5]],"ltp":100.0,"tv":31.78,"id":61044843}]}]}
{"op":"mcm","clk":"11957832102","pt":1725082724261,"mc":[{"id":"1.232462894","rc":[{"batb":[[0,5.6,5],[1,5.5,3.61],[2,5.2,14]],"ltp":100.0,"tv":31.78,"id":61044843}]}]}
{"op":"mcm","clk":"11957832188","pt":1725082727696,"mc":[{"id":"1.232462894","rc":[{"batb":[[0,5.5,3.61],[1,5.2,14],[2,2.2,329.5]],"ltp":100.0,"tv":31.78,"id":61044843}]}]}
{"op":"mcm","clk":"11957832278","pt":1725082730676,"mc":[{"id":"1.232462894","rc":[{"batb":[[0,5.6,5],[1,5.5,3.61],[2,5.2,14]],"ltp":100.0,"tv":31.78,"id":61044843}]}]}
{"op":"mcm","clk":"11957832427","pt":1725082733967,"mc":[{"id":"1.232462894","rc":[{"batb":[[0,5.5,3.61],[1,5.2,14],[2,2.2,329.5]],"ltp":100.0,"tv":31.78,"id":61044843}]}]}
{"op":"mcm","clk":"11957832520","pt":1725082737404,"mc":[{"id":"1.232462894","rc":[{"batb":[[0,5.6,5],[1,5.5,3.61],[2,5.2,14]],"ltp":100.0,"tv":31.78,"id":61044843}]}]}
{"op":"mcm","clk":"11957832621","pt":1725082740799,"mc":[{"id":"1.232462894","rc":[{"batb":[[0,5.5,3.61],[1,5.2,14],[2,2.2,329.5]],"ltp":100.0,"tv":31.78,"id":61044843}]}]}
{"op":"mcm","clk":"11957832682","pt":1725082742708,"mc":[{"id":"1.232462894","rc":[{"trd":[[1.01,6996.77]],"batl":[[0,1.01,7546.81]],"ltp":1.01,"tv":7396.77,"id":247649}],"tv":7428.56}]}
{"op":"mcm","clk":"11957832762","pt":1725082744613,"mc":[{"id":"1.232462894","rc":[{"batb":[[0,5.6,5],[1,5.5,3.61],[2,5.2,14]],"ltp":100.0,"tv":31.78,"id":61044843}]}]}
{"op":"mcm","clk":"11957832862","pt":1725082747901,"mc":[{"id":"1.232462894","rc":[{"batb":[[0,5.5,3.61],[1,5.2,14],[2,2.2,329.5]],"ltp":100.0,"tv":31.78,"id":61044843}]}]}
{"op":"mcm","clk":"11957833049","pt":1725082753015,"mc":[{"id":"1.232462894","rc":[{"batb":[[0,5.6,5],[1,5.5,3.61],[2,5.2,14]],"ltp":100.0,"tv":31.78,"id":61044843}]}]}
{"op":"mcm","clk":"11957833142","pt":1725082756306,"mc":[{"id":"1.232462894","rc":[{"batb":[[0,5.5,3.61],[1,5.2,14],[2,2.2,329.5]],"ltp":100.0,"tv":31.78,"id":61044843}]}]}
{"op":"mcm","clk":"11957833199","pt":1725082758733,"mc":[{"id":"1.232462894","rc":[{"batb":[[0,5.6,5],[1,5.5,3.61],[2,5.2,14]],"ltp":100.0,"tv":31.78,"id":61044843}]}]}
{"op":"mcm","clk":"11957833317","pt":1725082762338,"mc":[{"id":"1.232462894","rc":[{"batb":[[0,5.5,3.61],[1,5.2,14],[2,2.2,329.5]],"ltp":100.0,"tv":31.78,"id":61044843}]}]}
{"op":"mcm","clk":"11957833374","pt":1725082764809,"mc":[{"id":"1.232462894","rc":[{"batb":[[0,5.6,5],[1,5.5,3.61],[2,5.2,14]],"ltp":100.0,"tv":31.78,"id":61044843}]}]}
{"op":"mcm","clk":"11957833499","pt":1725082767535,"mc":[{"id":"1.232462894","rc":[{"trd":[[1.01,7006.44]],"batl":[[0,1.01,7537.14]],"ltp":1.01,"tv":7406.44,"id":247649},{"trd":[[100,29.9]],"ltp":100.0,"tv":31.88,"id":61044843}],"tv":7438.33}]}
{"op":"mcm","clk":"11957833519","pt":1725082768250,"mc":[{"id":"1.232462894","rc":[{"trd":[[1.01,7016.11]],"batl":[[0,1.01,7527.47]],"ltp":1.01,"tv":7416.11,"id":247649},{"trd":[[100,30]],"batb":[[0,5.5,3.61],[1,5.2,14],[2,2.2,329.5]],"ltp":100.0,"tv":31.98,"id":61044843}],"tv":7448.09}]}
{"op":"mcm","clk":"11957833583","pt":1725082770544,"mc":[{"id":"1.232462894","rc":[{"batb":[[0,5.6,5],[1,5.5,3.61],[2,5.2,14]],"ltp":100.0,"tv":31.98,"id":61044843}]}]}
{"op":"mcm","clk":"11957833665","pt":1725082773852,"mc":[{"id":"1.232462894","rc":[{"batb":[[0,5.5,3.61],[1,5.2,14],[2,2.2,329.5]],"ltp":100.0,"tv":31.98,"id":61044843}]}]}
{"op":"mcm","clk":"11957833858","pt":1725082780340,"mc":[{"id":"1.232462894","rc":[{"batb":[[0,5.6,5],[1,5.5,3.61],[2,5.2,14]],"ltp":100.0,"tv":31.98,"id":61044843}]}]}
{"op":"mcm","clk":"11957833983","pt":1725082783837,"mc":[{"id":"1.232462894","rc":[{"batb":[[0,5.5,3.61],[1,5.2,14],[2,2.2,329.5]],"ltp":100.0,"tv":31.98,"id":61044843}]}]}
{"op":"mcm","clk":"11957834097","pt":1725082787635,"mc":[{"id":"1.232462894","rc":[{"batb":[[0,5.6,5],[1,5.5,3.61],[2,5.2,14]],"ltp":100.0,"tv":31.98,"id":61044843}]}]}
{"op":"mcm","clk":"11957834208","pt":1725082790962,"mc":[{"id":"1.232462894","rc":[{"batb":[[0,5.5,3.61],[1,5.2,14],[2,2.2,329.5]],"ltp":100.0,"tv":31.98,"id":61044843}]}]}
{"op":"mcm","clk":"11957834249","pt":1725082792139,"mc":[{"id":"1.232462894","rc":[{"trd":[[1.01,7025.79]],"batl":[[0,1.01,7517.8]],"ltp":1.01,"tv":7425.78,"id":247649},{"trd":[[100,30.09]],"ltp":100.0,"tv":32.08,"id":61044843}],"tv":7457.86}]}
{"op":"mcm","clk":"11957834494","pt":1725082799270,"mc":[{"id":"1.232462894","rc":[{"batb":[[0,5.6,5],[1,5.5,3.61],[2,5.2,14]],"ltp":100.0,"tv":32.08,"id":61044843}]}]}
{"op":"mcm","clk":"11957834533","pt":1725082800252,"mc":[{"id":"1.232462894","rc":[{"trd":[[1.01,7035.46]],"batl":[[0,1.01,7508.13]],"ltp":1.01,"tv":7435.45,"id":247649},{"trd":[[100,30.19]],"ltp":100.0,"tv":32.17,"id":61044843}],"tv":7467.63}]}
{"op":"mcm","clk":"11957834602","pt":1725082802474,"mc":[{"id":"1.232462894","rc":[{"batb":[[0,5.5,3.61],[1,5.2,14],[2,2.2,329.5]],"ltp":100.0,"tv":32.17,"id":61044843}]}]}
{"op":"mcm","clk":"11957834691","pt":1725082804999,"mc":[{"id":"1.232462894","rc":[{"batb":[[0,5.6,5],[1,5.5,3.61],[2,5.2,14]],"ltp":100.0,"tv":32.17,"id":61044843}]}]}
{"op":"mcm","clk":"11957834823","pt":1725082808290,"mc":[{"id":"1.232462894","rc":[{"batb":[[0,5.5,3.61],[1,5.2,14],[2,2.2,329.5]],"ltp":100.0,"tv":32.17,"id":61044843}]}]}
{"op":"mcm","clk":"11957835096","pt":1725082814568,"mc":[{"id":"1.232462894","rc":[{"batb":[[0,5.6,5],[1,5.5,3.61],[2,5.2,14]],"ltp":100.0,"tv":32.17,"id":61044843}]}]}
{"op":"mcm","clk":"11957835240","pt":1725082817967,"mc":[{"id":"1.232462894","rc":[{"batb":[[0,5.5,3.61],[1,5.2,14],[2,2.2,329.5]],"ltp":100.0,"tv":32.17,"id":61044843}]}]}
{"op":"mcm","clk":"11957835419","pt":1725082823190,"mc":[{"id":"1.232462894","rc":[{"trd":[[1.01,7045.13]],"batl":[[0,1.01,7498.46]],"ltp":1.01,"tv":7445.12,"id":247649},{"trd":[[100,30.29]],"batb":[[0,5.6,5],[1,5.5,3.61],[2,5.2,14]],"ltp":100.0,"tv":32.27,"id":61044843}],"tv":7477.4}]}
{"op":"mcm","clk":"11957835473","pt":1725082825297,"mc":[{"id":"1.232462894","rc":[{"trd":[[1.01,7054.8]],"batl":[[0,1.01,7488.79]],"ltp":1.01,"tv":7454.79,"id":247649},{"trd":[[100,30.39]],"ltp":100.0,"tv":32.37,"id":61044843}],"tv":7487.17}]}
{"op":"mcm","clk":"11957835499","pt":1725082826621,"mc":[{"id":"1.232462894","rc":[{"batb":[[0,5.5,3.61],[1,5.2,14],[2,2.2,329.5]],"ltp":100.0,"tv":32.37,"id":61044843}]}]}
{"op":"mcm","clk":"11957835580","pt":1725082828986,"mc":[{"id":"1.232462894","rc":[{"batb":[[0,5.6,5],[1,5.5,3.61],[2,5.2,14]],"ltp":100.0,"tv":32.37,"id":61044843}]}]}
{"op":"mcm","clk":"11957835658","pt":1725082832523,"mc":[{"id":"1.232462894","rc":[{"batb":[[0,5.5,3.61],[1,5.2,14],[2,2.2,329.5]],"ltp":100.0,"tv":32.37,"id":61044843}]}]}
{"op":"mcm","clk":"11957835750","pt":1725082836216,"mc":[{"id":"1.232462894","rc":[{"batb":[[0,5.6,5],[1,5.5,3.61],[2,5.2,14]],"ltp":100.0,"tv":32.37,"id":61044843}]}]}
{"op":"mcm","clk":"11957835850","pt":1725082839609,"mc":[{"id":"1.232462894","rc":[{"batb":[[0,5.5,3.61],[1,5.2,14],[2,2.2,329.5]],"ltp":100.0,"tv":32.37,"id":61044843}]}]}
{"op":"mcm","clk":"11957835940","pt":1725082842224,"mc":[{"id":"1.232462894","rc":[{"batb":[[0,5.6,5],[1,5.5,3.61],[2,5.2,14]],"ltp":100.0,"tv":32.37,"id":61044843}]}]}
{"op":"mcm","clk":"11957836044","pt":1725082845607,"mc":[{"id":"1.232462894","rc":[{"batb":[[0,5.5,3.61],[1,5.2,14],[2,2.2,329.5]],"ltp":100.0,"tv":32.37,"id":61044843}]}]}
{"op":"mcm","clk":"11957836118","pt":1725082848832,"mc":[{"id":"1.232462894","rc":[{"batb":[[0,5.6,5],[1,5.5,3.61],[2,5.2,14]],"ltp":100.0,"tv":32.37,"id":61044843}]}]}
{"op":"mcm","clk":"11957836249","pt":1725082852128,"mc":[{"id":"1.232462894","rc":[{"batb":[[0,5.5,3.61],[1,5.2,14],[2,2.2,329.5]],"ltp":100.0,"tv":32.37,"id":61044843}]}]}
{"op":"mcm","clk":"11957836348","pt":1725082856329,"mc":[{"id":"1.232462894","rc":[{"batb":[[0,5.6,5],[1,5.5,3.61],[2,5.2,14]],"ltp":100.0,"tv":32.37,"id":61044843}]}]}
{"op":"mcm","clk":"11957836399","pt":1725082858169,"mc":[{"id":"1.232462894","rc":[{"trd":[[1.01,7064.66]],"batl":[[0,1.01,7479.02]],"ltp":1.01,"tv":7464.66,"id":247649},{"trd":[[100,30.49]],"ltp":100.0,"tv":32.47,"id":61044843}],"tv":7497.13}]}
{"op":"mcm","clk":"11957836452","pt":1725082859665,"mc":[{"id":"1.232462894","rc":[{"batb":[[0,5.5,3.61],[1,5.2,14],[2,2.2,329.5]],"ltp":100.0,"tv":32.47,"id":61044843}]}]}
{"op":"mcm","clk":"11957836648","pt":1725082863753,"mc":[{"id":"1.232462894","rc":[{"trd":[[1.01,7099.77]],"batl":[[0,1.01,7443.92]],"ltp":1.01,"tv":7499.76,"id":247649},{"trd":[[100,30.84]],"batb":[[0,5.6,5],[1,5.5,3.61],[2,5.2,14]],"ltp":100.0,"tv":32.82,"id":61044843}],"tv":7532.59}]}
{"op":"mcm","clk":"11957836687","pt":1725082865046,"mc":[{"id":"1.232462894","rc":[{"trd":[[1.01,7109.44]],"batl":[[0,1.01,7434.25]],"ltp":1.01,"tv":7509.43,"id":247649},{"trd":[[100,30.94]],"ltp":100.0,"tv":32.92,"id":61044843}],"tv":7542.36}]}
{"op":"mcm","clk":"11957836754","pt":1725082867157,"mc":[{"id":"1.232462894","rc":[{"batb":[[0,5.5,3.61],[1,5.2,14],[2,2.2,329.5]],"ltp":100.0,"tv":32.92,"id":61044843}]}]}
{"op":"mcm","clk":"11957836892","pt":1725082871185,"mc":[{"id":"1.232462894","rc":[{"batb":[[0,5.6,5],[1,5.5,3.61],[2,5.2,14]],"ltp":100.0,"tv":32.92,"id":61044843}]}]}
{"op":"mcm","clk":"11957837025","pt":1725082874579,"mc":[{"id":"1.232462894","rc":[{"batb":[[0,5.5,3.61],[1,5.2,14],[2,2.2,329.5]],"ltp":100.0,"tv":32.92,"id":61044843}]}]}
{"op":"mcm","clk":"11957837070","pt":1725082875861,"mc":[{"id":"1.232462894","rc":[{"trd":[[1.01,7117.82]],"batl":[[0,1.01,7430.06]],"ltp":1.01,"tv":7517.81,"id":247649}],"tv":7550.74}]}
{"op":"mcm","clk":"11957837144","pt":1725082877257,"mc":[{"id":"1.232462894","rc":[{"batb":[[0,5.6,5],[1,5.5,3.61],[2,5.2,14]],"ltp":100.0,"tv":32.92,"id":61044843}]}]}
{"op":"mcm","clk":"11957837282","pt":1725082880655,"mc":[{"id":"1.232462894","rc":[{"batb":[[0,5.5,3.61],[1,5.2,14],[2,2.2,329.5]],"ltp":100.0,"tv":32.92,"id":61044843}]}]}
{"op":"mcm","clk":"11957837478","pt":1725082885082,"mc":[{"id":"1.232462894","rc":[{"trd":[[1.01,7536.2]],"batl":[[0,1.01,7220.87]],"ltp":1.01,"tv":7936.19,"id":247649},{"batb":[[0,5.6,5],[1,5.5,3.61],[2,5.2,14]],"ltp":100.0,"tv":32.92,"id":61044843}],"tv":7969.12}]}
{"op":"mcm","clk":"11957837511","pt":1725082885967,"mc":[{"id":"1.232462894","rc":[{"trd":[[1.01,7545.87]],"batl":[[0,1.01,7211.2]],"ltp":1.01,"tv":7945.86,"id":247649},{"trd":[[100,31.03]],"ltp":100.0,"tv":33.02,"id":61044843}],"tv":7978.89}]}
{"op":"mcm","clk":"11957837648","pt":1725082888889,"mc":[{"id":"1.232462894","rc":[{"trd":[[1.01,7555.54]],"batl":[[0,1.01,7201.53]],"ltp":1.01,"tv":7955.53,"id":247649},{"trd":[[100,31.13]],"batb":[[0,5.5,3.61],[1,5.2,14],[2,2.2,329.5]],"ltp":100.0,"tv":33.11,"id":61044843}],"tv":7988.65}]}
{"op":"mcm","clk":"11957837820","pt":1725082894191,"mc":[{"id":"1.232462894","rc":[{"batb":[[0,5.6,5],[1,5.5,3.61],[2,5.2,14]],"ltp":100.0,"tv":33.11,"id":61044843}]}]}
{"op":"mcm","clk":"11957837938","pt":1725082897583,"mc":[{"id":"1.232462894","rc":[{"batb":[[0,5.5,3.61],[1,5.2,14],[2,2.2,329.5]],"ltp":100.0,"tv":33.11,"id":61044843}]}]}
{"op":"mcm","clk":"11957838118","pt":1725082901989,"mc":[{"id":"1.232462894","rc":[{"batb":[[0,5.6,5],[1,5.5,3.61],[2,5.2,14]],"ltp":100.0,"tv":33.11,"id":61044843}]}]}
{"op":"mcm","clk":"11957838236","pt":1725082905429,"mc":[{"id":"1.232462894","rc":[{"batb":[[0,5.5,3.61],[1,5.2,14],[2,2.2,329.5]],"ltp":100.0,"tv":33.11,"id":61044843}]}]}
{"op":"mcm","clk":"11957838321","pt":1725082907902,"mc":[{"id":"1.232462894","rc":[{"batb":[[0,5.6,5],[1,5.5,3.61],[2,5.2,14]],"ltp":100.0,"tv":33.11,"id":61044843}]}]}
{"op":"mcm","clk":"11957838442","pt":1725082911203,"mc":[{"id":"1.232462894","rc":[{"batb":[[0,5.5,3.61],[1,5.2,14],[2,2.2,329.5]],"ltp":100.0,"tv":33.11,"id":61044843}]}]}
{"op":"mcm","clk":"11957838562","pt":1725082914343,"mc":[{"id":"1.232462894","rc":[{"batb":[[0,5.6,5],[1,5.5,3.61],[2,5.2,14]],"ltp":100.0,"tv":33.11,"id":61044843}]}]}
{"op":"mcm","clk":"11957838682","pt":1725082917736,"mc":[{"id":"1.232462894","rc":[{"batb":[[0,5.5,3.61],[1,5.2,14],[2,2.2,329.5]],"ltp":100.0,"tv":33.11,"id":61044843}]}]}
{"op":"mcm","clk":"11957838749","pt":1725082919229,"mc":[{"id":"1.232462894","rc":[{"trd":[[1.01,7639.22]],"batl":[[0,1.01,7159.68]],"ltp":1.01,"tv":8039.22,"id":247649}],"tv":8072.34}]}
{"op":"mcm","clk":"11957838782","pt":1725082920315,"mc":[{"id":"1.232462894","rc":[{"batb":[[0,5.6,5],[1,5.5,3.61],[2,5.2,14]],"ltp":100.0,"tv":33.11,"id":61044843}]}]}
{"op":"mcm","clk":"11957838909","pt":1725082923844,"mc":[{"id":"1.232462894","rc":[{"batb":[[0,5.5,3.61],[1,5.2,14],[2,2.2,329.5]],"ltp":100.0,"tv":33.11,"id":61044843}]}]}
{"op":"mcm","clk":"11957838983","pt":1725082926948,"mc":[{"id":"1.232462894","rc":[{"batb":[[0,5.6,5],[1,5.5,3.61],[2,5.2,14]],"ltp":100.0,"tv":33.11,"id":61044843}]}]}
{"op":"mcm","clk":"11957839125","pt":1725082930233,"mc":[{"id":"1.232462894","rc":[{"batb":[[0,5.5,3.61],[1,5.2,14],[2,2.2,329.5]],"ltp":100.0,"tv":33.11,"id":61044843}]}]}
{"op":"mcm","clk":"11957839265","pt":1725082933835,"mc":[{"id":"1.232462894","rc":[{"batb":[[0,5.6,5],[1,5.5,3.61],[2,5.2,14]],"ltp":100.0,"tv":33.11,"id":61044843}]}]}
{"op":"mcm","clk":"11957839389","pt":1725082937232,"mc":[{"id":"1.232462894","rc":[{"batb":[[0,5.5,3.61],[1,5.2,14],[2,2.2,329.5]],"ltp":100.0,"tv":33.11,"id":61044843}]}]}
{"op":"mcm","clk":"11957839584","pt":1725082943058,"mc":[{"id":"1.232462894","rc":[{"trd":[[1.01,7672.74]],"batl":[[0,1.01,7142.92]],"ltp":1.01,"tv":8072.74,"id":247649},{"batb":[[0,5.6,5],[1,5.5,3.61],[2,5.2,14]],"ltp":100.0,"tv":33.11,"id":61044843}],"tv":8105.86}]}
{"op":"mcm","clk":"11957839621","pt":1725082944143,"mc":[{"id":"1.232462894","rc":[{"trd":[[1.01,7681.12]],"batl":[[0,1.01,7138.74]],"ltp":1.01,"tv":8081.11,"id":247649}],"tv":8114.23}]}
{"op":"mcm","clk":"11957839674","pt":1725082946050,"mc":[{"id":"1.232462894","rc":[{"batb":[[0,5.5,3.61],[1,5.2,14],[2,2.2,329.5]],"ltp":100.0,"tv":33.11,"id":61044843}]}]}
{"op":"mcm","clk":"11957839767","pt":1725082948850,"mc":[{"id":"1.232462894","rc":[{"batb":[[0,5.6,5],[1,5.5,3.61],[2,5.2,14]],"ltp":100.0,"tv":33.11,"id":61044843}]}]}
{"op":"mcm","clk":"11957839859","pt":1725082952056,"mc":[{"id":"1.232462894","rc":[{"batb":[[0,5.5,3.61],[1,5.2,14],[2,2.2,329.5]],"ltp":100.0,"tv":33.11,"id":61044843}]}]}
{"op":"mcm","clk":"11957839989","pt":1725082955862,"mc":[{"id":"1.232462894","rc":[{"batb":[[0,5.6,5],[1,5.5,3.61],[2,5.2,14]],"ltp":100.0,"tv":33.11,"id":61044843}]}]}
{"op":"mcm","clk":"11957840136","pt":1725082959172,"mc":[{"id":"1.232462894","rc":[{"batb":[[0,5.5,3.61],[1,5.2,14],[2,2.2,329.5]],"ltp":100.0,"tv":33.11,"id":61044843}]}]}
{"op":"mcm","clk":"11957840318","pt":1725082962870,"mc":[{"id":"1.232462894","rc":[{"trd":[[1.01,7703.13]],"batl":[[0,1.01,7127.73]],"ltp":1.01,"tv":8103.13,"id":247649},{"batb":[[0,5.6,5],[1,5.5,3.61],[2,5.2,14]],"ltp":100.0,"tv":33.11,"id":61044843}],"tv":8136.25}]}
{"op":"mcm","clk":"11957840401","pt":1725082966000,"mc":[{"id":"1.232462894","rc":[{"batb":[[0,5.5,3.61],[1,5.2,14],[2,2.2,329.5]],"ltp":100.0,"tv":33.11,"id":61044843}]}]}
{"op":"mcm","clk":"11957840451","pt":1725082967078,"mc":[{"id":"1.232462894","rc":[{"batb":[[0,130,25.76],[1,5.5,3.61],[2,5.2,14]],"ltp":100.0,"tv":33.11,"id":61044843}]}]}
{"op":"mcm","clk":"11957840683","pt":1725082972596,"mc":[{"id":"1.232462894","rc":[{"trd":[[1.01,7786.81]],"batl":[[0,1.01,7085.89]],"ltp":1.01,"tv":8186.81,"id":247649}],"tv":8219.93}]}
{"op":"mcm","clk":"11957857249","pt":1725082975604,"mc":[{"id":"1.232462894","rc":[{"trd":[[130,0.39]],"batb":[[0,130,25.66]],"ltp":130.0,"tv":33.31,"id":61044843}],"tv":8220.12}]}
{"op":"mcm","clk":"11957857557","pt":1725082983913,"mc":[{"id":"1.232462894","rc":[{"batl":[[2,1.03,243.78]],"ltp":1.01,"tv":8186.81,"id":247649}]}]}
{"op":"mcm","clk":"11957857718","pt":1725082987943,"mc":[{"id":"1.232462894","rc":[{"trd":[[130,0.59]],"batb":[[0,130,25.57]],"ltp":130.0,"tv":33.51,"id":61044843}],"tv":8220.32}]}
{"op":"mcm","clk":"11957859135","pt":1725083023340,"mc":[{"id":"1.232462894","rc":[{"batl":[[0,380,2.49],[1,400,16.53],[2,540,1.68]],"ltp":130.0,"tv":33.51,"id":61044843}]}]}
{"op":"mcm","clk":"11957859182","pt":1725083025141,"mc":[{"id":"1.232462894","rc":[{"trd":[[130,0.78]],"batb":[[0,130,25.47]],"ltp":130.0,"tv":33.7,"id":61044843}],"tv":8220.51}]}
{"op":"mcm","clk":"11957859401","pt":1725083033663,"mc":[{"id":"1.232462894","rc":[{"trd":[[1.01,7787.8]],"batl":[[0,1.01,7085.39]],"ltp":1.01,"tv":8187.8,"id":247649}],"tv":8221.5}]}
{"op":"mcm","clk":"11957859541","pt":1725083037870,"mc":[{"id":"1.232462894","rc":[{"batl":[[0,300,1.04],[1,380,1.55],[2,400,16.53]],"ltp":130.0,"tv":33.7,"id":61044843}]}]}
{"op":"mcm","clk":"11957859698","pt":1725083042663,"mc":[{"id":"1.232462894","rc":[{"trd":[[130,2.62]],"batb":[[0,130,24.55]],"ltp":130.0,"tv":35.53,"id":61044843}],"tv":8223.34}]}
{"op":"mcm","clk":"11957859880","pt":1725083048197,"mc":[{"id":"1.232462894","rc":[{"trd":[[1.01,7788.9]],"batl":[[0,1.01,7084.85]],"ltp":1.01,"tv":8188.89,"id":247649}],"tv":8224.43}]}
{"op":"mcm","clk":"11957860658","pt":1725083074727,"mc":[{"id":"1.232462894","rc":[{"batb":[[1,5.2,14],[2,2.2,329.5]],"batl":[[1,400,16.53],[2,540,1.68]],"ltp":130.0,"tv":35.53,"id":61044843}]}]}
{"op":"mcm","clk":"11957860705","pt":1725083076633,"mc":[{"id":"1.232462894","rc":[{"batb":[[2,3.95,3.61]],"batl":[[2,530,2.39]],"ltp":130.0,"tv":35.53,"id":61044843}]}]}
{"op":"mcm","clk":"11957860732","pt":1725083077509,"mc":[{"id":"1.232462894","rc":[{"batb":[[2,2.2,329.5]],"batl":[[2,540,1.68]],"ltp":130.0,"tv":35.53,"id":61044843}]}]}
{"op":"mcm","clk":"11957860997","pt":1725083085324,"mc":[{"id":"1.232462894","rc":[{"trd":[[130,2.81]],"batb":[[0,130,24.45],[2,3.95,3.61]],"batl":[[2,530,2.39]],"ltp":130.0,"tv":35.73,"id":61044843}],"tv":8224.63}]}
{"op":"mcm","clk":"11957861121","pt":1725083089120,"mc":[{"id":"1.232462894","rc":[{"batl":[[2,1.03,245.61]],"ltp":1.01,"tv":8188.89,"id":247649}]}]}
{"op":"mcm","clk":"11957861242","pt":1725083092656,"mc":[{"id":"1.232462894","rc":[{"batb":[[1,5.2,17.61],[2,2.2,329.5]],"batl":[[1,400,18.08],[2,540,1.68]],"ltp":130.0,"tv":35.73,"id":61044843}]}]}
{"op":"mcm","clk":"11957861413","pt":1725083097340,"mc":[{"id":"1.232462894","rc":[{"trd":[[130,3.01]],"batb":[[0,130,24.35]],"ltp":130.0,"tv":35.92,"id":61044843}],"tv":8224.82}]}
{"op":"mcm","clk":"11957861444","pt":1725083098341,"mc":[{"id":"1.232462894","rc":[{"batl":[[0,400,19.02],[1,540,1.68],[2,1000,0.84]],"ltp":130.0,"tv":35.92,"id":61044843}]}]}
{"op":"mcm","clk":"11957861508","pt":1725083100240,"mc":[{"id":"1.232462894","rc":[{"batb":[[1,5.2,14]],"batl":[[0,400,17.47]],"ltp":130.0,"tv":35.92,"id":61044843}]}]}
{"op":"mcm","clk":"11957861558","pt":1725083101760,"mc":[{"id":"1.232462894","marketDefinition":{"bspMarket":false,"turnInPlayEnabled":true,"persistenceEnabled":true,"marketBaseRate":5.0,"eventId":"33540261","eventTypeId":"4","numberOfWinners":1,"bettingType":"ODDS","marketType":"MATCH_ODDS","marketTime":"2024-08-31T05:45:00.000Z","suspendTime":"2024-08-31T05:45:00.000Z","bspReconciled":false,"complete":true,"inPlay":false,"crossMatching":true,"runnersVoidable":false,"numberOfActiveRunners":2,"betDelay":0,"status":"SUSPENDED","runners":[{"status":"ACTIVE","sortPriority":1,"id":247649,"name":"Hong Kong"},{"status":"ACTIVE","sortPriority":2,"id":61044843,"name":"Mongolia"}],"regulators":["MR_INT"],"countryCode":"GB","discountAllowed":true,"timezone":"GMT","openDate":"2024-08-31T05:45:00.000Z","version":6109493718,"name":"Match Odds","eventName":"Hong Kong v Mongolia"}}]}
{"op":"mcm","clk":"11957861954","pt":1725083114594,"mc":[{"id":"1.232462894","marketDefinition":{"bspMarket":false,"turnInPlayEnabled":true,"persistenceEnabled":true,"marketBaseRate":5.0,"eventId":"33540261","eventTypeId":"4","numberOfWinners":1,"bettingType":"ODDS","marketType":"MATCH_ODDS","marketTime":"2024-08-31T05:45:00.000Z","suspendTime":"2024-08-31T05:45:00.000Z","bspReconciled":false,"complete":true,"inPlay":true,"crossMatching":true,"runnersVoidable":false,"numberOfActiveRunners":2,"betDelay":5,"status":"OPEN","runners":[{"status":"ACTIVE","sortPriority":1,"id":247649,"name":"Hong Kong"},{"status":"ACTIVE","sortPriority":2,"id":61044843,"name":"Mongolia"}],"regulators":["MR_INT"],"countryCode":"GB","discountAllowed":true,"timezone":"GMT","openDate":"2024-08-31T05:45:00.000Z","version":6109493824,"name":"Match Odds","eventName":"Hong Kong v Mongolia"},"rc":[{"batl":[[0,1.01,2.96],[1,1.02,8501.21],[2,1.03,199.91]],"ltp":1.01,"tv":8188.89,"id":247649},{"batb":[[0,5.2,14],[1,2.2,329.5],[2,1.46,2]],"ltp":130.0,"tv":35.92,"id":61044843}]}]}
{"op":"mcm","clk":"11957862236","pt":1725083122294,"mc":[{"id":"1.232462894","rc":[{"batb":[[1,3.95,3.61],[2,2.2,329.5]],"batl":[[0,530,1.55]],"ltp":130.0,"tv":35.92,"id":61044843}]}]}
{"op":"mcm","clk":"11957862277","pt":1725083123373,"mc":[{"id":"1.232462894","rc":[{"batb":[[1,2.2,329.5],[2,1.46,2]],"ltp":130.0,"tv":35.92,"id":61044843}]}]}
{"op":"mcm","clk":"11957862922","pt":1725083144524,"mc":[{"id":"1.232462894","rc":[{"batb":[[1,3.95,3.61],[2,2.2,329.5]],"batl":[[0,580,1.55]],"ltp":130.0,"tv":35.92,"id":61044843}]}]}
{"op":"mcm","clk":"11957862991","pt":1725083146636,"mc":[{"id":"1.232462894","rc":[{"batl":[[2,1.03,201.73]],"ltp":1.01,"tv":8188.89,"id":247649},{"batb":[[1,2.2,329.5],[2,1.46,2]],"ltp":130.0,"tv":35.92,"id":61044843}]}]}
{"op":"mcm","clk":"11957863051","pt":1725083148531,"mc":[{"id":"1.232462894","rc":[{"batl":[[0,300,2.09],[1,580,1.55]],"ltp":130.0,"tv":35.92,"id":61044843}]}]}
{"op":"mcm","clk":"11957863110","pt":1725083150430,"mc":[{"id":"1.232462894","rc":[{"batb":[[0,5.2,14.1]],"ltp":130.0,"tv":35.92,"id":61044843}]}]}
{"op":"mcm","clk":"11957863147","pt":1725083151712,"mc":[{"id":"1.232462894","rc":[{"batb":[[0,5.2,17.7]],"ltp":130.0,"tv":35.92,"id":61044843}]}]}
{"op":"mcm","clk":"11957863416","pt":1725083159620,"mc":[{"id":"1.232462894","rc":[{"batb":[[0,5.2,14.1]],"batl":[[1,580,0]],"ltp":130.0,"tv":35.92,"id":61044843}]}]}
{"op":"mcm","clk":"11957863749","pt":1725083169036,"mc":[{"id":"1.232462894","rc":[{"batl":[[1,500,0.1]],"ltp":130.0,"tv":35.92,"id":61044843}]}]}
{"op":"mcm","clk":"11957863952","pt":1725083174633,"mc":[{"id":"1.232462894","rc":[{"batl":[[2,1.03,202.37]],"ltp":1.01,"tv":8188.89,"id":247649}]}]}
{"op":"mcm","clk":"11957863993","pt":1725083176066,"mc":[{"id":"1.232462894","rc":[{"batb":[[1,3.95,3.61],[2,2.2,329.5]],"batl":[[1,580,1.64]],"ltp":130.0,"tv":35.92,"id":61044843}]}]}
{"op":"mcm","clk":"11957864093","pt":1725083179148,"mc":[{"id":"1.232462894","rc":[{"trd":[[1.01,7792.46]],"batl":[[0,1.01,1.18]],"ltp":1.01,"tv":8192.45,"id":247649},{"batb":[[1,2.2,329.5],[2,1.46,2]],"ltp":130.0,"tv":35.92,"id":61044843}],"tv":8228.38}]}
{"op":"mcm","clk":"11957864203","pt":1725083183368,"mc":[{"id":"1.232462894","rc":[{"batb":[[0,5.2,17.7]],"ltp":130.0,"tv":35.92,"id":61044843}]}]}
{"op":"mcm","clk":"11957864244","pt":1725083184959,"mc":[{"id":"1.232462894","rc":[{"batb":[[0,5.2,14.1]],"batl":[[1,500,0.1]],"ltp":130.0,"tv":35.92,"id":61044843}]}]}
{"op":"mcm","clk":"11957864343","pt":1725083187983,"mc":[{"id":"1.232462894","rc":[{"trd":[[1.01,7793.63]],"batl":[[0,1.02,8501.21],[1,1.03,202.37],[2,1.09,4211.24]],"ltp":1.01,"tv":8193.63,"id":247649},{"trd":[[100,31.14]],"batb":[[0,5.2,14.01]],"ltp":100.0,"tv":35.94,"id":61044843}],"tv":8229.57}]}
{"op":"mcm","clk":"11957864811","pt":1725083200455,"mc":[{"id":"1.232462894","rc":[{"batb":[[1,3.95,3.61],[2,2.2,329.5]],"batl":[[1,580,1.64]],"ltp":100.0,"tv":35.94,"id":61044843}]}]}
{"op":"mcm","clk":"11957864890","pt":1725083202664,"mc":[{"id":"1.232462894","rc":[{"batb":[[1,2.2,329.5],[2,1.46,2]],"ltp":100.0,"tv":35.94,"id":61044843}]}]}
{"op":"mcm","clk":"11957865048","pt":1725083206872,"mc":[{"id":"1.232462894","rc":[{"trd":[[1.02,4.21]],"batl":[[0,1.02,8497]],"ltp":1.02,"tv":8197.84,"id":247649},{"trd":[[50,0.09]],"batb":[[0,5.2,14]],"ltp":50.0,"tv":36.02,"id":61044843}],"tv":8233.87}]}
{"op":"mcm","clk":"11957865090","pt":1725083207801,"mc":[{"id":"1.232462894","rc":[{"batb":[[0,5.2,17.61]],"ltp":50.0,"tv":36.02,"id":61044843}]}]}
{"op":"mcm","clk":"11957865140","pt":1725083208989,"mc":[{"id":"1.232462894","rc":[{"batl":[[0,300,2.19]],"ltp":50.0,"tv":36.02,"id":61044843}]}]}
{"op":"mcm","clk":"11957865391","pt":1725083214608,"mc":[{"id":"1.232462894","rc":[{"trd":[[1.02,9]],"batl":[[0,1.02,8492.21]],"ltp":1.02,"tv":8202.63,"id":247649},{"trd":[[50,0.18]],"ltp":50.0,"tv":36.12,"id":61044843}],"tv":8238.75}]}
{"op":"mcm","clk":"11957865430","pt":1725083215525,"mc":[{"id":"1.232462894","rc":[{"batb":[[0,5.2,14]],"batl":[[1,500,0.1]],"ltp":50.0,"tv":36.12,"id":61044843}]}]}
{"op":"mcm","clk":"11957865849","pt":1725083228505,"mc":[{"id":"1.232462894","rc":[{"trd":[[1.01,7795.46]],"ltp":1.01,"tv":8204.45,"id":247649},{"trd":[[100,31.16]],"batl":[[0,300,2.17]],"ltp":100.0,"tv":36.14,"id":61044843}],"tv":8240.6}]}
{"op":"mcm","clk":"11957865949","pt":1725083231450,"mc":[{"id":"1.232462894","rc":[{"trd":[[1.01,7803.29]],"batl":[[0,1.01,5045.65],[1,1.02,8492.21],[2,1.03,202.37]],"ltp":1.01,"tv":8212.29,"id":247649},{"trd":[[100,31.24]],"batl":[[0,300,2.09]],"ltp":100.0,"tv":36.22,"id":61044843}],"tv":8248.51}]}
{"op":"mcm","clk":"11957866164","pt":1725083236639,"mc":[{"id":"1.232462894","rc":[{"batl":[[1,1.02,8492.84]],"ltp":1.01,"tv":8212.29,"id":247649}]}]}
{"op":"mcm","clk":"11957866214","pt":1725083238032,"mc":[{"id":"1.232462894","rc":[{"trd":[[1.01,7812.96]],"batl":[[0,1.01,5037.81]],"ltp":1.01,"tv":8221.96,"id":247649},{"trd":[[100,31.34]],"ltp":100.0,"tv":36.32,"id":61044843}],"tv":8258.28}]}
{"op":"mcm","clk":"11957866390","pt":1725083243939,"mc":[{"id":"1.232462894","rc":[{"trd":[[1.01,7936.72]],"batl":[[0,1.01,4914.05]],"ltp":1.01,"tv":8345.72,"id":247649},{"trd":[[100,32.59]],"ltp":100.0,"tv":37.57,"id":61044843}],"tv":8383.29}]}
{"op":"mcm","clk":"11957866582","pt":1725083249933,"mc":[{"id":"1.232462894","rc":[{"trd":[[1.01,7953.46]],"batl":[[0,1.01,4905.68]],"ltp":1.01,"tv":8362.46,"id":247649}],"tv":8400.03}]}
{"op":"mcm","clk":"11957866872","pt":1725083260153,"mc":[{"id":"1.232462894","rc":[{"batl":[[0,1.01,9116.91]],"ltp":1.01,"tv":8362.46,"id":247649}]}]}
{"op":"mcm","clk":"11957867315","pt":1725083272175,"mc":[{"id":"1.232462894","rc":[{"trd":[[1.01,7954.93]],"batl":[[0,1.01,9116.18]],"ltp":1.01,"tv":8363.92,"id":247649}],"tv":8401.49}]}
{"op":"mcm","clk":"11957867347","pt":1725083273195,"mc":[{"id":"1.232462894","rc":[{"trd":[[1.01,7964.59]],"batl":[[0,1.01,9106.51]],"ltp":1.01,"tv":8373.59,"id":247649},{"trd":[[100,32.69]],"ltp":100.0,"tv":37.66,"id":61044843}],"tv":8411.26}]}
{"op":"mcm","clk":"11957868005","pt":1725083291483,"mc":[{"id":"1.232462894","rc":[{"batb":[[1,3.95,3.61],[2,2.2,329.5]],"batl":[[1,780,1.64]],"ltp":100.0,"tv":37.66,"id":61044843}]}]}
{"op":"mcm","clk":"11957868075","pt":1725083293694,"mc":[{"id":"1.232462894","rc":[{"batb":[[1,2.2,329.5],[2,1.46,2]],"ltp":100.0,"tv":37.66,"id":61044843}]}]}
{"op":"mcm","clk":"11957868128","pt":1725083295295,"mc":[{"id":"1.232462894","rc":[{"batl":[[2,1000,0.1]],"ltp":100.0,"tv":37.66,"id":61044843}]}]}
{"op":"mcm","clk":"11957868188","pt":1725083296722,"mc":[{"id":"1.232462894","rc":[{"trd":[[1.01,7965.55]],"batl":[[0,1.01,9106.03]],"ltp":1.01,"tv":8374.55,"id":247649}],"tv":8412.22}]}
{"op":"mcm","clk":"11957868254","pt":1725083298827,"mc":[{"id":"1.232462894","rc":[{"batb":[[0,5.2,17.61]],"ltp":100.0,"tv":37.66,"id":61044843}]}]}
{"op":"mcm","clk":"11957868674","pt":1725083312142,"mc":[{"id":"1.232462894","rc":[{"batb":[[0,5.2,14]],"batl":[[1,1000,0.2],[2,1000,0]],"ltp":100.0,"tv":37.66,"id":61044843}]}]}
{"op":"mcm","clk":"11957869016","pt":1725083321935,"mc":[{"id":"1.232462894","rc":[{"batb":[[0,150,53],[1,5.2,14],[2,2.2,329.5]],"ltp":100.0,"tv":37.66,"id":61044843}]}]}
{"op":"mcm","clk":"11957869079","pt":1725083323632,"mc":[{"id":"1.232462894","rc":[{"trd":[[1.01,8054.07]],"batl":[[0,1.01,9061.77]],"ltp":1.01,"tv":8463.07,"id":247649}],"tv":8500.74}]}
{"op":"mcm","clk":"11957869180","pt":1725083326259,"mc":[{"id":"1.232462894","rc":[{"batb":[[2,3.95,3.61]],"batl":[[1,780,1.64],[2,1000,0.1]],"ltp":100.0,"tv":37.66,"id":61044843}]}]}
{"op":"mcm","clk":"11957869246","pt":1725083328471,"mc":[{"id":"1.232462894","rc":[{"batb":[[2,2.2,329.5]],"ltp":100.0,"tv":37.66,"id":61044843}]}]}
{"op":"mcm","clk":"11957869343","pt":1725083330847,"mc":[{"id":"1.232462894","rc":[{"batl":[[0,1.01,14114.41]],"ltp":1.01,"tv":8463.07,"id":247649}]}]}
{"op":"mcm","clk":"11957869441","pt":1725083333560,"mc":[{"id":"1.232462894","rc":[{"batb":[[1,5.2,17.61]],"ltp":100.0,"tv":37.66,"id":61044843}]}]}
{"op":"mcm","clk":"11957869590","pt":1725083338080,"mc":[{"id":"1.232462894","rc":[{"trd":[[150,1.68]],"batb":[[0,150,52.16],[1,5.2,14]],"batl":[[1,1000,0.2],[2,1000,0]],"ltp":150.0,"tv":39.34,"id":61044843}],"tv":8502.42}]}
{"op":"mcm","clk":"11957870104","pt":1725083351600,"mc":[{"id":"1.232462894","rc":[{"batb":[[2,3.95,3.61]],"batl":[[1,870,1.64],[2,1000,0.1]],"ltp":150.0,"tv":39.34,"id":61044843}]}]}
{"op":"mcm","clk":"11957870217","pt":1725083353802,"mc":[{"id":"1.232462894","rc":[{"trd":[[1.01,8055.9]],"batl":[[0,1.01,14113.5]],"ltp":1.01,"tv":8464.89,"id":247649},{"batb":[[2,2.2,329.5]],"ltp":150.0,"tv":39.34,"id":61044843}],"tv":8504.24}]}
{"op":"mcm","clk":"11957870345","pt":1725083357707,"mc":[{"id":"1.232462894","rc":[{"trd":[[150,1.88]],"batb":[[0,150,52.06]],"ltp":150.0,"tv":39.54,"id":61044843}],"tv":8504.44}]}
{"op":"mcm","clk":"11957870385","pt":1725083358883,"mc":[{"id":"1.232462894","rc":[{"batb":[[1,5.2,17.61]],"ltp":150.0,"tv":39.54,"id":61044843}]}]}
{"op":"mcm","clk":"11957870562","pt":1725083363505,"mc":[{"id":"1.232462894","rc":[{"batb":[[1,5.2,14]],"batl":[[1,1000,0.2],[2,1000,0]],"ltp":150.0,"tv":39.54,"id":61044843}]}]}
{"op":"mcm","clk":"11957870621","pt":1725083364998,"mc":[{"id":"1.232462894","rc":[{"trd":[[1.01,8057.72]],"batl":[[0,1.01,14112.59]],"ltp":1.01,"tv":8466.72,"id":247649}],"tv":8506.26}]}
{"op":"mcm","clk":"11957870800","pt":1725083370906,"mc":[{"id":"1.232462894","rc":[{"batl":[[0,290,2.53],[1,300,2.09],[2,1000,0.2]],"ltp":150.0,"tv":39.54,"id":61044843}]}]}
{"op":"mcm","clk":"11957871101","pt":1725083378728,"mc":[{"id":"1.232462894","rc":[{"batb":[[2,3.95,3.61]],"batl":[[2,990,1.64]],"ltp":150.0,"tv":39.54,"id":61044843}]}]}
{"op":"mcm","clk":"11957871164","pt":1725083380406,"mc":[{"id":"1.232462894","rc":[{"batb":[[2,2.2,329.5]],"ltp":150.0,"tv":39.54,"id":61044843}]}]}
{"op":"mcm","clk":"11957871221","pt":1725083381823,"mc":[{"id":"1.232462894","rc":[{"trd":[[1.01,8066.1]],"batl":[[0,1.01,14108.4]],"ltp":1.01,"tv":8475.09,"id":247649}],"tv":8514.64}]}
{"op":"mcm","clk":"11957871278","pt":1725083383436,"mc":[{"id":"1.232462894","rc":[{"trd":[[1.01,8149.88]],"batl":[[0,1.01,14066.51]],"ltp":1.01,"tv":8558.87,"id":247649}],"tv":8598.42}]}
{"op":"mcm","clk":"11957871363","pt":1725083385522,"mc":[{"id":"1.232462894","rc":[{"batb":[[1,5.2,17.61]],"ltp":150.0,"tv":39.54,"id":61044843}]}]}
{"op":"mcm","clk":"11957871778","pt":1725083397646,"mc":[{"id":"1.232462894","rc":[{"batb":[[1,5.2,14]],"batl":[[2,1000,0.2]],"ltp":150.0,"tv":39.54,"id":61044843}]}]}
{"op":"mcm","clk":"11957871965","pt":1725083403140,"mc":[{"id":"1.232462894","rc":[{"trd":[[1.01,8175]],"batl":[[0,1.01,14053.95]],"ltp":1.01,"tv":8583.99,"id":247649}],"tv":8623.54}]}
{"op":"mcm","clk":"11957872019","pt":1725083404933,"mc":[{"id":"1.232462894","rc":[{"trd":[[1.01,8175.36]],"batl":[[0,1.01,14053.77]],"ltp":1.01,"tv":8584.36,"id":247649}],"tv":8623.91}]}
{"op":"mcm","clk":"11957872433","pt":1725083415161,"mc":[{"id":"1.232462894","rc":[{"trd":[[1.01,8177.19]],"batl":[[0,1.01,14052.86]],"ltp":1.01,"tv":8586.18,"id":247649}],"tv":8625.73}]}
{"op":"mcm","clk":"11957872553","pt":1725083417790,"mc":[{"id":"1.232462894","rc":[{"trd":[[1.01,8177.58]],"batl":[[0,1.01,14052.66]],"ltp":1.01,"tv":8586.57,"id":247649}],"tv":8626.12}]}
{"op":"mcm","clk":"11957872614","pt":1725083419181,"mc":[{"id":"1.232462894","rc":[{"batb":[[2,3.95,3.61]],"batl":[[2,990,1.64]],"ltp":150.0,"tv":39.54,"id":61044843}]}]}
{"op":"mcm","clk":"11957872678","pt":1725083421591,"mc":[{"id":"1.232462894","rc":[{"batb":[[2,2.2,329.5]],"ltp":150.0,"tv":39.54,"id":61044843}]}]}
{"op":"mcm","clk":"11957872775","pt":1725083424274,"mc":[{"id":"1.232462894","rc":[{"trd":[[150,2.08]],"batb":[[0,150,51.96]],"ltp":150.0,"tv":39.74,"id":61044843}],"tv":8626.32}]}
{"op":"mcm","clk":"11957872862","pt":1725083427178,"mc":[{"id":"1.232462894","rc":[{"trd":[[1.01,8558.68]],"batl":[[0,1.01,13862.11]],"ltp":1.01,"tv":8967.68,"id":247649},{"batb":[[1,5.2,17.61]],"ltp":150.0,"tv":39.74,"id":61044843}],"tv":9007.42}]}
{"op":"mcm","clk":"11957872878","pt":1725083427789,"mc":[{"id":"1.232462894","rc":[{"trd":[[150,2.9]],"batb":[[0,150,51.55]],"ltp":150.0,"tv":40.56,"id":61044843}],"tv":9008.24}]}
{"op":"mcm","clk":"11957873061","pt":1725083434717,"mc":[{"id":"1.232462894","rc":[{"trd":[[1.01,8559.07]],"batl":[[0,1.01,13861.92]],"ltp":1.01,"tv":8968.07,"id":247649}],"tv":9008.63}]}
{"op":"mcm","clk":"11957873096","pt":1725083436091,"mc":[{"id":"1.232462894","rc":[{"trd":[[150,3.09]],"batb":[[0,150,51.45]],"ltp":150.0,"tv":40.76,"id":61044843}],"tv":9008.83}]}
{"op":"mcm","clk":"11957873119","pt":1725083436719,"mc":[{"id":"1.232462894","rc":[{"batb":[[1,5.2,14]],"batl":[[2,1000,0.2]],"ltp":150.0,"tv":40.76,"id":61044843}]}]}
{"op":"mcm","clk":"11957873432","pt":1725083443633,"mc":[{"id":"1.232462894","rc":[{"trd":[[1.01,8559.46]],"batl":[[0,1.01,13861.73]],"ltp":1.01,"tv":8968.46,"id":247649}],"tv":9009.22}]}
{"op":"mcm","clk":"11957873700","pt":1725083450425,"mc":[{"id":"1.232462894","rc":[{"batb":[[2,3.95,3.61]],"batl":[[2,870,1.64]],"ltp":150.0,"tv":40.76,"id":61044843}]}]}
{"op":"mcm","clk":"11957873752","pt":1725083451421,"mc":[{"id":"1.232462894","rc":[{"trd":[[150,3.29]],"batb":[[0,150,51.35]],"ltp":150.0,"tv":40.95,"id":61044843}],"tv":9009.41}]}
{"op":"mcm","clk":"11957873803","pt":1725083452610,"mc":[{"id":"1.232462894","rc":[{"batb":[[2,2.2,329.5]],"ltp":150.0,"tv":40.95,"id":61044843}]}]}
{"op":"mcm","clk":"11957873979","pt":1725083457732,"mc":[{"id":"1.232462894","rc":[{"batb":[[1,5.2,17.61]],"ltp":150.0,"tv":40.95,"id":61044843}]}]}
{"op":"mcm","clk":"11957874176","pt":1725083463024,"mc":[{"id":"1.232462894","rc":[{"trd":[[150,3.49]],"batb":[[0,150,51.25]],"ltp":150.0,"tv":41.15,"id":61044843}],"tv":9009.61}]}
{"op":"mcm","clk":"11957874378","pt":1725083467239,"mc":[{"id":"1.232462894","rc":[{"batb":[[1,5.2,14]],"batl":[[2,1000,0.2]],"ltp":150.0,"tv":41.15,"id":61044843}]}]}
{"op":"mcm","clk":"11957874539","pt":1725083472058,"mc":[{"id":"1.232462894","rc":[{"trd":[[1.01,8559.66]],"batl":[[0,1.01,13861.63]],"ltp":1.01,"tv":8968.65,"id":247649},{"trd":[[150,3.69]],"batb":[[0,150,51.15]],"ltp":150.0,"tv":41.35,"id":61044843}],"tv":9010.01}]}
{"op":"mcm","clk":"11957874563","pt":1725083472551,"mc":[{"id":"1.232462894","rc":[{"trd":[[150,3.88]],"batb":[[0,150,51.05]],"ltp":150.0,"tv":41.55,"id":61044843}],"tv":9010.21}]}
{"op":"mcm","clk":"11957874735","pt":1725083478252,"mc":[{"id":"1.232462894","rc":[{"batl":[[1,1000,0.2],[2,1000,0]],"ltp":150.0,"tv":41.55,"id":61044843}]}]}
{"op":"mcm","clk":"11957874803","pt":1725083479687,"mc":[{"id":"1.232462894","rc":[{"batb":[[2,3.95,3.61]],"batl":[[1,990,1.64],[2,1000,0.1]],"ltp":150.0,"tv":41.55,"id":61044843}]}]}
{"op":"mcm","clk":"11957874896","pt":1725083481856,"mc":[{"id":"1.232462894","rc":[{"batb":[[2,2.2,329.5]],"ltp":150.0,"tv":41.55,"id":61044843}]}]}
{"op":"mcm","clk":"11957875020","pt":1725083485758,"mc":[{"id":"1.232462894","rc":[{"batl":[[2,1000,0]],"ltp":150.0,"tv":41.55,"id":61044843}]}]}
{"op":"mcm","clk":"11957875098","pt":1725083486984,"mc":[{"id":"1.232462894","rc":[{"batb":[[1,5.2,17.61]],"ltp":150.0,"tv":41.55,"id":61044843}]}]}
{"op":"mcm","clk":"11957875121","pt":1725083487563,"mc":[{"id":"1.232462894","rc":[{"batl":[[1,990,1.55]],"ltp":150.0,"tv":41.55,"id":61044843}]}]}
{"op":"mcm","clk":"11957875242","pt":1725083489562,"mc":[{"id":"1.232462894","rc":[{"batl":[[1,1.02,8492.21]],"ltp":1.01,"tv":8968.65,"id":247649}]}]}
{"op":"mcm","clk":"11957875393","pt":1725083493766,"mc":[{"id":"1.232462894","rc":[{"trd":[[1.01,8601.5]],"batl":[[0,1.01,13840.7]],"ltp":1.01,"tv":9010.5,"id":247649}],"tv":9052.05}]}
{"op":"mcm","clk":"11957875445","pt":1725083495195,"mc":[{"id":"1.232462894","rc":[{"trd":[[1.01,8668.44]],"batl":[[0,1.01,13807.23]],"ltp":1.01,"tv":9077.44,"id":247649},{"trd":[[150,4.59]],"batb":[[0,150,50.7]],"ltp":150.0,"tv":42.25,"id":61044843}],"tv":9119.69}]}
{"op":"mcm","clk":"11957875690","pt":1725083502313,"mc":[{"id":"1.232462894","rc":[{"batl":[[0,290,2.62]],"ltp":150.0,"tv":42.25,"id":61044843}]}]}
{"op":"mcm","clk":"11957876086","pt":1725083512824,"mc":[{"id":"1.232462894","rc":[{"trd":[[1.01,8680.26]],"batl":[[0,1.01,13801.32]],"ltp":1.01,"tv":9089.26,"id":247649}],"tv":9131.52}]}
{"op":"mcm","clk":"11957876179","pt":1725083514728,"mc":[{"id":"1.232462894","rc":[{"trd":[[150,5.29]],"batb":[[0,150,50.35]],"ltp":150.0,"tv":42.96,"id":61044843}],"tv":9132.22}]}
{"op":"mcm","clk":"11957876535","pt":1725083523999,"mc":[{"id":"1.232462894","rc":[{"trd":[[150,5.49]],"batb":[[0,150,50.25]],"ltp":150.0,"tv":43.15,"id":61044843}],"tv":9132.42}]}
{"op":"mcm","clk":"11957876638","pt":1725083526421,"mc":[{"id":"1.232462894","rc":[{"batl":[[0,290,3.46]],"ltp":150.0,"tv":43.15,"id":61044843}]}]}
{"op":"mcm","clk":"11957876753","pt":1725083530016,"mc":[{"id":"1.232462894","rc":[{"trd":[[1.01,8688.64]],"batl":[[0,1.01,13797.13]],"ltp":1.01,"tv":9097.64,"id":247649},{"trd":[[150,5.69]],"batb":[[0,150,50.15]],"ltp":150.0,"tv":43.35,"id":61044843}],"tv":9140.99}]}
{"op":"mcm","clk":"11957877204","pt":1725083541759,"mc":[{"id":"1.232462894","rc":[{"trd":[[150,5.89]],"batb":[[0,150,50.05]],"ltp":150.0,"tv":43.55,"id":61044843}],"tv":9141.19}]}
{"op":"mcm","clk":"11957877514","pt":1725083551350,"mc":[{"id":"1.232462894","rc":[{"trd":[[150,6.08]],"batb":[[0,150,49.95]],"ltp":150.0,"tv":43.75,"id":61044843}],"tv":9141.39}]}
{"op":"mcm","clk":"11957877694","pt":1725083556653,"mc":[{"id":"1.232462894","rc":[{"batb":[[1,5.2,14]],"batl":[[1,990,0]],"ltp":150.0,"tv":43.75,"id":61044843}]}]}
{"op":"mcm","clk":"11957877928","pt":1725083562454,"mc":[{"id":"1.232462894","rc":[{"trd":[[1.01,8708.18]],"batl":[[0,1.01,13787.36]],"ltp":1.01,"tv":9117.18,"id":247649}],"tv":9160.93}]}
{"op":"mcm","clk":"11957878093","pt":1725083567009,"mc":[{"id":"1.232462894","rc":[{"batl":[[0,270,0.94]],"ltp":150.0,"tv":43.75,"id":61044843}]}]}
{"op":"mcm","clk":"11957878118","pt":1725083567671,"mc":[{"id":"1.232462894","rc":[{"trd":[[150,6.19]],"batb":[[0,150,49.9]],"ltp":150.0,"tv":43.85,"id":61044843}],"tv":9161.03}]}
{"op":"mcm","clk":"11957878309","pt":1725083572177,"mc":[{"id":"1.232462894","rc":[{"trd":[[150,7.45]],"batb":[[0,150,49.27],[2,3.95,3.61]],"batl":[[0,390,3.46]],"ltp":150.0,"tv":45.11,"id":61044843}],"tv":9162.29}]}
{"op":"mcm","clk":"11957878361","pt":1725083573776,"mc":[{"id":"1.232462894","rc":[{"batb":[[2,2.2,329.5]],"ltp":150.0,"tv":45.11,"id":61044843}]}]}
{"op":"mcm","clk":"11957878393","pt":1725083574392,"mc":[{"id":"1.232462894","rc":[{"trd":[[1.01,8708.72]],"batl":[[0,1.01,13787.1]],"ltp":1.01,"tv":9117.72,"id":247649}],"tv":9162.83}]}
{"op":"mcm","clk":"11957878564","pt":1725083578907,"mc":[{"id":"1.232462894","rc":[{"batb":[[1,5.2,17.61]],"ltp":150.0,"tv":45.11,"id":61044843}]}]}
{"op":"mcm","clk":"11957878573","pt":1725083579319,"mc":[{"id":"1.232462894","rc":[{"batl":[[0,390,2.62]],"ltp":150.0,"tv":45.11,"id":61044843}]}]}
{"op":"mcm","clk":"11957878700","pt":1725083582619,"mc":[{"id":"1.232462894","rc":[{"batl":[[0,390,2.53]],"ltp":150.0,"tv":45.11,"id":61044843}]}]}
{"op":"mcm","clk":"11957878756","pt":1725083584214,"mc":[{"id":"1.232462894","rc":[{"trd":[[150,7.64]],"batb":[[0,150,49.17]],"ltp":150.0,"tv":45.31,"id":61044843}],"tv":9163.03}]}
{"op":"mcm","clk":"11957878870","pt":1725083587098,"mc":[{"id":"1.232462894","rc":[{"trd":[[150,7.84]],"batb":[[0,150,49.07],[1,5.2,14]],"ltp":150.0,"tv":45.51,"id":61044843}],"tv":9163.23}]}
{"op":"mcm","clk":"11957879120","pt":1725083593134,"mc":[{"id":"1.232462894","rc":[{"trd":[[1.01,8711.82]],"batl":[[0,1.01,13785.55]],"ltp":1.01,"tv":9120.82,"id":247649}],"tv":9166.33}]}
{"op":"mcm","clk":"11957879240","pt":1725083597017,"mc":[{"id":"1.232462894","rc":[{"batl":[[0,390,2.62]],"ltp":150.0,"tv":45.51,"id":61044843}]}]}
{"op":"mcm","clk":"11957879367","pt":1725083600711,"mc":[{"id":"1.232462894","rc":[{"batb":[[2,3.95,3.61]],"ltp":150.0,"tv":45.51,"id":61044843}]}]}
{"op":"mcm","clk":"11957879399","pt":1725083601731,"mc":[{"id":"1.232462894","rc":[{"batl":[[0,390,3.46]],"ltp":150.0,"tv":45.51,"id":61044843}]}]}
{"op":"mcm","clk":"11957879438","pt":1725083603014,"mc":[{"id":"1.232462894","rc":[{"batb":[[2,2.2,329.5]],"ltp":150.0,"tv":45.51,"id":61044843}]}]}
{"op":"mcm","clk":"11957879500","pt":1725083604711,"mc":[{"id":"1.232462894","rc":[{"batl":[[0,370,1.04],[1,390,2.53]],"ltp":150.0,"tv":45.51,"id":61044843}]}]}
{"op":"mcm","clk":"11957879621","pt":1725083608101,"mc":[{"id":"1.232462894","rc":[{"batb":[[1,5.2,17.61]],"ltp":150.0,"tv":45.51,"id":61044843}]}]}
{"op":"mcm","clk":"11957880258","pt":1725083623938,"mc":[{"id":"1.232462894","rc":[{"batb":[[1,5.2,14]],"ltp":150.0,"tv":45.51,"id":61044843}]}]}
{"op":"mcm","clk":"11957880589","pt":1725083632658,"mc":[{"id":"1.232462894","rc":[{"trd":[[150,8.2]],"batb":[[0,150,48.89]],"ltp":150.0,"tv":45.86,"id":61044843}],"tv":9166.69}]}
{"op":"mcm","clk":"11957880625","pt":1725083633887,"mc":[{"id":"1.232462894","rc":[{"trd":[[150,9.74]],"batb":[[0,150,48.12]],"ltp":150.0,"tv":47.4,"id":61044843}],"tv":9168.23}]}
{"op":"mcm","clk":"11957880809","pt":1725083638367,"mc":[{"id":"1.232462894","rc":[{"batb":[[2,3.95,3.61]],"ltp":150.0,"tv":47.4,"id":61044843}]}]}
{"op":"mcm","clk":"11957880929","pt":1725083640992,"mc":[{"id":"1.232462894","rc":[{"trd":[[150,9.94]],"batb":[[0,150,48.02],[2,2.2,329.5]],"ltp":150.0,"tv":47.6,"id":61044843}],"tv":9168.43}]}
{"op":"mcm","clk":"11957881135","pt":1725083645678,"mc":[{"id":"1.232462894","rc":[{"batb":[[1,5.2,17.61]],"ltp":150.0,"tv":47.6,"id":61044843}]}]}
{"op":"mcm","clk":"11957881217","pt":1725083647985,"mc":[{"id":"1.232462894","rc":[{"trd":[[150,14.12]],"batb":[[0,150,45.93]],"ltp":150.0,"tv":51.78,"id":61044843}],"tv":9172.61}]}
{"op":"mcm","clk":"11957881558","pt":1725083656113,"mc":[{"id":"1.232462894","rc":[{"batb":[[1,5.2,14]],"ltp":150.0,"tv":51.78,"id":61044843}]}]}
{"op":"mcm","clk":"11957881603","pt":1725083657302,"mc":[{"id":"1.232462894","rc":[{"batl":[[0,390,3.46],[1,390,0]],"ltp":150.0,"tv":51.78,"id":61044843}]}]}
{"op":"mcm","clk":"11957881778","pt":1725083661515,"mc":[{"id":"1.232462894","rc":[{"batl":[[0,390,3.37]],"ltp":150.0,"tv":51.78,"id":61044843}]}]}
{"op":"mcm","clk":"11957882127","pt":1725083668918,"mc":[{"id":"1.232462894","rc":[{"batl":[[0,370,0.84]],"ltp":150.0,"tv":51.78,"id":61044843}]}]}
{"op":"mcm","clk":"11957882219","pt":1725083670927,"mc":[{"id":"1.232462894","rc":[{"batb":[[2,3.95,3.61]],"ltp":150.0,"tv":51.78,"id":61044843}]}]}
{"op":"mcm","clk":"11957882304","pt":1725083673139,"mc":[{"id":"1.232462894","rc":[{"batb":[[2,2.2,329.5]],"ltp":150.0,"tv":51.78,"id":61044843}]}]}
{"op":"mcm","clk":"11957882345","pt":1725083674010,"mc":[{"id":"1.232462894","rc":[{"batl":[[0,590,3.37]],"ltp":150.0,"tv":51.78,"id":61044843}]}]}
{"op":"mcm","clk":"11957882514","pt":1725083678229,"mc":[{"id":"1.232462894","rc":[{"batb":[[1,5.2,17.61]],"ltp":150.0,"tv":51.78,"id":61044843}]}]}
{"op":"mcm","clk":"11957882716","pt":1725083682435,"mc":[{"id":"1.232462894","rc":[{"batl":[[0,590,2.53],[1,1000,0.1]],"ltp":150.0,"tv":51.78,"id":61044843}]}]}
{"op":"mcm","clk":"11957883046","pt":1725083689871,"mc":[{"id":"1.232462894","rc":[{"batb":[[1,5.2,14]],"ltp":150.0,"tv":51.78,"id":61044843}]}]}
{"op":"mcm","clk":"11957883504","pt":1725083701397,"mc":[{"id":"1.232462894","rc":[{"trd":[[1.01,8879.36]],"batl":[[0,1.01,13701.78]],"ltp":1.01,"tv":9288.36,"id":247649}],"tv":9340.15}]}
{"op":"mcm","clk":"11957883630","pt":1725083704596,"mc":[{"id":"1.232462894","rc":[{"batl":[[0,590,3.37]],"ltp":150.0,"tv":51.78,"id":61044843}]}]}
{"op":"mcm","clk":"11957883972","pt":1725083712494,"mc":[{"id":"1.232462894","rc":[{"batb":[[2,3.95,3.61]],"ltp":150.0,"tv":51.78,"id":61044843}]}]}
{"op":"mcm","clk":"11957884037","pt":1725083713579,"mc":[{"id":"1.232462894","rc":[{"batb":[[2,2.2,329.5]],"ltp":150.0,"tv":51.78,"id":61044843}]}]}
{"op":"mcm","clk":"11957884231","pt":1725083718712,"mc":[{"id":"1.232462894","rc":[{"batb":[[1,5.2,17.61]],"ltp":150.0,"tv":51.78,"id":61044843}]}]}
{"op":"mcm","clk":"11957884781","pt":1725083730613,"mc":[{"id":"1.232462894","rc":[{"batb":[[1,5.2,14]],"ltp":150.0,"tv":51.78,"id":61044843}]}]}
{"op":"mcm","clk":"11957884867","pt":1725083732996,"mc":[{"id":"1.232462894","rc":[{"trd":[[150,14.31]],"batb":[[0,150,45.83]],"ltp":150.0,"tv":51.98,"id":61044843}],"tv":9340.34}]}
{"op":"mcm","clk":"11957885252","pt":1725083741099,"mc":[{"id":"1.232462894","rc":[{"batl":[[1,1000,0]],"ltp":150.0,"tv":51.98,"id":61044843}]}]}
{"op":"mcm","clk":"11957885675","pt":1725083749726,"mc":[{"id":"1.232462894","rc":[{"trd":[[150,14.51]],"batb":[[0,150,45.73],[2,3.95,3.61]],"ltp":150.0,"tv":52.18,"id":61044843}],"tv":9340.54}]}
{"op":"mcm","clk":"11957885699","pt":1725083750401,"mc":[{"id":"1.232462894","rc":[{"batb":[[2,2.2,329.5]],"ltp":150.0,"tv":52.18,"id":61044843}]}]}
{"op":"mcm","clk":"11957885809","pt":1725083752927,"mc":[{"id":"1.232462894","rc":[{"batl":[[0,590,3.46]],"ltp":150.0,"tv":52.18,"id":61044843}]}]}
{"op":"mcm","clk":"11957885946","pt":1725083755558,"mc":[{"id":"1.232462894","rc":[{"batb":[[1,5.2,17.61]],"ltp":150.0,"tv":52.18,"id":61044843}]}]}
{"op":"mcm","clk":"11957886275","pt":1725083761355,"mc":[{"id":"1.232462894","rc":[{"trd":[[150,14.71]],"batb":[[0,150,45.63]],"ltp":150.0,"tv":52.37,"id":61044843}],"tv":9340.74}]}
{"op":"mcm","clk":"11957886874","pt":1725083773876,"mc":[{"id":"1.232462894","rc":[{"batb":[[1,5.2,14]],"ltp":150.0,"tv":52.37,"id":61044843}]}]}
{"op":"mcm","clk":"11957887096","pt":1725083779061,"mc":[{"id":"1.232462894","rc":[{"trd":[[150,14.91]],"batb":[[0,150,45.53]],"ltp":150.0,"tv":52.57,"id":61044843}],"tv":9340.94}]}
{"op":"mcm","clk":"11957887499","pt":1725083789179,"mc":[{"id":"1.232462894","rc":[{"trd":[[150,15.11]],"batb":[[0,150,45.43]],"ltp":150.0,"tv":52.77,"id":61044843}],"tv":9341.13}]}
{"op":"mcm","clk":"11957887850","pt":1725083799696,"mc":[{"id":"1.232462894","rc":[{"batb":[[2,3.95,3.61]],"ltp":150.0,"tv":52.77,"id":61044843}]}]}
{"op":"mcm","clk":"11957887909","pt":1725083800899,"mc":[{"id":"1.232462894","rc":[{"trd":[[150,15.3]],"batb":[[0,150,45.33],[2,2.2,329.5]],"ltp":150.0,"tv":52.97,"id":61044843}],"tv":9341.33}]}
{"op":"mcm","clk":"11957888365","pt":1725083812312,"mc":[{"id":"1.232462894","rc":[{"trd":[[1.01,8879.56]],"batl":[[0,1.01,13701.67]],"ltp":1.01,"tv":9288.56,"id":247649}],"tv":9341.53}]}
{"op":"mcm","clk":"11957888888","pt":1725083824831,"mc":[{"id":"1.232462894","rc":[{"trd":[[1.01,8880]],"batl":[[0,1.01,13701.46]],"ltp":1.01,"tv":9289.0,"id":247649}],"tv":9341.97}]}
{"op":"mcm","clk":"11957888930","pt":1725083826014,"mc":[{"id":"1.232462894","rc":[{"batb":[[2,3.95,3.61]],"ltp":150.0,"tv":52.97,"id":61044843}]}]}
{"op":"mcm","clk":"11957888970","pt":1725083827142,"mc":[{"id":"1.232462894","rc":[{"batb":[[2,2.2,329.5]],"ltp":150.0,"tv":52.97,"id":61044843}]}]}
{"op":"mcm","clk":"11957889249","pt":1725083832851,"mc":[{"id":"1.232462894","rc":[{"trd":[[1.01,8921.84]],"batl":[[0,1.01,13680.53]],"ltp":1.01,"tv":9330.84,"id":247649}],"tv":9383.81}]}
{"op":"mcm","clk":"11957889631","pt":1725083842643,"mc":[{"id":"1.232462894","rc":[{"trd":[[1.01,8923.61]],"batl":[[0,1.01,13679.65]],"ltp":1.01,"tv":9332.61,"id":247649}],"tv":9385.58}]}
{"op":"mcm","clk":"11957889867","pt":1725083848345,"mc":[{"id":"1.232462894","rc":[{"batl":[[0,590,2.62]],"ltp":150.0,"tv":52.97,"id":61044843}]}]}
{"op":"mcm","clk":"11957890029","pt":1725083851858,"mc":[{"id":"1.232462894","rc":[{"trd":[[1.01,8924]],"batl":[[0,1.01,13679.46]],"ltp":1.01,"tv":9333.0,"id":247649}],"tv":9385.97}]}
{"op":"mcm","clk":"11957890109","pt":1725083853764,"mc":[{"id":"1.232462894","rc":[{"batl":[[0,590,2.53]],"ltp":150.0,"tv":52.97,"id":61044843}]}]}
{"op":"mcm","clk":"11957890351","pt":1725083859454,"mc":[{"id":"1.232462894","rc":[{"trd":[[1.01,8924.2]],"batl":[[0,1.01,13679.36]],"ltp":1.01,"tv":9333.2,"id":247649}],"tv":9386.17}]}
{"op":"mcm","clk":"11957890590","pt":1725083865910,"mc":[{"id":"1.232462894","rc":[{"batl":[[0,1000,0.1]],"ltp":150.0,"tv":52.97,"id":61044843}]}]}
{"op":"mcm","clk":"11957890652","pt":1725083866884,"mc":[{"id":"1.232462894","rc":[{"batl":[[0,1000,2.62]],"ltp":150.0,"tv":52.97,"id":61044843}]}]}
{"op":"mcm","clk":"11957892059","pt":1725083901327,"mc":[{"id":"1.232462894","rc":[{"batl":[[0,1.01,13687.74]],"ltp":1.01,"tv":9333.2,"id":247649}]}]}
{"op":"mcm","clk":"11957893228","pt":1725083929973,"mc":[{"id":"1.232462894","rc":[{"trd":[[150,15.5]],"batb":[[0,150,45.23]],"ltp":150.0,"tv":53.16,"id":61044843}],"tv":9386.36}]}
{"op":"mcm","clk":"11957893892","pt":1725083947658,"mc":[{"id":"1.232462894","rc":[{"batl":[[0,1.01,13695.7]],"ltp":1.01,"tv":9333.2,"id":247649}]}]}
{"op":"mcm","clk":"11957893921","pt":1725083948375,"mc":[{"id":"1.232462894","rc":[{"trd":[[150,15.7]],"batb":[[0,150,45.13]],"ltp":150.0,"tv":53.36,"id":61044843}],"tv":9386.56}]}
{"op":"mcm","clk":"11957895103","pt":1725083975437,"mc":[{"id":"1.232462894","rc":[{"trd":[[150,15.9]],"batb":[[0,150,45.03]],"ltp":150.0,"tv":53.56,"id":61044843}],"tv":9386.76}]}
{"op":"mcm","clk":"11957895143","pt":1725083976408,"mc":[{"id":"1.232462894","rc":[{"batl":[[0,1.01,13687.32]],"ltp":1.01,"tv":9333.2,"id":247649}]}]}
{"op":"mcm","clk":"11957896184","pt":1725083997757,"mc":[{"id":"1.232462894","rc":[{"batl":[[0,1.01,13679.36]],"ltp":1.01,"tv":9333.2,"id":247649}]}]}
{"op":"mcm","clk":"11957896221","pt":1725083998526,"mc":[{"id":"1.232462894","rc":[{"trd":[[1.01,8940.96]],"batl":[[0,1.01,13670.97]],"ltp":1.01,"tv":9349.96,"id":247649}],"tv":9403.52}]}
{"op":"mcm","clk":"11957896740","pt":1725084005177,"mc":[{"id":"1.232462894","rc":[{"trd":[[150,16.09]],"batb":[[0,150,44.93]],"ltp":150.0,"tv":53.76,"id":61044843}],"tv":9403.72}]}
{"op":"mcm","clk":"11957897861","pt":1725084026705,"mc":[{"id":"1.232462894","rc":[{"batb":[[0,200,12.63],[1,150,44.93],[2,5.2,14]],"ltp":150.0,"tv":53.76,"id":61044843}]}]}
{"op":"mcm","clk":"11957898823","pt":1725084048137,"mc":[{"id":"1.232462894","rc":[{"trd":[[200,0.2]],"batb":[[0,200,12.53]],"ltp":200.0,"tv":53.96,"id":61044843}],"tv":9403.92}]}
{"op":"mcm","clk":"11957899124","pt":1725084055122,"mc":[{"id":"1.232462894","rc":[{"trd":[[200,4.38]],"batb":[[0,200,10.44]],"ltp":200.0,"tv":58.13,"id":61044843}],"tv":9408.1}]}
{"op":"mcm","clk":"11957899508","pt":1725084065220,"mc":[{"id":"1.232462894","rc":[{"trd":[[1.01,8941.35]],"batl":[[0,1.01,13670.78]],"ltp":1.01,"tv":9350.34,"id":247649}],"tv":9408.48}]}
{"op":"mcm","clk":"11957899753","pt":1725084071724,"mc":[{"id":"1.232462894","rc":[{"trd":[[200,4.58]],"batb":[[0,200,10.34]],"ltp":200.0,"tv":58.33,"id":61044843}],"tv":9408.68}]}
{"op":"mcm","clk":"11957900294","pt":1725084084056,"mc":[{"id":"1.232462894","rc":[{"trd":[[200,4.77]],"batb":[[0,200,10.24]],"ltp":200.0,"tv":58.53,"id":61044843}],"tv":9408.88}]}
{"op":"mcm","clk":"11957900360","pt":1725084085451,"mc":[{"id":"1.232462894","rc":[{"trd":[[200,4.97]],"batb":[[0,200,10.14]],"ltp":200.0,"tv":58.73,"id":61044843}],"tv":9409.08}]}
{"op":"mcm","clk":"11957901460","pt":1725084112176,"mc":[{"id":"1.232462894","rc":[{"batb":[[0,210,8.38],[1,200,10.14],[2,150,44.93]],"ltp":200.0,"tv":58.73,"id":61044843}]}]}
{"op":"mcm","clk":"11957902622","pt":1725084135219,"mc":[{"id":"1.232462894","rc":[{"batb":[[1,150,44.93],[2,5.2,14]],"ltp":200.0,"tv":58.73,"id":61044843}]}]}
{"op":"mcm","clk":"11957902874","pt":1725084140317,"mc":[{"id":"1.232462894","rc":[{"batb":[[0,240,10.14],[1,210,8.38],[2,150,44.93]],"ltp":200.0,"tv":58.73,"id":61044843}]}]}
{"op":"mcm","clk":"11957903610","pt":1725084154750,"mc":[{"id":"1.232462894","rc":[{"batb":[[0,250,4.19],[1,240,10.14],[2,210,8.38]],"ltp":200.0,"tv":58.73,"id":61044843}]}]}
{"op":"mcm","clk":"11957904095","pt":1725084163993,"mc":[{"id":"1.232462894","rc":[{"trd":[[250,0.2]],"batb":[[0,250,4.09]],"ltp":250.0,"tv":58.93,"id":61044843}],"tv":9409.28}]}
{"op":"mcm","clk":"11957904669","pt":1725084176810,"mc":[{"id":"1.232462894","rc":[{"trd":[[1.01,8942.26]],"batl":[[0,1.01,13670.33]],"ltp":1.01,"tv":9351.26,"id":247649},{"trd":[[250,0.38]],"batb":[[0,250,4]],"ltp":250.0,"tv":59.11,"id":61044843}],"tv":9410.37}]}
{"op":"mcm","clk":"11957904987","pt":1725084182015,"mc":[{"id":"1.232462894","rc":[{"batb":[[1,210,8.38],[2,150,44.93]],"ltp":250.0,"tv":59.11,"id":61044843}]}]}
{"op":"mcm","clk":"11957905226","pt":1725084187100,"mc":[{"id":"1.232462894","rc":[{"batb":[[0,260,10.14],[1,250,4],[2,210,8.38]],"ltp":250.0,"tv":59.11,"id":61044843}]}]}
{"op":"mcm","clk":"11957905633","pt":1725084195106,"mc":[{"id":"1.232462894","rc":[{"trd":[[260,0.2]],"batb":[[0,260,10.04]],"ltp":260.0,"tv":59.31,"id":61044843}],"tv":9410.57}]}
{"op":"mcm","clk":"11957906170","pt":1725084204734,"mc":[{"id":"1.232462894","rc":[{"trd":[[260,0.4]],"batb":[[0,260,9.94]],"ltp":260.0,"tv":59.5,"id":61044843}],"tv":9410.77}]}
{"op":"mcm","clk":"11957906738","pt":1725084216330,"mc":[{"id":"1.232462894","rc":[{"batb":[[0,270,4.19],[1,260,9.94],[2,250,4]],"ltp":260.0,"tv":59.5,"id":61044843}]}]}
{"op":"mcm","clk":"11957906919","pt":1725084219933,"mc":[{"id":"1.232462894","rc":[{"batb":[[2,210,8.38]],"ltp":260.0,"tv":59.5,"id":61044843}]}]}
{"op":"mcm","clk":"11957907354","pt":1725084229071,"mc":[{"id":"1.232462894","rc":[{"trd":[[1.01,8943.17]],"batl":[[0,1.01,13669.87]],"ltp":1.01,"tv":9352.17,"id":247649}],"tv":9411.68}]}
{"op":"mcm","clk":"11957907546","pt":1725084232974,"mc":[{"id":"1.232462894","rc":[{"batl":[[0,1000,2.53]],"ltp":260.0,"tv":59.5,"id":61044843}]}]}
{"op":"mcm","clk":"11957907697","pt":1725084235556,"mc":[{"id":"1.232462894","rc":[{"trd":[[1.01,8944.27]],"batl":[[0,1.01,13669.32]],"ltp":1.01,"tv":9353.26,"id":247649}],"tv":9412.77}]}
{"op":"mcm","clk":"11957909145","pt":1725084262483,"mc":[{"id":"1.232462894","rc":[{"batb":[[1,210,8.38],[2,150,44.93]],"ltp":260.0,"tv":59.5,"id":61044843}]}]}
{"op":"mcm","clk":"11957909388","pt":1725084267614,"mc":[{"id":"1.232462894","rc":[{"batb":[[0,300,9.94],[1,270,4.19],[2,210,8.38]],"ltp":260.0,"tv":59.5,"id":61044843}]}]}
{"op":"mcm","clk":"11957910690","pt":1725084294550,"mc":[{"id":"1.232462894","rc":[{"batb":[[0,310,4.19],[1,300,9.94],[2,270,4.19]],"ltp":260.0,"tv":59.5,"id":61044843}]}]}
{"op":"mcm","clk":"11957910857","pt":1725084298967,"mc":[{"id":"1.232462894","rc":[{"batb":[[2,210,8.38]],"ltp":260.0,"tv":59.5,"id":61044843}]}]}
{"op":"mcm","clk":"11957911619","pt":1725084314106,"mc":[{"id":"1.232462894","rc":[{"batb":[[1,210,8.38],[2,150,44.93]],"ltp":260.0,"tv":59.5,"id":61044843}]}]}
{"op":"mcm","clk":"11957911691","pt":1725084315764,"mc":[{"id":"1.232462894","rc":[{"batb":[[0,150,44.93],[1,5.2,14],[2,2.2,329.5]],"ltp":260.0,"tv":59.5,"id":61044843}]}]}
{"op":"mcm","clk":"11957911865","pt":1725084319212,"mc":[{"id":"1.232462894","rc":[{"batb":[[0,350,9.94],[1,150,44.93],[2,5.2,14]],"ltp":260.0,"tv":59.5,"id":61044843}]}]}
{"op":"mcm","clk":"11957911980","pt":1725084321476,"mc":[{"id":"1.232462894","rc":[{"trd":[[350,0.2]],"batb":[[0,350,9.84]],"ltp":350.0,"tv":59.7,"id":61044843}],"tv":9412.97}]}
{"op":"mcm","clk":"11957912399","pt":1725084328714,"mc":[{"id":"1.232462894","rc":[{"trd":[[350,0.4]],"batb":[[0,350,9.74]],"ltp":350.0,"tv":59.9,"id":61044843}],"tv":9413.17}]}
{"op":"mcm","clk":"11957912925","pt":1725084338705,"mc":[{"id":"1.232462894","rc":[{"trd":[[350,4.14]],"batb":[[0,350,7.87]],"ltp":350.0,"tv":63.64,"id":61044843}],"tv":9416.91}]}
{"op":"mcm","clk":"11957914580","pt":1725084370243,"mc":[{"id":"1.232462894","rc":[{"trd":[[350,4.33]],"batb":[[0,350,7.77]],"ltp":350.0,"tv":63.84,"id":61044843}],"tv":9417.11}]}
{"op":"mcm","clk":"11957914785","pt":1725084374666,"mc":[{"id":"1.232462894","rc":[{"trd":[[350,5.33]],"batb":[[0,350,7.27]],"ltp":350.0,"tv":64.83,"id":61044843}],"tv":9418.1}]}
{"op":"mcm","clk":"11957915844","pt":1725084397085,"mc":[{"id":"1.232462894","rc":[{"trd":[[350,5.53]],"batb":[[0,350,7.17]],"ltp":350.0,"tv":65.03,"id":61044843}],"tv":9418.3}]}
{"op":"mcm","clk":"11957916192","pt":1725084404315,"mc":[{"id":"1.232462894","rc":[{"trd":[[350,5.72]],"batb":[[0,350,7.07]],"ltp":350.0,"tv":65.23,"id":61044843}],"tv":9418.5}]}
{"op":"mcm","clk":"11957917405","pt":1725084427942,"mc":[{"id":"1.232462894","rc":[{"trd":[[1.01,8944.47]],"batl":[[0,1.01,13669.22]],"ltp":1.01,"tv":9353.46,"id":247649}],"tv":9418.7}]}
{"op":"mcm","clk":"11957918663","pt":1725084451070,"mc":[{"id":"1.232462894","rc":[{"batl":[[0,1.01,13677.6]],"ltp":1.01,"tv":9353.46,"id":247649}]}]}
{"op":"mcm","clk":"11957919415","pt":1725084464743,"mc":[{"id":"1.232462894","rc":[{"trd":[[350,9.55]],"batb":[[0,350,5.15]],"ltp":350.0,"tv":69.05,"id":61044843}],"tv":9422.52}]}
{"op":"mcm","clk":"11957920008","pt":1725084476302,"mc":[{"id":"1.232462894","rc":[{"trd":[[1.01,8944.66]],"batl":[[0,1.01,13677.5]],"ltp":1.01,"tv":9353.66,"id":247649}],"tv":9422.72}]}
{"op":"mcm","clk":"11957920071","pt":1725084477842,"mc":[{"id":"1.232462894","rc":[{"batl":[[0,1.01,13669.12]],"ltp":1.01,"tv":9353.66,"id":247649}]}]}
{"op":"mcm","clk":"11957920672","pt":1725084488246,"mc":[{"id":"1.232462894","rc":[{"batb":[[0,400,6.71],[1,350,5.15],[2,150,44.93]],"ltp":350.0,"tv":69.05,"id":61044843}]}]}
{"op":"mcm","clk":"11957921219","pt":1725084498722,"mc":[{"id":"1.232462894","rc":[{"trd":[[1.01,8946.13]],"batl":[[0,1.01,13668.39]],"ltp":1.01,"tv":9355.12,"id":247649}],"tv":9424.18}]}
{"op":"mcm","clk":"11957921442","pt":1725084503742,"mc":[{"id":"1.232462894","rc":[{"trd":[[400,0.2]],"batb":[[0,400,6.61]],"ltp":400.0,"tv":69.25,"id":61044843}],"tv":9424.38}]}
{"op":"mcm","clk":"11957922592","pt":1725084526287,"mc":[{"id":"1.232462894","rc":[{"trd":[[400,5.52]],"batb":[[0,400,3.95]],"ltp":400.0,"tv":74.57,"id":61044843}],"tv":9429.69}]}
{"op":"mcm","clk":"11957922801","pt":1725084530092,"mc":[{"id":"1.232462894","rc":[{"trd":[[1.01,8947.95]],"batl":[[0,1.01,13667.48]],"ltp":1.01,"tv":9356.95,"id":247649}],"tv":9431.52}]}
{"op":"mcm","clk":"11957924405","pt":1725084562721,"mc":[{"id":"1.232462894","rc":[{"trd":[[400,6.93]],"batb":[[0,400,3.24]],"ltp":400.0,"tv":75.98,"id":61044843}],"tv":9432.93}]}
{"op":"mcm","clk":"11957925249","pt":1725084577732,"mc":[{"id":"1.232462894","rc":[{"trd":[[1.01,8948.12]],"batl":[[0,1.01,13667.4]],"ltp":1.01,"tv":9357.11,"id":247649}],"tv":9433.1}]}
{"op":"mcm","clk":"11957926373","pt":1725084599031,"mc":[{"id":"1.232462894","rc":[{"batb":[[0,400,4.23]],"ltp":400.0,"tv":75.98,"id":61044843}]}]}
{"op":"mcm","clk":"11957926508","pt":1725084601745,"mc":[{"id":"1.232462894","rc":[{"batb":[[2,5.2,14]],"ltp":400.0,"tv":75.98,"id":61044843}]}]}
{"op":"mcm","clk":"11957927509","pt":1725084620645,"mc":[{"id":"1.232462894","rc":[{"trd":[[1.01,8955.19]],"batl":[[0,1.01,13663.86]],"ltp":1.01,"tv":9364.19,"id":247649}],"tv":9440.18}]}
{"op":"mcm","clk":"11957931864","pt":1725084701288,"mc":[{"id":"1.232462894","rc":[{"trd":[[1.01,8955.39]],"batl":[[0,1.01,13663.76]],"ltp":1.01,"tv":9364.39,"id":247649}],"tv":9440.38}]}
{"op":"mcm","clk":"11957933267","pt":1725084727599,"mc":[{"id":"1.232462894","rc":[{"trd":[[1.01,8963.77]],"batl":[[0,1.01,13659.57]],"ltp":1.01,"tv":9372.77,"id":247649}],"tv":9448.75}]}
{"op":"mcm","clk":"11957934039","pt":1725084745131,"mc":[{"id":"1.232462894","rc":[{"trd":[[1.01,8972.15]],"batl":[[0,1.01,13655.38]],"ltp":1.01,"tv":9381.14,"id":247649}],"tv":9457.13}]}
{"op":"mcm","clk":"11957934794","pt":1725084760050,"mc":[{"id":"1.232462894","rc":[{"trd":[[410,0.2]],"batb":[[0,400,4.13]],"ltp":410.0,"tv":76.18,"id":61044843}],"tv":9457.33}]}
{"op":"mcm","clk":"11957934933","pt":1725084762529,"mc":[{"id":"1.232462894","rc":[{"batb":[[0,600,10],[1,400,4.13],[2,350,5.15]],"ltp":410.0,"tv":76.18,"id":61044843}]}]}
{"op":"mcm","clk":"11957935772","pt":1725084782388,"mc":[{"id":"1.232462894","rc":[{"trd":[[600,0.2]],"batb":[[0,600,9.9]],"ltp":600.0,"tv":76.38,"id":61044843}],"tv":9457.52}]}
{"op":"mcm","clk":"11957935932","pt":1725084786452,"mc":[{"id":"1.232462894","rc":[{"batb":[[1,350,6.04],[2,5.2,14]],"ltp":600.0,"tv":76.38,"id":61044843}]}]}
{"op":"mcm","clk":"11957936462","pt":1725084797902,"mc":[{"id":"1.232462894","rc":[{"trd":[[1000,5.05]],"batb":[[0,1000,23.24],[1,600,9.9],[2,350,6.04]],"ltp":1000.0,"tv":81.43,"id":61044843}],"tv":9462.58}]}
{"op":"mcm","clk":"11957936777","pt":1725084804784,"mc":[{"id":"1.232462894","rc":[{"trd":[[1000,5.87]],"batb":[[0,1000,22.82]],"ltp":1000.0,"tv":82.25,"id":61044843}],"tv":9463.4}]}
{"op":"mcm","clk":"11957936926","pt":1725084808290,"mc":[{"id":"1.232462894","rc":[{"batb":[[1,350,6.04],[2,5.2,14]],"ltp":1000.0,"tv":82.25,"id":61044843}]}]}
{"op":"mcm","clk":"11957937143","pt":1725084813021,"mc":[{"id":"1.232462894","rc":[{"trd":[[1000,7.55]],"batb":[[0,1000,21.98]],"ltp":1000.0,"tv":83.93,"id":61044843}],"tv":9465.08}]}
{"op":"mcm","clk":"11957937866","pt":1725084832247,"mc":[{"id":"1.232462894","rc":[{"batl":[[0,1.01,13681.15]],"ltp":1.01,"tv":9381.14,"id":247649}]}]}
{"op":"mcm","clk":"11957938190","pt":1725084839946,"mc":[{"id":"1.232462894","rc":[{"batl":[[0,1.01,16257.27]],"ltp":1.01,"tv":9381.14,"id":247649}]}]}
{"op":"mcm","clk":"11957938381","pt":1725084844750,"mc":[{"id":"1.232462894","rc":[{"trd":[[1000,7.75]],"batb":[[0,1000,21.89]],"ltp":1000.0,"tv":84.13,"id":61044843}],"tv":9465.27}]}
{"op":"mcm","clk":"11957938970","pt":1725084858650,"mc":[{"id":"1.232462894","rc":[{"trd":[[1.01,8972.51]],"batl":[[0,1.01,16257.09]],"ltp":1.01,"tv":9381.51,"id":247649}],"tv":9465.64}]}
{"op":"mcm","clk":"11957939310","pt":1725084865436,"mc":[{"id":"1.232462894","rc":[{"batb":[[1,350,5.15]],"ltp":1000.0,"tv":84.13,"id":61044843}]}]}
{"op":"mcm","clk":"11957939609","pt":1725084871768,"mc":[{"id":"1.232462894","rc":[{"batb":[[0,1000,47.65]],"ltp":1000.0,"tv":84.13,"id":61044843}]}]}
{"op":"mcm","clk":"11957940324","pt":1725084886873,"mc":[{"id":"1.232462894","rc":[{"batb":[[1,790,10.3],[2,350,5.15]],"ltp":1000.0,"tv":84.13,"id":61044843}]}]}
{"op":"mcm","clk":"11957941045","pt":1725084904104,"mc":[{"id":"1.232462894","rc":[{"trd":[[1000,9.01]],"batb":[[0,1000,47.02]],"ltp":1000.0,"tv":85.39,"id":61044843}],"tv":9466.9}]}
{"op":"mcm","clk":"11957941142","pt":1725084907032,"mc":[{"id":"1.232462894","rc":[{"trd":[[1000,9.2]],"batb":[[0,1000,46.92]],"ltp":1000.0,"tv":85.58,"id":61044843}],"tv":9467.1}]}
{"op":"mcm","clk":"11957943317","pt":1725084951562,"mc":[{"id":"1.232462894","rc":[{"trd":[[1000,9.4]],"batb":[[0,1000,46.82]],"ltp":1000.0,"tv":85.78,"id":61044843}],"tv":9467.29}]}
{"op":"mcm","clk":"11957944420","pt":1725084973517,"mc":[{"id":"1.232462894","rc":[{"trd":[[1000,10.22]],"batb":[[0,1000,46.41]],"ltp":1000.0,"tv":86.6,"id":61044843}],"tv":9468.11}]}
{"op":"mcm","clk":"11957945894","pt":1725085009258,"mc":[{"id":"1.232462894","rc":[{"trd":[[1000,10.42]],"batb":[[0,1000,46.31]],"ltp":1000.0,"tv":86.79,"id":61044843}],"tv":9468.31}]}
{"op":"mcm","clk":"11957945919","pt":1725085010847,"mc":[{"id":"1.232462894","rc":[{"trd":[[1000,10.61]],"batb":[[0,1000,46.22]],"ltp":1000.0,"tv":86.99,"id":61044843}],"tv":9468.5}]}
{"op":"mcm","clk":"11957947422","pt":1725085054413,"mc":[{"id":"1.232462894","rc":[{"batl":[[0,1.01,16258.91]],"ltp":1.01,"tv":9381.51,"id":247649}]}]}
{"op":"mcm","clk":"11957947860","pt":1725085067230,"mc":[{"id":"1.232462894","rc":[{"trd":[[1000,10.81]],"batb":[[0,1000,46.12]],"ltp":1000.0,"tv":87.19,"id":61044843}],"tv":9468.7}]}
{"op":"mcm","clk":"11957948105","pt":1725085074535,"mc":[{"id":"1.232462894","rc":[{"batl":[[0,1.01,16260.74]],"ltp":1.01,"tv":9381.51,"id":247649}]}]}
{"op":"mcm","clk":"11957948210","pt":1725085078454,"mc":[{"id":"1.232462894","rc":[{"batl":[[0,1.01,16262.56]],"ltp":1.01,"tv":9381.51,"id":247649}]}]}
{"op":"mcm","clk":"11957948245","pt":1725085079845,"mc":[{"id":"1.232462894","rc":[{"trd":[[1000,11]],"batb":[[0,1000,46.02]],"ltp":1000.0,"tv":87.38,"id":61044843}],"tv":9468.9}]}
{"op":"mcm","clk":"11957948378","pt":1725085084644,"mc":[{"id":"1.232462894","rc":[{"batb":[[1,350,5.15],[2,5.2,14]],"ltp":1000.0,"tv":87.38,"id":61044843}]}]}
{"op":"mcm","clk":"11957948552","pt":1725085089643,"mc":[{"id":"1.232462894","rc":[{"batl":[[0,1.01,16264.39]],"ltp":1.01,"tv":9381.51,"id":247649},{"trd":[[1000,11.2]],"batb":[[0,1000,45.92]],"ltp":1000.0,"tv":87.58,"id":61044843}],"tv":9469.09}]}
{"op":"mcm","clk":"11957948812","pt":1725085096673,"mc":[{"id":"1.232462894","rc":[{"batb":[[0,1000,54.47]],"ltp":1000.0,"tv":87.58,"id":61044843}]}]}
{"op":"mcm","clk":"11957949134","pt":1725085105191,"mc":[{"id":"1.232462894","rc":[{"trd":[[1.01,8972.88]],"batl":[[0,1.01,16264.21]],"ltp":1.01,"tv":9381.88,"id":247649}],"tv":9469.46}]}
{"op":"mcm","clk":"11957949798","pt":1725085123815,"mc":[{"id":"1.232462894","rc":[{"batb":[[0,1000,88.16]],"ltp":1000.0,"tv":87.58,"id":61044843}]}]}
{"op":"mcm","clk":"11957950029","pt":1725085131987,"mc":[{"id":"1.232462894","rc":[{"trd":[[1000,11.39]],"batb":[[0,1000,88.07]],"ltp":1000.0,"tv":87.77,"id":61044843}],"tv":9469.65}]}
{"op":"mcm","clk":"11957950252","pt":1725085137729,"mc":[{"id":"1.232462894","rc":[{"trd":[[1000,11.57]],"batb":[[0,1000,87.98]],"ltp":1000.0,"tv":87.95,"id":61044843}],"tv":9469.83}]}
{"op":"mcm","clk":"11957950591","pt":1725085147697,"mc":[{"id":"1.232462894","rc":[{"trd":[[1.01,8975.39]],"batl":[[0,1.01,16262.95]],"ltp":1.01,"tv":9384.39,"id":247649}],"tv":9472.34}]}
{"op":"mcm","clk":"11957958833","pt":1725085377713,"mc":[{"id":"1.232462894","rc":[{"trd":[[1000,11.77]],"batb":[[0,1000,87.88]],"ltp":1000.0,"tv":88.14,"id":61044843}],"tv":9472.54}]}
{"op":"mcm","clk":"11957959286","pt":1725085390875,"mc":[{"id":"1.232462894","rc":[{"trd":[[1.01,8975.59]],"batl":[[0,1.01,16262.85]],"ltp":1.01,"tv":9384.59,"id":247649}],"tv":9472.74}]}
{"op":"mcm","clk":"11957960083","pt":1725085414938,"mc":[{"id":"1.232462894","rc":[{"trd":[[1.01,8975.79]],"batl":[[0,1.01,16262.75]],"ltp":1.01,"tv":9384.79,"id":247649}],"tv":9472.94}]}
{"op":"mcm","clk":"11957961707","pt":1725085459834,"mc":[{"id":"1.232462894","rc":[{"trd":[[1000,12.59]],"batb":[[0,1000,87.47]],"ltp":1000.0,"tv":88.97,"id":61044843}],"tv":9473.76}]}
{"op":"mcm","clk":"11957962140","pt":1725085470919,"mc":[{"id":"1.232462894","rc":[{"trd":[[1.01,8975.99]],"batl":[[0,1.01,16262.65]],"ltp":1.01,"tv":9384.99,"id":247649}],"tv":9473.96}]}
{"op":"mcm","clk":"11957962253","pt":1725085474621,"mc":[{"id":"1.232462894","rc":[{"trd":[[1000,13.41]],"batb":[[0,1000,87.06]],"ltp":1000.0,"tv":89.79,"id":61044843}],"tv":9474.78}]}
{"op":"mcm","clk":"11957964833","pt":1725085548806,"mc":[{"id":"1.232462894","rc":[{"trd":[[1000,13.61]],"batb":[[0,1000,86.96]],"ltp":1000.0,"tv":89.98,"id":61044843}],"tv":9474.97}]}
{"op":"mcm","clk":"11957967465","pt":1725085613731,"mc":[{"id":"1.232462894","rc":[{"trd":[[1000,15.02]],"batb":[[0,1000,86.25]],"ltp":1000.0,"tv":91.4,"id":61044843}],"tv":9476.39}]}
{"op":"mcm","clk":"11957973167","pt":1725085764871,"mc":[{"id":"1.232462894","rc":[{"batb":[[0,1000,91.21]],"ltp":1000.0,"tv":91.4,"id":61044843}]}]}
{"op":"mcm","clk":"11957979690","pt":1725085930404,"mc":[{"id":"1.232462894","rc":[{"trd":[[1.01,8977.99]],"batl":[[0,1.01,16261.64]],"ltp":1.01,"tv":9386.99,"id":247649}],"tv":9478.39}]}
{"op":"mcm","clk":"11957990620","pt":1725086209584,"mc":[{"id":"1.232462894","rc":[{"batl":[[0,1.01,16680.02]],"ltp":1.01,"tv":9386.99,"id":247649}]}]}
{"op":"mcm","clk":"11958004549","pt":1725086471028,"mc":[{"id":"1.232462894","rc":[{"batl":[[0,1.01,16771.42]],"ltp":1.01,"tv":9386.99,"id":247649}]}]}
{"op":"mcm","clk":"11958004987","pt":1725086479130,"mc":[{"id":"1.232462894","rc":[{"batb":[[2,9,6.09]],"ltp":1000.0,"tv":91.4,"id":61044843}]}]}
{"op":"mcm","clk":"11958006051","pt":1725086500980,"mc":[{"id":"1.232462894","rc":[{"batb":[[2,15,2.28]],"ltp":1000.0,"tv":91.4,"id":61044843}]}]}
{"op":"mcm","clk":"11958013134","pt":1725086641549,"mc":[{"id":"1.232462894","rc":[{"batl":[[0,1.01,16792.36]],"ltp":1.01,"tv":9386.99,"id":247649}]}]}
{"op":"mcm","clk":"11958013387","pt":1725086646125,"mc":[{"id":"1.232462894","rc":[{"batl":[[0,1.01,16771.42]],"ltp":1.01,"tv":9386.99,"id":247649}]}]}
{"op":"mcm","clk":"11958019148","pt":1725086756998,"mc":[{"id":"1.232462894","rc":[{"trd":[[1000,15.22]],"batb":[[0,1000,91.12]],"ltp":1000.0,"tv":91.59,"id":61044843}],"tv":9478.59}]}
{"op":"mcm","clk":"11958021954","pt":1725086809542,"mc":[{"id":"1.232462894","rc":[{"batb":[[0,1000,91.21]],"ltp":1000.0,"tv":91.59,"id":61044843}]}]}
{"op":"mcm","clk":"11958028241","pt":1725086942233,"mc":[{"id":"1.232462894","rc":[{"trd":[[1.01,8982.56]],"batl":[[0,1.01,16769.14]],"ltp":1.01,"tv":9391.55,"id":247649}],"tv":9483.15}]}
{"op":"mcm","clk":"11958028918","pt":1725086955617,"mc":[{"id":"1.232462894","rc":[{"batl":[[0,1.01,16771.42]],"ltp":1.01,"tv":9391.55,"id":247649}]}]}
{"op":"mcm","clk":"11958031687","pt":1725087021217,"mc":[{"id":"1.232462894","rc":[{"trd":[[1.01,9002.56]],"batl":[[0,1.01,16761.42]],"ltp":1.01,"tv":9411.55,"id":247649}],"tv":9503.15}]}
{"op":"mcm","clk":"11958033111","pt":1725087052267,"mc":[{"id":"1.232462894","rc":[{"trd":[[1.01,9022.55]],"batl":[[0,1.01,16751.43]],"ltp":1.01,"tv":9431.55,"id":247649}],"tv":9523.15}]}
{"op":"mcm","clk":"11958034583","pt":1725087084789,"mc":[{"id":"1.232462894","rc":[{"trd":[[1000,15.41]],"batb":[[0,1000,91.12]],"ltp":1000.0,"tv":91.79,"id":61044843}],"tv":9523.34}]}
{"op":"mcm","clk":"11958035478","pt":1725087102022,"mc":[{"id":"1.232462894","rc":[{"trd":[[1000,15.61]],"batb":[[0,1000,91.02]],"ltp":1000.0,"tv":91.99,"id":61044843}],"tv":9523.54}]}
{"op":"mcm","clk":"11958068725","pt":1725087882945,"mc":[{"id":"1.232462894","rc":[{"batl":[[0,1.01,16755.62]],"ltp":1.01,"tv":9431.55,"id":247649}]}]}
{"op":"mcm","clk":"11958069619","pt":1725087899795,"mc":[{"id":"1.232462894","rc":[{"batl":[[0,1.01,16751.43]],"ltp":1.01,"tv":9431.55,"id":247649}]}]}
{"op":"mcm","clk":"11958071297","pt":1725087931241,"mc":[{"id":"1.232462894","rc":[{"batl":[[0,1.01,16755.62]],"ltp":1.01,"tv":9431.55,"id":247649}]}]}
{"op":"mcm","clk":"11958071669","pt":1725087937908,"mc":[{"id":"1.232462894","rc":[{"batl":[[0,1.01,16751.43]],"ltp":1.01,"tv":9431.55,"id":247649}]}]}
{"op":"mcm","clk":"11958077579","pt":1725088050340,"mc":[{"id":"1.232462894","rc":[{"trd":[[1000,15.8]],"batb":[[0,1000,90.92]],"ltp":1000.0,"tv":92.18,"id":61044843}],"tv":9523.74}]}
{"op":"mcm","clk":"11958094386","pt":1725088326655,"mc":[{"id":"1.232462894","rc":[{"trd":[[1000,17.48]],"batb":[[0,1000,90.08]],"ltp":1000.0,"tv":93.86,"id":61044843}],"tv":9525.42}]}
{"op":"mcm","clk":"11958126478","pt":1725088603563,"mc":[{"id":"1.232462894","rc":[{"trd":[[1.01,9024.56]],"batl":[[0,1.01,16750.42]],"ltp":1.01,"tv":9433.55,"id":247649}],"tv":9527.42}]}
{"op":"mcm","clk":"11958131651","pt":1725088674555,"mc":[{"id":"1.232462894","rc":[{"trd":[[1.01,9026.56]],"batl":[[0,1.01,16749.42]],"ltp":1.01,"tv":9435.55,"id":247649}],"tv":9529.42}]}
{"op":"mcm","clk":"11958174678","pt":1725089396438,"mc":[{"id":"1.232462894","marketDefinition":{"bspMarket":false,"turnInPlayEnabled":true,"persistenceEnabled":true,"marketBaseRate":5.0,"eventId":"33540261","eventTypeId":"4","numberOfWinners":1,"bettingType":"ODDS","marketType":"MATCH_ODDS","marketTime":"2024-08-31T05:45:00.000Z","suspendTime":"2024-08-31T05:45:00.000Z","bspReconciled":false,"complete":true,"inPlay":true,"crossMatching":true,"runnersVoidable":false,"numberOfActiveRunners":2,"betDelay":5,"status":"SUSPENDED","runners":[{"status":"ACTIVE","sortPriority":1,"id":247649,"name":"Hong Kong"},{"status":"ACTIVE","sortPriority":2,"id":61044843,"name":"Mongolia"}],"regulators":["MR_INT"],"countryCode":"GB","discountAllowed":true,"timezone":"GMT","openDate":"2024-08-31T05:45:00.000Z","version":6109557869,"name":"Match Odds","eventName":"Hong Kong v Mongolia"}}]}
{"op":"mcm","clk":"11958178497","pt":1725089458653,"mc":[{"id":"1.232462894","tv":0.0}]}
{"op":"mcm","clk":"11958178547","pt":1725089459638,"mc":[{"id":"1.232462894","marketDefinition":{"bspMarket":false,"turnInPlayEnabled":true,"persistenceEnabled":true,"marketBaseRate":5.0,"eventId":"33540261","eventTypeId":"4","numberOfWinners":1,"bettingType":"ODDS","marketType":"MATCH_ODDS","marketTime":"2024-08-31T05:45:00.000Z","suspendTime":"2024-08-31T05:45:00.000Z","bspReconciled":false,"complete":true,"inPlay":true,"crossMatching":false,"runnersVoidable":false,"numberOfActiveRunners":0,"betDelay":5,"status":"CLOSED","settledTime":"2024-08-31T07:30:56.000Z","runners":[{"status":"WINNER","sortPriority":1,"id":247649,"name":"Hong Kong"},{"status":"LOSER","sortPriority":2,"id":61044843,"name":"Mongolia"}],"regulators":["MR_INT"],"countryCode":"GB","discountAllowed":true,"timezone":"GMT","openDate":"2024-08-31T05:45:00.000Z","version":6109562065,"name":"Match Odds","eventName":"Hong Kong v Mongolia"}}]}
