{"op":"mcm","clk":"11827368649","pt":1723017027145,"mc":[{"id":"1.231539716","marketDefinition":{"bspMarket":false,"turnInPlayEnabled":true,"persistenceEnabled":true,"marketBaseRate":5.0,"eventId":"33474911","eventTypeId":"4","numberOfWinners":1,"bettingType":"ODDS","marketType":"MATCH_ODDS","marketTime":"2024-08-09T10:00:00.000Z","suspendTime":"2024-08-09T10:00:00.000Z","bspReconciled":false,"complete":true,"inPlay":false,"crossMatching":false,"runnersVoidable":false,"numberOfActiveRunners":2,"betDelay":0,"status":"OPEN","runners":[{"status":"ACTIVE","sortPriority":1,"id":5995,"name":"Somerset"},{"status":"ACTIVE","sortPriority":2,"id":31372,"name":"Worcestershire"}],"regulators":["MR_INT"],"countryCode":"GB","discountAllowed":false,"timezone":"GMT","openDate":"2024-08-09T10:00:00.000Z","version":6060441509,"name":"Match Odds","eventName":"Somerset v Worcestershire"},"rc":[{"batb":[[0,1.03,200],[1,1.02,200],[2,1.01,220]],"ltp":0.0,"tv":0.0,"id":5995},{"batb":[[0,1.03,200],[1,1.02,200],[2,1.01,220]],"ltp":0.0,"tv":0.0,"id":31372}]}]}
{"op":"mcm","clk":"11827368769","pt":1723017031625,"mc":[{"id":"1.231539716","marketDefinition":{"bspMarket":false,"turnInPlayEnabled":true,"persistenceEnabled":true,"marketBaseRate":5.0,"eventId":"33474911","eventTypeId":"4","numberOfWinners":1,"bettingType":"ODDS","marketType":"MATCH_ODDS","marketTime":"2024-08-09T10:00:00.000Z","suspendTime":"2024-08-09T10:00:00.000Z","bspReconciled":false,"complete":true,"inPlay":false,"crossMatching":false,"runnersVoidable":false,"numberOfActiveRunners":2,"betDelay":0,"status":"OPEN","runners":[{"status":"ACTIVE","sortPriority":1,"id":5995,"name":"Somerset"},{"status":"ACTIVE","sortPriority":2,"id":31372,"name":"Worcestershire"}],"regulators":["MR_INT"],"countryCode":"GB","discountAllowed":true,"timezone":"GMT","openDate":"2024-08-09T10:00:00.000Z","version":6060441509,"name":"Match Odds","eventName":"Somerset v Worcestershire"}}]}
{"op":"mcm","clk":"11827443850","pt":1723019434123,"mc":[{"id":"1.231539716","rc":[{"batb":[[2,1.01,483.37]],"ltp":0.0,"tv":0.0,"id":5995},{"batb":[[2,1.01,483.37]],"ltp":0.0,"tv":0.0,"id":31372}]}]}
{"op":"mcm","clk":"11827445526","pt":1723019504406,"mc":[{"id":"1.231539716","rc":[{"batb":[[0,1.5,51.02],[1,1.03,200],[2,1.02,200]],"ltp":0.0,"tv":0.0,"id":31372}]}]}
{"op":"mcm","clk":"11827445927","pt":1723019519783,"mc":[{"id":"1.231539716","rc":[{"batb":[[0,1.5,51.02],[1,1.03,200],[2,1.02,200]],"ltp":0.0,"tv":0.0,"id":5995}]}]}
{"op":"mcm","clk":"11827446089","pt":1723019525517,"mc":[{"id":"1.231539716","marketDefinition":{"bspMarket":false,"turnInPlayEnabled":true,"persistenceEnabled":true,"marketBaseRate":5.0,"eventId":"33474911","eventTypeId":"4","numberOfWinners":1,"bettingType":"ODDS","marketType":"MATCH_ODDS","marketTime":"2024-08-09T10:00:00.000Z","suspendTime":"2024-08-09T10:00:00.000Z","bspReconciled":false,"complete":true,"inPlay":false,"crossMatching":true,"runnersVoidable":false,"numberOfActiveRunners":2,"betDelay":0,"status":"OPEN","runners":[{"status":"ACTIVE","sortPriority":1,"id":5995,"name":"Somerset"},{"status":"ACTIVE","sortPriority":2,"id":31372,"name":"Worcestershire"}],"regulators":["MR_INT"],"countryCode":"GB","discountAllowed":true,"timezone":"GMT","openDate":"2024-08-09T10:00:00.000Z","version":6060441509,"name":"Match Odds","eventName":"Somerset v Worcestershire"}}]}
{"op":"mcm","clk":"11827446221","pt":1723019531009,"mc":[{"id":"1.231539716","rc":[{"trd":[[1.5,102.03]],"batb":[[0,1.03,200],[1,1.02,200],[2,1.01,483.37]],"batl":[[0,1.5,0.24]],"ltp":1.5,"tv":102.03,"id":31372}],"tv":102.03}]}
{"op":"mcm","clk":"11827446426","pt":1723019538045,"mc":[{"id":"1.231539716","rc":[{"trd":[[1.5,102.03],[3,0.12]],"batb":[[0,1.03,200],[1,1.02,200],[2,1.01,483.37]],"batl":[[0,1.5,0.12]],"ltp":1.5,"tv":102.15,"id":5995},{"trd":[[1.5,102.27]],"ltp":1.5,"tv":102.27,"id":31372}],"tv":204.42}]}
{"op":"mcm","clk":"11827447737","pt":1723019587882,"mc":[{"id":"1.231539716","rc":[{"batb":[[0,1.45,56.69],[1,1.03,200],[2,1.02,200]],"ltp":1.5,"tv":102.27,"id":31372}]}]}
{"op":"mcm","clk":"11827447858","pt":1723019591867,"mc":[{"id":"1.231539716","rc":[{"batb":[[0,1.03,200],[1,1.02,200],[2,1.01,483.37]],"ltp":1.5,"tv":102.27,"id":31372}]}]}
{"op":"mcm","clk":"11827449058","pt":1723019641707,"mc":[{"id":"1.231539716","rc":[{"batb":[[0,1.51,85.03],[1,1.03,200],[2,1.02,200]],"ltp":1.5,"tv":102.27,"id":31372}]}]}
{"op":"mcm","clk":"11827449339","pt":1723019653853,"mc":[{"id":"1.231539716","rc":[{"batb":[[0,1.51,85.03],[1,1.03,200],[2,1.02,200]],"ltp":1.5,"tv":102.15,"id":5995}]}]}
{"op":"mcm","clk":"11827449579","pt":1723019665965,"mc":[{"id":"1.231539716","rc":[{"trd":[[1.51,170.06]],"batb":[[0,1.03,200],[1,1.02,200],[2,1.01,483.37]],"batl":[[0,1.51,4.67]],"ltp":1.51,"tv":272.32,"id":31372}],"tv":374.47}]}
{"op":"mcm","clk":"11827449790","pt":1723019675159,"mc":[{"id":"1.231539716","rc":[{"trd":[[1.51,170.06]],"batb":[[0,1.03,200],[1,1.02,200],[2,1.01,483.37]],"batl":[[0,1.51,4.67]],"ltp":1.51,"tv":272.2,"id":5995}],"tv":544.53}]}
{"op":"mcm","clk":"11827545473","pt":1723022269976,"mc":[{"id":"1.231539716","rc":[{"trd":[[1.5,101.98],[1.51,169.96]],"batb":[[0,1.25,100],[1,1.03,200],[2,1.02,200]],"ltp":1.51,"tv":272.06,"id":5995},{"trd":[[1.5,102.21],[1.51,169.96]],"batb":[[0,1.25,100],[1,1.03,200],[2,1.02,200]],"ltp":1.51,"tv":272.17,"id":31372}],"tv":544.23}]}
{"op":"mcm","clk":"11827872405","pt":1723026726608,"mc":[{"id":"1.231539716","rc":[{"trd":[[1.5,101.9],[1.51,169.83]],"ltp":1.51,"tv":271.85,"id":5995},{"trd":[[1.5,102.14],[1.51,169.83]],"ltp":1.51,"tv":271.96,"id":31372}],"tv":543.82}]}
{"op":"mcm","clk":"11827873895","pt":1723026742453,"mc":[{"id":"1.231539716","rc":[{"batb":[[2,1.02,207.87]],"ltp":1.51,"tv":271.85,"id":5995},{"batb":[[2,1.02,207.87]],"ltp":1.51,"tv":271.96,"id":31372}]}]}
{"op":"mcm","clk":"11827875007","pt":1723026755158,"mc":[{"id":"1.231539716","rc":[{"batb":[[2,1.02,247.21]],"ltp":1.51,"tv":271.85,"id":5995},{"batb":[[2,1.02,247.21]],"ltp":1.51,"tv":271.96,"id":31372}]}]}
{"op":"mcm","clk":"11827875972","pt":1723026766775,"mc":[{"id":"1.231539716","rc":[{"batb":[[1,1.03,207.87]],"ltp":1.51,"tv":271.85,"id":5995},{"batb":[[1,1.03,207.87]],"ltp":1.51,"tv":271.96,"id":31372}]}]}
{"op":"mcm","clk":"11827877114","pt":1723026779480,"mc":[{"id":"1.231539716","rc":[{"batb":[[1,1.04,7.87],[2,1.03,207.87]],"ltp":1.51,"tv":271.85,"id":5995},{"batb":[[1,1.04,7.87],[2,1.03,207.87]],"ltp":1.51,"tv":271.96,"id":31372}]}]}
{"op":"mcm","clk":"11827878417","pt":1723026793297,"mc":[{"id":"1.231539716","rc":[{"batb":[[1,1.05,7.87],[2,1.04,7.87]],"ltp":1.51,"tv":271.85,"id":5995},{"batb":[[1,1.05,7.87],[2,1.04,7.87]],"ltp":1.51,"tv":271.96,"id":31372}]}]}
{"op":"mcm","clk":"11827879573","pt":1723026805824,"mc":[{"id":"1.231539716","rc":[{"batb":[[1,1.06,7.87],[2,1.05,7.87]],"ltp":1.51,"tv":271.85,"id":5995},{"batb":[[1,1.06,7.87],[2,1.05,7.87]],"ltp":1.51,"tv":271.96,"id":31372}]}]}
{"op":"mcm","clk":"11827881011","pt":1723026820403,"mc":[{"id":"1.231539716","rc":[{"batb":[[1,1.07,7.87],[2,1.06,7.87]],"ltp":1.51,"tv":271.85,"id":5995},{"batb":[[1,1.07,7.87],[2,1.06,7.87]],"ltp":1.51,"tv":271.96,"id":31372}]}]}
{"op":"mcm","clk":"11827882493","pt":1723026836727,"mc":[{"id":"1.231539716","rc":[{"batb":[[1,1.08,7.87],[2,1.07,7.87]],"ltp":1.51,"tv":271.85,"id":5995},{"batb":[[1,1.08,7.87],[2,1.07,7.87]],"ltp":1.51,"tv":271.96,"id":31372}]}]}
{"op":"mcm","clk":"11827995295","pt":1723028183272,"mc":[{"id":"1.231539716","rc":[{"batb":[[0,1.5,45.51],[1,1.25,100],[2,1.08,7.87]],"ltp":1.51,"tv":271.85,"id":5995},{"batb":[[0,1.5,53.24],[1,1.25,100],[2,1.08,7.87]],"ltp":1.51,"tv":271.96,"id":31372}]}]}
{"op":"mcm","clk":"11828066152","pt":1723029174974,"mc":[{"id":"1.231539716","rc":[{"trd":[[1.5,101.85],[1.51,169.75]],"batb":[[0,1.5,45.51],[2,1.08,7.86]],"ltp":1.51,"tv":271.71,"id":5995},{"trd":[[1.5,102.09],[1.51,169.75]],"batb":[[0,1.5,53.23],[2,1.08,7.86]],"ltp":1.51,"tv":271.83,"id":31372}],"tv":543.55}]}
{"op":"mcm","clk":"11828455708","pt":1723034574965,"mc":[{"id":"1.231539716","rc":[{"trd":[[1.5,101.77],[1.51,169.61]],"batb":[[0,1.5,45.49],[2,1.08,7.86]],"ltp":1.51,"tv":271.49,"id":5995},{"trd":[[1.5,102],[1.51,169.61]],"batb":[[0,1.5,53.22],[2,1.08,7.86]],"ltp":1.51,"tv":271.61,"id":31372}],"tv":543.1}]}
{"op":"mcm","clk":"11828796166","pt":1723039808266,"mc":[{"id":"1.231539716","rc":[{"trd":[[1.5,101.83],[1.51,169.72]],"batb":[[0,1.51,16.92],[1,1.5,45.5],[2,1.25,100]],"ltp":1.51,"tv":271.66,"id":5995},{"trd":[[1.5,102.07],[1.51,169.72]],"batb":[[0,1.51,16.92],[1,1.5,53.23],[2,1.25,100]],"ltp":1.51,"tv":271.78,"id":31372}],"tv":543.45}]}
{"op":"mcm","clk":"11828927046","pt":1723041610462,"mc":[{"id":"1.231539716","rc":[{"batb":[[0,1.5,45.5],[1,1.25,100],[2,1.08,7.86]],"ltp":1.51,"tv":271.66,"id":5995},{"batb":[[0,1.5,53.23],[1,1.25,100],[2,1.08,7.86]],"ltp":1.51,"tv":271.78,"id":31372}]}]}
{"op":"mcm","clk":"11828930191","pt":1723041665231,"mc":[{"id":"1.231539716","rc":[{"batb":[[0,1.51,16.92],[1,1.5,45.5],[2,1.25,100]],"ltp":1.51,"tv":271.66,"id":5995},{"batb":[[0,1.51,16.92],[1,1.5,53.23],[2,1.25,100]],"ltp":1.51,"tv":271.78,"id":31372}]}]}
{"op":"mcm","clk":"11829072357","pt":1723043469290,"mc":[{"id":"1.231539716","rc":[{"trd":[[1.5,101.77],[1.51,169.61]],"batb":[[0,1.5,45.54],[1,1.25,100],[2,1.08,7.86]],"ltp":1.51,"tv":271.49,"id":5995},{"trd":[[1.5,102],[1.51,169.61]],"batb":[[0,1.5,53.27],[1,1.25,100],[2,1.08,7.86]],"ltp":1.51,"tv":271.61,"id":31372}],"tv":543.11}]}
{"op":"mcm","clk":"11829076459","pt":1723043514006,"mc":[{"id":"1.231539716","rc":[{"batb":[[0,1.51,16.93],[1,1.5,45.54],[2,1.25,100]],"ltp":1.51,"tv":271.49,"id":5995},{"batb":[[0,1.51,16.93],[1,1.5,53.27],[2,1.25,100]],"ltp":1.51,"tv":271.61,"id":31372}]}]}
{"op":"mcm","clk":"11829258445","pt":1723045314513,"mc":[{"id":"1.231539716","rc":[{"batb":[[0,1.5,45.54],[1,1.25,100],[2,1.08,7.86]],"ltp":1.51,"tv":271.49,"id":5995},{"batb":[[0,1.5,53.27],[1,1.25,100],[2,1.08,7.86]],"ltp":1.51,"tv":271.61,"id":31372}]}]}
{"op":"mcm","clk":"11829263183","pt":1723045360756,"mc":[{"id":"1.231539716","rc":[{"batb":[[0,1.51,16.93],[1,1.5,45.54],[2,1.25,100]],"ltp":1.51,"tv":271.49,"id":5995},{"batb":[[0,1.51,16.93],[1,1.5,53.27],[2,1.25,100]],"ltp":1.51,"tv":271.61,"id":31372}]}]}
{"op":"mcm","clk":"11829451989","pt":1723047163416,"mc":[{"id":"1.231539716","rc":[{"trd":[[1.5,101.82],[1.51,169.7]],"batb":[[0,1.5,45.53],[1,1.25,100],[2,1.08,7.86]],"ltp":1.51,"tv":271.64,"id":5995},{"trd":[[1.5,102.06],[1.51,169.7]],"batb":[[0,1.5,53.26],[1,1.25,100],[2,1.08,7.86]],"ltp":1.51,"tv":271.76,"id":31372}],"tv":543.4}]}
{"op":"mcm","clk":"11829456031","pt":1723047201491,"mc":[{"id":"1.231539716","rc":[{"batb":[[0,1.51,16.93],[1,1.5,45.53],[2,1.25,100]],"ltp":1.51,"tv":271.64,"id":5995},{"batb":[[0,1.51,16.93],[1,1.5,53.26],[2,1.25,100]],"ltp":1.51,"tv":271.76,"id":31372}]}]}
{"op":"mcm","clk":"11829651227","pt":1723049003301,"mc":[{"id":"1.231539716","rc":[{"batb":[[0,1.5,45.53],[1,1.25,100],[2,1.08,7.86]],"ltp":1.51,"tv":271.64,"id":5995},{"batb":[[0,1.5,53.26],[1,1.25,100],[2,1.08,7.86]],"ltp":1.51,"tv":271.76,"id":31372}]}]}
{"op":"mcm","clk":"11829652762","pt":1723049018825,"mc":[{"id":"1.231539716","rc":[{"batb":[[0,1.51,16.93],[1,1.5,45.53],[2,1.25,100]],"ltp":1.51,"tv":271.64,"id":5995},{"batb":[[0,1.51,16.93],[1,1.5,53.26],[2,1.25,100]],"ltp":1.51,"tv":271.76,"id":31372}]}]}
{"op":"mcm","clk":"11829817427","pt":1723050774974,"mc":[{"id":"1.231539716","rc":[{"trd":[[1.5,101.9],[1.51,169.83]],"batb":[[0,1.51,16.94],[1,1.5,45.56]],"ltp":1.51,"tv":271.83,"id":5995},{"trd":[[1.5,102.13],[1.51,169.83]],"batb":[[0,1.51,16.94],[1,1.5,53.29]],"ltp":1.51,"tv":271.95,"id":31372}],"tv":543.79}]}
{"op":"mcm","clk":"11829825035","pt":1723050819580,"mc":[{"id":"1.231539716","rc":[{"batb":[[0,1.5,45.56],[1,1.25,100],[2,1.08,7.87]],"ltp":1.51,"tv":271.83,"id":5995},{"batb":[[0,1.5,53.29],[1,1.25,100],[2,1.08,7.87]],"ltp":1.51,"tv":271.95,"id":31372}]}]}
{"op":"mcm","clk":"11829837085","pt":1723050952875,"mc":[{"id":"1.231539716","rc":[{"batb":[[0,1.51,16.94],[1,1.5,45.56],[2,1.25,100]],"ltp":1.51,"tv":271.83,"id":5995},{"batb":[[0,1.51,16.94],[1,1.5,53.29],[2,1.25,100]],"ltp":1.51,"tv":271.95,"id":31372}]}]}
{"op":"mcm","clk":"11830004192","pt":1723052754311,"mc":[{"id":"1.231539716","rc":[{"batb":[[0,1.5,45.56],[1,1.25,100],[2,1.08,7.87]],"ltp":1.51,"tv":271.83,"id":5995},{"batb":[[0,1.5,53.29],[1,1.25,100],[2,1.08,7.87]],"ltp":1.51,"tv":271.95,"id":31372}]}]}
{"op":"mcm","clk":"11830019611","pt":1723052918883,"mc":[{"id":"1.231539716","rc":[{"batb":[[0,1.51,16.94],[1,1.5,45.56],[2,1.25,100]],"ltp":1.51,"tv":271.83,"id":5995},{"batb":[[0,1.51,16.94],[1,1.5,53.29],[2,1.25,100]],"ltp":1.51,"tv":271.95,"id":31372}]}]}
{"op":"mcm","clk":"11830194703","pt":1723054719391,"mc":[{"id":"1.231539716","rc":[{"trd":[[1.5,101.99],[1.51,169.99]],"batb":[[0,1.5,45.6],[1,1.25,100],[2,1.08,7.88]],"ltp":1.51,"tv":272.1,"id":5995},{"trd":[[1.5,102.23],[1.51,169.99]],"batb":[[0,1.5,53.34],[1,1.25,100],[2,1.08,7.88]],"ltp":1.51,"tv":272.21,"id":31372}],"tv":544.32}]}
{"op":"mcm","clk":"11830209108","pt":1723054863060,"mc":[{"id":"1.231539716","rc":[{"batb":[[0,1.51,16.95],[1,1.5,45.6],[2,1.25,100]],"ltp":1.51,"tv":272.1,"id":5995},{"batb":[[0,1.51,16.95],[1,1.5,53.34],[2,1.25,100]],"ltp":1.51,"tv":272.21,"id":31372}]}]}
{"op":"mcm","clk":"11830254412","pt":1723055338988,"mc":[{"id":"1.231539716","rc":[{"batb":[[0,1.78,56.93],[1,1.51,16.95],[2,1.5,45.6]],"ltp":1.51,"tv":272.1,"id":5995},{"batb":[[0,2.18,37.63],[1,1.51,16.95],[2,1.5,53.34]],"ltp":1.51,"tv":272.21,"id":31372}]}]}
{"op":"mcm","clk":"11830261194","pt":1723055402044,"mc":[{"id":"1.231539716","rc":[{"trd":[[1.78,112]],"batb":[[0,1.51,17.88],[1,1.5,45.6],[2,1.25,100]],"ltp":1.78,"tv":384.1,"id":5995}],"tv":656.32}]}
{"op":"mcm","clk":"11830261511","pt":1723055404352,"mc":[{"id":"1.231539716","rc":[{"batb":[[0,1.74,60.01],[1,1.51,16.95],[2,1.5,45.6]],"ltp":1.78,"tv":384.1,"id":5995}]}]}
{"op":"mcm","clk":"11830262772","pt":1723055414730,"mc":[{"id":"1.231539716","rc":[{"batl":[[0,1.84,50]],"ltp":1.78,"tv":384.1,"id":5995}]}]}
{"op":"mcm","clk":"11830292389","pt":1723055675612,"mc":[{"id":"1.231539716","rc":[{"batb":[[0,1.75,4.51],[1,1.74,60.01],[2,1.51,16.95]],"ltp":1.78,"tv":384.1,"id":5995}]}]}
{"op":"mcm","clk":"11830293585","pt":1723055686541,"mc":[{"id":"1.231539716","rc":[{"batb":[[0,2.2,6],[1,2.18,37.63],[2,1.51,16.95]],"ltp":1.51,"tv":272.21,"id":31372}]}]}
{"op":"mcm","clk":"11830429365","pt":1723056663520,"mc":[{"id":"1.231539716","rc":[{"batb":[[2,1.5,45.6]],"ltp":1.78,"tv":384.1,"id":5995},{"batb":[[2,1.5,53.34]],"ltp":1.51,"tv":272.21,"id":31372}]}]}
{"op":"mcm","clk":"11830888162","pt":1723061074211,"mc":[{"id":"1.231539716","rc":[{"trd":[[1.5,102.05],[1.51,170.08]],"batb":[[0,1.75,4.51],[2,1.5,45.62]],"ltp":1.78,"tv":384.25,"id":5995},{"trd":[[1.5,102.29],[1.51,170.08]],"batb":[[0,2.2,6],[2,1.5,53.37]],"ltp":1.51,"tv":272.36,"id":31372}],"tv":656.61}]}
{"op":"mcm","clk":"11831010925","pt":1723062487197,"mc":[{"id":"1.231539716","rc":[{"batb":[[0,1.76,7],[1,1.75,4.51],[2,1.74,60.01]],"ltp":1.78,"tv":384.25,"id":5995}]}]}
{"op":"mcm","clk":"11831059854","pt":1723063278797,"mc":[{"id":"1.231539716","rc":[{"batb":[[2,1.25,100]],"ltp":1.51,"tv":272.36,"id":31372}]}]}
{"op":"mcm","clk":"11831264898","pt":1723066975011,"mc":[{"id":"1.231539716","rc":[{"trd":[[1.5,102.02],[1.51,170.03]],"ltp":1.78,"tv":384.16,"id":5995},{"trd":[[1.5,102.25],[1.51,170.03]],"ltp":1.51,"tv":272.28,"id":31372}],"tv":656.44}]}
{"op":"mcm","clk":"11831577955","pt":1723072374980,"mc":[{"id":"1.231539716","rc":[{"trd":[[1.5,102.07],[1.51,170.12]],"batb":[[1,1.75,4.51]],"ltp":1.78,"tv":384.31,"id":5995},{"trd":[[1.5,102.31],[1.51,170.12]],"batb":[[0,2.2,6]],"ltp":1.51,"tv":272.43,"id":31372}],"tv":656.74}]}
{"op":"mcm","clk":"11831944740","pt":1723077775022,"mc":[{"id":"1.231539716","rc":[{"trd":[[1.5,102.2],[1.51,170.34]],"batb":[[1,1.75,4.52]],"ltp":1.78,"tv":384.66,"id":5995},{"trd":[[1.5,102.44],[1.51,170.34]],"batb":[[0,2.2,6.01]],"ltp":1.51,"tv":272.77,"id":31372}],"tv":657.43}]}
{"op":"mcm","clk":"11832245609","pt":1723083175012,"mc":[{"id":"1.231539716","rc":[{"trd":[[1.5,102.16],[1.51,170.27]],"batb":[[1,1.75,4.51]],"ltp":1.78,"tv":384.55,"id":5995},{"trd":[[1.5,102.4],[1.51,170.27]],"batb":[[0,2.2,6]],"ltp":1.51,"tv":272.67,"id":31372}],"tv":657.22}]}
{"op":"mcm","clk":"11832506899","pt":1723088574996,"mc":[{"id":"1.231539716","rc":[{"trd":[[1.5,102.1],[1.51,170.16]],"ltp":1.78,"tv":384.37,"id":5995},{"trd":[[1.5,102.33],[1.51,170.16]],"ltp":1.51,"tv":272.49,"id":31372}],"tv":656.87}]}
{"op":"mcm","clk":"11832689844","pt":1723093974990,"mc":[{"id":"1.231539716","rc":[{"trd":[[1.5,102.13],[1.51,170.22]],"batb":[[1,1.75,4.51]],"ltp":1.78,"tv":384.46,"id":5995},{"trd":[[1.5,102.37],[1.51,170.22]],"batb":[[0,2.2,6]],"ltp":1.51,"tv":272.58,"id":31372}],"tv":657.04}]}
{"op":"mcm","clk":"11832853776","pt":1723099375013,"mc":[{"id":"1.231539716","rc":[{"trd":[[1.5,102.14],[1.51,170.23]],"batb":[[1,1.75,4.51]],"ltp":1.78,"tv":384.49,"id":5995},{"trd":[[1.5,102.38],[1.51,170.23]],"batb":[[0,2.2,6]],"ltp":1.51,"tv":272.61,"id":31372}],"tv":657.1}]}
{"op":"mcm","clk":"11833006835","pt":1723104775026,"mc":[{"id":"1.231539716","rc":[{"trd":[[1.5,102.08],[1.51,170.13]],"ltp":1.78,"tv":384.31,"id":5995},{"trd":[[1.5,102.31],[1.51,170.13]],"batb":[[0,2.2,6]],"ltp":1.51,"tv":272.43,"id":31372}],"tv":656.75}]}
{"op":"mcm","clk":"11833026592","pt":1723105304076,"mc":[{"id":"1.231539716","rc":[{"trd":[[1.76,2.02]],"batb":[[0,1.76,5.99]],"ltp":1.76,"tv":386.33,"id":5995}],"tv":658.77}]}
{"op":"mcm","clk":"11833110431","pt":1723108063011,"mc":[{"id":"1.231539716","rc":[{"trd":[[1.5,102.08],[1.51,170.14],[1.76,2.42]],"batb":[[0,1.76,5.79]],"ltp":1.76,"tv":386.75,"id":5995},{"trd":[[1.5,102.32],[1.51,170.14]],"ltp":1.51,"tv":272.45,"id":31372}],"tv":659.21}]}
{"op":"mcm","clk":"11833508508","pt":1723115409352,"mc":[{"id":"1.231539716","rc":[{"trd":[[1.5,102.09],[1.51,170.15]],"batb":[[1,1.75,4.51],[2,1.74,61.01]],"ltp":1.76,"tv":386.78,"id":5995},{"trd":[[1.5,102.33],[1.51,170.15]],"batb":[[0,2.2,6],[2,1.74,1]],"ltp":1.51,"tv":272.47,"id":31372}],"tv":659.26}]}
{"op":"mcm","clk":"11833541769","pt":1723115775607,"mc":[{"id":"1.231539716","rc":[{"trd":[[1.76,14]],"batb":[[0,1.75,4.51],[1,1.74,61.01],[2,1.25,100]],"batl":[[0,1.76,4.21],[1,1.84,50]],"ltp":1.76,"tv":398.36,"id":5995}],"tv":670.84}]}
{"op":"mcm","clk":"11833556956","pt":1723116047910,"mc":[{"id":"1.231539716","rc":[{"batl":[[1,1.83,4.61],[2,1.84,50]],"ltp":1.76,"tv":398.36,"id":5995}]}]}
{"op":"mcm","clk":"11833720992","pt":1723118959257,"mc":[{"id":"1.231539716","rc":[{"trd":[[1.5,102.06],[1.51,170.1],[1.76,17.2]],"batl":[[0,1.76,2.61]],"ltp":1.76,"tv":401.48,"id":5995},{"trd":[[1.5,102.3],[1.51,170.1]],"ltp":1.51,"tv":272.39,"id":31372}],"tv":673.87}]}
{"op":"mcm","clk":"11833863600","pt":1723121304953,"mc":[{"id":"1.231539716","rc":[{"batl":[[1,1.8,1000],[2,1.83,4.61]],"ltp":1.76,"tv":401.48,"id":5995}]}]}
{"op":"mcm","clk":"11833863734","pt":1723121307834,"mc":[{"id":"1.231539716","rc":[{"batl":[[2,1.84,50]],"ltp":1.76,"tv":401.48,"id":5995},{"batb":[[0,2.18,37.63],[1,1.74,1],[2,1.25,100]],"ltp":1.51,"tv":272.39,"id":31372}]}]}
{"op":"mcm","clk":"11833864008","pt":1723121314356,"mc":[{"id":"1.231539716","rc":[{"batl":[[1,1.84,50],[2,1.84,0]],"ltp":1.76,"tv":401.48,"id":5995}]}]}
{"op":"mcm","clk":"11833878034","pt":1723121585244,"mc":[{"id":"1.231539716","rc":[{"batb":[[0,2.2,6.15],[1,2.18,37.63],[2,1.74,1]],"ltp":1.51,"tv":272.39,"id":31372}]}]}
{"op":"mcm","clk":"11833892936","pt":1723121858506,"mc":[{"id":"1.231539716","rc":[{"batl":[[1,1.83,4.5],[2,1.84,50]],"ltp":1.76,"tv":401.48,"id":5995}]}]}
{"op":"mcm","clk":"11833965851","pt":1723123242581,"mc":[{"id":"1.231539716","rc":[{"trd":[[1.5,102.24],[1.51,170.4],[1.75,9],[1.76,17.2]],"batb":[[0,1.74,61.01],[1,1.25,100],[2,1.08,7.89]],"batl":[[0,1.76,2.62],[1,1.83,9.34]],"ltp":1.75,"tv":410.96,"id":5995},{"trd":[[1.5,102.47],[1.51,170.4]],"batb":[[0,2.2,6.14]],"ltp":1.51,"tv":272.87,"id":31372}],"tv":683.83}]}
{"op":"mcm","clk":"11833966656","pt":1723123261399,"mc":[{"id":"1.231539716","rc":[{"trd":[[1.74,117.22]],"batb":[[0,1.74,2.4]],"ltp":1.74,"tv":528.18,"id":5995}],"tv":801.05}]}
{"op":"mcm","clk":"11833966771","pt":1723123264078,"mc":[{"id":"1.231539716","rc":[{"batb":[[0,1.74,1],[1,1.7,63.44],[2,1.25,100]],"ltp":1.74,"tv":528.18,"id":5995}]}]}
{"op":"mcm","clk":"11833967477","pt":1723123280218,"mc":[{"id":"1.231539716","rc":[{"batl":[[0,1.76,2.61]],"ltp":1.74,"tv":528.18,"id":5995}]}]}
{"op":"mcm","clk":"11833968932","pt":1723123314479,"mc":[{"id":"1.231539716","rc":[{"trd":[[1.74,119.22]],"batb":[[0,1.7,63.44],[1,1.25,100],[2,1.08,7.89]],"batl":[[0,1.76,2.78]],"ltp":1.74,"tv":530.18,"id":5995}],"tv":803.05}]}
{"op":"mcm","clk":"11833970296","pt":1723123344089,"mc":[{"id":"1.231539716","rc":[{"trd":[[1.76,22.42]],"batb":[[0,1.7,63.55]],"batl":[[0,1.83,9.34],[1,1.84,50],[2,1.84,0]],"ltp":1.76,"tv":535.4,"id":5995}],"tv":808.27}]}
{"op":"mcm","clk":"11833972044","pt":1723123381547,"mc":[{"id":"1.231539716","rc":[{"batl":[[0,1.83,94.54]],"ltp":1.76,"tv":535.4,"id":5995}]}]}
{"op":"mcm","clk":"11833974842","pt":1723123444604,"mc":[{"id":"1.231539716","rc":[{"trd":[[1.83,18.68]],"batl":[[0,1.83,4.65]],"ltp":1.83,"tv":554.07,"id":5995}],"tv":826.94}]}
{"op":"mcm","clk":"11833974903","pt":1723123446097,"mc":[{"id":"1.231539716","rc":[{"batb":[[0,1.71,5.49],[1,1.7,63.44],[2,1.25,100]],"ltp":1.83,"tv":554.07,"id":5995}]}]}
{"op":"mcm","clk":"11833975750","pt":1723123467729,"mc":[{"id":"1.231539716","rc":[{"batl":[[0,1.84,50],[1,1.84,0]],"ltp":1.83,"tv":554.07,"id":5995}]}]}
{"op":"mcm","clk":"11833976073","pt":1723123476150,"mc":[{"id":"1.231539716","rc":[{"batb":[[0,1.71,10.67]],"ltp":1.83,"tv":554.07,"id":5995}]}]}
{"op":"mcm","clk":"11833976634","pt":1723123488463,"mc":[{"id":"1.231539716","rc":[{"batl":[[0,1.83,89.71],[1,1.84,50]],"ltp":1.83,"tv":554.07,"id":5995}]}]}
{"op":"mcm","clk":"11833980377","pt":1723123563536,"mc":[{"id":"1.231539716","rc":[{"batl":[[0,1.84,50],[1,1.84,0]],"ltp":1.83,"tv":554.07,"id":5995}]}]}
{"op":"mcm","clk":"11834010454","pt":1723124165850,"mc":[{"id":"1.231539716","rc":[{"batb":[[0,1.71,90.91]],"ltp":1.83,"tv":554.07,"id":5995}]}]}
{"op":"mcm","clk":"11834013112","pt":1723124229112,"mc":[{"id":"1.231539716","rc":[{"trd":[[1.71,21.12]],"batb":[[0,1.71,1.11]],"ltp":1.71,"tv":575.19,"id":5995}],"tv":848.06}]}
{"op":"mcm","clk":"11834013173","pt":1723124230705,"mc":[{"id":"1.231539716","rc":[{"batl":[[0,1.83,9.15],[1,1.84,50]],"ltp":1.71,"tv":575.19,"id":5995}]}]}
{"op":"mcm","clk":"11834034689","pt":1723124724360,"mc":[{"id":"1.231539716","rc":[{"batl":[[0,1.83,89.84]],"ltp":1.71,"tv":575.19,"id":5995}]}]}
{"op":"mcm","clk":"11834034925","pt":1723124731150,"mc":[{"id":"1.231539716","rc":[{"batl":[[0,1.82,4.41],[1,1.83,89.84],[2,1.84,50]],"ltp":1.71,"tv":575.19,"id":5995}]}]}
{"op":"mcm","clk":"11834038422","pt":1723124810111,"mc":[{"id":"1.231539716","rc":[{"trd":[[1.82,8.82]],"batb":[[0,1.71,1.21]],"batl":[[0,1.83,89.84],[1,1.84,50],[2,1.84,0]],"ltp":1.82,"tv":584.01,"id":5995}],"tv":856.88}]}
{"op":"mcm","clk":"11834038462","pt":1723124810934,"mc":[{"id":"1.231539716","rc":[{"batb":[[0,1.71,5.9]],"ltp":1.82,"tv":584.01,"id":5995}]}]}
{"op":"mcm","clk":"11834038913","pt":1723124819852,"mc":[{"id":"1.231539716","rc":[{"trd":[[1.83,36.97]],"batl":[[0,1.83,1.03]],"ltp":1.83,"tv":602.31,"id":5995}],"tv":875.18}]}
{"op":"mcm","clk":"11834038961","pt":1723124821022,"mc":[{"id":"1.231539716","rc":[{"batb":[[0,1.71,15.73]],"ltp":1.83,"tv":602.31,"id":5995}]}]}
{"op":"mcm","clk":"11834039129","pt":1723124824535,"mc":[{"id":"1.231539716","rc":[{"batb":[[0,1.71,15.63]],"ltp":1.83,"tv":602.31,"id":5995}]}]}
{"op":"mcm","clk":"11834060163","pt":1723125196039,"mc":[{"id":"1.231539716","rc":[{"batb":[[0,1.72,80.24],[1,1.71,15.63],[2,1.7,63.44]],"ltp":1.83,"tv":602.31,"id":5995}]}]}
{"op":"mcm","clk":"11834060245","pt":1723125197374,"mc":[{"id":"1.231539716","rc":[{"batb":[[0,1.73,4.64],[1,1.72,80.24],[2,1.71,10.94]],"ltp":1.83,"tv":602.31,"id":5995}]}]}
{"op":"mcm","clk":"11834060304","pt":1723125198144,"mc":[{"id":"1.231539716","rc":[{"batb":[[0,1.73,9.2],[2,1.71,1.11]],"ltp":1.83,"tv":602.31,"id":5995}]}]}
{"op":"mcm","clk":"11834062938","pt":1723125241428,"mc":[{"id":"1.231539716","rc":[{"trd":[[1.73,18.04]],"batb":[[0,1.72,80.42],[1,1.71,1.11],[2,1.7,63.44]],"ltp":1.73,"tv":620.35,"id":5995}],"tv":893.22}]}
{"op":"mcm","clk":"11834063080","pt":1723125244108,"mc":[{"id":"1.231539716","rc":[{"batb":[[0,1.72,80.24]],"batl":[[0,1.83,5.41]],"ltp":1.73,"tv":620.35,"id":5995}]}]}
{"op":"mcm","clk":"11834063622","pt":1723125253516,"mc":[{"id":"1.231539716","rc":[{"batb":[[0,1.71,1.11],[1,1.7,63.44],[2,1.25,100]],"ltp":1.73,"tv":620.35,"id":5995}]}]}
{"op":"mcm","clk":"11834074916","pt":1723125467889,"mc":[{"id":"1.231539716","rc":[{"batb":[[0,1.71,5.96]],"ltp":1.73,"tv":620.35,"id":5995}]}]}
{"op":"mcm","clk":"11834075004","pt":1723125469277,"mc":[{"id":"1.231539716","rc":[{"batl":[[0,1.83,87]],"ltp":1.73,"tv":620.35,"id":5995}]}]}
{"op":"mcm","clk":"11834078623","pt":1723125545282,"mc":[{"id":"1.231539716","rc":[{"trd":[[1.83,45.74]],"batb":[[0,1.71,11.17]],"batl":[[0,1.84,50.45],[1,1.84,0]],"ltp":1.83,"tv":629.11,"id":5995}],"tv":901.98}]}
{"op":"mcm","clk":"11834082421","pt":1723125616157,"mc":[{"id":"1.231539716","rc":[{"trd":[[1.5,101.98],[1.51,169.96],[1.71,21.09],[1.73,18.02],[1.75,8.99],[1.76,22.42],[1.82,8.81],[1.83,45.68]],"batb":[[0,1.71,11.14]],"batl":[[0,1.75,100],[1,1.84,50.45]],"ltp":1.83,"tv":628.28,"id":5995},{"trd":[[1.5,102.21],[1.51,169.96]],"batb":[[0,2.2,6.12]],"ltp":1.51,"tv":272.17,"id":31372}],"tv":900.46}]}
{"op":"mcm","clk":"11834082523","pt":1723125617752,"mc":[{"id":"1.231539716","rc":[{"batb":[[0,2.18,37.63],[1,1.74,1],[2,1.25,100]],"ltp":1.51,"tv":272.17,"id":31372}]}]}
{"op":"mcm","clk":"11834082669","pt":1723125620173,"mc":[{"id":"1.231539716","rc":[{"batl":[[1,1.76,200],[2,1.84,50.45]],"ltp":1.83,"tv":628.28,"id":5995}]}]}
{"op":"mcm","clk":"11834083573","pt":1723125636987,"mc":[{"id":"1.231539716","rc":[{"batl":[[2,1.77,300]],"ltp":1.83,"tv":628.28,"id":5995}]}]}
{"op":"mcm","clk":"11834099020","pt":1723125888900,"mc":[{"id":"1.231539716","rc":[{"batb":[[0,2.34,5.67],[1,2.18,37.63],[2,1.74,1]],"ltp":1.51,"tv":272.17,"id":31372}]}]}
{"op":"mcm","clk":"11834102123","pt":1723125954732,"mc":[{"id":"1.231539716","rc":[{"batb":[[0,1.71,10.03]],"ltp":1.83,"tv":628.28,"id":5995}]}]}
{"op":"mcm","clk":"11834110600","pt":1723126126650,"mc":[{"id":"1.231539716","rc":[{"batl":[[0,1.74,5.28],[1,1.75,100],[2,1.76,200]],"ltp":1.83,"tv":628.28,"id":5995}]}]}
{"op":"mcm","clk":"11834115564","pt":1723126211927,"mc":[{"id":"1.231539716","rc":[{"batb":[[0,1.71,86.67]],"ltp":1.83,"tv":628.28,"id":5995}]}]}
{"op":"mcm","clk":"11834119301","pt":1723126283010,"mc":[{"id":"1.231539716","rc":[{"trd":[[1.71,41.16]],"batb":[[0,1.71,1.03]],"ltp":1.71,"tv":648.35,"id":5995}],"tv":920.53}]}
{"op":"mcm","clk":"11834119353","pt":1723126284089,"mc":[{"id":"1.231539716","rc":[{"batl":[[0,1.74,18.83]],"ltp":1.71,"tv":648.35,"id":5995}]}]}
{"op":"mcm","clk":"11834160895","pt":1723126909046,"mc":[{"id":"1.231539716","rc":[{"batb":[[1,1.7,54.16]],"ltp":1.71,"tv":648.35,"id":5995},{"batb":[[1,2.18,32.13]],"ltp":1.51,"tv":272.17,"id":31372}]}]}
{"op":"mcm","clk":"11834190047","pt":1723127466818,"mc":[{"id":"1.231539716","rc":[{"batb":[[0,1.7,54.16],[1,1.25,100],[2,1.08,7.87]],"ltp":1.71,"tv":648.35,"id":5995}]}]}
{"op":"mcm","clk":"11834516087","pt":1723131775019,"mc":[{"id":"1.231539716","rc":[{"trd":[[1.5,101.88],[1.51,169.8],[1.71,41.17],[1.73,18.02],[1.75,8.99],[1.76,22.42],[1.82,8.81],[1.83,45.69]],"batb":[[2,1.08,7.86]],"batl":[[0,1.74,18.84]],"ltp":1.71,"tv":648.11,"id":5995},{"trd":[[1.5,102.11],[1.51,169.8]],"batb":[[0,2.34,5.67]],"ltp":1.51,"tv":271.91,"id":31372}],"tv":920.02}]}
{"op":"mcm","clk":"11834570303","pt":1723132363923,"mc":[{"id":"1.231539716","rc":[{"batb":[[1,1.08,7.86],[2,1.07,7.86]],"ltp":1.71,"tv":648.11,"id":5995}]}]}
{"op":"mcm","clk":"11834572452","pt":1723132390557,"mc":[{"id":"1.231539716","rc":[{"batb":[[1,1.23,217.39],[2,1.18,277.78]],"ltp":1.71,"tv":648.11,"id":5995}]}]}
{"op":"mcm","clk":"11834572502","pt":1723132391273,"mc":[{"id":"1.231539716","rc":[{"batb":[[1,1.53,94.34],[2,1.48,104.17]],"ltp":1.71,"tv":648.11,"id":5995}]}]}
{"op":"mcm","clk":"11834576674","pt":1723132448528,"mc":[{"id":"1.231539716","rc":[{"batb":[[1,1.48,104.17],[2,1.43,116.28]],"ltp":1.71,"tv":648.11,"id":5995}]}]}
{"op":"mcm","clk":"11834704421","pt":1723133856433,"mc":[{"id":"1.231539716","rc":[{"trd":[[1.5,101.71],[1.51,169.52],[1.71,41.14],[1.73,18],[1.75,8.99],[1.76,22.42],[1.82,8.8],[1.83,45.65]],"batb":[[0,1.7,85.16]],"batl":[[0,1.74,18.81]],"ltp":1.71,"tv":647.58,"id":5995},{"trd":[[1.5,101.95],[1.51,169.52]],"batb":[[0,2.34,5.66]],"ltp":1.51,"tv":271.47,"id":31372}],"tv":919.05}]}
{"op":"mcm","clk":"11834734288","pt":1723134128314,"mc":[{"id":"1.231539716","rc":[{"batl":[[0,2.42,4.45]],"ltp":1.51,"tv":271.47,"id":31372}]}]}
{"op":"mcm","clk":"11834781306","pt":1723134550896,"mc":[{"id":"1.231539716","rc":[{"batb":[[0,1.71,4.5],[1,1.7,85.16],[2,1.48,104.17]],"ltp":1.71,"tv":647.58,"id":5995}]}]}
{"op":"mcm","clk":"11835070927","pt":1723136798463,"mc":[{"id":"1.231539716","rc":[{"trd":[[1.5,101.7],[1.51,169.5],[1.71,41.13],[1.73,18],[1.75,8.99],[1.82,8.8],[1.83,45.64]],"batb":[[0,1.71,4.49],[2,1.52,67.5]],"batl":[[0,1.74,18.8]],"ltp":1.71,"tv":647.52,"id":5995},{"trd":[[1.5,101.94],[1.51,169.5]],"batb":[[0,2.34,5.66]],"batl":[[0,2.42,4.45]],"ltp":1.51,"tv":271.43,"id":31372}],"tv":918.95}]}
{"op":"mcm","clk":"11835073089","pt":1723136812972,"mc":[{"id":"1.231539716","rc":[{"batb":[[2,1.79,45]],"ltp":1.51,"tv":271.43,"id":31372}]}]}
{"op":"mcm","clk":"11835628685","pt":1723140400354,"mc":[{"id":"1.231539716","rc":[{"trd":[[1.5,101.66],[1.51,169.43],[1.71,41.13],[1.83,45.65]],"batl":[[0,1.74,18.8]],"ltp":1.71,"tv":647.41,"id":5995},{"trd":[[1.5,101.89],[1.51,169.43]],"batl":[[0,2.4,9.02],[1,2.42,4.45]],"ltp":1.51,"tv":271.32,"id":31372}],"tv":918.74}]}
{"op":"mcm","clk":"11835628946","pt":1723140401781,"mc":[{"id":"1.231539716","rc":[{"batl":[[1,2.42,0]],"ltp":1.51,"tv":271.32,"id":31372}]}]}
{"op":"mcm","clk":"11835629235","pt":1723140403174,"mc":[{"id":"1.231539716","rc":[{"batb":[[0,1.7,85.16],[1,1.52,67.5],[2,1.48,104.17]],"ltp":1.71,"tv":647.41,"id":5995}]}]}
{"op":"mcm","clk":"11835841806","pt":1723141544300,"mc":[{"id":"1.231539716","rc":[{"trd":[[1.71,53.79]],"batl":[[0,1.71,54.84],[1,1.74,18.8],[2,1.75,100]],"ltp":1.71,"tv":660.07,"id":5995},{"trd":[[2.4,9.02]],"ltp":2.4,"tv":280.34,"id":31372}],"tv":940.42}]}
{"op":"mcm","clk":"11835842027","pt":1723141545575,"mc":[{"id":"1.231539716","rc":[{"batl":[[0,1.71,60],[1,1.74,5.27]],"ltp":1.71,"tv":660.07,"id":5995},{"batb":[[0,2.18,32.13],[1,1.79,45],[2,1.74,1]],"ltp":2.4,"tv":280.34,"id":31372}]}]}
{"op":"mcm","clk":"11835842127","pt":1723141546212,"mc":[{"id":"1.231539716","rc":[{"batl":[[1,1.75,100],[2,1.76,200]],"ltp":1.71,"tv":660.07,"id":5995}]}]}
{"op":"mcm","clk":"11835842708","pt":1723141549597,"mc":[{"id":"1.231539716","rc":[{"batl":[[0,1.71,5.16]],"ltp":1.71,"tv":660.07,"id":5995}]}]}
{"op":"mcm","clk":"11835842728","pt":1723141549703,"mc":[{"id":"1.231539716","rc":[{"trd":[[1.7,109.68]],"batb":[[0,1.7,30.32]],"ltp":1.7,"tv":769.75,"id":5995}],"tv":1050.1}]}
{"op":"mcm","clk":"11835843116","pt":1723141552020,"mc":[{"id":"1.231539716","rc":[{"batl":[[0,1.74,12.96]],"ltp":1.7,"tv":769.75,"id":5995},{"batb":[[0,2.34,5.94],[1,2.18,32.13],[2,1.79,45]],"ltp":2.4,"tv":280.34,"id":31372}]}]}
{"op":"mcm","clk":"11835843326","pt":1723141553085,"mc":[{"id":"1.231539716","rc":[{"batb":[[1,1.66,53.07],[2,1.52,67.5]],"ltp":1.7,"tv":769.75,"id":5995}]}]}
{"op":"mcm","clk":"11835845942","pt":1723141568808,"mc":[{"id":"1.231539716","rc":[{"batl":[[0,1.74,18.26]],"ltp":1.7,"tv":769.75,"id":5995}]}]}
{"op":"mcm","clk":"11835916734","pt":1723141964729,"mc":[{"id":"1.231539716","rc":[{"batb":[[1,2.18,42.05]],"ltp":2.4,"tv":280.34,"id":31372}]}]}
{"op":"mcm","clk":"11836240628","pt":1723144015443,"mc":[{"id":"1.231539716","rc":[{"trd":[[1.5,101.61],[1.51,169.36]],"batb":[[0,1.71,4.55],[1,1.7,30.32],[2,1.66,53.07]],"ltp":1.7,"tv":769.63,"id":5995},{"trd":[[1.5,101.85],[1.51,169.36]],"ltp":2.4,"tv":280.22,"id":31372}],"tv":1049.85}]}
{"op":"mcm","clk":"11836241912","pt":1723144024748,"mc":[{"id":"1.231539716","rc":[{"batb":[[2,1.67,4.55]],"ltp":1.7,"tv":769.63,"id":5995}]}]}
{"op":"mcm","clk":"11836252476","pt":1723144110322,"mc":[{"id":"1.231539716","rc":[{"batl":[[0,2.7,4.55]],"ltp":2.4,"tv":280.22,"id":31372}]}]}
{"op":"mcm","clk":"11836253965","pt":1723144122346,"mc":[{"id":"1.231539716","rc":[{"batb":[[2,2.02,4.55]],"ltp":2.4,"tv":280.22,"id":31372}]}]}
{"op":"mcm","clk":"11836657568","pt":1723147521397,"mc":[{"id":"1.231539716","rc":[{"trd":[[1.5,101.65],[1.51,169.41],[1.71,53.8],[1.73,18],[1.74,139.22],[1.75,8.99],[1.82,8.8],[1.83,45.65]],"batb":[[0,1.71,4.55],[2,1.67,4.55]],"batl":[[0,1.74,8.26]],"ltp":1.74,"tv":789.74,"id":5995},{"trd":[[1.5,101.88],[1.51,169.41]],"batb":[[0,2.34,5.94],[2,2.02,4.55]],"batl":[[0,2.7,4.55]],"ltp":2.4,"tv":280.31,"id":31372}],"tv":1070.05}]}
{"op":"mcm","clk":"11836731197","pt":1723148548460,"mc":[{"id":"1.231539716","rc":[{"trd":[[1.74,143.23]],"batl":[[0,1.74,6.26]],"ltp":1.74,"tv":793.74,"id":5995}],"tv":1074.06}]}
{"op":"mcm","clk":"11836756261","pt":1723149033542,"mc":[{"id":"1.231539716","rc":[{"batb":[[0,1.72,5],[1,1.71,4.55],[2,1.7,30.32]],"ltp":1.74,"tv":793.74,"id":5995}]}]}
{"op":"mcm","clk":"11836756325","pt":1723149035040,"mc":[{"id":"1.231539716","rc":[{"batb":[[1,2.18,9.92]],"ltp":2.4,"tv":280.31,"id":31372}]}]}
{"op":"mcm","clk":"11836761681","pt":1723149155884,"mc":[{"id":"1.231539716","rc":[{"batb":[[0,1.71,4.55],[1,1.7,30.32],[2,1.67,4.55]],"ltp":1.74,"tv":793.74,"id":5995}]}]}
{"op":"mcm","clk":"11836761887","pt":1723149160358,"mc":[{"id":"1.231539716","rc":[{"batb":[[1,2.18,42.05]],"ltp":2.4,"tv":280.31,"id":31372}]}]}
{"op":"mcm","clk":"11836869965","pt":1723152523320,"mc":[{"id":"1.231539716","rc":[{"trd":[[1.5,101.61],[1.51,169.34]],"batb":[[0,1.71,4.55],[2,1.67,4.55]],"ltp":1.74,"tv":793.63,"id":5995},{"trd":[[1.5,101.84],[1.51,169.34]],"batb":[[2,2.02,4.55]],"batl":[[0,2.7,4.55]],"ltp":2.4,"tv":280.2,"id":31372}],"tv":1073.84}]}
{"op":"mcm","clk":"11836873678","pt":1723152658151,"mc":[{"id":"1.231539716","rc":[{"batb":[[0,2.36,14],[1,2.34,5.94],[2,2.18,42.05]],"ltp":2.4,"tv":280.2,"id":31372}]}]}
{"op":"mcm","clk":"11836873783","pt":1723152661233,"mc":[{"id":"1.231539716","rc":[{"batb":[[0,2.36,10]],"ltp":2.4,"tv":280.2,"id":31372}]}]}
{"op":"mcm","clk":"11836873812","pt":1723152662255,"mc":[{"id":"1.231539716","rc":[{"batb":[[0,2.34,5.94],[1,2.18,42.05],[2,2.02,4.55]],"ltp":2.4,"tv":280.2,"id":31372}]}]}
{"op":"mcm","clk":"11836873848","pt":1723152663847,"mc":[{"id":"1.231539716","rc":[{"batb":[[0,2.36,4],[1,2.34,5.94],[2,2.18,42.05]],"ltp":2.4,"tv":280.2,"id":31372}]}]}
{"op":"mcm","clk":"11836873905","pt":1723152665026,"mc":[{"id":"1.231539716","rc":[{"batb":[[0,2.38,10],[1,2.36,4],[2,2.34,5.94]],"ltp":2.4,"tv":280.2,"id":31372}]}]}
{"op":"mcm","clk":"11836873942","pt":1723152666558,"mc":[{"id":"1.231539716","rc":[{"batb":[[1,2.34,5.94],[2,2.18,9.92]],"ltp":2.4,"tv":280.2,"id":31372}]}]}
{"op":"mcm","clk":"11836874030","pt":1723152668521,"mc":[{"id":"1.231539716","rc":[{"batl":[[0,1.75,100],[1,1.76,200],[2,1.77,300]],"ltp":1.74,"tv":793.63,"id":5995},{"batb":[[0,2.36,4]],"ltp":2.4,"tv":280.2,"id":31372}]}]}
{"op":"mcm","clk":"11836874092","pt":1723152670527,"mc":[{"id":"1.231539716","rc":[{"batb":[[0,1.71,11.61]],"ltp":1.74,"tv":793.63,"id":5995},{"batb":[[0,2.38,10],[1,2.36,4],[2,2.34,5.94]],"ltp":2.4,"tv":280.2,"id":31372}]}]}
{"op":"mcm","clk":"11836874101","pt":1723152670731,"mc":[{"id":"1.231539716","rc":[{"batb":[[1,2.34,5.94],[2,2.18,9.92]],"ltp":2.4,"tv":280.2,"id":31372}]}]}
{"op":"mcm","clk":"11836874216","pt":1723152673245,"mc":[{"id":"1.231539716","rc":[{"batb":[[0,2.4,4],[1,2.38,10]],"ltp":2.4,"tv":280.2,"id":31372}]}]}
{"op":"mcm","clk":"11836874240","pt":1723152673862,"mc":[{"id":"1.231539716","rc":[{"batb":[[1,2.18,9.92],[2,2.02,4.55]],"ltp":2.4,"tv":280.2,"id":31372}]}]}
{"op":"mcm","clk":"11836874309","pt":1723152675554,"mc":[{"id":"1.231539716","rc":[{"batb":[[0,2.34,5.96]],"ltp":2.4,"tv":280.2,"id":31372}]}]}
{"op":"mcm","clk":"11836874349","pt":1723152676529,"mc":[{"id":"1.231539716","rc":[{"batb":[[0,2.36,10],[1,2.34,5.96],[2,2.18,42.05]],"ltp":2.4,"tv":280.2,"id":31372}]}]}
{"op":"mcm","clk":"11836874396","pt":1723152677966,"mc":[{"id":"1.231539716","rc":[{"batb":[[0,2.38,4],[1,2.36,10]],"ltp":2.4,"tv":280.2,"id":31372}]}]}
{"op":"mcm","clk":"11836874494","pt":1723152680124,"mc":[{"id":"1.231539716","rc":[{"batb":[[0,2.18,42.05],[1,2.02,4.55],[2,1.8,2]],"ltp":2.4,"tv":280.2,"id":31372}]}]}
{"op":"mcm","clk":"11836874677","pt":1723152684229,"mc":[{"id":"1.231539716","rc":[{"batb":[[0,2.2,14],[1,2.18,42.05],[2,2.02,4.55]],"ltp":2.4,"tv":280.2,"id":31372}]}]}
{"op":"mcm","clk":"11836874766","pt":1723152686439,"mc":[{"id":"1.231539716","rc":[{"batb":[[0,2.2,10]],"ltp":2.4,"tv":280.2,"id":31372}]}]}
{"op":"mcm","clk":"11836874819","pt":1723152687673,"mc":[{"id":"1.231539716","rc":[{"batb":[[0,2.18,42.05],[1,2.02,4.55],[2,1.8,2]],"ltp":2.4,"tv":280.2,"id":31372}]}]}
{"op":"mcm","clk":"11836874880","pt":1723152689465,"mc":[{"id":"1.231539716","rc":[{"batb":[[0,2.2,4],[1,2.18,42.05],[2,2.02,4.55]],"ltp":2.4,"tv":280.2,"id":31372}]}]}
{"op":"mcm","clk":"11836874915","pt":1723152690542,"mc":[{"id":"1.231539716","rc":[{"batb":[[0,2.22,10],[1,2.2,4],[2,2.18,42.05]],"ltp":2.4,"tv":280.2,"id":31372}]}]}
{"op":"mcm","clk":"11836874940","pt":1723152691774,"mc":[{"id":"1.231539716","rc":[{"batb":[[1,2.18,42.05],[2,2.02,4.55]],"ltp":2.4,"tv":280.2,"id":31372}]}]}
{"op":"mcm","clk":"11836875036","pt":1723152693851,"mc":[{"id":"1.231539716","rc":[{"batb":[[0,2.2,4]],"ltp":2.4,"tv":280.2,"id":31372}]}]}
{"op":"mcm","clk":"11836875139","pt":1723152696375,"mc":[{"id":"1.231539716","rc":[{"batb":[[0,2.2,10]],"ltp":2.4,"tv":280.2,"id":31372}]}]}
{"op":"mcm","clk":"11836875280","pt":1723152699761,"mc":[{"id":"1.231539716","rc":[{"batb":[[0,2.2,4]],"ltp":2.4,"tv":280.2,"id":31372}]}]}
{"op":"mcm","clk":"11836875371","pt":1723152702070,"mc":[{"id":"1.231539716","rc":[{"batb":[[0,2.2,10]],"ltp":2.4,"tv":280.2,"id":31372}]}]}
{"op":"mcm","clk":"11836875488","pt":1723152705567,"mc":[{"id":"1.231539716","rc":[{"batb":[[0,2.22,4]],"ltp":2.4,"tv":280.2,"id":31372}]}]}
{"op":"mcm","clk":"11836875577","pt":1723152707773,"mc":[{"id":"1.231539716","rc":[{"batb":[[0,2.2,10]],"ltp":2.4,"tv":280.2,"id":31372}]}]}
{"op":"mcm","clk":"11836875711","pt":1723152711368,"mc":[{"id":"1.231539716","rc":[{"batb":[[0,2.22,4]],"ltp":2.4,"tv":280.2,"id":31372}]}]}
{"op":"mcm","clk":"11836875723","pt":1723152711675,"mc":[{"id":"1.231539716","rc":[{"batb":[[0,2.34,5.66],[1,2.22,4],[2,2.18,42.05]],"ltp":2.4,"tv":280.2,"id":31372}]}]}
{"op":"mcm","clk":"11836875799","pt":1723152713780,"mc":[{"id":"1.231539716","rc":[{"batb":[[0,2.36,10],[1,2.34,5.66]],"ltp":2.4,"tv":280.2,"id":31372}]}]}
{"op":"mcm","clk":"11836875887","pt":1723152715886,"mc":[{"id":"1.231539716","rc":[{"batb":[[0,2.38,4],[1,2.36,10]],"ltp":2.4,"tv":280.2,"id":31372}]}]}
{"op":"mcm","clk":"11836875933","pt":1723152717070,"mc":[{"id":"1.231539716","rc":[{"batb":[[1,2.18,9.92],[2,2.02,4.55]],"ltp":2.4,"tv":280.2,"id":31372}]}]}
{"op":"mcm","clk":"11836875970","pt":1723152718198,"mc":[{"id":"1.231539716","rc":[{"batb":[[0,2.18,9.92],[1,2.02,4.55],[2,1.8,2]],"ltp":2.4,"tv":280.2,"id":31372}]}]}
{"op":"mcm","clk":"11836876059","pt":1723152720817,"mc":[{"id":"1.231539716","rc":[{"batb":[[0,2.2,14],[1,2.18,9.92],[2,2.02,4.55]],"ltp":2.4,"tv":280.2,"id":31372}]}]}
{"op":"mcm","clk":"11836876103","pt":1723152721794,"mc":[{"id":"1.231539716","rc":[{"batb":[[1,2.18,42.05]],"ltp":2.4,"tv":280.2,"id":31372}]}]}
{"op":"mcm","clk":"11836876144","pt":1723152723077,"mc":[{"id":"1.231539716","rc":[{"batb":[[0,2.2,10]],"ltp":2.4,"tv":280.2,"id":31372}]}]}
{"op":"mcm","clk":"11836876170","pt":1723152723999,"mc":[{"id":"1.231539716","rc":[{"batb":[[0,2.18,42.05],[1,2.02,4.55],[2,1.8,2]],"ltp":2.4,"tv":280.2,"id":31372}]}]}
{"op":"mcm","clk":"11836876305","pt":1723152727496,"mc":[{"id":"1.231539716","rc":[{"batb":[[0,2.2,14],[1,2.18,42.05],[2,2.02,4.55]],"ltp":2.4,"tv":280.2,"id":31372}]}]}
{"op":"mcm","clk":"11836876371","pt":1723152729596,"mc":[{"id":"1.231539716","rc":[{"batb":[[0,2.2,10]],"ltp":2.4,"tv":280.2,"id":31372}]}]}
{"op":"mcm","clk":"11836876448","pt":1723152730934,"mc":[{"id":"1.231539716","rc":[{"batb":[[0,2.18,42.05],[1,2.02,4.55],[2,1.8,2]],"ltp":2.4,"tv":280.2,"id":31372}]}]}
{"op":"mcm","clk":"11836876586","pt":1723152734520,"mc":[{"id":"1.231539716","rc":[{"batb":[[0,2.2,14],[1,2.18,42.05],[2,2.02,4.55]],"ltp":2.4,"tv":280.2,"id":31372}]}]}
{"op":"mcm","clk":"11836876656","pt":1723152736726,"mc":[{"id":"1.231539716","rc":[{"batb":[[0,2.2,10]],"ltp":2.4,"tv":280.2,"id":31372}]}]}
{"op":"mcm","clk":"11836876706","pt":1723152737921,"mc":[{"id":"1.231539716","rc":[{"batb":[[0,2.18,42.05],[1,2.02,4.55],[2,1.8,2]],"ltp":2.4,"tv":280.2,"id":31372}]}]}
{"op":"mcm","clk":"11836876736","pt":1723152739084,"mc":[{"id":"1.231539716","rc":[{"batb":[[0,2.2,4],[1,2.18,42.05],[2,2.02,4.55]],"ltp":2.4,"tv":280.2,"id":31372}]}]}
{"op":"mcm","clk":"11836876807","pt":1723152741394,"mc":[{"id":"1.231539716","rc":[{"batb":[[0,2.22,10]],"ltp":2.4,"tv":280.2,"id":31372}]}]}
{"op":"mcm","clk":"11836876882","pt":1723152743702,"mc":[{"id":"1.231539716","rc":[{"batb":[[0,2.24,4],[1,2.22,10],[2,2.18,42.05]],"ltp":2.4,"tv":280.2,"id":31372}]}]}
{"op":"mcm","clk":"11836876901","pt":1723152744624,"mc":[{"id":"1.231539716","rc":[{"batb":[[1,2.18,42.05],[2,2.02,4.55]],"ltp":2.4,"tv":280.2,"id":31372}]}]}
{"op":"mcm","clk":"11836876953","pt":1723152746011,"mc":[{"id":"1.231539716","rc":[{"batb":[[0,2.18,42.05],[1,2.02,4.55],[2,1.8,2]],"ltp":2.4,"tv":280.2,"id":31372}]}]}
{"op":"mcm","clk":"11836877031","pt":1723152748422,"mc":[{"id":"1.231539716","rc":[{"batb":[[0,2.2,14],[1,2.18,42.05],[2,2.02,4.55]],"ltp":2.4,"tv":280.2,"id":31372}]}]}
{"op":"mcm","clk":"11836877045","pt":1723152748729,"mc":[{"id":"1.231539716","rc":[{"batb":[[0,2.34,5.66],[1,2.2,14],[2,2.18,42.05]],"ltp":2.4,"tv":280.2,"id":31372}]}]}
{"op":"mcm","clk":"11836877122","pt":1723152750626,"mc":[{"id":"1.231539716","rc":[{"batb":[[1,2.2,10]],"ltp":2.4,"tv":280.2,"id":31372}]}]}
{"op":"mcm","clk":"11836877169","pt":1723152751706,"mc":[{"id":"1.231539716","rc":[{"batb":[[1,2.18,42.05],[2,2.02,4.55]],"ltp":2.4,"tv":280.2,"id":31372}]}]}
{"op":"mcm","clk":"11836877292","pt":1723152754523,"mc":[{"id":"1.231539716","rc":[{"batb":[[0,2.36,14],[1,2.34,5.66],[2,2.18,42.05]],"ltp":2.4,"tv":280.2,"id":31372}]}]}
{"op":"mcm","clk":"11836877313","pt":1723152755037,"mc":[{"id":"1.231539716","rc":[{"batb":[[1,2.18,42.05],[2,2.02,4.55]],"ltp":2.4,"tv":280.2,"id":31372}]}]}
{"op":"mcm","clk":"11836877380","pt":1723152757039,"mc":[{"id":"1.231539716","rc":[{"batb":[[0,2.36,10],[1,2.18,9.92]],"ltp":2.4,"tv":280.2,"id":31372}]}]}
{"op":"mcm","clk":"11836877401","pt":1723152757806,"mc":[{"id":"1.231539716","rc":[{"batb":[[0,2.18,9.92],[1,2.02,4.55],[2,1.8,2]],"ltp":2.4,"tv":280.2,"id":31372}]}]}
{"op":"mcm","clk":"11836877429","pt":1723152759039,"mc":[{"id":"1.231539716","rc":[{"batb":[[0,2.2,4],[1,2.18,9.92],[2,2.02,4.55]],"ltp":2.4,"tv":280.2,"id":31372}]}]}
{"op":"mcm","clk":"11836877472","pt":1723152760467,"mc":[{"id":"1.231539716","rc":[{"batb":[[0,2.22,10],[1,2.2,4],[2,2.18,9.92]],"ltp":2.4,"tv":280.2,"id":31372}]}]}
{"op":"mcm","clk":"11836877508","pt":1723152761446,"mc":[{"id":"1.231539716","rc":[{"batb":[[1,2.18,9.92],[2,2.02,4.55]],"ltp":2.4,"tv":280.2,"id":31372}]}]}
{"op":"mcm","clk":"11836877529","pt":1723152762071,"mc":[{"id":"1.231539716","rc":[{"batb":[[1,2.18,42.05]],"ltp":2.4,"tv":280.2,"id":31372}]}]}
{"op":"mcm","clk":"11836877600","pt":1723152763917,"mc":[{"id":"1.231539716","rc":[{"batb":[[0,2.2,4]],"ltp":2.4,"tv":280.2,"id":31372}]}]}
{"op":"mcm","clk":"11836877686","pt":1723152766414,"mc":[{"id":"1.231539716","rc":[{"batb":[[0,2.2,10]],"ltp":2.4,"tv":280.2,"id":31372}]}]}
{"op":"mcm","clk":"11836877846","pt":1723152769539,"mc":[{"id":"1.231539716","rc":[{"batb":[[0,2.22,4]],"ltp":2.4,"tv":280.2,"id":31372}]}]}
{"op":"mcm","clk":"11836877947","pt":1723152771262,"mc":[{"id":"1.231539716","rc":[{"batb":[[0,2.18,42.05],[1,2.02,4.55],[2,1.8,2]],"ltp":2.4,"tv":280.2,"id":31372}]}]}
{"op":"mcm","clk":"11836878000","pt":1723152772581,"mc":[{"id":"1.231539716","rc":[{"batb":[[0,2.2,10],[1,2.18,42.05],[2,2.02,4.55]],"ltp":2.4,"tv":280.2,"id":31372}]}]}
{"op":"mcm","clk":"11836878054","pt":1723152773864,"mc":[{"id":"1.231539716","rc":[{"batb":[[0,2.22,4],[1,2.2,10],[2,2.18,42.05]],"ltp":2.4,"tv":280.2,"id":31372}]}]}
{"op":"mcm","clk":"11836878180","pt":1723152776331,"mc":[{"id":"1.231539716","rc":[{"batb":[[0,2.18,42.05],[1,2.02,4.55],[2,1.8,2]],"ltp":2.4,"tv":280.2,"id":31372}]}]}
{"op":"mcm","clk":"11836878269","pt":1723152778644,"mc":[{"id":"1.231539716","rc":[{"batb":[[0,2.2,14],[1,2.18,42.05],[2,2.02,4.55]],"ltp":2.4,"tv":280.2,"id":31372}]}]}
{"op":"mcm","clk":"11836878374","pt":1723152781059,"mc":[{"id":"1.231539716","rc":[{"batb":[[0,2.2,10]],"ltp":2.4,"tv":280.2,"id":31372}]}]}
{"op":"mcm","clk":"11836878413","pt":1723152782066,"mc":[{"id":"1.231539716","rc":[{"batb":[[0,2.18,42.05],[1,2.02,4.55],[2,1.8,2]],"ltp":2.4,"tv":280.2,"id":31372}]}]}
{"op":"mcm","clk":"11836878454","pt":1723152783254,"mc":[{"id":"1.231539716","rc":[{"batb":[[0,2.2,4],[1,2.18,42.05],[2,2.02,4.55]],"ltp":2.4,"tv":280.2,"id":31372}]}]}
{"op":"mcm","clk":"11836878546","pt":1723152785455,"mc":[{"id":"1.231539716","rc":[{"batb":[[0,2.22,10],[1,2.2,4],[2,2.18,42.05]],"ltp":2.4,"tv":280.2,"id":31372}]}]}
{"op":"mcm","clk":"11836878561","pt":1723152785765,"mc":[{"id":"1.231539716","rc":[{"batb":[[0,2.34,5.66],[1,2.22,10]],"ltp":2.4,"tv":280.2,"id":31372}]}]}
{"op":"mcm","clk":"11836878628","pt":1723152787865,"mc":[{"id":"1.231539716","rc":[{"batb":[[0,2.36,4],[1,2.34,5.66],[2,2.22,10]],"ltp":2.4,"tv":280.2,"id":31372}]}]}
{"op":"mcm","clk":"11836878665","pt":1723152788753,"mc":[{"id":"1.231539716","rc":[{"batb":[[2,2.18,42.05]],"ltp":2.4,"tv":280.2,"id":31372}]}]}
{"op":"mcm","clk":"11836878737","pt":1723152790059,"mc":[{"id":"1.231539716","rc":[{"batb":[[0,2.34,5.66],[1,2.18,42.05],[2,2.02,4.55]],"ltp":2.4,"tv":280.2,"id":31372}]}]}
{"op":"mcm","clk":"11836878822","pt":1723152792640,"mc":[{"id":"1.231539716","rc":[{"batb":[[0,2.36,14],[1,2.34,5.66],[2,2.18,42.05]],"ltp":2.4,"tv":280.2,"id":31372}]}]}
{"op":"mcm","clk":"11836878862","pt":1723152793967,"mc":[{"id":"1.231539716","rc":[{"batb":[[1,2.18,42.05],[2,2.02,4.55]],"ltp":2.4,"tv":280.2,"id":31372}]}]}
{"op":"mcm","clk":"11836878900","pt":1723152794840,"mc":[{"id":"1.231539716","rc":[{"batb":[[0,2.36,10]],"ltp":2.4,"tv":280.2,"id":31372}]}]}
{"op":"mcm","clk":"11836878956","pt":1723152796073,"mc":[{"id":"1.231539716","rc":[{"batb":[[0,2.18,42.05],[1,2.02,4.55],[2,1.8,2]],"ltp":2.4,"tv":280.2,"id":31372}]}]}
{"op":"mcm","clk":"11836879033","pt":1723152798481,"mc":[{"id":"1.231539716","rc":[{"batb":[[0,2.2,14],[1,2.18,42.05],[2,2.02,4.55]],"ltp":2.4,"tv":280.2,"id":31372}]}]}
{"op":"mcm","clk":"11836879135","pt":1723152800857,"mc":[{"id":"1.231539716","rc":[{"batb":[[0,2.2,10]],"ltp":2.4,"tv":280.2,"id":31372}]}]}
{"op":"mcm","clk":"11836879163","pt":1723152801880,"mc":[{"id":"1.231539716","rc":[{"batb":[[0,2.18,42.05],[1,2.02,4.55],[2,1.8,2]],"ltp":2.4,"tv":280.2,"id":31372}]}]}
{"op":"mcm","clk":"11836879328","pt":1723152805171,"mc":[{"id":"1.231539716","rc":[{"batb":[[0,2.2,14],[1,2.18,42.05],[2,2.02,4.55]],"ltp":2.4,"tv":280.2,"id":31372}]}]}
{"op":"mcm","clk":"11836879474","pt":1723152807582,"mc":[{"id":"1.231539716","rc":[{"batb":[[0,2.2,10]],"ltp":2.4,"tv":280.2,"id":31372}]}]}
{"op":"mcm","clk":"11836879537","pt":1723152808454,"mc":[{"id":"1.231539716","rc":[{"batb":[[0,2.18,42.05],[1,2.02,4.55],[2,1.8,2]],"ltp":2.4,"tv":280.2,"id":31372}]}]}
{"op":"mcm","clk":"11836879681","pt":1723152810869,"mc":[{"id":"1.231539716","rc":[{"batb":[[0,2.2,14],[1,2.18,42.05],[2,2.02,4.55]],"ltp":2.4,"tv":280.2,"id":31372}]}]}
{"op":"mcm","clk":"11836879818","pt":1723152813080,"mc":[{"id":"1.231539716","rc":[{"batb":[[0,2.2,10]],"ltp":2.4,"tv":280.2,"id":31372}]}]}
{"op":"mcm","clk":"11836879907","pt":1723152814260,"mc":[{"id":"1.231539716","rc":[{"batb":[[0,2.18,42.05],[1,2.02,4.55],[2,1.8,2]],"ltp":2.4,"tv":280.2,"id":31372}]}]}
{"op":"mcm","clk":"11836879960","pt":1723152815693,"mc":[{"id":"1.231539716","rc":[{"batb":[[0,2.2,4],[1,2.18,42.05],[2,2.02,4.55]],"ltp":2.4,"tv":280.2,"id":31372}]}]}
{"op":"mcm","clk":"11836879996","pt":1723152816876,"mc":[{"id":"1.231539716","rc":[{"batb":[[0,2.22,10],[1,2.2,4],[2,2.18,42.05]],"ltp":2.4,"tv":280.2,"id":31372}]}]}
{"op":"mcm","clk":"11836880042","pt":1723152818104,"mc":[{"id":"1.231539716","rc":[{"batb":[[1,2.18,42.05],[2,2.02,4.55]],"ltp":2.4,"tv":280.2,"id":31372}]}]}
{"op":"mcm","clk":"11836880129","pt":1723152820272,"mc":[{"id":"1.231539716","rc":[{"batb":[[0,2.2,4]],"ltp":2.4,"tv":280.2,"id":31372}]}]}
{"op":"mcm","clk":"11836880226","pt":1723152822496,"mc":[{"id":"1.231539716","rc":[{"batb":[[0,2.36,10],[1,2.34,5.66],[2,2.18,42.05]],"ltp":2.4,"tv":280.2,"id":31372}]}]}
{"op":"mcm","clk":"11836880362","pt":1723152825581,"mc":[{"id":"1.231539716","rc":[{"batb":[[0,2.38,4],[1,2.18,42.05],[2,2.02,4.55]],"ltp":2.4,"tv":280.2,"id":31372}]}]}
{"op":"mcm","clk":"11836880420","pt":1723152827118,"mc":[{"id":"1.231539716","rc":[{"batb":[[0,2.18,42.05],[1,2.02,4.55],[2,1.8,2]],"ltp":2.4,"tv":280.2,"id":31372}]}]}
{"op":"mcm","clk":"11836880515","pt":1723152829583,"mc":[{"id":"1.231539716","rc":[{"batb":[[0,2.2,14],[1,2.18,42.05],[2,2.02,4.55]],"ltp":2.4,"tv":280.2,"id":31372}]}]}
{"op":"mcm","clk":"11836880577","pt":1723152831883,"mc":[{"id":"1.231539716","rc":[{"batb":[[0,2.2,10]],"ltp":2.4,"tv":280.2,"id":31372}]}]}
{"op":"mcm","clk":"11836880621","pt":1723152832908,"mc":[{"id":"1.231539716","rc":[{"batb":[[0,2.18,42.05],[1,2.02,4.55],[2,1.8,2]],"ltp":2.4,"tv":280.2,"id":31372}]}]}
{"op":"mcm","clk":"11836880664","pt":1723152834401,"mc":[{"id":"1.231539716","rc":[{"batb":[[0,2.2,4],[1,2.18,42.05],[2,2.02,4.55]],"ltp":2.4,"tv":280.2,"id":31372}]}]}
{"op":"mcm","clk":"11836880702","pt":1723152835494,"mc":[{"id":"1.231539716","rc":[{"batb":[[0,2.22,10],[1,2.2,4],[2,2.18,42.05]],"ltp":2.4,"tv":280.2,"id":31372}]}]}
{"op":"mcm","clk":"11836880744","pt":1723152836715,"mc":[{"id":"1.231539716","rc":[{"batb":[[1,2.18,42.05],[2,2.02,4.55]],"ltp":2.4,"tv":280.2,"id":31372}]}]}
{"op":"mcm","clk":"11836880825","pt":1723152838610,"mc":[{"id":"1.231539716","rc":[{"batb":[[0,2.18,42.05],[1,2.02,4.55],[2,1.8,2]],"ltp":2.4,"tv":280.2,"id":31372}]}]}
{"op":"mcm","clk":"11836880879","pt":1723152840204,"mc":[{"id":"1.231539716","rc":[{"batb":[[0,2.2,4],[1,2.18,42.05],[2,2.02,4.55]],"ltp":2.4,"tv":280.2,"id":31372}]}]}
{"op":"mcm","clk":"11836880921","pt":1723152841328,"mc":[{"id":"1.231539716","rc":[{"batb":[[0,2.22,10],[1,2.2,4],[2,2.18,42.05]],"ltp":2.4,"tv":280.2,"id":31372}]}]}
{"op":"mcm","clk":"11836880986","pt":1723152842613,"mc":[{"id":"1.231539716","rc":[{"batb":[[1,2.18,42.05],[2,2.02,4.55]],"ltp":2.4,"tv":280.2,"id":31372}]}]}
{"op":"mcm","clk":"11836881075","pt":1723152844918,"mc":[{"id":"1.231539716","rc":[{"batb":[[0,2.2,4]],"ltp":2.4,"tv":280.2,"id":31372}]}]}
{"op":"mcm","clk":"11836881175","pt":1723152847326,"mc":[{"id":"1.231539716","rc":[{"batb":[[0,2.2,10]],"ltp":2.4,"tv":280.2,"id":31372}]}]}
{"op":"mcm","clk":"11836881298","pt":1723152850608,"mc":[{"id":"1.231539716","rc":[{"batb":[[0,2.2,4]],"ltp":2.4,"tv":280.2,"id":31372}]}]}
{"op":"mcm","clk":"11836881357","pt":1723152851998,"mc":[{"id":"1.231539716","rc":[{"batl":[[0,1.74,4.91],[1,1.75,100],[2,1.76,200]],"ltp":1.74,"tv":793.63,"id":5995}]}]}
{"op":"mcm","clk":"11836881403","pt":1723152853024,"mc":[{"id":"1.231539716","rc":[{"batb":[[0,2.2,10]],"ltp":2.4,"tv":280.2,"id":31372}]}]}
{"op":"mcm","clk":"11836881480","pt":1723152855340,"mc":[{"id":"1.231539716","rc":[{"batb":[[0,2.22,4],[1,2.2,10],[2,2.18,42.05]],"ltp":2.4,"tv":280.2,"id":31372}]}]}
{"op":"mcm","clk":"11836881529","pt":1723152856322,"mc":[{"id":"1.231539716","rc":[{"batb":[[1,2.18,42.05],[2,2.02,4.55]],"ltp":2.4,"tv":280.2,"id":31372}]}]}
{"op":"mcm","clk":"11836881622","pt":1723152858534,"mc":[{"id":"1.231539716","rc":[{"batb":[[0,2.36,10],[1,2.34,5.94],[2,2.18,42.05]],"ltp":2.4,"tv":280.2,"id":31372}]}]}
{"op":"mcm","clk":"11836881691","pt":1723152860433,"mc":[{"id":"1.231539716","rc":[{"batb":[[0,2.38,4],[1,2.36,10],[2,2.34,5.94]],"ltp":2.4,"tv":280.2,"id":31372}]}]}
{"op":"mcm","clk":"11836881735","pt":1723152861720,"mc":[{"id":"1.231539716","rc":[{"batb":[[1,2.34,5.94],[2,2.18,42.05]],"ltp":2.4,"tv":280.2,"id":31372}]}]}
{"op":"mcm","clk":"11836881763","pt":1723152862747,"mc":[{"id":"1.231539716","rc":[{"batb":[[0,2.34,5.94],[1,2.18,42.05],[2,2.02,4.55]],"ltp":2.4,"tv":280.2,"id":31372}]}]}
{"op":"mcm","clk":"11836881822","pt":1723152864848,"mc":[{"id":"1.231539716","rc":[{"batb":[[0,2.36,14],[1,2.34,5.94],[2,2.18,42.05]],"ltp":2.4,"tv":280.2,"id":31372}]}]}
{"op":"mcm","clk":"11836881936","pt":1723152867529,"mc":[{"id":"1.231539716","rc":[{"batb":[[0,2.36,10],[2,2.18,9.92]],"ltp":2.4,"tv":280.2,"id":31372}]}]}
{"op":"mcm","clk":"11836881954","pt":1723152868142,"mc":[{"id":"1.231539716","rc":[{"batb":[[0,2.34,5.94],[1,2.18,9.92],[2,2.02,4.55]],"ltp":2.4,"tv":280.2,"id":31372}]}]}
{"op":"mcm","clk":"11836882014","pt":1723152869433,"mc":[{"id":"1.231539716","rc":[{"batb":[[0,2.36,4],[1,2.34,5.94],[2,2.18,9.92]],"ltp":2.4,"tv":280.2,"id":31372}]}]}
{"op":"mcm","clk":"11836882103","pt":1723152871945,"mc":[{"id":"1.231539716","rc":[{"batb":[[0,2.36,10]],"ltp":2.4,"tv":280.2,"id":31372}]}]}
{"op":"mcm","clk":"11836882231","pt":1723152875340,"mc":[{"id":"1.231539716","rc":[{"batb":[[0,2.38,4]],"ltp":2.4,"tv":280.2,"id":31372}]}]}
{"op":"mcm","clk":"11836882355","pt":1723152877550,"mc":[{"id":"1.231539716","rc":[{"batb":[[0,2.34,5.94],[1,2.18,42.05],[2,2.02,4.55]],"ltp":2.4,"tv":280.2,"id":31372}]}]}
{"op":"mcm","clk":"11836882362","pt":1723152877651,"mc":[{"id":"1.231539716","rc":[{"batb":[[0,2.36,10],[1,2.34,5.94],[2,2.18,42.05]],"ltp":2.4,"tv":280.2,"id":31372}]}]}
{"op":"mcm","clk":"11836882515","pt":1723152881144,"mc":[{"id":"1.231539716","rc":[{"batb":[[0,2.36,4]],"ltp":2.4,"tv":280.2,"id":31372}]}]}
{"op":"mcm","clk":"11836882620","pt":1723152883563,"mc":[{"id":"1.231539716","rc":[{"batb":[[0,2.36,10]],"ltp":2.4,"tv":280.2,"id":31372}]}]}
{"op":"mcm","clk":"11836882716","pt":1723152885878,"mc":[{"id":"1.231539716","rc":[{"batb":[[0,2.38,4],[1,2.36,10],[2,2.34,5.94]],"ltp":2.4,"tv":280.2,"id":31372}]}]}
{"op":"mcm","clk":"11836882769","pt":1723152886956,"mc":[{"id":"1.231539716","rc":[{"batb":[[1,2.34,5.94],[2,2.18,42.05]],"ltp":2.4,"tv":280.2,"id":31372}]}]}
{"op":"mcm","clk":"11836882810","pt":1723152888142,"mc":[{"id":"1.231539716","rc":[{"batb":[[0,2.34,5.94],[1,2.18,42.05],[2,2.02,4.55]],"ltp":2.4,"tv":280.2,"id":31372}]}]}
{"op":"mcm","clk":"11836882887","pt":1723152890350,"mc":[{"id":"1.231539716","rc":[{"batb":[[0,2.36,14],[1,2.34,5.94],[2,2.18,42.05]],"ltp":2.4,"tv":280.2,"id":31372}]}]}
{"op":"mcm","clk":"11836883000","pt":1723152893583,"mc":[{"id":"1.231539716","rc":[{"batb":[[0,2.34,5.94],[1,2.18,9.92],[2,2.02,4.55]],"ltp":2.4,"tv":280.2,"id":31372}]}]}
{"op":"mcm","clk":"11836883068","pt":1723152894971,"mc":[{"id":"1.231539716","rc":[{"batb":[[0,2.36,4],[1,2.34,5.94],[2,2.18,9.92]],"ltp":2.4,"tv":280.2,"id":31372}]}]}
{"op":"mcm","clk":"11836883131","pt":1723152896283,"mc":[{"id":"1.231539716","rc":[{"batb":[[0,2.38,10],[1,2.36,4],[2,2.34,5.94]],"ltp":2.4,"tv":280.2,"id":31372}]}]}
{"op":"mcm","clk":"11836883181","pt":1723152897262,"mc":[{"id":"1.231539716","rc":[{"batb":[[1,2.34,5.94],[2,2.18,9.92]],"ltp":2.4,"tv":280.2,"id":31372}]}]}
{"op":"mcm","clk":"11836883209","pt":1723152898079,"mc":[{"id":"1.231539716","rc":[{"batl":[[0,1.75,100],[1,1.76,200],[2,1.77,300]],"ltp":1.74,"tv":793.63,"id":5995}]}]}
{"op":"mcm","clk":"11836883270","pt":1723152900080,"mc":[{"id":"1.231539716","rc":[{"batb":[[0,2.36,4],[1,2.18,9.92],[2,2.02,4.55]],"ltp":2.4,"tv":280.2,"id":31372}]}]}
{"op":"mcm","clk":"11836883355","pt":1723152902489,"mc":[{"id":"1.231539716","rc":[{"batb":[[0,2.34,5.96],[1,2.2,10],[2,2.18,9.92]],"ltp":2.4,"tv":280.2,"id":31372}]}]}
{"op":"mcm","clk":"11836883368","pt":1723152902759,"mc":[{"id":"1.231539716","rc":[{"batb":[[2,2.18,42.05]],"ltp":2.4,"tv":280.2,"id":31372}]}]}
{"op":"mcm","clk":"11836883438","pt":1723152904854,"mc":[{"id":"1.231539716","rc":[{"batb":[[0,2.36,4],[1,2.34,5.96],[2,2.2,10]],"ltp":2.4,"tv":280.2,"id":31372}]}]}
{"op":"mcm","clk":"11836883477","pt":1723152905879,"mc":[{"id":"1.231539716","rc":[{"batb":[[2,2.18,42.05]],"ltp":2.4,"tv":280.2,"id":31372}]}]}
{"op":"mcm","clk":"11836883525","pt":1723152907363,"mc":[{"id":"1.231539716","rc":[{"batb":[[0,2.34,5.96],[1,2.18,42.05],[2,2.02,4.55]],"ltp":2.4,"tv":280.2,"id":31372}]}]}
{"op":"mcm","clk":"11836883620","pt":1723152909578,"mc":[{"id":"1.231539716","rc":[{"batb":[[0,2.36,14],[1,2.34,5.96],[2,2.18,42.05]],"ltp":2.4,"tv":280.2,"id":31372}]}]}
{"op":"mcm","clk":"11836883678","pt":1723152910870,"mc":[{"id":"1.231539716","rc":[{"batb":[[1,2.18,42.05],[2,2.02,4.55]],"ltp":2.4,"tv":280.2,"id":31372}]}]}
{"op":"mcm","clk":"11836883730","pt":1723152911956,"mc":[{"id":"1.231539716","rc":[{"batb":[[0,2.36,10]],"ltp":2.4,"tv":280.2,"id":31372}]}]}
{"op":"mcm","clk":"11836883783","pt":1723152913079,"mc":[{"id":"1.231539716","rc":[{"batb":[[0,2.18,9.92],[1,2.02,4.55],[2,1.8,2]],"ltp":2.4,"tv":280.2,"id":31372}]}]}
{"op":"mcm","clk":"11836883882","pt":1723152915494,"mc":[{"id":"1.231539716","rc":[{"batb":[[0,2.2,14],[1,2.18,9.92],[2,2.02,4.55]],"ltp":2.4,"tv":280.2,"id":31372}]}]}
{"op":"mcm","clk":"11836883978","pt":1723152917751,"mc":[{"id":"1.231539716","rc":[{"batb":[[0,2.2,10],[1,2.18,42.05]],"ltp":2.4,"tv":280.2,"id":31372}]}]}
{"op":"mcm","clk":"11836884026","pt":1723152918776,"mc":[{"id":"1.231539716","rc":[{"batb":[[0,2.18,42.05],[1,2.02,4.55],[2,1.8,2]],"ltp":2.4,"tv":280.2,"id":31372}]}]}
{"op":"mcm","clk":"11836884077","pt":1723152920060,"mc":[{"id":"1.231539716","rc":[{"batb":[[0,2.2,4],[1,2.18,42.05],[2,2.02,4.55]],"ltp":2.4,"tv":280.2,"id":31372}]}]}
{"op":"mcm","clk":"11836884184","pt":1723152922370,"mc":[{"id":"1.231539716","rc":[{"batb":[[0,2.22,10]],"ltp":2.4,"tv":280.2,"id":31372}]}]}
{"op":"mcm","clk":"11836884343","pt":1723152925961,"mc":[{"id":"1.231539716","rc":[{"batb":[[0,2.2,4]],"ltp":2.4,"tv":280.2,"id":31372}]}]}
{"op":"mcm","clk":"11836884446","pt":1723152928480,"mc":[{"id":"1.231539716","rc":[{"batb":[[0,2.2,10]],"ltp":2.4,"tv":280.2,"id":31372}]}]}
{"op":"mcm","clk":"11836884519","pt":1723152930785,"mc":[{"id":"1.231539716","rc":[{"batb":[[0,2.22,4],[1,2.2,10],[2,2.18,42.05]],"ltp":2.4,"tv":280.2,"id":31372}]}]}
{"op":"mcm","clk":"11836884557","pt":1723152931761,"mc":[{"id":"1.231539716","rc":[{"batb":[[1,2.18,42.05],[2,2.02,4.55]],"ltp":2.4,"tv":280.2,"id":31372}]}]}
{"op":"mcm","clk":"11836884601","pt":1723152933296,"mc":[{"id":"1.231539716","rc":[{"batb":[[0,2.18,42.05],[1,2.02,4.55],[2,1.8,2]],"ltp":2.4,"tv":280.2,"id":31372}]}]}
{"op":"mcm","clk":"11836884645","pt":1723152934372,"mc":[{"id":"1.231539716","rc":[{"batb":[[0,2.2,10],[1,2.18,42.05],[2,2.02,4.55]],"ltp":2.4,"tv":280.2,"id":31372}]}]}
{"op":"mcm","clk":"11836884690","pt":1723152935702,"mc":[{"id":"1.231539716","rc":[{"batb":[[0,2.22,4],[1,2.2,10],[2,2.18,42.05]],"ltp":2.4,"tv":280.2,"id":31372}]}]}
{"op":"mcm","clk":"11836884758","pt":1723152937601,"mc":[{"id":"1.231539716","rc":[{"batb":[[1,2.18,42.05],[2,2.02,4.55]],"ltp":2.4,"tv":280.2,"id":31372}]}]}
{"op":"mcm","clk":"11836884767","pt":1723152937959,"mc":[{"id":"1.231539716","rc":[{"batb":[[0,2.34,5.66]],"ltp":2.4,"tv":280.2,"id":31372}]}]}
{"op":"mcm","clk":"11836884858","pt":1723152940167,"mc":[{"id":"1.231539716","rc":[{"batb":[[0,2.36,14],[1,2.34,5.66],[2,2.18,42.05]],"ltp":2.4,"tv":280.2,"id":31372}]}]}
{"op":"mcm","clk":"11836884950","pt":1723152942471,"mc":[{"id":"1.231539716","rc":[{"batb":[[0,2.36,10],[1,2.18,42.05],[2,2.02,4.55]],"ltp":2.4,"tv":280.2,"id":31372}]}]}
{"op":"mcm","clk":"11836885001","pt":1723152943596,"mc":[{"id":"1.231539716","rc":[{"batb":[[0,2.18,9.92],[1,2.02,4.55],[2,1.8,2]],"ltp":2.4,"tv":280.2,"id":31372}]}]}
{"op":"mcm","clk":"11836885028","pt":1723152944672,"mc":[{"id":"1.231539716","rc":[{"batb":[[0,2.2,4],[1,2.18,9.92],[2,2.02,4.55]],"ltp":2.4,"tv":280.2,"id":31372}]}]}
{"op":"mcm","clk":"11836885075","pt":1723152946002,"mc":[{"id":"1.231539716","rc":[{"batb":[[0,2.22,10],[1,2.2,4],[2,2.18,9.92]],"ltp":2.4,"tv":280.2,"id":31372}]}]}
{"op":"mcm","clk":"11836885112","pt":1723152946979,"mc":[{"id":"1.231539716","rc":[{"batb":[[1,2.18,9.92],[2,2.02,4.55]],"ltp":2.4,"tv":280.2,"id":31372}]}]}
{"op":"mcm","clk":"11836885155","pt":1723152948009,"mc":[{"id":"1.231539716","rc":[{"batb":[[1,2.18,42.05]],"ltp":2.4,"tv":280.2,"id":31372}]}]}
{"op":"mcm","clk":"11836885206","pt":1723152949297,"mc":[{"id":"1.231539716","rc":[{"batb":[[0,2.24,4]],"ltp":2.4,"tv":280.2,"id":31372}]}]}
{"op":"mcm","clk":"11836885309","pt":1723152951501,"mc":[{"id":"1.231539716","rc":[{"batb":[[0,2.18,42.05],[1,2.02,4.55],[2,1.8,2]],"ltp":2.4,"tv":280.2,"id":31372}]}]}
{"op":"mcm","clk":"11836885318","pt":1723152951705,"mc":[{"id":"1.231539716","rc":[{"batb":[[0,2.2,10],[1,2.18,42.05],[2,2.02,4.55]],"ltp":2.4,"tv":280.2,"id":31372}]}]}
{"op":"mcm","clk":"11836885627","pt":1723152954380,"mc":[{"id":"1.231539716","rc":[{"batb":[[0,2.22,4],[1,2.2,10],[2,2.18,42.05]],"ltp":2.4,"tv":280.2,"id":31372}]}]}
{"op":"mcm","clk":"11836885711","pt":1723152954887,"mc":[{"id":"1.231539716","rc":[{"batb":[[1,2.18,42.05],[2,2.02,4.55]],"ltp":2.4,"tv":280.2,"id":31372}]}]}
{"op":"mcm","clk":"11836885851","pt":1723152956661,"mc":[{"id":"1.231539716","rc":[{"batb":[[0,2.18,42.05],[1,2.02,4.55],[2,1.8,2]],"ltp":2.4,"tv":280.2,"id":31372}]}]}
{"op":"mcm","clk":"11836885981","pt":1723152958973,"mc":[{"id":"1.231539716","rc":[{"batb":[[0,2.2,14],[1,2.18,42.05],[2,2.02,4.55]],"ltp":2.4,"tv":280.2,"id":31372}]}]}
{"op":"mcm","clk":"11836886097","pt":1723152961386,"mc":[{"id":"1.231539716","rc":[{"batb":[[0,2.2,10]],"ltp":2.4,"tv":280.2,"id":31372}]}]}
{"op":"mcm","clk":"11836886142","pt":1723152962362,"mc":[{"id":"1.231539716","rc":[{"batb":[[0,2.18,42.05],[1,2.02,4.55],[2,1.8,2]],"ltp":2.4,"tv":280.2,"id":31372}]}]}
{"op":"mcm","clk":"11836886226","pt":1723152964255,"mc":[{"id":"1.231539716","rc":[{"batb":[[0,2.2,4],[1,2.18,42.05],[2,2.02,4.55]],"ltp":2.4,"tv":280.2,"id":31372}]}]}
{"op":"mcm","clk":"11836886287","pt":1723152965948,"mc":[{"id":"1.231539716","rc":[{"batb":[[0,2.22,10],[1,2.2,4],[2,2.18,42.05]],"ltp":2.4,"tv":280.2,"id":31372}]}]}
{"op":"mcm","clk":"11836886317","pt":1723152966666,"mc":[{"id":"1.231539716","rc":[{"batb":[[1,2.18,42.05],[2,2.02,4.55]],"ltp":2.4,"tv":280.2,"id":31372}]}]}
{"op":"mcm","clk":"11836886430","pt":1723152969279,"mc":[{"id":"1.231539716","rc":[{"batb":[[0,2.24,4]],"ltp":2.4,"tv":280.2,"id":31372}]}]}
{"op":"mcm","clk":"11836886509","pt":1723152971389,"mc":[{"id":"1.231539716","rc":[{"batb":[[0,2.2,10]],"ltp":2.4,"tv":280.2,"id":31372}]}]}
{"op":"mcm","clk":"11836886651","pt":1723152974580,"mc":[{"id":"1.231539716","rc":[{"batb":[[0,2.18,42.05],[1,2.02,4.55],[2,1.8,2]],"ltp":2.4,"tv":280.2,"id":31372}]}]}
{"op":"mcm","clk":"11836886697","pt":1723152975553,"mc":[{"id":"1.231539716","rc":[{"batb":[[0,2.34,5.66],[1,2.2,4],[2,2.18,42.05]],"ltp":2.4,"tv":280.2,"id":31372}]}]}
{"op":"mcm","clk":"11836886755","pt":1723152977192,"mc":[{"id":"1.231539716","rc":[{"batb":[[0,2.36,10],[1,2.34,5.66]],"ltp":2.4,"tv":280.2,"id":31372}]}]}
{"op":"mcm","clk":"11836886799","pt":1723152978171,"mc":[{"id":"1.231539716","rc":[{"batb":[[2,2.18,9.92]],"ltp":2.4,"tv":280.2,"id":31372}]}]}
{"op":"mcm","clk":"11836886842","pt":1723152979557,"mc":[{"id":"1.231539716","rc":[{"batb":[[1,2.18,9.92],[2,2.02,4.55]],"ltp":2.4,"tv":280.2,"id":31372}]}]}
{"op":"mcm","clk":"11836886893","pt":1723152980379,"mc":[{"id":"1.231539716","rc":[{"batb":[[0,2.38,4]],"ltp":2.4,"tv":280.2,"id":31372}]}]}
{"op":"mcm","clk":"11836886965","pt":1723152981872,"mc":[{"id":"1.231539716","rc":[{"batb":[[0,2.18,9.92],[1,2.02,4.55],[2,1.8,2]],"ltp":2.4,"tv":280.2,"id":31372}]}]}
{"op":"mcm","clk":"11836887028","pt":1723152983261,"mc":[{"id":"1.231539716","rc":[{"batb":[[0,2.2,10],[1,2.18,42.05],[2,2.02,4.55]],"ltp":2.4,"tv":280.2,"id":31372}]}]}
{"op":"mcm","clk":"11836887089","pt":1723152985159,"mc":[{"id":"1.231539716","rc":[{"batb":[[0,2.22,4],[1,2.2,10],[2,2.18,42.05]],"ltp":2.4,"tv":280.2,"id":31372}]}]}
{"op":"mcm","clk":"11836887132","pt":1723152986589,"mc":[{"id":"1.231539716","rc":[{"batb":[[1,2.18,42.05],[2,2.02,4.55]],"ltp":2.4,"tv":280.2,"id":31372}]}]}
{"op":"mcm","clk":"11836887155","pt":1723152987562,"mc":[{"id":"1.231539716","rc":[{"batb":[[0,2.18,42.05],[1,2.02,4.55],[2,1.8,2]],"ltp":2.4,"tv":280.2,"id":31372}]}]}
{"op":"mcm","clk":"11836887221","pt":1723152989766,"mc":[{"id":"1.231539716","rc":[{"batb":[[0,2.2,14],[1,2.18,42.05],[2,2.02,4.55]],"ltp":2.4,"tv":280.2,"id":31372}]}]}
{"op":"mcm","clk":"11836887290","pt":1723152991966,"mc":[{"id":"1.231539716","rc":[{"batb":[[0,2.2,10]],"ltp":2.4,"tv":280.2,"id":31372}]}]}
{"op":"mcm","clk":"11836887313","pt":1723152993091,"mc":[{"id":"1.231539716","rc":[{"batb":[[0,2.18,42.05],[1,2.02,4.55],[2,1.8,2]],"ltp":2.4,"tv":280.2,"id":31372}]}]}
{"op":"mcm","clk":"11836887393","pt":1723152996268,"mc":[{"id":"1.231539716","rc":[{"batb":[[0,2.2,14],[1,2.18,42.05],[2,2.02,4.55]],"ltp":2.4,"tv":280.2,"id":31372}]}]}
{"op":"mcm","clk":"11836887460","pt":1723152998568,"mc":[{"id":"1.231539716","rc":[{"batb":[[0,2.2,10]],"ltp":2.4,"tv":280.2,"id":31372}]}]}
{"op":"mcm","clk":"11836887505","pt":1723152999596,"mc":[{"id":"1.231539716","rc":[{"batb":[[0,2.18,42.05],[1,2.02,4.55],[2,1.8,2]],"ltp":2.4,"tv":280.2,"id":31372}]}]}
{"op":"mcm","clk":"11836887541","pt":1723153000775,"mc":[{"id":"1.231539716","rc":[{"batb":[[0,2.2,4],[1,2.18,42.05],[2,2.02,4.55]],"ltp":2.4,"tv":280.2,"id":31372}]}]}
{"op":"mcm","clk":"11836887621","pt":1723153003189,"mc":[{"id":"1.231539716","rc":[{"batb":[[0,2.2,10]],"ltp":2.4,"tv":280.2,"id":31372}]}]}
{"op":"mcm","clk":"11836887740","pt":1723153006465,"mc":[{"id":"1.231539716","rc":[{"batb":[[0,2.22,4]],"ltp":2.4,"tv":280.2,"id":31372}]}]}
{"op":"mcm","clk":"11836887778","pt":1723153008000,"mc":[{"id":"1.231539716","rc":[{"batb":[[0,2.18,42.05],[1,2.02,4.55],[2,1.8,2]],"ltp":2.4,"tv":280.2,"id":31372}]}]}
{"op":"mcm","clk":"11836887817","pt":1723153009283,"mc":[{"id":"1.231539716","rc":[{"batb":[[0,2.2,10],[1,2.18,42.05],[2,2.02,4.55]],"ltp":2.4,"tv":280.2,"id":31372}]}]}
{"op":"mcm","clk":"11836887927","pt":1723153012615,"mc":[{"id":"1.231539716","rc":[{"batb":[[0,2.34,5.66],[1,2.22,4],[2,2.18,42.05]],"ltp":2.4,"tv":280.2,"id":31372}]}]}
{"op":"mcm","clk":"11836887988","pt":1723153014408,"mc":[{"id":"1.231539716","rc":[{"batb":[[1,2.18,42.05],[2,2.02,4.55]],"ltp":2.4,"tv":280.2,"id":31372}]}]}
{"op":"mcm","clk":"11836888086","pt":1723153017393,"mc":[{"id":"1.231539716","rc":[{"batb":[[0,2.36,14],[1,2.34,5.66],[2,2.18,42.05]],"ltp":2.4,"tv":280.2,"id":31372}]}]}
{"op":"mcm","clk":"11836888127","pt":1723153018521,"mc":[{"id":"1.231539716","rc":[{"batb":[[1,2.18,9.92],[2,2.02,4.55]],"ltp":2.4,"tv":280.2,"id":31372}]}]}
{"op":"mcm","clk":"11836888178","pt":1723153019803,"mc":[{"id":"1.231539716","rc":[{"batb":[[0,2.36,10]],"ltp":2.4,"tv":280.2,"id":31372}]}]}
{"op":"mcm","clk":"11836888209","pt":1723153020824,"mc":[{"id":"1.231539716","rc":[{"batb":[[0,2.18,9.92],[1,2.02,4.55],[2,1.8,2]],"ltp":2.4,"tv":280.2,"id":31372}]}]}
{"op":"mcm","clk":"11836888293","pt":1723153023489,"mc":[{"id":"1.231539716","rc":[{"batb":[[0,2.2,14],[1,2.18,42.05],[2,2.02,4.55]],"ltp":2.4,"tv":280.2,"id":31372}]}]}
{"op":"mcm","clk":"11836888361","pt":1723153025492,"mc":[{"id":"1.231539716","rc":[{"batb":[[0,2.2,10]],"ltp":2.4,"tv":280.2,"id":31372}]}]}
{"op":"mcm","clk":"11836888393","pt":1723153026514,"mc":[{"id":"1.231539716","rc":[{"batb":[[0,2.18,42.05],[1,2.02,4.55],[2,1.8,2]],"ltp":2.4,"tv":280.2,"id":31372}]}]}
{"op":"mcm","clk":"11836888433","pt":1723153027694,"mc":[{"id":"1.231539716","rc":[{"batb":[[0,2.2,4],[1,2.18,42.05],[2,2.02,4.55]],"ltp":2.4,"tv":280.2,"id":31372}]}]}
{"op":"mcm","clk":"11836888486","pt":1723153029127,"mc":[{"id":"1.231539716","rc":[{"batb":[[0,2.22,10],[1,2.2,4],[2,2.18,42.05]],"ltp":2.4,"tv":280.2,"id":31372}]}]}
{"op":"mcm","clk":"11836888527","pt":1723153030101,"mc":[{"id":"1.231539716","rc":[{"batb":[[1,2.18,42.05],[2,2.02,4.55]],"ltp":2.4,"tv":280.2,"id":31372}]}]}
{"op":"mcm","clk":"11836888595","pt":1723153032617,"mc":[{"id":"1.231539716","rc":[{"batb":[[0,2.2,4]],"ltp":2.4,"tv":280.2,"id":31372}]}]}
{"op":"mcm","clk":"11836888667","pt":1723153034922,"mc":[{"id":"1.231539716","rc":[{"batb":[[0,2.2,10]],"ltp":2.4,"tv":280.2,"id":31372}]}]}
{"op":"mcm","clk":"11836888791","pt":1723153038415,"mc":[{"id":"1.231539716","rc":[{"batb":[[0,2.2,4]],"ltp":2.4,"tv":280.2,"id":31372}]}]}
{"op":"mcm","clk":"11836888822","pt":1723153039131,"mc":[{"id":"1.231539716","rc":[{"batl":[[0,1.74,4.91],[1,1.75,100],[2,1.76,200]],"ltp":1.74,"tv":793.63,"id":5995}]}]}
{"op":"mcm","clk":"11836888894","pt":1723153040824,"mc":[{"id":"1.231539716","rc":[{"batb":[[0,2.2,10]],"ltp":2.4,"tv":280.2,"id":31372}]}]}
{"op":"mcm","clk":"11836888957","pt":1723153043030,"mc":[{"id":"1.231539716","rc":[{"batb":[[0,2.22,4],[1,2.2,10],[2,2.18,42.05]],"ltp":2.4,"tv":280.2,"id":31372}]}]}
{"op":"mcm","clk":"11836889004","pt":1723153044213,"mc":[{"id":"1.231539716","rc":[{"batb":[[1,2.18,42.05],[2,2.02,4.55]],"ltp":2.4,"tv":280.2,"id":31372}]}]}
{"op":"mcm","clk":"11836889036","pt":1723153045341,"mc":[{"id":"1.231539716","rc":[{"batb":[[0,2.18,42.05],[1,2.02,4.55],[2,1.8,2]],"ltp":2.4,"tv":280.2,"id":31372}]}]}
{"op":"mcm","clk":"11836889125","pt":1723153047754,"mc":[{"id":"1.231539716","rc":[{"batb":[[0,2.2,14],[1,2.18,42.05],[2,2.02,4.55]],"ltp":2.4,"tv":280.2,"id":31372}]}]}
{"op":"mcm","clk":"11836889186","pt":1723153050116,"mc":[{"id":"1.231539716","rc":[{"batb":[[0,2.2,10]],"ltp":2.4,"tv":280.2,"id":31372}]}]}
{"op":"mcm","clk":"11836889225","pt":1723153051243,"mc":[{"id":"1.231539716","rc":[{"batb":[[0,2.34,5.94]],"ltp":2.4,"tv":280.2,"id":31372}]}]}
{"op":"mcm","clk":"11836889294","pt":1723153053349,"mc":[{"id":"1.231539716","rc":[{"batb":[[0,2.36,14],[1,2.34,5.94],[2,2.18,42.05]],"ltp":2.4,"tv":280.2,"id":31372}]}]}
{"op":"mcm","clk":"11836889311","pt":1723153053719,"mc":[{"id":"1.231539716","rc":[{"batb":[[2,2.18,9.92]],"ltp":2.4,"tv":280.2,"id":31372}]}]}
{"op":"mcm","clk":"11836889393","pt":1723153055552,"mc":[{"id":"1.231539716","rc":[{"batb":[[0,2.36,10]],"ltp":2.4,"tv":280.2,"id":31372}]}]}
{"op":"mcm","clk":"11836889434","pt":1723153056528,"mc":[{"id":"1.231539716","rc":[{"batb":[[0,2.34,5.94],[1,2.18,9.92],[2,2.02,4.55]],"ltp":2.4,"tv":280.2,"id":31372}]}]}
{"op":"mcm","clk":"11836889505","pt":1723153057762,"mc":[{"id":"1.231539716","rc":[{"batb":[[0,2.36,4],[1,2.34,5.94],[2,2.18,9.92]],"ltp":2.4,"tv":280.2,"id":31372}]}]}
{"op":"mcm","clk":"11836889555","pt":1723153058736,"mc":[{"id":"1.231539716","rc":[{"batb":[[0,2.38,10],[1,2.36,4],[2,2.34,5.94]],"ltp":2.4,"tv":280.2,"id":31372}]}]}
{"op":"mcm","clk":"11836889615","pt":1723153060128,"mc":[{"id":"1.231539716","rc":[{"batb":[[1,2.34,5.94],[2,2.18,42.05]],"ltp":2.4,"tv":280.2,"id":31372}]}]}
{"op":"mcm","clk":"11836889689","pt":1723153062019,"mc":[{"id":"1.231539716","rc":[{"batb":[[0,2.34,5.94],[1,2.18,42.05],[2,2.02,4.55]],"ltp":2.4,"tv":280.2,"id":31372}]}]}
{"op":"mcm","clk":"11836889727","pt":1723153063147,"mc":[{"id":"1.231539716","rc":[{"batb":[[0,2.36,4],[1,2.34,5.94],[2,2.18,42.05]],"ltp":2.4,"tv":280.2,"id":31372}]}]}
{"op":"mcm","clk":"11836889774","pt":1723153064529,"mc":[{"id":"1.231539716","rc":[{"batb":[[0,2.38,10],[1,2.36,4],[2,2.34,5.94]],"ltp":2.4,"tv":280.2,"id":31372}]}]}
{"op":"mcm","clk":"11836889814","pt":1723153065655,"mc":[{"id":"1.231539716","rc":[{"batb":[[1,2.34,5.94],[2,2.18,42.05]],"ltp":2.4,"tv":280.2,"id":31372}]}]}
{"op":"mcm","clk":"11836889854","pt":1723153066836,"mc":[{"id":"1.231539716","rc":[{"batl":[[0,1.75,100],[1,1.76,200],[2,1.77,300]],"ltp":1.74,"tv":793.63,"id":5995}]}]}
{"op":"mcm","clk":"11836889892","pt":1723153068068,"mc":[{"id":"1.231539716","rc":[{"batb":[[0,2.4,4]],"ltp":2.4,"tv":280.2,"id":31372}]}]}
{"op":"mcm","clk":"11836889983","pt":1723153070431,"mc":[{"id":"1.231539716","rc":[{"trd":[[1.71,65.41]],"batb":[[0,1.7,30.32],[1,1.67,4.55],[2,1.66,53.07]],"ltp":1.71,"tv":805.24,"id":5995},{"trd":[[2.42,8.2]],"batb":[[0,2.42,1.8]],"ltp":2.42,"tv":288.4,"id":31372}],"tv":1093.65}]}
{"op":"mcm","clk":"11836890057","pt":1723153072534,"mc":[{"id":"1.231539716","rc":[{"batl":[[0,1.74,8.3],[1,1.75,100],[2,1.76,200]],"ltp":1.71,"tv":805.24,"id":5995}]}]}
{"op":"mcm","clk":"11836890079","pt":1723153073860,"mc":[{"id":"1.231539716","rc":[{"batb":[[0,2.36,4]],"ltp":2.42,"tv":288.4,"id":31372}]}]}
{"op":"mcm","clk":"11836890143","pt":1723153076374,"mc":[{"id":"1.231539716","rc":[{"batb":[[0,2.36,10]],"ltp":2.42,"tv":288.4,"id":31372}]}]}
{"op":"mcm","clk":"11836890265","pt":1723153079664,"mc":[{"id":"1.231539716","rc":[{"batb":[[0,2.38,4]],"ltp":2.42,"tv":288.4,"id":31372}]}]}
{"op":"mcm","clk":"11836890374","pt":1723153082070,"mc":[{"id":"1.231539716","rc":[{"batb":[[0,2.36,10]],"ltp":2.42,"tv":288.4,"id":31372}]}]}
{"op":"mcm","clk":"11836890478","pt":1723153085464,"mc":[{"id":"1.231539716","rc":[{"batb":[[0,2.36,4]],"ltp":2.42,"tv":288.4,"id":31372}]}]}
{"op":"mcm","clk":"11836890578","pt":1723153087961,"mc":[{"id":"1.231539716","rc":[{"batb":[[0,2.36,10]],"ltp":2.42,"tv":288.4,"id":31372}]}]}
{"op":"mcm","clk":"11836890707","pt":1723153091243,"mc":[{"id":"1.231539716","rc":[{"batb":[[0,2.36,4]],"ltp":2.42,"tv":288.4,"id":31372}]}]}
{"op":"mcm","clk":"11836890778","pt":1723153093751,"mc":[{"id":"1.231539716","rc":[{"batb":[[0,2.36,10]],"ltp":2.42,"tv":288.4,"id":31372}]}]}
{"op":"mcm","clk":"11836890874","pt":1723153097283,"mc":[{"id":"1.231539716","rc":[{"batb":[[0,2.36,4]],"ltp":2.42,"tv":288.4,"id":31372}]}]}
{"op":"mcm","clk":"11836890963","pt":1723153099590,"mc":[{"id":"1.231539716","rc":[{"batb":[[0,2.34,5.94],[1,2.18,42.05],[2,2.02,4.55]],"ltp":2.42,"tv":288.4,"id":31372}]}]}
{"op":"mcm","clk":"11836890967","pt":1723153099691,"mc":[{"id":"1.231539716","rc":[{"batb":[[0,2.36,10],[1,2.34,5.94],[2,2.18,42.05]],"ltp":2.42,"tv":288.4,"id":31372}]}]}
{"op":"mcm","clk":"11836891109","pt":1723153103074,"mc":[{"id":"1.231539716","rc":[{"batb":[[0,2.36,4]],"ltp":2.42,"tv":288.4,"id":31372}]}]}
{"op":"mcm","clk":"11836891185","pt":1723153105486,"mc":[{"id":"1.231539716","rc":[{"batb":[[0,2.34,5.94],[1,2.18,42.05],[2,2.02,4.55]],"ltp":2.42,"tv":288.4,"id":31372}]}]}
{"op":"mcm","clk":"11836891195","pt":1723153105692,"mc":[{"id":"1.231539716","rc":[{"batb":[[0,2.38,10],[1,2.34,5.94],[2,2.18,42.05]],"ltp":2.42,"tv":288.4,"id":31372}]}]}
{"op":"mcm","clk":"11836891264","pt":1723153107379,"mc":[{"id":"1.231539716","rc":[{"batl":[[0,1.75,100],[1,1.76,200],[2,1.77,300]],"ltp":1.71,"tv":805.24,"id":5995}]}]}
{"op":"mcm","clk":"11836891353","pt":1723153109481,"mc":[{"id":"1.231539716","rc":[{"batb":[[2,1.61,4.55]],"ltp":1.71,"tv":805.24,"id":5995},{"batb":[[0,2.4,4],[1,2.18,9.92],[2,2.02,4.55]],"ltp":2.42,"tv":288.4,"id":31372}]}]}
{"op":"mcm","clk":"11836891411","pt":1723153111374,"mc":[{"id":"1.231539716","rc":[{"batl":[[0,1.74,7.93],[1,1.75,100],[2,1.76,200]],"ltp":1.71,"tv":805.24,"id":5995},{"batb":[[0,2.42,10],[1,2.34,5.96],[2,2.18,9.92]],"ltp":2.42,"tv":288.4,"id":31372}]}]}
{"op":"mcm","clk":"11836891498","pt":1723153113475,"mc":[{"id":"1.231539716","rc":[{"batl":[[0,1.75,100],[1,1.76,200],[2,1.77,300]],"ltp":1.71,"tv":805.24,"id":5995},{"batb":[[1,2.18,9.92],[2,2.02,4.55]],"ltp":2.42,"tv":288.4,"id":31372}]}]}
{"op":"mcm","clk":"11836891538","pt":1723153114603,"mc":[{"id":"1.231539716","rc":[{"batb":[[0,2.18,9.92],[1,2.02,4.55],[2,1.8,2]],"ltp":2.42,"tv":288.4,"id":31372}]}]}
{"op":"mcm","clk":"11836891546","pt":1723153114709,"mc":[{"id":"1.231539716","rc":[{"batb":[[0,2.2,4],[1,2.18,9.92],[2,2.02,4.55]],"ltp":2.42,"tv":288.4,"id":31372}]}]}
{"op":"mcm","clk":"11836891630","pt":1723153117066,"mc":[{"id":"1.231539716","rc":[{"batb":[[0,2.2,10]],"ltp":2.42,"tv":288.4,"id":31372}]}]}
{"op":"mcm","clk":"11836891692","pt":1723153118860,"mc":[{"id":"1.231539716","rc":[{"batb":[[2,1.66,53.07]],"ltp":1.71,"tv":805.24,"id":5995},{"batb":[[1,2.18,42.05]],"ltp":2.42,"tv":288.4,"id":31372}]}]}
{"op":"mcm","clk":"11836891734","pt":1723153120399,"mc":[{"id":"1.231539716","rc":[{"batb":[[0,2.22,4]],"ltp":2.42,"tv":288.4,"id":31372}]}]}
{"op":"mcm","clk":"11836891831","pt":1723153122708,"mc":[{"id":"1.231539716","rc":[{"batb":[[0,2.24,10]],"ltp":2.42,"tv":288.4,"id":31372}]}]}
{"op":"mcm","clk":"11836891912","pt":1723153125114,"mc":[{"id":"1.231539716","rc":[{"batb":[[0,2.26,4],[1,2.24,10],[2,2.18,42.05]],"ltp":2.42,"tv":288.4,"id":31372}]}]}
{"op":"mcm","clk":"11836891936","pt":1723153125888,"mc":[{"id":"1.231539716","rc":[{"batb":[[1,2.18,42.05],[2,2.02,4.55]],"ltp":2.42,"tv":288.4,"id":31372}]}]}
{"op":"mcm","clk":"11836891991","pt":1723153127380,"mc":[{"id":"1.231539716","rc":[{"batb":[[0,2.18,42.05],[1,2.02,4.55],[2,1.8,2]],"ltp":2.42,"tv":288.4,"id":31372}]}]}
{"op":"mcm","clk":"11836892056","pt":1723153129686,"mc":[{"id":"1.231539716","rc":[{"batb":[[0,2.2,14],[1,2.18,42.05],[2,2.02,4.55]],"ltp":2.42,"tv":288.4,"id":31372}]}]}
{"op":"mcm","clk":"11836892129","pt":1723153131891,"mc":[{"id":"1.231539716","rc":[{"batb":[[0,2.2,10]],"ltp":2.42,"tv":288.4,"id":31372}]}]}
{"op":"mcm","clk":"11836892164","pt":1723153133019,"mc":[{"id":"1.231539716","rc":[{"batb":[[0,2.18,42.05],[1,2.02,4.55],[2,1.8,2]],"ltp":2.42,"tv":288.4,"id":31372}]}]}
{"op":"mcm","clk":"11836892189","pt":1723153134100,"mc":[{"id":"1.231539716","rc":[{"batb":[[0,2.2,4],[1,2.18,42.05],[2,2.02,4.55]],"ltp":2.42,"tv":288.4,"id":31372}]}]}
{"op":"mcm","clk":"11836892248","pt":1723153136399,"mc":[{"id":"1.231539716","rc":[{"batb":[[0,2.2,10]],"ltp":2.42,"tv":288.4,"id":31372}]}]}
{"op":"mcm","clk":"11836892322","pt":1723153139114,"mc":[{"id":"1.231539716","rc":[{"batb":[[0,2.22,4],[1,2.2,10],[2,2.18,42.05]],"ltp":2.42,"tv":288.4,"id":31372}]}]}
{"op":"mcm","clk":"11836892352","pt":1723153139784,"mc":[{"id":"1.231539716","rc":[{"batb":[[1,2.18,42.05],[2,2.02,4.55]],"ltp":2.42,"tv":288.4,"id":31372}]}]}
{"op":"mcm","clk":"11836892405","pt":1723153141420,"mc":[{"id":"1.231539716","rc":[{"batb":[[0,2.18,42.05],[1,2.02,4.55],[2,1.8,2]],"ltp":2.42,"tv":288.4,"id":31372}]}]}
{"op":"mcm","clk":"11836892447","pt":1723153142501,"mc":[{"id":"1.231539716","rc":[{"batb":[[0,2.2,10],[1,2.18,42.05],[2,2.02,4.55]],"ltp":2.42,"tv":288.4,"id":31372}]}]}
{"op":"mcm","clk":"11836892488","pt":1723153143727,"mc":[{"id":"1.231539716","rc":[{"batb":[[0,2.22,4],[1,2.2,10],[2,2.18,42.05]],"ltp":2.42,"tv":288.4,"id":31372}]}]}
{"op":"mcm","clk":"11836892559","pt":1723153146108,"mc":[{"id":"1.231539716","rc":[{"batb":[[0,2.18,42.05],[1,2.02,4.55],[2,1.8,2]],"ltp":2.42,"tv":288.4,"id":31372}]}]}
{"op":"mcm","clk":"11836892654","pt":1723153148418,"mc":[{"id":"1.231539716","rc":[{"batb":[[0,2.2,14],[1,2.18,42.05],[2,2.02,4.55]],"ltp":2.42,"tv":288.4,"id":31372}]}]}
{"op":"mcm","clk":"11836892703","pt":1723153149807,"mc":[{"id":"1.231539716","rc":[{"batl":[[0,1.74,7.51],[1,1.75,100],[2,1.76,200]],"ltp":1.71,"tv":805.24,"id":5995},{"batb":[[0,2.34,5.66],[1,2.2,14],[2,2.18,42.05]],"ltp":2.42,"tv":288.4,"id":31372}]}]}
{"op":"mcm","clk":"11836892768","pt":1723153151906,"mc":[{"id":"1.231539716","rc":[{"batb":[[1,2.2,10]],"ltp":2.42,"tv":288.4,"id":31372}]}]}
{"op":"mcm","clk":"11836892804","pt":1723153152726,"mc":[{"id":"1.231539716","rc":[{"batb":[[1,2.18,42.05],[2,2.02,4.55]],"ltp":2.42,"tv":288.4,"id":31372}]}]}
{"op":"mcm","clk":"11836892840","pt":1723153154109,"mc":[{"id":"1.231539716","rc":[{"batb":[[0,2.36,4],[1,2.34,5.66],[2,2.18,42.05]],"ltp":2.42,"tv":288.4,"id":31372}]}]}
{"op":"mcm","clk":"11836892892","pt":1723153155513,"mc":[{"id":"1.231539716","rc":[{"batb":[[0,2.38,10],[1,2.36,4],[2,2.34,5.66]],"ltp":2.42,"tv":288.4,"id":31372}]}]}
{"op":"mcm","clk":"11836892915","pt":1723153156426,"mc":[{"id":"1.231539716","rc":[{"batb":[[1,2.34,5.66],[2,2.18,42.05]],"ltp":2.42,"tv":288.4,"id":31372}]}]}
{"op":"mcm","clk":"11836892973","pt":1723153158421,"mc":[{"id":"1.231539716","rc":[{"batl":[[0,1.75,100],[1,1.76,200],[2,1.77,300]],"ltp":1.71,"tv":805.24,"id":5995}]}]}
{"op":"mcm","clk":"11836893011","pt":1723153159138,"mc":[{"id":"1.231539716","rc":[{"batb":[[0,2.36,4]],"ltp":2.42,"tv":288.4,"id":31372}]}]}
{"op":"mcm","clk":"11836893092","pt":1723153161551,"mc":[{"id":"1.231539716","rc":[{"batb":[[0,2.36,10]],"ltp":2.42,"tv":288.4,"id":31372}]}]}
{"op":"mcm","clk":"11836893118","pt":1723153162319,"mc":[{"id":"1.231539716","rc":[{"batb":[[1,2.18,42.05],[2,2.02,4.55]],"ltp":2.42,"tv":288.4,"id":31372}]}]}
{"op":"mcm","clk":"11836893203","pt":1723153165037,"mc":[{"id":"1.231539716","rc":[{"batb":[[0,2.2,4]],"ltp":2.42,"tv":288.4,"id":31372}]}]}
{"op":"mcm","clk":"11836893277","pt":1723153167450,"mc":[{"id":"1.231539716","rc":[{"batb":[[0,2.2,10]],"ltp":2.42,"tv":288.4,"id":31372}]}]}
{"op":"mcm","clk":"11836893378","pt":1723153170217,"mc":[{"id":"1.231539716","rc":[{"batb":[[0,2.22,4],[1,2.2,10],[2,2.18,42.05]],"ltp":2.42,"tv":288.4,"id":31372}]}]}
{"op":"mcm","clk":"11836893392","pt":1723153170728,"mc":[{"id":"1.231539716","rc":[{"batb":[[1,2.18,42.05],[2,2.02,4.55]],"ltp":2.42,"tv":288.4,"id":31372}]}]}
{"op":"mcm","clk":"11836893452","pt":1723153172627,"mc":[{"id":"1.231539716","rc":[{"batb":[[0,2.18,42.05],[1,2.02,4.55],[2,1.8,2]],"ltp":2.42,"tv":288.4,"id":31372}]}]}
{"op":"mcm","clk":"11836893491","pt":1723153173756,"mc":[{"id":"1.231539716","rc":[{"batb":[[0,2.2,10],[1,2.18,42.05],[2,2.02,4.55]],"ltp":2.42,"tv":288.4,"id":31372}]}]}
{"op":"mcm","clk":"11836893537","pt":1723153175236,"mc":[{"id":"1.231539716","rc":[{"batb":[[0,2.22,4],[1,2.2,10],[2,2.18,42.05]],"ltp":2.42,"tv":288.4,"id":31372}]}]}
{"op":"mcm","clk":"11836893620","pt":1723153177542,"mc":[{"id":"1.231539716","rc":[{"batb":[[0,2.18,42.05],[1,2.02,4.55],[2,1.8,2]],"ltp":2.42,"tv":288.4,"id":31372}]}]}
{"op":"mcm","clk":"11836893711","pt":1723153179744,"mc":[{"id":"1.231539716","rc":[{"batb":[[0,2.2,14],[1,2.18,42.05],[2,2.02,4.55]],"ltp":2.42,"tv":288.4,"id":31372}]}]}
{"op":"mcm","clk":"11836893794","pt":1723153182152,"mc":[{"id":"1.231539716","rc":[{"batb":[[0,2.2,10]],"ltp":2.42,"tv":288.4,"id":31372}]}]}
{"op":"mcm","clk":"11836893830","pt":1723153183227,"mc":[{"id":"1.231539716","rc":[{"batb":[[0,2.18,42.05],[1,2.02,4.55],[2,1.8,2]],"ltp":2.42,"tv":288.4,"id":31372}]}]}
{"op":"mcm","clk":"11836893949","pt":1723153186963,"mc":[{"id":"1.231539716","rc":[{"batl":[[0,1.74,12.79],[1,1.75,100],[2,1.76,200]],"ltp":1.71,"tv":805.24,"id":5995},{"batb":[[0,2.34,5.94],[1,2.2,14],[2,2.18,42.05]],"ltp":2.42,"tv":288.4,"id":31372}]}]}
{"op":"mcm","clk":"11836894010","pt":1723153189064,"mc":[{"id":"1.231539716","rc":[{"batb":[[1,2.2,10]],"ltp":2.42,"tv":288.4,"id":31372}]}]}
{"op":"mcm","clk":"11836894049","pt":1723153190048,"mc":[{"id":"1.231539716","rc":[{"batb":[[1,2.18,42.05],[2,2.02,4.55]],"ltp":2.42,"tv":288.4,"id":31372}]}]}
{"op":"mcm","clk":"11836894106","pt":1723153191276,"mc":[{"id":"1.231539716","rc":[{"batb":[[0,2.36,4],[1,2.34,5.94],[2,2.18,42.05]],"ltp":2.42,"tv":288.4,"id":31372}]}]}
{"op":"mcm","clk":"11836894193","pt":1723153193535,"mc":[{"id":"1.231539716","rc":[{"batb":[[0,2.38,10]],"ltp":2.42,"tv":288.4,"id":31372}]}]}
{"op":"mcm","clk":"11836894219","pt":1723153194458,"mc":[{"id":"1.231539716","rc":[{"batb":[[2,1.61,4.55]],"ltp":1.71,"tv":805.24,"id":5995},{"batb":[[2,2.18,9.92]],"ltp":2.42,"tv":288.4,"id":31372}]}]}
{"op":"mcm","clk":"11836894289","pt":1723153196969,"mc":[{"id":"1.231539716","rc":[{"batb":[[0,2.36,4]],"ltp":2.42,"tv":288.4,"id":31372}]}]}
{"op":"mcm","clk":"11836894371","pt":1723153199481,"mc":[{"id":"1.231539716","rc":[{"batb":[[2,1.66,53.07]],"ltp":1.71,"tv":805.24,"id":5995},{"batb":[[0,2.36,10],[2,2.18,42.05]],"ltp":2.42,"tv":288.4,"id":31372}]}]}
{"op":"mcm","clk":"11836894450","pt":1723153201947,"mc":[{"id":"1.231539716","rc":[{"batb":[[0,2.38,4],[1,2.36,10],[2,2.34,5.94]],"ltp":2.42,"tv":288.4,"id":31372}]}]}
{"op":"mcm","clk":"11836894487","pt":1723153202765,"mc":[{"id":"1.231539716","rc":[{"batb":[[1,2.34,5.94],[2,2.18,42.05]],"ltp":2.42,"tv":288.4,"id":31372}]}]}
{"op":"mcm","clk":"11836894539","pt":1723153204358,"mc":[{"id":"1.231539716","rc":[{"batb":[[0,2.34,5.94],[1,2.18,42.05],[2,2.02,4.55]],"ltp":2.42,"tv":288.4,"id":31372}]}]}
{"op":"mcm","clk":"11836894588","pt":1723153205586,"mc":[{"id":"1.231539716","rc":[{"batb":[[0,2.36,10],[1,2.34,5.94],[2,2.18,42.05]],"ltp":2.42,"tv":288.4,"id":31372}]}]}
{"op":"mcm","clk":"11836894661","pt":1723153207587,"mc":[{"id":"1.231539716","rc":[{"batb":[[0,2.38,4],[1,2.36,10],[2,2.34,5.94]],"ltp":2.42,"tv":288.4,"id":31372}]}]}
{"op":"mcm","clk":"11836894702","pt":1723153208869,"mc":[{"id":"1.231539716","rc":[{"batb":[[1,2.34,5.94],[2,2.18,42.05]],"ltp":2.42,"tv":288.4,"id":31372}]}]}
{"op":"mcm","clk":"11836894730","pt":1723153209892,"mc":[{"id":"1.231539716","rc":[{"batb":[[0,2.34,5.94],[1,2.18,42.05],[2,2.02,4.55]],"ltp":2.42,"tv":288.4,"id":31372}]}]}
{"op":"mcm","clk":"11836894894","pt":1723153213895,"mc":[{"id":"1.231539716","rc":[{"batb":[[0,2.36,14],[1,2.34,5.94],[2,2.18,42.05]],"ltp":2.42,"tv":288.4,"id":31372}]}]}
{"op":"mcm","clk":"11836894970","pt":1723153216053,"mc":[{"id":"1.231539716","rc":[{"batb":[[0,2.36,10]],"ltp":2.42,"tv":288.4,"id":31372}]}]}
{"op":"mcm","clk":"11836895015","pt":1723153217282,"mc":[{"id":"1.231539716","rc":[{"batb":[[0,2.34,5.94],[1,2.18,42.05],[2,2.02,4.55]],"ltp":2.42,"tv":288.4,"id":31372}]}]}
{"op":"mcm","clk":"11836895053","pt":1723153218363,"mc":[{"id":"1.231539716","rc":[{"batb":[[0,2.36,4],[1,2.34,5.94],[2,2.18,42.05]],"ltp":2.42,"tv":288.4,"id":31372}]}]}
{"op":"mcm","clk":"11836895085","pt":1723153219695,"mc":[{"id":"1.231539716","rc":[{"batb":[[0,2.38,10],[1,2.36,4],[2,2.34,5.94]],"ltp":2.42,"tv":288.4,"id":31372}]}]}
{"op":"mcm","clk":"11836895130","pt":1723153220872,"mc":[{"id":"1.231539716","rc":[{"batb":[[1,2.34,5.94],[2,2.18,42.05]],"ltp":2.42,"tv":288.4,"id":31372}]}]}
{"op":"mcm","clk":"11836895213","pt":1723153223280,"mc":[{"id":"1.231539716","rc":[{"batb":[[0,2.4,4]],"ltp":2.42,"tv":288.4,"id":31372}]}]}
{"op":"mcm","clk":"11836895292","pt":1723153225580,"mc":[{"id":"1.231539716","rc":[{"batb":[[0,2.34,5.94],[1,2.18,42.05],[2,2.02,4.55]],"ltp":2.42,"tv":288.4,"id":31372}]}]}
{"op":"mcm","clk":"11836895299","pt":1723153225691,"mc":[{"id":"1.231539716","rc":[{"batb":[[0,2.36,10],[1,2.34,5.94],[2,2.18,42.05]],"ltp":2.42,"tv":288.4,"id":31372}]}]}
{"op":"mcm","clk":"11836895368","pt":1723153228093,"mc":[{"id":"1.231539716","rc":[{"batb":[[0,2.38,4],[1,2.36,10],[2,2.34,5.94]],"ltp":2.42,"tv":288.4,"id":31372}]}]}
{"op":"mcm","clk":"11836895392","pt":1723153229015,"mc":[{"id":"1.231539716","rc":[{"batb":[[1,2.34,5.94],[2,2.18,42.05]],"ltp":2.42,"tv":288.4,"id":31372}]}]}
{"op":"mcm","clk":"11836895439","pt":1723153230400,"mc":[{"id":"1.231539716","rc":[{"batb":[[0,2.34,5.94],[1,2.18,42.05],[2,2.02,4.55]],"ltp":2.42,"tv":288.4,"id":31372}]}]}
{"op":"mcm","clk":"11836895494","pt":1723153231576,"mc":[{"id":"1.231539716","rc":[{"batb":[[0,2.36,10],[1,2.34,5.94],[2,2.18,42.05]],"ltp":2.42,"tv":288.4,"id":31372}]}]}
{"op":"mcm","clk":"11836895551","pt":1723153232807,"mc":[{"id":"1.231539716","rc":[{"batb":[[0,2.38,4],[1,2.36,10],[2,2.34,5.94]],"ltp":2.42,"tv":288.4,"id":31372}]}]}
{"op":"mcm","clk":"11836895621","pt":1723153235110,"mc":[{"id":"1.231539716","rc":[{"batb":[[0,2.34,5.94],[1,2.18,42.05],[2,2.02,4.55]],"ltp":2.42,"tv":288.4,"id":31372}]}]}
{"op":"mcm","clk":"11836895689","pt":1723153237317,"mc":[{"id":"1.231539716","rc":[{"batb":[[0,2.36,14],[1,2.34,5.94],[2,2.18,42.05]],"ltp":2.42,"tv":288.4,"id":31372}]}]}
{"op":"mcm","clk":"11836895769","pt":1723153239619,"mc":[{"id":"1.231539716","rc":[{"batb":[[0,2.36,10]],"ltp":2.42,"tv":288.4,"id":31372}]}]}
{"op":"mcm","clk":"11836895812","pt":1723153240499,"mc":[{"id":"1.231539716","rc":[{"batb":[[0,2.34,5.94],[1,2.18,42.05],[2,2.02,4.55]],"ltp":2.42,"tv":288.4,"id":31372}]}]}
{"op":"mcm","clk":"11836895886","pt":1723153243002,"mc":[{"id":"1.231539716","rc":[{"batb":[[0,2.36,14],[1,2.34,5.94],[2,2.18,42.05]],"ltp":2.42,"tv":288.4,"id":31372}]}]}
{"op":"mcm","clk":"11836895982","pt":1723153245309,"mc":[{"id":"1.231539716","rc":[{"batb":[[0,2.36,10]],"ltp":2.42,"tv":288.4,"id":31372}]}]}
{"op":"mcm","clk":"11836896024","pt":1723153246286,"mc":[{"id":"1.231539716","rc":[{"batb":[[0,2.34,5.94],[1,2.18,42.05],[2,2.02,4.55]],"ltp":2.42,"tv":288.4,"id":31372}]}]}
{"op":"mcm","clk":"11836896068","pt":1723153247512,"mc":[{"id":"1.231539716","rc":[{"batb":[[0,2.36,4],[1,2.34,5.94],[2,2.18,42.05]],"ltp":2.42,"tv":288.4,"id":31372}]}]}
{"op":"mcm","clk":"11836896111","pt":1723153248792,"mc":[{"id":"1.231539716","rc":[{"batb":[[0,2.38,10],[1,2.36,4],[2,2.34,5.94]],"ltp":2.42,"tv":288.4,"id":31372}]}]}
{"op":"mcm","clk":"11836896150","pt":1723153249816,"mc":[{"id":"1.231539716","rc":[{"batb":[[2,1.61,4.55]],"ltp":1.71,"tv":805.24,"id":5995},{"batb":[[1,2.34,5.94],[2,2.18,9.92]],"ltp":2.42,"tv":288.4,"id":31372}]}]}
{"op":"mcm","clk":"11836896236","pt":1723153252117,"mc":[{"id":"1.231539716","rc":[{"batb":[[0,2.36,4]],"ltp":2.42,"tv":288.4,"id":31372}]}]}
{"op":"mcm","clk":"11836896328","pt":1723153254523,"mc":[{"id":"1.231539716","rc":[{"batb":[[0,2.36,10]],"ltp":2.42,"tv":288.4,"id":31372}]}]}
{"op":"mcm","clk":"11836896334","pt":1723153254727,"mc":[{"id":"1.231539716","rc":[{"batb":[[2,1.66,53.07]],"ltp":1.71,"tv":805.24,"id":5995},{"batb":[[2,2.18,42.05]],"ltp":2.42,"tv":288.4,"id":31372}]}]}
{"op":"mcm","clk":"11836896422","pt":1723153256925,"mc":[{"id":"1.231539716","rc":[{"batb":[[0,2.38,4],[1,2.36,10],[2,2.34,5.94]],"ltp":2.42,"tv":288.4,"id":31372}]}]}
{"op":"mcm","clk":"11836896444","pt":1723153257798,"mc":[{"id":"1.231539716","rc":[{"batb":[[1,2.34,5.94],[2,2.18,42.05]],"ltp":2.42,"tv":288.4,"id":31372}]}]}
{"op":"mcm","clk":"11836896495","pt":1723153259231,"mc":[{"id":"1.231539716","rc":[{"batb":[[0,2.34,5.94],[1,2.18,42.05],[2,2.02,4.55]],"ltp":2.42,"tv":288.4,"id":31372}]}]}
{"op":"mcm","clk":"11836896567","pt":1723153261533,"mc":[{"id":"1.231539716","rc":[{"batb":[[0,2.36,14],[1,2.34,5.94],[2,2.18,42.05]],"ltp":2.42,"tv":288.4,"id":31372}]}]}
{"op":"mcm","clk":"11836896632","pt":1723153263941,"mc":[{"id":"1.231539716","rc":[{"batb":[[0,2.36,10]],"ltp":2.42,"tv":288.4,"id":31372}]}]}
{"op":"mcm","clk":"11836896662","pt":1723153264714,"mc":[{"id":"1.231539716","rc":[{"batb":[[0,2.34,5.94],[1,2.18,42.05],[2,2.02,4.55]],"ltp":2.42,"tv":288.4,"id":31372}]}]}
{"op":"mcm","clk":"11836896705","pt":1723153266145,"mc":[{"id":"1.231539716","rc":[{"batb":[[0,2.36,4],[1,2.34,5.94],[2,2.18,42.05]],"ltp":2.42,"tv":288.4,"id":31372}]}]}
{"op":"mcm","clk":"11836896746","pt":1723153267430,"mc":[{"id":"1.231539716","rc":[{"batb":[[0,2.38,10],[1,2.36,4],[2,2.34,5.94]],"ltp":2.42,"tv":288.4,"id":31372}]}]}
{"op":"mcm","clk":"11836896768","pt":1723153268355,"mc":[{"id":"1.231539716","rc":[{"batb":[[1,2.34,5.94],[2,2.18,42.05]],"ltp":2.42,"tv":288.4,"id":31372}]}]}
{"op":"mcm","clk":"11836896828","pt":1723153269941,"mc":[{"id":"1.231539716","rc":[{"batb":[[2,1.61,4.55]],"ltp":1.71,"tv":805.24,"id":5995},{"batb":[[2,2.18,9.92]],"ltp":2.42,"tv":288.4,"id":31372}]}]}
{"op":"mcm","clk":"11836896855","pt":1723153270809,"mc":[{"id":"1.231539716","rc":[{"batb":[[0,2.36,4]],"ltp":2.42,"tv":288.4,"id":31372}]}]}
{"op":"mcm","clk":"11836896926","pt":1723153273219,"mc":[{"id":"1.231539716","rc":[{"batb":[[0,2.36,10]],"ltp":2.42,"tv":288.4,"id":31372}]}]}
{"op":"mcm","clk":"11836896977","pt":1723153274911,"mc":[{"id":"1.231539716","rc":[{"batb":[[2,1.66,53.07]],"ltp":1.71,"tv":805.24,"id":5995},{"batb":[[2,2.18,42.05]],"ltp":2.42,"tv":288.4,"id":31372}]}]}
{"op":"mcm","clk":"11836897021","pt":1723153276546,"mc":[{"id":"1.231539716","rc":[{"batb":[[0,2.34,5.94],[1,2.18,42.05],[2,2.02,4.55]],"ltp":2.42,"tv":288.4,"id":31372}]}]}
{"op":"mcm","clk":"11836897026","pt":1723153276650,"mc":[{"id":"1.231539716","rc":[{"batb":[[0,2.36,4],[1,2.34,5.94],[2,2.18,42.05]],"ltp":2.42,"tv":288.4,"id":31372}]}]}
{"op":"mcm","clk":"11836897108","pt":1723153278957,"mc":[{"id":"1.231539716","rc":[{"batb":[[0,2.36,10]],"ltp":2.42,"tv":288.4,"id":31372}]}]}
{"op":"mcm","clk":"11836897235","pt":1723153282446,"mc":[{"id":"1.231539716","rc":[{"batb":[[0,2.36,4]],"ltp":2.42,"tv":288.4,"id":31372}]}]}
{"op":"mcm","clk":"11836897323","pt":1723153284956,"mc":[{"id":"1.231539716","rc":[{"batb":[[0,2.36,10]],"ltp":2.42,"tv":288.4,"id":31372}]}]}
{"op":"mcm","clk":"11836897400","pt":1723153287060,"mc":[{"id":"1.231539716","rc":[{"batb":[[0,2.38,4],[1,2.36,10],[2,2.34,5.94]],"ltp":2.42,"tv":288.4,"id":31372}]}]}
{"op":"mcm","clk":"11836897459","pt":1723153288239,"mc":[{"id":"1.231539716","rc":[{"batb":[[1,2.34,5.94],[2,2.18,42.05]],"ltp":2.42,"tv":288.4,"id":31372}]}]}
{"op":"mcm","clk":"11836897494","pt":1723153289362,"mc":[{"id":"1.231539716","rc":[{"batb":[[0,2.34,5.94],[1,2.18,42.05],[2,2.02,4.55]],"ltp":2.42,"tv":288.4,"id":31372}]}]}
{"op":"mcm","clk":"11836897578","pt":1723153291721,"mc":[{"id":"1.231539716","rc":[{"batb":[[0,2.36,14],[1,2.34,5.94],[2,2.18,42.05]],"ltp":2.42,"tv":288.4,"id":31372}]}]}
{"op":"mcm","clk":"11836897665","pt":1723153294135,"mc":[{"id":"1.231539716","rc":[{"batb":[[0,2.36,10]],"ltp":2.42,"tv":288.4,"id":31372}]}]}
{"op":"mcm","clk":"11836897702","pt":1723153295158,"mc":[{"id":"1.231539716","rc":[{"batb":[[0,2.34,5.94],[1,2.18,42.05],[2,2.02,4.55]],"ltp":2.42,"tv":288.4,"id":31372}]}]}
{"op":"mcm","clk":"11836897791","pt":1723153297565,"mc":[{"id":"1.231539716","rc":[{"batb":[[0,2.36,14],[1,2.34,5.94],[2,2.18,42.05]],"ltp":2.42,"tv":288.4,"id":31372}]}]}
{"op":"mcm","clk":"11836897858","pt":1723153299924,"mc":[{"id":"1.231539716","rc":[{"batb":[[0,2.36,10]],"ltp":2.42,"tv":288.4,"id":31372}]}]}
{"op":"mcm","clk":"11836897898","pt":1723153300948,"mc":[{"id":"1.231539716","rc":[{"batb":[[0,2.34,5.94],[1,2.18,42.05],[2,2.02,4.55]],"ltp":2.42,"tv":288.4,"id":31372}]}]}
{"op":"mcm","clk":"11836897976","pt":1723153303252,"mc":[{"id":"1.231539716","rc":[{"batb":[[0,2.36,14],[1,2.34,5.94],[2,2.18,42.05]],"ltp":2.42,"tv":288.4,"id":31372}]}]}
{"op":"mcm","clk":"11836898079","pt":1723153306525,"mc":[{"id":"1.231539716","rc":[{"batb":[[0,2.34,5.94],[1,2.18,42.05],[2,2.02,4.55]],"ltp":2.42,"tv":288.4,"id":31372}]}]}
{"op":"mcm","clk":"11836898174","pt":1723153309036,"mc":[{"id":"1.231539716","rc":[{"batb":[[0,2.36,14],[1,2.34,5.94],[2,2.18,42.05]],"ltp":2.42,"tv":288.4,"id":31372}]}]}
{"op":"mcm","clk":"11836898259","pt":1723153311443,"mc":[{"id":"1.231539716","rc":[{"batb":[[0,2.36,10]],"ltp":2.42,"tv":288.4,"id":31372}]}]}
{"op":"mcm","clk":"11836898302","pt":1723153312466,"mc":[{"id":"1.231539716","rc":[{"batb":[[0,2.34,5.94],[1,2.18,42.05],[2,2.02,4.55]],"ltp":2.42,"tv":288.4,"id":31372}]}]}
{"op":"mcm","clk":"11836898342","pt":1723153313643,"mc":[{"id":"1.231539716","rc":[{"batb":[[0,2.36,4],[1,2.34,5.94],[2,2.18,42.05]],"ltp":2.42,"tv":288.4,"id":31372}]}]}
{"op":"mcm","clk":"11836898404","pt":1723153315227,"mc":[{"id":"1.231539716","rc":[{"batb":[[2,1.61,4.55]],"ltp":1.71,"tv":805.24,"id":5995},{"batb":[[0,2.38,10],[1,2.36,4],[2,2.34,5.94]],"ltp":2.42,"tv":288.4,"id":31372}]}]}
{"op":"mcm","clk":"11836898430","pt":1723153316047,"mc":[{"id":"1.231539716","rc":[{"batb":[[1,2.34,5.94],[2,2.18,9.92]],"ltp":2.42,"tv":288.4,"id":31372}]}]}
{"op":"mcm","clk":"11836898502","pt":1723153318354,"mc":[{"id":"1.231539716","rc":[{"batb":[[0,2.36,4]],"ltp":2.42,"tv":288.4,"id":31372}]}]}
{"op":"mcm","clk":"11836898573","pt":1723153320348,"mc":[{"id":"1.231539716","rc":[{"batb":[[2,1.66,53.07]],"ltp":1.71,"tv":805.24,"id":5995},{"batb":[[0,2.38,10],[1,2.36,4],[2,2.34,5.94]],"ltp":2.42,"tv":288.4,"id":31372}]}]}
{"op":"mcm","clk":"11836898594","pt":1723153320861,"mc":[{"id":"1.231539716","rc":[{"batb":[[1,2.34,5.94],[2,2.18,42.05]],"ltp":2.42,"tv":288.4,"id":31372}]}]}
{"op":"mcm","clk":"11836898682","pt":1723153323780,"mc":[{"id":"1.231539716","rc":[{"batb":[[0,2.4,4]],"ltp":2.42,"tv":288.4,"id":31372}]}]}
{"op":"mcm","clk":"11836898776","pt":1723153326135,"mc":[{"id":"1.231539716","rc":[{"batb":[[0,2.42,10]],"ltp":2.42,"tv":288.4,"id":31372}]}]}
{"op":"mcm","clk":"11836898816","pt":1723153327365,"mc":[{"id":"1.231539716","rc":[{"batb":[[1,2.18,42.05],[2,2.02,4.55]],"ltp":2.42,"tv":288.4,"id":31372}]}]}
{"op":"mcm","clk":"11836898896","pt":1723153329567,"mc":[{"id":"1.231539716","rc":[{"batb":[[0,2.2,4]],"ltp":2.42,"tv":288.4,"id":31372}]}]}
{"op":"mcm","clk":"11836898969","pt":1723153332279,"mc":[{"id":"1.231539716","rc":[{"batb":[[0,2.34,5.66],[1,2.2,10],[2,2.18,42.05]],"ltp":2.42,"tv":288.4,"id":31372}]}]}
{"op":"mcm","clk":"11836899047","pt":1723153335258,"mc":[{"id":"1.231539716","rc":[{"batb":[[0,2.36,4],[1,2.34,5.66]],"ltp":2.42,"tv":288.4,"id":31372}]}]}
{"op":"mcm","clk":"11836899126","pt":1723153337763,"mc":[{"id":"1.231539716","rc":[{"batb":[[0,2.36,10]],"ltp":2.42,"tv":288.4,"id":31372}]}]}
{"op":"mcm","clk":"11836899201","pt":1723153339863,"mc":[{"id":"1.231539716","rc":[{"batb":[[0,2.38,4],[1,2.36,10],[2,2.34,5.66]],"ltp":2.42,"tv":288.4,"id":31372}]}]}
{"op":"mcm","clk":"11836899228","pt":1723153341088,"mc":[{"id":"1.231539716","rc":[{"batb":[[1,2.34,5.66],[2,2.18,42.05]],"ltp":2.42,"tv":288.4,"id":31372}]}]}
{"op":"mcm","clk":"11836899272","pt":1723153342168,"mc":[{"id":"1.231539716","rc":[{"batb":[[0,2.34,5.66],[1,2.18,42.05],[2,2.02,4.55]],"ltp":2.42,"tv":288.4,"id":31372}]}]}
{"op":"mcm","clk":"11836899316","pt":1723153343349,"mc":[{"id":"1.231539716","rc":[{"batb":[[0,2.36,10],[1,2.34,5.66],[2,2.18,42.05]],"ltp":2.42,"tv":288.4,"id":31372}]}]}
{"op":"mcm","clk":"11836899354","pt":1723153344473,"mc":[{"id":"1.231539716","rc":[{"batb":[[0,2.38,4],[1,2.36,10],[2,2.34,5.66]],"ltp":2.42,"tv":288.4,"id":31372}]}]}
{"op":"mcm","clk":"11836899429","pt":1723153346878,"mc":[{"id":"1.231539716","rc":[{"batb":[[0,2.34,5.66],[1,2.18,42.05],[2,2.02,4.55]],"ltp":2.42,"tv":288.4,"id":31372}]}]}
{"op":"mcm","clk":"11836899546","pt":1723153350263,"mc":[{"id":"1.231539716","rc":[{"batb":[[0,2.36,14],[1,2.34,5.66],[2,2.18,42.05]],"ltp":2.42,"tv":288.4,"id":31372}]}]}
{"op":"mcm","clk":"11836899639","pt":1723153352675,"mc":[{"id":"1.231539716","rc":[{"batb":[[0,2.36,10]],"ltp":2.42,"tv":288.4,"id":31372}]}]}
{"op":"mcm","clk":"11836899674","pt":1723153353699,"mc":[{"id":"1.231539716","rc":[{"batb":[[0,2.34,5.66],[1,2.18,42.05],[2,2.02,4.55]],"ltp":2.42,"tv":288.4,"id":31372}]}]}
{"op":"mcm","clk":"11836899719","pt":1723153354878,"mc":[{"id":"1.231539716","rc":[{"batb":[[0,2.36,4],[1,2.34,5.66],[2,2.18,42.05]],"ltp":2.42,"tv":288.4,"id":31372}]}]}
{"op":"mcm","clk":"11836899769","pt":1723153356210,"mc":[{"id":"1.231539716","rc":[{"batb":[[0,2.38,10],[1,2.36,4],[2,2.34,5.66]],"ltp":2.42,"tv":288.4,"id":31372}]}]}
{"op":"mcm","clk":"11836899812","pt":1723153357389,"mc":[{"id":"1.231539716","rc":[{"batb":[[1,2.34,5.66],[2,2.18,42.05]],"ltp":2.42,"tv":288.4,"id":31372}]}]}
{"op":"mcm","clk":"11836899896","pt":1723153359597,"mc":[{"id":"1.231539716","rc":[{"batb":[[0,2.4,4]],"ltp":2.42,"tv":288.4,"id":31372}]}]}
{"op":"mcm","clk":"11836899977","pt":1723153361998,"mc":[{"id":"1.231539716","rc":[{"batb":[[0,2.36,10]],"ltp":2.42,"tv":288.4,"id":31372}]}]}
{"op":"mcm","clk":"11836900105","pt":1723153365382,"mc":[{"id":"1.231539716","rc":[{"batb":[[0,2.38,4]],"ltp":2.42,"tv":288.4,"id":31372}]}]}
{"op":"mcm","clk":"11836900185","pt":1723153367796,"mc":[{"id":"1.231539716","rc":[{"batb":[[0,2.36,10]],"ltp":2.42,"tv":288.4,"id":31372}]}]}
{"op":"mcm","clk":"11836900316","pt":1723153371096,"mc":[{"id":"1.231539716","rc":[{"batb":[[0,2.38,4]],"ltp":2.42,"tv":288.4,"id":31372}]}]}
{"op":"mcm","clk":"11836900409","pt":1723153373506,"mc":[{"id":"1.231539716","rc":[{"batb":[[0,2.36,10]],"ltp":2.42,"tv":288.4,"id":31372}]}]}
{"op":"mcm","clk":"11836912804","pt":1723153375986,"mc":[{"id":"1.231539716","rc":[{"batb":[[0,2.38,4],[1,2.36,10],[2,2.34,5.66]],"ltp":2.42,"tv":288.4,"id":31372}]}]}
{"op":"mcm","clk":"11836912824","pt":1723153376699,"mc":[{"id":"1.231539716","rc":[{"batb":[[1,2.34,5.66],[2,2.18,42.05]],"ltp":2.42,"tv":288.4,"id":31372}]}]}
{"op":"mcm","clk":"11836912892","pt":1723153378312,"mc":[{"id":"1.231539716","rc":[{"batb":[[0,2.34,5.66],[1,2.18,42.05],[2,2.02,4.55]],"ltp":2.42,"tv":288.4,"id":31372}]}]}
{"op":"mcm","clk":"11836912950","pt":1723153379513,"mc":[{"id":"1.231539716","rc":[{"batb":[[0,2.36,10],[1,2.34,5.66],[2,2.18,42.05]],"ltp":2.42,"tv":288.4,"id":31372}]}]}
{"op":"mcm","clk":"11836913012","pt":1723153380713,"mc":[{"id":"1.231539716","rc":[{"batb":[[0,2.38,4],[1,2.36,10],[2,2.34,5.66]],"ltp":2.42,"tv":288.4,"id":31372}]}]}
{"op":"mcm","clk":"11836913098","pt":1723153382916,"mc":[{"id":"1.231539716","rc":[{"batb":[[0,2.34,5.66],[1,2.18,42.05],[2,2.02,4.55]],"ltp":2.42,"tv":288.4,"id":31372}]}]}
{"op":"mcm","clk":"11836913188","pt":1723153385324,"mc":[{"id":"1.231539716","rc":[{"batb":[[0,2.36,14],[1,2.34,5.66],[2,2.18,42.05]],"ltp":2.42,"tv":288.4,"id":31372}]}]}
{"op":"mcm","clk":"11836913270","pt":1723153387729,"mc":[{"id":"1.231539716","rc":[{"batb":[[0,2.36,10]],"ltp":2.42,"tv":288.4,"id":31372}]}]}
{"op":"mcm","clk":"11836913301","pt":1723153388806,"mc":[{"id":"1.231539716","rc":[{"batb":[[0,2.34,5.66],[1,2.18,42.05],[2,2.02,4.55]],"ltp":2.42,"tv":288.4,"id":31372}]}]}
{"op":"mcm","clk":"11836913371","pt":1723153391017,"mc":[{"id":"1.231539716","rc":[{"batb":[[0,2.36,14],[1,2.34,5.66],[2,2.18,42.05]],"ltp":2.42,"tv":288.4,"id":31372}]}]}
{"op":"mcm","clk":"11836913446","pt":1723153393324,"mc":[{"id":"1.231539716","rc":[{"batb":[[0,2.36,10]],"ltp":2.42,"tv":288.4,"id":31372}]}]}
{"op":"mcm","clk":"11836913476","pt":1723153394398,"mc":[{"id":"1.231539716","rc":[{"batb":[[0,2.34,5.66],[1,2.18,42.05],[2,2.02,4.55]],"ltp":2.42,"tv":288.4,"id":31372}]}]}
{"op":"mcm","clk":"11836913504","pt":1723153395527,"mc":[{"id":"1.231539716","rc":[{"batb":[[0,2.36,4],[1,2.34,5.66],[2,2.18,42.05]],"ltp":2.42,"tv":288.4,"id":31372}]}]}
{"op":"mcm","clk":"11836913597","pt":1723153397839,"mc":[{"id":"1.231539716","rc":[{"batb":[[0,2.38,10]],"ltp":2.42,"tv":288.4,"id":31372}]}]}
{"op":"mcm","clk":"11836913683","pt":1723153400511,"mc":[{"id":"1.231539716","rc":[{"batb":[[2,1.61,4.55]],"ltp":1.71,"tv":805.24,"id":5995},{"batb":[[0,2.4,4],[1,2.38,10],[2,2.34,5.66]],"ltp":2.42,"tv":288.4,"id":31372}]}]}
{"op":"mcm","clk":"11836913714","pt":1723153401225,"mc":[{"id":"1.231539716","rc":[{"batb":[[1,2.34,5.66],[2,2.18,9.92]],"ltp":2.42,"tv":288.4,"id":31372}]}]}
{"op":"mcm","clk":"11836913762","pt":1723153402629,"mc":[{"id":"1.231539716","rc":[{"batb":[[0,2.34,5.66],[1,2.18,9.92],[2,2.02,4.55]],"ltp":2.42,"tv":288.4,"id":31372}]}]}
{"op":"mcm","clk":"11836913801","pt":1723153403712,"mc":[{"id":"1.231539716","rc":[{"batb":[[0,2.36,10],[1,2.34,5.66],[2,2.18,9.92]],"ltp":2.42,"tv":288.4,"id":31372}]}]}
{"op":"mcm","clk":"11836913871","pt":1723153405610,"mc":[{"id":"1.231539716","rc":[{"batb":[[2,1.66,53.07]],"ltp":1.71,"tv":805.24,"id":5995},{"batb":[[0,2.38,4],[1,2.36,10],[2,2.34,5.66]],"ltp":2.42,"tv":288.4,"id":31372}]}]}
{"op":"mcm","clk":"11836913919","pt":1723153406939,"mc":[{"id":"1.231539716","rc":[{"batb":[[1,2.34,5.66],[2,2.18,42.05]],"ltp":2.42,"tv":288.4,"id":31372}]}]}
{"op":"mcm","clk":"11836913948","pt":1723153407920,"mc":[{"id":"1.231539716","rc":[{"batb":[[0,2.34,5.66],[1,2.18,42.05],[2,2.02,4.55]],"ltp":2.42,"tv":288.4,"id":31372}]}]}
{"op":"mcm","clk":"11836913985","pt":1723153409044,"mc":[{"id":"1.231539716","rc":[{"batb":[[0,2.36,10],[1,2.34,5.66],[2,2.18,42.05]],"ltp":2.42,"tv":288.4,"id":31372}]}]}
{"op":"mcm","clk":"11836914042","pt":1723153410635,"mc":[{"id":"1.231539716","rc":[{"batb":[[0,2.38,4],[1,2.36,10],[2,2.34,5.66]],"ltp":2.42,"tv":288.4,"id":31372}]}]}
{"op":"mcm","clk":"11836914110","pt":1723153412431,"mc":[{"id":"1.231539716","rc":[{"batb":[[1,2.34,5.66],[2,2.18,42.05]],"ltp":2.42,"tv":288.4,"id":31372}]}]}
{"op":"mcm","clk":"11836914126","pt":1723153412945,"mc":[{"id":"1.231539716","rc":[{"batb":[[0,2.34,5.66],[1,2.18,42.05],[2,2.02,4.55]],"ltp":2.42,"tv":288.4,"id":31372}]}]}
{"op":"mcm","clk":"11836914201","pt":1723153415249,"mc":[{"id":"1.231539716","rc":[{"batb":[[0,2.36,14],[1,2.34,5.66],[2,2.18,42.05]],"ltp":2.42,"tv":288.4,"id":31372}]}]}
{"op":"mcm","clk":"11836914273","pt":1723153417556,"mc":[{"id":"1.231539716","rc":[{"batb":[[0,2.36,10]],"ltp":2.42,"tv":288.4,"id":31372}]}]}
{"op":"mcm","clk":"11836914306","pt":1723153418536,"mc":[{"id":"1.231539716","rc":[{"batb":[[0,2.34,5.66],[1,2.18,42.05],[2,2.02,4.55]],"ltp":2.42,"tv":288.4,"id":31372}]}]}
{"op":"mcm","clk":"11836914434","pt":1723153422839,"mc":[{"id":"1.231539716","rc":[{"batb":[[0,2.36,14],[1,2.34,5.66],[2,2.18,42.05]],"ltp":2.42,"tv":288.4,"id":31372}]}]}
{"op":"mcm","clk":"11836914509","pt":1723153425146,"mc":[{"id":"1.231539716","rc":[{"batb":[[0,2.36,10]],"ltp":2.42,"tv":288.4,"id":31372}]}]}
{"op":"mcm","clk":"11836914539","pt":1723153426220,"mc":[{"id":"1.231539716","rc":[{"batb":[[0,2.34,5.66],[1,2.18,42.05],[2,2.02,4.55]],"ltp":2.42,"tv":288.4,"id":31372}]}]}
{"op":"mcm","clk":"11836914578","pt":1723153427963,"mc":[{"id":"1.231539716","rc":[{"batb":[[0,2.36,4],[1,2.34,5.66],[2,2.18,42.05]],"ltp":2.42,"tv":288.4,"id":31372}]}]}
{"op":"mcm","clk":"11836914615","pt":1723153429145,"mc":[{"id":"1.231539716","rc":[{"batb":[[0,2.38,10],[1,2.36,4],[2,2.34,5.66]],"ltp":2.42,"tv":288.4,"id":31372}]}]}
{"op":"mcm","clk":"11836914640","pt":1723153430266,"mc":[{"id":"1.231539716","rc":[{"batb":[[1,2.34,5.66],[2,2.18,42.05]],"ltp":2.42,"tv":288.4,"id":31372}]}]}
{"op":"mcm","clk":"11836914650","pt":1723153430728,"mc":[{"id":"1.231539716","rc":[{"batb":[[2,1.61,4.55]],"ltp":1.71,"tv":805.24,"id":5995},{"batb":[[2,2.18,9.92]],"ltp":2.42,"tv":288.4,"id":31372}]}]}
{"op":"mcm","clk":"11836914706","pt":1723153432528,"mc":[{"id":"1.231539716","rc":[{"batb":[[0,2.34,5.66],[1,2.18,9.92],[2,2.02,4.55]],"ltp":2.42,"tv":288.4,"id":31372}]}]}
{"op":"mcm","clk":"11836914709","pt":1723153432630,"mc":[{"id":"1.231539716","rc":[{"batb":[[0,2.36,4],[1,2.34,5.66],[2,2.18,9.92]],"ltp":2.42,"tv":288.4,"id":31372}]}]}
{"op":"mcm","clk":"11836914796","pt":1723153435036,"mc":[{"id":"1.231539716","rc":[{"batb":[[0,2.38,10]],"ltp":2.42,"tv":288.4,"id":31372}]}]}
{"op":"mcm","clk":"11836914938","pt":1723153438573,"mc":[{"id":"1.231539716","rc":[{"batb":[[0,2.36,4]],"ltp":2.42,"tv":288.4,"id":31372}]}]}
{"op":"mcm","clk":"11836915030","pt":1723153440841,"mc":[{"id":"1.231539716","rc":[{"batb":[[2,1.66,53.07]],"ltp":1.71,"tv":805.24,"id":5995},{"batb":[[0,2.36,10],[2,2.18,42.05]],"ltp":2.42,"tv":288.4,"id":31372}]}]}
{"op":"mcm","clk":"11836915151","pt":1723153444272,"mc":[{"id":"1.231539716","rc":[{"batb":[[0,2.36,4]],"ltp":2.42,"tv":288.4,"id":31372}]}]}
{"op":"mcm","clk":"11836915222","pt":1723153446576,"mc":[{"id":"1.231539716","rc":[{"batb":[[0,2.34,5.66],[1,2.18,42.05],[2,2.02,4.55]],"ltp":2.42,"tv":288.4,"id":31372}]}]}
{"op":"mcm","clk":"11836915224","pt":1723153446678,"mc":[{"id":"1.231539716","rc":[{"batb":[[0,2.38,10],[1,2.34,5.66],[2,2.18,42.05]],"ltp":2.42,"tv":288.4,"id":31372}]}]}
{"op":"mcm","clk":"11836915322","pt":1723153450062,"mc":[{"id":"1.231539716","rc":[{"batb":[[0,2.4,4]],"ltp":2.42,"tv":288.4,"id":31372}]}]}
{"op":"mcm","clk":"11836915388","pt":1723153452368,"mc":[{"id":"1.231539716","rc":[{"batb":[[0,2.42,10]],"ltp":2.42,"tv":288.4,"id":31372}]}]}
{"op":"mcm","clk":"11836915442","pt":1723153454466,"mc":[{"id":"1.231539716","rc":[{"batb":[[1,2.18,42.05],[2,2.02,4.55]],"ltp":2.42,"tv":288.4,"id":31372}]}]}
{"op":"mcm","clk":"11836915510","pt":1723153456569,"mc":[{"id":"1.231539716","rc":[{"batb":[[0,2.34,5.66],[1,2.2,4],[2,2.18,42.05]],"ltp":2.42,"tv":288.4,"id":31372}]}]}
{"op":"mcm","clk":"11836915575","pt":1723153458265,"mc":[{"id":"1.231539716","rc":[{"batb":[[0,2.36,10],[1,2.34,5.66]],"ltp":2.42,"tv":288.4,"id":31372}]}]}
{"op":"mcm","clk":"11836915692","pt":1723153461596,"mc":[{"id":"1.231539716","rc":[{"batb":[[0,2.38,4],[1,2.36,10],[2,2.34,5.66]],"ltp":2.42,"tv":288.4,"id":31372}]}]}
{"op":"mcm","clk":"11836915698","pt":1723153461699,"mc":[{"id":"1.231539716","rc":[{"batb":[[1,2.34,5.66],[2,2.18,42.05]],"ltp":2.42,"tv":288.4,"id":31372}]}]}
{"op":"mcm","clk":"11836915779","pt":1723153464060,"mc":[{"id":"1.231539716","rc":[{"batb":[[0,2.4,10]],"ltp":2.42,"tv":288.4,"id":31372}]}]}
{"op":"mcm","clk":"11836915835","pt":1723153466004,"mc":[{"id":"1.231539716","rc":[{"batb":[[2,1.61,4.55]],"ltp":1.71,"tv":805.24,"id":5995},{"batb":[[2,2.18,9.92]],"ltp":2.42,"tv":288.4,"id":31372}]}]}
{"op":"mcm","clk":"11836915881","pt":1723153467491,"mc":[{"id":"1.231539716","rc":[{"batb":[[0,2.36,4]],"ltp":2.42,"tv":288.4,"id":31372}]}]}
{"op":"mcm","clk":"11836915988","pt":1723153469799,"mc":[{"id":"1.231539716","rc":[{"batb":[[0,2.36,10]],"ltp":2.42,"tv":288.4,"id":31372}]}]}
{"op":"mcm","clk":"11836916020","pt":1723153470873,"mc":[{"id":"1.231539716","rc":[{"batb":[[2,1.66,53.07]],"ltp":1.71,"tv":805.24,"id":5995},{"batb":[[2,2.18,42.05]],"ltp":2.42,"tv":288.4,"id":31372}]}]}
{"op":"mcm","clk":"11836916106","pt":1723153472976,"mc":[{"id":"1.231539716","rc":[{"batb":[[0,2.38,4]],"ltp":2.42,"tv":288.4,"id":31372}]}]}
{"op":"mcm","clk":"11836916185","pt":1723153475290,"mc":[{"id":"1.231539716","rc":[{"batb":[[0,2.36,10]],"ltp":2.42,"tv":288.4,"id":31372}]}]}
{"op":"mcm","clk":"11836916257","pt":1723153477700,"mc":[{"id":"1.231539716","rc":[{"batb":[[0,2.38,4],[1,2.36,10],[2,2.34,5.66]],"ltp":2.42,"tv":288.4,"id":31372}]}]}
{"op":"mcm","clk":"11836916290","pt":1723153478624,"mc":[{"id":"1.231539716","rc":[{"batb":[[1,2.34,5.66],[2,2.18,42.05]],"ltp":2.42,"tv":288.4,"id":31372}]}]}
{"op":"mcm","clk":"11836916351","pt":1723153480112,"mc":[{"id":"1.231539716","rc":[{"batb":[[0,2.34,5.66],[1,2.18,42.05],[2,2.02,4.55]],"ltp":2.42,"tv":288.4,"id":31372}]}]}
{"op":"mcm","clk":"11836916503","pt":1723153484521,"mc":[{"id":"1.231539716","rc":[{"batb":[[0,2.36,14],[1,2.34,5.66],[2,2.18,42.05]],"ltp":2.42,"tv":288.4,"id":31372}]}]}
{"op":"mcm","clk":"11836916586","pt":1723153486728,"mc":[{"id":"1.231539716","rc":[{"batb":[[0,2.36,10]],"ltp":2.42,"tv":288.4,"id":31372}]}]}
{"op":"mcm","clk":"11836916617","pt":1723153487907,"mc":[{"id":"1.231539716","rc":[{"batb":[[0,2.34,5.66],[1,2.18,42.05],[2,2.02,4.55]],"ltp":2.42,"tv":288.4,"id":31372}]}]}
{"op":"mcm","clk":"11836916724","pt":1723153490723,"mc":[{"id":"1.231539716","rc":[{"batb":[[0,2.36,14],[1,2.34,5.66],[2,2.18,42.05]],"ltp":2.42,"tv":288.4,"id":31372}]}]}
{"op":"mcm","clk":"11836916795","pt":1723153492931,"mc":[{"id":"1.231539716","rc":[{"batb":[[0,2.36,10]],"ltp":2.42,"tv":288.4,"id":31372}]}]}
{"op":"mcm","clk":"11836916827","pt":1723153494109,"mc":[{"id":"1.231539716","rc":[{"batb":[[0,2.34,5.66],[1,2.18,42.05],[2,2.02,4.55]],"ltp":2.42,"tv":288.4,"id":31372}]}]}
{"op":"mcm","clk":"11836916992","pt":1723153498826,"mc":[{"id":"1.231539716","rc":[{"batb":[[0,2.36,14],[1,2.34,5.66],[2,2.18,42.05]],"ltp":2.42,"tv":288.4,"id":31372}]}]}
{"op":"mcm","clk":"11836917086","pt":1723153501134,"mc":[{"id":"1.231539716","rc":[{"batb":[[0,2.36,10]],"ltp":2.42,"tv":288.4,"id":31372}]}]}
{"op":"mcm","clk":"11836917125","pt":1723153502108,"mc":[{"id":"1.231539716","rc":[{"batb":[[0,2.34,5.66],[1,2.18,42.05],[2,2.02,4.55]],"ltp":2.42,"tv":288.4,"id":31372}]}]}
{"op":"mcm","clk":"11836917181","pt":1723153503546,"mc":[{"id":"1.231539716","rc":[{"batb":[[0,2.36,4],[1,2.34,5.66],[2,2.18,42.05]],"ltp":2.42,"tv":288.4,"id":31372}]}]}
{"op":"mcm","clk":"11836917223","pt":1723153504623,"mc":[{"id":"1.231539716","rc":[{"batb":[[0,2.38,10],[1,2.36,4],[2,2.34,5.66]],"ltp":2.42,"tv":288.4,"id":31372}]}]}
{"op":"mcm","clk":"11836917271","pt":1723153506112,"mc":[{"id":"1.231539716","rc":[{"batb":[[2,1.61,4.55]],"ltp":1.71,"tv":805.24,"id":5995},{"batb":[[1,2.34,5.66],[2,2.18,9.92]],"ltp":2.42,"tv":288.4,"id":31372}]}]}
{"op":"mcm","clk":"11836917317","pt":1723153508017,"mc":[{"id":"1.231539716","rc":[{"batb":[[0,2.36,4]],"ltp":2.42,"tv":288.4,"id":31372}]}]}
{"op":"mcm","clk":"11836917397","pt":1723153510322,"mc":[{"id":"1.231539716","rc":[{"batb":[[0,2.36,10]],"ltp":2.42,"tv":288.4,"id":31372}]}]}
{"op":"mcm","clk":"11836917419","pt":1723153511139,"mc":[{"id":"1.231539716","rc":[{"batb":[[2,1.66,53.07]],"ltp":1.71,"tv":805.24,"id":5995},{"batb":[[2,2.18,42.05]],"ltp":2.42,"tv":288.4,"id":31372}]}]}
{"op":"mcm","clk":"11836917523","pt":1723153513850,"mc":[{"id":"1.231539716","rc":[{"batb":[[0,2.36,4]],"ltp":2.42,"tv":288.4,"id":31372}]}]}
{"op":"mcm","clk":"11836917594","pt":1723153516254,"mc":[{"id":"1.231539716","rc":[{"batb":[[0,2.36,10]],"ltp":2.42,"tv":288.4,"id":31372}]}]}
{"op":"mcm","clk":"11836917726","pt":1723153519736,"mc":[{"id":"1.231539716","rc":[{"batb":[[0,2.36,4]],"ltp":2.42,"tv":288.4,"id":31372}]}]}
{"op":"mcm","clk":"11836917840","pt":1723153522161,"mc":[{"id":"1.231539716","rc":[{"batb":[[0,2.36,10]],"ltp":2.42,"tv":288.4,"id":31372}]}]}
{"op":"mcm","clk":"11836917962","pt":1723153525543,"mc":[{"id":"1.231539716","rc":[{"batb":[[0,2.34,5.66],[1,2.18,42.05],[2,2.02,4.55]],"ltp":2.42,"tv":288.4,"id":31372}]}]}
{"op":"mcm","clk":"11836917973","pt":1723153525748,"mc":[{"id":"1.231539716","rc":[{"batb":[[0,2.36,4],[1,2.34,5.66],[2,2.18,42.05]],"ltp":2.42,"tv":288.4,"id":31372}]}]}
{"op":"mcm","clk":"11836918065","pt":1723153528259,"mc":[{"id":"1.231539716","rc":[{"batb":[[0,2.36,10]],"ltp":2.42,"tv":288.4,"id":31372}]}]}
{"op":"mcm","clk":"11836918169","pt":1723153531743,"mc":[{"id":"1.231539716","rc":[{"batb":[[0,2.36,4]],"ltp":2.42,"tv":288.4,"id":31372}]}]}
{"op":"mcm","clk":"11836918242","pt":1723153534147,"mc":[{"id":"1.231539716","rc":[{"batb":[[0,2.36,10]],"ltp":2.42,"tv":288.4,"id":31372}]}]}
{"op":"mcm","clk":"11836918376","pt":1723153537581,"mc":[{"id":"1.231539716","rc":[{"batb":[[0,2.38,4]],"ltp":2.42,"tv":288.4,"id":31372}]}]}
{"op":"mcm","clk":"11836918456","pt":1723153539991,"mc":[{"id":"1.231539716","rc":[{"batb":[[0,2.36,10]],"ltp":2.42,"tv":288.4,"id":31372}]}]}
{"op":"mcm","clk":"11836918563","pt":1723153542197,"mc":[{"id":"1.231539716","rc":[{"batb":[[0,2.38,4],[1,2.36,10],[2,2.34,5.66]],"ltp":2.42,"tv":288.4,"id":31372}]}]}
{"op":"mcm","clk":"11836918601","pt":1723153543272,"mc":[{"id":"1.231539716","rc":[{"batb":[[1,2.34,5.66],[2,2.18,42.05]],"ltp":2.42,"tv":288.4,"id":31372}]}]}
{"op":"mcm","clk":"11836918651","pt":1723153544457,"mc":[{"id":"1.231539716","rc":[{"batb":[[0,2.34,5.66],[1,2.18,42.05],[2,2.02,4.55]],"ltp":2.42,"tv":288.4,"id":31372}]}]}
{"op":"mcm","clk":"11836918698","pt":1723153545689,"mc":[{"id":"1.231539716","rc":[{"batb":[[0,2.36,10],[1,2.34,5.66],[2,2.18,42.05]],"ltp":2.42,"tv":288.4,"id":31372}]}]}
{"op":"mcm","clk":"11836918739","pt":1723153546866,"mc":[{"id":"1.231539716","rc":[{"batb":[[0,2.38,4],[1,2.36,10],[2,2.34,5.66]],"ltp":2.42,"tv":288.4,"id":31372}]}]}
{"op":"mcm","clk":"11836918822","pt":1723153549479,"mc":[{"id":"1.231539716","rc":[{"batb":[[0,2.34,5.66],[1,2.18,42.05],[2,2.02,4.55]],"ltp":2.42,"tv":288.4,"id":31372}]}]}
{"op":"mcm","clk":"11836918920","pt":1723153551895,"mc":[{"id":"1.231539716","rc":[{"batb":[[0,2.36,14],[1,2.34,5.66],[2,2.18,42.05]],"ltp":2.42,"tv":288.4,"id":31372}]}]}
{"op":"mcm","clk":"11836919027","pt":1723153554207,"mc":[{"id":"1.231539716","rc":[{"batb":[[0,2.36,10]],"ltp":2.42,"tv":288.4,"id":31372}]}]}
{"op":"mcm","clk":"11836919064","pt":1723153555086,"mc":[{"id":"1.231539716","rc":[{"batb":[[0,2.34,5.66],[1,2.18,42.05],[2,2.02,4.55]],"ltp":2.42,"tv":288.4,"id":31372}]}]}
{"op":"mcm","clk":"11836919159","pt":1723153557598,"mc":[{"id":"1.231539716","rc":[{"batb":[[0,2.36,14],[1,2.34,5.66],[2,2.18,42.05]],"ltp":2.42,"tv":288.4,"id":31372}]}]}
{"op":"mcm","clk":"11836919253","pt":1723153560014,"mc":[{"id":"1.231539716","rc":[{"batb":[[0,2.36,10]],"ltp":2.42,"tv":288.4,"id":31372}]}]}
{"op":"mcm","clk":"11836919297","pt":1723153560891,"mc":[{"id":"1.231539716","rc":[{"batb":[[0,2.34,5.66],[1,2.18,42.05],[2,2.02,4.55]],"ltp":2.42,"tv":288.4,"id":31372}]}]}
{"op":"mcm","clk":"11836919414","pt":1723153563310,"mc":[{"id":"1.231539716","rc":[{"batb":[[0,2.36,14],[1,2.34,5.66],[2,2.18,42.05]],"ltp":2.42,"tv":288.4,"id":31372}]}]}
{"op":"mcm","clk":"11836919501","pt":1723153565625,"mc":[{"id":"1.231539716","rc":[{"batb":[[0,2.36,10]],"ltp":2.42,"tv":288.4,"id":31372}]}]}
{"op":"mcm","clk":"11836919567","pt":1723153566706,"mc":[{"id":"1.231539716","rc":[{"batb":[[0,2.34,5.66],[1,2.18,42.05],[2,2.02,4.55]],"ltp":2.42,"tv":288.4,"id":31372}]}]}
{"op":"mcm","clk":"11836919608","pt":1723153567889,"mc":[{"id":"1.231539716","rc":[{"batb":[[0,2.36,4],[1,2.34,5.66],[2,2.18,42.05]],"ltp":2.42,"tv":288.4,"id":31372}]}]}
{"op":"mcm","clk":"11836919658","pt":1723153569225,"mc":[{"id":"1.231539716","rc":[{"batb":[[0,2.38,10],[1,2.36,4],[2,2.34,5.66]],"ltp":2.42,"tv":288.4,"id":31372}]}]}
{"op":"mcm","clk":"11836919708","pt":1723153570306,"mc":[{"id":"1.231539716","rc":[{"batb":[[1,2.34,5.66],[2,2.18,42.05]],"ltp":2.42,"tv":288.4,"id":31372}]}]}
{"op":"mcm","clk":"11836919743","pt":1723153571536,"mc":[{"id":"1.231539716","rc":[{"batb":[[2,1.61,4.55]],"ltp":1.71,"tv":805.24,"id":5995},{"batb":[[2,2.18,9.92]],"ltp":2.42,"tv":288.4,"id":31372}]}]}
{"op":"mcm","clk":"11836919806","pt":1723153572615,"mc":[{"id":"1.231539716","rc":[{"batb":[[0,2.36,4]],"ltp":2.42,"tv":288.4,"id":31372}]}]}
{"op":"mcm","clk":"11836919901","pt":1723153575091,"mc":[{"id":"1.231539716","rc":[{"batb":[[0,2.38,10]],"ltp":2.42,"tv":288.4,"id":31372}]}]}
{"op":"mcm","clk":"11836920052","pt":1723153578235,"mc":[{"id":"1.231539716","rc":[{"batb":[[0,2.36,4]],"ltp":2.42,"tv":288.4,"id":31372}]}]}
{"op":"mcm","clk":"11836920210","pt":1723153580611,"mc":[{"id":"1.231539716","rc":[{"batb":[[0,2.36,10]],"ltp":2.42,"tv":288.4,"id":31372}]}]}
{"op":"mcm","clk":"11836920260","pt":1723153581431,"mc":[{"id":"1.231539716","rc":[{"batb":[[2,1.66,53.07]],"ltp":1.71,"tv":805.24,"id":5995},{"batb":[[2,2.18,42.05]],"ltp":2.42,"tv":288.4,"id":31372}]}]}
{"op":"mcm","clk":"11836920377","pt":1723153583029,"mc":[{"id":"1.231539716","rc":[{"batb":[[0,2.38,4],[1,2.36,10],[2,2.34,5.66]],"ltp":2.42,"tv":288.4,"id":31372}]}]}
{"op":"mcm","clk":"11836920435","pt":1723153583909,"mc":[{"id":"1.231539716","rc":[{"batb":[[1,2.34,5.66],[2,2.18,42.05]],"ltp":2.42,"tv":288.4,"id":31372}]}]}
{"op":"mcm","clk":"11836920556","pt":1723153585203,"mc":[{"id":"1.231539716","rc":[{"batb":[[0,2.34,5.66],[1,2.18,42.05],[2,2.02,4.55]],"ltp":2.42,"tv":288.4,"id":31372}]}]}
{"op":"mcm","clk":"11836920716","pt":1723153587521,"mc":[{"id":"1.231539716","rc":[{"batb":[[0,2.36,14],[1,2.34,5.66],[2,2.18,42.05]],"ltp":2.42,"tv":288.4,"id":31372}]}]}
{"op":"mcm","clk":"11836920874","pt":1723153589753,"mc":[{"id":"1.231539716","rc":[{"batb":[[0,2.36,10]],"ltp":2.42,"tv":288.4,"id":31372}]}]}
{"op":"mcm","clk":"11836920955","pt":1723153590834,"mc":[{"id":"1.231539716","rc":[{"batb":[[0,2.34,5.66],[1,2.18,42.05],[2,2.02,4.55]],"ltp":2.42,"tv":288.4,"id":31372}]}]}
{"op":"mcm","clk":"11836921036","pt":1723153592118,"mc":[{"id":"1.231539716","rc":[{"batb":[[0,2.36,4],[1,2.34,5.66],[2,2.18,42.05]],"ltp":2.42,"tv":288.4,"id":31372}]}]}
{"op":"mcm","clk":"11836921186","pt":1723153594437,"mc":[{"id":"1.231539716","rc":[{"batb":[[0,2.38,10]],"ltp":2.42,"tv":288.4,"id":31372}]}]}
{"op":"mcm","clk":"11836921321","pt":1723153596540,"mc":[{"id":"1.231539716","rc":[{"batb":[[2,1.61,4.55]],"ltp":1.71,"tv":805.24,"id":5995},{"batb":[[2,2.18,9.92]],"ltp":2.42,"tv":288.4,"id":31372}]}]}
{"op":"mcm","clk":"11836921395","pt":1723153597414,"mc":[{"id":"1.231539716","rc":[{"batl":[[0,1.74,7.88]],"ltp":1.71,"tv":805.24,"id":5995},{"batb":[[0,2.4,4],[1,2.38,10],[2,2.34,5.66]],"ltp":2.42,"tv":288.4,"id":31372}]}]}
{"op":"mcm","clk":"11836921413","pt":1723153597926,"mc":[{"id":"1.231539716","rc":[{"batl":[[0,1.75,100],[1,1.76,200],[2,1.77,300]],"ltp":1.71,"tv":805.24,"id":5995},{"batb":[[1,2.34,5.66],[2,2.18,9.92]],"ltp":2.42,"tv":288.4,"id":31372}]}]}
{"op":"mcm","clk":"11836921456","pt":1723153598957,"mc":[{"id":"1.231539716","rc":[{"batb":[[0,2.34,5.66],[1,2.18,9.92],[2,2.02,4.55]],"ltp":2.42,"tv":288.4,"id":31372}]}]}
{"op":"mcm","clk":"11836921534","pt":1723153600150,"mc":[{"id":"1.231539716","rc":[{"batl":[[0,1.74,8.08],[1,1.75,100],[2,1.76,200]],"ltp":1.71,"tv":805.24,"id":5995},{"batb":[[0,2.36,10],[1,2.34,5.66],[2,2.18,9.92]],"ltp":2.42,"tv":288.4,"id":31372}]}]}
{"op":"mcm","clk":"11836921600","pt":1723153601538,"mc":[{"id":"1.231539716","rc":[{"batb":[[2,1.66,53.07]],"ltp":1.71,"tv":805.24,"id":5995},{"batb":[[0,2.38,4],[1,2.36,10],[2,2.34,5.66]],"ltp":2.42,"tv":288.4,"id":31372}]}]}
{"op":"mcm","clk":"11836921670","pt":1723153603543,"mc":[{"id":"1.231539716","rc":[{"batb":[[0,2.34,5.66],[1,2.18,42.05],[2,2.02,4.55]],"ltp":2.42,"tv":288.4,"id":31372}]}]}
{"op":"mcm","clk":"11836921779","pt":1723153606878,"mc":[{"id":"1.231539716","rc":[{"batb":[[0,2.36,14],[1,2.34,5.66],[2,2.18,42.05]],"ltp":2.42,"tv":288.4,"id":31372}]}]}
{"op":"mcm","clk":"11836921884","pt":1723153609237,"mc":[{"id":"1.231539716","rc":[{"batb":[[0,2.36,10]],"ltp":2.42,"tv":288.4,"id":31372}]}]}
{"op":"mcm","clk":"11836921921","pt":1723153610269,"mc":[{"id":"1.231539716","rc":[{"batb":[[0,2.34,5.66],[1,2.18,42.05],[2,2.02,4.55]],"ltp":2.42,"tv":288.4,"id":31372}]}]}
{"op":"mcm","clk":"11836921977","pt":1723153611654,"mc":[{"id":"1.231539716","rc":[{"batb":[[0,2.36,4],[1,2.34,5.66],[2,2.18,42.05]],"ltp":2.42,"tv":288.4,"id":31372}]}]}
{"op":"mcm","clk":"11836922021","pt":1723153612937,"mc":[{"id":"1.231539716","rc":[{"batb":[[0,2.38,10],[1,2.36,4],[2,2.34,5.66]],"ltp":2.42,"tv":288.4,"id":31372}]}]}
{"op":"mcm","clk":"11836922056","pt":1723153613863,"mc":[{"id":"1.231539716","rc":[{"batb":[[1,2.34,5.66],[2,2.18,42.05]],"ltp":2.42,"tv":288.4,"id":31372}]}]}
{"op":"mcm","clk":"11836922198","pt":1723153616485,"mc":[{"id":"1.231539716","rc":[{"batl":[[0,1.75,100],[1,1.76,200],[2,1.77,300]],"ltp":1.71,"tv":805.24,"id":5995},{"batb":[[0,2.36,4]],"ltp":2.42,"tv":288.4,"id":31372}]}]}
{"op":"mcm","clk":"11836922311","pt":1723153618853,"mc":[{"id":"1.231539716","rc":[{"batb":[[0,2.36,10]],"ltp":2.42,"tv":288.4,"id":31372}]}]}
{"op":"mcm","clk":"11836922381","pt":1723153620593,"mc":[{"id":"1.231539716","rc":[{"batb":[[1,2.18,42.05],[2,2.02,4.55]],"ltp":2.42,"tv":288.4,"id":31372}]}]}
{"op":"mcm","clk":"11836922424","pt":1723153621567,"mc":[{"id":"1.231539716","rc":[{"batl":[[0,1.74,4.91],[1,1.75,100],[2,1.76,200]],"ltp":1.71,"tv":805.24,"id":5995},{"batb":[[0,2.38,4],[1,2.36,10],[2,2.18,42.05]],"ltp":2.42,"tv":288.4,"id":31372}]}]}
{"op":"mcm","clk":"11836922447","pt":1723153622284,"mc":[{"id":"1.231539716","rc":[{"batb":[[1,2.18,42.05],[2,2.02,4.55]],"ltp":2.42,"tv":288.4,"id":31372}]}]}
{"op":"mcm","clk":"11836922482","pt":1723153623055,"mc":[{"id":"1.231539716","rc":[{"batb":[[1,2.34,6.24],[2,2.18,42.05]],"ltp":2.42,"tv":288.4,"id":31372}]}]}
{"op":"mcm","clk":"11836922504","pt":1723153623771,"mc":[{"id":"1.231539716","rc":[{"batb":[[0,2.34,6.24],[1,2.18,42.05],[2,2.02,4.55]],"ltp":2.42,"tv":288.4,"id":31372}]}]}
{"op":"mcm","clk":"11836922558","pt":1723153625000,"mc":[{"id":"1.231539716","rc":[{"batb":[[0,2.36,10],[1,2.34,6.24],[2,2.18,42.05]],"ltp":2.42,"tv":288.4,"id":31372}]}]}
{"op":"mcm","clk":"11836922627","pt":1723153626280,"mc":[{"id":"1.231539716","rc":[{"batb":[[0,2.38,4],[1,2.36,10],[2,2.34,6.24]],"ltp":2.42,"tv":288.4,"id":31372}]}]}
{"op":"mcm","clk":"11836922736","pt":1723153628487,"mc":[{"id":"1.231539716","rc":[{"batb":[[0,2.34,6.24],[1,2.18,42.05],[2,2.02,4.55]],"ltp":2.42,"tv":288.4,"id":31372}]}]}
{"op":"mcm","clk":"11836922833","pt":1723153630897,"mc":[{"id":"1.231539716","rc":[{"batb":[[0,2.36,14],[1,2.34,6.24],[2,2.18,42.05]],"ltp":2.42,"tv":288.4,"id":31372}]}]}
{"op":"mcm","clk":"11836922942","pt":1723153633308,"mc":[{"id":"1.231539716","rc":[{"batb":[[0,2.36,10]],"ltp":2.42,"tv":288.4,"id":31372}]}]}
{"op":"mcm","clk":"11836922971","pt":1723153634180,"mc":[{"id":"1.231539716","rc":[{"batb":[[0,2.34,6.24],[1,2.18,42.05],[2,2.02,4.55]],"ltp":2.42,"tv":288.4,"id":31372}]}]}
{"op":"mcm","clk":"11836923036","pt":1723153635566,"mc":[{"id":"1.231539716","rc":[{"batb":[[0,2.36,4],[1,2.34,6.24],[2,2.18,42.05]],"ltp":2.42,"tv":288.4,"id":31372}]}]}
{"op":"mcm","clk":"11836923133","pt":1723153637976,"mc":[{"id":"1.231539716","rc":[{"batb":[[0,2.36,10]],"ltp":2.42,"tv":288.4,"id":31372}]}]}
{"op":"mcm","clk":"11836923277","pt":1723153641385,"mc":[{"id":"1.231539716","rc":[{"batb":[[0,2.38,4]],"ltp":2.42,"tv":288.4,"id":31372}]}]}
{"op":"mcm","clk":"11836923324","pt":1723153642209,"mc":[{"id":"1.231539716","rc":[{"batl":[[0,1.74,13.04]],"ltp":1.71,"tv":805.24,"id":5995}]}]}
{"op":"mcm","clk":"11836923383","pt":1723153643801,"mc":[{"id":"1.231539716","rc":[{"batb":[[0,2.4,10]],"ltp":2.42,"tv":288.4,"id":31372}]}]}
{"op":"mcm","clk":"11836923510","pt":1723153647187,"mc":[{"id":"1.231539716","rc":[{"batb":[[2,1.61,4.55]],"ltp":1.71,"tv":805.24,"id":5995},{"batb":[[0,2.42,4],[2,2.18,9.92]],"ltp":2.42,"tv":288.4,"id":31372}]}]}
{"op":"mcm","clk":"11836923585","pt":1723153649500,"mc":[{"id":"1.231539716","rc":[{"batb":[[0,2.36,10]],"ltp":2.42,"tv":288.4,"id":31372}]}]}
{"op":"mcm","clk":"11836923682","pt":1723153651912,"mc":[{"id":"1.231539716","rc":[{"batb":[[2,1.66,53.07]],"ltp":1.71,"tv":805.24,"id":5995},{"batb":[[0,2.38,4],[1,2.36,10],[2,2.34,6.24]],"ltp":2.42,"tv":288.4,"id":31372}]}]}
{"op":"mcm","clk":"11836923730","pt":1723153652888,"mc":[{"id":"1.231539716","rc":[{"batb":[[1,2.34,6.24],[2,2.18,42.05]],"ltp":2.42,"tv":288.4,"id":31372}]}]}
{"op":"mcm","clk":"11836923787","pt":1723153654223,"mc":[{"id":"1.231539716","rc":[{"batb":[[0,2.34,6.24],[1,2.18,42.05],[2,2.02,4.55]],"ltp":2.42,"tv":288.4,"id":31372}]}]}
{"op":"mcm","clk":"11836923826","pt":1723153655302,"mc":[{"id":"1.231539716","rc":[{"batb":[[0,2.36,10],[1,2.34,6.24],[2,2.18,42.05]],"ltp":2.42,"tv":288.4,"id":31372}]}]}
{"op":"mcm","clk":"11836923885","pt":1723153656587,"mc":[{"id":"1.231539716","rc":[{"batb":[[0,2.38,4],[1,2.36,10],[2,2.34,6.24]],"ltp":2.42,"tv":288.4,"id":31372}]}]}
{"op":"mcm","clk":"11836923981","pt":1723153658894,"mc":[{"id":"1.231539716","rc":[{"batb":[[0,2.34,6.24],[1,2.18,42.05],[2,2.02,4.55]],"ltp":2.42,"tv":288.4,"id":31372}]}]}
{"op":"mcm","clk":"11836924064","pt":1723153661200,"mc":[{"id":"1.231539716","rc":[{"batb":[[0,2.36,14],[1,2.34,6.24],[2,2.18,42.05]],"ltp":2.42,"tv":288.4,"id":31372}]}]}
{"op":"mcm","clk":"11836924184","pt":1723153663510,"mc":[{"id":"1.231539716","rc":[{"batb":[[0,2.36,10]],"ltp":2.42,"tv":288.4,"id":31372}]}]}
{"op":"mcm","clk":"11836924218","pt":1723153664635,"mc":[{"id":"1.231539716","rc":[{"batb":[[0,2.34,6.24],[1,2.18,42.05],[2,2.02,4.55]],"ltp":2.42,"tv":288.4,"id":31372}]}]}
{"op":"mcm","clk":"11836924315","pt":1723153666840,"mc":[{"id":"1.231539716","rc":[{"batb":[[0,2.36,14],[1,2.34,6.24],[2,2.18,42.05]],"ltp":2.42,"tv":288.4,"id":31372}]}]}
{"op":"mcm","clk":"11836924398","pt":1723153669199,"mc":[{"id":"1.231539716","rc":[{"batb":[[0,2.36,10]],"ltp":2.42,"tv":288.4,"id":31372}]}]}
{"op":"mcm","clk":"11836924449","pt":1723153670224,"mc":[{"id":"1.231539716","rc":[{"batb":[[0,2.34,6.24],[1,2.18,42.05],[2,2.02,4.55]],"ltp":2.42,"tv":288.4,"id":31372}]}]}
{"op":"mcm","clk":"11836924507","pt":1723153671511,"mc":[{"id":"1.231539716","rc":[{"batb":[[0,2.36,4],[1,2.34,6.24],[2,2.18,42.05]],"ltp":2.42,"tv":288.4,"id":31372}]}]}
{"op":"mcm","clk":"11836924564","pt":1723153672634,"mc":[{"id":"1.231539716","rc":[{"batb":[[0,2.38,10],[1,2.36,4],[2,2.34,6.24]],"ltp":2.42,"tv":288.4,"id":31372}]}]}
{"op":"mcm","clk":"11836924619","pt":1723153673914,"mc":[{"id":"1.231539716","rc":[{"batb":[[1,2.34,6.24],[2,2.18,42.05]],"ltp":2.42,"tv":288.4,"id":31372}]}]}
{"op":"mcm","clk":"11836924766","pt":1723153676122,"mc":[{"id":"1.231539716","rc":[{"batb":[[0,2.36,4]],"ltp":2.42,"tv":288.4,"id":31372}]}]}
{"op":"mcm","clk":"11836924861","pt":1723153678534,"mc":[{"id":"1.231539716","rc":[{"batb":[[0,2.34,6.24],[1,2.18,42.05],[2,2.02,4.55]],"ltp":2.42,"tv":288.4,"id":31372}]}]}
{"op":"mcm","clk":"11836924865","pt":1723153678637,"mc":[{"id":"1.231539716","rc":[{"batb":[[0,2.36,10],[1,2.34,6.24],[2,2.18,42.05]],"ltp":2.42,"tv":288.4,"id":31372}]}]}
{"op":"mcm","clk":"11836925038","pt":1723153681154,"mc":[{"id":"1.231539716","rc":[{"batb":[[0,2.38,4],[1,2.36,10],[2,2.34,6.24]],"ltp":2.42,"tv":288.4,"id":31372}]}]}
{"op":"mcm","clk":"11836925076","pt":1723153682026,"mc":[{"id":"1.231539716","rc":[{"batb":[[1,2.34,6.24],[2,2.18,42.05]],"ltp":2.42,"tv":288.4,"id":31372}]}]}
{"op":"mcm","clk":"11836925142","pt":1723153683410,"mc":[{"id":"1.231539716","rc":[{"batb":[[0,2.34,6.24],[1,2.18,42.05],[2,2.02,4.55]],"ltp":2.42,"tv":288.4,"id":31372}]}]}
{"op":"mcm","clk":"11836925190","pt":1723153684536,"mc":[{"id":"1.231539716","rc":[{"batb":[[0,2.36,10],[1,2.34,6.24],[2,2.18,42.05]],"ltp":2.42,"tv":288.4,"id":31372}]}]}
{"op":"mcm","clk":"11836925284","pt":1723153686636,"mc":[{"id":"1.231539716","rc":[{"batb":[[0,2.38,4],[1,2.36,10],[2,2.34,6.24]],"ltp":2.42,"tv":288.4,"id":31372}]}]}
{"op":"mcm","clk":"11836925346","pt":1723153687659,"mc":[{"id":"1.231539716","rc":[{"batb":[[1,2.34,6.24],[2,2.18,42.05]],"ltp":2.42,"tv":288.4,"id":31372}]}]}
{"op":"mcm","clk":"11836925403","pt":1723153688939,"mc":[{"id":"1.231539716","rc":[{"batb":[[0,2.34,6.24],[1,2.18,42.05],[2,2.02,4.55]],"ltp":2.42,"tv":288.4,"id":31372}]}]}
{"op":"mcm","clk":"11836925556","pt":1723153692328,"mc":[{"id":"1.231539716","rc":[{"batb":[[0,2.36,14],[1,2.34,6.24],[2,2.18,42.05]],"ltp":2.42,"tv":288.4,"id":31372}]}]}
{"op":"mcm","clk":"11836925695","pt":1723153695555,"mc":[{"id":"1.231539716","rc":[{"batb":[[0,2.34,6.24],[1,2.18,42.05],[2,2.02,4.55]],"ltp":2.42,"tv":288.4,"id":31372}]}]}
{"op":"mcm","clk":"11836925767","pt":1723153697042,"mc":[{"id":"1.231539716","rc":[{"batb":[[0,2.36,4],[1,2.34,6.24],[2,2.18,42.05]],"ltp":2.42,"tv":288.4,"id":31372}]}]}
{"op":"mcm","clk":"11836925821","pt":1723153698120,"mc":[{"id":"1.231539716","rc":[{"batb":[[0,2.38,10],[1,2.36,4],[2,2.34,6.24]],"ltp":2.42,"tv":288.4,"id":31372}]}]}
{"op":"mcm","clk":"11836925867","pt":1723153699454,"mc":[{"id":"1.231539716","rc":[{"batb":[[1,2.34,6.24],[2,2.18,42.05]],"ltp":2.42,"tv":288.4,"id":31372}]}]}
{"op":"mcm","clk":"11836925949","pt":1723153701349,"mc":[{"id":"1.231539716","rc":[{"batb":[[0,2.34,6.24],[1,2.18,42.05],[2,2.02,4.55]],"ltp":2.42,"tv":288.4,"id":31372}]}]}
{"op":"mcm","clk":"11836926014","pt":1723153702841,"mc":[{"id":"1.231539716","rc":[{"batb":[[0,2.36,4],[1,2.34,6.24],[2,2.18,42.05]],"ltp":2.42,"tv":288.4,"id":31372}]}]}
{"op":"mcm","clk":"11836926063","pt":1723153704020,"mc":[{"id":"1.231539716","rc":[{"batb":[[0,2.38,10],[1,2.36,4],[2,2.34,6.24]],"ltp":2.42,"tv":288.4,"id":31372}]}]}
{"op":"mcm","clk":"11836926115","pt":1723153705229,"mc":[{"id":"1.231539716","rc":[{"batb":[[1,2.34,6.24],[2,2.18,42.05]],"ltp":2.42,"tv":288.4,"id":31372}]}]}
{"op":"mcm","clk":"11836926199","pt":1723153707545,"mc":[{"id":"1.231539716","rc":[{"batb":[[2,1.61,4.55]],"ltp":1.71,"tv":805.24,"id":5995},{"batb":[[0,2.36,4],[2,2.18,9.92]],"ltp":2.42,"tv":288.4,"id":31372}]}]}
{"op":"mcm","clk":"11836926326","pt":1723153710064,"mc":[{"id":"1.231539716","rc":[{"batb":[[0,2.36,10]],"ltp":2.42,"tv":288.4,"id":31372}]}]}
{"op":"mcm","clk":"11836926405","pt":1723153712270,"mc":[{"id":"1.231539716","rc":[{"batb":[[2,1.66,53.07]],"ltp":1.71,"tv":805.24,"id":5995},{"batb":[[0,2.38,4],[1,2.36,10],[2,2.34,6.24]],"ltp":2.42,"tv":288.4,"id":31372}]}]}
{"op":"mcm","clk":"11836926469","pt":1723153713453,"mc":[{"id":"1.231539716","rc":[{"batb":[[1,2.34,6.24],[2,2.18,42.05]],"ltp":2.42,"tv":288.4,"id":31372}]}]}
{"op":"mcm","clk":"11836926516","pt":1723153714578,"mc":[{"id":"1.231539716","rc":[{"batb":[[0,2.34,6.24],[1,2.18,42.05],[2,2.02,4.55]],"ltp":2.42,"tv":288.4,"id":31372}]}]}
{"op":"mcm","clk":"11836926571","pt":1723153715758,"mc":[{"id":"1.231539716","rc":[{"batb":[[0,2.36,10],[1,2.34,6.24],[2,2.18,42.05]],"ltp":2.42,"tv":288.4,"id":31372}]}]}
{"op":"mcm","clk":"11836926690","pt":1723153718072,"mc":[{"id":"1.231539716","rc":[{"batb":[[0,2.38,4],[1,2.36,10],[2,2.34,6.24]],"ltp":2.42,"tv":288.4,"id":31372}]}]}
{"op":"mcm","clk":"11836926730","pt":1723153719051,"mc":[{"id":"1.231539716","rc":[{"batb":[[1,2.34,6.24],[2,2.18,42.05]],"ltp":2.42,"tv":288.4,"id":31372}]}]}
{"op":"mcm","clk":"11836926785","pt":1723153720485,"mc":[{"id":"1.231539716","rc":[{"batb":[[0,2.34,6.24],[1,2.18,42.05],[2,2.02,4.55]],"ltp":2.42,"tv":288.4,"id":31372}]}]}
{"op":"mcm","clk":"11836926840","pt":1723153721768,"mc":[{"id":"1.231539716","rc":[{"batb":[[0,2.36,10],[1,2.34,6.24],[2,2.18,42.05]],"ltp":2.42,"tv":288.4,"id":31372}]}]}
{"op":"mcm","clk":"11836926955","pt":1723153724378,"mc":[{"id":"1.231539716","rc":[{"batb":[[0,2.38,4],[1,2.36,10],[2,2.34,6.24]],"ltp":2.42,"tv":288.4,"id":31372}]}]}
{"op":"mcm","clk":"11836926997","pt":1723153725250,"mc":[{"id":"1.231539716","rc":[{"batb":[[1,2.34,6.24],[2,2.18,42.05]],"ltp":2.42,"tv":288.4,"id":31372}]}]}
{"op":"mcm","clk":"11836927054","pt":1723153726583,"mc":[{"id":"1.231539716","rc":[{"batb":[[0,2.34,6.24],[1,2.18,42.05],[2,2.02,4.55]],"ltp":2.42,"tv":288.4,"id":31372}]}]}
{"op":"mcm","clk":"11836927116","pt":1723153727860,"mc":[{"id":"1.231539716","rc":[{"batb":[[0,2.36,10],[1,2.34,6.24],[2,2.18,42.05]],"ltp":2.42,"tv":288.4,"id":31372}]}]}
{"op":"mcm","clk":"11836927271","pt":1723153731354,"mc":[{"id":"1.231539716","rc":[{"batb":[[0,2.36,4]],"ltp":2.42,"tv":288.4,"id":31372}]}]}
{"op":"mcm","clk":"11836927371","pt":1723153733767,"mc":[{"id":"1.231539716","rc":[{"batb":[[0,2.38,10]],"ltp":2.42,"tv":288.4,"id":31372}]}]}
{"op":"mcm","clk":"11836927486","pt":1723153737196,"mc":[{"id":"1.231539716","rc":[{"batb":[[0,2.36,4]],"ltp":2.42,"tv":288.4,"id":31372}]}]}
{"op":"mcm","clk":"11836927585","pt":1723153739611,"mc":[{"id":"1.231539716","rc":[{"batb":[[0,2.38,10]],"ltp":2.42,"tv":288.4,"id":31372}]}]}
{"op":"mcm","clk":"11836927735","pt":1723153742486,"mc":[{"id":"1.231539716","rc":[{"batb":[[2,1.61,4.55]],"ltp":1.71,"tv":805.24,"id":5995},{"batb":[[0,2.4,4],[1,2.38,10],[2,2.34,6.24]],"ltp":2.42,"tv":288.4,"id":31372}]}]}
{"op":"mcm","clk":"11836927743","pt":1723153742690,"mc":[{"id":"1.231539716","rc":[{"batb":[[1,2.34,6.24],[2,2.18,9.92]],"ltp":2.42,"tv":288.4,"id":31372}]}]}
{"op":"mcm","clk":"11836927840","pt":1723153744900,"mc":[{"id":"1.231539716","rc":[{"batb":[[0,2.36,10]],"ltp":2.42,"tv":288.4,"id":31372}]}]}
{"op":"mcm","clk":"11836927959","pt":1723153747309,"mc":[{"id":"1.231539716","rc":[{"batb":[[2,1.66,53.07]],"ltp":1.71,"tv":805.24,"id":5995},{"batb":[[0,2.38,4],[1,2.36,10],[2,2.34,6.24]],"ltp":2.42,"tv":288.4,"id":31372}]}]}
{"op":"mcm","clk":"11836927985","pt":1723153748127,"mc":[{"id":"1.231539716","rc":[{"batb":[[1,2.34,6.24],[2,2.18,42.05]],"ltp":2.42,"tv":288.4,"id":31372}]}]}
{"op":"mcm","clk":"11836928052","pt":1723153749713,"mc":[{"id":"1.231539716","rc":[{"batb":[[0,2.34,6.24],[1,2.18,42.05],[2,2.02,4.55]],"ltp":2.42,"tv":288.4,"id":31372}]}]}
{"op":"mcm","clk":"11836928141","pt":1723153751914,"mc":[{"id":"1.231539716","rc":[{"batb":[[0,2.36,14],[1,2.34,6.24],[2,2.18,42.05]],"ltp":2.42,"tv":288.4,"id":31372}]}]}
{"op":"mcm","clk":"11836928238","pt":1723153754219,"mc":[{"id":"1.231539716","rc":[{"batb":[[0,2.36,10]],"ltp":2.42,"tv":288.4,"id":31372}]}]}
{"op":"mcm","clk":"11836928289","pt":1723153755244,"mc":[{"id":"1.231539716","rc":[{"batb":[[0,2.34,6.24],[1,2.18,42.05],[2,2.02,4.55]],"ltp":2.42,"tv":288.4,"id":31372}]}]}
{"op":"mcm","clk":"11836928349","pt":1723153756423,"mc":[{"id":"1.231539716","rc":[{"batb":[[0,2.36,4],[1,2.34,6.24],[2,2.18,42.05]],"ltp":2.42,"tv":288.4,"id":31372}]}]}
{"op":"mcm","clk":"11836928403","pt":1723153757806,"mc":[{"id":"1.231539716","rc":[{"batb":[[0,2.38,10],[1,2.36,4],[2,2.34,6.24]],"ltp":2.42,"tv":288.4,"id":31372}]}]}
{"op":"mcm","clk":"11836928445","pt":1723153758830,"mc":[{"id":"1.231539716","rc":[{"batb":[[1,2.34,6.24],[2,2.18,42.05]],"ltp":2.42,"tv":288.4,"id":31372}]}]}
{"op":"mcm","clk":"11836928570","pt":1723153761141,"mc":[{"id":"1.231539716","rc":[{"batb":[[0,2.36,4]],"ltp":2.42,"tv":288.4,"id":31372}]}]}
{"op":"mcm","clk":"11836928677","pt":1723153763550,"mc":[{"id":"1.231539716","rc":[{"batb":[[0,2.36,10]],"ltp":2.42,"tv":288.4,"id":31372}]}]}
{"op":"mcm","clk":"11836928782","pt":1723153766011,"mc":[{"id":"1.231539716","rc":[{"batb":[[0,2.38,4],[1,2.36,10],[2,2.34,6.24]],"ltp":2.42,"tv":288.4,"id":31372}]}]}
{"op":"mcm","clk":"11836928812","pt":1723153766932,"mc":[{"id":"1.231539716","rc":[{"batb":[[1,2.34,6.24],[2,2.18,42.05]],"ltp":2.42,"tv":288.4,"id":31372}]}]}
{"op":"mcm","clk":"11836928882","pt":1723153768519,"mc":[{"id":"1.231539716","rc":[{"batb":[[0,2.34,6.24],[1,2.18,42.05],[2,2.02,4.55]],"ltp":2.42,"tv":288.4,"id":31372}]}]}
{"op":"mcm","clk":"11836928926","pt":1723153769749,"mc":[{"id":"1.231539716","rc":[{"batb":[[0,2.36,10],[1,2.34,6.24],[2,2.18,42.05]],"ltp":2.42,"tv":288.4,"id":31372}]}]}
{"op":"mcm","clk":"11836929016","pt":1723153771649,"mc":[{"id":"1.231539716","rc":[{"batb":[[0,2.38,4],[1,2.36,10],[2,2.34,6.24]],"ltp":2.42,"tv":288.4,"id":31372}]}]}
{"op":"mcm","clk":"11836929065","pt":1723153773042,"mc":[{"id":"1.231539716","rc":[{"batb":[[1,2.34,6.24],[2,2.18,42.05]],"ltp":2.42,"tv":288.4,"id":31372}]}]}
{"op":"mcm","clk":"11836929094","pt":1723153773958,"mc":[{"id":"1.231539716","rc":[{"batb":[[0,2.34,6.24],[1,2.18,42.05],[2,2.02,4.55]],"ltp":2.42,"tv":288.4,"id":31372}]}]}
{"op":"mcm","clk":"11836929144","pt":1723153775138,"mc":[{"id":"1.231539716","rc":[{"batb":[[0,2.36,10],[1,2.34,6.24],[2,2.18,42.05]],"ltp":2.42,"tv":288.4,"id":31372}]}]}
{"op":"mcm","clk":"11836929183","pt":1723153776265,"mc":[{"id":"1.231539716","rc":[{"batb":[[0,2.38,4],[1,2.36,10],[2,2.34,6.24]],"ltp":2.42,"tv":288.4,"id":31372}]}]}
{"op":"mcm","clk":"11836929260","pt":1723153778529,"mc":[{"id":"1.231539716","rc":[{"batb":[[0,2.34,6.24],[1,2.18,42.05],[2,2.02,4.55]],"ltp":2.42,"tv":288.4,"id":31372}]}]}
{"op":"mcm","clk":"11836929390","pt":1723153781973,"mc":[{"id":"1.231539716","rc":[{"batb":[[0,2.36,14],[1,2.34,6.24],[2,2.18,42.05]],"ltp":2.42,"tv":288.4,"id":31372}]}]}
{"op":"mcm","clk":"11836929476","pt":1723153784331,"mc":[{"id":"1.231539716","rc":[{"batb":[[0,2.36,10]],"ltp":2.42,"tv":288.4,"id":31372}]}]}
{"op":"mcm","clk":"11836929517","pt":1723153785354,"mc":[{"id":"1.231539716","rc":[{"batb":[[0,2.34,6.24],[1,2.18,42.05],[2,2.02,4.55]],"ltp":2.42,"tv":288.4,"id":31372}]}]}
{"op":"mcm","clk":"11836929566","pt":1723153786640,"mc":[{"id":"1.231539716","rc":[{"batb":[[0,2.36,4],[1,2.34,6.24],[2,2.18,42.05]],"ltp":2.42,"tv":288.4,"id":31372}]}]}
{"op":"mcm","clk":"11836929599","pt":1723153787866,"mc":[{"id":"1.231539716","rc":[{"batb":[[0,2.38,10],[1,2.36,4],[2,2.34,6.24]],"ltp":2.42,"tv":288.4,"id":31372}]}]}
{"op":"mcm","clk":"11836929644","pt":1723153788945,"mc":[{"id":"1.231539716","rc":[{"batb":[[1,2.34,6.24],[2,2.18,42.05]],"ltp":2.42,"tv":288.4,"id":31372}]}]}
{"op":"mcm","clk":"11836929739","pt":1723153791256,"mc":[{"id":"1.231539716","rc":[{"batb":[[0,2.36,4]],"ltp":2.42,"tv":288.4,"id":31372}]}]}
{"op":"mcm","clk":"11836929813","pt":1723153793470,"mc":[{"id":"1.231539716","rc":[{"batb":[[0,2.38,10],[1,2.36,4],[2,2.34,6.24]],"ltp":2.42,"tv":288.4,"id":31372}]}]}
{"op":"mcm","clk":"11836929826","pt":1723153793675,"mc":[{"id":"1.231539716","rc":[{"batb":[[1,2.34,6.24],[2,2.18,42.05]],"ltp":2.42,"tv":288.4,"id":31372}]}]}
{"op":"mcm","clk":"11836929901","pt":1723153795840,"mc":[{"id":"1.231539716","rc":[{"batb":[[0,2.4,4],[1,2.38,10],[2,2.34,6.24]],"ltp":2.42,"tv":288.4,"id":31372}]}]}
{"op":"mcm","clk":"11836929948","pt":1723153796769,"mc":[{"id":"1.231539716","rc":[{"batl":[[0,1.74,8.14]],"ltp":1.71,"tv":805.24,"id":5995},{"batb":[[1,2.34,6.24],[2,2.18,42.05]],"ltp":2.42,"tv":288.4,"id":31372}]}]}
{"op":"mcm","clk":"11836930022","pt":1723153798257,"mc":[{"id":"1.231539716","rc":[{"batb":[[0,2.34,6.24],[1,2.18,42.05],[2,2.02,4.55]],"ltp":2.42,"tv":288.4,"id":31372}]}]}
{"op":"mcm","clk":"11836930091","pt":1723153800057,"mc":[{"id":"1.231539716","rc":[{"batl":[[0,1.74,13.86]],"ltp":1.71,"tv":805.24,"id":5995},{"batb":[[0,2.36,10],[1,2.34,6.24],[2,2.18,42.05]],"ltp":2.42,"tv":288.4,"id":31372}]}]}
{"op":"mcm","clk":"11836930135","pt":1723153801288,"mc":[{"id":"1.231539716","rc":[{"batb":[[0,2.38,4],[1,2.36,10],[2,2.34,6.24]],"ltp":2.42,"tv":288.4,"id":31372}]}]}
{"op":"mcm","clk":"11836930220","pt":1723153803550,"mc":[{"id":"1.231539716","rc":[{"batb":[[0,2.34,6.24],[1,2.18,42.05],[2,2.02,4.55]],"ltp":2.42,"tv":288.4,"id":31372}]}]}
{"op":"mcm","clk":"11836930310","pt":1723153805867,"mc":[{"id":"1.231539716","rc":[{"batb":[[0,2.36,14],[1,2.34,6.24],[2,2.18,42.05]],"ltp":2.42,"tv":288.4,"id":31372}]}]}
{"op":"mcm","clk":"11836930404","pt":1723153808184,"mc":[{"id":"1.231539716","rc":[{"batb":[[0,2.36,10]],"ltp":2.42,"tv":288.4,"id":31372}]}]}
{"op":"mcm","clk":"11836930447","pt":1723153809264,"mc":[{"id":"1.231539716","rc":[{"batb":[[0,2.34,6.24],[1,2.18,42.05],[2,2.02,4.55]],"ltp":2.42,"tv":288.4,"id":31372}]}]}
{"op":"mcm","clk":"11836930493","pt":1723153810394,"mc":[{"id":"1.231539716","rc":[{"batb":[[0,2.36,4],[1,2.34,6.24],[2,2.18,42.05]],"ltp":2.42,"tv":288.4,"id":31372}]}]}
{"op":"mcm","clk":"11836930544","pt":1723153811573,"mc":[{"id":"1.231539716","rc":[{"batb":[[0,2.38,10],[1,2.36,4],[2,2.34,6.24]],"ltp":2.42,"tv":288.4,"id":31372}]}]}
{"op":"mcm","clk":"11836930602","pt":1723153812906,"mc":[{"id":"1.231539716","rc":[{"batb":[[2,1.61,4.55]],"ltp":1.71,"tv":805.24,"id":5995},{"batb":[[1,2.34,6.24],[2,2.18,9.92]],"ltp":2.42,"tv":288.4,"id":31372}]}]}
{"op":"mcm","clk":"11836930697","pt":1723153815070,"mc":[{"id":"1.231539716","rc":[{"batb":[[0,2.36,4]],"ltp":2.42,"tv":288.4,"id":31372}]}]}
{"op":"mcm","clk":"11836930769","pt":1723153817476,"mc":[{"id":"1.231539716","rc":[{"batb":[[0,2.36,10]],"ltp":2.42,"tv":288.4,"id":31372}]}]}
{"op":"mcm","clk":"11836930778","pt":1723153817782,"mc":[{"id":"1.231539716","rc":[{"batb":[[2,1.66,53.07]],"ltp":1.71,"tv":805.24,"id":5995},{"batb":[[2,2.18,42.05]],"ltp":2.42,"tv":288.4,"id":31372}]}]}
{"op":"mcm","clk":"11836930846","pt":1723153819886,"mc":[{"id":"1.231539716","rc":[{"batb":[[0,2.38,4],[1,2.36,10],[2,2.34,6.24]],"ltp":2.42,"tv":288.4,"id":31372}]}]}
{"op":"mcm","clk":"11836930877","pt":1723153820808,"mc":[{"id":"1.231539716","rc":[{"batb":[[1,2.34,6.24],[2,2.18,42.05]],"ltp":2.42,"tv":288.4,"id":31372}]}]}
{"op":"mcm","clk":"11836930943","pt":1723153822195,"mc":[{"id":"1.231539716","rc":[{"batb":[[0,2.34,6.24],[1,2.18,42.05],[2,2.02,4.55]],"ltp":2.42,"tv":288.4,"id":31372}]}]}
{"op":"mcm","clk":"11836931032","pt":1723153824401,"mc":[{"id":"1.231539716","rc":[{"batb":[[0,2.36,14],[1,2.34,6.24],[2,2.18,42.05]],"ltp":2.42,"tv":288.4,"id":31372}]}]}
{"op":"mcm","clk":"11836931126","pt":1723153826807,"mc":[{"id":"1.231539716","rc":[{"batb":[[0,2.36,10]],"ltp":2.42,"tv":288.4,"id":31372}]}]}
{"op":"mcm","clk":"11836931159","pt":1723153827682,"mc":[{"id":"1.231539716","rc":[{"batb":[[0,2.34,6.24],[1,2.18,42.05],[2,2.02,4.55]],"ltp":2.42,"tv":288.4,"id":31372}]}]}
{"op":"mcm","clk":"11836931201","pt":1723153829014,"mc":[{"id":"1.231539716","rc":[{"batb":[[0,2.36,4],[1,2.34,6.24],[2,2.18,42.05]],"ltp":2.42,"tv":288.4,"id":31372}]}]}
{"op":"mcm","clk":"11836931252","pt":1723153830197,"mc":[{"id":"1.231539716","rc":[{"batb":[[0,2.38,10],[1,2.36,4],[2,2.34,6.24]],"ltp":2.42,"tv":288.4,"id":31372}]}]}
{"op":"mcm","clk":"11836931296","pt":1723153831324,"mc":[{"id":"1.231539716","rc":[{"batb":[[1,2.34,6.24],[2,2.18,42.05]],"ltp":2.42,"tv":288.4,"id":31372}]}]}
{"op":"mcm","clk":"11836931386","pt":1723153833581,"mc":[{"id":"1.231539716","rc":[{"batb":[[2,1.61,4.55]],"ltp":1.71,"tv":805.24,"id":5995},{"batb":[[0,2.34,6.24],[1,2.18,9.92],[2,2.02,4.55]],"ltp":2.42,"tv":288.4,"id":31372}]}]}
{"op":"mcm","clk":"11836931391","pt":1723153833682,"mc":[{"id":"1.231539716","rc":[{"batb":[[0,2.36,4],[1,2.34,6.24],[2,2.18,9.92]],"ltp":2.42,"tv":288.4,"id":31372}]}]}
{"op":"mcm","clk":"11836931480","pt":1723153836093,"mc":[{"id":"1.231539716","rc":[{"batb":[[0,2.38,10]],"ltp":2.42,"tv":288.4,"id":31372}]}]}
{"op":"mcm","clk":"11836931613","pt":1723153839320,"mc":[{"id":"1.231539716","rc":[{"batb":[[0,2.36,4]],"ltp":2.42,"tv":288.4,"id":31372}]}]}
{"op":"mcm","clk":"11836931734","pt":1723153841688,"mc":[{"id":"1.231539716","rc":[{"batb":[[0,2.36,10]],"ltp":2.42,"tv":288.4,"id":31372}]}]}
{"op":"mcm","clk":"11836931781","pt":1723153842916,"mc":[{"id":"1.231539716","rc":[{"batb":[[2,1.66,53.07]],"ltp":1.71,"tv":805.24,"id":5995},{"batb":[[2,2.18,42.05]],"ltp":2.42,"tv":288.4,"id":31372}]}]}
{"op":"mcm","clk":"11836931834","pt":1723153844196,"mc":[{"id":"1.231539716","rc":[{"batb":[[0,2.38,4],[1,2.36,10],[2,2.34,6.24]],"ltp":2.42,"tv":288.4,"id":31372}]}]}
{"op":"mcm","clk":"11836931871","pt":1723153845116,"mc":[{"id":"1.231539716","rc":[{"batb":[[1,2.34,6.24],[2,2.18,42.05]],"ltp":2.42,"tv":288.4,"id":31372}]}]}
{"op":"mcm","clk":"11836931931","pt":1723153846399,"mc":[{"id":"1.231539716","rc":[{"batb":[[0,2.34,6.24],[1,2.18,42.05],[2,2.02,4.55]],"ltp":2.42,"tv":288.4,"id":31372}]}]}
{"op":"mcm","clk":"11836931963","pt":1723153847528,"mc":[{"id":"1.231539716","rc":[{"batb":[[0,2.36,10],[1,2.34,6.24],[2,2.18,42.05]],"ltp":2.42,"tv":288.4,"id":31372}]}]}
{"op":"mcm","clk":"11836932051","pt":1723153849939,"mc":[{"id":"1.231539716","rc":[{"batb":[[0,2.38,4],[1,2.36,10],[2,2.34,6.24]],"ltp":2.42,"tv":288.4,"id":31372}]}]}
{"op":"mcm","clk":"11836932077","pt":1723153850713,"mc":[{"id":"1.231539716","rc":[{"batb":[[1,2.34,6.24],[2,2.18,42.05]],"ltp":2.42,"tv":288.4,"id":31372}]}]}
{"op":"mcm","clk":"11836932146","pt":1723153852197,"mc":[{"id":"1.231539716","rc":[{"batb":[[0,2.34,6.24],[1,2.18,42.05],[2,2.02,4.55]],"ltp":2.42,"tv":288.4,"id":31372}]}]}
{"op":"mcm","clk":"11836932278","pt":1723153855433,"mc":[{"id":"1.231539716","rc":[{"batb":[[0,2.36,14],[1,2.34,6.24],[2,2.18,42.05]],"ltp":2.42,"tv":288.4,"id":31372}]}]}
{"op":"mcm","clk":"11836932360","pt":1723153857634,"mc":[{"id":"1.231539716","rc":[{"batb":[[0,2.36,10]],"ltp":2.42,"tv":288.4,"id":31372}]}]}
{"op":"mcm","clk":"11836932396","pt":1723153858710,"mc":[{"id":"1.231539716","rc":[{"batb":[[0,2.34,6.24],[1,2.18,42.05],[2,2.02,4.55]],"ltp":2.42,"tv":288.4,"id":31372}]}]}
{"op":"mcm","clk":"11836932502","pt":1723153861429,"mc":[{"id":"1.231539716","rc":[{"batb":[[0,2.36,14],[1,2.34,6.24],[2,2.18,42.05]],"ltp":2.42,"tv":288.4,"id":31372}]}]}
{"op":"mcm","clk":"11836932602","pt":1723153863845,"mc":[{"id":"1.231539716","rc":[{"batb":[[0,2.36,10]],"ltp":2.42,"tv":288.4,"id":31372}]}]}
{"op":"mcm","clk":"11836932635","pt":1723153864720,"mc":[{"id":"1.231539716","rc":[{"batb":[[0,2.34,6.24],[1,2.18,42.05],[2,2.02,4.55]],"ltp":2.42,"tv":288.4,"id":31372}]}]}
{"op":"mcm","clk":"11836932674","pt":1723153865947,"mc":[{"id":"1.231539716","rc":[{"batb":[[0,2.36,4],[1,2.34,6.24],[2,2.18,42.05]],"ltp":2.42,"tv":288.4,"id":31372}]}]}
{"op":"mcm","clk":"11836932749","pt":1723153867231,"mc":[{"id":"1.231539716","rc":[{"batb":[[0,2.38,10],[1,2.36,4],[2,2.34,6.24]],"ltp":2.42,"tv":288.4,"id":31372}]}]}
{"op":"mcm","clk":"11836932794","pt":1723153868153,"mc":[{"id":"1.231539716","rc":[{"batb":[[2,1.61,4.55]],"ltp":1.71,"tv":805.24,"id":5995},{"batb":[[1,2.34,6.24],[2,2.18,9.92]],"ltp":2.42,"tv":288.4,"id":31372}]}]}
{"op":"mcm","clk":"11836932895","pt":1723153870513,"mc":[{"id":"1.231539716","rc":[{"batb":[[0,2.34,6.24],[1,2.18,9.92],[2,2.02,4.55]],"ltp":2.42,"tv":288.4,"id":31372}]}]}
{"op":"mcm","clk":"11836932901","pt":1723153870622,"mc":[{"id":"1.231539716","rc":[{"batb":[[0,2.36,4],[1,2.34,6.24],[2,2.18,9.92]],"ltp":2.42,"tv":288.4,"id":31372}]}]}
{"op":"mcm","clk":"11836932989","pt":1723153873131,"mc":[{"id":"1.231539716","rc":[{"batb":[[2,1.66,53.07]],"ltp":1.71,"tv":805.24,"id":5995},{"batb":[[0,2.36,10],[2,2.18,42.05]],"ltp":2.42,"tv":288.4,"id":31372}]}]}
{"op":"mcm","clk":"11836933071","pt":1723153875443,"mc":[{"id":"1.231539716","rc":[{"batb":[[0,2.38,4],[1,2.36,10],[2,2.34,6.24]],"ltp":2.42,"tv":288.4,"id":31372}]}]}
{"op":"mcm","clk":"11836933118","pt":1723153876517,"mc":[{"id":"1.231539716","rc":[{"batb":[[1,2.34,6.24],[2,2.18,42.05]],"ltp":2.42,"tv":288.4,"id":31372}]}]}
{"op":"mcm","clk":"11836933166","pt":1723153877749,"mc":[{"id":"1.231539716","rc":[{"batb":[[0,2.34,6.24],[1,2.18,42.05],[2,2.02,4.55]],"ltp":2.42,"tv":288.4,"id":31372}]}]}
{"op":"mcm","clk":"11836933313","pt":1723153881131,"mc":[{"id":"1.231539716","rc":[{"batb":[[0,2.36,14],[1,2.34,6.24],[2,2.18,42.05]],"ltp":2.42,"tv":288.4,"id":31372}]}]}
{"op":"mcm","clk":"11836933418","pt":1723153883442,"mc":[{"id":"1.231539716","rc":[{"batb":[[0,2.36,10]],"ltp":2.42,"tv":288.4,"id":31372}]}]}
{"op":"mcm","clk":"11836933458","pt":1723153884566,"mc":[{"id":"1.231539716","rc":[{"batb":[[0,2.34,6.24],[1,2.18,42.05],[2,2.02,4.55]],"ltp":2.42,"tv":288.4,"id":31372}]}]}
{"op":"mcm","clk":"11836933494","pt":1723153885956,"mc":[{"id":"1.231539716","rc":[{"batb":[[0,2.36,4],[1,2.34,6.24],[2,2.18,42.05]],"ltp":2.42,"tv":288.4,"id":31372}]}]}
{"op":"mcm","clk":"11836933548","pt":1723153887139,"mc":[{"id":"1.231539716","rc":[{"batb":[[0,2.38,10],[1,2.36,4],[2,2.34,6.24]],"ltp":2.42,"tv":288.4,"id":31372}]}]}
{"op":"mcm","clk":"11836933591","pt":1723153888320,"mc":[{"id":"1.231539716","rc":[{"batb":[[2,1.61,4.55]],"ltp":1.71,"tv":805.24,"id":5995},{"batb":[[1,2.34,6.24],[2,2.18,9.92]],"ltp":2.42,"tv":288.4,"id":31372}]}]}
{"op":"mcm","clk":"11836933682","pt":1723153890574,"mc":[{"id":"1.231539716","rc":[{"batb":[[0,2.34,6.24],[1,2.18,9.92],[2,2.02,4.55]],"ltp":2.42,"tv":288.4,"id":31372}]}]}
{"op":"mcm","clk":"11836933691","pt":1723153890728,"mc":[{"id":"1.231539716","rc":[{"batb":[[0,2.36,4],[1,2.34,6.24],[2,2.18,9.92]],"ltp":2.42,"tv":288.4,"id":31372}]}]}
{"op":"mcm","clk":"11836933827","pt":1723153893157,"mc":[{"id":"1.231539716","rc":[{"batb":[[2,1.66,53.07]],"ltp":1.71,"tv":805.24,"id":5995},{"batb":[[0,2.36,10],[2,2.18,42.05]],"ltp":2.42,"tv":288.4,"id":31372}]}]}
{"op":"mcm","clk":"11836933925","pt":1723153895569,"mc":[{"id":"1.231539716","rc":[{"batb":[[0,2.38,4],[1,2.36,10],[2,2.34,6.24]],"ltp":2.42,"tv":288.4,"id":31372}]}]}
{"op":"mcm","clk":"11836933971","pt":1723153896647,"mc":[{"id":"1.231539716","rc":[{"batb":[[1,2.34,6.24],[2,2.18,42.05]],"ltp":2.42,"tv":288.4,"id":31372}]}]}
{"op":"mcm","clk":"11836934014","pt":1723153897876,"mc":[{"id":"1.231539716","rc":[{"batb":[[0,2.34,6.24],[1,2.18,42.05],[2,2.02,4.55]],"ltp":2.42,"tv":288.4,"id":31372}]}]}
{"op":"mcm","clk":"11836934091","pt":1723153900336,"mc":[{"id":"1.231539716","rc":[{"batb":[[0,2.36,14],[1,2.34,6.24],[2,2.18,42.05]],"ltp":2.42,"tv":288.4,"id":31372}]}]}
{"op":"mcm","clk":"11836934187","pt":1723153902747,"mc":[{"id":"1.231539716","rc":[{"batb":[[0,2.36,10]],"ltp":2.42,"tv":288.4,"id":31372}]}]}
{"op":"mcm","clk":"11836934213","pt":1723153903769,"mc":[{"id":"1.231539716","rc":[{"batb":[[0,2.34,6.24],[1,2.18,42.05],[2,2.02,4.55]],"ltp":2.42,"tv":288.4,"id":31372}]}]}
{"op":"mcm","clk":"11836934266","pt":1723153904960,"mc":[{"id":"1.231539716","rc":[{"batb":[[0,2.36,4],[1,2.34,6.24],[2,2.18,42.05]],"ltp":2.42,"tv":288.4,"id":31372}]}]}
{"op":"mcm","clk":"11836934312","pt":1723153906188,"mc":[{"id":"1.231539716","rc":[{"batb":[[0,2.38,10],[1,2.36,4],[2,2.34,6.24]],"ltp":2.42,"tv":288.4,"id":31372}]}]}
{"op":"mcm","clk":"11836934350","pt":1723153907263,"mc":[{"id":"1.231539716","rc":[{"batb":[[1,2.34,6.24],[2,2.18,42.05]],"ltp":2.42,"tv":288.4,"id":31372}]}]}
{"op":"mcm","clk":"11836934389","pt":1723153908288,"mc":[{"id":"1.231539716","rc":[{"batb":[[2,1.61,4.55]],"ltp":1.71,"tv":805.24,"id":5995},{"batb":[[2,2.18,9.92]],"ltp":2.42,"tv":288.4,"id":31372}]}]}
{"op":"mcm","clk":"11836934444","pt":1723153909570,"mc":[{"id":"1.231539716","rc":[{"batb":[[0,2.34,6.24],[1,2.18,9.92],[2,2.02,4.55]],"ltp":2.42,"tv":288.4,"id":31372}]}]}
{"op":"mcm","clk":"11836934455","pt":1723153909776,"mc":[{"id":"1.231539716","rc":[{"batb":[[0,2.36,4],[1,2.34,6.24],[2,2.18,9.92]],"ltp":2.42,"tv":288.4,"id":31372}]}]}
{"op":"mcm","clk":"11836934554","pt":1723153912188,"mc":[{"id":"1.231539716","rc":[{"batb":[[0,2.36,10]],"ltp":2.42,"tv":288.4,"id":31372}]}]}
{"op":"mcm","clk":"11836934597","pt":1723153913265,"mc":[{"id":"1.231539716","rc":[{"batb":[[2,1.66,53.07]],"ltp":1.71,"tv":805.24,"id":5995},{"batb":[[2,2.18,42.05]],"ltp":2.42,"tv":288.4,"id":31372}]}]}
{"op":"mcm","clk":"11836934690","pt":1723153915470,"mc":[{"id":"1.231539716","rc":[{"batb":[[0,2.36,4]],"ltp":2.42,"tv":288.4,"id":31372}]}]}
{"op":"mcm","clk":"11836934783","pt":1723153918393,"mc":[{"id":"1.231539716","rc":[{"batb":[[2,1.61,4.55]],"ltp":1.71,"tv":805.24,"id":5995},{"batb":[[0,2.38,10],[2,2.18,9.92]],"ltp":2.42,"tv":288.4,"id":31372}]}]}
{"op":"mcm","clk":"11836934912","pt":1723153921377,"mc":[{"id":"1.231539716","rc":[{"batb":[[0,2.4,4]],"ltp":2.42,"tv":288.4,"id":31372}]}]}
{"op":"mcm","clk":"11836935017","pt":1723153923583,"mc":[{"id":"1.231539716","rc":[{"batb":[[2,1.66,53.07]],"ltp":1.71,"tv":805.24,"id":5995},{"batb":[[0,2.34,6.24],[1,2.18,42.05],[2,2.02,4.55]],"ltp":2.42,"tv":288.4,"id":31372}]}]}
{"op":"mcm","clk":"11836935023","pt":1723153923691,"mc":[{"id":"1.231539716","rc":[{"batb":[[0,2.36,10],[1,2.34,6.24],[2,2.18,42.05]],"ltp":2.42,"tv":288.4,"id":31372}]}]}
{"op":"mcm","clk":"11836935173","pt":1723153927074,"mc":[{"id":"1.231539716","rc":[{"batb":[[0,2.36,4]],"ltp":2.42,"tv":288.4,"id":31372}]}]}
{"op":"mcm","clk":"11836935259","pt":1723153929488,"mc":[{"id":"1.231539716","rc":[{"batb":[[0,2.36,10]],"ltp":2.42,"tv":288.4,"id":31372}]}]}
{"op":"mcm","clk":"11836935367","pt":1723153932814,"mc":[{"id":"1.231539716","rc":[{"batb":[[0,2.36,4]],"ltp":2.42,"tv":288.4,"id":31372}]}]}
{"op":"mcm","clk":"11836935471","pt":1723153935284,"mc":[{"id":"1.231539716","rc":[{"batb":[[0,2.36,10]],"ltp":2.42,"tv":288.4,"id":31372}]}]}
{"op":"mcm","clk":"11836935582","pt":1723153938606,"mc":[{"id":"1.231539716","rc":[{"batb":[[0,2.38,4]],"ltp":2.42,"tv":288.4,"id":31372}]}]}
{"op":"mcm","clk":"11836935743","pt":1723153941028,"mc":[{"id":"1.231539716","rc":[{"batb":[[0,2.4,10]],"ltp":2.42,"tv":288.4,"id":31372}]}]}
{"op":"mcm","clk":"11836935918","pt":1723153943605,"mc":[{"id":"1.231539716","rc":[{"batb":[[2,1.61,4.55]],"ltp":1.71,"tv":805.24,"id":5995},{"batb":[[0,2.42,4],[1,2.4,10],[2,2.34,6.24]],"ltp":2.42,"tv":288.4,"id":31372}]}]}
{"op":"mcm","clk":"11836935962","pt":1723153944325,"mc":[{"id":"1.231539716","rc":[{"batb":[[1,2.34,6.24],[2,2.18,9.92]],"ltp":2.42,"tv":288.4,"id":31372}]}]}
{"op":"mcm","clk":"11836936049","pt":1723153945710,"mc":[{"id":"1.231539716","rc":[{"batb":[[0,2.34,6.24],[1,2.18,9.92],[2,2.02,4.55]],"ltp":2.42,"tv":288.4,"id":31372}]}]}
{"op":"mcm","clk":"11836936139","pt":1723153946894,"mc":[{"id":"1.231539716","rc":[{"batb":[[0,2.36,10],[1,2.34,6.24],[2,2.18,9.92]],"ltp":2.42,"tv":288.4,"id":31372}]}]}
{"op":"mcm","clk":"11836936246","pt":1723153948533,"mc":[{"id":"1.231539716","rc":[{"batb":[[2,1.66,53.07]],"ltp":1.71,"tv":805.24,"id":5995},{"batb":[[2,2.18,42.05]],"ltp":2.42,"tv":288.4,"id":31372}]}]}
{"op":"mcm","clk":"11836936256","pt":1723153948638,"mc":[{"id":"1.231539716","rc":[{"batb":[[0,2.38,4],[1,2.36,10],[2,2.34,6.24]],"ltp":2.42,"tv":288.4,"id":31372}]}]}
{"op":"mcm","clk":"11836936355","pt":1723153950433,"mc":[{"id":"1.231539716","rc":[{"batb":[[1,2.34,6.24],[2,2.18,42.05]],"ltp":2.42,"tv":288.4,"id":31372}]}]}
{"op":"mcm","clk":"11836936378","pt":1723153950894,"mc":[{"id":"1.231539716","rc":[{"batb":[[0,2.34,6.24],[1,2.18,42.05],[2,2.02,4.55]],"ltp":2.42,"tv":288.4,"id":31372}]}]}
{"op":"mcm","clk":"11836936504","pt":1723153954019,"mc":[{"id":"1.231539716","rc":[{"batb":[[0,2.36,14],[1,2.34,6.24],[2,2.18,42.05]],"ltp":2.42,"tv":288.4,"id":31372}]}]}
{"op":"mcm","clk":"11836936630","pt":1723153956436,"mc":[{"id":"1.231539716","rc":[{"batb":[[0,2.36,10]],"ltp":2.42,"tv":288.4,"id":31372}]}]}
{"op":"mcm","clk":"11836936671","pt":1723153957355,"mc":[{"id":"1.231539716","rc":[{"batb":[[0,2.34,6.24],[1,2.18,42.05],[2,2.02,4.55]],"ltp":2.42,"tv":288.4,"id":31372}]}]}
{"op":"mcm","clk":"11836936737","pt":1723153958640,"mc":[{"id":"1.231539716","rc":[{"batb":[[0,2.36,4],[1,2.34,6.24],[2,2.18,42.05]],"ltp":2.42,"tv":288.4,"id":31372}]}]}
{"op":"mcm","clk":"11836936819","pt":1723153959827,"mc":[{"id":"1.231539716","rc":[{"batb":[[0,2.38,10],[1,2.36,4],[2,2.34,6.24]],"ltp":2.42,"tv":288.4,"id":31372}]}]}
{"op":"mcm","clk":"11836936900","pt":1723153961037,"mc":[{"id":"1.231539716","rc":[{"batb":[[1,2.34,6.24],[2,2.18,42.05]],"ltp":2.42,"tv":288.4,"id":31372}]}]}
{"op":"mcm","clk":"11836936973","pt":1723153963145,"mc":[{"id":"1.231539716","rc":[{"batb":[[0,2.4,4]],"ltp":2.42,"tv":288.4,"id":31372}]}]}
{"op":"mcm","clk":"11836937089","pt":1723153965554,"mc":[{"id":"1.231539716","rc":[{"batb":[[0,2.42,10]],"ltp":2.42,"tv":288.4,"id":31372}]}]}
{"op":"mcm","clk":"11836937119","pt":1723153966222,"mc":[{"id":"1.231539716","rc":[{"batb":[[1,2.18,42.05],[2,2.02,4.55]],"ltp":2.42,"tv":288.4,"id":31372}]}]}
{"op":"mcm","clk":"11836937247","pt":1723153969047,"mc":[{"id":"1.231539716","rc":[{"batb":[[2,1.61,4.55]],"ltp":1.71,"tv":805.24,"id":5995},{"batb":[[0,2.2,4],[1,2.18,9.92]],"ltp":2.42,"tv":288.4,"id":31372}]}]}
{"op":"mcm","clk":"11836937273","pt":1723153969766,"mc":[{"id":"1.231539716","rc":[{"batb":[[0,2.34,5.66],[1,2.2,4],[2,2.18,9.92]],"ltp":2.42,"tv":288.4,"id":31372}]}]}
{"op":"mcm","clk":"11836937337","pt":1723153971458,"mc":[{"id":"1.231539716","rc":[{"batb":[[0,2.36,10],[1,2.34,5.66]],"ltp":2.42,"tv":288.4,"id":31372}]}]}
{"op":"mcm","clk":"11836937412","pt":1723153973761,"mc":[{"id":"1.231539716","rc":[{"batb":[[2,1.66,53.07]],"ltp":1.71,"tv":805.24,"id":5995},{"batb":[[0,2.38,4],[1,2.36,10],[2,2.34,5.66]],"ltp":2.42,"tv":288.4,"id":31372}]}]}
{"op":"mcm","clk":"11836937448","pt":1723153974733,"mc":[{"id":"1.231539716","rc":[{"batb":[[1,2.34,5.66],[2,2.18,42.05]],"ltp":2.42,"tv":288.4,"id":31372}]}]}
{"op":"mcm","clk":"11836937499","pt":1723153976070,"mc":[{"id":"1.231539716","rc":[{"batb":[[0,2.34,5.66],[1,2.18,42.05],[2,2.02,4.55]],"ltp":2.42,"tv":288.4,"id":31372}]}]}
{"op":"mcm","clk":"11836937536","pt":1723153977252,"mc":[{"id":"1.231539716","rc":[{"batb":[[0,2.36,10],[1,2.34,5.66],[2,2.18,42.05]],"ltp":2.42,"tv":288.4,"id":31372}]}]}
{"op":"mcm","clk":"11836937646","pt":1723153979460,"mc":[{"id":"1.231539716","rc":[{"batb":[[0,2.38,4],[1,2.36,10],[2,2.34,5.66]],"ltp":2.42,"tv":288.4,"id":31372}]}]}
{"op":"mcm","clk":"11836937696","pt":1723153980535,"mc":[{"id":"1.231539716","rc":[{"batb":[[1,2.34,5.66],[2,2.18,42.05]],"ltp":2.42,"tv":288.4,"id":31372}]}]}
{"op":"mcm","clk":"11836937757","pt":1723153981874,"mc":[{"id":"1.231539716","rc":[{"batb":[[0,2.34,5.66],[1,2.18,42.05],[2,2.02,4.55]],"ltp":2.42,"tv":288.4,"id":31372}]}]}
{"op":"mcm","clk":"11836937859","pt":1723153984155,"mc":[{"id":"1.231539716","rc":[{"batb":[[0,2.36,14],[1,2.34,5.66],[2,2.18,42.05]],"ltp":2.42,"tv":288.4,"id":31372}]}]}
{"op":"mcm","clk":"11836937946","pt":1723153986549,"mc":[{"id":"1.231539716","rc":[{"batb":[[0,2.36,10]],"ltp":2.42,"tv":288.4,"id":31372}]}]}
{"op":"mcm","clk":"11836937982","pt":1723153987573,"mc":[{"id":"1.231539716","rc":[{"batb":[[0,2.34,5.66],[1,2.18,42.05],[2,2.02,4.55]],"ltp":2.42,"tv":288.4,"id":31372}]}]}
{"op":"mcm","clk":"11836938085","pt":1723153989889,"mc":[{"id":"1.231539716","rc":[{"batb":[[0,2.36,14],[1,2.34,5.66],[2,2.18,42.05]],"ltp":2.42,"tv":288.4,"id":31372}]}]}
{"op":"mcm","clk":"11836938198","pt":1723153992297,"mc":[{"id":"1.231539716","rc":[{"batb":[[0,2.36,10]],"ltp":2.42,"tv":288.4,"id":31372}]}]}
{"op":"mcm","clk":"11836938221","pt":1723153993168,"mc":[{"id":"1.231539716","rc":[{"batb":[[0,2.34,5.66],[1,2.18,42.05],[2,2.02,4.55]],"ltp":2.42,"tv":288.4,"id":31372}]}]}
{"op":"mcm","clk":"11836938277","pt":1723153994702,"mc":[{"id":"1.231539716","rc":[{"batb":[[0,2.36,4],[1,2.34,5.66],[2,2.18,42.05]],"ltp":2.42,"tv":288.4,"id":31372}]}]}
{"op":"mcm","clk":"11836938368","pt":1723153997109,"mc":[{"id":"1.231539716","rc":[{"batb":[[0,2.38,10]],"ltp":2.42,"tv":288.4,"id":31372}]}]}
{"op":"mcm","clk":"11836938428","pt":1723153999006,"mc":[{"id":"1.231539716","rc":[{"batb":[[2,1.61,4.55]],"ltp":1.71,"tv":805.24,"id":5995},{"batb":[[2,2.18,9.92]],"ltp":2.42,"tv":288.4,"id":31372}]}]}
{"op":"mcm","clk":"11836938490","pt":1723154000393,"mc":[{"id":"1.231539716","rc":[{"batb":[[0,2.4,4]],"ltp":2.42,"tv":288.4,"id":31372}]}]}
{"op":"mcm","clk":"11836938589","pt":1723154003012,"mc":[{"id":"1.231539716","rc":[{"batb":[[0,2.36,10]],"ltp":2.42,"tv":288.4,"id":31372}]}]}
{"op":"mcm","clk":"11836938630","pt":1723154003885,"mc":[{"id":"1.231539716","rc":[{"batb":[[2,1.66,53.07]],"ltp":1.71,"tv":805.24,"id":5995},{"batb":[[2,2.18,42.05]],"ltp":2.42,"tv":288.4,"id":31372}]}]}
{"op":"mcm","clk":"11836938668","pt":1723154005117,"mc":[{"id":"1.231539716","rc":[{"batb":[[0,2.38,4],[1,2.36,10],[2,2.34,5.66]],"ltp":2.42,"tv":288.4,"id":31372}]}]}
{"op":"mcm","clk":"11836938712","pt":1723154006402,"mc":[{"id":"1.231539716","rc":[{"batb":[[1,2.34,5.66],[2,2.18,42.05]],"ltp":2.42,"tv":288.4,"id":31372}]}]}
{"op":"mcm","clk":"11836938748","pt":1723154007582,"mc":[{"id":"1.231539716","rc":[{"batb":[[0,2.34,5.66],[1,2.18,42.05],[2,2.02,4.55]],"ltp":2.42,"tv":288.4,"id":31372}]}]}
{"op":"mcm","clk":"11836938848","pt":1723154009993,"mc":[{"id":"1.231539716","rc":[{"batb":[[0,2.36,14],[1,2.34,5.66],[2,2.18,42.05]],"ltp":2.42,"tv":288.4,"id":31372}]}]}
{"op":"mcm","clk":"11836938933","pt":1723154012299,"mc":[{"id":"1.231539716","rc":[{"batb":[[0,2.36,10]],"ltp":2.42,"tv":288.4,"id":31372}]}]}
{"op":"mcm","clk":"11836938977","pt":1723154013427,"mc":[{"id":"1.231539716","rc":[{"batb":[[0,2.34,5.66],[1,2.18,42.05],[2,2.02,4.55]],"ltp":2.42,"tv":288.4,"id":31372}]}]}
{"op":"mcm","clk":"11836939017","pt":1723154014613,"mc":[{"id":"1.231539716","rc":[{"batb":[[0,2.36,4],[1,2.34,5.66],[2,2.18,42.05]],"ltp":2.42,"tv":288.4,"id":31372}]}]}
{"op":"mcm","clk":"11836939104","pt":1723154016489,"mc":[{"id":"1.231539716","rc":[{"batb":[[0,2.38,10],[1,2.36,4],[2,2.34,5.66]],"ltp":2.42,"tv":288.4,"id":31372}]}]}
{"op":"mcm","clk":"11836939125","pt":1723154016901,"mc":[{"id":"1.231539716","rc":[{"batb":[[1,2.34,5.66],[2,2.18,42.05]],"ltp":2.42,"tv":288.4,"id":31372}]}]}
{"op":"mcm","clk":"11836939228","pt":1723154019413,"mc":[{"id":"1.231539716","rc":[{"batb":[[2,1.61,4.55]],"ltp":1.71,"tv":805.24,"id":5995},{"batb":[[0,2.4,4],[1,2.38,10],[2,2.34,5.66]],"ltp":2.42,"tv":288.4,"id":31372}]}]}
{"op":"mcm","clk":"11836939244","pt":1723154019827,"mc":[{"id":"1.231539716","rc":[{"batb":[[1,2.34,5.66],[2,2.18,9.92]],"ltp":2.42,"tv":288.4,"id":31372}]}]}
{"op":"mcm","clk":"11836939312","pt":1723154021727,"mc":[{"id":"1.231539716","rc":[{"batb":[[0,2.34,5.66],[1,2.18,9.92],[2,2.02,4.55]],"ltp":2.42,"tv":288.4,"id":31372}]}]}
{"op":"mcm","clk":"11836939407","pt":1723154024032,"mc":[{"id":"1.231539716","rc":[{"batb":[[2,1.66,53.07]],"ltp":1.71,"tv":805.24,"id":5995},{"batb":[[0,2.38,4],[1,2.36,10],[2,2.34,5.66]],"ltp":2.42,"tv":288.4,"id":31372}]}]}
{"op":"mcm","clk":"11836939522","pt":1723154026134,"mc":[{"id":"1.231539716","rc":[{"batb":[[0,2.36,10],[1,2.34,5.66],[2,2.18,42.05]],"ltp":2.42,"tv":288.4,"id":31372}]}]}
{"op":"mcm","clk":"11836939562","pt":1723154027116,"mc":[{"id":"1.231539716","rc":[{"batb":[[0,2.34,5.66],[1,2.18,42.05],[2,2.02,4.55]],"ltp":2.42,"tv":288.4,"id":31372}]}]}
{"op":"mcm","clk":"11836939591","pt":1723154028237,"mc":[{"id":"1.231539716","rc":[{"batb":[[0,2.36,4],[1,2.34,5.66],[2,2.18,42.05]],"ltp":2.42,"tv":288.4,"id":31372}]}]}
{"op":"mcm","clk":"11836939632","pt":1723154029421,"mc":[{"id":"1.231539716","rc":[{"batb":[[0,2.38,10],[1,2.36,4],[2,2.34,5.66]],"ltp":2.42,"tv":288.4,"id":31372}]}]}
{"op":"mcm","clk":"11836939685","pt":1723154030602,"mc":[{"id":"1.231539716","rc":[{"batb":[[1,2.34,5.66],[2,2.18,42.05]],"ltp":2.42,"tv":288.4,"id":31372}]}]}
{"op":"mcm","clk":"11836939770","pt":1723154032808,"mc":[{"id":"1.231539716","rc":[{"batb":[[0,2.4,4]],"ltp":2.42,"tv":288.4,"id":31372}]}]}
{"op":"mcm","clk":"11836939875","pt":1723154035213,"mc":[{"id":"1.231539716","rc":[{"batb":[[0,2.42,10]],"ltp":2.42,"tv":288.4,"id":31372}]}]}
{"op":"mcm","clk":"11836939934","pt":1723154037110,"mc":[{"id":"1.231539716","rc":[{"batb":[[1,2.18,42.05],[2,2.02,4.55]],"ltp":2.42,"tv":288.4,"id":31372}]}]}
{"op":"mcm","clk":"11836939985","pt":1723154038544,"mc":[{"id":"1.231539716","rc":[{"batb":[[0,2.2,4]],"ltp":2.42,"tv":288.4,"id":31372}]}]}
{"op":"mcm","clk":"11836940013","pt":1723154039725,"mc":[{"id":"1.231539716","rc":[{"batb":[[0,2.34,5.66],[1,2.2,4],[2,2.18,42.05]],"ltp":2.42,"tv":288.4,"id":31372}]}]}
{"op":"mcm","clk":"11836940056","pt":1723154041008,"mc":[{"id":"1.231539716","rc":[{"batb":[[0,2.36,10],[1,2.34,5.66]],"ltp":2.42,"tv":288.4,"id":31372}]}]}
{"op":"mcm","clk":"11836940126","pt":1723154043316,"mc":[{"id":"1.231539716","rc":[{"batb":[[0,2.38,4],[1,2.36,10],[2,2.34,5.66]],"ltp":2.42,"tv":288.4,"id":31372}]}]}
{"op":"mcm","clk":"11836940161","pt":1723154044439,"mc":[{"id":"1.231539716","rc":[{"batb":[[1,2.34,5.66],[2,2.18,42.05]],"ltp":2.42,"tv":288.4,"id":31372}]}]}
{"op":"mcm","clk":"11836940200","pt":1723154045719,"mc":[{"id":"1.231539716","rc":[{"batb":[[0,2.34,5.66],[1,2.18,42.05],[2,2.02,4.55]],"ltp":2.42,"tv":288.4,"id":31372}]}]}
{"op":"mcm","clk":"11836940238","pt":1723154046846,"mc":[{"id":"1.231539716","rc":[{"batb":[[0,2.36,10],[1,2.34,5.66],[2,2.18,42.05]],"ltp":2.42,"tv":288.4,"id":31372}]}]}
{"op":"mcm","clk":"11836940281","pt":1723154048027,"mc":[{"id":"1.231539716","rc":[{"batb":[[0,2.38,4],[1,2.36,10],[2,2.34,5.66]],"ltp":2.42,"tv":288.4,"id":31372}]}]}
{"op":"mcm","clk":"11836940361","pt":1723154050333,"mc":[{"id":"1.231539716","rc":[{"batb":[[0,2.34,5.66],[1,2.18,42.05],[2,2.02,4.55]],"ltp":2.42,"tv":288.4,"id":31372}]}]}
{"op":"mcm","clk":"11836940457","pt":1723154052639,"mc":[{"id":"1.231539716","rc":[{"batb":[[0,2.36,14],[1,2.34,5.66],[2,2.18,42.05]],"ltp":2.42,"tv":288.4,"id":31372}]}]}
{"op":"mcm","clk":"11836940538","pt":1723154054946,"mc":[{"id":"1.231539716","rc":[{"batb":[[0,2.36,10]],"ltp":2.42,"tv":288.4,"id":31372}]}]}
{"op":"mcm","clk":"11836940577","pt":1723154056027,"mc":[{"id":"1.231539716","rc":[{"batb":[[0,2.34,5.66],[1,2.18,42.05],[2,2.02,4.55]],"ltp":2.42,"tv":288.4,"id":31372}]}]}
{"op":"mcm","clk":"11836940621","pt":1723154057252,"mc":[{"id":"1.231539716","rc":[{"batb":[[0,2.36,4],[1,2.34,5.66],[2,2.18,42.05]],"ltp":2.42,"tv":288.4,"id":31372}]}]}
{"op":"mcm","clk":"11836940706","pt":1723154059559,"mc":[{"id":"1.231539716","rc":[{"batb":[[0,2.38,10]],"ltp":2.42,"tv":288.4,"id":31372}]}]}
{"op":"mcm","clk":"11836940797","pt":1723154061661,"mc":[{"id":"1.231539716","rc":[{"batb":[[0,2.4,4],[1,2.38,10],[2,2.34,5.66]],"ltp":2.42,"tv":288.4,"id":31372}]}]}
{"op":"mcm","clk":"11836940849","pt":1723154062740,"mc":[{"id":"1.231539716","rc":[{"batb":[[1,2.34,5.66],[2,2.18,42.05]],"ltp":2.42,"tv":288.4,"id":31372}]}]}
{"op":"mcm","clk":"11836940884","pt":1723154063967,"mc":[{"id":"1.231539716","rc":[{"batb":[[0,2.34,5.66],[1,2.18,42.05],[2,2.02,4.55]],"ltp":2.42,"tv":288.4,"id":31372}]}]}
{"op":"mcm","clk":"11836940983","pt":1723154066477,"mc":[{"id":"1.231539716","rc":[{"batb":[[0,2.36,14],[1,2.34,5.66],[2,2.18,42.05]],"ltp":2.42,"tv":288.4,"id":31372}]}]}
{"op":"mcm","clk":"11836941072","pt":1723154068730,"mc":[{"id":"1.231539716","rc":[{"batb":[[0,2.36,10]],"ltp":2.42,"tv":288.4,"id":31372}]}]}
{"op":"mcm","clk":"11836941106","pt":1723154069655,"mc":[{"id":"1.231539716","rc":[{"batb":[[0,2.34,5.66],[1,2.18,42.05],[2,2.02,4.55]],"ltp":2.42,"tv":288.4,"id":31372}]}]}
{"op":"mcm","clk":"11836941165","pt":1723154071071,"mc":[{"id":"1.231539716","rc":[{"batb":[[0,2.36,4],[1,2.34,5.66],[2,2.18,42.05]],"ltp":2.42,"tv":288.4,"id":31372}]}]}
{"op":"mcm","clk":"11836941266","pt":1723154073435,"mc":[{"id":"1.231539716","rc":[{"batb":[[0,2.38,10]],"ltp":2.42,"tv":288.4,"id":31372}]}]}
{"op":"mcm","clk":"11836941298","pt":1723154074354,"mc":[{"id":"1.231539716","rc":[{"batb":[[2,1.61,4.55]],"ltp":1.71,"tv":805.24,"id":5995},{"batb":[[2,2.18,9.92]],"ltp":2.42,"tv":288.4,"id":31372}]}]}
{"op":"mcm","clk":"11836941335","pt":1723154075582,"mc":[{"id":"1.231539716","rc":[{"batb":[[0,2.4,4],[1,2.38,10],[2,2.34,5.66]],"ltp":2.42,"tv":288.4,"id":31372}]}]}
{"op":"mcm","clk":"11836941381","pt":1723154076659,"mc":[{"id":"1.231539716","rc":[{"batb":[[1,2.34,5.66],[2,2.18,9.92]],"ltp":2.42,"tv":288.4,"id":31372}]}]}
{"op":"mcm","clk":"11836941436","pt":1723154077940,"mc":[{"id":"1.231539716","rc":[{"batb":[[0,2.34,5.66],[1,2.18,9.92],[2,2.02,4.55]],"ltp":2.42,"tv":288.4,"id":31372}]}]}
{"op":"mcm","clk":"11836941496","pt":1723154079377,"mc":[{"id":"1.231539716","rc":[{"batb":[[2,1.66,53.07]],"ltp":1.71,"tv":805.24,"id":5995},{"batb":[[0,2.36,10],[1,2.34,5.66],[2,2.18,42.05]],"ltp":2.42,"tv":288.4,"id":31372}]}]}
{"op":"mcm","clk":"11836941621","pt":1723154082654,"mc":[{"id":"1.231539716","rc":[{"batb":[[0,2.38,4]],"ltp":2.42,"tv":288.4,"id":31372}]}]}
{"op":"mcm","clk":"11836941698","pt":1723154084967,"mc":[{"id":"1.231539716","rc":[{"batb":[[0,2.4,10]],"ltp":2.42,"tv":288.4,"id":31372}]}]}
{"op":"mcm","clk":"11836941809","pt":1723154088389,"mc":[{"id":"1.231539716","rc":[{"batb":[[0,2.42,4]],"ltp":2.42,"tv":288.4,"id":31372}]}]}
{"op":"mcm","clk":"11836941929","pt":1723154090900,"mc":[{"id":"1.231539716","rc":[{"batb":[[0,2.36,10]],"ltp":2.42,"tv":288.4,"id":31372}]}]}
{"op":"mcm","clk":"11836942054","pt":1723154094181,"mc":[{"id":"1.231539716","rc":[{"batb":[[0,2.36,4]],"ltp":2.42,"tv":288.4,"id":31372}]}]}
{"op":"mcm","clk":"11836942145","pt":1723154096582,"mc":[{"id":"1.231539716","rc":[{"batb":[[0,2.36,10]],"ltp":2.42,"tv":288.4,"id":31372}]}]}
{"op":"mcm","clk":"11836942233","pt":1723154099087,"mc":[{"id":"1.231539716","rc":[{"batb":[[0,2.38,4],[1,2.36,10],[2,2.34,5.66]],"ltp":2.42,"tv":288.4,"id":31372}]}]}
{"op":"mcm","clk":"11836942262","pt":1723154099909,"mc":[{"id":"1.231539716","rc":[{"batb":[[1,2.34,5.66],[2,2.18,42.05]],"ltp":2.42,"tv":288.4,"id":31372}]}]}
{"op":"mcm","clk":"11836942315","pt":1723154101391,"mc":[{"id":"1.231539716","rc":[{"batb":[[0,2.34,5.66],[1,2.18,42.05],[2,2.02,4.55]],"ltp":2.42,"tv":288.4,"id":31372}]}]}
{"op":"mcm","clk":"11836942396","pt":1723154103800,"mc":[{"id":"1.231539716","rc":[{"batb":[[0,2.36,14],[1,2.34,5.66],[2,2.18,42.05]],"ltp":2.42,"tv":288.4,"id":31372}]}]}
{"op":"mcm","clk":"11836942496","pt":1723154106005,"mc":[{"id":"1.231539716","rc":[{"batb":[[0,2.36,10]],"ltp":2.42,"tv":288.4,"id":31372}]}]}
{"op":"mcm","clk":"11836942543","pt":1723154107078,"mc":[{"id":"1.231539716","rc":[{"batb":[[0,2.34,5.66],[1,2.18,42.05],[2,2.02,4.55]],"ltp":2.42,"tv":288.4,"id":31372}]}]}
{"op":"mcm","clk":"11836942592","pt":1723154108308,"mc":[{"id":"1.231539716","rc":[{"batb":[[0,2.36,4],[1,2.34,5.66],[2,2.18,42.05]],"ltp":2.42,"tv":288.4,"id":31372}]}]}
{"op":"mcm","clk":"11836942664","pt":1723154109998,"mc":[{"id":"1.231539716","rc":[{"batb":[[0,2.38,10],[1,2.36,4],[2,2.34,5.66]],"ltp":2.42,"tv":288.4,"id":31372}]}]}
{"op":"mcm","clk":"11836942680","pt":1723154110815,"mc":[{"id":"1.231539716","rc":[{"batb":[[1,2.34,5.66],[2,2.18,42.05]],"ltp":2.42,"tv":288.4,"id":31372}]}]}
{"op":"mcm","clk":"11836942764","pt":1723154113424,"mc":[{"id":"1.231539716","rc":[{"batb":[[0,2.36,4]],"ltp":2.42,"tv":288.4,"id":31372}]}]}
{"op":"mcm","clk":"11836942847","pt":1723154115883,"mc":[{"id":"1.231539716","rc":[{"batb":[[0,2.36,10]],"ltp":2.42,"tv":288.4,"id":31372}]}]}
{"op":"mcm","clk":"11836942925","pt":1723154118091,"mc":[{"id":"1.231539716","rc":[{"batb":[[0,2.38,4],[1,2.36,10],[2,2.34,5.66]],"ltp":2.42,"tv":288.4,"id":31372}]}]}
{"op":"mcm","clk":"11836942983","pt":1723154119220,"mc":[{"id":"1.231539716","rc":[{"batb":[[1,2.34,5.66],[2,2.18,42.05]],"ltp":2.42,"tv":288.4,"id":31372}]}]}
{"op":"mcm","clk":"11836943030","pt":1723154120604,"mc":[{"id":"1.231539716","rc":[{"batb":[[0,2.34,5.66],[1,2.18,42.05],[2,2.02,4.55]],"ltp":2.42,"tv":288.4,"id":31372}]}]}
{"op":"mcm","clk":"11836943123","pt":1723154122911,"mc":[{"id":"1.231539716","rc":[{"batb":[[0,2.38,4],[1,2.36,10],[2,2.34,5.66]],"ltp":2.42,"tv":288.4,"id":31372}]}]}
{"op":"mcm","clk":"11836943204","pt":1723154125225,"mc":[{"id":"1.231539716","rc":[{"batb":[[0,2.36,10],[1,2.34,5.66],[2,2.18,42.05]],"ltp":2.42,"tv":288.4,"id":31372}]}]}
{"op":"mcm","clk":"11836943236","pt":1723154125895,"mc":[{"id":"1.231539716","rc":[{"batb":[[0,2.34,5.66],[1,2.18,42.05],[2,2.02,4.55]],"ltp":2.42,"tv":288.4,"id":31372}]}]}
{"op":"mcm","clk":"11836943337","pt":1723154129530,"mc":[{"id":"1.231539716","rc":[{"batb":[[0,2.36,14],[1,2.34,5.66],[2,2.18,42.05]],"ltp":2.42,"tv":288.4,"id":31372}]}]}
{"op":"mcm","clk":"11836943409","pt":1723154131835,"mc":[{"id":"1.231539716","rc":[{"batb":[[0,2.36,10]],"ltp":2.42,"tv":288.4,"id":31372}]}]}
{"op":"mcm","clk":"11836943438","pt":1723154132910,"mc":[{"id":"1.231539716","rc":[{"batb":[[0,2.34,5.66],[1,2.18,42.05],[2,2.02,4.55]],"ltp":2.42,"tv":288.4,"id":31372}]}]}
{"op":"mcm","clk":"11836943476","pt":1723154134144,"mc":[{"id":"1.231539716","rc":[{"batb":[[0,2.36,4],[1,2.34,5.66],[2,2.18,42.05]],"ltp":2.42,"tv":288.4,"id":31372}]}]}
{"op":"mcm","clk":"11836943517","pt":1723154135420,"mc":[{"id":"1.231539716","rc":[{"batb":[[0,2.38,10],[1,2.36,4],[2,2.34,5.66]],"ltp":2.42,"tv":288.4,"id":31372}]}]}
{"op":"mcm","clk":"11836943548","pt":1723154136545,"mc":[{"id":"1.231539716","rc":[{"batb":[[1,2.34,5.66],[2,2.18,42.05]],"ltp":2.42,"tv":288.4,"id":31372}]}]}
{"op":"mcm","clk":"11836943624","pt":1723154138747,"mc":[{"id":"1.231539716","rc":[{"batb":[[0,2.4,4]],"ltp":2.42,"tv":288.4,"id":31372}]}]}
{"op":"mcm","clk":"11836943731","pt":1723154141150,"mc":[{"id":"1.231539716","rc":[{"batb":[[0,2.42,10]],"ltp":2.42,"tv":288.4,"id":31372}]}]}
{"op":"mcm","clk":"11836943817","pt":1723154143047,"mc":[{"id":"1.231539716","rc":[{"batb":[[1,2.18,42.05],[2,2.02,4.55]],"ltp":2.42,"tv":288.4,"id":31372}]}]}
{"op":"mcm","clk":"11836943874","pt":1723154144535,"mc":[{"id":"1.231539716","rc":[{"batb":[[0,2.18,42.05],[1,2.02,4.55],[2,1.8,2]],"ltp":2.42,"tv":288.4,"id":31372}]}]}
{"op":"mcm","clk":"11836943904","pt":1723154145216,"mc":[{"id":"1.231539716","rc":[{"batb":[[0,2.34,5.66],[1,2.2,4],[2,2.18,42.05]],"ltp":2.42,"tv":288.4,"id":31372}]}]}
{"op":"mcm","clk":"11836943990","pt":1723154146956,"mc":[{"id":"1.231539716","rc":[{"batb":[[0,2.36,10],[1,2.34,5.66]],"ltp":2.42,"tv":288.4,"id":31372}]}]}
{"op":"mcm","clk":"11836944139","pt":1723154150341,"mc":[{"id":"1.231539716","rc":[{"batb":[[0,2.36,4]],"ltp":2.42,"tv":288.4,"id":31372}]}]}
{"op":"mcm","clk":"11836944264","pt":1723154153056,"mc":[{"id":"1.231539716","rc":[{"batb":[[0,2.36,10]],"ltp":2.42,"tv":288.4,"id":31372}]}]}
{"op":"mcm","clk":"11836944347","pt":1723154155256,"mc":[{"id":"1.231539716","rc":[{"batb":[[0,2.38,4],[1,2.36,10],[2,2.34,5.66]],"ltp":2.42,"tv":288.4,"id":31372}]}]}
{"op":"mcm","clk":"11836944384","pt":1723154156235,"mc":[{"id":"1.231539716","rc":[{"batb":[[1,2.34,5.66],[2,2.18,42.05]],"ltp":2.42,"tv":288.4,"id":31372}]}]}
{"op":"mcm","clk":"11836944427","pt":1723154157661,"mc":[{"id":"1.231539716","rc":[{"batb":[[0,2.34,5.66],[1,2.18,42.05],[2,2.02,4.55]],"ltp":2.42,"tv":288.4,"id":31372}]}]}
{"op":"mcm","clk":"11836944542","pt":1723154159866,"mc":[{"id":"1.231539716","rc":[{"batb":[[0,2.36,14],[1,2.34,5.66],[2,2.18,42.05]],"ltp":2.42,"tv":288.4,"id":31372}]}]}
{"op":"mcm","clk":"11836944620","pt":1723154162278,"mc":[{"id":"1.231539716","rc":[{"batb":[[0,2.36,10]],"ltp":2.42,"tv":288.4,"id":31372}]}]}
{"op":"mcm","clk":"11836944642","pt":1723154163148,"mc":[{"id":"1.231539716","rc":[{"batb":[[0,2.34,5.66],[1,2.18,42.05],[2,2.02,4.55]],"ltp":2.42,"tv":288.4,"id":31372}]}]}
{"op":"mcm","clk":"11836944740","pt":1723154165763,"mc":[{"id":"1.231539716","rc":[{"batb":[[0,2.36,14],[1,2.34,5.66],[2,2.18,42.05]],"ltp":2.42,"tv":288.4,"id":31372}]}]}
{"op":"mcm","clk":"11836944818","pt":1723154168081,"mc":[{"id":"1.231539716","rc":[{"batb":[[0,2.36,10]],"ltp":2.42,"tv":288.4,"id":31372}]}]}
{"op":"mcm","clk":"11836944856","pt":1723154168954,"mc":[{"id":"1.231539716","rc":[{"batb":[[0,2.34,5.66],[1,2.18,42.05],[2,2.02,4.55]],"ltp":2.42,"tv":288.4,"id":31372}]}]}
{"op":"mcm","clk":"11836944906","pt":1723154170392,"mc":[{"id":"1.231539716","rc":[{"batb":[[0,2.36,4],[1,2.34,5.66],[2,2.18,42.05]],"ltp":2.42,"tv":288.4,"id":31372}]}]}
{"op":"mcm","clk":"11836944962","pt":1723154171571,"mc":[{"id":"1.231539716","rc":[{"batb":[[0,2.38,10],[1,2.36,4],[2,2.34,5.66]],"ltp":2.42,"tv":288.4,"id":31372}]}]}
{"op":"mcm","clk":"11836945003","pt":1723154172751,"mc":[{"id":"1.231539716","rc":[{"batb":[[1,2.34,5.66],[2,2.18,42.05]],"ltp":2.42,"tv":288.4,"id":31372}]}]}
{"op":"mcm","clk":"11836945101","pt":1723154175157,"mc":[{"id":"1.231539716","rc":[{"batb":[[2,1.61,4.55]],"ltp":1.71,"tv":805.24,"id":5995},{"batb":[[0,2.36,4],[2,2.18,9.92]],"ltp":2.42,"tv":288.4,"id":31372}]}]}
{"op":"mcm","clk":"11836945182","pt":1723154177368,"mc":[{"id":"1.231539716","rc":[{"batb":[[0,2.38,10]],"ltp":2.42,"tv":288.4,"id":31372}]}]}
{"op":"mcm","clk":"11836945326","pt":1723154180591,"mc":[{"id":"1.231539716","rc":[{"batb":[[0,2.34,5.66],[1,2.18,9.92],[2,2.02,4.55]],"ltp":2.42,"tv":288.4,"id":31372}]}]}
{"op":"mcm","clk":"11836945332","pt":1723154180693,"mc":[{"id":"1.231539716","rc":[{"batb":[[0,2.36,4],[1,2.34,5.66],[2,2.18,9.92]],"ltp":2.42,"tv":288.4,"id":31372}]}]}
{"op":"mcm","clk":"11836945438","pt":1723154182950,"mc":[{"id":"1.231539716","rc":[{"batb":[[0,2.36,10]],"ltp":2.42,"tv":288.4,"id":31372}]}]}
{"op":"mcm","clk":"11836945512","pt":1723154184895,"mc":[{"id":"1.231539716","rc":[{"batb":[[2,1.66,53.07]],"ltp":1.71,"tv":805.24,"id":5995},{"batb":[[2,2.18,42.05]],"ltp":2.42,"tv":288.4,"id":31372}]}]}
{"op":"mcm","clk":"11836945568","pt":1723154186177,"mc":[{"id":"1.231539716","rc":[{"batb":[[0,2.38,4]],"ltp":2.42,"tv":288.4,"id":31372}]}]}
{"op":"mcm","clk":"11836945662","pt":1723154188583,"mc":[{"id":"1.231539716","rc":[{"batb":[[0,2.36,10]],"ltp":2.42,"tv":288.4,"id":31372}]}]}
{"op":"mcm","clk":"11836945757","pt":1723154191089,"mc":[{"id":"1.231539716","rc":[{"batb":[[0,2.38,4],[1,2.36,10],[2,2.34,5.66]],"ltp":2.42,"tv":288.4,"id":31372}]}]}
{"op":"mcm","clk":"11836945790","pt":1723154191807,"mc":[{"id":"1.231539716","rc":[{"batb":[[1,2.34,5.66],[2,2.18,42.05]],"ltp":2.42,"tv":288.4,"id":31372}]}]}
{"op":"mcm","clk":"11836945866","pt":1723154193296,"mc":[{"id":"1.231539716","rc":[{"batb":[[0,2.34,5.66],[1,2.18,42.05],[2,2.02,4.55]],"ltp":2.42,"tv":288.4,"id":31372}]}]}
{"op":"mcm","clk":"11836945959","pt":1723154195497,"mc":[{"id":"1.231539716","rc":[{"batb":[[0,2.38,4],[1,2.36,10],[2,2.34,5.66]],"ltp":2.42,"tv":288.4,"id":31372}]}]}
{"op":"mcm","clk":"11836946075","pt":1723154197703,"mc":[{"id":"1.231539716","rc":[{"batb":[[0,2.36,10],[1,2.34,5.66],[2,2.18,42.05]],"ltp":2.42,"tv":288.4,"id":31372}]}]}
{"op":"mcm","clk":"11836946117","pt":1723154198682,"mc":[{"id":"1.231539716","rc":[{"batb":[[0,2.34,5.66],[1,2.18,42.05],[2,2.02,4.55]],"ltp":2.42,"tv":288.4,"id":31372}]}]}
{"op":"mcm","clk":"11836946219","pt":1723154201400,"mc":[{"id":"1.231539716","rc":[{"batb":[[0,2.36,14],[1,2.34,5.66],[2,2.18,42.05]],"ltp":2.42,"tv":288.4,"id":31372}]}]}
{"op":"mcm","clk":"11836946330","pt":1723154203912,"mc":[{"id":"1.231539716","rc":[{"batb":[[0,2.36,10]],"ltp":2.42,"tv":288.4,"id":31372}]}]}
{"op":"mcm","clk":"11836946361","pt":1723154204683,"mc":[{"id":"1.231539716","rc":[{"batb":[[0,2.34,5.66],[1,2.18,42.05],[2,2.02,4.55]],"ltp":2.42,"tv":288.4,"id":31372}]}]}
{"op":"mcm","clk":"11836946440","pt":1723154207192,"mc":[{"id":"1.231539716","rc":[{"batb":[[0,2.36,14],[1,2.34,5.66],[2,2.18,42.05]],"ltp":2.42,"tv":288.4,"id":31372}]}]}
{"op":"mcm","clk":"11836946539","pt":1723154209601,"mc":[{"id":"1.231539716","rc":[{"batb":[[0,2.36,10]],"ltp":2.42,"tv":288.4,"id":31372}]}]}
{"op":"mcm","clk":"11836946578","pt":1723154210418,"mc":[{"id":"1.231539716","rc":[{"batb":[[0,2.34,5.66],[1,2.18,42.05],[2,2.02,4.55]],"ltp":2.42,"tv":288.4,"id":31372}]}]}
{"op":"mcm","clk":"11836946639","pt":1723154212008,"mc":[{"id":"1.231539716","rc":[{"batb":[[0,2.36,4],[1,2.34,5.66],[2,2.18,42.05]],"ltp":2.42,"tv":288.4,"id":31372}]}]}
{"op":"mcm","clk":"11836946717","pt":1723154214312,"mc":[{"id":"1.231539716","rc":[{"batb":[[0,2.38,10]],"ltp":2.42,"tv":288.4,"id":31372}]}]}
{"op":"mcm","clk":"11836946761","pt":1723154215031,"mc":[{"id":"1.231539716","rc":[{"batb":[[2,1.61,4.55]],"ltp":1.71,"tv":805.24,"id":5995},{"batb":[[2,2.18,9.92]],"ltp":2.42,"tv":288.4,"id":31372}]}]}
{"op":"mcm","clk":"11836946868","pt":1723154217640,"mc":[{"id":"1.231539716","rc":[{"batb":[[0,2.4,4]],"ltp":2.42,"tv":288.4,"id":31372}]}]}
{"op":"mcm","clk":"11836946981","pt":1723154220106,"mc":[{"id":"1.231539716","rc":[{"batb":[[2,1.66,53.07]],"ltp":1.71,"tv":805.24,"id":5995},{"batb":[[0,2.36,10],[2,2.18,42.05]],"ltp":2.42,"tv":288.4,"id":31372}]}]}
{"op":"mcm","clk":"11836947128","pt":1723154223342,"mc":[{"id":"1.231539716","rc":[{"batb":[[0,2.38,4]],"ltp":2.42,"tv":288.4,"id":31372}]}]}
{"op":"mcm","clk":"11836947192","pt":1723154225138,"mc":[{"id":"1.231539716","rc":[{"batb":[[0,2.34,5.66],[1,2.18,42.05],[2,2.02,4.55]],"ltp":2.42,"tv":288.4,"id":31372}]}]}
{"op":"mcm","clk":"11836947236","pt":1723154226223,"mc":[{"id":"1.231539716","rc":[{"batb":[[0,2.36,10],[1,2.34,5.66],[2,2.18,42.05]],"ltp":2.42,"tv":288.4,"id":31372}]}]}
{"op":"mcm","clk":"11836947298","pt":1723154227410,"mc":[{"id":"1.231539716","rc":[{"batb":[[0,2.38,4],[1,2.36,10],[2,2.34,5.66]],"ltp":2.42,"tv":288.4,"id":31372}]}]}
{"op":"mcm","clk":"11836947376","pt":1723154229668,"mc":[{"id":"1.231539716","rc":[{"batb":[[0,2.34,5.66],[1,2.18,42.05],[2,2.02,4.55]],"ltp":2.42,"tv":288.4,"id":31372}]}]}
{"op":"mcm","clk":"11836947474","pt":1723154232132,"mc":[{"id":"1.231539716","rc":[{"batb":[[0,2.36,14],[1,2.34,5.66],[2,2.18,42.05]],"ltp":2.42,"tv":288.4,"id":31372}]}]}
{"op":"mcm","clk":"11836947551","pt":1723154234443,"mc":[{"id":"1.231539716","rc":[{"batb":[[0,2.36,10]],"ltp":2.42,"tv":288.4,"id":31372}]}]}
{"op":"mcm","clk":"11836947580","pt":1723154235467,"mc":[{"id":"1.231539716","rc":[{"batb":[[0,2.34,5.66],[1,2.18,42.05],[2,2.02,4.55]],"ltp":2.42,"tv":288.4,"id":31372}]}]}
{"op":"mcm","clk":"11836947628","pt":1723154236748,"mc":[{"id":"1.231539716","rc":[{"batb":[[0,2.36,4],[1,2.34,5.66],[2,2.18,42.05]],"ltp":2.42,"tv":288.4,"id":31372}]}]}
{"op":"mcm","clk":"11836947676","pt":1723154237824,"mc":[{"id":"1.231539716","rc":[{"batb":[[0,2.38,10],[1,2.36,4],[2,2.34,5.66]],"ltp":2.42,"tv":288.4,"id":31372}]}]}
{"op":"mcm","clk":"11836947705","pt":1723154239053,"mc":[{"id":"1.231539716","rc":[{"batb":[[1,2.34,5.66],[2,2.18,42.05]],"ltp":2.42,"tv":288.4,"id":31372}]}]}
{"op":"mcm","clk":"11836947757","pt":1723154240333,"mc":[{"id":"1.231539716","rc":[{"batb":[[2,1.61,4.55]],"ltp":1.71,"tv":805.24,"id":5995},{"batb":[[2,2.18,9.92]],"ltp":2.42,"tv":288.4,"id":31372}]}]}
{"op":"mcm","clk":"11836947805","pt":1723154241458,"mc":[{"id":"1.231539716","rc":[{"batb":[[0,2.4,4]],"ltp":2.42,"tv":288.4,"id":31372}]}]}
{"op":"mcm","clk":"11836947903","pt":1723154243456,"mc":[{"id":"1.231539716","rc":[{"batb":[[0,2.42,10],[1,2.4,4],[2,2.34,5.66]],"ltp":2.42,"tv":288.4,"id":31372}]}]}
{"op":"mcm","clk":"11836947908","pt":1723154243763,"mc":[{"id":"1.231539716","rc":[{"batb":[[1,2.34,5.66],[2,2.18,9.92]],"ltp":2.42,"tv":288.4,"id":31372}]}]}
{"op":"mcm","clk":"11836947980","pt":1723154245555,"mc":[{"id":"1.231539716","rc":[{"batb":[[1,2.18,9.92],[2,2.02,4.55]],"ltp":2.42,"tv":288.4,"id":31372}]}]}
{"op":"mcm","clk":"11836948045","pt":1723154247451,"mc":[{"id":"1.231539716","rc":[{"batb":[[0,2.34,5.66],[1,2.2,4],[2,2.18,9.92]],"ltp":2.42,"tv":288.4,"id":31372}]}]}
{"op":"mcm","clk":"11836948104","pt":1723154249247,"mc":[{"id":"1.231539716","rc":[{"batb":[[0,2.36,10],[1,2.34,5.66]],"ltp":2.42,"tv":288.4,"id":31372}]}]}
{"op":"mcm","clk":"11836948145","pt":1723154250372,"mc":[{"id":"1.231539716","rc":[{"batb":[[2,1.66,53.07]],"ltp":1.71,"tv":805.24,"id":5995},{"batb":[[2,2.18,42.05]],"ltp":2.42,"tv":288.4,"id":31372}]}]}
{"op":"mcm","clk":"11836948198","pt":1723154251550,"mc":[{"id":"1.231539716","rc":[{"batb":[[0,2.38,4],[1,2.36,10],[2,2.34,5.66]],"ltp":2.42,"tv":288.4,"id":31372}]}]}
{"op":"mcm","clk":"11836948239","pt":1723154252471,"mc":[{"id":"1.231539716","rc":[{"batb":[[1,2.34,5.66],[2,2.18,42.05]],"ltp":2.42,"tv":288.4,"id":31372}]}]}
{"op":"mcm","clk":"11836948286","pt":1723154253854,"mc":[{"id":"1.231539716","rc":[{"batb":[[0,2.34,5.66],[1,2.18,42.05],[2,2.02,4.55]],"ltp":2.42,"tv":288.4,"id":31372}]}]}
{"op":"mcm","clk":"11836948334","pt":1723154255239,"mc":[{"id":"1.231539716","rc":[{"batb":[[0,2.36,10],[1,2.34,5.66],[2,2.18,42.05]],"ltp":2.42,"tv":288.4,"id":31372}]}]}
{"op":"mcm","clk":"11836948391","pt":1723154256470,"mc":[{"id":"1.231539716","rc":[{"batb":[[0,2.38,4],[1,2.36,10],[2,2.34,5.66]],"ltp":2.42,"tv":288.4,"id":31372}]}]}
{"op":"mcm","clk":"11836948472","pt":1723154258575,"mc":[{"id":"1.231539716","rc":[{"batb":[[1,2.34,5.66],[2,2.18,42.05]],"ltp":2.42,"tv":288.4,"id":31372}]}]}
{"op":"mcm","clk":"11836948480","pt":1723154258781,"mc":[{"id":"1.231539716","rc":[{"batb":[[0,2.34,5.66],[1,2.18,42.05],[2,2.02,4.55]],"ltp":2.42,"tv":288.4,"id":31372}]}]}
{"op":"mcm","clk":"11836948553","pt":1723154261191,"mc":[{"id":"1.231539716","rc":[{"batb":[[0,2.36,14],[1,2.34,5.66],[2,2.18,42.05]],"ltp":2.42,"tv":288.4,"id":31372}]}]}
{"op":"mcm","clk":"11836948619","pt":1723154263395,"mc":[{"id":"1.231539716","rc":[{"batb":[[0,2.36,10]],"ltp":2.42,"tv":288.4,"id":31372}]}]}
{"op":"mcm","clk":"11836948659","pt":1723154264469,"mc":[{"id":"1.231539716","rc":[{"batb":[[0,2.34,5.66],[1,2.18,42.05],[2,2.02,4.55]],"ltp":2.42,"tv":288.4,"id":31372}]}]}
{"op":"mcm","clk":"11836948695","pt":1723154265593,"mc":[{"id":"1.231539716","rc":[{"batb":[[0,2.36,4],[1,2.34,5.66],[2,2.18,42.05]],"ltp":2.42,"tv":288.4,"id":31372}]}]}
{"op":"mcm","clk":"11836948740","pt":1723154266877,"mc":[{"id":"1.231539716","rc":[{"batb":[[0,2.38,10],[1,2.36,4],[2,2.34,5.66]],"ltp":2.42,"tv":288.4,"id":31372}]}]}
{"op":"mcm","clk":"11836948768","pt":1723154267798,"mc":[{"id":"1.231539716","rc":[{"batb":[[1,2.34,5.66],[2,2.18,42.05]],"ltp":2.42,"tv":288.4,"id":31372}]}]}
{"op":"mcm","clk":"11836948849","pt":1723154270360,"mc":[{"id":"1.231539716","rc":[{"batb":[[0,2.36,4]],"ltp":2.42,"tv":288.4,"id":31372}]}]}
{"op":"mcm","clk":"11836948933","pt":1723154272564,"mc":[{"id":"1.231539716","rc":[{"batb":[[0,2.34,5.66],[1,2.18,42.05],[2,2.02,4.55]],"ltp":2.42,"tv":288.4,"id":31372}]}]}
{"op":"mcm","clk":"11836948941","pt":1723154272768,"mc":[{"id":"1.231539716","rc":[{"batb":[[0,2.36,10],[1,2.34,5.66],[2,2.18,42.05]],"ltp":2.42,"tv":288.4,"id":31372}]}]}
{"op":"mcm","clk":"11836949016","pt":1723154275177,"mc":[{"id":"1.231539716","rc":[{"batb":[[0,2.38,4],[1,2.36,10],[2,2.34,5.66]],"ltp":2.42,"tv":288.4,"id":31372}]}]}
{"op":"mcm","clk":"11836949042","pt":1723154276202,"mc":[{"id":"1.231539716","rc":[{"batb":[[1,2.34,5.66],[2,2.18,42.05]],"ltp":2.42,"tv":288.4,"id":31372}]}]}
{"op":"mcm","clk":"11836949100","pt":1723154277488,"mc":[{"id":"1.231539716","rc":[{"batb":[[0,2.34,5.66],[1,2.18,42.05],[2,2.02,4.55]],"ltp":2.42,"tv":288.4,"id":31372}]}]}
{"op":"mcm","clk":"11836949229","pt":1723154280869,"mc":[{"id":"1.231539716","rc":[{"batb":[[0,2.36,14],[1,2.34,5.66],[2,2.18,42.05]],"ltp":2.42,"tv":288.4,"id":31372}]}]}
{"op":"mcm","clk":"11836949299","pt":1723154283279,"mc":[{"id":"1.231539716","rc":[{"batb":[[0,2.36,10]],"ltp":2.42,"tv":288.4,"id":31372}]}]}
{"op":"mcm","clk":"11836949337","pt":1723154284304,"mc":[{"id":"1.231539716","rc":[{"batb":[[0,2.34,5.66],[1,2.18,42.05],[2,2.02,4.55]],"ltp":2.42,"tv":288.4,"id":31372}]}]}
{"op":"mcm","clk":"11836949387","pt":1723154285585,"mc":[{"id":"1.231539716","rc":[{"batb":[[0,2.36,4],[1,2.34,5.66],[2,2.18,42.05]],"ltp":2.42,"tv":288.4,"id":31372}]}]}
{"op":"mcm","clk":"11836949493","pt":1723154287990,"mc":[{"id":"1.231539716","rc":[{"batb":[[0,2.38,10]],"ltp":2.42,"tv":288.4,"id":31372}]}]}
{"op":"mcm","clk":"11836949625","pt":1723154291277,"mc":[{"id":"1.231539716","rc":[{"batb":[[2,1.61,4.55]],"ltp":1.71,"tv":805.24,"id":5995},{"batb":[[0,2.4,4],[2,2.18,9.92]],"ltp":2.42,"tv":288.4,"id":31372}]}]}
{"op":"mcm","clk":"11836949702","pt":1723154293222,"mc":[{"id":"1.231539716","rc":[{"batb":[[0,2.34,5.66],[1,2.18,9.92],[2,2.02,4.55]],"ltp":2.42,"tv":288.4,"id":31372}]}]}
{"op":"mcm","clk":"11836949751","pt":1723154294403,"mc":[{"id":"1.231539716","rc":[{"batb":[[0,2.36,10],[1,2.34,5.66],[2,2.18,9.92]],"ltp":2.42,"tv":288.4,"id":31372}]}]}
{"op":"mcm","clk":"11836949808","pt":1723154295785,"mc":[{"id":"1.231539716","rc":[{"batb":[[2,1.66,53.07]],"ltp":1.71,"tv":805.24,"id":5995},{"batb":[[0,2.38,4],[1,2.36,10],[2,2.34,5.66]],"ltp":2.42,"tv":288.4,"id":31372}]}]}
{"op":"mcm","clk":"11836949910","pt":1723154298097,"mc":[{"id":"1.231539716","rc":[{"batb":[[0,2.34,5.66],[1,2.18,42.05],[2,2.02,4.55]],"ltp":2.42,"tv":288.4,"id":31372}]}]}
{"op":"mcm","clk":"11836950020","pt":1723154300511,"mc":[{"id":"1.231539716","rc":[{"batb":[[0,2.36,14],[1,2.34,5.66],[2,2.18,42.05]],"ltp":2.42,"tv":288.4,"id":31372}]}]}
{"op":"mcm","clk":"11836950113","pt":1723154302820,"mc":[{"id":"1.231539716","rc":[{"batb":[[0,2.36,10]],"ltp":2.42,"tv":288.4,"id":31372}]}]}
{"op":"mcm","clk":"11836950145","pt":1723154303794,"mc":[{"id":"1.231539716","rc":[{"batb":[[0,2.34,5.66],[1,2.18,42.05],[2,2.02,4.55]],"ltp":2.42,"tv":288.4,"id":31372}]}]}
{"op":"mcm","clk":"11836950208","pt":1723154305228,"mc":[{"id":"1.231539716","rc":[{"batb":[[0,2.36,4],[1,2.34,5.66],[2,2.18,42.05]],"ltp":2.42,"tv":288.4,"id":31372}]}]}
{"op":"mcm","clk":"11836950263","pt":1723154306303,"mc":[{"id":"1.231539716","rc":[{"batb":[[0,2.38,10],[1,2.36,4],[2,2.34,5.66]],"ltp":2.42,"tv":288.4,"id":31372}]}]}
{"op":"mcm","clk":"11836950327","pt":1723154307534,"mc":[{"id":"1.231539716","rc":[{"batb":[[1,2.34,5.66],[2,2.18,42.05]],"ltp":2.42,"tv":288.4,"id":31372}]}]}
{"op":"mcm","clk":"11836950420","pt":1723154309836,"mc":[{"id":"1.231539716","rc":[{"batb":[[0,2.4,4]],"ltp":2.42,"tv":288.4,"id":31372}]}]}
{"op":"mcm","clk":"11836950533","pt":1723154312104,"mc":[{"id":"1.231539716","rc":[{"batb":[[0,2.42,10]],"ltp":2.42,"tv":288.4,"id":31372}]}]}
{"op":"mcm","clk":"11836950610","pt":1723154314312,"mc":[{"id":"1.231539716","rc":[{"batb":[[1,2.18,42.05],[2,2.02,4.55]],"ltp":2.42,"tv":288.4,"id":31372}]}]}
{"op":"mcm","clk":"11836950652","pt":1723154315544,"mc":[{"id":"1.231539716","rc":[{"batb":[[0,2.18,42.05],[1,2.02,4.55],[2,1.8,2]],"ltp":2.42,"tv":288.4,"id":31372}]}]}
{"op":"mcm","clk":"11836950660","pt":1723154315647,"mc":[{"id":"1.231539716","rc":[{"batb":[[0,2.2,4],[1,2.18,42.05],[2,2.02,4.55]],"ltp":2.42,"tv":288.4,"id":31372}]}]}
{"op":"mcm","clk":"11836950706","pt":1723154316626,"mc":[{"id":"1.231539716","rc":[{"batb":[[0,2.34,5.66],[1,2.2,4],[2,2.18,42.05]],"ltp":2.42,"tv":288.4,"id":31372}]}]}
{"op":"mcm","clk":"11836950771","pt":1723154317955,"mc":[{"id":"1.231539716","rc":[{"batb":[[0,2.36,10],[1,2.34,5.66]],"ltp":2.42,"tv":288.4,"id":31372}]}]}
{"op":"mcm","clk":"11836950930","pt":1723154321248,"mc":[{"id":"1.231539716","rc":[{"batb":[[0,2.38,4]],"ltp":2.42,"tv":288.4,"id":31372}]}]}
{"op":"mcm","clk":"11836951007","pt":1723154323555,"mc":[{"id":"1.231539716","rc":[{"batb":[[0,2.34,5.66],[1,2.18,42.05],[2,2.02,4.55]],"ltp":2.42,"tv":288.4,"id":31372}]}]}
{"op":"mcm","clk":"11836951014","pt":1723154323659,"mc":[{"id":"1.231539716","rc":[{"batb":[[0,2.36,10],[1,2.34,5.66],[2,2.18,42.05]],"ltp":2.42,"tv":288.4,"id":31372}]}]}
{"op":"mcm","clk":"11836951089","pt":1723154325862,"mc":[{"id":"1.231539716","rc":[{"batb":[[0,2.38,4],[1,2.36,10],[2,2.34,5.66]],"ltp":2.42,"tv":288.4,"id":31372}]}]}
{"op":"mcm","clk":"11836951136","pt":1723154326937,"mc":[{"id":"1.231539716","rc":[{"batb":[[1,2.34,5.66],[2,2.18,42.05]],"ltp":2.42,"tv":288.4,"id":31372}]}]}
{"op":"mcm","clk":"11836951195","pt":1723154328063,"mc":[{"id":"1.231539716","rc":[{"batb":[[0,2.34,5.66],[1,2.18,42.05],[2,2.02,4.55]],"ltp":2.42,"tv":288.4,"id":31372}]}]}
{"op":"mcm","clk":"11836951254","pt":1723154329342,"mc":[{"id":"1.231539716","rc":[{"batb":[[0,2.36,10],[1,2.34,5.66],[2,2.18,42.05]],"ltp":2.42,"tv":288.4,"id":31372}]}]}
{"op":"mcm","clk":"11836951308","pt":1723154330569,"mc":[{"id":"1.231539716","rc":[{"batb":[[0,2.38,4],[1,2.36,10],[2,2.34,5.66]],"ltp":2.42,"tv":288.4,"id":31372}]}]}
{"op":"mcm","clk":"11836951374","pt":1723154332461,"mc":[{"id":"1.231539716","rc":[{"batb":[[1,2.34,5.66],[2,2.18,42.05]],"ltp":2.42,"tv":288.4,"id":31372}]}]}
{"op":"mcm","clk":"11836951390","pt":1723154332975,"mc":[{"id":"1.231539716","rc":[{"batb":[[0,2.34,5.66],[1,2.18,42.05],[2,2.02,4.55]],"ltp":2.42,"tv":288.4,"id":31372}]}]}
{"op":"mcm","clk":"11836951465","pt":1723154335484,"mc":[{"id":"1.231539716","rc":[{"batb":[[0,2.36,14],[1,2.34,5.66],[2,2.18,42.05]],"ltp":2.42,"tv":288.4,"id":31372}]}]}
{"op":"mcm","clk":"11836951550","pt":1723154337842,"mc":[{"id":"1.231539716","rc":[{"batb":[[0,2.36,10]],"ltp":2.42,"tv":288.4,"id":31372}]}]}
{"op":"mcm","clk":"11836951583","pt":1723154338969,"mc":[{"id":"1.231539716","rc":[{"batb":[[0,2.34,5.66],[1,2.18,42.05],[2,2.02,4.55]],"ltp":2.42,"tv":288.4,"id":31372}]}]}
{"op":"mcm","clk":"11836951625","pt":1723154340146,"mc":[{"id":"1.231539716","rc":[{"batb":[[0,2.36,4],[1,2.34,5.66],[2,2.18,42.05]],"ltp":2.42,"tv":288.4,"id":31372}]}]}
{"op":"mcm","clk":"11836951678","pt":1723154341375,"mc":[{"id":"1.231539716","rc":[{"batb":[[0,2.38,10],[1,2.36,4],[2,2.34,5.66]],"ltp":2.42,"tv":288.4,"id":31372}]}]}
{"op":"mcm","clk":"11836951730","pt":1723154342454,"mc":[{"id":"1.231539716","rc":[{"batb":[[1,2.34,5.66],[2,2.18,42.05]],"ltp":2.42,"tv":288.4,"id":31372}]}]}
{"op":"mcm","clk":"11836951819","pt":1723154344860,"mc":[{"id":"1.231539716","rc":[{"batb":[[0,2.36,4]],"ltp":2.42,"tv":288.4,"id":31372}]}]}
{"op":"mcm","clk":"11836951921","pt":1723154347275,"mc":[{"id":"1.231539716","rc":[{"batb":[[0,2.38,10]],"ltp":2.42,"tv":288.4,"id":31372}]}]}
{"op":"mcm","clk":"11836952059","pt":1723154350660,"mc":[{"id":"1.231539716","rc":[{"batb":[[0,2.4,4]],"ltp":2.42,"tv":288.4,"id":31372}]}]}
{"op":"mcm","clk":"11836952152","pt":1723154353277,"mc":[{"id":"1.231539716","rc":[{"batb":[[0,2.36,10]],"ltp":2.42,"tv":288.4,"id":31372}]}]}
{"op":"mcm","clk":"11836952308","pt":1723154356765,"mc":[{"id":"1.231539716","rc":[{"batb":[[0,2.38,4]],"ltp":2.42,"tv":288.4,"id":31372}]}]}
{"op":"mcm","clk":"11836952416","pt":1723154358973,"mc":[{"id":"1.231539716","rc":[{"batb":[[0,2.4,10]],"ltp":2.42,"tv":288.4,"id":31372}]}]}
{"op":"mcm","clk":"11836952498","pt":1723154360870,"mc":[{"id":"1.231539716","rc":[{"batb":[[2,1.61,4.55]],"ltp":1.71,"tv":805.24,"id":5995},{"batb":[[2,2.18,9.92]],"ltp":2.42,"tv":288.4,"id":31372}]}]}
{"op":"mcm","clk":"11836952572","pt":1723154362611,"mc":[{"id":"1.231539716","rc":[{"batb":[[0,2.36,4]],"ltp":2.42,"tv":288.4,"id":31372}]}]}
{"op":"mcm","clk":"11836952673","pt":1723154364989,"mc":[{"id":"1.231539716","rc":[{"batb":[[0,2.36,10]],"ltp":2.42,"tv":288.4,"id":31372}]}]}
{"op":"mcm","clk":"11836952715","pt":1723154365891,"mc":[{"id":"1.231539716","rc":[{"batb":[[2,1.66,53.07]],"ltp":1.71,"tv":805.24,"id":5995},{"batb":[[2,2.18,42.05]],"ltp":2.42,"tv":288.4,"id":31372}]}]}
{"op":"mcm","clk":"11836952817","pt":1723154368399,"mc":[{"id":"1.231539716","rc":[{"batb":[[0,2.36,4]],"ltp":2.42,"tv":288.4,"id":31372}]}]}
{"op":"mcm","clk":"11836952923","pt":1723154370786,"mc":[{"id":"1.231539716","rc":[{"batb":[[0,2.36,10]],"ltp":2.42,"tv":288.4,"id":31372}]}]}
{"op":"mcm","clk":"11836953072","pt":1723154374224,"mc":[{"id":"1.231539716","rc":[{"batb":[[0,2.38,4]],"ltp":2.42,"tv":288.4,"id":31372}]}]}
{"op":"mcm","clk":"11836953142","pt":1723154376528,"mc":[{"id":"1.231539716","rc":[{"batb":[[0,2.34,5.66],[1,2.18,42.05],[2,2.02,4.55]],"ltp":2.42,"tv":288.4,"id":31372}]}]}
{"op":"mcm","clk":"11836953947","pt":1723154400327,"mc":[{"id":"1.231539716","rc":[{"batb":[[0,2.36,14],[1,2.34,5.66],[2,2.18,42.05]],"ltp":2.42,"tv":288.4,"id":31372}]}]}
{"op":"mcm","clk":"11836954066","pt":1723154402739,"mc":[{"id":"1.231539716","rc":[{"batb":[[0,2.36,10]],"ltp":2.42,"tv":288.4,"id":31372}]}]}
{"op":"mcm","clk":"11836954126","pt":1723154403970,"mc":[{"id":"1.231539716","rc":[{"batb":[[0,2.34,5.66],[1,2.18,42.05],[2,2.02,4.55]],"ltp":2.42,"tv":288.4,"id":31372}]}]}
{"op":"mcm","clk":"11836954194","pt":1723154405154,"mc":[{"id":"1.231539716","rc":[{"batb":[[0,2.36,4],[1,2.34,5.66],[2,2.18,42.05]],"ltp":2.42,"tv":288.4,"id":31372}]}]}
{"op":"mcm","clk":"11836954249","pt":1723154406340,"mc":[{"id":"1.231539716","rc":[{"batb":[[0,2.38,10],[1,2.36,4],[2,2.34,5.66]],"ltp":2.42,"tv":288.4,"id":31372}]}]}
{"op":"mcm","clk":"11836954298","pt":1723154407461,"mc":[{"id":"1.231539716","rc":[{"batb":[[1,2.34,5.66],[2,2.18,42.05]],"ltp":2.42,"tv":288.4,"id":31372}]}]}
{"op":"mcm","clk":"11836954378","pt":1723154409824,"mc":[{"id":"1.231539716","rc":[{"batb":[[0,2.36,4]],"ltp":2.42,"tv":288.4,"id":31372}]}]}
{"op":"mcm","clk":"11836954487","pt":1723154412247,"mc":[{"id":"1.231539716","rc":[{"batb":[[0,2.38,10]],"ltp":2.42,"tv":288.4,"id":31372}]}]}
{"op":"mcm","clk":"11836954572","pt":1723154414455,"mc":[{"id":"1.231539716","rc":[{"batb":[[0,2.4,4],[1,2.38,10],[2,2.34,5.66]],"ltp":2.42,"tv":288.4,"id":31372}]}]}
{"op":"mcm","clk":"11836954630","pt":1723154415379,"mc":[{"id":"1.231539716","rc":[{"batb":[[1,2.34,5.66],[2,2.18,42.05]],"ltp":2.42,"tv":288.4,"id":31372}]}]}
{"op":"mcm","clk":"11836954686","pt":1723154416665,"mc":[{"id":"1.231539716","rc":[{"batb":[[0,2.34,5.66],[1,2.18,42.05],[2,2.02,4.55]],"ltp":2.42,"tv":288.4,"id":31372}]}]}
{"op":"mcm","clk":"11836954745","pt":1723154417851,"mc":[{"id":"1.231539716","rc":[{"batb":[[0,2.36,10],[1,2.34,5.66],[2,2.18,42.05]],"ltp":2.42,"tv":288.4,"id":31372}]}]}
{"op":"mcm","clk":"11836954807","pt":1723154419341,"mc":[{"id":"1.231539716","rc":[{"batb":[[0,2.38,4],[1,2.36,10],[2,2.34,5.66]],"ltp":2.42,"tv":288.4,"id":31372}]}]}
{"op":"mcm","clk":"11836954904","pt":1723154421551,"mc":[{"id":"1.231539716","rc":[{"batb":[[0,2.34,5.66],[1,2.18,42.05],[2,2.02,4.55]],"ltp":2.42,"tv":288.4,"id":31372}]}]}
{"op":"mcm","clk":"11836955014","pt":1723154423972,"mc":[{"id":"1.231539716","rc":[{"batb":[[0,2.36,14],[1,2.34,5.66],[2,2.18,42.05]],"ltp":2.42,"tv":288.4,"id":31372}]}]}
{"op":"mcm","clk":"11836955138","pt":1723154426389,"mc":[{"id":"1.231539716","rc":[{"batb":[[0,2.36,10]],"ltp":2.42,"tv":288.4,"id":31372}]}]}
{"op":"mcm","clk":"11836955186","pt":1723154427267,"mc":[{"id":"1.231539716","rc":[{"batb":[[0,2.34,5.66],[1,2.18,42.05],[2,2.02,4.55]],"ltp":2.42,"tv":288.4,"id":31372}]}]}
{"op":"mcm","clk":"11836955261","pt":1723154428552,"mc":[{"id":"1.231539716","rc":[{"batb":[[0,2.36,4],[1,2.34,5.66],[2,2.18,42.05]],"ltp":2.42,"tv":288.4,"id":31372}]}]}
{"op":"mcm","clk":"11836955338","pt":1723154430088,"mc":[{"id":"1.231539716","rc":[{"batb":[[0,2.38,10],[1,2.36,4],[2,2.34,5.66]],"ltp":2.42,"tv":288.4,"id":31372}]}]}
{"op":"mcm","clk":"11836955378","pt":1723154431372,"mc":[{"id":"1.231539716","rc":[{"batb":[[2,1.61,4.55]],"ltp":1.71,"tv":805.24,"id":5995},{"batb":[[1,2.34,5.66],[2,2.18,9.92]],"ltp":2.42,"tv":288.4,"id":31372}]}]}
{"op":"mcm","clk":"11836955472","pt":1723154433477,"mc":[{"id":"1.231539716","rc":[{"batb":[[0,2.4,4]],"ltp":2.42,"tv":288.4,"id":31372}]}]}
