{"op":"mcm","clk":"11824031197","pt":1723458658613,"mc":[{"id":"1.231737525","marketDefinition":{"bspMarket":false,"turnInPlayEnabled":true,"persistenceEnabled":true,"marketBaseRate":5.0,"eventId":"33488511","eventTypeId":"4","numberOfWinners":1,"bettingType":"ODDS","marketType":"MATCH_ODDS","marketTime":"2024-08-15T17:30:00.000Z","suspendTime":"2024-08-15T17:30:00.000Z","bspReconciled":false,"complete":true,"inPlay":false,"crossMatching":true,"runnersVoidable":false,"numberOfActiveRunners":2,"betDelay":0,"status":"OPEN","runners":[{"status":"ACTIVE","sortPriority":1,"id":26354921,"name":"Birmingham Phoenix"},{"status":"ACTIVE","sortPriority":2,"id":26354922,"name":"Manchester Originals"}],"regulators":["MR_INT"],"countryCode":"GB","discountAllowed":false,"timezone":"GMT","openDate":"2024-08-15T17:30:00.000Z","version":6071699362,"name":"Match Odds","eventName":"Birmingham Phoenix v Manchester Originals"},"rc":[{"batb":[[0,1.01,20]],"ltp":0.0,"tv":0.0,"id":26354922},{"batb":[[0,1.01,20]],"ltp":0.0,"tv":0.0,"id":26354921}]}]}
{"op":"mcm","clk":"11824031230","pt":1723458659123,"mc":[{"id":"1.231737525","rc":[{"batb":[[0,1.06,100],[1,1.05,100],[2,1.04,100]],"ltp":0.0,"tv":0.0,"id":26354922},{"batb":[[0,1.06,100],[1,1.05,100],[2,1.04,100]],"ltp":0.0,"tv":0.0,"id":26354921}]}]}
{"op":"mcm","clk":"11824031340","pt":1723458660994,"mc":[{"id":"1.231737525","marketDefinition":{"bspMarket":false,"turnInPlayEnabled":true,"persistenceEnabled":true,"marketBaseRate":5.0,"eventId":"33488511","eventTypeId":"4","numberOfWinners":1,"bettingType":"ODDS","marketType":"MATCH_ODDS","marketTime":"2024-08-15T17:30:00.000Z","suspendTime":"2024-08-15T17:30:00.000Z","bspReconciled":false,"complete":true,"inPlay":false,"crossMatching":true,"runnersVoidable":false,"numberOfActiveRunners":2,"betDelay":0,"status":"OPEN","runners":[{"status":"ACTIVE","sortPriority":1,"id":26354921,"name":"Birmingham Phoenix"},{"status":"ACTIVE","sortPriority":2,"id":26354922,"name":"Manchester Originals"}],"regulators":["MR_INT"],"countryCode":"GB","discountAllowed":true,"timezone":"GMT","openDate":"2024-08-15T17:30:00.000Z","version":6071699362,"name":"Match Odds","eventName":"Birmingham Phoenix v Manchester Originals"}}]}
{"op":"mcm","clk":"11824058020","pt":1723459196440,"mc":[{"id":"1.231737525","rc":[{"batb":[[0,1.07,122.94],[1,1.06,100],[2,1.05,100]],"ltp":0.0,"tv":0.0,"id":26354922},{"batb":[[0,1.07,122.94],[1,1.06,100],[2,1.05,100]],"ltp":0.0,"tv":0.0,"id":26354921}]}]}
{"op":"mcm","clk":"11824069320","pt":1723459422976,"mc":[{"id":"1.231737525","rc":[{"batb":[[0,1.1,25000],[1,1.09,25000],[2,1.08,25000]],"ltp":0.0,"tv":0.0,"id":26354922},{"batb":[[0,1.1,25000],[1,1.09,25000],[2,1.08,25000]],"ltp":0.0,"tv":0.0,"id":26354921}]}]}
{"op":"mcm","clk":"11824072935","pt":1723459484571,"mc":[{"id":"1.231737525","rc":[{"batb":[[0,1.09,25000],[1,1.08,25000],[2,1.07,25122.94]],"ltp":0.0,"tv":0.0,"id":26354921}]}]}
{"op":"mcm","clk":"11824073014","pt":1723459485868,"mc":[{"id":"1.231737525","rc":[{"batb":[[0,1.07,25122.94],[1,1.06,25100],[2,1.05,25100]],"ltp":0.0,"tv":0.0,"id":26354921}]}]}
{"op":"mcm","clk":"11824073042","pt":1723459486380,"mc":[{"id":"1.231737525","rc":[{"batb":[[0,1.07,122.94]],"ltp":0.0,"tv":0.0,"id":26354921}]}]}
{"op":"mcm","clk":"11824073445","pt":1723459492964,"mc":[{"id":"1.231737525","rc":[{"batb":[[0,1.09,25000],[1,1.08,25000],[2,1.07,25122.94]],"ltp":0.0,"tv":0.0,"id":26354922}]}]}
{"op":"mcm","clk":"11824073508","pt":1723459493743,"mc":[{"id":"1.231737525","rc":[{"batb":[[0,1.07,25122.94],[1,1.06,25100],[2,1.05,25100]],"ltp":0.0,"tv":0.0,"id":26354922}]}]}
{"op":"mcm","clk":"11824073574","pt":1723459494877,"mc":[{"id":"1.231737525","rc":[{"batb":[[0,1.07,122.94]],"ltp":0.0,"tv":0.0,"id":26354922}]}]}
{"op":"mcm","clk":"11824159729","pt":1723460996763,"mc":[{"id":"1.231737525","rc":[{"batb":[[0,1.06,25100],[1,1.05,25100],[2,1.04,25100]],"ltp":0.0,"tv":0.0,"id":26354922},{"batb":[[0,1.06,25100],[1,1.05,25100],[2,1.04,25100]],"ltp":0.0,"tv":0.0,"id":26354921}]}]}
{"op":"mcm","clk":"11824163053","pt":1723461053943,"mc":[{"id":"1.231737525","rc":[{"batb":[[0,1.07,122.93],[1,1.06,25100],[2,1.05,25100]],"ltp":0.0,"tv":0.0,"id":26354922},{"batb":[[0,1.07,122.93],[1,1.06,25100],[2,1.05,25100]],"ltp":0.0,"tv":0.0,"id":26354921}]}]}
{"op":"mcm","clk":"11824263988","pt":1723462854001,"mc":[{"id":"1.231737525","rc":[{"batb":[[0,1.06,25100],[1,1.05,25100],[2,1.04,25100]],"ltp":0.0,"tv":0.0,"id":26354921}]}]}
{"op":"mcm","clk":"11824264003","pt":1723462854212,"mc":[{"id":"1.231737525","rc":[{"batb":[[0,1.06,25100],[1,1.05,25100],[2,1.04,25100]],"ltp":0.0,"tv":0.0,"id":26354922}]}]}
{"op":"mcm","clk":"11824266367","pt":1723462895584,"mc":[{"id":"1.231737525","rc":[{"batb":[[0,1.07,122.93],[1,1.06,25100],[2,1.05,25100]],"ltp":0.0,"tv":0.0,"id":26354922},{"batb":[[0,1.07,122.93],[1,1.06,25100],[2,1.05,25100]],"ltp":0.0,"tv":0.0,"id":26354921}]}]}
{"op":"mcm","clk":"11824388731","pt":1723464696010,"mc":[{"id":"1.231737525","rc":[{"batb":[[0,1.06,25100],[1,1.05,25100],[2,1.04,25100]],"ltp":0.0,"tv":0.0,"id":26354922},{"batb":[[0,1.06,25100],[1,1.05,25100],[2,1.04,25100]],"ltp":0.0,"tv":0.0,"id":26354921}]}]}
{"op":"mcm","clk":"11824390886","pt":1723464722537,"mc":[{"id":"1.231737525","rc":[{"batb":[[0,1.07,122.85],[1,1.06,25100],[2,1.05,25100]],"ltp":0.0,"tv":0.0,"id":26354922},{"batb":[[0,1.07,122.85],[1,1.06,25100],[2,1.05,25100]],"ltp":0.0,"tv":0.0,"id":26354921}]}]}
{"op":"mcm","clk":"11824522469","pt":1723466522908,"mc":[{"id":"1.231737525","rc":[{"batb":[[0,1.06,25100],[1,1.05,25100],[2,1.04,25100]],"ltp":0.0,"tv":0.0,"id":26354922},{"batb":[[0,1.06,25100],[1,1.05,25100],[2,1.04,25100]],"ltp":0.0,"tv":0.0,"id":26354921}]}]}
{"op":"mcm","clk":"11824523426","pt":1723466537532,"mc":[{"id":"1.231737525","rc":[{"batb":[[0,1.07,122.85],[1,1.06,25100],[2,1.05,25100]],"ltp":0.0,"tv":0.0,"id":26354922},{"batb":[[0,1.07,122.85],[1,1.06,25100],[2,1.05,25100]],"ltp":0.0,"tv":0.0,"id":26354921}]}]}
{"op":"mcm","clk":"11824559831","pt":1723467076838,"mc":[{"id":"1.231737525","rc":[{"batb":[[0,1.25,100],[1,1.07,122.85],[2,1.06,25100]],"ltp":0.0,"tv":0.0,"id":26354922},{"batb":[[0,1.25,100],[1,1.07,122.85],[2,1.06,25100]],"ltp":0.0,"tv":0.0,"id":26354921}]}]}
{"op":"mcm","clk":"11824641433","pt":1723468337900,"mc":[{"id":"1.231737525","rc":[{"batb":[[1,1.06,25100],[2,1.05,40103]],"ltp":0.0,"tv":0.0,"id":26354922},{"batb":[[1,1.06,25100],[2,1.05,40103]],"ltp":0.0,"tv":0.0,"id":26354921}]}]}
{"op":"mcm","clk":"11824641767","pt":1723468343871,"mc":[{"id":"1.231737525","rc":[{"batb":[[0,1.26,33.07],[1,1.25,100],[2,1.06,25100]],"ltp":0.0,"tv":0.0,"id":26354922},{"batb":[[0,1.26,33.07],[1,1.25,100],[2,1.06,25100]],"ltp":0.0,"tv":0.0,"id":26354921}]}]}
{"op":"mcm","clk":"11824726437","pt":1723469426435,"mc":[{"id":"1.231737525","rc":[{"batb":[[0,1.27,6.49],[1,1.26,33.07],[2,1.25,100]],"ltp":0.0,"tv":0.0,"id":26354922},{"batb":[[0,1.27,6.86],[1,1.26,33.07],[2,1.25,100]],"ltp":0.0,"tv":0.0,"id":26354921}]}]}
{"op":"mcm","clk":"11824779171","pt":1723470144290,"mc":[{"id":"1.231737525","rc":[{"batb":[[1,1.25,100],[2,1.06,25100]],"ltp":0.0,"tv":0.0,"id":26354922},{"batb":[[1,1.25,100],[2,1.06,25100]],"ltp":0.0,"tv":0.0,"id":26354921}]}]}
{"op":"mcm","clk":"11824782390","pt":1723470185272,"mc":[{"id":"1.231737525","rc":[{"batb":[[0,1.28,30.71],[1,1.27,6.49],[2,1.25,100]],"ltp":0.0,"tv":0.0,"id":26354922},{"batb":[[0,1.28,30.71],[1,1.27,6.86],[2,1.25,100]],"ltp":0.0,"tv":0.0,"id":26354921}]}]}
{"op":"mcm","clk":"11824850544","pt":1723471108732,"mc":[{"id":"1.231737525","rc":[{"batb":[[0,1.29,6.49],[1,1.28,30.71]],"ltp":0.0,"tv":0.0,"id":26354922},{"batb":[[0,1.29,6.86],[1,1.28,30.71]],"ltp":0.0,"tv":0.0,"id":26354921}]}]}
{"op":"mcm","clk":"11824925234","pt":1723471985610,"mc":[{"id":"1.231737525","rc":[{"batb":[[0,1.29,6.48],[1,1.25,100],[2,1.06,25100]],"ltp":0.0,"tv":0.0,"id":26354922},{"batb":[[0,1.29,6.86],[1,1.25,100],[2,1.06,25100]],"ltp":0.0,"tv":0.0,"id":26354921}]}]}
{"op":"mcm","clk":"11824930083","pt":1723472061006,"mc":[{"id":"1.231737525","rc":[{"batb":[[0,1.3,28.66],[1,1.29,6.48],[2,1.25,100]],"ltp":0.0,"tv":0.0,"id":26354922},{"batb":[[0,1.3,28.66],[1,1.29,6.86],[2,1.25,100]],"ltp":0.0,"tv":0.0,"id":26354921}]}]}
{"op":"mcm","clk":"11824983112","pt":1723472786549,"mc":[{"id":"1.231737525","rc":[{"batb":[[0,1.31,6.48],[1,1.3,28.66]],"ltp":0.0,"tv":0.0,"id":26354922},{"batb":[[0,1.31,6.86],[1,1.3,28.66]],"ltp":0.0,"tv":0.0,"id":26354921}]}]}
{"op":"mcm","clk":"11825065798","pt":1723473861343,"mc":[{"id":"1.231737525","rc":[{"batb":[[1,1.25,100],[2,1.06,25100]],"ltp":0.0,"tv":0.0,"id":26354922},{"batb":[[1,1.25,100],[2,1.06,25100]],"ltp":0.0,"tv":0.0,"id":26354921}]}]}
{"op":"mcm","clk":"11825071420","pt":1723473923538,"mc":[{"id":"1.231737525","rc":[{"batb":[[0,1.32,26.87],[1,1.31,6.48],[2,1.25,100]],"ltp":0.0,"tv":0.0,"id":26354922},{"batb":[[0,1.32,26.87],[1,1.31,6.86],[2,1.25,100]],"ltp":0.0,"tv":0.0,"id":26354921}]}]}
{"op":"mcm","clk":"11825108770","pt":1723474458938,"mc":[{"id":"1.231737525","rc":[{"batb":[[1,1.25,100],[2,1.06,25100]],"ltp":0.0,"tv":0.0,"id":26354922},{"batb":[[0,1.33,6.86],[1,1.32,26.87]],"ltp":0.0,"tv":0.0,"id":26354921}]}]}
{"op":"mcm","clk":"11825108780","pt":1723474459038,"mc":[{"id":"1.231737525","rc":[{"batb":[[0,1.33,6.48],[1,1.32,26.87],[2,1.25,100]],"ltp":0.0,"tv":0.0,"id":26354922}]}]}
{"op":"mcm","clk":"11825214536","pt":1723475723860,"mc":[{"id":"1.231737525","rc":[{"batb":[[0,1.33,6.48],[1,1.25,100],[2,1.06,25100]],"ltp":0.0,"tv":0.0,"id":26354922},{"batb":[[0,1.33,6.85],[1,1.25,100],[2,1.06,25100]],"ltp":0.0,"tv":0.0,"id":26354921}]}]}
{"op":"mcm","clk":"11825220879","pt":1723475785491,"mc":[{"id":"1.231737525","rc":[{"batb":[[0,1.34,25.27],[1,1.33,6.48],[2,1.25,100]],"ltp":0.0,"tv":0.0,"id":26354922},{"batb":[[0,1.34,25.27],[1,1.33,6.85],[2,1.25,100]],"ltp":0.0,"tv":0.0,"id":26354921}]}]}
{"op":"mcm","clk":"11825268830","pt":1723476235883,"mc":[{"id":"1.231737525","rc":[{"batb":[[0,1.35,6.85],[1,1.34,25.27]],"ltp":0.0,"tv":0.0,"id":26354921}]}]}
{"op":"mcm","clk":"11825268886","pt":1723476236299,"mc":[{"id":"1.231737525","rc":[{"batb":[[0,1.35,6.48],[1,1.34,25.27]],"ltp":0.0,"tv":0.0,"id":26354922}]}]}
{"op":"mcm","clk":"11825423926","pt":1723477585949,"mc":[{"id":"1.231737525","rc":[{"batb":[[1,1.25,100],[2,1.06,25100]],"ltp":0.0,"tv":0.0,"id":26354922},{"batb":[[1,1.25,100],[2,1.06,25100]],"ltp":0.0,"tv":0.0,"id":26354921}]}]}
{"op":"mcm","clk":"11825430146","pt":1723477637794,"mc":[{"id":"1.231737525","rc":[{"batb":[[0,1.36,23.87],[1,1.35,6.48],[2,1.25,100]],"ltp":0.0,"tv":0.0,"id":26354922},{"batb":[[0,1.36,23.87],[1,1.35,6.85],[2,1.25,100]],"ltp":0.0,"tv":0.0,"id":26354921}]}]}
{"op":"mcm","clk":"11825466055","pt":1723477944534,"mc":[{"id":"1.231737525","rc":[{"batb":[[1,1.26,6.48]],"ltp":0.0,"tv":0.0,"id":26354922},{"batb":[[1,1.26,6.85]],"ltp":0.0,"tv":0.0,"id":26354921}]}]}
{"op":"mcm","clk":"11825627975","pt":1723479174790,"mc":[{"id":"1.231737525","rc":[{"batb":[[0,1.36,23.88],[1,1.26,6.48]],"ltp":0.0,"tv":0.0,"id":26354922},{"batb":[[0,1.36,23.88],[1,1.26,6.86]],"ltp":0.0,"tv":0.0,"id":26354921}]}]}
{"op":"mcm","clk":"11825675457","pt":1723479437946,"mc":[{"id":"1.231737525","rc":[{"batb":[[0,1.26,6.48],[1,1.25,100],[2,1.06,25100]],"ltp":0.0,"tv":0.0,"id":26354922}]}]}
{"op":"mcm","clk":"11825675482","pt":1723479438152,"mc":[{"id":"1.231737525","rc":[{"batb":[[0,1.26,6.86],[1,1.25,100],[2,1.06,25100]],"ltp":0.0,"tv":0.0,"id":26354921}]}]}
{"op":"mcm","clk":"11825680838","pt":1723479472661,"mc":[{"id":"1.231737525","rc":[{"batb":[[0,1.27,31.85],[1,1.26,6.48],[2,1.25,100]],"ltp":0.0,"tv":0.0,"id":26354922},{"batb":[[0,1.27,31.85],[1,1.26,6.86],[2,1.25,100]],"ltp":0.0,"tv":0.0,"id":26354921}]}]}
{"op":"mcm","clk":"11825702645","pt":1723479621935,"mc":[{"id":"1.231737525","rc":[{"batb":[[0,1.28,6.48],[1,1.27,31.85]],"ltp":0.0,"tv":0.0,"id":26354922},{"batb":[[0,1.28,6.86],[1,1.27,31.85]],"ltp":0.0,"tv":0.0,"id":26354921}]}]}
{"op":"mcm","clk":"11825940928","pt":1723481272893,"mc":[{"id":"1.231737525","rc":[{"batb":[[1,1.25,100],[2,1.06,25100]],"ltp":0.0,"tv":0.0,"id":26354922}]}]}
{"op":"mcm","clk":"11825940955","pt":1723481273098,"mc":[{"id":"1.231737525","rc":[{"batb":[[1,1.25,100],[2,1.06,25100]],"ltp":0.0,"tv":0.0,"id":26354921}]}]}
{"op":"mcm","clk":"11825944234","pt":1723481296600,"mc":[{"id":"1.231737525","rc":[{"batb":[[0,1.29,29.65],[1,1.28,6.48],[2,1.25,100]],"ltp":0.0,"tv":0.0,"id":26354922},{"batb":[[0,1.29,29.65],[1,1.28,6.86],[2,1.25,100]],"ltp":0.0,"tv":0.0,"id":26354921}]}]}
{"op":"mcm","clk":"11825944416","pt":1723481298013,"mc":[{"id":"1.231737525","rc":[{"batb":[[0,1.3,6.86],[1,1.29,29.65]],"ltp":0.0,"tv":0.0,"id":26354921}]}]}
{"op":"mcm","clk":"11825944463","pt":1723481298420,"mc":[{"id":"1.231737525","rc":[{"batb":[[0,1.3,6.48],[1,1.29,29.65]],"ltp":0.0,"tv":0.0,"id":26354922}]}]}
{"op":"mcm","clk":"11826248425","pt":1723483096826,"mc":[{"id":"1.231737525","rc":[{"batb":[[0,1.3,6.49],[1,1.29,29.67]],"ltp":0.0,"tv":0.0,"id":26354922},{"batb":[[0,1.3,6.87],[1,1.25,100],[2,1.06,25100]],"ltp":0.0,"tv":0.0,"id":26354921}]}]}
{"op":"mcm","clk":"11826248465","pt":1723483097035,"mc":[{"id":"1.231737525","rc":[{"batb":[[1,1.25,100],[2,1.06,25100]],"ltp":0.0,"tv":0.0,"id":26354922}]}]}
{"op":"mcm","clk":"11826271668","pt":1723483224585,"mc":[{"id":"1.231737525","rc":[{"batb":[[0,1.31,27.76],[1,1.3,6.49],[2,1.25,100]],"ltp":0.0,"tv":0.0,"id":26354922},{"batb":[[0,1.31,27.76],[1,1.3,6.87],[2,1.25,100]],"ltp":0.0,"tv":0.0,"id":26354921}]}]}
{"op":"mcm","clk":"11826510568","pt":1723484488633,"mc":[{"id":"1.231737525","rc":[{"batb":[[0,1.32,6.49],[1,1.31,27.76]],"ltp":0.0,"tv":0.0,"id":26354922},{"batb":[[0,1.32,6.87],[1,1.31,27.76]],"ltp":0.0,"tv":0.0,"id":26354921}]}]}
{"op":"mcm","clk":"11826609761","pt":1723485024931,"mc":[{"id":"1.231737525","rc":[{"batb":[[1,1.25,100],[2,1.06,25100]],"ltp":0.0,"tv":0.0,"id":26354922},{"batb":[[1,1.25,100],[2,1.06,25100]],"ltp":0.0,"tv":0.0,"id":26354921}]}]}
{"op":"mcm","clk":"11826617710","pt":1723485072795,"mc":[{"id":"1.231737525","rc":[{"batb":[[0,1.33,26.07],[1,1.32,6.49],[2,1.25,100]],"ltp":0.0,"tv":0.0,"id":26354922},{"batb":[[0,1.33,26.07],[1,1.32,6.87],[2,1.25,100]],"ltp":0.0,"tv":0.0,"id":26354921}]}]}
{"op":"mcm","clk":"11826780307","pt":1723486090714,"mc":[{"id":"1.231737525","rc":[{"batb":[[0,1.34,6.49],[1,1.33,26.08]],"ltp":0.0,"tv":0.0,"id":26354922},{"batb":[[0,1.34,6.86],[1,1.33,26.08]],"ltp":0.0,"tv":0.0,"id":26354921}]}]}
{"op":"mcm","clk":"11826940451","pt":1723486873223,"mc":[{"id":"1.231737525","rc":[{"batb":[[1,1.25,100],[2,1.06,25100]],"ltp":0.0,"tv":0.0,"id":26354922},{"batb":[[1,1.25,100],[2,1.06,25100]],"ltp":0.0,"tv":0.0,"id":26354921}]}]}
{"op":"mcm","clk":"11826950126","pt":1723486917983,"mc":[{"id":"1.231737525","rc":[{"batb":[[0,1.35,24.59],[1,1.34,6.49],[2,1.25,100]],"ltp":0.0,"tv":0.0,"id":26354922},{"batb":[[0,1.35,24.59],[1,1.34,6.86],[2,1.25,100]],"ltp":0.0,"tv":0.0,"id":26354921}]}]}
{"op":"mcm","clk":"11827105454","pt":1723487687790,"mc":[{"id":"1.231737525","rc":[{"batb":[[1,1.26,6.49]],"ltp":0.0,"tv":0.0,"id":26354922},{"batb":[[1,1.26,6.86]],"ltp":0.0,"tv":0.0,"id":26354921}]}]}
{"op":"mcm","clk":"11827309214","pt":1723488718459,"mc":[{"id":"1.231737525","rc":[{"batb":[[0,1.26,6.49],[1,1.25,100],[2,1.06,25100]],"ltp":0.0,"tv":0.0,"id":26354922},{"batb":[[0,1.26,6.86],[1,1.25,100],[2,1.06,25100]],"ltp":0.0,"tv":0.0,"id":26354921}]}]}
{"op":"mcm","clk":"11827327553","pt":1723488826993,"mc":[{"id":"1.231737525","rc":[{"batb":[[0,1.27,31.88],[1,1.26,6.86],[2,1.25,100]],"ltp":0.0,"tv":0.0,"id":26354921}]}]}
{"op":"mcm","clk":"11827327573","pt":1723488827082,"mc":[{"id":"1.231737525","rc":[{"batb":[[0,1.27,31.88],[1,1.26,6.49],[2,1.25,100]],"ltp":0.0,"tv":0.0,"id":26354922}]}]}
{"op":"mcm","clk":"11827385706","pt":1723489222997,"mc":[{"id":"1.231737525","rc":[{"batb":[[0,1.27,31.86],[1,1.26,6.48]],"ltp":0.0,"tv":0.0,"id":26354922},{"batb":[[0,1.27,31.86],[1,1.25,100],[2,1.06,25100]],"ltp":0.0,"tv":0.0,"id":26354921}]}]}
{"op":"mcm","clk":"11827385810","pt":1723489223521,"mc":[{"id":"1.231737525","rc":[{"batb":[[0,1.28,6.48],[1,1.27,31.86]],"ltp":0.0,"tv":0.0,"id":26354922},{"batb":[[0,1.28,6.86],[1,1.27,31.86],[2,1.25,100]],"ltp":0.0,"tv":0.0,"id":26354921}]}]}
{"op":"mcm","clk":"11827402595","pt":1723489334292,"mc":[{"id":"1.231737525","rc":[{"batl":[[0,1.3,1.25]],"ltp":0.0,"tv":0.0,"id":26354921}]}]}
{"op":"mcm","clk":"11827614201","pt":1723490627426,"mc":[{"id":"1.231737525","rc":[{"batb":[[1,1.25,100],[2,1.06,25100]],"ltp":0.0,"tv":0.0,"id":26354922},{"batb":[[1,1.25,100],[2,1.06,25100]],"ltp":0.0,"tv":0.0,"id":26354921}]}]}
{"op":"mcm","clk":"11827618654","pt":1723490654952,"mc":[{"id":"1.231737525","rc":[{"batb":[[0,1.26,6.86]],"ltp":0.0,"tv":0.0,"id":26354921}]}]}
{"op":"mcm","clk":"11827618728","pt":1723490655365,"mc":[{"id":"1.231737525","rc":[{"batb":[[0,1.26,6.48]],"ltp":0.0,"tv":0.0,"id":26354922}]}]}
{"op":"mcm","clk":"11827636165","pt":1723490763791,"mc":[{"id":"1.231737525","rc":[{"batb":[[0,1.27,31.86],[1,1.26,6.48],[2,1.25,100]],"ltp":0.0,"tv":0.0,"id":26354922},{"batb":[[0,1.27,31.86],[1,1.26,6.86],[2,1.25,100]],"ltp":0.0,"tv":0.0,"id":26354921}]}]}
{"op":"mcm","clk":"11827745519","pt":1723491465577,"mc":[{"id":"1.231737525","rc":[{"batb":[[0,1.28,10],[1,1.27,31.86],[2,1.26,6.48]],"ltp":0.0,"tv":0.0,"id":26354922},{"batb":[[0,1.28,10],[1,1.27,31.86],[2,1.26,6.86]],"ltp":0.0,"tv":0.0,"id":26354921}]}]}
{"op":"mcm","clk":"11827851502","pt":1723492215956,"mc":[{"id":"1.231737525","rc":[{"batb":[[0,1.28,16.86],[2,1.25,100]],"ltp":0.0,"tv":0.0,"id":26354921}]}]}
{"op":"mcm","clk":"11827851558","pt":1723492216373,"mc":[{"id":"1.231737525","rc":[{"batb":[[0,1.28,16.48],[2,1.25,100]],"ltp":0.0,"tv":0.0,"id":26354922}]}]}
{"op":"mcm","clk":"11827896515","pt":1723492564240,"mc":[{"id":"1.231737525","rc":[{"batb":[[1,1.25,100],[2,1.06,25100]],"ltp":0.0,"tv":0.0,"id":26354922},{"batb":[[1,1.25,100],[2,1.06,25100]],"ltp":0.0,"tv":0.0,"id":26354921}]}]}
{"op":"mcm","clk":"11827913866","pt":1723492704606,"mc":[{"id":"1.231737525","rc":[{"batb":[[0,1.29,29.66],[1,1.28,16.48],[2,1.25,100]],"ltp":0.0,"tv":0.0,"id":26354922},{"batb":[[0,1.29,29.66],[1,1.28,16.86],[2,1.25,100]],"ltp":0.0,"tv":0.0,"id":26354921}]}]}
{"op":"mcm","clk":"11827959588","pt":1723493082397,"mc":[{"id":"1.231737525","rc":[{"batb":[[0,1.3,10],[1,1.29,29.67],[2,1.28,6.49]],"ltp":0.0,"tv":0.0,"id":26354922},{"batb":[[0,1.3,10],[1,1.29,29.67],[2,1.28,6.86]],"ltp":0.0,"tv":0.0,"id":26354921}]}]}
{"op":"mcm","clk":"11828021924","pt":1723493647829,"mc":[{"id":"1.231737525","rc":[{"batb":[[0,1.3,16.49],[2,1.25,100]],"ltp":0.0,"tv":0.0,"id":26354922},{"batb":[[0,1.3,16.86],[2,1.25,100]],"ltp":0.0,"tv":0.0,"id":26354921}]}]}
{"op":"mcm","clk":"11828080423","pt":1723494297963,"mc":[{"id":"1.231737525","rc":[{"trd":[[1.3,0.14]],"batb":[[0,1.3,16.79]],"ltp":1.3,"tv":0.14,"id":26354921}],"tv":0.14}]}
{"op":"mcm","clk":"11828097143","pt":1723494504902,"mc":[{"id":"1.231737525","rc":[{"batb":[[1,1.25,100],[2,1.06,25100]],"ltp":1.3,"tv":0.14,"id":26354921}]}]}
{"op":"mcm","clk":"11828097157","pt":1723494505109,"mc":[{"id":"1.231737525","rc":[{"batb":[[1,1.25,100],[2,1.06,25100]],"ltp":0.0,"tv":0.0,"id":26354922}]}]}
{"op":"mcm","clk":"11828098000","pt":1723494517088,"mc":[{"id":"1.231737525","rc":[{"batb":[[0,1.31,27.76],[1,1.3,16.49],[2,1.25,100]],"ltp":0.0,"tv":0.0,"id":26354922},{"batb":[[0,1.31,27.76],[1,1.3,16.79],[2,1.25,100]],"ltp":1.3,"tv":0.14,"id":26354921}]}]}
{"op":"mcm","clk":"11828099671","pt":1723494538935,"mc":[{"id":"1.231737525","rc":[{"batl":[[0,1.85,1]],"ltp":1.3,"tv":0.14,"id":26354921}]}]}
{"op":"mcm","clk":"11828100440","pt":1723494549236,"mc":[{"id":"1.231737525","rc":[{"batl":[[1,1.86,1]],"ltp":1.3,"tv":0.14,"id":26354921}]}]}
{"op":"mcm","clk":"11828148374","pt":1723495129995,"mc":[{"id":"1.231737525","rc":[{"batb":[[0,1.32,6.49],[1,1.31,27.76],[2,1.3,10]],"ltp":0.0,"tv":0.0,"id":26354922},{"batb":[[0,1.32,6.86],[1,1.31,27.76],[2,1.3,9.93]],"ltp":1.3,"tv":0.14,"id":26354921}]}]}
{"op":"mcm","clk":"11828230338","pt":1723496107160,"mc":[{"id":"1.231737525","rc":[{"batb":[[0,2.24,3.12],[1,1.32,6.49],[2,1.31,27.76]],"ltp":0.0,"tv":0.0,"id":26354922},{"batb":[[0,1.74,5.23],[1,1.32,6.86],[2,1.31,27.76]],"ltp":1.3,"tv":0.14,"id":26354921}]}]}
{"op":"mcm","clk":"11828241655","pt":1723496317513,"mc":[{"id":"1.231737525","rc":[{"batb":[[2,1.3,10]],"ltp":0.0,"tv":0.0,"id":26354922},{"batb":[[2,1.3,9.93]],"ltp":1.3,"tv":0.14,"id":26354921}]}]}
{"op":"mcm","clk":"11828262735","pt":1723496691547,"mc":[{"id":"1.231737525","rc":[{"batb":[[1,1.3,10],[2,1.26,6.49]],"ltp":0.0,"tv":0.0,"id":26354922},{"batb":[[1,1.3,9.93],[2,1.26,6.86]],"ltp":1.3,"tv":0.14,"id":26354921}]}]}
{"op":"mcm","clk":"11828303359","pt":1723497446676,"mc":[{"id":"1.231737525","rc":[{"batb":[[0,2.3,2.98]],"ltp":0.0,"tv":0.0,"id":26354922},{"batb":[[0,1.71,5.45]],"ltp":1.3,"tv":0.14,"id":26354921}]}]}
{"op":"mcm","clk":"11828337709","pt":1723498172998,"mc":[{"id":"1.231737525","rc":[{"batb":[[2,1.25,100]],"ltp":1.3,"tv":0.14,"id":26354921}]}]}
{"op":"mcm","clk":"11828337736","pt":1723498173411,"mc":[{"id":"1.231737525","rc":[{"batb":[[2,1.25,100]],"ltp":0.0,"tv":0.0,"id":26354922}]}]}
{"op":"mcm","clk":"11828339732","pt":1723498216362,"mc":[{"id":"1.231737525","rc":[{"trd":[[2.42,0.03]],"batb":[[1,1.25,100],[2,1.06,25100]],"ltp":2.42,"tv":0.03,"id":26354922},{"trd":[[1.71,0.04]],"batb":[[0,1.71,5.41],[1,1.25,100],[2,1.06,25100]],"ltp":1.71,"tv":0.18,"id":26354921}],"tv":0.21}]}
{"op":"mcm","clk":"11828339894","pt":1723498219548,"mc":[{"id":"1.231737525","rc":[{"batb":[[0,1.71,5.45]],"ltp":1.71,"tv":0.18,"id":26354921}]}]}
{"op":"mcm","clk":"11828340125","pt":1723498224769,"mc":[{"id":"1.231737525","rc":[{"trd":[[1.71,0.06]],"batb":[[0,1.71,5.44]],"ltp":1.71,"tv":0.2,"id":26354921}],"tv":0.23}]}
{"op":"mcm","clk":"11828340393","pt":1723498229599,"mc":[{"id":"1.231737525","rc":[{"batb":[[0,1.71,5.45]],"ltp":1.71,"tv":0.2,"id":26354921}]}]}
{"op":"mcm","clk":"11829320169","pt":1723526103469,"mc":[{"id":"1.231737525","rc":[{"batb":[[1,1.62,276.92],[2,1.25,100]],"ltp":1.71,"tv":0.2,"id":26354921}]}]}
{"op":"mcm","clk":"11829334582","pt":1723526837693,"mc":[{"id":"1.231737525","rc":[{"batl":[[0,2.6,8.6]],"ltp":2.42,"tv":0.03,"id":26354922},{"batb":[[1,1.63,13.87],[2,1.62,276.92]],"ltp":1.71,"tv":0.2,"id":26354921}]}]}
{"op":"mcm","clk":"11829339541","pt":1723527140461,"mc":[{"id":"1.231737525","rc":[{"batb":[[0,1.71,59.96]],"ltp":1.71,"tv":0.2,"id":26354921}]}]}
{"op":"mcm","clk":"11829339565","pt":1723527141950,"mc":[{"id":"1.231737525","rc":[{"batb":[[1,1.62,276.92],[2,1.25,100]],"ltp":1.71,"tv":0.2,"id":26354921}]}]}
{"op":"mcm","clk":"11829342477","pt":1723527250505,"mc":[{"id":"1.231737525","rc":[{"batb":[[0,1.72,7.45],[1,1.71,59.96],[2,1.62,276.92]],"ltp":1.71,"tv":0.2,"id":26354921}]}]}
{"op":"mcm","clk":"11829375717","pt":1723528555955,"mc":[{"id":"1.231737525","rc":[{"batb":[[2,1.25,100]],"ltp":1.71,"tv":0.2,"id":26354921}]}]}
{"op":"mcm","clk":"11829379325","pt":1723528764128,"mc":[{"id":"1.231737525","rc":[{"batb":[[0,1.71,59.96],[1,1.25,100],[2,1.06,25100]],"ltp":1.71,"tv":0.2,"id":26354921}]}]}
{"op":"mcm","clk":"11829499027","pt":1723533174806,"mc":[{"id":"1.231737525","rc":[{"batb":[[0,1.71,59.87]],"ltp":1.71,"tv":0.2,"id":26354921}]}]}
{"op":"mcm","clk":"11829762543","pt":1723538574797,"mc":[{"id":"1.231737525","rc":[{"batb":[[0,1.71,59.94]],"ltp":1.71,"tv":0.2,"id":26354921}]}]}
{"op":"mcm","clk":"11829922768","pt":1723540994861,"mc":[{"id":"1.231737525","rc":[{"trd":[[1.71,4.06]],"batb":[[0,1.71,59.94]],"ltp":1.71,"tv":4.19,"id":26354921}],"tv":4.22}]}
{"op":"mcm","clk":"11830138041","pt":1723543974787,"mc":[{"id":"1.231737525","rc":[{"batb":[[0,1.71,59.98]],"ltp":1.71,"tv":4.19,"id":26354921}]}]}
{"op":"mcm","clk":"11830326532","pt":1723546514878,"mc":[{"id":"1.231737525","rc":[{"batl":[[0,2.42,1]],"ltp":2.42,"tv":0.03,"id":26354922}]}]}
{"op":"mcm","clk":"11830489108","pt":1723548847654,"mc":[{"id":"1.231737525","rc":[{"batb":[[0,2.34,2.89]],"ltp":2.42,"tv":0.03,"id":26354922},{"batb":[[0,1.71,54.49],[1,1.68,5.69],[2,1.25,100]],"ltp":1.71,"tv":4.19,"id":26354921}]}]}
{"op":"mcm","clk":"11830940100","pt":1723554774791,"mc":[{"id":"1.231737525","rc":[{"batb":[[0,1.71,54.5]],"ltp":1.71,"tv":4.19,"id":26354921}]}]}
{"op":"mcm","clk":"11831011803","pt":1723555535073,"mc":[{"id":"1.231737525","rc":[{"trd":[[1.71,12.48]],"batb":[[0,1.71,50.29]],"ltp":1.71,"tv":12.62,"id":26354921}],"tv":12.65}]}
{"op":"mcm","clk":"11831067732","pt":1723556116012,"mc":[{"id":"1.231737525","rc":[{"batb":[[0,2.34,5.72]],"ltp":2.42,"tv":0.03,"id":26354922},{"batb":[[1,1.68,11.26]],"ltp":1.71,"tv":12.62,"id":26354921}]}]}
{"op":"mcm","clk":"11831067745","pt":1723556116113,"mc":[{"id":"1.231737525","rc":[{"batb":[[0,2.34,2.83]],"ltp":2.42,"tv":0.03,"id":26354922},{"batb":[[1,1.68,5.57]],"ltp":1.71,"tv":12.62,"id":26354921}]}]}
{"op":"mcm","clk":"11831424048","pt":1723560174789,"mc":[{"id":"1.231737525","rc":[{"trd":[[1.71,12.48]],"batb":[[0,1.71,50.29]],"ltp":1.71,"tv":12.61,"id":26354921}],"tv":12.64}]}
{"op":"mcm","clk":"11831805561","pt":1723564273483,"mc":[{"id":"1.231737525","rc":[{"trd":[[1.71,14.47]],"batb":[[0,1.71,49.23]],"ltp":1.71,"tv":14.6,"id":26354921}],"tv":14.63}]}
{"op":"mcm","clk":"11831932845","pt":1723565574793,"mc":[{"id":"1.231737525","rc":[{"batb":[[0,1.71,49.24]],"ltp":1.71,"tv":14.6,"id":26354921}]}]}
{"op":"mcm","clk":"11832408377","pt":1723570202337,"mc":[{"id":"1.231737525","rc":[{"batb":[[0,2.34,28.31]],"ltp":2.42,"tv":0.03,"id":26354922},{"trd":[[1.71,14.47]],"batb":[[0,1.71,49.27],[1,1.68,55.79]],"ltp":1.71,"tv":14.6,"id":26354921}],"tv":14.63}]}
{"op":"mcm","clk":"11832445821","pt":1723570523866,"mc":[{"id":"1.231737525","rc":[{"trd":[[1.71,35.32]],"batb":[[0,1.71,38.84]],"ltp":1.71,"tv":35.46,"id":26354921}],"tv":35.49}]}
{"op":"mcm","clk":"11833388721","pt":1723576374804,"mc":[{"id":"1.231737525","rc":[{"trd":[[1.71,35.31]],"batb":[[0,1.71,38.83]],"ltp":1.71,"tv":35.45,"id":26354921}],"tv":35.48}]}
{"op":"mcm","clk":"11833701797","pt":1723578202803,"mc":[{"id":"1.231737525","rc":[{"trd":[[1.71,41.32]],"batb":[[0,1.71,35.83]],"ltp":1.71,"tv":41.45,"id":26354921}],"tv":41.48}]}
{"op":"mcm","clk":"11833713742","pt":1723578307635,"mc":[{"id":"1.231737525","rc":[{"trd":[[1.71,61.31]],"batb":[[0,1.71,25.83]],"ltp":1.71,"tv":61.45,"id":26354921}],"tv":61.48}]}
{"op":"mcm","clk":"11834106787","pt":1723580908068,"mc":[{"id":"1.231737525","rc":[{"trd":[[1.71,113]],"batb":[[0,1.68,55.79],[1,1.25,100],[2,1.06,25100]],"batl":[[0,1.71,274.16],[1,1.85,1],[2,1.86,1]],"ltp":1.71,"tv":113.14,"id":26354921}],"tv":113.17}]}
{"op":"mcm","clk":"11834184365","pt":1723581643261,"mc":[{"id":"1.231737525","rc":[{"trd":[[2.42,1.03]],"batb":[[0,2.42,9.59],[1,2.34,28.31],[2,1.25,100]],"ltp":2.42,"tv":1.03,"id":26354922},{"trd":[[1.7,1.43]],"batl":[[0,1.7,12.03],[1,1.71,274.16],[2,1.85,1]],"ltp":1.7,"tv":114.56,"id":26354921}],"tv":115.59}]}
{"op":"mcm","clk":"11834444039","pt":1723587174800,"mc":[{"id":"1.231737525","rc":[{"trd":[[1.71,112.98]],"ltp":1.7,"tv":114.54,"id":26354921}],"tv":115.57}]}
{"op":"mcm","clk":"11834451498","pt":1723587179601,"mc":[{"id":"1.231737525","rc":[{"trd":[[1.7,11.73]],"batl":[[0,1.7,6.88]],"ltp":1.7,"tv":124.85,"id":26354921}],"tv":125.88}]}
{"op":"mcm","clk":"11834663567","pt":1723592574803,"mc":[{"id":"1.231737525","rc":[{"batb":[[0,2.42,9.59]],"ltp":2.42,"tv":1.03,"id":26354922},{"trd":[[1.7,11.73],[1.71,113]],"batl":[[0,1.7,6.88]],"ltp":1.7,"tv":124.87,"id":26354921}],"tv":125.9}]}
{"op":"mcm","clk":"11835004221","pt":1723597974788,"mc":[{"id":"1.231737525","rc":[{"batb":[[0,2.42,9.59]],"ltp":2.42,"tv":1.03,"id":26354922},{"trd":[[1.7,11.73],[1.71,113.05]],"batl":[[0,1.7,6.88]],"ltp":1.7,"tv":124.92,"id":26354921}],"tv":125.95}]}
{"op":"mcm","clk":"11835170450","pt":1723601111435,"mc":[{"id":"1.231737525","rc":[{"trd":[[1.71,113.03]],"batl":[[1,1.85,1],[2,1.86,1]],"ltp":1.7,"tv":124.89,"id":26354921}],"tv":125.92}]}
{"op":"mcm","clk":"11835170489","pt":1723601112208,"mc":[{"id":"1.231737525","rc":[{"batb":[[0,2.34,28.31],[1,1.25,100],[2,1.06,25100]],"ltp":2.42,"tv":1.03,"id":26354922},{"batl":[[0,1.85,1],[1,1.86,1],[2,1.86,0]],"ltp":1.7,"tv":124.89,"id":26354921}]}]}
{"op":"mcm","clk":"11835170577","pt":1723601114108,"mc":[{"id":"1.231737525","rc":[{"batb":[[0,1.69,6.62],[1,1.68,55.79],[2,1.25,100]],"ltp":1.7,"tv":124.89,"id":26354921}]}]}
{"op":"mcm","clk":"11835172015","pt":1723601142051,"mc":[{"id":"1.231737525","rc":[{"batl":[[0,1.7,200],[1,1.85,1],[2,1.86,1]],"ltp":1.7,"tv":124.89,"id":26354921}]}]}
{"op":"mcm","clk":"11835172541","pt":1723601152681,"mc":[{"id":"1.231737525","rc":[{"trd":[[1.69,13.24]],"batb":[[0,1.68,55.79],[1,1.25,100],[2,1.06,25100]],"batl":[[0,1.69,193.38]],"ltp":1.69,"tv":138.14,"id":26354921}],"tv":139.17}]}
{"op":"mcm","clk":"11835246629","pt":1723603348171,"mc":[{"id":"1.231737525","rc":[{"trd":[[1.69,27.5]],"batl":[[0,1.69,186.25]],"ltp":1.69,"tv":152.4,"id":26354921}],"tv":153.43}]}
{"op":"mcm","clk":"11835255736","pt":1723603393605,"mc":[{"id":"1.231737525","rc":[{"trd":[[1.69,37.86]],"batl":[[0,1.69,181.07]],"ltp":1.69,"tv":162.76,"id":26354921}],"tv":163.79}]}
{"op":"mcm","clk":"11835391486","pt":1723608774797,"mc":[{"id":"1.231737525","rc":[{"trd":[[1.69,37.86],[1.7,11.73],[1.71,112.96]],"ltp":1.69,"tv":162.69,"id":26354921}],"tv":163.72}]}
{"op":"mcm","clk":"11835475378","pt":1723614053982,"mc":[{"id":"1.231737525","rc":[{"trd":[[1.68,8],[1.71,112.94]],"batb":[[0,1.68,107.58]],"ltp":1.68,"tv":170.67,"id":26354921}],"tv":171.7}]}
{"op":"mcm","clk":"11835475381","pt":1723614054034,"mc":[{"id":"1.231737525","rc":[{"batb":[[0,1.68,55.79]],"ltp":1.68,"tv":170.67,"id":26354921}]}]}
{"op":"mcm","clk":"11835487636","pt":1723614381731,"mc":[{"id":"1.231737525","rc":[{"trd":[[1.68,18]],"batb":[[0,1.68,50.79]],"ltp":1.68,"tv":180.67,"id":26354921}],"tv":181.7}]}
{"op":"mcm","clk":"11835487681","pt":1723614385159,"mc":[{"id":"1.231737525","rc":[{"batb":[[0,1.68,55.79]],"ltp":1.68,"tv":180.67,"id":26354921}]}]}
{"op":"mcm","clk":"11835496021","pt":1723614873353,"mc":[{"id":"1.231737525","rc":[{"trd":[[1.69,52.13]],"batl":[[0,1.69,173.94]],"ltp":1.69,"tv":194.93,"id":26354921}],"tv":195.96}]}
{"op":"mcm","clk":"11835527631","pt":1723616039787,"mc":[{"id":"1.231737525","rc":[{"trd":[[1.71,113.06]],"batl":[[0,1.85,1],[1,1.86,1],[2,1.86,0]],"ltp":1.69,"tv":195.05,"id":26354921}],"tv":196.08}]}
{"op":"mcm","clk":"11835528031","pt":1723616058606,"mc":[{"id":"1.231737525","rc":[{"trd":[[1.68,129.58]],"batb":[[0,1.29,182.17]],"batl":[[0,1.68,120.21],[1,1.85,1],[2,1.86,1]],"ltp":1.68,"tv":306.63,"id":26354921}],"tv":307.66}]}
{"op":"mcm","clk":"11835528090","pt":1723616061110,"mc":[{"id":"1.231737525","rc":[{"batb":[[0,1.64,59.28],[1,1.29,182.17],[2,1.25,100]],"ltp":1.68,"tv":306.63,"id":26354921}]}]}
{"op":"mcm","clk":"11835534524","pt":1723616286568,"mc":[{"id":"1.231737525","rc":[{"batb":[[1,1.25,100],[2,1.06,25100]],"ltp":1.68,"tv":306.63,"id":26354921}]}]}
{"op":"mcm","clk":"11835535639","pt":1723616339739,"mc":[{"id":"1.231737525","rc":[{"trd":[[1.68,338.02]],"batl":[[0,1.68,15.99]],"ltp":1.68,"tv":515.07,"id":26354921}],"tv":516.1}]}
{"op":"mcm","clk":"11835543781","pt":1723616753532,"mc":[{"id":"1.231737525","rc":[{"batb":[[0,1.66,7],[1,1.64,59.28],[2,1.25,100]],"ltp":1.68,"tv":515.07,"id":26354921}]}]}
{"op":"mcm","clk":"11835543985","pt":1723616763484,"mc":[{"id":"1.231737525","rc":[{"batb":[[0,1.67,7]],"ltp":1.68,"tv":515.07,"id":26354921}]}]}
{"op":"mcm","clk":"11835544319","pt":1723616777376,"mc":[{"id":"1.231737525","rc":[{"batb":[[0,1.64,59.28],[1,1.25,100],[2,1.06,25100]],"ltp":1.68,"tv":515.07,"id":26354921}]}]}
{"op":"mcm","clk":"11835544662","pt":1723616790919,"mc":[{"id":"1.231737525","rc":[{"trd":[[1.68,352.06]],"batl":[[0,1.68,8.97]],"ltp":1.68,"tv":529.11,"id":26354921}],"tv":530.14}]}
{"op":"mcm","clk":"11835545581","pt":1723616826852,"mc":[{"id":"1.231737525","rc":[{"trd":[[1.68,370]],"batb":[[0,1.68,62.73],[1,1.64,59.28],[2,1.25,100]],"batl":[[0,1.85,1],[1,1.86,1],[2,1.86,0]],"ltp":1.68,"tv":547.05,"id":26354921}],"tv":548.08}]}
{"op":"mcm","clk":"11835570187","pt":1723617840199,"mc":[{"id":"1.231737525","rc":[{"batb":[[0,1.69,4.71],[1,1.68,62.73],[2,1.64,59.28]],"ltp":1.68,"tv":547.05,"id":26354921}]}]}
{"op":"mcm","clk":"11835622937","pt":1723619574788,"mc":[{"id":"1.231737525","rc":[{"trd":[[1.69,52.14],[1.7,11.75],[1.71,113.14]],"batb":[[0,1.69,4.72]],"ltp":1.68,"tv":547.17,"id":26354921}],"tv":548.2}]}
{"op":"mcm","clk":"11835830111","pt":1723624974793,"mc":[{"id":"1.231737525","rc":[{"trd":[[1.69,52.14],[1.7,11.75],[1.71,113.11]],"batb":[[0,1.69,4.72]],"ltp":1.68,"tv":547.14,"id":26354921}],"tv":548.17}]}
{"op":"mcm","clk":"11836075924","pt":1723629486589,"mc":[{"id":"1.231737525","rc":[{"batb":[[0,1.25,100],[1,1.06,25100],[2,1.05,40103]],"ltp":2.42,"tv":1.03,"id":26354922},{"trd":[[1.69,52.15],[1.7,11.76],[1.71,113.06]],"batb":[[0,1.69,4.73],[2,1.25,100]],"ltp":1.68,"tv":547.1,"id":26354921}],"tv":548.13}]}
{"op":"mcm","clk":"11836086876","pt":1723629624933,"mc":[{"id":"1.231737525","rc":[{"batb":[[0,1.26,33.16],[1,1.25,100],[2,1.06,25100]],"ltp":2.42,"tv":1.03,"id":26354922},{"batb":[[0,1.7,12.32],[1,1.69,4.73],[2,1.68,62.73]],"ltp":1.68,"tv":547.1,"id":26354921}]}]}
{"op":"mcm","clk":"11836086997","pt":1723629626349,"mc":[{"id":"1.231737525","rc":[{"batb":[[1,1.68,62.73],[2,1.25,100]],"ltp":1.68,"tv":547.1,"id":26354921}]}]}
{"op":"mcm","clk":"11836092795","pt":1723629698886,"mc":[{"id":"1.231737525","rc":[{"batl":[[0,1.82,250],[1,1.85,1],[2,1.86,1]],"ltp":1.68,"tv":547.1,"id":26354921}]}]}
{"op":"mcm","clk":"11836104768","pt":1723629856781,"mc":[{"id":"1.231737525","rc":[{"batl":[[0,1.8,12.91],[1,1.82,250],[2,1.85,1]],"ltp":1.68,"tv":547.1,"id":26354921}]}]}
{"op":"mcm","clk":"11836108626","pt":1723629909554,"mc":[{"id":"1.231737525","rc":[{"batl":[[1,1.81,17.16],[2,1.82,250]],"ltp":1.68,"tv":547.1,"id":26354921}]}]}
{"op":"mcm","clk":"11836154487","pt":1723630465575,"mc":[{"id":"1.231737525","rc":[{"batb":[[0,1.7,49.2]],"ltp":1.68,"tv":547.1,"id":26354921}]}]}
{"op":"mcm","clk":"11836227208","pt":1723631425181,"mc":[{"id":"1.231737525","rc":[{"batb":[[0,1.25,100],[1,1.06,25100],[2,1.05,40103]],"ltp":2.42,"tv":1.03,"id":26354922},{"batb":[[0,1.7,36.88]],"ltp":1.68,"tv":547.1,"id":26354921}]}]}
{"op":"mcm","clk":"11836257535","pt":1723631768072,"mc":[{"id":"1.231737525","rc":[{"batb":[[0,2.34,28.31],[1,1.25,100],[2,1.06,25100]],"ltp":2.42,"tv":1.03,"id":26354922},{"batb":[[1,1.68,118.52]],"ltp":1.68,"tv":547.1,"id":26354921}]}]}
{"op":"mcm","clk":"11836258166","pt":1723631771142,"mc":[{"id":"1.231737525","rc":[{"batl":[[1,1.82,250],[2,1.85,1]],"ltp":1.68,"tv":547.1,"id":26354921}]}]}
{"op":"mcm","clk":"11836551538","pt":1723635774798,"mc":[{"id":"1.231737525","rc":[{"trd":[[1.69,52.15],[1.7,11.76],[1.71,113.08]],"batb":[[0,1.7,36.89]],"batl":[[0,1.8,12.91]],"ltp":1.68,"tv":547.13,"id":26354921}],"tv":548.16}]}
{"op":"mcm","clk":"11836559174","pt":1723635783686,"mc":[{"id":"1.231737525","rc":[{"trd":[[1.7,31.76]],"batb":[[0,1.7,26.89]],"ltp":1.7,"tv":567.13,"id":26354921}],"tv":568.16}]}
{"op":"mcm","clk":"11836566041","pt":1723635894536,"mc":[{"id":"1.231737525","rc":[{"batl":[[0,1.79,36.06],[1,1.8,12.91],[2,1.82,250]],"ltp":1.7,"tv":567.13,"id":26354921}]}]}
{"op":"mcm","clk":"11836567099","pt":1723635911058,"mc":[{"id":"1.231737525","rc":[{"batl":[[0,1.8,12.91],[1,1.82,250],[2,1.85,1]],"ltp":1.7,"tv":567.13,"id":26354921}]}]}
{"op":"mcm","clk":"11836569163","pt":1723635939501,"mc":[{"id":"1.231737525","rc":[{"batl":[[0,1.79,36.06],[1,1.8,12.91],[2,1.82,250]],"ltp":1.7,"tv":567.13,"id":26354921}]}]}
{"op":"mcm","clk":"11836570765","pt":1723635964218,"mc":[{"id":"1.231737525","rc":[{"batl":[[2,1.81,16.23]],"ltp":1.7,"tv":567.13,"id":26354921}]}]}
{"op":"mcm","clk":"11836572610","pt":1723635989317,"mc":[{"id":"1.231737525","rc":[{"batb":[[2,1.59,36.06]],"ltp":1.7,"tv":567.13,"id":26354921}]}]}
{"op":"mcm","clk":"11836755866","pt":1723638733502,"mc":[{"id":"1.231737525","rc":[{"trd":[[1.69,52.15],[1.7,35.74],[1.71,113.01]],"batb":[[0,1.7,24.86]],"batl":[[1,1.8,12.89]],"ltp":1.7,"tv":571.04,"id":26354921}],"tv":572.07}]}
{"op":"mcm","clk":"11836874239","pt":1723640539431,"mc":[{"id":"1.231737525","rc":[{"batb":[[0,2.32,28.74]],"ltp":2.42,"tv":1.03,"id":26354922},{"trd":[[1.69,52.15],[1.7,35.75],[1.71,113.02]],"batb":[[0,1.7,24.86],[1,1.69,54.98],[2,1.68,62.73]],"batl":[[1,1.8,12.9]],"ltp":1.7,"tv":571.05,"id":26354921}],"tv":572.08}]}
{"op":"mcm","clk":"11837013491","pt":1723642516726,"mc":[{"id":"1.231737525","rc":[{"batb":[[0,2.32,31.11]],"ltp":2.42,"tv":1.03,"id":26354922},{"batb":[[1,1.69,59.52]],"ltp":1.7,"tv":571.05,"id":26354921}]}]}
{"op":"mcm","clk":"11837086968","pt":1723643704657,"mc":[{"id":"1.231737525","rc":[{"batl":[[0,1.75,12.9],[1,1.79,36.06],[2,1.8,12.9]],"ltp":1.7,"tv":571.05,"id":26354921}]}]}
{"op":"mcm","clk":"11837088028","pt":1723643724384,"mc":[{"id":"1.231737525","rc":[{"batl":[[0,1.79,36.06],[1,1.8,12.9],[2,1.81,16.23]],"ltp":1.7,"tv":571.05,"id":26354921}]}]}
{"op":"mcm","clk":"11837305180","pt":1723646574802,"mc":[{"id":"1.231737525","rc":[{"trd":[[1.69,52.16],[1.7,35.73],[1.71,112.9]],"batb":[[0,1.7,24.81]],"batl":[[1,1.8,12.87]],"ltp":1.7,"tv":570.92,"id":26354921}],"tv":571.95}]}
{"op":"mcm","clk":"11837576820","pt":1723649113997,"mc":[{"id":"1.231737525","rc":[{"trd":[[1.69,52.15],[1.7,35.73],[1.71,112.93]],"batb":[[0,1.7,24.82]],"batl":[[0,1.76,40],[1,1.79,36.06],[2,1.8,12.88]],"ltp":1.7,"tv":570.94,"id":26354921}],"tv":571.97}]}
{"op":"mcm","clk":"11837597501","pt":1723649325656,"mc":[{"id":"1.231737525","rc":[{"batl":[[0,1.75,6.09],[1,1.76,40],[2,1.79,36.06]],"ltp":1.7,"tv":570.94,"id":26354921}]}]}
{"op":"mcm","clk":"11837882338","pt":1723651974808,"mc":[{"id":"1.231737525","rc":[{"trd":[[1.69,52.15],[1.7,35.72],[1.71,112.91]],"batb":[[0,1.7,24.81]],"batl":[[0,1.75,6.08]],"ltp":1.7,"tv":570.92,"id":26354921}],"tv":571.95}]}
{"op":"mcm","clk":"11838053420","pt":1723653263050,"mc":[{"id":"1.231737525","rc":[{"trd":[[1.69,62.53],[1.7,85.34]],"batb":[[0,1.69,54.33],[1,1.68,62.73],[2,1.6,1283]],"ltp":1.69,"tv":630.92,"id":26354921}],"tv":631.95}]}
{"op":"mcm","clk":"11838053737","pt":1723653265237,"mc":[{"id":"1.231737525","rc":[{"batb":[[0,1.69,59.52]],"ltp":1.69,"tv":630.92,"id":26354921}]}]}
{"op":"mcm","clk":"11838057112","pt":1723653290697,"mc":[{"id":"1.231737525","rc":[{"batl":[[1,1.79,36.06],[2,1.8,12.87]],"ltp":1.69,"tv":630.92,"id":26354921}]}]}
{"op":"mcm","clk":"11838057298","pt":1723653292186,"mc":[{"id":"1.231737525","rc":[{"batl":[[0,1.79,36.06],[1,1.8,12.87],[2,1.81,16.23]],"ltp":1.69,"tv":630.92,"id":26354921}]}]}
{"op":"mcm","clk":"11838066801","pt":1723653362987,"mc":[{"id":"1.231737525","rc":[{"batb":[[2,1.1,15000]],"ltp":2.42,"tv":1.03,"id":26354922}]}]}
{"op":"mcm","clk":"11838067040","pt":1723653364762,"mc":[{"id":"1.231737525","rc":[{"batb":[[2,1.1,25000]],"ltp":2.42,"tv":1.03,"id":26354922}]}]}
{"op":"mcm","clk":"11838082224","pt":1723653476568,"mc":[{"id":"1.231737525","rc":[{"batb":[[0,1.7,4.47],[1,1.69,59.52],[2,1.68,62.73]],"ltp":1.69,"tv":630.92,"id":26354921}]}]}
{"op":"mcm","clk":"11838087137","pt":1723653511973,"mc":[{"id":"1.231737525","rc":[{"batl":[[0,1.79,72.12]],"ltp":1.69,"tv":630.92,"id":26354921}]}]}
{"op":"mcm","clk":"11838179889","pt":1723654177650,"mc":[{"id":"1.231737525","rc":[{"trd":[[2.32,0.76]],"batb":[[0,2.32,30.35]],"ltp":2.32,"tv":1.79,"id":26354922},{"trd":[[1.76,1]],"ltp":1.76,"tv":631.92,"id":26354921}],"tv":633.71}]}
{"op":"mcm","clk":"11838180021","pt":1723654178542,"mc":[{"id":"1.231737525","rc":[{"batb":[[0,2.32,31.11]],"ltp":2.32,"tv":1.79,"id":26354922}]}]}
{"op":"mcm","clk":"11838184162","pt":1723654209875,"mc":[{"id":"1.231737525","rc":[{"trd":[[1.7,93.65]],"batb":[[0,1.69,59.84],[1,1.68,62.73],[2,1.62,36.06]],"ltp":1.7,"tv":640.22,"id":26354921}],"tv":642.01}]}
{"op":"mcm","clk":"11838184228","pt":1723654210389,"mc":[{"id":"1.231737525","rc":[{"batb":[[0,1.69,59.52]],"ltp":1.7,"tv":640.22,"id":26354921}]}]}
{"op":"mcm","clk":"11838184540","pt":1723654212677,"mc":[{"id":"1.231737525","rc":[{"batl":[[0,1.75,4.03],[1,1.79,72.12],[2,1.8,12.87]],"ltp":1.7,"tv":640.22,"id":26354921}]}]}
{"op":"mcm","clk":"11838186711","pt":1723654229016,"mc":[{"id":"1.231737525","rc":[{"batb":[[2,1.63,138.46]],"ltp":1.7,"tv":640.22,"id":26354921}]}]}
{"op":"mcm","clk":"11838288932","pt":1723655056570,"mc":[{"id":"1.231737525","rc":[{"trd":[[1.69,62.53],[1.7,93.63],[1.71,112.88]],"batl":[[0,1.75,4.03],[2,1.8,12.86]],"ltp":1.7,"tv":640.18,"id":26354921}],"tv":641.97}]}
{"op":"mcm","clk":"11838371916","pt":1723655620977,"mc":[{"id":"1.231737525","rc":[{"batb":[[0,2.34,20],[1,2.32,31.11],[2,1.25,100]],"ltp":2.32,"tv":1.79,"id":26354922}]}]}
{"op":"mcm","clk":"11838371944","pt":1723655621179,"mc":[{"id":"1.231737525","rc":[{"batb":[[0,2.34,30]],"ltp":2.32,"tv":1.79,"id":26354922}]}]}
{"op":"mcm","clk":"11838400432","pt":1723655805490,"mc":[{"id":"1.231737525","rc":[{"batl":[[0,1.72,68.54],[1,1.75,4.03],[2,1.79,72.12]],"ltp":1.7,"tv":640.18,"id":26354921}]}]}
{"op":"mcm","clk":"11838400737","pt":1723655807473,"mc":[{"id":"1.231737525","rc":[{"batl":[[0,1.71,4.13],[1,1.72,68.54]],"ltp":1.7,"tv":640.18,"id":26354921}]}]}
{"op":"mcm","clk":"11838401453","pt":1723655812197,"mc":[{"id":"1.231737525","rc":[{"batl":[[2,1.75,68.54]],"ltp":1.7,"tv":640.18,"id":26354921}]}]}
{"op":"mcm","clk":"11838430158","pt":1723656018026,"mc":[{"id":"1.231737525","rc":[{"batl":[[0,1.71,9.59]],"ltp":1.7,"tv":640.18,"id":26354921}]}]}
{"op":"mcm","clk":"11838513186","pt":1723656640319,"mc":[{"id":"1.231737525","rc":[{"batl":[[0,1.7,10],[1,1.71,9.59],[2,1.72,68.54]],"ltp":1.7,"tv":640.18,"id":26354921}]}]}
{"op":"mcm","clk":"11838513392","pt":1723656641841,"mc":[{"id":"1.231737525","rc":[{"batl":[[0,1.7,20],[1,1.71,5.46]],"ltp":1.7,"tv":640.18,"id":26354921}]}]}
{"op":"mcm","clk":"11838513424","pt":1723656642051,"mc":[{"id":"1.231737525","rc":[{"batl":[[0,1.7,30]],"ltp":1.7,"tv":640.18,"id":26354921}]}]}
{"op":"mcm","clk":"11838520215","pt":1723656693473,"mc":[{"id":"1.231737525","rc":[{"batb":[[0,2.42,10],[1,2.34,30],[2,2.32,31.11]],"ltp":2.32,"tv":1.79,"id":26354922}]}]}
{"op":"mcm","clk":"11838520378","pt":1723656694785,"mc":[{"id":"1.231737525","rc":[{"batb":[[0,2.42,20],[2,1.25,100]],"ltp":2.32,"tv":1.79,"id":26354922},{"batb":[[0,1.68,62.73],[1,1.63,138.46],[2,1.62,36.06]],"ltp":1.7,"tv":640.18,"id":26354921}]}]}
{"op":"mcm","clk":"11838520426","pt":1723656695198,"mc":[{"id":"1.231737525","rc":[{"batl":[[0,1.69,4.18],[1,1.7,30],[2,1.71,5.46]],"ltp":1.7,"tv":640.18,"id":26354921}]}]}
{"op":"mcm","clk":"11838523452","pt":1723656719821,"mc":[{"id":"1.231737525","rc":[{"trd":[[1.68,495.46]],"batb":[[0,1.64,332.35]],"batl":[[0,1.68,37.27],[1,1.69,4.18],[2,1.7,30]],"ltp":1.68,"tv":765.64,"id":26354921}],"tv":767.43}]}
{"op":"mcm","clk":"11838523545","pt":1723656720512,"mc":[{"id":"1.231737525","rc":[{"batb":[[0,1.63,312.66],[1,1.62,36.06],[2,1.61,36.06]],"batl":[[0,1.69,4.18],[1,1.7,30],[2,1.71,5.46]],"ltp":1.68,"tv":765.64,"id":26354921}]}]}
{"op":"mcm","clk":"11838524040","pt":1723656724434,"mc":[{"id":"1.231737525","rc":[{"batb":[[2,2.32,31.11]],"ltp":2.32,"tv":1.79,"id":26354922},{"batb":[[0,1.63,138.46]],"ltp":1.68,"tv":765.64,"id":26354921}]}]}
{"op":"mcm","clk":"11838524642","pt":1723656729221,"mc":[{"id":"1.231737525","rc":[{"batl":[[0,1.69,14.18]],"ltp":1.68,"tv":765.64,"id":26354921}]}]}
{"op":"mcm","clk":"11838524838","pt":1723656730836,"mc":[{"id":"1.231737525","rc":[{"batl":[[2,1.72,68.54]],"ltp":1.68,"tv":765.64,"id":26354921}]}]}
{"op":"mcm","clk":"11838565047","pt":1723657020925,"mc":[{"id":"1.231737525","rc":[{"batb":[[0,2.46,20],[1,2.42,20],[2,2.34,30]],"ltp":2.32,"tv":1.79,"id":26354922}]}]}
{"op":"mcm","clk":"11838565419","pt":1723657023106,"mc":[{"id":"1.231737525","rc":[{"batb":[[1,2.44,10],[2,2.42,20]],"ltp":2.32,"tv":1.79,"id":26354922}]}]}
{"op":"mcm","clk":"11838580210","pt":1723657112734,"mc":[{"id":"1.231737525","rc":[{"batb":[[0,2.48,10],[1,2.46,20],[2,2.44,10]],"batl":[[0,2.58,6.52],[1,2.6,1.3]],"ltp":2.32,"tv":1.79,"id":26354922}]}]}
{"op":"mcm","clk":"11838580771","pt":1723657116006,"mc":[{"id":"1.231737525","rc":[{"batb":[[0,2.46,20],[1,2.44,10],[2,2.42,20]],"ltp":2.32,"tv":1.79,"id":26354922}]}]}
{"op":"mcm","clk":"11838585574","pt":1723657145543,"mc":[{"id":"1.231737525","rc":[{"batb":[[0,2.48,10],[1,2.46,20],[2,2.44,10]],"ltp":2.32,"tv":1.79,"id":26354922},{"batb":[[0,1.64,7.3],[1,1.63,138.46],[2,1.62,36.06]],"ltp":1.68,"tv":765.64,"id":26354921}]}]}
{"op":"mcm","clk":"11838586159","pt":1723657148946,"mc":[{"id":"1.231737525","rc":[{"batb":[[0,2.46,20],[1,2.44,10],[2,2.42,20]],"ltp":2.32,"tv":1.79,"id":26354922}]}]}
{"op":"mcm","clk":"11838608365","pt":1723657289354,"mc":[{"id":"1.231737525","rc":[{"batb":[[0,2.48,10],[1,2.46,20],[2,2.44,10]],"ltp":2.32,"tv":1.79,"id":26354922},{"batb":[[0,1.66,4.27],[1,1.64,7.3],[2,1.63,138.46]],"ltp":1.68,"tv":765.64,"id":26354921}]}]}
{"op":"mcm","clk":"11838608856","pt":1723657292616,"mc":[{"id":"1.231737525","rc":[{"batb":[[0,2.46,20],[1,2.44,10],[2,2.42,20]],"ltp":2.32,"tv":1.79,"id":26354922}]}]}
{"op":"mcm","clk":"11838640742","pt":1723657444908,"mc":[{"id":"1.231737525","rc":[{"batb":[[0,2.48,10],[1,2.46,20],[2,2.44,10]],"batl":[[0,2.58,10.85]],"ltp":2.32,"tv":1.79,"id":26354922}]}]}
{"op":"mcm","clk":"11838641229","pt":1723657448220,"mc":[{"id":"1.231737525","rc":[{"batb":[[0,2.46,20],[1,2.44,10],[2,2.42,20]],"ltp":2.32,"tv":1.79,"id":26354922}]}]}
{"op":"mcm","clk":"11838647565","pt":1723657488853,"mc":[{"id":"1.231737525","rc":[{"batl":[[0,1.69,26.18]],"ltp":1.68,"tv":765.64,"id":26354921}]}]}
{"op":"mcm","clk":"11838647594","pt":1723657489057,"mc":[{"id":"1.231737525","rc":[{"batb":[[0,2.48,10],[1,2.46,20],[2,2.44,10]],"ltp":2.32,"tv":1.79,"id":26354922}]}]}
{"op":"mcm","clk":"11838648107","pt":1723657492372,"mc":[{"id":"1.231737525","rc":[{"batb":[[0,2.46,20],[1,2.44,10],[2,2.42,20]],"ltp":2.32,"tv":1.79,"id":26354922}]}]}
{"op":"mcm","clk":"11838712050","pt":1723657919912,"mc":[{"id":"1.231737525","rc":[{"batb":[[0,2.48,10],[1,2.46,20],[2,2.44,10]],"ltp":2.32,"tv":1.79,"id":26354922}]}]}
{"op":"mcm","clk":"11838712490","pt":1723657923325,"mc":[{"id":"1.231737525","rc":[{"batb":[[0,2.46,20],[1,2.44,10],[2,2.42,20]],"ltp":2.32,"tv":1.79,"id":26354922}]}]}
{"op":"mcm","clk":"11838746734","pt":1723658197507,"mc":[{"id":"1.231737525","rc":[{"batb":[[0,2.48,10],[1,2.46,20],[2,2.44,10]],"ltp":2.32,"tv":1.79,"id":26354922},{"batb":[[1,1.64,232.3]],"ltp":1.68,"tv":765.64,"id":26354921}]}]}
{"op":"mcm","clk":"11838747129","pt":1723658200685,"mc":[{"id":"1.231737525","rc":[{"batb":[[0,2.46,20],[1,2.44,10],[2,2.42,20]],"ltp":2.32,"tv":1.79,"id":26354922}]}]}
{"op":"mcm","clk":"11838752957","pt":1723658249265,"mc":[{"id":"1.231737525","rc":[{"batb":[[0,2.48,10],[1,2.46,20],[2,2.44,10]],"ltp":2.32,"tv":1.79,"id":26354922},{"trd":[[1.66,8]],"batb":[[0,1.64,232.57],[1,1.63,138.46],[2,1.62,36.06]],"ltp":1.66,"tv":773.64,"id":26354921}],"tv":775.43}]}
{"op":"mcm","clk":"11838753380","pt":1723658252683,"mc":[{"id":"1.231737525","rc":[{"batb":[[0,2.46,20],[1,2.44,10],[2,2.42,20]],"ltp":2.32,"tv":1.79,"id":26354922}]}]}
{"op":"mcm","clk":"11838754375","pt":1723658260897,"mc":[{"id":"1.231737525","rc":[{"batb":[[0,2.48,10],[1,2.46,20],[2,2.44,10]],"ltp":2.32,"tv":1.79,"id":26354922},{"trd":[[1.64,31.46],[1.66,8.54]],"batb":[[0,1.64,216.57]],"ltp":1.64,"tv":805.64,"id":26354921}],"tv":807.43}]}
{"op":"mcm","clk":"11838754602","pt":1723658262824,"mc":[{"id":"1.231737525","rc":[{"batl":[[0,1.68,7.13],[1,1.69,26.18],[2,1.7,30]],"ltp":1.64,"tv":805.64,"id":26354921}]}]}
{"op":"mcm","clk":"11838754645","pt":1723658263207,"mc":[{"id":"1.231737525","rc":[{"batl":[[0,1.67,4.23],[1,1.68,7.13],[2,1.69,26.18]],"ltp":1.64,"tv":805.64,"id":26354921}]}]}
{"op":"mcm","clk":"11838754781","pt":1723658264227,"mc":[{"id":"1.231737525","rc":[{"batb":[[0,2.46,20],[1,2.44,10],[2,2.42,20]],"ltp":2.32,"tv":1.79,"id":26354922}]}]}
{"op":"mcm","clk":"11838754959","pt":1723658265633,"mc":[{"id":"1.231737525","rc":[{"batl":[[0,1.68,7.13],[1,1.69,26.18],[2,1.7,30]],"ltp":1.64,"tv":805.64,"id":26354921}]}]}
{"op":"mcm","clk":"11838766264","pt":1723658349797,"mc":[{"id":"1.231737525","rc":[{"batb":[[0,2.48,10],[1,2.46,20],[2,2.44,10]],"ltp":2.32,"tv":1.79,"id":26354922},{"batb":[[2,1.62,261.06]],"ltp":1.64,"tv":805.64,"id":26354921}]}]}
{"op":"mcm","clk":"11838766501","pt":1723658351717,"mc":[{"id":"1.231737525","rc":[{"batl":[[0,1.67,4.23],[1,1.68,7.13],[2,1.69,26.18]],"ltp":1.64,"tv":805.64,"id":26354921}]}]}
{"op":"mcm","clk":"11838766669","pt":1723658353008,"mc":[{"id":"1.231737525","rc":[{"batb":[[0,2.46,20],[1,2.44,10],[2,2.42,20]],"ltp":2.32,"tv":1.79,"id":26354922}]}]}
{"op":"mcm","clk":"11838766783","pt":1723658353801,"mc":[{"id":"1.231737525","rc":[{"batl":[[0,1.68,7.13],[1,1.69,26.18],[2,1.7,30]],"ltp":1.64,"tv":805.64,"id":26354921}]}]}
{"op":"mcm","clk":"11838767500","pt":1723658358732,"mc":[{"id":"1.231737525","rc":[{"batb":[[0,2.48,10],[1,2.46,20],[2,2.44,10]],"ltp":2.32,"tv":1.79,"id":26354922}]}]}
{"op":"mcm","clk":"11838767939","pt":1723658361942,"mc":[{"id":"1.231737525","rc":[{"batb":[[0,2.46,20],[1,2.44,10],[2,2.42,20]],"ltp":2.32,"tv":1.79,"id":26354922}]}]}
{"op":"mcm","clk":"11838771385","pt":1723658385631,"mc":[{"id":"1.231737525","rc":[{"batb":[[0,2.48,10],[1,2.46,20],[2,2.44,10]],"ltp":2.32,"tv":1.79,"id":26354922}]}]}
{"op":"mcm","clk":"11838771562","pt":1723658387041,"mc":[{"id":"1.231737525","rc":[{"batl":[[0,1.67,4.23],[1,1.68,7.13],[2,1.69,26.18]],"ltp":1.64,"tv":805.64,"id":26354921}]}]}
{"op":"mcm","clk":"11838771829","pt":1723658389062,"mc":[{"id":"1.231737525","rc":[{"batb":[[0,2.46,20],[1,2.44,10],[2,2.42,20]],"ltp":2.32,"tv":1.79,"id":26354922}]}]}
{"op":"mcm","clk":"11838771967","pt":1723658390156,"mc":[{"id":"1.231737525","rc":[{"batl":[[0,1.68,7.13],[1,1.69,26.18],[2,1.7,30]],"ltp":1.64,"tv":805.64,"id":26354921}]}]}
{"op":"mcm","clk":"11838785575","pt":1723658479971,"mc":[{"id":"1.231737525","rc":[{"batb":[[0,2.48,10],[1,2.46,20],[2,2.44,10]],"batl":[[0,2.58,10.85],[1,2.6,1.3]],"ltp":2.32,"tv":1.79,"id":26354922},{"trd":[[1.64,31.47],[1.69,62.53],[1.7,93.63],[1.71,112.89]],"batl":[[0,1.68,11.5],[1,1.69,26.18]],"ltp":1.64,"tv":805.66,"id":26354921}],"tv":807.45}]}
{"op":"mcm","clk":"11838786105","pt":1723658483471,"mc":[{"id":"1.231737525","rc":[{"batb":[[0,2.46,20],[1,2.44,10],[2,2.42,20]],"ltp":2.32,"tv":1.79,"id":26354922}]}]}
{"op":"mcm","clk":"11838839515","pt":1723658830882,"mc":[{"id":"1.231737525","rc":[{"batl":[[0,1.68,21.5]],"ltp":1.64,"tv":805.66,"id":26354921}]}]}
{"op":"mcm","clk":"11838839569","pt":1723658831299,"mc":[{"id":"1.231737525","rc":[{"batb":[[0,2.48,10],[1,2.46,20],[2,2.44,10]],"ltp":2.32,"tv":1.79,"id":26354922},{"batl":[[0,1.68,41.5]],"ltp":1.64,"tv":805.66,"id":26354921}]}]}
{"op":"mcm","clk":"11838839856","pt":1723658832999,"mc":[{"id":"1.231737525","rc":[{"batl":[[1,1.69,22]],"ltp":1.64,"tv":805.66,"id":26354921}]}]}
{"op":"mcm","clk":"11838840090","pt":1723658834481,"mc":[{"id":"1.231737525","rc":[{"batb":[[0,2.46,20],[1,2.44,10],[2,2.42,20]],"ltp":2.32,"tv":1.79,"id":26354922}]}]}
{"op":"mcm","clk":"11838981536","pt":1723659763566,"mc":[{"id":"1.231737525","rc":[{"batb":[[0,2.48,10],[1,2.46,20],[2,2.44,10]],"ltp":2.32,"tv":1.79,"id":26354922}]}]}
{"op":"mcm","clk":"11838981934","pt":1723659766938,"mc":[{"id":"1.231737525","rc":[{"batb":[[0,2.46,20],[1,2.44,10],[2,2.42,20]],"ltp":2.32,"tv":1.79,"id":26354922}]}]}
{"op":"mcm","clk":"11838996032","pt":1723659876283,"mc":[{"id":"1.231737525","rc":[{"batb":[[0,2.48,10],[1,2.46,20],[2,2.44,10]],"ltp":2.32,"tv":1.79,"id":26354922},{"trd":[[1.68,501.46]],"batl":[[0,1.68,38.51]],"ltp":1.68,"tv":811.66,"id":26354921}],"tv":813.45}]}
{"op":"mcm","clk":"11838996474","pt":1723659879701,"mc":[{"id":"1.231737525","rc":[{"batb":[[0,2.46,20],[1,2.44,10],[2,2.42,20]],"ltp":2.32,"tv":1.79,"id":26354922}]}]}
{"op":"mcm","clk":"11839038951","pt":1723660201362,"mc":[{"id":"1.231737525","rc":[{"batb":[[0,2.48,10],[1,2.46,20],[2,2.44,10]],"ltp":2.32,"tv":1.79,"id":26354922}]}]}
{"op":"mcm","clk":"11839039514","pt":1723660204770,"mc":[{"id":"1.231737525","rc":[{"batb":[[0,2.46,20],[1,2.44,10],[2,2.42,20]],"ltp":2.32,"tv":1.79,"id":26354922}]}]}
{"op":"mcm","clk":"11839148283","pt":1723661091869,"mc":[{"id":"1.231737525","rc":[{"batb":[[0,2.48,10],[1,2.46,20],[2,2.44,10]],"ltp":2.32,"tv":1.79,"id":26354922}]}]}
{"op":"mcm","clk":"11839148640","pt":1723661095051,"mc":[{"id":"1.231737525","rc":[{"batb":[[0,2.46,20],[1,2.44,10],[2,2.42,20]],"ltp":2.32,"tv":1.79,"id":26354922}]}]}
{"op":"mcm","clk":"11839157490","pt":1723661165657,"mc":[{"id":"1.231737525","rc":[{"batb":[[0,2.48,10],[1,2.46,20],[2,2.44,10]],"ltp":2.32,"tv":1.79,"id":26354922}]}]}
{"op":"mcm","clk":"11839157891","pt":1723661168988,"mc":[{"id":"1.231737525","rc":[{"batb":[[0,2.46,20],[1,2.44,10],[2,2.42,20]],"ltp":2.32,"tv":1.79,"id":26354922}]}]}
{"op":"mcm","clk":"11839165257","pt":1723661227660,"mc":[{"id":"1.231737525","rc":[{"batb":[[0,2.48,10],[1,2.46,20],[2,2.44,10]],"ltp":2.32,"tv":1.79,"id":26354922}]}]}
{"op":"mcm","clk":"11839165690","pt":1723661231061,"mc":[{"id":"1.231737525","rc":[{"batb":[[0,2.46,20],[1,2.44,10],[2,2.42,20]],"ltp":2.32,"tv":1.79,"id":26354922}]}]}
{"op":"mcm","clk":"11839174746","pt":1723661308104,"mc":[{"id":"1.231737525","rc":[{"batb":[[0,2.48,10],[1,2.46,20],[2,2.44,10]],"ltp":2.32,"tv":1.79,"id":26354922}]}]}
{"op":"mcm","clk":"11839175265","pt":1723661311601,"mc":[{"id":"1.231737525","rc":[{"batb":[[0,2.46,20],[1,2.44,10],[2,2.42,20]],"ltp":2.32,"tv":1.79,"id":26354922}]}]}
{"op":"mcm","clk":"11839177434","pt":1723661331759,"mc":[{"id":"1.231737525","rc":[{"batb":[[0,2.48,10],[1,2.46,20],[2,2.44,10]],"ltp":2.32,"tv":1.79,"id":26354922}]}]}
{"op":"mcm","clk":"11839177823","pt":1723661335112,"mc":[{"id":"1.231737525","rc":[{"batb":[[0,2.46,20],[1,2.44,10],[2,2.42,20]],"ltp":2.32,"tv":1.79,"id":26354922}]}]}
{"op":"mcm","clk":"11839184234","pt":1723661393094,"mc":[{"id":"1.231737525","rc":[{"batb":[[0,2.48,10],[1,2.46,20],[2,2.44,10]],"ltp":2.32,"tv":1.79,"id":26354922}]}]}
{"op":"mcm","clk":"11839184622","pt":1723661396591,"mc":[{"id":"1.231737525","rc":[{"batb":[[0,2.46,20],[1,2.44,10],[2,2.42,20]],"ltp":2.32,"tv":1.79,"id":26354922}]}]}
{"op":"mcm","clk":"11839188697","pt":1723661432055,"mc":[{"id":"1.231737525","rc":[{"batb":[[0,2.48,10],[1,2.46,20],[2,2.44,10]],"ltp":2.32,"tv":1.79,"id":26354922}]}]}
{"op":"mcm","clk":"11839189148","pt":1723661435454,"mc":[{"id":"1.231737525","rc":[{"batb":[[0,2.46,20],[1,2.44,10],[2,2.42,20]],"ltp":2.32,"tv":1.79,"id":26354922}]}]}
{"op":"mcm","clk":"11839191153","pt":1723661452482,"mc":[{"id":"1.231737525","rc":[{"batb":[[0,2.48,10],[1,2.46,20],[2,2.44,10]],"ltp":2.32,"tv":1.79,"id":26354922}]}]}
{"op":"mcm","clk":"11839191579","pt":1723661456073,"mc":[{"id":"1.231737525","rc":[{"batb":[[0,2.46,20],[1,2.44,10],[2,2.42,20]],"ltp":2.32,"tv":1.79,"id":26354922}]}]}
{"op":"mcm","clk":"11839191926","pt":1723661458982,"mc":[{"id":"1.231737525","rc":[{"batb":[[0,2.48,10],[1,2.46,20],[2,2.44,10]],"ltp":2.32,"tv":1.79,"id":26354922}]}]}
{"op":"mcm","clk":"11839192343","pt":1723661462493,"mc":[{"id":"1.231737525","rc":[{"batb":[[0,2.46,20],[1,2.44,10],[2,2.42,20]],"ltp":2.32,"tv":1.79,"id":26354922}]}]}
{"op":"mcm","clk":"11839192633","pt":1723661464986,"mc":[{"id":"1.231737525","rc":[{"batb":[[0,2.48,10],[1,2.46,20],[2,2.44,10]],"ltp":2.32,"tv":1.79,"id":26354922}]}]}
{"op":"mcm","clk":"11839193025","pt":1723661468181,"mc":[{"id":"1.231737525","rc":[{"batb":[[0,2.46,20],[1,2.44,10],[2,2.42,20]],"ltp":2.32,"tv":1.79,"id":26354922}]}]}
{"op":"mcm","clk":"11839193928","pt":1723661476001,"mc":[{"id":"1.231737525","rc":[{"batb":[[0,2.48,10],[1,2.46,20],[2,2.44,10]],"ltp":2.32,"tv":1.79,"id":26354922}]}]}
{"op":"mcm","clk":"11839194329","pt":1723661479379,"mc":[{"id":"1.231737525","rc":[{"batb":[[0,2.46,20],[1,2.44,10],[2,2.42,20]],"ltp":2.32,"tv":1.79,"id":26354922}]}]}
{"op":"mcm","clk":"11839197201","pt":1723661502935,"mc":[{"id":"1.231737525","rc":[{"batb":[[0,2.48,10],[1,2.46,20],[2,2.44,10]],"ltp":2.32,"tv":1.79,"id":26354922}]}]}
{"op":"mcm","clk":"11839197584","pt":1723661506123,"mc":[{"id":"1.231737525","rc":[{"batb":[[0,2.46,20],[1,2.44,10],[2,2.42,20]],"ltp":2.32,"tv":1.79,"id":26354922}]}]}
{"op":"mcm","clk":"11839198230","pt":1723661511839,"mc":[{"id":"1.231737525","rc":[{"batb":[[0,2.48,10],[1,2.46,20],[2,2.44,10]],"ltp":2.32,"tv":1.79,"id":26354922}]}]}
{"op":"mcm","clk":"11839198642","pt":1723661515227,"mc":[{"id":"1.231737525","rc":[{"batb":[[0,2.46,20],[1,2.44,10],[2,2.42,20]],"ltp":2.32,"tv":1.79,"id":26354922}]}]}
{"op":"mcm","clk":"11839202984","pt":1723661552878,"mc":[{"id":"1.231737525","rc":[{"batb":[[0,2.48,10],[1,2.46,20],[2,2.44,10]],"ltp":2.32,"tv":1.79,"id":26354922}]}]}
{"op":"mcm","clk":"11839203382","pt":1723661556108,"mc":[{"id":"1.231737525","rc":[{"batb":[[0,2.46,20],[1,2.44,10],[2,2.42,20]],"ltp":2.32,"tv":1.79,"id":26354922}]}]}
{"op":"mcm","clk":"11839353877","pt":1723662774796,"mc":[{"id":"1.231737525","rc":[{"trd":[[1.7,93.64],[1.71,112.89]],"ltp":1.68,"tv":811.66,"id":26354921}],"tv":813.45}]}
{"op":"mcm","clk":"11839581281","pt":1723664571403,"mc":[{"id":"1.231737525","rc":[{"batb":[[0,2.48,10],[1,2.46,20],[2,2.44,10]],"ltp":2.32,"tv":1.79,"id":26354922}]}]}
{"op":"mcm","clk":"11839581686","pt":1723664574685,"mc":[{"id":"1.231737525","rc":[{"batb":[[0,2.46,20],[1,2.44,10],[2,2.42,20]],"ltp":2.32,"tv":1.79,"id":26354922}]}]}
{"op":"mcm","clk":"11839661675","pt":1723665297525,"mc":[{"id":"1.231737525","rc":[{"batb":[[0,2.48,10],[1,2.46,20],[2,2.44,10]],"ltp":2.32,"tv":1.79,"id":26354922}]}]}
{"op":"mcm","clk":"11839662040","pt":1723665300828,"mc":[{"id":"1.231737525","rc":[{"batb":[[0,2.46,20],[1,2.44,10],[2,2.42,20]],"ltp":2.32,"tv":1.79,"id":26354922}]}]}
{"op":"mcm","clk":"11839754853","pt":1723666261929,"mc":[{"id":"1.231737525","rc":[{"batb":[[0,2.48,10],[1,2.46,20],[2,2.44,10]],"ltp":2.32,"tv":1.79,"id":26354922},{"trd":[[1.7,93.62],[1.71,112.86]],"ltp":1.68,"tv":811.61,"id":26354921}],"tv":813.4}]}
{"op":"mcm","clk":"11839755092","pt":1723666265232,"mc":[{"id":"1.231737525","rc":[{"batb":[[0,2.46,20],[1,2.44,10],[2,2.42,20]],"ltp":2.32,"tv":1.79,"id":26354922}]}]}
{"op":"mcm","clk":"11839755641","pt":1723666272445,"mc":[{"id":"1.231737525","rc":[{"batb":[[0,2.48,10],[1,2.46,20],[2,2.44,10]],"ltp":2.32,"tv":1.79,"id":26354922}]}]}
{"op":"mcm","clk":"11839755888","pt":1723666275739,"mc":[{"id":"1.231737525","rc":[{"batb":[[0,2.46,20],[1,2.44,10],[2,2.42,20]],"ltp":2.32,"tv":1.79,"id":26354922}]}]}
{"op":"mcm","clk":"11839756093","pt":1723666278366,"mc":[{"id":"1.231737525","rc":[{"batb":[[0,2.48,10],[1,2.46,20],[2,2.44,10]],"ltp":2.32,"tv":1.79,"id":26354922}]}]}
{"op":"mcm","clk":"11839756357","pt":1723666281668,"mc":[{"id":"1.231737525","rc":[{"batb":[[0,2.46,20],[1,2.44,10],[2,2.42,20]],"ltp":2.32,"tv":1.79,"id":26354922}]}]}
{"op":"mcm","clk":"11839756497","pt":1723666283852,"mc":[{"id":"1.231737525","rc":[{"batb":[[0,2.48,10],[1,2.46,20],[2,2.44,10]],"ltp":2.32,"tv":1.79,"id":26354922}]}]}
{"op":"mcm","clk":"11839756741","pt":1723666287370,"mc":[{"id":"1.231737525","rc":[{"batb":[[0,2.46,20],[1,2.44,10],[2,2.42,20]],"ltp":2.32,"tv":1.79,"id":26354922}]}]}
{"op":"mcm","clk":"11839756984","pt":1723666290564,"mc":[{"id":"1.231737525","rc":[{"batb":[[0,2.48,10],[1,2.46,20],[2,2.44,10]],"ltp":2.32,"tv":1.79,"id":26354922}]}]}
{"op":"mcm","clk":"11839757209","pt":1723666293763,"mc":[{"id":"1.231737525","rc":[{"batb":[[0,2.46,20],[1,2.44,10],[2,2.42,20]],"ltp":2.32,"tv":1.79,"id":26354922}]}]}
{"op":"mcm","clk":"11839757434","pt":1723666296966,"mc":[{"id":"1.231737525","rc":[{"batb":[[0,2.48,10],[1,2.46,20],[2,2.44,10]],"ltp":2.32,"tv":1.79,"id":26354922}]}]}
{"op":"mcm","clk":"11839757687","pt":1723666300267,"mc":[{"id":"1.231737525","rc":[{"batb":[[0,2.46,20],[1,2.44,10],[2,2.42,20]],"ltp":2.32,"tv":1.79,"id":26354922}]}]}
{"op":"mcm","clk":"11839757851","pt":1723666302581,"mc":[{"id":"1.231737525","rc":[{"batb":[[0,2.48,10],[1,2.46,20],[2,2.44,10]],"ltp":2.32,"tv":1.79,"id":26354922}]}]}
{"op":"mcm","clk":"11839758092","pt":1723666305875,"mc":[{"id":"1.231737525","rc":[{"batb":[[0,2.46,20],[1,2.44,10],[2,2.42,20]],"ltp":2.32,"tv":1.79,"id":26354922}]}]}
{"op":"mcm","clk":"11839758366","pt":1723666309385,"mc":[{"id":"1.231737525","rc":[{"batb":[[0,2.48,10],[1,2.46,20],[2,2.44,10]],"ltp":2.32,"tv":1.79,"id":26354922}]}]}
{"op":"mcm","clk":"11839758623","pt":1723666312780,"mc":[{"id":"1.231737525","rc":[{"batb":[[0,2.46,20],[1,2.44,10],[2,2.42,20]],"ltp":2.32,"tv":1.79,"id":26354922}]}]}
{"op":"mcm","clk":"11839758783","pt":1723666314985,"mc":[{"id":"1.231737525","rc":[{"batb":[[0,2.48,10],[1,2.46,20],[2,2.44,10]],"ltp":2.32,"tv":1.79,"id":26354922}]}]}
{"op":"mcm","clk":"11839759052","pt":1723666318492,"mc":[{"id":"1.231737525","rc":[{"batb":[[0,2.46,20],[1,2.44,10],[2,2.42,20]],"ltp":2.32,"tv":1.79,"id":26354922}]}]}
{"op":"mcm","clk":"11839759216","pt":1723666320815,"mc":[{"id":"1.231737525","rc":[{"batb":[[0,2.48,10],[1,2.46,20],[2,2.44,10]],"ltp":2.32,"tv":1.79,"id":26354922}]}]}
{"op":"mcm","clk":"11839759481","pt":1723666324113,"mc":[{"id":"1.231737525","rc":[{"batb":[[0,2.46,20],[1,2.44,10],[2,2.42,20]],"ltp":2.32,"tv":1.79,"id":26354922}]}]}
{"op":"mcm","clk":"11839759680","pt":1723666326706,"mc":[{"id":"1.231737525","rc":[{"batb":[[0,2.48,10],[1,2.46,20],[2,2.44,10]],"ltp":2.32,"tv":1.79,"id":26354922}]}]}
{"op":"mcm","clk":"11839759919","pt":1723666330039,"mc":[{"id":"1.231737525","rc":[{"batb":[[0,2.46,20],[1,2.44,10],[2,2.42,20]],"ltp":2.32,"tv":1.79,"id":26354922}]}]}
{"op":"mcm","clk":"11839760121","pt":1723666332314,"mc":[{"id":"1.231737525","rc":[{"batb":[[0,2.48,10],[1,2.46,20],[2,2.44,10]],"ltp":2.32,"tv":1.79,"id":26354922}]}]}
{"op":"mcm","clk":"11839760396","pt":1723666335727,"mc":[{"id":"1.231737525","rc":[{"batb":[[0,2.46,20],[1,2.44,10],[2,2.42,20]],"ltp":2.32,"tv":1.79,"id":26354922}]}]}
{"op":"mcm","clk":"11839760574","pt":1723666338045,"mc":[{"id":"1.231737525","rc":[{"batb":[[0,2.48,10],[1,2.46,20],[2,2.44,10]],"ltp":2.32,"tv":1.79,"id":26354922}]}]}
{"op":"mcm","clk":"11839760836","pt":1723666341417,"mc":[{"id":"1.231737525","rc":[{"batb":[[0,2.46,20],[1,2.44,10],[2,2.42,20]],"ltp":2.32,"tv":1.79,"id":26354922}]}]}
{"op":"mcm","clk":"11839761001","pt":1723666343637,"mc":[{"id":"1.231737525","rc":[{"batb":[[0,2.48,10],[1,2.46,20],[2,2.44,10]],"ltp":2.32,"tv":1.79,"id":26354922}]}]}
{"op":"mcm","clk":"11839761257","pt":1723666346961,"mc":[{"id":"1.231737525","rc":[{"batb":[[0,2.46,20],[1,2.44,10],[2,2.42,20]],"ltp":2.32,"tv":1.79,"id":26354922}]}]}
{"op":"mcm","clk":"11839761489","pt":1723666350321,"mc":[{"id":"1.231737525","rc":[{"batb":[[0,2.48,10],[1,2.46,20],[2,2.44,10]],"ltp":2.32,"tv":1.79,"id":26354922}]}]}
{"op":"mcm","clk":"11839761747","pt":1723666353327,"mc":[{"id":"1.231737525","rc":[{"batb":[[0,2.46,20],[1,2.44,10],[2,2.42,20]],"ltp":2.32,"tv":1.79,"id":26354922}]}]}
{"op":"mcm","clk":"11839761925","pt":1723666355650,"mc":[{"id":"1.231737525","rc":[{"batb":[[0,2.48,10],[1,2.46,20],[2,2.44,10]],"ltp":2.32,"tv":1.79,"id":26354922}]}]}
{"op":"mcm","clk":"11839762189","pt":1723666359161,"mc":[{"id":"1.231737525","rc":[{"batb":[[0,2.46,20],[1,2.44,10],[2,2.42,20]],"ltp":2.32,"tv":1.79,"id":26354922}]}]}
{"op":"mcm","clk":"11839762371","pt":1723666361449,"mc":[{"id":"1.231737525","rc":[{"batb":[[0,2.48,10],[1,2.46,20],[2,2.44,10]],"ltp":2.32,"tv":1.79,"id":26354922}]}]}
{"op":"mcm","clk":"11839762670","pt":1723666364746,"mc":[{"id":"1.231737525","rc":[{"batb":[[0,2.46,20],[1,2.44,10],[2,2.42,20]],"ltp":2.32,"tv":1.79,"id":26354922}]}]}
{"op":"mcm","clk":"11839762847","pt":1723666367057,"mc":[{"id":"1.231737525","rc":[{"batb":[[0,2.48,10],[1,2.46,20],[2,2.44,10]],"ltp":2.32,"tv":1.79,"id":26354922}]}]}
{"op":"mcm","clk":"11839763141","pt":1723666370363,"mc":[{"id":"1.231737525","rc":[{"batb":[[0,2.46,20],[1,2.44,10],[2,2.42,20]],"ltp":2.32,"tv":1.79,"id":26354922}]}]}
{"op":"mcm","clk":"11839763326","pt":1723666372685,"mc":[{"id":"1.231737525","rc":[{"batb":[[0,2.48,10],[1,2.46,20],[2,2.44,10]],"ltp":2.32,"tv":1.79,"id":26354922}]}]}
{"op":"mcm","clk":"11839763637","pt":1723666375950,"mc":[{"id":"1.231737525","rc":[{"batb":[[0,2.46,20],[1,2.44,10],[2,2.42,20]],"ltp":2.32,"tv":1.79,"id":26354922}]}]}
{"op":"mcm","clk":"11839763831","pt":1723666378268,"mc":[{"id":"1.231737525","rc":[{"batb":[[0,2.48,10],[1,2.46,20],[2,2.44,10]],"ltp":2.32,"tv":1.79,"id":26354922}]}]}
{"op":"mcm","clk":"11839764173","pt":1723666381670,"mc":[{"id":"1.231737525","rc":[{"batb":[[0,2.46,20],[1,2.44,10],[2,2.42,20]],"ltp":2.32,"tv":1.79,"id":26354922}]}]}
{"op":"mcm","clk":"11839764393","pt":1723666384098,"mc":[{"id":"1.231737525","rc":[{"batb":[[0,2.48,10],[1,2.46,20],[2,2.44,10]],"ltp":2.32,"tv":1.79,"id":26354922}]}]}
{"op":"mcm","clk":"11839764688","pt":1723666387496,"mc":[{"id":"1.231737525","rc":[{"batb":[[0,2.46,20],[1,2.44,10],[2,2.42,20]],"ltp":2.32,"tv":1.79,"id":26354922}]}]}
{"op":"mcm","clk":"11839764867","pt":1723666389786,"mc":[{"id":"1.231737525","rc":[{"batb":[[0,2.48,10],[1,2.46,20],[2,2.44,10]],"ltp":2.32,"tv":1.79,"id":26354922}]}]}
{"op":"mcm","clk":"11839765158","pt":1723666393293,"mc":[{"id":"1.231737525","rc":[{"batb":[[0,2.46,20],[1,2.44,10],[2,2.42,20]],"ltp":2.32,"tv":1.79,"id":26354922}]}]}
{"op":"mcm","clk":"11839765340","pt":1723666395601,"mc":[{"id":"1.231737525","rc":[{"batb":[[0,2.48,10],[1,2.46,20],[2,2.44,10]],"ltp":2.32,"tv":1.79,"id":26354922}]}]}
{"op":"mcm","clk":"11839765617","pt":1723666398973,"mc":[{"id":"1.231737525","rc":[{"batb":[[0,2.46,20],[1,2.44,10],[2,2.42,20]],"ltp":2.32,"tv":1.79,"id":26354922}]}]}
{"op":"mcm","clk":"11839765803","pt":1723666401391,"mc":[{"id":"1.231737525","rc":[{"batb":[[0,2.48,10],[1,2.46,20],[2,2.44,10]],"ltp":2.32,"tv":1.79,"id":26354922}]}]}
{"op":"mcm","clk":"11839766103","pt":1723666404696,"mc":[{"id":"1.231737525","rc":[{"batb":[[0,2.46,20],[1,2.44,10],[2,2.42,20]],"ltp":2.32,"tv":1.79,"id":26354922}]}]}
{"op":"mcm","clk":"11839766386","pt":1723666407702,"mc":[{"id":"1.231737525","rc":[{"batb":[[0,2.48,10],[1,2.46,20],[2,2.44,10]],"ltp":2.32,"tv":1.79,"id":26354922}]}]}
{"op":"mcm","clk":"11839766690","pt":1723666411010,"mc":[{"id":"1.231737525","rc":[{"batb":[[0,2.46,20],[1,2.44,10],[2,2.42,20]],"ltp":2.32,"tv":1.79,"id":26354922}]}]}
{"op":"mcm","clk":"11839766956","pt":1723666413225,"mc":[{"id":"1.231737525","rc":[{"batb":[[0,2.48,10],[1,2.46,20],[2,2.44,10]],"ltp":2.32,"tv":1.79,"id":26354922}]}]}
{"op":"mcm","clk":"11839767215","pt":1723666416385,"mc":[{"id":"1.231737525","rc":[{"batb":[[0,2.46,20],[1,2.44,10],[2,2.42,20]],"ltp":2.32,"tv":1.79,"id":26354922}]}]}
{"op":"mcm","clk":"11839767550","pt":1723666420296,"mc":[{"id":"1.231737525","rc":[{"batb":[[0,2.48,10],[1,2.46,20],[2,2.44,10]],"ltp":2.32,"tv":1.79,"id":26354922}]}]}
{"op":"mcm","clk":"11839767859","pt":1723666423600,"mc":[{"id":"1.231737525","rc":[{"batb":[[0,2.46,20],[1,2.44,10],[2,2.42,20]],"ltp":2.32,"tv":1.79,"id":26354922}]}]}
{"op":"mcm","clk":"11839768052","pt":1723666425930,"mc":[{"id":"1.231737525","rc":[{"batb":[[0,2.48,10],[1,2.46,20],[2,2.44,10]],"ltp":2.32,"tv":1.79,"id":26354922}]}]}
{"op":"mcm","clk":"11839768363","pt":1723666429265,"mc":[{"id":"1.231737525","rc":[{"batb":[[0,2.46,20],[1,2.44,10],[2,2.42,20]],"ltp":2.32,"tv":1.79,"id":26354922}]}]}
{"op":"mcm","clk":"11839768587","pt":1723666431856,"mc":[{"id":"1.231737525","rc":[{"batb":[[0,2.48,10],[1,2.46,20],[2,2.44,10]],"ltp":2.32,"tv":1.79,"id":26354922}]}]}
{"op":"mcm","clk":"11839768888","pt":1723666435383,"mc":[{"id":"1.231737525","rc":[{"batb":[[0,2.46,20],[1,2.44,10],[2,2.42,20]],"ltp":2.32,"tv":1.79,"id":26354922}]}]}
{"op":"mcm","clk":"11839769129","pt":1723666437676,"mc":[{"id":"1.231737525","rc":[{"batb":[[0,2.48,10],[1,2.46,20],[2,2.44,10]],"ltp":2.32,"tv":1.79,"id":26354922}]}]}
{"op":"mcm","clk":"11839769509","pt":1723666441147,"mc":[{"id":"1.231737525","rc":[{"batb":[[0,2.46,20],[1,2.44,10],[2,2.42,20]],"ltp":2.32,"tv":1.79,"id":26354922}]}]}
{"op":"mcm","clk":"11839769703","pt":1723666443490,"mc":[{"id":"1.231737525","rc":[{"batb":[[0,2.48,10],[1,2.46,20],[2,2.44,10]],"ltp":2.32,"tv":1.79,"id":26354922}]}]}
{"op":"mcm","clk":"11839769993","pt":1723666446846,"mc":[{"id":"1.231737525","rc":[{"batb":[[0,2.46,20],[1,2.44,10],[2,2.42,20]],"ltp":2.32,"tv":1.79,"id":26354922}]}]}
{"op":"mcm","clk":"11839770171","pt":1723666449173,"mc":[{"id":"1.231737525","rc":[{"batb":[[0,2.48,10],[1,2.46,20],[2,2.44,10]],"ltp":2.32,"tv":1.79,"id":26354922}]}]}
{"op":"mcm","clk":"11839770487","pt":1723666452578,"mc":[{"id":"1.231737525","rc":[{"batb":[[0,2.46,20],[1,2.44,10],[2,2.42,20]],"ltp":2.32,"tv":1.79,"id":26354922}]}]}
{"op":"mcm","clk":"11839770769","pt":1723666455978,"mc":[{"id":"1.231737525","rc":[{"batb":[[0,2.48,10],[1,2.46,20],[2,2.44,10]],"ltp":2.32,"tv":1.79,"id":26354922}]}]}
{"op":"mcm","clk":"11839771057","pt":1723666459280,"mc":[{"id":"1.231737525","rc":[{"batb":[[0,2.46,20],[1,2.44,10],[2,2.42,20]],"ltp":2.32,"tv":1.79,"id":26354922}]}]}
{"op":"mcm","clk":"11839771594","pt":1723666465581,"mc":[{"id":"1.231737525","rc":[{"batb":[[0,2.48,10],[1,2.46,20],[2,2.44,10]],"ltp":2.32,"tv":1.79,"id":26354922}]}]}
{"op":"mcm","clk":"11839771865","pt":1723666469091,"mc":[{"id":"1.231737525","rc":[{"batb":[[0,2.46,20],[1,2.44,10],[2,2.42,20]],"ltp":2.32,"tv":1.79,"id":26354922}]}]}
{"op":"mcm","clk":"11839772129","pt":1723666472292,"mc":[{"id":"1.231737525","rc":[{"batb":[[0,2.48,10],[1,2.46,20],[2,2.44,10]],"ltp":2.32,"tv":1.79,"id":26354922}]}]}
{"op":"mcm","clk":"11839772438","pt":1723666475618,"mc":[{"id":"1.231737525","rc":[{"batb":[[0,2.46,20],[1,2.44,10],[2,2.42,20]],"ltp":2.32,"tv":1.79,"id":26354922}]}]}
{"op":"mcm","clk":"11839772700","pt":1723666478931,"mc":[{"id":"1.231737525","rc":[{"batb":[[0,2.48,10],[1,2.46,20],[2,2.44,10]],"ltp":2.32,"tv":1.79,"id":26354922}]}]}
{"op":"mcm","clk":"11839772952","pt":1723666482180,"mc":[{"id":"1.231737525","rc":[{"batb":[[0,2.46,20],[1,2.44,10],[2,2.42,20]],"ltp":2.32,"tv":1.79,"id":26354922}]}]}
{"op":"mcm","clk":"11839773185","pt":1723666485531,"mc":[{"id":"1.231737525","rc":[{"batb":[[0,2.48,10],[1,2.46,20],[2,2.44,10]],"ltp":2.32,"tv":1.79,"id":26354922}]}]}
{"op":"mcm","clk":"11839773419","pt":1723666488685,"mc":[{"id":"1.231737525","rc":[{"batb":[[0,2.46,20],[1,2.44,10],[2,2.42,20]],"ltp":2.32,"tv":1.79,"id":26354922}]}]}
{"op":"mcm","clk":"11839773623","pt":1723666491630,"mc":[{"id":"1.231737525","rc":[{"batb":[[0,2.48,10],[1,2.46,20],[2,2.44,10]],"ltp":2.32,"tv":1.79,"id":26354922}]}]}
{"op":"mcm","clk":"11839773884","pt":1723666495032,"mc":[{"id":"1.231737525","rc":[{"batb":[[0,2.46,20],[1,2.44,10],[2,2.42,20]],"ltp":2.32,"tv":1.79,"id":26354922}]}]}
{"op":"mcm","clk":"11839774081","pt":1723666497318,"mc":[{"id":"1.231737525","rc":[{"batb":[[0,2.48,10],[1,2.46,20],[2,2.44,10]],"ltp":2.32,"tv":1.79,"id":26354922}]}]}
{"op":"mcm","clk":"11839774364","pt":1723666500625,"mc":[{"id":"1.231737525","rc":[{"batb":[[0,2.46,20],[1,2.44,10],[2,2.42,20]],"ltp":2.32,"tv":1.79,"id":26354922}]}]}
{"op":"mcm","clk":"11839774582","pt":1723666503022,"mc":[{"id":"1.231737525","rc":[{"batb":[[0,2.48,10],[1,2.46,20],[2,2.44,10]],"ltp":2.32,"tv":1.79,"id":26354922}]}]}
{"op":"mcm","clk":"11839774874","pt":1723666506545,"mc":[{"id":"1.231737525","rc":[{"batb":[[0,2.46,20],[1,2.44,10],[2,2.42,20]],"ltp":2.32,"tv":1.79,"id":26354922}]}]}
{"op":"mcm","clk":"11839775067","pt":1723666508825,"mc":[{"id":"1.231737525","rc":[{"batb":[[0,2.48,10],[1,2.46,20],[2,2.44,10]],"ltp":2.32,"tv":1.79,"id":26354922}]}]}
{"op":"mcm","clk":"11839775401","pt":1723666512341,"mc":[{"id":"1.231737525","rc":[{"batb":[[0,2.46,20],[1,2.44,10],[2,2.42,20]],"ltp":2.32,"tv":1.79,"id":26354922}]}]}
{"op":"mcm","clk":"11839775633","pt":1723666514553,"mc":[{"id":"1.231737525","rc":[{"batb":[[0,2.48,10],[1,2.46,20],[2,2.44,10]],"ltp":2.32,"tv":1.79,"id":26354922},{"batl":[[0,1.68,53.99]],"ltp":1.68,"tv":811.61,"id":26354921}]}]}
{"op":"mcm","clk":"11839775900","pt":1723666517969,"mc":[{"id":"1.231737525","rc":[{"batb":[[0,2.46,20],[1,2.44,10],[2,2.42,20]],"ltp":2.32,"tv":1.79,"id":26354922}]}]}
{"op":"mcm","clk":"11839776114","pt":1723666520240,"mc":[{"id":"1.231737525","rc":[{"batb":[[0,2.48,10],[1,2.46,20],[2,2.44,10]],"ltp":2.32,"tv":1.79,"id":26354922}]}]}
{"op":"mcm","clk":"11839776411","pt":1723666523446,"mc":[{"id":"1.231737525","rc":[{"batb":[[0,2.46,20],[1,2.44,10],[2,2.42,20]],"ltp":2.32,"tv":1.79,"id":26354922}]}]}
{"op":"mcm","clk":"11839776621","pt":1723666525929,"mc":[{"id":"1.231737525","rc":[{"batb":[[0,2.48,10],[1,2.46,20],[2,2.44,10]],"ltp":2.32,"tv":1.79,"id":26354922}]}]}
{"op":"mcm","clk":"11839776925","pt":1723666529340,"mc":[{"id":"1.231737525","rc":[{"batb":[[0,2.46,20],[1,2.44,10],[2,2.42,20]],"ltp":2.32,"tv":1.79,"id":26354922}]}]}
{"op":"mcm","clk":"11839777230","pt":1723666532638,"mc":[{"id":"1.231737525","rc":[{"batb":[[0,2.48,10],[1,2.46,20],[2,2.44,10]],"ltp":2.32,"tv":1.79,"id":26354922}]}]}
{"op":"mcm","clk":"11839777534","pt":1723666536052,"mc":[{"id":"1.231737525","rc":[{"batb":[[0,2.46,20],[1,2.44,10],[2,2.42,20]],"ltp":2.32,"tv":1.79,"id":26354922}]}]}
{"op":"mcm","clk":"11839777726","pt":1723666538470,"mc":[{"id":"1.231737525","rc":[{"batb":[[0,2.48,10],[1,2.46,20],[2,2.44,10]],"ltp":2.32,"tv":1.79,"id":26354922}]}]}
{"op":"mcm","clk":"11839777992","pt":1723666541735,"mc":[{"id":"1.231737525","rc":[{"batb":[[0,2.46,20],[1,2.44,10],[2,2.42,20]],"ltp":2.32,"tv":1.79,"id":26354922}]}]}
{"op":"mcm","clk":"11839778297","pt":1723666545366,"mc":[{"id":"1.231737525","rc":[{"batb":[[0,2.48,10],[1,2.46,20],[2,2.44,10]],"ltp":2.32,"tv":1.79,"id":26354922}]}]}
{"op":"mcm","clk":"11839778546","pt":1723666548762,"mc":[{"id":"1.231737525","rc":[{"batb":[[0,2.46,20],[1,2.44,10],[2,2.42,20]],"ltp":2.32,"tv":1.79,"id":26354922}]}]}
{"op":"mcm","clk":"11839778733","pt":1723666551057,"mc":[{"id":"1.231737525","rc":[{"batb":[[0,2.48,10],[1,2.46,20],[2,2.44,10]],"ltp":2.32,"tv":1.79,"id":26354922}]}]}
{"op":"mcm","clk":"11839779059","pt":1723666554482,"mc":[{"id":"1.231737525","rc":[{"batb":[[0,2.46,20],[1,2.44,10],[2,2.42,20]],"ltp":2.32,"tv":1.79,"id":26354922}]}]}
{"op":"mcm","clk":"11839779250","pt":1723666556753,"mc":[{"id":"1.231737525","rc":[{"batb":[[0,2.48,10],[1,2.46,20],[2,2.44,10]],"ltp":2.32,"tv":1.79,"id":26354922}]}]}
{"op":"mcm","clk":"11839779542","pt":1723666560278,"mc":[{"id":"1.231737525","rc":[{"batb":[[0,2.46,20],[1,2.44,10],[2,2.42,20]],"ltp":2.32,"tv":1.79,"id":26354922}]}]}
{"op":"mcm","clk":"11839779822","pt":1723666563448,"mc":[{"id":"1.231737525","rc":[{"batb":[[0,2.48,10],[1,2.46,20],[2,2.44,10]],"ltp":2.32,"tv":1.79,"id":26354922}]}]}
{"op":"mcm","clk":"11839780165","pt":1723666566876,"mc":[{"id":"1.231737525","rc":[{"batb":[[0,2.46,20],[1,2.44,10],[2,2.42,20]],"ltp":2.32,"tv":1.79,"id":26354922}]}]}
{"op":"mcm","clk":"11839780445","pt":1723666570080,"mc":[{"id":"1.231737525","rc":[{"batb":[[0,2.48,10],[1,2.46,20],[2,2.44,10]],"ltp":2.32,"tv":1.79,"id":26354922}]}]}
{"op":"mcm","clk":"11839780769","pt":1723666573398,"mc":[{"id":"1.231737525","rc":[{"batb":[[0,2.46,20],[1,2.44,10],[2,2.42,20]],"ltp":2.32,"tv":1.79,"id":26354922}]}]}
{"op":"mcm","clk":"11839780947","pt":1723666575564,"mc":[{"id":"1.231737525","rc":[{"batb":[[0,2.48,10],[1,2.46,20],[2,2.44,10]],"ltp":2.32,"tv":1.79,"id":26354922}]}]}
{"op":"mcm","clk":"11839781240","pt":1723666579078,"mc":[{"id":"1.231737525","rc":[{"batb":[[0,2.46,20],[1,2.44,10],[2,2.42,20]],"ltp":2.32,"tv":1.79,"id":26354922}]}]}
{"op":"mcm","clk":"11839781443","pt":1723666581361,"mc":[{"id":"1.231737525","rc":[{"batb":[[0,2.48,10],[1,2.46,20],[2,2.44,10]],"ltp":2.32,"tv":1.79,"id":26354922}]}]}
{"op":"mcm","clk":"11839781707","pt":1723666584693,"mc":[{"id":"1.231737525","rc":[{"batb":[[0,2.46,20],[1,2.44,10],[2,2.42,20]],"ltp":2.32,"tv":1.79,"id":26354922}]}]}
{"op":"mcm","clk":"11839781910","pt":1723666587277,"mc":[{"id":"1.231737525","rc":[{"batb":[[0,2.48,10],[1,2.46,20],[2,2.44,10]],"ltp":2.32,"tv":1.79,"id":26354922}]}]}
{"op":"mcm","clk":"11839782152","pt":1723666590684,"mc":[{"id":"1.231737525","rc":[{"batb":[[0,2.46,20],[1,2.44,10],[2,2.42,20]],"ltp":2.32,"tv":1.79,"id":26354922}]}]}
{"op":"mcm","clk":"11839782367","pt":1723666592996,"mc":[{"id":"1.231737525","rc":[{"batb":[[0,2.48,10],[1,2.46,20],[2,2.44,10]],"ltp":2.32,"tv":1.79,"id":26354922}]}]}
{"op":"mcm","clk":"11839782596","pt":1723666596420,"mc":[{"id":"1.231737525","rc":[{"batb":[[0,2.46,20],[1,2.44,10],[2,2.42,20]],"ltp":2.32,"tv":1.79,"id":26354922}]}]}
{"op":"mcm","clk":"11839782792","pt":1723666599174,"mc":[{"id":"1.231737525","rc":[{"batb":[[0,2.48,10],[1,2.46,20],[2,2.44,10]],"ltp":2.32,"tv":1.79,"id":26354922}]}]}
{"op":"mcm","clk":"11839783047","pt":1723666602479,"mc":[{"id":"1.231737525","rc":[{"batb":[[0,2.46,20],[1,2.44,10],[2,2.42,20]],"ltp":2.32,"tv":1.79,"id":26354922}]}]}
{"op":"mcm","clk":"11839783317","pt":1723666605690,"mc":[{"id":"1.231737525","rc":[{"batb":[[0,2.48,10],[1,2.46,20],[2,2.44,10]],"ltp":2.32,"tv":1.79,"id":26354922}]}]}
{"op":"mcm","clk":"11839783572","pt":1723666608882,"mc":[{"id":"1.231737525","rc":[{"batb":[[0,2.46,20],[1,2.44,10],[2,2.42,20]],"ltp":2.32,"tv":1.79,"id":26354922}]}]}
{"op":"mcm","clk":"11839783807","pt":1723666611605,"mc":[{"id":"1.231737525","rc":[{"batb":[[0,2.48,10],[1,2.46,20],[2,2.44,10]],"ltp":2.32,"tv":1.79,"id":26354922}]}]}
{"op":"mcm","clk":"11839784072","pt":1723666614986,"mc":[{"id":"1.231737525","rc":[{"batb":[[0,2.46,20],[1,2.44,10],[2,2.42,20]],"ltp":2.32,"tv":1.79,"id":26354922}]}]}
{"op":"mcm","clk":"11839784252","pt":1723666617292,"mc":[{"id":"1.231737525","rc":[{"batb":[[0,2.48,10],[1,2.46,20],[2,2.44,10]],"ltp":2.32,"tv":1.79,"id":26354922}]}]}
{"op":"mcm","clk":"11839784530","pt":1723666620487,"mc":[{"id":"1.231737525","rc":[{"batb":[[0,2.46,20],[1,2.44,10],[2,2.42,20]],"ltp":2.32,"tv":1.79,"id":26354922}]}]}
{"op":"mcm","clk":"11839784738","pt":1723666622807,"mc":[{"id":"1.231737525","rc":[{"batb":[[0,2.48,10],[1,2.46,20],[2,2.44,10]],"ltp":2.32,"tv":1.79,"id":26354922}]}]}
{"op":"mcm","clk":"11839785077","pt":1723666626213,"mc":[{"id":"1.231737525","rc":[{"batb":[[0,2.46,20],[1,2.44,10],[2,2.42,20]],"ltp":2.32,"tv":1.79,"id":26354922}]}]}
{"op":"mcm","clk":"11839785286","pt":1723666628580,"mc":[{"id":"1.231737525","rc":[{"batb":[[0,2.48,10],[1,2.46,20],[2,2.44,10]],"ltp":2.32,"tv":1.79,"id":26354922}]}]}
{"op":"mcm","clk":"11839785609","pt":1723666632035,"mc":[{"id":"1.231737525","rc":[{"batb":[[0,2.46,20],[1,2.44,10],[2,2.42,20]],"ltp":2.32,"tv":1.79,"id":26354922}]}]}
{"op":"mcm","clk":"11839785827","pt":1723666634300,"mc":[{"id":"1.231737525","rc":[{"batb":[[0,2.48,10],[1,2.46,20],[2,2.44,10]],"ltp":2.32,"tv":1.79,"id":26354922}]}]}
{"op":"mcm","clk":"11839786114","pt":1723666637495,"mc":[{"id":"1.231737525","rc":[{"batb":[[0,2.46,20],[1,2.44,10],[2,2.42,20]],"ltp":2.32,"tv":1.79,"id":26354922}]}]}
{"op":"mcm","clk":"11839786330","pt":1723666640116,"mc":[{"id":"1.231737525","rc":[{"batb":[[0,2.48,10],[1,2.46,20],[2,2.44,10]],"ltp":2.32,"tv":1.79,"id":26354922}]}]}
{"op":"mcm","clk":"11839786622","pt":1723666643416,"mc":[{"id":"1.231737525","rc":[{"batb":[[0,2.46,20],[1,2.44,10],[2,2.42,20]],"ltp":2.32,"tv":1.79,"id":26354922}]}]}
{"op":"mcm","clk":"11839786886","pt":1723666646835,"mc":[{"id":"1.231737525","rc":[{"batb":[[0,2.48,10],[1,2.46,20],[2,2.44,10]],"ltp":2.32,"tv":1.79,"id":26354922}]}]}
{"op":"mcm","clk":"11839787173","pt":1723666650134,"mc":[{"id":"1.231737525","rc":[{"batb":[[0,2.46,20],[1,2.44,10],[2,2.42,20]],"ltp":2.32,"tv":1.79,"id":26354922}]}]}
{"op":"mcm","clk":"11839787360","pt":1723666652507,"mc":[{"id":"1.231737525","rc":[{"batb":[[0,2.48,10],[1,2.46,20],[2,2.44,10]],"ltp":2.32,"tv":1.79,"id":26354922}]}]}
{"op":"mcm","clk":"11839787659","pt":1723666656042,"mc":[{"id":"1.231737525","rc":[{"batb":[[0,2.46,20],[1,2.44,10],[2,2.42,20]],"ltp":2.32,"tv":1.79,"id":26354922}]}]}
{"op":"mcm","clk":"11839787835","pt":1723666658314,"mc":[{"id":"1.231737525","rc":[{"batb":[[0,2.48,10],[1,2.46,20],[2,2.44,10]],"ltp":2.32,"tv":1.79,"id":26354922}]}]}
{"op":"mcm","clk":"11839788114","pt":1723666661722,"mc":[{"id":"1.231737525","rc":[{"batb":[[0,2.46,20],[1,2.44,10],[2,2.42,20]],"ltp":2.32,"tv":1.79,"id":26354922}]}]}
{"op":"mcm","clk":"11839788321","pt":1723666663941,"mc":[{"id":"1.231737525","rc":[{"batb":[[0,2.48,10],[1,2.46,20],[2,2.44,10]],"ltp":2.32,"tv":1.79,"id":26354922}]}]}
{"op":"mcm","clk":"11839788613","pt":1723666667242,"mc":[{"id":"1.231737525","rc":[{"batb":[[0,2.46,20],[1,2.44,10],[2,2.42,20]],"ltp":2.32,"tv":1.79,"id":26354922}]}]}
{"op":"mcm","clk":"11839788846","pt":1723666669724,"mc":[{"id":"1.231737525","rc":[{"batb":[[0,2.48,10],[1,2.46,20],[2,2.44,10]],"ltp":2.32,"tv":1.79,"id":26354922}]}]}
{"op":"mcm","clk":"11839789094","pt":1723666673075,"mc":[{"id":"1.231737525","rc":[{"batb":[[0,2.46,20],[1,2.44,10],[2,2.42,20]],"ltp":2.32,"tv":1.79,"id":26354922}]}]}
{"op":"mcm","clk":"11839789437","pt":1723666676860,"mc":[{"id":"1.231737525","rc":[{"batb":[[0,2.48,10],[1,2.46,20],[2,2.44,10]],"ltp":2.32,"tv":1.79,"id":26354922}]}]}
{"op":"mcm","clk":"11839789747","pt":1723666680263,"mc":[{"id":"1.231737525","rc":[{"batb":[[0,2.46,20],[1,2.44,10],[2,2.42,20]],"ltp":2.32,"tv":1.79,"id":26354922}]}]}
{"op":"mcm","clk":"11839790051","pt":1723666683585,"mc":[{"id":"1.231737525","rc":[{"batb":[[0,2.48,10],[1,2.46,20],[2,2.44,10]],"ltp":2.32,"tv":1.79,"id":26354922}]}]}
{"op":"mcm","clk":"11839790368","pt":1723666687048,"mc":[{"id":"1.231737525","rc":[{"batb":[[0,2.46,20],[1,2.44,10],[2,2.42,20]],"ltp":2.32,"tv":1.79,"id":26354922}]}]}
{"op":"mcm","clk":"11839790618","pt":1723666690153,"mc":[{"id":"1.231737525","rc":[{"batb":[[0,2.48,10],[1,2.46,20],[2,2.44,10]],"ltp":2.32,"tv":1.79,"id":26354922}]}]}
{"op":"mcm","clk":"11839790924","pt":1723666693558,"mc":[{"id":"1.231737525","rc":[{"batb":[[0,2.46,20],[1,2.44,10],[2,2.42,20]],"ltp":2.32,"tv":1.79,"id":26354922}]}]}
{"op":"mcm","clk":"11839791196","pt":1723666696659,"mc":[{"id":"1.231737525","rc":[{"batb":[[0,2.48,10],[1,2.46,20],[2,2.44,10]],"ltp":2.32,"tv":1.79,"id":26354922}]}]}
{"op":"mcm","clk":"11839791486","pt":1723666700167,"mc":[{"id":"1.231737525","rc":[{"batb":[[0,2.46,20],[1,2.44,10],[2,2.42,20]],"ltp":2.32,"tv":1.79,"id":26354922}]}]}
{"op":"mcm","clk":"11839791762","pt":1723666703368,"mc":[{"id":"1.231737525","rc":[{"batb":[[0,2.48,10],[1,2.46,20],[2,2.44,10]],"ltp":2.32,"tv":1.79,"id":26354922}]}]}
{"op":"mcm","clk":"11839792071","pt":1723666706779,"mc":[{"id":"1.231737525","rc":[{"batb":[[0,2.46,20],[1,2.44,10],[2,2.42,20]],"ltp":2.32,"tv":1.79,"id":26354922}]}]}
{"op":"mcm","clk":"11839792429","pt":1723666710211,"mc":[{"id":"1.231737525","rc":[{"batb":[[0,2.48,10],[1,2.46,20],[2,2.44,10]],"ltp":2.32,"tv":1.79,"id":26354922}]}]}
{"op":"mcm","clk":"11839792784","pt":1723666713591,"mc":[{"id":"1.231737525","rc":[{"batb":[[0,2.46,20],[1,2.44,10],[2,2.42,20]],"ltp":2.32,"tv":1.79,"id":26354922}]}]}
{"op":"mcm","clk":"11839793016","pt":1723666716083,"mc":[{"id":"1.231737525","rc":[{"batb":[[0,2.48,10],[1,2.46,20],[2,2.44,10]],"ltp":2.32,"tv":1.79,"id":26354922}]}]}
{"op":"mcm","clk":"11839793364","pt":1723666719492,"mc":[{"id":"1.231737525","rc":[{"batb":[[0,2.46,20],[1,2.44,10],[2,2.42,20]],"ltp":2.32,"tv":1.79,"id":26354922}]}]}
{"op":"mcm","clk":"11839793568","pt":1723666721730,"mc":[{"id":"1.231737525","rc":[{"batb":[[0,2.48,10],[1,2.46,20],[2,2.44,10]],"ltp":2.32,"tv":1.79,"id":26354922}]}]}
{"op":"mcm","clk":"11839793870","pt":1723666725164,"mc":[{"id":"1.231737525","rc":[{"batb":[[0,2.46,20],[1,2.44,10],[2,2.42,20]],"ltp":2.32,"tv":1.79,"id":26354922}]}]}
{"op":"mcm","clk":"11839794104","pt":1723666727588,"mc":[{"id":"1.231737525","rc":[{"batb":[[0,2.48,10],[1,2.46,20],[2,2.44,10]],"ltp":2.32,"tv":1.79,"id":26354922}]}]}
{"op":"mcm","clk":"11839794205","pt":1723666728784,"mc":[{"id":"1.231737525","rc":[{"batl":[[0,1.67,4.83],[1,1.68,53.99],[2,1.69,22]],"ltp":1.68,"tv":811.61,"id":26354921}]}]}
{"op":"mcm","clk":"11839794413","pt":1723666730898,"mc":[{"id":"1.231737525","rc":[{"batb":[[0,2.46,20],[1,2.44,10],[2,2.42,20]],"ltp":2.32,"tv":1.79,"id":26354922}]}]}
{"op":"mcm","clk":"11839794709","pt":1723666733377,"mc":[{"id":"1.231737525","rc":[{"batb":[[0,2.48,10],[1,2.46,20],[2,2.44,10]],"ltp":2.32,"tv":1.79,"id":26354922}]}]}
{"op":"mcm","clk":"11839795019","pt":1723666736682,"mc":[{"id":"1.231737525","rc":[{"batb":[[0,2.46,20],[1,2.44,10],[2,2.42,20]],"ltp":2.32,"tv":1.79,"id":26354922}]}]}
{"op":"mcm","clk":"11839795190","pt":1723666738902,"mc":[{"id":"1.231737525","rc":[{"batb":[[0,2.48,10],[1,2.46,20],[2,2.44,10]],"ltp":2.32,"tv":1.79,"id":26354922}]}]}
{"op":"mcm","clk":"11839795475","pt":1723666742216,"mc":[{"id":"1.231737525","rc":[{"batb":[[0,2.46,20],[1,2.44,10],[2,2.42,20]],"ltp":2.32,"tv":1.79,"id":26354922}]}]}
{"op":"mcm","clk":"11839795723","pt":1723666744597,"mc":[{"id":"1.231737525","rc":[{"batb":[[0,2.48,10],[1,2.46,20],[2,2.44,10]],"ltp":2.32,"tv":1.79,"id":26354922}]}]}
{"op":"mcm","clk":"11839796023","pt":1723666747809,"mc":[{"id":"1.231737525","rc":[{"batb":[[0,2.46,20],[1,2.44,10],[2,2.42,20]],"ltp":2.32,"tv":1.79,"id":26354922}]}]}
{"op":"mcm","clk":"11839796267","pt":1723666750209,"mc":[{"id":"1.231737525","rc":[{"batb":[[0,2.48,10],[1,2.46,20],[2,2.44,10]],"ltp":2.32,"tv":1.79,"id":26354922}]}]}
{"op":"mcm","clk":"11839796602","pt":1723666753619,"mc":[{"id":"1.231737525","rc":[{"batb":[[0,2.46,20],[1,2.44,10],[2,2.42,20]],"ltp":2.32,"tv":1.79,"id":26354922}]}]}
{"op":"mcm","clk":"11839796954","pt":1723666756995,"mc":[{"id":"1.231737525","rc":[{"batb":[[0,2.48,10],[1,2.46,20],[2,2.44,10]],"ltp":2.32,"tv":1.79,"id":26354922}]}]}
{"op":"mcm","clk":"11839797238","pt":1723666760432,"mc":[{"id":"1.231737525","rc":[{"batb":[[0,2.46,20],[1,2.44,10],[2,2.42,20]],"ltp":2.32,"tv":1.79,"id":26354922}]}]}
{"op":"mcm","clk":"11839797527","pt":1723666763441,"mc":[{"id":"1.231737525","rc":[{"batb":[[0,2.48,10],[1,2.46,20],[2,2.44,10]],"ltp":2.32,"tv":1.79,"id":26354922}]}]}
{"op":"mcm","clk":"11839797854","pt":1723666766945,"mc":[{"id":"1.231737525","rc":[{"batb":[[0,2.46,20],[1,2.44,10],[2,2.42,20]],"ltp":2.32,"tv":1.79,"id":26354922}]}]}
{"op":"mcm","clk":"11839798079","pt":1723666769127,"mc":[{"id":"1.231737525","rc":[{"batb":[[0,2.48,10],[1,2.46,20],[2,2.44,10]],"ltp":2.32,"tv":1.79,"id":26354922}]}]}
{"op":"mcm","clk":"11839798413","pt":1723666772524,"mc":[{"id":"1.231737525","rc":[{"batb":[[0,2.46,20],[1,2.44,10],[2,2.42,20]],"ltp":2.32,"tv":1.79,"id":26354922}]}]}
{"op":"mcm","clk":"11839798635","pt":1723666775053,"mc":[{"id":"1.231737525","rc":[{"batb":[[0,2.48,10],[1,2.46,20],[2,2.44,10]],"ltp":2.32,"tv":1.79,"id":26354922}]}]}
{"op":"mcm","clk":"11839798946","pt":1723666778313,"mc":[{"id":"1.231737525","rc":[{"batb":[[0,2.46,20],[1,2.44,10],[2,2.42,20]],"ltp":2.32,"tv":1.79,"id":26354922}]}]}
{"op":"mcm","clk":"11839799211","pt":1723666780542,"mc":[{"id":"1.231737525","rc":[{"batb":[[0,2.48,10],[1,2.46,20],[2,2.44,10]],"ltp":2.32,"tv":1.79,"id":26354922}]}]}
{"op":"mcm","clk":"11839799543","pt":1723666783956,"mc":[{"id":"1.231737525","rc":[{"batb":[[0,2.46,20],[1,2.44,10],[2,2.42,20]],"ltp":2.32,"tv":1.79,"id":26354922}]}]}
{"op":"mcm","clk":"11839799879","pt":1723666787469,"mc":[{"id":"1.231737525","rc":[{"batb":[[0,2.48,10],[1,2.46,20],[2,2.44,10]],"ltp":2.32,"tv":1.79,"id":26354922}]}]}
{"op":"mcm","clk":"11839800230","pt":1723666790787,"mc":[{"id":"1.231737525","rc":[{"batb":[[0,2.46,20],[1,2.44,10],[2,2.42,20]],"ltp":2.32,"tv":1.79,"id":26354922}]}]}
{"op":"mcm","clk":"11839800462","pt":1723666793155,"mc":[{"id":"1.231737525","rc":[{"batb":[[0,2.48,10],[1,2.46,20],[2,2.44,10]],"ltp":2.32,"tv":1.79,"id":26354922}]}]}
{"op":"mcm","clk":"11839800820","pt":1723666796564,"mc":[{"id":"1.231737525","rc":[{"batb":[[0,2.46,20],[1,2.44,10],[2,2.42,20]],"ltp":2.32,"tv":1.79,"id":26354922}]}]}
{"op":"mcm","clk":"11839801057","pt":1723666798842,"mc":[{"id":"1.231737525","rc":[{"batb":[[0,2.48,10],[1,2.46,20],[2,2.44,10]],"ltp":2.32,"tv":1.79,"id":26354922}]}]}
{"op":"mcm","clk":"11839801361","pt":1723666802050,"mc":[{"id":"1.231737525","rc":[{"batb":[[0,2.46,20],[1,2.44,10],[2,2.42,20]],"ltp":2.32,"tv":1.79,"id":26354922}]}]}
{"op":"mcm","clk":"11839801641","pt":1723666804656,"mc":[{"id":"1.231737525","rc":[{"batb":[[0,2.48,10],[1,2.46,20],[2,2.44,10]],"ltp":2.32,"tv":1.79,"id":26354922}]}]}
{"op":"mcm","clk":"11839802010","pt":1723666807966,"mc":[{"id":"1.231737525","rc":[{"batb":[[0,2.46,20],[1,2.44,10],[2,2.42,20]],"ltp":2.32,"tv":1.79,"id":26354922}]}]}
{"op":"mcm","clk":"11839802257","pt":1723666810338,"mc":[{"id":"1.231737525","rc":[{"batb":[[0,2.48,10],[1,2.46,20],[2,2.44,10]],"ltp":2.32,"tv":1.79,"id":26354922}]}]}
{"op":"mcm","clk":"11839802573","pt":1723666813774,"mc":[{"id":"1.231737525","rc":[{"batb":[[0,2.46,20],[1,2.44,10],[2,2.42,20]],"ltp":2.32,"tv":1.79,"id":26354922}]}]}
{"op":"mcm","clk":"11839802780","pt":1723666815997,"mc":[{"id":"1.231737525","rc":[{"batb":[[0,2.48,10],[1,2.46,20],[2,2.44,10]],"ltp":2.32,"tv":1.79,"id":26354922}]}]}
{"op":"mcm","clk":"11839803047","pt":1723666819246,"mc":[{"id":"1.231737525","rc":[{"batb":[[0,2.46,20],[1,2.44,10],[2,2.42,20]],"ltp":2.32,"tv":1.79,"id":26354922}]}]}
{"op":"mcm","clk":"11839803243","pt":1723666821566,"mc":[{"id":"1.231737525","rc":[{"batb":[[0,2.48,10],[1,2.46,20],[2,2.44,10]],"ltp":2.32,"tv":1.79,"id":26354922}]}]}
{"op":"mcm","clk":"11839803593","pt":1723666824870,"mc":[{"id":"1.231737525","rc":[{"batb":[[0,2.46,20],[1,2.44,10],[2,2.42,20]],"ltp":2.32,"tv":1.79,"id":26354922}]}]}
{"op":"mcm","clk":"11839803843","pt":1723666827462,"mc":[{"id":"1.231737525","rc":[{"batb":[[0,2.48,10],[1,2.46,20],[2,2.44,10]],"ltp":2.32,"tv":1.79,"id":26354922}]}]}
{"op":"mcm","clk":"11839804167","pt":1723666830814,"mc":[{"id":"1.231737525","rc":[{"batb":[[0,2.46,20],[1,2.44,10],[2,2.42,20]],"ltp":2.32,"tv":1.79,"id":26354922}]}]}
{"op":"mcm","clk":"11839804380","pt":1723666832981,"mc":[{"id":"1.231737525","rc":[{"batb":[[0,2.48,10],[1,2.46,20],[2,2.44,10]],"ltp":2.32,"tv":1.79,"id":26354922}]}]}
{"op":"mcm","clk":"11839804698","pt":1723666836386,"mc":[{"id":"1.231737525","rc":[{"batb":[[0,2.46,20],[1,2.44,10],[2,2.42,20]],"ltp":2.32,"tv":1.79,"id":26354922}]}]}
{"op":"mcm","clk":"11839804867","pt":1723666838597,"mc":[{"id":"1.231737525","rc":[{"batb":[[0,2.48,10],[1,2.46,20],[2,2.44,10]],"ltp":2.32,"tv":1.79,"id":26354922}]}]}
{"op":"mcm","clk":"11839805152","pt":1723666842068,"mc":[{"id":"1.231737525","rc":[{"batb":[[0,2.46,20],[1,2.44,10],[2,2.42,20]],"ltp":2.32,"tv":1.79,"id":26354922}]}]}
{"op":"mcm","clk":"11839805371","pt":1723666844531,"mc":[{"id":"1.231737525","rc":[{"batb":[[0,2.48,10],[1,2.46,20],[2,2.44,10]],"ltp":2.32,"tv":1.79,"id":26354922}]}]}
{"op":"mcm","clk":"11839805647","pt":1723666847739,"mc":[{"id":"1.231737525","rc":[{"batb":[[0,2.46,20],[1,2.44,10],[2,2.42,20]],"ltp":2.32,"tv":1.79,"id":26354922}]}]}
{"op":"mcm","clk":"11839805840","pt":1723666849917,"mc":[{"id":"1.231737525","rc":[{"batb":[[0,2.48,10],[1,2.46,20],[2,2.44,10]],"ltp":2.32,"tv":1.79,"id":26354922}]}]}
{"op":"mcm","clk":"11839806175","pt":1723666853542,"mc":[{"id":"1.231737525","rc":[{"batb":[[0,2.46,20],[1,2.44,10],[2,2.42,20]],"ltp":2.32,"tv":1.79,"id":26354922}]}]}
{"op":"mcm","clk":"11839806399","pt":1723666855824,"mc":[{"id":"1.231737525","rc":[{"batb":[[0,2.48,10],[1,2.46,20],[2,2.44,10]],"ltp":2.32,"tv":1.79,"id":26354922}]}]}
{"op":"mcm","clk":"11839806676","pt":1723666859025,"mc":[{"id":"1.231737525","rc":[{"batb":[[0,2.46,20],[1,2.44,10],[2,2.42,20]],"ltp":2.32,"tv":1.79,"id":26354922}]}]}
{"op":"mcm","clk":"11839807050","pt":1723666863218,"mc":[{"id":"1.231737525","rc":[{"batb":[[0,2.48,10],[1,2.46,20],[2,2.44,10]],"ltp":2.32,"tv":1.79,"id":26354922}]}]}
{"op":"mcm","clk":"11839807339","pt":1723666866619,"mc":[{"id":"1.231737525","rc":[{"batb":[[0,2.46,20],[1,2.44,10],[2,2.42,20]],"ltp":2.32,"tv":1.79,"id":26354922}]}]}
{"op":"mcm","clk":"11839807564","pt":1723666869001,"mc":[{"id":"1.231737525","rc":[{"batb":[[0,2.48,10],[1,2.46,20],[2,2.44,10]],"ltp":2.32,"tv":1.79,"id":26354922}]}]}
{"op":"mcm","clk":"11839807896","pt":1723666872520,"mc":[{"id":"1.231737525","rc":[{"batb":[[0,2.46,20],[1,2.44,10],[2,2.42,20]],"ltp":2.32,"tv":1.79,"id":26354922}]}]}
{"op":"mcm","clk":"11839808261","pt":1723666875821,"mc":[{"id":"1.231737525","rc":[{"batb":[[0,2.48,10],[1,2.46,20],[2,2.44,10]],"ltp":2.32,"tv":1.79,"id":26354922}]}]}
{"op":"mcm","clk":"11839808539","pt":1723666879113,"mc":[{"id":"1.231737525","rc":[{"batb":[[0,2.46,20],[1,2.44,10],[2,2.42,20]],"ltp":2.32,"tv":1.79,"id":26354922}]}]}
{"op":"mcm","clk":"11839808733","pt":1723666881429,"mc":[{"id":"1.231737525","rc":[{"batb":[[0,2.48,10],[1,2.46,20],[2,2.44,10]],"ltp":2.32,"tv":1.79,"id":26354922}]}]}
{"op":"mcm","clk":"11839809004","pt":1723666884823,"mc":[{"id":"1.231737525","rc":[{"batb":[[0,2.46,20],[1,2.44,10],[2,2.42,20]],"ltp":2.32,"tv":1.79,"id":26354922}]}]}
{"op":"mcm","clk":"11839809181","pt":1723666887145,"mc":[{"id":"1.231737525","rc":[{"batb":[[0,2.48,10],[1,2.46,20],[2,2.44,10]],"ltp":2.32,"tv":1.79,"id":26354922}]}]}
{"op":"mcm","clk":"11839809457","pt":1723666890439,"mc":[{"id":"1.231737525","rc":[{"batb":[[0,2.46,20],[1,2.44,10],[2,2.42,20]],"ltp":2.32,"tv":1.79,"id":26354922}]}]}
{"op":"mcm","clk":"11839809667","pt":1723666892812,"mc":[{"id":"1.231737525","rc":[{"batb":[[0,2.48,10],[1,2.46,20],[2,2.44,10]],"ltp":2.32,"tv":1.79,"id":26354922}]}]}
{"op":"mcm","clk":"11839809925","pt":1723666896109,"mc":[{"id":"1.231737525","rc":[{"batb":[[0,2.46,20],[1,2.44,10],[2,2.42,20]],"ltp":2.32,"tv":1.79,"id":26354922}]}]}
{"op":"mcm","clk":"11839810117","pt":1723666898438,"mc":[{"id":"1.231737525","rc":[{"batb":[[0,2.48,10],[1,2.46,20],[2,2.44,10]],"ltp":2.32,"tv":1.79,"id":26354922}]}]}
{"op":"mcm","clk":"11839810390","pt":1723666901823,"mc":[{"id":"1.231737525","rc":[{"batb":[[0,2.46,20],[1,2.44,10],[2,2.42,20]],"ltp":2.32,"tv":1.79,"id":26354922}]}]}
{"op":"mcm","clk":"11839810590","pt":1723666904135,"mc":[{"id":"1.231737525","rc":[{"batb":[[0,2.48,10],[1,2.46,20],[2,2.44,10]],"ltp":2.32,"tv":1.79,"id":26354922}]}]}
{"op":"mcm","clk":"11839810906","pt":1723666907440,"mc":[{"id":"1.231737525","rc":[{"batb":[[0,2.46,20],[1,2.44,10],[2,2.42,20]],"ltp":2.32,"tv":1.79,"id":26354922}]}]}
{"op":"mcm","clk":"11839811195","pt":1723666909856,"mc":[{"id":"1.231737525","rc":[{"batb":[[0,2.48,10],[1,2.46,20],[2,2.44,10]],"ltp":2.32,"tv":1.79,"id":26354922}]}]}
{"op":"mcm","clk":"11839811508","pt":1723666913227,"mc":[{"id":"1.231737525","rc":[{"batb":[[0,2.46,20],[1,2.44,10],[2,2.42,20]],"ltp":2.32,"tv":1.79,"id":26354922}]}]}
{"op":"mcm","clk":"11839811721","pt":1723666915669,"mc":[{"id":"1.231737525","rc":[{"batb":[[0,2.48,10],[1,2.46,20],[2,2.44,10]],"ltp":2.32,"tv":1.79,"id":26354922}]}]}
{"op":"mcm","clk":"11839811988","pt":1723666919039,"mc":[{"id":"1.231737525","rc":[{"batb":[[0,2.46,20],[1,2.44,10],[2,2.42,20]],"ltp":2.32,"tv":1.79,"id":26354922}]}]}
{"op":"mcm","clk":"11839812170","pt":1723666921472,"mc":[{"id":"1.231737525","rc":[{"batb":[[0,2.48,10],[1,2.46,20],[2,2.44,10]],"ltp":2.32,"tv":1.79,"id":26354922}]}]}
{"op":"mcm","clk":"11839812474","pt":1723666924775,"mc":[{"id":"1.231737525","rc":[{"batb":[[0,2.46,20],[1,2.44,10],[2,2.42,20]],"ltp":2.32,"tv":1.79,"id":26354922}]}]}
{"op":"mcm","clk":"11839812699","pt":1723666927244,"mc":[{"id":"1.231737525","rc":[{"batb":[[0,2.48,10],[1,2.46,20],[2,2.44,10]],"ltp":2.32,"tv":1.79,"id":26354922}]}]}
{"op":"mcm","clk":"11839812989","pt":1723666930545,"mc":[{"id":"1.231737525","rc":[{"batb":[[0,2.46,20],[1,2.44,10],[2,2.42,20]],"ltp":2.32,"tv":1.79,"id":26354922}]}]}
{"op":"mcm","clk":"11839813193","pt":1723666933165,"mc":[{"id":"1.231737525","rc":[{"batb":[[0,2.48,10],[1,2.46,20],[2,2.44,10]],"ltp":2.32,"tv":1.79,"id":26354922}]}]}
{"op":"mcm","clk":"11839813515","pt":1723666936665,"mc":[{"id":"1.231737525","rc":[{"batb":[[0,2.46,20],[1,2.44,10],[2,2.42,20]],"ltp":2.32,"tv":1.79,"id":26354922}]}]}
{"op":"mcm","clk":"11839813723","pt":1723666938986,"mc":[{"id":"1.231737525","rc":[{"batb":[[0,2.48,10],[1,2.46,20],[2,2.44,10]],"ltp":2.32,"tv":1.79,"id":26354922}]}]}
{"op":"mcm","clk":"11839814040","pt":1723666942445,"mc":[{"id":"1.231737525","rc":[{"batb":[[0,2.46,20],[1,2.44,10],[2,2.42,20]],"ltp":2.32,"tv":1.79,"id":26354922}]}]}
{"op":"mcm","clk":"11839814245","pt":1723666944868,"mc":[{"id":"1.231737525","rc":[{"batb":[[0,2.48,10],[1,2.46,20],[2,2.44,10]],"ltp":2.32,"tv":1.79,"id":26354922}]}]}
{"op":"mcm","clk":"11839814541","pt":1723666948281,"mc":[{"id":"1.231737525","rc":[{"batb":[[0,2.46,20],[1,2.44,10],[2,2.42,20]],"ltp":2.32,"tv":1.79,"id":26354922}]}]}
{"op":"mcm","clk":"11839814751","pt":1723666950596,"mc":[{"id":"1.231737525","rc":[{"batb":[[0,2.48,10],[1,2.46,20],[2,2.44,10]],"ltp":2.32,"tv":1.79,"id":26354922}]}]}
{"op":"mcm","clk":"11839815041","pt":1723666953958,"mc":[{"id":"1.231737525","rc":[{"batb":[[0,2.46,20],[1,2.44,10],[2,2.42,20]],"ltp":2.32,"tv":1.79,"id":26354922}]}]}
{"op":"mcm","clk":"11839815238","pt":1723666956390,"mc":[{"id":"1.231737525","rc":[{"batb":[[0,2.48,10],[1,2.46,20],[2,2.44,10]],"ltp":2.32,"tv":1.79,"id":26354922}]}]}
{"op":"mcm","clk":"11839815541","pt":1723666959792,"mc":[{"id":"1.231737525","rc":[{"batb":[[0,2.46,20],[1,2.44,10],[2,2.42,20]],"ltp":2.32,"tv":1.79,"id":26354922}]}]}
{"op":"mcm","clk":"11839815752","pt":1723666962067,"mc":[{"id":"1.231737525","rc":[{"batb":[[0,2.48,10],[1,2.46,20],[2,2.44,10]],"ltp":2.32,"tv":1.79,"id":26354922}]}]}
{"op":"mcm","clk":"11839816045","pt":1723666965437,"mc":[{"id":"1.231737525","rc":[{"batb":[[0,2.46,20],[1,2.44,10],[2,2.42,20]],"ltp":2.32,"tv":1.79,"id":26354922}]}]}
{"op":"mcm","clk":"11839816253","pt":1723666967613,"mc":[{"id":"1.231737525","rc":[{"batb":[[0,2.48,10],[1,2.46,20],[2,2.44,10]],"ltp":2.32,"tv":1.79,"id":26354922}]}]}
{"op":"mcm","clk":"11839816574","pt":1723666970919,"mc":[{"id":"1.231737525","rc":[{"batb":[[0,2.46,20],[1,2.44,10],[2,2.42,20]],"ltp":2.32,"tv":1.79,"id":26354922}]}]}
{"op":"mcm","clk":"11839816774","pt":1723666973189,"mc":[{"id":"1.231737525","rc":[{"batb":[[0,2.48,10],[1,2.46,20],[2,2.44,10]],"ltp":2.32,"tv":1.79,"id":26354922}]}]}
{"op":"mcm","clk":"11839817103","pt":1723666976509,"mc":[{"id":"1.231737525","rc":[{"batb":[[0,2.46,20],[1,2.44,10],[2,2.42,20]],"ltp":2.32,"tv":1.79,"id":26354922}]}]}
{"op":"mcm","clk":"11839817322","pt":1723666978690,"mc":[{"id":"1.231737525","rc":[{"batb":[[0,2.48,10],[1,2.46,20],[2,2.44,10]],"ltp":2.32,"tv":1.79,"id":26354922}]}]}
{"op":"mcm","clk":"11839817665","pt":1723666982221,"mc":[{"id":"1.231737525","rc":[{"batb":[[0,2.46,20],[1,2.44,10],[2,2.42,20]],"ltp":2.32,"tv":1.79,"id":26354922}]}]}
{"op":"mcm","clk":"11839817852","pt":1723666984391,"mc":[{"id":"1.231737525","rc":[{"batb":[[0,2.48,10],[1,2.46,20],[2,2.44,10]],"ltp":2.32,"tv":1.79,"id":26354922}]}]}
{"op":"mcm","clk":"11839818231","pt":1723666987812,"mc":[{"id":"1.231737525","rc":[{"batb":[[0,2.46,20],[1,2.44,10],[2,2.42,20]],"ltp":2.32,"tv":1.79,"id":26354922}]}]}
{"op":"mcm","clk":"11839818419","pt":1723666989930,"mc":[{"id":"1.231737525","rc":[{"batb":[[0,2.48,10],[1,2.46,20],[2,2.44,10]],"ltp":2.32,"tv":1.79,"id":26354922}]}]}
{"op":"mcm","clk":"11839818756","pt":1723666993290,"mc":[{"id":"1.231737525","rc":[{"batb":[[0,2.46,20],[1,2.44,10],[2,2.42,20]],"ltp":2.32,"tv":1.79,"id":26354922}]}]}
{"op":"mcm","clk":"11839818965","pt":1723666995507,"mc":[{"id":"1.231737525","rc":[{"batb":[[0,2.48,10],[1,2.46,20],[2,2.44,10]],"ltp":2.32,"tv":1.79,"id":26354922}]}]}
{"op":"mcm","clk":"11839819263","pt":1723666998816,"mc":[{"id":"1.231737525","rc":[{"batb":[[0,2.46,20],[1,2.44,10],[2,2.42,20]],"ltp":2.32,"tv":1.79,"id":26354922}]}]}
{"op":"mcm","clk":"11839819479","pt":1723667000989,"mc":[{"id":"1.231737525","rc":[{"batb":[[0,2.48,10],[1,2.46,20],[2,2.44,10]],"ltp":2.32,"tv":1.79,"id":26354922}]}]}
{"op":"mcm","clk":"11839819778","pt":1723667004402,"mc":[{"id":"1.231737525","rc":[{"batb":[[0,2.46,20],[1,2.44,10],[2,2.42,20]],"ltp":2.32,"tv":1.79,"id":26354922}]}]}
{"op":"mcm","clk":"11839819977","pt":1723667006615,"mc":[{"id":"1.231737525","rc":[{"batb":[[0,2.48,10],[1,2.46,20],[2,2.44,10]],"ltp":2.32,"tv":1.79,"id":26354922}]}]}
{"op":"mcm","clk":"11839820406","pt":1723667010024,"mc":[{"id":"1.231737525","rc":[{"batb":[[0,2.46,20],[1,2.44,10],[2,2.42,20]],"ltp":2.32,"tv":1.79,"id":26354922}]}]}
{"op":"mcm","clk":"11839820583","pt":1723667012240,"mc":[{"id":"1.231737525","rc":[{"batb":[[0,2.48,10],[1,2.46,20],[2,2.44,10]],"ltp":2.32,"tv":1.79,"id":26354922}]}]}
{"op":"mcm","clk":"11839820844","pt":1723667015436,"mc":[{"id":"1.231737525","rc":[{"batb":[[0,2.46,20],[1,2.44,10],[2,2.42,20]],"ltp":2.32,"tv":1.79,"id":26354922}]}]}
{"op":"mcm","clk":"11839821052","pt":1723667017811,"mc":[{"id":"1.231737525","rc":[{"batb":[[0,2.48,10],[1,2.46,20],[2,2.44,10]],"ltp":2.32,"tv":1.79,"id":26354922}]}]}
{"op":"mcm","clk":"11839821328","pt":1723667021012,"mc":[{"id":"1.231737525","rc":[{"batb":[[0,2.46,20],[1,2.44,10],[2,2.42,20]],"ltp":2.32,"tv":1.79,"id":26354922}]}]}
{"op":"mcm","clk":"11839821545","pt":1723667023230,"mc":[{"id":"1.231737525","rc":[{"batb":[[0,2.48,10],[1,2.46,20],[2,2.44,10]],"ltp":2.32,"tv":1.79,"id":26354922}]}]}
{"op":"mcm","clk":"11839821868","pt":1723667026631,"mc":[{"id":"1.231737525","rc":[{"batb":[[0,2.46,20],[1,2.44,10],[2,2.42,20]],"ltp":2.32,"tv":1.79,"id":26354922}]}]}
{"op":"mcm","clk":"11839822056","pt":1723667028845,"mc":[{"id":"1.231737525","rc":[{"batb":[[0,2.48,10],[1,2.46,20],[2,2.44,10]],"ltp":2.32,"tv":1.79,"id":26354922}]}]}
{"op":"mcm","clk":"11839822383","pt":1723667032261,"mc":[{"id":"1.231737525","rc":[{"batb":[[0,2.46,20],[1,2.44,10],[2,2.42,20]],"ltp":2.32,"tv":1.79,"id":26354922}]}]}
{"op":"mcm","clk":"11839822587","pt":1723667034421,"mc":[{"id":"1.231737525","rc":[{"batb":[[0,2.48,10],[1,2.46,20],[2,2.44,10]],"ltp":2.32,"tv":1.79,"id":26354922}]}]}
{"op":"mcm","clk":"11839822869","pt":1723667037817,"mc":[{"id":"1.231737525","rc":[{"batb":[[0,2.46,20],[1,2.44,10],[2,2.42,20]],"ltp":2.32,"tv":1.79,"id":26354922}]}]}
{"op":"mcm","clk":"11839823058","pt":1723667040041,"mc":[{"id":"1.231737525","rc":[{"batb":[[0,2.48,10],[1,2.46,20],[2,2.44,10]],"ltp":2.32,"tv":1.79,"id":26354922}]}]}
{"op":"mcm","clk":"11839823344","pt":1723667043333,"mc":[{"id":"1.231737525","rc":[{"batb":[[0,2.46,20],[1,2.44,10],[2,2.42,20]],"ltp":2.32,"tv":1.79,"id":26354922}]}]}
{"op":"mcm","clk":"11839823568","pt":1723667045851,"mc":[{"id":"1.231737525","rc":[{"batb":[[0,2.48,10],[1,2.46,20],[2,2.44,10]],"ltp":2.32,"tv":1.79,"id":26354922}]}]}
{"op":"mcm","clk":"11839823892","pt":1723667049146,"mc":[{"id":"1.231737525","rc":[{"batb":[[0,2.46,20],[1,2.44,10],[2,2.42,20]],"ltp":2.32,"tv":1.79,"id":26354922}]}]}
{"op":"mcm","clk":"11839824109","pt":1723667051340,"mc":[{"id":"1.231737525","rc":[{"batb":[[0,2.48,10],[1,2.46,20],[2,2.44,10]],"ltp":2.32,"tv":1.79,"id":26354922}]}]}
{"op":"mcm","clk":"11839824430","pt":1723667054743,"mc":[{"id":"1.231737525","rc":[{"batb":[[0,2.46,20],[1,2.44,10],[2,2.42,20]],"ltp":2.32,"tv":1.79,"id":26354922}]}]}
{"op":"mcm","clk":"11839824624","pt":1723667057087,"mc":[{"id":"1.231737525","rc":[{"batb":[[0,2.48,10],[1,2.46,20],[2,2.44,10]],"ltp":2.32,"tv":1.79,"id":26354922}]}]}
{"op":"mcm","clk":"11839824906","pt":1723667060442,"mc":[{"id":"1.231737525","rc":[{"batb":[[0,2.46,20],[1,2.44,10],[2,2.42,20]],"ltp":2.32,"tv":1.79,"id":26354922}]}]}
{"op":"mcm","clk":"11839825120","pt":1723667062859,"mc":[{"id":"1.231737525","rc":[{"batb":[[0,2.48,10],[1,2.46,20],[2,2.44,10]],"ltp":2.32,"tv":1.79,"id":26354922}]}]}
{"op":"mcm","clk":"11839825436","pt":1723667066371,"mc":[{"id":"1.231737525","rc":[{"batb":[[0,2.46,20],[1,2.44,10],[2,2.42,20]],"ltp":2.32,"tv":1.79,"id":26354922}]}]}
{"op":"mcm","clk":"11839825649","pt":1723667068586,"mc":[{"id":"1.231737525","rc":[{"batb":[[0,2.48,10],[1,2.46,20],[2,2.44,10]],"ltp":2.32,"tv":1.79,"id":26354922}]}]}
{"op":"mcm","clk":"11839825947","pt":1723667071876,"mc":[{"id":"1.231737525","rc":[{"batb":[[0,2.46,20],[1,2.44,10],[2,2.42,20]],"ltp":2.32,"tv":1.79,"id":26354922}]}]}
{"op":"mcm","clk":"11839826175","pt":1723667074197,"mc":[{"id":"1.231737525","rc":[{"batb":[[0,2.48,10],[1,2.46,20],[2,2.44,10]],"ltp":2.32,"tv":1.79,"id":26354922}]}]}
{"op":"mcm","clk":"11839826528","pt":1723667077596,"mc":[{"id":"1.231737525","rc":[{"batb":[[0,2.46,20],[1,2.44,10],[2,2.42,20]],"ltp":2.32,"tv":1.79,"id":26354922}]}]}
{"op":"mcm","clk":"11839826749","pt":1723667079758,"mc":[{"id":"1.231737525","rc":[{"batb":[[0,2.48,10],[1,2.46,20],[2,2.44,10]],"ltp":2.32,"tv":1.79,"id":26354922}]}]}
{"op":"mcm","clk":"11839827048","pt":1723667083156,"mc":[{"id":"1.231737525","rc":[{"batb":[[0,2.46,20],[1,2.44,10],[2,2.42,20]],"ltp":2.32,"tv":1.79,"id":26354922}]}]}
{"op":"mcm","clk":"11839827237","pt":1723667085380,"mc":[{"id":"1.231737525","rc":[{"batb":[[0,2.48,10],[1,2.46,20],[2,2.44,10]],"ltp":2.32,"tv":1.79,"id":26354922}]}]}
{"op":"mcm","clk":"11839827543","pt":1723667088684,"mc":[{"id":"1.231737525","rc":[{"batb":[[0,2.46,20],[1,2.44,10],[2,2.42,20]],"ltp":2.32,"tv":1.79,"id":26354922}]}]}
{"op":"mcm","clk":"11839827753","pt":1723667090900,"mc":[{"id":"1.231737525","rc":[{"batb":[[0,2.48,10],[1,2.46,20],[2,2.44,10]],"ltp":2.32,"tv":1.79,"id":26354922}]}]}
{"op":"mcm","clk":"11839828044","pt":1723667094094,"mc":[{"id":"1.231737525","rc":[{"batb":[[0,2.46,20],[1,2.44,10],[2,2.42,20]],"ltp":2.32,"tv":1.79,"id":26354922}]}]}
{"op":"mcm","clk":"11839828238","pt":1723667096410,"mc":[{"id":"1.231737525","rc":[{"batb":[[0,2.48,10],[1,2.46,20],[2,2.44,10]],"ltp":2.32,"tv":1.79,"id":26354922}]}]}
{"op":"mcm","clk":"11839828538","pt":1723667099710,"mc":[{"id":"1.231737525","rc":[{"batb":[[0,2.46,20],[1,2.44,10],[2,2.42,20]],"ltp":2.32,"tv":1.79,"id":26354922}]}]}
{"op":"mcm","clk":"11839828718","pt":1723667101881,"mc":[{"id":"1.231737525","rc":[{"batb":[[0,2.48,10],[1,2.46,20],[2,2.44,10]],"ltp":2.32,"tv":1.79,"id":26354922}]}]}
{"op":"mcm","clk":"11839828997","pt":1723667105175,"mc":[{"id":"1.231737525","rc":[{"batb":[[0,2.46,20],[1,2.44,10],[2,2.42,20]],"ltp":2.32,"tv":1.79,"id":26354922}]}]}
{"op":"mcm","clk":"11839829179","pt":1723667107497,"mc":[{"id":"1.231737525","rc":[{"batb":[[0,2.48,10],[1,2.46,20],[2,2.44,10]],"ltp":2.32,"tv":1.79,"id":26354922}]}]}
{"op":"mcm","clk":"11839829439","pt":1723667110898,"mc":[{"id":"1.231737525","rc":[{"batb":[[0,2.46,20],[1,2.44,10],[2,2.42,20]],"ltp":2.32,"tv":1.79,"id":26354922}]}]}
{"op":"mcm","clk":"11839829649","pt":1723667113525,"mc":[{"id":"1.231737525","rc":[{"batb":[[0,2.48,10],[1,2.46,20],[2,2.44,10]],"ltp":2.32,"tv":1.79,"id":26354922}]}]}
{"op":"mcm","clk":"11839829960","pt":1723667116986,"mc":[{"id":"1.231737525","rc":[{"batb":[[0,2.46,20],[1,2.44,10],[2,2.42,20]],"ltp":2.32,"tv":1.79,"id":26354922}]}]}
{"op":"mcm","clk":"11839830151","pt":1723667119305,"mc":[{"id":"1.231737525","rc":[{"batb":[[0,2.48,10],[1,2.46,20],[2,2.44,10]],"ltp":2.32,"tv":1.79,"id":26354922}]}]}
{"op":"mcm","clk":"11839830430","pt":1723667122604,"mc":[{"id":"1.231737525","rc":[{"batb":[[0,2.46,20],[1,2.44,10],[2,2.42,20]],"ltp":2.32,"tv":1.79,"id":26354922}]}]}
{"op":"mcm","clk":"11839830543","pt":1723667123735,"mc":[{"id":"1.231737525","rc":[{"batb":[[0,2.48,4.52],[1,2.46,20],[2,2.44,10]],"ltp":2.32,"tv":1.79,"id":26354922}]}]}
{"op":"mcm","clk":"11839830781","pt":1723667126006,"mc":[{"id":"1.231737525","rc":[{"batb":[[0,2.5,10]],"ltp":2.32,"tv":1.79,"id":26354922}]}]}
{"op":"mcm","clk":"11839830850","pt":1723667126740,"mc":[{"id":"1.231737525","rc":[{"batl":[[0,1.66,4.19],[1,1.67,4.83],[2,1.68,49.85]],"ltp":1.68,"tv":811.61,"id":26354921}]}]}
{"op":"mcm","clk":"11839831079","pt":1723667128554,"mc":[{"id":"1.231737525","rc":[{"batb":[[0,2.46,20],[1,2.44,10],[2,2.42,20]],"ltp":2.32,"tv":1.79,"id":26354922}]}]}
{"op":"mcm","clk":"11839831165","pt":1723667129313,"mc":[{"id":"1.231737525","rc":[{"batl":[[0,1.67,4.83],[1,1.68,49.85],[2,1.69,22]],"ltp":1.68,"tv":811.61,"id":26354921}]}]}
{"op":"mcm","clk":"11839831385","pt":1723667131830,"mc":[{"id":"1.231737525","rc":[{"batb":[[0,2.48,10],[1,2.46,20],[2,2.44,10]],"ltp":2.32,"tv":1.79,"id":26354922}]}]}
{"op":"mcm","clk":"11839831728","pt":1723667135220,"mc":[{"id":"1.231737525","rc":[{"batb":[[0,2.46,20],[1,2.44,10],[2,2.42,20]],"ltp":2.32,"tv":1.79,"id":26354922}]}]}
{"op":"mcm","clk":"11839831956","pt":1723667137641,"mc":[{"id":"1.231737525","rc":[{"batb":[[0,2.48,10],[1,2.46,20],[2,2.44,10]],"ltp":2.32,"tv":1.79,"id":26354922}]}]}
{"op":"mcm","clk":"11839832007","pt":1723667138209,"mc":[{"id":"1.231737525","rc":[{"batl":[[1,1.68,19.85],[2,1.69,12]],"ltp":1.68,"tv":811.61,"id":26354921}]}]}
{"op":"mcm","clk":"11839832225","pt":1723667140521,"mc":[{"id":"1.231737525","rc":[{"batb":[[1,2.32,31.11],[2,1.25,100]],"ltp":2.32,"tv":1.79,"id":26354922}]}]}
{"op":"mcm","clk":"11839832337","pt":1723667141818,"mc":[{"id":"1.231737525","rc":[{"batb":[[0,2.32,31.11],[1,1.25,100],[2,1.1,25000]],"ltp":2.32,"tv":1.79,"id":26354922},{"batl":[[1,1.68,15.48]],"ltp":1.68,"tv":811.61,"id":26354921}]}]}
{"op":"mcm","clk":"11839832374","pt":1723667142239,"mc":[{"id":"1.231737525","rc":[{"batl":[[0,1.67,9]],"ltp":1.68,"tv":811.61,"id":26354921}]}]}
{"op":"mcm","clk":"11839832497","pt":1723667143453,"mc":[{"id":"1.231737525","rc":[{"batb":[[0,2.34,10],[1,2.32,31.11],[2,1.25,100]],"ltp":2.32,"tv":1.79,"id":26354922}]}]}
{"op":"mcm","clk":"11839832810","pt":1723667146848,"mc":[{"id":"1.231737525","rc":[{"batb":[[0,2.32,31.11],[1,1.25,100],[2,1.1,25000]],"ltp":2.32,"tv":1.79,"id":26354922}]}]}
{"op":"mcm","clk":"11839833174","pt":1723667150648,"mc":[{"id":"1.231737525","rc":[{"batb":[[0,2.34,10],[1,2.32,31.11],[2,1.25,100]],"ltp":2.32,"tv":1.79,"id":26354922}]}]}
{"op":"mcm","clk":"11839833498","pt":1723667153831,"mc":[{"id":"1.231737525","rc":[{"batb":[[0,2.32,31.11],[1,1.25,100],[2,1.1,25000]],"ltp":2.32,"tv":1.79,"id":26354922}]}]}
{"op":"mcm","clk":"11839833770","pt":1723667156360,"mc":[{"id":"1.231737525","rc":[{"batb":[[0,2.34,10],[1,2.32,31.11],[2,1.25,100]],"ltp":2.32,"tv":1.79,"id":26354922}]}]}
{"op":"mcm","clk":"11839834083","pt":1723667159759,"mc":[{"id":"1.231737525","rc":[{"batb":[[0,2.32,31.11],[1,1.25,100],[2,1.1,25000]],"ltp":2.32,"tv":1.79,"id":26354922}]}]}
{"op":"mcm","clk":"11839834294","pt":1723667162073,"mc":[{"id":"1.231737525","rc":[{"batb":[[0,2.34,10],[1,2.32,31.11],[2,1.25,100]],"ltp":2.32,"tv":1.79,"id":26354922}]}]}
{"op":"mcm","clk":"11839834583","pt":1723667165569,"mc":[{"id":"1.231737525","rc":[{"batb":[[0,2.32,31.11],[1,1.25,100],[2,1.1,25000]],"ltp":2.32,"tv":1.79,"id":26354922}]}]}
{"op":"mcm","clk":"11839834774","pt":1723667167833,"mc":[{"id":"1.231737525","rc":[{"batb":[[0,2.34,10],[1,2.32,31.11],[2,1.25,100]],"ltp":2.32,"tv":1.79,"id":26354922}]}]}
{"op":"mcm","clk":"11839835041","pt":1723667171276,"mc":[{"id":"1.231737525","rc":[{"batb":[[0,2.32,31.11],[1,1.25,100],[2,1.1,25000]],"ltp":2.32,"tv":1.79,"id":26354922}]}]}
{"op":"mcm","clk":"11839835222","pt":1723667173551,"mc":[{"id":"1.231737525","rc":[{"batb":[[0,2.34,10],[1,2.32,31.11],[2,1.25,100]],"ltp":2.32,"tv":1.79,"id":26354922}]}]}
{"op":"mcm","clk":"11839835509","pt":1723667176846,"mc":[{"id":"1.231737525","rc":[{"batb":[[0,2.32,31.11],[1,1.25,100],[2,1.1,25000]],"ltp":2.32,"tv":1.79,"id":26354922}]}]}
{"op":"mcm","clk":"11839835723","pt":1723667179268,"mc":[{"id":"1.231737525","rc":[{"batb":[[0,2.34,10],[1,2.32,31.11],[2,1.25,100]],"ltp":2.32,"tv":1.79,"id":26354922}]}]}
{"op":"mcm","clk":"11839835861","pt":1723667180970,"mc":[{"id":"1.231737525","rc":[{"batb":[[0,1.65,10],[1,1.64,216.57],[2,1.63,138.46]],"ltp":1.68,"tv":811.61,"id":26354921}]}]}
{"op":"mcm","clk":"11839835989","pt":1723667182674,"mc":[{"id":"1.231737525","rc":[{"batb":[[0,2.32,31.11],[1,1.25,100],[2,1.1,25000]],"ltp":2.32,"tv":1.79,"id":26354922}]}]}
{"op":"mcm","clk":"11839836188","pt":1723667184994,"mc":[{"id":"1.231737525","rc":[{"batb":[[0,2.34,10],[1,2.32,31.11],[2,1.25,100]],"ltp":2.32,"tv":1.79,"id":26354922}]}]}
{"op":"mcm","clk":"11839836494","pt":1723667188246,"mc":[{"id":"1.231737525","rc":[{"batb":[[0,2.32,31.11],[1,1.25,100],[2,1.1,25000]],"ltp":2.32,"tv":1.79,"id":26354922}]}]}
{"op":"mcm","clk":"11839836714","pt":1723667190669,"mc":[{"id":"1.231737525","rc":[{"batb":[[0,2.34,10],[1,2.32,31.11],[2,1.25,100]],"ltp":2.32,"tv":1.79,"id":26354922}]}]}
{"op":"mcm","clk":"11839837035","pt":1723667194067,"mc":[{"id":"1.231737525","rc":[{"batb":[[0,2.32,31.11],[1,1.25,100],[2,1.1,25000]],"ltp":2.32,"tv":1.79,"id":26354922}]}]}
{"op":"mcm","clk":"11839837242","pt":1723667196390,"mc":[{"id":"1.231737525","rc":[{"batb":[[0,2.34,10],[1,2.32,31.11],[2,1.25,100]],"ltp":2.32,"tv":1.79,"id":26354922}]}]}
{"op":"mcm","clk":"11839837539","pt":1723667199795,"mc":[{"id":"1.231737525","rc":[{"batb":[[0,2.32,31.11],[1,1.25,100],[2,1.1,25000]],"ltp":2.32,"tv":1.79,"id":26354922}]}]}
{"op":"mcm","clk":"11839837753","pt":1723667202182,"mc":[{"id":"1.231737525","rc":[{"batb":[[0,2.34,10],[1,2.32,31.11],[2,1.25,100]],"ltp":2.32,"tv":1.79,"id":26354922}]}]}
{"op":"mcm","clk":"11839838021","pt":1723667205486,"mc":[{"id":"1.231737525","rc":[{"batb":[[0,2.32,31.11],[1,1.25,100],[2,1.1,25000]],"ltp":2.32,"tv":1.79,"id":26354922}]}]}
{"op":"mcm","clk":"11839838215","pt":1723667207804,"mc":[{"id":"1.231737525","rc":[{"batb":[[0,2.34,10],[1,2.32,31.11],[2,1.25,100]],"ltp":2.32,"tv":1.79,"id":26354922}]}]}
{"op":"mcm","clk":"11839838539","pt":1723667211109,"mc":[{"id":"1.231737525","rc":[{"batb":[[0,2.32,31.11],[1,1.25,100],[2,1.1,25000]],"ltp":2.32,"tv":1.79,"id":26354922}]}]}
{"op":"mcm","clk":"11839838739","pt":1723667213435,"mc":[{"id":"1.231737525","rc":[{"batb":[[0,2.34,10],[1,2.32,31.11],[2,1.25,100]],"ltp":2.32,"tv":1.79,"id":26354922}]}]}
{"op":"mcm","clk":"11839839015","pt":1723667216691,"mc":[{"id":"1.231737525","rc":[{"batb":[[0,2.32,31.11],[1,1.25,100],[2,1.1,25000]],"ltp":2.32,"tv":1.79,"id":26354922}]}]}
{"op":"mcm","clk":"11839839188","pt":1723667218906,"mc":[{"id":"1.231737525","rc":[{"batl":[[0,2.54,2],[1,2.58,10.85],[2,2.6,1.3]],"ltp":2.32,"tv":1.79,"id":26354922}]}]}
{"op":"mcm","clk":"11839839202","pt":1723667219110,"mc":[{"id":"1.231737525","rc":[{"batb":[[0,2.34,10],[1,2.32,31.11],[2,1.25,100]],"batl":[[0,2.54,3]],"ltp":2.32,"tv":1.79,"id":26354922}]}]}
{"op":"mcm","clk":"11839839454","pt":1723667222485,"mc":[{"id":"1.231737525","rc":[{"batb":[[0,2.32,31.11],[1,1.25,100],[2,1.1,25000]],"ltp":2.32,"tv":1.79,"id":26354922}]}]}
{"op":"mcm","clk":"11839839637","pt":1723667224819,"mc":[{"id":"1.231737525","rc":[{"batb":[[0,2.34,10],[1,2.32,31.11],[2,1.25,100]],"ltp":2.32,"tv":1.79,"id":26354922}]}]}
{"op":"mcm","clk":"11839839925","pt":1723667228117,"mc":[{"id":"1.231737525","rc":[{"batb":[[0,2.32,31.11],[1,1.25,100],[2,1.1,25000]],"ltp":2.32,"tv":1.79,"id":26354922}]}]}
{"op":"mcm","clk":"11839840103","pt":1723667230489,"mc":[{"id":"1.231737525","rc":[{"batb":[[0,2.34,10],[1,2.32,31.11],[2,1.25,100]],"ltp":2.32,"tv":1.79,"id":26354922}]}]}
{"op":"mcm","clk":"11839840365","pt":1723667233887,"mc":[{"id":"1.231737525","rc":[{"batb":[[0,2.32,31.11],[1,1.25,100],[2,1.1,25000]],"ltp":2.32,"tv":1.79,"id":26354922}]}]}
{"op":"mcm","clk":"11839840513","pt":1723667236211,"mc":[{"id":"1.231737525","rc":[{"batb":[[0,2.34,10],[1,2.32,31.11],[2,1.25,100]],"ltp":2.32,"tv":1.79,"id":26354922}]}]}
{"op":"mcm","clk":"11839840751","pt":1723667239608,"mc":[{"id":"1.231737525","rc":[{"batb":[[0,2.32,31.11],[1,1.25,100],[2,1.1,25000]],"ltp":2.32,"tv":1.79,"id":26354922}]}]}
{"op":"mcm","clk":"11839840916","pt":1723667241820,"mc":[{"id":"1.231737525","rc":[{"batb":[[0,2.34,10],[1,2.32,31.11],[2,1.25,100]],"ltp":2.32,"tv":1.79,"id":26354922}]}]}
{"op":"mcm","clk":"11839841154","pt":1723667244700,"mc":[{"id":"1.231737525","rc":[{"batl":[[0,2.54,246.99],[2,2.6,0]],"ltp":2.32,"tv":1.79,"id":26354922}]}]}
{"op":"mcm","clk":"11839841229","pt":1723667245525,"mc":[{"id":"1.231737525","rc":[{"batb":[[0,2.32,31.11],[1,1.25,100],[2,1.1,25000]],"batl":[[1,2.58,0]],"ltp":2.32,"tv":1.79,"id":26354922}]}]}
{"op":"mcm","clk":"11839841386","pt":1723667247430,"mc":[{"id":"1.231737525","rc":[{"batb":[[0,2.34,10],[1,2.32,31.11],[2,1.25,100]],"ltp":2.32,"tv":1.79,"id":26354922}]}]}
{"op":"mcm","clk":"11839841614","pt":1723667250838,"mc":[{"id":"1.231737525","rc":[{"batb":[[0,2.32,31.11],[1,1.25,100],[2,1.1,25000]],"ltp":2.32,"tv":1.79,"id":26354922}]}]}
{"op":"mcm","clk":"11839841777","pt":1723667253067,"mc":[{"id":"1.231737525","rc":[{"batb":[[0,2.34,10],[1,2.32,31.11],[2,1.25,100]],"ltp":2.32,"tv":1.79,"id":26354922}]}]}
{"op":"mcm","clk":"11839842049","pt":1723667256510,"mc":[{"id":"1.231737525","rc":[{"batb":[[0,2.32,31.11],[1,1.25,100],[2,1.1,25000]],"ltp":2.32,"tv":1.79,"id":26354922}]}]}
{"op":"mcm","clk":"11839842284","pt":1723667259760,"mc":[{"id":"1.231737525","rc":[{"batb":[[0,2.34,10],[1,2.32,31.11],[2,1.25,100]],"ltp":2.32,"tv":1.79,"id":26354922}]}]}
{"op":"mcm","clk":"11839842559","pt":1723667263118,"mc":[{"id":"1.231737525","rc":[{"batb":[[0,2.32,31.11],[1,1.25,100],[2,1.1,25000]],"ltp":2.32,"tv":1.79,"id":26354922}]}]}
{"op":"mcm","clk":"11839842738","pt":1723667265441,"mc":[{"id":"1.231737525","rc":[{"batb":[[0,2.34,10],[1,2.32,31.11],[2,1.25,100]],"ltp":2.32,"tv":1.79,"id":26354922}]}]}
{"op":"mcm","clk":"11839843009","pt":1723667268745,"mc":[{"id":"1.231737525","rc":[{"batb":[[0,2.32,31.11],[1,1.25,100],[2,1.1,25000]],"ltp":2.32,"tv":1.79,"id":26354922}]}]}
{"op":"mcm","clk":"11839843206","pt":1723667271236,"mc":[{"id":"1.231737525","rc":[{"batb":[[0,2.34,10],[1,2.32,31.11],[2,1.25,100]],"ltp":2.32,"tv":1.79,"id":26354922}]}]}
{"op":"mcm","clk":"11839843506","pt":1723667274737,"mc":[{"id":"1.231737525","rc":[{"batb":[[0,2.32,31.11],[1,1.25,100],[2,1.1,25000]],"ltp":2.32,"tv":1.79,"id":26354922}]}]}
{"op":"mcm","clk":"11839843732","pt":1723667277161,"mc":[{"id":"1.231737525","rc":[{"batb":[[0,2.34,10],[1,2.32,31.11],[2,1.25,100]],"ltp":2.32,"tv":1.79,"id":26354922}]}]}
{"op":"mcm","clk":"11839843822","pt":1723667278144,"mc":[{"id":"1.231737525","rc":[{"batl":[[0,2.5,3],[1,2.54,246.99]],"ltp":2.32,"tv":1.79,"id":26354922}]}]}
{"op":"mcm","clk":"11839844012","pt":1723667280473,"mc":[{"id":"1.231737525","rc":[{"batb":[[0,2.32,31.11],[1,1.25,100],[2,1.1,25000]],"ltp":2.32,"tv":1.79,"id":26354922}]}]}
{"op":"mcm","clk":"11839844224","pt":1723667282749,"mc":[{"id":"1.231737525","rc":[{"batb":[[0,2.34,10],[1,2.32,31.11],[2,1.25,100]],"ltp":2.32,"tv":1.79,"id":26354922}]}]}
{"op":"mcm","clk":"11839844509","pt":1723667285951,"mc":[{"id":"1.231737525","rc":[{"batb":[[0,2.32,31.11],[1,1.25,100],[2,1.1,25000]],"ltp":2.32,"tv":1.79,"id":26354922}]}]}
{"op":"mcm","clk":"11839844741","pt":1723667288485,"mc":[{"id":"1.231737525","rc":[{"batb":[[0,2.34,10],[1,2.32,31.11],[2,1.25,100]],"ltp":2.32,"tv":1.79,"id":26354922}]}]}
{"op":"mcm","clk":"11839845057","pt":1723667291974,"mc":[{"id":"1.231737525","rc":[{"batb":[[0,2.32,31.11],[1,1.25,100],[2,1.1,25000]],"ltp":2.32,"tv":1.79,"id":26354922}]}]}
{"op":"mcm","clk":"11839845273","pt":1723667294246,"mc":[{"id":"1.231737525","rc":[{"batb":[[0,2.34,10],[1,2.32,31.11],[2,1.25,100]],"ltp":2.32,"tv":1.79,"id":26354922}]}]}
{"op":"mcm","clk":"11839845585","pt":1723667297682,"mc":[{"id":"1.231737525","rc":[{"batb":[[0,2.32,31.11],[1,1.25,100],[2,1.1,25000]],"ltp":2.32,"tv":1.79,"id":26354922}]}]}
{"op":"mcm","clk":"11839845732","pt":1723667299183,"mc":[{"id":"1.231737525","rc":[{"batl":[[1,1.69,12],[2,1.72,68.54]],"ltp":1.68,"tv":811.61,"id":26354921}]}]}
{"op":"mcm","clk":"11839845838","pt":1723667300368,"mc":[{"id":"1.231737525","rc":[{"batb":[[0,2.34,10],[1,2.32,31.11],[2,1.25,100]],"ltp":2.32,"tv":1.79,"id":26354922},{"batl":[[0,1.69,12],[1,1.71,4.07]],"ltp":1.68,"tv":811.61,"id":26354921}]}]}
{"op":"mcm","clk":"11839846125","pt":1723667303660,"mc":[{"id":"1.231737525","rc":[{"batb":[[0,2.32,31.11],[1,1.25,100],[2,1.1,25000]],"ltp":2.32,"tv":1.79,"id":26354922},{"batl":[[1,1.71,8.2]],"ltp":1.68,"tv":811.61,"id":26354921}]}]}
{"op":"mcm","clk":"11839846342","pt":1723667306185,"mc":[{"id":"1.231737525","rc":[{"batb":[[0,2.34,10],[1,2.32,31.11],[2,1.25,100]],"ltp":2.32,"tv":1.79,"id":26354922}]}]}
{"op":"mcm","clk":"11839846678","pt":1723667309499,"mc":[{"id":"1.231737525","rc":[{"batb":[[0,2.32,31.11],[1,1.25,100],[2,1.1,25000]],"ltp":2.32,"tv":1.79,"id":26354922}]}]}
{"op":"mcm","clk":"11839846921","pt":1723667311778,"mc":[{"id":"1.231737525","rc":[{"batb":[[0,2.34,10],[1,2.32,31.11],[2,1.25,100]],"ltp":2.32,"tv":1.79,"id":26354922}]}]}
{"op":"mcm","clk":"11839847247","pt":1723667315260,"mc":[{"id":"1.231737525","rc":[{"batb":[[0,2.32,31.11],[1,1.25,100],[2,1.1,25000]],"ltp":2.32,"tv":1.79,"id":26354922}]}]}
{"op":"mcm","clk":"11839847551","pt":1723667318603,"mc":[{"id":"1.231737525","rc":[{"batb":[[0,2.34,10],[1,2.32,31.11],[2,1.25,100]],"ltp":2.32,"tv":1.79,"id":26354922}]}]}
{"op":"mcm","clk":"11839847856","pt":1723667322000,"mc":[{"id":"1.231737525","rc":[{"batb":[[0,2.32,31.11],[1,1.25,100],[2,1.1,25000]],"ltp":2.32,"tv":1.79,"id":26354922}]}]}
{"op":"mcm","clk":"11839848095","pt":1723667324378,"mc":[{"id":"1.231737525","rc":[{"batb":[[0,2.34,10],[1,2.32,31.11],[2,1.25,100]],"ltp":2.32,"tv":1.79,"id":26354922}]}]}
{"op":"mcm","clk":"11839848433","pt":1723667327564,"mc":[{"id":"1.231737525","rc":[{"batb":[[0,2.32,31.11],[1,1.25,100],[2,1.1,25000]],"ltp":2.32,"tv":1.79,"id":26354922}]}]}
{"op":"mcm","clk":"11839848680","pt":1723667330095,"mc":[{"id":"1.231737525","rc":[{"batb":[[0,2.34,10],[1,2.32,31.11],[2,1.25,100]],"ltp":2.32,"tv":1.79,"id":26354922}]}]}
{"op":"mcm","clk":"11839848986","pt":1723667333495,"mc":[{"id":"1.231737525","rc":[{"batb":[[0,2.32,31.11],[1,1.25,100],[2,1.1,25000]],"ltp":2.32,"tv":1.79,"id":26354922}]}]}
{"op":"mcm","clk":"11839849193","pt":1723667335813,"mc":[{"id":"1.231737525","rc":[{"batb":[[0,2.34,10],[1,2.32,31.11],[2,1.25,100]],"ltp":2.32,"tv":1.79,"id":26354922}]}]}
{"op":"mcm","clk":"11839849456","pt":1723667338189,"mc":[{"id":"1.231737525","rc":[{"batb":[[0,1.65,20]],"ltp":1.68,"tv":811.61,"id":26354921}]}]}
{"op":"mcm","clk":"11839849564","pt":1723667339326,"mc":[{"id":"1.231737525","rc":[{"batb":[[0,2.32,31.11],[1,1.25,100],[2,1.1,25000]],"ltp":2.32,"tv":1.79,"id":26354922}]}]}
{"op":"mcm","clk":"11839849685","pt":1723667340513,"mc":[{"id":"1.231737525","rc":[{"batl":[[1,2.52,3],[2,2.54,246.99]],"ltp":2.32,"tv":1.79,"id":26354922}]}]}
{"op":"mcm","clk":"11839849830","pt":1723667341706,"mc":[{"id":"1.231737525","rc":[{"batb":[[0,2.34,10],[1,2.32,31.11],[2,1.25,100]],"ltp":2.32,"tv":1.79,"id":26354922}]}]}
{"op":"mcm","clk":"11839850155","pt":1723667345016,"mc":[{"id":"1.231737525","rc":[{"batb":[[0,2.32,31.11],[1,1.25,100],[2,1.1,25000]],"ltp":2.32,"tv":1.79,"id":26354922}]}]}
{"op":"mcm","clk":"11839850373","pt":1723667347133,"mc":[{"id":"1.231737525","rc":[{"batb":[[0,2.34,10],[1,2.32,31.11],[2,1.25,100]],"ltp":2.32,"tv":1.79,"id":26354922},{"batb":[[0,1.66,800],[1,1.65,20],[2,1.64,216.57]],"ltp":1.68,"tv":811.61,"id":26354921}]}]}
{"op":"mcm","clk":"11839850545","pt":1723667348834,"mc":[{"id":"1.231737525","rc":[{"trd":[[1.69,86.53]],"batb":[[0,1.69,178],[1,1.66,800],[2,1.65,20]],"batl":[[0,1.71,8.2],[1,1.72,68.54],[2,1.74,30.67]],"ltp":1.69,"tv":835.61,"id":26354921}],"tv":837.4}]}
{"op":"mcm","clk":"11839850697","pt":1723667350534,"mc":[{"id":"1.231737525","rc":[{"batb":[[0,2.32,31.11],[1,1.25,100],[2,1.1,25000]],"ltp":2.32,"tv":1.79,"id":26354922}]}]}
{"op":"mcm","clk":"11839850925","pt":1723667352908,"mc":[{"id":"1.231737525","rc":[{"batb":[[0,2.34,10],[1,2.32,31.11],[2,1.25,100]],"ltp":2.32,"tv":1.79,"id":26354922}]}]}
{"op":"mcm","clk":"11839850997","pt":1723667353730,"mc":[{"id":"1.231737525","rc":[{"batb":[[0,1.69,237.52]],"ltp":1.69,"tv":835.61,"id":26354921}]}]}
{"op":"mcm","clk":"11839851126","pt":1723667354914,"mc":[{"id":"1.231737525","rc":[{"batb":[[1,1.67,800],[2,1.66,800]],"ltp":1.69,"tv":835.61,"id":26354921}]}]}
{"op":"mcm","clk":"11839851248","pt":1723667356315,"mc":[{"id":"1.231737525","rc":[{"batb":[[0,2.32,31.11],[1,1.25,100],[2,1.1,25000]],"ltp":2.32,"tv":1.79,"id":26354922}]}]}
{"op":"mcm","clk":"11839851562","pt":1723667359411,"mc":[{"id":"1.231737525","rc":[{"batb":[[0,2.34,10],[1,2.32,31.11],[2,1.25,100]],"ltp":2.32,"tv":1.79,"id":26354922}]}]}
{"op":"mcm","clk":"11839851892","pt":1723667362725,"mc":[{"id":"1.231737525","rc":[{"batb":[[0,2.32,31.11],[1,1.25,100],[2,1.1,25000]],"ltp":2.32,"tv":1.79,"id":26354922}]}]}
{"op":"mcm","clk":"11839852148","pt":1723667365268,"mc":[{"id":"1.231737525","rc":[{"batb":[[0,2.34,10],[1,2.32,31.11],[2,1.25,100]],"ltp":2.32,"tv":1.79,"id":26354922},{"batl":[[2,1.74,830.67]],"ltp":1.69,"tv":835.61,"id":26354921}]}]}
{"op":"mcm","clk":"11839852463","pt":1723667368511,"mc":[{"id":"1.231737525","rc":[{"batb":[[0,2.32,31.11],[1,1.25,100],[2,1.1,25000]],"ltp":2.32,"tv":1.79,"id":26354922}]}]}
{"op":"mcm","clk":"11839852700","pt":1723667370939,"mc":[{"id":"1.231737525","rc":[{"batb":[[0,2.34,10],[1,2.32,31.11],[2,1.25,100]],"ltp":2.32,"tv":1.79,"id":26354922}]}]}
{"op":"mcm","clk":"11839853083","pt":1723667374851,"mc":[{"id":"1.231737525","rc":[{"batb":[[0,2.32,31.11],[1,1.25,100],[2,1.1,25000]],"ltp":2.32,"tv":1.79,"id":26354922}]}]}
{"op":"mcm","clk":"11839853270","pt":1723667376611,"mc":[{"id":"1.231737525","rc":[{"batb":[[0,2.34,10],[1,2.32,31.11],[2,1.25,100]],"ltp":2.32,"tv":1.79,"id":26354922}]}]}
{"op":"mcm","clk":"11839853585","pt":1723667379964,"mc":[{"id":"1.231737525","rc":[{"batb":[[0,2.32,31.11],[1,1.25,100],[2,1.1,25000]],"ltp":2.32,"tv":1.79,"id":26354922}]}]}
{"op":"mcm","clk":"11839853823","pt":1723667382336,"mc":[{"id":"1.231737525","rc":[{"batb":[[0,2.34,10],[1,2.32,31.11],[2,1.25,100]],"ltp":2.32,"tv":1.79,"id":26354922}]}]}
{"op":"mcm","clk":"11839854145","pt":1723667385743,"mc":[{"id":"1.231737525","rc":[{"batb":[[0,2.32,31.11],[1,1.25,100],[2,1.1,25000]],"ltp":2.32,"tv":1.79,"id":26354922}]}]}
{"op":"mcm","clk":"11839854382","pt":1723667388066,"mc":[{"id":"1.231737525","rc":[{"batb":[[0,2.34,10],[1,2.32,31.11],[2,1.25,100]],"ltp":2.32,"tv":1.79,"id":26354922}]}]}
{"op":"mcm","clk":"11839854730","pt":1723667391475,"mc":[{"id":"1.231737525","rc":[{"batb":[[0,2.32,31.11],[1,1.25,100],[2,1.1,25000]],"ltp":2.32,"tv":1.79,"id":26354922}]}]}
{"op":"mcm","clk":"11839854963","pt":1723667393890,"mc":[{"id":"1.231737525","rc":[{"batb":[[0,2.34,10],[1,2.32,31.11],[2,1.25,100]],"ltp":2.32,"tv":1.79,"id":26354922}]}]}
{"op":"mcm","clk":"11839855286","pt":1723667397400,"mc":[{"id":"1.231737525","rc":[{"batb":[[0,2.32,31.11],[1,1.25,100],[2,1.1,25000]],"ltp":2.32,"tv":1.79,"id":26354922}]}]}
{"op":"mcm","clk":"11839855500","pt":1723667399568,"mc":[{"id":"1.231737525","rc":[{"batb":[[0,2.34,10],[1,2.32,31.11],[2,1.25,100]],"ltp":2.32,"tv":1.79,"id":26354922}]}]}
{"op":"mcm","clk":"11839855851","pt":1723667402875,"mc":[{"id":"1.231737525","rc":[{"batb":[[0,2.32,31.11],[1,1.25,100],[2,1.1,25000]],"ltp":2.32,"tv":1.79,"id":26354922}]}]}
{"op":"mcm","clk":"11839856140","pt":1723667405302,"mc":[{"id":"1.231737525","rc":[{"batb":[[0,2.34,10],[1,2.32,31.11],[2,1.25,100]],"ltp":2.32,"tv":1.79,"id":26354922}]}]}
{"op":"mcm","clk":"11839856540","pt":1723667408808,"mc":[{"id":"1.231737525","rc":[{"batb":[[0,2.32,31.11],[1,1.25,100],[2,1.1,25000]],"ltp":2.32,"tv":1.79,"id":26354922}]}]}
{"op":"mcm","clk":"11839856769","pt":1723667410674,"mc":[{"id":"1.231737525","rc":[{"trd":[[1.69,561.57]],"batb":[[0,1.67,800],[1,1.66,800],[2,1.65,20]],"batl":[[0,1.68,8.34],[1,1.69,4089.4],[2,1.72,68.54]],"ltp":1.69,"tv":1310.65,"id":26354921}],"tv":1312.44}]}
{"op":"mcm","clk":"11839856894","pt":1723667411843,"mc":[{"id":"1.231737525","rc":[{"batb":[[0,2.34,10],[1,2.32,31.11],[2,1.25,100]],"ltp":2.32,"tv":1.79,"id":26354922}]}]}
{"op":"mcm","clk":"11839857110","pt":1723667413782,"mc":[{"id":"1.231737525","rc":[{"batb":[[2,1.65,83.19]],"ltp":1.69,"tv":1310.65,"id":26354921}]}]}
{"op":"mcm","clk":"11839857269","pt":1723667415226,"mc":[{"id":"1.231737525","rc":[{"batb":[[0,2.32,31.11],[1,1.25,100],[2,1.1,25000]],"ltp":2.32,"tv":1.79,"id":26354922}]}]}
{"op":"mcm","clk":"11839857504","pt":1723667417405,"mc":[{"id":"1.231737525","rc":[{"batb":[[0,2.34,10],[1,2.32,31.11],[2,1.25,100]],"ltp":2.32,"tv":1.79,"id":26354922}]}]}
{"op":"mcm","clk":"11839857844","pt":1723667420612,"mc":[{"id":"1.231737525","rc":[{"batb":[[0,2.32,31.11],[1,1.25,100],[2,1.1,25000]],"ltp":2.32,"tv":1.79,"id":26354922}]}]}
{"op":"mcm","clk":"11839858097","pt":1723667423095,"mc":[{"id":"1.231737525","rc":[{"batb":[[0,2.34,10],[1,2.32,31.11],[2,1.25,100]],"ltp":2.32,"tv":1.79,"id":26354922}]}]}
{"op":"mcm","clk":"11839858434","pt":1723667426300,"mc":[{"id":"1.231737525","rc":[{"batb":[[0,2.32,31.11],[1,1.25,100],[2,1.1,25000]],"ltp":2.32,"tv":1.79,"id":26354922}]}]}
{"op":"mcm","clk":"11839858669","pt":1723667428527,"mc":[{"id":"1.231737525","rc":[{"batb":[[0,2.34,10],[1,2.32,31.11],[2,1.25,100]],"ltp":2.32,"tv":1.79,"id":26354922}]}]}
{"op":"mcm","clk":"11839859032","pt":1723667431993,"mc":[{"id":"1.231737525","rc":[{"batb":[[0,2.32,31.11],[1,1.25,100],[2,1.1,25000]],"ltp":2.32,"tv":1.79,"id":26354922}]}]}
{"op":"mcm","clk":"11839859150","pt":1723667433435,"mc":[{"id":"1.231737525","rc":[{"batb":[[1,1.1,25000],[2,1.09,25000]],"ltp":2.32,"tv":1.79,"id":26354922}]}]}
{"op":"mcm","clk":"11839859356","pt":1723667435716,"mc":[{"id":"1.231737525","rc":[{"batb":[[0,2.34,10],[1,2.32,31.11],[2,1.1,25000]],"ltp":2.32,"tv":1.79,"id":26354922}]}]}
{"op":"mcm","clk":"11839859689","pt":1723667439040,"mc":[{"id":"1.231737525","rc":[{"batb":[[0,2.32,31.11],[1,1.1,25000],[2,1.09,25000]],"ltp":2.32,"tv":1.79,"id":26354922}]}]}
{"op":"mcm","clk":"11839860009","pt":1723667442135,"mc":[{"id":"1.231737525","rc":[{"batb":[[0,2.34,10],[1,2.32,31.11],[2,1.1,25000]],"ltp":2.32,"tv":1.79,"id":26354922}]}]}
{"op":"mcm","clk":"11839860332","pt":1723667445524,"mc":[{"id":"1.231737525","rc":[{"batb":[[0,2.32,31.11],[1,1.1,25000],[2,1.09,25000]],"ltp":2.32,"tv":1.79,"id":26354922}]}]}
{"op":"mcm","clk":"11839860552","pt":1723667447842,"mc":[{"id":"1.231737525","rc":[{"batb":[[0,2.34,10],[1,2.32,31.11],[2,1.1,25000]],"ltp":2.32,"tv":1.79,"id":26354922}]}]}
{"op":"mcm","clk":"11839860696","pt":1723667449132,"mc":[{"id":"1.231737525","rc":[{"batb":[[2,1.65,759.41]],"ltp":1.69,"tv":1310.65,"id":26354921}]}]}
{"op":"mcm","clk":"11839860904","pt":1723667451242,"mc":[{"id":"1.231737525","rc":[{"batb":[[0,2.32,31.11],[1,1.1,25000],[2,1.09,25000]],"ltp":2.32,"tv":1.79,"id":26354922}]}]}
{"op":"mcm","clk":"11839861099","pt":1723667453357,"mc":[{"id":"1.231737525","rc":[{"batb":[[0,2.34,10],[1,2.32,31.11],[2,1.1,25000]],"ltp":2.32,"tv":1.79,"id":26354922}]}]}
{"op":"mcm","clk":"11839861436","pt":1723667456758,"mc":[{"id":"1.231737525","rc":[{"batb":[[0,2.32,31.11],[1,1.1,25000],[2,1.09,25000]],"ltp":2.32,"tv":1.79,"id":26354922}]}]}
{"op":"mcm","clk":"11839861648","pt":1723667459038,"mc":[{"id":"1.231737525","rc":[{"batb":[[0,2.34,10],[1,2.32,31.11],[2,1.1,25000]],"ltp":2.32,"tv":1.79,"id":26354922}]}]}
{"op":"mcm","clk":"11839861967","pt":1723667462547,"mc":[{"id":"1.231737525","rc":[{"batb":[[0,2.32,31.11],[1,1.1,25000],[2,1.09,25000]],"ltp":2.32,"tv":1.79,"id":26354922}]}]}
{"op":"mcm","clk":"11839862154","pt":1723667464767,"mc":[{"id":"1.231737525","rc":[{"batb":[[0,2.34,10],[1,2.32,31.11],[2,1.1,25000]],"ltp":2.32,"tv":1.79,"id":26354922}]}]}
{"op":"mcm","clk":"11839862542","pt":1723667468946,"mc":[{"id":"1.231737525","rc":[{"batb":[[0,2.32,31.11],[1,1.1,25000],[2,1.09,25000]],"ltp":2.32,"tv":1.79,"id":26354922}]}]}
{"op":"mcm","clk":"11839862689","pt":1723667470440,"mc":[{"id":"1.231737525","rc":[{"batb":[[0,2.34,10],[1,2.32,31.11],[2,1.1,25000]],"ltp":2.32,"tv":1.79,"id":26354922}]}]}
{"op":"mcm","clk":"11839863011","pt":1723667473841,"mc":[{"id":"1.231737525","rc":[{"batb":[[0,2.32,31.11],[1,1.1,25000],[2,1.09,25000]],"ltp":2.32,"tv":1.79,"id":26354922}]}]}
{"op":"mcm","clk":"11839863320","pt":1723667476935,"mc":[{"id":"1.231737525","rc":[{"batb":[[0,2.34,10],[1,2.32,31.11],[2,1.1,25000]],"ltp":2.32,"tv":1.79,"id":26354922}]}]}
{"op":"mcm","clk":"11839863587","pt":1723667479467,"mc":[{"id":"1.231737525","rc":[{"batb":[[0,2.32,31.11],[1,1.1,25000],[2,1.09,25000]],"ltp":2.32,"tv":1.79,"id":26354922}]}]}
{"op":"mcm","clk":"11839863877","pt":1723667482151,"mc":[{"id":"1.231737525","rc":[{"batb":[[0,2.34,10],[1,2.32,31.11],[2,1.1,25000]],"ltp":2.32,"tv":1.79,"id":26354922}]}]}
{"op":"mcm","clk":"11839864235","pt":1723667485555,"mc":[{"id":"1.231737525","rc":[{"batb":[[0,2.32,31.11],[1,1.1,25000],[2,1.09,25000]],"ltp":2.32,"tv":1.79,"id":26354922}]}]}
{"op":"mcm","clk":"11839864553","pt":1723667488660,"mc":[{"id":"1.231737525","rc":[{"batb":[[0,2.34,10],[1,2.32,31.11],[2,1.1,25000]],"ltp":2.32,"tv":1.79,"id":26354922}]}]}
{"op":"mcm","clk":"11839864875","pt":1723667491959,"mc":[{"id":"1.231737525","rc":[{"batb":[[0,2.32,31.11],[1,1.1,25000],[2,1.09,25000]],"ltp":2.32,"tv":1.79,"id":26354922}]}]}
{"op":"mcm","clk":"11839865114","pt":1723667494180,"mc":[{"id":"1.231737525","rc":[{"batb":[[0,2.34,10],[1,2.32,31.11],[2,1.1,25000]],"ltp":2.32,"tv":1.79,"id":26354922}]}]}
{"op":"mcm","clk":"11839865500","pt":1723667497481,"mc":[{"id":"1.231737525","rc":[{"batb":[[0,2.32,31.11],[1,1.1,25000],[2,1.09,25000]],"ltp":2.32,"tv":1.79,"id":26354922}]}]}
{"op":"mcm","clk":"11839865772","pt":1723667499853,"mc":[{"id":"1.231737525","rc":[{"batb":[[0,2.34,10],[1,2.32,31.11],[2,1.1,25000]],"ltp":2.32,"tv":1.79,"id":26354922}]}]}
{"op":"mcm","clk":"11839866118","pt":1723667503102,"mc":[{"id":"1.231737525","rc":[{"batb":[[0,2.32,31.11],[1,1.1,25000],[2,1.09,25000]],"ltp":2.32,"tv":1.79,"id":26354922}]}]}
{"op":"mcm","clk":"11839866358","pt":1723667505526,"mc":[{"id":"1.231737525","rc":[{"batb":[[0,2.34,10],[1,2.32,31.11],[2,1.1,25000]],"ltp":2.32,"tv":1.79,"id":26354922}]}]}
{"op":"mcm","clk":"11839866704","pt":1723667508899,"mc":[{"id":"1.231737525","rc":[{"batb":[[0,2.32,31.11],[1,1.1,25000],[2,1.09,25000]],"ltp":2.32,"tv":1.79,"id":26354922}]}]}
{"op":"mcm","clk":"11839867060","pt":1723667512005,"mc":[{"id":"1.231737525","rc":[{"batb":[[0,2.34,10],[1,2.32,31.11],[2,1.1,25000]],"ltp":2.32,"tv":1.79,"id":26354922}]}]}
{"op":"mcm","clk":"11839867384","pt":1723667515293,"mc":[{"id":"1.231737525","rc":[{"batb":[[0,2.32,31.11],[1,1.1,25000],[2,1.09,25000]],"ltp":2.32,"tv":1.79,"id":26354922}]}]}
{"op":"mcm","clk":"11839867639","pt":1723667517714,"mc":[{"id":"1.231737525","rc":[{"batb":[[0,2.34,10],[1,2.32,31.11],[2,1.1,25000]],"ltp":2.32,"tv":1.79,"id":26354922}]}]}
{"op":"mcm","clk":"11839867973","pt":1723667521075,"mc":[{"id":"1.231737525","rc":[{"batb":[[0,2.32,31.11],[1,1.1,25000],[2,1.09,25000]],"ltp":2.32,"tv":1.79,"id":26354922}]}]}
{"op":"mcm","clk":"11839868304","pt":1723667524281,"mc":[{"id":"1.231737525","rc":[{"batb":[[0,2.34,10],[1,2.32,31.11],[2,1.1,25000]],"ltp":2.32,"tv":1.79,"id":26354922}]}]}
{"op":"mcm","clk":"11839868638","pt":1723667527693,"mc":[{"id":"1.231737525","rc":[{"batb":[[0,2.32,31.11],[1,1.1,25000],[2,1.09,25000]],"ltp":2.32,"tv":1.79,"id":26354922}]}]}
{"op":"mcm","clk":"11839868824","pt":1723667529806,"mc":[{"id":"1.231737525","rc":[{"batb":[[0,2.34,10],[1,2.32,31.11],[2,1.1,25000]],"ltp":2.32,"tv":1.79,"id":26354922}]}]}
{"op":"mcm","clk":"11839869139","pt":1723667533212,"mc":[{"id":"1.231737525","rc":[{"batb":[[0,2.32,31.11],[1,1.1,25000],[2,1.09,25000]],"ltp":2.32,"tv":1.79,"id":26354922}]}]}
{"op":"mcm","clk":"11839869349","pt":1723667535384,"mc":[{"id":"1.231737525","rc":[{"batb":[[0,2.34,10],[1,2.32,31.11],[2,1.1,25000]],"ltp":2.32,"tv":1.79,"id":26354922}]}]}
{"op":"mcm","clk":"11839869690","pt":1723667538934,"mc":[{"id":"1.231737525","rc":[{"batb":[[0,2.32,31.11],[1,1.1,25000],[2,1.09,25000]],"ltp":2.32,"tv":1.79,"id":26354922}]}]}
{"op":"mcm","clk":"11839869909","pt":1723667541103,"mc":[{"id":"1.231737525","rc":[{"batb":[[0,2.34,10],[1,2.32,31.11],[2,1.1,25000]],"ltp":2.32,"tv":1.79,"id":26354922}]}]}
{"op":"mcm","clk":"11839870235","pt":1723667544503,"mc":[{"id":"1.231737525","rc":[{"batb":[[0,2.32,31.11],[1,1.1,25000],[2,1.09,25000]],"ltp":2.32,"tv":1.79,"id":26354922}]}]}
{"op":"mcm","clk":"11839870536","pt":1723667547906,"mc":[{"id":"1.231737525","rc":[{"batb":[[0,2.34,10],[1,2.32,31.11],[2,1.1,25000]],"ltp":2.32,"tv":1.79,"id":26354922}]}]}
{"op":"mcm","clk":"11839870813","pt":1723667551150,"mc":[{"id":"1.231737525","rc":[{"batb":[[0,2.32,31.11],[1,1.1,25000],[2,1.09,25000]],"ltp":2.32,"tv":1.79,"id":26354922}]}]}
{"op":"mcm","clk":"11839871057","pt":1723667553514,"mc":[{"id":"1.231737525","rc":[{"batb":[[0,2.34,10],[1,2.32,31.11],[2,1.1,25000]],"ltp":2.32,"tv":1.79,"id":26354922}]}]}
{"op":"mcm","clk":"11839871373","pt":1723667556922,"mc":[{"id":"1.231737525","rc":[{"batb":[[0,2.32,31.11],[1,1.1,25000],[2,1.09,25000]],"ltp":2.32,"tv":1.79,"id":26354922}]}]}
{"op":"mcm","clk":"11839871561","pt":1723667559241,"mc":[{"id":"1.231737525","rc":[{"batb":[[0,2.34,10],[1,2.32,31.11],[2,1.1,25000]],"ltp":2.32,"tv":1.79,"id":26354922}]}]}
{"op":"mcm","clk":"11839871873","pt":1723667562546,"mc":[{"id":"1.231737525","rc":[{"batb":[[0,2.32,31.11],[1,1.1,25000],[2,1.09,25000]],"ltp":2.32,"tv":1.79,"id":26354922}]}]}
{"op":"mcm","clk":"11839872082","pt":1723667564761,"mc":[{"id":"1.231737525","rc":[{"batb":[[0,2.34,10],[1,2.32,31.11],[2,1.1,25000]],"ltp":2.32,"tv":1.79,"id":26354922}]}]}
{"op":"mcm","clk":"11839872408","pt":1723667568125,"mc":[{"id":"1.231737525","rc":[{"batb":[[0,2.32,31.11],[1,1.1,25000],[2,1.09,25000]],"ltp":2.32,"tv":1.79,"id":26354922}]}]}
{"op":"mcm","clk":"11839872604","pt":1723667570440,"mc":[{"id":"1.231737525","rc":[{"batb":[[0,2.34,10],[1,2.32,31.11],[2,1.1,25000]],"ltp":2.32,"tv":1.79,"id":26354922}]}]}
{"op":"mcm","clk":"11839872922","pt":1723667573837,"mc":[{"id":"1.231737525","rc":[{"batb":[[0,2.32,31.11],[1,1.1,25000],[2,1.09,25000]],"ltp":2.32,"tv":1.79,"id":26354922}]}]}
{"op":"mcm","clk":"11839873125","pt":1723667576151,"mc":[{"id":"1.231737525","rc":[{"batb":[[0,2.34,10],[1,2.32,31.11],[2,1.1,25000]],"ltp":2.32,"tv":1.79,"id":26354922}]}]}
{"op":"mcm","clk":"11839873418","pt":1723667579446,"mc":[{"id":"1.231737525","rc":[{"batb":[[0,2.32,31.11],[1,1.1,25000],[2,1.09,25000]],"ltp":2.32,"tv":1.79,"id":26354922}]}]}
{"op":"mcm","clk":"11839873821","pt":1723667583875,"mc":[{"id":"1.231737525","rc":[{"batb":[[0,2.34,10],[1,2.32,31.11],[2,1.1,25000]],"ltp":2.32,"tv":1.79,"id":26354922}]}]}
{"op":"mcm","clk":"11839874090","pt":1723667587177,"mc":[{"id":"1.231737525","rc":[{"batb":[[0,2.32,31.11],[1,1.1,25000],[2,1.09,25000]],"ltp":2.32,"tv":1.79,"id":26354922}]}]}
{"op":"mcm","clk":"11839874322","pt":1723667589447,"mc":[{"id":"1.231737525","rc":[{"batb":[[0,2.34,10],[1,2.32,31.11],[2,1.1,25000]],"ltp":2.32,"tv":1.79,"id":26354922}]}]}
{"op":"mcm","clk":"11839874653","pt":1723667592854,"mc":[{"id":"1.231737525","rc":[{"batb":[[0,2.32,31.11],[1,1.1,25000],[2,1.09,25000]],"ltp":2.32,"tv":1.79,"id":26354922}]}]}
{"op":"mcm","clk":"11839875015","pt":1723667596894,"mc":[{"id":"1.231737525","rc":[{"batb":[[0,2.34,10],[1,2.32,31.11],[2,1.1,25000]],"ltp":2.32,"tv":1.79,"id":26354922}]}]}
{"op":"mcm","clk":"11839875319","pt":1723667600099,"mc":[{"id":"1.231737525","rc":[{"batb":[[0,2.32,31.11],[1,1.1,25000],[2,1.09,25000]],"ltp":2.32,"tv":1.79,"id":26354922}]}]}
{"op":"mcm","clk":"11839875572","pt":1723667602479,"mc":[{"id":"1.231737525","rc":[{"batb":[[0,2.34,10],[1,2.32,31.11],[2,1.1,25000]],"ltp":2.32,"tv":1.79,"id":26354922}]}]}
{"op":"mcm","clk":"11839875913","pt":1723667605983,"mc":[{"id":"1.231737525","rc":[{"batb":[[0,2.32,31.11],[1,1.1,25000],[2,1.09,25000]],"ltp":2.32,"tv":1.79,"id":26354922}]}]}
{"op":"mcm","clk":"11839876148","pt":1723667608298,"mc":[{"id":"1.231737525","rc":[{"batb":[[0,2.34,10],[1,2.32,31.11],[2,1.1,25000]],"ltp":2.32,"tv":1.79,"id":26354922}]}]}
{"op":"mcm","clk":"11839876445","pt":1723667611593,"mc":[{"id":"1.231737525","rc":[{"batb":[[0,2.32,31.11],[1,1.1,25000],[2,1.09,25000]],"ltp":2.32,"tv":1.79,"id":26354922}]}]}
{"op":"mcm","clk":"11839876661","pt":1723667613966,"mc":[{"id":"1.231737525","rc":[{"batb":[[0,2.34,10],[1,2.32,31.11],[2,1.1,25000]],"ltp":2.32,"tv":1.79,"id":26354922}]}]}
{"op":"mcm","clk":"11839876994","pt":1723667617308,"mc":[{"id":"1.231737525","rc":[{"batb":[[0,2.32,31.11],[1,1.1,25000],[2,1.09,25000]],"ltp":2.32,"tv":1.79,"id":26354922}]}]}
{"op":"mcm","clk":"11839877221","pt":1723667619579,"mc":[{"id":"1.231737525","rc":[{"batb":[[0,2.34,10],[1,2.32,31.11],[2,1.1,25000]],"ltp":2.32,"tv":1.79,"id":26354922}]}]}
{"op":"mcm","clk":"11839877534","pt":1723667622779,"mc":[{"id":"1.231737525","rc":[{"batb":[[0,2.32,31.11],[1,1.1,25000],[2,1.09,25000]],"ltp":2.32,"tv":1.79,"id":26354922}]}]}
{"op":"mcm","clk":"11839877741","pt":1723667625104,"mc":[{"id":"1.231737525","rc":[{"batb":[[0,2.34,10],[1,2.32,31.11],[2,1.1,25000]],"ltp":2.32,"tv":1.79,"id":26354922}]}]}
{"op":"mcm","clk":"11839878067","pt":1723667628504,"mc":[{"id":"1.231737525","rc":[{"batb":[[0,2.32,31.11],[1,1.1,25000],[2,1.09,25000]],"ltp":2.32,"tv":1.79,"id":26354922}]}]}
{"op":"mcm","clk":"11839878319","pt":1723667630887,"mc":[{"id":"1.231737525","rc":[{"batb":[[0,2.34,10],[1,2.32,31.11],[2,1.1,25000]],"ltp":2.32,"tv":1.79,"id":26354922}]}]}
{"op":"mcm","clk":"11839878647","pt":1723667634197,"mc":[{"id":"1.231737525","rc":[{"batb":[[0,2.32,31.11],[1,1.1,25000],[2,1.09,25000]],"ltp":2.32,"tv":1.79,"id":26354922}]}]}
{"op":"mcm","clk":"11839878885","pt":1723667636616,"mc":[{"id":"1.231737525","rc":[{"batb":[[0,2.34,10],[1,2.32,31.11],[2,1.1,25000]],"ltp":2.32,"tv":1.79,"id":26354922}]}]}
{"op":"mcm","clk":"11839879186","pt":1723667640025,"mc":[{"id":"1.231737525","rc":[{"batb":[[0,2.32,31.11],[1,1.1,25000],[2,1.09,25000]],"ltp":2.32,"tv":1.79,"id":26354922}]}]}
{"op":"mcm","clk":"11839879425","pt":1723667642316,"mc":[{"id":"1.231737525","rc":[{"batb":[[0,2.34,10],[1,2.32,31.11],[2,1.1,25000]],"ltp":2.32,"tv":1.79,"id":26354922}]}]}
{"op":"mcm","clk":"11839879754","pt":1723667645608,"mc":[{"id":"1.231737525","rc":[{"batb":[[0,2.32,31.11],[1,1.1,25000],[2,1.09,25000]],"ltp":2.32,"tv":1.79,"id":26354922}]}]}
{"op":"mcm","clk":"11839879951","pt":1723667648026,"mc":[{"id":"1.231737525","rc":[{"batb":[[0,2.34,10],[1,2.32,31.11],[2,1.1,25000]],"ltp":2.32,"tv":1.79,"id":26354922}]}]}
{"op":"mcm","clk":"11839880278","pt":1723667651431,"mc":[{"id":"1.231737525","rc":[{"batb":[[0,2.32,31.11],[1,1.1,25000],[2,1.09,25000]],"ltp":2.32,"tv":1.79,"id":26354922}]}]}
{"op":"mcm","clk":"11839880501","pt":1723667653803,"mc":[{"id":"1.231737525","rc":[{"batb":[[0,2.34,10],[1,2.32,31.11],[2,1.1,25000]],"ltp":2.32,"tv":1.79,"id":26354922}]}]}
{"op":"mcm","clk":"11839880795","pt":1723667657103,"mc":[{"id":"1.231737525","rc":[{"batb":[[0,2.32,31.11],[1,1.1,25000],[2,1.09,25000]],"ltp":2.32,"tv":1.79,"id":26354922}]}]}
{"op":"mcm","clk":"11839880975","pt":1723667659319,"mc":[{"id":"1.231737525","rc":[{"batb":[[0,2.34,10],[1,2.32,31.11],[2,1.1,25000]],"ltp":2.32,"tv":1.79,"id":26354922}]}]}
{"op":"mcm","clk":"11839881335","pt":1723667662613,"mc":[{"id":"1.231737525","rc":[{"batb":[[0,2.32,31.11],[1,1.1,25000],[2,1.09,25000]],"ltp":2.32,"tv":1.79,"id":26354922}]}]}
{"op":"mcm","clk":"11839881522","pt":1723667664924,"mc":[{"id":"1.231737525","rc":[{"batb":[[0,2.34,10],[1,2.32,31.11],[2,1.1,25000]],"ltp":2.32,"tv":1.79,"id":26354922}]}]}
{"op":"mcm","clk":"11839881809","pt":1723667668196,"mc":[{"id":"1.231737525","rc":[{"batb":[[0,2.32,31.11],[1,1.1,25000],[2,1.09,25000]],"ltp":2.32,"tv":1.79,"id":26354922}]}]}
{"op":"mcm","clk":"11839881986","pt":1723667670525,"mc":[{"id":"1.231737525","rc":[{"batb":[[0,2.34,10],[1,2.32,31.11],[2,1.1,25000]],"ltp":2.32,"tv":1.79,"id":26354922}]}]}
{"op":"mcm","clk":"11839882271","pt":1723667673822,"mc":[{"id":"1.231737525","rc":[{"batb":[[0,2.32,31.11],[1,1.1,25000],[2,1.09,25000]],"ltp":2.32,"tv":1.79,"id":26354922}]}]}
{"op":"mcm","clk":"11839882470","pt":1723667676342,"mc":[{"id":"1.231737525","rc":[{"batb":[[0,2.34,10],[1,2.32,31.11],[2,1.1,25000]],"ltp":2.32,"tv":1.79,"id":26354922}]}]}
{"op":"mcm","clk":"11839882773","pt":1723667679738,"mc":[{"id":"1.231737525","rc":[{"batb":[[0,2.32,31.11],[1,1.1,25000],[2,1.09,25000]],"ltp":2.32,"tv":1.79,"id":26354922}]}]}
{"op":"mcm","clk":"11839882990","pt":1723667682156,"mc":[{"id":"1.231737525","rc":[{"batb":[[0,2.34,10],[1,2.32,31.11],[2,1.1,25000]],"ltp":2.32,"tv":1.79,"id":26354922}]}]}
{"op":"mcm","clk":"11839883287","pt":1723667685553,"mc":[{"id":"1.231737525","rc":[{"batb":[[0,2.32,31.11],[1,1.1,25000],[2,1.09,25000]],"ltp":2.32,"tv":1.79,"id":26354922}]}]}
{"op":"mcm","clk":"11839883577","pt":1723667689465,"mc":[{"id":"1.231737525","rc":[{"batb":[[0,2.34,10],[1,2.32,31.11],[2,1.1,25000]],"ltp":2.32,"tv":1.79,"id":26354922}]}]}
{"op":"mcm","clk":"11839883867","pt":1723667692761,"mc":[{"id":"1.231737525","rc":[{"batb":[[0,2.32,31.11],[1,1.1,25000],[2,1.09,25000]],"ltp":2.32,"tv":1.79,"id":26354922}]}]}
{"op":"mcm","clk":"11839884069","pt":1723667695083,"mc":[{"id":"1.231737525","rc":[{"batb":[[0,2.34,10],[1,2.32,31.11],[2,1.1,25000]],"ltp":2.32,"tv":1.79,"id":26354922}]}]}
{"op":"mcm","clk":"11839884367","pt":1723667698371,"mc":[{"id":"1.231737525","rc":[{"batb":[[0,2.32,31.11],[1,1.1,25000],[2,1.09,25000]],"ltp":2.32,"tv":1.79,"id":26354922}]}]}
{"op":"mcm","clk":"11839884624","pt":1723667700792,"mc":[{"id":"1.231737525","rc":[{"batb":[[0,2.34,10],[1,2.32,31.11],[2,1.1,25000]],"ltp":2.32,"tv":1.79,"id":26354922}]}]}
{"op":"mcm","clk":"11839884925","pt":1723667704089,"mc":[{"id":"1.231737525","rc":[{"batb":[[0,2.32,31.11],[1,1.1,25000],[2,1.09,25000]],"ltp":2.32,"tv":1.79,"id":26354922}]}]}
{"op":"mcm","clk":"11839885122","pt":1723667706356,"mc":[{"id":"1.231737525","rc":[{"batb":[[0,2.34,10],[1,2.32,31.11],[2,1.1,25000]],"ltp":2.32,"tv":1.79,"id":26354922}]}]}
{"op":"mcm","clk":"11839885445","pt":1723667709653,"mc":[{"id":"1.231737525","rc":[{"batb":[[0,2.32,31.11],[1,1.1,25000],[2,1.09,25000]],"ltp":2.32,"tv":1.79,"id":26354922}]}]}
{"op":"mcm","clk":"11839885678","pt":1723667712076,"mc":[{"id":"1.231737525","rc":[{"batb":[[0,2.34,10],[1,2.32,31.11],[2,1.1,25000]],"ltp":2.32,"tv":1.79,"id":26354922}]}]}
{"op":"mcm","clk":"11839886004","pt":1723667715579,"mc":[{"id":"1.231737525","rc":[{"batb":[[0,2.32,31.11],[1,1.1,25000],[2,1.09,25000]],"ltp":2.32,"tv":1.79,"id":26354922}]}]}
{"op":"mcm","clk":"11839886216","pt":1723667717963,"mc":[{"id":"1.231737525","rc":[{"batb":[[0,2.34,10],[1,2.32,31.11],[2,1.1,25000]],"ltp":2.32,"tv":1.79,"id":26354922}]}]}
{"op":"mcm","clk":"11839886459","pt":1723667721264,"mc":[{"id":"1.231737525","rc":[{"batb":[[0,2.32,31.11],[1,1.1,25000],[2,1.09,25000]],"ltp":2.32,"tv":1.79,"id":26354922}]}]}
{"op":"mcm","clk":"11839886670","pt":1723667723582,"mc":[{"id":"1.231737525","rc":[{"batb":[[0,2.34,10],[1,2.32,31.11],[2,1.1,25000]],"ltp":2.32,"tv":1.79,"id":26354922}]}]}
{"op":"mcm","clk":"11839886987","pt":1723667726988,"mc":[{"id":"1.231737525","rc":[{"batb":[[0,2.32,31.11],[1,1.1,25000],[2,1.09,25000]],"ltp":2.32,"tv":1.79,"id":26354922}]}]}
{"op":"mcm","clk":"11839887266","pt":1723667729875,"mc":[{"id":"1.231737525","rc":[{"batb":[[0,2.34,10],[1,2.32,31.11],[2,1.1,25000]],"ltp":2.32,"tv":1.79,"id":26354922}]}]}
{"op":"mcm","clk":"11839887600","pt":1723667733274,"mc":[{"id":"1.231737525","rc":[{"batb":[[0,2.32,31.11],[1,1.1,25000],[2,1.09,25000]],"ltp":2.32,"tv":1.79,"id":26354922}]}]}
{"op":"mcm","clk":"11839887833","pt":1723667735598,"mc":[{"id":"1.231737525","rc":[{"batb":[[0,2.34,10],[1,2.32,31.11],[2,1.1,25000]],"ltp":2.32,"tv":1.79,"id":26354922}]}]}
{"op":"mcm","clk":"11839888101","pt":1723667738930,"mc":[{"id":"1.231737525","rc":[{"batb":[[0,2.32,31.11],[1,1.1,25000],[2,1.09,25000]],"ltp":2.32,"tv":1.79,"id":26354922}]}]}
{"op":"mcm","clk":"11839888310","pt":1723667741094,"mc":[{"id":"1.231737525","rc":[{"batb":[[0,2.34,10],[1,2.32,31.11],[2,1.1,25000]],"ltp":2.32,"tv":1.79,"id":26354922}]}]}
{"op":"mcm","clk":"11839888634","pt":1723667744498,"mc":[{"id":"1.231737525","rc":[{"batb":[[0,2.32,31.11],[1,1.1,25000],[2,1.09,25000]],"ltp":2.32,"tv":1.79,"id":26354922}]}]}
{"op":"mcm","clk":"11839888815","pt":1723667746807,"mc":[{"id":"1.231737525","rc":[{"batb":[[0,2.34,10],[1,2.32,31.11],[2,1.1,25000]],"ltp":2.32,"tv":1.79,"id":26354922}]}]}
{"op":"mcm","clk":"11839889056","pt":1723667750091,"mc":[{"id":"1.231737525","rc":[{"batb":[[0,2.32,31.11],[1,1.1,25000],[2,1.09,25000]],"ltp":2.32,"tv":1.79,"id":26354922}]}]}
{"op":"mcm","clk":"11839889254","pt":1723667752518,"mc":[{"id":"1.231737525","rc":[{"batb":[[0,2.34,10],[1,2.32,31.11],[2,1.1,25000]],"ltp":2.32,"tv":1.79,"id":26354922}]}]}
{"op":"mcm","clk":"11839889515","pt":1723667756018,"mc":[{"id":"1.231737525","rc":[{"batb":[[0,2.32,31.11],[1,1.1,25000],[2,1.09,25000]],"ltp":2.32,"tv":1.79,"id":26354922}]}]}
{"op":"mcm","clk":"11839889712","pt":1723667758297,"mc":[{"id":"1.231737525","rc":[{"batb":[[0,2.34,10],[1,2.32,31.11],[2,1.1,25000]],"ltp":2.32,"tv":1.79,"id":26354922}]}]}
{"op":"mcm","clk":"11839890010","pt":1723667761815,"mc":[{"id":"1.231737525","rc":[{"batb":[[0,2.32,31.11],[1,1.1,25000],[2,1.09,25000]],"ltp":2.32,"tv":1.79,"id":26354922}]}]}
{"op":"mcm","clk":"11839890258","pt":1723667764242,"mc":[{"id":"1.231737525","rc":[{"batb":[[0,2.34,10],[1,2.32,31.11],[2,1.1,25000]],"ltp":2.32,"tv":1.79,"id":26354922}]}]}
{"op":"mcm","clk":"11839890537","pt":1723667767543,"mc":[{"id":"1.231737525","rc":[{"batb":[[0,2.32,31.11],[1,1.1,25000],[2,1.09,25000]],"ltp":2.32,"tv":1.79,"id":26354922}]}]}
{"op":"mcm","clk":"11839890697","pt":1723667769813,"mc":[{"id":"1.231737525","rc":[{"batb":[[0,2.34,10],[1,2.32,31.11],[2,1.1,25000]],"ltp":2.32,"tv":1.79,"id":26354922}]}]}
{"op":"mcm","clk":"11839890990","pt":1723667773125,"mc":[{"id":"1.231737525","rc":[{"batb":[[0,2.32,31.11],[1,1.1,25000],[2,1.09,25000]],"ltp":2.32,"tv":1.79,"id":26354922}]}]}
{"op":"mcm","clk":"11839891198","pt":1723667775432,"mc":[{"id":"1.231737525","rc":[{"batb":[[0,2.34,10],[1,2.32,31.11],[2,1.1,25000]],"ltp":2.32,"tv":1.79,"id":26354922}]}]}
{"op":"mcm","clk":"11839891462","pt":1723667778733,"mc":[{"id":"1.231737525","rc":[{"batb":[[0,2.32,31.11],[1,1.1,25000],[2,1.09,25000]],"ltp":2.32,"tv":1.79,"id":26354922}]}]}
{"op":"mcm","clk":"11839891682","pt":1723667781151,"mc":[{"id":"1.231737525","rc":[{"batb":[[0,2.34,10],[1,2.32,31.11],[2,1.1,25000]],"ltp":2.32,"tv":1.79,"id":26354922}]}]}
{"op":"mcm","clk":"11839891960","pt":1723667784448,"mc":[{"id":"1.231737525","rc":[{"batb":[[0,2.32,31.11],[1,1.1,25000],[2,1.09,25000]],"ltp":2.32,"tv":1.79,"id":26354922}]}]}
{"op":"mcm","clk":"11839892165","pt":1723667786862,"mc":[{"id":"1.231737525","rc":[{"batb":[[0,2.34,10],[1,2.32,31.11],[2,1.1,25000]],"ltp":2.32,"tv":1.79,"id":26354922}]}]}
{"op":"mcm","clk":"11839892433","pt":1723667790251,"mc":[{"id":"1.231737525","rc":[{"batb":[[0,2.32,31.11],[1,1.1,25000],[2,1.09,25000]],"ltp":2.32,"tv":1.79,"id":26354922}]}]}
{"op":"mcm","clk":"11839892696","pt":1723667793248,"mc":[{"id":"1.231737525","rc":[{"batb":[[0,2.34,10],[1,2.32,31.11],[2,1.1,25000]],"ltp":2.32,"tv":1.79,"id":26354922}]}]}
{"op":"mcm","clk":"11839892947","pt":1723667796487,"mc":[{"id":"1.231737525","rc":[{"batb":[[0,2.32,31.11],[1,1.1,25000],[2,1.09,25000]],"ltp":2.32,"tv":1.79,"id":26354922}]}]}
{"op":"mcm","clk":"11839893141","pt":1723667798779,"mc":[{"id":"1.231737525","rc":[{"batb":[[0,2.34,10],[1,2.32,31.11],[2,1.1,25000]],"ltp":2.32,"tv":1.79,"id":26354922}]}]}
{"op":"mcm","clk":"11839893374","pt":1723667801663,"mc":[{"id":"1.231737525","rc":[{"batb":[[0,2.46,11.92],[1,2.34,10],[2,2.32,31.11]],"batl":[[0,2.48,17.17],[1,2.5,3],[2,2.52,3]],"ltp":2.32,"tv":1.79,"id":26354922}]}]}
{"op":"mcm","clk":"11839893408","pt":1723667802070,"mc":[{"id":"1.231737525","rc":[{"batb":[[1,2.32,31.11],[2,1.1,25000]],"ltp":2.32,"tv":1.79,"id":26354922}]}]}
{"op":"mcm","clk":"11839893603","pt":1723667804588,"mc":[{"id":"1.231737525","rc":[{"batb":[[1,1.1,25000],[2,1.09,25000]],"ltp":2.32,"tv":1.79,"id":26354922},{"batb":[[2,1.65,696.22]],"ltp":1.69,"tv":1310.65,"id":26354921}]}]}
{"op":"mcm","clk":"11839921188","pt":1723668128504,"mc":[{"id":"1.231737525","rc":[{"batb":[[0,1.67,900]],"ltp":1.69,"tv":1310.65,"id":26354921}]}]}
{"op":"mcm","clk":"11839922131","pt":1723668142772,"mc":[{"id":"1.231737525","rc":[{"batl":[[2,1.71,8]],"ltp":1.69,"tv":1310.65,"id":26354921}]}]}
{"op":"mcm","clk":"11839922201","pt":1723668143648,"mc":[{"id":"1.231737525","rc":[{"batl":[[2,1.7,8]],"ltp":1.69,"tv":1310.65,"id":26354921}]}]}
{"op":"mcm","clk":"11839922308","pt":1723668144940,"mc":[{"id":"1.231737525","rc":[{"trd":[[1.68,518.15]],"batb":[[0,1.68,11.65],[1,1.67,900],[2,1.66,800]],"batl":[[0,1.69,4089.4],[1,1.7,8],[2,1.71,8]],"ltp":1.68,"tv":1327.34,"id":26354921}],"tv":1329.13}]}
{"op":"mcm","clk":"11839922317","pt":1723668145030,"mc":[{"id":"1.231737525","rc":[{"batb":[[0,1.68,21.65]],"ltp":1.68,"tv":1327.34,"id":26354921}]}]}
{"op":"mcm","clk":"11839922524","pt":1723668147860,"mc":[{"id":"1.231737525","rc":[{"batb":[[0,1.68,31.65]],"ltp":1.68,"tv":1327.34,"id":26354921}]}]}
{"op":"mcm","clk":"11839922662","pt":1723668149961,"mc":[{"id":"1.231737525","rc":[{"batb":[[0,1.1,25000],[1,1.09,25000],[2,1.08,25000]],"ltp":2.32,"tv":1.79,"id":26354922}]}]}
{"op":"mcm","clk":"11839922720","pt":1723668150640,"mc":[{"id":"1.231737525","rc":[{"batb":[[0,2.32,31.11],[1,1.11,10],[2,1.1,25000]],"ltp":2.32,"tv":1.79,"id":26354922},{"batb":[[0,1.68,41.65]],"ltp":1.68,"tv":1327.34,"id":26354921}]}]}
{"op":"mcm","clk":"11839922905","pt":1723668153353,"mc":[{"id":"1.231737525","rc":[{"batb":[[1,1.1,25000],[2,1.09,25000]],"ltp":2.32,"tv":1.79,"id":26354922}]}]}
{"op":"mcm","clk":"11839923099","pt":1723668156433,"mc":[{"id":"1.231737525","rc":[{"batb":[[0,2.34,10],[1,2.32,31.11],[2,1.1,25000]],"ltp":2.32,"tv":1.79,"id":26354922}]}]}
{"op":"mcm","clk":"11839923372","pt":1723668159756,"mc":[{"id":"1.231737525","rc":[{"batb":[[0,2.32,31.11],[1,1.1,25000],[2,1.09,25000]],"ltp":2.32,"tv":1.79,"id":26354922}]}]}
{"op":"mcm","clk":"11839923548","pt":1723668162172,"mc":[{"id":"1.231737525","rc":[{"batb":[[0,2.34,10],[1,2.32,31.11],[2,1.1,25000]],"ltp":2.32,"tv":1.79,"id":26354922}]}]}
{"op":"mcm","clk":"11839923811","pt":1723668165460,"mc":[{"id":"1.231737525","rc":[{"batb":[[0,2.32,31.11],[1,1.1,25000],[2,1.09,25000]],"ltp":2.32,"tv":1.79,"id":26354922}]}]}
{"op":"mcm","clk":"11839923992","pt":1723668167773,"mc":[{"id":"1.231737525","rc":[{"batb":[[0,2.34,10],[1,2.32,31.11],[2,1.1,25000]],"ltp":2.32,"tv":1.79,"id":26354922}]}]}
{"op":"mcm","clk":"11839924228","pt":1723668171056,"mc":[{"id":"1.231737525","rc":[{"batb":[[0,2.32,31.11],[1,1.1,25000],[2,1.09,25000]],"ltp":2.32,"tv":1.79,"id":26354922}]}]}
{"op":"mcm","clk":"11839924450","pt":1723668173860,"mc":[{"id":"1.231737525","rc":[{"batb":[[0,2.34,10],[1,2.32,31.11],[2,1.1,25000]],"ltp":2.32,"tv":1.79,"id":26354922}]}]}
{"op":"mcm","clk":"11839933825","pt":1723668177268,"mc":[{"id":"1.231737525","rc":[{"batb":[[0,2.32,31.11],[1,1.1,25000],[2,1.09,25000]],"ltp":2.32,"tv":1.79,"id":26354922}]}]}
{"op":"mcm","clk":"11839934033","pt":1723668179685,"mc":[{"id":"1.231737525","rc":[{"batb":[[0,2.34,10],[1,2.32,31.11],[2,1.1,25000]],"ltp":2.32,"tv":1.79,"id":26354922}]}]}
{"op":"mcm","clk":"11839934320","pt":1723668182984,"mc":[{"id":"1.231737525","rc":[{"batb":[[0,2.32,31.11],[1,1.1,25000],[2,1.09,25000]],"ltp":2.32,"tv":1.79,"id":26354922}]}]}
{"op":"mcm","clk":"11839934531","pt":1723668185398,"mc":[{"id":"1.231737525","rc":[{"batb":[[0,2.34,10],[1,2.32,31.11],[2,1.1,25000]],"ltp":2.32,"tv":1.79,"id":26354922}]}]}
{"op":"mcm","clk":"11839934802","pt":1723668188671,"mc":[{"id":"1.231737525","rc":[{"batb":[[0,2.32,31.11],[1,1.1,25000],[2,1.09,25000]],"ltp":2.32,"tv":1.79,"id":26354922}]}]}
{"op":"mcm","clk":"11839935032","pt":1723668191201,"mc":[{"id":"1.231737525","rc":[{"batb":[[0,2.34,10],[1,2.32,31.11],[2,1.1,25000]],"ltp":2.32,"tv":1.79,"id":26354922}]}]}
{"op":"mcm","clk":"11839935310","pt":1723668194487,"mc":[{"id":"1.231737525","rc":[{"batb":[[0,2.32,31.11],[1,1.1,25000],[2,1.09,25000]],"ltp":2.32,"tv":1.79,"id":26354922}]}]}
{"op":"mcm","clk":"11839935496","pt":1723668196899,"mc":[{"id":"1.231737525","rc":[{"batb":[[0,2.34,10],[1,2.32,31.11],[2,1.1,25000]],"ltp":2.32,"tv":1.79,"id":26354922}]}]}
{"op":"mcm","clk":"11839935809","pt":1723668200196,"mc":[{"id":"1.231737525","rc":[{"batb":[[0,2.32,31.11],[1,1.1,25000],[2,1.09,25000]],"ltp":2.32,"tv":1.79,"id":26354922}]}]}
{"op":"mcm","clk":"11839936089","pt":1723668202635,"mc":[{"id":"1.231737525","rc":[{"batb":[[0,2.34,10],[1,2.32,31.11],[2,1.1,25000]],"ltp":2.32,"tv":1.79,"id":26354922}]}]}
{"op":"mcm","clk":"11839936358","pt":1723668205909,"mc":[{"id":"1.231737525","rc":[{"batb":[[0,2.32,31.11],[1,1.1,25000],[2,1.09,25000]],"ltp":2.32,"tv":1.79,"id":26354922}]}]}
{"op":"mcm","clk":"11839936554","pt":1723668208284,"mc":[{"id":"1.231737525","rc":[{"batb":[[0,2.34,10],[1,2.32,31.11],[2,1.1,25000]],"ltp":2.32,"tv":1.79,"id":26354922}]}]}
{"op":"mcm","clk":"11839936897","pt":1723668211593,"mc":[{"id":"1.231737525","rc":[{"batb":[[0,2.32,31.11],[1,1.1,25000],[2,1.09,25000]],"ltp":2.32,"tv":1.79,"id":26354922}]}]}
{"op":"mcm","clk":"11839937087","pt":1723668213903,"mc":[{"id":"1.231737525","rc":[{"batb":[[0,2.34,10],[1,2.32,31.11],[2,1.1,25000]],"ltp":2.32,"tv":1.79,"id":26354922}]}]}
{"op":"mcm","clk":"11839937419","pt":1723668217196,"mc":[{"id":"1.231737525","rc":[{"batb":[[0,2.32,31.11],[1,1.1,25000],[2,1.09,25000]],"ltp":2.32,"tv":1.79,"id":26354922}]}]}
{"op":"mcm","clk":"11839937650","pt":1723668219712,"mc":[{"id":"1.231737525","rc":[{"batb":[[0,2.34,10],[1,2.32,31.11],[2,1.1,25000]],"ltp":2.32,"tv":1.79,"id":26354922}]}]}
{"op":"mcm","clk":"11839937918","pt":1723668223115,"mc":[{"id":"1.231737525","rc":[{"batb":[[0,2.32,31.11],[1,1.1,25000],[2,1.09,25000]],"ltp":2.32,"tv":1.79,"id":26354922}]}]}
{"op":"mcm","clk":"11839938094","pt":1723668225515,"mc":[{"id":"1.231737525","rc":[{"batb":[[0,2.34,10],[1,2.32,31.11],[2,1.1,25000]],"ltp":2.32,"tv":1.79,"id":26354922}]}]}
{"op":"mcm","clk":"11839938327","pt":1723668228714,"mc":[{"id":"1.231737525","rc":[{"batb":[[0,2.32,31.11],[1,1.1,25000],[2,1.09,25000]],"ltp":2.32,"tv":1.79,"id":26354922}]}]}
{"op":"mcm","clk":"11839938507","pt":1723668231229,"mc":[{"id":"1.231737525","rc":[{"batb":[[0,2.34,10],[1,2.32,31.11],[2,1.1,25000]],"ltp":2.32,"tv":1.79,"id":26354922}]}]}
{"op":"mcm","clk":"11839938779","pt":1723668234422,"mc":[{"id":"1.231737525","rc":[{"batb":[[0,2.32,31.11],[1,1.1,25000],[2,1.09,25000]],"ltp":2.32,"tv":1.79,"id":26354922}]}]}
{"op":"mcm","clk":"11839938984","pt":1723668236839,"mc":[{"id":"1.231737525","rc":[{"batb":[[0,2.34,10],[1,2.32,31.11],[2,1.1,25000]],"ltp":2.32,"tv":1.79,"id":26354922}]}]}
{"op":"mcm","clk":"11839939247","pt":1723668240129,"mc":[{"id":"1.231737525","rc":[{"batb":[[0,2.32,31.11],[1,1.1,25000],[2,1.09,25000]],"ltp":2.32,"tv":1.79,"id":26354922}]}]}
{"op":"mcm","clk":"11839939416","pt":1723668242548,"mc":[{"id":"1.231737525","rc":[{"batb":[[0,2.34,10],[1,2.32,31.11],[2,1.1,25000]],"ltp":2.32,"tv":1.79,"id":26354922}]}]}
{"op":"mcm","clk":"11839939646","pt":1723668245834,"mc":[{"id":"1.231737525","rc":[{"batb":[[0,2.32,31.11],[1,1.1,25000],[2,1.09,25000]],"ltp":2.32,"tv":1.79,"id":26354922}]}]}
{"op":"mcm","clk":"11839939857","pt":1723668248721,"mc":[{"id":"1.231737525","rc":[{"batb":[[0,2.34,10],[1,2.32,31.11],[2,1.1,25000]],"ltp":2.32,"tv":1.79,"id":26354922}]}]}
{"op":"mcm","clk":"11839940113","pt":1723668252319,"mc":[{"id":"1.231737525","rc":[{"batb":[[0,2.32,31.11],[1,1.1,25000],[2,1.09,25000]],"ltp":2.32,"tv":1.79,"id":26354922}]}]}
{"op":"mcm","clk":"11839940283","pt":1723668254524,"mc":[{"id":"1.231737525","rc":[{"batb":[[0,2.34,10],[1,2.32,31.11],[2,1.1,25000]],"ltp":2.32,"tv":1.79,"id":26354922}]}]}
{"op":"mcm","clk":"11839940538","pt":1723668257963,"mc":[{"id":"1.231737525","rc":[{"batb":[[0,2.32,31.11],[1,1.1,25000],[2,1.09,25000]],"ltp":2.32,"tv":1.79,"id":26354922}]}]}
{"op":"mcm","clk":"11839940692","pt":1723668260275,"mc":[{"id":"1.231737525","rc":[{"batb":[[0,2.34,10],[1,2.32,31.11],[2,1.1,25000]],"ltp":2.32,"tv":1.79,"id":26354922}]}]}
{"op":"mcm","clk":"11839940964","pt":1723668263564,"mc":[{"id":"1.231737525","rc":[{"batb":[[0,2.32,31.11],[1,1.1,25000],[2,1.09,25000]],"ltp":2.32,"tv":1.79,"id":26354922}]}]}
{"op":"mcm","clk":"11839941161","pt":1723668265879,"mc":[{"id":"1.231737525","rc":[{"batb":[[0,2.34,10],[1,2.32,31.11],[2,1.1,25000]],"ltp":2.32,"tv":1.79,"id":26354922}]}]}
{"op":"mcm","clk":"11839941409","pt":1723668269176,"mc":[{"id":"1.231737525","rc":[{"batb":[[0,2.32,31.11],[1,1.1,25000],[2,1.09,25000]],"ltp":2.32,"tv":1.79,"id":26354922}]}]}
{"op":"mcm","clk":"11839941629","pt":1723668271545,"mc":[{"id":"1.231737525","rc":[{"batb":[[0,2.34,10],[1,2.32,31.11],[2,1.1,25000]],"ltp":2.32,"tv":1.79,"id":26354922}]}]}
{"op":"mcm","clk":"11839941891","pt":1723668274883,"mc":[{"id":"1.231737525","rc":[{"batb":[[0,2.32,31.11],[1,1.1,25000],[2,1.09,25000]],"ltp":2.32,"tv":1.79,"id":26354922}]}]}
{"op":"mcm","clk":"11839942083","pt":1723668277262,"mc":[{"id":"1.231737525","rc":[{"batb":[[0,2.34,10],[1,2.32,31.11],[2,1.1,25000]],"ltp":2.32,"tv":1.79,"id":26354922}]}]}
{"op":"mcm","clk":"11839942419","pt":1723668280658,"mc":[{"id":"1.231737525","rc":[{"batb":[[0,2.32,31.11],[1,1.1,25000],[2,1.09,25000]],"ltp":2.32,"tv":1.79,"id":26354922}]}]}
{"op":"mcm","clk":"11839942604","pt":1723668282874,"mc":[{"id":"1.231737525","rc":[{"batb":[[0,2.34,10],[1,2.32,31.11],[2,1.1,25000]],"ltp":2.32,"tv":1.79,"id":26354922}]}]}
{"op":"mcm","clk":"11839942876","pt":1723668286369,"mc":[{"id":"1.231737525","rc":[{"batb":[[0,2.32,31.11],[1,1.1,25000],[2,1.09,25000]],"ltp":2.32,"tv":1.79,"id":26354922}]}]}
{"op":"mcm","clk":"11839943116","pt":1723668289406,"mc":[{"id":"1.231737525","rc":[{"batb":[[0,2.34,10],[1,2.32,31.11],[2,1.1,25000]],"ltp":2.32,"tv":1.79,"id":26354922}]}]}
{"op":"mcm","clk":"11839943366","pt":1723668292601,"mc":[{"id":"1.231737525","rc":[{"batb":[[0,2.32,31.11],[1,1.1,25000],[2,1.09,25000]],"ltp":2.32,"tv":1.79,"id":26354922}]}]}
{"op":"mcm","clk":"11839943551","pt":1723668295068,"mc":[{"id":"1.231737525","rc":[{"batb":[[0,2.34,10],[1,2.32,31.11],[2,1.1,25000]],"ltp":2.32,"tv":1.79,"id":26354922}]}]}
{"op":"mcm","clk":"11839943804","pt":1723668298408,"mc":[{"id":"1.231737525","rc":[{"batb":[[0,2.32,31.11],[1,1.1,25000],[2,1.09,25000]],"ltp":2.32,"tv":1.79,"id":26354922}]}]}
{"op":"mcm","clk":"11839944036","pt":1723668300893,"mc":[{"id":"1.231737525","rc":[{"batb":[[0,2.34,10],[1,2.32,31.11],[2,1.1,25000]],"ltp":2.32,"tv":1.79,"id":26354922}]}]}
{"op":"mcm","clk":"11839944333","pt":1723668304295,"mc":[{"id":"1.231737525","rc":[{"batb":[[0,2.32,31.11],[1,1.1,25000],[2,1.09,25000]],"ltp":2.32,"tv":1.79,"id":26354922}]}]}
{"op":"mcm","clk":"11839944616","pt":1723668307618,"mc":[{"id":"1.231737525","rc":[{"batb":[[0,2.34,10],[1,2.32,31.11],[2,1.1,25000]],"ltp":2.32,"tv":1.79,"id":26354922}]}]}
{"op":"mcm","clk":"11839944888","pt":1723668311017,"mc":[{"id":"1.231737525","rc":[{"batb":[[0,2.32,31.11],[1,1.1,25000],[2,1.09,25000]],"ltp":2.32,"tv":1.79,"id":26354922}]}]}
{"op":"mcm","clk":"11839945118","pt":1723668313610,"mc":[{"id":"1.231737525","rc":[{"batb":[[0,2.34,10],[1,2.32,31.11],[2,1.1,25000]],"ltp":2.32,"tv":1.79,"id":26354922}]}]}
{"op":"mcm","clk":"11839945370","pt":1723668316911,"mc":[{"id":"1.231737525","rc":[{"batb":[[0,2.32,31.11],[1,1.1,25000],[2,1.09,25000]],"ltp":2.32,"tv":1.79,"id":26354922}]}]}
{"op":"mcm","clk":"11839945570","pt":1723668319299,"mc":[{"id":"1.231737525","rc":[{"batb":[[0,2.34,10],[1,2.32,31.11],[2,1.1,25000]],"ltp":2.32,"tv":1.79,"id":26354922}]}]}
{"op":"mcm","clk":"11839945845","pt":1723668322706,"mc":[{"id":"1.231737525","rc":[{"batb":[[0,2.32,31.11],[1,1.1,25000],[2,1.09,25000]],"ltp":2.32,"tv":1.79,"id":26354922}]}]}
{"op":"mcm","clk":"11839946042","pt":1723668325015,"mc":[{"id":"1.231737525","rc":[{"batb":[[0,2.34,10],[1,2.32,31.11],[2,1.1,25000]],"ltp":2.32,"tv":1.79,"id":26354922}]}]}
{"op":"mcm","clk":"11839946338","pt":1723668328418,"mc":[{"id":"1.231737525","rc":[{"batb":[[0,2.32,31.11],[1,1.1,25000],[2,1.09,25000]],"ltp":2.32,"tv":1.79,"id":26354922}]}]}
{"op":"mcm","clk":"11839946517","pt":1723668330732,"mc":[{"id":"1.231737525","rc":[{"batb":[[0,2.34,10],[1,2.32,31.11],[2,1.1,25000]],"ltp":2.32,"tv":1.79,"id":26354922}]}]}
{"op":"mcm","clk":"11839946782","pt":1723668334028,"mc":[{"id":"1.231737525","rc":[{"batb":[[0,2.32,31.11],[1,1.1,25000],[2,1.09,25000]],"ltp":2.32,"tv":1.79,"id":26354922}]}]}
{"op":"mcm","clk":"11839946971","pt":1723668336322,"mc":[{"id":"1.231737525","rc":[{"batb":[[0,2.34,10],[1,2.32,31.11],[2,1.1,25000]],"ltp":2.32,"tv":1.79,"id":26354922}]}]}
{"op":"mcm","clk":"11839947254","pt":1723668339720,"mc":[{"id":"1.231737525","rc":[{"batb":[[0,2.32,31.11],[1,1.1,25000],[2,1.09,25000]],"ltp":2.32,"tv":1.79,"id":26354922}]}]}
{"op":"mcm","clk":"11839947436","pt":1723668342114,"mc":[{"id":"1.231737525","rc":[{"batb":[[0,2.34,10],[1,2.32,31.11],[2,1.1,25000]],"ltp":2.32,"tv":1.79,"id":26354922}]}]}
{"op":"mcm","clk":"11839947693","pt":1723668345547,"mc":[{"id":"1.231737525","rc":[{"batb":[[0,2.32,31.11],[1,1.1,25000],[2,1.09,25000]],"ltp":2.32,"tv":1.79,"id":26354922}]}]}
{"op":"mcm","clk":"11839947845","pt":1723668347817,"mc":[{"id":"1.231737525","rc":[{"batb":[[0,2.34,10],[1,2.32,31.11],[2,1.1,25000]],"ltp":2.32,"tv":1.79,"id":26354922}]}]}
{"op":"mcm","clk":"11839948102","pt":1723668351306,"mc":[{"id":"1.231737525","rc":[{"batb":[[0,2.32,31.11],[1,1.1,25000],[2,1.09,25000]],"ltp":2.32,"tv":1.79,"id":26354922}]}]}
{"op":"mcm","clk":"11839948296","pt":1723668353832,"mc":[{"id":"1.231737525","rc":[{"batb":[[0,2.34,10],[1,2.32,31.11],[2,1.1,25000]],"ltp":2.32,"tv":1.79,"id":26354922}]}]}
{"op":"mcm","clk":"11839948554","pt":1723668357336,"mc":[{"id":"1.231737525","rc":[{"batb":[[0,2.32,31.11],[1,1.1,25000],[2,1.09,25000]],"ltp":2.32,"tv":1.79,"id":26354922}]}]}
{"op":"mcm","clk":"11839948794","pt":1723668360621,"mc":[{"id":"1.231737525","rc":[{"batb":[[0,2.34,10],[1,2.32,31.11],[2,1.1,25000]],"ltp":2.32,"tv":1.79,"id":26354922}]}]}
{"op":"mcm","clk":"11839949072","pt":1723668364061,"mc":[{"id":"1.231737525","rc":[{"batb":[[0,2.32,31.11],[1,1.1,25000],[2,1.09,25000]],"ltp":2.32,"tv":1.79,"id":26354922}]}]}
{"op":"mcm","clk":"11839949296","pt":1723668367050,"mc":[{"id":"1.231737525","rc":[{"batb":[[0,2.34,10],[1,2.32,31.11],[2,1.1,25000]],"ltp":2.32,"tv":1.79,"id":26354922}]}]}
{"op":"mcm","clk":"11839949577","pt":1723668370656,"mc":[{"id":"1.231737525","rc":[{"batb":[[0,2.32,31.11],[1,1.1,25000],[2,1.09,25000]],"ltp":2.32,"tv":1.79,"id":26354922}]}]}
{"op":"mcm","clk":"11839949758","pt":1723668372984,"mc":[{"id":"1.231737525","rc":[{"batb":[[0,2.34,10],[1,2.32,31.11],[2,1.1,25000]],"ltp":2.32,"tv":1.79,"id":26354922}]}]}
{"op":"mcm","clk":"11839950019","pt":1723668376455,"mc":[{"id":"1.231737525","rc":[{"batb":[[0,2.32,31.11],[1,1.1,25000],[2,1.09,25000]],"ltp":2.32,"tv":1.79,"id":26354922}]}]}
{"op":"mcm","clk":"11839950168","pt":1723668378670,"mc":[{"id":"1.231737525","rc":[{"batb":[[0,2.34,10],[1,2.32,31.11],[2,1.1,25000]],"ltp":2.32,"tv":1.79,"id":26354922}]}]}
{"op":"mcm","clk":"11839950448","pt":1723668382060,"mc":[{"id":"1.231737525","rc":[{"batb":[[0,2.32,31.11],[1,1.1,25000],[2,1.09,25000]],"ltp":2.32,"tv":1.79,"id":26354922}]}]}
{"op":"mcm","clk":"11839950638","pt":1723668384468,"mc":[{"id":"1.231737525","rc":[{"batb":[[0,2.34,10],[1,2.32,31.11],[2,1.1,25000]],"ltp":2.32,"tv":1.79,"id":26354922}]}]}
{"op":"mcm","clk":"11839950875","pt":1723668387855,"mc":[{"id":"1.231737525","rc":[{"batb":[[0,2.32,31.11],[1,1.1,25000],[2,1.09,25000]],"ltp":2.32,"tv":1.79,"id":26354922}]}]}
{"op":"mcm","clk":"11839951014","pt":1723668390063,"mc":[{"id":"1.231737525","rc":[{"batb":[[0,2.34,10],[1,2.32,31.11],[2,1.1,25000]],"ltp":2.32,"tv":1.79,"id":26354922}]}]}
{"op":"mcm","clk":"11839951281","pt":1723668393548,"mc":[{"id":"1.231737525","rc":[{"batb":[[0,2.32,31.11],[1,1.1,25000],[2,1.09,25000]],"ltp":2.32,"tv":1.79,"id":26354922}]}]}
{"op":"mcm","clk":"11839951442","pt":1723668396070,"mc":[{"id":"1.231737525","rc":[{"batb":[[0,2.34,10],[1,2.32,31.11],[2,1.1,25000]],"ltp":2.32,"tv":1.79,"id":26354922}]}]}
{"op":"mcm","clk":"11839951702","pt":1723668399397,"mc":[{"id":"1.231737525","rc":[{"batb":[[0,2.32,31.11],[1,1.1,25000],[2,1.09,25000]],"ltp":2.32,"tv":1.79,"id":26354922}]}]}
{"op":"mcm","clk":"11839951885","pt":1723668401669,"mc":[{"id":"1.231737525","rc":[{"batb":[[0,2.34,10],[1,2.32,31.11],[2,1.1,25000]],"ltp":2.32,"tv":1.79,"id":26354922}]}]}
{"op":"mcm","clk":"11839952133","pt":1723668405214,"mc":[{"id":"1.231737525","rc":[{"batb":[[0,2.32,31.11],[1,1.1,25000],[2,1.09,25000]],"ltp":2.32,"tv":1.79,"id":26354922}]}]}
{"op":"mcm","clk":"11839952292","pt":1723668407412,"mc":[{"id":"1.231737525","rc":[{"batb":[[0,2.34,10],[1,2.32,31.11],[2,1.1,25000]],"ltp":2.32,"tv":1.79,"id":26354922}]}]}
{"op":"mcm","clk":"11839952527","pt":1723668410803,"mc":[{"id":"1.231737525","rc":[{"batb":[[0,2.32,31.11],[1,1.1,25000],[2,1.09,25000]],"ltp":2.32,"tv":1.79,"id":26354922}]}]}
{"op":"mcm","clk":"11839952641","pt":1723668412905,"mc":[{"id":"1.231737525","rc":[{"batb":[[0,2.34,10],[1,2.32,31.11],[2,1.1,25000]],"ltp":2.32,"tv":1.79,"id":26354922}]}]}
{"op":"mcm","clk":"11839952893","pt":1723668416398,"mc":[{"id":"1.231737525","rc":[{"batb":[[0,2.32,31.11],[1,1.1,25000],[2,1.09,25000]],"ltp":2.32,"tv":1.79,"id":26354922}]}]}
{"op":"mcm","clk":"11839953061","pt":1723668418812,"mc":[{"id":"1.231737525","rc":[{"batb":[[0,2.34,10],[1,2.32,31.11],[2,1.1,25000]],"ltp":2.32,"tv":1.79,"id":26354922}]}]}
{"op":"mcm","clk":"11839953319","pt":1723668422205,"mc":[{"id":"1.231737525","rc":[{"batb":[[0,2.32,31.11],[1,1.1,25000],[2,1.09,25000]],"ltp":2.32,"tv":1.79,"id":26354922}]}]}
{"op":"mcm","clk":"11839953510","pt":1723668424716,"mc":[{"id":"1.231737525","rc":[{"batb":[[0,2.34,10],[1,2.32,31.11],[2,1.1,25000]],"ltp":2.32,"tv":1.79,"id":26354922}]}]}
{"op":"mcm","clk":"11839953759","pt":1723668428103,"mc":[{"id":"1.231737525","rc":[{"batb":[[0,2.32,31.11],[1,1.1,25000],[2,1.09,25000]],"ltp":2.32,"tv":1.79,"id":26354922}]}]}
{"op":"mcm","clk":"11839953926","pt":1723668430411,"mc":[{"id":"1.231737525","rc":[{"batb":[[0,2.34,10],[1,2.32,31.11],[2,1.1,25000]],"ltp":2.32,"tv":1.79,"id":26354922}]}]}
{"op":"mcm","clk":"11839954163","pt":1723668433846,"mc":[{"id":"1.231737525","rc":[{"batb":[[0,2.32,31.11],[1,1.1,25000],[2,1.09,25000]],"ltp":2.32,"tv":1.79,"id":26354922}]}]}
{"op":"mcm","clk":"11839954307","pt":1723668435849,"mc":[{"id":"1.231737525","rc":[{"batb":[[0,1.68,51.65]],"ltp":1.68,"tv":1327.34,"id":26354921}]}]}
{"op":"mcm","clk":"11839954322","pt":1723668436056,"mc":[{"id":"1.231737525","rc":[{"batb":[[0,2.34,10],[1,2.32,31.11],[2,1.1,25000]],"ltp":2.32,"tv":1.79,"id":26354922}]}]}
{"op":"mcm","clk":"11839954541","pt":1723668439439,"mc":[{"id":"1.231737525","rc":[{"batb":[[0,2.32,31.11],[1,1.1,25000],[2,1.09,25000]],"ltp":2.32,"tv":1.79,"id":26354922}]}]}
{"op":"mcm","clk":"11839954652","pt":1723668440930,"mc":[{"id":"1.231737525","rc":[{"batb":[[0,1.68,52.65]],"ltp":1.68,"tv":1327.34,"id":26354921}]}]}
{"op":"mcm","clk":"11839954712","pt":1723668441750,"mc":[{"id":"1.231737525","rc":[{"batb":[[0,2.34,10],[1,2.32,31.11],[2,1.1,25000]],"ltp":2.32,"tv":1.79,"id":26354922},{"batb":[[0,1.68,55.65]],"ltp":1.68,"tv":1327.34,"id":26354921}]}]}
{"op":"mcm","clk":"11839954775","pt":1723668442731,"mc":[{"id":"1.231737525","rc":[{"batb":[[0,1.68,58.65]],"ltp":1.68,"tv":1327.34,"id":26354921}]}]}
{"op":"mcm","clk":"11839954824","pt":1723668443339,"mc":[{"id":"1.231737525","rc":[{"batb":[[0,1.68,59.65]],"ltp":1.68,"tv":1327.34,"id":26354921}]}]}
{"op":"mcm","clk":"11839954918","pt":1723668444530,"mc":[{"id":"1.231737525","rc":[{"batb":[[0,1.68,60.65]],"ltp":1.68,"tv":1327.34,"id":26354921}]}]}
{"op":"mcm","clk":"11839955014","pt":1723668445860,"mc":[{"id":"1.231737525","rc":[{"batb":[[0,2.32,31.11],[1,1.1,25000],[2,1.09,25000]],"ltp":2.32,"tv":1.79,"id":26354922}]}]}
{"op":"mcm","clk":"11839955221","pt":1723668448949,"mc":[{"id":"1.231737525","rc":[{"batb":[[0,2.34,10],[1,2.32,31.11],[2,1.1,25000]],"ltp":2.32,"tv":1.79,"id":26354922}]}]}
{"op":"mcm","clk":"11839955454","pt":1723668452336,"mc":[{"id":"1.231737525","rc":[{"batb":[[0,2.32,31.11],[1,1.1,25000],[2,1.09,25000]],"ltp":2.32,"tv":1.79,"id":26354922}]}]}
{"op":"mcm","clk":"11839955640","pt":1723668454646,"mc":[{"id":"1.231737525","rc":[{"batb":[[0,2.34,10],[1,2.32,31.11],[2,1.1,25000]],"ltp":2.32,"tv":1.79,"id":26354922}]}]}
{"op":"mcm","clk":"11839955897","pt":1723668458185,"mc":[{"id":"1.231737525","rc":[{"batb":[[0,2.32,31.11],[1,1.1,25000],[2,1.09,25000]],"ltp":2.32,"tv":1.79,"id":26354922}]}]}
{"op":"mcm","clk":"11839956147","pt":1723668461470,"mc":[{"id":"1.231737525","rc":[{"batb":[[0,2.34,10],[1,2.32,31.11],[2,1.1,25000]],"ltp":2.32,"tv":1.79,"id":26354922}]}]}
{"op":"mcm","clk":"11839956366","pt":1723668464760,"mc":[{"id":"1.231737525","rc":[{"batb":[[0,2.32,31.11],[1,1.1,25000],[2,1.09,25000]],"ltp":2.32,"tv":1.79,"id":26354922}]}]}
{"op":"mcm","clk":"11839956538","pt":1723668467178,"mc":[{"id":"1.231737525","rc":[{"batb":[[0,2.34,10],[1,2.32,31.11],[2,1.1,25000]],"ltp":2.32,"tv":1.79,"id":26354922}]}]}
{"op":"mcm","clk":"11839956775","pt":1723668470576,"mc":[{"id":"1.231737525","rc":[{"batb":[[0,2.32,31.11],[1,1.1,25000],[2,1.09,25000]],"ltp":2.32,"tv":1.79,"id":26354922}]}]}
{"op":"mcm","clk":"11839957071","pt":1723668474277,"mc":[{"id":"1.231737525","rc":[{"batb":[[0,2.34,10],[1,2.32,31.11],[2,1.1,25000]],"ltp":2.32,"tv":1.79,"id":26354922}]}]}
{"op":"mcm","clk":"11839957342","pt":1723668477769,"mc":[{"id":"1.231737525","rc":[{"batb":[[0,2.32,31.11],[1,1.1,25000],[2,1.09,25000]],"ltp":2.32,"tv":1.79,"id":26354922}]}]}
{"op":"mcm","clk":"11839957491","pt":1723668480177,"mc":[{"id":"1.231737525","rc":[{"batb":[[0,2.34,10],[1,2.32,31.11],[2,1.1,25000]],"ltp":2.32,"tv":1.79,"id":26354922}]}]}
{"op":"mcm","clk":"11839957743","pt":1723668483512,"mc":[{"id":"1.231737525","rc":[{"batb":[[0,2.32,31.11],[1,1.1,25000],[2,1.09,25000]],"ltp":2.32,"tv":1.79,"id":26354922}]}]}
{"op":"mcm","clk":"11839957937","pt":1723668486179,"mc":[{"id":"1.231737525","rc":[{"batb":[[0,2.34,10],[1,2.32,31.11],[2,1.1,25000]],"ltp":2.32,"tv":1.79,"id":26354922}]}]}
{"op":"mcm","clk":"11839958186","pt":1723668489613,"mc":[{"id":"1.231737525","rc":[{"batb":[[0,2.32,31.11],[1,1.1,25000],[2,1.09,25000]],"ltp":2.32,"tv":1.79,"id":26354922}]}]}
{"op":"mcm","clk":"11839958402","pt":1723668492597,"mc":[{"id":"1.231737525","rc":[{"batb":[[0,2.34,10],[1,2.32,31.11],[2,1.1,25000]],"ltp":2.32,"tv":1.79,"id":26354922}]}]}
{"op":"mcm","clk":"11839958680","pt":1723668496026,"mc":[{"id":"1.231737525","rc":[{"batb":[[0,2.32,31.11],[1,1.1,25000],[2,1.09,25000]],"ltp":2.32,"tv":1.79,"id":26354922}]}]}
{"op":"mcm","clk":"11839958839","pt":1723668498233,"mc":[{"id":"1.231737525","rc":[{"batb":[[0,2.34,10],[1,2.32,31.11],[2,1.1,25000]],"ltp":2.32,"tv":1.79,"id":26354922}]}]}
{"op":"mcm","clk":"11839959076","pt":1723668501622,"mc":[{"id":"1.231737525","rc":[{"batb":[[0,2.32,31.11],[1,1.1,25000],[2,1.09,25000]],"ltp":2.32,"tv":1.79,"id":26354922}]}]}
{"op":"mcm","clk":"11839959240","pt":1723668504034,"mc":[{"id":"1.231737525","rc":[{"batb":[[0,2.34,10],[1,2.32,31.11],[2,1.1,25000]],"ltp":2.32,"tv":1.79,"id":26354922}]}]}
{"op":"mcm","clk":"11839959488","pt":1723668507525,"mc":[{"id":"1.231737525","rc":[{"batb":[[0,2.32,31.11],[1,1.1,25000],[2,1.09,25000]],"ltp":2.32,"tv":1.79,"id":26354922}]}]}
{"op":"mcm","clk":"11839959642","pt":1723668509828,"mc":[{"id":"1.231737525","rc":[{"batb":[[0,2.34,10],[1,2.32,31.11],[2,1.1,25000]],"ltp":2.32,"tv":1.79,"id":26354922}]}]}
{"op":"mcm","clk":"11839959864","pt":1723668513010,"mc":[{"id":"1.231737525","rc":[{"batb":[[0,2.32,31.11],[1,1.1,25000],[2,1.09,25000]],"ltp":2.32,"tv":1.79,"id":26354922}]}]}
{"op":"mcm","clk":"11839960038","pt":1723668515326,"mc":[{"id":"1.231737525","rc":[{"batb":[[0,2.34,10],[1,2.32,31.11],[2,1.1,25000]],"ltp":2.32,"tv":1.79,"id":26354922}]}]}
{"op":"mcm","clk":"11839960262","pt":1723668518758,"mc":[{"id":"1.231737525","rc":[{"batb":[[0,2.32,31.11],[1,1.1,25000],[2,1.09,25000]],"ltp":2.32,"tv":1.79,"id":26354922}]}]}
{"op":"mcm","clk":"11839960400","pt":1723668521026,"mc":[{"id":"1.231737525","rc":[{"batb":[[0,2.34,10],[1,2.32,31.11],[2,1.1,25000]],"ltp":2.32,"tv":1.79,"id":26354922}]}]}
{"op":"mcm","clk":"11839960650","pt":1723668524324,"mc":[{"id":"1.231737525","rc":[{"batb":[[0,2.32,31.11],[1,1.1,25000],[2,1.09,25000]],"ltp":2.32,"tv":1.79,"id":26354922}]}]}
{"op":"mcm","clk":"11839960925","pt":1723668527558,"mc":[{"id":"1.231737525","rc":[{"batb":[[0,2.34,10],[1,2.32,31.11],[2,1.1,25000]],"ltp":2.32,"tv":1.79,"id":26354922}]}]}
{"op":"mcm","clk":"11839961164","pt":1723668530936,"mc":[{"id":"1.231737525","rc":[{"batb":[[0,2.32,31.11],[1,1.1,25000],[2,1.09,25000]],"ltp":2.32,"tv":1.79,"id":26354922}]}]}
{"op":"mcm","clk":"11839961412","pt":1723668534259,"mc":[{"id":"1.231737525","rc":[{"batb":[[0,2.34,10],[1,2.32,31.11],[2,1.1,25000]],"ltp":2.32,"tv":1.79,"id":26354922}]}]}
{"op":"mcm","clk":"11839961643","pt":1723668537642,"mc":[{"id":"1.231737525","rc":[{"batb":[[0,2.32,31.11],[1,1.1,25000],[2,1.09,25000]],"ltp":2.32,"tv":1.79,"id":26354922}]}]}
{"op":"mcm","clk":"11839961830","pt":1723668540054,"mc":[{"id":"1.231737525","rc":[{"batb":[[0,2.34,10],[1,2.32,31.11],[2,1.1,25000]],"ltp":2.32,"tv":1.79,"id":26354922}]}]}
{"op":"mcm","clk":"11839962049","pt":1723668543487,"mc":[{"id":"1.231737525","rc":[{"batb":[[0,2.32,31.11],[1,1.1,25000],[2,1.09,25000]],"ltp":2.32,"tv":1.79,"id":26354922}]}]}
{"op":"mcm","clk":"11839962212","pt":1723668545848,"mc":[{"id":"1.231737525","rc":[{"batb":[[0,2.34,10],[1,2.32,31.11],[2,1.1,25000]],"ltp":2.32,"tv":1.79,"id":26354922}]}]}
{"op":"mcm","clk":"11839962417","pt":1723668549189,"mc":[{"id":"1.231737525","rc":[{"batb":[[0,2.32,31.11],[1,1.1,25000],[2,1.09,25000]],"ltp":2.32,"tv":1.79,"id":26354922}]}]}
{"op":"mcm","clk":"11839962565","pt":1723668551593,"mc":[{"id":"1.231737525","rc":[{"batb":[[0,2.34,10],[1,2.32,31.11],[2,1.1,25000]],"ltp":2.32,"tv":1.79,"id":26354922}]}]}
{"op":"mcm","clk":"11839962856","pt":1723668554993,"mc":[{"id":"1.231737525","rc":[{"batb":[[0,2.32,31.11],[1,1.1,25000],[2,1.09,25000]],"ltp":2.32,"tv":1.79,"id":26354922}]}]}
{"op":"mcm","clk":"11839963050","pt":1723668557294,"mc":[{"id":"1.231737525","rc":[{"batb":[[0,2.34,10],[1,2.32,31.11],[2,1.1,25000]],"ltp":2.32,"tv":1.79,"id":26354922}]}]}
{"op":"mcm","clk":"11839963294","pt":1723668560576,"mc":[{"id":"1.231737525","rc":[{"batb":[[0,2.32,31.11],[1,1.1,25000],[2,1.09,25000]],"ltp":2.32,"tv":1.79,"id":26354922}]}]}
{"op":"mcm","clk":"11839963479","pt":1723668562988,"mc":[{"id":"1.231737525","rc":[{"batb":[[0,2.34,10],[1,2.32,31.11],[2,1.1,25000]],"ltp":2.32,"tv":1.79,"id":26354922}]}]}
{"op":"mcm","clk":"11839963782","pt":1723668566375,"mc":[{"id":"1.231737525","rc":[{"batb":[[0,2.32,31.11],[1,1.1,25000],[2,1.09,25000]],"ltp":2.32,"tv":1.79,"id":26354922}]}]}
{"op":"mcm","clk":"11839963965","pt":1723668568682,"mc":[{"id":"1.231737525","rc":[{"batb":[[0,2.34,10],[1,2.32,31.11],[2,1.1,25000]],"ltp":2.32,"tv":1.79,"id":26354922}]}]}
{"op":"mcm","clk":"11839964198","pt":1723668571971,"mc":[{"id":"1.231737525","rc":[{"batb":[[0,2.32,31.11],[1,1.1,25000],[2,1.09,25000]],"ltp":2.32,"tv":1.79,"id":26354922}]}]}
{"op":"mcm","clk":"11839964368","pt":1723668574273,"mc":[{"id":"1.231737525","rc":[{"batb":[[0,2.34,10],[1,2.32,31.11],[2,1.1,25000]],"ltp":2.32,"tv":1.79,"id":26354922}]}]}
{"op":"mcm","clk":"11839964592","pt":1723668577591,"mc":[{"id":"1.231737525","rc":[{"batb":[[0,2.32,31.11],[1,1.1,25000],[2,1.09,25000]],"ltp":2.32,"tv":1.79,"id":26354922}]}]}
{"op":"mcm","clk":"11839964771","pt":1723668579998,"mc":[{"id":"1.231737525","rc":[{"batb":[[0,2.34,10],[1,2.32,31.11],[2,1.1,25000]],"ltp":2.32,"tv":1.79,"id":26354922}]}]}
{"op":"mcm","clk":"11839965003","pt":1723668583381,"mc":[{"id":"1.231737525","rc":[{"batb":[[0,2.32,31.11],[1,1.1,25000],[2,1.09,25000]],"ltp":2.32,"tv":1.79,"id":26354922}]}]}
{"op":"mcm","clk":"11839965207","pt":1723668586504,"mc":[{"id":"1.231737525","rc":[{"batb":[[0,2.34,10],[1,2.32,31.11],[2,1.1,25000]],"ltp":2.32,"tv":1.79,"id":26354922}]}]}
{"op":"mcm","clk":"11839965430","pt":1723668589907,"mc":[{"id":"1.231737525","rc":[{"batb":[[0,2.32,31.11],[1,1.1,25000],[2,1.09,25000]],"ltp":2.32,"tv":1.79,"id":26354922}]}]}
{"op":"mcm","clk":"11839965601","pt":1723668592219,"mc":[{"id":"1.231737525","rc":[{"batb":[[0,2.34,10],[1,2.32,31.11],[2,1.1,25000]],"ltp":2.32,"tv":1.79,"id":26354922}]}]}
{"op":"mcm","clk":"11839965861","pt":1723668595706,"mc":[{"id":"1.231737525","rc":[{"batb":[[0,2.32,31.11],[1,1.1,25000],[2,1.09,25000]],"ltp":2.32,"tv":1.79,"id":26354922}]}]}
{"op":"mcm","clk":"11839966131","pt":1723668599253,"mc":[{"id":"1.231737525","rc":[{"batb":[[0,2.34,10],[1,2.32,31.11],[2,1.1,25000]],"ltp":2.32,"tv":1.79,"id":26354922}]}]}
{"op":"mcm","clk":"11839966397","pt":1723668602519,"mc":[{"id":"1.231737525","rc":[{"batb":[[0,2.32,31.11],[1,1.1,25000],[2,1.09,25000]],"ltp":2.32,"tv":1.79,"id":26354922}]}]}
{"op":"mcm","clk":"11839966608","pt":1723668605248,"mc":[{"id":"1.231737525","rc":[{"batb":[[0,2.34,10],[1,2.32,31.11],[2,1.1,25000]],"ltp":2.32,"tv":1.79,"id":26354922}]}]}
{"op":"mcm","clk":"11839966899","pt":1723668608631,"mc":[{"id":"1.231737525","rc":[{"batb":[[0,2.32,31.11],[1,1.1,25000],[2,1.09,25000]],"ltp":2.32,"tv":1.79,"id":26354922}]}]}
{"op":"mcm","clk":"11839967115","pt":1723668611141,"mc":[{"id":"1.231737525","rc":[{"batb":[[0,2.34,10],[1,2.32,31.11],[2,1.1,25000]],"ltp":2.32,"tv":1.79,"id":26354922}]}]}
{"op":"mcm","clk":"11839967386","pt":1723668614326,"mc":[{"id":"1.231737525","rc":[{"batb":[[0,2.32,31.11],[1,1.1,25000],[2,1.09,25000]],"ltp":2.32,"tv":1.79,"id":26354922}]}]}
{"op":"mcm","clk":"11839967570","pt":1723668616550,"mc":[{"id":"1.231737525","rc":[{"batb":[[0,2.34,10],[1,2.32,31.11],[2,1.1,25000]],"ltp":2.32,"tv":1.79,"id":26354922}]}]}
{"op":"mcm","clk":"11839967833","pt":1723668619836,"mc":[{"id":"1.231737525","rc":[{"batb":[[0,2.32,31.11],[1,1.1,25000],[2,1.09,25000]],"ltp":2.32,"tv":1.79,"id":26354922}]}]}
{"op":"mcm","clk":"11839968040","pt":1723668622139,"mc":[{"id":"1.231737525","rc":[{"batb":[[0,2.34,10],[1,2.32,31.11],[2,1.1,25000]],"ltp":2.32,"tv":1.79,"id":26354922}]}]}
{"op":"mcm","clk":"11839968332","pt":1723668625522,"mc":[{"id":"1.231737525","rc":[{"batb":[[0,2.32,31.11],[1,1.1,25000],[2,1.09,25000]],"ltp":2.32,"tv":1.79,"id":26354922}]}]}
{"op":"mcm","clk":"11839968529","pt":1723668628046,"mc":[{"id":"1.231737525","rc":[{"batb":[[0,2.34,10],[1,2.32,31.11],[2,1.1,25000]],"ltp":2.32,"tv":1.79,"id":26354922}]}]}
{"op":"mcm","clk":"11839968848","pt":1723668631638,"mc":[{"id":"1.231737525","rc":[{"batb":[[0,2.32,31.11],[1,1.1,25000],[2,1.09,25000]],"ltp":2.32,"tv":1.79,"id":26354922}]}]}
{"op":"mcm","clk":"11839969024","pt":1723668633858,"mc":[{"id":"1.231737525","rc":[{"batb":[[0,2.34,10],[1,2.32,31.11],[2,1.1,25000]],"ltp":2.32,"tv":1.79,"id":26354922}]}]}
{"op":"mcm","clk":"11839969273","pt":1723668637140,"mc":[{"id":"1.231737525","rc":[{"batb":[[0,2.32,31.11],[1,1.1,25000],[2,1.09,25000]],"ltp":2.32,"tv":1.79,"id":26354922}]}]}
{"op":"mcm","clk":"11839969478","pt":1723668639544,"mc":[{"id":"1.231737525","rc":[{"batb":[[0,2.34,10],[1,2.32,31.11],[2,1.1,25000]],"ltp":2.32,"tv":1.79,"id":26354922}]}]}
{"op":"mcm","clk":"11839969779","pt":1723668642933,"mc":[{"id":"1.231737525","rc":[{"batb":[[0,2.32,31.11],[1,1.1,25000],[2,1.09,25000]],"ltp":2.32,"tv":1.79,"id":26354922}]}]}
{"op":"mcm","clk":"11839969965","pt":1723668645520,"mc":[{"id":"1.231737525","rc":[{"batb":[[0,2.34,10],[1,2.32,31.11],[2,1.1,25000]],"ltp":2.32,"tv":1.79,"id":26354922}]}]}
{"op":"mcm","clk":"11839970224","pt":1723668648787,"mc":[{"id":"1.231737525","rc":[{"batb":[[0,2.32,31.11],[1,1.1,25000],[2,1.09,25000]],"ltp":2.32,"tv":1.79,"id":26354922}]}]}
{"op":"mcm","clk":"11839970406","pt":1723668651280,"mc":[{"id":"1.231737525","rc":[{"batb":[[0,2.34,10],[1,2.32,31.11],[2,1.1,25000]],"ltp":2.32,"tv":1.79,"id":26354922}]}]}
{"op":"mcm","clk":"11839970628","pt":1723668654554,"mc":[{"id":"1.231737525","rc":[{"batb":[[0,2.32,31.11],[1,1.1,25000],[2,1.09,25000]],"ltp":2.32,"tv":1.79,"id":26354922}]}]}
{"op":"mcm","clk":"11839970762","pt":1723668656757,"mc":[{"id":"1.231737525","rc":[{"batb":[[0,2.34,10],[1,2.32,31.11],[2,1.1,25000]],"ltp":2.32,"tv":1.79,"id":26354922}]}]}
{"op":"mcm","clk":"11839971006","pt":1723668660189,"mc":[{"id":"1.231737525","rc":[{"batb":[[0,2.32,31.11],[1,1.1,25000],[2,1.09,25000]],"ltp":2.32,"tv":1.79,"id":26354922}]}]}
{"op":"mcm","clk":"11839971277","pt":1723668664186,"mc":[{"id":"1.231737525","rc":[{"batb":[[0,2.34,10],[1,2.32,31.11],[2,1.1,25000]],"ltp":2.32,"tv":1.79,"id":26354922}]}]}
{"op":"mcm","clk":"11839971471","pt":1723668667466,"mc":[{"id":"1.231737525","rc":[{"batb":[[0,2.32,31.11],[1,1.1,25000],[2,1.09,25000]],"ltp":2.32,"tv":1.79,"id":26354922}]}]}
{"op":"mcm","clk":"11839971631","pt":1723668669972,"mc":[{"id":"1.231737525","rc":[{"batb":[[0,2.34,10],[1,2.32,31.11],[2,1.1,25000]],"ltp":2.32,"tv":1.79,"id":26354922}]}]}
{"op":"mcm","clk":"11839971847","pt":1723668673402,"mc":[{"id":"1.231737525","rc":[{"batb":[[0,2.32,31.11],[1,1.1,25000],[2,1.09,25000]],"ltp":2.32,"tv":1.79,"id":26354922}]}]}
{"op":"mcm","clk":"11839971991","pt":1723668675807,"mc":[{"id":"1.231737525","rc":[{"batb":[[0,2.34,10],[1,2.32,31.11],[2,1.1,25000]],"ltp":2.32,"tv":1.79,"id":26354922}]}]}
{"op":"mcm","clk":"11839972212","pt":1723668679088,"mc":[{"id":"1.231737525","rc":[{"batb":[[0,2.32,31.11],[1,1.1,25000],[2,1.09,25000]],"ltp":2.32,"tv":1.79,"id":26354922}]}]}
{"op":"mcm","clk":"11839972372","pt":1723668681796,"mc":[{"id":"1.231737525","rc":[{"batb":[[0,2.34,10],[1,2.32,31.11],[2,1.1,25000]],"ltp":2.32,"tv":1.79,"id":26354922}]}]}
{"op":"mcm","clk":"11839972611","pt":1723668685275,"mc":[{"id":"1.231737525","rc":[{"batb":[[0,2.32,31.11],[1,1.1,25000],[2,1.09,25000]],"ltp":2.32,"tv":1.79,"id":26354922}]}]}
{"op":"mcm","clk":"11839972743","pt":1723668687573,"mc":[{"id":"1.231737525","rc":[{"batb":[[0,2.34,10],[1,2.32,31.11],[2,1.1,25000]],"ltp":2.32,"tv":1.79,"id":26354922}]}]}
{"op":"mcm","clk":"11839972964","pt":1723668691010,"mc":[{"id":"1.231737525","rc":[{"batb":[[0,2.32,31.11],[1,1.1,25000],[2,1.09,25000]],"ltp":2.32,"tv":1.79,"id":26354922}]}]}
{"op":"mcm","clk":"11839973142","pt":1723668693619,"mc":[{"id":"1.231737525","rc":[{"batb":[[0,2.34,10],[1,2.32,31.11],[2,1.1,25000]],"ltp":2.32,"tv":1.79,"id":26354922}]}]}
{"op":"mcm","clk":"11839973353","pt":1723668696899,"mc":[{"id":"1.231737525","rc":[{"batb":[[0,2.32,31.11],[1,1.1,25000],[2,1.09,25000]],"ltp":2.32,"tv":1.79,"id":26354922}]}]}
{"op":"mcm","clk":"11839973510","pt":1723668699307,"mc":[{"id":"1.231737525","rc":[{"batb":[[0,2.34,10],[1,2.32,31.11],[2,1.1,25000]],"ltp":2.32,"tv":1.79,"id":26354922}]}]}
{"op":"mcm","clk":"11839973735","pt":1723668702592,"mc":[{"id":"1.231737525","rc":[{"batb":[[0,2.32,31.11],[1,1.1,25000],[2,1.09,25000]],"ltp":2.32,"tv":1.79,"id":26354922}]}]}
{"op":"mcm","clk":"11839973888","pt":1723668704903,"mc":[{"id":"1.231737525","rc":[{"batb":[[0,2.34,10],[1,2.32,31.11],[2,1.1,25000]],"ltp":2.32,"tv":1.79,"id":26354922}]}]}
{"op":"mcm","clk":"11839974105","pt":1723668708232,"mc":[{"id":"1.231737525","rc":[{"batb":[[0,2.32,31.11],[1,1.1,25000],[2,1.09,25000]],"ltp":2.32,"tv":1.79,"id":26354922}]}]}
{"op":"mcm","clk":"11839974294","pt":1723668710339,"mc":[{"id":"1.231737525","rc":[{"batb":[[0,2.34,10],[1,2.32,31.11],[2,1.1,25000]],"ltp":2.32,"tv":1.79,"id":26354922}]}]}
{"op":"mcm","clk":"11839974529","pt":1723668713530,"mc":[{"id":"1.231737525","rc":[{"batb":[[0,2.32,31.11],[1,1.1,25000],[2,1.09,25000]],"ltp":2.32,"tv":1.79,"id":26354922}]}]}
{"op":"mcm","clk":"11839974712","pt":1723668716040,"mc":[{"id":"1.231737525","rc":[{"batb":[[0,2.34,10],[1,2.32,31.11],[2,1.1,25000]],"ltp":2.32,"tv":1.79,"id":26354922}]}]}
{"op":"mcm","clk":"11839974941","pt":1723668719322,"mc":[{"id":"1.231737525","rc":[{"batb":[[0,2.32,31.11],[1,1.1,25000],[2,1.09,25000]],"ltp":2.32,"tv":1.79,"id":26354922}]}]}
{"op":"mcm","clk":"11839975116","pt":1723668721937,"mc":[{"id":"1.231737525","rc":[{"batb":[[0,2.34,10],[1,2.32,31.11],[2,1.1,25000]],"ltp":2.32,"tv":1.79,"id":26354922}]}]}
{"op":"mcm","clk":"11839975327","pt":1723668725321,"mc":[{"id":"1.231737525","rc":[{"batb":[[0,2.32,31.11],[1,1.1,25000],[2,1.09,25000]],"ltp":2.32,"tv":1.79,"id":26354922}]}]}
{"op":"mcm","clk":"11839975488","pt":1723668727523,"mc":[{"id":"1.231737525","rc":[{"batb":[[0,2.34,10],[1,2.32,31.11],[2,1.1,25000]],"ltp":2.32,"tv":1.79,"id":26354922}]}]}
{"op":"mcm","clk":"11839975707","pt":1723668730856,"mc":[{"id":"1.231737525","rc":[{"batb":[[0,2.32,31.11],[1,1.1,25000],[2,1.09,25000]],"ltp":2.32,"tv":1.79,"id":26354922}]}]}
{"op":"mcm","clk":"11839975858","pt":1723668733926,"mc":[{"id":"1.231737525","rc":[{"batb":[[0,2.34,10],[1,2.32,31.11],[2,1.1,25000]],"ltp":2.32,"tv":1.79,"id":26354922}]}]}
{"op":"mcm","clk":"11839976117","pt":1723668736757,"mc":[{"id":"1.231737525","rc":[{"batb":[[0,2.32,31.11],[1,1.1,25000],[2,1.09,25000]],"ltp":2.32,"tv":1.79,"id":26354922}]}]}
{"op":"mcm","clk":"11839976350","pt":1723668739475,"mc":[{"id":"1.231737525","rc":[{"batb":[[0,2.34,10],[1,2.32,31.11],[2,1.1,25000]],"ltp":2.32,"tv":1.79,"id":26354922}]}]}
{"op":"mcm","clk":"11839976603","pt":1723668742857,"mc":[{"id":"1.231737525","rc":[{"batb":[[0,2.32,31.11],[1,1.1,25000],[2,1.09,25000]],"ltp":2.32,"tv":1.79,"id":26354922}]}]}
{"op":"mcm","clk":"11839976780","pt":1723668745166,"mc":[{"id":"1.231737525","rc":[{"batb":[[0,2.34,10],[1,2.32,31.11],[2,1.1,25000]],"ltp":2.32,"tv":1.79,"id":26354922}]}]}
{"op":"mcm","clk":"11839977026","pt":1723668748594,"mc":[{"id":"1.231737525","rc":[{"batb":[[0,2.32,31.11],[1,1.1,25000],[2,1.09,25000]],"ltp":2.32,"tv":1.79,"id":26354922}]}]}
{"op":"mcm","clk":"11839977175","pt":1723668750899,"mc":[{"id":"1.231737525","rc":[{"batb":[[0,2.34,10],[1,2.32,31.11],[2,1.1,25000]],"ltp":2.32,"tv":1.79,"id":26354922}]}]}
{"op":"mcm","clk":"11839977397","pt":1723668754275,"mc":[{"id":"1.231737525","rc":[{"batb":[[0,2.32,31.11],[1,1.1,25000],[2,1.09,25000]],"ltp":2.32,"tv":1.79,"id":26354922}]}]}
{"op":"mcm","clk":"11839977620","pt":1723668757560,"mc":[{"id":"1.231737525","rc":[{"batb":[[0,2.34,10],[1,2.32,31.11],[2,1.1,25000]],"ltp":2.32,"tv":1.79,"id":26354922}]}]}
{"op":"mcm","clk":"11839977870","pt":1723668760886,"mc":[{"id":"1.231737525","rc":[{"batb":[[0,2.32,31.11],[1,1.1,25000],[2,1.09,25000]],"ltp":2.32,"tv":1.79,"id":26354922}]}]}
{"op":"mcm","clk":"11839978053","pt":1723668763323,"mc":[{"id":"1.231737525","rc":[{"batb":[[0,2.34,10],[1,2.32,31.11],[2,1.1,25000]],"ltp":2.32,"tv":1.79,"id":26354922}]}]}
{"op":"mcm","clk":"11839978263","pt":1723668766802,"mc":[{"id":"1.231737525","rc":[{"batb":[[0,2.32,31.11],[1,1.1,25000],[2,1.09,25000]],"ltp":2.32,"tv":1.79,"id":26354922}]}]}
{"op":"mcm","clk":"11839978495","pt":1723668770122,"mc":[{"id":"1.231737525","rc":[{"batb":[[0,2.34,10],[1,2.32,31.11],[2,1.1,25000]],"ltp":2.32,"tv":1.79,"id":26354922}]}]}
{"op":"mcm","clk":"11839978759","pt":1723668773300,"mc":[{"id":"1.231737525","rc":[{"batb":[[0,2.32,31.11],[1,1.1,25000],[2,1.09,25000]],"ltp":2.32,"tv":1.79,"id":26354922}]}]}
{"op":"mcm","clk":"11839978932","pt":1723668775807,"mc":[{"id":"1.231737525","rc":[{"batb":[[0,2.34,10],[1,2.32,31.11],[2,1.1,25000]],"ltp":2.32,"tv":1.79,"id":26354922}]}]}
{"op":"mcm","clk":"11839979172","pt":1723668779093,"mc":[{"id":"1.231737525","rc":[{"batb":[[0,2.32,31.11],[1,1.1,25000],[2,1.09,25000]],"ltp":2.32,"tv":1.79,"id":26354922}]}]}
{"op":"mcm","clk":"11839979359","pt":1723668781705,"mc":[{"id":"1.231737525","rc":[{"batb":[[0,2.34,10],[1,2.32,31.11],[2,1.1,25000]],"ltp":2.32,"tv":1.79,"id":26354922}]}]}
{"op":"mcm","clk":"11839979592","pt":1723668784917,"mc":[{"id":"1.231737525","rc":[{"batb":[[0,2.32,31.11],[1,1.1,25000],[2,1.09,25000]],"ltp":2.32,"tv":1.79,"id":26354922}]}]}
{"op":"mcm","clk":"11839979748","pt":1723668787423,"mc":[{"id":"1.231737525","rc":[{"batb":[[0,2.34,10],[1,2.32,31.11],[2,1.1,25000]],"ltp":2.32,"tv":1.79,"id":26354922}]}]}
{"op":"mcm","clk":"11839979991","pt":1723668790916,"mc":[{"id":"1.231737525","rc":[{"batb":[[0,2.46,11.92]],"ltp":2.32,"tv":1.79,"id":26354922},{"trd":[[1.68,638.15]],"batb":[[0,1.67,900.65],[1,1.66,800],[2,1.65,696.77]],"ltp":1.68,"tv":1447.34,"id":26354921}],"tv":1449.13}]}
{"op":"mcm","clk":"11839980035","pt":1723668791520,"mc":[{"id":"1.231737525","rc":[{"batb":[[1,1.1,25000],[2,1.09,25000]],"ltp":2.32,"tv":1.79,"id":26354922},{"batb":[[2,1.65,676.22]],"ltp":1.68,"tv":1447.34,"id":26354921}]}]}
{"op":"mcm","clk":"11839981138","pt":1723668807912,"mc":[{"id":"1.231737525","rc":[{"trd":[[1.67,1486.42],[1.68,639.45]],"batb":[[0,1.67,156.79]],"ltp":1.67,"tv":2935.06,"id":26354921}],"tv":2936.85}]}
{"op":"mcm","clk":"11839981611","pt":1723668815531,"mc":[{"id":"1.231737525","rc":[{"trd":[[2.48,17.17]],"batl":[[0,2.5,3],[1,2.52,3],[2,2.54,246.99]],"ltp":2.48,"tv":18.96,"id":26354922},{"trd":[[1.67,1843.02]],"batb":[[0,1.66,800],[1,1.65,676.22],[2,1.64,216.57]],"batl":[[0,1.67,438.83],[1,1.69,4089.4],[2,1.7,8]],"ltp":1.67,"tv":3291.66,"id":26354921}],"tv":3310.62}]}
{"op":"mcm","clk":"11839981768","pt":1723668817930,"mc":[{"id":"1.231737525","rc":[{"trd":[[2.5,3]],"batb":[[0,2.5,17.03],[1,1.11,10],[2,1.1,25000]],"batl":[[0,2.52,3],[1,2.54,246.99],[2,2.54,0]],"ltp":2.5,"tv":21.96,"id":26354922}],"tv":3313.62}]}
{"op":"mcm","clk":"11839981968","pt":1723668821148,"mc":[{"id":"1.231737525","rc":[{"batb":[[1,1.1,25000],[2,1.09,25000]],"ltp":2.5,"tv":21.96,"id":26354922}]}]}
{"op":"mcm","clk":"11839982528","pt":1723668829953,"mc":[{"id":"1.231737525","rc":[{"batl":[[0,1.69,4089.4],[1,1.7,8],[2,1.71,8]],"ltp":1.67,"tv":3291.66,"id":26354921}]}]}
{"op":"mcm","clk":"11839982534","pt":1723668830057,"mc":[{"id":"1.231737525","rc":[{"trd":[[1.66,886.2]],"batb":[[0,1.66,361.17]],"ltp":1.66,"tv":4169.32,"id":26354921}],"tv":4191.28}]}
{"op":"mcm","clk":"11839982620","pt":1723668831235,"mc":[{"id":"1.231737525","rc":[{"batb":[[0,2.46,17.31],[1,1.11,10],[2,1.1,25000]],"ltp":2.5,"tv":21.96,"id":26354922}]}]}
{"op":"mcm","clk":"11839982770","pt":1723668833790,"mc":[{"id":"1.231737525","rc":[{"batb":[[0,2.46,29.23]],"ltp":2.5,"tv":21.96,"id":26354922}]}]}
{"op":"mcm","clk":"11839982816","pt":1723668834659,"mc":[{"id":"1.231737525","rc":[{"batb":[[1,1.1,25000],[2,1.09,25000]],"ltp":2.5,"tv":21.96,"id":26354922}]}]}
{"op":"mcm","clk":"11839982877","pt":1723668835681,"mc":[{"id":"1.231737525","rc":[{"batl":[[0,2.54,243.99],[1,2.54,0]],"ltp":2.5,"tv":21.96,"id":26354922}]}]}
{"op":"mcm","clk":"11839982954","pt":1723668836961,"mc":[{"id":"1.231737525","rc":[{"batb":[[0,2.46,33.23]],"batl":[[0,2.52,4],[1,2.54,243.99]],"ltp":2.5,"tv":21.96,"id":26354922},{"batb":[[0,1.67,4],[1,1.66,365.17],[2,1.65,676.22]],"batl":[[0,1.68,4],[1,1.69,4089.4],[2,1.7,8]],"ltp":1.66,"tv":4169.32,"id":26354921}]}]}
{"op":"mcm","clk":"11839984004","pt":1723668852769,"mc":[{"id":"1.231737525","rc":[{"batb":[[0,2.48,4],[1,2.46,33.23],[2,1.1,25000]],"batl":[[0,2.5,4],[1,2.52,4],[2,2.54,243.99]],"ltp":2.5,"tv":21.96,"id":26354922},{"batb":[[0,1.66,365.17],[1,1.65,676.22],[2,1.64,216.57]],"ltp":1.66,"tv":4169.32,"id":26354921}]}]}
{"op":"mcm","clk":"11839985102","pt":1723668867194,"mc":[{"id":"1.231737525","rc":[{"batb":[[0,1.67,4],[1,1.66,365.17],[2,1.65,676.22]],"ltp":1.66,"tv":4169.32,"id":26354921}]}]}
{"op":"mcm","clk":"11839985740","pt":1723668876922,"mc":[{"id":"1.231737525","rc":[{"batb":[[1,1.66,1165.17]],"ltp":1.66,"tv":4169.32,"id":26354921}]}]}
{"op":"mcm","clk":"11839985758","pt":1723668877233,"mc":[{"id":"1.231737525","rc":[{"batb":[[0,1.66,1165.17],[1,1.65,676.22],[2,1.64,216.57]],"ltp":1.66,"tv":4169.32,"id":26354921}]}]}
{"op":"mcm","clk":"11839986099","pt":1723668882333,"mc":[{"id":"1.231737525","rc":[{"batb":[[0,1.67,4],[1,1.66,1165.17],[2,1.65,676.22]],"ltp":1.66,"tv":4169.32,"id":26354921}]}]}
{"op":"mcm","clk":"11839986787","pt":1723668891937,"mc":[{"id":"1.231737525","rc":[{"batb":[[0,1.66,365.17],[1,1.65,676.22],[2,1.64,216.57]],"ltp":1.66,"tv":4169.32,"id":26354921}]}]}
{"op":"mcm","clk":"11839987165","pt":1723668897776,"mc":[{"id":"1.231737525","rc":[{"batb":[[0,2.46,33.23],[1,1.1,25000],[2,1.09,25000]],"ltp":2.5,"tv":21.96,"id":26354922},{"batb":[[0,1.67,804],[1,1.66,365.17],[2,1.65,676.22]],"ltp":1.66,"tv":4169.32,"id":26354921}]}]}
{"op":"mcm","clk":"11839987214","pt":1723668898338,"mc":[{"id":"1.231737525","rc":[{"batl":[[0,1.69,4089.4],[1,1.7,8],[2,1.71,8]],"ltp":1.66,"tv":4169.32,"id":26354921}]}]}
{"op":"mcm","clk":"11840006392","pt":1723669186879,"mc":[{"id":"1.231737525","rc":[{"batb":[[0,1.67,4]],"ltp":1.66,"tv":4169.32,"id":26354921}]}]}
{"op":"mcm","clk":"11840006476","pt":1723669188410,"mc":[{"id":"1.231737525","rc":[{"batb":[[0,1.67,21.12]],"batl":[[0,1.68,17.12],[1,1.69,4089.4],[2,1.7,8]],"ltp":1.66,"tv":4169.32,"id":26354921}]}]}
{"op":"mcm","clk":"11840006655","pt":1723669191681,"mc":[{"id":"1.231737525","rc":[{"batl":[[0,2.54,243.99],[1,2.52,0],[2,2.54,0]],"ltp":2.5,"tv":21.96,"id":26354922},{"batb":[[0,1.67,17.12],[1,1.65,676.22],[2,1.64,216.57]],"ltp":1.66,"tv":4169.32,"id":26354921}]}]}
{"op":"mcm","clk":"11840006690","pt":1723669192401,"mc":[{"id":"1.231737525","rc":[{"batb":[[0,1.65,676.22],[1,1.64,216.57],[2,1.63,138.46]],"ltp":1.66,"tv":4169.32,"id":26354921}]}]}
{"op":"mcm","clk":"11840006932","pt":1723669197405,"mc":[{"id":"1.231737525","rc":[{"batb":[[1,2.32,31.11],[2,1.1,25000]],"ltp":2.5,"tv":21.96,"id":26354922},{"batb":[[0,1.65,739.41]],"ltp":1.66,"tv":4169.32,"id":26354921}]}]}
{"op":"mcm","clk":"11840007071","pt":1723669199812,"mc":[{"id":"1.231737525","rc":[{"batl":[[0,2.54,247.99]],"ltp":2.5,"tv":21.96,"id":26354922},{"batb":[[0,1.66,4],[1,1.65,743.41],[2,1.64,216.57]],"batl":[[0,1.68,21.12]],"ltp":1.66,"tv":4169.32,"id":26354921}]}]}
{"op":"mcm","clk":"11840007859","pt":1723669210709,"mc":[{"id":"1.231737525","rc":[{"trd":[[2.48,17.17]],"batb":[[0,2.46,33.23]],"ltp":2.5,"tv":21.96,"id":26354922},{"trd":[[1.7,93.61],[1.71,112.85]],"batb":[[2,1.64,1016.57]],"batl":[[0,1.68,21.12]],"ltp":1.66,"tv":4169.31,"id":26354921}],"tv":4191.27}]}
{"op":"mcm","clk":"11840008171","pt":1723669214944,"mc":[{"id":"1.231737525","rc":[{"batb":[[0,2.48,4],[1,2.46,33.23],[2,2.32,31.11]],"batl":[[0,2.52,4],[1,2.54,247.99]],"ltp":2.5,"tv":21.96,"id":26354922}]}]}
{"op":"mcm","clk":"11840008726","pt":1723669222613,"mc":[{"id":"1.231737525","rc":[{"batb":[[0,1.66,21.12]],"ltp":1.66,"tv":4169.31,"id":26354921}]}]}
{"op":"mcm","clk":"11840009067","pt":1723669227555,"mc":[{"id":"1.231737525","rc":[{"batb":[[2,1.1,25000]],"ltp":2.5,"tv":21.96,"id":26354922},{"batb":[[1,1.65,680.22]],"ltp":1.66,"tv":4169.31,"id":26354921}]}]}
{"op":"mcm","clk":"11840013127","pt":1723669297016,"mc":[{"id":"1.231737525","rc":[{"batb":[[1,1.65,840.22]],"ltp":1.66,"tv":4169.31,"id":26354921}]}]}
{"op":"mcm","clk":"11840016208","pt":1723669353239,"mc":[{"id":"1.231737525","rc":[{"batb":[[1,1.65,680.22]],"ltp":1.66,"tv":4169.31,"id":26354921}]}]}
{"op":"mcm","clk":"11840029685","pt":1723669594408,"mc":[{"id":"1.231737525","rc":[{"batb":[[0,1.66,61.23]],"ltp":1.66,"tv":4169.31,"id":26354921}]}]}
{"op":"mcm","clk":"11840030699","pt":1723669616026,"mc":[{"id":"1.231737525","rc":[{"trd":[[1.66,888.2]],"batb":[[0,1.66,60.23]],"ltp":1.66,"tv":4171.31,"id":26354921}],"tv":4193.27}]}
{"op":"mcm","clk":"11840038575","pt":1723669774668,"mc":[{"id":"1.231737525","rc":[{"trd":[[2.48,20.77]],"batb":[[0,2.48,2.2]],"batl":[[0,2.5,4],[1,2.52,4],[2,2.54,247.99]],"ltp":2.48,"tv":25.56,"id":26354922}],"tv":4196.87}]}
{"op":"mcm","clk":"11840039043","pt":1723669783898,"mc":[{"id":"1.231737525","rc":[{"batl":[[0,2.54,243.99],[1,2.52,0],[2,2.54,0]],"ltp":2.48,"tv":25.56,"id":26354922},{"batb":[[0,1.66,20.12]],"ltp":1.66,"tv":4171.31,"id":26354921}]}]}
