{"op":"mcm","clk":"11927005933","pt":1724234660525,"mc":[{"id":"1.232092849","marketDefinition":{"bspMarket":false,"turnInPlayEnabled":true,"persistenceEnabled":true,"marketBaseRate":5.0,"eventId":"33514301","eventTypeId":"4","numberOfWinners":1,"bettingType":"ODDS","marketType":"MATCH_ODDS","marketTime":"2024-08-22T09:45:00.000Z","suspendTime":"2024-08-22T09:45:00.000Z","bspReconciled":false,"complete":true,"inPlay":false,"crossMatching":false,"runnersVoidable":false,"numberOfActiveRunners":2,"betDelay":0,"status":"OPEN","runners":[{"status":"ACTIVE","sortPriority":1,"id":19587212,"name":"Munster Reds"},{"status":"ACTIVE","sortPriority":2,"id":6847357,"name":"Northern Knights"}],"regulators":["MR_INT"],"countryCode":"GB","discountAllowed":false,"timezone":"GMT","openDate":"2024-08-22T09:45:00.000Z","version":6088949418,"name":"Match Odds","eventName":"Munster Reds v Northern Knights"},"rc":[{"batb":[[0,1.03,200],[1,1.02,200],[2,1.01,220]],"ltp":0.0,"tv":0.0,"id":6847357},{"batb":[[0,1.03,200],[1,1.02,200],[2,1.01,220]],"ltp":0.0,"tv":0.0,"id":19587212}]}]}
{"op":"mcm","clk":"11927006068","pt":1724234662037,"mc":[{"id":"1.232092849","marketDefinition":{"bspMarket":false,"turnInPlayEnabled":true,"persistenceEnabled":true,"marketBaseRate":5.0,"eventId":"33514301","eventTypeId":"4","numberOfWinners":1,"bettingType":"ODDS","marketType":"MATCH_ODDS","marketTime":"2024-08-22T09:45:00.000Z","suspendTime":"2024-08-22T09:45:00.000Z","bspReconciled":false,"complete":true,"inPlay":false,"crossMatching":false,"runnersVoidable":false,"numberOfActiveRunners":2,"betDelay":0,"status":"OPEN","runners":[{"status":"ACTIVE","sortPriority":1,"id":19587212,"name":"Munster Reds"},{"status":"ACTIVE","sortPriority":2,"id":6847357,"name":"Northern Knights"}],"regulators":["MR_INT"],"countryCode":"GB","discountAllowed":true,"timezone":"GMT","openDate":"2024-08-22T09:45:00.000Z","version":6088949418,"name":"Match Odds","eventName":"Munster Reds v Northern Knights"}}]}
{"op":"mcm","clk":"11927256503","pt":1724237196495,"mc":[{"id":"1.232092849","rc":[{"batb":[[2,1.01,482.32]],"ltp":0.0,"tv":0.0,"id":19587212}]}]}
{"op":"mcm","clk":"11927256546","pt":1724237196805,"mc":[{"id":"1.232092849","rc":[{"batb":[[2,1.01,482.32]],"ltp":0.0,"tv":0.0,"id":6847357}]}]}
{"op":"mcm","clk":"11927276885","pt":1724237394594,"mc":[{"id":"1.232092849","rc":[{"batb":[[0,1.21,83.27],[1,1.03,200],[2,1.02,200]],"ltp":0.0,"tv":0.0,"id":19587212}]}]}
{"op":"mcm","clk":"11927278018","pt":1724237406097,"mc":[{"id":"1.232092849","rc":[{"batb":[[0,1.21,83.27],[1,1.03,200],[2,1.02,200]],"ltp":0.0,"tv":0.0,"id":6847357}]}]}
{"op":"mcm","clk":"11927278136","pt":1724237407134,"mc":[{"id":"1.232092849","marketDefinition":{"bspMarket":false,"turnInPlayEnabled":true,"persistenceEnabled":true,"marketBaseRate":5.0,"eventId":"33514301","eventTypeId":"4","numberOfWinners":1,"bettingType":"ODDS","marketType":"MATCH_ODDS","marketTime":"2024-08-22T09:45:00.000Z","suspendTime":"2024-08-22T09:45:00.000Z","bspReconciled":false,"complete":true,"inPlay":false,"crossMatching":true,"runnersVoidable":false,"numberOfActiveRunners":2,"betDelay":0,"status":"OPEN","runners":[{"status":"ACTIVE","sortPriority":1,"id":19587212,"name":"Munster Reds"},{"status":"ACTIVE","sortPriority":2,"id":6847357,"name":"Northern Knights"}],"regulators":["MR_INT"],"countryCode":"GB","discountAllowed":true,"timezone":"GMT","openDate":"2024-08-22T09:45:00.000Z","version":6088949418,"name":"Match Odds","eventName":"Munster Reds v Northern Knights"}}]}
{"op":"mcm","clk":"11927400340","pt":1724238774867,"mc":[{"id":"1.232092849","rc":[{"batb":[[0,1.21,83.24]],"ltp":0.0,"tv":0.0,"id":6847357},{"batb":[[0,1.21,83.24]],"ltp":0.0,"tv":0.0,"id":19587212}]}]}
{"op":"mcm","clk":"11927455052","pt":1724239220792,"mc":[{"id":"1.232092849","rc":[{"batb":[[0,1.22,38.97],[1,1.21,83.24],[2,1.03,200]],"ltp":0.0,"tv":0.0,"id":6847357},{"batb":[[0,1.22,38.97],[1,1.21,83.24],[2,1.03,200]],"ltp":0.0,"tv":0.0,"id":19587212}]}]}
{"op":"mcm","clk":"11927562159","pt":1724240359967,"mc":[{"id":"1.232092849","rc":[{"batb":[[2,1.04,1.53]],"ltp":0.0,"tv":0.0,"id":6847357},{"batb":[[2,1.04,1.53]],"ltp":0.0,"tv":0.0,"id":19587212}]}]}
{"op":"mcm","clk":"11927568941","pt":1724240434036,"mc":[{"id":"1.232092849","rc":[{"batb":[[0,1.23,5.8],[1,1.22,38.97],[2,1.21,83.24]],"ltp":0.0,"tv":0.0,"id":6847357},{"batb":[[0,1.23,6.82],[1,1.22,38.97],[2,1.21,83.24]],"ltp":0.0,"tv":0.0,"id":19587212}]}]}
{"op":"mcm","clk":"11927621988","pt":1724241021406,"mc":[{"id":"1.232092849","rc":[{"batb":[[1,1.21,83.24],[2,1.04,1.53]],"ltp":0.0,"tv":0.0,"id":6847357},{"batb":[[1,1.21,83.24],[2,1.04,1.53]],"ltp":0.0,"tv":0.0,"id":19587212}]}]}
{"op":"mcm","clk":"11927629529","pt":1724241124314,"mc":[{"id":"1.232092849","rc":[{"batb":[[0,1.24,35.72],[1,1.23,5.8],[2,1.21,83.24]],"ltp":0.0,"tv":0.0,"id":6847357},{"batb":[[0,1.24,35.72],[1,1.23,6.82],[2,1.21,83.24]],"ltp":0.0,"tv":0.0,"id":19587212}]}]}
{"op":"mcm","clk":"11927725775","pt":1724242514486,"mc":[{"id":"1.232092849","rc":[{"batb":[[0,1.24,35.72],[1,1.23,5.81],[2,1.21,83.26]],"ltp":0.0,"tv":0.0,"id":6847357},{"batb":[[0,1.25,6.83],[1,1.24,35.72],[2,1.21,83.26]],"ltp":0.0,"tv":0.0,"id":19587212}]}]}
{"op":"mcm","clk":"11927725815","pt":1724242514953,"mc":[{"id":"1.232092849","rc":[{"batb":[[0,1.25,5.81],[1,1.24,35.72]],"ltp":0.0,"tv":0.0,"id":6847357}]}]}
{"op":"mcm","clk":"11927756977","pt":1724242924696,"mc":[{"id":"1.232092849","rc":[{"batb":[[1,1.21,83.26],[2,1.04,1.53]],"ltp":0.0,"tv":0.0,"id":6847357},{"batb":[[1,1.21,83.26],[2,1.04,1.53]],"ltp":0.0,"tv":0.0,"id":19587212}]}]}
{"op":"mcm","clk":"11927763182","pt":1724243004358,"mc":[{"id":"1.232092849","rc":[{"batb":[[0,1.26,32.97],[1,1.25,5.81],[2,1.21,83.26]],"ltp":0.0,"tv":0.0,"id":6847357},{"batb":[[0,1.26,32.97],[1,1.25,6.83],[2,1.21,83.26]],"ltp":0.0,"tv":0.0,"id":19587212}]}]}
{"op":"mcm","clk":"11927812857","pt":1724243787523,"mc":[{"id":"1.232092849","rc":[{"batb":[[0,1.26,33.51]],"ltp":0.0,"tv":0.0,"id":6847357}]}]}
{"op":"mcm","clk":"11927813406","pt":1724243797408,"mc":[{"id":"1.232092849","rc":[{"batb":[[0,1.26,33.51]],"ltp":0.0,"tv":0.0,"id":19587212}]}]}
{"op":"mcm","clk":"11927867075","pt":1724244567540,"mc":[{"id":"1.232092849","rc":[{"batb":[[1,1.21,83.26],[2,1.04,1.53]],"ltp":0.0,"tv":0.0,"id":6847357},{"batb":[[0,1.27,7.36],[1,1.26,32.97]],"ltp":0.0,"tv":0.0,"id":19587212}]}]}
{"op":"mcm","clk":"11927867078","pt":1724244567646,"mc":[{"id":"1.232092849","rc":[{"batb":[[0,1.27,6.34],[1,1.26,32.97],[2,1.21,83.26]],"ltp":0.0,"tv":0.0,"id":6847357}]}]}
{"op":"mcm","clk":"11927881771","pt":1724244805500,"mc":[{"id":"1.232092849","rc":[{"batb":[[1,1.21,83.26],[2,1.04,1.53]],"ltp":0.0,"tv":0.0,"id":6847357},{"batb":[[1,1.21,83.26],[2,1.04,1.53]],"ltp":0.0,"tv":0.0,"id":19587212}]}]}
{"op":"mcm","clk":"11927885533","pt":1724244860885,"mc":[{"id":"1.232092849","rc":[{"batb":[[0,1.28,31.15],[1,1.27,5.81],[2,1.21,83.26]],"ltp":0.0,"tv":0.0,"id":6847357},{"batb":[[0,1.28,31.15],[1,1.27,6.83],[2,1.21,83.26]],"ltp":0.0,"tv":0.0,"id":19587212}]}]}
{"op":"mcm","clk":"11928009624","pt":1724246661272,"mc":[{"id":"1.232092849","rc":[{"batb":[[0,1.27,6.34],[1,1.21,83.31],[2,1.04,1.53]],"ltp":0.0,"tv":0.0,"id":6847357},{"batb":[[0,1.27,7.36],[1,1.21,83.31],[2,1.04,1.53]],"ltp":0.0,"tv":0.0,"id":19587212}]}]}
{"op":"mcm","clk":"11928009830","pt":1724246664564,"mc":[{"id":"1.232092849","rc":[{"batb":[[0,1.21,83.85],[1,1.04,1.53],[2,1.03,200]],"ltp":0.0,"tv":0.0,"id":6847357},{"batb":[[0,1.22,7.36]],"ltp":0.0,"tv":0.0,"id":19587212}]}]}
{"op":"mcm","clk":"11928009839","pt":1724246664667,"mc":[{"id":"1.232092849","rc":[{"batb":[[0,1.22,6.34],[1,1.21,83.31],[2,1.04,1.53]],"ltp":0.0,"tv":0.0,"id":6847357}]}]}
{"op":"mcm","clk":"11928012427","pt":1724246705110,"mc":[{"id":"1.232092849","rc":[{"batb":[[0,1.23,37.8],[1,1.22,5.8],[2,1.21,83.31]],"ltp":0.0,"tv":0.0,"id":6847357},{"batb":[[0,1.23,37.8],[1,1.22,6.82],[2,1.21,83.31]],"ltp":0.0,"tv":0.0,"id":19587212}]}]}
{"op":"mcm","clk":"11928129011","pt":1724248505702,"mc":[{"id":"1.232092849","rc":[{"batb":[[0,1.22,6.34],[1,1.21,83.31],[2,1.04,1.53]],"ltp":0.0,"tv":0.0,"id":6847357},{"batb":[[0,1.22,7.36],[1,1.21,83.31],[2,1.04,1.53]],"ltp":0.0,"tv":0.0,"id":19587212}]}]}
{"op":"mcm","clk":"11928130548","pt":1724248535823,"mc":[{"id":"1.232092849","rc":[{"batb":[[0,1.23,37.8],[1,1.22,5.8],[2,1.21,83.31]],"ltp":0.0,"tv":0.0,"id":6847357},{"batb":[[0,1.23,37.8],[1,1.22,6.82],[2,1.21,83.31]],"ltp":0.0,"tv":0.0,"id":19587212}]}]}
{"op":"mcm","clk":"11928144760","pt":1724248827399,"mc":[{"id":"1.232092849","rc":[{"batb":[[0,1.23,37.75],[2,1.21,83.14]],"ltp":0.0,"tv":0.0,"id":6847357},{"batb":[[0,1.24,7.36],[1,1.23,37.22],[2,1.21,83.14]],"ltp":0.0,"tv":0.0,"id":19587212}]}]}
{"op":"mcm","clk":"11928144780","pt":1724248827711,"mc":[{"id":"1.232092849","rc":[{"batb":[[0,1.24,6.34],[1,1.23,37.22]],"ltp":0.0,"tv":0.0,"id":6847357}]}]}
{"op":"mcm","clk":"11928250475","pt":1724250336384,"mc":[{"id":"1.232092849","rc":[{"batb":[[1,1.21,83.14],[2,1.04,1.53]],"ltp":0.0,"tv":0.0,"id":6847357},{"batb":[[1,1.21,83.14],[2,1.04,1.53]],"ltp":0.0,"tv":0.0,"id":19587212}]}]}
{"op":"mcm","clk":"11928251783","pt":1724250353897,"mc":[{"id":"1.232092849","rc":[{"batb":[[0,1.25,34.78],[1,1.24,5.8],[2,1.21,83.14]],"ltp":0.0,"tv":0.0,"id":6847357},{"batb":[[0,1.25,34.78],[1,1.24,6.82],[2,1.21,83.14]],"ltp":0.0,"tv":0.0,"id":19587212}]}]}
{"op":"mcm","clk":"11928286707","pt":1724250991136,"mc":[{"id":"1.232092849","rc":[{"batb":[[0,1.26,6.34],[1,1.25,34.24]],"ltp":0.0,"tv":0.0,"id":6847357},{"batb":[[0,1.26,7.36],[1,1.25,34.24]],"ltp":0.0,"tv":0.0,"id":19587212}]}]}
{"op":"mcm","clk":"11928300785","pt":1724251266506,"mc":[{"id":"1.232092849","rc":[{"batb":[[0,1.26,5.8]],"ltp":0.0,"tv":0.0,"id":6847357},{"batb":[[0,1.26,6.82]],"ltp":0.0,"tv":0.0,"id":19587212}]}]}
{"op":"mcm","clk":"11928350616","pt":1724252071940,"mc":[{"id":"1.232092849","rc":[{"batl":[[0,3,0.08]],"ltp":0.0,"tv":0.0,"id":19587212}]}]}
{"op":"mcm","clk":"11928355295","pt":1724252154497,"mc":[{"id":"1.232092849","rc":[{"batb":[[1,1.21,83.14],[2,1.04,1.53]],"ltp":0.0,"tv":0.0,"id":19587212}]}]}
{"op":"mcm","clk":"11928355311","pt":1724252154703,"mc":[{"id":"1.232092849","rc":[{"batb":[[1,1.21,83.14],[2,1.04,1.53]],"ltp":0.0,"tv":0.0,"id":6847357}]}]}
{"op":"mcm","clk":"11928361362","pt":1724252268101,"mc":[{"id":"1.232092849","rc":[{"batb":[[0,1.27,31.7],[1,1.26,5.8],[2,1.21,83.14]],"ltp":0.0,"tv":0.0,"id":6847357},{"batb":[[0,1.27,31.7],[1,1.26,6.82],[2,1.21,83.14]],"ltp":0.0,"tv":0.0,"id":19587212}]}]}
{"op":"mcm","clk":"11928446619","pt":1724253188562,"mc":[{"id":"1.232092849","rc":[{"batb":[[0,1.28,5.8],[1,1.27,31.71],[2,1.21,83.22]],"ltp":0.0,"tv":0.0,"id":6847357},{"batb":[[0,1.28,6.81],[1,1.27,31.71],[2,1.21,83.22]],"ltp":0.0,"tv":0.0,"id":19587212}]}]}
{"op":"mcm","clk":"11928536227","pt":1724254068499,"mc":[{"id":"1.232092849","rc":[{"batb":[[1,1.21,83.22],[2,1.04,1.53]],"ltp":0.0,"tv":0.0,"id":6847357},{"batb":[[1,1.21,83.22],[2,1.04,1.53]],"ltp":0.0,"tv":0.0,"id":19587212}]}]}
{"op":"mcm","clk":"11928546215","pt":1724254170151,"mc":[{"id":"1.232092849","rc":[{"batb":[[0,1.29,6.13],[1,1.28,5.8],[2,1.21,83.22]],"ltp":0.0,"tv":0.0,"id":6847357}]}]}
{"op":"mcm","clk":"11928546695","pt":1724254175550,"mc":[{"id":"1.232092849","rc":[{"batb":[[0,1.29,6.13],[1,1.28,6.81],[2,1.21,83.22]],"ltp":0.0,"tv":0.0,"id":19587212}]}]}
{"op":"mcm","clk":"11928552632","pt":1724254235598,"mc":[{"id":"1.232092849","rc":[{"batb":[[0,1.3,28.53],[1,1.29,6.13],[2,1.28,5.8]],"ltp":0.0,"tv":0.0,"id":6847357},{"batb":[[0,1.3,28.53],[1,1.29,6.13],[2,1.28,6.81]],"ltp":0.0,"tv":0.0,"id":19587212}]}]}
{"op":"mcm","clk":"11928691592","pt":1724255234460,"mc":[{"id":"1.232092849","rc":[{"batb":[[0,1.33,6.13],[1,1.3,28.53]],"ltp":0.0,"tv":0.0,"id":6847357}]}]}
{"op":"mcm","clk":"11928691674","pt":1724255235202,"mc":[{"id":"1.232092849","rc":[{"batb":[[0,1.33,6.13],[1,1.3,28.53]],"ltp":0.0,"tv":0.0,"id":19587212}]}]}
{"op":"mcm","clk":"11928705935","pt":1724255359390,"mc":[{"id":"1.232092849","rc":[{"batb":[[1,1.31,5.8],[2,1.3,28.53]],"ltp":0.0,"tv":0.0,"id":6847357},{"batb":[[1,1.31,6.81],[2,1.3,28.53]],"ltp":0.0,"tv":0.0,"id":19587212}]}]}
{"op":"mcm","clk":"11928785179","pt":1724256036033,"mc":[{"id":"1.232092849","rc":[{"batb":[[0,1.33,6.12],[1,1.31,5.79],[2,1.21,83.31]],"ltp":0.0,"tv":0.0,"id":6847357},{"batb":[[0,1.33,6.12],[1,1.31,6.81],[2,1.21,83.31]],"ltp":0.0,"tv":0.0,"id":19587212}]}]}
{"op":"mcm","clk":"11928807415","pt":1724256199975,"mc":[{"id":"1.232092849","rc":[{"batb":[[0,1.34,25.18],[1,1.33,6.12],[2,1.31,5.79]],"ltp":0.0,"tv":0.0,"id":6847357},{"batb":[[0,1.34,25.18],[1,1.33,6.12],[2,1.31,6.81]],"ltp":0.0,"tv":0.0,"id":19587212}]}]}
{"op":"mcm","clk":"11928945113","pt":1724257126227,"mc":[{"id":"1.232092849","rc":[{"batb":[[0,1.53,6.12],[1,1.34,25.18]],"ltp":0.0,"tv":0.0,"id":19587212}]}]}
{"op":"mcm","clk":"11928945574","pt":1724257130025,"mc":[{"id":"1.232092849","rc":[{"batb":[[0,1.35,6.12],[1,1.34,25.18]],"ltp":0.0,"tv":0.0,"id":6847357}]}]}
{"op":"mcm","clk":"11928998792","pt":1724257535260,"mc":[{"id":"1.232092849","rc":[{"batb":[[0,1.35,11.91],[2,1.21,83.31]],"ltp":0.0,"tv":0.0,"id":6847357},{"batb":[[1,1.35,6.81],[2,1.34,25.18]],"ltp":0.0,"tv":0.0,"id":19587212}]}]}
{"op":"mcm","clk":"11929057342","pt":1724257971615,"mc":[{"id":"1.232092849","rc":[{"batb":[[2,1.22,25.23]],"ltp":0.0,"tv":0.0,"id":6847357}]}]}
{"op":"mcm","clk":"11929061578","pt":1724258000383,"mc":[{"id":"1.232092849","rc":[{"batb":[[1,1.22,25.23],[2,1.21,83.31]],"ltp":0.0,"tv":0.0,"id":6847357},{"batb":[[2,1.21,83.31]],"ltp":0.0,"tv":0.0,"id":19587212}]}]}
{"op":"mcm","clk":"11929085331","pt":1724258144825,"mc":[{"id":"1.232092849","rc":[{"batb":[[0,1.36,23.78],[1,1.35,11.91],[2,1.22,25.23]],"ltp":0.0,"tv":0.0,"id":6847357},{"batb":[[0,1.54,15.86],[1,1.53,6.12],[2,1.35,6.81]],"ltp":0.0,"tv":0.0,"id":19587212}]}]}
{"op":"mcm","clk":"11929321039","pt":1724259652341,"mc":[{"id":"1.232092849","rc":[{"batb":[[0,1.36,23.77],[1,1.35,11.89],[2,1.22,25.21]],"ltp":0.0,"tv":0.0,"id":6847357},{"batb":[[0,1.54,15.85],[1,1.53,6.11],[2,1.22,6.8]],"ltp":0.0,"tv":0.0,"id":19587212}]}]}
{"op":"mcm","clk":"11929321126","pt":1724259652893,"mc":[{"id":"1.232092849","rc":[{"batb":[[1,1.35,6.11],[2,1.23,5.78]],"ltp":0.0,"tv":0.0,"id":6847357}]}]}
{"op":"mcm","clk":"11929376806","pt":1724259955246,"mc":[{"id":"1.232092849","rc":[{"batb":[[0,1.35,6.11],[1,1.23,5.78],[2,1.22,25.21]],"ltp":0.0,"tv":0.0,"id":6847357},{"batb":[[0,1.53,6.11],[1,1.22,6.8],[2,1.21,83.2]],"ltp":0.0,"tv":0.0,"id":19587212}]}]}
{"op":"mcm","clk":"11929402192","pt":1724260096227,"mc":[{"id":"1.232092849","rc":[{"batb":[[0,1.36,23.77],[1,1.35,6.11],[2,1.23,5.78]],"ltp":0.0,"tv":0.0,"id":6847357},{"batb":[[0,1.54,15.85],[1,1.53,6.11],[2,1.22,6.8]],"ltp":0.0,"tv":0.0,"id":19587212}]}]}
{"op":"mcm","clk":"11929483499","pt":1724260490789,"mc":[{"id":"1.232092849","rc":[{"batb":[[0,1.58,6.11],[1,1.54,15.85]],"ltp":0.0,"tv":0.0,"id":19587212}]}]}
{"op":"mcm","clk":"11929483914","pt":1724260493192,"mc":[{"id":"1.232092849","rc":[{"batb":[[0,1.37,6.11],[1,1.36,23.77]],"ltp":0.0,"tv":0.0,"id":6847357}]}]}
{"op":"mcm","clk":"11929675510","pt":1724261692137,"mc":[{"id":"1.232092849","rc":[{"batb":[[2,1.21,83.2]],"ltp":0.0,"tv":0.0,"id":19587212}]}]}
{"op":"mcm","clk":"11929695882","pt":1724261817087,"mc":[{"id":"1.232092849","rc":[{"batb":[[0,1.36,23.77],[1,1.23,5.78],[2,1.21,83.2]],"ltp":0.0,"tv":0.0,"id":6847357},{"batb":[[0,1.54,15.85],[1,1.21,83.2],[2,1.04,1.53]],"ltp":0.0,"tv":0.0,"id":19587212}]}]}
{"op":"mcm","clk":"11929709107","pt":1724261896461,"mc":[{"id":"1.232092849","rc":[{"batb":[[0,1.23,5.78],[1,1.21,83.2],[2,1.04,1.53]],"ltp":0.0,"tv":0.0,"id":6847357}]}]}
{"op":"mcm","clk":"11929709134","pt":1724261896654,"mc":[{"id":"1.232092849","rc":[{"batb":[[0,1.21,83.2],[1,1.04,1.53],[2,1.03,200]],"ltp":0.0,"tv":0.0,"id":19587212}]}]}
{"op":"mcm","clk":"11929728283","pt":1724262010024,"mc":[{"id":"1.232092849","rc":[{"batb":[[0,1.24,35.65],[1,1.23,5.78],[2,1.21,83.2]],"ltp":0.0,"tv":0.0,"id":6847357},{"batb":[[0,1.22,38.9],[1,1.21,83.2],[2,1.04,1.53]],"ltp":0.0,"tv":0.0,"id":19587212}]}]}
{"op":"mcm","clk":"11929747392","pt":1724262120496,"mc":[{"id":"1.232092849","rc":[{"batb":[[0,1.57,64.7],[1,1.24,35.65],[2,1.23,5.78]],"ltp":0.0,"tv":0.0,"id":6847357},{"batb":[[0,2.6,23.05],[1,1.22,38.9],[2,1.21,83.2]],"ltp":0.0,"tv":0.0,"id":19587212}]}]}
{"op":"mcm","clk":"11929979661","pt":1724263689727,"mc":[{"id":"1.232092849","rc":[{"batb":[[1,1.24,35.67],[2,1.21,83.24]],"ltp":0.0,"tv":0.0,"id":6847357},{"batb":[[1,1.22,38.91],[2,1.21,83.24]],"ltp":0.0,"tv":0.0,"id":19587212}]}]}
{"op":"mcm","clk":"11930001198","pt":1724263810531,"mc":[{"id":"1.232092849","rc":[{"batb":[[1,1.21,83.24],[2,1.04,1.53]],"ltp":0.0,"tv":0.0,"id":6847357},{"batb":[[1,1.21,83.24],[2,1.04,1.53]],"ltp":0.0,"tv":0.0,"id":19587212}]}]}
{"op":"mcm","clk":"11930797671","pt":1724269257643,"mc":[{"id":"1.232092849","rc":[{"batb":[[1,1.21,83.23]],"ltp":0.0,"tv":0.0,"id":6847357},{"batb":[[1,1.45,42.58],[2,1.21,83.23]],"ltp":0.0,"tv":0.0,"id":19587212}]}]}
{"op":"mcm","clk":"11930997204","pt":1724271174853,"mc":[{"id":"1.232092849","rc":[{"batb":[[1,1.21,83.31]],"ltp":0.0,"tv":0.0,"id":6847357},{"batb":[[1,1.45,42.6],[2,1.21,83.31]],"ltp":0.0,"tv":0.0,"id":19587212}]}]}
{"op":"mcm","clk":"11931369461","pt":1724275518865,"mc":[{"id":"1.232092849","rc":[{"batb":[[0,1.59,62.51],[1,1.21,83.33]],"ltp":0.0,"tv":0.0,"id":6847357},{"batb":[[0,2.54,23.95],[1,1.45,42.59],[2,1.21,83.33]],"ltp":0.0,"tv":0.0,"id":19587212}]}]}
{"op":"mcm","clk":"11931702808","pt":1724280388187,"mc":[{"id":"1.232092849","rc":[{"batb":[[1,1.21,83.27]],"ltp":0.0,"tv":0.0,"id":6847357},{"batb":[[1,1.45,42.57],[2,1.21,83.27]],"ltp":0.0,"tv":0.0,"id":19587212}]}]}
{"op":"mcm","clk":"11931812089","pt":1724281974913,"mc":[{"id":"1.232092849","rc":[{"batb":[[1,1.21,83.29]],"ltp":0.0,"tv":0.0,"id":6847357},{"batb":[[1,1.45,42.6],[2,1.21,83.29]],"ltp":0.0,"tv":0.0,"id":19587212}]}]}
{"op":"mcm","clk":"11932256471","pt":1724287374880,"mc":[{"id":"1.232092849","rc":[{"batb":[[1,1.21,83.31]],"ltp":0.0,"tv":0.0,"id":6847357},{"batb":[[1,1.45,42.6],[2,1.21,83.31]],"ltp":0.0,"tv":0.0,"id":19587212}]}]}
{"op":"mcm","clk":"11932630942","pt":1724292774869,"mc":[{"id":"1.232092849","rc":[{"batb":[[1,1.21,83.23]],"ltp":0.0,"tv":0.0,"id":6847357},{"batb":[[1,1.45,42.58],[2,1.21,83.23]],"ltp":0.0,"tv":0.0,"id":19587212}]}]}
{"op":"mcm","clk":"11932927130","pt":1724298174875,"mc":[{"id":"1.232092849","rc":[{"batb":[[1,1.21,83.22]],"ltp":0.0,"tv":0.0,"id":6847357},{"batb":[[2,1.21,83.22]],"ltp":0.0,"tv":0.0,"id":19587212}]}]}
{"op":"mcm","clk":"11932937363","pt":1724298230080,"mc":[{"id":"1.232092849","rc":[{"batb":[[0,1.57,64.7]],"ltp":0.0,"tv":0.0,"id":6847357},{"batb":[[0,2.62,22.76]],"ltp":0.0,"tv":0.0,"id":19587212}]}]}
{"op":"mcm","clk":"11933172489","pt":1724302569183,"mc":[{"id":"1.232092849","rc":[{"batb":[[0,1.21,83.22],[1,1.04,1.53],[2,1.03,200]],"ltp":0.0,"tv":0.0,"id":6847357},{"batb":[[0,1.45,42.58],[1,1.21,83.22],[2,1.04,1.53]],"ltp":0.0,"tv":0.0,"id":19587212}]}]}
{"op":"mcm","clk":"11933172578","pt":1724302569687,"mc":[{"id":"1.232092849","rc":[{"batb":[[0,1.57,64.7],[1,1.21,83.22],[2,1.04,1.53]],"ltp":0.0,"tv":0.0,"id":6847357},{"batb":[[0,2.62,22.76],[1,1.45,42.58],[2,1.21,83.22]],"ltp":0.0,"tv":0.0,"id":19587212}]}]}
{"op":"mcm","clk":"11933211152","pt":1724303269487,"mc":[{"id":"1.232092849","rc":[{"batb":[[1,1.21,83.23]],"ltp":0.0,"tv":0.0,"id":6847357},{"batb":[[1,1.9,6.18],[2,1.45,42.59]],"batl":[[0,3.65,3.6]],"ltp":0.0,"tv":0.0,"id":19587212}]}]}
{"op":"mcm","clk":"11933220047","pt":1724303437536,"mc":[{"id":"1.232092849","rc":[{"trd":[[1.57,2]],"batb":[[0,1.57,63.7]],"ltp":1.57,"tv":2.0,"id":6847357}],"tv":2.0}]}
{"op":"mcm","clk":"11933220297","pt":1724303442539,"mc":[{"id":"1.232092849","rc":[{"batb":[[0,1.57,64.7]],"ltp":1.57,"tv":2.0,"id":6847357}]}]}
{"op":"mcm","clk":"11933263557","pt":1724304170519,"mc":[{"id":"1.232092849","rc":[{"trd":[[1.57,2.7]],"batb":[[0,1.57,64.35]],"ltp":1.57,"tv":2.7,"id":6847357}],"tv":2.7}]}
{"op":"mcm","clk":"11933263759","pt":1724304174560,"mc":[{"id":"1.232092849","rc":[{"batb":[[0,1.57,64.7]],"ltp":1.57,"tv":2.7,"id":6847357}]}]}
{"op":"mcm","clk":"11933296146","pt":1724304769646,"mc":[{"id":"1.232092849","rc":[{"batb":[[0,1.21,83.23],[1,1.04,1.53],[2,1.03,200]],"ltp":1.57,"tv":2.7,"id":6847357},{"batb":[[0,1.9,6.18],[1,1.45,42.59],[2,1.21,83.23]],"ltp":0.0,"tv":0.0,"id":19587212}]}]}
{"op":"mcm","clk":"11933296446","pt":1724304771255,"mc":[{"id":"1.232092849","rc":[{"batb":[[0,1.57,64.7],[1,1.21,83.23],[2,1.04,1.53]],"ltp":1.57,"tv":2.7,"id":6847357},{"batb":[[0,2.62,22.76],[1,1.9,6.18],[2,1.45,42.59]],"ltp":0.0,"tv":0.0,"id":19587212}]}]}
{"op":"mcm","clk":"11933337814","pt":1724305647452,"mc":[{"id":"1.232092849","rc":[{"batb":[[1,2.4,41.18],[2,1.9,6.18]],"ltp":0.0,"tv":0.0,"id":19587212}]}]}
{"op":"mcm","clk":"11933338273","pt":1724305657442,"mc":[{"id":"1.232092849","rc":[{"batb":[[1,1.5,41.18],[2,1.21,83.23]],"ltp":1.57,"tv":2.7,"id":6847357}]}]}
{"op":"mcm","clk":"11933484732","pt":1724308974850,"mc":[{"id":"1.232092849","rc":[{"batb":[[2,1.21,83.23]],"ltp":1.57,"tv":2.7,"id":6847357},{"batb":[[2,1.9,6.18]],"batl":[[0,3.65,3.61]],"ltp":0.0,"tv":0.0,"id":19587212}]}]}
{"op":"mcm","clk":"11933536385","pt":1724310323472,"mc":[{"id":"1.232092849","rc":[{"trd":[[1.57,132.11]],"batb":[[0,1.5,41.16],[1,1.21,83.25],[2,1.04,1.53]],"batl":[[0,1.55,321.57]],"ltp":1.57,"tv":132.1,"id":6847357},{"batb":[[1,2.4,41.16],[2,1.9,6.18]],"batl":[[0,3.65,3.6]],"ltp":0.0,"tv":0.0,"id":19587212}],"tv":132.1}]}
{"op":"mcm","clk":"11933536462","pt":1724310325885,"mc":[{"id":"1.232092849","rc":[{"batb":[[0,1.53,69.59],[1,1.5,41.16],[2,1.21,83.25]],"ltp":1.57,"tv":132.1,"id":6847357}]}]}
{"op":"mcm","clk":"11933548435","pt":1724310657580,"mc":[{"id":"1.232092849","rc":[{"trd":[[1.53,139.18]],"batb":[[0,1.5,41.16],[1,1.21,83.25],[2,1.04,1.53]],"batl":[[0,1.53,251.98]],"ltp":1.53,"tv":271.28,"id":6847357}],"tv":271.28}]}
{"op":"mcm","clk":"11933548557","pt":1724310661976,"mc":[{"id":"1.232092849","rc":[{"batb":[[1,1.49,75.27],[2,1.21,83.25]],"ltp":1.53,"tv":271.28,"id":6847357}]}]}
{"op":"mcm","clk":"11933549258","pt":1724310686923,"mc":[{"id":"1.232092849","rc":[{"batb":[[2,1.38,9.93]],"ltp":1.53,"tv":271.28,"id":6847357}]}]}
{"op":"mcm","clk":"11933549393","pt":1724310691413,"mc":[{"id":"1.232092849","rc":[{"batb":[[2,1.98,9.17]],"ltp":0.0,"tv":0.0,"id":19587212}]}]}
{"op":"mcm","clk":"11933549428","pt":1724310692235,"mc":[{"id":"1.232092849","rc":[{"batb":[[2,1.98,15.34]],"ltp":0.0,"tv":0.0,"id":19587212}]}]}
{"op":"mcm","clk":"11933559989","pt":1724310989600,"mc":[{"id":"1.232092849","rc":[{"batl":[[0,2.98,1.71],[1,3.65,3.6]],"ltp":0.0,"tv":0.0,"id":19587212}]}]}
{"op":"mcm","clk":"11933617966","pt":1724312701485,"mc":[{"id":"1.232092849","rc":[{"batb":[[1,1.49,111.77]],"ltp":1.53,"tv":271.28,"id":6847357},{"batb":[[1,2.6,11.18],[2,2.4,41.16]],"ltp":0.0,"tv":0.0,"id":19587212}]}]}
{"op":"mcm","clk":"11933619884","pt":1724312753516,"mc":[{"id":"1.232092849","rc":[{"batb":[[0,1.52,7.1],[1,1.5,76.92],[2,1.49,111.77]],"ltp":1.53,"tv":271.28,"id":6847357}]}]}
{"op":"mcm","clk":"11933627160","pt":1724312991761,"mc":[{"id":"1.232092849","rc":[{"batb":[[1,1.5,41.16],[2,1.49,75.27]],"ltp":1.53,"tv":271.28,"id":6847357},{"batb":[[1,2.4,41.16],[2,1.98,15.34]],"ltp":0.0,"tv":0.0,"id":19587212}]}]}
{"op":"mcm","clk":"11933627267","pt":1724312994171,"mc":[{"id":"1.232092849","rc":[{"batb":[[1,1.5,76.92]],"ltp":1.53,"tv":271.28,"id":6847357},{"batb":[[1,2.6,11.18],[2,2.4,41.16]],"ltp":0.0,"tv":0.0,"id":19587212}]}]}
{"op":"mcm","clk":"11933627302","pt":1724312995140,"mc":[{"id":"1.232092849","rc":[{"batb":[[1,1.5,41.16],[2,1.49,111.77]],"ltp":1.53,"tv":271.28,"id":6847357}]}]}
{"op":"mcm","clk":"11933627382","pt":1724312997138,"mc":[{"id":"1.232092849","rc":[{"batb":[[1,1.5,76.92]],"ltp":1.53,"tv":271.28,"id":6847357}]}]}
{"op":"mcm","clk":"11933661640","pt":1724313912992,"mc":[{"id":"1.232092849","rc":[{"trd":[[1.53,139.08],[1.57,132.01]],"batb":[[0,1.52,7.1],[1,1.5,76.86],[2,1.49,111.72]],"batl":[[0,1.62,25.77]],"ltp":1.53,"tv":271.09,"id":6847357},{"batb":[[1,2.6,11.16],[2,2.4,41.14]],"batl":[[0,2.98,1.71],[1,3.65,3.61]],"ltp":0.0,"tv":0.0,"id":19587212}],"tv":271.09}]}
{"op":"mcm","clk":"11933662178","pt":1724313933428,"mc":[{"id":"1.232092849","rc":[{"batl":[[1,1.7,25.77]],"ltp":1.53,"tv":271.09,"id":6847357}]}]}
{"op":"mcm","clk":"11933670235","pt":1724314201928,"mc":[{"id":"1.232092849","rc":[{"batl":[[0,1.56,2],[1,1.62,25.77],[2,1.7,25.77]],"ltp":1.53,"tv":271.09,"id":6847357}]}]}
{"op":"mcm","clk":"11933670283","pt":1724314202804,"mc":[{"id":"1.232092849","rc":[{"batb":[[0,2.62,33.78]],"ltp":0.0,"tv":0.0,"id":19587212}]}]}
{"op":"mcm","clk":"11933671115","pt":1724314227025,"mc":[{"id":"1.232092849","rc":[{"batl":[[0,1.53,3],[1,1.56,2],[2,1.62,25.77]],"ltp":1.53,"tv":271.09,"id":6847357}]}]}
{"op":"mcm","clk":"11933675744","pt":1724314374025,"mc":[{"id":"1.232092849","rc":[{"trd":[[1.53,145.08]],"batb":[[0,1.53,4.1]],"batl":[[0,1.56,2],[1,1.62,25.77],[2,1.7,25.77]],"ltp":1.53,"tv":277.09,"id":6847357}],"tv":277.09}]}
{"op":"mcm","clk":"11933725641","pt":1724315447086,"mc":[{"id":"1.232092849","rc":[{"batl":[[2,4.5,0.89]],"ltp":0.0,"tv":0.0,"id":19587212}]}]}
{"op":"mcm","clk":"11933726378","pt":1724315466641,"mc":[{"id":"1.232092849","rc":[{"batl":[[2,10,1.06]],"ltp":0.0,"tv":0.0,"id":19587212}]}]}
{"op":"mcm","clk":"11933735050","pt":1724315714962,"mc":[{"id":"1.232092849","rc":[{"trd":[[1.56,0.17]],"batl":[[0,1.56,1.83]],"ltp":1.56,"tv":277.26,"id":6847357},{"trd":[[2.78,0.1]],"batb":[[0,2.64,14],[1,2.62,33.78],[2,2.6,11.16]],"ltp":2.78,"tv":0.09,"id":19587212}],"tv":277.36}]}
{"op":"mcm","clk":"11933735140","pt":1724315717348,"mc":[{"id":"1.232092849","rc":[{"batb":[[0,2.64,20.88]],"ltp":2.78,"tv":0.09,"id":19587212}]}]}
{"op":"mcm","clk":"11933735182","pt":1724315718339,"mc":[{"id":"1.232092849","rc":[{"batb":[[0,2.62,33.78],[1,2.6,11.16],[2,2.4,41.14]],"ltp":2.78,"tv":0.09,"id":19587212}]}]}
{"op":"mcm","clk":"11933735264","pt":1724315721172,"mc":[{"id":"1.232092849","rc":[{"batb":[[0,2.64,14],[1,2.62,33.78],[2,2.6,11.16]],"ltp":2.78,"tv":0.09,"id":19587212}]}]}
{"op":"mcm","clk":"11933735381","pt":1724315724253,"mc":[{"id":"1.232092849","rc":[{"trd":[[1.53,145.27]],"batb":[[0,1.53,3.91]],"ltp":1.53,"tv":277.44,"id":6847357},{"trd":[[2.9,0.1]],"batb":[[0,2.64,10]],"ltp":2.9,"tv":0.19,"id":19587212}],"tv":277.64}]}
{"op":"mcm","clk":"11933735396","pt":1724315724770,"mc":[{"id":"1.232092849","rc":[{"batb":[[0,2.62,33.78],[1,2.6,11.16],[2,2.4,41.14]],"ltp":2.9,"tv":0.19,"id":19587212}]}]}
{"op":"mcm","clk":"11933735441","pt":1724315726463,"mc":[{"id":"1.232092849","rc":[{"batb":[[0,2.64,4],[1,2.62,33.78],[2,2.6,11.16]],"ltp":2.9,"tv":0.19,"id":19587212}]}]}
{"op":"mcm","clk":"11933735491","pt":1724315727592,"mc":[{"id":"1.232092849","rc":[{"batb":[[0,2.66,10],[1,2.64,4],[2,2.62,33.78]],"ltp":2.9,"tv":0.19,"id":19587212}]}]}
{"op":"mcm","clk":"11933735540","pt":1724315728774,"mc":[{"id":"1.232092849","rc":[{"batb":[[1,2.62,33.78],[2,2.6,11.16]],"ltp":2.9,"tv":0.19,"id":19587212}]}]}
{"op":"mcm","clk":"11933735640","pt":1724315731083,"mc":[{"id":"1.232092849","rc":[{"batb":[[0,2.64,4]],"ltp":2.9,"tv":0.19,"id":19587212}]}]}
{"op":"mcm","clk":"11933735731","pt":1724315733501,"mc":[{"id":"1.232092849","rc":[{"batb":[[0,2.64,10]],"ltp":2.9,"tv":0.19,"id":19587212}]}]}
{"op":"mcm","clk":"11933735869","pt":1724315736798,"mc":[{"id":"1.232092849","rc":[{"batb":[[0,2.64,4]],"ltp":2.9,"tv":0.19,"id":19587212}]}]}
{"op":"mcm","clk":"11933735937","pt":1724315739112,"mc":[{"id":"1.232092849","rc":[{"batb":[[0,2.66,10]],"ltp":2.9,"tv":0.19,"id":19587212}]}]}
{"op":"mcm","clk":"11933736036","pt":1724315742392,"mc":[{"id":"1.232092849","rc":[{"batb":[[0,2.62,33.78],[1,2.6,11.16],[2,2.4,41.14]],"ltp":2.9,"tv":0.19,"id":19587212}]}]}
{"op":"mcm","clk":"11933736044","pt":1724315742599,"mc":[{"id":"1.232092849","rc":[{"batb":[[0,2.64,4],[1,2.62,33.78],[2,2.6,11.16]],"ltp":2.9,"tv":0.19,"id":19587212}]}]}
{"op":"mcm","clk":"11933736118","pt":1724315745278,"mc":[{"id":"1.232092849","rc":[{"batb":[[0,2.64,10]],"ltp":2.9,"tv":0.19,"id":19587212}]}]}
{"op":"mcm","clk":"11933736221","pt":1724315747804,"mc":[{"id":"1.232092849","rc":[{"batb":[[0,2.66,4],[1,2.64,10],[2,2.62,33.78]],"ltp":2.9,"tv":0.19,"id":19587212}]}]}
{"op":"mcm","clk":"11933736248","pt":1724315748626,"mc":[{"id":"1.232092849","rc":[{"batb":[[1,2.62,33.78],[2,2.6,11.16]],"ltp":2.9,"tv":0.19,"id":19587212}]}]}
{"op":"mcm","clk":"11933736331","pt":1724315750322,"mc":[{"id":"1.232092849","rc":[{"batb":[[0,2.62,33.78],[1,2.6,11.16],[2,2.4,41.14]],"ltp":2.9,"tv":0.19,"id":19587212}]}]}
{"op":"mcm","clk":"11933736425","pt":1724315752896,"mc":[{"id":"1.232092849","rc":[{"batb":[[0,2.64,14],[1,2.62,33.78],[2,2.6,11.16]],"ltp":2.9,"tv":0.19,"id":19587212}]}]}
{"op":"mcm","clk":"11933736493","pt":1724315755319,"mc":[{"id":"1.232092849","rc":[{"batb":[[0,2.64,20.88]],"ltp":2.9,"tv":0.19,"id":19587212}]}]}
{"op":"mcm","clk":"11933736524","pt":1724315756198,"mc":[{"id":"1.232092849","rc":[{"batb":[[0,2.62,33.78],[1,2.6,11.16],[2,2.4,41.14]],"ltp":2.9,"tv":0.19,"id":19587212}]}]}
{"op":"mcm","clk":"11933736674","pt":1724315762022,"mc":[{"id":"1.232092849","rc":[{"batb":[[0,2.64,14],[1,2.62,33.78],[2,2.6,11.16]],"ltp":2.9,"tv":0.19,"id":19587212}]}]}
{"op":"mcm","clk":"11933736749","pt":1724315764544,"mc":[{"id":"1.232092849","rc":[{"batb":[[0,2.64,20.88]],"ltp":2.9,"tv":0.19,"id":19587212}]}]}
{"op":"mcm","clk":"11933736783","pt":1724315765422,"mc":[{"id":"1.232092849","rc":[{"batb":[[0,2.62,33.78],[1,2.6,11.16],[2,2.4,41.14]],"ltp":2.9,"tv":0.19,"id":19587212}]}]}
{"op":"mcm","clk":"11933736870","pt":1724315767937,"mc":[{"id":"1.232092849","rc":[{"batb":[[0,2.64,14],[1,2.62,33.78],[2,2.6,11.16]],"ltp":2.9,"tv":0.19,"id":19587212}]}]}
{"op":"mcm","clk":"11933736949","pt":1724315770459,"mc":[{"id":"1.232092849","rc":[{"batb":[[0,2.64,20.88]],"ltp":2.9,"tv":0.19,"id":19587212}]}]}
{"op":"mcm","clk":"11933736994","pt":1724315771236,"mc":[{"id":"1.232092849","rc":[{"batb":[[0,2.62,33.78],[1,2.6,11.16],[2,2.4,41.14]],"ltp":2.9,"tv":0.19,"id":19587212}]}]}
{"op":"mcm","clk":"11933737112","pt":1724315774948,"mc":[{"id":"1.232092849","rc":[{"batb":[[0,2.64,14],[1,2.62,33.78],[2,2.6,11.16]],"ltp":2.9,"tv":0.19,"id":19587212}]}]}
{"op":"mcm","clk":"11933737185","pt":1724315777158,"mc":[{"id":"1.232092849","rc":[{"batb":[[0,2.64,20.88]],"ltp":2.9,"tv":0.19,"id":19587212}]}]}
{"op":"mcm","clk":"11933737220","pt":1724315778235,"mc":[{"id":"1.232092849","rc":[{"batb":[[0,2.62,33.78],[1,2.6,11.16],[2,2.4,41.14]],"ltp":2.9,"tv":0.19,"id":19587212}]}]}
{"op":"mcm","clk":"11933737275","pt":1724315779772,"mc":[{"id":"1.232092849","rc":[{"batb":[[0,2.64,4],[1,2.62,33.78],[2,2.6,11.16]],"ltp":2.9,"tv":0.19,"id":19587212}]}]}
{"op":"mcm","clk":"11933737369","pt":1724315782341,"mc":[{"id":"1.232092849","rc":[{"batb":[[0,2.64,10]],"ltp":2.9,"tv":0.19,"id":19587212}]}]}
{"op":"mcm","clk":"11933737441","pt":1724315784654,"mc":[{"id":"1.232092849","rc":[{"batb":[[0,2.66,4],[1,2.64,10],[2,2.62,33.78]],"ltp":2.9,"tv":0.19,"id":19587212}]}]}
{"op":"mcm","clk":"11933737486","pt":1724315785951,"mc":[{"id":"1.232092849","rc":[{"batb":[[1,2.62,33.78],[2,2.6,11.16]],"ltp":2.9,"tv":0.19,"id":19587212}]}]}
{"op":"mcm","clk":"11933737537","pt":1724315787137,"mc":[{"id":"1.232092849","rc":[{"batb":[[0,2.62,33.78],[1,2.6,11.16],[2,2.4,41.14]],"ltp":2.9,"tv":0.19,"id":19587212}]}]}
{"op":"mcm","clk":"11933737633","pt":1724315790686,"mc":[{"id":"1.232092849","rc":[{"batb":[[0,2.64,14],[1,2.62,33.78],[2,2.6,11.16]],"ltp":2.9,"tv":0.19,"id":19587212}]}]}
{"op":"mcm","clk":"11933737709","pt":1724315793354,"mc":[{"id":"1.232092849","rc":[{"batb":[[0,2.64,10]],"ltp":2.9,"tv":0.19,"id":19587212}]}]}
{"op":"mcm","clk":"11933737734","pt":1724315793967,"mc":[{"id":"1.232092849","rc":[{"batb":[[0,2.62,33.78],[1,2.6,11.16],[2,2.4,41.14]],"ltp":2.9,"tv":0.19,"id":19587212}]}]}
{"op":"mcm","clk":"11933737772","pt":1724315795352,"mc":[{"id":"1.232092849","rc":[{"batb":[[0,2.64,4],[1,2.62,33.78],[2,2.6,11.16]],"ltp":2.9,"tv":0.19,"id":19587212}]}]}
{"op":"mcm","clk":"11933737819","pt":1724315796387,"mc":[{"id":"1.232092849","rc":[{"batb":[[0,2.66,10],[1,2.64,4],[2,2.62,33.78]],"ltp":2.9,"tv":0.19,"id":19587212}]}]}
{"op":"mcm","clk":"11933737863","pt":1724315797770,"mc":[{"id":"1.232092849","rc":[{"batb":[[1,2.62,33.78],[2,2.6,11.16]],"ltp":2.9,"tv":0.19,"id":19587212}]}]}
{"op":"mcm","clk":"11933737913","pt":1724315799562,"mc":[{"id":"1.232092849","rc":[{"batb":[[0,2.62,33.78],[1,2.6,11.16],[2,2.4,41.14]],"ltp":2.9,"tv":0.19,"id":19587212}]}]}
{"op":"mcm","clk":"11933738031","pt":1724315802391,"mc":[{"id":"1.232092849","rc":[{"batb":[[0,2.64,14],[1,2.62,33.78],[2,2.6,11.16]],"ltp":2.9,"tv":0.19,"id":19587212}]}]}
{"op":"mcm","clk":"11933738113","pt":1724315805372,"mc":[{"id":"1.232092849","rc":[{"batb":[[0,2.64,10]],"ltp":2.9,"tv":0.19,"id":19587212}]}]}
{"op":"mcm","clk":"11933738138","pt":1724315805888,"mc":[{"id":"1.232092849","rc":[{"batb":[[0,2.62,33.78],[1,2.6,11.16],[2,2.4,41.14]],"ltp":2.9,"tv":0.19,"id":19587212}]}]}
{"op":"mcm","clk":"11933738193","pt":1724315808106,"mc":[{"id":"1.232092849","rc":[{"batb":[[0,2.64,14],[1,2.62,33.78],[2,2.6,11.16]],"ltp":2.9,"tv":0.19,"id":19587212}]}]}
{"op":"mcm","clk":"11933738258","pt":1724315810571,"mc":[{"id":"1.232092849","rc":[{"batb":[[0,2.64,20.88]],"ltp":2.9,"tv":0.19,"id":19587212}]}]}
{"op":"mcm","clk":"11933738275","pt":1724315810873,"mc":[{"id":"1.232092849","rc":[{"batb":[[0,2.64,10]],"ltp":2.9,"tv":0.19,"id":19587212}]}]}
{"op":"mcm","clk":"11933738301","pt":1724315811595,"mc":[{"id":"1.232092849","rc":[{"batb":[[0,2.62,33.78],[1,2.6,11.16],[2,2.4,41.14]],"ltp":2.9,"tv":0.19,"id":19587212}]}]}
{"op":"mcm","clk":"11933738341","pt":1724315812671,"mc":[{"id":"1.232092849","rc":[{"batb":[[0,2.64,4],[1,2.62,33.78],[2,2.6,11.16]],"ltp":2.9,"tv":0.19,"id":19587212}]}]}
{"op":"mcm","clk":"11933738436","pt":1724315815200,"mc":[{"id":"1.232092849","rc":[{"batb":[[0,2.66,10]],"ltp":2.9,"tv":0.19,"id":19587212}]}]}
{"op":"mcm","clk":"11933738490","pt":1724315817379,"mc":[{"id":"1.232092849","rc":[{"batb":[[0,2.68,4],[1,2.66,10],[2,2.62,33.78]],"ltp":2.9,"tv":0.19,"id":19587212}]}]}
{"op":"mcm","clk":"11933738513","pt":1724315818096,"mc":[{"id":"1.232092849","rc":[{"batb":[[1,2.62,33.78],[2,2.6,11.16]],"ltp":2.9,"tv":0.19,"id":19587212}]}]}
{"op":"mcm","clk":"11933738593","pt":1724315819897,"mc":[{"id":"1.232092849","rc":[{"batb":[[0,2.62,33.78],[1,2.6,11.16],[2,2.4,41.14]],"ltp":2.9,"tv":0.19,"id":19587212}]}]}
{"op":"mcm","clk":"11933738668","pt":1724315821705,"mc":[{"id":"1.232092849","rc":[{"batb":[[0,2.64,10],[1,2.62,33.78],[2,2.6,11.16]],"ltp":2.9,"tv":0.19,"id":19587212}]}]}
{"op":"mcm","clk":"11933738705","pt":1724315822886,"mc":[{"id":"1.232092849","rc":[{"batb":[[0,2.66,4],[1,2.64,10],[2,2.62,33.78]],"ltp":2.9,"tv":0.19,"id":19587212}]}]}
{"op":"mcm","clk":"11933738776","pt":1724315825214,"mc":[{"id":"1.232092849","rc":[{"batb":[[0,2.64,10.88],[1,2.62,33.78],[2,2.6,11.16]],"ltp":2.9,"tv":0.19,"id":19587212}]}]}
{"op":"mcm","clk":"11933738786","pt":1724315825885,"mc":[{"id":"1.232092849","rc":[{"batb":[[0,2.62,33.78],[1,2.6,11.16],[2,2.4,41.14]],"ltp":2.9,"tv":0.19,"id":19587212}]}]}
{"op":"mcm","clk":"11933738835","pt":1724315827580,"mc":[{"id":"1.232092849","rc":[{"batb":[[0,2.64,10],[1,2.62,33.78],[2,2.6,11.16]],"ltp":2.9,"tv":0.19,"id":19587212}]}]}
{"op":"mcm","clk":"11933738842","pt":1724315827735,"mc":[{"id":"1.232092849","rc":[{"batb":[[0,2.64,14]],"ltp":2.9,"tv":0.19,"id":19587212}]}]}
{"op":"mcm","clk":"11933738927","pt":1724315830202,"mc":[{"id":"1.232092849","rc":[{"batb":[[0,2.64,20.88]],"ltp":2.9,"tv":0.19,"id":19587212}]}]}
{"op":"mcm","clk":"11933738954","pt":1724315831023,"mc":[{"id":"1.232092849","rc":[{"batb":[[0,2.62,33.78],[1,2.6,11.16],[2,2.4,41.14]],"ltp":2.9,"tv":0.19,"id":19587212}]}]}
{"op":"mcm","clk":"11933739043","pt":1724315833337,"mc":[{"id":"1.232092849","rc":[{"batb":[[0,2.64,14],[1,2.62,33.78],[2,2.6,11.16]],"ltp":2.9,"tv":0.19,"id":19587212}]}]}
{"op":"mcm","clk":"11933739111","pt":1724315836307,"mc":[{"id":"1.232092849","rc":[{"batb":[[0,2.64,10]],"ltp":2.9,"tv":0.19,"id":19587212}]}]}
{"op":"mcm","clk":"11933739132","pt":1724315836820,"mc":[{"id":"1.232092849","rc":[{"batb":[[0,2.62,33.78],[1,2.6,11.16],[2,2.4,41.14]],"ltp":2.9,"tv":0.19,"id":19587212}]}]}
{"op":"mcm","clk":"11933739183","pt":1724315839130,"mc":[{"id":"1.232092849","rc":[{"batb":[[0,2.64,14],[1,2.62,33.78],[2,2.6,11.16]],"ltp":2.9,"tv":0.19,"id":19587212}]}]}
{"op":"mcm","clk":"11933739267","pt":1724315841437,"mc":[{"id":"1.232092849","rc":[{"batb":[[0,2.64,20.88]],"ltp":2.9,"tv":0.19,"id":19587212}]}]}
{"op":"mcm","clk":"11933739318","pt":1724315842510,"mc":[{"id":"1.232092849","rc":[{"batb":[[0,2.62,33.78],[1,2.6,11.16],[2,2.4,41.14]],"ltp":2.9,"tv":0.19,"id":19587212}]}]}
{"op":"mcm","clk":"11933739387","pt":1724315844504,"mc":[{"id":"1.232092849","rc":[{"batb":[[0,2.64,4],[1,2.62,33.78],[2,2.6,11.16]],"ltp":2.9,"tv":0.19,"id":19587212}]}]}
{"op":"mcm","clk":"11933739449","pt":1724315846125,"mc":[{"id":"1.232092849","rc":[{"batb":[[0,2.66,10],[1,2.64,4],[2,2.62,33.78]],"ltp":2.9,"tv":0.19,"id":19587212}]}]}
{"op":"mcm","clk":"11933739472","pt":1724315846842,"mc":[{"id":"1.232092849","rc":[{"batb":[[1,2.62,33.78],[2,2.6,11.16]],"ltp":2.9,"tv":0.19,"id":19587212}]}]}
{"op":"mcm","clk":"11933739523","pt":1724315849413,"mc":[{"id":"1.232092849","rc":[{"batb":[[0,2.68,4]],"ltp":2.9,"tv":0.19,"id":19587212}]}]}
{"op":"mcm","clk":"11933739572","pt":1724315851721,"mc":[{"id":"1.232092849","rc":[{"batb":[[0,2.64,10]],"ltp":2.9,"tv":0.19,"id":19587212}]}]}
{"op":"mcm","clk":"11933739617","pt":1724315853820,"mc":[{"id":"1.232092849","rc":[{"batb":[[0,2.66,4],[1,2.64,10],[2,2.62,33.78]],"ltp":2.9,"tv":0.19,"id":19587212}]}]}
{"op":"mcm","clk":"11933739652","pt":1724315855153,"mc":[{"id":"1.232092849","rc":[{"batb":[[1,2.62,33.78],[2,2.6,11.16]],"ltp":2.9,"tv":0.19,"id":19587212}]}]}
{"op":"mcm","clk":"11933739680","pt":1724315856340,"mc":[{"id":"1.232092849","rc":[{"batb":[[0,2.62,33.78],[1,2.6,11.16],[2,2.4,41.14]],"ltp":2.9,"tv":0.19,"id":19587212}]}]}
{"op":"mcm","clk":"11933739882","pt":1724315861351,"mc":[{"id":"1.232092849","rc":[{"batb":[[0,2.64,14],[1,2.62,33.78],[2,2.6,11.16]],"ltp":2.9,"tv":0.19,"id":19587212}]}]}
{"op":"mcm","clk":"11933739993","pt":1724315864373,"mc":[{"id":"1.232092849","rc":[{"batb":[[0,2.64,10]],"ltp":2.9,"tv":0.19,"id":19587212}]}]}
{"op":"mcm","clk":"11933740011","pt":1724315864733,"mc":[{"id":"1.232092849","rc":[{"batb":[[0,2.62,33.78],[1,2.6,11.16],[2,2.4,41.14]],"ltp":2.9,"tv":0.19,"id":19587212}]}]}
{"op":"mcm","clk":"11933740073","pt":1724315866166,"mc":[{"id":"1.232092849","rc":[{"batb":[[0,2.64,4],[1,2.62,33.78],[2,2.6,11.16]],"ltp":2.9,"tv":0.19,"id":19587212}]}]}
{"op":"mcm","clk":"11933740107","pt":1724315867348,"mc":[{"id":"1.232092849","rc":[{"batb":[[0,2.66,10],[1,2.64,4],[2,2.62,33.78]],"ltp":2.9,"tv":0.19,"id":19587212}]}]}
{"op":"mcm","clk":"11933740146","pt":1724315868582,"mc":[{"id":"1.232092849","rc":[{"batb":[[1,2.62,33.78],[2,2.6,11.16]],"ltp":2.9,"tv":0.19,"id":19587212}]}]}
{"op":"mcm","clk":"11933740237","pt":1724315870847,"mc":[{"id":"1.232092849","rc":[{"batb":[[0,2.64,4]],"ltp":2.9,"tv":0.19,"id":19587212}]}]}
{"op":"mcm","clk":"11933740310","pt":1724315873168,"mc":[{"id":"1.232092849","rc":[{"batb":[[0,2.64,10]],"ltp":2.9,"tv":0.19,"id":19587212}]}]}
{"op":"mcm","clk":"11933740402","pt":1724315876459,"mc":[{"id":"1.232092849","rc":[{"batb":[[0,2.66,4]],"ltp":2.9,"tv":0.19,"id":19587212}]}]}
{"op":"mcm","clk":"11933740445","pt":1724315878305,"mc":[{"id":"1.232092849","rc":[{"batb":[[0,2.62,33.78],[1,2.6,11.16],[2,2.4,41.14]],"ltp":2.9,"tv":0.19,"id":19587212}]}]}
{"op":"mcm","clk":"11933740476","pt":1724315879789,"mc":[{"id":"1.232092849","rc":[{"batb":[[0,2.64,10],[1,2.62,33.78],[2,2.6,11.16]],"ltp":2.9,"tv":0.19,"id":19587212}]}]}
{"op":"mcm","clk":"11933740550","pt":1724315881796,"mc":[{"id":"1.232092849","rc":[{"batb":[[0,2.66,4],[1,2.64,10],[2,2.62,33.78]],"ltp":2.9,"tv":0.19,"id":19587212}]}]}
{"op":"mcm","clk":"11933740592","pt":1724315883079,"mc":[{"id":"1.232092849","rc":[{"batb":[[1,2.62,33.78],[2,2.6,11.16]],"ltp":2.9,"tv":0.19,"id":19587212}]}]}
{"op":"mcm","clk":"11933740636","pt":1724315884274,"mc":[{"id":"1.232092849","rc":[{"batb":[[0,2.62,33.78],[1,2.6,11.16],[2,2.4,41.14]],"ltp":2.9,"tv":0.19,"id":19587212}]}]}
{"op":"mcm","clk":"11933740700","pt":1724315886180,"mc":[{"id":"1.232092849","rc":[{"batb":[[0,2.64,10],[1,2.62,33.78],[2,2.6,11.16]],"ltp":2.9,"tv":0.19,"id":19587212}]}]}
{"op":"mcm","clk":"11933740749","pt":1724315887672,"mc":[{"id":"1.232092849","rc":[{"batb":[[0,2.66,4],[1,2.64,10],[2,2.62,33.78]],"ltp":2.9,"tv":0.19,"id":19587212}]}]}
{"op":"mcm","clk":"11933740833","pt":1724315889516,"mc":[{"id":"1.232092849","rc":[{"batb":[[1,2.62,33.78],[2,2.6,11.16]],"ltp":2.9,"tv":0.19,"id":19587212}]}]}
{"op":"mcm","clk":"11933740846","pt":1724315890087,"mc":[{"id":"1.232092849","rc":[{"batb":[[0,2.62,33.78],[1,2.6,11.16],[2,2.4,41.14]],"ltp":2.9,"tv":0.19,"id":19587212}]}]}
{"op":"mcm","clk":"11933740909","pt":1724315892415,"mc":[{"id":"1.232092849","rc":[{"batb":[[0,2.64,14],[1,2.62,33.78],[2,2.6,11.16]],"ltp":2.9,"tv":0.19,"id":19587212}]}]}
{"op":"mcm","clk":"11933740993","pt":1724315895419,"mc":[{"id":"1.232092849","rc":[{"batb":[[0,2.64,10]],"ltp":2.9,"tv":0.19,"id":19587212}]}]}
{"op":"mcm","clk":"11933741010","pt":1724315895827,"mc":[{"id":"1.232092849","rc":[{"batb":[[0,2.62,33.78],[1,2.6,11.16],[2,2.4,41.14]],"ltp":2.9,"tv":0.19,"id":19587212}]}]}
{"op":"mcm","clk":"11933741039","pt":1724315896908,"mc":[{"id":"1.232092849","rc":[{"batb":[[0,2.64,4],[1,2.62,33.78],[2,2.6,11.16]],"ltp":2.9,"tv":0.19,"id":19587212}]}]}
{"op":"mcm","clk":"11933741085","pt":1724315898188,"mc":[{"id":"1.232092849","rc":[{"batb":[[0,2.66,10],[1,2.64,4],[2,2.62,33.78]],"ltp":2.9,"tv":0.19,"id":19587212}]}]}
{"op":"mcm","clk":"11933741114","pt":1724315899110,"mc":[{"id":"1.232092849","rc":[{"batb":[[1,2.62,33.78],[2,2.6,11.16]],"ltp":2.9,"tv":0.19,"id":19587212}]}]}
{"op":"mcm","clk":"11933741175","pt":1724315901526,"mc":[{"id":"1.232092849","rc":[{"batb":[[0,2.68,4]],"ltp":2.9,"tv":0.19,"id":19587212}]}]}
{"op":"mcm","clk":"11933741246","pt":1724315904198,"mc":[{"id":"1.232092849","rc":[{"batb":[[0,2.64,10]],"ltp":2.9,"tv":0.19,"id":19587212}]}]}
{"op":"mcm","clk":"11933741369","pt":1724315907431,"mc":[{"id":"1.232092849","rc":[{"batb":[[0,2.66,4]],"ltp":2.9,"tv":0.19,"id":19587212}]}]}
{"op":"mcm","clk":"11933741428","pt":1724315909522,"mc":[{"id":"1.232092849","rc":[{"batb":[[0,2.62,33.78],[1,2.6,11.16],[2,2.4,41.14]],"ltp":2.9,"tv":0.19,"id":19587212}]}]}
{"op":"mcm","clk":"11933741433","pt":1724315909627,"mc":[{"id":"1.232092849","rc":[{"batb":[[0,2.64,10],[1,2.62,33.78],[2,2.6,11.16]],"ltp":2.9,"tv":0.19,"id":19587212}]}]}
{"op":"mcm","clk":"11933741503","pt":1724315911735,"mc":[{"id":"1.232092849","rc":[{"batb":[[0,2.66,4],[1,2.64,10],[2,2.62,33.78]],"ltp":2.9,"tv":0.19,"id":19587212}]}]}
{"op":"mcm","clk":"11933741542","pt":1724315912914,"mc":[{"id":"1.232092849","rc":[{"batb":[[1,2.62,33.78],[2,2.6,11.16]],"ltp":2.9,"tv":0.19,"id":19587212}]}]}
{"op":"mcm","clk":"11933741572","pt":1724315914246,"mc":[{"id":"1.232092849","rc":[{"batb":[[0,2.62,33.78],[1,2.6,11.16],[2,2.4,41.14]],"ltp":2.9,"tv":0.19,"id":19587212}]}]}
{"op":"mcm","clk":"11933741605","pt":1724315915431,"mc":[{"id":"1.232092849","rc":[{"batb":[[0,2.64,10],[1,2.62,33.78],[2,2.6,11.16]],"ltp":2.9,"tv":0.19,"id":19587212}]}]}
{"op":"mcm","clk":"11933741638","pt":1724315916561,"mc":[{"id":"1.232092849","rc":[{"batb":[[0,2.66,4],[1,2.64,10],[2,2.62,33.78]],"ltp":2.9,"tv":0.19,"id":19587212}]}]}
{"op":"mcm","clk":"11933741744","pt":1724315919442,"mc":[{"id":"1.232092849","rc":[{"batb":[[0,2.62,33.78],[1,2.6,11.16],[2,2.4,41.14]],"ltp":2.9,"tv":0.19,"id":19587212}]}]}
{"op":"mcm","clk":"11933741806","pt":1724315921237,"mc":[{"id":"1.232092849","rc":[{"batb":[[0,2.64,14],[1,2.62,33.78],[2,2.6,11.16]],"ltp":2.9,"tv":0.19,"id":19587212}]}]}
{"op":"mcm","clk":"11933741899","pt":1724315924323,"mc":[{"id":"1.232092849","rc":[{"batb":[[0,2.64,10]],"ltp":2.9,"tv":0.19,"id":19587212}]}]}
{"op":"mcm","clk":"11933741912","pt":1724315924634,"mc":[{"id":"1.232092849","rc":[{"batb":[[0,2.62,33.78],[1,2.6,11.16],[2,2.4,41.14]],"ltp":2.9,"tv":0.19,"id":19587212}]}]}
{"op":"mcm","clk":"11933741979","pt":1724315926937,"mc":[{"id":"1.232092849","rc":[{"batb":[[0,2.64,14],[1,2.62,33.78],[2,2.6,11.16]],"ltp":2.9,"tv":0.19,"id":19587212}]}]}
{"op":"mcm","clk":"11933742048","pt":1724315929457,"mc":[{"id":"1.232092849","rc":[{"batb":[[0,2.64,20.88]],"ltp":2.9,"tv":0.19,"id":19587212}]}]}
{"op":"mcm","clk":"11933742081","pt":1724315930436,"mc":[{"id":"1.232092849","rc":[{"batb":[[0,2.62,33.78],[1,2.6,11.16],[2,2.4,41.14]],"ltp":2.9,"tv":0.19,"id":19587212}]}]}
{"op":"mcm","clk":"11933742123","pt":1724315931668,"mc":[{"id":"1.232092849","rc":[{"batb":[[0,2.64,4],[1,2.62,33.78],[2,2.6,11.16]],"ltp":2.9,"tv":0.19,"id":19587212}]}]}
{"op":"mcm","clk":"11933742172","pt":1724315932955,"mc":[{"id":"1.232092849","rc":[{"batb":[[0,2.66,10],[1,2.64,4],[2,2.62,33.78]],"ltp":2.9,"tv":0.19,"id":19587212}]}]}
{"op":"mcm","clk":"11933742203","pt":1724315934040,"mc":[{"id":"1.232092849","rc":[{"batb":[[1,2.62,33.78],[2,2.6,11.16]],"ltp":2.9,"tv":0.19,"id":19587212}]}]}
{"op":"mcm","clk":"11933742286","pt":1724315936457,"mc":[{"id":"1.232092849","rc":[{"batb":[[0,2.68,4]],"ltp":2.9,"tv":0.19,"id":19587212}]}]}
{"op":"mcm","clk":"11933742381","pt":1724315938978,"mc":[{"id":"1.232092849","rc":[{"batb":[[0,2.64,10]],"ltp":2.9,"tv":0.19,"id":19587212}]}]}
{"op":"mcm","clk":"11933742510","pt":1724315942282,"mc":[{"id":"1.232092849","rc":[{"batb":[[0,2.66,4]],"ltp":2.9,"tv":0.19,"id":19587212}]}]}
{"op":"mcm","clk":"11933742584","pt":1724315944863,"mc":[{"id":"1.232092849","rc":[{"batb":[[0,2.64,10]],"ltp":2.9,"tv":0.19,"id":19587212}]}]}
{"op":"mcm","clk":"11933742731","pt":1724315948475,"mc":[{"id":"1.232092849","rc":[{"batb":[[0,2.64,4]],"ltp":2.9,"tv":0.19,"id":19587212}]}]}
{"op":"mcm","clk":"11933742788","pt":1724315950274,"mc":[{"id":"1.232092849","rc":[{"batb":[[2,1.49,36.45]],"ltp":1.53,"tv":277.44,"id":6847357},{"batb":[[0,2.64,26.48],[1,2.62,11.02]],"ltp":2.9,"tv":0.19,"id":19587212}]}]}
{"op":"mcm","clk":"11933742817","pt":1724315950889,"mc":[{"id":"1.232092849","rc":[{"batb":[[0,2.66,10],[1,2.64,22.48],[2,2.62,11.02]],"ltp":2.9,"tv":0.19,"id":19587212}]}]}
{"op":"mcm","clk":"11933742905","pt":1724315952956,"mc":[{"id":"1.232092849","rc":[{"batb":[[0,2.68,4],[1,2.66,10],[2,2.64,33.36]],"ltp":2.9,"tv":0.19,"id":19587212}]}]}
{"op":"mcm","clk":"11933742946","pt":1724315954288,"mc":[{"id":"1.232092849","rc":[{"batb":[[1,2.64,33.36],[2,2.62,11.02]],"ltp":2.9,"tv":0.19,"id":19587212}]}]}
{"op":"mcm","clk":"11933742981","pt":1724315955258,"mc":[{"id":"1.232092849","rc":[{"batb":[[0,2.64,33.36],[1,2.62,11.02],[2,2.6,11.16]],"ltp":2.9,"tv":0.19,"id":19587212}]}]}
{"op":"mcm","clk":"11933743092","pt":1724315958089,"mc":[{"id":"1.232092849","rc":[{"batb":[[0,2.66,14],[1,2.64,33.36],[2,2.62,11.02]],"ltp":2.9,"tv":0.19,"id":19587212}]}]}
{"op":"mcm","clk":"11933743172","pt":1724315960397,"mc":[{"id":"1.232092849","rc":[{"batb":[[0,2.66,20.76]],"ltp":2.9,"tv":0.19,"id":19587212}]}]}
{"op":"mcm","clk":"11933743207","pt":1724315961474,"mc":[{"id":"1.232092849","rc":[{"batb":[[0,2.64,33.36],[1,2.62,11.02],[2,2.6,11.16]],"ltp":2.9,"tv":0.19,"id":19587212}]}]}
{"op":"mcm","clk":"11933743246","pt":1724315962700,"mc":[{"id":"1.232092849","rc":[{"batb":[[0,2.66,4],[1,2.64,33.36],[2,2.62,11.02]],"ltp":2.9,"tv":0.19,"id":19587212}]}]}
{"op":"mcm","clk":"11933743296","pt":1724315964397,"mc":[{"id":"1.232092849","rc":[{"batb":[[0,2.68,10],[1,2.66,4],[2,2.64,33.36]],"ltp":2.9,"tv":0.19,"id":19587212}]}]}
{"op":"mcm","clk":"11933743321","pt":1724315964859,"mc":[{"id":"1.232092849","rc":[{"batb":[[1,2.64,33.36],[2,2.62,11.02]],"ltp":2.9,"tv":0.19,"id":19587212}]}]}
{"op":"mcm","clk":"11933743394","pt":1724315967280,"mc":[{"id":"1.232092849","rc":[{"batb":[[0,2.7,4],[1,2.68,10],[2,2.64,33.36]],"ltp":2.9,"tv":0.19,"id":19587212}]}]}
{"op":"mcm","clk":"11933743402","pt":1724315967791,"mc":[{"id":"1.232092849","rc":[{"batb":[[1,2.64,33.36],[2,2.62,11.02]],"ltp":2.9,"tv":0.19,"id":19587212}]}]}
{"op":"mcm","clk":"11933743484","pt":1724315969972,"mc":[{"id":"1.232092849","rc":[{"batb":[[0,2.66,10]],"ltp":2.9,"tv":0.19,"id":19587212}]}]}
{"op":"mcm","clk":"11933743562","pt":1724315972288,"mc":[{"id":"1.232092849","rc":[{"batb":[[0,2.68,4],[1,2.66,10],[2,2.64,33.36]],"ltp":2.9,"tv":0.19,"id":19587212}]}]}
{"op":"mcm","clk":"11933743590","pt":1724315973310,"mc":[{"id":"1.232092849","rc":[{"batb":[[1,2.64,33.36],[2,2.62,11.02]],"ltp":2.9,"tv":0.19,"id":19587212}]}]}
{"op":"mcm","clk":"11933743631","pt":1724315974805,"mc":[{"id":"1.232092849","rc":[{"batb":[[0,2.64,33.36],[1,2.62,11.02],[2,2.6,11.16]],"ltp":2.9,"tv":0.19,"id":19587212}]}]}
{"op":"mcm","clk":"11933743674","pt":1724315975980,"mc":[{"id":"1.232092849","rc":[{"batb":[[0,2.66,10],[1,2.64,33.36],[2,2.62,11.02]],"ltp":2.9,"tv":0.19,"id":19587212}]}]}
{"op":"mcm","clk":"11933743717","pt":1724315977114,"mc":[{"id":"1.232092849","rc":[{"batb":[[0,2.68,4],[1,2.66,10],[2,2.64,33.36]],"ltp":2.9,"tv":0.19,"id":19587212}]}]}
{"op":"mcm","clk":"11933743791","pt":1724315979511,"mc":[{"id":"1.232092849","rc":[{"batb":[[0,2.64,33.36],[1,2.62,11.02],[2,2.6,11.16]],"ltp":2.9,"tv":0.19,"id":19587212}]}]}
{"op":"mcm","clk":"11933744032","pt":1724315985113,"mc":[{"id":"1.232092849","rc":[{"batb":[[0,2.66,14],[1,2.64,33.36],[2,2.62,11.02]],"ltp":2.9,"tv":0.19,"id":19587212}]}]}
{"op":"mcm","clk":"11933744129","pt":1724315987322,"mc":[{"id":"1.232092849","rc":[{"batb":[[0,2.66,20.76]],"ltp":2.9,"tv":0.19,"id":19587212}]}]}
{"op":"mcm","clk":"11933744147","pt":1724315987938,"mc":[{"id":"1.232092849","rc":[{"batb":[[0,2.66,10]],"ltp":2.9,"tv":0.19,"id":19587212}]}]}
{"op":"mcm","clk":"11933744189","pt":1724315988717,"mc":[{"id":"1.232092849","rc":[{"batb":[[0,2.64,33.36],[1,2.62,11.02],[2,2.6,11.16]],"ltp":2.9,"tv":0.19,"id":19587212}]}]}
{"op":"mcm","clk":"11933744249","pt":1724315990058,"mc":[{"id":"1.232092849","rc":[{"batb":[[0,2.66,4],[1,2.64,33.36],[2,2.62,11.02]],"ltp":2.9,"tv":0.19,"id":19587212}]}]}
{"op":"mcm","clk":"11933744379","pt":1724315992541,"mc":[{"id":"1.232092849","rc":[{"batb":[[0,2.64,33.36],[1,2.62,11.02],[2,2.6,11.16]],"ltp":2.9,"tv":0.19,"id":19587212}]}]}
{"op":"mcm","clk":"11933744384","pt":1724315992640,"mc":[{"id":"1.232092849","rc":[{"batb":[[0,2.66,10],[1,2.64,33.36],[2,2.62,11.02]],"ltp":2.9,"tv":0.19,"id":19587212}]}]}
{"op":"mcm","clk":"11933744505","pt":1724315995947,"mc":[{"id":"1.232092849","rc":[{"batb":[[0,2.66,4]],"ltp":2.9,"tv":0.19,"id":19587212}]}]}
{"op":"mcm","clk":"11933744583","pt":1724315998154,"mc":[{"id":"1.232092849","rc":[{"batb":[[0,2.64,33.36],[1,2.62,11.02],[2,2.6,11.16]],"ltp":2.9,"tv":0.19,"id":19587212}]}]}
{"op":"mcm","clk":"11933744640","pt":1724315999843,"mc":[{"id":"1.232092849","rc":[{"batb":[[0,2.66,10],[1,2.64,33.36],[2,2.62,11.02]],"ltp":2.9,"tv":0.19,"id":19587212}]}]}
{"op":"mcm","clk":"11933744699","pt":1724316001030,"mc":[{"id":"1.232092849","rc":[{"batb":[[0,2.68,4],[1,2.66,10],[2,2.64,33.36]],"ltp":2.9,"tv":0.19,"id":19587212}]}]}
{"op":"mcm","clk":"11933744786","pt":1724316003452,"mc":[{"id":"1.232092849","rc":[{"batb":[[0,2.66,10.76],[1,2.64,33.36],[2,2.62,11.02]],"ltp":2.9,"tv":0.19,"id":19587212}]}]}
{"op":"mcm","clk":"11933744806","pt":1724316003963,"mc":[{"id":"1.232092849","rc":[{"batb":[[0,2.64,33.36],[1,2.62,11.02],[2,2.6,11.16]],"ltp":2.9,"tv":0.19,"id":19587212}]}]}
{"op":"mcm","clk":"11933744890","pt":1724316005866,"mc":[{"id":"1.232092849","rc":[{"batb":[[0,2.66,14],[1,2.64,33.36],[2,2.62,11.02]],"ltp":2.9,"tv":0.19,"id":19587212}]}]}
{"op":"mcm","clk":"11933744977","pt":1724316008371,"mc":[{"id":"1.232092849","rc":[{"batb":[[0,2.66,20.76]],"ltp":2.9,"tv":0.19,"id":19587212}]}]}
{"op":"mcm","clk":"11933745008","pt":1724316009037,"mc":[{"id":"1.232092849","rc":[{"batb":[[0,2.64,33.36],[1,2.62,11.02],[2,2.6,11.16]],"ltp":2.9,"tv":0.19,"id":19587212}]}]}
{"op":"mcm","clk":"11933745146","pt":1724316012738,"mc":[{"id":"1.232092849","rc":[{"batb":[[0,2.66,14],[1,2.64,33.36],[2,2.62,11.02]],"ltp":2.9,"tv":0.19,"id":19587212}]}]}
{"op":"mcm","clk":"11933745238","pt":1724316015356,"mc":[{"id":"1.232092849","rc":[{"batb":[[0,2.66,20.76]],"ltp":2.9,"tv":0.19,"id":19587212}]}]}
{"op":"mcm","clk":"11933745268","pt":1724316016177,"mc":[{"id":"1.232092849","rc":[{"batb":[[0,2.64,33.36],[1,2.62,11.02],[2,2.6,11.16]],"ltp":2.9,"tv":0.19,"id":19587212}]}]}
{"op":"mcm","clk":"11933745328","pt":1724316017664,"mc":[{"id":"1.232092849","rc":[{"batb":[[0,2.66,4],[1,2.64,33.36],[2,2.62,11.02]],"ltp":2.9,"tv":0.19,"id":19587212}]}]}
{"op":"mcm","clk":"11933745376","pt":1724316018845,"mc":[{"id":"1.232092849","rc":[{"batb":[[0,2.68,10],[1,2.66,4],[2,2.64,33.36]],"ltp":2.9,"tv":0.19,"id":19587212}]}]}
{"op":"mcm","clk":"11933745415","pt":1724316019986,"mc":[{"id":"1.232092849","rc":[{"batb":[[1,2.64,33.36],[2,2.62,11.02]],"ltp":2.9,"tv":0.19,"id":19587212}]}]}
{"op":"mcm","clk":"11933745496","pt":1724316022446,"mc":[{"id":"1.232092849","rc":[{"batb":[[0,2.66,4]],"ltp":2.9,"tv":0.19,"id":19587212}]}]}
{"op":"mcm","clk":"11933745594","pt":1724316024966,"mc":[{"id":"1.232092849","rc":[{"batb":[[0,2.66,10]],"ltp":2.9,"tv":0.19,"id":19587212}]}]}
{"op":"mcm","clk":"11933745736","pt":1724316028551,"mc":[{"id":"1.232092849","rc":[{"batb":[[0,2.66,4]],"ltp":2.9,"tv":0.19,"id":19587212}]}]}
{"op":"mcm","clk":"11933745830","pt":1724316031068,"mc":[{"id":"1.232092849","rc":[{"batb":[[0,2.66,10]],"ltp":2.9,"tv":0.19,"id":19587212}]}]}
{"op":"mcm","clk":"11933745932","pt":1724316034510,"mc":[{"id":"1.232092849","rc":[{"batb":[[0,2.66,4]],"ltp":2.9,"tv":0.19,"id":19587212}]}]}
{"op":"mcm","clk":"11933746026","pt":1724316036875,"mc":[{"id":"1.232092849","rc":[{"batb":[[0,2.66,10]],"ltp":2.9,"tv":0.19,"id":19587212}]}]}
{"op":"mcm","clk":"11933746110","pt":1724316039278,"mc":[{"id":"1.232092849","rc":[{"batb":[[0,2.68,4],[1,2.66,10],[2,2.64,33.36]],"ltp":2.9,"tv":0.19,"id":19587212}]}]}
{"op":"mcm","clk":"11933746137","pt":1724316040096,"mc":[{"id":"1.232092849","rc":[{"batb":[[1,2.64,33.36],[2,2.62,11.02]],"ltp":2.9,"tv":0.19,"id":19587212}]}]}
{"op":"mcm","clk":"11933746188","pt":1724316041581,"mc":[{"id":"1.232092849","rc":[{"batb":[[0,2.64,33.36],[1,2.62,11.02],[2,2.6,11.16]],"ltp":2.9,"tv":0.19,"id":19587212}]}]}
{"op":"mcm","clk":"11933746222","pt":1724316042704,"mc":[{"id":"1.232092849","rc":[{"batb":[[0,2.66,10],[1,2.64,33.36],[2,2.62,11.02]],"ltp":2.9,"tv":0.19,"id":19587212}]}]}
{"op":"mcm","clk":"11933746354","pt":1724316046090,"mc":[{"id":"1.232092849","rc":[{"batb":[[0,2.68,4]],"ltp":2.9,"tv":0.19,"id":19587212}]}]}
{"op":"mcm","clk":"11933746459","pt":1724316048511,"mc":[{"id":"1.232092849","rc":[{"batb":[[0,2.64,33.36],[1,2.62,11.02],[2,2.6,11.16]],"ltp":2.9,"tv":0.19,"id":19587212}]}]}
{"op":"mcm","clk":"11933746475","pt":1724316048822,"mc":[{"id":"1.232092849","rc":[{"batb":[[0,2.66,10],[1,2.64,33.36],[2,2.62,11.02]],"ltp":2.9,"tv":0.19,"id":19587212}]}]}
{"op":"mcm","clk":"11933746600","pt":1724316052103,"mc":[{"id":"1.232092849","rc":[{"batb":[[0,2.68,4]],"ltp":2.9,"tv":0.19,"id":19587212}]}]}
{"op":"mcm","clk":"11933746695","pt":1724316054723,"mc":[{"id":"1.232092849","rc":[{"batb":[[0,2.66,10]],"ltp":2.9,"tv":0.19,"id":19587212}]}]}
{"op":"mcm","clk":"11933746831","pt":1724316058219,"mc":[{"id":"1.232092849","rc":[{"batb":[[0,2.66,4]],"ltp":2.9,"tv":0.19,"id":19587212}]}]}
{"op":"mcm","clk":"11933746943","pt":1724316060801,"mc":[{"id":"1.232092849","rc":[{"batb":[[0,2.66,10]],"ltp":2.9,"tv":0.19,"id":19587212}]}]}
{"op":"mcm","clk":"11933747082","pt":1724316064415,"mc":[{"id":"1.232092849","rc":[{"batb":[[0,2.66,4]],"ltp":2.9,"tv":0.19,"id":19587212}]}]}
{"op":"mcm","clk":"11933747214","pt":1724316066802,"mc":[{"id":"1.232092849","rc":[{"batb":[[0,2.66,10]],"ltp":2.9,"tv":0.19,"id":19587212}]}]}
{"op":"mcm","clk":"11933747325","pt":1724316070246,"mc":[{"id":"1.232092849","rc":[{"batb":[[0,2.68,4]],"ltp":2.9,"tv":0.19,"id":19587212}]}]}
{"op":"mcm","clk":"11933747393","pt":1724316072455,"mc":[{"id":"1.232092849","rc":[{"batb":[[0,2.64,33.36],[1,2.62,11.02],[2,2.6,11.16]],"ltp":2.9,"tv":0.19,"id":19587212}]}]}
{"op":"mcm","clk":"11933747407","pt":1724316072611,"mc":[{"id":"1.232092849","rc":[{"batb":[[0,2.66,10],[1,2.64,33.36],[2,2.62,11.02]],"ltp":2.9,"tv":0.19,"id":19587212}]}]}
{"op":"mcm","clk":"11933747540","pt":1724316076045,"mc":[{"id":"1.232092849","rc":[{"batb":[[0,2.68,4]],"ltp":2.9,"tv":0.19,"id":19587212}]}]}
{"op":"mcm","clk":"11933747625","pt":1724316078351,"mc":[{"id":"1.232092849","rc":[{"batb":[[0,2.7,10]],"ltp":2.9,"tv":0.19,"id":19587212}]}]}
{"op":"mcm","clk":"11933747736","pt":1724316081265,"mc":[{"id":"1.232092849","rc":[{"batb":[[0,2.72,4],[1,2.7,10],[2,2.64,33.36]],"ltp":2.9,"tv":0.19,"id":19587212}]}]}
{"op":"mcm","clk":"11933747750","pt":1724316081633,"mc":[{"id":"1.232092849","rc":[{"batb":[[1,2.64,33.36],[2,2.62,11.02]],"ltp":2.9,"tv":0.19,"id":19587212}]}]}
{"op":"mcm","clk":"11933747836","pt":1724316083534,"mc":[{"id":"1.232092849","rc":[{"batb":[[0,2.64,33.36],[1,2.62,11.02],[2,2.6,11.16]],"ltp":2.9,"tv":0.19,"id":19587212}]}]}
{"op":"mcm","clk":"11933747855","pt":1724316083953,"mc":[{"id":"1.232092849","rc":[{"batb":[[0,2.74,10],[1,2.64,33.36],[2,2.62,11.02]],"ltp":2.9,"tv":0.19,"id":19587212}]}]}
{"op":"mcm","clk":"11933747946","pt":1724316086165,"mc":[{"id":"1.232092849","rc":[{"batb":[[0,2.76,4],[1,2.74,10],[2,2.64,33.36]],"ltp":2.9,"tv":0.19,"id":19587212}]}]}
{"op":"mcm","clk":"11933748001","pt":1724316087447,"mc":[{"id":"1.232092849","rc":[{"batb":[[1,2.64,33.36],[2,2.62,11.02]],"ltp":2.9,"tv":0.19,"id":19587212}]}]}
{"op":"mcm","clk":"11933748048","pt":1724316088420,"mc":[{"id":"1.232092849","rc":[{"batb":[[0,2.64,33.36],[1,2.62,11.02],[2,2.6,11.16]],"ltp":2.9,"tv":0.19,"id":19587212}]}]}
{"op":"mcm","clk":"11933748113","pt":1724316089957,"mc":[{"id":"1.232092849","rc":[{"batb":[[0,2.66,10],[1,2.64,33.36],[2,2.62,11.02]],"ltp":2.9,"tv":0.19,"id":19587212}]}]}
{"op":"mcm","clk":"11933748188","pt":1724316091753,"mc":[{"id":"1.232092849","rc":[{"batb":[[0,2.68,4],[1,2.66,10],[2,2.64,33.36]],"ltp":2.9,"tv":0.19,"id":19587212}]}]}
{"op":"mcm","clk":"11933748245","pt":1724316093235,"mc":[{"id":"1.232092849","rc":[{"batb":[[1,2.64,33.36],[2,2.62,11.02]],"ltp":2.9,"tv":0.19,"id":19587212}]}]}
{"op":"mcm","clk":"11933748284","pt":1724316094271,"mc":[{"id":"1.232092849","rc":[{"batb":[[0,2.64,33.36],[1,2.62,11.02],[2,2.6,11.16]],"ltp":2.9,"tv":0.19,"id":19587212}]}]}
{"op":"mcm","clk":"11933748453","pt":1724316097975,"mc":[{"id":"1.232092849","rc":[{"batb":[[0,2.66,14],[1,2.64,33.36],[2,2.62,11.02]],"ltp":2.9,"tv":0.19,"id":19587212}]}]}
{"op":"mcm","clk":"11933748558","pt":1724316100440,"mc":[{"id":"1.232092849","rc":[{"batb":[[0,2.66,20.76]],"ltp":2.9,"tv":0.19,"id":19587212}]}]}
{"op":"mcm","clk":"11933748599","pt":1724316101469,"mc":[{"id":"1.232092849","rc":[{"batb":[[0,2.64,33.36],[1,2.62,11.02],[2,2.6,11.16]],"ltp":2.9,"tv":0.19,"id":19587212}]}]}
{"op":"mcm","clk":"11933748649","pt":1724316102653,"mc":[{"id":"1.232092849","rc":[{"batb":[[0,2.66,4],[1,2.64,33.36],[2,2.62,11.02]],"ltp":2.9,"tv":0.19,"id":19587212}]}]}
{"op":"mcm","clk":"11933748750","pt":1724316105165,"mc":[{"id":"1.232092849","rc":[{"batb":[[0,2.66,10]],"ltp":2.9,"tv":0.19,"id":19587212}]}]}
{"op":"mcm","clk":"11933748893","pt":1724316108348,"mc":[{"id":"1.232092849","rc":[{"batb":[[0,2.68,4]],"ltp":2.9,"tv":0.19,"id":19587212}]}]}
{"op":"mcm","clk":"11933748989","pt":1724316110863,"mc":[{"id":"1.232092849","rc":[{"batb":[[0,2.66,10]],"ltp":2.9,"tv":0.19,"id":19587212}]}]}
{"op":"mcm","clk":"11933749068","pt":1724316113166,"mc":[{"id":"1.232092849","rc":[{"batb":[[0,2.68,4],[1,2.66,10],[2,2.64,33.36]],"ltp":2.9,"tv":0.19,"id":19587212}]}]}
{"op":"mcm","clk":"11933749108","pt":1724316114139,"mc":[{"id":"1.232092849","rc":[{"batb":[[1,2.64,33.36],[2,2.62,11.02]],"ltp":2.9,"tv":0.19,"id":19587212}]}]}
{"op":"mcm","clk":"11933749163","pt":1724316115575,"mc":[{"id":"1.232092849","rc":[{"batb":[[0,2.64,33.36],[1,2.62,11.02],[2,2.6,11.16]],"ltp":2.9,"tv":0.19,"id":19587212}]}]}
{"op":"mcm","clk":"11933749214","pt":1724316116854,"mc":[{"id":"1.232092849","rc":[{"batb":[[0,2.66,10],[1,2.64,33.36],[2,2.62,11.02]],"ltp":2.9,"tv":0.19,"id":19587212}]}]}
{"op":"mcm","clk":"11933749252","pt":1724316118082,"mc":[{"id":"1.232092849","rc":[{"batb":[[0,2.68,4],[1,2.66,10],[2,2.64,33.36]],"ltp":2.9,"tv":0.19,"id":19587212}]}]}
{"op":"mcm","clk":"11933749342","pt":1724316120552,"mc":[{"id":"1.232092849","rc":[{"batb":[[0,2.64,33.36],[1,2.62,11.02],[2,2.6,11.16]],"ltp":2.9,"tv":0.19,"id":19587212}]}]}
{"op":"mcm","clk":"11933749427","pt":1724316122771,"mc":[{"id":"1.232092849","rc":[{"batb":[[0,2.68,4],[1,2.66,10],[2,2.64,33.36]],"ltp":2.9,"tv":0.19,"id":19587212}]}]}
{"op":"mcm","clk":"11933749538","pt":1724316125562,"mc":[{"id":"1.232092849","rc":[{"batb":[[0,2.66,10],[1,2.64,33.36],[2,2.62,11.02]],"ltp":2.9,"tv":0.19,"id":19587212}]}]}
{"op":"mcm","clk":"11933749560","pt":1724316126077,"mc":[{"id":"1.232092849","rc":[{"batb":[[0,2.64,33.36],[1,2.62,11.02],[2,2.6,11.16]],"ltp":2.9,"tv":0.19,"id":19587212}]}]}
{"op":"mcm","clk":"11933749683","pt":1724316128802,"mc":[{"id":"1.232092849","rc":[{"batb":[[0,2.66,14],[1,2.64,33.36],[2,2.62,11.02]],"ltp":2.9,"tv":0.19,"id":19587212}]}]}
{"op":"mcm","clk":"11933749774","pt":1724316131578,"mc":[{"id":"1.232092849","rc":[{"batb":[[0,2.66,10]],"ltp":2.9,"tv":0.19,"id":19587212}]}]}
{"op":"mcm","clk":"11933749787","pt":1724316132293,"mc":[{"id":"1.232092849","rc":[{"batb":[[0,2.64,33.36],[1,2.62,11.02],[2,2.6,11.16]],"ltp":2.9,"tv":0.19,"id":19587212}]}]}
{"op":"mcm","clk":"11933749826","pt":1724316133673,"mc":[{"id":"1.232092849","rc":[{"batb":[[0,2.66,4],[1,2.64,33.36],[2,2.62,11.02]],"ltp":2.9,"tv":0.19,"id":19587212}]}]}
{"op":"mcm","clk":"11933749899","pt":1724316136079,"mc":[{"id":"1.232092849","rc":[{"batb":[[0,2.66,10]],"ltp":2.9,"tv":0.19,"id":19587212}]}]}
{"op":"mcm","clk":"11933750014","pt":1724316139405,"mc":[{"id":"1.232092849","rc":[{"batb":[[0,2.64,33.36],[1,2.62,11.02],[2,2.6,11.16]],"ltp":2.9,"tv":0.19,"id":19587212}]}]}
{"op":"mcm","clk":"11933750021","pt":1724316139609,"mc":[{"id":"1.232092849","rc":[{"batb":[[0,2.66,4],[1,2.64,33.36],[2,2.62,11.02]],"ltp":2.9,"tv":0.19,"id":19587212}]}]}
{"op":"mcm","clk":"11933750081","pt":1724316142015,"mc":[{"id":"1.232092849","rc":[{"batb":[[0,2.66,10]],"ltp":2.9,"tv":0.19,"id":19587212}]}]}
{"op":"mcm","clk":"11933750146","pt":1724316144119,"mc":[{"id":"1.232092849","rc":[{"batb":[[0,2.68,4],[1,2.66,10],[2,2.64,33.36]],"ltp":2.9,"tv":0.19,"id":19587212}]}]}
{"op":"mcm","clk":"11933750197","pt":1724316145208,"mc":[{"id":"1.232092849","rc":[{"batb":[[1,2.64,33.36],[2,2.62,11.02]],"ltp":2.9,"tv":0.19,"id":19587212}]}]}
{"op":"mcm","clk":"11933750249","pt":1724316146595,"mc":[{"id":"1.232092849","rc":[{"batb":[[0,2.64,33.36],[1,2.62,11.02],[2,2.6,11.16]],"ltp":2.9,"tv":0.19,"id":19587212}]}]}
{"op":"mcm","clk":"11933750302","pt":1724316147819,"mc":[{"id":"1.232092849","rc":[{"batb":[[0,2.66,10],[1,2.64,33.36],[2,2.62,11.02]],"ltp":2.9,"tv":0.19,"id":19587212}]}]}
{"op":"mcm","clk":"11933750344","pt":1724316148996,"mc":[{"id":"1.232092849","rc":[{"batb":[[0,2.68,4],[1,2.66,10],[2,2.64,33.36]],"ltp":2.9,"tv":0.19,"id":19587212}]}]}
{"op":"mcm","clk":"11933750437","pt":1724316151505,"mc":[{"id":"1.232092849","rc":[{"batb":[[0,2.64,33.36],[1,2.62,11.02],[2,2.6,11.16]],"ltp":2.9,"tv":0.19,"id":19587212}]}]}
{"op":"mcm","clk":"11933750490","pt":1724316153601,"mc":[{"id":"1.232092849","rc":[{"batb":[[0,2.66,14],[1,2.64,33.36],[2,2.62,11.02]],"ltp":2.9,"tv":0.19,"id":19587212}]}]}
{"op":"mcm","clk":"11933750580","pt":1724316156531,"mc":[{"id":"1.232092849","rc":[{"batb":[[0,2.66,10]],"ltp":2.9,"tv":0.19,"id":19587212}]}]}
{"op":"mcm","clk":"11933750607","pt":1724316157051,"mc":[{"id":"1.232092849","rc":[{"batb":[[0,2.64,33.36],[1,2.62,11.02],[2,2.6,11.16]],"ltp":2.9,"tv":0.19,"id":19587212}]}]}
{"op":"mcm","clk":"11933750663","pt":1724316158531,"mc":[{"id":"1.232092849","rc":[{"batb":[[0,2.66,4],[1,2.64,33.36],[2,2.62,11.02]],"ltp":2.9,"tv":0.19,"id":19587212}]}]}
{"op":"mcm","clk":"11933750726","pt":1724316159706,"mc":[{"id":"1.232092849","rc":[{"batb":[[0,2.68,10],[1,2.66,4],[2,2.64,33.36]],"ltp":2.9,"tv":0.19,"id":19587212}]}]}
{"op":"mcm","clk":"11933750760","pt":1724316160729,"mc":[{"id":"1.232092849","rc":[{"batb":[[1,2.64,33.36],[2,2.62,11.02]],"ltp":2.9,"tv":0.19,"id":19587212}]}]}
{"op":"mcm","clk":"11933750847","pt":1724316163030,"mc":[{"id":"1.232092849","rc":[{"batb":[[0,2.66,4]],"ltp":2.9,"tv":0.19,"id":19587212}]}]}
{"op":"mcm","clk":"11933750914","pt":1724316165433,"mc":[{"id":"1.232092849","rc":[{"batb":[[0,2.68,10]],"ltp":2.9,"tv":0.19,"id":19587212}]}]}
{"op":"mcm","clk":"11933750989","pt":1724316167843,"mc":[{"id":"1.232092849","rc":[{"batb":[[0,2.7,4],[1,2.68,10],[2,2.64,33.36]],"ltp":2.9,"tv":0.19,"id":19587212}]}]}
{"op":"mcm","clk":"11933751006","pt":1724316168864,"mc":[{"id":"1.232092849","rc":[{"batb":[[1,2.64,33.36],[2,2.62,11.02]],"ltp":2.9,"tv":0.19,"id":19587212}]}]}
{"op":"mcm","clk":"11933751039","pt":1724316170145,"mc":[{"id":"1.232092849","rc":[{"batb":[[0,2.64,33.36],[1,2.62,11.02],[2,2.6,11.16]],"ltp":2.9,"tv":0.19,"id":19587212}]}]}
{"op":"mcm","clk":"11933751111","pt":1724316172351,"mc":[{"id":"1.232092849","rc":[{"batb":[[0,2.68,4],[1,2.66,10],[2,2.64,33.36]],"ltp":2.9,"tv":0.19,"id":19587212}]}]}
{"op":"mcm","clk":"11933751160","pt":1724316173946,"mc":[{"id":"1.232092849","rc":[{"batb":[[1,2.66,20.76]],"ltp":2.9,"tv":0.19,"id":19587212}]}]}
{"op":"mcm","clk":"11933751195","pt":1724316175536,"mc":[{"id":"1.232092849","rc":[{"batb":[[0,2.64,33.36],[1,2.62,11.02],[2,2.6,11.16]],"ltp":2.9,"tv":0.19,"id":19587212}]}]}
{"op":"mcm","clk":"11933751242","pt":1724316177225,"mc":[{"id":"1.232092849","rc":[{"batb":[[0,2.66,4],[1,2.64,33.36],[2,2.62,11.02]],"ltp":2.9,"tv":0.19,"id":19587212}]}]}
{"op":"mcm","clk":"11933751281","pt":1724316178348,"mc":[{"id":"1.232092849","rc":[{"batb":[[0,2.68,10],[1,2.66,4],[2,2.64,33.36]],"ltp":2.9,"tv":0.19,"id":19587212}]}]}
{"op":"mcm","clk":"11933751312","pt":1724316179630,"mc":[{"id":"1.232092849","rc":[{"batb":[[1,2.64,33.36],[2,2.62,11.02]],"ltp":2.9,"tv":0.19,"id":19587212}]}]}
{"op":"mcm","clk":"11933751391","pt":1724316181846,"mc":[{"id":"1.232092849","rc":[{"batb":[[0,2.66,4]],"ltp":2.9,"tv":0.19,"id":19587212}]}]}
{"op":"mcm","clk":"11933751479","pt":1724316184360,"mc":[{"id":"1.232092849","rc":[{"batb":[[0,2.66,10]],"ltp":2.9,"tv":0.19,"id":19587212}]}]}
{"op":"mcm","clk":"11933751608","pt":1724316187855,"mc":[{"id":"1.232092849","rc":[{"batb":[[0,2.66,4]],"ltp":2.9,"tv":0.19,"id":19587212}]}]}
{"op":"mcm","clk":"11933751688","pt":1724316190260,"mc":[{"id":"1.232092849","rc":[{"batb":[[0,2.66,10]],"ltp":2.9,"tv":0.19,"id":19587212}]}]}
{"op":"mcm","clk":"11933751784","pt":1724316192569,"mc":[{"id":"1.232092849","rc":[{"batb":[[0,2.68,4],[1,2.66,10],[2,2.64,33.36]],"ltp":2.9,"tv":0.19,"id":19587212}]}]}
{"op":"mcm","clk":"11933751821","pt":1724316193546,"mc":[{"id":"1.232092849","rc":[{"batb":[[1,2.64,33.36],[2,2.62,11.02]],"ltp":2.9,"tv":0.19,"id":19587212}]}]}
{"op":"mcm","clk":"11933751855","pt":1724316194880,"mc":[{"id":"1.232092849","rc":[{"batb":[[0,2.64,33.36],[1,2.62,11.02],[2,2.6,11.16]],"ltp":2.9,"tv":0.19,"id":19587212}]}]}
{"op":"mcm","clk":"11933751916","pt":1724316197131,"mc":[{"id":"1.232092849","rc":[{"batb":[[0,2.68,4],[1,2.66,10],[2,2.64,33.36]],"ltp":2.9,"tv":0.19,"id":19587212}]}]}
{"op":"mcm","clk":"11933751983","pt":1724316199479,"mc":[{"id":"1.232092849","rc":[{"batb":[[0,2.66,20.76],[1,2.64,33.36],[2,2.62,11.02]],"ltp":2.9,"tv":0.19,"id":19587212}]}]}
{"op":"mcm","clk":"11933751999","pt":1724316200251,"mc":[{"id":"1.232092849","rc":[{"batb":[[0,2.64,33.36],[1,2.62,11.02],[2,2.6,11.16]],"ltp":2.9,"tv":0.19,"id":19587212}]}]}
{"op":"mcm","clk":"11933752077","pt":1724316202759,"mc":[{"id":"1.232092849","rc":[{"batb":[[0,2.66,14],[1,2.64,33.36],[2,2.62,11.02]],"ltp":2.9,"tv":0.19,"id":19587212}]}]}
{"op":"mcm","clk":"11933752151","pt":1724316205585,"mc":[{"id":"1.232092849","rc":[{"batb":[[0,2.66,10]],"ltp":2.9,"tv":0.19,"id":19587212}]}]}
{"op":"mcm","clk":"11933752169","pt":1724316206256,"mc":[{"id":"1.232092849","rc":[{"batb":[[0,2.64,33.36],[1,2.62,11.02],[2,2.6,11.16]],"ltp":2.9,"tv":0.19,"id":19587212}]}]}
{"op":"mcm","clk":"11933752270","pt":1724316209379,"mc":[{"id":"1.232092849","rc":[{"batb":[[0,2.66,14],[1,2.64,33.36],[2,2.62,11.02]],"ltp":2.9,"tv":0.19,"id":19587212}]}]}
{"op":"mcm","clk":"11933752348","pt":1724316210982,"mc":[{"id":"1.232092849","rc":[{"batb":[[0,2.66,24.76]],"ltp":2.9,"tv":0.19,"id":19587212}]}]}
{"op":"mcm","clk":"11933752424","pt":1724316212571,"mc":[{"id":"1.232092849","rc":[{"batb":[[0,2.66,10]],"ltp":2.9,"tv":0.19,"id":19587212}]}]}
{"op":"mcm","clk":"11933752427","pt":1724316212674,"mc":[{"id":"1.232092849","rc":[{"batb":[[0,2.64,33.36],[1,2.62,11.02],[2,2.6,11.16]],"ltp":2.9,"tv":0.19,"id":19587212}]}]}
{"op":"mcm","clk":"11933752511","pt":1724316215290,"mc":[{"id":"1.232092849","rc":[{"batb":[[0,2.66,14],[1,2.64,33.36],[2,2.62,11.02]],"ltp":2.9,"tv":0.19,"id":19587212}]}]}
{"op":"mcm","clk":"11933752575","pt":1724316216986,"mc":[{"id":"1.232092849","rc":[{"batb":[[0,2.66,24.76]],"ltp":2.9,"tv":0.19,"id":19587212}]}]}
{"op":"mcm","clk":"11933752620","pt":1724316218058,"mc":[{"id":"1.232092849","rc":[{"batb":[[0,2.66,10]],"ltp":2.9,"tv":0.19,"id":19587212}]}]}
{"op":"mcm","clk":"11933752649","pt":1724316218777,"mc":[{"id":"1.232092849","rc":[{"batb":[[0,2.64,33.36],[1,2.62,11.02],[2,2.6,11.16]],"ltp":2.9,"tv":0.19,"id":19587212}]}]}
{"op":"mcm","clk":"11933752695","pt":1724316221088,"mc":[{"id":"1.232092849","rc":[{"batb":[[0,2.68,10],[1,2.66,4],[2,2.64,33.36]],"ltp":2.9,"tv":0.19,"id":19587212}]}]}
{"op":"mcm","clk":"11933752782","pt":1724316223565,"mc":[{"id":"1.232092849","rc":[{"batb":[[1,2.64,33.36],[2,2.62,11.02]],"ltp":2.9,"tv":0.19,"id":19587212}]}]}
{"op":"mcm","clk":"11933752803","pt":1724316224395,"mc":[{"id":"1.232092849","rc":[{"batb":[[0,2.64,33.36],[1,2.62,11.02],[2,2.6,11.16]],"ltp":2.9,"tv":0.19,"id":19587212}]}]}
{"op":"mcm","clk":"11933752911","pt":1724316227602,"mc":[{"id":"1.232092849","rc":[{"batb":[[0,2.66,14],[1,2.64,33.36],[2,2.62,11.02]],"ltp":2.9,"tv":0.19,"id":19587212}]}]}
{"op":"mcm","clk":"11933752994","pt":1724316230517,"mc":[{"id":"1.232092849","rc":[{"batb":[[0,2.66,10]],"ltp":2.9,"tv":0.19,"id":19587212}]}]}
{"op":"mcm","clk":"11933753033","pt":1724316231288,"mc":[{"id":"1.232092849","rc":[{"batb":[[0,2.64,33.36],[1,2.62,11.02],[2,2.6,11.16]],"ltp":2.9,"tv":0.19,"id":19587212}]}]}
{"op":"mcm","clk":"11933753107","pt":1724316233531,"mc":[{"id":"1.232092849","rc":[{"batb":[[0,2.68,10],[1,2.66,4],[2,2.64,33.36]],"ltp":2.9,"tv":0.19,"id":19587212}]}]}
{"op":"mcm","clk":"11933753170","pt":1724316235728,"mc":[{"id":"1.232092849","rc":[{"batb":[[1,2.64,33.36],[2,2.62,11.02]],"ltp":2.9,"tv":0.19,"id":19587212}]}]}
{"op":"mcm","clk":"11933753208","pt":1724316236918,"mc":[{"id":"1.232092849","rc":[{"batb":[[0,2.64,33.36],[1,2.62,11.02],[2,2.6,11.16]],"ltp":2.9,"tv":0.19,"id":19587212}]}]}
{"op":"mcm","clk":"11933753283","pt":1724316239216,"mc":[{"id":"1.232092849","rc":[{"batb":[[0,2.66,14],[1,2.64,33.36],[2,2.62,11.02]],"ltp":2.9,"tv":0.19,"id":19587212}]}]}
{"op":"mcm","clk":"11933753336","pt":1724316241050,"mc":[{"id":"1.232092849","rc":[{"batb":[[0,2.66,24.76]],"ltp":2.9,"tv":0.19,"id":19587212}]}]}
{"op":"mcm","clk":"11933753371","pt":1724316242553,"mc":[{"id":"1.232092849","rc":[{"batb":[[0,2.64,33.36],[1,2.62,11.02],[2,2.6,11.16]],"ltp":2.9,"tv":0.19,"id":19587212}]}]}
{"op":"mcm","clk":"11933753519","pt":1724316247221,"mc":[{"id":"1.232092849","rc":[{"batb":[[0,2.66,14],[1,2.64,33.36],[2,2.62,11.02]],"ltp":2.9,"tv":0.19,"id":19587212}]}]}
{"op":"mcm","clk":"11933753577","pt":1724316249010,"mc":[{"id":"1.232092849","rc":[{"batb":[[0,2.66,24.76]],"ltp":2.9,"tv":0.19,"id":19587212}]}]}
{"op":"mcm","clk":"11933753640","pt":1724316250550,"mc":[{"id":"1.232092849","rc":[{"batb":[[0,2.64,33.36],[1,2.62,11.02],[2,2.6,11.16]],"ltp":2.9,"tv":0.19,"id":19587212}]}]}
{"op":"mcm","clk":"11933753763","pt":1724316253728,"mc":[{"id":"1.232092849","rc":[{"batb":[[0,2.66,14],[1,2.64,33.36],[2,2.62,11.02]],"ltp":2.9,"tv":0.19,"id":19587212}]}]}
{"op":"mcm","clk":"11933753825","pt":1724316256230,"mc":[{"id":"1.232092849","rc":[{"batb":[[0,2.66,20.76]],"ltp":2.9,"tv":0.19,"id":19587212}]}]}
{"op":"mcm","clk":"11933753861","pt":1724316257254,"mc":[{"id":"1.232092849","rc":[{"batb":[[0,2.64,33.36],[1,2.62,11.02],[2,2.6,11.16]],"ltp":2.9,"tv":0.19,"id":19587212}]}]}
{"op":"mcm","clk":"11933753929","pt":1724316259735,"mc":[{"id":"1.232092849","rc":[{"batb":[[0,2.66,14],[1,2.64,33.36],[2,2.62,11.02]],"ltp":2.9,"tv":0.19,"id":19587212}]}]}
{"op":"mcm","clk":"11933754031","pt":1724316262244,"mc":[{"id":"1.232092849","rc":[{"batb":[[0,2.66,20.76]],"ltp":2.9,"tv":0.19,"id":19587212}]}]}
{"op":"mcm","clk":"11933754075","pt":1724316263272,"mc":[{"id":"1.232092849","rc":[{"batb":[[0,2.64,33.36],[1,2.62,11.02],[2,2.6,11.16]],"ltp":2.9,"tv":0.19,"id":19587212}]}]}
{"op":"mcm","clk":"11933754151","pt":1724316265062,"mc":[{"id":"1.232092849","rc":[{"batb":[[0,2.66,4],[1,2.64,33.36],[2,2.62,11.02]],"ltp":2.9,"tv":0.19,"id":19587212}]}]}
{"op":"mcm","clk":"11933754266","pt":1724316267469,"mc":[{"id":"1.232092849","rc":[{"batb":[[0,2.64,33.36],[1,2.62,11.02],[2,2.6,11.16]],"ltp":2.9,"tv":0.19,"id":19587212}]}]}
{"op":"mcm","clk":"11933754275","pt":1724316267672,"mc":[{"id":"1.232092849","rc":[{"batb":[[0,2.66,10],[1,2.64,33.36],[2,2.62,11.02]],"ltp":2.9,"tv":0.19,"id":19587212}]}]}
{"op":"mcm","clk":"11933754436","pt":1724316271148,"mc":[{"id":"1.232092849","rc":[{"batb":[[0,2.66,4]],"ltp":2.9,"tv":0.19,"id":19587212}]}]}
{"op":"mcm","clk":"11933754531","pt":1724316273455,"mc":[{"id":"1.232092849","rc":[{"batb":[[0,2.64,33.36],[1,2.62,11.02],[2,2.6,11.16]],"ltp":2.9,"tv":0.19,"id":19587212}]}]}
{"op":"mcm","clk":"11933754538","pt":1724316273658,"mc":[{"id":"1.232092849","rc":[{"batb":[[0,2.66,10],[1,2.64,33.36],[2,2.62,11.02]],"ltp":2.9,"tv":0.19,"id":19587212}]}]}
{"op":"mcm","clk":"11933754682","pt":1724316277166,"mc":[{"id":"1.232092849","rc":[{"batb":[[0,2.66,4]],"ltp":2.9,"tv":0.19,"id":19587212}]}]}
{"op":"mcm","clk":"11933754794","pt":1724316279577,"mc":[{"id":"1.232092849","rc":[{"batb":[[0,2.64,33.36],[1,2.62,11.02],[2,2.6,11.16]],"ltp":2.9,"tv":0.19,"id":19587212}]}]}
{"op":"mcm","clk":"11933754798","pt":1724316279680,"mc":[{"id":"1.232092849","rc":[{"batb":[[0,2.66,10],[1,2.64,33.36],[2,2.62,11.02]],"ltp":2.9,"tv":0.19,"id":19587212}]}]}
{"op":"mcm","clk":"11933754928","pt":1724316283180,"mc":[{"id":"1.232092849","rc":[{"batb":[[0,2.66,4]],"ltp":2.9,"tv":0.19,"id":19587212}]}]}
{"op":"mcm","clk":"11933755023","pt":1724316285494,"mc":[{"id":"1.232092849","rc":[{"batb":[[0,2.66,10]],"ltp":2.9,"tv":0.19,"id":19587212}]}]}
{"op":"mcm","clk":"11933755119","pt":1724316287864,"mc":[{"id":"1.232092849","rc":[{"batb":[[0,2.68,4],[1,2.66,10],[2,2.64,33.36]],"ltp":2.9,"tv":0.19,"id":19587212}]}]}
{"op":"mcm","clk":"11933755164","pt":1724316288994,"mc":[{"id":"1.232092849","rc":[{"batb":[[1,2.64,33.36],[2,2.62,11.02]],"ltp":2.9,"tv":0.19,"id":19587212}]}]}
{"op":"mcm","clk":"11933755222","pt":1724316290203,"mc":[{"id":"1.232092849","rc":[{"batb":[[0,2.64,33.36],[1,2.62,11.02],[2,2.6,11.16]],"ltp":2.9,"tv":0.19,"id":19587212}]}]}
{"op":"mcm","clk":"11933755322","pt":1724316292461,"mc":[{"id":"1.232092849","rc":[{"batb":[[0,2.68,4],[1,2.66,10],[2,2.64,33.36]],"ltp":2.9,"tv":0.19,"id":19587212}]}]}
{"op":"mcm","clk":"11933755403","pt":1724316295084,"mc":[{"id":"1.232092849","rc":[{"batb":[[0,2.66,20.76],[1,2.64,33.36],[2,2.62,11.02]],"ltp":2.9,"tv":0.19,"id":19587212}]}]}
{"op":"mcm","clk":"11933755425","pt":1724316295700,"mc":[{"id":"1.232092849","rc":[{"batb":[[0,2.64,33.36],[1,2.62,11.02],[2,2.6,11.16]],"ltp":2.9,"tv":0.19,"id":19587212}]}]}
{"op":"mcm","clk":"11933755475","pt":1724316297493,"mc":[{"id":"1.232092849","rc":[{"batb":[[0,2.66,4],[1,2.64,33.36],[2,2.62,11.02]],"ltp":2.9,"tv":0.19,"id":19587212}]}]}
{"op":"mcm","clk":"11933755510","pt":1724316298571,"mc":[{"id":"1.232092849","rc":[{"batb":[[0,2.68,10],[1,2.66,4],[2,2.64,33.36]],"ltp":2.9,"tv":0.19,"id":19587212}]}]}
{"op":"mcm","clk":"11933755555","pt":1724316299871,"mc":[{"id":"1.232092849","rc":[{"batb":[[1,2.64,33.36],[2,2.62,11.02]],"ltp":2.9,"tv":0.19,"id":19587212}]}]}
{"op":"mcm","clk":"11933755644","pt":1724316302294,"mc":[{"id":"1.232092849","rc":[{"batb":[[0,2.62,4],[1,2.6,11.16],[2,2.4,41.14]],"ltp":2.9,"tv":0.19,"id":19587212}]}]}
{"op":"mcm","clk":"11933755743","pt":1724316304607,"mc":[{"id":"1.232092849","rc":[{"batb":[[0,2.6,11.16],[1,2.4,41.14],[2,2,6.18]],"ltp":2.9,"tv":0.19,"id":19587212}]}]}
{"op":"mcm","clk":"11933755826","pt":1724316306709,"mc":[{"id":"1.232092849","rc":[{"batb":[[0,2.64,5],[1,2.6,11.16],[2,2.4,41.14]],"ltp":2.9,"tv":0.19,"id":19587212}]}]}
{"op":"mcm","clk":"11933774475","pt":1724316739326,"mc":[{"id":"1.232092849","rc":[{"trd":[[1.5,156.28],[1.53,153.09]],"batb":[[0,1.38,9.93],[1,1.21,83],[2,1.04,1.53]],"ltp":1.5,"tv":441.55,"id":6847357},{"trd":[[2.98,1.29]],"batl":[[0,3.65,4.02],[1,10,1.06],[2,100,0.67]],"ltp":2.98,"tv":1.48,"id":19587212}],"tv":443.03}]}
{"op":"mcm","clk":"11933774517","pt":1724316740351,"mc":[{"id":"1.232092849","rc":[{"batb":[[1,1.21,168.04]],"ltp":1.5,"tv":441.55,"id":6847357},{"batb":[[1,2.4,41.14],[2,2,6.18]],"ltp":2.98,"tv":1.48,"id":19587212}]}]}
{"op":"mcm","clk":"11933788995","pt":1724317100943,"mc":[{"id":"1.232092849","rc":[{"batl":[[2,1.7,26.08]],"ltp":1.5,"tv":441.55,"id":6847357}]}]}
{"op":"mcm","clk":"11933789210","pt":1724317106819,"mc":[{"id":"1.232092849","rc":[{"batl":[[2,1.7,25.77]],"ltp":1.5,"tv":441.55,"id":6847357}]}]}
{"op":"mcm","clk":"11933792476","pt":1724317200453,"mc":[{"id":"1.232092849","rc":[{"batb":[[0,2.66,14],[1,2.64,5],[2,2.4,41.14]],"ltp":2.98,"tv":1.48,"id":19587212}]}]}
{"op":"mcm","clk":"11933792617","pt":1724317202951,"mc":[{"id":"1.232092849","rc":[{"trd":[[1.5,156.12],[1.53,153.02],[1.57,131.96]],"batb":[[0,1.38,9.91],[1,1.21,167.88]],"batl":[[1,1.62,25.72],[2,1.7,25.72]],"ltp":1.5,"tv":441.26,"id":6847357},{"trd":[[2.98,1.29]],"batb":[[0,2.66,10],[2,2.4,41.09]],"batl":[[0,3.65,4.02],[1,10,1.06]],"ltp":2.98,"tv":1.48,"id":19587212}],"tv":442.75}]}
{"op":"mcm","clk":"11933792656","pt":1724317203671,"mc":[{"id":"1.232092849","rc":[{"batb":[[0,2.64,5],[1,2.4,41.09],[2,2,6.17]],"ltp":2.98,"tv":1.48,"id":19587212}]}]}
{"op":"mcm","clk":"11933792886","pt":1724317208749,"mc":[{"id":"1.232092849","rc":[{"batb":[[0,2.66,14],[1,2.64,5],[2,2.4,41.09]],"ltp":2.98,"tv":1.48,"id":19587212}]}]}
{"op":"mcm","clk":"11933792973","pt":1724317211078,"mc":[{"id":"1.232092849","rc":[{"batb":[[0,2.66,10]],"ltp":2.98,"tv":1.48,"id":19587212}]}]}
{"op":"mcm","clk":"11933793033","pt":1724317212157,"mc":[{"id":"1.232092849","rc":[{"batb":[[0,2.64,5],[1,2.4,41.09],[2,2,6.17]],"ltp":2.98,"tv":1.48,"id":19587212}]}]}
{"op":"mcm","clk":"11933793160","pt":1724317214896,"mc":[{"id":"1.232092849","rc":[{"batb":[[0,2.66,14],[1,2.64,5],[2,2.4,41.09]],"ltp":2.98,"tv":1.48,"id":19587212}]}]}
{"op":"mcm","clk":"11933793279","pt":1724317217193,"mc":[{"id":"1.232092849","rc":[{"batb":[[0,2.66,10]],"ltp":2.98,"tv":1.48,"id":19587212}]}]}
{"op":"mcm","clk":"11933793328","pt":1724317218180,"mc":[{"id":"1.232092849","rc":[{"batb":[[0,2.64,5],[1,2.4,41.09],[2,2,6.17]],"ltp":2.98,"tv":1.48,"id":19587212}]}]}
{"op":"mcm","clk":"11933793467","pt":1724317222292,"mc":[{"id":"1.232092849","rc":[{"batb":[[0,2.66,14],[1,2.64,5],[2,2.4,41.09]],"ltp":2.98,"tv":1.48,"id":19587212}]}]}
{"op":"mcm","clk":"11933793551","pt":1724317224603,"mc":[{"id":"1.232092849","rc":[{"batb":[[0,2.66,10]],"ltp":2.98,"tv":1.48,"id":19587212}]}]}
{"op":"mcm","clk":"11933793587","pt":1724317225982,"mc":[{"id":"1.232092849","rc":[{"batb":[[0,2.64,5],[1,2.4,41.09],[2,2,6.17]],"ltp":2.98,"tv":1.48,"id":19587212}]}]}
{"op":"mcm","clk":"11933793657","pt":1724317227994,"mc":[{"id":"1.232092849","rc":[{"batb":[[0,2.66,4],[1,2.64,5],[2,2.4,41.09]],"ltp":2.98,"tv":1.48,"id":19587212}]}]}
{"op":"mcm","clk":"11933793741","pt":1724317230271,"mc":[{"id":"1.232092849","rc":[{"batb":[[0,2.68,10]],"ltp":2.98,"tv":1.48,"id":19587212}]}]}
{"op":"mcm","clk":"11933793924","pt":1724317233298,"mc":[{"id":"1.232092849","rc":[{"batb":[[0,2.64,5],[1,2.4,41.09],[2,2,6.17]],"ltp":2.98,"tv":1.48,"id":19587212}]}]}
{"op":"mcm","clk":"11933794011","pt":1724317235571,"mc":[{"id":"1.232092849","rc":[{"batb":[[0,2.68,10],[1,2.66,4],[2,2.64,5]],"ltp":2.98,"tv":1.48,"id":19587212}]}]}
{"op":"mcm","clk":"11933794147","pt":1724317237790,"mc":[{"id":"1.232092849","rc":[{"batb":[[1,2.64,5],[2,2.4,41.09]],"ltp":2.98,"tv":1.48,"id":19587212}]}]}
{"op":"mcm","clk":"11933794254","pt":1724317239590,"mc":[{"id":"1.232092849","rc":[{"batb":[[0,2.64,5],[1,2.4,41.09],[2,2,6.17]],"ltp":2.98,"tv":1.48,"id":19587212}]}]}
{"op":"mcm","clk":"11933794331","pt":1724317241093,"mc":[{"id":"1.232092849","rc":[{"batb":[[0,2.66,4],[1,2.64,5],[2,2.4,41.09]],"ltp":2.98,"tv":1.48,"id":19587212}]}]}
{"op":"mcm","clk":"11933794397","pt":1724317242489,"mc":[{"id":"1.232092849","rc":[{"batb":[[0,2.68,10],[1,2.66,4],[2,2.64,5]],"ltp":2.98,"tv":1.48,"id":19587212}]}]}
{"op":"mcm","clk":"11933794430","pt":1724317243516,"mc":[{"id":"1.232092849","rc":[{"batb":[[1,2.64,5],[2,2.4,41.09]],"ltp":2.98,"tv":1.48,"id":19587212}]}]}
{"op":"mcm","clk":"11933794547","pt":1724317246000,"mc":[{"id":"1.232092849","rc":[{"batb":[[0,2.66,4]],"ltp":2.98,"tv":1.48,"id":19587212}]}]}
{"op":"mcm","clk":"11933794622","pt":1724317248411,"mc":[{"id":"1.232092849","rc":[{"batb":[[0,2.66,10]],"ltp":2.98,"tv":1.48,"id":19587212}]}]}
{"op":"mcm","clk":"11933794759","pt":1724317252127,"mc":[{"id":"1.232092849","rc":[{"batb":[[0,2.66,4]],"ltp":2.98,"tv":1.48,"id":19587212}]}]}
{"op":"mcm","clk":"11933794828","pt":1724317254530,"mc":[{"id":"1.232092849","rc":[{"batb":[[0,2.68,10]],"ltp":2.98,"tv":1.48,"id":19587212}]}]}
{"op":"mcm","clk":"11933794996","pt":1724317258024,"mc":[{"id":"1.232092849","rc":[{"batb":[[0,2.66,4]],"ltp":2.98,"tv":1.48,"id":19587212}]}]}
{"op":"mcm","clk":"11933795104","pt":1724317260453,"mc":[{"id":"1.232092849","rc":[{"batb":[[0,2.64,5],[1,2.4,41.09],[2,2,6.17]],"ltp":2.98,"tv":1.48,"id":19587212}]}]}
{"op":"mcm","clk":"11933795116","pt":1724317260616,"mc":[{"id":"1.232092849","rc":[{"batb":[[0,2.66,10],[1,2.64,5],[2,2.4,41.09]],"ltp":2.98,"tv":1.48,"id":19587212}]}]}
{"op":"mcm","clk":"11933795242","pt":1724317264318,"mc":[{"id":"1.232092849","rc":[{"batb":[[0,2.66,4]],"ltp":2.98,"tv":1.48,"id":19587212}]}]}
{"op":"mcm","clk":"11933795318","pt":1724317266435,"mc":[{"id":"1.232092849","rc":[{"batb":[[0,2.68,10],[1,2.66,4],[2,2.64,5]],"ltp":2.98,"tv":1.48,"id":19587212}]}]}
{"op":"mcm","clk":"11933795326","pt":1724317266646,"mc":[{"id":"1.232092849","rc":[{"batb":[[1,2.64,5],[2,2.4,41.09]],"ltp":2.98,"tv":1.48,"id":19587212}]}]}
{"op":"mcm","clk":"11933795425","pt":1724317269146,"mc":[{"id":"1.232092849","rc":[{"batb":[[0,2.7,4],[1,2.68,10],[2,2.64,5]],"ltp":2.98,"tv":1.48,"id":19587212}]}]}
{"op":"mcm","clk":"11933795446","pt":1724317269868,"mc":[{"id":"1.232092849","rc":[{"batb":[[1,2.64,5],[2,2.4,41.09]],"ltp":2.98,"tv":1.48,"id":19587212}]}]}
{"op":"mcm","clk":"11933795505","pt":1724317271362,"mc":[{"id":"1.232092849","rc":[{"batb":[[0,2.64,5],[1,2.4,41.09],[2,2,6.17]],"ltp":2.98,"tv":1.48,"id":19587212}]}]}
{"op":"mcm","clk":"11933795560","pt":1724317272961,"mc":[{"id":"1.232092849","rc":[{"batb":[[0,2.66,10],[1,2.64,5],[2,2.4,41.09]],"ltp":2.98,"tv":1.48,"id":19587212}]}]}
{"op":"mcm","clk":"11933795603","pt":1724317274256,"mc":[{"id":"1.232092849","rc":[{"batb":[[0,2.68,4],[1,2.66,10],[2,2.64,5]],"ltp":2.98,"tv":1.48,"id":19587212}]}]}
{"op":"mcm","clk":"11933795709","pt":1724317276485,"mc":[{"id":"1.232092849","rc":[{"batb":[[0,2.64,5],[1,2.4,41.09],[2,2,6.17]],"ltp":2.98,"tv":1.48,"id":19587212}]}]}
{"op":"mcm","clk":"11933795866","pt":1724317279876,"mc":[{"id":"1.232092849","rc":[{"batb":[[0,2.66,14],[1,2.64,5],[2,2.4,41.09]],"ltp":2.98,"tv":1.48,"id":19587212}]}]}
{"op":"mcm","clk":"11933795976","pt":1724317282495,"mc":[{"id":"1.232092849","rc":[{"batb":[[0,2.66,10]],"ltp":2.98,"tv":1.48,"id":19587212}]}]}
{"op":"mcm","clk":"11933796006","pt":1724317283281,"mc":[{"id":"1.232092849","rc":[{"batb":[[0,2.64,5],[1,2.4,41.09],[2,2,6.17]],"ltp":2.98,"tv":1.48,"id":19587212}]}]}
{"op":"mcm","clk":"11933796087","pt":1724317285487,"mc":[{"id":"1.232092849","rc":[{"batb":[[0,2.66,14],[1,2.64,5],[2,2.4,41.09]],"ltp":2.98,"tv":1.48,"id":19587212}]}]}
{"op":"mcm","clk":"11933796197","pt":1724317287902,"mc":[{"id":"1.232092849","rc":[{"batb":[[0,2.66,10]],"ltp":2.98,"tv":1.48,"id":19587212}]}]}
{"op":"mcm","clk":"11933796238","pt":1724317288889,"mc":[{"id":"1.232092849","rc":[{"batb":[[0,2.64,5],[1,2.4,41.09],[2,2,6.17]],"ltp":2.98,"tv":1.48,"id":19587212}]}]}
{"op":"mcm","clk":"11933796326","pt":1724317291598,"mc":[{"id":"1.232092849","rc":[{"batb":[[0,2.66,14],[1,2.64,5],[2,2.4,41.09]],"ltp":2.98,"tv":1.48,"id":19587212}]}]}
{"op":"mcm","clk":"11933796402","pt":1724317294012,"mc":[{"id":"1.232092849","rc":[{"batb":[[0,2.66,10]],"ltp":2.98,"tv":1.48,"id":19587212}]}]}
{"op":"mcm","clk":"11933796453","pt":1724317295100,"mc":[{"id":"1.232092849","rc":[{"batb":[[0,2.64,5],[1,2.4,41.09],[2,2,6.17]],"ltp":2.98,"tv":1.48,"id":19587212}]}]}
{"op":"mcm","clk":"11933796548","pt":1724317297617,"mc":[{"id":"1.232092849","rc":[{"batb":[[0,2.66,14],[1,2.64,5],[2,2.4,41.09]],"ltp":2.98,"tv":1.48,"id":19587212}]}]}
{"op":"mcm","clk":"11933796625","pt":1724317299929,"mc":[{"id":"1.232092849","rc":[{"batb":[[0,2.66,10]],"ltp":2.98,"tv":1.48,"id":19587212}]}]}
{"op":"mcm","clk":"11933796666","pt":1724317300911,"mc":[{"id":"1.232092849","rc":[{"batb":[[0,2.64,5],[1,2.4,41.09],[2,2,6.17]],"ltp":2.98,"tv":1.48,"id":19587212}]}]}
{"op":"mcm","clk":"11933796726","pt":1724317302298,"mc":[{"id":"1.232092849","rc":[{"batb":[[0,2.66,4],[1,2.64,5],[2,2.4,41.09]],"ltp":2.98,"tv":1.48,"id":19587212}]}]}
{"op":"mcm","clk":"11933796832","pt":1724317304826,"mc":[{"id":"1.232092849","rc":[{"batb":[[0,2.66,10]],"ltp":2.98,"tv":1.48,"id":19587212}]}]}
{"op":"mcm","clk":"11933796916","pt":1724317307046,"mc":[{"id":"1.232092849","rc":[{"batb":[[0,2.68,4],[1,2.66,10],[2,2.64,5]],"ltp":2.98,"tv":1.48,"id":19587212}]}]}
{"op":"mcm","clk":"11933796947","pt":1724317308229,"mc":[{"id":"1.232092849","rc":[{"batb":[[1,2.64,5],[2,2.4,41.09]],"ltp":2.98,"tv":1.48,"id":19587212}]}]}
{"op":"mcm","clk":"11933796990","pt":1724317309527,"mc":[{"id":"1.232092849","rc":[{"batb":[[0,2.64,5],[1,2.4,41.09],[2,2,6.17]],"ltp":2.98,"tv":1.48,"id":19587212}]}]}
{"op":"mcm","clk":"11933797077","pt":1724317312236,"mc":[{"id":"1.232092849","rc":[{"batb":[[0,2.66,14],[1,2.64,5],[2,2.4,41.09]],"ltp":2.98,"tv":1.48,"id":19587212}]}]}
{"op":"mcm","clk":"11933797164","pt":1724317314652,"mc":[{"id":"1.232092849","rc":[{"batb":[[0,2.66,10]],"ltp":2.98,"tv":1.48,"id":19587212}]}]}
{"op":"mcm","clk":"11933797206","pt":1724317315628,"mc":[{"id":"1.232092849","rc":[{"batb":[[0,2.64,5],[1,2.4,41.09],[2,2,6.17]],"ltp":2.98,"tv":1.48,"id":19587212}]}]}
{"op":"mcm","clk":"11933797359","pt":1724317319032,"mc":[{"id":"1.232092849","rc":[{"batb":[[0,2.66,14],[1,2.64,5],[2,2.4,41.09]],"ltp":2.98,"tv":1.48,"id":19587212}]}]}
{"op":"mcm","clk":"11933797474","pt":1724317321460,"mc":[{"id":"1.232092849","rc":[{"batb":[[0,2.66,10]],"ltp":2.98,"tv":1.48,"id":19587212}]}]}
{"op":"mcm","clk":"11933797508","pt":1724317322348,"mc":[{"id":"1.232092849","rc":[{"batb":[[0,2.64,5],[1,2.4,41.09],[2,2,6.17]],"ltp":2.98,"tv":1.48,"id":19587212}]}]}
{"op":"mcm","clk":"11933797600","pt":1724317325025,"mc":[{"id":"1.232092849","rc":[{"batb":[[0,2.66,14],[1,2.64,5],[2,2.4,41.09]],"ltp":2.98,"tv":1.48,"id":19587212}]}]}
{"op":"mcm","clk":"11933797716","pt":1724317327558,"mc":[{"id":"1.232092849","rc":[{"batb":[[0,2.66,10]],"ltp":2.98,"tv":1.48,"id":19587212}]}]}
{"op":"mcm","clk":"11933797759","pt":1724317328336,"mc":[{"id":"1.232092849","rc":[{"batb":[[0,2.64,5],[1,2.4,41.09],[2,2,6.17]],"ltp":2.98,"tv":1.48,"id":19587212}]}]}
{"op":"mcm","clk":"11933798003","pt":1724317332777,"mc":[{"id":"1.232092849","rc":[{"batb":[[0,2.66,14],[1,2.64,5],[2,2.4,41.09]],"ltp":2.98,"tv":1.48,"id":19587212}]}]}
{"op":"mcm","clk":"11933798111","pt":1724317335045,"mc":[{"id":"1.232092849","rc":[{"batb":[[0,2.66,10]],"ltp":2.98,"tv":1.48,"id":19587212}]}]}
{"op":"mcm","clk":"11933798165","pt":1724317336072,"mc":[{"id":"1.232092849","rc":[{"batb":[[0,2.64,5],[1,2.4,41.09],[2,2,6.17]],"ltp":2.98,"tv":1.48,"id":19587212}]}]}
{"op":"mcm","clk":"11933798373","pt":1724317340264,"mc":[{"id":"1.232092849","rc":[{"batb":[[0,2.66,14],[1,2.64,5],[2,2.4,41.09]],"ltp":2.98,"tv":1.48,"id":19587212}]}]}
{"op":"mcm","clk":"11933798514","pt":1724317342786,"mc":[{"id":"1.232092849","rc":[{"batb":[[0,2.66,10]],"ltp":2.98,"tv":1.48,"id":19587212}]}]}
{"op":"mcm","clk":"11933798553","pt":1724317343866,"mc":[{"id":"1.232092849","rc":[{"batb":[[0,2.64,5],[1,2.4,41.09],[2,2,6.17]],"ltp":2.98,"tv":1.48,"id":19587212}]}]}
{"op":"mcm","clk":"11933798611","pt":1724317345077,"mc":[{"id":"1.232092849","rc":[{"batb":[[0,2.66,4],[1,2.64,5],[2,2.4,41.09]],"ltp":2.98,"tv":1.48,"id":19587212}]}]}
{"op":"mcm","clk":"11933798734","pt":1724317347451,"mc":[{"id":"1.232092849","rc":[{"batb":[[0,2.66,10]],"ltp":2.98,"tv":1.48,"id":19587212}]}]}
{"op":"mcm","clk":"11933798823","pt":1724317349883,"mc":[{"id":"1.232092849","rc":[{"batb":[[0,2.68,4],[1,2.66,10],[2,2.64,5]],"ltp":2.98,"tv":1.48,"id":19587212}]}]}
{"op":"mcm","clk":"11933798861","pt":1724317350868,"mc":[{"id":"1.232092849","rc":[{"batb":[[1,2.64,5],[2,2.4,41.09]],"ltp":2.98,"tv":1.48,"id":19587212}]}]}
{"op":"mcm","clk":"11933798922","pt":1724317352158,"mc":[{"id":"1.232092849","rc":[{"batb":[[0,2.64,5],[1,2.4,41.09],[2,2,6.17]],"ltp":2.98,"tv":1.48,"id":19587212}]}]}
{"op":"mcm","clk":"11933799001","pt":1724317353399,"mc":[{"id":"1.232092849","rc":[{"batb":[[0,2.66,10],[1,2.64,5],[2,2.4,41.09]],"ltp":2.98,"tv":1.48,"id":19587212}]}]}
{"op":"mcm","clk":"11933799067","pt":1724317354992,"mc":[{"id":"1.232092849","rc":[{"batb":[[0,2.68,4],[1,2.66,10],[2,2.64,5]],"ltp":2.98,"tv":1.48,"id":19587212}]}]}
{"op":"mcm","clk":"11933799169","pt":1724317357466,"mc":[{"id":"1.232092849","rc":[{"batb":[[0,2.64,5],[1,2.4,41.09],[2,2,6.17]],"ltp":2.98,"tv":1.48,"id":19587212}]}]}
{"op":"mcm","clk":"11933799256","pt":1724317359481,"mc":[{"id":"1.232092849","rc":[{"batb":[[0,2.66,10],[1,2.64,5],[2,2.4,41.09]],"ltp":2.98,"tv":1.48,"id":19587212}]}]}
{"op":"mcm","clk":"11933799321","pt":1724317360980,"mc":[{"id":"1.232092849","rc":[{"batb":[[0,2.68,4],[1,2.66,10],[2,2.64,5]],"ltp":2.98,"tv":1.48,"id":19587212}]}]}
{"op":"mcm","clk":"11933799424","pt":1724317363511,"mc":[{"id":"1.232092849","rc":[{"batb":[[0,2.64,5],[1,2.4,41.09],[2,2,6.17]],"ltp":2.98,"tv":1.48,"id":19587212}]}]}
{"op":"mcm","clk":"11933799533","pt":1724317365794,"mc":[{"id":"1.232092849","rc":[{"batb":[[0,2.66,14],[1,2.64,5],[2,2.4,41.09]],"ltp":2.98,"tv":1.48,"id":19587212}]}]}
{"op":"mcm","clk":"11933799625","pt":1724317368213,"mc":[{"id":"1.232092849","rc":[{"batb":[[0,2.66,10]],"ltp":2.98,"tv":1.48,"id":19587212}]}]}
{"op":"mcm","clk":"11933799671","pt":1724317369193,"mc":[{"id":"1.232092849","rc":[{"batb":[[0,2.64,5],[1,2.4,41.09],[2,2,6.17]],"ltp":2.98,"tv":1.48,"id":19587212}]}]}
{"op":"mcm","clk":"11933799766","pt":1724317371521,"mc":[{"id":"1.232092849","rc":[{"batb":[[0,2.66,14],[1,2.64,5],[2,2.4,41.09]],"ltp":2.98,"tv":1.48,"id":19587212}]}]}
{"op":"mcm","clk":"11933799840","pt":1724317373829,"mc":[{"id":"1.232092849","rc":[{"batb":[[0,2.66,10]],"ltp":2.98,"tv":1.48,"id":19587212}]}]}
{"op":"mcm","clk":"11933799879","pt":1724317374807,"mc":[{"id":"1.232092849","rc":[{"batb":[[0,2.64,5],[1,2.4,41.09],[2,2,6.17]],"ltp":2.98,"tv":1.48,"id":19587212}]}]}
{"op":"mcm","clk":"11933799920","pt":1724317375894,"mc":[{"id":"1.232092849","rc":[{"batb":[[0,2.66,4],[1,2.64,5],[2,2.4,41.09]],"ltp":2.98,"tv":1.48,"id":19587212}]}]}
{"op":"mcm","clk":"11933799985","pt":1724317377489,"mc":[{"id":"1.232092849","rc":[{"batb":[[0,2.68,10],[1,2.66,4],[2,2.64,5]],"ltp":2.98,"tv":1.48,"id":19587212}]}]}
{"op":"mcm","clk":"11933800012","pt":1724317378311,"mc":[{"id":"1.232092849","rc":[{"batb":[[1,2.64,5],[2,2.4,41.09]],"ltp":2.98,"tv":1.48,"id":19587212}]}]}
{"op":"mcm","clk":"11933800127","pt":1724317380830,"mc":[{"id":"1.232092849","rc":[{"batb":[[0,2.66,4]],"ltp":2.98,"tv":1.48,"id":19587212}]}]}
{"op":"mcm","clk":"11933800252","pt":1724317383207,"mc":[{"id":"1.232092849","rc":[{"batb":[[0,2.64,5],[1,2.4,41.09],[2,2,6.17]],"ltp":2.98,"tv":1.48,"id":19587212}]}]}
{"op":"mcm","clk":"11933800325","pt":1724317385012,"mc":[{"id":"1.232092849","rc":[{"batb":[[0,2.66,10],[1,2.64,5],[2,2.4,41.09]],"ltp":2.98,"tv":1.48,"id":19587212}]}]}
{"op":"mcm","clk":"11933800345","pt":1724317385624,"mc":[{"id":"1.232092849","rc":[{"batb":[[0,2.66,14]],"ltp":2.98,"tv":1.48,"id":19587212}]}]}
{"op":"mcm","clk":"11933800447","pt":1724317388146,"mc":[{"id":"1.232092849","rc":[{"batb":[[0,2.66,10]],"ltp":2.98,"tv":1.48,"id":19587212}]}]}
{"op":"mcm","clk":"11933800481","pt":1724317388816,"mc":[{"id":"1.232092849","rc":[{"batb":[[0,2.64,5],[1,2.4,41.09],[2,2,6.17]],"ltp":2.98,"tv":1.48,"id":19587212}]}]}
{"op":"mcm","clk":"11933800572","pt":1724317390515,"mc":[{"id":"1.232092849","rc":[{"batb":[[0,2.66,4],[1,2.64,5],[2,2.4,41.09]],"ltp":2.98,"tv":1.48,"id":19587212}]}]}
{"op":"mcm","clk":"11933800614","pt":1724317391749,"mc":[{"id":"1.232092849","rc":[{"batb":[[0,2.68,10],[1,2.66,4],[2,2.64,5]],"ltp":2.98,"tv":1.48,"id":19587212}]}]}
{"op":"mcm","clk":"11933800660","pt":1724317392830,"mc":[{"id":"1.232092849","rc":[{"batb":[[1,2.64,5],[2,2.4,41.09]],"ltp":2.98,"tv":1.48,"id":19587212}]}]}
{"op":"mcm","clk":"11933800765","pt":1724317395144,"mc":[{"id":"1.232092849","rc":[{"batb":[[0,2.66,4]],"ltp":2.98,"tv":1.48,"id":19587212}]}]}
{"op":"mcm","clk":"11933800867","pt":1724317397349,"mc":[{"id":"1.232092849","rc":[{"batb":[[0,2.64,5],[1,2.4,41.09],[2,2,6.17]],"ltp":2.98,"tv":1.48,"id":19587212}]}]}
{"op":"mcm","clk":"11933800907","pt":1724317398329,"mc":[{"id":"1.232092849","rc":[{"batb":[[0,2.68,10],[1,2.64,5],[2,2.4,41.09]],"ltp":2.98,"tv":1.48,"id":19587212}]}]}
{"op":"mcm","clk":"11933800997","pt":1724317400231,"mc":[{"id":"1.232092849","rc":[{"batb":[[0,2.7,4],[1,2.68,10],[2,2.64,5]],"ltp":2.98,"tv":1.48,"id":19587212}]}]}
{"op":"mcm","clk":"11933801078","pt":1724317401826,"mc":[{"id":"1.232092849","rc":[{"batb":[[1,2.64,5],[2,2.4,41.09]],"ltp":2.98,"tv":1.48,"id":19587212}]}]}
{"op":"mcm","clk":"11933801125","pt":1724317403159,"mc":[{"id":"1.232092849","rc":[{"batb":[[0,2.64,5],[1,2.4,41.09],[2,2,6.17]],"ltp":2.98,"tv":1.48,"id":19587212}]}]}
{"op":"mcm","clk":"11933801157","pt":1724317404243,"mc":[{"id":"1.232092849","rc":[{"batb":[[0,2.66,10],[1,2.64,5],[2,2.4,41.09]],"ltp":2.98,"tv":1.48,"id":19587212}]}]}
{"op":"mcm","clk":"11933801227","pt":1724317406362,"mc":[{"id":"1.232092849","rc":[{"batb":[[0,2.68,4],[1,2.66,10],[2,2.64,5]],"ltp":2.98,"tv":1.48,"id":19587212}]}]}
{"op":"mcm","clk":"11933801259","pt":1724317407455,"mc":[{"id":"1.232092849","rc":[{"batb":[[1,2.64,5],[2,2.4,41.09]],"ltp":2.98,"tv":1.48,"id":19587212}]}]}
{"op":"mcm","clk":"11933801300","pt":1724317408649,"mc":[{"id":"1.232092849","rc":[{"batb":[[0,2.64,5],[1,2.4,41.09],[2,2,6.17]],"ltp":2.98,"tv":1.48,"id":19587212}]}]}
{"op":"mcm","clk":"11933801341","pt":1724317409883,"mc":[{"id":"1.232092849","rc":[{"batb":[[0,2.66,10],[1,2.64,5],[2,2.4,41.09]],"ltp":2.98,"tv":1.48,"id":19587212}]}]}
{"op":"mcm","clk":"11933801433","pt":1724317412256,"mc":[{"id":"1.232092849","rc":[{"batb":[[0,2.68,4],[1,2.66,10],[2,2.64,5]],"ltp":2.98,"tv":1.48,"id":19587212}]}]}
{"op":"mcm","clk":"11933801483","pt":1724317413238,"mc":[{"id":"1.232092849","rc":[{"batb":[[1,2.64,5],[2,2.4,41.09]],"ltp":2.98,"tv":1.48,"id":19587212}]}]}
{"op":"mcm","clk":"11933801546","pt":1724317414786,"mc":[{"id":"1.232092849","rc":[{"batb":[[0,2.64,5],[1,2.4,41.09],[2,2,6.17]],"ltp":2.98,"tv":1.48,"id":19587212}]}]}
{"op":"mcm","clk":"11933801630","pt":1724317416956,"mc":[{"id":"1.232092849","rc":[{"batb":[[0,2.66,14],[1,2.64,5],[2,2.4,41.09]],"ltp":2.98,"tv":1.48,"id":19587212}]}]}
{"op":"mcm","clk":"11933801732","pt":1724317419484,"mc":[{"id":"1.232092849","rc":[{"batb":[[0,2.66,10]],"ltp":2.98,"tv":1.48,"id":19587212}]}]}
{"op":"mcm","clk":"11933801760","pt":1724317420258,"mc":[{"id":"1.232092849","rc":[{"batb":[[0,2.64,5],[1,2.4,41.09],[2,2,6.17]],"ltp":2.98,"tv":1.48,"id":19587212}]}]}
{"op":"mcm","clk":"11933801867","pt":1724317423197,"mc":[{"id":"1.232092849","rc":[{"batb":[[0,2.66,14],[1,2.64,5],[2,2.4,41.09]],"ltp":2.98,"tv":1.48,"id":19587212}]}]}
{"op":"mcm","clk":"11933802002","pt":1724317426464,"mc":[{"id":"1.232092849","rc":[{"batb":[[0,2.64,5],[1,2.4,41.09],[2,2,6.17]],"ltp":2.98,"tv":1.48,"id":19587212}]}]}
{"op":"mcm","clk":"11933802053","pt":1724317427694,"mc":[{"id":"1.232092849","rc":[{"batb":[[0,2.66,4],[1,2.64,5],[2,2.4,41.09]],"ltp":2.98,"tv":1.48,"id":19587212}]}]}
{"op":"mcm","clk":"11933802134","pt":1724317429954,"mc":[{"id":"1.232092849","rc":[{"batb":[[0,2.68,10]],"ltp":2.98,"tv":1.48,"id":19587212}]}]}
{"op":"mcm","clk":"11933802234","pt":1724317432367,"mc":[{"id":"1.232092849","rc":[{"batb":[[0,2.7,4],[1,2.68,10],[2,2.64,5]],"ltp":2.98,"tv":1.48,"id":19587212}]}]}
{"op":"mcm","clk":"11933802255","pt":1724317432879,"mc":[{"id":"1.232092849","rc":[{"batb":[[1,2.64,5],[2,2.4,41.09]],"ltp":2.98,"tv":1.48,"id":19587212}]}]}
{"op":"mcm","clk":"11933802314","pt":1724317434789,"mc":[{"id":"1.232092849","rc":[{"batb":[[0,2.64,5],[1,2.4,41.09],[2,2,6.17]],"ltp":2.98,"tv":1.48,"id":19587212}]}]}
{"op":"mcm","clk":"11933802353","pt":1724317435874,"mc":[{"id":"1.232092849","rc":[{"batb":[[0,2.66,10],[1,2.64,5],[2,2.4,41.09]],"ltp":2.98,"tv":1.48,"id":19587212}]}]}
{"op":"mcm","clk":"11933802483","pt":1724317439175,"mc":[{"id":"1.232092849","rc":[{"batb":[[0,2.66,4]],"ltp":2.98,"tv":1.48,"id":19587212}]}]}
{"op":"mcm","clk":"11933802573","pt":1724317441575,"mc":[{"id":"1.232092849","rc":[{"batb":[[0,2.68,10]],"ltp":2.98,"tv":1.48,"id":19587212}]}]}
{"op":"mcm","clk":"11933802659","pt":1724317443791,"mc":[{"id":"1.232092849","rc":[{"batb":[[0,2.7,4],[1,2.68,10],[2,2.64,5]],"ltp":2.98,"tv":1.48,"id":19587212}]}]}
{"op":"mcm","clk":"11933802701","pt":1724317444784,"mc":[{"id":"1.232092849","rc":[{"batb":[[1,2.64,5],[2,2.4,41.09]],"ltp":2.98,"tv":1.48,"id":19587212}]}]}
{"op":"mcm","clk":"11933802762","pt":1724317446215,"mc":[{"id":"1.232092849","rc":[{"batb":[[1,1.23,18.3],[2,1.21,167.88]],"ltp":1.5,"tv":441.26,"id":6847357},{"batb":[[0,2.64,5],[1,2.4,41.09],[2,2,6.17]],"ltp":2.98,"tv":1.48,"id":19587212}]}]}
{"op":"mcm","clk":"11933802849","pt":1724317448275,"mc":[{"id":"1.232092849","rc":[{"batb":[[0,2.66,14],[1,2.64,5],[2,2.4,41.09]],"ltp":2.98,"tv":1.48,"id":19587212}]}]}
{"op":"mcm","clk":"11933802953","pt":1724317450690,"mc":[{"id":"1.232092849","rc":[{"batb":[[0,2.66,10]],"ltp":2.98,"tv":1.48,"id":19587212}]}]}
{"op":"mcm","clk":"11933803005","pt":1724317451618,"mc":[{"id":"1.232092849","rc":[{"batb":[[0,2.64,5],[1,2.4,41.09],[2,2,6.17]],"ltp":2.98,"tv":1.48,"id":19587212}]}]}
{"op":"mcm","clk":"11933803196","pt":1724317455421,"mc":[{"id":"1.232092849","rc":[{"batb":[[0,2.66,14],[1,2.64,5],[2,2.4,41.09]],"ltp":2.98,"tv":1.48,"id":19587212}]}]}
{"op":"mcm","clk":"11933803310","pt":1724317457933,"mc":[{"id":"1.232092849","rc":[{"batb":[[0,2.66,10]],"ltp":2.98,"tv":1.48,"id":19587212}]}]}
{"op":"mcm","clk":"11933803341","pt":1724317458600,"mc":[{"id":"1.232092849","rc":[{"batb":[[0,2.64,5],[1,2.4,41.09],[2,2,6.17]],"ltp":2.98,"tv":1.48,"id":19587212}]}]}
{"op":"mcm","clk":"11933803433","pt":1724317460918,"mc":[{"id":"1.232092849","rc":[{"batb":[[0,2.68,10],[1,2.66,4],[2,2.64,5]],"ltp":2.98,"tv":1.48,"id":19587212}]}]}
{"op":"mcm","clk":"11933803538","pt":1724317463144,"mc":[{"id":"1.232092849","rc":[{"batb":[[1,2.64,5],[2,2.4,41.09]],"ltp":2.98,"tv":1.48,"id":19587212}]}]}
{"op":"mcm","clk":"11933803581","pt":1724317464337,"mc":[{"id":"1.232092849","rc":[{"batb":[[0,2.64,5],[1,2.4,41.09],[2,2,6.17]],"ltp":2.98,"tv":1.48,"id":19587212}]}]}
{"op":"mcm","clk":"11933803623","pt":1724317465435,"mc":[{"id":"1.232092849","rc":[{"batb":[[0,2.66,4],[1,2.64,5],[2,2.4,41.09]],"ltp":2.98,"tv":1.48,"id":19587212}]}]}
{"op":"mcm","clk":"11933803688","pt":1724317467307,"mc":[{"id":"1.232092849","rc":[{"batb":[[0,2.68,10],[1,2.66,4],[2,2.64,5]],"ltp":2.98,"tv":1.48,"id":19587212}]}]}
{"op":"mcm","clk":"11933803712","pt":1724317467823,"mc":[{"id":"1.232092849","rc":[{"batb":[[1,2.64,5],[2,2.4,41.09]],"ltp":2.98,"tv":1.48,"id":19587212}]}]}
{"op":"mcm","clk":"11933803832","pt":1724317470760,"mc":[{"id":"1.232092849","rc":[{"batb":[[0,2.66,4]],"ltp":2.98,"tv":1.48,"id":19587212}]}]}
{"op":"mcm","clk":"11933803933","pt":1724317472921,"mc":[{"id":"1.232092849","rc":[{"batb":[[0,2.64,5],[1,2.4,41.09],[2,2,6.17]],"ltp":2.98,"tv":1.48,"id":19587212}]}]}
{"op":"mcm","clk":"11933803972","pt":1724317473954,"mc":[{"id":"1.232092849","rc":[{"batb":[[0,2.68,10],[1,2.64,5],[2,2.4,41.09]],"ltp":2.98,"tv":1.48,"id":19587212}]}]}
{"op":"mcm","clk":"11933804125","pt":1724317478071,"mc":[{"id":"1.232092849","rc":[{"batb":[[0,2.66,4]],"ltp":2.98,"tv":1.48,"id":19587212}]}]}
{"op":"mcm","clk":"11933804222","pt":1724317480441,"mc":[{"id":"1.232092849","rc":[{"batb":[[0,2.66,10]],"ltp":2.98,"tv":1.48,"id":19587212}]}]}
{"op":"mcm","clk":"11933804343","pt":1724317483742,"mc":[{"id":"1.232092849","rc":[{"batb":[[0,2.66,4]],"ltp":2.98,"tv":1.48,"id":19587212}]}]}
{"op":"mcm","clk":"11933804434","pt":1724317486054,"mc":[{"id":"1.232092849","rc":[{"batb":[[0,2.68,10]],"ltp":2.98,"tv":1.48,"id":19587212}]}]}
{"op":"mcm","clk":"11933804596","pt":1724317489546,"mc":[{"id":"1.232092849","rc":[{"batb":[[0,2.64,5],[1,2.4,41.09],[2,2,6.17]],"ltp":2.98,"tv":1.48,"id":19587212}]}]}
{"op":"mcm","clk":"11933804602","pt":1724317489654,"mc":[{"id":"1.232092849","rc":[{"batb":[[0,2.66,4],[1,2.64,5],[2,2.4,41.09]],"ltp":2.98,"tv":1.48,"id":19587212}]}]}
{"op":"mcm","clk":"11933804702","pt":1724317492173,"mc":[{"id":"1.232092849","rc":[{"batb":[[0,2.66,10]],"ltp":2.98,"tv":1.48,"id":19587212}]}]}
{"op":"mcm","clk":"11933804833","pt":1724317495363,"mc":[{"id":"1.232092849","rc":[{"batb":[[0,2.68,4]],"ltp":2.98,"tv":1.48,"id":19587212}]}]}
{"op":"mcm","clk":"11933804915","pt":1724317497376,"mc":[{"id":"1.232092849","rc":[{"batb":[[0,2.64,5],[1,2.4,41.09],[2,2,6.17]],"ltp":2.98,"tv":1.48,"id":19587212}]}]}
{"op":"mcm","clk":"11933805132","pt":1724317501954,"mc":[{"id":"1.232092849","rc":[{"batb":[[0,2.66,14],[1,2.64,5],[2,2.4,41.09]],"ltp":2.98,"tv":1.48,"id":19587212}]}]}
{"op":"mcm","clk":"11933805242","pt":1724317504377,"mc":[{"id":"1.232092849","rc":[{"batb":[[0,2.66,10]],"ltp":2.98,"tv":1.48,"id":19587212}]}]}
{"op":"mcm","clk":"11933805304","pt":1724317505454,"mc":[{"id":"1.232092849","rc":[{"batb":[[0,2.64,5],[1,2.4,41.09],[2,2,6.17]],"ltp":2.98,"tv":1.48,"id":19587212}]}]}
{"op":"mcm","clk":"11933805355","pt":1724317506687,"mc":[{"id":"1.232092849","rc":[{"batb":[[0,2.66,4],[1,2.64,5],[2,2.4,41.09]],"ltp":2.98,"tv":1.48,"id":19587212}]}]}
{"op":"mcm","clk":"11933805432","pt":1724317508291,"mc":[{"id":"1.232092849","rc":[{"batb":[[0,2.68,10],[1,2.66,4],[2,2.64,5]],"ltp":2.98,"tv":1.48,"id":19587212}]}]}
{"op":"mcm","clk":"11933805474","pt":1724317509059,"mc":[{"id":"1.232092849","rc":[{"batb":[[1,2.64,5],[2,2.4,41.09]],"ltp":2.98,"tv":1.48,"id":19587212}]}]}
{"op":"mcm","clk":"11933805582","pt":1724317511880,"mc":[{"id":"1.232092849","rc":[{"batb":[[0,2.66,4]],"ltp":2.98,"tv":1.48,"id":19587212}]}]}
{"op":"mcm","clk":"11933805698","pt":1724317514192,"mc":[{"id":"1.232092849","rc":[{"batb":[[0,2.66,10]],"ltp":2.98,"tv":1.48,"id":19587212}]}]}
{"op":"mcm","clk":"11933805857","pt":1724317517004,"mc":[{"id":"1.232092849","rc":[{"batb":[[0,2.68,4],[1,2.66,10],[2,2.64,5]],"ltp":2.98,"tv":1.48,"id":19587212}]}]}
{"op":"mcm","clk":"11933805897","pt":1724317517717,"mc":[{"id":"1.232092849","rc":[{"batb":[[1,2.64,5],[2,2.4,41.09]],"ltp":2.98,"tv":1.48,"id":19587212}]}]}
{"op":"mcm","clk":"11933806003","pt":1724317519540,"mc":[{"id":"1.232092849","rc":[{"batb":[[0,2.64,5],[1,2.4,41.09],[2,2,6.17]],"ltp":2.98,"tv":1.48,"id":19587212}]}]}
{"op":"mcm","clk":"11933806090","pt":1724317521936,"mc":[{"id":"1.232092849","rc":[{"batb":[[0,2.66,14],[1,2.64,5],[2,2.4,41.09]],"ltp":2.98,"tv":1.48,"id":19587212}]}]}
{"op":"mcm","clk":"11933806186","pt":1724317524402,"mc":[{"id":"1.232092849","rc":[{"batb":[[0,2.66,10]],"ltp":2.98,"tv":1.48,"id":19587212}]}]}
{"op":"mcm","clk":"11933806228","pt":1724317525442,"mc":[{"id":"1.232092849","rc":[{"batb":[[0,2.64,5],[1,2.4,41.09],[2,2,6.17]],"ltp":2.98,"tv":1.48,"id":19587212}]}]}
{"op":"mcm","clk":"11933806440","pt":1724317530299,"mc":[{"id":"1.232092849","rc":[{"batb":[[0,2.66,14],[1,2.64,5],[2,2.4,41.09]],"ltp":2.98,"tv":1.48,"id":19587212}]}]}
{"op":"mcm","clk":"11933806541","pt":1724317532718,"mc":[{"id":"1.232092849","rc":[{"batb":[[0,2.66,10]],"ltp":2.98,"tv":1.48,"id":19587212}]}]}
{"op":"mcm","clk":"11933806589","pt":1724317533901,"mc":[{"id":"1.232092849","rc":[{"batb":[[0,2.64,5],[1,2.4,41.09],[2,2,6.17]],"ltp":2.98,"tv":1.48,"id":19587212}]}]}
{"op":"mcm","clk":"11933806791","pt":1724317537924,"mc":[{"id":"1.232092849","rc":[{"batb":[[0,2.66,14],[1,2.64,5],[2,2.4,41.09]],"ltp":2.98,"tv":1.48,"id":19587212}]}]}
{"op":"mcm","clk":"11933806947","pt":1724317540353,"mc":[{"id":"1.232092849","rc":[{"batb":[[0,2.66,10]],"ltp":2.98,"tv":1.48,"id":19587212}]}]}
{"op":"mcm","clk":"11933806997","pt":1724317541339,"mc":[{"id":"1.232092849","rc":[{"batb":[[0,2.64,5],[1,2.4,41.09],[2,2,6.17]],"ltp":2.98,"tv":1.48,"id":19587212}]}]}
{"op":"mcm","clk":"11933807125","pt":1724317544740,"mc":[{"id":"1.232092849","rc":[{"batb":[[0,2.66,14],[1,2.64,5],[2,2.4,41.09]],"ltp":2.98,"tv":1.48,"id":19587212}]}]}
{"op":"mcm","clk":"11933807223","pt":1724317546961,"mc":[{"id":"1.232092849","rc":[{"batb":[[0,2.66,10]],"ltp":2.98,"tv":1.48,"id":19587212}]}]}
{"op":"mcm","clk":"11933807275","pt":1724317548050,"mc":[{"id":"1.232092849","rc":[{"batb":[[0,2.64,5],[1,2.4,41.09],[2,2,6.17]],"ltp":2.98,"tv":1.48,"id":19587212}]}]}
{"op":"mcm","clk":"11933809140","pt":1724317590398,"mc":[{"id":"1.232092849","rc":[{"batb":[[0,2.66,14],[1,2.64,5],[2,2.4,41.09]],"ltp":2.98,"tv":1.48,"id":19587212}]}]}
{"op":"mcm","clk":"11933809230","pt":1724317593016,"mc":[{"id":"1.232092849","rc":[{"batb":[[0,2.66,10]],"ltp":2.98,"tv":1.48,"id":19587212}]}]}
{"op":"mcm","clk":"11933809272","pt":1724317593791,"mc":[{"id":"1.232092849","rc":[{"batb":[[0,2.64,5],[1,2.4,41.09],[2,2,6.17]],"ltp":2.98,"tv":1.48,"id":19587212}]}]}
{"op":"mcm","clk":"11933809351","pt":1724317596000,"mc":[{"id":"1.232092849","rc":[{"batb":[[0,2.66,14],[1,2.64,5],[2,2.4,41.09]],"ltp":2.98,"tv":1.48,"id":19587212}]}]}
{"op":"mcm","clk":"11933809459","pt":1724317598509,"mc":[{"id":"1.232092849","rc":[{"batb":[[0,2.66,10]],"ltp":2.98,"tv":1.48,"id":19587212}]}]}
{"op":"mcm","clk":"11933809492","pt":1724317599333,"mc":[{"id":"1.232092849","rc":[{"batb":[[0,2.64,5],[1,2.4,41.09],[2,2,6.17]],"ltp":2.98,"tv":1.48,"id":19587212}]}]}
{"op":"mcm","clk":"11933809683","pt":1724317603125,"mc":[{"id":"1.232092849","rc":[{"batb":[[0,2.66,14],[1,2.64,5],[2,2.4,41.09]],"ltp":2.98,"tv":1.48,"id":19587212}]}]}
{"op":"mcm","clk":"11933809813","pt":1724317606019,"mc":[{"id":"1.232092849","rc":[{"batb":[[0,2.66,10]],"ltp":2.98,"tv":1.48,"id":19587212}]}]}
{"op":"mcm","clk":"11933809855","pt":1724317606942,"mc":[{"id":"1.232092849","rc":[{"batb":[[0,2.64,5],[1,2.4,41.09],[2,2,6.17]],"ltp":2.98,"tv":1.48,"id":19587212}]}]}
{"op":"mcm","clk":"11933810159","pt":1724317613930,"mc":[{"id":"1.232092849","rc":[{"batb":[[0,2.66,14],[1,2.64,5],[2,2.4,41.09]],"ltp":2.98,"tv":1.48,"id":19587212}]}]}
{"op":"mcm","clk":"11933810267","pt":1724317616342,"mc":[{"id":"1.232092849","rc":[{"batb":[[0,2.66,10]],"ltp":2.98,"tv":1.48,"id":19587212}]}]}
{"op":"mcm","clk":"11933810315","pt":1724317617440,"mc":[{"id":"1.232092849","rc":[{"batb":[[0,2.64,5],[1,2.4,41.09],[2,2,6.17]],"ltp":2.98,"tv":1.48,"id":19587212}]}]}
{"op":"mcm","clk":"11933810348","pt":1724317618635,"mc":[{"id":"1.232092849","rc":[{"batb":[[0,2.66,4],[1,2.64,5],[2,2.4,41.09]],"ltp":2.98,"tv":1.48,"id":19587212}]}]}
{"op":"mcm","clk":"11933810411","pt":1724317620133,"mc":[{"id":"1.232092849","rc":[{"batb":[[0,2.68,10],[1,2.66,4],[2,2.64,5]],"ltp":2.98,"tv":1.48,"id":19587212}]}]}
{"op":"mcm","clk":"11933810439","pt":1724317621120,"mc":[{"id":"1.232092849","rc":[{"batb":[[1,2.64,5],[2,2.4,41.09]],"ltp":2.98,"tv":1.48,"id":19587212}]}]}
{"op":"mcm","clk":"11933810534","pt":1724317623538,"mc":[{"id":"1.232092849","rc":[{"batb":[[0,2.66,4]],"ltp":2.98,"tv":1.48,"id":19587212}]}]}
{"op":"mcm","clk":"11933810627","pt":1724317625964,"mc":[{"id":"1.232092849","rc":[{"batb":[[0,2.66,10]],"ltp":2.98,"tv":1.48,"id":19587212}]}]}
{"op":"mcm","clk":"11933810765","pt":1724317629355,"mc":[{"id":"1.232092849","rc":[{"batb":[[0,2.68,4]],"ltp":2.98,"tv":1.48,"id":19587212}]}]}
{"op":"mcm","clk":"11933810880","pt":1724317631732,"mc":[{"id":"1.232092849","rc":[{"batb":[[0,2.66,10]],"ltp":2.98,"tv":1.48,"id":19587212}]}]}
{"op":"mcm","clk":"11933811015","pt":1724317635074,"mc":[{"id":"1.232092849","rc":[{"batb":[[0,2.68,4]],"ltp":2.98,"tv":1.48,"id":19587212}]}]}
{"op":"mcm","clk":"11933811130","pt":1724317637335,"mc":[{"id":"1.232092849","rc":[{"batb":[[0,2.66,10]],"ltp":2.98,"tv":1.48,"id":19587212}]}]}
{"op":"mcm","clk":"11933811335","pt":1724317640575,"mc":[{"id":"1.232092849","rc":[{"batb":[[0,2.64,5],[1,2.4,41.09],[2,2,6.17]],"ltp":2.98,"tv":1.48,"id":19587212}]}]}
{"op":"mcm","clk":"11933811360","pt":1724317640945,"mc":[{"id":"1.232092849","rc":[{"batb":[[0,2.66,4],[1,2.64,5],[2,2.4,41.09]],"ltp":2.98,"tv":1.48,"id":19587212}]}]}
{"op":"mcm","clk":"11933811480","pt":1724317643465,"mc":[{"id":"1.232092849","rc":[{"batb":[[0,2.66,10]],"ltp":2.98,"tv":1.48,"id":19587212}]}]}
{"op":"mcm","clk":"11933811639","pt":1724317646862,"mc":[{"id":"1.232092849","rc":[{"batb":[[0,2.68,4]],"ltp":2.98,"tv":1.48,"id":19587212}]}]}
{"op":"mcm","clk":"11933811726","pt":1724317649483,"mc":[{"id":"1.232092849","rc":[{"batb":[[0,2.66,10]],"ltp":2.98,"tv":1.48,"id":19587212}]}]}
{"op":"mcm","clk":"11933811885","pt":1724317653088,"mc":[{"id":"1.232092849","rc":[{"batb":[[0,2.66,4]],"ltp":2.98,"tv":1.48,"id":19587212}]}]}
{"op":"mcm","clk":"11933811989","pt":1724317655464,"mc":[{"id":"1.232092849","rc":[{"batb":[[0,2.68,10]],"ltp":2.98,"tv":1.48,"id":19587212}]}]}
{"op":"mcm","clk":"11933812157","pt":1724317659073,"mc":[{"id":"1.232092849","rc":[{"batb":[[0,2.66,4]],"ltp":2.98,"tv":1.48,"id":19587212}]}]}
{"op":"mcm","clk":"11933812264","pt":1724317661299,"mc":[{"id":"1.232092849","rc":[{"batb":[[0,2.68,10]],"ltp":2.98,"tv":1.48,"id":19587212}]}]}
{"op":"mcm","clk":"11933812418","pt":1724317664901,"mc":[{"id":"1.232092849","rc":[{"batb":[[0,2.66,4]],"ltp":2.98,"tv":1.48,"id":19587212}]}]}
{"op":"mcm","clk":"11933812521","pt":1724317667164,"mc":[{"id":"1.232092849","rc":[{"batb":[[0,2.68,10]],"ltp":2.98,"tv":1.48,"id":19587212}]}]}
{"op":"mcm","clk":"11933812674","pt":1724317670505,"mc":[{"id":"1.232092849","rc":[{"batb":[[0,2.64,5],[1,2.4,41.09],[2,2,6.17]],"ltp":2.98,"tv":1.48,"id":19587212}]}]}
{"op":"mcm","clk":"11933812686","pt":1724317670704,"mc":[{"id":"1.232092849","rc":[{"batb":[[0,2.66,4],[1,2.64,5],[2,2.4,41.09]],"ltp":2.98,"tv":1.48,"id":19587212}]}]}
{"op":"mcm","clk":"11933812810","pt":1724317673289,"mc":[{"id":"1.232092849","rc":[{"batb":[[0,2.66,10]],"ltp":2.98,"tv":1.48,"id":19587212}]}]}
{"op":"mcm","clk":"11933812959","pt":1724317676481,"mc":[{"id":"1.232092849","rc":[{"batb":[[0,2.68,4]],"ltp":2.98,"tv":1.48,"id":19587212}]}]}
{"op":"mcm","clk":"11933813053","pt":1724317678402,"mc":[{"id":"1.232092849","rc":[{"batb":[[0,2.64,5],[1,2.4,41.09],[2,2,6.17]],"ltp":2.98,"tv":1.48,"id":19587212}]}]}
{"op":"mcm","clk":"11933813122","pt":1724317680095,"mc":[{"id":"1.232092849","rc":[{"batb":[[0,2.66,10],[1,2.64,5],[2,2.4,41.09]],"ltp":2.98,"tv":1.48,"id":19587212}]}]}
{"op":"mcm","clk":"11933813307","pt":1724317683484,"mc":[{"id":"1.232092849","rc":[{"batb":[[0,2.64,5],[1,2.4,41.09],[2,2,6.17]],"ltp":2.98,"tv":1.48,"id":19587212}]}]}
{"op":"mcm","clk":"11933813313","pt":1724317683588,"mc":[{"id":"1.232092849","rc":[{"batb":[[0,2.66,4],[1,2.64,5],[2,2.4,41.09]],"ltp":2.98,"tv":1.48,"id":19587212}]}]}
{"op":"mcm","clk":"11933813437","pt":1724317686105,"mc":[{"id":"1.232092849","rc":[{"batb":[[0,2.66,10]],"ltp":2.98,"tv":1.48,"id":19587212}]}]}
{"op":"mcm","clk":"11933813619","pt":1724317689502,"mc":[{"id":"1.232092849","rc":[{"batb":[[0,2.68,4]],"ltp":2.98,"tv":1.48,"id":19587212}]}]}
{"op":"mcm","clk":"11933813746","pt":1724317692228,"mc":[{"id":"1.232092849","rc":[{"batb":[[0,2.66,10]],"ltp":2.98,"tv":1.48,"id":19587212}]}]}
{"op":"mcm","clk":"11933813826","pt":1724317694322,"mc":[{"id":"1.232092849","rc":[{"batb":[[0,2.68,4],[1,2.66,10],[2,2.64,5]],"ltp":2.98,"tv":1.48,"id":19587212}]}]}
{"op":"mcm","clk":"11933813958","pt":1724317696528,"mc":[{"id":"1.232092849","rc":[{"batb":[[0,2.64,5],[1,2.4,41.09],[2,2,6.17]],"ltp":2.98,"tv":1.48,"id":19587212}]}]}
{"op":"mcm","clk":"11933814437","pt":1724317706390,"mc":[{"id":"1.232092849","rc":[{"batb":[[0,2.66,14],[1,2.64,5],[2,2.4,41.09]],"ltp":2.98,"tv":1.48,"id":19587212}]}]}
{"op":"mcm","clk":"11933814529","pt":1724317708858,"mc":[{"id":"1.232092849","rc":[{"batb":[[0,2.66,10]],"ltp":2.98,"tv":1.48,"id":19587212}]}]}
{"op":"mcm","clk":"11933814577","pt":1724317709881,"mc":[{"id":"1.232092849","rc":[{"batb":[[0,2.64,5],[1,2.4,41.09],[2,2,6.17]],"ltp":2.98,"tv":1.48,"id":19587212}]}]}
{"op":"mcm","clk":"11933814643","pt":1724317711495,"mc":[{"id":"1.232092849","rc":[{"batb":[[0,2.66,4],[1,2.64,5],[2,2.4,41.09]],"ltp":2.98,"tv":1.48,"id":19587212}]}]}
{"op":"mcm","clk":"11933814750","pt":1724317713752,"mc":[{"id":"1.232092849","rc":[{"batb":[[0,2.68,10]],"ltp":2.98,"tv":1.48,"id":19587212}]}]}
{"op":"mcm","clk":"11933814898","pt":1724317717361,"mc":[{"id":"1.232092849","rc":[{"batb":[[0,2.66,4]],"ltp":2.98,"tv":1.48,"id":19587212}]}]}
{"op":"mcm","clk":"11933814989","pt":1724317719575,"mc":[{"id":"1.232092849","rc":[{"batb":[[0,2.64,5],[1,2.4,41.09],[2,2,6.17]],"ltp":2.98,"tv":1.48,"id":19587212}]}]}
{"op":"mcm","clk":"11933814994","pt":1724317719675,"mc":[{"id":"1.232092849","rc":[{"batb":[[0,2.66,10],[1,2.64,5],[2,2.4,41.09]],"ltp":2.98,"tv":1.48,"id":19587212}]}]}
{"op":"mcm","clk":"11933815181","pt":1724317723173,"mc":[{"id":"1.232092849","rc":[{"batb":[[0,2.66,4]],"ltp":2.98,"tv":1.48,"id":19587212}]}]}
{"op":"mcm","clk":"11933815309","pt":1724317725582,"mc":[{"id":"1.232092849","rc":[{"batb":[[0,2.66,10]],"ltp":2.98,"tv":1.48,"id":19587212}]}]}
{"op":"mcm","clk":"11933815461","pt":1724317728882,"mc":[{"id":"1.232092849","rc":[{"batb":[[0,2.66,4]],"ltp":2.98,"tv":1.48,"id":19587212}]}]}
{"op":"mcm","clk":"11933815586","pt":1724317731198,"mc":[{"id":"1.232092849","rc":[{"batb":[[0,2.66,10]],"ltp":2.98,"tv":1.48,"id":19587212}]}]}
{"op":"mcm","clk":"11933815779","pt":1724317734785,"mc":[{"id":"1.232092849","rc":[{"batb":[[0,2.66,4]],"ltp":2.98,"tv":1.48,"id":19587212}]}]}
{"op":"mcm","clk":"11933815913","pt":1724317737196,"mc":[{"id":"1.232092849","rc":[{"batb":[[0,2.66,10]],"ltp":2.98,"tv":1.48,"id":19587212}]}]}
{"op":"mcm","clk":"11933816063","pt":1724317740525,"mc":[{"id":"1.232092849","rc":[{"batb":[[0,2.64,5],[1,2.4,41.09],[2,2,6.17]],"ltp":2.98,"tv":1.48,"id":19587212}]}]}
{"op":"mcm","clk":"11933816071","pt":1724317740729,"mc":[{"id":"1.232092849","rc":[{"batb":[[0,2.66,4],[1,2.64,5],[2,2.4,41.09]],"ltp":2.98,"tv":1.48,"id":19587212}]}]}
{"op":"mcm","clk":"11933816168","pt":1724317743000,"mc":[{"id":"1.232092849","rc":[{"batb":[[0,2.66,10]],"ltp":2.98,"tv":1.48,"id":19587212}]}]}
{"op":"mcm","clk":"11933816304","pt":1724317746442,"mc":[{"id":"1.232092849","rc":[{"batb":[[0,2.66,4]],"ltp":2.98,"tv":1.48,"id":19587212}]}]}
{"op":"mcm","clk":"11933816372","pt":1724317748406,"mc":[{"id":"1.232092849","rc":[{"batb":[[0,2.68,10],[1,2.66,4],[2,2.64,5]],"ltp":2.98,"tv":1.48,"id":19587212}]}]}
{"op":"mcm","clk":"11933816389","pt":1724317748606,"mc":[{"id":"1.232092849","rc":[{"batb":[[1,2.64,5],[2,2.4,41.09]],"ltp":2.98,"tv":1.48,"id":19587212}]}]}
{"op":"mcm","clk":"11933816490","pt":1724317751949,"mc":[{"id":"1.232092849","rc":[{"batb":[[0,2.66,4]],"ltp":2.98,"tv":1.48,"id":19587212}]}]}
{"op":"mcm","clk":"11933816569","pt":1724317754231,"mc":[{"id":"1.232092849","rc":[{"batb":[[0,2.68,10]],"ltp":2.98,"tv":1.48,"id":19587212}]}]}
{"op":"mcm","clk":"11933816651","pt":1724317756458,"mc":[{"id":"1.232092849","rc":[{"batb":[[0,2.7,4],[1,2.68,10],[2,2.64,5]],"ltp":2.98,"tv":1.48,"id":19587212}]}]}
{"op":"mcm","clk":"11933816696","pt":1724317757437,"mc":[{"id":"1.232092849","rc":[{"batb":[[1,2.64,5],[2,2.4,41.09]],"ltp":2.98,"tv":1.48,"id":19587212}]}]}
{"op":"mcm","clk":"11933816753","pt":1724317758824,"mc":[{"id":"1.232092849","rc":[{"batb":[[0,2.64,5],[1,2.4,41.09],[2,2,6.17]],"ltp":2.98,"tv":1.48,"id":19587212}]}]}
{"op":"mcm","clk":"11933816877","pt":1724317761033,"mc":[{"id":"1.232092849","rc":[{"batb":[[0,2.66,14],[1,2.64,5],[2,2.4,41.09]],"ltp":2.98,"tv":1.48,"id":19587212}]}]}
{"op":"mcm","clk":"11933817000","pt":1724317763347,"mc":[{"id":"1.232092849","rc":[{"batb":[[0,2.66,10]],"ltp":2.98,"tv":1.48,"id":19587212}]}]}
{"op":"mcm","clk":"11933817043","pt":1724317764333,"mc":[{"id":"1.232092849","rc":[{"batb":[[0,2.64,5],[1,2.4,41.09],[2,2,6.17]],"ltp":2.98,"tv":1.48,"id":19587212}]}]}
{"op":"mcm","clk":"11933817128","pt":1724317766960,"mc":[{"id":"1.232092849","rc":[{"batb":[[0,2.66,14],[1,2.64,5],[2,2.4,41.09]],"ltp":2.98,"tv":1.48,"id":19587212}]}]}
{"op":"mcm","clk":"11933817237","pt":1724317769174,"mc":[{"id":"1.232092849","rc":[{"batb":[[0,2.66,10]],"ltp":2.98,"tv":1.48,"id":19587212}]}]}
{"op":"mcm","clk":"11933817301","pt":1724317770260,"mc":[{"id":"1.232092849","rc":[{"batb":[[0,2.64,5],[1,2.4,41.09],[2,2,6.17]],"ltp":2.98,"tv":1.48,"id":19587212}]}]}
{"op":"mcm","clk":"11933817416","pt":1724317772474,"mc":[{"id":"1.232092849","rc":[{"batb":[[0,2.66,14],[1,2.64,5],[2,2.4,41.09]],"ltp":2.98,"tv":1.48,"id":19587212}]}]}
{"op":"mcm","clk":"11933817511","pt":1724317774949,"mc":[{"id":"1.232092849","rc":[{"batb":[[0,2.66,10]],"ltp":2.98,"tv":1.48,"id":19587212}]}]}
{"op":"mcm","clk":"11933817537","pt":1724317775870,"mc":[{"id":"1.232092849","rc":[{"batb":[[0,2.64,5],[1,2.4,41.09],[2,2,6.17]],"ltp":2.98,"tv":1.48,"id":19587212}]}]}
{"op":"mcm","clk":"11933817587","pt":1724317777054,"mc":[{"id":"1.232092849","rc":[{"batb":[[0,2.66,4],[1,2.64,5],[2,2.4,41.09]],"ltp":2.98,"tv":1.48,"id":19587212}]}]}
{"op":"mcm","clk":"11933817665","pt":1724317778492,"mc":[{"id":"1.232092849","rc":[{"batb":[[0,2.68,10],[1,2.66,4],[2,2.64,5]],"ltp":2.98,"tv":1.48,"id":19587212}]}]}
{"op":"mcm","clk":"11933817732","pt":1724317779483,"mc":[{"id":"1.232092849","rc":[{"batb":[[1,2.64,5],[2,2.4,41.09]],"ltp":2.98,"tv":1.48,"id":19587212}]}]}
{"op":"mcm","clk":"11933817846","pt":1724317781878,"mc":[{"id":"1.232092849","rc":[{"batb":[[0,2.66,4]],"ltp":2.98,"tv":1.48,"id":19587212}]}]}
{"op":"mcm","clk":"11933817965","pt":1724317784461,"mc":[{"id":"1.232092849","rc":[{"batb":[[0,2.66,10]],"ltp":2.98,"tv":1.48,"id":19587212}]}]}
{"op":"mcm","clk":"11933818127","pt":1724317787397,"mc":[{"id":"1.232092849","rc":[{"batb":[[0,2.68,4],[1,2.66,10],[2,2.64,5]],"ltp":2.98,"tv":1.48,"id":19587212}]}]}
{"op":"mcm","clk":"11933818159","pt":1724317787762,"mc":[{"id":"1.232092849","rc":[{"batb":[[1,2.64,5],[2,2.4,41.09]],"ltp":2.98,"tv":1.48,"id":19587212}]}]}
{"op":"mcm","clk":"11933818320","pt":1724317789985,"mc":[{"id":"1.232092849","rc":[{"batb":[[0,2.66,10]],"ltp":2.98,"tv":1.48,"id":19587212}]}]}
{"op":"mcm","clk":"11933818491","pt":1724317793088,"mc":[{"id":"1.232092849","rc":[{"batb":[[0,2.68,4]],"ltp":2.98,"tv":1.48,"id":19587212}]}]}
{"op":"mcm","clk":"11933818578","pt":1724317795347,"mc":[{"id":"1.232092849","rc":[{"batb":[[0,2.66,10]],"ltp":2.98,"tv":1.48,"id":19587212}]}]}
{"op":"mcm","clk":"11933818723","pt":1724317798539,"mc":[{"id":"1.232092849","rc":[{"batb":[[0,2.68,4],[1,2.66,10],[2,2.64,5]],"ltp":2.98,"tv":1.48,"id":19587212}]}]}
{"op":"mcm","clk":"11933818727","pt":1724317798646,"mc":[{"id":"1.232092849","rc":[{"batb":[[1,2.64,5],[2,2.4,41.09]],"ltp":2.98,"tv":1.48,"id":19587212}]}]}
{"op":"mcm","clk":"11933818868","pt":1724317801178,"mc":[{"id":"1.232092849","rc":[{"batb":[[0,2.66,10]],"ltp":2.98,"tv":1.48,"id":19587212}]}]}
{"op":"mcm","clk":"11933819012","pt":1724317804460,"mc":[{"id":"1.232092849","rc":[{"batb":[[0,2.64,5],[1,2.4,41.09],[2,2,6.17]],"ltp":2.98,"tv":1.48,"id":19587212}]}]}
{"op":"mcm","clk":"11933819021","pt":1724317804666,"mc":[{"id":"1.232092849","rc":[{"batb":[[0,2.66,4],[1,2.64,5],[2,2.4,41.09]],"ltp":2.98,"tv":1.48,"id":19587212}]}]}
{"op":"mcm","clk":"11933819119","pt":1724317807096,"mc":[{"id":"1.232092849","rc":[{"batb":[[0,2.66,10]],"ltp":2.98,"tv":1.48,"id":19587212}]}]}
{"op":"mcm","clk":"11933819274","pt":1724317810301,"mc":[{"id":"1.232092849","rc":[{"batb":[[0,2.68,4]],"ltp":2.98,"tv":1.48,"id":19587212}]}]}
{"op":"mcm","clk":"11933819394","pt":1724317812214,"mc":[{"id":"1.232092849","rc":[{"batb":[[0,2.64,5],[1,2.4,41.09],[2,2,6.17]],"ltp":2.98,"tv":1.48,"id":19587212}]}]}
{"op":"mcm","clk":"11933819628","pt":1724317817283,"mc":[{"id":"1.232092849","rc":[{"batb":[[0,2.66,14],[1,2.64,5],[2,2.4,41.09]],"ltp":2.98,"tv":1.48,"id":19587212}]}]}
{"op":"mcm","clk":"11933819727","pt":1724317819399,"mc":[{"id":"1.232092849","rc":[{"batb":[[0,2.66,10]],"ltp":2.98,"tv":1.48,"id":19587212}]}]}
{"op":"mcm","clk":"11933819778","pt":1724317820691,"mc":[{"id":"1.232092849","rc":[{"batb":[[0,2.64,5],[1,2.4,41.09],[2,2,6.17]],"ltp":2.98,"tv":1.48,"id":19587212}]}]}
{"op":"mcm","clk":"11933819891","pt":1724317823630,"mc":[{"id":"1.232092849","rc":[{"batb":[[0,2.66,14],[1,2.64,5],[2,2.4,41.09]],"ltp":2.98,"tv":1.48,"id":19587212}]}]}
{"op":"mcm","clk":"11933820001","pt":1724317825800,"mc":[{"id":"1.232092849","rc":[{"batb":[[0,2.66,10]],"ltp":2.98,"tv":1.48,"id":19587212}]}]}
{"op":"mcm","clk":"11933820067","pt":1724317826935,"mc":[{"id":"1.232092849","rc":[{"batb":[[0,2.64,5],[1,2.4,41.09],[2,2,6.17]],"ltp":2.98,"tv":1.48,"id":19587212}]}]}
{"op":"mcm","clk":"11933820229","pt":1724317831114,"mc":[{"id":"1.232092849","rc":[{"batb":[[0,2.66,14],[1,2.64,5],[2,2.4,41.09]],"ltp":2.98,"tv":1.48,"id":19587212}]}]}
{"op":"mcm","clk":"11933820349","pt":1724317833545,"mc":[{"id":"1.232092849","rc":[{"batb":[[0,2.66,10]],"ltp":2.98,"tv":1.48,"id":19587212}]}]}
{"op":"mcm","clk":"11933820394","pt":1724317834626,"mc":[{"id":"1.232092849","rc":[{"batb":[[0,2.64,5],[1,2.4,41.09],[2,2,6.17]],"ltp":2.98,"tv":1.48,"id":19587212}]}]}
{"op":"mcm","clk":"11933820461","pt":1724317835915,"mc":[{"id":"1.232092849","rc":[{"batb":[[0,2.66,4],[1,2.64,5],[2,2.4,41.09]],"ltp":2.98,"tv":1.48,"id":19587212}]}]}
{"op":"mcm","clk":"11933820572","pt":1724317838431,"mc":[{"id":"1.232092849","rc":[{"batb":[[0,2.66,10]],"ltp":2.98,"tv":1.48,"id":19587212}]}]}
{"op":"mcm","clk":"11933820721","pt":1724317842077,"mc":[{"id":"1.232092849","rc":[{"batb":[[0,2.66,4]],"ltp":2.98,"tv":1.48,"id":19587212}]}]}
{"op":"mcm","clk":"11933820808","pt":1724317844333,"mc":[{"id":"1.232092849","rc":[{"batb":[[0,2.64,5],[1,2.4,41.09],[2,2,6.17]],"ltp":2.98,"tv":1.48,"id":19587212}]}]}
{"op":"mcm","clk":"11933820823","pt":1724317844640,"mc":[{"id":"1.232092849","rc":[{"batb":[[0,2.66,10],[1,2.64,5],[2,2.4,41.09]],"ltp":2.98,"tv":1.48,"id":19587212}]}]}
{"op":"mcm","clk":"11933820945","pt":1724317848023,"mc":[{"id":"1.232092849","rc":[{"batb":[[0,2.66,4]],"ltp":2.98,"tv":1.48,"id":19587212}]}]}
{"op":"mcm","clk":"11933821035","pt":1724317850529,"mc":[{"id":"1.232092849","rc":[{"batb":[[0,2.66,10]],"ltp":2.98,"tv":1.48,"id":19587212}]}]}
{"op":"mcm","clk":"11933821136","pt":1724317854116,"mc":[{"id":"1.232092849","rc":[{"batb":[[0,2.66,4]],"ltp":2.98,"tv":1.48,"id":19587212}]}]}
{"op":"mcm","clk":"11933821205","pt":1724317856524,"mc":[{"id":"1.232092849","rc":[{"batb":[[0,2.64,5],[1,2.4,41.09],[2,2,6.17]],"ltp":2.98,"tv":1.48,"id":19587212}]}]}
{"op":"mcm","clk":"11933821213","pt":1724317856727,"mc":[{"id":"1.232092849","rc":[{"batb":[[0,2.66,10],[1,2.64,5],[2,2.4,41.09]],"ltp":2.98,"tv":1.48,"id":19587212}]}]}
{"op":"mcm","clk":"11933821400","pt":1724317860141,"mc":[{"id":"1.232092849","rc":[{"batb":[[0,2.66,4]],"ltp":2.98,"tv":1.48,"id":19587212}]}]}
{"op":"mcm","clk":"11933821483","pt":1724317862538,"mc":[{"id":"1.232092849","rc":[{"batb":[[0,2.64,5],[1,2.4,41.09],[2,2,6.17]],"ltp":2.98,"tv":1.48,"id":19587212}]}]}
{"op":"mcm","clk":"11933821490","pt":1724317862641,"mc":[{"id":"1.232092849","rc":[{"batb":[[0,2.66,10],[1,2.64,5],[2,2.4,41.09]],"ltp":2.98,"tv":1.48,"id":19587212}]}]}
{"op":"mcm","clk":"11933821645","pt":1724317866121,"mc":[{"id":"1.232092849","rc":[{"batb":[[0,2.66,4]],"ltp":2.98,"tv":1.48,"id":19587212}]}]}
{"op":"mcm","clk":"11933821754","pt":1724317868532,"mc":[{"id":"1.232092849","rc":[{"batb":[[0,2.64,5],[1,2.4,41.09],[2,2,6.17]],"ltp":2.98,"tv":1.48,"id":19587212}]}]}
{"op":"mcm","clk":"11933821757","pt":1724317868633,"mc":[{"id":"1.232092849","rc":[{"batb":[[0,2.66,10],[1,2.64,5],[2,2.4,41.09]],"ltp":2.98,"tv":1.48,"id":19587212}]}]}
{"op":"mcm","clk":"11933821956","pt":1724317872337,"mc":[{"id":"1.232092849","rc":[{"batb":[[0,2.66,4]],"ltp":2.98,"tv":1.48,"id":19587212}]}]}
{"op":"mcm","clk":"11933822080","pt":1724317875054,"mc":[{"id":"1.232092849","rc":[{"batb":[[0,2.66,10]],"ltp":2.98,"tv":1.48,"id":19587212}]}]}
{"op":"mcm","clk":"11933822214","pt":1724317878550,"mc":[{"id":"1.232092849","rc":[{"batb":[[0,2.68,4]],"ltp":2.98,"tv":1.48,"id":19587212}]}]}
{"op":"mcm","clk":"11933822279","pt":1724317880858,"mc":[{"id":"1.232092849","rc":[{"batb":[[0,2.66,10]],"ltp":2.98,"tv":1.48,"id":19587212}]}]}
{"op":"mcm","clk":"11933822429","pt":1724317884365,"mc":[{"id":"1.232092849","rc":[{"batb":[[0,2.66,4]],"ltp":2.98,"tv":1.48,"id":19587212}]}]}
{"op":"mcm","clk":"11933822529","pt":1724317886980,"mc":[{"id":"1.232092849","rc":[{"batb":[[0,2.66,10]],"ltp":2.98,"tv":1.48,"id":19587212}]}]}
{"op":"mcm","clk":"11933822649","pt":1724317890469,"mc":[{"id":"1.232092849","rc":[{"batb":[[0,2.66,4]],"ltp":2.98,"tv":1.48,"id":19587212}]}]}
{"op":"mcm","clk":"11933822742","pt":1724317892884,"mc":[{"id":"1.232092849","rc":[{"batb":[[0,2.66,10]],"ltp":2.98,"tv":1.48,"id":19587212}]}]}
{"op":"mcm","clk":"11933822864","pt":1724317896374,"mc":[{"id":"1.232092849","rc":[{"batb":[[0,2.66,4]],"ltp":2.98,"tv":1.48,"id":19587212}]}]}
{"op":"mcm","clk":"11933822948","pt":1724317898576,"mc":[{"id":"1.232092849","rc":[{"batb":[[0,2.64,5],[1,2.4,41.09],[2,2,6.17]],"ltp":2.98,"tv":1.48,"id":19587212}]}]}
{"op":"mcm","clk":"11933822953","pt":1724317898680,"mc":[{"id":"1.232092849","rc":[{"batb":[[0,2.66,10],[1,2.64,5],[2,2.4,41.09]],"ltp":2.98,"tv":1.48,"id":19587212}]}]}
{"op":"mcm","clk":"11933823059","pt":1724317902114,"mc":[{"id":"1.232092849","rc":[{"batb":[[0,2.66,4]],"ltp":2.98,"tv":1.48,"id":19587212}]}]}
{"op":"mcm","clk":"11933823147","pt":1724317904493,"mc":[{"id":"1.232092849","rc":[{"batb":[[0,2.64,5],[1,2.4,41.09],[2,2,6.17]],"ltp":2.98,"tv":1.48,"id":19587212}]}]}
{"op":"mcm","clk":"11933823154","pt":1724317904593,"mc":[{"id":"1.232092849","rc":[{"batb":[[0,2.66,10],[1,2.64,5],[2,2.4,41.09]],"ltp":2.98,"tv":1.48,"id":19587212}]}]}
{"op":"mcm","clk":"11933823268","pt":1724317908004,"mc":[{"id":"1.232092849","rc":[{"batb":[[0,2.66,4]],"ltp":2.98,"tv":1.48,"id":19587212}]}]}
{"op":"mcm","clk":"11933823329","pt":1724317910417,"mc":[{"id":"1.232092849","rc":[{"batb":[[0,2.64,5],[1,2.4,41.09],[2,2,6.17]],"ltp":2.98,"tv":1.48,"id":19587212}]}]}
{"op":"mcm","clk":"11933823336","pt":1724317910622,"mc":[{"id":"1.232092849","rc":[{"batb":[[0,2.66,10],[1,2.64,5],[2,2.4,41.09]],"ltp":2.98,"tv":1.48,"id":19587212}]}]}
{"op":"mcm","clk":"11933823435","pt":1724317913296,"mc":[{"id":"1.232092849","rc":[{"batb":[[0,2.68,4],[1,2.66,10],[2,2.64,5]],"ltp":2.98,"tv":1.48,"id":19587212}]}]}
{"op":"mcm","clk":"11933823462","pt":1724317914113,"mc":[{"id":"1.232092849","rc":[{"batb":[[1,2.64,5],[2,2.4,41.09]],"ltp":2.98,"tv":1.48,"id":19587212}]}]}
{"op":"mcm","clk":"11933823512","pt":1724317915807,"mc":[{"id":"1.232092849","rc":[{"batb":[[0,2.64,5],[1,2.4,41.09],[2,2,6.17]],"ltp":2.98,"tv":1.48,"id":19587212}]}]}
{"op":"mcm","clk":"11933823623","pt":1724317918108,"mc":[{"id":"1.232092849","rc":[{"batb":[[0,2.68,4],[1,2.66,10],[2,2.64,5]],"ltp":2.98,"tv":1.48,"id":19587212}]}]}
{"op":"mcm","clk":"11933823725","pt":1724317920527,"mc":[{"id":"1.232092849","rc":[{"batb":[[0,2.66,10],[1,2.64,5],[2,2.4,41.09]],"ltp":2.98,"tv":1.48,"id":19587212}]}]}
{"op":"mcm","clk":"11933823758","pt":1724317921306,"mc":[{"id":"1.232092849","rc":[{"batb":[[0,2.64,5],[1,2.4,41.09],[2,2,6.17]],"ltp":2.98,"tv":1.48,"id":19587212}]}]}
{"op":"mcm","clk":"11933824961","pt":1724317949652,"mc":[{"id":"1.232092849","rc":[{"batb":[[0,2.66,14],[1,2.64,5],[2,2.4,41.09]],"ltp":2.98,"tv":1.48,"id":19587212}]}]}
{"op":"mcm","clk":"11933825117","pt":1724317953456,"mc":[{"id":"1.232092849","rc":[{"batb":[[0,2.64,5],[1,2.4,41.09],[2,2,6.17]],"ltp":2.98,"tv":1.48,"id":19587212}]}]}
{"op":"mcm","clk":"11933825441","pt":1724317961483,"mc":[{"id":"1.232092849","rc":[{"batb":[[0,2.66,14],[1,2.64,5],[2,2.4,41.09]],"ltp":2.98,"tv":1.48,"id":19587212}]}]}
{"op":"mcm","clk":"11933825554","pt":1724317964171,"mc":[{"id":"1.232092849","rc":[{"batb":[[0,2.66,10]],"ltp":2.98,"tv":1.48,"id":19587212}]}]}
{"op":"mcm","clk":"11933825609","pt":1724317965159,"mc":[{"id":"1.232092849","rc":[{"batb":[[0,2.64,5],[1,2.4,41.09],[2,2,6.17]],"ltp":2.98,"tv":1.48,"id":19587212}]}]}
{"op":"mcm","clk":"11933825804","pt":1724317970874,"mc":[{"id":"1.232092849","rc":[{"batb":[[0,2.66,14],[1,2.64,5],[2,2.4,41.09]],"ltp":2.98,"tv":1.48,"id":19587212}]}]}
{"op":"mcm","clk":"11933825885","pt":1724317973364,"mc":[{"id":"1.232092849","rc":[{"batb":[[0,2.66,10]],"ltp":2.98,"tv":1.48,"id":19587212}]}]}
{"op":"mcm","clk":"11933825920","pt":1724317974183,"mc":[{"id":"1.232092849","rc":[{"batb":[[0,2.64,5],[1,2.4,41.09],[2,2,6.17]],"ltp":2.98,"tv":1.48,"id":19587212}]}]}
{"op":"mcm","clk":"11933826267","pt":1724317985796,"mc":[{"id":"1.232092849","rc":[{"batb":[[0,2.66,14],[1,2.64,5],[2,2.4,41.09]],"ltp":2.98,"tv":1.48,"id":19587212}]}]}
{"op":"mcm","clk":"11933826403","pt":1724317988391,"mc":[{"id":"1.232092849","rc":[{"batb":[[0,2.66,10]],"ltp":2.98,"tv":1.48,"id":19587212}]}]}
{"op":"mcm","clk":"11933826446","pt":1724317989421,"mc":[{"id":"1.232092849","rc":[{"batb":[[0,2.64,5],[1,2.4,41.09],[2,2,6.17]],"ltp":2.98,"tv":1.48,"id":19587212}]}]}
{"op":"mcm","clk":"11933826761","pt":1724317999004,"mc":[{"id":"1.232092849","rc":[{"batb":[[0,2.66,14],[1,2.64,5],[2,2.4,41.09]],"ltp":2.98,"tv":1.48,"id":19587212}]}]}
{"op":"mcm","clk":"11933826865","pt":1724318001728,"mc":[{"id":"1.232092849","rc":[{"batb":[[0,2.66,10]],"ltp":2.98,"tv":1.48,"id":19587212}]}]}
{"op":"mcm","clk":"11933826913","pt":1724318002710,"mc":[{"id":"1.232092849","rc":[{"batb":[[0,2.64,5],[1,2.4,41.09],[2,2,6.17]],"ltp":2.98,"tv":1.48,"id":19587212}]}]}
{"op":"mcm","clk":"11933827309","pt":1724318012542,"mc":[{"id":"1.232092849","rc":[{"batb":[[0,2.66,14],[1,2.64,5],[2,2.4,41.09]],"ltp":2.98,"tv":1.48,"id":19587212}]}]}
{"op":"mcm","clk":"11933827365","pt":1724318014847,"mc":[{"id":"1.232092849","rc":[{"batb":[[0,2.66,10]],"ltp":2.98,"tv":1.48,"id":19587212}]}]}
{"op":"mcm","clk":"11933827412","pt":1724318016135,"mc":[{"id":"1.232092849","rc":[{"batb":[[0,2.64,5],[1,2.4,41.09],[2,2,6.17]],"ltp":2.98,"tv":1.48,"id":19587212}]}]}
{"op":"mcm","clk":"11933827666","pt":1724318022428,"mc":[{"id":"1.232092849","rc":[{"batb":[[0,2.66,14],[1,2.64,5],[2,2.4,41.09]],"ltp":2.98,"tv":1.48,"id":19587212}]}]}
{"op":"mcm","clk":"11933827757","pt":1724318024736,"mc":[{"id":"1.232092849","rc":[{"batb":[[0,2.66,10]],"ltp":2.98,"tv":1.48,"id":19587212}]}]}
{"op":"mcm","clk":"11933827817","pt":1724318025765,"mc":[{"id":"1.232092849","rc":[{"batb":[[0,2.64,5],[1,2.4,41.09],[2,2,6.17]],"ltp":2.98,"tv":1.48,"id":19587212}]}]}
{"op":"mcm","clk":"11933827914","pt":1724318028229,"mc":[{"id":"1.232092849","rc":[{"batb":[[0,2.66,14],[1,2.64,5],[2,2.4,41.09]],"ltp":2.98,"tv":1.48,"id":19587212}]}]}
{"op":"mcm","clk":"11933828033","pt":1724318030847,"mc":[{"id":"1.232092849","rc":[{"batb":[[0,2.66,10]],"ltp":2.98,"tv":1.48,"id":19587212}]}]}
{"op":"mcm","clk":"11933828069","pt":1724318031624,"mc":[{"id":"1.232092849","rc":[{"batb":[[0,2.64,5],[1,2.4,41.09],[2,2,6.17]],"ltp":2.98,"tv":1.48,"id":19587212}]}]}
{"op":"mcm","clk":"11933828143","pt":1724318033157,"mc":[{"id":"1.232092849","rc":[{"batb":[[0,2.66,4],[1,2.64,5],[2,2.4,41.09]],"ltp":2.98,"tv":1.48,"id":19587212}]}]}
{"op":"mcm","clk":"11933828236","pt":1724318035565,"mc":[{"id":"1.232092849","rc":[{"batb":[[0,2.66,10]],"ltp":2.98,"tv":1.48,"id":19587212}]}]}
{"op":"mcm","clk":"11933828370","pt":1724318038946,"mc":[{"id":"1.232092849","rc":[{"batb":[[0,2.66,4]],"ltp":2.98,"tv":1.48,"id":19587212}]}]}
{"op":"mcm","clk":"11933828459","pt":1724318041469,"mc":[{"id":"1.232092849","rc":[{"batb":[[0,2.66,10]],"ltp":2.98,"tv":1.48,"id":19587212}]}]}
{"op":"mcm","clk":"11933828625","pt":1724318044987,"mc":[{"id":"1.232092849","rc":[{"batb":[[0,2.66,4]],"ltp":2.98,"tv":1.48,"id":19587212}]}]}
{"op":"mcm","clk":"11933828694","pt":1724318047337,"mc":[{"id":"1.232092849","rc":[{"batb":[[0,2.66,10]],"ltp":2.98,"tv":1.48,"id":19587212}]}]}
{"op":"mcm","clk":"11933828822","pt":1724318050772,"mc":[{"id":"1.232092849","rc":[{"batb":[[0,2.66,4]],"ltp":2.98,"tv":1.48,"id":19587212}]}]}
{"op":"mcm","clk":"11933828893","pt":1724318053251,"mc":[{"id":"1.232092849","rc":[{"batb":[[0,2.66,10]],"ltp":2.98,"tv":1.48,"id":19587212}]}]}
{"op":"mcm","clk":"11933828989","pt":1724318056691,"mc":[{"id":"1.232092849","rc":[{"batb":[[0,2.66,4]],"ltp":2.98,"tv":1.48,"id":19587212}]}]}
{"op":"mcm","clk":"11933829070","pt":1724318059361,"mc":[{"id":"1.232092849","rc":[{"batb":[[0,2.66,10]],"ltp":2.98,"tv":1.48,"id":19587212}]}]}
{"op":"mcm","clk":"11933829197","pt":1724318062897,"mc":[{"id":"1.232092849","rc":[{"batb":[[0,2.66,4]],"ltp":2.98,"tv":1.48,"id":19587212}]}]}
{"op":"mcm","clk":"11933829284","pt":1724318065103,"mc":[{"id":"1.232092849","rc":[{"batb":[[0,2.68,10]],"ltp":2.98,"tv":1.48,"id":19587212}]}]}
{"op":"mcm","clk":"11933829400","pt":1724318068483,"mc":[{"id":"1.232092849","rc":[{"batb":[[0,2.7,4]],"ltp":2.98,"tv":1.48,"id":19587212}]}]}
{"op":"mcm","clk":"11933829498","pt":1724318071195,"mc":[{"id":"1.232092849","rc":[{"batb":[[0,2.66,10]],"ltp":2.98,"tv":1.48,"id":19587212}]}]}
{"op":"mcm","clk":"11933829596","pt":1724318074421,"mc":[{"id":"1.232092849","rc":[{"batb":[[0,2.68,4]],"ltp":2.98,"tv":1.48,"id":19587212}]}]}
{"op":"mcm","clk":"11933829657","pt":1724318076215,"mc":[{"id":"1.232092849","rc":[{"batb":[[0,2.64,5],[1,2.4,41.09],[2,2,6.17]],"ltp":2.98,"tv":1.48,"id":19587212}]}]}
{"op":"mcm","clk":"11933829732","pt":1724318078519,"mc":[{"id":"1.232092849","rc":[{"batb":[[0,2.66,14],[1,2.64,5],[2,2.4,41.09]],"ltp":2.98,"tv":1.48,"id":19587212}]}]}
{"op":"mcm","clk":"11933829820","pt":1724318080892,"mc":[{"id":"1.232092849","rc":[{"batb":[[0,2.66,10]],"ltp":2.98,"tv":1.48,"id":19587212}]}]}
{"op":"mcm","clk":"11933829848","pt":1724318081935,"mc":[{"id":"1.232092849","rc":[{"batb":[[0,2.64,5],[1,2.4,41.09],[2,2,6.17]],"ltp":2.98,"tv":1.48,"id":19587212}]}]}
{"op":"mcm","clk":"11933829900","pt":1724318083387,"mc":[{"id":"1.232092849","rc":[{"batb":[[0,2.66,4],[1,2.64,5],[2,2.4,41.09]],"ltp":2.98,"tv":1.48,"id":19587212}]}]}
{"op":"mcm","clk":"11933829930","pt":1724318084627,"mc":[{"id":"1.232092849","rc":[{"batb":[[0,2.68,10],[1,2.66,4],[2,2.64,5]],"ltp":2.98,"tv":1.48,"id":19587212}]}]}
{"op":"mcm","clk":"11933829978","pt":1724318086007,"mc":[{"id":"1.232092849","rc":[{"batb":[[1,2.64,5],[2,2.4,41.09]],"ltp":2.98,"tv":1.48,"id":19587212}]}]}
{"op":"mcm","clk":"11933830046","pt":1724318087898,"mc":[{"id":"1.232092849","rc":[{"batb":[[0,2.64,5],[1,2.4,41.09],[2,2,6.17]],"ltp":2.98,"tv":1.48,"id":19587212}]}]}
{"op":"mcm","clk":"11933830222","pt":1724318093001,"mc":[{"id":"1.232092849","rc":[{"batb":[[0,2.66,14],[1,2.64,5],[2,2.4,41.09]],"ltp":2.98,"tv":1.48,"id":19587212}]}]}
{"op":"mcm","clk":"11933830304","pt":1724318095708,"mc":[{"id":"1.232092849","rc":[{"batb":[[0,2.66,10]],"ltp":2.98,"tv":1.48,"id":19587212}]}]}
{"op":"mcm","clk":"11933830341","pt":1724318096631,"mc":[{"id":"1.232092849","rc":[{"batb":[[0,2.64,5],[1,2.4,41.09],[2,2,6.17]],"ltp":2.98,"tv":1.48,"id":19587212}]}]}
{"op":"mcm","clk":"11933830415","pt":1724318098535,"mc":[{"id":"1.232092849","rc":[{"batb":[[0,2.66,4],[1,2.64,5],[2,2.4,41.09]],"ltp":2.98,"tv":1.48,"id":19587212}]}]}
{"op":"mcm","clk":"11933830426","pt":1724318098742,"mc":[{"id":"1.232092849","rc":[{"batb":[[0,2.68,10],[1,2.66,4],[2,2.64,5]],"ltp":2.98,"tv":1.48,"id":19587212}]}]}
{"op":"mcm","clk":"11933830518","pt":1724318101112,"mc":[{"id":"1.232092849","rc":[{"batb":[[1,2.64,5],[2,2.4,41.09]],"ltp":2.98,"tv":1.48,"id":19587212}]}]}
{"op":"mcm","clk":"11933830555","pt":1724318102146,"mc":[{"id":"1.232092849","rc":[{"batb":[[0,2.64,5],[1,2.4,41.09],[2,2,6.17]],"ltp":2.98,"tv":1.48,"id":19587212}]}]}
{"op":"mcm","clk":"11933830677","pt":1724318105139,"mc":[{"id":"1.232092849","rc":[{"batb":[[0,2.66,14],[1,2.64,5],[2,2.4,41.09]],"ltp":2.98,"tv":1.48,"id":19587212}]}]}
{"op":"mcm","clk":"11933830763","pt":1724318107614,"mc":[{"id":"1.232092849","rc":[{"batb":[[0,2.66,10]],"ltp":2.98,"tv":1.48,"id":19587212}]}]}
{"op":"mcm","clk":"11933830802","pt":1724318108637,"mc":[{"id":"1.232092849","rc":[{"batb":[[0,2.64,5],[1,2.4,41.09],[2,2,6.17]],"ltp":2.98,"tv":1.48,"id":19587212}]}]}
{"op":"mcm","clk":"11933830871","pt":1724318110444,"mc":[{"id":"1.232092849","rc":[{"batb":[[0,2.66,4],[1,2.64,5],[2,2.4,41.09]],"ltp":2.98,"tv":1.48,"id":19587212}]}]}
{"op":"mcm","clk":"11933830961","pt":1724318112717,"mc":[{"id":"1.232092849","rc":[{"batb":[[0,2.68,10]],"ltp":2.98,"tv":1.48,"id":19587212}]}]}
{"op":"mcm","clk":"11933831085","pt":1724318116157,"mc":[{"id":"1.232092849","rc":[{"batb":[[0,2.66,4]],"ltp":2.98,"tv":1.48,"id":19587212}]}]}
{"op":"mcm","clk":"11933831163","pt":1724318118566,"mc":[{"id":"1.232092849","rc":[{"batb":[[0,2.64,5],[1,2.4,41.09],[2,2,6.17]],"ltp":2.98,"tv":1.48,"id":19587212}]}]}
{"op":"mcm","clk":"11933831167","pt":1724318118626,"mc":[{"id":"1.232092849","rc":[{"batb":[[0,2.66,10],[1,2.64,5],[2,2.4,41.09]],"ltp":2.98,"tv":1.48,"id":19587212}]}]}
{"op":"mcm","clk":"11933831279","pt":1724318122167,"mc":[{"id":"1.232092849","rc":[{"batb":[[0,2.66,4]],"ltp":2.98,"tv":1.48,"id":19587212}]}]}
{"op":"mcm","clk":"11933831330","pt":1724318124537,"mc":[{"id":"1.232092849","rc":[{"batb":[[0,2.64,5],[1,2.4,41.09],[2,2,6.17]],"ltp":2.98,"tv":1.48,"id":19587212}]}]}
{"op":"mcm","clk":"11933831333","pt":1724318124639,"mc":[{"id":"1.232092849","rc":[{"batb":[[0,2.66,10],[1,2.64,5],[2,2.4,41.09]],"ltp":2.98,"tv":1.48,"id":19587212}]}]}
{"op":"mcm","clk":"11933831450","pt":1724318128067,"mc":[{"id":"1.232092849","rc":[{"batb":[[0,2.66,4]],"ltp":2.98,"tv":1.48,"id":19587212}]}]}
{"op":"mcm","clk":"11933831537","pt":1724318130436,"mc":[{"id":"1.232092849","rc":[{"batb":[[0,2.66,10]],"ltp":2.98,"tv":1.48,"id":19587212}]}]}
{"op":"mcm","clk":"11933831643","pt":1724318133139,"mc":[{"id":"1.232092849","rc":[{"batb":[[0,2.68,4],[1,2.66,10],[2,2.64,5]],"ltp":2.98,"tv":1.48,"id":19587212}]}]}
{"op":"mcm","clk":"11933831668","pt":1724318133650,"mc":[{"id":"1.232092849","rc":[{"batb":[[1,2.64,5],[2,2.4,41.09]],"ltp":2.98,"tv":1.48,"id":19587212}]}]}
{"op":"mcm","clk":"11933831741","pt":1724318135566,"mc":[{"id":"1.232092849","rc":[{"batb":[[0,2.64,5],[1,2.4,41.09],[2,2,6.17]],"ltp":2.98,"tv":1.48,"id":19587212}]}]}
{"op":"mcm","clk":"11933832237","pt":1724318146750,"mc":[{"id":"1.232092849","rc":[{"batb":[[0,2.66,14],[1,2.64,5],[2,2.4,41.09]],"ltp":2.98,"tv":1.48,"id":19587212}]}]}
{"op":"mcm","clk":"11933832318","pt":1724318149177,"mc":[{"id":"1.232092849","rc":[{"batb":[[0,2.66,10]],"ltp":2.98,"tv":1.48,"id":19587212}]}]}
{"op":"mcm","clk":"11933832362","pt":1724318150257,"mc":[{"id":"1.232092849","rc":[{"batb":[[0,2.64,5],[1,2.4,41.09],[2,2,6.17]],"ltp":2.98,"tv":1.48,"id":19587212}]}]}
{"op":"mcm","clk":"11933832406","pt":1724318151487,"mc":[{"id":"1.232092849","rc":[{"batb":[[0,2.66,4],[1,2.64,5],[2,2.4,41.09]],"ltp":2.98,"tv":1.48,"id":19587212}]}]}
{"op":"mcm","clk":"11933832496","pt":1724318154057,"mc":[{"id":"1.232092849","rc":[{"batb":[[0,2.66,10]],"ltp":2.98,"tv":1.48,"id":19587212}]}]}
{"op":"mcm","clk":"11933832605","pt":1724318157500,"mc":[{"id":"1.232092849","rc":[{"batb":[[0,2.64,5],[1,2.4,41.09],[2,2,6.17]],"ltp":2.98,"tv":1.48,"id":19587212}]}]}
{"op":"mcm","clk":"11933832607","pt":1724318157604,"mc":[{"id":"1.232092849","rc":[{"batb":[[0,2.66,4],[1,2.64,5],[2,2.4,41.09]],"ltp":2.98,"tv":1.48,"id":19587212}]}]}
{"op":"mcm","clk":"11933832708","pt":1724318159879,"mc":[{"id":"1.232092849","rc":[{"batb":[[0,2.66,10]],"ltp":2.98,"tv":1.48,"id":19587212}]}]}
{"op":"mcm","clk":"11933832786","pt":1724318162411,"mc":[{"id":"1.232092849","rc":[{"batb":[[0,2.68,4],[1,2.66,10],[2,2.64,5]],"ltp":2.98,"tv":1.48,"id":19587212}]}]}
{"op":"mcm","clk":"11933832830","pt":1724318163391,"mc":[{"id":"1.232092849","rc":[{"batb":[[1,2.64,5],[2,2.4,41.09]],"ltp":2.98,"tv":1.48,"id":19587212}]}]}
{"op":"mcm","clk":"11933832905","pt":1724318164888,"mc":[{"id":"1.232092849","rc":[{"batb":[[0,2.64,5],[1,2.4,41.09],[2,2,6.17]],"ltp":2.98,"tv":1.48,"id":19587212}]}]}
{"op":"mcm","clk":"11933833104","pt":1724318170711,"mc":[{"id":"1.232092849","rc":[{"batb":[[0,2.66,14],[1,2.64,5],[2,2.4,41.09]],"ltp":2.98,"tv":1.48,"id":19587212}]}]}
{"op":"mcm","clk":"11933833191","pt":1724318173212,"mc":[{"id":"1.232092849","rc":[{"batb":[[0,2.66,10]],"ltp":2.98,"tv":1.48,"id":19587212}]}]}
{"op":"mcm","clk":"11933833230","pt":1724318174289,"mc":[{"id":"1.232092849","rc":[{"batb":[[0,2.64,5],[1,2.4,41.09],[2,2,6.17]],"ltp":2.98,"tv":1.48,"id":19587212}]}]}
{"op":"mcm","clk":"11933833280","pt":1724318175522,"mc":[{"id":"1.232092849","rc":[{"batb":[[0,2.66,4],[1,2.64,5],[2,2.4,41.09]],"ltp":2.98,"tv":1.48,"id":19587212}]}]}
{"op":"mcm","clk":"11933833381","pt":1724318178007,"mc":[{"id":"1.232092849","rc":[{"batb":[[0,2.66,10]],"ltp":2.98,"tv":1.48,"id":19587212}]}]}
{"op":"mcm","clk":"11933833496","pt":1724318181305,"mc":[{"id":"1.232092849","rc":[{"batb":[[0,2.68,4]],"ltp":2.98,"tv":1.48,"id":19587212}]}]}
{"op":"mcm","clk":"11933833579","pt":1724318183528,"mc":[{"id":"1.232092849","rc":[{"batb":[[0,2.66,10]],"ltp":2.98,"tv":1.48,"id":19587212}]}]}
{"op":"mcm","clk":"11933833677","pt":1724318186213,"mc":[{"id":"1.232092849","rc":[{"batb":[[0,2.68,4],[1,2.66,10],[2,2.64,5]],"ltp":2.98,"tv":1.48,"id":19587212}]}]}
{"op":"mcm","clk":"11933833694","pt":1724318186933,"mc":[{"id":"1.232092849","rc":[{"batb":[[1,2.64,5],[2,2.4,41.09]],"ltp":2.98,"tv":1.48,"id":19587212}]}]}
{"op":"mcm","clk":"11933833756","pt":1724318188640,"mc":[{"id":"1.232092849","rc":[{"batb":[[0,2.64,5],[1,2.4,41.09],[2,2,6.17]],"ltp":2.98,"tv":1.48,"id":19587212}]}]}
{"op":"mcm","clk":"11933833824","pt":1724318190700,"mc":[{"id":"1.232092849","rc":[{"batb":[[0,2.68,4],[1,2.66,10],[2,2.64,5]],"ltp":2.98,"tv":1.48,"id":19587212}]}]}
{"op":"mcm","clk":"11933833902","pt":1724318193114,"mc":[{"id":"1.232092849","rc":[{"batb":[[0,2.66,10],[1,2.64,5],[2,2.4,41.09]],"ltp":2.98,"tv":1.48,"id":19587212}]}]}
{"op":"mcm","clk":"11933833926","pt":1724318193935,"mc":[{"id":"1.232092849","rc":[{"batb":[[0,2.64,5],[1,2.4,41.09],[2,2,6.17]],"ltp":2.98,"tv":1.48,"id":19587212}]}]}
{"op":"mcm","clk":"11933834002","pt":1724318196542,"mc":[{"id":"1.232092849","rc":[{"batb":[[0,2.66,14],[1,2.64,5],[2,2.4,41.09]],"ltp":2.98,"tv":1.48,"id":19587212}]}]}
{"op":"mcm","clk":"11933834058","pt":1724318198849,"mc":[{"id":"1.232092849","rc":[{"batb":[[0,2.66,10]],"ltp":2.98,"tv":1.48,"id":19587212}]}]}
{"op":"mcm","clk":"11933834092","pt":1724318199820,"mc":[{"id":"1.232092849","rc":[{"batb":[[0,2.64,5],[1,2.4,41.09],[2,2,6.17]],"ltp":2.98,"tv":1.48,"id":19587212}]}]}
{"op":"mcm","clk":"11933834129","pt":1724318200950,"mc":[{"id":"1.232092849","rc":[{"batb":[[0,2.66,4],[1,2.64,5],[2,2.4,41.09]],"ltp":2.98,"tv":1.48,"id":19587212}]}]}
{"op":"mcm","clk":"11933834211","pt":1724318203322,"mc":[{"id":"1.232092849","rc":[{"batb":[[0,2.66,10]],"ltp":2.98,"tv":1.48,"id":19587212}]}]}
{"op":"mcm","clk":"11933834291","pt":1724318206148,"mc":[{"id":"1.232092849","rc":[{"batb":[[0,2.68,4],[1,2.66,10],[2,2.64,5]],"ltp":2.98,"tv":1.48,"id":19587212}]}]}
{"op":"mcm","clk":"11933834317","pt":1724318206661,"mc":[{"id":"1.232092849","rc":[{"batb":[[1,2.64,5],[2,2.4,41.09]],"ltp":2.98,"tv":1.48,"id":19587212}]}]}
{"op":"mcm","clk":"11933834373","pt":1724318208557,"mc":[{"id":"1.232092849","rc":[{"batb":[[0,2.64,5],[1,2.4,41.09],[2,2,6.17]],"ltp":2.98,"tv":1.48,"id":19587212}]}]}
{"op":"mcm","clk":"11933834452","pt":1724318210657,"mc":[{"id":"1.232092849","rc":[{"batb":[[0,2.66,14],[1,2.64,5],[2,2.4,41.09]],"ltp":2.98,"tv":1.48,"id":19587212}]}]}
{"op":"mcm","clk":"11933834529","pt":1724318212973,"mc":[{"id":"1.232092849","rc":[{"batb":[[0,2.66,10]],"ltp":2.98,"tv":1.48,"id":19587212}]}]}
{"op":"mcm","clk":"11933834560","pt":1724318213956,"mc":[{"id":"1.232092849","rc":[{"batb":[[0,2.64,5],[1,2.4,41.09],[2,2,6.17]],"ltp":2.98,"tv":1.48,"id":19587212}]}]}
{"op":"mcm","clk":"11933834686","pt":1724318216847,"mc":[{"id":"1.232092849","rc":[{"batb":[[0,2.66,14],[1,2.64,5],[2,2.4,41.09]],"ltp":2.98,"tv":1.48,"id":19587212}]}]}
{"op":"mcm","clk":"11933834768","pt":1724318219352,"mc":[{"id":"1.232092849","rc":[{"batb":[[0,2.66,10]],"ltp":2.98,"tv":1.48,"id":19587212}]}]}
{"op":"mcm","clk":"11933834809","pt":1724318220381,"mc":[{"id":"1.232092849","rc":[{"batb":[[0,2.64,5],[1,2.4,41.09],[2,2,6.17]],"ltp":2.98,"tv":1.48,"id":19587212}]}]}
{"op":"mcm","clk":"11933834861","pt":1724318221871,"mc":[{"id":"1.232092849","rc":[{"batb":[[0,2.66,4],[1,2.64,5],[2,2.4,41.09]],"ltp":2.98,"tv":1.48,"id":19587212}]}]}
{"op":"mcm","clk":"11933834971","pt":1724318224385,"mc":[{"id":"1.232092849","rc":[{"batb":[[0,2.68,10]],"ltp":2.98,"tv":1.48,"id":19587212}]}]}
{"op":"mcm","clk":"11933835113","pt":1724318227886,"mc":[{"id":"1.232092849","rc":[{"batl":[[1,1.6,6.73],[2,1.62,25.72]],"ltp":1.5,"tv":441.26,"id":6847357},{"batb":[[0,2.66,4]],"ltp":2.98,"tv":1.48,"id":19587212}]}]}
{"op":"mcm","clk":"11933835210","pt":1724318230247,"mc":[{"id":"1.232092849","rc":[{"batb":[[0,2.66,10]],"ltp":2.98,"tv":1.48,"id":19587212}]}]}
{"op":"mcm","clk":"11933835325","pt":1724318233785,"mc":[{"id":"1.232092849","rc":[{"batb":[[0,2.66,4]],"ltp":2.98,"tv":1.48,"id":19587212}]}]}
{"op":"mcm","clk":"11933835412","pt":1724318236207,"mc":[{"id":"1.232092849","rc":[{"batb":[[0,2.66,10]],"ltp":2.98,"tv":1.48,"id":19587212}]}]}
{"op":"mcm","clk":"11933835531","pt":1724318239899,"mc":[{"id":"1.232092849","rc":[{"batb":[[0,2.66,4]],"ltp":2.98,"tv":1.48,"id":19587212}]}]}
{"op":"mcm","clk":"11933835609","pt":1724318242308,"mc":[{"id":"1.232092849","rc":[{"batb":[[0,2.66,10]],"ltp":2.98,"tv":1.48,"id":19587212}]}]}
{"op":"mcm","clk":"11933835740","pt":1724318245990,"mc":[{"id":"1.232092849","rc":[{"batb":[[0,2.66,4]],"ltp":2.98,"tv":1.48,"id":19587212}]}]}
{"op":"mcm","clk":"11933835815","pt":1724318248400,"mc":[{"id":"1.232092849","rc":[{"batb":[[0,2.68,10]],"ltp":2.98,"tv":1.48,"id":19587212}]}]}
{"op":"mcm","clk":"11933835938","pt":1724318251714,"mc":[{"id":"1.232092849","rc":[{"batb":[[0,2.66,4]],"ltp":2.98,"tv":1.48,"id":19587212}]}]}
{"op":"mcm","clk":"11933836026","pt":1724318254096,"mc":[{"id":"1.232092849","rc":[{"batb":[[0,2.66,10]],"ltp":2.98,"tv":1.48,"id":19587212}]}]}
{"op":"mcm","clk":"11933836136","pt":1724318257497,"mc":[{"id":"1.232092849","rc":[{"batb":[[0,2.66,4]],"ltp":2.98,"tv":1.48,"id":19587212}]}]}
{"op":"mcm","clk":"11933836219","pt":1724318259910,"mc":[{"id":"1.232092849","rc":[{"batb":[[0,2.66,10]],"ltp":2.98,"tv":1.48,"id":19587212}]}]}
{"op":"mcm","clk":"11933836326","pt":1724318263393,"mc":[{"id":"1.232092849","rc":[{"batb":[[0,2.66,4]],"ltp":2.98,"tv":1.48,"id":19587212}]}]}
{"op":"mcm","clk":"11933836406","pt":1724318265801,"mc":[{"id":"1.232092849","rc":[{"batb":[[0,2.66,10]],"ltp":2.98,"tv":1.48,"id":19587212}]}]}
{"op":"mcm","clk":"11933836538","pt":1724318269091,"mc":[{"id":"1.232092849","rc":[{"batb":[[2,1.22,7.03]],"ltp":1.5,"tv":441.26,"id":6847357},{"batb":[[0,2.68,4]],"ltp":2.98,"tv":1.48,"id":19587212}]}]}
{"op":"mcm","clk":"11933836607","pt":1724318271401,"mc":[{"id":"1.232092849","rc":[{"batb":[[0,2.64,5],[1,2.4,41.09],[2,2,6.17]],"ltp":2.98,"tv":1.48,"id":19587212}]}]}
{"op":"mcm","clk":"11933836616","pt":1724318271613,"mc":[{"id":"1.232092849","rc":[{"batb":[[0,2.66,10],[1,2.64,5],[2,2.4,41.09]],"ltp":2.98,"tv":1.48,"id":19587212}]}]}
{"op":"mcm","clk":"11933836744","pt":1724318275105,"mc":[{"id":"1.232092849","rc":[{"batb":[[0,2.66,4]],"ltp":2.98,"tv":1.48,"id":19587212}]}]}
{"op":"mcm","clk":"11933836835","pt":1724318277517,"mc":[{"id":"1.232092849","rc":[{"batb":[[0,2.64,5],[1,2.4,41.09],[2,2,6.17]],"ltp":2.98,"tv":1.48,"id":19587212}]}]}
{"op":"mcm","clk":"11933836840","pt":1724318277720,"mc":[{"id":"1.232092849","rc":[{"batb":[[0,2.66,10],[1,2.64,5],[2,2.4,41.09]],"ltp":2.98,"tv":1.48,"id":19587212}]}]}
{"op":"mcm","clk":"11933836914","pt":1724318279725,"mc":[{"id":"1.232092849","rc":[{"batb":[[0,2.68,4],[1,2.66,10],[2,2.64,5]],"ltp":2.98,"tv":1.48,"id":19587212}]}]}
{"op":"mcm","clk":"11933836951","pt":1724318281014,"mc":[{"id":"1.232092849","rc":[{"batb":[[1,2.64,5],[2,2.4,41.09]],"ltp":2.98,"tv":1.48,"id":19587212}]}]}
{"op":"mcm","clk":"11933836998","pt":1724318282246,"mc":[{"id":"1.232092849","rc":[{"batb":[[0,2.64,5],[1,2.4,41.09],[2,2,6.17]],"ltp":2.98,"tv":1.48,"id":19587212}]}]}
{"op":"mcm","clk":"11933837113","pt":1724318285212,"mc":[{"id":"1.232092849","rc":[{"batb":[[0,2.66,14],[1,2.64,5],[2,2.4,41.09]],"ltp":2.98,"tv":1.48,"id":19587212}]}]}
{"op":"mcm","clk":"11933837199","pt":1724318287527,"mc":[{"id":"1.232092849","rc":[{"batb":[[0,2.66,10]],"ltp":2.98,"tv":1.48,"id":19587212}]}]}
{"op":"mcm","clk":"11933837231","pt":1724318288513,"mc":[{"id":"1.232092849","rc":[{"batb":[[0,2.64,5],[1,2.4,41.09],[2,2,6.17]],"ltp":2.98,"tv":1.48,"id":19587212}]}]}
{"op":"mcm","clk":"11933837419","pt":1724318293524,"mc":[{"id":"1.232092849","rc":[{"batb":[[0,2.66,14],[1,2.64,5],[2,2.4,41.09]],"ltp":2.98,"tv":1.48,"id":19587212}]}]}
{"op":"mcm","clk":"11933837516","pt":1724318296046,"mc":[{"id":"1.232092849","rc":[{"batb":[[0,2.66,10]],"ltp":2.98,"tv":1.48,"id":19587212}]}]}
{"op":"mcm","clk":"11933837558","pt":1724318296923,"mc":[{"id":"1.232092849","rc":[{"batb":[[0,2.64,5],[1,2.4,41.09],[2,2,6.17]],"ltp":2.98,"tv":1.48,"id":19587212}]}]}
{"op":"mcm","clk":"11933837926","pt":1724318305443,"mc":[{"id":"1.232092849","rc":[{"batb":[[0,2.66,14],[1,2.64,5],[2,2.4,41.09]],"ltp":2.98,"tv":1.48,"id":19587212}]}]}
{"op":"mcm","clk":"11933838035","pt":1724318307964,"mc":[{"id":"1.232092849","rc":[{"batb":[[0,2.66,10]],"ltp":2.98,"tv":1.48,"id":19587212}]}]}
{"op":"mcm","clk":"11933838078","pt":1724318308938,"mc":[{"id":"1.232092849","rc":[{"batb":[[0,2.64,5],[1,2.4,41.09],[2,2,6.17]],"ltp":2.98,"tv":1.48,"id":19587212}]}]}
{"op":"mcm","clk":"11933838112","pt":1724318310175,"mc":[{"id":"1.232092849","rc":[{"batb":[[0,2.66,4],[1,2.64,5],[2,2.4,41.09]],"ltp":2.98,"tv":1.48,"id":19587212}]}]}
{"op":"mcm","clk":"11933838195","pt":1724318312567,"mc":[{"id":"1.232092849","rc":[{"batb":[[0,2.66,10]],"ltp":2.98,"tv":1.48,"id":19587212}]}]}
{"op":"mcm","clk":"11933838312","pt":1724318315850,"mc":[{"id":"1.232092849","rc":[{"batb":[[0,2.68,4]],"ltp":2.98,"tv":1.48,"id":19587212}]}]}
{"op":"mcm","clk":"11933838398","pt":1724318318572,"mc":[{"id":"1.232092849","rc":[{"batb":[[0,2.66,10]],"ltp":2.98,"tv":1.48,"id":19587212}]}]}
{"op":"mcm","clk":"11933838477","pt":1724318321166,"mc":[{"id":"1.232092849","rc":[{"batb":[[0,2.68,4],[1,2.66,10],[2,2.64,5]],"ltp":2.98,"tv":1.48,"id":19587212}]}]}
{"op":"mcm","clk":"11933838501","pt":1724318322052,"mc":[{"id":"1.232092849","rc":[{"batb":[[1,2.64,5],[2,2.4,41.09]],"ltp":2.98,"tv":1.48,"id":19587212}]}]}
{"op":"mcm","clk":"11933838551","pt":1724318323548,"mc":[{"id":"1.232092849","rc":[{"batb":[[0,2.64,5],[1,2.4,41.09],[2,2,6.17]],"ltp":2.98,"tv":1.48,"id":19587212}]}]}
{"op":"mcm","clk":"11933838635","pt":1724318326077,"mc":[{"id":"1.232092849","rc":[{"batb":[[0,2.66,14],[1,2.64,5],[2,2.4,41.09]],"ltp":2.98,"tv":1.48,"id":19587212}]}]}
{"op":"mcm","clk":"11933838724","pt":1724318328394,"mc":[{"id":"1.232092849","rc":[{"batb":[[0,2.66,10]],"ltp":2.98,"tv":1.48,"id":19587212}]}]}
{"op":"mcm","clk":"11933838753","pt":1724318329578,"mc":[{"id":"1.232092849","rc":[{"batb":[[0,2.64,5],[1,2.4,41.09],[2,2,6.17]],"ltp":2.98,"tv":1.48,"id":19587212}]}]}
{"op":"mcm","clk":"11933839006","pt":1724318335573,"mc":[{"id":"1.232092849","rc":[{"batb":[[0,2.66,14],[1,2.64,5],[2,2.4,41.09]],"ltp":2.98,"tv":1.48,"id":19587212}]}]}
{"op":"mcm","clk":"11933839104","pt":1724318338162,"mc":[{"id":"1.232092849","rc":[{"batb":[[0,2.66,10]],"ltp":2.98,"tv":1.48,"id":19587212}]}]}
{"op":"mcm","clk":"11933839169","pt":1724318339085,"mc":[{"id":"1.232092849","rc":[{"batb":[[0,2.64,5],[1,2.4,41.09],[2,2,6.17]],"ltp":2.98,"tv":1.48,"id":19587212}]}]}
{"op":"mcm","clk":"11933839240","pt":1724318340712,"mc":[{"id":"1.232092849","rc":[{"batb":[[0,2.66,4],[1,2.64,5],[2,2.4,41.09]],"ltp":2.98,"tv":1.48,"id":19587212}]}]}
{"op":"mcm","clk":"11933839432","pt":1724318343286,"mc":[{"id":"1.232092849","rc":[{"batb":[[0,2.66,10]],"ltp":2.98,"tv":1.48,"id":19587212}]}]}
{"op":"mcm","clk":"11933839584","pt":1724318345791,"mc":[{"id":"1.232092849","rc":[{"batb":[[0,2.68,4],[1,2.66,10],[2,2.64,5]],"ltp":2.98,"tv":1.48,"id":19587212}]}]}
{"op":"mcm","clk":"11933839638","pt":1724318346611,"mc":[{"id":"1.232092849","rc":[{"batb":[[1,2.64,5],[2,2.4,41.09]],"ltp":2.98,"tv":1.48,"id":19587212}]}]}
{"op":"mcm","clk":"11933839720","pt":1724318348208,"mc":[{"id":"1.232092849","rc":[{"batb":[[0,2.64,5],[1,2.4,41.09],[2,2,6.17]],"ltp":2.98,"tv":1.48,"id":19587212}]}]}
{"op":"mcm","clk":"11933839853","pt":1724318350784,"mc":[{"id":"1.232092849","rc":[{"batb":[[0,2.66,14],[1,2.64,5],[2,2.4,41.09]],"ltp":2.98,"tv":1.48,"id":19587212}]}]}
{"op":"mcm","clk":"11933839968","pt":1724318353000,"mc":[{"id":"1.232092849","rc":[{"batb":[[0,2.66,10]],"ltp":2.98,"tv":1.48,"id":19587212}]}]}
{"op":"mcm","clk":"11933840030","pt":1724318354288,"mc":[{"id":"1.232092849","rc":[{"batb":[[0,2.64,5],[1,2.4,41.09],[2,2,6.17]],"ltp":2.98,"tv":1.48,"id":19587212}]}]}
{"op":"mcm","clk":"11933840241","pt":1724318357693,"mc":[{"id":"1.232092849","rc":[{"batb":[[0,2.66,14],[1,2.64,5],[2,2.4,41.09]],"ltp":2.98,"tv":1.48,"id":19587212}]}]}
{"op":"mcm","clk":"11933840352","pt":1724318360107,"mc":[{"id":"1.232092849","rc":[{"batb":[[0,2.66,10]],"ltp":2.98,"tv":1.48,"id":19587212}]}]}
{"op":"mcm","clk":"11933840406","pt":1724318361090,"mc":[{"id":"1.232092849","rc":[{"batb":[[0,2.64,5],[1,2.4,41.09],[2,2,6.17]],"ltp":2.98,"tv":1.48,"id":19587212}]}]}
{"op":"mcm","clk":"11933840578","pt":1724318365337,"mc":[{"id":"1.232092849","rc":[{"batb":[[0,2.66,14],[1,2.64,5],[2,2.4,41.09]],"ltp":2.98,"tv":1.48,"id":19587212}]}]}
{"op":"mcm","clk":"11933840680","pt":1724318367723,"mc":[{"id":"1.232092849","rc":[{"batb":[[0,2.66,10]],"ltp":2.98,"tv":1.48,"id":19587212}]}]}
{"op":"mcm","clk":"11933840731","pt":1724318368816,"mc":[{"id":"1.232092849","rc":[{"batb":[[0,2.64,5],[1,2.4,41.09],[2,2,6.17]],"ltp":2.98,"tv":1.48,"id":19587212}]}]}
{"op":"mcm","clk":"11933841012","pt":1724318375419,"mc":[{"id":"1.232092849","rc":[{"batb":[[0,2.66,14],[1,2.64,5],[2,2.4,41.09]],"ltp":2.98,"tv":1.48,"id":19587212}]}]}
{"op":"mcm","clk":"11933841116","pt":1724318377935,"mc":[{"id":"1.232092849","rc":[{"batb":[[0,2.66,10]],"ltp":2.98,"tv":1.48,"id":19587212}]}]}
{"op":"mcm","clk":"11933841150","pt":1724318378810,"mc":[{"id":"1.232092849","rc":[{"batb":[[0,2.64,5],[1,2.4,41.09],[2,2,6.17]],"ltp":2.98,"tv":1.48,"id":19587212}]}]}
{"op":"mcm","clk":"11933841274","pt":1724318382021,"mc":[{"id":"1.232092849","rc":[{"batb":[[0,2.66,14],[1,2.64,5],[2,2.4,41.09]],"ltp":2.98,"tv":1.48,"id":19587212}]}]}
{"op":"mcm","clk":"11933841377","pt":1724318384539,"mc":[{"id":"1.232092849","rc":[{"batb":[[0,2.66,10]],"ltp":2.98,"tv":1.48,"id":19587212}]}]}
{"op":"mcm","clk":"11933841403","pt":1724318385458,"mc":[{"id":"1.232092849","rc":[{"batb":[[0,2.64,5],[1,2.4,41.09],[2,2,6.17]],"ltp":2.98,"tv":1.48,"id":19587212}]}]}
{"op":"mcm","clk":"11933841479","pt":1724318387924,"mc":[{"id":"1.232092849","rc":[{"batb":[[0,2.66,14],[1,2.64,5],[2,2.4,41.09]],"ltp":2.98,"tv":1.48,"id":19587212}]}]}
{"op":"mcm","clk":"11933841561","pt":1724318390537,"mc":[{"id":"1.232092849","rc":[{"batb":[[0,2.66,10]],"ltp":2.98,"tv":1.48,"id":19587212}]}]}
{"op":"mcm","clk":"11933841607","pt":1724318391560,"mc":[{"id":"1.232092849","rc":[{"batb":[[0,2.64,5],[1,2.4,41.09],[2,2,6.17]],"ltp":2.98,"tv":1.48,"id":19587212}]}]}
{"op":"mcm","clk":"11933841696","pt":1724318393746,"mc":[{"id":"1.232092849","rc":[{"batb":[[0,2.66,14],[1,2.64,5],[2,2.4,41.09]],"ltp":2.98,"tv":1.48,"id":19587212}]}]}
{"op":"mcm","clk":"11933841790","pt":1724318396357,"mc":[{"id":"1.232092849","rc":[{"batb":[[0,2.66,10]],"ltp":2.98,"tv":1.48,"id":19587212}]}]}
{"op":"mcm","clk":"11933841820","pt":1724318397177,"mc":[{"id":"1.232092849","rc":[{"batb":[[0,2.64,5],[1,2.4,41.09],[2,2,6.17]],"ltp":2.98,"tv":1.48,"id":19587212}]}]}
{"op":"mcm","clk":"11933841933","pt":1724318400260,"mc":[{"id":"1.232092849","rc":[{"batb":[[0,2.66,14],[1,2.64,5],[2,2.4,41.09]],"ltp":2.98,"tv":1.48,"id":19587212}]}]}
{"op":"mcm","clk":"11933842033","pt":1724318402652,"mc":[{"id":"1.232092849","rc":[{"batb":[[0,2.66,10]],"ltp":2.98,"tv":1.48,"id":19587212}]}]}
{"op":"mcm","clk":"11933842071","pt":1724318403778,"mc":[{"id":"1.232092849","rc":[{"batb":[[0,2.64,5],[1,2.4,41.09],[2,2,6.17]],"ltp":2.98,"tv":1.48,"id":19587212}]}]}
{"op":"mcm","clk":"11933842120","pt":1724318405065,"mc":[{"id":"1.232092849","rc":[{"batb":[[0,2.66,4],[1,2.64,5],[2,2.4,41.09]],"ltp":2.98,"tv":1.48,"id":19587212}]}]}
{"op":"mcm","clk":"11933842205","pt":1724318407479,"mc":[{"id":"1.232092849","rc":[{"batb":[[0,2.64,5],[1,2.4,41.09],[2,2,6.17]],"ltp":2.98,"tv":1.48,"id":19587212}]}]}
{"op":"mcm","clk":"11933842221","pt":1724318407684,"mc":[{"id":"1.232092849","rc":[{"batb":[[0,2.66,10],[1,2.64,5],[2,2.4,41.09]],"ltp":2.98,"tv":1.48,"id":19587212}]}]}
{"op":"mcm","clk":"11933842394","pt":1724318411378,"mc":[{"id":"1.232092849","rc":[{"batb":[[0,2.66,4]],"ltp":2.98,"tv":1.48,"id":19587212}]}]}
{"op":"mcm","clk":"11933842488","pt":1724318413687,"mc":[{"id":"1.232092849","rc":[{"batb":[[0,2.68,10]],"ltp":2.98,"tv":1.48,"id":19587212}]}]}
{"op":"mcm","clk":"11933842643","pt":1724318417185,"mc":[{"id":"1.232092849","rc":[{"batb":[[0,2.66,4]],"ltp":2.98,"tv":1.48,"id":19587212}]}]}
{"op":"mcm","clk":"11933842728","pt":1724318419498,"mc":[{"id":"1.232092849","rc":[{"batb":[[0,2.64,5],[1,2.4,41.09],[2,2,6.17]],"ltp":2.98,"tv":1.48,"id":19587212}]}]}
{"op":"mcm","clk":"11933842742","pt":1724318419759,"mc":[{"id":"1.232092849","rc":[{"batb":[[0,2.66,10],[1,2.64,5],[2,2.4,41.09]],"ltp":2.98,"tv":1.48,"id":19587212}]}]}
{"op":"mcm","clk":"11933842879","pt":1724318423472,"mc":[{"id":"1.232092849","rc":[{"batb":[[0,2.66,4]],"ltp":2.98,"tv":1.48,"id":19587212}]}]}
{"op":"mcm","clk":"11933843001","pt":1724318425778,"mc":[{"id":"1.232092849","rc":[{"batb":[[0,2.66,10]],"ltp":2.98,"tv":1.48,"id":19587212}]}]}
{"op":"mcm","clk":"11933843153","pt":1724318429081,"mc":[{"id":"1.232092849","rc":[{"batb":[[0,2.66,4]],"ltp":2.98,"tv":1.48,"id":19587212}]}]}
{"op":"mcm","clk":"11933843239","pt":1724318431498,"mc":[{"id":"1.232092849","rc":[{"batb":[[0,2.64,5],[1,2.4,41.09],[2,2,6.17]],"ltp":2.98,"tv":1.48,"id":19587212}]}]}
{"op":"mcm","clk":"11933843244","pt":1724318431600,"mc":[{"id":"1.232092849","rc":[{"batb":[[0,2.66,10],[1,2.64,5],[2,2.4,41.09]],"ltp":2.98,"tv":1.48,"id":19587212}]}]}
{"op":"mcm","clk":"11933843372","pt":1724318435102,"mc":[{"id":"1.232092849","rc":[{"batb":[[0,2.66,4]],"ltp":2.98,"tv":1.48,"id":19587212}]}]}
{"op":"mcm","clk":"11933843454","pt":1724318437509,"mc":[{"id":"1.232092849","rc":[{"batb":[[0,2.64,5],[1,2.4,41.09],[2,2,6.17]],"ltp":2.98,"tv":1.48,"id":19587212}]}]}
{"op":"mcm","clk":"11933843457","pt":1724318437610,"mc":[{"id":"1.232092849","rc":[{"batb":[[0,2.66,10],[1,2.64,5],[2,2.4,41.09]],"ltp":2.98,"tv":1.48,"id":19587212}]}]}
{"op":"mcm","clk":"11933843592","pt":1724318440908,"mc":[{"id":"1.232092849","rc":[{"batb":[[0,2.68,4]],"ltp":2.98,"tv":1.48,"id":19587212}]}]}
{"op":"mcm","clk":"11933843666","pt":1724318443478,"mc":[{"id":"1.232092849","rc":[{"batb":[[0,2.66,10]],"ltp":2.98,"tv":1.48,"id":19587212}]}]}
{"op":"mcm","clk":"11933843820","pt":1724318446824,"mc":[{"id":"1.232092849","rc":[{"batb":[[0,2.68,4]],"ltp":2.98,"tv":1.48,"id":19587212}]}]}
{"op":"mcm","clk":"11933843937","pt":1724318449714,"mc":[{"id":"1.232092849","rc":[{"batb":[[0,2.66,10]],"ltp":2.98,"tv":1.48,"id":19587212}]}]}
{"op":"mcm","clk":"11933844053","pt":1724318453205,"mc":[{"id":"1.232092849","rc":[{"batb":[[0,2.66,4]],"ltp":2.98,"tv":1.48,"id":19587212}]}]}
{"op":"mcm","clk":"11933844136","pt":1724318455510,"mc":[{"id":"1.232092849","rc":[{"batb":[[0,2.64,5],[1,2.4,41.09],[2,2,6.17]],"ltp":2.98,"tv":1.48,"id":19587212}]}]}
{"op":"mcm","clk":"11933844140","pt":1724318455614,"mc":[{"id":"1.232092849","rc":[{"batb":[[0,2.66,10],[1,2.64,5],[2,2.4,41.09]],"ltp":2.98,"tv":1.48,"id":19587212}]}]}
{"op":"mcm","clk":"11933844330","pt":1724318459326,"mc":[{"id":"1.232092849","rc":[{"batb":[[0,2.66,4]],"ltp":2.98,"tv":1.48,"id":19587212}]}]}
{"op":"mcm","clk":"11933844453","pt":1724318461809,"mc":[{"id":"1.232092849","rc":[{"batb":[[0,2.66,10]],"ltp":2.98,"tv":1.48,"id":19587212}]}]}
{"op":"mcm","clk":"11933844595","pt":1724318465203,"mc":[{"id":"1.232092849","rc":[{"batb":[[0,2.66,4]],"ltp":2.98,"tv":1.48,"id":19587212}]}]}
{"op":"mcm","clk":"11933844711","pt":1724318467531,"mc":[{"id":"1.232092849","rc":[{"batb":[[0,2.64,5],[1,2.4,41.09],[2,2,6.17]],"ltp":2.98,"tv":1.48,"id":19587212}]}]}
{"op":"mcm","clk":"11933844717","pt":1724318467635,"mc":[{"id":"1.232092849","rc":[{"batb":[[0,2.68,10],[1,2.64,5],[2,2.4,41.09]],"ltp":2.98,"tv":1.48,"id":19587212}]}]}
{"op":"mcm","clk":"11933844908","pt":1724318471133,"mc":[{"id":"1.232092849","rc":[{"batb":[[0,2.66,4]],"ltp":2.98,"tv":1.48,"id":19587212}]}]}
{"op":"mcm","clk":"11933844990","pt":1724318473552,"mc":[{"id":"1.232092849","rc":[{"batb":[[0,2.64,5],[1,2.4,41.09],[2,2,6.17]],"ltp":2.98,"tv":1.48,"id":19587212}]}]}
{"op":"mcm","clk":"11933844995","pt":1724318473602,"mc":[{"id":"1.232092849","rc":[{"batb":[[0,2.66,10],[1,2.64,5],[2,2.4,41.09]],"ltp":2.98,"tv":1.48,"id":19587212}]}]}
{"op":"mcm","clk":"11933845137","pt":1724318477050,"mc":[{"id":"1.232092849","rc":[{"batb":[[0,2.66,4]],"ltp":2.98,"tv":1.48,"id":19587212}]}]}
{"op":"mcm","clk":"11933845228","pt":1724318479527,"mc":[{"id":"1.232092849","rc":[{"batb":[[0,2.66,10]],"ltp":2.98,"tv":1.48,"id":19587212}]}]}
{"op":"mcm","clk":"11933845345","pt":1724318482916,"mc":[{"id":"1.232092849","rc":[{"batb":[[0,2.66,4]],"ltp":2.98,"tv":1.48,"id":19587212}]}]}
{"op":"mcm","clk":"11933845435","pt":1724318485255,"mc":[{"id":"1.232092849","rc":[{"batb":[[0,2.66,10]],"ltp":2.98,"tv":1.48,"id":19587212}]}]}
{"op":"mcm","clk":"11933845534","pt":1724318488551,"mc":[{"id":"1.232092849","rc":[{"batb":[[0,2.64,5],[1,2.4,41.09],[2,2,6.17]],"ltp":2.98,"tv":1.48,"id":19587212}]}]}
{"op":"mcm","clk":"11933845539","pt":1724318488655,"mc":[{"id":"1.232092849","rc":[{"batb":[[0,2.66,4],[1,2.64,5],[2,2.4,41.09]],"ltp":2.98,"tv":1.48,"id":19587212}]}]}
{"op":"mcm","clk":"11933845641","pt":1724318491134,"mc":[{"id":"1.232092849","rc":[{"batb":[[0,2.66,10]],"ltp":2.98,"tv":1.48,"id":19587212}]}]}
{"op":"mcm","clk":"11933845781","pt":1724318494476,"mc":[{"id":"1.232092849","rc":[{"batb":[[0,2.66,4]],"ltp":2.98,"tv":1.48,"id":19587212}]}]}
{"op":"mcm","clk":"11933845862","pt":1724318496859,"mc":[{"id":"1.232092849","rc":[{"batb":[[0,2.66,10]],"ltp":2.98,"tv":1.48,"id":19587212}]}]}
{"op":"mcm","clk":"11933846015","pt":1724318500167,"mc":[{"id":"1.232092849","rc":[{"batb":[[0,2.66,4]],"ltp":2.98,"tv":1.48,"id":19587212}]}]}
{"op":"mcm","clk":"11933846095","pt":1724318502556,"mc":[{"id":"1.232092849","rc":[{"batb":[[0,2.64,5],[1,2.4,41.09],[2,2,6.17]],"ltp":2.98,"tv":1.48,"id":19587212}]}]}
{"op":"mcm","clk":"11933846102","pt":1724318502656,"mc":[{"id":"1.232092849","rc":[{"batb":[[0,2.66,10],[1,2.64,5],[2,2.4,41.09]],"ltp":2.98,"tv":1.48,"id":19587212}]}]}
{"op":"mcm","clk":"11933846243","pt":1724318506047,"mc":[{"id":"1.232092849","rc":[{"batb":[[0,2.66,4]],"ltp":2.98,"tv":1.48,"id":19587212}]}]}
{"op":"mcm","clk":"11933846365","pt":1724318508568,"mc":[{"id":"1.232092849","rc":[{"batb":[[0,2.66,10]],"ltp":2.98,"tv":1.48,"id":19587212}]}]}
{"op":"mcm","clk":"11933846503","pt":1724318512058,"mc":[{"id":"1.232092849","rc":[{"batb":[[0,2.66,4]],"ltp":2.98,"tv":1.48,"id":19587212}]}]}
{"op":"mcm","clk":"11933846614","pt":1724318514572,"mc":[{"id":"1.232092849","rc":[{"batb":[[0,2.66,10]],"ltp":2.98,"tv":1.48,"id":19587212}]}]}
{"op":"mcm","clk":"11933846722","pt":1724318516886,"mc":[{"id":"1.232092849","rc":[{"batb":[[0,2.68,4],[1,2.66,10],[2,2.64,5]],"ltp":2.98,"tv":1.48,"id":19587212}]}]}
{"op":"mcm","clk":"11933846766","pt":1724318517973,"mc":[{"id":"1.232092849","rc":[{"batb":[[1,2.64,5],[2,2.4,41.09]],"ltp":2.98,"tv":1.48,"id":19587212}]}]}
{"op":"mcm","clk":"11933846817","pt":1724318519304,"mc":[{"id":"1.232092849","rc":[{"batb":[[0,2.64,5],[1,2.4,41.09],[2,2,6.17]],"ltp":2.98,"tv":1.48,"id":19587212}]}]}
{"op":"mcm","clk":"11933847165","pt":1724318527782,"mc":[{"id":"1.232092849","rc":[{"batb":[[0,2.66,14],[1,2.64,5],[2,2.4,41.09]],"ltp":2.98,"tv":1.48,"id":19587212}]}]}
{"op":"mcm","clk":"11933847263","pt":1724318530311,"mc":[{"id":"1.232092849","rc":[{"batb":[[0,2.66,10]],"ltp":2.98,"tv":1.48,"id":19587212}]}]}
{"op":"mcm","clk":"11933847297","pt":1724318531296,"mc":[{"id":"1.232092849","rc":[{"batb":[[0,2.64,5],[1,2.4,41.09],[2,2,6.17]],"ltp":2.98,"tv":1.48,"id":19587212}]}]}
{"op":"mcm","clk":"11933847387","pt":1724318533812,"mc":[{"id":"1.232092849","rc":[{"batb":[[0,2.66,14],[1,2.64,5],[2,2.4,41.09]],"ltp":2.98,"tv":1.48,"id":19587212}]}]}
{"op":"mcm","clk":"11933847503","pt":1724318536433,"mc":[{"id":"1.232092849","rc":[{"batb":[[0,2.66,10]],"ltp":2.98,"tv":1.48,"id":19587212}]}]}
{"op":"mcm","clk":"11933847528","pt":1724318537218,"mc":[{"id":"1.232092849","rc":[{"batb":[[0,2.64,5],[1,2.4,41.09],[2,2,6.17]],"ltp":2.98,"tv":1.48,"id":19587212}]}]}
{"op":"mcm","clk":"11933847630","pt":1724318540511,"mc":[{"id":"1.232092849","rc":[{"batb":[[0,2.66,14],[1,2.64,5],[2,2.4,41.09]],"ltp":2.98,"tv":1.48,"id":19587212}]}]}
{"op":"mcm","clk":"11933847710","pt":1724318543024,"mc":[{"id":"1.232092849","rc":[{"batb":[[0,2.66,10]],"ltp":2.98,"tv":1.48,"id":19587212}]}]}
{"op":"mcm","clk":"11933847733","pt":1724318543904,"mc":[{"id":"1.232092849","rc":[{"batb":[[0,2.64,5],[1,2.4,41.09],[2,2,6.17]],"ltp":2.98,"tv":1.48,"id":19587212}]}]}
{"op":"mcm","clk":"11933847767","pt":1724318545236,"mc":[{"id":"1.232092849","rc":[{"batb":[[0,2.66,4],[1,2.64,5],[2,2.4,41.09]],"ltp":2.98,"tv":1.48,"id":19587212}]}]}
{"op":"mcm","clk":"11933847807","pt":1724318546626,"mc":[{"id":"1.232092849","rc":[{"batb":[[0,2.68,10],[1,2.66,4],[2,2.64,5]],"ltp":2.98,"tv":1.48,"id":19587212}]}]}
{"op":"mcm","clk":"11933847835","pt":1724318547745,"mc":[{"id":"1.232092849","rc":[{"batb":[[1,2.64,5],[2,2.4,41.09]],"ltp":2.98,"tv":1.48,"id":19587212}]}]}
{"op":"mcm","clk":"11933847917","pt":1724318549906,"mc":[{"id":"1.232092849","rc":[{"batb":[[0,2.7,4]],"ltp":2.98,"tv":1.48,"id":19587212}]}]}
{"op":"mcm","clk":"11933848020","pt":1724318552233,"mc":[{"id":"1.232092849","rc":[{"batb":[[0,2.66,10]],"ltp":2.98,"tv":1.48,"id":19587212}]}]}
{"op":"mcm","clk":"11933848150","pt":1724318555528,"mc":[{"id":"1.232092849","rc":[{"batb":[[0,2.68,4]],"ltp":2.98,"tv":1.48,"id":19587212}]}]}
{"op":"mcm","clk":"11933848247","pt":1724318558045,"mc":[{"id":"1.232092849","rc":[{"batb":[[0,2.66,10]],"ltp":2.98,"tv":1.48,"id":19587212}]}]}
{"op":"mcm","clk":"11933848345","pt":1724318561333,"mc":[{"id":"1.232092849","rc":[{"batb":[[0,2.66,4]],"ltp":2.98,"tv":1.48,"id":19587212}]}]}
{"op":"mcm","clk":"11933848427","pt":1724318563833,"mc":[{"id":"1.232092849","rc":[{"batb":[[0,2.68,10]],"ltp":2.98,"tv":1.48,"id":19587212}]}]}
{"op":"mcm","clk":"11933848537","pt":1724318567441,"mc":[{"id":"1.232092849","rc":[{"batb":[[0,2.66,4]],"ltp":2.98,"tv":1.48,"id":19587212}]}]}
{"op":"mcm","clk":"11933848627","pt":1724318569957,"mc":[{"id":"1.232092849","rc":[{"batb":[[0,2.66,10]],"ltp":2.98,"tv":1.48,"id":19587212}]}]}
{"op":"mcm","clk":"11933848767","pt":1724318573243,"mc":[{"id":"1.232092849","rc":[{"batb":[[0,2.68,4]],"ltp":2.98,"tv":1.48,"id":19587212}]}]}
{"op":"mcm","clk":"11933848863","pt":1724318575459,"mc":[{"id":"1.232092849","rc":[{"batb":[[0,2.66,10]],"ltp":2.98,"tv":1.48,"id":19587212}]}]}
{"op":"mcm","clk":"11933848958","pt":1724318578353,"mc":[{"id":"1.232092849","rc":[{"batb":[[0,2.68,4],[1,2.66,10],[2,2.64,5]],"ltp":2.98,"tv":1.48,"id":19587212}]}]}
{"op":"mcm","clk":"11933848974","pt":1724318578662,"mc":[{"id":"1.232092849","rc":[{"batb":[[1,2.64,5],[2,2.4,41.09]],"ltp":2.98,"tv":1.48,"id":19587212}]}]}
{"op":"mcm","clk":"11933849055","pt":1724318580974,"mc":[{"id":"1.232092849","rc":[{"batb":[[0,2.66,10]],"ltp":2.98,"tv":1.48,"id":19587212}]}]}
{"op":"mcm","clk":"11933849156","pt":1724318583488,"mc":[{"id":"1.232092849","rc":[{"batb":[[0,2.68,4],[1,2.66,10],[2,2.64,5]],"ltp":2.98,"tv":1.48,"id":19587212}]}]}
{"op":"mcm","clk":"11933849187","pt":1724318584371,"mc":[{"id":"1.232092849","rc":[{"batb":[[1,2.64,5],[2,2.4,41.09]],"ltp":2.98,"tv":1.48,"id":19587212}]}]}
{"op":"mcm","clk":"11933849249","pt":1724318585756,"mc":[{"id":"1.232092849","rc":[{"batb":[[0,2.64,5],[1,2.4,41.09],[2,2,6.17]],"ltp":2.98,"tv":1.48,"id":19587212}]}]}
{"op":"mcm","clk":"11933849407","pt":1724318589457,"mc":[{"id":"1.232092849","rc":[{"batb":[[0,2.66,14],[1,2.64,5],[2,2.4,41.09]],"ltp":2.98,"tv":1.48,"id":19587212}]}]}
{"op":"mcm","clk":"11933849507","pt":1724318592080,"mc":[{"id":"1.232092849","rc":[{"batb":[[0,2.66,10]],"ltp":2.98,"tv":1.48,"id":19587212}]}]}
{"op":"mcm","clk":"11933849535","pt":1724318592798,"mc":[{"id":"1.232092849","rc":[{"batb":[[0,2.64,5],[1,2.4,41.09],[2,2,6.17]],"ltp":2.98,"tv":1.48,"id":19587212}]}]}
{"op":"mcm","clk":"11933849710","pt":1724318597687,"mc":[{"id":"1.232092849","rc":[{"batb":[[0,2.66,14],[1,2.64,5],[2,2.4,41.09]],"ltp":2.98,"tv":1.48,"id":19587212}]}]}
{"op":"mcm","clk":"11933849788","pt":1724318600118,"mc":[{"id":"1.232092849","rc":[{"batb":[[0,2.66,10]],"ltp":2.98,"tv":1.48,"id":19587212}]}]}
{"op":"mcm","clk":"11933849830","pt":1724318601092,"mc":[{"id":"1.232092849","rc":[{"batb":[[0,2.64,5],[1,2.4,41.09],[2,2,6.17]],"ltp":2.98,"tv":1.48,"id":19587212}]}]}
{"op":"mcm","clk":"11933849889","pt":1724318602481,"mc":[{"id":"1.232092849","rc":[{"batb":[[0,2.66,4],[1,2.64,5],[2,2.4,41.09]],"ltp":2.98,"tv":1.48,"id":19587212}]}]}
{"op":"mcm","clk":"11933849912","pt":1724318603603,"mc":[{"id":"1.232092849","rc":[{"batb":[[0,2.68,10],[1,2.66,4],[2,2.64,5]],"ltp":2.98,"tv":1.48,"id":19587212}]}]}
{"op":"mcm","clk":"11933849959","pt":1724318604901,"mc":[{"id":"1.232092849","rc":[{"batb":[[1,2.64,5],[2,2.4,41.09]],"ltp":2.98,"tv":1.48,"id":19587212}]}]}
{"op":"mcm","clk":"11933850009","pt":1724318607003,"mc":[{"id":"1.232092849","rc":[{"batb":[[0,2.66,4]],"ltp":2.98,"tv":1.48,"id":19587212}]}]}
{"op":"mcm","clk":"11933850077","pt":1724318609414,"mc":[{"id":"1.232092849","rc":[{"batb":[[0,2.64,5],[1,2.4,41.09],[2,2,6.17]],"ltp":2.98,"tv":1.48,"id":19587212}]}]}
{"op":"mcm","clk":"11933850081","pt":1724318609621,"mc":[{"id":"1.232092849","rc":[{"batb":[[0,2.66,10],[1,2.64,5],[2,2.4,41.09]],"ltp":2.98,"tv":1.48,"id":19587212}]}]}
{"op":"mcm","clk":"11933850215","pt":1724318613114,"mc":[{"id":"1.232092849","rc":[{"batb":[[0,2.66,4]],"ltp":2.98,"tv":1.48,"id":19587212}]}]}
{"op":"mcm","clk":"11933850318","pt":1724318615524,"mc":[{"id":"1.232092849","rc":[{"batb":[[0,2.66,10]],"ltp":2.98,"tv":1.48,"id":19587212}]}]}
{"op":"mcm","clk":"11933850445","pt":1724318618926,"mc":[{"id":"1.232092849","rc":[{"batb":[[0,2.68,4]],"ltp":2.98,"tv":1.48,"id":19587212}]}]}
{"op":"mcm","clk":"11933850508","pt":1724318621439,"mc":[{"id":"1.232092849","rc":[{"batb":[[0,2.66,10]],"ltp":2.98,"tv":1.48,"id":19587212}]}]}
{"op":"mcm","clk":"11933850619","pt":1724318625036,"mc":[{"id":"1.232092849","rc":[{"batb":[[0,2.66,4]],"ltp":2.98,"tv":1.48,"id":19587212}]}]}
{"op":"mcm","clk":"11933850706","pt":1724318627519,"mc":[{"id":"1.232092849","rc":[{"batb":[[0,2.66,10]],"ltp":2.98,"tv":1.48,"id":19587212}]}]}
{"op":"mcm","clk":"11933850822","pt":1724318630960,"mc":[{"id":"1.232092849","rc":[{"batb":[[0,2.68,4]],"ltp":2.98,"tv":1.48,"id":19587212}]}]}
{"op":"mcm","clk":"11933850905","pt":1724318633119,"mc":[{"id":"1.232092849","rc":[{"batb":[[0,2.66,10]],"ltp":2.98,"tv":1.48,"id":19587212}]}]}
{"op":"mcm","clk":"11933850998","pt":1724318636448,"mc":[{"id":"1.232092849","rc":[{"batb":[[0,2.64,5],[1,2.4,41.09],[2,2,6.17]],"ltp":2.98,"tv":1.48,"id":19587212}]}]}
{"op":"mcm","clk":"11933851007","pt":1724318636651,"mc":[{"id":"1.232092849","rc":[{"batb":[[0,2.66,4],[1,2.64,5],[2,2.4,41.09]],"ltp":2.98,"tv":1.48,"id":19587212}]}]}
{"op":"mcm","clk":"11933851097","pt":1724318638956,"mc":[{"id":"1.232092849","rc":[{"batb":[[0,2.68,10]],"ltp":2.98,"tv":1.48,"id":19587212}]}]}
{"op":"mcm","clk":"11933851218","pt":1724318642572,"mc":[{"id":"1.232092849","rc":[{"batb":[[0,2.66,4]],"ltp":2.98,"tv":1.48,"id":19587212}]}]}
{"op":"mcm","clk":"11933851319","pt":1724318645149,"mc":[{"id":"1.232092849","rc":[{"batb":[[0,2.66,10]],"ltp":2.98,"tv":1.48,"id":19587212}]}]}
{"op":"mcm","clk":"11933851417","pt":1724318648543,"mc":[{"id":"1.232092849","rc":[{"batb":[[0,2.66,4]],"ltp":2.98,"tv":1.48,"id":19587212}]}]}
{"op":"mcm","clk":"11933851526","pt":1724318651142,"mc":[{"id":"1.232092849","rc":[{"batb":[[0,2.66,10]],"ltp":2.98,"tv":1.48,"id":19587212}]}]}
{"op":"mcm","clk":"11933851644","pt":1724318654542,"mc":[{"id":"1.232092849","rc":[{"batb":[[0,2.64,5],[1,2.4,41.09],[2,2,6.17]],"ltp":2.98,"tv":1.48,"id":19587212}]}]}
{"op":"mcm","clk":"11933851648","pt":1724318654643,"mc":[{"id":"1.232092849","rc":[{"batb":[[0,2.66,4],[1,2.64,5],[2,2.4,41.09]],"ltp":2.98,"tv":1.48,"id":19587212}]}]}
{"op":"mcm","clk":"11933851766","pt":1724318657379,"mc":[{"id":"1.232092849","rc":[{"batb":[[0,2.66,10]],"ltp":2.98,"tv":1.48,"id":19587212}]}]}
{"op":"mcm","clk":"11933851886","pt":1724318660779,"mc":[{"id":"1.232092849","rc":[{"batb":[[0,2.68,4]],"ltp":2.98,"tv":1.48,"id":19587212}]}]}
{"op":"mcm","clk":"11933851979","pt":1724318663090,"mc":[{"id":"1.232092849","rc":[{"batb":[[0,2.7,10]],"ltp":2.98,"tv":1.48,"id":19587212}]}]}
{"op":"mcm","clk":"11933852100","pt":1724318666561,"mc":[{"id":"1.232092849","rc":[{"batb":[[0,2.66,4]],"ltp":2.98,"tv":1.48,"id":19587212}]}]}
{"op":"mcm","clk":"11933852214","pt":1724318669089,"mc":[{"id":"1.232092849","rc":[{"batb":[[0,2.66,10]],"ltp":2.98,"tv":1.48,"id":19587212}]}]}
{"op":"mcm","clk":"11933852351","pt":1724318672693,"mc":[{"id":"1.232092849","rc":[{"batb":[[0,2.68,4]],"ltp":2.98,"tv":1.48,"id":19587212}]}]}
{"op":"mcm","clk":"11933852432","pt":1724318675169,"mc":[{"id":"1.232092849","rc":[{"batb":[[0,2.66,10]],"ltp":2.98,"tv":1.48,"id":19587212}]}]}
{"op":"mcm","clk":"11933852578","pt":1724318678409,"mc":[{"id":"1.232092849","rc":[{"batb":[[0,2.64,5],[1,2.4,41.09],[2,2,6.17]],"ltp":2.98,"tv":1.48,"id":19587212}]}]}
{"op":"mcm","clk":"11933852584","pt":1724318678613,"mc":[{"id":"1.232092849","rc":[{"batb":[[0,2.66,4],[1,2.64,5],[2,2.4,41.09]],"ltp":2.98,"tv":1.48,"id":19587212}]}]}
{"op":"mcm","clk":"11933852678","pt":1724318680887,"mc":[{"id":"1.232092849","rc":[{"batb":[[0,2.66,10]],"ltp":2.98,"tv":1.48,"id":19587212}]}]}
{"op":"mcm","clk":"11933852770","pt":1724318684291,"mc":[{"id":"1.232092849","rc":[{"batb":[[0,2.66,4]],"ltp":2.98,"tv":1.48,"id":19587212}]}]}
{"op":"mcm","clk":"11933852834","pt":1724318686714,"mc":[{"id":"1.232092849","rc":[{"batb":[[0,2.66,10]],"ltp":2.98,"tv":1.48,"id":19587212}]}]}
{"op":"mcm","clk":"11933852977","pt":1724318690120,"mc":[{"id":"1.232092849","rc":[{"batb":[[0,2.66,4]],"ltp":2.98,"tv":1.48,"id":19587212}]}]}
{"op":"mcm","clk":"11933853075","pt":1724318692395,"mc":[{"id":"1.232092849","rc":[{"batb":[[0,2.64,5],[1,2.4,41.09],[2,2,6.17]],"ltp":2.98,"tv":1.48,"id":19587212}]}]}
{"op":"mcm","clk":"11933853083","pt":1724318692600,"mc":[{"id":"1.232092849","rc":[{"batb":[[0,2.66,10],[1,2.64,5],[2,2.4,41.09]],"ltp":2.98,"tv":1.48,"id":19587212}]}]}
{"op":"mcm","clk":"11933853234","pt":1724318696322,"mc":[{"id":"1.232092849","rc":[{"batb":[[0,2.66,4]],"ltp":2.98,"tv":1.48,"id":19587212}]}]}
{"op":"mcm","clk":"11933853324","pt":1724318698744,"mc":[{"id":"1.232092849","rc":[{"batb":[[0,2.66,10]],"ltp":2.98,"tv":1.48,"id":19587212}]}]}
{"op":"mcm","clk":"11933853431","pt":1724318701914,"mc":[{"id":"1.232092849","rc":[{"batb":[[0,2.68,4],[1,2.64,44.97]],"ltp":2.98,"tv":1.48,"id":19587212}]}]}
{"op":"mcm","clk":"11933853516","pt":1724318704239,"mc":[{"id":"1.232092849","rc":[{"batb":[[0,2.66,10]],"ltp":2.98,"tv":1.48,"id":19587212}]}]}
{"op":"mcm","clk":"11933853641","pt":1724318707549,"mc":[{"id":"1.232092849","rc":[{"batb":[[0,2.64,44.97],[1,2.4,41.09],[2,2,6.17]],"ltp":2.98,"tv":1.48,"id":19587212}]}]}
{"op":"mcm","clk":"11933853645","pt":1724318707652,"mc":[{"id":"1.232092849","rc":[{"batb":[[0,2.66,4],[1,2.64,44.97],[2,2.4,41.09]],"ltp":2.98,"tv":1.48,"id":19587212}]}]}
{"op":"mcm","clk":"11933853737","pt":1724318710238,"mc":[{"id":"1.232092849","rc":[{"batb":[[0,2.66,10]],"ltp":2.98,"tv":1.48,"id":19587212}]}]}
{"op":"mcm","clk":"11933853832","pt":1724318712526,"mc":[{"id":"1.232092849","rc":[{"batb":[[0,2.68,4],[1,2.66,10],[2,2.64,44.97]],"ltp":2.98,"tv":1.48,"id":19587212}]}]}
{"op":"mcm","clk":"11933853910","pt":1724318713524,"mc":[{"id":"1.232092849","rc":[{"batb":[[1,2.64,44.97],[2,2.4,41.09]],"ltp":2.98,"tv":1.48,"id":19587212}]}]}
{"op":"mcm","clk":"11933853983","pt":1724318714854,"mc":[{"id":"1.232092849","rc":[{"batb":[[0,2.64,44.97],[1,2.4,41.09],[2,2,6.17]],"ltp":2.98,"tv":1.48,"id":19587212}]}]}
{"op":"mcm","clk":"11933854202","pt":1724318718841,"mc":[{"id":"1.232092849","rc":[{"batb":[[0,2.66,14],[1,2.64,44.97],[2,2.4,41.09]],"ltp":2.98,"tv":1.48,"id":19587212}]}]}
{"op":"mcm","clk":"11933854310","pt":1724318721333,"mc":[{"id":"1.232092849","rc":[{"batb":[[0,2.66,10]],"ltp":2.98,"tv":1.48,"id":19587212}]}]}
{"op":"mcm","clk":"11933854342","pt":1724318722354,"mc":[{"id":"1.232092849","rc":[{"batb":[[0,2.64,44.97],[1,2.4,41.09],[2,2,6.17]],"ltp":2.98,"tv":1.48,"id":19587212}]}]}
{"op":"mcm","clk":"11933854431","pt":1724318725033,"mc":[{"id":"1.232092849","rc":[{"batb":[[0,2.66,14],[1,2.64,44.97],[2,2.4,41.09]],"ltp":2.98,"tv":1.48,"id":19587212}]}]}
{"op":"mcm","clk":"11933854543","pt":1724318727566,"mc":[{"id":"1.232092849","rc":[{"batb":[[0,2.66,10]],"ltp":2.98,"tv":1.48,"id":19587212}]}]}
{"op":"mcm","clk":"11933854572","pt":1724318728547,"mc":[{"id":"1.232092849","rc":[{"batb":[[0,2.64,44.97],[1,2.4,41.09],[2,2,6.17]],"ltp":2.98,"tv":1.48,"id":19587212}]}]}
{"op":"mcm","clk":"11933854617","pt":1724318729737,"mc":[{"id":"1.232092849","rc":[{"batb":[[0,2.66,4],[1,2.64,44.97],[2,2.4,41.09]],"ltp":2.98,"tv":1.48,"id":19587212}]}]}
{"op":"mcm","clk":"11933854675","pt":1724318731253,"mc":[{"id":"1.232092849","rc":[{"batb":[[0,2.68,10],[1,2.66,4],[2,2.64,44.97]],"ltp":2.98,"tv":1.48,"id":19587212}]}]}
{"op":"mcm","clk":"11933854717","pt":1724318732077,"mc":[{"id":"1.232092849","rc":[{"batb":[[1,2.64,44.97],[2,2.4,41.09]],"ltp":2.98,"tv":1.48,"id":19587212}]}]}
{"op":"mcm","clk":"11933854827","pt":1724318734963,"mc":[{"id":"1.232092849","rc":[{"batb":[[0,2.66,4]],"ltp":2.98,"tv":1.48,"id":19587212}]}]}
{"op":"mcm","clk":"11933854907","pt":1724318737279,"mc":[{"id":"1.232092849","rc":[{"batb":[[0,2.66,10]],"ltp":2.98,"tv":1.48,"id":19587212}]}]}
{"op":"mcm","clk":"11933855028","pt":1724318740491,"mc":[{"id":"1.232092849","rc":[{"batb":[[0,2.64,44.97],[1,2.4,41.09],[2,2,6.17]],"ltp":2.98,"tv":1.48,"id":19587212}]}]}
{"op":"mcm","clk":"11933855045","pt":1724318740752,"mc":[{"id":"1.232092849","rc":[{"batb":[[0,2.66,4],[1,2.64,44.97],[2,2.4,41.09]],"ltp":2.98,"tv":1.48,"id":19587212}]}]}
{"op":"mcm","clk":"11933855123","pt":1724318743289,"mc":[{"id":"1.232092849","rc":[{"batb":[[0,2.66,10]],"ltp":2.98,"tv":1.48,"id":19587212}]}]}
{"op":"mcm","clk":"11933855253","pt":1724318746790,"mc":[{"id":"1.232092849","rc":[{"batb":[[0,2.68,4]],"ltp":2.98,"tv":1.48,"id":19587212}]}]}
{"op":"mcm","clk":"11933855373","pt":1724318749267,"mc":[{"id":"1.232092849","rc":[{"batb":[[0,2.66,10]],"ltp":2.98,"tv":1.48,"id":19587212}]}]}
{"op":"mcm","clk":"11933855508","pt":1724318752568,"mc":[{"id":"1.232092849","rc":[{"batb":[[0,2.66,4]],"ltp":2.98,"tv":1.48,"id":19587212}]}]}
{"op":"mcm","clk":"11933855614","pt":1724318755097,"mc":[{"id":"1.232092849","rc":[{"batb":[[0,2.66,10]],"ltp":2.98,"tv":1.48,"id":19587212}]}]}
{"op":"mcm","clk":"11933855749","pt":1724318758292,"mc":[{"id":"1.232092849","rc":[{"batb":[[0,2.68,4]],"ltp":2.98,"tv":1.48,"id":19587212}]}]}
{"op":"mcm","clk":"11933855819","pt":1724318760085,"mc":[{"id":"1.232092849","rc":[{"batb":[[0,2.64,44.97],[1,2.4,41.09],[2,2,6.17]],"ltp":2.98,"tv":1.48,"id":19587212}]}]}
{"op":"mcm","clk":"11933855954","pt":1724318763485,"mc":[{"id":"1.232092849","rc":[{"batb":[[0,2.66,14],[1,2.64,44.97],[2,2.4,41.09]],"ltp":2.98,"tv":1.48,"id":19587212}]}]}
{"op":"mcm","clk":"11933856039","pt":1724318765898,"mc":[{"id":"1.232092849","rc":[{"batb":[[0,2.66,10]],"ltp":2.98,"tv":1.48,"id":19587212}]}]}
{"op":"mcm","clk":"11933856079","pt":1724318766926,"mc":[{"id":"1.232092849","rc":[{"batb":[[0,2.64,44.97],[1,2.4,41.09],[2,2,6.17]],"ltp":2.98,"tv":1.48,"id":19587212}]}]}
{"op":"mcm","clk":"11933856117","pt":1724318768112,"mc":[{"id":"1.232092849","rc":[{"batb":[[0,2.66,4],[1,2.64,44.97],[2,2.4,41.09]],"ltp":2.98,"tv":1.48,"id":19587212}]}]}
{"op":"mcm","clk":"11933856192","pt":1724318770393,"mc":[{"id":"1.232092849","rc":[{"batb":[[0,2.66,10]],"ltp":2.98,"tv":1.48,"id":19587212}]}]}
{"op":"mcm","clk":"11933856343","pt":1724318773801,"mc":[{"id":"1.232092849","rc":[{"batb":[[0,2.66,4]],"ltp":2.98,"tv":1.48,"id":19587212}]}]}
{"op":"mcm","clk":"11933856480","pt":1724318776525,"mc":[{"id":"1.232092849","rc":[{"batb":[[0,2.66,10]],"ltp":2.98,"tv":1.48,"id":19587212}]}]}
{"op":"mcm","clk":"11933856627","pt":1724318780133,"mc":[{"id":"1.232092849","rc":[{"batb":[[0,2.66,4]],"ltp":2.98,"tv":1.48,"id":19587212}]}]}
{"op":"mcm","clk":"11933856706","pt":1724318782540,"mc":[{"id":"1.232092849","rc":[{"batb":[[0,2.66,10]],"ltp":2.98,"tv":1.48,"id":19587212}]}]}
{"op":"mcm","clk":"11933856837","pt":1724318785930,"mc":[{"id":"1.232092849","rc":[{"batb":[[0,2.66,4]],"ltp":2.98,"tv":1.48,"id":19587212}]}]}
{"op":"mcm","clk":"11933856942","pt":1724318788451,"mc":[{"id":"1.232092849","rc":[{"batb":[[0,2.66,10]],"ltp":2.98,"tv":1.48,"id":19587212}]}]}
{"op":"mcm","clk":"11933857038","pt":1724318791131,"mc":[{"id":"1.232092849","rc":[{"batb":[[0,2.68,4],[1,2.66,10],[2,2.64,44.97]],"ltp":2.98,"tv":1.48,"id":19587212}]}]}
{"op":"mcm","clk":"11933857070","pt":1724318791852,"mc":[{"id":"1.232092849","rc":[{"batb":[[1,2.64,44.97],[2,2.4,41.09]],"ltp":2.98,"tv":1.48,"id":19587212}]}]}
{"op":"mcm","clk":"11933857134","pt":1724318793549,"mc":[{"id":"1.232092849","rc":[{"batb":[[0,2.64,44.97],[1,2.4,41.09],[2,2,6.17]],"ltp":2.98,"tv":1.48,"id":19587212}]}]}
{"op":"mcm","clk":"11933857288","pt":1724318797051,"mc":[{"id":"1.232092849","rc":[{"batb":[[0,2.66,14],[1,2.64,44.97],[2,2.4,41.09]],"ltp":2.98,"tv":1.48,"id":19587212}]}]}
{"op":"mcm","clk":"11933857377","pt":1724318799563,"mc":[{"id":"1.232092849","rc":[{"batb":[[0,2.66,10]],"ltp":2.98,"tv":1.48,"id":19587212}]}]}
{"op":"mcm","clk":"11933857396","pt":1724318800160,"mc":[{"id":"1.232092849","rc":[{"batb":[[0,2.64,44.97],[1,2.4,41.09],[2,2,6.17]],"ltp":2.98,"tv":1.48,"id":19587212}]}]}
{"op":"mcm","clk":"11933857504","pt":1724318803269,"mc":[{"id":"1.232092849","rc":[{"batb":[[0,2.66,14],[1,2.64,44.97],[2,2.4,41.09]],"ltp":2.98,"tv":1.48,"id":19587212}]}]}
{"op":"mcm","clk":"11933857582","pt":1724318805851,"mc":[{"id":"1.232092849","rc":[{"batb":[[0,2.66,10]],"ltp":2.98,"tv":1.48,"id":19587212}]}]}
{"op":"mcm","clk":"11933857626","pt":1724318806862,"mc":[{"id":"1.232092849","rc":[{"batb":[[0,2.64,44.97],[1,2.4,41.09],[2,2,6.17]],"ltp":2.98,"tv":1.48,"id":19587212}]}]}
{"op":"mcm","clk":"11933857740","pt":1724318809335,"mc":[{"id":"1.232092849","rc":[{"batb":[[0,2.66,14],[1,2.64,44.97],[2,2.4,41.09]],"ltp":2.98,"tv":1.48,"id":19587212}]}]}
{"op":"mcm","clk":"11933857829","pt":1724318811850,"mc":[{"id":"1.232092849","rc":[{"batb":[[0,2.66,10]],"ltp":2.98,"tv":1.48,"id":19587212}]}]}
{"op":"mcm","clk":"11933857863","pt":1724318812865,"mc":[{"id":"1.232092849","rc":[{"batb":[[0,2.64,44.97],[1,2.4,41.09],[2,2,6.17]],"ltp":2.98,"tv":1.48,"id":19587212}]}]}
{"op":"mcm","clk":"11933857917","pt":1724318813952,"mc":[{"id":"1.232092849","rc":[{"batb":[[0,2.66,4],[1,2.64,44.97],[2,2.4,41.09]],"ltp":2.98,"tv":1.48,"id":19587212}]}]}
{"op":"mcm","clk":"11933857979","pt":1724318815181,"mc":[{"id":"1.232092849","rc":[{"batb":[[0,2.68,10],[1,2.66,4],[2,2.64,44.97]],"ltp":2.98,"tv":1.48,"id":19587212}]}]}
{"op":"mcm","clk":"11933858022","pt":1724318816359,"mc":[{"id":"1.232092849","rc":[{"batb":[[1,2.64,44.97],[2,2.4,41.09]],"ltp":2.98,"tv":1.48,"id":19587212}]}]}
{"op":"mcm","clk":"11933858108","pt":1724318818562,"mc":[{"id":"1.232092849","rc":[{"batb":[[0,2.7,4]],"ltp":2.98,"tv":1.48,"id":19587212}]}]}
{"op":"mcm","clk":"11933858207","pt":1724318821082,"mc":[{"id":"1.232092849","rc":[{"batb":[[0,2.66,10]],"ltp":2.98,"tv":1.48,"id":19587212}]}]}
{"op":"mcm","clk":"11933858299","pt":1724318823557,"mc":[{"id":"1.232092849","rc":[{"batb":[[0,2.68,4],[1,2.66,10],[2,2.64,44.97]],"ltp":2.98,"tv":1.48,"id":19587212}]}]}
{"op":"mcm","clk":"11933858335","pt":1724318824485,"mc":[{"id":"1.232092849","rc":[{"batb":[[1,2.64,44.97],[2,2.4,41.09]],"ltp":2.98,"tv":1.48,"id":19587212}]}]}
{"op":"mcm","clk":"11933858406","pt":1724318825971,"mc":[{"id":"1.232092849","rc":[{"batb":[[0,2.64,44.97],[1,2.4,41.09],[2,2,6.17]],"ltp":2.98,"tv":1.48,"id":19587212}]}]}
{"op":"mcm","clk":"11933858575","pt":1724318829268,"mc":[{"id":"1.232092849","rc":[{"batb":[[0,2.66,14],[1,2.64,44.97],[2,2.4,41.09]],"ltp":2.98,"tv":1.48,"id":19587212}]}]}
{"op":"mcm","clk":"11933858660","pt":1724318831572,"mc":[{"id":"1.232092849","rc":[{"batb":[[0,2.66,10]],"ltp":2.98,"tv":1.48,"id":19587212}]}]}
{"op":"mcm","clk":"11933858698","pt":1724318832598,"mc":[{"id":"1.232092849","rc":[{"batb":[[0,2.64,44.97],[1,2.4,41.09],[2,2,6.17]],"ltp":2.98,"tv":1.48,"id":19587212}]}]}
{"op":"mcm","clk":"11933858840","pt":1724318835379,"mc":[{"id":"1.232092849","rc":[{"batb":[[0,2.66,14],[1,2.64,44.97],[2,2.4,41.09]],"ltp":2.98,"tv":1.48,"id":19587212}]}]}
{"op":"mcm","clk":"11933858960","pt":1724318837687,"mc":[{"id":"1.232092849","rc":[{"batb":[[0,2.66,10]],"ltp":2.98,"tv":1.48,"id":19587212}]}]}
{"op":"mcm","clk":"11933859010","pt":1724318838811,"mc":[{"id":"1.232092849","rc":[{"batb":[[0,2.64,44.97],[1,2.4,41.09],[2,2,6.17]],"ltp":2.98,"tv":1.48,"id":19587212}]}]}
{"op":"mcm","clk":"11933859290","pt":1724318844915,"mc":[{"id":"1.232092849","rc":[{"batb":[[0,2.66,14],[1,2.64,44.97],[2,2.4,41.09]],"ltp":2.98,"tv":1.48,"id":19587212}]}]}
{"op":"mcm","clk":"11933859376","pt":1724318847446,"mc":[{"id":"1.232092849","rc":[{"batb":[[0,2.66,10]],"ltp":2.98,"tv":1.48,"id":19587212}]}]}
{"op":"mcm","clk":"11933859411","pt":1724318848220,"mc":[{"id":"1.232092849","rc":[{"batb":[[0,2.64,44.97],[1,2.4,41.09],[2,2,6.17]],"ltp":2.98,"tv":1.48,"id":19587212}]}]}
{"op":"mcm","clk":"11933859558","pt":1724318851017,"mc":[{"id":"1.232092849","rc":[{"batb":[[0,2.66,14],[1,2.64,44.97],[2,2.4,41.09]],"ltp":2.98,"tv":1.48,"id":19587212}]}]}
{"op":"mcm","clk":"11933859660","pt":1724318853439,"mc":[{"id":"1.232092849","rc":[{"batb":[[0,2.66,10]],"ltp":2.98,"tv":1.48,"id":19587212}]}]}
{"op":"mcm","clk":"11933859704","pt":1724318854617,"mc":[{"id":"1.232092849","rc":[{"batb":[[0,2.64,44.97],[1,2.4,41.09],[2,2,6.17]],"ltp":2.98,"tv":1.48,"id":19587212}]}]}
{"op":"mcm","clk":"11933859753","pt":1724318855701,"mc":[{"id":"1.232092849","rc":[{"batb":[[0,2.66,4],[1,2.64,44.97],[2,2.4,41.09]],"ltp":2.98,"tv":1.48,"id":19587212}]}]}
{"op":"mcm","clk":"11933859866","pt":1724318858213,"mc":[{"id":"1.232092849","rc":[{"batb":[[0,2.66,10]],"ltp":2.98,"tv":1.48,"id":19587212}]}]}
{"op":"mcm","clk":"11933859984","pt":1724318861447,"mc":[{"id":"1.232092849","rc":[{"batb":[[0,2.68,4]],"ltp":2.98,"tv":1.48,"id":19587212}]}]}
{"op":"mcm","clk":"11933860072","pt":1724318863354,"mc":[{"id":"1.232092849","rc":[{"batb":[[0,2.64,44.97],[1,2.4,41.09],[2,2,6.17]],"ltp":2.98,"tv":1.48,"id":19587212}]}]}
{"op":"mcm","clk":"11933860152","pt":1724318865157,"mc":[{"id":"1.232092849","rc":[{"batb":[[0,2.66,10],[1,2.64,44.97],[2,2.4,41.09]],"ltp":2.98,"tv":1.48,"id":19587212}]}]}
{"op":"mcm","clk":"11933860336","pt":1724318868557,"mc":[{"id":"1.232092849","rc":[{"batb":[[0,2.64,44.97],[1,2.4,41.09],[2,2,6.17]],"ltp":2.98,"tv":1.48,"id":19587212}]}]}
{"op":"mcm","clk":"11933860348","pt":1724318868820,"mc":[{"id":"1.232092849","rc":[{"batb":[[0,2.66,4],[1,2.64,44.97],[2,2.4,41.09]],"ltp":2.98,"tv":1.48,"id":19587212}]}]}
{"op":"mcm","clk":"11933860449","pt":1724318871232,"mc":[{"id":"1.232092849","rc":[{"batb":[[0,2.66,10]],"ltp":2.98,"tv":1.48,"id":19587212}]}]}
{"op":"mcm","clk":"11933860652","pt":1724318875039,"mc":[{"id":"1.232092849","rc":[{"batb":[[0,2.68,4]],"ltp":2.98,"tv":1.48,"id":19587212}]}]}
{"op":"mcm","clk":"11933860812","pt":1724318878254,"mc":[{"id":"1.232092849","rc":[{"batb":[[0,2.66,10]],"ltp":2.98,"tv":1.48,"id":19587212}]}]}
{"op":"mcm","clk":"11933860980","pt":1724318881453,"mc":[{"id":"1.232092849","rc":[{"batb":[[0,2.64,44.97],[1,2.4,41.09],[2,2,6.17]],"ltp":2.98,"tv":1.48,"id":19587212}]}]}
{"op":"mcm","clk":"11933860994","pt":1724318881667,"mc":[{"id":"1.232092849","rc":[{"batb":[[0,2.66,4],[1,2.64,44.97],[2,2.4,41.09]],"ltp":2.98,"tv":1.48,"id":19587212}]}]}
{"op":"mcm","clk":"11933861088","pt":1724318883949,"mc":[{"id":"1.232092849","rc":[{"batb":[[0,2.68,10]],"ltp":2.98,"tv":1.48,"id":19587212}]}]}
{"op":"mcm","clk":"11933861244","pt":1724318887137,"mc":[{"id":"1.232092849","rc":[{"batb":[[0,2.66,4]],"ltp":2.98,"tv":1.48,"id":19587212}]}]}
{"op":"mcm","clk":"11933861349","pt":1724318889555,"mc":[{"id":"1.232092849","rc":[{"batb":[[0,2.66,10]],"ltp":2.98,"tv":1.48,"id":19587212}]}]}
{"op":"mcm","clk":"11933861506","pt":1724318893063,"mc":[{"id":"1.232092849","rc":[{"batb":[[0,2.66,4]],"ltp":2.98,"tv":1.48,"id":19587212}]}]}
{"op":"mcm","clk":"11933861584","pt":1724318895476,"mc":[{"id":"1.232092849","rc":[{"batb":[[0,2.66,10]],"ltp":2.98,"tv":1.48,"id":19587212}]}]}
{"op":"mcm","clk":"11933861729","pt":1724318898891,"mc":[{"id":"1.232092849","rc":[{"batb":[[0,2.66,4]],"ltp":2.98,"tv":1.48,"id":19587212}]}]}
{"op":"mcm","clk":"11933861855","pt":1724318901161,"mc":[{"id":"1.232092849","rc":[{"batb":[[0,2.66,10]],"ltp":2.98,"tv":1.48,"id":19587212}]}]}
{"op":"mcm","clk":"11933862008","pt":1724318904459,"mc":[{"id":"1.232092849","rc":[{"batb":[[0,2.66,4]],"ltp":2.98,"tv":1.48,"id":19587212}]}]}
{"op":"mcm","clk":"11933862117","pt":1724318907050,"mc":[{"id":"1.232092849","rc":[{"batb":[[0,2.66,10]],"ltp":2.98,"tv":1.48,"id":19587212}]}]}
{"op":"mcm","clk":"11933862191","pt":1724318909161,"mc":[{"id":"1.232092849","rc":[{"batb":[[0,2.68,4],[1,2.66,10],[2,2.64,44.97]],"ltp":2.98,"tv":1.48,"id":19587212}]}]}
{"op":"mcm","clk":"11933862229","pt":1724318910496,"mc":[{"id":"1.232092849","rc":[{"batb":[[1,2.64,44.97],[2,2.4,41.09]],"ltp":2.98,"tv":1.48,"id":19587212}]}]}
{"op":"mcm","clk":"11933862268","pt":1724318911689,"mc":[{"id":"1.232092849","rc":[{"batb":[[0,2.64,44.97],[1,2.4,41.09],[2,2,6.17]],"ltp":2.98,"tv":1.48,"id":19587212}]}]}
{"op":"mcm","clk":"11933862714","pt":1724318921173,"mc":[{"id":"1.232092849","rc":[{"batb":[[0,2.66,14],[1,2.64,44.97],[2,2.4,41.09]],"ltp":2.98,"tv":1.48,"id":19587212}]}]}
{"op":"mcm","clk":"11933862849","pt":1724318923789,"mc":[{"id":"1.232092849","rc":[{"batb":[[0,2.66,10]],"ltp":2.98,"tv":1.48,"id":19587212}]}]}
{"op":"mcm","clk":"11933862918","pt":1724318924815,"mc":[{"id":"1.232092849","rc":[{"batb":[[0,2.64,44.97],[1,2.4,41.09],[2,2,6.17]],"ltp":2.98,"tv":1.48,"id":19587212}]}]}
{"op":"mcm","clk":"11933862996","pt":1724318925997,"mc":[{"id":"1.232092849","rc":[{"batb":[[0,2.66,4],[1,2.64,44.97],[2,2.4,41.09]],"ltp":2.98,"tv":1.48,"id":19587212}]}]}
{"op":"mcm","clk":"11933863113","pt":1724318928406,"mc":[{"id":"1.232092849","rc":[{"batb":[[0,2.66,10]],"ltp":2.98,"tv":1.48,"id":19587212}]}]}
{"op":"mcm","clk":"11933863240","pt":1724318931388,"mc":[{"id":"1.232092849","rc":[{"batb":[[0,2.68,4],[1,2.66,10],[2,2.64,44.97]],"ltp":2.98,"tv":1.48,"id":19587212}]}]}
{"op":"mcm","clk":"11933863248","pt":1724318931598,"mc":[{"id":"1.232092849","rc":[{"batb":[[1,2.64,44.97],[2,2.4,41.09]],"ltp":2.98,"tv":1.48,"id":19587212}]}]}
{"op":"mcm","clk":"11933863353","pt":1724318933906,"mc":[{"id":"1.232092849","rc":[{"batb":[[0,2.66,10]],"ltp":2.98,"tv":1.48,"id":19587212}]}]}
{"op":"mcm","clk":"11933863518","pt":1724318937386,"mc":[{"id":"1.232092849","rc":[{"batb":[[0,2.66,4]],"ltp":2.98,"tv":1.48,"id":19587212}]}]}
{"op":"mcm","clk":"11933863650","pt":1724318939923,"mc":[{"id":"1.232092849","rc":[{"batb":[[0,2.66,10]],"ltp":2.98,"tv":1.48,"id":19587212}]}]}
{"op":"mcm","clk":"11933863844","pt":1724318943541,"mc":[{"id":"1.232092849","rc":[{"batb":[[0,2.66,4]],"ltp":2.98,"tv":1.48,"id":19587212}]}]}
{"op":"mcm","clk":"11933863959","pt":1724318945913,"mc":[{"id":"1.232092849","rc":[{"batb":[[0,2.66,10]],"ltp":2.98,"tv":1.48,"id":19587212}]}]}
{"op":"mcm","clk":"11933864153","pt":1724318949457,"mc":[{"id":"1.232092849","rc":[{"batb":[[0,2.66,4]],"ltp":2.98,"tv":1.48,"id":19587212}]}]}
{"op":"mcm","clk":"11933864268","pt":1724318951821,"mc":[{"id":"1.232092849","rc":[{"batb":[[0,2.66,10]],"ltp":2.98,"tv":1.48,"id":19587212}]}]}
{"op":"mcm","clk":"11933864437","pt":1724318955359,"mc":[{"id":"1.232092849","rc":[{"batb":[[0,2.66,4]],"ltp":2.98,"tv":1.48,"id":19587212}]}]}
{"op":"mcm","clk":"11933864546","pt":1724318957568,"mc":[{"id":"1.232092849","rc":[{"batb":[[0,2.64,44.97],[1,2.4,41.09],[2,2,6.17]],"ltp":2.98,"tv":1.48,"id":19587212}]}]}
{"op":"mcm","clk":"11933864553","pt":1724318957623,"mc":[{"id":"1.232092849","rc":[{"batb":[[0,2.68,10],[1,2.64,44.97],[2,2.4,41.09]],"ltp":2.98,"tv":1.48,"id":19587212}]}]}
{"op":"mcm","clk":"11933864754","pt":1724318961162,"mc":[{"id":"1.232092849","rc":[{"batb":[[0,2.66,4]],"ltp":2.98,"tv":1.48,"id":19587212}]}]}
{"op":"mcm","clk":"11933864887","pt":1724318963929,"mc":[{"id":"1.232092849","rc":[{"batb":[[0,2.66,10]],"ltp":2.98,"tv":1.48,"id":19587212}]}]}
{"op":"mcm","clk":"11933864988","pt":1724318966139,"mc":[{"id":"1.232092849","rc":[{"batb":[[0,2.68,4],[1,2.66,10],[2,2.64,44.97]],"ltp":2.98,"tv":1.48,"id":19587212}]}]}
{"op":"mcm","clk":"11933865038","pt":1724318967274,"mc":[{"id":"1.232092849","rc":[{"batb":[[1,2.64,44.97],[2,2.4,41.09]],"ltp":2.98,"tv":1.48,"id":19587212}]}]}
{"op":"mcm","clk":"11933865110","pt":1724318968776,"mc":[{"id":"1.232092849","rc":[{"batb":[[0,2.64,44.97],[1,2.4,41.09],[2,2,6.17]],"ltp":2.98,"tv":1.48,"id":19587212}]}]}
{"op":"mcm","clk":"11933865225","pt":1724318971164,"mc":[{"id":"1.232092849","rc":[{"batb":[[0,2.66,14],[1,2.64,44.97],[2,2.4,41.09]],"ltp":2.98,"tv":1.48,"id":19587212}]}]}
{"op":"mcm","clk":"11933865371","pt":1724318973654,"mc":[{"id":"1.232092849","rc":[{"batb":[[0,2.66,10]],"ltp":2.98,"tv":1.48,"id":19587212}]}]}
{"op":"mcm","clk":"11933865414","pt":1724318974636,"mc":[{"id":"1.232092849","rc":[{"batb":[[0,2.64,44.97],[1,2.4,41.09],[2,2,6.17]],"ltp":2.98,"tv":1.48,"id":19587212}]}]}
{"op":"mcm","clk":"11933865523","pt":1724318976946,"mc":[{"id":"1.232092849","rc":[{"batb":[[0,2.66,14],[1,2.64,44.97],[2,2.4,41.09]],"ltp":2.98,"tv":1.48,"id":19587212}]}]}
{"op":"mcm","clk":"11933865636","pt":1724318979267,"mc":[{"id":"1.232092849","rc":[{"batb":[[0,2.66,10]],"ltp":2.98,"tv":1.48,"id":19587212}]}]}
{"op":"mcm","clk":"11933865677","pt":1724318980192,"mc":[{"id":"1.232092849","rc":[{"batb":[[0,2.64,44.97],[1,2.4,41.09],[2,2,6.17]],"ltp":2.98,"tv":1.48,"id":19587212}]}]}
{"op":"mcm","clk":"11933865769","pt":1724318981645,"mc":[{"id":"1.232092849","rc":[{"batb":[[0,2.66,4],[1,2.64,44.97],[2,2.4,41.09]],"ltp":2.98,"tv":1.48,"id":19587212}]}]}
{"op":"mcm","clk":"11933865872","pt":1724318984156,"mc":[{"id":"1.232092849","rc":[{"batb":[[0,2.66,10]],"ltp":2.98,"tv":1.48,"id":19587212}]}]}
{"op":"mcm","clk":"11933866005","pt":1724318987555,"mc":[{"id":"1.232092849","rc":[{"batb":[[0,2.68,4]],"ltp":2.98,"tv":1.48,"id":19587212}]}]}
{"op":"mcm","clk":"11933866095","pt":1724318989173,"mc":[{"id":"1.232092849","rc":[{"batb":[[0,2.64,44.97],[1,2.4,41.09],[2,2,6.17]],"ltp":2.98,"tv":1.48,"id":19587212}]}]}
{"op":"mcm","clk":"11933866177","pt":1724318990953,"mc":[{"id":"1.232092849","rc":[{"batb":[[0,2.66,10],[1,2.64,44.97],[2,2.4,41.09]],"ltp":2.98,"tv":1.48,"id":19587212}]}]}
{"op":"mcm","clk":"11933866353","pt":1724318994200,"mc":[{"id":"1.232092849","rc":[{"batb":[[0,2.68,4]],"ltp":2.98,"tv":1.48,"id":19587212}]}]}
{"op":"mcm","clk":"11933866442","pt":1724318996366,"mc":[{"id":"1.232092849","rc":[{"batb":[[0,2.7,10]],"ltp":2.98,"tv":1.48,"id":19587212}]}]}
{"op":"mcm","clk":"11933866544","pt":1724318998779,"mc":[{"id":"1.232092849","rc":[{"batb":[[0,2.72,4],[1,2.7,10],[2,2.64,44.97]],"ltp":2.98,"tv":1.48,"id":19587212}]}]}
{"op":"mcm","clk":"11933866588","pt":1724318999597,"mc":[{"id":"1.232092849","rc":[{"batb":[[1,2.64,44.97],[2,2.4,41.09]],"ltp":2.98,"tv":1.48,"id":19587212}]}]}
{"op":"mcm","clk":"11933866650","pt":1724319000998,"mc":[{"id":"1.232092849","rc":[{"batb":[[0,2.64,44.97],[1,2.4,41.09],[2,2,6.17]],"ltp":2.98,"tv":1.48,"id":19587212}]}]}
{"op":"mcm","clk":"11933866710","pt":1724319002200,"mc":[{"id":"1.232092849","rc":[{"batb":[[0,2.66,10],[1,2.64,44.97],[2,2.4,41.09]],"ltp":2.98,"tv":1.48,"id":19587212}]}]}
{"op":"mcm","clk":"11933866773","pt":1724319003396,"mc":[{"id":"1.232092849","rc":[{"batb":[[0,2.68,4],[1,2.66,10],[2,2.64,44.97]],"ltp":2.98,"tv":1.48,"id":19587212}]}]}
{"op":"mcm","clk":"11933866897","pt":1724319005785,"mc":[{"id":"1.232092849","rc":[{"batb":[[0,2.64,44.97],[1,2.4,41.09],[2,2,6.17]],"ltp":2.98,"tv":1.48,"id":19587212}]}]}
{"op":"mcm","clk":"11933867054","pt":1724319008888,"mc":[{"id":"1.232092849","rc":[{"batb":[[0,2.66,14],[1,2.64,44.97],[2,2.4,41.09]],"ltp":2.98,"tv":1.48,"id":19587212}]}]}
{"op":"mcm","clk":"11933867182","pt":1724319011208,"mc":[{"id":"1.232092849","rc":[{"batb":[[0,2.66,10]],"ltp":2.98,"tv":1.48,"id":19587212}]}]}
