{"op":"mcm","clk":"11783471548","pt":1722416365420,"mc":[{"id":"1.231282404","marketDefinition":{"bspMarket":false,"turnInPlayEnabled":true,"persistenceEnabled":true,"marketBaseRate":5.0,"eventId":"33457835","eventTypeId":"4","numberOfWinners":1,"bettingType":"ODDS","marketType":"MATCH_ODDS","marketTime":"2024-08-02T20:00:00.000Z","suspendTime":"2024-08-02T20:00:00.000Z","bspReconciled":false,"complete":true,"inPlay":false,"crossMatching":true,"runnersVoidable":false,"numberOfActiveRunners":2,"betDelay":0,"status":"OPEN","runners":[{"status":"ACTIVE","sortPriority":1,"id":19144239,"name":"Vancouver Knights"},{"status":"ACTIVE","sortPriority":2,"id":58385184,"name":"Surrey Jaguars"}],"regulators":["MR_INT"],"countryCode":"GB","discountAllowed":false,"timezone":"GMT","openDate":"2024-08-02T20:00:00.000Z","version":6048541967,"name":"Match Odds","eventName":"Vancouver Knights v Surrey Jaguars"},"rc":[{"batb":[[0,1.03,200],[1,1.02,200],[2,1.01,220]],"ltp":0.0,"tv":0.0,"id":58385184},{"batb":[[0,1.03,200],[1,1.02,200],[2,1.01,220]],"ltp":0.0,"tv":0.0,"id":19144239}]}]}
{"op":"mcm","clk":"11783471598","pt":1722416366688,"mc":[{"id":"1.231282404","marketDefinition":{"bspMarket":false,"turnInPlayEnabled":true,"persistenceEnabled":true,"marketBaseRate":5.0,"eventId":"33457835","eventTypeId":"4","numberOfWinners":1,"bettingType":"ODDS","marketType":"MATCH_ODDS","marketTime":"2024-08-02T20:00:00.000Z","suspendTime":"2024-08-02T20:00:00.000Z","bspReconciled":false,"complete":true,"inPlay":false,"crossMatching":true,"runnersVoidable":false,"numberOfActiveRunners":2,"betDelay":0,"status":"OPEN","runners":[{"status":"ACTIVE","sortPriority":1,"id":19144239,"name":"Vancouver Knights"},{"status":"ACTIVE","sortPriority":2,"id":58385184,"name":"Surrey Jaguars"}],"regulators":["MR_INT"],"countryCode":"GB","discountAllowed":true,"timezone":"GMT","openDate":"2024-08-02T20:00:00.000Z","version":6048541967,"name":"Match Odds","eventName":"Vancouver Knights v Surrey Jaguars"}}]}
{"op":"mcm","clk":"11783472641","pt":1722416397678,"mc":[{"id":"1.231282404","rc":[{"batb":[[2,1.01,6315.2]],"ltp":0.0,"tv":0.0,"id":58385184},{"batb":[[0,1.04,1606.57],[1,1.03,2326.37],[2,1.02,3339.85]],"ltp":0.0,"tv":0.0,"id":19144239}]}]}
{"op":"mcm","clk":"11783472651","pt":1722416397939,"mc":[{"id":"1.231282404","rc":[{"batb":[[0,1.04,1606.57],[1,1.03,2326.37],[2,1.02,3339.85]],"ltp":0.0,"tv":0.0,"id":58385184}]}]}
{"op":"mcm","clk":"11783558254","pt":1722418374167,"mc":[{"id":"1.231282404","rc":[{"batb":[[0,1.05,100],[1,1.04,1608.88],[2,1.03,2329.42]],"ltp":0.0,"tv":0.0,"id":58385184},{"batb":[[0,1.05,100],[1,1.04,1608.88],[2,1.03,2329.42]],"ltp":0.0,"tv":0.0,"id":19144239}]}]}
{"op":"mcm","clk":"11784312647","pt":1722429775035,"mc":[{"id":"1.231282404","rc":[{"batb":[[1,1.04,1608.47],[2,1.03,2328.88]],"ltp":0.0,"tv":0.0,"id":58385184},{"batb":[[1,1.04,1608.47],[2,1.03,2328.88]],"ltp":0.0,"tv":0.0,"id":19144239}]}]}
{"op":"mcm","clk":"11784781946","pt":1722435175079,"mc":[{"id":"1.231282404","rc":[{"batb":[[1,1.04,1610.23],[2,1.03,2331.22]],"ltp":0.0,"tv":0.0,"id":58385184},{"batb":[[1,1.04,1610.23],[2,1.03,2331.22]],"ltp":0.0,"tv":0.0,"id":19144239}]}]}
{"op":"mcm","clk":"11785151862","pt":1722439158933,"mc":[{"id":"1.231282404","rc":[{"batb":[[1,1.04,1606.44],[2,1.03,2326.19]],"ltp":0.0,"tv":0.0,"id":58385184},{"batb":[[0,1.05,100.91],[1,1.04,1606.44],[2,1.03,2326.19]],"ltp":0.0,"tv":0.0,"id":19144239}]}]}
{"op":"mcm","clk":"11785153119","pt":1722439170927,"mc":[{"id":"1.231282404","rc":[{"batb":[[0,1.05,100.91]],"ltp":0.0,"tv":0.0,"id":58385184}]}]}
{"op":"mcm","clk":"11785546108","pt":1722442874346,"mc":[{"id":"1.231282404","rc":[{"batb":[[1,1.04,1607.52],[2,1.03,2327.62]],"ltp":0.0,"tv":0.0,"id":58385184},{"batb":[[1,1.04,1607.52],[2,1.03,2327.62]],"batl":[[0,8,0.95]],"ltp":0.0,"tv":0.0,"id":19144239}]}]}
{"op":"mcm","clk":"11785548199","pt":1722442890883,"mc":[{"id":"1.231282404","rc":[{"batl":[[0,8,0.95]],"ltp":0.0,"tv":0.0,"id":58385184}]}]}
{"op":"mcm","clk":"11785565864","pt":1722443032976,"mc":[{"id":"1.231282404","rc":[{"batb":[[0,1.15,10],[1,1.05,100.91],[2,1.04,1607.52]],"ltp":0.0,"tv":0.0,"id":58385184},{"batb":[[0,1.15,10],[1,1.05,100.91],[2,1.04,1607.52]],"ltp":0.0,"tv":0.0,"id":19144239}]}]}
{"op":"mcm","clk":"11786007313","pt":1722445975025,"mc":[{"id":"1.231282404","rc":[{"batb":[[2,1.04,1605.89]],"ltp":0.0,"tv":0.0,"id":58385184},{"batb":[[2,1.04,1605.89]],"ltp":0.0,"tv":0.0,"id":19144239}]}]}
{"op":"mcm","clk":"11786064787","pt":1722446316917,"mc":[{"id":"1.231282404","rc":[{"batb":[[0,1.25,200],[1,1.15,10],[2,1.05,100.91]],"ltp":0.0,"tv":0.0,"id":58385184},{"batb":[[0,1.25,200],[1,1.15,10],[2,1.05,100.91]],"ltp":0.0,"tv":0.0,"id":19144239}]}]}
{"op":"mcm","clk":"11786302031","pt":1722447781419,"mc":[{"id":"1.231282404","rc":[{"batb":[[0,1.26,7.35],[1,1.25,200],[2,1.15,10]],"ltp":0.0,"tv":0.0,"id":19144239}]}]}
{"op":"mcm","clk":"11786302121","pt":1722447781796,"mc":[{"id":"1.231282404","rc":[{"batb":[[0,1.26,7.67],[1,1.25,200],[2,1.15,10]],"ltp":0.0,"tv":0.0,"id":58385184}]}]}
{"op":"mcm","clk":"11787027506","pt":1722453308659,"mc":[{"id":"1.231282404","rc":[{"batb":[[0,1.26,7.66],[2,1.05,100.91]],"batl":[[0,8,0.95]],"ltp":0.0,"tv":0.0,"id":58385184},{"batb":[[0,1.26,7.34],[2,1.05,100.91]],"batl":[[0,8,0.95]],"ltp":0.0,"tv":0.0,"id":19144239}]}]}
{"op":"mcm","clk":"11787027518","pt":1722453308725,"mc":[{"id":"1.231282404","rc":[{"batb":[[0,1.27,10],[1,1.26,7.66],[2,1.25,200]],"ltp":0.0,"tv":0.0,"id":58385184},{"batb":[[0,1.27,10],[1,1.26,7.34],[2,1.25,200]],"ltp":0.0,"tv":0.0,"id":19144239}]}]}
{"op":"mcm","clk":"11787062404","pt":1722453665824,"mc":[{"id":"1.231282404","rc":[{"batl":[[0,8,1.73]],"ltp":0.0,"tv":0.0,"id":58385184},{"batl":[[0,8,1.73]],"ltp":0.0,"tv":0.0,"id":19144239}]}]}
{"op":"mcm","clk":"11787063209","pt":1722453673938,"mc":[{"id":"1.231282404","rc":[{"batl":[[0,6,1.56],[1,8,0.95]],"ltp":0.0,"tv":0.0,"id":58385184},{"batl":[[0,6,1.56],[1,8,0.95]],"ltp":0.0,"tv":0.0,"id":19144239}]}]}
{"op":"mcm","clk":"11787063907","pt":1722453681258,"mc":[{"id":"1.231282404","rc":[{"batl":[[1,8,1.73]],"ltp":0.0,"tv":0.0,"id":58385184},{"batl":[[1,8,1.73]],"ltp":0.0,"tv":0.0,"id":19144239}]}]}
{"op":"mcm","clk":"11787064646","pt":1722453689679,"mc":[{"id":"1.231282404","rc":[{"batl":[[2,12,0.78]],"ltp":0.0,"tv":0.0,"id":58385184},{"batl":[[2,12,0.78]],"ltp":0.0,"tv":0.0,"id":19144239}]}]}
{"op":"mcm","clk":"11787081031","pt":1722453880280,"mc":[{"id":"1.231282404","rc":[{"batb":[[0,4.1,2.33],[1,1.27,10],[2,1.26,7.66]],"ltp":0.0,"tv":0.0,"id":58385184}]}]}
{"op":"mcm","clk":"11787082062","pt":1722453892171,"mc":[{"id":"1.231282404","rc":[{"batb":[[0,1.27,10],[1,1.26,7.66],[2,1.25,200]],"ltp":0.0,"tv":0.0,"id":58385184}]}]}
{"op":"mcm","clk":"11787280709","pt":1722456159656,"mc":[{"id":"1.231282404","rc":[{"batb":[[1,1.26,7.66]],"ltp":0.0,"tv":0.0,"id":58385184},{"batb":[[1,1.26,7.34]],"ltp":0.0,"tv":0.0,"id":19144239}]}]}
{"op":"mcm","clk":"11787493438","pt":1722459790627,"mc":[{"id":"1.231282404","rc":[{"batb":[[0,1.32,14],[1,1.27,10],[2,1.26,7.66]],"ltp":0.0,"tv":0.0,"id":58385184},{"batb":[[0,1.3,12],[1,1.27,10],[2,1.26,7.34]],"ltp":0.0,"tv":0.0,"id":19144239}]}]}
{"op":"mcm","clk":"11787494576","pt":1722459821168,"mc":[{"id":"1.231282404","rc":[{"batb":[[0,1.33,10],[1,1.32,14]],"ltp":0.0,"tv":0.0,"id":58385184},{"batb":[[0,1.31,10],[1,1.3,12]],"ltp":0.0,"tv":0.0,"id":19144239}]}]}
{"op":"mcm","clk":"11787906786","pt":1722467575010,"mc":[{"id":"1.231282404","rc":[{"batb":[[2,1.26,7.66]],"ltp":0.0,"tv":0.0,"id":58385184},{"batb":[[2,1.26,7.34]],"ltp":0.0,"tv":0.0,"id":19144239}]}]}
{"op":"mcm","clk":"11788244359","pt":1722472975074,"mc":[{"id":"1.231282404","rc":[{"batb":[[2,1.26,7.66]],"ltp":0.0,"tv":0.0,"id":58385184},{"batb":[[2,1.26,7.34]],"ltp":0.0,"tv":0.0,"id":19144239}]}]}
{"op":"mcm","clk":"11788384807","pt":1722474888574,"mc":[{"id":"1.231282404","rc":[{"batl":[[1,12,1.56],[2,12,0]],"ltp":0.0,"tv":0.0,"id":58385184},{"batl":[[1,12,1.56],[2,12,0]],"ltp":0.0,"tv":0.0,"id":19144239}]}]}
{"op":"mcm","clk":"11788931168","pt":1722483775085,"mc":[{"id":"1.231282404","rc":[{"batb":[[2,1.26,7.66]],"ltp":0.0,"tv":0.0,"id":58385184},{"batb":[[2,1.26,7.35]],"ltp":0.0,"tv":0.0,"id":19144239}]}]}
{"op":"mcm","clk":"11789156753","pt":1722489175063,"mc":[{"id":"1.231282404","rc":[{"batb":[[2,1.26,7.67]],"ltp":0.0,"tv":0.0,"id":58385184},{"batb":[[2,1.26,7.35]],"ltp":0.0,"tv":0.0,"id":19144239}]}]}
{"op":"mcm","clk":"11789193763","pt":1722490063932,"mc":[{"id":"1.231282404","rc":[{"batb":[[0,1.34,14],[1,1.33,10]],"ltp":0.0,"tv":0.0,"id":58385184},{"batb":[[0,1.33,12],[1,1.31,10]],"ltp":0.0,"tv":0.0,"id":19144239}]}]}
{"op":"mcm","clk":"11789308047","pt":1722493152246,"mc":[{"id":"1.231282404","rc":[{"batb":[[0,1.35,10],[1,1.34,14]],"ltp":0.0,"tv":0.0,"id":58385184},{"batb":[[0,1.34,10],[1,1.33,12]],"ltp":0.0,"tv":0.0,"id":19144239}]}]}
{"op":"mcm","clk":"11789592065","pt":1722499975050,"mc":[{"id":"1.231282404","rc":[{"batb":[[2,1.26,7.7]],"batl":[[0,6,1.56],[1,12,1.56]],"ltp":0.0,"tv":0.0,"id":58385184},{"batb":[[2,1.26,7.38]],"batl":[[0,6,1.56],[1,12,1.56]],"ltp":0.0,"tv":0.0,"id":19144239}]}]}
{"op":"mcm","clk":"11789596837","pt":1722500044836,"mc":[{"id":"1.231282404","rc":[{"batb":[[0,1.34,10.91]],"ltp":0.0,"tv":0.0,"id":19144239}]}]}
{"op":"mcm","clk":"11789597366","pt":1722500056859,"mc":[{"id":"1.231282404","rc":[{"batb":[[0,1.35,10.91]],"ltp":0.0,"tv":0.0,"id":58385184}]}]}
{"op":"mcm","clk":"11789809315","pt":1722504639665,"mc":[{"id":"1.231282404","rc":[{"batb":[[0,1.36,14.91],[1,1.35,10],[2,1.26,7.71]],"batl":[[0,6,1.56],[1,12,1.56]],"ltp":0.0,"tv":0.0,"id":58385184},{"batb":[[0,1.36,12],[1,1.34,10.91],[2,1.26,7.39]],"batl":[[0,6,1.56],[1,12,1.56]],"ltp":0.0,"tv":0.0,"id":19144239}]}]}
{"op":"mcm","clk":"11789809334","pt":1722504639936,"mc":[{"id":"1.231282404","rc":[{"batb":[[0,1.39,28.44],[1,1.36,14],[2,1.35,10]],"ltp":0.0,"tv":0.0,"id":58385184},{"batb":[[0,1.71,19.07],[1,1.36,12],[2,1.34,10.91]],"ltp":0.0,"tv":0.0,"id":19144239}]}]}
{"op":"mcm","clk":"11789828887","pt":1722505051146,"mc":[{"id":"1.231282404","rc":[{"batb":[[0,1.49,83.33],[1,1.39,28.44],[2,1.36,14]],"ltp":0.0,"tv":0.0,"id":58385184}]}]}
{"op":"mcm","clk":"11789839555","pt":1722505240168,"mc":[{"id":"1.231282404","rc":[{"batb":[[0,1.55,24.65],[1,1.49,83.33],[2,1.36,14.91]],"ltp":0.0,"tv":0.0,"id":58385184}]}]}
{"op":"mcm","clk":"11790114144","pt":1722509495491,"mc":[{"id":"1.231282404","rc":[{"batb":[[0,1.56,6],[1,1.55,24.65],[2,1.49,83.33]],"batl":[[0,6,1.57],[1,12,1.57]],"ltp":0.0,"tv":0.0,"id":58385184},{"batb":[[0,1.72,5],[1,1.71,19.07],[2,1.36,12]],"batl":[[0,6,1.57],[1,12,1.57]],"ltp":0.0,"tv":0.0,"id":19144239}]}]}
{"op":"mcm","clk":"11790130937","pt":1722509740344,"mc":[{"id":"1.231282404","rc":[{"batb":[[0,1.57,24.38],[1,1.56,6]],"ltp":0.0,"tv":0.0,"id":58385184},{"batb":[[0,1.77,18.42],[1,1.72,5]],"ltp":0.0,"tv":0.0,"id":19144239}]}]}
{"op":"mcm","clk":"11790174083","pt":1722510339532,"mc":[{"id":"1.231282404","rc":[{"batl":[[0,6,1.57],[1,12,1.57]],"ltp":0.0,"tv":0.0,"id":58385184},{"batl":[[0,6,1.57],[1,12,1.57]],"ltp":0.0,"tv":0.0,"id":19144239}]}]}
{"op":"mcm","clk":"11790259726","pt":1722511446128,"mc":[{"id":"1.231282404","rc":[{"batb":[[0,1.74,17.32],[1,1.57,24.38],[2,1.56,6]],"ltp":0.0,"tv":0.0,"id":58385184},{"batb":[[1,1.74,17.32],[2,1.72,5]],"ltp":0.0,"tv":0.0,"id":19144239}]}]}
{"op":"mcm","clk":"11790266825","pt":1722511540156,"mc":[{"id":"1.231282404","rc":[{"batb":[[1,1.56,6],[2,1.49,83.33]],"ltp":0.0,"tv":0.0,"id":58385184}]}]}
{"op":"mcm","clk":"11790281447","pt":1722511746257,"mc":[{"id":"1.231282404","rc":[{"batb":[[0,1.78,47.38],[1,1.74,17.32],[2,1.56,6]],"ltp":0.0,"tv":0.0,"id":58385184},{"batb":[[0,2.18,31.32],[1,1.77,18.42],[2,1.74,17.32]],"ltp":0.0,"tv":0.0,"id":19144239}]}]}
{"op":"mcm","clk":"11790340154","pt":1722512578890,"mc":[{"id":"1.231282404","rc":[{"batb":[[2,1.49,83.33]],"ltp":0.0,"tv":0.0,"id":58385184},{"batb":[[1,1.74,17.32],[2,1.36,12]],"ltp":0.0,"tv":0.0,"id":19144239}]}]}
{"op":"mcm","clk":"11790458165","pt":1722514185157,"mc":[{"id":"1.231282404","rc":[{"batl":[[0,6,1.56],[1,12,1.56]],"ltp":0.0,"tv":0.0,"id":58385184},{"batl":[[0,6,1.56],[1,12,1.56]],"ltp":0.0,"tv":0.0,"id":19144239}]}]}
{"op":"mcm","clk":"11790478180","pt":1722514452363,"mc":[{"id":"1.231282404","rc":[{"batb":[[0,1.74,17.32],[1,1.49,83.33],[2,1.36,14.91]],"ltp":0.0,"tv":0.0,"id":58385184},{"batb":[[0,1.92,16.96]],"ltp":0.0,"tv":0.0,"id":19144239}]}]}
{"op":"mcm","clk":"11790591301","pt":1722515971311,"mc":[{"id":"1.231282404","rc":[{"batb":[[0,1.92,66.96]],"ltp":0.0,"tv":0.0,"id":19144239}]}]}
{"op":"mcm","clk":"11790698632","pt":1722517410475,"mc":[{"id":"1.231282404","rc":[{"batb":[[0,1.78,47.38],[1,1.74,17.32],[2,1.49,83.33]],"batl":[[0,6,1.56],[1,12,1.56]],"ltp":0.0,"tv":0.0,"id":58385184},{"batb":[[0,2.18,31.32],[1,1.92,66.96],[2,1.74,17.32]],"batl":[[0,6,1.56],[1,12,1.56]],"ltp":0.0,"tv":0.0,"id":19144239}]}]}
{"op":"mcm","clk":"11790755302","pt":1722518324555,"mc":[{"id":"1.231282404","rc":[{"batb":[[2,1.73,31]],"ltp":0.0,"tv":0.0,"id":58385184},{"batb":[[1,1.92,50]],"ltp":0.0,"tv":0.0,"id":19144239}]}]}
{"op":"mcm","clk":"11790755718","pt":1722518333465,"mc":[{"id":"1.231282404","rc":[{"batl":[[0,1.9,22.63],[1,6,1.56],[2,12,1.56]],"ltp":0.0,"tv":0.0,"id":58385184}]}]}
{"op":"mcm","clk":"11790911924","pt":1722521574996,"mc":[{"id":"1.231282404","rc":[{"batl":[[1,6,1.56],[2,12,1.56]],"ltp":0.0,"tv":0.0,"id":58385184},{"batl":[[0,6,1.56],[1,12,1.56]],"ltp":0.0,"tv":0.0,"id":19144239}]}]}
{"op":"mcm","clk":"11790933256","pt":1722522109991,"mc":[{"id":"1.231282404","rc":[{"batb":[[0,1.78,55.33]],"ltp":0.0,"tv":0.0,"id":58385184},{"batb":[[0,2.18,36.57]],"ltp":0.0,"tv":0.0,"id":19144239}]}]}
{"op":"mcm","clk":"11791055102","pt":1722525647710,"mc":[{"id":"1.231282404","rc":[{"batl":[[1,6,1.56],[2,12,1.56]],"ltp":0.0,"tv":0.0,"id":58385184},{"batl":[[0,6,1.56],[1,12,1.56]],"ltp":0.0,"tv":0.0,"id":19144239}]}]}
{"op":"mcm","clk":"11791548147","pt":1722532375095,"mc":[{"id":"1.231282404","rc":[{"batl":[[1,6,1.57],[2,12,1.57]],"ltp":0.0,"tv":0.0,"id":58385184},{"batl":[[0,6,1.57],[1,12,1.57]],"ltp":0.0,"tv":0.0,"id":19144239}]}]}
{"op":"mcm","clk":"11792458728","pt":1722538296641,"mc":[{"id":"1.231282404","rc":[{"batb":[[1,1.89,50]],"ltp":0.0,"tv":0.0,"id":19144239}]}]}
{"op":"mcm","clk":"11792722272","pt":1722540811220,"mc":[{"id":"1.231282404","rc":[{"batl":[[1,6,1.57],[2,12,1.57]],"ltp":0.0,"tv":0.0,"id":58385184},{"batl":[[0,6,1.57],[1,12,1.57]],"ltp":0.0,"tv":0.0,"id":19144239}]}]}
{"op":"mcm","clk":"11792784147","pt":1722541531725,"mc":[{"id":"1.231282404","rc":[{"batb":[[0,1.74,17.32],[1,1.73,31],[2,1.25,40.91]],"ltp":0.0,"tv":0.0,"id":58385184},{"batb":[[0,1.89,50],[1,1.74,17.32],[2,1.25,40.91]],"ltp":0.0,"tv":0.0,"id":19144239}]}]}
{"op":"mcm","clk":"11792784489","pt":1722541534318,"mc":[{"id":"1.231282404","rc":[{"batb":[[0,1.78,55.33],[1,1.74,17.32],[2,1.73,31]],"ltp":0.0,"tv":0.0,"id":58385184},{"batb":[[0,2.18,36.57],[1,1.89,50],[2,1.74,17.32]],"ltp":0.0,"tv":0.0,"id":19144239}]}]}
{"op":"mcm","clk":"11792897277","pt":1722543175093,"mc":[{"id":"1.231282404","rc":[{"batl":[[1,6,1.57],[2,12,1.57]],"ltp":0.0,"tv":0.0,"id":58385184},{"batl":[[0,6,1.57],[1,12,1.57]],"ltp":0.0,"tv":0.0,"id":19144239}]}]}
{"op":"mcm","clk":"11793317071","pt":1722553075501,"mc":[{"id":"1.231282404","rc":[{"batb":[[0,1.81,53.28]],"ltp":0.0,"tv":0.0,"id":58385184},{"batb":[[0,2.12,38.53]],"ltp":0.0,"tv":0.0,"id":19144239}]}]}
{"op":"mcm","clk":"11794114841","pt":1722574681185,"mc":[{"id":"1.231282404","rc":[{"batb":[[1,1.8,50]],"ltp":0.0,"tv":0.0,"id":19144239}]}]}
{"op":"mcm","clk":"11794361433","pt":1722580975074,"mc":[{"id":"1.231282404","rc":[{"batl":[[1,6,1.57],[2,12,1.57]],"ltp":0.0,"tv":0.0,"id":58385184},{"batl":[[0,6,1.57],[1,12,1.57]],"ltp":0.0,"tv":0.0,"id":19144239}]}]}
{"op":"mcm","clk":"11794479255","pt":1722583563845,"mc":[{"id":"1.231282404","rc":[{"trd":[[1.9,0.14]],"batl":[[0,1.9,22.56]],"ltp":1.9,"tv":0.14,"id":58385184}],"tv":0.14}]}
{"op":"mcm","clk":"11794635883","pt":1722586375166,"mc":[{"id":"1.231282404","rc":[{"batl":[[1,6,1.57],[2,12,1.57]],"ltp":1.9,"tv":0.14,"id":58385184},{"batl":[[0,6,1.57],[1,12,1.57]],"ltp":0.0,"tv":0.0,"id":19144239}]}]}
{"op":"mcm","clk":"11794697901","pt":1722587403255,"mc":[{"id":"1.231282404","rc":[{"batb":[[0,1.74,17.32],[1,1.73,31],[2,1.51,1]],"ltp":1.9,"tv":0.14,"id":58385184},{"batb":[[0,1.8,50],[1,1.74,17.32],[2,1.51,1]],"ltp":0.0,"tv":0.0,"id":19144239}]}]}
{"op":"mcm","clk":"11794808525","pt":1722589328783,"mc":[{"id":"1.231282404","rc":[{"batl":[[1,6,1.57],[2,12,1.57]],"ltp":1.9,"tv":0.14,"id":58385184},{"batb":[[0,2.34,1.18],[1,1.8,50],[2,1.74,17.32]],"batl":[[0,6,1.57],[1,12,1.57]],"ltp":0.0,"tv":0.0,"id":19144239}]}]}
{"op":"mcm","clk":"11794809580","pt":1722589345403,"mc":[{"id":"1.231282404","rc":[{"batb":[[0,1.8,50],[1,1.74,17.32],[2,1.51,1]],"ltp":0.0,"tv":0.0,"id":19144239}]}]}
{"op":"mcm","clk":"11794814825","pt":1722589423424,"mc":[{"id":"1.231282404","rc":[{"batl":[[0,2.12,1.18],[1,6,1.57],[2,12,1.57]],"ltp":0.0,"tv":0.0,"id":19144239}]}]}
{"op":"mcm","clk":"11794817415","pt":1722589459372,"mc":[{"id":"1.231282404","rc":[{"batl":[[0,6,1.57],[1,12,1.57],[2,12,0]],"ltp":0.0,"tv":0.0,"id":19144239}]}]}
{"op":"mcm","clk":"11794823438","pt":1722589543033,"mc":[{"id":"1.231282404","rc":[{"batb":[[0,2.34,1.18],[1,1.8,50],[2,1.74,17.32]],"ltp":0.0,"tv":0.0,"id":19144239}]}]}
{"op":"mcm","clk":"11794825654","pt":1722589573595,"mc":[{"id":"1.231282404","rc":[{"batb":[[0,1.8,50],[1,1.74,17.32],[2,1.51,1]],"ltp":0.0,"tv":0.0,"id":19144239}]}]}
{"op":"mcm","clk":"11794831139","pt":1722589645757,"mc":[{"id":"1.231282404","rc":[{"batl":[[0,2.12,1.18],[1,6,1.57],[2,12,1.57]],"ltp":0.0,"tv":0.0,"id":19144239}]}]}
{"op":"mcm","clk":"11794835320","pt":1722589702224,"mc":[{"id":"1.231282404","rc":[{"batl":[[0,6,1.57],[1,12,1.57],[2,12,0]],"ltp":0.0,"tv":0.0,"id":19144239}]}]}
{"op":"mcm","clk":"11794841681","pt":1722589790246,"mc":[{"id":"1.231282404","rc":[{"batb":[[0,2.34,1.18],[1,1.8,50],[2,1.74,17.32]],"ltp":0.0,"tv":0.0,"id":19144239}]}]}
{"op":"mcm","clk":"11794844281","pt":1722589825311,"mc":[{"id":"1.231282404","rc":[{"batb":[[0,1.8,50],[1,1.74,17.32],[2,1.51,1]],"ltp":0.0,"tv":0.0,"id":19144239}]}]}
{"op":"mcm","clk":"11794849837","pt":1722589899838,"mc":[{"id":"1.231282404","rc":[{"batl":[[0,2.12,1.18],[1,6,1.57],[2,12,1.57]],"ltp":0.0,"tv":0.0,"id":19144239}]}]}
{"op":"mcm","clk":"11794853804","pt":1722589952460,"mc":[{"id":"1.231282404","rc":[{"batl":[[0,6,1.57],[1,12,1.57],[2,12,0]],"ltp":0.0,"tv":0.0,"id":19144239}]}]}
{"op":"mcm","clk":"11794857658","pt":1722590011652,"mc":[{"id":"1.231282404","rc":[{"batb":[[0,2.34,1.18],[1,1.8,50],[2,1.74,17.32]],"ltp":0.0,"tv":0.0,"id":19144239}]}]}
{"op":"mcm","clk":"11794860377","pt":1722590051392,"mc":[{"id":"1.231282404","rc":[{"batb":[[0,1.8,50],[1,1.74,17.32],[2,1.51,1]],"ltp":0.0,"tv":0.0,"id":19144239}]}]}
{"op":"mcm","clk":"11794864906","pt":1722590119375,"mc":[{"id":"1.231282404","rc":[{"batl":[[0,2.12,1.18],[1,6,1.57],[2,12,1.57]],"ltp":0.0,"tv":0.0,"id":19144239}]}]}
{"op":"mcm","clk":"11794867949","pt":1722590164321,"mc":[{"id":"1.231282404","rc":[{"batl":[[0,6,1.57],[1,12,1.57],[2,12,0]],"ltp":0.0,"tv":0.0,"id":19144239}]}]}
{"op":"mcm","clk":"11794871751","pt":1722590222703,"mc":[{"id":"1.231282404","rc":[{"batb":[[0,1.81,53.28],[1,1.74,17.32],[2,1.73,31]],"ltp":1.9,"tv":0.14,"id":58385184},{"batb":[[0,2.12,38.53],[1,1.8,50],[2,1.74,17.32]],"ltp":0.0,"tv":0.0,"id":19144239}]}]}
{"op":"mcm","clk":"11794875614","pt":1722590257751,"mc":[{"id":"1.231282404","rc":[{"batb":[[0,2.22,1.18],[1,2.12,38.53],[2,1.8,50]],"ltp":0.0,"tv":0.0,"id":19144239}]}]}
{"op":"mcm","clk":"11794878817","pt":1722590302765,"mc":[{"id":"1.231282404","rc":[{"batb":[[0,2.12,38.53],[1,1.8,50],[2,1.74,17.32]],"ltp":0.0,"tv":0.0,"id":19144239}]}]}
{"op":"mcm","clk":"11795324130","pt":1722596277960,"mc":[{"id":"1.231282404","rc":[{"batb":[[1,1.9,73.46],[2,1.8,50]],"ltp":0.0,"tv":0.0,"id":19144239}]}]}
{"op":"mcm","clk":"11795367640","pt":1722596852976,"mc":[{"id":"1.231282404","rc":[{"batb":[[1,1.9,73.48]],"ltp":0.0,"tv":0.0,"id":19144239}]}]}
{"op":"mcm","clk":"11795680978","pt":1722600708648,"mc":[{"id":"1.231282404","rc":[{"trd":[[1.9,88.25]],"batb":[[0,1.91,10],[1,1.9,488.3],[2,1.81,53.28]],"batl":[[0,6,1.57],[1,12,1.57],[2,12,0]],"ltp":1.9,"tv":88.25,"id":58385184},{"trd":[[2.12,38.53]],"batb":[[0,1.93,34.36],[1,1.91,10],[2,1.9,73.47]],"ltp":2.12,"tv":38.53,"id":19144239}],"tv":126.78}]}
{"op":"mcm","clk":"11795681228","pt":1722600711885,"mc":[{"id":"1.231282404","rc":[{"batb":[[0,1.9,488.3],[1,1.81,53.28],[2,1.74,17.32]],"ltp":1.9,"tv":88.25,"id":58385184},{"batb":[[1,1.9,73.47],[2,1.8,50]],"ltp":2.12,"tv":38.53,"id":19144239}]}]}
{"op":"mcm","clk":"11795681312","pt":1722600712983,"mc":[{"id":"1.231282404","rc":[{"batb":[[0,2.04,41.5],[1,1.93,34.36],[2,1.9,73.47]],"ltp":2.12,"tv":38.53,"id":19144239}]}]}
{"op":"mcm","clk":"11795683959","pt":1722600746982,"mc":[{"id":"1.231282404","rc":[{"batb":[[0,1.91,10],[1,1.9,488.3],[2,1.81,53.28]],"ltp":1.9,"tv":88.25,"id":58385184},{"batb":[[0,2.06,10],[1,2.04,41.5]],"ltp":2.12,"tv":38.53,"id":19144239}]}]}
{"op":"mcm","clk":"11795684067","pt":1722600748176,"mc":[{"id":"1.231282404","rc":[{"batb":[[2,1.74,17.32]],"ltp":1.9,"tv":88.25,"id":58385184},{"batb":[[1,1.9,73.47],[2,1.8,50]],"ltp":2.12,"tv":38.53,"id":19144239}]}]}
{"op":"mcm","clk":"11795684259","pt":1722600750513,"mc":[{"id":"1.231282404","rc":[{"batb":[[0,1.9,488.3],[1,1.74,17.32],[2,1.73,31]],"ltp":1.9,"tv":88.25,"id":58385184},{"batb":[[0,1.96,33.82]],"ltp":2.12,"tv":38.53,"id":19144239}]}]}
{"op":"mcm","clk":"11795684526","pt":1722600753388,"mc":[{"id":"1.231282404","rc":[{"batb":[[1,1.81,53.28],[2,1.74,17.32]],"ltp":1.9,"tv":88.25,"id":58385184},{"batb":[[0,2.04,41.5],[1,1.96,33.82],[2,1.9,73.47]],"ltp":2.12,"tv":38.53,"id":19144239}]}]}
{"op":"mcm","clk":"11795684588","pt":1722600754432,"mc":[{"id":"1.231282404","rc":[{"batb":[[0,1.91,10],[1,1.9,488.3],[2,1.81,53.28]],"ltp":1.9,"tv":88.25,"id":58385184},{"batb":[[0,2.06,10],[1,2.04,41.5],[2,1.96,33.82]],"ltp":2.12,"tv":38.53,"id":19144239}]}]}
{"op":"mcm","clk":"11795684867","pt":1722600758207,"mc":[{"id":"1.231282404","rc":[{"batb":[[0,1.9,488.3],[1,1.81,53.28],[2,1.74,17.32]],"ltp":1.9,"tv":88.25,"id":58385184},{"batb":[[0,2.04,41.5],[1,1.96,33.82],[2,1.9,73.47]],"ltp":2.12,"tv":38.53,"id":19144239}]}]}
{"op":"mcm","clk":"11795685276","pt":1722600763301,"mc":[{"id":"1.231282404","rc":[{"trd":[[1.9,179.63]],"batb":[[0,1.9,442.61]],"ltp":1.9,"tv":179.62,"id":58385184}],"tv":218.15}]}
{"op":"mcm","clk":"11795685356","pt":1722600764315,"mc":[{"id":"1.231282404","rc":[{"batb":[[0,1.91,10],[1,1.9,442.61],[2,1.81,53.28]],"ltp":1.9,"tv":179.62,"id":58385184},{"batb":[[0,2.06,10],[1,2.04,41.5]],"ltp":2.12,"tv":38.53,"id":19144239}]}]}
{"op":"mcm","clk":"11795685503","pt":1722600766498,"mc":[{"id":"1.231282404","rc":[{"trd":[[1.91,20]],"batb":[[0,1.9,442.61],[1,1.81,53.28],[2,1.74,17.32]],"batl":[[0,1.91,35.69],[1,6,1.57],[2,12,1.57]],"ltp":1.91,"tv":199.62,"id":58385184}],"tv":238.15}]}
{"op":"mcm","clk":"11795685652","pt":1722600767999,"mc":[{"id":"1.231282404","rc":[{"batb":[[0,2.04,41.5],[1,1.9,73.47],[2,1.8,50]],"ltp":2.12,"tv":38.53,"id":19144239}]}]}
{"op":"mcm","clk":"11795685824","pt":1722600770217,"mc":[{"id":"1.231282404","rc":[{"trd":[[1.9,271]],"batb":[[0,1.9,396.92]],"ltp":1.9,"tv":291.0,"id":58385184},{"batb":[[0,2.06,10],[1,2.04,41.5],[2,1.9,73.47]],"ltp":2.12,"tv":38.53,"id":19144239}],"tv":329.53}]}
{"op":"mcm","clk":"11795686068","pt":1722600773630,"mc":[{"id":"1.231282404","rc":[{"batb":[[0,2.04,41.5],[1,1.9,73.47],[2,1.8,50]],"ltp":2.12,"tv":38.53,"id":19144239}]}]}
{"op":"mcm","clk":"11795687381","pt":1722600790130,"mc":[{"id":"1.231282404","rc":[{"trd":[[1.9,362.38]],"batb":[[0,1.9,351.23]],"ltp":1.9,"tv":382.37,"id":58385184}],"tv":420.9}]}
{"op":"mcm","clk":"11795687512","pt":1722600791634,"mc":[{"id":"1.231282404","rc":[{"batb":[[0,2.06,10],[1,2.04,41.5],[2,1.9,73.47]],"ltp":2.12,"tv":38.53,"id":19144239}]}]}
{"op":"mcm","clk":"11795687762","pt":1722600794455,"mc":[{"id":"1.231282404","rc":[{"trd":[[1.9,453.75]],"batb":[[0,1.9,305.54]],"ltp":1.9,"tv":473.75,"id":58385184}],"tv":512.28}]}
{"op":"mcm","clk":"11795687891","pt":1722600795954,"mc":[{"id":"1.231282404","rc":[{"batb":[[0,2.04,41.5],[1,1.9,73.47],[2,1.8,50]],"ltp":2.12,"tv":38.53,"id":19144239}]}]}
{"op":"mcm","clk":"11795688024","pt":1722600797466,"mc":[{"id":"1.231282404","rc":[{"trd":[[1.9,545.13]],"batb":[[0,1.9,259.85]],"ltp":1.9,"tv":565.13,"id":58385184}],"tv":603.66}]}
{"op":"mcm","clk":"11795688169","pt":1722600799378,"mc":[{"id":"1.231282404","rc":[{"batb":[[0,2.06,10],[1,2.04,41.5],[2,1.9,73.47]],"ltp":2.12,"tv":38.53,"id":19144239}]}]}
{"op":"mcm","clk":"11795688247","pt":1722600800257,"mc":[{"id":"1.231282404","rc":[{"trd":[[1.9,636.51]],"batb":[[0,1.9,214.16]],"ltp":1.9,"tv":656.5,"id":58385184}],"tv":695.03}]}
{"op":"mcm","clk":"11795688497","pt":1722600803676,"mc":[{"id":"1.231282404","rc":[{"trd":[[1.9,727.88]],"batb":[[0,1.9,168.47]],"ltp":1.9,"tv":747.88,"id":58385184},{"batb":[[0,2.04,41.5],[1,1.9,73.47],[2,1.8,50]],"ltp":2.12,"tv":38.53,"id":19144239}],"tv":786.41}]}
{"op":"mcm","clk":"11795688984","pt":1722600809453,"mc":[{"id":"1.231282404","rc":[{"trd":[[1.9,819.26]],"batb":[[0,1.9,122.78]],"ltp":1.9,"tv":839.25,"id":58385184}],"tv":877.78}]}
{"op":"mcm","clk":"11795689035","pt":1722600810178,"mc":[{"id":"1.231282404","rc":[{"batb":[[0,2.06,10],[1,2.04,41.5],[2,1.9,73.47]],"ltp":2.12,"tv":38.53,"id":19144239}]}]}
{"op":"mcm","clk":"11795689219","pt":1722600812247,"mc":[{"id":"1.231282404","rc":[{"trd":[[1.9,910.64]],"batb":[[0,1.9,77.09]],"ltp":1.9,"tv":930.63,"id":58385184}],"tv":969.16}]}
{"op":"mcm","clk":"11795689404","pt":1722600814473,"mc":[{"id":"1.231282404","rc":[{"batb":[[0,2.04,41.5],[1,1.9,73.47],[2,1.8,50]],"ltp":2.12,"tv":38.53,"id":19144239}]}]}
{"op":"mcm","clk":"11795689452","pt":1722600815088,"mc":[{"id":"1.231282404","rc":[{"trd":[[1.9,1002.01]],"batb":[[0,1.9,31.4]],"ltp":1.9,"tv":1022.01,"id":58385184}],"tv":1060.54}]}
{"op":"mcm","clk":"11795689704","pt":1722600818281,"mc":[{"id":"1.231282404","rc":[{"trd":[[1.9,1064.81]],"batb":[[0,1.81,53.28],[1,1.74,17.32],[2,1.73,31]],"batl":[[0,1.9,14.29],[1,1.91,35.69],[2,6,1.57]],"ltp":1.9,"tv":1084.81,"id":58385184},{"batb":[[0,2.06,10],[1,2.04,41.5],[2,1.9,73.47]],"ltp":2.12,"tv":38.53,"id":19144239}],"tv":1123.34}]}
{"op":"mcm","clk":"11795689953","pt":1722600821473,"mc":[{"id":"1.231282404","rc":[{"batb":[[0,2.04,41.5],[1,1.9,73.47],[2,1.8,50]],"ltp":2.12,"tv":38.53,"id":19144239}]}]}
{"op":"mcm","clk":"11795696634","pt":1722600900950,"mc":[{"id":"1.231282404","rc":[{"batb":[[0,2.06,10],[1,2.04,41.5],[2,1.9,73.47]],"ltp":2.12,"tv":38.53,"id":19144239}]}]}
{"op":"mcm","clk":"11795696971","pt":1722600904839,"mc":[{"id":"1.231282404","rc":[{"batb":[[0,2.04,41.5],[1,1.9,73.47],[2,1.8,50]],"ltp":2.12,"tv":38.53,"id":19144239}]}]}
{"op":"mcm","clk":"11795697566","pt":1722600911223,"mc":[{"id":"1.231282404","rc":[{"batb":[[0,2.06,10],[1,2.04,41.5],[2,1.9,73.47]],"ltp":2.12,"tv":38.53,"id":19144239}]}]}
{"op":"mcm","clk":"11795697872","pt":1722600914750,"mc":[{"id":"1.231282404","rc":[{"batb":[[0,2.04,41.5],[1,1.9,73.47],[2,1.8,50]],"ltp":2.12,"tv":38.53,"id":19144239}]}]}
{"op":"mcm","clk":"11795698620","pt":1722600922973,"mc":[{"id":"1.231282404","rc":[{"batb":[[0,2.06,10],[1,2.04,41.5],[2,1.9,73.47]],"ltp":2.12,"tv":38.53,"id":19144239}]}]}
{"op":"mcm","clk":"11795699027","pt":1722600927567,"mc":[{"id":"1.231282404","rc":[{"batb":[[0,2.04,41.5],[1,1.9,73.47],[2,1.8,50]],"ltp":2.12,"tv":38.53,"id":19144239}]}]}
{"op":"mcm","clk":"11795699918","pt":1722600937384,"mc":[{"id":"1.231282404","rc":[{"trd":[[1.95,10.56]],"batb":[[0,1.96,10],[1,1.95,533.38],[2,1.81,53.28]],"batl":[[0,6,1.57],[1,12,1.57],[2,6,0]],"ltp":1.95,"tv":1095.37,"id":58385184},{"trd":[[2.06,10]],"ltp":2.06,"tv":48.53,"id":19144239}],"tv":1143.9}]}
{"op":"mcm","clk":"11795699981","pt":1722600938199,"mc":[{"id":"1.231282404","rc":[{"trd":[[1.96,20]],"batb":[[0,1.95,533.38],[1,1.81,53.28],[2,1.74,17.32]],"ltp":1.96,"tv":1115.37,"id":58385184}],"tv":1163.9}]}
{"op":"mcm","clk":"11795700505","pt":1722600944106,"mc":[{"id":"1.231282404","rc":[{"batb":[[0,1.95,1127.29]],"ltp":1.96,"tv":1115.37,"id":58385184}]}]}
{"op":"mcm","clk":"11795700591","pt":1722600945016,"mc":[{"id":"1.231282404","rc":[{"trd":[[1.95,21.13]],"batb":[[0,1.96,10],[1,1.95,1116.73],[2,1.81,53.28]],"ltp":1.95,"tv":1125.93,"id":58385184},{"trd":[[2.06,20]],"ltp":2.06,"tv":58.53,"id":19144239}],"tv":1184.46}]}
{"op":"mcm","clk":"11795700953","pt":1722600949618,"mc":[{"id":"1.231282404","rc":[{"batb":[[0,1.95,1710.64],[1,1.81,53.28],[2,1.74,17.32]],"ltp":1.95,"tv":1125.93,"id":58385184}]}]}
{"op":"mcm","clk":"11795700983","pt":1722600949983,"mc":[{"id":"1.231282404","rc":[{"trd":[[1.95,31.69]],"batb":[[0,1.95,1700.08]],"ltp":1.95,"tv":1136.5,"id":58385184},{"trd":[[2.06,30]],"ltp":2.06,"tv":68.53,"id":19144239}],"tv":1205.03}]}
{"op":"mcm","clk":"11795701189","pt":1722600952617,"mc":[{"id":"1.231282404","rc":[{"batb":[[0,1.95,2293.99]],"ltp":1.95,"tv":1136.5,"id":58385184}]}]}
{"op":"mcm","clk":"11795701196","pt":1722600952725,"mc":[{"id":"1.231282404","rc":[{"trd":[[1.95,42.26]],"batb":[[0,1.96,10],[1,1.95,2283.43],[2,1.81,53.28]],"ltp":1.95,"tv":1147.06,"id":58385184},{"trd":[[2.06,40]],"ltp":2.06,"tv":78.53,"id":19144239}],"tv":1225.59}]}
{"op":"mcm","clk":"11795701329","pt":1722600954278,"mc":[{"id":"1.231282404","rc":[{"batb":[[2,1.74,17.32]],"ltp":1.95,"tv":1147.06,"id":58385184}]}]}
{"op":"mcm","clk":"11795701418","pt":1722600955307,"mc":[{"id":"1.231282404","rc":[{"trd":[[1.95,42.78],[1.96,30]],"batb":[[0,1.95,2282.91],[1,1.74,17.32],[2,1.73,31]],"batl":[[0,5,1.66],[1,7,1.57],[2,12,0.78]],"ltp":1.95,"tv":1157.58,"id":58385184},{"trd":[[2.06,50]],"ltp":2.06,"tv":88.53,"id":19144239}],"tv":1246.11}]}
{"op":"mcm","clk":"11795701913","pt":1722600961421,"mc":[{"id":"1.231282404","rc":[{"trd":[[1.95,53.34],[1.96,31.74]],"batb":[[0,1.96,9.13],[1,1.95,2272.34],[2,1.74,17.32]],"batl":[[0,6,1.57],[1,12,1.57],[2,12,0]],"ltp":1.96,"tv":1169.89,"id":58385184},{"trd":[[2.06,60]],"ltp":2.06,"tv":98.53,"id":19144239}],"tv":1268.42}]}
{"op":"mcm","clk":"11795702203","pt":1722600964821,"mc":[{"id":"1.231282404","rc":[{"batb":[[0,1.95,2272.34],[1,1.74,17.32],[2,1.73,31]],"ltp":1.96,"tv":1169.89,"id":58385184}]}]}
{"op":"mcm","clk":"11795702315","pt":1722600966006,"mc":[{"id":"1.231282404","rc":[{"trd":[[1.95,63.9]],"batb":[[0,1.95,2261.78]],"ltp":1.95,"tv":1180.45,"id":58385184},{"trd":[[2.06,70]],"ltp":2.06,"tv":108.53,"id":19144239}],"tv":1288.98}]}
{"op":"mcm","clk":"11795702774","pt":1722600971017,"mc":[{"id":"1.231282404","rc":[{"trd":[[1.95,74.47]],"batb":[[0,1.96,10],[1,1.95,2251.22],[2,1.74,17.32]],"ltp":1.95,"tv":1191.02,"id":58385184},{"trd":[[2.06,80]],"ltp":2.06,"tv":118.53,"id":19144239}],"tv":1309.55}]}
{"op":"mcm","clk":"11795703209","pt":1722600975440,"mc":[{"id":"1.231282404","rc":[{"trd":[[1.95,85.03]],"batb":[[0,1.95,2240.65],[1,1.74,17.32],[2,1.73,31]],"ltp":1.95,"tv":1201.58,"id":58385184},{"trd":[[2.06,90]],"ltp":2.06,"tv":128.53,"id":19144239}],"tv":1330.11}]}
{"op":"mcm","clk":"11795703261","pt":1722600975963,"mc":[{"id":"1.231282404","rc":[{"batb":[[0,1.95,2241.53]],"ltp":1.95,"tv":1201.58,"id":58385184}]}]}
{"op":"mcm","clk":"11795704039","pt":1722600984432,"mc":[{"id":"1.231282404","rc":[{"trd":[[1.95,94.72],[1.96,32.62]],"batb":[[0,1.96,10],[1,1.95,2230.96],[2,1.74,17.32]],"ltp":1.95,"tv":1212.14,"id":58385184},{"trd":[[2.06,100]],"ltp":2.06,"tv":138.53,"id":19144239}],"tv":1350.67}]}
{"op":"mcm","clk":"11795704366","pt":1722600988048,"mc":[{"id":"1.231282404","rc":[{"batb":[[0,1.95,2230.96],[1,1.74,17.32],[2,1.73,31]],"ltp":1.95,"tv":1212.14,"id":58385184}]}]}
{"op":"mcm","clk":"11795704434","pt":1722600988927,"mc":[{"id":"1.231282404","rc":[{"trd":[[1.95,105.28]],"batb":[[0,1.95,2220.4]],"ltp":1.95,"tv":1222.71,"id":58385184},{"trd":[[2.06,110]],"ltp":2.06,"tv":148.53,"id":19144239}],"tv":1371.24}]}
{"op":"mcm","clk":"11795706446","pt":1722601012749,"mc":[{"id":"1.231282404","rc":[{"batb":[[0,1.95,2814.31]],"ltp":1.95,"tv":1222.71,"id":58385184}]}]}
{"op":"mcm","clk":"11795706552","pt":1722601013843,"mc":[{"id":"1.231282404","rc":[{"trd":[[1.95,115.85]],"batb":[[0,1.96,10],[1,1.95,2803.75],[2,1.74,17.32]],"ltp":1.95,"tv":1233.27,"id":58385184},{"trd":[[2.06,120]],"ltp":2.06,"tv":158.53,"id":19144239}],"tv":1391.8}]}
{"op":"mcm","clk":"11795706829","pt":1722601016760,"mc":[{"id":"1.231282404","rc":[{"batb":[[0,1.96,603.91]],"ltp":1.95,"tv":1233.27,"id":58385184}]}]}
{"op":"mcm","clk":"11795706968","pt":1722601018279,"mc":[{"id":"1.231282404","rc":[{"trd":[[1.96,43.13]],"batb":[[0,1.96,583.4]],"ltp":1.96,"tv":1243.78,"id":58385184},{"trd":[[2.06,130]],"ltp":2.06,"tv":168.53,"id":19144239}],"tv":1412.31}]}
{"op":"mcm","clk":"11795707121","pt":1722601019665,"mc":[{"id":"1.231282404","rc":[{"batb":[[0,1.96,1177.32]],"ltp":1.96,"tv":1243.78,"id":58385184}]}]}
{"op":"mcm","clk":"11795707222","pt":1722601020692,"mc":[{"id":"1.231282404","rc":[{"trd":[[1.97,10]],"ltp":1.97,"tv":1253.78,"id":58385184},{"trd":[[2.04,9.66]],"batb":[[0,2.04,31.84]],"ltp":2.04,"tv":178.19,"id":19144239}],"tv":1431.97}]}
{"op":"mcm","clk":"11795707381","pt":1722601022484,"mc":[{"id":"1.231282404","rc":[{"batb":[[0,1.96,1771.23]],"ltp":1.97,"tv":1253.78,"id":58385184}]}]}
{"op":"mcm","clk":"11795707447","pt":1722601023204,"mc":[{"id":"1.231282404","rc":[{"trd":[[1.96,53.64]],"batb":[[0,1.96,1760.72]],"ltp":1.96,"tv":1264.29,"id":58385184},{"trd":[[2.06,140]],"ltp":2.06,"tv":188.19,"id":19144239}],"tv":1452.48}]}
{"op":"mcm","clk":"11795707585","pt":1722601024605,"mc":[{"id":"1.231282404","rc":[{"batb":[[0,2.04,41.5]],"ltp":2.06,"tv":188.19,"id":19144239}]}]}
{"op":"mcm","clk":"11795707671","pt":1722601025801,"mc":[{"id":"1.231282404","rc":[{"trd":[[1.96,64.15],[1.97,20]],"batb":[[0,1.96,1750.21]],"ltp":1.97,"tv":1284.8,"id":58385184},{"trd":[[2.04,19.32],[2.06,150]],"batb":[[0,2.04,31.84]],"ltp":2.04,"tv":207.85,"id":19144239}],"tv":1492.65}]}
{"op":"mcm","clk":"11795707754","pt":1722601026794,"mc":[{"id":"1.231282404","rc":[{"batb":[[0,1.96,2344.13]],"ltp":1.97,"tv":1284.8,"id":58385184}]}]}
{"op":"mcm","clk":"11795707982","pt":1722601029593,"mc":[{"id":"1.231282404","rc":[{"batb":[[0,2.04,41.5]],"ltp":2.04,"tv":207.85,"id":19144239}]}]}
{"op":"mcm","clk":"11795708021","pt":1722601030110,"mc":[{"id":"1.231282404","rc":[{"trd":[[1.96,74.66],[1.97,30]],"batb":[[0,1.96,2927.53]],"ltp":1.97,"tv":1305.31,"id":58385184},{"trd":[[2.04,28.98],[2.06,160]],"batb":[[0,2.04,31.84]],"ltp":2.04,"tv":227.51,"id":19144239}],"tv":1532.82}]}
{"op":"mcm","clk":"11795708489","pt":1722601034603,"mc":[{"id":"1.231282404","rc":[{"batb":[[0,2.04,73.34]],"ltp":2.04,"tv":227.51,"id":19144239}]}]}
{"op":"mcm","clk":"11795708521","pt":1722601034912,"mc":[{"id":"1.231282404","rc":[{"trd":[[1.96,85.17],[1.97,40]],"batb":[[0,1.96,2917.02]],"ltp":1.97,"tv":1325.82,"id":58385184},{"trd":[[2.04,38.64],[2.06,170]],"batb":[[0,2.04,31.84]],"ltp":2.04,"tv":247.17,"id":19144239}],"tv":1572.99}]}
{"op":"mcm","clk":"11795708942","pt":1722601040194,"mc":[{"id":"1.231282404","rc":[{"trd":[[1.96,95.68],[1.97,50]],"batb":[[0,1.96,2906.51]],"ltp":1.97,"tv":1346.33,"id":58385184},{"trd":[[2.04,48.3],[2.06,180]],"ltp":2.04,"tv":266.83,"id":19144239}],"tv":1613.16}]}
{"op":"mcm","clk":"11795709204","pt":1722601042731,"mc":[{"id":"1.231282404","rc":[{"trd":[[1.96,5510.26]],"batb":[[0,1.96,199.21]],"ltp":1.96,"tv":6760.91,"id":58385184}],"tv":7027.74}]}
{"op":"mcm","clk":"11795709427","pt":1722601045022,"mc":[{"id":"1.231282404","rc":[{"trd":[[1.96,5520.77],[1.97,60]],"batb":[[0,1.96,188.7]],"ltp":1.97,"tv":6781.42,"id":58385184},{"trd":[[2.04,57.96],[2.06,190]],"ltp":2.04,"tv":286.49,"id":19144239}],"tv":7067.91}]}
{"op":"mcm","clk":"11795709671","pt":1722601048502,"mc":[{"id":"1.231282404","rc":[{"trd":[[1.95,5163.59],[1.96,5898.17]],"batb":[[0,1.96,10],[1,1.95,274.59]],"ltp":1.95,"tv":12206.56,"id":58385184},{"trd":[[2.06,200]],"ltp":2.06,"tv":296.49,"id":19144239}],"tv":12503.05}]}
{"op":"mcm","clk":"11795709780","pt":1722601049844,"mc":[{"id":"1.231282404","rc":[{"batb":[[2,1.81,53.28]],"ltp":1.95,"tv":12206.56,"id":58385184},{"batb":[[0,2.04,41.5]],"ltp":2.06,"tv":296.49,"id":19144239}]}]}
{"op":"mcm","clk":"11795709879","pt":1722601050931,"mc":[{"id":"1.231282404","rc":[{"trd":[[1.95,5164.11],[1.96,5908.17]],"batb":[[0,1.95,274.07],[1,1.81,53.28],[2,1.74,17.32]],"ltp":1.95,"tv":12217.08,"id":58385184},{"trd":[[2.06,210]],"ltp":2.06,"tv":306.49,"id":19144239}],"tv":12523.57}]}
{"op":"mcm","clk":"11795710242","pt":1722601055015,"mc":[{"id":"1.231282404","rc":[{"batb":[[0,1.96,10],[1,1.95,274.07],[2,1.81,53.28]],"ltp":1.95,"tv":12217.08,"id":58385184},{"batb":[[0,1.91,43.88]],"ltp":2.06,"tv":306.49,"id":19144239}]}]}
{"op":"mcm","clk":"11795710343","pt":1722601056215,"mc":[{"id":"1.231282404","rc":[{"trd":[[1.95,5712.25],[1.96,5928.17]],"batb":[[0,1.81,53.28],[1,1.74,17.32],[2,1.73,31]],"batl":[[0,1.93,2423.21],[1,6,1.57],[2,12,1.57]],"ltp":1.95,"tv":12785.22,"id":58385184}],"tv":13091.71}]}
{"op":"mcm","clk":"11795710650","pt":1722601059903,"mc":[{"id":"1.231282404","rc":[{"batb":[[0,1.91,33.88]],"ltp":2.06,"tv":306.49,"id":19144239}]}]}
{"op":"mcm","clk":"11795714016","pt":1722601096383,"mc":[{"id":"1.231282404","rc":[{"batl":[[0,6,1.57],[1,12,1.57],[2,12,0]],"ltp":1.95,"tv":12785.22,"id":58385184}]}]}
{"op":"mcm","clk":"11795714198","pt":1722601098262,"mc":[{"id":"1.231282404","rc":[{"batb":[[0,1.82,10],[1,1.81,53.28],[2,1.74,17.32]],"ltp":1.95,"tv":12785.22,"id":58385184},{"batb":[[0,1.92,10],[1,1.91,33.88],[2,1.9,73.47]],"ltp":2.06,"tv":306.49,"id":19144239}]}]}
{"op":"mcm","clk":"11795714562","pt":1722601102291,"mc":[{"id":"1.231282404","rc":[{"batb":[[0,1.81,53.28],[1,1.74,17.32],[2,1.73,31]],"ltp":1.95,"tv":12785.22,"id":58385184},{"batb":[[0,1.91,33.88],[1,1.9,73.47],[2,1.8,50]],"ltp":2.06,"tv":306.49,"id":19144239}]}]}
{"op":"mcm","clk":"11795723520","pt":1722601206205,"mc":[{"id":"1.231282404","rc":[{"batb":[[0,1.82,10],[1,1.81,53.28],[2,1.74,17.32]],"batl":[[0,2.04,3.17],[1,6,1.57],[2,12,1.57]],"ltp":1.95,"tv":12785.22,"id":58385184},{"batb":[[0,1.92,10],[1,1.91,33.88],[2,1.9,73.47]],"ltp":2.06,"tv":306.49,"id":19144239}]}]}
{"op":"mcm","clk":"11795724061","pt":1722601209553,"mc":[{"id":"1.231282404","rc":[{"batb":[[0,1.81,53.28],[1,1.74,17.32],[2,1.73,31]],"ltp":1.95,"tv":12785.22,"id":58385184},{"batb":[[0,1.91,33.88],[1,1.9,73.47],[2,1.8,50]],"ltp":2.06,"tv":306.49,"id":19144239}]}]}
{"op":"mcm","clk":"11795724851","pt":1722601216990,"mc":[{"id":"1.231282404","rc":[{"batb":[[0,1.83,3.29],[1,1.82,10],[2,1.81,53.28]],"ltp":1.95,"tv":12785.22,"id":58385184},{"batb":[[0,1.92,10]],"ltp":2.06,"tv":306.49,"id":19144239}]}]}
{"op":"mcm","clk":"11795725175","pt":1722601220886,"mc":[{"id":"1.231282404","rc":[{"batb":[[1,1.81,53.28],[2,1.74,17.32]],"ltp":1.95,"tv":12785.22,"id":58385184},{"batb":[[0,1.9,73.47],[1,1.8,50],[2,1.74,17.32]],"ltp":2.06,"tv":306.49,"id":19144239}]}]}
{"op":"mcm","clk":"11795727869","pt":1722601252116,"mc":[{"id":"1.231282404","rc":[{"batb":[[0,1.81,54.24],[1,1.74,17.32],[2,1.73,31]],"ltp":1.95,"tv":12785.22,"id":58385184}]}]}
{"op":"mcm","clk":"11795727972","pt":1722601253572,"mc":[{"id":"1.231282404","rc":[{"batb":[[0,1.82,10.96],[1,1.81,53.28],[2,1.74,17.32]],"ltp":1.95,"tv":12785.22,"id":58385184},{"batb":[[0,1.91,10],[1,1.9,73.47],[2,1.8,50]],"ltp":2.06,"tv":306.49,"id":19144239}]}]}
{"op":"mcm","clk":"11795728331","pt":1722601258074,"mc":[{"id":"1.231282404","rc":[{"batb":[[0,1.81,54.24],[1,1.74,17.32],[2,1.73,31]],"ltp":1.95,"tv":12785.22,"id":58385184},{"batb":[[0,1.9,73.47],[1,1.8,50],[2,1.74,17.32]],"ltp":2.06,"tv":306.49,"id":19144239}]}]}
{"op":"mcm","clk":"11795728765","pt":1722601263509,"mc":[{"id":"1.231282404","rc":[{"batb":[[0,1.96,593.91],[1,1.81,54.24],[2,1.74,17.32]],"batl":[[0,5,1.75],[1,7,1.57],[2,12,0.78]],"ltp":1.95,"tv":12785.22,"id":58385184},{"batb":[[0,1.91,33.88],[1,1.9,73.47],[2,1.8,50]],"ltp":2.06,"tv":306.49,"id":19144239}]}]}
{"op":"mcm","clk":"11795728792","pt":1722601263823,"mc":[{"id":"1.231282404","rc":[{"batb":[[1,1.82,10.96],[2,1.81,53.28]],"ltp":1.95,"tv":12785.22,"id":58385184},{"batb":[[0,1.91,43.88]],"ltp":2.06,"tv":306.49,"id":19144239}]}]}
{"op":"mcm","clk":"11795729094","pt":1722601267903,"mc":[{"id":"1.231282404","rc":[{"batb":[[1,1.81,54.24],[2,1.74,17.32]],"ltp":1.95,"tv":12785.22,"id":58385184},{"batb":[[0,1.91,33.88]],"ltp":2.06,"tv":306.49,"id":19144239}]}]}
{"op":"mcm","clk":"11795729298","pt":1722601270590,"mc":[{"id":"1.231282404","rc":[{"batb":[[0,1.96,1187.83]],"ltp":1.95,"tv":12785.22,"id":58385184}]}]}
{"op":"mcm","clk":"11795729329","pt":1722601271010,"mc":[{"id":"1.231282404","rc":[{"batb":[[0,1.97,10],[1,1.96,1187.83],[2,1.81,54.24]],"ltp":1.95,"tv":12785.22,"id":58385184},{"batb":[[0,1.92,10],[1,1.91,33.88],[2,1.9,73.47]],"ltp":2.06,"tv":306.49,"id":19144239}]}]}
{"op":"mcm","clk":"11795729629","pt":1722601274320,"mc":[{"id":"1.231282404","rc":[{"batb":[[0,1.96,1187.83],[1,1.81,54.24],[2,1.74,17.32]],"ltp":1.95,"tv":12785.22,"id":58385184},{"batb":[[0,1.91,33.88],[1,1.9,73.47],[2,1.8,50]],"ltp":2.06,"tv":306.49,"id":19144239}]}]}
{"op":"mcm","clk":"11795729728","pt":1722601275116,"mc":[{"id":"1.231282404","rc":[{"batb":[[0,1.96,1188.84]],"ltp":1.95,"tv":12785.22,"id":58385184}]}]}
{"op":"mcm","clk":"11795730115","pt":1722601279328,"mc":[{"id":"1.231282404","rc":[{"batb":[[0,1.97,10],[1,1.96,1188.84],[2,1.81,54.24]],"ltp":1.95,"tv":12785.22,"id":58385184},{"batb":[[0,1.92,10],[1,1.91,33.88],[2,1.9,73.47]],"ltp":2.06,"tv":306.49,"id":19144239}]}]}
{"op":"mcm","clk":"11795730158","pt":1722601280010,"mc":[{"id":"1.231282404","rc":[{"batb":[[1,1.96,1782.75]],"ltp":1.95,"tv":12785.22,"id":58385184}]}]}
{"op":"mcm","clk":"11795730283","pt":1722601281201,"mc":[{"id":"1.231282404","rc":[{"batb":[[2,1.74,18.28]],"ltp":1.95,"tv":12785.22,"id":58385184}]}]}
{"op":"mcm","clk":"11795730446","pt":1722601283018,"mc":[{"id":"1.231282404","rc":[{"batb":[[0,1.96,1782.75],[1,1.74,18.28],[2,1.73,31]],"ltp":1.95,"tv":12785.22,"id":58385184},{"batb":[[0,1.91,33.88],[1,1.9,73.47],[2,1.8,50]],"ltp":2.06,"tv":306.49,"id":19144239}]}]}
{"op":"mcm","clk":"11795730571","pt":1722601284843,"mc":[{"id":"1.231282404","rc":[{"batb":[[0,1.96,2376.67]],"ltp":1.95,"tv":12785.22,"id":58385184}]}]}
{"op":"mcm","clk":"11795730786","pt":1722601287513,"mc":[{"id":"1.231282404","rc":[{"batb":[[0,1.97,10],[1,1.96,2376.67],[2,1.74,18.28]],"ltp":1.95,"tv":12785.22,"id":58385184},{"batb":[[0,1.92,10],[1,1.91,33.88],[2,1.9,73.47]],"ltp":2.06,"tv":306.49,"id":19144239}]}]}
{"op":"mcm","clk":"11795731113","pt":1722601291437,"mc":[{"id":"1.231282404","rc":[{"batb":[[0,1.96,2970.58],[1,1.74,18.28],[2,1.73,31]],"ltp":1.95,"tv":12785.22,"id":58385184},{"batb":[[0,1.91,33.88],[1,1.9,73.47],[2,1.8,50]],"ltp":2.06,"tv":306.49,"id":19144239}]}]}
{"op":"mcm","clk":"11795731453","pt":1722601295529,"mc":[{"id":"1.231282404","rc":[{"batb":[[0,1.97,10],[1,1.96,2970.58],[2,1.74,18.28]],"batl":[[0,2.08,1.92],[1,6,1.57],[2,12,1.57]],"ltp":1.95,"tv":12785.22,"id":58385184},{"batb":[[0,1.92,10],[1,1.91,33.88],[2,1.9,73.47]],"ltp":2.06,"tv":306.49,"id":19144239}]}]}
{"op":"mcm","clk":"11795731749","pt":1722601298827,"mc":[{"id":"1.231282404","rc":[{"batb":[[0,1.96,2970.58],[1,1.74,18.28],[2,1.73,31]],"ltp":1.95,"tv":12785.22,"id":58385184},{"batb":[[0,1.91,33.88],[1,1.9,73.47],[2,1.8,50]],"ltp":2.06,"tv":306.49,"id":19144239}]}]}
{"op":"mcm","clk":"11795732154","pt":1722601303436,"mc":[{"id":"1.231282404","rc":[{"batb":[[0,1.97,10],[1,1.96,3564.5],[2,1.74,18.28]],"ltp":1.95,"tv":12785.22,"id":58385184},{"batb":[[0,1.92,10],[1,1.91,33.88],[2,1.9,73.47]],"ltp":2.06,"tv":306.49,"id":19144239}]}]}
{"op":"mcm","clk":"11795732469","pt":1722601307155,"mc":[{"id":"1.231282404","rc":[{"batb":[[0,1.96,3564.5],[1,1.74,18.28],[2,1.73,31]],"ltp":1.95,"tv":12785.22,"id":58385184},{"batb":[[0,1.9,73.47],[1,1.8,50],[2,1.74,17.32]],"ltp":2.06,"tv":306.49,"id":19144239}]}]}
{"op":"mcm","clk":"11795732963","pt":1722601312567,"mc":[{"id":"1.231282404","rc":[{"batb":[[0,1.97,10],[1,1.96,4158.41],[2,1.74,18.28]],"ltp":1.95,"tv":12785.22,"id":58385184},{"batb":[[0,1.91,10],[1,1.9,73.47],[2,1.8,50]],"ltp":2.06,"tv":306.49,"id":19144239}]}]}
{"op":"mcm","clk":"11795733265","pt":1722601315932,"mc":[{"id":"1.231282404","rc":[{"batb":[[0,1.96,4158.41],[1,1.74,18.28],[2,1.73,31]],"ltp":1.95,"tv":12785.22,"id":58385184},{"batb":[[0,1.9,73.47],[1,1.8,50],[2,1.74,17.32]],"ltp":2.06,"tv":306.49,"id":19144239}]}]}
{"op":"mcm","clk":"11795733894","pt":1722601323663,"mc":[{"id":"1.231282404","rc":[{"batb":[[0,1.96,4752.32]],"ltp":1.95,"tv":12785.22,"id":58385184}]}]}
{"op":"mcm","clk":"11795733910","pt":1722601323874,"mc":[{"id":"1.231282404","rc":[{"batb":[[0,1.97,10],[1,1.96,4752.32],[2,1.74,18.28]],"ltp":1.95,"tv":12785.22,"id":58385184},{"batb":[[0,1.91,10],[1,1.9,73.47],[2,1.8,50]],"ltp":2.06,"tv":306.49,"id":19144239}]}]}
{"op":"mcm","clk":"11795734015","pt":1722601325072,"mc":[{"id":"1.231282404","rc":[{"batb":[[2,1.85,1.92]],"ltp":1.95,"tv":12785.22,"id":58385184}]}]}
{"op":"mcm","clk":"11795734103","pt":1722601326169,"mc":[{"id":"1.231282404","rc":[{"trd":[[1.97,80]],"batb":[[0,1.96,4752.32],[1,1.85,1.92],[2,1.74,17.32]],"batl":[[0,1.97,40],[1,2.08,1.92],[2,6,1.57]],"ltp":1.97,"tv":12805.22,"id":58385184}],"tv":13111.71}]}
{"op":"mcm","clk":"11795734201","pt":1722601327253,"mc":[{"id":"1.231282404","rc":[{"batb":[[0,1.9,73.47],[1,1.8,50],[2,1.74,17.32]],"ltp":2.06,"tv":306.49,"id":19144239}]}]}
{"op":"mcm","clk":"11795734703","pt":1722601332461,"mc":[{"id":"1.231282404","rc":[{"batb":[[0,1.96,5346.24]],"ltp":1.97,"tv":12805.22,"id":58385184},{"batb":[[0,1.91,10],[1,1.9,73.47],[2,1.8,50]],"ltp":2.06,"tv":306.49,"id":19144239}]}]}
{"op":"mcm","clk":"11795735063","pt":1722601336247,"mc":[{"id":"1.231282404","rc":[{"batb":[[0,1.9,73.47],[1,1.8,50],[2,1.74,17.32]],"ltp":2.06,"tv":306.49,"id":19144239}]}]}
{"op":"mcm","clk":"11795735166","pt":1722601337492,"mc":[{"id":"1.231282404","rc":[{"trd":[[1.96,16620.61]],"batb":[[0,1.85,1.92],[1,1.74,17.32],[2,1.73,31]],"batl":[[0,1.96,14693.8]],"ltp":1.96,"tv":23497.66,"id":58385184}],"tv":23804.15}]}
{"op":"mcm","clk":"11795735321","pt":1722601339472,"mc":[{"id":"1.231282404","rc":[{"trd":[[1.96,17808.43]],"batl":[[0,1.96,14099.89]],"ltp":1.96,"tv":24685.49,"id":58385184},{"batb":[[0,1.91,10],[1,1.9,73.47],[2,1.8,50]],"ltp":2.06,"tv":306.49,"id":19144239}],"tv":24991.98}]}
{"op":"mcm","clk":"11795735499","pt":1722601341651,"mc":[{"id":"1.231282404","rc":[{"batb":[[1,1.81,53.28],[2,1.74,17.32]],"ltp":1.96,"tv":24685.49,"id":58385184}]}]}
{"op":"mcm","clk":"11795735541","pt":1722601342176,"mc":[{"id":"1.231282404","rc":[{"trd":[[1.96,18996.26]],"batl":[[0,1.96,13505.98]],"ltp":1.96,"tv":25873.31,"id":58385184}],"tv":26179.8}]}
{"op":"mcm","clk":"11795735611","pt":1722601342902,"mc":[{"id":"1.231282404","rc":[{"batb":[[0,1.9,73.47],[1,1.8,50],[2,1.74,17.32]],"ltp":2.06,"tv":306.49,"id":19144239}]}]}
{"op":"mcm","clk":"11795736840","pt":1722601356905,"mc":[{"id":"1.231282404","rc":[{"batl":[[0,1.96,40]],"ltp":1.96,"tv":25873.31,"id":58385184}]}]}
{"op":"mcm","clk":"11795736918","pt":1722601358104,"mc":[{"id":"1.231282404","rc":[{"batb":[[0,1.91,10],[1,1.9,73.47],[2,1.8,50]],"ltp":2.06,"tv":306.49,"id":19144239}]}]}
{"op":"mcm","clk":"11795737238","pt":1722601361901,"mc":[{"id":"1.231282404","rc":[{"batb":[[0,1.9,73.47],[1,1.8,50],[2,1.74,17.32]],"ltp":2.06,"tv":306.49,"id":19144239}]}]}
{"op":"mcm","clk":"11795742837","pt":1722601429599,"mc":[{"id":"1.231282404","rc":[{"batb":[[0,2.08,10],[1,2.06,10.29],[2,1.9,73.47]],"ltp":2.06,"tv":306.49,"id":19144239}]}]}
{"op":"mcm","clk":"11795742963","pt":1722601431049,"mc":[{"id":"1.231282404","rc":[{"batl":[[0,2.08,1.92],[1,6,1.57],[2,12,1.57]],"ltp":1.96,"tv":25873.31,"id":58385184}]}]}
{"op":"mcm","clk":"11795743096","pt":1722601432856,"mc":[{"id":"1.231282404","rc":[{"batb":[[0,2.06,10.29],[1,1.9,73.47],[2,1.74,17.32]],"ltp":2.06,"tv":306.49,"id":19144239}]}]}
{"op":"mcm","clk":"11795743552","pt":1722601438124,"mc":[{"id":"1.231282404","rc":[{"batb":[[0,2.08,4],[1,2.06,14.29],[2,1.9,73.47]],"ltp":2.06,"tv":306.49,"id":19144239}]}]}
{"op":"mcm","clk":"11795743649","pt":1722601439359,"mc":[{"id":"1.231282404","rc":[{"batb":[[0,2.1,10],[1,2.08,4],[2,2.06,14.29]],"ltp":2.06,"tv":306.49,"id":19144239}]}]}
{"op":"mcm","clk":"11795743974","pt":1722601443108,"mc":[{"id":"1.231282404","rc":[{"batb":[[0,2.08,4],[1,2.06,14.29],[2,1.9,73.47]],"ltp":2.06,"tv":306.49,"id":19144239}]}]}
{"op":"mcm","clk":"11795744458","pt":1722601449477,"mc":[{"id":"1.231282404","rc":[{"trd":[[1.91,30]],"batb":[[0,1.9,593.91],[1,1.85,1.92],[2,1.81,53.28]],"ltp":1.91,"tv":25883.31,"id":58385184},{"trd":[[2.1,9.1]],"batb":[[0,2.08,4.9]],"ltp":2.1,"tv":315.59,"id":19144239}],"tv":26198.9}]}
{"op":"mcm","clk":"11795744485","pt":1722601449784,"mc":[{"id":"1.231282404","rc":[{"batb":[[0,2.06,11.19],[1,1.9,73.47],[2,1.74,17.32]],"ltp":2.1,"tv":315.59,"id":19144239}]}]}
{"op":"mcm","clk":"11795744814","pt":1722601453195,"mc":[{"id":"1.231282404","rc":[{"batb":[[0,1.91,4],[1,1.9,597.91],[2,1.85,1.92]],"ltp":1.91,"tv":25883.31,"id":58385184},{"batb":[[0,2.06,10.29]],"batl":[[0,2.12,4],[1,6,1.57],[2,12,1.57]],"ltp":2.1,"tv":315.59,"id":19144239}]}]}
{"op":"mcm","clk":"11795744935","pt":1722601454589,"mc":[{"id":"1.231282404","rc":[{"batb":[[0,1.91,14],[1,1.9,1191.83]],"ltp":1.91,"tv":25883.31,"id":58385184}]}]}
{"op":"mcm","clk":"11795745303","pt":1722601458774,"mc":[{"id":"1.231282404","rc":[{"batb":[[0,1.91,4]],"ltp":1.91,"tv":25883.31,"id":58385184}]}]}
{"op":"mcm","clk":"11795745596","pt":1722601462487,"mc":[{"id":"1.231282404","rc":[{"batb":[[0,1.92,10],[1,1.91,4],[2,1.9,1191.83]],"ltp":1.91,"tv":25883.31,"id":58385184}]}]}
{"op":"mcm","clk":"11795745619","pt":1722601462797,"mc":[{"id":"1.231282404","rc":[{"batb":[[2,1.9,1785.74]],"ltp":1.91,"tv":25883.31,"id":58385184}]}]}
{"op":"mcm","clk":"11795745867","pt":1722601465801,"mc":[{"id":"1.231282404","rc":[{"batb":[[0,1.91,4],[1,1.9,1785.74],[2,1.85,1.92]],"ltp":1.91,"tv":25883.31,"id":58385184}]}]}
{"op":"mcm","clk":"11795746096","pt":1722601468390,"mc":[{"id":"1.231282404","rc":[{"batb":[[0,1.92,10],[1,1.91,4],[2,1.9,1785.74]],"ltp":1.91,"tv":25883.31,"id":58385184},{"batl":[[0,2.1,4],[1,2.12,4],[2,6,1.57]],"ltp":2.1,"tv":315.59,"id":19144239}]}]}
{"op":"mcm","clk":"11795746391","pt":1722601471710,"mc":[{"id":"1.231282404","rc":[{"batb":[[0,1.91,4],[1,1.9,1785.74],[2,1.85,1.92]],"ltp":1.91,"tv":25883.31,"id":58385184}]}]}
{"op":"mcm","clk":"11795746478","pt":1722601472796,"mc":[{"id":"1.231282404","rc":[{"batb":[[0,1.92,593.91],[1,1.91,4],[2,1.9,1785.74]],"ltp":1.91,"tv":25883.31,"id":58385184}]}]}
{"op":"mcm","clk":"11795746577","pt":1722601474041,"mc":[{"id":"1.231282404","rc":[{"batb":[[0,1.93,10],[1,1.92,593.91],[2,1.91,4]],"ltp":1.91,"tv":25883.31,"id":58385184}]}]}
{"op":"mcm","clk":"11795746755","pt":1722601476310,"mc":[{"id":"1.231282404","rc":[{"batb":[[1,1.92,1187.83]],"ltp":1.91,"tv":25883.31,"id":58385184}]}]}
{"op":"mcm","clk":"11795746895","pt":1722601478115,"mc":[{"id":"1.231282404","rc":[{"batb":[[0,1.92,1187.83],[1,1.91,4],[2,1.9,1785.74]],"ltp":1.91,"tv":25883.31,"id":58385184}]}]}
{"op":"mcm","clk":"11795747004","pt":1722601479312,"mc":[{"id":"1.231282404","rc":[{"batb":[[0,1.92,1781.74]],"ltp":1.91,"tv":25883.31,"id":58385184}]}]}
{"op":"mcm","clk":"11795747259","pt":1722601482510,"mc":[{"id":"1.231282404","rc":[{"batb":[[0,1.92,2375.66]],"ltp":1.91,"tv":25883.31,"id":58385184}]}]}
{"op":"mcm","clk":"11795747355","pt":1722601483430,"mc":[{"id":"1.231282404","rc":[{"batb":[[0,1.93,14],[1,1.92,2375.66],[2,1.91,4]],"ltp":1.91,"tv":25883.31,"id":58385184}]}]}
{"op":"mcm","clk":"11795747501","pt":1722601485128,"mc":[{"id":"1.231282404","rc":[{"batb":[[1,1.92,2969.57]],"ltp":1.91,"tv":25883.31,"id":58385184}]}]}
{"op":"mcm","clk":"11795747635","pt":1722601486630,"mc":[{"id":"1.231282404","rc":[{"trd":[[1.92,92],[1.93,8]],"batb":[[0,1.92,2923.57],[1,1.91,4],[2,1.9,1785.74]],"ltp":1.92,"tv":25983.31,"id":58385184}],"tv":26298.9}]}
{"op":"mcm","clk":"11795747731","pt":1722601487923,"mc":[{"id":"1.231282404","rc":[{"trd":[[1.92,4092.01]],"batb":[[0,1.92,1517.47]],"ltp":1.92,"tv":29983.32,"id":58385184}],"tv":30298.91}]}
{"op":"mcm","clk":"11795747802","pt":1722601488820,"mc":[{"id":"1.231282404","rc":[{"batb":[[0,1.93,10],[1,1.92,1517.47],[2,1.91,4]],"ltp":1.92,"tv":29983.32,"id":58385184}]}]}
{"op":"mcm","clk":"11795747958","pt":1722601490634,"mc":[{"id":"1.231282404","rc":[{"batb":[[1,1.92,2111.39]],"ltp":1.92,"tv":29983.32,"id":58385184}]}]}
{"op":"mcm","clk":"11795748145","pt":1722601492558,"mc":[{"id":"1.231282404","rc":[{"batb":[[0,1.92,2111.39],[1,1.91,4],[2,1.9,1785.74]],"ltp":1.92,"tv":29983.32,"id":58385184}]}]}
{"op":"mcm","clk":"11795748235","pt":1722601493545,"mc":[{"id":"1.231282404","rc":[{"batb":[[0,1.92,2705.3]],"ltp":1.92,"tv":29983.32,"id":58385184}]}]}
{"op":"mcm","clk":"11795748349","pt":1722601494737,"mc":[{"id":"1.231282404","rc":[{"batb":[[0,1.93,10],[1,1.92,2705.3],[2,1.91,4]],"ltp":1.92,"tv":29983.32,"id":58385184}]}]}
{"op":"mcm","clk":"11795748508","pt":1722601496646,"mc":[{"id":"1.231282404","rc":[{"trd":[[1.92,8072.03],[1.93,28]],"batb":[[0,1.92,1309.2],[1,1.91,4],[2,1.9,1785.74]],"ltp":1.92,"tv":33983.34,"id":58385184}],"tv":34298.93}]}
{"op":"mcm","clk":"11795748652","pt":1722601498454,"mc":[{"id":"1.231282404","rc":[{"batb":[[0,1.92,1313.2]],"ltp":1.92,"tv":33983.34,"id":58385184}]}]}
{"op":"mcm","clk":"11795748746","pt":1722601499538,"mc":[{"id":"1.231282404","rc":[{"batb":[[0,1.93,10],[1,1.92,1907.12],[2,1.91,4]],"ltp":1.92,"tv":33983.34,"id":58385184}]}]}
{"op":"mcm","clk":"11795748782","pt":1722601499948,"mc":[{"id":"1.231282404","rc":[{"trd":[[1.92,8571.37],[1.93,48]],"batb":[[0,1.92,1657.44],[1,1.91,4],[2,1.9,1785.74]],"ltp":1.92,"tv":34502.68,"id":58385184}],"tv":34818.27}]}
{"op":"mcm","clk":"11795749475","pt":1722601507433,"mc":[{"id":"1.231282404","rc":[{"trd":[[1.92,12551.38],[1.93,68]],"batb":[[0,1.92,261.34]],"ltp":1.92,"tv":38502.69,"id":58385184}],"tv":38818.28}]}
{"op":"mcm","clk":"11795749729","pt":1722601510554,"mc":[{"id":"1.231282404","rc":[{"batb":[[0,1.92,855.26]],"ltp":1.92,"tv":38502.69,"id":58385184}]}]}
{"op":"mcm","clk":"11795749822","pt":1722601511639,"mc":[{"id":"1.231282404","rc":[{"trd":[[1.91,38],[1.92,14261.89],[1.93,88]],"batb":[[0,1.9,1785.74],[1,1.85,1.92],[2,1.74,17.32]],"batl":[[0,1.91,1130.75],[1,2.08,1.92],[2,6,1.57]],"ltp":1.91,"tv":40241.2,"id":58385184}],"tv":40556.79}]}
{"op":"mcm","clk":"11795749897","pt":1722601512568,"mc":[{"id":"1.231282404","rc":[{"batb":[[2,1.81,21.25]],"ltp":1.91,"tv":40241.2,"id":58385184},{"batl":[[0,2.12,4],[1,6,1.57],[2,12,1.57]],"ltp":2.1,"tv":315.59,"id":19144239}]}]}
{"op":"mcm","clk":"11795749976","pt":1722601513659,"mc":[{"id":"1.231282404","rc":[{"trd":[[1.91,1225.82]],"batl":[[0,1.91,536.84]],"ltp":1.91,"tv":41429.02,"id":58385184},{"batb":[[0,2.08,4],[1,2.06,10.29],[2,1.9,73.47]],"ltp":2.1,"tv":315.59,"id":19144239}],"tv":41744.61}]}
{"op":"mcm","clk":"11795750355","pt":1722601518171,"mc":[{"id":"1.231282404","rc":[{"trd":[[1.9,1324.47]],"batb":[[0,1.9,1655.91]],"ltp":1.9,"tv":41688.68,"id":58385184}],"tv":42004.27}]}
{"op":"mcm","clk":"11795750746","pt":1722601522583,"mc":[{"id":"1.231282404","rc":[{"trd":[[1.89,4.49],[1.9,4636.28]],"batb":[[0,1.85,1.92],[1,1.81,74.53],[2,1.74,17.32]],"batl":[[0,1.89,339.61],[1,1.91,536.84],[2,2.08,1.92]],"ltp":1.89,"tv":45004.99,"id":58385184},{"trd":[[2.12,42.53]],"batb":[[0,2.1,10],[1,2.08,4],[2,2.06,10.29]],"batl":[[0,6,1.57],[1,12,1.57],[2,12,0]],"ltp":2.12,"tv":319.59,"id":19144239}],"tv":45324.58}]}
{"op":"mcm","clk":"11795750808","pt":1722601523462,"mc":[{"id":"1.231282404","rc":[{"batb":[[1,1.81,53.28]],"batl":[[1,1.9,129.83],[2,1.91,536.84]],"ltp":1.89,"tv":45004.99,"id":58385184}]}]}
{"op":"mcm","clk":"11795751037","pt":1722601525888,"mc":[{"id":"1.231282404","rc":[{"batb":[[0,2.08,4],[1,2.06,10.29],[2,1.9,73.47]],"ltp":2.12,"tv":319.59,"id":19144239}]}]}
{"op":"mcm","clk":"11795751286","pt":1722601528890,"mc":[{"id":"1.231282404","rc":[{"batl":[[0,1.88,4],[1,1.89,343.61],[2,1.9,129.83]],"ltp":1.89,"tv":45004.99,"id":58385184},{"batb":[[0,2.16,10],[1,2.14,4],[2,2.12,4]],"ltp":2.12,"tv":319.59,"id":19144239}]}]}
{"op":"mcm","clk":"11795751554","pt":1722601532282,"mc":[{"id":"1.231282404","rc":[{"trd":[[1.88,12.55],[1.89,87.39]],"batl":[[0,1.89,302.16],[1,1.9,129.83],[2,1.91,536.84]],"ltp":1.89,"tv":45100.44,"id":58385184},{"trd":[[2.14,4]],"batb":[[0,2.12,4],[1,2.08,4],[2,2.06,10.29]],"ltp":2.14,"tv":323.59,"id":19144239}],"tv":45424.03}]}
{"op":"mcm","clk":"11795752172","pt":1722601539599,"mc":[{"id":"1.231282404","rc":[{"trd":[[1.89,691.71],[1.9,4900.41]],"batb":[[0,1.9,157.46],[1,1.85,1.92],[2,1.81,53.28]],"batl":[[0,1.91,536.84],[1,2.08,1.92],[2,6,1.57]],"ltp":1.9,"tv":45968.88,"id":58385184},{"trd":[[2.12,46.53]],"batb":[[0,2.1,10]],"ltp":2.12,"tv":327.59,"id":19144239}],"tv":46296.47}]}
{"op":"mcm","clk":"11795752293","pt":1722601541106,"mc":[{"id":"1.231282404","rc":[{"batb":[[1,1.89,6],[2,1.85,1.92]],"ltp":1.9,"tv":45968.88,"id":58385184}]}]}
{"op":"mcm","clk":"11795752482","pt":1722601543398,"mc":[{"id":"1.231282404","rc":[{"trd":[[1.91,2299.5]],"batb":[[0,1.92,10],[1,1.91,57.07],[2,1.9,157.46]],"batl":[[0,2.08,1.92],[1,6,1.57],[2,12,1.57]],"ltp":1.91,"tv":47042.56,"id":58385184},{"batb":[[0,2.08,4],[1,2.06,10.29],[2,1.9,73.47]],"ltp":2.12,"tv":327.59,"id":19144239}],"tv":47370.15}]}
{"op":"mcm","clk":"11795752515","pt":1722601543803,"mc":[{"id":"1.231282404","rc":[{"batb":[[1,1.91,61.07]],"ltp":1.91,"tv":47042.56,"id":58385184},{"batb":[[0,2.06,10.29],[1,1.9,73.47],[2,1.74,17.32]],"batl":[[0,2.1,4],[1,6,1.57],[2,12,1.57]],"ltp":2.12,"tv":327.59,"id":19144239}]}]}
{"op":"mcm","clk":"11795752713","pt":1722601546605,"mc":[{"id":"1.231282404","rc":[{"trd":[[1.95,5718.19]],"batb":[[0,1.91,61.07],[1,1.9,157.46],[2,1.89,6]],"ltp":1.95,"tv":47048.5,"id":58385184},{"trd":[[2.06,215.62]],"batb":[[0,2.06,4.67]],"ltp":2.06,"tv":333.21,"id":19144239}],"tv":47381.71}]}
{"op":"mcm","clk":"11795752864","pt":1722601548679,"mc":[{"id":"1.231282404","rc":[{"trd":[[1.95,5723.12]],"batb":[[0,1.95,588.98],[1,1.91,61.07],[2,1.9,157.46]],"ltp":1.95,"tv":47053.43,"id":58385184},{"trd":[[2.06,220.29]],"batb":[[0,1.9,73.47],[1,1.74,17.32],[2,1.51,1]],"ltp":2.06,"tv":337.88,"id":19144239}],"tv":47391.31}]}
{"op":"mcm","clk":"11795752933","pt":1722601549615,"mc":[{"id":"1.231282404","rc":[{"batb":[[0,1.96,10],[1,1.95,588.98],[2,1.91,61.07]],"ltp":1.95,"tv":47053.43,"id":58385184},{"batb":[[0,1.91,10],[1,1.9,73.47],[2,1.74,17.32]],"ltp":2.06,"tv":337.88,"id":19144239}]}]}
{"op":"mcm","clk":"11795753168","pt":1722601552906,"mc":[{"id":"1.231282404","rc":[{"batb":[[0,1.95,588.98],[1,1.91,61.07],[2,1.9,163.46]],"ltp":1.95,"tv":47053.43,"id":58385184},{"batb":[[0,1.9,73.47],[1,1.74,17.32],[2,1.51,1]],"ltp":2.06,"tv":337.88,"id":19144239}]}]}
{"op":"mcm","clk":"11795754084","pt":1722601564614,"mc":[{"id":"1.231282404","rc":[{"trd":[[1.95,6723.12]],"batb":[[0,1.96,10],[1,1.95,88.98],[2,1.91,61.07]],"ltp":1.95,"tv":48053.43,"id":58385184},{"batb":[[0,1.91,10],[1,1.9,73.47],[2,1.74,17.32]],"ltp":2.06,"tv":337.88,"id":19144239}],"tv":48391.31}]}
{"op":"mcm","clk":"11795754411","pt":1722601568501,"mc":[{"id":"1.231282404","rc":[{"batb":[[0,1.95,88.98],[1,1.91,61.07],[2,1.9,163.46]],"ltp":1.95,"tv":48053.43,"id":58385184},{"batb":[[0,1.9,73.47],[1,1.74,17.32],[2,1.51,1]],"ltp":2.06,"tv":337.88,"id":19144239}]}]}
{"op":"mcm","clk":"11795754659","pt":1722601571604,"mc":[{"id":"1.231282404","rc":[{"trd":[[1.95,6743.12]],"batb":[[0,1.95,78.98]],"ltp":1.95,"tv":48073.43,"id":58385184}],"tv":48411.31}]}
{"op":"mcm","clk":"11795754678","pt":1722601571908,"mc":[{"id":"1.231282404","rc":[{"batb":[[0,1.96,10],[1,1.95,78.98],[2,1.91,61.07]],"ltp":1.95,"tv":48073.43,"id":58385184},{"batb":[[0,1.91,10],[1,1.9,73.47],[2,1.74,17.32]],"ltp":2.06,"tv":337.88,"id":19144239}]}]}
{"op":"mcm","clk":"11795754926","pt":1722601575218,"mc":[{"id":"1.231282404","rc":[{"batb":[[0,1.95,78.98],[1,1.91,61.07],[2,1.9,163.46]],"ltp":1.95,"tv":48073.43,"id":58385184},{"batb":[[0,1.9,73.47],[1,1.74,17.32],[2,1.51,1]],"ltp":2.06,"tv":337.88,"id":19144239}]}]}
{"op":"mcm","clk":"11795755412","pt":1722601581426,"mc":[{"id":"1.231282404","rc":[{"trd":[[1.95,6901.08]],"batb":[[0,1.91,61.07],[1,1.9,163.46],[2,1.85,1.92]],"batl":[[0,1.95,50.85],[1,2.08,1.92],[2,6,1.57]],"ltp":1.95,"tv":48231.39,"id":58385184}],"tv":48569.27}]}
{"op":"mcm","clk":"11795755474","pt":1722601582036,"mc":[{"id":"1.231282404","rc":[{"batb":[[0,1.91,10],[1,1.9,73.47],[2,1.74,17.32]],"ltp":2.06,"tv":337.88,"id":19144239}]}]}
{"op":"mcm","clk":"11795755783","pt":1722601585930,"mc":[{"id":"1.231282404","rc":[{"batb":[[0,1.9,73.47],[1,1.74,17.32],[2,1.51,1]],"ltp":2.06,"tv":337.88,"id":19144239}]}]}
{"op":"mcm","clk":"11795756031","pt":1722601589158,"mc":[{"id":"1.231282404","rc":[{"batl":[[0,1.95,54.85]],"ltp":1.95,"tv":48231.39,"id":58385184},{"batb":[[0,2.04,4],[1,1.9,73.47],[2,1.74,17.32]],"batl":[[0,2.08,4],[1,2.1,4],[2,6,1.57]],"ltp":2.06,"tv":337.88,"id":19144239}]}]}
{"op":"mcm","clk":"11795757107","pt":1722601602478,"mc":[{"id":"1.231282404","rc":[{"batb":[[2,1.87,1.92]],"ltp":1.95,"tv":48231.39,"id":58385184}]}]}
{"op":"mcm","clk":"11795757284","pt":1722601604248,"mc":[{"id":"1.231282404","rc":[{"batb":[[0,1.92,4],[1,1.91,61.07],[2,1.9,163.46]],"batl":[[0,1.94,4],[1,1.95,54.85],[2,2.08,1.92]],"ltp":1.95,"tv":48231.39,"id":58385184}]}]}
{"op":"mcm","clk":"11795834029","pt":1722602535338,"mc":[{"id":"1.231282404","rc":[{"batb":[[0,1.92,9.21]],"batl":[[0,1.94,8.42]],"ltp":1.95,"tv":48231.39,"id":58385184}]}]}
{"op":"mcm","clk":"11795834360","pt":1722602540048,"mc":[{"id":"1.231282404","rc":[{"batb":[[0,2.06,4],[1,2.04,4],[2,1.9,73.47]],"ltp":2.06,"tv":337.88,"id":19144239}]}]}
{"op":"mcm","clk":"11795861730","pt":1722602771653,"mc":[{"id":"1.231282404","rc":[{"trd":[[1.92,14284.64]],"batb":[[0,1.91,61.07],[1,1.9,163.46],[2,1.87,1.92]],"batl":[[0,1.92,2424.16],[1,1.94,8.42],[2,1.95,54.85]],"ltp":1.92,"tv":48254.15,"id":58385184},{"trd":[[2.08,4]],"batl":[[0,6,1.57],[1,12,1.57],[2,6,0]],"ltp":2.08,"tv":341.88,"id":19144239}],"tv":48596.03}]}
{"op":"mcm","clk":"11795861738","pt":1722602771760,"mc":[{"id":"1.231282404","rc":[{"batb":[[0,1.91,57.07]],"ltp":1.92,"tv":48254.15,"id":58385184}]}]}
{"op":"mcm","clk":"11795861907","pt":1722602774159,"mc":[{"id":"1.231282404","rc":[{"batl":[[0,1.92,2429.37],[1,1.94,4]],"ltp":1.92,"tv":48254.15,"id":58385184}]}]}
{"op":"mcm","clk":"11795862490","pt":1722602781567,"mc":[{"id":"1.231282404","rc":[{"batl":[[0,1.92,2433.37]],"ltp":1.92,"tv":48254.15,"id":58385184},{"batb":[[0,2.08,4],[1,2.06,4],[2,2.04,4]],"ltp":2.08,"tv":341.88,"id":19144239}]}]}
{"op":"mcm","clk":"11795863601","pt":1722602799952,"mc":[{"id":"1.231282404","rc":[{"trd":[[1.92,15084.64]],"batl":[[0,1.92,2033.37]],"ltp":1.92,"tv":49054.15,"id":58385184}],"tv":49396.03}]}
{"op":"mcm","clk":"11795864052","pt":1722602808104,"mc":[{"id":"1.231282404","rc":[{"trd":[[1.91,2413.65],[1.92,15284.64]],"batb":[[0,1.9,163.46],[1,1.87,1.92],[2,1.74,17.32]],"batl":[[0,1.91,2380.63],[1,1.92,1933.37],[2,1.94,4]],"ltp":1.91,"tv":49368.29,"id":58385184}],"tv":49710.17}]}
{"op":"mcm","clk":"11795864169","pt":1722602809903,"mc":[{"id":"1.231282404","rc":[{"batb":[[2,1.81,53.28]],"ltp":1.91,"tv":49368.29,"id":58385184}]}]}
{"op":"mcm","clk":"11795864278","pt":1722602811677,"mc":[{"id":"1.231282404","rc":[{"batl":[[0,1.91,2384.63]],"ltp":1.91,"tv":49368.29,"id":58385184},{"batb":[[0,2.1,4],[1,2.08,4],[2,2.06,4]],"ltp":2.08,"tv":341.88,"id":19144239}]}]}
{"op":"mcm","clk":"11795864325","pt":1722602812502,"mc":[{"id":"1.231282404","rc":[{"batb":[[0,2.08,4],[1,2.06,4],[2,2.04,4]],"ltp":2.08,"tv":341.88,"id":19144239}]}]}
{"op":"mcm","clk":"11795864512","pt":1722602815216,"mc":[{"id":"1.231282404","rc":[{"batl":[[0,1.91,4],[1,1.92,9.21]],"ltp":1.91,"tv":49368.29,"id":58385184}]}]}
{"op":"mcm","clk":"11795864593","pt":1722602816609,"mc":[{"id":"1.231282404","rc":[{"batl":[[0,1.94,5.16],[1,1.95,50.85],[2,2.08,1.92]],"ltp":1.91,"tv":49368.29,"id":58385184},{"batb":[[0,2.06,4],[1,2.04,4],[2,1.9,73.47]],"ltp":2.08,"tv":341.88,"id":19144239}]}]}
{"op":"mcm","clk":"11795864717","pt":1722602818684,"mc":[{"id":"1.231282404","rc":[{"batl":[[0,1.94,9.68]],"ltp":1.91,"tv":49368.29,"id":58385184}]}]}
{"op":"mcm","clk":"11795864876","pt":1722602821497,"mc":[{"id":"1.231282404","rc":[{"trd":[[1.9,5227.33]],"batb":[[0,1.87,1.92],[1,1.81,53.28],[2,1.74,17.32]],"batl":[[0,1.9,324.08],[1,1.94,5.16],[2,1.95,50.85]],"ltp":1.9,"tv":49695.21,"id":58385184}],"tv":50037.09}]}
{"op":"mcm","clk":"11795865027","pt":1722602823643,"mc":[{"id":"1.231282404","rc":[{"batl":[[1,1.95,50.85],[2,2.08,1.92]],"ltp":1.9,"tv":49695.21,"id":58385184}]}]}
{"op":"mcm","clk":"11795865258","pt":1722602826910,"mc":[{"id":"1.231282404","rc":[{"batl":[[0,1.89,4],[1,1.9,328.08],[2,1.95,50.85]],"ltp":1.9,"tv":49695.21,"id":58385184},{"batb":[[0,2.12,4],[1,2.1,4],[2,2.06,4]],"ltp":2.08,"tv":341.88,"id":19144239}]}]}
{"op":"mcm","clk":"11795865500","pt":1722602830490,"mc":[{"id":"1.231282404","rc":[{"batl":[[0,1.89,9.3]],"ltp":1.9,"tv":49695.21,"id":58385184}]}]}
{"op":"mcm","clk":"11795866647","pt":1722602846579,"mc":[{"id":"1.231282404","rc":[{"batl":[[0,1.89,5.3],[1,1.95,50.85],[2,2.08,1.92]],"ltp":1.9,"tv":49695.21,"id":58385184},{"batb":[[0,1.9,73.47],[1,1.74,17.32],[2,1.51,1]],"ltp":2.08,"tv":341.88,"id":19144239}]}]}
{"op":"mcm","clk":"11795866805","pt":1722602848982,"mc":[{"id":"1.231282404","rc":[{"batl":[[0,1.95,50.85],[1,2.08,1.92],[2,6,1.57]],"ltp":1.9,"tv":49695.21,"id":58385184}]}]}
{"op":"mcm","clk":"11795867283","pt":1722602857057,"mc":[{"id":"1.231282404","rc":[{"batb":[[0,2.06,4],[1,2.04,4],[2,1.9,73.47]],"ltp":2.08,"tv":341.88,"id":19144239}]}]}
{"op":"mcm","clk":"11795868665","pt":1722602878465,"mc":[{"id":"1.231282404","rc":[{"batl":[[0,1.94,5.16],[1,1.95,50.85],[2,2.08,1.92]],"ltp":1.9,"tv":49695.21,"id":58385184}]}]}
{"op":"mcm","clk":"11795871010","pt":1722602912408,"mc":[{"id":"1.231282404","rc":[{"batl":[[0,1.94,9.68]],"ltp":1.9,"tv":49695.21,"id":58385184}]}]}
{"op":"mcm","clk":"11795871188","pt":1722602915024,"mc":[{"id":"1.231282404","rc":[{"batl":[[0,1.94,4.52]],"ltp":1.9,"tv":49695.21,"id":58385184}]}]}
{"op":"mcm","clk":"11795875376","pt":1722602974260,"mc":[{"id":"1.231282404","rc":[{"batl":[[0,1.94,9]],"ltp":1.9,"tv":49695.21,"id":58385184}]}]}
{"op":"mcm","clk":"11795875567","pt":1722602977388,"mc":[{"id":"1.231282404","rc":[{"batl":[[0,1.94,4.52]],"ltp":1.9,"tv":49695.21,"id":58385184}]}]}
{"op":"mcm","clk":"11795879568","pt":1722603037449,"mc":[{"id":"1.231282404","rc":[{"batl":[[0,1.94,9]],"ltp":1.9,"tv":49695.21,"id":58385184}]}]}
{"op":"mcm","clk":"11795879776","pt":1722603040166,"mc":[{"id":"1.231282404","rc":[{"batl":[[0,1.94,4.48]],"ltp":1.9,"tv":49695.21,"id":58385184}]}]}
{"op":"mcm","clk":"11795883280","pt":1722603096058,"mc":[{"id":"1.231282404","rc":[{"batb":[[0,1.81,53.28],[1,1.74,17.32],[2,1.73,31]],"ltp":1.9,"tv":49695.21,"id":58385184}]}]}
{"op":"mcm","clk":"11795883703","pt":1722603101543,"mc":[{"id":"1.231282404","rc":[{"batl":[[0,1.94,8.95],[2,6,1.57]],"ltp":1.9,"tv":49695.21,"id":58385184}]}]}
{"op":"mcm","clk":"11795883915","pt":1722603104633,"mc":[{"id":"1.231282404","rc":[{"batl":[[0,1.94,4.48]],"ltp":1.9,"tv":49695.21,"id":58385184}]}]}
{"op":"mcm","clk":"11795885795","pt":1722603130472,"mc":[{"id":"1.231282404","rc":[{"batb":[[0,2.06,8.57]],"ltp":2.08,"tv":341.88,"id":19144239}]}]}
{"op":"mcm","clk":"11795886021","pt":1722603133371,"mc":[{"id":"1.231282404","rc":[{"batb":[[0,2.06,4]],"ltp":2.08,"tv":341.88,"id":19144239}]}]}
{"op":"mcm","clk":"11795886965","pt":1722603147192,"mc":[{"id":"1.231282404","rc":[{"batb":[[0,1.82,14],[1,1.81,53.28],[2,1.74,17.32]],"ltp":1.9,"tv":49695.21,"id":58385184}]}]}
{"op":"mcm","clk":"11795888253","pt":1722603164510,"mc":[{"id":"1.231282404","rc":[{"batl":[[0,1.94,8.95]],"ltp":1.9,"tv":49695.21,"id":58385184}]}]}
{"op":"mcm","clk":"11795888391","pt":1722603166688,"mc":[{"id":"1.231282404","rc":[{"batl":[[0,1.94,4.48]],"ltp":1.9,"tv":49695.21,"id":58385184}]}]}
{"op":"mcm","clk":"11795889007","pt":1722603175490,"mc":[{"id":"1.231282404","rc":[{"batb":[[0,1.9,593.91],[1,1.82,14],[2,1.81,53.28]],"ltp":1.9,"tv":49695.21,"id":58385184}]}]}
{"op":"mcm","clk":"11795889075","pt":1722603176623,"mc":[{"id":"1.231282404","rc":[{"batb":[[0,1.9,73.47],[1,1.74,17.32],[2,1.51,1]],"batl":[[0,2.1,17],[1,6,1.57],[2,12,1.57]],"ltp":2.08,"tv":341.88,"id":19144239}]}]}
{"op":"mcm","clk":"11795889239","pt":1722603179006,"mc":[{"id":"1.231282404","rc":[{"batb":[[0,1.9,1187.83]],"ltp":1.9,"tv":49695.21,"id":58385184}]}]}
{"op":"mcm","clk":"11795889980","pt":1722603188929,"mc":[{"id":"1.231282404","rc":[{"batb":[[0,1.9,1191.83]],"ltp":1.9,"tv":49695.21,"id":58385184},{"batl":[[0,2.1,21]],"ltp":2.08,"tv":341.88,"id":19144239}]}]}
{"op":"mcm","clk":"11795891246","pt":1722603205824,"mc":[{"id":"1.231282404","rc":[{"batb":[[0,1.9,1785.74]],"ltp":1.9,"tv":49695.21,"id":58385184}]}]}
{"op":"mcm","clk":"11795891315","pt":1722603206814,"mc":[{"id":"1.231282404","rc":[{"batb":[[2,1.81,8.33]],"ltp":1.9,"tv":49695.21,"id":58385184}]}]}
{"op":"mcm","clk":"11795902647","pt":1722603372368,"mc":[{"id":"1.231282404","rc":[{"batb":[[0,1.91,17.2],[1,1.9,1785.74],[2,1.82,14]],"ltp":1.9,"tv":49695.21,"id":58385184}]}]}
{"op":"mcm","clk":"11795903569","pt":1722603385089,"mc":[{"id":"1.231282404","rc":[{"batb":[[0,1.91,21.2]],"ltp":1.9,"tv":49695.21,"id":58385184}]}]}
{"op":"mcm","clk":"11795912064","pt":1722603487479,"mc":[{"id":"1.231282404","rc":[{"trd":[[1.9,6160.01],[1.91,2456.05]],"batb":[[0,1.9,1319.4],[1,1.82,14],[2,1.74,17.32]],"ltp":1.9,"tv":50670.29,"id":58385184}],"tv":51012.17}]}
{"op":"mcm","clk":"11795912125","pt":1722603488271,"mc":[{"id":"1.231282404","rc":[{"batb":[[2,1.81,53.28]],"batl":[[0,1.94,21.41]],"ltp":1.9,"tv":50670.29,"id":58385184}]}]}
{"op":"mcm","clk":"11795912695","pt":1722603495079,"mc":[{"id":"1.231282404","rc":[{"trd":[[1.9,7135.09]],"batb":[[0,1.9,831.86]],"ltp":1.9,"tv":51645.37,"id":58385184}],"tv":51987.25}]}
{"op":"mcm","clk":"11795913523","pt":1722603505505,"mc":[{"id":"1.231282404","rc":[{"trd":[[1.9,8110.18]],"batb":[[0,1.9,344.31]],"ltp":1.9,"tv":52620.46,"id":58385184}],"tv":52962.34}]}
{"op":"mcm","clk":"11795913556","pt":1722603505889,"mc":[{"id":"1.231282404","rc":[{"batb":[[0,1.9,348.31]],"ltp":1.9,"tv":52620.46,"id":58385184}]}]}
{"op":"mcm","clk":"11795914354","pt":1722603514998,"mc":[{"id":"1.231282404","rc":[{"trd":[[1.9,8830.01]],"batb":[[0,1.82,14],[1,1.81,53.28],[2,1.74,17.32]],"batl":[[0,1.9,116.02],[1,1.94,21.41],[2,1.95,50.85]],"ltp":1.9,"tv":53340.29,"id":58385184},{"trd":[[2.1,30.1]],"batl":[[0,6,1.57],[1,12,1.57],[2,12,0]],"ltp":2.1,"tv":362.88,"id":19144239}],"tv":53703.17}]}
{"op":"mcm","clk":"11795914492","pt":1722603516621,"mc":[{"id":"1.231282404","rc":[{"batl":[[1,1.94,16.93]],"ltp":1.9,"tv":53340.29,"id":58385184}]}]}
{"op":"mcm","clk":"11795914565","pt":1722603517501,"mc":[{"id":"1.231282404","rc":[{"batl":[[0,1.89,5.3],[1,1.9,116.02]],"ltp":1.9,"tv":53340.29,"id":58385184},{"batb":[[0,2.12,16.84],[1,1.9,73.47],[2,1.74,17.32]],"ltp":2.1,"tv":362.88,"id":19144239}]}]}
{"op":"mcm","clk":"11795914585","pt":1722603517701,"mc":[{"id":"1.231282404","rc":[{"batl":[[0,1.89,12.17],[2,1.91,17.2]],"ltp":1.9,"tv":53340.29,"id":58385184}]}]}
{"op":"mcm","clk":"11795914886","pt":1722603521229,"mc":[{"id":"1.231282404","rc":[{"batl":[[2,1.95,50.85]],"ltp":1.9,"tv":53340.29,"id":58385184},{"batb":[[0,2.14,4],[1,2.12,20.84],[2,1.9,73.47]],"batl":[[0,2.22,4],[1,6,1.57],[2,12,1.57]],"ltp":2.1,"tv":362.88,"id":19144239}]}]}
{"op":"mcm","clk":"11795916143","pt":1722603536013,"mc":[{"id":"1.231282404","rc":[{"batb":[[0,1.82,18]],"batl":[[0,1.88,4],[1,1.89,12.17],[2,1.9,116.02]],"ltp":1.9,"tv":53340.29,"id":58385184}]}]}
{"op":"mcm","clk":"11795917320","pt":1722603548134,"mc":[{"id":"1.231282404","rc":[{"batl":[[0,1.88,21.47],[1,1.89,22.63]],"ltp":1.9,"tv":53340.29,"id":58385184}]}]}
{"op":"mcm","clk":"11795917608","pt":1722603551117,"mc":[{"id":"1.231282404","rc":[{"batl":[[0,1.87,9.35],[1,1.88,21.47],[2,1.89,17.33]],"ltp":1.9,"tv":53340.29,"id":58385184}]}]}
{"op":"mcm","clk":"11795917891","pt":1722603554335,"mc":[{"id":"1.231282404","rc":[{"batl":[[2,1.89,10.46]],"ltp":1.9,"tv":53340.29,"id":58385184}]}]}
{"op":"mcm","clk":"11795918007","pt":1722603555715,"mc":[{"id":"1.231282404","rc":[{"batl":[[2,1.9,116.02]],"ltp":1.9,"tv":53340.29,"id":58385184}]}]}
{"op":"mcm","clk":"11795925868","pt":1722603656653,"mc":[{"id":"1.231282404","rc":[{"trd":[[1.89,690.36],[1.9,8810.63],[1.91,2450.71],[1.92,15252.84],[1.95,6885.38],[1.96,18953.81]],"batl":[[0,1.87,9.35],[1,1.88,21.48]],"ltp":1.9,"tv":53224.27,"id":58385184},{"trd":[[2.1,30.11]],"batb":[[1,2.12,20.85],[2,1.9,73.14]],"batl":[[1,6,1.56],[2,12,1.56]],"ltp":2.1,"tv":362.89,"id":19144239}],"tv":53587.17}]}
{"op":"mcm","clk":"11795950184","pt":1722603975805,"mc":[{"id":"1.231282404","rc":[{"batl":[[2,1.95,50.85]],"ltp":1.9,"tv":53224.27,"id":58385184}]}]}
{"op":"mcm","clk":"11795951036","pt":1722603987577,"mc":[{"id":"1.231282404","rc":[{"trd":[[1.82,36]],"batb":[[0,1.81,53.28],[1,1.74,17.32],[2,1.73,31]],"batl":[[0,1.82,487.6],[1,1.87,9.35],[2,1.88,4]],"ltp":1.82,"tv":53260.27,"id":58385184},{"batb":[[0,2.16,10],[1,2.14,4],[2,2.12,20.85]],"batl":[[0,6,1.56],[1,12,1.56],[2,12,0]],"ltp":2.1,"tv":362.89,"id":19144239}],"tv":53623.17}]}
{"op":"mcm","clk":"11795951100","pt":1722603988973,"mc":[{"id":"1.231282404","rc":[{"batl":[[0,1.82,491.6]],"ltp":1.82,"tv":53260.27,"id":58385184},{"batb":[[0,2.22,4],[1,2.2,4],[2,2.16,10]],"ltp":2.1,"tv":362.89,"id":19144239}]}]}
{"op":"mcm","clk":"11795951167","pt":1722603990273,"mc":[{"id":"1.231282404","rc":[{"batl":[[0,1.82,497.1],[1,1.87,4]],"ltp":1.82,"tv":53260.27,"id":58385184},{"batb":[[0,2.22,20.1]],"ltp":2.1,"tv":362.89,"id":19144239}]}]}
{"op":"mcm","clk":"11795951214","pt":1722603990908,"mc":[{"id":"1.231282404","rc":[{"batb":[[2,2.14,4]],"ltp":2.1,"tv":362.89,"id":19144239}]}]}
{"op":"mcm","clk":"11795951920","pt":1722604001217,"mc":[{"id":"1.231282404","rc":[{"batl":[[0,1.82,419.2]],"ltp":1.82,"tv":53260.27,"id":58385184}]}]}
{"op":"mcm","clk":"11795952024","pt":1722604002603,"mc":[{"id":"1.231282404","rc":[{"trd":[[1.81,12.38]],"batb":[[0,1.81,40.9]],"batl":[[0,1.82,27.56]],"ltp":1.81,"tv":53272.65,"id":58385184},{"trd":[[2.24,10]],"ltp":2.24,"tv":372.89,"id":19144239}],"tv":53645.55}]}
{"op":"mcm","clk":"11795952129","pt":1722604004002,"mc":[{"id":"1.231282404","rc":[{"batl":[[0,2.24,4],[1,6,1.56],[2,12,1.56]],"ltp":2.24,"tv":372.89,"id":19144239}]}]}
{"op":"mcm","clk":"11795952229","pt":1722604005605,"mc":[{"id":"1.231282404","rc":[{"batb":[[0,1.81,94.18]],"ltp":1.81,"tv":53272.65,"id":58385184}]}]}
{"op":"mcm","clk":"11795952235","pt":1722604005705,"mc":[{"id":"1.231282404","rc":[{"batb":[[0,1.81,53.28]],"ltp":1.81,"tv":53272.65,"id":58385184}]}]}
{"op":"mcm","clk":"11795952410","pt":1722604008501,"mc":[{"id":"1.231282404","rc":[{"trd":[[1.82,38.08]],"batl":[[0,1.82,26.53]],"ltp":1.82,"tv":53274.73,"id":58385184}],"tv":53647.62}]}
{"op":"mcm","clk":"11795953128","pt":1722604019213,"mc":[{"id":"1.231282404","rc":[{"batb":[[0,1.81,57.28]],"ltp":1.82,"tv":53274.73,"id":58385184}]}]}
{"op":"mcm","clk":"11795962666","pt":1722604154675,"mc":[{"id":"1.231282404","rc":[{"trd":[[1.82,115.63]],"batb":[[0,1.81,58.18]],"batl":[[0,1.87,4],[1,1.88,4],[2,1.95,50.85]],"ltp":1.82,"tv":53352.29,"id":58385184},{"trd":[[2.22,20.1]],"batb":[[0,2.2,4],[1,2.14,4],[2,2.12,4]],"ltp":2.22,"tv":392.98,"id":19144239}],"tv":53745.28}]}
{"op":"mcm","clk":"11795962722","pt":1722604155459,"mc":[{"id":"1.231282404","rc":[{"batl":[[0,1.95,50.85],[1,6,1.56],[2,12,1.56]],"ltp":1.82,"tv":53352.29,"id":58385184},{"batb":[[0,1.91,10],[1,1.9,73.14],[2,1.74,17.32]],"ltp":2.22,"tv":392.98,"id":19144239}]}]}
{"op":"mcm","clk":"11795962969","pt":1722604158985,"mc":[{"id":"1.231282404","rc":[{"batb":[[0,1.9,73.14],[1,1.74,17.32],[2,1.51,1]],"ltp":2.22,"tv":392.98,"id":19144239}]}]}
{"op":"mcm","clk":"11795974924","pt":1722604324318,"mc":[{"id":"1.231282404","rc":[{"batl":[[0,1.91,487.54],[1,1.95,50.85],[2,6,1.56]],"ltp":1.82,"tv":53352.29,"id":58385184},{"batb":[[0,1.91,10],[1,1.9,73.14],[2,1.74,17.32]],"ltp":2.22,"tv":392.98,"id":19144239}]}]}
{"op":"mcm","clk":"11795974974","pt":1722604324839,"mc":[{"id":"1.231282404","rc":[{"batb":[[0,1.81,54.18]],"ltp":1.82,"tv":53352.29,"id":58385184},{"batl":[[0,6,1.56],[1,12,1.56],[2,12,0]],"ltp":2.22,"tv":392.98,"id":19144239}]}]}
{"op":"mcm","clk":"11795975191","pt":1722604327522,"mc":[{"id":"1.231282404","rc":[{"batb":[[0,1.9,73.14],[1,1.74,17.32],[2,1.51,1]],"ltp":2.22,"tv":392.98,"id":19144239}]}]}
{"op":"mcm","clk":"11795975467","pt":1722604331047,"mc":[{"id":"1.231282404","rc":[{"batb":[[0,1.91,10],[1,1.9,73.14],[2,1.74,17.32]],"ltp":2.22,"tv":392.98,"id":19144239}]}]}
{"op":"mcm","clk":"11795976018","pt":1722604338064,"mc":[{"id":"1.231282404","rc":[{"batb":[[0,1.9,73.14],[1,1.74,17.32],[2,1.51,1]],"ltp":2.22,"tv":392.98,"id":19144239}]}]}
{"op":"mcm","clk":"11795977330","pt":1722604356064,"mc":[{"id":"1.231282404","rc":[{"batl":[[0,1.9,16.72],[1,1.91,487.54],[2,1.95,50.85]],"ltp":1.82,"tv":53352.29,"id":58385184}]}]}
{"op":"mcm","clk":"11795977425","pt":1722604357398,"mc":[{"id":"1.231282404","rc":[{"batb":[[0,1.91,10],[1,1.9,73.14],[2,1.74,17.32]],"ltp":2.22,"tv":392.98,"id":19144239}]}]}
{"op":"mcm","clk":"11795977735","pt":1722604361174,"mc":[{"id":"1.231282404","rc":[{"batb":[[0,1.9,73.14],[1,1.74,17.32],[2,1.51,1]],"ltp":2.22,"tv":392.98,"id":19144239}]}]}
{"op":"mcm","clk":"11795994571","pt":1722604585631,"mc":[{"id":"1.231282404","rc":[{"batl":[[0,1.9,32.86]],"ltp":1.82,"tv":53352.29,"id":58385184},{"batb":[[0,1.91,10],[1,1.9,73.14],[2,1.74,17.32]],"ltp":2.22,"tv":392.98,"id":19144239}]}]}
{"op":"mcm","clk":"11795994801","pt":1722604589144,"mc":[{"id":"1.231282404","rc":[{"batb":[[0,1.9,73.14],[1,1.74,17.32],[2,1.51,1]],"ltp":2.22,"tv":392.98,"id":19144239}]}]}
{"op":"mcm","clk":"11796013124","pt":1722604822232,"mc":[{"id":"1.231282404","rc":[{"batb":[[0,1.91,10],[1,1.9,73.14],[2,1.74,17.32]],"ltp":2.22,"tv":392.98,"id":19144239}]}]}
{"op":"mcm","clk":"11796013504","pt":1722604827020,"mc":[{"id":"1.231282404","rc":[{"batb":[[0,1.9,73.14],[1,1.74,17.32],[2,1.51,1]],"ltp":2.22,"tv":392.98,"id":19144239}]}]}
{"op":"mcm","clk":"11796050743","pt":1722605326696,"mc":[{"id":"1.231282404","rc":[{"batb":[[0,1.91,10],[1,1.9,73.14],[2,1.74,17.32]],"ltp":2.22,"tv":392.98,"id":19144239}]}]}
{"op":"mcm","clk":"11796051175","pt":1722605333139,"mc":[{"id":"1.231282404","rc":[{"batb":[[0,1.9,73.14],[1,1.74,17.32],[2,1.51,1]],"ltp":2.22,"tv":392.98,"id":19144239}]}]}
{"op":"mcm","clk":"11796051428","pt":1722605336881,"mc":[{"id":"1.231282404","rc":[{"batb":[[0,1.91,10],[1,1.9,73.14],[2,1.74,17.32]],"ltp":2.22,"tv":392.98,"id":19144239}]}]}
{"op":"mcm","clk":"11796051864","pt":1722605342778,"mc":[{"id":"1.231282404","rc":[{"batb":[[0,1.9,73.14],[1,1.74,17.32],[2,1.51,1]],"ltp":2.22,"tv":392.98,"id":19144239}]}]}
{"op":"mcm","clk":"11796052053","pt":1722605344970,"mc":[{"id":"1.231282404","rc":[{"batb":[[0,1.91,10],[1,1.9,73.14],[2,1.74,17.32]],"ltp":2.22,"tv":392.98,"id":19144239}]}]}
{"op":"mcm","clk":"11796052474","pt":1722605350783,"mc":[{"id":"1.231282404","rc":[{"batb":[[0,1.9,73.14],[1,1.74,17.32],[2,1.51,1]],"ltp":2.22,"tv":392.98,"id":19144239}]}]}
{"op":"mcm","clk":"11796052700","pt":1722605354307,"mc":[{"id":"1.231282404","rc":[{"batb":[[0,1.91,10],[1,1.9,73.14],[2,1.74,17.32]],"ltp":2.22,"tv":392.98,"id":19144239}]}]}
{"op":"mcm","clk":"11796053092","pt":1722605360708,"mc":[{"id":"1.231282404","rc":[{"batb":[[0,1.9,73.14],[1,1.74,17.32],[2,1.51,1]],"ltp":2.22,"tv":392.98,"id":19144239}]}]}
{"op":"mcm","clk":"11796053292","pt":1722605363616,"mc":[{"id":"1.231282404","rc":[{"batb":[[0,1.91,10],[1,1.9,73.14],[2,1.74,17.32]],"ltp":2.22,"tv":392.98,"id":19144239}]}]}
{"op":"mcm","clk":"11796053693","pt":1722605369715,"mc":[{"id":"1.231282404","rc":[{"batb":[[0,1.9,73.14],[1,1.74,17.32],[2,1.51,1]],"ltp":2.22,"tv":392.98,"id":19144239}]}]}
{"op":"mcm","clk":"11796061345","pt":1722605474209,"mc":[{"id":"1.231282404","rc":[{"batb":[[2,1.73,41]],"ltp":1.82,"tv":53352.29,"id":58385184},{"batb":[[0,1.91,10],[1,1.9,73.14],[2,1.74,17.32]],"ltp":2.22,"tv":392.98,"id":19144239}]}]}
{"op":"mcm","clk":"11796061607","pt":1722605477625,"mc":[{"id":"1.231282404","rc":[{"batb":[[0,1.9,73.14],[1,1.74,17.32],[2,1.51,1]],"ltp":2.22,"tv":392.98,"id":19144239}]}]}
{"op":"mcm","clk":"11796081593","pt":1722605729367,"mc":[{"id":"1.231282404","rc":[{"batb":[[0,1.91,10],[1,1.9,73.14],[2,1.74,17.32]],"ltp":2.22,"tv":392.98,"id":19144239}]}]}
{"op":"mcm","clk":"11796081936","pt":1722605733588,"mc":[{"id":"1.231282404","rc":[{"batb":[[0,1.9,73.14],[1,1.74,17.32],[2,1.51,1]],"ltp":2.22,"tv":392.98,"id":19144239}]}]}
{"op":"mcm","clk":"11796096110","pt":1722605914829,"mc":[{"id":"1.231282404","rc":[{"batb":[[0,1.91,10],[1,1.9,73.14],[2,1.74,17.32]],"ltp":2.22,"tv":392.98,"id":19144239}]}]}
{"op":"mcm","clk":"11796096451","pt":1722605919246,"mc":[{"id":"1.231282404","rc":[{"batb":[[0,1.9,73.14],[1,1.74,17.32],[2,1.51,1]],"ltp":2.22,"tv":392.98,"id":19144239}]}]}
{"op":"mcm","clk":"11796100586","pt":1722605969112,"mc":[{"id":"1.231282404","rc":[{"batb":[[0,1.91,10],[1,1.9,73.14],[2,1.74,17.32]],"ltp":2.22,"tv":392.98,"id":19144239}]}]}
{"op":"mcm","clk":"11796101212","pt":1722605977212,"mc":[{"id":"1.231282404","rc":[{"batb":[[0,1.9,73.14],[1,1.74,17.32],[2,1.51,1]],"ltp":2.22,"tv":392.98,"id":19144239}]}]}
{"op":"mcm","clk":"11796101560","pt":1722605981406,"mc":[{"id":"1.231282404","rc":[{"batb":[[0,1.91,10],[1,1.9,73.14],[2,1.74,17.32]],"ltp":2.22,"tv":392.98,"id":19144239}]}]}
{"op":"mcm","clk":"11796101995","pt":1722605987330,"mc":[{"id":"1.231282404","rc":[{"batb":[[0,1.9,73.14],[1,1.74,17.32],[2,1.51,1]],"ltp":2.22,"tv":392.98,"id":19144239}]}]}
{"op":"mcm","clk":"11796102759","pt":1722605997523,"mc":[{"id":"1.231282404","rc":[{"batb":[[0,1.81,53.28]],"ltp":1.82,"tv":53352.29,"id":58385184}]}]}
{"op":"mcm","clk":"11796102880","pt":1722605999348,"mc":[{"id":"1.231282404","rc":[{"batb":[[0,1.91,10],[1,1.9,73.14],[2,1.74,17.32]],"ltp":2.22,"tv":392.98,"id":19144239}]}]}
{"op":"mcm","clk":"11796103188","pt":1722606003542,"mc":[{"id":"1.231282404","rc":[{"batb":[[0,1.9,73.14],[1,1.74,17.32],[2,1.51,1]],"ltp":2.22,"tv":392.98,"id":19144239}]}]}
{"op":"mcm","clk":"11796104962","pt":1722606026474,"mc":[{"id":"1.231282404","rc":[{"batb":[[1,1.75,129.83],[2,1.74,17.32]],"ltp":1.82,"tv":53352.29,"id":58385184}]}]}
{"op":"mcm","clk":"11796105063","pt":1722606027669,"mc":[{"id":"1.231282404","rc":[{"batb":[[0,1.91,10],[1,1.9,73.14],[2,1.74,17.32]],"ltp":2.22,"tv":392.98,"id":19144239}]}]}
{"op":"mcm","clk":"11796105228","pt":1722606029956,"mc":[{"id":"1.231282404","rc":[{"batb":[[0,1.9,73.14],[1,1.74,17.32],[2,1.51,1]],"ltp":2.22,"tv":392.98,"id":19144239}]}]}
{"op":"mcm","clk":"11796105771","pt":1722606037664,"mc":[{"id":"1.231282404","rc":[{"batb":[[0,1.91,10],[1,1.9,73.14],[2,1.74,17.32]],"ltp":2.22,"tv":392.98,"id":19144239}]}]}
{"op":"mcm","clk":"11796106092","pt":1722606041160,"mc":[{"id":"1.231282404","rc":[{"batb":[[0,1.9,73.14],[1,1.74,17.32],[2,1.51,1]],"ltp":2.22,"tv":392.98,"id":19144239}]}]}
{"op":"mcm","clk":"11796108000","pt":1722606066101,"mc":[{"id":"1.231282404","rc":[{"batb":[[0,1.81,53.4]],"ltp":1.82,"tv":53352.29,"id":58385184},{"batb":[[0,1.91,10],[1,1.9,73.14],[2,1.74,17.32]],"ltp":2.22,"tv":392.98,"id":19144239}]}]}
{"op":"mcm","clk":"11796108231","pt":1722606069610,"mc":[{"id":"1.231282404","rc":[{"batb":[[0,1.9,73.14],[1,1.74,17.32],[2,1.51,1]],"ltp":2.22,"tv":392.98,"id":19144239}]}]}
{"op":"mcm","clk":"11796126374","pt":1722606366219,"mc":[{"id":"1.231282404","rc":[{"batb":[[0,1.81,53.46]],"ltp":1.82,"tv":53352.29,"id":58385184},{"batb":[[0,1.91,10],[1,1.9,73.14],[2,1.74,17.32]],"ltp":2.22,"tv":392.98,"id":19144239}]}]}
{"op":"mcm","clk":"11796126572","pt":1722606369604,"mc":[{"id":"1.231282404","rc":[{"batb":[[0,1.9,73.14],[1,1.74,17.32],[2,1.51,1]],"ltp":2.22,"tv":392.98,"id":19144239}]}]}
{"op":"mcm","clk":"11796146126","pt":1722606639360,"mc":[{"id":"1.231282404","rc":[{"batb":[[0,1.91,10],[1,1.9,73.14],[2,1.74,17.32]],"ltp":2.22,"tv":392.98,"id":19144239}]}]}
{"op":"mcm","clk":"11796146477","pt":1722606644688,"mc":[{"id":"1.231282404","rc":[{"batb":[[0,1.9,73.14],[1,1.74,17.32],[2,1.51,1]],"ltp":2.22,"tv":392.98,"id":19144239}]}]}
{"op":"mcm","clk":"11796148159","pt":1722606666296,"mc":[{"id":"1.231282404","rc":[{"batb":[[0,1.81,53.52]],"ltp":1.82,"tv":53352.29,"id":58385184}]}]}
{"op":"mcm","clk":"11796148214","pt":1722606667075,"mc":[{"id":"1.231282404","rc":[{"batb":[[0,1.91,10],[1,1.9,73.14],[2,1.74,17.32]],"ltp":2.22,"tv":392.98,"id":19144239}]}]}
{"op":"mcm","clk":"11796148467","pt":1722606670899,"mc":[{"id":"1.231282404","rc":[{"batb":[[0,1.9,73.14],[1,1.74,17.32],[2,1.51,1]],"ltp":2.22,"tv":392.98,"id":19144239}]}]}
{"op":"mcm","clk":"11796154697","pt":1722606761297,"mc":[{"id":"1.231282404","rc":[{"batl":[[1,1.95,50.85],[2,6,1.56]],"ltp":1.82,"tv":53352.29,"id":58385184}]}]}
{"op":"mcm","clk":"11796154758","pt":1722606761977,"mc":[{"id":"1.231282404","rc":[{"batl":[[0,1.9,16.72]],"ltp":1.82,"tv":53352.29,"id":58385184}]}]}
{"op":"mcm","clk":"11796154864","pt":1722606763577,"mc":[{"id":"1.231282404","rc":[{"batl":[[0,1.95,50.85],[1,6,1.56],[2,12,1.56]],"ltp":1.82,"tv":53352.29,"id":58385184},{"batb":[[0,1.91,10],[1,1.9,73.14],[2,1.74,17.32]],"ltp":2.22,"tv":392.98,"id":19144239}]}]}
{"op":"mcm","clk":"11796155141","pt":1722606767307,"mc":[{"id":"1.231282404","rc":[{"batb":[[0,1.9,73.14],[1,1.74,17.32],[2,1.51,1]],"ltp":2.22,"tv":392.98,"id":19144239}]}]}
{"op":"mcm","clk":"11796161220","pt":1722606855677,"mc":[{"id":"1.231282404","rc":[{"batl":[[0,6,1.56],[1,12,1.56],[2,12,0]],"ltp":1.82,"tv":53352.29,"id":58385184}]}]}
{"op":"mcm","clk":"11796161297","pt":1722606856657,"mc":[{"id":"1.231282404","rc":[{"batb":[[0,1.82,10.24],[1,1.81,53.28],[2,1.75,129.83]],"ltp":1.82,"tv":53352.29,"id":58385184},{"batb":[[0,1.91,43.71],[1,1.9,73.14],[2,1.74,17.32]],"ltp":2.22,"tv":392.98,"id":19144239}]}]}
{"op":"mcm","clk":"11796161573","pt":1722606860361,"mc":[{"id":"1.231282404","rc":[{"batb":[[0,1.81,53.52],[1,1.75,129.83],[2,1.74,17.32]],"ltp":1.82,"tv":53352.29,"id":58385184},{"batb":[[0,1.91,33.71]],"ltp":2.22,"tv":392.98,"id":19144239}]}]}
{"op":"mcm","clk":"11796167889","pt":1722606966088,"mc":[{"id":"1.231282404","rc":[{"batb":[[0,1.81,53.58]],"ltp":1.82,"tv":53352.29,"id":58385184}]}]}
{"op":"mcm","clk":"11796167951","pt":1722606967173,"mc":[{"id":"1.231282404","rc":[{"batb":[[0,1.82,10.3],[1,1.81,53.28],[2,1.75,129.83]],"ltp":1.82,"tv":53352.29,"id":58385184},{"batb":[[0,1.92,10],[1,1.91,33.71],[2,1.9,73.14]],"ltp":2.22,"tv":392.98,"id":19144239}]}]}
{"op":"mcm","clk":"11796168215","pt":1722606970990,"mc":[{"id":"1.231282404","rc":[{"batb":[[0,1.81,53.58],[1,1.75,129.83],[2,1.74,17.32]],"ltp":1.82,"tv":53352.29,"id":58385184},{"batb":[[0,1.91,33.71],[1,1.9,73.14],[2,1.74,17.32]],"ltp":2.22,"tv":392.98,"id":19144239}]}]}
{"op":"mcm","clk":"11796169605","pt":1722606991609,"mc":[{"id":"1.231282404","rc":[{"batb":[[0,1.94,100],[1,1.91,33.71],[2,1.9,73.14]],"ltp":2.22,"tv":392.98,"id":19144239}]}]}
{"op":"mcm","clk":"11796169612","pt":1722606991711,"mc":[{"id":"1.231282404","rc":[{"batb":[[0,1.82,10.3],[1,1.81,53.28],[2,1.75,129.83]],"ltp":1.82,"tv":53352.29,"id":58385184},{"batb":[[0,1.95,10],[1,1.94,100],[2,1.91,33.71]],"ltp":2.22,"tv":392.98,"id":19144239}]}]}
{"op":"mcm","clk":"11796169869","pt":1722606995030,"mc":[{"id":"1.231282404","rc":[{"batb":[[0,1.81,53.58],[1,1.75,129.83],[2,1.74,17.32]],"ltp":1.82,"tv":53352.29,"id":58385184},{"batb":[[0,1.94,100],[1,1.91,33.71],[2,1.9,73.14]],"ltp":2.22,"tv":392.98,"id":19144239}]}]}
{"op":"mcm","clk":"11796170060","pt":1722606997215,"mc":[{"id":"1.231282404","rc":[{"batb":[[0,1.82,10.3],[1,1.81,53.28],[2,1.75,129.83]],"ltp":1.82,"tv":53352.29,"id":58385184},{"batb":[[0,1.95,10],[1,1.94,100],[2,1.91,33.71]],"ltp":2.22,"tv":392.98,"id":19144239}]}]}
{"op":"mcm","clk":"11796170451","pt":1722607002018,"mc":[{"id":"1.231282404","rc":[{"batb":[[0,1.81,53.58],[1,1.75,129.83],[2,1.74,17.32]],"ltp":1.82,"tv":53352.29,"id":58385184},{"batb":[[0,1.94,100],[1,1.9,73.14],[2,1.74,17.32]],"ltp":2.22,"tv":392.98,"id":19144239}]}]}
{"op":"mcm","clk":"11796170893","pt":1722607008041,"mc":[{"id":"1.231282404","rc":[{"batb":[[0,1.82,10.3],[1,1.81,53.28],[2,1.75,129.83]],"ltp":1.82,"tv":53352.29,"id":58385184},{"batb":[[0,1.92,100],[1,1.91,43.71],[2,1.9,73.14]],"ltp":2.22,"tv":392.98,"id":19144239}]}]}
{"op":"mcm","clk":"11796171117","pt":1722607011247,"mc":[{"id":"1.231282404","rc":[{"batb":[[0,1.81,53.58],[1,1.75,129.83],[2,1.74,17.32]],"ltp":1.82,"tv":53352.29,"id":58385184},{"batb":[[1,1.91,33.71]],"ltp":2.22,"tv":392.98,"id":19144239}]}]}
{"op":"mcm","clk":"11796173110","pt":1722607039964,"mc":[{"id":"1.231282404","rc":[{"batb":[[0,1.82,10.3],[1,1.81,53.28],[2,1.75,129.83]],"batl":[[0,2.08,8.88],[1,6,1.56],[2,12,1.56]],"ltp":1.82,"tv":53352.29,"id":58385184},{"batb":[[0,1.93,10],[1,1.92,100]],"ltp":2.22,"tv":392.98,"id":19144239}]}]}
{"op":"mcm","clk":"11796173303","pt":1722607043282,"mc":[{"id":"1.231282404","rc":[{"batb":[[0,1.81,53.58],[1,1.75,129.83],[2,1.74,17.32]],"ltp":1.82,"tv":53352.29,"id":58385184},{"batb":[[0,1.92,100],[1,1.9,73.14],[2,1.74,17.32]],"ltp":2.22,"tv":392.98,"id":19144239}]}]}
{"op":"mcm","clk":"11796176089","pt":1722607084593,"mc":[{"id":"1.231282404","rc":[{"batb":[[1,1.76,9.09],[2,1.75,129.83]],"ltp":1.82,"tv":53352.29,"id":58385184},{"batb":[[0,2.02,7.92],[1,1.92,100],[2,1.9,73.14]],"ltp":2.22,"tv":392.98,"id":19144239}]}]}
{"op":"mcm","clk":"11796176100","pt":1722607084703,"mc":[{"id":"1.231282404","rc":[{"batb":[[0,1.82,10.3],[1,1.81,53.28],[2,1.76,9.09]],"ltp":1.82,"tv":53352.29,"id":58385184},{"batb":[[0,2.04,10],[1,2.02,7.92],[2,1.92,100]],"ltp":2.22,"tv":392.98,"id":19144239}]}]}
{"op":"mcm","clk":"11796176324","pt":1722607088311,"mc":[{"id":"1.231282404","rc":[{"batb":[[0,1.81,53.58],[1,1.76,9.09],[2,1.75,129.83]],"batl":[[0,6,1.56],[1,12,1.56],[2,12,0]],"ltp":1.82,"tv":53352.29,"id":58385184},{"batb":[[0,2.02,7.92],[1,1.92,100],[2,1.9,73.14]],"ltp":2.22,"tv":392.98,"id":19144239}]}]}
{"op":"mcm","clk":"11796177478","pt":1722607104517,"mc":[{"id":"1.231282404","rc":[{"batl":[[0,2,40],[1,6,1.56],[2,12,1.56]],"ltp":1.82,"tv":53352.29,"id":58385184}]}]}
{"op":"mcm","clk":"11796177528","pt":1722607105231,"mc":[{"id":"1.231282404","rc":[{"batb":[[0,1.82,10.3],[1,1.81,53.28],[2,1.76,9.09]],"ltp":1.82,"tv":53352.29,"id":58385184},{"batb":[[0,2.04,10],[1,2.02,7.92],[2,1.92,100]],"ltp":2.22,"tv":392.98,"id":19144239}]}]}
{"op":"mcm","clk":"11796177784","pt":1722607108639,"mc":[{"id":"1.231282404","rc":[{"batb":[[0,1.81,53.58],[1,1.76,9.09],[2,1.75,129.83]],"ltp":1.82,"tv":53352.29,"id":58385184},{"batb":[[0,2.02,7.92],[1,1.92,100],[2,1.9,73.14]],"ltp":2.22,"tv":392.98,"id":19144239}]}]}
{"op":"mcm","clk":"11796185144","pt":1722607212112,"mc":[{"id":"1.231282404","rc":[{"trd":[[1.82,115.61],[1.89,689.66],[1.9,8800.57],[1.91,2447.92],[1.92,15236.33],[1.95,6877.23],[1.96,18931.79]],"batb":[[0,1.82,10.3],[1,1.81,53.28],[2,1.76,9.09]],"batl":[[1,6,1.56],[2,12,1.56]],"ltp":1.82,"tv":53292.04,"id":58385184},{"trd":[[2.1,30.1],[2.22,20.08]],"batb":[[0,2.04,10],[1,2.02,7.91],[2,1.92,100]],"batl":[[0,6,1.56],[1,12,1.56]],"ltp":2.22,"tv":392.96,"id":19144239}],"tv":53685.0}]}
{"op":"mcm","clk":"11796185509","pt":1722607216345,"mc":[{"id":"1.231282404","rc":[{"batb":[[0,1.81,53.58],[1,1.76,9.09],[2,1.75,129.83]],"ltp":1.82,"tv":53292.04,"id":58385184},{"batb":[[0,2.02,7.91],[1,1.92,100],[2,1.9,72.97]],"ltp":2.22,"tv":392.96,"id":19144239}]}]}
{"op":"mcm","clk":"11796186163","pt":1722607223547,"mc":[{"id":"1.231282404","rc":[{"batb":[[1,1.9,72.97],[2,1.85,100]],"ltp":2.22,"tv":392.96,"id":19144239}]}]}
{"op":"mcm","clk":"11796186353","pt":1722607225423,"mc":[{"id":"1.231282404","rc":[{"batb":[[0,1.82,10.3],[1,1.81,53.28],[2,1.76,9.09]],"ltp":1.82,"tv":53292.04,"id":58385184},{"batb":[[0,2.04,10],[1,2.02,7.91],[2,1.9,72.97]],"ltp":2.22,"tv":392.96,"id":19144239}]}]}
{"op":"mcm","clk":"11796186804","pt":1722607230632,"mc":[{"id":"1.231282404","rc":[{"batb":[[0,1.81,53.58],[1,1.76,9.09],[2,1.75,129.83]],"ltp":1.82,"tv":53292.04,"id":58385184},{"batb":[[0,2.02,7.91],[1,1.9,72.97],[2,1.85,100]],"ltp":2.22,"tv":392.96,"id":19144239}]}]}
{"op":"mcm","clk":"11796187132","pt":1722607234543,"mc":[{"id":"1.231282404","rc":[{"batb":[[0,1.82,10.3],[1,1.81,53.28],[2,1.76,9.09]],"ltp":1.82,"tv":53292.04,"id":58385184},{"batb":[[0,2.04,10],[1,2.02,7.91],[2,1.9,72.97]],"ltp":2.22,"tv":392.96,"id":19144239}]}]}
{"op":"mcm","clk":"11796187429","pt":1722607237871,"mc":[{"id":"1.231282404","rc":[{"batb":[[0,1.81,53.58],[1,1.76,9.09],[2,1.75,129.83]],"ltp":1.82,"tv":53292.04,"id":58385184},{"batb":[[0,2.02,7.91],[1,1.9,72.97],[2,1.85,100]],"ltp":2.22,"tv":392.96,"id":19144239}]}]}
{"op":"mcm","clk":"11796189636","pt":1722607266194,"mc":[{"id":"1.231282404","rc":[{"batb":[[0,1.82,10.36],[1,1.81,53.28],[2,1.76,9.09]],"ltp":1.82,"tv":53292.04,"id":58385184},{"batb":[[0,2.04,10],[1,2.02,7.91],[2,1.9,72.97]],"ltp":2.22,"tv":392.96,"id":19144239}]}]}
{"op":"mcm","clk":"11796189908","pt":1722607269365,"mc":[{"id":"1.231282404","rc":[{"batb":[[0,1.81,53.64],[1,1.76,9.09],[2,1.75,129.83]],"ltp":1.82,"tv":53292.04,"id":58385184},{"batb":[[0,2.02,7.91],[1,1.9,72.97],[2,1.85,100]],"ltp":2.22,"tv":392.96,"id":19144239}]}]}
{"op":"mcm","clk":"11796190095","pt":1722607271693,"mc":[{"id":"1.231282404","rc":[{"batb":[[0,1.82,10.36],[1,1.81,53.28],[2,1.76,9.09]],"ltp":1.82,"tv":53292.04,"id":58385184},{"batb":[[0,2.04,10],[1,2.02,7.91],[2,1.9,72.97]],"ltp":2.22,"tv":392.96,"id":19144239}]}]}
{"op":"mcm","clk":"11796190486","pt":1722607276267,"mc":[{"id":"1.231282404","rc":[{"batb":[[0,1.81,53.64],[1,1.76,9.09],[2,1.75,129.83]],"ltp":1.82,"tv":53292.04,"id":58385184},{"batb":[[0,2.02,7.91],[1,1.9,72.97],[2,1.85,100]],"ltp":2.22,"tv":392.96,"id":19144239}]}]}
{"op":"mcm","clk":"11796195252","pt":1722607343915,"mc":[{"id":"1.231282404","rc":[{"batb":[[0,1.82,10.36],[1,1.81,53.28],[2,1.76,9.09]],"ltp":1.82,"tv":53292.04,"id":58385184},{"batb":[[0,2.04,10],[1,2.02,7.91],[2,1.9,72.97]],"ltp":2.22,"tv":392.96,"id":19144239}]}]}
{"op":"mcm","clk":"11796195679","pt":1722607347836,"mc":[{"id":"1.231282404","rc":[{"batb":[[0,1.81,53.64],[1,1.76,9.09],[2,1.75,129.83]],"ltp":1.82,"tv":53292.04,"id":58385184},{"batb":[[0,2.02,7.91],[1,1.9,72.97],[2,1.85,100]],"ltp":2.22,"tv":392.96,"id":19144239}]}]}
{"op":"mcm","clk":"11796195943","pt":1722607351320,"mc":[{"id":"1.231282404","rc":[{"batb":[[0,1.82,10.36],[1,1.81,53.28],[2,1.76,9.09]],"ltp":1.82,"tv":53292.04,"id":58385184},{"batb":[[0,2.04,10],[1,2.02,7.91],[2,1.9,72.97]],"ltp":2.22,"tv":392.96,"id":19144239}]}]}
{"op":"mcm","clk":"11796196343","pt":1722607356732,"mc":[{"id":"1.231282404","rc":[{"batb":[[0,1.81,53.64],[1,1.76,9.09],[2,1.75,129.83]],"ltp":1.82,"tv":53292.04,"id":58385184},{"batb":[[0,2.02,7.91],[1,1.9,72.97],[2,1.85,100]],"ltp":2.22,"tv":392.96,"id":19144239}]}]}
{"op":"mcm","clk":"11796211604","pt":1722607566262,"mc":[{"id":"1.231282404","rc":[{"batb":[[0,1.82,10.42],[1,1.81,53.28],[2,1.76,9.09]],"ltp":1.82,"tv":53292.04,"id":58385184},{"batb":[[0,2.04,10],[1,2.02,7.91],[2,1.9,72.97]],"ltp":2.22,"tv":392.96,"id":19144239}]}]}
{"op":"mcm","clk":"11796211799","pt":1722607569563,"mc":[{"id":"1.231282404","rc":[{"batb":[[0,1.81,53.7],[1,1.76,9.09],[2,1.75,129.83]],"ltp":1.82,"tv":53292.04,"id":58385184},{"batb":[[0,2.02,7.91],[1,1.9,72.97],[2,1.85,100]],"ltp":2.22,"tv":392.96,"id":19144239}]}]}
{"op":"mcm","clk":"11796217173","pt":1722607644337,"mc":[{"id":"1.231282404","rc":[{"batl":[[0,1.98,18.04],[1,2,40],[2,6,1.56]],"ltp":1.82,"tv":53292.04,"id":58385184},{"batb":[[0,2.04,10],[1,2.02,7.91],[2,1.9,72.97]],"ltp":2.22,"tv":392.96,"id":19144239}]}]}
{"op":"mcm","clk":"11796217406","pt":1722607647603,"mc":[{"id":"1.231282404","rc":[{"batb":[[0,2.02,7.91],[1,1.9,72.97],[2,1.85,100]],"ltp":2.22,"tv":392.96,"id":19144239}]}]}
{"op":"mcm","clk":"11796218773","pt":1722607668739,"mc":[{"id":"1.231282404","rc":[{"batb":[[0,2.04,10],[1,2.02,7.91],[2,1.9,72.97]],"ltp":2.22,"tv":392.96,"id":19144239}]}]}
{"op":"mcm","clk":"11796218900","pt":1722607670355,"mc":[{"id":"1.231282404","rc":[{"batl":[[0,1.98,34.27]],"ltp":1.82,"tv":53292.04,"id":58385184}]}]}
{"op":"mcm","clk":"11796219099","pt":1722607672834,"mc":[{"id":"1.231282404","rc":[{"batb":[[0,2.02,7.91],[1,1.9,72.97],[2,1.85,100]],"ltp":2.22,"tv":392.96,"id":19144239}]}]}
{"op":"mcm","clk":"11796226968","pt":1722607776672,"mc":[{"id":"1.231282404","rc":[{"trd":[[1.82,116.46]],"batb":[[0,1.81,53.28]],"batl":[[0,1.82,1.13],[1,1.98,34.27],[2,2,40]],"ltp":1.82,"tv":53292.89,"id":58385184}],"tv":53685.85}]}
{"op":"mcm","clk":"11796226977","pt":1722607776785,"mc":[{"id":"1.231282404","rc":[{"batb":[[0,2.04,10],[1,2.02,7.91],[2,1.9,72.97]],"ltp":2.22,"tv":392.96,"id":19144239}]}]}
{"op":"mcm","clk":"11796227108","pt":1722607778286,"mc":[{"id":"1.231282404","rc":[{"batb":[[0,1.81,57.28]],"ltp":1.82,"tv":53292.89,"id":58385184}]}]}
{"op":"mcm","clk":"11796227254","pt":1722607780159,"mc":[{"id":"1.231282404","rc":[{"batb":[[0,2.02,7.91],[1,1.9,72.97],[2,1.85,100]],"ltp":2.22,"tv":392.96,"id":19144239}]}]}
{"op":"mcm","clk":"11796229060","pt":1722607802403,"mc":[{"id":"1.231282404","rc":[{"batl":[[0,1.98,34.27],[1,2,40],[2,6,1.56]],"ltp":1.82,"tv":53292.89,"id":58385184}]}]}
{"op":"mcm","clk":"11796229114","pt":1722607802989,"mc":[{"id":"1.231282404","rc":[{"batb":[[0,2.04,10],[1,2.02,7.91],[2,1.9,72.97]],"ltp":2.22,"tv":392.96,"id":19144239}]}]}
{"op":"mcm","clk":"11796229422","pt":1722607806489,"mc":[{"id":"1.231282404","rc":[{"trd":[[2.04,58.72]],"batb":[[0,2.02,7.91],[1,1.9,72.97],[2,1.85,100]],"ltp":2.04,"tv":393.72,"id":19144239}],"tv":53686.61}]}
{"op":"mcm","clk":"11796233234","pt":1722607853455,"mc":[{"id":"1.231282404","rc":[{"batb":[[0,1.96,1.56],[1,1.81,57.28],[2,1.76,9.09]],"ltp":1.82,"tv":53292.89,"id":58385184},{"batb":[[0,2.04,10],[1,2.02,7.91],[2,1.9,72.97]],"ltp":2.04,"tv":393.72,"id":19144239}]}]}
{"op":"mcm","clk":"11796233487","pt":1722607856636,"mc":[{"id":"1.231282404","rc":[{"batb":[[0,2.02,7.91],[1,1.9,72.97],[2,1.85,100]],"ltp":2.04,"tv":393.72,"id":19144239}]}]}
{"op":"mcm","clk":"11796233717","pt":1722607859551,"mc":[{"id":"1.231282404","rc":[{"batb":[[0,2.04,10],[1,2.02,7.91],[2,1.9,72.97]],"ltp":2.04,"tv":393.72,"id":19144239}]}]}
{"op":"mcm","clk":"11796234304","pt":1722607866634,"mc":[{"id":"1.231282404","rc":[{"trd":[[1.96,18935.03]],"batb":[[0,1.81,57.28],[1,1.76,9.09],[2,1.75,129.83]],"batl":[[0,1.98,34.45]],"ltp":1.96,"tv":53296.13,"id":58385184},{"batb":[[0,2.02,7.91],[1,1.9,72.97],[2,1.85,100]],"ltp":2.04,"tv":393.72,"id":19144239}],"tv":53689.85}]}
{"op":"mcm","clk":"11796235583","pt":1722607881372,"mc":[{"id":"1.231282404","rc":[{"trd":[[1.81,15.74]],"batb":[[0,1.81,55.6]],"ltp":1.81,"tv":53299.49,"id":58385184}],"tv":53693.22}]}
{"op":"mcm","clk":"11796235753","pt":1722607883182,"mc":[{"id":"1.231282404","rc":[{"batb":[[0,2.04,10],[1,2.02,7.91],[2,1.9,72.97]],"ltp":2.04,"tv":393.72,"id":19144239}]}]}
{"op":"mcm","clk":"11796235889","pt":1722607884488,"mc":[{"id":"1.231282404","rc":[{"batb":[[0,1.83,1.62],[1,1.81,55.6],[2,1.76,9.09]],"ltp":1.81,"tv":53299.49,"id":58385184}]}]}
{"op":"mcm","clk":"11796236068","pt":1722607886463,"mc":[{"id":"1.231282404","rc":[{"batb":[[1,1.81,57.28]],"ltp":1.81,"tv":53299.49,"id":58385184}]}]}
{"op":"mcm","clk":"11796236190","pt":1722607887868,"mc":[{"id":"1.231282404","rc":[{"batb":[[0,2.02,7.91],[1,1.9,72.97],[2,1.85,100]],"ltp":2.04,"tv":393.72,"id":19144239}]}]}
{"op":"mcm","clk":"11796255741","pt":1722607985974,"mc":[{"id":"1.231282404","rc":[{"batl":[[0,1.84,1.56],[1,1.98,34.45],[2,2,40]],"ltp":1.81,"tv":53299.49,"id":58385184},{"batb":[[0,2.04,10],[1,2.02,7.91],[2,1.9,72.97]],"ltp":2.04,"tv":393.72,"id":19144239}]}]}
{"op":"mcm","clk":"11796255966","pt":1722607989498,"mc":[{"id":"1.231282404","rc":[{"batb":[[0,2.02,7.91],[1,1.9,72.97],[2,1.85,100]],"batl":[[0,2.22,4],[1,6,1.56],[2,12,1.56]],"ltp":2.04,"tv":393.72,"id":19144239}]}]}
{"op":"mcm","clk":"11796256039","pt":1722607990487,"mc":[{"id":"1.231282404","rc":[{"batb":[[1,1.82,4.51],[2,1.81,57.28]],"ltp":1.81,"tv":53299.49,"id":58385184}]}]}
{"op":"mcm","clk":"11796256577","pt":1722607998009,"mc":[{"id":"1.231282404","rc":[{"batl":[[0,1.98,34.45],[1,2,40],[2,6,1.56]],"ltp":1.81,"tv":53299.49,"id":58385184},{"batb":[[0,2.04,10],[1,2.02,7.91],[2,1.9,72.97]],"ltp":2.04,"tv":393.72,"id":19144239}]}]}
{"op":"mcm","clk":"11796256820","pt":1722608001423,"mc":[{"id":"1.231282404","rc":[{"batb":[[0,2.02,7.91],[1,1.9,72.97],[2,1.85,100]],"ltp":2.04,"tv":393.72,"id":19144239}]}]}
{"op":"mcm","clk":"11796266391","pt":1722608132769,"mc":[{"id":"1.231282404","rc":[{"batb":[[0,2.04,10],[1,2.02,7.91],[2,1.9,72.97]],"ltp":2.04,"tv":393.72,"id":19144239}]}]}
{"op":"mcm","clk":"11796266825","pt":1722608138086,"mc":[{"id":"1.231282404","rc":[{"batb":[[0,2.02,7.91],[1,1.9,72.97],[2,1.85,100]],"ltp":2.04,"tv":393.72,"id":19144239}]}]}
{"op":"mcm","clk":"11796268530","pt":1722608162127,"mc":[{"id":"1.231282404","rc":[{"batl":[[0,1.95,91.06],[1,1.98,34.45],[2,2,40]],"ltp":1.81,"tv":53299.49,"id":58385184},{"batb":[[0,2.04,10],[1,2.02,7.91],[2,1.9,72.97]],"ltp":2.04,"tv":393.72,"id":19144239}]}]}
{"op":"mcm","clk":"11796268777","pt":1722608165417,"mc":[{"id":"1.231282404","rc":[{"batb":[[0,2.02,7.91],[1,1.9,72.97],[2,1.85,100]],"ltp":2.04,"tv":393.72,"id":19144239}]}]}
{"op":"mcm","clk":"11796268875","pt":1722608166515,"mc":[{"id":"1.231282404","rc":[{"batb":[[0,1.83,1.68]],"ltp":1.81,"tv":53299.49,"id":58385184}]}]}
{"op":"mcm","clk":"11796270761","pt":1722608190221,"mc":[{"id":"1.231282404","rc":[{"batl":[[0,1.98,34.45],[1,2,40],[2,6,1.56]],"ltp":1.81,"tv":53299.49,"id":58385184},{"batb":[[0,2.04,10],[1,2.02,7.91],[2,1.9,72.97]],"ltp":2.04,"tv":393.72,"id":19144239}]}]}
{"op":"mcm","clk":"11796271037","pt":1722608193531,"mc":[{"id":"1.231282404","rc":[{"batb":[[0,2.02,7.91],[1,1.9,72.97],[2,1.85,100]],"ltp":2.04,"tv":393.72,"id":19144239}]}]}
{"op":"mcm","clk":"11796271187","pt":1722608195761,"mc":[{"id":"1.231282404","rc":[{"batb":[[0,2.04,10],[1,2.02,7.91],[2,1.9,72.97]],"ltp":2.04,"tv":393.72,"id":19144239}]}]}
{"op":"mcm","clk":"11796271506","pt":1722608200028,"mc":[{"id":"1.231282404","rc":[{"batb":[[0,2.02,7.91],[1,1.9,72.97],[2,1.85,100]],"ltp":2.04,"tv":393.72,"id":19144239}]}]}
{"op":"mcm","clk":"11796271761","pt":1722608202939,"mc":[{"id":"1.231282404","rc":[{"batb":[[0,2.04,10],[1,2.02,7.91],[2,1.9,72.97]],"ltp":2.04,"tv":393.72,"id":19144239}]}]}
{"op":"mcm","clk":"11796272135","pt":1722608207514,"mc":[{"id":"1.231282404","rc":[{"batb":[[0,2.02,7.91],[1,1.9,72.97],[2,1.85,100]],"ltp":2.04,"tv":393.72,"id":19144239}]}]}
{"op":"mcm","clk":"11796293374","pt":1722608466916,"mc":[{"id":"1.231282404","rc":[{"batb":[[0,1.83,1.8]],"ltp":1.81,"tv":53299.49,"id":58385184},{"batb":[[0,2.04,10],[1,2.02,7.91],[2,1.9,72.97]],"ltp":2.04,"tv":393.72,"id":19144239}]}]}
{"op":"mcm","clk":"11796293666","pt":1722608470132,"mc":[{"id":"1.231282404","rc":[{"batb":[[0,2.02,7.91],[1,1.9,72.97],[2,1.85,100]],"ltp":2.04,"tv":393.72,"id":19144239}]}]}
{"op":"mcm","clk":"11796296843","pt":1722608509050,"mc":[{"id":"1.231282404","rc":[{"batb":[[2,1.81,58.92]],"ltp":1.81,"tv":53299.49,"id":58385184},{"batb":[[0,2.04,10],[1,2.02,7.91],[2,1.9,72.97]],"ltp":2.04,"tv":393.72,"id":19144239}]}]}
{"op":"mcm","clk":"11796297113","pt":1722608512492,"mc":[{"id":"1.231282404","rc":[{"batb":[[0,2.02,7.91],[1,1.9,72.97],[2,1.85,100]],"ltp":2.04,"tv":393.72,"id":19144239}]}]}
{"op":"mcm","clk":"11796320102","pt":1722608766604,"mc":[{"id":"1.231282404","rc":[{"batb":[[0,1.83,1.92]],"ltp":1.81,"tv":53299.49,"id":58385184}]}]}
{"op":"mcm","clk":"11796320111","pt":1722608766703,"mc":[{"id":"1.231282404","rc":[{"batb":[[0,2.04,10],[1,2.02,7.91],[2,1.9,72.97]],"ltp":2.04,"tv":393.72,"id":19144239}]}]}
{"op":"mcm","clk":"11796320364","pt":1722608770117,"mc":[{"id":"1.231282404","rc":[{"batb":[[0,2.02,7.91],[1,1.9,72.97],[2,1.85,100]],"ltp":2.04,"tv":393.72,"id":19144239}]}]}
{"op":"mcm","clk":"11796330246","pt":1722608888489,"mc":[{"id":"1.231282404","rc":[{"trd":[[1.84,0.6]],"batb":[[0,1.82,4.51],[1,1.81,58.92],[2,1.76,9.09]],"batl":[[0,1.83,1.24],[1,1.98,34.45],[2,2,40]],"ltp":1.84,"tv":53300.09,"id":58385184},{"batb":[[0,2.04,10],[1,2.02,7.91],[2,1.9,72.97]],"ltp":2.04,"tv":393.72,"id":19144239}],"tv":53693.82}]}
{"op":"mcm","clk":"11796330526","pt":1722608891797,"mc":[{"id":"1.231282404","rc":[{"batb":[[0,2.02,7.91],[1,1.9,72.97],[2,1.85,100]],"ltp":2.04,"tv":393.72,"id":19144239}]}]}
{"op":"mcm","clk":"11796330805","pt":1722608895286,"mc":[{"id":"1.231282404","rc":[{"batb":[[0,1.82,8.51]],"ltp":1.84,"tv":53300.09,"id":58385184},{"batb":[[0,2.04,10],[1,2.02,7.91],[2,1.9,72.97]],"ltp":2.04,"tv":393.72,"id":19144239}]}]}
{"op":"mcm","clk":"11796331109","pt":1722608898903,"mc":[{"id":"1.231282404","rc":[{"batb":[[0,2.02,7.91],[1,1.9,72.97],[2,1.85,100]],"ltp":2.04,"tv":393.72,"id":19144239}]}]}
{"op":"mcm","clk":"11796333883","pt":1722608932546,"mc":[{"id":"1.231282404","rc":[{"trd":[[1.83,2]],"batl":[[0,1.98,34.69],[1,2,40],[2,6,1.56]],"ltp":1.83,"tv":53302.09,"id":58385184},{"batb":[[0,2.04,10],[1,2.02,7.91],[2,1.9,72.97]],"ltp":2.04,"tv":393.72,"id":19144239}],"tv":53695.82}]}
{"op":"mcm","clk":"11796334142","pt":1722608935861,"mc":[{"id":"1.231282404","rc":[{"batb":[[0,2.02,7.91],[1,1.9,72.97],[2,1.85,100]],"ltp":2.04,"tv":393.72,"id":19144239}]}]}
{"op":"mcm","clk":"11796344903","pt":1722609065909,"mc":[{"id":"1.231282404","rc":[{"trd":[[1.83,2.24]],"batl":[[0,1.98,34.57]],"ltp":1.83,"tv":53302.33,"id":58385184},{"batb":[[0,2.04,10],[1,2.02,7.91],[2,1.9,72.97]],"ltp":2.04,"tv":393.72,"id":19144239}],"tv":53696.06}]}
{"op":"mcm","clk":"11796345179","pt":1722609069329,"mc":[{"id":"1.231282404","rc":[{"batb":[[0,2.02,7.91],[1,1.9,72.97],[2,1.85,100]],"ltp":2.04,"tv":393.72,"id":19144239}]}]}
{"op":"mcm","clk":"11796350979","pt":1722609145591,"mc":[{"id":"1.231282404","rc":[{"batl":[[0,1.98,34.45]],"ltp":1.83,"tv":53302.33,"id":58385184}]}]}
{"op":"mcm","clk":"11796350992","pt":1722609145789,"mc":[{"id":"1.231282404","rc":[{"batb":[[0,2.04,10],[1,2.02,7.91],[2,1.9,72.97]],"ltp":2.04,"tv":393.72,"id":19144239}]}]}
{"op":"mcm","clk":"11796351245","pt":1722609149103,"mc":[{"id":"1.231282404","rc":[{"batb":[[0,2.02,7.91],[1,1.9,72.97],[2,1.85,100]],"ltp":2.04,"tv":393.72,"id":19144239}]}]}
{"op":"mcm","clk":"11796368344","pt":1722609366202,"mc":[{"id":"1.231282404","rc":[{"batb":[[0,1.82,8.63]],"ltp":1.83,"tv":53302.33,"id":58385184},{"batb":[[0,2.04,10],[1,2.02,7.91],[2,1.9,72.97]],"ltp":2.04,"tv":393.72,"id":19144239}]}]}
{"op":"mcm","clk":"11796368623","pt":1722609369654,"mc":[{"id":"1.231282404","rc":[{"batb":[[0,2.02,7.91],[1,1.9,72.97],[2,1.85,100]],"ltp":2.04,"tv":393.72,"id":19144239}]}]}
{"op":"mcm","clk":"11796374171","pt":1722609446665,"mc":[{"id":"1.231282404","rc":[{"batl":[[0,1.97,89.8],[1,1.98,34.27],[2,2,40]],"ltp":1.83,"tv":53302.33,"id":58385184},{"batb":[[0,2.04,10],[1,2.02,7.91],[2,1.9,72.97]],"ltp":2.04,"tv":393.72,"id":19144239}]}]}
{"op":"mcm","clk":"11796374403","pt":1722609450170,"mc":[{"id":"1.231282404","rc":[{"batb":[[0,2.02,7.91],[1,1.9,72.97],[2,1.85,100]],"ltp":2.04,"tv":393.72,"id":19144239}]}]}
{"op":"mcm","clk":"11796374664","pt":1722609453706,"mc":[{"id":"1.231282404","rc":[{"batl":[[0,1.98,34.45],[1,2,40],[2,6,1.56]],"ltp":1.83,"tv":53302.33,"id":58385184}]}]}
{"op":"mcm","clk":"11796374809","pt":1722609455293,"mc":[{"id":"1.231282404","rc":[{"batb":[[0,2.04,10],[1,2.02,7.91],[2,1.9,72.97]],"ltp":2.04,"tv":393.72,"id":19144239}]}]}
{"op":"mcm","clk":"11796375185","pt":1722609460103,"mc":[{"id":"1.231282404","rc":[{"batb":[[0,2.02,7.91],[1,1.9,72.97],[2,1.85,100]],"ltp":2.04,"tv":393.72,"id":19144239}]}]}
{"op":"mcm","clk":"11796376086","pt":1722609471712,"mc":[{"id":"1.231282404","rc":[{"batl":[[0,1.97,89.8],[1,1.98,34.27],[2,2,40]],"ltp":1.83,"tv":53302.33,"id":58385184}]}]}
{"op":"mcm","clk":"11796376258","pt":1722609473706,"mc":[{"id":"1.231282404","rc":[{"batb":[[0,2.04,10],[1,2.02,7.91],[2,1.9,72.97]],"ltp":2.04,"tv":393.72,"id":19144239}]}]}
{"op":"mcm","clk":"11796376640","pt":1722609478491,"mc":[{"id":"1.231282404","rc":[{"batb":[[0,2.02,7.91],[1,1.9,72.97],[2,1.85,100]],"ltp":2.04,"tv":393.72,"id":19144239}]}]}
{"op":"mcm","clk":"11796376689","pt":1722609479206,"mc":[{"id":"1.231282404","rc":[{"batl":[[0,1.96,6.63],[1,1.97,89.62],[2,1.98,34.27]],"ltp":1.83,"tv":53302.33,"id":58385184}]}]}
{"op":"mcm","clk":"11796378800","pt":1722609510644,"mc":[{"id":"1.231282404","rc":[{"trd":[[1.96,18947.93]],"batl":[[0,1.97,6.27],[1,1.98,34.27],[2,2,40]],"ltp":1.96,"tv":53315.23,"id":58385184},{"batb":[[0,2.04,10],[1,2.02,7.91],[2,1.9,72.97]],"ltp":2.04,"tv":393.72,"id":19144239}],"tv":53708.96}]}
{"op":"mcm","clk":"11796378895","pt":1722609512042,"mc":[{"id":"1.231282404","rc":[{"batb":[[0,1.82,13.43]],"ltp":1.96,"tv":53315.23,"id":58385184}]}]}
{"op":"mcm","clk":"11796379002","pt":1722609514145,"mc":[{"id":"1.231282404","rc":[{"batb":[[0,2.02,7.91],[1,1.9,72.97],[2,1.85,100]],"ltp":2.04,"tv":393.72,"id":19144239}]}]}
{"op":"mcm","clk":"11796379691","pt":1722609524444,"mc":[{"id":"1.231282404","rc":[{"batl":[[0,1.98,34.27],[1,2,40],[2,6,1.56]],"ltp":1.96,"tv":53315.23,"id":58385184}]}]}
{"op":"mcm","clk":"11796379711","pt":1722609524753,"mc":[{"id":"1.231282404","rc":[{"batb":[[0,2.04,10],[1,2.02,7.91],[2,1.9,72.97]],"ltp":2.04,"tv":393.72,"id":19144239}]}]}
{"op":"mcm","clk":"11796379943","pt":1722609528156,"mc":[{"id":"1.231282404","rc":[{"batb":[[0,2.02,7.91],[1,1.9,72.97],[2,1.85,100]],"ltp":2.04,"tv":393.72,"id":19144239}]}]}
{"op":"mcm","clk":"11796385475","pt":1722609614016,"mc":[{"id":"1.231282404","rc":[{"batb":[[0,2.04,10],[1,2.02,7.91],[2,1.9,72.97]],"ltp":2.04,"tv":393.72,"id":19144239}]}]}
{"op":"mcm","clk":"11796385776","pt":1722609617742,"mc":[{"id":"1.231282404","rc":[{"batb":[[0,2.02,7.91],[1,1.9,72.97],[2,1.85,100]],"ltp":2.04,"tv":393.72,"id":19144239}]}]}
{"op":"mcm","clk":"11796388914","pt":1722609666088,"mc":[{"id":"1.231282404","rc":[{"batb":[[0,1.82,13.66]],"ltp":1.96,"tv":53315.23,"id":58385184}]}]}
{"op":"mcm","clk":"11796388986","pt":1722609667181,"mc":[{"id":"1.231282404","rc":[{"batb":[[0,2.04,10],[1,2.02,7.91],[2,1.9,72.97]],"ltp":2.04,"tv":393.72,"id":19144239}]}]}
{"op":"mcm","clk":"11796389234","pt":1722609670890,"mc":[{"id":"1.231282404","rc":[{"batb":[[0,2.02,7.91],[1,1.9,72.97],[2,1.85,100]],"ltp":2.04,"tv":393.72,"id":19144239}]}]}
{"op":"mcm","clk":"11796405842","pt":1722609930564,"mc":[{"id":"1.231282404","rc":[{"batb":[[0,1.83,83.57],[1,1.82,13.31],[2,1.81,58.92]],"ltp":1.96,"tv":53315.23,"id":58385184},{"batb":[[0,2.04,10],[1,2.02,7.91],[2,1.9,72.97]],"ltp":2.04,"tv":393.72,"id":19144239}]}]}
{"op":"mcm","clk":"11796405919","pt":1722609931557,"mc":[{"id":"1.231282404","rc":[{"batb":[[0,1.84,6.88],[1,1.83,83.57],[2,1.82,4]],"ltp":1.96,"tv":53315.23,"id":58385184}]}]}
{"op":"mcm","clk":"11796406088","pt":1722609934043,"mc":[{"id":"1.231282404","rc":[{"batb":[[0,2.02,7.91],[1,1.9,72.97],[2,1.85,100]],"ltp":2.04,"tv":393.72,"id":19144239}]}]}
{"op":"mcm","clk":"11796408032","pt":1722609962289,"mc":[{"id":"1.231282404","rc":[{"batb":[[0,1.84,13.67]],"ltp":1.96,"tv":53315.23,"id":58385184}]}]}
{"op":"mcm","clk":"11796408067","pt":1722609962694,"mc":[{"id":"1.231282404","rc":[{"batb":[[0,2.04,10],[1,2.02,7.91],[2,1.9,72.97]],"ltp":2.04,"tv":393.72,"id":19144239}]}]}
{"op":"mcm","clk":"11796408376","pt":1722609966291,"mc":[{"id":"1.231282404","rc":[{"batb":[[0,1.84,13.73]],"ltp":1.96,"tv":53315.23,"id":58385184},{"batb":[[0,2.02,7.91],[1,1.9,72.97],[2,1.85,100]],"ltp":2.04,"tv":393.72,"id":19144239}]}]}
{"op":"mcm","clk":"11796411118","pt":1722610004242,"mc":[{"id":"1.231282404","rc":[{"trd":[[1.84,27.94],[1.85,0.12]],"batb":[[0,1.83,83.57],[1,1.82,4],[2,1.81,58.92]],"batl":[[0,1.84,76.16],[1,1.98,34.27],[2,2,40]],"ltp":1.84,"tv":53342.69,"id":58385184},{"batb":[[0,2.04,10],[1,2.02,7.91],[2,1.9,72.97]],"ltp":2.04,"tv":393.72,"id":19144239}],"tv":53736.41}]}
{"op":"mcm","clk":"11796411291","pt":1722610006561,"mc":[{"id":"1.231282404","rc":[{"batl":[[0,1.84,82.95]],"ltp":1.84,"tv":53342.69,"id":58385184}]}]}
{"op":"mcm","clk":"11796411367","pt":1722610007554,"mc":[{"id":"1.231282404","rc":[{"batb":[[0,2.02,7.91],[1,1.9,72.97],[2,1.85,100]],"ltp":2.04,"tv":393.72,"id":19144239}]}]}
{"op":"mcm","clk":"11796411719","pt":1722610012088,"mc":[{"id":"1.231282404","rc":[{"batb":[[0,1.83,87.57]],"ltp":1.84,"tv":53342.69,"id":58385184},{"batb":[[0,2.18,4],[1,2.02,7.91],[2,1.9,72.97]],"ltp":2.04,"tv":393.72,"id":19144239}]}]}
{"op":"mcm","clk":"11796412078","pt":1722610016714,"mc":[{"id":"1.231282404","rc":[{"batb":[[1,1.9,72.97],[2,1.85,100]],"ltp":2.04,"tv":393.72,"id":19144239}]}]}
{"op":"mcm","clk":"11796413527","pt":1722610037047,"mc":[{"id":"1.231282404","rc":[{"trd":[[1.83,2.94]],"batb":[[0,1.83,11.41]],"batl":[[0,1.84,6.79]],"ltp":1.83,"tv":53343.39,"id":58385184}],"tv":53737.11}]}
{"op":"mcm","clk":"11796413626","pt":1722610038338,"mc":[{"id":"1.231282404","rc":[{"batb":[[0,1.83,7.41]],"batl":[[0,1.97,6.34]],"ltp":1.83,"tv":53343.39,"id":58385184},{"batb":[[0,1.9,72.97],[1,1.85,100],[2,1.8,200]],"ltp":2.04,"tv":393.72,"id":19144239}]}]}
{"op":"mcm","clk":"11796413663","pt":1722610038952,"mc":[{"id":"1.231282404","rc":[{"batb":[[0,1.91,10],[1,1.9,72.97],[2,1.85,100]],"ltp":2.04,"tv":393.72,"id":19144239}]}]}
{"op":"mcm","clk":"11796413783","pt":1722610040348,"mc":[{"id":"1.231282404","rc":[{"batb":[[0,1.92,40.99],[1,1.91,10],[2,1.9,72.97]],"ltp":2.04,"tv":393.72,"id":19144239}]}]}
{"op":"mcm","clk":"11796413941","pt":1722610042520,"mc":[{"id":"1.231282404","rc":[{"batb":[[1,1.9,72.97],[2,1.85,100]],"ltp":2.04,"tv":393.72,"id":19144239}]}]}
{"op":"mcm","clk":"11796415239","pt":1722610061778,"mc":[{"id":"1.231282404","rc":[{"batb":[[0,1.82,4.65],[1,1.81,58.92],[2,1.75,129.83]],"ltp":1.83,"tv":53343.39,"id":58385184}]}]}
{"op":"mcm","clk":"11796415334","pt":1722610063180,"mc":[{"id":"1.231282404","rc":[{"batb":[[0,1.93,10],[1,1.92,40.99],[2,1.9,72.97]],"ltp":2.04,"tv":393.72,"id":19144239}]}]}
{"op":"mcm","clk":"11796415624","pt":1722610067173,"mc":[{"id":"1.231282404","rc":[{"batb":[[0,1.92,40.99],[1,1.9,72.97],[2,1.85,100]],"ltp":2.04,"tv":393.72,"id":19144239}]}]}
{"op":"mcm","clk":"11796417457","pt":1722610093474,"mc":[{"id":"1.231282404","rc":[{"batl":[[0,1.95,6.41],[1,1.96,18.04],[2,1.98,34.27]],"ltp":1.83,"tv":53343.39,"id":58385184}]}]}
{"op":"mcm","clk":"11796417579","pt":1722610095295,"mc":[{"id":"1.231282404","rc":[{"batb":[[0,1.93,10],[1,1.92,40.99],[2,1.9,72.97]],"ltp":2.04,"tv":393.72,"id":19144239}]}]}
{"op":"mcm","clk":"11796417711","pt":1722610097006,"mc":[{"id":"1.231282404","rc":[{"batl":[[2,1.98,16.23]],"ltp":1.83,"tv":53343.39,"id":58385184}]}]}
{"op":"mcm","clk":"11796417900","pt":1722610099765,"mc":[{"id":"1.231282404","rc":[{"batb":[[0,1.92,40.99],[1,1.9,72.97],[2,1.85,100]],"ltp":2.04,"tv":393.72,"id":19144239}]}]}
{"op":"mcm","clk":"11796419405","pt":1722610118593,"mc":[{"id":"1.231282404","rc":[{"batl":[[0,1.94,16.23],[1,1.95,6.41],[2,1.96,18.04]],"ltp":1.83,"tv":53343.39,"id":58385184}]}]}
{"op":"mcm","clk":"11796419488","pt":1722610119629,"mc":[{"id":"1.231282404","rc":[{"batb":[[0,1.93,10],[1,1.92,40.99],[2,1.9,72.97]],"ltp":2.04,"tv":393.72,"id":19144239}]}]}
{"op":"mcm","clk":"11796419860","pt":1722610124232,"mc":[{"id":"1.231282404","rc":[{"batb":[[0,1.92,40.99],[1,1.9,72.97],[2,1.85,100]],"ltp":2.04,"tv":393.72,"id":19144239}]}]}
{"op":"mcm","clk":"11796430543","pt":1722610266391,"mc":[{"id":"1.231282404","rc":[{"batb":[[0,1.82,4.71]],"ltp":1.83,"tv":53343.39,"id":58385184},{"batb":[[0,1.93,10],[1,1.92,40.99],[2,1.9,72.97]],"ltp":2.04,"tv":393.72,"id":19144239}]}]}
{"op":"mcm","clk":"11796430786","pt":1722610269689,"mc":[{"id":"1.231282404","rc":[{"batb":[[0,1.92,40.99],[1,1.9,72.97],[2,1.85,100]],"ltp":2.04,"tv":393.72,"id":19144239}]}]}
{"op":"mcm","clk":"11796434662","pt":1722610325552,"mc":[{"id":"1.231282404","rc":[{"batb":[[2,1.74,17.32]],"ltp":2.04,"tv":393.72,"id":19144239}]}]}
{"op":"mcm","clk":"11796434739","pt":1722610326781,"mc":[{"id":"1.231282404","rc":[{"batb":[[0,1.93,10],[1,1.92,40.99],[2,1.9,72.97]],"ltp":2.04,"tv":393.72,"id":19144239}]}]}
{"op":"mcm","clk":"11796435014","pt":1722610330755,"mc":[{"id":"1.231282404","rc":[{"batb":[[0,1.92,40.99],[1,1.9,72.97],[2,1.74,17.32]],"ltp":2.04,"tv":393.72,"id":19144239}]}]}
{"op":"mcm","clk":"11796446033","pt":1722610485638,"mc":[{"id":"1.231282404","rc":[{"batb":[[0,1.92,46.59]],"batl":[[1,2.9,4.08],[2,6,1.56]],"ltp":2.04,"tv":393.72,"id":19144239}]}]}
{"op":"mcm","clk":"11796446284","pt":1722610489441,"mc":[{"id":"1.231282404","rc":[{"batb":[[0,1.93,10],[1,1.92,46.59],[2,1.9,72.97]],"ltp":2.04,"tv":393.72,"id":19144239}]}]}
{"op":"mcm","clk":"11796446695","pt":1722610495254,"mc":[{"id":"1.231282404","rc":[{"batb":[[0,1.92,46.59],[1,1.9,72.97],[2,1.74,23.94]],"ltp":2.04,"tv":393.72,"id":19144239}]}]}
{"op":"mcm","clk":"11796451782","pt":1722610566431,"mc":[{"id":"1.231282404","rc":[{"batb":[[0,1.82,4.77]],"ltp":1.83,"tv":53343.39,"id":58385184}]}]}
{"op":"mcm","clk":"11796451816","pt":1722610567006,"mc":[{"id":"1.231282404","rc":[{"batb":[[0,1.93,10],[1,1.92,46.59],[2,1.9,72.97]],"ltp":2.04,"tv":393.72,"id":19144239}]}]}
{"op":"mcm","clk":"11796452073","pt":1722610570525,"mc":[{"id":"1.231282404","rc":[{"batb":[[0,1.92,46.59],[1,1.9,72.97],[2,1.74,23.94]],"ltp":2.04,"tv":393.72,"id":19144239}]}]}
{"op":"mcm","clk":"11796454917","pt":1722610614675,"mc":[{"id":"1.231282404","rc":[{"batl":[[0,1.93,6.48],[1,1.94,36.23]],"ltp":1.83,"tv":53343.39,"id":58385184},{"batb":[[0,1.93,10],[1,1.92,46.59],[2,1.9,72.97]],"ltp":2.04,"tv":393.72,"id":19144239}]}]}
{"op":"mcm","clk":"11796455149","pt":1722610618076,"mc":[{"id":"1.231282404","rc":[{"batb":[[0,1.92,46.59],[1,1.9,72.97],[2,1.74,23.94]],"ltp":2.04,"tv":393.72,"id":19144239}]}]}
{"op":"mcm","clk":"11796455688","pt":1722610625279,"mc":[{"id":"1.231282404","rc":[{"batl":[[1,1.94,16.23]],"ltp":1.83,"tv":53343.39,"id":58385184}]}]}
{"op":"mcm","clk":"11796455776","pt":1722610626776,"mc":[{"id":"1.231282404","rc":[{"batb":[[0,1.93,10],[1,1.92,46.59],[2,1.9,72.97]],"ltp":2.04,"tv":393.72,"id":19144239}]}]}
{"op":"mcm","clk":"11796456067","pt":1722610631080,"mc":[{"id":"1.231282404","rc":[{"batb":[[0,1.92,46.59],[1,1.9,72.97],[2,1.74,23.94]],"ltp":2.04,"tv":393.72,"id":19144239}]}]}
{"op":"mcm","clk":"11796456778","pt":1722610641515,"mc":[{"id":"1.231282404","rc":[{"batl":[[0,1.92,20],[1,1.93,6.48],[2,1.94,16.23]],"ltp":1.83,"tv":53343.39,"id":58385184}]}]}
{"op":"mcm","clk":"11796456834","pt":1722610642506,"mc":[{"id":"1.231282404","rc":[{"batl":[[0,1.91,6.54],[1,1.92,20]],"ltp":1.83,"tv":53343.39,"id":58385184},{"batb":[[0,1.93,10],[1,1.92,46.59],[2,1.9,72.97]],"ltp":2.04,"tv":393.72,"id":19144239}]}]}
{"op":"mcm","clk":"11796457138","pt":1722610646728,"mc":[{"id":"1.231282404","rc":[{"batb":[[0,1.92,46.59],[1,1.9,72.97],[2,1.74,23.94]],"ltp":2.04,"tv":393.72,"id":19144239}]}]}
{"op":"mcm","clk":"11796457310","pt":1722610649511,"mc":[{"id":"1.231282404","rc":[{"batl":[[0,1.94,16.23],[1,1.96,18.04],[2,6,1.56]],"ltp":1.83,"tv":53343.39,"id":58385184},{"batb":[[0,1.93,10],[1,1.92,46.59],[2,1.9,72.97]],"ltp":2.04,"tv":393.72,"id":19144239}]}]}
{"op":"mcm","clk":"11796457518","pt":1722610652511,"mc":[{"id":"1.231282404","rc":[{"batl":[[1,1.95,6.41],[2,1.96,18.04]],"ltp":1.83,"tv":53343.39,"id":58385184},{"batb":[[0,1.92,46.59],[1,1.9,72.97],[2,1.74,23.94]],"ltp":2.04,"tv":393.72,"id":19144239}]}]}
{"op":"mcm","clk":"11796457980","pt":1722610658414,"mc":[{"id":"1.231282404","rc":[{"batl":[[0,1.89,1],[1,1.94,16.23]],"ltp":1.83,"tv":53343.39,"id":58385184}]}]}
{"op":"mcm","clk":"11796458164","pt":1722610661040,"mc":[{"id":"1.231282404","rc":[{"batb":[[0,1.93,10],[1,1.92,46.59],[2,1.9,72.97]],"ltp":2.04,"tv":393.72,"id":19144239}]}]}
{"op":"mcm","clk":"11796458563","pt":1722610666017,"mc":[{"id":"1.231282404","rc":[{"batb":[[0,1.92,46.59],[1,1.9,72.97],[2,1.74,23.94]],"ltp":2.04,"tv":393.72,"id":19144239}]}]}
{"op":"mcm","clk":"11796459049","pt":1722610673641,"mc":[{"id":"1.231282404","rc":[{"batl":[[1,1.9,1],[2,1.94,16.23]],"ltp":1.83,"tv":53343.39,"id":58385184}]}]}
{"op":"mcm","clk":"11796459108","pt":1722610674424,"mc":[{"id":"1.231282404","rc":[{"batb":[[0,1.93,10],[1,1.92,46.59],[2,1.9,72.97]],"ltp":2.04,"tv":393.72,"id":19144239}]}]}
{"op":"mcm","clk":"11796459357","pt":1722610678237,"mc":[{"id":"1.231282404","rc":[{"batl":[[2,1.93,6.48]],"ltp":1.83,"tv":53343.39,"id":58385184},{"batb":[[0,1.92,46.59],[1,1.9,72.97],[2,1.74,23.94]],"ltp":2.04,"tv":393.72,"id":19144239}]}]}
{"op":"mcm","clk":"11796459557","pt":1722610680355,"mc":[{"id":"1.231282404","rc":[{"batb":[[0,1.93,10],[1,1.92,46.59],[2,1.9,72.97]],"ltp":2.04,"tv":393.72,"id":19144239}]}]}
{"op":"mcm","clk":"11796459974","pt":1722610685658,"mc":[{"id":"1.231282404","rc":[{"batb":[[0,1.92,46.59],[1,1.9,72.97],[2,1.74,23.94]],"ltp":2.04,"tv":393.72,"id":19144239}]}]}
{"op":"mcm","clk":"11796460018","pt":1722610686165,"mc":[{"id":"1.231282404","rc":[{"batl":[[2,1.91,1]],"ltp":1.83,"tv":53343.39,"id":58385184}]}]}
{"op":"mcm","clk":"11796460813","pt":1722610696651,"mc":[{"id":"1.231282404","rc":[{"batb":[[0,1.93,10],[1,1.92,46.59],[2,1.9,72.97]],"ltp":2.04,"tv":393.72,"id":19144239}]}]}
{"op":"mcm","clk":"11796461182","pt":1722610701663,"mc":[{"id":"1.231282404","rc":[{"batb":[[0,1.92,46.59],[1,1.9,72.97],[2,1.74,23.94]],"ltp":2.04,"tv":393.72,"id":19144239}]}]}
{"op":"mcm","clk":"11796461472","pt":1722610705530,"mc":[{"id":"1.231282404","rc":[{"batl":[[0,1.92,10],[1,1.93,6.48],[2,1.94,16.23]],"ltp":1.83,"tv":53343.39,"id":58385184}]}]}
{"op":"mcm","clk":"11796461814","pt":1722610710033,"mc":[{"id":"1.231282404","rc":[{"batb":[[0,1.93,10],[1,1.92,46.59],[2,1.9,72.97]],"ltp":2.04,"tv":393.72,"id":19144239}]}]}
{"op":"mcm","clk":"11796462368","pt":1722610717964,"mc":[{"id":"1.231282404","rc":[{"batb":[[0,1.92,46.59],[1,1.9,72.97],[2,1.74,23.94]],"ltp":2.04,"tv":393.72,"id":19144239}]}]}
{"op":"mcm","clk":"11796462610","pt":1722610721862,"mc":[{"id":"1.231282404","rc":[{"batb":[[0,1.93,10],[1,1.92,46.59],[2,1.9,72.97]],"ltp":2.04,"tv":393.72,"id":19144239}]}]}
{"op":"mcm","clk":"11796462935","pt":1722610727250,"mc":[{"id":"1.231282404","rc":[{"batb":[[0,1.92,46.59],[1,1.9,72.97],[2,1.74,23.94]],"ltp":2.04,"tv":393.72,"id":19144239}]}]}
{"op":"mcm","clk":"11796473469","pt":1722610865590,"mc":[{"id":"1.231282404","rc":[{"trd":[[1.81,15.75],[1.82,116.54],[1.84,27.98],[1.89,690.16],[1.9,8807.69],[1.91,2449.94],[1.92,15248.03],[1.95,6882.99],[1.96,18963.52]],"batl":[[1,1.93,6.5]],"ltp":1.83,"tv":53386.21,"id":58385184},{"trd":[[2.1,30.16],[2.22,20.14]],"batb":[[0,1.93,10],[1,1.92,46.72],[2,1.9,73.09]],"batl":[[1,2.9,4.07],[2,6,1.56]],"ltp":2.04,"tv":393.83,"id":19144239}],"tv":53780.04}]}
{"op":"mcm","clk":"11796473475","pt":1722610865698,"mc":[{"id":"1.231282404","rc":[{"batb":[[0,1.82,4.83]],"ltp":1.83,"tv":53386.21,"id":58385184}]}]}
{"op":"mcm","clk":"11796473717","pt":1722610868641,"mc":[{"id":"1.231282404","rc":[{"batb":[[0,1.92,46.72],[1,1.9,73.09],[2,1.74,23.94]],"ltp":2.04,"tv":393.83,"id":19144239}]}]}
{"op":"mcm","clk":"11796496361","pt":1722611166166,"mc":[{"id":"1.231282404","rc":[{"batb":[[0,1.82,4.89]],"ltp":1.83,"tv":53386.21,"id":58385184},{"batb":[[0,1.93,10],[1,1.92,46.72],[2,1.9,73.09]],"ltp":2.04,"tv":393.83,"id":19144239}]}]}
{"op":"mcm","clk":"11796496600","pt":1722611169433,"mc":[{"id":"1.231282404","rc":[{"batb":[[0,1.92,46.72],[1,1.9,73.09],[2,1.74,23.94]],"ltp":2.04,"tv":393.83,"id":19144239}]}]}
{"op":"mcm","clk":"11796516469","pt":1722611466138,"mc":[{"id":"1.231282404","rc":[{"batb":[[0,1.82,4.95]],"ltp":1.83,"tv":53386.21,"id":58385184},{"batb":[[0,1.93,10],[1,1.92,46.72],[2,1.9,73.09]],"ltp":2.04,"tv":393.83,"id":19144239}]}]}
{"op":"mcm","clk":"11796516707","pt":1722611469455,"mc":[{"id":"1.231282404","rc":[{"batb":[[0,1.92,46.72],[1,1.9,73.09],[2,1.74,23.94]],"ltp":2.04,"tv":393.83,"id":19144239}]}]}
{"op":"mcm","clk":"11796531116","pt":1722611679086,"mc":[{"id":"1.231282404","rc":[{"batb":[[0,1.93,10],[1,1.92,41.12],[2,1.9,73.09]],"batl":[[1,6,1.56],[2,12,1.56]],"ltp":2.04,"tv":393.83,"id":19144239}]}]}
{"op":"mcm","clk":"11796531361","pt":1722611682587,"mc":[{"id":"1.231282404","rc":[{"batb":[[0,1.92,41.12],[1,1.9,73.09],[2,1.74,17.32]],"ltp":2.04,"tv":393.83,"id":19144239}]}]}
{"op":"mcm","clk":"11796536636","pt":1722611753921,"mc":[{"id":"1.231282404","rc":[{"batb":[[0,1.93,10],[1,1.92,41.12],[2,1.9,73.09]],"batl":[[1,2.9,4.07],[2,6,1.56]],"ltp":2.04,"tv":393.83,"id":19144239}]}]}
{"op":"mcm","clk":"11796536881","pt":1722611757240,"mc":[{"id":"1.231282404","rc":[{"batb":[[0,1.92,41.12],[1,1.9,73.09],[2,1.74,17.32]],"ltp":2.04,"tv":393.83,"id":19144239}]}]}
{"op":"mcm","clk":"11796537142","pt":1722611761146,"mc":[{"id":"1.231282404","rc":[{"batb":[[0,1.93,10],[1,1.92,41.12],[2,1.9,73.09]],"ltp":2.04,"tv":393.83,"id":19144239}]}]}
{"op":"mcm","clk":"11796537369","pt":1722611764540,"mc":[{"id":"1.231282404","rc":[{"batb":[[0,1.92,41.12],[1,1.9,73.09],[2,1.74,23.94]],"ltp":2.04,"tv":393.83,"id":19144239}]}]}
{"op":"mcm","clk":"11796537452","pt":1722611765940,"mc":[{"id":"1.231282404","rc":[{"batb":[[0,1.83,1.01],[1,1.82,4],[2,1.81,58.92]],"ltp":1.83,"tv":53386.21,"id":58385184}]}]}
{"op":"mcm","clk":"11796557265","pt":1722612066242,"mc":[{"id":"1.231282404","rc":[{"batb":[[0,1.83,1.13]],"ltp":1.83,"tv":53386.21,"id":58385184},{"batb":[[0,1.93,10],[1,1.92,41.12],[2,1.9,73.09]],"ltp":2.04,"tv":393.83,"id":19144239}]}]}
{"op":"mcm","clk":"11796557538","pt":1722612069615,"mc":[{"id":"1.231282404","rc":[{"batb":[[0,1.92,41.12],[1,1.9,73.09],[2,1.74,23.94]],"ltp":2.04,"tv":393.83,"id":19144239}]}]}
{"op":"mcm","clk":"11796557747","pt":1722612072137,"mc":[{"id":"1.231282404","rc":[{"batb":[[0,1.93,10],[1,1.92,41.12],[2,1.9,73.09]],"ltp":2.04,"tv":393.83,"id":19144239}]}]}
{"op":"mcm","clk":"11796558129","pt":1722612077040,"mc":[{"id":"1.231282404","rc":[{"batb":[[0,1.92,41.12],[1,1.9,73.09],[2,1.74,23.94]],"ltp":2.04,"tv":393.83,"id":19144239}]}]}
{"op":"mcm","clk":"11796564585","pt":1722612170588,"mc":[{"id":"1.231282404","rc":[{"batb":[[0,2.08,1]],"ltp":2.04,"tv":393.83,"id":19144239}]}]}
{"op":"mcm","clk":"11796564594","pt":1722612170689,"mc":[{"id":"1.231282404","rc":[{"batb":[[1,1.82,5.14]],"ltp":1.83,"tv":53386.21,"id":58385184}]}]}
{"op":"mcm","clk":"11796579163","pt":1722612366013,"mc":[{"id":"1.231282404","rc":[{"batb":[[0,1.83,1.25]],"ltp":1.83,"tv":53386.21,"id":58385184}]}]}
{"op":"mcm","clk":"11796602801","pt":1722612666578,"mc":[{"id":"1.231282404","rc":[{"batb":[[0,1.83,1.37]],"ltp":1.83,"tv":53386.21,"id":58385184}]}]}
{"op":"mcm","clk":"11796625900","pt":1722612965912,"mc":[{"id":"1.231282404","rc":[{"batb":[[0,1.83,1.49]],"ltp":1.83,"tv":53386.21,"id":58385184}]}]}
{"op":"mcm","clk":"11796636817","pt":1722613114647,"mc":[{"id":"1.231282404","rc":[{"trd":[[1.83,4.96],[1.84,28.94]],"batb":[[0,1.82,5.14],[1,1.81,58.92],[2,1.75,129.83]],"batl":[[0,1.83,9.87],[1,1.92,10],[2,1.93,6.5]],"ltp":1.83,"tv":53389.19,"id":58385184}],"tv":53783.02}]}
{"op":"mcm","clk":"11796636880","pt":1722613115328,"mc":[{"id":"1.231282404","rc":[{"batl":[[2,1.94,16.23]],"ltp":1.83,"tv":53389.19,"id":58385184}]}]}
{"op":"mcm","clk":"11796639000","pt":1722613142553,"mc":[{"id":"1.231282404","rc":[{"trd":[[1.83,22.96]],"batl":[[0,1.92,10.87],[1,1.94,16.23],[2,1.96,18.04]],"ltp":1.83,"tv":53407.19,"id":58385184}],"tv":53801.02}]}
{"op":"mcm","clk":"11796639052","pt":1722613143071,"mc":[{"id":"1.231282404","rc":[{"batl":[[1,1.93,6.5],[2,1.94,16.23]],"ltp":1.83,"tv":53407.19,"id":58385184}]}]}
{"op":"mcm","clk":"11796684458","pt":1722613575667,"mc":[{"id":"1.231282404","rc":[{"batb":[[2,1.74,17.32]],"batl":[[1,6,1.56],[2,12,1.56]],"ltp":2.04,"tv":393.83,"id":19144239}]}]}
{"op":"mcm","clk":"11796684600","pt":1722613577552,"mc":[{"id":"1.231282404","rc":[{"batl":[[1,2.9,4.07],[2,6,1.56]],"ltp":2.04,"tv":393.83,"id":19144239}]}]}
{"op":"mcm","clk":"11796685223","pt":1722613584858,"mc":[{"id":"1.231282404","rc":[{"batb":[[2,1.74,23.94]],"ltp":2.04,"tv":393.83,"id":19144239}]}]}
{"op":"mcm","clk":"11796713502","pt":1722613926395,"mc":[{"id":"1.231282404","rc":[{"trd":[[1.83,23.2]],"batl":[[0,1.92,10.75]],"ltp":1.83,"tv":53407.43,"id":58385184}],"tv":53801.26}]}
{"op":"mcm","clk":"11796738755","pt":1722614225255,"mc":[{"id":"1.231282404","rc":[{"trd":[[1.83,23.44]],"batl":[[0,1.92,10.63]],"ltp":1.83,"tv":53407.67,"id":58385184}],"tv":53801.5}]}
{"op":"mcm","clk":"11796762358","pt":1722614493384,"mc":[{"id":"1.231282404","rc":[{"trd":[[1.81,15.75],[1.83,23.45],[1.89,690.44],[1.9,8811.8],[1.91,2451.08],[1.92,15254.77],[1.95,6886.32],[1.96,18972.53]],"batl":[[0,1.92,10]],"ltp":1.83,"tv":53432.29,"id":58385184},{"batb":[[1,1.9,73.16],[2,1.74,23.95]],"batl":[[1,2.9,4.08]],"ltp":2.04,"tv":393.83,"id":19144239}],"tv":53826.12}]}
{"op":"mcm","clk":"11796763803","pt":1722614507697,"mc":[{"id":"1.231282404","rc":[{"trd":[[1.82,125.64]],"batb":[[0,1.81,59.51],[1,1.75,129.83],[2,1.74,17.32]],"ltp":1.82,"tv":53441.39,"id":58385184}],"tv":53835.22}]}
{"op":"mcm","clk":"11796765834","pt":1722614525817,"mc":[{"id":"1.231282404","rc":[{"batb":[[0,1.81,59.57]],"ltp":1.82,"tv":53441.39,"id":58385184}]}]}
{"op":"mcm","clk":"11796786044","pt":1722614686768,"mc":[{"id":"1.231282404","rc":[{"batl":[[0,1.92,5]],"ltp":1.82,"tv":53441.39,"id":58385184}]}]}
{"op":"mcm","clk":"11796794985","pt":1722614756804,"mc":[{"id":"1.231282404","rc":[{"batb":[[1,1.76,12.63],[2,1.75,129.83]],"ltp":1.82,"tv":53441.39,"id":58385184}]}]}
{"op":"mcm","clk":"11796803349","pt":1722614826045,"mc":[{"id":"1.231282404","rc":[{"batb":[[0,1.81,59.63]],"ltp":1.82,"tv":53441.39,"id":58385184}]}]}
{"op":"mcm","clk":"11796840526","pt":1722615126351,"mc":[{"id":"1.231282404","rc":[{"batb":[[0,1.81,59.69]],"ltp":1.82,"tv":53441.39,"id":58385184}]}]}
{"op":"mcm","clk":"11796874964","pt":1722615426771,"mc":[{"id":"1.231282404","rc":[{"batb":[[0,1.81,59.75]],"ltp":1.82,"tv":53441.39,"id":58385184}]}]}
{"op":"mcm","clk":"11796911505","pt":1722615726017,"mc":[{"id":"1.231282404","rc":[{"batb":[[0,1.82,1.07],[1,1.81,58.92],[2,1.76,12.63]],"ltp":1.82,"tv":53441.39,"id":58385184}]}]}
{"op":"mcm","clk":"11796946832","pt":1722616026288,"mc":[{"id":"1.231282404","rc":[{"batb":[[0,1.82,1.31]],"ltp":1.82,"tv":53441.39,"id":58385184}]}]}
{"op":"mcm","clk":"11796984493","pt":1722616326335,"mc":[{"id":"1.231282404","rc":[{"batb":[[0,1.82,1.55]],"ltp":1.82,"tv":53441.39,"id":58385184}]}]}
{"op":"mcm","clk":"11797023170","pt":1722616626324,"mc":[{"id":"1.231282404","rc":[{"batb":[[0,1.82,1.79]],"ltp":1.82,"tv":53441.39,"id":58385184}]}]}
{"op":"mcm","clk":"11797064123","pt":1722616925486,"mc":[{"id":"1.231282404","rc":[{"batb":[[0,2.2,1.09],[1,2.08,1],[2,1.9,73.16]],"ltp":2.04,"tv":393.83,"id":19144239}]}]}
{"op":"mcm","clk":"11797064282","pt":1722616926655,"mc":[{"id":"1.231282404","rc":[{"batb":[[0,1.82,5.97]],"ltp":1.82,"tv":53441.39,"id":58385184}]}]}
{"op":"mcm","clk":"11797065159","pt":1722616932892,"mc":[{"id":"1.231282404","rc":[{"batb":[[0,2.08,1],[1,1.9,73.16],[2,1.74,23.95]],"ltp":2.04,"tv":393.83,"id":19144239}]}]}
{"op":"mcm","clk":"11797067146","pt":1722616946897,"mc":[{"id":"1.231282404","rc":[{"batb":[[0,1.9,1.09],[1,1.82,5.97],[2,1.81,58.92]],"ltp":1.82,"tv":53441.39,"id":58385184}]}]}
{"op":"mcm","clk":"11797068781","pt":1722616957905,"mc":[{"id":"1.231282404","rc":[{"trd":[[1.9,8813.96]],"batb":[[0,1.82,5.98],[1,1.81,58.92],[2,1.76,12.63]],"ltp":1.9,"tv":53443.55,"id":58385184}],"tv":53837.38}]}
{"op":"mcm","clk":"11797068922","pt":1722616958701,"mc":[{"id":"1.231282404","rc":[{"batb":[[0,1.82,5.97]],"ltp":1.9,"tv":53443.55,"id":58385184}]}]}
{"op":"mcm","clk":"11797069434","pt":1722616962110,"mc":[{"id":"1.231282404","rc":[{"trd":[[1.82,126.08],[1.83,25.25]],"batb":[[0,1.82,4.85]],"ltp":1.82,"tv":53445.79,"id":58385184}],"tv":53839.62}]}
{"op":"mcm","clk":"11797070024","pt":1722616966626,"mc":[{"id":"1.231282404","rc":[{"batb":[[0,1.81,55.77],[1,1.76,12.63],[2,1.75,129.83]],"batl":[[0,1.89,326.4],[1,1.92,5],[2,1.93,6.5]],"ltp":1.82,"tv":53445.79,"id":58385184},{"batl":[[0,2.9,4.08],[1,6,1.56],[2,12,1.56]],"ltp":2.04,"tv":393.83,"id":19144239}]}]}
{"op":"mcm","clk":"11797070161","pt":1722616967634,"mc":[{"id":"1.231282404","rc":[{"batl":[[0,1.88,6.67],[1,1.89,326.4],[2,1.92,5]],"ltp":1.82,"tv":53445.79,"id":58385184}]}]}
{"op":"mcm","clk":"11797070176","pt":1722616967704,"mc":[{"id":"1.231282404","rc":[{"batb":[[0,2.1,2],[1,2.08,1],[2,1.9,73.16]],"ltp":2.04,"tv":393.83,"id":19144239}]}]}
{"op":"mcm","clk":"11797070576","pt":1722616970711,"mc":[{"id":"1.231282404","rc":[{"batb":[[0,2.08,1],[1,1.9,73.16],[2,1.74,23.95]],"ltp":2.04,"tv":393.83,"id":19144239}]}]}
{"op":"mcm","clk":"11797070735","pt":1722616972040,"mc":[{"id":"1.231282404","rc":[{"batb":[[0,2.14,14],[1,2.12,4],[2,2.08,1]],"batl":[[0,2.24,4],[1,2.9,4.08],[2,6,1.56]],"ltp":2.04,"tv":393.83,"id":19144239}]}]}
{"op":"mcm","clk":"11797071171","pt":1722616975372,"mc":[{"id":"1.231282404","rc":[{"batb":[[0,2.14,4]],"ltp":2.04,"tv":393.83,"id":19144239}]}]}
{"op":"mcm","clk":"11797071919","pt":1722616981041,"mc":[{"id":"1.231282404","rc":[{"trd":[[1.88,30.44]],"batl":[[0,1.89,60.7],[1,1.92,5],[2,1.94,16.23]],"ltp":1.88,"tv":53463.68,"id":58385184},{"trd":[[2.14,8]],"batb":[[0,2.14,10]],"ltp":2.14,"tv":397.83,"id":19144239}],"tv":53861.51}]}
{"op":"mcm","clk":"11797072412","pt":1722616984737,"mc":[{"id":"1.231282404","rc":[{"batb":[[0,2.12,4],[1,2.08,1],[2,1.9,73.16]],"ltp":2.14,"tv":397.83,"id":19144239}]}]}
{"op":"mcm","clk":"11797074238","pt":1722616998629,"mc":[{"id":"1.231282404","rc":[{"batl":[[0,1.88,4.56],[1,1.89,60.7],[2,1.92,5]],"ltp":1.88,"tv":53463.68,"id":58385184},{"batb":[[0,2.14,10],[1,2.12,4],[2,2.08,1]],"ltp":2.14,"tv":397.83,"id":19144239}]}]}
{"op":"mcm","clk":"11797074690","pt":1722617002249,"mc":[{"id":"1.231282404","rc":[{"batb":[[0,2.14,4]],"batl":[[0,2.22,4],[1,2.24,4],[2,2.9,4.08]],"ltp":2.14,"tv":397.83,"id":19144239}]}]}
{"op":"mcm","clk":"11797075105","pt":1722617005552,"mc":[{"id":"1.231282404","rc":[{"batb":[[0,1.82,5.4],[1,1.81,54.92],[2,1.76,12.63]],"ltp":1.88,"tv":53463.68,"id":58385184}]}]}
{"op":"mcm","clk":"11797075945","pt":1722617011937,"mc":[{"id":"1.231282404","rc":[{"batb":[[0,1.83,1.26],[1,1.82,5.4],[2,1.81,54.92]],"ltp":1.88,"tv":53463.68,"id":58385184}]}]}
{"op":"mcm","clk":"11797076656","pt":1722617017377,"mc":[{"id":"1.231282404","rc":[{"batl":[[0,1.87,4],[1,1.88,8.56],[2,1.89,60.7]],"ltp":1.88,"tv":53463.68,"id":58385184}]}]}
{"op":"mcm","clk":"11797078351","pt":1722617030676,"mc":[{"id":"1.231282404","rc":[{"batl":[[2,1.92,5]],"ltp":1.88,"tv":53463.68,"id":58385184},{"batb":[[0,2.08,1],[1,1.9,73.16],[2,1.74,23.95]],"ltp":2.14,"tv":397.83,"id":19144239}]}]}
{"op":"mcm","clk":"11797078417","pt":1722617031174,"mc":[{"id":"1.231282404","rc":[{"batl":[[0,1.88,4.56],[1,1.92,5],[2,1.94,16.23]],"ltp":1.88,"tv":53463.68,"id":58385184}]}]}
{"op":"mcm","clk":"11797078524","pt":1722617032072,"mc":[{"id":"1.231282404","rc":[{"batl":[[0,1.92,5],[1,1.94,16.23],[2,1.96,18.04]],"ltp":1.88,"tv":53463.68,"id":58385184}]}]}
{"op":"mcm","clk":"11797078692","pt":1722617033589,"mc":[{"id":"1.231282404","rc":[{"batb":[[0,1.82,5.4],[1,1.81,54.92],[2,1.76,12.63]],"ltp":1.88,"tv":53463.68,"id":58385184}]}]}
{"op":"mcm","clk":"11797079111","pt":1722617037003,"mc":[{"id":"1.231282404","rc":[{"batl":[[0,1.83,3.64],[1,1.92,5],[2,1.94,16.23]],"ltp":1.88,"tv":53463.68,"id":58385184}]}]}
{"op":"mcm","clk":"11797080034","pt":1722617044102,"mc":[{"id":"1.231282404","rc":[{"trd":[[1.83,27.77]],"batl":[[0,1.83,2.38]],"ltp":1.83,"tv":53466.2,"id":58385184}],"tv":53864.03}]}
{"op":"mcm","clk":"11797080460","pt":1722617047516,"mc":[{"id":"1.231282404","rc":[{"batb":[[0,1.82,9.4]],"ltp":1.83,"tv":53466.2,"id":58385184}]}]}
{"op":"mcm","clk":"11797085455","pt":1722617087956,"mc":[{"id":"1.231282404","rc":[{"batl":[[0,1.92,5],[1,1.94,16.23],[2,1.96,18.04]],"ltp":1.83,"tv":53466.2,"id":58385184}]}]}
{"op":"mcm","clk":"11797087061","pt":1722617100968,"mc":[{"id":"1.231282404","rc":[{"trd":[[1.82,130.85]],"batb":[[0,1.82,7.02]],"ltp":1.82,"tv":53470.97,"id":58385184}],"tv":53868.8}]}
{"op":"mcm","clk":"11797102491","pt":1722617226651,"mc":[{"id":"1.231282404","rc":[{"batb":[[0,1.82,7.2]],"ltp":1.82,"tv":53470.97,"id":58385184}]}]}
{"op":"mcm","clk":"11797102600","pt":1722617227654,"mc":[{"id":"1.231282404","rc":[{"batl":[[0,1.91,18.04],[1,1.92,5],[2,1.94,16.23]],"ltp":1.82,"tv":53470.97,"id":58385184}]}]}
{"op":"mcm","clk":"11797106015","pt":1722617253693,"mc":[{"id":"1.231282404","rc":[{"batl":[[0,1.92,5],[1,1.94,16.23],[2,1.96,18.04]],"ltp":1.82,"tv":53470.97,"id":58385184}]}]}
{"op":"mcm","clk":"11797131727","pt":1722617480311,"mc":[{"id":"1.231282404","rc":[{"batl":[[0,1.91,8],[1,1.92,5],[2,1.94,16.23]],"ltp":1.82,"tv":53470.97,"id":58385184}]}]}
{"op":"mcm","clk":"11797136892","pt":1722617525635,"mc":[{"id":"1.231282404","rc":[{"batb":[[0,1.82,7.38]],"ltp":1.82,"tv":53470.97,"id":58385184}]}]}
{"op":"mcm","clk":"11797152751","pt":1722617664615,"mc":[{"id":"1.231282404","rc":[{"batb":[[0,1.82,3.38]],"batl":[[0,1.89,1969.23],[1,1.91,8],[2,1.92,5]],"ltp":1.82,"tv":53470.97,"id":58385184},{"batl":[[0,2.9,4.08],[1,6,1.56],[2,12,1.56]],"ltp":2.14,"tv":397.83,"id":19144239}]}]}
{"op":"mcm","clk":"11797152844","pt":1722617665409,"mc":[{"id":"1.231282404","rc":[{"batl":[[0,1.88,17.06],[1,1.89,1969.23],[2,1.91,8]],"ltp":1.82,"tv":53470.97,"id":58385184},{"batb":[[0,2.14,14.31],[1,2.1,2],[2,2.08,1]],"ltp":2.14,"tv":397.83,"id":19144239}]}]}
{"op":"mcm","clk":"11797152926","pt":1722617666295,"mc":[{"id":"1.231282404","rc":[{"batl":[[0,1.87,4],[1,1.88,21.06],[2,1.89,1969.23]],"ltp":1.82,"tv":53470.97,"id":58385184},{"batb":[[0,2.16,10],[1,2.14,18.31],[2,2.1,2]],"ltp":2.14,"tv":397.83,"id":19144239}]}]}
{"op":"mcm","clk":"11797153184","pt":1722617668392,"mc":[{"id":"1.231282404","rc":[{"batb":[[2,2.08,1]],"ltp":2.14,"tv":397.83,"id":19144239}]}]}
{"op":"mcm","clk":"11797153425","pt":1722617670590,"mc":[{"id":"1.231282404","rc":[{"batb":[[0,2.16,2]],"ltp":2.14,"tv":397.83,"id":19144239}]}]}
{"op":"mcm","clk":"11797153790","pt":1722617673653,"mc":[{"id":"1.231282404","rc":[{"batl":[[2,1.91,8]],"ltp":1.82,"tv":53470.97,"id":58385184},{"batb":[[0,2.16,10]],"ltp":2.14,"tv":397.83,"id":19144239}]}]}
{"op":"mcm","clk":"11797153995","pt":1722617675646,"mc":[{"id":"1.231282404","rc":[{"batl":[[1,1.88,4]],"ltp":1.82,"tv":53470.97,"id":58385184},{"batb":[[1,2.14,4]],"ltp":2.14,"tv":397.83,"id":19144239}]}]}
{"op":"mcm","clk":"11797154093","pt":1722617676524,"mc":[{"id":"1.231282404","rc":[{"batb":[[0,2.18,2],[1,2.16,10],[2,2.14,4]],"ltp":2.14,"tv":397.83,"id":19144239}]}]}
{"op":"mcm","clk":"11797154168","pt":1722617677211,"mc":[{"id":"1.231282404","rc":[{"batb":[[1,2.14,4],[2,2.08,1]],"ltp":2.14,"tv":397.83,"id":19144239}]}]}
{"op":"mcm","clk":"11797154243","pt":1722617677938,"mc":[{"id":"1.231282404","rc":[{"batl":[[0,1.87,1969.23],[1,1.91,8],[2,1.92,5]],"ltp":1.82,"tv":53470.97,"id":58385184},{"batb":[[1,2.08,1],[2,1.9,73.16]],"ltp":2.14,"tv":397.83,"id":19144239}]}]}
{"op":"mcm","clk":"11797154451","pt":1722617679825,"mc":[{"id":"1.231282404","rc":[{"batb":[[0,2.08,1],[1,1.9,73.16],[2,1.74,23.95]],"ltp":2.14,"tv":397.83,"id":19144239}]}]}
{"op":"mcm","clk":"11797154632","pt":1722617681445,"mc":[{"id":"1.231282404","rc":[{"batl":[[0,1.86,4],[1,1.87,1973.23],[2,1.91,8]],"ltp":1.82,"tv":53470.97,"id":58385184},{"batb":[[0,2.14,4],[1,2.08,1],[2,1.9,73.16]],"ltp":2.14,"tv":397.83,"id":19144239}]}]}
{"op":"mcm","clk":"11797154700","pt":1722617682027,"mc":[{"id":"1.231282404","rc":[{"batb":[[0,2.16,12],[1,2.14,4],[2,2.08,1]],"ltp":2.14,"tv":397.83,"id":19144239}]}]}
{"op":"mcm","clk":"11797154886","pt":1722617683646,"mc":[{"id":"1.231282404","rc":[{"batl":[[1,1.87,4]],"ltp":1.82,"tv":53470.97,"id":58385184}]}]}
{"op":"mcm","clk":"11797154993","pt":1722617684636,"mc":[{"id":"1.231282404","rc":[{"batb":[[0,2.16,10]],"ltp":2.14,"tv":397.83,"id":19144239}]}]}
{"op":"mcm","clk":"11797155178","pt":1722617686201,"mc":[{"id":"1.231282404","rc":[{"batl":[[0,1.91,8],[1,1.92,5],[2,1.94,16.23]],"ltp":1.82,"tv":53470.97,"id":58385184},{"batb":[[0,2.08,1],[1,1.9,73.16],[2,1.74,23.95]],"ltp":2.14,"tv":397.83,"id":19144239}]}]}
{"op":"mcm","clk":"11797155522","pt":1722617689527,"mc":[{"id":"1.231282404","rc":[{"batl":[[0,1.89,1969.23],[1,1.91,8],[2,1.92,5]],"ltp":1.82,"tv":53470.97,"id":58385184},{"batb":[[0,2.1,2],[1,2.08,1],[2,1.9,73.16]],"ltp":2.14,"tv":397.83,"id":19144239}]}]}
{"op":"mcm","clk":"11797155737","pt":1722617691826,"mc":[{"id":"1.231282404","rc":[{"batb":[[0,2.08,1],[1,1.9,73.16],[2,1.74,23.95]],"ltp":2.14,"tv":397.83,"id":19144239}]}]}
{"op":"mcm","clk":"11797156319","pt":1722617696519,"mc":[{"id":"1.231282404","rc":[{"batb":[[0,2.12,4],[1,2.08,1],[2,1.9,73.16]],"ltp":2.14,"tv":397.83,"id":19144239}]}]}
{"op":"mcm","clk":"11797156367","pt":1722617696940,"mc":[{"id":"1.231282404","rc":[{"batb":[[0,2.14,12],[1,2.12,4],[2,2.08,1]],"ltp":2.14,"tv":397.83,"id":19144239}]}]}
{"op":"mcm","clk":"11797156608","pt":1722617699143,"mc":[{"id":"1.231282404","rc":[{"batb":[[0,2.14,10]],"ltp":2.14,"tv":397.83,"id":19144239}]}]}
{"op":"mcm","clk":"11797156736","pt":1722617700343,"mc":[{"id":"1.231282404","rc":[{"batb":[[0,2.12,4],[1,2.08,1],[2,1.9,73.16]],"ltp":2.14,"tv":397.83,"id":19144239}]}]}
{"op":"mcm","clk":"11797159593","pt":1722617721786,"mc":[{"id":"1.231282404","rc":[{"batl":[[0,1.88,17.06],[1,1.89,1969.23],[2,1.91,8]],"ltp":1.82,"tv":53470.97,"id":58385184}]}]}
{"op":"mcm","clk":"11797159714","pt":1722617722784,"mc":[{"id":"1.231282404","rc":[{"batb":[[0,2.14,12],[1,2.12,4],[2,2.08,1]],"ltp":2.14,"tv":397.83,"id":19144239}]}]}
{"op":"mcm","clk":"11797160062","pt":1722617725475,"mc":[{"id":"1.231282404","rc":[{"batb":[[0,2.14,10]],"ltp":2.14,"tv":397.83,"id":19144239}]}]}
{"op":"mcm","clk":"11797160237","pt":1722617726673,"mc":[{"id":"1.231282404","rc":[{"batl":[[0,1.87,4],[1,1.88,21.06],[2,1.89,1969.23]],"ltp":1.82,"tv":53470.97,"id":58385184},{"batb":[[0,2.14,4]],"ltp":2.14,"tv":397.83,"id":19144239}]}]}
{"op":"mcm","clk":"11797160385","pt":1722617727783,"mc":[{"id":"1.231282404","rc":[{"batb":[[0,2.16,2],[1,2.14,4],[2,2.12,4]],"ltp":2.14,"tv":397.83,"id":19144239}]}]}
{"op":"mcm","clk":"11797160789","pt":1722617730596,"mc":[{"id":"1.231282404","rc":[{"batl":[[2,1.91,8]],"ltp":1.82,"tv":53470.97,"id":58385184},{"batb":[[0,2.14,4],[1,2.12,4],[2,2.08,1]],"ltp":2.14,"tv":397.83,"id":19144239}]}]}
{"op":"mcm","clk":"11797160863","pt":1722617731074,"mc":[{"id":"1.231282404","rc":[{"batl":[[1,1.88,4]],"ltp":1.82,"tv":53470.97,"id":58385184},{"batb":[[0,2.16,10],[1,2.14,4],[2,2.12,4]],"ltp":2.14,"tv":397.83,"id":19144239}]}]}
{"op":"mcm","clk":"11797161298","pt":1722617734370,"mc":[{"id":"1.231282404","rc":[{"batb":[[0,2.14,4],[1,2.12,4],[2,2.08,1]],"ltp":2.14,"tv":397.83,"id":19144239}]}]}
{"op":"mcm","clk":"11797161373","pt":1722617734897,"mc":[{"id":"1.231282404","rc":[{"batl":[[0,1.85,1969.23],[1,1.91,8],[2,1.92,5]],"ltp":1.82,"tv":53470.97,"id":58385184},{"batb":[[0,2.16,2],[1,2.08,1],[2,1.9,73.16]],"ltp":2.14,"tv":397.83,"id":19144239}]}]}
{"op":"mcm","clk":"11797161683","pt":1722617737194,"mc":[{"id":"1.231282404","rc":[{"batb":[[0,2.08,1],[1,1.9,73.16],[2,1.74,23.95]],"ltp":2.14,"tv":397.83,"id":19144239}]}]}
{"op":"mcm","clk":"11797162341","pt":1722617742009,"mc":[{"id":"1.231282404","rc":[{"batl":[[0,1.84,4],[1,1.85,1973.23],[2,1.91,8]],"ltp":1.82,"tv":53470.97,"id":58385184},{"batb":[[0,2.18,12],[1,2.16,4],[2,2.08,1]],"ltp":2.14,"tv":397.83,"id":19144239}]}]}
{"op":"mcm","clk":"11797162642","pt":1722617744583,"mc":[{"id":"1.231282404","rc":[{"batb":[[0,2.18,10]],"ltp":2.14,"tv":397.83,"id":19144239}]}]}
{"op":"mcm","clk":"11797162776","pt":1722617745587,"mc":[{"id":"1.231282404","rc":[{"batb":[[0,2.16,4],[1,2.08,1],[2,1.9,73.16]],"ltp":2.14,"tv":397.83,"id":19144239}]}]}
{"op":"mcm","clk":"11797164223","pt":1722617757315,"mc":[{"id":"1.231282404","rc":[{"batb":[[0,2.2,12],[1,2.18,4],[2,2.16,4]],"ltp":2.14,"tv":397.83,"id":19144239}]}]}
{"op":"mcm","clk":"11797164497","pt":1722617759718,"mc":[{"id":"1.231282404","rc":[{"batb":[[0,2.2,10]],"ltp":2.14,"tv":397.83,"id":19144239}]}]}
{"op":"mcm","clk":"11797164634","pt":1722617760727,"mc":[{"id":"1.231282404","rc":[{"batb":[[0,2.18,4],[1,2.16,4],[2,2.08,1]],"ltp":2.14,"tv":397.83,"id":19144239}]}]}
{"op":"mcm","clk":"11797165549","pt":1722617768227,"mc":[{"id":"1.231282404","rc":[{"batl":[[0,1.84,21.06]],"ltp":1.82,"tv":53470.97,"id":58385184},{"batb":[[0,2.2,12],[1,2.18,4],[2,2.16,4]],"ltp":2.14,"tv":397.83,"id":19144239}]}]}
{"op":"mcm","clk":"11797165932","pt":1722617771631,"mc":[{"id":"1.231282404","rc":[{"batb":[[0,2.18,4],[1,2.16,4],[2,2.08,1]],"ltp":2.14,"tv":397.83,"id":19144239}]}]}
{"op":"mcm","clk":"11797165984","pt":1722617772003,"mc":[{"id":"1.231282404","rc":[{"batb":[[0,2.2,4],[1,2.18,4],[2,2.16,4]],"ltp":2.14,"tv":397.83,"id":19144239}]}]}
{"op":"mcm","clk":"11797171766","pt":1722617819636,"mc":[{"id":"1.231282404","rc":[{"trd":[[1.82,133.87],[1.83,28.13]],"batb":[[0,1.81,54.92],[1,1.76,12.63],[2,1.75,129.83]],"ltp":1.82,"tv":53474.34,"id":58385184},{"trd":[[2.22,22.91]],"batb":[[0,2.22,9.23],[1,2.2,4],[2,2.18,4]],"ltp":2.22,"tv":400.6,"id":19144239}],"tv":53874.95}]}
{"op":"mcm","clk":"11797171878","pt":1722617820546,"mc":[{"id":"1.231282404","rc":[{"batb":[[1,1.75,129.83],[2,1.74,17.32]],"ltp":1.82,"tv":53474.34,"id":58385184},{"batb":[[1,2.08,1],[2,1.9,73.16]],"ltp":2.22,"tv":400.6,"id":19144239}]}]}
{"op":"mcm","clk":"11797171992","pt":1722617821484,"mc":[{"id":"1.231282404","rc":[{"batb":[[0,2.22,7.23]],"ltp":2.22,"tv":400.6,"id":19144239}]}]}
{"op":"mcm","clk":"11797172118","pt":1722617822368,"mc":[{"id":"1.231282404","rc":[{"batb":[[0,2.08,1],[1,1.9,73.16],[2,1.74,23.95]],"ltp":2.22,"tv":400.6,"id":19144239}]}]}
{"op":"mcm","clk":"11797172535","pt":1722617825669,"mc":[{"id":"1.231282404","rc":[{"batb":[[0,1.81,55.04]],"batl":[[0,1.84,38.11]],"ltp":1.82,"tv":53474.34,"id":58385184},{"batb":[[0,2.1,2],[1,2.08,1],[2,1.9,73.16]],"ltp":2.22,"tv":400.6,"id":19144239}]}]}
{"op":"mcm","clk":"11797172826","pt":1722617827961,"mc":[{"id":"1.231282404","rc":[{"batb":[[0,2.08,1],[1,1.9,73.16],[2,1.74,23.95]],"ltp":2.22,"tv":400.6,"id":19144239}]}]}
{"op":"mcm","clk":"11797173398","pt":1722617832459,"mc":[{"id":"1.231282404","rc":[{"batb":[[0,2.18,4],[1,2.08,1],[2,1.9,73.16]],"ltp":2.22,"tv":400.6,"id":19144239}]}]}
{"op":"mcm","clk":"11797173431","pt":1722617832766,"mc":[{"id":"1.231282404","rc":[{"batb":[[0,2.2,12],[1,2.18,4],[2,2.08,1]],"ltp":2.22,"tv":400.6,"id":19144239}]}]}
{"op":"mcm","clk":"11797173739","pt":1722617835353,"mc":[{"id":"1.231282404","rc":[{"batb":[[0,2.2,10]],"ltp":2.22,"tv":400.6,"id":19144239}]}]}
{"op":"mcm","clk":"11797173862","pt":1722617836349,"mc":[{"id":"1.231282404","rc":[{"batb":[[0,2.18,4],[1,2.08,1],[2,1.9,73.16]],"ltp":2.22,"tv":400.6,"id":19144239}]}]}
{"op":"mcm","clk":"11797174751","pt":1722617843476,"mc":[{"id":"1.231282404","rc":[{"batb":[[1,1.76,10.82],[2,1.75,129.83]],"ltp":1.82,"tv":53474.34,"id":58385184},{"batb":[[0,2.2,12],[1,2.18,4],[2,2.08,1]],"ltp":2.22,"tv":400.6,"id":19144239}]}]}
{"op":"mcm","clk":"11797175126","pt":1722617846583,"mc":[{"id":"1.231282404","rc":[{"batb":[[0,2.2,10]],"ltp":2.22,"tv":400.6,"id":19144239}]}]}
{"op":"mcm","clk":"11797175266","pt":1722617847578,"mc":[{"id":"1.231282404","rc":[{"batb":[[0,2.2,4]],"ltp":2.22,"tv":400.6,"id":19144239}]}]}
{"op":"mcm","clk":"11797177759","pt":1722617868214,"mc":[{"id":"1.231282404","rc":[{"trd":[[1.82,133.99]],"batb":[[0,1.81,54.92]],"ltp":1.82,"tv":53474.46,"id":58385184},{"trd":[[2.22,23.01]],"batb":[[0,2.22,11.9],[1,2.2,4],[2,2.18,4]],"ltp":2.22,"tv":400.7,"id":19144239}],"tv":53875.17}]}
{"op":"mcm","clk":"11797178424","pt":1722617873603,"mc":[{"id":"1.231282404","rc":[{"batb":[[0,2.22,9.9]],"ltp":2.22,"tv":400.7,"id":19144239}]}]}
{"op":"mcm","clk":"11797178551","pt":1722617874496,"mc":[{"id":"1.231282404","rc":[{"batb":[[0,2.2,4],[1,2.18,4],[2,2.08,1]],"ltp":2.22,"tv":400.7,"id":19144239}]}]}
{"op":"mcm","clk":"11797178863","pt":1722617877206,"mc":[{"id":"1.231282404","rc":[{"batb":[[0,2.22,12],[1,2.2,4],[2,2.18,4]],"ltp":2.22,"tv":400.7,"id":19144239}]}]}
{"op":"mcm","clk":"11797178938","pt":1722617877830,"mc":[{"id":"1.231282404","rc":[{"batl":[[0,2.24,4],[1,2.9,4.08],[2,6,1.56]],"ltp":2.22,"tv":400.7,"id":19144239}]}]}
{"op":"mcm","clk":"11797179465","pt":1722617881909,"mc":[{"id":"1.231282404","rc":[{"batb":[[0,2.22,10]],"ltp":2.22,"tv":400.7,"id":19144239}]}]}
{"op":"mcm","clk":"11797179639","pt":1722617883137,"mc":[{"id":"1.231282404","rc":[{"batb":[[0,2.2,4],[1,2.18,4],[2,2.08,1]],"ltp":2.22,"tv":400.7,"id":19144239}]}]}
{"op":"mcm","clk":"11797179734","pt":1722617883732,"mc":[{"id":"1.231282404","rc":[{"batl":[[0,2.9,4.08],[1,6,1.56],[2,12,1.56]],"ltp":2.22,"tv":400.7,"id":19144239}]}]}
{"op":"mcm","clk":"11797180046","pt":1722617886212,"mc":[{"id":"1.231282404","rc":[{"batb":[[0,2.22,12],[1,2.2,4],[2,2.18,4]],"ltp":2.22,"tv":400.7,"id":19144239}]}]}
{"op":"mcm","clk":"11797180560","pt":1722617890119,"mc":[{"id":"1.231282404","rc":[{"batb":[[0,2.22,10]],"ltp":2.22,"tv":400.7,"id":19144239}]}]}
{"op":"mcm","clk":"11797180723","pt":1722617891220,"mc":[{"id":"1.231282404","rc":[{"batb":[[0,2.2,4],[1,2.18,4],[2,2.08,1]],"ltp":2.22,"tv":400.7,"id":19144239}]}]}
{"op":"mcm","clk":"11797188859","pt":1722617955100,"mc":[{"id":"1.231282404","rc":[{"batl":[[2,1.9,8]],"ltp":1.82,"tv":53474.46,"id":58385184},{"batb":[[0,2.22,12],[1,2.2,4],[2,2.18,4]],"ltp":2.22,"tv":400.7,"id":19144239}]}]}
{"op":"mcm","clk":"11797189215","pt":1722617957805,"mc":[{"id":"1.231282404","rc":[{"batb":[[0,2.22,10]],"ltp":2.22,"tv":400.7,"id":19144239}]}]}
{"op":"mcm","clk":"11797189357","pt":1722617958924,"mc":[{"id":"1.231282404","rc":[{"batb":[[0,2.2,4],[1,2.18,4],[2,2.08,1]],"ltp":2.22,"tv":400.7,"id":19144239}]}]}
{"op":"mcm","clk":"11797189594","pt":1722617960797,"mc":[{"id":"1.231282404","rc":[{"batb":[[0,2.22,2],[1,2.2,4],[2,2.18,4]],"ltp":2.22,"tv":400.7,"id":19144239}]}]}
{"op":"mcm","clk":"11797190177","pt":1722617964905,"mc":[{"id":"1.231282404","rc":[{"batb":[[0,2.2,4],[1,2.18,4],[2,2.08,1]],"ltp":2.22,"tv":400.7,"id":19144239}]}]}
{"op":"mcm","clk":"11797190383","pt":1722617966008,"mc":[{"id":"1.231282404","rc":[{"batb":[[0,2.22,10],[1,2.2,4],[2,2.18,4]],"ltp":2.22,"tv":400.7,"id":19144239}]}]}
{"op":"mcm","clk":"11797190713","pt":1722617968415,"mc":[{"id":"1.231282404","rc":[{"batl":[[0,2.24,4],[1,2.9,4.08],[2,6,1.56]],"ltp":2.22,"tv":400.7,"id":19144239}]}]}
{"op":"mcm","clk":"11797190986","pt":1722617970631,"mc":[{"id":"1.231282404","rc":[{"batb":[[0,2.22,2]],"batl":[[0,2.9,4.08],[1,6,1.56],[2,12,1.56]],"ltp":2.22,"tv":400.7,"id":19144239}]}]}
{"op":"mcm","clk":"11797191284","pt":1722617972997,"mc":[{"id":"1.231282404","rc":[{"batb":[[0,2.2,4],[1,2.18,4],[2,2.08,1]],"ltp":2.22,"tv":400.7,"id":19144239}]}]}
{"op":"mcm","clk":"11797191460","pt":1722617974415,"mc":[{"id":"1.231282404","rc":[{"batb":[[0,2.22,10],[1,2.2,4],[2,2.18,4]],"ltp":2.22,"tv":400.7,"id":19144239}]}]}
{"op":"mcm","clk":"11797191952","pt":1722617978339,"mc":[{"id":"1.231282404","rc":[{"batb":[[0,2.2,4],[1,2.18,4],[2,2.08,1]],"ltp":2.22,"tv":400.7,"id":19144239}]}]}
{"op":"mcm","clk":"11797192120","pt":1722617979636,"mc":[{"id":"1.231282404","rc":[{"batb":[[0,2.22,2],[1,2.2,4],[2,2.18,4]],"ltp":2.22,"tv":400.7,"id":19144239}]}]}
{"op":"mcm","clk":"11797192617","pt":1722617983553,"mc":[{"id":"1.231282404","rc":[{"batb":[[0,2.2,4],[1,2.18,4],[2,2.08,1]],"batl":[[0,2.24,4],[1,2.9,4.08],[2,6,1.56]],"ltp":2.22,"tv":400.7,"id":19144239}]}]}
{"op":"mcm","clk":"11797192646","pt":1722617983821,"mc":[{"id":"1.231282404","rc":[{"batb":[[0,2.22,10],[1,2.2,4],[2,2.18,4]],"ltp":2.22,"tv":400.7,"id":19144239}]}]}
{"op":"mcm","clk":"11797193071","pt":1722617987664,"mc":[{"id":"1.231282404","rc":[{"batb":[[0,2.2,4],[1,2.18,4],[2,2.08,1]],"ltp":2.22,"tv":400.7,"id":19144239}]}]}
{"op":"mcm","clk":"11797193165","pt":1722617988437,"mc":[{"id":"1.231282404","rc":[{"batb":[[0,2.22,2],[1,2.2,4],[2,2.18,4]],"batl":[[0,2.9,4.08],[1,6,1.56],[2,12,1.56]],"ltp":2.22,"tv":400.7,"id":19144239}]}]}
{"op":"mcm","clk":"11797193498","pt":1722617990871,"mc":[{"id":"1.231282404","rc":[{"batb":[[0,2.2,4],[1,2.18,4],[2,2.08,1]],"ltp":2.22,"tv":400.7,"id":19144239}]}]}
{"op":"mcm","clk":"11797193644","pt":1722617992056,"mc":[{"id":"1.231282404","rc":[{"batb":[[0,2.22,10],[1,2.2,4],[2,2.18,4]],"ltp":2.22,"tv":400.7,"id":19144239}]}]}
{"op":"mcm","clk":"11797194234","pt":1722617996745,"mc":[{"id":"1.231282404","rc":[{"batb":[[0,2.2,4],[1,2.18,4],[2,2.08,1]],"ltp":2.22,"tv":400.7,"id":19144239}]}]}
{"op":"mcm","clk":"11797194456","pt":1722617998484,"mc":[{"id":"1.231282404","rc":[{"batb":[[0,2.22,2],[1,2.2,4],[2,2.18,4]],"ltp":2.22,"tv":400.7,"id":19144239}]}]}
{"op":"mcm","clk":"11797194963","pt":1722618001590,"mc":[{"id":"1.231282404","rc":[{"batb":[[0,2.2,4],[1,2.18,4],[2,2.08,1]],"ltp":2.22,"tv":400.7,"id":19144239}]}]}
{"op":"mcm","clk":"11797195007","pt":1722618001765,"mc":[{"id":"1.231282404","rc":[{"batb":[[0,2.22,10],[1,2.2,4],[2,2.18,4]],"ltp":2.22,"tv":400.7,"id":19144239}]}]}
{"op":"mcm","clk":"11797195718","pt":1722618005477,"mc":[{"id":"1.231282404","rc":[{"batb":[[0,2.22,2]],"ltp":2.22,"tv":400.7,"id":19144239}]}]}
{"op":"mcm","clk":"11797196056","pt":1722618007768,"mc":[{"id":"1.231282404","rc":[{"trd":[[1.81,15.75],[1.82,134.01],[1.83,28.14],[1.84,28.95],[1.88,30.44],[1.89,690.66],[1.9,8817.08],[1.91,2451.95],[1.92,15259.89],[1.95,6888.85],[1.96,18979.35]],"batl":[[0,1.84,38.13]],"ltp":1.82,"tv":53493.2,"id":58385184},{"trd":[[2.1,30.17],[2.22,23.01]],"batb":[[0,2.2,4],[1,2.18,4],[2,2.08,1]],"batl":[[0,2.9,4.08]],"ltp":2.22,"tv":400.72,"id":19144239}],"tv":53893.92}]}
{"op":"mcm","clk":"11797196362","pt":1722618009779,"mc":[{"id":"1.231282404","rc":[{"batb":[[0,2.22,10],[1,2.2,4],[2,2.18,4]],"ltp":2.22,"tv":400.72,"id":19144239}]}]}
{"op":"mcm","clk":"11797197043","pt":1722618014200,"mc":[{"id":"1.231282404","rc":[{"batb":[[0,2.2,4],[1,2.18,4],[2,2.08,1]],"batl":[[0,2.24,4],[1,2.9,4.08],[2,6,1.56]],"ltp":2.22,"tv":400.72,"id":19144239}]}]}
{"op":"mcm","clk":"11797197163","pt":1722618014695,"mc":[{"id":"1.231282404","rc":[{"batl":[[0,2.9,4.08],[1,6,1.56],[2,12,1.56]],"ltp":2.22,"tv":400.72,"id":19144239}]}]}
{"op":"mcm","clk":"11797197384","pt":1722618016062,"mc":[{"id":"1.231282404","rc":[{"batb":[[0,2.22,2],[1,2.2,4],[2,2.18,4]],"ltp":2.22,"tv":400.72,"id":19144239}]}]}
{"op":"mcm","clk":"11797197978","pt":1722618019469,"mc":[{"id":"1.231282404","rc":[{"batb":[[0,2.2,4],[1,2.18,4],[2,2.08,1]],"ltp":2.22,"tv":400.72,"id":19144239}]}]}
{"op":"mcm","clk":"11797198033","pt":1722618019796,"mc":[{"id":"1.231282404","rc":[{"batb":[[0,2.22,10],[1,2.2,4],[2,2.18,4]],"ltp":2.22,"tv":400.72,"id":19144239}]}]}
{"op":"mcm","clk":"11797198675","pt":1722618023675,"mc":[{"id":"1.231282404","rc":[{"batb":[[0,2.22,2]],"ltp":2.22,"tv":400.72,"id":19144239}]}]}
{"op":"mcm","clk":"11797199189","pt":1722618026369,"mc":[{"id":"1.231282404","rc":[{"batb":[[0,2.22,10]],"ltp":2.22,"tv":400.72,"id":19144239}]}]}
{"op":"mcm","clk":"11797199651","pt":1722618029600,"mc":[{"id":"1.231282404","rc":[{"batb":[[0,2.2,4],[1,2.18,4],[2,2.08,1]],"batl":[[0,2.24,4],[1,2.9,4.08],[2,6,1.56]],"ltp":2.22,"tv":400.72,"id":19144239}]}]}
{"op":"mcm","clk":"11797199772","pt":1722618030502,"mc":[{"id":"1.231282404","rc":[{"batb":[[0,2.22,2],[1,2.2,4],[2,2.18,4]],"batl":[[0,2.9,4.08],[1,6,1.56],[2,12,1.56]],"ltp":2.22,"tv":400.72,"id":19144239}]}]}
{"op":"mcm","clk":"11797200061","pt":1722618032675,"mc":[{"id":"1.231282404","rc":[{"batb":[[0,2.2,4],[1,2.18,4],[2,2.08,1]],"ltp":2.22,"tv":400.72,"id":19144239}]}]}
{"op":"mcm","clk":"11797200089","pt":1722618032891,"mc":[{"id":"1.231282404","rc":[{"batb":[[0,2.22,10],[1,2.2,4],[2,2.18,4]],"ltp":2.22,"tv":400.72,"id":19144239}]}]}
{"op":"mcm","clk":"11797200649","pt":1722618036620,"mc":[{"id":"1.231282404","rc":[{"batb":[[0,2.22,2]],"ltp":2.22,"tv":400.72,"id":19144239}]}]}
{"op":"mcm","clk":"11797201035","pt":1722618039258,"mc":[{"id":"1.231282404","rc":[{"batb":[[0,2.22,10]],"ltp":2.22,"tv":400.72,"id":19144239}]}]}
{"op":"mcm","clk":"11797201524","pt":1722618042655,"mc":[{"id":"1.231282404","rc":[{"batb":[[0,2.2,4],[1,2.18,4],[2,2.08,1]],"ltp":2.22,"tv":400.72,"id":19144239}]}]}
{"op":"mcm","clk":"11797201925","pt":1722618045574,"mc":[{"id":"1.231282404","rc":[{"batb":[[0,2.22,12],[1,2.2,4],[2,2.18,4]],"ltp":2.22,"tv":400.72,"id":19144239}]}]}
{"op":"mcm","clk":"11797202572","pt":1722618050180,"mc":[{"id":"1.231282404","rc":[{"batb":[[0,2.22,10]],"ltp":2.22,"tv":400.72,"id":19144239}]}]}
{"op":"mcm","clk":"11797202742","pt":1722618051244,"mc":[{"id":"1.231282404","rc":[{"batb":[[0,2.2,4],[1,2.18,4],[2,2.08,1]],"ltp":2.22,"tv":400.72,"id":19144239}]}]}
{"op":"mcm","clk":"11797203022","pt":1722618053138,"mc":[{"id":"1.231282404","rc":[{"batb":[[0,2.22,2],[1,2.2,4],[2,2.18,4]],"ltp":2.22,"tv":400.72,"id":19144239}]}]}
{"op":"mcm","clk":"11797203672","pt":1722618057578,"mc":[{"id":"1.231282404","rc":[{"batb":[[0,2.2,4],[1,2.18,4],[2,2.08,1]],"ltp":2.22,"tv":400.72,"id":19144239}]}]}
{"op":"mcm","clk":"11797203903","pt":1722618059164,"mc":[{"id":"1.231282404","rc":[{"batb":[[0,2.22,10],[1,2.2,4],[2,2.18,4]],"batl":[[0,2.24,4],[1,2.9,4.08],[2,6,1.56]],"ltp":2.22,"tv":400.72,"id":19144239}]}]}
{"op":"mcm","clk":"11797204095","pt":1722618060560,"mc":[{"id":"1.231282404","rc":[{"trd":[[1.81,81.03]],"batb":[[0,1.81,22.28]],"ltp":1.81,"tv":53558.48,"id":58385184}],"tv":53959.2}]}
{"op":"mcm","clk":"11797204219","pt":1722618061378,"mc":[{"id":"1.231282404","rc":[{"batb":[[0,1.81,54.92]],"ltp":1.81,"tv":53558.48,"id":58385184}]}]}
{"op":"mcm","clk":"11797204395","pt":1722618062575,"mc":[{"id":"1.231282404","rc":[{"batb":[[0,2.2,4],[1,2.18,4],[2,2.08,1]],"ltp":2.22,"tv":400.72,"id":19144239}]}]}
{"op":"mcm","clk":"11797204440","pt":1722618062892,"mc":[{"id":"1.231282404","rc":[{"batl":[[0,2.9,4.08],[1,6,1.56],[2,12,1.56]],"ltp":2.22,"tv":400.72,"id":19144239}]}]}
{"op":"mcm","clk":"11797204635","pt":1722618064220,"mc":[{"id":"1.231282404","rc":[{"batb":[[0,2.22,2],[1,2.2,4],[2,2.18,4]],"ltp":2.22,"tv":400.72,"id":19144239}]}]}
{"op":"mcm","clk":"11797205152","pt":1722618067400,"mc":[{"id":"1.231282404","rc":[{"batb":[[0,2.2,4],[1,2.18,4],[2,2.08,1]],"ltp":2.22,"tv":400.72,"id":19144239}]}]}
{"op":"mcm","clk":"11797205337","pt":1722618068783,"mc":[{"id":"1.231282404","rc":[{"batb":[[0,2.22,10],[1,2.2,4],[2,2.18,4]],"ltp":2.22,"tv":400.72,"id":19144239}]}]}
{"op":"mcm","clk":"11797205951","pt":1722618072798,"mc":[{"id":"1.231282404","rc":[{"batb":[[0,2.22,2]],"ltp":2.22,"tv":400.72,"id":19144239}]}]}
{"op":"mcm","clk":"11797206176","pt":1722618074288,"mc":[{"id":"1.231282404","rc":[{"batl":[[0,2.24,4],[1,2.9,4.08],[2,6,1.56]],"ltp":2.22,"tv":400.72,"id":19144239}]}]}
{"op":"mcm","clk":"11797206335","pt":1722618075396,"mc":[{"id":"1.231282404","rc":[{"batb":[[0,2.2,4],[1,2.18,4],[2,2.08,1]],"ltp":2.22,"tv":400.72,"id":19144239}]}]}
{"op":"mcm","clk":"11797206449","pt":1722618076188,"mc":[{"id":"1.231282404","rc":[{"batb":[[0,2.22,10],[1,2.2,4],[2,2.18,4]],"batl":[[0,2.9,4.08],[1,6,1.56],[2,12,1.56]],"ltp":2.22,"tv":400.72,"id":19144239}]}]}
{"op":"mcm","clk":"11797206927","pt":1722618079777,"mc":[{"id":"1.231282404","rc":[{"batb":[[0,2.22,2]],"ltp":2.22,"tv":400.72,"id":19144239}]}]}
{"op":"mcm","clk":"11797207272","pt":1722618082306,"mc":[{"id":"1.231282404","rc":[{"batb":[[0,2.22,10]],"ltp":2.22,"tv":400.72,"id":19144239}]}]}
{"op":"mcm","clk":"11797207736","pt":1722618085575,"mc":[{"id":"1.231282404","rc":[{"batb":[[0,2.2,4],[1,2.18,4],[2,2.08,1]],"ltp":2.22,"tv":400.72,"id":19144239}]}]}
{"op":"mcm","clk":"11797207753","pt":1722618085681,"mc":[{"id":"1.231282404","rc":[{"batb":[[0,2.22,2],[1,2.2,4],[2,2.18,4]],"ltp":2.22,"tv":400.72,"id":19144239}]}]}
{"op":"mcm","clk":"11797208060","pt":1722618088093,"mc":[{"id":"1.231282404","rc":[{"batb":[[0,2.22,10]],"ltp":2.22,"tv":400.72,"id":19144239}]}]}
{"op":"mcm","clk":"11797208239","pt":1722618089300,"mc":[{"id":"1.231282404","rc":[{"batl":[[0,2.24,4],[1,2.9,4.08],[2,6,1.56]],"ltp":2.22,"tv":400.72,"id":19144239}]}]}
{"op":"mcm","clk":"11797208539","pt":1722618091405,"mc":[{"id":"1.231282404","rc":[{"batb":[[0,2.2,4],[1,2.18,4],[2,2.08,1]],"ltp":2.22,"tv":400.72,"id":19144239}]}]}
{"op":"mcm","clk":"11797208699","pt":1722618092511,"mc":[{"id":"1.231282404","rc":[{"batb":[[0,2.22,2],[1,2.2,4],[2,2.18,4]],"batl":[[0,2.9,4.08],[1,6,1.56],[2,12,1.56]],"ltp":2.22,"tv":400.72,"id":19144239}]}]}
{"op":"mcm","clk":"11797209340","pt":1722618097015,"mc":[{"id":"1.231282404","rc":[{"batl":[[1,1.85,1976.84]],"ltp":1.81,"tv":53558.48,"id":58385184},{"batb":[[0,2.2,4],[1,2.18,4],[2,2.08,1]],"ltp":2.22,"tv":400.72,"id":19144239}]}]}
{"op":"mcm","clk":"11797209503","pt":1722618098118,"mc":[{"id":"1.231282404","rc":[{"batb":[[0,2.22,10],[1,2.2,4],[2,2.18,4]],"ltp":2.22,"tv":400.72,"id":19144239}]}]}
{"op":"mcm","clk":"11797210203","pt":1722618103390,"mc":[{"id":"1.231282404","rc":[{"batb":[[0,2.22,2]],"ltp":2.22,"tv":400.72,"id":19144239}]}]}
{"op":"mcm","clk":"11797210349","pt":1722618104494,"mc":[{"id":"1.231282404","rc":[{"batl":[[0,2.24,4],[1,2.9,4.08],[2,6,1.56]],"ltp":2.22,"tv":400.72,"id":19144239}]}]}
{"op":"mcm","clk":"11797210596","pt":1722618106503,"mc":[{"id":"1.231282404","rc":[{"batb":[[0,2.2,4],[1,2.18,4],[2,2.08,1]],"batl":[[0,2.9,4.08],[1,6,1.56],[2,12,1.56]],"ltp":2.22,"tv":400.72,"id":19144239}]}]}
{"op":"mcm","clk":"11797210639","pt":1722618106784,"mc":[{"id":"1.231282404","rc":[{"batb":[[0,2.22,10],[1,2.2,4],[2,2.18,4]],"ltp":2.22,"tv":400.72,"id":19144239}]}]}
{"op":"mcm","clk":"11797211170","pt":1722618110356,"mc":[{"id":"1.231282404","rc":[{"batb":[[0,2.2,4],[1,2.18,4],[2,2.08,1]],"ltp":2.22,"tv":400.72,"id":19144239}]}]}
{"op":"mcm","clk":"11797211560","pt":1722618113162,"mc":[{"id":"1.231282404","rc":[{"batb":[[0,2.22,12],[1,2.2,4],[2,2.18,4]],"ltp":2.22,"tv":400.72,"id":19144239}]}]}
{"op":"mcm","clk":"11797212147","pt":1722618116900,"mc":[{"id":"1.231282404","rc":[{"batb":[[0,2.22,10]],"ltp":2.22,"tv":400.72,"id":19144239}]}]}
{"op":"mcm","clk":"11797212273","pt":1722618117796,"mc":[{"id":"1.231282404","rc":[{"batb":[[0,2.2,4],[1,2.18,4],[2,2.08,1]],"ltp":2.22,"tv":400.72,"id":19144239}]}]}
{"op":"mcm","clk":"11797213360","pt":1722618125604,"mc":[{"id":"1.231282404","rc":[{"batb":[[0,1.81,54.98]],"ltp":1.81,"tv":53558.48,"id":58385184}]}]}
{"op":"mcm","clk":"11797213413","pt":1722618125881,"mc":[{"id":"1.231282404","rc":[{"batb":[[0,2.22,12],[1,2.2,4],[2,2.18,4]],"ltp":2.22,"tv":400.72,"id":19144239}]}]}
{"op":"mcm","clk":"11797213795","pt":1722618128406,"mc":[{"id":"1.231282404","rc":[{"batb":[[0,2.22,10]],"ltp":2.22,"tv":400.72,"id":19144239}]}]}
{"op":"mcm","clk":"11797213938","pt":1722618129311,"mc":[{"id":"1.231282404","rc":[{"batb":[[0,2.2,4],[1,2.18,4],[2,2.08,1]],"ltp":2.22,"tv":400.72,"id":19144239}]}]}
{"op":"mcm","clk":"11797214216","pt":1722618131313,"mc":[{"id":"1.231282404","rc":[{"batb":[[0,2.22,2],[1,2.2,4],[2,2.18,4]],"ltp":2.22,"tv":400.72,"id":19144239}]}]}
{"op":"mcm","clk":"11797214853","pt":1722618135519,"mc":[{"id":"1.231282404","rc":[{"batb":[[0,2.2,4],[1,2.18,4],[2,2.08,1]],"batl":[[0,2.24,4],[1,2.9,4.08],[2,6,1.56]],"ltp":2.22,"tv":400.72,"id":19144239}]}]}
{"op":"mcm","clk":"11797214970","pt":1722618136321,"mc":[{"id":"1.231282404","rc":[{"batl":[[0,2.9,4.08],[1,6,1.56],[2,12,1.56]],"ltp":2.22,"tv":400.72,"id":19144239}]}]}
{"op":"mcm","clk":"11797215117","pt":1722618137320,"mc":[{"id":"1.231282404","rc":[{"batb":[[0,2.22,10],[1,2.2,4],[2,2.18,4]],"ltp":2.22,"tv":400.72,"id":19144239}]}]}
{"op":"mcm","clk":"11797215749","pt":1722618141615,"mc":[{"id":"1.231282404","rc":[{"batb":[[0,2.22,2]],"ltp":2.22,"tv":400.72,"id":19144239}]}]}
{"op":"mcm","clk":"11797216130","pt":1722618144415,"mc":[{"id":"1.231282404","rc":[{"batb":[[0,2.22,10]],"ltp":2.22,"tv":400.72,"id":19144239}]}]}
{"op":"mcm","clk":"11797216648","pt":1722618148413,"mc":[{"id":"1.231282404","rc":[{"batb":[[0,2.22,2]],"ltp":2.22,"tv":400.72,"id":19144239}]}]}
{"op":"mcm","clk":"11797216861","pt":1722618149930,"mc":[{"id":"1.231282404","rc":[{"batl":[[0,2.24,4],[1,2.9,4.08],[2,6,1.56]],"ltp":2.22,"tv":400.72,"id":19144239}]}]}
{"op":"mcm","clk":"11797217044","pt":1722618151320,"mc":[{"id":"1.231282404","rc":[{"batb":[[0,2.22,10]],"batl":[[0,2.9,4.08],[1,6,1.56],[2,12,1.56]],"ltp":2.22,"tv":400.72,"id":19144239}]}]}
{"op":"mcm","clk":"11797217577","pt":1722618155045,"mc":[{"id":"1.231282404","rc":[{"batb":[[0,2.22,2]],"ltp":2.22,"tv":400.72,"id":19144239}]}]}
{"op":"mcm","clk":"11797217929","pt":1722618157632,"mc":[{"id":"1.231282404","rc":[{"batb":[[0,2.2,4],[1,2.18,4],[2,2.08,1]],"ltp":2.22,"tv":400.72,"id":19144239}]}]}
{"op":"mcm","clk":"11797217956","pt":1722618157835,"mc":[{"id":"1.231282404","rc":[{"batb":[[0,2.22,10],[1,2.2,4],[2,2.18,4]],"ltp":2.22,"tv":400.72,"id":19144239}]}]}
{"op":"mcm","clk":"11797218471","pt":1722618161541,"mc":[{"id":"1.231282404","rc":[{"batb":[[0,2.22,2]],"ltp":2.22,"tv":400.72,"id":19144239}]}]}
{"op":"mcm","clk":"11797218791","pt":1722618163938,"mc":[{"id":"1.231282404","rc":[{"batb":[[0,2.2,4],[1,2.18,4],[2,2.08,1]],"ltp":2.22,"tv":400.72,"id":19144239}]}]}
{"op":"mcm","clk":"11797219080","pt":1722618166022,"mc":[{"id":"1.231282404","rc":[{"batb":[[0,2.22,10],[1,2.2,4],[2,2.18,4]],"ltp":2.22,"tv":400.72,"id":19144239}]}]}
{"op":"mcm","clk":"11797219758","pt":1722618170850,"mc":[{"id":"1.231282404","rc":[{"batb":[[0,2.2,4],[1,2.18,4],[2,2.08,1]],"ltp":2.22,"tv":400.72,"id":19144239}]}]}
{"op":"mcm","clk":"11797219877","pt":1722618171755,"mc":[{"id":"1.231282404","rc":[{"batb":[[0,2.22,2],[1,2.2,4],[2,2.18,4]],"ltp":2.22,"tv":400.72,"id":19144239}]}]}
{"op":"mcm","clk":"11797220272","pt":1722618174557,"mc":[{"id":"1.231282404","rc":[{"batb":[[0,2.2,4],[1,2.18,4],[2,2.08,1]],"ltp":2.22,"tv":400.72,"id":19144239}]}]}
{"op":"mcm","clk":"11797220324","pt":1722618174862,"mc":[{"id":"1.231282404","rc":[{"batb":[[0,2.22,10],[1,2.2,4],[2,2.18,4]],"ltp":2.22,"tv":400.72,"id":19144239}]}]}
{"op":"mcm","clk":"11797220854","pt":1722618178466,"mc":[{"id":"1.231282404","rc":[{"batb":[[0,2.22,2]],"ltp":2.22,"tv":400.72,"id":19144239}]}]}
{"op":"mcm","clk":"11797221103","pt":1722618180180,"mc":[{"id":"1.231282404","rc":[{"batl":[[0,2.24,4],[1,2.9,4.08],[2,6,1.56]],"ltp":2.22,"tv":400.72,"id":19144239}]}]}
{"op":"mcm","clk":"11797221290","pt":1722618181367,"mc":[{"id":"1.231282404","rc":[{"batb":[[0,2.2,4],[1,2.18,4],[2,2.08,1]],"batl":[[0,2.9,4.08],[1,6,1.56],[2,12,1.56]],"ltp":2.22,"tv":400.72,"id":19144239}]}]}
{"op":"mcm","clk":"11797221394","pt":1722618181859,"mc":[{"id":"1.231282404","rc":[{"batb":[[0,2.22,10],[1,2.2,4],[2,2.18,4]],"ltp":2.22,"tv":400.72,"id":19144239}]}]}
{"op":"mcm","clk":"11797222002","pt":1722618185544,"mc":[{"id":"1.231282404","rc":[{"batb":[[0,2.22,2]],"ltp":2.22,"tv":400.72,"id":19144239}]}]}
{"op":"mcm","clk":"11797222432","pt":1722618188181,"mc":[{"id":"1.231282404","rc":[{"batb":[[0,2.22,10]],"ltp":2.22,"tv":400.72,"id":19144239}]}]}
{"op":"mcm","clk":"11797222965","pt":1722618191472,"mc":[{"id":"1.231282404","rc":[{"batb":[[0,2.2,4],[1,2.18,4],[2,2.08,1]],"ltp":2.22,"tv":400.72,"id":19144239}]}]}
{"op":"mcm","clk":"11797223020","pt":1722618191774,"mc":[{"id":"1.231282404","rc":[{"batb":[[0,2.22,2],[1,2.2,4],[2,2.18,4]],"ltp":2.22,"tv":400.72,"id":19144239}]}]}
{"op":"mcm","clk":"11797223528","pt":1722618194677,"mc":[{"id":"1.231282404","rc":[{"batb":[[0,2.22,10]],"ltp":2.22,"tv":400.72,"id":19144239}]}]}
{"op":"mcm","clk":"11797223627","pt":1722618195283,"mc":[{"id":"1.231282404","rc":[{"batl":[[0,2.24,4],[1,2.9,4.08],[2,6,1.56]],"ltp":2.22,"tv":400.72,"id":19144239}]}]}
{"op":"mcm","clk":"11797224138","pt":1722618198661,"mc":[{"id":"1.231282404","rc":[{"batb":[[0,2.2,4],[1,2.18,4],[2,2.08,1]],"batl":[[0,2.9,4.08],[1,6,1.56],[2,12,1.56]],"ltp":2.22,"tv":400.72,"id":19144239}]}]}
{"op":"mcm","clk":"11797224579","pt":1722618201387,"mc":[{"id":"1.231282404","rc":[{"batb":[[0,2.22,12],[1,2.2,4],[2,2.18,4]],"ltp":2.22,"tv":400.72,"id":19144239}]}]}
{"op":"mcm","clk":"11797224803","pt":1722618202783,"mc":[{"id":"1.231282404","rc":[{"batl":[[1,1.85,7.61]],"ltp":1.81,"tv":53558.48,"id":58385184}]}]}
{"op":"mcm","clk":"11797225370","pt":1722618206287,"mc":[{"id":"1.231282404","rc":[{"batl":[[0,1.84,21.07]],"ltp":1.81,"tv":53558.48,"id":58385184},{"batb":[[0,2.22,10],[1,2.08,1],[2,1.9,73.22]],"ltp":2.22,"tv":400.72,"id":19144239}]}]}
{"op":"mcm","clk":"11797225449","pt":1722618206884,"mc":[{"id":"1.231282404","rc":[{"batl":[[0,1.84,17.07],[1,1.85,3.61]],"ltp":1.81,"tv":53558.48,"id":58385184},{"batb":[[0,2.08,1],[1,1.9,73.22],[2,1.74,23.94]],"ltp":2.22,"tv":400.72,"id":19144239}]}]}
{"op":"mcm","clk":"11797225698","pt":1722618208490,"mc":[{"id":"1.231282404","rc":[{"batl":[[0,1.85,3.61],[1,1.9,8],[2,1.92,5]],"ltp":1.81,"tv":53558.48,"id":58385184},{"batb":[[0,2.1,2],[1,2.08,1],[2,1.9,73.22]],"ltp":2.22,"tv":400.72,"id":19144239}]}]}
{"op":"mcm","clk":"11797226005","pt":1722618210497,"mc":[{"id":"1.231282404","rc":[{"batb":[[0,1.81,58.98]],"ltp":1.81,"tv":53558.48,"id":58385184},{"batl":[[0,2.22,4],[1,2.24,4],[2,2.9,4.08]],"ltp":2.22,"tv":400.72,"id":19144239}]}]}
{"op":"mcm","clk":"11797226080","pt":1722618211007,"mc":[{"id":"1.231282404","rc":[{"batb":[[0,2.08,1],[1,1.9,73.22],[2,1.74,23.94]],"ltp":2.22,"tv":400.72,"id":19144239}]}]}
{"op":"mcm","clk":"11797245786","pt":1722618333928,"mc":[{"id":"1.231282404","rc":[{"trd":[[1.81,83.07]],"batb":[[0,1.81,57.96]],"ltp":1.81,"tv":53560.52,"id":58385184}],"tv":53961.24}]}
{"op":"mcm","clk":"11797246369","pt":1722618337168,"mc":[{"id":"1.231282404","rc":[{"batb":[[0,1.81,58.98]],"ltp":1.81,"tv":53560.52,"id":58385184}]}]}
{"op":"mcm","clk":"11797262346","pt":1722618425765,"mc":[{"id":"1.231282404","rc":[{"batb":[[0,1.81,59.04]],"ltp":1.81,"tv":53560.52,"id":58385184}]}]}
{"op":"mcm","clk":"11797265448","pt":1722618440660,"mc":[{"id":"1.231282404","rc":[{"batb":[[1,1.75,129.83],[2,1.74,17.32]],"ltp":1.81,"tv":53560.52,"id":58385184}]}]}
{"op":"mcm","clk":"11797316360","pt":1722618726183,"mc":[{"id":"1.231282404","rc":[{"batb":[[0,1.81,59.1]],"ltp":1.81,"tv":53560.52,"id":58385184}]}]}
{"op":"mcm","clk":"11797320118","pt":1722618747852,"mc":[{"id":"1.231282404","rc":[{"trd":[[1.85,0.14]],"batl":[[0,1.85,3.59]],"ltp":1.85,"tv":53560.54,"id":58385184},{"trd":[[2.16,0.02]],"ltp":2.16,"tv":400.74,"id":19144239}],"tv":53961.28}]}
{"op":"mcm","clk":"11797355771","pt":1722618875494,"mc":[{"id":"1.231282404","rc":[{"trd":[[1.81,118.91],[1.82,134.25]],"batb":[[0,1.81,41.06]],"ltp":1.81,"tv":53596.62,"id":58385184}],"tv":53997.36}]}
{"op":"mcm","clk":"11797356521","pt":1722618879106,"mc":[{"id":"1.231282404","rc":[{"batb":[[0,1.81,54.92]],"ltp":1.81,"tv":53596.62,"id":58385184}]}]}
{"op":"mcm","clk":"11797358780","pt":1722618890712,"mc":[{"id":"1.231282404","rc":[{"batb":[[0,1.81,58.92]],"ltp":1.81,"tv":53596.62,"id":58385184}]}]}
{"op":"mcm","clk":"11797384857","pt":1722619026515,"mc":[{"id":"1.231282404","rc":[{"batb":[[0,1.81,58.98]],"ltp":1.81,"tv":53596.62,"id":58385184}]}]}
{"op":"mcm","clk":"11797393555","pt":1722619074159,"mc":[{"id":"1.231282404","rc":[{"trd":[[2.22,24.81]],"batl":[[0,2.22,3.1]],"ltp":2.22,"tv":402.54,"id":19144239}],"tv":53999.16}]}
{"op":"mcm","clk":"11797411852","pt":1722619174881,"mc":[{"id":"1.231282404","rc":[{"trd":[[1.85,0.19]],"batl":[[0,1.85,3.54]],"ltp":1.85,"tv":53596.67,"id":58385184},{"trd":[[2.16,0.06]],"ltp":2.16,"tv":402.58,"id":19144239}],"tv":53999.26}]}
{"op":"mcm","clk":"11797435060","pt":1722619301035,"mc":[{"id":"1.231282404","rc":[{"batl":[[2,2.9,4.56]],"ltp":2.16,"tv":402.58,"id":19144239}]}]}
{"op":"mcm","clk":"11797439745","pt":1722619326471,"mc":[{"id":"1.231282404","rc":[{"batb":[[0,1.81,59.16]],"ltp":1.85,"tv":53596.67,"id":58385184}]}]}
{"op":"mcm","clk":"11797448463","pt":1722619373385,"mc":[{"id":"1.231282404","rc":[{"trd":[[1.81,119.61],[1.82,134.73]],"batb":[[0,1.81,58.57]],"ltp":1.81,"tv":53597.85,"id":58385184}],"tv":54000.44}]}
{"op":"mcm","clk":"11797448947","pt":1722619375885,"mc":[{"id":"1.231282404","rc":[{"batb":[[0,1.81,58.92]],"ltp":1.81,"tv":53597.85,"id":58385184}]}]}
{"op":"mcm","clk":"11797495738","pt":1722619626818,"mc":[{"id":"1.231282404","rc":[{"batb":[[0,1.81,59.1]],"ltp":1.81,"tv":53597.85,"id":58385184}]}]}
{"op":"mcm","clk":"11797504544","pt":1722619675967,"mc":[{"id":"1.231282404","rc":[{"trd":[[1.85,3.73],[1.9,8825.08],[1.92,15264.89]],"batb":[[0,1.82,10.18],[1,1.81,58.92],[2,1.75,129.83]],"batl":[[0,6,1.56],[1,12,1.56],[2,1.92,0]],"ltp":1.92,"tv":53614.39,"id":58385184},{"trd":[[2.08,10.61],[2.1,37.4],[2.16,3.09]],"batb":[[0,1.91,43.74]],"batl":[[0,2.16,24.37],[1,2.22,3.1],[2,2.24,4]],"ltp":2.08,"tv":419.46,"id":19144239}],"tv":54033.86}]}
{"op":"mcm","clk":"11797504858","pt":1722619677775,"mc":[{"id":"1.231282404","rc":[{"batl":[[0,2.08,3.98],[1,6,1.56],[2,12,1.56]],"ltp":1.92,"tv":53614.39,"id":58385184}]}]}
{"op":"mcm","clk":"11797505113","pt":1722619679288,"mc":[{"id":"1.231282404","rc":[{"batb":[[0,1.81,59.1],[1,1.75,129.83],[2,1.74,17.32]],"ltp":1.92,"tv":53614.39,"id":58385184},{"batb":[[0,1.91,33.74]],"ltp":2.08,"tv":419.46,"id":19144239}]}]}
{"op":"mcm","clk":"11797507031","pt":1722619690600,"mc":[{"id":"1.231282404","rc":[{"batb":[[0,1.82,10.18],[1,1.81,58.92],[2,1.75,129.83]],"ltp":1.92,"tv":53614.39,"id":58385184},{"batb":[[0,1.92,10]],"ltp":2.08,"tv":419.46,"id":19144239}]}]}
{"op":"mcm","clk":"11797507510","pt":1722619693291,"mc":[{"id":"1.231282404","rc":[{"batl":[[0,2.1,3.95]],"ltp":1.92,"tv":53614.39,"id":58385184},{"batb":[[0,1.92,43.57]],"ltp":2.08,"tv":419.46,"id":19144239}]}]}
{"op":"mcm","clk":"11797507681","pt":1722619694225,"mc":[{"id":"1.231282404","rc":[{"batb":[[0,1.81,59.1],[1,1.75,129.83],[2,1.74,17.32]],"ltp":1.92,"tv":53614.39,"id":58385184},{"batb":[[0,1.92,33.57]],"ltp":2.08,"tv":419.46,"id":19144239}]}]}
{"op":"mcm","clk":"11797511781","pt":1722619716320,"mc":[{"id":"1.231282404","rc":[{"batb":[[0,1.82,10.18],[1,1.81,58.92],[2,1.75,129.83]],"ltp":1.92,"tv":53614.39,"id":58385184},{"batb":[[0,1.93,10],[1,1.92,33.57],[2,1.9,73.22]],"ltp":2.08,"tv":419.46,"id":19144239}]}]}
{"op":"mcm","clk":"11797512455","pt":1722619719827,"mc":[{"id":"1.231282404","rc":[{"batb":[[0,1.81,59.1],[1,1.75,129.83],[2,1.74,17.32]],"ltp":1.92,"tv":53614.39,"id":58385184},{"batb":[[0,1.92,33.57],[1,1.9,73.22],[2,1.74,23.94]],"ltp":2.08,"tv":419.46,"id":19144239}]}]}
{"op":"mcm","clk":"11797513904","pt":1722619728047,"mc":[{"id":"1.231282404","rc":[{"batb":[[0,1.82,10.18],[1,1.81,58.92],[2,1.75,129.83]],"ltp":1.92,"tv":53614.39,"id":58385184},{"batb":[[0,1.93,10],[1,1.92,33.57],[2,1.9,73.22]],"ltp":2.08,"tv":419.46,"id":19144239}]}]}
{"op":"mcm","clk":"11797514463","pt":1722619731301,"mc":[{"id":"1.231282404","rc":[{"batb":[[0,1.81,59.1],[1,1.75,129.83],[2,1.74,17.32]],"ltp":1.92,"tv":53614.39,"id":58385184},{"batb":[[0,1.92,33.57],[1,1.9,73.22],[2,1.74,23.94]],"ltp":2.08,"tv":419.46,"id":19144239}]}]}
{"op":"mcm","clk":"11797518724","pt":1722619755347,"mc":[{"id":"1.231282404","rc":[{"batb":[[0,1.82,10.18],[1,1.81,58.92],[2,1.75,129.83]],"ltp":1.92,"tv":53614.39,"id":58385184},{"batb":[[0,1.94,10],[1,1.93,50],[2,1.92,33.57]],"ltp":2.08,"tv":419.46,"id":19144239}]}]}
{"op":"mcm","clk":"11797518935","pt":1722619756662,"mc":[{"id":"1.231282404","rc":[{"batl":[[0,6,1.56],[1,12,1.56],[2,12,0]],"ltp":1.92,"tv":53614.39,"id":58385184}]}]}
{"op":"mcm","clk":"11797518979","pt":1722619756825,"mc":[{"id":"1.231282404","rc":[{"batl":[[0,2.06,4.03],[1,6,1.56],[2,12,1.56]],"ltp":1.92,"tv":53614.39,"id":58385184}]}]}
{"op":"mcm","clk":"11797519336","pt":1722619758836,"mc":[{"id":"1.231282404","rc":[{"batb":[[0,1.81,59.1],[1,1.75,129.83],[2,1.74,17.32]],"ltp":1.92,"tv":53614.39,"id":58385184},{"batb":[[0,1.93,50],[1,1.92,33.57],[2,1.9,73.22]],"ltp":2.08,"tv":419.46,"id":19144239}]}]}
{"op":"mcm","clk":"11797522674","pt":1722619777173,"mc":[{"id":"1.231282404","rc":[{"batb":[[0,1.82,10.18],[1,1.81,54.92],[2,1.75,129.83]],"ltp":1.92,"tv":53614.39,"id":58385184},{"batb":[[0,1.97,10],[1,1.96,1969.23],[2,1.93,50]],"batl":[[1,2.9,4.56],[2,6,1.56]],"ltp":2.08,"tv":419.46,"id":19144239}]}]}
{"op":"mcm","clk":"11797523327","pt":1722619780680,"mc":[{"id":"1.231282404","rc":[{"batb":[[0,1.81,55.1],[1,1.75,129.83],[2,1.74,17.32]],"ltp":1.92,"tv":53614.39,"id":58385184},{"batb":[[0,1.96,1969.23],[1,1.93,50],[2,1.9,73.22]],"ltp":2.08,"tv":419.46,"id":19144239}]}]}
{"op":"mcm","clk":"11797527151","pt":1722619801421,"mc":[{"id":"1.231282404","rc":[{"batb":[[0,1.82,10.18],[1,1.81,54.92],[2,1.75,129.83]],"ltp":1.92,"tv":53614.39,"id":58385184},{"batb":[[0,1.97,10],[1,1.96,1969.23],[2,1.93,50]],"ltp":2.08,"tv":419.46,"id":19144239}]}]}
{"op":"mcm","clk":"11797527877","pt":1722619805010,"mc":[{"id":"1.231282404","rc":[{"batb":[[0,1.81,55.1],[1,1.75,129.83],[2,1.74,17.32]],"ltp":1.92,"tv":53614.39,"id":58385184},{"batb":[[0,1.96,1969.23],[1,1.93,50],[2,1.9,73.22]],"ltp":2.08,"tv":419.46,"id":19144239}]}]}
{"op":"mcm","clk":"11797528387","pt":1722619807531,"mc":[{"id":"1.231282404","rc":[{"batb":[[0,1.82,10.18],[1,1.81,54.92],[2,1.75,129.83]],"ltp":1.92,"tv":53614.39,"id":58385184},{"batb":[[0,1.97,10],[1,1.96,1969.23],[2,1.93,50]],"ltp":2.08,"tv":419.46,"id":19144239}]}]}
{"op":"mcm","clk":"11797528927","pt":1722619810335,"mc":[{"id":"1.231282404","rc":[{"batl":[[0,2.04,17.07],[1,2.06,4.03],[2,6,1.56]],"ltp":1.92,"tv":53614.39,"id":58385184}]}]}
{"op":"mcm","clk":"11797529096","pt":1722619811130,"mc":[{"id":"1.231282404","rc":[{"batb":[[0,1.81,55.1],[1,1.75,129.83],[2,1.74,17.32]],"ltp":1.92,"tv":53614.39,"id":58385184},{"batb":[[0,1.96,1969.23],[1,1.93,50],[2,1.9,73.22]],"ltp":2.08,"tv":419.46,"id":19144239}]}]}
{"op":"mcm","clk":"11797531525","pt":1722619824159,"mc":[{"id":"1.231282404","rc":[{"trd":[[2.16,51.83]],"batb":[[0,2.16,65.79],[1,1.96,1969.23],[2,1.93,50]],"batl":[[0,2.9,4.56],[1,6,1.56],[2,12,1.56]],"ltp":2.16,"tv":468.2,"id":19144239}],"tv":54082.6}]}
{"op":"mcm","clk":"11797531869","pt":1722619826023,"mc":[{"id":"1.231282404","rc":[{"batb":[[0,1.82,10.18],[1,1.81,54.92],[2,1.75,129.83]],"ltp":1.92,"tv":53614.39,"id":58385184},{"batb":[[0,2.18,12],[1,2.16,65.79],[2,1.96,1969.23]],"ltp":2.16,"tv":468.2,"id":19144239}]}]}
{"op":"mcm","clk":"11797532075","pt":1722619827040,"mc":[{"id":"1.231282404","rc":[{"trd":[[1.84,36.95],[1.85,4.65]],"batb":[[0,1.82,14.18]],"batl":[[0,1.85,3.54],[1,1.86,4.46]],"ltp":1.85,"tv":53623.31,"id":58385184},{"batb":[[0,2.18,16]],"ltp":2.16,"tv":468.2,"id":19144239}],"tv":54091.52}]}
{"op":"mcm","clk":"11797532203","pt":1722619827742,"mc":[{"id":"1.231282404","rc":[{"batb":[[1,1.75,129.83],[2,1.74,17.32]],"ltp":1.85,"tv":53623.31,"id":58385184}]}]}
{"op":"mcm","clk":"11797532521","pt":1722619829447,"mc":[{"id":"1.231282404","rc":[{"batl":[[0,1.84,4.51],[1,1.85,3.54]],"ltp":1.85,"tv":53623.31,"id":58385184}]}]}
{"op":"mcm","clk":"11797533237","pt":1722619833353,"mc":[{"id":"1.231282404","rc":[{"batb":[[2,1.93,50]],"ltp":2.16,"tv":468.2,"id":19144239}]}]}
{"op":"mcm","clk":"11797533864","pt":1722619836482,"mc":[{"id":"1.231282404","rc":[{"batb":[[0,2.18,14]],"ltp":2.16,"tv":468.2,"id":19144239}]}]}
{"op":"mcm","clk":"11797534065","pt":1722619837493,"mc":[{"id":"1.231282404","rc":[{"batb":[[0,1.82,4.18]],"ltp":1.85,"tv":53623.31,"id":58385184},{"batb":[[0,2.18,4]],"ltp":2.16,"tv":468.2,"id":19144239}]}]}
{"op":"mcm","clk":"11797534167","pt":1722619837954,"mc":[{"id":"1.231282404","rc":[{"trd":[[1.82,135.09]],"batb":[[0,1.81,54.92]],"batl":[[1,6,1.56],[2,12,1.56]],"ltp":1.82,"tv":53623.67,"id":58385184}],"tv":54091.88}]}
{"op":"mcm","clk":"11797534677","pt":1722619840488,"mc":[{"id":"1.231282404","rc":[{"batb":[[0,2.2,12],[1,2.18,4],[2,2.16,65.79]],"ltp":2.16,"tv":468.2,"id":19144239}]}]}
{"op":"mcm","clk":"11797534764","pt":1722619840993,"mc":[{"id":"1.231282404","rc":[{"batl":[[0,6,1.56],[1,12,1.56],[2,12,0]],"ltp":1.82,"tv":53623.67,"id":58385184}]}]}
{"op":"mcm","clk":"11797535014","pt":1722619842158,"mc":[{"id":"1.231282404","rc":[{"trd":[[1.84,44.95]],"batb":[[0,1.81,58.92]],"ltp":1.84,"tv":53631.67,"id":58385184},{"batb":[[0,2.2,16]],"batl":[[0,2.22,4],[1,2.24,4],[2,2.9,4.56]],"ltp":2.16,"tv":468.2,"id":19144239}],"tv":54099.88}]}
{"op":"mcm","clk":"11797535191","pt":1722619843177,"mc":[{"id":"1.231282404","rc":[{"trd":[[1.83,37.2]],"ltp":1.83,"tv":53640.73,"id":58385184}],"tv":54108.94}]}
{"op":"mcm","clk":"11797535378","pt":1722619844181,"mc":[{"id":"1.231282404","rc":[{"batb":[[0,1.82,10],[1,1.81,58.92],[2,1.75,129.83]],"ltp":1.83,"tv":53640.73,"id":58385184}]}]}
{"op":"mcm","clk":"11797535596","pt":1722619845359,"mc":[{"id":"1.231282404","rc":[{"batb":[[0,1.82,14.8]],"ltp":1.83,"tv":53640.73,"id":58385184},{"batb":[[0,2.2,14]],"ltp":2.16,"tv":468.2,"id":19144239}]}]}
{"op":"mcm","clk":"11797535774","pt":1722619846362,"mc":[{"id":"1.231282404","rc":[{"batb":[[0,2.2,4]],"ltp":2.16,"tv":468.2,"id":19144239}]}]}
{"op":"mcm","clk":"11797535875","pt":1722619846951,"mc":[{"id":"1.231282404","rc":[{"batb":[[0,2.18,4],[1,2.16,65.79],[2,1.93,50]],"ltp":2.16,"tv":468.2,"id":19144239}]}]}
{"op":"mcm","clk":"11797536630","pt":1722619851175,"mc":[{"id":"1.231282404","rc":[{"batb":[[0,1.82,4.8]],"ltp":1.83,"tv":53640.73,"id":58385184}]}]}
{"op":"mcm","clk":"11797537673","pt":1722619857194,"mc":[{"id":"1.231282404","rc":[{"trd":[[1.85,9.36],[1.86,2.7]],"batb":[[0,1.82,8.8]],"batl":[[0,1.86,8.71],[1,6,1.56],[2,12,1.56]],"ltp":1.86,"tv":53648.14,"id":58385184},{"trd":[[2.18,4]],"batb":[[0,2.16,69.79],[1,1.93,50],[2,1.9,73.22]],"ltp":2.18,"tv":472.2,"id":19144239}],"tv":54120.35}]}
{"op":"mcm","clk":"11797544259","pt":1722619892993,"mc":[{"id":"1.231282404","rc":[{"batl":[[0,1.86,8.86]],"ltp":1.86,"tv":53648.14,"id":58385184}]}]}
{"op":"mcm","clk":"11797549499","pt":1722619922378,"mc":[{"id":"1.231282404","rc":[{"batl":[[1,1.98,25.25],[2,6,1.56]],"ltp":1.86,"tv":53648.14,"id":58385184}]}]}
{"op":"mcm","clk":"11797550393","pt":1722619926772,"mc":[{"id":"1.231282404","rc":[{"batb":[[1,1.81,59.11]],"ltp":1.86,"tv":53648.14,"id":58385184}]}]}
{"op":"mcm","clk":"11797571117","pt":1722620037490,"mc":[{"id":"1.231282404","rc":[{"batb":[[0,2.18,4.89],[1,2.16,69.79],[2,1.93,50]],"ltp":2.18,"tv":472.2,"id":19144239}]}]}
{"op":"mcm","clk":"11797571283","pt":1722620038493,"mc":[{"id":"1.231282404","rc":[{"batb":[[1,1.81,4.19]],"ltp":1.86,"tv":53648.14,"id":58385184},{"batb":[[0,2.18,8.89]],"ltp":2.18,"tv":472.2,"id":19144239}]}]}
{"op":"mcm","clk":"11797571422","pt":1722620039180,"mc":[{"id":"1.231282404","rc":[{"batb":[[0,1.82,4.8],[1,1.75,130.02],[2,1.74,17.32]],"ltp":1.86,"tv":53648.14,"id":58385184},{"batb":[[0,2.2,12],[1,2.18,8.89],[2,2.16,69.79]],"batl":[[0,2.9,4.56],[1,6,1.56],[2,12,1.56]],"ltp":2.18,"tv":472.2,"id":19144239}]}]}
{"op":"mcm","clk":"11797571608","pt":1722620040200,"mc":[{"id":"1.231282404","rc":[{"batb":[[0,1.76,40.74],[1,1.75,129.83]],"ltp":1.86,"tv":53648.14,"id":58385184}]}]}
{"op":"mcm","clk":"11797571858","pt":1722620041389,"mc":[{"id":"1.231282404","rc":[{"batb":[[0,2.2,10]],"ltp":2.18,"tv":472.2,"id":19144239}]}]}
{"op":"mcm","clk":"11797572258","pt":1722620043490,"mc":[{"id":"1.231282404","rc":[{"batb":[[0,1.81,55.11],[1,1.76,40.55],[2,1.75,129.83]],"ltp":1.86,"tv":53648.14,"id":58385184},{"batb":[[0,2.18,4],[1,2.16,69.79],[2,1.93,50]],"ltp":2.18,"tv":472.2,"id":19144239}]}]}
{"op":"mcm","clk":"11797572480","pt":1722620044512,"mc":[{"id":"1.231282404","rc":[{"batl":[[0,1.86,4.86]],"ltp":1.86,"tv":53648.14,"id":58385184},{"batb":[[0,2.2,2],[1,2.18,4],[2,2.16,69.79]],"ltp":2.18,"tv":472.2,"id":19144239}]}]}
{"op":"mcm","clk":"11797573170","pt":1722620048243,"mc":[{"id":"1.231282404","rc":[{"batb":[[0,2.18,4],[1,2.16,69.79],[2,1.93,50]],"ltp":2.18,"tv":472.2,"id":19144239}]}]}
{"op":"mcm","clk":"11797573359","pt":1722620049189,"mc":[{"id":"1.231282404","rc":[{"batb":[[0,2.2,10],[1,2.18,4],[2,2.16,69.79]],"ltp":2.18,"tv":472.2,"id":19144239}]}]}
{"op":"mcm","clk":"11797574121","pt":1722620053398,"mc":[{"id":"1.231282404","rc":[{"batb":[[0,1.81,59.11]],"ltp":1.86,"tv":53648.14,"id":58385184},{"batb":[[0,2.2,4]],"batl":[[0,2.22,4],[1,2.24,4],[2,2.9,4.56]],"ltp":2.18,"tv":472.2,"id":19144239}]}]}
{"op":"mcm","clk":"11797580070","pt":1722620084679,"mc":[{"id":"1.231282404","rc":[{"batb":[[1,2.18,9.23]],"ltp":2.18,"tv":472.2,"id":19144239}]}]}
{"op":"mcm","clk":"11797580158","pt":1722620085156,"mc":[{"id":"1.231282404","rc":[{"batb":[[1,1.75,129.83],[2,1.74,17.32]],"ltp":1.86,"tv":53648.14,"id":58385184},{"batb":[[0,2.18,9.23],[1,2.16,69.79],[2,1.93,50]],"ltp":2.18,"tv":472.2,"id":19144239}]}]}
{"op":"mcm","clk":"11797580546","pt":1722620087320,"mc":[{"id":"1.231282404","rc":[{"batb":[[0,1.82,4.8],[1,1.81,59.11],[2,1.75,129.83]],"ltp":1.86,"tv":53648.14,"id":58385184}]}]}
{"op":"mcm","clk":"11797582712","pt":1722620098748,"mc":[{"id":"1.231282404","rc":[{"batb":[[0,1.82,8.8]],"batl":[[0,1.84,4],[1,1.85,4],[2,1.86,4.86]],"ltp":1.86,"tv":53648.14,"id":58385184}]}]}
{"op":"mcm","clk":"11797583056","pt":1722620100435,"mc":[{"id":"1.231282404","rc":[{"batl":[[2,1.98,25.4]],"ltp":1.86,"tv":53648.14,"id":58385184}]}]}
{"op":"mcm","clk":"11797583888","pt":1722620104341,"mc":[{"id":"1.231282404","rc":[{"batb":[[0,1.82,4.8],[1,1.75,130.02],[2,1.74,17.32]],"ltp":1.86,"tv":53648.14,"id":58385184},{"batb":[[0,2.2,12],[1,2.18,9.23],[2,2.16,69.79]],"batl":[[0,2.9,4.56],[1,6,1.56],[2,12,1.56]],"ltp":2.18,"tv":472.2,"id":19144239}]}]}
{"op":"mcm","clk":"11797584170","pt":1722620105555,"mc":[{"id":"1.231282404","rc":[{"batb":[[0,1.76,40.58],[1,1.75,129.83]],"ltp":1.86,"tv":53648.14,"id":58385184},{"batb":[[1,2.18,4]],"ltp":2.18,"tv":472.2,"id":19144239}]}]}
{"op":"mcm","clk":"11797584445","pt":1722620106834,"mc":[{"id":"1.231282404","rc":[{"batb":[[0,2.2,10]],"ltp":2.18,"tv":472.2,"id":19144239}]}]}
{"op":"mcm","clk":"11797584823","pt":1722620108637,"mc":[{"id":"1.231282404","rc":[{"batb":[[0,1.81,55.11],[1,1.76,40.39],[2,1.75,129.83]],"batl":[[0,1.98,25.4],[1,6,1.56],[2,12,1.56]],"ltp":1.86,"tv":53648.14,"id":58385184},{"batb":[[0,2.18,4],[1,2.16,69.79],[2,1.93,50]],"ltp":2.18,"tv":472.2,"id":19144239}]}]}
{"op":"mcm","clk":"11797585848","pt":1722620113831,"mc":[{"id":"1.231282404","rc":[{"batb":[[0,1.81,59.11]],"ltp":1.86,"tv":53648.14,"id":58385184},{"batl":[[0,2.22,4],[1,2.24,4],[2,2.9,4.56]],"ltp":2.18,"tv":472.2,"id":19144239}]}]}
{"op":"mcm","clk":"11797589146","pt":1722620131075,"mc":[{"id":"1.231282404","rc":[{"batb":[[1,1.75,129.83],[2,1.74,17.32]],"ltp":1.86,"tv":53648.14,"id":58385184},{"batb":[[0,2.18,8.63]],"ltp":2.18,"tv":472.2,"id":19144239}]}]}
{"op":"mcm","clk":"11797591856","pt":1722620143981,"mc":[{"id":"1.231282404","rc":[{"batl":[[0,1.85,4],[1,1.98,25.4],[2,6,1.56]],"ltp":1.86,"tv":53648.14,"id":58385184}]}]}
{"op":"mcm","clk":"11797592491","pt":1722620147156,"mc":[{"id":"1.231282404","rc":[{"batb":[[0,1.82,4.8],[1,1.81,59.11],[2,1.75,129.83]],"ltp":1.86,"tv":53648.14,"id":58385184}]}]}
{"op":"mcm","clk":"11797594926","pt":1722620159132,"mc":[{"id":"1.231282404","rc":[{"batb":[[0,1.82,8.8]],"batl":[[0,1.84,4],[1,1.85,4],[2,1.98,25.4]],"ltp":1.86,"tv":53648.14,"id":58385184}]}]}
{"op":"mcm","clk":"11797595978","pt":1722620164430,"mc":[{"id":"1.231282404","rc":[{"batb":[[0,1.82,4.8],[1,1.75,130.02],[2,1.74,17.32]],"ltp":1.86,"tv":53648.14,"id":58385184},{"batb":[[0,2.2,12],[1,2.18,8.63],[2,2.16,69.79]],"batl":[[0,2.9,4.56],[1,6,1.56],[2,12,1.56]],"ltp":2.18,"tv":472.2,"id":19144239}]}]}
{"op":"mcm","clk":"11797596431","pt":1722620166874,"mc":[{"id":"1.231282404","rc":[{"batb":[[0,1.76,40.58],[1,1.75,129.83]],"ltp":1.86,"tv":53648.14,"id":58385184},{"batb":[[0,2.2,10],[1,2.18,4]],"ltp":2.18,"tv":472.2,"id":19144239}]}]}
{"op":"mcm","clk":"11797596736","pt":1722620168465,"mc":[{"id":"1.231282404","rc":[{"batl":[[0,1.98,25.4],[1,6,1.56],[2,12,1.56]],"ltp":1.86,"tv":53648.14,"id":58385184},{"batb":[[0,2.18,4],[1,2.16,69.79],[2,1.93,50]],"ltp":2.18,"tv":472.2,"id":19144239}]}]}
{"op":"mcm","clk":"11797596931","pt":1722620169467,"mc":[{"id":"1.231282404","rc":[{"batb":[[0,1.81,55.11],[1,1.76,40.39],[2,1.75,129.83]],"ltp":1.86,"tv":53648.14,"id":58385184},{"batb":[[0,2.22,2],[1,2.18,4],[2,2.16,69.79]],"ltp":2.18,"tv":472.2,"id":19144239}]}]}
{"op":"mcm","clk":"11797597143","pt":1722620170578,"mc":[{"id":"1.231282404","rc":[{"batb":[[1,2.2,10],[2,2.16,65.79]],"ltp":2.18,"tv":472.2,"id":19144239}]}]}
{"op":"mcm","clk":"11797597670","pt":1722620173191,"mc":[{"id":"1.231282404","rc":[{"batb":[[0,2.2,10],[1,2.16,65.79],[2,1.93,50]],"ltp":2.18,"tv":472.2,"id":19144239}]}]}
{"op":"mcm","clk":"11797597883","pt":1722620174197,"mc":[{"id":"1.231282404","rc":[{"batb":[[0,1.81,59.11]],"batl":[[0,1.84,4],[1,1.98,25.4],[2,6,1.56]],"ltp":1.86,"tv":53648.14,"id":58385184},{"batb":[[0,2.2,14]],"batl":[[0,2.22,4],[1,2.24,4],[2,2.9,4.56]],"ltp":2.18,"tv":472.2,"id":19144239}]}]}
{"op":"mcm","clk":"11797598163","pt":1722620175482,"mc":[{"id":"1.231282404","rc":[{"batl":[[0,1.98,25.4],[1,6,1.56],[2,12,1.56]],"ltp":1.86,"tv":53648.14,"id":58385184},{"batb":[[0,2.16,65.79],[1,1.93,50],[2,1.9,73.22]],"ltp":2.18,"tv":472.2,"id":19144239}]}]}
{"op":"mcm","clk":"11797600861","pt":1722620189526,"mc":[{"id":"1.231282404","rc":[{"batb":[[1,1.75,129.83],[2,1.74,17.32]],"batl":[[0,1.86,4.15],[1,1.87,4],[2,1.98,25.25]],"ltp":1.86,"tv":53648.14,"id":58385184},{"batb":[[0,2.16,69.79]],"ltp":2.18,"tv":472.2,"id":19144239}]}]}
{"op":"mcm","clk":"11797600959","pt":1722620190148,"mc":[{"id":"1.231282404","rc":[{"batb":[[0,2.18,4.59],[1,2.16,69.79],[2,1.93,50]],"ltp":2.18,"tv":472.2,"id":19144239}]}]}
{"op":"mcm","clk":"11797603612","pt":1722620204435,"mc":[{"id":"1.231282404","rc":[{"batb":[[0,2.18,8.59]],"ltp":2.18,"tv":472.2,"id":19144239}]}]}
{"op":"mcm","clk":"11797603916","pt":1722620206146,"mc":[{"id":"1.231282404","rc":[{"batb":[[0,1.82,4.8],[1,1.81,59.11],[2,1.75,129.83]],"ltp":1.86,"tv":53648.14,"id":58385184}]}]}
{"op":"mcm","clk":"11797606513","pt":1722620219538,"mc":[{"id":"1.231282404","rc":[{"batb":[[0,1.82,8.8]],"batl":[[0,1.84,4],[1,1.85,4],[2,1.86,4.15]],"ltp":1.86,"tv":53648.14,"id":58385184}]}]}
{"op":"mcm","clk":"11797607548","pt":1722620224573,"mc":[{"id":"1.231282404","rc":[{"batb":[[0,1.82,4.8],[1,1.75,130.02],[2,1.74,17.32]],"ltp":1.86,"tv":53648.14,"id":58385184},{"batb":[[0,2.2,12],[1,2.18,8.59],[2,2.16,69.79]],"batl":[[0,2.9,4.56],[1,6,1.56],[2,12,1.56]],"ltp":2.18,"tv":472.2,"id":19144239}]}]}
{"op":"mcm","clk":"11797607736","pt":1722620225639,"mc":[{"id":"1.231282404","rc":[{"batl":[[0,1.98,25.4],[1,6,1.56],[2,12,1.56]],"ltp":1.86,"tv":53648.14,"id":58385184}]}]}
{"op":"mcm","clk":"11797607916","pt":1722620226654,"mc":[{"id":"1.231282404","rc":[{"batb":[[0,1.75,130.2],[1,1.74,17.32],[2,1.71,129.83]],"ltp":1.86,"tv":53648.14,"id":58385184},{"batb":[[1,2.18,4]],"ltp":2.18,"tv":472.2,"id":19144239}]}]}
{"op":"mcm","clk":"11797607959","pt":1722620226869,"mc":[{"id":"1.231282404","rc":[{"batb":[[0,1.76,40.76],[1,1.75,129.83],[2,1.74,17.32]],"ltp":1.86,"tv":53648.14,"id":58385184},{"batb":[[0,2.2,10]],"ltp":2.18,"tv":472.2,"id":19144239}]}]}
{"op":"mcm","clk":"11797608186","pt":1722620227872,"mc":[{"id":"1.231282404","rc":[{"batb":[[0,2.18,4],[1,2.16,69.79],[2,1.93,50]],"ltp":2.18,"tv":472.2,"id":19144239}]}]}
{"op":"mcm","clk":"11797608429","pt":1722620229153,"mc":[{"id":"1.231282404","rc":[{"batb":[[0,1.81,55.29],[1,1.76,40.39],[2,1.75,129.83]],"ltp":1.86,"tv":53648.14,"id":58385184},{"batb":[[0,2.2,2],[1,2.18,4],[2,2.16,69.79]],"ltp":2.18,"tv":472.2,"id":19144239}]}]}
{"op":"mcm","clk":"11797608891","pt":1722620231569,"mc":[{"id":"1.231282404","rc":[{"batb":[[0,2.18,4],[1,2.16,69.79],[2,1.93,50]],"ltp":2.18,"tv":472.2,"id":19144239}]}]}
{"op":"mcm","clk":"11797608933","pt":1722620231768,"mc":[{"id":"1.231282404","rc":[{"batb":[[0,2.2,10],[1,2.18,4],[2,2.16,69.79]],"ltp":2.18,"tv":472.2,"id":19144239}]}]}
{"op":"mcm","clk":"11797609491","pt":1722620234648,"mc":[{"id":"1.231282404","rc":[{"batb":[[0,1.81,59.29]],"batl":[[0,1.84,4],[1,1.98,25.4],[2,6,1.56]],"ltp":1.86,"tv":53648.14,"id":58385184},{"batb":[[0,2.2,14]],"batl":[[0,2.22,4],[1,2.24,4],[2,2.9,4.56]],"ltp":2.18,"tv":472.2,"id":19144239}]}]}
{"op":"mcm","clk":"11797609711","pt":1722620235663,"mc":[{"id":"1.231282404","rc":[{"trd":[[1.84,52.95]],"batb":[[0,1.81,763.02]],"batl":[[0,1.98,25.4],[1,6,1.56],[2,12,1.56]],"ltp":1.84,"tv":53656.14,"id":58385184},{"batb":[[0,2.18,4],[1,2.16,69.79],[2,1.93,50]],"ltp":2.18,"tv":472.2,"id":19144239}],"tv":54128.35}]}
{"op":"mcm","clk":"11797609834","pt":1722620236291,"mc":[{"id":"1.231282404","rc":[{"batb":[[0,2.16,65.79],[1,1.93,50],[2,1.9,73.22]],"ltp":2.18,"tv":472.2,"id":19144239}]}]}
{"op":"mcm","clk":"11797615272","pt":1722620261436,"mc":[{"id":"1.231282404","rc":[{"batb":[[0,1.81,59.29],[1,1.75,129.83],[2,1.74,17.32]],"ltp":1.84,"tv":53656.14,"id":58385184}]}]}
{"op":"mcm","clk":"11797615984","pt":1722620264829,"mc":[{"id":"1.231282404","rc":[{"batl":[[0,1.86,4.15],[1,1.87,4],[2,1.98,25.25]],"ltp":1.84,"tv":53656.14,"id":58385184},{"batb":[[0,2.16,69.79]],"ltp":2.18,"tv":472.2,"id":19144239}]}]}
{"op":"mcm","clk":"11797616228","pt":1722620266140,"mc":[{"id":"1.231282404","rc":[{"batb":[[0,1.82,5],[1,1.81,59.11],[2,1.75,129.83]],"ltp":1.84,"tv":53656.14,"id":58385184},{"batb":[[0,2.18,4.59],[1,2.16,69.79],[2,1.93,50]],"ltp":2.18,"tv":472.2,"id":19144239}]}]}
{"op":"mcm","clk":"11797619127","pt":1722620279933,"mc":[{"id":"1.231282404","rc":[{"batb":[[0,1.82,9]],"ltp":1.84,"tv":53656.14,"id":58385184},{"batb":[[0,2.18,8.59]],"ltp":2.18,"tv":472.2,"id":19144239}]}]}
{"op":"mcm","clk":"11797620061","pt":1722620284283,"mc":[{"id":"1.231282404","rc":[{"batb":[[1,1.81,4.19]],"ltp":1.84,"tv":53656.14,"id":58385184}]}]}
{"op":"mcm","clk":"11797620308","pt":1722620285351,"mc":[{"id":"1.231282404","rc":[{"batb":[[0,1.82,5],[1,1.75,130.02],[2,1.74,17.32]],"ltp":1.84,"tv":53656.14,"id":58385184},{"batb":[[0,2.2,12],[1,2.18,8.59],[2,2.16,69.79]],"batl":[[0,2.9,4.56],[1,6,1.56],[2,12,1.56]],"ltp":2.18,"tv":472.2,"id":19144239}]}]}
{"op":"mcm","clk":"11797620551","pt":1722620286579,"mc":[{"id":"1.231282404","rc":[{"batb":[[0,1.76,40.76],[1,1.75,129.83]],"ltp":1.84,"tv":53656.14,"id":58385184},{"batb":[[1,2.18,4]],"ltp":2.18,"tv":472.2,"id":19144239}]}]}
{"op":"mcm","clk":"11797620848","pt":1722620287884,"mc":[{"id":"1.231282404","rc":[{"batb":[[0,2.2,10]],"ltp":2.18,"tv":472.2,"id":19144239}]}]}
{"op":"mcm","clk":"11797621102","pt":1722620289158,"mc":[{"id":"1.231282404","rc":[{"batb":[[0,1.81,55.29],[1,1.76,40.39],[2,1.75,129.83]],"ltp":1.84,"tv":53656.14,"id":58385184},{"batb":[[0,2.18,4],[1,2.16,69.79],[2,1.93,50]],"ltp":2.18,"tv":472.2,"id":19144239}]}]}
{"op":"mcm","clk":"11797621581","pt":1722620291670,"mc":[{"id":"1.231282404","rc":[{"trd":[[1.82,136.09],[1.83,37.38]],"batb":[[0,1.81,55.11]],"batl":[[0,1.98,25.4],[1,6,1.56],[2,12,1.56]],"ltp":1.82,"tv":53657.32,"id":58385184},{"trd":[[2.22,25.78]],"batb":[[0,2.22,1.03],[1,2.2,10],[2,2.18,4]],"ltp":2.22,"tv":473.17,"id":19144239}],"tv":54130.5}]}
{"op":"mcm","clk":"11797621702","pt":1722620292264,"mc":[{"id":"1.231282404","rc":[{"batb":[[2,2.16,65.79]],"ltp":2.22,"tv":473.17,"id":19144239}]}]}
{"op":"mcm","clk":"11797622372","pt":1722620295662,"mc":[{"id":"1.231282404","rc":[{"batb":[[0,1.81,59.11]],"ltp":1.82,"tv":53657.32,"id":58385184},{"batb":[[0,2.2,10],[1,2.16,65.79],[2,1.93,50]],"batl":[[0,2.24,4],[1,2.9,4.56],[2,6,1.56]],"ltp":2.22,"tv":473.17,"id":19144239}]}]}
{"op":"mcm","clk":"11797622744","pt":1722620297483,"mc":[{"id":"1.231282404","rc":[{"batb":[[0,2.16,65.79],[1,1.93,50],[2,1.9,73.22]],"ltp":2.22,"tv":473.17,"id":19144239}]}]}
{"op":"mcm","clk":"11797625510","pt":1722620310479,"mc":[{"id":"1.231282404","rc":[{"batb":[[1,1.75,129.83],[2,1.74,17.32]],"batl":[[0,1.86,4.15],[1,1.87,4],[2,1.98,25.25]],"ltp":1.82,"tv":53657.32,"id":58385184},{"batb":[[0,2.16,69.79]],"ltp":2.22,"tv":473.17,"id":19144239}]}]}
{"op":"mcm","clk":"11797625731","pt":1722620311402,"mc":[{"id":"1.231282404","rc":[{"batb":[[0,2.18,4.59],[1,2.16,69.79],[2,1.93,50]],"ltp":2.22,"tv":473.17,"id":19144239}]}]}
{"op":"mcm","clk":"11797628929","pt":1722620325445,"mc":[{"id":"1.231282404","rc":[{"batb":[[0,2.18,8.59]],"batl":[[0,2.22,4],[1,2.24,4],[2,2.9,4.56]],"ltp":2.22,"tv":473.17,"id":19144239}]}]}
{"op":"mcm","clk":"11797629808","pt":1722620329339,"mc":[{"id":"1.231282404","rc":[{"batb":[[0,1.82,4.8],[1,1.81,59.11],[2,1.75,129.83]],"ltp":1.82,"tv":53657.32,"id":58385184}]}]}
{"op":"mcm","clk":"11797632354","pt":1722620340555,"mc":[{"id":"1.231282404","rc":[{"batb":[[0,1.82,8.8]],"batl":[[0,1.84,4],[1,1.85,4],[2,1.86,4.15]],"ltp":1.82,"tv":53657.32,"id":58385184}]}]}
{"op":"mcm","clk":"11797633224","pt":1722620344543,"mc":[{"id":"1.231282404","rc":[{"batb":[[1,1.81,4.19]],"ltp":1.82,"tv":53657.32,"id":58385184}]}]}
{"op":"mcm","clk":"11797633391","pt":1722620345346,"mc":[{"id":"1.231282404","rc":[{"batb":[[0,1.82,4.8],[1,1.75,130.02],[2,1.74,17.32]],"ltp":1.82,"tv":53657.32,"id":58385184},{"batl":[[0,2.9,4.56],[1,6,1.56],[2,12,1.56]],"ltp":2.22,"tv":473.17,"id":19144239}]}]}
{"op":"mcm","clk":"11797633493","pt":1722620345828,"mc":[{"id":"1.231282404","rc":[{"batl":[[0,1.98,25.4],[1,6,1.56],[2,12,1.56]],"ltp":1.82,"tv":53657.32,"id":58385184}]}]}
{"op":"mcm","clk":"11797633704","pt":1722620346954,"mc":[{"id":"1.231282404","rc":[{"batb":[[0,1.76,40.58],[1,1.75,129.83]],"ltp":1.82,"tv":53657.32,"id":58385184}]}]}
{"op":"mcm","clk":"11797634041","pt":1722620348446,"mc":[{"id":"1.231282404","rc":[{"batb":[[0,2.2,12],[1,2.18,8.59],[2,2.16,69.79]],"ltp":2.22,"tv":473.17,"id":19144239}]}]}
{"op":"mcm","clk":"11797634306","pt":1722620349557,"mc":[{"id":"1.231282404","rc":[{"batb":[[0,1.81,55.11],[1,1.76,40.39],[2,1.75,129.83]],"ltp":1.82,"tv":53657.32,"id":58385184},{"batb":[[1,2.18,4]],"ltp":2.22,"tv":473.17,"id":19144239}]}]}
{"op":"mcm","clk":"11797635013","pt":1722620352819,"mc":[{"id":"1.231282404","rc":[{"batb":[[0,2.2,10]],"ltp":2.22,"tv":473.17,"id":19144239}]}]}
{"op":"mcm","clk":"11797635314","pt":1722620354072,"mc":[{"id":"1.231282404","rc":[{"batb":[[0,2.18,4],[1,2.16,69.79],[2,1.93,50]],"ltp":2.22,"tv":473.17,"id":19144239}]}]}
{"op":"mcm","clk":"11797635675","pt":1722620355604,"mc":[{"id":"1.231282404","rc":[{"batb":[[0,1.81,59.11]],"ltp":1.82,"tv":53657.32,"id":58385184},{"trd":[[2.22,29.78]],"batl":[[0,2.22,2],[1,2.24,4],[2,2.9,4.56]],"ltp":2.22,"tv":477.17,"id":19144239}],"tv":54134.5}]}
{"op":"mcm","clk":"11797635725","pt":1722620355829,"mc":[{"id":"1.231282404","rc":[{"batb":[[0,2.18,8.78]],"ltp":2.22,"tv":477.17,"id":19144239}]}]}
{"op":"mcm","clk":"11797636143","pt":1722620357685,"mc":[{"id":"1.231282404","rc":[{"batb":[[0,2.2,10],[1,2.18,8.78],[2,2.16,69.79]],"ltp":2.22,"tv":477.17,"id":19144239}]}]}
{"op":"mcm","clk":"11797636717","pt":1722620360200,"mc":[{"id":"1.231282404","rc":[{"batb":[[1,1.75,129.83],[2,1.74,17.32]],"ltp":1.82,"tv":53657.32,"id":58385184},{"batb":[[1,2.18,4]],"ltp":2.22,"tv":477.17,"id":19144239}]}]}
{"op":"mcm","clk":"11797637578","pt":1722620364023,"mc":[{"id":"1.231282404","rc":[{"batb":[[0,2.18,4],[1,2.16,69.79],[2,1.93,50]],"ltp":2.22,"tv":477.17,"id":19144239}]}]}
{"op":"mcm","clk":"11797642862","pt":1722620388637,"mc":[{"id":"1.231282404","rc":[{"batb":[[0,1.82,4.62],[1,1.81,59.11],[2,1.75,129.83]],"ltp":1.82,"tv":53657.32,"id":58385184}]}]}
