{"op":"mcm","clk":"11919122770","pt":1724501855545,"mc":[{"id":"1.232224347","marketDefinition":{"bspMarket":false,"turnInPlayEnabled":true,"persistenceEnabled":true,"marketBaseRate":5.0,"eventId":"33523474","eventTypeId":"4","numberOfWinners":1,"bettingType":"ODDS","marketType":"MATCH_ODDS","marketTime":"2024-08-25T09:30:00.000Z","suspendTime":"2024-08-25T09:30:00.000Z","bspReconciled":false,"complete":true,"inPlay":false,"crossMatching":false,"runnersVoidable":false,"numberOfActiveRunners":2,"betDelay":0,"status":"OPEN","runners":[{"status":"ACTIVE","sortPriority":1,"id":61077258,"name":"Bulgaria"},{"status":"ACTIVE","sortPriority":2,"id":48800301,"name":"Malta"}],"regulators":["MR_INT"],"countryCode":"GB","discountAllowed":false,"timezone":"GMT","openDate":"2024-08-25T09:30:00.000Z","version":6094669315,"name":"Match Odds","eventName":"Bulgaria v Malta"},"rc":[{"batb":[[0,1.03,200],[1,1.02,200],[2,1.01,220]],"ltp":0.0,"tv":0.0,"id":61077258},{"batb":[[0,1.03,200],[1,1.02,200],[2,1.01,220]],"ltp":0.0,"tv":0.0,"id":48800301}]}]}
{"op":"mcm","clk":"11919123045","pt":1724501856912,"mc":[{"id":"1.232224347","marketDefinition":{"bspMarket":false,"turnInPlayEnabled":true,"persistenceEnabled":true,"marketBaseRate":5.0,"eventId":"33523474","eventTypeId":"4","numberOfWinners":1,"bettingType":"ODDS","marketType":"MATCH_ODDS","marketTime":"2024-08-25T09:30:00.000Z","suspendTime":"2024-08-25T09:30:00.000Z","bspReconciled":false,"complete":true,"inPlay":false,"crossMatching":false,"runnersVoidable":false,"numberOfActiveRunners":2,"betDelay":0,"status":"OPEN","runners":[{"status":"ACTIVE","sortPriority":1,"id":61077258,"name":"Bulgaria"},{"status":"ACTIVE","sortPriority":2,"id":48800301,"name":"Malta"}],"regulators":["MR_INT"],"countryCode":"GB","discountAllowed":true,"timezone":"GMT","openDate":"2024-08-25T09:30:00.000Z","version":6094669315,"name":"Match Odds","eventName":"Bulgaria v Malta"}}]}
{"op":"mcm","clk":"11920069445","pt":1724506521543,"mc":[{"id":"1.232224347","rc":[{"batb":[[0,1.05,200],[1,1.04,250],[2,1.03,533.33]],"ltp":0.0,"tv":0.0,"id":61077258},{"batb":[[0,1.05,200],[1,1.04,250],[2,1.03,533.33]],"ltp":0.0,"tv":0.0,"id":48800301}]}]}
{"op":"mcm","clk":"11920556815","pt":1724508529593,"mc":[{"id":"1.232224347","rc":[{"batb":[[1,1.04,251.05]],"ltp":0.0,"tv":0.0,"id":61077258},{"batb":[[1,1.04,251.05]],"ltp":0.0,"tv":0.0,"id":48800301}]}]}
{"op":"mcm","clk":"11920564676","pt":1724508552383,"mc":[{"id":"1.232224347","marketDefinition":{"bspMarket":false,"turnInPlayEnabled":true,"persistenceEnabled":true,"marketBaseRate":5.0,"eventId":"33523474","eventTypeId":"4","numberOfWinners":1,"bettingType":"ODDS","marketType":"MATCH_ODDS","marketTime":"2024-08-25T09:30:00.000Z","suspendTime":"2024-08-25T09:30:00.000Z","bspReconciled":false,"complete":true,"inPlay":false,"crossMatching":true,"runnersVoidable":false,"numberOfActiveRunners":2,"betDelay":0,"status":"OPEN","runners":[{"status":"ACTIVE","sortPriority":1,"id":61077258,"name":"Bulgaria"},{"status":"ACTIVE","sortPriority":2,"id":48800301,"name":"Malta"}],"regulators":["MR_INT"],"countryCode":"GB","discountAllowed":true,"timezone":"GMT","openDate":"2024-08-25T09:30:00.000Z","version":6094669315,"name":"Match Odds","eventName":"Bulgaria v Malta"}}]}
{"op":"mcm","clk":"11921631729","pt":1724511731318,"mc":[{"id":"1.232224347","rc":[{"batl":[[0,14,0.76]],"ltp":0.0,"tv":0.0,"id":61077258},{"batl":[[0,14,0.76]],"ltp":0.0,"tv":0.0,"id":48800301}]}]}
{"op":"mcm","clk":"11921636471","pt":1724511746895,"mc":[{"id":"1.232224347","rc":[{"batl":[[0,24,1.51]],"ltp":0.0,"tv":0.0,"id":61077258},{"batl":[[0,24,1.51]],"ltp":0.0,"tv":0.0,"id":48800301}]}]}
{"op":"mcm","clk":"11923073063","pt":1724520816741,"mc":[{"id":"1.232224347","rc":[{"batb":[[0,1.1,1000],[1,1.05,200],[2,1.04,251.05]],"ltp":0.0,"tv":0.0,"id":48800301}]}]}
{"op":"mcm","clk":"11923073144","pt":1724520817208,"mc":[{"id":"1.232224347","rc":[{"batb":[[0,1.1,1000],[1,1.05,200],[2,1.04,251.05]],"ltp":0.0,"tv":0.0,"id":61077258}]}]}
{"op":"mcm","clk":"11923317528","pt":1724522128694,"mc":[{"id":"1.232224347","rc":[{"batb":[[0,1.12,1.76],[1,1.1,1000],[2,1.05,200]],"ltp":0.0,"tv":0.0,"id":61077258}]}]}
{"op":"mcm","clk":"11923318728","pt":1724522136693,"mc":[{"id":"1.232224347","rc":[{"batb":[[0,1.12,1.76],[1,1.1,1000],[2,1.05,200]],"ltp":0.0,"tv":0.0,"id":48800301}]}]}
{"op":"mcm","clk":"11923372887","pt":1724522479862,"mc":[{"id":"1.232224347","rc":[{"batb":[[0,2.04,41.29],[1,1.12,1.76],[2,1.1,1000]],"ltp":0.0,"tv":0.0,"id":61077258},{"batb":[[0,1.88,48.8],[1,1.12,1.76],[2,1.1,1000]],"ltp":0.0,"tv":0.0,"id":48800301}]}]}
{"op":"mcm","clk":"11923935726","pt":1724525769817,"mc":[{"id":"1.232224347","rc":[{"batb":[[1,1.21,24.75],[2,1.12,1.76]],"ltp":0.0,"tv":0.0,"id":61077258},{"batb":[[1,1.21,24.75],[2,1.12,1.76]],"ltp":0.0,"tv":0.0,"id":48800301}]}]}
{"op":"mcm","clk":"11924901657","pt":1724533523769,"mc":[{"id":"1.232224347","rc":[{"batl":[[0,1.96,50],[1,24,1.51]],"ltp":0.0,"tv":0.0,"id":48800301}]}]}
{"op":"mcm","clk":"11925065606","pt":1724535199311,"mc":[{"id":"1.232224347","rc":[{"batb":[[0,2.06,4.38],[1,2.04,41.29],[2,1.21,24.75]],"ltp":0.0,"tv":0.0,"id":61077258}]}]}
{"op":"mcm","clk":"11925425458","pt":1724540998532,"mc":[{"id":"1.232224347","rc":[{"batb":[[0,2.08,39.76],[1,2.06,4.38]],"ltp":0.0,"tv":0.0,"id":61077258},{"batb":[[0,1.84,51.13]],"ltp":0.0,"tv":0.0,"id":48800301}]}]}
{"op":"mcm","clk":"11925425503","pt":1724540999453,"mc":[{"id":"1.232224347","rc":[{"batb":[[1,1.21,24.75],[2,1.12,1.76]],"ltp":0.0,"tv":0.0,"id":61077258}]}]}
{"op":"mcm","clk":"11925889748","pt":1724547026852,"mc":[{"id":"1.232224347","rc":[{"trd":[[2.2,5.5]],"ltp":2.2,"tv":5.5,"id":61077258},{"trd":[[1.84,6.58]],"batb":[[0,1.84,44.55]],"ltp":1.84,"tv":6.58,"id":48800301}],"tv":12.08}]}
{"op":"mcm","clk":"11925889832","pt":1724547027850,"mc":[{"id":"1.232224347","rc":[{"batb":[[0,1.84,95.68]],"ltp":1.84,"tv":6.58,"id":48800301}]}]}
{"op":"mcm","clk":"11925889841","pt":1724547027944,"mc":[{"id":"1.232224347","rc":[{"batb":[[0,1.84,51.13]],"ltp":1.84,"tv":6.58,"id":48800301}]}]}
{"op":"mcm","clk":"11926152471","pt":1724550582463,"mc":[{"id":"1.232224347","rc":[{"batb":[[0,2.1,5],[1,2.08,39.76],[2,1.21,24.75]],"ltp":2.2,"tv":5.5,"id":61077258},{"trd":[[1.84,108.84]],"batb":[[0,1.21,24.75],[1,1.12,1.76],[2,1.1,1000]],"batl":[[0,1.84,327.14],[1,1.96,50],[2,24,1.51]],"ltp":1.84,"tv":108.83,"id":48800301}],"tv":114.33}]}
{"op":"mcm","clk":"11926152605","pt":1724550584527,"mc":[{"id":"1.232224347","rc":[{"batb":[[0,1.8,53.68],[1,1.21,24.75],[2,1.12,1.76]],"ltp":1.84,"tv":108.83,"id":48800301}]}]}
{"op":"mcm","clk":"11926152677","pt":1724550585767,"mc":[{"id":"1.232224347","rc":[{"batb":[[0,2.08,39.76],[1,1.21,24.75],[2,1.12,1.76]],"ltp":2.2,"tv":5.5,"id":61077258}]}]}
{"op":"mcm","clk":"11926152813","pt":1724550588041,"mc":[{"id":"1.232224347","rc":[{"batb":[[0,2.1,5],[1,2.08,39.76],[2,1.21,24.75]],"ltp":2.2,"tv":5.5,"id":61077258}]}]}
{"op":"mcm","clk":"11926153018","pt":1724550591244,"mc":[{"id":"1.232224347","rc":[{"batb":[[0,2.08,39.76],[1,1.21,24.75],[2,1.12,1.76]],"ltp":2.2,"tv":5.5,"id":61077258}]}]}
{"op":"mcm","clk":"11926153165","pt":1724550593457,"mc":[{"id":"1.232224347","rc":[{"batb":[[0,2.1,5],[1,2.08,39.76],[2,1.21,24.75]],"ltp":2.2,"tv":5.5,"id":61077258}]}]}
{"op":"mcm","clk":"11926153347","pt":1724550596760,"mc":[{"id":"1.232224347","rc":[{"batb":[[0,2.08,39.76],[1,1.21,24.75],[2,1.12,1.76]],"ltp":2.2,"tv":5.5,"id":61077258}]}]}
{"op":"mcm","clk":"11926153478","pt":1724550598866,"mc":[{"id":"1.232224347","rc":[{"batb":[[0,2.1,5],[1,2.08,39.76],[2,1.21,24.75]],"ltp":2.2,"tv":5.5,"id":61077258}]}]}
{"op":"mcm","clk":"11926153729","pt":1724550602053,"mc":[{"id":"1.232224347","rc":[{"batb":[[0,2.08,39.76],[1,1.21,24.75],[2,1.12,1.76]],"ltp":2.2,"tv":5.5,"id":61077258}]}]}
{"op":"mcm","clk":"11926153912","pt":1724550605166,"mc":[{"id":"1.232224347","rc":[{"batb":[[0,2.1,5],[1,2.08,39.76],[2,1.21,24.75]],"ltp":2.2,"tv":5.5,"id":61077258}]}]}
{"op":"mcm","clk":"11926154103","pt":1724550608356,"mc":[{"id":"1.232224347","rc":[{"batb":[[0,2.08,39.76],[1,1.21,24.75],[2,1.12,1.76]],"ltp":2.2,"tv":5.5,"id":61077258}]}]}
{"op":"mcm","clk":"11926154248","pt":1724550610680,"mc":[{"id":"1.232224347","rc":[{"batb":[[0,2.1,5],[1,2.08,39.76],[2,1.21,24.75]],"ltp":2.2,"tv":5.5,"id":61077258}]}]}
{"op":"mcm","clk":"11926154432","pt":1724550613874,"mc":[{"id":"1.232224347","rc":[{"batb":[[0,2.08,39.76],[1,1.21,24.75],[2,1.12,1.76]],"ltp":2.2,"tv":5.5,"id":61077258}]}]}
{"op":"mcm","clk":"11926154498","pt":1724550614672,"mc":[{"id":"1.232224347","rc":[{"trd":[[1.8,105.92]],"batb":[[0,1.21,24.75],[1,1.12,1.76],[2,1.1,1000]],"ltp":1.8,"tv":214.75,"id":48800301}],"tv":220.25}]}
{"op":"mcm","clk":"11926154634","pt":1724550616791,"mc":[{"id":"1.232224347","rc":[{"batb":[[0,2.1,5],[1,2.08,39.76],[2,1.21,24.75]],"ltp":2.2,"tv":5.5,"id":61077258}]}]}
{"op":"mcm","clk":"11926154862","pt":1724550619986,"mc":[{"id":"1.232224347","rc":[{"batb":[[0,2.08,39.76],[1,1.21,24.75],[2,1.12,1.76]],"ltp":2.2,"tv":5.5,"id":61077258}]}]}
{"op":"mcm","clk":"11926155057","pt":1724550622201,"mc":[{"id":"1.232224347","rc":[{"batb":[[0,2.1,5],[1,2.08,39.76],[2,1.21,24.75]],"ltp":2.2,"tv":5.5,"id":61077258}]}]}
{"op":"mcm","clk":"11926155259","pt":1724550625394,"mc":[{"id":"1.232224347","rc":[{"batb":[[0,2.08,39.76],[1,1.21,24.75],[2,1.12,1.76]],"ltp":2.2,"tv":5.5,"id":61077258}]}]}
{"op":"mcm","clk":"11926155466","pt":1724550628488,"mc":[{"id":"1.232224347","rc":[{"batb":[[0,2.1,5],[1,2.08,39.76],[2,1.21,24.75]],"ltp":2.2,"tv":5.5,"id":61077258}]}]}
{"op":"mcm","clk":"11926155668","pt":1724550631830,"mc":[{"id":"1.232224347","rc":[{"batb":[[0,2.08,39.76],[1,1.21,24.75],[2,1.12,1.76]],"ltp":2.2,"tv":5.5,"id":61077258}]}]}
{"op":"mcm","clk":"11926155811","pt":1724550634210,"mc":[{"id":"1.232224347","rc":[{"batb":[[0,2.1,5],[1,2.08,39.76],[2,1.21,24.75]],"ltp":2.2,"tv":5.5,"id":61077258}]}]}
{"op":"mcm","clk":"11926156016","pt":1724550637624,"mc":[{"id":"1.232224347","rc":[{"batb":[[0,2.08,39.76],[1,1.21,24.75],[2,1.12,1.76]],"ltp":2.2,"tv":5.5,"id":61077258}]}]}
{"op":"mcm","clk":"11926156192","pt":1724550639835,"mc":[{"id":"1.232224347","rc":[{"batb":[[0,2.1,5],[1,2.08,39.76],[2,1.21,24.75]],"ltp":2.2,"tv":5.5,"id":61077258}]}]}
{"op":"mcm","clk":"11926156387","pt":1724550643028,"mc":[{"id":"1.232224347","rc":[{"batb":[[0,2.08,39.76],[1,1.21,24.75],[2,1.12,1.76]],"ltp":2.2,"tv":5.5,"id":61077258}]}]}
{"op":"mcm","clk":"11926156639","pt":1724550646748,"mc":[{"id":"1.232224347","rc":[{"batb":[[0,2.1,5],[1,2.08,39.76],[2,1.21,24.75]],"ltp":2.2,"tv":5.5,"id":61077258}]}]}
{"op":"mcm","clk":"11926156869","pt":1724550649936,"mc":[{"id":"1.232224347","rc":[{"batb":[[0,2.08,39.76],[1,1.21,24.75],[2,1.12,1.76]],"ltp":2.2,"tv":5.5,"id":61077258}]}]}
{"op":"mcm","clk":"11926157068","pt":1724550653034,"mc":[{"id":"1.232224347","rc":[{"batb":[[0,2.1,5],[1,2.08,39.76],[2,1.21,24.75]],"ltp":2.2,"tv":5.5,"id":61077258}]}]}
{"op":"mcm","clk":"11926157292","pt":1724550656443,"mc":[{"id":"1.232224347","rc":[{"batb":[[0,2.08,39.76],[1,1.21,24.75],[2,1.12,1.76]],"ltp":2.2,"tv":5.5,"id":61077258}]}]}
{"op":"mcm","clk":"11926157442","pt":1724550658610,"mc":[{"id":"1.232224347","rc":[{"batb":[[0,2.1,5],[1,2.08,39.76],[2,1.21,24.75]],"ltp":2.2,"tv":5.5,"id":61077258}]}]}
{"op":"mcm","clk":"11926157647","pt":1724550661857,"mc":[{"id":"1.232224347","rc":[{"batb":[[0,2.08,39.76],[1,1.21,24.75],[2,1.12,1.76]],"ltp":2.2,"tv":5.5,"id":61077258}]}]}
{"op":"mcm","clk":"11926157795","pt":1724550664042,"mc":[{"id":"1.232224347","rc":[{"batb":[[0,2.1,5],[1,2.08,39.76],[2,1.21,24.75]],"ltp":2.2,"tv":5.5,"id":61077258}]}]}
{"op":"mcm","clk":"11926158011","pt":1724550667236,"mc":[{"id":"1.232224347","rc":[{"batb":[[0,2.08,39.76],[1,1.21,24.75],[2,1.12,1.76]],"ltp":2.2,"tv":5.5,"id":61077258}]}]}
{"op":"mcm","clk":"11926158165","pt":1724550669460,"mc":[{"id":"1.232224347","rc":[{"batb":[[0,2.1,5],[1,2.08,39.76],[2,1.21,24.75]],"ltp":2.2,"tv":5.5,"id":61077258}]}]}
{"op":"mcm","clk":"11926158425","pt":1724550673050,"mc":[{"id":"1.232224347","rc":[{"batb":[[0,2.08,39.76],[1,1.21,24.75],[2,1.12,1.76]],"ltp":2.2,"tv":5.5,"id":61077258}]}]}
{"op":"mcm","clk":"11926158574","pt":1724550675275,"mc":[{"id":"1.232224347","rc":[{"batb":[[0,2.1,5],[1,2.08,39.76],[2,1.21,24.75]],"ltp":2.2,"tv":5.5,"id":61077258}]}]}
{"op":"mcm","clk":"11926158806","pt":1724550678486,"mc":[{"id":"1.232224347","rc":[{"batb":[[0,2.08,39.76],[1,1.21,24.75],[2,1.12,1.76]],"ltp":2.2,"tv":5.5,"id":61077258}]}]}
{"op":"mcm","clk":"11926159011","pt":1724550680648,"mc":[{"id":"1.232224347","rc":[{"batb":[[0,2.1,5],[1,2.08,39.76],[2,1.21,24.75]],"ltp":2.2,"tv":5.5,"id":61077258}]}]}
{"op":"mcm","clk":"11926159240","pt":1724550683846,"mc":[{"id":"1.232224347","rc":[{"batb":[[0,2.08,39.76],[1,1.21,24.75],[2,1.12,1.76]],"ltp":2.2,"tv":5.5,"id":61077258}]}]}
{"op":"mcm","clk":"11926159464","pt":1724550686679,"mc":[{"id":"1.232224347","rc":[{"batb":[[0,2.1,5],[1,2.08,39.76],[2,1.21,24.75]],"ltp":2.2,"tv":5.5,"id":61077258}]}]}
{"op":"mcm","clk":"11926159715","pt":1724550689982,"mc":[{"id":"1.232224347","rc":[{"batb":[[0,2.08,39.76],[1,1.21,24.75],[2,1.12,1.76]],"ltp":2.2,"tv":5.5,"id":61077258}]}]}
{"op":"mcm","clk":"11926159923","pt":1724550693081,"mc":[{"id":"1.232224347","rc":[{"batb":[[0,2.1,5],[1,2.08,39.76],[2,1.21,24.75]],"ltp":2.2,"tv":5.5,"id":61077258}]}]}
{"op":"mcm","clk":"11926160118","pt":1724550696282,"mc":[{"id":"1.232224347","rc":[{"batb":[[0,2.08,39.76],[1,1.21,24.75],[2,1.12,1.76]],"ltp":2.2,"tv":5.5,"id":61077258}]}]}
{"op":"mcm","clk":"11926160300","pt":1724550699066,"mc":[{"id":"1.232224347","rc":[{"batb":[[0,2.1,5],[1,2.08,39.76],[2,1.21,24.75]],"ltp":2.2,"tv":5.5,"id":61077258}]}]}
{"op":"mcm","clk":"11926160553","pt":1724550702361,"mc":[{"id":"1.232224347","rc":[{"batb":[[0,2.08,39.76],[1,1.21,24.75],[2,1.12,1.76]],"ltp":2.2,"tv":5.5,"id":61077258}]}]}
{"op":"mcm","clk":"11926160704","pt":1724550704573,"mc":[{"id":"1.232224347","rc":[{"batb":[[0,2.1,5],[1,2.08,39.76],[2,1.21,24.75]],"ltp":2.2,"tv":5.5,"id":61077258}]}]}
{"op":"mcm","clk":"11926160905","pt":1724550707774,"mc":[{"id":"1.232224347","rc":[{"batb":[[0,2.08,39.76],[1,1.21,24.75],[2,1.12,1.76]],"ltp":2.2,"tv":5.5,"id":61077258}]}]}
{"op":"mcm","clk":"11926161085","pt":1724550710865,"mc":[{"id":"1.232224347","rc":[{"batb":[[0,2.1,5],[1,2.08,39.76],[2,1.21,24.75]],"ltp":2.2,"tv":5.5,"id":61077258}]}]}
{"op":"mcm","clk":"11926161287","pt":1724550714103,"mc":[{"id":"1.232224347","rc":[{"batb":[[0,2.08,39.76],[1,1.21,24.75],[2,1.12,1.76]],"ltp":2.2,"tv":5.5,"id":61077258}]}]}
{"op":"mcm","clk":"11926161435","pt":1724550716269,"mc":[{"id":"1.232224347","rc":[{"batb":[[0,2.1,5],[1,2.08,39.76],[2,1.21,24.75]],"ltp":2.2,"tv":5.5,"id":61077258}]}]}
{"op":"mcm","clk":"11926161634","pt":1724550719409,"mc":[{"id":"1.232224347","rc":[{"batb":[[0,2.08,39.76],[1,1.21,24.75],[2,1.12,1.76]],"ltp":2.2,"tv":5.5,"id":61077258}]}]}
{"op":"mcm","clk":"11926161784","pt":1724550721591,"mc":[{"id":"1.232224347","rc":[{"batb":[[0,2.1,5],[1,2.08,39.76],[2,1.21,24.75]],"ltp":2.2,"tv":5.5,"id":61077258}]}]}
{"op":"mcm","clk":"11926161996","pt":1724550724802,"mc":[{"id":"1.232224347","rc":[{"batb":[[0,2.08,39.76],[1,1.21,24.75],[2,1.12,1.76]],"ltp":2.2,"tv":5.5,"id":61077258}]}]}
{"op":"mcm","clk":"11926162148","pt":1724550727022,"mc":[{"id":"1.232224347","rc":[{"batb":[[0,2.1,5],[1,2.08,39.76],[2,1.21,24.75]],"ltp":2.2,"tv":5.5,"id":61077258}]}]}
{"op":"mcm","clk":"11926162355","pt":1724550730309,"mc":[{"id":"1.232224347","rc":[{"batb":[[0,2.08,39.76],[1,1.21,24.75],[2,1.12,1.76]],"ltp":2.2,"tv":5.5,"id":61077258}]}]}
{"op":"mcm","clk":"11926162555","pt":1724550732890,"mc":[{"id":"1.232224347","rc":[{"batb":[[0,2.1,5],[1,2.08,39.76],[2,1.21,24.75]],"ltp":2.2,"tv":5.5,"id":61077258}]}]}
{"op":"mcm","clk":"11926162759","pt":1724550736134,"mc":[{"id":"1.232224347","rc":[{"batb":[[0,2.08,39.76],[1,1.21,24.75],[2,1.12,1.76]],"ltp":2.2,"tv":5.5,"id":61077258}]}]}
{"op":"mcm","clk":"11926162908","pt":1724550738315,"mc":[{"id":"1.232224347","rc":[{"batb":[[0,2.1,5],[1,2.08,39.76],[2,1.21,24.75]],"ltp":2.2,"tv":5.5,"id":61077258}]}]}
{"op":"mcm","clk":"11926163127","pt":1724550741637,"mc":[{"id":"1.232224347","rc":[{"batb":[[0,2.08,39.76],[1,1.21,24.75],[2,1.12,1.76]],"ltp":2.2,"tv":5.5,"id":61077258}]}]}
{"op":"mcm","clk":"11926163293","pt":1724550743804,"mc":[{"id":"1.232224347","rc":[{"batb":[[0,2.1,5],[1,2.08,39.76],[2,1.21,24.75]],"ltp":2.2,"tv":5.5,"id":61077258}]}]}
{"op":"mcm","clk":"11926163526","pt":1724550747149,"mc":[{"id":"1.232224347","rc":[{"batb":[[0,2.08,39.76],[1,1.21,24.75],[2,1.12,1.76]],"ltp":2.2,"tv":5.5,"id":61077258}]}]}
{"op":"mcm","clk":"11926163665","pt":1724550749301,"mc":[{"id":"1.232224347","rc":[{"batb":[[0,2.1,5],[1,2.08,39.76],[2,1.21,24.75]],"ltp":2.2,"tv":5.5,"id":61077258}]}]}
{"op":"mcm","clk":"11926163924","pt":1724550752756,"mc":[{"id":"1.232224347","rc":[{"batb":[[0,2.08,39.76],[1,1.21,24.75],[2,1.12,1.76]],"ltp":2.2,"tv":5.5,"id":61077258}]}]}
{"op":"mcm","clk":"11926164055","pt":1724550754920,"mc":[{"id":"1.232224347","rc":[{"batb":[[0,2.1,5],[1,2.08,39.76],[2,1.21,24.75]],"ltp":2.2,"tv":5.5,"id":61077258}]}]}
{"op":"mcm","clk":"11926164303","pt":1724550758235,"mc":[{"id":"1.232224347","rc":[{"batb":[[0,2.08,39.76],[1,1.21,24.75],[2,1.12,1.76]],"ltp":2.2,"tv":5.5,"id":61077258}]}]}
{"op":"mcm","clk":"11926164454","pt":1724550760442,"mc":[{"id":"1.232224347","rc":[{"batb":[[0,2.1,5],[1,2.08,39.76],[2,1.21,24.75]],"ltp":2.2,"tv":5.5,"id":61077258}]}]}
{"op":"mcm","clk":"11926164697","pt":1724550763748,"mc":[{"id":"1.232224347","rc":[{"batb":[[0,2.08,39.76],[1,1.21,24.75],[2,1.12,1.76]],"ltp":2.2,"tv":5.5,"id":61077258}]}]}
{"op":"mcm","clk":"11926164827","pt":1724550765952,"mc":[{"id":"1.232224347","rc":[{"batb":[[0,2.1,5],[1,2.08,39.76],[2,1.21,24.75]],"ltp":2.2,"tv":5.5,"id":61077258}]}]}
{"op":"mcm","clk":"11926165107","pt":1724550769268,"mc":[{"id":"1.232224347","rc":[{"batb":[[0,2.08,39.76],[1,1.21,24.75],[2,1.12,1.76]],"ltp":2.2,"tv":5.5,"id":61077258}]}]}
{"op":"mcm","clk":"11926165260","pt":1724550771850,"mc":[{"id":"1.232224347","rc":[{"batb":[[0,2.1,5],[1,2.08,39.76],[2,1.21,24.75]],"ltp":2.2,"tv":5.5,"id":61077258}]}]}
{"op":"mcm","clk":"11926165496","pt":1724550775077,"mc":[{"id":"1.232224347","rc":[{"batb":[[0,2.08,39.76],[1,1.21,24.75],[2,1.12,1.76]],"ltp":2.2,"tv":5.5,"id":61077258}]}]}
{"op":"mcm","clk":"11926165630","pt":1724550777246,"mc":[{"id":"1.232224347","rc":[{"batb":[[0,2.1,5],[1,2.08,39.76],[2,1.21,24.75]],"ltp":2.2,"tv":5.5,"id":61077258}]}]}
{"op":"mcm","clk":"11926165836","pt":1724550780439,"mc":[{"id":"1.232224347","rc":[{"batb":[[0,2.08,39.76],[1,1.21,24.75],[2,1.12,1.76]],"ltp":2.2,"tv":5.5,"id":61077258}]}]}
{"op":"mcm","clk":"11926165997","pt":1724550782661,"mc":[{"id":"1.232224347","rc":[{"batb":[[0,2.1,5],[1,2.08,39.76],[2,1.21,24.75]],"ltp":2.2,"tv":5.5,"id":61077258}]}]}
{"op":"mcm","clk":"11926166236","pt":1724550785963,"mc":[{"id":"1.232224347","rc":[{"batb":[[0,2.08,39.76],[1,1.21,24.75],[2,1.12,1.76]],"ltp":2.2,"tv":5.5,"id":61077258}]}]}
{"op":"mcm","clk":"11926166409","pt":1724550788173,"mc":[{"id":"1.232224347","rc":[{"batb":[[0,2.1,5],[1,2.08,39.76],[2,1.21,24.75]],"ltp":2.2,"tv":5.5,"id":61077258}]}]}
{"op":"mcm","clk":"11926166638","pt":1724550791483,"mc":[{"id":"1.232224347","rc":[{"batb":[[0,2.08,39.76],[1,1.21,24.75],[2,1.12,1.76]],"ltp":2.2,"tv":5.5,"id":61077258}]}]}
{"op":"mcm","clk":"11926166797","pt":1724550794001,"mc":[{"id":"1.232224347","rc":[{"batb":[[0,2.1,5],[1,2.08,39.76],[2,1.21,24.75]],"ltp":2.2,"tv":5.5,"id":61077258}]}]}
{"op":"mcm","clk":"11926167008","pt":1724550797293,"mc":[{"id":"1.232224347","rc":[{"batb":[[0,2.08,39.76],[1,1.21,24.75],[2,1.12,1.76]],"ltp":2.2,"tv":5.5,"id":61077258}]}]}
{"op":"mcm","clk":"11926167146","pt":1724550799502,"mc":[{"id":"1.232224347","rc":[{"batb":[[0,2.1,5],[1,2.08,39.76],[2,1.21,24.75]],"ltp":2.2,"tv":5.5,"id":61077258}]}]}
{"op":"mcm","clk":"11926167329","pt":1724550802787,"mc":[{"id":"1.232224347","rc":[{"batb":[[0,2.08,39.76],[1,1.21,24.75],[2,1.12,1.76]],"ltp":2.2,"tv":5.5,"id":61077258}]}]}
{"op":"mcm","clk":"11926167502","pt":1724550804995,"mc":[{"id":"1.232224347","rc":[{"batb":[[0,2.1,5],[1,2.08,39.76],[2,1.21,24.75]],"ltp":2.2,"tv":5.5,"id":61077258}]}]}
{"op":"mcm","clk":"11926167725","pt":1724550808176,"mc":[{"id":"1.232224347","rc":[{"batb":[[0,2.08,39.76],[1,1.21,24.75],[2,1.12,1.76]],"ltp":2.2,"tv":5.5,"id":61077258}]}]}
{"op":"mcm","clk":"11926167888","pt":1724550810807,"mc":[{"id":"1.232224347","rc":[{"batb":[[0,2.1,5],[1,2.08,39.76],[2,1.21,24.75]],"ltp":2.2,"tv":5.5,"id":61077258}]}]}
{"op":"mcm","clk":"11926168120","pt":1724550814119,"mc":[{"id":"1.232224347","rc":[{"batb":[[0,2.08,39.76],[1,1.21,24.75],[2,1.12,1.76]],"ltp":2.2,"tv":5.5,"id":61077258}]}]}
{"op":"mcm","clk":"11926168282","pt":1724550816281,"mc":[{"id":"1.232224347","rc":[{"batb":[[0,2.1,5],[1,2.08,39.76],[2,1.21,24.75]],"ltp":2.2,"tv":5.5,"id":61077258}]}]}
{"op":"mcm","clk":"11926168516","pt":1724550819520,"mc":[{"id":"1.232224347","rc":[{"batb":[[0,2.08,39.76],[1,1.21,24.75],[2,1.12,1.76]],"ltp":2.2,"tv":5.5,"id":61077258}]}]}
{"op":"mcm","clk":"11926168765","pt":1724550822816,"mc":[{"id":"1.232224347","rc":[{"batb":[[0,2.1,5],[1,2.08,39.76],[2,1.21,24.75]],"ltp":2.2,"tv":5.5,"id":61077258}]}]}
{"op":"mcm","clk":"11926169025","pt":1724550826119,"mc":[{"id":"1.232224347","rc":[{"batb":[[0,2.08,39.76],[1,1.21,24.75],[2,1.12,1.76]],"ltp":2.2,"tv":5.5,"id":61077258}]}]}
{"op":"mcm","clk":"11926169095","pt":1724550826997,"mc":[{"id":"1.232224347","rc":[{"batl":[[0,1.96,50],[1,24,1.51],[2,24,0]],"ltp":1.8,"tv":214.75,"id":48800301}]}]}
{"op":"mcm","clk":"11926169315","pt":1724550829907,"mc":[{"id":"1.232224347","rc":[{"batb":[[0,2.1,5],[1,2.08,39.76],[2,1.21,24.75]],"ltp":2.2,"tv":5.5,"id":61077258}]}]}
{"op":"mcm","clk":"11926169556","pt":1724550833113,"mc":[{"id":"1.232224347","rc":[{"batb":[[0,2.08,39.76],[1,1.21,24.75],[2,1.12,1.76]],"ltp":2.2,"tv":5.5,"id":61077258}]}]}
{"op":"mcm","clk":"11926169767","pt":1724550836205,"mc":[{"id":"1.232224347","rc":[{"batb":[[0,2.1,5],[1,2.08,39.76],[2,1.21,24.75]],"ltp":2.2,"tv":5.5,"id":61077258}]}]}
{"op":"mcm","clk":"11926169985","pt":1724550839507,"mc":[{"id":"1.232224347","rc":[{"batb":[[0,2.08,39.76],[1,1.21,24.75],[2,1.12,1.76]],"ltp":2.2,"tv":5.5,"id":61077258}]}]}
{"op":"mcm","clk":"11926170150","pt":1724550841740,"mc":[{"id":"1.232224347","rc":[{"batb":[[0,2.1,5],[1,2.08,39.76],[2,1.21,24.75]],"ltp":2.2,"tv":5.5,"id":61077258}]}]}
{"op":"mcm","clk":"11926170378","pt":1724550844943,"mc":[{"id":"1.232224347","rc":[{"batb":[[0,2.08,39.76],[1,1.21,24.75],[2,1.12,1.76]],"ltp":2.2,"tv":5.5,"id":61077258}]}]}
{"op":"mcm","clk":"11926170531","pt":1724550847155,"mc":[{"id":"1.232224347","rc":[{"batb":[[0,2.1,5],[1,2.08,39.76],[2,1.21,24.75]],"ltp":2.2,"tv":5.5,"id":61077258}]}]}
{"op":"mcm","clk":"11926170775","pt":1724550850455,"mc":[{"id":"1.232224347","rc":[{"batb":[[0,2.08,39.76],[1,1.21,24.75],[2,1.12,1.76]],"ltp":2.2,"tv":5.5,"id":61077258}]}]}
{"op":"mcm","clk":"11926170978","pt":1724550853454,"mc":[{"id":"1.232224347","rc":[{"batb":[[0,2.1,5],[1,2.08,39.76],[2,1.21,24.75]],"ltp":2.2,"tv":5.5,"id":61077258}]}]}
{"op":"mcm","clk":"11926171197","pt":1724550856752,"mc":[{"id":"1.232224347","rc":[{"batb":[[0,2.08,39.76],[1,1.21,24.75],[2,1.12,1.76]],"ltp":2.2,"tv":5.5,"id":61077258}]}]}
{"op":"mcm","clk":"11926171261","pt":1724550857631,"mc":[{"id":"1.232224347","rc":[{"batl":[[0,14,1.29],[1,24,0.76]],"ltp":2.2,"tv":5.5,"id":61077258}]}]}
{"op":"mcm","clk":"11926171397","pt":1724550859749,"mc":[{"id":"1.232224347","rc":[{"batb":[[0,2.1,5],[1,2.08,39.76],[2,1.21,24.75]],"ltp":2.2,"tv":5.5,"id":61077258}]}]}
{"op":"mcm","clk":"11926171575","pt":1724550863028,"mc":[{"id":"1.232224347","rc":[{"batb":[[0,2.08,39.76],[1,1.21,24.75],[2,1.12,1.76]],"ltp":2.2,"tv":5.5,"id":61077258}]}]}
{"op":"mcm","clk":"11926171734","pt":1724550865750,"mc":[{"id":"1.232224347","rc":[{"batb":[[0,2.1,5],[1,2.08,39.76],[2,1.21,24.75]],"ltp":2.2,"tv":5.5,"id":61077258}]}]}
{"op":"mcm","clk":"11926171920","pt":1724550869041,"mc":[{"id":"1.232224347","rc":[{"batb":[[0,2.08,39.76],[1,1.21,24.75],[2,1.12,1.76]],"ltp":2.2,"tv":5.5,"id":61077258}]}]}
{"op":"mcm","clk":"11926172068","pt":1724550871562,"mc":[{"id":"1.232224347","rc":[{"batb":[[0,2.1,5],[1,2.08,39.76],[2,1.21,24.75]],"ltp":2.2,"tv":5.5,"id":61077258}]}]}
{"op":"mcm","clk":"11926172282","pt":1724550874963,"mc":[{"id":"1.232224347","rc":[{"batb":[[0,2.08,39.76],[1,1.21,24.75],[2,1.12,1.76]],"ltp":2.2,"tv":5.5,"id":61077258}]}]}
{"op":"mcm","clk":"11926172412","pt":1724550877075,"mc":[{"id":"1.232224347","rc":[{"batb":[[0,2.1,5],[1,2.08,39.76],[2,1.21,24.75]],"ltp":2.2,"tv":5.5,"id":61077258}]}]}
{"op":"mcm","clk":"11926172514","pt":1724550878664,"mc":[{"id":"1.232224347","rc":[{"batl":[[0,1.96,50.54]],"ltp":1.8,"tv":214.75,"id":48800301}]}]}
{"op":"mcm","clk":"11926172635","pt":1724550880366,"mc":[{"id":"1.232224347","rc":[{"batb":[[0,2.08,39.76],[1,1.21,24.75],[2,1.12,1.76]],"ltp":2.2,"tv":5.5,"id":61077258}]}]}
{"op":"mcm","clk":"11926172783","pt":1724550882499,"mc":[{"id":"1.232224347","rc":[{"batb":[[0,2.1,5],[1,2.08,39.76],[2,1.21,24.75]],"ltp":2.2,"tv":5.5,"id":61077258}]}]}
{"op":"mcm","clk":"11926173019","pt":1724550885661,"mc":[{"id":"1.232224347","rc":[{"batb":[[0,2.08,39.76],[1,1.21,24.75],[2,1.12,1.76]],"ltp":2.2,"tv":5.5,"id":61077258}]}]}
{"op":"mcm","clk":"11926173197","pt":1724550887875,"mc":[{"id":"1.232224347","rc":[{"batb":[[0,2.1,5],[1,2.08,39.76],[2,1.21,24.75]],"ltp":2.2,"tv":5.5,"id":61077258}]}]}
{"op":"mcm","clk":"11926173467","pt":1724550891177,"mc":[{"id":"1.232224347","rc":[{"batb":[[0,2.08,39.76],[1,1.21,24.75],[2,1.12,1.76]],"ltp":2.2,"tv":5.5,"id":61077258}]}]}
{"op":"mcm","clk":"11926173585","pt":1724550893389,"mc":[{"id":"1.232224347","rc":[{"batb":[[0,2.1,5],[1,2.08,39.76],[2,1.21,24.75]],"ltp":2.2,"tv":5.5,"id":61077258}]}]}
{"op":"mcm","clk":"11926173787","pt":1724550896706,"mc":[{"id":"1.232224347","rc":[{"batb":[[0,2.08,39.76],[1,1.21,24.75],[2,1.12,1.76]],"ltp":2.2,"tv":5.5,"id":61077258}]}]}
{"op":"mcm","clk":"11926173932","pt":1724550898816,"mc":[{"id":"1.232224347","rc":[{"batb":[[0,2.1,5],[1,2.08,39.76],[2,1.21,24.75]],"ltp":2.2,"tv":5.5,"id":61077258}]}]}
{"op":"mcm","clk":"11926174163","pt":1724550902126,"mc":[{"id":"1.232224347","rc":[{"batb":[[0,2.08,39.76],[1,1.21,24.75],[2,1.12,1.76]],"ltp":2.2,"tv":5.5,"id":61077258}]}]}
{"op":"mcm","clk":"11926174346","pt":1724550904706,"mc":[{"id":"1.232224347","rc":[{"batb":[[0,2.1,5],[1,2.08,39.76],[2,1.21,24.75]],"ltp":2.2,"tv":5.5,"id":61077258}]}]}
{"op":"mcm","clk":"11926174552","pt":1724550908023,"mc":[{"id":"1.232224347","rc":[{"batb":[[0,2.08,39.76],[1,1.21,24.75],[2,1.12,1.76]],"ltp":2.2,"tv":5.5,"id":61077258}]}]}
{"op":"mcm","clk":"11926174733","pt":1724550910803,"mc":[{"id":"1.232224347","rc":[{"batb":[[0,2.1,5],[1,2.08,39.76],[2,1.21,24.75]],"ltp":2.2,"tv":5.5,"id":61077258}]}]}
{"op":"mcm","clk":"11926174933","pt":1724550914137,"mc":[{"id":"1.232224347","rc":[{"batb":[[0,2.08,39.76],[1,1.21,24.75],[2,1.12,1.76]],"ltp":2.2,"tv":5.5,"id":61077258}]}]}
{"op":"mcm","clk":"11926175075","pt":1724550916245,"mc":[{"id":"1.232224347","rc":[{"batb":[[0,2.1,5],[1,2.08,39.76],[2,1.21,24.75]],"ltp":2.2,"tv":5.5,"id":61077258}]}]}
{"op":"mcm","clk":"11926175339","pt":1724550919506,"mc":[{"id":"1.232224347","rc":[{"batb":[[0,2.08,39.76],[1,1.21,24.75],[2,1.12,1.76]],"ltp":2.2,"tv":5.5,"id":61077258}]}]}
{"op":"mcm","clk":"11926175666","pt":1724550924855,"mc":[{"id":"1.232224347","rc":[{"batb":[[0,2.1,5],[1,2.08,39.76],[2,1.21,24.75]],"ltp":2.2,"tv":5.5,"id":61077258}]}]}
{"op":"mcm","clk":"11926175850","pt":1724550928148,"mc":[{"id":"1.232224347","rc":[{"batb":[[0,2.08,39.76],[1,1.21,24.75],[2,1.12,1.76]],"ltp":2.2,"tv":5.5,"id":61077258}]}]}
{"op":"mcm","clk":"11926175996","pt":1724550930458,"mc":[{"id":"1.232224347","rc":[{"batb":[[0,2.1,5],[1,2.08,39.76],[2,1.21,24.75]],"ltp":2.2,"tv":5.5,"id":61077258}]}]}
{"op":"mcm","clk":"11926176171","pt":1724550933765,"mc":[{"id":"1.232224347","rc":[{"batb":[[0,2.08,39.76],[1,1.21,24.75],[2,1.12,1.76]],"ltp":2.2,"tv":5.5,"id":61077258}]}]}
{"op":"mcm","clk":"11926176314","pt":1724550936047,"mc":[{"id":"1.232224347","rc":[{"batb":[[0,2.1,5],[1,2.08,39.76],[2,1.21,24.75]],"ltp":2.2,"tv":5.5,"id":61077258}]}]}
{"op":"mcm","clk":"11926176488","pt":1724550939342,"mc":[{"id":"1.232224347","rc":[{"batb":[[0,2.08,39.76],[1,1.21,24.75],[2,1.12,1.76]],"ltp":2.2,"tv":5.5,"id":61077258}]}]}
{"op":"mcm","clk":"11926176612","pt":1724550941764,"mc":[{"id":"1.232224347","rc":[{"batb":[[0,2.1,5],[1,2.08,39.76],[2,1.21,24.75]],"ltp":2.2,"tv":5.5,"id":61077258}]}]}
{"op":"mcm","clk":"11926176774","pt":1724550945073,"mc":[{"id":"1.232224347","rc":[{"batb":[[0,2.08,39.76],[1,1.21,24.75],[2,1.12,1.76]],"ltp":2.2,"tv":5.5,"id":61077258}]}]}
{"op":"mcm","clk":"11926176950","pt":1724550947649,"mc":[{"id":"1.232224347","rc":[{"batb":[[0,2.1,5],[1,2.08,39.76],[2,1.21,24.75]],"ltp":2.2,"tv":5.5,"id":61077258}]}]}
{"op":"mcm","clk":"11926177152","pt":1724550950948,"mc":[{"id":"1.232224347","rc":[{"batb":[[0,2.08,39.76],[1,1.21,24.75],[2,1.12,1.76]],"ltp":2.2,"tv":5.5,"id":61077258}]}]}
{"op":"mcm","clk":"11926177356","pt":1724550954658,"mc":[{"id":"1.232224347","rc":[{"batb":[[0,2.1,5],[1,2.08,39.76],[2,1.21,24.75]],"ltp":2.2,"tv":5.5,"id":61077258}]}]}
{"op":"mcm","clk":"11926177529","pt":1724550958060,"mc":[{"id":"1.232224347","rc":[{"batb":[[0,2.08,39.76],[1,1.21,24.75],[2,1.12,1.76]],"ltp":2.2,"tv":5.5,"id":61077258}]}]}
{"op":"mcm","clk":"11926177658","pt":1724550960370,"mc":[{"id":"1.232224347","rc":[{"batb":[[0,2.1,5],[1,2.08,39.76],[2,1.21,24.75]],"ltp":2.2,"tv":5.5,"id":61077258}]}]}
{"op":"mcm","clk":"11926177865","pt":1724550963669,"mc":[{"id":"1.232224347","rc":[{"batb":[[0,2.08,39.76],[1,1.21,24.75],[2,1.12,1.76]],"ltp":2.2,"tv":5.5,"id":61077258}]}]}
{"op":"mcm","clk":"11926178016","pt":1724550966398,"mc":[{"id":"1.232224347","rc":[{"batb":[[0,2.1,5],[1,2.08,39.76],[2,1.21,24.75]],"ltp":2.2,"tv":5.5,"id":61077258}]}]}
{"op":"mcm","clk":"11926178200","pt":1724550969703,"mc":[{"id":"1.232224347","rc":[{"batb":[[0,2.08,39.76],[1,1.21,24.75],[2,1.12,1.76]],"ltp":2.2,"tv":5.5,"id":61077258}]}]}
{"op":"mcm","clk":"11926178398","pt":1724550972597,"mc":[{"id":"1.232224347","rc":[{"batb":[[0,2.1,5],[1,2.08,39.76],[2,1.21,24.75]],"ltp":2.2,"tv":5.5,"id":61077258}]}]}
{"op":"mcm","clk":"11926178620","pt":1724550976103,"mc":[{"id":"1.232224347","rc":[{"batb":[[0,2.08,39.76],[1,1.21,24.75],[2,1.12,1.76]],"ltp":2.2,"tv":5.5,"id":61077258}]}]}
{"op":"mcm","clk":"11926178760","pt":1724550978785,"mc":[{"id":"1.232224347","rc":[{"batb":[[0,2.1,5],[1,2.08,39.76],[2,1.21,24.75]],"ltp":2.2,"tv":5.5,"id":61077258}]}]}
{"op":"mcm","clk":"11926178991","pt":1724550982122,"mc":[{"id":"1.232224347","rc":[{"batb":[[0,2.08,39.76],[1,1.21,24.75],[2,1.12,1.76]],"ltp":2.2,"tv":5.5,"id":61077258}]}]}
{"op":"mcm","clk":"11926179199","pt":1724550984911,"mc":[{"id":"1.232224347","rc":[{"batb":[[0,2.1,5],[1,2.08,39.76],[2,1.21,24.75]],"ltp":2.2,"tv":5.5,"id":61077258}]}]}
{"op":"mcm","clk":"11926179421","pt":1724550988209,"mc":[{"id":"1.232224347","rc":[{"batb":[[0,2.08,39.76],[1,1.21,24.75],[2,1.12,1.76]],"ltp":2.2,"tv":5.5,"id":61077258}]}]}
{"op":"mcm","clk":"11926179582","pt":1724550990891,"mc":[{"id":"1.232224347","rc":[{"batb":[[0,2.1,5],[1,2.08,39.76],[2,1.21,24.75]],"ltp":2.2,"tv":5.5,"id":61077258}]}]}
{"op":"mcm","clk":"11926179792","pt":1724550994333,"mc":[{"id":"1.232224347","rc":[{"batb":[[0,2.08,39.76],[1,1.21,24.75],[2,1.12,1.76]],"ltp":2.2,"tv":5.5,"id":61077258}]}]}
{"op":"mcm","clk":"11926179931","pt":1724550996921,"mc":[{"id":"1.232224347","rc":[{"batb":[[0,2.1,5],[1,2.08,39.76],[2,1.21,24.75]],"ltp":2.2,"tv":5.5,"id":61077258}]}]}
{"op":"mcm","clk":"11926180161","pt":1724551000330,"mc":[{"id":"1.232224347","rc":[{"batb":[[0,2.08,39.76],[1,1.21,24.75],[2,1.12,1.76]],"ltp":2.2,"tv":5.5,"id":61077258}]}]}
{"op":"mcm","clk":"11926180316","pt":1724551002905,"mc":[{"id":"1.232224347","rc":[{"batb":[[0,2.1,5],[1,2.08,39.76],[2,1.21,24.75]],"ltp":2.2,"tv":5.5,"id":61077258}]}]}
{"op":"mcm","clk":"11926180498","pt":1724551006249,"mc":[{"id":"1.232224347","rc":[{"batb":[[0,2.08,39.76],[1,1.21,24.75],[2,1.12,1.76]],"ltp":2.2,"tv":5.5,"id":61077258}]}]}
{"op":"mcm","clk":"11926180636","pt":1724551008935,"mc":[{"id":"1.232224347","rc":[{"batb":[[0,2.1,5],[1,2.08,39.76],[2,1.21,24.75]],"ltp":2.2,"tv":5.5,"id":61077258}]}]}
{"op":"mcm","clk":"11926180803","pt":1724551012113,"mc":[{"id":"1.232224347","rc":[{"batb":[[0,2.08,39.76],[1,1.21,24.75],[2,1.12,1.76]],"ltp":2.2,"tv":5.5,"id":61077258}]}]}
{"op":"mcm","clk":"11926180988","pt":1724551015043,"mc":[{"id":"1.232224347","rc":[{"batb":[[0,2.1,5],[1,2.08,39.76],[2,1.21,24.75]],"ltp":2.2,"tv":5.5,"id":61077258}]}]}
{"op":"mcm","clk":"11926181195","pt":1724551018558,"mc":[{"id":"1.232224347","rc":[{"batb":[[0,2.08,39.76],[1,1.21,24.75],[2,1.12,1.76]],"ltp":2.2,"tv":5.5,"id":61077258}]}]}
{"op":"mcm","clk":"11926181315","pt":1724551020856,"mc":[{"id":"1.232224347","rc":[{"batb":[[0,2.1,5],[1,2.08,39.76],[2,1.21,24.75]],"ltp":2.2,"tv":5.5,"id":61077258}]}]}
{"op":"mcm","clk":"11926181507","pt":1724551024251,"mc":[{"id":"1.232224347","rc":[{"batb":[[0,2.08,39.76],[1,1.21,24.75],[2,1.12,1.76]],"ltp":2.2,"tv":5.5,"id":61077258}]}]}
{"op":"mcm","clk":"11926181651","pt":1724551026934,"mc":[{"id":"1.232224347","rc":[{"batb":[[0,2.1,5],[1,2.08,39.76],[2,1.21,24.75]],"ltp":2.2,"tv":5.5,"id":61077258}]}]}
{"op":"mcm","clk":"11926181854","pt":1724551030463,"mc":[{"id":"1.232224347","rc":[{"batb":[[0,2.08,39.76],[1,1.21,24.75],[2,1.12,1.76]],"ltp":2.2,"tv":5.5,"id":61077258}]}]}
{"op":"mcm","clk":"11926182012","pt":1724551032959,"mc":[{"id":"1.232224347","rc":[{"batb":[[0,2.1,5],[1,2.08,39.76],[2,1.21,24.75]],"ltp":2.2,"tv":5.5,"id":61077258}]}]}
{"op":"mcm","clk":"11926182235","pt":1724551036366,"mc":[{"id":"1.232224347","rc":[{"batb":[[0,2.08,39.76],[1,1.21,24.75],[2,1.12,1.76]],"ltp":2.2,"tv":5.5,"id":61077258}]}]}
{"op":"mcm","clk":"11926182386","pt":1724551038854,"mc":[{"id":"1.232224347","rc":[{"batb":[[0,2.1,5],[1,2.08,39.76],[2,1.21,24.75]],"ltp":2.2,"tv":5.5,"id":61077258}]}]}
{"op":"mcm","clk":"11926182617","pt":1724551042155,"mc":[{"id":"1.232224347","rc":[{"batb":[[0,2.08,39.76],[1,1.21,24.75],[2,1.12,1.76]],"ltp":2.2,"tv":5.5,"id":61077258}]}]}
{"op":"mcm","clk":"11926182787","pt":1724551044873,"mc":[{"id":"1.232224347","rc":[{"batb":[[0,2.1,5],[1,2.08,39.76],[2,1.21,24.75]],"ltp":2.2,"tv":5.5,"id":61077258}]}]}
{"op":"mcm","clk":"11926182968","pt":1724551048178,"mc":[{"id":"1.232224347","rc":[{"batb":[[0,2.08,39.76],[1,1.21,24.75],[2,1.12,1.76]],"ltp":2.2,"tv":5.5,"id":61077258}]}]}
{"op":"mcm","clk":"11926183172","pt":1724551051578,"mc":[{"id":"1.232224347","rc":[{"batb":[[0,2.1,5],[1,2.08,39.76],[2,1.21,24.75]],"ltp":2.2,"tv":5.5,"id":61077258}]}]}
{"op":"mcm","clk":"11926183388","pt":1724551054870,"mc":[{"id":"1.232224347","rc":[{"batb":[[0,2.08,39.76],[1,1.21,24.75],[2,1.12,1.76]],"ltp":2.2,"tv":5.5,"id":61077258}]}]}
{"op":"mcm","clk":"11926183516","pt":1724551057181,"mc":[{"id":"1.232224347","rc":[{"batb":[[0,2.1,5],[1,2.08,39.76],[2,1.21,24.75]],"ltp":2.2,"tv":5.5,"id":61077258}]}]}
{"op":"mcm","clk":"11926183686","pt":1724551060476,"mc":[{"id":"1.232224347","rc":[{"batb":[[0,2.08,39.76],[1,1.21,24.75],[2,1.12,1.76]],"ltp":2.2,"tv":5.5,"id":61077258}]}]}
{"op":"mcm","clk":"11926183882","pt":1724551063598,"mc":[{"id":"1.232224347","rc":[{"batb":[[0,2.1,5],[1,2.08,39.76],[2,1.21,24.75]],"ltp":2.2,"tv":5.5,"id":61077258}]}]}
{"op":"mcm","clk":"11926184088","pt":1724551066895,"mc":[{"id":"1.232224347","rc":[{"batb":[[0,2.08,39.76],[1,1.21,24.75],[2,1.12,1.76]],"ltp":2.2,"tv":5.5,"id":61077258}]}]}
{"op":"mcm","clk":"11926184245","pt":1724551069284,"mc":[{"id":"1.232224347","rc":[{"batb":[[0,2.1,5],[1,2.08,39.76],[2,1.21,24.75]],"ltp":2.2,"tv":5.5,"id":61077258}]}]}
{"op":"mcm","clk":"11926184487","pt":1724551072721,"mc":[{"id":"1.232224347","rc":[{"batb":[[0,2.08,39.76],[1,1.21,24.75],[2,1.12,1.76]],"ltp":2.2,"tv":5.5,"id":61077258}]}]}
{"op":"mcm","clk":"11926184665","pt":1724551074987,"mc":[{"id":"1.232224347","rc":[{"batb":[[0,2.1,5],[1,2.08,39.76],[2,1.21,24.75]],"ltp":2.2,"tv":5.5,"id":61077258}]}]}
{"op":"mcm","clk":"11926184855","pt":1724551078332,"mc":[{"id":"1.232224347","rc":[{"batb":[[0,2.08,39.76],[1,1.21,24.75],[2,1.12,1.76]],"ltp":2.2,"tv":5.5,"id":61077258}]}]}
{"op":"mcm","clk":"11926184972","pt":1724551080598,"mc":[{"id":"1.232224347","rc":[{"batb":[[0,2.1,5],[1,2.08,39.76],[2,1.21,24.75]],"ltp":2.2,"tv":5.5,"id":61077258}]}]}
{"op":"mcm","clk":"11926185144","pt":1724551083832,"mc":[{"id":"1.232224347","rc":[{"batb":[[0,2.08,39.76],[1,1.21,24.75],[2,1.12,1.76]],"ltp":2.2,"tv":5.5,"id":61077258}]}]}
{"op":"mcm","clk":"11926185253","pt":1724551085992,"mc":[{"id":"1.232224347","rc":[{"batb":[[0,2.1,5],[1,2.08,39.76],[2,1.21,24.75]],"ltp":2.2,"tv":5.5,"id":61077258}]}]}
{"op":"mcm","clk":"11926185432","pt":1724551089432,"mc":[{"id":"1.232224347","rc":[{"batb":[[0,2.08,39.76],[1,1.21,24.75],[2,1.12,1.76]],"ltp":2.2,"tv":5.5,"id":61077258}]}]}
{"op":"mcm","clk":"11926185580","pt":1724551092208,"mc":[{"id":"1.232224347","rc":[{"batb":[[0,2.1,5],[1,2.08,39.76],[2,1.21,24.75]],"ltp":2.2,"tv":5.5,"id":61077258}]}]}
{"op":"mcm","clk":"11926185740","pt":1724551095539,"mc":[{"id":"1.232224347","rc":[{"batb":[[0,2.08,39.76],[1,1.21,24.75],[2,1.12,1.76]],"ltp":2.2,"tv":5.5,"id":61077258}]}]}
{"op":"mcm","clk":"11926185870","pt":1724551097927,"mc":[{"id":"1.232224347","rc":[{"batb":[[0,2.1,5],[1,2.08,39.76],[2,1.21,24.75]],"ltp":2.2,"tv":5.5,"id":61077258}]}]}
{"op":"mcm","clk":"11926186041","pt":1724551101111,"mc":[{"id":"1.232224347","rc":[{"batb":[[0,2.08,39.76],[1,1.21,24.75],[2,1.12,1.76]],"ltp":2.2,"tv":5.5,"id":61077258}]}]}
{"op":"mcm","clk":"11926186206","pt":1724551103957,"mc":[{"id":"1.232224347","rc":[{"batb":[[0,2.1,5],[1,2.08,39.76],[2,1.21,24.75]],"ltp":2.2,"tv":5.5,"id":61077258}]}]}
{"op":"mcm","clk":"11926186394","pt":1724551107251,"mc":[{"id":"1.232224347","rc":[{"batb":[[0,2.08,39.76],[1,1.21,24.75],[2,1.12,1.76]],"ltp":2.2,"tv":5.5,"id":61077258}]}]}
{"op":"mcm","clk":"11926186535","pt":1724551109923,"mc":[{"id":"1.232224347","rc":[{"batb":[[0,2.1,5],[1,2.08,39.76],[2,1.21,24.75]],"ltp":2.2,"tv":5.5,"id":61077258}]}]}
{"op":"mcm","clk":"11926186739","pt":1724551113127,"mc":[{"id":"1.232224347","rc":[{"batb":[[0,2.08,39.76],[1,1.21,24.75],[2,1.12,1.76]],"ltp":2.2,"tv":5.5,"id":61077258}]}]}
{"op":"mcm","clk":"11926186925","pt":1724551116021,"mc":[{"id":"1.232224347","rc":[{"batb":[[0,2.1,5],[1,2.08,39.76],[2,1.21,24.75]],"ltp":2.2,"tv":5.5,"id":61077258}]}]}
{"op":"mcm","clk":"11926187127","pt":1724551119409,"mc":[{"id":"1.232224347","rc":[{"batb":[[0,2.08,39.76],[1,1.21,24.75],[2,1.12,1.76]],"ltp":2.2,"tv":5.5,"id":61077258}]}]}
{"op":"mcm","clk":"11926187247","pt":1724551122029,"mc":[{"id":"1.232224347","rc":[{"batb":[[0,2.1,5],[1,2.08,39.76],[2,1.21,24.75]],"ltp":2.2,"tv":5.5,"id":61077258}]}]}
{"op":"mcm","clk":"11926187415","pt":1724551125324,"mc":[{"id":"1.232224347","rc":[{"batb":[[0,2.08,39.76],[1,1.21,24.75],[2,1.12,1.76]],"ltp":2.2,"tv":5.5,"id":61077258}]}]}
{"op":"mcm","clk":"11926187583","pt":1724551128052,"mc":[{"id":"1.232224347","rc":[{"batb":[[0,2.1,5],[1,2.08,39.76],[2,1.21,24.75]],"ltp":2.2,"tv":5.5,"id":61077258}]}]}
{"op":"mcm","clk":"11926187740","pt":1724551131346,"mc":[{"id":"1.232224347","rc":[{"batb":[[0,2.08,39.76],[1,1.21,24.75],[2,1.12,1.76]],"ltp":2.2,"tv":5.5,"id":61077258}]}]}
{"op":"mcm","clk":"11926187890","pt":1724551134069,"mc":[{"id":"1.232224347","rc":[{"batb":[[0,2.1,5],[1,2.08,39.76],[2,1.21,24.75]],"ltp":2.2,"tv":5.5,"id":61077258}]}]}
{"op":"mcm","clk":"11926188050","pt":1724551137486,"mc":[{"id":"1.232224347","rc":[{"batb":[[0,2.08,39.76],[1,1.21,24.75],[2,1.12,1.76]],"ltp":2.2,"tv":5.5,"id":61077258}]}]}
{"op":"mcm","clk":"11926188161","pt":1724551139949,"mc":[{"id":"1.232224347","rc":[{"batb":[[0,2.1,5],[1,2.08,39.76],[2,1.21,24.75]],"ltp":2.2,"tv":5.5,"id":61077258}]}]}
{"op":"mcm","clk":"11926188341","pt":1724551143253,"mc":[{"id":"1.232224347","rc":[{"batb":[[0,2.08,39.76],[1,1.21,24.75],[2,1.12,1.76]],"ltp":2.2,"tv":5.5,"id":61077258}]}]}
{"op":"mcm","clk":"11926188539","pt":1724551145987,"mc":[{"id":"1.232224347","rc":[{"batb":[[0,2.1,5],[1,2.08,39.76],[2,1.21,24.75]],"ltp":2.2,"tv":5.5,"id":61077258}]}]}
{"op":"mcm","clk":"11926188729","pt":1724551149148,"mc":[{"id":"1.232224347","rc":[{"batb":[[0,2.08,39.76],[1,1.21,24.75],[2,1.12,1.76]],"ltp":2.2,"tv":5.5,"id":61077258}]}]}
{"op":"mcm","clk":"11926188895","pt":1724551152075,"mc":[{"id":"1.232224347","rc":[{"batb":[[0,2.1,5],[1,2.08,39.76],[2,1.21,24.75]],"ltp":2.2,"tv":5.5,"id":61077258}]}]}
{"op":"mcm","clk":"11926189043","pt":1724551155370,"mc":[{"id":"1.232224347","rc":[{"batb":[[0,2.08,39.76],[1,1.21,24.75],[2,1.12,1.76]],"ltp":2.2,"tv":5.5,"id":61077258}]}]}
{"op":"mcm","clk":"11926189204","pt":1724551158299,"mc":[{"id":"1.232224347","rc":[{"batb":[[0,2.1,5],[1,2.08,39.76],[2,1.21,24.75]],"ltp":2.2,"tv":5.5,"id":61077258}]}]}
{"op":"mcm","clk":"11926189293","pt":1724551159682,"mc":[{"id":"1.232224347","rc":[{"batb":[[0,1.21,25.63]],"ltp":1.8,"tv":214.75,"id":48800301}]}]}
{"op":"mcm","clk":"11926189434","pt":1724551161795,"mc":[{"id":"1.232224347","rc":[{"batb":[[0,2.08,39.76],[1,1.21,24.75],[2,1.12,1.76]],"ltp":2.2,"tv":5.5,"id":61077258}]}]}
{"op":"mcm","clk":"11926189556","pt":1724551164007,"mc":[{"id":"1.232224347","rc":[{"batb":[[0,2.1,5],[1,2.08,39.76],[2,1.21,24.75]],"ltp":2.2,"tv":5.5,"id":61077258}]}]}
{"op":"mcm","clk":"11926189756","pt":1724551167404,"mc":[{"id":"1.232224347","rc":[{"batb":[[0,2.08,39.76],[1,1.21,24.75],[2,1.12,1.76]],"ltp":2.2,"tv":5.5,"id":61077258}]}]}
{"op":"mcm","clk":"11926189914","pt":1724551170028,"mc":[{"id":"1.232224347","rc":[{"batb":[[0,2.1,5],[1,2.08,39.76],[2,1.21,24.75]],"ltp":2.2,"tv":5.5,"id":61077258}]}]}
{"op":"mcm","clk":"11926190124","pt":1724551173418,"mc":[{"id":"1.232224347","rc":[{"batb":[[0,2.08,39.76],[1,1.21,24.75],[2,1.12,1.76]],"ltp":2.2,"tv":5.5,"id":61077258}]}]}
{"op":"mcm","clk":"11926190267","pt":1724551175985,"mc":[{"id":"1.232224347","rc":[{"batb":[[0,2.1,5],[1,2.08,39.76],[2,1.21,24.75]],"ltp":2.2,"tv":5.5,"id":61077258}]}]}
{"op":"mcm","clk":"11926190466","pt":1724551179323,"mc":[{"id":"1.232224347","rc":[{"batb":[[0,2.08,39.76],[1,1.21,24.75],[2,1.12,1.76]],"ltp":2.2,"tv":5.5,"id":61077258}]}]}
{"op":"mcm","clk":"11926190653","pt":1724551182013,"mc":[{"id":"1.232224347","rc":[{"batb":[[0,2.1,5],[1,2.08,39.76],[2,1.21,24.75]],"ltp":2.2,"tv":5.5,"id":61077258}]}]}
{"op":"mcm","clk":"11926190851","pt":1724551185410,"mc":[{"id":"1.232224347","rc":[{"batb":[[0,2.08,39.76],[1,1.21,24.75],[2,1.12,1.76]],"ltp":2.2,"tv":5.5,"id":61077258}]}]}
{"op":"mcm","clk":"11926190996","pt":1724551187990,"mc":[{"id":"1.232224347","rc":[{"batb":[[0,2.1,5],[1,2.08,39.76],[2,1.21,24.75]],"ltp":2.2,"tv":5.5,"id":61077258}]}]}
{"op":"mcm","clk":"11926191196","pt":1724551191429,"mc":[{"id":"1.232224347","rc":[{"batb":[[0,2.08,39.76],[1,1.21,24.75],[2,1.12,1.76]],"ltp":2.2,"tv":5.5,"id":61077258}]}]}
{"op":"mcm","clk":"11926191418","pt":1724551195133,"mc":[{"id":"1.232224347","rc":[{"batb":[[0,2.1,5],[1,2.08,39.76],[2,1.21,24.75]],"ltp":2.2,"tv":5.5,"id":61077258}]}]}
{"op":"mcm","clk":"11926191643","pt":1724551198437,"mc":[{"id":"1.232224347","rc":[{"batb":[[0,2.08,39.76],[1,1.21,24.75],[2,1.12,1.76]],"ltp":2.2,"tv":5.5,"id":61077258}]}]}
{"op":"mcm","clk":"11926191889","pt":1724551201333,"mc":[{"id":"1.232224347","rc":[{"batb":[[0,2.1,5],[1,2.08,39.76],[2,1.21,24.75]],"ltp":2.2,"tv":5.5,"id":61077258}]}]}
{"op":"mcm","clk":"11926192202","pt":1724551204521,"mc":[{"id":"1.232224347","rc":[{"batb":[[0,2.08,39.76],[1,1.21,24.75],[2,1.12,1.76]],"ltp":2.2,"tv":5.5,"id":61077258}]}]}
{"op":"mcm","clk":"11926192402","pt":1724551206747,"mc":[{"id":"1.232224347","rc":[{"batb":[[0,2.1,5],[1,2.08,39.76],[2,1.21,24.75]],"ltp":2.2,"tv":5.5,"id":61077258}]}]}
{"op":"mcm","clk":"11926192644","pt":1724551210027,"mc":[{"id":"1.232224347","rc":[{"batb":[[0,2.08,39.76],[1,1.21,24.75],[2,1.12,1.76]],"ltp":2.2,"tv":5.5,"id":61077258}]}]}
{"op":"mcm","clk":"11926192922","pt":1724551212525,"mc":[{"id":"1.232224347","rc":[{"batb":[[0,2.1,5],[1,2.08,39.76],[2,1.21,24.75]],"ltp":2.2,"tv":5.5,"id":61077258}]}]}
{"op":"mcm","clk":"11926193207","pt":1724551215934,"mc":[{"id":"1.232224347","rc":[{"batb":[[0,2.08,39.76],[1,1.21,24.75],[2,1.12,1.76]],"ltp":2.2,"tv":5.5,"id":61077258}]}]}
{"op":"mcm","clk":"11926193354","pt":1724551218139,"mc":[{"id":"1.232224347","rc":[{"batb":[[0,2.1,5],[1,2.08,39.76],[2,1.21,24.75]],"ltp":2.2,"tv":5.5,"id":61077258}]}]}
{"op":"mcm","clk":"11926193549","pt":1724551221535,"mc":[{"id":"1.232224347","rc":[{"batb":[[0,2.08,39.76],[1,1.21,24.75],[2,1.12,1.76]],"ltp":2.2,"tv":5.5,"id":61077258}]}]}
{"op":"mcm","clk":"11926193700","pt":1724551224051,"mc":[{"id":"1.232224347","rc":[{"batb":[[0,2.1,5],[1,2.08,39.76],[2,1.21,24.75]],"ltp":2.2,"tv":5.5,"id":61077258}]}]}
{"op":"mcm","clk":"11926193926","pt":1724551227556,"mc":[{"id":"1.232224347","rc":[{"batb":[[0,2.08,39.76],[1,1.21,24.75],[2,1.12,1.76]],"ltp":2.2,"tv":5.5,"id":61077258}]}]}
{"op":"mcm","clk":"11926194097","pt":1724551230090,"mc":[{"id":"1.232224347","rc":[{"batb":[[0,2.1,5],[1,2.08,39.76],[2,1.21,24.75]],"ltp":2.2,"tv":5.5,"id":61077258}]}]}
{"op":"mcm","clk":"11926194279","pt":1724551233536,"mc":[{"id":"1.232224347","rc":[{"batb":[[0,2.08,39.76],[1,1.21,24.75],[2,1.12,1.76]],"ltp":2.2,"tv":5.5,"id":61077258}]}]}
{"op":"mcm","clk":"11926194438","pt":1724551236156,"mc":[{"id":"1.232224347","rc":[{"batb":[[0,2.1,5],[1,2.08,39.76],[2,1.21,24.75]],"ltp":2.2,"tv":5.5,"id":61077258}]}]}
{"op":"mcm","clk":"11926194667","pt":1724551239569,"mc":[{"id":"1.232224347","rc":[{"batb":[[0,2.08,39.76],[1,1.21,24.75],[2,1.12,1.76]],"ltp":2.2,"tv":5.5,"id":61077258}]}]}
{"op":"mcm","clk":"11926194849","pt":1724551242047,"mc":[{"id":"1.232224347","rc":[{"batb":[[0,2.1,5],[1,2.08,39.76],[2,1.21,24.75]],"ltp":2.2,"tv":5.5,"id":61077258}]}]}
{"op":"mcm","clk":"11926195099","pt":1724551245647,"mc":[{"id":"1.232224347","rc":[{"batb":[[0,2.08,39.76],[1,1.21,24.75],[2,1.12,1.76]],"ltp":2.2,"tv":5.5,"id":61077258}]}]}
{"op":"mcm","clk":"11926195246","pt":1724551248173,"mc":[{"id":"1.232224347","rc":[{"batb":[[0,2.1,5],[1,2.08,39.76],[2,1.21,24.75]],"ltp":2.2,"tv":5.5,"id":61077258}]}]}
{"op":"mcm","clk":"11926195487","pt":1724551251582,"mc":[{"id":"1.232224347","rc":[{"batb":[[0,2.08,39.76],[1,1.21,24.75],[2,1.12,1.76]],"ltp":2.2,"tv":5.5,"id":61077258}]}]}
{"op":"mcm","clk":"11926195654","pt":1724551254480,"mc":[{"id":"1.232224347","rc":[{"batb":[[0,2.1,5],[1,2.08,39.76],[2,1.21,24.75]],"ltp":2.2,"tv":5.5,"id":61077258}]}]}
{"op":"mcm","clk":"11926195817","pt":1724551257676,"mc":[{"id":"1.232224347","rc":[{"batb":[[0,2.08,39.76],[1,1.21,24.75],[2,1.12,1.76]],"ltp":2.2,"tv":5.5,"id":61077258}]}]}
{"op":"mcm","clk":"11926195951","pt":1724551259797,"mc":[{"id":"1.232224347","rc":[{"batb":[[0,2.1,5],[1,2.08,39.76],[2,1.21,24.75]],"ltp":2.2,"tv":5.5,"id":61077258}]}]}
{"op":"mcm","clk":"11926196158","pt":1724551263099,"mc":[{"id":"1.232224347","rc":[{"batb":[[0,2.08,39.76],[1,1.21,24.75],[2,1.12,1.76]],"ltp":2.2,"tv":5.5,"id":61077258}]}]}
{"op":"mcm","clk":"11926196306","pt":1724551265284,"mc":[{"id":"1.232224347","rc":[{"batb":[[0,2.1,5],[1,2.08,39.76],[2,1.21,24.75]],"ltp":2.2,"tv":5.5,"id":61077258}]}]}
{"op":"mcm","clk":"11926196504","pt":1724551268700,"mc":[{"id":"1.232224347","rc":[{"batb":[[0,2.08,39.76],[1,1.21,24.75],[2,1.12,1.76]],"ltp":2.2,"tv":5.5,"id":61077258}]}]}
{"op":"mcm","clk":"11926196630","pt":1724551270871,"mc":[{"id":"1.232224347","rc":[{"batb":[[0,2.1,5],[1,2.08,39.76],[2,1.21,24.75]],"ltp":2.2,"tv":5.5,"id":61077258}]}]}
{"op":"mcm","clk":"11926196854","pt":1724551274169,"mc":[{"id":"1.232224347","rc":[{"batb":[[0,2.08,39.76],[1,1.21,24.75],[2,1.12,1.76]],"ltp":2.2,"tv":5.5,"id":61077258}]}]}
{"op":"mcm","clk":"11926196964","pt":1724551276391,"mc":[{"id":"1.232224347","rc":[{"batb":[[0,2.1,5],[1,2.08,39.76],[2,1.21,24.75]],"ltp":2.2,"tv":5.5,"id":61077258}]}]}
{"op":"mcm","clk":"11926197150","pt":1724551279594,"mc":[{"id":"1.232224347","rc":[{"batb":[[0,2.08,39.76],[1,1.21,24.75],[2,1.12,1.76]],"ltp":2.2,"tv":5.5,"id":61077258}]}]}
{"op":"mcm","clk":"11926197319","pt":1724551282798,"mc":[{"id":"1.232224347","rc":[{"batb":[[0,2.1,5],[1,2.08,39.76],[2,1.21,24.75]],"ltp":2.2,"tv":5.5,"id":61077258}]}]}
{"op":"mcm","clk":"11926197478","pt":1724551285994,"mc":[{"id":"1.232224347","rc":[{"batb":[[0,2.08,39.76],[1,1.21,24.75],[2,1.12,1.76]],"ltp":2.2,"tv":5.5,"id":61077258}]}]}
{"op":"mcm","clk":"11926197641","pt":1724551288991,"mc":[{"id":"1.232224347","rc":[{"batb":[[0,2.1,5],[1,2.08,39.76],[2,1.21,24.75]],"ltp":2.2,"tv":5.5,"id":61077258}]}]}
{"op":"mcm","clk":"11926197828","pt":1724551292297,"mc":[{"id":"1.232224347","rc":[{"batb":[[0,2.08,39.76],[1,1.21,24.75],[2,1.12,1.76]],"ltp":2.2,"tv":5.5,"id":61077258}]}]}
{"op":"mcm","clk":"11926197985","pt":1724551295081,"mc":[{"id":"1.232224347","rc":[{"batb":[[0,2.1,5],[1,2.08,39.76],[2,1.21,24.75]],"ltp":2.2,"tv":5.5,"id":61077258}]}]}
{"op":"mcm","clk":"11926198158","pt":1724551298425,"mc":[{"id":"1.232224347","rc":[{"batb":[[0,2.08,39.76],[1,1.21,24.75],[2,1.12,1.76]],"ltp":2.2,"tv":5.5,"id":61077258}]}]}
{"op":"mcm","clk":"11926198270","pt":1724551300597,"mc":[{"id":"1.232224347","rc":[{"batb":[[0,2.1,5],[1,2.08,39.76],[2,1.21,24.75]],"ltp":2.2,"tv":5.5,"id":61077258}]}]}
{"op":"mcm","clk":"11926198452","pt":1724551303906,"mc":[{"id":"1.232224347","rc":[{"batb":[[0,2.08,39.76],[1,1.21,24.75],[2,1.12,1.76]],"ltp":2.2,"tv":5.5,"id":61077258}]}]}
{"op":"mcm","clk":"11926198590","pt":1724551306528,"mc":[{"id":"1.232224347","rc":[{"batb":[[0,2.1,5],[1,2.08,39.76],[2,1.21,24.75]],"ltp":2.2,"tv":5.5,"id":61077258}]}]}
{"op":"mcm","clk":"11926198765","pt":1724551309826,"mc":[{"id":"1.232224347","rc":[{"batb":[[0,2.08,39.76],[1,1.21,24.75],[2,1.12,1.76]],"ltp":2.2,"tv":5.5,"id":61077258}]}]}
{"op":"mcm","clk":"11926198914","pt":1724551312918,"mc":[{"id":"1.232224347","rc":[{"batb":[[0,2.1,5],[1,2.08,39.76],[2,1.21,24.75]],"ltp":2.2,"tv":5.5,"id":61077258}]}]}
{"op":"mcm","clk":"11926199140","pt":1724551316223,"mc":[{"id":"1.232224347","rc":[{"batb":[[0,2.08,39.76],[1,1.21,24.75],[2,1.12,1.76]],"ltp":2.2,"tv":5.5,"id":61077258}]}]}
{"op":"mcm","clk":"11926199272","pt":1724551318438,"mc":[{"id":"1.232224347","rc":[{"batb":[[0,2.1,5],[1,2.08,39.76],[2,1.21,24.75]],"ltp":2.2,"tv":5.5,"id":61077258}]}]}
{"op":"mcm","clk":"11926199432","pt":1724551321752,"mc":[{"id":"1.232224347","rc":[{"batb":[[0,2.08,39.76],[1,1.21,24.75],[2,1.12,1.76]],"ltp":2.2,"tv":5.5,"id":61077258}]}]}
{"op":"mcm","clk":"11926199581","pt":1724551323930,"mc":[{"id":"1.232224347","rc":[{"batb":[[0,2.1,5],[1,2.08,39.76],[2,1.21,24.75]],"ltp":2.2,"tv":5.5,"id":61077258}]}]}
{"op":"mcm","clk":"11926199795","pt":1724551327233,"mc":[{"id":"1.232224347","rc":[{"batb":[[0,2.08,39.76],[1,1.21,24.75],[2,1.12,1.76]],"ltp":2.2,"tv":5.5,"id":61077258}]}]}
{"op":"mcm","clk":"11926199933","pt":1724551329455,"mc":[{"id":"1.232224347","rc":[{"batb":[[0,2.1,5],[1,2.08,39.76],[2,1.21,24.75]],"ltp":2.2,"tv":5.5,"id":61077258}]}]}
{"op":"mcm","clk":"11926200138","pt":1724551332749,"mc":[{"id":"1.232224347","rc":[{"batb":[[0,2.08,39.76],[1,1.21,24.75],[2,1.12,1.76]],"ltp":2.2,"tv":5.5,"id":61077258}]}]}
{"op":"mcm","clk":"11926200269","pt":1724551334966,"mc":[{"id":"1.232224347","rc":[{"batb":[[0,2.1,5],[1,2.08,39.76],[2,1.21,24.75]],"ltp":2.2,"tv":5.5,"id":61077258}]}]}
{"op":"mcm","clk":"11926200484","pt":1724551338119,"mc":[{"id":"1.232224347","rc":[{"batb":[[0,2.08,39.76],[1,1.21,24.75],[2,1.12,1.76]],"ltp":2.2,"tv":5.5,"id":61077258}]}]}
{"op":"mcm","clk":"11926200618","pt":1724551340337,"mc":[{"id":"1.232224347","rc":[{"batb":[[0,2.1,5],[1,2.08,39.76],[2,1.21,24.75]],"ltp":2.2,"tv":5.5,"id":61077258}]}]}
{"op":"mcm","clk":"11926200798","pt":1724551343533,"mc":[{"id":"1.232224347","rc":[{"batb":[[0,2.08,39.76],[1,1.21,24.75],[2,1.12,1.76]],"ltp":2.2,"tv":5.5,"id":61077258}]}]}
{"op":"mcm","clk":"11926200924","pt":1724551345746,"mc":[{"id":"1.232224347","rc":[{"batb":[[0,2.1,5],[1,2.08,39.76],[2,1.21,24.75]],"ltp":2.2,"tv":5.5,"id":61077258}]}]}
{"op":"mcm","clk":"11926201121","pt":1724551348961,"mc":[{"id":"1.232224347","rc":[{"batb":[[0,2.08,39.76],[1,1.21,24.75],[2,1.12,1.76]],"ltp":2.2,"tv":5.5,"id":61077258}]}]}
{"op":"mcm","clk":"11926201245","pt":1724551351134,"mc":[{"id":"1.232224347","rc":[{"batb":[[0,2.1,5],[1,2.08,39.76],[2,1.21,24.75]],"ltp":2.2,"tv":5.5,"id":61077258}]}]}
{"op":"mcm","clk":"11926201442","pt":1724551354550,"mc":[{"id":"1.232224347","rc":[{"batb":[[0,2.08,39.76],[1,1.21,24.75],[2,1.12,1.76]],"ltp":2.2,"tv":5.5,"id":61077258}]}]}
{"op":"mcm","clk":"11926201608","pt":1724551356665,"mc":[{"id":"1.232224347","rc":[{"batb":[[0,2.1,5],[1,2.08,39.76],[2,1.21,24.75]],"ltp":2.2,"tv":5.5,"id":61077258}]}]}
{"op":"mcm","clk":"11926201770","pt":1724551359854,"mc":[{"id":"1.232224347","rc":[{"batb":[[0,2.08,39.76],[1,1.21,24.75],[2,1.12,1.76]],"ltp":2.2,"tv":5.5,"id":61077258}]}]}
{"op":"mcm","clk":"11926201932","pt":1724551362994,"mc":[{"id":"1.232224347","rc":[{"batb":[[0,2.1,5],[1,2.08,39.76],[2,1.21,24.75]],"ltp":2.2,"tv":5.5,"id":61077258}]}]}
{"op":"mcm","clk":"11926202094","pt":1724551366139,"mc":[{"id":"1.232224347","rc":[{"batb":[[0,2.08,39.76],[1,1.21,24.75],[2,1.12,1.76]],"ltp":2.2,"tv":5.5,"id":61077258}]}]}
{"op":"mcm","clk":"11926202238","pt":1724551368263,"mc":[{"id":"1.232224347","rc":[{"batb":[[0,2.1,5],[1,2.08,39.76],[2,1.21,24.75]],"ltp":2.2,"tv":5.5,"id":61077258}]}]}
{"op":"mcm","clk":"11926202423","pt":1724551371676,"mc":[{"id":"1.232224347","rc":[{"batb":[[0,2.08,39.76],[1,1.21,24.75],[2,1.12,1.76]],"ltp":2.2,"tv":5.5,"id":61077258}]}]}
{"op":"mcm","clk":"11926202532","pt":1724551373952,"mc":[{"id":"1.232224347","rc":[{"batb":[[0,2.1,5],[1,2.08,39.76],[2,1.21,24.75]],"ltp":2.2,"tv":5.5,"id":61077258}]}]}
{"op":"mcm","clk":"11926202687","pt":1724551377255,"mc":[{"id":"1.232224347","rc":[{"batb":[[0,2.08,39.76],[1,1.21,24.75],[2,1.12,1.76]],"ltp":2.2,"tv":5.5,"id":61077258}]}]}
{"op":"mcm","clk":"11926202866","pt":1724551380454,"mc":[{"id":"1.232224347","rc":[{"batb":[[0,2.1,5],[1,2.08,39.76],[2,1.21,24.75]],"ltp":2.2,"tv":5.5,"id":61077258}]}]}
{"op":"mcm","clk":"11926203040","pt":1724551383662,"mc":[{"id":"1.232224347","rc":[{"batb":[[0,2.08,39.76],[1,1.21,24.75],[2,1.12,1.76]],"ltp":2.2,"tv":5.5,"id":61077258}]}]}
{"op":"mcm","clk":"11926203168","pt":1724551386079,"mc":[{"id":"1.232224347","rc":[{"batb":[[0,2.1,5],[1,2.08,39.76],[2,1.21,24.75]],"ltp":2.2,"tv":5.5,"id":61077258}]}]}
{"op":"mcm","clk":"11926203347","pt":1724551389371,"mc":[{"id":"1.232224347","rc":[{"batb":[[0,2.08,39.76],[1,1.21,24.75],[2,1.12,1.76]],"ltp":2.2,"tv":5.5,"id":61077258}]}]}
{"op":"mcm","clk":"11926203510","pt":1724551392603,"mc":[{"id":"1.232224347","rc":[{"batb":[[0,2.1,5],[1,2.08,39.76],[2,1.21,24.75]],"ltp":2.2,"tv":5.5,"id":61077258}]}]}
{"op":"mcm","clk":"11926203694","pt":1724551395906,"mc":[{"id":"1.232224347","rc":[{"batb":[[0,2.08,39.76],[1,1.21,24.75],[2,1.12,1.76]],"ltp":2.2,"tv":5.5,"id":61077258}]}]}
{"op":"mcm","clk":"11926203819","pt":1724551397970,"mc":[{"id":"1.232224347","rc":[{"batb":[[0,2.1,5],[1,2.08,39.76],[2,1.21,24.75]],"ltp":2.2,"tv":5.5,"id":61077258}]}]}
{"op":"mcm","clk":"11926203996","pt":1724551401178,"mc":[{"id":"1.232224347","rc":[{"batb":[[0,2.08,39.76],[1,1.21,24.75],[2,1.12,1.76]],"ltp":2.2,"tv":5.5,"id":61077258}]}]}
{"op":"mcm","clk":"11926204105","pt":1724551403285,"mc":[{"id":"1.232224347","rc":[{"batb":[[0,2.1,5],[1,2.08,39.76],[2,1.21,24.75]],"ltp":2.2,"tv":5.5,"id":61077258}]}]}
{"op":"mcm","clk":"11926204319","pt":1724551406688,"mc":[{"id":"1.232224347","rc":[{"batb":[[0,2.08,39.76],[1,1.21,24.75],[2,1.12,1.76]],"ltp":2.2,"tv":5.5,"id":61077258}]}]}
{"op":"mcm","clk":"11926204431","pt":1724551408899,"mc":[{"id":"1.232224347","rc":[{"batb":[[0,2.1,5],[1,2.08,39.76],[2,1.21,24.75]],"ltp":2.2,"tv":5.5,"id":61077258}]}]}
{"op":"mcm","clk":"11926204567","pt":1724551412186,"mc":[{"id":"1.232224347","rc":[{"batb":[[0,2.08,39.76],[1,1.21,24.75],[2,1.12,1.76]],"ltp":2.2,"tv":5.5,"id":61077258}]}]}
{"op":"mcm","clk":"11926204659","pt":1724551414399,"mc":[{"id":"1.232224347","rc":[{"batb":[[0,2.1,5],[1,2.08,39.76],[2,1.21,24.75]],"ltp":2.2,"tv":5.5,"id":61077258}]}]}
{"op":"mcm","clk":"11926204828","pt":1724551417609,"mc":[{"id":"1.232224347","rc":[{"batb":[[0,2.08,39.76],[1,1.21,24.75],[2,1.12,1.76]],"ltp":2.2,"tv":5.5,"id":61077258}]}]}
{"op":"mcm","clk":"11926204958","pt":1724551419802,"mc":[{"id":"1.232224347","rc":[{"batb":[[0,2.1,5],[1,2.08,39.76],[2,1.21,24.75]],"ltp":2.2,"tv":5.5,"id":61077258}]}]}
{"op":"mcm","clk":"11926205156","pt":1724551423252,"mc":[{"id":"1.232224347","rc":[{"batb":[[0,2.08,39.76],[1,1.21,24.75],[2,1.12,1.76]],"ltp":2.2,"tv":5.5,"id":61077258}]}]}
{"op":"mcm","clk":"11926205307","pt":1724551426334,"mc":[{"id":"1.232224347","rc":[{"batb":[[0,2.1,5],[1,2.08,39.76],[2,1.21,24.75]],"ltp":2.2,"tv":5.5,"id":61077258}]}]}
{"op":"mcm","clk":"11926205467","pt":1724551429622,"mc":[{"id":"1.232224347","rc":[{"batb":[[0,2.08,39.76],[1,1.21,24.75],[2,1.12,1.76]],"ltp":2.2,"tv":5.5,"id":61077258}]}]}
{"op":"mcm","clk":"11926205684","pt":1724551434819,"mc":[{"id":"1.232224347","rc":[{"batb":[[0,2.1,5],[1,2.08,39.76],[2,1.21,24.75]],"ltp":2.2,"tv":5.5,"id":61077258}]}]}
{"op":"mcm","clk":"11926205847","pt":1724551438019,"mc":[{"id":"1.232224347","rc":[{"batb":[[0,2.08,39.76],[1,1.21,24.75],[2,1.12,1.76]],"ltp":2.2,"tv":5.5,"id":61077258}]}]}
{"op":"mcm","clk":"11926206029","pt":1724551441975,"mc":[{"id":"1.232224347","rc":[{"batb":[[0,2.1,5],[1,2.08,39.76],[2,1.21,24.75]],"ltp":2.2,"tv":5.5,"id":61077258}]}]}
{"op":"mcm","clk":"11926206268","pt":1724551445237,"mc":[{"id":"1.232224347","rc":[{"batb":[[0,2.08,39.76],[1,1.21,24.75],[2,1.12,1.76]],"ltp":2.2,"tv":5.5,"id":61077258}]}]}
{"op":"mcm","clk":"11926206410","pt":1724551447484,"mc":[{"id":"1.232224347","rc":[{"batb":[[0,2.1,5],[1,2.08,39.76],[2,1.21,24.75]],"ltp":2.2,"tv":5.5,"id":61077258}]}]}
{"op":"mcm","clk":"11926206566","pt":1724551450756,"mc":[{"id":"1.232224347","rc":[{"batb":[[0,2.08,39.76],[1,1.21,24.75],[2,1.12,1.76]],"ltp":2.2,"tv":5.5,"id":61077258}]}]}
{"op":"mcm","clk":"11926206745","pt":1724551454151,"mc":[{"id":"1.232224347","rc":[{"batb":[[0,2.1,5],[1,2.08,39.76],[2,1.21,24.75]],"ltp":2.2,"tv":5.5,"id":61077258}]}]}
{"op":"mcm","clk":"11926206899","pt":1724551457453,"mc":[{"id":"1.232224347","rc":[{"batb":[[0,2.08,39.76],[1,1.21,24.75],[2,1.12,1.76]],"ltp":2.2,"tv":5.5,"id":61077258}]}]}
{"op":"mcm","clk":"11926207008","pt":1724551459559,"mc":[{"id":"1.232224347","rc":[{"batb":[[0,2.1,5],[1,2.08,39.76],[2,1.21,24.75]],"ltp":2.2,"tv":5.5,"id":61077258}]}]}
{"op":"mcm","clk":"11926207153","pt":1724551462842,"mc":[{"id":"1.232224347","rc":[{"batb":[[0,2.08,39.76],[1,1.21,24.75],[2,1.12,1.76]],"ltp":2.2,"tv":5.5,"id":61077258}]}]}
{"op":"mcm","clk":"11926207244","pt":1724551465047,"mc":[{"id":"1.232224347","rc":[{"batb":[[0,2.1,5],[1,2.08,39.76],[2,1.21,24.75]],"ltp":2.2,"tv":5.5,"id":61077258}]}]}
{"op":"mcm","clk":"11926207379","pt":1724551468289,"mc":[{"id":"1.232224347","rc":[{"batb":[[0,2.08,39.76],[1,1.21,24.75],[2,1.12,1.76]],"ltp":2.2,"tv":5.5,"id":61077258}]}]}
{"op":"mcm","clk":"11926207515","pt":1724551470459,"mc":[{"id":"1.232224347","rc":[{"batb":[[0,2.1,5],[1,2.08,39.76],[2,1.21,24.75]],"ltp":2.2,"tv":5.5,"id":61077258}]}]}
{"op":"mcm","clk":"11926207713","pt":1724551473699,"mc":[{"id":"1.232224347","rc":[{"batb":[[0,2.08,39.76],[1,1.21,24.75],[2,1.12,1.76]],"ltp":2.2,"tv":5.5,"id":61077258}]}]}
{"op":"mcm","clk":"11926207833","pt":1724551475866,"mc":[{"id":"1.232224347","rc":[{"batb":[[0,2.1,5],[1,2.08,39.76],[2,1.21,24.75]],"ltp":2.2,"tv":5.5,"id":61077258}]}]}
{"op":"mcm","clk":"11926208002","pt":1724551479198,"mc":[{"id":"1.232224347","rc":[{"batb":[[0,2.08,39.76],[1,1.21,24.75],[2,1.12,1.76]],"ltp":2.2,"tv":5.5,"id":61077258}]}]}
{"op":"mcm","clk":"11926208097","pt":1724551481304,"mc":[{"id":"1.232224347","rc":[{"batb":[[0,2.1,5],[1,2.08,39.76],[2,1.21,24.75]],"ltp":2.2,"tv":5.5,"id":61077258}]}]}
{"op":"mcm","clk":"11926208266","pt":1724551484600,"mc":[{"id":"1.232224347","rc":[{"batb":[[0,2.08,39.76],[1,1.21,24.75],[2,1.12,1.76]],"ltp":2.2,"tv":5.5,"id":61077258}]}]}
{"op":"mcm","clk":"11926208438","pt":1724551486803,"mc":[{"id":"1.232224347","rc":[{"batb":[[0,2.1,5],[1,2.08,39.76],[2,1.21,24.75]],"ltp":2.2,"tv":5.5,"id":61077258}]}]}
{"op":"mcm","clk":"11926208633","pt":1724551490192,"mc":[{"id":"1.232224347","rc":[{"batb":[[0,2.08,39.76],[1,1.21,24.75],[2,1.12,1.76]],"ltp":2.2,"tv":5.5,"id":61077258}]}]}
{"op":"mcm","clk":"11926208725","pt":1724551492412,"mc":[{"id":"1.232224347","rc":[{"batb":[[0,2.1,5],[1,2.08,39.76],[2,1.21,24.75]],"ltp":2.2,"tv":5.5,"id":61077258}]}]}
{"op":"mcm","clk":"11926208871","pt":1724551495604,"mc":[{"id":"1.232224347","rc":[{"batb":[[0,2.08,39.76],[1,1.21,24.75],[2,1.12,1.76]],"ltp":2.2,"tv":5.5,"id":61077258}]}]}
{"op":"mcm","clk":"11926209028","pt":1724551498688,"mc":[{"id":"1.232224347","rc":[{"batb":[[0,2.1,5],[1,2.08,39.76],[2,1.21,24.75]],"ltp":2.2,"tv":5.5,"id":61077258}]}]}
{"op":"mcm","clk":"11926209187","pt":1724551501893,"mc":[{"id":"1.232224347","rc":[{"batb":[[0,2.08,39.76],[1,1.21,24.75],[2,1.12,1.76]],"ltp":2.2,"tv":5.5,"id":61077258}]}]}
{"op":"mcm","clk":"11926209373","pt":1724551504633,"mc":[{"id":"1.232224347","rc":[{"batb":[[0,2.1,5],[1,2.08,39.76],[2,1.21,24.75]],"ltp":2.2,"tv":5.5,"id":61077258}]}]}
{"op":"mcm","clk":"11926209584","pt":1724551507992,"mc":[{"id":"1.232224347","rc":[{"batb":[[0,2.08,39.76],[1,1.21,24.75],[2,1.12,1.76]],"ltp":2.2,"tv":5.5,"id":61077258}]}]}
{"op":"mcm","clk":"11926209728","pt":1724551510314,"mc":[{"id":"1.232224347","rc":[{"batb":[[0,2.1,5],[1,2.08,39.76],[2,1.21,24.75]],"ltp":2.2,"tv":5.5,"id":61077258}]}]}
{"op":"mcm","clk":"11926209904","pt":1724551513506,"mc":[{"id":"1.232224347","rc":[{"batb":[[0,2.08,39.76],[1,1.21,24.75],[2,1.12,1.76]],"ltp":2.2,"tv":5.5,"id":61077258}]}]}
{"op":"mcm","clk":"11926210078","pt":1724551516248,"mc":[{"id":"1.232224347","rc":[{"batb":[[0,2.1,5],[1,2.08,39.76],[2,1.21,24.75]],"ltp":2.2,"tv":5.5,"id":61077258}]}]}
{"op":"mcm","clk":"11926210301","pt":1724551519749,"mc":[{"id":"1.232224347","rc":[{"batb":[[0,2.08,39.76],[1,1.21,24.75],[2,1.12,1.76]],"ltp":2.2,"tv":5.5,"id":61077258}]}]}
{"op":"mcm","clk":"11926210471","pt":1724551522746,"mc":[{"id":"1.232224347","rc":[{"batb":[[0,2.1,5],[1,2.08,39.76],[2,1.21,24.75]],"ltp":2.2,"tv":5.5,"id":61077258}]}]}
{"op":"mcm","clk":"11926210662","pt":1724551525938,"mc":[{"id":"1.232224347","rc":[{"batb":[[0,2.08,39.76],[1,1.21,24.75],[2,1.12,1.76]],"ltp":2.2,"tv":5.5,"id":61077258}]}]}
{"op":"mcm","clk":"11926210799","pt":1724551528150,"mc":[{"id":"1.232224347","rc":[{"batb":[[0,2.1,5],[1,2.08,39.76],[2,1.21,24.75]],"ltp":2.2,"tv":5.5,"id":61077258}]}]}
{"op":"mcm","clk":"11926210967","pt":1724551531360,"mc":[{"id":"1.232224347","rc":[{"batb":[[0,2.08,39.76],[1,1.21,24.75],[2,1.12,1.76]],"ltp":2.2,"tv":5.5,"id":61077258}]}]}
{"op":"mcm","clk":"11926211142","pt":1724551534137,"mc":[{"id":"1.232224347","rc":[{"batb":[[0,2.1,5],[1,2.08,39.76],[2,1.21,24.75]],"ltp":2.2,"tv":5.5,"id":61077258}]}]}
{"op":"mcm","clk":"11926211354","pt":1724551537438,"mc":[{"id":"1.232224347","rc":[{"batb":[[0,2.08,39.76],[1,1.21,24.75],[2,1.12,1.76]],"ltp":2.2,"tv":5.5,"id":61077258}]}]}
{"op":"mcm","clk":"11926211473","pt":1724551539542,"mc":[{"id":"1.232224347","rc":[{"batb":[[0,2.1,5],[1,2.08,39.76],[2,1.21,24.75]],"ltp":2.2,"tv":5.5,"id":61077258}]}]}
{"op":"mcm","clk":"11926211701","pt":1724551542838,"mc":[{"id":"1.232224347","rc":[{"batb":[[0,2.08,39.76],[1,1.21,24.75],[2,1.12,1.76]],"ltp":2.2,"tv":5.5,"id":61077258}]}]}
{"op":"mcm","clk":"11926211877","pt":1724551545567,"mc":[{"id":"1.232224347","rc":[{"batb":[[0,2.1,5],[1,2.08,39.76],[2,1.21,24.75]],"ltp":2.2,"tv":5.5,"id":61077258}]}]}
{"op":"mcm","clk":"11926212106","pt":1724551548844,"mc":[{"id":"1.232224347","rc":[{"batb":[[0,2.08,39.76],[1,1.21,24.75],[2,1.12,1.76]],"ltp":2.2,"tv":5.5,"id":61077258}]}]}
{"op":"mcm","clk":"11926212255","pt":1724551551060,"mc":[{"id":"1.232224347","rc":[{"batb":[[0,2.1,5],[1,2.08,39.76],[2,1.21,24.75]],"ltp":2.2,"tv":5.5,"id":61077258}]}]}
{"op":"mcm","clk":"11926212441","pt":1724551554454,"mc":[{"id":"1.232224347","rc":[{"batb":[[0,2.08,39.76],[1,1.21,24.75],[2,1.12,1.76]],"ltp":2.2,"tv":5.5,"id":61077258}]}]}
{"op":"mcm","clk":"11926212571","pt":1724551556660,"mc":[{"id":"1.232224347","rc":[{"batb":[[0,2.1,5],[1,2.08,39.76],[2,1.21,24.75]],"ltp":2.2,"tv":5.5,"id":61077258}]}]}
{"op":"mcm","clk":"11926212765","pt":1724551559960,"mc":[{"id":"1.232224347","rc":[{"batb":[[0,2.08,39.76],[1,1.21,24.75],[2,1.12,1.76]],"ltp":2.2,"tv":5.5,"id":61077258}]}]}
{"op":"mcm","clk":"11926213010","pt":1724551564094,"mc":[{"id":"1.232224347","rc":[{"batb":[[0,2.1,5],[1,2.08,39.76],[2,1.21,24.75]],"ltp":2.2,"tv":5.5,"id":61077258}]}]}
{"op":"mcm","clk":"11926213199","pt":1724551567395,"mc":[{"id":"1.232224347","rc":[{"batb":[[0,2.08,39.76],[1,1.21,24.75],[2,1.12,1.76]],"ltp":2.2,"tv":5.5,"id":61077258}]}]}
{"op":"mcm","clk":"11926213340","pt":1724551569670,"mc":[{"id":"1.232224347","rc":[{"batb":[[0,2.1,5],[1,2.08,39.76],[2,1.21,24.75]],"ltp":2.2,"tv":5.5,"id":61077258}]}]}
{"op":"mcm","clk":"11926213558","pt":1724551573082,"mc":[{"id":"1.232224347","rc":[{"batb":[[0,2.08,39.76],[1,1.21,24.75],[2,1.12,1.76]],"ltp":2.2,"tv":5.5,"id":61077258}]}]}
{"op":"mcm","clk":"11926213689","pt":1724551575300,"mc":[{"id":"1.232224347","rc":[{"batb":[[0,2.1,5],[1,2.08,39.76],[2,1.21,24.75]],"ltp":2.2,"tv":5.5,"id":61077258}]}]}
{"op":"mcm","clk":"11926213914","pt":1724551578809,"mc":[{"id":"1.232224347","rc":[{"batb":[[0,2.08,39.76],[1,1.21,24.75],[2,1.12,1.76]],"ltp":2.2,"tv":5.5,"id":61077258}]}]}
{"op":"mcm","clk":"11926214125","pt":1724551581904,"mc":[{"id":"1.232224347","rc":[{"batb":[[0,2.1,5],[1,2.08,39.76],[2,1.21,24.75]],"ltp":2.2,"tv":5.5,"id":61077258}]}]}
{"op":"mcm","clk":"11926214343","pt":1724551585199,"mc":[{"id":"1.232224347","rc":[{"batb":[[0,2.08,39.76],[1,1.21,24.75],[2,1.12,1.76]],"ltp":2.2,"tv":5.5,"id":61077258}]}]}
{"op":"mcm","clk":"11926214476","pt":1724551587413,"mc":[{"id":"1.232224347","rc":[{"batb":[[0,2.1,5],[1,2.08,39.76],[2,1.21,24.75]],"ltp":2.2,"tv":5.5,"id":61077258}]}]}
{"op":"mcm","clk":"11926214653","pt":1724551590708,"mc":[{"id":"1.232224347","rc":[{"batb":[[0,2.08,39.76],[1,1.21,24.75],[2,1.12,1.76]],"ltp":2.2,"tv":5.5,"id":61077258}]}]}
{"op":"mcm","clk":"11926214779","pt":1724551592926,"mc":[{"id":"1.232224347","rc":[{"batb":[[0,2.1,5],[1,2.08,39.76],[2,1.21,24.75]],"ltp":2.2,"tv":5.5,"id":61077258}]}]}
{"op":"mcm","clk":"11926214979","pt":1724551596332,"mc":[{"id":"1.232224347","rc":[{"batb":[[0,2.08,39.76],[1,1.21,24.75],[2,1.12,1.76]],"ltp":2.2,"tv":5.5,"id":61077258}]}]}
{"op":"mcm","clk":"11926215161","pt":1724551599297,"mc":[{"id":"1.232224347","rc":[{"batb":[[0,2.1,5],[1,2.08,39.76],[2,1.21,24.75]],"ltp":2.2,"tv":5.5,"id":61077258}]}]}
{"op":"mcm","clk":"11926215392","pt":1724551602612,"mc":[{"id":"1.232224347","rc":[{"batb":[[0,2.08,39.76],[1,1.21,24.75],[2,1.12,1.76]],"ltp":2.2,"tv":5.5,"id":61077258}]}]}
{"op":"mcm","clk":"11926215557","pt":1724551605815,"mc":[{"id":"1.232224347","rc":[{"batb":[[0,2.1,5],[1,2.08,39.76],[2,1.21,24.75]],"ltp":2.2,"tv":5.5,"id":61077258}]}]}
{"op":"mcm","clk":"11926215777","pt":1724551609224,"mc":[{"id":"1.232224347","rc":[{"batb":[[0,2.08,39.76],[1,1.21,24.75],[2,1.12,1.76]],"ltp":2.2,"tv":5.5,"id":61077258}]}]}
{"op":"mcm","clk":"11926215890","pt":1724551611710,"mc":[{"id":"1.232224347","rc":[{"batb":[[0,2.1,5],[1,2.08,39.76],[2,1.21,24.75]],"ltp":2.2,"tv":5.5,"id":61077258}]}]}
{"op":"mcm","clk":"11926216069","pt":1724551615107,"mc":[{"id":"1.232224347","rc":[{"batb":[[0,2.08,39.76],[1,1.21,24.75],[2,1.12,1.76]],"ltp":2.2,"tv":5.5,"id":61077258}]}]}
{"op":"mcm","clk":"11926216244","pt":1724551618840,"mc":[{"id":"1.232224347","rc":[{"batb":[[0,2.1,5],[1,2.08,39.76],[2,1.21,24.75]],"ltp":2.2,"tv":5.5,"id":61077258}]}]}
{"op":"mcm","clk":"11926216443","pt":1724551622258,"mc":[{"id":"1.232224347","rc":[{"batb":[[0,2.08,39.76],[1,1.21,24.75],[2,1.12,1.76]],"ltp":2.2,"tv":5.5,"id":61077258}]}]}
{"op":"mcm","clk":"11926216687","pt":1724551626644,"mc":[{"id":"1.232224347","rc":[{"batb":[[0,2.1,5],[1,2.08,39.76],[2,1.21,24.75]],"ltp":2.2,"tv":5.5,"id":61077258}]}]}
{"op":"mcm","clk":"11926216891","pt":1724551629850,"mc":[{"id":"1.232224347","rc":[{"batb":[[0,2.08,39.76],[1,1.21,24.75],[2,1.12,1.76]],"ltp":2.2,"tv":5.5,"id":61077258}]}]}
{"op":"mcm","clk":"11926217071","pt":1724551632429,"mc":[{"id":"1.232224347","rc":[{"batb":[[0,2.1,5],[1,2.08,39.76],[2,1.21,24.75]],"ltp":2.2,"tv":5.5,"id":61077258}]}]}
{"op":"mcm","clk":"11926217262","pt":1724551635949,"mc":[{"id":"1.232224347","rc":[{"batb":[[0,2.08,39.76],[1,1.21,24.75],[2,1.12,1.76]],"ltp":2.2,"tv":5.5,"id":61077258}]}]}
{"op":"mcm","clk":"11926217421","pt":1724551638138,"mc":[{"id":"1.232224347","rc":[{"batb":[[0,2.1,5],[1,2.08,39.76],[2,1.21,24.75]],"ltp":2.2,"tv":5.5,"id":61077258}]}]}
{"op":"mcm","clk":"11926217611","pt":1724551641543,"mc":[{"id":"1.232224347","rc":[{"batb":[[0,2.08,39.76],[1,1.21,24.75],[2,1.12,1.76]],"ltp":2.2,"tv":5.5,"id":61077258}]}]}
{"op":"mcm","clk":"11926217776","pt":1724551644267,"mc":[{"id":"1.232224347","rc":[{"batb":[[0,2.1,5],[1,2.08,39.76],[2,1.21,24.75]],"ltp":2.2,"tv":5.5,"id":61077258}]}]}
{"op":"mcm","clk":"11926217959","pt":1724551647468,"mc":[{"id":"1.232224347","rc":[{"batb":[[0,2.08,39.76],[1,1.21,24.75],[2,1.12,1.76]],"ltp":2.2,"tv":5.5,"id":61077258}]}]}
{"op":"mcm","clk":"11926218164","pt":1724551651076,"mc":[{"id":"1.232224347","rc":[{"batb":[[0,2.1,5],[1,2.08,39.76],[2,1.21,24.75]],"ltp":2.2,"tv":5.5,"id":61077258}]}]}
{"op":"mcm","clk":"11926218381","pt":1724551654374,"mc":[{"id":"1.232224347","rc":[{"batb":[[0,2.08,39.76],[1,1.21,24.75],[2,1.12,1.76]],"ltp":2.2,"tv":5.5,"id":61077258}]}]}
{"op":"mcm","clk":"11926218533","pt":1724551656892,"mc":[{"id":"1.232224347","rc":[{"batb":[[0,2.1,5],[1,2.08,39.76],[2,1.21,24.75]],"ltp":2.2,"tv":5.5,"id":61077258}]}]}
{"op":"mcm","clk":"11926218701","pt":1724551660100,"mc":[{"id":"1.232224347","rc":[{"batb":[[0,2.08,39.76],[1,1.21,24.75],[2,1.12,1.76]],"ltp":2.2,"tv":5.5,"id":61077258}]}]}
{"op":"mcm","clk":"11926218930","pt":1724551664176,"mc":[{"id":"1.232224347","rc":[{"batb":[[0,2.1,5],[1,2.08,39.76],[2,1.21,24.75]],"ltp":2.2,"tv":5.5,"id":61077258}]}]}
{"op":"mcm","clk":"11926219106","pt":1724551667373,"mc":[{"id":"1.232224347","rc":[{"batb":[[0,2.08,39.76],[1,1.21,24.75],[2,1.12,1.76]],"ltp":2.2,"tv":5.5,"id":61077258}]}]}
{"op":"mcm","clk":"11926219260","pt":1724551670201,"mc":[{"id":"1.232224347","rc":[{"batb":[[0,2.1,5],[1,2.08,39.76],[2,1.21,24.75]],"ltp":2.2,"tv":5.5,"id":61077258}]}]}
{"op":"mcm","clk":"11926219455","pt":1724551673698,"mc":[{"id":"1.232224347","rc":[{"batb":[[0,2.08,39.76],[1,1.21,24.75],[2,1.12,1.76]],"ltp":2.2,"tv":5.5,"id":61077258}]}]}
{"op":"mcm","clk":"11926219586","pt":1724551676582,"mc":[{"id":"1.232224347","rc":[{"batb":[[0,2.1,5],[1,2.08,39.76],[2,1.21,24.75]],"ltp":2.2,"tv":5.5,"id":61077258}]}]}
{"op":"mcm","clk":"11926219757","pt":1724551679923,"mc":[{"id":"1.232224347","rc":[{"batb":[[0,2.08,39.76],[1,1.21,24.75],[2,1.12,1.76]],"ltp":2.2,"tv":5.5,"id":61077258}]}]}
{"op":"mcm","clk":"11926219939","pt":1724551683429,"mc":[{"id":"1.232224347","rc":[{"batb":[[0,2.1,5],[1,2.08,39.76],[2,1.21,24.75]],"ltp":2.2,"tv":5.5,"id":61077258}]}]}
{"op":"mcm","clk":"11926220074","pt":1724551686722,"mc":[{"id":"1.232224347","rc":[{"batb":[[0,2.08,39.76],[1,1.21,24.75],[2,1.12,1.76]],"ltp":2.2,"tv":5.5,"id":61077258}]}]}
{"op":"mcm","clk":"11926220212","pt":1724551689811,"mc":[{"id":"1.232224347","rc":[{"batb":[[0,2.1,5],[1,2.08,39.76],[2,1.21,24.75]],"ltp":2.2,"tv":5.5,"id":61077258}]}]}
{"op":"mcm","clk":"11926220441","pt":1724551693339,"mc":[{"id":"1.232224347","rc":[{"batb":[[0,2.08,39.76],[1,1.21,24.75],[2,1.12,1.76]],"ltp":2.2,"tv":5.5,"id":61077258}]}]}
{"op":"mcm","clk":"11926220562","pt":1724551695523,"mc":[{"id":"1.232224347","rc":[{"batb":[[0,2.1,5],[1,2.08,39.76],[2,1.21,24.75]],"ltp":2.2,"tv":5.5,"id":61077258}]}]}
{"op":"mcm","clk":"11926220767","pt":1724551698825,"mc":[{"id":"1.232224347","rc":[{"batb":[[0,2.08,39.76],[1,1.21,24.75],[2,1.12,1.76]],"ltp":2.2,"tv":5.5,"id":61077258}]}]}
{"op":"mcm","clk":"11926220937","pt":1724551701656,"mc":[{"id":"1.232224347","rc":[{"batb":[[0,2.1,5],[1,2.08,39.76],[2,1.21,24.75]],"ltp":2.2,"tv":5.5,"id":61077258}]}]}
{"op":"mcm","clk":"11926221133","pt":1724551704954,"mc":[{"id":"1.232224347","rc":[{"batb":[[0,2.08,39.76],[1,1.21,24.75],[2,1.12,1.76]],"ltp":2.2,"tv":5.5,"id":61077258}]}]}
{"op":"mcm","clk":"11926221285","pt":1724551707935,"mc":[{"id":"1.232224347","rc":[{"batb":[[0,2.1,5],[1,2.08,39.76],[2,1.21,24.75]],"ltp":2.2,"tv":5.5,"id":61077258}]}]}
{"op":"mcm","clk":"11926221456","pt":1724551711230,"mc":[{"id":"1.232224347","rc":[{"batb":[[0,2.08,39.76],[1,1.21,24.75],[2,1.12,1.76]],"ltp":2.2,"tv":5.5,"id":61077258}]}]}
{"op":"mcm","clk":"11926221669","pt":1724551715256,"mc":[{"id":"1.232224347","rc":[{"batb":[[0,2.1,5],[1,2.08,39.76],[2,1.21,24.75]],"ltp":2.2,"tv":5.5,"id":61077258}]}]}
{"op":"mcm","clk":"11926221867","pt":1724551718564,"mc":[{"id":"1.232224347","rc":[{"batb":[[0,2.08,39.76],[1,1.21,24.75],[2,1.12,1.76]],"ltp":2.2,"tv":5.5,"id":61077258}]}]}
{"op":"mcm","clk":"11926222056","pt":1724551722072,"mc":[{"id":"1.232224347","rc":[{"batb":[[0,2.1,5],[1,2.08,39.76],[2,1.21,24.75]],"ltp":2.2,"tv":5.5,"id":61077258}]}]}
{"op":"mcm","clk":"11926222276","pt":1724551725474,"mc":[{"id":"1.232224347","rc":[{"batb":[[0,2.08,39.76],[1,1.21,24.75],[2,1.12,1.76]],"ltp":2.2,"tv":5.5,"id":61077258}]}]}
{"op":"mcm","clk":"11926222456","pt":1724551728265,"mc":[{"id":"1.232224347","rc":[{"batb":[[0,2.1,5],[1,2.08,39.76],[2,1.21,24.75]],"ltp":2.2,"tv":5.5,"id":61077258}]}]}
{"op":"mcm","clk":"11926222640","pt":1724551731765,"mc":[{"id":"1.232224347","rc":[{"batb":[[0,2.08,39.76],[1,1.21,24.75],[2,1.12,1.76]],"ltp":2.2,"tv":5.5,"id":61077258}]}]}
{"op":"mcm","clk":"11926222780","pt":1724551733982,"mc":[{"id":"1.232224347","rc":[{"batb":[[0,2.1,5],[1,2.08,39.76],[2,1.21,24.75]],"ltp":2.2,"tv":5.5,"id":61077258}]}]}
{"op":"mcm","clk":"11926223009","pt":1724551737177,"mc":[{"id":"1.232224347","rc":[{"batb":[[0,2.08,39.76],[1,1.21,24.75],[2,1.12,1.76]],"ltp":2.2,"tv":5.5,"id":61077258}]}]}
{"op":"mcm","clk":"11926223266","pt":1724551741512,"mc":[{"id":"1.232224347","rc":[{"batb":[[0,2.1,5],[1,2.08,39.76],[2,1.21,24.75]],"ltp":2.2,"tv":5.5,"id":61077258}]}]}
{"op":"mcm","clk":"11926223426","pt":1724551744780,"mc":[{"id":"1.232224347","rc":[{"batb":[[0,2.08,39.76],[1,1.21,24.75],[2,1.12,1.76]],"ltp":2.2,"tv":5.5,"id":61077258}]}]}
{"op":"mcm","clk":"11926223569","pt":1724551747368,"mc":[{"id":"1.232224347","rc":[{"batb":[[0,2.1,5],[1,2.08,39.76],[2,1.21,24.75]],"ltp":2.2,"tv":5.5,"id":61077258}]}]}
{"op":"mcm","clk":"11926223737","pt":1724551750675,"mc":[{"id":"1.232224347","rc":[{"batb":[[0,2.08,39.76],[1,1.21,24.75],[2,1.12,1.76]],"ltp":2.2,"tv":5.5,"id":61077258}]}]}
{"op":"mcm","clk":"11926224027","pt":1724551755881,"mc":[{"id":"1.232224347","rc":[{"batb":[[0,2.1,5],[1,2.08,39.76],[2,1.21,24.75]],"ltp":2.2,"tv":5.5,"id":61077258}]}]}
{"op":"mcm","clk":"11926224198","pt":1724551759185,"mc":[{"id":"1.232224347","rc":[{"batb":[[0,2.08,39.76],[1,1.21,24.75],[2,1.12,1.76]],"ltp":2.2,"tv":5.5,"id":61077258}]}]}
{"op":"mcm","clk":"11926224364","pt":1724551762180,"mc":[{"id":"1.232224347","rc":[{"batb":[[0,2.1,5],[1,2.08,39.76],[2,1.21,24.75]],"ltp":2.2,"tv":5.5,"id":61077258}]}]}
{"op":"mcm","clk":"11926224553","pt":1724551765623,"mc":[{"id":"1.232224347","rc":[{"batb":[[0,2.08,39.76],[1,1.21,24.75],[2,1.12,1.76]],"ltp":2.2,"tv":5.5,"id":61077258}]}]}
{"op":"mcm","clk":"11926224690","pt":1724551768092,"mc":[{"id":"1.232224347","rc":[{"batb":[[0,2.1,5],[1,2.08,39.76],[2,1.21,24.75]],"ltp":2.2,"tv":5.5,"id":61077258}]}]}
{"op":"mcm","clk":"11926224850","pt":1724551771635,"mc":[{"id":"1.232224347","rc":[{"batb":[[0,2.08,39.76],[1,1.21,24.75],[2,1.12,1.76]],"ltp":2.2,"tv":5.5,"id":61077258}]}]}
{"op":"mcm","clk":"11926225013","pt":1724551774725,"mc":[{"id":"1.232224347","rc":[{"batb":[[0,2.1,5],[1,2.08,39.76],[2,1.21,24.75]],"ltp":2.2,"tv":5.5,"id":61077258}]}]}
{"op":"mcm","clk":"11926225194","pt":1724551778044,"mc":[{"id":"1.232224347","rc":[{"batb":[[0,2.08,39.76],[1,1.21,24.75],[2,1.12,1.76]],"ltp":2.2,"tv":5.5,"id":61077258}]}]}
{"op":"mcm","clk":"11926225325","pt":1724551780826,"mc":[{"id":"1.232224347","rc":[{"batb":[[0,2.1,5],[1,2.08,39.76],[2,1.21,24.75]],"ltp":2.2,"tv":5.5,"id":61077258}]}]}
{"op":"mcm","clk":"11926225478","pt":1724551784319,"mc":[{"id":"1.232224347","rc":[{"batb":[[0,2.08,39.76],[1,1.21,24.75],[2,1.12,1.76]],"ltp":2.2,"tv":5.5,"id":61077258}]}]}
{"op":"mcm","clk":"11926225607","pt":1724551787111,"mc":[{"id":"1.232224347","rc":[{"batb":[[0,2.1,5],[1,2.08,39.76],[2,1.21,24.75]],"ltp":2.2,"tv":5.5,"id":61077258}]}]}
{"op":"mcm","clk":"11926225786","pt":1724551790515,"mc":[{"id":"1.232224347","rc":[{"batb":[[0,2.08,39.76],[1,1.21,24.75],[2,1.12,1.76]],"ltp":2.2,"tv":5.5,"id":61077258}]}]}
{"op":"mcm","clk":"11926225916","pt":1724551792731,"mc":[{"id":"1.232224347","rc":[{"batb":[[0,2.1,5],[1,2.08,39.76],[2,1.21,24.75]],"ltp":2.2,"tv":5.5,"id":61077258}]}]}
{"op":"mcm","clk":"11926226095","pt":1724551796025,"mc":[{"id":"1.232224347","rc":[{"batb":[[0,2.08,39.76],[1,1.21,24.75],[2,1.12,1.76]],"ltp":2.2,"tv":5.5,"id":61077258}]}]}
{"op":"mcm","clk":"11926226279","pt":1724551799222,"mc":[{"id":"1.232224347","rc":[{"batb":[[0,2.1,5],[1,2.08,39.76],[2,1.21,24.75]],"ltp":2.2,"tv":5.5,"id":61077258}]}]}
{"op":"mcm","clk":"11926226529","pt":1724551802557,"mc":[{"id":"1.232224347","rc":[{"batb":[[0,2.08,39.76],[1,1.21,24.75],[2,1.12,1.76]],"ltp":2.2,"tv":5.5,"id":61077258}]}]}
{"op":"mcm","clk":"11926226706","pt":1724551805663,"mc":[{"id":"1.232224347","rc":[{"batb":[[0,2.1,5],[1,2.08,39.76],[2,1.21,24.75]],"ltp":2.2,"tv":5.5,"id":61077258}]}]}
{"op":"mcm","clk":"11926226875","pt":1724551809268,"mc":[{"id":"1.232224347","rc":[{"batb":[[0,2.08,39.76],[1,1.21,24.75],[2,1.12,1.76]],"ltp":2.2,"tv":5.5,"id":61077258}]}]}
{"op":"mcm","clk":"11926226983","pt":1724551811434,"mc":[{"id":"1.232224347","rc":[{"batb":[[0,2.1,5],[1,2.08,39.76],[2,1.21,24.75]],"ltp":2.2,"tv":5.5,"id":61077258}]}]}
{"op":"mcm","clk":"11926227138","pt":1724551814753,"mc":[{"id":"1.232224347","rc":[{"batb":[[0,2.08,39.76],[1,1.21,24.75],[2,1.12,1.76]],"ltp":2.2,"tv":5.5,"id":61077258}]}]}
{"op":"mcm","clk":"11926227252","pt":1724551816968,"mc":[{"id":"1.232224347","rc":[{"batb":[[0,2.1,5],[1,2.08,39.76],[2,1.21,24.75]],"ltp":2.2,"tv":5.5,"id":61077258}]}]}
{"op":"mcm","clk":"11926227427","pt":1724551820271,"mc":[{"id":"1.232224347","rc":[{"batb":[[0,2.08,39.76],[1,1.21,24.75],[2,1.12,1.76]],"ltp":2.2,"tv":5.5,"id":61077258}]}]}
{"op":"mcm","clk":"11926227540","pt":1724551822490,"mc":[{"id":"1.232224347","rc":[{"batb":[[0,2.1,5],[1,2.08,39.76],[2,1.21,24.75]],"ltp":2.2,"tv":5.5,"id":61077258}]}]}
{"op":"mcm","clk":"11926227729","pt":1724551825790,"mc":[{"id":"1.232224347","rc":[{"batb":[[0,2.08,39.76],[1,1.21,24.75],[2,1.12,1.76]],"ltp":2.2,"tv":5.5,"id":61077258}]}]}
{"op":"mcm","clk":"11926227852","pt":1724551827963,"mc":[{"id":"1.232224347","rc":[{"batb":[[0,2.1,5],[1,2.08,39.76],[2,1.21,24.75]],"ltp":2.2,"tv":5.5,"id":61077258}]}]}
{"op":"mcm","clk":"11926228032","pt":1724551831266,"mc":[{"id":"1.232224347","rc":[{"batb":[[0,2.08,39.76],[1,1.21,24.75],[2,1.12,1.76]],"ltp":2.2,"tv":5.5,"id":61077258}]}]}
{"op":"mcm","clk":"11926228186","pt":1724551834463,"mc":[{"id":"1.232224347","rc":[{"batb":[[0,2.1,5],[1,2.08,39.76],[2,1.21,24.75]],"ltp":2.2,"tv":5.5,"id":61077258}]}]}
{"op":"mcm","clk":"11926228415","pt":1724551837761,"mc":[{"id":"1.232224347","rc":[{"batb":[[0,2.08,39.76],[1,1.21,24.75],[2,1.12,1.76]],"ltp":2.2,"tv":5.5,"id":61077258}]}]}
{"op":"mcm","clk":"11926228545","pt":1724551840091,"mc":[{"id":"1.232224347","rc":[{"batb":[[0,2.1,5],[1,2.08,39.76],[2,1.21,24.75]],"ltp":2.2,"tv":5.5,"id":61077258}]}]}
{"op":"mcm","clk":"11926228718","pt":1724551843488,"mc":[{"id":"1.232224347","rc":[{"batb":[[0,2.08,39.76],[1,1.21,24.75],[2,1.12,1.76]],"ltp":2.2,"tv":5.5,"id":61077258}]}]}
{"op":"mcm","clk":"11926228842","pt":1724551845802,"mc":[{"id":"1.232224347","rc":[{"batb":[[0,2.1,5],[1,2.08,39.76],[2,1.21,24.75]],"ltp":2.2,"tv":5.5,"id":61077258}]}]}
{"op":"mcm","clk":"11926228993","pt":1724551849098,"mc":[{"id":"1.232224347","rc":[{"batb":[[0,2.08,39.76],[1,1.21,24.75],[2,1.12,1.76]],"ltp":2.2,"tv":5.5,"id":61077258}]}]}
{"op":"mcm","clk":"11926229105","pt":1724551851412,"mc":[{"id":"1.232224347","rc":[{"batb":[[0,2.1,5],[1,2.08,39.76],[2,1.21,24.75]],"ltp":2.2,"tv":5.5,"id":61077258}]}]}
{"op":"mcm","clk":"11926229296","pt":1724551854804,"mc":[{"id":"1.232224347","rc":[{"batb":[[0,2.08,39.76],[1,1.21,24.75],[2,1.12,1.76]],"ltp":2.2,"tv":5.5,"id":61077258}]}]}
{"op":"mcm","clk":"11926229447","pt":1724551858200,"mc":[{"id":"1.232224347","rc":[{"batb":[[0,2.1,5],[1,2.08,39.76],[2,1.21,24.75]],"ltp":2.2,"tv":5.5,"id":61077258}]}]}
{"op":"mcm","clk":"11926229614","pt":1724551861505,"mc":[{"id":"1.232224347","rc":[{"batb":[[0,2.08,39.76],[1,1.21,24.75],[2,1.12,1.76]],"ltp":2.2,"tv":5.5,"id":61077258}]}]}
{"op":"mcm","clk":"11926229738","pt":1724551863824,"mc":[{"id":"1.232224347","rc":[{"batb":[[0,2.1,5],[1,2.08,39.76],[2,1.21,24.75]],"ltp":2.2,"tv":5.5,"id":61077258}]}]}
{"op":"mcm","clk":"11926229911","pt":1724551867290,"mc":[{"id":"1.232224347","rc":[{"batb":[[0,2.08,39.76],[1,1.21,24.75],[2,1.12,1.76]],"ltp":2.2,"tv":5.5,"id":61077258}]}]}
{"op":"mcm","clk":"11926230029","pt":1724551869605,"mc":[{"id":"1.232224347","rc":[{"batb":[[0,2.1,5],[1,2.08,39.76],[2,1.21,24.75]],"ltp":2.2,"tv":5.5,"id":61077258}]}]}
{"op":"mcm","clk":"11926230191","pt":1724551872929,"mc":[{"id":"1.232224347","rc":[{"batb":[[0,2.08,39.76],[1,1.21,24.75],[2,1.12,1.76]],"ltp":2.2,"tv":5.5,"id":61077258}]}]}
{"op":"mcm","clk":"11926230343","pt":1724551875419,"mc":[{"id":"1.232224347","rc":[{"batb":[[0,2.1,5],[1,2.08,39.76],[2,1.21,24.75]],"ltp":2.2,"tv":5.5,"id":61077258}]}]}
{"op":"mcm","clk":"11926230513","pt":1724551878623,"mc":[{"id":"1.232224347","rc":[{"batb":[[0,2.08,39.76],[1,1.21,24.75],[2,1.12,1.76]],"ltp":2.2,"tv":5.5,"id":61077258}]}]}
{"op":"mcm","clk":"11926230640","pt":1724551880937,"mc":[{"id":"1.232224347","rc":[{"batb":[[0,2.1,5],[1,2.08,39.76],[2,1.21,24.75]],"ltp":2.2,"tv":5.5,"id":61077258}]}]}
{"op":"mcm","clk":"11926230830","pt":1724551884242,"mc":[{"id":"1.232224347","rc":[{"batb":[[0,2.08,39.76],[1,1.21,24.75],[2,1.12,1.76]],"ltp":2.2,"tv":5.5,"id":61077258}]}]}
{"op":"mcm","clk":"11926230962","pt":1724551886821,"mc":[{"id":"1.232224347","rc":[{"batb":[[0,2.1,5],[1,2.08,39.76],[2,1.21,24.75]],"ltp":2.2,"tv":5.5,"id":61077258}]}]}
{"op":"mcm","clk":"11926231147","pt":1724551890327,"mc":[{"id":"1.232224347","rc":[{"batb":[[0,2.08,39.76],[1,1.21,24.75],[2,1.12,1.76]],"ltp":2.2,"tv":5.5,"id":61077258}]}]}
{"op":"mcm","clk":"11926231280","pt":1724551892748,"mc":[{"id":"1.232224347","rc":[{"batb":[[0,2.1,5],[1,2.08,39.76],[2,1.21,24.75]],"ltp":2.2,"tv":5.5,"id":61077258}]}]}
{"op":"mcm","clk":"11926231450","pt":1724551896053,"mc":[{"id":"1.232224347","rc":[{"batb":[[0,2.08,39.76],[1,1.21,24.75],[2,1.12,1.76]],"ltp":2.2,"tv":5.5,"id":61077258}]}]}
{"op":"mcm","clk":"11926231569","pt":1724551898316,"mc":[{"id":"1.232224347","rc":[{"batb":[[0,2.1,5],[1,2.08,39.76],[2,1.21,24.75]],"ltp":2.2,"tv":5.5,"id":61077258}]}]}
{"op":"mcm","clk":"11926231790","pt":1724551901630,"mc":[{"id":"1.232224347","rc":[{"batb":[[0,2.08,39.76],[1,1.21,24.75],[2,1.12,1.76]],"ltp":2.2,"tv":5.5,"id":61077258}]}]}
{"op":"mcm","clk":"11926231904","pt":1724551903958,"mc":[{"id":"1.232224347","rc":[{"batb":[[0,2.1,5],[1,2.08,39.76],[2,1.21,24.75]],"ltp":2.2,"tv":5.5,"id":61077258}]}]}
{"op":"mcm","clk":"11926232076","pt":1724551907151,"mc":[{"id":"1.232224347","rc":[{"batb":[[0,2.08,39.76],[1,1.21,24.75],[2,1.12,1.76]],"ltp":2.2,"tv":5.5,"id":61077258}]}]}
{"op":"mcm","clk":"11926232218","pt":1724551909944,"mc":[{"id":"1.232224347","rc":[{"batb":[[0,2.1,5],[1,2.08,39.76],[2,1.21,24.75]],"ltp":2.2,"tv":5.5,"id":61077258}]}]}
{"op":"mcm","clk":"11926232396","pt":1724551913244,"mc":[{"id":"1.232224347","rc":[{"batb":[[0,2.08,39.76],[1,1.21,24.75],[2,1.12,1.76]],"ltp":2.2,"tv":5.5,"id":61077258}]}]}
{"op":"mcm","clk":"11926232520","pt":1724551915571,"mc":[{"id":"1.232224347","rc":[{"batb":[[0,2.1,5],[1,2.08,39.76],[2,1.21,24.75]],"ltp":2.2,"tv":5.5,"id":61077258}]}]}
{"op":"mcm","clk":"11926232685","pt":1724551918868,"mc":[{"id":"1.232224347","rc":[{"batb":[[0,2.08,39.76],[1,1.21,24.75],[2,1.12,1.76]],"ltp":2.2,"tv":5.5,"id":61077258}]}]}
{"op":"mcm","clk":"11926232882","pt":1724551922484,"mc":[{"id":"1.232224347","rc":[{"batb":[[0,2.1,5],[1,2.08,39.76],[2,1.21,24.75]],"ltp":2.2,"tv":5.5,"id":61077258}]}]}
{"op":"mcm","clk":"11926233075","pt":1724551925764,"mc":[{"id":"1.232224347","rc":[{"batb":[[0,2.08,39.76],[1,1.21,24.75],[2,1.12,1.76]],"ltp":2.2,"tv":5.5,"id":61077258}]}]}
{"op":"mcm","clk":"11926233207","pt":1724551928055,"mc":[{"id":"1.232224347","rc":[{"batb":[[0,2.1,5],[1,2.08,39.76],[2,1.21,24.75]],"ltp":2.2,"tv":5.5,"id":61077258}]}]}
{"op":"mcm","clk":"11926233372","pt":1724551931362,"mc":[{"id":"1.232224347","rc":[{"batb":[[0,2.08,39.76],[1,1.21,24.75],[2,1.12,1.76]],"ltp":2.2,"tv":5.5,"id":61077258}]}]}
{"op":"mcm","clk":"11926233479","pt":1724551933781,"mc":[{"id":"1.232224347","rc":[{"batb":[[0,2.1,5],[1,2.08,39.76],[2,1.21,24.75]],"ltp":2.2,"tv":5.5,"id":61077258}]}]}
{"op":"mcm","clk":"11926233676","pt":1724551937085,"mc":[{"id":"1.232224347","rc":[{"batb":[[0,2.08,39.76],[1,1.21,24.75],[2,1.12,1.76]],"ltp":2.2,"tv":5.5,"id":61077258}]}]}
{"op":"mcm","clk":"11926233796","pt":1724551939292,"mc":[{"id":"1.232224347","rc":[{"batb":[[0,2.1,5],[1,2.08,39.76],[2,1.21,24.75]],"ltp":2.2,"tv":5.5,"id":61077258}]}]}
{"op":"mcm","clk":"11926233983","pt":1724551942700,"mc":[{"id":"1.232224347","rc":[{"batb":[[0,2.08,39.76],[1,1.21,24.75],[2,1.12,1.76]],"ltp":2.2,"tv":5.5,"id":61077258}]}]}
{"op":"mcm","clk":"11926234077","pt":1724551944964,"mc":[{"id":"1.232224347","rc":[{"batb":[[0,2.1,5],[1,2.08,39.76],[2,1.21,24.75]],"ltp":2.2,"tv":5.5,"id":61077258}]}]}
{"op":"mcm","clk":"11926234268","pt":1724551948271,"mc":[{"id":"1.232224347","rc":[{"batb":[[0,2.08,39.76],[1,1.21,24.75],[2,1.12,1.76]],"ltp":2.2,"tv":5.5,"id":61077258}]}]}
{"op":"mcm","clk":"11926234416","pt":1724551950397,"mc":[{"id":"1.232224347","rc":[{"batb":[[0,2.1,5],[1,2.08,39.76],[2,1.21,24.75]],"ltp":2.2,"tv":5.5,"id":61077258}]}]}
{"op":"mcm","clk":"11926234650","pt":1724551953704,"mc":[{"id":"1.232224347","rc":[{"batb":[[0,2.08,39.76],[1,1.21,24.75],[2,1.12,1.76]],"ltp":2.2,"tv":5.5,"id":61077258}]}]}
{"op":"mcm","clk":"11926234765","pt":1724551955920,"mc":[{"id":"1.232224347","rc":[{"batb":[[0,2.1,5],[1,2.08,39.76],[2,1.21,24.75]],"ltp":2.2,"tv":5.5,"id":61077258}]}]}
{"op":"mcm","clk":"11926234937","pt":1724551959225,"mc":[{"id":"1.232224347","rc":[{"batb":[[0,2.08,39.76],[1,1.21,24.75],[2,1.12,1.76]],"ltp":2.2,"tv":5.5,"id":61077258}]}]}
{"op":"mcm","clk":"11926235087","pt":1724551962021,"mc":[{"id":"1.232224347","rc":[{"batb":[[0,2.1,5],[1,2.08,39.76],[2,1.21,24.75]],"ltp":2.2,"tv":5.5,"id":61077258}]}]}
{"op":"mcm","clk":"11926235285","pt":1724551965308,"mc":[{"id":"1.232224347","rc":[{"batb":[[0,2.08,39.76],[1,1.21,24.75],[2,1.12,1.76]],"ltp":2.2,"tv":5.5,"id":61077258}]}]}
{"op":"mcm","clk":"11926235475","pt":1724551967794,"mc":[{"id":"1.232224347","rc":[{"batb":[[0,2.1,5],[1,2.08,39.76],[2,1.21,24.75]],"ltp":2.2,"tv":5.5,"id":61077258}]}]}
{"op":"mcm","clk":"11926235639","pt":1724551971140,"mc":[{"id":"1.232224347","rc":[{"batb":[[0,2.08,39.76],[1,1.21,24.75],[2,1.12,1.76]],"ltp":2.2,"tv":5.5,"id":61077258}]}]}
{"op":"mcm","clk":"11926235730","pt":1724551973302,"mc":[{"id":"1.232224347","rc":[{"batb":[[0,2.1,5],[1,2.08,39.76],[2,1.21,24.75]],"ltp":2.2,"tv":5.5,"id":61077258}]}]}
{"op":"mcm","clk":"11926235881","pt":1724551976638,"mc":[{"id":"1.232224347","rc":[{"batb":[[0,2.08,39.76],[1,1.21,24.75],[2,1.12,1.76]],"ltp":2.2,"tv":5.5,"id":61077258}]}]}
{"op":"mcm","clk":"11926235967","pt":1724551978908,"mc":[{"id":"1.232224347","rc":[{"batb":[[0,2.1,5],[1,2.08,39.76],[2,1.21,24.75]],"ltp":2.2,"tv":5.5,"id":61077258}]}]}
{"op":"mcm","clk":"11926236193","pt":1724551982329,"mc":[{"id":"1.232224347","rc":[{"batb":[[0,2.08,39.76],[1,1.21,24.75],[2,1.12,1.76]],"ltp":2.2,"tv":5.5,"id":61077258}]}]}
{"op":"mcm","clk":"11926236295","pt":1724551984513,"mc":[{"id":"1.232224347","rc":[{"batb":[[0,2.1,5],[1,2.08,39.76],[2,1.21,24.75]],"ltp":2.2,"tv":5.5,"id":61077258}]}]}
{"op":"mcm","clk":"11926236404","pt":1724551987850,"mc":[{"id":"1.232224347","rc":[{"batb":[[0,2.08,39.76],[1,1.21,24.75],[2,1.12,1.76]],"ltp":2.2,"tv":5.5,"id":61077258}]}]}
{"op":"mcm","clk":"11926236492","pt":1724551990030,"mc":[{"id":"1.232224347","rc":[{"batb":[[0,2.1,5],[1,2.08,39.76],[2,1.21,24.75]],"ltp":2.2,"tv":5.5,"id":61077258}]}]}
{"op":"mcm","clk":"11926236632","pt":1724551993440,"mc":[{"id":"1.232224347","rc":[{"batb":[[0,2.08,39.76],[1,1.21,24.75],[2,1.12,1.76]],"ltp":2.2,"tv":5.5,"id":61077258}]}]}
{"op":"mcm","clk":"11926236770","pt":1724551995666,"mc":[{"id":"1.232224347","rc":[{"batb":[[0,2.1,5],[1,2.08,39.76],[2,1.21,24.75]],"ltp":2.2,"tv":5.5,"id":61077258}]}]}
{"op":"mcm","clk":"11926236960","pt":1724551998935,"mc":[{"id":"1.232224347","rc":[{"batb":[[0,2.08,39.76],[1,1.21,24.75],[2,1.12,1.76]],"ltp":2.2,"tv":5.5,"id":61077258}]}]}
{"op":"mcm","clk":"11926237130","pt":1724552001936,"mc":[{"id":"1.232224347","rc":[{"batb":[[0,2.1,5],[1,2.08,39.76],[2,1.21,24.75]],"ltp":2.2,"tv":5.5,"id":61077258}]}]}
{"op":"mcm","clk":"11926237295","pt":1724552005335,"mc":[{"id":"1.232224347","rc":[{"batb":[[0,2.08,39.76],[1,1.21,24.75],[2,1.12,1.76]],"ltp":2.2,"tv":5.5,"id":61077258}]}]}
{"op":"mcm","clk":"11926237415","pt":1724552007557,"mc":[{"id":"1.232224347","rc":[{"batb":[[0,2.1,5],[1,2.08,39.76],[2,1.21,24.75]],"ltp":2.2,"tv":5.5,"id":61077258}]}]}
{"op":"mcm","clk":"11926237599","pt":1724552010858,"mc":[{"id":"1.232224347","rc":[{"batb":[[0,2.08,39.76],[1,1.21,24.75],[2,1.12,1.76]],"ltp":2.2,"tv":5.5,"id":61077258}]}]}
{"op":"mcm","clk":"11926237759","pt":1724552013370,"mc":[{"id":"1.232224347","rc":[{"batb":[[0,2.1,5],[1,2.08,39.76],[2,1.21,24.75]],"ltp":2.2,"tv":5.5,"id":61077258}]}]}
{"op":"mcm","clk":"11926237961","pt":1724552016776,"mc":[{"id":"1.232224347","rc":[{"batb":[[0,2.08,39.76],[1,1.21,24.75],[2,1.12,1.76]],"ltp":2.2,"tv":5.5,"id":61077258}]}]}
{"op":"mcm","clk":"11926238098","pt":1724552018953,"mc":[{"id":"1.232224347","rc":[{"batb":[[0,2.1,5],[1,2.08,39.76],[2,1.21,24.75]],"ltp":2.2,"tv":5.5,"id":61077258}]}]}
{"op":"mcm","clk":"11926238277","pt":1724552022458,"mc":[{"id":"1.232224347","rc":[{"batb":[[0,2.08,39.76],[1,1.21,24.75],[2,1.12,1.76]],"ltp":2.2,"tv":5.5,"id":61077258}]}]}
{"op":"mcm","clk":"11926238437","pt":1724552025551,"mc":[{"id":"1.232224347","rc":[{"batb":[[0,2.1,5],[1,2.08,39.76],[2,1.21,24.75]],"ltp":2.2,"tv":5.5,"id":61077258}]}]}
{"op":"mcm","clk":"11926238631","pt":1724552028951,"mc":[{"id":"1.232224347","rc":[{"batb":[[0,2.08,39.76],[1,1.21,24.75],[2,1.12,1.76]],"ltp":2.2,"tv":5.5,"id":61077258}]}]}
{"op":"mcm","clk":"11926238784","pt":1724552032047,"mc":[{"id":"1.232224347","rc":[{"batb":[[0,2.1,5],[1,2.08,39.76],[2,1.21,24.75]],"ltp":2.2,"tv":5.5,"id":61077258}]}]}
{"op":"mcm","clk":"11926238958","pt":1724552035349,"mc":[{"id":"1.232224347","rc":[{"batb":[[0,2.08,39.76],[1,1.21,24.75],[2,1.12,1.76]],"ltp":2.2,"tv":5.5,"id":61077258}]}]}
{"op":"mcm","clk":"11926239091","pt":1724552038081,"mc":[{"id":"1.232224347","rc":[{"batb":[[0,2.1,5],[1,2.08,39.76],[2,1.21,24.75]],"ltp":2.2,"tv":5.5,"id":61077258}]}]}
{"op":"mcm","clk":"11926239250","pt":1724552041411,"mc":[{"id":"1.232224347","rc":[{"batb":[[0,2.08,39.76],[1,1.21,24.75],[2,1.12,1.76]],"ltp":2.2,"tv":5.5,"id":61077258}]}]}
{"op":"mcm","clk":"11926239383","pt":1724552043808,"mc":[{"id":"1.232224347","rc":[{"batb":[[0,2.1,5],[1,2.08,39.76],[2,1.21,24.75]],"ltp":2.2,"tv":5.5,"id":61077258}]}]}
{"op":"mcm","clk":"11926239591","pt":1724552047067,"mc":[{"id":"1.232224347","rc":[{"batb":[[0,2.08,39.76],[1,1.21,24.75],[2,1.12,1.76]],"ltp":2.2,"tv":5.5,"id":61077258}]}]}
{"op":"mcm","clk":"11926239719","pt":1724552049282,"mc":[{"id":"1.232224347","rc":[{"batb":[[0,2.1,5],[1,2.08,39.76],[2,1.21,24.75]],"ltp":2.2,"tv":5.5,"id":61077258}]}]}
{"op":"mcm","clk":"11926239900","pt":1724552052574,"mc":[{"id":"1.232224347","rc":[{"batb":[[0,2.08,39.76],[1,1.21,24.75],[2,1.12,1.76]],"ltp":2.2,"tv":5.5,"id":61077258}]}]}
{"op":"mcm","clk":"11926240039","pt":1724552055299,"mc":[{"id":"1.232224347","rc":[{"batb":[[0,2.1,5],[1,2.08,39.76],[2,1.21,24.75]],"ltp":2.2,"tv":5.5,"id":61077258}]}]}
{"op":"mcm","clk":"11926240209","pt":1724552058599,"mc":[{"id":"1.232224347","rc":[{"batb":[[0,2.08,39.76],[1,1.21,24.75],[2,1.12,1.76]],"ltp":2.2,"tv":5.5,"id":61077258}]}]}
{"op":"mcm","clk":"11926240341","pt":1724552060825,"mc":[{"id":"1.232224347","rc":[{"batb":[[0,2.1,5],[1,2.08,39.76],[2,1.21,24.75]],"ltp":2.2,"tv":5.5,"id":61077258}]}]}
{"op":"mcm","clk":"11926240518","pt":1724552064172,"mc":[{"id":"1.232224347","rc":[{"batb":[[0,2.08,39.76],[1,1.21,24.75],[2,1.12,1.76]],"ltp":2.2,"tv":5.5,"id":61077258}]}]}
{"op":"mcm","clk":"11926240696","pt":1724552068254,"mc":[{"id":"1.232224347","rc":[{"batb":[[0,2.1,5],[1,2.08,39.76],[2,1.21,24.75]],"ltp":2.2,"tv":5.5,"id":61077258}]}]}
{"op":"mcm","clk":"11926240900","pt":1724552071658,"mc":[{"id":"1.232224347","rc":[{"batb":[[0,2.08,39.76],[1,1.21,24.75],[2,1.12,1.76]],"ltp":2.2,"tv":5.5,"id":61077258}]}]}
{"op":"mcm","clk":"11926241015","pt":1724552073773,"mc":[{"id":"1.232224347","rc":[{"batb":[[0,2.1,5],[1,2.08,39.76],[2,1.21,24.75]],"ltp":2.2,"tv":5.5,"id":61077258}]}]}
{"op":"mcm","clk":"11926241213","pt":1724552077071,"mc":[{"id":"1.232224347","rc":[{"batb":[[0,2.08,39.76],[1,1.21,24.75],[2,1.12,1.76]],"ltp":2.2,"tv":5.5,"id":61077258}]}]}
{"op":"mcm","clk":"11926241374","pt":1724552080121,"mc":[{"id":"1.232224347","rc":[{"batb":[[0,2.1,5],[1,2.08,39.76],[2,1.21,24.75]],"ltp":2.2,"tv":5.5,"id":61077258}]}]}
{"op":"mcm","clk":"11926241548","pt":1724552083473,"mc":[{"id":"1.232224347","rc":[{"batb":[[0,2.08,39.76],[1,1.21,24.75],[2,1.12,1.76]],"ltp":2.2,"tv":5.5,"id":61077258}]}]}
{"op":"mcm","clk":"11926241664","pt":1724552085697,"mc":[{"id":"1.232224347","rc":[{"batb":[[0,2.1,5],[1,2.08,39.76],[2,1.21,24.75]],"ltp":2.2,"tv":5.5,"id":61077258}]}]}
{"op":"mcm","clk":"11926241818","pt":1724552088994,"mc":[{"id":"1.232224347","rc":[{"batb":[[0,2.08,39.76],[1,1.21,24.75],[2,1.12,1.76]],"ltp":2.2,"tv":5.5,"id":61077258}]}]}
{"op":"mcm","clk":"11926242002","pt":1724552092504,"mc":[{"id":"1.232224347","rc":[{"batb":[[0,2.1,5],[1,2.08,39.76],[2,1.21,24.75]],"ltp":2.2,"tv":5.5,"id":61077258}]}]}
{"op":"mcm","clk":"11926242182","pt":1724552095779,"mc":[{"id":"1.232224347","rc":[{"batb":[[0,2.08,39.76],[1,1.21,24.75],[2,1.12,1.76]],"ltp":2.2,"tv":5.5,"id":61077258}]}]}
{"op":"mcm","clk":"11926242358","pt":1724552098814,"mc":[{"id":"1.232224347","rc":[{"batb":[[0,2.1,5],[1,2.08,39.76],[2,1.21,24.75]],"ltp":2.2,"tv":5.5,"id":61077258}]}]}
{"op":"mcm","clk":"11926242569","pt":1724552102085,"mc":[{"id":"1.232224347","rc":[{"batb":[[0,2.08,39.76],[1,1.21,24.75],[2,1.12,1.76]],"ltp":2.2,"tv":5.5,"id":61077258}]}]}
{"op":"mcm","clk":"11926242724","pt":1724552104503,"mc":[{"id":"1.232224347","rc":[{"batb":[[0,2.1,5],[1,2.08,39.76],[2,1.21,24.75]],"ltp":2.2,"tv":5.5,"id":61077258}]}]}
{"op":"mcm","clk":"11926242902","pt":1724552108015,"mc":[{"id":"1.232224347","rc":[{"batb":[[0,2.08,39.76],[1,1.21,24.75],[2,1.12,1.76]],"ltp":2.2,"tv":5.5,"id":61077258}]}]}
{"op":"mcm","clk":"11926243021","pt":1724552110122,"mc":[{"id":"1.232224347","rc":[{"batb":[[0,2.1,5],[1,2.08,39.76],[2,1.21,24.75]],"ltp":2.2,"tv":5.5,"id":61077258}]}]}
{"op":"mcm","clk":"11926243254","pt":1724552113428,"mc":[{"id":"1.232224347","rc":[{"batb":[[0,2.08,39.76],[1,1.21,24.75],[2,1.12,1.76]],"ltp":2.2,"tv":5.5,"id":61077258}]}]}
{"op":"mcm","clk":"11926243394","pt":1724552115608,"mc":[{"id":"1.232224347","rc":[{"batb":[[0,2.1,5],[1,2.08,39.76],[2,1.21,24.75]],"ltp":2.2,"tv":5.5,"id":61077258}]}]}
{"op":"mcm","clk":"11926243618","pt":1724552119015,"mc":[{"id":"1.232224347","rc":[{"batb":[[0,2.08,39.76],[1,1.21,24.75],[2,1.12,1.76]],"ltp":2.2,"tv":5.5,"id":61077258}]}]}
{"op":"mcm","clk":"11926243859","pt":1724552123113,"mc":[{"id":"1.232224347","rc":[{"batb":[[0,2.1,5],[1,2.08,39.76],[2,1.21,24.75]],"ltp":2.2,"tv":5.5,"id":61077258}]}]}
{"op":"mcm","clk":"11926244028","pt":1724552126417,"mc":[{"id":"1.232224347","rc":[{"batb":[[0,2.08,39.76],[1,1.21,24.75],[2,1.12,1.76]],"ltp":2.2,"tv":5.5,"id":61077258}]}]}
{"op":"mcm","clk":"11926244193","pt":1724552129350,"mc":[{"id":"1.232224347","rc":[{"batb":[[0,2.1,5],[1,2.08,39.76],[2,1.21,24.75]],"ltp":2.2,"tv":5.5,"id":61077258}]}]}
{"op":"mcm","clk":"11926244407","pt":1724552132638,"mc":[{"id":"1.232224347","rc":[{"batb":[[0,2.08,39.76],[1,1.21,24.75],[2,1.12,1.76]],"ltp":2.2,"tv":5.5,"id":61077258}]}]}
{"op":"mcm","clk":"11926244619","pt":1724552135847,"mc":[{"id":"1.232224347","rc":[{"batb":[[0,2.1,5],[1,2.08,39.76],[2,1.21,24.75]],"ltp":2.2,"tv":5.5,"id":61077258}]}]}
{"op":"mcm","clk":"11926244817","pt":1724552139153,"mc":[{"id":"1.232224347","rc":[{"batb":[[0,2.08,39.76],[1,1.21,24.75],[2,1.12,1.76]],"ltp":2.2,"tv":5.5,"id":61077258}]}]}
{"op":"mcm","clk":"11926244929","pt":1724552141430,"mc":[{"id":"1.232224347","rc":[{"batb":[[0,2.1,5],[1,2.08,39.76],[2,1.21,24.75]],"ltp":2.2,"tv":5.5,"id":61077258}]}]}
{"op":"mcm","clk":"11926245109","pt":1724552144735,"mc":[{"id":"1.232224347","rc":[{"batb":[[0,2.08,39.76],[1,1.21,24.75],[2,1.12,1.76]],"ltp":2.2,"tv":5.5,"id":61077258}]}]}
{"op":"mcm","clk":"11926245198","pt":1724552146951,"mc":[{"id":"1.232224347","rc":[{"batb":[[0,2.1,5],[1,2.08,39.76],[2,1.21,24.75]],"ltp":2.2,"tv":5.5,"id":61077258}]}]}
{"op":"mcm","clk":"11926245372","pt":1724552150262,"mc":[{"id":"1.232224347","rc":[{"batb":[[0,2.08,39.76],[1,1.21,24.75],[2,1.12,1.76]],"ltp":2.2,"tv":5.5,"id":61077258}]}]}
{"op":"mcm","clk":"11926245613","pt":1724552155225,"mc":[{"id":"1.232224347","rc":[{"batb":[[0,2.1,5],[1,2.08,39.76],[2,1.21,24.75]],"ltp":2.2,"tv":5.5,"id":61077258}]}]}
{"op":"mcm","clk":"11926245774","pt":1724552158575,"mc":[{"id":"1.232224347","rc":[{"batb":[[0,2.08,39.76],[1,1.21,24.75],[2,1.12,1.76]],"ltp":2.2,"tv":5.5,"id":61077258}]}]}
{"op":"mcm","clk":"11926245908","pt":1724552160754,"mc":[{"id":"1.232224347","rc":[{"batb":[[0,2.1,5],[1,2.08,39.76],[2,1.21,24.75]],"ltp":2.2,"tv":5.5,"id":61077258}]}]}
{"op":"mcm","clk":"11926246149","pt":1724552164073,"mc":[{"id":"1.232224347","rc":[{"batb":[[0,2.08,39.76],[1,1.21,24.75],[2,1.12,1.76]],"ltp":2.2,"tv":5.5,"id":61077258}]}]}
{"op":"mcm","clk":"11926246230","pt":1724552165674,"mc":[{"id":"1.232224347","rc":[{"batb":[[0,1.5,246.54],[1,1.21,25.63],[2,1.12,1.76]],"ltp":1.8,"tv":214.75,"id":48800301}]}]}
{"op":"mcm","clk":"11926246285","pt":1724552166757,"mc":[{"id":"1.232224347","rc":[{"batb":[[0,2.1,5],[1,2.08,39.76],[2,1.21,24.75]],"ltp":2.2,"tv":5.5,"id":61077258}]}]}
{"op":"mcm","clk":"11926246471","pt":1724552170188,"mc":[{"id":"1.232224347","rc":[{"batb":[[0,2.08,39.76],[1,1.21,24.75],[2,1.12,1.76]],"ltp":2.2,"tv":5.5,"id":61077258}]}]}
{"op":"mcm","clk":"11926246689","pt":1724552173787,"mc":[{"id":"1.232224347","rc":[{"batb":[[0,2.1,5],[1,2.08,39.76],[2,1.21,24.75]],"ltp":2.2,"tv":5.5,"id":61077258}]}]}
{"op":"mcm","clk":"11926246936","pt":1724552177368,"mc":[{"id":"1.232224347","rc":[{"batb":[[0,2.08,39.76],[1,1.21,24.75],[2,1.12,1.76]],"ltp":2.2,"tv":5.5,"id":61077258}]}]}
{"op":"mcm","clk":"11926247106","pt":1724552180668,"mc":[{"id":"1.232224347","rc":[{"batb":[[0,2.1,5],[1,2.08,39.76],[2,1.21,24.75]],"ltp":2.2,"tv":5.5,"id":61077258}]}]}
{"op":"mcm","clk":"11926247301","pt":1724552183996,"mc":[{"id":"1.232224347","rc":[{"batb":[[0,2.08,39.76],[1,1.21,24.75],[2,1.12,1.76]],"ltp":2.2,"tv":5.5,"id":61077258}]}]}
{"op":"mcm","clk":"11926247503","pt":1724552187094,"mc":[{"id":"1.232224347","rc":[{"batb":[[0,2.1,5],[1,2.08,39.76],[2,1.21,24.75]],"ltp":2.2,"tv":5.5,"id":61077258}]}]}
{"op":"mcm","clk":"11926247685","pt":1724552190393,"mc":[{"id":"1.232224347","rc":[{"batb":[[0,2.08,39.76],[1,1.21,24.75],[2,1.12,1.76]],"ltp":2.2,"tv":5.5,"id":61077258}]}]}
{"op":"mcm","clk":"11926247892","pt":1724552194166,"mc":[{"id":"1.232224347","rc":[{"batb":[[0,2.1,5],[1,2.08,39.76],[2,1.21,24.75]],"ltp":2.2,"tv":5.5,"id":61077258}]}]}
{"op":"mcm","clk":"11926248062","pt":1724552197416,"mc":[{"id":"1.232224347","rc":[{"batb":[[0,2.08,39.76],[1,1.21,24.75],[2,1.12,1.76]],"ltp":2.2,"tv":5.5,"id":61077258}]}]}
{"op":"mcm","clk":"11926248238","pt":1724552200308,"mc":[{"id":"1.232224347","rc":[{"batb":[[0,2.1,5],[1,2.08,39.76],[2,1.21,24.75]],"ltp":2.2,"tv":5.5,"id":61077258}]}]}
{"op":"mcm","clk":"11926248419","pt":1724552203612,"mc":[{"id":"1.232224347","rc":[{"batb":[[0,2.08,39.76],[1,1.21,24.75],[2,1.12,1.76]],"ltp":2.2,"tv":5.5,"id":61077258}]}]}
{"op":"mcm","clk":"11926248530","pt":1724552205985,"mc":[{"id":"1.232224347","rc":[{"batb":[[0,2.1,5],[1,2.08,39.76],[2,1.21,24.75]],"ltp":2.2,"tv":5.5,"id":61077258}]}]}
{"op":"mcm","clk":"11926248731","pt":1724552209232,"mc":[{"id":"1.232224347","rc":[{"batb":[[0,2.08,39.76],[1,1.21,24.75],[2,1.12,1.76]],"ltp":2.2,"tv":5.5,"id":61077258}]}]}
{"op":"mcm","clk":"11926248907","pt":1724552212632,"mc":[{"id":"1.232224347","rc":[{"batb":[[0,2.1,5],[1,2.08,39.76],[2,1.21,24.75]],"ltp":2.2,"tv":5.5,"id":61077258}]}]}
{"op":"mcm","clk":"11926249060","pt":1724552215936,"mc":[{"id":"1.232224347","rc":[{"batb":[[0,2.08,39.76],[1,1.21,24.75],[2,1.12,1.76]],"ltp":2.2,"tv":5.5,"id":61077258}]}]}
{"op":"mcm","clk":"11926249201","pt":1724552218824,"mc":[{"id":"1.232224347","rc":[{"batb":[[0,2.1,5],[1,2.08,39.76],[2,1.21,24.75]],"ltp":2.2,"tv":5.5,"id":61077258}]}]}
{"op":"mcm","clk":"11926249396","pt":1724552222145,"mc":[{"id":"1.232224347","rc":[{"batb":[[0,2.08,39.76],[1,1.21,24.75],[2,1.12,1.76]],"ltp":2.2,"tv":5.5,"id":61077258}]}]}
{"op":"mcm","clk":"11926249576","pt":1724552225306,"mc":[{"id":"1.232224347","rc":[{"batb":[[0,2.1,5],[1,2.08,39.76],[2,1.21,24.75]],"ltp":2.2,"tv":5.5,"id":61077258}]}]}
{"op":"mcm","clk":"11926249756","pt":1724552228646,"mc":[{"id":"1.232224347","rc":[{"batb":[[0,2.08,39.76],[1,1.21,24.75],[2,1.12,1.76]],"ltp":2.2,"tv":5.5,"id":61077258}]}]}
{"op":"mcm","clk":"11926249850","pt":1724552231027,"mc":[{"id":"1.232224347","rc":[{"batb":[[0,2.1,5],[1,2.08,39.76],[2,1.21,24.75]],"ltp":2.2,"tv":5.5,"id":61077258}]}]}
{"op":"mcm","clk":"11926250019","pt":1724552234552,"mc":[{"id":"1.232224347","rc":[{"batb":[[0,2.08,39.76],[1,1.21,24.75],[2,1.12,1.76]],"ltp":2.2,"tv":5.5,"id":61077258}]}]}
{"op":"mcm","clk":"11926250250","pt":1724552238849,"mc":[{"id":"1.232224347","rc":[{"batb":[[0,2.1,5],[1,2.08,39.76],[2,1.21,24.75]],"ltp":2.2,"tv":5.5,"id":61077258}]}]}
{"op":"mcm","clk":"11926250422","pt":1724552242360,"mc":[{"id":"1.232224347","rc":[{"batb":[[0,2.08,39.76],[1,1.21,24.75],[2,1.12,1.76]],"ltp":2.2,"tv":5.5,"id":61077258}]}]}
{"op":"mcm","clk":"11926250550","pt":1724552244539,"mc":[{"id":"1.232224347","rc":[{"batb":[[0,2.1,5],[1,2.08,39.76],[2,1.21,24.75]],"ltp":2.2,"tv":5.5,"id":61077258}]}]}
{"op":"mcm","clk":"11926250768","pt":1724552248069,"mc":[{"id":"1.232224347","rc":[{"batb":[[0,2.08,39.76],[1,1.21,24.75],[2,1.12,1.76]],"ltp":2.2,"tv":5.5,"id":61077258}]}]}
{"op":"mcm","clk":"11926250898","pt":1724552250242,"mc":[{"id":"1.232224347","rc":[{"batb":[[0,2.1,5],[1,2.08,39.76],[2,1.21,24.75]],"ltp":2.2,"tv":5.5,"id":61077258}]}]}
{"op":"mcm","clk":"11926251069","pt":1724552253548,"mc":[{"id":"1.232224347","rc":[{"batb":[[0,2.08,39.76],[1,1.21,24.75],[2,1.12,1.76]],"ltp":2.2,"tv":5.5,"id":61077258}]}]}
{"op":"mcm","clk":"11926251203","pt":1724552255762,"mc":[{"id":"1.232224347","rc":[{"batb":[[0,2.1,5],[1,2.08,39.76],[2,1.21,24.75]],"ltp":2.2,"tv":5.5,"id":61077258}]}]}
{"op":"mcm","clk":"11926251253","pt":1724552256643,"mc":[{"id":"1.232224347","rc":[{"batb":[[1,1.43,135.6],[2,1.21,25.63]],"ltp":1.8,"tv":214.75,"id":48800301}]}]}
{"op":"mcm","clk":"11926251416","pt":1724552259371,"mc":[{"id":"1.232224347","rc":[{"batb":[[0,2.08,39.76],[1,1.21,24.75],[2,1.12,1.76]],"ltp":2.2,"tv":5.5,"id":61077258}]}]}
{"op":"mcm","clk":"11926251519","pt":1724552261843,"mc":[{"id":"1.232224347","rc":[{"batb":[[0,2.1,5],[1,2.08,39.76],[2,1.21,24.75]],"ltp":2.2,"tv":5.5,"id":61077258}]}]}
{"op":"mcm","clk":"11926251709","pt":1724552265083,"mc":[{"id":"1.232224347","rc":[{"batb":[[0,2.08,39.76],[1,1.21,24.75],[2,1.12,1.76]],"ltp":2.2,"tv":5.5,"id":61077258}]}]}
{"op":"mcm","clk":"11926251847","pt":1724552267567,"mc":[{"id":"1.232224347","rc":[{"batb":[[0,2.1,5],[1,2.08,39.76],[2,1.21,24.75]],"ltp":2.2,"tv":5.5,"id":61077258}]}]}
{"op":"mcm","clk":"11926252057","pt":1724552270959,"mc":[{"id":"1.232224347","rc":[{"batb":[[0,2.08,39.76],[1,1.21,24.75],[2,1.12,1.76]],"ltp":2.2,"tv":5.5,"id":61077258}]}]}
{"op":"mcm","clk":"11926252189","pt":1724552273173,"mc":[{"id":"1.232224347","rc":[{"batb":[[0,2.1,5],[1,2.08,39.76],[2,1.21,24.75]],"ltp":2.2,"tv":5.5,"id":61077258}]}]}
{"op":"mcm","clk":"11926252387","pt":1724552276490,"mc":[{"id":"1.232224347","rc":[{"batb":[[0,2.08,39.76],[1,1.21,24.75],[2,1.12,1.76]],"ltp":2.2,"tv":5.5,"id":61077258}]}]}
{"op":"mcm","clk":"11926252632","pt":1724552280574,"mc":[{"id":"1.232224347","rc":[{"batb":[[0,2.1,5],[1,2.08,39.76],[2,1.21,24.75]],"ltp":2.2,"tv":5.5,"id":61077258}]}]}
{"op":"mcm","clk":"11926252874","pt":1724552283890,"mc":[{"id":"1.232224347","rc":[{"batb":[[0,2.08,39.76],[1,1.21,24.75],[2,1.12,1.76]],"ltp":2.2,"tv":5.5,"id":61077258}]}]}
{"op":"mcm","clk":"11926253025","pt":1724552286072,"mc":[{"id":"1.232224347","rc":[{"batb":[[0,2.1,5],[1,2.08,39.76],[2,1.21,24.75]],"ltp":2.2,"tv":5.5,"id":61077258}]}]}
{"op":"mcm","clk":"11926253230","pt":1724552289378,"mc":[{"id":"1.232224347","rc":[{"batb":[[0,2.08,39.76],[1,1.21,24.75],[2,1.12,1.76]],"ltp":2.2,"tv":5.5,"id":61077258}]}]}
{"op":"mcm","clk":"11926253398","pt":1724552292595,"mc":[{"id":"1.232224347","rc":[{"batb":[[0,2.1,5],[1,2.08,39.76],[2,1.21,24.75]],"ltp":2.2,"tv":5.5,"id":61077258}]}]}
{"op":"mcm","clk":"11926253576","pt":1724552295903,"mc":[{"id":"1.232224347","rc":[{"batb":[[0,2.08,39.76],[1,1.21,24.75],[2,1.12,1.76]],"ltp":2.2,"tv":5.5,"id":61077258}]}]}
{"op":"mcm","clk":"11926253712","pt":1724552298126,"mc":[{"id":"1.232224347","rc":[{"batb":[[0,2.1,5],[1,2.08,39.76],[2,1.21,24.75]],"ltp":2.2,"tv":5.5,"id":61077258}]}]}
{"op":"mcm","clk":"11926253877","pt":1724552301388,"mc":[{"id":"1.232224347","rc":[{"batb":[[0,2.08,39.76],[1,1.21,24.75],[2,1.12,1.76]],"ltp":2.2,"tv":5.5,"id":61077258}]}]}
{"op":"mcm","clk":"11926254117","pt":1724552305618,"mc":[{"id":"1.232224347","rc":[{"batb":[[0,2.1,5],[1,2.08,39.76],[2,1.21,24.75]],"ltp":2.2,"tv":5.5,"id":61077258}]}]}
{"op":"mcm","clk":"11926254329","pt":1724552308918,"mc":[{"id":"1.232224347","rc":[{"batb":[[0,2.08,39.76],[1,1.21,24.75],[2,1.12,1.76]],"ltp":2.2,"tv":5.5,"id":61077258}]}]}
{"op":"mcm","clk":"11926254475","pt":1724552311130,"mc":[{"id":"1.232224347","rc":[{"batb":[[0,2.1,5],[1,2.08,39.76],[2,1.21,24.75]],"ltp":2.2,"tv":5.5,"id":61077258}]}]}
{"op":"mcm","clk":"11926254665","pt":1724552314434,"mc":[{"id":"1.232224347","rc":[{"batb":[[0,2.08,39.76],[1,1.21,24.75],[2,1.12,1.76]],"ltp":2.2,"tv":5.5,"id":61077258}]}]}
{"op":"mcm","clk":"11926254817","pt":1724552316719,"mc":[{"id":"1.232224347","rc":[{"batb":[[0,2.1,5],[1,2.08,39.76],[2,1.21,24.75]],"ltp":2.2,"tv":5.5,"id":61077258}]}]}
{"op":"mcm","clk":"11926254998","pt":1724552319927,"mc":[{"id":"1.232224347","rc":[{"batb":[[0,2.08,39.76],[1,1.21,24.75],[2,1.12,1.76]],"ltp":2.2,"tv":5.5,"id":61077258}]}]}
{"op":"mcm","clk":"11926255125","pt":1724552322448,"mc":[{"id":"1.232224347","rc":[{"batb":[[0,2.1,5],[1,2.08,39.76],[2,1.21,24.75]],"ltp":2.2,"tv":5.5,"id":61077258}]}]}
{"op":"mcm","clk":"11926255308","pt":1724552325754,"mc":[{"id":"1.232224347","rc":[{"batb":[[0,2.08,39.76],[1,1.21,24.75],[2,1.12,1.76]],"ltp":2.2,"tv":5.5,"id":61077258}]}]}
{"op":"mcm","clk":"11926255419","pt":1724552327927,"mc":[{"id":"1.232224347","rc":[{"batb":[[0,2.1,5],[1,2.08,39.76],[2,1.21,24.75]],"ltp":2.2,"tv":5.5,"id":61077258}]}]}
{"op":"mcm","clk":"11926255573","pt":1724552331326,"mc":[{"id":"1.232224347","rc":[{"batb":[[0,2.08,39.76],[1,1.21,24.75],[2,1.12,1.76]],"ltp":2.2,"tv":5.5,"id":61077258}]}]}
{"op":"mcm","clk":"11926255744","pt":1724552334639,"mc":[{"id":"1.232224347","rc":[{"batb":[[0,2.1,5],[1,2.08,39.76],[2,1.21,24.75]],"ltp":2.2,"tv":5.5,"id":61077258}]}]}
{"op":"mcm","clk":"11926255961","pt":1724552337939,"mc":[{"id":"1.232224347","rc":[{"batb":[[0,2.08,39.76],[1,1.21,24.75],[2,1.12,1.76]],"ltp":2.2,"tv":5.5,"id":61077258}]}]}
{"op":"mcm","clk":"11926256100","pt":1724552340366,"mc":[{"id":"1.232224347","rc":[{"batb":[[0,2.1,5],[1,2.08,39.76],[2,1.21,24.75]],"ltp":2.2,"tv":5.5,"id":61077258}]}]}
{"op":"mcm","clk":"11926256308","pt":1724552343666,"mc":[{"id":"1.232224347","rc":[{"batb":[[0,2.08,39.76],[1,1.21,24.75],[2,1.12,1.76]],"ltp":2.2,"tv":5.5,"id":61077258}]}]}
{"op":"mcm","clk":"11926256480","pt":1724552346777,"mc":[{"id":"1.232224347","rc":[{"batb":[[0,2.1,5],[1,2.08,39.76],[2,1.21,24.75]],"ltp":2.2,"tv":5.5,"id":61077258}]}]}
{"op":"mcm","clk":"11926256674","pt":1724552349941,"mc":[{"id":"1.232224347","rc":[{"batb":[[0,2.08,39.76],[1,1.21,24.75],[2,1.12,1.76]],"ltp":2.2,"tv":5.5,"id":61077258}]}]}
{"op":"mcm","clk":"11926256806","pt":1724552352260,"mc":[{"id":"1.232224347","rc":[{"batb":[[0,2.1,5],[1,2.08,39.76],[2,1.21,24.75]],"ltp":2.2,"tv":5.5,"id":61077258}]}]}
{"op":"mcm","clk":"11926256991","pt":1724552355672,"mc":[{"id":"1.232224347","rc":[{"batb":[[0,2.08,39.76],[1,1.21,24.75],[2,1.12,1.76]],"ltp":2.2,"tv":5.5,"id":61077258}]}]}
{"op":"mcm","clk":"11926257190","pt":1724552359078,"mc":[{"id":"1.232224347","rc":[{"batb":[[0,2.1,5],[1,2.08,39.76],[2,1.21,24.75]],"ltp":2.2,"tv":5.5,"id":61077258}]}]}
{"op":"mcm","clk":"11926257375","pt":1724552362251,"mc":[{"id":"1.232224347","rc":[{"batb":[[0,2.08,39.76],[1,1.21,24.75],[2,1.12,1.76]],"ltp":2.2,"tv":5.5,"id":61077258}]}]}
{"op":"mcm","clk":"11926257508","pt":1724552364470,"mc":[{"id":"1.232224347","rc":[{"batb":[[0,2.1,5],[1,2.08,39.76],[2,1.21,24.75]],"ltp":2.2,"tv":5.5,"id":61077258}]}]}
{"op":"mcm","clk":"11926257711","pt":1724552368083,"mc":[{"id":"1.232224347","rc":[{"batb":[[0,2.08,39.76],[1,1.21,24.75],[2,1.12,1.76]],"ltp":2.2,"tv":5.5,"id":61077258}]}]}
{"op":"mcm","clk":"11926257841","pt":1724552370497,"mc":[{"id":"1.232224347","rc":[{"batb":[[0,2.1,5],[1,2.08,39.76],[2,1.21,24.75]],"ltp":2.2,"tv":5.5,"id":61077258}]}]}
{"op":"mcm","clk":"11926258036","pt":1724552373901,"mc":[{"id":"1.232224347","rc":[{"batb":[[0,2.08,39.76],[1,1.21,24.75],[2,1.12,1.76]],"ltp":2.2,"tv":5.5,"id":61077258}]}]}
{"op":"mcm","clk":"11926258213","pt":1724552377203,"mc":[{"id":"1.232224347","rc":[{"batb":[[0,2.1,5],[1,2.08,39.76],[2,1.21,24.75]],"ltp":2.2,"tv":5.5,"id":61077258}]}]}
{"op":"mcm","clk":"11926258421","pt":1724552380515,"mc":[{"id":"1.232224347","rc":[{"batb":[[0,2.08,39.76],[1,1.21,24.75],[2,1.12,1.76]],"ltp":2.2,"tv":5.5,"id":61077258}]}]}
{"op":"mcm","clk":"11926258757","pt":1724552385796,"mc":[{"id":"1.232224347","rc":[{"batb":[[0,2.1,5],[1,2.08,39.76],[2,1.21,24.75]],"ltp":2.2,"tv":5.5,"id":61077258}]}]}
{"op":"mcm","clk":"11926258942","pt":1724552388989,"mc":[{"id":"1.232224347","rc":[{"batb":[[0,2.08,39.76],[1,1.21,24.75],[2,1.12,1.76]],"ltp":2.2,"tv":5.5,"id":61077258}]}]}
{"op":"mcm","clk":"11926259061","pt":1724552391204,"mc":[{"id":"1.232224347","rc":[{"batb":[[0,2.1,5],[1,2.08,39.76],[2,1.21,24.75]],"ltp":2.2,"tv":5.5,"id":61077258}]}]}
{"op":"mcm","clk":"11926259246","pt":1724552394497,"mc":[{"id":"1.232224347","rc":[{"batb":[[0,2.08,39.76],[1,1.21,24.75],[2,1.12,1.76]],"ltp":2.2,"tv":5.5,"id":61077258}]}]}
{"op":"mcm","clk":"11926259424","pt":1724552397390,"mc":[{"id":"1.232224347","rc":[{"batb":[[0,2.1,5],[1,2.08,39.76],[2,1.21,24.75]],"ltp":2.2,"tv":5.5,"id":61077258}]}]}
{"op":"mcm","clk":"11926259605","pt":1724552400591,"mc":[{"id":"1.232224347","rc":[{"batb":[[0,2.08,39.76],[1,1.21,24.75],[2,1.12,1.76]],"ltp":2.2,"tv":5.5,"id":61077258}]}]}
{"op":"mcm","clk":"11926259746","pt":1724552402813,"mc":[{"id":"1.232224347","rc":[{"batb":[[0,2.1,5],[1,2.08,39.76],[2,1.21,24.75]],"ltp":2.2,"tv":5.5,"id":61077258}]}]}
{"op":"mcm","clk":"11926259964","pt":1724552406134,"mc":[{"id":"1.232224347","rc":[{"batb":[[0,2.08,39.76],[1,1.21,24.75],[2,1.12,1.76]],"ltp":2.2,"tv":5.5,"id":61077258}]}]}
{"op":"mcm","clk":"11926260156","pt":1724552409127,"mc":[{"id":"1.232224347","rc":[{"batb":[[0,2.1,5],[1,2.08,39.76],[2,1.21,24.75]],"ltp":2.2,"tv":5.5,"id":61077258}]}]}
{"op":"mcm","clk":"11926260329","pt":1724552412356,"mc":[{"id":"1.232224347","rc":[{"batb":[[0,2.08,39.76],[1,1.21,24.75],[2,1.12,1.76]],"ltp":2.2,"tv":5.5,"id":61077258}]}]}
{"op":"mcm","clk":"11926260501","pt":1724552415513,"mc":[{"id":"1.232224347","rc":[{"batb":[[0,2.1,5],[1,2.08,39.76],[2,1.21,24.75]],"ltp":2.2,"tv":5.5,"id":61077258}]}]}
{"op":"mcm","clk":"11926260722","pt":1724552419046,"mc":[{"id":"1.232224347","rc":[{"batb":[[0,2.08,39.76],[1,1.21,24.75],[2,1.12,1.76]],"ltp":2.2,"tv":5.5,"id":61077258}]}]}
{"op":"mcm","clk":"11926260846","pt":1724552421328,"mc":[{"id":"1.232224347","rc":[{"batb":[[0,2.1,5],[1,2.08,39.76],[2,1.21,24.75]],"ltp":2.2,"tv":5.5,"id":61077258}]}]}
{"op":"mcm","clk":"11926261054","pt":1724552424733,"mc":[{"id":"1.232224347","rc":[{"batb":[[0,2.08,39.76],[1,1.21,24.75],[2,1.12,1.76]],"ltp":2.2,"tv":5.5,"id":61077258}]}]}
{"op":"mcm","clk":"11926261169","pt":1724552426846,"mc":[{"id":"1.232224347","rc":[{"batb":[[0,2.1,5],[1,2.08,39.76],[2,1.21,24.75]],"ltp":2.2,"tv":5.5,"id":61077258}]}]}
{"op":"mcm","clk":"11926261527","pt":1724552432631,"mc":[{"id":"1.232224347","rc":[{"batb":[[0,2.08,39.76],[1,1.21,24.75],[2,1.12,1.76]],"ltp":2.2,"tv":5.5,"id":61077258}]}]}
{"op":"mcm","clk":"11926261677","pt":1724552434866,"mc":[{"id":"1.232224347","rc":[{"batb":[[0,2.1,5],[1,2.08,39.76],[2,1.21,24.75]],"ltp":2.2,"tv":5.5,"id":61077258}]}]}
{"op":"mcm","clk":"11926261878","pt":1724552438167,"mc":[{"id":"1.232224347","rc":[{"batb":[[0,2.08,39.76],[1,1.21,24.75],[2,1.12,1.76]],"ltp":2.2,"tv":5.5,"id":61077258}]}]}
{"op":"mcm","clk":"11926262011","pt":1724552440338,"mc":[{"id":"1.232224347","rc":[{"batb":[[0,2.1,5],[1,2.08,39.76],[2,1.21,24.75]],"ltp":2.2,"tv":5.5,"id":61077258}]}]}
{"op":"mcm","clk":"11926262182","pt":1724552443667,"mc":[{"id":"1.232224347","rc":[{"batb":[[0,2.08,39.76],[1,1.21,24.75],[2,1.12,1.76]],"ltp":2.2,"tv":5.5,"id":61077258}]}]}
{"op":"mcm","clk":"11926262388","pt":1724552447278,"mc":[{"id":"1.232224347","rc":[{"batb":[[0,2.1,5],[1,2.08,39.76],[2,1.21,24.75]],"ltp":2.2,"tv":5.5,"id":61077258}]}]}
{"op":"mcm","clk":"11926262560","pt":1724552450539,"mc":[{"id":"1.232224347","rc":[{"batb":[[0,2.08,39.76],[1,1.21,24.75],[2,1.12,1.76]],"ltp":2.2,"tv":5.5,"id":61077258}]}]}
{"op":"mcm","clk":"11926262677","pt":1724552452747,"mc":[{"id":"1.232224347","rc":[{"batb":[[0,2.1,5],[1,2.08,39.76],[2,1.21,24.75]],"ltp":2.2,"tv":5.5,"id":61077258}]}]}
{"op":"mcm","clk":"11926262850","pt":1724552456150,"mc":[{"id":"1.232224347","rc":[{"batb":[[0,2.08,39.76],[1,1.21,24.75],[2,1.12,1.76]],"ltp":2.2,"tv":5.5,"id":61077258}]}]}
{"op":"mcm","clk":"11926262960","pt":1724552458368,"mc":[{"id":"1.232224347","rc":[{"batb":[[0,2.1,5],[1,2.08,39.76],[2,1.21,24.75]],"ltp":2.2,"tv":5.5,"id":61077258}]}]}
{"op":"mcm","clk":"11926263157","pt":1724552461657,"mc":[{"id":"1.232224347","rc":[{"batb":[[0,2.08,39.76],[1,1.21,24.75],[2,1.12,1.76]],"ltp":2.2,"tv":5.5,"id":61077258}]}]}
{"op":"mcm","clk":"11926263298","pt":1724552463873,"mc":[{"id":"1.232224347","rc":[{"batb":[[0,2.1,5],[1,2.08,39.76],[2,1.21,24.75]],"ltp":2.2,"tv":5.5,"id":61077258}]}]}
{"op":"mcm","clk":"11926263474","pt":1724552467167,"mc":[{"id":"1.232224347","rc":[{"batb":[[0,2.08,39.76],[1,1.21,24.75],[2,1.12,1.76]],"ltp":2.2,"tv":5.5,"id":61077258}]}]}
{"op":"mcm","clk":"11926263604","pt":1724552469390,"mc":[{"id":"1.232224347","rc":[{"batb":[[0,2.1,5],[1,2.08,39.76],[2,1.21,24.75]],"ltp":2.2,"tv":5.5,"id":61077258}]}]}
{"op":"mcm","clk":"11926263787","pt":1724552472893,"mc":[{"id":"1.232224347","rc":[{"batb":[[0,2.08,39.76],[1,1.21,24.75],[2,1.12,1.76]],"ltp":2.2,"tv":5.5,"id":61077258}]}]}
{"op":"mcm","clk":"11926263965","pt":1724552475587,"mc":[{"id":"1.232224347","rc":[{"batb":[[0,2.1,5],[1,2.08,39.76],[2,1.21,24.75]],"ltp":2.2,"tv":5.5,"id":61077258}]}]}
{"op":"mcm","clk":"11926264146","pt":1724552478877,"mc":[{"id":"1.232224347","rc":[{"batb":[[0,2.08,39.76],[1,1.21,24.75],[2,1.12,1.76]],"ltp":2.2,"tv":5.5,"id":61077258}]}]}
{"op":"mcm","clk":"11926264323","pt":1724552481503,"mc":[{"id":"1.232224347","rc":[{"batb":[[0,2.1,5],[1,2.08,39.76],[2,1.21,24.75]],"ltp":2.2,"tv":5.5,"id":61077258}]}]}
{"op":"mcm","clk":"11926264478","pt":1724552484798,"mc":[{"id":"1.232224347","rc":[{"batb":[[0,2.08,39.76],[1,1.21,24.75],[2,1.12,1.76]],"ltp":2.2,"tv":5.5,"id":61077258}]}]}
{"op":"mcm","clk":"11926264668","pt":1724552488013,"mc":[{"id":"1.232224347","rc":[{"batb":[[0,2.1,5],[1,2.08,39.76],[2,1.21,24.75]],"ltp":2.2,"tv":5.5,"id":61077258}]}]}
{"op":"mcm","clk":"11926264863","pt":1724552491408,"mc":[{"id":"1.232224347","rc":[{"batb":[[0,2.08,39.76],[1,1.21,24.75],[2,1.12,1.76]],"ltp":2.2,"tv":5.5,"id":61077258}]}]}
{"op":"mcm","clk":"11926265033","pt":1724552494605,"mc":[{"id":"1.232224347","rc":[{"batb":[[0,2.1,5],[1,2.08,39.76],[2,1.21,24.75]],"ltp":2.2,"tv":5.5,"id":61077258}]}]}
{"op":"mcm","clk":"11926265236","pt":1724552497915,"mc":[{"id":"1.232224347","rc":[{"batb":[[0,2.08,39.76],[1,1.21,24.75],[2,1.12,1.76]],"ltp":2.2,"tv":5.5,"id":61077258}]}]}
{"op":"mcm","clk":"11926265356","pt":1724552500238,"mc":[{"id":"1.232224347","rc":[{"batb":[[0,2.1,5],[1,2.08,39.76],[2,1.21,24.75]],"ltp":2.2,"tv":5.5,"id":61077258}]}]}
{"op":"mcm","clk":"11926265527","pt":1724552503504,"mc":[{"id":"1.232224347","rc":[{"batb":[[0,2.08,39.76],[1,1.21,24.75],[2,1.12,1.76]],"ltp":2.2,"tv":5.5,"id":61077258}]}]}
{"op":"mcm","clk":"11926265648","pt":1724552506229,"mc":[{"id":"1.232224347","rc":[{"batb":[[0,2.1,5],[1,2.08,39.76],[2,1.21,24.75]],"ltp":2.2,"tv":5.5,"id":61077258}]}]}
{"op":"mcm","clk":"11926265807","pt":1724552509529,"mc":[{"id":"1.232224347","rc":[{"batb":[[0,2.08,39.76],[1,1.21,24.75],[2,1.12,1.76]],"ltp":2.2,"tv":5.5,"id":61077258}]}]}
{"op":"mcm","clk":"11926266003","pt":1724552512830,"mc":[{"id":"1.232224347","rc":[{"batb":[[0,2.1,5],[1,2.08,39.76],[2,1.21,24.75]],"ltp":2.2,"tv":5.5,"id":61077258}]}]}
{"op":"mcm","clk":"11926266195","pt":1724552516023,"mc":[{"id":"1.232224347","rc":[{"batb":[[0,2.08,39.76],[1,1.21,24.75],[2,1.12,1.76]],"ltp":2.2,"tv":5.5,"id":61077258}]}]}
{"op":"mcm","clk":"11926266347","pt":1724552518720,"mc":[{"id":"1.232224347","rc":[{"batb":[[0,2.1,5],[1,2.08,39.76],[2,1.21,24.75]],"ltp":2.2,"tv":5.5,"id":61077258}]}]}
{"op":"mcm","clk":"11926266541","pt":1724552522028,"mc":[{"id":"1.232224347","rc":[{"batb":[[0,2.08,39.76],[1,1.21,24.75],[2,1.12,1.76]],"ltp":2.2,"tv":5.5,"id":61077258}]}]}
{"op":"mcm","clk":"11926266684","pt":1724552524248,"mc":[{"id":"1.232224347","rc":[{"batb":[[0,2.1,5],[1,2.08,39.76],[2,1.21,24.75]],"ltp":2.2,"tv":5.5,"id":61077258}]}]}
{"op":"mcm","clk":"11926266911","pt":1724552527653,"mc":[{"id":"1.232224347","rc":[{"batb":[[0,2.08,39.76],[1,1.21,24.75],[2,1.12,1.76]],"ltp":2.2,"tv":5.5,"id":61077258}]}]}
{"op":"mcm","clk":"11926267085","pt":1724552530751,"mc":[{"id":"1.232224347","rc":[{"batb":[[0,2.1,5],[1,2.08,39.76],[2,1.21,24.75]],"ltp":2.2,"tv":5.5,"id":61077258}]}]}
{"op":"mcm","clk":"11926267261","pt":1724552534049,"mc":[{"id":"1.232224347","rc":[{"batb":[[0,2.08,39.76],[1,1.21,24.75],[2,1.12,1.76]],"ltp":2.2,"tv":5.5,"id":61077258}]}]}
{"op":"mcm","clk":"11926267433","pt":1724552536839,"mc":[{"id":"1.232224347","rc":[{"batb":[[0,2.1,5],[1,2.08,39.76],[2,1.21,24.75]],"ltp":2.2,"tv":5.5,"id":61077258}]}]}
{"op":"mcm","clk":"11926267628","pt":1724552540135,"mc":[{"id":"1.232224347","rc":[{"batb":[[0,2.08,39.76],[1,1.21,24.75],[2,1.12,1.76]],"ltp":2.2,"tv":5.5,"id":61077258}]}]}
{"op":"mcm","clk":"11926267747","pt":1724552542255,"mc":[{"id":"1.232224347","rc":[{"batb":[[0,2.1,5],[1,2.08,39.76],[2,1.21,24.75]],"ltp":2.2,"tv":5.5,"id":61077258}]}]}
{"op":"mcm","clk":"11926267939","pt":1724552545570,"mc":[{"id":"1.232224347","rc":[{"batb":[[0,2.08,39.76],[1,1.21,24.75],[2,1.12,1.76]],"ltp":2.2,"tv":5.5,"id":61077258}]}]}
{"op":"mcm","clk":"11926268111","pt":1724552548360,"mc":[{"id":"1.232224347","rc":[{"batb":[[0,2.1,5],[1,2.08,39.76],[2,1.21,24.75]],"ltp":2.2,"tv":5.5,"id":61077258}]}]}
{"op":"mcm","clk":"11926268275","pt":1724552551772,"mc":[{"id":"1.232224347","rc":[{"batb":[[0,2.08,39.76],[1,1.21,24.75],[2,1.12,1.76]],"ltp":2.2,"tv":5.5,"id":61077258}]}]}
{"op":"mcm","clk":"11926268365","pt":1724552553945,"mc":[{"id":"1.232224347","rc":[{"batb":[[0,2.1,5],[1,2.08,39.76],[2,1.21,24.75]],"ltp":2.2,"tv":5.5,"id":61077258}]}]}
{"op":"mcm","clk":"11926268502","pt":1724552557251,"mc":[{"id":"1.232224347","rc":[{"batb":[[0,2.08,39.76],[1,1.21,24.75],[2,1.12,1.76]],"ltp":2.2,"tv":5.5,"id":61077258}]}]}
{"op":"mcm","clk":"11926268621","pt":1724552559474,"mc":[{"id":"1.232224347","rc":[{"batb":[[0,2.1,5],[1,2.08,39.76],[2,1.21,24.75]],"ltp":2.2,"tv":5.5,"id":61077258}]}]}
{"op":"mcm","clk":"11926268775","pt":1724552562757,"mc":[{"id":"1.232224347","rc":[{"batb":[[0,2.08,39.76],[1,1.21,24.75],[2,1.12,1.76]],"ltp":2.2,"tv":5.5,"id":61077258}]}]}
{"op":"mcm","clk":"11926268978","pt":1724552566779,"mc":[{"id":"1.232224347","rc":[{"batb":[[0,2.1,5],[1,2.08,39.76],[2,1.21,24.75]],"ltp":2.2,"tv":5.5,"id":61077258}]}]}
{"op":"mcm","clk":"11926269160","pt":1724552570277,"mc":[{"id":"1.232224347","rc":[{"batb":[[0,2.08,39.76],[1,1.21,24.75],[2,1.12,1.76]],"ltp":2.2,"tv":5.5,"id":61077258}]}]}
{"op":"mcm","clk":"11926269257","pt":1724552572794,"mc":[{"id":"1.232224347","rc":[{"batb":[[0,2.1,5],[1,2.08,39.76],[2,1.21,24.75]],"ltp":2.2,"tv":5.5,"id":61077258}]}]}
{"op":"mcm","clk":"11926269372","pt":1724552575987,"mc":[{"id":"1.232224347","rc":[{"batb":[[0,2.08,39.76],[1,1.21,24.75],[2,1.12,1.76]],"ltp":2.2,"tv":5.5,"id":61077258}]}]}
{"op":"mcm","clk":"11926269495","pt":1724552578884,"mc":[{"id":"1.232224347","rc":[{"batb":[[0,2.1,5],[1,2.08,39.76],[2,1.21,24.75]],"ltp":2.2,"tv":5.5,"id":61077258}]}]}
{"op":"mcm","clk":"11926269670","pt":1724552582182,"mc":[{"id":"1.232224347","rc":[{"batb":[[0,2.08,39.76],[1,1.21,24.75],[2,1.12,1.76]],"ltp":2.2,"tv":5.5,"id":61077258}]}]}
{"op":"mcm","clk":"11926269886","pt":1724552586212,"mc":[{"id":"1.232224347","rc":[{"batb":[[0,2.1,5],[1,2.08,39.76],[2,1.21,24.75]],"ltp":2.2,"tv":5.5,"id":61077258}]}]}
{"op":"mcm","clk":"11926270053","pt":1724552589516,"mc":[{"id":"1.232224347","rc":[{"batb":[[0,2.08,39.76],[1,1.21,24.75],[2,1.12,1.76]],"ltp":2.2,"tv":5.5,"id":61077258}]}]}
{"op":"mcm","clk":"11926270200","pt":1724552592600,"mc":[{"id":"1.232224347","rc":[{"batb":[[0,2.1,5],[1,2.08,39.76],[2,1.21,24.75]],"ltp":2.2,"tv":5.5,"id":61077258}]}]}
{"op":"mcm","clk":"11926270359","pt":1724552595903,"mc":[{"id":"1.232224347","rc":[{"batb":[[0,2.08,39.76],[1,1.21,24.75],[2,1.12,1.76]],"ltp":2.2,"tv":5.5,"id":61077258}]}]}
{"op":"mcm","clk":"11926270478","pt":1724552598322,"mc":[{"id":"1.232224347","rc":[{"batb":[[0,2.1,5],[1,2.08,39.76],[2,1.21,24.75]],"ltp":2.2,"tv":5.5,"id":61077258}]}]}
{"op":"mcm","clk":"11926270639","pt":1724552601720,"mc":[{"id":"1.232224347","rc":[{"batb":[[0,2.08,39.76],[1,1.21,24.75],[2,1.12,1.76]],"ltp":2.2,"tv":5.5,"id":61077258}]}]}
{"op":"mcm","clk":"11926270792","pt":1724552605016,"mc":[{"id":"1.232224347","rc":[{"batb":[[0,2.1,5],[1,2.08,39.76],[2,1.21,24.75]],"ltp":2.2,"tv":5.5,"id":61077258}]}]}
{"op":"mcm","clk":"11926270944","pt":1724552608319,"mc":[{"id":"1.232224347","rc":[{"batb":[[0,2.08,39.76],[1,1.21,24.75],[2,1.12,1.76]],"ltp":2.2,"tv":5.5,"id":61077258}]}]}
{"op":"mcm","clk":"11926271040","pt":1724552611240,"mc":[{"id":"1.232224347","rc":[{"batb":[[0,2.1,5],[1,2.08,39.76],[2,1.21,24.75]],"ltp":2.2,"tv":5.5,"id":61077258}]}]}
{"op":"mcm","clk":"11926271222","pt":1724552614435,"mc":[{"id":"1.232224347","rc":[{"batb":[[0,2.08,39.76],[1,1.21,24.75],[2,1.12,1.76]],"ltp":2.2,"tv":5.5,"id":61077258}]}]}
{"op":"mcm","clk":"11926271346","pt":1724552616832,"mc":[{"id":"1.232224347","rc":[{"batb":[[0,2.1,5],[1,2.08,39.76],[2,1.21,24.75]],"ltp":2.2,"tv":5.5,"id":61077258}]}]}
{"op":"mcm","clk":"11926271487","pt":1724552620122,"mc":[{"id":"1.232224347","rc":[{"batb":[[0,2.08,39.76],[1,1.21,24.75],[2,1.12,1.76]],"ltp":2.2,"tv":5.5,"id":61077258}]}]}
{"op":"mcm","clk":"11926271594","pt":1724552622839,"mc":[{"id":"1.232224347","rc":[{"batb":[[0,2.1,5],[1,2.08,39.76],[2,1.21,24.75]],"ltp":2.2,"tv":5.5,"id":61077258}]}]}
{"op":"mcm","clk":"11926271760","pt":1724552626154,"mc":[{"id":"1.232224347","rc":[{"batb":[[0,2.08,39.76],[1,1.21,24.75],[2,1.12,1.76]],"ltp":2.2,"tv":5.5,"id":61077258}]}]}
{"op":"mcm","clk":"11926271913","pt":1724552629243,"mc":[{"id":"1.232224347","rc":[{"batb":[[0,2.1,5],[1,2.08,39.76],[2,1.21,24.75]],"ltp":2.2,"tv":5.5,"id":61077258}]}]}
{"op":"mcm","clk":"11926272072","pt":1724552632432,"mc":[{"id":"1.232224347","rc":[{"batb":[[0,2.08,39.76],[1,1.21,24.75],[2,1.12,1.76]],"ltp":2.2,"tv":5.5,"id":61077258}]}]}
{"op":"mcm","clk":"11926272185","pt":1724552634847,"mc":[{"id":"1.232224347","rc":[{"batb":[[0,2.1,5],[1,2.08,39.76],[2,1.21,24.75]],"ltp":2.2,"tv":5.5,"id":61077258}]}]}
{"op":"mcm","clk":"11926272353","pt":1724552638239,"mc":[{"id":"1.232224347","rc":[{"batb":[[0,2.08,39.76],[1,1.21,24.75],[2,1.12,1.76]],"ltp":2.2,"tv":5.5,"id":61077258}]}]}
{"op":"mcm","clk":"11926272537","pt":1724552641070,"mc":[{"id":"1.232224347","rc":[{"batb":[[0,2.1,5],[1,2.08,39.76],[2,1.21,24.75]],"ltp":2.2,"tv":5.5,"id":61077258}]}]}
{"op":"mcm","clk":"11926272729","pt":1724552644260,"mc":[{"id":"1.232224347","rc":[{"batb":[[0,2.08,39.76],[1,1.21,24.75],[2,1.12,1.76]],"ltp":2.2,"tv":5.5,"id":61077258}]}]}
{"op":"mcm","clk":"11926272859","pt":1724552646577,"mc":[{"id":"1.232224347","rc":[{"batb":[[0,2.1,5],[1,2.08,39.76],[2,1.21,24.75]],"ltp":2.2,"tv":5.5,"id":61077258}]}]}
{"op":"mcm","clk":"11926273034","pt":1724552649767,"mc":[{"id":"1.232224347","rc":[{"batb":[[0,2.08,39.76],[1,1.21,24.75],[2,1.12,1.76]],"ltp":2.2,"tv":5.5,"id":61077258}]}]}
{"op":"mcm","clk":"11926273208","pt":1724552653069,"mc":[{"id":"1.232224347","rc":[{"batb":[[0,2.1,5],[1,2.08,39.76],[2,1.21,24.75]],"ltp":2.2,"tv":5.5,"id":61077258}]}]}
{"op":"mcm","clk":"11926273359","pt":1724552656265,"mc":[{"id":"1.232224347","rc":[{"batb":[[0,2.08,39.76],[1,1.21,24.75],[2,1.12,1.76]],"ltp":2.2,"tv":5.5,"id":61077258}]}]}
{"op":"mcm","clk":"11926273758","pt":1724552662870,"mc":[{"id":"1.232224347","rc":[{"batb":[[0,2.1,5],[1,2.08,39.76],[2,1.21,24.75]],"ltp":2.2,"tv":5.5,"id":61077258}]}]}
{"op":"mcm","clk":"11926273950","pt":1724552666174,"mc":[{"id":"1.232224347","rc":[{"batb":[[0,2.08,39.76],[1,1.21,24.75],[2,1.12,1.76]],"ltp":2.2,"tv":5.5,"id":61077258}]}]}
{"op":"mcm","clk":"11926274064","pt":1724552669103,"mc":[{"id":"1.232224347","rc":[{"batb":[[0,2.1,5],[1,2.08,39.76],[2,1.21,24.75]],"ltp":2.2,"tv":5.5,"id":61077258}]}]}
{"op":"mcm","clk":"11926274261","pt":1724552672297,"mc":[{"id":"1.232224347","rc":[{"batb":[[0,2.08,39.76],[1,1.21,24.75],[2,1.12,1.76]],"ltp":2.2,"tv":5.5,"id":61077258}]}]}
{"op":"mcm","clk":"11926274412","pt":1724552674798,"mc":[{"id":"1.232224347","rc":[{"batb":[[0,2.1,5],[1,2.08,39.76],[2,1.21,24.75]],"ltp":2.2,"tv":5.5,"id":61077258}]}]}
{"op":"mcm","clk":"11926274607","pt":1724552677994,"mc":[{"id":"1.232224347","rc":[{"batb":[[0,2.08,39.76],[1,1.21,24.75],[2,1.12,1.76]],"ltp":2.2,"tv":5.5,"id":61077258}]}]}
{"op":"mcm","clk":"11926274784","pt":1724552680919,"mc":[{"id":"1.232224347","rc":[{"batb":[[0,2.1,5],[1,2.08,39.76],[2,1.21,24.75]],"ltp":2.2,"tv":5.5,"id":61077258}]}]}
{"op":"mcm","clk":"11926274977","pt":1724552684191,"mc":[{"id":"1.232224347","rc":[{"batb":[[0,2.08,39.76],[1,1.21,24.75],[2,1.12,1.76]],"ltp":2.2,"tv":5.5,"id":61077258}]}]}
{"op":"mcm","clk":"11926275106","pt":1724552686414,"mc":[{"id":"1.232224347","rc":[{"batb":[[0,2.1,5],[1,2.08,39.76],[2,1.21,24.75]],"ltp":2.2,"tv":5.5,"id":61077258}]}]}
{"op":"mcm","clk":"11926275281","pt":1724552689621,"mc":[{"id":"1.232224347","rc":[{"batb":[[0,2.08,39.76],[1,1.21,24.75],[2,1.12,1.76]],"ltp":2.2,"tv":5.5,"id":61077258}]}]}
{"op":"mcm","clk":"11926275435","pt":1724552692111,"mc":[{"id":"1.232224347","rc":[{"batb":[[0,2.1,5],[1,2.08,39.76],[2,1.21,24.75]],"ltp":2.2,"tv":5.5,"id":61077258}]}]}
{"op":"mcm","clk":"11926275588","pt":1724552695303,"mc":[{"id":"1.232224347","rc":[{"batb":[[0,2.08,39.76],[1,1.21,24.75],[2,1.12,1.76]],"ltp":2.2,"tv":5.5,"id":61077258}]}]}
{"op":"mcm","clk":"11926275808","pt":1724552699408,"mc":[{"id":"1.232224347","rc":[{"batb":[[0,2.1,5],[1,2.08,39.76],[2,1.21,24.75]],"ltp":2.2,"tv":5.5,"id":61077258}]}]}
{"op":"mcm","clk":"11926276037","pt":1724552702636,"mc":[{"id":"1.232224347","rc":[{"batb":[[0,2.08,39.76],[1,1.21,24.75],[2,1.12,1.76]],"ltp":2.2,"tv":5.5,"id":61077258}]}]}
{"op":"mcm","clk":"11926276197","pt":1724552705021,"mc":[{"id":"1.232224347","rc":[{"batb":[[0,2.1,5],[1,2.08,39.76],[2,1.21,24.75]],"ltp":2.2,"tv":5.5,"id":61077258}]}]}
{"op":"mcm","clk":"11926276399","pt":1724552708225,"mc":[{"id":"1.232224347","rc":[{"batb":[[0,2.08,39.76],[1,1.21,24.75],[2,1.12,1.76]],"ltp":2.2,"tv":5.5,"id":61077258}]}]}
{"op":"mcm","clk":"11926276616","pt":1724552711335,"mc":[{"id":"1.232224347","rc":[{"batb":[[0,2.1,5],[1,2.08,39.76],[2,1.21,24.75]],"ltp":2.2,"tv":5.5,"id":61077258}]}]}
{"op":"mcm","clk":"11926276861","pt":1724552714643,"mc":[{"id":"1.232224347","rc":[{"batb":[[0,2.08,39.76],[1,1.21,24.75],[2,1.12,1.76]],"ltp":2.2,"tv":5.5,"id":61077258}]}]}
{"op":"mcm","clk":"11926276976","pt":1724552716855,"mc":[{"id":"1.232224347","rc":[{"batb":[[0,2.1,5],[1,2.08,39.76],[2,1.21,24.75]],"ltp":2.2,"tv":5.5,"id":61077258}]}]}
{"op":"mcm","clk":"11926277158","pt":1724552720062,"mc":[{"id":"1.232224347","rc":[{"batb":[[0,2.08,39.76],[1,1.21,24.75],[2,1.12,1.76]],"ltp":2.2,"tv":5.5,"id":61077258}]}]}
{"op":"mcm","clk":"11926277479","pt":1724552725455,"mc":[{"id":"1.232224347","rc":[{"batb":[[0,2.1,5],[1,2.08,39.76],[2,1.21,24.75]],"ltp":2.2,"tv":5.5,"id":61077258}]}]}
{"op":"mcm","clk":"11926277662","pt":1724552728660,"mc":[{"id":"1.232224347","rc":[{"batb":[[0,2.08,39.76],[1,1.21,24.75],[2,1.12,1.76]],"ltp":2.2,"tv":5.5,"id":61077258}]}]}
{"op":"mcm","clk":"11926277806","pt":1724552731554,"mc":[{"id":"1.232224347","rc":[{"batb":[[0,2.1,5],[1,2.08,39.76],[2,1.21,24.75]],"ltp":2.2,"tv":5.5,"id":61077258}]}]}
{"op":"mcm","clk":"11926277986","pt":1724552734650,"mc":[{"id":"1.232224347","rc":[{"batb":[[0,2.08,39.76],[1,1.21,24.75],[2,1.1,1000]],"ltp":2.2,"tv":5.5,"id":61077258}]}]}
{"op":"mcm","clk":"11926278152","pt":1724552737744,"mc":[{"id":"1.232224347","rc":[{"batb":[[0,2.1,5],[1,2.08,39.76],[2,1.21,24.75]],"ltp":2.2,"tv":5.5,"id":61077258}]}]}
{"op":"mcm","clk":"11926278293","pt":1724552740269,"mc":[{"id":"1.232224347","rc":[{"batb":[[0,2.08,39.76],[1,1.21,24.75],[2,1.1,1000]],"ltp":2.2,"tv":5.5,"id":61077258}]}]}
{"op":"mcm","clk":"11926278627","pt":1724552745952,"mc":[{"id":"1.232224347","rc":[{"batb":[[0,2.1,5],[1,2.08,39.76],[2,1.21,24.75]],"ltp":2.2,"tv":5.5,"id":61077258}]}]}
{"op":"mcm","clk":"11926278805","pt":1724552749174,"mc":[{"id":"1.232224347","rc":[{"batb":[[0,2.08,39.76],[1,1.21,24.75],[2,1.1,1000]],"ltp":2.2,"tv":5.5,"id":61077258}]}]}
{"op":"mcm","clk":"11926278982","pt":1724552752063,"mc":[{"id":"1.232224347","rc":[{"batb":[[0,2.1,5],[1,2.08,39.76],[2,1.21,24.75]],"ltp":2.2,"tv":5.5,"id":61077258}]}]}
{"op":"mcm","clk":"11926279158","pt":1724552755367,"mc":[{"id":"1.232224347","rc":[{"batb":[[0,2.08,39.76],[1,1.21,24.75],[2,1.1,1000]],"ltp":2.2,"tv":5.5,"id":61077258}]}]}
{"op":"mcm","clk":"11926279244","pt":1724552757579,"mc":[{"id":"1.232224347","rc":[{"batb":[[0,2.1,5],[1,2.08,39.76],[2,1.21,24.75]],"ltp":2.2,"tv":5.5,"id":61077258}]}]}
{"op":"mcm","clk":"11926279429","pt":1724552760890,"mc":[{"id":"1.232224347","rc":[{"batb":[[0,2.08,39.76],[1,1.21,24.75],[2,1.1,1000]],"ltp":2.2,"tv":5.5,"id":61077258}]}]}
{"op":"mcm","clk":"11926279804","pt":1724552766797,"mc":[{"id":"1.232224347","rc":[{"batb":[[0,2.1,5],[1,2.08,39.76],[2,1.21,24.75]],"ltp":2.2,"tv":5.5,"id":61077258}]}]}
{"op":"mcm","clk":"11926280019","pt":1724552770007,"mc":[{"id":"1.232224347","rc":[{"batb":[[0,2.08,39.76],[1,1.21,24.75],[2,1.1,1000]],"ltp":2.2,"tv":5.5,"id":61077258}]}]}
{"op":"mcm","clk":"11926280332","pt":1724552775204,"mc":[{"id":"1.232224347","rc":[{"batb":[[0,2.1,5],[1,2.08,39.76],[2,1.21,24.75]],"ltp":2.2,"tv":5.5,"id":61077258}]}]}
{"op":"mcm","clk":"11926280515","pt":1724552778509,"mc":[{"id":"1.232224347","rc":[{"batb":[[0,2.08,39.76],[1,1.21,24.75],[2,1.1,1000]],"ltp":2.2,"tv":5.5,"id":61077258}]}]}
{"op":"mcm","clk":"11926280695","pt":1724552781190,"mc":[{"id":"1.232224347","rc":[{"batb":[[0,2.1,5],[1,2.08,39.76],[2,1.21,24.75]],"ltp":2.2,"tv":5.5,"id":61077258}]}]}
{"op":"mcm","clk":"11926280892","pt":1724552784531,"mc":[{"id":"1.232224347","rc":[{"batb":[[0,2.08,39.76],[1,1.21,24.75],[2,1.1,1000]],"ltp":2.2,"tv":5.5,"id":61077258}]}]}
{"op":"mcm","clk":"11926281026","pt":1724552786896,"mc":[{"id":"1.232224347","rc":[{"batb":[[0,2.1,5],[1,2.08,39.76],[2,1.21,24.75]],"ltp":2.2,"tv":5.5,"id":61077258}]}]}
{"op":"mcm","clk":"11926281199","pt":1724552790242,"mc":[{"id":"1.232224347","rc":[{"batb":[[0,2.08,39.76],[1,1.21,24.75],[2,1.1,1000]],"ltp":2.2,"tv":5.5,"id":61077258}]}]}
{"op":"mcm","clk":"11926281377","pt":1724552793233,"mc":[{"id":"1.232224347","rc":[{"batb":[[0,2.1,5],[1,2.08,39.76],[2,1.21,24.75]],"ltp":2.2,"tv":5.5,"id":61077258}]}]}
{"op":"mcm","clk":"11926281594","pt":1724552796538,"mc":[{"id":"1.232224347","rc":[{"batb":[[0,2.08,39.76],[1,1.21,24.75],[2,1.1,1000]],"ltp":2.2,"tv":5.5,"id":61077258}]}]}
{"op":"mcm","clk":"11926281715","pt":1724552798705,"mc":[{"id":"1.232224347","rc":[{"batb":[[0,2.1,5],[1,2.08,39.76],[2,1.21,24.75]],"ltp":2.2,"tv":5.5,"id":61077258}]}]}
{"op":"mcm","clk":"11926281891","pt":1724552801947,"mc":[{"id":"1.232224347","rc":[{"batb":[[0,2.08,39.76],[1,1.21,24.75],[2,1.1,1000]],"ltp":2.2,"tv":5.5,"id":61077258}]}]}
{"op":"mcm","clk":"11926282014","pt":1724552804116,"mc":[{"id":"1.232224347","rc":[{"batb":[[0,2.1,5],[1,2.08,39.76],[2,1.21,24.75]],"ltp":2.2,"tv":5.5,"id":61077258}]}]}
{"op":"mcm","clk":"11926282209","pt":1724552807419,"mc":[{"id":"1.232224347","rc":[{"batb":[[0,2.08,39.76],[1,1.21,24.75],[2,1.1,1000]],"ltp":2.2,"tv":5.5,"id":61077258}]}]}
{"op":"mcm","clk":"11926282335","pt":1724552809649,"mc":[{"id":"1.232224347","rc":[{"batb":[[0,2.1,5],[1,2.08,39.76],[2,1.21,24.75]],"ltp":2.2,"tv":5.5,"id":61077258}]}]}
{"op":"mcm","clk":"11926282484","pt":1724552812836,"mc":[{"id":"1.232224347","rc":[{"batb":[[0,2.08,39.76],[1,1.21,24.75],[2,1.1,1000]],"ltp":2.2,"tv":5.5,"id":61077258}]}]}
{"op":"mcm","clk":"11926282622","pt":1724552815274,"mc":[{"id":"1.232224347","rc":[{"batb":[[0,2.1,5],[1,2.08,39.76],[2,1.21,24.75]],"ltp":2.2,"tv":5.5,"id":61077258}]}]}
{"op":"mcm","clk":"11926282794","pt":1724552818439,"mc":[{"id":"1.232224347","rc":[{"batb":[[0,2.08,39.76],[1,1.21,24.75],[2,1.1,1000]],"ltp":2.2,"tv":5.5,"id":61077258}]}]}
{"op":"mcm","clk":"11926282976","pt":1724552821455,"mc":[{"id":"1.232224347","rc":[{"batb":[[0,2.1,5],[1,2.08,39.76],[2,1.21,24.75]],"ltp":2.2,"tv":5.5,"id":61077258}]}]}
{"op":"mcm","clk":"11926283175","pt":1724552824862,"mc":[{"id":"1.232224347","rc":[{"batb":[[0,2.08,39.76],[1,1.21,24.75],[2,1.1,1000]],"ltp":2.2,"tv":5.5,"id":61077258}]}]}
{"op":"mcm","clk":"11926283307","pt":1724552827076,"mc":[{"id":"1.232224347","rc":[{"batb":[[0,2.1,5],[1,2.08,39.76],[2,1.21,24.75]],"ltp":2.2,"tv":5.5,"id":61077258}]}]}
{"op":"mcm","clk":"11926283513","pt":1724552830379,"mc":[{"id":"1.232224347","rc":[{"batb":[[0,2.08,39.76],[1,1.21,24.75],[2,1.1,1000]],"ltp":2.2,"tv":5.5,"id":61077258}]}]}
{"op":"mcm","clk":"11926283719","pt":1724552833266,"mc":[{"id":"1.232224347","rc":[{"batb":[[0,2.1,5],[1,2.08,39.76],[2,1.21,24.75]],"ltp":2.2,"tv":5.5,"id":61077258}]}]}
{"op":"mcm","clk":"11926283925","pt":1724552836566,"mc":[{"id":"1.232224347","rc":[{"batb":[[0,2.08,39.76],[1,1.21,24.75],[2,1.1,1000]],"ltp":2.2,"tv":5.5,"id":61077258}]}]}
{"op":"mcm","clk":"11926284072","pt":1724552838887,"mc":[{"id":"1.232224347","rc":[{"batb":[[0,2.1,5],[1,2.08,39.76],[2,1.21,24.75]],"ltp":2.2,"tv":5.5,"id":61077258}]}]}
{"op":"mcm","clk":"11926284264","pt":1724552842090,"mc":[{"id":"1.232224347","rc":[{"batb":[[0,2.08,39.76],[1,1.21,24.75],[2,1.1,1000]],"ltp":2.2,"tv":5.5,"id":61077258}]}]}
{"op":"mcm","clk":"11926284442","pt":1724552845183,"mc":[{"id":"1.232224347","rc":[{"batb":[[0,2.1,5],[1,2.08,39.76],[2,1.21,24.75]],"ltp":2.2,"tv":5.5,"id":61077258}]}]}
{"op":"mcm","clk":"11926284624","pt":1724552848480,"mc":[{"id":"1.232224347","rc":[{"batb":[[0,2.08,39.76],[1,1.21,24.75],[2,1.1,1000]],"ltp":2.2,"tv":5.5,"id":61077258}]}]}
{"op":"mcm","clk":"11926284810","pt":1724552852294,"mc":[{"id":"1.232224347","rc":[{"batb":[[0,2.1,5],[1,2.08,39.76],[2,1.21,24.75]],"ltp":2.2,"tv":5.5,"id":61077258}]}]}
{"op":"mcm","clk":"11926284965","pt":1724552855588,"mc":[{"id":"1.232224347","rc":[{"batb":[[0,2.08,39.76],[1,1.21,24.75],[2,1.1,1000]],"ltp":2.2,"tv":5.5,"id":61077258}]}]}
{"op":"mcm","clk":"11926285051","pt":1724552857801,"mc":[{"id":"1.232224347","rc":[{"batb":[[0,2.1,5],[1,2.08,39.76],[2,1.21,24.75]],"ltp":2.2,"tv":5.5,"id":61077258}]}]}
{"op":"mcm","clk":"11926285220","pt":1724552861309,"mc":[{"id":"1.232224347","rc":[{"batb":[[0,2.08,39.76],[1,1.21,24.75],[2,1.1,1000]],"ltp":2.2,"tv":5.5,"id":61077258}]}]}
{"op":"mcm","clk":"11926285312","pt":1724552863518,"mc":[{"id":"1.232224347","rc":[{"batb":[[0,2.1,5],[1,2.08,39.76],[2,1.21,24.75]],"ltp":2.2,"tv":5.5,"id":61077258}]}]}
{"op":"mcm","clk":"11926285470","pt":1724552866987,"mc":[{"id":"1.232224347","rc":[{"batb":[[0,2.08,39.76],[1,1.21,24.75],[2,1.1,1000]],"ltp":2.2,"tv":5.5,"id":61077258}]}]}
{"op":"mcm","clk":"11926285651","pt":1724552870193,"mc":[{"id":"1.232224347","rc":[{"batb":[[0,2.1,5],[1,2.08,39.76],[2,1.21,24.75]],"ltp":2.2,"tv":5.5,"id":61077258}]}]}
{"op":"mcm","clk":"11926285827","pt":1724552873487,"mc":[{"id":"1.232224347","rc":[{"batb":[[0,2.08,39.76],[1,1.21,24.75],[2,1.1,1000]],"ltp":2.2,"tv":5.5,"id":61077258}]}]}
{"op":"mcm","clk":"11926285947","pt":1724552876313,"mc":[{"id":"1.232224347","rc":[{"batb":[[0,2.1,5],[1,2.08,39.76],[2,1.21,24.75]],"ltp":2.2,"tv":5.5,"id":61077258}]}]}
{"op":"mcm","clk":"11926286107","pt":1724552879605,"mc":[{"id":"1.232224347","rc":[{"batb":[[0,2.08,39.76],[1,1.21,24.75],[2,1.1,1000]],"ltp":2.2,"tv":5.5,"id":61077258}]}]}
{"op":"mcm","clk":"11926286226","pt":1724552881934,"mc":[{"id":"1.232224347","rc":[{"batb":[[0,2.1,5],[1,2.08,39.76],[2,1.21,24.75]],"ltp":2.2,"tv":5.5,"id":61077258}]}]}
{"op":"mcm","clk":"11926286390","pt":1724552885128,"mc":[{"id":"1.232224347","rc":[{"batb":[[0,2.08,39.76],[1,1.21,24.75],[2,1.1,1000]],"ltp":2.2,"tv":5.5,"id":61077258}]}]}
{"op":"mcm","clk":"11926286553","pt":1724552888220,"mc":[{"id":"1.232224347","rc":[{"batb":[[0,2.1,5],[1,2.08,39.76],[2,1.21,24.75]],"ltp":2.2,"tv":5.5,"id":61077258}]}]}
{"op":"mcm","clk":"11926286702","pt":1724552891525,"mc":[{"id":"1.232224347","rc":[{"batb":[[0,2.08,39.76],[1,1.21,24.75],[2,1.1,1000]],"ltp":2.2,"tv":5.5,"id":61077258}]}]}
{"op":"mcm","clk":"11926286906","pt":1724552895605,"mc":[{"id":"1.232224347","rc":[{"batb":[[0,2.1,5],[1,2.08,39.76],[2,1.21,24.75]],"ltp":2.2,"tv":5.5,"id":61077258}]}]}
{"op":"mcm","clk":"11926287082","pt":1724552898911,"mc":[{"id":"1.232224347","rc":[{"batb":[[0,2.08,39.76],[1,1.21,24.75],[2,1.1,1000]],"ltp":2.2,"tv":5.5,"id":61077258}]}]}
{"op":"mcm","clk":"11926287182","pt":1724552901122,"mc":[{"id":"1.232224347","rc":[{"batb":[[0,2.1,5],[1,2.08,39.76],[2,1.21,24.75]],"ltp":2.2,"tv":5.5,"id":61077258}]}]}
{"op":"mcm","clk":"11926287320","pt":1724552904423,"mc":[{"id":"1.232224347","rc":[{"batb":[[0,2.08,39.76],[1,1.21,24.75],[2,1.1,1000]],"ltp":2.2,"tv":5.5,"id":61077258}]}]}
{"op":"mcm","clk":"11926287412","pt":1724552906643,"mc":[{"id":"1.232224347","rc":[{"batb":[[0,2.1,5],[1,2.08,39.76],[2,1.21,24.75]],"ltp":2.2,"tv":5.5,"id":61077258}]}]}
{"op":"mcm","clk":"11926287582","pt":1724552909917,"mc":[{"id":"1.232224347","rc":[{"batb":[[0,2.08,39.76],[1,1.21,24.75],[2,1.1,1000]],"ltp":2.2,"tv":5.5,"id":61077258}]}]}
{"op":"mcm","clk":"11926287697","pt":1724552912129,"mc":[{"id":"1.232224347","rc":[{"batb":[[0,2.1,5],[1,2.08,39.76],[2,1.21,24.75]],"ltp":2.2,"tv":5.5,"id":61077258}]}]}
{"op":"mcm","clk":"11926287848","pt":1724552915440,"mc":[{"id":"1.232224347","rc":[{"batb":[[0,2.08,39.76],[1,1.21,24.75],[2,1.1,1000]],"ltp":2.2,"tv":5.5,"id":61077258}]}]}
{"op":"mcm","clk":"11926287988","pt":1724552918343,"mc":[{"id":"1.232224347","rc":[{"batb":[[0,2.1,5],[1,2.08,39.76],[2,1.21,24.75]],"ltp":2.2,"tv":5.5,"id":61077258}]}]}
{"op":"mcm","clk":"11926288145","pt":1724552921635,"mc":[{"id":"1.232224347","rc":[{"batb":[[0,2.08,39.76],[1,1.21,24.75],[2,1.1,1000]],"ltp":2.2,"tv":5.5,"id":61077258}]}]}
{"op":"mcm","clk":"11926288301","pt":1724552926070,"mc":[{"id":"1.232224347","rc":[{"batb":[[0,2.1,5],[1,2.08,39.76],[2,1.21,24.75]],"ltp":2.2,"tv":5.5,"id":61077258}]}]}
{"op":"mcm","clk":"11926288458","pt":1724552929338,"mc":[{"id":"1.232224347","rc":[{"batb":[[0,2.08,39.76],[1,1.21,24.75],[2,1.1,1000]],"ltp":2.2,"tv":5.5,"id":61077258}]}]}
{"op":"mcm","clk":"11926288614","pt":1724552932635,"mc":[{"id":"1.232224347","rc":[{"batb":[[0,2.1,5],[1,2.08,39.76],[2,1.21,24.75]],"ltp":2.2,"tv":5.5,"id":61077258}]}]}
{"op":"mcm","clk":"11926288783","pt":1724552935977,"mc":[{"id":"1.232224347","rc":[{"batb":[[0,2.08,39.76],[1,1.21,24.75],[2,1.1,1000]],"ltp":2.2,"tv":5.5,"id":61077258}]}]}
{"op":"mcm","clk":"11926288894","pt":1724552938963,"mc":[{"id":"1.232224347","rc":[{"batb":[[0,2.1,5],[1,2.08,39.76],[2,1.21,24.75]],"ltp":2.2,"tv":5.5,"id":61077258}]}]}
{"op":"mcm","clk":"11926289067","pt":1724552942276,"mc":[{"id":"1.232224347","rc":[{"batb":[[0,2.08,39.76],[1,1.21,24.75],[2,1.1,1000]],"ltp":2.2,"tv":5.5,"id":61077258}]}]}
{"op":"mcm","clk":"11926289240","pt":1724552944775,"mc":[{"id":"1.232224347","rc":[{"batb":[[0,2.1,5],[1,2.08,39.76],[2,1.21,24.75]],"ltp":2.2,"tv":5.5,"id":61077258}]}]}
{"op":"mcm","clk":"11926289405","pt":1724552948176,"mc":[{"id":"1.232224347","rc":[{"batb":[[0,2.08,39.76],[1,1.21,24.75],[2,1.1,1000]],"ltp":2.2,"tv":5.5,"id":61077258}]}]}
{"op":"mcm","clk":"11926289591","pt":1724552951487,"mc":[{"id":"1.232224347","rc":[{"batb":[[0,2.1,5],[1,2.08,39.76],[2,1.21,24.75]],"ltp":2.2,"tv":5.5,"id":61077258}]}]}
{"op":"mcm","clk":"11926289753","pt":1724552954797,"mc":[{"id":"1.232224347","rc":[{"batb":[[0,2.08,39.76],[1,1.21,24.75],[2,1.1,1000]],"ltp":2.2,"tv":5.5,"id":61077258}]}]}
{"op":"mcm","clk":"11926289827","pt":1724552956296,"mc":[{"id":"1.232224347","rc":[{"batb":[[0,2.1,4],[1,2.08,39.76],[2,1.21,24.75]],"batl":[[0,2.98,6.06],[1,14,1.29],[2,24,0.76]],"ltp":2.2,"tv":5.5,"id":61077258},{"batb":[[0,1.51,12.1],[1,1.5,246.54],[2,1.43,135.6]],"ltp":1.8,"tv":214.75,"id":48800301}]}]}
{"op":"mcm","clk":"11926289896","pt":1724552957373,"mc":[{"id":"1.232224347","rc":[{"batb":[[0,2.12,5],[1,2.1,4],[2,2.08,39.76]],"ltp":2.2,"tv":5.5,"id":61077258}]}]}
{"op":"mcm","clk":"11926289971","pt":1724552958707,"mc":[{"id":"1.232224347","rc":[{"batb":[[1,2.08,39.76],[2,1.21,24.75]],"ltp":2.2,"tv":5.5,"id":61077258}]}]}
{"op":"mcm","clk":"11926290078","pt":1724552960823,"mc":[{"id":"1.232224347","rc":[{"batb":[[0,2.08,39.76],[1,1.21,24.75],[2,1.1,1000]],"ltp":2.2,"tv":5.5,"id":61077258}]}]}
{"op":"mcm","clk":"11926290088","pt":1724552960927,"mc":[{"id":"1.232224347","rc":[{"batb":[[0,2.1,4],[1,2.08,39.76],[2,1.21,24.75]],"ltp":2.2,"tv":5.5,"id":61077258}]}]}
{"op":"mcm","clk":"11926290190","pt":1724552963295,"mc":[{"id":"1.232224347","rc":[{"batb":[[0,2.1,5]],"ltp":2.2,"tv":5.5,"id":61077258}]}]}
{"op":"mcm","clk":"11926290346","pt":1724552966600,"mc":[{"id":"1.232224347","rc":[{"batb":[[0,2.12,4]],"ltp":2.2,"tv":5.5,"id":61077258}]}]}
{"op":"mcm","clk":"11926290461","pt":1724552968817,"mc":[{"id":"1.232224347","rc":[{"batb":[[0,2.08,39.76],[1,1.21,24.75],[2,1.1,1000]],"ltp":2.2,"tv":5.5,"id":61077258}]}]}
{"op":"mcm","clk":"11926290468","pt":1724552969022,"mc":[{"id":"1.232224347","rc":[{"batb":[[0,2.1,5],[1,2.08,39.76],[2,1.21,24.75]],"ltp":2.2,"tv":5.5,"id":61077258}]}]}
{"op":"mcm","clk":"11926290589","pt":1724552971495,"mc":[{"id":"1.232224347","rc":[{"batb":[[0,2.12,4],[1,2.1,5],[2,2.08,39.76]],"ltp":2.2,"tv":5.5,"id":61077258}]}]}
{"op":"mcm","clk":"11926290634","pt":1724552972319,"mc":[{"id":"1.232224347","rc":[{"batb":[[1,2.08,39.76],[2,1.21,24.75]],"ltp":2.2,"tv":5.5,"id":61077258}]}]}
{"op":"mcm","clk":"11926290712","pt":1724552973917,"mc":[{"id":"1.232224347","rc":[{"batb":[[0,2.08,39.76],[1,1.21,24.75],[2,1.1,1000]],"ltp":2.2,"tv":5.5,"id":61077258}]}]}
{"op":"mcm","clk":"11926290783","pt":1724552975118,"mc":[{"id":"1.232224347","rc":[{"batb":[[0,2.1,5],[1,2.08,39.76],[2,1.21,24.75]],"ltp":2.2,"tv":5.5,"id":61077258}]}]}
{"op":"mcm","clk":"11926290837","pt":1724552976298,"mc":[{"id":"1.232224347","rc":[{"batb":[[0,2.12,4],[1,2.1,5],[2,2.08,39.76]],"ltp":2.2,"tv":5.5,"id":61077258}]}]}
{"op":"mcm","clk":"11926290945","pt":1724552978718,"mc":[{"id":"1.232224347","rc":[{"batb":[[0,2.08,39.76],[1,1.21,24.75],[2,1.1,1000]],"ltp":2.2,"tv":5.5,"id":61077258}]}]}
{"op":"mcm","clk":"11926291003","pt":1724552979804,"mc":[{"id":"1.232224347","rc":[{"batb":[[1,1.43,135.6],[2,1.21,25.63]],"ltp":1.8,"tv":214.75,"id":48800301}]}]}
{"op":"mcm","clk":"11926291061","pt":1724552980939,"mc":[{"id":"1.232224347","rc":[{"batb":[[0,2.1,9],[1,2.08,39.76],[2,1.21,24.75]],"ltp":2.2,"tv":5.5,"id":61077258}]}]}
{"op":"mcm","clk":"11926291195","pt":1724552983724,"mc":[{"id":"1.232224347","rc":[{"batb":[[0,2.1,5]],"batl":[[0,14,1.29],[1,24,0.76],[2,24,0]],"ltp":2.2,"tv":5.5,"id":61077258},{"batb":[[0,1.21,25.63],[1,1.1,1000],[2,1.05,200]],"ltp":1.8,"tv":214.75,"id":48800301}]}]}
{"op":"mcm","clk":"11926291227","pt":1724552984409,"mc":[{"id":"1.232224347","rc":[{"batb":[[0,2.08,39.76],[1,1.21,24.75],[2,1.1,1000]],"ltp":2.2,"tv":5.5,"id":61077258}]}]}
{"op":"mcm","clk":"11926291394","pt":1724552987549,"mc":[{"id":"1.232224347","rc":[{"batb":[[0,2.1,5],[1,2.08,39.76],[2,1.21,24.75]],"ltp":2.2,"tv":5.5,"id":61077258}]}]}
{"op":"mcm","clk":"11926291503","pt":1724552990734,"mc":[{"id":"1.232224347","rc":[{"batb":[[0,2.08,39.76],[1,1.21,24.75],[2,1.1,1000]],"ltp":2.2,"tv":5.5,"id":61077258}]}]}
{"op":"mcm","clk":"11926291615","pt":1724552993212,"mc":[{"id":"1.232224347","rc":[{"batb":[[0,2.1,5],[1,2.08,39.76],[2,1.21,24.75]],"ltp":2.2,"tv":5.5,"id":61077258}]}]}
{"op":"mcm","clk":"11926291717","pt":1724552996547,"mc":[{"id":"1.232224347","rc":[{"batb":[[0,2.08,39.76],[1,1.21,24.75],[2,1.1,1000]],"ltp":2.2,"tv":5.5,"id":61077258}]}]}
{"op":"mcm","clk":"11926291843","pt":1724552999026,"mc":[{"id":"1.232224347","rc":[{"batb":[[0,2.1,5],[1,2.08,39.76],[2,1.21,24.75]],"ltp":2.2,"tv":5.5,"id":61077258}]}]}
{"op":"mcm","clk":"11926292046","pt":1724553002251,"mc":[{"id":"1.232224347","rc":[{"batb":[[0,2.08,39.76],[1,1.21,24.75],[2,1.1,1000]],"ltp":2.2,"tv":5.5,"id":61077258}]}]}
{"op":"mcm","clk":"11926292268","pt":1724553006053,"mc":[{"id":"1.232224347","rc":[{"batb":[[0,2.1,5],[1,2.08,39.76],[2,1.21,24.75]],"ltp":2.2,"tv":5.5,"id":61077258}]}]}
{"op":"mcm","clk":"11926292447","pt":1724553009431,"mc":[{"id":"1.232224347","rc":[{"batb":[[0,2.08,39.76],[1,1.21,24.75],[2,1.1,1000]],"ltp":2.2,"tv":5.5,"id":61077258}]}]}
{"op":"mcm","clk":"11926292573","pt":1724553011659,"mc":[{"id":"1.232224347","rc":[{"batb":[[0,2.1,5],[1,2.08,39.76],[2,1.21,24.75]],"ltp":2.2,"tv":5.5,"id":61077258}]}]}
{"op":"mcm","clk":"11926292738","pt":1724553014936,"mc":[{"id":"1.232224347","rc":[{"batb":[[0,2.08,39.76],[1,1.21,24.75],[2,1.1,1000]],"ltp":2.2,"tv":5.5,"id":61077258}]}]}
{"op":"mcm","clk":"11926292940","pt":1724553017832,"mc":[{"id":"1.232224347","rc":[{"batb":[[0,2.1,5],[1,2.08,39.76],[2,1.21,24.75]],"ltp":2.2,"tv":5.5,"id":61077258}]}]}
{"op":"mcm","clk":"11926293174","pt":1724553021147,"mc":[{"id":"1.232224347","rc":[{"batb":[[0,2.08,39.76],[1,1.21,24.75],[2,1.1,1000]],"ltp":2.2,"tv":5.5,"id":61077258}]}]}
{"op":"mcm","clk":"11926293339","pt":1724553023574,"mc":[{"id":"1.232224347","rc":[{"batb":[[0,2.1,5],[1,2.08,39.76],[2,1.21,24.75]],"ltp":2.2,"tv":5.5,"id":61077258}]}]}
{"op":"mcm","clk":"11926293563","pt":1724553026874,"mc":[{"id":"1.232224347","rc":[{"batb":[[0,2.08,39.76],[1,1.21,24.75],[2,1.1,1000]],"ltp":2.2,"tv":5.5,"id":61077258}]}]}
{"op":"mcm","clk":"11926293713","pt":1724553029559,"mc":[{"id":"1.232224347","rc":[{"batb":[[0,2.1,5],[1,2.08,39.76],[2,1.21,24.75]],"ltp":2.2,"tv":5.5,"id":61077258}]}]}
{"op":"mcm","clk":"11926293890","pt":1724553032869,"mc":[{"id":"1.232224347","rc":[{"batb":[[0,2.08,39.76],[1,1.21,24.75],[2,1.1,1000]],"ltp":2.2,"tv":5.5,"id":61077258}]}]}
{"op":"mcm","clk":"11926294060","pt":1724553036064,"mc":[{"id":"1.232224347","rc":[{"batb":[[0,2.1,5],[1,2.08,39.76],[2,1.21,24.75]],"ltp":2.2,"tv":5.5,"id":61077258}]}]}
{"op":"mcm","clk":"11926294220","pt":1724553039483,"mc":[{"id":"1.232224347","rc":[{"batb":[[0,2.08,39.76],[1,1.21,24.75],[2,1.1,1000]],"ltp":2.2,"tv":5.5,"id":61077258}]}]}
{"op":"mcm","clk":"11926294337","pt":1724553041756,"mc":[{"id":"1.232224347","rc":[{"batb":[[0,2.1,5],[1,2.08,39.76],[2,1.21,24.75]],"ltp":2.2,"tv":5.5,"id":61077258}]}]}
{"op":"mcm","clk":"11926294513","pt":1724553044973,"mc":[{"id":"1.232224347","rc":[{"batb":[[0,2.08,39.76],[1,1.21,24.75],[2,1.1,1000]],"ltp":2.2,"tv":5.5,"id":61077258}]}]}
{"op":"mcm","clk":"11926294623","pt":1724553047190,"mc":[{"id":"1.232224347","rc":[{"batb":[[0,2.1,5],[1,2.08,39.76],[2,1.21,24.75]],"ltp":2.2,"tv":5.5,"id":61077258}]}]}
{"op":"mcm","clk":"11926294807","pt":1724553050481,"mc":[{"id":"1.232224347","rc":[{"batb":[[0,2.08,39.76],[1,1.21,24.75],[2,1.1,1000]],"ltp":2.2,"tv":5.5,"id":61077258}]}]}
{"op":"mcm","clk":"11926294957","pt":1724553053004,"mc":[{"id":"1.232224347","rc":[{"batb":[[0,2.1,5],[1,2.08,39.76],[2,1.21,24.75]],"ltp":2.2,"tv":5.5,"id":61077258}]}]}
{"op":"mcm","clk":"11926295109","pt":1724553056373,"mc":[{"id":"1.232224347","rc":[{"batb":[[0,2.08,39.76],[1,1.21,24.75],[2,1.1,1000]],"ltp":2.2,"tv":5.5,"id":61077258}]}]}
{"op":"mcm","clk":"11926295301","pt":1724553060183,"mc":[{"id":"1.232224347","rc":[{"batb":[[0,2.1,5],[1,2.08,39.76],[2,1.21,24.75]],"ltp":2.2,"tv":5.5,"id":61077258}]}]}
{"op":"mcm","clk":"11926295512","pt":1724553063595,"mc":[{"id":"1.232224347","rc":[{"batb":[[0,2.08,39.76],[1,1.21,24.75],[2,1.1,1000]],"ltp":2.2,"tv":5.5,"id":61077258}]}]}
{"op":"mcm","clk":"11926295657","pt":1724553065919,"mc":[{"id":"1.232224347","rc":[{"batb":[[0,2.1,5],[1,2.08,39.76],[2,1.21,24.75]],"ltp":2.2,"tv":5.5,"id":61077258}]}]}
{"op":"mcm","clk":"11926295842","pt":1724553069223,"mc":[{"id":"1.232224347","rc":[{"batb":[[0,2.08,39.76],[1,1.21,24.75],[2,1.1,1000]],"ltp":2.2,"tv":5.5,"id":61077258}]}]}
{"op":"mcm","clk":"11926296046","pt":1724553072221,"mc":[{"id":"1.232224347","rc":[{"batb":[[0,2.1,5],[1,2.08,39.76],[2,1.21,24.75]],"ltp":2.2,"tv":5.5,"id":61077258}]}]}
{"op":"mcm","clk":"11926296217","pt":1724553075521,"mc":[{"id":"1.232224347","rc":[{"batb":[[0,2.08,39.76],[1,1.21,24.75],[2,1.1,1000]],"ltp":2.2,"tv":5.5,"id":61077258}]}]}
{"op":"mcm","clk":"11926296469","pt":1724553079233,"mc":[{"id":"1.232224347","rc":[{"batb":[[0,2.1,5],[1,2.08,39.76],[2,1.21,24.75]],"ltp":2.2,"tv":5.5,"id":61077258}]}]}
{"op":"mcm","clk":"11926296637","pt":1724553082637,"mc":[{"id":"1.232224347","rc":[{"batb":[[0,2.08,39.76],[1,1.21,24.75],[2,1.1,1000]],"ltp":2.2,"tv":5.5,"id":61077258}]}]}
{"op":"mcm","clk":"11926296740","pt":1724553084809,"mc":[{"id":"1.232224347","rc":[{"batb":[[0,2.1,5],[1,2.08,39.76],[2,1.21,24.75]],"ltp":2.2,"tv":5.5,"id":61077258}]}]}
{"op":"mcm","clk":"11926296914","pt":1724553088199,"mc":[{"id":"1.232224347","rc":[{"batb":[[0,2.08,39.76],[1,1.21,24.75],[2,1.1,1000]],"ltp":2.2,"tv":5.5,"id":61077258}]}]}
{"op":"mcm","clk":"11926297044","pt":1724553090410,"mc":[{"id":"1.232224347","rc":[{"batb":[[0,2.1,5],[1,2.08,39.76],[2,1.21,24.75]],"ltp":2.2,"tv":5.5,"id":61077258}]}]}
{"op":"mcm","clk":"11926297191","pt":1724553093744,"mc":[{"id":"1.232224347","rc":[{"batb":[[0,2.08,39.76],[1,1.21,24.75],[2,1.1,1000]],"ltp":2.2,"tv":5.5,"id":61077258}]}]}
{"op":"mcm","clk":"11926297270","pt":1724553095898,"mc":[{"id":"1.232224347","rc":[{"batb":[[0,2.1,5],[1,2.08,39.76],[2,1.21,24.75]],"ltp":2.2,"tv":5.5,"id":61077258}]}]}
{"op":"mcm","clk":"11926297406","pt":1724553099317,"mc":[{"id":"1.232224347","rc":[{"batb":[[0,2.08,39.76],[1,1.21,24.75],[2,1.1,1000]],"ltp":2.2,"tv":5.5,"id":61077258}]}]}
{"op":"mcm","clk":"11926297532","pt":1724553102043,"mc":[{"id":"1.232224347","rc":[{"batb":[[0,2.1,5],[1,2.08,39.76],[2,1.21,24.75]],"ltp":2.2,"tv":5.5,"id":61077258}]}]}
{"op":"mcm","clk":"11926297701","pt":1724553105241,"mc":[{"id":"1.232224347","rc":[{"batb":[[0,2.08,39.76],[1,1.21,24.75],[2,1.1,1000]],"ltp":2.2,"tv":5.5,"id":61077258}]}]}
{"op":"mcm","clk":"11926297860","pt":1724553108237,"mc":[{"id":"1.232224347","rc":[{"batb":[[0,2.1,5],[1,2.08,39.76],[2,1.21,24.75]],"ltp":2.2,"tv":5.5,"id":61077258}]}]}
{"op":"mcm","clk":"11926298005","pt":1724553111732,"mc":[{"id":"1.232224347","rc":[{"batb":[[0,2.08,39.76],[1,1.21,24.75],[2,1.1,1000]],"ltp":2.2,"tv":5.5,"id":61077258}]}]}
{"op":"mcm","clk":"11926298180","pt":1724553115075,"mc":[{"id":"1.232224347","rc":[{"batb":[[0,2.1,5],[1,2.08,39.76],[2,1.21,24.75]],"ltp":2.2,"tv":5.5,"id":61077258}]}]}
{"op":"mcm","clk":"11926298344","pt":1724553118362,"mc":[{"id":"1.232224347","rc":[{"batb":[[0,2.08,39.76],[1,1.21,24.75],[2,1.1,1000]],"ltp":2.2,"tv":5.5,"id":61077258}]}]}
{"op":"mcm","clk":"11926298462","pt":1724553120939,"mc":[{"id":"1.232224347","rc":[{"batb":[[0,2.1,5],[1,2.08,39.76],[2,1.21,24.75]],"ltp":2.2,"tv":5.5,"id":61077258}]}]}
{"op":"mcm","clk":"11926298641","pt":1724553124245,"mc":[{"id":"1.232224347","rc":[{"batb":[[0,2.08,39.76],[1,1.21,24.75],[2,1.1,1000]],"ltp":2.2,"tv":5.5,"id":61077258}]}]}
{"op":"mcm","clk":"11926298766","pt":1724553126664,"mc":[{"id":"1.232224347","rc":[{"batb":[[0,2.1,5],[1,2.08,39.76],[2,1.21,24.75]],"ltp":2.2,"tv":5.5,"id":61077258}]}]}
{"op":"mcm","clk":"11926298928","pt":1724553130061,"mc":[{"id":"1.232224347","rc":[{"batb":[[0,2.08,39.76],[1,1.21,24.75],[2,1.1,1000]],"ltp":2.2,"tv":5.5,"id":61077258}]}]}
{"op":"mcm","clk":"11926299034","pt":1724553132374,"mc":[{"id":"1.232224347","rc":[{"batb":[[0,2.1,5],[1,2.08,39.76],[2,1.21,24.75]],"ltp":2.2,"tv":5.5,"id":61077258}]}]}
{"op":"mcm","clk":"11926299236","pt":1724553135680,"mc":[{"id":"1.232224347","rc":[{"batb":[[0,2.08,39.76],[1,1.21,24.75],[2,1.1,1000]],"ltp":2.2,"tv":5.5,"id":61077258}]}]}
{"op":"mcm","clk":"11926299452","pt":1724553138984,"mc":[{"id":"1.232224347","rc":[{"batb":[[0,2.1,5],[1,2.08,39.76],[2,1.21,24.75]],"ltp":2.2,"tv":5.5,"id":61077258}]}]}
{"op":"mcm","clk":"11926299652","pt":1724553142494,"mc":[{"id":"1.232224347","rc":[{"batb":[[0,2.08,39.76],[1,1.21,24.75],[2,1.1,1000]],"ltp":2.2,"tv":5.5,"id":61077258}]}]}
{"op":"mcm","clk":"11926299908","pt":1724553145991,"mc":[{"id":"1.232224347","rc":[{"batb":[[0,2.1,5],[1,2.08,39.76],[2,1.21,24.75]],"ltp":2.2,"tv":5.5,"id":61077258}]}]}
{"op":"mcm","clk":"11926300129","pt":1724553149320,"mc":[{"id":"1.232224347","rc":[{"batb":[[0,2.08,39.76],[1,1.21,24.75],[2,1.1,1000]],"ltp":2.2,"tv":5.5,"id":61077258}]}]}
{"op":"mcm","clk":"11926300315","pt":1724553152411,"mc":[{"id":"1.232224347","rc":[{"batb":[[0,2.1,5],[1,2.08,39.76],[2,1.21,24.75]],"ltp":2.2,"tv":5.5,"id":61077258}]}]}
{"op":"mcm","clk":"11926300486","pt":1724553155695,"mc":[{"id":"1.232224347","rc":[{"batb":[[0,2.08,39.76],[1,1.21,24.75],[2,1.1,1000]],"ltp":2.2,"tv":5.5,"id":61077258}]}]}
{"op":"mcm","clk":"11926300650","pt":1724553158797,"mc":[{"id":"1.232224347","rc":[{"batb":[[0,2.1,5],[1,2.08,39.76],[2,1.21,24.75]],"ltp":2.2,"tv":5.5,"id":61077258}]}]}
{"op":"mcm","clk":"11926300800","pt":1724553162010,"mc":[{"id":"1.232224347","rc":[{"batb":[[0,2.08,39.76],[1,1.21,24.75],[2,1.1,1000]],"ltp":2.2,"tv":5.5,"id":61077258}]}]}
{"op":"mcm","clk":"11926300911","pt":1724553164680,"mc":[{"id":"1.232224347","rc":[{"batb":[[0,2.1,5],[1,2.08,39.76],[2,1.21,24.75]],"ltp":2.2,"tv":5.5,"id":61077258}]}]}
{"op":"mcm","clk":"11926301079","pt":1724553167972,"mc":[{"id":"1.232224347","rc":[{"batb":[[0,2.08,39.76],[1,1.21,24.75],[2,1.1,1000]],"ltp":2.2,"tv":5.5,"id":61077258}]}]}
{"op":"mcm","clk":"11926301345","pt":1724553173014,"mc":[{"id":"1.232224347","rc":[{"batb":[[0,2.1,5],[1,2.08,39.76],[2,1.21,24.75]],"ltp":2.2,"tv":5.5,"id":61077258}]}]}
{"op":"mcm","clk":"11926301523","pt":1724553176304,"mc":[{"id":"1.232224347","rc":[{"batb":[[0,2.08,39.76],[1,1.21,24.75],[2,1.1,1000]],"ltp":2.2,"tv":5.5,"id":61077258}]}]}
{"op":"mcm","clk":"11926301627","pt":1724553178621,"mc":[{"id":"1.232224347","rc":[{"batb":[[0,2.1,5],[1,2.08,39.76],[2,1.21,24.75]],"ltp":2.2,"tv":5.5,"id":61077258}]}]}
{"op":"mcm","clk":"11926301795","pt":1724553181807,"mc":[{"id":"1.232224347","rc":[{"batb":[[0,2.08,39.76],[1,1.21,24.75],[2,1.1,1000]],"ltp":2.2,"tv":5.5,"id":61077258}]}]}
{"op":"mcm","clk":"11926301955","pt":1724553185217,"mc":[{"id":"1.232224347","rc":[{"batb":[[0,2.1,5],[1,2.08,39.76],[2,1.21,24.75]],"ltp":2.2,"tv":5.5,"id":61077258}]}]}
{"op":"mcm","clk":"11926302131","pt":1724553188621,"mc":[{"id":"1.232224347","rc":[{"batb":[[0,2.08,39.76],[1,1.21,24.75],[2,1.1,1000]],"ltp":2.2,"tv":5.5,"id":61077258}]}]}
{"op":"mcm","clk":"11926302255","pt":1724553191202,"mc":[{"id":"1.232224347","rc":[{"batb":[[0,2.1,5],[1,2.08,39.76],[2,1.21,24.75]],"ltp":2.2,"tv":5.5,"id":61077258}]}]}
{"op":"mcm","clk":"11926302444","pt":1724553194631,"mc":[{"id":"1.232224347","rc":[{"batb":[[0,2.08,39.76],[1,1.21,24.75],[2,1.1,1000]],"ltp":2.2,"tv":5.5,"id":61077258}]}]}
{"op":"mcm","clk":"11926302797","pt":1724553201644,"mc":[{"id":"1.232224347","rc":[{"batb":[[0,2.1,5],[1,2.08,39.76],[2,1.21,24.75]],"ltp":2.2,"tv":5.5,"id":61077258}]}]}
{"op":"mcm","clk":"11926302981","pt":1724553205139,"mc":[{"id":"1.232224347","rc":[{"batb":[[0,2.08,39.76],[1,1.21,24.75],[2,1.1,1000]],"ltp":2.2,"tv":5.5,"id":61077258}]}]}
{"op":"mcm","clk":"11926303174","pt":1724553208837,"mc":[{"id":"1.232224347","rc":[{"batb":[[0,2.1,5],[1,2.08,39.76],[2,1.21,24.75]],"ltp":2.2,"tv":5.5,"id":61077258}]}]}
{"op":"mcm","clk":"11926303367","pt":1724553212318,"mc":[{"id":"1.232224347","rc":[{"batb":[[0,2.08,39.76],[1,1.21,24.75],[2,1.1,1000]],"ltp":2.2,"tv":5.5,"id":61077258}]}]}
{"op":"mcm","clk":"11926303491","pt":1724553214943,"mc":[{"id":"1.232224347","rc":[{"batb":[[0,2.1,5],[1,2.08,39.76],[2,1.21,24.75]],"ltp":2.2,"tv":5.5,"id":61077258}]}]}
{"op":"mcm","clk":"11926303650","pt":1724553218343,"mc":[{"id":"1.232224347","rc":[{"batb":[[0,2.08,39.76],[1,1.21,24.75],[2,1.1,1000]],"ltp":2.2,"tv":5.5,"id":61077258}]}]}
{"op":"mcm","clk":"11926303965","pt":1724553224129,"mc":[{"id":"1.232224347","rc":[{"batb":[[0,2.1,5],[1,2.08,39.76],[2,1.21,24.75]],"ltp":2.2,"tv":5.5,"id":61077258}]}]}
{"op":"mcm","clk":"11926304132","pt":1724553227463,"mc":[{"id":"1.232224347","rc":[{"batb":[[0,2.08,39.76],[1,1.21,24.75],[2,1.1,1000]],"ltp":2.2,"tv":5.5,"id":61077258}]}]}
{"op":"mcm","clk":"11926304529","pt":1724553234734,"mc":[{"id":"1.232224347","rc":[{"batb":[[0,2.1,5],[1,2.08,39.76],[2,1.21,24.75]],"ltp":2.2,"tv":5.5,"id":61077258}]}]}
{"op":"mcm","clk":"11926304698","pt":1724553238074,"mc":[{"id":"1.232224347","rc":[{"batb":[[0,2.08,39.76],[1,1.21,24.75],[2,1.1,1000]],"ltp":2.2,"tv":5.5,"id":61077258}]}]}
{"op":"mcm","clk":"11926304838","pt":1724553240859,"mc":[{"id":"1.232224347","rc":[{"batb":[[0,2.1,5],[1,2.08,39.76],[2,1.21,24.75]],"ltp":2.2,"tv":5.5,"id":61077258}]}]}
{"op":"mcm","clk":"11926305037","pt":1724553244113,"mc":[{"id":"1.232224347","rc":[{"batb":[[0,2.08,39.76],[1,1.21,24.75],[2,1.1,1000]],"ltp":2.2,"tv":5.5,"id":61077258}]}]}
{"op":"mcm","clk":"11926305219","pt":1724553246997,"mc":[{"id":"1.232224347","rc":[{"batb":[[0,2.1,5],[1,2.08,39.76],[2,1.21,24.75]],"ltp":2.2,"tv":5.5,"id":61077258}]}]}
{"op":"mcm","clk":"11926305408","pt":1724553250291,"mc":[{"id":"1.232224347","rc":[{"batb":[[0,2.08,39.76],[1,1.21,24.75],[2,1.1,1000]],"ltp":2.2,"tv":5.5,"id":61077258}]}]}
{"op":"mcm","clk":"11926305708","pt":1724553255575,"mc":[{"id":"1.232224347","rc":[{"batb":[[0,2.1,5],[1,2.08,39.76],[2,1.21,24.75]],"ltp":2.2,"tv":5.5,"id":61077258}]}]}
{"op":"mcm","clk":"11926305857","pt":1724553259094,"mc":[{"id":"1.232224347","rc":[{"batb":[[0,2.08,39.76],[1,1.21,24.75],[2,1.1,1000]],"ltp":2.2,"tv":5.5,"id":61077258}]}]}
{"op":"mcm","clk":"11926306238","pt":1724553266662,"mc":[{"id":"1.232224347","rc":[{"batb":[[0,2.1,5],[1,2.08,39.76],[2,1.21,24.75]],"ltp":2.2,"tv":5.5,"id":61077258}]}]}
{"op":"mcm","clk":"11926306390","pt":1724553269995,"mc":[{"id":"1.232224347","rc":[{"batb":[[0,2.08,39.76],[1,1.21,24.75],[2,1.1,1000]],"ltp":2.2,"tv":5.5,"id":61077258}]}]}
{"op":"mcm","clk":"11926306528","pt":1724553272673,"mc":[{"id":"1.232224347","rc":[{"batb":[[0,2.1,5],[1,2.08,39.76],[2,1.21,24.75]],"ltp":2.2,"tv":5.5,"id":61077258}]}]}
{"op":"mcm","clk":"11926306743","pt":1724553275980,"mc":[{"id":"1.232224347","rc":[{"batb":[[0,2.08,39.76],[1,1.21,24.75],[2,1.1,1000]],"ltp":2.2,"tv":5.5,"id":61077258}]}]}
{"op":"mcm","clk":"11926306927","pt":1724553279480,"mc":[{"id":"1.232224347","rc":[{"batb":[[0,2.1,5],[1,2.08,39.76],[2,1.21,24.75]],"ltp":2.2,"tv":5.5,"id":61077258}]}]}
{"op":"mcm","clk":"11926307092","pt":1724553282812,"mc":[{"id":"1.232224347","rc":[{"batb":[[0,2.08,39.76],[1,1.21,24.75],[2,1.1,1000]],"ltp":2.2,"tv":5.5,"id":61077258}]}]}
{"op":"mcm","clk":"11926307196","pt":1724553284985,"mc":[{"id":"1.232224347","rc":[{"batb":[[0,2.1,5],[1,2.08,39.76],[2,1.21,24.75]],"ltp":2.2,"tv":5.5,"id":61077258}]}]}
{"op":"mcm","clk":"11926307335","pt":1724553288318,"mc":[{"id":"1.232224347","rc":[{"batb":[[0,2.08,39.76],[1,1.21,24.75],[2,1.1,1000]],"ltp":2.2,"tv":5.5,"id":61077258}]}]}
{"op":"mcm","clk":"11926307496","pt":1724553292090,"mc":[{"id":"1.232224347","rc":[{"batb":[[0,2.1,5],[1,2.08,39.76],[2,1.21,24.75]],"ltp":2.2,"tv":5.5,"id":61077258}]}]}
{"op":"mcm","clk":"11926307647","pt":1724553295487,"mc":[{"id":"1.232224347","rc":[{"batb":[[0,2.08,39.76],[1,1.21,24.75],[2,1.1,1000]],"ltp":2.2,"tv":5.5,"id":61077258}]}]}
{"op":"mcm","clk":"11926307801","pt":1724553299329,"mc":[{"id":"1.232224347","rc":[{"batb":[[0,2.1,5],[1,2.08,39.76],[2,1.21,24.75]],"ltp":2.2,"tv":5.5,"id":61077258}]}]}
{"op":"mcm","clk":"11926307939","pt":1724553302601,"mc":[{"id":"1.232224347","rc":[{"batb":[[0,2.08,39.76],[1,1.21,24.75],[2,1.1,1000]],"ltp":2.2,"tv":5.5,"id":61077258}]}]}
{"op":"mcm","clk":"11926308199","pt":1724553307097,"mc":[{"id":"1.232224347","rc":[{"batb":[[0,2.1,5],[1,2.08,39.76],[2,1.21,24.75]],"ltp":2.2,"tv":5.5,"id":61077258}]}]}
{"op":"mcm","clk":"11926308422","pt":1724553310598,"mc":[{"id":"1.232224347","rc":[{"batb":[[0,2.08,39.76],[1,1.21,24.75],[2,1.1,1000]],"ltp":2.2,"tv":5.5,"id":61077258}]}]}
{"op":"mcm","clk":"11926308563","pt":1724553313013,"mc":[{"id":"1.232224347","rc":[{"batb":[[0,2.1,5],[1,2.08,39.76],[2,1.21,24.75]],"ltp":2.2,"tv":5.5,"id":61077258}]}]}
{"op":"mcm","clk":"11926308754","pt":1724553316310,"mc":[{"id":"1.232224347","rc":[{"batb":[[0,2.08,39.76],[1,1.21,24.75],[2,1.1,1000]],"ltp":2.2,"tv":5.5,"id":61077258}]}]}
{"op":"mcm","clk":"11926308904","pt":1724553318731,"mc":[{"id":"1.232224347","rc":[{"batb":[[0,2.1,5],[1,2.08,39.76],[2,1.21,24.75]],"ltp":2.2,"tv":5.5,"id":61077258}]}]}
{"op":"mcm","clk":"11926309126","pt":1724553322437,"mc":[{"id":"1.232224347","rc":[{"batb":[[0,2.08,39.76],[1,1.21,24.75],[2,1.1,1000]],"ltp":2.2,"tv":5.5,"id":61077258}]}]}
{"op":"mcm","clk":"11926309266","pt":1724553324716,"mc":[{"id":"1.232224347","rc":[{"batb":[[0,2.1,5],[1,2.08,39.76],[2,1.21,24.75]],"ltp":2.2,"tv":5.5,"id":61077258}]}]}
{"op":"mcm","clk":"11926309434","pt":1724553328034,"mc":[{"id":"1.232224347","rc":[{"batb":[[0,2.08,39.76],[1,1.21,24.75],[2,1.1,1000]],"ltp":2.2,"tv":5.5,"id":61077258}]}]}
{"op":"mcm","clk":"11926309725","pt":1724553333731,"mc":[{"id":"1.232224347","rc":[{"batb":[[0,2.1,5],[1,2.08,39.76],[2,1.21,24.75]],"ltp":2.2,"tv":5.5,"id":61077258},{"batb":[[0,1.22,2.64],[1,1.21,24.75],[2,1.1,1000]],"ltp":1.8,"tv":214.75,"id":48800301}]}]}
{"op":"mcm","clk":"11926309858","pt":1724553336660,"mc":[{"id":"1.232224347","rc":[{"batb":[[0,2.08,39.76],[1,1.21,24.75],[2,1.1,1000]],"ltp":2.2,"tv":5.5,"id":61077258}]}]}
{"op":"mcm","clk":"11926310186","pt":1724553343040,"mc":[{"id":"1.232224347","rc":[{"batb":[[0,2.1,5],[1,2.08,39.76],[2,1.21,24.75]],"ltp":2.2,"tv":5.5,"id":61077258}]}]}
{"op":"mcm","clk":"11926310340","pt":1724553346340,"mc":[{"id":"1.232224347","rc":[{"batb":[[0,2.08,39.76],[1,1.21,24.75],[2,1.1,1000]],"ltp":2.2,"tv":5.5,"id":61077258}]}]}
{"op":"mcm","clk":"11926310534","pt":1724553349929,"mc":[{"id":"1.232224347","rc":[{"batb":[[0,2.1,5],[1,2.08,39.76],[2,1.21,24.75]],"ltp":2.2,"tv":5.5,"id":61077258}]}]}
{"op":"mcm","clk":"11926310690","pt":1724553353430,"mc":[{"id":"1.232224347","rc":[{"batb":[[0,2.08,39.76],[1,1.21,24.75],[2,1.1,1000]],"ltp":2.2,"tv":5.5,"id":61077258}]}]}
{"op":"mcm","clk":"11926310824","pt":1724553356559,"mc":[{"id":"1.232224347","rc":[{"batb":[[0,2.1,5],[1,2.08,39.76],[2,1.21,24.75]],"ltp":2.2,"tv":5.5,"id":61077258}]}]}
{"op":"mcm","clk":"11926310997","pt":1724553359773,"mc":[{"id":"1.232224347","rc":[{"batb":[[0,2.08,39.76],[1,1.21,24.75],[2,1.1,1000]],"ltp":2.2,"tv":5.5,"id":61077258}]}]}
{"op":"mcm","clk":"11926311274","pt":1724553363860,"mc":[{"id":"1.232224347","rc":[{"batb":[[0,2.1,5],[1,2.08,39.76],[2,1.21,24.75]],"ltp":2.2,"tv":5.5,"id":61077258}]}]}
{"op":"mcm","clk":"11926311486","pt":1724553367255,"mc":[{"id":"1.232224347","rc":[{"batb":[[0,2.08,39.76],[1,1.21,24.75],[2,1.1,1000]],"ltp":2.2,"tv":5.5,"id":61077258}]}]}
{"op":"mcm","clk":"11926311611","pt":1724553369565,"mc":[{"id":"1.232224347","rc":[{"batb":[[0,2.1,5],[1,2.08,39.76],[2,1.21,24.75]],"ltp":2.2,"tv":5.5,"id":61077258}]}]}
{"op":"mcm","clk":"11926311763","pt":1724553372858,"mc":[{"id":"1.232224347","rc":[{"batb":[[0,2.08,39.76],[1,1.21,24.75],[2,1.1,1000]],"ltp":2.2,"tv":5.5,"id":61077258}]}]}
{"op":"mcm","clk":"11926312061","pt":1724553378583,"mc":[{"id":"1.232224347","rc":[{"batb":[[0,2.1,5],[1,2.08,39.76],[2,1.21,24.75]],"ltp":2.2,"tv":5.5,"id":61077258}]}]}
{"op":"mcm","clk":"11926312222","pt":1724553381875,"mc":[{"id":"1.232224347","rc":[{"batb":[[0,2.08,39.76],[1,1.21,24.75],[2,1.1,1000]],"ltp":2.2,"tv":5.5,"id":61077258}]}]}
{"op":"mcm","clk":"11926312491","pt":1724553387070,"mc":[{"id":"1.232224347","rc":[{"batb":[[0,2.1,5],[1,2.08,39.76],[2,1.21,24.75]],"ltp":2.2,"tv":5.5,"id":61077258}]}]}
{"op":"mcm","clk":"11926312657","pt":1724553390371,"mc":[{"id":"1.232224347","rc":[{"batb":[[0,2.08,39.76],[1,1.21,24.75],[2,1.1,1000]],"ltp":2.2,"tv":5.5,"id":61077258}]}]}
{"op":"mcm","clk":"11926312898","pt":1724553394585,"mc":[{"id":"1.232224347","rc":[{"batb":[[0,2.1,5],[1,2.08,39.76],[2,1.21,24.75]],"ltp":2.2,"tv":5.5,"id":61077258}]}]}
{"op":"mcm","clk":"11926313051","pt":1724553397888,"mc":[{"id":"1.232224347","rc":[{"batb":[[0,2.08,39.76],[1,1.21,24.75],[2,1.1,1000]],"ltp":2.2,"tv":5.5,"id":61077258}]}]}
{"op":"mcm","clk":"11926313204","pt":1724553400917,"mc":[{"id":"1.232224347","rc":[{"batb":[[0,2.1,5],[1,2.08,39.76],[2,1.21,24.75]],"ltp":2.2,"tv":5.5,"id":61077258}]}]}
{"op":"mcm","clk":"11926313366","pt":1724553404208,"mc":[{"id":"1.232224347","rc":[{"batb":[[0,2.08,39.76],[1,1.21,24.75],[2,1.1,1000]],"ltp":2.2,"tv":5.5,"id":61077258}]}]}
{"op":"mcm","clk":"11926313457","pt":1724553406415,"mc":[{"id":"1.232224347","rc":[{"batb":[[0,2.1,5],[1,2.08,39.76],[2,1.21,24.75]],"ltp":2.2,"tv":5.5,"id":61077258}]}]}
{"op":"mcm","clk":"11926313603","pt":1724553409708,"mc":[{"id":"1.232224347","rc":[{"batb":[[0,2.08,39.76],[1,1.21,24.75],[2,1.1,1000]],"ltp":2.2,"tv":5.5,"id":61077258}]}]}
{"op":"mcm","clk":"11926313745","pt":1724553412807,"mc":[{"id":"1.232224347","rc":[{"batb":[[0,2.1,5],[1,2.08,39.76],[2,1.21,24.75]],"ltp":2.2,"tv":5.5,"id":61077258}]}]}
{"op":"mcm","clk":"11926313914","pt":1724553416106,"mc":[{"id":"1.232224347","rc":[{"batb":[[0,2.08,39.76],[1,1.21,24.75],[2,1.1,1000]],"ltp":2.2,"tv":5.5,"id":61077258}]}]}
{"op":"mcm","clk":"11926314378","pt":1724553424318,"mc":[{"id":"1.232224347","rc":[{"batb":[[0,2.1,5],[1,2.08,39.76],[2,1.21,24.75]],"ltp":2.2,"tv":5.5,"id":61077258}]}]}
{"op":"mcm","clk":"11926314576","pt":1724553427922,"mc":[{"id":"1.232224347","rc":[{"batb":[[0,2.08,39.76],[1,1.21,24.75],[2,1.1,1000]],"ltp":2.2,"tv":5.5,"id":61077258}]}]}
{"op":"mcm","clk":"11926314718","pt":1724553430924,"mc":[{"id":"1.232224347","rc":[{"batb":[[0,2.1,5],[1,2.08,39.76],[2,1.21,24.75]],"ltp":2.2,"tv":5.5,"id":61077258}]}]}
{"op":"mcm","clk":"11926314868","pt":1724553434254,"mc":[{"id":"1.232224347","rc":[{"batb":[[0,2.08,39.76],[1,1.21,24.75],[2,1.1,1000]],"ltp":2.2,"tv":5.5,"id":61077258}]}]}
{"op":"mcm","clk":"11926315003","pt":1724553436733,"mc":[{"id":"1.232224347","rc":[{"batb":[[0,2.1,5],[1,2.08,39.76],[2,1.21,24.75]],"ltp":2.2,"tv":5.5,"id":61077258}]}]}
{"op":"mcm","clk":"11926315176","pt":1724553440038,"mc":[{"id":"1.232224347","rc":[{"batb":[[0,2.08,39.76],[1,1.21,24.75],[2,1.1,1000]],"ltp":2.2,"tv":5.5,"id":61077258}]}]}
{"op":"mcm","clk":"11926315566","pt":1724553446638,"mc":[{"id":"1.232224347","rc":[{"batb":[[0,2.1,5],[1,2.08,39.76],[2,1.21,24.75]],"ltp":2.2,"tv":5.5,"id":61077258}]}]}
{"op":"mcm","clk":"11926315747","pt":1724553449979,"mc":[{"id":"1.232224347","rc":[{"batb":[[0,2.08,39.76],[1,1.21,24.75],[2,1.1,1000]],"ltp":2.2,"tv":5.5,"id":61077258}]}]}
{"op":"mcm","clk":"11926316125","pt":1724553456748,"mc":[{"id":"1.232224347","rc":[{"batb":[[0,2.1,5],[1,2.08,39.76],[2,1.21,24.75]],"ltp":2.2,"tv":5.5,"id":61077258}]}]}
{"op":"mcm","clk":"11926316307","pt":1724553460146,"mc":[{"id":"1.232224347","rc":[{"batb":[[0,2.08,39.76],[1,1.21,24.75],[2,1.1,1000]],"ltp":2.2,"tv":5.5,"id":61077258}]}]}
{"op":"mcm","clk":"11926316476","pt":1724553463185,"mc":[{"id":"1.232224347","rc":[{"batb":[[0,2.1,5],[1,2.08,39.76],[2,1.21,24.75]],"ltp":2.2,"tv":5.5,"id":61077258}]}]}
{"op":"mcm","clk":"11926316645","pt":1724553466481,"mc":[{"id":"1.232224347","rc":[{"batb":[[0,2.08,39.76],[1,1.21,24.75],[2,1.1,1000]],"ltp":2.2,"tv":5.5,"id":61077258}]}]}
{"op":"mcm","clk":"11926316759","pt":1724553469061,"mc":[{"id":"1.232224347","rc":[{"batb":[[0,2.1,5],[1,2.08,39.76],[2,1.21,24.75]],"ltp":2.2,"tv":5.5,"id":61077258}]}]}
{"op":"mcm","clk":"11926316943","pt":1724553472361,"mc":[{"id":"1.232224347","rc":[{"batb":[[0,2.08,39.76],[1,1.21,24.75],[2,1.1,1000]],"ltp":2.2,"tv":5.5,"id":61077258}]}]}
{"op":"mcm","clk":"11926317222","pt":1724553477878,"mc":[{"id":"1.232224347","rc":[{"batb":[[0,2.1,5],[1,2.08,39.76],[2,1.21,24.75]],"ltp":2.2,"tv":5.5,"id":61077258}]}]}
{"op":"mcm","clk":"11926317390","pt":1724553481381,"mc":[{"id":"1.232224347","rc":[{"batb":[[0,2.08,39.76],[1,1.21,24.75],[2,1.1,1000]],"ltp":2.2,"tv":5.5,"id":61077258}]}]}
{"op":"mcm","clk":"11926317604","pt":1724553485090,"mc":[{"id":"1.232224347","rc":[{"batb":[[0,2.1,5],[1,2.08,39.76],[2,1.21,24.75]],"ltp":2.2,"tv":5.5,"id":61077258}]}]}
{"op":"mcm","clk":"11926317810","pt":1724553488393,"mc":[{"id":"1.232224347","rc":[{"batb":[[0,2.08,39.76],[1,1.21,24.75],[2,1.1,1000]],"ltp":2.2,"tv":5.5,"id":61077258}]}]}
{"op":"mcm","clk":"11926318020","pt":1724553491507,"mc":[{"id":"1.232224347","rc":[{"batb":[[0,2.1,5],[1,2.08,39.76],[2,1.21,24.75]],"ltp":2.2,"tv":5.5,"id":61077258}]}]}
{"op":"mcm","clk":"11926318237","pt":1724553494800,"mc":[{"id":"1.232224347","rc":[{"batb":[[0,2.08,39.76],[1,1.21,24.75],[2,1.1,1000]],"ltp":2.2,"tv":5.5,"id":61077258}]}]}
{"op":"mcm","clk":"11926318581","pt":1724553501104,"mc":[{"id":"1.232224347","rc":[{"batb":[[0,2.1,5],[1,2.08,39.76],[2,1.21,24.75]],"ltp":2.2,"tv":5.5,"id":61077258}]}]}
{"op":"mcm","clk":"11926318781","pt":1724553504615,"mc":[{"id":"1.232224347","rc":[{"batb":[[0,2.08,39.76],[1,1.21,24.75],[2,1.1,1000]],"ltp":2.2,"tv":5.5,"id":61077258}]}]}
{"op":"mcm","clk":"11926318931","pt":1724553506997,"mc":[{"id":"1.232224347","rc":[{"batb":[[0,2.1,5],[1,2.08,39.76],[2,1.21,24.75]],"ltp":2.2,"tv":5.5,"id":61077258}]}]}
{"op":"mcm","clk":"11926319100","pt":1724553510236,"mc":[{"id":"1.232224347","rc":[{"batb":[[0,2.08,39.76],[1,1.21,24.75],[2,1.1,1000]],"ltp":2.2,"tv":5.5,"id":61077258}]}]}
{"op":"mcm","clk":"11926319256","pt":1724553512613,"mc":[{"id":"1.232224347","rc":[{"batb":[[0,2.1,5],[1,2.08,39.76],[2,1.21,24.75]],"ltp":2.2,"tv":5.5,"id":61077258}]}]}
{"op":"mcm","clk":"11926319440","pt":1724553515919,"mc":[{"id":"1.232224347","rc":[{"batb":[[0,2.08,39.76],[1,1.21,24.75],[2,1.1,1000]],"ltp":2.2,"tv":5.5,"id":61077258}]}]}
{"op":"mcm","clk":"11926319576","pt":1724553518137,"mc":[{"id":"1.232224347","rc":[{"batb":[[0,2.1,5],[1,2.08,39.76],[2,1.21,24.75]],"ltp":2.2,"tv":5.5,"id":61077258}]}]}
{"op":"mcm","clk":"11926319755","pt":1724553521537,"mc":[{"id":"1.232224347","rc":[{"batb":[[0,2.08,39.76],[1,1.21,24.75],[2,1.1,1000]],"ltp":2.2,"tv":5.5,"id":61077258}]}]}
{"op":"mcm","clk":"11926319881","pt":1724553523709,"mc":[{"id":"1.232224347","rc":[{"batb":[[0,2.1,5],[1,2.08,39.76],[2,1.21,24.75]],"ltp":2.2,"tv":5.5,"id":61077258}]}]}
{"op":"mcm","clk":"11926320086","pt":1724553527019,"mc":[{"id":"1.232224347","rc":[{"batb":[[0,2.08,39.76],[1,1.21,24.75],[2,1.1,1000]],"ltp":2.2,"tv":5.5,"id":61077258}]}]}
{"op":"mcm","clk":"11926320302","pt":1724553530652,"mc":[{"id":"1.232224347","rc":[{"batb":[[0,2.1,5],[1,2.08,39.76],[2,1.21,24.75]],"ltp":2.2,"tv":5.5,"id":61077258}]}]}
{"op":"mcm","clk":"11926320518","pt":1724553533948,"mc":[{"id":"1.232224347","rc":[{"batb":[[0,2.08,39.76],[1,1.21,24.75],[2,1.1,1000]],"ltp":2.2,"tv":5.5,"id":61077258}]}]}
{"op":"mcm","clk":"11926320625","pt":1724553536732,"mc":[{"id":"1.232224347","rc":[{"batb":[[0,2.1,5],[1,2.08,39.76],[2,1.21,24.75]],"ltp":2.2,"tv":5.5,"id":61077258}]}]}
{"op":"mcm","clk":"11926320825","pt":1724553540240,"mc":[{"id":"1.232224347","rc":[{"batb":[[0,2.08,39.76],[1,1.21,24.75],[2,1.1,1000]],"ltp":2.2,"tv":5.5,"id":61077258}]}]}
{"op":"mcm","clk":"11926321005","pt":1724553543143,"mc":[{"id":"1.232224347","rc":[{"batb":[[0,2.1,5],[1,2.08,39.76],[2,1.21,24.75]],"ltp":2.2,"tv":5.5,"id":61077258}]}]}
{"op":"mcm","clk":"11926321149","pt":1724553546550,"mc":[{"id":"1.232224347","rc":[{"batb":[[0,2.08,39.76],[1,1.21,24.75],[2,1.1,1000]],"ltp":2.2,"tv":5.5,"id":61077258}]}]}
{"op":"mcm","clk":"11926321342","pt":1724553551145,"mc":[{"id":"1.232224347","rc":[{"batb":[[0,2.1,5],[1,2.08,39.76],[2,1.21,24.75]],"ltp":2.2,"tv":5.5,"id":61077258}]}]}
{"op":"mcm","clk":"11926321487","pt":1724553554452,"mc":[{"id":"1.232224347","rc":[{"batb":[[0,2.08,39.76],[1,1.21,24.75],[2,1.1,1000]],"ltp":2.2,"tv":5.5,"id":61077258}]}]}
{"op":"mcm","clk":"11926321731","pt":1724553559083,"mc":[{"id":"1.232224347","rc":[{"batb":[[0,2.1,5],[1,2.08,39.76],[2,1.21,24.75]],"ltp":2.2,"tv":5.5,"id":61077258}]}]}
{"op":"mcm","clk":"11926321876","pt":1724553562376,"mc":[{"id":"1.232224347","rc":[{"batb":[[0,2.08,39.76],[1,1.21,24.75],[2,1.1,1000]],"ltp":2.2,"tv":5.5,"id":61077258}]}]}
{"op":"mcm","clk":"11926322287","pt":1724553571262,"mc":[{"id":"1.232224347","rc":[{"batb":[[0,2.1,5],[1,2.08,39.76],[2,1.21,24.75]],"ltp":2.2,"tv":5.5,"id":61077258}]}]}
{"op":"mcm","clk":"11926322408","pt":1724553574664,"mc":[{"id":"1.232224347","rc":[{"batb":[[0,2.08,39.76],[1,1.21,24.75],[2,1.1,1000]],"ltp":2.2,"tv":5.5,"id":61077258}]}]}
{"op":"mcm","clk":"11926322490","pt":1724553577388,"mc":[{"id":"1.232224347","rc":[{"batb":[[0,2.1,5],[1,2.08,39.76],[2,1.21,24.75]],"ltp":2.2,"tv":5.5,"id":61077258}]}]}
{"op":"mcm","clk":"11926322611","pt":1724553580677,"mc":[{"id":"1.232224347","rc":[{"batb":[[0,2.08,39.76],[1,1.21,24.75],[2,1.1,1000]],"ltp":2.2,"tv":5.5,"id":61077258}]}]}
{"op":"mcm","clk":"11926322791","pt":1724553585815,"mc":[{"id":"1.232224347","rc":[{"batb":[[0,2.1,5],[1,2.08,39.76],[2,1.21,24.75]],"ltp":2.2,"tv":5.5,"id":61077258}]}]}
{"op":"mcm","clk":"11926322925","pt":1724553589113,"mc":[{"id":"1.232224347","rc":[{"batb":[[0,2.08,39.76],[1,1.21,24.75],[2,1.1,1000]],"ltp":2.2,"tv":5.5,"id":61077258}]}]}
{"op":"mcm","clk":"11926323290","pt":1724553597906,"mc":[{"id":"1.232224347","rc":[{"batb":[[0,2.1,5],[1,2.08,39.76],[2,1.21,24.75]],"ltp":2.2,"tv":5.5,"id":61077258}]}]}
{"op":"mcm","clk":"11926323448","pt":1724553601098,"mc":[{"id":"1.232224347","rc":[{"batb":[[0,2.08,39.76],[1,1.21,24.75],[2,1.1,1000]],"ltp":2.2,"tv":5.5,"id":61077258}]}]}
{"op":"mcm","clk":"11926323582","pt":1724553603726,"mc":[{"id":"1.232224347","rc":[{"batb":[[0,2.1,5],[1,2.08,39.76],[2,1.21,24.75]],"ltp":2.2,"tv":5.5,"id":61077258}]}]}
{"op":"mcm","clk":"11926323765","pt":1724553607022,"mc":[{"id":"1.232224347","rc":[{"batb":[[0,2.08,39.76],[1,1.21,24.75],[2,1.1,1000]],"ltp":2.2,"tv":5.5,"id":61077258}]}]}
{"op":"mcm","clk":"11926324001","pt":1724553612803,"mc":[{"id":"1.232224347","rc":[{"batb":[[0,2.1,5],[1,2.08,39.76],[2,1.21,24.75]],"ltp":2.2,"tv":5.5,"id":61077258}]}]}
{"op":"mcm","clk":"11926324184","pt":1724553616352,"mc":[{"id":"1.232224347","rc":[{"batb":[[0,2.08,39.76],[1,1.21,24.75],[2,1.1,1000]],"ltp":2.2,"tv":5.5,"id":61077258}]}]}
{"op":"mcm","clk":"11926324469","pt":1724553622055,"mc":[{"id":"1.232224347","rc":[{"batb":[[0,2.1,5],[1,2.08,39.76],[2,1.21,24.75]],"ltp":2.2,"tv":5.5,"id":61077258}]}]}
{"op":"mcm","clk":"11926324629","pt":1724553625461,"mc":[{"id":"1.232224347","rc":[{"batb":[[0,2.08,39.76],[1,1.21,24.75],[2,1.1,1000]],"ltp":2.2,"tv":5.5,"id":61077258}]}]}
{"op":"mcm","clk":"11926324835","pt":1724553630153,"mc":[{"id":"1.232224347","rc":[{"batb":[[0,2.1,5],[1,2.08,39.76],[2,1.21,24.75]],"ltp":2.2,"tv":5.5,"id":61077258}]}]}
{"op":"mcm","clk":"11926325009","pt":1724553633657,"mc":[{"id":"1.232224347","rc":[{"batb":[[0,2.08,39.76],[1,1.21,24.75],[2,1.1,1000]],"ltp":2.2,"tv":5.5,"id":61077258}]}]}
{"op":"mcm","clk":"11926325362","pt":1724553639643,"mc":[{"id":"1.232224347","rc":[{"batb":[[0,2.1,5],[1,2.08,39.76],[2,1.21,24.75]],"ltp":2.2,"tv":5.5,"id":61077258}]}]}
{"op":"mcm","clk":"11926325531","pt":1724553643037,"mc":[{"id":"1.232224347","rc":[{"batb":[[0,2.08,39.76],[1,1.21,24.75],[2,1.1,1000]],"ltp":2.2,"tv":5.5,"id":61077258}]}]}
{"op":"mcm","clk":"11926325703","pt":1724553646337,"mc":[{"id":"1.232224347","rc":[{"batb":[[0,2.1,5],[1,2.08,39.76],[2,1.21,24.75]],"ltp":2.2,"tv":5.5,"id":61077258}]}]}
{"op":"mcm","clk":"11926325887","pt":1724553649849,"mc":[{"id":"1.232224347","rc":[{"batb":[[0,2.08,39.76],[1,1.21,24.75],[2,1.1,1000]],"ltp":2.2,"tv":5.5,"id":61077258}]}]}
{"op":"mcm","clk":"11926326016","pt":1724553652169,"mc":[{"id":"1.232224347","rc":[{"batb":[[0,2.1,5],[1,2.08,39.76],[2,1.21,24.75]],"ltp":2.2,"tv":5.5,"id":61077258}]}]}
{"op":"mcm","clk":"11926326171","pt":1724553655675,"mc":[{"id":"1.232224347","rc":[{"batb":[[0,2.08,39.76],[1,1.21,24.75],[2,1.1,1000]],"ltp":2.2,"tv":5.5,"id":61077258}]}]}
{"op":"mcm","clk":"11926326282","pt":1724553658361,"mc":[{"id":"1.232224347","rc":[{"batb":[[0,2.1,5],[1,2.08,39.76],[2,1.21,24.75]],"ltp":2.2,"tv":5.5,"id":61077258}]}]}
{"op":"mcm","clk":"11926326498","pt":1724553663154,"mc":[{"id":"1.232224347","rc":[{"batb":[[0,2.08,39.76],[1,1.21,24.75],[2,1.1,1000]],"ltp":2.2,"tv":5.5,"id":61077258}]}]}
{"op":"mcm","clk":"11926326690","pt":1724553666759,"mc":[{"id":"1.232224347","rc":[{"batb":[[0,2.1,5],[1,2.08,39.76],[2,1.21,24.75]],"ltp":2.2,"tv":5.5,"id":61077258}]}]}
{"op":"mcm","clk":"11926326896","pt":1724553670265,"mc":[{"id":"1.232224347","rc":[{"batb":[[0,2.08,39.76],[1,1.21,24.75],[2,1.1,1000]],"ltp":2.2,"tv":5.5,"id":61077258}]}]}
{"op":"mcm","clk":"11926327092","pt":1724553673975,"mc":[{"id":"1.232224347","rc":[{"batb":[[0,2.1,5],[1,2.08,39.76],[2,1.21,24.75]],"ltp":2.2,"tv":5.5,"id":61077258}]}]}
{"op":"mcm","clk":"11926327265","pt":1724553677281,"mc":[{"id":"1.232224347","rc":[{"batb":[[0,2.08,39.76],[1,1.21,24.75],[2,1.1,1000]],"ltp":2.2,"tv":5.5,"id":61077258}]}]}
{"op":"mcm","clk":"11926327446","pt":1724553680676,"mc":[{"id":"1.232224347","rc":[{"batb":[[0,2.1,5],[1,2.08,39.76],[2,1.21,24.75]],"ltp":2.2,"tv":5.5,"id":61077258}]}]}
{"op":"mcm","clk":"11926327630","pt":1724553684171,"mc":[{"id":"1.232224347","rc":[{"batb":[[0,2.08,39.76],[1,1.21,24.75],[2,1.1,1000]],"ltp":2.2,"tv":5.5,"id":61077258}]}]}
{"op":"mcm","clk":"11926327809","pt":1724553687578,"mc":[{"id":"1.232224347","rc":[{"batb":[[0,2.1,5],[1,2.08,39.76],[2,1.21,24.75]],"ltp":2.2,"tv":5.5,"id":61077258}]}]}
{"op":"mcm","clk":"11926327962","pt":1724553690882,"mc":[{"id":"1.232224347","rc":[{"batb":[[0,2.08,39.76],[1,1.21,24.75],[2,1.1,1000]],"ltp":2.2,"tv":5.5,"id":61077258}]}]}
{"op":"mcm","clk":"11926328179","pt":1724553695617,"mc":[{"id":"1.232224347","rc":[{"batb":[[0,2.1,5],[1,2.08,39.76],[2,1.21,24.75]],"ltp":2.2,"tv":5.5,"id":61077258}]}]}
{"op":"mcm","clk":"11926328349","pt":1724553699118,"mc":[{"id":"1.232224347","rc":[{"batb":[[0,2.08,39.76],[1,1.21,24.75],[2,1.1,1000]],"ltp":2.2,"tv":5.5,"id":61077258}]}]}
{"op":"mcm","clk":"11926328645","pt":1724553704602,"mc":[{"id":"1.232224347","rc":[{"batb":[[0,2.1,5],[1,2.08,39.76],[2,1.21,24.75]],"ltp":2.2,"tv":5.5,"id":61077258}]}]}
{"op":"mcm","clk":"11926328830","pt":1724553708000,"mc":[{"id":"1.232224347","rc":[{"batb":[[0,2.08,39.76],[1,1.21,24.75],[2,1.1,1000]],"ltp":2.2,"tv":5.5,"id":61077258}]}]}
{"op":"mcm","clk":"11926329012","pt":1724553711033,"mc":[{"id":"1.232224347","rc":[{"batb":[[0,2.1,5],[1,2.08,39.76],[2,1.21,24.75]],"ltp":2.2,"tv":5.5,"id":61077258}]}]}
{"op":"mcm","clk":"11926329213","pt":1724553714559,"mc":[{"id":"1.232224347","rc":[{"batb":[[0,2.08,39.76],[1,1.21,24.75],[2,1.1,1000]],"ltp":2.2,"tv":5.5,"id":61077258}]}]}
{"op":"mcm","clk":"11926329471","pt":1724553718943,"mc":[{"id":"1.232224347","rc":[{"batb":[[0,2.1,5],[1,2.08,39.76],[2,1.21,24.75]],"ltp":2.2,"tv":5.5,"id":61077258}]}]}
{"op":"mcm","clk":"11926329677","pt":1724553722432,"mc":[{"id":"1.232224347","rc":[{"batb":[[0,2.08,39.76],[1,1.21,24.75],[2,1.1,1000]],"ltp":2.2,"tv":5.5,"id":61077258}]}]}
{"op":"mcm","clk":"11926330180","pt":1724553731137,"mc":[{"id":"1.232224347","rc":[{"batb":[[0,2.1,5],[1,2.08,39.76],[2,1.21,24.75]],"ltp":2.2,"tv":5.5,"id":61077258}]}]}
{"op":"mcm","clk":"11926330397","pt":1724553734646,"mc":[{"id":"1.232224347","rc":[{"batb":[[0,2.08,39.76],[1,1.21,24.75],[2,1.1,1000]],"ltp":2.2,"tv":5.5,"id":61077258}]}]}
{"op":"mcm","clk":"11926331014","pt":1724553743541,"mc":[{"id":"1.232224347","rc":[{"batb":[[0,2.1,5],[1,2.08,39.76],[2,1.21,24.75]],"ltp":2.2,"tv":5.5,"id":61077258}]}]}
{"op":"mcm","clk":"11926331287","pt":1724553747058,"mc":[{"id":"1.232224347","rc":[{"batb":[[0,2.08,39.76],[1,1.21,24.75],[2,1.1,1000]],"ltp":2.2,"tv":5.5,"id":61077258}]}]}
{"op":"mcm","clk":"11926332069","pt":1724553758766,"mc":[{"id":"1.232224347","rc":[{"batb":[[0,2.1,5],[1,2.08,39.76],[2,1.21,24.75]],"ltp":2.2,"tv":5.5,"id":61077258}]}]}
{"op":"mcm","clk":"11926332294","pt":1724553762169,"mc":[{"id":"1.232224347","rc":[{"batb":[[0,2.08,39.76],[1,1.21,24.75],[2,1.1,1000]],"ltp":2.2,"tv":5.5,"id":61077258}]}]}
{"op":"mcm","clk":"11926332473","pt":1724553765264,"mc":[{"id":"1.232224347","rc":[{"batb":[[0,2.1,5],[1,2.08,39.76],[2,1.21,24.75]],"ltp":2.2,"tv":5.5,"id":61077258}]}]}
{"op":"mcm","clk":"11926332678","pt":1724553768779,"mc":[{"id":"1.232224347","rc":[{"batb":[[0,2.08,39.76],[1,1.21,24.75],[2,1.1,1000]],"ltp":2.2,"tv":5.5,"id":61077258}]}]}
{"op":"mcm","clk":"11926332978","pt":1724553773796,"mc":[{"id":"1.232224347","rc":[{"batb":[[0,2.1,5],[1,2.08,39.76],[2,1.21,24.75]],"ltp":2.2,"tv":5.5,"id":61077258}]}]}
{"op":"mcm","clk":"11926333179","pt":1724553777093,"mc":[{"id":"1.232224347","rc":[{"batb":[[0,2.08,39.76],[1,1.21,24.75],[2,1.1,1000]],"ltp":2.2,"tv":5.5,"id":61077258}]}]}
{"op":"mcm","clk":"11926333427","pt":1724553781415,"mc":[{"id":"1.232224347","rc":[{"batb":[[0,2.1,5],[1,2.08,39.76],[2,1.21,24.75]],"ltp":2.2,"tv":5.5,"id":61077258}]}]}
{"op":"mcm","clk":"11926333678","pt":1724553784990,"mc":[{"id":"1.232224347","rc":[{"batb":[[0,2.08,39.76],[1,1.21,24.75],[2,1.1,1000]],"ltp":2.2,"tv":5.5,"id":61077258}]}]}
{"op":"mcm","clk":"11926333858","pt":1724553787531,"mc":[{"id":"1.232224347","rc":[{"batb":[[0,2.1,5],[1,2.08,39.76],[2,1.21,24.75]],"ltp":2.2,"tv":5.5,"id":61077258}]}]}
{"op":"mcm","clk":"11926334078","pt":1724553791205,"mc":[{"id":"1.232224347","rc":[{"batb":[[0,2.08,39.76],[1,1.21,24.75],[2,1.1,1000]],"ltp":2.2,"tv":5.5,"id":61077258}]}]}
{"op":"mcm","clk":"11926334282","pt":1724553794723,"mc":[{"id":"1.232224347","rc":[{"batb":[[0,2.1,5],[1,2.08,39.76],[2,1.21,24.75]],"ltp":2.2,"tv":5.5,"id":61077258}]}]}
{"op":"mcm","clk":"11926334490","pt":1724553797925,"mc":[{"id":"1.232224347","rc":[{"batb":[[0,2.08,39.76],[1,1.21,24.75],[2,1.1,1000]],"ltp":2.2,"tv":5.5,"id":61077258}]}]}
{"op":"mcm","clk":"11926334730","pt":1724553802153,"mc":[{"id":"1.232224347","rc":[{"batb":[[0,2.1,5],[1,2.08,39.76],[2,1.21,24.75]],"ltp":2.2,"tv":5.5,"id":61077258}]}]}
{"op":"mcm","clk":"11926334938","pt":1724553805423,"mc":[{"id":"1.232224347","rc":[{"batb":[[0,2.08,39.76],[1,1.21,24.75],[2,1.1,1000]],"ltp":2.2,"tv":5.5,"id":61077258}]}]}
{"op":"mcm","clk":"11926335110","pt":1724553808151,"mc":[{"id":"1.232224347","rc":[{"batb":[[0,2.1,5],[1,2.08,39.76],[2,1.21,24.75]],"ltp":2.2,"tv":5.5,"id":61077258}]}]}
{"op":"mcm","clk":"11926335306","pt":1724553811444,"mc":[{"id":"1.232224347","rc":[{"batb":[[0,2.08,39.76],[1,1.21,24.75],[2,1.1,1000]],"ltp":2.2,"tv":5.5,"id":61077258}]}]}
{"op":"mcm","clk":"11926335670","pt":1724553816242,"mc":[{"id":"1.232224347","rc":[{"batb":[[0,2.1,5],[1,2.08,39.76],[2,1.21,24.75]],"ltp":2.2,"tv":5.5,"id":61077258}]}]}
{"op":"mcm","clk":"11926335868","pt":1724553819533,"mc":[{"id":"1.232224347","rc":[{"batb":[[0,2.08,39.76],[1,1.21,24.75],[2,1.1,1000]],"ltp":2.2,"tv":5.5,"id":61077258}]}]}
{"op":"mcm","clk":"11926336058","pt":1724553822161,"mc":[{"id":"1.232224347","rc":[{"batb":[[0,2.1,5],[1,2.08,39.76],[2,1.21,24.75]],"ltp":2.2,"tv":5.5,"id":61077258}]}]}
{"op":"mcm","clk":"11926336282","pt":1724553825561,"mc":[{"id":"1.232224347","rc":[{"batb":[[0,2.08,39.76],[1,1.21,24.75],[2,1.1,1000]],"ltp":2.2,"tv":5.5,"id":61077258}]}]}
{"op":"mcm","clk":"11926336509","pt":1724553829156,"mc":[{"id":"1.232224347","rc":[{"batb":[[0,2.1,5],[1,2.08,39.76],[2,1.21,24.75]],"ltp":2.2,"tv":5.5,"id":61077258}]}]}
{"op":"mcm","clk":"11926336716","pt":1724553832453,"mc":[{"id":"1.232224347","rc":[{"batb":[[0,2.08,39.76],[1,1.21,24.75],[2,1.1,1000]],"ltp":2.2,"tv":5.5,"id":61077258}]}]}
{"op":"mcm","clk":"11926337186","pt":1724553839147,"mc":[{"id":"1.232224347","rc":[{"batb":[[0,2.1,5],[1,2.08,39.76],[2,1.21,24.75]],"ltp":2.2,"tv":5.5,"id":61077258}]}]}
{"op":"mcm","clk":"11926337421","pt":1724553842485,"mc":[{"id":"1.232224347","rc":[{"batb":[[0,2.08,39.76],[1,1.21,24.75],[2,1.1,1000]],"ltp":2.2,"tv":5.5,"id":61077258}]}]}
{"op":"mcm","clk":"11926338046","pt":1724553850471,"mc":[{"id":"1.232224347","rc":[{"batb":[[0,2.1,5],[1,2.08,39.76],[2,1.21,24.75]],"ltp":2.2,"tv":5.5,"id":61077258}]}]}
{"op":"mcm","clk":"11926338125","pt":1724553851765,"mc":[{"id":"1.232224347","rc":[{"batb":[[0,1.21,25.63],[1,1.1,1000],[2,1.05,200]],"ltp":1.8,"tv":214.75,"id":48800301}]}]}
{"op":"mcm","clk":"11926338137","pt":1724553851971,"mc":[{"id":"1.232224347","rc":[{"batb":[[0,1.25,1.76],[1,1.21,25.63],[2,1.1,1000]],"ltp":1.8,"tv":214.75,"id":48800301}]}]}
{"op":"mcm","clk":"11926338239","pt":1724553853669,"mc":[{"id":"1.232224347","rc":[{"batb":[[0,2.08,39.76],[1,1.21,24.75],[2,1.1,1000]],"ltp":2.2,"tv":5.5,"id":61077258}]}]}
{"op":"mcm","clk":"11926338923","pt":1724553862804,"mc":[{"id":"1.232224347","rc":[{"batb":[[0,2.1,5],[1,2.08,39.76],[2,1.21,24.75]],"ltp":2.2,"tv":5.5,"id":61077258}]}]}
{"op":"mcm","clk":"11926339167","pt":1724553866011,"mc":[{"id":"1.232224347","rc":[{"batb":[[0,2.08,39.76],[1,1.21,24.75],[2,1.1,1000]],"ltp":2.2,"tv":5.5,"id":61077258}]}]}
{"op":"mcm","clk":"11926339658","pt":1724553874326,"mc":[{"id":"1.232224347","rc":[{"batb":[[0,2.1,5],[1,2.08,39.76],[2,1.21,24.75]],"ltp":2.2,"tv":5.5,"id":61077258}]}]}
{"op":"mcm","clk":"11926339859","pt":1724553877728,"mc":[{"id":"1.232224347","rc":[{"batb":[[0,2.08,39.76],[1,1.21,24.75],[2,1.1,1000]],"ltp":2.2,"tv":5.5,"id":61077258}]}]}
{"op":"mcm","clk":"11926340221","pt":1724553883342,"mc":[{"id":"1.232224347","rc":[{"batb":[[0,2.1,5],[1,2.08,39.76],[2,1.21,24.75]],"ltp":2.2,"tv":5.5,"id":61077258}]}]}
{"op":"mcm","clk":"11926340414","pt":1724553886636,"mc":[{"id":"1.232224347","rc":[{"batb":[[0,2.08,39.76],[1,1.21,24.75],[2,1.1,1000]],"ltp":2.2,"tv":5.5,"id":61077258}]}]}
{"op":"mcm","clk":"11926341085","pt":1724553897139,"mc":[{"id":"1.232224347","rc":[{"batb":[[0,2.1,5],[1,2.08,39.76],[2,1.21,24.75]],"ltp":2.2,"tv":5.5,"id":61077258}]}]}
{"op":"mcm","clk":"11926341278","pt":1724553900352,"mc":[{"id":"1.232224347","rc":[{"batb":[[0,2.08,39.76],[1,1.21,24.75],[2,1.1,1000]],"ltp":2.2,"tv":5.5,"id":61077258}]}]}
{"op":"mcm","clk":"11926341439","pt":1724553902761,"mc":[{"id":"1.232224347","rc":[{"batb":[[0,2.1,5],[1,2.08,39.76],[2,1.21,24.75]],"ltp":2.2,"tv":5.5,"id":61077258}]}]}
{"op":"mcm","clk":"11926341633","pt":1724553905917,"mc":[{"id":"1.232224347","rc":[{"batb":[[0,2.08,39.76],[1,1.21,24.75],[2,1.1,1000]],"ltp":2.2,"tv":5.5,"id":61077258}]}]}
{"op":"mcm","clk":"11926341851","pt":1724553909337,"mc":[{"id":"1.232224347","rc":[{"batb":[[0,2.1,5],[1,2.08,39.76],[2,1.21,24.75]],"ltp":2.2,"tv":5.5,"id":61077258}]}]}
{"op":"mcm","clk":"11926342046","pt":1724553912543,"mc":[{"id":"1.232224347","rc":[{"batb":[[0,2.08,39.76],[1,1.21,24.75],[2,1.1,1000]],"ltp":2.2,"tv":5.5,"id":61077258}]}]}
{"op":"mcm","clk":"11926342253","pt":1724553915749,"mc":[{"id":"1.232224347","rc":[{"batb":[[0,2.1,5],[1,2.08,39.76],[2,1.21,24.75]],"ltp":2.2,"tv":5.5,"id":61077258}]}]}
{"op":"mcm","clk":"11926342502","pt":1724553919066,"mc":[{"id":"1.232224347","rc":[{"batb":[[0,2.08,39.76],[1,1.21,24.75],[2,1.1,1000]],"ltp":2.2,"tv":5.5,"id":61077258}]}]}
{"op":"mcm","clk":"11926342776","pt":1724553923144,"mc":[{"id":"1.232224347","rc":[{"batb":[[0,2.1,5],[1,2.08,39.76],[2,1.21,24.75]],"ltp":2.2,"tv":5.5,"id":61077258}]}]}
{"op":"mcm","clk":"11926342988","pt":1724553926441,"mc":[{"id":"1.232224347","rc":[{"batb":[[0,2.08,39.76],[1,1.21,24.75],[2,1.1,1000]],"ltp":2.2,"tv":5.5,"id":61077258}]}]}
{"op":"mcm","clk":"11926343240","pt":1724553930153,"mc":[{"id":"1.232224347","rc":[{"batb":[[0,2.1,5],[1,2.08,39.76],[2,1.21,24.75]],"ltp":2.2,"tv":5.5,"id":61077258}]}]}
{"op":"mcm","clk":"11926343486","pt":1724553933364,"mc":[{"id":"1.232224347","rc":[{"batb":[[0,2.08,39.76],[1,1.21,24.75],[2,1.1,1000]],"ltp":2.2,"tv":5.5,"id":61077258}]}]}
{"op":"mcm","clk":"11926343633","pt":1724553935687,"mc":[{"id":"1.232224347","rc":[{"batb":[[0,2.1,5],[1,2.08,39.76],[2,1.21,24.75]],"ltp":2.2,"tv":5.5,"id":61077258}]}]}
{"op":"mcm","clk":"11926343843","pt":1724553938860,"mc":[{"id":"1.232224347","rc":[{"batb":[[0,2.08,39.76],[1,1.21,24.75],[2,1.1,1000]],"ltp":2.2,"tv":5.5,"id":61077258}]}]}
{"op":"mcm","clk":"11926344086","pt":1724553942174,"mc":[{"id":"1.232224347","rc":[{"batb":[[0,2.1,5],[1,2.08,39.76],[2,1.21,24.75]],"ltp":2.2,"tv":5.5,"id":61077258}]}]}
{"op":"mcm","clk":"11926344346","pt":1724553945381,"mc":[{"id":"1.232224347","rc":[{"batb":[[0,2.08,39.76],[1,1.21,24.75],[2,1.1,1000]],"ltp":2.2,"tv":5.5,"id":61077258}]}]}
{"op":"mcm","clk":"11926344853","pt":1724553954002,"mc":[{"id":"1.232224347","rc":[{"batb":[[0,2.1,5],[1,2.08,39.76],[2,1.21,24.75]],"ltp":2.2,"tv":5.5,"id":61077258}]}]}
{"op":"mcm","clk":"11926345055","pt":1724553957277,"mc":[{"id":"1.232224347","rc":[{"batb":[[0,2.08,39.76],[1,1.21,24.75],[2,1.1,1000]],"ltp":2.2,"tv":5.5,"id":61077258}]}]}
{"op":"mcm","clk":"11926346032","pt":1724553973041,"mc":[{"id":"1.232224347","rc":[{"batb":[[0,2.1,5],[1,2.08,39.76],[2,1.21,24.75]],"ltp":2.2,"tv":5.5,"id":61077258}]}]}
{"op":"mcm","clk":"11926346247","pt":1724553976403,"mc":[{"id":"1.232224347","rc":[{"batb":[[0,2.08,39.76],[1,1.21,24.75],[2,1.1,1000]],"ltp":2.2,"tv":5.5,"id":61077258}]}]}
{"op":"mcm","clk":"11926346451","pt":1724553979405,"mc":[{"id":"1.232224347","rc":[{"batb":[[0,2.1,5],[1,2.08,39.76],[2,1.21,24.75]],"ltp":2.2,"tv":5.5,"id":61077258}]}]}
{"op":"mcm","clk":"11926346759","pt":1724553982618,"mc":[{"id":"1.232224347","rc":[{"batb":[[0,2.08,39.76],[1,1.21,24.75],[2,1.1,1000]],"ltp":2.2,"tv":5.5,"id":61077258}]}]}
{"op":"mcm","clk":"11926346955","pt":1724553985046,"mc":[{"id":"1.232224347","rc":[{"batb":[[0,2.1,5],[1,2.08,39.76],[2,1.21,24.75]],"ltp":2.2,"tv":5.5,"id":61077258}]}]}
{"op":"mcm","clk":"11926347169","pt":1724553988337,"mc":[{"id":"1.232224347","rc":[{"batb":[[0,2.08,39.76],[1,1.21,24.75],[2,1.1,1000]],"ltp":2.2,"tv":5.5,"id":61077258}]}]}
{"op":"mcm","clk":"11926347468","pt":1724553992941,"mc":[{"id":"1.232224347","rc":[{"batb":[[0,2.1,5],[1,2.08,39.76],[2,1.21,24.75]],"ltp":2.2,"tv":5.5,"id":61077258}]}]}
{"op":"mcm","clk":"11926347690","pt":1724553996257,"mc":[{"id":"1.232224347","rc":[{"batb":[[0,2.08,39.76],[1,1.21,24.75],[2,1.1,1000]],"ltp":2.2,"tv":5.5,"id":61077258}]}]}
{"op":"mcm","clk":"11926348002","pt":1724554000861,"mc":[{"id":"1.232224347","rc":[{"batb":[[0,2.1,5],[1,2.08,39.76],[2,1.21,24.75]],"ltp":2.2,"tv":5.5,"id":61077258}]}]}
{"op":"mcm","clk":"11926348204","pt":1724554004026,"mc":[{"id":"1.232224347","rc":[{"batb":[[0,2.08,39.76],[1,1.21,24.75],[2,1.1,1000]],"ltp":2.2,"tv":5.5,"id":61077258}]}]}
{"op":"mcm","clk":"11926348829","pt":1724554012639,"mc":[{"id":"1.232224347","rc":[{"batb":[[0,2.1,5],[1,2.08,39.76],[2,1.21,24.75]],"ltp":2.2,"tv":5.5,"id":61077258}]}]}
{"op":"mcm","clk":"11926349035","pt":1724554016043,"mc":[{"id":"1.232224347","rc":[{"batb":[[0,2.08,39.76],[1,1.21,24.75],[2,1.1,1000]],"ltp":2.2,"tv":5.5,"id":61077258}]}]}
{"op":"mcm","clk":"11926349236","pt":1724554019145,"mc":[{"id":"1.232224347","rc":[{"batb":[[0,2.1,5],[1,2.08,39.76],[2,1.21,24.75]],"ltp":2.2,"tv":5.5,"id":61077258}]}]}
{"op":"mcm","clk":"11926349485","pt":1724554022372,"mc":[{"id":"1.232224347","rc":[{"batb":[[0,2.08,39.76],[1,1.21,24.75],[2,1.1,1000]],"ltp":2.2,"tv":5.5,"id":61077258}]}]}
{"op":"mcm","clk":"11926349639","pt":1724554024552,"mc":[{"id":"1.232224347","rc":[{"batb":[[0,2.1,5],[1,2.08,39.76],[2,1.21,24.75]],"ltp":2.2,"tv":5.5,"id":61077258}]}]}
{"op":"mcm","clk":"11926349890","pt":1724554027961,"mc":[{"id":"1.232224347","rc":[{"batb":[[0,2.08,39.76],[1,1.21,24.75],[2,1.1,1000]],"ltp":2.2,"tv":5.5,"id":61077258}]}]}
{"op":"mcm","clk":"11926350371","pt":1724554035772,"mc":[{"id":"1.232224347","rc":[{"batb":[[0,2.1,5],[1,2.08,39.76],[2,1.21,24.75]],"ltp":2.2,"tv":5.5,"id":61077258}]}]}
{"op":"mcm","clk":"11926350614","pt":1724554039170,"mc":[{"id":"1.232224347","rc":[{"batb":[[0,2.08,39.76],[1,1.21,24.75],[2,1.1,1000]],"ltp":2.2,"tv":5.5,"id":61077258}]}]}
{"op":"mcm","clk":"11926350989","pt":1724554045210,"mc":[{"id":"1.232224347","rc":[{"batb":[[0,2.1,5],[1,2.08,39.76],[2,1.21,24.75]],"ltp":2.2,"tv":5.5,"id":61077258}]}]}
{"op":"mcm","clk":"11926351173","pt":1724554048508,"mc":[{"id":"1.232224347","rc":[{"batb":[[0,2.08,39.76],[1,1.21,24.75],[2,1.1,1000]],"ltp":2.2,"tv":5.5,"id":61077258}]}]}
{"op":"mcm","clk":"11926351758","pt":1724554058028,"mc":[{"id":"1.232224347","rc":[{"batb":[[0,2.1,5],[1,2.08,39.76],[2,1.21,24.75]],"ltp":2.2,"tv":5.5,"id":61077258}]}]}
{"op":"mcm","clk":"11926351965","pt":1724554061296,"mc":[{"id":"1.232224347","rc":[{"batb":[[0,2.08,39.76],[1,1.21,24.75],[2,1.1,1000]],"ltp":2.2,"tv":5.5,"id":61077258}]}]}
{"op":"mcm","clk":"11926352175","pt":1724554064598,"mc":[{"id":"1.232224347","rc":[{"batb":[[0,2.1,5],[1,2.08,39.76],[2,1.21,24.75]],"ltp":2.2,"tv":5.5,"id":61077258}]}]}
{"op":"mcm","clk":"11926352356","pt":1724554068094,"mc":[{"id":"1.232224347","rc":[{"batb":[[0,2.08,39.76],[1,1.21,24.75],[2,1.1,1000]],"ltp":2.2,"tv":5.5,"id":61077258}]}]}
{"op":"mcm","clk":"11926352518","pt":1724554071190,"mc":[{"id":"1.232224347","rc":[{"batb":[[0,2.1,5],[1,2.08,39.76],[2,1.21,24.75]],"ltp":2.2,"tv":5.5,"id":61077258}]}]}
{"op":"mcm","clk":"11926352696","pt":1724554074737,"mc":[{"id":"1.232224347","rc":[{"batb":[[0,2.08,39.76],[1,1.21,24.75],[2,1.1,1000]],"ltp":2.2,"tv":5.5,"id":61077258}]}]}
{"op":"mcm","clk":"11926352835","pt":1724554077818,"mc":[{"id":"1.232224347","rc":[{"batb":[[0,2.1,5],[1,2.08,39.76],[2,1.21,24.75]],"ltp":2.2,"tv":5.5,"id":61077258}]}]}
{"op":"mcm","clk":"11926353008","pt":1724554081115,"mc":[{"id":"1.232224347","rc":[{"batb":[[0,2.08,39.76],[1,1.21,24.75],[2,1.1,1000]],"ltp":2.2,"tv":5.5,"id":61077258}]}]}
{"op":"mcm","clk":"11926353157","pt":1724554084250,"mc":[{"id":"1.232224347","rc":[{"batb":[[0,2.1,5],[1,2.08,39.76],[2,1.21,24.75]],"ltp":2.2,"tv":5.5,"id":61077258}]}]}
{"op":"mcm","clk":"11926353310","pt":1724554087755,"mc":[{"id":"1.232224347","rc":[{"batb":[[0,2.08,39.76],[1,1.21,24.75],[2,1.1,1000]],"ltp":2.2,"tv":5.5,"id":61077258}]}]}
{"op":"mcm","clk":"11926353521","pt":1724554091946,"mc":[{"id":"1.232224347","rc":[{"batb":[[0,2.1,5],[1,2.08,39.76],[2,1.21,24.75]],"ltp":2.2,"tv":5.5,"id":61077258}]}]}
{"op":"mcm","clk":"11926353655","pt":1724554095234,"mc":[{"id":"1.232224347","rc":[{"batb":[[0,2.08,39.76],[1,1.21,24.75],[2,1.1,1000]],"ltp":2.2,"tv":5.5,"id":61077258}]}]}
{"op":"mcm","clk":"11926354096","pt":1724554104664,"mc":[{"id":"1.232224347","rc":[{"batb":[[0,2.1,5],[1,2.08,39.76],[2,1.21,24.75]],"ltp":2.2,"tv":5.5,"id":61077258}]}]}
{"op":"mcm","clk":"11926354231","pt":1724554107949,"mc":[{"id":"1.232224347","rc":[{"batb":[[0,2.08,39.76],[1,1.21,24.75],[2,1.1,1000]],"ltp":2.2,"tv":5.5,"id":61077258}]}]}
{"op":"mcm","clk":"11926354520","pt":1724554114379,"mc":[{"id":"1.232224347","rc":[{"batb":[[0,2.1,5],[1,2.08,39.76],[2,1.21,24.75]],"ltp":2.2,"tv":5.5,"id":61077258}]}]}
{"op":"mcm","clk":"11926354706","pt":1724554117683,"mc":[{"id":"1.232224347","rc":[{"batb":[[0,2.08,39.76],[1,1.21,24.75],[2,1.1,1000]],"ltp":2.2,"tv":5.5,"id":61077258}]}]}
{"op":"mcm","clk":"11926354957","pt":1724554123592,"mc":[{"id":"1.232224347","rc":[{"batb":[[0,2.1,5],[1,2.08,39.76],[2,1.21,24.75]],"ltp":2.2,"tv":5.5,"id":61077258}]}]}
{"op":"mcm","clk":"11926355078","pt":1724554126883,"mc":[{"id":"1.232224347","rc":[{"batb":[[0,2.08,39.76],[1,1.21,24.75],[2,1.1,1000]],"ltp":2.2,"tv":5.5,"id":61077258}]}]}
{"op":"mcm","clk":"11926355157","pt":1724554129197,"mc":[{"id":"1.232224347","rc":[{"batb":[[0,2.1,5],[1,2.08,39.76],[2,1.21,24.75]],"ltp":2.2,"tv":5.5,"id":61077258}]}]}
{"op":"mcm","clk":"11926355282","pt":1724554132485,"mc":[{"id":"1.232224347","rc":[{"batb":[[0,2.08,39.76],[1,1.21,24.75],[2,1.1,1000]],"ltp":2.2,"tv":5.5,"id":61077258}]}]}
{"op":"mcm","clk":"11926355376","pt":1724554134807,"mc":[{"id":"1.232224347","rc":[{"batb":[[0,2.1,5],[1,2.08,39.76],[2,1.21,24.75]],"ltp":2.2,"tv":5.5,"id":61077258}]}]}
{"op":"mcm","clk":"11926355507","pt":1724554137690,"mc":[{"id":"1.232224347","rc":[{"batb":[[0,1.5,246.54],[1,1.25,1.76],[2,1.21,25.63]],"ltp":1.8,"tv":214.75,"id":48800301}]}]}
{"op":"mcm","clk":"11926355550","pt":1724554138314,"mc":[{"id":"1.232224347","rc":[{"batb":[[0,2.08,39.76],[1,1.21,24.75],[2,1.1,1000]],"ltp":2.2,"tv":5.5,"id":61077258}]}]}
