{"op":"mcm","clk":"11993489500","pt":1725011964245,"mc":[{"id":"1.232459454","marketDefinition":{"bspMarket":false,"turnInPlayEnabled":true,"persistenceEnabled":true,"marketBaseRate":5.0,"eventId":"33540029","eventTypeId":"4","numberOfWinners":1,"bettingType":"ODDS","marketType":"MATCH_ODDS","marketTime":"2024-08-31T01:30:00.000Z","suspendTime":"2024-08-31T01:30:00.000Z","bspReconciled":false,"complete":true,"inPlay":false,"crossMatching":false,"runnersVoidable":false,"numberOfActiveRunners":2,"betDelay":0,"status":"OPEN","runners":[{"status":"ACTIVE","sortPriority":1,"id":8858707,"name":"Maldives"},{"status":"ACTIVE","sortPriority":2,"id":7587363,"name":"Singapore"}],"regulators":["MR_INT"],"countryCode":"GB","discountAllowed":false,"timezone":"GMT","openDate":"2024-08-31T01:30:00.000Z","version":6107614122,"name":"Match Odds","eventName":"Maldives v Singapore"},"rc":[{"batb":[[0,1.03,200],[1,1.02,200],[2,1.01,220]],"ltp":0.0,"tv":0.0,"id":8858707},{"batb":[[0,1.03,200],[1,1.02,200],[2,1.01,220]],"ltp":0.0,"tv":0.0,"id":7587363}]}]}
{"op":"mcm","clk":"11993489568","pt":1725011965385,"mc":[{"id":"1.232459454","marketDefinition":{"bspMarket":false,"turnInPlayEnabled":true,"persistenceEnabled":true,"marketBaseRate":5.0,"eventId":"33540029","eventTypeId":"4","numberOfWinners":1,"bettingType":"ODDS","marketType":"MATCH_ODDS","marketTime":"2024-08-31T01:30:00.000Z","suspendTime":"2024-08-31T01:30:00.000Z","bspReconciled":false,"complete":true,"inPlay":false,"crossMatching":false,"runnersVoidable":false,"numberOfActiveRunners":2,"betDelay":0,"status":"OPEN","runners":[{"status":"ACTIVE","sortPriority":1,"id":8858707,"name":"Maldives"},{"status":"ACTIVE","sortPriority":2,"id":7587363,"name":"Singapore"}],"regulators":["MR_INT"],"countryCode":"GB","discountAllowed":true,"timezone":"GMT","openDate":"2024-08-31T01:30:00.000Z","version":6107614122,"name":"Match Odds","eventName":"Maldives v Singapore"}}]}
{"op":"mcm","clk":"11993524522","pt":1725012410188,"mc":[{"id":"1.232459454","rc":[{"batb":[[0,1.04,100],[1,1.03,200],[2,1.02,200]],"ltp":0.0,"tv":0.0,"id":8858707}]}]}
{"op":"mcm","clk":"11993526638","pt":1725012435490,"mc":[{"id":"1.232459454","rc":[{"batb":[[0,1.04,100],[1,1.03,200],[2,1.02,200]],"ltp":0.0,"tv":0.0,"id":7587363}]}]}
{"op":"mcm","clk":"11993616549","pt":1725013682702,"mc":[{"id":"1.232459454","rc":[{"trd":[[1.04,4]],"batb":[[0,1.04,98]],"ltp":1.04,"tv":4.0,"id":8858707}],"tv":4.0}]}
{"op":"mcm","clk":"11993628299","pt":1725013862809,"mc":[{"id":"1.232459454","rc":[{"trd":[[1.04,6]],"batb":[[0,1.04,97]],"ltp":1.04,"tv":6.0,"id":7587363}],"tv":10.0}]}
{"op":"mcm","clk":"11993681177","pt":1725014605426,"mc":[{"id":"1.232459454","rc":[{"batb":[[0,1.05,20],[1,1.04,98],[2,1.03,200]],"ltp":1.04,"tv":4.0,"id":8858707},{"batb":[[0,1.05,20],[1,1.04,97],[2,1.03,200]],"ltp":1.04,"tv":6.0,"id":7587363}]}]}
{"op":"mcm","clk":"11993682181","pt":1725014620596,"mc":[{"id":"1.232459454","marketDefinition":{"bspMarket":false,"turnInPlayEnabled":true,"persistenceEnabled":true,"marketBaseRate":5.0,"eventId":"33540029","eventTypeId":"4","numberOfWinners":1,"bettingType":"ODDS","marketType":"MATCH_ODDS","marketTime":"2024-08-31T01:30:00.000Z","suspendTime":"2024-08-31T01:30:00.000Z","bspReconciled":false,"complete":true,"inPlay":false,"crossMatching":true,"runnersVoidable":false,"numberOfActiveRunners":2,"betDelay":0,"status":"OPEN","runners":[{"status":"ACTIVE","sortPriority":1,"id":8858707,"name":"Maldives"},{"status":"ACTIVE","sortPriority":2,"id":7587363,"name":"Singapore"}],"regulators":["MR_INT"],"countryCode":"GB","discountAllowed":true,"timezone":"GMT","openDate":"2024-08-31T01:30:00.000Z","version":6107614122,"name":"Match Odds","eventName":"Maldives v Singapore"}}]}
{"op":"mcm","clk":"11993729717","pt":1725015251742,"mc":[{"id":"1.232459454","rc":[{"batb":[[0,6,1.14],[1,1.05,20],[2,1.04,98]],"ltp":1.04,"tv":4.0,"id":8858707}]}]}
{"op":"mcm","clk":"11993730367","pt":1725015259434,"mc":[{"id":"1.232459454","rc":[{"batb":[[0,1.05,20],[1,1.04,98],[2,1.03,200]],"ltp":1.04,"tv":4.0,"id":8858707}]}]}
{"op":"mcm","clk":"11993731997","pt":1725015279851,"mc":[{"id":"1.232459454","rc":[{"batb":[[0,6,1.14],[1,1.05,20],[2,1.04,97]],"ltp":1.04,"tv":6.0,"id":7587363}]}]}
{"op":"mcm","clk":"11993733982","pt":1725015305814,"mc":[{"id":"1.232459454","rc":[{"batb":[[0,1.05,20],[1,1.04,97],[2,1.03,200]],"ltp":1.04,"tv":6.0,"id":7587363}]}]}
{"op":"mcm","clk":"11993742654","pt":1725015409981,"mc":[{"id":"1.232459454","rc":[{"batb":[[0,6,1.14],[1,1.05,20],[2,1.04,97]],"ltp":1.04,"tv":6.0,"id":7587363}]}]}
{"op":"mcm","clk":"11993743825","pt":1725015425602,"mc":[{"id":"1.232459454","rc":[{"batb":[[0,1.05,20],[1,1.04,97],[2,1.03,200]],"ltp":1.04,"tv":6.0,"id":7587363}]}]}
{"op":"mcm","clk":"11993747659","pt":1725015474848,"mc":[{"id":"1.232459454","rc":[{"batb":[[0,6,1.14],[1,1.05,20],[2,1.04,97]],"ltp":1.04,"tv":6.0,"id":7587363}]}]}
{"op":"mcm","clk":"11993748541","pt":1725015486766,"mc":[{"id":"1.232459454","rc":[{"batb":[[0,1.05,20],[1,1.04,97],[2,1.03,200]],"ltp":1.04,"tv":6.0,"id":7587363}]}]}
{"op":"mcm","clk":"11993752658","pt":1725015541432,"mc":[{"id":"1.232459454","rc":[{"batb":[[0,6,1.14],[1,1.05,20],[2,1.04,97]],"ltp":1.04,"tv":6.0,"id":7587363}]}]}
{"op":"mcm","clk":"11993753671","pt":1725015555181,"mc":[{"id":"1.232459454","rc":[{"batb":[[0,1.05,20],[1,1.04,97],[2,1.03,200]],"ltp":1.04,"tv":6.0,"id":7587363}]}]}
{"op":"mcm","clk":"11993756923","pt":1725015599397,"mc":[{"id":"1.232459454","rc":[{"batb":[[0,6,1.14],[1,1.05,20],[2,1.04,97]],"ltp":1.04,"tv":6.0,"id":7587363}]}]}
{"op":"mcm","clk":"11993758109","pt":1725015612346,"mc":[{"id":"1.232459454","rc":[{"batb":[[0,1.05,20],[1,1.04,97],[2,1.03,200]],"ltp":1.04,"tv":6.0,"id":7587363}]}]}
{"op":"mcm","clk":"11993761230","pt":1725015652805,"mc":[{"id":"1.232459454","rc":[{"batb":[[0,6,1.14],[1,1.05,20],[2,1.04,97]],"ltp":1.04,"tv":6.0,"id":7587363}]}]}
{"op":"mcm","clk":"11993762200","pt":1725015665277,"mc":[{"id":"1.232459454","rc":[{"batb":[[0,1.05,20],[1,1.04,97],[2,1.03,200]],"ltp":1.04,"tv":6.0,"id":7587363}]}]}
{"op":"mcm","clk":"11993765771","pt":1725015714568,"mc":[{"id":"1.232459454","rc":[{"batb":[[0,6,1.14],[1,1.05,20],[2,1.04,97]],"ltp":1.04,"tv":6.0,"id":7587363}]}]}
{"op":"mcm","clk":"11993767274","pt":1725015737812,"mc":[{"id":"1.232459454","rc":[{"batb":[[0,1.05,20],[1,1.04,97],[2,1.03,200]],"ltp":1.04,"tv":6.0,"id":7587363}]}]}
{"op":"mcm","clk":"11993771095","pt":1725015794665,"mc":[{"id":"1.232459454","rc":[{"batb":[[0,6,1.14],[1,1.05,20],[2,1.04,97]],"ltp":1.04,"tv":6.0,"id":7587363}]}]}
{"op":"mcm","clk":"11993771776","pt":1725015804989,"mc":[{"id":"1.232459454","rc":[{"batb":[[0,1.05,20],[1,1.04,97],[2,1.03,200]],"ltp":1.04,"tv":6.0,"id":7587363}]}]}
{"op":"mcm","clk":"11993774049","pt":1725015837605,"mc":[{"id":"1.232459454","rc":[{"batb":[[0,6,1.14],[1,1.05,20],[2,1.04,97]],"ltp":1.04,"tv":6.0,"id":7587363}]}]}
{"op":"mcm","clk":"11993775149","pt":1725015852422,"mc":[{"id":"1.232459454","rc":[{"batb":[[0,1.05,20],[1,1.04,97],[2,1.03,200]],"ltp":1.04,"tv":6.0,"id":7587363}]}]}
{"op":"mcm","clk":"11993781059","pt":1725015939954,"mc":[{"id":"1.232459454","rc":[{"batb":[[0,6,1.14],[1,1.05,20],[2,1.04,97]],"ltp":1.04,"tv":6.0,"id":7587363}]}]}
{"op":"mcm","clk":"11993781966","pt":1725015952578,"mc":[{"id":"1.232459454","rc":[{"batb":[[0,1.05,20],[1,1.04,97],[2,1.03,200]],"ltp":1.04,"tv":6.0,"id":7587363}]}]}
{"op":"mcm","clk":"11993784316","pt":1725015982920,"mc":[{"id":"1.232459454","rc":[{"batb":[[0,6,1.14],[1,1.05,20],[2,1.04,97]],"ltp":1.04,"tv":6.0,"id":7587363}]}]}
{"op":"mcm","clk":"11993785138","pt":1725015994643,"mc":[{"id":"1.232459454","rc":[{"batb":[[0,1.05,20],[1,1.04,97],[2,1.03,200]],"ltp":1.04,"tv":6.0,"id":7587363}]}]}
{"op":"mcm","clk":"11993794709","pt":1725016128632,"mc":[{"id":"1.232459454","rc":[{"batb":[[0,6,1.14],[1,1.05,20],[2,1.04,97]],"ltp":1.04,"tv":6.0,"id":7587363}]}]}
{"op":"mcm","clk":"11993795629","pt":1725016144664,"mc":[{"id":"1.232459454","rc":[{"batb":[[0,1.05,20],[1,1.04,97],[2,1.03,200]],"ltp":1.04,"tv":6.0,"id":7587363}]}]}
{"op":"mcm","clk":"11993797165","pt":1725016170596,"mc":[{"id":"1.232459454","rc":[{"batb":[[0,6,1.14],[1,1.05,20],[2,1.04,97]],"ltp":1.04,"tv":6.0,"id":7587363}]}]}
{"op":"mcm","clk":"11993797934","pt":1725016182889,"mc":[{"id":"1.232459454","rc":[{"batb":[[0,1.05,20],[1,1.04,97],[2,1.03,200]],"ltp":1.04,"tv":6.0,"id":7587363}]}]}
{"op":"mcm","clk":"11993863991","pt":1725016914016,"mc":[{"id":"1.232459454","rc":[{"batb":[[0,5.9,1.14],[1,1.05,20],[2,1.04,97]],"ltp":1.04,"tv":6.0,"id":7587363}]}]}
{"op":"mcm","clk":"11993864901","pt":1725016928016,"mc":[{"id":"1.232459454","rc":[{"batb":[[0,1.05,20],[1,1.04,97],[2,1.03,200]],"ltp":1.04,"tv":6.0,"id":7587363}]}]}
{"op":"mcm","clk":"11993891421","pt":1725017313132,"mc":[{"id":"1.232459454","rc":[{"batb":[[0,6,1.14],[1,1.05,20],[2,1.04,97]],"ltp":1.04,"tv":6.0,"id":7587363}]}]}
{"op":"mcm","clk":"11993892480","pt":1725017327629,"mc":[{"id":"1.232459454","rc":[{"batb":[[0,1.05,20],[1,1.04,97],[2,1.03,200]],"ltp":1.04,"tv":6.0,"id":7587363}]}]}
{"op":"mcm","clk":"11993895439","pt":1725017372680,"mc":[{"id":"1.232459454","rc":[{"batb":[[0,5.9,1.14],[1,1.05,20],[2,1.04,97]],"ltp":1.04,"tv":6.0,"id":7587363}]}]}
{"op":"mcm","clk":"11993896388","pt":1725017386586,"mc":[{"id":"1.232459454","rc":[{"batb":[[0,1.05,20],[1,1.04,97],[2,1.03,200]],"ltp":1.04,"tv":6.0,"id":7587363}]}]}
{"op":"mcm","clk":"11993916759","pt":1725017644679,"mc":[{"id":"1.232459454","rc":[{"batb":[[0,6,1.14],[1,1.05,20],[2,1.04,97]],"ltp":1.04,"tv":6.0,"id":7587363}]}]}
{"op":"mcm","clk":"11993917947","pt":1725017659289,"mc":[{"id":"1.232459454","rc":[{"batb":[[0,1.05,20],[1,1.04,97],[2,1.03,200]],"ltp":1.04,"tv":6.0,"id":7587363}]}]}
{"op":"mcm","clk":"11993938262","pt":1725017916739,"mc":[{"id":"1.232459454","rc":[{"batb":[[0,6,1.14],[1,1.05,20],[2,1.04,97]],"ltp":1.04,"tv":6.0,"id":7587363}]}]}
{"op":"mcm","clk":"11993939056","pt":1725017928050,"mc":[{"id":"1.232459454","rc":[{"batb":[[0,1.05,20],[1,1.04,97],[2,1.03,200]],"ltp":1.04,"tv":6.0,"id":7587363}]}]}
{"op":"mcm","clk":"11993954593","pt":1725018134295,"mc":[{"id":"1.232459454","rc":[{"batb":[[0,3,6.5],[1,1.05,20],[2,1.04,98]],"ltp":1.04,"tv":4.0,"id":8858707}]}]}
{"op":"mcm","clk":"11993956066","pt":1725018154024,"mc":[{"id":"1.232459454","rc":[{"batb":[[0,4.3,13.4],[1,3,6.5],[2,1.05,20]],"ltp":1.04,"tv":4.0,"id":8858707},{"batb":[[0,1.25,176.98],[1,1.05,20],[2,1.04,97]],"ltp":1.04,"tv":6.0,"id":7587363}]}]}
{"op":"mcm","clk":"11994001027","pt":1725018714415,"mc":[{"id":"1.232459454","rc":[{"trd":[[5,3.54]],"ltp":5.0,"tv":7.54,"id":8858707},{"trd":[[1.25,14.15]],"batb":[[0,1.25,162.83]],"ltp":1.25,"tv":20.15,"id":7587363}],"tv":27.68}]}
{"op":"mcm","clk":"11994001200","pt":1725018717106,"mc":[{"id":"1.232459454","rc":[{"batb":[[0,1.25,176.98]],"ltp":1.25,"tv":20.15,"id":7587363}]}]}
{"op":"mcm","clk":"11994002679","pt":1725018738454,"mc":[{"id":"1.232459454","rc":[{"trd":[[5,11.56]],"ltp":5.0,"tv":15.56,"id":8858707},{"trd":[[1.25,46.24]],"batb":[[0,1.25,144.89]],"ltp":1.25,"tv":52.24,"id":7587363}],"tv":67.8}]}
{"op":"mcm","clk":"11994002975","pt":1725018742248,"mc":[{"id":"1.232459454","rc":[{"batb":[[0,1.25,176.98]],"ltp":1.25,"tv":52.24,"id":7587363}]}]}
{"op":"mcm","clk":"11994011411","pt":1725018858815,"mc":[{"id":"1.232459454","rc":[{"trd":[[5,19.58]],"ltp":5.0,"tv":23.58,"id":8858707},{"trd":[[1.25,78.33]],"batb":[[0,1.25,144.89]],"ltp":1.25,"tv":84.33,"id":7587363}],"tv":107.91}]}
{"op":"mcm","clk":"11994011756","pt":1725018862812,"mc":[{"id":"1.232459454","rc":[{"batb":[[0,1.25,176.98]],"ltp":1.25,"tv":84.33,"id":7587363}]}]}
{"op":"mcm","clk":"11994028629","pt":1725019101829,"mc":[{"id":"1.232459454","rc":[{"trd":[[5,28.67]],"ltp":5.0,"tv":32.66,"id":8858707},{"trd":[[1.25,114.68]],"batb":[[0,1.25,140.63]],"ltp":1.25,"tv":120.68,"id":7587363}],"tv":153.34}]}
{"op":"mcm","clk":"11994028763","pt":1725019104037,"mc":[{"id":"1.232459454","rc":[{"batb":[[0,1.25,176.98]],"ltp":1.25,"tv":120.68,"id":7587363}]}]}
{"op":"mcm","clk":"11994032951","pt":1725019160502,"mc":[{"id":"1.232459454","rc":[{"trd":[[1.25,468.64]],"batb":[[0,1.05,20],[1,1.04,97],[2,1.03,200]],"batl":[[0,1.25,103.06]],"ltp":1.25,"tv":474.64,"id":7587363}],"tv":507.31}]}
{"op":"mcm","clk":"11994033254","pt":1725019164280,"mc":[{"id":"1.232459454","rc":[{"batb":[[0,1.21,210.69],[1,1.05,20],[2,1.04,97]],"ltp":1.25,"tv":474.64,"id":7587363}]}]}
{"op":"mcm","clk":"11994041766","pt":1725019264693,"mc":[{"id":"1.232459454","rc":[{"trd":[[5,28.66]],"ltp":5.0,"tv":32.66,"id":8858707},{"trd":[[1.21,421.38],[1.25,468.6]],"batb":[[0,1.05,20],[1,1.04,97],[2,1.03,200]],"batl":[[0,1.21,69.29],[1,1.25,103.04]],"ltp":1.21,"tv":895.97,"id":7587363}],"tv":928.63}]}
{"op":"mcm","clk":"11994042003","pt":1725019267292,"mc":[{"id":"1.232459454","rc":[{"batl":[[0,1.25,103.04],[1,1.25,0]],"ltp":1.21,"tv":895.97,"id":7587363}]}]}
{"op":"mcm","clk":"11994044070","pt":1725019291809,"mc":[{"id":"1.232459454","rc":[{"batb":[[0,4.4,5],[1,4.3,13.4],[2,3,6.5]],"batl":[[0,7,68]],"ltp":5.0,"tv":32.66,"id":8858707}]}]}
{"op":"mcm","clk":"11994044423","pt":1725019295332,"mc":[{"id":"1.232459454","rc":[{"batb":[[0,4.3,13.4],[1,3,6.5],[2,1.05,20]],"ltp":5.0,"tv":32.66,"id":8858707}]}]}
{"op":"mcm","clk":"11994045619","pt":1725019307857,"mc":[{"id":"1.232459454","rc":[{"batb":[[0,4.4,5],[1,4.3,13.4],[2,3,6.5]],"ltp":5.0,"tv":32.66,"id":8858707}]}]}
{"op":"mcm","clk":"11994045926","pt":1725019311536,"mc":[{"id":"1.232459454","rc":[{"batb":[[0,4.3,13.4],[1,3,6.5],[2,1.05,20]],"ltp":5.0,"tv":32.66,"id":8858707}]}]}
{"op":"mcm","clk":"11994048084","pt":1725019336166,"mc":[{"id":"1.232459454","rc":[{"batb":[[0,4.4,5],[1,4.3,13.4],[2,3,6.5]],"ltp":5.0,"tv":32.66,"id":8858707}]}]}
{"op":"mcm","clk":"11994048441","pt":1725019339997,"mc":[{"id":"1.232459454","rc":[{"batb":[[0,4.3,13.4],[1,3,6.5],[2,1.05,20]],"ltp":5.0,"tv":32.66,"id":8858707}]}]}
{"op":"mcm","clk":"11994048659","pt":1725019342688,"mc":[{"id":"1.232459454","rc":[{"batb":[[0,4.4,5],[1,4.3,13.4],[2,3,6.5]],"ltp":5.0,"tv":32.66,"id":8858707}]}]}
{"op":"mcm","clk":"11994048928","pt":1725019346202,"mc":[{"id":"1.232459454","rc":[{"batb":[[0,4.3,13.4],[1,3,6.5],[2,1.05,20]],"ltp":5.0,"tv":32.66,"id":8858707}]}]}
{"op":"mcm","clk":"11994049663","pt":1725019355484,"mc":[{"id":"1.232459454","rc":[{"batb":[[0,4.4,5],[1,4.3,13.4],[2,3,6.5]],"ltp":5.0,"tv":32.66,"id":8858707}]}]}
{"op":"mcm","clk":"11994050049","pt":1725019359314,"mc":[{"id":"1.232459454","rc":[{"batb":[[0,4.3,13.4],[1,3,6.5],[2,1.05,20]],"ltp":5.0,"tv":32.66,"id":8858707}]}]}
{"op":"mcm","clk":"11994053104","pt":1725019398123,"mc":[{"id":"1.232459454","rc":[{"batb":[[0,4.4,5],[1,4.3,13.4],[2,3,6.5]],"ltp":5.0,"tv":32.66,"id":8858707}]}]}
{"op":"mcm","clk":"11994053466","pt":1725019401748,"mc":[{"id":"1.232459454","rc":[{"batb":[[0,4.3,13.4],[1,3,6.5],[2,1.05,20]],"ltp":5.0,"tv":32.66,"id":8858707}]}]}
{"op":"mcm","clk":"11994053764","pt":1725019405058,"mc":[{"id":"1.232459454","rc":[{"batb":[[0,4.4,5],[1,4.3,13.4],[2,3,6.5]],"ltp":5.0,"tv":32.66,"id":8858707}]}]}
{"op":"mcm","clk":"11994054080","pt":1725019408624,"mc":[{"id":"1.232459454","rc":[{"batb":[[0,4.3,13.4],[1,3,6.5],[2,1.05,20]],"ltp":5.0,"tv":32.66,"id":8858707}]}]}
{"op":"mcm","clk":"11994054787","pt":1725019416641,"mc":[{"id":"1.232459454","rc":[{"batb":[[0,4.4,5],[1,4.3,13.4],[2,3,6.5]],"ltp":5.0,"tv":32.66,"id":8858707}]}]}
{"op":"mcm","clk":"11994055097","pt":1725019420515,"mc":[{"id":"1.232459454","rc":[{"batb":[[0,4.3,13.4],[1,3,6.5],[2,1.05,20]],"ltp":5.0,"tv":32.66,"id":8858707}]}]}
{"op":"mcm","clk":"11994055660","pt":1725019426866,"mc":[{"id":"1.232459454","rc":[{"batb":[[0,4.4,5],[1,4.3,13.4],[2,3,6.5]],"ltp":5.0,"tv":32.66,"id":8858707}]}]}
{"op":"mcm","clk":"11994056024","pt":1725019430491,"mc":[{"id":"1.232459454","rc":[{"batb":[[0,4.3,13.4],[1,3,6.5],[2,1.05,20]],"ltp":5.0,"tv":32.66,"id":8858707}]}]}
{"op":"mcm","clk":"11994056517","pt":1725019435894,"mc":[{"id":"1.232459454","rc":[{"batb":[[0,4.4,5],[1,4.3,13.4],[2,3,6.5]],"ltp":5.0,"tv":32.66,"id":8858707}]}]}
{"op":"mcm","clk":"11994056801","pt":1725019439499,"mc":[{"id":"1.232459454","rc":[{"batb":[[0,4.3,13.4],[1,3,6.5],[2,1.05,20]],"ltp":5.0,"tv":32.66,"id":8858707}]}]}
{"op":"mcm","clk":"11994057273","pt":1725019444774,"mc":[{"id":"1.232459454","rc":[{"batb":[[0,4.4,5],[1,4.3,13.4],[2,3,6.5]],"ltp":5.0,"tv":32.66,"id":8858707}]}]}
{"op":"mcm","clk":"11994057556","pt":1725019448491,"mc":[{"id":"1.232459454","rc":[{"batb":[[0,4.3,13.4],[1,3,6.5],[2,1.05,20]],"ltp":5.0,"tv":32.66,"id":8858707}]}]}
{"op":"mcm","clk":"11994058446","pt":1725019459002,"mc":[{"id":"1.232459454","rc":[{"batb":[[0,4.4,5],[1,4.3,13.4],[2,3,6.5]],"ltp":5.0,"tv":32.66,"id":8858707}]}]}
{"op":"mcm","clk":"11994058757","pt":1725019462902,"mc":[{"id":"1.232459454","rc":[{"batb":[[0,4.3,13.4],[1,3,6.5],[2,1.05,20]],"ltp":5.0,"tv":32.66,"id":8858707}]}]}
{"op":"mcm","clk":"11994059161","pt":1725019467724,"mc":[{"id":"1.232459454","rc":[{"batb":[[0,4.4,5],[1,4.3,13.4],[2,3,6.5]],"ltp":5.0,"tv":32.66,"id":8858707}]}]}
{"op":"mcm","clk":"11994059460","pt":1725019471498,"mc":[{"id":"1.232459454","rc":[{"batb":[[0,4.3,13.4],[1,3,6.5],[2,1.05,20]],"ltp":5.0,"tv":32.66,"id":8858707}]}]}
{"op":"mcm","clk":"11994060199","pt":1725019480042,"mc":[{"id":"1.232459454","rc":[{"batb":[[0,4.4,5],[1,4.3,13.4],[2,3,6.5]],"ltp":5.0,"tv":32.66,"id":8858707}]}]}
{"op":"mcm","clk":"11994060614","pt":1725019483829,"mc":[{"id":"1.232459454","rc":[{"batb":[[0,4.3,13.4],[1,3,6.5],[2,1.05,20]],"ltp":5.0,"tv":32.66,"id":8858707}]}]}
{"op":"mcm","clk":"11994060866","pt":1725019486514,"mc":[{"id":"1.232459454","rc":[{"batb":[[0,4.4,5],[1,4.3,13.4],[2,3,6.5]],"ltp":5.0,"tv":32.66,"id":8858707}]}]}
{"op":"mcm","clk":"11994061183","pt":1725019490130,"mc":[{"id":"1.232459454","rc":[{"batb":[[0,4.3,13.4],[1,3,6.5],[2,1.05,20]],"ltp":5.0,"tv":32.66,"id":8858707}]}]}
{"op":"mcm","clk":"11994061521","pt":1725019494162,"mc":[{"id":"1.232459454","rc":[{"batb":[[0,4.4,5],[1,4.3,13.4],[2,3,6.5]],"ltp":5.0,"tv":32.66,"id":8858707}]}]}
{"op":"mcm","clk":"11994061855","pt":1725019498040,"mc":[{"id":"1.232459454","rc":[{"batb":[[0,4.3,13.4],[1,3,6.5],[2,1.05,20]],"ltp":5.0,"tv":32.66,"id":8858707}]}]}
{"op":"mcm","clk":"11994062616","pt":1725019506038,"mc":[{"id":"1.232459454","rc":[{"batb":[[0,4.4,5],[1,4.3,13.4],[2,3,6.5]],"ltp":5.0,"tv":32.66,"id":8858707}]}]}
{"op":"mcm","clk":"11994062972","pt":1725019509875,"mc":[{"id":"1.232459454","rc":[{"batb":[[0,4.3,13.4],[1,3,6.5],[2,1.05,20]],"ltp":5.0,"tv":32.66,"id":8858707}]}]}
{"op":"mcm","clk":"11994064133","pt":1725019521897,"mc":[{"id":"1.232459454","rc":[{"batb":[[0,4.4,5],[1,4.3,13.4],[2,3,6.5]],"ltp":5.0,"tv":32.66,"id":8858707}]}]}
{"op":"mcm","clk":"11994064450","pt":1725019525465,"mc":[{"id":"1.232459454","rc":[{"batb":[[0,4.3,13.4],[1,3,6.5],[2,1.05,20]],"ltp":5.0,"tv":32.66,"id":8858707}]}]}
{"op":"mcm","clk":"11994067311","pt":1725019555631,"mc":[{"id":"1.232459454","rc":[{"batb":[[0,4.4,5],[1,4.3,13.4],[2,3,6.5]],"ltp":5.0,"tv":32.66,"id":8858707}]}]}
{"op":"mcm","clk":"11994067660","pt":1725019560021,"mc":[{"id":"1.232459454","rc":[{"batb":[[0,4.3,13.4],[1,3,6.5],[2,1.05,20]],"ltp":5.0,"tv":32.66,"id":8858707}]}]}
{"op":"mcm","clk":"11994068113","pt":1725019564832,"mc":[{"id":"1.232459454","rc":[{"batb":[[0,4.4,5],[1,4.3,13.4],[2,3,6.5]],"ltp":5.0,"tv":32.66,"id":8858707}]}]}
{"op":"mcm","clk":"11994068500","pt":1725019568722,"mc":[{"id":"1.232459454","rc":[{"batb":[[0,4.3,13.4],[1,3,6.5],[2,1.05,20]],"ltp":5.0,"tv":32.66,"id":8858707}]}]}
{"op":"mcm","clk":"11994068706","pt":1725019570902,"mc":[{"id":"1.232459454","rc":[{"batb":[[0,4.4,5],[1,4.3,13.4],[2,3,6.5]],"ltp":5.0,"tv":32.66,"id":8858707}]}]}
{"op":"mcm","clk":"11994069068","pt":1725019574431,"mc":[{"id":"1.232459454","rc":[{"batb":[[0,4.3,13.4],[1,3,6.5],[2,1.05,20]],"ltp":5.0,"tv":32.66,"id":8858707}]}]}
{"op":"mcm","clk":"11994069480","pt":1725019578534,"mc":[{"id":"1.232459454","rc":[{"batb":[[0,4.4,5],[1,4.3,13.4],[2,3,6.5]],"ltp":5.0,"tv":32.66,"id":8858707}]}]}
{"op":"mcm","clk":"11994069916","pt":1725019582723,"mc":[{"id":"1.232459454","rc":[{"batb":[[0,4.3,13.4],[1,3,6.5],[2,1.05,20]],"ltp":5.0,"tv":32.66,"id":8858707}]}]}
{"op":"mcm","clk":"11994070291","pt":1725019586228,"mc":[{"id":"1.232459454","rc":[{"batb":[[0,4.4,5],[1,4.3,13.4],[2,3,6.5]],"ltp":5.0,"tv":32.66,"id":8858707},{"batb":[[0,1.04,97],[1,1.03,200],[2,1.02,200]],"ltp":1.21,"tv":895.97,"id":7587363}]}]}
{"op":"mcm","clk":"11994070586","pt":1725019589440,"mc":[{"id":"1.232459454","rc":[{"batb":[[0,4.3,13.4],[1,3,6.5],[2,1.04,98]],"ltp":5.0,"tv":32.66,"id":8858707}]}]}
{"op":"mcm","clk":"11994071429","pt":1725019597637,"mc":[{"id":"1.232459454","rc":[{"batb":[[0,4.4,5],[1,4.3,13.4],[2,3,6.5]],"ltp":5.0,"tv":32.66,"id":8858707}]}]}
{"op":"mcm","clk":"11994071775","pt":1725019601178,"mc":[{"id":"1.232459454","rc":[{"batb":[[0,4.3,13.4],[1,3,6.5],[2,1.04,98]],"ltp":5.0,"tv":32.66,"id":8858707}]}]}
{"op":"mcm","clk":"11994072056","pt":1725019604189,"mc":[{"id":"1.232459454","rc":[{"batb":[[0,4.4,5],[1,4.3,13.4],[2,3,6.5]],"ltp":5.0,"tv":32.66,"id":8858707}]}]}
{"op":"mcm","clk":"11994072342","pt":1725019607381,"mc":[{"id":"1.232459454","rc":[{"batb":[[0,4.3,13.4],[1,3,6.5],[2,1.04,98]],"ltp":5.0,"tv":32.66,"id":8858707}]}]}
{"op":"mcm","clk":"11994072981","pt":1725019614483,"mc":[{"id":"1.232459454","rc":[{"batb":[[0,4.4,5],[1,4.3,13.4],[2,3,6.5]],"ltp":5.0,"tv":32.66,"id":8858707}]}]}
{"op":"mcm","clk":"11994073307","pt":1725019618162,"mc":[{"id":"1.232459454","rc":[{"batb":[[0,4.3,13.4],[1,3,6.5],[2,1.04,98]],"ltp":5.0,"tv":32.66,"id":8858707}]}]}
{"op":"mcm","clk":"11994073758","pt":1725019623393,"mc":[{"id":"1.232459454","rc":[{"batb":[[0,4.4,5],[1,4.3,13.4],[2,3,6.5]],"ltp":5.0,"tv":32.66,"id":8858707}]}]}
{"op":"mcm","clk":"11994074102","pt":1725019626958,"mc":[{"id":"1.232459454","rc":[{"batb":[[0,4.3,13.4],[1,3,6.5],[2,1.04,98]],"ltp":5.0,"tv":32.66,"id":8858707}]}]}
{"op":"mcm","clk":"11994074224","pt":1725019628291,"mc":[{"id":"1.232459454","rc":[{"batb":[[0,1.17,16.76],[1,1.04,97],[2,1.03,200]],"ltp":1.21,"tv":895.97,"id":7587363}]}]}
{"op":"mcm","clk":"11994074621","pt":1725019631866,"mc":[{"id":"1.232459454","rc":[{"batb":[[0,4.4,5],[1,4.3,13.4],[2,3,6.5]],"ltp":5.0,"tv":32.66,"id":8858707}]}]}
{"op":"mcm","clk":"11994075073","pt":1725019635596,"mc":[{"id":"1.232459454","rc":[{"batb":[[0,4.3,13.4],[1,3,6.5],[2,1.04,98]],"ltp":5.0,"tv":32.66,"id":8858707}]}]}
{"op":"mcm","clk":"11994076507","pt":1725019646699,"mc":[{"id":"1.232459454","rc":[{"batb":[[0,4.4,5],[1,4.3,13.4],[2,3,6.5]],"ltp":5.0,"tv":32.66,"id":8858707}]}]}
{"op":"mcm","clk":"11994076862","pt":1725019650329,"mc":[{"id":"1.232459454","rc":[{"batb":[[0,4.3,13.4],[1,3,6.5],[2,1.04,98]],"ltp":5.0,"tv":32.66,"id":8858707}]}]}
{"op":"mcm","clk":"11994077680","pt":1725019658533,"mc":[{"id":"1.232459454","rc":[{"batb":[[0,4.4,5],[1,4.3,13.4],[2,3,6.5]],"ltp":5.0,"tv":32.66,"id":8858707}]}]}
{"op":"mcm","clk":"11994077995","pt":1725019661919,"mc":[{"id":"1.232459454","rc":[{"batb":[[0,4.3,13.4],[1,3,6.5],[2,1.04,98]],"ltp":5.0,"tv":32.66,"id":8858707}]}]}
{"op":"mcm","clk":"11994078821","pt":1725019670347,"mc":[{"id":"1.232459454","rc":[{"batb":[[0,4.4,5],[1,4.3,13.4],[2,3,6.5]],"ltp":5.0,"tv":32.66,"id":8858707}]}]}
{"op":"mcm","clk":"11994079176","pt":1725019674177,"mc":[{"id":"1.232459454","rc":[{"batb":[[0,4.3,13.4],[1,3,6.5],[2,1.04,98]],"ltp":5.0,"tv":32.66,"id":8858707}]}]}
{"op":"mcm","clk":"11994079405","pt":1725019676475,"mc":[{"id":"1.232459454","rc":[{"batb":[[0,4.4,5],[1,4.3,13.4],[2,3,6.5]],"ltp":5.0,"tv":32.66,"id":8858707}]}]}
{"op":"mcm","clk":"11994079751","pt":1725019680063,"mc":[{"id":"1.232459454","rc":[{"batb":[[0,4.3,13.4],[1,3,6.5],[2,1.04,98]],"ltp":5.0,"tv":32.66,"id":8858707}]}]}
{"op":"mcm","clk":"11994080059","pt":1725019682881,"mc":[{"id":"1.232459454","rc":[{"batb":[[0,4.4,5],[1,4.3,13.4],[2,3,6.5]],"ltp":5.0,"tv":32.66,"id":8858707}]}]}
{"op":"mcm","clk":"11994080444","pt":1725019686470,"mc":[{"id":"1.232459454","rc":[{"batb":[[0,4.3,13.4],[1,3,6.5],[2,1.04,98]],"ltp":5.0,"tv":32.66,"id":8858707}]}]}
{"op":"mcm","clk":"11994081087","pt":1725019694010,"mc":[{"id":"1.232459454","rc":[{"batb":[[0,4.4,5],[1,4.3,13.4],[2,3,6.5]],"ltp":5.0,"tv":32.66,"id":8858707}]}]}
{"op":"mcm","clk":"11994081401","pt":1725019697594,"mc":[{"id":"1.232459454","rc":[{"batb":[[0,4.3,13.4],[1,3,6.5],[2,1.04,98]],"ltp":5.0,"tv":32.66,"id":8858707}]}]}
{"op":"mcm","clk":"11994082250","pt":1725019706218,"mc":[{"id":"1.232459454","rc":[{"batb":[[0,4.4,5],[1,4.3,13.4],[2,3,6.5]],"ltp":5.0,"tv":32.66,"id":8858707}]}]}
{"op":"mcm","clk":"11994082590","pt":1725019710012,"mc":[{"id":"1.232459454","rc":[{"batb":[[0,4.3,13.4],[1,3,6.5],[2,1.04,98]],"ltp":5.0,"tv":32.66,"id":8858707}]}]}
{"op":"mcm","clk":"11994083710","pt":1725019721644,"mc":[{"id":"1.232459454","rc":[{"batb":[[0,4.4,5],[1,4.3,13.4],[2,3,6.5]],"ltp":5.0,"tv":32.66,"id":8858707}]}]}
{"op":"mcm","clk":"11994084064","pt":1725019725320,"mc":[{"id":"1.232459454","rc":[{"batb":[[0,4.3,13.4],[1,3,6.5],[2,1.04,98]],"ltp":5.0,"tv":32.66,"id":8858707}]}]}
{"op":"mcm","clk":"11994084349","pt":1725019728328,"mc":[{"id":"1.232459454","rc":[{"batb":[[0,4.4,5],[1,4.3,13.4],[2,3,6.5]],"ltp":5.0,"tv":32.66,"id":8858707}]}]}
{"op":"mcm","clk":"11994084710","pt":1725019731942,"mc":[{"id":"1.232459454","rc":[{"batb":[[0,4.3,13.4],[1,3,6.5],[2,1.04,98]],"ltp":5.0,"tv":32.66,"id":8858707}]}]}
{"op":"mcm","clk":"11994086339","pt":1725019749459,"mc":[{"id":"1.232459454","rc":[{"batb":[[0,4.4,5],[1,4.3,13.4],[2,3,6.5]],"ltp":5.0,"tv":32.66,"id":8858707}]}]}
{"op":"mcm","clk":"11994086741","pt":1725019753054,"mc":[{"id":"1.232459454","rc":[{"batb":[[0,4.3,13.4],[1,3,6.5],[2,1.04,98]],"ltp":5.0,"tv":32.66,"id":8858707}]}]}
{"op":"mcm","clk":"11994087151","pt":1725019757596,"mc":[{"id":"1.232459454","rc":[{"batb":[[0,4.4,5],[1,4.3,13.4],[2,3,6.5]],"ltp":5.0,"tv":32.66,"id":8858707}]}]}
{"op":"mcm","clk":"11994087490","pt":1725019761083,"mc":[{"id":"1.232459454","rc":[{"batb":[[0,4.3,13.4],[1,3,6.5],[2,1.04,98]],"ltp":5.0,"tv":32.66,"id":8858707}]}]}
{"op":"mcm","clk":"11994088605","pt":1725019772690,"mc":[{"id":"1.232459454","rc":[{"batb":[[0,4.4,5],[1,4.3,13.4],[2,3,6.5]],"ltp":5.0,"tv":32.66,"id":8858707}]}]}
{"op":"mcm","clk":"11994088981","pt":1725019776414,"mc":[{"id":"1.232459454","rc":[{"batb":[[0,4.3,13.4],[1,3,6.5],[2,1.04,98]],"ltp":5.0,"tv":32.66,"id":8858707}]}]}
{"op":"mcm","clk":"11994089738","pt":1725019784333,"mc":[{"id":"1.232459454","rc":[{"batb":[[0,4.4,5],[1,4.3,13.4],[2,3,6.5]],"ltp":5.0,"tv":32.66,"id":8858707}]}]}
{"op":"mcm","clk":"11994090157","pt":1725019788633,"mc":[{"id":"1.232459454","rc":[{"batb":[[0,4.3,13.4],[1,3,6.5],[2,1.04,98]],"ltp":5.0,"tv":32.66,"id":8858707}]}]}
{"op":"mcm","clk":"11994090682","pt":1725019793919,"mc":[{"id":"1.232459454","rc":[{"batb":[[0,4.4,5],[1,4.3,13.4],[2,3,6.5]],"ltp":5.0,"tv":32.66,"id":8858707}]}]}
{"op":"mcm","clk":"11994091057","pt":1725019797647,"mc":[{"id":"1.232459454","rc":[{"batb":[[0,4.3,13.4],[1,3,6.5],[2,1.04,98]],"ltp":5.0,"tv":32.66,"id":8858707}]}]}
{"op":"mcm","clk":"11994091703","pt":1725019803623,"mc":[{"id":"1.232459454","rc":[{"batb":[[0,4.4,5],[1,4.3,13.4],[2,3,6.5]],"ltp":5.0,"tv":32.66,"id":8858707}]}]}
{"op":"mcm","clk":"11994092117","pt":1725019807361,"mc":[{"id":"1.232459454","rc":[{"batb":[[0,4.3,13.4],[1,3,6.5],[2,1.04,98]],"ltp":5.0,"tv":32.66,"id":8858707}]}]}
{"op":"mcm","clk":"11994093368","pt":1725019819966,"mc":[{"id":"1.232459454","rc":[{"batb":[[0,4.4,5],[1,4.3,13.4],[2,3,6.5]],"ltp":5.0,"tv":32.66,"id":8858707}]}]}
{"op":"mcm","clk":"11994093716","pt":1725019823551,"mc":[{"id":"1.232459454","rc":[{"batb":[[0,4.3,13.4],[1,3,6.5],[2,1.04,98]],"ltp":5.0,"tv":32.66,"id":8858707}]}]}
{"op":"mcm","clk":"11994094758","pt":1725019834551,"mc":[{"id":"1.232459454","rc":[{"batb":[[0,4.4,5],[1,4.3,13.4],[2,3,6.5]],"ltp":5.0,"tv":32.66,"id":8858707}]}]}
{"op":"mcm","clk":"11994095104","pt":1725019838381,"mc":[{"id":"1.232459454","rc":[{"batb":[[0,4.3,13.4],[1,3,6.5],[2,1.04,98]],"ltp":5.0,"tv":32.66,"id":8858707}]}]}
{"op":"mcm","clk":"11994095350","pt":1725019840976,"mc":[{"id":"1.232459454","rc":[{"batb":[[0,4.4,5],[1,4.3,13.4],[2,3,6.5]],"ltp":5.0,"tv":32.66,"id":8858707}]}]}
{"op":"mcm","clk":"11994095694","pt":1725019844491,"mc":[{"id":"1.232459454","rc":[{"batb":[[0,4.3,13.4],[1,3,6.5],[2,1.04,98]],"ltp":5.0,"tv":32.66,"id":8858707}]}]}
{"op":"mcm","clk":"11994095993","pt":1725019847998,"mc":[{"id":"1.232459454","rc":[{"batb":[[0,4.4,5],[1,4.3,13.4],[2,3,6.5]],"ltp":5.0,"tv":32.66,"id":8858707}]}]}
{"op":"mcm","clk":"11994096310","pt":1725019851874,"mc":[{"id":"1.232459454","rc":[{"batb":[[0,4.3,13.4],[1,3,6.5],[2,1.04,98]],"ltp":5.0,"tv":32.66,"id":8858707}]}]}
{"op":"mcm","clk":"11994096936","pt":1725019858824,"mc":[{"id":"1.232459454","rc":[{"batb":[[0,4.4,5],[1,4.3,13.4],[2,3,6.5]],"ltp":5.0,"tv":32.66,"id":8858707}]}]}
{"op":"mcm","clk":"11994097306","pt":1725019862516,"mc":[{"id":"1.232459454","rc":[{"batb":[[0,4.3,13.4],[1,3,6.5],[2,1.04,98]],"ltp":5.0,"tv":32.66,"id":8858707}]}]}
{"op":"mcm","clk":"11994098272","pt":1725019872461,"mc":[{"id":"1.232459454","rc":[{"batb":[[0,4.4,5],[1,4.3,13.4],[2,3,6.5]],"ltp":5.0,"tv":32.66,"id":8858707}]}]}
{"op":"mcm","clk":"11994098596","pt":1725019876143,"mc":[{"id":"1.232459454","rc":[{"batb":[[0,4.3,13.4],[1,3,6.5],[2,1.04,98]],"ltp":5.0,"tv":32.66,"id":8858707}]}]}
{"op":"mcm","clk":"11994098753","pt":1725019877851,"mc":[{"id":"1.232459454","rc":[{"batl":[[0,1.24,138.21],[1,1.25,103.04]],"ltp":1.21,"tv":895.97,"id":7587363}]}]}
{"op":"mcm","clk":"11994099191","pt":1725019882865,"mc":[{"id":"1.232459454","rc":[{"batb":[[0,4.4,5],[1,4.3,13.4],[2,3,6.5]],"ltp":5.0,"tv":32.66,"id":8858707}]}]}
{"op":"mcm","clk":"11994099546","pt":1725019886559,"mc":[{"id":"1.232459454","rc":[{"batb":[[0,4.3,13.4],[1,3,6.5],[2,1.04,98]],"ltp":5.0,"tv":32.66,"id":8858707}]}]}
{"op":"mcm","clk":"11994100071","pt":1725019890025,"mc":[{"id":"1.232459454","rc":[{"batb":[[0,4.4,5],[1,4.3,13.4],[2,3,6.5]],"ltp":5.0,"tv":32.66,"id":8858707}]}]}
{"op":"mcm","clk":"11994100681","pt":1725019894083,"mc":[{"id":"1.232459454","rc":[{"batb":[[0,4.3,13.4],[1,3,6.5],[2,1.04,98]],"ltp":5.0,"tv":32.66,"id":8858707}]}]}
{"op":"mcm","clk":"11994101209","pt":1725019898780,"mc":[{"id":"1.232459454","rc":[{"batb":[[0,4.4,5],[1,4.3,13.4],[2,3,6.5]],"ltp":5.0,"tv":32.66,"id":8858707}]}]}
{"op":"mcm","clk":"11994101617","pt":1725019902366,"mc":[{"id":"1.232459454","rc":[{"batb":[[0,4.3,13.4],[1,3,6.5],[2,1.04,98]],"ltp":5.0,"tv":32.66,"id":8858707}]}]}
{"op":"mcm","clk":"11994102067","pt":1725019906409,"mc":[{"id":"1.232459454","rc":[{"batb":[[0,4.4,5],[1,4.3,13.4],[2,3,6.5]],"ltp":5.0,"tv":32.66,"id":8858707}]}]}
{"op":"mcm","clk":"11994102414","pt":1725019909790,"mc":[{"id":"1.232459454","rc":[{"batb":[[0,4.3,13.4],[1,3,6.5],[2,1.04,98]],"ltp":5.0,"tv":32.66,"id":8858707}]}]}
{"op":"mcm","clk":"11994103455","pt":1725019919411,"mc":[{"id":"1.232459454","rc":[{"batb":[[0,4.4,5],[1,4.3,13.4],[2,3,6.5]],"ltp":5.0,"tv":32.66,"id":8858707}]}]}
{"op":"mcm","clk":"11994103916","pt":1725019922809,"mc":[{"id":"1.232459454","rc":[{"batb":[[0,4.3,13.4],[1,3,6.5],[2,1.04,98]],"ltp":5.0,"tv":32.66,"id":8858707}]}]}
{"op":"mcm","clk":"11994104804","pt":1725019930899,"mc":[{"id":"1.232459454","rc":[{"batb":[[0,4.4,5],[1,4.3,13.4],[2,3,6.5]],"ltp":5.0,"tv":32.66,"id":8858707}]}]}
{"op":"mcm","clk":"11994105200","pt":1725019934395,"mc":[{"id":"1.232459454","rc":[{"batb":[[0,4.3,13.4],[1,3,6.5],[2,1.04,98]],"ltp":5.0,"tv":32.66,"id":8858707}]}]}
{"op":"mcm","clk":"11994105549","pt":1725019937996,"mc":[{"id":"1.232459454","rc":[{"batb":[[0,4.4,5],[1,4.3,13.4],[2,3,6.5]],"ltp":5.0,"tv":32.66,"id":8858707}]}]}
{"op":"mcm","clk":"11994105883","pt":1725019941520,"mc":[{"id":"1.232459454","rc":[{"batb":[[0,4.3,13.4],[1,3,6.5],[2,1.04,98]],"ltp":5.0,"tv":32.66,"id":8858707}]}]}
{"op":"mcm","clk":"11994106311","pt":1725019945746,"mc":[{"id":"1.232459454","rc":[{"batb":[[0,4.4,5],[1,4.3,13.4],[2,3,6.5]],"ltp":5.0,"tv":32.66,"id":8858707}]}]}
{"op":"mcm","clk":"11994106638","pt":1725019949240,"mc":[{"id":"1.232459454","rc":[{"batb":[[0,4.3,13.4],[1,3,6.5],[2,1.04,98]],"ltp":5.0,"tv":32.66,"id":8858707}]}]}
{"op":"mcm","clk":"11994106949","pt":1725019952029,"mc":[{"id":"1.232459454","rc":[{"batb":[[0,4.4,5],[1,4.3,13.4],[2,3,6.5]],"ltp":5.0,"tv":32.66,"id":8858707}]}]}
{"op":"mcm","clk":"11994107399","pt":1725019955931,"mc":[{"id":"1.232459454","rc":[{"batb":[[0,4.3,13.4],[1,3,6.5],[2,1.04,98]],"ltp":5.0,"tv":32.66,"id":8858707}]}]}
{"op":"mcm","clk":"11994107610","pt":1725019958232,"mc":[{"id":"1.232459454","rc":[{"batb":[[0,4.4,5],[1,4.3,13.4],[2,3,6.5]],"ltp":5.0,"tv":32.66,"id":8858707}]}]}
{"op":"mcm","clk":"11994107955","pt":1725019961832,"mc":[{"id":"1.232459454","rc":[{"batb":[[0,4.3,13.4],[1,3,6.5],[2,1.04,98]],"ltp":5.0,"tv":32.66,"id":8858707}]}]}
{"op":"mcm","clk":"11994108244","pt":1725019964750,"mc":[{"id":"1.232459454","rc":[{"batb":[[0,4.4,5],[1,4.3,13.4],[2,3,6.5]],"ltp":5.0,"tv":32.66,"id":8858707}]}]}
{"op":"mcm","clk":"11994108635","pt":1725019968461,"mc":[{"id":"1.232459454","rc":[{"batb":[[0,4.3,13.4],[1,3,6.5],[2,1.04,98]],"ltp":5.0,"tv":32.66,"id":8858707}]}]}
{"op":"mcm","clk":"11994109447","pt":1725019975978,"mc":[{"id":"1.232459454","rc":[{"batb":[[0,4.4,5],[1,4.3,13.4],[2,3,6.5]],"ltp":5.0,"tv":32.66,"id":8858707}]}]}
{"op":"mcm","clk":"11994109897","pt":1725019979789,"mc":[{"id":"1.232459454","rc":[{"batb":[[0,4.3,13.4],[1,3,6.5],[2,1.04,98]],"ltp":5.0,"tv":32.66,"id":8858707}]}]}
{"op":"mcm","clk":"11994111349","pt":1725019993383,"mc":[{"id":"1.232459454","rc":[{"batb":[[0,4.4,5],[1,4.3,13.4],[2,3,6.5]],"ltp":5.0,"tv":32.66,"id":8858707}]}]}
{"op":"mcm","clk":"11994111742","pt":1725019997179,"mc":[{"id":"1.232459454","rc":[{"batb":[[0,4.3,13.4],[1,3,6.5],[2,1.04,98]],"ltp":5.0,"tv":32.66,"id":8858707}]}]}
{"op":"mcm","clk":"11994112398","pt":1725020002794,"mc":[{"id":"1.232459454","rc":[{"batb":[[0,4.4,5],[1,4.3,13.4],[2,3,6.5]],"ltp":5.0,"tv":32.66,"id":8858707}]}]}
{"op":"mcm","clk":"11994112771","pt":1725020006026,"mc":[{"id":"1.232459454","rc":[{"batb":[[0,4.3,13.4],[1,3,6.5],[2,1.04,98]],"ltp":5.0,"tv":32.66,"id":8858707}]}]}
{"op":"mcm","clk":"11994113101","pt":1725020008719,"mc":[{"id":"1.232459454","rc":[{"batb":[[0,4.4,5],[1,4.3,13.4],[2,3,6.5]],"ltp":5.0,"tv":32.66,"id":8858707}]}]}
{"op":"mcm","clk":"11994113543","pt":1725020012586,"mc":[{"id":"1.232459454","rc":[{"batb":[[0,4.3,13.4],[1,3,6.5],[2,1.04,98]],"ltp":5.0,"tv":32.66,"id":8858707}]}]}
{"op":"mcm","clk":"11994114223","pt":1725020018915,"mc":[{"id":"1.232459454","rc":[{"batb":[[0,4.4,5],[1,4.3,13.4],[2,3,6.5]],"ltp":5.0,"tv":32.66,"id":8858707}]}]}
{"op":"mcm","clk":"11994114618","pt":1725020022614,"mc":[{"id":"1.232459454","rc":[{"batb":[[0,4.3,13.4],[1,3,6.5],[2,1.04,98]],"ltp":5.0,"tv":32.66,"id":8858707}]}]}
{"op":"mcm","clk":"11994114986","pt":1725020026002,"mc":[{"id":"1.232459454","rc":[{"batb":[[0,4.4,5],[1,4.3,13.4],[2,3,6.5]],"ltp":5.0,"tv":32.66,"id":8858707}]}]}
{"op":"mcm","clk":"11994115313","pt":1725020029229,"mc":[{"id":"1.232459454","rc":[{"batb":[[0,4.3,13.4],[1,3,6.5],[2,1.04,98]],"ltp":5.0,"tv":32.66,"id":8858707}]}]}
{"op":"mcm","clk":"11994115649","pt":1725020032827,"mc":[{"id":"1.232459454","rc":[{"batb":[[0,4.4,5],[1,4.3,13.4],[2,3,6.5]],"ltp":5.0,"tv":32.66,"id":8858707}]}]}
{"op":"mcm","clk":"11994115739","pt":1725020033817,"mc":[{"id":"1.232459454","rc":[{"batb":[[0,1.04,97],[1,1.03,200],[2,1.02,200]],"ltp":1.21,"tv":895.97,"id":7587363}]}]}
{"op":"mcm","clk":"11994115995","pt":1725020036310,"mc":[{"id":"1.232459454","rc":[{"batb":[[0,4.3,13.4],[1,3,6.5],[2,1.04,98]],"ltp":5.0,"tv":32.66,"id":8858707}]}]}
{"op":"mcm","clk":"11994116099","pt":1725020037399,"mc":[{"id":"1.232459454","rc":[{"batl":[[0,1.25,103.04],[1,1.25,0]],"ltp":1.21,"tv":895.97,"id":7587363}]}]}
{"op":"mcm","clk":"11994116185","pt":1725020038516,"mc":[{"id":"1.232459454","rc":[{"batb":[[0,4.4,5],[1,4.3,13.4],[2,3,6.5]],"ltp":5.0,"tv":32.66,"id":8858707}]}]}
{"op":"mcm","clk":"11994116699","pt":1725020043310,"mc":[{"id":"1.232459454","rc":[{"batb":[[0,4.3,13.4],[1,3,6.5],[2,1.04,98]],"ltp":5.0,"tv":32.66,"id":8858707}]}]}
{"op":"mcm","clk":"11994117299","pt":1725020049043,"mc":[{"id":"1.232459454","rc":[{"batb":[[0,4.4,5],[1,4.3,13.4],[2,3,6.5]],"ltp":5.0,"tv":32.66,"id":8858707}]}]}
{"op":"mcm","clk":"11994117650","pt":1725020052425,"mc":[{"id":"1.232459454","rc":[{"batb":[[0,4.3,13.4],[1,3,6.5],[2,1.04,98]],"ltp":5.0,"tv":32.66,"id":8858707}]}]}
{"op":"mcm","clk":"11994119264","pt":1725020067456,"mc":[{"id":"1.232459454","rc":[{"batb":[[0,4.4,5],[1,4.3,13.4],[2,3,6.5]],"ltp":5.0,"tv":32.66,"id":8858707}]}]}
{"op":"mcm","clk":"11994119642","pt":1725020071308,"mc":[{"id":"1.232459454","rc":[{"batb":[[0,4.3,13.4],[1,3,6.5],[2,1.04,98]],"ltp":5.0,"tv":32.66,"id":8858707}]}]}
{"op":"mcm","clk":"11994120055","pt":1725020075983,"mc":[{"id":"1.232459454","rc":[{"batb":[[0,4.4,5],[1,4.3,13.4],[2,3,6.5]],"ltp":5.0,"tv":32.66,"id":8858707}]}]}
{"op":"mcm","clk":"11994120362","pt":1725020079507,"mc":[{"id":"1.232459454","rc":[{"batb":[[0,4.3,13.4],[1,3,6.5],[2,1.04,98]],"ltp":5.0,"tv":32.66,"id":8858707}]}]}
{"op":"mcm","clk":"11994120580","pt":1725020081795,"mc":[{"id":"1.232459454","rc":[{"batb":[[0,4.4,5],[1,4.3,13.4],[2,3,6.5]],"ltp":5.0,"tv":32.66,"id":8858707},{"batb":[[0,1.05,5.52],[1,1.04,97],[2,1.03,200]],"ltp":1.21,"tv":895.97,"id":7587363}]}]}
{"op":"mcm","clk":"11994120897","pt":1725020085069,"mc":[{"id":"1.232459454","rc":[{"batb":[[0,4.3,13.4],[1,3,6.5],[2,1.04,98]],"ltp":5.0,"tv":32.66,"id":8858707}]}]}
{"op":"mcm","clk":"11994121820","pt":1725020095296,"mc":[{"id":"1.232459454","rc":[{"batb":[[0,4.4,5],[1,4.3,13.4],[2,3,6.5]],"ltp":5.0,"tv":32.66,"id":8858707}]}]}
{"op":"mcm","clk":"11994122101","pt":1725020099219,"mc":[{"id":"1.232459454","rc":[{"batb":[[0,4.3,13.4],[1,3,6.5],[2,1.04,98]],"ltp":5.0,"tv":32.66,"id":8858707}]}]}
{"op":"mcm","clk":"11994122699","pt":1725020105103,"mc":[{"id":"1.232459454","rc":[{"batb":[[0,4.4,5],[1,4.3,13.4],[2,3,6.5]],"ltp":5.0,"tv":32.66,"id":8858707}]}]}
{"op":"mcm","clk":"11994123074","pt":1725020108810,"mc":[{"id":"1.232459454","rc":[{"batb":[[0,4.3,13.4],[1,3,6.5],[2,1.04,98]],"ltp":5.0,"tv":32.66,"id":8858707}]}]}
{"op":"mcm","clk":"11994126854","pt":1725020147123,"mc":[{"id":"1.232459454","rc":[{"batb":[[0,4.4,5],[1,4.3,13.4],[2,3,6.5]],"ltp":5.0,"tv":32.66,"id":8858707}]}]}
{"op":"mcm","clk":"11994127222","pt":1725020150830,"mc":[{"id":"1.232459454","rc":[{"batb":[[0,4.3,13.4],[1,3,6.5],[2,1.04,98]],"ltp":5.0,"tv":32.66,"id":8858707}]}]}
{"op":"mcm","clk":"11994128034","pt":1725020158840,"mc":[{"id":"1.232459454","rc":[{"batb":[[0,4.4,5],[1,4.3,13.4],[2,3,6.5]],"ltp":5.0,"tv":32.66,"id":8858707}]}]}
{"op":"mcm","clk":"11994128492","pt":1725020163251,"mc":[{"id":"1.232459454","rc":[{"batb":[[0,4.3,13.4],[1,3,6.5],[2,1.04,98]],"ltp":5.0,"tv":32.66,"id":8858707}]}]}
{"op":"mcm","clk":"11994128940","pt":1725020167848,"mc":[{"id":"1.232459454","rc":[{"batb":[[0,4.4,5],[1,4.3,13.4],[2,3,6.5]],"ltp":5.0,"tv":32.66,"id":8858707}]}]}
{"op":"mcm","clk":"11994129256","pt":1725020171249,"mc":[{"id":"1.232459454","rc":[{"batb":[[0,4.3,13.4],[1,3,6.5],[2,1.04,98]],"ltp":5.0,"tv":32.66,"id":8858707}]}]}
{"op":"mcm","clk":"11994130563","pt":1725020185050,"mc":[{"id":"1.232459454","rc":[{"batb":[[0,4.4,5],[1,4.3,13.4],[2,3,6.5]],"ltp":5.0,"tv":32.66,"id":8858707}]}]}
{"op":"mcm","clk":"11994130941","pt":1725020188666,"mc":[{"id":"1.232459454","rc":[{"batb":[[0,4.3,13.4],[1,3,6.5],[2,1.04,98]],"ltp":5.0,"tv":32.66,"id":8858707}]}]}
{"op":"mcm","clk":"11994131900","pt":1725020199244,"mc":[{"id":"1.232459454","rc":[{"batb":[[0,4.4,5],[1,4.3,13.4],[2,3,6.5]],"ltp":5.0,"tv":32.66,"id":8858707}]}]}
{"op":"mcm","clk":"11994132171","pt":1725020202169,"mc":[{"id":"1.232459454","rc":[{"batb":[[0,4.3,13.4],[1,3,6.5],[2,1.04,98]],"ltp":5.0,"tv":32.66,"id":8858707}]}]}
{"op":"mcm","clk":"11994132806","pt":1725020209873,"mc":[{"id":"1.232459454","rc":[{"batb":[[0,4.4,5],[1,4.3,13.4],[2,3,6.5]],"ltp":5.0,"tv":32.66,"id":8858707}]}]}
{"op":"mcm","clk":"11994133280","pt":1725020215074,"mc":[{"id":"1.232459454","rc":[{"batb":[[0,4.3,13.4],[1,3,6.5],[2,1.04,98]],"ltp":5.0,"tv":32.66,"id":8858707}]}]}
{"op":"mcm","clk":"11994133558","pt":1725020218566,"mc":[{"id":"1.232459454","rc":[{"batb":[[0,4.4,5],[1,4.3,13.4],[2,3,6.5]],"ltp":5.0,"tv":32.66,"id":8858707}]}]}
{"op":"mcm","clk":"11994133857","pt":1725020222072,"mc":[{"id":"1.232459454","rc":[{"batb":[[0,4.3,13.4],[1,3,6.5],[2,1.04,98]],"ltp":5.0,"tv":32.66,"id":8858707}]}]}
{"op":"mcm","clk":"11994134975","pt":1725020235514,"mc":[{"id":"1.232459454","rc":[{"batb":[[0,4.4,5],[1,4.3,13.4],[2,3,6.5]],"ltp":5.0,"tv":32.66,"id":8858707}]}]}
{"op":"mcm","clk":"11994135363","pt":1725020240026,"mc":[{"id":"1.232459454","rc":[{"batb":[[0,4.3,13.4],[1,3,6.5],[2,1.04,98]],"ltp":5.0,"tv":32.66,"id":8858707}]}]}
{"op":"mcm","clk":"11994135998","pt":1725020246330,"mc":[{"id":"1.232459454","rc":[{"batb":[[0,4.4,5],[1,4.3,13.4],[2,3,6.5]],"ltp":5.0,"tv":32.66,"id":8858707}]}]}
{"op":"mcm","clk":"11994136347","pt":1725020250224,"mc":[{"id":"1.232459454","rc":[{"batb":[[0,4.3,13.4],[1,3,6.5],[2,1.04,98]],"ltp":5.0,"tv":32.66,"id":8858707}]}]}
{"op":"mcm","clk":"11994136591","pt":1725020252553,"mc":[{"id":"1.232459454","rc":[{"batb":[[0,4.4,5],[1,4.3,13.4],[2,3,6.5]],"ltp":5.0,"tv":32.66,"id":8858707}]}]}
{"op":"mcm","clk":"11994136957","pt":1725020256556,"mc":[{"id":"1.232459454","rc":[{"batb":[[0,4.3,13.4],[1,3,6.5],[2,1.04,98]],"ltp":5.0,"tv":32.66,"id":8858707}]}]}
{"op":"mcm","clk":"11994137893","pt":1725020266864,"mc":[{"id":"1.232459454","rc":[{"batb":[[0,4.4,5],[1,4.3,13.4],[2,3,6.5]],"ltp":5.0,"tv":32.66,"id":8858707}]}]}
{"op":"mcm","clk":"11994138285","pt":1725020270966,"mc":[{"id":"1.232459454","rc":[{"batb":[[0,4.3,13.4],[1,3,6.5],[2,1.04,98]],"ltp":5.0,"tv":32.66,"id":8858707}]}]}
{"op":"mcm","clk":"11994139016","pt":1725020279153,"mc":[{"id":"1.232459454","rc":[{"batb":[[0,4.4,5],[1,4.3,13.4],[2,3,6.5]],"ltp":5.0,"tv":32.66,"id":8858707}]}]}
{"op":"mcm","clk":"11994139338","pt":1725020282788,"mc":[{"id":"1.232459454","rc":[{"batb":[[0,4.3,13.4],[1,3,6.5],[2,1.04,98]],"ltp":5.0,"tv":32.66,"id":8858707}]}]}
{"op":"mcm","clk":"11994141002","pt":1725020300577,"mc":[{"id":"1.232459454","rc":[{"batb":[[0,4.4,5],[1,4.3,13.4],[2,3,6.5]],"ltp":5.0,"tv":32.66,"id":8858707}]}]}
{"op":"mcm","clk":"11994141330","pt":1725020304299,"mc":[{"id":"1.232459454","rc":[{"batb":[[0,4.3,13.4],[1,3,6.5],[2,1.04,98]],"ltp":5.0,"tv":32.66,"id":8858707}]}]}
{"op":"mcm","clk":"11994142081","pt":1725020314391,"mc":[{"id":"1.232459454","rc":[{"batb":[[0,4.4,5],[1,4.3,13.4],[2,3,6.5]],"ltp":5.0,"tv":32.66,"id":8858707}]}]}
{"op":"mcm","clk":"11994142365","pt":1725020318195,"mc":[{"id":"1.232459454","rc":[{"batb":[[0,4.3,13.4],[1,3,6.5],[2,1.04,98]],"ltp":5.0,"tv":32.66,"id":8858707}]}]}
{"op":"mcm","clk":"11994143097","pt":1725020326818,"mc":[{"id":"1.232459454","rc":[{"batb":[[0,4.4,5],[1,4.3,13.4],[2,3,6.5]],"ltp":5.0,"tv":32.66,"id":8858707}]}]}
{"op":"mcm","clk":"11994143348","pt":1725020330235,"mc":[{"id":"1.232459454","rc":[{"batb":[[0,4.3,13.4],[1,3,6.5],[2,1.04,98]],"ltp":5.0,"tv":32.66,"id":8858707}]}]}
{"op":"mcm","clk":"11994143568","pt":1725020333232,"mc":[{"id":"1.232459454","rc":[{"batb":[[0,4.4,5],[1,4.3,13.4],[2,3,6.5]],"ltp":5.0,"tv":32.66,"id":8858707}]}]}
{"op":"mcm","clk":"11994143797","pt":1725020336549,"mc":[{"id":"1.232459454","rc":[{"batb":[[0,4.3,13.4],[1,3,6.5],[2,1.04,98]],"ltp":5.0,"tv":32.66,"id":8858707}]}]}
{"op":"mcm","clk":"11994144389","pt":1725020342939,"mc":[{"id":"1.232459454","rc":[{"batb":[[0,4.4,5],[1,4.3,13.4],[2,3,6.5]],"ltp":5.0,"tv":32.66,"id":8858707}]}]}
{"op":"mcm","clk":"11994144764","pt":1725020346838,"mc":[{"id":"1.232459454","rc":[{"batb":[[0,4.3,13.4],[1,3,6.5],[2,1.04,98]],"ltp":5.0,"tv":32.66,"id":8858707}]}]}
{"op":"mcm","clk":"11994145007","pt":1725020349324,"mc":[{"id":"1.232459454","rc":[{"batb":[[0,4.4,5],[1,4.3,13.4],[2,3,6.5]],"ltp":5.0,"tv":32.66,"id":8858707}]}]}
{"op":"mcm","clk":"11994145374","pt":1725020353024,"mc":[{"id":"1.232459454","rc":[{"batb":[[0,4.3,13.4],[1,3,6.5],[2,1.04,98]],"ltp":5.0,"tv":32.66,"id":8858707}]}]}
{"op":"mcm","clk":"11994145625","pt":1725020355731,"mc":[{"id":"1.232459454","rc":[{"batb":[[0,4.4,5],[1,4.3,13.4],[2,3,6.5]],"ltp":5.0,"tv":32.66,"id":8858707}]}]}
{"op":"mcm","clk":"11994145943","pt":1725020359544,"mc":[{"id":"1.232459454","rc":[{"batb":[[0,4.3,13.4],[1,3,6.5],[2,1.04,98]],"ltp":5.0,"tv":32.66,"id":8858707}]}]}
{"op":"mcm","clk":"11994146181","pt":1725020362083,"mc":[{"id":"1.232459454","rc":[{"batb":[[0,4.4,5],[1,4.3,13.4],[2,3,6.5]],"ltp":5.0,"tv":32.66,"id":8858707}]}]}
{"op":"mcm","clk":"11994146480","pt":1725020365767,"mc":[{"id":"1.232459454","rc":[{"batb":[[0,4.3,13.4],[1,3,6.5],[2,1.04,98]],"ltp":5.0,"tv":32.66,"id":8858707}]}]}
{"op":"mcm","clk":"11994147023","pt":1725020372894,"mc":[{"id":"1.232459454","rc":[{"batb":[[0,4.4,5],[1,4.3,13.4],[2,3,6.5]],"ltp":5.0,"tv":32.66,"id":8858707}]}]}
{"op":"mcm","clk":"11994147337","pt":1725020376670,"mc":[{"id":"1.232459454","rc":[{"batb":[[0,4.3,13.4],[1,3,6.5],[2,1.04,98]],"ltp":5.0,"tv":32.66,"id":8858707}]}]}
{"op":"mcm","clk":"11994147699","pt":1725020381601,"mc":[{"id":"1.232459454","rc":[{"batb":[[0,4.4,5],[1,4.3,13.4],[2,3,6.5]],"ltp":5.0,"tv":32.66,"id":8858707}]}]}
{"op":"mcm","clk":"11994148017","pt":1725020385195,"mc":[{"id":"1.232459454","rc":[{"batb":[[0,4.3,13.4],[1,3,6.5],[2,1.04,98]],"ltp":5.0,"tv":32.66,"id":8858707}]}]}
{"op":"mcm","clk":"11994148610","pt":1725020389701,"mc":[{"id":"1.232459454","rc":[{"batb":[[0,4.4,5],[1,4.3,13.4],[2,3,6.5]],"ltp":5.0,"tv":32.66,"id":8858707}]}]}
{"op":"mcm","clk":"11994149171","pt":1725020393422,"mc":[{"id":"1.232459454","rc":[{"batb":[[0,4.3,13.4],[1,3,6.5],[2,1.04,98]],"ltp":5.0,"tv":32.66,"id":8858707}]}]}
{"op":"mcm","clk":"11994149729","pt":1725020399511,"mc":[{"id":"1.232459454","rc":[{"batb":[[0,4.4,5],[1,4.3,13.4],[2,3,6.5]],"ltp":5.0,"tv":32.66,"id":8858707}]}]}
{"op":"mcm","clk":"11994150108","pt":1725020402747,"mc":[{"id":"1.232459454","rc":[{"batb":[[0,4.3,13.4],[1,3,6.5],[2,1.04,98]],"ltp":5.0,"tv":32.66,"id":8858707}]}]}
{"op":"mcm","clk":"11994150768","pt":1725020408529,"mc":[{"id":"1.232459454","rc":[{"batb":[[0,4.4,5],[1,4.3,13.4],[2,3,6.5]],"ltp":5.0,"tv":32.66,"id":8858707}]}]}
{"op":"mcm","clk":"11994151083","pt":1725020411846,"mc":[{"id":"1.232459454","rc":[{"batb":[[0,4.3,13.4],[1,3,6.5],[2,1.04,98]],"ltp":5.0,"tv":32.66,"id":8858707}]}]}
{"op":"mcm","clk":"11994151874","pt":1725020419778,"mc":[{"id":"1.232459454","rc":[{"batb":[[0,4.4,5],[1,4.3,13.4],[2,3,6.5]],"ltp":5.0,"tv":32.66,"id":8858707}]}]}
{"op":"mcm","clk":"11994152288","pt":1725020423465,"mc":[{"id":"1.232459454","rc":[{"batb":[[0,4.3,13.4],[1,3,6.5],[2,1.04,98]],"ltp":5.0,"tv":32.66,"id":8858707}]}]}
{"op":"mcm","clk":"11994152987","pt":1725020430279,"mc":[{"id":"1.232459454","rc":[{"batb":[[0,4.4,5],[1,4.3,13.4],[2,3,6.5]],"ltp":5.0,"tv":32.66,"id":8858707}]}]}
{"op":"mcm","clk":"11994153355","pt":1725020434178,"mc":[{"id":"1.232459454","rc":[{"batb":[[0,4.3,13.4],[1,3,6.5],[2,1.04,98]],"ltp":5.0,"tv":32.66,"id":8858707}]}]}
{"op":"mcm","clk":"11994153582","pt":1725020436577,"mc":[{"id":"1.232459454","rc":[{"batb":[[0,4.4,5],[1,4.3,13.4],[2,3,6.5]],"ltp":5.0,"tv":32.66,"id":8858707}]}]}
{"op":"mcm","clk":"11994153901","pt":1725020440000,"mc":[{"id":"1.232459454","rc":[{"batb":[[0,4.3,13.4],[1,3,6.5],[2,1.04,98]],"ltp":5.0,"tv":32.66,"id":8858707}]}]}
{"op":"mcm","clk":"11994154820","pt":1725020448702,"mc":[{"id":"1.232459454","rc":[{"batb":[[0,4.4,5],[1,4.3,13.4],[2,3,6.5]],"ltp":5.0,"tv":32.66,"id":8858707}]}]}
{"op":"mcm","clk":"11994155200","pt":1725020452403,"mc":[{"id":"1.232459454","rc":[{"batb":[[0,4.3,13.4],[1,3,6.5],[2,1.04,98]],"ltp":5.0,"tv":32.66,"id":8858707}]}]}
{"op":"mcm","clk":"11994155576","pt":1725020456000,"mc":[{"id":"1.232459454","rc":[{"batb":[[0,4.4,5],[1,4.3,13.4],[2,3,6.5]],"ltp":5.0,"tv":32.66,"id":8858707}]}]}
{"op":"mcm","clk":"11994155937","pt":1725020459204,"mc":[{"id":"1.232459454","rc":[{"batb":[[0,4.3,13.4],[1,3,6.5],[2,1.04,98]],"ltp":5.0,"tv":32.66,"id":8858707}]}]}
{"op":"mcm","clk":"11994156352","pt":1725020462795,"mc":[{"id":"1.232459454","rc":[{"batb":[[0,4.4,5],[1,4.3,13.4],[2,3,6.5]],"ltp":5.0,"tv":32.66,"id":8858707},{"batb":[[0,1.17,16.76],[1,1.05,5.52],[2,1.04,97]],"ltp":1.21,"tv":895.97,"id":7587363}]}]}
{"op":"mcm","clk":"11994156672","pt":1725020466116,"mc":[{"id":"1.232459454","rc":[{"batb":[[0,4.3,13.4],[1,3,6.5],[2,1.04,98]],"ltp":5.0,"tv":32.66,"id":8858707}]}]}
{"op":"mcm","clk":"11994157339","pt":1725020472742,"mc":[{"id":"1.232459454","rc":[{"batb":[[0,4.4,5],[1,4.3,13.4],[2,3,6.5]],"ltp":5.0,"tv":32.66,"id":8858707}]}]}
{"op":"mcm","clk":"11994157795","pt":1725020476527,"mc":[{"id":"1.232459454","rc":[{"batb":[[0,4.3,13.4],[1,3,6.5],[2,1.04,98]],"ltp":5.0,"tv":32.66,"id":8858707}]}]}
{"op":"mcm","clk":"11994158061","pt":1725020479014,"mc":[{"id":"1.232459454","rc":[{"batb":[[0,4.4,5],[1,4.3,13.4],[2,3,6.5]],"ltp":5.0,"tv":32.66,"id":8858707}]}]}
{"op":"mcm","clk":"11994158396","pt":1725020482646,"mc":[{"id":"1.232459454","rc":[{"batb":[[0,4.3,13.4],[1,3,6.5],[2,1.04,98]],"ltp":5.0,"tv":32.66,"id":8858707}]}]}
{"op":"mcm","clk":"11994159074","pt":1725020488733,"mc":[{"id":"1.232459454","rc":[{"batb":[[0,4.4,5],[1,4.3,13.4],[2,3,6.5]],"ltp":5.0,"tv":32.66,"id":8858707}]}]}
{"op":"mcm","clk":"11994159375","pt":1725020491952,"mc":[{"id":"1.232459454","rc":[{"batb":[[0,4.3,13.4],[1,3,6.5],[2,1.04,98]],"ltp":5.0,"tv":32.66,"id":8858707}]}]}
{"op":"mcm","clk":"11994159934","pt":1725020497352,"mc":[{"id":"1.232459454","rc":[{"batb":[[0,4.4,5],[1,4.3,13.4],[2,3,6.5]],"ltp":5.0,"tv":32.66,"id":8858707}]}]}
{"op":"mcm","clk":"11994160314","pt":1725020501187,"mc":[{"id":"1.232459454","rc":[{"batb":[[0,4.3,13.4],[1,3,6.5],[2,1.04,98]],"ltp":5.0,"tv":32.66,"id":8858707}]}]}
{"op":"mcm","clk":"11994160556","pt":1725020503673,"mc":[{"id":"1.232459454","rc":[{"batb":[[0,4.4,5],[1,4.3,13.4],[2,3,6.5]],"ltp":5.0,"tv":32.66,"id":8858707}]}]}
{"op":"mcm","clk":"11994160916","pt":1725020507362,"mc":[{"id":"1.232459454","rc":[{"batb":[[0,4.3,13.4],[1,3,6.5],[2,1.04,98]],"ltp":5.0,"tv":32.66,"id":8858707}]}]}
{"op":"mcm","clk":"11994161404","pt":1725020512569,"mc":[{"id":"1.232459454","rc":[{"batb":[[0,4.4,5],[1,4.3,13.4],[2,3,6.5]],"ltp":5.0,"tv":32.66,"id":8858707}]}]}
{"op":"mcm","clk":"11994161675","pt":1725020515885,"mc":[{"id":"1.232459454","rc":[{"batb":[[0,4.3,13.4],[1,3,6.5],[2,1.04,98]],"ltp":5.0,"tv":32.66,"id":8858707}]}]}
{"op":"mcm","clk":"11994162050","pt":1725020520180,"mc":[{"id":"1.232459454","rc":[{"batb":[[0,4.4,5],[1,4.3,13.4],[2,3,6.5]],"ltp":5.0,"tv":32.66,"id":8858707}]}]}
{"op":"mcm","clk":"11994162332","pt":1725020523678,"mc":[{"id":"1.232459454","rc":[{"batb":[[0,4.3,13.4],[1,3,6.5],[2,1.04,98]],"ltp":5.0,"tv":32.66,"id":8858707}]}]}
{"op":"mcm","clk":"11994163011","pt":1725020531292,"mc":[{"id":"1.232459454","rc":[{"batb":[[0,4.4,5],[1,4.3,13.4],[2,3,6.5]],"ltp":5.0,"tv":32.66,"id":8858707}]}]}
{"op":"mcm","clk":"11994163358","pt":1725020535298,"mc":[{"id":"1.232459454","rc":[{"batb":[[0,4.3,13.4],[1,3,6.5],[2,1.04,98]],"ltp":5.0,"tv":32.66,"id":8858707}]}]}
{"op":"mcm","clk":"11994164547","pt":1725020548109,"mc":[{"id":"1.232459454","rc":[{"batb":[[0,4.4,5],[1,4.3,13.4],[2,3,6.5]],"ltp":5.0,"tv":32.66,"id":8858707},{"batb":[[1,1.04,97],[2,1.03,200]],"ltp":1.21,"tv":895.97,"id":7587363}]}]}
{"op":"mcm","clk":"11994164881","pt":1725020551647,"mc":[{"id":"1.232459454","rc":[{"batb":[[0,4.3,13.4],[1,3,6.5],[2,1.04,98]],"ltp":5.0,"tv":32.66,"id":8858707}]}]}
{"op":"mcm","clk":"11994165430","pt":1725020556329,"mc":[{"id":"1.232459454","rc":[{"batb":[[0,4.4,5],[1,4.3,13.4],[2,3,6.5]],"ltp":5.0,"tv":32.66,"id":8858707}]}]}
{"op":"mcm","clk":"11994165924","pt":1725020560961,"mc":[{"id":"1.232459454","rc":[{"batb":[[0,4.3,13.4],[1,3,6.5],[2,1.04,98]],"ltp":5.0,"tv":32.66,"id":8858707}]}]}
{"op":"mcm","clk":"11994167379","pt":1725020575670,"mc":[{"id":"1.232459454","rc":[{"batb":[[0,4.4,5],[1,4.3,13.4],[2,3,6.5]],"ltp":5.0,"tv":32.66,"id":8858707}]}]}
{"op":"mcm","clk":"11994167671","pt":1725020579357,"mc":[{"id":"1.232459454","rc":[{"batb":[[0,4.3,13.4],[1,3,6.5],[2,1.04,98]],"ltp":5.0,"tv":32.66,"id":8858707}]}]}
{"op":"mcm","clk":"11994168291","pt":1725020585877,"mc":[{"id":"1.232459454","rc":[{"batb":[[0,4.4,5],[1,4.3,13.4],[2,3,6.5]],"ltp":5.0,"tv":32.66,"id":8858707}]}]}
{"op":"mcm","clk":"11994168688","pt":1725020589785,"mc":[{"id":"1.232459454","rc":[{"batb":[[0,4.3,13.4],[1,3,6.5],[2,1.04,98]],"ltp":5.0,"tv":32.66,"id":8858707}]}]}
{"op":"mcm","clk":"11994171288","pt":1725020617119,"mc":[{"id":"1.232459454","rc":[{"batb":[[0,4.4,5],[1,4.3,13.4],[2,3,6.5]],"ltp":5.0,"tv":32.66,"id":8858707}]}]}
{"op":"mcm","clk":"11994171606","pt":1725020620801,"mc":[{"id":"1.232459454","rc":[{"batb":[[0,4.3,13.4],[1,3,6.5],[2,1.04,98]],"ltp":5.0,"tv":32.66,"id":8858707}]}]}
{"op":"mcm","clk":"11994171868","pt":1725020623402,"mc":[{"id":"1.232459454","rc":[{"batb":[[0,4.4,5],[1,4.3,13.4],[2,3,6.5]],"ltp":5.0,"tv":32.66,"id":8858707}]}]}
{"op":"mcm","clk":"11994172197","pt":1725020627051,"mc":[{"id":"1.232459454","rc":[{"batb":[[0,4.3,13.4],[1,3,6.5],[2,1.04,98]],"ltp":5.0,"tv":32.66,"id":8858707}]}]}
{"op":"mcm","clk":"11994173573","pt":1725020642161,"mc":[{"id":"1.232459454","rc":[{"batb":[[0,4.4,5],[1,4.3,13.4],[2,3,6.5]],"ltp":5.0,"tv":32.66,"id":8858707}]}]}
{"op":"mcm","clk":"11994173967","pt":1725020645956,"mc":[{"id":"1.232459454","rc":[{"batb":[[0,4.3,13.4],[1,3,6.5],[2,1.04,98]],"ltp":5.0,"tv":32.66,"id":8858707}]}]}
{"op":"mcm","clk":"11994174942","pt":1725020655393,"mc":[{"id":"1.232459454","rc":[{"batb":[[0,4.4,5],[1,4.3,13.4],[2,3,6.5]],"ltp":5.0,"tv":32.66,"id":8858707}]}]}
{"op":"mcm","clk":"11994175311","pt":1725020659163,"mc":[{"id":"1.232459454","rc":[{"batb":[[0,4.3,13.4],[1,3,6.5],[2,1.04,98]],"ltp":5.0,"tv":32.66,"id":8858707}]}]}
{"op":"mcm","clk":"11994175586","pt":1725020661992,"mc":[{"id":"1.232459454","rc":[{"batb":[[0,4.4,5],[1,4.3,13.4],[2,3,6.5]],"ltp":5.0,"tv":32.66,"id":8858707}]}]}
{"op":"mcm","clk":"11994175946","pt":1725020665707,"mc":[{"id":"1.232459454","rc":[{"batb":[[0,4.3,13.4],[1,3,6.5],[2,1.04,98]],"ltp":5.0,"tv":32.66,"id":8858707}]}]}
{"op":"mcm","clk":"11994176313","pt":1725020669302,"mc":[{"id":"1.232459454","rc":[{"batb":[[0,4.4,5],[1,4.3,13.4],[2,3,6.5]],"ltp":5.0,"tv":32.66,"id":8858707}]}]}
{"op":"mcm","clk":"11994176700","pt":1725020673006,"mc":[{"id":"1.232459454","rc":[{"batb":[[0,4.3,13.4],[1,3,6.5],[2,1.04,98]],"ltp":5.0,"tv":32.66,"id":8858707}]}]}
{"op":"mcm","clk":"11994177207","pt":1725020678782,"mc":[{"id":"1.232459454","rc":[{"batb":[[0,4.4,5],[1,4.3,13.4],[2,3,6.5]],"ltp":5.0,"tv":32.66,"id":8858707}]}]}
{"op":"mcm","clk":"11994177561","pt":1725020682328,"mc":[{"id":"1.232459454","rc":[{"batb":[[0,4.3,13.4],[1,3,6.5],[2,1.04,98]],"ltp":5.0,"tv":32.66,"id":8858707}]}]}
{"op":"mcm","clk":"11994178535","pt":1725020689532,"mc":[{"id":"1.232459454","rc":[{"batb":[[0,4.4,5],[1,4.3,13.4],[2,3,6.5]],"ltp":5.0,"tv":32.66,"id":8858707}]}]}
{"op":"mcm","clk":"11994179011","pt":1725020693254,"mc":[{"id":"1.232459454","rc":[{"batb":[[0,4.3,13.4],[1,3,6.5],[2,1.04,98]],"ltp":5.0,"tv":32.66,"id":8858707}]}]}
{"op":"mcm","clk":"11994179677","pt":1725020699330,"mc":[{"id":"1.232459454","rc":[{"batb":[[0,4.4,5],[1,4.3,13.4],[2,3,6.5]],"ltp":5.0,"tv":32.66,"id":8858707}]}]}
{"op":"mcm","clk":"11994180136","pt":1725020703246,"mc":[{"id":"1.232459454","rc":[{"batb":[[0,4.3,13.4],[1,3,6.5],[2,1.04,98]],"ltp":5.0,"tv":32.66,"id":8858707}]}]}
{"op":"mcm","clk":"11994180930","pt":1725020710671,"mc":[{"id":"1.232459454","rc":[{"batb":[[0,4.4,5],[1,4.3,13.4],[2,3,6.5]],"ltp":5.0,"tv":32.66,"id":8858707}]}]}
{"op":"mcm","clk":"11994181345","pt":1725020714061,"mc":[{"id":"1.232459454","rc":[{"batb":[[0,4.3,13.4],[1,3,6.5],[2,1.04,98]],"ltp":5.0,"tv":32.66,"id":8858707}]}]}
{"op":"mcm","clk":"11994182576","pt":1725020725477,"mc":[{"id":"1.232459454","rc":[{"batb":[[0,4.4,5],[1,4.3,13.4],[2,3,6.5]],"ltp":5.0,"tv":32.66,"id":8858707}]}]}
{"op":"mcm","clk":"11994182963","pt":1725020728965,"mc":[{"id":"1.232459454","rc":[{"batb":[[0,4.3,13.4],[1,3,6.5],[2,1.04,98]],"ltp":5.0,"tv":32.66,"id":8858707}]}]}
{"op":"mcm","clk":"11994183796","pt":1725020736381,"mc":[{"id":"1.232459454","rc":[{"batb":[[0,4.4,5],[1,4.3,13.4],[2,3,6.5]],"ltp":5.0,"tv":32.66,"id":8858707}]}]}
{"op":"mcm","clk":"11994184150","pt":1725020740188,"mc":[{"id":"1.232459454","rc":[{"batb":[[0,4.3,13.4],[1,3,6.5],[2,1.04,98]],"ltp":5.0,"tv":32.66,"id":8858707}]}]}
{"op":"mcm","clk":"11994184637","pt":1725020745788,"mc":[{"id":"1.232459454","rc":[{"batb":[[0,4.4,5],[1,4.3,13.4],[2,3,6.5]],"ltp":5.0,"tv":32.66,"id":8858707}]}]}
{"op":"mcm","clk":"11994184911","pt":1725020749115,"mc":[{"id":"1.232459454","rc":[{"batb":[[0,1.18,4.19],[1,1.17,16.76],[2,1.04,97]],"ltp":1.21,"tv":895.97,"id":7587363}]}]}
{"op":"mcm","clk":"11994184976","pt":1725020749685,"mc":[{"id":"1.232459454","rc":[{"batb":[[0,4.3,13.4],[1,3,6.5],[2,1.04,98]],"ltp":5.0,"tv":32.66,"id":8858707}]}]}
{"op":"mcm","clk":"11994185358","pt":1725020753097,"mc":[{"id":"1.232459454","rc":[{"batb":[[0,4.4,5],[1,4.3,13.4],[2,3,6.5]],"ltp":5.0,"tv":32.66,"id":8858707}]}]}
{"op":"mcm","clk":"11994185722","pt":1725020756886,"mc":[{"id":"1.232459454","rc":[{"batb":[[0,4.3,13.4],[1,3,6.5],[2,1.04,98]],"ltp":5.0,"tv":32.66,"id":8858707}]}]}
{"op":"mcm","clk":"11994186381","pt":1725020763906,"mc":[{"id":"1.232459454","rc":[{"batb":[[0,4.4,5],[1,4.3,13.4],[2,3,6.5]],"ltp":5.0,"tv":32.66,"id":8858707}]}]}
{"op":"mcm","clk":"11994189315","pt":1725020794271,"mc":[{"id":"1.232459454","rc":[{"batb":[[0,4.3,13.4],[1,3,6.5],[2,1.04,98]],"ltp":5.0,"tv":32.66,"id":8858707}]}]}
{"op":"mcm","clk":"11994189722","pt":1725020798151,"mc":[{"id":"1.232459454","rc":[{"batb":[[0,4.5,5],[1,4.3,13.4],[2,3,6.5]],"ltp":5.0,"tv":32.66,"id":8858707}]}]}
{"op":"mcm","clk":"11994190507","pt":1725020805669,"mc":[{"id":"1.232459454","rc":[{"batb":[[0,4.3,13.4],[1,3,6.5],[2,1.04,98]],"ltp":5.0,"tv":32.66,"id":8858707}]}]}
{"op":"mcm","clk":"11994190732","pt":1725020807856,"mc":[{"id":"1.232459454","rc":[{"batb":[[0,4.4,5],[1,4.3,13.4],[2,3,6.5]],"ltp":5.0,"tv":32.66,"id":8858707}]}]}
{"op":"mcm","clk":"11994191168","pt":1725020812288,"mc":[{"id":"1.232459454","rc":[{"batb":[[0,4.3,13.4],[1,3,6.5],[2,1.04,98]],"ltp":5.0,"tv":32.66,"id":8858707}]}]}
{"op":"mcm","clk":"11994191512","pt":1725020815551,"mc":[{"id":"1.232459454","rc":[{"batb":[[0,5,2.02],[1,4.3,13.4],[2,3,6.5]],"ltp":5.0,"tv":32.66,"id":8858707}]}]}
{"op":"mcm","clk":"11994191653","pt":1725020817052,"mc":[{"id":"1.232459454","rc":[{"batb":[[0,1.2,4.19],[1,1.18,4.19],[2,1.17,16.76]],"ltp":1.21,"tv":895.97,"id":7587363}]}]}
{"op":"mcm","clk":"11994193035","pt":1725020830160,"mc":[{"id":"1.232459454","rc":[{"batb":[[0,1.21,4.19],[1,1.2,4.19],[2,1.18,4.19]],"ltp":1.21,"tv":895.97,"id":7587363}]}]}
{"op":"mcm","clk":"11994198695","pt":1725020887957,"mc":[{"id":"1.232459454","rc":[{"batb":[[0,1.22,4.19],[1,1.21,4.19],[2,1.2,4.19]],"ltp":1.21,"tv":895.97,"id":7587363}]}]}
{"op":"mcm","clk":"11994230305","pt":1725021216690,"mc":[{"id":"1.232459454","rc":[{"batb":[[0,5.5,2.02],[1,4.4,5],[2,4.3,13.4]],"ltp":5.0,"tv":32.66,"id":8858707}]}]}
{"op":"mcm","clk":"11994230600","pt":1725021220007,"mc":[{"id":"1.232459454","rc":[{"batb":[[1,4.3,13.4],[2,3,6.5]],"ltp":5.0,"tv":32.66,"id":8858707}]}]}
{"op":"mcm","clk":"11994230791","pt":1725021222108,"mc":[{"id":"1.232459454","rc":[{"batb":[[0,5.1,2.02],[1,4.4,5],[2,4.3,13.4]],"ltp":5.0,"tv":32.66,"id":8858707}]}]}
{"op":"mcm","clk":"11994231053","pt":1725021225393,"mc":[{"id":"1.232459454","rc":[{"batb":[[1,4.3,13.4],[2,3,6.5]],"ltp":5.0,"tv":32.66,"id":8858707}]}]}
{"op":"mcm","clk":"11994231385","pt":1725021228816,"mc":[{"id":"1.232459454","rc":[{"batb":[[0,5,2.02]],"ltp":5.0,"tv":32.66,"id":8858707}]}]}
{"op":"mcm","clk":"11994231468","pt":1725021229703,"mc":[{"id":"1.232459454","rc":[{"batb":[[1,4.4,5],[2,4.3,13.4]],"ltp":5.0,"tv":32.66,"id":8858707}]}]}
{"op":"mcm","clk":"11994231782","pt":1725021233227,"mc":[{"id":"1.232459454","rc":[{"batb":[[1,4.3,13.4],[2,3,6.5]],"ltp":5.0,"tv":32.66,"id":8858707}]}]}
{"op":"mcm","clk":"11994235946","pt":1725021271673,"mc":[{"id":"1.232459454","rc":[{"trd":[[5.6,0.91],[5.8,0.87]],"batb":[[0,5.8,1.74],[1,5,2.02],[2,4.3,13.4]],"ltp":5.8,"tv":34.45,"id":8858707},{"trd":[[1.21,425.57],[1.22,4.19]],"batb":[[0,1.2,4.19],[1,1.19,4.19],[2,1.18,4.19]],"ltp":1.21,"tv":904.35,"id":7587363}],"tv":938.8}]}
{"op":"mcm","clk":"11994236393","pt":1725021275743,"mc":[{"id":"1.232459454","rc":[{"batb":[[0,5,2.02],[1,4.3,13.4],[2,3,6.5]],"ltp":5.8,"tv":34.45,"id":8858707}]}]}
{"op":"mcm","clk":"11994237597","pt":1725021289077,"mc":[{"id":"1.232459454","rc":[{"batb":[[0,5.3,5],[1,5.2,5.29],[2,5,2.02]],"ltp":5.8,"tv":34.45,"id":8858707}]}]}
{"op":"mcm","clk":"11994237911","pt":1725021292880,"mc":[{"id":"1.232459454","rc":[{"batb":[[0,5.2,5.29],[1,5,2.02],[2,4.3,13.4]],"ltp":5.8,"tv":34.45,"id":8858707}]}]}
{"op":"mcm","clk":"11994238126","pt":1725021295568,"mc":[{"id":"1.232459454","rc":[{"batb":[[0,5.3,5],[1,5.2,5.29],[2,5,2.02]],"ltp":5.8,"tv":34.45,"id":8858707}]}]}
{"op":"mcm","clk":"11994238447","pt":1725021299501,"mc":[{"id":"1.232459454","rc":[{"batb":[[0,5.2,5.29],[1,5,2.02],[2,4.3,13.4]],"ltp":5.8,"tv":34.45,"id":8858707}]}]}
{"op":"mcm","clk":"11994238983","pt":1725021304908,"mc":[{"id":"1.232459454","rc":[{"batb":[[0,5.3,5],[1,5.2,5.29],[2,5,2.02]],"ltp":5.8,"tv":34.45,"id":8858707}]}]}
{"op":"mcm","clk":"11994239293","pt":1725021308185,"mc":[{"id":"1.232459454","rc":[{"batb":[[0,5.2,5.29],[1,5,2.02],[2,4.3,13.4]],"ltp":5.8,"tv":34.45,"id":8858707}]}]}
{"op":"mcm","clk":"11994239864","pt":1725021314296,"mc":[{"id":"1.232459454","rc":[{"batb":[[0,5.3,5],[1,5.2,5.29],[2,5,2.02]],"ltp":5.8,"tv":34.45,"id":8858707}]}]}
{"op":"mcm","clk":"11994240212","pt":1725021317888,"mc":[{"id":"1.232459454","rc":[{"batb":[[0,5.2,5.29],[1,5,2.02],[2,4.3,13.4]],"ltp":5.8,"tv":34.45,"id":8858707}]}]}
{"op":"mcm","clk":"11994240712","pt":1725021323800,"mc":[{"id":"1.232459454","rc":[{"batb":[[0,5.3,5],[1,5.2,5.29],[2,5,2.02]],"ltp":5.8,"tv":34.45,"id":8858707}]}]}
{"op":"mcm","clk":"11994241009","pt":1725021327624,"mc":[{"id":"1.232459454","rc":[{"batb":[[0,5.2,5.29],[1,5,2.02],[2,4.3,13.4]],"ltp":5.8,"tv":34.45,"id":8858707}]}]}
{"op":"mcm","clk":"11994241650","pt":1725021334290,"mc":[{"id":"1.232459454","rc":[{"batb":[[0,5.3,5],[1,5.2,5.29],[2,5,2.02]],"ltp":5.8,"tv":34.45,"id":8858707}]}]}
{"op":"mcm","clk":"11994241935","pt":1725021337908,"mc":[{"id":"1.232459454","rc":[{"batb":[[0,5.2,5.29],[1,5,2.02],[2,4.3,13.4]],"ltp":5.8,"tv":34.45,"id":8858707}]}]}
{"op":"mcm","clk":"11994242858","pt":1725021349027,"mc":[{"id":"1.232459454","rc":[{"batb":[[0,5.3,5],[1,5.2,5.29],[2,5,2.02]],"ltp":5.8,"tv":34.45,"id":8858707}]}]}
{"op":"mcm","clk":"11994243221","pt":1725021352827,"mc":[{"id":"1.232459454","rc":[{"batb":[[0,5.2,5.29],[1,5,2.02],[2,4.3,13.4]],"ltp":5.8,"tv":34.45,"id":8858707}]}]}
{"op":"mcm","clk":"11994243940","pt":1725021360134,"mc":[{"id":"1.232459454","rc":[{"batb":[[0,5.3,5],[1,5.2,5.29],[2,5,2.02]],"ltp":5.8,"tv":34.45,"id":8858707}]}]}
{"op":"mcm","clk":"11994244284","pt":1725021363954,"mc":[{"id":"1.232459454","rc":[{"batb":[[0,5.2,5.29],[1,5,2.02],[2,4.3,13.4]],"ltp":5.8,"tv":34.45,"id":8858707}]}]}
{"op":"mcm","clk":"11994244797","pt":1725021369361,"mc":[{"id":"1.232459454","rc":[{"batb":[[0,5.3,5],[1,5.2,5.29],[2,5,2.02]],"ltp":5.8,"tv":34.45,"id":8858707}]}]}
{"op":"mcm","clk":"11994245203","pt":1725021373973,"mc":[{"id":"1.232459454","rc":[{"batb":[[0,5.2,5.29],[1,5,2.02],[2,4.3,13.4]],"ltp":5.8,"tv":34.45,"id":8858707}]}]}
{"op":"mcm","clk":"11994245752","pt":1725021380059,"mc":[{"id":"1.232459454","rc":[{"batb":[[0,5.3,5],[1,5.2,5.29],[2,5,2.02]],"ltp":5.8,"tv":34.45,"id":8858707}]}]}
{"op":"mcm","clk":"11994246085","pt":1725021383371,"mc":[{"id":"1.232459454","rc":[{"batb":[[0,5.2,5.29],[1,5,2.02],[2,4.3,13.4]],"ltp":5.8,"tv":34.45,"id":8858707}]}]}
{"op":"mcm","clk":"11994246451","pt":1725021386787,"mc":[{"id":"1.232459454","rc":[{"batb":[[0,5.3,5],[1,5.2,5.29],[2,5,2.02]],"ltp":5.8,"tv":34.45,"id":8858707}]}]}
{"op":"mcm","clk":"11994246810","pt":1725021390266,"mc":[{"id":"1.232459454","rc":[{"batb":[[0,5.2,5.29],[1,5,2.02],[2,4.3,13.4]],"ltp":5.8,"tv":34.45,"id":8858707}]}]}
{"op":"mcm","clk":"11994247400","pt":1725021395790,"mc":[{"id":"1.232459454","rc":[{"batb":[[0,5.3,5],[1,5.2,5.29],[2,5,2.02]],"ltp":5.8,"tv":34.45,"id":8858707}]}]}
{"op":"mcm","clk":"11994247798","pt":1725021399687,"mc":[{"id":"1.232459454","rc":[{"batb":[[0,5.2,5.29],[1,5,2.02],[2,4.3,13.4]],"ltp":5.8,"tv":34.45,"id":8858707}]}]}
{"op":"mcm","clk":"11994248210","pt":1725021403694,"mc":[{"id":"1.232459454","rc":[{"batb":[[0,5.3,5],[1,5.2,5.29],[2,5,2.02]],"ltp":5.8,"tv":34.45,"id":8858707}]}]}
{"op":"mcm","clk":"11994248581","pt":1725021407591,"mc":[{"id":"1.232459454","rc":[{"batb":[[0,5.2,5.29],[1,5,2.02],[2,4.3,13.4]],"ltp":5.8,"tv":34.45,"id":8858707}]}]}
{"op":"mcm","clk":"11994248837","pt":1725021410806,"mc":[{"id":"1.232459454","rc":[{"batb":[[0,5.3,5],[1,5.2,5.29],[2,5,2.02]],"ltp":5.8,"tv":34.45,"id":8858707}]}]}
{"op":"mcm","clk":"11994249168","pt":1725021414615,"mc":[{"id":"1.232459454","rc":[{"batb":[[0,5.2,5.29],[1,5,2.02],[2,4.3,13.4]],"ltp":5.8,"tv":34.45,"id":8858707}]}]}
{"op":"mcm","clk":"11994249401","pt":1725021416897,"mc":[{"id":"1.232459454","rc":[{"batb":[[0,5.3,5],[1,5.2,5.29],[2,5,2.02]],"ltp":5.8,"tv":34.45,"id":8858707}]}]}
{"op":"mcm","clk":"11994249778","pt":1725021420706,"mc":[{"id":"1.232459454","rc":[{"batb":[[0,5.2,5.29],[1,5,2.02],[2,4.3,13.4]],"ltp":5.8,"tv":34.45,"id":8858707}]}]}
{"op":"mcm","clk":"11994250089","pt":1725021423014,"mc":[{"id":"1.232459454","rc":[{"batb":[[0,5.3,5],[1,5.2,5.29],[2,5,2.02]],"ltp":5.8,"tv":34.45,"id":8858707}]}]}
{"op":"mcm","clk":"11994250533","pt":1725021426664,"mc":[{"id":"1.232459454","rc":[{"batb":[[0,5.2,5.29],[1,5,2.02],[2,4.3,13.4]],"ltp":5.8,"tv":34.45,"id":8858707}]}]}
{"op":"mcm","clk":"11994251242","pt":1725021432534,"mc":[{"id":"1.232459454","rc":[{"batb":[[0,5.3,5],[1,5.2,5.29],[2,5,2.02]],"ltp":5.8,"tv":34.45,"id":8858707}]}]}
{"op":"mcm","clk":"11994251614","pt":1725021436229,"mc":[{"id":"1.232459454","rc":[{"batb":[[0,5.2,5.29],[1,5,2.02],[2,4.3,13.4]],"ltp":5.8,"tv":34.45,"id":8858707}]}]}
{"op":"mcm","clk":"11994252377","pt":1725021442653,"mc":[{"id":"1.232459454","rc":[{"batb":[[0,5.3,5],[1,5.2,5.29],[2,5,2.02]],"ltp":5.8,"tv":34.45,"id":8858707}]}]}
{"op":"mcm","clk":"11994252777","pt":1725021446049,"mc":[{"id":"1.232459454","rc":[{"batb":[[0,5.2,5.29],[1,5,2.02],[2,4.3,13.4]],"ltp":5.8,"tv":34.45,"id":8858707}]}]}
{"op":"mcm","clk":"11994253047","pt":1725021448755,"mc":[{"id":"1.232459454","rc":[{"batb":[[0,5.3,5],[1,5.2,5.29],[2,5,2.02]],"ltp":5.8,"tv":34.45,"id":8858707}]}]}
{"op":"mcm","clk":"11994253404","pt":1725021452167,"mc":[{"id":"1.232459454","rc":[{"batb":[[0,5.2,5.29],[1,5,2.02],[2,4.3,13.4]],"ltp":5.8,"tv":34.45,"id":8858707}]}]}
{"op":"mcm","clk":"11994254062","pt":1725021459074,"mc":[{"id":"1.232459454","rc":[{"batb":[[0,5.3,5],[1,5.2,5.29],[2,5,2.02]],"ltp":5.8,"tv":34.45,"id":8858707}]}]}
{"op":"mcm","clk":"11994254411","pt":1725021462860,"mc":[{"id":"1.232459454","rc":[{"batb":[[0,5.2,5.29],[1,5,2.02],[2,4.3,13.4]],"ltp":5.8,"tv":34.45,"id":8858707}]}]}
{"op":"mcm","clk":"11994254881","pt":1725021468166,"mc":[{"id":"1.232459454","rc":[{"batb":[[0,5.3,5],[1,5.2,5.29],[2,5,2.02]],"ltp":5.8,"tv":34.45,"id":8858707}]}]}
{"op":"mcm","clk":"11994255202","pt":1725021471793,"mc":[{"id":"1.232459454","rc":[{"batb":[[0,5.2,5.29],[1,5,2.02],[2,4.3,13.4]],"ltp":5.8,"tv":34.45,"id":8858707}]}]}
{"op":"mcm","clk":"11994255486","pt":1725021474495,"mc":[{"id":"1.232459454","rc":[{"batb":[[0,5.3,5],[1,5.2,5.29],[2,5,2.02]],"ltp":5.8,"tv":34.45,"id":8858707}]}]}
{"op":"mcm","clk":"11994255843","pt":1725021478397,"mc":[{"id":"1.232459454","rc":[{"batb":[[0,5.2,5.29],[1,5,2.02],[2,4.3,13.4]],"ltp":5.8,"tv":34.45,"id":8858707}]}]}
{"op":"mcm","clk":"11994256200","pt":1725021482002,"mc":[{"id":"1.232459454","rc":[{"batb":[[0,5.3,5],[1,5.2,5.29],[2,5,2.02]],"ltp":5.8,"tv":34.45,"id":8858707}]}]}
{"op":"mcm","clk":"11994256557","pt":1725021485295,"mc":[{"id":"1.232459454","rc":[{"batb":[[0,5.2,5.29],[1,5,2.02],[2,4.3,13.4]],"ltp":5.8,"tv":34.45,"id":8858707}]}]}
{"op":"mcm","clk":"11994257182","pt":1725021491093,"mc":[{"id":"1.232459454","rc":[{"batb":[[0,5.3,5],[1,5.2,5.29],[2,5,2.02]],"ltp":5.8,"tv":34.45,"id":8858707}]}]}
{"op":"mcm","clk":"11994257546","pt":1725021494938,"mc":[{"id":"1.232459454","rc":[{"batb":[[0,5.2,5.29],[1,5,2.02],[2,4.3,13.4]],"ltp":5.8,"tv":34.45,"id":8858707}]}]}
{"op":"mcm","clk":"11994257902","pt":1725021498529,"mc":[{"id":"1.232459454","rc":[{"batb":[[0,5.3,5],[1,5.2,5.29],[2,5,2.02]],"ltp":5.8,"tv":34.45,"id":8858707}]}]}
{"op":"mcm","clk":"11994258208","pt":1725021501721,"mc":[{"id":"1.232459454","rc":[{"batb":[[0,5.2,5.29],[1,5,2.02],[2,4.3,13.4]],"ltp":5.8,"tv":34.45,"id":8858707}]}]}
{"op":"mcm","clk":"11994258452","pt":1725021504022,"mc":[{"id":"1.232459454","rc":[{"batb":[[0,5.3,5],[1,5.2,5.29],[2,5,2.02]],"ltp":5.8,"tv":34.45,"id":8858707}]}]}
{"op":"mcm","clk":"11994258785","pt":1725021507552,"mc":[{"id":"1.232459454","rc":[{"batb":[[0,5.2,5.29],[1,5,2.02],[2,4.3,13.4]],"ltp":5.8,"tv":34.45,"id":8858707}]}]}
{"op":"mcm","clk":"11994259070","pt":1725021510431,"mc":[{"id":"1.232459454","rc":[{"batb":[[0,5.3,5],[1,5.2,5.29],[2,5,2.02]],"ltp":5.8,"tv":34.45,"id":8858707}]}]}
{"op":"mcm","clk":"11994259409","pt":1725021513927,"mc":[{"id":"1.232459454","rc":[{"batb":[[0,5.2,5.29],[1,5,2.02],[2,4.3,13.4]],"ltp":5.8,"tv":34.45,"id":8858707}]}]}
{"op":"mcm","clk":"11994259644","pt":1725021516429,"mc":[{"id":"1.232459454","rc":[{"batb":[[0,5.3,5],[1,5.2,5.29],[2,5,2.02]],"ltp":5.8,"tv":34.45,"id":8858707}]}]}
{"op":"mcm","clk":"11994259982","pt":1725021519946,"mc":[{"id":"1.232459454","rc":[{"batb":[[0,5.2,5.29],[1,5,2.02],[2,4.3,13.4]],"ltp":5.8,"tv":34.45,"id":8858707}]}]}
{"op":"mcm","clk":"11994260341","pt":1725021523453,"mc":[{"id":"1.232459454","rc":[{"batb":[[0,5.3,5],[1,5.2,5.29],[2,5,2.02]],"ltp":5.8,"tv":34.45,"id":8858707}]}]}
{"op":"mcm","clk":"11994260737","pt":1725021527752,"mc":[{"id":"1.232459454","rc":[{"batb":[[0,5.2,5.29],[1,5,2.02],[2,4.3,13.4]],"ltp":5.8,"tv":34.45,"id":8858707}]}]}
{"op":"mcm","clk":"11994261669","pt":1725021536670,"mc":[{"id":"1.232459454","rc":[{"batb":[[0,5.3,5],[1,5.2,5.29],[2,5,2.02]],"ltp":5.8,"tv":34.45,"id":8858707}]}]}
{"op":"mcm","clk":"11994262015","pt":1725021540356,"mc":[{"id":"1.232459454","rc":[{"batb":[[0,5.2,5.29],[1,5,2.02],[2,4.3,13.4]],"ltp":5.8,"tv":34.45,"id":8858707}]}]}
{"op":"mcm","clk":"11994262310","pt":1725021543257,"mc":[{"id":"1.232459454","rc":[{"batb":[[0,5.3,5],[1,5.2,5.29],[2,5,2.02]],"ltp":5.8,"tv":34.45,"id":8858707}]}]}
{"op":"mcm","clk":"11994262609","pt":1725021546591,"mc":[{"id":"1.232459454","rc":[{"batb":[[0,5.2,5.29],[1,5,2.02],[2,4.3,13.4]],"ltp":5.8,"tv":34.45,"id":8858707}]}]}
{"op":"mcm","clk":"11994263010","pt":1725021550079,"mc":[{"id":"1.232459454","rc":[{"batb":[[0,5.3,5],[1,5.2,5.29],[2,5,2.02]],"ltp":5.8,"tv":34.45,"id":8858707}]}]}
{"op":"mcm","clk":"11994263364","pt":1725021553603,"mc":[{"id":"1.232459454","rc":[{"batb":[[0,5.2,5.29],[1,5,2.02],[2,4.3,13.4]],"ltp":5.8,"tv":34.45,"id":8858707}]}]}
{"op":"mcm","clk":"11994263741","pt":1725021557289,"mc":[{"id":"1.232459454","rc":[{"batb":[[0,5.3,5],[1,5.2,5.29],[2,5,2.02]],"ltp":5.8,"tv":34.45,"id":8858707}]}]}
{"op":"mcm","clk":"11994264099","pt":1725021560888,"mc":[{"id":"1.232459454","rc":[{"batb":[[0,5.2,5.29],[1,5,2.02],[2,4.3,13.4]],"ltp":5.8,"tv":34.45,"id":8858707}]}]}
{"op":"mcm","clk":"11994264392","pt":1725021563787,"mc":[{"id":"1.232459454","rc":[{"batb":[[0,5.3,5],[1,5.2,5.29],[2,5,2.02]],"ltp":5.8,"tv":34.45,"id":8858707}]}]}
{"op":"mcm","clk":"11994264756","pt":1725021567500,"mc":[{"id":"1.232459454","rc":[{"batb":[[0,5.2,5.29],[1,5,2.02],[2,4.3,13.4]],"ltp":5.8,"tv":34.45,"id":8858707}]}]}
{"op":"mcm","clk":"11994264970","pt":1725021569701,"mc":[{"id":"1.232459454","rc":[{"batb":[[0,5.3,5],[1,5.2,5.29],[2,5,2.02]],"ltp":5.8,"tv":34.45,"id":8858707}]}]}
{"op":"mcm","clk":"11994265340","pt":1725021573495,"mc":[{"id":"1.232459454","rc":[{"batb":[[0,5.2,5.29],[1,5,2.02],[2,4.3,13.4]],"ltp":5.8,"tv":34.45,"id":8858707}]}]}
{"op":"mcm","clk":"11994265572","pt":1725021575992,"mc":[{"id":"1.232459454","rc":[{"batb":[[0,5.3,5],[1,5.2,5.29],[2,5,2.02]],"ltp":5.8,"tv":34.45,"id":8858707}]}]}
{"op":"mcm","clk":"11994265973","pt":1725021579741,"mc":[{"id":"1.232459454","rc":[{"batb":[[0,5.2,5.29],[1,5,2.02],[2,4.3,13.4]],"ltp":5.8,"tv":34.45,"id":8858707}]}]}
{"op":"mcm","clk":"11994266206","pt":1725021581933,"mc":[{"id":"1.232459454","rc":[{"batb":[[0,5.3,5],[1,5.2,5.29],[2,5,2.02]],"ltp":5.8,"tv":34.45,"id":8858707}]}]}
{"op":"mcm","clk":"11994266638","pt":1725021585527,"mc":[{"id":"1.232459454","rc":[{"batb":[[0,5.2,5.29],[1,5,2.02],[2,4.3,13.4]],"ltp":5.8,"tv":34.45,"id":8858707}]}]}
{"op":"mcm","clk":"11994266971","pt":1725021589045,"mc":[{"id":"1.232459454","rc":[{"batb":[[0,5.3,5],[1,5.2,5.29],[2,5,2.02]],"ltp":5.8,"tv":34.45,"id":8858707}]}]}
{"op":"mcm","clk":"11994267368","pt":1725021593015,"mc":[{"id":"1.232459454","rc":[{"batb":[[0,5.2,5.29],[1,5,2.02],[2,4.3,13.4]],"ltp":5.8,"tv":34.45,"id":8858707}]}]}
{"op":"mcm","clk":"11994267747","pt":1725021596430,"mc":[{"id":"1.232459454","rc":[{"batb":[[0,5.3,5],[1,5.2,5.29],[2,5,2.02]],"ltp":5.8,"tv":34.45,"id":8858707}]}]}
{"op":"mcm","clk":"11994268159","pt":1725021600225,"mc":[{"id":"1.232459454","rc":[{"batb":[[0,5.2,5.29],[1,5,2.02],[2,4.3,13.4]],"ltp":5.8,"tv":34.45,"id":8858707}]}]}
{"op":"mcm","clk":"11994268843","pt":1725021606762,"mc":[{"id":"1.232459454","rc":[{"batb":[[0,5.3,5],[1,5.2,5.29],[2,5,2.02]],"ltp":5.8,"tv":34.45,"id":8858707}]}]}
{"op":"mcm","clk":"11994269251","pt":1725021610653,"mc":[{"id":"1.232459454","rc":[{"batb":[[0,5.2,5.29],[1,5,2.02],[2,4.3,13.4]],"ltp":5.8,"tv":34.45,"id":8858707}]}]}
{"op":"mcm","clk":"11994269588","pt":1725021613342,"mc":[{"id":"1.232459454","rc":[{"batb":[[0,5.3,5],[1,5.2,5.29],[2,5,2.02]],"ltp":5.8,"tv":34.45,"id":8858707}]}]}
{"op":"mcm","clk":"11994269979","pt":1725021617063,"mc":[{"id":"1.232459454","rc":[{"batb":[[0,5.2,5.29],[1,5,2.02],[2,4.3,13.4]],"ltp":5.8,"tv":34.45,"id":8858707}]}]}
{"op":"mcm","clk":"11994271054","pt":1725021629779,"mc":[{"id":"1.232459454","rc":[{"batb":[[0,5.3,5],[1,5.2,5.29],[2,5,2.02]],"ltp":5.8,"tv":34.45,"id":8858707}]}]}
{"op":"mcm","clk":"11994271399","pt":1725021633587,"mc":[{"id":"1.232459454","rc":[{"batb":[[0,5.2,5.29],[1,5,2.02],[2,4.3,13.4]],"ltp":5.8,"tv":34.45,"id":8858707}]}]}
{"op":"mcm","clk":"11994272019","pt":1725021640194,"mc":[{"id":"1.232459454","rc":[{"batb":[[0,5.3,5],[1,5.2,5.29],[2,5,2.02]],"ltp":5.8,"tv":34.45,"id":8858707}]}]}
{"op":"mcm","clk":"11994272352","pt":1725021643872,"mc":[{"id":"1.232459454","rc":[{"batb":[[0,5.2,5.29],[1,5,2.02],[2,4.3,13.4]],"ltp":5.8,"tv":34.45,"id":8858707}]}]}
{"op":"mcm","clk":"11994273267","pt":1725021654228,"mc":[{"id":"1.232459454","rc":[{"batb":[[0,5.3,5],[1,5.2,5.29],[2,5,2.02]],"ltp":5.8,"tv":34.45,"id":8858707}]}]}
{"op":"mcm","clk":"11994273574","pt":1725021658010,"mc":[{"id":"1.232459454","rc":[{"batb":[[0,5.2,5.29],[1,5,2.02],[2,4.3,13.4]],"ltp":5.8,"tv":34.45,"id":8858707}]}]}
{"op":"mcm","clk":"11994273831","pt":1725021660712,"mc":[{"id":"1.232459454","rc":[{"batb":[[0,5.3,5],[1,5.2,5.29],[2,5,2.02]],"ltp":5.8,"tv":34.45,"id":8858707}]}]}
{"op":"mcm","clk":"11994274205","pt":1725021664415,"mc":[{"id":"1.232459454","rc":[{"batb":[[0,5.2,5.29],[1,5,2.02],[2,4.3,13.4]],"ltp":5.8,"tv":34.45,"id":8858707}]}]}
{"op":"mcm","clk":"11994274560","pt":1725021667715,"mc":[{"id":"1.232459454","rc":[{"batb":[[0,5.3,5],[1,5.2,5.29],[2,5,2.02]],"ltp":5.8,"tv":34.45,"id":8858707}]}]}
{"op":"mcm","clk":"11994274874","pt":1725021671032,"mc":[{"id":"1.232459454","rc":[{"batb":[[0,5.2,5.29],[1,5,2.02],[2,4.3,13.4]],"ltp":5.8,"tv":34.45,"id":8858707}]}]}
{"op":"mcm","clk":"11994276256","pt":1725021686344,"mc":[{"id":"1.232459454","rc":[{"batb":[[0,5.3,5],[1,5.2,5.29],[2,5,2.02]],"ltp":5.8,"tv":34.45,"id":8858707}]}]}
{"op":"mcm","clk":"11994276628","pt":1725021690564,"mc":[{"id":"1.232459454","rc":[{"batb":[[0,5.2,5.29],[1,5,2.02],[2,4.3,13.4]],"ltp":5.8,"tv":34.45,"id":8858707}]}]}
{"op":"mcm","clk":"11994277016","pt":1725021694949,"mc":[{"id":"1.232459454","rc":[{"batb":[[0,5.3,5],[1,5.2,5.29],[2,5,2.02]],"ltp":5.8,"tv":34.45,"id":8858707}]}]}
{"op":"mcm","clk":"11994277380","pt":1725021698650,"mc":[{"id":"1.232459454","rc":[{"batb":[[0,5.2,5.29],[1,5,2.02],[2,4.3,13.4]],"ltp":5.8,"tv":34.45,"id":8858707}]}]}
{"op":"mcm","clk":"11994278530","pt":1725021711296,"mc":[{"id":"1.232459454","rc":[{"batb":[[0,5.3,5],[1,5.2,5.29],[2,5,2.02]],"ltp":5.8,"tv":34.45,"id":8858707}]}]}
{"op":"mcm","clk":"11994278880","pt":1725021715075,"mc":[{"id":"1.232459454","rc":[{"batb":[[0,5.2,5.29],[1,5,2.02],[2,4.3,13.4]],"ltp":5.8,"tv":34.45,"id":8858707}]}]}
{"op":"mcm","clk":"11994279961","pt":1725021726903,"mc":[{"id":"1.232459454","rc":[{"batb":[[0,5.3,5],[1,5.2,5.29],[2,5,2.02]],"ltp":5.8,"tv":34.45,"id":8858707}]}]}
{"op":"mcm","clk":"11994280316","pt":1725021730877,"mc":[{"id":"1.232459454","rc":[{"batb":[[0,5.2,5.29],[1,5,2.02],[2,4.3,13.4]],"ltp":5.8,"tv":34.45,"id":8858707}]}]}
{"op":"mcm","clk":"11994280880","pt":1725021737790,"mc":[{"id":"1.232459454","rc":[{"batb":[[0,5.3,5],[1,5.2,5.29],[2,5,2.02]],"ltp":5.8,"tv":34.45,"id":8858707}]}]}
{"op":"mcm","clk":"11994281229","pt":1725021742227,"mc":[{"id":"1.232459454","rc":[{"batb":[[0,5.2,5.29],[1,5,2.02],[2,4.3,13.4]],"ltp":5.8,"tv":34.45,"id":8858707}]}]}
{"op":"mcm","clk":"11994304093","pt":1725021811089,"mc":[{"id":"1.232459454","rc":[{"batl":[[0,6.6,72.14]],"ltp":5.8,"tv":34.45,"id":8858707}]}]}
{"op":"mcm","clk":"11994304187","pt":1725021811920,"mc":[{"id":"1.232459454","rc":[{"batb":[[0,5.3,5],[1,5.2,5.29],[2,5,2.02]],"ltp":5.8,"tv":34.45,"id":8858707}]}]}
{"op":"mcm","clk":"11994304524","pt":1725021815400,"mc":[{"id":"1.232459454","rc":[{"batb":[[0,5.2,5.29],[1,5,2.02],[2,4.3,13.4]],"ltp":5.8,"tv":34.45,"id":8858707}]}]}
{"op":"mcm","clk":"11994306535","pt":1725021837019,"mc":[{"id":"1.232459454","rc":[{"batb":[[0,5.3,5],[1,5.2,5.29],[2,5,2.02]],"ltp":5.8,"tv":34.45,"id":8858707}]}]}
{"op":"mcm","clk":"11994306885","pt":1725021840818,"mc":[{"id":"1.232459454","rc":[{"batb":[[0,5.2,5.29],[1,5,2.02],[2,4.3,13.4]],"ltp":5.8,"tv":34.45,"id":8858707}]}]}
{"op":"mcm","clk":"11994307420","pt":1725021846025,"mc":[{"id":"1.232459454","rc":[{"batb":[[0,5.3,5],[1,5.2,5.29],[2,5,2.02]],"ltp":5.8,"tv":34.45,"id":8858707}]}]}
{"op":"mcm","clk":"11994307835","pt":1725021850031,"mc":[{"id":"1.232459454","rc":[{"batb":[[0,5.2,5.29],[1,5,2.02],[2,4.3,13.4]],"ltp":5.8,"tv":34.45,"id":8858707}]}]}
{"op":"mcm","clk":"11994307949","pt":1725021851378,"mc":[{"id":"1.232459454","rc":[{"trd":[[6,0.84]],"ltp":6.0,"tv":35.29,"id":8858707},{"trd":[[1.2,4.19]],"batb":[[0,1.19,4.19],[1,1.18,4.19],[2,1.17,16.76]],"ltp":1.2,"tv":908.54,"id":7587363}],"tv":943.83}]}
{"op":"mcm","clk":"11994308847","pt":1725021859676,"mc":[{"id":"1.232459454","rc":[{"batb":[[0,5.3,5],[1,5.2,5.29],[2,5,2.02]],"ltp":6.0,"tv":35.29,"id":8858707}]}]}
{"op":"mcm","clk":"11994309203","pt":1725021863577,"mc":[{"id":"1.232459454","rc":[{"batb":[[0,5.2,5.29],[1,5,2.02],[2,4.3,13.4]],"ltp":6.0,"tv":35.29,"id":8858707}]}]}
{"op":"mcm","clk":"11994309481","pt":1725021866883,"mc":[{"id":"1.232459454","rc":[{"batb":[[0,5.3,5],[1,5.2,5.29],[2,5,2.02]],"ltp":6.0,"tv":35.29,"id":8858707}]}]}
{"op":"mcm","clk":"11994309796","pt":1725021870580,"mc":[{"id":"1.232459454","rc":[{"batb":[[0,5.2,5.29],[1,5,2.02],[2,4.3,13.4]],"ltp":6.0,"tv":35.29,"id":8858707}]}]}
{"op":"mcm","clk":"11994311552","pt":1725021889300,"mc":[{"id":"1.232459454","rc":[{"batb":[[0,5.3,5],[1,5.2,5.29],[2,5,2.02]],"ltp":6.0,"tv":35.29,"id":8858707}]}]}
{"op":"mcm","clk":"11994311907","pt":1725021892928,"mc":[{"id":"1.232459454","rc":[{"batb":[[0,5.2,5.29],[1,5,2.02],[2,4.3,13.4]],"ltp":6.0,"tv":35.29,"id":8858707}]}]}
{"op":"mcm","clk":"11994312246","pt":1725021896229,"mc":[{"id":"1.232459454","rc":[{"batb":[[0,5.3,5],[1,5.2,5.29],[2,5,2.02]],"ltp":6.0,"tv":35.29,"id":8858707}]}]}
{"op":"mcm","clk":"11994312594","pt":1725021900125,"mc":[{"id":"1.232459454","rc":[{"batb":[[0,5.2,5.29],[1,5,2.02],[2,4.3,13.4]],"ltp":6.0,"tv":35.29,"id":8858707}]}]}
{"op":"mcm","clk":"11994316005","pt":1725021931356,"mc":[{"id":"1.232459454","rc":[{"batb":[[0,5.3,5],[1,5.2,5.29],[2,5,2.02]],"ltp":6.0,"tv":35.29,"id":8858707}]}]}
{"op":"mcm","clk":"11994316436","pt":1725021935444,"mc":[{"id":"1.232459454","rc":[{"batb":[[0,5.2,5.29],[1,5,2.02],[2,4.3,13.4]],"ltp":6.0,"tv":35.29,"id":8858707}]}]}
{"op":"mcm","clk":"11994317191","pt":1725021942977,"mc":[{"id":"1.232459454","rc":[{"batb":[[0,5.3,5],[1,5.2,5.29],[2,5,2.02]],"ltp":6.0,"tv":35.29,"id":8858707}]}]}
{"op":"mcm","clk":"11994317633","pt":1725021946871,"mc":[{"id":"1.232459454","rc":[{"batb":[[0,5.2,5.29],[1,5,2.02],[2,4.3,13.4]],"ltp":6.0,"tv":35.29,"id":8858707}]}]}
{"op":"mcm","clk":"11994319558","pt":1725021965102,"mc":[{"id":"1.232459454","rc":[{"batb":[[0,5.3,5],[1,5.2,5.29],[2,5,2.02]],"ltp":6.0,"tv":35.29,"id":8858707}]}]}
{"op":"mcm","clk":"11994320022","pt":1725021968998,"mc":[{"id":"1.232459454","rc":[{"batb":[[0,5.2,5.29],[1,5,2.02],[2,4.3,13.4]],"ltp":6.0,"tv":35.29,"id":8858707}]}]}
{"op":"mcm","clk":"11994320831","pt":1725021977024,"mc":[{"id":"1.232459454","rc":[{"batb":[[0,5.3,5],[1,5.2,5.29],[2,5,2.02]],"ltp":6.0,"tv":35.29,"id":8858707}]}]}
{"op":"mcm","clk":"11994321172","pt":1725021980711,"mc":[{"id":"1.232459454","rc":[{"batb":[[0,5.2,5.29],[1,5,2.02],[2,4.3,13.4]],"ltp":6.0,"tv":35.29,"id":8858707}]}]}
{"op":"mcm","clk":"11994321452","pt":1725021983410,"mc":[{"id":"1.232459454","rc":[{"batb":[[0,5.3,5],[1,5.2,5.29],[2,5,2.02]],"ltp":6.0,"tv":35.29,"id":8858707}]}]}
{"op":"mcm","clk":"11994321854","pt":1725021987147,"mc":[{"id":"1.232459454","rc":[{"batb":[[0,5.2,5.29],[1,5,2.02],[2,4.3,13.4]],"ltp":6.0,"tv":35.29,"id":8858707}]}]}
{"op":"mcm","clk":"11994323781","pt":1725022005449,"mc":[{"id":"1.232459454","rc":[{"batb":[[0,5.3,5],[1,5.2,5.29],[2,5,2.02]],"ltp":6.0,"tv":35.29,"id":8858707}]}]}
{"op":"mcm","clk":"11994324170","pt":1725022009335,"mc":[{"id":"1.232459454","rc":[{"batb":[[0,5.2,5.29],[1,5,2.02],[2,4.3,13.4]],"ltp":6.0,"tv":35.29,"id":8858707}]}]}
{"op":"mcm","clk":"11994325079","pt":1725022018455,"mc":[{"id":"1.232459454","rc":[{"batb":[[0,5.3,5],[1,5.2,5.29],[2,5,2.02]],"ltp":6.0,"tv":35.29,"id":8858707}]}]}
{"op":"mcm","clk":"11994325444","pt":1725022022296,"mc":[{"id":"1.232459454","rc":[{"batb":[[0,5.2,5.29],[1,5,2.02],[2,4.3,13.4]],"ltp":6.0,"tv":35.29,"id":8858707}]}]}
{"op":"mcm","clk":"11994326265","pt":1725022030209,"mc":[{"id":"1.232459454","rc":[{"batb":[[0,5.3,5],[1,5.2,5.29],[2,5,2.02]],"ltp":6.0,"tv":35.29,"id":8858707}]}]}
{"op":"mcm","clk":"11994326648","pt":1725022034117,"mc":[{"id":"1.232459454","rc":[{"batb":[[0,5.2,5.29],[1,5,2.02],[2,4.3,13.4]],"ltp":6.0,"tv":35.29,"id":8858707}]}]}
{"op":"mcm","clk":"11994327293","pt":1725022040415,"mc":[{"id":"1.232459454","rc":[{"batb":[[0,5.3,5],[1,5.2,5.29],[2,5,2.02]],"ltp":6.0,"tv":35.29,"id":8858707}]}]}
{"op":"mcm","clk":"11994327687","pt":1725022044224,"mc":[{"id":"1.232459454","rc":[{"batb":[[0,5.2,5.29],[1,5,2.02],[2,4.3,13.4]],"ltp":6.0,"tv":35.29,"id":8858707}]}]}
{"op":"mcm","clk":"11994328145","pt":1725022048900,"mc":[{"id":"1.232459454","rc":[{"batb":[[0,5.3,5],[1,5.2,5.29],[2,5,2.02]],"ltp":6.0,"tv":35.29,"id":8858707},{"batl":[[0,1.22,103.16]],"ltp":1.2,"tv":908.54,"id":7587363}]}]}
{"op":"mcm","clk":"11994328479","pt":1725022052218,"mc":[{"id":"1.232459454","rc":[{"batb":[[0,5.2,5.29],[1,5,2.02],[2,4.3,13.4]],"ltp":6.0,"tv":35.29,"id":8858707}]}]}
{"op":"mcm","clk":"11994329957","pt":1725022066813,"mc":[{"id":"1.232459454","rc":[{"batb":[[0,5.3,5],[1,5.2,5.29],[2,5,2.02]],"ltp":6.0,"tv":35.29,"id":8858707}]}]}
{"op":"mcm","clk":"11994330368","pt":1725022070954,"mc":[{"id":"1.232459454","rc":[{"batb":[[0,5.2,5.29],[1,5,2.02],[2,4.3,13.4]],"ltp":6.0,"tv":35.29,"id":8858707}]}]}
{"op":"mcm","clk":"11994330757","pt":1725022075335,"mc":[{"id":"1.232459454","rc":[{"batb":[[0,5.3,5],[1,5.2,5.29],[2,5,2.02]],"ltp":6.0,"tv":35.29,"id":8858707}]}]}
{"op":"mcm","clk":"11994331183","pt":1725022079247,"mc":[{"id":"1.232459454","rc":[{"batb":[[0,5.2,5.29],[1,5,2.02],[2,4.3,13.4]],"ltp":6.0,"tv":35.29,"id":8858707}]}]}
{"op":"mcm","clk":"11994331813","pt":1725022085244,"mc":[{"id":"1.232459454","rc":[{"batb":[[0,5.3,5],[1,5.2,5.29],[2,5,2.02]],"ltp":6.0,"tv":35.29,"id":8858707}]}]}
{"op":"mcm","clk":"11994332222","pt":1725022089263,"mc":[{"id":"1.232459454","rc":[{"batb":[[0,5.2,5.29],[1,5,2.02],[2,4.3,13.4]],"ltp":6.0,"tv":35.29,"id":8858707}]}]}
{"op":"mcm","clk":"11994333335","pt":1725022099779,"mc":[{"id":"1.232459454","rc":[{"batb":[[0,5.3,5],[1,5.2,5.29],[2,5,2.02]],"ltp":6.0,"tv":35.29,"id":8858707}]}]}
{"op":"mcm","clk":"11994333733","pt":1725022103563,"mc":[{"id":"1.232459454","rc":[{"batb":[[0,5.2,5.29],[1,5,2.02],[2,4.3,13.4]],"ltp":6.0,"tv":35.29,"id":8858707}]}]}
{"op":"mcm","clk":"11994334392","pt":1725022109693,"mc":[{"id":"1.232459454","rc":[{"batb":[[0,5,2.02],[1,4.3,13.4],[2,3,6.5]],"ltp":6.0,"tv":35.29,"id":8858707}]}]}
{"op":"mcm","clk":"11994421620","pt":1725023054126,"mc":[{"id":"1.232459454","rc":[{"trd":[[5,28.68],[5.6,0.91],[5.8,0.88],[6,0.84]],"batb":[[0,5,2.02]],"ltp":6.0,"tv":35.31,"id":8858707},{"trd":[[1.21,425.67],[1.25,468.69]],"ltp":1.2,"tv":908.73,"id":7587363}],"tv":944.05}]}
{"op":"mcm","clk":"11994423322","pt":1725023072877,"mc":[{"id":"1.232459454","rc":[{"batl":[[0,6,79.27]],"ltp":6.0,"tv":35.31,"id":8858707}]}]}
{"op":"mcm","clk":"11994435445","pt":1725023194432,"mc":[{"id":"1.232459454","rc":[{"batl":[[0,6,58.88]],"ltp":6.0,"tv":35.31,"id":8858707}]}]}
{"op":"mcm","clk":"11994436844","pt":1725023207663,"mc":[{"id":"1.232459454","rc":[{"batl":[[1,6.4,16.82]],"ltp":6.0,"tv":35.31,"id":8858707}]}]}
{"op":"mcm","clk":"11994450401","pt":1725023329096,"mc":[{"id":"1.232459454","rc":[{"batl":[[0,5.8,16.82],[1,6,58.88]],"ltp":6.0,"tv":35.31,"id":8858707}]}]}
{"op":"mcm","clk":"11994451312","pt":1725023337096,"mc":[{"id":"1.232459454","rc":[{"batl":[[0,6,75.71],[1,6,0]],"ltp":6.0,"tv":35.31,"id":8858707}]}]}
{"op":"mcm","clk":"11994465958","pt":1725023464856,"mc":[{"id":"1.232459454","rc":[{"batl":[[0,5.9,5.69],[1,6,75.71]],"ltp":6.0,"tv":35.31,"id":8858707}]}]}
{"op":"mcm","clk":"11994626783","pt":1725024756086,"mc":[{"id":"1.232459454","rc":[{"batb":[[0,5.3,1.01],[1,5,2.02],[2,4.3,13.4]],"ltp":6.0,"tv":35.31,"id":8858707}]}]}
{"op":"mcm","clk":"11994628599","pt":1725024774894,"mc":[{"id":"1.232459454","rc":[{"trd":[[5.9,0.34]],"batl":[[0,5.9,5.52]],"ltp":5.9,"tv":35.65,"id":8858707}],"tv":944.39}]}
{"op":"mcm","clk":"11994632515","pt":1725024809321,"mc":[{"id":"1.232459454","rc":[{"trd":[[5.9,3.68]],"batl":[[0,5.9,3.84]],"ltp":5.9,"tv":38.99,"id":8858707}],"tv":947.73}]}
{"op":"mcm","clk":"11994643876","pt":1725024913676,"mc":[{"id":"1.232459454","rc":[{"batb":[[2,4.3,13.16]],"ltp":5.9,"tv":38.99,"id":8858707}]}]}
{"op":"mcm","clk":"11994645863","pt":1725024931371,"mc":[{"id":"1.232459454","rc":[{"batl":[[1,6,0]],"ltp":5.9,"tv":38.99,"id":8858707}]}]}
{"op":"mcm","clk":"11994647837","pt":1725024948997,"mc":[{"id":"1.232459454","rc":[{"batl":[[0,5.7,83.49]],"ltp":5.9,"tv":38.99,"id":8858707}]}]}
{"op":"mcm","clk":"11994682542","pt":1725025270125,"mc":[{"id":"1.232459454","rc":[{"batb":[[2,4.9,11.13]],"ltp":5.9,"tv":38.99,"id":8858707},{"batb":[[0,1.21,206.8],[1,1.19,4.19],[2,1.18,4.19]],"ltp":1.2,"tv":908.73,"id":7587363}]}]}
{"op":"mcm","clk":"11994683233","pt":1725025276615,"mc":[{"id":"1.232459454","rc":[{"batl":[[0,1.23,16.76]],"ltp":1.2,"tv":908.73,"id":7587363}]}]}
{"op":"mcm","clk":"11994683471","pt":1725025278826,"mc":[{"id":"1.232459454","rc":[{"batb":[[1,5,4.19]],"ltp":5.9,"tv":38.99,"id":8858707}]}]}
{"op":"mcm","clk":"11994709131","pt":1725025466097,"mc":[{"id":"1.232459454","rc":[{"trd":[[1.21,489.85]],"batb":[[0,1.21,174.71]],"ltp":1.21,"tv":972.91,"id":7587363}],"tv":1011.91}]}
{"op":"mcm","clk":"11994709690","pt":1725025471176,"mc":[{"id":"1.232459454","rc":[{"batb":[[0,1.21,196.5]],"ltp":1.21,"tv":972.91,"id":7587363}]}]}
{"op":"mcm","clk":"11994750181","pt":1725025763650,"mc":[{"id":"1.232459454","rc":[{"trd":[[1.23,8]],"batl":[[0,1.23,12.76]],"ltp":1.23,"tv":980.91,"id":7587363}],"tv":1019.91}]}
{"op":"mcm","clk":"11994751246","pt":1725025773812,"mc":[{"id":"1.232459454","rc":[{"trd":[[1.23,18]],"batl":[[0,1.23,7.76]],"ltp":1.23,"tv":990.91,"id":7587363}],"tv":1029.91}]}
{"op":"mcm","clk":"11994752492","pt":1725025786127,"mc":[{"id":"1.232459454","rc":[{"trd":[[1.23,26]],"batl":[[0,1.23,3.76]],"ltp":1.23,"tv":998.91,"id":7587363}],"tv":1037.91}]}
{"op":"mcm","clk":"11994753091","pt":1725025792149,"mc":[{"id":"1.232459454","rc":[{"trd":[[1.23,33.52]],"batb":[[0,1.21,196.74]],"ltp":1.23,"tv":1006.43,"id":7587363}],"tv":1045.43}]}
{"op":"mcm","clk":"11994753189","pt":1725025793032,"mc":[{"id":"1.232459454","rc":[{"batb":[[1,5,2.02]],"ltp":5.9,"tv":38.99,"id":8858707}]}]}
{"op":"mcm","clk":"11994770734","pt":1725025965485,"mc":[{"id":"1.232459454","rc":[{"batb":[[0,1.21,196.5]],"ltp":1.23,"tv":1006.43,"id":7587363}]}]}
{"op":"mcm","clk":"11994858187","pt":1725026749685,"mc":[{"id":"1.232459454","rc":[{"trd":[[5,28.69],[5.9,3.68]],"batb":[[1,5,2.02]],"ltp":5.9,"tv":39.0,"id":8858707},{"trd":[[1.21,490.17],[1.25,468.96]],"ltp":1.23,"tv":1007.02,"id":7587363}],"tv":1046.03}]}
{"op":"mcm","clk":"11994859962","pt":1725026764744,"mc":[{"id":"1.232459454","rc":[{"trd":[[5.3,1.06]],"batb":[[0,5,2.5],[1,4.9,11.13],[2,3,6.5]],"ltp":5.3,"tv":40.06,"id":8858707}],"tv":1047.09}]}
{"op":"mcm","clk":"11994865625","pt":1725026814812,"mc":[{"id":"1.232459454","rc":[{"batl":[[0,5.5,86.67]],"ltp":5.3,"tv":40.06,"id":8858707}]}]}
{"op":"mcm","clk":"11994886718","pt":1725027030680,"mc":[{"id":"1.232459454","rc":[{"trd":[[5.3,1.54]],"batb":[[0,5,2.02]],"ltp":5.3,"tv":40.54,"id":8858707},{"trd":[[1.24,2.06]],"batb":[[0,1.24,26.23],[1,1.21,196.5],[2,1.19,4.19]],"ltp":1.24,"tv":1009.08,"id":7587363}],"tv":1049.62}]}
{"op":"mcm","clk":"11994888725","pt":1725027051693,"mc":[{"id":"1.232459454","rc":[{"batb":[[0,1.21,196.5],[1,1.19,4.19],[2,1.18,4.19]],"ltp":1.24,"tv":1009.08,"id":7587363}]}]}
{"op":"mcm","clk":"11994888810","pt":1725027052673,"mc":[{"id":"1.232459454","rc":[{"batb":[[0,5.2,3.54],[1,5,2.02],[2,4.9,11.13]],"ltp":5.3,"tv":40.54,"id":8858707}]}]}
{"op":"mcm","clk":"11994889290","pt":1725027057700,"mc":[{"id":"1.232459454","rc":[{"batb":[[0,5,2.02],[1,4.9,11.13],[2,3,6.5]],"ltp":5.3,"tv":40.54,"id":8858707}]}]}
{"op":"mcm","clk":"11994925901","pt":1725027247705,"mc":[{"id":"1.232459454","rc":[{"batb":[[0,1.23,28.28],[1,1.21,196.5],[2,1.19,4.19]],"ltp":1.24,"tv":1009.08,"id":7587363}]}]}
{"op":"mcm","clk":"11994933361","pt":1725027318722,"mc":[{"id":"1.232459454","rc":[{"batb":[[0,1.21,196.5],[1,1.19,4.19],[2,1.18,4.19]],"ltp":1.24,"tv":1009.08,"id":7587363}]}]}
{"op":"mcm","clk":"11994935610","pt":1725027339632,"mc":[{"id":"1.232459454","rc":[{"batl":[[0,5.5,86.69]],"ltp":5.3,"tv":40.54,"id":8858707}]}]}
{"op":"mcm","clk":"11995006105","pt":1725027968025,"mc":[{"id":"1.232459454","rc":[{"batl":[[0,5.4,4.25],[1,5.5,86.69]],"ltp":5.3,"tv":40.54,"id":8858707}]}]}
{"op":"mcm","clk":"11995056493","pt":1725028401223,"mc":[{"id":"1.232459454","rc":[{"batb":[[1,1.2,4.19],[2,1.19,4.19]],"ltp":1.24,"tv":1009.08,"id":7587363}]}]}
{"op":"mcm","clk":"11995270831","pt":1725030183347,"mc":[{"id":"1.232459454","rc":[{"trd":[[5,28.69]],"batl":[[0,5.4,4.25],[1,5.5,86.67]],"ltp":5.3,"tv":40.54,"id":8858707},{"trd":[[1.21,490.12],[1.25,468.91]],"ltp":1.24,"tv":1008.98,"id":7587363}],"tv":1049.53}]}
{"op":"mcm","clk":"11995275440","pt":1725030218886,"mc":[{"id":"1.232459454","rc":[{"batb":[[0,5,2.87]],"ltp":5.3,"tv":40.54,"id":8858707}]}]}
{"op":"mcm","clk":"11995303331","pt":1725030438127,"mc":[{"id":"1.232459454","rc":[{"batb":[[0,5.1,1.85],[1,5,2.02],[2,4.9,11.13]],"ltp":5.3,"tv":40.54,"id":8858707}]}]}
{"op":"mcm","clk":"11995358464","pt":1725030801462,"mc":[{"id":"1.232459454","rc":[{"trd":[[5.4,8]],"batl":[[0,5.5,86.92],[1,5.5,0]],"ltp":5.4,"tv":48.54,"id":8858707}],"tv":1057.53}]}
{"op":"mcm","clk":"11995358827","pt":1725030803762,"mc":[{"id":"1.232459454","rc":[{"batl":[[0,5.5,86.67]],"ltp":5.4,"tv":48.54,"id":8858707}]}]}
{"op":"mcm","clk":"11995363134","pt":1725030831303,"mc":[{"id":"1.232459454","rc":[{"trd":[[5.1,1.47]],"batb":[[0,5,2.41],[1,4.9,11.13],[2,3,6.5]],"ltp":5.1,"tv":50.01,"id":8858707},{"trd":[[1.25,474.91]],"ltp":1.25,"tv":1014.98,"id":7587363}],"tv":1065.0}]}
{"op":"mcm","clk":"11995365138","pt":1725030844401,"mc":[{"id":"1.232459454","rc":[{"trd":[[4.9,5.2],[5,32.73],[5.1,2.23]],"batb":[[0,4.9,8.53],[1,3,6.5],[2,2.02,10.7]],"ltp":4.9,"tv":60.02,"id":8858707}],"tv":1075.01}]}
{"op":"mcm","clk":"11995365560","pt":1725030847116,"mc":[{"id":"1.232459454","rc":[{"batb":[[0,4.9,11.13]],"ltp":4.9,"tv":60.02,"id":8858707},{"batb":[[0,1.21,206.8]],"ltp":1.25,"tv":1014.98,"id":7587363}]}]}
{"op":"mcm","clk":"11995386101","pt":1725030982803,"mc":[{"id":"1.232459454","rc":[{"batl":[[0,5.3,88.64]],"ltp":4.9,"tv":60.02,"id":8858707}]}]}
{"op":"mcm","clk":"11995387125","pt":1725030990613,"mc":[{"id":"1.232459454","rc":[{"batl":[[0,5.3,67.38]],"ltp":4.9,"tv":60.02,"id":8858707}]}]}
{"op":"mcm","clk":"11995501344","pt":1725031771547,"mc":[{"id":"1.232459454","rc":[{"batl":[[0,5.3,84.22]],"ltp":4.9,"tv":60.02,"id":8858707}]}]}
{"op":"mcm","clk":"11995586249","pt":1725032310370,"mc":[{"id":"1.232459454","rc":[{"batb":[[0,1.24,41.89],[1,1.21,206.8],[2,1.2,4.19]],"ltp":1.25,"tv":1014.98,"id":7587363}]}]}
{"op":"mcm","clk":"11995587310","pt":1725032317778,"mc":[{"id":"1.232459454","rc":[{"batb":[[0,1.21,206.8],[1,1.2,4.19],[2,1.19,4.19]],"ltp":1.25,"tv":1014.98,"id":7587363}]}]}
{"op":"mcm","clk":"11995668390","pt":1725032621994,"mc":[{"id":"1.232459454","rc":[{"trd":[[4.9,16.33]],"batb":[[0,3,6.5],[1,2.02,10.7],[2,2,139.9]],"ltp":4.9,"tv":71.15,"id":8858707},{"trd":[[1.26,43.28]],"batb":[[0,1.26,64.78],[1,1.21,206.8],[2,1.2,4.19]],"ltp":1.26,"tv":1058.26,"id":7587363}],"tv":1129.42}]}
{"op":"mcm","clk":"11995668802","pt":1725032624670,"mc":[{"id":"1.232459454","rc":[{"batb":[[0,4.5,12.4],[1,3,6.5],[2,2.04,5.33]],"ltp":4.9,"tv":71.15,"id":8858707}]}]}
{"op":"mcm","clk":"11995669089","pt":1725032626979,"mc":[{"id":"1.232459454","rc":[{"batb":[[2,2.06,10.49]],"ltp":4.9,"tv":71.15,"id":8858707}]}]}
{"op":"mcm","clk":"11995670471","pt":1725032635898,"mc":[{"id":"1.232459454","rc":[{"batb":[[0,1.21,206.8],[1,1.2,4.19],[2,1.19,4.19]],"ltp":1.26,"tv":1058.26,"id":7587363}]}]}
{"op":"mcm","clk":"11995671750","pt":1725032645382,"mc":[{"id":"1.232459454","rc":[{"batl":[[0,1.46,41.84]],"ltp":1.26,"tv":1058.26,"id":7587363}]}]}
{"op":"mcm","clk":"11995671885","pt":1725032646392,"mc":[{"id":"1.232459454","rc":[{"batb":[[2,2,139.9]],"ltp":4.9,"tv":71.15,"id":8858707}]}]}
{"op":"mcm","clk":"11995673595","pt":1725032658399,"mc":[{"id":"1.232459454","rc":[{"batb":[[1,3.2,6.75],[2,3,6.5]],"ltp":4.9,"tv":71.15,"id":8858707}]}]}
{"op":"mcm","clk":"11995675399","pt":1725032671027,"mc":[{"id":"1.232459454","rc":[{"batb":[[0,1.24,67.85],[1,1.21,206.8],[2,1.2,4.19]],"ltp":1.26,"tv":1058.26,"id":7587363}]}]}
{"op":"mcm","clk":"11995682911","pt":1725032720869,"mc":[{"id":"1.232459454","rc":[{"batb":[[0,1.21,206.8],[1,1.2,4.19],[2,1.19,4.19]],"ltp":1.26,"tv":1058.26,"id":7587363}]}]}
{"op":"mcm","clk":"11995719036","pt":1725032844321,"mc":[{"id":"1.232459454","rc":[{"trd":[[5.3,33.62]],"batl":[[0,5.3,52.15]],"ltp":5.3,"tv":103.23,"id":8858707},{"trd":[[1.23,171.73]],"ltp":1.23,"tv":1196.47,"id":7587363}],"tv":1299.7}]}
{"op":"mcm","clk":"11995751387","pt":1725033114771,"mc":[{"id":"1.232459454","rc":[{"batb":[[0,1.21,210.99],[2,1.18,4.19]],"ltp":1.23,"tv":1196.47,"id":7587363}]}]}
{"op":"mcm","clk":"11995757917","pt":1725033174738,"mc":[{"id":"1.232459454","rc":[{"batb":[[0,1.22,4.19],[1,1.21,210.99],[2,1.2,4.19]],"ltp":1.23,"tv":1196.47,"id":7587363}]}]}
{"op":"mcm","clk":"11995797602","pt":1725033534742,"mc":[{"id":"1.232459454","rc":[{"batb":[[0,1.23,4.19],[1,1.22,4.19],[2,1.21,210.99]],"ltp":1.23,"tv":1196.47,"id":7587363}]}]}
{"op":"mcm","clk":"11995862234","pt":1725034042321,"mc":[{"id":"1.232459454","rc":[{"trd":[[5,32.74],[5.1,2.24],[5.3,33.62]],"ltp":5.3,"tv":103.24,"id":8858707},{"trd":[[1.24,2.06]],"batb":[[0,1.24,4.19],[1,1.23,4.19],[2,1.22,4.19]],"ltp":1.23,"tv":1196.47,"id":7587363}],"tv":1299.72}]}
{"op":"mcm","clk":"11996058764","pt":1725035242277,"mc":[{"id":"1.232459454","rc":[{"batb":[[0,1.25,4.19],[1,1.24,4.19],[2,1.23,4.19]],"ltp":1.23,"tv":1196.47,"id":7587363}]}]}
{"op":"mcm","clk":"11996060158","pt":1725035251668,"mc":[{"id":"1.232459454","rc":[{"batb":[[0,1.26,4.19],[1,1.25,4.19],[2,1.24,4.19]],"ltp":1.23,"tv":1196.47,"id":7587363}]}]}
{"op":"mcm","clk":"11996065126","pt":1725035285033,"mc":[{"id":"1.232459454","rc":[{"trd":[[4.5,1.2]],"batb":[[0,4.5,11.2]],"ltp":4.5,"tv":104.44,"id":8858707},{"trd":[[1.29,4.19]],"ltp":1.29,"tv":1200.66,"id":7587363}],"tv":1305.11}]}
{"op":"mcm","clk":"11996065445","pt":1725035287040,"mc":[{"id":"1.232459454","rc":[{"batb":[[0,4.5,12.4]],"ltp":4.5,"tv":104.44,"id":8858707}]}]}
{"op":"mcm","clk":"11996293438","pt":1725036552218,"mc":[{"id":"1.232459454","rc":[{"batb":[[0,1.27,4.19],[1,1.26,4.19],[2,1.25,4.19]],"ltp":1.29,"tv":1200.66,"id":7587363}]}]}
{"op":"mcm","clk":"11996305319","pt":1725036641507,"mc":[{"id":"1.232459454","rc":[{"batb":[[0,1.28,4.19],[1,1.27,4.19],[2,1.26,4.19]],"ltp":1.29,"tv":1200.66,"id":7587363}]}]}
{"op":"mcm","clk":"11996311570","pt":1725036689852,"mc":[{"id":"1.232459454","rc":[{"trd":[[4.6,0.38]],"ltp":4.6,"tv":104.82,"id":8858707},{"trd":[[1.28,1.37]],"batb":[[0,1.28,2.82]],"ltp":1.28,"tv":1202.03,"id":7587363}],"tv":1306.86}]}
{"op":"mcm","clk":"11996326121","pt":1725036800603,"mc":[{"id":"1.232459454","rc":[{"trd":[[1.26,51.66],[1.27,8.38],[1.28,7.01]],"batb":[[0,1.25,4.19],[1,1.21,206.8],[2,1.13,167.36]],"batl":[[0,1.26,83.72],[1,1.46,41.84]],"ltp":1.26,"tv":1224.43,"id":7587363}],"tv":1329.26}]}
{"op":"mcm","clk":"11996326274","pt":1725036801905,"mc":[{"id":"1.232459454","rc":[{"batb":[[0,4.9,2.22],[1,4.5,12.4],[2,3.2,6.75]],"ltp":4.6,"tv":104.82,"id":8858707}]}]}
{"op":"mcm","clk":"11996326627","pt":1725036804584,"mc":[{"id":"1.232459454","rc":[{"batb":[[0,4.9,6.63],[2,3,6.5]],"ltp":4.6,"tv":104.82,"id":8858707}]}]}
{"op":"mcm","clk":"11996326852","pt":1725036806208,"mc":[{"id":"1.232459454","rc":[{"batl":[[0,1.46,41.84],[1,1.46,0]],"ltp":1.26,"tv":1224.43,"id":7587363}]}]}
{"op":"mcm","clk":"11996326936","pt":1725036806903,"mc":[{"id":"1.232459454","rc":[{"batb":[[0,4.9,4.4]],"ltp":4.6,"tv":104.82,"id":8858707}]}]}
{"op":"mcm","clk":"11996327160","pt":1725036808609,"mc":[{"id":"1.232459454","rc":[{"batb":[[0,4.5,12.4],[1,3.2,6.75]],"ltp":4.6,"tv":104.82,"id":8858707}]}]}
{"op":"mcm","clk":"11996330227","pt":1725036831948,"mc":[{"id":"1.232459454","rc":[{"trd":[[1.25,483.29]],"batb":[[0,1.21,206.8],[1,1.13,167.36],[2,1.1,30.01]],"batl":[[0,1.25,77.17],[1,1.46,41.84]],"ltp":1.25,"tv":1232.81,"id":7587363}],"tv":1337.64}]}
{"op":"mcm","clk":"11996330430","pt":1725036833237,"mc":[{"id":"1.232459454","rc":[{"batb":[[0,5.1,2.13],[1,4.5,12.4],[2,3.2,6.75]],"ltp":4.6,"tv":104.82,"id":8858707}]}]}
{"op":"mcm","clk":"11996330572","pt":1725036834258,"mc":[{"id":"1.232459454","rc":[{"batb":[[2,3,6.5]],"ltp":4.6,"tv":104.82,"id":8858707}]}]}
{"op":"mcm","clk":"11996331256","pt":1725036838840,"mc":[{"id":"1.232459454","rc":[{"batb":[[0,5.1,6.37]],"ltp":4.6,"tv":104.82,"id":8858707}]}]}
{"op":"mcm","clk":"11996331869","pt":1725036843356,"mc":[{"id":"1.232459454","rc":[{"batl":[[0,1.46,41.84],[1,1.46,0]],"ltp":1.25,"tv":1232.81,"id":7587363}]}]}
{"op":"mcm","clk":"11996331932","pt":1725036843738,"mc":[{"id":"1.232459454","rc":[{"batb":[[0,5.1,4.24]],"ltp":4.6,"tv":104.82,"id":8858707}]}]}
{"op":"mcm","clk":"11996332123","pt":1725036845150,"mc":[{"id":"1.232459454","rc":[{"batb":[[0,4.5,12.4],[1,3,6.5],[2,2,139.98]],"ltp":4.6,"tv":104.82,"id":8858707}]}]}
{"op":"mcm","clk":"11996348231","pt":1725036958807,"mc":[{"id":"1.232459454","rc":[{"batb":[[1,3.2,6.75],[2,3,6.5]],"ltp":4.6,"tv":104.82,"id":8858707}]}]}
{"op":"mcm","clk":"11996378983","pt":1725037210979,"mc":[{"id":"1.232459454","rc":[{"trd":[[5,32.75],[5.1,2.24],[5.3,33.62],[5.6,0.92]],"batl":[[0,5.2,58.96]],"ltp":4.6,"tv":104.84,"id":8858707},{"trd":[[1.24,2.06],[1.25,483.27],[1.26,51.64],[1.27,8.36],[1.28,6.99]],"ltp":1.25,"tv":1232.72,"id":7587363}],"tv":1337.57}]}
{"op":"mcm","clk":"11996499988","pt":1725037963576,"mc":[{"id":"1.232459454","rc":[{"batb":[[1,3.05,7.08]],"ltp":4.6,"tv":104.84,"id":8858707}]}]}
{"op":"mcm","clk":"11996607344","pt":1725038376308,"mc":[{"id":"1.232459454","rc":[{"batb":[[0,4.6,19.05],[1,4.5,12.4],[2,3.05,7.08]],"ltp":4.6,"tv":104.84,"id":8858707}]}]}
{"op":"mcm","clk":"11996607668","pt":1725038378373,"mc":[{"id":"1.232459454","rc":[{"batb":[[0,4.7,2.32],[1,4.6,19.05],[2,4.5,12.4]],"ltp":4.6,"tv":104.84,"id":8858707}]}]}
{"op":"mcm","clk":"11996607699","pt":1725038378568,"mc":[{"id":"1.232459454","rc":[{"batb":[[0,4.7,6.91]],"ltp":4.6,"tv":104.84,"id":8858707}]}]}
{"op":"mcm","clk":"11996641455","pt":1725038570872,"mc":[{"id":"1.232459454","rc":[{"batb":[[0,1.22,4.19],[1,1.21,206.8],[2,1.13,167.36]],"ltp":1.25,"tv":1232.72,"id":7587363}]}]}
{"op":"mcm","clk":"11996671584","pt":1725038745053,"mc":[{"id":"1.232459454","rc":[{"batb":[[0,4.7,23.13]],"ltp":4.6,"tv":104.84,"id":8858707}]}]}
{"op":"mcm","clk":"11996713411","pt":1725038977109,"mc":[{"id":"1.232459454","rc":[{"batl":[[0,6.8,10.23]],"ltp":4.6,"tv":104.84,"id":8858707}]}]}
{"op":"mcm","clk":"11996715457","pt":1725038987103,"mc":[{"id":"1.232459454","rc":[{"batl":[[0,5.1,59.8],[1,6.8,10.23]],"ltp":4.6,"tv":104.84,"id":8858707}]}]}
{"op":"mcm","clk":"11996865876","pt":1725039757109,"mc":[{"id":"1.232459454","rc":[{"batb":[[1,4.5,12.4],[2,3,6.5]],"batl":[[1,6.8,0]],"ltp":4.6,"tv":104.84,"id":8858707}]}]}
{"op":"mcm","clk":"11996948769","pt":1725040170474,"mc":[{"id":"1.232459454","rc":[{"batb":[[0,4.7,6.91]],"ltp":4.6,"tv":104.84,"id":8858707}]}]}
{"op":"mcm","clk":"11996953148","pt":1725040181580,"mc":[{"id":"1.232459454","rc":[{"batb":[[0,4.7,2.32],[1,4.6,4.7],[2,4.5,12.4]],"ltp":4.6,"tv":104.84,"id":8858707}]}]}
{"op":"mcm","clk":"11996954640","pt":1725040188376,"mc":[{"id":"1.232459454","rc":[{"batb":[[0,4.6,4.7],[1,4.5,12.4],[2,3,6.5]],"ltp":4.6,"tv":104.84,"id":8858707}]}]}
{"op":"mcm","clk":"11996954676","pt":1725040188541,"mc":[{"id":"1.232459454","rc":[{"batb":[[0,4.6,7.07]],"ltp":4.6,"tv":104.84,"id":8858707}]}]}
{"op":"mcm","clk":"11996955009","pt":1725040190076,"mc":[{"id":"1.232459454","rc":[{"batb":[[0,4.7,16.22],[1,4.6,7.07],[2,4.5,12.4]],"ltp":4.6,"tv":104.84,"id":8858707}]}]}
{"op":"mcm","clk":"11997102338","pt":1725040961681,"mc":[{"id":"1.232459454","rc":[{"trd":[[5,32.76],[5.1,119.2],[5.3,33.63],[5.4,8]],"batb":[[1,4.6,7.07]],"batl":[[0,5.1,1.35]],"ltp":5.1,"tv":221.83,"id":8858707},{"trd":[[1.21,490.23],[1.25,483.36]],"ltp":1.25,"tv":1232.92,"id":7587363}],"tv":1454.75}]}
{"op":"mcm","clk":"11997104089","pt":1725040970711,"mc":[{"id":"1.232459454","rc":[{"trd":[[5.1,120.97]],"batl":[[0,5.1,0.46]],"ltp":5.1,"tv":223.6,"id":8858707}],"tv":1456.52}]}
{"op":"mcm","clk":"11997121975","pt":1725041051318,"mc":[{"id":"1.232459454","rc":[{"batb":[[0,4.8,2.27],[1,4.7,16.22],[2,4.6,4.7]],"ltp":5.1,"tv":223.6,"id":8858707},{"batl":[[0,1.27,7.09]],"ltp":1.25,"tv":1232.92,"id":7587363}]}]}
{"op":"mcm","clk":"11997122589","pt":1725041053915,"mc":[{"id":"1.232459454","rc":[{"batb":[[0,4.8,6.77],[2,4.5,12.4]],"ltp":5.1,"tv":223.6,"id":8858707}]}]}
{"op":"mcm","clk":"11997128785","pt":1725041082228,"mc":[{"id":"1.232459454","rc":[{"batb":[[0,4.8,2.27],[1,4.5,12.4],[2,3,6.5]],"ltp":5.1,"tv":223.6,"id":8858707}]}]}
{"op":"mcm","clk":"11997128829","pt":1725041082437,"mc":[{"id":"1.232459454","rc":[{"batb":[[1,4.6,4.7],[2,4.5,12.4]],"ltp":5.1,"tv":223.6,"id":8858707}]}]}
{"op":"mcm","clk":"11997129249","pt":1725041084317,"mc":[{"id":"1.232459454","rc":[{"batb":[[0,4.6,2.37],[1,4.5,12.4],[2,3,6.5]],"ltp":5.1,"tv":223.6,"id":8858707},{"batl":[[0,1.27,67.13]],"ltp":1.25,"tv":1232.92,"id":7587363}]}]}
{"op":"mcm","clk":"11997129632","pt":1725041086122,"mc":[{"id":"1.232459454","rc":[{"batb":[[0,4.5,12.4],[1,3,6.5],[2,2,140.17]],"ltp":5.1,"tv":223.6,"id":8858707}]}]}
{"op":"mcm","clk":"11997140602","pt":1725041135253,"mc":[{"id":"1.232459454","rc":[{"batb":[[0,4.8,2.27],[1,4.5,12.4],[2,3,6.5]],"ltp":5.1,"tv":223.6,"id":8858707}]}]}
{"op":"mcm","clk":"11997153573","pt":1725041194053,"mc":[{"id":"1.232459454","rc":[{"batb":[[0,4.8,6.77]],"ltp":5.1,"tv":223.6,"id":8858707},{"batl":[[0,1.27,7.09]],"ltp":1.25,"tv":1232.92,"id":7587363}]}]}
{"op":"mcm","clk":"11997153934","pt":1725041195661,"mc":[{"id":"1.232459454","rc":[{"batb":[[0,4.8,4.5],[1,4.6,2.37],[2,4.5,12.4]],"ltp":5.1,"tv":223.6,"id":8858707}]}]}
{"op":"mcm","clk":"11997154172","pt":1725041196840,"mc":[{"id":"1.232459454","rc":[{"batb":[[0,4.6,2.37],[1,4.5,12.4],[2,3,6.5]],"ltp":5.1,"tv":223.6,"id":8858707},{"batl":[[0,1.27,67.13]],"ltp":1.25,"tv":1232.92,"id":7587363}]}]}
{"op":"mcm","clk":"11997154486","pt":1725041198152,"mc":[{"id":"1.232459454","rc":[{"batb":[[0,4.5,12.4],[1,3,6.5],[2,2,140.17]],"ltp":5.1,"tv":223.6,"id":8858707}]}]}
{"op":"mcm","clk":"11997159767","pt":1725041220980,"mc":[{"id":"1.232459454","rc":[{"batb":[[0,4.8,2.27],[1,4.5,12.4],[2,3,6.5]],"ltp":5.1,"tv":223.6,"id":8858707}]}]}
{"op":"mcm","clk":"11997173637","pt":1725041279139,"mc":[{"id":"1.232459454","rc":[{"batl":[[0,1.26,75.33],[1,1.27,7.09]],"ltp":1.25,"tv":1232.92,"id":7587363}]}]}
{"op":"mcm","clk":"11997173857","pt":1725041280133,"mc":[{"id":"1.232459454","rc":[{"batb":[[0,4.9,4.41],[1,4.8,2.27],[2,4.5,12.4]],"ltp":5.1,"tv":223.6,"id":8858707}]}]}
{"op":"mcm","clk":"11997271065","pt":1725041677873,"mc":[{"id":"1.232459454","rc":[{"batl":[[2,1.5,5.02]],"ltp":1.25,"tv":1232.92,"id":7587363}]}]}
{"op":"mcm","clk":"11997350856","pt":1725042001756,"mc":[{"id":"1.232459454","rc":[{"batl":[[0,1.25,8.01],[1,1.26,75.33],[2,1.27,7.09]],"ltp":1.25,"tv":1232.92,"id":7587363}]}]}
{"op":"mcm","clk":"11997470985","pt":1725042498319,"mc":[{"id":"1.232459454","rc":[{"batb":[[2,1.13,169.36]],"ltp":1.25,"tv":1232.92,"id":7587363}]}]}
{"op":"mcm","clk":"11997791328","pt":1725043642248,"mc":[{"id":"1.232459454","rc":[{"batb":[[1,4.5,12.4],[2,3,6.5]],"ltp":5.1,"tv":223.6,"id":8858707},{"batl":[[1,1.27,7.09],[2,1.5,5.02]],"ltp":1.25,"tv":1232.92,"id":7587363}]}]}
{"op":"mcm","clk":"11997791419","pt":1725043642733,"mc":[{"id":"1.232459454","rc":[{"batb":[[0,4.6,7.07]],"ltp":5.1,"tv":223.6,"id":8858707}]}]}
{"op":"mcm","clk":"11997829906","pt":1725043809270,"mc":[{"id":"1.232459454","rc":[{"batb":[[0,4.7,58.99],[1,4.6,4.7],[2,4.5,12.4]],"ltp":5.1,"tv":223.6,"id":8858707}]}]}
{"op":"mcm","clk":"11997830110","pt":1725043810185,"mc":[{"id":"1.232459454","rc":[{"batb":[[0,4.8,6.77],[1,4.7,58.99]],"ltp":5.1,"tv":223.6,"id":8858707}]}]}
{"op":"mcm","clk":"11998354015","pt":1725046174786,"mc":[{"id":"1.232459454","rc":[{"trd":[[5,32.75],[5.1,120.92],[5.3,33.62],[5.4,8]],"batb":[[0,4.8,6.76],[1,4.5,12.4],[2,3,6.5]],"ltp":5.1,"tv":223.52,"id":8858707},{"trd":[[1.21,490.14],[1.25,483.28]],"batl":[[0,1.25,8],[1,1.27,7.09]],"ltp":1.25,"tv":1232.76,"id":7587363}],"tv":1456.29}]}
{"op":"mcm","clk":"11998354371","pt":1725046176376,"mc":[{"id":"1.232459454","rc":[{"batb":[[0,4.6,2.37]],"ltp":5.1,"tv":223.52,"id":8858707}]}]}
{"op":"mcm","clk":"11998354413","pt":1725046176583,"mc":[{"id":"1.232459454","rc":[{"batb":[[0,4.6,7.07]],"ltp":5.1,"tv":223.52,"id":8858707}]}]}
{"op":"mcm","clk":"11998391251","pt":1725046344305,"mc":[{"id":"1.232459454","rc":[{"batb":[[0,4.7,58.96],[1,4.6,2.37],[2,4.5,12.4]],"ltp":5.1,"tv":223.52,"id":8858707}]}]}
{"op":"mcm","clk":"11998391283","pt":1725046344402,"mc":[{"id":"1.232459454","rc":[{"batb":[[0,4.8,4.5],[1,4.7,58.96],[2,4.6,2.37]],"ltp":5.1,"tv":223.52,"id":8858707}]}]}
{"op":"mcm","clk":"11998391620","pt":1725046346130,"mc":[{"id":"1.232459454","rc":[{"batb":[[0,4.8,6.76],[2,4.5,12.4]],"ltp":5.1,"tv":223.52,"id":8858707}]}]}
{"op":"mcm","clk":"11998735014","pt":1725048322233,"mc":[{"id":"1.232459454","rc":[{"trd":[[5,32.74],[5.1,120.81],[5.3,33.59],[5.4,8],[5.9,3.68]],"batb":[[0,4.8,6.76],[1,4.7,58.92]],"ltp":5.1,"tv":223.37,"id":8858707},{"trd":[[1.21,489.98],[1.24,2.06],[1.25,483.16],[1.26,51.65],[1.27,8.37],[1.28,7]],"batl":[[0,1.25,8],[1,1.27,7.08]],"ltp":1.25,"tv":1232.5,"id":7587363}],"tv":1455.88}]}
{"op":"mcm","clk":"11998841381","pt":1725049010412,"mc":[{"id":"1.232459454","rc":[{"batb":[[1,4.5,12.4],[2,3,6.5]],"ltp":5.1,"tv":223.37,"id":8858707}]}]}
{"op":"mcm","clk":"11998841524","pt":1725049011656,"mc":[{"id":"1.232459454","rc":[{"batb":[[0,4.8,2.26],[1,4.6,4.7],[2,4.5,12.4]],"ltp":5.1,"tv":223.37,"id":8858707}]}]}
{"op":"mcm","clk":"11998841653","pt":1725049012956,"mc":[{"id":"1.232459454","rc":[{"batb":[[0,4.6,7.06],[1,4.5,12.4],[2,3,6.5]],"ltp":5.1,"tv":223.37,"id":8858707}]}]}
{"op":"mcm","clk":"11998858466","pt":1725049163217,"mc":[{"id":"1.232459454","rc":[{"batb":[[0,4.7,58.92],[1,4.6,7.06],[2,4.5,12.4]],"ltp":5.1,"tv":223.37,"id":8858707}]}]}
{"op":"mcm","clk":"11998858764","pt":1725049166221,"mc":[{"id":"1.232459454","rc":[{"batb":[[0,4.8,2.26],[1,4.7,58.92]],"ltp":5.1,"tv":223.37,"id":8858707}]}]}
{"op":"mcm","clk":"11998858786","pt":1725049166426,"mc":[{"id":"1.232459454","rc":[{"batb":[[0,4.8,6.76]],"ltp":5.1,"tv":223.37,"id":8858707}]}]}
{"op":"mcm","clk":"11998981778","pt":1725050370164,"mc":[{"id":"1.232459454","rc":[{"trd":[[5.1,121.74]],"batb":[[0,4.8,7.38]],"ltp":5.1,"tv":224.3,"id":8858707}],"tv":1456.8}]}
{"op":"mcm","clk":"11998981918","pt":1725050372280,"mc":[{"id":"1.232459454","rc":[{"batb":[[0,4.8,6.76]],"ltp":5.1,"tv":224.3,"id":8858707}]}]}
{"op":"mcm","clk":"11998982519","pt":1725050380176,"mc":[{"id":"1.232459454","rc":[{"trd":[[1.25,486.94]],"batl":[[0,1.25,6.1]],"ltp":1.25,"tv":1236.28,"id":7587363}],"tv":1460.58}]}
{"op":"mcm","clk":"11998983979","pt":1725050399087,"mc":[{"id":"1.232459454","rc":[{"trd":[[5.6,1.83]],"batb":[[0,5.7,3.55],[1,4.8,6.76]],"ltp":5.6,"tv":225.21,"id":8858707},{"trd":[[1.22,8.38]],"batb":[[0,1.21,206.8],[1,1.13,169.36],[2,1.1,30.01]],"ltp":1.22,"tv":1240.47,"id":7587363}],"tv":1465.69}]}
{"op":"mcm","clk":"11998984111","pt":1725050400275,"mc":[{"id":"1.232459454","rc":[{"batb":[[1,4.8,4.49],[2,4.6,2.37]],"ltp":5.6,"tv":225.21,"id":8858707}]}]}
{"op":"mcm","clk":"11998984146","pt":1725050400785,"mc":[{"id":"1.232459454","rc":[{"batb":[[1,4.6,7.06],[2,4.5,12.4]],"ltp":5.6,"tv":225.21,"id":8858707}]}]}
{"op":"mcm","clk":"11998985443","pt":1725050415722,"mc":[{"id":"1.232459454","rc":[{"batb":[[0,4.6,7.06],[1,4.5,12.4],[2,3,6.5]],"ltp":5.6,"tv":225.21,"id":8858707}]}]}
{"op":"mcm","clk":"11998985761","pt":1725050419313,"mc":[{"id":"1.232459454","rc":[{"batb":[[0,4.7,58.92],[1,4.6,7.06],[2,4.5,12.4]],"ltp":5.6,"tv":225.21,"id":8858707}]}]}
{"op":"mcm","clk":"11998985820","pt":1725050420032,"mc":[{"id":"1.232459454","rc":[{"batb":[[0,4.8,2.26],[1,4.7,58.92],[2,4.6,4.7]],"ltp":5.6,"tv":225.21,"id":8858707}]}]}
{"op":"mcm","clk":"11998986003","pt":1725050422121,"mc":[{"id":"1.232459454","rc":[{"batb":[[0,4.8,6.76],[2,4.5,12.4]],"ltp":5.6,"tv":225.21,"id":8858707}]}]}
{"op":"mcm","clk":"11998988975","pt":1725050462860,"mc":[{"id":"1.232459454","rc":[{"trd":[[1.25,495.12]],"batl":[[0,1.25,2.01]],"ltp":1.25,"tv":1248.65,"id":7587363}],"tv":1473.87}]}
{"op":"mcm","clk":"11999035441","pt":1725051284005,"mc":[{"id":"1.232459454","rc":[{"batb":[[1,4.5,12.4],[2,3,6.5]],"ltp":5.6,"tv":225.21,"id":8858707}]}]}
{"op":"mcm","clk":"11999035483","pt":1725051285230,"mc":[{"id":"1.232459454","rc":[{"batb":[[0,4.8,4.49]],"ltp":5.6,"tv":225.21,"id":8858707}]}]}
{"op":"mcm","clk":"11999035499","pt":1725051285440,"mc":[{"id":"1.232459454","rc":[{"batb":[[1,4.6,2.37],[2,4.5,12.4]],"ltp":5.6,"tv":225.21,"id":8858707}]}]}
{"op":"mcm","clk":"11999035671","pt":1725051288727,"mc":[{"id":"1.232459454","rc":[{"batb":[[0,4.6,7.06],[1,4.5,12.4],[2,3,6.5]],"ltp":5.6,"tv":225.21,"id":8858707}]}]}
{"op":"mcm","clk":"11999089184","pt":1725052456615,"mc":[{"id":"1.232459454","rc":[{"trd":[[5,32.75],[5.1,121.78],[5.3,33.59],[5.6,1.83]],"batb":[[0,4.7,58.91],[1,4.6,7.06],[2,4.5,12.4]],"ltp":5.6,"tv":225.26,"id":8858707},{"trd":[[1.21,489.96],[1.24,2.06],[1.25,495.16],[1.26,51.67],[1.27,8.39],[1.28,7.02]],"batl":[[0,1.25,2.01],[1,1.27,7.08]],"ltp":1.25,"tv":1248.73,"id":7587363}],"tv":1474.0}]}
{"op":"mcm","clk":"11999089230","pt":1725052457891,"mc":[{"id":"1.232459454","rc":[{"batb":[[0,4.8,2.26],[1,4.7,58.91],[2,4.6,4.7]],"ltp":5.6,"tv":225.26,"id":8858707}]}]}
{"op":"mcm","clk":"11999089300","pt":1725052459481,"mc":[{"id":"1.232459454","rc":[{"batb":[[0,4.8,6.76],[2,4.5,12.4]],"ltp":5.6,"tv":225.26,"id":8858707}]}]}
{"op":"mcm","clk":"11999232466","pt":1725056024323,"mc":[{"id":"1.232459454","rc":[{"trd":[[5,32.74],[5.1,121.8],[5.3,33.62],[5.4,8],[5.9,3.68]],"batb":[[0,4.8,6.76],[1,4.5,12.4],[2,3,6.5]],"ltp":5.6,"tv":225.3,"id":8858707},{"trd":[[1.21,490.12],[1.25,495.29],[1.26,51.66],[1.27,8.38],[1.28,7.01]],"batl":[[1,1.27,7.08]],"ltp":1.25,"tv":1249.01,"id":7587363}],"tv":1474.32}]}
{"op":"mcm","clk":"11999232534","pt":1725056026021,"mc":[{"id":"1.232459454","rc":[{"batb":[[0,4.8,4.5],[1,4.6,2.37],[2,4.5,12.4]],"ltp":5.6,"tv":225.3,"id":8858707}]}]}
{"op":"mcm","clk":"11999232705","pt":1725056029716,"mc":[{"id":"1.232459454","rc":[{"batb":[[0,4.7,4.6]],"ltp":5.6,"tv":225.3,"id":8858707}]}]}
{"op":"mcm","clk":"11999238335","pt":1725056178816,"mc":[{"id":"1.232459454","rc":[{"batb":[[0,4.8,58.96],[1,4.7,4.6],[2,4.6,2.37]],"ltp":5.6,"tv":225.3,"id":8858707}]}]}
{"op":"mcm","clk":"11999238363","pt":1725056179533,"mc":[{"id":"1.232459454","rc":[{"batb":[[0,4.9,4.4],[1,4.8,58.96]],"ltp":5.6,"tv":225.3,"id":8858707}]}]}
{"op":"mcm","clk":"11999238415","pt":1725056180716,"mc":[{"id":"1.232459454","rc":[{"batb":[[0,4.9,6.63],[2,4.5,12.4]],"ltp":5.6,"tv":225.3,"id":8858707}]}]}
{"op":"mcm","clk":"11999252173","pt":1725056522158,"mc":[{"id":"1.232459454","rc":[{"trd":[[1.21,696.23]],"batb":[[0,1.21,103.74]],"ltp":1.21,"tv":1455.13,"id":7587363}],"tv":1680.44}]}
{"op":"mcm","clk":"11999252325","pt":1725056526202,"mc":[{"id":"1.232459454","rc":[{"batb":[[0,1.21,162.33]],"ltp":1.21,"tv":1455.13,"id":7587363}]}]}
{"op":"mcm","clk":"11999269844","pt":1725057039205,"mc":[{"id":"1.232459454","rc":[{"trd":[[4.8,37.41],[4.9,29.58],[5,33.25]],"batb":[[0,4.8,40.25],[1,4.5,12.4],[2,3,6.5]],"ltp":4.8,"tv":276.47,"id":8858707},{"trd":[[1.25,497.3]],"batl":[[0,1.27,7.08],[1,1.5,5.02],[2,1.5,0]],"ltp":1.25,"tv":1457.14,"id":7587363}],"tv":1733.62}]}
{"op":"mcm","clk":"11999269873","pt":1725057040123,"mc":[{"id":"1.232459454","rc":[{"batb":[[0,4.6,58.96]],"ltp":4.8,"tv":276.47,"id":8858707}]}]}
{"op":"mcm","clk":"11999271408","pt":1725057088776,"mc":[{"id":"1.232459454","rc":[{"batb":[[0,4.5,12.4],[1,3,6.5],[2,2.06,84.39]],"ltp":4.8,"tv":276.47,"id":8858707}]}]}
{"op":"mcm","clk":"11999271885","pt":1725057103702,"mc":[{"id":"1.232459454","rc":[{"trd":[[1.21,696.36]],"batb":[[0,1.21,162.26]],"ltp":1.21,"tv":1457.26,"id":7587363}],"tv":1733.74}]}
{"op":"mcm","clk":"11999276730","pt":1725057244560,"mc":[{"id":"1.232459454","rc":[{"batb":[[0,4.6,58.96],[1,4.5,12.4],[2,3,6.5]],"ltp":4.8,"tv":276.47,"id":8858707}]}]}
{"op":"mcm","clk":"11999290436","pt":1725057673418,"mc":[{"id":"1.232459454","rc":[{"batl":[[0,1.27,8]],"ltp":1.21,"tv":1457.26,"id":7587363}]}]}
{"op":"mcm","clk":"11999293854","pt":1725057781772,"mc":[{"id":"1.232459454","rc":[{"batb":[[0,4.7,30.4],[1,4.6,58.96],[2,4.5,12.4]],"ltp":4.8,"tv":276.47,"id":8858707}]}]}
{"op":"mcm","clk":"11999312367","pt":1725058256362,"mc":[{"id":"1.232459454","rc":[{"trd":[[1.21,727.27]],"batb":[[0,1.21,146.8]],"ltp":1.21,"tv":1488.18,"id":7587363}],"tv":1764.66}]}
{"op":"mcm","clk":"11999312489","pt":1725058258871,"mc":[{"id":"1.232459454","rc":[{"batb":[[0,1.21,145.74]],"ltp":1.21,"tv":1488.18,"id":7587363}]}]}
{"op":"mcm","clk":"11999350944","pt":1725059062994,"mc":[{"id":"1.232459454","rc":[{"batl":[[0,1.23,25.76],[1,1.27,8],[2,1.5,5.02]],"ltp":1.21,"tv":1488.18,"id":7587363}]}]}
{"op":"mcm","clk":"11999351015","pt":1725059064792,"mc":[{"id":"1.232459454","rc":[{"batl":[[1,1.25,25.76],[2,1.27,8]],"ltp":1.21,"tv":1488.18,"id":7587363}]}]}
{"op":"mcm","clk":"11999351082","pt":1725059065980,"mc":[{"id":"1.232459454","rc":[{"batl":[[1,1.25,51.53]],"ltp":1.21,"tv":1488.18,"id":7587363}]}]}
{"op":"mcm","clk":"11999412967","pt":1725059950947,"mc":[{"id":"1.232459454","rc":[{"batb":[[1,1.14,6.57],[2,1.13,169.36]],"ltp":1.21,"tv":1488.18,"id":7587363}]}]}
{"op":"mcm","clk":"11999426529","pt":1725060211321,"mc":[{"id":"1.232459454","rc":[{"batb":[[1,4.5,12.4],[2,3,6.5]],"ltp":4.8,"tv":276.47,"id":8858707}]}]}
{"op":"mcm","clk":"11999442225","pt":1725060440846,"mc":[{"id":"1.232459454","rc":[{"batb":[[0,4.5,12.4],[1,3,6.5],[2,2.06,84.39]],"ltp":4.8,"tv":276.47,"id":8858707}]}]}
{"op":"mcm","clk":"11999442382","pt":1725060443627,"mc":[{"id":"1.232459454","rc":[{"batb":[[0,4.6,58.96],[1,4.5,12.4],[2,3,6.5]],"ltp":4.8,"tv":276.47,"id":8858707}]}]}
{"op":"mcm","clk":"11999451465","pt":1725060601783,"mc":[{"id":"1.232459454","rc":[{"batb":[[0,5.2,4.21]],"ltp":4.8,"tv":276.47,"id":8858707},{"batb":[[1,1.2,84.22],[2,1.14,6.57]],"ltp":1.21,"tv":1488.18,"id":7587363}]}]}
{"op":"mcm","clk":"11999451945","pt":1725060607920,"mc":[{"id":"1.232459454","rc":[{"batb":[[0,4.5,12.4],[1,3,6.5],[2,2.06,84.39]],"ltp":4.8,"tv":276.47,"id":8858707},{"batb":[[1,1.14,6.57],[2,1.13,169.36]],"ltp":1.21,"tv":1488.18,"id":7587363}]}]}
{"op":"mcm","clk":"11999452281","pt":1725060611994,"mc":[{"id":"1.232459454","rc":[{"batb":[[0,4.6,58.96],[1,4.5,12.4],[2,3,6.5]],"ltp":4.8,"tv":276.47,"id":8858707}]}]}
{"op":"mcm","clk":"11999458435","pt":1725060723130,"mc":[{"id":"1.232459454","rc":[{"batb":[[0,5.2,4.21],[1,4.6,58.96],[2,4.5,12.4]],"ltp":4.8,"tv":276.47,"id":8858707},{"batb":[[1,1.2,84.22],[2,1.14,6.57]],"ltp":1.21,"tv":1488.18,"id":7587363}]}]}
{"op":"mcm","clk":"11999458455","pt":1725060723434,"mc":[{"id":"1.232459454","rc":[{"batb":[[1,4.5,12.4],[2,3,6.5]],"ltp":4.8,"tv":276.47,"id":8858707}]}]}
{"op":"mcm","clk":"11999472740","pt":1725060978490,"mc":[{"id":"1.232459454","rc":[{"batb":[[2,3.1,4.12]],"batl":[[0,14.5,2.06]],"ltp":4.8,"tv":276.47,"id":8858707}]}]}
{"op":"mcm","clk":"11999473072","pt":1725060985772,"mc":[{"id":"1.232459454","rc":[{"batl":[[0,12.5,2.06]],"ltp":4.8,"tv":276.47,"id":8858707}]}]}
{"op":"mcm","clk":"11999473948","pt":1725061002298,"mc":[{"id":"1.232459454","rc":[{"batl":[[0,10.5,9.57],[1,12.5,2.06]],"ltp":4.8,"tv":276.47,"id":8858707}]}]}
{"op":"mcm","clk":"11999474534","pt":1725061011603,"mc":[{"id":"1.232459454","rc":[{"trd":[[1.23,180.11]],"batl":[[0,1.23,21.57]],"ltp":1.23,"tv":1496.56,"id":7587363}],"tv":1773.04}]}
{"op":"mcm","clk":"11999511266","pt":1725061659197,"mc":[{"id":"1.232459454","rc":[{"trd":[[5.3,35.62]],"batb":[[0,4.5,12.4],[1,3.1,4.12],[2,3,6.5]],"ltp":5.3,"tv":278.47,"id":8858707},{"trd":[[1.23,188.72]],"batl":[[0,1.23,12.96]],"ltp":1.23,"tv":1505.18,"id":7587363}],"tv":1783.66}]}
{"op":"mcm","clk":"11999511302","pt":1725061659712,"mc":[{"id":"1.232459454","rc":[{"batb":[[0,5,4.42],[1,4.5,12.4],[2,3.1,4.12]],"ltp":5.3,"tv":278.47,"id":8858707}]}]}
{"op":"mcm","clk":"11999525698","pt":1725061879356,"mc":[{"id":"1.232459454","rc":[{"trd":[[1.21,1018.75]],"batb":[[0,1.16,58.96],[1,1.15,374.2]],"batl":[[0,1.21,105.57],[1,1.23,12.96],[2,1.25,51.53]],"ltp":1.21,"tv":1796.66,"id":7587363}],"tv":2075.14}]}
{"op":"mcm","clk":"11999525807","pt":1725061880795,"mc":[{"id":"1.232459454","rc":[{"batb":[[0,5.6,3.85]],"ltp":5.3,"tv":278.47,"id":8858707},{"batb":[[1,1.15,458.42]],"ltp":1.21,"tv":1796.66,"id":7587363}]}]}
{"op":"mcm","clk":"11999534233","pt":1725062025352,"mc":[{"id":"1.232459454","rc":[{"batb":[[1,1.15,84.22]],"ltp":1.21,"tv":1796.66,"id":7587363}]}]}
{"op":"mcm","clk":"11999534261","pt":1725062026064,"mc":[{"id":"1.232459454","rc":[{"batb":[[1,1.14,6.57],[2,1.13,253.58]],"ltp":1.21,"tv":1796.66,"id":7587363}]}]}
{"op":"mcm","clk":"11999560328","pt":1725062466983,"mc":[{"id":"1.232459454","rc":[{"batb":[[0,1.17,4.19],[1,1.16,58.96],[2,1.14,6.57]],"ltp":1.21,"tv":1796.66,"id":7587363}]}]}
{"op":"mcm","clk":"11999568377","pt":1725062566729,"mc":[{"id":"1.232459454","rc":[{"trd":[[5.7,5.15]],"ltp":5.7,"tv":283.63,"id":8858707},{"trd":[[1.21,1043.02]],"batl":[[0,1.21,81.3]],"ltp":1.21,"tv":1820.93,"id":7587363}],"tv":2104.56}]}
{"op":"mcm","clk":"11999596265","pt":1725063037356,"mc":[{"id":"1.232459454","rc":[{"batl":[[0,12.5,2.06],[1,12.5,0]],"ltp":5.7,"tv":283.63,"id":8858707},{"batb":[[1,1.14,6.57],[2,1.13,253.58]],"ltp":1.21,"tv":1820.93,"id":7587363}]}]}
{"op":"mcm","clk":"11999600672","pt":1725063104795,"mc":[{"id":"1.232459454","rc":[{"batb":[[0,4.5,12.4],[1,3.1,4.12],[2,3,6.5]],"ltp":5.7,"tv":283.63,"id":8858707},{"batb":[[2,1.13,169.36]],"ltp":1.21,"tv":1820.93,"id":7587363}]}]}
{"op":"mcm","clk":"11999608264","pt":1725063220572,"mc":[{"id":"1.232459454","rc":[{"batb":[[0,5.6,3.85],[1,4.5,12.4],[2,3.1,4.12]],"ltp":5.7,"tv":283.63,"id":8858707},{"batb":[[2,1.13,253.58]],"ltp":1.21,"tv":1820.93,"id":7587363}]}]}
{"op":"mcm","clk":"11999615300","pt":1725063323359,"mc":[{"id":"1.232459454","rc":[{"batb":[[0,6.6,1.09],[1,5.6,3.85],[2,4.5,12.4]],"ltp":5.7,"tv":283.63,"id":8858707}]}]}
{"op":"mcm","clk":"11999615314","pt":1725063323667,"mc":[{"id":"1.232459454","rc":[{"batb":[[1,5.7,3.76],[2,5.6,3.85]],"ltp":5.7,"tv":283.63,"id":8858707}]}]}
{"op":"mcm","clk":"11999618639","pt":1725063373391,"mc":[{"id":"1.232459454","rc":[{"batb":[[0,5.7,3.76],[1,5.6,3.85],[2,4.5,12.4]],"ltp":5.7,"tv":283.63,"id":8858707}]}]}
{"op":"mcm","clk":"11999635693","pt":1725063617027,"mc":[{"id":"1.232459454","rc":[{"batb":[[0,1.17,3.78]],"ltp":1.21,"tv":1820.93,"id":7587363}]}]}
{"op":"mcm","clk":"11999669639","pt":1725064202129,"mc":[{"id":"1.232459454","rc":[{"batb":[[2,3.1,4.12]],"ltp":5.7,"tv":283.63,"id":8858707}]}]}
{"op":"mcm","clk":"11999693226","pt":1725064550496,"mc":[{"id":"1.232459454","rc":[{"batl":[[0,12.5,2.9]],"ltp":5.7,"tv":283.63,"id":8858707}]}]}
{"op":"mcm","clk":"11999747160","pt":1725065038578,"mc":[{"id":"1.232459454","rc":[{"batb":[[2,3,6.5]],"batl":[[0,8,0.84]],"ltp":5.7,"tv":283.63,"id":8858707}]}]}
{"op":"mcm","clk":"11999757119","pt":1725065166046,"mc":[{"id":"1.232459454","rc":[{"batb":[[2,3.1,4.12]],"batl":[[0,14,2.9]],"ltp":5.7,"tv":283.63,"id":8858707}]}]}
{"op":"mcm","clk":"11999757722","pt":1725065173353,"mc":[{"id":"1.232459454","rc":[{"batl":[[0,8,0.84]],"ltp":5.7,"tv":283.63,"id":8858707}]}]}
{"op":"mcm","clk":"11999757733","pt":1725065173454,"mc":[{"id":"1.232459454","rc":[{"batl":[[0,12.5,2.9]],"ltp":5.7,"tv":283.63,"id":8858707}]}]}
{"op":"mcm","clk":"11999759779","pt":1725065198968,"mc":[{"id":"1.232459454","rc":[{"batl":[[0,11,2.9]],"ltp":5.7,"tv":283.63,"id":8858707}]}]}
{"op":"mcm","clk":"11999809406","pt":1725065883005,"mc":[{"id":"1.232459454","rc":[{"trd":[[5.7,5.98]],"batb":[[0,5.7,3.35]],"ltp":5.7,"tv":284.45,"id":8858707}],"tv":2105.38}]}
{"op":"mcm","clk":"11999830880","pt":1725066200647,"mc":[{"id":"1.232459454","rc":[{"trd":[[4.8,37.41],[5.7,11.28]],"batb":[[0,5.6,4.55],[1,3.1,4.12],[2,3,6.5]],"ltp":5.7,"tv":289.75,"id":8858707},{"trd":[[1.21,1043.01],[1.23,188.72]],"batl":[[1,1.23,12.96],[2,1.25,51.52]],"ltp":1.21,"tv":1820.91,"id":7587363}],"tv":2110.67}]}
{"op":"mcm","clk":"11999830952","pt":1725066201566,"mc":[{"id":"1.232459454","rc":[{"batb":[[1,4.5,5],[2,3.1,4.12]],"ltp":5.7,"tv":289.75,"id":8858707}]}]}
{"op":"mcm","clk":"11999834084","pt":1725066250733,"mc":[{"id":"1.232459454","rc":[{"batb":[[2,3,6.5]],"batl":[[0,8,0.84]],"ltp":5.7,"tv":289.75,"id":8858707}]}]}
{"op":"mcm","clk":"11999834721","pt":1725066260703,"mc":[{"id":"1.232459454","rc":[{"batb":[[0,1.17,4.28]],"ltp":1.21,"tv":1820.91,"id":7587363}]}]}
{"op":"mcm","clk":"11999835302","pt":1725066269726,"mc":[{"id":"1.232459454","rc":[{"batb":[[2,3,10.62]],"batl":[[0,13,2.9]],"ltp":5.7,"tv":289.75,"id":8858707}]}]}
{"op":"mcm","clk":"11999835809","pt":1725066277042,"mc":[{"id":"1.232459454","rc":[{"batl":[[0,11,2.9]],"ltp":5.7,"tv":289.75,"id":8858707}]}]}
{"op":"mcm","clk":"11999836812","pt":1725066291945,"mc":[{"id":"1.232459454","rc":[{"batb":[[0,6,1.09],[1,5.6,4.55],[2,4.5,5]],"ltp":5.7,"tv":289.75,"id":8858707}]}]}
{"op":"mcm","clk":"11999837004","pt":1725066295373,"mc":[{"id":"1.232459454","rc":[{"batb":[[0,5.6,4.55],[1,4.5,5],[2,3,10.62]],"ltp":5.7,"tv":289.75,"id":8858707}]}]}
{"op":"mcm","clk":"11999845474","pt":1725066424099,"mc":[{"id":"1.232459454","rc":[{"trd":[[6.6,0.09]],"batb":[[0,5.7,1.7],[1,5.6,3.85],[2,4.5,5]],"ltp":6.6,"tv":289.84,"id":8858707},{"trd":[[1.18,0.5]],"batb":[[0,1.17,3.78]],"ltp":1.18,"tv":1821.41,"id":7587363}],"tv":2111.26}]}
{"op":"mcm","clk":"11999845626","pt":1725066426718,"mc":[{"id":"1.232459454","rc":[{"batb":[[0,5.6,4.55],[1,4.5,5],[2,3,10.62]],"ltp":6.6,"tv":289.84,"id":8858707}]}]}
{"op":"mcm","clk":"11999845686","pt":1725066427742,"mc":[{"id":"1.232459454","rc":[{"trd":[[5.7,11.48]],"batb":[[0,5.6,4.45]],"ltp":5.7,"tv":290.04,"id":8858707}],"tv":2111.45}]}
{"op":"mcm","clk":"11999846201","pt":1725066437141,"mc":[{"id":"1.232459454","rc":[{"trd":[[1.21,1043.97]],"batl":[[0,1.21,80.82]],"ltp":1.21,"tv":1822.37,"id":7587363}],"tv":2112.42}]}
{"op":"mcm","clk":"11999846955","pt":1725066449852,"mc":[{"id":"1.232459454","rc":[{"batl":[[0,11,3]],"ltp":5.7,"tv":290.04,"id":8858707}]}]}
{"op":"mcm","clk":"11999848474","pt":1725066472767,"mc":[{"id":"1.232459454","rc":[{"trd":[[1.17,7.56]],"batb":[[0,1.15,93.55]],"ltp":1.17,"tv":1829.93,"id":7587363}],"tv":2119.97}]}
{"op":"mcm","clk":"11999848805","pt":1725066477655,"mc":[{"id":"1.232459454","rc":[{"batl":[[0,1.2,257.61],[1,1.21,80.82],[2,1.23,12.96]],"ltp":1.17,"tv":1829.93,"id":7587363}]}]}
{"op":"mcm","clk":"11999848977","pt":1725066479973,"mc":[{"id":"1.232459454","rc":[{"batb":[[0,5.9,3.61],[1,5.6,4.45],[2,4.5,5]],"ltp":5.7,"tv":290.04,"id":8858707}]}]}
{"op":"mcm","clk":"11999849197","pt":1725066483071,"mc":[{"id":"1.232459454","rc":[{"batb":[[2,3,10.62]],"ltp":5.7,"tv":290.04,"id":8858707}]}]}
{"op":"mcm","clk":"11999851514","pt":1725066516662,"mc":[{"id":"1.232459454","rc":[{"trd":[[6,3.13]],"ltp":6.0,"tv":292.32,"id":8858707},{"trd":[[1.2,15.61]],"batl":[[0,1.2,246.19]],"ltp":1.2,"tv":1841.35,"id":7587363}],"tv":2133.68}]}
{"op":"mcm","clk":"11999853092","pt":1725066541845,"mc":[{"id":"1.232459454","rc":[{"batb":[[1,1.13,253.58],[2,1.1,30.01]],"ltp":1.2,"tv":1841.35,"id":7587363}]}]}
{"op":"mcm","clk":"11999853381","pt":1725066546284,"mc":[{"id":"1.232459454","rc":[{"batb":[[0,1.17,41.84],[1,1.15,93.55],[2,1.13,253.58]],"ltp":1.2,"tv":1841.35,"id":7587363}]}]}
{"op":"mcm","clk":"11999853494","pt":1725066548060,"mc":[{"id":"1.232459454","rc":[{"batb":[[1,1.15,177.77]],"ltp":1.2,"tv":1841.35,"id":7587363}]}]}
{"op":"mcm","clk":"11999854627","pt":1725066566199,"mc":[{"id":"1.232459454","rc":[{"batb":[[1,1.13,253.58],[2,1.1,30.01]],"ltp":1.2,"tv":1841.35,"id":7587363}]}]}
{"op":"mcm","clk":"11999855222","pt":1725066576178,"mc":[{"id":"1.232459454","rc":[{"trd":[[6,3.97]],"batl":[[0,11,2.9]],"ltp":6.0,"tv":293.16,"id":8858707},{"trd":[[1.2,19.81]],"batl":[[0,1.2,241.99]],"ltp":1.2,"tv":1845.55,"id":7587363}],"tv":2138.72}]}
{"op":"mcm","clk":"11999855848","pt":1725066586781,"mc":[{"id":"1.232459454","rc":[{"trd":[[6,4.07]],"ltp":6.0,"tv":293.26,"id":8858707},{"trd":[[1.2,20.3]],"batl":[[0,1.2,241.5]],"ltp":1.2,"tv":1846.04,"id":7587363}],"tv":2139.31}]}
{"op":"mcm","clk":"11999856372","pt":1725066595206,"mc":[{"id":"1.232459454","rc":[{"trd":[[6,4.16]],"ltp":6.0,"tv":293.36,"id":8858707},{"trd":[[1.2,20.79]],"batl":[[0,1.2,241.01]],"ltp":1.2,"tv":1846.53,"id":7587363}],"tv":2139.89}]}
{"op":"mcm","clk":"11999856454","pt":1725066596504,"mc":[{"id":"1.232459454","rc":[{"batb":[[0,1.14,94.39]],"ltp":1.2,"tv":1846.53,"id":7587363}]}]}
{"op":"mcm","clk":"11999856902","pt":1725066603438,"mc":[{"id":"1.232459454","rc":[{"batb":[[2,4.5,24.81]],"ltp":6.0,"tv":293.36,"id":8858707},{"batb":[[0,1.17,500],[1,1.14,94.39],[2,1.13,253.58]],"ltp":1.2,"tv":1846.53,"id":7587363}]}]}
{"op":"mcm","clk":"11999857010","pt":1725066605137,"mc":[{"id":"1.232459454","rc":[{"batb":[[1,1.16,84.22],[2,1.14,94.39]],"ltp":1.2,"tv":1846.53,"id":7587363}]}]}
{"op":"mcm","clk":"11999859400","pt":1725066639044,"mc":[{"id":"1.232459454","rc":[{"trd":[[1.2,104.47]],"batb":[[2,1.13,253.58]],"batl":[[0,1.2,199.17]],"ltp":1.2,"tv":1930.21,"id":7587363}],"tv":2223.57}]}
{"op":"mcm","clk":"11999860517","pt":1725066655092,"mc":[{"id":"1.232459454","rc":[{"batb":[[0,6.8,1.52],[1,6,3.54],[2,5.9,3.61]],"ltp":6.0,"tv":293.36,"id":8858707}]}]}
{"op":"mcm","clk":"11999861363","pt":1725066667069,"mc":[{"id":"1.232459454","rc":[{"batb":[[0,6,3.54],[1,5.9,3.61],[2,5.6,4.45]],"ltp":6.0,"tv":293.36,"id":8858707}]}]}
{"op":"mcm","clk":"11999865405","pt":1725066718551,"mc":[{"id":"1.232459454","rc":[{"trd":[[6,4.36]],"batb":[[0,6,3.44]],"ltp":6.0,"tv":293.56,"id":8858707}],"tv":2223.77}]}
{"op":"mcm","clk":"11999868597","pt":1725066760994,"mc":[{"id":"1.232459454","rc":[{"trd":[[6,4.56]],"batb":[[0,6,3.34]],"ltp":6.0,"tv":293.76,"id":8858707}],"tv":2223.97}]}
{"op":"mcm","clk":"11999868704","pt":1725066762480,"mc":[{"id":"1.232459454","rc":[{"trd":[[6,4.76]],"batb":[[0,6,3.23]],"ltp":6.0,"tv":293.96,"id":8858707}],"tv":2224.17}]}
{"op":"mcm","clk":"11999869803","pt":1725066778996,"mc":[{"id":"1.232459454","rc":[{"trd":[[6,4.96]],"batb":[[0,6,3.13]],"ltp":6.0,"tv":294.15,"id":8858707}],"tv":2224.37}]}
{"op":"mcm","clk":"11999870144","pt":1725066784139,"mc":[{"id":"1.232459454","rc":[{"trd":[[1.17,8.1]],"batb":[[0,1.17,499.73]],"ltp":1.17,"tv":1930.75,"id":7587363}],"tv":2224.91}]}
{"op":"mcm","clk":"11999870194","pt":1725066784602,"mc":[{"id":"1.232459454","rc":[{"trd":[[6,5.16]],"batb":[[0,6,3.03]],"ltp":6.0,"tv":294.35,"id":8858707},{"batb":[[0,1.17,500]],"ltp":1.17,"tv":1930.75,"id":7587363}],"tv":2225.11}]}
{"op":"mcm","clk":"11999872230","pt":1725066813443,"mc":[{"id":"1.232459454","rc":[{"trd":[[6,5.36]],"batb":[[0,6,2.93]],"ltp":6.0,"tv":294.55,"id":8858707}],"tv":2225.31}]}
{"op":"mcm","clk":"11999872999","pt":1725066824554,"mc":[{"id":"1.232459454","rc":[{"batb":[[0,6.8,2.31],[1,6,2.93],[2,5.9,3.61]],"ltp":6.0,"tv":294.55,"id":8858707}]}]}
{"op":"mcm","clk":"11999873389","pt":1725066829965,"mc":[{"id":"1.232459454","rc":[{"batb":[[0,6,2.93],[1,5.9,3.61],[2,5.6,4.45]],"ltp":6.0,"tv":294.55,"id":8858707}]}]}
{"op":"mcm","clk":"11999873953","pt":1725066837894,"mc":[{"id":"1.232459454","rc":[{"trd":[[6,5.56]],"batb":[[0,6,2.83]],"ltp":6.0,"tv":294.75,"id":8858707}],"tv":2225.51}]}
{"op":"mcm","clk":"11999874427","pt":1725066845313,"mc":[{"id":"1.232459454","rc":[{"trd":[[1.2,106.3]],"batl":[[0,1.2,198.26]],"ltp":1.2,"tv":1932.58,"id":7587363}],"tv":2227.33}]}
{"op":"mcm","clk":"11999877244","pt":1725066886569,"mc":[{"id":"1.232459454","rc":[{"batl":[[0,14,2.9]],"ltp":6.0,"tv":294.75,"id":8858707}]}]}
{"op":"mcm","clk":"11999877339","pt":1725066887958,"mc":[{"id":"1.232459454","rc":[{"batl":[[0,12.5,2.9]],"ltp":6.0,"tv":294.75,"id":8858707}]}]}
{"op":"mcm","clk":"11999877799","pt":1725066895653,"mc":[{"id":"1.232459454","rc":[{"trd":[[6,5.74]],"batb":[[0,6,2.74]],"ltp":6.0,"tv":294.93,"id":8858707}],"tv":2227.52}]}
{"op":"mcm","clk":"11999878200","pt":1725066901297,"mc":[{"id":"1.232459454","rc":[{"trd":[[6.2,4.62]],"ltp":6.2,"tv":299.55,"id":8858707}],"tv":2232.13}]}
{"op":"mcm","clk":"11999878335","pt":1725066903256,"mc":[{"id":"1.232459454","rc":[{"batb":[[0,4.5,24.81],[1,3,10.62],[2,2.06,84.39]],"ltp":6.2,"tv":299.55,"id":8858707},{"batb":[[1,1.13,169.36],[2,1.1,30.01]],"ltp":1.2,"tv":1932.58,"id":7587363}]}]}
{"op":"mcm","clk":"11999879137","pt":1725066913280,"mc":[{"id":"1.232459454","rc":[{"trd":[[1.17,32.56]],"batb":[[0,1.17,487.77]],"ltp":1.17,"tv":1957.04,"id":7587363}],"tv":2256.59}]}
{"op":"mcm","clk":"11999879296","pt":1725066915399,"mc":[{"id":"1.232459454","rc":[{"batb":[[0,1.17,500]],"ltp":1.17,"tv":1957.04,"id":7587363}]}]}
{"op":"mcm","clk":"11999881020","pt":1725066940336,"mc":[{"id":"1.232459454","rc":[{"batl":[[0,6.2,1.09],[1,12.5,2.9]],"ltp":6.2,"tv":299.55,"id":8858707}]}]}
{"op":"mcm","clk":"11999881230","pt":1725066943109,"mc":[{"id":"1.232459454","rc":[{"batl":[[1,11,2.9]],"ltp":6.2,"tv":299.55,"id":8858707}]}]}
{"op":"mcm","clk":"11999881619","pt":1725066948306,"mc":[{"id":"1.232459454","rc":[{"batl":[[0,11,2.9],[1,11,0]],"ltp":6.2,"tv":299.55,"id":8858707}]}]}
{"op":"mcm","clk":"11999881817","pt":1725066950923,"mc":[{"id":"1.232459454","rc":[{"batb":[[0,6.4,16.08]],"ltp":6.2,"tv":299.55,"id":8858707},{"batb":[[0,1.15,374.23],[1,1.14,500],[2,1.13,169.36]],"ltp":1.17,"tv":1957.04,"id":7587363}]}]}
{"op":"mcm","clk":"11999883768","pt":1725066977553,"mc":[{"id":"1.232459454","rc":[{"trd":[[6.4,0.02]],"batb":[[0,6.4,16.07]],"ltp":6.4,"tv":299.57,"id":8858707}],"tv":2256.61}]}
{"op":"mcm","clk":"11999884021","pt":1725066980945,"mc":[{"id":"1.232459454","rc":[{"batb":[[0,6.4,16.08]],"ltp":6.4,"tv":299.57,"id":8858707}]}]}
{"op":"mcm","clk":"11999884278","pt":1725066984443,"mc":[{"id":"1.232459454","rc":[{"batl":[[0,1.17,333],[1,1.2,198.26],[2,1.21,80.82]],"ltp":1.17,"tv":1957.04,"id":7587363}]}]}
{"op":"mcm","clk":"11999885819","pt":1725067004285,"mc":[{"id":"1.232459454","rc":[{"trd":[[6.8,0.84]],"ltp":6.8,"tv":300.41,"id":8858707},{"trd":[[1.17,37.44]],"batl":[[0,1.17,328.12]],"ltp":1.17,"tv":1961.92,"id":7587363}],"tv":2262.33}]}
{"op":"mcm","clk":"11999886796","pt":1725067016599,"mc":[{"id":"1.232459454","rc":[{"trd":[[6.8,1.06]],"ltp":6.8,"tv":300.63,"id":8858707},{"trd":[[1.17,38.71]],"batl":[[0,1.17,326.85]],"ltp":1.17,"tv":1963.19,"id":7587363}],"tv":2263.82}]}
{"op":"mcm","clk":"11999886986","pt":1725067019216,"mc":[{"id":"1.232459454","rc":[{"trd":[[7.4,2.18]],"batb":[[0,6.6,3.16],[1,6.4,16.08],[2,3,10.62]],"batl":[[0,7.4,57.64],[1,11,2.9]],"ltp":7.4,"tv":302.8,"id":8858707},{"batb":[[0,1.14,584.22],[1,1.13,169.36],[2,1.1,30.01]],"ltp":1.17,"tv":1963.19,"id":7587363}],"tv":2266.0}]}
{"op":"mcm","clk":"11999887136","pt":1725067021416,"mc":[{"id":"1.232459454","rc":[{"trd":[[6.8,1.16]],"ltp":6.8,"tv":302.9,"id":8858707},{"trd":[[1.17,39.28]],"batl":[[0,1.17,326.28]],"ltp":1.17,"tv":1963.76,"id":7587363}],"tv":2266.66}]}
{"op":"mcm","clk":"11999887432","pt":1725067025298,"mc":[{"id":"1.232459454","rc":[{"trd":[[1.17,53.01]],"batl":[[0,1.17,319.41]],"ltp":1.17,"tv":1977.49,"id":7587363}],"tv":2280.4}]}
{"op":"mcm","clk":"11999887705","pt":1725067028725,"mc":[{"id":"1.232459454","rc":[{"trd":[[6.8,1.25]],"ltp":6.8,"tv":303.0,"id":8858707},{"trd":[[1.17,53.58]],"batl":[[0,1.17,318.84]],"ltp":1.17,"tv":1978.06,"id":7587363}],"tv":2281.07}]}
{"op":"mcm","clk":"11999888098","pt":1725067033304,"mc":[{"id":"1.232459454","rc":[{"trd":[[6.8,1.35]],"ltp":6.8,"tv":303.1,"id":8858707},{"trd":[[1.17,54.15]],"batl":[[0,1.17,318.27]],"ltp":1.17,"tv":1978.63,"id":7587363}],"tv":2281.74}]}
{"op":"mcm","clk":"11999889721","pt":1725067053510,"mc":[{"id":"1.232459454","rc":[{"trd":[[1.17,70.91]],"batl":[[0,1.17,309.89]],"ltp":1.17,"tv":1995.39,"id":7587363}],"tv":2298.5}]}
{"op":"mcm","clk":"11999891562","pt":1725067075652,"mc":[{"id":"1.232459454","rc":[{"trd":[[6.8,2.06]],"ltp":6.8,"tv":303.81,"id":8858707},{"trd":[[1.17,75.03]],"batl":[[0,1.17,305.77]],"ltp":1.17,"tv":1999.51,"id":7587363}],"tv":2303.32}]}
{"op":"mcm","clk":"11999891761","pt":1725067078159,"mc":[{"id":"1.232459454","rc":[{"trd":[[7.4,8.68]],"batl":[[0,11,2.9],[1,11,0]],"ltp":7.4,"tv":310.31,"id":8858707},{"trd":[[1.15,41.84]],"ltp":1.15,"tv":2041.35,"id":7587363}],"tv":2351.66}]}
{"op":"mcm","clk":"11999891797","pt":1725067078672,"mc":[{"id":"1.232459454","rc":[{"batb":[[0,1.14,982.71]],"ltp":1.15,"tv":2041.35,"id":7587363}]}]}
{"op":"mcm","clk":"11999896458","pt":1725067137515,"mc":[{"id":"1.232459454","rc":[{"trd":[[6.8,2.16]],"ltp":6.8,"tv":310.4,"id":8858707},{"trd":[[1.17,75.6]],"batl":[[0,1.17,305.2]],"ltp":1.17,"tv":2041.92,"id":7587363}],"tv":2352.33}]}
{"op":"mcm","clk":"11999899116","pt":1725067169685,"mc":[{"id":"1.232459454","rc":[{"batb":[[0,1.15,12.39],[1,1.14,982.71],[2,1.13,169.36]],"ltp":1.17,"tv":2041.92,"id":7587363}]}]}
{"op":"mcm","clk":"11999899681","pt":1725067176465,"mc":[{"id":"1.232459454","rc":[{"batl":[[1,14,0.07]],"ltp":6.8,"tv":310.4,"id":8858707}]}]}
{"op":"mcm","clk":"11999900902","pt":1725067192373,"mc":[{"id":"1.232459454","rc":[{"batb":[[2,1.13,2]],"ltp":1.17,"tv":2041.92,"id":7587363}]}]}
{"op":"mcm","clk":"11999900921","pt":1725067192579,"mc":[{"id":"1.232459454","rc":[{"batb":[[1,1.14,584.22]],"ltp":1.17,"tv":2041.92,"id":7587363}]}]}
{"op":"mcm","clk":"11999901504","pt":1725067200101,"mc":[{"id":"1.232459454","rc":[{"trd":[[1.17,82.3]],"batl":[[0,1.17,301.85]],"ltp":1.17,"tv":2048.62,"id":7587363}],"tv":2359.03}]}
{"op":"mcm","clk":"11999902349","pt":1725067210077,"mc":[{"id":"1.232459454","rc":[{"trd":[[7.6,2.18]],"batl":[[0,11,2.06]],"ltp":7.6,"tv":312.58,"id":8858707}],"tv":2361.21}]}
{"op":"mcm","clk":"11999902830","pt":1725067215502,"mc":[{"id":"1.232459454","rc":[{"trd":[[1.17,96.42]],"batl":[[0,1.17,294.79]],"ltp":1.17,"tv":2062.74,"id":7587363}],"tv":2375.32}]}
{"op":"mcm","clk":"11999903730","pt":1725067226932,"mc":[{"id":"1.232459454","rc":[{"trd":[[6.8,2.26]],"ltp":6.8,"tv":312.68,"id":8858707},{"trd":[[1.17,96.99]],"batl":[[0,1.17,294.22]],"ltp":1.17,"tv":2063.31,"id":7587363}],"tv":2375.99}]}
{"op":"mcm","clk":"11999903805","pt":1725067227917,"mc":[{"id":"1.232459454","rc":[{"batb":[[0,1.15,14.51],[1,1.14,982.71]],"ltp":1.17,"tv":2063.31,"id":7587363}]}]}
{"op":"mcm","clk":"11999905701","pt":1725067252286,"mc":[{"id":"1.232459454","rc":[{"batb":[[0,6.8,14.97],[1,6.6,3.16]],"ltp":6.8,"tv":312.68,"id":8858707},{"batb":[[1,1.14,482.71],[2,1.13,502]],"ltp":1.17,"tv":2063.31,"id":7587363}]}]}
{"op":"mcm","clk":"11999905757","pt":1725067252955,"mc":[{"id":"1.232459454","rc":[{"batb":[[1,1.13,586.22],[2,1.1,30.01]],"ltp":1.17,"tv":2063.31,"id":7587363}]}]}
{"op":"mcm","clk":"11999907366","pt":1725067274091,"mc":[{"id":"1.232459454","rc":[{"trd":[[6.8,2.45]],"batb":[[0,6.8,14.87]],"ltp":6.8,"tv":312.87,"id":8858707}],"tv":2376.19}]}
{"op":"mcm","clk":"11999907639","pt":1725067277379,"mc":[{"id":"1.232459454","rc":[{"trd":[[6.8,2.65]],"batb":[[0,6.8,14.97]],"ltp":6.8,"tv":313.07,"id":8858707}],"tv":2376.39}]}
{"op":"mcm","clk":"11999909478","pt":1725067303083,"mc":[{"id":"1.232459454","rc":[{"trd":[[6.8,2.85]],"batb":[[0,6.8,14.87]],"ltp":6.8,"tv":313.27,"id":8858707}],"tv":2376.58}]}
{"op":"mcm","clk":"11999909759","pt":1725067307820,"mc":[{"id":"1.232459454","rc":[{"batb":[[0,6.8,14.97]],"ltp":6.8,"tv":313.27,"id":8858707}]}]}
{"op":"mcm","clk":"11999909952","pt":1725067311114,"mc":[{"id":"1.232459454","rc":[{"trd":[[1.17,105.37]],"batl":[[0,1.17,290.03]],"ltp":1.17,"tv":2071.69,"id":7587363}],"tv":2384.96}]}
{"op":"mcm","clk":"11999909978","pt":1725067311522,"mc":[{"id":"1.232459454","rc":[{"trd":[[6.8,3.67]],"batb":[[0,6.8,14.56]],"ltp":6.8,"tv":314.09,"id":8858707}],"tv":2385.78}]}
{"op":"mcm","clk":"11999910067","pt":1725067312809,"mc":[{"id":"1.232459454","rc":[{"batb":[[0,6.8,14.97]],"ltp":6.8,"tv":314.09,"id":8858707}]}]}
{"op":"mcm","clk":"11999911855","pt":1725067338955,"mc":[{"id":"1.232459454","rc":[{"batb":[[0,1.14,398.49],[1,1.13,600.74]],"ltp":1.17,"tv":2071.69,"id":7587363}]}]}
{"op":"mcm","clk":"11999912461","pt":1725067348073,"mc":[{"id":"1.232459454","rc":[{"batb":[[0,1.15,14.51],[1,1.14,398.49],[2,1.13,586.22]],"ltp":1.17,"tv":2071.69,"id":7587363}]}]}
{"op":"mcm","clk":"11999912528","pt":1725067349050,"mc":[{"id":"1.232459454","rc":[{"batb":[[1,1.14,482.71]],"ltp":1.17,"tv":2071.69,"id":7587363}]}]}
{"op":"mcm","clk":"11999913162","pt":1725067359289,"mc":[{"id":"1.232459454","rc":[{"trd":[[1.17,105.57]],"batl":[[0,1.17,289.93]],"ltp":1.17,"tv":2071.89,"id":7587363}],"tv":2385.98}]}
{"op":"mcm","clk":"11999913215","pt":1725067360164,"mc":[{"id":"1.232459454","rc":[{"batb":[[1,1.13,586.22],[2,1.1,30.01]],"ltp":1.17,"tv":2071.89,"id":7587363}]}]}
{"op":"mcm","clk":"11999913712","pt":1725067367673,"mc":[{"id":"1.232459454","rc":[{"batb":[[2,3,14.74]],"batl":[[0,10.5,2.06],[1,11,2.06],[2,14,0.07]],"ltp":6.8,"tv":314.09,"id":8858707}]}]}
{"op":"mcm","clk":"11999916389","pt":1725067409329,"mc":[{"id":"1.232459454","rc":[{"trd":[[1.17,106.67]],"batl":[[0,1.17,289.38]],"ltp":1.17,"tv":2072.99,"id":7587363}],"tv":2387.08}]}
{"op":"mcm","clk":"11999916729","pt":1725067414742,"mc":[{"id":"1.232459454","rc":[{"trd":[[6.8,3.87]],"batb":[[0,6.8,14.87]],"ltp":6.8,"tv":314.29,"id":8858707}],"tv":2387.28}]}
{"op":"mcm","clk":"11999916930","pt":1725067418344,"mc":[{"id":"1.232459454","rc":[{"batb":[[0,6.8,14.97]],"ltp":6.8,"tv":314.29,"id":8858707}]}]}
{"op":"mcm","clk":"11999917082","pt":1725067420457,"mc":[{"id":"1.232459454","rc":[{"batl":[[0,1.17,466.38]],"ltp":1.17,"tv":2072.99,"id":7587363}]}]}
{"op":"mcm","clk":"11999917477","pt":1725067426225,"mc":[{"id":"1.232459454","rc":[{"trd":[[1.15,42.21]],"batb":[[0,1.15,14.33]],"ltp":1.15,"tv":2073.35,"id":7587363}],"tv":2387.65}]}
{"op":"mcm","clk":"11999918403","pt":1725067438552,"mc":[{"id":"1.232459454","rc":[{"trd":[[6.8,4.06]],"batb":[[0,6.8,14.87]],"ltp":6.8,"tv":314.49,"id":8858707}],"tv":2387.85}]}
{"op":"mcm","clk":"11999918735","pt":1725067443355,"mc":[{"id":"1.232459454","rc":[{"batb":[[0,6.8,29.84]],"ltp":6.8,"tv":314.49,"id":8858707},{"trd":[[1.17,115.05]],"batl":[[0,1.17,462.19]],"ltp":1.17,"tv":2081.73,"id":7587363}],"tv":2396.23}]}
{"op":"mcm","clk":"11999918741","pt":1725067443454,"mc":[{"id":"1.232459454","rc":[{"batb":[[0,6.8,14.97]],"ltp":6.8,"tv":314.49,"id":8858707}]}]}
{"op":"mcm","clk":"11999920952","pt":1725067476610,"mc":[{"id":"1.232459454","rc":[{"trd":[[6.8,4.26]],"batb":[[0,6.8,14.87]],"ltp":6.8,"tv":314.68,"id":8858707}],"tv":2396.42}]}
{"op":"mcm","clk":"11999921065","pt":1725067478475,"mc":[{"id":"1.232459454","rc":[{"batb":[[0,6.8,14.97]],"ltp":6.8,"tv":314.68,"id":8858707}]}]}
{"op":"mcm","clk":"11999921244","pt":1725067481100,"mc":[{"id":"1.232459454","rc":[{"trd":[[1.17,115.69]],"batl":[[0,1.17,461.87]],"ltp":1.17,"tv":2082.37,"id":7587363}],"tv":2397.06}]}
{"op":"mcm","clk":"11999921535","pt":1725067485721,"mc":[{"id":"1.232459454","rc":[{"trd":[[6.8,5.94]],"batb":[[0,6.8,14.13]],"ltp":6.8,"tv":316.36,"id":8858707}],"tv":2398.74}]}
{"op":"mcm","clk":"11999921751","pt":1725067488601,"mc":[{"id":"1.232459454","rc":[{"batb":[[0,6.8,14.97]],"ltp":6.8,"tv":316.36,"id":8858707}]}]}
{"op":"mcm","clk":"11999922517","pt":1725067501112,"mc":[{"id":"1.232459454","rc":[{"trd":[[7.8,5.95]],"batb":[[0,7.8,1.07],[1,6.8,18.02],[2,6.6,3.16]],"ltp":7.8,"tv":322.31,"id":8858707},{"trd":[[1.15,56.54]],"batb":[[0,1.13,586.22],[1,1.1,30.01],[2,1.09,168.45]],"ltp":1.15,"tv":2096.7,"id":7587363}],"tv":2419.02}]}
{"op":"mcm","clk":"11999922551","pt":1725067501522,"mc":[{"id":"1.232459454","rc":[{"trd":[[7.8,8.09]],"batb":[[0,6.8,18.02],[1,6.6,3.16],[2,3,14.74]],"ltp":7.8,"tv":324.45,"id":8858707},{"batb":[[0,1.13,1012.21]],"ltp":1.15,"tv":2096.7,"id":7587363}],"tv":2421.16}]}
{"op":"mcm","clk":"11999923456","pt":1725067512444,"mc":[{"id":"1.232459454","rc":[{"batb":[[0,1.14,83.77],[1,1.13,1012.21],[2,1.1,30.01]],"ltp":1.15,"tv":2096.7,"id":7587363}]}]}
{"op":"mcm","clk":"11999925130","pt":1725067535440,"mc":[{"id":"1.232459454","rc":[{"batb":[[1,1.13,586.22]],"ltp":1.15,"tv":2096.7,"id":7587363}]}]}
{"op":"mcm","clk":"11999925437","pt":1725067540479,"mc":[{"id":"1.232459454","rc":[{"trd":[[1.14,8.32]],"batb":[[0,1.14,79.61]],"ltp":1.14,"tv":2105.03,"id":7587363}],"tv":2429.49}]}
{"op":"mcm","clk":"11999926131","pt":1725067550661,"mc":[{"id":"1.232459454","rc":[{"trd":[[6.8,6.4]],"batb":[[0,6.8,17.79]],"ltp":6.8,"tv":324.91,"id":8858707}],"tv":2429.94}]}
{"op":"mcm","clk":"11999926332","pt":1725067553863,"mc":[{"id":"1.232459454","rc":[{"batb":[[0,6.8,18.02]],"ltp":6.8,"tv":324.91,"id":8858707}]}]}
{"op":"mcm","clk":"11999928320","pt":1725067581101,"mc":[{"id":"1.232459454","rc":[{"trd":[[6.8,6.6]],"batb":[[0,6.8,17.92]],"ltp":6.8,"tv":325.11,"id":8858707}],"tv":2430.14}]}
{"op":"mcm","clk":"11999929808","pt":1725067601141,"mc":[{"id":"1.232459454","rc":[{"trd":[[6.8,6.8]],"batb":[[0,6.8,17.82]],"ltp":6.8,"tv":325.31,"id":8858707}],"tv":2430.34}]}
{"op":"mcm","clk":"11999930829","pt":1725067614757,"mc":[{"id":"1.232459454","rc":[{"batb":[[0,1.15,4.19],[1,1.14,79.61],[2,1.13,586.22]],"ltp":1.14,"tv":2105.03,"id":7587363}]}]}
{"op":"mcm","clk":"11999931451","pt":1725067622077,"mc":[{"id":"1.232459454","rc":[{"trd":[[6.8,7]],"batb":[[0,6.8,17.72]],"ltp":6.8,"tv":325.51,"id":8858707}],"tv":2430.54}]}
{"op":"mcm","clk":"11999933689","pt":1725067654707,"mc":[{"id":"1.232459454","rc":[{"batb":[[1,1.13,586.22],[2,1.1,30.01]],"ltp":1.14,"tv":2105.03,"id":7587363}]}]}
{"op":"mcm","clk":"11999934129","pt":1725067662650,"mc":[{"id":"1.232459454","rc":[{"trd":[[6.8,7.36]],"batb":[[0,6.8,17.53]],"ltp":6.8,"tv":325.88,"id":8858707}],"tv":2430.91}]}
{"op":"mcm","clk":"11999934389","pt":1725067667309,"mc":[{"id":"1.232459454","rc":[{"trd":[[7.8,8.71],[8.6,0.12]],"ltp":8.6,"tv":326.62,"id":8858707},{"trd":[[1.15,60.73]],"batb":[[0,1.13,586.22],[1,1.1,30.01],[2,1.09,168.45]],"ltp":1.15,"tv":2109.22,"id":7587363}],"tv":2435.84}]}
{"op":"mcm","clk":"11999934395","pt":1725067667413,"mc":[{"id":"1.232459454","rc":[{"batb":[[0,1.13,1012.21]],"ltp":1.15,"tv":2109.22,"id":7587363}]}]}
{"op":"mcm","clk":"11999934576","pt":1725067671315,"mc":[{"id":"1.232459454","rc":[{"trd":[[1.17,124.83]],"batl":[[0,1.17,457.3]],"ltp":1.17,"tv":2118.35,"id":7587363}],"tv":2444.97}]}
{"op":"mcm","clk":"11999935717","pt":1725067691027,"mc":[{"id":"1.232459454","rc":[{"trd":[[8.4,4.62]],"ltp":8.4,"tv":331.23,"id":8858707}],"tv":2449.59}]}
{"op":"mcm","clk":"11999936205","pt":1725067698676,"mc":[{"id":"1.232459454","rc":[{"trd":[[1.17,157.97]],"batl":[[0,1.17,440.73]],"ltp":1.17,"tv":2151.49,"id":7587363}],"tv":2482.73}]}
{"op":"mcm","clk":"11999936741","pt":1725067708158,"mc":[{"id":"1.232459454","rc":[{"batb":[[2,1.07,168.45]],"ltp":1.17,"tv":2151.49,"id":7587363}]}]}
{"op":"mcm","clk":"11999938677","pt":1725067740081,"mc":[{"id":"1.232459454","rc":[{"batb":[[2,3,6.5]],"batl":[[0,14,0.07],[1,11,0],[2,14,0]],"ltp":8.4,"tv":331.23,"id":8858707}]}]}
{"op":"mcm","clk":"11999939898","pt":1725067760040,"mc":[{"id":"1.232459454","rc":[{"trd":[[6.8,7.56]],"batb":[[0,6.8,17.43]],"ltp":6.8,"tv":331.43,"id":8858707}],"tv":2482.93}]}
{"op":"mcm","clk":"11999941370","pt":1725067787266,"mc":[{"id":"1.232459454","rc":[{"batb":[[0,8.6,1.52],[1,6.8,17.43],[2,6.6,3.16]],"ltp":6.8,"tv":331.43,"id":8858707}]}]}
{"op":"mcm","clk":"11999941392","pt":1725067787673,"mc":[{"id":"1.232459454","rc":[{"trd":[[8.6,3.17]],"batb":[[0,6.8,17.43],[1,6.6,3.16],[2,3,6.5]],"ltp":8.6,"tv":334.49,"id":8858707}],"tv":2485.98}]}
{"op":"mcm","clk":"11999941543","pt":1725067790091,"mc":[{"id":"1.232459454","rc":[{"batb":[[0,6.8,2.46],[1,6.6,18.67]],"ltp":8.6,"tv":334.49,"id":8858707}]}]}
{"op":"mcm","clk":"11999941929","pt":1725067797891,"mc":[{"id":"1.232459454","rc":[{"trd":[[1.17,159]],"batl":[[0,1.17,440.21]],"ltp":1.17,"tv":2152.53,"id":7587363}],"tv":2487.02}]}
{"op":"mcm","clk":"11999942059","pt":1725067800217,"mc":[{"id":"1.232459454","rc":[{"batb":[[0,1.13,586.22]],"ltp":1.17,"tv":2152.53,"id":7587363}]}]}
{"op":"mcm","clk":"11999942270","pt":1725067802804,"mc":[{"id":"1.232459454","marketDefinition":{"bspMarket":false,"turnInPlayEnabled":true,"persistenceEnabled":true,"marketBaseRate":5.0,"eventId":"33540029","eventTypeId":"4","numberOfWinners":1,"bettingType":"ODDS","marketType":"MATCH_ODDS","marketTime":"2024-08-31T01:30:00.000Z","suspendTime":"2024-08-31T01:30:00.000Z","bspReconciled":false,"complete":true,"inPlay":false,"crossMatching":true,"runnersVoidable":false,"numberOfActiveRunners":2,"betDelay":0,"status":"SUSPENDED","runners":[{"status":"ACTIVE","sortPriority":1,"id":8858707,"name":"Maldives"},{"status":"ACTIVE","sortPriority":2,"id":7587363,"name":"Singapore"}],"regulators":["MR_INT"],"countryCode":"GB","discountAllowed":true,"timezone":"GMT","openDate":"2024-08-31T01:30:00.000Z","version":6109185507,"name":"Match Odds","eventName":"Maldives v Singapore"},"rc":[{"batb":[[0,6.6,15.51],[1,3,6.5],[2,2.44,42.28]],"ltp":8.6,"tv":334.49,"id":8858707},{"batb":[[0,1.13,502]],"ltp":1.17,"tv":2152.53,"id":7587363}]}]}
{"op":"mcm","clk":"11999942352","pt":1725067803903,"mc":[{"id":"1.232459454","marketDefinition":{"bspMarket":false,"turnInPlayEnabled":true,"persistenceEnabled":true,"marketBaseRate":5.0,"eventId":"33540029","eventTypeId":"4","numberOfWinners":1,"bettingType":"ODDS","marketType":"MATCH_ODDS","marketTime":"2024-08-31T01:30:00.000Z","suspendTime":"2024-08-31T01:30:00.000Z","bspReconciled":false,"complete":true,"inPlay":true,"crossMatching":true,"runnersVoidable":false,"numberOfActiveRunners":2,"betDelay":5,"status":"OPEN","runners":[{"status":"ACTIVE","sortPriority":1,"id":8858707,"name":"Maldives"},{"status":"ACTIVE","sortPriority":2,"id":7587363,"name":"Singapore"}],"regulators":["MR_INT"],"countryCode":"GB","discountAllowed":true,"timezone":"GMT","openDate":"2024-08-31T01:30:00.000Z","version":6109185559,"name":"Match Odds","eventName":"Maldives v Singapore"},"rc":[{"batb":[[0,3,6.5],[1,2.44,42.28],[2,2.28,42.11]],"ltp":8.6,"tv":334.49,"id":8858707},{"batb":[[0,1.13,2],[1,1.07,168.45],[2,1.05,168.45]],"batl":[[0,2.6,3.02],[1,1.2,0],[2,1.21,0]],"ltp":1.17,"tv":2152.53,"id":7587363}]}]}
{"op":"mcm","clk":"11999942704","pt":1725067809004,"mc":[{"id":"1.232459454","rc":[{"batb":[[0,1.14,4.19],[1,1.13,2],[2,1.07,168.45]],"ltp":1.17,"tv":2152.53,"id":7587363}]}]}
{"op":"mcm","clk":"11999942780","pt":1725067810082,"mc":[{"id":"1.232459454","rc":[{"batl":[[1,1000,3.09]],"ltp":1.17,"tv":2152.53,"id":7587363}]}]}
{"op":"mcm","clk":"11999942856","pt":1725067811005,"mc":[{"id":"1.232459454","rc":[{"batl":[[1,1000,0.52]],"ltp":1.17,"tv":2152.53,"id":7587363}]}]}
{"op":"mcm","clk":"11999942918","pt":1725067811929,"mc":[{"id":"1.232459454","rc":[{"batl":[[1,1000,0]],"ltp":1.17,"tv":2152.53,"id":7587363}]}]}
{"op":"mcm","clk":"11999943298","pt":1725067817034,"mc":[{"id":"1.232459454","rc":[{"batl":[[0,2.6,3.53]],"ltp":1.17,"tv":2152.53,"id":7587363}]}]}
{"op":"mcm","clk":"11999943866","pt":1725067825313,"mc":[{"id":"1.232459454","rc":[{"batl":[[0,1.45,42.41],[1,2.6,3.02]],"ltp":1.17,"tv":2152.53,"id":7587363}]}]}
{"op":"mcm","clk":"11999944297","pt":1725067831640,"mc":[{"id":"1.232459454","rc":[{"trd":[[3.2,3.98],[5.5,0.11]],"ltp":3.2,"tv":338.58,"id":8858707},{"trd":[[1.22,8.9],[1.45,8.77]],"batl":[[0,1.45,33.12]],"ltp":1.45,"tv":2161.81,"id":7587363}],"tv":2500.39}]}
{"op":"mcm","clk":"11999944513","pt":1725067835035,"mc":[{"id":"1.232459454","rc":[{"batl":[[0,1.4,4.19],[1,1.45,33.12],[2,2.6,3.02]],"ltp":1.45,"tv":2161.81,"id":7587363}]}]}
{"op":"mcm","clk":"11999945416","pt":1725067849172,"mc":[{"id":"1.232459454","rc":[{"batl":[[0,15,0.91]],"ltp":3.2,"tv":338.58,"id":8858707}]}]}
{"op":"mcm","clk":"11999945459","pt":1725067849738,"mc":[{"id":"1.232459454","rc":[{"batb":[[0,1.15,50.27],[1,1.14,4.19],[2,1.13,2]],"batl":[[0,1.38,41.89],[1,1.4,4.19],[2,1.45,33.12]],"ltp":1.45,"tv":2161.81,"id":7587363}]}]}
{"op":"mcm","clk":"11999945791","pt":1725067854681,"mc":[{"id":"1.232459454","rc":[{"trd":[[3.6,0.1]],"ltp":3.6,"tv":338.67,"id":8858707},{"trd":[[1.38,0.25]],"batl":[[0,1.38,41.64]],"ltp":1.38,"tv":2162.06,"id":7587363}],"tv":2500.74}]}
{"op":"mcm","clk":"11999945872","pt":1725067855766,"mc":[{"id":"1.232459454","rc":[{"batl":[[2,2.6,3.02]],"ltp":1.38,"tv":2162.06,"id":7587363}]}]}
{"op":"mcm","clk":"11999946000","pt":1725067857868,"mc":[{"id":"1.232459454","rc":[{"batb":[[0,7,1.52],[1,3,6.5],[2,2.44,42.28]],"ltp":3.6,"tv":338.67,"id":8858707}]}]}
{"op":"mcm","clk":"11999946224","pt":1725067861463,"mc":[{"id":"1.232459454","rc":[{"batb":[[0,1.16,10.53],[1,1.15,50.27],[2,1.14,4.19]],"ltp":1.38,"tv":2162.06,"id":7587363}]}]}
{"op":"mcm","clk":"11999946912","pt":1725067871299,"mc":[{"id":"1.232459454","rc":[{"trd":[[7,1.52]],"batb":[[0,3,6.5],[1,2.44,42.28],[2,2.28,42.11]],"ltp":7.0,"tv":340.2,"id":8858707},{"trd":[[1.17,168.11]],"batb":[[0,1.17,48.7],[1,1.16,10.53],[2,1.15,50.27]],"ltp":1.17,"tv":2171.17,"id":7587363}],"tv":2511.37}]}
{"op":"mcm","clk":"11999947623","pt":1725067882414,"mc":[{"id":"1.232459454","rc":[{"batb":[[0,3.6,7.21],[1,3,6.5],[2,2.44,42.28]],"batl":[[0,12.5,2.06],[1,15,0.91]],"ltp":7.0,"tv":340.2,"id":8858707}]}]}
{"op":"mcm","clk":"11999947802","pt":1725067885386,"mc":[{"id":"1.232459454","rc":[{"batb":[[1,1.15,50.27],[2,1.14,4.19]],"ltp":1.17,"tv":2171.17,"id":7587363}]}]}
{"op":"mcm","clk":"11999947871","pt":1725067887328,"mc":[{"id":"1.232459454","rc":[{"batb":[[0,1.17,47.03]],"ltp":1.17,"tv":2171.17,"id":7587363}]}]}
{"op":"mcm","clk":"11999948024","pt":1725067889998,"mc":[{"id":"1.232459454","rc":[{"trd":[[3.6,5.87]],"batb":[[0,3.6,4.33]],"ltp":3.6,"tv":345.97,"id":8858707}],"tv":2517.15}]}
{"op":"mcm","clk":"11999948537","pt":1725067897530,"mc":[{"id":"1.232459454","rc":[{"batb":[[0,3,6.5],[1,2.44,42.28],[2,2.28,42.11]],"batl":[[0,15,0.91],[1,15,0]],"ltp":3.6,"tv":345.97,"id":8858707}]}]}
{"op":"mcm","clk":"11999948767","pt":1725067901650,"mc":[{"id":"1.232459454","rc":[{"batl":[[0,1.36,4.19],[1,1.38,41.64],[2,1.4,4.19]],"ltp":1.17,"tv":2171.17,"id":7587363}]}]}
{"op":"mcm","clk":"11999948913","pt":1725067903858,"mc":[{"id":"1.232459454","rc":[{"trd":[[1.36,0.04]],"batl":[[0,1.36,4.17]],"ltp":1.36,"tv":2171.21,"id":7587363}],"tv":2517.18}]}
{"op":"mcm","clk":"11999949363","pt":1725067911454,"mc":[{"id":"1.232459454","rc":[{"batl":[[1,1.4,4.19],[2,2.6,3.02]],"ltp":1.36,"tv":2171.21,"id":7587363}]}]}
{"op":"mcm","clk":"11999949479","pt":1725067913959,"mc":[{"id":"1.232459454","rc":[{"batb":[[0,3,7.18]],"ltp":3.6,"tv":345.97,"id":8858707}]}]}
{"op":"mcm","clk":"11999949553","pt":1725067915344,"mc":[{"id":"1.232459454","rc":[{"batb":[[0,3,6.5]],"ltp":3.6,"tv":345.97,"id":8858707}]}]}
{"op":"mcm","clk":"11999949625","pt":1725067916527,"mc":[{"id":"1.232459454","rc":[{"batl":[[0,1.35,41.64],[1,1.36,4.17],[2,1.4,4.19]],"ltp":1.36,"tv":2171.21,"id":7587363}]}]}
{"op":"mcm","clk":"11999949828","pt":1725067920533,"mc":[{"id":"1.232459454","rc":[{"batb":[[0,3.55,3.61],[1,3,6.5],[2,2.44,42.28]],"batl":[[0,12,2.06],[1,15,0.91]],"ltp":3.6,"tv":345.97,"id":8858707}]}]}
{"op":"mcm","clk":"11999950065","pt":1725067925353,"mc":[{"id":"1.232459454","rc":[{"batb":[[0,1.17,47.13]],"ltp":1.36,"tv":2171.21,"id":7587363}]}]}
{"op":"mcm","clk":"11999950193","pt":1725067927668,"mc":[{"id":"1.232459454","rc":[{"batb":[[0,3,6.5],[1,2.44,42.28],[2,2.28,42.11]],"batl":[[0,15,0.91],[1,15,0]],"ltp":3.6,"tv":345.97,"id":8858707}]}]}
{"op":"mcm","clk":"11999950698","pt":1725067936178,"mc":[{"id":"1.232459454","rc":[{"batb":[[0,1.17,41.26]],"ltp":1.36,"tv":2171.21,"id":7587363}]}]}
{"op":"mcm","clk":"11999950764","pt":1725067937359,"mc":[{"id":"1.232459454","rc":[{"batb":[[1,1.15,50.45]],"ltp":1.36,"tv":2171.21,"id":7587363}]}]}
{"op":"mcm","clk":"11999950999","pt":1725067941272,"mc":[{"id":"1.232459454","rc":[{"trd":[[6,5.76]],"batb":[[0,6.8,1.07],[1,5.6,1.52],[2,3,6.5]],"ltp":6.0,"tv":345.99,"id":8858707},{"trd":[[1.2,106.39]],"batb":[[0,1.17,41.16]],"ltp":1.2,"tv":2171.31,"id":7587363}],"tv":2517.3}]}
{"op":"mcm","clk":"11999951257","pt":1725067944980,"mc":[{"id":"1.232459454","rc":[{"batb":[[0,5.6,1.52],[1,3,6.5],[2,2.44,42.28]],"ltp":6.0,"tv":345.99,"id":8858707}]}]}
{"op":"mcm","clk":"11999951438","pt":1725067947900,"mc":[{"id":"1.232459454","rc":[{"batl":[[0,15,1.02]],"ltp":6.0,"tv":345.99,"id":8858707}]}]}
{"op":"mcm","clk":"11999951900","pt":1725067955127,"mc":[{"id":"1.232459454","rc":[{"batl":[[1,1.36,4.67]],"ltp":1.2,"tv":2171.31,"id":7587363}]}]}
{"op":"mcm","clk":"11999952157","pt":1725067959081,"mc":[{"id":"1.232459454","rc":[{"batb":[[1,3.85,3.61],[2,3,6.5]],"batl":[[0,11.5,2.17],[1,15,0.91]],"ltp":6.0,"tv":345.99,"id":8858707}]}]}
{"op":"mcm","clk":"11999952350","pt":1725067961909,"mc":[{"id":"1.232459454","rc":[{"batb":[[1,3,6.5],[2,2.44,42.28]],"batl":[[0,15,1.02],[1,15,0]],"ltp":6.0,"tv":345.99,"id":8858707}]}]}
{"op":"mcm","clk":"11999952542","pt":1725067964990,"mc":[{"id":"1.232459454","rc":[{"batb":[[0,3,6.5],[1,2.44,42.28],[2,2.28,42.11]],"ltp":6.0,"tv":345.99,"id":8858707}]}]}
{"op":"mcm","clk":"11999952621","pt":1725067966320,"mc":[{"id":"1.232459454","rc":[{"batb":[[0,3.5,4.12],[1,3,6.5],[2,2.44,42.28]],"ltp":6.0,"tv":345.99,"id":8858707},{"batb":[[0,1.17,41.62]],"ltp":1.2,"tv":2171.31,"id":7587363}]}]}
{"op":"mcm","clk":"11999952634","pt":1725067966527,"mc":[{"id":"1.232459454","rc":[{"batb":[[0,3,6.5],[1,2.44,42.28],[2,2.28,42.11]],"ltp":6.0,"tv":345.99,"id":8858707}]}]}
{"op":"mcm","clk":"11999953162","pt":1725067975418,"mc":[{"id":"1.232459454","rc":[{"batb":[[0,1.18,21.38],[1,1.17,41.16],[2,1.15,50.45]],"ltp":1.2,"tv":2171.31,"id":7587363}]}]}
{"op":"mcm","clk":"11999953292","pt":1725067978335,"mc":[{"id":"1.232459454","rc":[{"batl":[[0,3.95,1.52],[1,15,1.02]],"ltp":6.0,"tv":345.99,"id":8858707},{"batb":[[0,1.18,63.22]],"ltp":1.2,"tv":2171.31,"id":7587363}]}]}
{"op":"mcm","clk":"11999953426","pt":1725067980911,"mc":[{"id":"1.232459454","rc":[{"batl":[[0,1.34,11.43],[1,1.35,41.64],[2,1.36,4.67]],"ltp":1.2,"tv":2171.31,"id":7587363}]}]}
{"op":"mcm","clk":"11999953480","pt":1725067981630,"mc":[{"id":"1.232459454","rc":[{"trd":[[3.9,0.1]],"ltp":3.9,"tv":346.08,"id":8858707},{"trd":[[1.34,0.28]],"batl":[[0,1.34,11.15]],"ltp":1.34,"tv":2171.59,"id":7587363}],"tv":2517.68}]}
{"op":"mcm","clk":"11999953617","pt":1725067984101,"mc":[{"id":"1.232459454","rc":[{"trd":[[3.95,1.52]],"batl":[[0,15,1.02],[1,15,0]],"ltp":3.95,"tv":347.61,"id":8858707},{"trd":[[1.33,4.52]],"ltp":1.33,"tv":2176.11,"id":7587363}],"tv":2523.73}]}
{"op":"mcm","clk":"11999953785","pt":1725067986820,"mc":[{"id":"1.232459454","rc":[{"batl":[[0,1.34,5.02]],"ltp":1.33,"tv":2176.11,"id":7587363}]}]}
{"op":"mcm","clk":"11999953885","pt":1725067988514,"mc":[{"id":"1.232459454","rc":[{"batl":[[0,1.35,41.64],[1,1.36,4.67],[2,1.4,4.19]],"ltp":1.33,"tv":2176.11,"id":7587363}]}]}
{"op":"mcm","clk":"11999954009","pt":1725067990617,"mc":[{"id":"1.232459454","rc":[{"batl":[[0,1.33,16.76],[1,1.35,41.64],[2,1.36,4.67]],"ltp":1.33,"tv":2176.11,"id":7587363}]}]}
{"op":"mcm","clk":"11999954338","pt":1725067996163,"mc":[{"id":"1.232459454","rc":[{"trd":[[1.18,9.77],[1.22,9.81]],"batb":[[0,1.18,58.12]],"ltp":1.18,"tv":2186.31,"id":7587363}],"tv":2533.92}]}
{"op":"mcm","clk":"11999954454","pt":1725067997858,"mc":[{"id":"1.232459454","rc":[{"batl":[[0,1.33,21.78],[2,1.4,4.69]],"ltp":1.18,"tv":2186.31,"id":7587363}]}]}
{"op":"mcm","clk":"11999954888","pt":1725068005533,"mc":[{"id":"1.232459454","rc":[{"batb":[[0,1.19,8.38],[1,1.18,58.12],[2,1.17,41.16]],"ltp":1.18,"tv":2186.31,"id":7587363}]}]}
{"op":"mcm","clk":"11999955090","pt":1725068009332,"mc":[{"id":"1.232459454","rc":[{"batl":[[0,1.33,21.88]],"ltp":1.18,"tv":2186.31,"id":7587363}]}]}
{"op":"mcm","clk":"11999955196","pt":1725068011342,"mc":[{"id":"1.232459454","rc":[{"batb":[[0,3.85,3.61],[1,3,6.5],[2,2.96,4.12]],"batl":[[0,12,2.17],[1,15,0.91]],"ltp":3.95,"tv":347.61,"id":8858707}]}]}
{"op":"mcm","clk":"11999955294","pt":1725068012980,"mc":[{"id":"1.232459454","rc":[{"batl":[[1,14,0.07]],"ltp":3.95,"tv":347.61,"id":8858707},{"batl":[[0,1.32,21.02],[1,1.33,21.78],[2,1.35,41.64]],"ltp":1.18,"tv":2186.31,"id":7587363}]}]}
{"op":"mcm","clk":"11999955319","pt":1725068013444,"mc":[{"id":"1.232459454","rc":[{"batb":[[2,2.44,42.28]],"ltp":3.95,"tv":347.61,"id":8858707}]}]}
{"op":"mcm","clk":"11999955394","pt":1725068014781,"mc":[{"id":"1.232459454","rc":[{"trd":[[4.3,0.03]],"batl":[[0,4.3,1.49],[1,12,2.17],[2,14,0.07]],"ltp":4.3,"tv":347.64,"id":8858707},{"trd":[[1.3,0.1]],"batl":[[0,1.32,20.92]],"ltp":1.3,"tv":2186.4,"id":7587363}],"tv":2534.05}]}
{"op":"mcm","clk":"11999955513","pt":1725068016842,"mc":[{"id":"1.232459454","rc":[{"batl":[[1,1.33,16.76]],"ltp":1.3,"tv":2186.4,"id":7587363}]}]}
{"op":"mcm","clk":"11999955611","pt":1725068018587,"mc":[{"id":"1.232459454","rc":[{"batb":[[1,3.5,4.12],[2,3,6.5]],"ltp":4.3,"tv":347.64,"id":8858707}]}]}
{"op":"mcm","clk":"11999955814","pt":1725068021976,"mc":[{"id":"1.232459454","rc":[{"trd":[[4.3,1.52]],"batl":[[0,12,2.27],[1,14,0.07],[2,14,0]],"ltp":4.3,"tv":349.13,"id":8858707},{"trd":[[1.3,5.03]],"ltp":1.3,"tv":2191.34,"id":7587363}],"tv":2540.48}]}
{"op":"mcm","clk":"11999956046","pt":1725068026280,"mc":[{"id":"1.232459454","rc":[{"batl":[[0,1.3,4.19],[1,1.32,20.92],[2,1.33,16.76]],"ltp":1.3,"tv":2191.34,"id":7587363}]}]}
{"op":"mcm","clk":"11999956051","pt":1725068026384,"mc":[{"id":"1.232459454","rc":[{"batb":[[0,3,6.5],[1,2.44,42.28],[2,2.28,42.11]],"batl":[[0,14,0.28],[1,14,0]],"ltp":4.3,"tv":349.13,"id":8858707}]}]}
{"op":"mcm","clk":"11999956235","pt":1725068030089,"mc":[{"id":"1.232459454","rc":[{"batl":[[0,1.3,9.21]],"ltp":1.3,"tv":2191.34,"id":7587363}]}]}
{"op":"mcm","clk":"11999956297","pt":1725068030862,"mc":[{"id":"1.232459454","rc":[{"batb":[[1,1.18,16.28]],"batl":[[0,1.3,13.4],[1,1.33,16.76],[2,1.4,4.69]],"ltp":1.3,"tv":2191.34,"id":7587363}]}]}
{"op":"mcm","clk":"11999956694","pt":1725068036968,"mc":[{"id":"1.232459454","rc":[{"batl":[[0,14,0.18]],"ltp":4.3,"tv":349.13,"id":8858707}]}]}
{"op":"mcm","clk":"11999956900","pt":1725068040498,"mc":[{"id":"1.232459454","rc":[{"batl":[[0,4.5,1.52],[1,14,0.18]],"ltp":4.3,"tv":349.13,"id":8858707}]}]}
{"op":"mcm","clk":"11999957026","pt":1725068042301,"mc":[{"id":"1.232459454","rc":[{"batl":[[0,1.3,8.38]],"ltp":1.3,"tv":2191.34,"id":7587363}]}]}
{"op":"mcm","clk":"11999957163","pt":1725068044618,"mc":[{"id":"1.232459454","rc":[{"trd":[[4.5,4.25]],"batl":[[0,14,0.18],[1,14,0]],"ltp":4.5,"tv":352.18,"id":8858707}],"tv":2543.52}]}
{"op":"mcm","clk":"11999957298","pt":1725068046617,"mc":[{"id":"1.232459454","rc":[{"trd":[[4.3,1.62]],"ltp":4.3,"tv":352.28,"id":8858707},{"trd":[[1.3,5.35]],"batl":[[0,1.3,8.06]],"ltp":1.3,"tv":2191.66,"id":7587363}],"tv":2543.94}]}
{"op":"mcm","clk":"11999957548","pt":1725068050697,"mc":[{"id":"1.232459454","rc":[{"batl":[[0,4.4,1.09],[1,14,0.18]],"ltp":4.3,"tv":352.28,"id":8858707}]}]}
{"op":"mcm","clk":"11999957608","pt":1725068051675,"mc":[{"id":"1.232459454","rc":[{"trd":[[4.4,1.09]],"batl":[[0,14,0.18],[1,14,0]],"ltp":4.4,"tv":353.36,"id":8858707},{"trd":[[1.29,7.89]],"batl":[[0,1.3,8.55]],"ltp":1.29,"tv":2195.36,"id":7587363}],"tv":2548.73}]}
{"op":"mcm","clk":"11999957678","pt":1725068052807,"mc":[{"id":"1.232459454","rc":[{"batl":[[0,1.28,5.51],[1,1.3,8.06],[2,1.33,16.76]],"ltp":1.29,"tv":2195.36,"id":7587363}]}]}
{"op":"mcm","clk":"11999957845","pt":1725068055682,"mc":[{"id":"1.232459454","rc":[{"trd":[[1.19,5.52]],"batb":[[0,1.19,5.62]],"batl":[[0,1.3,8.55],[1,1.33,16.76],[2,1.4,4.69]],"ltp":1.19,"tv":2200.88,"id":7587363}],"tv":2554.25}]}
{"op":"mcm","clk":"11999957916","pt":1725068056712,"mc":[{"id":"1.232459454","rc":[{"trd":[[1.28,7.99],[1.3,6.59]],"batl":[[0,1.3,3.57]],"ltp":1.3,"tv":2203.1,"id":7587363}],"tv":2556.47}]}
{"op":"mcm","clk":"11999958577","pt":1725068067008,"mc":[{"id":"1.232459454","rc":[{"batb":[[0,1.27,1.52],[1,1.19,5.62],[2,1.18,16.28]],"ltp":1.3,"tv":2203.1,"id":7587363}]}]}
{"op":"mcm","clk":"11999958830","pt":1725068070923,"mc":[{"id":"1.232459454","rc":[{"trd":[[4.3,1.72],[4.8,37.81],[6.4,0.38]],"ltp":4.3,"tv":354.22,"id":8858707},{"trd":[[1.19,7.45],[1.27,9.91],[1.3,6.91]],"batb":[[0,1.19,3.69],[1,1.18,16.28],[2,1.17,41.16]],"batl":[[0,1.3,3.25]],"ltp":1.3,"tv":2206.87,"id":7587363}],"tv":2561.1}]}
{"op":"mcm","clk":"11999958937","pt":1725068073022,"mc":[{"id":"1.232459454","rc":[{"batl":[[0,14,0.07]],"ltp":4.3,"tv":354.22,"id":8858707}]}]}
{"op":"mcm","clk":"11999958998","pt":1725068073900,"mc":[{"id":"1.232459454","rc":[{"batb":[[1,2.96,4.12],[2,2.44,42.28]],"batl":[[0,12,2.06],[1,14,0.07]],"ltp":4.3,"tv":354.22,"id":8858707}]}]}
{"op":"mcm","clk":"11999959065","pt":1725068075034,"mc":[{"id":"1.232459454","rc":[{"batl":[[1,1.4,4.69],[2,2.6,3.02]],"ltp":1.3,"tv":2206.87,"id":7587363}]}]}
{"op":"mcm","clk":"11999959139","pt":1725068076219,"mc":[{"id":"1.232459454","rc":[{"batb":[[1,2.44,42.28],[2,2.28,42.11]],"ltp":4.3,"tv":354.22,"id":8858707}]}]}
{"op":"mcm","clk":"11999959196","pt":1725068077042,"mc":[{"id":"1.232459454","rc":[{"batl":[[0,14,0.07],[1,14,0]],"ltp":4.3,"tv":354.22,"id":8858707}]}]}
{"op":"mcm","clk":"11999959239","pt":1725068077815,"mc":[{"id":"1.232459454","rc":[{"batb":[[0,2.44,42.28],[1,2.28,42.11],[2,2.04,84.22]],"ltp":4.3,"tv":354.22,"id":8858707}]}]}
{"op":"mcm","clk":"11999959568","pt":1725068082913,"mc":[{"id":"1.232459454","rc":[{"trd":[[3.5,0.04],[3.75,0.18],[4.3,2.7]],"ltp":3.5,"tv":355.42,"id":8858707},{"trd":[[1.3,10.16],[1.36,0.53],[1.4,0.1]],"batb":[[0,1.2,83.67],[1,1.19,3.69],[2,1.18,16.28]],"batl":[[0,1.4,4.09],[1,2.6,3.02],[2,2.6,0]],"ltp":1.4,"tv":2210.72,"id":7587363}],"tv":2566.15}]}
{"op":"mcm","clk":"11999960057","pt":1725068090727,"mc":[{"id":"1.232459454","rc":[{"batl":[[0,14,0.17]],"ltp":3.5,"tv":355.42,"id":8858707}]}]}
{"op":"mcm","clk":"11999960382","pt":1725068095651,"mc":[{"id":"1.232459454","rc":[{"batl":[[0,14,0.07]],"ltp":3.5,"tv":355.42,"id":8858707}]}]}
{"op":"mcm","clk":"11999960502","pt":1725068097552,"mc":[{"id":"1.232459454","rc":[{"batb":[[0,1.21,8.38],[1,1.2,83.67],[2,1.19,3.69]],"ltp":1.4,"tv":2210.72,"id":7587363}]}]}
{"op":"mcm","clk":"11999960601","pt":1725068098843,"mc":[{"id":"1.232459454","rc":[{"batl":[[0,3.65,1.52],[1,14,0.07]],"ltp":3.5,"tv":355.42,"id":8858707}]}]}
{"op":"mcm","clk":"11999960703","pt":1725068100335,"mc":[{"id":"1.232459454","rc":[{"trd":[[3.65,1.52],[3.7,1.09]],"batl":[[0,14,0.07],[1,14,0]],"ltp":3.7,"tv":358.03,"id":8858707},{"trd":[[1.37,6.99]],"batl":[[0,1.37,13.93],[1,1.4,4.09],[2,2.6,3.02]],"ltp":1.37,"tv":2217.71,"id":7587363}],"tv":2575.75}]}
{"op":"mcm","clk":"11999960890","pt":1725068102354,"mc":[{"id":"1.232459454","rc":[{"batl":[[1,1.39,5.02],[2,1.4,4.09]],"ltp":1.37,"tv":2217.71,"id":7587363}]}]}
{"op":"mcm","clk":"11999961273","pt":1725068106845,"mc":[{"id":"1.232459454","rc":[{"batl":[[1,1.4,4.09],[2,2.6,3.02]],"ltp":1.37,"tv":2217.71,"id":7587363}]}]}
{"op":"mcm","clk":"11999961697","pt":1725068113184,"mc":[{"id":"1.232459454","rc":[{"batb":[[2,1.18,16.28]],"ltp":1.37,"tv":2217.71,"id":7587363}]}]}
{"op":"mcm","clk":"11999961774","pt":1725068114262,"mc":[{"id":"1.232459454","rc":[{"batb":[[1,1.18,16.28],[2,1.17,41.16]],"ltp":1.37,"tv":2217.71,"id":7587363}]}]}
{"op":"mcm","clk":"11999961882","pt":1725068115954,"mc":[{"id":"1.232459454","rc":[{"batl":[[0,5,2.1],[1,14,0.07]],"ltp":3.7,"tv":358.03,"id":8858707}]}]}
{"op":"mcm","clk":"11999962007","pt":1725068117652,"mc":[{"id":"1.232459454","rc":[{"trd":[[3.7,1.18]],"ltp":3.7,"tv":358.13,"id":8858707},{"trd":[[1.37,7.25]],"batl":[[0,1.37,13.67]],"ltp":1.37,"tv":2217.97,"id":7587363}],"tv":2576.1}]}
{"op":"mcm","clk":"11999962116","pt":1725068118943,"mc":[{"id":"1.232459454","rc":[{"batl":[[0,3.8,1.09],[1,5,2.1],[2,14,0.07]],"ltp":3.7,"tv":358.13,"id":8858707}]}]}
{"op":"mcm","clk":"11999962428","pt":1725068123070,"mc":[{"id":"1.232459454","rc":[{"batl":[[0,1.37,14.51]],"ltp":1.37,"tv":2217.97,"id":7587363}]}]}
{"op":"mcm","clk":"11999962542","pt":1725068124452,"mc":[{"id":"1.232459454","rc":[{"batl":[[0,5,2.1],[1,14,0.07],[2,14,0]],"ltp":3.7,"tv":358.13,"id":8858707}]}]}
{"op":"mcm","clk":"11999962750","pt":1725068127483,"mc":[{"id":"1.232459454","rc":[{"batl":[[2,1.45,4.19]],"ltp":1.37,"tv":2217.97,"id":7587363}]}]}
{"op":"mcm","clk":"11999962840","pt":1725068128567,"mc":[{"id":"1.232459454","rc":[{"trd":[[5,35.35]],"batl":[[0,14,0.07],[1,14,0]],"ltp":5.0,"tv":360.23,"id":8858707},{"trd":[[1.18,10.73],[1.21,1060.73],[1.25,505.7]],"batb":[[0,1.18,15.8],[1,1.17,41.16],[2,1.15,50.45]],"ltp":1.18,"tv":2244.09,"id":7587363}],"tv":2604.32}]}
{"op":"mcm","clk":"11999962915","pt":1725068129647,"mc":[{"id":"1.232459454","rc":[{"trd":[[3.75,0.28]],"ltp":3.75,"tv":360.33,"id":8858707},{"trd":[[1.36,0.8]],"batl":[[0,1.4,4.66],[1,1.45,4.19],[2,2.6,3.02]],"ltp":1.36,"tv":2244.36,"id":7587363}],"tv":2604.69}]}
{"op":"mcm","clk":"11999963177","pt":1725068133355,"mc":[{"id":"1.232459454","rc":[{"batl":[[0,1.36,1.52],[1,1.4,4.09],[2,1.45,4.19]],"ltp":1.36,"tv":2244.36,"id":7587363}]}]}
{"op":"mcm","clk":"11999963243","pt":1725068134272,"mc":[{"id":"1.232459454","rc":[{"batl":[[0,1.35,1.79],[1,1.4,4.66]],"ltp":1.36,"tv":2244.36,"id":7587363}]}]}
{"op":"mcm","clk":"11999963356","pt":1725068135977,"mc":[{"id":"1.232459454","rc":[{"batl":[[0,1.36,1.52],[1,1.4,4.09]],"ltp":1.36,"tv":2244.36,"id":7587363}]}]}
{"op":"mcm","clk":"11999963513","pt":1725068138354,"mc":[{"id":"1.232459454","rc":[{"trd":[[3.85,0.1]],"ltp":3.85,"tv":360.43,"id":8858707},{"trd":[[1.35,0.28]],"batl":[[0,1.36,1.24]],"ltp":1.35,"tv":2244.64,"id":7587363}],"tv":2605.07}]}
{"op":"mcm","clk":"11999963698","pt":1725068140778,"mc":[{"id":"1.232459454","rc":[{"batb":[[0,1.22,41.84],[1,1.18,15.8],[2,1.17,41.16]],"ltp":1.35,"tv":2244.64,"id":7587363}]}]}
{"op":"mcm","clk":"11999963764","pt":1725068141552,"mc":[{"id":"1.232459454","rc":[{"batl":[[0,1.25,5.11],[1,1.36,1.24],[2,1.4,4.09]],"ltp":1.35,"tv":2244.64,"id":7587363}]}]}
{"op":"mcm","clk":"11999963990","pt":1725068145262,"mc":[{"id":"1.232459454","rc":[{"batl":[[0,1.36,1.24],[1,1.4,4.09],[2,1.45,4.19]],"ltp":1.35,"tv":2244.64,"id":7587363}]}]}
{"op":"mcm","clk":"11999964053","pt":1725068146284,"mc":[{"id":"1.232459454","rc":[{"batl":[[0,6,2.1],[1,14,0.07]],"ltp":3.85,"tv":360.43,"id":8858707}]}]}
{"op":"mcm","clk":"11999964108","pt":1725068147263,"mc":[{"id":"1.232459454","rc":[{"batb":[[1,1.19,83.77],[2,1.18,15.8]],"ltp":1.35,"tv":2244.64,"id":7587363}]}]}
{"op":"mcm","clk":"11999964230","pt":1725068149262,"mc":[{"id":"1.232459454","rc":[{"batb":[[0,3,4.12],[1,2.44,42.28],[2,2.28,42.11]],"batl":[[1,13,2.06],[2,14,0.07]],"ltp":3.85,"tv":360.43,"id":8858707}]}]}
{"op":"mcm","clk":"11999964307","pt":1725068150694,"mc":[{"id":"1.232459454","rc":[{"batl":[[0,1.4,4.76],[1,1.45,4.19],[2,2.6,3.02]],"ltp":1.35,"tv":2244.64,"id":7587363}]}]}
{"op":"mcm","clk":"11999964424","pt":1725068152307,"mc":[{"id":"1.232459454","rc":[{"batb":[[0,2.44,42.28],[1,2.28,42.11],[2,2.04,84.22]],"batl":[[1,14,0.07],[2,14,0]],"ltp":3.85,"tv":360.43,"id":8858707},{"trd":[[1.25,519.94]],"batb":[[0,1.25,13.8],[1,1.22,41.84],[2,1.19,83.77]],"ltp":1.25,"tv":2258.87,"id":7587363}],"tv":2619.3}]}
{"op":"mcm","clk":"11999964449","pt":1725068152698,"mc":[{"id":"1.232459454","rc":[{"trd":[[1.25,522.77]],"batb":[[0,1.25,12.38]],"ltp":1.25,"tv":2261.71,"id":7587363}],"tv":2622.14}]}
{"op":"mcm","clk":"11999964620","pt":1725068155371,"mc":[{"id":"1.232459454","rc":[{"trd":[[1.22,79.97],[1.25,547.54]],"batb":[[0,1.22,6.76],[1,1.18,15.8],[2,1.17,41.16]],"ltp":1.22,"tv":2356.63,"id":7587363}],"tv":2717.06}]}
{"op":"mcm","clk":"11999964722","pt":1725068157166,"mc":[{"id":"1.232459454","rc":[{"trd":[[1.22,81.29]],"batb":[[0,1.22,6.1]],"ltp":1.22,"tv":2357.95,"id":7587363}],"tv":2718.38}]}
{"op":"mcm","clk":"11999964839","pt":1725068159270,"mc":[{"id":"1.232459454","rc":[{"batl":[[0,1.35,9.05],[1,1.4,4.09],[2,1.45,4.19]],"ltp":1.22,"tv":2357.95,"id":7587363}]}]}
{"op":"mcm","clk":"11999964868","pt":1725068159783,"mc":[{"id":"1.232459454","rc":[{"batb":[[0,1.18,15.8],[1,1.17,41.16],[2,1.14,4.37]],"ltp":1.22,"tv":2357.95,"id":7587363}]}]}
{"op":"mcm","clk":"11999964915","pt":1725068160605,"mc":[{"id":"1.232459454","rc":[{"batl":[[0,1.22,5.11],[1,1.35,9.05],[2,1.4,4.09]],"ltp":1.22,"tv":2357.95,"id":7587363}]}]}
{"op":"mcm","clk":"11999965201","pt":1725068165298,"mc":[{"id":"1.232459454","rc":[{"trd":[[1.22,84.33]],"batl":[[0,1.22,3.59]],"ltp":1.22,"tv":2360.99,"id":7587363}],"tv":2721.43}]}
{"op":"mcm","clk":"11999965253","pt":1725068165873,"mc":[{"id":"1.232459454","rc":[{"batl":[[2,1.37,4.19]],"ltp":1.22,"tv":2360.99,"id":7587363}]}]}
{"op":"mcm","clk":"11999965361","pt":1725068167107,"mc":[{"id":"1.232459454","rc":[{"batb":[[0,2.68,1.01],[1,2.44,42.11],[2,2.28,42.11]],"ltp":3.85,"tv":360.43,"id":8858707}]}]}
{"op":"mcm","clk":"11999965579","pt":1725068169897,"mc":[{"id":"1.232459454","rc":[{"batb":[[0,2.44,42.28],[1,2.28,42.11],[2,2.04,84.22]],"ltp":3.85,"tv":360.43,"id":8858707}]}]}
{"op":"mcm","clk":"11999965792","pt":1725068172777,"mc":[{"id":"1.232459454","rc":[{"batb":[[0,1.22,46.68],[1,1.18,15.8],[2,1.17,41.16]],"batl":[[0,1.35,9.05],[1,1.37,4.19],[2,1.4,4.09]],"ltp":1.22,"tv":2360.99,"id":7587363}]}]}
{"op":"mcm","clk":"11999965865","pt":1725068173925,"mc":[{"id":"1.232459454","rc":[{"batl":[[0,6,2.25]],"ltp":3.85,"tv":360.43,"id":8858707}]}]}
{"op":"mcm","clk":"11999965942","pt":1725068175096,"mc":[{"id":"1.232459454","rc":[{"batb":[[0,1.22,48.78]],"batl":[[0,1.32,8.38],[1,1.35,9.05],[2,1.37,4.19]],"ltp":1.22,"tv":2360.99,"id":7587363}]}]}
{"op":"mcm","clk":"11999965995","pt":1725068176015,"mc":[{"id":"1.232459454","rc":[{"batb":[[0,1.22,52.97]],"batl":[[1,1.35,9.11]],"ltp":1.22,"tv":2360.99,"id":7587363}]}]}
{"op":"mcm","clk":"11999966075","pt":1725068177311,"mc":[{"id":"1.232459454","rc":[{"trd":[[4.1,0.1]],"ltp":4.1,"tv":360.53,"id":8858707},{"trd":[[1.22,87.53],[1.32,0.3]],"batb":[[0,1.22,51.37]],"batl":[[0,1.32,8.08],[1,1.35,8.44]],"ltp":1.22,"tv":2364.49,"id":7587363}],"tv":2725.02}]}
{"op":"mcm","clk":"11999966143","pt":1725068178293,"mc":[{"id":"1.232459454","rc":[{"trd":[[1.22,87.83]],"batb":[[0,1.22,64.45]],"ltp":1.22,"tv":2364.79,"id":7587363}],"tv":2725.32}]}
{"op":"mcm","clk":"11999966165","pt":1725068178601,"mc":[{"id":"1.232459454","rc":[{"batb":[[0,1.22,85.37]],"ltp":1.22,"tv":2364.79,"id":7587363}]}]}
{"op":"mcm","clk":"11999966369","pt":1725068181980,"mc":[{"id":"1.232459454","rc":[{"trd":[[5.6,2.75]],"ltp":5.6,"tv":361.45,"id":8858707},{"trd":[[1.22,92.05]],"batb":[[0,1.22,81.15]],"ltp":1.22,"tv":2369.01,"id":7587363}],"tv":2730.46}]}
{"op":"mcm","clk":"11999966687","pt":1725068187327,"mc":[{"id":"1.232459454","rc":[{"batl":[[0,6,2.33]],"ltp":5.6,"tv":361.45,"id":8858707},{"batl":[[0,1.32,8.23]],"ltp":1.22,"tv":2369.01,"id":7587363}]}]}
{"op":"mcm","clk":"11999966790","pt":1725068188720,"mc":[{"id":"1.232459454","rc":[{"batl":[[0,1.3,8.38],[1,1.32,8.23],[2,1.35,8.44]],"ltp":1.22,"tv":2369.01,"id":7587363}]}]}
{"op":"mcm","clk":"11999966978","pt":1725068191599,"mc":[{"id":"1.232459454","rc":[{"batl":[[1,1.32,9.07]],"ltp":1.22,"tv":2369.01,"id":7587363}]}]}
{"op":"mcm","clk":"11999967052","pt":1725068192629,"mc":[{"id":"1.232459454","rc":[{"trd":[[1.22,92.23]],"batb":[[0,1.22,81.06]],"ltp":1.22,"tv":2369.19,"id":7587363}],"tv":2730.64}]}
{"op":"mcm","clk":"11999967132","pt":1725068193618,"mc":[{"id":"1.232459454","rc":[{"batl":[[0,1.3,50.22]],"ltp":1.22,"tv":2369.19,"id":7587363}]}]}
{"op":"mcm","clk":"11999967232","pt":1725068195206,"mc":[{"id":"1.232459454","rc":[{"batl":[[0,1.3,50.37]],"ltp":1.22,"tv":2369.19,"id":7587363}]}]}
{"op":"mcm","clk":"11999967245","pt":1725068195417,"mc":[{"id":"1.232459454","rc":[{"batl":[[2,1.35,8.38]],"ltp":1.22,"tv":2369.19,"id":7587363}]}]}
{"op":"mcm","clk":"11999967424","pt":1725068198243,"mc":[{"id":"1.232459454","rc":[{"trd":[[1.3,10.2]],"batl":[[0,1.3,50.35],[1,1.32,8.23]],"ltp":1.3,"tv":2369.23,"id":7587363}],"tv":2730.68}]}
{"op":"mcm","clk":"11999967445","pt":1725068198605,"mc":[{"id":"1.232459454","rc":[{"batb":[[0,1.22,81.2]],"ltp":1.3,"tv":2369.23,"id":7587363}]}]}
{"op":"mcm","clk":"11999967576","pt":1725068200664,"mc":[{"id":"1.232459454","rc":[{"batl":[[0,1.3,50.41]],"ltp":1.3,"tv":2369.23,"id":7587363}]}]}
{"op":"mcm","clk":"11999967758","pt":1725068203041,"mc":[{"id":"1.232459454","rc":[{"batb":[[2,1.14,4.37]],"ltp":1.3,"tv":2369.23,"id":7587363}]}]}
{"op":"mcm","clk":"11999967847","pt":1725068204425,"mc":[{"id":"1.232459454","rc":[{"batb":[[0,1.22,81.15]],"ltp":1.3,"tv":2369.23,"id":7587363}]}]}
{"op":"mcm","clk":"11999968065","pt":1725068207625,"mc":[{"id":"1.232459454","rc":[{"batb":[[0,1.22,72.77]],"ltp":1.3,"tv":2369.23,"id":7587363}]}]}
{"op":"mcm","clk":"11999968256","pt":1725068210353,"mc":[{"id":"1.232459454","rc":[{"trd":[[4.3,6.87],[4.4,1.11]],"ltp":4.3,"tv":365.64,"id":8858707},{"trd":[[1.29,7.95],[1.3,23.99]],"batl":[[0,1.3,36.56]],"ltp":1.3,"tv":2383.08,"id":7587363}],"tv":2748.72}]}
{"op":"mcm","clk":"11999968320","pt":1725068211438,"mc":[{"id":"1.232459454","rc":[{"batl":[[0,1.3,37.4]],"ltp":1.3,"tv":2383.08,"id":7587363}]}]}
{"op":"mcm","clk":"11999968480","pt":1725068214057,"mc":[{"id":"1.232459454","rc":[{"trd":[[1.23,188.9]],"batb":[[0,1.22,71.93]],"ltp":1.23,"tv":2383.26,"id":7587363}],"tv":2748.9}]}
{"op":"mcm","clk":"11999968600","pt":1725068215856,"mc":[{"id":"1.232459454","rc":[{"batl":[[0,6,2.19]],"ltp":4.3,"tv":365.64,"id":8858707}]}]}
{"op":"mcm","clk":"11999968763","pt":1725068218268,"mc":[{"id":"1.232459454","rc":[{"batb":[[0,1.23,20.92],[1,1.22,71.93],[2,1.18,15.8]],"batl":[[0,1.3,1.13]],"ltp":1.23,"tv":2383.26,"id":7587363}]}]}
{"op":"mcm","clk":"11999968833","pt":1725068219372,"mc":[{"id":"1.232459454","rc":[{"batl":[[0,14,0.16],[1,14,0]],"ltp":4.3,"tv":365.64,"id":8858707}]}]}
{"op":"mcm","clk":"11999968873","pt":1725068219935,"mc":[{"id":"1.232459454","rc":[{"batl":[[1,1.35,12.72],[2,1.37,4.19]],"ltp":1.23,"tv":2383.26,"id":7587363}]}]}
{"op":"mcm","clk":"11999969085","pt":1725068223383,"mc":[{"id":"1.232459454","rc":[{"batl":[[0,1.35,13.01],[1,1.37,4.19],[2,1.4,4.24]],"ltp":1.23,"tv":2383.26,"id":7587363}]}]}
{"op":"mcm","clk":"11999969226","pt":1725068225494,"mc":[{"id":"1.232459454","rc":[{"trd":[[4.3,6.91],[4.5,4.29]],"batl":[[0,14,0.22]],"ltp":4.3,"tv":365.72,"id":8858707},{"trd":[[1.28,8.14],[1.3,24.14]],"batl":[[0,1.35,12.72]],"ltp":1.3,"tv":2383.55,"id":7587363}],"tv":2749.28}]}
{"op":"mcm","clk":"11999969424","pt":1725068228354,"mc":[{"id":"1.232459454","rc":[{"batb":[[0,1.3,41.89],[1,1.23,20.92],[2,1.22,71.93]],"batl":[[0,1.35,12.86]],"ltp":1.3,"tv":2383.55,"id":7587363}]}]}
{"op":"mcm","clk":"11999969593","pt":1725068230772,"mc":[{"id":"1.232459454","rc":[{"batl":[[0,1.35,12.72]],"ltp":1.3,"tv":2383.55,"id":7587363}]}]}
{"op":"mcm","clk":"11999969679","pt":1725068232053,"mc":[{"id":"1.232459454","rc":[{"batb":[[0,1.23,20.92],[1,1.22,71.93],[2,1.18,15.8]],"ltp":1.3,"tv":2383.55,"id":7587363}]}]}
{"op":"mcm","clk":"11999969760","pt":1725068233178,"mc":[{"id":"1.232459454","rc":[{"trd":[[1.35,0.58]],"batb":[[0,1.37,4.01],[1,1.23,20.92],[2,1.22,71.93]],"batl":[[0,1.4,4.24],[1,1.45,4.19],[2,2.6,3.02]],"ltp":1.35,"tv":2383.85,"id":7587363}],"tv":2749.57}]}
{"op":"mcm","clk":"11999969888","pt":1725068235078,"mc":[{"id":"1.232459454","rc":[{"batl":[[0,14,0.37]],"ltp":4.3,"tv":365.72,"id":8858707}]}]}
{"op":"mcm","clk":"11999970061","pt":1725068237755,"mc":[{"id":"1.232459454","rc":[{"batb":[[1,1.25,418.84],[2,1.23,20.92]],"ltp":1.35,"tv":2383.85,"id":7587363}]}]}
{"op":"mcm","clk":"11999970208","pt":1725068240372,"mc":[{"id":"1.232459454","rc":[{"batb":[[0,1.23,20.92],[1,1.22,71.93],[2,1.14,4.37]],"ltp":1.35,"tv":2383.85,"id":7587363}]}]}
{"op":"mcm","clk":"11999970237","pt":1725068240789,"mc":[{"id":"1.232459454","rc":[{"batl":[[0,14,0.31]],"ltp":4.3,"tv":365.72,"id":8858707},{"batb":[[1,1.22,67.74]],"ltp":1.35,"tv":2383.85,"id":7587363}]}]}
{"op":"mcm","clk":"11999970358","pt":1725068242688,"mc":[{"id":"1.232459454","rc":[{"batb":[[0,4.4,2.1],[1,2.44,42.28],[2,2.28,42.11]],"ltp":4.3,"tv":365.72,"id":8858707},{"batb":[[0,1.23,21.76]],"ltp":1.35,"tv":2383.85,"id":7587363}]}]}
{"op":"mcm","clk":"11999970410","pt":1725068243606,"mc":[{"id":"1.232459454","rc":[{"batl":[[0,1.4,5.15]],"ltp":1.35,"tv":2383.85,"id":7587363}]}]}
{"op":"mcm","clk":"11999970581","pt":1725068246084,"mc":[{"id":"1.232459454","rc":[{"batb":[[0,1.28,8.38],[1,1.23,21.76],[2,1.22,67.74]],"ltp":1.35,"tv":2383.85,"id":7587363}]}]}
{"op":"mcm","clk":"11999970682","pt":1725068247471,"mc":[{"id":"1.232459454","rc":[{"batl":[[0,1.37,1.06],[1,1.4,4.24],[2,1.45,4.19]],"ltp":1.35,"tv":2383.85,"id":7587363}]}]}
{"op":"mcm","clk":"11999970767","pt":1725068248807,"mc":[{"id":"1.232459454","rc":[{"batl":[[0,1.37,1.21]],"ltp":1.35,"tv":2383.85,"id":7587363}]}]}
{"op":"mcm","clk":"11999970999","pt":1725068252312,"mc":[{"id":"1.232459454","rc":[{"trd":[[4.4,1.4]],"batb":[[0,4.4,1.95]],"ltp":4.4,"tv":366.02,"id":8858707},{"batb":[[2,1.22,46.82]],"batl":[[0,1.37,17.82]],"ltp":1.35,"tv":2383.85,"id":7587363}],"tv":2749.87}]}
{"op":"mcm","clk":"11999971254","pt":1725068256126,"mc":[{"id":"1.232459454","rc":[{"batb":[[0,1.22,47.66],[1,1.14,4.37],[2,1.13,2]],"ltp":1.35,"tv":2383.85,"id":7587363}]}]}
{"op":"mcm","clk":"11999971308","pt":1725068257107,"mc":[{"id":"1.232459454","rc":[{"batl":[[0,14,0.45]],"ltp":4.4,"tv":366.02,"id":8858707},{"batb":[[0,1.23,42.73],[1,1.22,46.82],[2,1.14,4.37]],"ltp":1.35,"tv":2383.85,"id":7587363}]}]}
{"op":"mcm","clk":"11999971375","pt":1725068258136,"mc":[{"id":"1.232459454","rc":[{"trd":[[4.4,1.77]],"batb":[[0,4.4,1.58]],"ltp":4.4,"tv":366.39,"id":8858707},{"trd":[[1.3,25.4]],"ltp":1.3,"tv":2385.11,"id":7587363}],"tv":2751.5}]}
{"op":"mcm","clk":"11999971440","pt":1725068259109,"mc":[{"id":"1.232459454","rc":[{"batl":[[0,1.37,17.97]],"ltp":1.3,"tv":2385.11,"id":7587363}]}]}
{"op":"mcm","clk":"11999971490","pt":1725068259982,"mc":[{"id":"1.232459454","rc":[{"trd":[[4.4,1.97]],"batb":[[0,4.4,1.38]],"ltp":4.4,"tv":366.59,"id":8858707},{"trd":[[1.28,8.44],[1.3,26.09]],"batl":[[0,1.37,17.82]],"ltp":1.3,"tv":2386.09,"id":7587363}],"tv":2752.69}]}
{"op":"mcm","clk":"11999971554","pt":1725068261106,"mc":[{"id":"1.232459454","rc":[{"trd":[[4.4,3.21]],"batb":[[0,2.44,42.42],[1,2.28,42.11],[2,2.04,84.22]],"ltp":4.4,"tv":367.83,"id":8858707},{"trd":[[1.3,30.28]],"ltp":1.3,"tv":2390.28,"id":7587363}],"tv":2758.12}]}
{"op":"mcm","clk":"11999971884","pt":1725068265896,"mc":[{"id":"1.232459454","rc":[{"batb":[[0,1.23,42.88]],"ltp":1.3,"tv":2390.28,"id":7587363}]}]}
{"op":"mcm","clk":"11999971956","pt":1725068267019,"mc":[{"id":"1.232459454","rc":[{"batb":[[1,1.22,42.63]],"ltp":1.3,"tv":2390.28,"id":7587363}]}]}
{"op":"mcm","clk":"11999972091","pt":1725068268920,"mc":[{"id":"1.232459454","rc":[{"trd":[[4.4,3.49]],"batb":[[0,2.44,42.28]],"batl":[[0,4.9,1.09],[1,14,0.31]],"ltp":4.4,"tv":368.11,"id":8858707},{"batb":[[0,1.26,17.75],[1,1.23,41.89],[2,1.22,42.63]],"ltp":1.3,"tv":2390.28,"id":7587363}],"tv":2758.4}]}
{"op":"mcm","clk":"11999972292","pt":1725068272010,"mc":[{"id":"1.232459454","rc":[{"batl":[[0,14,0.45],[1,14,0]],"ltp":4.4,"tv":368.11,"id":8858707}]}]}
{"op":"mcm","clk":"11999972336","pt":1725068272630,"mc":[{"id":"1.232459454","rc":[{"batb":[[1,1.24,20.92],[2,1.23,41.89]],"ltp":1.3,"tv":2390.28,"id":7587363}]}]}
{"op":"mcm","clk":"11999972458","pt":1725068274529,"mc":[{"id":"1.232459454","rc":[{"batl":[[0,14,0.5]],"ltp":4.4,"tv":368.11,"id":8858707}]}]}
{"op":"mcm","clk":"11999972641","pt":1725068277032,"mc":[{"id":"1.232459454","rc":[{"batb":[[1,1.24,20.99]],"ltp":1.3,"tv":2390.28,"id":7587363}]}]}
{"op":"mcm","clk":"11999972938","pt":1725068281356,"mc":[{"id":"1.232459454","rc":[{"batl":[[0,1.36,41.84],[1,1.37,17.82],[2,1.4,4.24]],"ltp":1.3,"tv":2390.28,"id":7587363}]}]}
{"op":"mcm","clk":"11999973302","pt":1725068286956,"mc":[{"id":"1.232459454","rc":[{"batb":[[0,1.26,16.76]],"ltp":1.3,"tv":2390.28,"id":7587363}]}]}
{"op":"mcm","clk":"11999973405","pt":1725068288148,"mc":[{"id":"1.232459454","rc":[{"batl":[[0,1.36,42.13]],"ltp":1.3,"tv":2390.28,"id":7587363}]}]}
{"op":"mcm","clk":"11999973530","pt":1725068290048,"mc":[{"id":"1.232459454","rc":[{"trd":[[3.75,0.38]],"ltp":3.75,"tv":368.21,"id":8858707},{"trd":[[1.36,1.07]],"batl":[[0,1.36,41.86]],"ltp":1.36,"tv":2390.55,"id":7587363}],"tv":2758.76}]}
{"op":"mcm","clk":"11999973597","pt":1725068291159,"mc":[{"id":"1.232459454","rc":[{"batl":[[0,14,0.42]],"ltp":3.75,"tv":368.21,"id":8858707}]}]}
{"op":"mcm","clk":"11999974114","pt":1725068299344,"mc":[{"id":"1.232459454","rc":[{"batb":[[2,1.22,42.63]],"batl":[[0,1.36,41.72]],"ltp":1.36,"tv":2390.55,"id":7587363}]}]}
{"op":"mcm","clk":"11999974149","pt":1725068299961,"mc":[{"id":"1.232459454","rc":[{"batl":[[0,1.35,56.08],[1,1.36,41.72],[2,1.37,17.82]],"ltp":1.36,"tv":2390.55,"id":7587363}]}]}
{"op":"mcm","clk":"11999974277","pt":1725068301095,"mc":[{"id":"1.232459454","rc":[{"batb":[[0,1.26,17.6]],"ltp":1.36,"tv":2390.55,"id":7587363}]}]}
{"op":"mcm","clk":"11999974357","pt":1725068302175,"mc":[{"id":"1.232459454","rc":[{"batb":[[1,1.24,21.27]],"ltp":1.36,"tv":2390.55,"id":7587363}]}]}
{"op":"mcm","clk":"11999974547","pt":1725068304547,"mc":[{"id":"1.232459454","rc":[{"batl":[[0,1.35,56.23]],"ltp":1.36,"tv":2390.55,"id":7587363}]}]}
{"op":"mcm","clk":"11999974688","pt":1725068306663,"mc":[{"id":"1.232459454","rc":[{"trd":[[3.85,2.41]],"ltp":3.85,"tv":370.51,"id":8858707},{"trd":[[1.35,7.16]],"batl":[[0,1.35,49.65]],"ltp":1.35,"tv":2397.13,"id":7587363}],"tv":2767.65}]}
{"op":"mcm","clk":"11999974887","pt":1725068309185,"mc":[{"id":"1.232459454","rc":[{"batb":[[2,1.22,40.53]],"batl":[[0,1.35,53.84]],"ltp":1.35,"tv":2397.13,"id":7587363}]}]}
{"op":"mcm","clk":"11999974932","pt":1725068309855,"mc":[{"id":"1.232459454","rc":[{"batl":[[0,1.35,53.69]],"ltp":1.35,"tv":2397.13,"id":7587363}]}]}
{"op":"mcm","clk":"11999975073","pt":1725068311761,"mc":[{"id":"1.232459454","rc":[{"batl":[[0,14,0.12]],"ltp":3.85,"tv":370.51,"id":8858707}]}]}
{"op":"mcm","clk":"11999975287","pt":1725068315068,"mc":[{"id":"1.232459454","rc":[{"batl":[[0,14,0.17]],"ltp":3.85,"tv":370.51,"id":8858707}]}]}
{"op":"mcm","clk":"11999975391","pt":1725068316515,"mc":[{"id":"1.232459454","rc":[{"trd":[[4.4,3.54],[4.6,0.42]],"batl":[[0,14,0.07]],"ltp":4.6,"tv":370.61,"id":8858707},{"trd":[[1.26,64.06],[1.27,11.75],[1.29,8.13]],"batb":[[0,1.26,10.56]],"ltp":1.26,"tv":2411.54,"id":7587363}],"tv":2782.16}]}
{"op":"mcm","clk":"11999975571","pt":1725068319089,"mc":[{"id":"1.232459454","rc":[{"batl":[[0,14,0.26]],"ltp":4.6,"tv":370.61,"id":8858707}]}]}
{"op":"mcm","clk":"11999975888","pt":1725068323274,"mc":[{"id":"1.232459454","rc":[{"batl":[[1,1.37,17.97],[2,1.4,4.38]],"ltp":1.26,"tv":2411.54,"id":7587363}]}]}
{"op":"mcm","clk":"11999975944","pt":1725068323998,"mc":[{"id":"1.232459454","rc":[{"trd":[[3.85,2.55]],"ltp":3.85,"tv":370.76,"id":8858707},{"trd":[[1.35,7.58]],"batb":[[0,1.24,21.27],[1,1.22,40.53],[2,1.14,4.37]],"batl":[[0,1.35,53.27]],"ltp":1.35,"tv":2411.96,"id":7587363}],"tv":2782.72}]}
{"op":"mcm","clk":"11999976275","pt":1725068328878,"mc":[{"id":"1.232459454","rc":[{"trd":[[3.85,2.7]],"ltp":3.85,"tv":370.9,"id":8858707},{"trd":[[1.35,8]],"batl":[[0,1.35,52.85]],"ltp":1.35,"tv":2412.38,"id":7587363}],"tv":2783.29}]}
{"op":"mcm","clk":"11999976339","pt":1725068329804,"mc":[{"id":"1.232459454","rc":[{"batl":[[0,1.35,53]],"ltp":1.35,"tv":2412.38,"id":7587363}]}]}
{"op":"mcm","clk":"11999976378","pt":1725068330522,"mc":[{"id":"1.232459454","rc":[{"batl":[[0,1.35,53.84]],"ltp":1.35,"tv":2412.38,"id":7587363}]}]}
{"op":"mcm","clk":"11999976459","pt":1725068331503,"mc":[{"id":"1.232459454","rc":[{"trd":[[3.9,0.24]],"ltp":3.9,"tv":371.05,"id":8858707},{"trd":[[1.34,0.71]],"batl":[[0,1.35,53.41]],"ltp":1.34,"tv":2412.81,"id":7587363}],"tv":2783.87}]}
{"op":"mcm","clk":"11999976617","pt":1725068333811,"mc":[{"id":"1.232459454","rc":[{"batb":[[0,1.24,21.41]],"ltp":1.34,"tv":2412.81,"id":7587363}]}]}
{"op":"mcm","clk":"11999976855","pt":1725068336956,"mc":[{"id":"1.232459454","rc":[{"batb":[[0,1.25,1.26],[1,1.24,20.99],[2,1.22,40.53]],"ltp":1.34,"tv":2412.81,"id":7587363}]}]}
{"op":"mcm","clk":"11999976991","pt":1725068338804,"mc":[{"id":"1.232459454","rc":[{"trd":[[3.9,0.38]],"batl":[[0,14,0.27]],"ltp":3.9,"tv":371.19,"id":8858707},{"trd":[[1.34,1.12]],"batl":[[0,1.35,53]],"ltp":1.34,"tv":2413.22,"id":7587363}],"tv":2784.42}]}
{"op":"mcm","clk":"11999977240","pt":1725068342716,"mc":[{"id":"1.232459454","rc":[{"batb":[[0,1.24,21.41],[1,1.22,40.53],[2,1.14,4.37]],"ltp":1.34,"tv":2413.22,"id":7587363}]}]}
{"op":"mcm","clk":"11999977479","pt":1725068346120,"mc":[{"id":"1.232459454","rc":[{"trd":[[3.9,0.39]],"batl":[[0,14,0.26]],"ltp":3.9,"tv":371.19,"id":8858707},{"trd":[[1.25,548.08],[1.26,64.36],[1.34,1.14]],"batb":[[0,1.24,20.59]],"ltp":1.25,"tv":2414.08,"id":7587363}],"tv":2785.28}]}
{"op":"mcm","clk":"11999977557","pt":1725068346947,"mc":[{"id":"1.232459454","rc":[{"trd":[[3.85,2.85]],"ltp":3.85,"tv":371.34,"id":8858707},{"trd":[[1.35,8.42]],"batl":[[0,1.35,52.58]],"ltp":1.35,"tv":2414.5,"id":7587363}],"tv":2785.85}]}
{"op":"mcm","clk":"11999977617","pt":1725068347618,"mc":[{"id":"1.232459454","rc":[{"trd":[[1.24,2.2]],"batb":[[0,1.22,40.53],[1,1.14,4.37],[2,1.13,2]],"batl":[[0,1.24,119.15],[1,1.35,52.58],[2,1.37,17.97]],"ltp":1.24,"tv":2414.65,"id":7587363}],"tv":2785.99}]}
{"op":"mcm","clk":"11999977701","pt":1725068348960,"mc":[{"id":"1.232459454","rc":[{"batb":[[0,3.85,3.61],[1,2.9,4.21],[2,2.44,42.2]],"batl":[[0,11,2.06],[1,14,0.26]],"ltp":3.85,"tv":371.34,"id":8858707}]}]}
{"op":"mcm","clk":"11999977788","pt":1725068350037,"mc":[{"id":"1.232459454","rc":[{"batl":[[1,1.35,52.72]],"ltp":1.24,"tv":2414.65,"id":7587363}]}]}
{"op":"mcm","clk":"11999977875","pt":1725068351119,"mc":[{"id":"1.232459454","rc":[{"batb":[[1,2.44,42.28],[2,2.28,42.11]],"ltp":3.85,"tv":371.34,"id":8858707}]}]}
{"op":"mcm","clk":"11999978029","pt":1725068353231,"mc":[{"id":"1.232459454","rc":[{"batl":[[0,1.24,77.26]],"ltp":1.24,"tv":2414.65,"id":7587363}]}]}
{"op":"mcm","clk":"11999978275","pt":1725068356210,"mc":[{"id":"1.232459454","rc":[{"batb":[[1,3.2,4.12],[2,2.44,42.28]],"ltp":3.85,"tv":371.34,"id":8858707}]}]}
{"op":"mcm","clk":"11999978314","pt":1725068356726,"mc":[{"id":"1.232459454","rc":[{"trd":[[5.1,132.42]],"ltp":5.1,"tv":381.96,"id":8858707},{"trd":[[1.24,45.88]],"batl":[[0,1.24,33.58]],"ltp":1.24,"tv":2458.33,"id":7587363}],"tv":2840.29}]}
{"op":"mcm","clk":"11999978668","pt":1725068361356,"mc":[{"id":"1.232459454","rc":[{"batb":[[0,2.44,42.28],[1,2.28,42.11],[2,2.04,84.22]],"batl":[[0,14,0.26],[1,14,0]],"ltp":5.1,"tv":381.96,"id":8858707},{"batb":[[0,1.22,40.67]],"ltp":1.24,"tv":2458.33,"id":7587363}]}]}
{"op":"mcm","clk":"11999978727","pt":1725068362024,"mc":[{"id":"1.232459454","rc":[{"batl":[[0,13,1.03],[1,14,0.07]],"ltp":5.1,"tv":381.96,"id":8858707},{"batb":[[1,1.14,4.52]],"ltp":1.24,"tv":2458.33,"id":7587363}]}]}
{"op":"mcm","clk":"11999978908","pt":1725068364348,"mc":[{"id":"1.232459454","rc":[{"trd":[[5.1,132.61]],"ltp":5.1,"tv":382.15,"id":8858707},{"trd":[[1.24,46.86]],"batl":[[0,1.24,32.7]],"ltp":1.24,"tv":2459.31,"id":7587363}],"tv":2841.46}]}
{"op":"mcm","clk":"11999978931","pt":1725068364656,"mc":[{"id":"1.232459454","rc":[{"batl":[[0,1.24,24.32]],"ltp":1.24,"tv":2459.31,"id":7587363}]}]}
{"op":"mcm","clk":"11999979020","pt":1725068365841,"mc":[{"id":"1.232459454","rc":[{"trd":[[5.1,132.75]],"ltp":5.1,"tv":382.3,"id":8858707},{"trd":[[1.24,47.46]],"batl":[[0,1.24,23.72]],"ltp":1.24,"tv":2459.91,"id":7587363}],"tv":2842.21}]}
{"op":"mcm","clk":"11999979244","pt":1725068368770,"mc":[{"id":"1.232459454","rc":[{"trd":[[1.24,47.58]],"batl":[[0,1.24,23.66]],"ltp":1.24,"tv":2460.02,"id":7587363}],"tv":2842.33}]}
{"op":"mcm","clk":"11999979460","pt":1725068371652,"mc":[{"id":"1.232459454","rc":[{"trd":[[5.1,132.9]],"ltp":5.1,"tv":382.44,"id":8858707},{"trd":[[1.24,48.18]],"batl":[[0,1.24,23.06]],"ltp":1.24,"tv":2460.62,"id":7587363}],"tv":2843.07}]}
{"op":"mcm","clk":"11999979578","pt":1725068373042,"mc":[{"id":"1.232459454","rc":[{"batb":[[0,2.9,4.21],[1,2.44,42.2],[2,2.28,42.11]],"batl":[[0,11,2.9],[1,14,0.26]],"ltp":5.1,"tv":382.44,"id":8858707},{"batl":[[1,1.33,19.82],[2,1.35,52.72]],"ltp":1.24,"tv":2460.62,"id":7587363}]}]}
{"op":"mcm","clk":"11999979703","pt":1725068374738,"mc":[{"id":"1.232459454","rc":[{"batb":[[0,2.44,42.28],[1,2.28,42.11],[2,2.04,84.22]],"ltp":5.1,"tv":382.44,"id":8858707}]}]}
{"op":"mcm","clk":"11999979825","pt":1725068376435,"mc":[{"id":"1.232459454","rc":[{"batb":[[0,1.22,40.53]],"ltp":1.24,"tv":2460.62,"id":7587363}]}]}
{"op":"mcm","clk":"11999980084","pt":1725068379887,"mc":[{"id":"1.232459454","rc":[{"batb":[[0,3.2,4.12],[1,2.44,42.28],[2,2.28,42.11]],"ltp":5.1,"tv":382.44,"id":8858707}]}]}
{"op":"mcm","clk":"11999980374","pt":1725068383283,"mc":[{"id":"1.232459454","rc":[{"trd":[[5.1,133]],"ltp":5.1,"tv":382.54,"id":8858707},{"trd":[[1.24,48.58]],"batl":[[0,1.24,22.66]],"ltp":1.24,"tv":2461.02,"id":7587363}],"tv":2843.57}]}
{"op":"mcm","clk":"11999980507","pt":1725068384990,"mc":[{"id":"1.232459454","rc":[{"trd":[[5.1,133.09]],"ltp":5.1,"tv":382.64,"id":8858707},{"trd":[[1.24,48.98]],"batl":[[0,1.24,22.26]],"ltp":1.24,"tv":2461.42,"id":7587363}],"tv":2844.07}]}
{"op":"mcm","clk":"11999980601","pt":1725068386579,"mc":[{"id":"1.232459454","rc":[{"batl":[[0,11,2.06]],"ltp":5.1,"tv":382.64,"id":8858707}]}]}
{"op":"mcm","clk":"11999980761","pt":1725068388586,"mc":[{"id":"1.232459454","rc":[{"trd":[[5.1,133.11]],"ltp":5.1,"tv":382.65,"id":8858707},{"trd":[[1.24,49.04]],"batl":[[0,1.24,22.2]],"ltp":1.24,"tv":2461.48,"id":7587363}],"tv":2844.14}]}
{"op":"mcm","clk":"11999980881","pt":1725068390178,"mc":[{"id":"1.232459454","rc":[{"batb":[[0,1.23,20.92],[1,1.22,40.53],[2,1.14,4.52]],"batl":[[0,1.24,18.01]],"ltp":1.24,"tv":2461.48,"id":7587363}]}]}
{"op":"mcm","clk":"11999981139","pt":1725068393469,"mc":[{"id":"1.232459454","rc":[{"batb":[[0,1.24,2.91],[1,1.23,20.92],[2,1.22,40.53]],"batl":[[0,1.33,19.82],[1,1.35,52.72],[2,1.37,17.97]],"ltp":1.24,"tv":2461.48,"id":7587363}]}]}
{"op":"mcm","clk":"11999981307","pt":1725068395984,"mc":[{"id":"1.232459454","rc":[{"batb":[[0,1.22,40.53],[1,1.14,4.52],[2,1.13,2]],"batl":[[0,1.23,18.64],[1,1.33,19.82],[2,1.35,52.72]],"ltp":1.24,"tv":2461.48,"id":7587363}]}]}
{"op":"mcm","clk":"11999981405","pt":1725068397277,"mc":[{"id":"1.232459454","rc":[{"trd":[[5.3,35.68]],"ltp":5.3,"tv":382.72,"id":8858707},{"trd":[[1.23,189.18]],"batl":[[0,1.23,18.36],[2,1.35,4.48]],"ltp":1.23,"tv":2461.76,"id":7587363}],"tv":2844.49}]}
{"op":"mcm","clk":"11999981704","pt":1725068401088,"mc":[{"id":"1.232459454","rc":[{"trd":[[1.23,225.9]],"batl":[[0,1.33,19.67],[1,1.35,4.48],[2,1.37,17.97]],"ltp":1.23,"tv":2498.48,"id":7587363}],"tv":2881.2}]}
{"op":"mcm","clk":"11999981775","pt":1725068401917,"mc":[{"id":"1.232459454","rc":[{"batl":[[0,11,2.25]],"ltp":5.3,"tv":382.72,"id":8858707}]}]}
{"op":"mcm","clk":"11999981858","pt":1725068402999,"mc":[{"id":"1.232459454","rc":[{"batl":[[0,11,2.35]],"ltp":5.3,"tv":382.72,"id":8858707}]}]}
{"op":"mcm","clk":"11999982053","pt":1725068405773,"mc":[{"id":"1.232459454","rc":[{"batl":[[0,1.33,19.82]],"ltp":1.23,"tv":2498.48,"id":7587363}]}]}
{"op":"mcm","clk":"11999982169","pt":1725068407323,"mc":[{"id":"1.232459454","rc":[{"batb":[[0,1.23,20.92],[1,1.22,40.53],[2,1.14,4.52]],"ltp":1.23,"tv":2498.48,"id":7587363}]}]}
{"op":"mcm","clk":"11999982206","pt":1725068407688,"mc":[{"id":"1.232459454","rc":[{"batl":[[0,11,2.95]],"ltp":5.3,"tv":382.72,"id":8858707}]}]}
{"op":"mcm","clk":"11999982293","pt":1725068408716,"mc":[{"id":"1.232459454","rc":[{"batl":[[0,1.33,19.96]],"ltp":1.23,"tv":2498.48,"id":7587363}]}]}
{"op":"mcm","clk":"11999982552","pt":1725068411904,"mc":[{"id":"1.232459454","rc":[{"batl":[[0,1.3,21.21],[1,1.33,19.67],[2,1.35,4.48]],"ltp":1.23,"tv":2498.48,"id":7587363}]}]}
{"op":"mcm","clk":"11999982835","pt":1725068415811,"mc":[{"id":"1.232459454","rc":[{"batb":[[0,1.23,21.07]],"batl":[[1,1.33,61.56]],"ltp":1.23,"tv":2498.48,"id":7587363}]}]}
{"op":"mcm","clk":"11999982921","pt":1725068417110,"mc":[{"id":"1.232459454","rc":[{"batb":[[1,1.22,39.87]],"batl":[[1,1.32,41.89],[2,1.33,61.56]],"ltp":1.23,"tv":2498.48,"id":7587363}]}]}
{"op":"mcm","clk":"11999983003","pt":1725068418338,"mc":[{"id":"1.232459454","rc":[{"batl":[[0,1.3,92.34]],"ltp":1.23,"tv":2498.48,"id":7587363}]}]}
{"op":"mcm","clk":"11999983079","pt":1725068419321,"mc":[{"id":"1.232459454","rc":[{"trd":[[5.1,133.21]],"batl":[[0,11,2.34]],"ltp":5.1,"tv":382.82,"id":8858707},{"trd":[[1.24,49.44]],"batl":[[0,1.24,20.52],[1,1.3,92.34],[2,1.32,41.89]],"ltp":1.24,"tv":2498.88,"id":7587363}],"tv":2881.7}]}
{"op":"mcm","clk":"11999983347","pt":1725068422814,"mc":[{"id":"1.232459454","rc":[{"batl":[[1,1.3,21.21]],"ltp":1.24,"tv":2498.88,"id":7587363}]}]}
{"op":"mcm","clk":"11999983584","pt":1725068425655,"mc":[{"id":"1.232459454","rc":[{"batb":[[0,1.23,31.32]],"ltp":1.24,"tv":2498.88,"id":7587363}]}]}
{"op":"mcm","clk":"11999983742","pt":1725068427612,"mc":[{"id":"1.232459454","rc":[{"batb":[[0,3.2,4.27]],"ltp":5.1,"tv":382.82,"id":8858707}]}]}
{"op":"mcm","clk":"11999983817","pt":1725068428645,"mc":[{"id":"1.232459454","rc":[{"trd":[[1.24,49.63]],"batl":[[0,1.24,20.42]],"ltp":1.24,"tv":2499.08,"id":7587363}],"tv":2881.9}]}
{"op":"mcm","clk":"11999984001","pt":1725068430239,"mc":[{"id":"1.232459454","rc":[{"trd":[[5.1,133.3]],"ltp":5.1,"tv":382.91,"id":8858707},{"trd":[[1.24,50.03]],"batl":[[0,1.24,20.02]],"ltp":1.24,"tv":2499.48,"id":7587363}],"tv":2882.4}]}
{"op":"mcm","clk":"11999984131","pt":1725068431833,"mc":[{"id":"1.232459454","rc":[{"batb":[[0,1.23,32.22]],"batl":[[0,1.3,21.21],[1,1.32,41.89],[2,1.33,19.67]],"ltp":1.24,"tv":2499.48,"id":7587363}]}]}
{"op":"mcm","clk":"11999984383","pt":1725068435119,"mc":[{"id":"1.232459454","rc":[{"batl":[[0,11,2.53]],"ltp":5.1,"tv":382.91,"id":8858707}]}]}
{"op":"mcm","clk":"11999984542","pt":1725068437237,"mc":[{"id":"1.232459454","rc":[{"batl":[[0,14,0.91],[1,14,0]],"ltp":5.1,"tv":382.91,"id":8858707},{"batb":[[0,1.24,34.51],[1,1.23,31.32],[2,1.22,39.87]],"ltp":1.24,"tv":2499.48,"id":7587363}]}]}
{"op":"mcm","clk":"11999984606","pt":1725068438161,"mc":[{"id":"1.232459454","rc":[{"batb":[[0,2.44,42.43],[1,2.28,42.11],[2,2.04,84.22]],"ltp":5.1,"tv":382.91,"id":8858707},{"batl":[[1,1.33,19.67],[2,1.35,4.48]],"ltp":1.24,"tv":2499.48,"id":7587363}]}]}
{"op":"mcm","clk":"11999984694","pt":1725068439348,"mc":[{"id":"1.232459454","rc":[{"batl":[[0,8,1.08],[1,14,0.54]],"ltp":5.1,"tv":382.91,"id":8858707}]}]}
{"op":"mcm","clk":"11999984724","pt":1725068439757,"mc":[{"id":"1.232459454","rc":[{"batb":[[0,1.24,39.82]],"ltp":1.24,"tv":2499.48,"id":7587363}]}]}
{"op":"mcm","clk":"11999984997","pt":1725068443153,"mc":[{"id":"1.232459454","rc":[{"batl":[[0,1.29,112.18],[1,1.3,21.07],[2,1.33,19.67]],"ltp":1.24,"tv":2499.48,"id":7587363}]}]}
{"op":"mcm","clk":"11999985031","pt":1725068443565,"mc":[{"id":"1.232459454","rc":[{"batl":[[0,10,1.26],[1,14,0.26]],"ltp":5.1,"tv":382.91,"id":8858707}]}]}
{"op":"mcm","clk":"11999985157","pt":1725068445258,"mc":[{"id":"1.232459454","rc":[{"batl":[[0,8.6,1.08],[1,14,0.54]],"ltp":5.1,"tv":382.91,"id":8858707}]}]}
{"op":"mcm","clk":"11999985229","pt":1725068446043,"mc":[{"id":"1.232459454","rc":[{"batl":[[0,10,1.26],[1,14,0.26]],"ltp":5.1,"tv":382.91,"id":8858707},{"batl":[[0,1.29,41.89],[2,1.35,4.48]],"ltp":1.24,"tv":2499.48,"id":7587363}]}]}
{"op":"mcm","clk":"11999985387","pt":1725068447938,"mc":[{"id":"1.232459454","rc":[{"batl":[[0,1.29,42.04]],"ltp":1.24,"tv":2499.48,"id":7587363}]}]}
{"op":"mcm","clk":"11999985635","pt":1725068450974,"mc":[{"id":"1.232459454","rc":[{"batb":[[0,2.44,42.28]],"ltp":5.1,"tv":382.91,"id":8858707},{"batb":[[1,1.23,31.17]],"batl":[[1,1.35,4.63],[2,1.37,17.97]],"ltp":1.24,"tv":2499.48,"id":7587363}]}]}
{"op":"mcm","clk":"11999985690","pt":1725068451645,"mc":[{"id":"1.232459454","rc":[{"batl":[[1,14,0.35]],"ltp":5.1,"tv":382.91,"id":8858707}]}]}
{"op":"mcm","clk":"11999985845","pt":1725068453664,"mc":[{"id":"1.232459454","rc":[{"trd":[[1.28,8.73]],"batb":[[0,1.29,209.27],[1,1.24,39.82],[2,1.23,31.17]],"batl":[[0,1.35,4.64],[1,1.37,17.97],[2,1.4,4.24]],"ltp":1.28,"tv":2499.77,"id":7587363}],"tv":2882.69}]}
