{"op":"mcm","clk":"11893839000","pt":1724230720582,"mc":[{"id":"1.232089285","marketDefinition":{"bspMarket":false,"turnInPlayEnabled":true,"persistenceEnabled":true,"marketBaseRate":5.0,"eventId":"33514168","eventTypeId":"4","numberOfWinners":1,"bettingType":"ODDS","marketType":"MATCH_ODDS","marketTime":"2024-08-22T19:00:00.000Z","suspendTime":"2024-08-22T19:00:00.000Z","bspReconciled":false,"complete":true,"inPlay":false,"crossMatching":true,"runnersVoidable":false,"numberOfActiveRunners":2,"betDelay":0,"status":"OPEN","runners":[{"status":"ACTIVE","sortPriority":1,"id":67083366,"name":"New York Strikers"},{"status":"ACTIVE","sortPriority":2,"id":72922097,"name":"Caribbean Tigers"}],"regulators":["MR_INT"],"countryCode":"GB","discountAllowed":false,"timezone":"GMT","openDate":"2024-08-22T19:00:00.000Z","version":6088908184,"name":"Match Odds","eventName":"New York Strikers v Caribbean Tigers"},"rc":[{"batb":[[0,1.03,200],[1,1.02,200],[2,1.01,220]],"ltp":0.0,"tv":0.0,"id":67083366},{"batb":[[0,1.03,200],[1,1.02,200],[2,1.01,220]],"ltp":0.0,"tv":0.0,"id":72922097}]}]}
{"op":"mcm","clk":"11893839275","pt":1724230725653,"mc":[{"id":"1.232089285","marketDefinition":{"bspMarket":false,"turnInPlayEnabled":true,"persistenceEnabled":true,"marketBaseRate":5.0,"eventId":"33514168","eventTypeId":"4","numberOfWinners":1,"bettingType":"ODDS","marketType":"MATCH_ODDS","marketTime":"2024-08-22T19:00:00.000Z","suspendTime":"2024-08-22T19:00:00.000Z","bspReconciled":false,"complete":true,"inPlay":false,"crossMatching":true,"runnersVoidable":false,"numberOfActiveRunners":2,"betDelay":0,"status":"OPEN","runners":[{"status":"ACTIVE","sortPriority":1,"id":67083366,"name":"New York Strikers"},{"status":"ACTIVE","sortPriority":2,"id":72922097,"name":"Caribbean Tigers"}],"regulators":["MR_INT"],"countryCode":"GB","discountAllowed":true,"timezone":"GMT","openDate":"2024-08-22T19:00:00.000Z","version":6088908184,"name":"Match Odds","eventName":"New York Strikers v Caribbean Tigers"}}]}
{"op":"mcm","clk":"11894010043","pt":1724233232870,"mc":[{"id":"1.232089285","rc":[{"batb":[[0,1.2,1105],[1,1.03,200],[2,1.02,200]],"ltp":0.0,"tv":0.0,"id":67083366},{"batb":[[0,1.2,1105],[1,1.03,200],[2,1.02,200]],"ltp":0.0,"tv":0.0,"id":72922097}]}]}
{"op":"mcm","clk":"11894057959","pt":1724233903174,"mc":[{"id":"1.232089285","rc":[{"batb":[[1,1.04,1.53],[2,1.03,200]],"ltp":0.0,"tv":0.0,"id":67083366},{"batb":[[1,1.04,1.53],[2,1.03,200]],"ltp":0.0,"tv":0.0,"id":72922097}]}]}
{"op":"mcm","clk":"11894082982","pt":1724234265625,"mc":[{"id":"1.232089285","rc":[{"batb":[[0,1.21,7.13],[1,1.2,1105],[2,1.04,1.53]],"ltp":0.0,"tv":0.0,"id":67083366},{"batb":[[0,1.21,6.65],[1,1.2,1105],[2,1.04,1.53]],"ltp":0.0,"tv":0.0,"id":72922097}]}]}
{"op":"mcm","clk":"11894102092","pt":1724234479551,"mc":[{"id":"1.232089285","rc":[{"batb":[[0,1.21,7.12]],"ltp":0.0,"tv":0.0,"id":67083366},{"batb":[[0,1.21,6.65]],"ltp":0.0,"tv":0.0,"id":72922097}]}]}
{"op":"mcm","clk":"11894142828","pt":1724234940795,"mc":[{"id":"1.232089285","rc":[{"batl":[[0,5.9,10.91]],"ltp":0.0,"tv":0.0,"id":67083366},{"batl":[[0,5.9,10.92]],"ltp":0.0,"tv":0.0,"id":72922097}]}]}
{"op":"mcm","clk":"11894178590","pt":1724235357443,"mc":[{"id":"1.232089285","rc":[{"batb":[[0,1.21,7.66]],"ltp":0.0,"tv":0.0,"id":67083366}]}]}
{"op":"mcm","clk":"11894179543","pt":1724235367520,"mc":[{"id":"1.232089285","rc":[{"batb":[[0,1.21,7.18]],"ltp":0.0,"tv":0.0,"id":72922097}]}]}
{"op":"mcm","clk":"11894385679","pt":1724237456608,"mc":[{"id":"1.232089285","rc":[{"batb":[[0,1.21,90.93]],"ltp":0.0,"tv":0.0,"id":67083366}]}]}
{"op":"mcm","clk":"11894388941","pt":1724237495057,"mc":[{"id":"1.232089285","rc":[{"batb":[[0,1.21,90.45]],"ltp":0.0,"tv":0.0,"id":72922097}]}]}
{"op":"mcm","clk":"11894542835","pt":1724239221677,"mc":[{"id":"1.232089285","rc":[{"batb":[[0,1.22,39.51],[1,1.21,90.35],[2,1.2,1105]],"ltp":0.0,"tv":0.0,"id":67083366},{"batb":[[0,1.22,39.51],[1,1.21,89.88],[2,1.2,1105]],"ltp":0.0,"tv":0.0,"id":72922097}]}]}
{"op":"mcm","clk":"11894672235","pt":1724240565298,"mc":[{"id":"1.232089285","rc":[{"batb":[[0,1.23,7.65],[1,1.22,38.97],[2,1.21,83.24]],"ltp":0.0,"tv":0.0,"id":67083366},{"batb":[[0,1.23,7.17],[1,1.22,38.97],[2,1.21,83.24]],"ltp":0.0,"tv":0.0,"id":72922097}]}]}
{"op":"mcm","clk":"11894712754","pt":1724241023263,"mc":[{"id":"1.232089285","rc":[{"batb":[[1,1.21,83.24],[2,1.2,1105]],"ltp":0.0,"tv":0.0,"id":67083366},{"batb":[[1,1.21,83.24],[2,1.2,1105]],"ltp":0.0,"tv":0.0,"id":72922097}]}]}
{"op":"mcm","clk":"11894718118","pt":1724241084867,"mc":[{"id":"1.232089285","rc":[{"batb":[[0,1.23,7.11]],"ltp":0.0,"tv":0.0,"id":67083366}]}]}
{"op":"mcm","clk":"11894718402","pt":1724241088540,"mc":[{"id":"1.232089285","rc":[{"batb":[[0,1.23,6.64]],"ltp":0.0,"tv":0.0,"id":72922097}]}]}
{"op":"mcm","clk":"11894721581","pt":1724241125087,"mc":[{"id":"1.232089285","rc":[{"batb":[[0,1.24,35.72],[1,1.23,7.11],[2,1.21,83.24]],"ltp":0.0,"tv":0.0,"id":67083366},{"batb":[[0,1.24,35.72],[1,1.23,6.64],[2,1.21,83.24]],"ltp":0.0,"tv":0.0,"id":72922097}]}]}
{"op":"mcm","clk":"11894813657","pt":1724242374920,"mc":[{"id":"1.232089285","rc":[{"batb":[[0,1.24,35.72],[1,1.23,7.12],[2,1.21,83.26]],"ltp":0.0,"tv":0.0,"id":67083366},{"batb":[[0,1.24,35.72],[1,1.23,6.65],[2,1.21,83.26]],"ltp":0.0,"tv":0.0,"id":72922097}]}]}
{"op":"mcm","clk":"11894838891","pt":1724242644249,"mc":[{"id":"1.232089285","rc":[{"batb":[[0,1.25,7.12],[1,1.24,35.72]],"ltp":0.0,"tv":0.0,"id":67083366},{"batb":[[0,1.25,6.65],[1,1.24,35.72]],"ltp":0.0,"tv":0.0,"id":72922097}]}]}
{"op":"mcm","clk":"11894855760","pt":1724242926258,"mc":[{"id":"1.232089285","rc":[{"batb":[[1,1.21,83.26],[2,1.2,1105]],"ltp":0.0,"tv":0.0,"id":67083366},{"batb":[[1,1.21,83.26],[2,1.2,1105]],"ltp":0.0,"tv":0.0,"id":72922097}]}]}
{"op":"mcm","clk":"11894860820","pt":1724243005233,"mc":[{"id":"1.232089285","rc":[{"batb":[[0,1.26,32.97],[1,1.25,7.12],[2,1.21,83.26]],"ltp":0.0,"tv":0.0,"id":67083366},{"batb":[[0,1.26,32.97],[1,1.25,6.65],[2,1.21,83.26]],"ltp":0.0,"tv":0.0,"id":72922097}]}]}
{"op":"mcm","clk":"11894964497","pt":1724244697386,"mc":[{"id":"1.232089285","rc":[{"batb":[[0,1.27,7.12],[1,1.26,32.97]],"ltp":0.0,"tv":0.0,"id":67083366},{"batb":[[0,1.27,6.65],[1,1.26,32.97]],"ltp":0.0,"tv":0.0,"id":72922097}]}]}
{"op":"mcm","clk":"11894970522","pt":1724244805629,"mc":[{"id":"1.232089285","rc":[{"batb":[[1,1.21,83.26],[2,1.2,1105]],"ltp":0.0,"tv":0.0,"id":67083366}]}]}
{"op":"mcm","clk":"11894970537","pt":1724244805833,"mc":[{"id":"1.232089285","rc":[{"batb":[[1,1.21,83.26],[2,1.2,1105]],"ltp":0.0,"tv":0.0,"id":72922097}]}]}
{"op":"mcm","clk":"11894973756","pt":1724244861802,"mc":[{"id":"1.232089285","rc":[{"batb":[[0,1.28,30.62],[1,1.27,7.12],[2,1.21,83.26]],"ltp":0.0,"tv":0.0,"id":67083366},{"batb":[[0,1.28,30.62],[1,1.27,6.65],[2,1.21,83.26]],"ltp":0.0,"tv":0.0,"id":72922097}]}]}
{"op":"mcm","clk":"11895084054","pt":1724246663175,"mc":[{"id":"1.232089285","rc":[{"batb":[[0,1.27,7.11],[1,1.21,83.31],[2,1.2,1105]],"ltp":0.0,"tv":0.0,"id":67083366},{"batb":[[0,1.27,6.64],[1,1.21,83.31],[2,1.2,1105]],"ltp":0.0,"tv":0.0,"id":72922097}]}]}
{"op":"mcm","clk":"11895086852","pt":1724246705829,"mc":[{"id":"1.232089285","rc":[{"batb":[[0,1.28,30.61],[1,1.27,7.11],[2,1.21,83.31]],"ltp":0.0,"tv":0.0,"id":67083366},{"batb":[[0,1.28,30.61],[1,1.27,6.64],[2,1.21,83.31]],"ltp":0.0,"tv":0.0,"id":72922097}]}]}
{"op":"mcm","clk":"11895092977","pt":1724246808366,"mc":[{"id":"1.232089285","rc":[{"batb":[[0,1.29,7.11],[1,1.28,30.61]],"ltp":0.0,"tv":0.0,"id":67083366},{"batb":[[0,1.29,6.64],[1,1.28,30.61]],"ltp":0.0,"tv":0.0,"id":72922097}]}]}
{"op":"mcm","clk":"11895221692","pt":1724248506567,"mc":[{"id":"1.232089285","rc":[{"batb":[[1,1.21,83.31],[2,1.2,1105]],"ltp":0.0,"tv":0.0,"id":67083366},{"batb":[[1,1.21,83.31],[2,1.2,1105]],"ltp":0.0,"tv":0.0,"id":72922097}]}]}
{"op":"mcm","clk":"11895223771","pt":1724248536584,"mc":[{"id":"1.232089285","rc":[{"batb":[[0,1.3,28.57],[1,1.29,7.11],[2,1.21,83.31]],"ltp":0.0,"tv":0.0,"id":67083366},{"batb":[[0,1.3,28.57],[1,1.29,6.64],[2,1.21,83.31]],"ltp":0.0,"tv":0.0,"id":72922097}]}]}
{"op":"mcm","clk":"11895256262","pt":1724248962314,"mc":[{"id":"1.232089285","rc":[{"batb":[[0,1.31,7.11],[1,1.3,28.53],[2,1.21,83.14]],"ltp":0.0,"tv":0.0,"id":67083366},{"batb":[[0,1.31,6.64],[1,1.3,28.53],[2,1.21,83.14]],"ltp":0.0,"tv":0.0,"id":72922097}]}]}
{"op":"mcm","clk":"11895377126","pt":1724250337983,"mc":[{"id":"1.232089285","rc":[{"batb":[[1,1.21,83.14],[2,1.2,1105]],"ltp":0.0,"tv":0.0,"id":67083366},{"batb":[[1,1.21,83.14],[2,1.2,1105]],"ltp":0.0,"tv":0.0,"id":72922097}]}]}
{"op":"mcm","clk":"11895378441","pt":1724250354683,"mc":[{"id":"1.232089285","rc":[{"batb":[[0,1.32,26.75],[1,1.31,7.11],[2,1.21,83.14]],"ltp":0.0,"tv":0.0,"id":67083366},{"batb":[[0,1.32,26.75],[1,1.31,6.64],[2,1.21,83.14]],"ltp":0.0,"tv":0.0,"id":72922097}]}]}
{"op":"mcm","clk":"11895443381","pt":1724251125361,"mc":[{"id":"1.232089285","rc":[{"batb":[[0,1.33,7.11],[1,1.32,26.75]],"ltp":0.0,"tv":0.0,"id":67083366}]}]}
{"op":"mcm","clk":"11895443425","pt":1724251125868,"mc":[{"id":"1.232089285","rc":[{"batb":[[0,1.33,6.64],[1,1.32,26.75]],"ltp":0.0,"tv":0.0,"id":72922097}]}]}
{"op":"mcm","clk":"11895542401","pt":1724252155116,"mc":[{"id":"1.232089285","rc":[{"batb":[[1,1.21,83.14],[2,1.2,1105]],"ltp":0.0,"tv":0.0,"id":67083366},{"batb":[[1,1.21,83.14],[2,1.2,1105]],"ltp":0.0,"tv":0.0,"id":72922097}]}]}
{"op":"mcm","clk":"11895551732","pt":1724252269107,"mc":[{"id":"1.232089285","rc":[{"batb":[[0,1.34,25.18],[1,1.33,7.11],[2,1.21,83.14]],"ltp":0.0,"tv":0.0,"id":67083366},{"batb":[[0,1.34,25.18],[1,1.33,6.64],[2,1.21,83.14]],"ltp":0.0,"tv":0.0,"id":72922097}]}]}
{"op":"mcm","clk":"11895654269","pt":1724253174887,"mc":[{"id":"1.232089285","rc":[{"batb":[[1,1.33,7.11],[2,1.21,83.22]],"ltp":0.0,"tv":0.0,"id":67083366},{"batb":[[1,1.33,6.63],[2,1.21,83.22]],"ltp":0.0,"tv":0.0,"id":72922097}]}]}
{"op":"mcm","clk":"11895682147","pt":1724253334430,"mc":[{"id":"1.232089285","rc":[{"batb":[[0,1.35,7.11],[1,1.34,25.18]],"ltp":0.0,"tv":0.0,"id":67083366}]}]}
{"op":"mcm","clk":"11895682195","pt":1724253334859,"mc":[{"id":"1.232089285","rc":[{"batb":[[0,1.35,6.63],[1,1.34,25.18]],"ltp":0.0,"tv":0.0,"id":72922097}]}]}
{"op":"mcm","clk":"11895779428","pt":1724254070054,"mc":[{"id":"1.232089285","rc":[{"batb":[[1,1.21,83.22],[2,1.2,1105]],"ltp":0.0,"tv":0.0,"id":67083366},{"batb":[[1,1.21,83.22],[2,1.2,1105]],"ltp":0.0,"tv":0.0,"id":72922097}]}]}
{"op":"mcm","clk":"11895800572","pt":1724254236468,"mc":[{"id":"1.232089285","rc":[{"batb":[[0,1.36,23.78],[1,1.35,7.11],[2,1.21,83.22]],"ltp":0.0,"tv":0.0,"id":67083366},{"batb":[[0,1.36,23.78],[1,1.35,6.63],[2,1.21,83.22]],"ltp":0.0,"tv":0.0,"id":72922097}]}]}
{"op":"mcm","clk":"11895995491","pt":1724255517587,"mc":[{"id":"1.232089285","rc":[{"batb":[[1,1.21,83.22],[2,1.2,1105]],"ltp":0.0,"tv":0.0,"id":67083366}]}]}
{"op":"mcm","clk":"11895995585","pt":1724255518063,"mc":[{"id":"1.232089285","rc":[{"batb":[[1,1.22,7.11],[2,1.21,83.22]],"ltp":0.0,"tv":0.0,"id":67083366},{"batb":[[1,1.22,6.63]],"ltp":0.0,"tv":0.0,"id":72922097}]}]}
{"op":"mcm","clk":"11896068701","pt":1724256037436,"mc":[{"id":"1.232089285","rc":[{"batb":[[0,1.22,7.1],[1,1.21,83.31],[2,1.2,1105]],"ltp":0.0,"tv":0.0,"id":67083366},{"batb":[[0,1.22,6.62],[1,1.21,83.31],[2,1.2,1105]],"ltp":0.0,"tv":0.0,"id":72922097}]}]}
{"op":"mcm","clk":"11896094021","pt":1724256200758,"mc":[{"id":"1.232089285","rc":[{"batb":[[0,1.23,37.23],[1,1.22,7.1],[2,1.21,83.31]],"ltp":0.0,"tv":0.0,"id":67083366},{"batb":[[0,1.23,37.23],[1,1.22,6.62],[2,1.21,83.31]],"ltp":0.0,"tv":0.0,"id":72922097}]}]}
{"op":"mcm","clk":"11896337773","pt":1724257680199,"mc":[{"id":"1.232089285","rc":[{"batb":[[0,1.24,7.1],[1,1.23,37.23]],"ltp":0.0,"tv":0.0,"id":67083366},{"batb":[[0,1.24,6.62],[1,1.23,37.23]],"ltp":0.0,"tv":0.0,"id":72922097}]}]}
{"op":"mcm","clk":"11896388538","pt":1724258001221,"mc":[{"id":"1.232089285","rc":[{"batb":[[1,1.21,83.31],[2,1.2,1105]],"ltp":0.0,"tv":0.0,"id":67083366},{"batb":[[1,1.21,83.31],[2,1.2,1105]],"ltp":0.0,"tv":0.0,"id":72922097}]}]}
{"op":"mcm","clk":"11896413778","pt":1724258145726,"mc":[{"id":"1.232089285","rc":[{"batb":[[0,1.25,34.25],[1,1.24,7.1],[2,1.21,83.31]],"ltp":0.0,"tv":0.0,"id":67083366},{"batb":[[0,1.25,34.25],[1,1.24,6.62],[2,1.21,83.31]],"ltp":0.0,"tv":0.0,"id":72922097}]}]}
{"op":"mcm","clk":"11896690829","pt":1724259653524,"mc":[{"id":"1.232089285","rc":[{"batb":[[0,1.26,7.09],[1,1.25,34.23],[2,1.21,83.2]],"ltp":0.0,"tv":0.0,"id":67083366},{"batb":[[0,1.25,34.23],[1,1.24,6.62],[2,1.21,83.2]],"ltp":0.0,"tv":0.0,"id":72922097}]}]}
{"op":"mcm","clk":"11896690891","pt":1724259653951,"mc":[{"id":"1.232089285","rc":[{"batb":[[0,1.26,6.62],[1,1.25,34.23]],"ltp":0.0,"tv":0.0,"id":72922097}]}]}
{"op":"mcm","clk":"11896741902","pt":1724259953993,"mc":[{"id":"1.232089285","rc":[{"batb":[[1,1.21,83.2],[2,1.2,1105]],"ltp":0.0,"tv":0.0,"id":67083366},{"batb":[[1,1.21,83.2],[2,1.2,1105]],"ltp":0.0,"tv":0.0,"id":72922097}]}]}
{"op":"mcm","clk":"11896767185","pt":1724260097180,"mc":[{"id":"1.232089285","rc":[{"batb":[[0,1.27,31.69],[1,1.26,7.09],[2,1.21,83.2]],"ltp":0.0,"tv":0.0,"id":67083366},{"batb":[[0,1.27,31.69],[1,1.26,6.62],[2,1.21,83.2]],"ltp":0.0,"tv":0.0,"id":72922097}]}]}
{"op":"mcm","clk":"11897034265","pt":1724261702213,"mc":[{"id":"1.232089285","rc":[{"batb":[[0,1.28,7.09],[1,1.27,31.69]],"ltp":0.0,"tv":0.0,"id":67083366},{"batb":[[0,1.28,6.62],[1,1.27,31.69]],"ltp":0.0,"tv":0.0,"id":72922097}]}]}
{"op":"mcm","clk":"11897065738","pt":1724261897517,"mc":[{"id":"1.232089285","rc":[{"batb":[[1,1.21,83.2],[2,1.2,1105]],"ltp":0.0,"tv":0.0,"id":72922097}]}]}
{"op":"mcm","clk":"11897065787","pt":1724261897785,"mc":[{"id":"1.232089285","rc":[{"batb":[[1,1.21,83.2],[2,1.2,1105]],"ltp":0.0,"tv":0.0,"id":67083366}]}]}
{"op":"mcm","clk":"11897082971","pt":1724262010817,"mc":[{"id":"1.232089285","rc":[{"batb":[[0,1.29,29.51],[1,1.28,7.09],[2,1.21,83.2]],"ltp":0.0,"tv":0.0,"id":67083366},{"batb":[[0,1.29,29.51],[1,1.28,6.62],[2,1.21,83.2]],"ltp":0.0,"tv":0.0,"id":72922097}]}]}
{"op":"mcm","clk":"11897334061","pt":1724263690616,"mc":[{"id":"1.232089285","rc":[{"batb":[[0,1.29,29.52],[1,1.21,83.24],[2,1.2,1105]],"ltp":0.0,"tv":0.0,"id":67083366},{"batb":[[0,1.29,29.52],[1,1.28,6.61],[2,1.21,83.24]],"ltp":0.0,"tv":0.0,"id":72922097}]}]}
{"op":"mcm","clk":"11897334177","pt":1724263691201,"mc":[{"id":"1.232089285","rc":[{"batb":[[0,1.3,7.09],[1,1.29,29.52],[2,1.21,83.24]],"ltp":0.0,"tv":0.0,"id":67083366},{"batb":[[0,1.3,6.61],[1,1.29,29.52]],"ltp":0.0,"tv":0.0,"id":72922097}]}]}
{"op":"mcm","clk":"11897355639","pt":1724263811598,"mc":[{"id":"1.232089285","rc":[{"batb":[[1,1.21,83.24],[2,1.2,1105]],"ltp":0.0,"tv":0.0,"id":72922097}]}]}
{"op":"mcm","clk":"11897355678","pt":1724263811803,"mc":[{"id":"1.232089285","rc":[{"batb":[[1,1.21,83.24],[2,1.2,1105]],"ltp":0.0,"tv":0.0,"id":67083366}]}]}
{"op":"mcm","clk":"11897366346","pt":1724263868796,"mc":[{"id":"1.232089285","rc":[{"batb":[[0,1.31,27.61],[1,1.3,7.09],[2,1.21,83.24]],"ltp":0.0,"tv":0.0,"id":67083366},{"batb":[[0,1.31,27.61],[1,1.3,6.61],[2,1.21,83.24]],"ltp":0.0,"tv":0.0,"id":72922097}]}]}
{"op":"mcm","clk":"11897440694","pt":1724264209570,"mc":[{"id":"1.232089285","rc":[{"batb":[[0,1.32,20],[1,1.31,27.61],[2,1.3,7.09]],"ltp":0.0,"tv":0.0,"id":67083366},{"batb":[[0,1.32,20],[1,1.31,27.61],[2,1.3,6.61]],"ltp":0.0,"tv":0.0,"id":72922097}]}]}
{"op":"mcm","clk":"11897713715","pt":1724265661577,"mc":[{"id":"1.232089285","rc":[{"batb":[[0,1.32,27.09],[2,1.21,83.24]],"ltp":0.0,"tv":0.0,"id":67083366}]}]}
{"op":"mcm","clk":"11897713824","pt":1724265662070,"mc":[{"id":"1.232089285","rc":[{"batb":[[0,1.32,26.61],[2,1.21,83.24]],"ltp":0.0,"tv":0.0,"id":72922097}]}]}
{"op":"mcm","clk":"11897715261","pt":1724265669455,"mc":[{"id":"1.232089285","rc":[{"batb":[[1,1.21,83.24],[2,1.2,1105]],"ltp":0.0,"tv":0.0,"id":72922097}]}]}
{"op":"mcm","clk":"11897715296","pt":1724265669654,"mc":[{"id":"1.232089285","rc":[{"batb":[[1,1.21,83.24],[2,1.2,1105]],"ltp":0.0,"tv":0.0,"id":67083366}]}]}
{"op":"mcm","clk":"11897719879","pt":1724265694901,"mc":[{"id":"1.232089285","rc":[{"batb":[[0,1.33,25.94],[1,1.32,27.09],[2,1.21,83.24]],"ltp":0.0,"tv":0.0,"id":67083366},{"batb":[[0,1.33,25.94],[1,1.32,26.61],[2,1.21,83.24]],"ltp":0.0,"tv":0.0,"id":72922097}]}]}
{"op":"mcm","clk":"11898001681","pt":1724267495577,"mc":[{"id":"1.232089285","rc":[{"batb":[[0,1.32,27.08],[1,1.21,83.23],[2,1.2,1105]],"ltp":0.0,"tv":0.0,"id":67083366},{"batb":[[0,1.32,26.61],[1,1.21,83.23],[2,1.2,1105]],"ltp":0.0,"tv":0.0,"id":72922097}]}]}
{"op":"mcm","clk":"11898022012","pt":1724267615596,"mc":[{"id":"1.232089285","rc":[{"batb":[[0,1.32,20],[1,1.22,7.08],[2,1.21,83.23]],"ltp":0.0,"tv":0.0,"id":67083366},{"batb":[[0,1.32,20]],"ltp":0.0,"tv":0.0,"id":72922097}]}]}
{"op":"mcm","clk":"11898022029","pt":1724267615703,"mc":[{"id":"1.232089285","rc":[{"batb":[[1,1.22,6.61],[2,1.21,83.23]],"ltp":0.0,"tv":0.0,"id":72922097}]}]}
{"op":"mcm","clk":"11898029499","pt":1724267665986,"mc":[{"id":"1.232089285","rc":[{"batb":[[0,1.33,25.93],[1,1.32,20],[2,1.22,7.08]],"ltp":0.0,"tv":0.0,"id":67083366},{"batb":[[0,1.33,25.93],[1,1.32,20],[2,1.22,6.61]],"ltp":0.0,"tv":0.0,"id":72922097}]}]}
{"op":"mcm","clk":"11898300407","pt":1724269466586,"mc":[{"id":"1.232089285","rc":[{"batb":[[0,1.32,20],[1,1.22,7.08],[2,1.21,83.23]],"ltp":0.0,"tv":0.0,"id":67083366},{"batb":[[0,1.32,20],[1,1.22,6.61],[2,1.21,83.23]],"ltp":0.0,"tv":0.0,"id":72922097}]}]}
{"op":"mcm","clk":"11898314850","pt":1724269570001,"mc":[{"id":"1.232089285","rc":[{"batb":[[0,1.33,25.93],[1,1.32,20],[2,1.22,7.08]],"ltp":0.0,"tv":0.0,"id":67083366},{"batb":[[0,1.33,25.93],[1,1.32,20],[2,1.22,6.61]],"ltp":0.0,"tv":0.0,"id":72922097}]}]}
{"op":"mcm","clk":"11898321358","pt":1724269617158,"mc":[{"id":"1.232089285","rc":[{"batb":[[0,1.34,7.08],[1,1.33,25.93],[2,1.32,20]],"ltp":0.0,"tv":0.0,"id":67083366},{"batb":[[0,1.34,6.61],[1,1.33,25.93],[2,1.32,20]],"ltp":0.0,"tv":0.0,"id":72922097}]}]}
{"op":"mcm","clk":"11898482375","pt":1724271370572,"mc":[{"id":"1.232089285","rc":[{"batb":[[0,1.34,7.09],[1,1.32,20],[2,1.21,83.31]],"ltp":0.0,"tv":0.0,"id":67083366},{"batb":[[0,1.34,6.62],[1,1.33,25.95]],"ltp":0.0,"tv":0.0,"id":72922097}]}]}
{"op":"mcm","clk":"11898482400","pt":1724271370733,"mc":[{"id":"1.232089285","rc":[{"batb":[[1,1.32,20],[2,1.21,83.31]],"ltp":0.0,"tv":0.0,"id":72922097}]}]}
{"op":"mcm","clk":"11898494119","pt":1724271495818,"mc":[{"id":"1.232089285","rc":[{"batb":[[0,1.35,24.46],[1,1.34,7.09],[2,1.32,20]],"ltp":0.0,"tv":0.0,"id":67083366},{"batb":[[0,1.35,24.46],[1,1.34,6.62],[2,1.32,20]],"ltp":0.0,"tv":0.0,"id":72922097}]}]}
{"op":"mcm","clk":"11898516004","pt":1724271716625,"mc":[{"id":"1.232089285","rc":[{"batb":[[0,1.36,7.09],[1,1.35,24.46]],"ltp":0.0,"tv":0.0,"id":67083366},{"batb":[[0,1.36,6.62],[1,1.35,24.46]],"ltp":0.0,"tv":0.0,"id":72922097}]}]}
{"op":"mcm","clk":"11898638953","pt":1724273290840,"mc":[{"id":"1.232089285","rc":[{"batb":[[0,1.37,20],[1,1.36,7.09],[2,1.35,24.46]],"ltp":0.0,"tv":0.0,"id":67083366},{"batb":[[0,1.38,20],[1,1.36,6.62],[2,1.35,24.46]],"ltp":0.0,"tv":0.0,"id":72922097}]}]}
{"op":"mcm","clk":"11898639337","pt":1724273296287,"mc":[{"id":"1.232089285","rc":[{"batb":[[2,1.21,83.31]],"ltp":0.0,"tv":0.0,"id":67083366},{"batb":[[2,1.21,83.31]],"ltp":0.0,"tv":0.0,"id":72922097}]}]}
{"op":"mcm","clk":"11898643269","pt":1724273355352,"mc":[{"id":"1.232089285","rc":[{"batb":[[0,1.38,22.53],[1,1.37,20],[2,1.36,7.09]],"ltp":0.0,"tv":0.0,"id":67083366},{"batb":[[0,1.39,21.95],[1,1.38,20],[2,1.36,6.62]],"ltp":0.0,"tv":0.0,"id":72922097}]}]}
{"op":"mcm","clk":"11898662047","pt":1724273689234,"mc":[{"id":"1.232089285","rc":[{"batb":[[2,1.22,7.09]],"ltp":0.0,"tv":0.0,"id":67083366},{"batb":[[2,1.22,6.62]],"ltp":0.0,"tv":0.0,"id":72922097}]}]}
{"op":"mcm","clk":"11898714959","pt":1724274774850,"mc":[{"id":"1.232089285","rc":[{"batb":[[0,1.38,22.52]],"ltp":0.0,"tv":0.0,"id":67083366},{"batb":[[0,1.39,21.95]],"ltp":0.0,"tv":0.0,"id":72922097}]}]}
{"op":"mcm","clk":"11898738646","pt":1724275155881,"mc":[{"id":"1.232089285","rc":[{"batb":[[0,1.37,20],[1,1.22,7.09],[2,1.21,83.33]],"ltp":0.0,"tv":0.0,"id":67083366},{"batb":[[0,1.38,20],[1,1.22,6.62],[2,1.21,83.33]],"ltp":0.0,"tv":0.0,"id":72922097}]}]}
{"op":"mcm","clk":"11898739603","pt":1724275175493,"mc":[{"id":"1.232089285","rc":[{"batb":[[0,1.38,22.52],[1,1.37,20],[2,1.22,7.09]],"ltp":0.0,"tv":0.0,"id":67083366},{"batb":[[0,1.39,21.95],[1,1.38,20],[2,1.22,6.62]],"ltp":0.0,"tv":0.0,"id":72922097}]}]}
{"op":"mcm","clk":"11898759641","pt":1724275630018,"mc":[{"id":"1.232089285","rc":[{"batl":[[0,2.5,1]],"ltp":0.0,"tv":0.0,"id":72922097}]}]}
{"op":"mcm","clk":"11898760249","pt":1724275642836,"mc":[{"id":"1.232089285","rc":[{"batl":[[0,2.5,1]],"ltp":0.0,"tv":0.0,"id":67083366}]}]}
{"op":"mcm","clk":"11898818895","pt":1724276976120,"mc":[{"id":"1.232089285","rc":[{"batb":[[0,1.37,20],[1,1.22,7.09],[2,1.21,83.33]],"ltp":0.0,"tv":0.0,"id":67083366},{"batb":[[0,1.38,20],[1,1.22,6.62],[2,1.21,83.33]],"ltp":0.0,"tv":0.0,"id":72922097}]}]}
{"op":"mcm","clk":"11898827557","pt":1724277152745,"mc":[{"id":"1.232089285","rc":[{"batb":[[0,1.38,22.52],[1,1.37,20],[2,1.22,7.09]],"ltp":0.0,"tv":0.0,"id":67083366},{"batb":[[0,1.39,21.95],[1,1.38,20],[2,1.22,6.62]],"ltp":0.0,"tv":0.0,"id":72922097}]}]}
{"op":"mcm","clk":"11898927530","pt":1724278953150,"mc":[{"id":"1.232089285","rc":[{"batb":[[0,1.37,20],[1,1.22,7.09],[2,1.21,83.27]],"ltp":0.0,"tv":0.0,"id":67083366},{"batb":[[0,1.38,20],[1,1.22,6.61],[2,1.21,83.27]],"ltp":0.0,"tv":0.0,"id":72922097}]}]}
{"op":"mcm","clk":"11898935788","pt":1724279090949,"mc":[{"id":"1.232089285","rc":[{"batb":[[0,1.38,22.52],[1,1.37,20],[2,1.22,7.09]],"ltp":0.0,"tv":0.0,"id":67083366},{"batb":[[0,1.39,21.94],[1,1.38,20],[2,1.22,6.61]],"ltp":0.0,"tv":0.0,"id":72922097}]}]}
{"op":"mcm","clk":"11899048828","pt":1724280891424,"mc":[{"id":"1.232089285","rc":[{"batb":[[0,1.37,20],[1,1.22,7.09],[2,1.21,83.27]],"ltp":0.0,"tv":0.0,"id":67083366},{"batb":[[0,1.38,20],[1,1.22,6.61],[2,1.21,83.27]],"ltp":0.0,"tv":0.0,"id":72922097}]}]}
{"op":"mcm","clk":"11899054347","pt":1724281007480,"mc":[{"id":"1.232089285","rc":[{"batb":[[0,1.38,22.52],[1,1.37,20],[2,1.22,7.09]],"ltp":0.0,"tv":0.0,"id":67083366},{"batb":[[0,1.39,21.94],[1,1.38,20],[2,1.22,6.61]],"ltp":0.0,"tv":0.0,"id":72922097}]}]}
{"op":"mcm","clk":"11899141273","pt":1724282808437,"mc":[{"id":"1.232089285","rc":[{"batb":[[0,1.37,20],[1,1.22,7.09],[2,1.21,83.29]],"ltp":0.0,"tv":0.0,"id":67083366},{"batb":[[0,1.39,21.96]],"ltp":0.0,"tv":0.0,"id":72922097}]}]}
{"op":"mcm","clk":"11899141280","pt":1724282808643,"mc":[{"id":"1.232089285","rc":[{"batb":[[0,1.38,20],[1,1.22,6.61],[2,1.21,83.29]],"ltp":0.0,"tv":0.0,"id":72922097}]}]}
{"op":"mcm","clk":"11899145451","pt":1724282900660,"mc":[{"id":"1.232089285","rc":[{"batb":[[0,1.38,22.53],[1,1.37,20],[2,1.22,7.09]],"ltp":0.0,"tv":0.0,"id":67083366},{"batb":[[0,1.39,21.96],[1,1.38,20],[2,1.22,6.61]],"ltp":0.0,"tv":0.0,"id":72922097}]}]}
{"op":"mcm","clk":"11899226329","pt":1724284701190,"mc":[{"id":"1.232089285","rc":[{"batb":[[0,1.37,20],[1,1.22,7.09],[2,1.21,83.29]],"ltp":0.0,"tv":0.0,"id":67083366},{"batb":[[0,1.38,20],[1,1.22,6.61],[2,1.21,83.29]],"ltp":0.0,"tv":0.0,"id":72922097}]}]}
{"op":"mcm","clk":"11899230226","pt":1724284776911,"mc":[{"id":"1.232089285","rc":[{"batb":[[0,1.38,22.53],[1,1.37,20],[2,1.22,7.09]],"ltp":0.0,"tv":0.0,"id":67083366},{"batb":[[0,1.39,21.96],[1,1.38,20],[2,1.22,6.61]],"ltp":0.0,"tv":0.0,"id":72922097}]}]}
{"op":"mcm","clk":"11899336761","pt":1724286577410,"mc":[{"id":"1.232089285","rc":[{"batb":[[0,1.37,20],[1,1.22,7.09],[2,1.21,83.31]],"ltp":0.0,"tv":0.0,"id":67083366},{"batb":[[0,1.38,20],[1,1.22,6.62],[2,1.21,83.31]],"ltp":0.0,"tv":0.0,"id":72922097}]}]}
{"op":"mcm","clk":"11899339501","pt":1724286628188,"mc":[{"id":"1.232089285","rc":[{"batb":[[0,1.38,22.53],[1,1.37,20],[2,1.22,7.09]],"ltp":0.0,"tv":0.0,"id":67083366},{"batb":[[0,1.39,21.96],[1,1.38,20],[2,1.22,6.62]],"ltp":0.0,"tv":0.0,"id":72922097}]}]}
{"op":"mcm","clk":"11899365374","pt":1724287075471,"mc":[{"id":"1.232089285","rc":[{"batl":[[0,2.5,1.93]],"ltp":0.0,"tv":0.0,"id":72922097}]}]}
{"op":"mcm","clk":"11899366129","pt":1724287089848,"mc":[{"id":"1.232089285","rc":[{"batl":[[0,2.5,1.93]],"ltp":0.0,"tv":0.0,"id":67083366}]}]}
{"op":"mcm","clk":"11899444684","pt":1724288428558,"mc":[{"id":"1.232089285","rc":[{"batb":[[0,1.37,20],[1,1.22,7.09],[2,1.21,83.25]],"ltp":0.0,"tv":0.0,"id":67083366},{"batb":[[0,1.38,20],[1,1.22,6.62],[2,1.21,83.25]],"ltp":0.0,"tv":0.0,"id":72922097}]}]}
{"op":"mcm","clk":"11899761899","pt":1724294923853,"mc":[{"id":"1.232089285","rc":[{"batb":[[0,1.37,20.89],[1,1.22,7.09],[2,1.21,83.23]],"ltp":0.0,"tv":0.0,"id":67083366},{"batb":[[1,1.22,6.62],[2,1.21,83.23]],"ltp":0.0,"tv":0.0,"id":72922097}]}]}
{"op":"mcm","clk":"11899819446","pt":1724296374942,"mc":[{"id":"1.232089285","rc":[{"batb":[[2,1.21,83.22]],"ltp":0.0,"tv":0.0,"id":67083366},{"batb":[[2,1.21,83.22]],"ltp":0.0,"tv":0.0,"id":72922097}]}]}
{"op":"mcm","clk":"11899848364","pt":1724296898822,"mc":[{"id":"1.232089285","rc":[{"trd":[[2.32,0.93]],"batl":[[0,2.5,1]],"ltp":2.32,"tv":0.93,"id":67083366},{"trd":[[1.75,1.24]],"batl":[[0,1.75,3.95],[1,2.5,1.93]],"ltp":1.75,"tv":1.24,"id":72922097}],"tv":2.17}]}
{"op":"mcm","clk":"11899895897","pt":1724298316870,"mc":[{"id":"1.232089285","rc":[{"trd":[[2.32,3.91]],"ltp":2.32,"tv":3.91,"id":67083366},{"trd":[[1.75,5.19]],"batl":[[0,2.5,1.93],[1,2.5,0]],"ltp":1.75,"tv":5.19,"id":72922097}],"tv":9.1}]}
{"op":"mcm","clk":"11899896026","pt":1724298320455,"mc":[{"id":"1.232089285","rc":[{"batl":[[0,2.5,1]],"ltp":1.75,"tv":5.19,"id":72922097}]}]}
{"op":"mcm","clk":"11899896964","pt":1724298348910,"mc":[{"id":"1.232089285","rc":[{"batb":[[0,1.98,4.62],[1,1.37,20.89],[2,1.22,7.09]],"ltp":2.32,"tv":3.91,"id":67083366}]}]}
{"op":"mcm","clk":"11899898500","pt":1724298398569,"mc":[{"id":"1.232089285","rc":[{"batb":[[0,1.98,4.58]],"ltp":2.32,"tv":3.91,"id":67083366}]}]}
{"op":"mcm","clk":"11899899034","pt":1724298414540,"mc":[{"id":"1.232089285","rc":[{"batb":[[0,2,4.54]],"ltp":2.32,"tv":3.91,"id":67083366}]}]}
{"op":"mcm","clk":"11899907919","pt":1724298703976,"mc":[{"id":"1.232089285","rc":[{"batb":[[0,2.2,4.12]],"ltp":2.32,"tv":3.91,"id":67083366}]}]}
{"op":"mcm","clk":"11899909278","pt":1724298743511,"mc":[{"id":"1.232089285","rc":[{"trd":[[2.5,2]],"batb":[[0,2.5,2.64],[1,2.2,4.12],[2,1.37,20.89]],"ltp":2.5,"tv":5.91,"id":67083366}],"tv":11.1}]}
{"op":"mcm","clk":"11899909389","pt":1724298746946,"mc":[{"id":"1.232089285","rc":[{"batb":[[1,1.37,20.89],[2,1.22,7.09]],"ltp":2.5,"tv":5.91,"id":67083366}]}]}
{"op":"mcm","clk":"11899910144","pt":1724298771460,"mc":[{"id":"1.232089285","rc":[{"batb":[[0,1.42,3.91],[1,1.38,20],[2,1.22,6.62]],"ltp":1.75,"tv":5.19,"id":72922097}]}]}
{"op":"mcm","clk":"11899910335","pt":1724298777555,"mc":[{"id":"1.232089285","rc":[{"batb":[[0,1.38,20],[1,1.22,6.62],[2,1.21,83.22]],"ltp":1.75,"tv":5.19,"id":72922097}]}]}
{"op":"mcm","clk":"11899910339","pt":1724298777655,"mc":[{"id":"1.232089285","rc":[{"batb":[[0,1.42,4.08],[1,1.38,20],[2,1.22,6.62]],"ltp":1.75,"tv":5.19,"id":72922097}]}]}
{"op":"mcm","clk":"11899911301","pt":1724298806491,"mc":[{"id":"1.232089285","rc":[{"batb":[[0,1.42,5.02]],"ltp":1.75,"tv":5.19,"id":72922097}]}]}
{"op":"mcm","clk":"11899911372","pt":1724298808790,"mc":[{"id":"1.232089285","rc":[{"trd":[[2.5,7.28]],"batb":[[0,1.37,20.89],[1,1.22,7.09],[2,1.21,83.22]],"batl":[[0,2.5,0.91]],"ltp":2.5,"tv":11.19,"id":67083366}],"tv":16.38}]}
{"op":"mcm","clk":"11899912061","pt":1724298833432,"mc":[{"id":"1.232089285","rc":[{"batl":[[0,2.5,1.93]],"ltp":1.75,"tv":5.19,"id":72922097}]}]}
{"op":"mcm","clk":"11899912341","pt":1724298842569,"mc":[{"id":"1.232089285","rc":[{"batb":[[0,1.42,4.08]],"ltp":1.75,"tv":5.19,"id":72922097}]}]}
{"op":"mcm","clk":"11899912345","pt":1724298842673,"mc":[{"id":"1.232089285","rc":[{"batb":[[0,1.42,5.02]],"ltp":1.75,"tv":5.19,"id":72922097}]}]}
{"op":"mcm","clk":"11899913265","pt":1724298870597,"mc":[{"id":"1.232089285","rc":[{"batl":[[0,2.5,1]],"ltp":1.75,"tv":5.19,"id":72922097}]}]}
{"op":"mcm","clk":"11899913270","pt":1724298870695,"mc":[{"id":"1.232089285","rc":[{"batl":[[0,2.5,1.93]],"ltp":1.75,"tv":5.19,"id":72922097}]}]}
{"op":"mcm","clk":"11899913610","pt":1724298882521,"mc":[{"id":"1.232089285","rc":[{"batl":[[0,2.3,2.55],[1,2.5,1]],"ltp":1.75,"tv":5.19,"id":72922097}]}]}
{"op":"mcm","clk":"11899914635","pt":1724298917037,"mc":[{"id":"1.232089285","rc":[{"batb":[[0,1.78,10.97],[1,1.37,20.89],[2,1.22,7.09]],"ltp":2.5,"tv":11.19,"id":67083366},{"batb":[[0,1.43,20.84],[1,1.42,4.08],[2,1.38,20]],"ltp":1.75,"tv":5.19,"id":72922097}]}]}
{"op":"mcm","clk":"11899917116","pt":1724299005636,"mc":[{"id":"1.232089285","rc":[{"batb":[[0,1.43,24.92],[1,1.38,20],[2,1.22,6.62]],"ltp":1.75,"tv":5.19,"id":72922097}]}]}
{"op":"mcm","clk":"11899917311","pt":1724299011543,"mc":[{"id":"1.232089285","rc":[{"batb":[[0,1.43,23.98]],"ltp":1.75,"tv":5.19,"id":72922097}]}]}
{"op":"mcm","clk":"11899917314","pt":1724299011645,"mc":[{"id":"1.232089285","rc":[{"batb":[[0,1.43,24.92]],"ltp":1.75,"tv":5.19,"id":72922097}]}]}
{"op":"mcm","clk":"11899933041","pt":1724299463616,"mc":[{"id":"1.232089285","rc":[{"batb":[[1,1.37,20]],"ltp":2.5,"tv":11.19,"id":67083366},{"batb":[[0,1.43,24.92]],"ltp":1.75,"tv":5.19,"id":72922097}]}]}
{"op":"mcm","clk":"11899933047","pt":1724299463722,"mc":[{"id":"1.232089285","rc":[{"batb":[[0,1.78,11.86]],"ltp":2.5,"tv":11.19,"id":67083366}]}]}
{"op":"mcm","clk":"11899935195","pt":1724299519613,"mc":[{"id":"1.232089285","rc":[{"batl":[[0,2.5,1.93],[1,2.5,0]],"ltp":1.75,"tv":5.19,"id":72922097}]}]}
{"op":"mcm","clk":"11899951876","pt":1724300093241,"mc":[{"id":"1.232089285","rc":[{"batb":[[2,1.21,83.22]],"ltp":2.5,"tv":11.19,"id":67083366}]}]}
{"op":"mcm","clk":"11899964333","pt":1724300717455,"mc":[{"id":"1.232089285","rc":[{"batb":[[0,1.37,20.89],[1,1.21,83.22],[2,1.2,1105]],"ltp":2.5,"tv":11.19,"id":67083366},{"batb":[[0,1.43,5.02]],"ltp":1.75,"tv":5.19,"id":72922097}]}]}
{"op":"mcm","clk":"11899966190","pt":1724300801966,"mc":[{"id":"1.232089285","rc":[{"batb":[[0,1.84,11.08],[1,1.37,20],[2,1.21,83.22]],"ltp":2.5,"tv":11.19,"id":67083366},{"batb":[[0,1.44,20.38],[1,1.43,4.08],[2,1.38,20]],"ltp":1.75,"tv":5.19,"id":72922097}]}]}
{"op":"mcm","clk":"11899967147","pt":1724300845136,"mc":[{"id":"1.232089285","rc":[{"batl":[[0,2,0.17]],"ltp":2.5,"tv":11.19,"id":67083366}]}]}
{"op":"mcm","clk":"11900021109","pt":1724302602419,"mc":[{"id":"1.232089285","rc":[{"batb":[[0,1.37,20.89],[1,1.21,83.22],[2,1.2,1105]],"ltp":2.5,"tv":11.19,"id":67083366},{"batb":[[0,1.43,5.02],[1,1.38,20],[2,1.22,6.62]],"ltp":1.75,"tv":5.19,"id":72922097}]}]}
{"op":"mcm","clk":"11900022659","pt":1724302679263,"mc":[{"id":"1.232089285","rc":[{"batb":[[0,1.84,11.08],[1,1.37,20],[2,1.21,83.22]],"ltp":2.5,"tv":11.19,"id":67083366},{"batb":[[0,1.44,20.38],[1,1.43,4.08],[2,1.38,20]],"ltp":1.75,"tv":5.19,"id":72922097}]}]}
{"op":"mcm","clk":"11900032758","pt":1724303050113,"mc":[{"id":"1.232089285","rc":[{"batb":[[0,1.84,11.08],[2,1.21,83.23]],"ltp":2.5,"tv":11.19,"id":67083366},{"batb":[[0,1.44,20.39]],"ltp":1.75,"tv":5.19,"id":72922097}],"tv":16.38}]}
{"op":"mcm","clk":"11900033180","pt":1724303063832,"mc":[{"id":"1.232089285","rc":[{"batl":[[0,2.2,1.87],[1,2.5,1]],"ltp":1.75,"tv":5.19,"id":72922097}]}]}
{"op":"mcm","clk":"11900068498","pt":1724304479621,"mc":[{"id":"1.232089285","rc":[{"batb":[[0,1.37,20.89],[1,1.21,83.23],[2,1.2,1105]],"ltp":2.5,"tv":11.19,"id":67083366},{"batb":[[0,1.43,5.02],[1,1.38,20],[2,1.22,6.62]],"ltp":1.75,"tv":5.19,"id":72922097}]}]}
{"op":"mcm","clk":"11900070042","pt":1724304550875,"mc":[{"id":"1.232089285","rc":[{"batb":[[0,1.85,10.07],[1,1.37,20.89],[2,1.21,83.23]],"ltp":2.5,"tv":11.19,"id":67083366},{"batb":[[0,1.44,20.39],[1,1.43,4.08],[2,1.38,20]],"ltp":1.75,"tv":5.19,"id":72922097}]}]}
{"op":"mcm","clk":"11900125584","pt":1724306351354,"mc":[{"id":"1.232089285","rc":[{"batb":[[0,1.37,20.89],[1,1.21,83.23],[2,1.2,1105]],"ltp":2.5,"tv":11.19,"id":67083366},{"batb":[[0,1.43,5.02],[1,1.38,20],[2,1.22,6.62]],"ltp":1.75,"tv":5.19,"id":72922097}]}]}
{"op":"mcm","clk":"11900129649","pt":1724306482534,"mc":[{"id":"1.232089285","rc":[{"batb":[[0,1.85,10.07],[1,1.37,20.89],[2,1.21,83.23]],"ltp":2.5,"tv":11.19,"id":67083366},{"batb":[[0,1.44,20.39],[1,1.43,4.08],[2,1.38,20]],"ltp":1.75,"tv":5.19,"id":72922097}]}]}
{"op":"mcm","clk":"11900192663","pt":1724308283124,"mc":[{"id":"1.232089285","rc":[{"batb":[[0,1.37,20.89],[1,1.21,83.23],[2,1.2,1105]],"ltp":2.5,"tv":11.19,"id":67083366},{"batb":[[0,1.43,5.02],[1,1.38,20],[2,1.22,6.62]],"ltp":1.75,"tv":5.19,"id":72922097}]}]}
{"op":"mcm","clk":"11900197353","pt":1724308410565,"mc":[{"id":"1.232089285","rc":[{"batb":[[0,1.85,10.07],[1,1.37,20.89],[2,1.21,83.23]],"ltp":2.5,"tv":11.19,"id":67083366},{"batb":[[0,1.44,20.39],[1,1.43,4.08],[2,1.38,20]],"ltp":1.75,"tv":5.19,"id":72922097}]}]}
{"op":"mcm","clk":"11900208343","pt":1724308732254,"mc":[{"id":"1.232089285","rc":[{"trd":[[2.94,0.48]],"batb":[[0,1.85,10.66]],"ltp":2.94,"tv":11.67,"id":67083366},{"trd":[[1.52,0.93]],"batb":[[0,1.44,19.45]],"ltp":1.52,"tv":6.12,"id":72922097}],"tv":17.8}]}
{"op":"mcm","clk":"11900208423","pt":1724308736090,"mc":[{"id":"1.232089285","rc":[{"batb":[[0,1.85,10.07]],"ltp":2.94,"tv":11.67,"id":67083366}]}]}
{"op":"mcm","clk":"11900208632","pt":1724308742753,"mc":[{"id":"1.232089285","rc":[{"batb":[[0,3.1,1.07],[1,1.85,10.07],[2,1.37,20.89]],"ltp":2.94,"tv":11.67,"id":67083366}]}]}
{"op":"mcm","clk":"11900208939","pt":1724308754004,"mc":[{"id":"1.232089285","rc":[{"batb":[[0,1.85,10.07],[1,1.37,20.89],[2,1.21,83.23]],"ltp":2.94,"tv":11.67,"id":67083366}]}]}
{"op":"mcm","clk":"11900209249","pt":1724308765681,"mc":[{"id":"1.232089285","rc":[{"batb":[[0,2.02,1.22],[1,1.44,19.45],[2,1.43,4.08]],"ltp":1.52,"tv":6.12,"id":72922097}]}]}
{"op":"mcm","clk":"11900209600","pt":1724308778536,"mc":[{"id":"1.232089285","rc":[{"batb":[[0,1.44,19.45],[1,1.43,4.08],[2,1.38,20]],"ltp":1.52,"tv":6.12,"id":72922097}]}]}
{"op":"mcm","clk":"11900210180","pt":1724308799917,"mc":[{"id":"1.232089285","rc":[{"batb":[[0,3.1,1.15],[1,1.85,10.07],[2,1.37,20.89]],"ltp":2.94,"tv":11.67,"id":67083366}]}]}
{"op":"mcm","clk":"11900210757","pt":1724308824137,"mc":[{"id":"1.232089285","rc":[{"batb":[[0,1.85,10.07],[1,1.37,20.89],[2,1.21,83.23]],"ltp":2.94,"tv":11.67,"id":67083366}]}]}
{"op":"mcm","clk":"11900211407","pt":1724308847986,"mc":[{"id":"1.232089285","rc":[{"batb":[[0,2,1.22],[1,1.44,19.45],[2,1.43,4.08]],"ltp":1.52,"tv":6.12,"id":72922097}]}]}
{"op":"mcm","clk":"11900212101","pt":1724308874410,"mc":[{"id":"1.232089285","rc":[{"batb":[[0,1.44,19.45],[1,1.43,4.08],[2,1.38,20]],"ltp":1.52,"tv":6.12,"id":72922097}]}]}
{"op":"mcm","clk":"11900212500","pt":1724308889091,"mc":[{"id":"1.232089285","rc":[{"batb":[[0,3.1,1.22],[1,1.85,10.07],[2,1.37,20.89]],"ltp":2.94,"tv":11.67,"id":67083366}]}]}
{"op":"mcm","clk":"11900213810","pt":1724308929346,"mc":[{"id":"1.232089285","rc":[{"batb":[[0,1.85,10.07],[1,1.37,20.89],[2,1.21,83.23]],"ltp":2.94,"tv":11.67,"id":67083366}]}]}
{"op":"mcm","clk":"11900214472","pt":1724308950982,"mc":[{"id":"1.232089285","rc":[{"batb":[[0,1.44,20.44]],"ltp":1.52,"tv":6.12,"id":72922097}]}]}
{"op":"mcm","clk":"11900214615","pt":1724308956449,"mc":[{"id":"1.232089285","rc":[{"batb":[[0,1.44,19.45]],"ltp":1.52,"tv":6.12,"id":72922097}]}]}
{"op":"mcm","clk":"11900214850","pt":1724308962245,"mc":[{"id":"1.232089285","rc":[{"batb":[[0,2,1.22],[1,1.44,19.45],[2,1.43,4.08]],"ltp":1.52,"tv":6.12,"id":72922097}]}]}
{"op":"mcm","clk":"11900215372","pt":1724308980711,"mc":[{"id":"1.232089285","rc":[{"batb":[[0,1.44,19.45],[1,1.43,4.08],[2,1.38,20]],"ltp":1.52,"tv":6.12,"id":72922097}]}]}
{"op":"mcm","clk":"11900215791","pt":1724308993195,"mc":[{"id":"1.232089285","rc":[{"batb":[[0,3.2,1.07],[1,1.85,10.07],[2,1.37,20.89]],"ltp":2.94,"tv":11.67,"id":67083366}]}]}
{"op":"mcm","clk":"11900216376","pt":1724309011529,"mc":[{"id":"1.232089285","rc":[{"batb":[[0,1.85,10.07],[1,1.37,20.89],[2,1.21,83.23]],"ltp":2.94,"tv":11.67,"id":67083366}]}]}
{"op":"mcm","clk":"11900216514","pt":1724309016545,"mc":[{"id":"1.232089285","rc":[{"trd":[[2.06,1.36]],"batl":[[0,2.2,1.19]],"ltp":2.06,"tv":7.48,"id":72922097}],"tv":19.16}]}
{"op":"mcm","clk":"11900217236","pt":1724309040443,"mc":[{"id":"1.232089285","rc":[{"batb":[[0,1.44,20.39]],"ltp":2.06,"tv":7.48,"id":72922097}]}]}
{"op":"mcm","clk":"11900217680","pt":1724309051864,"mc":[{"id":"1.232089285","rc":[{"batl":[[0,2.06,1.19],[1,2.5,1.93]],"ltp":2.06,"tv":7.48,"id":72922097}]}]}
{"op":"mcm","clk":"11900224733","pt":1724309269019,"mc":[{"id":"1.232089285","rc":[{"trd":[[1.98,0.93],[2.06,1.61]],"batl":[[0,2.5,1.93],[1,2.5,0]],"ltp":2.06,"tv":8.67,"id":72922097}],"tv":20.35}]}
{"op":"mcm","clk":"11900236484","pt":1724309607569,"mc":[{"id":"1.232089285","rc":[{"batb":[[0,1.44,19.45]],"ltp":2.06,"tv":8.67,"id":72922097}]}]}
{"op":"mcm","clk":"11900236490","pt":1724309607674,"mc":[{"id":"1.232089285","rc":[{"batb":[[0,1.62,1.44],[1,1.44,19.45],[2,1.43,4.08]],"ltp":2.06,"tv":8.67,"id":72922097}]}]}
{"op":"mcm","clk":"11900237092","pt":1724309632502,"mc":[{"id":"1.232089285","rc":[{"batl":[[0,2.2,1.87],[1,2.5,1]],"ltp":2.06,"tv":8.67,"id":72922097}]}]}
{"op":"mcm","clk":"11900237591","pt":1724309649493,"mc":[{"id":"1.232089285","rc":[{"batb":[[0,1.62,2.37]],"ltp":2.06,"tv":8.67,"id":72922097}]}]}
{"op":"mcm","clk":"11900246858","pt":1724309940052,"mc":[{"id":"1.232089285","rc":[{"batb":[[0,1.62,1.43]],"ltp":2.06,"tv":8.67,"id":72922097}]}]}
{"op":"mcm","clk":"11900257137","pt":1724310211013,"mc":[{"id":"1.232089285","rc":[{"trd":[[2.32,3.91],[2.5,7.28]],"batb":[[0,1.37,20.89],[1,1.21,83.25],[2,1.2,1105]],"ltp":2.94,"tv":11.67,"id":67083366},{"trd":[[2.06,1.61]],"batb":[[1,1.43,4.08],[2,1.38,20]],"batl":[[0,2.2,1.87]],"ltp":2.06,"tv":8.67,"id":72922097}],"tv":20.34}]}
{"op":"mcm","clk":"11900262424","pt":1724310336611,"mc":[{"id":"1.232089285","rc":[{"batb":[[0,1.85,10.07],[1,1.37,20.89],[2,1.21,83.25]],"ltp":2.94,"tv":11.67,"id":67083366},{"batb":[[1,1.44,19.45],[2,1.43,4.08]],"ltp":2.06,"tv":8.67,"id":72922097}]}]}
{"op":"mcm","clk":"11900267111","pt":1724310456449,"mc":[{"id":"1.232089285","rc":[{"batb":[[0,1.85,10.67]],"ltp":2.94,"tv":11.67,"id":67083366}]}]}
{"op":"mcm","clk":"11900273895","pt":1724310618839,"mc":[{"id":"1.232089285","rc":[{"batb":[[0,1.85,10.07]],"ltp":2.94,"tv":11.67,"id":67083366}]}]}
{"op":"mcm","clk":"11900335045","pt":1724312137223,"mc":[{"id":"1.232089285","rc":[{"batb":[[0,1.37,20.89],[1,1.21,83.25],[2,1.2,1105]],"ltp":2.94,"tv":11.67,"id":67083366},{"batb":[[1,1.43,4.08],[2,1.38,20]],"ltp":2.06,"tv":8.67,"id":72922097}]}]}
{"op":"mcm","clk":"11900339730","pt":1724312260231,"mc":[{"id":"1.232089285","rc":[{"batb":[[0,1.85,10.07],[1,1.37,20.89],[2,1.21,83.25]],"ltp":2.94,"tv":11.67,"id":67083366},{"batb":[[1,1.44,19.45],[2,1.43,4.08]],"ltp":2.06,"tv":8.67,"id":72922097}]}]}
{"op":"mcm","clk":"11900424510","pt":1724314060414,"mc":[{"id":"1.232089285","rc":[{"trd":[[2.32,3.91],[2.5,7.28]],"batb":[[0,1.85,10.05],[2,1.21,83]],"ltp":2.94,"tv":11.66,"id":67083366},{"batb":[[1,1.43,4.08],[2,1.38,20]],"ltp":2.06,"tv":8.67,"id":72922097}],"tv":20.33}]}
{"op":"mcm","clk":"11900424524","pt":1724314060675,"mc":[{"id":"1.232089285","rc":[{"batb":[[0,1.37,20.89],[1,1.21,83],[2,1.2,1105]],"ltp":2.94,"tv":11.66,"id":67083366}]}]}
{"op":"mcm","clk":"11900431347","pt":1724314187172,"mc":[{"id":"1.232089285","rc":[{"batb":[[0,1.85,10.05],[1,1.37,20.89],[2,1.21,83]],"ltp":2.94,"tv":11.66,"id":67083366},{"batb":[[1,1.44,19.42],[2,1.43,4.08]],"ltp":2.06,"tv":8.67,"id":72922097}]}]}
{"op":"mcm","clk":"11900524736","pt":1724315987579,"mc":[{"id":"1.232089285","rc":[{"batb":[[0,1.37,20.89],[1,1.21,83],[2,1.2,1105]],"ltp":2.94,"tv":11.66,"id":67083366},{"batb":[[1,1.43,4.08],[2,1.38,20]],"ltp":2.06,"tv":8.67,"id":72922097}]}]}
{"op":"mcm","clk":"11900531756","pt":1724316115729,"mc":[{"id":"1.232089285","rc":[{"batb":[[0,1.85,10.05],[1,1.37,20.89],[2,1.21,83]],"ltp":2.94,"tv":11.66,"id":67083366},{"batb":[[1,1.44,19.42],[2,1.43,4.08]],"ltp":2.06,"tv":8.67,"id":72922097}]}]}
{"op":"mcm","clk":"11900646273","pt":1724317915955,"mc":[{"id":"1.232089285","rc":[{"trd":[[2.32,3.9],[2.5,7.27]],"batb":[[0,1.37,20.89],[1,1.21,82.92],[2,1.2,1105]],"ltp":2.94,"tv":11.65,"id":67083366},{"trd":[[1.52,0.93],[1.98,0.93],[2.06,1.61]],"batb":[[0,1.62,1.43],[1,1.43,4.07],[2,1.38,20]],"batl":[[0,2.2,1.86]],"ltp":2.06,"tv":8.66,"id":72922097}],"tv":20.31}]}
{"op":"mcm","clk":"11900671057","pt":1724318090780,"mc":[{"id":"1.232089285","rc":[{"batb":[[0,1.85,10.05],[1,1.37,20.89],[2,1.21,82.92]],"ltp":2.94,"tv":11.65,"id":67083366},{"batb":[[1,1.44,19.41],[2,1.43,4.07]],"ltp":2.06,"tv":8.66,"id":72922097}]}]}
{"op":"mcm","clk":"11900720614","pt":1724318679695,"mc":[{"id":"1.232089285","rc":[{"batb":[[1,1.37,20]],"ltp":2.94,"tv":11.65,"id":67083366}]}]}
{"op":"mcm","clk":"11900810493","pt":1724319891166,"mc":[{"id":"1.232089285","rc":[{"batb":[[0,1.37,20],[1,1.21,82.92],[2,1.2,1105]],"ltp":2.94,"tv":11.65,"id":67083366},{"batb":[[1,1.43,4.07],[2,1.38,20]],"ltp":2.06,"tv":8.66,"id":72922097}]}]}
{"op":"mcm","clk":"11900814502","pt":1724319933939,"mc":[{"id":"1.232089285","rc":[{"batb":[[0,1.84,10.17],[1,1.37,20],[2,1.21,82.92]],"ltp":2.94,"tv":11.65,"id":67083366},{"batb":[[1,1.44,19.41],[2,1.43,4.07]],"ltp":2.06,"tv":8.66,"id":72922097}]}]}
{"op":"mcm","clk":"11900966720","pt":1724321734376,"mc":[{"id":"1.232089285","rc":[{"trd":[[2.32,3.9],[2.5,7.26]],"batb":[[0,1.37,20],[1,1.21,82.9],[2,1.2,1105]],"ltp":2.94,"tv":11.64,"id":67083366},{"trd":[[2.06,1.61]],"batb":[[0,1.62,1.43],[1,1.43,4.07],[2,1.38,20]],"batl":[[0,2.2,1.86]],"ltp":2.06,"tv":8.66,"id":72922097}],"tv":20.3}]}
{"op":"mcm","clk":"11900969250","pt":1724321768816,"mc":[{"id":"1.232089285","rc":[{"batb":[[0,1.84,10.16],[1,1.37,20],[2,1.21,82.9]],"ltp":2.94,"tv":11.64,"id":67083366},{"batb":[[1,1.44,19.39],[2,1.43,4.07]],"ltp":2.06,"tv":8.66,"id":72922097}]}]}
{"op":"mcm","clk":"11901136614","pt":1724323569046,"mc":[{"id":"1.232089285","rc":[{"batb":[[0,1.37,20],[1,1.21,82.9],[2,1.2,1105]],"ltp":2.94,"tv":11.64,"id":67083366},{"batb":[[1,1.43,4.07],[2,1.38,20]],"ltp":2.06,"tv":8.66,"id":72922097}]}]}
{"op":"mcm","clk":"11901138939","pt":1724323596007,"mc":[{"id":"1.232089285","rc":[{"batb":[[0,1.84,10.16],[1,1.37,20],[2,1.21,82.9]],"ltp":2.94,"tv":11.64,"id":67083366},{"batb":[[1,1.44,19.39],[2,1.43,4.07]],"ltp":2.06,"tv":8.66,"id":72922097}]}]}
{"op":"mcm","clk":"11901295401","pt":1724325396556,"mc":[{"id":"1.232089285","rc":[{"trd":[[2.32,3.9],[2.5,7.27]],"batb":[[0,1.37,20],[1,1.21,82.9],[2,1.2,1105]],"ltp":2.94,"tv":11.64,"id":67083366},{"batb":[[1,1.43,4.07],[2,1.38,20]],"ltp":2.06,"tv":8.66,"id":72922097}],"tv":20.31}]}
{"op":"mcm","clk":"11901297482","pt":1724325416995,"mc":[{"id":"1.232089285","rc":[{"batb":[[0,1.84,10.17],[1,1.37,20],[2,1.21,82.9]],"ltp":2.94,"tv":11.64,"id":67083366},{"batb":[[1,1.44,19.41],[2,1.43,4.07]],"ltp":2.06,"tv":8.66,"id":72922097}]}]}
{"op":"mcm","clk":"11901387800","pt":1724326360143,"mc":[{"id":"1.232089285","rc":[{"trd":[[1.44,17.69],[1.62,0.99],[1.66,1.86]],"batb":[[0,1.44,10.56],[1,1.43,4.07],[2,1.38,20]],"ltp":1.44,"tv":29.2,"id":72922097}],"tv":40.85}]}
{"op":"mcm","clk":"11901399449","pt":1724326485666,"mc":[{"id":"1.232089285","rc":[{"batb":[[0,1.44,11.49]],"ltp":1.44,"tv":29.2,"id":72922097}]}]}
{"op":"mcm","clk":"11901400649","pt":1724326500908,"mc":[{"id":"1.232089285","rc":[{"batb":[[1,1.38,20],[2,1.32,4.07]],"ltp":1.44,"tv":29.2,"id":72922097}]}]}
{"op":"mcm","clk":"11901468365","pt":1724327217275,"mc":[{"id":"1.232089285","rc":[{"batb":[[0,1.37,20],[1,1.21,82.9],[2,1.2,1105]],"ltp":2.94,"tv":11.64,"id":67083366},{"batb":[[0,1.38,20.93],[1,1.32,4.07],[2,1.22,6.6]],"ltp":1.44,"tv":29.2,"id":72922097}]}]}
{"op":"mcm","clk":"11901469017","pt":1724327224202,"mc":[{"id":"1.232089285","rc":[{"batb":[[0,1.84,10.17],[1,1.37,20],[2,1.21,82.9]],"ltp":2.94,"tv":11.64,"id":67083366}]}]}
{"op":"mcm","clk":"11901503721","pt":1724327617733,"mc":[{"id":"1.232089285","rc":[{"batl":[[0,3.5,24.62]],"ltp":2.94,"tv":11.64,"id":67083366}]}]}
{"op":"mcm","clk":"11901573379","pt":1724328343047,"mc":[{"id":"1.232089285","rc":[{"trd":[[2.32,3.9],[2.5,7.27]],"batb":[[0,1.84,10.16],[2,1.21,82.85]],"ltp":2.94,"tv":11.65,"id":67083366},{"trd":[[1.44,17.68]],"batb":[[1,1.32,4.07],[2,1.22,6.6]],"batl":[[0,2.2,1.86]],"ltp":1.44,"tv":29.2,"id":72922097}],"tv":40.85}]}
{"op":"mcm","clk":"11901643217","pt":1724329024455,"mc":[{"id":"1.232089285","rc":[{"batb":[[0,1.37,20],[1,1.21,82.85],[2,1.2,1105]],"ltp":2.94,"tv":11.65,"id":67083366}]}]}
{"op":"mcm","clk":"11901643846","pt":1724329030268,"mc":[{"id":"1.232089285","rc":[{"batb":[[0,1.84,10.16],[1,1.37,20],[2,1.21,82.85]],"ltp":2.94,"tv":11.65,"id":67083366}]}]}
{"op":"mcm","clk":"11901655935","pt":1724329149975,"mc":[{"id":"1.232089285","rc":[{"batl":[[0,1.53,1.11],[1,2.2,1.86],[2,2.5,1]],"ltp":1.44,"tv":29.2,"id":72922097}]}]}
{"op":"mcm","clk":"11901657855","pt":1724329170705,"mc":[{"id":"1.232089285","rc":[{"batb":[[2,1.28,98.46]],"ltp":1.44,"tv":29.2,"id":72922097}]}]}
{"op":"mcm","clk":"11901660398","pt":1724329197562,"mc":[{"id":"1.232089285","rc":[{"batl":[[0,2.2,1.86],[1,2.5,1],[2,2.5,0]],"ltp":1.44,"tv":29.2,"id":72922097}]}]}
{"op":"mcm","clk":"11901661273","pt":1724329206226,"mc":[{"id":"1.232089285","rc":[{"batl":[[0,1.53,1.11],[1,2.2,1.86],[2,2.5,1]],"ltp":1.44,"tv":29.2,"id":72922097}]}]}
{"op":"mcm","clk":"11901663607","pt":1724329230698,"mc":[{"id":"1.232089285","rc":[{"batl":[[0,2.2,1.86],[1,2.5,1],[2,2.5,0]],"ltp":1.44,"tv":29.2,"id":72922097}]}]}
{"op":"mcm","clk":"11901665883","pt":1724329255751,"mc":[{"id":"1.232089285","rc":[{"batb":[[0,1.99,1.11],[1,1.38,20.93],[2,1.32,4.07]],"ltp":1.44,"tv":29.2,"id":72922097}]}]}
{"op":"mcm","clk":"11901668154","pt":1724329279826,"mc":[{"id":"1.232089285","rc":[{"batb":[[0,1.38,20.93],[1,1.32,4.07],[2,1.28,98.46]],"ltp":1.44,"tv":29.2,"id":72922097}]}]}
{"op":"mcm","clk":"11901669664","pt":1724329297385,"mc":[{"id":"1.232089285","rc":[{"batl":[[0,1.53,1.11],[1,2.2,1.86],[2,2.5,1]],"ltp":1.44,"tv":29.2,"id":72922097}]}]}
{"op":"mcm","clk":"11901672022","pt":1724329322703,"mc":[{"id":"1.232089285","rc":[{"batl":[[0,2.2,1.86],[1,2.5,1],[2,2.5,0]],"ltp":1.44,"tv":29.2,"id":72922097}]}]}
{"op":"mcm","clk":"11901674736","pt":1724329349630,"mc":[{"id":"1.232089285","rc":[{"batb":[[0,1.99,1.11],[1,1.38,20.93],[2,1.32,4.07]],"ltp":1.44,"tv":29.2,"id":72922097}]}]}
{"op":"mcm","clk":"11901675338","pt":1724329355925,"mc":[{"id":"1.232089285","rc":[{"batb":[[0,1.38,20.93],[1,1.32,4.07],[2,1.28,98.46]],"ltp":1.44,"tv":29.2,"id":72922097}]}]}
{"op":"mcm","clk":"11901677226","pt":1724329375184,"mc":[{"id":"1.232089285","rc":[{"batl":[[0,1.53,1.11],[1,2.2,1.86],[2,2.5,1]],"ltp":1.44,"tv":29.2,"id":72922097}]}]}
{"op":"mcm","clk":"11901680294","pt":1724329405632,"mc":[{"id":"1.232089285","rc":[{"batl":[[0,2.2,1.86],[1,2.5,1],[2,2.5,0]],"ltp":1.44,"tv":29.2,"id":72922097}]}]}
{"op":"mcm","clk":"11901681035","pt":1724329413035,"mc":[{"id":"1.232089285","rc":[{"batb":[[0,1.99,1.11],[1,1.38,20.93],[2,1.32,4.07]],"ltp":1.44,"tv":29.2,"id":72922097}]}]}
{"op":"mcm","clk":"11901683113","pt":1724329436469,"mc":[{"id":"1.232089285","rc":[{"batb":[[0,1.38,20.93],[1,1.32,4.07],[2,1.28,98.46]],"ltp":1.44,"tv":29.2,"id":72922097}]}]}
{"op":"mcm","clk":"11901686571","pt":1724329474712,"mc":[{"id":"1.232089285","rc":[{"batl":[[0,1.53,1.11],[1,2.2,1.86],[2,2.5,1]],"ltp":1.44,"tv":29.2,"id":72922097}]}]}
{"op":"mcm","clk":"11901701141","pt":1724329641271,"mc":[{"id":"1.232089285","rc":[{"batl":[[0,2.2,1.86],[1,2.5,1],[2,2.5,0]],"ltp":1.44,"tv":29.2,"id":72922097}]}]}
{"op":"mcm","clk":"11901801331","pt":1724330830501,"mc":[{"id":"1.232089285","rc":[{"batb":[[0,1.37,20],[1,1.21,82.85],[2,1.2,1105]],"ltp":2.94,"tv":11.65,"id":67083366}]}]}
{"op":"mcm","clk":"11901806554","pt":1724330906939,"mc":[{"id":"1.232089285","rc":[{"batl":[[0,2.02,52.26],[1,2.5,1.93]],"ltp":1.44,"tv":29.2,"id":72922097}]}]}
{"op":"mcm","clk":"11901808268","pt":1724330931275,"mc":[{"id":"1.232089285","rc":[{"batb":[[0,1.21,82.85],[1,1.2,1105],[2,1.04,1.53]],"ltp":2.94,"tv":11.65,"id":67083366},{"batb":[[0,1.35,20.93]],"ltp":1.44,"tv":29.2,"id":72922097}]}]}
{"op":"mcm","clk":"11901812225","pt":1724330987254,"mc":[{"id":"1.232089285","rc":[{"batb":[[2,1.29,6.6]],"ltp":1.44,"tv":29.2,"id":72922097}]}]}
{"op":"mcm","clk":"11901815162","pt":1724331025085,"mc":[{"id":"1.232089285","rc":[{"batb":[[0,1.99,8.62],[1,1.21,82.85],[2,1.2,1105]],"ltp":2.94,"tv":11.65,"id":67083366}]}]}
{"op":"mcm","clk":"11901832769","pt":1724331237628,"mc":[{"id":"1.232089285","rc":[{"trd":[[2.94,0.96]],"batb":[[0,3.6,1.81],[1,1.99,8.62],[2,1.21,82.85]],"ltp":2.94,"tv":12.13,"id":67083366},{"trd":[[1.52,1.86]],"batb":[[0,1.35,20]],"ltp":1.52,"tv":30.13,"id":72922097}],"tv":42.26}]}
{"op":"mcm","clk":"11901833435","pt":1724331244433,"mc":[{"id":"1.232089285","rc":[{"batb":[[0,1.99,8.62],[1,1.21,82.85],[2,1.2,1105]],"ltp":2.94,"tv":12.13,"id":67083366}]}]}
{"op":"mcm","clk":"11901834144","pt":1724331252198,"mc":[{"id":"1.232089285","rc":[{"trd":[[2,1.4]],"batl":[[0,2.02,51.56]],"ltp":2.0,"tv":31.53,"id":72922097}],"tv":43.67}]}
{"op":"mcm","clk":"11901835727","pt":1724331270178,"mc":[{"id":"1.232089285","rc":[{"batb":[[0,2.02,3.05],[1,1.99,8.62],[2,1.21,82.85]],"ltp":2.94,"tv":12.13,"id":67083366}]}]}
{"op":"mcm","clk":"11901836481","pt":1724331278873,"mc":[{"id":"1.232089285","rc":[{"batb":[[0,1.99,8.62],[1,1.21,82.85],[2,1.2,1105]],"ltp":2.94,"tv":12.13,"id":67083366}]}]}
{"op":"mcm","clk":"11901837458","pt":1724331290535,"mc":[{"id":"1.232089285","rc":[{"batl":[[0,3.85,3.05]],"ltp":2.94,"tv":12.13,"id":67083366}]}]}
{"op":"mcm","clk":"11901839914","pt":1724331315754,"mc":[{"id":"1.232089285","rc":[{"batl":[[0,2.02,51.33]],"ltp":2.0,"tv":31.53,"id":72922097}]}]}
{"op":"mcm","clk":"11901840913","pt":1724331326750,"mc":[{"id":"1.232089285","rc":[{"batb":[[0,1.35,20.93]],"ltp":2.0,"tv":31.53,"id":72922097}]}]}
{"op":"mcm","clk":"11901842163","pt":1724331342434,"mc":[{"id":"1.232089285","rc":[{"batb":[[0,2.02,3.05],[1,1.99,8.62],[2,1.21,82.85]],"ltp":2.94,"tv":12.13,"id":67083366}]}]}
{"op":"mcm","clk":"11901842575","pt":1724331347978,"mc":[{"id":"1.232089285","rc":[{"batb":[[0,1.99,8.62],[1,1.21,82.85],[2,1.2,1105]],"ltp":2.94,"tv":12.13,"id":67083366}]}]}
{"op":"mcm","clk":"11901842629","pt":1724331348650,"mc":[{"id":"1.232089285","rc":[{"batl":[[0,2.02,52.26]],"ltp":2.0,"tv":31.53,"id":72922097}]}]}
{"op":"mcm","clk":"11901953832","pt":1724332825345,"mc":[{"id":"1.232089285","rc":[{"trd":[[2.32,3.9],[2.5,7.27]],"batb":[[0,1.21,82.92],[1,1.2,1105],[2,1.04,1.53]],"ltp":2.94,"tv":12.12,"id":67083366},{"trd":[[1.44,17.68],[1.52,1.86],[2.06,1.61]],"batb":[[1,1.32,4.07],[2,1.29,6.6]],"ltp":2.0,"tv":31.52,"id":72922097}],"tv":43.65}]}
{"op":"mcm","clk":"11901965268","pt":1724333005242,"mc":[{"id":"1.232089285","rc":[{"batb":[[0,1.99,8.62],[1,1.21,82.92],[2,1.2,1105]],"ltp":2.94,"tv":12.12,"id":67083366}]}]}
{"op":"mcm","clk":"11901980639","pt":1724333234787,"mc":[{"id":"1.232089285","rc":[{"batb":[[2,1.04,1.53]],"ltp":2.94,"tv":12.12,"id":67083366}]}]}
{"op":"mcm","clk":"11902016940","pt":1724333711643,"mc":[{"id":"1.232089285","rc":[{"batb":[[0,1.36,2.67],[1,1.35,20],[2,1.32,4.07]],"ltp":2.0,"tv":31.52,"id":72922097}]}]}
{"op":"mcm","clk":"11902018206","pt":1724333733649,"mc":[{"id":"1.232089285","rc":[{"batl":[[0,2,1.57],[1,2.02,51.33],[2,2.5,1.93]],"ltp":2.0,"tv":31.52,"id":72922097}]}]}
{"op":"mcm","clk":"11902092980","pt":1724334805536,"mc":[{"id":"1.232089285","rc":[{"batb":[[0,1.21,82.92],[1,1.04,1.53],[2,1.03,200]],"ltp":2.94,"tv":12.12,"id":67083366}]}]}
{"op":"mcm","clk":"11902095777","pt":1724334867602,"mc":[{"id":"1.232089285","rc":[{"trd":[[2,0.64],[2.1,0.84]],"batl":[[0,2,389.53]],"ltp":2.0,"tv":13.6,"id":67083366},{"trd":[[1.9,0.93],[2,2.04]],"batl":[[0,2.02,51.33],[1,2.5,1.93],[2,2.5,0]],"ltp":2.0,"tv":33.09,"id":72922097}],"tv":46.7}]}
{"op":"mcm","clk":"11902099069","pt":1724334947185,"mc":[{"id":"1.232089285","rc":[{"trd":[[2,381.76]],"batl":[[0,2,8.4]],"ltp":2.0,"tv":394.73,"id":67083366},{"trd":[[2,383.16]],"ltp":2.0,"tv":414.22,"id":72922097}],"tv":808.95}]}
{"op":"mcm","clk":"11902099123","pt":1724334948400,"mc":[{"id":"1.232089285","rc":[{"batb":[[0,1.22,10],[1,1.21,82.92],[2,1.04,1.53]],"ltp":2.0,"tv":394.73,"id":67083366}]}]}
{"op":"mcm","clk":"11902099247","pt":1724334951895,"mc":[{"id":"1.232089285","rc":[{"batb":[[0,1.21,82.92],[1,1.04,1.53],[2,1.03,200]],"ltp":2.0,"tv":394.73,"id":67083366}]}]}
{"op":"mcm","clk":"11902099564","pt":1724334959296,"mc":[{"id":"1.232089285","rc":[{"batb":[[0,1.22,10],[1,1.21,82.92],[2,1.04,1.53]],"ltp":2.0,"tv":394.73,"id":67083366}]}]}
{"op":"mcm","clk":"11902099720","pt":1724334962694,"mc":[{"id":"1.232089285","rc":[{"batb":[[0,1.21,82.92],[1,1.04,1.53],[2,1.03,200]],"ltp":2.0,"tv":394.73,"id":67083366}]}]}
{"op":"mcm","clk":"11902099962","pt":1724334968513,"mc":[{"id":"1.232089285","rc":[{"batb":[[0,1.22,10],[1,1.21,82.92],[2,1.04,1.53]],"ltp":2.0,"tv":394.73,"id":67083366}]}]}
{"op":"mcm","clk":"11902100113","pt":1724334971918,"mc":[{"id":"1.232089285","rc":[{"batb":[[0,1.21,82.92],[1,1.04,1.53],[2,1.03,200]],"ltp":2.0,"tv":394.73,"id":67083366}]}]}
{"op":"mcm","clk":"11902100207","pt":1724334974336,"mc":[{"id":"1.232089285","rc":[{"batb":[[0,1.22,10],[1,1.21,82.92],[2,1.04,1.53]],"ltp":2.0,"tv":394.73,"id":67083366}]}]}
{"op":"mcm","clk":"11902100358","pt":1724334977829,"mc":[{"id":"1.232089285","rc":[{"batb":[[0,1.21,82.92],[1,1.04,1.53],[2,1.03,200]],"ltp":2.0,"tv":394.73,"id":67083366}]}]}
{"op":"mcm","clk":"11902100483","pt":1724334980717,"mc":[{"id":"1.232089285","rc":[{"batb":[[0,1.22,10],[1,1.21,82.92],[2,1.04,1.53]],"ltp":2.0,"tv":394.73,"id":67083366}]}]}
{"op":"mcm","clk":"11902100627","pt":1724334984041,"mc":[{"id":"1.232089285","rc":[{"batb":[[0,1.21,82.92],[1,1.04,1.53],[2,1.03,200]],"ltp":2.0,"tv":394.73,"id":67083366}]}]}
{"op":"mcm","clk":"11902100757","pt":1724334986259,"mc":[{"id":"1.232089285","rc":[{"trd":[[2,389.76]],"batb":[[0,1.22,10],[1,1.21,82.92],[2,1.04,1.53]],"batl":[[0,2,0.4]],"ltp":2.0,"tv":402.73,"id":67083366},{"trd":[[2,391.16]],"ltp":2.0,"tv":422.22,"id":72922097}],"tv":824.95}]}
{"op":"mcm","clk":"11902100925","pt":1724334989579,"mc":[{"id":"1.232089285","rc":[{"batb":[[0,1.21,82.92],[1,1.04,1.53],[2,1.03,200]],"ltp":2.0,"tv":402.73,"id":67083366}]}]}
{"op":"mcm","clk":"11902101182","pt":1724334994374,"mc":[{"id":"1.232089285","rc":[{"batb":[[0,1.22,10],[1,1.21,82.92],[2,1.04,1.53]],"ltp":2.0,"tv":402.73,"id":67083366}]}]}
{"op":"mcm","clk":"11902101320","pt":1724334997773,"mc":[{"id":"1.232089285","rc":[{"batb":[[0,1.21,82.92],[1,1.04,1.53],[2,1.03,200]],"ltp":2.0,"tv":402.73,"id":67083366}]}]}
{"op":"mcm","clk":"11902101447","pt":1724335000667,"mc":[{"id":"1.232089285","rc":[{"batb":[[0,1.22,10],[1,1.21,82.92],[2,1.04,1.53]],"ltp":2.0,"tv":402.73,"id":67083366}]}]}
{"op":"mcm","clk":"11902101575","pt":1724335003955,"mc":[{"id":"1.232089285","rc":[{"batb":[[0,1.21,82.92],[1,1.04,1.53],[2,1.03,200]],"ltp":2.0,"tv":402.73,"id":67083366}]}]}
{"op":"mcm","clk":"11902101785","pt":1724335009372,"mc":[{"id":"1.232089285","rc":[{"batb":[[0,1.22,10],[1,1.21,82.92],[2,1.04,1.53]],"ltp":2.0,"tv":402.73,"id":67083366}]}]}
{"op":"mcm","clk":"11902101942","pt":1724335012889,"mc":[{"id":"1.232089285","rc":[{"batb":[[0,1.21,82.92],[1,1.04,1.53],[2,1.03,200]],"ltp":2.0,"tv":402.73,"id":67083366}]}]}
{"op":"mcm","clk":"11902102091","pt":1724335016478,"mc":[{"id":"1.232089285","rc":[{"batb":[[0,1.22,10],[1,1.21,82.92],[2,1.04,1.53]],"ltp":2.0,"tv":402.73,"id":67083366},{"batb":[[0,1.64,10],[1,1.63,8],[2,1.36,2.67]],"ltp":2.0,"tv":422.22,"id":72922097}]}]}
{"op":"mcm","clk":"11902102258","pt":1724335019876,"mc":[{"id":"1.232089285","rc":[{"batb":[[0,1.21,82.92],[1,1.04,1.53],[2,1.03,200]],"ltp":2.0,"tv":402.73,"id":67083366},{"batb":[[0,1.63,8],[1,1.36,2.67],[2,1.35,20]],"ltp":2.0,"tv":422.22,"id":72922097}]}]}
{"op":"mcm","clk":"11902102357","pt":1724335022000,"mc":[{"id":"1.232089285","rc":[{"batb":[[0,1.22,10],[1,1.21,82.92],[2,1.04,1.53]],"ltp":2.0,"tv":402.73,"id":67083366},{"batb":[[0,1.64,10],[1,1.63,8],[2,1.36,2.67]],"ltp":2.0,"tv":422.22,"id":72922097}]}]}
{"op":"mcm","clk":"11902102512","pt":1724335025287,"mc":[{"id":"1.232089285","rc":[{"batb":[[0,1.21,82.92],[1,1.04,1.53],[2,1.03,200]],"ltp":2.0,"tv":402.73,"id":67083366},{"batb":[[0,1.63,8],[1,1.36,2.67],[2,1.35,20]],"ltp":2.0,"tv":422.22,"id":72922097}]}]}
{"op":"mcm","clk":"11902102646","pt":1724335028123,"mc":[{"id":"1.232089285","rc":[{"batb":[[0,1.22,10],[1,1.21,82.92],[2,1.04,1.53]],"ltp":2.0,"tv":402.73,"id":67083366},{"batb":[[0,1.64,10],[1,1.63,8],[2,1.36,2.67]],"ltp":2.0,"tv":422.22,"id":72922097}]}]}
{"op":"mcm","clk":"11902102818","pt":1724335031526,"mc":[{"id":"1.232089285","rc":[{"batb":[[0,1.21,82.92],[1,1.04,1.53],[2,1.03,200]],"ltp":2.0,"tv":402.73,"id":67083366},{"batb":[[0,1.63,8],[1,1.36,2.67],[2,1.35,20]],"ltp":2.0,"tv":422.22,"id":72922097}]}]}
{"op":"mcm","clk":"11902103037","pt":1724335036125,"mc":[{"id":"1.232089285","rc":[{"batb":[[0,1.22,10],[1,1.21,82.92],[2,1.04,1.53]],"ltp":2.0,"tv":402.73,"id":67083366},{"batb":[[0,1.64,10],[1,1.63,8],[2,1.36,2.67]],"ltp":2.0,"tv":422.22,"id":72922097}]}]}
{"op":"mcm","clk":"11902103248","pt":1724335039535,"mc":[{"id":"1.232089285","rc":[{"batb":[[0,1.21,82.92],[1,1.04,1.53],[2,1.03,200]],"ltp":2.0,"tv":402.73,"id":67083366},{"batb":[[0,1.63,8],[1,1.36,2.67],[2,1.35,20]],"ltp":2.0,"tv":422.22,"id":72922097}]}]}
{"op":"mcm","clk":"11902103791","pt":1724335050230,"mc":[{"id":"1.232089285","rc":[{"batb":[[0,1.22,10],[1,1.21,82.92],[2,1.04,1.53]],"ltp":2.0,"tv":402.73,"id":67083366},{"batb":[[0,1.64,10],[1,1.63,8],[2,1.36,2.67]],"ltp":2.0,"tv":422.22,"id":72922097}]}]}
{"op":"mcm","clk":"11902103962","pt":1724335053544,"mc":[{"id":"1.232089285","rc":[{"batb":[[0,1.21,82.92],[1,1.04,1.53],[2,1.03,200]],"ltp":2.0,"tv":402.73,"id":67083366},{"batb":[[0,1.63,8],[1,1.36,2.67],[2,1.35,20]],"ltp":2.0,"tv":422.22,"id":72922097}]}]}
{"op":"mcm","clk":"11902104166","pt":1724335057562,"mc":[{"id":"1.232089285","rc":[{"batb":[[0,1.22,10],[1,1.21,82.92],[2,1.04,1.53]],"ltp":2.0,"tv":402.73,"id":67083366},{"batb":[[0,1.64,10],[1,1.63,8],[2,1.36,2.67]],"ltp":2.0,"tv":422.22,"id":72922097}]}]}
{"op":"mcm","clk":"11902104324","pt":1724335061058,"mc":[{"id":"1.232089285","rc":[{"batb":[[0,1.21,82.92],[1,1.04,1.53],[2,1.03,200]],"ltp":2.0,"tv":402.73,"id":67083366},{"batb":[[0,1.63,8],[1,1.36,2.67],[2,1.35,20]],"ltp":2.0,"tv":422.22,"id":72922097}]}]}
{"op":"mcm","clk":"11902104571","pt":1724335065654,"mc":[{"id":"1.232089285","rc":[{"batb":[[0,1.22,10],[1,1.21,82.92],[2,1.04,1.53]],"ltp":2.0,"tv":402.73,"id":67083366},{"batb":[[0,1.64,10],[1,1.63,8],[2,1.36,2.67]],"ltp":2.0,"tv":422.22,"id":72922097}]}]}
{"op":"mcm","clk":"11902104773","pt":1724335069048,"mc":[{"id":"1.232089285","rc":[{"batb":[[0,1.21,82.92],[1,1.04,1.53],[2,1.03,200]],"ltp":2.0,"tv":402.73,"id":67083366},{"batb":[[0,1.63,8],[1,1.36,2.67],[2,1.35,20]],"ltp":2.0,"tv":422.22,"id":72922097}]}]}
{"op":"mcm","clk":"11902104932","pt":1724335072040,"mc":[{"id":"1.232089285","rc":[{"batb":[[0,1.22,10],[1,1.21,82.92],[2,1.04,1.53]],"ltp":2.0,"tv":402.73,"id":67083366},{"batb":[[0,1.64,10],[1,1.63,8],[2,1.36,2.67]],"ltp":2.0,"tv":422.22,"id":72922097}]}]}
{"op":"mcm","clk":"11902105107","pt":1724335075446,"mc":[{"id":"1.232089285","rc":[{"batb":[[0,1.21,82.92],[1,1.04,1.53],[2,1.03,200]],"ltp":2.0,"tv":402.73,"id":67083366},{"batb":[[0,1.63,8],[1,1.36,2.67],[2,1.35,20]],"ltp":2.0,"tv":422.22,"id":72922097}]}]}
{"op":"mcm","clk":"11902105565","pt":1724335081861,"mc":[{"id":"1.232089285","rc":[{"batb":[[0,1.22,10],[1,1.21,82.92],[2,1.04,1.53]],"ltp":2.0,"tv":402.73,"id":67083366},{"batb":[[0,1.64,10],[1,1.63,8],[2,1.36,2.67]],"ltp":2.0,"tv":422.22,"id":72922097}]}]}
{"op":"mcm","clk":"11902105794","pt":1724335085362,"mc":[{"id":"1.232089285","rc":[{"batb":[[0,1.21,82.92],[1,1.04,1.53],[2,1.03,200]],"ltp":2.0,"tv":402.73,"id":67083366},{"batb":[[0,1.63,8],[1,1.36,2.67],[2,1.35,20]],"ltp":2.0,"tv":422.22,"id":72922097}]}]}
{"op":"mcm","clk":"11902105987","pt":1724335089192,"mc":[{"id":"1.232089285","rc":[{"batb":[[0,1.22,10],[1,1.21,82.92],[2,1.04,1.53]],"ltp":2.0,"tv":402.73,"id":67083366},{"batb":[[0,1.64,10],[1,1.63,8],[2,1.36,2.67]],"ltp":2.0,"tv":422.22,"id":72922097}]}]}
{"op":"mcm","clk":"11902106214","pt":1724335092654,"mc":[{"id":"1.232089285","rc":[{"batb":[[0,1.21,82.92],[1,1.04,1.53],[2,1.03,200]],"ltp":2.0,"tv":402.73,"id":67083366},{"batb":[[0,1.63,8],[1,1.36,2.67],[2,1.35,20]],"ltp":2.0,"tv":422.22,"id":72922097}]}]}
{"op":"mcm","clk":"11902106708","pt":1724335101805,"mc":[{"id":"1.232089285","rc":[{"batb":[[0,1.22,10],[1,1.21,82.92],[2,1.04,1.53]],"ltp":2.0,"tv":402.73,"id":67083366},{"batb":[[0,1.64,10],[1,1.63,8],[2,1.36,2.67]],"ltp":2.0,"tv":422.22,"id":72922097}]}]}
{"op":"mcm","clk":"11902106903","pt":1724335105095,"mc":[{"id":"1.232089285","rc":[{"batb":[[0,1.21,82.92],[1,1.04,1.53],[2,1.03,200]],"ltp":2.0,"tv":402.73,"id":67083366},{"batb":[[0,1.63,8],[1,1.36,2.67],[2,1.35,20]],"ltp":2.0,"tv":422.22,"id":72922097}]}]}
{"op":"mcm","clk":"11902107549","pt":1724335114142,"mc":[{"id":"1.232089285","rc":[{"batb":[[0,1.22,10],[1,1.21,82.92],[2,1.04,1.53]],"ltp":2.0,"tv":402.73,"id":67083366},{"batb":[[0,1.64,10],[1,1.63,8],[2,1.36,2.67]],"ltp":2.0,"tv":422.22,"id":72922097}]}]}
{"op":"mcm","clk":"11902107750","pt":1724335117598,"mc":[{"id":"1.232089285","rc":[{"batb":[[0,1.21,82.92],[1,1.04,1.53],[2,1.03,200]],"ltp":2.0,"tv":402.73,"id":67083366}]}]}
{"op":"mcm","clk":"11902107759","pt":1724335117707,"mc":[{"id":"1.232089285","rc":[{"batb":[[0,1.63,8],[1,1.36,2.67],[2,1.35,20]],"ltp":2.0,"tv":422.22,"id":72922097}]}]}
{"op":"mcm","clk":"11902108165","pt":1724335125105,"mc":[{"id":"1.232089285","rc":[{"batb":[[0,1.22,10],[1,1.21,82.92],[2,1.04,1.53]],"ltp":2.0,"tv":402.73,"id":67083366},{"batb":[[0,1.64,10],[1,1.63,8],[2,1.36,2.67]],"ltp":2.0,"tv":422.22,"id":72922097}]}]}
{"op":"mcm","clk":"11902108373","pt":1724335128409,"mc":[{"id":"1.232089285","rc":[{"batb":[[0,1.21,82.92],[1,1.04,1.53],[2,1.03,200]],"ltp":2.0,"tv":402.73,"id":67083366},{"batb":[[0,1.63,8],[1,1.36,2.67],[2,1.35,20]],"ltp":2.0,"tv":422.22,"id":72922097}]}]}
{"op":"mcm","clk":"11902108665","pt":1724335133570,"mc":[{"id":"1.232089285","rc":[{"batb":[[0,1.22,10],[1,1.21,82.92],[2,1.04,1.53]],"ltp":2.0,"tv":402.73,"id":67083366},{"batb":[[0,1.64,10],[1,1.63,8],[2,1.36,2.67]],"ltp":2.0,"tv":422.22,"id":72922097}]}]}
{"op":"mcm","clk":"11902108875","pt":1724335137175,"mc":[{"id":"1.232089285","rc":[{"batb":[[0,1.21,82.92],[1,1.04,1.53],[2,1.03,200]],"ltp":2.0,"tv":402.73,"id":67083366},{"batb":[[0,1.63,8],[1,1.36,2.67],[2,1.35,20]],"ltp":2.0,"tv":422.22,"id":72922097}]}]}
{"op":"mcm","clk":"11902109143","pt":1724335141370,"mc":[{"id":"1.232089285","rc":[{"batb":[[0,1.22,10],[1,1.21,82.92],[2,1.04,1.53]],"ltp":2.0,"tv":402.73,"id":67083366},{"batb":[[0,1.66,10],[1,1.65,16.76],[2,1.63,8]],"ltp":2.0,"tv":422.22,"id":72922097}]}]}
{"op":"mcm","clk":"11902109353","pt":1724335144541,"mc":[{"id":"1.232089285","rc":[{"batb":[[0,1.21,82.92],[1,1.04,1.53],[2,1.03,200]],"ltp":2.0,"tv":402.73,"id":67083366},{"batb":[[0,1.65,16.76],[1,1.63,8],[2,1.36,2.67]],"ltp":2.0,"tv":422.22,"id":72922097}]}]}
{"op":"mcm","clk":"11902109536","pt":1724335147638,"mc":[{"id":"1.232089285","rc":[{"batb":[[0,1.22,10],[1,1.21,82.92],[2,1.04,1.53]],"ltp":2.0,"tv":402.73,"id":67083366},{"batb":[[0,1.66,10],[1,1.65,16.76],[2,1.63,8]],"ltp":2.0,"tv":422.22,"id":72922097}]}]}
{"op":"mcm","clk":"11902109704","pt":1724335150988,"mc":[{"id":"1.232089285","rc":[{"batb":[[0,1.21,82.92],[1,1.04,1.53],[2,1.03,200]],"ltp":2.0,"tv":402.73,"id":67083366},{"batb":[[0,1.65,16.76],[1,1.63,8],[2,1.36,2.67]],"ltp":2.0,"tv":422.22,"id":72922097}]}]}
{"op":"mcm","clk":"11902110423","pt":1724335163916,"mc":[{"id":"1.232089285","rc":[{"batb":[[0,1.22,10],[1,1.21,82.92],[2,1.04,1.53]],"ltp":2.0,"tv":402.73,"id":67083366},{"batb":[[0,1.66,10],[1,1.65,16.76],[2,1.63,8]],"ltp":2.0,"tv":422.22,"id":72922097}]}]}
{"op":"mcm","clk":"11902110627","pt":1724335167222,"mc":[{"id":"1.232089285","rc":[{"batb":[[0,1.21,82.92],[1,1.04,1.53],[2,1.03,200]],"ltp":2.0,"tv":402.73,"id":67083366},{"batb":[[0,1.65,16.76],[1,1.63,8],[2,1.36,2.67]],"ltp":2.0,"tv":422.22,"id":72922097}]}]}
{"op":"mcm","clk":"11902111022","pt":1724335174385,"mc":[{"id":"1.232089285","rc":[{"batb":[[0,1.22,10],[1,1.21,82.92],[2,1.04,1.53]],"ltp":2.0,"tv":402.73,"id":67083366},{"batb":[[0,1.66,10],[1,1.65,16.76],[2,1.63,8]],"ltp":2.0,"tv":422.22,"id":72922097}]}]}
{"op":"mcm","clk":"11902111229","pt":1724335177903,"mc":[{"id":"1.232089285","rc":[{"batb":[[0,1.21,82.92],[1,1.04,1.53],[2,1.03,200]],"ltp":2.0,"tv":402.73,"id":67083366},{"batb":[[0,1.65,16.76],[1,1.63,8],[2,1.36,2.67]],"ltp":2.0,"tv":422.22,"id":72922097}]}]}
{"op":"mcm","clk":"11902111366","pt":1724335180118,"mc":[{"id":"1.232089285","rc":[{"batb":[[0,1.22,10],[1,1.21,82.92],[2,1.04,1.53]],"ltp":2.0,"tv":402.73,"id":67083366},{"batb":[[0,1.66,10],[1,1.65,16.76],[2,1.63,8]],"ltp":2.0,"tv":422.22,"id":72922097}]}]}
{"op":"mcm","clk":"11902111556","pt":1724335183396,"mc":[{"id":"1.232089285","rc":[{"batb":[[0,1.21,82.92],[1,1.04,1.53],[2,1.03,200]],"ltp":2.0,"tv":402.73,"id":67083366},{"batb":[[0,1.65,16.76],[1,1.63,8],[2,1.36,2.67]],"ltp":2.0,"tv":422.22,"id":72922097}]}]}
{"op":"mcm","clk":"11902112070","pt":1724335192166,"mc":[{"id":"1.232089285","rc":[{"batb":[[0,1.66,10],[1,1.65,16.76],[2,1.63,8]],"ltp":2.0,"tv":422.22,"id":72922097}]}]}
{"op":"mcm","clk":"11902112233","pt":1724335195509,"mc":[{"id":"1.232089285","rc":[{"batb":[[0,1.65,16.76],[1,1.63,8],[2,1.36,2.67]],"ltp":2.0,"tv":422.22,"id":72922097}]}]}
{"op":"mcm","clk":"11902112571","pt":1724335200259,"mc":[{"id":"1.232089285","rc":[{"batb":[[0,1.66,10],[1,1.65,16.76],[2,1.63,8]],"ltp":2.0,"tv":422.22,"id":72922097}]}]}
{"op":"mcm","clk":"11902112914","pt":1724335203649,"mc":[{"id":"1.232089285","rc":[{"trd":[[2,390.3],[2.1,0.84],[2.32,3.91],[2.5,7.27],[2.94,0.96]],"ltp":2.0,"tv":403.28,"id":67083366},{"trd":[[1.44,17.67],[1.52,1.87],[1.9,0.93],[1.98,0.93],[2,391.66],[2.06,1.61]],"batb":[[0,1.65,16.76],[1,1.63,8],[2,1.36,2.67]],"batl":[[0,2.02,51.26],[1,2.5,1.93]],"ltp":2.0,"tv":422.71,"id":72922097}],"tv":826.0}]}
{"op":"mcm","clk":"11902113225","pt":1724335207648,"mc":[{"id":"1.232089285","rc":[{"batb":[[0,1.21,82.81]],"ltp":2.0,"tv":403.28,"id":67083366},{"trd":[[1.44,17.66]],"batb":[[0,1.66,10],[1,1.65,16.76],[2,1.63,8]],"ltp":2.0,"tv":422.7,"id":72922097}],"tv":825.99}]}
{"op":"mcm","clk":"11902113440","pt":1724335210971,"mc":[{"id":"1.232089285","rc":[{"batb":[[0,1.65,16.76],[1,1.63,8],[2,1.36,2.67]],"ltp":2.0,"tv":422.7,"id":72922097}]}]}
{"op":"mcm","clk":"11902113739","pt":1724335215264,"mc":[{"id":"1.232089285","rc":[{"batb":[[0,1.66,10],[1,1.65,16.76],[2,1.63,8]],"ltp":2.0,"tv":422.7,"id":72922097}]}]}
{"op":"mcm","clk":"11902113945","pt":1724335218553,"mc":[{"id":"1.232089285","rc":[{"batb":[[0,1.65,16.76],[1,1.63,8],[2,1.36,2.67]],"ltp":2.0,"tv":422.7,"id":72922097}]}]}
{"op":"mcm","clk":"11902114611","pt":1724335227976,"mc":[{"id":"1.232089285","rc":[{"batb":[[0,1.66,10],[1,1.65,16.76],[2,1.63,8]],"ltp":2.0,"tv":422.7,"id":72922097}]}]}
{"op":"mcm","clk":"11902114855","pt":1724335231406,"mc":[{"id":"1.232089285","rc":[{"batb":[[0,1.65,16.76],[1,1.63,8],[2,1.36,2.67]],"ltp":2.0,"tv":422.7,"id":72922097}]}]}
{"op":"mcm","clk":"11902115228","pt":1724335235976,"mc":[{"id":"1.232089285","rc":[{"batb":[[0,1.66,10],[1,1.65,16.76],[2,1.63,8]],"ltp":2.0,"tv":422.7,"id":72922097}]}]}
{"op":"mcm","clk":"11902115502","pt":1724335239403,"mc":[{"id":"1.232089285","rc":[{"batb":[[0,1.65,16.76],[1,1.63,8],[2,1.36,2.67]],"ltp":2.0,"tv":422.7,"id":72922097}]}]}
{"op":"mcm","clk":"11902116047","pt":1724335246914,"mc":[{"id":"1.232089285","rc":[{"batb":[[0,1.66,10],[1,1.65,16.76],[2,1.63,8]],"ltp":2.0,"tv":422.7,"id":72922097}]}]}
{"op":"mcm","clk":"11902116277","pt":1724335250309,"mc":[{"id":"1.232089285","rc":[{"batb":[[0,1.65,16.76],[1,1.63,8],[2,1.36,2.67]],"ltp":2.0,"tv":422.7,"id":72922097}]}]}
{"op":"mcm","clk":"11902116911","pt":1724335258704,"mc":[{"id":"1.232089285","rc":[{"batb":[[0,1.66,10],[1,1.65,16.76],[2,1.63,8]],"ltp":2.0,"tv":422.7,"id":72922097}]}]}
{"op":"mcm","clk":"11902117132","pt":1724335262037,"mc":[{"id":"1.232089285","rc":[{"batb":[[0,1.65,16.76],[1,1.63,8],[2,1.36,2.67]],"ltp":2.0,"tv":422.7,"id":72922097}]}]}
{"op":"mcm","clk":"11902117353","pt":1724335264503,"mc":[{"id":"1.232089285","rc":[{"batb":[[0,1.66,10],[1,1.65,16.76],[2,1.63,8]],"ltp":2.0,"tv":422.7,"id":72922097}]}]}
{"op":"mcm","clk":"11902117580","pt":1724335267924,"mc":[{"id":"1.232089285","rc":[{"batb":[[0,1.65,16.76],[1,1.63,8],[2,1.36,2.67]],"ltp":2.0,"tv":422.7,"id":72922097}]}]}
{"op":"mcm","clk":"11902117728","pt":1724335270127,"mc":[{"id":"1.232089285","rc":[{"batb":[[0,1.66,10],[1,1.65,16.76],[2,1.63,8]],"ltp":2.0,"tv":422.7,"id":72922097}]}]}
{"op":"mcm","clk":"11902117984","pt":1724335273603,"mc":[{"id":"1.232089285","rc":[{"batb":[[0,1.65,16.76],[1,1.63,8],[2,1.36,2.67]],"ltp":2.0,"tv":422.7,"id":72922097}]}]}
{"op":"mcm","clk":"11902118579","pt":1724335283438,"mc":[{"id":"1.232089285","rc":[{"batb":[[0,1.66,10],[1,1.65,16.76],[2,1.63,8]],"ltp":2.0,"tv":422.7,"id":72922097}]}]}
{"op":"mcm","clk":"11902118777","pt":1724335286749,"mc":[{"id":"1.232089285","rc":[{"batb":[[0,1.65,16.76],[1,1.63,8],[2,1.36,2.67]],"ltp":2.0,"tv":422.7,"id":72922097}]}]}
{"op":"mcm","clk":"11902119051","pt":1724335290730,"mc":[{"id":"1.232089285","rc":[{"batb":[[0,1.66,10],[1,1.65,16.76],[2,1.63,8]],"ltp":2.0,"tv":422.7,"id":72922097}]}]}
{"op":"mcm","clk":"11902119296","pt":1724335294337,"mc":[{"id":"1.232089285","rc":[{"batb":[[0,1.65,16.76],[1,1.63,8],[2,1.36,2.67]],"ltp":2.0,"tv":422.7,"id":72922097}]}]}
{"op":"mcm","clk":"11902119503","pt":1724335298249,"mc":[{"id":"1.232089285","rc":[{"batb":[[0,1.66,10],[1,1.65,16.76],[2,1.63,8]],"ltp":2.0,"tv":422.7,"id":72922097}]}]}
{"op":"mcm","clk":"11902119700","pt":1724335301657,"mc":[{"id":"1.232089285","rc":[{"batb":[[0,1.65,16.76],[1,1.63,8],[2,1.36,2.67]],"ltp":2.0,"tv":422.7,"id":72922097}]}]}
{"op":"mcm","clk":"11902120047","pt":1724335306097,"mc":[{"id":"1.232089285","rc":[{"batb":[[0,1.66,10],[1,1.65,16.76],[2,1.63,8]],"ltp":2.0,"tv":422.7,"id":72922097}]}]}
{"op":"mcm","clk":"11902120240","pt":1724335309394,"mc":[{"id":"1.232089285","rc":[{"batb":[[0,1.65,16.76],[1,1.63,8],[2,1.36,2.67]],"ltp":2.0,"tv":422.7,"id":72922097}]}]}
{"op":"mcm","clk":"11902121092","pt":1724335321875,"mc":[{"id":"1.232089285","rc":[{"batb":[[0,1.66,10],[1,1.65,16.76],[2,1.63,8]],"ltp":2.0,"tv":422.7,"id":72922097}]}]}
{"op":"mcm","clk":"11902121349","pt":1724335325288,"mc":[{"id":"1.232089285","rc":[{"batb":[[0,2,10],[1,1.21,82.81],[2,1.04,1.53]],"ltp":2.0,"tv":403.28,"id":67083366},{"batb":[[0,1.65,16.76],[1,1.63,8],[2,1.36,2.67]],"ltp":2.0,"tv":422.7,"id":72922097}]}]}
{"op":"mcm","clk":"11902121561","pt":1724335328197,"mc":[{"id":"1.232089285","rc":[{"batb":[[0,1.66,10],[1,1.65,16.76],[2,1.63,8]],"ltp":2.0,"tv":422.7,"id":72922097}]}]}
{"op":"mcm","clk":"11902121786","pt":1724335331496,"mc":[{"id":"1.232089285","rc":[{"batb":[[0,1.65,16.76],[1,1.63,8],[2,1.36,2.67]],"ltp":2.0,"tv":422.7,"id":72922097}]}]}
{"op":"mcm","clk":"11902122403","pt":1724335340857,"mc":[{"id":"1.232089285","rc":[{"batb":[[0,1.66,10],[1,1.65,16.76],[2,1.63,8]],"ltp":2.0,"tv":422.7,"id":72922097}]}]}
{"op":"mcm","clk":"11902122942","pt":1724335344135,"mc":[{"id":"1.232089285","rc":[{"batb":[[0,1.65,16.76],[1,1.63,8],[2,1.36,2.67]],"ltp":2.0,"tv":422.7,"id":72922097}]}]}
{"op":"mcm","clk":"11902123846","pt":1724335347639,"mc":[{"id":"1.232089285","rc":[{"batb":[[0,1.66,10],[1,1.65,16.76],[2,1.63,8]],"ltp":2.0,"tv":422.7,"id":72922097}]}]}
{"op":"mcm","clk":"11902124957","pt":1724335351049,"mc":[{"id":"1.232089285","rc":[{"batb":[[0,1.65,16.76],[1,1.63,8],[2,1.36,2.67]],"ltp":2.0,"tv":422.7,"id":72922097}]}]}
{"op":"mcm","clk":"11902125839","pt":1724335362076,"mc":[{"id":"1.232089285","rc":[{"batb":[[0,1.66,10],[1,1.65,16.76],[2,1.63,8]],"ltp":2.0,"tv":422.7,"id":72922097}]}]}
{"op":"mcm","clk":"11902126069","pt":1724335365469,"mc":[{"id":"1.232089285","rc":[{"batb":[[0,1.65,16.76],[1,1.63,8],[2,1.36,2.67]],"ltp":2.0,"tv":422.7,"id":72922097}]}]}
{"op":"mcm","clk":"11902126372","pt":1724335369561,"mc":[{"id":"1.232089285","rc":[{"batb":[[0,1.66,10],[1,1.65,16.76],[2,1.63,8]],"ltp":2.0,"tv":422.7,"id":72922097}]}]}
{"op":"mcm","clk":"11902126657","pt":1724335372987,"mc":[{"id":"1.232089285","rc":[{"batb":[[0,1.65,16.76],[1,1.63,8],[2,1.36,2.67]],"ltp":2.0,"tv":422.7,"id":72922097}]}]}
{"op":"mcm","clk":"11902126983","pt":1724335378068,"mc":[{"id":"1.232089285","rc":[{"batb":[[0,1.66,10],[1,1.65,16.76],[2,1.63,8]],"ltp":2.0,"tv":422.7,"id":72922097}]}]}
{"op":"mcm","clk":"11902127242","pt":1724335381388,"mc":[{"id":"1.232089285","rc":[{"batb":[[0,1.65,16.76],[1,1.63,8],[2,1.36,2.67]],"ltp":2.0,"tv":422.7,"id":72922097}]}]}
{"op":"mcm","clk":"11902127551","pt":1724335385875,"mc":[{"id":"1.232089285","rc":[{"batb":[[0,1.66,10],[1,1.65,16.76],[2,1.63,8]],"ltp":2.0,"tv":422.7,"id":72922097}]}]}
{"op":"mcm","clk":"11902127798","pt":1724335389182,"mc":[{"id":"1.232089285","rc":[{"batb":[[0,1.65,16.76],[1,1.63,8],[2,1.36,2.67]],"ltp":2.0,"tv":422.7,"id":72922097}]}]}
{"op":"mcm","clk":"11902128753","pt":1724335401810,"mc":[{"id":"1.232089285","rc":[{"batb":[[0,1.66,10],[1,1.65,16.76],[2,1.63,8]],"ltp":2.0,"tv":422.7,"id":72922097}]}]}
{"op":"mcm","clk":"11902129015","pt":1724335405133,"mc":[{"id":"1.232089285","rc":[{"batb":[[0,1.65,16.76],[1,1.63,8],[2,1.36,2.67]],"ltp":2.0,"tv":422.7,"id":72922097}]}]}
{"op":"mcm","clk":"11902129229","pt":1724335407908,"mc":[{"id":"1.232089285","rc":[{"batb":[[0,1.66,10],[1,1.65,16.76],[2,1.63,8]],"ltp":2.0,"tv":422.7,"id":72922097}]}]}
{"op":"mcm","clk":"11902129451","pt":1724335411312,"mc":[{"id":"1.232089285","rc":[{"batb":[[0,1.65,16.76],[1,1.63,8],[2,1.36,2.67]],"ltp":2.0,"tv":422.7,"id":72922097}]}]}
{"op":"mcm","clk":"11902129637","pt":1724335414116,"mc":[{"id":"1.232089285","rc":[{"batb":[[0,1.66,10],[1,1.65,16.76],[2,1.63,8]],"ltp":2.0,"tv":422.7,"id":72922097}]}]}
{"op":"mcm","clk":"11902129839","pt":1724335417452,"mc":[{"id":"1.232089285","rc":[{"batb":[[0,1.65,16.76],[1,1.63,8],[2,1.36,2.67]],"ltp":2.0,"tv":422.7,"id":72922097}]}]}
{"op":"mcm","clk":"11902130416","pt":1724335424525,"mc":[{"id":"1.232089285","rc":[{"batb":[[0,1.66,10],[1,1.65,16.76],[2,1.63,8]],"ltp":2.0,"tv":422.7,"id":72922097}]}]}
{"op":"mcm","clk":"11902130715","pt":1724335428512,"mc":[{"id":"1.232089285","rc":[{"batb":[[0,1.65,16.76],[1,1.63,8],[2,1.36,2.67]],"ltp":2.0,"tv":422.7,"id":72922097}]}]}
{"op":"mcm","clk":"11902130994","pt":1724335431938,"mc":[{"id":"1.232089285","rc":[{"batb":[[0,1.66,10],[1,1.65,16.76],[2,1.63,8]],"ltp":2.0,"tv":422.7,"id":72922097}]}]}
{"op":"mcm","clk":"11902131272","pt":1724335435504,"mc":[{"id":"1.232089285","rc":[{"batb":[[0,1.65,16.76],[1,1.63,8],[2,1.36,2.67]],"ltp":2.0,"tv":422.7,"id":72922097}]}]}
{"op":"mcm","clk":"11902131599","pt":1724335438836,"mc":[{"id":"1.232089285","rc":[{"batb":[[0,1.66,10],[1,1.65,16.76],[2,1.63,8]],"ltp":2.0,"tv":422.7,"id":72922097}]}]}
{"op":"mcm","clk":"11902131911","pt":1724335442277,"mc":[{"id":"1.232089285","rc":[{"batb":[[0,1.65,16.76],[1,1.63,8],[2,1.36,2.67]],"ltp":2.0,"tv":422.7,"id":72922097}]}]}
{"op":"mcm","clk":"11902132104","pt":1724335444451,"mc":[{"id":"1.232089285","rc":[{"batb":[[0,1.66,10],[1,1.65,16.76],[2,1.63,8]],"ltp":2.0,"tv":422.7,"id":72922097}]}]}
{"op":"mcm","clk":"11902132373","pt":1724335447763,"mc":[{"id":"1.232089285","rc":[{"batb":[[0,1.65,16.76],[1,1.63,8],[2,1.36,2.67]],"ltp":2.0,"tv":422.7,"id":72922097}]}]}
{"op":"mcm","clk":"11902132828","pt":1724335453198,"mc":[{"id":"1.232089285","rc":[{"batb":[[0,1.66,10],[1,1.65,16.76],[2,1.63,8]],"ltp":2.0,"tv":422.7,"id":72922097}]}]}
{"op":"mcm","clk":"11902133111","pt":1724335456562,"mc":[{"id":"1.232089285","rc":[{"batb":[[0,1.65,16.76],[1,1.63,8],[2,1.36,2.67]],"ltp":2.0,"tv":422.7,"id":72922097}]}]}
{"op":"mcm","clk":"11902134049","pt":1724335468887,"mc":[{"id":"1.232089285","rc":[{"batb":[[0,1.66,10],[1,1.65,16.76],[2,1.63,8]],"ltp":2.0,"tv":422.7,"id":72922097}]}]}
{"op":"mcm","clk":"11902134365","pt":1724335472594,"mc":[{"id":"1.232089285","rc":[{"batb":[[0,1.65,16.76],[1,1.63,8],[2,1.36,2.67]],"ltp":2.0,"tv":422.7,"id":72922097}]}]}
{"op":"mcm","clk":"11902135167","pt":1724335482806,"mc":[{"id":"1.232089285","rc":[{"batb":[[0,1.66,10],[1,1.65,16.76],[2,1.63,8]],"ltp":2.0,"tv":422.7,"id":72922097}]}]}
{"op":"mcm","clk":"11902135446","pt":1724335486331,"mc":[{"id":"1.232089285","rc":[{"batb":[[0,1.65,16.76],[1,1.63,8],[2,1.36,2.67]],"ltp":2.0,"tv":422.7,"id":72922097}]}]}
{"op":"mcm","clk":"11902136521","pt":1724335500493,"mc":[{"id":"1.232089285","rc":[{"batb":[[0,1.66,10],[1,1.65,16.76],[2,1.63,8]],"ltp":2.0,"tv":422.7,"id":72922097}]}]}
{"op":"mcm","clk":"11902136826","pt":1724335503824,"mc":[{"id":"1.232089285","rc":[{"batb":[[0,1.65,16.76],[1,1.63,8],[2,1.36,2.67]],"ltp":2.0,"tv":422.7,"id":72922097}]}]}
{"op":"mcm","clk":"11902137086","pt":1724335507349,"mc":[{"id":"1.232089285","rc":[{"batb":[[0,1.66,10],[1,1.65,16.76],[2,1.63,8]],"ltp":2.0,"tv":422.7,"id":72922097}]}]}
{"op":"mcm","clk":"11902137307","pt":1724335510761,"mc":[{"id":"1.232089285","rc":[{"batb":[[0,1.65,16.76],[1,1.63,8],[2,1.36,2.67]],"ltp":2.0,"tv":422.7,"id":72922097}]}]}
{"op":"mcm","clk":"11902137631","pt":1724335514836,"mc":[{"id":"1.232089285","rc":[{"batb":[[0,1.66,10],[1,1.65,16.76],[2,1.63,8]],"ltp":2.0,"tv":422.7,"id":72922097}]}]}
{"op":"mcm","clk":"11902137853","pt":1724335518249,"mc":[{"id":"1.232089285","rc":[{"batb":[[0,1.65,16.76],[1,1.63,8],[2,1.36,2.67]],"ltp":2.0,"tv":422.7,"id":72922097}]}]}
{"op":"mcm","clk":"11902138309","pt":1724335525344,"mc":[{"id":"1.232089285","rc":[{"batb":[[0,1.66,10],[1,1.65,16.76],[2,1.63,8]],"ltp":2.0,"tv":422.7,"id":72922097}]}]}
{"op":"mcm","clk":"11902138541","pt":1724335528841,"mc":[{"id":"1.232089285","rc":[{"batb":[[0,1.65,16.76],[1,1.63,8],[2,1.36,2.67]],"ltp":2.0,"tv":422.7,"id":72922097}]}]}
{"op":"mcm","clk":"11902138929","pt":1724335534758,"mc":[{"id":"1.232089285","rc":[{"batb":[[0,1.66,10],[1,1.65,16.76],[2,1.63,8]],"ltp":2.0,"tv":422.7,"id":72922097}]}]}
{"op":"mcm","clk":"11902139154","pt":1724335537981,"mc":[{"id":"1.232089285","rc":[{"batb":[[0,1.65,16.76],[1,1.63,8],[2,1.36,2.67]],"ltp":2.0,"tv":422.7,"id":72922097}]}]}
{"op":"mcm","clk":"11902139814","pt":1724335548294,"mc":[{"id":"1.232089285","rc":[{"batb":[[0,1.66,10],[1,1.65,16.76],[2,1.63,8]],"ltp":2.0,"tv":422.7,"id":72922097}]}]}
{"op":"mcm","clk":"11902140067","pt":1724335551775,"mc":[{"id":"1.232089285","rc":[{"batb":[[0,1.65,16.76],[1,1.63,8],[2,1.36,2.67]],"ltp":2.0,"tv":422.7,"id":72922097}]}]}
{"op":"mcm","clk":"11902140242","pt":1724335554492,"mc":[{"id":"1.232089285","rc":[{"batb":[[0,1.66,10],[1,1.65,16.76],[2,1.63,8]],"ltp":2.0,"tv":422.7,"id":72922097}]}]}
{"op":"mcm","clk":"11902140492","pt":1724335558008,"mc":[{"id":"1.232089285","rc":[{"batb":[[0,1.65,16.76],[1,1.63,8],[2,1.36,2.67]],"ltp":2.0,"tv":422.7,"id":72922097}]}]}
{"op":"mcm","clk":"11902141032","pt":1724335565197,"mc":[{"id":"1.232089285","rc":[{"batb":[[0,1.66,10],[1,1.65,16.76],[2,1.63,8]],"ltp":2.0,"tv":422.7,"id":72922097}]}]}
{"op":"mcm","clk":"11902141224","pt":1724335568405,"mc":[{"id":"1.232089285","rc":[{"batb":[[0,1.65,16.76],[1,1.63,8],[2,1.36,2.67]],"ltp":2.0,"tv":422.7,"id":72922097}]}]}
{"op":"mcm","clk":"11902142005","pt":1724335579229,"mc":[{"id":"1.232089285","rc":[{"batb":[[0,1.66,10],[1,1.65,16.76],[2,1.63,8]],"ltp":2.0,"tv":422.7,"id":72922097}]}]}
{"op":"mcm","clk":"11902142269","pt":1724335582420,"mc":[{"id":"1.232089285","rc":[{"batb":[[0,1.65,16.76],[1,1.63,8],[2,1.36,2.67]],"ltp":2.0,"tv":422.7,"id":72922097}]}]}
{"op":"mcm","clk":"11902142862","pt":1724335590044,"mc":[{"id":"1.232089285","rc":[{"batb":[[0,1.66,10],[1,1.65,16.76],[2,1.63,8]],"ltp":2.0,"tv":422.7,"id":72922097}]}]}
{"op":"mcm","clk":"11902143122","pt":1724335593458,"mc":[{"id":"1.232089285","rc":[{"batb":[[0,1.65,16.76],[1,1.63,8],[2,1.36,2.67]],"ltp":2.0,"tv":422.7,"id":72922097}]}]}
{"op":"mcm","clk":"11902143360","pt":1724335596464,"mc":[{"id":"1.232089285","rc":[{"batb":[[0,1.66,10],[1,1.65,16.76],[2,1.63,8]],"ltp":2.0,"tv":422.7,"id":72922097}]}]}
{"op":"mcm","clk":"11902143660","pt":1724335599967,"mc":[{"id":"1.232089285","rc":[{"batb":[[0,1.65,16.76],[1,1.63,8],[2,1.36,2.67]],"ltp":2.0,"tv":422.7,"id":72922097}]}]}
{"op":"mcm","clk":"11902143816","pt":1724335602370,"mc":[{"id":"1.232089285","rc":[{"batb":[[0,1.66,10],[1,1.65,16.76],[2,1.63,8]],"ltp":2.0,"tv":422.7,"id":72922097}]}]}
{"op":"mcm","clk":"11902144087","pt":1724335606145,"mc":[{"id":"1.232089285","rc":[{"batb":[[0,1.65,16.76],[1,1.63,8],[2,1.36,2.67]],"ltp":2.0,"tv":422.7,"id":72922097}]}]}
{"op":"mcm","clk":"11902144629","pt":1724335613685,"mc":[{"id":"1.232089285","rc":[{"batb":[[0,1.66,10],[1,1.65,16.76],[2,1.63,8]],"ltp":2.0,"tv":422.7,"id":72922097}]}]}
{"op":"mcm","clk":"11902144836","pt":1724335616945,"mc":[{"id":"1.232089285","rc":[{"batb":[[0,1.65,16.76],[1,1.63,8],[2,1.36,2.67]],"ltp":2.0,"tv":422.7,"id":72922097}]}]}
{"op":"mcm","clk":"11902145149","pt":1724335621755,"mc":[{"id":"1.232089285","rc":[{"batb":[[0,1.66,10],[1,1.65,16.76],[2,1.63,8]],"ltp":2.0,"tv":422.7,"id":72922097}]}]}
{"op":"mcm","clk":"11902145365","pt":1724335625358,"mc":[{"id":"1.232089285","rc":[{"batb":[[0,1.65,16.76],[1,1.63,8],[2,1.36,2.67]],"ltp":2.0,"tv":422.7,"id":72922097}]}]}
{"op":"mcm","clk":"11902145514","pt":1724335628189,"mc":[{"id":"1.232089285","rc":[{"batb":[[0,1.66,10],[1,1.65,16.76],[2,1.63,8]],"ltp":2.0,"tv":422.7,"id":72922097}]}]}
{"op":"mcm","clk":"11902145727","pt":1724335631701,"mc":[{"id":"1.232089285","rc":[{"batb":[[0,1.65,16.76],[1,1.63,8],[2,1.36,2.67]],"ltp":2.0,"tv":422.7,"id":72922097}]}]}
{"op":"mcm","clk":"11902145864","pt":1724335633909,"mc":[{"id":"1.232089285","rc":[{"batb":[[0,1.66,10],[1,1.65,16.76],[2,1.63,8]],"ltp":2.0,"tv":422.7,"id":72922097}]}]}
{"op":"mcm","clk":"11902146057","pt":1724335636889,"mc":[{"id":"1.232089285","rc":[{"trd":[[1.66,21.86]],"batb":[[0,1.65,16.76],[1,1.63,8],[2,1.36,2.67]],"batl":[[0,1.66,41.93],[1,2.02,51.26],[2,2.5,1.93]],"ltp":1.66,"tv":442.7,"id":72922097}],"tv":845.99}]}
{"op":"mcm","clk":"11902147088","pt":1724335650518,"mc":[{"id":"1.232089285","rc":[{"trd":[[1.65,33.52]],"batb":[[0,1.63,8],[1,1.36,2.67],[2,1.35,20]],"batl":[[0,1.65,35.17],[1,1.66,41.93],[2,2.02,51.26]],"ltp":1.65,"tv":476.22,"id":72922097}],"tv":879.51}]}
{"op":"mcm","clk":"11902147321","pt":1724335653615,"mc":[{"id":"1.232089285","rc":[{"batl":[[0,2.02,51.26],[1,2.5,1.93],[2,2.02,0]],"ltp":1.65,"tv":476.22,"id":72922097}]}]}
{"op":"mcm","clk":"11902147328","pt":1724335653720,"mc":[{"id":"1.232089285","rc":[{"batb":[[0,1.64,10],[1,1.63,8],[2,1.36,2.67]],"ltp":1.65,"tv":476.22,"id":72922097}]}]}
{"op":"mcm","clk":"11902147567","pt":1724335656916,"mc":[{"id":"1.232089285","rc":[{"batb":[[0,1.63,8],[1,1.36,2.67],[2,1.35,20]],"ltp":1.65,"tv":476.22,"id":72922097}]}]}
{"op":"mcm","clk":"11902147773","pt":1724335659903,"mc":[{"id":"1.232089285","rc":[{"batb":[[0,1.64,10],[1,1.63,8],[2,1.36,2.67]],"ltp":1.65,"tv":476.22,"id":72922097}]}]}
{"op":"mcm","clk":"11902147997","pt":1724335663204,"mc":[{"id":"1.232089285","rc":[{"batb":[[0,1.63,8],[1,1.36,2.67],[2,1.35,20]],"ltp":1.65,"tv":476.22,"id":72922097}]}]}
{"op":"mcm","clk":"11902148738","pt":1724335674955,"mc":[{"id":"1.232089285","rc":[{"batb":[[0,1.64,10],[1,1.63,8],[2,1.36,2.67]],"ltp":1.65,"tv":476.22,"id":72922097}]}]}
{"op":"mcm","clk":"11902148974","pt":1724335678107,"mc":[{"id":"1.232089285","rc":[{"batb":[[0,1.63,8],[1,1.36,2.67],[2,1.35,20]],"ltp":1.65,"tv":476.22,"id":72922097}]}]}
{"op":"mcm","clk":"11902149583","pt":1724335686139,"mc":[{"id":"1.232089285","rc":[{"batb":[[0,1.64,10],[1,1.63,8],[2,1.36,2.67]],"ltp":1.65,"tv":476.22,"id":72922097}]}]}
{"op":"mcm","clk":"11902149822","pt":1724335689344,"mc":[{"id":"1.232089285","rc":[{"batb":[[0,1.63,8],[1,1.36,2.67],[2,1.35,20]],"ltp":1.65,"tv":476.22,"id":72922097}]}]}
{"op":"mcm","clk":"11902149974","pt":1724335691661,"mc":[{"id":"1.232089285","rc":[{"batb":[[0,1.64,10],[1,1.63,8],[2,1.36,2.67]],"ltp":1.65,"tv":476.22,"id":72922097}]}]}
{"op":"mcm","clk":"11902150205","pt":1724335694968,"mc":[{"id":"1.232089285","rc":[{"batb":[[0,1.63,8],[1,1.36,2.67],[2,1.35,20]],"ltp":1.65,"tv":476.22,"id":72922097}]}]}
{"op":"mcm","clk":"11902150845","pt":1724335702162,"mc":[{"id":"1.232089285","rc":[{"batb":[[0,1.64,10],[1,1.63,8],[2,1.36,2.67]],"ltp":1.65,"tv":476.22,"id":72922097}]}]}
{"op":"mcm","clk":"11902151089","pt":1724335705464,"mc":[{"id":"1.232089285","rc":[{"trd":[[1.67,1.84]],"batb":[[0,1.63,8],[1,1.36,2.67],[2,1.35,20]],"batl":[[0,1.64,51.01],[1,2.02,51.26],[2,2.5,1.93]],"ltp":1.67,"tv":478.06,"id":72922097}],"tv":881.35}]}
{"op":"mcm","clk":"11902151756","pt":1724335714149,"mc":[{"id":"1.232089285","rc":[{"trd":[[1.63,16]],"batb":[[0,1.36,2.67],[1,1.35,20],[2,1.32,4.07]],"batl":[[0,1.63,43.93],[1,1.64,51.01],[2,2.02,51.26]],"ltp":1.63,"tv":494.06,"id":72922097}],"tv":897.35}]}
{"op":"mcm","clk":"11902152031","pt":1724335718067,"mc":[{"id":"1.232089285","rc":[{"batl":[[0,2.02,51.26],[1,2.5,1.93],[2,2.02,0]],"ltp":1.63,"tv":494.06,"id":72922097}]}]}
{"op":"mcm","clk":"11902157174","pt":1724335788764,"mc":[{"id":"1.232089285","rc":[{"trd":[[1.61,2.32]],"ltp":1.61,"tv":496.38,"id":72922097}],"tv":899.67}]}
{"op":"mcm","clk":"11902164293","pt":1724335883203,"mc":[{"id":"1.232089285","rc":[{"batb":[[0,1.37,10.93],[1,1.36,279.52],[2,1.35,20]],"ltp":1.61,"tv":496.38,"id":72922097}]}]}
{"op":"mcm","clk":"11902164527","pt":1724335886520,"mc":[{"id":"1.232089285","rc":[{"batb":[[0,1.36,280.45],[1,1.35,20],[2,1.32,4.07]],"ltp":1.61,"tv":496.38,"id":72922097}]}]}
{"op":"mcm","clk":"11902164581","pt":1724335887304,"mc":[{"id":"1.232089285","rc":[{"batb":[[1,1.22,454.55],[2,1.21,82.81]],"ltp":2.0,"tv":403.28,"id":67083366}]}]}
{"op":"mcm","clk":"11902164883","pt":1724335892222,"mc":[{"id":"1.232089285","rc":[{"batb":[[0,1.37,10.93],[1,1.36,279.52],[2,1.35,20]],"ltp":1.61,"tv":496.38,"id":72922097}]}]}
{"op":"mcm","clk":"11902165094","pt":1724335895820,"mc":[{"id":"1.232089285","rc":[{"batb":[[0,1.36,280.45],[1,1.35,20],[2,1.32,4.07]],"ltp":1.61,"tv":496.38,"id":72922097}]}]}
{"op":"mcm","clk":"11902165324","pt":1724335898925,"mc":[{"id":"1.232089285","rc":[{"batb":[[0,1.37,10.93],[1,1.36,279.52],[2,1.35,20]],"ltp":1.61,"tv":496.38,"id":72922097}]}]}
{"op":"mcm","clk":"11902165553","pt":1724335902340,"mc":[{"id":"1.232089285","rc":[{"batb":[[0,1.36,280.45],[1,1.35,20],[2,1.32,4.07]],"ltp":1.61,"tv":496.38,"id":72922097}]}]}
{"op":"mcm","clk":"11902166045","pt":1724335909371,"mc":[{"id":"1.232089285","rc":[{"batb":[[0,1.37,10.93],[1,1.36,279.52],[2,1.35,20]],"ltp":1.61,"tv":496.38,"id":72922097}]}]}
{"op":"mcm","clk":"11902166250","pt":1724335912836,"mc":[{"id":"1.232089285","rc":[{"batb":[[0,1.36,280.45],[1,1.35,20],[2,1.32,4.07]],"ltp":1.61,"tv":496.38,"id":72922097}]}]}
{"op":"mcm","clk":"11902166805","pt":1724335921078,"mc":[{"id":"1.232089285","rc":[{"batb":[[0,1.45,10],[1,1.44,21.38],[2,1.36,280.45]],"ltp":1.61,"tv":496.38,"id":72922097}]}]}
{"op":"mcm","clk":"11902167045","pt":1724335924264,"mc":[{"id":"1.232089285","rc":[{"batb":[[0,1.44,21.38],[1,1.36,280.45],[2,1.35,20]],"ltp":1.61,"tv":496.38,"id":72922097}]}]}
{"op":"mcm","clk":"11902167590","pt":1724335932474,"mc":[{"id":"1.232089285","rc":[{"batb":[[0,1.45,10],[1,1.44,21.38],[2,1.36,280.45]],"ltp":1.61,"tv":496.38,"id":72922097}]}]}
{"op":"mcm","clk":"11902167807","pt":1724335935890,"mc":[{"id":"1.232089285","rc":[{"batb":[[0,1.44,21.38],[1,1.36,280.45],[2,1.35,20]],"ltp":1.61,"tv":496.38,"id":72922097}]}]}
{"op":"mcm","clk":"11902168551","pt":1724335946299,"mc":[{"id":"1.232089285","rc":[{"batb":[[0,1.45,10.92],[1,1.44,21.38],[2,1.36,280.45]],"ltp":1.61,"tv":496.38,"id":72922097}]}]}
{"op":"mcm","clk":"11902168822","pt":1724335949709,"mc":[{"id":"1.232089285","rc":[{"batb":[[0,1.44,22.3],[1,1.36,280.45],[2,1.35,20]],"ltp":1.61,"tv":496.38,"id":72922097}]}]}
{"op":"mcm","clk":"11902169589","pt":1724335960194,"mc":[{"id":"1.232089285","rc":[{"batb":[[0,1.45,10.92],[1,1.44,21.38],[2,1.36,280.45]],"ltp":1.61,"tv":496.38,"id":72922097}]}]}
{"op":"mcm","clk":"11902169840","pt":1724335963800,"mc":[{"id":"1.232089285","rc":[{"batb":[[0,1.44,22.3],[1,1.36,280.45],[2,1.35,20]],"ltp":1.61,"tv":496.38,"id":72922097}]}]}
{"op":"mcm","clk":"11902170029","pt":1724335966529,"mc":[{"id":"1.232089285","rc":[{"batl":[[0,1.82,41.84],[1,2.02,51.26],[2,2.5,1.93]],"ltp":1.61,"tv":496.38,"id":72922097}]}]}
{"op":"mcm","clk":"11902174337","pt":1724336036608,"mc":[{"id":"1.232089285","rc":[{"batb":[[0,1.42,1.85],[1,1.36,279.52]],"ltp":1.61,"tv":496.38,"id":72922097}]}]}
{"op":"mcm","clk":"11902177484","pt":1724336084492,"mc":[{"id":"1.232089285","rc":[{"batb":[[0,1.43,62.7],[1,1.36,280.45]],"ltp":1.61,"tv":496.38,"id":72922097}]}]}
{"op":"mcm","clk":"11902178085","pt":1724336095740,"mc":[{"id":"1.232089285","rc":[{"trd":[[1.43,123.56],[1.51,1.84]],"batb":[[0,1.36,280.45],[1,1.35,20],[2,1.32,4.07]],"batl":[[0,1.82,42.42]],"ltp":1.43,"tv":621.78,"id":72922097}],"tv":1025.06}]}
{"op":"mcm","clk":"11902178316","pt":1724336099695,"mc":[{"id":"1.232089285","rc":[{"batl":[[0,1.82,41.84]],"ltp":1.43,"tv":621.78,"id":72922097}]}]}
{"op":"mcm","clk":"11902180027","pt":1724336122909,"mc":[{"id":"1.232089285","rc":[{"batb":[[0,1.46,41.84],[1,1.36,280.45],[2,1.35,20]],"ltp":1.43,"tv":621.78,"id":72922097}]}]}
{"op":"mcm","clk":"11902181250","pt":1724336137745,"mc":[{"id":"1.232089285","rc":[{"batb":[[0,1.46,42.38]],"ltp":1.43,"tv":621.78,"id":72922097}]}]}
{"op":"mcm","clk":"11902182827","pt":1724336158941,"mc":[{"id":"1.232089285","rc":[{"batl":[[0,1.81,48.74],[1,1.82,41.84],[2,2.02,51.26]],"ltp":1.43,"tv":621.78,"id":72922097}]}]}
{"op":"mcm","clk":"11902183652","pt":1724336169680,"mc":[{"id":"1.232089285","rc":[{"trd":[[1.81,97.47]],"batb":[[0,1.81,3.38],[1,1.46,42.38],[2,1.36,280.45]],"batl":[[0,1.82,41.84],[1,2.02,51.26],[2,2.5,1.93]],"ltp":1.81,"tv":719.25,"id":72922097}],"tv":1122.54}]}
{"op":"mcm","clk":"11902184007","pt":1724336173771,"mc":[{"id":"1.232089285","rc":[{"batb":[[0,1.46,42.38],[1,1.36,280.45],[2,1.35,20]],"ltp":1.81,"tv":719.25,"id":72922097}]}]}
{"op":"mcm","clk":"11902185061","pt":1724336188092,"mc":[{"id":"1.232089285","rc":[{"batl":[[0,1.77,4.19],[1,1.82,41.84],[2,2.02,51.26]],"ltp":1.81,"tv":719.25,"id":72922097}]}]}
{"op":"mcm","clk":"11902185797","pt":1724336197719,"mc":[{"id":"1.232089285","rc":[{"trd":[[1.77,1.72]],"batl":[[0,1.77,3.33]],"ltp":1.77,"tv":720.97,"id":72922097}],"tv":1124.26}]}
{"op":"mcm","clk":"11902186790","pt":1724336211368,"mc":[{"id":"1.232089285","rc":[{"batl":[[1,1.81,13.01],[2,1.82,41.84]],"ltp":1.77,"tv":720.97,"id":72922097}]}]}
{"op":"mcm","clk":"11902197813","pt":1724336347469,"mc":[{"id":"1.232089285","rc":[{"batl":[[0,1.75,16.76],[1,1.77,3.33],[2,1.81,13.01]],"ltp":1.77,"tv":720.97,"id":72922097}]}]}
{"op":"mcm","clk":"11902197930","pt":1724336348766,"mc":[{"id":"1.232089285","rc":[{"batb":[[0,1.5,1.54],[1,1.46,41.84],[2,1.36,280.45]],"ltp":1.77,"tv":720.97,"id":72922097}]}]}
{"op":"mcm","clk":"11902211177","pt":1724336568984,"mc":[{"id":"1.232089285","rc":[{"batl":[[1,1.81,13.01],[2,1.82,41.84]],"ltp":1.77,"tv":720.97,"id":72922097}]}]}
{"op":"mcm","clk":"11902211803","pt":1724336580544,"mc":[{"id":"1.232089285","rc":[{"batb":[[1,1.36,280.45],[2,1.35,20]],"ltp":1.77,"tv":720.97,"id":72922097}]}]}
{"op":"mcm","clk":"11902211842","pt":1724336581471,"mc":[{"id":"1.232089285","rc":[{"batb":[[0,2.02,14],[1,2,10],[2,1.22,454.55]],"batl":[[0,3.75,7.6]],"ltp":2.0,"tv":403.28,"id":67083366}]}]}
{"op":"mcm","clk":"11902211964","pt":1724336583748,"mc":[{"id":"1.232089285","rc":[{"batb":[[0,2.02,10]],"ltp":2.0,"tv":403.28,"id":67083366}]}]}
{"op":"mcm","clk":"11902212016","pt":1724336584779,"mc":[{"id":"1.232089285","rc":[{"batb":[[0,2,10],[1,1.22,454.55],[2,1.21,82.81]],"ltp":2.0,"tv":403.28,"id":67083366}]}]}
{"op":"mcm","clk":"11902212284","pt":1724336589466,"mc":[{"id":"1.232089285","rc":[{"batb":[[0,2.02,14],[1,2,10],[2,1.22,454.55]],"ltp":2.0,"tv":403.28,"id":67083366},{"batl":[[1,1.82,41.84],[2,2.02,51.26]],"ltp":1.77,"tv":720.97,"id":72922097}]}]}
{"op":"mcm","clk":"11902212443","pt":1724336591893,"mc":[{"id":"1.232089285","rc":[{"batb":[[0,2.02,10]],"ltp":2.0,"tv":403.28,"id":67083366}]}]}
{"op":"mcm","clk":"11902212511","pt":1724336592873,"mc":[{"id":"1.232089285","rc":[{"batb":[[0,2,10],[1,1.22,454.55],[2,1.21,82.81]],"ltp":2.0,"tv":403.28,"id":67083366}]}]}
{"op":"mcm","clk":"11902212697","pt":1724336595772,"mc":[{"id":"1.232089285","rc":[{"batb":[[0,2.02,14],[1,2,10],[2,1.22,454.55]],"ltp":2.0,"tv":403.28,"id":67083366}]}]}
{"op":"mcm","clk":"11902212831","pt":1724336598302,"mc":[{"id":"1.232089285","rc":[{"batb":[[0,2.02,10]],"ltp":2.0,"tv":403.28,"id":67083366}]}]}
{"op":"mcm","clk":"11902212870","pt":1724336598975,"mc":[{"id":"1.232089285","rc":[{"batb":[[0,2,10],[1,1.22,454.55],[2,1.21,82.81]],"ltp":2.0,"tv":403.28,"id":67083366}]}]}
{"op":"mcm","clk":"11902213007","pt":1724336601186,"mc":[{"id":"1.232089285","rc":[{"batb":[[0,2.02,14],[1,2,10],[2,1.22,454.55]],"ltp":2.0,"tv":403.28,"id":67083366}]}]}
{"op":"mcm","clk":"11902213125","pt":1724336603404,"mc":[{"id":"1.232089285","rc":[{"batb":[[0,2.02,10]],"ltp":2.0,"tv":403.28,"id":67083366}]}]}
{"op":"mcm","clk":"11902213187","pt":1724336604687,"mc":[{"id":"1.232089285","rc":[{"batb":[[0,2,10],[1,1.22,454.55],[2,1.21,82.81]],"ltp":2.0,"tv":403.28,"id":67083366}]}]}
{"op":"mcm","clk":"11902213559","pt":1724336610998,"mc":[{"id":"1.232089285","rc":[{"batb":[[0,2.02,14],[1,2,10],[2,1.22,454.55]],"ltp":2.0,"tv":403.28,"id":67083366}]}]}
{"op":"mcm","clk":"11902213720","pt":1724336613284,"mc":[{"id":"1.232089285","rc":[{"batb":[[0,2.02,10]],"ltp":2.0,"tv":403.28,"id":67083366}]}]}
{"op":"mcm","clk":"11902213800","pt":1724336614427,"mc":[{"id":"1.232089285","rc":[{"batb":[[0,2,10],[1,1.22,454.55],[2,1.21,82.81]],"ltp":2.0,"tv":403.28,"id":67083366}]}]}
{"op":"mcm","clk":"11902214786","pt":1724336628627,"mc":[{"id":"1.232089285","rc":[{"batb":[[0,2.02,14],[1,2,10],[2,1.22,454.55]],"ltp":2.0,"tv":403.28,"id":67083366}]}]}
{"op":"mcm","clk":"11902214915","pt":1724336631156,"mc":[{"id":"1.232089285","rc":[{"batb":[[0,2.02,10]],"ltp":2.0,"tv":403.28,"id":67083366}]}]}
{"op":"mcm","clk":"11902214967","pt":1724336632139,"mc":[{"id":"1.232089285","rc":[{"batb":[[0,2,10],[1,1.22,454.55],[2,1.21,82.81]],"ltp":2.0,"tv":403.28,"id":67083366}]}]}
{"op":"mcm","clk":"11902215133","pt":1724336634938,"mc":[{"id":"1.232089285","rc":[{"batb":[[0,2.02,14],[1,2,10],[2,1.22,454.55]],"ltp":2.0,"tv":403.28,"id":67083366}]}]}
{"op":"mcm","clk":"11902215299","pt":1724336637223,"mc":[{"id":"1.232089285","rc":[{"batb":[[0,2.02,10]],"ltp":2.0,"tv":403.28,"id":67083366}]}]}
{"op":"mcm","clk":"11902215359","pt":1724336638261,"mc":[{"id":"1.232089285","rc":[{"batb":[[0,2,10],[1,1.22,454.55],[2,1.21,82.81]],"ltp":2.0,"tv":403.28,"id":67083366}]}]}
{"op":"mcm","clk":"11902215919","pt":1724336646143,"mc":[{"id":"1.232089285","rc":[{"batb":[[0,2.02,14],[1,2,10],[2,1.22,454.55]],"ltp":2.0,"tv":403.28,"id":67083366}]}]}
{"op":"mcm","clk":"11902216082","pt":1724336648372,"mc":[{"id":"1.232089285","rc":[{"batb":[[0,2.02,10]],"ltp":2.0,"tv":403.28,"id":67083366}]}]}
{"op":"mcm","clk":"11902216152","pt":1724336649469,"mc":[{"id":"1.232089285","rc":[{"batb":[[0,2,10],[1,1.22,454.55],[2,1.21,82.81]],"ltp":2.0,"tv":403.28,"id":67083366}]}]}
{"op":"mcm","clk":"11902217350","pt":1724336669793,"mc":[{"id":"1.232089285","rc":[{"batb":[[0,2.02,14],[1,2,10],[2,1.22,454.55]],"ltp":2.0,"tv":403.28,"id":67083366}]}]}
{"op":"mcm","clk":"11902217517","pt":1724336672503,"mc":[{"id":"1.232089285","rc":[{"batb":[[0,2.02,10]],"ltp":2.0,"tv":403.28,"id":67083366}]}]}
{"op":"mcm","clk":"11902217547","pt":1724336673076,"mc":[{"id":"1.232089285","rc":[{"batb":[[0,2,10],[1,1.22,454.55],[2,1.21,82.81]],"ltp":2.0,"tv":403.28,"id":67083366}]}]}
{"op":"mcm","clk":"11902218315","pt":1724336685875,"mc":[{"id":"1.232089285","rc":[{"batb":[[0,2.02,14],[1,2,10],[2,1.22,454.55]],"ltp":2.0,"tv":403.28,"id":67083366}]}]}
{"op":"mcm","clk":"11902218573","pt":1724336689916,"mc":[{"id":"1.232089285","rc":[{"batb":[[0,2.02,10]],"ltp":2.0,"tv":403.28,"id":67083366}]}]}
{"op":"mcm","clk":"11902218631","pt":1724336690997,"mc":[{"id":"1.232089285","rc":[{"batb":[[0,2,10],[1,1.22,454.55],[2,1.21,82.81]],"ltp":2.0,"tv":403.28,"id":67083366}]}]}
{"op":"mcm","clk":"11902219276","pt":1724336701337,"mc":[{"id":"1.232089285","rc":[{"batb":[[0,2.02,14],[1,2,10],[2,1.22,454.55]],"ltp":2.0,"tv":403.28,"id":67083366}]}]}
{"op":"mcm","clk":"11902219446","pt":1724336703614,"mc":[{"id":"1.232089285","rc":[{"batb":[[0,2.02,10]],"ltp":2.0,"tv":403.28,"id":67083366}]}]}
{"op":"mcm","clk":"11902219511","pt":1724336704602,"mc":[{"id":"1.232089285","rc":[{"batb":[[0,2,10],[1,1.22,454.55],[2,1.21,82.81]],"ltp":2.0,"tv":403.28,"id":67083366}]}]}
{"op":"mcm","clk":"11902219982","pt":1724336710313,"mc":[{"id":"1.232089285","rc":[{"batb":[[0,2.02,14],[1,2,10],[2,1.22,454.55]],"batl":[[0,3.75,12.51]],"ltp":2.0,"tv":403.28,"id":67083366}]}]}
{"op":"mcm","clk":"11902220152","pt":1724336712734,"mc":[{"id":"1.232089285","rc":[{"batb":[[0,2.02,10]],"ltp":2.0,"tv":403.28,"id":67083366}]}]}
{"op":"mcm","clk":"11902220243","pt":1724336713818,"mc":[{"id":"1.232089285","rc":[{"batb":[[0,2,10],[1,1.22,454.55],[2,1.21,82.81]],"ltp":2.0,"tv":403.28,"id":67083366}]}]}
{"op":"mcm","clk":"11902221120","pt":1724336726966,"mc":[{"id":"1.232089285","rc":[{"batb":[[0,2.02,14],[1,2,10],[2,1.22,454.55]],"ltp":2.0,"tv":403.28,"id":67083366}]}]}
{"op":"mcm","clk":"11902221314","pt":1724336729451,"mc":[{"id":"1.232089285","rc":[{"batb":[[0,2.02,10]],"ltp":2.0,"tv":403.28,"id":67083366}]}]}
{"op":"mcm","clk":"11902221384","pt":1724336730325,"mc":[{"id":"1.232089285","rc":[{"batb":[[0,2,10],[1,1.22,454.55],[2,1.21,82.81]],"ltp":2.0,"tv":403.28,"id":67083366}]}]}
{"op":"mcm","clk":"11902221863","pt":1724336737064,"mc":[{"id":"1.232089285","rc":[{"batb":[[0,2.02,14],[1,2,10],[2,1.22,454.55]],"ltp":2.0,"tv":403.28,"id":67083366}]}]}
{"op":"mcm","clk":"11902221988","pt":1724336739241,"mc":[{"id":"1.232089285","rc":[{"batb":[[0,2.02,10]],"ltp":2.0,"tv":403.28,"id":67083366}]}]}
{"op":"mcm","clk":"11902222058","pt":1724336740435,"mc":[{"id":"1.232089285","rc":[{"batb":[[0,2,10],[1,1.22,454.55],[2,1.21,82.81]],"ltp":2.0,"tv":403.28,"id":67083366}]}]}
{"op":"mcm","clk":"11902222417","pt":1724336745859,"mc":[{"id":"1.232089285","rc":[{"batb":[[0,2.02,14],[1,2,10],[2,1.22,454.55]],"ltp":2.0,"tv":403.28,"id":67083366}]}]}
{"op":"mcm","clk":"11902222560","pt":1724336748236,"mc":[{"id":"1.232089285","rc":[{"batb":[[0,2.02,10]],"ltp":2.0,"tv":403.28,"id":67083366}]}]}
{"op":"mcm","clk":"11902222625","pt":1724336749370,"mc":[{"id":"1.232089285","rc":[{"batb":[[0,2,10],[1,1.22,454.55],[2,1.21,82.81]],"ltp":2.0,"tv":403.28,"id":67083366}]}]}
{"op":"mcm","clk":"11902222724","pt":1724336750975,"mc":[{"id":"1.232089285","rc":[{"batb":[[0,2.02,4],[1,2,10],[2,1.22,454.55]],"ltp":2.0,"tv":403.28,"id":67083366}]}]}
{"op":"mcm","clk":"11902222894","pt":1724336753251,"mc":[{"id":"1.232089285","rc":[{"batb":[[0,2.04,10]],"ltp":2.0,"tv":403.28,"id":67083366}]}]}
{"op":"mcm","clk":"11902223010","pt":1724336755467,"mc":[{"id":"1.232089285","rc":[{"batb":[[0,2.06,4],[1,2.04,10],[2,2,10]],"ltp":2.0,"tv":403.28,"id":67083366}]}]}
{"op":"mcm","clk":"11902223073","pt":1724336756451,"mc":[{"id":"1.232089285","rc":[{"batb":[[1,2,10],[2,1.22,454.55]],"ltp":2.0,"tv":403.28,"id":67083366}]}]}
{"op":"mcm","clk":"11902223143","pt":1724336757748,"mc":[{"id":"1.232089285","rc":[{"batb":[[0,2,10],[1,1.22,454.55],[2,1.21,82.81]],"ltp":2.0,"tv":403.28,"id":67083366}]}]}
{"op":"mcm","clk":"11902223394","pt":1724336761588,"mc":[{"id":"1.232089285","rc":[{"batb":[[0,2.02,14],[1,2,10],[2,1.22,454.55]],"ltp":2.0,"tv":403.28,"id":67083366}]}]}
{"op":"mcm","clk":"11902223540","pt":1724336764369,"mc":[{"id":"1.232089285","rc":[{"batb":[[0,2.02,10]],"ltp":2.0,"tv":403.28,"id":67083366}]}]}
{"op":"mcm","clk":"11902223583","pt":1724336765393,"mc":[{"id":"1.232089285","rc":[{"batb":[[0,2,10],[1,1.22,454.55],[2,1.21,82.81]],"ltp":2.0,"tv":403.28,"id":67083366}]}]}
{"op":"mcm","clk":"11902223796","pt":1724336769203,"mc":[{"id":"1.232089285","rc":[{"batb":[[0,2.02,14],[1,2,10],[2,1.22,454.55]],"ltp":2.0,"tv":403.28,"id":67083366}]}]}
{"op":"mcm","clk":"11902223936","pt":1724336771411,"mc":[{"id":"1.232089285","rc":[{"batb":[[0,2.02,10]],"ltp":2.0,"tv":403.28,"id":67083366}]}]}
{"op":"mcm","clk":"11902224038","pt":1724336772902,"mc":[{"id":"1.232089285","rc":[{"batb":[[0,2,10],[1,1.22,454.55],[2,1.21,82.81]],"ltp":2.0,"tv":403.28,"id":67083366}]}]}
{"op":"mcm","clk":"11902225294","pt":1724336791814,"mc":[{"id":"1.232089285","rc":[{"batb":[[0,2.02,14],[1,2,10],[2,1.22,454.55]],"ltp":2.0,"tv":403.28,"id":67083366}]}]}
{"op":"mcm","clk":"11902225438","pt":1724336794024,"mc":[{"id":"1.232089285","rc":[{"batb":[[0,2.02,10]],"ltp":2.0,"tv":403.28,"id":67083366}]}]}
{"op":"mcm","clk":"11902225531","pt":1724336795213,"mc":[{"id":"1.232089285","rc":[{"batb":[[0,2,10],[1,1.22,454.55],[2,1.21,82.81]],"ltp":2.0,"tv":403.28,"id":67083366}]}]}
{"op":"mcm","clk":"11902225853","pt":1724336799931,"mc":[{"id":"1.232089285","rc":[{"batb":[[0,2.02,14],[1,2,10],[2,1.22,454.55]],"ltp":2.0,"tv":403.28,"id":67083366}]}]}
{"op":"mcm","clk":"11902226012","pt":1724336802235,"mc":[{"id":"1.232089285","rc":[{"batb":[[0,2.02,10]],"ltp":2.0,"tv":403.28,"id":67083366}]}]}
{"op":"mcm","clk":"11902226057","pt":1724336803261,"mc":[{"id":"1.232089285","rc":[{"batb":[[0,2,10],[1,1.22,454.55],[2,1.21,82.81]],"ltp":2.0,"tv":403.28,"id":67083366}]}]}
{"op":"mcm","clk":"11902226682","pt":1724336812746,"mc":[{"id":"1.232089285","rc":[{"batb":[[0,2.02,14],[1,2,10],[2,1.22,454.55]],"ltp":2.0,"tv":403.28,"id":67083366}]}]}
{"op":"mcm","clk":"11902226849","pt":1724336815676,"mc":[{"id":"1.232089285","rc":[{"batb":[[0,2.02,10]],"ltp":2.0,"tv":403.28,"id":67083366}]}]}
{"op":"mcm","clk":"11902226904","pt":1724336816648,"mc":[{"id":"1.232089285","rc":[{"batb":[[0,2,10],[1,1.22,454.55],[2,1.21,82.81]],"ltp":2.0,"tv":403.28,"id":67083366}]}]}
{"op":"mcm","clk":"11902227475","pt":1724336824671,"mc":[{"id":"1.232089285","rc":[{"batb":[[0,2.02,14],[1,2,10],[2,1.22,454.55]],"ltp":2.0,"tv":403.28,"id":67083366}]}]}
{"op":"mcm","clk":"11902227636","pt":1724336826888,"mc":[{"id":"1.232089285","rc":[{"batb":[[0,2.02,10]],"ltp":2.0,"tv":403.28,"id":67083366}]}]}
{"op":"mcm","clk":"11902227706","pt":1724336827970,"mc":[{"id":"1.232089285","rc":[{"batb":[[0,2,10],[1,1.22,454.55],[2,1.21,82.81]],"ltp":2.0,"tv":403.28,"id":67083366}]}]}
{"op":"mcm","clk":"11902227796","pt":1724336829155,"mc":[{"id":"1.232089285","rc":[{"batb":[[0,2.02,4],[1,2,10],[2,1.22,454.55]],"ltp":2.0,"tv":403.28,"id":67083366}]}]}
{"op":"mcm","clk":"11902227893","pt":1724336830584,"mc":[{"id":"1.232089285","rc":[{"batb":[[0,2.04,10],[1,2.02,4],[2,2,10]],"ltp":2.0,"tv":403.28,"id":67083366}]}]}
{"op":"mcm","clk":"11902227960","pt":1724336831463,"mc":[{"id":"1.232089285","rc":[{"batb":[[1,2,10],[2,1.22,454.55]],"ltp":2.0,"tv":403.28,"id":67083366}]}]}
{"op":"mcm","clk":"11902228137","pt":1724336834080,"mc":[{"id":"1.232089285","rc":[{"batb":[[0,2.02,4]],"ltp":2.0,"tv":403.28,"id":67083366}]}]}
{"op":"mcm","clk":"11902228319","pt":1724336836596,"mc":[{"id":"1.232089285","rc":[{"batb":[[0,2.02,10]],"ltp":2.0,"tv":403.28,"id":67083366}]}]}
{"op":"mcm","clk":"11902228555","pt":1724336840151,"mc":[{"id":"1.232089285","rc":[{"batb":[[0,2.02,4]],"ltp":2.0,"tv":403.28,"id":67083366}]}]}
{"op":"mcm","clk":"11902228716","pt":1724336842573,"mc":[{"id":"1.232089285","rc":[{"batb":[[0,2.02,10]],"ltp":2.0,"tv":403.28,"id":67083366}]}]}
{"op":"mcm","clk":"11902228923","pt":1724336845199,"mc":[{"id":"1.232089285","rc":[{"batb":[[0,2.04,4],[1,2.02,10],[2,2,10]],"ltp":2.0,"tv":403.28,"id":67083366}]}]}
{"op":"mcm","clk":"11902228969","pt":1724336845871,"mc":[{"id":"1.232089285","rc":[{"batb":[[1,2,10],[2,1.22,454.55]],"ltp":2.0,"tv":403.28,"id":67083366}]}]}
{"op":"mcm","clk":"11902229086","pt":1724336847461,"mc":[{"id":"1.232089285","rc":[{"batb":[[0,2,10],[1,1.22,454.55],[2,1.21,82.81]],"ltp":2.0,"tv":403.28,"id":67083366}]}]}
{"op":"mcm","clk":"11902229590","pt":1724336853702,"mc":[{"id":"1.232089285","rc":[{"batb":[[0,2.02,14],[1,2,10],[2,1.22,454.55]],"ltp":2.0,"tv":403.28,"id":67083366}]}]}
{"op":"mcm","clk":"11902229766","pt":1724336855914,"mc":[{"id":"1.232089285","rc":[{"batb":[[0,2.02,10]],"ltp":2.0,"tv":403.28,"id":67083366}]}]}
{"op":"mcm","clk":"11902229850","pt":1724336857098,"mc":[{"id":"1.232089285","rc":[{"batb":[[0,2,10],[1,1.22,454.55],[2,1.21,82.81]],"ltp":2.0,"tv":403.28,"id":67083366}]}]}
{"op":"mcm","clk":"11902230152","pt":1724336861211,"mc":[{"id":"1.232089285","rc":[{"batb":[[0,2.02,14],[1,2,10],[2,1.22,454.55]],"ltp":2.0,"tv":403.28,"id":67083366}]}]}
{"op":"mcm","clk":"11902230316","pt":1724336863423,"mc":[{"id":"1.232089285","rc":[{"batb":[[0,2.02,10]],"ltp":2.0,"tv":403.28,"id":67083366}]}]}
{"op":"mcm","clk":"11902230381","pt":1724336864401,"mc":[{"id":"1.232089285","rc":[{"batb":[[0,2,10],[1,1.22,454.55],[2,1.21,82.81]],"ltp":2.0,"tv":403.28,"id":67083366}]}]}
{"op":"mcm","clk":"11902230797","pt":1724336870005,"mc":[{"id":"1.232089285","rc":[{"batb":[[0,2.02,14],[1,2,10],[2,1.22,454.55]],"ltp":2.0,"tv":403.28,"id":67083366}]}]}
{"op":"mcm","clk":"11902230976","pt":1724336872332,"mc":[{"id":"1.232089285","rc":[{"batb":[[0,2.02,10]],"ltp":2.0,"tv":403.28,"id":67083366}]}]}
{"op":"mcm","clk":"11902231037","pt":1724336873283,"mc":[{"id":"1.232089285","rc":[{"batb":[[0,2,10],[1,1.22,454.55],[2,1.21,82.81]],"ltp":2.0,"tv":403.28,"id":67083366}]}]}
{"op":"mcm","clk":"11902231339","pt":1724336877500,"mc":[{"id":"1.232089285","rc":[{"batb":[[0,2.02,14],[1,2,10],[2,1.22,454.55]],"ltp":2.0,"tv":403.28,"id":67083366}]}]}
{"op":"mcm","clk":"11902231537","pt":1724336880021,"mc":[{"id":"1.232089285","rc":[{"batb":[[0,2.02,10]],"ltp":2.0,"tv":403.28,"id":67083366}]}]}
{"op":"mcm","clk":"11902231607","pt":1724336880900,"mc":[{"id":"1.232089285","rc":[{"batb":[[0,2,10],[1,1.22,454.55],[2,1.21,82.81]],"ltp":2.0,"tv":403.28,"id":67083366}]}]}
{"op":"mcm","clk":"11902232064","pt":1724336885945,"mc":[{"id":"1.232089285","rc":[{"batb":[[0,2.02,14],[1,2,10],[2,1.22,454.55]],"ltp":2.0,"tv":403.28,"id":67083366}]}]}
{"op":"mcm","clk":"11902232288","pt":1724336888219,"mc":[{"id":"1.232089285","rc":[{"batb":[[0,2.02,10]],"ltp":2.0,"tv":403.28,"id":67083366}]}]}
{"op":"mcm","clk":"11902232373","pt":1724336889506,"mc":[{"id":"1.232089285","rc":[{"batb":[[0,2,10],[1,1.22,454.55],[2,1.21,82.81]],"ltp":2.0,"tv":403.28,"id":67083366}]}]}
{"op":"mcm","clk":"11902233447","pt":1724336904347,"mc":[{"id":"1.232089285","rc":[{"batb":[[0,2.02,14],[1,2,10],[2,1.22,454.55]],"ltp":2.0,"tv":403.28,"id":67083366},{"batb":[[1,1.38,139.57],[2,1.36,279.52]],"ltp":1.77,"tv":720.97,"id":72922097}]}]}
{"op":"mcm","clk":"11902233520","pt":1724336905536,"mc":[{"id":"1.232089285","rc":[{"batl":[[0,3.75,7.6]],"ltp":2.0,"tv":403.28,"id":67083366}]}]}
{"op":"mcm","clk":"11902233599","pt":1724336906568,"mc":[{"id":"1.232089285","rc":[{"batb":[[0,2.02,10]],"ltp":2.0,"tv":403.28,"id":67083366}]}]}
{"op":"mcm","clk":"11902233675","pt":1724336907547,"mc":[{"id":"1.232089285","rc":[{"batb":[[0,2,10],[1,1.22,454.55],[2,1.21,82.81]],"ltp":2.0,"tv":403.28,"id":67083366}]}]}
{"op":"mcm","clk":"11902235607","pt":1724336937458,"mc":[{"id":"1.232089285","rc":[{"trd":[[1.5,2]],"batb":[[0,1.38,139.57],[1,1.36,279.52],[2,1.35,20]],"batl":[[0,1.75,16.89]],"ltp":1.5,"tv":722.97,"id":72922097}],"tv":1126.26}]}
{"op":"mcm","clk":"11902236044","pt":1724336943764,"mc":[{"id":"1.232089285","rc":[{"trd":[[2.32,16.55],[3,0.07]],"batb":[[0,2.02,10],[1,2,10],[2,1.22,454.55]],"batl":[[0,2.32,8.21]],"ltp":2.32,"tv":415.99,"id":67083366},{"trd":[[1.5,2.13],[1.75,21.95]],"batl":[[0,1.82,41.84],[1,2.02,51.26],[2,2.5,1.93]],"ltp":1.75,"tv":739.86,"id":72922097}],"tv":1155.86}]}
{"op":"mcm","clk":"11902236266","pt":1724336947221,"mc":[{"id":"1.232089285","rc":[{"batb":[[0,2,10],[1,1.22,454.55],[2,1.21,82.81]],"ltp":2.32,"tv":415.99,"id":67083366}]}]}
{"op":"mcm","clk":"11902237410","pt":1724336964313,"mc":[{"id":"1.232089285","rc":[{"trd":[[2.24,1.67]],"batb":[[0,2.02,10],[1,2,10],[2,1.22,454.55]],"batl":[[0,2.24,6.54]],"ltp":2.24,"tv":417.66,"id":67083366}],"tv":1157.53}]}
{"op":"mcm","clk":"11902237610","pt":1724336967500,"mc":[{"id":"1.232089285","rc":[{"batb":[[0,2,10],[1,1.22,454.55],[2,1.21,82.81]],"ltp":2.24,"tv":417.66,"id":67083366}]}]}
{"op":"mcm","clk":"11902239029","pt":1724336989147,"mc":[{"id":"1.232089285","rc":[{"trd":[[2.2,6.54]],"ltp":2.2,"tv":424.2,"id":67083366},{"trd":[[1.82,7.91]],"batl":[[0,1.82,33.93]],"ltp":1.82,"tv":747.77,"id":72922097}],"tv":1171.98}]}
{"op":"mcm","clk":"11902240858","pt":1724337027366,"mc":[{"id":"1.232089285","rc":[{"trd":[[1.42,1.86]],"batb":[[0,1.36,279.62],[1,1.35,20],[2,1.32,4.07]],"ltp":1.42,"tv":749.63,"id":72922097}],"tv":1173.84}]}
{"op":"mcm","clk":"11902243479","pt":1724337077445,"mc":[{"id":"1.232089285","rc":[{"batb":[[0,2.02,14],[1,2,10],[2,1.22,454.55]],"batl":[[0,3.75,4.91]],"ltp":2.2,"tv":424.2,"id":67083366}]}]}
{"op":"mcm","clk":"11902243658","pt":1724337080631,"mc":[{"id":"1.232089285","rc":[{"batb":[[0,2,10],[1,1.22,454.55],[2,1.21,82.81]],"ltp":2.2,"tv":424.2,"id":67083366}]}]}
{"op":"mcm","clk":"11902245120","pt":1724337107750,"mc":[{"id":"1.232089285","rc":[{"batb":[[0,2.02,14],[1,2,10],[2,1.22,454.55]],"ltp":2.2,"tv":424.2,"id":67083366}]}]}
{"op":"mcm","clk":"11902245293","pt":1724337110390,"mc":[{"id":"1.232089285","rc":[{"batb":[[0,2.02,10]],"ltp":2.2,"tv":424.2,"id":67083366}]}]}
{"op":"mcm","clk":"11902245349","pt":1724337111177,"mc":[{"id":"1.232089285","rc":[{"batb":[[0,2,10],[1,1.22,454.55],[2,1.21,82.81]],"ltp":2.2,"tv":424.2,"id":67083366}]}]}
{"op":"mcm","clk":"11902245943","pt":1724337120666,"mc":[{"id":"1.232089285","rc":[{"batb":[[0,2.02,14],[1,2,10],[2,1.22,454.55]],"ltp":2.2,"tv":424.2,"id":67083366}]}]}
{"op":"mcm","clk":"11902246063","pt":1724337123088,"mc":[{"id":"1.232089285","rc":[{"batb":[[0,2.02,10]],"ltp":2.2,"tv":424.2,"id":67083366}]}]}
{"op":"mcm","clk":"11902246124","pt":1724337123963,"mc":[{"id":"1.232089285","rc":[{"batb":[[0,2,10],[1,1.22,454.55],[2,1.21,82.81]],"ltp":2.2,"tv":424.2,"id":67083366}]}]}
{"op":"mcm","clk":"11902246397","pt":1724337128696,"mc":[{"id":"1.232089285","rc":[{"batb":[[0,2.02,14],[1,2,10],[2,1.22,454.55]],"ltp":2.2,"tv":424.2,"id":67083366}]}]}
{"op":"mcm","clk":"11902246533","pt":1724337131267,"mc":[{"id":"1.232089285","rc":[{"batb":[[0,2.02,10]],"ltp":2.2,"tv":424.2,"id":67083366}]}]}
{"op":"mcm","clk":"11902246581","pt":1724337132199,"mc":[{"id":"1.232089285","rc":[{"batb":[[0,2,10],[1,1.22,454.55],[2,1.21,82.81]],"ltp":2.2,"tv":424.2,"id":67083366}]}]}
{"op":"mcm","clk":"11902246604","pt":1724337132870,"mc":[{"id":"1.232089285","rc":[{"trd":[[1.82,8.41]],"batb":[[2,1.29,6.61]],"batl":[[0,1.82,33.68],[2,2.5,1]],"ltp":1.82,"tv":750.14,"id":72922097}],"tv":1174.34}]}
{"op":"mcm","clk":"11902247073","pt":1724337141211,"mc":[{"id":"1.232089285","rc":[{"batb":[[0,2.02,14],[1,2,10],[2,1.22,454.55]],"ltp":2.2,"tv":424.2,"id":67083366}]}]}
{"op":"mcm","clk":"11902247247","pt":1724337144510,"mc":[{"id":"1.232089285","rc":[{"batb":[[0,2,10],[1,1.22,454.55],[2,1.21,82.81]],"ltp":2.2,"tv":424.2,"id":67083366}]}]}
{"op":"mcm","clk":"11902247515","pt":1724337150312,"mc":[{"id":"1.232089285","rc":[{"batb":[[0,2.02,14],[1,2,10],[2,1.22,454.55]],"ltp":2.2,"tv":424.2,"id":67083366}]}]}
{"op":"mcm","clk":"11902247649","pt":1724337152833,"mc":[{"id":"1.232089285","rc":[{"batb":[[0,2.02,10]],"ltp":2.2,"tv":424.2,"id":67083366}]}]}
{"op":"mcm","clk":"11902247710","pt":1724337153809,"mc":[{"id":"1.232089285","rc":[{"batb":[[0,2,10],[1,1.22,454.55],[2,1.21,82.81]],"ltp":2.2,"tv":424.2,"id":67083366}]}]}
{"op":"mcm","clk":"11902247960","pt":1724337158224,"mc":[{"id":"1.232089285","rc":[{"batb":[[0,2.02,14],[1,2,10],[2,1.22,454.55]],"ltp":2.2,"tv":424.2,"id":67083366}]}]}
{"op":"mcm","clk":"11902248125","pt":1724337161523,"mc":[{"id":"1.232089285","rc":[{"batb":[[0,2,10],[1,1.22,454.55],[2,1.21,82.81]],"ltp":2.2,"tv":424.2,"id":67083366}]}]}
{"op":"mcm","clk":"11902248213","pt":1724337163630,"mc":[{"id":"1.232089285","rc":[{"batb":[[0,2.04,10],[1,2.02,4],[2,2,10]],"ltp":2.2,"tv":424.2,"id":67083366}]}]}
{"op":"mcm","clk":"11902248313","pt":1724337165837,"mc":[{"id":"1.232089285","rc":[{"batb":[[1,2,10],[2,1.22,454.55]],"ltp":2.2,"tv":424.2,"id":67083366}]}]}
{"op":"mcm","clk":"11902248356","pt":1724337167028,"mc":[{"id":"1.232089285","rc":[{"batb":[[0,2,10],[1,1.22,454.55],[2,1.21,82.81]],"ltp":2.2,"tv":424.2,"id":67083366}]}]}
{"op":"mcm","clk":"11902248851","pt":1724337177357,"mc":[{"id":"1.232089285","rc":[{"batb":[[0,2.02,14],[1,2,10],[2,1.22,454.55]],"ltp":2.2,"tv":424.2,"id":67083366}]}]}
{"op":"mcm","clk":"11902248972","pt":1724337179732,"mc":[{"id":"1.232089285","rc":[{"batb":[[0,2.02,10]],"ltp":2.2,"tv":424.2,"id":67083366}]}]}
{"op":"mcm","clk":"11902249033","pt":1724337180829,"mc":[{"id":"1.232089285","rc":[{"batb":[[0,2,10],[1,1.22,454.55],[2,1.21,82.81]],"ltp":2.2,"tv":424.2,"id":67083366}]}]}
{"op":"mcm","clk":"11902249301","pt":1724337185931,"mc":[{"id":"1.232089285","rc":[{"batb":[[0,2.02,14],[1,2,10],[2,1.22,454.55]],"ltp":2.2,"tv":424.2,"id":67083366}]}]}
{"op":"mcm","clk":"11902249458","pt":1724337188367,"mc":[{"id":"1.232089285","rc":[{"batb":[[0,2.02,10]],"ltp":2.2,"tv":424.2,"id":67083366}]}]}
{"op":"mcm","clk":"11902249508","pt":1724337189357,"mc":[{"id":"1.232089285","rc":[{"batb":[[0,2,10],[1,1.22,454.55],[2,1.21,82.81]],"ltp":2.2,"tv":424.2,"id":67083366}]}]}
{"op":"mcm","clk":"11902250977","pt":1724337215599,"mc":[{"id":"1.232089285","rc":[{"batb":[[0,2.02,14],[1,2,10],[2,1.22,454.55]],"ltp":2.2,"tv":424.2,"id":67083366}]}]}
{"op":"mcm","clk":"11902251100","pt":1724337218277,"mc":[{"id":"1.232089285","rc":[{"batb":[[0,2.02,10]],"ltp":2.2,"tv":424.2,"id":67083366}]}]}
{"op":"mcm","clk":"11902251147","pt":1724337219103,"mc":[{"id":"1.232089285","rc":[{"batb":[[0,2,10],[1,1.22,454.55],[2,1.21,82.81]],"ltp":2.2,"tv":424.2,"id":67083366}]}]}
{"op":"mcm","clk":"11902252133","pt":1724337238619,"mc":[{"id":"1.232089285","rc":[{"batl":[[0,3.75,12.79]],"ltp":2.2,"tv":424.2,"id":67083366}]}]}
{"op":"mcm","clk":"11902252136","pt":1724337238722,"mc":[{"id":"1.232089285","rc":[{"batb":[[0,2.02,14],[1,2,10],[2,1.22,454.55]],"ltp":2.2,"tv":424.2,"id":67083366}]}]}
{"op":"mcm","clk":"11902252191","pt":1724337239805,"mc":[{"id":"1.232089285","rc":[{"batb":[[0,1.38,1.02],[1,1.36,279.52],[2,1.35,20]],"ltp":1.82,"tv":750.14,"id":72922097}]}]}
{"op":"mcm","clk":"11902252277","pt":1724337241206,"mc":[{"id":"1.232089285","rc":[{"batb":[[0,2.02,10]],"ltp":2.2,"tv":424.2,"id":67083366}]}]}
{"op":"mcm","clk":"11902252375","pt":1724337242198,"mc":[{"id":"1.232089285","rc":[{"batb":[[0,2,10],[1,1.22,454.55],[2,1.21,82.81]],"ltp":2.2,"tv":424.2,"id":67083366}]}]}
{"op":"mcm","clk":"11902253061","pt":1724337258149,"mc":[{"id":"1.232089285","rc":[{"batb":[[0,2.02,14],[1,2,10],[2,1.22,454.55]],"ltp":2.2,"tv":424.2,"id":67083366}]}]}
{"op":"mcm","clk":"11902253242","pt":1724337261557,"mc":[{"id":"1.232089285","rc":[{"batb":[[0,2,10],[1,1.22,454.55],[2,1.21,82.81]],"ltp":2.2,"tv":424.2,"id":67083366}]}]}
{"op":"mcm","clk":"11902253302","pt":1724337262845,"mc":[{"id":"1.232089285","rc":[{"batb":[[0,2.02,4],[1,2,10],[2,1.22,454.55]],"ltp":2.2,"tv":424.2,"id":67083366}]}]}
{"op":"mcm","clk":"11902253420","pt":1724337265428,"mc":[{"id":"1.232089285","rc":[{"batb":[[0,2.02,10]],"ltp":2.2,"tv":424.2,"id":67083366}]}]}
{"op":"mcm","clk":"11902253616","pt":1724337269030,"mc":[{"id":"1.232089285","rc":[{"batb":[[0,2.02,4]],"ltp":2.2,"tv":424.2,"id":67083366}]}]}
{"op":"mcm","clk":"11902253754","pt":1724337271330,"mc":[{"id":"1.232089285","rc":[{"batb":[[0,2.02,10]],"ltp":2.2,"tv":424.2,"id":67083366}]}]}
{"op":"mcm","clk":"11902253889","pt":1724337273447,"mc":[{"id":"1.232089285","rc":[{"batb":[[0,2.04,4],[1,2.02,10],[2,2,10]],"ltp":2.2,"tv":424.2,"id":67083366}]}]}
{"op":"mcm","clk":"11902253978","pt":1724337274745,"mc":[{"id":"1.232089285","rc":[{"batb":[[1,2,10],[2,1.22,454.55]],"ltp":2.2,"tv":424.2,"id":67083366}]}]}
{"op":"mcm","clk":"11902254046","pt":1724337276039,"mc":[{"id":"1.232089285","rc":[{"batb":[[0,2,10],[1,1.22,454.55],[2,1.21,82.81]],"ltp":2.2,"tv":424.2,"id":67083366}]}]}
{"op":"mcm","clk":"11902254702","pt":1724337288868,"mc":[{"id":"1.232089285","rc":[{"batb":[[0,2.02,14],[1,2,10],[2,1.22,454.55]],"ltp":2.2,"tv":424.2,"id":67083366}]}]}
{"op":"mcm","clk":"11902254833","pt":1724337291350,"mc":[{"id":"1.232089285","rc":[{"batb":[[0,2.02,10]],"ltp":2.2,"tv":424.2,"id":67083366}]}]}
{"op":"mcm","clk":"11902254871","pt":1724337292493,"mc":[{"id":"1.232089285","rc":[{"batb":[[0,2,10],[1,1.22,454.55],[2,1.21,82.81]],"ltp":2.2,"tv":424.2,"id":67083366}]}]}
{"op":"mcm","clk":"11902255680","pt":1724337306271,"mc":[{"id":"1.232089285","rc":[{"batb":[[0,2.02,14],[1,2,10],[2,1.22,454.55]],"ltp":2.2,"tv":424.2,"id":67083366}]}]}
{"op":"mcm","clk":"11902255835","pt":1724337308963,"mc":[{"id":"1.232089285","rc":[{"batb":[[0,2.02,10]],"ltp":2.2,"tv":424.2,"id":67083366}]}]}
{"op":"mcm","clk":"11902255888","pt":1724337309895,"mc":[{"id":"1.232089285","rc":[{"batb":[[0,2,10],[1,1.22,454.55],[2,1.21,82.81]],"ltp":2.2,"tv":424.2,"id":67083366}]}]}
{"op":"mcm","clk":"11902256473","pt":1724337320746,"mc":[{"id":"1.232089285","rc":[{"batb":[[0,2.02,14],[1,2,10],[2,1.22,454.55]],"ltp":2.2,"tv":424.2,"id":67083366}]}]}
{"op":"mcm","clk":"11902256599","pt":1724337323171,"mc":[{"id":"1.232089285","rc":[{"batb":[[0,2.02,10]],"ltp":2.2,"tv":424.2,"id":67083366}]}]}
{"op":"mcm","clk":"11902256660","pt":1724337324266,"mc":[{"id":"1.232089285","rc":[{"batb":[[0,2,10],[1,1.22,454.55],[2,1.21,82.81]],"ltp":2.2,"tv":424.2,"id":67083366}]}]}
{"op":"mcm","clk":"11902256876","pt":1724337327986,"mc":[{"id":"1.232089285","rc":[{"batb":[[0,2.02,14],[1,2,10],[2,1.22,454.55]],"ltp":2.2,"tv":424.2,"id":67083366}]}]}
{"op":"mcm","clk":"11902257008","pt":1724337330157,"mc":[{"id":"1.232089285","rc":[{"batb":[[0,2.02,10]],"ltp":2.2,"tv":424.2,"id":67083366}]}]}
{"op":"mcm","clk":"11902257075","pt":1724337331190,"mc":[{"id":"1.232089285","rc":[{"batb":[[0,2,10],[1,1.22,454.55],[2,1.21,82.81]],"ltp":2.2,"tv":424.2,"id":67083366}]}]}
{"op":"mcm","clk":"11902257237","pt":1724337334249,"mc":[{"id":"1.232089285","rc":[{"batb":[[0,2.02,14],[1,2,10],[2,1.22,454.55]],"ltp":2.2,"tv":424.2,"id":67083366}]}]}
{"op":"mcm","clk":"11902257336","pt":1724337336569,"mc":[{"id":"1.232089285","rc":[{"batb":[[0,2.02,10]],"ltp":2.2,"tv":424.2,"id":67083366}]}]}
{"op":"mcm","clk":"11902257390","pt":1724337337494,"mc":[{"id":"1.232089285","rc":[{"batb":[[0,2,10],[1,1.22,454.55],[2,1.21,82.81]],"ltp":2.2,"tv":424.2,"id":67083366}]}]}
{"op":"mcm","clk":"11902257491","pt":1724337339350,"mc":[{"id":"1.232089285","rc":[{"batb":[[0,2.02,4],[1,2,10],[2,1.22,454.55]],"ltp":2.2,"tv":424.2,"id":67083366}]}]}
{"op":"mcm","clk":"11902257604","pt":1724337341578,"mc":[{"id":"1.232089285","rc":[{"batb":[[0,2,10],[1,1.22,454.55],[2,1.21,82.81]],"ltp":2.2,"tv":424.2,"id":67083366}]}]}
{"op":"mcm","clk":"11902257612","pt":1724337341680,"mc":[{"id":"1.232089285","rc":[{"batb":[[0,2.02,10],[1,2,10],[2,1.22,454.55]],"ltp":2.2,"tv":424.2,"id":67083366}]}]}
{"op":"mcm","clk":"11902257739","pt":1724337343906,"mc":[{"id":"1.232089285","rc":[{"batb":[[0,2.04,4],[1,2.02,10],[2,2,10]],"ltp":2.2,"tv":424.2,"id":67083366}]}]}
{"op":"mcm","clk":"11902257799","pt":1724337345010,"mc":[{"id":"1.232089285","rc":[{"batb":[[1,2,10],[2,1.22,454.55]],"ltp":2.2,"tv":424.2,"id":67083366}]}]}
{"op":"mcm","clk":"11902257869","pt":1724337346074,"mc":[{"id":"1.232089285","rc":[{"batb":[[0,2,10],[1,1.22,454.55],[2,1.21,82.81]],"ltp":2.2,"tv":424.2,"id":67083366}]}]}
{"op":"mcm","clk":"11902258713","pt":1724337360515,"mc":[{"id":"1.232089285","rc":[{"batb":[[0,2.02,14],[1,2,10],[2,1.22,454.55]],"ltp":2.2,"tv":424.2,"id":67083366}]}]}
{"op":"mcm","clk":"11902258728","pt":1724337360705,"mc":[{"id":"1.232089285","rc":[{"batb":[[0,2.2,5.13],[1,2.02,19.64],[2,2,10]],"batl":[[0,3.65,3.59],[1,3.75,12.79]],"ltp":2.2,"tv":424.2,"id":67083366}]}]}
{"op":"mcm","clk":"11902258868","pt":1724337362831,"mc":[{"id":"1.232089285","rc":[{"batb":[[1,2.02,15.64]],"ltp":2.2,"tv":424.2,"id":67083366}]}]}
{"op":"mcm","clk":"11902258937","pt":1724337363706,"mc":[{"id":"1.232089285","rc":[{"batb":[[1,2.02,5.64]],"ltp":2.2,"tv":424.2,"id":67083366}]}]}
{"op":"mcm","clk":"11902259301","pt":1724337368718,"mc":[{"id":"1.232089285","rc":[{"batb":[[0,2.22,14],[1,2.2,5.13],[2,2.02,5.64]],"ltp":2.2,"tv":424.2,"id":67083366}]}]}
{"op":"mcm","clk":"11902259494","pt":1724337371102,"mc":[{"id":"1.232089285","rc":[{"batb":[[0,2.22,10]],"ltp":2.2,"tv":424.2,"id":67083366}]}]}
{"op":"mcm","clk":"11902259571","pt":1724337372293,"mc":[{"id":"1.232089285","rc":[{"batb":[[0,2.2,5.13],[1,2.02,5.64],[2,2,10]],"ltp":2.2,"tv":424.2,"id":67083366}]}]}
{"op":"mcm","clk":"11902260234","pt":1724337383517,"mc":[{"id":"1.232089285","rc":[{"batb":[[0,2.22,14],[1,2.2,5.13],[2,2.02,5.64]],"ltp":2.2,"tv":424.2,"id":67083366},{"batl":[[0,1.81,138.64],[1,1.82,33.68],[2,2.02,51.26]],"ltp":1.82,"tv":750.14,"id":72922097}]}]}
{"op":"mcm","clk":"11902260377","pt":1724337385538,"mc":[{"id":"1.232089285","rc":[{"batb":[[0,2.22,10]],"ltp":2.2,"tv":424.2,"id":67083366}]}]}
{"op":"mcm","clk":"11902260428","pt":1724337386426,"mc":[{"id":"1.232089285","rc":[{"batb":[[0,2.2,5.13],[1,2.02,5.64],[2,2,10]],"ltp":2.2,"tv":424.2,"id":67083366}]}]}
{"op":"mcm","clk":"11902260533","pt":1724337388130,"mc":[{"id":"1.232089285","rc":[{"batb":[[0,2.22,4],[1,2.2,5.13],[2,2.02,5.64]],"ltp":2.2,"tv":424.2,"id":67083366}]}]}
{"op":"mcm","clk":"11902260664","pt":1724337390408,"mc":[{"id":"1.232089285","rc":[{"batb":[[0,2.24,10]],"ltp":2.2,"tv":424.2,"id":67083366}]}]}
{"op":"mcm","clk":"11902260846","pt":1724337393210,"mc":[{"id":"1.232089285","rc":[{"batb":[[0,2.22,4]],"ltp":2.2,"tv":424.2,"id":67083366}]}]}
{"op":"mcm","clk":"11902261006","pt":1724337395936,"mc":[{"id":"1.232089285","rc":[{"batb":[[0,2.22,10]],"ltp":2.2,"tv":424.2,"id":67083366}]}]}
{"op":"mcm","clk":"11902261189","pt":1724337399242,"mc":[{"id":"1.232089285","rc":[{"batb":[[0,2.24,4]],"ltp":2.2,"tv":424.2,"id":67083366}]}]}
{"op":"mcm","clk":"11902261319","pt":1724337401417,"mc":[{"id":"1.232089285","rc":[{"batb":[[0,2.22,10]],"ltp":2.2,"tv":424.2,"id":67083366}]}]}
{"op":"mcm","clk":"11902261555","pt":1724337405029,"mc":[{"id":"1.232089285","rc":[{"batb":[[0,2.22,4]],"ltp":2.2,"tv":424.2,"id":67083366}]}]}
{"op":"mcm","clk":"11902261729","pt":1724337407355,"mc":[{"id":"1.232089285","rc":[{"batb":[[0,2.22,10]],"ltp":2.2,"tv":424.2,"id":67083366}]}]}
{"op":"mcm","clk":"11902261957","pt":1724337411122,"mc":[{"id":"1.232089285","rc":[{"batb":[[0,2.22,4]],"ltp":2.2,"tv":424.2,"id":67083366}]}]}
{"op":"mcm","clk":"11902262076","pt":1724337413751,"mc":[{"id":"1.232089285","rc":[{"batb":[[0,2.22,10]],"ltp":2.2,"tv":424.2,"id":67083366}]}]}
{"op":"mcm","clk":"11902262289","pt":1724337417252,"mc":[{"id":"1.232089285","rc":[{"batb":[[0,2.22,4]],"ltp":2.2,"tv":424.2,"id":67083366}]}]}
{"op":"mcm","clk":"11902262437","pt":1724337419526,"mc":[{"id":"1.232089285","rc":[{"batb":[[0,2.22,10]],"ltp":2.2,"tv":424.2,"id":67083366}]}]}
{"op":"mcm","clk":"11902262565","pt":1724337421655,"mc":[{"id":"1.232089285","rc":[{"batb":[[0,2.24,4],[1,2.22,10],[2,2.2,5.13]],"ltp":2.2,"tv":424.2,"id":67083366}]}]}
{"op":"mcm","clk":"11902262638","pt":1724337422849,"mc":[{"id":"1.232089285","rc":[{"batb":[[1,2.2,5.13],[2,2.02,5.64]],"ltp":2.2,"tv":424.2,"id":67083366}]}]}
{"op":"mcm","clk":"11902262700","pt":1724337424141,"mc":[{"id":"1.232089285","rc":[{"batb":[[0,2.2,5.13],[1,2.02,5.64],[2,2,10]],"ltp":2.2,"tv":424.2,"id":67083366}]}]}
{"op":"mcm","clk":"11902263485","pt":1724337437632,"mc":[{"id":"1.232089285","rc":[{"batb":[[0,2.22,14],[1,2.2,5.13],[2,2.02,5.64]],"ltp":2.2,"tv":424.2,"id":67083366},{"batl":[[0,1.8,29.29],[1,1.81,138.64],[2,1.82,33.68]],"ltp":1.82,"tv":750.14,"id":72922097}]}]}
{"op":"mcm","clk":"11902263601","pt":1724337439953,"mc":[{"id":"1.232089285","rc":[{"batb":[[0,2.22,10]],"ltp":2.2,"tv":424.2,"id":67083366}]}]}
{"op":"mcm","clk":"11902263661","pt":1724337440985,"mc":[{"id":"1.232089285","rc":[{"batb":[[0,2.2,5.13],[1,2.02,5.64],[2,2,10]],"ltp":2.2,"tv":424.2,"id":67083366}]}]}
{"op":"mcm","clk":"11902264296","pt":1724337445994,"mc":[{"id":"1.232089285","rc":[{"batb":[[0,2.22,14],[1,2.2,5.13],[2,2.02,5.64]],"ltp":2.2,"tv":424.2,"id":67083366}]}]}
{"op":"mcm","clk":"11902264707","pt":1724337448895,"mc":[{"id":"1.232089285","rc":[{"batb":[[0,2.22,10]],"ltp":2.2,"tv":424.2,"id":67083366}]}]}
{"op":"mcm","clk":"11902264832","pt":1724337449822,"mc":[{"id":"1.232089285","rc":[{"batb":[[0,2.2,5.13],[1,2.02,5.64],[2,2,10]],"ltp":2.2,"tv":424.2,"id":67083366}]}]}
{"op":"mcm","clk":"11902266406","pt":1724337461620,"mc":[{"id":"1.232089285","rc":[{"batb":[[0,2.22,14],[1,2.2,5.13],[2,2.02,5.64]],"ltp":2.2,"tv":424.2,"id":67083366}]}]}
{"op":"mcm","clk":"11902266627","pt":1724337463910,"mc":[{"id":"1.232089285","rc":[{"batb":[[0,2.22,10]],"ltp":2.2,"tv":424.2,"id":67083366}]}]}
{"op":"mcm","clk":"11902266713","pt":1724337464795,"mc":[{"id":"1.232089285","rc":[{"batb":[[0,2.2,5.13],[1,2.02,5.64],[2,2,10]],"ltp":2.2,"tv":424.2,"id":67083366}]}]}
{"op":"mcm","clk":"11902266850","pt":1724337466303,"mc":[{"id":"1.232089285","rc":[{"batb":[[0,2.22,4],[1,2.2,5.13],[2,2.02,5.64]],"ltp":2.2,"tv":424.2,"id":67083366}]}]}
{"op":"mcm","clk":"11902267047","pt":1724337468737,"mc":[{"id":"1.232089285","rc":[{"batb":[[0,2.2,5.13],[1,2.02,5.64],[2,2,10]],"ltp":2.2,"tv":424.2,"id":67083366}]}]}
{"op":"mcm","clk":"11902267220","pt":1724337470512,"mc":[{"id":"1.232089285","rc":[{"batb":[[0,2.22,10],[1,2.2,5.13],[2,2.02,5.64]],"ltp":2.2,"tv":424.2,"id":67083366}]}]}
{"op":"mcm","clk":"11902267282","pt":1724337471233,"mc":[{"id":"1.232089285","rc":[{"batb":[[0,2.24,4],[1,2.22,10],[2,2.2,5.13]],"ltp":2.2,"tv":424.2,"id":67083366}]}]}
{"op":"mcm","clk":"11902267482","pt":1724337474209,"mc":[{"id":"1.232089285","rc":[{"batb":[[0,2.2,5.13],[1,2.02,5.64],[2,2,10]],"ltp":2.2,"tv":424.2,"id":67083366}]}]}
{"op":"mcm","clk":"11902267672","pt":1724337477219,"mc":[{"id":"1.232089285","rc":[{"batb":[[0,2.22,14],[1,2.2,5.13],[2,2.02,5.64]],"ltp":2.2,"tv":424.2,"id":67083366}]}]}
{"op":"mcm","clk":"11902267896","pt":1724337480408,"mc":[{"id":"1.232089285","rc":[{"batb":[[0,2.2,5.13],[1,2.02,5.64],[2,2,10]],"ltp":2.2,"tv":424.2,"id":67083366}]}]}
{"op":"mcm","clk":"11902268549","pt":1724337491839,"mc":[{"id":"1.232089285","rc":[{"batb":[[0,2.22,14],[1,2.2,5.13],[2,2.02,5.64]],"ltp":2.2,"tv":424.2,"id":67083366}]}]}
{"op":"mcm","clk":"11902268639","pt":1724337493552,"mc":[{"id":"1.232089285","rc":[{"batl":[[0,1.8,2.9]],"ltp":1.82,"tv":750.14,"id":72922097}]}]}
{"op":"mcm","clk":"11902268684","pt":1724337494232,"mc":[{"id":"1.232089285","rc":[{"batb":[[0,2.22,10]],"ltp":2.2,"tv":424.2,"id":67083366}]}]}
{"op":"mcm","clk":"11902268746","pt":1724337495322,"mc":[{"id":"1.232089285","rc":[{"batb":[[0,2.2,5.13],[1,2.02,5.64],[2,2,10]],"ltp":2.2,"tv":424.2,"id":67083366}]}]}
{"op":"mcm","clk":"11902269029","pt":1724337500932,"mc":[{"id":"1.232089285","rc":[{"batb":[[0,2.22,14],[1,2.2,5.13],[2,2.02,5.64]],"ltp":2.2,"tv":424.2,"id":67083366},{"batl":[[0,1.81,138.78],[1,1.82,33.68],[2,2.02,51.26]],"ltp":1.82,"tv":750.14,"id":72922097}]}]}
{"op":"mcm","clk":"11902269138","pt":1724337503326,"mc":[{"id":"1.232089285","rc":[{"batb":[[0,2.22,10]],"ltp":2.2,"tv":424.2,"id":67083366}]}]}
{"op":"mcm","clk":"11902269180","pt":1724337504464,"mc":[{"id":"1.232089285","rc":[{"batb":[[0,2.2,5.13],[1,2.02,5.64],[2,2,10]],"ltp":2.2,"tv":424.2,"id":67083366}]}]}
{"op":"mcm","clk":"11902269376","pt":1724337508571,"mc":[{"id":"1.232089285","rc":[{"batb":[[0,2.22,14],[1,2.2,5.13],[2,2.02,5.64]],"ltp":2.2,"tv":424.2,"id":67083366},{"batl":[[0,1.82,33.82],[1,2.02,51.26],[2,2.5,1]],"ltp":1.82,"tv":750.14,"id":72922097}]}]}
{"op":"mcm","clk":"11902269493","pt":1724337510758,"mc":[{"id":"1.232089285","rc":[{"batb":[[0,2.22,10]],"ltp":2.2,"tv":424.2,"id":67083366}]}]}
{"op":"mcm","clk":"11902269519","pt":1724337511743,"mc":[{"id":"1.232089285","rc":[{"batb":[[0,2.2,5.13],[1,2.02,5.64],[2,2,10]],"ltp":2.2,"tv":424.2,"id":67083366}]}]}
{"op":"mcm","clk":"11902269896","pt":1724337519183,"mc":[{"id":"1.232089285","rc":[{"batb":[[0,2.22,14],[1,2.2,5.13],[2,2.02,5.64]],"ltp":2.2,"tv":424.2,"id":67083366}]}]}
{"op":"mcm","clk":"11902269973","pt":1724337520577,"mc":[{"id":"1.232089285","rc":[{"batl":[[0,3.75,12.79],[1,3.75,0]],"ltp":2.2,"tv":424.2,"id":67083366},{"batb":[[0,1.4,17.68],[1,1.36,279.62]],"ltp":1.82,"tv":750.14,"id":72922097}]}]}
{"op":"mcm","clk":"11902270011","pt":1724337521148,"mc":[{"id":"1.232089285","rc":[{"batl":[[0,3.5,3.59]],"ltp":2.2,"tv":424.2,"id":67083366}]}]}
{"op":"mcm","clk":"11902270031","pt":1724337521664,"mc":[{"id":"1.232089285","rc":[{"batb":[[0,2.22,10]],"ltp":2.2,"tv":424.2,"id":67083366}]}]}
{"op":"mcm","clk":"11902270108","pt":1724337523157,"mc":[{"id":"1.232089285","rc":[{"batb":[[0,2.2,5.13],[1,2.02,5.64],[2,2,10]],"ltp":2.2,"tv":424.2,"id":67083366}]}]}
{"op":"mcm","clk":"11902270206","pt":1724337525402,"mc":[{"id":"1.232089285","rc":[{"batb":[[0,2.24,10],[1,2.22,4],[2,2.2,5.13]],"ltp":2.2,"tv":424.2,"id":67083366}]}]}
{"op":"mcm","clk":"11902270283","pt":1724337527378,"mc":[{"id":"1.232089285","rc":[{"batb":[[1,2.2,5.13],[2,2.02,5.64]],"ltp":2.2,"tv":424.2,"id":67083366}]}]}
{"op":"mcm","clk":"11902270355","pt":1724337528982,"mc":[{"id":"1.232089285","rc":[{"batb":[[0,2.2,5.13],[1,2.02,5.64],[2,2,10]],"ltp":2.2,"tv":424.2,"id":67083366}]}]}
{"op":"mcm","clk":"11902270488","pt":1724337532580,"mc":[{"id":"1.232089285","rc":[{"batb":[[0,2.22,14],[1,2.2,5.13],[2,2.02,5.64]],"ltp":2.2,"tv":424.2,"id":67083366}]}]}
{"op":"mcm","clk":"11902270622","pt":1724337535197,"mc":[{"id":"1.232089285","rc":[{"batb":[[0,2.22,10]],"ltp":2.2,"tv":424.2,"id":67083366}]}]}
{"op":"mcm","clk":"11902270649","pt":1724337535972,"mc":[{"id":"1.232089285","rc":[{"batb":[[0,2.2,5.13],[1,2.02,5.64],[2,2,10]],"ltp":2.2,"tv":424.2,"id":67083366}]}]}
{"op":"mcm","clk":"11902270825","pt":1724337539473,"mc":[{"id":"1.232089285","rc":[{"batb":[[0,2.22,14],[1,2.2,5.13],[2,2.02,5.64]],"ltp":2.2,"tv":424.2,"id":67083366}]}]}
{"op":"mcm","clk":"11902270982","pt":1724337542005,"mc":[{"id":"1.232089285","rc":[{"batb":[[0,2.22,10]],"ltp":2.2,"tv":424.2,"id":67083366}]}]}
{"op":"mcm","clk":"11902271032","pt":1724337542882,"mc":[{"id":"1.232089285","rc":[{"batb":[[0,2.2,5.13],[1,2.02,5.64],[2,2,10]],"ltp":2.2,"tv":424.2,"id":67083366}]}]}
{"op":"mcm","clk":"11902271140","pt":1724337545608,"mc":[{"id":"1.232089285","rc":[{"batb":[[0,2.22,14],[1,2.2,5.13],[2,2.02,5.64]],"ltp":2.2,"tv":424.2,"id":67083366}]}]}
{"op":"mcm","clk":"11902271263","pt":1724337547979,"mc":[{"id":"1.232089285","rc":[{"batb":[[0,2.22,10]],"ltp":2.2,"tv":424.2,"id":67083366}]}]}
{"op":"mcm","clk":"11902271336","pt":1724337549065,"mc":[{"id":"1.232089285","rc":[{"batb":[[0,2.2,5.13],[1,2.02,5.64],[2,2,10]],"ltp":2.2,"tv":424.2,"id":67083366}]}]}
{"op":"mcm","clk":"11902271675","pt":1724337553919,"mc":[{"id":"1.232089285","rc":[{"batb":[[0,2.22,14],[1,2.2,5.13],[2,2.02,5.64]],"ltp":2.2,"tv":424.2,"id":67083366}]}]}
{"op":"mcm","clk":"11902271847","pt":1724337556407,"mc":[{"id":"1.232089285","rc":[{"batb":[[0,2.22,10]],"ltp":2.2,"tv":424.2,"id":67083366}]}]}
{"op":"mcm","clk":"11902271882","pt":1724337557025,"mc":[{"id":"1.232089285","rc":[{"batb":[[0,2.2,5.13],[1,2.02,5.64],[2,2,10]],"ltp":2.2,"tv":424.2,"id":67083366}]}]}
{"op":"mcm","clk":"11902272150","pt":1724337562386,"mc":[{"id":"1.232089285","rc":[{"batb":[[0,2.22,14],[1,2.2,5.13],[2,2.02,5.64]],"ltp":2.2,"tv":424.2,"id":67083366}]}]}
{"op":"mcm","clk":"11902272246","pt":1724337564804,"mc":[{"id":"1.232089285","rc":[{"batb":[[0,2.22,10]],"ltp":2.2,"tv":424.2,"id":67083366}]}]}
{"op":"mcm","clk":"11902272303","pt":1724337565729,"mc":[{"id":"1.232089285","rc":[{"batb":[[0,2.2,5.13],[1,2.02,5.64],[2,2,10]],"ltp":2.2,"tv":424.2,"id":67083366}]}]}
{"op":"mcm","clk":"11902272516","pt":1724337569600,"mc":[{"id":"1.232089285","rc":[{"batb":[[0,2.22,14],[1,2.2,5.13],[2,2.02,5.64]],"ltp":2.2,"tv":424.2,"id":67083366}]}]}
{"op":"mcm","clk":"11902272651","pt":1724337572021,"mc":[{"id":"1.232089285","rc":[{"batb":[[0,2.22,10]],"ltp":2.2,"tv":424.2,"id":67083366}]}]}
{"op":"mcm","clk":"11902272728","pt":1724337573108,"mc":[{"id":"1.232089285","rc":[{"batb":[[0,2.2,5.13],[1,2.02,5.64],[2,2,10]],"ltp":2.2,"tv":424.2,"id":67083366}]}]}
{"op":"mcm","clk":"11902272807","pt":1724337574602,"mc":[{"id":"1.232089285","rc":[{"batb":[[0,2.22,4],[1,2.2,5.13],[2,2.02,5.64]],"ltp":2.2,"tv":424.2,"id":67083366}]}]}
{"op":"mcm","clk":"11902272967","pt":1724337577030,"mc":[{"id":"1.232089285","rc":[{"batb":[[0,2.22,10]],"ltp":2.2,"tv":424.2,"id":67083366}]}]}
{"op":"mcm","clk":"11902273187","pt":1724337580548,"mc":[{"id":"1.232089285","rc":[{"batb":[[0,2.22,4]],"ltp":2.2,"tv":424.2,"id":67083366}]}]}
{"op":"mcm","clk":"11902273301","pt":1724337582925,"mc":[{"id":"1.232089285","rc":[{"batb":[[0,2.22,10]],"ltp":2.2,"tv":424.2,"id":67083366}]}]}
{"op":"mcm","clk":"11902273516","pt":1724337586536,"mc":[{"id":"1.232089285","rc":[{"batb":[[0,2.22,4]],"ltp":2.2,"tv":424.2,"id":67083366}]}]}
{"op":"mcm","clk":"11902273664","pt":1724337589169,"mc":[{"id":"1.232089285","rc":[{"batb":[[0,2.22,10]],"ltp":2.2,"tv":424.2,"id":67083366}]}]}
{"op":"mcm","clk":"11902273862","pt":1724337592453,"mc":[{"id":"1.232089285","rc":[{"batb":[[0,2.24,4]],"ltp":2.2,"tv":424.2,"id":67083366}]}]}
{"op":"mcm","clk":"11902273948","pt":1724337594235,"mc":[{"id":"1.232089285","rc":[{"batb":[[0,2.2,5.13],[1,2.02,5.64],[2,2,10]],"ltp":2.2,"tv":424.2,"id":67083366}]}]}
{"op":"mcm","clk":"11902274425","pt":1724337602088,"mc":[{"id":"1.232089285","rc":[{"batb":[[0,2.22,14],[1,2.2,5.13],[2,2.02,5.64]],"ltp":2.2,"tv":424.2,"id":67083366}]}]}
{"op":"mcm","clk":"11902274592","pt":1724337604578,"mc":[{"id":"1.232089285","rc":[{"batb":[[0,2.22,10]],"ltp":2.2,"tv":424.2,"id":67083366}]}]}
{"op":"mcm","clk":"11902274633","pt":1724337605455,"mc":[{"id":"1.232089285","rc":[{"batb":[[0,2.2,5.13],[1,2.02,5.64],[2,2,10]],"ltp":2.2,"tv":424.2,"id":67083366}]}]}
{"op":"mcm","clk":"11902275008","pt":1724337611855,"mc":[{"id":"1.232089285","rc":[{"batb":[[0,2.22,14],[1,2.2,5.13],[2,2.02,5.64]],"ltp":2.2,"tv":424.2,"id":67083366}]}]}
{"op":"mcm","clk":"11902275131","pt":1724337614277,"mc":[{"id":"1.232089285","rc":[{"batb":[[0,2.22,10]],"ltp":2.2,"tv":424.2,"id":67083366}]}]}
{"op":"mcm","clk":"11902275179","pt":1724337615306,"mc":[{"id":"1.232089285","rc":[{"batb":[[0,2.2,5.13],[1,2.02,5.64],[2,2,10]],"ltp":2.2,"tv":424.2,"id":67083366}]}]}
{"op":"mcm","clk":"11902275402","pt":1724337619807,"mc":[{"id":"1.232089285","rc":[{"batb":[[0,2.22,14],[1,2.2,5.13],[2,2.02,5.64]],"ltp":2.2,"tv":424.2,"id":67083366}]}]}
{"op":"mcm","clk":"11902275524","pt":1724337621588,"mc":[{"id":"1.232089285","rc":[{"batb":[[0,2.22,10]],"ltp":2.2,"tv":424.2,"id":67083366}]}]}
{"op":"mcm","clk":"11902275576","pt":1724337622619,"mc":[{"id":"1.232089285","rc":[{"batb":[[0,2.2,5.13],[1,2.02,5.64],[2,2,10]],"ltp":2.2,"tv":424.2,"id":67083366}]}]}
{"op":"mcm","clk":"11902275649","pt":1724337624280,"mc":[{"id":"1.232089285","rc":[{"batb":[[0,2.22,4],[1,2.2,5.13],[2,2.02,5.64]],"ltp":2.2,"tv":424.2,"id":67083366}]}]}
{"op":"mcm","clk":"11902275761","pt":1724337626394,"mc":[{"id":"1.232089285","rc":[{"batb":[[0,2.24,10]],"ltp":2.2,"tv":424.2,"id":67083366}]}]}
{"op":"mcm","clk":"11902275926","pt":1724337629590,"mc":[{"id":"1.232089285","rc":[{"batb":[[0,2.22,4]],"ltp":2.2,"tv":424.2,"id":67083366}]}]}
{"op":"mcm","clk":"11902276065","pt":1724337632037,"mc":[{"id":"1.232089285","rc":[{"batb":[[0,2.22,10]],"ltp":2.2,"tv":424.2,"id":67083366}]}]}
{"op":"mcm","clk":"11902276288","pt":1724337635561,"mc":[{"id":"1.232089285","rc":[{"batb":[[0,2.22,4]],"ltp":2.2,"tv":424.2,"id":67083366}]}]}
{"op":"mcm","clk":"11902276436","pt":1724337638225,"mc":[{"id":"1.232089285","rc":[{"batb":[[0,2.22,10]],"ltp":2.2,"tv":424.2,"id":67083366}]}]}
{"op":"mcm","clk":"11902276638","pt":1724337641636,"mc":[{"id":"1.232089285","rc":[{"batb":[[0,2.22,4]],"ltp":2.2,"tv":424.2,"id":67083366}]}]}
{"op":"mcm","clk":"11902276769","pt":1724337644221,"mc":[{"id":"1.232089285","rc":[{"batb":[[0,2.22,10]],"ltp":2.2,"tv":424.2,"id":67083366}]}]}
{"op":"mcm","clk":"11902276949","pt":1724337647754,"mc":[{"id":"1.232089285","rc":[{"batb":[[0,2.22,4]],"ltp":2.2,"tv":424.2,"id":67083366}]}]}
{"op":"mcm","clk":"11902277059","pt":1724337650132,"mc":[{"id":"1.232089285","rc":[{"batb":[[0,2.24,10]],"ltp":2.2,"tv":424.2,"id":67083366}]}]}
{"op":"mcm","clk":"11902277286","pt":1724337654061,"mc":[{"id":"1.232089285","rc":[{"batb":[[0,2.22,4]],"ltp":2.2,"tv":424.2,"id":67083366}]}]}
{"op":"mcm","clk":"11902277388","pt":1724337656441,"mc":[{"id":"1.232089285","rc":[{"batb":[[0,2.22,10]],"ltp":2.2,"tv":424.2,"id":67083366}]}]}
{"op":"mcm","clk":"11902277617","pt":1724337660066,"mc":[{"id":"1.232089285","rc":[{"batb":[[0,2.22,4]],"ltp":2.2,"tv":424.2,"id":67083366}]}]}
{"op":"mcm","clk":"11902277751","pt":1724337662554,"mc":[{"id":"1.232089285","rc":[{"batb":[[0,2.2,5.13],[1,2.02,5.64],[2,2,10]],"ltp":2.2,"tv":424.2,"id":67083366}]}]}
{"op":"mcm","clk":"11902277768","pt":1724337662762,"mc":[{"id":"1.232089285","rc":[{"batb":[[0,2.22,10],[1,2.2,5.13],[2,2.02,5.64]],"ltp":2.2,"tv":424.2,"id":67083366}]}]}
{"op":"mcm","clk":"11902277924","pt":1724337666175,"mc":[{"id":"1.232089285","rc":[{"batb":[[0,2.22,4]],"ltp":2.2,"tv":424.2,"id":67083366}]}]}
{"op":"mcm","clk":"11902278034","pt":1724337668542,"mc":[{"id":"1.232089285","rc":[{"batb":[[0,2.2,5.13],[1,2.02,5.64],[2,2,10]],"ltp":2.2,"tv":424.2,"id":67083366}]}]}
{"op":"mcm","clk":"11902278051","pt":1724337668749,"mc":[{"id":"1.232089285","rc":[{"batb":[[0,2.22,10],[1,2.2,5.13],[2,2.02,5.64]],"ltp":2.2,"tv":424.2,"id":67083366}]}]}
{"op":"mcm","clk":"11902278254","pt":1724337672068,"mc":[{"id":"1.232089285","rc":[{"batb":[[0,2.22,4]],"ltp":2.2,"tv":424.2,"id":67083366}]}]}
{"op":"mcm","clk":"11902278359","pt":1724337674587,"mc":[{"id":"1.232089285","rc":[{"batb":[[0,2.2,5.13],[1,2.02,5.64],[2,2,10]],"ltp":2.2,"tv":424.2,"id":67083366}]}]}
{"op":"mcm","clk":"11902278365","pt":1724337674692,"mc":[{"id":"1.232089285","rc":[{"batb":[[0,2.22,10],[1,2.2,5.13],[2,2.02,5.64]],"ltp":2.2,"tv":424.2,"id":67083366}]}]}
{"op":"mcm","clk":"11902278418","pt":1724337675879,"mc":[{"id":"1.232089285","rc":[{"batb":[[0,1.41,10.92],[1,1.4,16.76],[2,1.36,279.62]],"batl":[[0,2.02,51.4],[1,2.5,1],[2,2.5,0]],"ltp":1.82,"tv":750.14,"id":72922097}]}]}
{"op":"mcm","clk":"11902278474","pt":1724337677072,"mc":[{"id":"1.232089285","rc":[{"batb":[[0,2.24,4],[1,2.22,10],[2,2.2,5.13]],"batl":[[0,3.45,3.59]],"ltp":2.2,"tv":424.2,"id":67083366}]}]}
{"op":"mcm","clk":"11902278526","pt":1724337678102,"mc":[{"id":"1.232089285","rc":[{"batb":[[1,2.2,5.13],[2,2.02,5.64]],"ltp":2.2,"tv":424.2,"id":67083366}]}]}
{"op":"mcm","clk":"11902278573","pt":1724337679398,"mc":[{"id":"1.232089285","rc":[{"batb":[[0,2.2,5.13],[1,2.02,5.64],[2,2,10]],"ltp":2.2,"tv":424.2,"id":67083366},{"batb":[[0,1.4,17.68],[1,1.36,279.62],[2,1.35,20]],"ltp":1.82,"tv":750.14,"id":72922097}]}]}
{"op":"mcm","clk":"11902278809","pt":1724337684203,"mc":[{"id":"1.232089285","rc":[{"batb":[[0,2.22,14],[1,2.2,5.13],[2,2.02,5.64]],"ltp":2.2,"tv":424.2,"id":67083366},{"batb":[[0,1.41,10.92],[1,1.4,16.76],[2,1.36,279.62]],"ltp":1.82,"tv":750.14,"id":72922097}]}]}
{"op":"mcm","clk":"11902278947","pt":1724337686991,"mc":[{"id":"1.232089285","rc":[{"batb":[[0,2.22,10]],"ltp":2.2,"tv":424.2,"id":67083366}]}]}
{"op":"mcm","clk":"11902278987","pt":1724337687772,"mc":[{"id":"1.232089285","rc":[{"batb":[[0,2.2,5.13],[1,2.02,5.64],[2,2,10]],"ltp":2.2,"tv":424.2,"id":67083366},{"batb":[[0,1.4,17.68],[1,1.36,279.62],[2,1.35,20]],"ltp":1.82,"tv":750.14,"id":72922097}]}]}
{"op":"mcm","clk":"11902279465","pt":1724337695522,"mc":[{"id":"1.232089285","rc":[{"batb":[[0,2.22,14],[1,2.2,5.13],[2,2.02,5.64]],"ltp":2.2,"tv":424.2,"id":67083366},{"batl":[[0,1.8,33.47],[1,2.02,51.4],[2,2.5,1]],"ltp":1.82,"tv":750.14,"id":72922097}]}]}
{"op":"mcm","clk":"11902279608","pt":1724337697694,"mc":[{"id":"1.232089285","rc":[{"batb":[[0,2.22,10]],"ltp":2.2,"tv":424.2,"id":67083366}]}]}
{"op":"mcm","clk":"11902279666","pt":1724337698826,"mc":[{"id":"1.232089285","rc":[{"batb":[[0,2.2,5.13],[1,2.02,5.64],[2,2,10]],"ltp":2.2,"tv":424.2,"id":67083366}]}]}
{"op":"mcm","clk":"11902279805","pt":1724337702226,"mc":[{"id":"1.232089285","rc":[{"batb":[[0,2.22,14],[1,2.2,5.13],[2,2.02,5.64]],"ltp":2.2,"tv":424.2,"id":67083366}]}]}
{"op":"mcm","clk":"11902279955","pt":1724337704711,"mc":[{"id":"1.232089285","rc":[{"batb":[[0,2.22,10]],"ltp":2.2,"tv":424.2,"id":67083366}]}]}
{"op":"mcm","clk":"11902280000","pt":1724337705640,"mc":[{"id":"1.232089285","rc":[{"batb":[[0,2.2,5.13],[1,2.02,5.64],[2,2,10]],"ltp":2.2,"tv":424.2,"id":67083366}]}]}
{"op":"mcm","clk":"11902280185","pt":1724337710119,"mc":[{"id":"1.232089285","rc":[{"batb":[[0,2.22,14],[1,2.2,5.13],[2,2.02,5.64]],"ltp":2.2,"tv":424.2,"id":67083366}]}]}
{"op":"mcm","clk":"11902280282","pt":1724337712541,"mc":[{"id":"1.232089285","rc":[{"batb":[[0,2.22,10]],"ltp":2.2,"tv":424.2,"id":67083366}]}]}
{"op":"mcm","clk":"11902280316","pt":1724337713424,"mc":[{"id":"1.232089285","rc":[{"batb":[[0,2.2,5.13],[1,2.02,5.64],[2,2,10]],"ltp":2.2,"tv":424.2,"id":67083366}]}]}
{"op":"mcm","clk":"11902280414","pt":1724337715802,"mc":[{"id":"1.232089285","rc":[{"batb":[[0,2.22,14],[1,2.2,5.13],[2,2.02,5.64]],"ltp":2.2,"tv":424.2,"id":67083366}]}]}
{"op":"mcm","clk":"11902280492","pt":1724337718128,"mc":[{"id":"1.232089285","rc":[{"batb":[[0,2.22,10]],"ltp":2.2,"tv":424.2,"id":67083366}]}]}
{"op":"mcm","clk":"11902280531","pt":1724337719107,"mc":[{"id":"1.232089285","rc":[{"batb":[[0,2.2,5.13],[1,2.02,5.64],[2,2,10]],"ltp":2.2,"tv":424.2,"id":67083366}]}]}
{"op":"mcm","clk":"11902280704","pt":1724337722429,"mc":[{"id":"1.232089285","rc":[{"batb":[[0,2.22,14],[1,2.2,5.13],[2,2.02,5.64]],"ltp":2.2,"tv":424.2,"id":67083366}]}]}
{"op":"mcm","clk":"11902280830","pt":1724337725125,"mc":[{"id":"1.232089285","rc":[{"batb":[[0,2.22,10]],"ltp":2.2,"tv":424.2,"id":67083366}]}]}
{"op":"mcm","clk":"11902280881","pt":1724337726161,"mc":[{"id":"1.232089285","rc":[{"batb":[[0,2.2,5.13],[1,2.02,5.64],[2,2,10]],"ltp":2.2,"tv":424.2,"id":67083366}]}]}
{"op":"mcm","clk":"11902281067","pt":1724337730056,"mc":[{"id":"1.232089285","rc":[{"batb":[[0,2.22,14],[1,2.2,5.13],[2,2.02,5.64]],"ltp":2.2,"tv":424.2,"id":67083366}]}]}
{"op":"mcm","clk":"11902281201","pt":1724337732538,"mc":[{"id":"1.232089285","rc":[{"batb":[[0,2.22,10]],"ltp":2.2,"tv":424.2,"id":67083366}]}]}
{"op":"mcm","clk":"11902281252","pt":1724337733568,"mc":[{"id":"1.232089285","rc":[{"batb":[[0,2.2,5.13],[1,2.02,5.64],[2,2,10]],"ltp":2.2,"tv":424.2,"id":67083366}]}]}
{"op":"mcm","clk":"11902281338","pt":1724337735232,"mc":[{"id":"1.232089285","rc":[{"batb":[[0,2.22,4],[1,2.2,5.13],[2,2.02,5.64]],"ltp":2.2,"tv":424.2,"id":67083366}]}]}
{"op":"mcm","clk":"11902281447","pt":1724337737459,"mc":[{"id":"1.232089285","rc":[{"batb":[[0,2.24,10]],"ltp":2.2,"tv":424.2,"id":67083366}]}]}
{"op":"mcm","clk":"11902281570","pt":1724337740255,"mc":[{"id":"1.232089285","rc":[{"batb":[[0,2.2,5.13],[1,2.02,5.64],[2,2,10]],"ltp":2.2,"tv":424.2,"id":67083366}]}]}
{"op":"mcm","clk":"11902281609","pt":1724337741342,"mc":[{"id":"1.232089285","rc":[{"batb":[[0,2.22,4],[1,2.2,5.13],[2,2.02,5.64]],"ltp":2.2,"tv":424.2,"id":67083366}]}]}
{"op":"mcm","clk":"11902281778","pt":1724337744484,"mc":[{"id":"1.232089285","rc":[{"batb":[[0,2.22,10]],"ltp":2.2,"tv":424.2,"id":67083366}]}]}
{"op":"mcm","clk":"11902282080","pt":1724337748147,"mc":[{"id":"1.232089285","rc":[{"batb":[[0,2.22,4]],"ltp":2.2,"tv":424.2,"id":67083366}]}]}
{"op":"mcm","clk":"11902282248","pt":1724337750882,"mc":[{"id":"1.232089285","rc":[{"batb":[[0,2.22,10]],"ltp":2.2,"tv":424.2,"id":67083366}]}]}
{"op":"mcm","clk":"11902282392","pt":1724337754250,"mc":[{"id":"1.232089285","rc":[{"batb":[[0,2.22,4]],"ltp":2.2,"tv":424.2,"id":67083366}]}]}
{"op":"mcm","clk":"11902282480","pt":1724337756564,"mc":[{"id":"1.232089285","rc":[{"batb":[[0,2.22,10]],"ltp":2.2,"tv":424.2,"id":67083366}]}]}
{"op":"mcm","clk":"11902282663","pt":1724337759871,"mc":[{"id":"1.232089285","rc":[{"batb":[[0,2.22,4]],"ltp":2.2,"tv":424.2,"id":67083366}]}]}
{"op":"mcm","clk":"11902282789","pt":1724337762198,"mc":[{"id":"1.232089285","rc":[{"batb":[[0,2.2,5.13],[1,2.02,5.64],[2,2,10]],"ltp":2.2,"tv":424.2,"id":67083366}]}]}
{"op":"mcm","clk":"11902282818","pt":1724337762875,"mc":[{"id":"1.232089285","rc":[{"batb":[[0,2.24,10],[1,2.2,5.13],[2,2.02,5.64]],"ltp":2.2,"tv":424.2,"id":67083366}]}]}
{"op":"mcm","clk":"11902282996","pt":1724337764992,"mc":[{"id":"1.232089285","rc":[{"batb":[[0,2.26,4],[1,2.24,10],[2,2.2,5.13]],"ltp":2.2,"tv":424.2,"id":67083366}]}]}
{"op":"mcm","clk":"11902283123","pt":1724337767576,"mc":[{"id":"1.232089285","rc":[{"batb":[[0,2.2,5.13],[1,2.02,5.64],[2,2,10]],"ltp":2.2,"tv":424.2,"id":67083366}]}]}
{"op":"mcm","clk":"11902283342","pt":1724337772017,"mc":[{"id":"1.232089285","rc":[{"batb":[[0,2.22,14],[1,2.2,5.13],[2,2.02,5.64]],"ltp":2.2,"tv":424.2,"id":67083366}]}]}
{"op":"mcm","clk":"11902283456","pt":1724337774594,"mc":[{"id":"1.232089285","rc":[{"batb":[[0,2.22,10]],"ltp":2.2,"tv":424.2,"id":67083366}]}]}
{"op":"mcm","clk":"11902283510","pt":1724337775586,"mc":[{"id":"1.232089285","rc":[{"batb":[[0,2.2,5.13],[1,2.02,5.64],[2,2,10]],"ltp":2.2,"tv":424.2,"id":67083366}]}]}
{"op":"mcm","clk":"11902284057","pt":1724337786804,"mc":[{"id":"1.232089285","rc":[{"batb":[[0,2.22,14],[1,2.2,5.13],[2,2.02,5.64]],"ltp":2.2,"tv":424.2,"id":67083366}]}]}
{"op":"mcm","clk":"11902284187","pt":1724337789602,"mc":[{"id":"1.232089285","rc":[{"batb":[[0,2.22,10]],"ltp":2.2,"tv":424.2,"id":67083366}]}]}
{"op":"mcm","clk":"11902284223","pt":1724337790430,"mc":[{"id":"1.232089285","rc":[{"batb":[[0,2.2,5.13],[1,2.02,5.64],[2,2,10]],"ltp":2.2,"tv":424.2,"id":67083366}]}]}
{"op":"mcm","clk":"11902285013","pt":1724337808557,"mc":[{"id":"1.232089285","rc":[{"batb":[[0,2.22,14],[1,2.2,5.13],[2,2.02,5.64]],"ltp":2.2,"tv":424.2,"id":67083366}]}]}
{"op":"mcm","clk":"11902285161","pt":1724337811047,"mc":[{"id":"1.232089285","rc":[{"batb":[[0,2.22,10]],"ltp":2.2,"tv":424.2,"id":67083366}]}]}
{"op":"mcm","clk":"11902285217","pt":1724337812346,"mc":[{"id":"1.232089285","rc":[{"batb":[[0,2.2,5.13],[1,2.02,5.64],[2,2,10]],"ltp":2.2,"tv":424.2,"id":67083366}]}]}
{"op":"mcm","clk":"11902285353","pt":1724337814836,"mc":[{"id":"1.232089285","rc":[{"batb":[[0,2.22,14],[1,2.2,5.13],[2,2.02,5.64]],"ltp":2.2,"tv":424.2,"id":67083366}]}]}
{"op":"mcm","clk":"11902285478","pt":1724337817325,"mc":[{"id":"1.232089285","rc":[{"batb":[[0,2.22,10]],"ltp":2.2,"tv":424.2,"id":67083366}]}]}
{"op":"mcm","clk":"11902285517","pt":1724337818466,"mc":[{"id":"1.232089285","rc":[{"batb":[[0,2.2,5.13],[1,2.02,5.64],[2,2,10]],"ltp":2.2,"tv":424.2,"id":67083366}]}]}
{"op":"mcm","clk":"11902285580","pt":1724337819862,"mc":[{"id":"1.232089285","rc":[{"batb":[[0,2.22,4],[1,2.2,5.13],[2,2.02,5.64]],"ltp":2.2,"tv":424.2,"id":67083366}]}]}
{"op":"mcm","clk":"11902285638","pt":1724337821054,"mc":[{"id":"1.232089285","rc":[{"batb":[[0,2.24,10],[1,2.22,4],[2,2.2,5.13]],"ltp":2.2,"tv":424.2,"id":67083366}]}]}
{"op":"mcm","clk":"11902285680","pt":1724337822350,"mc":[{"id":"1.232089285","rc":[{"batb":[[1,2.2,5.13],[2,2.02,5.64]],"ltp":2.2,"tv":424.2,"id":67083366}]}]}
{"op":"mcm","clk":"11902285791","pt":1724337824583,"mc":[{"id":"1.232089285","rc":[{"batb":[[0,2.22,4]],"ltp":2.2,"tv":424.2,"id":67083366}]}]}
{"op":"mcm","clk":"11902285889","pt":1724337827170,"mc":[{"id":"1.232089285","rc":[{"batb":[[0,2.22,10]],"ltp":2.2,"tv":424.2,"id":67083366}]}]}
{"op":"mcm","clk":"11902286063","pt":1724337830555,"mc":[{"id":"1.232089285","rc":[{"batb":[[0,2.24,4]],"ltp":2.2,"tv":424.2,"id":67083366}]}]}
{"op":"mcm","clk":"11902286167","pt":1724337832251,"mc":[{"id":"1.232089285","rc":[{"batb":[[0,2.2,5.13],[1,2.02,5.64],[2,2,10]],"ltp":2.2,"tv":424.2,"id":67083366}]}]}
{"op":"mcm","clk":"11902286558","pt":1724337840568,"mc":[{"id":"1.232089285","rc":[{"batb":[[0,2.22,14],[1,2.2,5.13],[2,2.02,5.64]],"ltp":2.2,"tv":424.2,"id":67083366}]}]}
{"op":"mcm","clk":"11902286697","pt":1724337843073,"mc":[{"id":"1.232089285","rc":[{"batb":[[0,2.22,10]],"ltp":2.2,"tv":424.2,"id":67083366}]}]}
{"op":"mcm","clk":"11902286747","pt":1724337843987,"mc":[{"id":"1.232089285","rc":[{"batb":[[0,2.2,5.13],[1,2.02,5.64],[2,2,10]],"ltp":2.2,"tv":424.2,"id":67083366}]}]}
{"op":"mcm","clk":"11902287046","pt":1724337849171,"mc":[{"id":"1.232089285","rc":[{"batb":[[0,2.22,14],[1,2.2,5.13],[2,2.02,5.64]],"ltp":2.2,"tv":424.2,"id":67083366}]}]}
{"op":"mcm","clk":"11902287170","pt":1724337851487,"mc":[{"id":"1.232089285","rc":[{"batb":[[0,2.22,10]],"ltp":2.2,"tv":424.2,"id":67083366}]}]}
{"op":"mcm","clk":"11902287273","pt":1724337853400,"mc":[{"id":"1.232089285","rc":[{"batb":[[0,2.26,7.14]],"ltp":2.2,"tv":424.2,"id":67083366},{"batb":[[1,1.37,6.71],[2,1.36,279.52]],"ltp":1.82,"tv":750.14,"id":72922097}]}]}
{"op":"mcm","clk":"11902287608","pt":1724337859182,"mc":[{"id":"1.232089285","rc":[{"batb":[[0,2.28,14],[1,2.26,7.14],[2,2.2,5.13]],"ltp":2.2,"tv":424.2,"id":67083366}]}]}
{"op":"mcm","clk":"11902287727","pt":1724337861615,"mc":[{"id":"1.232089285","rc":[{"batb":[[0,2.28,10]],"ltp":2.2,"tv":424.2,"id":67083366}]}]}
{"op":"mcm","clk":"11902287780","pt":1724337862491,"mc":[{"id":"1.232089285","rc":[{"batb":[[0,2.26,7.14],[1,2.2,5.13],[2,2.02,5.64]],"ltp":2.2,"tv":424.2,"id":67083366}]}]}
{"op":"mcm","clk":"11902287938","pt":1724337865600,"mc":[{"id":"1.232089285","rc":[{"batb":[[0,2.28,14],[1,2.26,7.14],[2,2.2,5.13]],"ltp":2.2,"tv":424.2,"id":67083366}]}]}
{"op":"mcm","clk":"11902288076","pt":1724337867821,"mc":[{"id":"1.232089285","rc":[{"batb":[[0,2.28,10]],"ltp":2.2,"tv":424.2,"id":67083366}]}]}
{"op":"mcm","clk":"11902288120","pt":1724337868816,"mc":[{"id":"1.232089285","rc":[{"batb":[[0,2.26,7.14],[1,2.2,5.13],[2,2.02,5.64]],"ltp":2.2,"tv":424.2,"id":67083366}]}]}
{"op":"mcm","clk":"11902288186","pt":1724337869992,"mc":[{"id":"1.232089285","rc":[{"batb":[[0,2.3,4],[1,2.26,7.14],[2,2.2,5.13]],"ltp":2.2,"tv":424.2,"id":67083366}]}]}
{"op":"mcm","clk":"11902288277","pt":1724337871137,"mc":[{"id":"1.232089285","rc":[{"batb":[[0,2.32,10],[1,2.3,4],[2,2.26,7.14]],"ltp":2.2,"tv":424.2,"id":67083366}]}]}
{"op":"mcm","clk":"11902288411","pt":1724337873326,"mc":[{"id":"1.232089285","rc":[{"batb":[[1,2.26,7.14],[2,2.2,5.13]],"ltp":2.2,"tv":424.2,"id":67083366}]}]}
{"op":"mcm","clk":"11902288598","pt":1724337876020,"mc":[{"id":"1.232089285","rc":[{"batb":[[0,2.28,4]],"ltp":2.2,"tv":424.2,"id":67083366}]}]}
{"op":"mcm","clk":"11902288744","pt":1724337878317,"mc":[{"id":"1.232089285","rc":[{"batb":[[0,2.28,10]],"ltp":2.2,"tv":424.2,"id":67083366}]}]}
{"op":"mcm","clk":"11902288904","pt":1724337881621,"mc":[{"id":"1.232089285","rc":[{"batb":[[0,2.26,7.14],[1,2.2,5.13],[2,2.02,5.64]],"ltp":2.2,"tv":424.2,"id":67083366}]}]}
{"op":"mcm","clk":"11902288910","pt":1724337881725,"mc":[{"id":"1.232089285","rc":[{"batb":[[0,2.28,4],[1,2.26,7.14],[2,2.2,5.13]],"ltp":2.2,"tv":424.2,"id":67083366}]}]}
{"op":"mcm","clk":"11902289117","pt":1724337885612,"mc":[{"id":"1.232089285","rc":[{"batb":[[0,2.26,7.14],[1,2.2,5.13],[2,2.02,5.64]],"ltp":2.2,"tv":424.2,"id":67083366}]}]}
{"op":"mcm","clk":"11902289127","pt":1724337885717,"mc":[{"id":"1.232089285","rc":[{"batb":[[0,2.3,10],[1,2.26,7.14],[2,2.2,5.13]],"ltp":2.2,"tv":424.2,"id":67083366}]}]}
{"op":"mcm","clk":"11902289330","pt":1724337889454,"mc":[{"id":"1.232089285","rc":[{"batb":[[0,2.28,4]],"ltp":2.2,"tv":424.2,"id":67083366}]}]}
{"op":"mcm","clk":"11902289446","pt":1724337891954,"mc":[{"id":"1.232089285","rc":[{"batb":[[0,2.3,10]],"ltp":2.2,"tv":424.2,"id":67083366}]}]}
{"op":"mcm","clk":"11902289602","pt":1724337895473,"mc":[{"id":"1.232089285","rc":[{"batb":[[0,2.32,4]],"ltp":2.2,"tv":424.2,"id":67083366}]}]}
{"op":"mcm","clk":"11902289757","pt":1724337897971,"mc":[{"id":"1.232089285","rc":[{"batb":[[0,2.28,10]],"ltp":2.2,"tv":424.2,"id":67083366}]}]}
{"op":"mcm","clk":"11902289971","pt":1724337901473,"mc":[{"id":"1.232089285","rc":[{"batb":[[0,2.28,4]],"ltp":2.2,"tv":424.2,"id":67083366}]}]}
{"op":"mcm","clk":"11902290149","pt":1724337904084,"mc":[{"id":"1.232089285","rc":[{"batb":[[0,2.28,10]],"ltp":2.2,"tv":424.2,"id":67083366}]}]}
{"op":"mcm","clk":"11902290341","pt":1724337907566,"mc":[{"id":"1.232089285","rc":[{"batb":[[0,2.28,4]],"ltp":2.2,"tv":424.2,"id":67083366}]}]}
{"op":"mcm","clk":"11902290486","pt":1724337909859,"mc":[{"id":"1.232089285","rc":[{"batb":[[0,2.28,10]],"ltp":2.2,"tv":424.2,"id":67083366}]}]}
{"op":"mcm","clk":"11902290687","pt":1724337913269,"mc":[{"id":"1.232089285","rc":[{"batb":[[0,2.3,4]],"ltp":2.2,"tv":424.2,"id":67083366}]}]}
{"op":"mcm","clk":"11902290799","pt":1724337915285,"mc":[{"id":"1.232089285","rc":[{"batb":[[0,2.26,7.14],[1,2.2,5.13],[2,2.02,5.64]],"ltp":2.2,"tv":424.2,"id":67083366}]}]}
{"op":"mcm","clk":"11902291811","pt":1724337930903,"mc":[{"id":"1.232089285","rc":[{"batb":[[0,2.28,14],[1,2.26,7.14],[2,2.2,5.13]],"ltp":2.2,"tv":424.2,"id":67083366}]}]}
{"op":"mcm","clk":"11902292000","pt":1724337933792,"mc":[{"id":"1.232089285","rc":[{"batb":[[0,2.28,10]],"ltp":2.2,"tv":424.2,"id":67083366}]}]}
{"op":"mcm","clk":"11902292077","pt":1724337935000,"mc":[{"id":"1.232089285","rc":[{"batb":[[0,2.26,7.14],[1,2.2,5.13],[2,2.02,5.64]],"ltp":2.2,"tv":424.2,"id":67083366}]}]}
{"op":"mcm","clk":"11902292746","pt":1724337946520,"mc":[{"id":"1.232089285","rc":[{"batb":[[0,2.28,14],[1,2.26,7.14],[2,2.2,5.13]],"ltp":2.2,"tv":424.2,"id":67083366}]}]}
{"op":"mcm","clk":"11902292891","pt":1724337948926,"mc":[{"id":"1.232089285","rc":[{"batb":[[0,2.28,10]],"ltp":2.2,"tv":424.2,"id":67083366}]}]}
{"op":"mcm","clk":"11902292951","pt":1724337949808,"mc":[{"id":"1.232089285","rc":[{"batb":[[0,2.26,7.14],[1,2.2,5.13],[2,2.02,5.64]],"ltp":2.2,"tv":424.2,"id":67083366}]}]}
{"op":"mcm","clk":"11902293366","pt":1724337955923,"mc":[{"id":"1.232089285","rc":[{"batb":[[0,2.28,14],[1,2.26,7.14],[2,2.2,5.13]],"ltp":2.2,"tv":424.2,"id":67083366}]}]}
{"op":"mcm","clk":"11902293494","pt":1724337958105,"mc":[{"id":"1.232089285","rc":[{"batb":[[0,2.28,10]],"ltp":2.2,"tv":424.2,"id":67083366}]}]}
{"op":"mcm","clk":"11902293572","pt":1724337959348,"mc":[{"id":"1.232089285","rc":[{"batb":[[0,2.26,7.14],[1,2.2,5.13],[2,2.02,5.64]],"ltp":2.2,"tv":424.2,"id":67083366}]}]}
{"op":"mcm","clk":"11902293842","pt":1724337962716,"mc":[{"id":"1.232089285","rc":[{"batb":[[0,2.28,14],[1,2.26,7.14],[2,2.2,5.13]],"ltp":2.2,"tv":424.2,"id":67083366}]}]}
{"op":"mcm","clk":"11902294014","pt":1724337965251,"mc":[{"id":"1.232089285","rc":[{"batb":[[0,2.28,10]],"ltp":2.2,"tv":424.2,"id":67083366}]}]}
{"op":"mcm","clk":"11902294101","pt":1724337966238,"mc":[{"id":"1.232089285","rc":[{"batb":[[0,2.26,7.14],[1,2.2,5.13],[2,2.02,5.64]],"ltp":2.2,"tv":424.2,"id":67083366}]}]}
{"op":"mcm","clk":"11902294158","pt":1724337966906,"mc":[{"id":"1.232089285","rc":[{"batb":[[0,1.5,1],[1,1.4,17.68],[2,1.37,6.71]],"ltp":1.82,"tv":750.14,"id":72922097}]}]}
{"op":"mcm","clk":"11902295251","pt":1724337982747,"mc":[{"id":"1.232089285","rc":[{"batb":[[0,2.28,14],[1,2.26,7.14],[2,2.2,5.13]],"ltp":2.2,"tv":424.2,"id":67083366}]}]}
{"op":"mcm","clk":"11902295401","pt":1724337985280,"mc":[{"id":"1.232089285","rc":[{"batb":[[0,2.28,10]],"ltp":2.2,"tv":424.2,"id":67083366}]}]}
{"op":"mcm","clk":"11902295441","pt":1724337986267,"mc":[{"id":"1.232089285","rc":[{"batb":[[0,2.26,7.14],[1,2.2,5.13],[2,2.02,5.64]],"ltp":2.2,"tv":424.2,"id":67083366}]}]}
{"op":"mcm","clk":"11902295707","pt":1724337990950,"mc":[{"id":"1.232089285","rc":[{"batb":[[0,2.28,14],[1,2.26,7.14],[2,2.2,5.13]],"ltp":2.2,"tv":424.2,"id":67083366}]}]}
{"op":"mcm","clk":"11902295853","pt":1724337993473,"mc":[{"id":"1.232089285","rc":[{"batb":[[0,2.28,10]],"ltp":2.2,"tv":424.2,"id":67083366},{"batb":[[2,1.37,6.61]],"batl":[[1,2.02,51.26]],"ltp":1.82,"tv":750.14,"id":72922097}]}]}
{"op":"mcm","clk":"11902295909","pt":1724337994460,"mc":[{"id":"1.232089285","rc":[{"batb":[[0,2.26,7.14],[1,2.2,5.13],[2,2.02,5.64]],"ltp":2.2,"tv":424.2,"id":67083366}]}]}
{"op":"mcm","clk":"11902296241","pt":1724337999886,"mc":[{"id":"1.232089285","rc":[{"batb":[[0,2.28,14],[1,2.26,7.14],[2,2.2,5.13]],"ltp":2.2,"tv":424.2,"id":67083366}]}]}
{"op":"mcm","clk":"11902296376","pt":1724338002478,"mc":[{"id":"1.232089285","rc":[{"batb":[[0,2.28,10]],"ltp":2.2,"tv":424.2,"id":67083366}]}]}
{"op":"mcm","clk":"11902296426","pt":1724338003356,"mc":[{"id":"1.232089285","rc":[{"batb":[[0,2.26,7.14],[1,2.2,5.13],[2,2.02,5.64]],"ltp":2.2,"tv":424.2,"id":67083366}]}]}
{"op":"mcm","clk":"11902296510","pt":1724338005060,"mc":[{"id":"1.232089285","rc":[{"batb":[[0,2.28,4],[1,2.26,7.14],[2,2.2,5.13]],"ltp":2.2,"tv":424.2,"id":67083366}]}]}
{"op":"mcm","clk":"11902296655","pt":1724338007584,"mc":[{"id":"1.232089285","rc":[{"batb":[[0,2.28,10]],"ltp":2.2,"tv":424.2,"id":67083366}]}]}
{"op":"mcm","clk":"11902296899","pt":1724338011097,"mc":[{"id":"1.232089285","rc":[{"batb":[[0,2.28,4]],"ltp":2.2,"tv":424.2,"id":67083366}]}]}
{"op":"mcm","clk":"11902297079","pt":1724338013473,"mc":[{"id":"1.232089285","rc":[{"batb":[[0,2.26,7.14],[1,2.2,5.13],[2,2.02,5.64]],"ltp":2.2,"tv":424.2,"id":67083366}]}]}
{"op":"mcm","clk":"11902297184","pt":1724338015386,"mc":[{"id":"1.232089285","rc":[{"batl":[[0,2.02,51.26],[1,2.5,1],[2,2.5,0]],"ltp":1.82,"tv":750.14,"id":72922097}]}]}
{"op":"mcm","clk":"11902297738","pt":1724338023719,"mc":[{"id":"1.232089285","rc":[{"batl":[[0,1.76,33.47],[1,2.02,51.26],[2,2.5,1]],"ltp":1.82,"tv":750.14,"id":72922097}]}]}
{"op":"mcm","clk":"11902300183","pt":1724338055968,"mc":[{"id":"1.232089285","rc":[{"batb":[[0,2.46,30.38],[1,2.26,7.14],[2,2.2,5.13]],"ltp":2.2,"tv":424.2,"id":67083366},{"batb":[[0,1.63,70.42],[1,1.5,1],[2,1.4,17.68]],"ltp":1.82,"tv":750.14,"id":72922097}]}]}
{"op":"mcm","clk":"11902300592","pt":1724338061743,"mc":[{"id":"1.232089285","rc":[{"batb":[[1,2.34,2.66],[2,2.26,7.14]],"ltp":2.2,"tv":424.2,"id":67083366}]}]}
{"op":"mcm","clk":"11902302577","pt":1724338091776,"mc":[{"id":"1.232089285","rc":[{"batb":[[1,2.26,7.14],[2,2.2,5.13]],"ltp":2.2,"tv":424.2,"id":67083366}]}]}
{"op":"mcm","clk":"11902302935","pt":1724338096675,"mc":[{"id":"1.232089285","rc":[{"batb":[[2,1.37,7.53]],"ltp":1.82,"tv":750.14,"id":72922097}]}]}
{"op":"mcm","clk":"11902303093","pt":1724338098894,"mc":[{"id":"1.232089285","rc":[{"batb":[[2,1.37,6.61]],"ltp":1.82,"tv":750.14,"id":72922097}]}]}
{"op":"mcm","clk":"11902303742","pt":1724338109095,"mc":[{"id":"1.232089285","rc":[{"batl":[[0,2.02,51.26],[1,2.5,1],[2,2.5,0]],"ltp":1.82,"tv":750.14,"id":72922097}]}]}
{"op":"mcm","clk":"11902304073","pt":1724338113996,"mc":[{"id":"1.232089285","rc":[{"trd":[[2.46,0.61]],"batb":[[0,2.46,29.77]],"ltp":2.46,"tv":424.81,"id":67083366},{"trd":[[1.69,0.89]],"ltp":1.69,"tv":751.03,"id":72922097}],"tv":1175.84}]}
{"op":"mcm","clk":"11902304218","pt":1724338116214,"mc":[{"id":"1.232089285","rc":[{"batb":[[0,2.5,2.64],[1,2.46,30.38],[2,2.26,7.14]],"ltp":2.46,"tv":424.81,"id":67083366}]}]}
{"op":"mcm","clk":"11902306780","pt":1724338156969,"mc":[{"id":"1.232089285","rc":[{"batl":[[0,1.66,33.47],[1,2.02,51.26],[2,2.5,1]],"ltp":1.69,"tv":751.03,"id":72922097}]}]}
{"op":"mcm","clk":"11902312331","pt":1724338267216,"mc":[{"id":"1.232089285","rc":[{"batb":[[0,1.64,5.29],[1,1.63,70.42],[2,1.5,1]],"ltp":1.69,"tv":751.03,"id":72922097}]}]}
{"op":"mcm","clk":"11902312744","pt":1724338276507,"mc":[{"id":"1.232089285","rc":[{"trd":[[1.63,156.84],[1.64,10.58]],"batb":[[0,1.59,75.19],[1,1.5,1],[2,1.37,6.61]],"batl":[[0,1.63,54.12],[1,1.66,33.47],[2,2.02,51.26]],"ltp":1.63,"tv":902.44,"id":72922097}],"tv":1327.26}]}
{"op":"mcm","clk":"11902312750","pt":1724338276818,"mc":[{"id":"1.232089285","rc":[{"batl":[[0,1.62,5.35],[1,1.63,54.12],[2,1.66,33.47]],"ltp":1.63,"tv":902.44,"id":72922097}]}]}
{"op":"mcm","clk":"11902312951","pt":1724338282148,"mc":[{"id":"1.232089285","rc":[{"batl":[[1,1.66,33.47],[2,2.02,51.26]],"ltp":1.63,"tv":902.44,"id":72922097}]}]}
{"op":"mcm","clk":"11902313227","pt":1724338286824,"mc":[{"id":"1.232089285","rc":[{"batl":[[0,1.66,33.47],[1,2.02,51.26],[2,2.5,1]],"ltp":1.63,"tv":902.44,"id":72922097}]}]}
{"op":"mcm","clk":"11902313418","pt":1724338290935,"mc":[{"id":"1.232089285","rc":[{"batl":[[0,1.65,5.25],[1,1.66,33.47],[2,2.02,51.26]],"ltp":1.63,"tv":902.44,"id":72922097}]}]}
{"op":"mcm","clk":"11902314055","pt":1724338304466,"mc":[{"id":"1.232089285","rc":[{"batl":[[0,1.64,2],[1,1.65,5.25],[2,1.66,33.47]],"ltp":1.63,"tv":902.44,"id":72922097}]}]}
{"op":"mcm","clk":"11902323437","pt":1724338472233,"mc":[{"id":"1.232089285","rc":[{"trd":[[1.59,152.73]],"batb":[[0,1.55,80.66]],"batl":[[0,1.59,52.29],[1,1.64,2],[2,1.65,5.25]],"ltp":1.59,"tv":1055.17,"id":72922097}],"tv":1479.99}]}
{"op":"mcm","clk":"11902323504","pt":1724338473522,"mc":[{"id":"1.232089285","rc":[{"batl":[[0,1.58,5.49],[1,1.59,52.29],[2,1.64,2]],"ltp":1.59,"tv":1055.17,"id":72922097}]}]}
{"op":"mcm","clk":"11902323584","pt":1724338474911,"mc":[{"id":"1.232089285","rc":[{"batl":[[1,1.64,2],[2,1.66,33.47]],"ltp":1.59,"tv":1055.17,"id":72922097}]}]}
{"op":"mcm","clk":"11902323691","pt":1724338476818,"mc":[{"id":"1.232089285","rc":[{"batl":[[0,1.64,2],[1,1.65,5.25]],"ltp":1.59,"tv":1055.17,"id":72922097}]}]}
{"op":"mcm","clk":"11902342646","pt":1724338818591,"mc":[{"id":"1.232089285","rc":[{"trd":[[2,390.19],[2.32,16.54],[2.5,7.27]],"batb":[[0,2.54,10],[1,2.52,4],[2,2.5,2.64]],"batl":[[0,3.45,3.59]],"ltp":2.46,"tv":424.7,"id":67083366},{"trd":[[1.43,123.52],[1.44,17.65],[1.81,97.44],[2,391.57]],"batb":[[2,1.37,6.61]],"ltp":1.59,"tv":1055.01,"id":72922097}],"tv":1479.71}]}
{"op":"mcm","clk":"11902342801","pt":1724338820864,"mc":[{"id":"1.232089285","rc":[{"batb":[[1,2.5,2.64],[2,2.46,30.38]],"ltp":2.46,"tv":424.7,"id":67083366}]}]}
{"op":"mcm","clk":"11902342879","pt":1724338822101,"mc":[{"id":"1.232089285","rc":[{"batb":[[0,2.5,2.64],[1,2.46,30.38],[2,2.26,7.14]],"ltp":2.46,"tv":424.7,"id":67083366}]}]}
{"op":"mcm","clk":"11902343000","pt":1724338824369,"mc":[{"id":"1.232089285","rc":[{"batb":[[0,2.54,10],[1,2.52,4],[2,2.5,2.64]],"ltp":2.46,"tv":424.7,"id":67083366}]}]}
{"op":"mcm","clk":"11902343155","pt":1724338826486,"mc":[{"id":"1.232089285","rc":[{"batb":[[1,2.5,2.64],[2,2.46,30.38]],"ltp":2.46,"tv":424.7,"id":67083366}]}]}
{"op":"mcm","clk":"11902343242","pt":1724338827984,"mc":[{"id":"1.232089285","rc":[{"batb":[[0,2.5,2.64],[1,2.46,30.38],[2,2.26,7.14]],"ltp":2.46,"tv":424.7,"id":67083366}]}]}
{"op":"mcm","clk":"11902343901","pt":1724338837299,"mc":[{"id":"1.232089285","rc":[{"batb":[[0,2.54,10],[1,2.52,4],[2,2.5,2.64]],"ltp":2.46,"tv":424.7,"id":67083366}]}]}
{"op":"mcm","clk":"11902344066","pt":1724338839718,"mc":[{"id":"1.232089285","rc":[{"batb":[[1,2.5,2.64],[2,2.46,30.38]],"ltp":2.46,"tv":424.7,"id":67083366}]}]}
{"op":"mcm","clk":"11902344234","pt":1724338841680,"mc":[{"id":"1.232089285","rc":[{"batb":[[0,2.5,2.64],[1,2.46,30.38],[2,2.26,7.14]],"ltp":2.46,"tv":424.7,"id":67083366}]}]}
{"op":"mcm","clk":"11902344548","pt":1724338846425,"mc":[{"id":"1.232089285","rc":[{"batb":[[0,2.52,4],[1,2.5,2.64],[2,2.46,30.38]],"ltp":2.46,"tv":424.7,"id":67083366}]}]}
{"op":"mcm","clk":"11902344584","pt":1724338846836,"mc":[{"id":"1.232089285","rc":[{"batb":[[0,2.54,10],[1,2.52,4],[2,2.5,2.64]],"ltp":2.46,"tv":424.7,"id":67083366}]}]}
{"op":"mcm","clk":"11902344727","pt":1724338848809,"mc":[{"id":"1.232089285","rc":[{"batb":[[1,2.5,2.64],[2,2.46,30.38]],"ltp":2.46,"tv":424.7,"id":67083366}]}]}
{"op":"mcm","clk":"11902344799","pt":1724338850200,"mc":[{"id":"1.232089285","rc":[{"batb":[[0,2.5,2.64],[1,2.46,30.38],[2,2.26,7.14]],"ltp":2.46,"tv":424.7,"id":67083366}]}]}
{"op":"mcm","clk":"11902345426","pt":1724338860138,"mc":[{"id":"1.232089285","rc":[{"batb":[[0,2.54,10],[1,2.52,4],[2,2.5,2.64]],"ltp":2.46,"tv":424.7,"id":67083366}]}]}
{"op":"mcm","clk":"11902345589","pt":1724338862411,"mc":[{"id":"1.232089285","rc":[{"batb":[[1,2.5,2.64],[2,2.46,30.38]],"ltp":2.46,"tv":424.7,"id":67083366}]}]}
{"op":"mcm","clk":"11902345675","pt":1724338863750,"mc":[{"id":"1.232089285","rc":[{"batb":[[0,2.5,2.64],[1,2.46,30.38],[2,2.26,7.14]],"ltp":2.46,"tv":424.7,"id":67083366}]}]}
{"op":"mcm","clk":"11902345789","pt":1724338865311,"mc":[{"id":"1.232089285","rc":[{"batb":[[0,2.52,4],[1,2.5,2.64],[2,2.46,30.38]],"ltp":2.46,"tv":424.7,"id":67083366}]}]}
{"op":"mcm","clk":"11902345878","pt":1724338866547,"mc":[{"id":"1.232089285","rc":[{"batb":[[0,2.54,10],[1,2.52,4],[2,2.5,2.64]],"ltp":2.46,"tv":424.7,"id":67083366}]}]}
{"op":"mcm","clk":"11902345948","pt":1724338867739,"mc":[{"id":"1.232089285","rc":[{"batb":[[1,2.5,2.64],[2,2.46,30.38]],"ltp":2.46,"tv":424.7,"id":67083366}]}]}
{"op":"mcm","clk":"11902346108","pt":1724338870056,"mc":[{"id":"1.232089285","rc":[{"batb":[[0,2.52,4]],"ltp":2.46,"tv":424.7,"id":67083366}]}]}
{"op":"mcm","clk":"11902346321","pt":1724338872541,"mc":[{"id":"1.232089285","rc":[{"batb":[[0,2.5,2.64],[1,2.46,30.38],[2,2.26,7.14]],"ltp":2.46,"tv":424.7,"id":67083366}]}]}
{"op":"mcm","clk":"11902347652","pt":1724338891571,"mc":[{"id":"1.232089285","rc":[{"batb":[[0,2.54,10],[1,2.52,4],[2,2.5,2.64]],"ltp":2.46,"tv":424.7,"id":67083366}]}]}
{"op":"mcm","clk":"11902347826","pt":1724338893648,"mc":[{"id":"1.232089285","rc":[{"batb":[[1,2.5,2.64],[2,2.46,30.38]],"ltp":2.46,"tv":424.7,"id":67083366}]}]}
{"op":"mcm","clk":"11902347927","pt":1724338894785,"mc":[{"id":"1.232089285","rc":[{"batb":[[0,2.5,2.64],[1,2.46,30.38],[2,2.26,7.14]],"ltp":2.46,"tv":424.7,"id":67083366}]}]}
{"op":"mcm","clk":"11902348331","pt":1724338900863,"mc":[{"id":"1.232089285","rc":[{"batb":[[0,2.54,10],[1,2.52,4],[2,2.5,2.64]],"ltp":2.46,"tv":424.7,"id":67083366}]}]}
{"op":"mcm","clk":"11902348486","pt":1724338903086,"mc":[{"id":"1.232089285","rc":[{"batb":[[1,2.5,2.64],[2,2.46,30.38]],"ltp":2.46,"tv":424.7,"id":67083366}]}]}
{"op":"mcm","clk":"11902348574","pt":1724338904378,"mc":[{"id":"1.232089285","rc":[{"batb":[[0,2.5,2.64],[1,2.46,30.38],[2,2.26,7.14]],"ltp":2.46,"tv":424.7,"id":67083366}]}]}
{"op":"mcm","clk":"11902348656","pt":1724338905568,"mc":[{"id":"1.232089285","rc":[{"batb":[[0,2.52,4],[1,2.5,2.64],[2,2.46,30.38]],"ltp":2.46,"tv":424.7,"id":67083366}]}]}
{"op":"mcm","clk":"11902348817","pt":1724338908098,"mc":[{"id":"1.232089285","rc":[{"batb":[[0,2.5,2.64],[1,2.46,30.38],[2,2.26,7.14]],"ltp":2.46,"tv":424.7,"id":67083366}]}]}
{"op":"mcm","clk":"11902349419","pt":1724338917919,"mc":[{"id":"1.232089285","rc":[{"batb":[[0,2.54,10],[1,2.52,4],[2,2.5,2.64]],"ltp":2.46,"tv":424.7,"id":67083366}]}]}
{"op":"mcm","clk":"11902349572","pt":1724338920185,"mc":[{"id":"1.232089285","rc":[{"batb":[[1,2.5,2.64],[2,2.46,30.38]],"ltp":2.46,"tv":424.7,"id":67083366}]}]}
{"op":"mcm","clk":"11902349667","pt":1724338921490,"mc":[{"id":"1.232089285","rc":[{"batb":[[0,2.5,2.64],[1,2.46,30.38],[2,2.26,7.14]],"ltp":2.46,"tv":424.7,"id":67083366}]}]}
{"op":"mcm","clk":"11902349757","pt":1724338922581,"mc":[{"id":"1.232089285","rc":[{"batb":[[0,2.52,4],[1,2.5,2.64],[2,2.46,30.38]],"ltp":2.46,"tv":424.7,"id":67083366}]}]}
{"op":"mcm","clk":"11902349924","pt":1724338924916,"mc":[{"id":"1.232089285","rc":[{"batb":[[0,2.5,2.64],[1,2.46,30.38],[2,2.26,7.14]],"ltp":2.46,"tv":424.7,"id":67083366}]}]}
{"op":"mcm","clk":"11902350123","pt":1724338927512,"mc":[{"id":"1.232089285","rc":[{"batb":[[0,2.52,4],[1,2.5,2.64],[2,2.46,30.38]],"ltp":2.46,"tv":424.7,"id":67083366}]}]}
{"op":"mcm","clk":"11902350144","pt":1724338927822,"mc":[{"id":"1.232089285","rc":[{"batb":[[0,2.54,10],[1,2.52,4],[2,2.5,2.64]],"ltp":2.46,"tv":424.7,"id":67083366}]}]}
{"op":"mcm","clk":"11902350300","pt":1724338929896,"mc":[{"id":"1.232089285","rc":[{"batb":[[1,2.5,2.64],[2,2.46,30.38]],"ltp":2.46,"tv":424.7,"id":67083366}]}]}
{"op":"mcm","clk":"11902350410","pt":1724338931284,"mc":[{"id":"1.232089285","rc":[{"batb":[[0,2.5,2.64],[1,2.46,30.38],[2,2.26,7.14]],"ltp":2.46,"tv":424.7,"id":67083366}]}]}
{"op":"mcm","clk":"11902351208","pt":1724338943612,"mc":[{"id":"1.232089285","rc":[{"batb":[[0,2.52,4],[1,2.5,2.64],[2,2.46,30.38]],"ltp":2.46,"tv":424.7,"id":67083366}]}]}
{"op":"mcm","clk":"11902351215","pt":1724338943715,"mc":[{"id":"1.232089285","rc":[{"batb":[[0,2.54,10],[1,2.52,4],[2,2.5,2.64]],"ltp":2.46,"tv":424.7,"id":67083366}]}]}
{"op":"mcm","clk":"11902351372","pt":1724338946239,"mc":[{"id":"1.232089285","rc":[{"batb":[[1,2.5,2.64],[2,2.46,30.38]],"ltp":2.46,"tv":424.7,"id":67083366}]}]}
{"op":"mcm","clk":"11902351436","pt":1724338947322,"mc":[{"id":"1.232089285","rc":[{"batb":[[0,2.5,2.64],[1,2.46,30.38],[2,2.26,7.14]],"ltp":2.46,"tv":424.7,"id":67083366}]}]}
{"op":"mcm","clk":"11902352291","pt":1724338959272,"mc":[{"id":"1.232089285","rc":[{"batb":[[0,2.54,10],[1,2.52,4],[2,2.5,2.64]],"ltp":2.46,"tv":424.7,"id":67083366}]}]}
{"op":"mcm","clk":"11902352614","pt":1724338961337,"mc":[{"id":"1.232089285","rc":[{"batb":[[1,2.5,2.64],[2,2.46,30.38]],"ltp":2.46,"tv":424.7,"id":67083366}]}]}
{"op":"mcm","clk":"11902352785","pt":1724338962548,"mc":[{"id":"1.232089285","rc":[{"batb":[[0,2.5,2.64],[1,2.46,30.38],[2,2.26,7.14]],"ltp":2.46,"tv":424.7,"id":67083366}]}]}
{"op":"mcm","clk":"11902353705","pt":1724338974369,"mc":[{"id":"1.232089285","rc":[{"batb":[[0,2.52,4],[1,2.5,2.64],[2,2.46,30.38]],"ltp":2.46,"tv":424.7,"id":67083366}]}]}
{"op":"mcm","clk":"11902353719","pt":1724338974837,"mc":[{"id":"1.232089285","rc":[{"batb":[[0,2.54,10],[1,2.52,4],[2,2.5,2.64]],"ltp":2.46,"tv":424.7,"id":67083366}]}]}
{"op":"mcm","clk":"11902353849","pt":1724338976748,"mc":[{"id":"1.232089285","rc":[{"batb":[[1,2.5,2.64],[2,2.46,30.38]],"ltp":2.46,"tv":424.7,"id":67083366}]}]}
{"op":"mcm","clk":"11902353944","pt":1724338978193,"mc":[{"id":"1.232089285","rc":[{"batb":[[0,2.5,2.64],[1,2.46,30.38],[2,2.26,7.14]],"ltp":2.46,"tv":424.7,"id":67083366}]}]}
{"op":"mcm","clk":"11902354731","pt":1724338989498,"mc":[{"id":"1.232089285","rc":[{"batb":[[0,2.52,4],[1,2.5,2.64],[2,2.46,30.38]],"ltp":2.46,"tv":424.7,"id":67083366}]}]}
{"op":"mcm","clk":"11902354764","pt":1724338989862,"mc":[{"id":"1.232089285","rc":[{"batb":[[0,2.54,10],[1,2.52,4],[2,2.5,2.64]],"ltp":2.46,"tv":424.7,"id":67083366}]}]}
{"op":"mcm","clk":"11902354865","pt":1724338992178,"mc":[{"id":"1.232089285","rc":[{"batb":[[1,2.5,2.64],[2,2.46,30.38]],"ltp":2.46,"tv":424.7,"id":67083366}]}]}
{"op":"mcm","clk":"11902354938","pt":1724338993162,"mc":[{"id":"1.232089285","rc":[{"batb":[[0,2.5,2.64],[1,2.46,30.38],[2,2.26,7.14]],"ltp":2.46,"tv":424.7,"id":67083366}]}]}
{"op":"mcm","clk":"11902355279","pt":1724338997596,"mc":[{"id":"1.232089285","rc":[{"batb":[[0,2.52,4],[1,2.5,2.64],[2,2.46,30.38]],"ltp":2.46,"tv":424.7,"id":67083366}]}]}
{"op":"mcm","clk":"11902355290","pt":1724338997695,"mc":[{"id":"1.232089285","rc":[{"batb":[[0,2.54,10],[1,2.52,4],[2,2.5,2.64]],"ltp":2.46,"tv":424.7,"id":67083366}]}]}
{"op":"mcm","clk":"11902355484","pt":1724339000085,"mc":[{"id":"1.232089285","rc":[{"batb":[[1,2.5,2.64],[2,2.46,30.38]],"ltp":2.46,"tv":424.7,"id":67083366}]}]}
{"op":"mcm","clk":"11902355571","pt":1724339001213,"mc":[{"id":"1.232089285","rc":[{"batb":[[0,2.5,2.64],[1,2.46,30.38],[2,2.26,7.14]],"ltp":2.46,"tv":424.7,"id":67083366}]}]}
{"op":"mcm","clk":"11902355797","pt":1724339004307,"mc":[{"id":"1.232089285","rc":[{"batb":[[0,2.54,10],[1,2.52,4],[2,2.5,2.64]],"ltp":2.46,"tv":424.7,"id":67083366}]}]}
{"op":"mcm","clk":"11902355935","pt":1724339006525,"mc":[{"id":"1.232089285","rc":[{"batb":[[1,2.5,2.64],[2,2.46,30.38]],"ltp":2.46,"tv":424.7,"id":67083366}]}]}
{"op":"mcm","clk":"11902356019","pt":1724339007707,"mc":[{"id":"1.232089285","rc":[{"batb":[[0,2.5,2.64],[1,2.46,30.38],[2,2.26,7.14]],"ltp":2.46,"tv":424.7,"id":67083366}]}]}
{"op":"mcm","clk":"11902356816","pt":1724339018043,"mc":[{"id":"1.232089285","rc":[{"batb":[[0,2.54,10],[1,2.52,4],[2,2.5,2.64]],"ltp":2.46,"tv":424.7,"id":67083366}]}]}
{"op":"mcm","clk":"11902356978","pt":1724339020057,"mc":[{"id":"1.232089285","rc":[{"batb":[[1,2.5,2.64],[2,2.46,30.38]],"ltp":2.46,"tv":424.7,"id":67083366}]}]}
{"op":"mcm","clk":"11902357087","pt":1724339021339,"mc":[{"id":"1.232089285","rc":[{"batb":[[0,2.5,2.64],[1,2.46,30.38],[2,2.26,7.14]],"ltp":2.46,"tv":424.7,"id":67083366}]}]}
{"op":"mcm","clk":"11902358107","pt":1724339033456,"mc":[{"id":"1.232089285","rc":[{"batb":[[0,2.52,4],[1,2.5,2.64],[2,2.46,30.38]],"ltp":2.46,"tv":424.7,"id":67083366}]}]}
{"op":"mcm","clk":"11902358126","pt":1724339033769,"mc":[{"id":"1.232089285","rc":[{"batb":[[0,2.54,10],[1,2.52,4],[2,2.5,2.64]],"ltp":2.46,"tv":424.7,"id":67083366}]}]}
{"op":"mcm","clk":"11902358281","pt":1724339035829,"mc":[{"id":"1.232089285","rc":[{"batb":[[1,2.5,2.64],[2,2.46,30.38]],"ltp":2.46,"tv":424.7,"id":67083366}]}]}
{"op":"mcm","clk":"11902358373","pt":1724339037074,"mc":[{"id":"1.232089285","rc":[{"batb":[[0,2.5,2.64],[1,2.46,30.38],[2,2.26,7.14]],"ltp":2.46,"tv":424.7,"id":67083366}]}]}
{"op":"mcm","clk":"11902359038","pt":1724339045255,"mc":[{"id":"1.232089285","rc":[{"batb":[[0,2.54,10],[1,2.52,4],[2,2.5,2.64]],"ltp":2.46,"tv":424.7,"id":67083366}]}]}
{"op":"mcm","clk":"11902359198","pt":1724339047466,"mc":[{"id":"1.232089285","rc":[{"batb":[[1,2.5,2.64],[2,2.46,30.38]],"ltp":2.46,"tv":424.7,"id":67083366}]}]}
{"op":"mcm","clk":"11902359285","pt":1724339048701,"mc":[{"id":"1.232089285","rc":[{"batb":[[0,2.5,2.64],[1,2.46,30.38],[2,2.26,7.14]],"ltp":2.46,"tv":424.7,"id":67083366}]}]}
{"op":"mcm","clk":"11902359781","pt":1724339054294,"mc":[{"id":"1.232089285","rc":[{"batb":[[0,2.54,10],[1,2.52,4],[2,2.5,2.64]],"ltp":2.46,"tv":424.7,"id":67083366}]}]}
{"op":"mcm","clk":"11902359953","pt":1724339056474,"mc":[{"id":"1.232089285","rc":[{"batb":[[1,2.5,2.64],[2,2.46,30.38]],"ltp":2.46,"tv":424.7,"id":67083366}]}]}
{"op":"mcm","clk":"11902360048","pt":1724339057668,"mc":[{"id":"1.232089285","rc":[{"batb":[[0,2.5,2.64],[1,2.46,30.38],[2,2.26,7.14]],"ltp":2.46,"tv":424.7,"id":67083366}]}]}
{"op":"mcm","clk":"11902360525","pt":1724339063982,"mc":[{"id":"1.232089285","rc":[{"batb":[[0,2.54,10],[1,2.52,4],[2,2.5,2.64]],"ltp":2.46,"tv":424.7,"id":67083366}]}]}
{"op":"mcm","clk":"11902360667","pt":1724339066199,"mc":[{"id":"1.232089285","rc":[{"batb":[[1,2.5,2.64],[2,2.46,30.38]],"ltp":2.46,"tv":424.7,"id":67083366}]}]}
{"op":"mcm","clk":"11902360751","pt":1724339067497,"mc":[{"id":"1.232089285","rc":[{"batb":[[0,2.5,2.64],[1,2.46,30.38],[2,2.26,7.14]],"ltp":2.46,"tv":424.7,"id":67083366}]}]}
{"op":"mcm","clk":"11902363905","pt":1724339107352,"mc":[{"id":"1.232089285","rc":[{"batb":[[0,2.52,4],[1,2.5,2.64],[2,2.46,30.38]],"ltp":2.46,"tv":424.7,"id":67083366}]}]}
{"op":"mcm","clk":"11902363933","pt":1724339107659,"mc":[{"id":"1.232089285","rc":[{"batb":[[0,2.54,10],[1,2.52,4],[2,2.5,2.64]],"ltp":2.46,"tv":424.7,"id":67083366}]}]}
{"op":"mcm","clk":"11902364104","pt":1724339109626,"mc":[{"id":"1.232089285","rc":[{"batb":[[1,2.5,2.64],[2,2.46,30.38]],"ltp":2.46,"tv":424.7,"id":67083366}]}]}
{"op":"mcm","clk":"11902364217","pt":1724339110966,"mc":[{"id":"1.232089285","rc":[{"batb":[[0,2.5,2.64],[1,2.46,30.38],[2,2.26,7.14]],"ltp":2.46,"tv":424.7,"id":67083366}]}]}
{"op":"mcm","clk":"11902364937","pt":1724339119053,"mc":[{"id":"1.232089285","rc":[{"batb":[[0,2.54,10],[1,2.52,4],[2,2.5,2.64]],"ltp":2.46,"tv":424.7,"id":67083366}]}]}
{"op":"mcm","clk":"11902365145","pt":1724339121072,"mc":[{"id":"1.232089285","rc":[{"batb":[[1,2.5,2.64],[2,2.46,30.38]],"ltp":2.46,"tv":424.7,"id":67083366}]}]}
{"op":"mcm","clk":"11902365279","pt":1724339122324,"mc":[{"id":"1.232089285","rc":[{"batb":[[0,2.5,2.64],[1,2.46,30.38],[2,2.26,7.14]],"ltp":2.46,"tv":424.7,"id":67083366}]}]}
{"op":"mcm","clk":"11902366372","pt":1724339130038,"mc":[{"id":"1.232089285","rc":[{"batb":[[0,2.54,10],[1,2.52,4],[2,2.5,2.64]],"ltp":2.46,"tv":424.7,"id":67083366}]}]}
{"op":"mcm","clk":"11902366725","pt":1724339132235,"mc":[{"id":"1.232089285","rc":[{"batb":[[1,2.5,2.64],[2,2.46,30.38]],"ltp":2.46,"tv":424.7,"id":67083366}]}]}
{"op":"mcm","clk":"11902366894","pt":1724339133354,"mc":[{"id":"1.232089285","rc":[{"batb":[[0,2.5,2.64],[1,2.46,30.38],[2,2.26,7.14]],"ltp":2.46,"tv":424.7,"id":67083366}]}]}
{"op":"mcm","clk":"11902367355","pt":1724339136443,"mc":[{"id":"1.232089285","rc":[{"batb":[[0,2.54,10],[1,2.52,4],[2,2.5,2.64]],"ltp":2.46,"tv":424.7,"id":67083366}]}]}
{"op":"mcm","clk":"11902367629","pt":1724339138427,"mc":[{"id":"1.232089285","rc":[{"batb":[[1,2.5,2.64],[2,2.46,30.38]],"ltp":2.46,"tv":424.7,"id":67083366}]}]}
{"op":"mcm","clk":"11902367745","pt":1724339139650,"mc":[{"id":"1.232089285","rc":[{"batb":[[0,2.5,2.64],[1,2.46,30.38],[2,2.26,7.14]],"ltp":2.46,"tv":424.7,"id":67083366}]}]}
{"op":"mcm","clk":"11902369269","pt":1724339149558,"mc":[{"id":"1.232089285","rc":[{"batb":[[0,2.54,10],[1,2.52,4],[2,2.5,2.64]],"ltp":2.46,"tv":424.7,"id":67083366}]}]}
{"op":"mcm","clk":"11902369576","pt":1724339151657,"mc":[{"id":"1.232089285","rc":[{"batb":[[1,2.5,2.64],[2,2.46,30.38]],"ltp":2.46,"tv":424.7,"id":67083366}]}]}
{"op":"mcm","clk":"11902369768","pt":1724339152869,"mc":[{"id":"1.232089285","rc":[{"batb":[[0,2.5,2.64],[1,2.46,30.38],[2,2.26,7.14]],"ltp":2.46,"tv":424.7,"id":67083366}]}]}
{"op":"mcm","clk":"11902371009","pt":1724339161478,"mc":[{"id":"1.232089285","rc":[{"batb":[[0,2.52,4],[1,2.5,2.64],[2,2.46,30.38]],"ltp":2.46,"tv":424.7,"id":67083366}]}]}
{"op":"mcm","clk":"11902371039","pt":1724339161645,"mc":[{"id":"1.232089285","rc":[{"batb":[[0,2.54,10],[1,2.52,4],[2,2.5,2.64]],"ltp":2.46,"tv":424.7,"id":67083366}]}]}
{"op":"mcm","clk":"11902371385","pt":1724339163858,"mc":[{"id":"1.232089285","rc":[{"batb":[[1,2.5,2.64],[2,2.46,30.38]],"ltp":2.46,"tv":424.7,"id":67083366}]}]}
{"op":"mcm","clk":"11902371579","pt":1724339165050,"mc":[{"id":"1.232089285","rc":[{"batb":[[0,2.5,2.64],[1,2.46,30.38],[2,2.26,7.14]],"ltp":2.46,"tv":424.7,"id":67083366}]}]}
{"op":"mcm","clk":"11902374723","pt":1724339195397,"mc":[{"id":"1.232089285","rc":[{"batb":[[0,2.52,4],[1,2.5,2.64],[2,2.46,30.38]],"ltp":2.46,"tv":424.7,"id":67083366}]}]}
{"op":"mcm","clk":"11902374771","pt":1724339195802,"mc":[{"id":"1.232089285","rc":[{"batb":[[0,2.54,10],[1,2.52,4],[2,2.5,2.64]],"ltp":2.46,"tv":424.7,"id":67083366}]}]}
{"op":"mcm","clk":"11902374935","pt":1724339197819,"mc":[{"id":"1.232089285","rc":[{"batb":[[1,2.5,2.64],[2,2.46,30.38]],"ltp":2.46,"tv":424.7,"id":67083366}]}]}
{"op":"mcm","clk":"11902375077","pt":1724339199231,"mc":[{"id":"1.232089285","rc":[{"batb":[[0,2.5,2.64],[1,2.46,30.38],[2,2.26,7.14]],"ltp":2.46,"tv":424.7,"id":67083366}]}]}
{"op":"mcm","clk":"11902375509","pt":1724339203018,"mc":[{"id":"1.232089285","rc":[{"batb":[[0,2.54,10],[1,2.52,4],[2,2.5,2.64]],"ltp":2.46,"tv":424.7,"id":67083366}]}]}
{"op":"mcm","clk":"11902375703","pt":1724339205529,"mc":[{"id":"1.232089285","rc":[{"batb":[[1,2.5,2.64],[2,2.46,30.38]],"ltp":2.46,"tv":424.7,"id":67083366}]}]}
{"op":"mcm","clk":"11902375780","pt":1724339206420,"mc":[{"id":"1.232089285","rc":[{"batb":[[0,2.5,2.64],[1,2.46,30.38],[2,2.26,7.14]],"ltp":2.46,"tv":424.7,"id":67083366}]}]}
{"op":"mcm","clk":"11902376822","pt":1724339218246,"mc":[{"id":"1.232089285","rc":[{"batb":[[0,2.54,10],[1,2.52,4],[2,2.5,2.64]],"ltp":2.46,"tv":424.7,"id":67083366}]}]}
{"op":"mcm","clk":"11902377011","pt":1724339220521,"mc":[{"id":"1.232089285","rc":[{"batb":[[1,2.5,2.64],[2,2.46,30.38]],"ltp":2.46,"tv":424.7,"id":67083366}]}]}
{"op":"mcm","clk":"11902377087","pt":1724339221448,"mc":[{"id":"1.232089285","rc":[{"batb":[[0,2.5,2.64],[1,2.46,30.38],[2,2.26,7.14]],"ltp":2.46,"tv":424.7,"id":67083366}]}]}
{"op":"mcm","clk":"11902379450","pt":1724339246308,"mc":[{"id":"1.232089285","rc":[{"batb":[[0,2.54,10],[1,2.52,4],[2,2.5,2.64]],"ltp":2.46,"tv":424.7,"id":67083366}]}]}
{"op":"mcm","clk":"11902379627","pt":1724339248285,"mc":[{"id":"1.232089285","rc":[{"batb":[[1,2.5,2.64],[2,2.46,30.38]],"ltp":2.46,"tv":424.7,"id":67083366}]}]}
{"op":"mcm","clk":"11902379745","pt":1724339249682,"mc":[{"id":"1.232089285","rc":[{"batb":[[0,2.5,2.64],[1,2.46,30.38],[2,2.26,7.14]],"ltp":2.46,"tv":424.7,"id":67083366}]}]}
{"op":"mcm","clk":"11902380144","pt":1724339254106,"mc":[{"id":"1.232089285","rc":[{"batb":[[0,2.54,10],[1,2.52,4],[2,2.5,2.64]],"ltp":2.46,"tv":424.7,"id":67083366}]}]}
{"op":"mcm","clk":"11902380382","pt":1724339256493,"mc":[{"id":"1.232089285","rc":[{"batb":[[1,2.5,2.64],[2,2.46,30.38]],"ltp":2.46,"tv":424.7,"id":67083366}]}]}
{"op":"mcm","clk":"11902380480","pt":1724339257491,"mc":[{"id":"1.232089285","rc":[{"batb":[[0,2.5,2.64],[1,2.46,30.38],[2,2.26,7.14]],"ltp":2.46,"tv":424.7,"id":67083366}]}]}
{"op":"mcm","clk":"11902380827","pt":1724339261114,"mc":[{"id":"1.232089285","rc":[{"batb":[[0,2.54,10],[1,2.52,4],[2,2.5,2.64]],"ltp":2.46,"tv":424.7,"id":67083366}]}]}
{"op":"mcm","clk":"11902380972","pt":1724339262996,"mc":[{"id":"1.232089285","rc":[{"batb":[[1,2.5,2.64],[2,2.46,30.38]],"ltp":2.46,"tv":424.7,"id":67083366}]}]}
{"op":"mcm","clk":"11902381082","pt":1724339264501,"mc":[{"id":"1.232089285","rc":[{"batb":[[0,2.5,2.64],[1,2.46,30.38],[2,2.26,7.14]],"ltp":2.46,"tv":424.7,"id":67083366}]}]}
{"op":"mcm","clk":"11902381732","pt":1724339272312,"mc":[{"id":"1.232089285","rc":[{"batb":[[0,2.54,10],[1,2.52,4],[2,2.5,2.64]],"ltp":2.46,"tv":424.7,"id":67083366}]}]}
{"op":"mcm","clk":"11902381918","pt":1724339274529,"mc":[{"id":"1.232089285","rc":[{"batb":[[1,2.5,2.64],[2,2.46,30.38]],"ltp":2.46,"tv":424.7,"id":67083366}]}]}
{"op":"mcm","clk":"11902382148","pt":1724339277431,"mc":[{"id":"1.232089285","rc":[{"batb":[[0,2.5,2.64],[1,2.46,30.38],[2,2.26,7.14]],"ltp":2.46,"tv":424.7,"id":67083366}]}]}
{"op":"mcm","clk":"11902382186","pt":1724339277823,"mc":[{"id":"1.232089285","rc":[{"batb":[[0,2.52,4],[1,2.5,2.64],[2,2.46,30.38]],"ltp":2.46,"tv":424.7,"id":67083366}]}]}
{"op":"mcm","clk":"11902382415","pt":1724339280252,"mc":[{"id":"1.232089285","rc":[{"batb":[[0,2.5,2.64],[1,2.46,30.38],[2,2.26,7.14]],"ltp":2.46,"tv":424.7,"id":67083366}]}]}
{"op":"mcm","clk":"11902382727","pt":1724339283422,"mc":[{"id":"1.232089285","rc":[{"batb":[[0,2.54,10],[1,2.52,4],[2,2.5,2.64]],"ltp":2.46,"tv":424.7,"id":67083366}]}]}
{"op":"mcm","clk":"11902382919","pt":1724339285635,"mc":[{"id":"1.232089285","rc":[{"batb":[[1,2.5,2.64],[2,2.46,30.38]],"ltp":2.46,"tv":424.7,"id":67083366}]}]}
{"op":"mcm","clk":"11902382996","pt":1724339286831,"mc":[{"id":"1.232089285","rc":[{"batb":[[0,2.5,2.64],[1,2.46,30.38],[2,2.26,7.14]],"ltp":2.46,"tv":424.7,"id":67083366}]}]}
{"op":"mcm","clk":"11902383828","pt":1724339297261,"mc":[{"id":"1.232089285","rc":[{"batb":[[0,2.54,10],[1,2.52,4],[2,2.5,2.64]],"ltp":2.46,"tv":424.7,"id":67083366}]}]}
{"op":"mcm","clk":"11902384000","pt":1724339299245,"mc":[{"id":"1.232089285","rc":[{"batb":[[1,2.5,2.64],[2,2.46,30.38]],"ltp":2.46,"tv":424.7,"id":67083366}]}]}
{"op":"mcm","clk":"11902384100","pt":1724339300536,"mc":[{"id":"1.232089285","rc":[{"batb":[[0,2.5,2.64],[1,2.46,30.38],[2,2.26,7.14]],"ltp":2.46,"tv":424.7,"id":67083366}]}]}
{"op":"mcm","clk":"11902384220","pt":1724339302154,"mc":[{"id":"1.232089285","rc":[{"batb":[[0,2.52,4],[1,2.5,2.64],[2,2.46,30.38]],"ltp":2.46,"tv":424.7,"id":67083366}]}]}
{"op":"mcm","clk":"11902384397","pt":1724339304336,"mc":[{"id":"1.232089285","rc":[{"batb":[[0,2.54,10]],"ltp":2.46,"tv":424.7,"id":67083366}]}]}
{"op":"mcm","clk":"11902384693","pt":1724339307755,"mc":[{"id":"1.232089285","rc":[{"batb":[[0,2.52,4]],"ltp":2.46,"tv":424.7,"id":67083366}]}]}
{"op":"mcm","clk":"11902384880","pt":1724339310071,"mc":[{"id":"1.232089285","rc":[{"batb":[[0,2.5,2.64],[1,2.46,30.38],[2,2.26,7.14]],"ltp":2.46,"tv":424.7,"id":67083366}]}]}
{"op":"mcm","clk":"11902385602","pt":1724339318971,"mc":[{"id":"1.232089285","rc":[{"batb":[[0,2.54,10],[1,2.52,4],[2,2.5,2.64]],"ltp":2.46,"tv":424.7,"id":67083366}]}]}
{"op":"mcm","clk":"11902385792","pt":1724339321371,"mc":[{"id":"1.232089285","rc":[{"batb":[[1,2.5,2.64],[2,2.46,30.38]],"ltp":2.46,"tv":424.7,"id":67083366}]}]}
{"op":"mcm","clk":"11902385888","pt":1724339322471,"mc":[{"id":"1.232089285","rc":[{"batb":[[0,2.5,2.64],[1,2.46,30.38],[2,2.26,7.14]],"ltp":2.46,"tv":424.7,"id":67083366}]}]}
{"op":"mcm","clk":"11902386345","pt":1724339327577,"mc":[{"id":"1.232089285","rc":[{"batb":[[0,2.52,4],[1,2.5,2.64],[2,2.46,30.38]],"ltp":2.46,"tv":424.7,"id":67083366}]}]}
{"op":"mcm","clk":"11902386372","pt":1724339327986,"mc":[{"id":"1.232089285","rc":[{"batb":[[0,2.54,10],[1,2.52,4],[2,2.5,2.64]],"ltp":2.46,"tv":424.7,"id":67083366}]}]}
{"op":"mcm","clk":"11902386560","pt":1724339330180,"mc":[{"id":"1.232089285","rc":[{"batb":[[1,2.5,2.64],[2,2.46,30.38]],"ltp":2.46,"tv":424.7,"id":67083366}]}]}
{"op":"mcm","clk":"11902386644","pt":1724339331269,"mc":[{"id":"1.232089285","rc":[{"batb":[[0,2.5,2.64],[1,2.46,30.38],[2,2.26,7.14]],"ltp":2.46,"tv":424.7,"id":67083366}]}]}
{"op":"mcm","clk":"11902387103","pt":1724339337282,"mc":[{"id":"1.232089285","rc":[{"batb":[[0,2.54,10],[1,2.52,4],[2,2.5,2.64]],"ltp":2.46,"tv":424.7,"id":67083366}]}]}
{"op":"mcm","clk":"11902387298","pt":1724339339699,"mc":[{"id":"1.232089285","rc":[{"batb":[[1,2.5,2.64],[2,2.46,30.38]],"ltp":2.46,"tv":424.7,"id":67083366}]}]}
{"op":"mcm","clk":"11902387405","pt":1724339340795,"mc":[{"id":"1.232089285","rc":[{"batb":[[0,2.5,2.64],[1,2.46,30.38],[2,2.26,7.14]],"ltp":2.46,"tv":424.7,"id":67083366}]}]}
{"op":"mcm","clk":"11902388481","pt":1724339352113,"mc":[{"id":"1.232089285","rc":[{"batb":[[0,2.54,10],[1,2.52,4],[2,2.5,2.64]],"ltp":2.46,"tv":424.7,"id":67083366}]}]}
{"op":"mcm","clk":"11902388661","pt":1724339354193,"mc":[{"id":"1.232089285","rc":[{"batb":[[1,2.5,2.64],[2,2.46,30.38]],"ltp":2.46,"tv":424.7,"id":67083366}]}]}
{"op":"mcm","clk":"11902388757","pt":1724339355529,"mc":[{"id":"1.232089285","rc":[{"batb":[[0,2.5,2.64],[1,2.46,30.38],[2,2.26,7.14]],"ltp":2.46,"tv":424.7,"id":67083366}]}]}
{"op":"mcm","clk":"11902389673","pt":1724339368049,"mc":[{"id":"1.232089285","rc":[{"batb":[[0,2.54,10],[1,2.52,4],[2,2.5,2.64]],"ltp":2.46,"tv":424.7,"id":67083366}]}]}
{"op":"mcm","clk":"11902389807","pt":1724339370316,"mc":[{"id":"1.232089285","rc":[{"batb":[[1,2.5,2.64],[2,2.46,30.38]],"ltp":2.46,"tv":424.7,"id":67083366}]}]}
{"op":"mcm","clk":"11902389889","pt":1724339371639,"mc":[{"id":"1.232089285","rc":[{"batb":[[0,2.5,2.64],[1,2.46,30.38],[2,2.26,7.14]],"ltp":2.46,"tv":424.7,"id":67083366}]}]}
{"op":"mcm","clk":"11902389990","pt":1724339372936,"mc":[{"id":"1.232089285","rc":[{"batb":[[0,2.52,4],[1,2.5,2.64],[2,2.46,30.38]],"ltp":2.46,"tv":424.7,"id":67083366}]}]}
{"op":"mcm","clk":"11902390118","pt":1724339375256,"mc":[{"id":"1.232089285","rc":[{"batb":[[0,2.54,10]],"ltp":2.46,"tv":424.7,"id":67083366}]}]}
{"op":"mcm","clk":"11902390325","pt":1724339378424,"mc":[{"id":"1.232089285","rc":[{"batb":[[0,2.5,2.64],[1,2.46,30.38],[2,2.26,7.14]],"ltp":2.46,"tv":424.7,"id":67083366}]}]}
{"op":"mcm","clk":"11902390353","pt":1724339378732,"mc":[{"id":"1.232089285","rc":[{"batb":[[0,2.52,4],[1,2.5,2.64],[2,2.46,30.38]],"ltp":2.46,"tv":424.7,"id":67083366}]}]}
{"op":"mcm","clk":"11902390530","pt":1724339381129,"mc":[{"id":"1.232089285","rc":[{"batb":[[0,2.5,2.64],[1,2.46,30.38],[2,2.26,7.14]],"ltp":2.46,"tv":424.7,"id":67083366}]}]}
{"op":"mcm","clk":"11902390769","pt":1724339384158,"mc":[{"id":"1.232089285","rc":[{"batb":[[0,2.54,10],[1,2.52,4],[2,2.5,2.64]],"ltp":2.46,"tv":424.7,"id":67083366}]}]}
{"op":"mcm","clk":"11902390880","pt":1724339386172,"mc":[{"id":"1.232089285","rc":[{"batb":[[1,2.5,2.64],[2,2.46,30.38]],"ltp":2.46,"tv":424.7,"id":67083366}]}]}
{"op":"mcm","clk":"11902391003","pt":1724339387639,"mc":[{"id":"1.232089285","rc":[{"batb":[[0,2.5,2.64],[1,2.46,30.38],[2,2.26,7.14]],"ltp":2.46,"tv":424.7,"id":67083366}]}]}
{"op":"mcm","clk":"11902391112","pt":1724339389250,"mc":[{"id":"1.232089285","rc":[{"batb":[[0,2.52,4],[1,2.5,2.64],[2,2.46,30.38]],"ltp":2.46,"tv":424.7,"id":67083366}]}]}
{"op":"mcm","clk":"11902391310","pt":1724339391553,"mc":[{"id":"1.232089285","rc":[{"batb":[[0,2.5,2.64],[1,2.46,30.38],[2,2.26,7.14]],"ltp":2.46,"tv":424.7,"id":67083366}]}]}
{"op":"mcm","clk":"11902391812","pt":1724339398585,"mc":[{"id":"1.232089285","rc":[{"batb":[[0,2.52,4],[1,2.5,2.64],[2,2.46,30.38]],"ltp":2.46,"tv":424.7,"id":67083366}]}]}
{"op":"mcm","clk":"11902391839","pt":1724339398789,"mc":[{"id":"1.232089285","rc":[{"batb":[[0,2.54,10],[1,2.52,4],[2,2.5,2.64]],"ltp":2.46,"tv":424.7,"id":67083366}]}]}
{"op":"mcm","clk":"11902392027","pt":1724339400998,"mc":[{"id":"1.232089285","rc":[{"batb":[[1,2.5,2.64],[2,2.46,30.38]],"ltp":2.46,"tv":424.7,"id":67083366}]}]}
{"op":"mcm","clk":"11902392120","pt":1724339402288,"mc":[{"id":"1.232089285","rc":[{"batb":[[0,2.5,2.64],[1,2.46,30.38],[2,2.26,7.14]],"ltp":2.46,"tv":424.7,"id":67083366}]}]}
{"op":"mcm","clk":"11902392620","pt":1724339408469,"mc":[{"id":"1.232089285","rc":[{"batb":[[0,2.52,4],[1,2.5,2.64],[2,2.46,30.38]],"ltp":2.46,"tv":424.7,"id":67083366}]}]}
{"op":"mcm","clk":"11902392630","pt":1724339408676,"mc":[{"id":"1.232089285","rc":[{"batb":[[0,2.54,10],[1,2.52,4],[2,2.5,2.64]],"ltp":2.46,"tv":424.7,"id":67083366}]}]}
{"op":"mcm","clk":"11902392783","pt":1724339410902,"mc":[{"id":"1.232089285","rc":[{"batb":[[1,2.5,2.64],[2,2.46,30.38]],"ltp":2.46,"tv":424.7,"id":67083366}]}]}
{"op":"mcm","clk":"11902392890","pt":1724339412094,"mc":[{"id":"1.232089285","rc":[{"batb":[[0,2.5,2.64],[1,2.46,30.38],[2,2.26,7.14]],"ltp":2.46,"tv":424.7,"id":67083366}]}]}
{"op":"mcm","clk":"11902393031","pt":1724339413905,"mc":[{"id":"1.232089285","rc":[{"batb":[[0,2.52,4],[1,2.5,2.64],[2,2.46,30.38]],"ltp":2.46,"tv":424.7,"id":67083366}]}]}
{"op":"mcm","clk":"11902393221","pt":1724339416320,"mc":[{"id":"1.232089285","rc":[{"batb":[[0,2.5,2.64],[1,2.46,30.38],[2,2.26,7.14]],"ltp":2.46,"tv":424.7,"id":67083366}]}]}
{"op":"mcm","clk":"11902393660","pt":1724339422995,"mc":[{"id":"1.232089285","rc":[{"batb":[[0,2.54,10],[1,2.52,4],[2,2.5,2.64]],"ltp":2.46,"tv":424.7,"id":67083366}]}]}
{"op":"mcm","clk":"11902393838","pt":1724339425012,"mc":[{"id":"1.232089285","rc":[{"batb":[[1,2.5,2.64],[2,2.46,30.38]],"ltp":2.46,"tv":424.7,"id":67083366}]}]}
{"op":"mcm","clk":"11902393989","pt":1724339426519,"mc":[{"id":"1.232089285","rc":[{"batb":[[0,2.5,2.64],[1,2.46,30.38],[2,2.26,7.14]],"ltp":2.46,"tv":424.7,"id":67083366}]}]}
{"op":"mcm","clk":"11902394732","pt":1724339436519,"mc":[{"id":"1.232089285","rc":[{"batb":[[0,2.54,10],[1,2.52,4],[2,2.5,2.64]],"ltp":2.46,"tv":424.7,"id":67083366}]}]}
{"op":"mcm","clk":"11902394920","pt":1724339438725,"mc":[{"id":"1.232089285","rc":[{"batb":[[1,2.5,2.64],[2,2.46,30.38]],"ltp":2.46,"tv":424.7,"id":67083366}]}]}
{"op":"mcm","clk":"11902395000","pt":1724339439928,"mc":[{"id":"1.232089285","rc":[{"batb":[[0,2.5,2.64],[1,2.46,30.38],[2,2.26,7.14]],"ltp":2.46,"tv":424.7,"id":67083366}]}]}
{"op":"mcm","clk":"11902395684","pt":1724339449029,"mc":[{"id":"1.232089285","rc":[{"batb":[[0,2.54,10],[1,2.52,4],[2,2.5,2.64]],"ltp":2.46,"tv":424.7,"id":67083366}]}]}
{"op":"mcm","clk":"11902395807","pt":1724339451139,"mc":[{"id":"1.232089285","rc":[{"batb":[[1,2.5,2.64],[2,2.46,30.38]],"ltp":2.46,"tv":424.7,"id":67083366}]}]}
{"op":"mcm","clk":"11902395925","pt":1724339452744,"mc":[{"id":"1.232089285","rc":[{"batb":[[0,2.5,2.64],[1,2.46,30.38],[2,2.26,7.14]],"ltp":2.46,"tv":424.7,"id":67083366}]}]}
{"op":"mcm","clk":"11902396587","pt":1724339460444,"mc":[{"id":"1.232089285","rc":[{"batb":[[0,2.52,4],[1,2.5,2.64],[2,2.46,30.38]],"ltp":2.46,"tv":424.7,"id":67083366}]}]}
{"op":"mcm","clk":"11902396615","pt":1724339460758,"mc":[{"id":"1.232089285","rc":[{"batb":[[0,2.54,10],[1,2.52,4],[2,2.5,2.64]],"ltp":2.46,"tv":424.7,"id":67083366}]}]}
{"op":"mcm","clk":"11902396801","pt":1724339462930,"mc":[{"id":"1.232089285","rc":[{"batb":[[1,2.5,2.64],[2,2.46,30.38]],"ltp":2.46,"tv":424.7,"id":67083366}]}]}
{"op":"mcm","clk":"11902396900","pt":1724339464057,"mc":[{"id":"1.232089285","rc":[{"batb":[[0,2.5,2.64],[1,2.46,30.38],[2,2.26,7.14]],"ltp":2.46,"tv":424.7,"id":67083366}]}]}
{"op":"mcm","clk":"11902397464","pt":1724339471268,"mc":[{"id":"1.232089285","rc":[{"batb":[[0,2.54,10],[1,2.52,4],[2,2.5,2.64]],"ltp":2.46,"tv":424.7,"id":67083366}]}]}
{"op":"mcm","clk":"11902397621","pt":1724339473442,"mc":[{"id":"1.232089285","rc":[{"batb":[[1,2.5,2.64],[2,2.46,30.38]],"ltp":2.46,"tv":424.7,"id":67083366}]}]}
{"op":"mcm","clk":"11902397726","pt":1724339474681,"mc":[{"id":"1.232089285","rc":[{"batb":[[0,2.5,2.64],[1,2.46,30.38],[2,2.26,7.14]],"ltp":2.46,"tv":424.7,"id":67083366}]}]}
{"op":"mcm","clk":"11902401779","pt":1724339513951,"mc":[{"id":"1.232089285","rc":[{"batb":[[0,2.54,10],[1,2.52,4],[2,2.5,2.64]],"ltp":2.46,"tv":424.7,"id":67083366}]}]}
{"op":"mcm","clk":"11902401990","pt":1724339516188,"mc":[{"id":"1.232089285","rc":[{"batb":[[1,2.5,2.64],[2,2.46,30.38]],"ltp":2.46,"tv":424.7,"id":67083366}]}]}
{"op":"mcm","clk":"11902402111","pt":1724339517477,"mc":[{"id":"1.232089285","rc":[{"batb":[[0,2.5,2.64],[1,2.46,30.38],[2,2.26,7.14]],"ltp":2.46,"tv":424.7,"id":67083366}]}]}
{"op":"mcm","clk":"11902404985","pt":1724339551285,"mc":[{"id":"1.232089285","rc":[{"batb":[[0,2.52,4],[1,2.5,2.64],[2,2.46,30.38]],"ltp":2.46,"tv":424.7,"id":67083366}]}]}
{"op":"mcm","clk":"11902405027","pt":1724339551754,"mc":[{"id":"1.232089285","rc":[{"batb":[[0,2.54,10],[1,2.52,4],[2,2.5,2.64]],"ltp":2.46,"tv":424.7,"id":67083366}]}]}
{"op":"mcm","clk":"11902405212","pt":1724339553929,"mc":[{"id":"1.232089285","rc":[{"batb":[[1,2.5,2.64],[2,2.46,30.38]],"ltp":2.46,"tv":424.7,"id":67083366}]}]}
{"op":"mcm","clk":"11902405320","pt":1724339555036,"mc":[{"id":"1.232089285","rc":[{"batb":[[0,2.5,2.64],[1,2.46,30.38],[2,2.26,7.14]],"ltp":2.46,"tv":424.7,"id":67083366}]}]}
{"op":"mcm","clk":"11902406338","pt":1724339567582,"mc":[{"id":"1.232089285","rc":[{"batb":[[0,2.54,10],[1,2.52,4],[2,2.5,2.64]],"ltp":2.46,"tv":424.7,"id":67083366}]}]}
{"op":"mcm","clk":"11902406560","pt":1724339569668,"mc":[{"id":"1.232089285","rc":[{"batb":[[1,2.5,2.64],[2,2.46,30.38]],"ltp":2.46,"tv":424.7,"id":67083366}]}]}
{"op":"mcm","clk":"11902406665","pt":1724339570963,"mc":[{"id":"1.232089285","rc":[{"batb":[[0,2.5,2.64],[1,2.46,30.38],[2,2.26,7.14]],"ltp":2.46,"tv":424.7,"id":67083366}]}]}
{"op":"mcm","clk":"11902406878","pt":1724339573562,"mc":[{"id":"1.232089285","rc":[{"batb":[[0,2.54,10],[1,2.52,4],[2,2.5,2.64]],"ltp":2.46,"tv":424.7,"id":67083366}]}]}
{"op":"mcm","clk":"11902419446","pt":1724339575765,"mc":[{"id":"1.232089285","rc":[{"batb":[[1,2.5,2.64],[2,2.46,30.38]],"ltp":2.46,"tv":424.7,"id":67083366}]}]}
{"op":"mcm","clk":"11902419564","pt":1724339577060,"mc":[{"id":"1.232089285","rc":[{"batb":[[0,2.5,2.64],[1,2.46,30.38],[2,2.26,7.14]],"ltp":2.46,"tv":424.7,"id":67083366}]}]}
{"op":"mcm","clk":"11902419667","pt":1724339578460,"mc":[{"id":"1.232089285","rc":[{"batb":[[0,2.52,4],[1,2.5,2.64],[2,2.46,30.38]],"ltp":2.46,"tv":424.7,"id":67083366}]}]}
{"op":"mcm","clk":"11902419901","pt":1724339581004,"mc":[{"id":"1.232089285","rc":[{"batb":[[0,2.5,2.64],[1,2.46,30.38],[2,2.26,7.14]],"ltp":2.46,"tv":424.7,"id":67083366}]}]}
{"op":"mcm","clk":"11902421546","pt":1724339598498,"mc":[{"id":"1.232089285","rc":[{"batb":[[0,2.52,4],[1,2.5,2.64],[2,2.46,30.38]],"ltp":2.46,"tv":424.7,"id":67083366}]}]}
{"op":"mcm","clk":"11902421575","pt":1724339598906,"mc":[{"id":"1.232089285","rc":[{"batb":[[0,2.54,10],[1,2.52,4],[2,2.5,2.64]],"ltp":2.46,"tv":424.7,"id":67083366}]}]}
{"op":"mcm","clk":"11902421754","pt":1724339600992,"mc":[{"id":"1.232089285","rc":[{"batb":[[1,2.5,2.64],[2,2.46,30.38]],"ltp":2.46,"tv":424.7,"id":67083366}]}]}
{"op":"mcm","clk":"11902421859","pt":1724339602299,"mc":[{"id":"1.232089285","rc":[{"batb":[[0,2.5,2.64],[1,2.46,30.38],[2,2.26,7.14]],"ltp":2.46,"tv":424.7,"id":67083366}]}]}
{"op":"mcm","clk":"11902422658","pt":1724339612102,"mc":[{"id":"1.232089285","rc":[{"batb":[[0,2.54,10],[1,2.52,4],[2,2.5,2.64]],"ltp":2.46,"tv":424.7,"id":67083366}]}]}
{"op":"mcm","clk":"11902422870","pt":1724339614226,"mc":[{"id":"1.232089285","rc":[{"batb":[[1,2.5,2.64],[2,2.46,30.38]],"ltp":2.46,"tv":424.7,"id":67083366}]}]}
{"op":"mcm","clk":"11902422986","pt":1724339615631,"mc":[{"id":"1.232089285","rc":[{"batb":[[0,2.5,2.64],[1,2.46,30.38],[2,2.26,7.14]],"ltp":2.46,"tv":424.7,"id":67083366}]}]}
{"op":"mcm","clk":"11902423230","pt":1724339618536,"mc":[{"id":"1.232089285","rc":[{"batb":[[0,2.52,4],[1,2.5,2.64],[2,2.46,30.38]],"ltp":2.46,"tv":424.7,"id":67083366}]}]}
{"op":"mcm","clk":"11902423258","pt":1724339618916,"mc":[{"id":"1.232089285","rc":[{"batb":[[0,2.54,10],[1,2.52,4],[2,2.5,2.64]],"ltp":2.46,"tv":424.7,"id":67083366}]}]}
{"op":"mcm","clk":"11902423410","pt":1724339621316,"mc":[{"id":"1.232089285","rc":[{"batb":[[1,2.5,2.64],[2,2.46,30.38]],"ltp":2.46,"tv":424.7,"id":67083366}]}]}
{"op":"mcm","clk":"11902423486","pt":1724339622244,"mc":[{"id":"1.232089285","rc":[{"batb":[[0,2.5,2.64],[1,2.46,30.38],[2,2.26,7.14]],"ltp":2.46,"tv":424.7,"id":67083366}]}]}
{"op":"mcm","clk":"11902423589","pt":1724339623516,"mc":[{"id":"1.232089285","rc":[{"batb":[[0,2.52,4],[1,2.5,2.64],[2,2.46,30.38]],"ltp":2.46,"tv":424.7,"id":67083366}]}]}
{"op":"mcm","clk":"11902423782","pt":1724339625925,"mc":[{"id":"1.232089285","rc":[{"batb":[[0,2.5,2.64],[1,2.46,30.38],[2,2.26,7.14]],"ltp":2.46,"tv":424.7,"id":67083366}]}]}
{"op":"mcm","clk":"11902424211","pt":1724339631330,"mc":[{"id":"1.232089285","rc":[{"batb":[[0,2.54,10],[1,2.52,4],[2,2.5,2.64]],"ltp":2.46,"tv":424.7,"id":67083366}]}]}
{"op":"mcm","clk":"11902424394","pt":1724339633663,"mc":[{"id":"1.232089285","rc":[{"batb":[[1,2.5,2.64],[2,2.46,30.38]],"ltp":2.46,"tv":424.7,"id":67083366}]}]}
{"op":"mcm","clk":"11902424502","pt":1724339635167,"mc":[{"id":"1.232089285","rc":[{"batb":[[0,2.5,2.64],[1,2.46,30.38],[2,2.26,7.14]],"ltp":2.46,"tv":424.7,"id":67083366}]}]}
{"op":"mcm","clk":"11902424919","pt":1724339640470,"mc":[{"id":"1.232089285","rc":[{"batb":[[0,2.54,10],[1,2.52,4],[2,2.5,2.64]],"ltp":2.46,"tv":424.7,"id":67083366}]}]}
{"op":"mcm","clk":"11902425141","pt":1724339642459,"mc":[{"id":"1.232089285","rc":[{"batb":[[1,2.5,2.64],[2,2.46,30.38]],"ltp":2.46,"tv":424.7,"id":67083366}]}]}
{"op":"mcm","clk":"11902425253","pt":1724339643752,"mc":[{"id":"1.232089285","rc":[{"batb":[[0,2.5,2.64],[1,2.46,30.38],[2,2.26,7.14]],"ltp":2.46,"tv":424.7,"id":67083366}]}]}
{"op":"mcm","clk":"11902427267","pt":1724339667978,"mc":[{"id":"1.232089285","rc":[{"batb":[[0,2.54,10],[1,2.52,4],[2,2.5,2.64]],"ltp":2.46,"tv":424.7,"id":67083366}]}]}
{"op":"mcm","clk":"11902427490","pt":1724339670222,"mc":[{"id":"1.232089285","rc":[{"batb":[[1,2.5,2.64],[2,2.46,30.38]],"ltp":2.46,"tv":424.7,"id":67083366}]}]}
{"op":"mcm","clk":"11902427621","pt":1724339671693,"mc":[{"id":"1.232089285","rc":[{"batb":[[0,2.5,2.64],[1,2.46,30.38],[2,2.26,7.14]],"ltp":2.46,"tv":424.7,"id":67083366}]}]}
{"op":"mcm","clk":"11902428543","pt":1724339681622,"mc":[{"id":"1.232089285","rc":[{"batb":[[0,2.52,4],[1,2.5,2.64],[2,2.46,30.38]],"ltp":2.46,"tv":424.7,"id":67083366}]}]}
{"op":"mcm","clk":"11902428595","pt":1724339682140,"mc":[{"id":"1.232089285","rc":[{"batb":[[0,2.54,10],[1,2.52,4],[2,2.5,2.64]],"ltp":2.46,"tv":424.7,"id":67083366}]}]}
{"op":"mcm","clk":"11902428785","pt":1724339684110,"mc":[{"id":"1.232089285","rc":[{"batb":[[1,2.5,2.64],[2,2.46,30.38]],"ltp":2.46,"tv":424.7,"id":67083366}]}]}
