{"op":"mcm","clk":"11771899861","pt":1722763444506,"mc":[{"id":"1.231431360","marketDefinition":{"bspMarket":false,"turnInPlayEnabled":true,"persistenceEnabled":true,"marketBaseRate":5.0,"eventId":"33467055","eventTypeId":"4","numberOfWinners":1,"bettingType":"ODDS","marketType":"MATCH_ODDS","marketTime":"2024-08-07T10:00:00.000Z","suspendTime":"2024-08-07T10:00:00.000Z","bspReconciled":false,"complete":true,"inPlay":false,"crossMatching":false,"runnersVoidable":false,"numberOfActiveRunners":2,"betDelay":0,"status":"OPEN","runners":[{"status":"ACTIVE","sortPriority":1,"id":2219,"name":"Gloucestershire"},{"status":"ACTIVE","sortPriority":2,"id":31379,"name":"Sussex"}],"regulators":["MR_INT"],"countryCode":"GB","discountAllowed":false,"timezone":"GMT","openDate":"2024-08-07T10:00:00.000Z","version":6056050633,"name":"Match Odds","eventName":"Gloucestershire v Sussex"},"rc":[{"batb":[[0,1.03,200],[1,1.02,200],[2,1.01,220]],"ltp":0.0,"tv":0.0,"id":31379},{"batb":[[0,1.03,200],[1,1.02,200],[2,1.01,220]],"ltp":0.0,"tv":0.0,"id":2219}]}]}
{"op":"mcm","clk":"11771899968","pt":1722763445671,"mc":[{"id":"1.231431360","marketDefinition":{"bspMarket":false,"turnInPlayEnabled":true,"persistenceEnabled":true,"marketBaseRate":5.0,"eventId":"33467055","eventTypeId":"4","numberOfWinners":1,"bettingType":"ODDS","marketType":"MATCH_ODDS","marketTime":"2024-08-07T10:00:00.000Z","suspendTime":"2024-08-07T10:00:00.000Z","bspReconciled":false,"complete":true,"inPlay":false,"crossMatching":false,"runnersVoidable":false,"numberOfActiveRunners":2,"betDelay":0,"status":"OPEN","runners":[{"status":"ACTIVE","sortPriority":1,"id":2219,"name":"Gloucestershire"},{"status":"ACTIVE","sortPriority":2,"id":31379,"name":"Sussex"}],"regulators":["MR_INT"],"countryCode":"GB","discountAllowed":true,"timezone":"GMT","openDate":"2024-08-07T10:00:00.000Z","version":6056050633,"name":"Match Odds","eventName":"Gloucestershire v Sussex"}}]}
{"op":"mcm","clk":"11772258056","pt":1722767233821,"mc":[{"id":"1.231431360","rc":[{"batb":[[2,1.01,227.81]],"ltp":0.0,"tv":0.0,"id":31379},{"batb":[[2,1.01,227.81]],"ltp":0.0,"tv":0.0,"id":2219}]}]}
{"op":"mcm","clk":"11772261659","pt":1722767284697,"mc":[{"id":"1.231431360","rc":[{"batb":[[1,1.02,207.81]],"ltp":0.0,"tv":0.0,"id":31379},{"batb":[[1,1.02,207.81]],"ltp":0.0,"tv":0.0,"id":2219}]}]}
{"op":"mcm","clk":"11772262742","pt":1722767300704,"mc":[{"id":"1.231431360","rc":[{"batb":[[1,1.02,246.85]],"ltp":0.0,"tv":0.0,"id":31379},{"batb":[[1,1.02,246.85]],"ltp":0.0,"tv":0.0,"id":2219}]}]}
{"op":"mcm","clk":"11772263593","pt":1722767312418,"mc":[{"id":"1.231431360","rc":[{"batb":[[0,1.03,207.81]],"ltp":0.0,"tv":0.0,"id":31379},{"batb":[[0,1.03,207.81]],"ltp":0.0,"tv":0.0,"id":2219}]}]}
{"op":"mcm","clk":"11772264685","pt":1722767328887,"mc":[{"id":"1.231431360","rc":[{"batb":[[0,1.04,7.81],[1,1.03,207.81],[2,1.02,246.85]],"ltp":0.0,"tv":0.0,"id":31379},{"batb":[[0,1.04,7.81],[1,1.03,207.81],[2,1.02,246.85]],"ltp":0.0,"tv":0.0,"id":2219}]}]}
{"op":"mcm","clk":"11772265422","pt":1722767341073,"mc":[{"id":"1.231431360","rc":[{"batb":[[0,1.05,7.81],[1,1.04,7.81],[2,1.03,207.81]],"ltp":0.0,"tv":0.0,"id":31379},{"batb":[[0,1.05,7.81],[1,1.04,7.81],[2,1.03,207.81]],"ltp":0.0,"tv":0.0,"id":2219}]}]}
{"op":"mcm","clk":"11772266345","pt":1722767354163,"mc":[{"id":"1.231431360","rc":[{"batb":[[0,1.06,7.81],[1,1.05,7.81],[2,1.04,7.81]],"ltp":0.0,"tv":0.0,"id":31379},{"batb":[[0,1.06,7.81],[1,1.05,7.81],[2,1.04,7.81]],"ltp":0.0,"tv":0.0,"id":2219}]}]}
{"op":"mcm","clk":"11772267226","pt":1722767368379,"mc":[{"id":"1.231431360","rc":[{"batb":[[0,1.07,7.81],[1,1.06,7.81],[2,1.05,7.81]],"ltp":0.0,"tv":0.0,"id":31379},{"batb":[[0,1.07,7.81],[1,1.06,7.81],[2,1.05,7.81]],"ltp":0.0,"tv":0.0,"id":2219}]}]}
{"op":"mcm","clk":"11772268530","pt":1722767385592,"mc":[{"id":"1.231431360","rc":[{"batb":[[0,1.08,7.81],[1,1.07,7.81],[2,1.06,7.81]],"ltp":0.0,"tv":0.0,"id":31379},{"batb":[[0,1.08,7.81],[1,1.07,7.81],[2,1.06,7.81]],"ltp":0.0,"tv":0.0,"id":2219}]}]}
{"op":"mcm","clk":"11772274578","pt":1722767465007,"mc":[{"id":"1.231431360","marketDefinition":{"bspMarket":false,"turnInPlayEnabled":true,"persistenceEnabled":true,"marketBaseRate":5.0,"eventId":"33467055","eventTypeId":"4","numberOfWinners":1,"bettingType":"ODDS","marketType":"MATCH_ODDS","marketTime":"2024-08-07T10:00:00.000Z","suspendTime":"2024-08-07T10:00:00.000Z","bspReconciled":false,"complete":true,"inPlay":false,"crossMatching":true,"runnersVoidable":false,"numberOfActiveRunners":2,"betDelay":0,"status":"OPEN","runners":[{"status":"ACTIVE","sortPriority":1,"id":2219,"name":"Gloucestershire"},{"status":"ACTIVE","sortPriority":2,"id":31379,"name":"Sussex"}],"regulators":["MR_INT"],"countryCode":"GB","discountAllowed":true,"timezone":"GMT","openDate":"2024-08-07T10:00:00.000Z","version":6056050633,"name":"Match Odds","eventName":"Gloucestershire v Sussex"}}]}
{"op":"mcm","clk":"11772302006","pt":1722767780306,"mc":[{"id":"1.231431360","rc":[{"batb":[[0,1.09,95.17],[1,1.08,7.81],[2,1.07,7.81]],"ltp":0.0,"tv":0.0,"id":31379},{"batb":[[0,1.09,95.17],[1,1.08,7.81],[2,1.07,7.81]],"ltp":0.0,"tv":0.0,"id":2219}]}]}
{"op":"mcm","clk":"11772465343","pt":1722769580481,"mc":[{"id":"1.231431360","rc":[{"batb":[[0,1.08,7.81],[1,1.07,7.81],[2,1.06,7.81]],"ltp":0.0,"tv":0.0,"id":31379},{"batb":[[0,1.08,7.81],[1,1.07,7.81],[2,1.06,7.81]],"ltp":0.0,"tv":0.0,"id":2219}]}]}
{"op":"mcm","clk":"11772468805","pt":1722769610533,"mc":[{"id":"1.231431360","rc":[{"batb":[[0,1.09,95.17],[1,1.08,7.81],[2,1.07,7.81]],"ltp":0.0,"tv":0.0,"id":31379},{"batb":[[0,1.09,95.17],[1,1.08,7.81],[2,1.07,7.81]],"ltp":0.0,"tv":0.0,"id":2219}]}]}
{"op":"mcm","clk":"11772666547","pt":1722771410918,"mc":[{"id":"1.231431360","rc":[{"batb":[[0,1.08,7.81],[1,1.07,7.81],[2,1.06,7.81]],"ltp":0.0,"tv":0.0,"id":31379},{"batb":[[0,1.08,7.81],[1,1.07,7.81],[2,1.06,7.81]],"ltp":0.0,"tv":0.0,"id":2219}]}]}
{"op":"mcm","clk":"11772668623","pt":1722771428655,"mc":[{"id":"1.231431360","rc":[{"batb":[[0,1.09,95.17],[1,1.08,7.81],[2,1.07,7.81]],"ltp":0.0,"tv":0.0,"id":31379},{"batb":[[0,1.09,95.17],[1,1.08,7.81],[2,1.07,7.81]],"ltp":0.0,"tv":0.0,"id":2219}]}]}
{"op":"mcm","clk":"11772889846","pt":1722773229262,"mc":[{"id":"1.231431360","rc":[{"batb":[[0,1.08,7.81],[1,1.07,7.81],[2,1.06,7.81]],"ltp":0.0,"tv":0.0,"id":31379},{"batb":[[0,1.08,7.81],[1,1.07,7.81],[2,1.06,7.81]],"ltp":0.0,"tv":0.0,"id":2219}]}]}
{"op":"mcm","clk":"11772891910","pt":1722773243858,"mc":[{"id":"1.231431360","rc":[{"batb":[[0,1.09,95.17],[1,1.08,7.81],[2,1.07,7.81]],"ltp":0.0,"tv":0.0,"id":31379},{"batb":[[0,1.09,95.17],[1,1.08,7.81],[2,1.07,7.81]],"ltp":0.0,"tv":0.0,"id":2219}]}]}
{"op":"mcm","clk":"11773142987","pt":1722775044197,"mc":[{"id":"1.231431360","rc":[{"batb":[[0,1.08,7.81],[1,1.07,7.81],[2,1.06,7.81]],"ltp":0.0,"tv":0.0,"id":31379},{"batb":[[0,1.08,7.81],[1,1.07,7.81],[2,1.06,7.81]],"ltp":0.0,"tv":0.0,"id":2219}]}]}
{"op":"mcm","clk":"11773144041","pt":1722775051240,"mc":[{"id":"1.231431360","rc":[{"batb":[[0,1.09,95.17],[1,1.08,7.81],[2,1.07,7.81]],"ltp":0.0,"tv":0.0,"id":31379},{"batb":[[0,1.09,95.17],[1,1.08,7.81],[2,1.07,7.81]],"ltp":0.0,"tv":0.0,"id":2219}]}]}
{"op":"mcm","clk":"11773394790","pt":1722776851470,"mc":[{"id":"1.231431360","rc":[{"batb":[[0,1.08,7.81],[1,1.07,7.81],[2,1.06,7.81]],"ltp":0.0,"tv":0.0,"id":2219}]}]}
{"op":"mcm","clk":"11773394976","pt":1722776852727,"mc":[{"id":"1.231431360","rc":[{"batb":[[0,1.08,7.81],[1,1.07,7.81],[2,1.06,7.81]],"ltp":0.0,"tv":0.0,"id":31379}]}]}
{"op":"mcm","clk":"11773413393","pt":1722776971811,"mc":[{"id":"1.231431360","rc":[{"batb":[[0,1.09,95.17],[1,1.08,7.81],[2,1.07,7.81]],"ltp":0.0,"tv":0.0,"id":31379},{"batb":[[0,1.09,95.17],[1,1.08,7.81],[2,1.07,7.81]],"ltp":0.0,"tv":0.0,"id":2219}]}]}
{"op":"mcm","clk":"11773672169","pt":1722778772494,"mc":[{"id":"1.231431360","rc":[{"batb":[[0,1.08,7.81],[1,1.07,7.81],[2,1.06,7.81]],"ltp":0.0,"tv":0.0,"id":31379},{"batb":[[0,1.08,7.81],[1,1.07,7.81],[2,1.06,7.81]],"ltp":0.0,"tv":0.0,"id":2219}]}]}
{"op":"mcm","clk":"11773682708","pt":1722778849277,"mc":[{"id":"1.231431360","rc":[{"batb":[[0,1.09,95.17],[1,1.08,7.81],[2,1.07,7.81]],"ltp":0.0,"tv":0.0,"id":31379},{"batb":[[0,1.09,95.17],[1,1.08,7.81],[2,1.07,7.81]],"ltp":0.0,"tv":0.0,"id":2219}]}]}
{"op":"mcm","clk":"11773919640","pt":1722780649640,"mc":[{"id":"1.231431360","rc":[{"batb":[[0,1.08,7.81],[1,1.07,7.81],[2,1.06,7.81]],"ltp":0.0,"tv":0.0,"id":31379},{"batb":[[0,1.08,7.81],[1,1.07,7.81],[2,1.06,7.81]],"ltp":0.0,"tv":0.0,"id":2219}]}]}
{"op":"mcm","clk":"11773925462","pt":1722780687151,"mc":[{"id":"1.231431360","rc":[{"batb":[[0,1.09,95.17],[1,1.08,7.81],[2,1.07,7.81]],"ltp":0.0,"tv":0.0,"id":31379},{"batb":[[0,1.09,95.17],[1,1.08,7.81],[2,1.07,7.81]],"ltp":0.0,"tv":0.0,"id":2219}]}]}
{"op":"mcm","clk":"11774182391","pt":1722782487654,"mc":[{"id":"1.231431360","rc":[{"batb":[[0,1.08,7.81],[1,1.07,7.81],[2,1.06,7.81]],"ltp":0.0,"tv":0.0,"id":31379}]}]}
{"op":"mcm","clk":"11774182405","pt":1722782487750,"mc":[{"id":"1.231431360","rc":[{"batb":[[0,1.08,7.81],[1,1.07,7.81],[2,1.06,7.81]],"ltp":0.0,"tv":0.0,"id":2219}]}]}
{"op":"mcm","clk":"11774208011","pt":1722782602801,"mc":[{"id":"1.231431360","rc":[{"batb":[[0,1.09,95.17],[1,1.08,7.81],[2,1.07,7.81]],"ltp":0.0,"tv":0.0,"id":31379},{"batb":[[0,1.09,95.17],[1,1.08,7.81],[2,1.07,7.81]],"ltp":0.0,"tv":0.0,"id":2219}]}]}
{"op":"mcm","clk":"11774461813","pt":1722784403435,"mc":[{"id":"1.231431360","rc":[{"batb":[[0,1.08,7.81],[1,1.07,7.81],[2,1.06,7.81]],"ltp":0.0,"tv":0.0,"id":31379},{"batb":[[0,1.08,7.81],[1,1.07,7.81],[2,1.06,7.81]],"ltp":0.0,"tv":0.0,"id":2219}]}]}
{"op":"mcm","clk":"11774470353","pt":1722784453767,"mc":[{"id":"1.231431360","rc":[{"batb":[[0,1.09,95.17],[1,1.08,7.81],[2,1.07,7.81]],"ltp":0.0,"tv":0.0,"id":31379},{"batb":[[0,1.09,95.17],[1,1.08,7.81],[2,1.07,7.81]],"ltp":0.0,"tv":0.0,"id":2219}]}]}
{"op":"mcm","clk":"11774753440","pt":1722786254373,"mc":[{"id":"1.231431360","rc":[{"batb":[[0,1.08,7.81],[1,1.07,7.81],[2,1.06,7.81]],"ltp":0.0,"tv":0.0,"id":31379},{"batb":[[0,1.08,7.81],[1,1.07,7.81],[2,1.06,7.81]],"ltp":0.0,"tv":0.0,"id":2219}]}]}
{"op":"mcm","clk":"11774753883","pt":1722786257288,"mc":[{"id":"1.231431360","rc":[{"batb":[[0,1.09,95.17],[1,1.08,7.81],[2,1.07,7.81]],"ltp":0.0,"tv":0.0,"id":31379},{"batb":[[0,1.09,95.17],[1,1.08,7.81],[2,1.07,7.81]],"ltp":0.0,"tv":0.0,"id":2219}]}]}
{"op":"mcm","clk":"11775009893","pt":1722788058996,"mc":[{"id":"1.231431360","rc":[{"batb":[[0,1.08,7.81],[1,1.07,7.81],[2,1.06,7.81]],"ltp":0.0,"tv":0.0,"id":31379},{"batb":[[0,1.08,7.81],[1,1.07,7.81],[2,1.06,7.81]],"ltp":0.0,"tv":0.0,"id":2219}]}]}
{"op":"mcm","clk":"11775020620","pt":1722788138730,"mc":[{"id":"1.231431360","rc":[{"batb":[[0,1.09,95.17],[1,1.08,7.81],[2,1.07,7.81]],"ltp":0.0,"tv":0.0,"id":31379},{"batb":[[0,1.09,95.17],[1,1.08,7.81],[2,1.07,7.81]],"ltp":0.0,"tv":0.0,"id":2219}]}]}
{"op":"mcm","clk":"11775266076","pt":1722789939449,"mc":[{"id":"1.231431360","rc":[{"batb":[[0,1.08,7.81],[1,1.07,7.81],[2,1.06,7.81]],"ltp":0.0,"tv":0.0,"id":31379},{"batb":[[0,1.08,7.81],[1,1.07,7.81],[2,1.06,7.81]],"ltp":0.0,"tv":0.0,"id":2219}]}]}
{"op":"mcm","clk":"11775270862","pt":1722789972844,"mc":[{"id":"1.231431360","rc":[{"batb":[[0,1.09,95.17],[1,1.08,7.81],[2,1.07,7.81]],"ltp":0.0,"tv":0.0,"id":31379},{"batb":[[0,1.09,95.17],[1,1.08,7.81],[2,1.07,7.81]],"ltp":0.0,"tv":0.0,"id":2219}]}]}
{"op":"mcm","clk":"11775506013","pt":1722791773252,"mc":[{"id":"1.231431360","rc":[{"batb":[[0,1.08,7.81],[1,1.07,7.81],[2,1.06,7.81]],"ltp":0.0,"tv":0.0,"id":31379},{"batb":[[0,1.08,7.81],[1,1.07,7.81],[2,1.06,7.81]],"ltp":0.0,"tv":0.0,"id":2219}]}]}
{"op":"mcm","clk":"11775512923","pt":1722791817522,"mc":[{"id":"1.231431360","rc":[{"batb":[[0,1.09,95.17],[1,1.08,7.81],[2,1.07,7.81]],"ltp":0.0,"tv":0.0,"id":31379},{"batb":[[0,1.09,95.17],[1,1.08,7.81],[2,1.07,7.81]],"ltp":0.0,"tv":0.0,"id":2219}]}]}
{"op":"mcm","clk":"11775784959","pt":1722793617297,"mc":[{"id":"1.231431360","rc":[{"batb":[[0,1.38,131.58],[1,1.33,151.52],[2,1.28,178.57]],"ltp":0.0,"tv":0.0,"id":31379},{"batb":[[0,1.38,131.58],[1,1.33,151.52],[2,1.28,178.57]],"ltp":0.0,"tv":0.0,"id":2219}]}]}
{"op":"mcm","clk":"11775792261","pt":1722793666946,"mc":[{"id":"1.231431360","rc":[{"batb":[[0,1.39,21.96],[1,1.38,131.58],[2,1.33,151.52]],"ltp":0.0,"tv":0.0,"id":31379},{"batb":[[0,1.39,21.96],[1,1.38,131.58],[2,1.33,151.52]],"ltp":0.0,"tv":0.0,"id":2219}]}]}
{"op":"mcm","clk":"11775979739","pt":1722794927470,"mc":[{"id":"1.231431360","rc":[{"batb":[[0,2.08,4.1],[1,1.39,21.96],[2,1.38,131.58]],"ltp":0.0,"tv":0.0,"id":31379},{"batb":[[0,1.84,5.27],[1,1.39,21.96],[2,1.38,131.58]],"ltp":0.0,"tv":0.0,"id":2219}]}]}
{"op":"mcm","clk":"11776086544","pt":1722795467537,"mc":[{"id":"1.231431360","rc":[{"batb":[[1,1.38,131.58],[2,1.33,151.52]],"ltp":0.0,"tv":0.0,"id":31379},{"batb":[[1,1.38,131.58],[2,1.33,151.52]],"ltp":0.0,"tv":0.0,"id":2219}]}]}
{"op":"mcm","clk":"11778188511","pt":1722813175095,"mc":[{"id":"1.231431360","rc":[{"batb":[[1,1.44,272],[2,1.38,131.58]],"ltp":0.0,"tv":0.0,"id":31379}]}]}
{"op":"mcm","clk":"11778287150","pt":1722814508293,"mc":[{"id":"1.231431360","rc":[{"batb":[[1,1.45,13.55],[2,1.44,272]],"ltp":0.0,"tv":0.0,"id":31379},{"batl":[[0,3.25,6.04]],"ltp":0.0,"tv":0.0,"id":2219}]}]}
{"op":"mcm","clk":"11778292891","pt":1722814585342,"mc":[{"id":"1.231431360","rc":[{"batb":[[1,1.46,272],[2,1.45,13.55]],"ltp":0.0,"tv":0.0,"id":31379}]}]}
{"op":"mcm","clk":"11778292966","pt":1722814586475,"mc":[{"id":"1.231431360","rc":[{"batb":[[2,1.38,131.58]],"ltp":0.0,"tv":0.0,"id":31379}]}]}
{"op":"mcm","clk":"11778381607","pt":1722815907803,"mc":[{"id":"1.231431360","rc":[{"batb":[[1,1.47,13.55],[2,1.46,272]],"ltp":0.0,"tv":0.0,"id":31379},{"batl":[[0,3.15,6.31]],"ltp":0.0,"tv":0.0,"id":2219}]}]}
{"op":"mcm","clk":"11778657203","pt":1722820374949,"mc":[{"id":"1.231431360","rc":[{"batb":[[1,1.47,13.58]],"ltp":0.0,"tv":0.0,"id":31379},{"batl":[[0,3.15,6.32]],"ltp":0.0,"tv":0.0,"id":2219}]}]}
{"op":"mcm","clk":"11778820633","pt":1722823170114,"mc":[{"id":"1.231431360","rc":[{"batb":[[0,1.47,13.58],[1,1.46,272],[2,1.38,131.58]],"ltp":0.0,"tv":0.0,"id":31379},{"batb":[[0,1.38,131.58],[1,1.33,151.52],[2,1.28,178.57]],"ltp":0.0,"tv":0.0,"id":2219}]}]}
{"op":"mcm","clk":"11778821723","pt":1722823192538,"mc":[{"id":"1.231431360","rc":[{"batb":[[0,1.48,17.88],[1,1.47,13.58],[2,1.46,272]],"ltp":0.0,"tv":0.0,"id":31379},{"batb":[[0,1.39,22.01],[1,1.38,131.58],[2,1.33,151.52]],"ltp":0.0,"tv":0.0,"id":2219}]}]}
{"op":"mcm","clk":"11778821776","pt":1722823193870,"mc":[{"id":"1.231431360","rc":[{"batb":[[1,1.46,272],[2,1.38,131.58]],"ltp":0.0,"tv":0.0,"id":31379}]}]}
{"op":"mcm","clk":"11778870973","pt":1722824505660,"mc":[{"id":"1.231431360","rc":[{"batb":[[0,1.48,17.88],[1,1.47,7.48],[2,1.46,272]],"ltp":0.0,"tv":0.0,"id":31379},{"batb":[[0,1.39,28.59]],"batl":[[0,3.15,6.32]],"ltp":0.0,"tv":0.0,"id":2219}]}]}
{"op":"mcm","clk":"11778888746","pt":1722824993068,"mc":[{"id":"1.231431360","rc":[{"batb":[[0,1.47,7.48],[1,1.46,272],[2,1.38,131.58]],"ltp":0.0,"tv":0.0,"id":31379},{"batb":[[0,1.39,6.58]],"ltp":0.0,"tv":0.0,"id":2219}]}]}
{"op":"mcm","clk":"11778888777","pt":1722824994090,"mc":[{"id":"1.231431360","rc":[{"batb":[[0,1.47,21.88]],"ltp":0.0,"tv":0.0,"id":31379}]}]}
{"op":"mcm","clk":"11778890905","pt":1722825041810,"mc":[{"id":"1.231431360","rc":[{"batb":[[0,1.48,17.88],[1,1.47,21.88],[2,1.46,272]],"ltp":0.0,"tv":0.0,"id":31379},{"batb":[[0,1.4,21.45],[1,1.39,6.58],[2,1.38,131.58]],"ltp":0.0,"tv":0.0,"id":2219}]}]}
{"op":"mcm","clk":"11778890976","pt":1722825043450,"mc":[{"id":"1.231431360","rc":[{"batb":[[1,1.47,7.48]],"ltp":0.0,"tv":0.0,"id":31379}]}]}
{"op":"mcm","clk":"11778891061","pt":1722825045414,"mc":[{"id":"1.231431360","rc":[{"batl":[[0,3.15,6.1]],"ltp":0.0,"tv":0.0,"id":2219}]}]}
{"op":"mcm","clk":"11778904576","pt":1722825361168,"mc":[{"id":"1.231431360","rc":[{"batb":[[0,2.08,4.1],[1,1.48,17.88],[2,1.47,7.48]],"ltp":0.0,"tv":0.0,"id":31379},{"batb":[[0,1.84,5.27],[1,1.4,21.45],[2,1.39,6.58]],"ltp":0.0,"tv":0.0,"id":2219}]}]}
{"op":"mcm","clk":"11778937192","pt":1722826038234,"mc":[{"id":"1.231431360","rc":[{"batb":[[2,1.46,272]],"ltp":0.0,"tv":0.0,"id":31379},{"batb":[[2,1.38,131.58]],"ltp":0.0,"tv":0.0,"id":2219}]}]}
{"op":"mcm","clk":"11778971614","pt":1722826842240,"mc":[{"id":"1.231431360","rc":[{"batb":[[1,1.46,272],[2,1.38,131.58]],"ltp":0.0,"tv":0.0,"id":31379},{"batb":[[1,1.38,131.58],[2,1.33,151.52]],"ltp":0.0,"tv":0.0,"id":2219}]}]}
{"op":"mcm","clk":"11778972013","pt":1722826852422,"mc":[{"id":"1.231431360","rc":[{"batb":[[1,1.47,13.56],[2,1.46,272]],"ltp":0.0,"tv":0.0,"id":31379},{"batl":[[0,3.15,6.31]],"ltp":0.0,"tv":0.0,"id":2219}]}]}
{"op":"mcm","clk":"11779149545","pt":1722831174952,"mc":[{"id":"1.231431360","rc":[{"batb":[[1,1.47,13.57]],"ltp":0.0,"tv":0.0,"id":31379},{"batl":[[0,3.15,6.31]],"ltp":0.0,"tv":0.0,"id":2219}]}]}
{"op":"mcm","clk":"11779563942","pt":1722841974942,"mc":[{"id":"1.231431360","rc":[{"batb":[[1,1.47,13.6]],"ltp":0.0,"tv":0.0,"id":31379},{"batl":[[0,3.15,6.33]],"ltp":0.0,"tv":0.0,"id":2219}]}]}
{"op":"mcm","clk":"11779686018","pt":1722847374920,"mc":[{"id":"1.231431360","rc":[{"batb":[[1,1.47,13.6]],"ltp":0.0,"tv":0.0,"id":31379},{"batl":[[0,3.15,6.32]],"ltp":0.0,"tv":0.0,"id":2219}]}]}
{"op":"mcm","clk":"11779813088","pt":1722851145183,"mc":[{"id":"1.231431360","rc":[{"batb":[[1,1.47,13.63]],"ltp":0.0,"tv":0.0,"id":31379},{"batb":[[0,1.85,7.69],[1,1.84,5.27],[2,1.38,131.58]],"batl":[[0,3.15,6.34]],"ltp":0.0,"tv":0.0,"id":2219}]}]}
{"op":"mcm","clk":"11779815103","pt":1722851192464,"mc":[{"id":"1.231431360","rc":[{"batb":[[0,1.86,3.84],[1,1.85,7.69],[2,1.84,5.27]],"ltp":0.0,"tv":0.0,"id":2219}]}]}
{"op":"mcm","clk":"11779845538","pt":1722852002433,"mc":[{"id":"1.231431360","rc":[{"batb":[[0,2.08,41.06]],"ltp":0.0,"tv":0.0,"id":31379},{"batb":[[2,1.84,52.79]],"ltp":0.0,"tv":0.0,"id":2219}]}]}
{"op":"mcm","clk":"11779845612","pt":1722852003830,"mc":[{"id":"1.231431360","rc":[{"batb":[[1,1.46,272],[2,1.38,131.58]],"ltp":0.0,"tv":0.0,"id":31379}]}]}
{"op":"mcm","clk":"11779881928","pt":1722852774882,"mc":[{"id":"1.231431360","rc":[{"batb":[[0,1.86,3.85],[1,1.85,7.7]],"ltp":0.0,"tv":0.0,"id":2219}]}]}
{"op":"mcm","clk":"11780125182","pt":1722858174904,"mc":[{"id":"1.231431360","rc":[{"batb":[[0,1.86,3.85],[1,1.85,7.7]],"ltp":0.0,"tv":0.0,"id":2219}]}]}
{"op":"mcm","clk":"11780344890","pt":1722863574944,"mc":[{"id":"1.231431360","rc":[{"batb":[[0,1.86,3.85],[1,1.85,7.7]],"ltp":0.0,"tv":0.0,"id":2219}]}]}
{"op":"mcm","clk":"11780486988","pt":1722867709758,"mc":[{"id":"1.231431360","rc":[{"batb":[[0,2.08,35.54]],"ltp":0.0,"tv":0.0,"id":31379},{"batb":[[0,1.86,3.84],[1,1.85,7.68],[2,1.84,45.7]],"ltp":0.0,"tv":0.0,"id":2219}]}]}
{"op":"mcm","clk":"11780833347","pt":1722874374923,"mc":[{"id":"1.231431360","rc":[{"batb":[[0,1.86,3.84],[1,1.85,7.68]],"ltp":0.0,"tv":0.0,"id":2219}]}]}
{"op":"mcm","clk":"11781117331","pt":1722878092039,"mc":[{"id":"1.231431360","rc":[{"batb":[[0,1.86,3.84],[1,1.85,7.68]],"ltp":0.0,"tv":0.0,"id":2219}]}]}
{"op":"mcm","clk":"11781117771","pt":1722878097237,"mc":[{"id":"1.231431360","rc":[{"batb":[[2,1.33,151.52]],"ltp":0.0,"tv":0.0,"id":31379}]}]}
{"op":"mcm","clk":"11781406233","pt":1722881430078,"mc":[{"id":"1.231431360","rc":[{"batb":[[0,1.86,3.84],[1,1.85,7.69]],"ltp":0.0,"tv":0.0,"id":2219}]}]}
{"op":"mcm","clk":"11781406679","pt":1722881434258,"mc":[{"id":"1.231431360","rc":[{"batb":[[2,1.38,131.58]],"ltp":0.0,"tv":0.0,"id":31379}]}]}
{"op":"mcm","clk":"11781623261","pt":1722883711409,"mc":[{"id":"1.231431360","rc":[{"batb":[[1,1.74,17.32],[2,1.46,272]],"ltp":0.0,"tv":0.0,"id":31379}]}]}
{"op":"mcm","clk":"11781649416","pt":1722884097157,"mc":[{"id":"1.231431360","rc":[{"batl":[[0,1.92,30.34]],"ltp":0.0,"tv":0.0,"id":2219}]}]}
{"op":"mcm","clk":"11781731435","pt":1722885174889,"mc":[{"id":"1.231431360","rc":[{"batb":[[0,1.86,3.84],[1,1.85,7.69]],"ltp":0.0,"tv":0.0,"id":2219}]}]}
{"op":"mcm","clk":"11782101466","pt":1722890574905,"mc":[{"id":"1.231431360","rc":[{"batb":[[0,1.86,3.84],[1,1.85,7.68]],"ltp":0.0,"tv":0.0,"id":2219}]}]}
{"op":"mcm","clk":"11782177968","pt":1722892119399,"mc":[{"id":"1.231431360","rc":[{"batb":[[0,1.86,3.84],[1,1.85,7.68]],"ltp":0.0,"tv":0.0,"id":2219}]}]}
{"op":"mcm","clk":"11782382884","pt":1722895974895,"mc":[{"id":"1.231431360","rc":[{"batb":[[0,1.86,3.84],[1,1.85,7.68]],"ltp":0.0,"tv":0.0,"id":2219}]}]}
{"op":"mcm","clk":"11782711206","pt":1722901374918,"mc":[{"id":"1.231431360","rc":[{"batb":[[0,1.86,3.84],[1,1.85,7.67]],"ltp":0.0,"tv":0.0,"id":2219}]}]}
{"op":"mcm","clk":"11782943344","pt":1722906774924,"mc":[{"id":"1.231431360","rc":[{"batb":[[0,1.86,3.83],[1,1.85,7.66]],"ltp":0.0,"tv":0.0,"id":2219}]}]}
{"op":"mcm","clk":"11783133514","pt":1722912174915,"mc":[{"id":"1.231431360","rc":[{"batb":[[0,1.86,3.83],[1,1.85,7.66]],"ltp":0.0,"tv":0.0,"id":2219}]}]}
{"op":"mcm","clk":"11783261499","pt":1722917574926,"mc":[{"id":"1.231431360","rc":[{"batb":[[0,1.86,3.83],[1,1.85,7.67]],"ltp":0.0,"tv":0.0,"id":2219}]}]}
{"op":"mcm","clk":"11783424029","pt":1722922974920,"mc":[{"id":"1.231431360","rc":[{"batb":[[0,1.86,3.84],[1,1.85,7.67]],"ltp":0.0,"tv":0.0,"id":2219}]}]}
{"op":"mcm","clk":"11783604436","pt":1722928374893,"mc":[{"id":"1.231431360","rc":[{"batb":[[0,1.86,3.84],[1,1.85,7.68]],"ltp":0.0,"tv":0.0,"id":2219}]}]}
{"op":"mcm","clk":"11783747563","pt":1722933140824,"mc":[{"id":"1.231431360","rc":[{"batb":[[0,1.86,3.85],[1,1.85,7.69]],"ltp":0.0,"tv":0.0,"id":2219}]}]}
{"op":"mcm","clk":"11783886625","pt":1722937302541,"mc":[{"id":"1.231431360","rc":[{"batb":[[0,1.86,3.85],[1,1.85,7.7]],"ltp":0.0,"tv":0.0,"id":2219}]}]}
{"op":"mcm","clk":"11783966897","pt":1722939089940,"mc":[{"id":"1.231431360","rc":[{"batb":[[0,1.74,17.32],[1,1.46,272],[2,1.25,100]],"ltp":0.0,"tv":0.0,"id":31379},{"batb":[[0,1.86,3.86],[1,1.85,7.71],[2,1.74,17.32]],"ltp":0.0,"tv":0.0,"id":2219}]}]}
{"op":"mcm","clk":"11783968006","pt":1722939114750,"mc":[{"id":"1.231431360","rc":[{"batb":[[0,1.75,67.91],[1,1.74,17.32],[2,1.46,272]],"ltp":0.0,"tv":0.0,"id":31379}]}]}
{"op":"mcm","clk":"11784019579","pt":1722940187523,"mc":[{"id":"1.231431360","rc":[{"batb":[[0,1.74,17.32],[1,1.46,272],[2,1.25,100]],"ltp":0.0,"tv":0.0,"id":31379}]}]}
{"op":"mcm","clk":"11784019587","pt":1722940187727,"mc":[{"id":"1.231431360","rc":[{"batb":[[0,1.75,44.09],[1,1.74,17.32],[2,1.46,272]],"ltp":0.0,"tv":0.0,"id":31379}]}]}
{"op":"mcm","clk":"11784043530","pt":1722940775947,"mc":[{"id":"1.231431360","rc":[{"batb":[[0,1.74,17.32],[1,1.46,272],[2,1.25,100]],"ltp":0.0,"tv":0.0,"id":31379}]}]}
{"op":"mcm","clk":"11784043577","pt":1722940776963,"mc":[{"id":"1.231431360","rc":[{"batb":[[0,1.75,68.54],[1,1.74,17.32],[2,1.46,272]],"ltp":0.0,"tv":0.0,"id":31379}]}]}
{"op":"mcm","clk":"11784045046","pt":1722940811079,"mc":[{"id":"1.231431360","rc":[{"batb":[[0,2,8.06],[1,1.75,68.54],[2,1.74,17.32]],"ltp":0.0,"tv":0.0,"id":31379},{"batb":[[2,1.77,9.11]],"ltp":0.0,"tv":0.0,"id":2219}]}]}
{"op":"mcm","clk":"11784045291","pt":1722940816208,"mc":[{"id":"1.231431360","rc":[{"batb":[[2,1.75,9.2]],"ltp":0.0,"tv":0.0,"id":2219}]}]}
{"op":"mcm","clk":"11784048871","pt":1722940897972,"mc":[{"id":"1.231431360","rc":[{"batb":[[1,1.74,17.32],[2,1.46,272]],"ltp":0.0,"tv":0.0,"id":31379}]}]}
{"op":"mcm","clk":"11784056110","pt":1722941071419,"mc":[{"id":"1.231431360","rc":[{"batb":[[0,2.08,35.54],[1,2,8.06],[2,1.74,17.32]],"ltp":0.0,"tv":0.0,"id":31379},{"batb":[[2,1.84,45.7]],"ltp":0.0,"tv":0.0,"id":2219}]}]}
{"op":"mcm","clk":"11784057006","pt":1722941088446,"mc":[{"id":"1.231431360","rc":[{"batb":[[1,2.04,7.92]],"ltp":0.0,"tv":0.0,"id":31379}]}]}
{"op":"mcm","clk":"11784120374","pt":1722942578296,"mc":[{"id":"1.231431360","rc":[{"batb":[[0,2.14,38.68],[1,2.08,35.54],[2,2.04,7.94]],"ltp":0.0,"tv":0.0,"id":31379},{"batb":[[0,1.86,3.86],[1,1.85,7.73]],"ltp":0.0,"tv":0.0,"id":2219}]}]}
{"op":"mcm","clk":"11784120584","pt":1722942583535,"mc":[{"id":"1.231431360","rc":[{"batb":[[1,2.04,7.94],[2,1.74,17.32]],"ltp":0.0,"tv":0.0,"id":31379},{"batb":[[2,1.74,17.32]],"ltp":0.0,"tv":0.0,"id":2219}]}]}
{"op":"mcm","clk":"11784121144","pt":1722942598756,"mc":[{"id":"1.231431360","rc":[{"batb":[[1,1.74,17.32],[2,1.46,272]],"ltp":0.0,"tv":0.0,"id":31379}]}]}
{"op":"mcm","clk":"11784298316","pt":1722946447286,"mc":[{"id":"1.231431360","rc":[{"batb":[[2,1.25,100]],"ltp":0.0,"tv":0.0,"id":31379},{"batb":[[0,1.86,3.86],[1,1.85,7.72]],"ltp":0.0,"tv":0.0,"id":2219}]}]}
{"op":"mcm","clk":"11784490340","pt":1722949974885,"mc":[{"id":"1.231431360","rc":[{"batb":[[0,1.86,3.87],[1,1.85,7.73]],"ltp":0.0,"tv":0.0,"id":2219}]}]}
{"op":"mcm","clk":"11784517143","pt":1722950411707,"mc":[{"id":"1.231431360","rc":[{"trd":[[1.85,15.46],[1.86,7.74]],"batb":[[0,1.74,17.32],[1,1.25,100],[2,1.08,7.89]],"batl":[[0,1.8,88.4]],"ltp":1.85,"tv":23.19,"id":2219}],"tv":23.19}]}
{"op":"mcm","clk":"11784517303","pt":1722950415009,"mc":[{"id":"1.231431360","rc":[{"batb":[[1,2.08,35.54],[2,1.74,17.32]],"ltp":0.0,"tv":0.0,"id":31379}]}]}
{"op":"mcm","clk":"11784519715","pt":1722950465284,"mc":[{"id":"1.231431360","rc":[{"batb":[[0,1.84,45.7],[1,1.74,17.32],[2,1.25,100]],"ltp":1.85,"tv":23.19,"id":2219}]}]}
{"op":"mcm","clk":"11784521448","pt":1722950500919,"mc":[{"id":"1.231431360","rc":[{"trd":[[1.84,91.4]],"batb":[[0,1.74,17.32],[1,1.25,100],[2,1.08,7.89]],"batl":[[0,1.8,24.3]],"ltp":1.84,"tv":114.59,"id":2219}],"tv":114.59}]}
{"op":"mcm","clk":"11784521695","pt":1722950505414,"mc":[{"id":"1.231431360","rc":[{"batb":[[0,1.8,47.98],[1,1.74,17.32],[2,1.25,100]],"ltp":1.84,"tv":114.59,"id":2219}]}]}
{"op":"mcm","clk":"11784615874","pt":1722952266496,"mc":[{"id":"1.231431360","rc":[{"trd":[[1.74,34.64],[1.8,95.96]],"batb":[[0,1.25,100],[1,1.08,7.89],[2,1.07,7.89]],"batl":[[0,1.7,234.7]],"ltp":1.74,"tv":245.19,"id":2219}],"tv":245.19}]}
{"op":"mcm","clk":"11784615898","pt":1722952266782,"mc":[{"id":"1.231431360","rc":[{"batb":[[0,1.29,183.96],[1,1.25,100],[2,1.08,7.89]],"ltp":1.74,"tv":245.19,"id":2219}]}]}
{"op":"mcm","clk":"11784616312","pt":1722952273297,"mc":[{"id":"1.231431360","rc":[{"batb":[[0,1.76,50.51],[1,1.29,183.96],[2,1.25,100]],"ltp":1.74,"tv":245.19,"id":2219}]}]}
{"op":"mcm","clk":"11784616516","pt":1722952275890,"mc":[{"id":"1.231431360","rc":[{"trd":[[1.76,101.02]],"batb":[[0,1.29,183.96],[1,1.25,100],[2,1.08,7.89]],"batl":[[0,1.7,49.49]],"ltp":1.76,"tv":346.21,"id":2219}],"tv":346.21}]}
{"op":"mcm","clk":"11784617127","pt":1722952285820,"mc":[{"id":"1.231431360","rc":[{"batl":[[1,1.71,200]],"ltp":1.76,"tv":346.21,"id":2219}]}]}
{"op":"mcm","clk":"11784617359","pt":1722952289512,"mc":[{"id":"1.231431360","rc":[{"batl":[[2,1.72,300]],"ltp":1.76,"tv":346.21,"id":2219}]}]}
{"op":"mcm","clk":"11784624415","pt":1722952405059,"mc":[{"id":"1.231431360","rc":[{"trd":[[1.7,38.04]],"batl":[[0,1.7,30.47]],"ltp":1.7,"tv":384.25,"id":2219}],"tv":384.25}]}
{"op":"mcm","clk":"11784625514","pt":1722952422786,"mc":[{"id":"1.231431360","rc":[{"batl":[[0,1.7,65.01]],"ltp":1.7,"tv":384.25,"id":2219}]}]}
{"op":"mcm","clk":"11784627834","pt":1722952460607,"mc":[{"id":"1.231431360","rc":[{"batl":[[0,1.69,78.74],[1,1.7,65.01],[2,1.71,200]],"ltp":1.7,"tv":384.25,"id":2219}]}]}
{"op":"mcm","clk":"11784627916","pt":1722952462042,"mc":[{"id":"1.231431360","rc":[{"trd":[[1.69,70.54]],"batl":[[0,1.7,65.01],[1,1.71,200],[2,1.72,300]],"ltp":1.69,"tv":454.79,"id":2219}],"tv":454.79}]}
{"op":"mcm","clk":"11784628171","pt":1722952466149,"mc":[{"id":"1.231431360","rc":[{"batl":[[0,1.69,158.45],[1,1.7,65.01],[2,1.71,200]],"ltp":1.69,"tv":454.79,"id":2219}]}]}
{"op":"mcm","clk":"11784631400","pt":1722952515562,"mc":[{"id":"1.231431360","rc":[{"trd":[[1.69,97.48]],"batl":[[0,1.69,144.98]],"ltp":1.69,"tv":481.73,"id":2219}],"tv":481.73}]}
{"op":"mcm","clk":"11784631416","pt":1722952515764,"mc":[{"id":"1.231431360","rc":[{"batl":[[0,1.7,65.01],[1,1.71,200],[2,1.72,300]],"ltp":1.69,"tv":481.73,"id":2219}]}]}
{"op":"mcm","clk":"11784632265","pt":1722952530315,"mc":[{"id":"1.231431360","rc":[{"batl":[[0,1.69,17.27],[1,1.7,65.01],[2,1.71,200]],"ltp":1.69,"tv":481.73,"id":2219}]}]}
{"op":"mcm","clk":"11784633523","pt":1722952551931,"mc":[{"id":"1.231431360","rc":[{"trd":[[1.69,123]],"batl":[[0,1.69,4.51]],"ltp":1.69,"tv":507.25,"id":2219}],"tv":507.25}]}
{"op":"mcm","clk":"11784633655","pt":1722952553892,"mc":[{"id":"1.231431360","rc":[{"trd":[[1.69,132.02]],"batb":[[0,1.29,184.84]],"batl":[[0,1.7,65.01],[1,1.71,200],[2,1.72,300]],"ltp":1.69,"tv":516.27,"id":2219}],"tv":516.27}]}
{"op":"mcm","clk":"11784635737","pt":1722952587780,"mc":[{"id":"1.231431360","rc":[{"trd":[[1.7,48.24]],"batl":[[0,1.7,59.91]],"ltp":1.7,"tv":526.47,"id":2219}],"tv":526.47}]}
{"op":"mcm","clk":"11784638239","pt":1722952625930,"mc":[{"id":"1.231431360","rc":[{"trd":[[1.7,157.36]],"batl":[[0,1.7,5.35]],"ltp":1.7,"tv":635.59,"id":2219}],"tv":635.59}]}
{"op":"mcm","clk":"11784645669","pt":1722952742596,"mc":[{"id":"1.231431360","rc":[{"trd":[[1.7,168.06]],"batb":[[0,1.7,13.4],[1,1.29,184.84],[2,1.25,100]],"batl":[[0,1.71,200],[1,1.72,300],[2,1.73,400]],"ltp":1.7,"tv":646.29,"id":2219}],"tv":646.29}]}
{"op":"mcm","clk":"11784645690","pt":1722952742796,"mc":[{"id":"1.231431360","rc":[{"trd":[[1.7,194.36]],"batb":[[0,1.69,1.13],[1,1.29,183.96]],"ltp":1.7,"tv":672.59,"id":2219}],"tv":672.59}]}
{"op":"mcm","clk":"11784645785","pt":1722952743998,"mc":[{"id":"1.231431360","rc":[{"trd":[[1.69,133.74],[1.7,194.86],[1.71,10.66]],"batb":[[0,1.29,183.98],[1,1.25,100],[2,1.08,7.89]],"batl":[[0,1.71,194.67]],"ltp":1.71,"tv":685.47,"id":2219}],"tv":685.47}]}
{"op":"mcm","clk":"11784647723","pt":1722952772926,"mc":[{"id":"1.231431360","rc":[{"batl":[[0,1.71,907.93]],"ltp":1.71,"tv":685.47,"id":2219}]}]}
{"op":"mcm","clk":"11784649121","pt":1722952797044,"mc":[{"id":"1.231431360","rc":[{"trd":[[1.71,20.5]],"batl":[[0,1.71,903.01]],"ltp":1.71,"tv":695.31,"id":2219}],"tv":695.31}]}
{"op":"mcm","clk":"11784660040","pt":1722952945307,"mc":[{"id":"1.231431360","rc":[{"batb":[[0,2.42,6.2],[1,2.14,38.68],[2,2.08,35.54]],"ltp":0.0,"tv":0.0,"id":31379},{"trd":[[1.69,133.79],[1.7,194.8],[1.85,15.45],[1.86,7.73]],"batb":[[0,1.3,6.87],[1,1.29,183.96],[2,1.25,100]],"ltp":1.71,"tv":695.29,"id":2219}],"tv":695.29}]}
{"op":"mcm","clk":"11784661218","pt":1722952959663,"mc":[{"id":"1.231431360","rc":[{"trd":[[1.71,28.78]],"batb":[[1,1.25,100],[2,1.08,7.88]],"batl":[[0,1.71,185.61]],"ltp":1.71,"tv":703.57,"id":2219}],"tv":703.57}]}
{"op":"mcm","clk":"11784661230","pt":1722952959723,"mc":[{"id":"1.231431360","rc":[{"batb":[[0,1.31,179.84],[1,1.3,6.85],[2,1.25,100]],"ltp":1.71,"tv":703.57,"id":2219}]}]}
{"op":"mcm","clk":"11784662301","pt":1722952973754,"mc":[{"id":"1.231431360","rc":[{"trd":[[1.71,49.24]],"batl":[[0,1.71,175.38]],"ltp":1.71,"tv":724.03,"id":2219}],"tv":724.03}]}
{"op":"mcm","clk":"11784666596","pt":1722953041422,"mc":[{"id":"1.231431360","rc":[{"trd":[[1.71,69.7]],"batl":[[0,1.71,165.15]],"ltp":1.71,"tv":744.49,"id":2219}],"tv":744.49}]}
{"op":"mcm","clk":"11784667666","pt":1722953060143,"mc":[{"id":"1.231431360","rc":[{"batl":[[0,1.7,8.54],[1,1.71,165.15],[2,1.72,300]],"ltp":1.71,"tv":744.49,"id":2219}]}]}
{"op":"mcm","clk":"11784670313","pt":1722953102506,"mc":[{"id":"1.231431360","rc":[{"trd":[[1.7,211.88],[1.71,73.08]],"batl":[[0,1.71,163.46],[1,1.72,300],[2,1.73,400]],"ltp":1.71,"tv":764.95,"id":2219}],"tv":764.95}]}
{"op":"mcm","clk":"11784670441","pt":1722953104516,"mc":[{"id":"1.231431360","rc":[{"batb":[[0,1.32,11.02],[1,1.31,179.82],[2,1.3,6.85]],"ltp":1.71,"tv":764.95,"id":2219}]}]}
{"op":"mcm","clk":"11784672849","pt":1722953144242,"mc":[{"id":"1.231431360","rc":[{"trd":[[1.71,83.74]],"batb":[[0,1.34,175.78],[1,1.32,11]],"batl":[[0,1.71,158.13]],"ltp":1.71,"tv":775.61,"id":2219}],"tv":775.61}]}
{"op":"mcm","clk":"11784672978","pt":1722953146150,"mc":[{"id":"1.231431360","rc":[{"batb":[[0,1.35,10.77],[1,1.34,175.76]],"ltp":1.71,"tv":775.61,"id":2219}]}]}
{"op":"mcm","clk":"11784673857","pt":1722953160161,"mc":[{"id":"1.231431360","rc":[{"trd":[[1.71,104.8]],"batb":[[0,1.37,171.91],[1,1.35,10.75]],"batl":[[0,1.71,147.6]],"ltp":1.71,"tv":796.67,"id":2219}],"tv":796.67}]}
{"op":"mcm","clk":"11784673978","pt":1722953162179,"mc":[{"id":"1.231431360","rc":[{"batb":[[1,1.3,6.85],[2,1.25,100]],"ltp":1.71,"tv":796.67,"id":2219}]}]}
{"op":"mcm","clk":"11784674132","pt":1722953164868,"mc":[{"id":"1.231431360","rc":[{"batb":[[0,1.38,10.54],[1,1.37,171.89],[2,1.3,6.85]],"ltp":1.71,"tv":796.67,"id":2219}]}]}
{"op":"mcm","clk":"11784676413","pt":1722953200506,"mc":[{"id":"1.231431360","rc":[{"trd":[[1.71,125.86]],"batb":[[0,1.39,169.42],[1,1.38,10.52]],"batl":[[0,1.71,137.07]],"ltp":1.71,"tv":817.73,"id":2219}],"tv":817.73}]}
{"op":"mcm","clk":"11784676508","pt":1722953202105,"mc":[{"id":"1.231431360","rc":[{"batb":[[0,1.4,10.39],[1,1.39,169.4]],"ltp":1.71,"tv":817.73,"id":2219}]}]}
{"op":"mcm","clk":"11784677967","pt":1722953225641,"mc":[{"id":"1.231431360","rc":[{"trd":[[1.71,147.16]],"batl":[[0,1.71,126.42]],"ltp":1.71,"tv":839.03,"id":2219}],"tv":839.03}]}
{"op":"mcm","clk":"11784677987","pt":1722953225949,"mc":[{"id":"1.231431360","rc":[{"batb":[[0,1.42,141.71],[1,1.4,10.37]],"ltp":1.71,"tv":839.03,"id":2219}]}]}
{"op":"mcm","clk":"11784678065","pt":1722953227243,"mc":[{"id":"1.231431360","rc":[{"batb":[[0,1.43,10.17],[1,1.42,141.69]],"ltp":1.71,"tv":839.03,"id":2219}]}]}
{"op":"mcm","clk":"11784679912","pt":1722953261470,"mc":[{"id":"1.231431360","rc":[{"trd":[[1.71,155.34]],"batb":[[0,1.44,163.49],[1,1.43,10.15]],"batl":[[0,1.71,122.33]],"ltp":1.71,"tv":847.21,"id":2219}],"tv":847.21}]}
{"op":"mcm","clk":"11784680066","pt":1722953264251,"mc":[{"id":"1.231431360","rc":[{"batb":[[0,1.45,10.03],[1,1.44,163.47]],"ltp":1.71,"tv":847.21,"id":2219}]}]}
{"op":"mcm","clk":"11784683752","pt":1722953325407,"mc":[{"id":"1.231431360","rc":[{"trd":[[1.71,166]],"batb":[[0,1.46,137.8],[1,1.45,10.01]],"batl":[[0,1.71,117]],"ltp":1.71,"tv":857.87,"id":2219}],"tv":857.87}]}
{"op":"mcm","clk":"11784683865","pt":1722953327320,"mc":[{"id":"1.231431360","rc":[{"batb":[[0,1.47,9.89],[1,1.46,137.78]],"ltp":1.71,"tv":857.87,"id":2219}]}]}
{"op":"mcm","clk":"11784684051","pt":1722953330618,"mc":[{"id":"1.231431360","rc":[{"trd":[[1.71,170.08]],"batl":[[0,1.71,114.96]],"ltp":1.71,"tv":861.95,"id":2219}],"tv":861.95}]}
{"op":"mcm","clk":"11784686922","pt":1722953374568,"mc":[{"id":"1.231431360","rc":[{"batb":[[1,1.3,6.85],[2,1.25,100]],"ltp":1.71,"tv":861.95,"id":2219}]}]}
{"op":"mcm","clk":"11784686929","pt":1722953374671,"mc":[{"id":"1.231431360","rc":[{"batb":[[0,1.48,135.92],[1,1.47,9.87],[2,1.3,6.85]],"ltp":1.71,"tv":861.95,"id":2219}]}]}
{"op":"mcm","clk":"11784687017","pt":1722953376282,"mc":[{"id":"1.231431360","rc":[{"batb":[[0,1.49,9.76],[1,1.48,135.9]],"ltp":1.71,"tv":861.95,"id":2219}]}]}
{"op":"mcm","clk":"11784696707","pt":1722953513185,"mc":[{"id":"1.231431360","rc":[{"batb":[[0,1.6,18.13],[1,1.49,9.74]],"ltp":1.71,"tv":861.95,"id":2219}]}]}
{"op":"mcm","clk":"11784696791","pt":1722953514216,"mc":[{"id":"1.231431360","rc":[{"batb":[[0,1.61,9.03],[1,1.6,18.11]],"ltp":1.71,"tv":861.95,"id":2219}]}]}
{"op":"mcm","clk":"11784698115","pt":1722953532615,"mc":[{"id":"1.231431360","rc":[{"trd":[[1.61,18.02],[1.69,133.83]],"batb":[[0,1.3,6.85],[1,1.25,100],[2,1.08,7.88]],"batl":[[0,1.6,3.9],[1,1.71,114.96],[2,1.72,300]],"ltp":1.61,"tv":880.01,"id":2219}],"tv":880.01}]}
{"op":"mcm","clk":"11784698133","pt":1722953532817,"mc":[{"id":"1.231431360","rc":[{"trd":[[1.6,7.58]],"batb":[[0,1.31,150.44],[1,1.3,6.85],[2,1.25,100]],"batl":[[0,1.71,115.07],[1,1.72,300],[2,1.73,400]],"ltp":1.6,"tv":887.59,"id":2219}],"tv":887.59}]}
{"op":"mcm","clk":"11784698215","pt":1722953533831,"mc":[{"id":"1.231431360","rc":[{"batl":[[0,1.7,6.19],[1,1.71,114.96],[2,1.72,300]],"ltp":1.6,"tv":887.59,"id":2219}]}]}
{"op":"mcm","clk":"11784698351","pt":1722953535815,"mc":[{"id":"1.231431360","rc":[{"batl":[[0,1.7,6.08]],"ltp":1.6,"tv":887.59,"id":2219}]}]}
{"op":"mcm","clk":"11784699467","pt":1722953550036,"mc":[{"id":"1.231431360","rc":[{"trd":[[1.7,224.04],[1.71,188.98]],"batl":[[0,1.71,105.51],[1,1.72,300],[2,1.73,400]],"ltp":1.71,"tv":918.65,"id":2219}],"tv":918.65}]}
{"op":"mcm","clk":"11784699567","pt":1722953551230,"mc":[{"id":"1.231431360","rc":[{"batb":[[0,1.32,7.83],[1,1.31,150.44],[2,1.3,6.85]],"ltp":1.71,"tv":918.65,"id":2219}]}]}
{"op":"mcm","clk":"11784699908","pt":1722953555720,"mc":[{"id":"1.231431360","rc":[{"batl":[[0,1.7,124.26],[1,1.71,105.51],[2,1.72,300]],"ltp":1.71,"tv":918.65,"id":2219}]}]}
{"op":"mcm","clk":"11784702868","pt":1722953598187,"mc":[{"id":"1.231431360","rc":[{"trd":[[1.7,234.76]],"batb":[[0,1.38,170.63],[1,1.32,7.83]],"batl":[[0,1.7,118.9]],"ltp":1.7,"tv":929.37,"id":2219}],"tv":929.37}]}
{"op":"mcm","clk":"11784702925","pt":1722953599131,"mc":[{"id":"1.231431360","rc":[{"batb":[[0,1.39,7.44],[1,1.38,170.63]],"ltp":1.7,"tv":929.37,"id":2219}]}]}
{"op":"mcm","clk":"11784707066","pt":1722953659444,"mc":[{"id":"1.231431360","rc":[{"trd":[[1.7,261.54]],"batb":[[0,1.4,168.18],[1,1.39,7.44]],"batl":[[0,1.7,105.51]],"ltp":1.7,"tv":956.15,"id":2219}],"tv":956.15}]}
{"op":"mcm","clk":"11784707203","pt":1722953661042,"mc":[{"id":"1.231431360","rc":[{"batb":[[0,1.41,7.34],[1,1.4,168.18]],"ltp":1.7,"tv":956.15,"id":2219}]}]}
{"op":"mcm","clk":"11784707429","pt":1722953664356,"mc":[{"id":"1.231431360","rc":[{"batb":[[1,2.28,29.99],[2,2.14,38.68]],"ltp":0.0,"tv":0.0,"id":31379}]}]}
{"op":"mcm","clk":"11784708569","pt":1722953682491,"mc":[{"id":"1.231431360","rc":[{"batb":[[0,1.43,164.62],[1,1.41,7.34]],"ltp":1.7,"tv":956.15,"id":2219}]}]}
{"op":"mcm","clk":"11784708694","pt":1722953684192,"mc":[{"id":"1.231431360","rc":[{"batb":[[0,1.44,7.18],[1,1.43,164.62]],"ltp":1.7,"tv":956.15,"id":2219}]}]}
{"op":"mcm","clk":"11784715928","pt":1722953786668,"mc":[{"id":"1.231431360","rc":[{"trd":[[1.7,288.32]],"batb":[[1,1.3,6.85],[2,1.25,100]],"batl":[[0,1.7,92.12]],"ltp":1.7,"tv":982.93,"id":2219}],"tv":982.93}]}
{"op":"mcm","clk":"11784715932","pt":1722953786765,"mc":[{"id":"1.231431360","rc":[{"batb":[[0,1.45,138.73],[1,1.44,7.18],[2,1.3,6.85]],"ltp":1.7,"tv":982.93,"id":2219}]}]}
{"op":"mcm","clk":"11784716020","pt":1722953788058,"mc":[{"id":"1.231431360","rc":[{"batb":[[0,1.46,7.09],[1,1.45,138.73]],"ltp":1.7,"tv":982.93,"id":2219}]}]}
{"op":"mcm","clk":"11784716671","pt":1722953797517,"mc":[{"id":"1.231431360","rc":[{"trd":[[1.69,152.98]],"ltp":1.69,"tv":1002.07,"id":2219}],"tv":1002.07}]}
{"op":"mcm","clk":"11784717083","pt":1722953803082,"mc":[{"id":"1.231431360","rc":[{"batb":[[0,1.47,105.02],[1,1.46,7.09]],"ltp":1.69,"tv":1002.07,"id":2219}]}]}
{"op":"mcm","clk":"11784717285","pt":1722953805400,"mc":[{"id":"1.231431360","rc":[{"batb":[[1,1.3,6.85],[2,1.25,100]],"ltp":1.69,"tv":1002.07,"id":2219}]}]}
{"op":"mcm","clk":"11784717495","pt":1722953808597,"mc":[{"id":"1.231431360","rc":[{"trd":[[1.7,314.64]],"batb":[[0,1.48,6.99],[1,1.47,105.02],[2,1.3,6.85]],"batl":[[0,1.7,78.96]],"ltp":1.7,"tv":1028.39,"id":2219}],"tv":1028.39}]}
{"op":"mcm","clk":"11784719420","pt":1722953833551,"mc":[{"id":"1.231431360","rc":[{"trd":[[1.69,172.12]],"batb":[[0,1.49,103.6],[1,1.48,6.99]],"ltp":1.69,"tv":1047.54,"id":2219}],"tv":1047.54}]}
{"op":"mcm","clk":"11784719617","pt":1722953835563,"mc":[{"id":"1.231431360","rc":[{"batb":[[0,1.5,6.9],[1,1.49,103.6]],"ltp":1.69,"tv":1047.54,"id":2219}]}]}
{"op":"mcm","clk":"11784720874","pt":1722953851453,"mc":[{"id":"1.231431360","rc":[{"batb":[[0,1.51,102.22],[1,1.3,6.85],[2,1.25,100]],"ltp":1.69,"tv":1047.54,"id":2219}]}]}
{"op":"mcm","clk":"11784721077","pt":1722953853973,"mc":[{"id":"1.231431360","rc":[{"batb":[[0,1.52,6.8],[1,1.51,102.22],[2,1.3,6.85]],"ltp":1.69,"tv":1047.54,"id":2219}]}]}
{"op":"mcm","clk":"11784728004","pt":1722953945489,"mc":[{"id":"1.231431360","rc":[{"trd":[[1.7,435.34]],"batl":[[0,1.7,18.61]],"ltp":1.7,"tv":1168.24,"id":2219}],"tv":1168.24}]}
{"op":"mcm","clk":"11784728038","pt":1722953945926,"mc":[{"id":"1.231431360","rc":[{"batb":[[0,1.53,100.87],[1,1.52,6.8]],"ltp":1.7,"tv":1168.24,"id":2219}]}]}
{"op":"mcm","clk":"11784728138","pt":1722953947182,"mc":[{"id":"1.231431360","rc":[{"batb":[[0,1.54,6.72],[1,1.53,100.87]],"ltp":1.7,"tv":1168.24,"id":2219}]}]}
{"op":"mcm","clk":"11784731500","pt":1722953991588,"mc":[{"id":"1.231431360","rc":[{"batb":[[1,1.3,6.85],[2,1.25,100]],"ltp":1.7,"tv":1168.24,"id":2219}]}]}
{"op":"mcm","clk":"11784731509","pt":1722953991689,"mc":[{"id":"1.231431360","rc":[{"batb":[[0,1.55,76.48],[1,1.54,6.72],[2,1.3,6.85]],"ltp":1.7,"tv":1168.24,"id":2219}]}]}
{"op":"mcm","clk":"11784731621","pt":1722953993494,"mc":[{"id":"1.231431360","rc":[{"batb":[[0,1.56,6.63],[1,1.55,76.48]],"ltp":1.7,"tv":1168.24,"id":2219}]}]}
{"op":"mcm","clk":"11784738596","pt":1722954078415,"mc":[{"id":"1.231431360","rc":[{"trd":[[1.7,863.93]],"batb":[[0,1.57,48.61],[1,1.56,6.63]],"batl":[[0,1.71,105.51],[1,1.72,300],[2,1.73,400]],"ltp":1.7,"tv":1596.83,"id":2219}],"tv":1596.83}]}
{"op":"mcm","clk":"11784738694","pt":1722954079602,"mc":[{"id":"1.231431360","rc":[{"batb":[[0,1.58,6.54],[1,1.57,48.61]],"ltp":1.7,"tv":1596.83,"id":2219}]}]}
{"op":"mcm","clk":"11784741274","pt":1722954111318,"mc":[{"id":"1.231431360","rc":[{"batb":[[1,2.28,29.55]],"ltp":0.0,"tv":0.0,"id":31379}]}]}
{"op":"mcm","clk":"11784743609","pt":1722954139560,"mc":[{"id":"1.231431360","rc":[{"batb":[[0,1.58,54.84],[1,1.3,6.85],[2,1.25,100]],"ltp":1.7,"tv":1596.83,"id":2219}]}]}
{"op":"mcm","clk":"11784758076","pt":1722954347857,"mc":[{"id":"1.231431360","rc":[{"trd":[[1.71,215.6]],"batl":[[0,1.71,92.2]],"ltp":1.71,"tv":1623.45,"id":2219}],"tv":1623.45}]}
{"op":"mcm","clk":"11784763815","pt":1722954423431,"mc":[{"id":"1.231431360","rc":[{"trd":[[1.71,242.52]],"batl":[[0,1.71,78.74]],"ltp":1.71,"tv":1650.37,"id":2219}],"tv":1650.37}]}
{"op":"mcm","clk":"11784766271","pt":1722954454558,"mc":[{"id":"1.231431360","rc":[{"batb":[[0,1.59,45.08],[1,1.58,54.84],[2,1.3,6.85]],"ltp":1.71,"tv":1650.37,"id":2219}]}]}
{"op":"mcm","clk":"11784766381","pt":1722954455854,"mc":[{"id":"1.231431360","rc":[{"batb":[[0,1.6,6.47],[1,1.59,45.08],[2,1.58,48.3]],"ltp":1.71,"tv":1650.37,"id":2219}]}]}
{"op":"mcm","clk":"11784771527","pt":1722954530232,"mc":[{"id":"1.231431360","rc":[{"batb":[[2,1.3,6.85]],"ltp":1.71,"tv":1650.37,"id":2219}]}]}
{"op":"mcm","clk":"11784774994","pt":1722954578481,"mc":[{"id":"1.231431360","rc":[{"trd":[[1.71,269.14]],"batl":[[0,1.71,65.43]],"ltp":1.71,"tv":1676.99,"id":2219}],"tv":1676.99}]}
{"op":"mcm","clk":"11784782344","pt":1722954667662,"mc":[{"id":"1.231431360","rc":[{"batb":[[2,1.25,100]],"ltp":1.71,"tv":1676.99,"id":2219}]}]}
{"op":"mcm","clk":"11784782390","pt":1722954668174,"mc":[{"id":"1.231431360","rc":[{"batb":[[0,2.28,29.55],[1,2.14,38.68],[2,2.1,7.7]],"ltp":0.0,"tv":0.0,"id":31379},{"batl":[[0,1.71,778.69]],"ltp":1.71,"tv":1676.99,"id":2219}]}]}
{"op":"mcm","clk":"11784786889","pt":1722954720032,"mc":[{"id":"1.231431360","rc":[{"trd":[[1.71,486]],"batl":[[0,1.72,300],[1,1.73,400],[2,1.74,500]],"ltp":1.71,"tv":1893.85,"id":2219}],"tv":1893.85}]}
{"op":"mcm","clk":"11784801938","pt":1722954916955,"mc":[{"id":"1.231431360","rc":[{"batl":[[0,1.71,17.2],[1,1.72,300],[2,1.73,400]],"ltp":1.71,"tv":1893.85,"id":2219}]}]}
{"op":"mcm","clk":"11784808945","pt":1722955012227,"mc":[{"id":"1.231431360","rc":[{"batb":[[2,1.74,17.32]],"ltp":0.0,"tv":0.0,"id":31379}]}]}
{"op":"mcm","clk":"11784813354","pt":1722955070970,"mc":[{"id":"1.231431360","rc":[{"batb":[[2,2.12,7.63]],"ltp":0.0,"tv":0.0,"id":31379}]}]}
{"op":"mcm","clk":"11784830164","pt":1722955276215,"mc":[{"id":"1.231431360","rc":[{"batb":[[0,2.4,12.46],[1,2.28,29.55],[2,2.14,38.68]],"ltp":0.0,"tv":0.0,"id":31379}]}]}
{"op":"mcm","clk":"11784854471","pt":1722955520989,"mc":[{"id":"1.231431360","rc":[{"trd":[[1.71,505.26]],"batl":[[0,1.71,7.57]],"ltp":1.71,"tv":1913.11,"id":2219}],"tv":1913.11}]}
{"op":"mcm","clk":"11784859598","pt":1722955587399,"mc":[{"id":"1.231431360","rc":[{"trd":[[1.6,7.72]],"batb":[[0,1.6,6.4]],"ltp":1.6,"tv":1913.24,"id":2219}],"tv":1913.24}]}
{"op":"mcm","clk":"11784873114","pt":1722955753578,"mc":[{"id":"1.231431360","rc":[{"batb":[[1,2.32,28.65]],"ltp":0.0,"tv":0.0,"id":31379},{"batb":[[0,1.7,54.03],[1,1.6,6.4],[2,1.59,45.08]],"ltp":1.6,"tv":1913.24,"id":2219}]}]}
{"op":"mcm","clk":"11784873159","pt":1722955753992,"mc":[{"id":"1.231431360","rc":[{"trd":[[1.7,971.63],[1.71,517.23]],"batb":[[0,1.59,68.5],[1,1.25,100],[2,1.08,7.88]],"batl":[[0,1.71,1.58]],"ltp":1.71,"tv":2032.91,"id":2219}],"tv":2032.91}]}
{"op":"mcm","clk":"11784873386","pt":1722955756681,"mc":[{"id":"1.231431360","rc":[{"batl":[[0,1.71,17.24]],"ltp":1.71,"tv":2032.91,"id":2219}]}]}
{"op":"mcm","clk":"11784873607","pt":1722955758905,"mc":[{"id":"1.231431360","rc":[{"batb":[[2,2.16,7.5]],"ltp":0.0,"tv":0.0,"id":31379},{"batb":[[0,1.66,13.6],[1,1.59,68.32],[2,1.25,100]],"ltp":1.71,"tv":2032.91,"id":2219}]}]}
{"op":"mcm","clk":"11784875251","pt":1722955779972,"mc":[{"id":"1.231431360","rc":[{"batb":[[2,2.14,38.68]],"ltp":0.0,"tv":0.0,"id":31379},{"batb":[[1,1.59,45.08]],"ltp":1.71,"tv":2032.91,"id":2219}]}]}
{"op":"mcm","clk":"11784919488","pt":1722956331631,"mc":[{"id":"1.231431360","rc":[{"batl":[[0,1.7,223.08],[1,1.71,17.24],[2,1.72,300]],"ltp":1.71,"tv":2032.91,"id":2219}]}]}
{"op":"mcm","clk":"11784919591","pt":1722956332719,"mc":[{"id":"1.231431360","rc":[{"batl":[[1,1.71,1.58]],"ltp":1.71,"tv":2032.91,"id":2219}]}]}
{"op":"mcm","clk":"11784919703","pt":1722956334422,"mc":[{"id":"1.231431360","rc":[{"batb":[[0,2.32,28.65],[1,2.14,38.68],[2,1.74,17.32]],"ltp":0.0,"tv":0.0,"id":31379},{"batl":[[0,1.72,300],[1,1.73,400],[2,1.74,500]],"ltp":1.71,"tv":2032.91,"id":2219}]}]}
{"op":"mcm","clk":"11784920037","pt":1722956338315,"mc":[{"id":"1.231431360","rc":[{"batb":[[1,2.16,7.5],[2,2.14,38.68]],"ltp":0.0,"tv":0.0,"id":31379}]}]}
{"op":"mcm","clk":"11784947775","pt":1722956653419,"mc":[{"id":"1.231431360","rc":[{"batb":[[1,2.16,7.5]],"ltp":0.0,"tv":0.0,"id":31379},{"trd":[[1.6,7.71],[1.61,18.02],[1.69,172.12],[1.7,971.59],[1.71,517.23],[1.85,15.44],[1.86,7.72]],"batl":[[0,1.71,14.73],[1,1.72,300],[2,1.73,400]],"ltp":1.71,"tv":2032.85,"id":2219}],"tv":2032.85}]}
{"op":"mcm","clk":"11784948437","pt":1722956660550,"mc":[{"id":"1.231431360","rc":[{"batb":[[1,2.14,38.68],[2,1.74,17.32]],"ltp":0.0,"tv":0.0,"id":31379}]}]}
{"op":"mcm","clk":"11784954333","pt":1722956726815,"mc":[{"id":"1.231431360","rc":[{"batb":[[0,2.4,12.47],[1,2.32,28.65],[2,2.14,38.68]],"ltp":0.0,"tv":0.0,"id":31379}]}]}
{"op":"mcm","clk":"11785251663","pt":1722959450658,"mc":[{"id":"1.231431360","rc":[{"batb":[[0,1.66,59.6]],"ltp":1.71,"tv":2032.85,"id":2219}]}]}
{"op":"mcm","clk":"11785251829","pt":1722959452420,"mc":[{"id":"1.231431360","rc":[{"batb":[[0,1.67,16],[1,1.66,59.6],[2,1.59,45.08]],"ltp":1.71,"tv":2032.85,"id":2219}]}]}
{"op":"mcm","clk":"11785254656","pt":1722959483973,"mc":[{"id":"1.231431360","rc":[{"batb":[[0,1.67,20.47]],"ltp":1.71,"tv":2032.85,"id":2219}]}]}
{"op":"mcm","clk":"11785397098","pt":1722960774894,"mc":[{"id":"1.231431360","rc":[{"batb":[[0,2.4,12.47]],"ltp":0.0,"tv":0.0,"id":31379},{"trd":[[1.6,7.72],[1.61,18.03],[1.69,172.26],[1.7,971.87],[1.71,517.25],[1.85,15.45],[1.86,7.73]],"batb":[[0,1.67,20.48]],"batl":[[0,1.71,14.74]],"ltp":1.71,"tv":2033.33,"id":2219}],"tv":2033.33}]}
{"op":"mcm","clk":"11786066737","pt":1722966174898,"mc":[{"id":"1.231431360","rc":[{"batb":[[0,2.4,12.46]],"ltp":0.0,"tv":0.0,"id":31379},{"trd":[[1.6,7.71],[1.61,18.02],[1.69,172.27],[1.7,971.48],[1.71,517.22],[1.85,15.44],[1.86,7.73]],"batb":[[0,1.67,20.46]],"batl":[[0,1.71,14.72]],"ltp":1.71,"tv":2032.88,"id":2219}],"tv":2032.88}]}
{"op":"mcm","clk":"11786083728","pt":1722966261090,"mc":[{"id":"1.231431360","rc":[{"batb":[[1,2.14,38.68],[2,1.74,17.32]],"ltp":0.0,"tv":0.0,"id":31379},{"trd":[[1.7,1236.38]],"batb":[[0,1.67,20.64],[1,1.66,46]],"ltp":1.7,"tv":2297.78,"id":2219}],"tv":2297.78}]}
{"op":"mcm","clk":"11786084064","pt":1722966263281,"mc":[{"id":"1.231431360","rc":[{"batb":[[0,1.67,4.65]],"ltp":1.7,"tv":2297.78,"id":2219}]}]}
{"op":"mcm","clk":"11786084516","pt":1722966266120,"mc":[{"id":"1.231431360","rc":[{"batb":[[1,2.32,28.65],[2,2.14,38.68]],"ltp":0.0,"tv":0.0,"id":31379},{"batb":[[1,1.66,59.6]],"ltp":1.7,"tv":2297.78,"id":2219}]}]}
{"op":"mcm","clk":"11786084797","pt":1722966267995,"mc":[{"id":"1.231431360","rc":[{"batb":[[0,1.67,9.48]],"ltp":1.7,"tv":2297.78,"id":2219}]}]}
{"op":"mcm","clk":"11786089262","pt":1722966297936,"mc":[{"id":"1.231431360","rc":[{"batb":[[0,1.67,9.3]],"ltp":1.7,"tv":2297.78,"id":2219}]}]}
{"op":"mcm","clk":"11786622563","pt":1722970077515,"mc":[{"id":"1.231431360","rc":[{"batb":[[0,2.4,12.47]],"ltp":0.0,"tv":0.0,"id":31379},{"trd":[[1.6,7.72],[1.61,18.03],[1.67,18.61],[1.69,172.35],[1.7,1236.75],[1.71,517.25],[1.85,15.45],[1.86,7.73]],"batb":[[0,1.66,59.6],[1,1.59,45.08],[2,1.48,104.17]],"batl":[[0,1.71,14.74]],"ltp":1.67,"tv":2316.91,"id":2219}],"tv":2316.91}]}
{"op":"mcm","clk":"11786622674","pt":1722970078231,"mc":[{"id":"1.231431360","rc":[{"batb":[[0,1.67,11.17],[1,1.66,59.6],[2,1.59,45.08]],"ltp":1.67,"tv":2316.91,"id":2219}]}]}
{"op":"mcm","clk":"11786622836","pt":1722970079129,"mc":[{"id":"1.231431360","rc":[{"trd":[[1.67,40.95]],"batb":[[0,1.66,59.6],[1,1.59,45.08],[2,1.48,104.17]],"ltp":1.67,"tv":2339.25,"id":2219}],"tv":2339.25}]}
{"op":"mcm","clk":"11786622986","pt":1722970080234,"mc":[{"id":"1.231431360","rc":[{"batl":[[0,1.71,36.31]],"ltp":1.67,"tv":2339.25,"id":2219}]}]}
{"op":"mcm","clk":"11786623466","pt":1722970083837,"mc":[{"id":"1.231431360","rc":[{"trd":[[1.66,119.2]],"batb":[[0,1.59,45.08],[1,1.48,104.17],[2,1.43,116.28]],"ltp":1.66,"tv":2458.45,"id":2219}],"tv":2458.45}]}
{"op":"mcm","clk":"11786623967","pt":1722970087237,"mc":[{"id":"1.231431360","rc":[{"batb":[[0,1.66,5],[1,1.59,45.08],[2,1.48,104.17]],"ltp":1.66,"tv":2458.45,"id":2219}]}]}
{"op":"mcm","clk":"11786624103","pt":1722970088253,"mc":[{"id":"1.231431360","rc":[{"trd":[[1.66,127.79]],"batb":[[0,1.59,45.78],[1,1.48,104.17],[2,1.43,116.28]],"ltp":1.66,"tv":2467.04,"id":2219}],"tv":2467.04}]}
{"op":"mcm","clk":"11786624744","pt":1722970092440,"mc":[{"id":"1.231431360","rc":[{"batb":[[0,1.59,45.08]],"ltp":1.66,"tv":2467.04,"id":2219}]}]}
{"op":"mcm","clk":"11786625247","pt":1722970095828,"mc":[{"id":"1.231431360","rc":[{"trd":[[1.59,27.52]],"batb":[[0,1.59,31.32]],"ltp":1.59,"tv":2494.57,"id":2219}],"tv":2494.57}]}
{"op":"mcm","clk":"11786626004","pt":1722970100534,"mc":[{"id":"1.231431360","rc":[{"batb":[[2,2.18,7.42]],"ltp":0.0,"tv":0.0,"id":31379}]}]}
{"op":"mcm","clk":"11786636220","pt":1722970171218,"mc":[{"id":"1.231431360","rc":[{"batb":[[0,1.6,57.3],[1,1.59,31.32],[2,1.48,104.17]],"ltp":1.59,"tv":2494.57,"id":2219}]}]}
{"op":"mcm","clk":"11786704134","pt":1722970672955,"mc":[{"id":"1.231431360","rc":[{"batl":[[0,1.7,189.34],[1,1.71,36.31],[2,1.72,300]],"ltp":1.59,"tv":2494.57,"id":2219}]}]}
{"op":"mcm","clk":"11786704292","pt":1722970674159,"mc":[{"id":"1.231431360","rc":[{"batb":[[0,2.32,28.65],[1,2.18,7.42],[2,2.14,38.68]],"ltp":0.0,"tv":0.0,"id":31379},{"batl":[[0,1.69,4.42],[1,1.7,189.34]],"ltp":1.59,"tv":2494.57,"id":2219}]}]}
{"op":"mcm","clk":"11786708384","pt":1722970705391,"mc":[{"id":"1.231431360","rc":[{"batl":[[0,1.69,18.97]],"ltp":1.59,"tv":2494.57,"id":2219}]}]}
{"op":"mcm","clk":"11786730294","pt":1722970866467,"mc":[{"id":"1.231431360","rc":[{"batb":[[1,2.28,7.1]],"ltp":0.0,"tv":0.0,"id":31379},{"trd":[[1.59,27.52],[1.6,7.72],[1.61,18.03],[1.66,127.78],[1.67,40.94],[1.69,172.31],[1.7,1236.63],[1.71,517.24],[1.85,15.45],[1.86,7.73]],"batl":[[0,1.69,18.97],[1,1.7,189.28]],"ltp":1.59,"tv":2494.36,"id":2219}],"tv":2494.36}]}
{"op":"mcm","clk":"11786740581","pt":1722970949205,"mc":[{"id":"1.231431360","rc":[{"batl":[[0,1.68,13.53],[1,1.69,18.97],[2,1.7,189.28]],"ltp":1.59,"tv":2494.36,"id":2219}]}]}
{"op":"mcm","clk":"11786740807","pt":1722970951118,"mc":[{"id":"1.231431360","rc":[{"batl":[[1,1.69,14.55]],"ltp":1.59,"tv":2494.36,"id":2219}]}]}
{"op":"mcm","clk":"11786765164","pt":1722971145532,"mc":[{"id":"1.231431360","rc":[{"trd":[[1.6,7.86]],"batb":[[0,1.6,57.23]],"ltp":1.6,"tv":2494.5,"id":2219}],"tv":2494.5}]}
{"op":"mcm","clk":"11786783662","pt":1722971295915,"mc":[{"id":"1.231431360","rc":[{"trd":[[1.68,6.28]],"batl":[[0,1.68,10.39]],"ltp":1.68,"tv":2500.78,"id":2219}],"tv":2500.78}]}
{"op":"mcm","clk":"11786783942","pt":1722971298218,"mc":[{"id":"1.231431360","rc":[{"batb":[[0,2.44,9.98],[1,2.32,28.65],[2,2.28,7.1]],"ltp":0.0,"tv":0.0,"id":31379}]}]}
{"op":"mcm","clk":"11786788595","pt":1722971337463,"mc":[{"id":"1.231431360","rc":[{"trd":[[1.68,12.56]],"batl":[[0,1.68,7.25]],"ltp":1.68,"tv":2507.06,"id":2219}],"tv":2507.06}]}
{"op":"mcm","clk":"11786788843","pt":1722971339767,"mc":[{"id":"1.231431360","rc":[{"batl":[[1,1.69,29.84]],"ltp":1.68,"tv":2507.06,"id":2219}]}]}
{"op":"mcm","clk":"11786872426","pt":1722971975604,"mc":[{"id":"1.231431360","rc":[{"batb":[[2,2.14,38.68]],"ltp":0.0,"tv":0.0,"id":31379}]}]}
{"op":"mcm","clk":"11786872684","pt":1722971977912,"mc":[{"id":"1.231431360","rc":[{"batb":[[2,2.3,7.03]],"ltp":0.0,"tv":0.0,"id":31379}]}]}
{"op":"mcm","clk":"11786909531","pt":1722972324465,"mc":[{"id":"1.231431360","rc":[{"trd":[[1.6,8]],"batb":[[0,1.6,57.16]],"ltp":1.6,"tv":2507.2,"id":2219}],"tv":2507.2}]}
{"op":"mcm","clk":"11786961789","pt":1722972827024,"mc":[{"id":"1.231431360","rc":[{"batb":[[2,2.14,38.68]],"ltp":0.0,"tv":0.0,"id":31379}]}]}
{"op":"mcm","clk":"11787017296","pt":1722973415643,"mc":[{"id":"1.231431360","rc":[{"trd":[[1.6,122.32]],"batb":[[0,1.59,31.32],[1,1.48,104.17],[2,1.43,116.28]],"batl":[[0,1.6,742.84],[1,1.68,7.25],[2,1.69,29.84]],"ltp":1.6,"tv":2621.52,"id":2219}],"tv":2621.52}]}
{"op":"mcm","clk":"11787017485","pt":1722973417463,"mc":[{"id":"1.231431360","rc":[{"batb":[[0,2.32,28.65],[1,2.14,38.68],[2,1.74,17.32]],"ltp":0.0,"tv":0.0,"id":31379},{"batl":[[0,1.6,747.5],[2,1.7,189.28]],"ltp":1.6,"tv":2621.52,"id":2219}]}]}
{"op":"mcm","clk":"11787018272","pt":1722973425967,"mc":[{"id":"1.231431360","rc":[{"trd":[[1.59,90.16]],"batb":[[0,1.48,104.17],[1,1.43,116.28],[2,1.38,131.58]],"batl":[[0,1.59,711.52],[1,1.6,4.66],[2,1.68,7.25]],"ltp":1.59,"tv":2684.16,"id":2219}],"tv":2684.16}]}
{"op":"mcm","clk":"11787018414","pt":1722973427570,"mc":[{"id":"1.231431360","rc":[{"batl":[[1,1.68,7.25],[2,1.7,189.28]],"ltp":1.59,"tv":2684.16,"id":2219}]}]}
{"op":"mcm","clk":"11787018424","pt":1722973427674,"mc":[{"id":"1.231431360","rc":[{"batl":[[0,1.58,4.72],[1,1.59,711.52],[2,1.68,7.25]],"ltp":1.59,"tv":2684.16,"id":2219}]}]}
{"op":"mcm","clk":"11787018871","pt":1722973432755,"mc":[{"id":"1.231431360","rc":[{"batl":[[1,1.68,7.25],[2,1.7,189.28]],"ltp":1.59,"tv":2684.16,"id":2219}]}]}
{"op":"mcm","clk":"11787019129","pt":1722973435966,"mc":[{"id":"1.231431360","rc":[{"batl":[[0,1.68,7.25],[1,1.69,4.41]],"ltp":1.59,"tv":2684.16,"id":2219}]}]}
{"op":"mcm","clk":"11787019514","pt":1722973440485,"mc":[{"id":"1.231431360","rc":[{"batb":[[0,2.34,6.91],[1,2.32,28.65],[2,2.14,38.68]],"ltp":0.0,"tv":0.0,"id":31379}]}]}
{"op":"mcm","clk":"11787020451","pt":1722973450898,"mc":[{"id":"1.231431360","rc":[{"batb":[[0,2.32,28.65],[1,2.14,38.68],[2,1.74,17.32]],"ltp":0.0,"tv":0.0,"id":31379}]}]}
{"op":"mcm","clk":"11787022134","pt":1722973469079,"mc":[{"id":"1.231431360","rc":[{"batl":[[1,1.69,18.63]],"ltp":1.59,"tv":2684.16,"id":2219}]}]}
{"op":"mcm","clk":"11787022522","pt":1722973473188,"mc":[{"id":"1.231431360","rc":[{"batb":[[0,1.6,30.72],[1,1.48,104.17],[2,1.43,116.28]],"ltp":1.59,"tv":2684.16,"id":2219}]}]}
{"op":"mcm","clk":"11787027544","pt":1722973530468,"mc":[{"id":"1.231431360","rc":[{"trd":[[1.6,122.46]],"batb":[[0,1.6,30.65]],"ltp":1.6,"tv":2684.3,"id":2219}],"tv":2684.3}]}
{"op":"mcm","clk":"11787031126","pt":1722973570815,"mc":[{"id":"1.231431360","rc":[{"batb":[[0,1.61,8.64],[1,1.6,30.65],[2,1.48,104.17]],"ltp":1.6,"tv":2684.3,"id":2219}]}]}
{"op":"mcm","clk":"11787034233","pt":1722973601635,"mc":[{"id":"1.231431360","rc":[{"batb":[[0,2.32,35.62]],"ltp":0.0,"tv":0.0,"id":31379}]}]}
{"op":"mcm","clk":"11787052988","pt":1722973797243,"mc":[{"id":"1.231431360","rc":[{"trd":[[1.6,181.18],[1.61,35.31]],"batb":[[0,1.6,1.29],[1,1.48,104.17],[2,1.43,116.28]],"ltp":1.6,"tv":2760.3,"id":2219}],"tv":2760.3}]}
{"op":"mcm","clk":"11787053222","pt":1722973799973,"mc":[{"id":"1.231431360","rc":[{"batb":[[1,1.49,5.18],[2,1.48,104.17]],"ltp":1.6,"tv":2760.3,"id":2219}]}]}
{"op":"mcm","clk":"11787053346","pt":1722973801172,"mc":[{"id":"1.231431360","rc":[{"batb":[[0,2.32,28.65]],"ltp":0.0,"tv":0.0,"id":31379}]}]}
{"op":"mcm","clk":"11787061099","pt":1722973876964,"mc":[{"id":"1.231431360","rc":[{"trd":[[1.6,183.76]],"batb":[[0,1.49,5.18],[1,1.48,104.17],[2,1.43,116.28]],"batl":[[0,1.68,7.31]],"ltp":1.6,"tv":2762.88,"id":2219}],"tv":2762.88}]}
{"op":"mcm","clk":"11787066557","pt":1722973931139,"mc":[{"id":"1.231431360","rc":[{"batb":[[0,1.49,89.93]],"ltp":1.6,"tv":2762.88,"id":2219}]}]}
{"op":"mcm","clk":"11787074809","pt":1722974015620,"mc":[{"id":"1.231431360","rc":[{"batl":[[0,1.68,7.25]],"ltp":1.6,"tv":2762.88,"id":2219}]}]}
{"op":"mcm","clk":"11787079287","pt":1722974063066,"mc":[{"id":"1.231431360","rc":[{"batb":[[0,1.5,360],[1,1.49,89.93],[2,1.48,104.17]],"ltp":1.6,"tv":2762.88,"id":2219}]}]}
{"op":"mcm","clk":"11787079384","pt":1722974064372,"mc":[{"id":"1.231431360","rc":[{"batb":[[1,1.49,84.75]],"ltp":1.6,"tv":2762.88,"id":2219}]}]}
{"op":"mcm","clk":"11787082537","pt":1722974107422,"mc":[{"id":"1.231431360","rc":[{"batb":[[0,1.51,84.75],[1,1.5,360]],"ltp":1.6,"tv":2762.88,"id":2219}]}]}
{"op":"mcm","clk":"11787084418","pt":1722974133627,"mc":[{"id":"1.231431360","rc":[{"batb":[[0,2.34,6.91],[1,2.32,28.65],[2,2.14,38.68]],"ltp":0.0,"tv":0.0,"id":31379}]}]}
{"op":"mcm","clk":"11787086520","pt":1722974160757,"mc":[{"id":"1.231431360","rc":[{"batb":[[0,1.53,135],[1,1.51,84.75],[2,1.5,360]],"ltp":1.6,"tv":2762.88,"id":2219}]}]}
{"op":"mcm","clk":"11787089034","pt":1722974193212,"mc":[{"id":"1.231431360","rc":[{"batb":[[0,2.32,28.65],[1,2.14,38.68],[2,1.74,17.32]],"ltp":0.0,"tv":0.0,"id":31379}]}]}
{"op":"mcm","clk":"11787089081","pt":1722974193778,"mc":[{"id":"1.231431360","rc":[{"batb":[[0,1.51,84.75],[1,1.5,360],[2,1.48,104.17]],"ltp":1.6,"tv":2762.88,"id":2219}]}]}
{"op":"mcm","clk":"11787091327","pt":1722974224344,"mc":[{"id":"1.231431360","rc":[{"batb":[[0,2.34,6.91],[1,2.32,28.65],[2,2.14,38.68]],"ltp":0.0,"tv":0.0,"id":31379}]}]}
{"op":"mcm","clk":"11787091785","pt":1722974230743,"mc":[{"id":"1.231431360","rc":[{"batb":[[0,1.51,82.5]],"ltp":1.6,"tv":2762.88,"id":2219}]}]}
{"op":"mcm","clk":"11787093721","pt":1722974255082,"mc":[{"id":"1.231431360","rc":[{"batb":[[0,1.51,9.01]],"ltp":1.6,"tv":2762.88,"id":2219}]}]}
{"op":"mcm","clk":"11787111965","pt":1722974504611,"mc":[{"id":"1.231431360","rc":[{"batb":[[0,2.34,6.91]],"ltp":0.0,"tv":0.0,"id":31379},{"trd":[[1.59,90.17],[1.6,183.78],[1.61,35.32],[1.66,127.81],[1.67,40.97],[1.69,172.31],[1.7,1236.85],[1.71,517.26],[1.85,15.45],[1.86,7.73]],"batb":[[0,1.51,26.56]],"batl":[[1,1.69,18.64],[2,1.7,189.37]],"ltp":1.6,"tv":2763.23,"id":2219}],"tv":2763.23}]}
{"op":"mcm","clk":"11787112168","pt":1722974507439,"mc":[{"id":"1.231431360","rc":[{"batb":[[0,2.44,7.15],[1,2.34,6.91],[2,2.32,28.65]],"ltp":0.0,"tv":0.0,"id":31379},{"batb":[[0,1.52,7.45],[1,1.51,26.56],[2,1.5,360]],"ltp":1.6,"tv":2763.23,"id":2219}]}]}
{"op":"mcm","clk":"11787119694","pt":1722974607517,"mc":[{"id":"1.231431360","rc":[{"batb":[[0,1.53,45.08],[1,1.52,7.45],[2,1.51,26.56]],"ltp":1.6,"tv":2763.23,"id":2219}]}]}
{"op":"mcm","clk":"11787119800","pt":1722974608712,"mc":[{"id":"1.231431360","rc":[{"batb":[[2,1.51,9.01]],"ltp":1.6,"tv":2763.23,"id":2219}]}]}
{"op":"mcm","clk":"11787120190","pt":1722974613610,"mc":[{"id":"1.231431360","rc":[{"batl":[[0,1.69,18.64],[1,1.7,189.37],[2,1.72,300]],"ltp":1.6,"tv":2763.23,"id":2219}]}]}
{"op":"mcm","clk":"11787121366","pt":1722974627505,"mc":[{"id":"1.231431360","rc":[{"batl":[[0,1.68,36.06],[1,1.69,18.64],[2,1.7,189.37]],"ltp":1.6,"tv":2763.23,"id":2219}]}]}
{"op":"mcm","clk":"11787121458","pt":1722974628640,"mc":[{"id":"1.231431360","rc":[{"batl":[[0,1.67,4.48],[1,1.68,36.06]],"ltp":1.6,"tv":2763.23,"id":2219}]}]}
{"op":"mcm","clk":"11787123013","pt":1722974648337,"mc":[{"id":"1.231431360","rc":[{"batb":[[1,2.32,28.65],[2,2.14,38.68]],"ltp":0.0,"tv":0.0,"id":31379}]}]}
{"op":"mcm","clk":"11787123261","pt":1722974651436,"mc":[{"id":"1.231431360","rc":[{"batb":[[1,1.52,187.45]],"ltp":1.6,"tv":2763.23,"id":2219}]}]}
{"op":"mcm","clk":"11787126524","pt":1722974693974,"mc":[{"id":"1.231431360","rc":[{"batb":[[0,1.54,54.96],[1,1.53,45.08],[2,1.52,187.45]],"ltp":1.6,"tv":2763.23,"id":2219}]}]}
{"op":"mcm","clk":"11787127595","pt":1722974707023,"mc":[{"id":"1.231431360","rc":[{"batb":[[0,1.53,45.08],[1,1.52,187.45],[2,1.51,9.01]],"ltp":1.6,"tv":2763.23,"id":2219}]}]}
{"op":"mcm","clk":"11787139439","pt":1722974851728,"mc":[{"id":"1.231431360","rc":[{"batl":[[0,1.67,80.22]],"ltp":1.6,"tv":2763.23,"id":2219}]}]}
{"op":"mcm","clk":"11787141103","pt":1722974871562,"mc":[{"id":"1.231431360","rc":[{"batb":[[1,2.34,6.91],[2,2.32,28.65]],"ltp":0.0,"tv":0.0,"id":31379}]}]}
{"op":"mcm","clk":"11787141943","pt":1722974881354,"mc":[{"id":"1.231431360","rc":[{"batl":[[1,1.7,189.37],[2,1.72,300]],"ltp":1.6,"tv":2763.23,"id":2219}]}]}
{"op":"mcm","clk":"11787142302","pt":1722974885634,"mc":[{"id":"1.231431360","rc":[{"batl":[[0,1.66,5.69],[1,1.67,80.22],[2,1.7,189.37]],"ltp":1.6,"tv":2763.23,"id":2219}]}]}
{"op":"mcm","clk":"11787143217","pt":1722974898348,"mc":[{"id":"1.231431360","rc":[{"batl":[[0,1.65,36.06],[1,1.66,5.69],[2,1.67,80.22]],"ltp":1.6,"tv":2763.23,"id":2219}]}]}
{"op":"mcm","clk":"11787143371","pt":1722974900463,"mc":[{"id":"1.231431360","rc":[{"batl":[[0,1.64,4.55],[1,1.65,36.06],[2,1.67,75.74]],"ltp":1.6,"tv":2763.23,"id":2219}]}]}
{"op":"mcm","clk":"11787143520","pt":1722974902262,"mc":[{"id":"1.231431360","rc":[{"batb":[[1,2.32,28.65],[2,2.14,38.68]],"ltp":0.0,"tv":0.0,"id":31379}]}]}
{"op":"mcm","clk":"11787146043","pt":1722974931833,"mc":[{"id":"1.231431360","rc":[{"batb":[[1,2.34,6.91],[2,2.32,28.65]],"ltp":0.0,"tv":0.0,"id":31379}]}]}
{"op":"mcm","clk":"11787147306","pt":1722974946608,"mc":[{"id":"1.231431360","rc":[{"trd":[[1.64,5.65]],"batl":[[0,1.64,1.73],[1,1.67,75.74],[2,1.7,189.37]],"ltp":1.64,"tv":2768.88,"id":2219}],"tv":2768.88}]}
{"op":"mcm","clk":"11787147508","pt":1722974948831,"mc":[{"id":"1.231431360","rc":[{"batl":[[0,1.66,5.82]],"ltp":1.64,"tv":2768.88,"id":2219}]}]}
{"op":"mcm","clk":"11787148557","pt":1722974961529,"mc":[{"id":"1.231431360","rc":[{"batb":[[1,2.32,28.65],[2,2.14,38.68]],"ltp":0.0,"tv":0.0,"id":31379}]}]}
{"op":"mcm","clk":"11787150285","pt":1722974981524,"mc":[{"id":"1.231431360","rc":[{"batl":[[0,1.65,38.59],[1,1.66,5.82],[2,1.67,75.74]],"ltp":1.64,"tv":2768.88,"id":2219}]}]}
{"op":"mcm","clk":"11787150473","pt":1722974983738,"mc":[{"id":"1.231431360","rc":[{"batl":[[1,1.67,75.74],[2,1.7,189.37]],"ltp":1.64,"tv":2768.88,"id":2219}]}]}
{"op":"mcm","clk":"11787151393","pt":1722974994473,"mc":[{"id":"1.231431360","rc":[{"batb":[[1,2.34,6.91],[2,2.32,28.65]],"ltp":0.0,"tv":0.0,"id":31379}]}]}
{"op":"mcm","clk":"11787155690","pt":1722975047126,"mc":[{"id":"1.231431360","rc":[{"batb":[[2,1.5,360]],"batl":[[1,1.7,189.37],[2,1.72,300]],"ltp":1.64,"tv":2768.88,"id":2219}]}]}
{"op":"mcm","clk":"11787158940","pt":1722975090145,"mc":[{"id":"1.231431360","rc":[{"batb":[[0,1.54,180],[1,1.53,45.08],[2,1.52,187.45]],"ltp":1.64,"tv":2768.88,"id":2219}]}]}
{"op":"mcm","clk":"11787159161","pt":1722975092976,"mc":[{"id":"1.231431360","rc":[{"batl":[[0,1.64,75.74],[1,1.65,38.59],[2,1.7,189.37]],"ltp":1.64,"tv":2768.88,"id":2219}]}]}
{"op":"mcm","clk":"11787160786","pt":1722975116972,"mc":[{"id":"1.231431360","rc":[{"batb":[[1,2.32,28.65],[2,2.14,38.68]],"ltp":0.0,"tv":0.0,"id":31379}]}]}
{"op":"mcm","clk":"11787161364","pt":1722975126192,"mc":[{"id":"1.231431360","rc":[{"batl":[[0,1.63,5.69],[1,1.64,75.74],[2,1.65,38.59]],"ltp":1.64,"tv":2768.88,"id":2219}]}]}
{"op":"mcm","clk":"11787162508","pt":1722975144021,"mc":[{"id":"1.231431360","rc":[{"batb":[[1,2.34,6.91],[2,2.32,28.65]],"ltp":0.0,"tv":0.0,"id":31379}]}]}
{"op":"mcm","clk":"11787162672","pt":1722975146595,"mc":[{"id":"1.231431360","rc":[{"trd":[[1.63,10.28]],"batl":[[0,1.64,76.29],[1,1.65,38.59],[2,1.7,189.37]],"ltp":1.63,"tv":2779.16,"id":2219}],"tv":2779.16}]}
{"op":"mcm","clk":"11787162813","pt":1722975149016,"mc":[{"id":"1.231431360","rc":[{"batb":[[0,1.55,13.52],[1,1.54,180],[2,1.53,45.08]],"ltp":1.63,"tv":2779.16,"id":2219}]}]}
{"op":"mcm","clk":"11787163472","pt":1722975160032,"mc":[{"id":"1.231431360","rc":[{"trd":[[1.63,11.38]],"batl":[[0,1.65,39.14],[1,1.7,189.37],[2,1.72,300]],"ltp":1.63,"tv":2780.26,"id":2219}],"tv":2780.26}]}
{"op":"mcm","clk":"11787165816","pt":1722975199791,"mc":[{"id":"1.231431360","rc":[{"batb":[[0,1.55,27.04]],"ltp":1.63,"tv":2780.26,"id":2219}]}]}
{"op":"mcm","clk":"11787182223","pt":1722975448683,"mc":[{"id":"1.231431360","rc":[{"batb":[[2,1.52,187.45]],"ltp":1.63,"tv":2780.26,"id":2219}]}]}
{"op":"mcm","clk":"11787184499","pt":1722975483494,"mc":[{"id":"1.231431360","rc":[{"batl":[[0,2.84,7.28]],"ltp":0.0,"tv":0.0,"id":31379}]}]}
{"op":"mcm","clk":"11787224888","pt":1722976044539,"mc":[{"id":"1.231431360","rc":[{"batb":[[0,2.34,6.91],[1,2.32,28.65],[2,2.14,38.68]],"ltp":0.0,"tv":0.0,"id":31379},{"batb":[[2,1.52,180]],"ltp":1.63,"tv":2780.26,"id":2219}]}]}
{"op":"mcm","clk":"11787235482","pt":1722976199166,"mc":[{"id":"1.231431360","rc":[{"batb":[[0,1.56,18.04],[1,1.55,27.04],[2,1.54,180]],"ltp":1.63,"tv":2780.26,"id":2219}]}]}
{"op":"mcm","clk":"11787235580","pt":1722976200908,"mc":[{"id":"1.231431360","rc":[{"batb":[[0,1.57,4.1],[1,1.56,18.04]],"ltp":1.63,"tv":2780.26,"id":2219}]}]}
{"op":"mcm","clk":"11787235737","pt":1722976202870,"mc":[{"id":"1.231431360","rc":[{"batl":[[0,1.65,38.59]],"ltp":1.63,"tv":2780.26,"id":2219}]}]}
{"op":"mcm","clk":"11787236531","pt":1722976215096,"mc":[{"id":"1.231431360","rc":[{"batb":[[1,1.54,180],[2,1.52,180]],"ltp":1.63,"tv":2780.26,"id":2219}]}]}
{"op":"mcm","clk":"11787236578","pt":1722976215914,"mc":[{"id":"1.231431360","rc":[{"batl":[[0,2.84,7.46]],"ltp":0.0,"tv":0.0,"id":31379},{"batb":[[0,1.55,17.98]],"ltp":1.63,"tv":2780.26,"id":2219}]}]}
{"op":"mcm","clk":"11787238084","pt":1722976241536,"mc":[{"id":"1.231431360","rc":[{"batb":[[0,1.57,18.04],[1,1.55,17.98],[2,1.54,180]],"ltp":1.63,"tv":2780.26,"id":2219}]}]}
{"op":"mcm","clk":"11787238218","pt":1722976243651,"mc":[{"id":"1.231431360","rc":[{"batb":[[1,1.54,180],[2,1.52,180]],"ltp":1.63,"tv":2780.26,"id":2219}]}]}
{"op":"mcm","clk":"11787238226","pt":1722976243758,"mc":[{"id":"1.231431360","rc":[{"batb":[[0,1.58,4.07],[1,1.57,18.04],[2,1.54,180]],"ltp":1.63,"tv":2780.26,"id":2219}]}]}
{"op":"mcm","clk":"11787238631","pt":1722976249632,"mc":[{"id":"1.231431360","rc":[{"batb":[[1,1.54,180],[2,1.52,180]],"ltp":1.63,"tv":2780.26,"id":2219}]}]}
{"op":"mcm","clk":"11787238672","pt":1722976250455,"mc":[{"id":"1.231431360","rc":[{"batb":[[0,1.54,180],[1,1.52,180],[2,1.5,360]],"ltp":1.63,"tv":2780.26,"id":2219}]}]}
{"op":"mcm","clk":"11787239191","pt":1722976259448,"mc":[{"id":"1.231431360","rc":[{"batb":[[0,1.55,8.83],[1,1.54,180],[2,1.52,180]],"ltp":1.63,"tv":2780.26,"id":2219}]}]}
{"op":"mcm","clk":"11787239447","pt":1722976263727,"mc":[{"id":"1.231431360","rc":[{"batl":[[0,2.84,7.65]],"ltp":0.0,"tv":0.0,"id":31379},{"batb":[[0,1.55,26.5]],"ltp":1.63,"tv":2780.26,"id":2219}]}]}
{"op":"mcm","clk":"11787240321","pt":1722976278151,"mc":[{"id":"1.231431360","rc":[{"batb":[[0,1.62,18.04],[1,1.55,26.5],[2,1.54,180]],"ltp":1.63,"tv":2780.26,"id":2219}]}]}
{"op":"mcm","clk":"11787240401","pt":1722976279477,"mc":[{"id":"1.231431360","rc":[{"batb":[[0,1.63,3.95],[1,1.62,18.04]],"ltp":1.63,"tv":2780.26,"id":2219}]}]}
{"op":"mcm","clk":"11787241058","pt":1722976289279,"mc":[{"id":"1.231431360","rc":[{"batb":[[0,2.32,28.65],[1,2.14,38.68],[2,1.74,17.32]],"ltp":0.0,"tv":0.0,"id":31379}]}]}
{"op":"mcm","clk":"11787241317","pt":1722976293491,"mc":[{"id":"1.231431360","rc":[{"batb":[[0,2.54,4],[1,2.52,4],[2,2.32,28.65]],"batl":[[0,2.6,4]],"ltp":0.0,"tv":0.0,"id":31379},{"batb":[[0,1.63,7.95]],"batl":[[0,1.65,42.59]],"ltp":1.63,"tv":2780.26,"id":2219}]}]}
{"op":"mcm","clk":"11787241850","pt":1722976301812,"mc":[{"id":"1.231431360","rc":[{"trd":[[1.63,25.8]],"batb":[[0,1.62,18.78],[1,1.54,180],[2,1.52,180]],"ltp":1.63,"tv":2794.68,"id":2219}],"tv":2794.68}]}
{"op":"mcm","clk":"11787242320","pt":1722976308600,"mc":[{"id":"1.231431360","rc":[{"batb":[[0,1.62,22.78]],"batl":[[0,1.64,4],[1,1.65,42.59],[2,1.7,189.37]],"ltp":1.63,"tv":2794.68,"id":2219}]}]}
{"op":"mcm","clk":"11787242366","pt":1722976309317,"mc":[{"id":"1.231431360","rc":[{"batl":[[0,1.65,38.59],[1,1.7,189.37],[2,1.72,300]],"ltp":1.63,"tv":2794.68,"id":2219}]}]}
{"op":"mcm","clk":"11787242856","pt":1722976318242,"mc":[{"id":"1.231431360","rc":[{"batb":[[0,1.62,4.74],[1,1.56,18.04],[2,1.54,180]],"ltp":1.63,"tv":2794.68,"id":2219}]}]}
{"op":"mcm","clk":"11787242909","pt":1722976318907,"mc":[{"id":"1.231431360","rc":[{"batb":[[0,1.56,18.04],[1,1.54,180],[2,1.52,180]],"ltp":1.63,"tv":2794.68,"id":2219}]}]}
{"op":"mcm","clk":"11787246776","pt":1722976383400,"mc":[{"id":"1.231431360","rc":[{"batl":[[0,2.84,7.28]],"ltp":0.0,"tv":0.0,"id":31379},{"batb":[[0,1.55,13.52]],"ltp":1.63,"tv":2794.68,"id":2219}]}]}
{"op":"mcm","clk":"11787247182","pt":1722976389090,"mc":[{"id":"1.231431360","rc":[{"batb":[[0,1.55,23.02]],"ltp":1.63,"tv":2794.68,"id":2219}]}]}
{"op":"mcm","clk":"11787248551","pt":1722976410708,"mc":[{"id":"1.231431360","rc":[{"batb":[[2,2.34,6.91]],"ltp":0.0,"tv":0.0,"id":31379}]}]}
{"op":"mcm","clk":"11787249323","pt":1722976422808,"mc":[{"id":"1.231431360","rc":[{"batl":[[0,2.84,12.39]],"ltp":0.0,"tv":0.0,"id":31379}]}]}
{"op":"mcm","clk":"11787249410","pt":1722976424714,"mc":[{"id":"1.231431360","rc":[{"batl":[[0,2.84,7.28]],"ltp":0.0,"tv":0.0,"id":31379}]}]}
{"op":"mcm","clk":"11787254669","pt":1722976509544,"mc":[{"id":"1.231431360","rc":[{"batl":[[0,2.84,12.39]],"ltp":0.0,"tv":0.0,"id":31379}]}]}
{"op":"mcm","clk":"11787254782","pt":1722976511151,"mc":[{"id":"1.231431360","rc":[{"batl":[[0,2.84,7.28]],"ltp":0.0,"tv":0.0,"id":31379}]}]}
{"op":"mcm","clk":"11787259653","pt":1722976597406,"mc":[{"id":"1.231431360","rc":[{"batl":[[0,2.84,12.39]],"ltp":0.0,"tv":0.0,"id":31379}]}]}
{"op":"mcm","clk":"11787259756","pt":1722976599099,"mc":[{"id":"1.231431360","rc":[{"batl":[[0,2.84,7.28]],"ltp":0.0,"tv":0.0,"id":31379}]}]}
{"op":"mcm","clk":"11787262840","pt":1722976649977,"mc":[{"id":"1.231431360","rc":[{"trd":[[1.65,4.8]],"batl":[[0,1.65,36.19]],"ltp":1.65,"tv":2799.48,"id":2219}],"tv":2799.48}]}
{"op":"mcm","clk":"11787264658","pt":1722976682916,"mc":[{"id":"1.231431360","rc":[{"batl":[[0,2.84,12.39]],"ltp":0.0,"tv":0.0,"id":31379}]}]}
{"op":"mcm","clk":"11787264769","pt":1722976684507,"mc":[{"id":"1.231431360","rc":[{"batl":[[0,2.84,7.28]],"ltp":0.0,"tv":0.0,"id":31379}]}]}
{"op":"mcm","clk":"11787265763","pt":1722976701054,"mc":[{"id":"1.231431360","rc":[{"trd":[[1.65,9.6]],"batl":[[0,1.65,33.79]],"ltp":1.65,"tv":2804.28,"id":2219}],"tv":2804.28}]}
{"op":"mcm","clk":"11787269641","pt":1722976770390,"mc":[{"id":"1.231431360","rc":[{"batl":[[0,2.84,12.39]],"ltp":0.0,"tv":0.0,"id":31379}]}]}
{"op":"mcm","clk":"11787269724","pt":1722976772333,"mc":[{"id":"1.231431360","rc":[{"batl":[[0,2.84,7.28]],"ltp":0.0,"tv":0.0,"id":31379}]}]}
{"op":"mcm","clk":"11787269968","pt":1722976776599,"mc":[{"id":"1.231431360","rc":[{"trd":[[1.65,14.4]],"batl":[[0,1.65,31.39]],"ltp":1.65,"tv":2809.08,"id":2219}],"tv":2809.08}]}
{"op":"mcm","clk":"11787272689","pt":1722976823552,"mc":[{"id":"1.231431360","rc":[{"trd":[[1.65,19.2]],"batl":[[0,1.65,28.99]],"ltp":1.65,"tv":2813.88,"id":2219}],"tv":2813.88}]}
{"op":"mcm","clk":"11787274477","pt":1722976858083,"mc":[{"id":"1.231431360","rc":[{"batl":[[0,2.84,12.39]],"ltp":0.0,"tv":0.0,"id":31379}]}]}
{"op":"mcm","clk":"11787274583","pt":1722976860389,"mc":[{"id":"1.231431360","rc":[{"batl":[[0,2.84,7.28]],"ltp":0.0,"tv":0.0,"id":31379}]}]}
{"op":"mcm","clk":"11787279084","pt":1722976944371,"mc":[{"id":"1.231431360","rc":[{"batl":[[0,2.84,12.39]],"ltp":0.0,"tv":0.0,"id":31379}]}]}
{"op":"mcm","clk":"11787279174","pt":1722976946373,"mc":[{"id":"1.231431360","rc":[{"batl":[[0,2.84,7.28]],"ltp":0.0,"tv":0.0,"id":31379}]}]}
{"op":"mcm","clk":"11787291941","pt":1722977031080,"mc":[{"id":"1.231431360","rc":[{"batl":[[0,2.84,12.39]],"ltp":0.0,"tv":0.0,"id":31379}]}]}
{"op":"mcm","clk":"11787292032","pt":1722977032464,"mc":[{"id":"1.231431360","rc":[{"batl":[[0,2.84,7.28]],"ltp":0.0,"tv":0.0,"id":31379}]}]}
{"op":"mcm","clk":"11787296773","pt":1722977117503,"mc":[{"id":"1.231431360","rc":[{"batl":[[0,2.84,12.39]],"ltp":0.0,"tv":0.0,"id":31379}]}]}
{"op":"mcm","clk":"11787296863","pt":1722977118892,"mc":[{"id":"1.231431360","rc":[{"batl":[[0,2.84,7.28]],"ltp":0.0,"tv":0.0,"id":31379}]}]}
{"op":"mcm","clk":"11787301613","pt":1722977204070,"mc":[{"id":"1.231431360","rc":[{"batl":[[0,2.84,12.39]],"ltp":0.0,"tv":0.0,"id":31379}]}]}
{"op":"mcm","clk":"11787301671","pt":1722977205560,"mc":[{"id":"1.231431360","rc":[{"batl":[[0,2.84,7.28]],"ltp":0.0,"tv":0.0,"id":31379}]}]}
{"op":"mcm","clk":"11787305477","pt":1722977288940,"mc":[{"id":"1.231431360","rc":[{"batl":[[0,2.84,12.39]],"ltp":0.0,"tv":0.0,"id":31379}]}]}
{"op":"mcm","clk":"11787305550","pt":1722977290477,"mc":[{"id":"1.231431360","rc":[{"batl":[[0,2.84,7.28]],"ltp":0.0,"tv":0.0,"id":31379}]}]}
{"op":"mcm","clk":"11787309235","pt":1722977375045,"mc":[{"id":"1.231431360","rc":[{"batl":[[0,2.84,12.39]],"ltp":0.0,"tv":0.0,"id":31379}]}]}
{"op":"mcm","clk":"11787309334","pt":1722977376843,"mc":[{"id":"1.231431360","rc":[{"batl":[[0,2.84,7.28]],"ltp":0.0,"tv":0.0,"id":31379}]}]}
{"op":"mcm","clk":"11787313129","pt":1722977461427,"mc":[{"id":"1.231431360","rc":[{"batl":[[0,2.84,12.39]],"ltp":0.0,"tv":0.0,"id":31379}]}]}
{"op":"mcm","clk":"11787313214","pt":1722977463228,"mc":[{"id":"1.231431360","rc":[{"batl":[[0,2.84,7.28]],"ltp":0.0,"tv":0.0,"id":31379}]}]}
{"op":"mcm","clk":"11787314942","pt":1722977507271,"mc":[{"id":"1.231431360","rc":[{"batb":[[0,1.58,10],[1,1.55,23.02],[2,1.54,180]],"ltp":1.65,"tv":2813.88,"id":2219}]}]}
{"op":"mcm","clk":"11787314988","pt":1722977508299,"mc":[{"id":"1.231431360","rc":[{"batb":[[1,1.54,180],[2,1.52,180]],"ltp":1.65,"tv":2813.88,"id":2219}]}]}
{"op":"mcm","clk":"11787316312","pt":1722977540685,"mc":[{"id":"1.231431360","rc":[{"batb":[[0,1.54,180],[1,1.52,180],[2,1.5,360]],"ltp":1.65,"tv":2813.88,"id":2219}]}]}
{"op":"mcm","clk":"11787316422","pt":1722977542734,"mc":[{"id":"1.231431360","rc":[{"batb":[[0,1.55,14.53],[1,1.54,180],[2,1.52,180]],"ltp":1.65,"tv":2813.88,"id":2219}]}]}
{"op":"mcm","clk":"11787316564","pt":1722977546231,"mc":[{"id":"1.231431360","rc":[{"batb":[[0,1.55,24.02]],"ltp":1.65,"tv":2813.88,"id":2219}]}]}
{"op":"mcm","clk":"11787316712","pt":1722977550696,"mc":[{"id":"1.231431360","rc":[{"batl":[[0,2.84,12.39]],"ltp":0.0,"tv":0.0,"id":31379}]}]}
{"op":"mcm","clk":"11787316782","pt":1722977552903,"mc":[{"id":"1.231431360","rc":[{"batl":[[0,2.84,7.28]],"ltp":0.0,"tv":0.0,"id":31379}]}]}
{"op":"mcm","clk":"11787316877","pt":1722977555934,"mc":[{"id":"1.231431360","rc":[{"batb":[[0,1.56,10],[1,1.55,24.02],[2,1.54,180]],"ltp":1.65,"tv":2813.88,"id":2219}]}]}
{"op":"mcm","clk":"11787333023","pt":1722978007200,"mc":[{"id":"1.231431360","rc":[{"batb":[[0,2.34,6.92],[1,2.32,28.65],[2,2.14,38.68]],"ltp":0.0,"tv":0.0,"id":31379},{"trd":[[1.59,90.17],[1.6,183.78],[1.61,35.32],[1.63,25.81],[1.64,5.65],[1.65,60.16],[1.66,127.83],[1.67,40.98],[1.69,172.29],[1.7,1236.91],[1.71,517.27]],"batb":[[1,1.55,24.03]],"batl":[[0,1.65,8.51],[1,1.7,189.37]],"ltp":1.65,"tv":2854.92,"id":2219}],"tv":2854.92}]}
{"op":"mcm","clk":"11787333160","pt":1722978010529,"mc":[{"id":"1.231431360","rc":[{"batb":[[0,2.44,6.8],[1,2.34,6.92],[2,2.32,28.65]],"ltp":0.0,"tv":0.0,"id":31379},{"batl":[[1,1.69,9.71],[2,1.7,189.37]],"ltp":1.65,"tv":2854.92,"id":2219}]}]}
{"op":"mcm","clk":"11787343633","pt":1722978283316,"mc":[{"id":"1.231431360","rc":[{"batb":[[1,2.32,28.65],[2,2.14,38.68]],"ltp":0.0,"tv":0.0,"id":31379}]}]}
{"op":"mcm","clk":"11787369197","pt":1722978975668,"mc":[{"id":"1.231431360","rc":[{"batb":[[0,2.32,28.65],[1,2.14,38.68],[2,1.74,17.32]],"ltp":0.0,"tv":0.0,"id":31379},{"batl":[[1,1.67,300],[2,1.68,400]],"ltp":1.65,"tv":2854.92,"id":2219}]}]}
{"op":"mcm","clk":"11787370212","pt":1722979006349,"mc":[{"id":"1.231431360","rc":[{"batl":[[1,1.66,17.23],[2,1.67,300]],"ltp":1.65,"tv":2854.92,"id":2219}]}]}
{"op":"mcm","clk":"11787383871","pt":1722979328409,"mc":[{"id":"1.231431360","rc":[{"batb":[[0,2.52,26.7],[1,2.32,28.65],[2,2.14,38.68]],"ltp":0.0,"tv":0.0,"id":31379},{"batb":[[0,1.56,52.62]],"ltp":1.65,"tv":2854.92,"id":2219}]}]}
{"op":"mcm","clk":"11787383886","pt":1722979328818,"mc":[{"id":"1.231431360","rc":[{"batb":[[1,1.55,9.5]],"ltp":1.65,"tv":2854.92,"id":2219}]}]}
{"op":"mcm","clk":"11787383924","pt":1722979329740,"mc":[{"id":"1.231431360","rc":[{"batb":[[1,1.54,180],[2,1.52,180]],"ltp":1.65,"tv":2854.92,"id":2219}]}]}
{"op":"mcm","clk":"11787392998","pt":1722979575891,"mc":[{"id":"1.231431360","rc":[{"batb":[[0,1.56,10],[1,1.55,43.13],[2,1.54,180]],"ltp":1.65,"tv":2854.92,"id":2219}]}]}
{"op":"mcm","clk":"11787395215","pt":1722979634616,"mc":[{"id":"1.231431360","rc":[{"batb":[[1,1.54,180],[2,1.52,180]],"ltp":1.65,"tv":2854.92,"id":2219}]}]}
{"op":"mcm","clk":"11787395250","pt":1722979635639,"mc":[{"id":"1.231431360","rc":[{"batl":[[0,2.84,7.7]],"ltp":0.0,"tv":0.0,"id":31379}]}]}
{"op":"mcm","clk":"11787395544","pt":1722979643928,"mc":[{"id":"1.231431360","rc":[{"batl":[[0,2.84,12.46]],"ltp":0.0,"tv":0.0,"id":31379}]}]}
{"op":"mcm","clk":"11787397117","pt":1722979687864,"mc":[{"id":"1.231431360","rc":[{"batb":[[1,1.55,43.13],[2,1.54,180]],"ltp":1.65,"tv":2854.92,"id":2219}]}]}
{"op":"mcm","clk":"11787397151","pt":1722979688888,"mc":[{"id":"1.231431360","rc":[{"batl":[[0,2.84,7.7]],"ltp":0.0,"tv":0.0,"id":31379}]}]}
{"op":"mcm","clk":"11787399333","pt":1722979742364,"mc":[{"id":"1.231431360","rc":[{"batb":[[1,1.54,180],[2,1.52,180]],"ltp":1.65,"tv":2854.92,"id":2219}]}]}
{"op":"mcm","clk":"11787399373","pt":1722979743234,"mc":[{"id":"1.231431360","rc":[{"batl":[[0,2.84,7.7]],"ltp":0.0,"tv":0.0,"id":31379}]}]}
{"op":"mcm","clk":"11787399625","pt":1722979750136,"mc":[{"id":"1.231431360","rc":[{"batl":[[0,2.84,12.46]],"ltp":0.0,"tv":0.0,"id":31379}]}]}
{"op":"mcm","clk":"11787401459","pt":1722979796689,"mc":[{"id":"1.231431360","rc":[{"batb":[[1,1.55,43.13],[2,1.54,180]],"ltp":1.65,"tv":2854.92,"id":2219}]}]}
{"op":"mcm","clk":"11787401516","pt":1722979798123,"mc":[{"id":"1.231431360","rc":[{"batl":[[0,2.84,7.7]],"ltp":0.0,"tv":0.0,"id":31379}]}]}
{"op":"mcm","clk":"11787403646","pt":1722979850746,"mc":[{"id":"1.231431360","rc":[{"batb":[[1,1.54,180],[2,1.52,180]],"ltp":1.65,"tv":2854.92,"id":2219}]}]}
{"op":"mcm","clk":"11787403719","pt":1722979852690,"mc":[{"id":"1.231431360","rc":[{"batl":[[0,2.84,7.7]],"ltp":0.0,"tv":0.0,"id":31379}]}]}
{"op":"mcm","clk":"11787403866","pt":1722979856268,"mc":[{"id":"1.231431360","rc":[{"batl":[[0,2.84,12.46]],"ltp":0.0,"tv":0.0,"id":31379}]}]}
{"op":"mcm","clk":"11787405768","pt":1722979904608,"mc":[{"id":"1.231431360","rc":[{"batb":[[1,1.55,43.13],[2,1.54,180]],"ltp":1.65,"tv":2854.92,"id":2219}]}]}
{"op":"mcm","clk":"11787405861","pt":1722979906505,"mc":[{"id":"1.231431360","rc":[{"batl":[[0,2.84,7.7]],"ltp":0.0,"tv":0.0,"id":31379}]}]}
{"op":"mcm","clk":"11787407988","pt":1722979959873,"mc":[{"id":"1.231431360","rc":[{"batb":[[1,1.54,180],[2,1.52,180]],"ltp":1.65,"tv":2854.92,"id":2219}]}]}
{"op":"mcm","clk":"11787408044","pt":1722979961364,"mc":[{"id":"1.231431360","rc":[{"batl":[[0,2.84,7.7]],"ltp":0.0,"tv":0.0,"id":31379}]}]}
{"op":"mcm","clk":"11787408117","pt":1722979963262,"mc":[{"id":"1.231431360","rc":[{"batl":[[0,2.84,12.46]],"ltp":0.0,"tv":0.0,"id":31379}]}]}
{"op":"mcm","clk":"11787410128","pt":1722980016644,"mc":[{"id":"1.231431360","rc":[{"batl":[[0,2.84,7.7]],"ltp":0.0,"tv":0.0,"id":31379},{"batb":[[1,1.55,43.13],[2,1.54,180]],"ltp":1.65,"tv":2854.92,"id":2219}]}]}
{"op":"mcm","clk":"11787412692","pt":1722980074480,"mc":[{"id":"1.231431360","rc":[{"batb":[[1,1.54,180],[2,1.52,180]],"ltp":1.65,"tv":2854.92,"id":2219}]}]}
{"op":"mcm","clk":"11787412744","pt":1722980075811,"mc":[{"id":"1.231431360","rc":[{"batl":[[0,2.84,7.7]],"ltp":0.0,"tv":0.0,"id":31379}]}]}
{"op":"mcm","clk":"11787413094","pt":1722980083394,"mc":[{"id":"1.231431360","rc":[{"batl":[[0,2.84,12.46]],"ltp":0.0,"tv":0.0,"id":31379}]}]}
{"op":"mcm","clk":"11787415033","pt":1722980131175,"mc":[{"id":"1.231431360","rc":[{"batb":[[1,1.55,43.13],[2,1.54,180]],"ltp":1.65,"tv":2854.92,"id":2219}]}]}
{"op":"mcm","clk":"11787415077","pt":1722980132349,"mc":[{"id":"1.231431360","rc":[{"batl":[[0,2.84,7.7]],"ltp":0.0,"tv":0.0,"id":31379}]}]}
{"op":"mcm","clk":"11787416876","pt":1722980185526,"mc":[{"id":"1.231431360","rc":[{"batb":[[1,1.54,180],[2,1.52,180]],"ltp":1.65,"tv":2854.92,"id":2219}]}]}
{"op":"mcm","clk":"11787416986","pt":1722980189002,"mc":[{"id":"1.231431360","rc":[{"batl":[[0,2.84,12.46]],"ltp":0.0,"tv":0.0,"id":31379}]}]}
{"op":"mcm","clk":"11787418673","pt":1722980238381,"mc":[{"id":"1.231431360","rc":[{"batb":[[1,1.55,43.13],[2,1.54,180]],"ltp":1.65,"tv":2854.92,"id":2219}]}]}
{"op":"mcm","clk":"11787418702","pt":1722980239604,"mc":[{"id":"1.231431360","rc":[{"batl":[[0,2.84,7.7]],"ltp":0.0,"tv":0.0,"id":31379}]}]}
{"op":"mcm","clk":"11787420382","pt":1722980291537,"mc":[{"id":"1.231431360","rc":[{"batb":[[1,1.54,180],[2,1.52,180]],"ltp":1.65,"tv":2854.92,"id":2219}]}]}
{"op":"mcm","clk":"11787420442","pt":1722980293123,"mc":[{"id":"1.231431360","rc":[{"batl":[[0,2.84,7.7]],"ltp":0.0,"tv":0.0,"id":31379}]}]}
{"op":"mcm","clk":"11787420569","pt":1722980296814,"mc":[{"id":"1.231431360","rc":[{"batl":[[0,2.84,12.46]],"ltp":0.0,"tv":0.0,"id":31379}]}]}
{"op":"mcm","clk":"11787422148","pt":1722980343395,"mc":[{"id":"1.231431360","rc":[{"batb":[[1,1.55,43.13],[2,1.54,180]],"ltp":1.65,"tv":2854.92,"id":2219}]}]}
{"op":"mcm","clk":"11787422196","pt":1722980344676,"mc":[{"id":"1.231431360","rc":[{"batl":[[0,2.84,7.7]],"ltp":0.0,"tv":0.0,"id":31379}]}]}
{"op":"mcm","clk":"11787423728","pt":1722980388914,"mc":[{"id":"1.231431360","rc":[{"batb":[[1,2.36,6.88],[2,2.32,28.65]],"ltp":0.0,"tv":0.0,"id":31379}]}]}
{"op":"mcm","clk":"11787423951","pt":1722980396641,"mc":[{"id":"1.231431360","rc":[{"batl":[[0,2.84,7.7]],"ltp":0.0,"tv":0.0,"id":31379},{"batb":[[1,1.54,180],[2,1.52,180]],"ltp":1.65,"tv":2854.92,"id":2219}]}]}
{"op":"mcm","clk":"11787424148","pt":1722980402541,"mc":[{"id":"1.231431360","rc":[{"batl":[[0,2.84,12.46]],"ltp":0.0,"tv":0.0,"id":31379}]}]}
{"op":"mcm","clk":"11787424663","pt":1722980419174,"mc":[{"id":"1.231431360","rc":[{"batb":[[1,2.32,28.65],[2,2.14,38.68]],"ltp":0.0,"tv":0.0,"id":31379}]}]}
{"op":"mcm","clk":"11787425494","pt":1722980448069,"mc":[{"id":"1.231431360","rc":[{"batb":[[1,1.55,43.13],[2,1.54,180]],"ltp":1.65,"tv":2854.92,"id":2219}]}]}
{"op":"mcm","clk":"11787425522","pt":1722980449297,"mc":[{"id":"1.231431360","rc":[{"batl":[[0,2.84,7.7]],"ltp":0.0,"tv":0.0,"id":31379}]}]}
{"op":"mcm","clk":"11787426421","pt":1722980480000,"mc":[{"id":"1.231431360","rc":[{"batb":[[1,2.36,6.86],[2,2.32,28.65]],"ltp":0.0,"tv":0.0,"id":31379}]}]}
{"op":"mcm","clk":"11787427132","pt":1722980501318,"mc":[{"id":"1.231431360","rc":[{"batb":[[1,1.54,180],[2,1.52,180]],"ltp":1.65,"tv":2854.92,"id":2219}]}]}
{"op":"mcm","clk":"11787427191","pt":1722980502950,"mc":[{"id":"1.231431360","rc":[{"batl":[[0,2.84,7.7]],"ltp":0.0,"tv":0.0,"id":31379}]}]}
{"op":"mcm","clk":"11787427396","pt":1722980509350,"mc":[{"id":"1.231431360","rc":[{"batl":[[0,2.84,12.46]],"ltp":0.0,"tv":0.0,"id":31379}]}]}
{"op":"mcm","clk":"11787428905","pt":1722980555297,"mc":[{"id":"1.231431360","rc":[{"batb":[[1,1.55,43.13],[2,1.54,180]],"ltp":1.65,"tv":2854.92,"id":2219}]}]}
{"op":"mcm","clk":"11787428938","pt":1722980556475,"mc":[{"id":"1.231431360","rc":[{"batl":[[0,2.84,7.7]],"ltp":0.0,"tv":0.0,"id":31379}]}]}
{"op":"mcm","clk":"11787430331","pt":1722980601016,"mc":[{"id":"1.231431360","rc":[{"batb":[[1,2.32,28.65],[2,2.14,38.68]],"ltp":0.0,"tv":0.0,"id":31379}]}]}
{"op":"mcm","clk":"11787430720","pt":1722980610963,"mc":[{"id":"1.231431360","rc":[{"batb":[[1,1.54,180],[2,1.52,180]],"ltp":1.65,"tv":2854.92,"id":2219}]}]}
{"op":"mcm","clk":"11787430805","pt":1722980613167,"mc":[{"id":"1.231431360","rc":[{"batl":[[0,2.84,7.7]],"ltp":0.0,"tv":0.0,"id":31379}]}]}
{"op":"mcm","clk":"11787430831","pt":1722980613936,"mc":[{"id":"1.231431360","rc":[{"batl":[[0,2.84,12.46]],"ltp":0.0,"tv":0.0,"id":31379}]}]}
{"op":"mcm","clk":"11787432720","pt":1722980665405,"mc":[{"id":"1.231431360","rc":[{"batb":[[1,1.55,43.13],[2,1.54,180]],"ltp":1.65,"tv":2854.92,"id":2219}]}]}
{"op":"mcm","clk":"11787432792","pt":1722980667299,"mc":[{"id":"1.231431360","rc":[{"batl":[[0,2.84,7.7]],"ltp":0.0,"tv":0.0,"id":31379}]}]}
{"op":"mcm","clk":"11787434865","pt":1722980724460,"mc":[{"id":"1.231431360","rc":[{"batb":[[1,1.54,180],[2,1.52,180]],"ltp":1.65,"tv":2854.92,"id":2219}]}]}
{"op":"mcm","clk":"11787434918","pt":1722980726047,"mc":[{"id":"1.231431360","rc":[{"batl":[[0,2.84,7.7]],"ltp":0.0,"tv":0.0,"id":31379}]}]}
{"op":"mcm","clk":"11787435214","pt":1722980733579,"mc":[{"id":"1.231431360","rc":[{"batl":[[0,2.84,12.46]],"ltp":0.0,"tv":0.0,"id":31379}]}]}
{"op":"mcm","clk":"11787437193","pt":1722980781547,"mc":[{"id":"1.231431360","rc":[{"batb":[[1,1.55,43.13],[2,1.54,180]],"ltp":1.65,"tv":2854.92,"id":2219}]}]}
{"op":"mcm","clk":"11787437247","pt":1722980782739,"mc":[{"id":"1.231431360","rc":[{"batl":[[0,2.84,7.7]],"ltp":0.0,"tv":0.0,"id":31379}]}]}
{"op":"mcm","clk":"11787439356","pt":1722980836511,"mc":[{"id":"1.231431360","rc":[{"batb":[[1,1.54,180],[2,1.52,180]],"ltp":1.65,"tv":2854.92,"id":2219}]}]}
{"op":"mcm","clk":"11787439526","pt":1722980841126,"mc":[{"id":"1.231431360","rc":[{"batl":[[0,2.84,12.46]],"ltp":0.0,"tv":0.0,"id":31379}]}]}
{"op":"mcm","clk":"11787441195","pt":1722980888571,"mc":[{"id":"1.231431360","rc":[{"batb":[[1,1.55,43.13],[2,1.54,180]],"ltp":1.65,"tv":2854.92,"id":2219}]}]}
{"op":"mcm","clk":"11787441215","pt":1722980889288,"mc":[{"id":"1.231431360","rc":[{"batl":[[0,2.84,7.7]],"ltp":0.0,"tv":0.0,"id":31379}]}]}
{"op":"mcm","clk":"11787443465","pt":1722980940443,"mc":[{"id":"1.231431360","rc":[{"batb":[[1,1.54,180],[2,1.52,180]],"ltp":1.65,"tv":2854.92,"id":2219}]}]}
{"op":"mcm","clk":"11787443524","pt":1722980941828,"mc":[{"id":"1.231431360","rc":[{"batl":[[0,2.84,7.7]],"ltp":0.0,"tv":0.0,"id":31379}]}]}
{"op":"mcm","clk":"11787443735","pt":1722980947406,"mc":[{"id":"1.231431360","rc":[{"batl":[[0,2.84,12.46]],"ltp":0.0,"tv":0.0,"id":31379}]}]}
{"op":"mcm","clk":"11787445495","pt":1722980994070,"mc":[{"id":"1.231431360","rc":[{"batb":[[1,1.55,43.13],[2,1.54,180]],"ltp":1.65,"tv":2854.92,"id":2219}]}]}
{"op":"mcm","clk":"11787445582","pt":1722980996068,"mc":[{"id":"1.231431360","rc":[{"batl":[[0,2.84,7.7]],"ltp":0.0,"tv":0.0,"id":31379}]}]}
{"op":"mcm","clk":"11787447713","pt":1722981047557,"mc":[{"id":"1.231431360","rc":[{"batb":[[1,1.54,180],[2,1.52,180]],"ltp":1.65,"tv":2854.92,"id":2219}]}]}
{"op":"mcm","clk":"11787447806","pt":1722981049465,"mc":[{"id":"1.231431360","rc":[{"batl":[[0,2.84,7.7]],"ltp":0.0,"tv":0.0,"id":31379}]}]}
{"op":"mcm","clk":"11787448090","pt":1722981056469,"mc":[{"id":"1.231431360","rc":[{"batl":[[0,2.84,12.46]],"ltp":0.0,"tv":0.0,"id":31379}]}]}
{"op":"mcm","clk":"11787449777","pt":1722981098578,"mc":[{"id":"1.231431360","rc":[{"batb":[[1,1.55,43.13],[2,1.54,180]],"ltp":1.65,"tv":2854.92,"id":2219}]}]}
{"op":"mcm","clk":"11787449830","pt":1722981100010,"mc":[{"id":"1.231431360","rc":[{"batl":[[0,2.84,7.7]],"ltp":0.0,"tv":0.0,"id":31379}]}]}
{"op":"mcm","clk":"11787451983","pt":1722981156987,"mc":[{"id":"1.231431360","rc":[{"batb":[[1,1.54,180],[2,1.52,180]],"ltp":1.65,"tv":2854.92,"id":2219}]}]}
{"op":"mcm","clk":"11787452055","pt":1722981158988,"mc":[{"id":"1.231431360","rc":[{"batl":[[0,2.84,7.7]],"ltp":0.0,"tv":0.0,"id":31379}]}]}
{"op":"mcm","clk":"11787452221","pt":1722981163697,"mc":[{"id":"1.231431360","rc":[{"batl":[[0,2.84,12.46]],"ltp":0.0,"tv":0.0,"id":31379}]}]}
{"op":"mcm","clk":"11787454125","pt":1722981213264,"mc":[{"id":"1.231431360","rc":[{"batb":[[1,1.55,43.13],[2,1.54,180]],"ltp":1.65,"tv":2854.92,"id":2219}]}]}
{"op":"mcm","clk":"11787454186","pt":1722981214953,"mc":[{"id":"1.231431360","rc":[{"batl":[[0,2.84,7.7]],"ltp":0.0,"tv":0.0,"id":31379}]}]}
{"op":"mcm","clk":"11787456795","pt":1722981273899,"mc":[{"id":"1.231431360","rc":[{"batb":[[1,1.54,180],[2,1.52,180]],"ltp":1.65,"tv":2854.92,"id":2219}]}]}
{"op":"mcm","clk":"11787456826","pt":1722981274718,"mc":[{"id":"1.231431360","rc":[{"batl":[[0,2.84,7.7]],"ltp":0.0,"tv":0.0,"id":31379}]}]}
{"op":"mcm","clk":"11787457073","pt":1722981280819,"mc":[{"id":"1.231431360","rc":[{"batl":[[0,2.84,12.46]],"ltp":0.0,"tv":0.0,"id":31379}]}]}
{"op":"mcm","clk":"11787458960","pt":1722981327799,"mc":[{"id":"1.231431360","rc":[{"batb":[[1,2.36,6.88],[2,2.32,28.65]],"ltp":0.0,"tv":0.0,"id":31379}]}]}
{"op":"mcm","clk":"11787459578","pt":1722981343550,"mc":[{"id":"1.231431360","rc":[{"batb":[[1,1.55,43.13],[2,1.54,180]],"ltp":1.65,"tv":2854.92,"id":2219}]}]}
{"op":"mcm","clk":"11787459607","pt":1722981344321,"mc":[{"id":"1.231431360","rc":[{"batl":[[0,2.84,7.7]],"ltp":0.0,"tv":0.0,"id":31379}]}]}
{"op":"mcm","clk":"11787462260","pt":1722981409499,"mc":[{"id":"1.231431360","rc":[{"batb":[[1,1.54,180],[2,1.52,180]],"ltp":1.65,"tv":2854.92,"id":2219}]}]}
{"op":"mcm","clk":"11787462458","pt":1722981413703,"mc":[{"id":"1.231431360","rc":[{"batl":[[0,2.84,12.46]],"ltp":0.0,"tv":0.0,"id":31379}]}]}
{"op":"mcm","clk":"11787464703","pt":1722981463452,"mc":[{"id":"1.231431360","rc":[{"batl":[[0,2.84,7.7]],"ltp":0.0,"tv":0.0,"id":31379},{"batb":[[1,1.55,43.13],[2,1.54,180]],"ltp":1.65,"tv":2854.92,"id":2219}]}]}
{"op":"mcm","clk":"11787467049","pt":1722981516582,"mc":[{"id":"1.231431360","rc":[{"batb":[[1,1.54,180],[2,1.52,180]],"ltp":1.65,"tv":2854.92,"id":2219}]}]}
{"op":"mcm","clk":"11787467170","pt":1722981519400,"mc":[{"id":"1.231431360","rc":[{"batl":[[0,2.84,12.46]],"ltp":0.0,"tv":0.0,"id":31379}]}]}
{"op":"mcm","clk":"11787469160","pt":1722981567553,"mc":[{"id":"1.231431360","rc":[{"batb":[[1,1.55,43.13],[2,1.54,180]],"ltp":1.65,"tv":2854.92,"id":2219}]}]}
{"op":"mcm","clk":"11787469190","pt":1722981568372,"mc":[{"id":"1.231431360","rc":[{"batl":[[0,2.84,7.7]],"ltp":0.0,"tv":0.0,"id":31379}]}]}
{"op":"mcm","clk":"11787469718","pt":1722981581380,"mc":[{"id":"1.231431360","rc":[{"trd":[[1.56,0.2]],"batb":[[0,1.56,9.9]],"ltp":1.56,"tv":2855.12,"id":2219}],"tv":2855.12}]}
{"op":"mcm","clk":"11787470447","pt":1722981597829,"mc":[{"id":"1.231431360","rc":[{"trd":[[1.56,0.44]],"batb":[[0,1.56,9.78]],"ltp":1.56,"tv":2855.36,"id":2219}],"tv":2855.36}]}
{"op":"mcm","clk":"11787471761","pt":1722981620932,"mc":[{"id":"1.231431360","rc":[{"batb":[[0,2.52,26.7],[1,2.36,6.88]],"ltp":0.0,"tv":0.0,"id":31379},{"trd":[[1.59,90.17],[1.6,183.77],[1.61,35.31],[1.63,25.8],[1.64,5.65],[1.66,127.8],[1.67,40.96],[1.69,172.27],[1.7,1236.78],[1.71,517.25],[1.85,15.45]],"batb":[[1,1.54,180],[2,1.52,180]],"batl":[[1,1.66,17.22]],"ltp":1.56,"tv":2855.12,"id":2219}],"tv":2855.12}]}
{"op":"mcm","clk":"11787471836","pt":1722981622621,"mc":[{"id":"1.231431360","rc":[{"batl":[[0,2.84,7.69]],"ltp":0.0,"tv":0.0,"id":31379}]}]}
{"op":"mcm","clk":"11787471991","pt":1722981626355,"mc":[{"id":"1.231431360","rc":[{"batl":[[0,2.84,12.45]],"ltp":0.0,"tv":0.0,"id":31379}]}]}
{"op":"mcm","clk":"11787472591","pt":1722981639776,"mc":[{"id":"1.231431360","rc":[{"trd":[[1.65,60.44]],"batl":[[0,1.65,8.37]],"ltp":1.65,"tv":2855.4,"id":2219}],"tv":2855.4}]}
{"op":"mcm","clk":"11787474071","pt":1722981674777,"mc":[{"id":"1.231431360","rc":[{"batb":[[1,1.55,43.14],[2,1.54,180]],"ltp":1.65,"tv":2855.4,"id":2219}]}]}
{"op":"mcm","clk":"11787474167","pt":1722981676323,"mc":[{"id":"1.231431360","rc":[{"batl":[[0,2.84,7.69]],"ltp":0.0,"tv":0.0,"id":31379}]}]}
{"op":"mcm","clk":"11787476576","pt":1722981728093,"mc":[{"id":"1.231431360","rc":[{"batb":[[1,1.54,180],[2,1.52,180]],"ltp":1.65,"tv":2855.4,"id":2219}]}]}
{"op":"mcm","clk":"11787476632","pt":1722981729172,"mc":[{"id":"1.231431360","rc":[{"batl":[[0,2.84,7.69]],"ltp":0.0,"tv":0.0,"id":31379}]}]}
{"op":"mcm","clk":"11787476856","pt":1722981733778,"mc":[{"id":"1.231431360","rc":[{"batl":[[0,2.84,12.45]],"ltp":0.0,"tv":0.0,"id":31379}]}]}
{"op":"mcm","clk":"11787479024","pt":1722981782447,"mc":[{"id":"1.231431360","rc":[{"batb":[[1,1.55,43.14],[2,1.54,180]],"ltp":1.65,"tv":2855.4,"id":2219}]}]}
{"op":"mcm","clk":"11787479115","pt":1722981784449,"mc":[{"id":"1.231431360","rc":[{"batl":[[0,2.84,7.69]],"ltp":0.0,"tv":0.0,"id":31379}]}]}
{"op":"mcm","clk":"11787481403","pt":1722981836427,"mc":[{"id":"1.231431360","rc":[{"batb":[[1,1.54,180],[2,1.52,180]],"ltp":1.65,"tv":2855.4,"id":2219}]}]}
{"op":"mcm","clk":"11787481443","pt":1722981837297,"mc":[{"id":"1.231431360","rc":[{"batl":[[0,2.84,7.69]],"ltp":0.0,"tv":0.0,"id":31379}]}]}
{"op":"mcm","clk":"11787481634","pt":1722981842428,"mc":[{"id":"1.231431360","rc":[{"batl":[[0,2.84,12.45]],"ltp":0.0,"tv":0.0,"id":31379}]}]}
{"op":"mcm","clk":"11787483754","pt":1722981891949,"mc":[{"id":"1.231431360","rc":[{"batb":[[1,1.55,43.14],[2,1.54,180]],"ltp":1.65,"tv":2855.4,"id":2219}]}]}
{"op":"mcm","clk":"11787483795","pt":1722981892770,"mc":[{"id":"1.231431360","rc":[{"batl":[[0,2.84,7.69]],"ltp":0.0,"tv":0.0,"id":31379}]}]}
{"op":"mcm","clk":"11787486092","pt":1722981948840,"mc":[{"id":"1.231431360","rc":[{"batb":[[1,1.54,180],[2,1.52,180]],"ltp":1.65,"tv":2855.4,"id":2219}]}]}
{"op":"mcm","clk":"11787486153","pt":1722981950017,"mc":[{"id":"1.231431360","rc":[{"batl":[[0,2.84,12.72]],"ltp":0.0,"tv":0.0,"id":31379}]}]}
{"op":"mcm","clk":"11787489028","pt":1722982012739,"mc":[{"id":"1.231431360","rc":[{"batb":[[1,1.55,43.14],[2,1.54,180]],"ltp":1.65,"tv":2855.4,"id":2219}]}]}
{"op":"mcm","clk":"11787489090","pt":1722982014427,"mc":[{"id":"1.231431360","rc":[{"batl":[[0,2.84,7.69]],"ltp":0.0,"tv":0.0,"id":31379}]}]}
{"op":"mcm","clk":"11787491591","pt":1722982069648,"mc":[{"id":"1.231431360","rc":[{"batb":[[1,1.54,180],[2,1.52,180]],"ltp":1.65,"tv":2855.4,"id":2219}]}]}
{"op":"mcm","clk":"11787491700","pt":1722982071648,"mc":[{"id":"1.231431360","rc":[{"batl":[[0,2.84,7.69]],"ltp":0.0,"tv":0.0,"id":31379}]}]}
{"op":"mcm","clk":"11787492006","pt":1722982078261,"mc":[{"id":"1.231431360","rc":[{"batl":[[0,2.84,12.45]],"ltp":0.0,"tv":0.0,"id":31379}]}]}
{"op":"mcm","clk":"11787494118","pt":1722982123324,"mc":[{"id":"1.231431360","rc":[{"batb":[[1,1.55,43.14],[2,1.54,180]],"ltp":1.65,"tv":2855.4,"id":2219}]}]}
{"op":"mcm","clk":"11787494158","pt":1722982123938,"mc":[{"id":"1.231431360","rc":[{"batl":[[0,2.84,7.69]],"ltp":0.0,"tv":0.0,"id":31379}]}]}
{"op":"mcm","clk":"11787496471","pt":1722982176970,"mc":[{"id":"1.231431360","rc":[{"batb":[[1,1.54,180],[2,1.52,180]],"ltp":1.65,"tv":2855.4,"id":2219}]}]}
{"op":"mcm","clk":"11787496591","pt":1722982179228,"mc":[{"id":"1.231431360","rc":[{"batl":[[0,2.84,7.69]],"ltp":0.0,"tv":0.0,"id":31379}]}]}
{"op":"mcm","clk":"11787496906","pt":1722982185787,"mc":[{"id":"1.231431360","rc":[{"batl":[[0,2.84,12.45]],"ltp":0.0,"tv":0.0,"id":31379}]}]}
{"op":"mcm","clk":"11787499053","pt":1722982229934,"mc":[{"id":"1.231431360","rc":[{"batb":[[1,1.55,43.14],[2,1.54,180]],"ltp":1.65,"tv":2855.4,"id":2219}]}]}
{"op":"mcm","clk":"11787499115","pt":1722982231279,"mc":[{"id":"1.231431360","rc":[{"batl":[[0,2.84,7.69]],"ltp":0.0,"tv":0.0,"id":31379}]}]}
{"op":"mcm","clk":"11787501637","pt":1722982284531,"mc":[{"id":"1.231431360","rc":[{"batb":[[1,1.54,180],[2,1.52,180]],"ltp":1.65,"tv":2855.4,"id":2219}]}]}
{"op":"mcm","clk":"11787502096","pt":1722982295143,"mc":[{"id":"1.231431360","rc":[{"batl":[[0,2.84,12.45]],"ltp":0.0,"tv":0.0,"id":31379}]}]}
{"op":"mcm","clk":"11787504202","pt":1722982337797,"mc":[{"id":"1.231431360","rc":[{"batb":[[1,1.55,43.14],[2,1.54,180]],"ltp":1.65,"tv":2855.4,"id":2219}]}]}
{"op":"mcm","clk":"11787504273","pt":1722982339079,"mc":[{"id":"1.231431360","rc":[{"batl":[[0,2.84,7.69]],"ltp":0.0,"tv":0.0,"id":31379}]}]}
{"op":"mcm","clk":"11787514521","pt":1722982391963,"mc":[{"id":"1.231431360","rc":[{"batb":[[1,1.54,180],[2,1.52,180]],"ltp":1.65,"tv":2855.4,"id":2219}]}]}
{"op":"mcm","clk":"11787514576","pt":1722982393348,"mc":[{"id":"1.231431360","rc":[{"batl":[[0,2.84,7.69]],"ltp":0.0,"tv":0.0,"id":31379}]}]}
{"op":"mcm","clk":"11787515008","pt":1722982401153,"mc":[{"id":"1.231431360","rc":[{"batl":[[0,2.84,12.45]],"ltp":0.0,"tv":0.0,"id":31379}]}]}
{"op":"mcm","clk":"11787517214","pt":1722982446628,"mc":[{"id":"1.231431360","rc":[{"batb":[[1,1.55,43.14],[2,1.54,180]],"ltp":1.65,"tv":2855.4,"id":2219}]}]}
{"op":"mcm","clk":"11787517257","pt":1722982447608,"mc":[{"id":"1.231431360","rc":[{"batl":[[0,2.84,7.69]],"ltp":0.0,"tv":0.0,"id":31379}]}]}
{"op":"mcm","clk":"11787519597","pt":1722982500076,"mc":[{"id":"1.231431360","rc":[{"batb":[[1,1.54,180],[2,1.52,180]],"ltp":1.65,"tv":2855.4,"id":2219}]}]}
{"op":"mcm","clk":"11787519659","pt":1722982501406,"mc":[{"id":"1.231431360","rc":[{"batl":[[0,2.84,7.69]],"ltp":0.0,"tv":0.0,"id":31379}]}]}
{"op":"mcm","clk":"11787520103","pt":1722982510592,"mc":[{"id":"1.231431360","rc":[{"batl":[[0,2.84,12.45]],"ltp":0.0,"tv":0.0,"id":31379}]}]}
{"op":"mcm","clk":"11787522001","pt":1722982556183,"mc":[{"id":"1.231431360","rc":[{"batb":[[1,1.55,43.14],[2,1.54,180]],"ltp":1.65,"tv":2855.4,"id":2219}]}]}
{"op":"mcm","clk":"11787522058","pt":1722982557670,"mc":[{"id":"1.231431360","rc":[{"batl":[[0,2.84,7.69]],"ltp":0.0,"tv":0.0,"id":31379}]}]}
{"op":"mcm","clk":"11787524665","pt":1722982618150,"mc":[{"id":"1.231431360","rc":[{"batb":[[1,1.54,180],[2,1.52,180]],"ltp":1.65,"tv":2855.4,"id":2219}]}]}
{"op":"mcm","clk":"11787524711","pt":1722982619326,"mc":[{"id":"1.231431360","rc":[{"batl":[[0,2.84,7.69]],"ltp":0.0,"tv":0.0,"id":31379}]}]}
{"op":"mcm","clk":"11787525015","pt":1722982625932,"mc":[{"id":"1.231431360","rc":[{"batl":[[0,2.84,12.45]],"ltp":0.0,"tv":0.0,"id":31379}]}]}
{"op":"mcm","clk":"11787527214","pt":1722982674196,"mc":[{"id":"1.231431360","rc":[{"batb":[[1,1.55,43.14],[2,1.54,180]],"ltp":1.65,"tv":2855.4,"id":2219}]}]}
{"op":"mcm","clk":"11787527273","pt":1722982675418,"mc":[{"id":"1.231431360","rc":[{"batl":[[0,2.84,7.69]],"ltp":0.0,"tv":0.0,"id":31379}]}]}
{"op":"mcm","clk":"11787529469","pt":1722982730176,"mc":[{"id":"1.231431360","rc":[{"batb":[[1,1.54,180],[2,1.52,180]],"ltp":1.65,"tv":2855.4,"id":2219}]}]}
{"op":"mcm","clk":"11787529502","pt":1722982730941,"mc":[{"id":"1.231431360","rc":[{"batl":[[0,2.84,5.03]],"ltp":0.0,"tv":0.0,"id":31379}]}]}
{"op":"mcm","clk":"11787529535","pt":1722982731961,"mc":[{"id":"1.231431360","rc":[{"batl":[[0,2.84,12.31]],"ltp":0.0,"tv":0.0,"id":31379}]}]}
{"op":"mcm","clk":"11787531731","pt":1722982783900,"mc":[{"id":"1.231431360","rc":[{"batb":[[1,1.55,43.14],[2,1.54,180]],"ltp":1.65,"tv":2855.4,"id":2219}]}]}
{"op":"mcm","clk":"11787534024","pt":1722982838439,"mc":[{"id":"1.231431360","rc":[{"batb":[[1,2.32,28.65],[2,2.14,38.68]],"ltp":0.0,"tv":0.0,"id":31379},{"batb":[[1,1.54,180],[2,1.52,180]],"ltp":1.65,"tv":2855.4,"id":2219}]}]}
{"op":"mcm","clk":"11787534045","pt":1722982838851,"mc":[{"id":"1.231431360","rc":[{"batl":[[0,2.84,5.03]],"ltp":0.0,"tv":0.0,"id":31379}]}]}
{"op":"mcm","clk":"11787534111","pt":1722982840280,"mc":[{"id":"1.231431360","rc":[{"batl":[[0,2.84,12.31]],"ltp":0.0,"tv":0.0,"id":31379}]}]}
{"op":"mcm","clk":"11787537092","pt":1722982892632,"mc":[{"id":"1.231431360","rc":[{"batl":[[0,2.84,7.28]],"ltp":0.0,"tv":0.0,"id":31379},{"batb":[[1,1.55,43.14],[2,1.54,180]],"ltp":1.65,"tv":2855.4,"id":2219}]}]}
{"op":"mcm","clk":"11787539574","pt":1722982948811,"mc":[{"id":"1.231431360","rc":[{"batb":[[1,1.54,180],[2,1.52,180]],"ltp":1.65,"tv":2855.4,"id":2219}]}]}
{"op":"mcm","clk":"11787539688","pt":1722982951306,"mc":[{"id":"1.231431360","rc":[{"batl":[[0,2.84,7.69]],"ltp":0.0,"tv":0.0,"id":31379}]}]}
{"op":"mcm","clk":"11787539938","pt":1722982957715,"mc":[{"id":"1.231431360","rc":[{"batl":[[0,2.84,12.45]],"ltp":0.0,"tv":0.0,"id":31379}]}]}
{"op":"mcm","clk":"11787541866","pt":1722983003639,"mc":[{"id":"1.231431360","rc":[{"batb":[[1,1.55,43.14],[2,1.54,180]],"ltp":1.65,"tv":2855.4,"id":2219}]}]}
{"op":"mcm","clk":"11787541931","pt":1722983005230,"mc":[{"id":"1.231431360","rc":[{"batl":[[0,2.84,7.69]],"ltp":0.0,"tv":0.0,"id":31379}]}]}
{"op":"mcm","clk":"11787544079","pt":1722983059644,"mc":[{"id":"1.231431360","rc":[{"batb":[[1,1.54,180],[2,1.52,180]],"ltp":1.65,"tv":2855.4,"id":2219}]}]}
{"op":"mcm","clk":"11787544101","pt":1722983060207,"mc":[{"id":"1.231431360","rc":[{"batl":[[0,2.84,7.69]],"ltp":0.0,"tv":0.0,"id":31379}]}]}
{"op":"mcm","clk":"11787544209","pt":1722983063429,"mc":[{"id":"1.231431360","rc":[{"batl":[[0,2.84,12.45]],"ltp":0.0,"tv":0.0,"id":31379}]}]}
{"op":"mcm","clk":"11787546374","pt":1722983119862,"mc":[{"id":"1.231431360","rc":[{"batb":[[1,1.55,43.14],[2,1.54,180]],"ltp":1.65,"tv":2855.4,"id":2219}]}]}
{"op":"mcm","clk":"11787546424","pt":1722983121099,"mc":[{"id":"1.231431360","rc":[{"batl":[[0,2.84,7.69]],"ltp":0.0,"tv":0.0,"id":31379}]}]}
{"op":"mcm","clk":"11787549260","pt":1722983188530,"mc":[{"id":"1.231431360","rc":[{"batb":[[1,1.54,180],[2,1.52,180]],"ltp":1.65,"tv":2855.4,"id":2219}]}]}
{"op":"mcm","clk":"11787549285","pt":1722983189349,"mc":[{"id":"1.231431360","rc":[{"batl":[[0,2.84,7.69]],"ltp":0.0,"tv":0.0,"id":31379}]}]}
{"op":"mcm","clk":"11787549660","pt":1722983198179,"mc":[{"id":"1.231431360","rc":[{"batl":[[0,2.84,12.45]],"ltp":0.0,"tv":0.0,"id":31379}]}]}
{"op":"mcm","clk":"11787550597","pt":1722983220086,"mc":[{"id":"1.231431360","rc":[{"batb":[[1,2.38,6.82],[2,2.32,28.65]],"ltp":0.0,"tv":0.0,"id":31379}]}]}
{"op":"mcm","clk":"11787550793","pt":1722983224892,"mc":[{"id":"1.231431360","rc":[{"batb":[[1,2.32,28.65],[2,2.14,38.68]],"ltp":0.0,"tv":0.0,"id":31379}]}]}
{"op":"mcm","clk":"11787551975","pt":1722983250625,"mc":[{"id":"1.231431360","rc":[{"batl":[[0,2.84,7.69]],"ltp":0.0,"tv":0.0,"id":31379},{"batb":[[1,1.55,43.14],[2,1.54,180]],"ltp":1.65,"tv":2855.4,"id":2219}]}]}
{"op":"mcm","clk":"11787553353","pt":1722983284455,"mc":[{"id":"1.231431360","rc":[{"batb":[[1,2.34,6.91],[2,2.32,28.65]],"ltp":0.0,"tv":0.0,"id":31379}]}]}
{"op":"mcm","clk":"11787554194","pt":1722983305882,"mc":[{"id":"1.231431360","rc":[{"batb":[[1,1.54,180],[2,1.52,180]],"ltp":1.65,"tv":2855.4,"id":2219}]}]}
{"op":"mcm","clk":"11787554259","pt":1722983306813,"mc":[{"id":"1.231431360","rc":[{"batl":[[0,2.84,7.69]],"ltp":0.0,"tv":0.0,"id":31379}]}]}
{"op":"mcm","clk":"11787554776","pt":1722983317301,"mc":[{"id":"1.231431360","rc":[{"batl":[[0,2.84,12.45]],"ltp":0.0,"tv":0.0,"id":31379}]}]}
{"op":"mcm","clk":"11787556475","pt":1722983358271,"mc":[{"id":"1.231431360","rc":[{"batb":[[1,1.55,43.14],[2,1.54,180]],"ltp":1.65,"tv":2855.4,"id":2219}]}]}
{"op":"mcm","clk":"11787556557","pt":1722983360059,"mc":[{"id":"1.231431360","rc":[{"batl":[[0,2.84,7.69]],"ltp":0.0,"tv":0.0,"id":31379}]}]}
{"op":"mcm","clk":"11787558739","pt":1722983411511,"mc":[{"id":"1.231431360","rc":[{"batb":[[1,1.54,180],[2,1.52,180]],"ltp":1.65,"tv":2855.4,"id":2219}]}]}
{"op":"mcm","clk":"11787558768","pt":1722983412124,"mc":[{"id":"1.231431360","rc":[{"batl":[[0,2.84,7.69]],"ltp":0.0,"tv":0.0,"id":31379}]}]}
{"op":"mcm","clk":"11787558839","pt":1722983413817,"mc":[{"id":"1.231431360","rc":[{"batl":[[0,2.84,12.45]],"ltp":0.0,"tv":0.0,"id":31379}]}]}
{"op":"mcm","clk":"11787561168","pt":1722983463358,"mc":[{"id":"1.231431360","rc":[{"batb":[[1,1.55,43.14],[2,1.54,180]],"ltp":1.65,"tv":2855.4,"id":2219}]}]}
{"op":"mcm","clk":"11787561253","pt":1722983465355,"mc":[{"id":"1.231431360","rc":[{"batl":[[0,2.84,7.69]],"ltp":0.0,"tv":0.0,"id":31379}]}]}
{"op":"mcm","clk":"11787562174","pt":1722983485304,"mc":[{"id":"1.231431360","rc":[{"batb":[[1,2.32,28.65],[2,2.14,38.68]],"ltp":0.0,"tv":0.0,"id":31379}]}]}
{"op":"mcm","clk":"11787563553","pt":1722983516134,"mc":[{"id":"1.231431360","rc":[{"batb":[[1,1.54,180],[2,1.52,180]],"ltp":1.65,"tv":2855.4,"id":2219}]}]}
{"op":"mcm","clk":"11787563623","pt":1722983517713,"mc":[{"id":"1.231431360","rc":[{"batl":[[0,2.84,7.69]],"ltp":0.0,"tv":0.0,"id":31379}]}]}
{"op":"mcm","clk":"11787563986","pt":1722983526310,"mc":[{"id":"1.231431360","rc":[{"batl":[[0,2.84,12.45]],"ltp":0.0,"tv":0.0,"id":31379}]}]}
{"op":"mcm","clk":"11787565687","pt":1722983568291,"mc":[{"id":"1.231431360","rc":[{"batb":[[1,1.55,43.14],[2,1.54,180]],"ltp":1.65,"tv":2855.4,"id":2219}]}]}
{"op":"mcm","clk":"11787565731","pt":1722983569570,"mc":[{"id":"1.231431360","rc":[{"batl":[[0,2.84,7.69]],"ltp":0.0,"tv":0.0,"id":31379}]}]}
{"op":"mcm","clk":"11787566101","pt":1722983577602,"mc":[{"id":"1.231431360","rc":[{"batb":[[1,2.36,6.85],[2,2.32,28.65]],"ltp":0.0,"tv":0.0,"id":31379}]}]}
{"op":"mcm","clk":"11787567303","pt":1722983607745,"mc":[{"id":"1.231431360","rc":[{"batb":[[1,2.32,28.65],[2,2.14,38.68]],"ltp":0.0,"tv":0.0,"id":31379}]}]}
{"op":"mcm","clk":"11787567969","pt":1722983621650,"mc":[{"id":"1.231431360","rc":[{"batb":[[1,1.54,180],[2,1.52,180]],"ltp":1.65,"tv":2855.4,"id":2219}]}]}
{"op":"mcm","clk":"11787568044","pt":1722983623432,"mc":[{"id":"1.231431360","rc":[{"batl":[[0,2.84,7.69]],"ltp":0.0,"tv":0.0,"id":31379}]}]}
{"op":"mcm","clk":"11787568158","pt":1722983626452,"mc":[{"id":"1.231431360","rc":[{"batl":[[0,2.84,12.45]],"ltp":0.0,"tv":0.0,"id":31379}]}]}
{"op":"mcm","clk":"11787568698","pt":1722983640095,"mc":[{"id":"1.231431360","rc":[{"batb":[[1,2.36,6.85],[2,2.32,28.65]],"ltp":0.0,"tv":0.0,"id":31379}]}]}
{"op":"mcm","clk":"11787569955","pt":1722983674991,"mc":[{"id":"1.231431360","rc":[{"batb":[[1,1.55,43.14],[2,1.54,180]],"ltp":1.65,"tv":2855.4,"id":2219}]}]}
{"op":"mcm","clk":"11787569980","pt":1722983675809,"mc":[{"id":"1.231431360","rc":[{"batl":[[0,2.84,7.69]],"ltp":0.0,"tv":0.0,"id":31379}]}]}
{"op":"mcm","clk":"11787571947","pt":1722983728658,"mc":[{"id":"1.231431360","rc":[{"batb":[[1,1.54,180],[2,1.52,180]],"ltp":1.65,"tv":2855.4,"id":2219}]}]}
{"op":"mcm","clk":"11787572135","pt":1722983733565,"mc":[{"id":"1.231431360","rc":[{"batl":[[0,2.84,12.45]],"ltp":0.0,"tv":0.0,"id":31379}]}]}
{"op":"mcm","clk":"11787574215","pt":1722983783582,"mc":[{"id":"1.231431360","rc":[{"batl":[[0,2.84,7.69]],"ltp":0.0,"tv":0.0,"id":31379},{"batb":[[1,1.55,43.14],[2,1.54,180]],"ltp":1.65,"tv":2855.4,"id":2219}]}]}
{"op":"mcm","clk":"11787576467","pt":1722983836640,"mc":[{"id":"1.231431360","rc":[{"batb":[[1,1.54,180],[2,1.52,180]],"ltp":1.65,"tv":2855.4,"id":2219}]}]}
{"op":"mcm","clk":"11787576560","pt":1722983838745,"mc":[{"id":"1.231431360","rc":[{"batl":[[0,2.84,7.69]],"ltp":0.0,"tv":0.0,"id":31379}]}]}
{"op":"mcm","clk":"11787576671","pt":1722983841148,"mc":[{"id":"1.231431360","rc":[{"batl":[[0,2.84,12.45]],"ltp":0.0,"tv":0.0,"id":31379}]}]}
{"op":"mcm","clk":"11787579218","pt":1722983897615,"mc":[{"id":"1.231431360","rc":[{"batb":[[1,1.55,43.14],[2,1.54,180]],"ltp":1.65,"tv":2855.4,"id":2219}]}]}
{"op":"mcm","clk":"11787579318","pt":1722983899810,"mc":[{"id":"1.231431360","rc":[{"batl":[[0,2.84,7.69]],"ltp":0.0,"tv":0.0,"id":31379}]}]}
{"op":"mcm","clk":"11787581607","pt":1722983953455,"mc":[{"id":"1.231431360","rc":[{"batb":[[1,1.54,180],[2,1.52,180]],"ltp":1.65,"tv":2855.4,"id":2219}]}]}
{"op":"mcm","clk":"11787581934","pt":1722983962067,"mc":[{"id":"1.231431360","rc":[{"batl":[[0,2.84,12.45]],"ltp":0.0,"tv":0.0,"id":31379}]}]}
{"op":"mcm","clk":"11787583839","pt":1722984005341,"mc":[{"id":"1.231431360","rc":[{"batb":[[1,1.55,43.14],[2,1.54,180]],"ltp":1.65,"tv":2855.4,"id":2219}]}]}
{"op":"mcm","clk":"11787583885","pt":1722984006212,"mc":[{"id":"1.231431360","rc":[{"batl":[[0,2.84,7.69]],"ltp":0.0,"tv":0.0,"id":31379}]}]}
{"op":"mcm","clk":"11787586143","pt":1722984057591,"mc":[{"id":"1.231431360","rc":[{"batb":[[1,1.54,180],[2,1.52,180]],"ltp":1.65,"tv":2855.4,"id":2219}]}]}
{"op":"mcm","clk":"11787586455","pt":1722984064598,"mc":[{"id":"1.231431360","rc":[{"batb":[[1,2.32,28.65],[2,2.14,38.68]],"ltp":0.0,"tv":0.0,"id":31379}]}]}
{"op":"mcm","clk":"11787586633","pt":1722984068385,"mc":[{"id":"1.231431360","rc":[{"batl":[[0,2.84,12.45]],"ltp":0.0,"tv":0.0,"id":31379}]}]}
{"op":"mcm","clk":"11787588266","pt":1722984108119,"mc":[{"id":"1.231431360","rc":[{"batb":[[1,1.55,43.14],[2,1.54,180]],"ltp":1.65,"tv":2855.4,"id":2219}]}]}
{"op":"mcm","clk":"11787588319","pt":1722984109250,"mc":[{"id":"1.231431360","rc":[{"batl":[[0,2.84,7.69]],"ltp":0.0,"tv":0.0,"id":31379}]}]}
{"op":"mcm","clk":"11787590214","pt":1722984159854,"mc":[{"id":"1.231431360","rc":[{"batb":[[1,1.54,180],[2,1.52,180]],"ltp":1.65,"tv":2855.4,"id":2219}]}]}
{"op":"mcm","clk":"11787590268","pt":1722984161647,"mc":[{"id":"1.231431360","rc":[{"batl":[[0,2.84,7.69]],"ltp":0.0,"tv":0.0,"id":31379}]}]}
{"op":"mcm","clk":"11787590432","pt":1722984166354,"mc":[{"id":"1.231431360","rc":[{"batl":[[0,2.84,12.45]],"ltp":0.0,"tv":0.0,"id":31379}]}]}
{"op":"mcm","clk":"11787592324","pt":1722984213512,"mc":[{"id":"1.231431360","rc":[{"batl":[[0,2.84,7.69]],"ltp":0.0,"tv":0.0,"id":31379},{"batb":[[1,1.55,43.14],[2,1.54,180]],"ltp":1.65,"tv":2855.4,"id":2219}]}]}
{"op":"mcm","clk":"11787594431","pt":1722984267498,"mc":[{"id":"1.231431360","rc":[{"batb":[[1,1.54,180],[2,1.52,180]],"ltp":1.65,"tv":2855.4,"id":2219}]}]}
{"op":"mcm","clk":"11787594482","pt":1722984268677,"mc":[{"id":"1.231431360","rc":[{"batl":[[0,2.84,7.69]],"ltp":0.0,"tv":0.0,"id":31379}]}]}
{"op":"mcm","clk":"11787594761","pt":1722984276002,"mc":[{"id":"1.231431360","rc":[{"batl":[[0,2.84,12.45]],"ltp":0.0,"tv":0.0,"id":31379}]}]}
{"op":"mcm","clk":"11787596812","pt":1722984320540,"mc":[{"id":"1.231431360","rc":[{"batb":[[1,1.55,43.14],[2,1.54,180]],"ltp":1.65,"tv":2855.4,"id":2219}]}]}
{"op":"mcm","clk":"11787599205","pt":1722984374104,"mc":[{"id":"1.231431360","rc":[{"batb":[[1,1.54,180],[2,1.52,180]],"ltp":1.65,"tv":2855.4,"id":2219}]}]}
{"op":"mcm","clk":"11787599279","pt":1722984376109,"mc":[{"id":"1.231431360","rc":[{"batl":[[0,2.84,7.69]],"ltp":0.0,"tv":0.0,"id":31379}]}]}
{"op":"mcm","clk":"11787599568","pt":1722984382608,"mc":[{"id":"1.231431360","rc":[{"batl":[[0,2.84,12.45]],"ltp":0.0,"tv":0.0,"id":31379}]}]}
{"op":"mcm","clk":"11787601596","pt":1722984427127,"mc":[{"id":"1.231431360","rc":[{"batb":[[1,1.55,43.14],[2,1.54,180]],"ltp":1.65,"tv":2855.4,"id":2219}]}]}
{"op":"mcm","clk":"11787601651","pt":1722984427840,"mc":[{"id":"1.231431360","rc":[{"batl":[[0,2.84,7.69]],"ltp":0.0,"tv":0.0,"id":31379}]}]}
{"op":"mcm","clk":"11787602743","pt":1722984454083,"mc":[{"id":"1.231431360","rc":[{"batb":[[2,1.54,888.83]],"ltp":1.65,"tv":2855.4,"id":2219}]}]}
{"op":"mcm","clk":"11787603988","pt":1722984484405,"mc":[{"id":"1.231431360","rc":[{"batb":[[1,1.54,888.83],[2,1.52,180]],"ltp":1.65,"tv":2855.4,"id":2219}]}]}
{"op":"mcm","clk":"11787604028","pt":1722984485377,"mc":[{"id":"1.231431360","rc":[{"batl":[[0,2.84,17.22]],"ltp":0.0,"tv":0.0,"id":31379}]}]}
{"op":"mcm","clk":"11787606684","pt":1722984543445,"mc":[{"id":"1.231431360","rc":[{"batb":[[1,1.55,43.14],[2,1.54,888.83]],"ltp":1.65,"tv":2855.4,"id":2219}]}]}
{"op":"mcm","clk":"11787609124","pt":1722984595528,"mc":[{"id":"1.231431360","rc":[{"batb":[[1,1.54,888.83],[2,1.52,180]],"ltp":1.65,"tv":2855.4,"id":2219}]}]}
{"op":"mcm","clk":"11787609235","pt":1722984597837,"mc":[{"id":"1.231431360","rc":[{"batl":[[0,2.84,17.22]],"ltp":0.0,"tv":0.0,"id":31379}]}]}
{"op":"mcm","clk":"11787611560","pt":1722984648384,"mc":[{"id":"1.231431360","rc":[{"batb":[[1,1.55,43.14],[2,1.54,888.83]],"ltp":1.65,"tv":2855.4,"id":2219}]}]}
{"op":"mcm","clk":"11787613809","pt":1722984700633,"mc":[{"id":"1.231431360","rc":[{"batb":[[1,1.54,888.83],[2,1.52,180]],"ltp":1.65,"tv":2855.4,"id":2219}]}]}
{"op":"mcm","clk":"11787613877","pt":1722984702226,"mc":[{"id":"1.231431360","rc":[{"batl":[[0,2.84,17.22]],"ltp":0.0,"tv":0.0,"id":31379}]}]}
{"op":"mcm","clk":"11787615485","pt":1722984739205,"mc":[{"id":"1.231431360","rc":[{"trd":[[1.65,77.18]],"batb":[[0,1.65,11.63],[1,1.56,9.78],[2,1.54,888.83]],"batl":[[0,1.66,17.22],[1,1.67,300],[2,1.68,400]],"ltp":1.65,"tv":2872.14,"id":2219}],"tv":2872.14}]}
{"op":"mcm","clk":"11787615697","pt":1722984743912,"mc":[{"id":"1.231431360","rc":[{"batb":[[1,2.14,38.68],[2,1.74,17.32]],"ltp":0.0,"tv":0.0,"id":31379}]}]}
{"op":"mcm","clk":"11787616029","pt":1722984751904,"mc":[{"id":"1.231431360","rc":[{"batb":[[0,2.52,30.7]],"ltp":0.0,"tv":0.0,"id":31379},{"batl":[[0,1.66,21.22]],"ltp":1.65,"tv":2872.14,"id":2219}]}]}
{"op":"mcm","clk":"11787616213","pt":1722984757129,"mc":[{"id":"1.231431360","rc":[{"batb":[[0,2.52,4]],"ltp":0.0,"tv":0.0,"id":31379}]}]}
{"op":"mcm","clk":"11787616277","pt":1722984758825,"mc":[{"id":"1.231431360","rc":[{"batb":[[1,2.32,28.65],[2,2.14,38.68]],"ltp":0.0,"tv":0.0,"id":31379}]}]}
{"op":"mcm","clk":"11787618366","pt":1722984812053,"mc":[{"id":"1.231431360","rc":[{"batb":[[1,1.57,42.62],[2,1.56,9.78]],"ltp":1.65,"tv":2872.14,"id":2219}]}]}
{"op":"mcm","clk":"11787620437","pt":1722984867527,"mc":[{"id":"1.231431360","rc":[{"batb":[[1,1.56,9.78],[2,1.54,888.83]],"ltp":1.65,"tv":2872.14,"id":2219}]}]}
{"op":"mcm","clk":"11787622717","pt":1722984922669,"mc":[{"id":"1.231431360","rc":[{"batb":[[1,1.57,42.62],[2,1.56,9.78]],"ltp":1.65,"tv":2872.14,"id":2219}]}]}
{"op":"mcm","clk":"11787625006","pt":1722984980203,"mc":[{"id":"1.231431360","rc":[{"batb":[[1,1.56,9.78],[2,1.54,888.83]],"ltp":1.65,"tv":2872.14,"id":2219}]}]}
{"op":"mcm","clk":"11787628289","pt":1722985048987,"mc":[{"id":"1.231431360","rc":[{"batb":[[1,1.57,42.62],[2,1.56,9.78]],"ltp":1.65,"tv":2872.14,"id":2219}]}]}
{"op":"mcm","clk":"11787630905","pt":1722985106651,"mc":[{"id":"1.231431360","rc":[{"batb":[[1,1.56,9.78],[2,1.54,888.83]],"ltp":1.65,"tv":2872.14,"id":2219}]}]}
{"op":"mcm","clk":"11787633651","pt":1722985164410,"mc":[{"id":"1.231431360","rc":[{"batb":[[1,1.57,42.62],[2,1.56,9.78]],"ltp":1.65,"tv":2872.14,"id":2219}]}]}
{"op":"mcm","clk":"11787636460","pt":1722985218732,"mc":[{"id":"1.231431360","rc":[{"trd":[[1.59,90.17],[1.6,183.78],[1.61,35.32],[1.63,25.8],[1.66,127.81],[1.67,40.97],[1.69,172.29],[1.7,1236.85],[1.71,517.26],[1.85,15.45]],"batb":[[1,1.56,9.78],[2,1.54,889.05]],"batl":[[0,1.66,21.22]],"ltp":1.65,"tv":2872.28,"id":2219}],"tv":2872.28}]}
{"op":"mcm","clk":"11787638971","pt":1722985272313,"mc":[{"id":"1.231431360","rc":[{"batb":[[1,1.57,42.65],[2,1.56,9.78]],"ltp":1.65,"tv":2872.28,"id":2219}]}]}
{"op":"mcm","clk":"11787641369","pt":1722985324963,"mc":[{"id":"1.231431360","rc":[{"batb":[[1,1.56,9.78],[2,1.54,889.05]],"ltp":1.65,"tv":2872.28,"id":2219}]}]}
{"op":"mcm","clk":"11787643865","pt":1722985377244,"mc":[{"id":"1.231431360","rc":[{"batb":[[1,1.57,42.65],[2,1.56,9.78]],"ltp":1.65,"tv":2872.28,"id":2219}]}]}
{"op":"mcm","clk":"11787646477","pt":1722985429304,"mc":[{"id":"1.231431360","rc":[{"batb":[[1,1.56,9.78],[2,1.54,889.05]],"ltp":1.65,"tv":2872.28,"id":2219}]}]}
{"op":"mcm","clk":"11787648741","pt":1722985482954,"mc":[{"id":"1.231431360","rc":[{"batb":[[1,1.57,42.65],[2,1.56,9.78]],"ltp":1.65,"tv":2872.28,"id":2219}]}]}
{"op":"mcm","clk":"11787651026","pt":1722985535512,"mc":[{"id":"1.231431360","rc":[{"batb":[[1,1.56,9.78],[2,1.54,889.05]],"ltp":1.65,"tv":2872.28,"id":2219}]}]}
{"op":"mcm","clk":"11787653365","pt":1722985587972,"mc":[{"id":"1.231431360","rc":[{"batb":[[1,1.57,42.65],[2,1.56,9.78]],"ltp":1.65,"tv":2872.28,"id":2219}]}]}
{"op":"mcm","clk":"11787655782","pt":1722985640442,"mc":[{"id":"1.231431360","rc":[{"batb":[[1,1.56,9.78],[2,1.54,889.05]],"ltp":1.65,"tv":2872.28,"id":2219}]}]}
{"op":"mcm","clk":"11787657337","pt":1722985674653,"mc":[{"id":"1.231431360","rc":[{"batb":[[2,1.54,180]],"ltp":1.65,"tv":2872.28,"id":2219}]}]}
{"op":"mcm","clk":"11787658226","pt":1722985694687,"mc":[{"id":"1.231431360","rc":[{"batb":[[1,1.57,42.65],[2,1.56,9.78]],"ltp":1.65,"tv":2872.28,"id":2219}]}]}
{"op":"mcm","clk":"11787661268","pt":1722985753632,"mc":[{"id":"1.231431360","rc":[{"batb":[[1,1.56,9.78],[2,1.54,180]],"ltp":1.65,"tv":2872.28,"id":2219}]}]}
{"op":"mcm","clk":"11787664258","pt":1722985808599,"mc":[{"id":"1.231431360","rc":[{"batb":[[1,1.57,42.65],[2,1.56,9.78]],"ltp":1.65,"tv":2872.28,"id":2219}]}]}
{"op":"mcm","clk":"11787667180","pt":1722985864297,"mc":[{"id":"1.231431360","rc":[{"batb":[[1,1.56,9.78],[2,1.54,180]],"ltp":1.65,"tv":2872.28,"id":2219}]}]}
{"op":"mcm","clk":"11787669899","pt":1722985917308,"mc":[{"id":"1.231431360","rc":[{"batb":[[1,1.57,42.65],[2,1.56,9.78]],"ltp":1.65,"tv":2872.28,"id":2219}]}]}
{"op":"mcm","clk":"11787672717","pt":1722985971222,"mc":[{"id":"1.231431360","rc":[{"batb":[[1,1.56,9.78],[2,1.54,180]],"ltp":1.65,"tv":2872.28,"id":2219}]}]}
{"op":"mcm","clk":"11787675327","pt":1722986023663,"mc":[{"id":"1.231431360","rc":[{"batb":[[1,1.57,42.65],[2,1.56,9.78]],"ltp":1.65,"tv":2872.28,"id":2219}]}]}
{"op":"mcm","clk":"11787678024","pt":1722986077712,"mc":[{"id":"1.231431360","rc":[{"batb":[[1,1.56,9.78],[2,1.54,180]],"ltp":1.65,"tv":2872.28,"id":2219}]}]}
{"op":"mcm","clk":"11787680626","pt":1722986131270,"mc":[{"id":"1.231431360","rc":[{"batb":[[1,1.57,42.65],[2,1.56,9.78]],"ltp":1.65,"tv":2872.28,"id":2219}]}]}
{"op":"mcm","clk":"11787683170","pt":1722986184750,"mc":[{"id":"1.231431360","rc":[{"batb":[[1,1.56,9.78],[2,1.54,180]],"ltp":1.65,"tv":2872.28,"id":2219}]}]}
{"op":"mcm","clk":"11787685757","pt":1722986237142,"mc":[{"id":"1.231431360","rc":[{"batb":[[1,1.57,42.65],[2,1.56,9.78]],"ltp":1.65,"tv":2872.28,"id":2219}]}]}
{"op":"mcm","clk":"11787688510","pt":1722986289570,"mc":[{"id":"1.231431360","rc":[{"batb":[[1,1.56,9.78],[2,1.54,180]],"ltp":1.65,"tv":2872.28,"id":2219}]}]}
{"op":"mcm","clk":"11787691409","pt":1722986347426,"mc":[{"id":"1.231431360","rc":[{"batb":[[1,1.57,42.65],[2,1.56,9.78]],"ltp":1.65,"tv":2872.28,"id":2219}]}]}
{"op":"mcm","clk":"11787693625","pt":1722986401208,"mc":[{"id":"1.231431360","rc":[{"batb":[[1,1.56,9.78],[2,1.54,180]],"ltp":1.65,"tv":2872.28,"id":2219}]}]}
{"op":"mcm","clk":"11787696237","pt":1722986455384,"mc":[{"id":"1.231431360","rc":[{"batb":[[1,1.57,42.65],[2,1.56,9.78]],"ltp":1.65,"tv":2872.28,"id":2219}]}]}
{"op":"mcm","clk":"11787698654","pt":1722986509659,"mc":[{"id":"1.231431360","rc":[{"batb":[[1,1.56,9.78],[2,1.54,180]],"ltp":1.65,"tv":2872.28,"id":2219}]}]}
{"op":"mcm","clk":"11787701296","pt":1722986565983,"mc":[{"id":"1.231431360","rc":[{"batb":[[1,1.57,42.65],[2,1.56,9.78]],"ltp":1.65,"tv":2872.28,"id":2219}]}]}
{"op":"mcm","clk":"11787703841","pt":1722986622352,"mc":[{"id":"1.231431360","rc":[{"batb":[[1,1.56,9.78],[2,1.54,180]],"ltp":1.65,"tv":2872.28,"id":2219}]}]}
{"op":"mcm","clk":"11787706483","pt":1722986677230,"mc":[{"id":"1.231431360","rc":[{"batb":[[1,1.57,42.65],[2,1.56,9.78]],"ltp":1.65,"tv":2872.28,"id":2219}]}]}
{"op":"mcm","clk":"11787709200","pt":1722986734551,"mc":[{"id":"1.231431360","rc":[{"batb":[[1,1.56,9.78],[2,1.54,180]],"ltp":1.65,"tv":2872.28,"id":2219}]}]}
{"op":"mcm","clk":"11787712210","pt":1722986792138,"mc":[{"id":"1.231431360","rc":[{"batb":[[1,1.57,42.65],[2,1.56,9.78]],"ltp":1.65,"tv":2872.28,"id":2219}]}]}
{"op":"mcm","clk":"11787715090","pt":1722986853706,"mc":[{"id":"1.231431360","rc":[{"batb":[[1,1.56,9.78],[2,1.54,180]],"ltp":1.65,"tv":2872.28,"id":2219}]}]}
{"op":"mcm","clk":"11787718073","pt":1722986915848,"mc":[{"id":"1.231431360","rc":[{"batb":[[1,1.57,42.65],[2,1.56,9.78]],"ltp":1.65,"tv":2872.28,"id":2219}]}]}
{"op":"mcm","clk":"11787720889","pt":1722986972592,"mc":[{"id":"1.231431360","rc":[{"batb":[[1,1.56,9.78],[2,1.54,180]],"ltp":1.65,"tv":2872.28,"id":2219}]}]}
{"op":"mcm","clk":"11787724023","pt":1722987028547,"mc":[{"id":"1.231431360","rc":[{"batb":[[1,1.57,42.65],[2,1.56,9.78]],"ltp":1.65,"tv":2872.28,"id":2219}]}]}
{"op":"mcm","clk":"11787726622","pt":1722987085849,"mc":[{"id":"1.231431360","rc":[{"batb":[[1,1.56,9.78],[2,1.54,180]],"ltp":1.65,"tv":2872.28,"id":2219}]}]}
{"op":"mcm","clk":"11787729315","pt":1722987141570,"mc":[{"id":"1.231431360","rc":[{"batb":[[1,1.57,42.65],[2,1.56,9.78]],"ltp":1.65,"tv":2872.28,"id":2219}]}]}
{"op":"mcm","clk":"11787731890","pt":1722987197651,"mc":[{"id":"1.231431360","rc":[{"batb":[[1,1.56,9.78],[2,1.54,180]],"ltp":1.65,"tv":2872.28,"id":2219}]}]}
{"op":"mcm","clk":"11787732875","pt":1722987216242,"mc":[{"id":"1.231431360","rc":[{"trd":[[1.65,80.5]],"batb":[[0,1.65,9.97]],"ltp":1.65,"tv":2875.6,"id":2219}],"tv":2875.6}]}
{"op":"mcm","clk":"11787734537","pt":1722987252014,"mc":[{"id":"1.231431360","rc":[{"batb":[[1,1.57,42.65],[2,1.56,9.78]],"ltp":1.65,"tv":2875.6,"id":2219}]}]}
{"op":"mcm","clk":"11787736955","pt":1722987306579,"mc":[{"id":"1.231431360","rc":[{"batb":[[1,1.56,9.78],[2,1.54,180]],"ltp":1.65,"tv":2875.6,"id":2219}]}]}
{"op":"mcm","clk":"11787739305","pt":1722987360372,"mc":[{"id":"1.231431360","rc":[{"batb":[[1,1.57,42.65],[2,1.56,9.78]],"ltp":1.65,"tv":2875.6,"id":2219}]}]}
{"op":"mcm","clk":"11787740924","pt":1722987394911,"mc":[{"id":"1.231431360","rc":[{"batb":[[1,1.58,4.58],[2,1.57,42.65]],"ltp":1.65,"tv":2875.6,"id":2219}]}]}
{"op":"mcm","clk":"11787741346","pt":1722987404968,"mc":[{"id":"1.231431360","rc":[{"batb":[[1,1.59,4.58],[2,1.58,4.58]],"ltp":1.65,"tv":2875.6,"id":2219}]}]}
{"op":"mcm","clk":"11787744066","pt":1722987467003,"mc":[{"id":"1.231431360","rc":[{"batb":[[1,1.6,41.62],[2,1.59,4.58]],"ltp":1.65,"tv":2875.6,"id":2219}]}]}
{"op":"mcm","clk":"11787746554","pt":1722987520663,"mc":[{"id":"1.231431360","rc":[{"batb":[[1,1.59,4.58],[2,1.58,4.58]],"ltp":1.65,"tv":2875.6,"id":2219}]}]}
{"op":"mcm","clk":"11787749089","pt":1722987576915,"mc":[{"id":"1.231431360","rc":[{"batb":[[1,1.6,41.62],[2,1.59,4.58]],"ltp":1.65,"tv":2875.6,"id":2219}]}]}
{"op":"mcm","clk":"11787751869","pt":1722987636810,"mc":[{"id":"1.231431360","rc":[{"batb":[[1,1.59,4.58],[2,1.58,4.58]],"ltp":1.65,"tv":2875.6,"id":2219}]}]}
{"op":"mcm","clk":"11787754160","pt":1722987690620,"mc":[{"id":"1.231431360","rc":[{"batb":[[1,1.6,41.62],[2,1.59,4.58]],"ltp":1.65,"tv":2875.6,"id":2219}]}]}
{"op":"mcm","clk":"11787756293","pt":1722987747117,"mc":[{"id":"1.231431360","rc":[{"batb":[[1,1.59,4.58],[2,1.58,4.58]],"ltp":1.65,"tv":2875.6,"id":2219}]}]}
{"op":"mcm","clk":"11787766082","pt":1722987800783,"mc":[{"id":"1.231431360","rc":[{"batb":[[1,1.6,41.62],[2,1.59,4.58]],"ltp":1.65,"tv":2875.6,"id":2219}]}]}
{"op":"mcm","clk":"11787768555","pt":1722987853735,"mc":[{"id":"1.231431360","rc":[{"batb":[[1,1.59,4.58],[2,1.58,4.58]],"ltp":1.65,"tv":2875.6,"id":2219}]}]}
{"op":"mcm","clk":"11787770956","pt":1722987906329,"mc":[{"id":"1.231431360","rc":[{"batb":[[1,1.6,41.62],[2,1.59,4.58]],"ltp":1.65,"tv":2875.6,"id":2219}]}]}
{"op":"mcm","clk":"11787773401","pt":1722987959629,"mc":[{"id":"1.231431360","rc":[{"batb":[[1,1.59,4.58],[2,1.58,4.58]],"ltp":1.65,"tv":2875.6,"id":2219}]}]}
{"op":"mcm","clk":"11787776012","pt":1722988014957,"mc":[{"id":"1.231431360","rc":[{"batb":[[1,1.6,41.62],[2,1.59,4.58]],"ltp":1.65,"tv":2875.6,"id":2219}]}]}
{"op":"mcm","clk":"11787778470","pt":1722988068105,"mc":[{"id":"1.231431360","rc":[{"batb":[[1,1.59,4.58],[2,1.58,4.58]],"ltp":1.65,"tv":2875.6,"id":2219}]}]}
{"op":"mcm","clk":"11787781021","pt":1722988120794,"mc":[{"id":"1.231431360","rc":[{"batb":[[1,1.6,41.62],[2,1.59,4.58]],"ltp":1.65,"tv":2875.6,"id":2219}]}]}
{"op":"mcm","clk":"11787783761","pt":1722988174831,"mc":[{"id":"1.231431360","rc":[{"batb":[[1,1.59,4.58],[2,1.58,4.58]],"ltp":1.65,"tv":2875.6,"id":2219}]}]}
{"op":"mcm","clk":"11787786344","pt":1722988230595,"mc":[{"id":"1.231431360","rc":[{"batb":[[1,1.6,41.62],[2,1.59,4.58]],"ltp":1.65,"tv":2875.6,"id":2219}]}]}
{"op":"mcm","clk":"11787789027","pt":1722988287524,"mc":[{"id":"1.231431360","rc":[{"batb":[[1,1.59,4.58],[2,1.58,4.58]],"ltp":1.65,"tv":2875.6,"id":2219}]}]}
{"op":"mcm","clk":"11787791701","pt":1722988343861,"mc":[{"id":"1.231431360","rc":[{"batb":[[1,1.6,41.62],[2,1.59,4.58]],"ltp":1.65,"tv":2875.6,"id":2219}]}]}
{"op":"mcm","clk":"11787794556","pt":1722988403103,"mc":[{"id":"1.231431360","rc":[{"batb":[[1,1.59,4.58],[2,1.58,4.58]],"ltp":1.65,"tv":2875.6,"id":2219}]}]}
{"op":"mcm","clk":"11787797399","pt":1722988461758,"mc":[{"id":"1.231431360","rc":[{"batb":[[1,1.6,41.62],[2,1.59,4.58]],"ltp":1.65,"tv":2875.6,"id":2219}]}]}
{"op":"mcm","clk":"11787800365","pt":1722988516930,"mc":[{"id":"1.231431360","rc":[{"batb":[[1,1.59,4.58],[2,1.58,4.58]],"ltp":1.65,"tv":2875.6,"id":2219}]}]}
{"op":"mcm","clk":"11787803338","pt":1722988572663,"mc":[{"id":"1.231431360","rc":[{"batb":[[1,1.6,41.62],[2,1.59,4.58]],"ltp":1.65,"tv":2875.6,"id":2219}]}]}
{"op":"mcm","clk":"11787806349","pt":1722988629628,"mc":[{"id":"1.231431360","rc":[{"batb":[[1,1.59,4.58],[2,1.58,4.58]],"ltp":1.65,"tv":2875.6,"id":2219}]}]}
{"op":"mcm","clk":"11787809458","pt":1722988690812,"mc":[{"id":"1.231431360","rc":[{"batb":[[1,1.6,41.62],[2,1.59,4.58]],"ltp":1.65,"tv":2875.6,"id":2219}]}]}
{"op":"mcm","clk":"11787812898","pt":1722988753319,"mc":[{"id":"1.231431360","rc":[{"batb":[[1,1.59,4.58],[2,1.58,4.58]],"ltp":1.65,"tv":2875.6,"id":2219}]}]}
{"op":"mcm","clk":"11787815922","pt":1722988806792,"mc":[{"id":"1.231431360","rc":[{"trd":[[1.59,90.17],[1.6,183.81],[1.61,35.33],[1.63,25.81],[1.64,5.65],[1.66,127.84],[1.67,40.99],[1.69,172.3],[1.7,1237.08],[1.71,517.28],[1.85,15.46],[1.86,7.73]],"batb":[[1,1.6,41.59],[2,1.59,4.58]],"batl":[[0,1.66,21.23]],"ltp":1.65,"tv":2875.96,"id":2219}],"tv":2875.96}]}
{"op":"mcm","clk":"11787819423","pt":1722988862638,"mc":[{"id":"1.231431360","rc":[{"batb":[[1,1.59,4.58],[2,1.58,4.58]],"ltp":1.65,"tv":2875.96,"id":2219}]}]}
{"op":"mcm","clk":"11787822352","pt":1722988919303,"mc":[{"id":"1.231431360","rc":[{"batb":[[1,1.6,41.59],[2,1.59,4.58]],"ltp":1.65,"tv":2875.96,"id":2219}]}]}
{"op":"mcm","clk":"11787824876","pt":1722988972149,"mc":[{"id":"1.231431360","rc":[{"batb":[[1,1.59,4.58],[2,1.58,4.58]],"ltp":1.65,"tv":2875.96,"id":2219}]}]}
{"op":"mcm","clk":"11787828130","pt":1722989026069,"mc":[{"id":"1.231431360","rc":[{"batb":[[1,1.6,41.59],[2,1.59,4.58]],"ltp":1.65,"tv":2875.96,"id":2219}]}]}
{"op":"mcm","clk":"11787831071","pt":1722989077173,"mc":[{"id":"1.231431360","rc":[{"batb":[[1,1.59,4.58],[2,1.58,4.58]],"ltp":1.65,"tv":2875.96,"id":2219}]}]}
{"op":"mcm","clk":"11787834104","pt":1722989129929,"mc":[{"id":"1.231431360","rc":[{"batb":[[1,1.6,41.59],[2,1.59,4.58]],"ltp":1.65,"tv":2875.96,"id":2219}]}]}
{"op":"mcm","clk":"11787837007","pt":1722989180190,"mc":[{"id":"1.231431360","rc":[{"batb":[[1,1.59,4.58],[2,1.58,4.58]],"ltp":1.65,"tv":2875.96,"id":2219}]}]}
{"op":"mcm","clk":"11787840206","pt":1722989232239,"mc":[{"id":"1.231431360","rc":[{"batb":[[1,1.6,41.59],[2,1.59,4.58]],"ltp":1.65,"tv":2875.96,"id":2219}]}]}
{"op":"mcm","clk":"11787843495","pt":1722989284294,"mc":[{"id":"1.231431360","rc":[{"batb":[[1,1.59,4.58],[2,1.58,4.58]],"ltp":1.65,"tv":2875.96,"id":2219}]}]}
{"op":"mcm","clk":"11787846262","pt":1722989334780,"mc":[{"id":"1.231431360","rc":[{"batb":[[1,1.6,41.59],[2,1.59,4.58]],"ltp":1.65,"tv":2875.96,"id":2219}]}]}
{"op":"mcm","clk":"11787849394","pt":1722989386690,"mc":[{"id":"1.231431360","rc":[{"batb":[[1,1.59,4.58],[2,1.58,4.58]],"ltp":1.65,"tv":2875.96,"id":2219}]}]}
{"op":"mcm","clk":"11787852881","pt":1722989438338,"mc":[{"id":"1.231431360","rc":[{"batb":[[1,1.6,41.59],[2,1.59,4.58]],"ltp":1.65,"tv":2875.96,"id":2219}]}]}
{"op":"mcm","clk":"11787856395","pt":1722989492216,"mc":[{"id":"1.231431360","rc":[{"batb":[[1,1.59,4.58],[2,1.58,4.58]],"ltp":1.65,"tv":2875.96,"id":2219}]}]}
{"op":"mcm","clk":"11787860000","pt":1722989548260,"mc":[{"id":"1.231431360","rc":[{"batb":[[1,1.6,41.59],[2,1.59,4.58]],"ltp":1.65,"tv":2875.96,"id":2219}]}]}
{"op":"mcm","clk":"11787863482","pt":1722989601334,"mc":[{"id":"1.231431360","rc":[{"batb":[[1,1.59,4.58],[2,1.58,4.58]],"ltp":1.65,"tv":2875.96,"id":2219}]}]}
{"op":"mcm","clk":"11787866774","pt":1722989655309,"mc":[{"id":"1.231431360","rc":[{"batb":[[1,1.6,41.59],[2,1.59,4.58]],"ltp":1.65,"tv":2875.96,"id":2219}]}]}
{"op":"mcm","clk":"11787870086","pt":1722989708031,"mc":[{"id":"1.231431360","rc":[{"batb":[[1,1.59,4.58],[2,1.58,4.58]],"ltp":1.65,"tv":2875.96,"id":2219}]}]}
{"op":"mcm","clk":"11787873243","pt":1722989760221,"mc":[{"id":"1.231431360","rc":[{"batb":[[1,1.6,41.59],[2,1.59,4.58]],"ltp":1.65,"tv":2875.96,"id":2219}]}]}
{"op":"mcm","clk":"11787876297","pt":1722989811468,"mc":[{"id":"1.231431360","rc":[{"batb":[[1,1.59,4.58],[2,1.58,4.58]],"ltp":1.65,"tv":2875.96,"id":2219}]}]}
{"op":"mcm","clk":"11787879563","pt":1722989864415,"mc":[{"id":"1.231431360","rc":[{"batb":[[1,1.6,41.59],[2,1.59,4.58]],"ltp":1.65,"tv":2875.96,"id":2219}]}]}
{"op":"mcm","clk":"11787883158","pt":1722989916293,"mc":[{"id":"1.231431360","rc":[{"batb":[[1,1.59,4.58],[2,1.58,4.58]],"ltp":1.65,"tv":2875.96,"id":2219}]}]}
{"op":"mcm","clk":"11787886805","pt":1722989967284,"mc":[{"id":"1.231431360","rc":[{"batb":[[1,1.6,41.59],[2,1.59,4.58]],"ltp":1.65,"tv":2875.96,"id":2219}]}]}
{"op":"mcm","clk":"11787890473","pt":1722990019627,"mc":[{"id":"1.231431360","rc":[{"batb":[[1,1.59,4.58],[2,1.58,4.58]],"ltp":1.65,"tv":2875.96,"id":2219}]}]}
{"op":"mcm","clk":"11787894397","pt":1722990070175,"mc":[{"id":"1.231431360","rc":[{"batb":[[1,1.6,41.59],[2,1.59,4.58]],"ltp":1.65,"tv":2875.96,"id":2219}]}]}
{"op":"mcm","clk":"11787898512","pt":1722990123334,"mc":[{"id":"1.231431360","rc":[{"batb":[[1,1.59,4.58],[2,1.58,4.58]],"ltp":1.65,"tv":2875.96,"id":2219}]}]}
{"op":"mcm","clk":"11787902499","pt":1722990180391,"mc":[{"id":"1.231431360","rc":[{"batb":[[1,1.6,41.59],[2,1.59,4.58]],"ltp":1.65,"tv":2875.96,"id":2219}]}]}
{"op":"mcm","clk":"11787906609","pt":1722990233832,"mc":[{"id":"1.231431360","rc":[{"batb":[[1,1.59,4.58],[2,1.58,4.58]],"ltp":1.65,"tv":2875.96,"id":2219}]}]}
{"op":"mcm","clk":"11787910770","pt":1722990290997,"mc":[{"id":"1.231431360","rc":[{"batb":[[1,1.6,41.59],[2,1.59,4.58]],"ltp":1.65,"tv":2875.96,"id":2219}]}]}
{"op":"mcm","clk":"11787914696","pt":1722990343295,"mc":[{"id":"1.231431360","rc":[{"batb":[[1,1.59,4.58],[2,1.58,4.58]],"ltp":1.65,"tv":2875.96,"id":2219}]}]}
{"op":"mcm","clk":"11787918491","pt":1722990398161,"mc":[{"id":"1.231431360","rc":[{"batb":[[1,1.6,41.59],[2,1.59,4.58]],"ltp":1.65,"tv":2875.96,"id":2219}]}]}
{"op":"mcm","clk":"11787922580","pt":1722990454397,"mc":[{"id":"1.231431360","rc":[{"batb":[[1,1.59,4.58],[2,1.58,4.58]],"ltp":1.65,"tv":2875.96,"id":2219}]}]}
{"op":"mcm","clk":"11787926998","pt":1722990514286,"mc":[{"id":"1.231431360","rc":[{"batb":[[1,1.6,41.59],[2,1.59,4.58]],"ltp":1.65,"tv":2875.96,"id":2219}]}]}
{"op":"mcm","clk":"11787931290","pt":1722990573563,"mc":[{"id":"1.231431360","rc":[{"batb":[[1,1.59,4.58],[2,1.58,4.58]],"ltp":1.65,"tv":2875.96,"id":2219}]}]}
{"op":"mcm","clk":"11787935330","pt":1722990626844,"mc":[{"id":"1.231431360","rc":[{"batb":[[1,1.6,41.59],[2,1.59,4.58]],"ltp":1.65,"tv":2875.96,"id":2219}]}]}
{"op":"mcm","clk":"11787939518","pt":1722990678186,"mc":[{"id":"1.231431360","rc":[{"batb":[[1,1.59,4.58],[2,1.58,4.58]],"ltp":1.65,"tv":2875.96,"id":2219}]}]}
{"op":"mcm","clk":"11787943734","pt":1722990731149,"mc":[{"id":"1.231431360","rc":[{"batb":[[1,1.6,41.59],[2,1.59,4.58]],"ltp":1.65,"tv":2875.96,"id":2219}]}]}
{"op":"mcm","clk":"11787947924","pt":1722990788222,"mc":[{"id":"1.231431360","rc":[{"batb":[[1,1.59,4.58],[2,1.58,4.58]],"ltp":1.65,"tv":2875.96,"id":2219}]}]}
{"op":"mcm","clk":"11787951871","pt":1722990841068,"mc":[{"id":"1.231431360","rc":[{"batb":[[1,1.6,41.59],[2,1.59,4.58]],"ltp":1.65,"tv":2875.96,"id":2219}]}]}
{"op":"mcm","clk":"11787956329","pt":1722990899128,"mc":[{"id":"1.231431360","rc":[{"batb":[[1,1.59,4.58],[2,1.58,4.58]],"ltp":1.65,"tv":2875.96,"id":2219}]}]}
{"op":"mcm","clk":"11787960783","pt":1722990954274,"mc":[{"id":"1.231431360","rc":[{"batb":[[1,1.6,41.59],[2,1.59,4.58]],"ltp":1.65,"tv":2875.96,"id":2219}]}]}
{"op":"mcm","clk":"11787964909","pt":1722991006159,"mc":[{"id":"1.231431360","rc":[{"batb":[[1,1.59,4.58],[2,1.58,4.58]],"ltp":1.65,"tv":2875.96,"id":2219}]}]}
{"op":"mcm","clk":"11787969007","pt":1722991058004,"mc":[{"id":"1.231431360","rc":[{"batb":[[1,1.6,41.59],[2,1.59,4.58]],"ltp":1.65,"tv":2875.96,"id":2219}]}]}
{"op":"mcm","clk":"11787973116","pt":1722991111845,"mc":[{"id":"1.231431360","rc":[{"batb":[[1,1.59,4.58],[2,1.58,4.58]],"ltp":1.65,"tv":2875.96,"id":2219}]}]}
{"op":"mcm","clk":"11787977142","pt":1722991164196,"mc":[{"id":"1.231431360","rc":[{"batb":[[1,1.6,41.59],[2,1.59,4.58]],"ltp":1.65,"tv":2875.96,"id":2219}]}]}
{"op":"mcm","clk":"11787981029","pt":1722991215529,"mc":[{"id":"1.231431360","rc":[{"batb":[[1,1.59,4.58],[2,1.58,4.58]],"ltp":1.65,"tv":2875.96,"id":2219}]}]}
{"op":"mcm","clk":"11787984506","pt":1722991266301,"mc":[{"id":"1.231431360","rc":[{"batb":[[1,1.6,41.59],[2,1.59,4.58]],"ltp":1.65,"tv":2875.96,"id":2219}]}]}
{"op":"mcm","clk":"11787987718","pt":1722991320668,"mc":[{"id":"1.231431360","rc":[{"batb":[[1,1.59,4.58],[2,1.58,4.58]],"ltp":1.65,"tv":2875.96,"id":2219}]}]}
{"op":"mcm","clk":"11787990934","pt":1722991377597,"mc":[{"id":"1.231431360","rc":[{"batb":[[1,1.6,41.59],[2,1.59,4.58]],"ltp":1.65,"tv":2875.96,"id":2219}]}]}
{"op":"mcm","clk":"11787994715","pt":1722991431694,"mc":[{"id":"1.231431360","rc":[{"batb":[[1,1.59,4.58],[2,1.58,4.58]],"ltp":1.65,"tv":2875.96,"id":2219}]}]}
{"op":"mcm","clk":"11787998607","pt":1722991485244,"mc":[{"id":"1.231431360","rc":[{"batb":[[1,1.6,41.59],[2,1.59,4.58]],"ltp":1.65,"tv":2875.96,"id":2219}]}]}
{"op":"mcm","clk":"11788002716","pt":1722991540284,"mc":[{"id":"1.231431360","rc":[{"batb":[[1,1.59,4.58],[2,1.58,4.58]],"ltp":1.65,"tv":2875.96,"id":2219}]}]}
{"op":"mcm","clk":"11788006198","pt":1722991592230,"mc":[{"id":"1.231431360","rc":[{"batb":[[1,1.6,41.59],[2,1.59,4.58]],"ltp":1.65,"tv":2875.96,"id":2219}]}]}
{"op":"mcm","clk":"11788009837","pt":1722991644183,"mc":[{"id":"1.231431360","rc":[{"batb":[[1,1.59,4.58],[2,1.58,4.58]],"ltp":1.65,"tv":2875.96,"id":2219}]}]}
{"op":"mcm","clk":"11788013518","pt":1722991697314,"mc":[{"id":"1.231431360","rc":[{"batb":[[1,1.6,41.59],[2,1.59,4.58]],"ltp":1.65,"tv":2875.96,"id":2219}]}]}
{"op":"mcm","clk":"11788017216","pt":1722991748464,"mc":[{"id":"1.231431360","rc":[{"batb":[[1,1.59,4.58],[2,1.58,4.58]],"ltp":1.65,"tv":2875.96,"id":2219}]}]}
{"op":"mcm","clk":"11788020603","pt":1722991799146,"mc":[{"id":"1.231431360","rc":[{"batb":[[1,1.6,41.59],[2,1.59,4.58]],"ltp":1.65,"tv":2875.96,"id":2219}]}]}
{"op":"mcm","clk":"11788024223","pt":1722991850516,"mc":[{"id":"1.231431360","rc":[{"batb":[[1,1.59,4.58],[2,1.58,4.58]],"ltp":1.65,"tv":2875.96,"id":2219}]}]}
{"op":"mcm","clk":"11788027211","pt":1722991901047,"mc":[{"id":"1.231431360","rc":[{"batb":[[1,1.6,41.59],[2,1.59,4.58]],"ltp":1.65,"tv":2875.96,"id":2219}]}]}
{"op":"mcm","clk":"11788030294","pt":1722991954313,"mc":[{"id":"1.231431360","rc":[{"batb":[[1,1.59,4.58],[2,1.58,4.58]],"ltp":1.65,"tv":2875.96,"id":2219}]}]}
{"op":"mcm","clk":"11788033616","pt":1722992012206,"mc":[{"id":"1.231431360","rc":[{"batb":[[1,1.6,41.59],[2,1.59,4.58]],"ltp":1.65,"tv":2875.96,"id":2219}]}]}
{"op":"mcm","clk":"11788037036","pt":1722992067843,"mc":[{"id":"1.231431360","rc":[{"batb":[[1,1.59,4.58],[2,1.58,4.58]],"ltp":1.65,"tv":2875.96,"id":2219}]}]}
{"op":"mcm","clk":"11788040393","pt":1722992125007,"mc":[{"id":"1.231431360","rc":[{"batb":[[1,1.6,41.59],[2,1.59,4.58]],"ltp":1.65,"tv":2875.96,"id":2219}]}]}
{"op":"mcm","clk":"11788043773","pt":1722992180776,"mc":[{"id":"1.231431360","rc":[{"batb":[[1,1.59,4.58],[2,1.58,4.58]],"ltp":1.65,"tv":2875.96,"id":2219}]}]}
{"op":"mcm","clk":"11788047132","pt":1722992235751,"mc":[{"id":"1.231431360","rc":[{"batb":[[1,1.6,41.59],[2,1.59,4.58]],"ltp":1.65,"tv":2875.96,"id":2219}]}]}
{"op":"mcm","clk":"11788050883","pt":1722992295290,"mc":[{"id":"1.231431360","rc":[{"batb":[[1,1.59,4.58],[2,1.58,4.58]],"ltp":1.65,"tv":2875.96,"id":2219}]}]}
{"op":"mcm","clk":"11788054626","pt":1722992353587,"mc":[{"id":"1.231431360","rc":[{"batb":[[1,1.6,41.59],[2,1.59,4.58]],"ltp":1.65,"tv":2875.96,"id":2219}]}]}
{"op":"mcm","clk":"11788058295","pt":1722992413502,"mc":[{"id":"1.231431360","rc":[{"trd":[[1.59,90.16],[1.6,183.75],[1.61,35.3],[1.63,25.8],[1.64,5.64],[1.66,127.77],[1.67,40.94],[1.69,172.32],[1.7,1236.52],[1.71,517.23],[1.85,15.44],[1.86,7.73]],"batb":[[1,1.59,4.58],[2,1.58,4.58]],"batl":[[0,1.66,21.21]],"ltp":1.65,"tv":2875.12,"id":2219}],"tv":2875.12}]}
{"op":"mcm","clk":"11788061951","pt":1722992468895,"mc":[{"id":"1.231431360","rc":[{"batb":[[1,1.6,41.7],[2,1.59,4.58]],"ltp":1.65,"tv":2875.12,"id":2219}]}]}
{"op":"mcm","clk":"11788065302","pt":1722992522347,"mc":[{"id":"1.231431360","rc":[{"batb":[[1,1.59,4.58],[2,1.58,4.58]],"ltp":1.65,"tv":2875.12,"id":2219}]}]}
{"op":"mcm","clk":"11788068139","pt":1722992576193,"mc":[{"id":"1.231431360","rc":[{"batb":[[1,1.6,41.7],[2,1.59,4.58]],"ltp":1.65,"tv":2875.12,"id":2219}]}]}
{"op":"mcm","clk":"11788071244","pt":1722992633433,"mc":[{"id":"1.231431360","rc":[{"batb":[[1,1.59,4.58],[2,1.58,4.58]],"ltp":1.65,"tv":2875.12,"id":2219}]}]}
{"op":"mcm","clk":"11788073774","pt":1722992689269,"mc":[{"id":"1.231431360","rc":[{"batb":[[1,1.6,41.7],[2,1.59,4.58]],"ltp":1.65,"tv":2875.12,"id":2219}]}]}
{"op":"mcm","clk":"11788076608","pt":1722992743131,"mc":[{"id":"1.231431360","rc":[{"batb":[[1,1.59,4.58],[2,1.58,4.58]],"ltp":1.65,"tv":2875.12,"id":2219}]}]}
{"op":"mcm","clk":"11788080105","pt":1722992799581,"mc":[{"id":"1.231431360","rc":[{"batb":[[1,1.6,41.7],[2,1.59,4.58]],"ltp":1.65,"tv":2875.12,"id":2219}]}]}
{"op":"mcm","clk":"11788083929","pt":1722992853849,"mc":[{"id":"1.231431360","rc":[{"batb":[[1,1.59,4.58],[2,1.58,4.58]],"ltp":1.65,"tv":2875.12,"id":2219}]}]}
{"op":"mcm","clk":"11788087571","pt":1722992908298,"mc":[{"id":"1.231431360","rc":[{"batb":[[1,1.6,41.7],[2,1.59,4.58]],"ltp":1.65,"tv":2875.12,"id":2219}]}]}
{"op":"mcm","clk":"11788091027","pt":1722992960336,"mc":[{"id":"1.231431360","rc":[{"batb":[[1,1.59,4.58],[2,1.58,4.58]],"ltp":1.65,"tv":2875.12,"id":2219}]}]}
{"op":"mcm","clk":"11788094433","pt":1722993011888,"mc":[{"id":"1.231431360","rc":[{"batb":[[1,1.6,41.7],[2,1.59,4.58]],"ltp":1.65,"tv":2875.12,"id":2219}]}]}
{"op":"mcm","clk":"11788097758","pt":1722993063455,"mc":[{"id":"1.231431360","rc":[{"batb":[[1,1.59,4.58],[2,1.58,4.58]],"ltp":1.65,"tv":2875.12,"id":2219}]}]}
{"op":"mcm","clk":"11788101164","pt":1722993114004,"mc":[{"id":"1.231431360","rc":[{"batb":[[1,1.6,41.7],[2,1.59,4.58]],"ltp":1.65,"tv":2875.12,"id":2219}]}]}
{"op":"mcm","clk":"11788104169","pt":1722993165166,"mc":[{"id":"1.231431360","rc":[{"batb":[[1,1.59,4.58],[2,1.58,4.58]],"ltp":1.65,"tv":2875.12,"id":2219}]}]}
{"op":"mcm","clk":"11788115199","pt":1722993218440,"mc":[{"id":"1.231431360","rc":[{"batb":[[1,1.6,41.7],[2,1.59,4.58]],"ltp":1.65,"tv":2875.12,"id":2219}]}]}
{"op":"mcm","clk":"11788117198","pt":1722993250672,"mc":[{"id":"1.231431360","rc":[{"trd":[[1.65,82.5]],"batb":[[0,1.65,8.97]],"ltp":1.65,"tv":2877.12,"id":2219}],"tv":2877.12}]}
{"op":"mcm","clk":"11788118772","pt":1722993275479,"mc":[{"id":"1.231431360","rc":[{"batb":[[1,1.59,4.58],[2,1.58,4.58]],"ltp":1.65,"tv":2877.12,"id":2219}]}]}
{"op":"mcm","clk":"11788122326","pt":1722993329523,"mc":[{"id":"1.231431360","rc":[{"batb":[[1,1.59,46.79]],"ltp":1.65,"tv":2877.12,"id":2219}]}]}
{"op":"mcm","clk":"11788125670","pt":1722993383553,"mc":[{"id":"1.231431360","rc":[{"batb":[[1,1.59,4.58]],"ltp":1.65,"tv":2877.12,"id":2219}]}]}
{"op":"mcm","clk":"11788128812","pt":1722993437741,"mc":[{"id":"1.231431360","rc":[{"batb":[[1,1.59,46.79]],"ltp":1.65,"tv":2877.12,"id":2219}]}]}
{"op":"mcm","clk":"11788132423","pt":1722993491584,"mc":[{"id":"1.231431360","rc":[{"batb":[[1,1.59,4.58]],"ltp":1.65,"tv":2877.12,"id":2219}]}]}
{"op":"mcm","clk":"11788135941","pt":1722993544231,"mc":[{"id":"1.231431360","rc":[{"batb":[[1,1.59,46.79]],"ltp":1.65,"tv":2877.12,"id":2219}]}]}
{"op":"mcm","clk":"11788138843","pt":1722993595184,"mc":[{"id":"1.231431360","rc":[{"batb":[[1,1.59,4.58]],"ltp":1.65,"tv":2877.12,"id":2219}]}]}
{"op":"mcm","clk":"11788141812","pt":1722993646213,"mc":[{"id":"1.231431360","rc":[{"batb":[[1,1.59,46.79]],"ltp":1.65,"tv":2877.12,"id":2219}]}]}
{"op":"mcm","clk":"11788144795","pt":1722993697360,"mc":[{"id":"1.231431360","rc":[{"batb":[[1,1.59,4.58]],"ltp":1.65,"tv":2877.12,"id":2219}]}]}
{"op":"mcm","clk":"11788147952","pt":1722993749121,"mc":[{"id":"1.231431360","rc":[{"batb":[[1,1.59,46.79]],"ltp":1.65,"tv":2877.12,"id":2219}]}]}
{"op":"mcm","clk":"11788151066","pt":1722993800187,"mc":[{"id":"1.231431360","rc":[{"batb":[[1,1.59,4.58]],"ltp":1.65,"tv":2877.12,"id":2219}]}]}
{"op":"mcm","clk":"11788154024","pt":1722993855633,"mc":[{"id":"1.231431360","rc":[{"batb":[[1,1.59,46.79]],"ltp":1.65,"tv":2877.12,"id":2219}]}]}
{"op":"mcm","clk":"11788157093","pt":1722993913195,"mc":[{"id":"1.231431360","rc":[{"batb":[[1,1.59,4.58]],"ltp":1.65,"tv":2877.12,"id":2219}]}]}
{"op":"mcm","clk":"11788160372","pt":1722993967900,"mc":[{"id":"1.231431360","rc":[{"batb":[[1,1.59,46.79]],"ltp":1.65,"tv":2877.12,"id":2219}]}]}
{"op":"mcm","clk":"11788163675","pt":1722994025784,"mc":[{"id":"1.231431360","rc":[{"batb":[[1,1.59,4.58]],"ltp":1.65,"tv":2877.12,"id":2219}]}]}
{"op":"mcm","clk":"11788167061","pt":1722994084534,"mc":[{"id":"1.231431360","rc":[{"batb":[[1,1.59,46.79]],"ltp":1.65,"tv":2877.12,"id":2219}]}]}
{"op":"mcm","clk":"11788170506","pt":1722994142812,"mc":[{"id":"1.231431360","rc":[{"batb":[[1,1.59,4.58]],"ltp":1.65,"tv":2877.12,"id":2219}]}]}
{"op":"mcm","clk":"11788174479","pt":1722994203654,"mc":[{"id":"1.231431360","rc":[{"batb":[[1,1.59,46.79]],"ltp":1.65,"tv":2877.12,"id":2219}]}]}
{"op":"mcm","clk":"11788178345","pt":1722994262739,"mc":[{"id":"1.231431360","rc":[{"batb":[[1,1.59,4.58]],"ltp":1.65,"tv":2877.12,"id":2219}]}]}
{"op":"mcm","clk":"11788181518","pt":1722994316253,"mc":[{"id":"1.231431360","rc":[{"batb":[[1,1.59,46.79]],"ltp":1.65,"tv":2877.12,"id":2219}]}]}
{"op":"mcm","clk":"11788184800","pt":1722994369815,"mc":[{"id":"1.231431360","rc":[{"batb":[[1,1.59,4.58]],"ltp":1.65,"tv":2877.12,"id":2219}]}]}
{"op":"mcm","clk":"11788188077","pt":1722994421569,"mc":[{"id":"1.231431360","rc":[{"batb":[[1,1.59,46.79]],"ltp":1.65,"tv":2877.12,"id":2219}]}]}
{"op":"mcm","clk":"11788191630","pt":1722994475323,"mc":[{"id":"1.231431360","rc":[{"batb":[[1,1.59,4.58]],"ltp":1.65,"tv":2877.12,"id":2219}]}]}
{"op":"mcm","clk":"11788195809","pt":1722994531681,"mc":[{"id":"1.231431360","rc":[{"batb":[[1,1.59,46.79]],"ltp":1.65,"tv":2877.12,"id":2219}]}]}
{"op":"mcm","clk":"11788199540","pt":1722994587533,"mc":[{"id":"1.231431360","rc":[{"batb":[[1,1.59,4.58]],"ltp":1.65,"tv":2877.12,"id":2219}]}]}
{"op":"mcm","clk":"11788202719","pt":1722994642156,"mc":[{"id":"1.231431360","rc":[{"batb":[[1,1.59,46.79]],"ltp":1.65,"tv":2877.12,"id":2219}]}]}
{"op":"mcm","clk":"11788206078","pt":1722994695552,"mc":[{"id":"1.231431360","rc":[{"batb":[[1,1.59,4.58]],"ltp":1.65,"tv":2877.12,"id":2219}]}]}
{"op":"mcm","clk":"11788209745","pt":1722994750209,"mc":[{"id":"1.231431360","rc":[{"batb":[[1,1.59,46.79]],"ltp":1.65,"tv":2877.12,"id":2219}]}]}
{"op":"mcm","clk":"11788213611","pt":1722994803546,"mc":[{"id":"1.231431360","rc":[{"batb":[[1,1.59,4.58]],"ltp":1.65,"tv":2877.12,"id":2219}]}]}
{"op":"mcm","clk":"11788217368","pt":1722994859535,"mc":[{"id":"1.231431360","rc":[{"batb":[[1,1.59,46.79]],"ltp":1.65,"tv":2877.12,"id":2219}]}]}
{"op":"mcm","clk":"11788221360","pt":1722994913270,"mc":[{"id":"1.231431360","rc":[{"batb":[[1,1.59,4.58]],"ltp":1.65,"tv":2877.12,"id":2219}]}]}
{"op":"mcm","clk":"11788225311","pt":1722994966639,"mc":[{"id":"1.231431360","rc":[{"batb":[[1,1.59,46.79]],"ltp":1.65,"tv":2877.12,"id":2219}]}]}
{"op":"mcm","clk":"11788229054","pt":1722995020763,"mc":[{"id":"1.231431360","rc":[{"batb":[[1,1.59,4.58]],"ltp":1.65,"tv":2877.12,"id":2219}]}]}
{"op":"mcm","clk":"11788232981","pt":1722995074655,"mc":[{"id":"1.231431360","rc":[{"batb":[[1,1.59,46.79]],"ltp":1.65,"tv":2877.12,"id":2219}]}]}
{"op":"mcm","clk":"11788236626","pt":1722995129027,"mc":[{"id":"1.231431360","rc":[{"batb":[[1,1.59,4.58]],"ltp":1.65,"tv":2877.12,"id":2219}]}]}
{"op":"mcm","clk":"11788240762","pt":1722995185392,"mc":[{"id":"1.231431360","rc":[{"batb":[[1,1.59,46.79]],"ltp":1.65,"tv":2877.12,"id":2219}]}]}
{"op":"mcm","clk":"11788245033","pt":1722995242666,"mc":[{"id":"1.231431360","rc":[{"batb":[[1,1.59,4.58]],"ltp":1.65,"tv":2877.12,"id":2219}]}]}
{"op":"mcm","clk":"11788248898","pt":1722995295307,"mc":[{"id":"1.231431360","rc":[{"batb":[[1,1.59,46.79]],"ltp":1.65,"tv":2877.12,"id":2219}]}]}
{"op":"mcm","clk":"11788253052","pt":1722995349643,"mc":[{"id":"1.231431360","rc":[{"batb":[[1,1.59,4.58]],"ltp":1.65,"tv":2877.12,"id":2219}]}]}
{"op":"mcm","clk":"11788257096","pt":1722995403583,"mc":[{"id":"1.231431360","rc":[{"batb":[[1,1.59,46.79]],"ltp":1.65,"tv":2877.12,"id":2219}]}]}
{"op":"mcm","clk":"11788260981","pt":1722995459260,"mc":[{"id":"1.231431360","rc":[{"batb":[[1,1.59,4.58]],"ltp":1.65,"tv":2877.12,"id":2219}]}]}
{"op":"mcm","clk":"11788264560","pt":1722995512544,"mc":[{"id":"1.231431360","rc":[{"batb":[[1,1.59,46.79]],"ltp":1.65,"tv":2877.12,"id":2219}]}]}
{"op":"mcm","clk":"11788268294","pt":1722995564846,"mc":[{"id":"1.231431360","rc":[{"batb":[[1,1.59,4.58]],"ltp":1.65,"tv":2877.12,"id":2219}]}]}
{"op":"mcm","clk":"11788271736","pt":1722995617194,"mc":[{"id":"1.231431360","rc":[{"batb":[[1,1.59,46.79]],"ltp":1.65,"tv":2877.12,"id":2219}]}]}
{"op":"mcm","clk":"11788275507","pt":1722995674676,"mc":[{"id":"1.231431360","rc":[{"batb":[[1,1.59,4.58]],"ltp":1.65,"tv":2877.12,"id":2219}]}]}
{"op":"mcm","clk":"11788279129","pt":1722995731041,"mc":[{"id":"1.231431360","rc":[{"batb":[[1,1.59,46.79]],"ltp":1.65,"tv":2877.12,"id":2219}]}]}
{"op":"mcm","clk":"11788282583","pt":1722995784868,"mc":[{"id":"1.231431360","rc":[{"batb":[[1,1.59,4.58]],"ltp":1.65,"tv":2877.12,"id":2219}]}]}
{"op":"mcm","clk":"11788285920","pt":1722995847195,"mc":[{"id":"1.231431360","rc":[{"batb":[[1,1.59,46.79]],"ltp":1.65,"tv":2877.12,"id":2219}]}]}
{"op":"mcm","clk":"11788289148","pt":1722995905549,"mc":[{"id":"1.231431360","rc":[{"batb":[[1,1.59,4.58]],"ltp":1.65,"tv":2877.12,"id":2219}]}]}
{"op":"mcm","clk":"11788292174","pt":1722995963291,"mc":[{"id":"1.231431360","rc":[{"batb":[[1,1.59,46.79]],"ltp":1.65,"tv":2877.12,"id":2219}]}]}
{"op":"mcm","clk":"11788292613","pt":1722995971906,"mc":[{"id":"1.231431360","rc":[{"trd":[[1.65,82.52]],"batb":[[0,1.65,8.96]],"ltp":1.65,"tv":2877.14,"id":2219}],"tv":2877.14}]}
{"op":"mcm","clk":"11788293007","pt":1722995980407,"mc":[{"id":"1.231431360","rc":[{"trd":[[1.65,82.55]],"batb":[[0,1.65,8.95]],"ltp":1.65,"tv":2877.17,"id":2219}],"tv":2877.17}]}
{"op":"mcm","clk":"11788293381","pt":1722995987955,"mc":[{"id":"1.231431360","rc":[{"trd":[[1.65,82.57]],"batb":[[0,1.65,8.94]],"ltp":1.65,"tv":2877.19,"id":2219}],"tv":2877.19}]}
{"op":"mcm","clk":"11788293858","pt":1722995997959,"mc":[{"id":"1.231431360","rc":[{"trd":[[1.65,82.59]],"batb":[[0,1.65,8.93]],"ltp":1.65,"tv":2877.21,"id":2219}],"tv":2877.21}]}
{"op":"mcm","clk":"11788294243","pt":1722996005173,"mc":[{"id":"1.231431360","rc":[{"trd":[[1.59,90.15],[1.6,183.76],[1.61,35.29],[1.63,25.79],[1.64,5.64],[1.65,82.61],[1.66,127.71],[1.67,40.9],[1.69,172.29],[1.7,1236.3],[1.71,517.21]],"batb":[[0,1.65,8.92],[1,1.59,46.8]],"batl":[[0,1.66,21.19]],"ltp":1.65,"tv":2876.83,"id":2219}],"tv":2876.83}]}
{"op":"mcm","clk":"11788294977","pt":1722996018254,"mc":[{"id":"1.231431360","rc":[{"batb":[[1,1.59,4.57]],"ltp":1.65,"tv":2876.83,"id":2219}]}]}
{"op":"mcm","clk":"11788295207","pt":1722996022958,"mc":[{"id":"1.231431360","rc":[{"trd":[[1.65,82.64]],"batb":[[0,1.65,8.91]],"ltp":1.65,"tv":2876.85,"id":2219}],"tv":2876.85}]}
{"op":"mcm","clk":"11788296496","pt":1722996044612,"mc":[{"id":"1.231431360","rc":[{"trd":[[1.65,82.66]],"batb":[[0,1.65,8.9]],"ltp":1.65,"tv":2876.88,"id":2219}],"tv":2876.88}]}
{"op":"mcm","clk":"11788297644","pt":1722996064503,"mc":[{"id":"1.231431360","rc":[{"trd":[[1.65,82.68]],"batb":[[0,1.65,8.89]],"ltp":1.65,"tv":2876.9,"id":2219}],"tv":2876.9}]}
{"op":"mcm","clk":"11788298704","pt":1722996082007,"mc":[{"id":"1.231431360","rc":[{"batb":[[1,1.59,46.8]],"ltp":1.65,"tv":2876.9,"id":2219}]}]}
{"op":"mcm","clk":"11788298814","pt":1722996083959,"mc":[{"id":"1.231431360","rc":[{"trd":[[1.65,82.7]],"batb":[[0,1.65,8.88]],"ltp":1.65,"tv":2876.92,"id":2219}],"tv":2876.92}]}
{"op":"mcm","clk":"11788299376","pt":1722996092548,"mc":[{"id":"1.231431360","rc":[{"trd":[[1.65,82.73]],"batb":[[0,1.65,8.87]],"ltp":1.65,"tv":2876.95,"id":2219}],"tv":2876.95}]}
{"op":"mcm","clk":"11788299900","pt":1722996101159,"mc":[{"id":"1.231431360","rc":[{"trd":[[1.65,82.75]],"batb":[[0,1.65,8.86]],"ltp":1.65,"tv":2876.97,"id":2219}],"tv":2876.97}]}
{"op":"mcm","clk":"11788300605","pt":1722996113668,"mc":[{"id":"1.231431360","rc":[{"trd":[[1.65,82.77]],"batb":[[0,1.65,8.85]],"ltp":1.65,"tv":2876.99,"id":2219}],"tv":2876.99}]}
{"op":"mcm","clk":"11788301555","pt":1722996130555,"mc":[{"id":"1.231431360","rc":[{"trd":[[1.65,82.81]],"batb":[[0,1.65,8.83]],"ltp":1.65,"tv":2877.03,"id":2219}],"tv":2877.03}]}
{"op":"mcm","clk":"11788301860","pt":1722996136304,"mc":[{"id":"1.231431360","rc":[{"batb":[[1,1.59,4.57]],"ltp":1.65,"tv":2877.03,"id":2219}]}]}
{"op":"mcm","clk":"11788302468","pt":1722996148576,"mc":[{"id":"1.231431360","rc":[{"trd":[[1.65,82.85]],"batb":[[0,1.65,8.81]],"ltp":1.65,"tv":2877.07,"id":2219}],"tv":2877.07}]}
{"op":"mcm","clk":"11788303294","pt":1722996164105,"mc":[{"id":"1.231431360","rc":[{"trd":[[1.65,82.89]],"batb":[[0,1.65,8.79]],"ltp":1.65,"tv":2877.1,"id":2219}],"tv":2877.1}]}
{"op":"mcm","clk":"11788304200","pt":1722996185538,"mc":[{"id":"1.231431360","rc":[{"trd":[[1.65,82.92]],"batb":[[0,1.65,8.77]],"ltp":1.65,"tv":2877.14,"id":2219}],"tv":2877.14}]}
{"op":"mcm","clk":"11788304403","pt":1722996190423,"mc":[{"id":"1.231431360","rc":[{"batb":[[1,1.59,46.8]],"ltp":1.65,"tv":2877.14,"id":2219}]}]}
{"op":"mcm","clk":"11788305275","pt":1722996212047,"mc":[{"id":"1.231431360","rc":[{"trd":[[1.65,82.96]],"batb":[[0,1.65,8.75]],"ltp":1.65,"tv":2877.18,"id":2219}],"tv":2877.18}]}
{"op":"mcm","clk":"11788305819","pt":1722996224979,"mc":[{"id":"1.231431360","rc":[{"trd":[[2.52,6.1]],"batb":[[0,2.32,29.6],[1,2.14,38.68],[2,1.74,17.32]],"ltp":2.52,"tv":6.09,"id":31379}],"tv":2883.27}]}
{"op":"mcm","clk":"11788305846","pt":1722996225799,"mc":[{"id":"1.231431360","rc":[{"batb":[[0,2.5,12.56],[1,2.32,28.65],[2,2.14,38.68]],"ltp":2.52,"tv":6.09,"id":31379}]}]}
{"op":"mcm","clk":"11788305990","pt":1722996228698,"mc":[{"id":"1.231431360","rc":[{"batb":[[1,2.14,38.68],[2,1.74,17.32]],"ltp":2.52,"tv":6.09,"id":31379}]}]}
{"op":"mcm","clk":"11788306407","pt":1722996238494,"mc":[{"id":"1.231431360","rc":[{"batb":[[0,2.5,16.56]],"ltp":2.52,"tv":6.09,"id":31379}]}]}
{"op":"mcm","clk":"11788306577","pt":1722996242294,"mc":[{"id":"1.231431360","rc":[{"batb":[[1,1.59,4.57]],"ltp":1.65,"tv":2877.18,"id":2219}]}]}
{"op":"mcm","clk":"11788309012","pt":1722996295257,"mc":[{"id":"1.231431360","rc":[{"batb":[[1,1.59,46.8]],"ltp":1.65,"tv":2877.18,"id":2219}]}]}
{"op":"mcm","clk":"11788310283","pt":1722996321963,"mc":[{"id":"1.231431360","rc":[{"batb":[[0,1.65,43.15]],"ltp":1.65,"tv":2877.18,"id":2219}]}]}
{"op":"mcm","clk":"11788310368","pt":1722996324473,"mc":[{"id":"1.231431360","rc":[{"batl":[[0,1.66,4]],"ltp":1.65,"tv":2877.18,"id":2219}]}]}
{"op":"mcm","clk":"11788311539","pt":1722996349819,"mc":[{"id":"1.231431360","rc":[{"batb":[[1,1.59,4.57]],"ltp":1.65,"tv":2877.18,"id":2219}]}]}
{"op":"mcm","clk":"11788321586","pt":1722996554905,"mc":[{"id":"1.231431360","rc":[{"trd":[[1.65,84.14]],"batb":[[0,1.65,42.56]],"ltp":1.65,"tv":2878.35,"id":2219}],"tv":2884.45}]}
{"op":"mcm","clk":"11788332426","pt":1722996776437,"mc":[{"id":"1.231431360","rc":[{"batb":[[1,1.63,20.13],[2,1.59,4.57]],"ltp":1.65,"tv":2878.35,"id":2219}]}]}
{"op":"mcm","clk":"11788344883","pt":1722997038981,"mc":[{"id":"1.231431360","rc":[{"batb":[[0,1.65,8.16]],"ltp":1.65,"tv":2878.35,"id":2219}]}]}
{"op":"mcm","clk":"11788345023","pt":1722997041767,"mc":[{"id":"1.231431360","rc":[{"batl":[[0,1.66,21.19]],"ltp":1.65,"tv":2878.35,"id":2219}]}]}
{"op":"mcm","clk":"11788346787","pt":1722997080945,"mc":[{"id":"1.231431360","rc":[{"trd":[[2.52,7.05]],"batb":[[0,2.5,15.61]],"ltp":2.52,"tv":7.04,"id":31379},{"trd":[[1.66,171.54]],"batb":[[0,1.66,11.42],[1,1.65,8.16],[2,1.63,20.13]],"batl":[[0,1.67,300],[1,1.68,400],[2,1.69,500]],"ltp":1.66,"tv":2922.18,"id":2219}],"tv":2929.23}]}
{"op":"mcm","clk":"11788346847","pt":1722997082131,"mc":[{"id":"1.231431360","rc":[{"batb":[[2,1.64,17.4]],"ltp":1.66,"tv":2922.18,"id":2219}]}]}
{"op":"mcm","clk":"11788346896","pt":1722997083207,"mc":[{"id":"1.231431360","rc":[{"batl":[[0,1.67,304]],"ltp":1.66,"tv":2922.18,"id":2219}]}]}
{"op":"mcm","clk":"11788347128","pt":1722997087650,"mc":[{"id":"1.231431360","rc":[{"batb":[[0,2.5,25.66]],"ltp":2.52,"tv":7.04,"id":31379},{"trd":[[1.66,194.38]],"batb":[[0,1.65,8.16],[1,1.64,17.4],[2,1.63,20.13]],"batl":[[0,1.66,4.65],[1,1.67,304],[2,1.68,400]],"ltp":1.66,"tv":2945.03,"id":2219}],"tv":2952.07}]}
{"op":"mcm","clk":"11788464215","pt":1722999724453,"mc":[{"id":"1.231431360","rc":[{"trd":[[2.54,5.3],[2.58,11.05],[2.6,12.62],[2.7,1.95]],"batb":[[0,2.5,25.65]],"ltp":2.7,"tv":37.96,"id":31379},{"trd":[[1.59,93.46],[1.6,183.74],[1.61,35.28],[1.63,45.92],[1.64,23.02],[1.65,92.3],[1.66,194.32],[1.67,40.88],[1.69,172.28],[1.7,1236.12],[1.71,517.2],[1.85,15.44]],"batb":[[0,1.59,1.25],[1,1.58,4.57],[2,1.56,9.78]],"batl":[[0,1.66,4.65]],"ltp":1.59,"tv":2993.69,"id":2219}],"tv":3031.66}]}
{"op":"mcm","clk":"11788464281","pt":1722999725944,"mc":[{"id":"1.231431360","rc":[{"batl":[[0,1.66,21.83]],"ltp":1.59,"tv":2993.69,"id":2219}]}]}
{"op":"mcm","clk":"11788464303","pt":1722999726815,"mc":[{"id":"1.231431360","rc":[{"batb":[[1,2.32,28.65],[2,2.14,38.68]],"ltp":2.7,"tv":37.96,"id":31379}]}]}
{"op":"mcm","clk":"11788464681","pt":1722999738832,"mc":[{"id":"1.231431360","rc":[{"batb":[[1,2.34,6.9],[2,2.32,28.65]],"ltp":2.7,"tv":37.96,"id":31379}]}]}
{"op":"mcm","clk":"11788465523","pt":1722999763747,"mc":[{"id":"1.231431360","rc":[{"batb":[[0,2.52,26.79],[1,2.5,25.65],[2,2.34,6.9]],"ltp":2.7,"tv":37.96,"id":31379}]}]}
{"op":"mcm","clk":"11788465559","pt":1722999764785,"mc":[{"id":"1.231431360","rc":[{"batb":[[1,2.5,15.61]],"ltp":2.7,"tv":37.96,"id":31379}]}]}
{"op":"mcm","clk":"11788471482","pt":1722999942654,"mc":[{"id":"1.231431360","rc":[{"batb":[[2,2.44,26.26]],"ltp":2.7,"tv":37.96,"id":31379}]}]}
{"op":"mcm","clk":"11788471904","pt":1722999958999,"mc":[{"id":"1.231431360","rc":[{"trd":[[1.59,95.97]],"batb":[[0,1.58,4.57],[1,1.56,9.78],[2,1.54,180]],"batl":[[0,1.66,22.68]],"ltp":1.59,"tv":2996.2,"id":2219}],"tv":3034.17}]}
{"op":"mcm","clk":"11788471940","pt":1722999960593,"mc":[{"id":"1.231431360","rc":[{"batb":[[0,2.54,12],[1,2.52,26.79],[2,2.5,15.61]],"batl":[[0,2.84,12.65]],"ltp":2.7,"tv":37.96,"id":31379},{"batl":[[0,1.66,18.03]],"ltp":1.59,"tv":2996.2,"id":2219}]}]}
{"op":"mcm","clk":"11788472005","pt":1722999962396,"mc":[{"id":"1.231431360","rc":[{"batb":[[0,2.54,10],[2,2.5,4]],"ltp":2.7,"tv":37.96,"id":31379},{"batb":[[2,1.55,12.23]],"ltp":1.59,"tv":2996.2,"id":2219}]}]}
{"op":"mcm","clk":"11788472029","pt":1722999963114,"mc":[{"id":"1.231431360","rc":[{"batb":[[0,2.52,26.79],[1,2.5,4],[2,2.44,26.26]],"ltp":2.7,"tv":37.96,"id":31379}]}]}
{"op":"mcm","clk":"11788472059","pt":1722999963888,"mc":[{"id":"1.231431360","rc":[{"batl":[[0,2.84,7.89]],"ltp":2.7,"tv":37.96,"id":31379}]}]}
{"op":"mcm","clk":"11788472092","pt":1722999965016,"mc":[{"id":"1.231431360","rc":[{"batb":[[0,2.54,2],[1,2.52,26.79],[2,2.5,4]],"ltp":2.7,"tv":37.96,"id":31379}]}]}
{"op":"mcm","clk":"11788472161","pt":1722999967384,"mc":[{"id":"1.231431360","rc":[{"batb":[[0,2.54,10]],"ltp":2.7,"tv":37.96,"id":31379}]}]}
{"op":"mcm","clk":"11788472191","pt":1722999969093,"mc":[{"id":"1.231431360","rc":[{"batl":[[0,1.66,17.18]],"ltp":1.59,"tv":2996.2,"id":2219}]}]}
{"op":"mcm","clk":"11788472234","pt":1722999970634,"mc":[{"id":"1.231431360","rc":[{"batb":[[0,2.56,2]],"ltp":2.7,"tv":37.96,"id":31379}]}]}
{"op":"mcm","clk":"11788472288","pt":1722999972428,"mc":[{"id":"1.231431360","rc":[{"batb":[[0,2.52,26.79],[1,2.5,4],[2,2.44,26.26]],"ltp":2.7,"tv":37.96,"id":31379}]}]}
{"op":"mcm","clk":"11788472309","pt":1722999974026,"mc":[{"id":"1.231431360","rc":[{"batb":[[0,2.54,10],[1,2.52,26.79],[2,2.5,4]],"ltp":2.7,"tv":37.96,"id":31379}]}]}
{"op":"mcm","clk":"11788472375","pt":1722999976391,"mc":[{"id":"1.231431360","rc":[{"batb":[[0,2.56,2],[1,2.54,10],[2,2.52,26.79]],"ltp":2.7,"tv":37.96,"id":31379}]}]}
{"op":"mcm","clk":"11788472395","pt":1722999977312,"mc":[{"id":"1.231431360","rc":[{"batb":[[1,2.52,26.79],[2,2.5,4]],"ltp":2.7,"tv":37.96,"id":31379}]}]}
{"op":"mcm","clk":"11788472430","pt":1722999978642,"mc":[{"id":"1.231431360","rc":[{"batb":[[0,2.52,26.79],[1,2.5,4],[2,2.44,26.26]],"ltp":2.7,"tv":37.96,"id":31379}]}]}
{"op":"mcm","clk":"11788472462","pt":1722999979717,"mc":[{"id":"1.231431360","rc":[{"batb":[[0,2.54,10],[1,2.52,26.79],[2,2.5,4]],"ltp":2.7,"tv":37.96,"id":31379}]}]}
{"op":"mcm","clk":"11788472486","pt":1722999980806,"mc":[{"id":"1.231431360","rc":[{"batb":[[0,2.56,2],[1,2.54,10],[2,2.52,26.79]],"ltp":2.7,"tv":37.96,"id":31379}]}]}
{"op":"mcm","clk":"11788472544","pt":1722999983109,"mc":[{"id":"1.231431360","rc":[{"batb":[[0,2.52,26.79],[1,2.5,4],[2,2.44,26.26]],"ltp":2.7,"tv":37.96,"id":31379}]}]}
{"op":"mcm","clk":"11788472618","pt":1722999986230,"mc":[{"id":"1.231431360","rc":[{"batb":[[0,2.54,12],[1,2.52,26.79],[2,2.5,4]],"ltp":2.7,"tv":37.96,"id":31379},{"batb":[[1,1.56,52.54]],"ltp":1.59,"tv":2996.2,"id":2219}]}]}
{"op":"mcm","clk":"11788472635","pt":1722999986846,"mc":[{"id":"1.231431360","rc":[{"batb":[[1,1.57,12.07],[2,1.56,52.54]],"ltp":1.59,"tv":2996.2,"id":2219}]}]}
{"op":"mcm","clk":"11788472682","pt":1722999988639,"mc":[{"id":"1.231431360","rc":[{"batb":[[0,2.54,10]],"ltp":2.7,"tv":37.96,"id":31379}]}]}
{"op":"mcm","clk":"11788472693","pt":1722999989512,"mc":[{"id":"1.231431360","rc":[{"batb":[[0,2.52,26.79],[1,2.5,4],[2,2.44,26.26]],"ltp":2.7,"tv":37.96,"id":31379}]}]}
{"op":"mcm","clk":"11788472956","pt":1722999999941,"mc":[{"id":"1.231431360","rc":[{"trd":[[1.58,2.52]],"batb":[[0,1.58,3.31]],"ltp":1.58,"tv":2998.73,"id":2219}],"tv":3036.69}]}
{"op":"mcm","clk":"11788474168","pt":1723000041901,"mc":[{"id":"1.231431360","rc":[{"batb":[[2,1.56,9.78]],"ltp":1.58,"tv":2998.73,"id":2219}]}]}
{"op":"mcm","clk":"11788474215","pt":1723000043597,"mc":[{"id":"1.231431360","rc":[{"batb":[[0,2.54,12],[1,2.52,26.79],[2,2.5,4]],"batl":[[0,2.84,7.28]],"ltp":2.7,"tv":37.96,"id":31379},{"batb":[[1,1.56,9.78],[2,1.55,12.23]],"ltp":1.58,"tv":2998.73,"id":2219}]}]}
{"op":"mcm","clk":"11788474245","pt":1723000045089,"mc":[{"id":"1.231431360","rc":[{"batl":[[0,2.84,12.4]],"ltp":2.7,"tv":37.96,"id":31379}]}]}
{"op":"mcm","clk":"11788474267","pt":1723000045809,"mc":[{"id":"1.231431360","rc":[{"batb":[[0,2.54,10]],"ltp":2.7,"tv":37.96,"id":31379}]}]}
{"op":"mcm","clk":"11788474299","pt":1723000046991,"mc":[{"id":"1.231431360","rc":[{"batb":[[0,2.52,26.79],[1,2.5,4],[2,2.44,26.26]],"batl":[[0,2.84,7.28]],"ltp":2.7,"tv":37.96,"id":31379}]}]}
{"op":"mcm","clk":"11788474341","pt":1723000048117,"mc":[{"id":"1.231431360","rc":[{"batb":[[0,2.54,2],[1,2.52,26.79],[2,2.5,4]],"ltp":2.7,"tv":37.96,"id":31379}]}]}
{"op":"mcm","clk":"11788474403","pt":1723000050526,"mc":[{"id":"1.231431360","rc":[{"batb":[[0,2.54,10]],"ltp":2.7,"tv":37.96,"id":31379}]}]}
{"op":"mcm","clk":"11788474488","pt":1723000054018,"mc":[{"id":"1.231431360","rc":[{"batb":[[0,2.54,2]],"ltp":2.7,"tv":37.96,"id":31379}]}]}
{"op":"mcm","clk":"11788474566","pt":1723000056514,"mc":[{"id":"1.231431360","rc":[{"batb":[[0,2.54,10]],"ltp":2.7,"tv":37.96,"id":31379}]}]}
{"op":"mcm","clk":"11788474683","pt":1723000059635,"mc":[{"id":"1.231431360","rc":[{"batb":[[0,2.56,2]],"ltp":2.7,"tv":37.96,"id":31379}]}]}
{"op":"mcm","clk":"11788474756","pt":1723000061911,"mc":[{"id":"1.231431360","rc":[{"batb":[[0,2.54,10]],"ltp":2.7,"tv":37.96,"id":31379}]}]}
{"op":"mcm","clk":"11788474873","pt":1723000065705,"mc":[{"id":"1.231431360","rc":[{"batb":[[0,2.56,2]],"ltp":2.7,"tv":37.96,"id":31379}]}]}
{"op":"mcm","clk":"11788474953","pt":1723000068132,"mc":[{"id":"1.231431360","rc":[{"batb":[[0,2.54,10]],"ltp":2.7,"tv":37.96,"id":31379}]}]}
{"op":"mcm","clk":"11788475064","pt":1723000071325,"mc":[{"id":"1.231431360","rc":[{"batb":[[0,2.56,2]],"ltp":2.7,"tv":37.96,"id":31379}]}]}
{"op":"mcm","clk":"11788475139","pt":1723000073529,"mc":[{"id":"1.231431360","rc":[{"batb":[[0,2.54,10]],"ltp":2.7,"tv":37.96,"id":31379}]}]}
{"op":"mcm","clk":"11788475199","pt":1723000075641,"mc":[{"id":"1.231431360","rc":[{"batb":[[0,2.56,2],[1,2.54,10],[2,2.52,26.79]],"ltp":2.7,"tv":37.96,"id":31379}]}]}
{"op":"mcm","clk":"11788475233","pt":1723000076937,"mc":[{"id":"1.231431360","rc":[{"batb":[[1,2.52,26.79],[2,2.5,4]],"ltp":2.7,"tv":37.96,"id":31379}]}]}
{"op":"mcm","clk":"11788475271","pt":1723000077864,"mc":[{"id":"1.231431360","rc":[{"batb":[[0,2.52,26.79],[1,2.5,4],[2,2.44,26.26]],"ltp":2.7,"tv":37.96,"id":31379}]}]}
{"op":"mcm","clk":"11788475324","pt":1723000080025,"mc":[{"id":"1.231431360","rc":[{"batb":[[0,2.54,12],[1,2.52,26.79],[2,2.5,4]],"ltp":2.7,"tv":37.96,"id":31379}]}]}
{"op":"mcm","clk":"11788475384","pt":1723000082252,"mc":[{"id":"1.231431360","rc":[{"batb":[[0,2.54,10]],"ltp":2.7,"tv":37.96,"id":31379}]}]}
{"op":"mcm","clk":"11788475430","pt":1723000083442,"mc":[{"id":"1.231431360","rc":[{"batb":[[0,2.52,26.79],[1,2.5,4],[2,2.44,26.26]],"ltp":2.7,"tv":37.96,"id":31379}]}]}
{"op":"mcm","clk":"11788475476","pt":1723000084521,"mc":[{"id":"1.231431360","rc":[{"batb":[[0,2.54,2],[1,2.52,26.79],[2,2.5,4]],"ltp":2.7,"tv":37.96,"id":31379}]}]}
{"op":"mcm","clk":"11788475565","pt":1723000086942,"mc":[{"id":"1.231431360","rc":[{"batb":[[0,2.54,10]],"ltp":2.7,"tv":37.96,"id":31379}]}]}
{"op":"mcm","clk":"11788475642","pt":1723000089058,"mc":[{"id":"1.231431360","rc":[{"batb":[[0,2.56,2],[1,2.54,10],[2,2.52,26.79]],"ltp":2.7,"tv":37.96,"id":31379}]}]}
{"op":"mcm","clk":"11788475690","pt":1723000090650,"mc":[{"id":"1.231431360","rc":[{"batb":[[1,2.52,26.79],[2,2.5,4]],"ltp":2.7,"tv":37.96,"id":31379},{"batl":[[0,1.64,18.04]],"ltp":1.58,"tv":2998.73,"id":2219}]}]}
{"op":"mcm","clk":"11788475711","pt":1723000091370,"mc":[{"id":"1.231431360","rc":[{"batb":[[0,2.52,26.79],[1,2.5,4],[2,2.44,26.26]],"ltp":2.7,"tv":37.96,"id":31379}]}]}
{"op":"mcm","clk":"11788475785","pt":1723000093636,"mc":[{"id":"1.231431360","rc":[{"batb":[[0,2.56,2],[1,2.54,10],[2,2.52,26.79]],"ltp":2.7,"tv":37.96,"id":31379}]}]}
{"op":"mcm","clk":"11788475839","pt":1723000095844,"mc":[{"id":"1.231431360","rc":[{"batb":[[0,2.54,10],[1,2.52,26.79],[2,2.5,4]],"ltp":2.7,"tv":37.96,"id":31379}]}]}
{"op":"mcm","clk":"11788475871","pt":1723000096864,"mc":[{"id":"1.231431360","rc":[{"batb":[[0,2.52,26.79],[1,2.5,4],[2,2.44,26.26]],"ltp":2.7,"tv":37.96,"id":31379}]}]}
{"op":"mcm","clk":"11788475909","pt":1723000098664,"mc":[{"id":"1.231431360","rc":[{"batb":[[0,2.54,2],[1,2.52,26.79],[2,2.5,4]],"ltp":2.7,"tv":37.96,"id":31379}]}]}
{"op":"mcm","clk":"11788475944","pt":1723000100261,"mc":[{"id":"1.231431360","rc":[{"batb":[[0,2.58,10],[1,2.56,26.27],[2,2.54,2]],"ltp":2.7,"tv":37.96,"id":31379},{"batb":[[1,1.57,42.76],[2,1.56,9.78]],"batl":[[0,1.64,22.04]],"ltp":1.58,"tv":2998.73,"id":2219}]}]}
{"op":"mcm","clk":"11788475959","pt":1723000101075,"mc":[{"id":"1.231431360","rc":[{"batb":[[2,2.5,4]],"ltp":2.7,"tv":37.96,"id":31379},{"batb":[[0,1.58,15.31]],"ltp":1.58,"tv":2998.73,"id":2219}]}]}
{"op":"mcm","clk":"11788476012","pt":1723000103183,"mc":[{"id":"1.231431360","rc":[{"batb":[[0,2.56,26.27],[1,2.5,4],[2,2.44,26.26]],"ltp":2.7,"tv":37.96,"id":31379}]}]}
{"op":"mcm","clk":"11788477168","pt":1723000144443,"mc":[{"id":"1.231431360","rc":[{"batl":[[0,1.64,4]],"ltp":1.58,"tv":2998.73,"id":2219}]}]}
{"op":"mcm","clk":"11788477544","pt":1723000156369,"mc":[{"id":"1.231431360","rc":[{"batb":[[0,2.5,4],[1,2.44,26.26],[2,2.38,6.78]],"ltp":2.7,"tv":37.96,"id":31379},{"batb":[[1,1.56,9.78],[2,1.54,180]],"ltp":1.58,"tv":2998.73,"id":2219}]}]}
{"op":"mcm","clk":"11788477565","pt":1723000157348,"mc":[{"id":"1.231431360","rc":[{"batb":[[0,2.5,15.61]],"ltp":2.7,"tv":37.96,"id":31379},{"batb":[[0,1.58,3.31],[2,1.55,12.23]],"batl":[[0,1.66,17.18]],"ltp":1.58,"tv":2998.73,"id":2219}]}]}
{"op":"mcm","clk":"11788477633","pt":1723000159668,"mc":[{"id":"1.231431360","rc":[{"batb":[[0,2.52,12],[1,2.5,15.61],[2,2.44,26.26]],"batl":[[0,2.84,12.4]],"ltp":2.7,"tv":37.96,"id":31379}]}]}
{"op":"mcm","clk":"11788477654","pt":1723000160543,"mc":[{"id":"1.231431360","rc":[{"batl":[[0,2.84,7.64]],"ltp":2.7,"tv":37.96,"id":31379}]}]}
{"op":"mcm","clk":"11788477672","pt":1723000161164,"mc":[{"id":"1.231431360","rc":[{"batb":[[0,2.52,10]],"ltp":2.7,"tv":37.96,"id":31379}]}]}
{"op":"mcm","clk":"11788477697","pt":1723000162351,"mc":[{"id":"1.231431360","rc":[{"batb":[[0,2.5,15.61],[1,2.44,26.26],[2,2.38,6.78]],"ltp":2.7,"tv":37.96,"id":31379}]}]}
{"op":"mcm","clk":"11788477743","pt":1723000163435,"mc":[{"id":"1.231431360","rc":[{"batb":[[0,2.52,2],[1,2.5,15.61],[2,2.44,26.26]],"ltp":2.7,"tv":37.96,"id":31379}]}]}
{"op":"mcm","clk":"11788477798","pt":1723000165668,"mc":[{"id":"1.231431360","rc":[{"batb":[[0,2.5,15.61],[1,2.44,26.26],[2,2.38,6.78]],"ltp":2.7,"tv":37.96,"id":31379}]}]}
{"op":"mcm","clk":"11788477802","pt":1723000165779,"mc":[{"id":"1.231431360","rc":[{"batb":[[0,2.52,10],[1,2.5,15.61],[2,2.44,26.26]],"ltp":2.7,"tv":37.96,"id":31379}]}]}
{"op":"mcm","clk":"11788477871","pt":1723000167849,"mc":[{"id":"1.231431360","rc":[{"batb":[[0,2.54,2],[1,2.52,10],[2,2.5,15.61]],"ltp":2.7,"tv":37.96,"id":31379}]}]}
{"op":"mcm","clk":"11788477907","pt":1723000169039,"mc":[{"id":"1.231431360","rc":[{"batb":[[1,2.5,15.61],[2,2.44,26.26]],"ltp":2.7,"tv":37.96,"id":31379}]}]}
{"op":"mcm","clk":"11788477943","pt":1723000170318,"mc":[{"id":"1.231431360","rc":[{"batb":[[0,2.5,15.61],[1,2.44,26.26],[2,2.38,6.78]],"ltp":2.7,"tv":37.96,"id":31379}]}]}
{"op":"mcm","clk":"11788478008","pt":1723000172485,"mc":[{"id":"1.231431360","rc":[{"batb":[[0,2.54,2],[1,2.52,10],[2,2.5,15.61]],"ltp":2.7,"tv":37.96,"id":31379}]}]}
{"op":"mcm","clk":"11788478124","pt":1723000175654,"mc":[{"id":"1.231431360","rc":[{"batb":[[0,2.5,15.61],[1,2.44,26.26],[2,2.38,6.78]],"ltp":2.7,"tv":37.96,"id":31379}]}]}
{"op":"mcm","clk":"11788478246","pt":1723000178053,"mc":[{"id":"1.231431360","rc":[{"batb":[[0,2.52,12],[1,2.5,15.61],[2,2.44,26.26]],"ltp":2.7,"tv":37.96,"id":31379}]}]}
{"op":"mcm","clk":"11788478310","pt":1723000180371,"mc":[{"id":"1.231431360","rc":[{"batb":[[0,2.52,10]],"ltp":2.7,"tv":37.96,"id":31379}]}]}
{"op":"mcm","clk":"11788478337","pt":1723000181398,"mc":[{"id":"1.231431360","rc":[{"batb":[[0,2.5,15.61],[1,2.44,26.26],[2,2.38,6.78]],"ltp":2.7,"tv":37.96,"id":31379}]}]}
{"op":"mcm","clk":"11788478403","pt":1723000183576,"mc":[{"id":"1.231431360","rc":[{"batb":[[0,2.52,12],[1,2.5,15.61],[2,2.44,26.26]],"ltp":2.7,"tv":37.96,"id":31379}]}]}
{"op":"mcm","clk":"11788478476","pt":1723000185984,"mc":[{"id":"1.231431360","rc":[{"batb":[[0,2.52,10]],"ltp":2.7,"tv":37.96,"id":31379}]}]}
{"op":"mcm","clk":"11788478506","pt":1723000187104,"mc":[{"id":"1.231431360","rc":[{"batb":[[0,2.5,15.61],[1,2.44,26.26],[2,2.38,6.78]],"ltp":2.7,"tv":37.96,"id":31379}]}]}
{"op":"mcm","clk":"11788478551","pt":1723000189061,"mc":[{"id":"1.231431360","rc":[{"batb":[[0,2.52,2],[1,2.5,15.61],[2,2.44,26.26]],"ltp":2.7,"tv":37.96,"id":31379}]}]}
{"op":"mcm","clk":"11788478623","pt":1723000191475,"mc":[{"id":"1.231431360","rc":[{"batb":[[0,2.52,10]],"ltp":2.7,"tv":37.96,"id":31379}]}]}
{"op":"mcm","clk":"11788478686","pt":1723000193579,"mc":[{"id":"1.231431360","rc":[{"batb":[[0,2.54,2],[1,2.52,10],[2,2.5,15.61]],"ltp":2.7,"tv":37.96,"id":31379}]}]}
{"op":"mcm","clk":"11788478721","pt":1723000194713,"mc":[{"id":"1.231431360","rc":[{"batb":[[1,2.5,15.61],[2,2.44,26.26]],"ltp":2.7,"tv":37.96,"id":31379}]}]}
{"op":"mcm","clk":"11788478762","pt":1723000195892,"mc":[{"id":"1.231431360","rc":[{"batb":[[0,2.5,15.61],[1,2.44,26.26],[2,2.38,6.78]],"ltp":2.7,"tv":37.96,"id":31379}]}]}
{"op":"mcm","clk":"11788478781","pt":1723000197015,"mc":[{"id":"1.231431360","rc":[{"batb":[[0,2.52,10],[1,2.5,15.61],[2,2.44,26.26]],"ltp":2.7,"tv":37.96,"id":31379}]}]}
{"op":"mcm","clk":"11788478798","pt":1723000198097,"mc":[{"id":"1.231431360","rc":[{"batb":[[0,2.54,2],[1,2.52,10],[2,2.5,15.61]],"ltp":2.7,"tv":37.96,"id":31379}]}]}
{"op":"mcm","clk":"11788478839","pt":1723000200315,"mc":[{"id":"1.231431360","rc":[{"batb":[[0,2.5,15.61],[1,2.44,26.26],[2,2.38,6.78]],"ltp":2.7,"tv":37.96,"id":31379}]}]}
{"op":"mcm","clk":"11788478911","pt":1723000202514,"mc":[{"id":"1.231431360","rc":[{"batb":[[0,2.52,12],[1,2.5,15.61],[2,2.44,26.26]],"ltp":2.7,"tv":37.96,"id":31379}]}]}
{"op":"mcm","clk":"11788478981","pt":1723000204793,"mc":[{"id":"1.231431360","rc":[{"batb":[[0,2.52,10]],"ltp":2.7,"tv":37.96,"id":31379}]}]}
{"op":"mcm","clk":"11788479013","pt":1723000205824,"mc":[{"id":"1.231431360","rc":[{"batb":[[0,2.5,15.61],[1,2.44,26.26],[2,2.38,6.78]],"ltp":2.7,"tv":37.96,"id":31379}]}]}
{"op":"mcm","clk":"11788479112","pt":1723000208216,"mc":[{"id":"1.231431360","rc":[{"batb":[[0,2.52,12],[1,2.5,15.61],[2,2.44,26.26]],"ltp":2.7,"tv":37.96,"id":31379}]}]}
{"op":"mcm","clk":"11788479192","pt":1723000210423,"mc":[{"id":"1.231431360","rc":[{"batb":[[0,2.52,10]],"ltp":2.7,"tv":37.96,"id":31379}]}]}
{"op":"mcm","clk":"11788479223","pt":1723000211601,"mc":[{"id":"1.231431360","rc":[{"batb":[[0,2.52,26.79]],"ltp":2.7,"tv":37.96,"id":31379},{"batb":[[1,1.56,52.54]],"ltp":1.58,"tv":2998.73,"id":2219}]}]}
{"op":"mcm","clk":"11788479257","pt":1723000212321,"mc":[{"id":"1.231431360","rc":[{"batb":[[1,1.57,12.07],[2,1.56,52.54]],"ltp":1.58,"tv":2998.73,"id":2219}]}]}
{"op":"mcm","clk":"11788481272","pt":1723000271091,"mc":[{"id":"1.231431360","rc":[{"batb":[[2,1.56,9.78]],"ltp":1.58,"tv":2998.73,"id":2219}]}]}
{"op":"mcm","clk":"11788481359","pt":1723000272993,"mc":[{"id":"1.231431360","rc":[{"batb":[[1,1.56,9.78],[2,1.55,12.23]],"ltp":1.58,"tv":2998.73,"id":2219}]}]}
{"op":"mcm","clk":"11788481431","pt":1723000274595,"mc":[{"id":"1.231431360","rc":[{"batb":[[0,2.54,12],[1,2.52,26.79],[2,2.5,15.61]],"batl":[[0,2.84,4.76]],"ltp":2.7,"tv":37.96,"id":31379}]}]}
{"op":"mcm","clk":"11788481478","pt":1723000275884,"mc":[{"id":"1.231431360","rc":[{"batb":[[2,2.5,4]],"batl":[[0,2.84,12.4]],"ltp":2.7,"tv":37.96,"id":31379}]}]}
{"op":"mcm","clk":"11788481515","pt":1723000276863,"mc":[{"id":"1.231431360","rc":[{"batb":[[0,2.54,10]],"ltp":2.7,"tv":37.96,"id":31379}]}]}
{"op":"mcm","clk":"11788481544","pt":1723000277791,"mc":[{"id":"1.231431360","rc":[{"batb":[[0,2.52,26.79],[1,2.5,4],[2,2.44,26.26]],"batl":[[0,2.84,7.64]],"ltp":2.7,"tv":37.96,"id":31379}]}]}
{"op":"mcm","clk":"11788481638","pt":1723000280100,"mc":[{"id":"1.231431360","rc":[{"batb":[[0,2.54,12],[1,2.52,26.79],[2,2.5,4]],"ltp":2.7,"tv":37.96,"id":31379}]}]}
{"op":"mcm","clk":"11788481718","pt":1723000282408,"mc":[{"id":"1.231431360","rc":[{"batb":[[0,2.54,10]],"ltp":2.7,"tv":37.96,"id":31379}]}]}
{"op":"mcm","clk":"11788481753","pt":1723000283387,"mc":[{"id":"1.231431360","rc":[{"batb":[[0,2.52,26.79],[1,2.5,4],[2,2.44,26.26]],"ltp":2.7,"tv":37.96,"id":31379}]}]}
{"op":"mcm","clk":"11788481788","pt":1723000284468,"mc":[{"id":"1.231431360","rc":[{"batb":[[0,2.54,2],[1,2.52,26.79],[2,2.5,4]],"ltp":2.7,"tv":37.96,"id":31379}]}]}
{"op":"mcm","clk":"11788481896","pt":1723000286983,"mc":[{"id":"1.231431360","rc":[{"batb":[[0,2.54,10]],"ltp":2.7,"tv":37.96,"id":31379}]}]}
{"op":"mcm","clk":"11788481958","pt":1723000289086,"mc":[{"id":"1.231431360","rc":[{"batb":[[0,2.56,2],[1,2.54,10],[2,2.52,26.79]],"ltp":2.7,"tv":37.96,"id":31379}]}]}
{"op":"mcm","clk":"11788481989","pt":1723000290313,"mc":[{"id":"1.231431360","rc":[{"batb":[[1,2.52,26.79],[2,2.5,4]],"ltp":2.7,"tv":37.96,"id":31379}]}]}
{"op":"mcm","clk":"11788482034","pt":1723000291510,"mc":[{"id":"1.231431360","rc":[{"batb":[[0,2.52,26.79],[1,2.5,4],[2,2.44,26.26]],"ltp":2.7,"tv":37.96,"id":31379}]}]}
{"op":"mcm","clk":"11788482076","pt":1723000292589,"mc":[{"id":"1.231431360","rc":[{"batb":[[0,2.54,10],[1,2.52,26.79],[2,2.5,4]],"ltp":2.7,"tv":37.96,"id":31379}]}]}
{"op":"mcm","clk":"11788482124","pt":1723000293818,"mc":[{"id":"1.231431360","rc":[{"batb":[[0,2.56,2],[1,2.54,10],[2,2.52,26.79]],"ltp":2.7,"tv":37.96,"id":31379}]}]}
{"op":"mcm","clk":"11788482206","pt":1723000296029,"mc":[{"id":"1.231431360","rc":[{"batb":[[0,2.52,26.79],[1,2.5,4],[2,2.44,26.26]],"ltp":2.7,"tv":37.96,"id":31379}]}]}
{"op":"mcm","clk":"11788482309","pt":1723000299112,"mc":[{"id":"1.231431360","rc":[{"batb":[[0,2.54,12],[1,2.52,26.79],[2,2.5,4]],"ltp":2.7,"tv":37.96,"id":31379}]}]}
{"op":"mcm","clk":"11788482390","pt":1723000301316,"mc":[{"id":"1.231431360","rc":[{"batb":[[0,2.54,10]],"ltp":2.7,"tv":37.96,"id":31379}]}]}
{"op":"mcm","clk":"11788482423","pt":1723000302403,"mc":[{"id":"1.231431360","rc":[{"batb":[[0,2.52,26.79],[1,2.5,4],[2,2.44,26.26]],"ltp":2.7,"tv":37.96,"id":31379}]}]}
{"op":"mcm","clk":"11788482476","pt":1723000303586,"mc":[{"id":"1.231431360","rc":[{"batb":[[0,2.54,2],[1,2.52,26.79],[2,2.5,4]],"ltp":2.7,"tv":37.96,"id":31379}]}]}
{"op":"mcm","clk":"11788482555","pt":1723000306091,"mc":[{"id":"1.231431360","rc":[{"batb":[[0,2.54,10]],"ltp":2.7,"tv":37.96,"id":31379}]}]}
{"op":"mcm","clk":"11788482658","pt":1723000309427,"mc":[{"id":"1.231431360","rc":[{"batb":[[0,2.56,2]],"ltp":2.7,"tv":37.96,"id":31379}]}]}
{"op":"mcm","clk":"11788482729","pt":1723000311607,"mc":[{"id":"1.231431360","rc":[{"batb":[[0,2.54,10]],"ltp":2.7,"tv":37.96,"id":31379}]}]}
{"op":"mcm","clk":"11788482809","pt":1723000313720,"mc":[{"id":"1.231431360","rc":[{"batb":[[0,2.56,2],[1,2.54,10],[2,2.52,26.79]],"ltp":2.7,"tv":37.96,"id":31379}]}]}
{"op":"mcm","clk":"11788482860","pt":1723000315106,"mc":[{"id":"1.231431360","rc":[{"batb":[[1,2.52,26.79],[2,2.5,4]],"ltp":2.7,"tv":37.96,"id":31379}]}]}
{"op":"mcm","clk":"11788482903","pt":1723000316138,"mc":[{"id":"1.231431360","rc":[{"batb":[[0,2.52,26.79],[1,2.5,4],[2,2.44,26.26]],"ltp":2.7,"tv":37.96,"id":31379}]}]}
{"op":"mcm","clk":"11788482979","pt":1723000318341,"mc":[{"id":"1.231431360","rc":[{"batb":[[0,2.54,12],[1,2.52,26.79],[2,2.5,4]],"ltp":2.7,"tv":37.96,"id":31379}]}]}
{"op":"mcm","clk":"11788483040","pt":1723000320535,"mc":[{"id":"1.231431360","rc":[{"batb":[[0,2.54,10]],"ltp":2.7,"tv":37.96,"id":31379}]}]}
{"op":"mcm","clk":"11788483098","pt":1723000321711,"mc":[{"id":"1.231431360","rc":[{"batb":[[0,2.52,26.79],[1,2.5,4],[2,2.44,26.26]],"ltp":2.7,"tv":37.96,"id":31379}]}]}
{"op":"mcm","clk":"11788483136","pt":1723000322843,"mc":[{"id":"1.231431360","rc":[{"batb":[[0,2.54,2],[1,2.52,26.79],[2,2.5,4]],"ltp":2.7,"tv":37.96,"id":31379}]}]}
{"op":"mcm","clk":"11788483235","pt":1723000325215,"mc":[{"id":"1.231431360","rc":[{"batb":[[0,2.54,10]],"ltp":2.7,"tv":37.96,"id":31379}]}]}
{"op":"mcm","clk":"11788483303","pt":1723000327527,"mc":[{"id":"1.231431360","rc":[{"batb":[[0,2.56,2],[1,2.54,10]],"ltp":2.7,"tv":37.96,"id":31379},{"batb":[[1,1.57,42.76],[2,1.56,9.78]],"ltp":1.58,"tv":2998.73,"id":2219}]}]}
{"op":"mcm","clk":"11788483339","pt":1723000328554,"mc":[{"id":"1.231431360","rc":[{"batb":[[1,2.5,4],[2,2.44,26.26]],"ltp":2.7,"tv":37.96,"id":31379}]}]}
{"op":"mcm","clk":"11788483378","pt":1723000329532,"mc":[{"id":"1.231431360","rc":[{"batb":[[1,2.5,14.34]],"ltp":2.7,"tv":37.96,"id":31379},{"batb":[[0,1.58,15.31]],"batl":[[0,1.67,304],[1,1.68,400],[2,1.69,500]],"ltp":1.58,"tv":2998.73,"id":2219}]}]}
{"op":"mcm","clk":"11788483392","pt":1723000329943,"mc":[{"id":"1.231431360","rc":[{"batb":[[0,2.5,14.34],[1,2.44,26.26],[2,2.38,6.78]],"ltp":2.7,"tv":37.96,"id":31379}]}]}
{"op":"mcm","clk":"11788483437","pt":1723000331023,"mc":[{"id":"1.231431360","rc":[{"batb":[[0,2.5,25.95]],"ltp":2.7,"tv":37.96,"id":31379},{"batl":[[0,1.66,17.18],[1,1.67,304],[2,1.68,400]],"ltp":1.58,"tv":2998.73,"id":2219}]}]}
{"op":"mcm","clk":"11788485269","pt":1723000384297,"mc":[{"id":"1.231431360","rc":[{"batb":[[0,2.52,26.79],[1,2.5,25.95],[2,2.44,26.26]],"ltp":2.7,"tv":37.96,"id":31379},{"batb":[[1,1.56,9.78],[2,1.54,180]],"ltp":1.58,"tv":2998.73,"id":2219}]}]}
{"op":"mcm","clk":"11788485332","pt":1723000386304,"mc":[{"id":"1.231431360","rc":[{"batb":[[1,2.5,15.61]],"ltp":2.7,"tv":37.96,"id":31379},{"batb":[[0,1.58,3.31],[2,1.55,12.23]],"ltp":1.58,"tv":2998.73,"id":2219}]}]}
{"op":"mcm","clk":"11788485408","pt":1723000388306,"mc":[{"id":"1.231431360","rc":[{"batb":[[0,2.54,12],[1,2.52,26.79],[2,2.5,15.61]],"batl":[[0,2.84,12.04]],"ltp":2.7,"tv":37.96,"id":31379}]}]}
{"op":"mcm","clk":"11788485473","pt":1723000390519,"mc":[{"id":"1.231431360","rc":[{"batb":[[0,2.54,10],[2,2.5,4]],"ltp":2.7,"tv":37.96,"id":31379}]}]}
{"op":"mcm","clk":"11788485517","pt":1723000391602,"mc":[{"id":"1.231431360","rc":[{"batb":[[0,2.52,26.79],[1,2.5,4],[2,2.44,26.26]],"batl":[[0,2.84,7.28]],"ltp":2.7,"tv":37.96,"id":31379}]}]}
{"op":"mcm","clk":"11788485554","pt":1723000392689,"mc":[{"id":"1.231431360","rc":[{"batb":[[0,2.54,2],[1,2.52,26.79],[2,2.5,4]],"ltp":2.7,"tv":37.96,"id":31379}]}]}
{"op":"mcm","clk":"11788485639","pt":1723000395091,"mc":[{"id":"1.231431360","rc":[{"batb":[[0,2.54,10]],"ltp":2.7,"tv":37.96,"id":31379}]}]}
{"op":"mcm","clk":"11788485752","pt":1723000398577,"mc":[{"id":"1.231431360","rc":[{"batb":[[0,2.54,2]],"ltp":2.7,"tv":37.96,"id":31379}]}]}
{"op":"mcm","clk":"11788485811","pt":1723000400990,"mc":[{"id":"1.231431360","rc":[{"batb":[[0,2.54,10]],"ltp":2.7,"tv":37.96,"id":31379}]}]}
{"op":"mcm","clk":"11788485886","pt":1723000403102,"mc":[{"id":"1.231431360","rc":[{"batb":[[0,2.56,2],[1,2.54,10],[2,2.52,26.79]],"ltp":2.7,"tv":37.96,"id":31379}]}]}
{"op":"mcm","clk":"11788485916","pt":1723000404330,"mc":[{"id":"1.231431360","rc":[{"batb":[[1,2.52,26.79],[2,2.5,4]],"ltp":2.7,"tv":37.96,"id":31379}]}]}
{"op":"mcm","clk":"11788485957","pt":1723000405511,"mc":[{"id":"1.231431360","rc":[{"batb":[[0,2.52,26.79],[1,2.5,4],[2,2.44,26.26]],"ltp":2.7,"tv":37.96,"id":31379}]}]}
{"op":"mcm","clk":"11788485998","pt":1723000406642,"mc":[{"id":"1.231431360","rc":[{"batb":[[0,2.54,10],[1,2.52,26.79],[2,2.5,4]],"ltp":2.7,"tv":37.96,"id":31379}]}]}
{"op":"mcm","clk":"11788486033","pt":1723000407727,"mc":[{"id":"1.231431360","rc":[{"batb":[[0,2.56,2],[1,2.54,10],[2,2.52,26.79]],"ltp":2.7,"tv":37.96,"id":31379}]}]}
{"op":"mcm","clk":"11788486113","pt":1723000409990,"mc":[{"id":"1.231431360","rc":[{"batb":[[0,2.52,26.79],[1,2.5,4],[2,2.44,26.26]],"ltp":2.7,"tv":37.96,"id":31379}]}]}
{"op":"mcm","clk":"11788486199","pt":1723000412305,"mc":[{"id":"1.231431360","rc":[{"batb":[[0,2.54,12],[1,2.52,26.79],[2,2.5,4]],"ltp":2.7,"tv":37.96,"id":31379}]}]}
{"op":"mcm","clk":"11788486283","pt":1723000414412,"mc":[{"id":"1.231431360","rc":[{"batb":[[0,2.54,10]],"ltp":2.7,"tv":37.96,"id":31379}]}]}
{"op":"mcm","clk":"11788486344","pt":1723000415808,"mc":[{"id":"1.231431360","rc":[{"batb":[[0,2.52,26.79],[1,2.5,4],[2,2.44,26.26]],"ltp":2.7,"tv":37.96,"id":31379}]}]}
{"op":"mcm","clk":"11788486404","pt":1723000416901,"mc":[{"id":"1.231431360","rc":[{"batb":[[0,2.54,2],[1,2.52,26.79],[2,2.5,4]],"ltp":2.7,"tv":37.96,"id":31379}]}]}
{"op":"mcm","clk":"11788486510","pt":1723000419341,"mc":[{"id":"1.231431360","rc":[{"batb":[[0,2.54,10]],"ltp":2.7,"tv":37.96,"id":31379}]}]}
{"op":"mcm","clk":"11788486607","pt":1723000421412,"mc":[{"id":"1.231431360","rc":[{"batb":[[0,2.56,2],[1,2.54,10],[2,2.52,26.79]],"ltp":2.7,"tv":37.96,"id":31379}]}]}
{"op":"mcm","clk":"11788486663","pt":1723000422647,"mc":[{"id":"1.231431360","rc":[{"batb":[[1,2.52,26.79],[2,2.5,4]],"ltp":2.7,"tv":37.96,"id":31379}]}]}
{"op":"mcm","clk":"11788486721","pt":1723000423827,"mc":[{"id":"1.231431360","rc":[{"batb":[[0,2.52,26.79],[1,2.5,4],[2,2.44,26.26]],"ltp":2.7,"tv":37.96,"id":31379}]}]}
{"op":"mcm","clk":"11788486790","pt":1723000424912,"mc":[{"id":"1.231431360","rc":[{"batb":[[0,2.54,10],[1,2.52,26.79],[2,2.5,4]],"ltp":2.7,"tv":37.96,"id":31379}]}]}
{"op":"mcm","clk":"11788486894","pt":1723000427019,"mc":[{"id":"1.231431360","rc":[{"batb":[[0,2.56,2],[1,2.54,10],[2,2.52,26.79]],"ltp":2.7,"tv":37.96,"id":31379}]}]}
{"op":"mcm","clk":"11788486956","pt":1723000428216,"mc":[{"id":"1.231431360","rc":[{"batb":[[1,2.52,26.79],[2,2.5,4]],"ltp":2.7,"tv":37.96,"id":31379}]}]}
{"op":"mcm","clk":"11788486998","pt":1723000429430,"mc":[{"id":"1.231431360","rc":[{"batb":[[0,2.52,26.79],[1,2.5,4],[2,2.44,26.26]],"ltp":2.7,"tv":37.96,"id":31379}]}]}
{"op":"mcm","clk":"11788487038","pt":1723000430531,"mc":[{"id":"1.231431360","rc":[{"batb":[[0,2.54,10],[1,2.52,26.79],[2,2.5,4]],"ltp":2.7,"tv":37.96,"id":31379}]}]}
{"op":"mcm","clk":"11788487115","pt":1723000432618,"mc":[{"id":"1.231431360","rc":[{"batb":[[0,2.56,2],[1,2.54,10],[2,2.52,26.79]],"ltp":2.7,"tv":37.96,"id":31379}]}]}
{"op":"mcm","clk":"11788487165","pt":1723000433749,"mc":[{"id":"1.231431360","rc":[{"batb":[[1,2.52,26.79],[2,2.5,4]],"ltp":2.7,"tv":37.96,"id":31379}]}]}
{"op":"mcm","clk":"11788487220","pt":1723000434934,"mc":[{"id":"1.231431360","rc":[{"batb":[[0,2.52,26.79],[1,2.5,4],[2,2.44,26.26]],"ltp":2.7,"tv":37.96,"id":31379}]}]}
{"op":"mcm","clk":"11788487272","pt":1723000436011,"mc":[{"id":"1.231431360","rc":[{"batb":[[0,2.54,10],[1,2.52,26.79],[2,2.5,4]],"ltp":2.7,"tv":37.96,"id":31379}]}]}
{"op":"mcm","clk":"11788487368","pt":1723000438108,"mc":[{"id":"1.231431360","rc":[{"batb":[[0,2.56,2],[1,2.54,10],[2,2.52,26.79]],"ltp":2.7,"tv":37.96,"id":31379}]}]}
{"op":"mcm","clk":"11788487435","pt":1723000439338,"mc":[{"id":"1.231431360","rc":[{"batb":[[1,2.52,26.79],[2,2.5,4]],"ltp":2.7,"tv":37.96,"id":31379}]}]}
{"op":"mcm","clk":"11788487480","pt":1723000440517,"mc":[{"id":"1.231431360","rc":[{"batb":[[0,2.52,26.79],[1,2.5,4],[2,2.44,26.26]],"ltp":2.7,"tv":37.96,"id":31379}]}]}
{"op":"mcm","clk":"11788487520","pt":1723000441649,"mc":[{"id":"1.231431360","rc":[{"batb":[[0,2.54,10],[1,2.52,26.79],[2,2.5,4]],"ltp":2.7,"tv":37.96,"id":31379}]}]}
{"op":"mcm","clk":"11788487668","pt":1723000444841,"mc":[{"id":"1.231431360","rc":[{"batb":[[0,2.56,2]],"ltp":2.7,"tv":37.96,"id":31379}]}]}
{"op":"mcm","clk":"11788487740","pt":1723000446138,"mc":[{"id":"1.231431360","rc":[{"batb":[[1,2.5,4],[2,2.44,26.26]],"ltp":2.7,"tv":37.96,"id":31379},{"batb":[[1,1.57,42.76],[2,1.56,9.78]],"ltp":1.58,"tv":2998.73,"id":2219}]}]}
{"op":"mcm","clk":"11788487788","pt":1723000447313,"mc":[{"id":"1.231431360","rc":[{"batb":[[0,2.52,10]],"ltp":2.7,"tv":37.96,"id":31379},{"batb":[[0,1.58,15.31]],"ltp":1.58,"tv":2998.73,"id":2219}]}]}
{"op":"mcm","clk":"11788487941","pt":1723000450653,"mc":[{"id":"1.231431360","rc":[{"batb":[[0,2.5,4],[1,2.44,26.26],[2,2.38,6.78]],"ltp":2.7,"tv":37.96,"id":31379}]}]}
{"op":"mcm","clk":"11788487982","pt":1723000451422,"mc":[{"id":"1.231431360","rc":[{"batb":[[0,2.5,15.61]],"ltp":2.7,"tv":37.96,"id":31379}]}]}
{"op":"mcm","clk":"11788488647","pt":1723000467052,"mc":[{"id":"1.231431360","rc":[{"batb":[[0,1.59,9.02],[1,1.58,15.31],[2,1.57,42.76]],"ltp":1.58,"tv":2998.73,"id":2219}]}]}
{"op":"mcm","clk":"11788488986","pt":1723000475578,"mc":[{"id":"1.231431360","rc":[{"batb":[[2,2.14,38.68]],"ltp":2.7,"tv":37.96,"id":31379}]}]}
{"op":"mcm","clk":"11788490170","pt":1723000502107,"mc":[{"id":"1.231431360","rc":[{"batb":[[0,2.52,26.79],[1,2.5,15.61],[2,2.44,26.26]],"ltp":2.7,"tv":37.96,"id":31379},{"batb":[[0,1.59,51.26],[2,1.56,9.78]],"ltp":1.58,"tv":2998.73,"id":2219}]}]}
{"op":"mcm","clk":"11788490225","pt":1723000503087,"mc":[{"id":"1.231431360","rc":[{"batb":[[0,1.6,11.85],[1,1.59,51.26],[2,1.58,3.31]],"ltp":1.58,"tv":2998.73,"id":2219}]}]}
{"op":"mcm","clk":"11788490426","pt":1723000507406,"mc":[{"id":"1.231431360","rc":[{"batl":[[0,1.66,21.18]],"ltp":1.58,"tv":2998.73,"id":2219}]}]}
{"op":"mcm","clk":"11788492088","pt":1723000544953,"mc":[{"id":"1.231431360","rc":[{"trd":[[2.52,10.21]],"batb":[[0,2.52,25.21]],"ltp":2.52,"tv":41.12,"id":31379}],"tv":3039.85}]}
{"op":"mcm","clk":"11788492443","pt":1723000553053,"mc":[{"id":"1.231431360","rc":[{"batb":[[1,1.59,42.24]],"ltp":1.58,"tv":2998.73,"id":2219}]}]}
{"op":"mcm","clk":"11788492697","pt":1723000558586,"mc":[{"id":"1.231431360","rc":[{"batb":[[0,1.58,3.31],[1,1.56,9.78],[2,1.55,12.23]],"ltp":1.58,"tv":2998.73,"id":2219}]}]}
{"op":"mcm","clk":"11788492730","pt":1723000559360,"mc":[{"id":"1.231431360","rc":[{"batb":[[0,2.54,12],[1,2.52,25.21],[2,2.5,15.61]],"batl":[[0,2.84,7.28]],"ltp":2.52,"tv":41.12,"id":31379}]}]}
{"op":"mcm","clk":"11788492755","pt":1723000560075,"mc":[{"id":"1.231431360","rc":[{"batl":[[0,2.84,12.4]],"ltp":2.52,"tv":41.12,"id":31379}]}]}
{"op":"mcm","clk":"11788492827","pt":1723000561462,"mc":[{"id":"1.231431360","rc":[{"batb":[[2,2.5,4]],"ltp":2.52,"tv":41.12,"id":31379}]}]}
{"op":"mcm","clk":"11788492856","pt":1723000561980,"mc":[{"id":"1.231431360","rc":[{"batb":[[0,2.54,10]],"batl":[[0,2.84,7.28]],"ltp":2.52,"tv":41.12,"id":31379}]}]}
{"op":"mcm","clk":"11788492888","pt":1723000562698,"mc":[{"id":"1.231431360","rc":[{"batb":[[0,2.52,25.21],[1,2.5,4],[2,2.44,26.26]],"ltp":2.52,"tv":41.12,"id":31379}]}]}
{"op":"mcm","clk":"11788492971","pt":1723000564802,"mc":[{"id":"1.231431360","rc":[{"batb":[[0,2.54,12],[1,2.52,25.21],[2,2.5,4]],"ltp":2.52,"tv":41.12,"id":31379}]}]}
{"op":"mcm","clk":"11788493085","pt":1723000567065,"mc":[{"id":"1.231431360","rc":[{"batb":[[0,2.54,10]],"ltp":2.52,"tv":41.12,"id":31379}]}]}
{"op":"mcm","clk":"11788493148","pt":1723000568202,"mc":[{"id":"1.231431360","rc":[{"batb":[[0,2.52,25.21],[1,2.5,4],[2,2.44,26.26]],"ltp":2.52,"tv":41.12,"id":31379}]}]}
{"op":"mcm","clk":"11788493196","pt":1723000569283,"mc":[{"id":"1.231431360","rc":[{"batb":[[0,2.54,2],[1,2.52,25.21],[2,2.5,4]],"ltp":2.52,"tv":41.12,"id":31379}]}]}
{"op":"mcm","clk":"11788493306","pt":1723000571902,"mc":[{"id":"1.231431360","rc":[{"batb":[[0,2.54,10]],"ltp":2.52,"tv":41.12,"id":31379}]}]}
{"op":"mcm","clk":"11788493403","pt":1723000574206,"mc":[{"id":"1.231431360","rc":[{"batb":[[0,2.56,2],[1,2.54,10],[2,2.52,25.21]],"ltp":2.52,"tv":41.12,"id":31379}]}]}
{"op":"mcm","clk":"11788493440","pt":1723000575185,"mc":[{"id":"1.231431360","rc":[{"batb":[[1,2.52,25.21],[2,2.5,4]],"ltp":2.52,"tv":41.12,"id":31379}]}]}
{"op":"mcm","clk":"11788493506","pt":1723000576723,"mc":[{"id":"1.231431360","rc":[{"batb":[[0,2.52,25.21],[1,2.5,4],[2,2.44,26.26]],"ltp":2.52,"tv":41.12,"id":31379}]}]}
{"op":"mcm","clk":"11788493558","pt":1723000577904,"mc":[{"id":"1.231431360","rc":[{"batb":[[0,2.54,10],[1,2.52,25.21],[2,2.5,4]],"ltp":2.52,"tv":41.12,"id":31379}]}]}
{"op":"mcm","clk":"11788493596","pt":1723000578983,"mc":[{"id":"1.231431360","rc":[{"batb":[[0,2.56,2],[1,2.54,10],[2,2.52,25.21]],"ltp":2.52,"tv":41.12,"id":31379}]}]}
{"op":"mcm","clk":"11788493677","pt":1723000581288,"mc":[{"id":"1.231431360","rc":[{"batb":[[0,2.52,25.21],[1,2.5,4],[2,2.44,26.26]],"ltp":2.52,"tv":41.12,"id":31379}]}]}
{"op":"mcm","clk":"11788493761","pt":1723000583498,"mc":[{"id":"1.231431360","rc":[{"batb":[[0,2.54,12],[1,2.52,25.21],[2,2.5,4]],"ltp":2.52,"tv":41.12,"id":31379}]}]}
{"op":"mcm","clk":"11788493867","pt":1723000585804,"mc":[{"id":"1.231431360","rc":[{"batb":[[0,2.54,10]],"ltp":2.52,"tv":41.12,"id":31379}]}]}
{"op":"mcm","clk":"11788493896","pt":1723000586744,"mc":[{"id":"1.231431360","rc":[{"batb":[[0,2.52,25.21],[1,2.5,4],[2,2.44,26.26]],"ltp":2.52,"tv":41.12,"id":31379}]}]}
{"op":"mcm","clk":"11788494000","pt":1723000589090,"mc":[{"id":"1.231431360","rc":[{"batb":[[0,2.54,12],[1,2.52,25.21],[2,2.5,4]],"ltp":2.52,"tv":41.12,"id":31379}]}]}
{"op":"mcm","clk":"11788494087","pt":1723000591400,"mc":[{"id":"1.231431360","rc":[{"batb":[[0,2.54,10]],"ltp":2.52,"tv":41.12,"id":31379}]}]}
{"op":"mcm","clk":"11788494128","pt":1723000592426,"mc":[{"id":"1.231431360","rc":[{"batb":[[0,2.52,25.21],[1,2.5,4],[2,2.44,26.26]],"ltp":2.52,"tv":41.12,"id":31379}]}]}
{"op":"mcm","clk":"11788494175","pt":1723000593503,"mc":[{"id":"1.231431360","rc":[{"batb":[[0,2.54,2],[1,2.52,25.21],[2,2.5,4]],"ltp":2.52,"tv":41.12,"id":31379}]}]}
{"op":"mcm","clk":"11788494282","pt":1723000595916,"mc":[{"id":"1.231431360","rc":[{"batb":[[0,2.54,10]],"ltp":2.52,"tv":41.12,"id":31379}]}]}
{"op":"mcm","clk":"11788494418","pt":1723000599109,"mc":[{"id":"1.231431360","rc":[{"batb":[[0,2.56,2]],"ltp":2.52,"tv":41.12,"id":31379}]}]}
{"op":"mcm","clk":"11788494532","pt":1723000601635,"mc":[{"id":"1.231431360","rc":[{"batb":[[0,2.54,10]],"ltp":2.52,"tv":41.12,"id":31379}]}]}
{"op":"mcm","clk":"11788494622","pt":1723000603751,"mc":[{"id":"1.231431360","rc":[{"batb":[[0,2.56,2],[1,2.54,10],[2,2.52,25.21]],"ltp":2.52,"tv":41.12,"id":31379}]}]}
{"op":"mcm","clk":"11788494678","pt":1723000605033,"mc":[{"id":"1.231431360","rc":[{"batb":[[1,2.52,25.21],[2,2.5,4]],"ltp":2.52,"tv":41.12,"id":31379}]}]}
{"op":"mcm","clk":"11788494720","pt":1723000606057,"mc":[{"id":"1.231431360","rc":[{"batb":[[0,2.52,25.21],[1,2.5,4],[2,2.44,26.26]],"ltp":2.52,"tv":41.12,"id":31379}]}]}
{"op":"mcm","clk":"11788494796","pt":1723000607852,"mc":[{"id":"1.231431360","rc":[{"batb":[[0,2.54,10],[1,2.52,25.21],[2,2.5,4]],"ltp":2.52,"tv":41.12,"id":31379}]}]}
{"op":"mcm","clk":"11788494868","pt":1723000609955,"mc":[{"id":"1.231431360","rc":[{"batb":[[0,2.56,2],[1,2.54,10],[2,2.52,25.21]],"ltp":2.52,"tv":41.12,"id":31379}]}]}
{"op":"mcm","clk":"11788494925","pt":1723000611152,"mc":[{"id":"1.231431360","rc":[{"batb":[[1,2.52,25.21],[2,2.5,4]],"ltp":2.52,"tv":41.12,"id":31379}]}]}
{"op":"mcm","clk":"11788494985","pt":1723000612655,"mc":[{"id":"1.231431360","rc":[{"batb":[[0,2.52,25.21],[1,2.5,4],[2,2.44,26.26]],"ltp":2.52,"tv":41.12,"id":31379},{"batb":[[1,1.56,52.54]],"ltp":1.58,"tv":2998.73,"id":2219}]}]}
{"op":"mcm","clk":"11788495069","pt":1723000614220,"mc":[{"id":"1.231431360","rc":[{"batb":[[0,2.54,10],[1,2.52,25.21],[2,2.5,4]],"ltp":2.52,"tv":41.12,"id":31379},{"batb":[[1,1.57,12.07],[2,1.56,52.54]],"ltp":1.58,"tv":2998.73,"id":2219}]}]}
{"op":"mcm","clk":"11788495109","pt":1723000615346,"mc":[{"id":"1.231431360","rc":[{"batb":[[0,2.56,2],[1,2.54,10],[2,2.52,25.21]],"ltp":2.52,"tv":41.12,"id":31379}]}]}
{"op":"mcm","clk":"11788495213","pt":1723000617659,"mc":[{"id":"1.231431360","rc":[{"batb":[[0,2.52,25.21],[1,2.5,4],[2,2.44,26.26]],"ltp":2.52,"tv":41.12,"id":31379}]}]}
{"op":"mcm","clk":"11788497351","pt":1723000667608,"mc":[{"id":"1.231431360","rc":[{"batb":[[1,1.56,9.78],[2,1.55,12.23]],"ltp":1.58,"tv":2998.73,"id":2219}]}]}
{"op":"mcm","clk":"11788497411","pt":1723000669197,"mc":[{"id":"1.231431360","rc":[{"batb":[[0,2.54,12],[1,2.52,25.21],[2,2.5,4]],"batl":[[0,2.84,12.4]],"ltp":2.52,"tv":41.12,"id":31379}]}]}
{"op":"mcm","clk":"11788497478","pt":1723000671198,"mc":[{"id":"1.231431360","rc":[{"batb":[[0,2.54,10]],"batl":[[0,2.84,7.28]],"ltp":2.52,"tv":41.12,"id":31379}]}]}
{"op":"mcm","clk":"11788497527","pt":1723000672228,"mc":[{"id":"1.231431360","rc":[{"batb":[[0,2.52,25.21],[1,2.5,4],[2,2.44,26.26]],"ltp":2.52,"tv":41.12,"id":31379}]}]}
{"op":"mcm","clk":"11788497575","pt":1723000673504,"mc":[{"id":"1.231431360","rc":[{"batb":[[0,2.54,2],[1,2.52,25.21],[2,2.5,4]],"ltp":2.52,"tv":41.12,"id":31379}]}]}
{"op":"mcm","clk":"11788497664","pt":1723000675814,"mc":[{"id":"1.231431360","rc":[{"batb":[[0,2.54,10]],"ltp":2.52,"tv":41.12,"id":31379}]}]}
{"op":"mcm","clk":"11788497736","pt":1723000677927,"mc":[{"id":"1.231431360","rc":[{"batb":[[0,2.56,2],[1,2.54,10],[2,2.52,25.21]],"ltp":2.52,"tv":41.12,"id":31379}]}]}
{"op":"mcm","clk":"11788497794","pt":1723000679218,"mc":[{"id":"1.231431360","rc":[{"batb":[[1,2.52,25.21],[2,2.5,4]],"ltp":2.52,"tv":41.12,"id":31379}]}]}
{"op":"mcm","clk":"11788497827","pt":1723000680134,"mc":[{"id":"1.231431360","rc":[{"batb":[[0,2.52,25.21],[1,2.5,4],[2,2.44,26.26]],"ltp":2.52,"tv":41.12,"id":31379}]}]}
{"op":"mcm","clk":"11788497915","pt":1723000682398,"mc":[{"id":"1.231431360","rc":[{"batb":[[0,2.54,12],[1,2.52,25.21],[2,2.5,4]],"ltp":2.52,"tv":41.12,"id":31379}]}]}
{"op":"mcm","clk":"11788497996","pt":1723000684808,"mc":[{"id":"1.231431360","rc":[{"batb":[[0,2.54,10]],"ltp":2.52,"tv":41.12,"id":31379}]}]}
{"op":"mcm","clk":"11788498032","pt":1723000685836,"mc":[{"id":"1.231431360","rc":[{"batb":[[0,2.52,25.21],[1,2.5,4],[2,2.44,26.26]],"ltp":2.52,"tv":41.12,"id":31379}]}]}
{"op":"mcm","clk":"11788498069","pt":1723000686909,"mc":[{"id":"1.231431360","rc":[{"batb":[[0,2.54,2],[1,2.52,25.21],[2,2.5,4]],"ltp":2.52,"tv":41.12,"id":31379}]}]}
{"op":"mcm","clk":"11788498156","pt":1723000689223,"mc":[{"id":"1.231431360","rc":[{"batb":[[0,2.54,10]],"ltp":2.52,"tv":41.12,"id":31379}]}]}
{"op":"mcm","clk":"11788498226","pt":1723000691322,"mc":[{"id":"1.231431360","rc":[{"batb":[[0,2.56,2],[1,2.54,10],[2,2.52,25.21]],"ltp":2.52,"tv":41.12,"id":31379}]}]}
{"op":"mcm","clk":"11788498316","pt":1723000693639,"mc":[{"id":"1.231431360","rc":[{"batb":[[0,2.52,25.21],[1,2.5,4],[2,2.44,26.26]],"ltp":2.52,"tv":41.12,"id":31379}]}]}
{"op":"mcm","clk":"11788498386","pt":1723000695941,"mc":[{"id":"1.231431360","rc":[{"batb":[[0,2.54,12],[1,2.52,25.21],[2,2.5,4]],"ltp":2.52,"tv":41.12,"id":31379}]}]}
{"op":"mcm","clk":"11788498471","pt":1723000698146,"mc":[{"id":"1.231431360","rc":[{"batb":[[0,2.54,10]],"ltp":2.52,"tv":41.12,"id":31379}]}]}
{"op":"mcm","clk":"11788498537","pt":1723000699331,"mc":[{"id":"1.231431360","rc":[{"batb":[[0,2.52,25.21],[1,2.5,4],[2,2.44,26.26]],"ltp":2.52,"tv":41.12,"id":31379}]}]}
{"op":"mcm","clk":"11788498585","pt":1723000700457,"mc":[{"id":"1.231431360","rc":[{"batb":[[0,2.54,2],[1,2.52,25.21],[2,2.5,4]],"ltp":2.52,"tv":41.12,"id":31379}]}]}
{"op":"mcm","clk":"11788498695","pt":1723000702920,"mc":[{"id":"1.231431360","rc":[{"batb":[[0,2.54,10]],"ltp":2.52,"tv":41.12,"id":31379}]}]}
{"op":"mcm","clk":"11788498769","pt":1723000705023,"mc":[{"id":"1.231431360","rc":[{"batb":[[0,2.56,2],[1,2.54,10],[2,2.52,25.21]],"ltp":2.52,"tv":41.12,"id":31379}]}]}
{"op":"mcm","clk":"11788498813","pt":1723000706162,"mc":[{"id":"1.231431360","rc":[{"batb":[[1,2.52,25.21],[2,2.5,4]],"ltp":2.52,"tv":41.12,"id":31379}]}]}
{"op":"mcm","clk":"11788498858","pt":1723000707338,"mc":[{"id":"1.231431360","rc":[{"batb":[[0,2.52,25.21],[1,2.5,4],[2,2.44,26.26]],"ltp":2.52,"tv":41.12,"id":31379}]}]}
{"op":"mcm","clk":"11788498934","pt":1723000709238,"mc":[{"id":"1.231431360","rc":[{"batb":[[0,2.54,10],[1,2.52,25.21],[2,2.5,4]],"ltp":2.52,"tv":41.12,"id":31379}]}]}
{"op":"mcm","clk":"11788498971","pt":1723000710673,"mc":[{"id":"1.231431360","rc":[{"batb":[[0,2.56,2],[1,2.54,10],[2,2.52,25.21]],"ltp":2.52,"tv":41.12,"id":31379}]}]}
{"op":"mcm","clk":"11788499072","pt":1723000712875,"mc":[{"id":"1.231431360","rc":[{"batb":[[0,2.52,25.21],[1,2.5,4],[2,2.44,26.26]],"ltp":2.52,"tv":41.12,"id":31379}]}]}
{"op":"mcm","clk":"11788499141","pt":1723000715182,"mc":[{"id":"1.231431360","rc":[{"batb":[[0,2.54,12],[1,2.52,25.21],[2,2.5,4]],"ltp":2.52,"tv":41.12,"id":31379}]}]}
{"op":"mcm","clk":"11788499214","pt":1723000717643,"mc":[{"id":"1.231431360","rc":[{"batb":[[0,2.54,10]],"ltp":2.52,"tv":41.12,"id":31379}]}]}
{"op":"mcm","clk":"11788499241","pt":1723000718576,"mc":[{"id":"1.231431360","rc":[{"batb":[[0,2.52,25.21],[1,2.5,4],[2,2.44,26.26]],"ltp":2.52,"tv":41.12,"id":31379}]}]}
{"op":"mcm","clk":"11788499324","pt":1723000720877,"mc":[{"id":"1.231431360","rc":[{"batb":[[0,2.54,12],[1,2.52,25.21],[2,2.5,4]],"ltp":2.52,"tv":41.12,"id":31379}]}]}
{"op":"mcm","clk":"11788499375","pt":1723000722259,"mc":[{"id":"1.231431360","rc":[{"batb":[[0,2.54,36.73],[1,2.5,4],[2,2.44,26.26]],"ltp":2.52,"tv":41.12,"id":31379},{"batb":[[0,1.58,15.31],[1,1.57,42.76],[2,1.56,9.78]],"ltp":1.58,"tv":2998.73,"id":2219}]}]}
{"op":"mcm","clk":"11788499400","pt":1723000723078,"mc":[{"id":"1.231431360","rc":[{"batb":[[0,2.54,34.73]],"ltp":2.52,"tv":41.12,"id":31379},{"batl":[[0,1.66,4]],"ltp":1.58,"tv":2998.73,"id":2219}]}]}
{"op":"mcm","clk":"11788499428","pt":1723000724052,"mc":[{"id":"1.231431360","rc":[{"batb":[[0,2.54,24.73]],"ltp":2.52,"tv":41.12,"id":31379}]}]}
{"op":"mcm","clk":"11788501491","pt":1723000776634,"mc":[{"id":"1.231431360","rc":[{"batb":[[0,2.5,15.61],[1,2.44,26.26],[2,2.38,6.78]],"ltp":2.52,"tv":41.12,"id":31379},{"batb":[[1,1.56,9.78],[2,1.54,180]],"batl":[[0,1.66,21.18]],"ltp":1.58,"tv":2998.73,"id":2219}]}]}
{"op":"mcm","clk":"11788501570","pt":1723000778431,"mc":[{"id":"1.231431360","rc":[{"batb":[[0,2.52,12],[1,2.5,15.61],[2,2.44,26.26]],"batl":[[0,2.84,7.28]],"ltp":2.52,"tv":41.12,"id":31379},{"batb":[[0,1.58,3.31],[2,1.55,12.23]],"ltp":1.58,"tv":2998.73,"id":2219}]}]}
{"op":"mcm","clk":"11788501625","pt":1723000779655,"mc":[{"id":"1.231431360","rc":[{"batl":[[0,2.84,12.4]],"ltp":2.52,"tv":41.12,"id":31379}]}]}
{"op":"mcm","clk":"11788501661","pt":1723000780636,"mc":[{"id":"1.231431360","rc":[{"batb":[[0,2.52,10]],"ltp":2.52,"tv":41.12,"id":31379}]}]}
{"op":"mcm","clk":"11788501695","pt":1723000781552,"mc":[{"id":"1.231431360","rc":[{"batl":[[0,2.84,7.28]],"ltp":2.52,"tv":41.12,"id":31379}]}]}
{"op":"mcm","clk":"11788501709","pt":1723000781857,"mc":[{"id":"1.231431360","rc":[{"batb":[[0,2.5,15.61],[1,2.44,26.26],[2,2.38,6.78]],"ltp":2.52,"tv":41.12,"id":31379}]}]}
{"op":"mcm","clk":"11788501752","pt":1723000782935,"mc":[{"id":"1.231431360","rc":[{"batb":[[0,2.52,2],[1,2.5,15.61],[2,2.44,26.26]],"ltp":2.52,"tv":41.12,"id":31379}]}]}
{"op":"mcm","clk":"11788501855","pt":1723000785450,"mc":[{"id":"1.231431360","rc":[{"batb":[[0,2.52,10]],"ltp":2.52,"tv":41.12,"id":31379}]}]}
{"op":"mcm","clk":"11788501981","pt":1723000788781,"mc":[{"id":"1.231431360","rc":[{"batb":[[0,2.52,2]],"ltp":2.52,"tv":41.12,"id":31379}]}]}
{"op":"mcm","clk":"11788502074","pt":1723000791180,"mc":[{"id":"1.231431360","rc":[{"batb":[[0,2.52,10]],"ltp":2.52,"tv":41.12,"id":31379}]}]}
{"op":"mcm","clk":"11788502196","pt":1723000794667,"mc":[{"id":"1.231431360","rc":[{"batb":[[0,2.52,2]],"ltp":2.52,"tv":41.12,"id":31379}]}]}
{"op":"mcm","clk":"11788502311","pt":1723000797272,"mc":[{"id":"1.231431360","rc":[{"batb":[[0,2.52,10]],"ltp":2.52,"tv":41.12,"id":31379}]}]}
{"op":"mcm","clk":"11788502427","pt":1723000800571,"mc":[{"id":"1.231431360","rc":[{"batb":[[0,2.54,2]],"ltp":2.52,"tv":41.12,"id":31379}]}]}
{"op":"mcm","clk":"11788502502","pt":1723000802162,"mc":[{"id":"1.231431360","rc":[{"batb":[[0,2.5,15.61],[1,2.44,26.26],[2,2.38,6.78]],"ltp":2.52,"tv":41.12,"id":31379}]}]}
{"op":"mcm","clk":"11788502555","pt":1723000803285,"mc":[{"id":"1.231431360","rc":[{"batb":[[0,2.52,10],[1,2.5,15.61],[2,2.44,26.26]],"ltp":2.52,"tv":41.12,"id":31379}]}]}
{"op":"mcm","clk":"11788502613","pt":1723000804371,"mc":[{"id":"1.231431360","rc":[{"batb":[[0,2.54,2],[1,2.52,10],[2,2.5,15.61]],"ltp":2.52,"tv":41.12,"id":31379}]}]}
{"op":"mcm","clk":"11788502716","pt":1723000806576,"mc":[{"id":"1.231431360","rc":[{"batb":[[0,2.5,15.61],[1,2.44,26.26],[2,2.38,6.78]],"ltp":2.52,"tv":41.12,"id":31379}]}]}
{"op":"mcm","clk":"11788502830","pt":1723000808981,"mc":[{"id":"1.231431360","rc":[{"batb":[[0,2.52,12],[1,2.5,15.61],[2,2.44,26.26]],"ltp":2.52,"tv":41.12,"id":31379}]}]}
{"op":"mcm","clk":"11788502932","pt":1723000811298,"mc":[{"id":"1.231431360","rc":[{"batb":[[0,2.52,10]],"ltp":2.52,"tv":41.12,"id":31379}]}]}
{"op":"mcm","clk":"11788502980","pt":1723000812270,"mc":[{"id":"1.231431360","rc":[{"batb":[[0,2.5,15.61],[1,2.44,26.26],[2,2.38,6.78]],"ltp":2.52,"tv":41.12,"id":31379}]}]}
{"op":"mcm","clk":"11788503025","pt":1723000813502,"mc":[{"id":"1.231431360","rc":[{"batb":[[0,2.52,2],[1,2.5,15.61],[2,2.44,26.26]],"ltp":2.52,"tv":41.12,"id":31379}]}]}
{"op":"mcm","clk":"11788503111","pt":1723000815669,"mc":[{"id":"1.231431360","rc":[{"batb":[[0,2.5,15.61],[1,2.44,26.26],[2,2.38,6.78]],"ltp":2.52,"tv":41.12,"id":31379}]}]}
{"op":"mcm","clk":"11788503116","pt":1723000815770,"mc":[{"id":"1.231431360","rc":[{"batb":[[0,2.52,10],[1,2.5,15.61],[2,2.44,26.26]],"ltp":2.52,"tv":41.12,"id":31379}]}]}
