{"op":"mcm","clk":"11977650185","pt":1724784849373,"mc":[{"id":"1.232352479","marketDefinition":{"bspMarket":false,"turnInPlayEnabled":true,"persistenceEnabled":true,"marketBaseRate":5.0,"eventId":"33532598","eventTypeId":"4","numberOfWinners":1,"bettingType":"ODDS","marketType":"MATCH_ODDS","marketTime":"2024-08-28T09:30:00.000Z","suspendTime":"2024-08-28T09:30:00.000Z","bspReconciled":false,"complete":true,"inPlay":false,"crossMatching":false,"runnersVoidable":false,"numberOfActiveRunners":2,"betDelay":0,"status":"OPEN","runners":[{"status":"ACTIVE","sortPriority":1,"id":24640635,"name":"Spain"},{"status":"ACTIVE","sortPriority":2,"id":48610314,"name":"Finland"}],"regulators":["MR_INT"],"countryCode":"GB","discountAllowed":false,"timezone":"GMT","openDate":"2024-08-28T09:30:00.000Z","version":6103813222,"name":"Match Odds","eventName":"Spain v Finland"},"rc":[{"batb":[[0,1.03,200],[1,1.02,200],[2,1.01,220]],"ltp":0.0,"tv":0.0,"id":24640635},{"batb":[[0,1.03,200],[1,1.02,200],[2,1.01,220]],"ltp":0.0,"tv":0.0,"id":48610314}]}]}
{"op":"mcm","clk":"11977650995","pt":1724784854617,"mc":[{"id":"1.232352479","marketDefinition":{"bspMarket":false,"turnInPlayEnabled":true,"persistenceEnabled":true,"marketBaseRate":5.0,"eventId":"33532598","eventTypeId":"4","numberOfWinners":1,"bettingType":"ODDS","marketType":"MATCH_ODDS","marketTime":"2024-08-28T09:30:00.000Z","suspendTime":"2024-08-28T09:30:00.000Z","bspReconciled":false,"complete":true,"inPlay":false,"crossMatching":false,"runnersVoidable":false,"numberOfActiveRunners":2,"betDelay":0,"status":"OPEN","runners":[{"status":"ACTIVE","sortPriority":1,"id":24640635,"name":"Spain"},{"status":"ACTIVE","sortPriority":2,"id":48610314,"name":"Finland"}],"regulators":["MR_INT"],"countryCode":"GB","discountAllowed":true,"timezone":"GMT","openDate":"2024-08-28T09:30:00.000Z","version":6103813222,"name":"Match Odds","eventName":"Spain v Finland"}}]}
{"op":"mcm","clk":"11977818288","pt":1724786013352,"mc":[{"id":"1.232352479","rc":[{"batb":[[0,1.5,59.65],[1,1.03,200],[2,1.02,200]],"ltp":0.0,"tv":0.0,"id":24640635}]}]}
{"op":"mcm","clk":"11977820042","pt":1724786026591,"mc":[{"id":"1.232352479","rc":[{"batb":[[0,1.5,59.65],[1,1.03,200],[2,1.02,200]],"ltp":0.0,"tv":0.0,"id":48610314}]}]}
{"op":"mcm","clk":"11977822554","pt":1724786042730,"mc":[{"id":"1.232352479","rc":[{"trd":[[1.5,98.09]],"batb":[[0,1.5,10.6]],"ltp":1.5,"tv":98.09,"id":48610314}],"tv":98.09}]}
{"op":"mcm","clk":"11977823950","pt":1724786052692,"mc":[{"id":"1.232352479","rc":[{"trd":[[1.5,98.09]],"batb":[[0,1.5,10.6]],"ltp":1.5,"tv":98.09,"id":24640635}],"tv":196.18}]}
{"op":"mcm","clk":"11977825936","pt":1724786066671,"mc":[{"id":"1.232352479","rc":[{"batb":[[0,1.5,70.25]],"ltp":1.5,"tv":98.09,"id":48610314}]}]}
{"op":"mcm","clk":"11977827786","pt":1724786079916,"mc":[{"id":"1.232352479","rc":[{"batb":[[0,1.5,70.25]],"ltp":1.5,"tv":98.09,"id":24640635}]}]}
{"op":"mcm","clk":"11977829379","pt":1724786090732,"mc":[{"id":"1.232352479","rc":[{"trd":[[1.5,159.4]],"batb":[[0,1.5,39.6]],"ltp":1.5,"tv":159.4,"id":48610314}],"tv":257.49}]}
{"op":"mcm","clk":"11977830427","pt":1724786097753,"mc":[{"id":"1.232352479","rc":[{"trd":[[1.5,159.4]],"batb":[[0,1.5,39.6]],"ltp":1.5,"tv":159.4,"id":24640635}],"tv":318.8}]}
{"op":"mcm","clk":"11977831959","pt":1724786107750,"mc":[{"id":"1.232352479","rc":[{"trd":[[1.5,194.96]],"batb":[[0,1.5,21.82]],"ltp":1.5,"tv":194.96,"id":48610314}],"tv":354.36}]}
{"op":"mcm","clk":"11977833160","pt":1724786115759,"mc":[{"id":"1.232352479","rc":[{"trd":[[1.5,194.96]],"batb":[[0,1.5,21.82]],"ltp":1.5,"tv":194.96,"id":24640635}],"tv":389.92}]}
{"op":"mcm","clk":"11977834981","pt":1724786127737,"mc":[{"id":"1.232352479","rc":[{"trd":[[1.5,213.35]],"batb":[[0,1.5,12.62]],"ltp":1.5,"tv":213.35,"id":48610314}],"tv":408.31}]}
{"op":"mcm","clk":"11977836440","pt":1724786137788,"mc":[{"id":"1.232352479","rc":[{"trd":[[1.5,213.35]],"batb":[[0,1.5,12.62]],"ltp":1.5,"tv":213.35,"id":24640635}],"tv":426.7}]}
{"op":"mcm","clk":"11977838169","pt":1724786149672,"mc":[{"id":"1.232352479","rc":[{"trd":[[1.5,221.94]],"batb":[[0,1.5,8.33]],"ltp":1.5,"tv":221.93,"id":48610314}],"tv":435.28}]}
{"op":"mcm","clk":"11977839477","pt":1724786158716,"mc":[{"id":"1.232352479","rc":[{"trd":[[1.5,221.94]],"batb":[[0,1.5,8.33]],"ltp":1.5,"tv":221.93,"id":24640635}],"tv":443.87}]}
{"op":"mcm","clk":"11977840932","pt":1724786168669,"mc":[{"id":"1.232352479","rc":[{"trd":[[1.5,226.84]],"batb":[[0,1.5,5.88]],"ltp":1.5,"tv":226.84,"id":48610314}],"tv":448.77}]}
{"op":"mcm","clk":"11977842156","pt":1724786176694,"mc":[{"id":"1.232352479","rc":[{"trd":[[1.5,226.84]],"batb":[[0,1.5,5.88]],"ltp":1.5,"tv":226.84,"id":24640635}],"tv":453.68}]}
{"op":"mcm","clk":"11977845636","pt":1724786198248,"mc":[{"id":"1.232352479","rc":[{"batb":[[0,1.03,200],[1,1.02,200],[2,1.01,220]],"ltp":1.5,"tv":226.84,"id":48610314}]}]}
{"op":"mcm","clk":"11977845877","pt":1724786199941,"mc":[{"id":"1.232352479","rc":[{"batb":[[0,1.03,200],[1,1.02,200],[2,1.01,220]],"ltp":1.5,"tv":226.84,"id":24640635}]}]}
{"op":"mcm","clk":"11977895573","pt":1724786541130,"mc":[{"id":"1.232352479","rc":[{"batb":[[0,1.47,85.99],[1,1.03,200],[2,1.02,200]],"ltp":1.5,"tv":226.84,"id":24640635},{"batb":[[0,2.92,21.05],[1,1.03,200],[2,1.02,200]],"ltp":1.5,"tv":226.84,"id":48610314}]}]}
{"op":"mcm","clk":"11977898619","pt":1724786561594,"mc":[{"id":"1.232352479","marketDefinition":{"bspMarket":false,"turnInPlayEnabled":true,"persistenceEnabled":true,"marketBaseRate":5.0,"eventId":"33532598","eventTypeId":"4","numberOfWinners":1,"bettingType":"ODDS","marketType":"MATCH_ODDS","marketTime":"2024-08-28T09:30:00.000Z","suspendTime":"2024-08-28T09:30:00.000Z","bspReconciled":false,"complete":true,"inPlay":false,"crossMatching":true,"runnersVoidable":false,"numberOfActiveRunners":2,"betDelay":0,"status":"OPEN","runners":[{"status":"ACTIVE","sortPriority":1,"id":24640635,"name":"Spain"},{"status":"ACTIVE","sortPriority":2,"id":48610314,"name":"Finland"}],"regulators":["MR_INT"],"countryCode":"GB","discountAllowed":true,"timezone":"GMT","openDate":"2024-08-28T09:30:00.000Z","version":6103813222,"name":"Match Odds","eventName":"Spain v Finland"}}]}
{"op":"mcm","clk":"11977994063","pt":1724787189913,"mc":[{"id":"1.232352479","rc":[{"batb":[[0,1.48,5],[1,1.47,85.99],[2,1.03,200]],"batl":[[0,15,0.75]],"ltp":1.5,"tv":226.84,"id":24640635},{"batb":[[0,2.94,5],[1,2.92,21.05],[2,1.03,200]],"batl":[[0,15,0.75]],"ltp":1.5,"tv":226.84,"id":48610314}]}]}
{"op":"mcm","clk":"11977994654","pt":1724787193916,"mc":[{"id":"1.232352479","rc":[{"batb":[[0,1.47,85.99],[1,1.03,200],[2,1.02,200]],"ltp":1.5,"tv":226.84,"id":24640635},{"batb":[[0,2.92,21.05],[1,1.03,200],[2,1.02,200]],"ltp":1.5,"tv":226.84,"id":48610314}]}]}
{"op":"mcm","clk":"11977995094","pt":1724787197034,"mc":[{"id":"1.232352479","rc":[{"batb":[[0,1.48,5],[1,1.47,85.99],[2,1.03,200]],"ltp":1.5,"tv":226.84,"id":24640635},{"batb":[[0,2.94,5],[1,2.92,21.05],[2,1.03,200]],"ltp":1.5,"tv":226.84,"id":48610314}]}]}
{"op":"mcm","clk":"11977995565","pt":1724787200232,"mc":[{"id":"1.232352479","rc":[{"batb":[[0,1.47,85.99],[1,1.03,200],[2,1.02,200]],"ltp":1.5,"tv":226.84,"id":24640635},{"batb":[[0,2.92,21.05],[1,1.03,200],[2,1.02,200]],"ltp":1.5,"tv":226.84,"id":48610314}]}]}
{"op":"mcm","clk":"11977996034","pt":1724787203549,"mc":[{"id":"1.232352479","rc":[{"batb":[[0,1.48,5],[1,1.47,85.99],[2,1.03,200]],"ltp":1.5,"tv":226.84,"id":24640635},{"batb":[[0,2.94,5],[1,2.92,21.05],[2,1.03,200]],"ltp":1.5,"tv":226.84,"id":48610314}]}]}
{"op":"mcm","clk":"11977996563","pt":1724787206950,"mc":[{"id":"1.232352479","rc":[{"batb":[[0,1.47,85.99],[1,1.03,200],[2,1.02,200]],"ltp":1.5,"tv":226.84,"id":24640635},{"batb":[[0,2.92,21.05],[1,1.03,200],[2,1.02,200]],"ltp":1.5,"tv":226.84,"id":48610314}]}]}
{"op":"mcm","clk":"11977996940","pt":1724787209688,"mc":[{"id":"1.232352479","rc":[{"batb":[[0,1.48,5],[1,1.47,85.99],[2,1.03,200]],"ltp":1.5,"tv":226.84,"id":24640635},{"batb":[[0,2.94,5],[1,2.92,21.05],[2,1.03,200]],"ltp":1.5,"tv":226.84,"id":48610314}]}]}
{"op":"mcm","clk":"11977997411","pt":1724787213137,"mc":[{"id":"1.232352479","rc":[{"batb":[[0,1.47,85.99],[1,1.03,200],[2,1.02,200]],"ltp":1.5,"tv":226.84,"id":24640635},{"batb":[[0,2.92,21.05],[1,1.03,200],[2,1.02,200]],"ltp":1.5,"tv":226.84,"id":48610314}]}]}
{"op":"mcm","clk":"11977997751","pt":1724787215750,"mc":[{"id":"1.232352479","rc":[{"batb":[[0,1.48,5],[1,1.47,85.99],[2,1.03,200]],"ltp":1.5,"tv":226.84,"id":24640635},{"batb":[[0,2.94,5],[1,2.92,21.05],[2,1.03,200]],"ltp":1.5,"tv":226.84,"id":48610314}]}]}
{"op":"mcm","clk":"11977998197","pt":1724787219253,"mc":[{"id":"1.232352479","rc":[{"batb":[[0,1.47,85.99],[1,1.03,200],[2,1.02,200]],"ltp":1.5,"tv":226.84,"id":24640635},{"batb":[[0,2.92,21.05],[1,1.03,200],[2,1.02,200]],"ltp":1.5,"tv":226.84,"id":48610314}]}]}
{"op":"mcm","clk":"11977998596","pt":1724787222149,"mc":[{"id":"1.232352479","rc":[{"batb":[[0,1.48,5],[1,1.47,85.99],[2,1.03,200]],"ltp":1.5,"tv":226.84,"id":24640635},{"batb":[[0,2.94,5],[1,2.92,21.05],[2,1.03,200]],"ltp":1.5,"tv":226.84,"id":48610314}]}]}
{"op":"mcm","clk":"11977999087","pt":1724787225563,"mc":[{"id":"1.232352479","rc":[{"batb":[[0,1.47,85.99],[1,1.03,200],[2,1.02,200]],"ltp":1.5,"tv":226.84,"id":24640635},{"batb":[[0,2.92,21.05],[1,1.03,200],[2,1.02,200]],"ltp":1.5,"tv":226.84,"id":48610314}]}]}
{"op":"mcm","clk":"11977999432","pt":1724787227969,"mc":[{"id":"1.232352479","rc":[{"batb":[[0,1.48,5],[1,1.47,85.99],[2,1.03,200]],"ltp":1.5,"tv":226.84,"id":24640635},{"batb":[[0,2.94,5],[1,2.92,21.05],[2,1.03,200]],"ltp":1.5,"tv":226.84,"id":48610314}]}]}
{"op":"mcm","clk":"11977999897","pt":1724787231479,"mc":[{"id":"1.232352479","rc":[{"batb":[[0,1.47,85.99],[1,1.03,200],[2,1.02,200]],"ltp":1.5,"tv":226.84,"id":24640635},{"batb":[[0,2.92,21.05],[1,1.03,200],[2,1.02,200]],"ltp":1.5,"tv":226.84,"id":48610314}]}]}
{"op":"mcm","clk":"11978000198","pt":1724787233787,"mc":[{"id":"1.232352479","rc":[{"batb":[[0,1.48,5],[1,1.47,85.99],[2,1.03,200]],"ltp":1.5,"tv":226.84,"id":24640635},{"batb":[[0,2.94,5],[1,2.92,21.05],[2,1.03,200]],"ltp":1.5,"tv":226.84,"id":48610314}]}]}
{"op":"mcm","clk":"11978000764","pt":1724787237055,"mc":[{"id":"1.232352479","rc":[{"batb":[[0,1.47,85.99],[1,1.03,200],[2,1.02,200]],"ltp":1.5,"tv":226.84,"id":24640635},{"batb":[[0,2.92,21.05],[1,1.03,200],[2,1.02,200]],"ltp":1.5,"tv":226.84,"id":48610314}]}]}
{"op":"mcm","clk":"11978001107","pt":1724787239556,"mc":[{"id":"1.232352479","rc":[{"batb":[[0,1.48,5],[1,1.47,85.99],[2,1.03,200]],"ltp":1.5,"tv":226.84,"id":24640635},{"batb":[[0,2.94,5],[1,2.92,21.05],[2,1.03,200]],"ltp":1.5,"tv":226.84,"id":48610314}]}]}
{"op":"mcm","clk":"11978001487","pt":1724787242971,"mc":[{"id":"1.232352479","rc":[{"batb":[[0,1.47,85.99],[1,1.03,200],[2,1.02,200]],"ltp":1.5,"tv":226.84,"id":24640635},{"batb":[[0,2.92,21.05],[1,1.03,200],[2,1.02,200]],"ltp":1.5,"tv":226.84,"id":48610314}]}]}
{"op":"mcm","clk":"11978001774","pt":1724787245387,"mc":[{"id":"1.232352479","rc":[{"batb":[[0,1.48,5],[1,1.47,85.99],[2,1.03,200]],"ltp":1.5,"tv":226.84,"id":24640635},{"batb":[[0,2.94,5],[1,2.92,21.05],[2,1.03,200]],"ltp":1.5,"tv":226.84,"id":48610314}]}]}
{"op":"mcm","clk":"11978002142","pt":1724787248679,"mc":[{"id":"1.232352479","rc":[{"batb":[[0,1.47,85.99],[1,1.03,200],[2,1.02,200]],"ltp":1.5,"tv":226.84,"id":24640635},{"batb":[[0,2.92,21.05],[1,1.03,200],[2,1.02,200]],"ltp":1.5,"tv":226.84,"id":48610314}]}]}
{"op":"mcm","clk":"11978002517","pt":1724787251367,"mc":[{"id":"1.232352479","rc":[{"batb":[[0,1.48,5],[1,1.47,85.99],[2,1.03,200]],"ltp":1.5,"tv":226.84,"id":24640635},{"batb":[[0,2.94,5],[1,2.92,21.05],[2,1.03,200]],"ltp":1.5,"tv":226.84,"id":48610314}]}]}
{"op":"mcm","clk":"11978002927","pt":1724787254985,"mc":[{"id":"1.232352479","rc":[{"batb":[[0,1.47,85.99],[1,1.03,200],[2,1.02,200]],"ltp":1.5,"tv":226.84,"id":24640635},{"batb":[[0,2.92,21.05],[1,1.03,200],[2,1.02,200]],"ltp":1.5,"tv":226.84,"id":48610314}]}]}
{"op":"mcm","clk":"11978003186","pt":1724787257386,"mc":[{"id":"1.232352479","rc":[{"batb":[[0,1.48,5],[1,1.47,85.99],[2,1.03,200]],"ltp":1.5,"tv":226.84,"id":24640635},{"batb":[[0,2.94,5],[1,2.92,21.05],[2,1.03,200]],"ltp":1.5,"tv":226.84,"id":48610314}]}]}
{"op":"mcm","clk":"11978003588","pt":1724787260970,"mc":[{"id":"1.232352479","rc":[{"batb":[[0,1.47,85.99],[1,1.03,200],[2,1.02,200]],"ltp":1.5,"tv":226.84,"id":24640635},{"batb":[[0,2.92,21.05],[1,1.03,200],[2,1.02,200]],"ltp":1.5,"tv":226.84,"id":48610314}]}]}
{"op":"mcm","clk":"11978003843","pt":1724787263343,"mc":[{"id":"1.232352479","rc":[{"batb":[[0,1.48,5],[1,1.47,85.99],[2,1.03,200]],"ltp":1.5,"tv":226.84,"id":24640635},{"batb":[[0,2.94,5],[1,2.92,21.05],[2,1.03,200]],"ltp":1.5,"tv":226.84,"id":48610314}]}]}
{"op":"mcm","clk":"11978004269","pt":1724787266739,"mc":[{"id":"1.232352479","rc":[{"batb":[[0,1.47,85.99],[1,1.03,200],[2,1.02,200]],"ltp":1.5,"tv":226.84,"id":24640635},{"batb":[[0,2.92,21.05],[1,1.03,200],[2,1.02,200]],"ltp":1.5,"tv":226.84,"id":48610314}]}]}
{"op":"mcm","clk":"11978004633","pt":1724787269325,"mc":[{"id":"1.232352479","rc":[{"batb":[[0,1.48,5],[1,1.47,85.99],[2,1.03,200]],"ltp":1.5,"tv":226.84,"id":24640635},{"batb":[[0,2.94,5],[1,2.92,21.05],[2,1.03,200]],"ltp":1.5,"tv":226.84,"id":48610314}]}]}
{"op":"mcm","clk":"11978004963","pt":1724787272643,"mc":[{"id":"1.232352479","rc":[{"batb":[[0,1.47,85.99],[1,1.03,200],[2,1.02,200]],"ltp":1.5,"tv":226.84,"id":24640635},{"batb":[[0,2.92,21.05],[1,1.03,200],[2,1.02,200]],"ltp":1.5,"tv":226.84,"id":48610314}]}]}
{"op":"mcm","clk":"11978005268","pt":1724787275318,"mc":[{"id":"1.232352479","rc":[{"batb":[[0,1.48,5],[1,1.47,85.99],[2,1.03,200]],"ltp":1.5,"tv":226.84,"id":24640635},{"batb":[[0,2.94,5],[1,2.92,21.05],[2,1.03,200]],"ltp":1.5,"tv":226.84,"id":48610314}]}]}
{"op":"mcm","clk":"11978005653","pt":1724787278823,"mc":[{"id":"1.232352479","rc":[{"batb":[[0,1.47,85.99],[1,1.03,200],[2,1.02,200]],"ltp":1.5,"tv":226.84,"id":24640635},{"batb":[[0,2.92,21.05],[1,1.03,200],[2,1.02,200]],"ltp":1.5,"tv":226.84,"id":48610314}]}]}
{"op":"mcm","clk":"11978005876","pt":1724787280922,"mc":[{"id":"1.232352479","rc":[{"batb":[[0,1.48,5],[1,1.47,85.99],[2,1.03,200]],"ltp":1.5,"tv":226.84,"id":24640635},{"batb":[[0,2.94,5],[1,2.92,21.05],[2,1.03,200]],"ltp":1.5,"tv":226.84,"id":48610314}]}]}
{"op":"mcm","clk":"11978006258","pt":1724787284326,"mc":[{"id":"1.232352479","rc":[{"batb":[[0,1.47,85.99],[1,1.03,200],[2,1.02,200]],"ltp":1.5,"tv":226.84,"id":24640635},{"batb":[[0,2.92,21.05],[1,1.03,200],[2,1.02,200]],"ltp":1.5,"tv":226.84,"id":48610314}]}]}
{"op":"mcm","clk":"11978006691","pt":1724787287744,"mc":[{"id":"1.232352479","rc":[{"batb":[[0,1.48,5],[1,1.47,85.99],[2,1.03,200]],"ltp":1.5,"tv":226.84,"id":24640635},{"batb":[[0,2.94,5],[1,2.92,21.05],[2,1.03,200]],"ltp":1.5,"tv":226.84,"id":48610314}]}]}
{"op":"mcm","clk":"11978007106","pt":1724787291022,"mc":[{"id":"1.232352479","rc":[{"batb":[[0,1.47,85.99],[1,1.03,200],[2,1.02,200]],"ltp":1.5,"tv":226.84,"id":24640635},{"batb":[[0,2.92,21.05],[1,1.03,200],[2,1.02,200]],"ltp":1.5,"tv":226.84,"id":48610314}]}]}
{"op":"mcm","clk":"11978007538","pt":1724787294460,"mc":[{"id":"1.232352479","rc":[{"batb":[[0,1.48,5],[1,1.47,85.99],[2,1.03,200]],"ltp":1.5,"tv":226.84,"id":24640635},{"batb":[[0,2.94,5],[1,2.92,21.05],[2,1.03,200]],"ltp":1.5,"tv":226.84,"id":48610314}]}]}
{"op":"mcm","clk":"11978008022","pt":1724787298588,"mc":[{"id":"1.232352479","rc":[{"batb":[[0,1.47,85.99],[1,1.43,93.99]],"ltp":1.5,"tv":226.84,"id":24640635},{"batb":[[0,3,20.2]],"ltp":1.5,"tv":226.84,"id":48610314}]}]}
{"op":"mcm","clk":"11978008034","pt":1724787298650,"mc":[{"id":"1.232352479","rc":[{"batb":[[0,1.43,93.99],[1,1.03,200],[2,1.02,200]],"ltp":1.5,"tv":226.84,"id":24640635},{"batb":[[1,1.03,200],[2,1.02,200]],"ltp":1.5,"tv":226.84,"id":48610314}]}]}
{"op":"mcm","clk":"11978008374","pt":1724787301169,"mc":[{"id":"1.232352479","rc":[{"batb":[[0,1.44,5],[1,1.43,93.99],[2,1.03,200]],"ltp":1.5,"tv":226.84,"id":24640635},{"batb":[[0,3.05,5],[1,3,20.2],[2,1.03,200]],"ltp":1.5,"tv":226.84,"id":48610314}]}]}
{"op":"mcm","clk":"11978008769","pt":1724787304482,"mc":[{"id":"1.232352479","rc":[{"batb":[[0,1.43,93.99],[1,1.03,200],[2,1.02,200]],"ltp":1.5,"tv":226.84,"id":24640635},{"batb":[[0,3,20.2],[1,1.03,200],[2,1.02,200]],"ltp":1.5,"tv":226.84,"id":48610314}]}]}
{"op":"mcm","clk":"11978009068","pt":1724787306891,"mc":[{"id":"1.232352479","rc":[{"batb":[[0,1.44,5],[1,1.43,93.99],[2,1.03,200]],"ltp":1.5,"tv":226.84,"id":24640635},{"batb":[[0,3.05,5],[1,3,20.2],[2,1.03,200]],"ltp":1.5,"tv":226.84,"id":48610314}]}]}
{"op":"mcm","clk":"11978009466","pt":1724787310294,"mc":[{"id":"1.232352479","rc":[{"batb":[[0,1.43,93.99],[1,1.03,200],[2,1.02,200]],"ltp":1.5,"tv":226.84,"id":24640635},{"batb":[[0,3,20.2],[1,1.03,200],[2,1.02,200]],"ltp":1.5,"tv":226.84,"id":48610314}]}]}
{"op":"mcm","clk":"11978009980","pt":1724787314376,"mc":[{"id":"1.232352479","rc":[{"batb":[[0,1.44,5],[1,1.43,93.99],[2,1.03,200]],"ltp":1.5,"tv":226.84,"id":24640635},{"batb":[[0,3.05,5],[1,3,20.2],[2,1.03,200]],"ltp":1.5,"tv":226.84,"id":48610314}]}]}
{"op":"mcm","clk":"11978010414","pt":1724787317886,"mc":[{"id":"1.232352479","rc":[{"batb":[[0,1.43,93.99],[1,1.03,200],[2,1.02,200]],"ltp":1.5,"tv":226.84,"id":24640635},{"batb":[[0,3,20.2],[1,1.03,200],[2,1.02,200]],"ltp":1.5,"tv":226.84,"id":48610314}]}]}
{"op":"mcm","clk":"11978010799","pt":1724787321306,"mc":[{"id":"1.232352479","rc":[{"batb":[[0,1.44,5],[1,1.43,93.99],[2,1.03,200]],"ltp":1.5,"tv":226.84,"id":24640635},{"batb":[[0,3.05,5],[1,3,20.2],[2,1.03,200]],"ltp":1.5,"tv":226.84,"id":48610314}]}]}
{"op":"mcm","clk":"11978011156","pt":1724787324590,"mc":[{"id":"1.232352479","rc":[{"batb":[[0,1.43,93.99],[1,1.03,200],[2,1.02,200]],"ltp":1.5,"tv":226.84,"id":24640635},{"batb":[[0,3,20.2],[1,1.03,200],[2,1.02,200]],"ltp":1.5,"tv":226.84,"id":48610314}]}]}
{"op":"mcm","clk":"11978011655","pt":1724787328809,"mc":[{"id":"1.232352479","rc":[{"batb":[[0,1.44,5],[1,1.43,93.99],[2,1.03,200]],"ltp":1.5,"tv":226.84,"id":24640635},{"batb":[[0,3.05,5],[1,3,20.2],[2,1.03,200]],"ltp":1.5,"tv":226.84,"id":48610314}]}]}
{"op":"mcm","clk":"11978012110","pt":1724787332198,"mc":[{"id":"1.232352479","rc":[{"batb":[[0,1.43,93.99],[1,1.03,200],[2,1.02,200]],"ltp":1.5,"tv":226.84,"id":24640635},{"batb":[[0,3,20.2],[1,1.03,200],[2,1.02,200]],"ltp":1.5,"tv":226.84,"id":48610314}]}]}
{"op":"mcm","clk":"11978012527","pt":1724787335478,"mc":[{"id":"1.232352479","rc":[{"batb":[[0,1.44,5],[1,1.43,93.99],[2,1.03,200]],"ltp":1.5,"tv":226.84,"id":24640635},{"batb":[[0,3.05,5],[1,3,20.2],[2,1.03,200]],"ltp":1.5,"tv":226.84,"id":48610314}]}]}
{"op":"mcm","clk":"11978012907","pt":1724787339001,"mc":[{"id":"1.232352479","rc":[{"batb":[[0,1.43,93.99],[1,1.03,200],[2,1.02,200]],"ltp":1.5,"tv":226.84,"id":24640635},{"batb":[[0,3,20.2],[1,1.03,200],[2,1.02,200]],"ltp":1.5,"tv":226.84,"id":48610314}]}]}
{"op":"mcm","clk":"11978013203","pt":1724787341624,"mc":[{"id":"1.232352479","rc":[{"batb":[[0,1.44,5],[1,1.43,93.99],[2,1.03,200]],"ltp":1.5,"tv":226.84,"id":24640635},{"batb":[[0,3.05,5],[1,3,20.2],[2,1.03,200]],"ltp":1.5,"tv":226.84,"id":48610314}]}]}
{"op":"mcm","clk":"11978013607","pt":1724787345095,"mc":[{"id":"1.232352479","rc":[{"batb":[[0,1.43,93.99],[1,1.03,200],[2,1.02,200]],"ltp":1.5,"tv":226.84,"id":24640635},{"batb":[[0,3,20.2],[1,1.03,200],[2,1.02,200]],"ltp":1.5,"tv":226.84,"id":48610314}]}]}
{"op":"mcm","clk":"11978014309","pt":1724787351010,"mc":[{"id":"1.232352479","rc":[{"batb":[[0,1.44,5],[1,1.43,93.99],[2,1.03,200]],"ltp":1.5,"tv":226.84,"id":24640635},{"batb":[[0,3.05,5],[1,3,20.2],[2,1.03,200]],"ltp":1.5,"tv":226.84,"id":48610314}]}]}
{"op":"mcm","clk":"11978014756","pt":1724787354529,"mc":[{"id":"1.232352479","rc":[{"batb":[[0,1.43,93.99],[1,1.03,200],[2,1.02,200]],"ltp":1.5,"tv":226.84,"id":24640635},{"batb":[[0,3,20.2],[1,1.03,200],[2,1.02,200]],"ltp":1.5,"tv":226.84,"id":48610314}]}]}
{"op":"mcm","clk":"11978015093","pt":1724787356936,"mc":[{"id":"1.232352479","rc":[{"batb":[[0,1.44,5],[1,1.43,93.99],[2,1.03,200]],"ltp":1.5,"tv":226.84,"id":24640635},{"batb":[[0,3.05,5],[1,3,20.2],[2,1.03,200]],"ltp":1.5,"tv":226.84,"id":48610314}]}]}
{"op":"mcm","clk":"11978015464","pt":1724787360240,"mc":[{"id":"1.232352479","rc":[{"batb":[[0,1.43,93.99],[1,1.03,200],[2,1.02,200]],"ltp":1.5,"tv":226.84,"id":24640635},{"batb":[[0,3,20.2],[1,1.03,200],[2,1.02,200]],"ltp":1.5,"tv":226.84,"id":48610314}]}]}
{"op":"mcm","clk":"11978015916","pt":1724787364310,"mc":[{"id":"1.232352479","rc":[{"batb":[[0,1.44,5],[1,1.43,93.99],[2,1.03,200]],"ltp":1.5,"tv":226.84,"id":24640635},{"batb":[[0,3.05,5],[1,3,20.2],[2,1.03,200]],"ltp":1.5,"tv":226.84,"id":48610314}]}]}
{"op":"mcm","clk":"11978016331","pt":1724787367635,"mc":[{"id":"1.232352479","rc":[{"batb":[[0,1.43,93.99],[1,1.03,200],[2,1.02,200]],"ltp":1.5,"tv":226.84,"id":24640635},{"batb":[[0,3,20.2],[1,1.03,200],[2,1.02,200]],"ltp":1.5,"tv":226.84,"id":48610314}]}]}
{"op":"mcm","clk":"11978016707","pt":1724787370812,"mc":[{"id":"1.232352479","rc":[{"batb":[[0,1.44,5],[1,1.43,93.99],[2,1.03,200]],"ltp":1.5,"tv":226.84,"id":24640635},{"batb":[[0,3.05,5],[1,3,20.2],[2,1.03,200]],"ltp":1.5,"tv":226.84,"id":48610314}]}]}
{"op":"mcm","clk":"11978017088","pt":1724787374145,"mc":[{"id":"1.232352479","rc":[{"batb":[[0,1.43,93.99],[1,1.03,200],[2,1.02,200]],"ltp":1.5,"tv":226.84,"id":24640635},{"batb":[[0,3,20.2],[1,1.03,200],[2,1.02,200]],"ltp":1.5,"tv":226.84,"id":48610314}]}]}
{"op":"mcm","clk":"11978017345","pt":1724787376347,"mc":[{"id":"1.232352479","rc":[{"batb":[[0,1.44,5],[1,1.43,93.99],[2,1.03,200]],"ltp":1.5,"tv":226.84,"id":24640635},{"batb":[[0,3.05,5],[1,3,20.2],[2,1.03,200]],"ltp":1.5,"tv":226.84,"id":48610314}]}]}
{"op":"mcm","clk":"11978017753","pt":1724787379762,"mc":[{"id":"1.232352479","rc":[{"batb":[[0,1.43,93.99],[1,1.03,200],[2,1.02,200]],"ltp":1.5,"tv":226.84,"id":24640635},{"batb":[[0,3,20.2],[1,1.03,200],[2,1.02,200]],"ltp":1.5,"tv":226.84,"id":48610314}]}]}
{"op":"mcm","clk":"11978018574","pt":1724787386214,"mc":[{"id":"1.232352479","rc":[{"batb":[[0,1.44,5],[1,1.43,93.99],[2,1.03,200]],"ltp":1.5,"tv":226.84,"id":24640635},{"batb":[[0,3.05,5],[1,3,20.2],[2,1.03,200]],"ltp":1.5,"tv":226.84,"id":48610314}]}]}
{"op":"mcm","clk":"11978019052","pt":1724787389749,"mc":[{"id":"1.232352479","rc":[{"batb":[[0,1.43,93.99],[1,1.03,200],[2,1.02,200]],"ltp":1.5,"tv":226.84,"id":24640635},{"batb":[[0,3,20.2],[1,1.03,200],[2,1.02,200]],"ltp":1.5,"tv":226.84,"id":48610314}]}]}
{"op":"mcm","clk":"11978019344","pt":1724787392148,"mc":[{"id":"1.232352479","rc":[{"batb":[[0,1.44,5],[1,1.43,93.99],[2,1.03,200]],"ltp":1.5,"tv":226.84,"id":24640635},{"batb":[[0,3.05,5],[1,3,20.2],[2,1.03,200]],"ltp":1.5,"tv":226.84,"id":48610314}]}]}
{"op":"mcm","clk":"11978019816","pt":1724787395468,"mc":[{"id":"1.232352479","rc":[{"batb":[[0,1.43,93.99],[1,1.03,200],[2,1.02,200]],"ltp":1.5,"tv":226.84,"id":24640635},{"batb":[[0,3,20.2],[1,1.03,200],[2,1.02,200]],"ltp":1.5,"tv":226.84,"id":48610314}]}]}
{"op":"mcm","clk":"11978020184","pt":1724787398198,"mc":[{"id":"1.232352479","rc":[{"batb":[[0,1.44,5],[1,1.43,93.99],[2,1.03,200]],"ltp":1.5,"tv":226.84,"id":24640635},{"batb":[[0,3.05,5],[1,3,20.2],[2,1.03,200]],"ltp":1.5,"tv":226.84,"id":48610314}]}]}
{"op":"mcm","clk":"11978020591","pt":1724787401555,"mc":[{"id":"1.232352479","rc":[{"batb":[[0,1.43,93.99],[1,1.03,200],[2,1.02,200]],"ltp":1.5,"tv":226.84,"id":24640635},{"batb":[[0,3,20.2],[1,1.03,200],[2,1.02,200]],"ltp":1.5,"tv":226.84,"id":48610314}]}]}
{"op":"mcm","clk":"11978020889","pt":1724787404073,"mc":[{"id":"1.232352479","rc":[{"batb":[[0,1.44,5],[1,1.43,93.99],[2,1.03,200]],"ltp":1.5,"tv":226.84,"id":24640635},{"batb":[[0,3.05,5],[1,3,20.2],[2,1.03,200]],"ltp":1.5,"tv":226.84,"id":48610314}]}]}
{"op":"mcm","clk":"11978021283","pt":1724787407422,"mc":[{"id":"1.232352479","rc":[{"batb":[[0,1.43,93.99],[1,1.03,200],[2,1.02,200]],"ltp":1.5,"tv":226.84,"id":24640635},{"batb":[[0,3,20.2],[1,1.03,200],[2,1.02,200]],"ltp":1.5,"tv":226.84,"id":48610314}]}]}
{"op":"mcm","clk":"11978021616","pt":1724787410117,"mc":[{"id":"1.232352479","rc":[{"batb":[[0,1.44,5],[1,1.43,93.99],[2,1.03,200]],"ltp":1.5,"tv":226.84,"id":24640635},{"batb":[[0,3.05,5],[1,3,20.2],[2,1.03,200]],"ltp":1.5,"tv":226.84,"id":48610314}]}]}
{"op":"mcm","clk":"11978022037","pt":1724787413421,"mc":[{"id":"1.232352479","rc":[{"batb":[[0,1.43,93.99],[1,1.03,200],[2,1.02,200]],"ltp":1.5,"tv":226.84,"id":24640635},{"batb":[[0,3,20.2],[1,1.03,200],[2,1.02,200]],"ltp":1.5,"tv":226.84,"id":48610314}]}]}
{"op":"mcm","clk":"11978022383","pt":1724787416100,"mc":[{"id":"1.232352479","rc":[{"batb":[[0,1.44,5],[1,1.43,93.99],[2,1.03,200]],"ltp":1.5,"tv":226.84,"id":24640635},{"batb":[[0,3.05,5],[1,3,20.2],[2,1.03,200]],"ltp":1.5,"tv":226.84,"id":48610314}]}]}
{"op":"mcm","clk":"11978022792","pt":1724787419619,"mc":[{"id":"1.232352479","rc":[{"batb":[[0,1.43,93.99],[1,1.03,200],[2,1.02,200]],"ltp":1.5,"tv":226.84,"id":24640635},{"batb":[[0,3,20.2],[1,1.03,200],[2,1.02,200]],"ltp":1.5,"tv":226.84,"id":48610314}]}]}
{"op":"mcm","clk":"11978023358","pt":1724787424153,"mc":[{"id":"1.232352479","rc":[{"batb":[[0,1.44,5],[1,1.43,93.99],[2,1.03,200]],"ltp":1.5,"tv":226.84,"id":24640635},{"batb":[[0,3.05,5],[1,3,20.2],[2,1.03,200]],"ltp":1.5,"tv":226.84,"id":48610314}]}]}
{"op":"mcm","clk":"11978023769","pt":1724787427614,"mc":[{"id":"1.232352479","rc":[{"batb":[[0,1.43,93.99],[1,1.03,200],[2,1.02,200]],"ltp":1.5,"tv":226.84,"id":24640635},{"batb":[[0,3,20.2],[1,1.03,200],[2,1.02,200]],"ltp":1.5,"tv":226.84,"id":48610314}]}]}
{"op":"mcm","clk":"11978024145","pt":1724787430574,"mc":[{"id":"1.232352479","rc":[{"batb":[[0,1.44,5],[1,1.43,93.99],[2,1.03,200]],"ltp":1.5,"tv":226.84,"id":24640635},{"batb":[[0,3.05,5],[1,3,20.2],[2,1.03,200]],"ltp":1.5,"tv":226.84,"id":48610314}]}]}
{"op":"mcm","clk":"11978024629","pt":1724787434035,"mc":[{"id":"1.232352479","rc":[{"batb":[[0,1.43,93.99],[1,1.03,200],[2,1.02,200]],"ltp":1.5,"tv":226.84,"id":24640635},{"batb":[[0,3,20.2],[1,1.03,200],[2,1.02,200]],"ltp":1.5,"tv":226.84,"id":48610314}]}]}
{"op":"mcm","clk":"11978025026","pt":1724787437313,"mc":[{"id":"1.232352479","rc":[{"batb":[[0,1.44,5],[1,1.43,93.99],[2,1.03,200]],"ltp":1.5,"tv":226.84,"id":24640635},{"batb":[[0,3.05,5],[1,3,20.2],[2,1.03,200]],"ltp":1.5,"tv":226.84,"id":48610314}]}]}
{"op":"mcm","clk":"11978025410","pt":1724787440825,"mc":[{"id":"1.232352479","rc":[{"batb":[[0,1.43,93.99],[1,1.03,200],[2,1.02,200]],"ltp":1.5,"tv":226.84,"id":24640635},{"batb":[[0,3,20.2],[1,1.03,200],[2,1.02,200]],"ltp":1.5,"tv":226.84,"id":48610314}]}]}
{"op":"mcm","clk":"11978025810","pt":1724787444002,"mc":[{"id":"1.232352479","rc":[{"batb":[[0,1.44,5],[1,1.43,93.99],[2,1.03,200]],"ltp":1.5,"tv":226.84,"id":24640635},{"batb":[[0,3.05,5],[1,3,20.2],[2,1.03,200]],"ltp":1.5,"tv":226.84,"id":48610314}]}]}
{"op":"mcm","clk":"11978026233","pt":1724787447412,"mc":[{"id":"1.232352479","rc":[{"batb":[[0,1.43,93.99],[1,1.03,200],[2,1.02,200]],"ltp":1.5,"tv":226.84,"id":24640635},{"batb":[[0,3,20.2],[1,1.03,200],[2,1.02,200]],"ltp":1.5,"tv":226.84,"id":48610314}]}]}
{"op":"mcm","clk":"11978026592","pt":1724787450205,"mc":[{"id":"1.232352479","rc":[{"batb":[[0,1.44,5],[1,1.43,93.99],[2,1.03,200]],"ltp":1.5,"tv":226.84,"id":24640635},{"batb":[[0,3.05,5],[1,3,20.2],[2,1.03,200]],"ltp":1.5,"tv":226.84,"id":48610314}]}]}
{"op":"mcm","clk":"11978027035","pt":1724787453820,"mc":[{"id":"1.232352479","rc":[{"batb":[[0,1.43,93.99],[1,1.03,200],[2,1.02,200]],"ltp":1.5,"tv":226.84,"id":24640635},{"batb":[[0,3,20.2],[1,1.03,200],[2,1.02,200]],"ltp":1.5,"tv":226.84,"id":48610314}]}]}
{"op":"mcm","clk":"11978027389","pt":1724787456811,"mc":[{"id":"1.232352479","rc":[{"batb":[[0,1.44,5],[1,1.43,93.99],[2,1.03,200]],"ltp":1.5,"tv":226.84,"id":24640635},{"batb":[[0,3.05,5],[1,3,20.2],[2,1.03,200]],"ltp":1.5,"tv":226.84,"id":48610314}]}]}
{"op":"mcm","clk":"11978027810","pt":1724787460127,"mc":[{"id":"1.232352479","rc":[{"batb":[[0,1.43,93.99],[1,1.03,200],[2,1.02,200]],"ltp":1.5,"tv":226.84,"id":24640635},{"batb":[[0,3,20.2],[1,1.03,200],[2,1.02,200]],"ltp":1.5,"tv":226.84,"id":48610314}]}]}
{"op":"mcm","clk":"11978028196","pt":1724787463120,"mc":[{"id":"1.232352479","rc":[{"batb":[[0,1.44,5],[1,1.43,93.99],[2,1.03,200]],"ltp":1.5,"tv":226.84,"id":24640635},{"batb":[[0,3.05,5],[1,3,20.2],[2,1.03,200]],"ltp":1.5,"tv":226.84,"id":48610314}]}]}
{"op":"mcm","clk":"11978028662","pt":1724787466452,"mc":[{"id":"1.232352479","rc":[{"batb":[[0,1.43,93.99],[1,1.03,200],[2,1.02,200]],"ltp":1.5,"tv":226.84,"id":24640635},{"batb":[[0,3,20.2],[1,1.03,200],[2,1.02,200]],"ltp":1.5,"tv":226.84,"id":48610314}]}]}
{"op":"mcm","clk":"11978028994","pt":1724787469027,"mc":[{"id":"1.232352479","rc":[{"batb":[[0,1.44,5],[1,1.43,93.99],[2,1.03,200]],"ltp":1.5,"tv":226.84,"id":24640635},{"batb":[[0,3.05,5],[1,3,20.2],[2,1.03,200]],"ltp":1.5,"tv":226.84,"id":48610314}]}]}
{"op":"mcm","clk":"11978029452","pt":1724787472771,"mc":[{"id":"1.232352479","rc":[{"batb":[[0,1.43,93.99],[1,1.03,200],[2,1.02,200]],"ltp":1.5,"tv":226.84,"id":24640635},{"batb":[[0,3,20.2],[1,1.03,200],[2,1.02,200]],"ltp":1.5,"tv":226.84,"id":48610314}]}]}
{"op":"mcm","clk":"11978029829","pt":1724787475868,"mc":[{"id":"1.232352479","rc":[{"batb":[[0,1.44,5],[1,1.43,93.99],[2,1.03,200]],"ltp":1.5,"tv":226.84,"id":24640635},{"batb":[[0,3.05,5],[1,3,20.2],[2,1.03,200]],"ltp":1.5,"tv":226.84,"id":48610314}]}]}
{"op":"mcm","clk":"11978030237","pt":1724787479283,"mc":[{"id":"1.232352479","rc":[{"batb":[[0,1.43,93.99],[1,1.03,200],[2,1.02,200]],"ltp":1.5,"tv":226.84,"id":24640635},{"batb":[[0,3,20.2],[1,1.03,200],[2,1.02,200]],"ltp":1.5,"tv":226.84,"id":48610314}]}]}
{"op":"mcm","clk":"11978030648","pt":1724787482503,"mc":[{"id":"1.232352479","rc":[{"batb":[[0,1.44,5],[1,1.43,93.99],[2,1.03,200]],"ltp":1.5,"tv":226.84,"id":24640635},{"batb":[[0,3.05,5],[1,3,20.2],[2,1.03,200]],"ltp":1.5,"tv":226.84,"id":48610314}]}]}
{"op":"mcm","clk":"11978031047","pt":1724787485654,"mc":[{"id":"1.232352479","rc":[{"batb":[[0,1.43,93.99],[1,1.03,200],[2,1.02,200]],"ltp":1.5,"tv":226.84,"id":24640635},{"batb":[[0,3,20.2],[1,1.03,200],[2,1.02,200]],"ltp":1.5,"tv":226.84,"id":48610314}]}]}
{"op":"mcm","clk":"11978031390","pt":1724787488389,"mc":[{"id":"1.232352479","rc":[{"batb":[[0,1.44,5],[1,1.43,93.99],[2,1.03,200]],"ltp":1.5,"tv":226.84,"id":24640635},{"batb":[[0,3.05,5],[1,3,20.2],[2,1.03,200]],"ltp":1.5,"tv":226.84,"id":48610314}]}]}
{"op":"mcm","clk":"11978031794","pt":1724787491775,"mc":[{"id":"1.232352479","rc":[{"batb":[[0,1.43,93.99],[1,1.03,200],[2,1.02,200]],"ltp":1.5,"tv":226.84,"id":24640635},{"batb":[[0,3,20.2],[1,1.03,200],[2,1.02,200]],"ltp":1.5,"tv":226.84,"id":48610314}]}]}
{"op":"mcm","clk":"11978032149","pt":1724787494481,"mc":[{"id":"1.232352479","rc":[{"batb":[[0,1.44,5],[1,1.43,93.99],[2,1.03,200]],"ltp":1.5,"tv":226.84,"id":24640635},{"batb":[[0,3.05,5],[1,3,20.2],[2,1.03,200]],"ltp":1.5,"tv":226.84,"id":48610314}]}]}
{"op":"mcm","clk":"11978032555","pt":1724787497951,"mc":[{"id":"1.232352479","rc":[{"batb":[[0,1.43,93.99],[1,1.03,200],[2,1.02,200]],"ltp":1.5,"tv":226.84,"id":24640635},{"batb":[[0,3,20.2],[1,1.03,200],[2,1.02,200]],"ltp":1.5,"tv":226.84,"id":48610314}]}]}
{"op":"mcm","clk":"11978032811","pt":1724787500193,"mc":[{"id":"1.232352479","rc":[{"batb":[[0,1.44,5],[1,1.43,93.99],[2,1.03,200]],"ltp":1.5,"tv":226.84,"id":24640635},{"batb":[[0,3.05,5],[1,3,20.2],[2,1.03,200]],"ltp":1.5,"tv":226.84,"id":48610314}]}]}
{"op":"mcm","clk":"11978033198","pt":1724787503408,"mc":[{"id":"1.232352479","rc":[{"batb":[[0,1.43,93.99],[1,1.03,200],[2,1.02,200]],"ltp":1.5,"tv":226.84,"id":24640635},{"batb":[[0,3,20.2],[1,1.03,200],[2,1.02,200]],"ltp":1.5,"tv":226.84,"id":48610314}]}]}
{"op":"mcm","clk":"11978033646","pt":1724787507172,"mc":[{"id":"1.232352479","rc":[{"batb":[[0,1.44,5],[1,1.43,93.99],[2,1.03,200]],"ltp":1.5,"tv":226.84,"id":24640635},{"batb":[[0,3.05,5],[1,3,20.2],[2,1.03,200]],"ltp":1.5,"tv":226.84,"id":48610314}]}]}
{"op":"mcm","clk":"11978034054","pt":1724787510613,"mc":[{"id":"1.232352479","rc":[{"batb":[[0,1.43,93.99],[1,1.03,200],[2,1.02,200]],"ltp":1.5,"tv":226.84,"id":24640635},{"batb":[[0,3,20.2],[1,1.03,200],[2,1.02,200]],"ltp":1.5,"tv":226.84,"id":48610314}]}]}
{"op":"mcm","clk":"11978034341","pt":1724787513041,"mc":[{"id":"1.232352479","rc":[{"batb":[[0,1.44,5],[1,1.43,93.99],[2,1.03,200]],"ltp":1.5,"tv":226.84,"id":24640635},{"batb":[[0,3.05,5],[1,3,20.2],[2,1.03,200]],"ltp":1.5,"tv":226.84,"id":48610314}]}]}
{"op":"mcm","clk":"11978034774","pt":1724787516330,"mc":[{"id":"1.232352479","rc":[{"batb":[[0,1.43,93.99],[1,1.03,200],[2,1.02,200]],"ltp":1.5,"tv":226.84,"id":24640635},{"batb":[[0,3,20.2],[1,1.03,200],[2,1.02,200]],"ltp":1.5,"tv":226.84,"id":48610314}]}]}
{"op":"mcm","clk":"11978035080","pt":1724787518608,"mc":[{"id":"1.232352479","rc":[{"batb":[[0,1.44,5],[1,1.43,93.99],[2,1.03,200]],"ltp":1.5,"tv":226.84,"id":24640635},{"batb":[[0,3.05,5],[1,3,20.2],[2,1.03,200]],"ltp":1.5,"tv":226.84,"id":48610314}]}]}
{"op":"mcm","clk":"11978035506","pt":1724787522011,"mc":[{"id":"1.232352479","rc":[{"batb":[[0,1.43,93.99],[1,1.03,200],[2,1.02,200]],"ltp":1.5,"tv":226.84,"id":24640635},{"batb":[[0,3,20.2],[1,1.03,200],[2,1.02,200]],"ltp":1.5,"tv":226.84,"id":48610314}]}]}
{"op":"mcm","clk":"11978035860","pt":1724787524608,"mc":[{"id":"1.232352479","rc":[{"batb":[[0,1.44,5],[1,1.43,93.99],[2,1.03,200]],"ltp":1.5,"tv":226.84,"id":24640635},{"batb":[[0,3.05,5],[1,3,20.2],[2,1.03,200]],"ltp":1.5,"tv":226.84,"id":48610314}]}]}
{"op":"mcm","clk":"11978036320","pt":1724787528106,"mc":[{"id":"1.232352479","rc":[{"batb":[[0,1.43,93.99],[1,1.03,200],[2,1.02,200]],"ltp":1.5,"tv":226.84,"id":24640635},{"batb":[[0,3,20.2],[1,1.03,200],[2,1.02,200]],"ltp":1.5,"tv":226.84,"id":48610314}]}]}
{"op":"mcm","clk":"11978036660","pt":1724787531021,"mc":[{"id":"1.232352479","rc":[{"batb":[[0,1.44,5],[1,1.43,93.99],[2,1.03,200]],"ltp":1.5,"tv":226.84,"id":24640635},{"batb":[[0,3.05,5],[1,3,20.2],[2,1.03,200]],"ltp":1.5,"tv":226.84,"id":48610314}]}]}
{"op":"mcm","clk":"11978037043","pt":1724787534318,"mc":[{"id":"1.232352479","rc":[{"batb":[[0,1.43,93.99],[1,1.03,200],[2,1.02,200]],"ltp":1.5,"tv":226.84,"id":24640635},{"batb":[[0,3,20.2],[1,1.03,200],[2,1.02,200]],"ltp":1.5,"tv":226.84,"id":48610314}]}]}
{"op":"mcm","clk":"11978037356","pt":1724787537167,"mc":[{"id":"1.232352479","rc":[{"batb":[[0,1.44,5],[1,1.43,93.99],[2,1.03,200]],"ltp":1.5,"tv":226.84,"id":24640635},{"batb":[[0,3.05,5],[1,3,20.2],[2,1.03,200]],"ltp":1.5,"tv":226.84,"id":48610314}]}]}
{"op":"mcm","clk":"11978037785","pt":1724787540725,"mc":[{"id":"1.232352479","rc":[{"batb":[[0,1.43,93.99],[1,1.03,200],[2,1.02,200]],"ltp":1.5,"tv":226.84,"id":24640635},{"batb":[[0,3,20.2],[1,1.03,200],[2,1.02,200]],"ltp":1.5,"tv":226.84,"id":48610314}]}]}
{"op":"mcm","clk":"11978038170","pt":1724787543842,"mc":[{"id":"1.232352479","rc":[{"batb":[[0,1.44,5],[1,1.43,93.99],[2,1.03,200]],"ltp":1.5,"tv":226.84,"id":24640635},{"batb":[[0,3.05,5],[1,3,20.2],[2,1.03,200]],"ltp":1.5,"tv":226.84,"id":48610314}]}]}
{"op":"mcm","clk":"11978038601","pt":1724787547141,"mc":[{"id":"1.232352479","rc":[{"batb":[[0,1.43,93.99],[1,1.03,200],[2,1.02,200]],"ltp":1.5,"tv":226.84,"id":24640635},{"batb":[[0,3,20.2],[1,1.03,200],[2,1.02,200]],"ltp":1.5,"tv":226.84,"id":48610314}]}]}
{"op":"mcm","clk":"11978039001","pt":1724787550523,"mc":[{"id":"1.232352479","rc":[{"batb":[[0,1.44,5],[1,1.43,93.99],[2,1.03,200]],"ltp":1.5,"tv":226.84,"id":24640635},{"batb":[[0,3.05,5],[1,3,20.2],[2,1.03,200]],"ltp":1.5,"tv":226.84,"id":48610314}]}]}
{"op":"mcm","clk":"11978039455","pt":1724787554152,"mc":[{"id":"1.232352479","rc":[{"batb":[[0,1.43,93.99],[1,1.03,200],[2,1.02,200]],"ltp":1.5,"tv":226.84,"id":24640635},{"batb":[[0,3,20.2],[1,1.03,200],[2,1.02,200]],"ltp":1.5,"tv":226.84,"id":48610314}]}]}
{"op":"mcm","clk":"11978039835","pt":1724787557233,"mc":[{"id":"1.232352479","rc":[{"batb":[[0,1.44,5],[1,1.43,93.99],[2,1.03,200]],"ltp":1.5,"tv":226.84,"id":24640635},{"batb":[[0,3.05,5],[1,3,20.2],[2,1.03,200]],"ltp":1.5,"tv":226.84,"id":48610314}]}]}
{"op":"mcm","clk":"11978040261","pt":1724787560826,"mc":[{"id":"1.232352479","rc":[{"batb":[[0,1.43,93.99],[1,1.03,200],[2,1.02,200]],"ltp":1.5,"tv":226.84,"id":24640635},{"batb":[[0,3,20.2],[1,1.03,200],[2,1.02,200]],"ltp":1.5,"tv":226.84,"id":48610314}]}]}
{"op":"mcm","clk":"11978040532","pt":1724787563077,"mc":[{"id":"1.232352479","rc":[{"batb":[[0,1.44,5],[1,1.43,93.99],[2,1.03,200]],"ltp":1.5,"tv":226.84,"id":24640635},{"batb":[[0,3.05,5],[1,3,20.2],[2,1.03,200]],"ltp":1.5,"tv":226.84,"id":48610314}]}]}
{"op":"mcm","clk":"11978040957","pt":1724787566670,"mc":[{"id":"1.232352479","rc":[{"batb":[[0,1.43,93.99],[1,1.03,200],[2,1.02,200]],"ltp":1.5,"tv":226.84,"id":24640635},{"batb":[[0,3,20.2],[1,1.03,200],[2,1.02,200]],"ltp":1.5,"tv":226.84,"id":48610314}]}]}
{"op":"mcm","clk":"11978041727","pt":1724787573480,"mc":[{"id":"1.232352479","rc":[{"batb":[[0,1.44,5],[1,1.43,93.99],[2,1.03,200]],"ltp":1.5,"tv":226.84,"id":24640635},{"batb":[[0,3.05,5],[1,3,20.2],[2,1.03,200]],"ltp":1.5,"tv":226.84,"id":48610314}]}]}
{"op":"mcm","clk":"11978042125","pt":1724787576873,"mc":[{"id":"1.232352479","rc":[{"batb":[[0,1.43,93.99],[1,1.03,200],[2,1.02,200]],"ltp":1.5,"tv":226.84,"id":24640635},{"batb":[[0,3,20.2],[1,1.03,200],[2,1.02,200]],"ltp":1.5,"tv":226.84,"id":48610314}]}]}
{"op":"mcm","clk":"11978042376","pt":1724787579074,"mc":[{"id":"1.232352479","rc":[{"batb":[[0,1.44,5],[1,1.43,93.99],[2,1.03,200]],"ltp":1.5,"tv":226.84,"id":24640635},{"batb":[[0,3.05,5],[1,3,20.2],[2,1.03,200]],"ltp":1.5,"tv":226.84,"id":48610314}]}]}
{"op":"mcm","clk":"11978042777","pt":1724787582369,"mc":[{"id":"1.232352479","rc":[{"batb":[[0,1.43,93.99],[1,1.03,200],[2,1.02,200]],"ltp":1.5,"tv":226.84,"id":24640635},{"batb":[[0,3,20.2],[1,1.03,200],[2,1.02,200]],"ltp":1.5,"tv":226.84,"id":48610314}]}]}
{"op":"mcm","clk":"11978043025","pt":1724787584785,"mc":[{"id":"1.232352479","rc":[{"batb":[[0,1.44,5],[1,1.43,93.99],[2,1.03,200]],"ltp":1.5,"tv":226.84,"id":24640635},{"batb":[[0,3.05,5],[1,3,20.2],[2,1.03,200]],"ltp":1.5,"tv":226.84,"id":48610314}]}]}
{"op":"mcm","clk":"11978043439","pt":1724787588072,"mc":[{"id":"1.232352479","rc":[{"batb":[[0,1.43,93.99],[1,1.03,200],[2,1.02,200]],"ltp":1.5,"tv":226.84,"id":24640635},{"batb":[[0,3,20.2],[1,1.03,200],[2,1.02,200]],"ltp":1.5,"tv":226.84,"id":48610314}]}]}
{"op":"mcm","clk":"11978043799","pt":1724787591393,"mc":[{"id":"1.232352479","rc":[{"batb":[[0,1.44,5],[1,1.43,93.99],[2,1.03,200]],"ltp":1.5,"tv":226.84,"id":24640635},{"batb":[[0,3.05,5],[1,3,20.2],[2,1.03,200]],"ltp":1.5,"tv":226.84,"id":48610314}]}]}
{"op":"mcm","clk":"11978044175","pt":1724787594895,"mc":[{"id":"1.232352479","rc":[{"batb":[[0,1.43,93.99],[1,1.03,200],[2,1.02,200]],"ltp":1.5,"tv":226.84,"id":24640635},{"batb":[[0,3,20.2],[1,1.03,200],[2,1.02,200]],"ltp":1.5,"tv":226.84,"id":48610314}]}]}
{"op":"mcm","clk":"11978044605","pt":1724787598315,"mc":[{"id":"1.232352479","rc":[{"batb":[[0,1.44,5],[1,1.43,93.99],[2,1.03,200]],"ltp":1.5,"tv":226.84,"id":24640635},{"batb":[[0,3.05,5],[1,3,20.2],[2,1.03,200]],"ltp":1.5,"tv":226.84,"id":48610314}]}]}
{"op":"mcm","clk":"11978044960","pt":1724787601608,"mc":[{"id":"1.232352479","rc":[{"batb":[[0,1.43,93.99],[1,1.03,200],[2,1.02,200]],"ltp":1.5,"tv":226.84,"id":24640635},{"batb":[[0,3,20.2],[1,1.03,200],[2,1.02,200]],"ltp":1.5,"tv":226.84,"id":48610314}]}]}
{"op":"mcm","clk":"11978045475","pt":1724787606119,"mc":[{"id":"1.232352479","rc":[{"batb":[[0,1.44,5],[1,1.43,93.99],[2,1.03,200]],"ltp":1.5,"tv":226.84,"id":24640635},{"batb":[[0,3.05,5],[1,3,20.2],[2,1.03,200]],"ltp":1.5,"tv":226.84,"id":48610314}]}]}
{"op":"mcm","clk":"11978045893","pt":1724787609633,"mc":[{"id":"1.232352479","rc":[{"batb":[[0,1.43,93.99],[1,1.03,200],[2,1.02,200]],"ltp":1.5,"tv":226.84,"id":24640635},{"batb":[[0,3,20.2],[1,1.03,200],[2,1.02,200]],"ltp":1.5,"tv":226.84,"id":48610314}]}]}
{"op":"mcm","clk":"11978046257","pt":1724787612837,"mc":[{"id":"1.232352479","rc":[{"batb":[[0,1.44,5],[1,1.43,93.99],[2,1.03,200]],"ltp":1.5,"tv":226.84,"id":24640635},{"batb":[[0,3.05,5],[1,3,20.2],[2,1.03,200]],"ltp":1.5,"tv":226.84,"id":48610314}]}]}
{"op":"mcm","clk":"11978046665","pt":1724787616218,"mc":[{"id":"1.232352479","rc":[{"batb":[[0,1.43,93.99],[1,1.03,200],[2,1.02,200]],"ltp":1.5,"tv":226.84,"id":24640635},{"batb":[[0,3,20.2],[1,1.03,200],[2,1.02,200]],"ltp":1.5,"tv":226.84,"id":48610314}]}]}
{"op":"mcm","clk":"11978046971","pt":1724787618520,"mc":[{"id":"1.232352479","rc":[{"batb":[[0,1.44,5],[1,1.43,93.99],[2,1.03,200]],"ltp":1.5,"tv":226.84,"id":24640635},{"batb":[[0,3.05,5],[1,3,20.2],[2,1.03,200]],"ltp":1.5,"tv":226.84,"id":48610314}]}]}
{"op":"mcm","clk":"11978047347","pt":1724787621826,"mc":[{"id":"1.232352479","rc":[{"batb":[[0,1.43,93.99],[1,1.03,200],[2,1.02,200]],"ltp":1.5,"tv":226.84,"id":24640635},{"batb":[[0,3,20.2],[1,1.03,200],[2,1.02,200]],"ltp":1.5,"tv":226.84,"id":48610314}]}]}
{"op":"mcm","clk":"11978047717","pt":1724787624780,"mc":[{"id":"1.232352479","rc":[{"batb":[[0,1.44,5],[1,1.43,93.99],[2,1.03,200]],"ltp":1.5,"tv":226.84,"id":24640635},{"batb":[[0,3.05,5],[1,3,20.2],[2,1.03,200]],"ltp":1.5,"tv":226.84,"id":48610314}]}]}
{"op":"mcm","clk":"11978048142","pt":1724787628314,"mc":[{"id":"1.232352479","rc":[{"batb":[[0,1.43,93.99],[1,1.03,200],[2,1.02,200]],"ltp":1.5,"tv":226.84,"id":24640635},{"batb":[[0,3,20.2],[1,1.03,200],[2,1.02,200]],"ltp":1.5,"tv":226.84,"id":48610314}]}]}
{"op":"mcm","clk":"11978048499","pt":1724787631662,"mc":[{"id":"1.232352479","rc":[{"batb":[[0,1.44,5],[1,1.43,93.99],[2,1.03,200]],"ltp":1.5,"tv":226.84,"id":24640635},{"batb":[[0,3.05,5],[1,3,20.2],[2,1.03,200]],"ltp":1.5,"tv":226.84,"id":48610314}]}]}
{"op":"mcm","clk":"11978048871","pt":1724787635032,"mc":[{"id":"1.232352479","rc":[{"batb":[[0,1.43,93.99],[1,1.03,200],[2,1.02,200]],"ltp":1.5,"tv":226.84,"id":24640635},{"batb":[[0,3,20.2],[1,1.03,200],[2,1.02,200]],"ltp":1.5,"tv":226.84,"id":48610314}]}]}
{"op":"mcm","clk":"11978049154","pt":1724787637546,"mc":[{"id":"1.232352479","rc":[{"batb":[[0,1.44,5],[1,1.43,93.99],[2,1.03,200]],"ltp":1.5,"tv":226.84,"id":24640635},{"batb":[[0,3.05,5],[1,3,20.2],[2,1.03,200]],"ltp":1.5,"tv":226.84,"id":48610314}]}]}
{"op":"mcm","clk":"11978049543","pt":1724787640847,"mc":[{"id":"1.232352479","rc":[{"batb":[[0,1.43,93.99],[1,1.03,200],[2,1.02,200]],"ltp":1.5,"tv":226.84,"id":24640635},{"batb":[[0,3,20.2],[1,1.03,200],[2,1.02,200]],"ltp":1.5,"tv":226.84,"id":48610314}]}]}
{"op":"mcm","clk":"11978049990","pt":1724787644738,"mc":[{"id":"1.232352479","rc":[{"batb":[[0,1.44,5],[1,1.43,93.99],[2,1.03,200]],"ltp":1.5,"tv":226.84,"id":24640635},{"batb":[[0,3.05,5],[1,3,20.2],[2,1.03,200]],"ltp":1.5,"tv":226.84,"id":48610314}]}]}
{"op":"mcm","clk":"11978050388","pt":1724787648246,"mc":[{"id":"1.232352479","rc":[{"batb":[[0,1.43,93.99],[1,1.03,200],[2,1.02,200]],"ltp":1.5,"tv":226.84,"id":24640635},{"batb":[[0,3,20.2],[1,1.03,200],[2,1.02,200]],"ltp":1.5,"tv":226.84,"id":48610314}]}]}
{"op":"mcm","clk":"11978050826","pt":1724787651972,"mc":[{"id":"1.232352479","rc":[{"batb":[[0,1.44,5],[1,1.43,93.99],[2,1.03,200]],"ltp":1.5,"tv":226.84,"id":24640635},{"batb":[[0,3.05,5],[1,3,20.2],[2,1.03,200]],"ltp":1.5,"tv":226.84,"id":48610314}]}]}
{"op":"mcm","clk":"11978051207","pt":1724787655386,"mc":[{"id":"1.232352479","rc":[{"batb":[[0,1.43,93.99],[1,1.03,200],[2,1.02,200]],"ltp":1.5,"tv":226.84,"id":24640635},{"batb":[[0,3,20.2],[1,1.03,200],[2,1.02,200]],"ltp":1.5,"tv":226.84,"id":48610314}]}]}
{"op":"mcm","clk":"11978051481","pt":1724787657808,"mc":[{"id":"1.232352479","rc":[{"batb":[[0,1.44,5],[1,1.43,93.99],[2,1.03,200]],"ltp":1.5,"tv":226.84,"id":24640635},{"batb":[[0,3.05,5],[1,3,20.2],[2,1.03,200]],"ltp":1.5,"tv":226.84,"id":48610314}]}]}
{"op":"mcm","clk":"11978051859","pt":1724787661185,"mc":[{"id":"1.232352479","rc":[{"batb":[[0,1.43,93.99],[1,1.03,200],[2,1.02,200]],"ltp":1.5,"tv":226.84,"id":24640635},{"batb":[[0,3,20.2],[1,1.03,200],[2,1.02,200]],"ltp":1.5,"tv":226.84,"id":48610314}]}]}
{"op":"mcm","clk":"11978052416","pt":1724787665964,"mc":[{"id":"1.232352479","rc":[{"batb":[[0,1.44,5],[1,1.43,93.99],[2,1.03,200]],"ltp":1.5,"tv":226.84,"id":24640635},{"batb":[[0,3.05,5],[1,3,20.2],[2,1.03,200]],"ltp":1.5,"tv":226.84,"id":48610314}]}]}
{"op":"mcm","clk":"11978052786","pt":1724787669174,"mc":[{"id":"1.232352479","rc":[{"batb":[[0,1.43,93.99],[1,1.03,200],[2,1.02,200]],"ltp":1.5,"tv":226.84,"id":24640635},{"batb":[[0,3,20.2],[1,1.03,200],[2,1.02,200]],"ltp":1.5,"tv":226.84,"id":48610314}]}]}
{"op":"mcm","clk":"11978053279","pt":1724787673494,"mc":[{"id":"1.232352479","rc":[{"batb":[[0,1.44,5],[1,1.43,93.99],[2,1.03,200]],"ltp":1.5,"tv":226.84,"id":24640635},{"batb":[[0,3.05,5],[1,3,20.2],[2,1.03,200]],"ltp":1.5,"tv":226.84,"id":48610314}]}]}
{"op":"mcm","clk":"11978053692","pt":1724787677014,"mc":[{"id":"1.232352479","rc":[{"batb":[[0,1.43,93.99],[1,1.03,200],[2,1.02,200]],"ltp":1.5,"tv":226.84,"id":24640635},{"batb":[[0,3,20.2],[1,1.03,200],[2,1.02,200]],"ltp":1.5,"tv":226.84,"id":48610314}]}]}
{"op":"mcm","clk":"11978053965","pt":1724787679272,"mc":[{"id":"1.232352479","rc":[{"batb":[[0,1.44,5],[1,1.43,93.99],[2,1.03,200]],"ltp":1.5,"tv":226.84,"id":24640635},{"batb":[[0,3.05,5],[1,3,20.2],[2,1.03,200]],"ltp":1.5,"tv":226.84,"id":48610314}]}]}
{"op":"mcm","clk":"11978054316","pt":1724787682689,"mc":[{"id":"1.232352479","rc":[{"batb":[[0,1.43,93.99],[1,1.03,200],[2,1.02,200]],"ltp":1.5,"tv":226.84,"id":24640635},{"batb":[[0,3,20.2],[1,1.03,200],[2,1.02,200]],"ltp":1.5,"tv":226.84,"id":48610314}]}]}
{"op":"mcm","clk":"11978054613","pt":1724787685103,"mc":[{"id":"1.232352479","rc":[{"batb":[[0,1.44,5],[1,1.43,93.99],[2,1.03,200]],"ltp":1.5,"tv":226.84,"id":24640635},{"batb":[[0,3.05,5],[1,3,20.2],[2,1.03,200]],"ltp":1.5,"tv":226.84,"id":48610314}]}]}
{"op":"mcm","clk":"11978054983","pt":1724787688411,"mc":[{"id":"1.232352479","rc":[{"batb":[[0,1.43,93.99],[1,1.03,200],[2,1.02,200]],"ltp":1.5,"tv":226.84,"id":24640635},{"batb":[[0,3,20.2],[1,1.03,200],[2,1.02,200]],"ltp":1.5,"tv":226.84,"id":48610314}]}]}
{"op":"mcm","clk":"11978055459","pt":1724787691802,"mc":[{"id":"1.232352479","rc":[{"batb":[[0,1.44,5],[1,1.43,93.99],[2,1.03,200]],"ltp":1.5,"tv":226.84,"id":24640635},{"batb":[[0,3.05,5],[1,3,20.2],[2,1.03,200]],"ltp":1.5,"tv":226.84,"id":48610314}]}]}
{"op":"mcm","clk":"11978055873","pt":1724787695419,"mc":[{"id":"1.232352479","rc":[{"batb":[[0,1.43,93.99],[1,1.03,200],[2,1.02,200]],"ltp":1.5,"tv":226.84,"id":24640635},{"batb":[[0,3,20.2],[1,1.03,200],[2,1.02,200]],"ltp":1.5,"tv":226.84,"id":48610314}]}]}
{"op":"mcm","clk":"11978056259","pt":1724787698032,"mc":[{"id":"1.232352479","rc":[{"batb":[[0,1.44,5],[1,1.43,93.99],[2,1.03,200]],"ltp":1.5,"tv":226.84,"id":24640635},{"batb":[[0,3.05,5],[1,3,20.2],[2,1.03,200]],"ltp":1.5,"tv":226.84,"id":48610314}]}]}
{"op":"mcm","clk":"11978056659","pt":1724787701449,"mc":[{"id":"1.232352479","rc":[{"batb":[[0,1.43,93.99],[1,1.03,200],[2,1.02,200]],"ltp":1.5,"tv":226.84,"id":24640635},{"batb":[[0,3,20.2],[1,1.03,200],[2,1.02,200]],"ltp":1.5,"tv":226.84,"id":48610314}]}]}
{"op":"mcm","clk":"11978057162","pt":1724787705854,"mc":[{"id":"1.232352479","rc":[{"batb":[[0,1.44,5],[1,1.43,93.99],[2,1.03,200]],"ltp":1.5,"tv":226.84,"id":24640635},{"batb":[[0,3.05,5],[1,3,20.2],[2,1.03,200]],"ltp":1.5,"tv":226.84,"id":48610314}]}]}
{"op":"mcm","clk":"11978057534","pt":1724787709235,"mc":[{"id":"1.232352479","rc":[{"batb":[[0,1.43,93.99],[1,1.03,200],[2,1.02,200]],"ltp":1.5,"tv":226.84,"id":24640635},{"batb":[[0,3,20.2],[1,1.03,200],[2,1.02,200]],"ltp":1.5,"tv":226.84,"id":48610314}]}]}
{"op":"mcm","clk":"11978057858","pt":1724787711849,"mc":[{"id":"1.232352479","rc":[{"batb":[[0,1.44,5],[1,1.43,93.99],[2,1.03,200]],"ltp":1.5,"tv":226.84,"id":24640635},{"batb":[[0,3.05,5],[1,3,20.2],[2,1.03,200]],"ltp":1.5,"tv":226.84,"id":48610314}]}]}
{"op":"mcm","clk":"11978058270","pt":1724787715303,"mc":[{"id":"1.232352479","rc":[{"batb":[[0,1.43,93.99],[1,1.03,200],[2,1.02,200]],"ltp":1.5,"tv":226.84,"id":24640635},{"batb":[[0,3,20.2],[1,1.03,200],[2,1.02,200]],"ltp":1.5,"tv":226.84,"id":48610314}]}]}
{"op":"mcm","clk":"11978058606","pt":1724787718189,"mc":[{"id":"1.232352479","rc":[{"batb":[[0,1.44,5],[1,1.43,93.99],[2,1.03,200]],"ltp":1.5,"tv":226.84,"id":24640635},{"batb":[[0,3.05,5],[1,3,20.2],[2,1.03,200]],"ltp":1.5,"tv":226.84,"id":48610314}]}]}
{"op":"mcm","clk":"11978059090","pt":1724787721762,"mc":[{"id":"1.232352479","rc":[{"batb":[[0,1.43,93.99],[1,1.03,200],[2,1.02,200]],"ltp":1.5,"tv":226.84,"id":24640635},{"batb":[[0,3,20.2],[1,1.03,200],[2,1.02,200]],"ltp":1.5,"tv":226.84,"id":48610314}]}]}
{"op":"mcm","clk":"11978059761","pt":1724787727226,"mc":[{"id":"1.232352479","rc":[{"batb":[[0,1.44,5],[1,1.43,93.99],[2,1.03,200]],"ltp":1.5,"tv":226.84,"id":24640635},{"batb":[[0,3.05,5],[1,3,20.2],[2,1.03,200]],"ltp":1.5,"tv":226.84,"id":48610314}]}]}
{"op":"mcm","clk":"11978060172","pt":1724787730742,"mc":[{"id":"1.232352479","rc":[{"batb":[[0,1.43,93.99],[1,1.03,200],[2,1.02,200]],"ltp":1.5,"tv":226.84,"id":24640635},{"batb":[[0,3,20.2],[1,1.03,200],[2,1.02,200]],"ltp":1.5,"tv":226.84,"id":48610314}]}]}
{"op":"mcm","clk":"11978061044","pt":1724787737730,"mc":[{"id":"1.232352479","rc":[{"batb":[[0,1.44,5],[1,1.43,93.99],[2,1.03,200]],"ltp":1.5,"tv":226.84,"id":24640635},{"batb":[[0,3.05,5],[1,3,20.2],[2,1.03,200]],"ltp":1.5,"tv":226.84,"id":48610314}]}]}
{"op":"mcm","clk":"11978061427","pt":1724787741015,"mc":[{"id":"1.232352479","rc":[{"batb":[[0,1.43,93.99],[1,1.03,200],[2,1.02,200]],"ltp":1.5,"tv":226.84,"id":24640635},{"batb":[[0,3,20.2],[1,1.03,200],[2,1.02,200]],"ltp":1.5,"tv":226.84,"id":48610314}]}]}
{"op":"mcm","clk":"11978061773","pt":1724787744058,"mc":[{"id":"1.232352479","rc":[{"batb":[[0,1.44,5],[1,1.43,93.99],[2,1.03,200]],"ltp":1.5,"tv":226.84,"id":24640635},{"batb":[[0,3.05,5],[1,3,20.2],[2,1.03,200]],"ltp":1.5,"tv":226.84,"id":48610314}]}]}
{"op":"mcm","clk":"11978062198","pt":1724787747623,"mc":[{"id":"1.232352479","rc":[{"batb":[[0,1.43,93.99],[1,1.03,200],[2,1.02,200]],"ltp":1.5,"tv":226.84,"id":24640635},{"batb":[[0,3,20.2],[1,1.03,200],[2,1.02,200]],"ltp":1.5,"tv":226.84,"id":48610314}]}]}
{"op":"mcm","clk":"11978062795","pt":1724787752917,"mc":[{"id":"1.232352479","rc":[{"batb":[[0,1.44,5],[1,1.43,93.99],[2,1.03,200]],"ltp":1.5,"tv":226.84,"id":24640635},{"batb":[[0,3.05,5],[1,3,20.2],[2,1.03,200]],"ltp":1.5,"tv":226.84,"id":48610314}]}]}
{"op":"mcm","clk":"11978063169","pt":1724787756215,"mc":[{"id":"1.232352479","rc":[{"batb":[[0,1.43,93.99],[1,1.03,200],[2,1.02,200]],"ltp":1.5,"tv":226.84,"id":24640635},{"batb":[[0,3,20.2],[1,1.03,200],[2,1.02,200]],"ltp":1.5,"tv":226.84,"id":48610314}]}]}
{"op":"mcm","clk":"11978063553","pt":1724787760127,"mc":[{"id":"1.232352479","rc":[{"batb":[[0,1.44,5],[1,1.43,93.99],[2,1.03,200]],"ltp":1.5,"tv":226.84,"id":24640635},{"batb":[[0,3.05,5],[1,3,20.2],[2,1.03,200]],"ltp":1.5,"tv":226.84,"id":48610314}]}]}
{"op":"mcm","clk":"11978063923","pt":1724787763545,"mc":[{"id":"1.232352479","rc":[{"batb":[[0,1.43,93.99],[1,1.03,200],[2,1.02,200]],"ltp":1.5,"tv":226.84,"id":24640635},{"batb":[[0,3,20.2],[1,1.03,200],[2,1.02,200]],"ltp":1.5,"tv":226.84,"id":48610314}]}]}
{"op":"mcm","clk":"11978064251","pt":1724787766451,"mc":[{"id":"1.232352479","rc":[{"batb":[[0,1.44,5],[1,1.43,93.99],[2,1.03,200]],"ltp":1.5,"tv":226.84,"id":24640635},{"batb":[[0,3.05,5],[1,3,20.2],[2,1.03,200]],"ltp":1.5,"tv":226.84,"id":48610314}]}]}
{"op":"mcm","clk":"11978064702","pt":1724787769935,"mc":[{"id":"1.232352479","rc":[{"batb":[[0,1.43,93.99],[1,1.03,200],[2,1.02,200]],"ltp":1.5,"tv":226.84,"id":24640635},{"batb":[[0,3,20.2],[1,1.03,200],[2,1.02,200]],"ltp":1.5,"tv":226.84,"id":48610314}]}]}
{"op":"mcm","clk":"11978065235","pt":1724787774646,"mc":[{"id":"1.232352479","rc":[{"batb":[[0,1.44,5],[1,1.43,93.99],[2,1.03,200]],"ltp":1.5,"tv":226.84,"id":24640635},{"batb":[[0,3.05,5],[1,3,20.2],[2,1.03,200]],"ltp":1.5,"tv":226.84,"id":48610314}]}]}
{"op":"mcm","clk":"11978065618","pt":1724787777889,"mc":[{"id":"1.232352479","rc":[{"batb":[[0,1.43,93.99],[1,1.03,200],[2,1.02,200]],"ltp":1.5,"tv":226.84,"id":24640635},{"batb":[[0,3,20.2],[1,1.03,200],[2,1.02,200]],"ltp":1.5,"tv":226.84,"id":48610314}]}]}
{"op":"mcm","clk":"11978066052","pt":1724787781274,"mc":[{"id":"1.232352479","rc":[{"batb":[[0,1.44,5],[1,1.43,93.99],[2,1.03,200]],"ltp":1.5,"tv":226.84,"id":24640635},{"batb":[[0,3.05,5],[1,3,20.2],[2,1.03,200]],"ltp":1.5,"tv":226.84,"id":48610314}]}]}
{"op":"mcm","clk":"11978066494","pt":1724787784567,"mc":[{"id":"1.232352479","rc":[{"batb":[[0,1.43,93.99],[1,1.03,200],[2,1.02,200]],"ltp":1.5,"tv":226.84,"id":24640635},{"batb":[[0,3,20.2],[1,1.03,200],[2,1.02,200]],"ltp":1.5,"tv":226.84,"id":48610314}]}]}
{"op":"mcm","clk":"11978067637","pt":1724787793269,"mc":[{"id":"1.232352479","rc":[{"batb":[[0,1.44,5],[1,1.43,93.99],[2,1.03,200]],"ltp":1.5,"tv":226.84,"id":24640635},{"batb":[[0,3.05,5],[1,3,20.2],[2,1.03,200]],"ltp":1.5,"tv":226.84,"id":48610314}]}]}
{"op":"mcm","clk":"11978068112","pt":1724787796781,"mc":[{"id":"1.232352479","rc":[{"batb":[[0,1.43,93.99],[1,1.03,200],[2,1.02,200]],"ltp":1.5,"tv":226.84,"id":24640635},{"batb":[[0,3,20.2],[1,1.03,200],[2,1.02,200]],"ltp":1.5,"tv":226.84,"id":48610314}]}]}
{"op":"mcm","clk":"11978070389","pt":1724787814585,"mc":[{"id":"1.232352479","rc":[{"batb":[[0,1.44,5],[1,1.43,93.99],[2,1.03,200]],"ltp":1.5,"tv":226.84,"id":24640635},{"batb":[[0,3.05,5],[1,3,20.2],[2,1.03,200]],"ltp":1.5,"tv":226.84,"id":48610314}]}]}
{"op":"mcm","clk":"11978070793","pt":1724787817824,"mc":[{"id":"1.232352479","rc":[{"batb":[[0,1.43,93.99],[1,1.03,200],[2,1.02,200]],"ltp":1.5,"tv":226.84,"id":24640635},{"batb":[[0,3,20.2],[1,1.03,200],[2,1.02,200]],"ltp":1.5,"tv":226.84,"id":48610314}]}]}
{"op":"mcm","clk":"11978071679","pt":1724787825040,"mc":[{"id":"1.232352479","rc":[{"batb":[[0,1.44,5],[1,1.43,93.99],[2,1.03,200]],"ltp":1.5,"tv":226.84,"id":24640635},{"batb":[[0,3.05,5],[1,3,20.2],[2,1.03,200]],"ltp":1.5,"tv":226.84,"id":48610314}]}]}
{"op":"mcm","clk":"11978072140","pt":1724787828526,"mc":[{"id":"1.232352479","rc":[{"batb":[[0,1.43,93.99],[1,1.03,200],[2,1.02,200]],"ltp":1.5,"tv":226.84,"id":24640635}]}]}
{"op":"mcm","clk":"11978072155","pt":1724787828620,"mc":[{"id":"1.232352479","rc":[{"batb":[[0,3,20.2],[1,1.03,200],[2,1.02,200]],"ltp":1.5,"tv":226.84,"id":48610314}]}]}
{"op":"mcm","clk":"11978073957","pt":1724787843319,"mc":[{"id":"1.232352479","rc":[{"batb":[[0,1.44,5],[1,1.43,93.99],[2,1.03,200]],"ltp":1.5,"tv":226.84,"id":24640635},{"batb":[[0,3.05,5],[1,3,20.2],[2,1.03,200]],"ltp":1.5,"tv":226.84,"id":48610314}]}]}
{"op":"mcm","clk":"11978074386","pt":1724787846729,"mc":[{"id":"1.232352479","rc":[{"batb":[[0,1.43,93.99],[1,1.03,200],[2,1.02,200]],"ltp":1.5,"tv":226.84,"id":24640635},{"batb":[[0,3,20.2],[1,1.03,200],[2,1.02,200]],"ltp":1.5,"tv":226.84,"id":48610314}]}]}
{"op":"mcm","clk":"11978074779","pt":1724787849939,"mc":[{"id":"1.232352479","rc":[{"batb":[[0,1.44,5],[1,1.43,93.99],[2,1.03,200]],"ltp":1.5,"tv":226.84,"id":24640635},{"batb":[[0,3.05,5],[1,3,20.2],[2,1.03,200]],"ltp":1.5,"tv":226.84,"id":48610314}]}]}
{"op":"mcm","clk":"11978075212","pt":1724787853251,"mc":[{"id":"1.232352479","rc":[{"batb":[[0,1.43,93.99],[1,1.03,200],[2,1.02,200]],"ltp":1.5,"tv":226.84,"id":24640635},{"batb":[[0,3,20.2],[1,1.03,200],[2,1.02,200]],"ltp":1.5,"tv":226.84,"id":48610314}]}]}
{"op":"mcm","clk":"11978075590","pt":1724787856346,"mc":[{"id":"1.232352479","rc":[{"batb":[[0,1.44,5],[1,1.43,93.99],[2,1.03,200]],"ltp":1.5,"tv":226.84,"id":24640635},{"batb":[[0,3.05,5],[1,3,20.2],[2,1.03,200]],"ltp":1.5,"tv":226.84,"id":48610314}]}]}
{"op":"mcm","clk":"11978076026","pt":1724787859843,"mc":[{"id":"1.232352479","rc":[{"batb":[[0,1.43,93.99],[1,1.03,200],[2,1.02,200]],"ltp":1.5,"tv":226.84,"id":24640635},{"batb":[[0,3,20.2],[1,1.03,200],[2,1.02,200]],"ltp":1.5,"tv":226.84,"id":48610314}]}]}
{"op":"mcm","clk":"11978076625","pt":1724787864436,"mc":[{"id":"1.232352479","rc":[{"batb":[[0,1.44,5],[1,1.43,93.99],[2,1.03,200]],"ltp":1.5,"tv":226.84,"id":24640635},{"batb":[[0,3.05,5],[1,3,20.2],[2,1.03,200]],"ltp":1.5,"tv":226.84,"id":48610314}]}]}
{"op":"mcm","clk":"11978077037","pt":1724787867905,"mc":[{"id":"1.232352479","rc":[{"batb":[[0,1.43,93.99],[1,1.03,200],[2,1.02,200]],"ltp":1.5,"tv":226.84,"id":24640635},{"batb":[[0,3,20.2],[1,1.03,200],[2,1.02,200]],"ltp":1.5,"tv":226.84,"id":48610314}]}]}
{"op":"mcm","clk":"11978077522","pt":1724787872048,"mc":[{"id":"1.232352479","rc":[{"batb":[[0,1.44,5],[1,1.43,93.99],[2,1.03,200]],"ltp":1.5,"tv":226.84,"id":24640635},{"batb":[[0,3.05,5],[1,3,20.2],[2,1.03,200]],"ltp":1.5,"tv":226.84,"id":48610314}]}]}
{"op":"mcm","clk":"11978077883","pt":1724787875315,"mc":[{"id":"1.232352479","rc":[{"batb":[[0,1.43,93.99],[1,1.03,200],[2,1.02,200]],"ltp":1.5,"tv":226.84,"id":24640635},{"batb":[[0,3,20.2],[1,1.03,200],[2,1.02,200]],"ltp":1.5,"tv":226.84,"id":48610314}]}]}
{"op":"mcm","clk":"11978078408","pt":1724787879603,"mc":[{"id":"1.232352479","rc":[{"batb":[[0,1.44,5],[1,1.43,93.99],[2,1.03,200]],"ltp":1.5,"tv":226.84,"id":24640635},{"batb":[[0,3.05,5],[1,3,20.2],[2,1.03,200]],"ltp":1.5,"tv":226.84,"id":48610314}]}]}
{"op":"mcm","clk":"11978078804","pt":1724787883020,"mc":[{"id":"1.232352479","rc":[{"batb":[[0,1.43,93.99],[1,1.03,200],[2,1.02,200]],"ltp":1.5,"tv":226.84,"id":24640635},{"batb":[[0,3,20.2],[1,1.03,200],[2,1.02,200]],"ltp":1.5,"tv":226.84,"id":48610314}]}]}
{"op":"mcm","clk":"11978079659","pt":1724787889688,"mc":[{"id":"1.232352479","rc":[{"batb":[[0,1.44,5],[1,1.43,93.99],[2,1.03,200]],"ltp":1.5,"tv":226.84,"id":24640635},{"batb":[[0,3.05,5],[1,3,20.2],[2,1.03,200]],"ltp":1.5,"tv":226.84,"id":48610314}]}]}
{"op":"mcm","clk":"11978080070","pt":1724787893102,"mc":[{"id":"1.232352479","rc":[{"batb":[[0,1.43,93.99],[1,1.03,200],[2,1.02,200]],"ltp":1.5,"tv":226.84,"id":24640635},{"batb":[[0,3,20.2],[1,1.03,200],[2,1.02,200]],"ltp":1.5,"tv":226.84,"id":48610314}]}]}
{"op":"mcm","clk":"11978080819","pt":1724787899194,"mc":[{"id":"1.232352479","rc":[{"batb":[[0,1.44,5],[1,1.43,93.99],[2,1.03,200]],"ltp":1.5,"tv":226.84,"id":24640635},{"batb":[[0,3.05,5],[1,3,20.2],[2,1.03,200]],"ltp":1.5,"tv":226.84,"id":48610314}]}]}
{"op":"mcm","clk":"11978081275","pt":1724787902721,"mc":[{"id":"1.232352479","rc":[{"batb":[[0,1.43,93.99],[1,1.03,200],[2,1.02,200]],"ltp":1.5,"tv":226.84,"id":24640635},{"batb":[[0,3,20.2],[1,1.03,200],[2,1.02,200]],"ltp":1.5,"tv":226.84,"id":48610314}]}]}
{"op":"mcm","clk":"11978081577","pt":1724787905192,"mc":[{"id":"1.232352479","rc":[{"batb":[[0,1.44,5],[1,1.43,93.99],[2,1.03,200]],"ltp":1.5,"tv":226.84,"id":24640635},{"batb":[[0,3.05,5],[1,3,20.2],[2,1.03,200]],"ltp":1.5,"tv":226.84,"id":48610314}]}]}
{"op":"mcm","clk":"11978082030","pt":1724787908595,"mc":[{"id":"1.232352479","rc":[{"batb":[[0,1.43,93.99],[1,1.03,200],[2,1.02,200]],"ltp":1.5,"tv":226.84,"id":24640635},{"batb":[[0,3,20.2],[1,1.03,200],[2,1.02,200]],"ltp":1.5,"tv":226.84,"id":48610314}]}]}
{"op":"mcm","clk":"11978083441","pt":1724787919106,"mc":[{"id":"1.232352479","rc":[{"batb":[[0,1.44,5],[1,1.43,93.99],[2,1.03,200]],"ltp":1.5,"tv":226.84,"id":24640635},{"batb":[[0,3.05,5],[1,3,20.2],[2,1.03,200]],"ltp":1.5,"tv":226.84,"id":48610314}]}]}
{"op":"mcm","clk":"11978083858","pt":1724787922413,"mc":[{"id":"1.232352479","rc":[{"batb":[[0,1.43,93.99],[1,1.03,200],[2,1.02,200]],"ltp":1.5,"tv":226.84,"id":24640635},{"batb":[[0,3,20.2],[1,1.03,200],[2,1.02,200]],"ltp":1.5,"tv":226.84,"id":48610314}]}]}
{"op":"mcm","clk":"11978084352","pt":1724787925731,"mc":[{"id":"1.232352479","rc":[{"batb":[[0,1.44,5],[1,1.43,93.99],[2,1.03,200]],"ltp":1.5,"tv":226.84,"id":24640635},{"batb":[[0,3.05,5],[1,3,20.2],[2,1.03,200]],"ltp":1.5,"tv":226.84,"id":48610314}]}]}
{"op":"mcm","clk":"11978084800","pt":1724787929251,"mc":[{"id":"1.232352479","rc":[{"batb":[[0,1.43,93.99],[1,1.03,200],[2,1.02,200]],"ltp":1.5,"tv":226.84,"id":24640635},{"batb":[[0,3,20.2],[1,1.03,200],[2,1.02,200]],"ltp":1.5,"tv":226.84,"id":48610314}]}]}
{"op":"mcm","clk":"11978086748","pt":1724787944454,"mc":[{"id":"1.232352479","rc":[{"batb":[[0,1.44,5],[1,1.43,93.99],[2,1.03,200]],"ltp":1.5,"tv":226.84,"id":24640635},{"batb":[[0,3.05,5],[1,3,20.2],[2,1.03,200]],"ltp":1.5,"tv":226.84,"id":48610314}]}]}
{"op":"mcm","clk":"11978087157","pt":1724787947758,"mc":[{"id":"1.232352479","rc":[{"batb":[[0,1.43,93.99],[1,1.03,200],[2,1.02,200]],"ltp":1.5,"tv":226.84,"id":24640635},{"batb":[[0,3,20.2],[1,1.03,200],[2,1.02,200]],"ltp":1.5,"tv":226.84,"id":48610314}]}]}
{"op":"mcm","clk":"11978087729","pt":1724787952169,"mc":[{"id":"1.232352479","rc":[{"batb":[[0,1.44,5],[1,1.43,93.99],[2,1.03,200]],"ltp":1.5,"tv":226.84,"id":24640635},{"batb":[[0,3.05,5],[1,3,20.2],[2,1.03,200]],"ltp":1.5,"tv":226.84,"id":48610314}]}]}
{"op":"mcm","clk":"11978088154","pt":1724787955546,"mc":[{"id":"1.232352479","rc":[{"batb":[[0,1.43,93.99],[1,1.03,200],[2,1.02,200]],"ltp":1.5,"tv":226.84,"id":24640635},{"batb":[[0,3,20.2],[1,1.03,200],[2,1.02,200]],"ltp":1.5,"tv":226.84,"id":48610314}]}]}
{"op":"mcm","clk":"11978088802","pt":1724787960727,"mc":[{"id":"1.232352479","rc":[{"batb":[[0,1.44,5],[1,1.43,93.99],[2,1.03,200]],"ltp":1.5,"tv":226.84,"id":24640635},{"batb":[[0,3.05,5],[1,3,20.2],[2,1.03,200]],"ltp":1.5,"tv":226.84,"id":48610314}]}]}
{"op":"mcm","clk":"11978089315","pt":1724787964138,"mc":[{"id":"1.232352479","rc":[{"batb":[[0,1.43,93.99],[1,1.03,200],[2,1.02,200]],"ltp":1.5,"tv":226.84,"id":24640635},{"batb":[[0,3,20.2],[1,1.03,200],[2,1.02,200]],"ltp":1.5,"tv":226.84,"id":48610314}]}]}
{"op":"mcm","clk":"11978089607","pt":1724787966399,"mc":[{"id":"1.232352479","rc":[{"batb":[[0,1.44,5],[1,1.43,93.99],[2,1.03,200]],"ltp":1.5,"tv":226.84,"id":24640635},{"batb":[[0,3.05,5],[1,3,20.2],[2,1.03,200]],"ltp":1.5,"tv":226.84,"id":48610314}]}]}
{"op":"mcm","clk":"11978090094","pt":1724787969943,"mc":[{"id":"1.232352479","rc":[{"batb":[[0,1.43,93.99],[1,1.03,200],[2,1.02,200]],"ltp":1.5,"tv":226.84,"id":24640635},{"batb":[[0,3,20.2],[1,1.03,200],[2,1.02,200]],"ltp":1.5,"tv":226.84,"id":48610314}]}]}
{"op":"mcm","clk":"11978090465","pt":1724787972702,"mc":[{"id":"1.232352479","rc":[{"batb":[[0,1.44,5],[1,1.43,93.99],[2,1.03,200]],"ltp":1.5,"tv":226.84,"id":24640635},{"batb":[[0,3.05,5],[1,3,20.2],[2,1.03,200]],"ltp":1.5,"tv":226.84,"id":48610314}]}]}
{"op":"mcm","clk":"11978090984","pt":1724787976113,"mc":[{"id":"1.232352479","rc":[{"batb":[[0,1.43,93.99],[1,1.03,200],[2,1.02,200]],"ltp":1.5,"tv":226.84,"id":24640635},{"batb":[[0,3,20.2],[1,1.03,200],[2,1.02,200]],"ltp":1.5,"tv":226.84,"id":48610314}]}]}
{"op":"mcm","clk":"11978092114","pt":1724787984535,"mc":[{"id":"1.232352479","rc":[{"batb":[[0,1.44,5],[1,1.43,93.99],[2,1.03,200]],"ltp":1.5,"tv":226.84,"id":24640635},{"batb":[[0,3.05,5],[1,3,20.2],[2,1.03,200]],"ltp":1.5,"tv":226.84,"id":48610314}]}]}
{"op":"mcm","clk":"11978092569","pt":1724787987932,"mc":[{"id":"1.232352479","rc":[{"batb":[[0,1.43,93.99],[1,1.03,200],[2,1.02,200]],"ltp":1.5,"tv":226.84,"id":24640635},{"batb":[[0,3,20.2],[1,1.03,200],[2,1.02,200]],"ltp":1.5,"tv":226.84,"id":48610314}]}]}
{"op":"mcm","clk":"11978093783","pt":1724787997015,"mc":[{"id":"1.232352479","rc":[{"trd":[[1.43,1.5]],"batb":[[0,1.44,5],[1,1.43,93.24],[2,1.03,200]],"ltp":1.43,"tv":228.34,"id":24640635},{"batb":[[0,3.05,5],[1,3,20.2],[2,1.03,200]],"ltp":1.5,"tv":226.84,"id":48610314}],"tv":455.18}]}
{"op":"mcm","clk":"11978094277","pt":1724788000547,"mc":[{"id":"1.232352479","rc":[{"batb":[[0,1.43,93.99],[1,1.03,200],[2,1.02,200]],"ltp":1.43,"tv":228.34,"id":24640635},{"batb":[[0,3,20.2],[1,1.03,200],[2,1.02,200]],"ltp":1.5,"tv":226.84,"id":48610314}]}]}
{"op":"mcm","clk":"11978095245","pt":1724788008209,"mc":[{"id":"1.232352479","rc":[{"batb":[[0,1.44,5],[1,1.43,93.99],[2,1.03,200]],"ltp":1.43,"tv":228.34,"id":24640635},{"batb":[[0,3.05,5],[1,3,20.2],[2,1.03,200]],"ltp":1.5,"tv":226.84,"id":48610314}]}]}
{"op":"mcm","clk":"11978095667","pt":1724788011667,"mc":[{"id":"1.232352479","rc":[{"batb":[[0,1.43,93.99],[1,1.03,200],[2,1.02,200]],"ltp":1.43,"tv":228.34,"id":24640635},{"batb":[[0,3,20.2],[1,1.03,200],[2,1.02,200]],"ltp":1.5,"tv":226.84,"id":48610314}]}]}
{"op":"mcm","clk":"11978096034","pt":1724788014369,"mc":[{"id":"1.232352479","rc":[{"batb":[[0,1.44,5],[1,1.43,93.99],[2,1.03,200]],"ltp":1.43,"tv":228.34,"id":24640635},{"batb":[[0,3.05,5],[1,3,20.2],[2,1.03,200]],"ltp":1.5,"tv":226.84,"id":48610314}]}]}
{"op":"mcm","clk":"11978096484","pt":1724788017772,"mc":[{"id":"1.232352479","rc":[{"batb":[[0,1.43,93.99],[1,1.03,200],[2,1.02,200]],"ltp":1.43,"tv":228.34,"id":24640635},{"batb":[[0,3,20.2],[1,1.03,200],[2,1.02,200]],"ltp":1.5,"tv":226.84,"id":48610314}]}]}
{"op":"mcm","clk":"11978097167","pt":1724788023120,"mc":[{"id":"1.232352479","rc":[{"batb":[[0,1.44,5],[1,1.43,93.99],[2,1.03,200]],"ltp":1.43,"tv":228.34,"id":24640635},{"batb":[[0,3.05,5],[1,3,20.2],[2,1.03,200]],"ltp":1.5,"tv":226.84,"id":48610314}]}]}
{"op":"mcm","clk":"11978097615","pt":1724788026457,"mc":[{"id":"1.232352479","rc":[{"batb":[[0,1.43,93.99],[1,1.03,200],[2,1.02,200]],"ltp":1.43,"tv":228.34,"id":24640635},{"batb":[[0,3,20.2],[1,1.03,200],[2,1.02,200]],"ltp":1.5,"tv":226.84,"id":48610314}]}]}
{"op":"mcm","clk":"11978098524","pt":1724788033172,"mc":[{"id":"1.232352479","rc":[{"batb":[[0,1.44,5],[1,1.43,93.99],[2,1.03,200]],"ltp":1.43,"tv":228.34,"id":24640635},{"batb":[[0,3.05,5],[1,3,20.2],[2,1.03,200]],"ltp":1.5,"tv":226.84,"id":48610314}]}]}
{"op":"mcm","clk":"11978099008","pt":1724788036668,"mc":[{"id":"1.232352479","rc":[{"batb":[[0,1.43,93.99],[1,1.03,200],[2,1.02,200]],"ltp":1.43,"tv":228.34,"id":24640635},{"batb":[[0,3,20.2],[1,1.03,200],[2,1.02,200]],"ltp":1.5,"tv":226.84,"id":48610314}]}]}
{"op":"mcm","clk":"11978099357","pt":1724788039386,"mc":[{"id":"1.232352479","rc":[{"batb":[[0,1.44,5],[1,1.43,93.99],[2,1.03,200]],"ltp":1.43,"tv":228.34,"id":24640635},{"batb":[[0,3.05,5],[1,3,20.2],[2,1.03,200]],"ltp":1.5,"tv":226.84,"id":48610314}]}]}
{"op":"mcm","clk":"11978099693","pt":1724788042278,"mc":[{"id":"1.232352479","rc":[{"trd":[[1.49,0.72]],"ltp":1.49,"tv":229.06,"id":24640635},{"trd":[[3.05,0.35]],"batb":[[0,3.05,4.65]],"ltp":3.05,"tv":227.19,"id":48610314}],"tv":456.25}]}
{"op":"mcm","clk":"11978099759","pt":1724788042797,"mc":[{"id":"1.232352479","rc":[{"batb":[[0,1.43,93.99],[1,1.03,200],[2,1.02,200]],"ltp":1.49,"tv":229.06,"id":24640635},{"batb":[[0,3,20.2],[1,1.03,200],[2,1.02,200]],"ltp":3.05,"tv":227.19,"id":48610314}]}]}
{"op":"mcm","clk":"11978100514","pt":1724788048486,"mc":[{"id":"1.232352479","rc":[{"batb":[[0,1.44,5],[1,1.43,93.99],[2,1.03,200]],"ltp":1.49,"tv":229.06,"id":24640635},{"batb":[[0,3.05,5],[1,3,20.2],[2,1.03,200]],"ltp":3.05,"tv":227.19,"id":48610314}]}]}
{"op":"mcm","clk":"11978100957","pt":1724788051928,"mc":[{"id":"1.232352479","rc":[{"batb":[[0,1.43,93.99],[1,1.03,200],[2,1.02,200]],"ltp":1.49,"tv":229.06,"id":24640635},{"batb":[[0,3,20.2],[1,1.03,200],[2,1.02,200]],"ltp":3.05,"tv":227.19,"id":48610314}]}]}
{"op":"mcm","clk":"11978101380","pt":1724788055547,"mc":[{"id":"1.232352479","rc":[{"batb":[[0,1.44,5],[1,1.43,93.99],[2,1.03,200]],"ltp":1.49,"tv":229.06,"id":24640635},{"batb":[[0,3.05,5],[1,3,20.2],[2,1.03,200]],"ltp":3.05,"tv":227.19,"id":48610314}]}]}
{"op":"mcm","clk":"11978101811","pt":1724788059008,"mc":[{"id":"1.232352479","rc":[{"batb":[[0,1.43,93.99],[1,1.03,200],[2,1.02,200]],"ltp":1.49,"tv":229.06,"id":24640635},{"batb":[[0,3,20.2],[1,1.03,200],[2,1.02,200]],"ltp":3.05,"tv":227.19,"id":48610314}]}]}
{"op":"mcm","clk":"11978102328","pt":1724788063205,"mc":[{"id":"1.232352479","rc":[{"batb":[[0,1.44,5],[1,1.43,93.99],[2,1.03,200]],"ltp":1.49,"tv":229.06,"id":24640635},{"batb":[[0,3.05,5],[1,3,20.2],[2,1.03,200]],"ltp":3.05,"tv":227.19,"id":48610314}]}]}
{"op":"mcm","clk":"11978102724","pt":1724788066613,"mc":[{"id":"1.232352479","rc":[{"batb":[[0,1.43,93.99],[1,1.03,200],[2,1.02,200]],"ltp":1.49,"tv":229.06,"id":24640635},{"batb":[[0,3,20.2],[1,1.03,200],[2,1.02,200]],"ltp":3.05,"tv":227.19,"id":48610314}]}]}
{"op":"mcm","clk":"11978103055","pt":1724788069228,"mc":[{"id":"1.232352479","rc":[{"batb":[[0,1.44,5],[1,1.43,93.99],[2,1.03,200]],"ltp":1.49,"tv":229.06,"id":24640635},{"batb":[[0,3.05,5],[1,3,20.2],[2,1.03,200]],"ltp":3.05,"tv":227.19,"id":48610314}]}]}
{"op":"mcm","clk":"11978103516","pt":1724788072539,"mc":[{"id":"1.232352479","rc":[{"batb":[[0,1.43,93.99],[1,1.03,200],[2,1.02,200]],"ltp":1.49,"tv":229.06,"id":24640635},{"batb":[[0,3,20.2],[1,1.03,200],[2,1.02,200]],"ltp":3.05,"tv":227.19,"id":48610314}]}]}
{"op":"mcm","clk":"11978104244","pt":1724788078765,"mc":[{"id":"1.232352479","rc":[{"batb":[[0,1.44,5],[1,1.43,93.99],[2,1.03,200]],"ltp":1.49,"tv":229.06,"id":24640635},{"batb":[[0,3.05,5],[1,3,20.2],[2,1.03,200]],"ltp":3.05,"tv":227.19,"id":48610314}]}]}
{"op":"mcm","clk":"11978104724","pt":1724788082257,"mc":[{"id":"1.232352479","rc":[{"batb":[[0,1.43,93.99],[1,1.03,200],[2,1.02,200]],"ltp":1.49,"tv":229.06,"id":24640635},{"batb":[[0,3,20.2],[1,1.03,200],[2,1.02,200]],"ltp":3.05,"tv":227.19,"id":48610314}]}]}
{"op":"mcm","clk":"11978105518","pt":1724788088385,"mc":[{"id":"1.232352479","rc":[{"batb":[[0,1.44,5],[1,1.43,93.99],[2,1.03,200]],"ltp":1.49,"tv":229.06,"id":24640635},{"batb":[[0,3.05,5],[1,3,20.2],[2,1.03,200]],"ltp":3.05,"tv":227.19,"id":48610314}]}]}
{"op":"mcm","clk":"11978105991","pt":1724788091996,"mc":[{"id":"1.232352479","rc":[{"batb":[[0,1.43,93.99],[1,1.03,200],[2,1.02,200]],"ltp":1.49,"tv":229.06,"id":24640635},{"batb":[[0,3,20.2],[1,1.03,200],[2,1.02,200]],"ltp":3.05,"tv":227.19,"id":48610314}]}]}
{"op":"mcm","clk":"11978106821","pt":1724788098479,"mc":[{"id":"1.232352479","rc":[{"batb":[[0,1.44,5],[1,1.43,93.99],[2,1.03,200]],"ltp":1.49,"tv":229.06,"id":24640635},{"batb":[[0,3.05,5],[1,3,20.2],[2,1.03,200]],"ltp":3.05,"tv":227.19,"id":48610314}]}]}
{"op":"mcm","clk":"11978107299","pt":1724788102172,"mc":[{"id":"1.232352479","rc":[{"batb":[[0,1.43,93.99],[1,1.03,200],[2,1.02,200]],"ltp":1.49,"tv":229.06,"id":24640635},{"batb":[[0,3,20.2],[1,1.03,200],[2,1.02,200]],"ltp":3.05,"tv":227.19,"id":48610314}]}]}
{"op":"mcm","clk":"11978108851","pt":1724788113709,"mc":[{"id":"1.232352479","rc":[{"batb":[[0,1.44,5],[1,1.43,93.99],[2,1.03,200]],"ltp":1.49,"tv":229.06,"id":24640635},{"batb":[[0,3.05,5],[1,3,20.2],[2,1.03,200]],"ltp":3.05,"tv":227.19,"id":48610314}]}]}
{"op":"mcm","clk":"11978109255","pt":1724788117002,"mc":[{"id":"1.232352479","rc":[{"batb":[[0,1.43,93.99],[1,1.03,200],[2,1.02,200]],"ltp":1.49,"tv":229.06,"id":24640635},{"batb":[[0,3,20.2],[1,1.03,200],[2,1.02,200]],"ltp":3.05,"tv":227.19,"id":48610314}]}]}
{"op":"mcm","clk":"11978111078","pt":1724788130017,"mc":[{"id":"1.232352479","rc":[{"batb":[[0,1.44,5],[1,1.43,93.99],[2,1.03,200]],"ltp":1.49,"tv":229.06,"id":24640635},{"batb":[[0,3.05,5],[1,3,20.2],[2,1.03,200]],"ltp":3.05,"tv":227.19,"id":48610314}]}]}
{"op":"mcm","clk":"11978111569","pt":1724788133650,"mc":[{"id":"1.232352479","rc":[{"batb":[[0,1.43,93.99],[1,1.03,200],[2,1.02,200]],"ltp":1.49,"tv":229.06,"id":24640635},{"batb":[[0,3,20.2],[1,1.03,200],[2,1.02,200]],"ltp":3.05,"tv":227.19,"id":48610314}]}]}
{"op":"mcm","clk":"11978112917","pt":1724788143862,"mc":[{"id":"1.232352479","rc":[{"batb":[[0,1.44,5],[1,1.43,93.99],[2,1.03,200]],"ltp":1.49,"tv":229.06,"id":24640635},{"batb":[[0,3.05,5],[1,3,20.2],[2,1.03,200]],"ltp":3.05,"tv":227.19,"id":48610314}]}]}
{"op":"mcm","clk":"11978113355","pt":1724788147361,"mc":[{"id":"1.232352479","rc":[{"batb":[[0,1.43,93.99],[1,1.03,200],[2,1.02,200]],"ltp":1.49,"tv":229.06,"id":24640635},{"batb":[[0,3,20.2],[1,1.03,200],[2,1.02,200]],"ltp":3.05,"tv":227.19,"id":48610314}]}]}
{"op":"mcm","clk":"11978113764","pt":1724788150583,"mc":[{"id":"1.232352479","rc":[{"batb":[[0,1.44,5],[1,1.43,93.99],[2,1.03,200]],"ltp":1.49,"tv":229.06,"id":24640635},{"batb":[[0,3.05,5],[1,3,20.2],[2,1.03,200]],"ltp":3.05,"tv":227.19,"id":48610314}]}]}
{"op":"mcm","clk":"11978114187","pt":1724788154064,"mc":[{"id":"1.232352479","rc":[{"batb":[[0,1.43,93.99],[1,1.03,200],[2,1.02,200]],"ltp":1.49,"tv":229.06,"id":24640635},{"batb":[[0,3,20.2],[1,1.03,200],[2,1.02,200]],"ltp":3.05,"tv":227.19,"id":48610314}]}]}
{"op":"mcm","clk":"11978117313","pt":1724788175095,"mc":[{"id":"1.232352479","rc":[{"batb":[[0,1.44,5],[1,1.43,93.99],[2,1.03,200]],"ltp":1.49,"tv":229.06,"id":24640635},{"batb":[[0,3.05,5],[1,3,20.2],[2,1.03,200]],"ltp":3.05,"tv":227.19,"id":48610314}]}]}
{"op":"mcm","clk":"11978117798","pt":1724788178522,"mc":[{"id":"1.232352479","rc":[{"batb":[[0,1.43,93.99],[1,1.03,200],[2,1.02,200]],"ltp":1.49,"tv":229.06,"id":24640635},{"batb":[[0,3,20.2],[1,1.03,200],[2,1.02,200]],"ltp":3.05,"tv":227.19,"id":48610314}]}]}
{"op":"mcm","clk":"11978118362","pt":1724788182589,"mc":[{"id":"1.232352479","rc":[{"batb":[[0,1.44,5],[1,1.43,93.99],[2,1.03,200]],"ltp":1.49,"tv":229.06,"id":24640635},{"batb":[[0,3.05,5],[1,3,20.2],[2,1.03,200]],"ltp":3.05,"tv":227.19,"id":48610314}]}]}
{"op":"mcm","clk":"11978118867","pt":1724788186110,"mc":[{"id":"1.232352479","rc":[{"batb":[[0,1.43,93.99],[1,1.03,200],[2,1.02,200]],"ltp":1.49,"tv":229.06,"id":24640635},{"batb":[[0,3,20.2],[1,1.03,200],[2,1.02,200]],"ltp":3.05,"tv":227.19,"id":48610314}]}]}
{"op":"mcm","clk":"11978119874","pt":1724788193523,"mc":[{"id":"1.232352479","rc":[{"batb":[[0,1.44,5],[1,1.43,93.99],[2,1.03,200]],"ltp":1.49,"tv":229.06,"id":24640635},{"batb":[[0,3.05,5],[1,3,20.2],[2,1.03,200]],"ltp":3.05,"tv":227.19,"id":48610314}]}]}
{"op":"mcm","clk":"11978120327","pt":1724788196922,"mc":[{"id":"1.232352479","rc":[{"batb":[[0,1.43,93.99],[1,1.03,200],[2,1.02,200]],"ltp":1.49,"tv":229.06,"id":24640635},{"batb":[[0,3,20.2],[1,1.03,200],[2,1.02,200]],"ltp":3.05,"tv":227.19,"id":48610314}]}]}
{"op":"mcm","clk":"11978121888","pt":1724788208130,"mc":[{"id":"1.232352479","rc":[{"batb":[[0,1.44,5],[1,1.43,93.99],[2,1.03,200]],"ltp":1.49,"tv":229.06,"id":24640635},{"batb":[[0,3.05,5],[1,3,20.2],[2,1.03,200]],"ltp":3.05,"tv":227.19,"id":48610314}]}]}
{"op":"mcm","clk":"11978122357","pt":1724788211747,"mc":[{"id":"1.232352479","rc":[{"batb":[[0,1.43,93.99],[1,1.03,200],[2,1.02,200]],"ltp":1.49,"tv":229.06,"id":24640635},{"batb":[[0,3,20.2],[1,1.03,200],[2,1.02,200]],"ltp":3.05,"tv":227.19,"id":48610314}]}]}
{"op":"mcm","clk":"11978122655","pt":1724788213952,"mc":[{"id":"1.232352479","rc":[{"batb":[[0,1.44,5],[1,1.43,93.99],[2,1.03,200]],"ltp":1.49,"tv":229.06,"id":24640635},{"batb":[[0,3.05,5],[1,3,20.2],[2,1.03,200]],"ltp":3.05,"tv":227.19,"id":48610314}]}]}
{"op":"mcm","clk":"11978123142","pt":1724788217311,"mc":[{"id":"1.232352479","rc":[{"batb":[[0,1.43,93.99],[1,1.03,200],[2,1.02,200]],"ltp":1.49,"tv":229.06,"id":24640635},{"batb":[[0,3,20.2],[1,1.03,200],[2,1.02,200]],"ltp":3.05,"tv":227.19,"id":48610314}]}]}
{"op":"mcm","clk":"11978123399","pt":1724788219448,"mc":[{"id":"1.232352479","rc":[{"batb":[[0,3.05,5],[1,3,20.2],[2,1.03,200]],"ltp":3.05,"tv":227.19,"id":48610314}]}]}
{"op":"mcm","clk":"11978123428","pt":1724788219661,"mc":[{"id":"1.232352479","rc":[{"batb":[[0,1.44,5],[1,1.43,93.99],[2,1.03,200]],"ltp":1.49,"tv":229.06,"id":24640635}]}]}
{"op":"mcm","clk":"11978123884","pt":1724788223064,"mc":[{"id":"1.232352479","rc":[{"batb":[[0,1.43,93.99],[1,1.03,200],[2,1.02,200]],"ltp":1.49,"tv":229.06,"id":24640635},{"batb":[[0,3,20.2],[1,1.03,200],[2,1.02,200]],"ltp":3.05,"tv":227.19,"id":48610314}]}]}
{"op":"mcm","clk":"11978124748","pt":1724788229154,"mc":[{"id":"1.232352479","rc":[{"batb":[[0,1.44,5],[1,1.43,93.99],[2,1.03,200]],"ltp":1.49,"tv":229.06,"id":24640635},{"batb":[[0,3.05,5],[1,3,20.2],[2,1.03,200]],"ltp":3.05,"tv":227.19,"id":48610314}]}]}
{"op":"mcm","clk":"11978125245","pt":1724788232554,"mc":[{"id":"1.232352479","rc":[{"batb":[[0,1.43,93.99],[1,1.03,200],[2,1.02,200]],"ltp":1.49,"tv":229.06,"id":24640635},{"batb":[[0,3,20.2],[1,1.03,200],[2,1.02,200]],"ltp":3.05,"tv":227.19,"id":48610314}]}]}
{"op":"mcm","clk":"11978125890","pt":1724788237481,"mc":[{"id":"1.232352479","rc":[{"batb":[[0,1.44,5],[1,1.43,93.99],[2,1.03,200]],"ltp":1.49,"tv":229.06,"id":24640635},{"batb":[[0,3.05,5],[1,3,20.2],[2,1.03,200]],"ltp":3.05,"tv":227.19,"id":48610314}]}]}
{"op":"mcm","clk":"11978126360","pt":1724788241163,"mc":[{"id":"1.232352479","rc":[{"batb":[[0,1.43,93.99],[1,1.03,200],[2,1.02,200]],"ltp":1.49,"tv":229.06,"id":24640635},{"batb":[[0,3,20.2],[1,1.03,200],[2,1.02,200]],"ltp":3.05,"tv":227.19,"id":48610314}]}]}
{"op":"mcm","clk":"11978127654","pt":1724788250352,"mc":[{"id":"1.232352479","rc":[{"batb":[[0,1.44,5],[1,1.43,93.99],[2,1.03,200]],"ltp":1.49,"tv":229.06,"id":24640635},{"batb":[[0,3.05,5],[1,3,20.2],[2,1.03,200]],"ltp":3.05,"tv":227.19,"id":48610314}]}]}
{"op":"mcm","clk":"11978128067","pt":1724788253784,"mc":[{"id":"1.232352479","rc":[{"batb":[[0,1.43,93.99],[1,1.03,200],[2,1.02,200]],"ltp":1.49,"tv":229.06,"id":24640635},{"batb":[[0,3,20.2],[1,1.03,200],[2,1.02,200]],"ltp":3.05,"tv":227.19,"id":48610314}]}]}
{"op":"mcm","clk":"11978128515","pt":1724788257381,"mc":[{"id":"1.232352479","rc":[{"batb":[[0,1.44,5],[1,1.43,93.99],[2,1.03,200]],"ltp":1.49,"tv":229.06,"id":24640635},{"batb":[[0,3.05,5],[1,3,20.2],[2,1.03,200]],"ltp":3.05,"tv":227.19,"id":48610314}]}]}
{"op":"mcm","clk":"11978128988","pt":1724788260696,"mc":[{"id":"1.232352479","rc":[{"batb":[[0,1.43,93.99],[1,1.03,200],[2,1.02,200]],"ltp":1.49,"tv":229.06,"id":24640635},{"batb":[[0,3,20.2],[1,1.03,200],[2,1.02,200]],"ltp":3.05,"tv":227.19,"id":48610314}]}]}
{"op":"mcm","clk":"11978129381","pt":1724788263601,"mc":[{"id":"1.232352479","rc":[{"batb":[[0,1.44,5],[1,1.43,93.99],[2,1.03,200]],"ltp":1.49,"tv":229.06,"id":24640635},{"batb":[[0,3.05,5],[1,3,20.2],[2,1.03,200]],"ltp":3.05,"tv":227.19,"id":48610314}]}]}
{"op":"mcm","clk":"11978129828","pt":1724788266989,"mc":[{"id":"1.232352479","rc":[{"batb":[[0,1.43,93.99],[1,1.03,200],[2,1.02,200]],"ltp":1.49,"tv":229.06,"id":24640635},{"batb":[[0,3,20.2],[1,1.03,200],[2,1.02,200]],"ltp":3.05,"tv":227.19,"id":48610314}]}]}
{"op":"mcm","clk":"11978130075","pt":1724788269097,"mc":[{"id":"1.232352479","rc":[{"batb":[[0,1.44,5],[1,1.43,93.99],[2,1.03,200]],"ltp":1.49,"tv":229.06,"id":24640635},{"batb":[[0,3.05,5],[1,3,20.2],[2,1.03,200]],"ltp":3.05,"tv":227.19,"id":48610314}]}]}
{"op":"mcm","clk":"11978130479","pt":1724788272487,"mc":[{"id":"1.232352479","rc":[{"batb":[[0,1.43,93.99],[1,1.03,200],[2,1.02,200]],"ltp":1.49,"tv":229.06,"id":24640635},{"batb":[[0,3,20.2],[1,1.03,200],[2,1.02,200]],"ltp":3.05,"tv":227.19,"id":48610314}]}]}
{"op":"mcm","clk":"11978131721","pt":1724788283154,"mc":[{"id":"1.232352479","rc":[{"batb":[[0,1.44,5],[1,1.43,93.99],[2,1.03,200]],"ltp":1.49,"tv":229.06,"id":24640635},{"batb":[[0,3.05,5],[1,3,20.2],[2,1.03,200]],"ltp":3.05,"tv":227.19,"id":48610314}]}]}
{"op":"mcm","clk":"11978132124","pt":1724788286543,"mc":[{"id":"1.232352479","rc":[{"batb":[[0,1.43,93.99],[1,1.03,200],[2,1.02,200]],"ltp":1.49,"tv":229.06,"id":24640635},{"batb":[[0,3,20.2],[1,1.03,200],[2,1.02,200]],"ltp":3.05,"tv":227.19,"id":48610314}]}]}
{"op":"mcm","clk":"11978132474","pt":1724788289747,"mc":[{"id":"1.232352479","rc":[{"batb":[[0,1.44,5],[1,1.43,93.99],[2,1.03,200]],"ltp":1.49,"tv":229.06,"id":24640635},{"batb":[[0,3.05,5],[1,3,20.2],[2,1.03,200]],"ltp":3.05,"tv":227.19,"id":48610314}]}]}
{"op":"mcm","clk":"11978132960","pt":1724788293154,"mc":[{"id":"1.232352479","rc":[{"batb":[[0,1.43,93.99],[1,1.03,200],[2,1.02,200]],"ltp":1.49,"tv":229.06,"id":24640635},{"batb":[[0,3,20.2],[1,1.03,200],[2,1.02,200]],"ltp":3.05,"tv":227.19,"id":48610314}]}]}
{"op":"mcm","clk":"11978133437","pt":1724788296429,"mc":[{"id":"1.232352479","rc":[{"batb":[[0,1.44,5],[1,1.43,93.99],[2,1.03,200]],"ltp":1.49,"tv":229.06,"id":24640635},{"batb":[[0,3.05,5],[1,3,20.2],[2,1.03,200]],"ltp":3.05,"tv":227.19,"id":48610314}]}]}
{"op":"mcm","clk":"11978133910","pt":1724788299930,"mc":[{"id":"1.232352479","rc":[{"batb":[[0,1.43,93.99],[1,1.03,200],[2,1.02,200]],"ltp":1.49,"tv":229.06,"id":24640635},{"batb":[[0,3,20.2],[1,1.03,200],[2,1.02,200]],"ltp":3.05,"tv":227.19,"id":48610314}]}]}
{"op":"mcm","clk":"11978134377","pt":1724788303856,"mc":[{"id":"1.232352479","rc":[{"batb":[[0,1.44,5],[1,1.43,93.99],[2,1.03,200]],"ltp":1.49,"tv":229.06,"id":24640635},{"batb":[[0,3.05,5],[1,3,20.2],[2,1.03,200]],"ltp":3.05,"tv":227.19,"id":48610314}]}]}
{"op":"mcm","clk":"11978134826","pt":1724788307224,"mc":[{"id":"1.232352479","rc":[{"batb":[[0,1.43,93.99],[1,1.03,200],[2,1.02,200]],"ltp":1.49,"tv":229.06,"id":24640635},{"batb":[[0,3,20.2],[1,1.03,200],[2,1.02,200]],"ltp":3.05,"tv":227.19,"id":48610314}]}]}
{"op":"mcm","clk":"11978135846","pt":1724788315635,"mc":[{"id":"1.232352479","rc":[{"batb":[[0,1.44,5],[1,1.43,93.99],[2,1.03,200]],"ltp":1.49,"tv":229.06,"id":24640635},{"batb":[[0,3.05,5],[1,3,20.2],[2,1.03,200]],"ltp":3.05,"tv":227.19,"id":48610314}]}]}
{"op":"mcm","clk":"11978136275","pt":1724788319137,"mc":[{"id":"1.232352479","rc":[{"batb":[[0,1.43,93.99],[1,1.03,200],[2,1.02,200]],"ltp":1.49,"tv":229.06,"id":24640635},{"batb":[[0,3,20.2],[1,1.03,200],[2,1.02,200]],"ltp":3.05,"tv":227.19,"id":48610314}]}]}
{"op":"mcm","clk":"11978137395","pt":1724788328337,"mc":[{"id":"1.232352479","rc":[{"batb":[[0,1.44,5],[1,1.43,93.99],[2,1.03,200]],"ltp":1.49,"tv":229.06,"id":24640635},{"batb":[[0,3.05,5],[1,3,20.2],[2,1.03,200]],"ltp":3.05,"tv":227.19,"id":48610314}]}]}
{"op":"mcm","clk":"11978137925","pt":1724788331965,"mc":[{"id":"1.232352479","rc":[{"batb":[[0,1.43,93.99],[1,1.03,200],[2,1.02,200]],"ltp":1.49,"tv":229.06,"id":24640635},{"batb":[[0,3,20.2],[1,1.03,200],[2,1.02,200]],"ltp":3.05,"tv":227.19,"id":48610314}]}]}
{"op":"mcm","clk":"11978138869","pt":1724788339164,"mc":[{"id":"1.232352479","rc":[{"batb":[[0,1.44,5],[1,1.43,93.99],[2,1.03,200]],"ltp":1.49,"tv":229.06,"id":24640635},{"batb":[[0,3.05,5],[1,3,20.2],[2,1.03,200]],"ltp":3.05,"tv":227.19,"id":48610314}]}]}
{"op":"mcm","clk":"11978139311","pt":1724788342785,"mc":[{"id":"1.232352479","rc":[{"batb":[[0,1.43,93.99],[1,1.03,200],[2,1.02,200]],"ltp":1.49,"tv":229.06,"id":24640635},{"batb":[[0,3,20.2],[1,1.03,200],[2,1.02,200]],"ltp":3.05,"tv":227.19,"id":48610314}]}]}
{"op":"mcm","clk":"11978139821","pt":1724788346707,"mc":[{"id":"1.232352479","rc":[{"batb":[[0,1.44,5],[1,1.43,93.99],[2,1.03,200]],"ltp":1.49,"tv":229.06,"id":24640635},{"batb":[[0,3.05,5],[1,3,20.2],[2,1.03,200]],"ltp":3.05,"tv":227.19,"id":48610314}]}]}
{"op":"mcm","clk":"11978140237","pt":1724788350267,"mc":[{"id":"1.232352479","rc":[{"batb":[[0,1.43,93.99],[1,1.03,200],[2,1.02,200]],"ltp":1.49,"tv":229.06,"id":24640635},{"batb":[[0,3,20.2],[1,1.03,200],[2,1.02,200]],"ltp":3.05,"tv":227.19,"id":48610314}]}]}
{"op":"mcm","clk":"11978140702","pt":1724788353887,"mc":[{"id":"1.232352479","rc":[{"batb":[[0,1.44,5],[1,1.43,93.99],[2,1.03,200]],"ltp":1.49,"tv":229.06,"id":24640635},{"batb":[[0,3.05,5],[1,3,20.2],[2,1.03,200]],"ltp":3.05,"tv":227.19,"id":48610314}]}]}
{"op":"mcm","clk":"11978141145","pt":1724788357403,"mc":[{"id":"1.232352479","rc":[{"batb":[[0,1.43,93.99],[1,1.03,200],[2,1.02,200]],"ltp":1.49,"tv":229.06,"id":24640635},{"batb":[[0,3,20.2],[1,1.03,200],[2,1.02,200]],"ltp":3.05,"tv":227.19,"id":48610314}]}]}
{"op":"mcm","clk":"11978141626","pt":1724788361195,"mc":[{"id":"1.232352479","rc":[{"batb":[[0,1.44,5],[1,1.43,93.99],[2,1.03,200]],"ltp":1.49,"tv":229.06,"id":24640635},{"batb":[[0,3.05,5],[1,3,20.2],[2,1.03,200]],"ltp":3.05,"tv":227.19,"id":48610314}]}]}
{"op":"mcm","clk":"11978142075","pt":1724788364602,"mc":[{"id":"1.232352479","rc":[{"batb":[[0,1.43,93.99],[1,1.03,200],[2,1.02,200]],"ltp":1.49,"tv":229.06,"id":24640635},{"batb":[[0,3,20.2],[1,1.03,200],[2,1.02,200]],"ltp":3.05,"tv":227.19,"id":48610314}]}]}
{"op":"mcm","clk":"11978142782","pt":1724788370112,"mc":[{"id":"1.232352479","rc":[{"batb":[[0,1.44,5],[1,1.43,93.99],[2,1.03,200]],"ltp":1.49,"tv":229.06,"id":24640635},{"batb":[[0,3.05,5],[1,3,20.2],[2,1.03,200]],"ltp":3.05,"tv":227.19,"id":48610314}]}]}
{"op":"mcm","clk":"11978143205","pt":1724788373481,"mc":[{"id":"1.232352479","rc":[{"batb":[[0,1.43,93.99],[1,1.03,200],[2,1.02,200]],"ltp":1.49,"tv":229.06,"id":24640635},{"batb":[[0,3,20.2],[1,1.03,200],[2,1.02,200]],"ltp":3.05,"tv":227.19,"id":48610314}]}]}
{"op":"mcm","clk":"11978143981","pt":1724788379819,"mc":[{"id":"1.232352479","rc":[{"batb":[[0,1.44,5],[1,1.43,93.99],[2,1.03,200]],"ltp":1.49,"tv":229.06,"id":24640635},{"batb":[[0,3.05,5],[1,3,20.2],[2,1.03,200]],"ltp":3.05,"tv":227.19,"id":48610314}]}]}
{"op":"mcm","clk":"11978144421","pt":1724788383199,"mc":[{"id":"1.232352479","rc":[{"batb":[[0,1.43,93.99],[1,1.03,200],[2,1.02,200]],"ltp":1.49,"tv":229.06,"id":24640635},{"batb":[[0,3,20.2],[1,1.03,200],[2,1.02,200]],"ltp":3.05,"tv":227.19,"id":48610314}]}]}
{"op":"mcm","clk":"11978145681","pt":1724788393346,"mc":[{"id":"1.232352479","rc":[{"batb":[[0,1.45,5],[1,1.44,4.61],[2,1.43,93.99]],"ltp":1.49,"tv":229.06,"id":24640635},{"batb":[[0,3.05,5],[1,3,20.2],[2,1.03,200]],"ltp":3.05,"tv":227.19,"id":48610314}]}]}
{"op":"mcm","clk":"11978146045","pt":1724788396523,"mc":[{"id":"1.232352479","rc":[{"batb":[[0,1.44,4.61],[1,1.43,93.99],[2,1.03,200]],"ltp":1.49,"tv":229.06,"id":24640635}]}]}
{"op":"mcm","clk":"11978146062","pt":1724788396619,"mc":[{"id":"1.232352479","rc":[{"batb":[[0,3,20.2],[1,1.03,200],[2,1.02,200]],"ltp":3.05,"tv":227.19,"id":48610314}]}]}
{"op":"mcm","clk":"11978146765","pt":1724788402145,"mc":[{"id":"1.232352479","rc":[{"batb":[[0,1.45,5],[1,1.44,4.61],[2,1.43,93.99]],"ltp":1.49,"tv":229.06,"id":24640635},{"batb":[[0,3.05,5],[1,3,20.2],[2,1.03,200]],"ltp":3.05,"tv":227.19,"id":48610314}]}]}
{"op":"mcm","clk":"11978147185","pt":1724788405718,"mc":[{"id":"1.232352479","rc":[{"batb":[[0,1.44,4.61],[1,1.43,93.99],[2,1.03,200]],"ltp":1.49,"tv":229.06,"id":24640635},{"batb":[[0,3,20.2],[1,1.03,200],[2,1.02,200]],"ltp":3.05,"tv":227.19,"id":48610314}]}]}
{"op":"mcm","clk":"11978147533","pt":1724788408658,"mc":[{"id":"1.232352479","rc":[{"batb":[[0,1.45,5],[1,1.44,4.61],[2,1.43,93.99]],"ltp":1.49,"tv":229.06,"id":24640635},{"batb":[[0,3.05,5],[1,3,20.2],[2,1.03,200]],"ltp":3.05,"tv":227.19,"id":48610314}]}]}
{"op":"mcm","clk":"11978147974","pt":1724788412142,"mc":[{"id":"1.232352479","rc":[{"batb":[[0,1.44,4.61],[1,1.43,93.99],[2,1.03,200]],"ltp":1.49,"tv":229.06,"id":24640635},{"batb":[[0,3,20.2],[1,1.03,200],[2,1.02,200]],"ltp":3.05,"tv":227.19,"id":48610314}]}]}
{"op":"mcm","clk":"11978148516","pt":1724788416175,"mc":[{"id":"1.232352479","rc":[{"batb":[[0,1.45,5],[1,1.44,4.61],[2,1.43,93.99]],"ltp":1.49,"tv":229.06,"id":24640635},{"batb":[[0,3.05,5],[1,3,20.2],[2,1.03,200]],"ltp":3.05,"tv":227.19,"id":48610314}]}]}
{"op":"mcm","clk":"11978148923","pt":1724788419754,"mc":[{"id":"1.232352479","rc":[{"batb":[[0,1.44,4.61],[1,1.43,93.99],[2,1.03,200]],"ltp":1.49,"tv":229.06,"id":24640635},{"batb":[[0,3,20.2],[1,1.03,200],[2,1.02,200]],"ltp":3.05,"tv":227.19,"id":48610314}]}]}
{"op":"mcm","clk":"11978149422","pt":1724788423379,"mc":[{"id":"1.232352479","rc":[{"batb":[[0,1.45,5],[1,1.44,4.61],[2,1.43,93.99]],"ltp":1.49,"tv":229.06,"id":24640635},{"batb":[[0,3.05,5],[1,3,20.2],[2,1.03,200]],"ltp":3.05,"tv":227.19,"id":48610314}]}]}
{"op":"mcm","clk":"11978149787","pt":1724788426679,"mc":[{"id":"1.232352479","rc":[{"batb":[[0,1.44,4.61],[1,1.43,93.99],[2,1.03,200]],"ltp":1.49,"tv":229.06,"id":24640635},{"batb":[[0,3,20.2],[1,1.03,200],[2,1.02,200]],"ltp":3.05,"tv":227.19,"id":48610314}]}]}
{"op":"mcm","clk":"11978150540","pt":1724788433841,"mc":[{"id":"1.232352479","rc":[{"batb":[[0,1.45,5],[1,1.44,4.61],[2,1.43,93.99]],"ltp":1.49,"tv":229.06,"id":24640635},{"batb":[[0,3.05,5],[1,3,20.2],[2,1.03,200]],"ltp":3.05,"tv":227.19,"id":48610314}]}]}
{"op":"mcm","clk":"11978150985","pt":1724788437458,"mc":[{"id":"1.232352479","rc":[{"batb":[[0,1.44,4.61],[1,1.43,93.99],[2,1.03,200]],"ltp":1.49,"tv":229.06,"id":24640635},{"batb":[[0,3,20.2],[1,1.03,200],[2,1.02,200]],"ltp":3.05,"tv":227.19,"id":48610314}]}]}
{"op":"mcm","clk":"11978151476","pt":1724788441482,"mc":[{"id":"1.232352479","rc":[{"batb":[[0,1.45,5],[1,1.44,4.61],[2,1.43,93.99]],"ltp":1.49,"tv":229.06,"id":24640635},{"batb":[[0,3.05,5],[1,3,20.2],[2,1.03,200]],"ltp":3.05,"tv":227.19,"id":48610314}]}]}
{"op":"mcm","clk":"11978151870","pt":1724788444856,"mc":[{"id":"1.232352479","rc":[{"batb":[[0,1.44,4.61],[1,1.43,93.99],[2,1.03,200]],"ltp":1.49,"tv":229.06,"id":24640635},{"batb":[[0,3,20.2],[1,1.03,200],[2,1.02,200]],"ltp":3.05,"tv":227.19,"id":48610314}]}]}
{"op":"mcm","clk":"11978152164","pt":1724788447476,"mc":[{"id":"1.232352479","rc":[{"batb":[[0,1.45,5],[1,1.44,4.61],[2,1.43,93.99]],"ltp":1.49,"tv":229.06,"id":24640635},{"batb":[[0,3.05,5],[1,3,20.2],[2,1.03,200]],"ltp":3.05,"tv":227.19,"id":48610314}]}]}
{"op":"mcm","clk":"11978152565","pt":1724788451049,"mc":[{"id":"1.232352479","rc":[{"batb":[[0,1.44,4.61],[1,1.43,93.99],[2,1.03,200]],"ltp":1.49,"tv":229.06,"id":24640635},{"batb":[[0,3,20.2],[1,1.03,200],[2,1.02,200]],"ltp":3.05,"tv":227.19,"id":48610314}]}]}
{"op":"mcm","clk":"11978153018","pt":1724788455091,"mc":[{"id":"1.232352479","rc":[{"batb":[[0,1.45,5],[1,1.44,4.61],[2,1.43,93.99]],"ltp":1.49,"tv":229.06,"id":24640635},{"batb":[[0,3.05,5],[1,3,20.2],[2,1.03,200]],"ltp":3.05,"tv":227.19,"id":48610314}]}]}
{"op":"mcm","clk":"11978153395","pt":1724788458384,"mc":[{"id":"1.232352479","rc":[{"batb":[[0,1.44,4.61],[1,1.43,93.99],[2,1.03,200]],"ltp":1.49,"tv":229.06,"id":24640635},{"batb":[[0,3,20.2],[1,1.03,200],[2,1.02,200]],"ltp":3.05,"tv":227.19,"id":48610314}]}]}
{"op":"mcm","clk":"11978154072","pt":1724788463497,"mc":[{"id":"1.232352479","rc":[{"batb":[[0,1.45,5],[1,1.44,4.61],[2,1.43,93.99]],"ltp":1.49,"tv":229.06,"id":24640635},{"batb":[[0,3.05,5],[1,3,20.2],[2,1.03,200]],"ltp":3.05,"tv":227.19,"id":48610314}]}]}
{"op":"mcm","clk":"11978154456","pt":1724788466699,"mc":[{"id":"1.232352479","rc":[{"batb":[[0,1.44,4.61],[1,1.43,93.99],[2,1.03,200]],"ltp":1.49,"tv":229.06,"id":24640635},{"batb":[[0,3,20.2],[1,1.03,200],[2,1.02,200]],"ltp":3.05,"tv":227.19,"id":48610314}]}]}
{"op":"mcm","clk":"11978154869","pt":1724788470310,"mc":[{"id":"1.232352479","rc":[{"batb":[[0,1.45,5],[1,1.44,4.61],[2,1.43,93.99]],"ltp":1.49,"tv":229.06,"id":24640635},{"batb":[[0,3.05,5],[1,3,20.2],[2,1.03,200]],"ltp":3.05,"tv":227.19,"id":48610314}]}]}
{"op":"mcm","clk":"11978155228","pt":1724788473719,"mc":[{"id":"1.232352479","rc":[{"batb":[[0,1.44,4.61],[1,1.43,93.99],[2,1.03,200]],"ltp":1.49,"tv":229.06,"id":24640635},{"batb":[[0,3,20.2],[1,1.03,200],[2,1.02,200]],"ltp":3.05,"tv":227.19,"id":48610314}]}]}
{"op":"mcm","clk":"11978155661","pt":1724788477326,"mc":[{"id":"1.232352479","rc":[{"batb":[[0,1.45,5],[1,1.44,4.61],[2,1.43,93.99]],"ltp":1.49,"tv":229.06,"id":24640635},{"batb":[[0,3.05,5],[1,3,20.2],[2,1.03,200]],"ltp":3.05,"tv":227.19,"id":48610314}]}]}
{"op":"mcm","clk":"11978156056","pt":1724788480832,"mc":[{"id":"1.232352479","rc":[{"batb":[[0,1.44,4.61],[1,1.43,93.99],[2,1.03,200]],"ltp":1.49,"tv":229.06,"id":24640635},{"batb":[[0,3,20.2],[1,1.03,200],[2,1.02,200]],"ltp":3.05,"tv":227.19,"id":48610314}]}]}
{"op":"mcm","clk":"11978156323","pt":1724788483223,"mc":[{"id":"1.232352479","rc":[{"batb":[[0,1.45,5],[1,1.44,4.61],[2,1.43,93.99]],"ltp":1.49,"tv":229.06,"id":24640635},{"batb":[[0,3.05,5],[1,3,20.2],[2,1.03,200]],"ltp":3.05,"tv":227.19,"id":48610314}]}]}
{"op":"mcm","clk":"11978156663","pt":1724788486824,"mc":[{"id":"1.232352479","rc":[{"batb":[[0,1.44,4.61],[1,1.43,93.99],[2,1.03,200]],"ltp":1.49,"tv":229.06,"id":24640635},{"batb":[[0,3,20.2],[1,1.03,200],[2,1.02,200]],"ltp":3.05,"tv":227.19,"id":48610314}]}]}
{"op":"mcm","clk":"11978156921","pt":1724788489236,"mc":[{"id":"1.232352479","rc":[{"batb":[[0,1.45,5],[1,1.44,4.61],[2,1.43,93.99]],"ltp":1.49,"tv":229.06,"id":24640635},{"batb":[[0,3.05,5],[1,3,20.2],[2,1.03,200]],"ltp":3.05,"tv":227.19,"id":48610314}]}]}
{"op":"mcm","clk":"11978157289","pt":1724788492732,"mc":[{"id":"1.232352479","rc":[{"batb":[[0,1.44,4.61],[1,1.43,93.99],[2,1.03,200]],"ltp":1.49,"tv":229.06,"id":24640635},{"batb":[[0,3,20.2],[1,1.03,200],[2,1.02,200]],"ltp":3.05,"tv":227.19,"id":48610314}]}]}
{"op":"mcm","clk":"11978157764","pt":1724788497019,"mc":[{"id":"1.232352479","rc":[{"batb":[[0,1.45,5],[1,1.44,4.61],[2,1.43,93.99]],"ltp":1.49,"tv":229.06,"id":24640635},{"batb":[[0,3.05,5],[1,3,20.2],[2,1.03,200]],"ltp":3.05,"tv":227.19,"id":48610314}]}]}
{"op":"mcm","clk":"11978158143","pt":1724788500629,"mc":[{"id":"1.232352479","rc":[{"batb":[[0,1.44,4.61],[1,1.43,93.99],[2,1.03,200]],"ltp":1.49,"tv":229.06,"id":24640635},{"batb":[[0,3,20.2],[1,1.03,200],[2,1.02,200]],"ltp":3.05,"tv":227.19,"id":48610314}]}]}
{"op":"mcm","clk":"11978158546","pt":1724788504248,"mc":[{"id":"1.232352479","rc":[{"batb":[[0,1.45,5],[1,1.44,4.61],[2,1.43,93.99]],"ltp":1.49,"tv":229.06,"id":24640635},{"batb":[[0,3.05,5],[1,3,20.2],[2,1.03,200]],"ltp":3.05,"tv":227.19,"id":48610314}]}]}
{"op":"mcm","clk":"11978158977","pt":1724788507747,"mc":[{"id":"1.232352479","rc":[{"batb":[[0,1.44,4.61],[1,1.43,93.99],[2,1.03,200]],"ltp":1.49,"tv":229.06,"id":24640635},{"batb":[[0,3,20.2],[1,1.03,200],[2,1.02,200]],"ltp":3.05,"tv":227.19,"id":48610314}]}]}
{"op":"mcm","clk":"11978159482","pt":1724788512133,"mc":[{"id":"1.232352479","rc":[{"batb":[[0,1.45,5],[1,1.44,4.61],[2,1.43,93.99]],"ltp":1.49,"tv":229.06,"id":24640635},{"batb":[[0,3.05,5],[1,3,20.2],[2,1.03,200]],"ltp":3.05,"tv":227.19,"id":48610314}]}]}
{"op":"mcm","clk":"11978159882","pt":1724788515529,"mc":[{"id":"1.232352479","rc":[{"batb":[[0,1.44,4.61],[1,1.43,93.99],[2,1.03,200]],"ltp":1.49,"tv":229.06,"id":24640635}]}]}
{"op":"mcm","clk":"11978159897","pt":1724788515634,"mc":[{"id":"1.232352479","rc":[{"batb":[[0,3,20.2],[1,1.03,200],[2,1.02,200]],"ltp":3.05,"tv":227.19,"id":48610314}]}]}
{"op":"mcm","clk":"11978160329","pt":1724788519351,"mc":[{"id":"1.232352479","rc":[{"batb":[[0,1.45,5],[1,1.44,4.61],[2,1.43,93.99]],"ltp":1.49,"tv":229.06,"id":24640635},{"batb":[[0,3.05,5],[1,3,20.2],[2,1.03,200]],"ltp":3.05,"tv":227.19,"id":48610314}]}]}
{"op":"mcm","clk":"11978160701","pt":1724788522662,"mc":[{"id":"1.232352479","rc":[{"batb":[[0,1.44,4.61],[1,1.43,93.99],[2,1.03,200]],"ltp":1.49,"tv":229.06,"id":24640635},{"batb":[[0,3,20.2],[1,1.03,200],[2,1.02,200]],"ltp":3.05,"tv":227.19,"id":48610314}]}]}
{"op":"mcm","clk":"11978160971","pt":1724788525063,"mc":[{"id":"1.232352479","rc":[{"batb":[[0,1.45,5],[1,1.44,4.61],[2,1.43,93.99]],"ltp":1.49,"tv":229.06,"id":24640635},{"batb":[[0,3.05,5],[1,3,20.2],[2,1.03,200]],"ltp":3.05,"tv":227.19,"id":48610314}]}]}
{"op":"mcm","clk":"11978161361","pt":1724788528237,"mc":[{"id":"1.232352479","rc":[{"batb":[[0,1.44,4.61],[1,1.43,93.99],[2,1.03,200]],"ltp":1.49,"tv":229.06,"id":24640635}]}]}
{"op":"mcm","clk":"11978161418","pt":1724788528756,"mc":[{"id":"1.232352479","rc":[{"batb":[[0,3,20.2],[1,1.03,200],[2,1.02,200]],"ltp":3.05,"tv":227.19,"id":48610314}]}]}
{"op":"mcm","clk":"11978161905","pt":1724788532544,"mc":[{"id":"1.232352479","rc":[{"batb":[[0,1.45,5],[1,1.44,4.61],[2,1.43,93.99]],"ltp":1.49,"tv":229.06,"id":24640635},{"batb":[[0,3.05,5],[1,3,20.2],[2,1.03,200]],"ltp":3.05,"tv":227.19,"id":48610314}]}]}
{"op":"mcm","clk":"11978162347","pt":1724788535958,"mc":[{"id":"1.232352479","rc":[{"batb":[[0,1.44,4.61],[1,1.43,93.99],[2,1.03,200]],"ltp":1.49,"tv":229.06,"id":24640635},{"batb":[[0,3,20.2],[1,1.03,200],[2,1.02,200]],"ltp":3.05,"tv":227.19,"id":48610314}]}]}
{"op":"mcm","clk":"11978162781","pt":1724788539669,"mc":[{"id":"1.232352479","rc":[{"batb":[[0,1.45,5],[1,1.44,4.61],[2,1.43,93.99]],"ltp":1.49,"tv":229.06,"id":24640635},{"batb":[[0,3.05,5],[1,3,20.2],[2,1.03,200]],"ltp":3.05,"tv":227.19,"id":48610314}]}]}
{"op":"mcm","clk":"11978163178","pt":1724788542977,"mc":[{"id":"1.232352479","rc":[{"batb":[[0,1.44,4.61],[1,1.43,93.99],[2,1.03,200]],"ltp":1.49,"tv":229.06,"id":24640635},{"batb":[[0,3,20.2],[1,1.03,200],[2,1.02,200]],"ltp":3.05,"tv":227.19,"id":48610314}]}]}
{"op":"mcm","clk":"11978164680","pt":1724788556085,"mc":[{"id":"1.232352479","rc":[{"batb":[[0,1.45,5],[1,1.44,4.61],[2,1.43,93.99]],"ltp":1.49,"tv":229.06,"id":24640635},{"batb":[[0,3.05,5],[1,3,20.2],[2,1.03,200]],"ltp":3.05,"tv":227.19,"id":48610314}]}]}
{"op":"mcm","clk":"11978165066","pt":1724788559388,"mc":[{"id":"1.232352479","rc":[{"batb":[[0,1.44,4.61],[1,1.43,93.99],[2,1.03,200]],"ltp":1.49,"tv":229.06,"id":24640635},{"batb":[[0,3,20.2],[1,1.03,200],[2,1.02,200]],"ltp":3.05,"tv":227.19,"id":48610314}]}]}
{"op":"mcm","clk":"11978165726","pt":1724788564714,"mc":[{"id":"1.232352479","rc":[{"batb":[[0,1.45,5],[1,1.44,4.61],[2,1.43,93.99]],"ltp":1.49,"tv":229.06,"id":24640635},{"batb":[[0,3.05,5],[1,3,20.2],[2,1.03,200]],"ltp":3.05,"tv":227.19,"id":48610314}]}]}
{"op":"mcm","clk":"11978166167","pt":1724788568207,"mc":[{"id":"1.232352479","rc":[{"batb":[[0,1.44,4.61],[1,1.43,93.99],[2,1.03,200]],"ltp":1.49,"tv":229.06,"id":24640635},{"batb":[[0,3,20.2],[1,1.03,200],[2,1.02,200]],"ltp":3.05,"tv":227.19,"id":48610314}]}]}
{"op":"mcm","clk":"11978167270","pt":1724788577290,"mc":[{"id":"1.232352479","rc":[{"batb":[[0,1.45,5],[1,1.44,4.61],[2,1.43,93.99]],"ltp":1.49,"tv":229.06,"id":24640635},{"batb":[[0,3.05,5],[1,3,20.2],[2,1.03,200]],"ltp":3.05,"tv":227.19,"id":48610314}]}]}
{"op":"mcm","clk":"11978167719","pt":1724788580809,"mc":[{"id":"1.232352479","rc":[{"batb":[[0,1.44,4.61],[1,1.43,93.99],[2,1.03,200]],"ltp":1.49,"tv":229.06,"id":24640635},{"batb":[[0,3,20.2],[1,1.03,200],[2,1.02,200]],"ltp":3.05,"tv":227.19,"id":48610314}]}]}
{"op":"mcm","clk":"11978168152","pt":1724788584128,"mc":[{"id":"1.232352479","rc":[{"batb":[[0,1.45,5],[1,1.44,4.61],[2,1.43,93.99]],"ltp":1.49,"tv":229.06,"id":24640635},{"batb":[[0,3.05,5],[1,3,20.2],[2,1.03,200]],"ltp":3.05,"tv":227.19,"id":48610314}]}]}
{"op":"mcm","clk":"11978168597","pt":1724788587709,"mc":[{"id":"1.232352479","rc":[{"batb":[[0,1.44,4.61],[1,1.43,93.99],[2,1.03,200]],"ltp":1.49,"tv":229.06,"id":24640635},{"batb":[[0,3,20.2],[1,1.03,200],[2,1.02,200]],"ltp":3.05,"tv":227.19,"id":48610314}]}]}
{"op":"mcm","clk":"11978168994","pt":1724788591125,"mc":[{"id":"1.232352479","rc":[{"batb":[[0,1.45,5],[1,1.44,4.61],[2,1.43,93.99]],"ltp":1.49,"tv":229.06,"id":24640635},{"batb":[[0,3.05,5],[1,3,20.2],[2,1.03,200]],"ltp":3.05,"tv":227.19,"id":48610314}]}]}
{"op":"mcm","clk":"11978169430","pt":1724788594614,"mc":[{"id":"1.232352479","rc":[{"batb":[[0,1.44,4.61],[1,1.43,93.99],[2,1.03,200]],"ltp":1.49,"tv":229.06,"id":24640635},{"batb":[[0,3,20.2],[1,1.03,200],[2,1.02,200]],"ltp":3.05,"tv":227.19,"id":48610314}]}]}
{"op":"mcm","clk":"11978172856","pt":1724788622361,"mc":[{"id":"1.232352479","rc":[{"batb":[[0,1.45,5],[1,1.44,4.61],[2,1.43,93.99]],"ltp":1.49,"tv":229.06,"id":24640635},{"batb":[[0,3.05,5],[1,3,20.2],[2,1.03,200]],"ltp":3.05,"tv":227.19,"id":48610314}]}]}
{"op":"mcm","clk":"11978173297","pt":1724788625744,"mc":[{"id":"1.232352479","rc":[{"batb":[[0,1.44,4.61],[1,1.43,93.99],[2,1.03,200]],"ltp":1.49,"tv":229.06,"id":24640635},{"batb":[[0,3,20.2],[1,1.03,200],[2,1.02,200]],"ltp":3.05,"tv":227.19,"id":48610314}]}]}
{"op":"mcm","clk":"11978173997","pt":1724788630842,"mc":[{"id":"1.232352479","rc":[{"batb":[[0,1.45,5],[1,1.44,4.61],[2,1.43,93.99]],"ltp":1.49,"tv":229.06,"id":24640635},{"batb":[[0,3.05,5],[1,3,20.2],[2,1.03,200]],"ltp":3.05,"tv":227.19,"id":48610314}]}]}
{"op":"mcm","clk":"11978174461","pt":1724788634257,"mc":[{"id":"1.232352479","rc":[{"batb":[[0,1.44,4.61],[1,1.43,93.99],[2,1.03,200]],"ltp":1.49,"tv":229.06,"id":24640635},{"batb":[[0,3,20.2],[1,1.03,200],[2,1.02,200]],"ltp":3.05,"tv":227.19,"id":48610314}]}]}
{"op":"mcm","clk":"11978174765","pt":1724788636574,"mc":[{"id":"1.232352479","rc":[{"batb":[[0,1.45,5],[1,1.44,4.61],[2,1.43,93.99]],"ltp":1.49,"tv":229.06,"id":24640635},{"batb":[[0,3.05,5],[1,3,20.2],[2,1.03,200]],"ltp":3.05,"tv":227.19,"id":48610314}]}]}
{"op":"mcm","clk":"11978175184","pt":1724788639865,"mc":[{"id":"1.232352479","rc":[{"batb":[[0,1.44,4.61],[1,1.43,93.99],[2,1.03,200]],"ltp":1.49,"tv":229.06,"id":24640635},{"batb":[[0,3,20.2],[1,1.03,200],[2,1.02,200]],"ltp":3.05,"tv":227.19,"id":48610314}]}]}
{"op":"mcm","clk":"11978175976","pt":1724788645582,"mc":[{"id":"1.232352479","rc":[{"batb":[[0,1.45,5],[1,1.44,4.61],[2,1.43,93.99]],"ltp":1.49,"tv":229.06,"id":24640635},{"batb":[[0,3.05,5],[1,3,20.2],[2,1.03,200]],"ltp":3.05,"tv":227.19,"id":48610314}]}]}
{"op":"mcm","clk":"11978176506","pt":1724788648964,"mc":[{"id":"1.232352479","rc":[{"batb":[[0,1.44,4.61],[1,1.43,93.99],[2,1.03,200]],"ltp":1.49,"tv":229.06,"id":24640635},{"batb":[[0,3,20.2],[1,1.03,200],[2,1.02,200]],"ltp":3.05,"tv":227.19,"id":48610314}]}]}
{"op":"mcm","clk":"11978177033","pt":1724788652469,"mc":[{"id":"1.232352479","rc":[{"batb":[[0,1.45,5],[1,1.44,4.61],[2,1.43,93.99]],"ltp":1.49,"tv":229.06,"id":24640635},{"batb":[[0,3.05,5],[1,3,20.2],[2,1.03,200]],"ltp":3.05,"tv":227.19,"id":48610314}]}]}
{"op":"mcm","clk":"11978177545","pt":1724788655958,"mc":[{"id":"1.232352479","rc":[{"batb":[[0,1.44,4.61],[1,1.43,93.99],[2,1.03,200]],"ltp":1.49,"tv":229.06,"id":24640635},{"batb":[[0,3,20.2],[1,1.03,200],[2,1.02,200]],"ltp":3.05,"tv":227.19,"id":48610314}]}]}
{"op":"mcm","clk":"11978178149","pt":1724788660010,"mc":[{"id":"1.232352479","rc":[{"batb":[[0,1.45,5],[1,1.44,4.61],[2,1.43,93.99]],"ltp":1.49,"tv":229.06,"id":24640635},{"batb":[[0,3.05,5],[1,3,20.2],[2,1.03,200]],"ltp":3.05,"tv":227.19,"id":48610314}]}]}
{"op":"mcm","clk":"11978178607","pt":1724788663394,"mc":[{"id":"1.232352479","rc":[{"batb":[[0,1.44,4.61],[1,1.43,93.99],[2,1.03,200]],"ltp":1.49,"tv":229.06,"id":24640635},{"batb":[[0,3,20.2],[1,1.03,200],[2,1.02,200]],"ltp":3.05,"tv":227.19,"id":48610314}]}]}
{"op":"mcm","clk":"11978179689","pt":1724788671994,"mc":[{"id":"1.232352479","rc":[{"batb":[[0,1.45,5],[1,1.44,4.61],[2,1.43,93.99]],"ltp":1.49,"tv":229.06,"id":24640635},{"batb":[[0,3.05,5],[1,3,20.2],[2,1.03,200]],"ltp":3.05,"tv":227.19,"id":48610314}]}]}
{"op":"mcm","clk":"11978180139","pt":1724788675395,"mc":[{"id":"1.232352479","rc":[{"batb":[[0,1.44,4.61],[1,1.43,93.99],[2,1.03,200]],"ltp":1.49,"tv":229.06,"id":24640635},{"batb":[[0,3,20.2],[1,1.03,200],[2,1.02,200]],"ltp":3.05,"tv":227.19,"id":48610314}]}]}
{"op":"mcm","clk":"11978180869","pt":1724788680603,"mc":[{"id":"1.232352479","rc":[{"batb":[[0,1.45,5],[1,1.44,4.61],[2,1.43,93.99]],"ltp":1.49,"tv":229.06,"id":24640635},{"batb":[[0,3.05,5],[1,3,20.2],[2,1.03,200]],"ltp":3.05,"tv":227.19,"id":48610314}]}]}
{"op":"mcm","clk":"11978181345","pt":1724788684300,"mc":[{"id":"1.232352479","rc":[{"batb":[[0,1.44,4.61],[1,1.43,93.99],[2,1.03,200]],"ltp":1.49,"tv":229.06,"id":24640635},{"batb":[[0,3,20.2],[1,1.03,200],[2,1.02,200]],"ltp":3.05,"tv":227.19,"id":48610314}]}]}
{"op":"mcm","clk":"11978181770","pt":1724788687215,"mc":[{"id":"1.232352479","rc":[{"batb":[[0,1.45,5],[1,1.44,4.61],[2,1.43,93.99]],"ltp":1.49,"tv":229.06,"id":24640635},{"batb":[[0,3.05,5],[1,3,20.2],[2,1.03,200]],"ltp":3.05,"tv":227.19,"id":48610314}]}]}
{"op":"mcm","clk":"11978182219","pt":1724788690810,"mc":[{"id":"1.232352479","rc":[{"batb":[[0,1.44,4.61],[1,1.43,93.99],[2,1.03,200]],"ltp":1.49,"tv":229.06,"id":24640635},{"batb":[[0,3,20.2],[1,1.03,200],[2,1.02,200]],"ltp":3.05,"tv":227.19,"id":48610314}]}]}
{"op":"mcm","clk":"11978184425","pt":1724788707921,"mc":[{"id":"1.232352479","rc":[{"batb":[[0,1.45,5],[1,1.44,4.61],[2,1.43,93.99]],"ltp":1.49,"tv":229.06,"id":24640635},{"batb":[[0,3.05,5],[1,3,20.2],[2,1.03,200]],"ltp":3.05,"tv":227.19,"id":48610314}]}]}
{"op":"mcm","clk":"11978184877","pt":1724788711323,"mc":[{"id":"1.232352479","rc":[{"batb":[[0,1.44,4.61],[1,1.43,93.99],[2,1.03,200]],"ltp":1.49,"tv":229.06,"id":24640635},{"batb":[[0,3,20.2],[1,1.03,200],[2,1.02,200]],"ltp":3.05,"tv":227.19,"id":48610314}]}]}
{"op":"mcm","clk":"11978185164","pt":1724788713753,"mc":[{"id":"1.232352479","rc":[{"batb":[[0,1.45,5],[1,1.44,4.61],[2,1.43,93.99]],"ltp":1.49,"tv":229.06,"id":24640635},{"batb":[[0,3.05,5],[1,3,20.2],[2,1.03,200]],"ltp":3.05,"tv":227.19,"id":48610314}]}]}
{"op":"mcm","clk":"11978185574","pt":1724788717163,"mc":[{"id":"1.232352479","rc":[{"batb":[[0,1.44,4.61],[1,1.43,93.99],[2,1.03,200]],"ltp":1.49,"tv":229.06,"id":24640635},{"batb":[[0,3,20.2],[1,1.03,200],[2,1.02,200]],"ltp":3.05,"tv":227.19,"id":48610314}]}]}
{"op":"mcm","clk":"11978186105","pt":1724788721247,"mc":[{"id":"1.232352479","rc":[{"batb":[[0,1.45,5],[1,1.44,4.61],[2,1.43,93.99]],"ltp":1.49,"tv":229.06,"id":24640635},{"batb":[[0,3.05,5],[1,3,20.2],[2,1.03,200]],"ltp":3.05,"tv":227.19,"id":48610314}]}]}
{"op":"mcm","clk":"11978186589","pt":1724788724758,"mc":[{"id":"1.232352479","rc":[{"batb":[[0,1.44,4.61],[1,1.43,93.99],[2,1.03,200]],"ltp":1.49,"tv":229.06,"id":24640635},{"batb":[[0,3,20.2],[1,1.03,200],[2,1.02,200]],"ltp":3.05,"tv":227.19,"id":48610314}]}]}
{"op":"mcm","clk":"11978189242","pt":1724788743571,"mc":[{"id":"1.232352479","rc":[{"batb":[[0,1.45,5],[1,1.44,4.61],[2,1.43,93.99]],"ltp":1.49,"tv":229.06,"id":24640635},{"batb":[[0,3.05,5],[1,3,20.2],[2,1.03,200]],"ltp":3.05,"tv":227.19,"id":48610314}]}]}
{"op":"mcm","clk":"11978189772","pt":1724788747049,"mc":[{"id":"1.232352479","rc":[{"batb":[[0,1.44,4.61],[1,1.43,93.99],[2,1.03,200]],"ltp":1.49,"tv":229.06,"id":24640635},{"batb":[[0,3,20.2],[1,1.03,200],[2,1.02,200]],"ltp":3.05,"tv":227.19,"id":48610314}]}]}
{"op":"mcm","clk":"11978196737","pt":1724788794722,"mc":[{"id":"1.232352479","rc":[{"batb":[[0,1.45,5],[1,1.44,12.02],[2,1.43,93.99]],"ltp":1.49,"tv":229.06,"id":24640635},{"batb":[[0,3.05,5],[1,3,20.2],[2,1.03,200]],"ltp":3.05,"tv":227.19,"id":48610314}]}]}
{"op":"mcm","clk":"11978197193","pt":1724788798032,"mc":[{"id":"1.232352479","rc":[{"batb":[[0,1.44,12.02],[1,1.43,93.99],[2,1.03,200]],"ltp":1.49,"tv":229.06,"id":24640635},{"batb":[[0,3,20.2],[1,1.03,200],[2,1.02,200]],"ltp":3.05,"tv":227.19,"id":48610314}]}]}
{"op":"mcm","clk":"11978206220","pt":1724788863109,"mc":[{"id":"1.232352479","rc":[{"trd":[[1.5,226.83]],"batb":[[0,1.45,5],[1,1.44,12.02],[2,1.43,93.99]],"ltp":1.49,"tv":229.05,"id":24640635},{"trd":[[1.5,226.83]],"batb":[[0,3.05,5],[1,3,20.2],[2,1.03,200]],"ltp":3.05,"tv":227.18,"id":48610314}],"tv":456.23}]}
{"op":"mcm","clk":"11978206687","pt":1724788866500,"mc":[{"id":"1.232352479","rc":[{"batb":[[0,1.44,12.02],[1,1.43,93.99],[2,1.03,200]],"ltp":1.49,"tv":229.05,"id":24640635},{"batb":[[0,3,20.2],[1,1.03,200],[2,1.02,200]],"ltp":3.05,"tv":227.18,"id":48610314}]}]}
{"op":"mcm","clk":"11978208330","pt":1724788877543,"mc":[{"id":"1.232352479","rc":[{"batb":[[0,1.45,5],[1,1.44,12.02],[2,1.43,93.99]],"ltp":1.49,"tv":229.05,"id":24640635},{"batb":[[0,3.05,5],[1,3,20.2],[2,1.03,200]],"ltp":3.05,"tv":227.18,"id":48610314}]}]}
{"op":"mcm","clk":"11978208776","pt":1724788881063,"mc":[{"id":"1.232352479","rc":[{"batb":[[0,1.44,12.02],[1,1.43,93.99],[2,1.03,200]],"ltp":1.49,"tv":229.05,"id":24640635},{"batb":[[0,3,20.2],[1,1.03,200],[2,1.02,200]],"ltp":3.05,"tv":227.18,"id":48610314}]}]}
{"op":"mcm","clk":"11978215917","pt":1724788931314,"mc":[{"id":"1.232352479","rc":[{"trd":[[1.44,24]],"batb":[[0,1.44,5.02]],"ltp":1.44,"tv":253.05,"id":24640635},{"batb":[[0,3.05,5],[1,3,20.2],[2,1.03,200]],"ltp":3.05,"tv":227.18,"id":48610314}],"tv":480.23}]}
{"op":"mcm","clk":"11978216032","pt":1724788932069,"mc":[{"id":"1.232352479","rc":[{"batl":[[0,1.49,4.46],[1,15,0.75]],"ltp":1.44,"tv":253.05,"id":24640635}]}]}
{"op":"mcm","clk":"11978216130","pt":1724788932647,"mc":[{"id":"1.232352479","rc":[{"batb":[[0,1.44,5]],"ltp":1.44,"tv":253.05,"id":24640635}]}]}
{"op":"mcm","clk":"11978216425","pt":1724788934723,"mc":[{"id":"1.232352479","rc":[{"batb":[[0,1.43,93.99],[1,1.03,200],[2,1.02,200]],"batl":[[0,1.49,11.6]],"ltp":1.44,"tv":253.05,"id":24640635},{"batb":[[0,3,20.2],[1,1.03,200],[2,1.02,200]],"ltp":3.05,"tv":227.18,"id":48610314}]}]}
{"op":"mcm","clk":"11978220524","pt":1724788961990,"mc":[{"id":"1.232352479","rc":[{"trd":[[1.43,187.5]],"batb":[[0,1.03,200.99],[1,1.02,200],[2,1.01,220.75]],"ltp":1.43,"tv":439.05,"id":24640635},{"batb":[[0,3.05,5],[1,3,20.2],[2,1.03,200]],"ltp":3.05,"tv":227.18,"id":48610314}],"tv":666.23}]}
{"op":"mcm","clk":"11978220755","pt":1724788963362,"mc":[{"id":"1.232352479","rc":[{"batb":[[0,1.39,103.63],[1,1.03,200],[2,1.02,200]],"ltp":1.43,"tv":439.05,"id":24640635}]}]}
{"op":"mcm","clk":"11978221068","pt":1724788965358,"mc":[{"id":"1.232352479","rc":[{"batb":[[0,3,20.2],[1,1.03,200],[2,1.02,200]],"ltp":3.05,"tv":227.18,"id":48610314}]}]}
{"op":"mcm","clk":"11978265337","pt":1724789273734,"mc":[{"id":"1.232352479","rc":[{"batb":[[0,3.05,5],[1,3,20.2],[2,1.03,200]],"ltp":3.05,"tv":227.18,"id":48610314}]}]}
{"op":"mcm","clk":"11978265810","pt":1724789277003,"mc":[{"id":"1.232352479","rc":[{"batb":[[0,3,20.2],[1,1.03,200],[2,1.02,200]],"ltp":3.05,"tv":227.18,"id":48610314}]}]}
{"op":"mcm","clk":"11978368364","pt":1724789938119,"mc":[{"id":"1.232352479","rc":[{"batb":[[0,3.05,5],[1,3,20.2],[2,1.03,200]],"ltp":3.05,"tv":227.18,"id":48610314}]}]}
{"op":"mcm","clk":"11978368859","pt":1724789941955,"mc":[{"id":"1.232352479","rc":[{"batb":[[0,3,20.2],[1,1.03,200],[2,1.02,200]],"ltp":3.05,"tv":227.18,"id":48610314}]}]}
{"op":"mcm","clk":"11978369856","pt":1724789948647,"mc":[{"id":"1.232352479","rc":[{"batb":[[0,3.05,5],[1,3,20.2],[2,1.03,200]],"ltp":3.05,"tv":227.18,"id":48610314}]}]}
{"op":"mcm","clk":"11978370337","pt":1724789952162,"mc":[{"id":"1.232352479","rc":[{"batb":[[0,3,20.2],[1,1.03,200],[2,1.02,200]],"ltp":3.05,"tv":227.18,"id":48610314}]}]}
{"op":"mcm","clk":"11978371731","pt":1724789962480,"mc":[{"id":"1.232352479","rc":[{"batb":[[0,3.05,5],[1,3,20.2],[2,1.03,200]],"ltp":3.05,"tv":227.18,"id":48610314}]}]}
{"op":"mcm","clk":"11978372222","pt":1724789965926,"mc":[{"id":"1.232352479","rc":[{"batb":[[0,3,20.2],[1,1.03,200],[2,1.02,200]],"ltp":3.05,"tv":227.18,"id":48610314}]}]}
{"op":"mcm","clk":"11978373773","pt":1724789977023,"mc":[{"id":"1.232352479","rc":[{"batb":[[0,3.05,5],[1,3,20.2],[2,1.03,200]],"ltp":3.05,"tv":227.18,"id":48610314}]}]}
{"op":"mcm","clk":"11978374284","pt":1724789980519,"mc":[{"id":"1.232352479","rc":[{"batb":[[0,3,20.2],[1,1.03,200],[2,1.02,200]],"ltp":3.05,"tv":227.18,"id":48610314}]}]}
{"op":"mcm","clk":"11978374916","pt":1724789984825,"mc":[{"id":"1.232352479","rc":[{"batb":[[0,3.05,5],[1,3,20.2],[2,1.03,200]],"ltp":3.05,"tv":227.18,"id":48610314}]}]}
{"op":"mcm","clk":"11978375374","pt":1724789988222,"mc":[{"id":"1.232352479","rc":[{"batb":[[0,3,20.2],[1,1.03,200],[2,1.02,200]],"ltp":3.05,"tv":227.18,"id":48610314}]}]}
{"op":"mcm","clk":"11978375804","pt":1724789990898,"mc":[{"id":"1.232352479","rc":[{"batb":[[0,3.05,5],[1,3,20.2],[2,1.03,200]],"ltp":3.05,"tv":227.18,"id":48610314}]}]}
{"op":"mcm","clk":"11978376326","pt":1724789994537,"mc":[{"id":"1.232352479","rc":[{"batb":[[0,3,20.2],[1,1.03,200],[2,1.02,200]],"ltp":3.05,"tv":227.18,"id":48610314}]}]}
{"op":"mcm","clk":"11978376656","pt":1724789996828,"mc":[{"id":"1.232352479","rc":[{"batb":[[0,3.05,5],[1,3,20.2],[2,1.03,200]],"ltp":3.05,"tv":227.18,"id":48610314}]}]}
{"op":"mcm","clk":"11978377151","pt":1724790000463,"mc":[{"id":"1.232352479","rc":[{"batb":[[0,3,20.2],[1,1.03,200],[2,1.02,200]],"ltp":3.05,"tv":227.18,"id":48610314}]}]}
{"op":"mcm","clk":"11978378299","pt":1724790007939,"mc":[{"id":"1.232352479","rc":[{"batb":[[0,3.05,5],[1,3,20.2],[2,1.03,200]],"ltp":3.05,"tv":227.18,"id":48610314}]}]}
{"op":"mcm","clk":"11978378799","pt":1724790011441,"mc":[{"id":"1.232352479","rc":[{"batb":[[0,3,20.2],[1,1.03,200],[2,1.02,200]],"ltp":3.05,"tv":227.18,"id":48610314}]}]}
{"op":"mcm","clk":"11978379333","pt":1724790014965,"mc":[{"id":"1.232352479","rc":[{"batb":[[0,3.05,5],[1,3,20.2],[2,1.03,200]],"ltp":3.05,"tv":227.18,"id":48610314}]}]}
{"op":"mcm","clk":"11978379815","pt":1724790018459,"mc":[{"id":"1.232352479","rc":[{"batb":[[0,3,20.2],[1,1.03,200],[2,1.02,200]],"ltp":3.05,"tv":227.18,"id":48610314}]}]}
{"op":"mcm","clk":"11978380757","pt":1724790025070,"mc":[{"id":"1.232352479","rc":[{"batb":[[0,3.05,5],[1,3,20.2],[2,1.03,200]],"ltp":3.05,"tv":227.18,"id":48610314}]}]}
{"op":"mcm","clk":"11978381260","pt":1724790028577,"mc":[{"id":"1.232352479","rc":[{"batb":[[0,3,20.2],[1,1.03,200],[2,1.02,200]],"ltp":3.05,"tv":227.18,"id":48610314}]}]}
{"op":"mcm","clk":"11978381647","pt":1724790031469,"mc":[{"id":"1.232352479","rc":[{"batb":[[0,3.05,5],[1,3,20.2],[2,1.03,200]],"ltp":3.05,"tv":227.18,"id":48610314}]}]}
{"op":"mcm","clk":"11978382117","pt":1724790034869,"mc":[{"id":"1.232352479","rc":[{"batb":[[0,3,20.2],[1,1.03,200],[2,1.02,200]],"ltp":3.05,"tv":227.18,"id":48610314}]}]}
{"op":"mcm","clk":"11978382674","pt":1724790038814,"mc":[{"id":"1.232352479","rc":[{"batb":[[0,3.05,5],[1,3,20.2],[2,1.03,200]],"ltp":3.05,"tv":227.18,"id":48610314}]}]}
{"op":"mcm","clk":"11978383252","pt":1724790042686,"mc":[{"id":"1.232352479","rc":[{"batb":[[0,3,20.2],[1,1.03,200],[2,1.02,200]],"ltp":3.05,"tv":227.18,"id":48610314}]}]}
{"op":"mcm","clk":"11978383967","pt":1724790047693,"mc":[{"id":"1.232352479","rc":[{"batb":[[0,3.05,5],[1,3,20.2],[2,1.03,200]],"ltp":3.05,"tv":227.18,"id":48610314}]}]}
{"op":"mcm","clk":"11978384465","pt":1724790051152,"mc":[{"id":"1.232352479","rc":[{"batb":[[0,3,20.2],[1,1.03,200],[2,1.02,200]],"ltp":3.05,"tv":227.18,"id":48610314}]}]}
{"op":"mcm","clk":"11978385141","pt":1724790056079,"mc":[{"id":"1.232352479","rc":[{"batb":[[0,3.05,5],[1,3,20.2],[2,1.03,200]],"ltp":3.05,"tv":227.18,"id":48610314}]}]}
{"op":"mcm","clk":"11978385616","pt":1724790059397,"mc":[{"id":"1.232352479","rc":[{"batb":[[0,3,20.2],[1,1.03,200],[2,1.02,200]],"ltp":3.05,"tv":227.18,"id":48610314}]}]}
{"op":"mcm","clk":"11978386409","pt":1724790064780,"mc":[{"id":"1.232352479","rc":[{"batb":[[0,3.05,5],[1,3,20.2],[2,1.03,200]],"ltp":3.05,"tv":227.18,"id":48610314}]}]}
{"op":"mcm","clk":"11978386899","pt":1724790068133,"mc":[{"id":"1.232352479","rc":[{"batb":[[0,3,20.2],[1,1.03,200],[2,1.02,200]],"ltp":3.05,"tv":227.18,"id":48610314}]}]}
{"op":"mcm","clk":"11978387579","pt":1724790072610,"mc":[{"id":"1.232352479","rc":[{"batb":[[0,3.05,5],[1,3,20.2],[2,1.03,200]],"ltp":3.05,"tv":227.18,"id":48610314}]}]}
{"op":"mcm","clk":"11978388083","pt":1724790075891,"mc":[{"id":"1.232352479","rc":[{"batb":[[0,3,20.2],[1,1.03,200],[2,1.02,200]],"ltp":3.05,"tv":227.18,"id":48610314}]}]}
{"op":"mcm","clk":"11978389050","pt":1724790082506,"mc":[{"id":"1.232352479","rc":[{"batb":[[0,3.05,5],[1,3,20.2],[2,1.03,200]],"ltp":3.05,"tv":227.18,"id":48610314}]}]}
{"op":"mcm","clk":"11978389538","pt":1724790085902,"mc":[{"id":"1.232352479","rc":[{"batb":[[0,3,20.2],[1,1.03,200],[2,1.02,200]],"ltp":3.05,"tv":227.18,"id":48610314}]}]}
{"op":"mcm","clk":"11978389978","pt":1724790088954,"mc":[{"id":"1.232352479","rc":[{"batb":[[0,3.05,5],[1,3,20.2],[2,1.03,200]],"ltp":3.05,"tv":227.18,"id":48610314}]}]}
{"op":"mcm","clk":"11978390605","pt":1724790092410,"mc":[{"id":"1.232352479","rc":[{"batb":[[0,3,20.2],[1,1.03,200],[2,1.02,200]],"ltp":3.05,"tv":227.18,"id":48610314}]}]}
{"op":"mcm","clk":"11978391125","pt":1724790095126,"mc":[{"id":"1.232352479","rc":[{"batb":[[0,3.05,5],[1,3,20.2],[2,1.03,200]],"ltp":3.05,"tv":227.18,"id":48610314}]}]}
{"op":"mcm","clk":"11978391764","pt":1724790098830,"mc":[{"id":"1.232352479","rc":[{"batb":[[0,3,20.2],[1,1.03,200],[2,1.02,200]],"ltp":3.05,"tv":227.18,"id":48610314}]}]}
{"op":"mcm","clk":"11978392451","pt":1724790103584,"mc":[{"id":"1.232352479","rc":[{"batb":[[0,3.05,5],[1,3,20.2],[2,1.03,200]],"ltp":3.05,"tv":227.18,"id":48610314}]}]}
{"op":"mcm","clk":"11978392991","pt":1724790107160,"mc":[{"id":"1.232352479","rc":[{"batb":[[0,3,20.2],[1,1.03,200],[2,1.02,200]],"ltp":3.05,"tv":227.18,"id":48610314}]}]}
{"op":"mcm","clk":"11978393423","pt":1724790110174,"mc":[{"id":"1.232352479","rc":[{"batb":[[0,3.05,5],[1,3,20.2],[2,1.03,200]],"ltp":3.05,"tv":227.18,"id":48610314}]}]}
{"op":"mcm","clk":"11978393919","pt":1724790113538,"mc":[{"id":"1.232352479","rc":[{"batb":[[0,3,20.2],[1,1.03,200],[2,1.02,200]],"ltp":3.05,"tv":227.18,"id":48610314}]}]}
{"op":"mcm","clk":"11978394835","pt":1724790119948,"mc":[{"id":"1.232352479","rc":[{"batb":[[0,3.05,5],[1,3,20.2],[2,1.03,200]],"ltp":3.05,"tv":227.18,"id":48610314}]}]}
{"op":"mcm","clk":"11978395385","pt":1724790123466,"mc":[{"id":"1.232352479","rc":[{"batb":[[0,3,20.2],[1,1.03,200],[2,1.02,200]],"ltp":3.05,"tv":227.18,"id":48610314}]}]}
{"op":"mcm","clk":"11978395824","pt":1724790126483,"mc":[{"id":"1.232352479","rc":[{"batb":[[0,3.05,5],[1,3,20.2],[2,1.03,200]],"ltp":3.05,"tv":227.18,"id":48610314}]}]}
{"op":"mcm","clk":"11978396298","pt":1724790129787,"mc":[{"id":"1.232352479","rc":[{"batb":[[0,3,20.2],[1,1.03,200],[2,1.02,200]],"ltp":3.05,"tv":227.18,"id":48610314}]}]}
{"op":"mcm","clk":"11978396848","pt":1724790133796,"mc":[{"id":"1.232352479","rc":[{"batb":[[0,3.05,5],[1,3,20.2],[2,1.03,200]],"ltp":3.05,"tv":227.18,"id":48610314}]}]}
{"op":"mcm","clk":"11978397361","pt":1724790137098,"mc":[{"id":"1.232352479","rc":[{"batb":[[0,3,20.2],[1,1.03,200],[2,1.02,200]],"ltp":3.05,"tv":227.18,"id":48610314}]}]}
{"op":"mcm","clk":"11978397929","pt":1724790141110,"mc":[{"id":"1.232352479","rc":[{"batb":[[0,3.05,5],[1,3,20.2],[2,1.03,200]],"ltp":3.05,"tv":227.18,"id":48610314}]}]}
{"op":"mcm","clk":"11978398375","pt":1724790144509,"mc":[{"id":"1.232352479","rc":[{"batb":[[0,3,20.2],[1,1.03,200],[2,1.02,200]],"ltp":3.05,"tv":227.18,"id":48610314}]}]}
{"op":"mcm","clk":"11978399141","pt":1724790150136,"mc":[{"id":"1.232352479","rc":[{"batb":[[0,3.05,5],[1,3,20.2],[2,1.03,200]],"ltp":3.05,"tv":227.18,"id":48610314}]}]}
{"op":"mcm","clk":"11978399674","pt":1724790153702,"mc":[{"id":"1.232352479","rc":[{"batb":[[0,3,20.2],[1,1.03,200],[2,1.02,200]],"ltp":3.05,"tv":227.18,"id":48610314}]}]}
{"op":"mcm","clk":"11978400291","pt":1724790158325,"mc":[{"id":"1.232352479","rc":[{"batb":[[0,3.05,5],[1,3,20.2],[2,1.03,200]],"ltp":3.05,"tv":227.18,"id":48610314}]}]}
{"op":"mcm","clk":"11978400788","pt":1724790161916,"mc":[{"id":"1.232352479","rc":[{"batb":[[0,3,20.2],[1,1.03,200],[2,1.02,200]],"ltp":3.05,"tv":227.18,"id":48610314}]}]}
{"op":"mcm","clk":"11978401193","pt":1724790164552,"mc":[{"id":"1.232352479","rc":[{"batb":[[0,3.05,5],[1,3,20.2],[2,1.03,200]],"ltp":3.05,"tv":227.18,"id":48610314}]}]}
{"op":"mcm","clk":"11978401711","pt":1724790168133,"mc":[{"id":"1.232352479","rc":[{"batb":[[0,3,20.2],[1,1.03,200],[2,1.02,200]],"ltp":3.05,"tv":227.18,"id":48610314}]}]}
{"op":"mcm","clk":"11978402176","pt":1724790171334,"mc":[{"id":"1.232352479","rc":[{"batb":[[0,3.05,5],[1,3,20.2],[2,1.03,200]],"ltp":3.05,"tv":227.18,"id":48610314}]}]}
{"op":"mcm","clk":"11978402635","pt":1724790174726,"mc":[{"id":"1.232352479","rc":[{"batb":[[0,3,20.2],[1,1.03,200],[2,1.02,200]],"ltp":3.05,"tv":227.18,"id":48610314}]}]}
{"op":"mcm","clk":"11978403115","pt":1724790178125,"mc":[{"id":"1.232352479","rc":[{"batb":[[0,3.05,5],[1,3,20.2],[2,1.03,200]],"ltp":3.05,"tv":227.18,"id":48610314}]}]}
{"op":"mcm","clk":"11978403549","pt":1724790181405,"mc":[{"id":"1.232352479","rc":[{"batb":[[0,3,20.2],[1,1.03,200],[2,1.02,200]],"ltp":3.05,"tv":227.18,"id":48610314}]}]}
{"op":"mcm","clk":"11978404044","pt":1724790185013,"mc":[{"id":"1.232352479","rc":[{"batb":[[0,3.05,5],[1,3,20.2],[2,1.03,200]],"ltp":3.05,"tv":227.18,"id":48610314}]}]}
{"op":"mcm","clk":"11978404509","pt":1724790188602,"mc":[{"id":"1.232352479","rc":[{"batb":[[0,3,20.2],[1,1.03,200],[2,1.02,200]],"ltp":3.05,"tv":227.18,"id":48610314}]}]}
{"op":"mcm","clk":"11978404812","pt":1724790190944,"mc":[{"id":"1.232352479","rc":[{"batb":[[0,3.05,5],[1,3,20.2],[2,1.03,200]],"ltp":3.05,"tv":227.18,"id":48610314}]}]}
{"op":"mcm","clk":"11978405268","pt":1724790194519,"mc":[{"id":"1.232352479","rc":[{"batb":[[0,3,20.2],[1,1.03,200],[2,1.02,200]],"ltp":3.05,"tv":227.18,"id":48610314}]}]}
{"op":"mcm","clk":"11978405660","pt":1724790197785,"mc":[{"id":"1.232352479","rc":[{"batb":[[0,3.05,5],[1,3,20.2],[2,1.03,200]],"ltp":3.05,"tv":227.18,"id":48610314}]}]}
{"op":"mcm","clk":"11978406065","pt":1724790201332,"mc":[{"id":"1.232352479","rc":[{"batb":[[0,3,20.2],[1,1.03,200],[2,1.02,200]],"ltp":3.05,"tv":227.18,"id":48610314}]}]}
{"op":"mcm","clk":"11978406432","pt":1724790204042,"mc":[{"id":"1.232352479","rc":[{"batb":[[0,3.05,5],[1,3,20.2],[2,1.03,200]],"ltp":3.05,"tv":227.18,"id":48610314}]}]}
{"op":"mcm","clk":"11978406867","pt":1724790207422,"mc":[{"id":"1.232352479","rc":[{"batb":[[0,3,20.2],[1,1.03,200],[2,1.02,200]],"ltp":3.05,"tv":227.18,"id":48610314}]}]}
{"op":"mcm","clk":"11978407196","pt":1724790210246,"mc":[{"id":"1.232352479","rc":[{"batb":[[0,3.05,5],[1,3,20.2],[2,1.03,200]],"ltp":3.05,"tv":227.18,"id":48610314}]}]}
{"op":"mcm","clk":"11978407763","pt":1724790213949,"mc":[{"id":"1.232352479","rc":[{"batb":[[0,3,20.2],[1,1.03,200],[2,1.02,200]],"ltp":3.05,"tv":227.18,"id":48610314}]}]}
{"op":"mcm","clk":"11978408490","pt":1724790219727,"mc":[{"id":"1.232352479","rc":[{"batb":[[0,3.05,5],[1,3,20.2],[2,1.03,200]],"ltp":3.05,"tv":227.18,"id":48610314}]}]}
{"op":"mcm","clk":"11978408913","pt":1724790223119,"mc":[{"id":"1.232352479","rc":[{"batb":[[0,3,20.2],[1,1.03,200],[2,1.02,200]],"ltp":3.05,"tv":227.18,"id":48610314}]}]}
{"op":"mcm","clk":"11978409746","pt":1724790229557,"mc":[{"id":"1.232352479","rc":[{"batb":[[0,3.05,5],[1,3,20.2],[2,1.03,200]],"ltp":3.05,"tv":227.18,"id":48610314}]}]}
{"op":"mcm","clk":"11978410178","pt":1724790232844,"mc":[{"id":"1.232352479","rc":[{"batb":[[0,3,20.2],[1,1.03,200],[2,1.02,200]],"ltp":3.05,"tv":227.18,"id":48610314}]}]}
{"op":"mcm","clk":"11978410456","pt":1724790235185,"mc":[{"id":"1.232352479","rc":[{"batb":[[0,3.05,5],[1,3,20.2],[2,1.03,200]],"ltp":3.05,"tv":227.18,"id":48610314}]}]}
{"op":"mcm","clk":"11978410897","pt":1724790238772,"mc":[{"id":"1.232352479","rc":[{"batb":[[0,3,20.2],[1,1.03,200],[2,1.02,200]],"ltp":3.05,"tv":227.18,"id":48610314}]}]}
{"op":"mcm","clk":"11978411178","pt":1724790241060,"mc":[{"id":"1.232352479","rc":[{"batb":[[0,3.05,5],[1,3,20.2],[2,1.03,200]],"ltp":3.05,"tv":227.18,"id":48610314}]}]}
{"op":"mcm","clk":"11978411699","pt":1724790244660,"mc":[{"id":"1.232352479","rc":[{"batb":[[0,3,20.2],[1,1.03,200],[2,1.02,200]],"ltp":3.05,"tv":227.18,"id":48610314}]}]}
{"op":"mcm","clk":"11978412054","pt":1724790247166,"mc":[{"id":"1.232352479","rc":[{"batb":[[0,3.05,5],[1,3,20.2],[2,1.03,200]],"ltp":3.05,"tv":227.18,"id":48610314}]}]}
{"op":"mcm","clk":"11978412501","pt":1724790250534,"mc":[{"id":"1.232352479","rc":[{"batb":[[0,3,20.2],[1,1.03,200],[2,1.02,200]],"ltp":3.05,"tv":227.18,"id":48610314}]}]}
{"op":"mcm","clk":"11978412815","pt":1724790252970,"mc":[{"id":"1.232352479","rc":[{"batb":[[0,3.05,5],[1,3,20.2],[2,1.03,200]],"ltp":3.05,"tv":227.18,"id":48610314}]}]}
{"op":"mcm","clk":"11978413251","pt":1724790256360,"mc":[{"id":"1.232352479","rc":[{"batb":[[0,3,20.2],[1,1.03,200],[2,1.02,200]],"ltp":3.05,"tv":227.18,"id":48610314}]}]}
{"op":"mcm","clk":"11978413729","pt":1724790260262,"mc":[{"id":"1.232352479","rc":[{"batb":[[0,3.05,5],[1,3,20.2],[2,1.03,200]],"ltp":3.05,"tv":227.18,"id":48610314}]}]}
{"op":"mcm","clk":"11978414154","pt":1724790263767,"mc":[{"id":"1.232352479","rc":[{"batb":[[0,3,20.2],[1,1.03,200],[2,1.02,200]],"ltp":3.05,"tv":227.18,"id":48610314}]}]}
{"op":"mcm","clk":"11978414569","pt":1724790267167,"mc":[{"id":"1.232352479","rc":[{"batb":[[0,3.05,5],[1,3,20.2],[2,1.03,200]],"ltp":3.05,"tv":227.18,"id":48610314}]}]}
{"op":"mcm","clk":"11978414960","pt":1724790270690,"mc":[{"id":"1.232352479","rc":[{"batb":[[0,3,20.2],[1,1.03,200],[2,1.02,200]],"ltp":3.05,"tv":227.18,"id":48610314}]}]}
{"op":"mcm","clk":"11978415358","pt":1724790273662,"mc":[{"id":"1.232352479","rc":[{"batb":[[0,3.05,5],[1,3,20.2],[2,1.03,200]],"ltp":3.05,"tv":227.18,"id":48610314}]}]}
{"op":"mcm","clk":"11978415790","pt":1724790276987,"mc":[{"id":"1.232352479","rc":[{"batb":[[0,3,20.2],[1,1.03,200],[2,1.02,200]],"ltp":3.05,"tv":227.18,"id":48610314}]}]}
{"op":"mcm","clk":"11978416540","pt":1724790282884,"mc":[{"id":"1.232352479","rc":[{"batb":[[0,3.05,5],[1,3,20.2],[2,1.03,200]],"ltp":3.05,"tv":227.18,"id":48610314}]}]}
{"op":"mcm","clk":"11978416968","pt":1724790286086,"mc":[{"id":"1.232352479","rc":[{"batb":[[0,3,20.2],[1,1.03,200],[2,1.02,200]],"ltp":3.05,"tv":227.18,"id":48610314}]}]}
{"op":"mcm","clk":"11978417324","pt":1724790289000,"mc":[{"id":"1.232352479","rc":[{"batb":[[0,3.05,5],[1,3,20.2],[2,1.03,200]],"ltp":3.05,"tv":227.18,"id":48610314}]}]}
{"op":"mcm","clk":"11978417808","pt":1724790292606,"mc":[{"id":"1.232352479","rc":[{"batb":[[0,3,20.2],[1,1.03,200],[2,1.02,200]],"ltp":3.05,"tv":227.18,"id":48610314}]}]}
{"op":"mcm","clk":"11978418154","pt":1724790295179,"mc":[{"id":"1.232352479","rc":[{"batb":[[0,3.05,5],[1,3,20.2],[2,1.03,200]],"ltp":3.05,"tv":227.18,"id":48610314}]}]}
{"op":"mcm","clk":"11978418594","pt":1724790298512,"mc":[{"id":"1.232352479","rc":[{"batb":[[0,3,20.2],[1,1.03,200],[2,1.02,200]],"ltp":3.05,"tv":227.18,"id":48610314}]}]}
{"op":"mcm","clk":"11978419067","pt":1724790302473,"mc":[{"id":"1.232352479","rc":[{"batb":[[0,3.05,5],[1,3,20.2],[2,1.03,200]],"ltp":3.05,"tv":227.18,"id":48610314}]}]}
{"op":"mcm","clk":"11978419549","pt":1724790306021,"mc":[{"id":"1.232352479","rc":[{"batb":[[0,3,20.2],[1,1.03,200],[2,1.02,200]],"ltp":3.05,"tv":227.18,"id":48610314}]}]}
{"op":"mcm","clk":"11978420031","pt":1724790309412,"mc":[{"id":"1.232352479","rc":[{"batb":[[0,3.05,5],[1,3,20.2],[2,1.03,200]],"ltp":3.05,"tv":227.18,"id":48610314}]}]}
{"op":"mcm","clk":"11978420467","pt":1724790312831,"mc":[{"id":"1.232352479","rc":[{"batb":[[0,3,20.2],[1,1.03,200],[2,1.02,200]],"ltp":3.05,"tv":227.18,"id":48610314}]}]}
{"op":"mcm","clk":"11978420732","pt":1724790315016,"mc":[{"id":"1.232352479","rc":[{"batb":[[0,3.05,5],[1,3,20.2],[2,1.03,200]],"ltp":3.05,"tv":227.18,"id":48610314}]}]}
{"op":"mcm","clk":"11978421147","pt":1724790318331,"mc":[{"id":"1.232352479","rc":[{"batb":[[0,3,20.2],[1,1.03,200],[2,1.02,200]],"ltp":3.05,"tv":227.18,"id":48610314}]}]}
{"op":"mcm","clk":"11978421507","pt":1724790321147,"mc":[{"id":"1.232352479","rc":[{"batb":[[0,3.05,5],[1,3,20.2],[2,1.03,200]],"ltp":3.05,"tv":227.18,"id":48610314}]}]}
{"op":"mcm","clk":"11978421947","pt":1724790324752,"mc":[{"id":"1.232352479","rc":[{"batb":[[0,3,20.2],[1,1.03,200],[2,1.02,200]],"ltp":3.05,"tv":227.18,"id":48610314}]}]}
{"op":"mcm","clk":"11978422306","pt":1724790327258,"mc":[{"id":"1.232352479","rc":[{"batb":[[0,3.05,5],[1,3,20.2],[2,1.03,200]],"ltp":3.05,"tv":227.18,"id":48610314}]}]}
{"op":"mcm","clk":"11978422742","pt":1724790330627,"mc":[{"id":"1.232352479","rc":[{"batb":[[0,3,20.2],[1,1.03,200],[2,1.02,200]],"ltp":3.05,"tv":227.18,"id":48610314}]}]}
{"op":"mcm","clk":"11978423252","pt":1724790334647,"mc":[{"id":"1.232352479","rc":[{"batb":[[0,3.05,5],[1,3,20.2],[2,1.03,200]],"ltp":3.05,"tv":227.18,"id":48610314}]}]}
{"op":"mcm","clk":"11978423696","pt":1724790338034,"mc":[{"id":"1.232352479","rc":[{"batb":[[0,3,20.2],[1,1.03,200],[2,1.02,200]],"ltp":3.05,"tv":227.18,"id":48610314}]}]}
{"op":"mcm","clk":"11978424061","pt":1724790341231,"mc":[{"id":"1.232352479","rc":[{"batb":[[0,3.05,5],[1,3,20.2],[2,1.03,200]],"ltp":3.05,"tv":227.18,"id":48610314}]}]}
{"op":"mcm","clk":"11978424476","pt":1724790344577,"mc":[{"id":"1.232352479","rc":[{"batb":[[0,3,20.2],[1,1.03,200],[2,1.02,200]],"ltp":3.05,"tv":227.18,"id":48610314}]}]}
{"op":"mcm","clk":"11978424873","pt":1724790347635,"mc":[{"id":"1.232352479","rc":[{"batb":[[0,3.05,5],[1,3,20.2],[2,1.03,200]],"ltp":3.05,"tv":227.18,"id":48610314}]}]}
{"op":"mcm","clk":"11978425276","pt":1724790351058,"mc":[{"id":"1.232352479","rc":[{"batb":[[0,3,20.2],[1,1.03,200],[2,1.02,200]],"ltp":3.05,"tv":227.18,"id":48610314}]}]}
{"op":"mcm","clk":"11978425711","pt":1724790354956,"mc":[{"id":"1.232352479","rc":[{"batb":[[0,3.05,5],[1,3,20.2],[2,1.03,200]],"ltp":3.05,"tv":227.18,"id":48610314}]}]}
{"op":"mcm","clk":"11978426088","pt":1724790358274,"mc":[{"id":"1.232352479","rc":[{"batb":[[0,3,20.2],[1,1.03,200],[2,1.02,200]],"ltp":3.05,"tv":227.18,"id":48610314}]}]}
{"op":"mcm","clk":"11978426583","pt":1724790362240,"mc":[{"id":"1.232352479","rc":[{"batb":[[0,3.05,5],[1,3,20.2],[2,1.03,200]],"ltp":3.05,"tv":227.18,"id":48610314}]}]}
{"op":"mcm","clk":"11978426969","pt":1724790365565,"mc":[{"id":"1.232352479","rc":[{"batb":[[0,3,20.2],[1,1.03,200],[2,1.02,200]],"ltp":3.05,"tv":227.18,"id":48610314}]}]}
{"op":"mcm","clk":"11978427313","pt":1724790368263,"mc":[{"id":"1.232352479","rc":[{"batb":[[0,3.05,5],[1,3,20.2],[2,1.03,200]],"ltp":3.05,"tv":227.18,"id":48610314}]}]}
{"op":"mcm","clk":"11978427735","pt":1724790371758,"mc":[{"id":"1.232352479","rc":[{"batb":[[0,3,20.2],[1,1.03,200],[2,1.02,200]],"ltp":3.05,"tv":227.18,"id":48610314}]}]}
{"op":"mcm","clk":"11978428098","pt":1724790374764,"mc":[{"id":"1.232352479","rc":[{"batb":[[0,3.05,5],[1,3,20.2],[2,1.03,200]],"ltp":3.05,"tv":227.18,"id":48610314}]}]}
{"op":"mcm","clk":"11978428484","pt":1724790378194,"mc":[{"id":"1.232352479","rc":[{"batb":[[0,3,20.2],[1,1.03,200],[2,1.02,200]],"ltp":3.05,"tv":227.18,"id":48610314}]}]}
{"op":"mcm","clk":"11978428785","pt":1724790380600,"mc":[{"id":"1.232352479","rc":[{"batb":[[0,3.05,5],[1,3,20.2],[2,1.03,200]],"ltp":3.05,"tv":227.18,"id":48610314}]}]}
{"op":"mcm","clk":"11978429208","pt":1724790383884,"mc":[{"id":"1.232352479","rc":[{"batb":[[0,3,20.2],[1,1.03,200],[2,1.02,200]],"ltp":3.05,"tv":227.18,"id":48610314}]}]}
{"op":"mcm","clk":"11978429670","pt":1724790387610,"mc":[{"id":"1.232352479","rc":[{"batb":[[0,3.05,5],[1,3,20.2],[2,1.03,200]],"ltp":3.05,"tv":227.18,"id":48610314}]}]}
{"op":"mcm","clk":"11978430120","pt":1724790391218,"mc":[{"id":"1.232352479","rc":[{"batb":[[0,3,20.2],[1,1.03,200],[2,1.02,200]],"ltp":3.05,"tv":227.18,"id":48610314}]}]}
{"op":"mcm","clk":"11978430491","pt":1724790393678,"mc":[{"id":"1.232352479","rc":[{"batb":[[0,3.05,5],[1,3,20.2],[2,1.03,200]],"ltp":3.05,"tv":227.18,"id":48610314}]}]}
{"op":"mcm","clk":"11978431051","pt":1724790397380,"mc":[{"id":"1.232352479","rc":[{"batb":[[0,3,20.2],[1,1.03,200],[2,1.02,200]],"ltp":3.05,"tv":227.18,"id":48610314}]}]}
{"op":"mcm","clk":"11978431357","pt":1724790399980,"mc":[{"id":"1.232352479","rc":[{"batb":[[0,3.05,5],[1,3,20.2],[2,1.03,200]],"ltp":3.05,"tv":227.18,"id":48610314}]}]}
{"op":"mcm","clk":"11978431789","pt":1724790403308,"mc":[{"id":"1.232352479","rc":[{"batb":[[0,3,20.2],[1,1.03,200],[2,1.02,200]],"ltp":3.05,"tv":227.18,"id":48610314}]}]}
{"op":"mcm","clk":"11978432108","pt":1724790405803,"mc":[{"id":"1.232352479","rc":[{"batb":[[0,3.05,5],[1,3,20.2],[2,1.03,200]],"ltp":3.05,"tv":227.18,"id":48610314}]}]}
{"op":"mcm","clk":"11978432580","pt":1724790409406,"mc":[{"id":"1.232352479","rc":[{"batb":[[0,3,20.2],[1,1.03,200],[2,1.02,200]],"ltp":3.05,"tv":227.18,"id":48610314}]}]}
{"op":"mcm","clk":"11978432913","pt":1724790412009,"mc":[{"id":"1.232352479","rc":[{"batb":[[0,3.05,5],[1,3,20.2],[2,1.03,200]],"ltp":3.05,"tv":227.18,"id":48610314}]}]}
{"op":"mcm","clk":"11978433378","pt":1724790415304,"mc":[{"id":"1.232352479","rc":[{"batb":[[0,3,20.2],[1,1.03,200],[2,1.02,200]],"ltp":3.05,"tv":227.18,"id":48610314}]}]}
{"op":"mcm","clk":"11978433746","pt":1724790418226,"mc":[{"id":"1.232352479","rc":[{"batb":[[0,3.05,5],[1,3,20.2],[2,1.03,200]],"ltp":3.05,"tv":227.18,"id":48610314}]}]}
{"op":"mcm","clk":"11978434127","pt":1724790421411,"mc":[{"id":"1.232352479","rc":[{"batb":[[0,3,20.2],[1,1.03,200],[2,1.02,200]],"ltp":3.05,"tv":227.18,"id":48610314}]}]}
{"op":"mcm","clk":"11978434596","pt":1724790425307,"mc":[{"id":"1.232352479","rc":[{"batb":[[0,3.05,5],[1,3,20.2],[2,1.03,200]],"ltp":3.05,"tv":227.18,"id":48610314}]}]}
{"op":"mcm","clk":"11978435002","pt":1724790428729,"mc":[{"id":"1.232352479","rc":[{"batb":[[0,3,20.2],[1,1.03,200],[2,1.02,200]],"ltp":3.05,"tv":227.18,"id":48610314}]}]}
{"op":"mcm","clk":"11978435476","pt":1724790432711,"mc":[{"id":"1.232352479","rc":[{"batb":[[0,3.05,5],[1,3,20.2],[2,1.03,200]],"ltp":3.05,"tv":227.18,"id":48610314}]}]}
{"op":"mcm","clk":"11978435944","pt":1724790436258,"mc":[{"id":"1.232352479","rc":[{"batb":[[0,3,20.2],[1,1.03,200],[2,1.02,200]],"ltp":3.05,"tv":227.18,"id":48610314}]}]}
{"op":"mcm","clk":"11978437060","pt":1724790445193,"mc":[{"id":"1.232352479","rc":[{"batb":[[0,3.05,5],[1,3,20.2],[2,1.03,200]],"ltp":3.05,"tv":227.18,"id":48610314}]}]}
{"op":"mcm","clk":"11978437520","pt":1724790448738,"mc":[{"id":"1.232352479","rc":[{"batb":[[0,3,20.2],[1,1.03,200],[2,1.02,200]],"ltp":3.05,"tv":227.18,"id":48610314}]}]}
{"op":"mcm","clk":"11978438849","pt":1724790459989,"mc":[{"id":"1.232352479","rc":[{"batb":[[0,3.05,5],[1,3,20.2],[2,1.03,200]],"ltp":3.05,"tv":227.18,"id":48610314}]}]}
{"op":"mcm","clk":"11978439262","pt":1724790463482,"mc":[{"id":"1.232352479","rc":[{"batb":[[0,3,20.2],[1,1.03,200],[2,1.02,200]],"ltp":3.05,"tv":227.18,"id":48610314}]}]}
{"op":"mcm","clk":"11978439580","pt":1724790466120,"mc":[{"id":"1.232352479","rc":[{"batb":[[0,3.05,5],[1,3,20.2],[2,1.03,200]],"ltp":3.05,"tv":227.18,"id":48610314}]}]}
{"op":"mcm","clk":"11978439963","pt":1724790469484,"mc":[{"id":"1.232352479","rc":[{"batb":[[0,3,20.2],[1,1.03,200],[2,1.02,200]],"ltp":3.05,"tv":227.18,"id":48610314}]}]}
{"op":"mcm","clk":"11978440323","pt":1724790472610,"mc":[{"id":"1.232352479","rc":[{"batb":[[0,3.05,5],[1,3,20.2],[2,1.03,200]],"ltp":3.05,"tv":227.18,"id":48610314}]}]}
{"op":"mcm","clk":"11978440729","pt":1724790476113,"mc":[{"id":"1.232352479","rc":[{"batb":[[0,3,20.2],[1,1.03,200],[2,1.02,200]],"ltp":3.05,"tv":227.18,"id":48610314}]}]}
{"op":"mcm","clk":"11978440970","pt":1724790478405,"mc":[{"id":"1.232352479","rc":[{"batb":[[0,3.05,5],[1,3,20.2],[2,1.03,200]],"ltp":3.05,"tv":227.18,"id":48610314}]}]}
{"op":"mcm","clk":"11978441350","pt":1724790481849,"mc":[{"id":"1.232352479","rc":[{"batb":[[0,3,20.2],[1,1.03,200],[2,1.02,200]],"ltp":3.05,"tv":227.18,"id":48610314}]}]}
{"op":"mcm","clk":"11978441703","pt":1724790484719,"mc":[{"id":"1.232352479","rc":[{"batb":[[0,3.05,5],[1,3,20.2],[2,1.03,200]],"ltp":3.05,"tv":227.18,"id":48610314}]}]}
{"op":"mcm","clk":"11978442149","pt":1724790488313,"mc":[{"id":"1.232352479","rc":[{"batb":[[0,3,20.2],[1,1.03,200],[2,1.02,200]],"ltp":3.05,"tv":227.18,"id":48610314}]}]}
{"op":"mcm","clk":"11978442471","pt":1724790490754,"mc":[{"id":"1.232352479","rc":[{"batb":[[0,3.05,5],[1,3,20.2],[2,1.03,200]],"ltp":3.05,"tv":227.18,"id":48610314}]}]}
{"op":"mcm","clk":"11978442881","pt":1724790494133,"mc":[{"id":"1.232352479","rc":[{"batb":[[0,3,20.2],[1,1.03,200],[2,1.02,200]],"ltp":3.05,"tv":227.18,"id":48610314}]}]}
{"op":"mcm","clk":"11978443212","pt":1724790496853,"mc":[{"id":"1.232352479","rc":[{"batb":[[0,3.05,5],[1,3,20.2],[2,1.03,200]],"ltp":3.05,"tv":227.18,"id":48610314}]}]}
{"op":"mcm","clk":"11978443643","pt":1724790500276,"mc":[{"id":"1.232352479","rc":[{"batb":[[0,3,20.2],[1,1.03,200],[2,1.02,200]],"ltp":3.05,"tv":227.18,"id":48610314}]}]}
{"op":"mcm","clk":"11978444044","pt":1724790503751,"mc":[{"id":"1.232352479","rc":[{"batb":[[0,3.05,5],[1,3,20.2],[2,1.03,200]],"ltp":3.05,"tv":227.18,"id":48610314}]}]}
{"op":"mcm","clk":"11978444512","pt":1724790507142,"mc":[{"id":"1.232352479","rc":[{"batb":[[0,3,20.2],[1,1.03,200],[2,1.02,200]],"ltp":3.05,"tv":227.18,"id":48610314}]}]}
{"op":"mcm","clk":"11978444847","pt":1724790509795,"mc":[{"id":"1.232352479","rc":[{"batb":[[0,3.05,5],[1,3,20.2],[2,1.03,200]],"ltp":3.05,"tv":227.18,"id":48610314}]}]}
{"op":"mcm","clk":"11978445259","pt":1724790513067,"mc":[{"id":"1.232352479","rc":[{"batb":[[0,3,20.2],[1,1.03,200],[2,1.02,200]],"ltp":3.05,"tv":227.18,"id":48610314}]}]}
{"op":"mcm","clk":"11978445591","pt":1724790515573,"mc":[{"id":"1.232352479","rc":[{"batb":[[0,3.05,5],[1,3,20.2],[2,1.03,200]],"ltp":3.05,"tv":227.18,"id":48610314}]}]}
{"op":"mcm","clk":"11978446000","pt":1724790518968,"mc":[{"id":"1.232352479","rc":[{"batb":[[0,3,20.2],[1,1.03,200],[2,1.02,200]],"ltp":3.05,"tv":227.18,"id":48610314}]}]}
{"op":"mcm","clk":"11978446553","pt":1724790523195,"mc":[{"id":"1.232352479","rc":[{"batb":[[0,3.05,5],[1,3,20.2],[2,1.03,200]],"ltp":3.05,"tv":227.18,"id":48610314}]}]}
{"op":"mcm","clk":"11978447035","pt":1724790526599,"mc":[{"id":"1.232352479","rc":[{"batb":[[0,3,20.2],[1,1.03,200],[2,1.02,200]],"ltp":3.05,"tv":227.18,"id":48610314}]}]}
{"op":"mcm","clk":"11978447511","pt":1724790530402,"mc":[{"id":"1.232352479","rc":[{"batb":[[0,3.05,5],[1,3,20.2],[2,1.03,200]],"ltp":3.05,"tv":227.18,"id":48610314}]}]}
{"op":"mcm","clk":"11978447937","pt":1724790533991,"mc":[{"id":"1.232352479","rc":[{"batb":[[0,3,20.2],[1,1.03,200],[2,1.02,200]],"ltp":3.05,"tv":227.18,"id":48610314}]}]}
{"op":"mcm","clk":"11978448211","pt":1724790536505,"mc":[{"id":"1.232352479","rc":[{"batb":[[0,3.05,5],[1,3,20.2],[2,1.03,200]],"ltp":3.05,"tv":227.18,"id":48610314}]}]}
{"op":"mcm","clk":"11978448567","pt":1724790539880,"mc":[{"id":"1.232352479","rc":[{"batb":[[0,3,20.2],[1,1.03,200],[2,1.02,200]],"ltp":3.05,"tv":227.18,"id":48610314}]}]}
{"op":"mcm","clk":"11978448855","pt":1724790542487,"mc":[{"id":"1.232352479","rc":[{"batb":[[0,3.05,5],[1,3,20.2],[2,1.03,200]],"ltp":3.05,"tv":227.18,"id":48610314}]}]}
{"op":"mcm","clk":"11978449247","pt":1724790545907,"mc":[{"id":"1.232352479","rc":[{"batb":[[0,3,20.2],[1,1.03,200],[2,1.02,200]],"ltp":3.05,"tv":227.18,"id":48610314}]}]}
{"op":"mcm","clk":"11978449531","pt":1724790548499,"mc":[{"id":"1.232352479","rc":[{"batb":[[0,3.05,5],[1,3,20.2],[2,1.03,200]],"ltp":3.05,"tv":227.18,"id":48610314}]}]}
{"op":"mcm","clk":"11978450107","pt":1724790552040,"mc":[{"id":"1.232352479","rc":[{"batb":[[0,3,20.2],[1,1.03,200],[2,1.02,200]],"ltp":3.05,"tv":227.18,"id":48610314}]}]}
{"op":"mcm","clk":"11978450556","pt":1724790555315,"mc":[{"id":"1.232352479","rc":[{"batb":[[0,3.05,5],[1,3,20.2],[2,1.03,200]],"ltp":3.05,"tv":227.18,"id":48610314}]}]}
{"op":"mcm","clk":"11978450990","pt":1724790558838,"mc":[{"id":"1.232352479","rc":[{"batb":[[0,3,20.2],[1,1.03,200],[2,1.02,200]],"ltp":3.05,"tv":227.18,"id":48610314}]}]}
{"op":"mcm","clk":"11978451458","pt":1724790562739,"mc":[{"id":"1.232352479","rc":[{"batb":[[0,3.05,5],[1,3,20.2],[2,1.03,200]],"ltp":3.05,"tv":227.18,"id":48610314}]}]}
{"op":"mcm","clk":"11978451874","pt":1724790566129,"mc":[{"id":"1.232352479","rc":[{"batb":[[0,3,20.2],[1,1.03,200],[2,1.02,200]],"ltp":3.05,"tv":227.18,"id":48610314}]}]}
{"op":"mcm","clk":"11978452226","pt":1724790569340,"mc":[{"id":"1.232352479","rc":[{"batb":[[0,3.05,5],[1,3,20.2],[2,1.03,200]],"ltp":3.05,"tv":227.18,"id":48610314}]}]}
{"op":"mcm","clk":"11978452614","pt":1724790572640,"mc":[{"id":"1.232352479","rc":[{"batb":[[0,3,20.2],[1,1.03,200],[2,1.02,200]],"ltp":3.05,"tv":227.18,"id":48610314}]}]}
{"op":"mcm","clk":"11978452999","pt":1724790575859,"mc":[{"id":"1.232352479","rc":[{"batb":[[0,3.05,5],[1,3,20.2],[2,1.03,200]],"ltp":3.05,"tv":227.18,"id":48610314}]}]}
{"op":"mcm","clk":"11978453329","pt":1724790579130,"mc":[{"id":"1.232352479","rc":[{"batb":[[0,3,20.2],[1,1.03,200],[2,1.02,200]],"ltp":3.05,"tv":227.18,"id":48610314}]}]}
{"op":"mcm","clk":"11978453725","pt":1724790582720,"mc":[{"id":"1.232352479","rc":[{"batb":[[0,3.05,5],[1,3,20.2],[2,1.03,200]],"ltp":3.05,"tv":227.18,"id":48610314}]}]}
{"op":"mcm","clk":"11978454098","pt":1724790586042,"mc":[{"id":"1.232352479","rc":[{"batb":[[0,3,20.2],[1,1.03,200],[2,1.02,200]],"ltp":3.05,"tv":227.18,"id":48610314}]}]}
{"op":"mcm","clk":"11978454471","pt":1724790589148,"mc":[{"id":"1.232352479","rc":[{"batb":[[0,3.05,5],[1,3,20.2],[2,1.03,200]],"ltp":3.05,"tv":227.18,"id":48610314}]}]}
{"op":"mcm","clk":"11978454861","pt":1724790592423,"mc":[{"id":"1.232352479","rc":[{"batb":[[0,3,20.2],[1,1.03,200],[2,1.02,200]],"ltp":3.05,"tv":227.18,"id":48610314}]}]}
{"op":"mcm","clk":"11978455149","pt":1724790595073,"mc":[{"id":"1.232352479","rc":[{"batb":[[0,3.05,5],[1,3,20.2],[2,1.03,200]],"ltp":3.05,"tv":227.18,"id":48610314}]}]}
{"op":"mcm","clk":"11978455512","pt":1724790598565,"mc":[{"id":"1.232352479","rc":[{"batb":[[0,3,20.2],[1,1.03,200],[2,1.02,200]],"ltp":3.05,"tv":227.18,"id":48610314}]}]}
{"op":"mcm","clk":"11978455760","pt":1724790600751,"mc":[{"id":"1.232352479","rc":[{"batb":[[0,3.05,5],[1,3,20.2],[2,1.03,200]],"ltp":3.05,"tv":227.18,"id":48610314}]}]}
{"op":"mcm","clk":"11978456147","pt":1724790604186,"mc":[{"id":"1.232352479","rc":[{"batb":[[0,3,20.2],[1,1.03,200],[2,1.02,200]],"ltp":3.05,"tv":227.18,"id":48610314}]}]}
{"op":"mcm","clk":"11978456465","pt":1724790606692,"mc":[{"id":"1.232352479","rc":[{"batb":[[0,3.05,5],[1,3,20.2],[2,1.03,200]],"ltp":3.05,"tv":227.18,"id":48610314}]}]}
{"op":"mcm","clk":"11978456885","pt":1724790609966,"mc":[{"id":"1.232352479","rc":[{"batb":[[0,3,20.2],[1,1.03,200],[2,1.02,200]],"ltp":3.05,"tv":227.18,"id":48610314}]}]}
{"op":"mcm","clk":"11978457249","pt":1724790612773,"mc":[{"id":"1.232352479","rc":[{"batb":[[0,3.05,5],[1,3,20.2],[2,1.03,200]],"ltp":3.05,"tv":227.18,"id":48610314}]}]}
{"op":"mcm","clk":"11978457675","pt":1724790616094,"mc":[{"id":"1.232352479","rc":[{"batb":[[0,3,20.2],[1,1.03,200],[2,1.02,200]],"ltp":3.05,"tv":227.18,"id":48610314}]}]}
{"op":"mcm","clk":"11978458000","pt":1724790618688,"mc":[{"id":"1.232352479","rc":[{"batb":[[0,3.05,5],[1,3,20.2],[2,1.03,200]],"ltp":3.05,"tv":227.18,"id":48610314}]}]}
{"op":"mcm","clk":"11978458385","pt":1724790621978,"mc":[{"id":"1.232352479","rc":[{"batb":[[0,3,20.2],[1,1.03,200],[2,1.02,200]],"ltp":3.05,"tv":227.18,"id":48610314}]}]}
{"op":"mcm","clk":"11978458698","pt":1724790624579,"mc":[{"id":"1.232352479","rc":[{"batb":[[0,3.05,5],[1,3,20.2],[2,1.03,200]],"ltp":3.05,"tv":227.18,"id":48610314}]}]}
{"op":"mcm","clk":"11978459146","pt":1724790628007,"mc":[{"id":"1.232352479","rc":[{"batb":[[0,3,20.2],[1,1.03,200],[2,1.02,200]],"ltp":3.05,"tv":227.18,"id":48610314}]}]}
{"op":"mcm","clk":"11978459445","pt":1724790630340,"mc":[{"id":"1.232352479","rc":[{"batb":[[0,3.05,5],[1,3,20.2],[2,1.03,200]],"ltp":3.05,"tv":227.18,"id":48610314}]}]}
{"op":"mcm","clk":"11978459892","pt":1724790633807,"mc":[{"id":"1.232352479","rc":[{"batb":[[0,3,20.2],[1,1.03,200],[2,1.02,200]],"ltp":3.05,"tv":227.18,"id":48610314}]}]}
{"op":"mcm","clk":"11978460411","pt":1724790637941,"mc":[{"id":"1.232352479","rc":[{"batb":[[0,3.05,5],[1,3,20.2],[2,1.03,200]],"ltp":3.05,"tv":227.18,"id":48610314}]}]}
{"op":"mcm","clk":"11978460804","pt":1724790641200,"mc":[{"id":"1.232352479","rc":[{"batb":[[0,3,20.2],[1,1.03,200],[2,1.02,200]],"ltp":3.05,"tv":227.18,"id":48610314}]}]}
{"op":"mcm","clk":"11978461116","pt":1724790643818,"mc":[{"id":"1.232352479","rc":[{"batb":[[0,3.05,5],[1,3,20.2],[2,1.03,200]],"ltp":3.05,"tv":227.18,"id":48610314}]}]}
{"op":"mcm","clk":"11978461520","pt":1724790647087,"mc":[{"id":"1.232352479","rc":[{"batb":[[0,3,20.2],[1,1.03,200],[2,1.02,200]],"ltp":3.05,"tv":227.18,"id":48610314}]}]}
{"op":"mcm","clk":"11978461843","pt":1724790649621,"mc":[{"id":"1.232352479","rc":[{"batb":[[0,3.05,5],[1,3,20.2],[2,1.03,200]],"ltp":3.05,"tv":227.18,"id":48610314}]}]}
{"op":"mcm","clk":"11978462237","pt":1724790653017,"mc":[{"id":"1.232352479","rc":[{"batb":[[0,3,20.2],[1,1.03,200],[2,1.02,200]],"ltp":3.05,"tv":227.18,"id":48610314}]}]}
{"op":"mcm","clk":"11978462838","pt":1724790658107,"mc":[{"id":"1.232352479","rc":[{"batb":[[0,3.05,5],[1,3,20.2],[2,1.03,200]],"ltp":3.05,"tv":227.18,"id":48610314}]}]}
{"op":"mcm","clk":"11978463207","pt":1724790661401,"mc":[{"id":"1.232352479","rc":[{"batb":[[0,3,20.2],[1,1.03,200],[2,1.02,200]],"ltp":3.05,"tv":227.18,"id":48610314}]}]}
{"op":"mcm","clk":"11978463507","pt":1724790663899,"mc":[{"id":"1.232352479","rc":[{"batb":[[0,3.05,5],[1,3,20.2],[2,1.03,200]],"ltp":3.05,"tv":227.18,"id":48610314}]}]}
{"op":"mcm","clk":"11978463874","pt":1724790667532,"mc":[{"id":"1.232352479","rc":[{"batb":[[0,3,20.2],[1,1.03,200],[2,1.02,200]],"ltp":3.05,"tv":227.18,"id":48610314}]}]}
{"op":"mcm","clk":"11978464206","pt":1724790670635,"mc":[{"id":"1.232352479","rc":[{"batb":[[0,3.05,5],[1,3,20.2],[2,1.03,200]],"ltp":3.05,"tv":227.18,"id":48610314}]}]}
{"op":"mcm","clk":"11978464585","pt":1724790673920,"mc":[{"id":"1.232352479","rc":[{"batb":[[0,3,20.2],[1,1.03,200],[2,1.02,200]],"ltp":3.05,"tv":227.18,"id":48610314}]}]}
{"op":"mcm","clk":"11978465288","pt":1724790679728,"mc":[{"id":"1.232352479","rc":[{"batb":[[0,3.05,5],[1,3,20.2],[2,1.03,200]],"ltp":3.05,"tv":227.18,"id":48610314}]}]}
{"op":"mcm","clk":"11978465670","pt":1724790683314,"mc":[{"id":"1.232352479","rc":[{"batb":[[0,3,20.2],[1,1.03,200],[2,1.02,200]],"ltp":3.05,"tv":227.18,"id":48610314}]}]}
{"op":"mcm","clk":"11978466080","pt":1724790687225,"mc":[{"id":"1.232352479","rc":[{"batb":[[0,3.05,5],[1,3,20.2],[2,1.03,200]],"ltp":3.05,"tv":227.18,"id":48610314}]}]}
{"op":"mcm","clk":"11978466543","pt":1724790690625,"mc":[{"id":"1.232352479","rc":[{"batb":[[0,3,20.2],[1,1.03,200],[2,1.02,200]],"ltp":3.05,"tv":227.18,"id":48610314}]}]}
{"op":"mcm","clk":"11978466932","pt":1724790693277,"mc":[{"id":"1.232352479","rc":[{"batb":[[0,3.05,5],[1,3,20.2],[2,1.03,200]],"ltp":3.05,"tv":227.18,"id":48610314}]}]}
{"op":"mcm","clk":"11978467394","pt":1724790696567,"mc":[{"id":"1.232352479","rc":[{"batb":[[0,3,20.2],[1,1.03,200],[2,1.02,200]],"ltp":3.05,"tv":227.18,"id":48610314}]}]}
{"op":"mcm","clk":"11978467805","pt":1724790700346,"mc":[{"id":"1.232352479","rc":[{"batb":[[0,3.05,5],[1,3,20.2],[2,1.03,200]],"ltp":3.05,"tv":227.18,"id":48610314}]}]}
{"op":"mcm","clk":"11978468141","pt":1724790703664,"mc":[{"id":"1.232352479","rc":[{"batb":[[0,3,20.2],[1,1.03,200],[2,1.02,200]],"ltp":3.05,"tv":227.18,"id":48610314}]}]}
{"op":"mcm","clk":"11978468463","pt":1724790706934,"mc":[{"id":"1.232352479","rc":[{"batb":[[0,3.05,5],[1,3,20.2],[2,1.03,200]],"ltp":3.05,"tv":227.18,"id":48610314}]}]}
{"op":"mcm","clk":"11978468850","pt":1724790710358,"mc":[{"id":"1.232352479","rc":[{"batb":[[0,3,20.2],[1,1.03,200],[2,1.02,200]],"ltp":3.05,"tv":227.18,"id":48610314}]}]}
{"op":"mcm","clk":"11978469239","pt":1724790713543,"mc":[{"id":"1.232352479","rc":[{"batb":[[0,3.05,5],[1,3,20.2],[2,1.03,200]],"ltp":3.05,"tv":227.18,"id":48610314}]}]}
{"op":"mcm","clk":"11978469615","pt":1724790716859,"mc":[{"id":"1.232352479","rc":[{"batb":[[0,3,20.2],[1,1.03,200],[2,1.02,200]],"ltp":3.05,"tv":227.18,"id":48610314}]}]}
{"op":"mcm","clk":"11978470016","pt":1724790720350,"mc":[{"id":"1.232352479","rc":[{"batb":[[0,3.05,5],[1,3,20.2],[2,1.03,200]],"ltp":3.05,"tv":227.18,"id":48610314}]}]}
{"op":"mcm","clk":"11978470372","pt":1724790723558,"mc":[{"id":"1.232352479","rc":[{"batb":[[0,3,20.2],[1,1.03,200],[2,1.02,200]],"ltp":3.05,"tv":227.18,"id":48610314}]}]}
{"op":"mcm","clk":"11978470937","pt":1724790728392,"mc":[{"id":"1.232352479","rc":[{"batb":[[0,3.05,5],[1,3,20.2],[2,1.03,200]],"ltp":3.05,"tv":227.18,"id":48610314}]}]}
{"op":"mcm","clk":"11978471309","pt":1724790731766,"mc":[{"id":"1.232352479","rc":[{"batb":[[0,3,20.2],[1,1.03,200],[2,1.02,200]],"ltp":3.05,"tv":227.18,"id":48610314}]}]}
{"op":"mcm","clk":"11978471573","pt":1724790734256,"mc":[{"id":"1.232352479","rc":[{"batb":[[0,3.05,5],[1,3,20.2],[2,1.03,200]],"ltp":3.05,"tv":227.18,"id":48610314}]}]}
{"op":"mcm","clk":"11978471959","pt":1724790737785,"mc":[{"id":"1.232352479","rc":[{"batb":[[0,3,20.2],[1,1.03,200],[2,1.02,200]],"ltp":3.05,"tv":227.18,"id":48610314}]}]}
{"op":"mcm","clk":"11978472261","pt":1724790739975,"mc":[{"id":"1.232352479","rc":[{"batb":[[0,3.05,5],[1,3,20.2],[2,1.03,200]],"ltp":3.05,"tv":227.18,"id":48610314}]}]}
{"op":"mcm","clk":"11978472695","pt":1724790743406,"mc":[{"id":"1.232352479","rc":[{"batb":[[0,3,20.2],[1,1.03,200],[2,1.02,200]],"ltp":3.05,"tv":227.18,"id":48610314}]}]}
{"op":"mcm","clk":"11978473022","pt":1724790746166,"mc":[{"id":"1.232352479","rc":[{"batb":[[0,3.05,5],[1,3,20.2],[2,1.03,200]],"ltp":3.05,"tv":227.18,"id":48610314}]}]}
{"op":"mcm","clk":"11978473344","pt":1724790749487,"mc":[{"id":"1.232352479","rc":[{"batb":[[0,3,20.2],[1,1.03,200],[2,1.02,200]],"ltp":3.05,"tv":227.18,"id":48610314}]}]}
{"op":"mcm","clk":"11978473655","pt":1724790752194,"mc":[{"id":"1.232352479","rc":[{"batb":[[0,3.05,5],[1,3,20.2],[2,1.03,200]],"ltp":3.05,"tv":227.18,"id":48610314}]}]}
{"op":"mcm","clk":"11978474064","pt":1724790755679,"mc":[{"id":"1.232352479","rc":[{"batb":[[0,3,20.2],[1,1.03,200],[2,1.02,200]],"ltp":3.05,"tv":227.18,"id":48610314}]}]}
{"op":"mcm","clk":"11978474435","pt":1724790758791,"mc":[{"id":"1.232352479","rc":[{"batb":[[0,3.05,5],[1,3,20.2],[2,1.03,200]],"ltp":3.05,"tv":227.18,"id":48610314}]}]}
{"op":"mcm","clk":"11978474793","pt":1724790762103,"mc":[{"id":"1.232352479","rc":[{"batb":[[0,3,20.2],[1,1.03,200],[2,1.02,200]],"ltp":3.05,"tv":227.18,"id":48610314}]}]}
{"op":"mcm","clk":"11978475459","pt":1724790768115,"mc":[{"id":"1.232352479","rc":[{"batb":[[0,3.05,5],[1,3,20.2],[2,1.03,200]],"ltp":3.05,"tv":227.18,"id":48610314}]}]}
{"op":"mcm","clk":"11978475878","pt":1724790771395,"mc":[{"id":"1.232352479","rc":[{"batb":[[0,3,20.2],[1,1.03,200],[2,1.02,200]],"ltp":3.05,"tv":227.18,"id":48610314}]}]}
{"op":"mcm","clk":"11978476200","pt":1724790773683,"mc":[{"id":"1.232352479","rc":[{"batb":[[0,3.05,5],[1,3,20.2],[2,1.03,200]],"ltp":3.05,"tv":227.18,"id":48610314}]}]}
{"op":"mcm","clk":"11978476572","pt":1724790777098,"mc":[{"id":"1.232352479","rc":[{"batb":[[0,3,20.2],[1,1.03,200],[2,1.02,200]],"ltp":3.05,"tv":227.18,"id":48610314}]}]}
{"op":"mcm","clk":"11978476911","pt":1724790780225,"mc":[{"id":"1.232352479","rc":[{"batb":[[0,3.05,5],[1,3,20.2],[2,1.03,200]],"ltp":3.05,"tv":227.18,"id":48610314}]}]}
{"op":"mcm","clk":"11978477327","pt":1724790783692,"mc":[{"id":"1.232352479","rc":[{"batb":[[0,3,20.2],[1,1.03,200],[2,1.02,200]],"ltp":3.05,"tv":227.18,"id":48610314}]}]}
{"op":"mcm","clk":"11978477731","pt":1724790787312,"mc":[{"id":"1.232352479","rc":[{"batb":[[0,3.05,5],[1,3,20.2],[2,1.03,200]],"ltp":3.05,"tv":227.18,"id":48610314}]}]}
{"op":"mcm","clk":"11978478081","pt":1724790790622,"mc":[{"id":"1.232352479","rc":[{"batb":[[0,3,20.2],[1,1.03,200],[2,1.02,200]],"ltp":3.05,"tv":227.18,"id":48610314}]}]}
{"op":"mcm","clk":"11978478399","pt":1724790793627,"mc":[{"id":"1.232352479","rc":[{"batb":[[0,3.05,5],[1,3,20.2],[2,1.03,200]],"ltp":3.05,"tv":227.18,"id":48610314}]}]}
{"op":"mcm","clk":"11978478780","pt":1724790796906,"mc":[{"id":"1.232352479","rc":[{"batb":[[0,3,20.2],[1,1.03,200],[2,1.02,200]],"ltp":3.05,"tv":227.18,"id":48610314}]}]}
{"op":"mcm","clk":"11978479145","pt":1724790800225,"mc":[{"id":"1.232352479","rc":[{"batb":[[0,3.05,5],[1,3,20.2],[2,1.03,200]],"ltp":3.05,"tv":227.18,"id":48610314}]}]}
{"op":"mcm","clk":"11978479496","pt":1724790803541,"mc":[{"id":"1.232352479","rc":[{"batb":[[0,3,20.2],[1,1.03,200],[2,1.02,200]],"ltp":3.05,"tv":227.18,"id":48610314}]}]}
{"op":"mcm","clk":"11978479801","pt":1724790806441,"mc":[{"id":"1.232352479","rc":[{"batb":[[0,3.05,5],[1,3,20.2],[2,1.03,200]],"ltp":3.05,"tv":227.18,"id":48610314}]}]}
{"op":"mcm","clk":"11978480212","pt":1724790810326,"mc":[{"id":"1.232352479","rc":[{"batb":[[0,3,20.2],[1,1.03,200],[2,1.02,200]],"ltp":3.05,"tv":227.18,"id":48610314}]}]}
{"op":"mcm","clk":"11978480494","pt":1724790812717,"mc":[{"id":"1.232352479","rc":[{"batb":[[0,3.05,5],[1,3,20.2],[2,1.03,200]],"ltp":3.05,"tv":227.18,"id":48610314}]}]}
{"op":"mcm","clk":"11978480889","pt":1724790816034,"mc":[{"id":"1.232352479","rc":[{"batb":[[0,3,20.2],[1,1.03,200],[2,1.02,200]],"ltp":3.05,"tv":227.18,"id":48610314}]}]}
{"op":"mcm","clk":"11978481172","pt":1724790818725,"mc":[{"id":"1.232352479","rc":[{"batb":[[0,3.05,5],[1,3,20.2],[2,1.03,200]],"ltp":3.05,"tv":227.18,"id":48610314}]}]}
{"op":"mcm","clk":"11978481561","pt":1724790822040,"mc":[{"id":"1.232352479","rc":[{"batb":[[0,3,20.2],[1,1.03,200],[2,1.02,200]],"ltp":3.05,"tv":227.18,"id":48610314}]}]}
{"op":"mcm","clk":"11978481922","pt":1724790825363,"mc":[{"id":"1.232352479","rc":[{"batb":[[0,3.05,5],[1,3,20.2],[2,1.03,200]],"ltp":3.05,"tv":227.18,"id":48610314}]}]}
{"op":"mcm","clk":"11978482336","pt":1724790828836,"mc":[{"id":"1.232352479","rc":[{"batb":[[0,3,20.2],[1,1.03,200],[2,1.02,200]],"ltp":3.05,"tv":227.18,"id":48610314}]}]}
{"op":"mcm","clk":"11978482755","pt":1724790832560,"mc":[{"id":"1.232352479","rc":[{"batb":[[0,3.05,5],[1,3,20.2],[2,1.03,200]],"ltp":3.05,"tv":227.18,"id":48610314}]}]}
{"op":"mcm","clk":"11978483111","pt":1724790836048,"mc":[{"id":"1.232352479","rc":[{"batb":[[0,3,20.2],[1,1.03,200],[2,1.02,200]],"ltp":3.05,"tv":227.18,"id":48610314}]}]}
{"op":"mcm","clk":"11978483387","pt":1724790838950,"mc":[{"id":"1.232352479","rc":[{"batb":[[0,3.05,5],[1,3,20.2],[2,1.03,200]],"ltp":3.05,"tv":227.18,"id":48610314}]}]}
{"op":"mcm","clk":"11978483733","pt":1724790842488,"mc":[{"id":"1.232352479","rc":[{"batb":[[0,3,20.2],[1,1.03,200],[2,1.02,200]],"ltp":3.05,"tv":227.18,"id":48610314}]}]}
{"op":"mcm","clk":"11978484380","pt":1724790849192,"mc":[{"id":"1.232352479","rc":[{"batb":[[0,3.05,5],[1,3,20.2],[2,1.03,200]],"ltp":3.05,"tv":227.18,"id":48610314}]}]}
{"op":"mcm","clk":"11978484753","pt":1724790852882,"mc":[{"id":"1.232352479","rc":[{"batb":[[0,3,20.2],[1,1.03,200],[2,1.02,200]],"ltp":3.05,"tv":227.18,"id":48610314}]}]}
{"op":"mcm","clk":"11978485102","pt":1724790856298,"mc":[{"id":"1.232352479","rc":[{"batb":[[0,3.05,5],[1,3,20.2],[2,1.03,200]],"ltp":3.05,"tv":227.18,"id":48610314}]}]}
{"op":"mcm","clk":"11978485453","pt":1724790859718,"mc":[{"id":"1.232352479","rc":[{"batb":[[0,3,20.2],[1,1.03,200],[2,1.02,200]],"ltp":3.05,"tv":227.18,"id":48610314}]}]}
{"op":"mcm","clk":"11978485752","pt":1724790862489,"mc":[{"id":"1.232352479","rc":[{"batb":[[0,3.05,5],[1,3,20.2],[2,1.03,200]],"ltp":3.05,"tv":227.18,"id":48610314}]}]}
{"op":"mcm","clk":"11978486107","pt":1724790866095,"mc":[{"id":"1.232352479","rc":[{"batb":[[0,3,20.2],[1,1.03,200],[2,1.02,200]],"ltp":3.05,"tv":227.18,"id":48610314}]}]}
{"op":"mcm","clk":"11978486335","pt":1724790868425,"mc":[{"id":"1.232352479","rc":[{"batb":[[0,3.05,5],[1,3,20.2],[2,1.03,200]],"ltp":3.05,"tv":227.18,"id":48610314}]}]}
{"op":"mcm","clk":"11978486679","pt":1724790871792,"mc":[{"id":"1.232352479","rc":[{"batb":[[0,3,20.2],[1,1.03,200],[2,1.02,200]],"ltp":3.05,"tv":227.18,"id":48610314}]}]}
{"op":"mcm","clk":"11978486943","pt":1724790874480,"mc":[{"id":"1.232352479","rc":[{"batb":[[0,3.05,5],[1,3,20.2],[2,1.03,200]],"ltp":3.05,"tv":227.18,"id":48610314}]}]}
{"op":"mcm","clk":"11978487310","pt":1724790877789,"mc":[{"id":"1.232352479","rc":[{"batb":[[0,3,20.2],[1,1.03,200],[2,1.02,200]],"ltp":3.05,"tv":227.18,"id":48610314}]}]}
{"op":"mcm","clk":"11978487564","pt":1724790880163,"mc":[{"id":"1.232352479","rc":[{"batb":[[0,3.05,5],[1,3,20.2],[2,1.03,200]],"ltp":3.05,"tv":227.18,"id":48610314}]}]}
{"op":"mcm","clk":"11978487932","pt":1724790883784,"mc":[{"id":"1.232352479","rc":[{"batb":[[0,3,20.2],[1,1.03,200],[2,1.02,200]],"ltp":3.05,"tv":227.18,"id":48610314}]}]}
{"op":"mcm","clk":"11978488214","pt":1724790886416,"mc":[{"id":"1.232352479","rc":[{"batb":[[0,3.05,5],[1,3,20.2],[2,1.03,200]],"ltp":3.05,"tv":227.18,"id":48610314}]}]}
{"op":"mcm","clk":"11978488550","pt":1724790889676,"mc":[{"id":"1.232352479","rc":[{"batb":[[0,3,20.2],[1,1.03,200],[2,1.02,200]],"ltp":3.05,"tv":227.18,"id":48610314}]}]}
{"op":"mcm","clk":"11978488800","pt":1724790892204,"mc":[{"id":"1.232352479","rc":[{"batb":[[0,3.05,5],[1,3,20.2],[2,1.03,200]],"ltp":3.05,"tv":227.18,"id":48610314}]}]}
{"op":"mcm","clk":"11978489164","pt":1724790895830,"mc":[{"id":"1.232352479","rc":[{"batb":[[0,3,20.2],[1,1.03,200],[2,1.02,200]],"ltp":3.05,"tv":227.18,"id":48610314}]}]}
{"op":"mcm","clk":"11978489441","pt":1724790898409,"mc":[{"id":"1.232352479","rc":[{"batb":[[0,3.05,5],[1,3,20.2],[2,1.03,200]],"ltp":3.05,"tv":227.18,"id":48610314}]}]}
{"op":"mcm","clk":"11978489784","pt":1724790901704,"mc":[{"id":"1.232352479","rc":[{"batb":[[0,3,20.2],[1,1.03,200],[2,1.02,200]],"ltp":3.05,"tv":227.18,"id":48610314}]}]}
{"op":"mcm","clk":"11978490062","pt":1724790904221,"mc":[{"id":"1.232352479","rc":[{"batb":[[0,3.05,5],[1,3,20.2],[2,1.03,200]],"ltp":3.05,"tv":227.18,"id":48610314}]}]}
{"op":"mcm","clk":"11978490409","pt":1724790907539,"mc":[{"id":"1.232352479","rc":[{"batb":[[0,3,20.2],[1,1.03,200],[2,1.02,200]],"ltp":3.05,"tv":227.18,"id":48610314}]}]}
{"op":"mcm","clk":"11978490753","pt":1724790910532,"mc":[{"id":"1.232352479","rc":[{"batb":[[0,3.05,5],[1,3,20.2],[2,1.03,200]],"ltp":3.05,"tv":227.18,"id":48610314}]}]}
{"op":"mcm","clk":"11978491133","pt":1724790913837,"mc":[{"id":"1.232352479","rc":[{"batb":[[0,3,20.2],[1,1.03,200],[2,1.02,200]],"ltp":3.05,"tv":227.18,"id":48610314}]}]}
{"op":"mcm","clk":"11978491452","pt":1724790917327,"mc":[{"id":"1.232352479","rc":[{"batb":[[0,3.05,5],[1,3,20.2],[2,1.03,200]],"ltp":3.05,"tv":227.18,"id":48610314}]}]}
{"op":"mcm","clk":"11978491784","pt":1724790920727,"mc":[{"id":"1.232352479","rc":[{"batb":[[0,3,20.2],[1,1.03,200],[2,1.02,200]],"ltp":3.05,"tv":227.18,"id":48610314}]}]}
{"op":"mcm","clk":"11978492060","pt":1724790923406,"mc":[{"id":"1.232352479","rc":[{"batb":[[0,3.05,5],[1,3,20.2],[2,1.03,200]],"ltp":3.05,"tv":227.18,"id":48610314}]}]}
{"op":"mcm","clk":"11978492394","pt":1724790926757,"mc":[{"id":"1.232352479","rc":[{"batb":[[0,3,20.2],[1,1.03,200],[2,1.02,200]],"ltp":3.05,"tv":227.18,"id":48610314}]}]}
{"op":"mcm","clk":"11978492786","pt":1724790930636,"mc":[{"id":"1.232352479","rc":[{"batb":[[0,3.05,5],[1,3,20.2],[2,1.03,200]],"ltp":3.05,"tv":227.18,"id":48610314}]}]}
{"op":"mcm","clk":"11978493136","pt":1724790934050,"mc":[{"id":"1.232352479","rc":[{"batb":[[0,3,20.2],[1,1.03,200],[2,1.02,200]],"ltp":3.05,"tv":227.18,"id":48610314}]}]}
{"op":"mcm","clk":"11978493387","pt":1724790936635,"mc":[{"id":"1.232352479","rc":[{"batb":[[0,3.05,5],[1,3,20.2],[2,1.03,200]],"ltp":3.05,"tv":227.18,"id":48610314}]}]}
{"op":"mcm","clk":"11978493710","pt":1724790940037,"mc":[{"id":"1.232352479","rc":[{"batb":[[0,3,20.2],[1,1.03,200],[2,1.02,200]],"ltp":3.05,"tv":227.18,"id":48610314}]}]}
{"op":"mcm","clk":"11978493953","pt":1724790942721,"mc":[{"id":"1.232352479","rc":[{"batb":[[0,3.05,5],[1,3,20.2],[2,1.03,200]],"ltp":3.05,"tv":227.18,"id":48610314}]}]}
{"op":"mcm","clk":"11978494289","pt":1724790946028,"mc":[{"id":"1.232352479","rc":[{"batb":[[0,3,20.2],[1,1.03,200],[2,1.02,200]],"ltp":3.05,"tv":227.18,"id":48610314}]}]}
{"op":"mcm","clk":"11978494514","pt":1724790948349,"mc":[{"id":"1.232352479","rc":[{"batb":[[0,3.05,5],[1,3,20.2],[2,1.03,200]],"ltp":3.05,"tv":227.18,"id":48610314}]}]}
{"op":"mcm","clk":"11978494863","pt":1724790951755,"mc":[{"id":"1.232352479","rc":[{"batb":[[0,3,20.2],[1,1.03,200],[2,1.02,200]],"ltp":3.05,"tv":227.18,"id":48610314}]}]}
{"op":"mcm","clk":"11978495208","pt":1724790955488,"mc":[{"id":"1.232352479","rc":[{"batb":[[0,3.05,5],[1,3,20.2],[2,1.03,200]],"ltp":3.05,"tv":227.18,"id":48610314}]}]}
{"op":"mcm","clk":"11978495524","pt":1724790958828,"mc":[{"id":"1.232352479","rc":[{"batb":[[0,3,20.2],[1,1.03,200],[2,1.02,200]],"ltp":3.05,"tv":227.18,"id":48610314}]}]}
{"op":"mcm","clk":"11978495752","pt":1724790961573,"mc":[{"id":"1.232352479","rc":[{"batb":[[0,3.05,5],[1,3,20.2],[2,1.03,200]],"ltp":3.05,"tv":227.18,"id":48610314}]}]}
{"op":"mcm","clk":"11978496078","pt":1724790965054,"mc":[{"id":"1.232352479","rc":[{"batb":[[0,3,20.2],[1,1.03,200],[2,1.02,200]],"ltp":3.05,"tv":227.18,"id":48610314}]}]}
{"op":"mcm","clk":"11978496533","pt":1724790969968,"mc":[{"id":"1.232352479","rc":[{"batb":[[0,3.05,5],[1,3,20.2],[2,1.03,200]],"ltp":3.05,"tv":227.18,"id":48610314}]}]}
{"op":"mcm","clk":"11978496844","pt":1724790973580,"mc":[{"id":"1.232352479","rc":[{"batb":[[0,3,20.2],[1,1.03,200],[2,1.02,200]],"ltp":3.05,"tv":227.18,"id":48610314}]}]}
{"op":"mcm","clk":"11978497088","pt":1724790976375,"mc":[{"id":"1.232352479","rc":[{"batb":[[0,3.05,5],[1,3,20.2],[2,1.03,200]],"ltp":3.05,"tv":227.18,"id":48610314}]}]}
{"op":"mcm","clk":"11978497399","pt":1724790979883,"mc":[{"id":"1.232352479","rc":[{"batb":[[0,3,20.2],[1,1.03,200],[2,1.02,200]],"ltp":3.05,"tv":227.18,"id":48610314}]}]}
{"op":"mcm","clk":"11978497612","pt":1724790982262,"mc":[{"id":"1.232352479","rc":[{"batb":[[0,3.05,5],[1,3,20.2],[2,1.03,200]],"ltp":3.05,"tv":227.18,"id":48610314}]}]}
{"op":"mcm","clk":"11978497909","pt":1724790985675,"mc":[{"id":"1.232352479","rc":[{"batb":[[0,3,20.2],[1,1.03,200],[2,1.02,200]],"ltp":3.05,"tv":227.18,"id":48610314}]}]}
{"op":"mcm","clk":"11978498132","pt":1724790987994,"mc":[{"id":"1.232352479","rc":[{"batb":[[0,3.05,5],[1,3,20.2],[2,1.03,200]],"ltp":3.05,"tv":227.18,"id":48610314}]}]}
{"op":"mcm","clk":"11978498520","pt":1724790991474,"mc":[{"id":"1.232352479","rc":[{"batb":[[0,3,20.2],[1,1.03,200],[2,1.02,200]],"ltp":3.05,"tv":227.18,"id":48610314}]}]}
{"op":"mcm","clk":"11978498714","pt":1724790993702,"mc":[{"id":"1.232352479","rc":[{"batb":[[0,3.05,5],[1,3,20.2],[2,1.03,200]],"ltp":3.05,"tv":227.18,"id":48610314}]}]}
{"op":"mcm","clk":"11978499089","pt":1724790996908,"mc":[{"id":"1.232352479","rc":[{"batb":[[0,3,20.2],[1,1.03,200],[2,1.02,200]],"ltp":3.05,"tv":227.18,"id":48610314}]}]}
{"op":"mcm","clk":"11978499332","pt":1724790999489,"mc":[{"id":"1.232352479","rc":[{"batb":[[0,3.05,5],[1,3,20.2],[2,1.03,200]],"ltp":3.05,"tv":227.18,"id":48610314}]}]}
{"op":"mcm","clk":"11978499667","pt":1724791002901,"mc":[{"id":"1.232352479","rc":[{"batb":[[0,3,20.2],[1,1.03,200],[2,1.02,200]],"ltp":3.05,"tv":227.18,"id":48610314}]}]}
{"op":"mcm","clk":"11978499879","pt":1724791005227,"mc":[{"id":"1.232352479","rc":[{"batb":[[0,3.05,5],[1,3,20.2],[2,1.03,200]],"ltp":3.05,"tv":227.18,"id":48610314}]}]}
{"op":"mcm","clk":"11978500201","pt":1724791008644,"mc":[{"id":"1.232352479","rc":[{"batb":[[0,3,20.2],[1,1.03,200],[2,1.02,200]],"ltp":3.05,"tv":227.18,"id":48610314}]}]}
{"op":"mcm","clk":"11978500525","pt":1724791011735,"mc":[{"id":"1.232352479","rc":[{"batb":[[0,3.05,5],[1,3,20.2],[2,1.03,200]],"ltp":3.05,"tv":227.18,"id":48610314}]}]}
{"op":"mcm","clk":"11978500835","pt":1724791015216,"mc":[{"id":"1.232352479","rc":[{"batb":[[0,3,20.2],[1,1.03,200],[2,1.02,200]],"ltp":3.05,"tv":227.18,"id":48610314}]}]}
{"op":"mcm","clk":"11978501062","pt":1724791017636,"mc":[{"id":"1.232352479","rc":[{"batb":[[0,3.05,5],[1,3,20.2],[2,1.03,200]],"ltp":3.05,"tv":227.18,"id":48610314}]}]}
{"op":"mcm","clk":"11978501399","pt":1724791020952,"mc":[{"id":"1.232352479","rc":[{"batb":[[0,3,20.2],[1,1.03,200],[2,1.02,200]],"ltp":3.05,"tv":227.18,"id":48610314}]}]}
{"op":"mcm","clk":"11978501606","pt":1724791023349,"mc":[{"id":"1.232352479","rc":[{"batb":[[0,3.05,5],[1,3,20.2],[2,1.03,200]],"ltp":3.05,"tv":227.18,"id":48610314}]}]}
{"op":"mcm","clk":"11978501859","pt":1724791026651,"mc":[{"id":"1.232352479","rc":[{"batb":[[0,3,20.2],[1,1.03,200],[2,1.02,200]],"ltp":3.05,"tv":227.18,"id":48610314}]}]}
{"op":"mcm","clk":"11978502141","pt":1724791028935,"mc":[{"id":"1.232352479","rc":[{"batb":[[0,3.05,5],[1,3,20.2],[2,1.03,200]],"ltp":3.05,"tv":227.18,"id":48610314}]}]}
{"op":"mcm","clk":"11978502452","pt":1724791032342,"mc":[{"id":"1.232352479","rc":[{"batb":[[0,3,20.2],[1,1.03,200],[2,1.02,200]],"ltp":3.05,"tv":227.18,"id":48610314}]}]}
{"op":"mcm","clk":"11978502784","pt":1724791037051,"mc":[{"id":"1.232352479","rc":[{"batb":[[0,3.05,5],[1,3,20.2],[2,1.03,200]],"ltp":3.05,"tv":227.18,"id":48610314}]}]}
{"op":"mcm","clk":"11978503078","pt":1724791040366,"mc":[{"id":"1.232352479","rc":[{"batb":[[0,3,20.2],[1,1.03,200],[2,1.02,200]],"ltp":3.05,"tv":227.18,"id":48610314}]}]}
{"op":"mcm","clk":"11978503292","pt":1724791042645,"mc":[{"id":"1.232352479","rc":[{"batb":[[0,3.05,5],[1,3,20.2],[2,1.03,200]],"ltp":3.05,"tv":227.18,"id":48610314}]}]}
{"op":"mcm","clk":"11978503610","pt":1724791046057,"mc":[{"id":"1.232352479","rc":[{"batb":[[0,3,20.2],[1,1.03,200],[2,1.02,200]],"ltp":3.05,"tv":227.18,"id":48610314}]}]}
{"op":"mcm","clk":"11978503907","pt":1724791049668,"mc":[{"id":"1.232352479","rc":[{"batb":[[0,3.05,5],[1,3,20.2],[2,1.03,200]],"ltp":3.05,"tv":227.18,"id":48610314}]}]}
{"op":"mcm","clk":"11978504215","pt":1724791052983,"mc":[{"id":"1.232352479","rc":[{"batb":[[0,3,20.2],[1,1.03,200],[2,1.02,200]],"ltp":3.05,"tv":227.18,"id":48610314}]}]}
{"op":"mcm","clk":"11978504575","pt":1724791056459,"mc":[{"id":"1.232352479","rc":[{"batb":[[0,3.05,5],[1,3,20.2],[2,1.03,200]],"ltp":3.05,"tv":227.18,"id":48610314}]}]}
{"op":"mcm","clk":"11978504894","pt":1724791059879,"mc":[{"id":"1.232352479","rc":[{"batb":[[0,3,20.2],[1,1.03,200],[2,1.02,200]],"ltp":3.05,"tv":227.18,"id":48610314}]}]}
{"op":"mcm","clk":"11978505119","pt":1724791062253,"mc":[{"id":"1.232352479","rc":[{"batb":[[0,3.05,5],[1,3,20.2],[2,1.03,200]],"ltp":3.05,"tv":227.18,"id":48610314}]}]}
{"op":"mcm","clk":"11978505500","pt":1724791065871,"mc":[{"id":"1.232352479","rc":[{"batb":[[0,3,20.2],[1,1.03,200],[2,1.02,200]],"ltp":3.05,"tv":227.18,"id":48610314}]}]}
{"op":"mcm","clk":"11978505740","pt":1724791068304,"mc":[{"id":"1.232352479","rc":[{"batb":[[0,3.05,5],[1,3,20.2],[2,1.03,200]],"ltp":3.05,"tv":227.18,"id":48610314}]}]}
{"op":"mcm","clk":"11978506039","pt":1724791071510,"mc":[{"id":"1.232352479","rc":[{"batb":[[0,3,20.2],[1,1.03,200],[2,1.02,200]],"ltp":3.05,"tv":227.18,"id":48610314}]}]}
{"op":"mcm","clk":"11978506300","pt":1724791074300,"mc":[{"id":"1.232352479","rc":[{"batb":[[0,3.05,5],[1,3,20.2],[2,1.03,200]],"ltp":3.05,"tv":227.18,"id":48610314}]}]}
{"op":"mcm","clk":"11978506589","pt":1724791077622,"mc":[{"id":"1.232352479","rc":[{"batb":[[0,3,20.2],[1,1.03,200],[2,1.02,200]],"ltp":3.05,"tv":227.18,"id":48610314}]}]}
{"op":"mcm","clk":"11978506933","pt":1724791081303,"mc":[{"id":"1.232352479","rc":[{"batb":[[0,3.05,5],[1,3,20.2],[2,1.03,200]],"ltp":3.05,"tv":227.18,"id":48610314}]}]}
{"op":"mcm","clk":"11978507259","pt":1724791084707,"mc":[{"id":"1.232352479","rc":[{"batb":[[0,3,20.2],[1,1.03,200],[2,1.02,200]],"ltp":3.05,"tv":227.18,"id":48610314}]}]}
{"op":"mcm","clk":"11978507498","pt":1724791087312,"mc":[{"id":"1.232352479","rc":[{"batb":[[0,3.05,5],[1,3,20.2],[2,1.03,200]],"ltp":3.05,"tv":227.18,"id":48610314}]}]}
{"op":"mcm","clk":"11978507825","pt":1724791090692,"mc":[{"id":"1.232352479","rc":[{"batb":[[0,3,20.2],[1,1.03,200],[2,1.02,200]],"ltp":3.05,"tv":227.18,"id":48610314}]}]}
{"op":"mcm","clk":"11978508074","pt":1724791093320,"mc":[{"id":"1.232352479","rc":[{"batb":[[0,3.05,5],[1,3,20.2],[2,1.03,200]],"ltp":3.05,"tv":227.18,"id":48610314}]}]}
{"op":"mcm","clk":"11978508392","pt":1724791096727,"mc":[{"id":"1.232352479","rc":[{"batb":[[0,3,20.2],[1,1.03,200],[2,1.02,200]],"ltp":3.05,"tv":227.18,"id":48610314}]}]}
{"op":"mcm","clk":"11978508698","pt":1724791100131,"mc":[{"id":"1.232352479","rc":[{"batb":[[0,3.05,5],[1,3,20.2],[2,1.03,200]],"ltp":3.05,"tv":227.18,"id":48610314}]}]}
{"op":"mcm","clk":"11978509053","pt":1724791103647,"mc":[{"id":"1.232352479","rc":[{"batb":[[0,3,20.2],[1,1.03,200],[2,1.02,200]],"ltp":3.05,"tv":227.18,"id":48610314}]}]}
{"op":"mcm","clk":"11978509277","pt":1724791106021,"mc":[{"id":"1.232352479","rc":[{"batb":[[0,3.05,5],[1,3,20.2],[2,1.03,200]],"ltp":3.05,"tv":227.18,"id":48610314}]}]}
{"op":"mcm","clk":"11978509580","pt":1724791109318,"mc":[{"id":"1.232352479","rc":[{"batb":[[0,3,20.2],[1,1.03,200],[2,1.02,200]],"ltp":3.05,"tv":227.18,"id":48610314}]}]}
{"op":"mcm","clk":"11978509905","pt":1724791112930,"mc":[{"id":"1.232352479","rc":[{"batb":[[0,3.05,5],[1,3,20.2],[2,1.03,200]],"ltp":3.05,"tv":227.18,"id":48610314}]}]}
{"op":"mcm","clk":"11978510191","pt":1724791116336,"mc":[{"id":"1.232352479","rc":[{"batb":[[0,3,20.2],[1,1.03,200],[2,1.02,200]],"ltp":3.05,"tv":227.18,"id":48610314}]}]}
{"op":"mcm","clk":"11978510432","pt":1724791119139,"mc":[{"id":"1.232352479","rc":[{"batb":[[0,3.05,5],[1,3,20.2],[2,1.03,200]],"ltp":3.05,"tv":227.18,"id":48610314}]}]}
{"op":"mcm","clk":"11978510719","pt":1724791122536,"mc":[{"id":"1.232352479","rc":[{"batb":[[0,3,20.2],[1,1.03,200],[2,1.02,200]],"ltp":3.05,"tv":227.18,"id":48610314}]}]}
{"op":"mcm","clk":"11978510946","pt":1724791125064,"mc":[{"id":"1.232352479","rc":[{"batb":[[0,3.05,5],[1,3,20.2],[2,1.03,200]],"ltp":3.05,"tv":227.18,"id":48610314}]}]}
{"op":"mcm","clk":"11978511312","pt":1724791128266,"mc":[{"id":"1.232352479","rc":[{"batb":[[0,3,20.2],[1,1.03,200],[2,1.02,200]],"ltp":3.05,"tv":227.18,"id":48610314}]}]}
{"op":"mcm","clk":"11978511534","pt":1724791130644,"mc":[{"id":"1.232352479","rc":[{"batb":[[0,3.05,5],[1,3,20.2],[2,1.03,200]],"ltp":3.05,"tv":227.18,"id":48610314}]}]}
{"op":"mcm","clk":"11978511882","pt":1724791134071,"mc":[{"id":"1.232352479","rc":[{"batb":[[0,3,20.2],[1,1.03,200],[2,1.02,200]],"ltp":3.05,"tv":227.18,"id":48610314}]}]}
{"op":"mcm","clk":"11978512111","pt":1724791136450,"mc":[{"id":"1.232352479","rc":[{"batb":[[0,3.05,5],[1,3,20.2],[2,1.03,200]],"ltp":3.05,"tv":227.18,"id":48610314}]}]}
{"op":"mcm","clk":"11978512417","pt":1724791139919,"mc":[{"id":"1.232352479","rc":[{"batb":[[0,3,20.2],[1,1.03,200],[2,1.02,200]],"ltp":3.05,"tv":227.18,"id":48610314}]}]}
{"op":"mcm","clk":"11978512633","pt":1724791142407,"mc":[{"id":"1.232352479","rc":[{"batb":[[0,3.05,5],[1,3,20.2],[2,1.03,200]],"ltp":3.05,"tv":227.18,"id":48610314}]}]}
{"op":"mcm","clk":"11978512915","pt":1724791145661,"mc":[{"id":"1.232352479","rc":[{"batb":[[0,3,20.2],[1,1.03,200],[2,1.02,200]],"ltp":3.05,"tv":227.18,"id":48610314}]}]}
{"op":"mcm","clk":"11978513151","pt":1724791148281,"mc":[{"id":"1.232352479","rc":[{"batb":[[0,3.05,5],[1,3,20.2],[2,1.03,200]],"ltp":3.05,"tv":227.18,"id":48610314}]}]}
{"op":"mcm","clk":"11978513502","pt":1724791151699,"mc":[{"id":"1.232352479","rc":[{"batb":[[0,3,20.2],[1,1.03,200],[2,1.02,200]],"ltp":3.05,"tv":227.18,"id":48610314}]}]}
{"op":"mcm","clk":"11978513750","pt":1724791154080,"mc":[{"id":"1.232352479","rc":[{"batb":[[0,3.05,5],[1,3,20.2],[2,1.03,200]],"ltp":3.05,"tv":227.18,"id":48610314}]}]}
{"op":"mcm","clk":"11978514067","pt":1724791157394,"mc":[{"id":"1.232352479","rc":[{"batb":[[0,3,20.2],[1,1.03,200],[2,1.02,200]],"ltp":3.05,"tv":227.18,"id":48610314}]}]}
{"op":"mcm","clk":"11978514332","pt":1724791160100,"mc":[{"id":"1.232352479","rc":[{"batb":[[0,3.05,5],[1,3,20.2],[2,1.03,200]],"ltp":3.05,"tv":227.18,"id":48610314}]}]}
{"op":"mcm","clk":"11978514684","pt":1724791163495,"mc":[{"id":"1.232352479","rc":[{"batb":[[0,3,20.2],[1,1.03,200],[2,1.02,200]],"ltp":3.05,"tv":227.18,"id":48610314}]}]}
{"op":"mcm","clk":"11978515022","pt":1724791166906,"mc":[{"id":"1.232352479","rc":[{"batb":[[0,3.05,5],[1,3,20.2],[2,1.03,200]],"ltp":3.05,"tv":227.18,"id":48610314}]}]}
{"op":"mcm","clk":"11978515336","pt":1724791170201,"mc":[{"id":"1.232352479","rc":[{"batb":[[0,3,20.2],[1,1.03,200],[2,1.02,200]],"ltp":3.05,"tv":227.18,"id":48610314}]}]}
{"op":"mcm","clk":"11978515700","pt":1724791173877,"mc":[{"id":"1.232352479","rc":[{"batb":[[0,3.05,5],[1,3,20.2],[2,1.03,200]],"ltp":3.05,"tv":227.18,"id":48610314}]}]}
{"op":"mcm","clk":"11978516008","pt":1724791177289,"mc":[{"id":"1.232352479","rc":[{"batb":[[0,3,20.2],[1,1.03,200],[2,1.02,200]],"ltp":3.05,"tv":227.18,"id":48610314}]}]}
{"op":"mcm","clk":"11978516224","pt":1724791179815,"mc":[{"id":"1.232352479","rc":[{"batb":[[0,3.05,5],[1,3,20.2],[2,1.03,200]],"ltp":3.05,"tv":227.18,"id":48610314}]}]}
{"op":"mcm","clk":"11978516505","pt":1724791183378,"mc":[{"id":"1.232352479","rc":[{"batb":[[0,3,20.2],[1,1.03,200],[2,1.02,200]],"ltp":3.05,"tv":227.18,"id":48610314}]}]}
{"op":"mcm","clk":"11978516805","pt":1724791187091,"mc":[{"id":"1.232352479","rc":[{"batb":[[0,3.05,5],[1,3,20.2],[2,1.03,200]],"ltp":3.05,"tv":227.18,"id":48610314}]}]}
{"op":"mcm","clk":"11978517058","pt":1724791190500,"mc":[{"id":"1.232352479","rc":[{"batb":[[0,3,20.2],[1,1.03,200],[2,1.02,200]],"ltp":3.05,"tv":227.18,"id":48610314}]}]}
{"op":"mcm","clk":"11978517311","pt":1724791193501,"mc":[{"id":"1.232352479","rc":[{"batb":[[0,3.05,5],[1,3,20.2],[2,1.03,200]],"ltp":3.05,"tv":227.18,"id":48610314}]}]}
{"op":"mcm","clk":"11978517565","pt":1724791196691,"mc":[{"id":"1.232352479","rc":[{"batb":[[0,3,20.2],[1,1.03,200],[2,1.02,200]],"ltp":3.05,"tv":227.18,"id":48610314}]}]}
{"op":"mcm","clk":"11978517790","pt":1724791199110,"mc":[{"id":"1.232352479","rc":[{"batb":[[0,3.05,5],[1,3,20.2],[2,1.03,200]],"ltp":3.05,"tv":227.18,"id":48610314}]}]}
{"op":"mcm","clk":"11978518110","pt":1724791202636,"mc":[{"id":"1.232352479","rc":[{"batb":[[0,3,20.2],[1,1.03,200],[2,1.02,200]],"ltp":3.05,"tv":227.18,"id":48610314}]}]}
{"op":"mcm","clk":"11978518447","pt":1724791206351,"mc":[{"id":"1.232352479","rc":[{"batb":[[0,3.05,5],[1,3,20.2],[2,1.03,200]],"ltp":3.05,"tv":227.18,"id":48610314}]}]}
{"op":"mcm","clk":"11978518758","pt":1724791209826,"mc":[{"id":"1.232352479","rc":[{"batb":[[0,3,20.2],[1,1.03,200],[2,1.02,200]],"ltp":3.05,"tv":227.18,"id":48610314}]}]}
{"op":"mcm","clk":"11978519251","pt":1724791214752,"mc":[{"id":"1.232352479","rc":[{"batb":[[0,3.05,5],[1,3,20.2],[2,1.03,200]],"ltp":3.05,"tv":227.18,"id":48610314}]}]}
{"op":"mcm","clk":"11978519586","pt":1724791218142,"mc":[{"id":"1.232352479","rc":[{"batb":[[0,3,20.2],[1,1.03,200],[2,1.02,200]],"ltp":3.05,"tv":227.18,"id":48610314}]}]}
{"op":"mcm","clk":"11978519884","pt":1724791221566,"mc":[{"id":"1.232352479","rc":[{"batb":[[0,3.05,5],[1,3,20.2],[2,1.03,200]],"ltp":3.05,"tv":227.18,"id":48610314}]}]}
{"op":"mcm","clk":"11978520244","pt":1724791225148,"mc":[{"id":"1.232352479","rc":[{"batb":[[0,3,20.2],[1,1.03,200],[2,1.02,200]],"ltp":3.05,"tv":227.18,"id":48610314}]}]}
{"op":"mcm","clk":"11978520449","pt":1724791227468,"mc":[{"id":"1.232352479","rc":[{"batb":[[0,3.05,5],[1,3,20.2],[2,1.03,200]],"ltp":3.05,"tv":227.18,"id":48610314}]}]}
{"op":"mcm","clk":"11978520757","pt":1724791230927,"mc":[{"id":"1.232352479","rc":[{"batb":[[0,3,20.2],[1,1.03,200],[2,1.02,200]],"ltp":3.05,"tv":227.18,"id":48610314}]}]}
{"op":"mcm","clk":"11978521194","pt":1724791236549,"mc":[{"id":"1.232352479","rc":[{"batb":[[0,3.05,5],[1,3,20.2],[2,1.03,200]],"ltp":3.05,"tv":227.18,"id":48610314}]}]}
{"op":"mcm","clk":"11978521483","pt":1724791239961,"mc":[{"id":"1.232352479","rc":[{"batb":[[0,3,20.2],[1,1.03,200],[2,1.02,200]],"ltp":3.05,"tv":227.18,"id":48610314}]}]}
{"op":"mcm","clk":"11978521734","pt":1724791242545,"mc":[{"id":"1.232352479","rc":[{"batb":[[0,3.05,5],[1,3,20.2],[2,1.03,200]],"ltp":3.05,"tv":227.18,"id":48610314}]}]}
{"op":"mcm","clk":"11978522013","pt":1724791245955,"mc":[{"id":"1.232352479","rc":[{"batb":[[0,3,20.2],[1,1.03,200],[2,1.02,200]],"ltp":3.05,"tv":227.18,"id":48610314}]}]}
{"op":"mcm","clk":"11978522399","pt":1724791250457,"mc":[{"id":"1.232352479","rc":[{"batb":[[0,3.05,5],[1,3,20.2],[2,1.03,200]],"ltp":3.05,"tv":227.18,"id":48610314}]}]}
{"op":"mcm","clk":"11978522760","pt":1724791254065,"mc":[{"id":"1.232352479","rc":[{"batb":[[0,3,20.2],[1,1.03,200],[2,1.02,200]],"ltp":3.05,"tv":227.18,"id":48610314}]}]}
{"op":"mcm","clk":"11978523029","pt":1724791257381,"mc":[{"id":"1.232352479","rc":[{"batb":[[0,3.05,5],[1,3,20.2],[2,1.03,200]],"ltp":3.05,"tv":227.18,"id":48610314}]}]}
{"op":"mcm","clk":"11978523295","pt":1724791260892,"mc":[{"id":"1.232352479","rc":[{"batb":[[0,3,20.2],[1,1.03,200],[2,1.02,200]],"ltp":3.05,"tv":227.18,"id":48610314}]}]}
{"op":"mcm","clk":"11978523487","pt":1724791263162,"mc":[{"id":"1.232352479","rc":[{"batb":[[0,3.05,5],[1,3,20.2],[2,1.03,200]],"ltp":3.05,"tv":227.18,"id":48610314}]}]}
{"op":"mcm","clk":"11978523781","pt":1724791266465,"mc":[{"id":"1.232352479","rc":[{"batb":[[0,3,20.2],[1,1.03,200],[2,1.02,200]],"ltp":3.05,"tv":227.18,"id":48610314}]}]}
{"op":"mcm","clk":"11978524073","pt":1724791269769,"mc":[{"id":"1.232352479","rc":[{"batb":[[0,3.05,5],[1,3,20.2],[2,1.03,200]],"ltp":3.05,"tv":227.18,"id":48610314}]}]}
{"op":"mcm","clk":"11978524357","pt":1724791273172,"mc":[{"id":"1.232352479","rc":[{"batb":[[0,3,20.2],[1,1.03,200],[2,1.02,200]],"ltp":3.05,"tv":227.18,"id":48610314}]}]}
{"op":"mcm","clk":"11978524617","pt":1724791276273,"mc":[{"id":"1.232352479","rc":[{"batb":[[0,3.05,5],[1,3,20.2],[2,1.03,200]],"ltp":3.05,"tv":227.18,"id":48610314}]}]}
{"op":"mcm","clk":"11978524906","pt":1724791279786,"mc":[{"id":"1.232352479","rc":[{"batb":[[0,3,20.2],[1,1.03,200],[2,1.02,200]],"ltp":3.05,"tv":227.18,"id":48610314}]}]}
{"op":"mcm","clk":"11978525110","pt":1724791282382,"mc":[{"id":"1.232352479","rc":[{"batb":[[0,3.05,5],[1,3,20.2],[2,1.03,200]],"ltp":3.05,"tv":227.18,"id":48610314}]}]}
{"op":"mcm","clk":"11978525434","pt":1724791285703,"mc":[{"id":"1.232352479","rc":[{"batb":[[0,3,20.2],[1,1.03,200],[2,1.02,200]],"ltp":3.05,"tv":227.18,"id":48610314}]}]}
{"op":"mcm","clk":"11978525853","pt":1724791290815,"mc":[{"id":"1.232352479","rc":[{"batb":[[0,3.05,5],[1,3,20.2],[2,1.03,200]],"ltp":3.05,"tv":227.18,"id":48610314}]}]}
{"op":"mcm","clk":"11978526118","pt":1724791294129,"mc":[{"id":"1.232352479","rc":[{"batb":[[0,3,20.2],[1,1.03,200],[2,1.02,200]],"ltp":3.05,"tv":227.18,"id":48610314}]}]}
{"op":"mcm","clk":"11978526407","pt":1724791297341,"mc":[{"id":"1.232352479","rc":[{"batb":[[0,3.05,5],[1,3,20.2],[2,1.03,200]],"ltp":3.05,"tv":227.18,"id":48610314}]}]}
{"op":"mcm","clk":"11978526705","pt":1724791300804,"mc":[{"id":"1.232352479","rc":[{"batb":[[0,3,20.2],[1,1.03,200],[2,1.02,200]],"ltp":3.05,"tv":227.18,"id":48610314}]}]}
{"op":"mcm","clk":"11978527050","pt":1724791304824,"mc":[{"id":"1.232352479","rc":[{"batb":[[0,3.05,5],[1,3,20.2],[2,1.03,200]],"ltp":3.05,"tv":227.18,"id":48610314}]}]}
{"op":"mcm","clk":"11978527342","pt":1724791308182,"mc":[{"id":"1.232352479","rc":[{"batb":[[0,3,20.2],[1,1.03,200],[2,1.02,200]],"ltp":3.05,"tv":227.18,"id":48610314}]}]}
{"op":"mcm","clk":"11978527646","pt":1724791311711,"mc":[{"id":"1.232352479","rc":[{"batb":[[0,3.05,5],[1,3,20.2],[2,1.03,200]],"ltp":3.05,"tv":227.18,"id":48610314}]}]}
{"op":"mcm","clk":"11978527922","pt":1724791315228,"mc":[{"id":"1.232352479","rc":[{"batb":[[0,3,20.2],[1,1.03,200],[2,1.02,200]],"ltp":3.05,"tv":227.18,"id":48610314}]}]}
{"op":"mcm","clk":"11978528124","pt":1724791317914,"mc":[{"id":"1.232352479","rc":[{"batb":[[0,3.05,5],[1,3,20.2],[2,1.03,200]],"ltp":3.05,"tv":227.18,"id":48610314}]}]}
{"op":"mcm","clk":"11978528422","pt":1724791321327,"mc":[{"id":"1.232352479","rc":[{"batb":[[0,3,20.2],[1,1.03,200],[2,1.02,200]],"ltp":3.05,"tv":227.18,"id":48610314}]}]}
{"op":"mcm","clk":"11978528615","pt":1724791323813,"mc":[{"id":"1.232352479","rc":[{"batb":[[0,3.05,5],[1,3,20.2],[2,1.03,200]],"ltp":3.05,"tv":227.18,"id":48610314}]}]}
{"op":"mcm","clk":"11978528851","pt":1724791327126,"mc":[{"id":"1.232352479","rc":[{"batb":[[0,3,20.2],[1,1.03,200],[2,1.02,200]],"ltp":3.05,"tv":227.18,"id":48610314}]}]}
{"op":"mcm","clk":"11978529072","pt":1724791329613,"mc":[{"id":"1.232352479","rc":[{"batb":[[0,3.05,5],[1,3,20.2],[2,1.03,200]],"ltp":3.05,"tv":227.18,"id":48610314}]}]}
{"op":"mcm","clk":"11978529438","pt":1724791333232,"mc":[{"id":"1.232352479","rc":[{"batb":[[0,3,20.2],[1,1.03,200],[2,1.02,200]],"ltp":3.05,"tv":227.18,"id":48610314}]}]}
{"op":"mcm","clk":"11978529730","pt":1724791336547,"mc":[{"id":"1.232352479","rc":[{"batb":[[0,3.05,5],[1,3,20.2],[2,1.03,200]],"ltp":3.05,"tv":227.18,"id":48610314}]}]}
{"op":"mcm","clk":"11978530019","pt":1724791339960,"mc":[{"id":"1.232352479","rc":[{"batb":[[0,3,20.2],[1,1.03,200],[2,1.02,200]],"ltp":3.05,"tv":227.18,"id":48610314}]}]}
{"op":"mcm","clk":"11978530249","pt":1724791342960,"mc":[{"id":"1.232352479","rc":[{"batb":[[0,3.05,5],[1,3,20.2],[2,1.03,200]],"ltp":3.05,"tv":227.18,"id":48610314}]}]}
{"op":"mcm","clk":"11978530511","pt":1724791346475,"mc":[{"id":"1.232352479","rc":[{"batb":[[0,3,20.2],[1,1.03,200],[2,1.02,200]],"ltp":3.05,"tv":227.18,"id":48610314}]}]}
{"op":"mcm","clk":"11978530876","pt":1724791351645,"mc":[{"id":"1.232352479","rc":[{"batb":[[0,3.05,5],[1,3,20.2],[2,1.03,200]],"ltp":3.05,"tv":227.18,"id":48610314}]}]}
{"op":"mcm","clk":"11978531125","pt":1724791354959,"mc":[{"id":"1.232352479","rc":[{"batb":[[0,3,20.2],[1,1.03,200],[2,1.02,200]],"ltp":3.05,"tv":227.18,"id":48610314}]}]}
{"op":"mcm","clk":"11978531360","pt":1724791357549,"mc":[{"id":"1.232352479","rc":[{"batb":[[0,3.05,5],[1,3,20.2],[2,1.03,200]],"ltp":3.05,"tv":227.18,"id":48610314}]}]}
{"op":"mcm","clk":"11978531627","pt":1724791361053,"mc":[{"id":"1.232352479","rc":[{"batb":[[0,3,20.2],[1,1.03,200],[2,1.02,200]],"ltp":3.05,"tv":227.18,"id":48610314}]}]}
{"op":"mcm","clk":"11978531801","pt":1724791363689,"mc":[{"id":"1.232352479","rc":[{"batb":[[0,3.05,5],[1,3,20.2],[2,1.03,200]],"ltp":3.05,"tv":227.18,"id":48610314}]}]}
{"op":"mcm","clk":"11978532055","pt":1724791367149,"mc":[{"id":"1.232352479","rc":[{"batb":[[0,3,20.2],[1,1.03,200],[2,1.02,200]],"ltp":3.05,"tv":227.18,"id":48610314}]}]}
{"op":"mcm","clk":"11978532321","pt":1724791370704,"mc":[{"id":"1.232352479","rc":[{"batb":[[0,3.05,5],[1,3,20.2],[2,1.03,200]],"ltp":3.05,"tv":227.18,"id":48610314}]}]}
{"op":"mcm","clk":"11978532526","pt":1724791373964,"mc":[{"id":"1.232352479","rc":[{"batb":[[0,3,20.2],[1,1.03,200],[2,1.02,200]],"ltp":3.05,"tv":227.18,"id":48610314}]}]}
{"op":"mcm","clk":"11978532732","pt":1724791377581,"mc":[{"id":"1.232352479","rc":[{"batb":[[0,3.05,5],[1,3,20.2],[2,1.03,200]],"ltp":3.05,"tv":227.18,"id":48610314}]}]}
{"op":"mcm","clk":"11978532960","pt":1724791380880,"mc":[{"id":"1.232352479","rc":[{"batb":[[0,3,20.2],[1,1.03,200],[2,1.02,200]],"ltp":3.05,"tv":227.18,"id":48610314}]}]}
{"op":"mcm","clk":"11978533134","pt":1724791383470,"mc":[{"id":"1.232352479","rc":[{"batb":[[0,3.05,5],[1,3,20.2],[2,1.03,200]],"ltp":3.05,"tv":227.18,"id":48610314}]}]}
{"op":"mcm","clk":"11978533388","pt":1724791386994,"mc":[{"id":"1.232352479","rc":[{"batb":[[0,3,20.2],[1,1.03,200],[2,1.02,200]],"ltp":3.05,"tv":227.18,"id":48610314}]}]}
{"op":"mcm","clk":"11978533540","pt":1724791389323,"mc":[{"id":"1.232352479","rc":[{"batb":[[0,3.05,5],[1,3,20.2],[2,1.03,200]],"ltp":3.05,"tv":227.18,"id":48610314}]}]}
{"op":"mcm","clk":"11978533738","pt":1724791392668,"mc":[{"id":"1.232352479","rc":[{"batb":[[0,3,20.2],[1,1.03,200],[2,1.02,200]],"ltp":3.05,"tv":227.18,"id":48610314}]}]}
{"op":"mcm","clk":"11978533898","pt":1724791395084,"mc":[{"id":"1.232352479","rc":[{"batb":[[0,3.05,5],[1,3,20.2],[2,1.03,200]],"ltp":3.05,"tv":227.18,"id":48610314}]}]}
{"op":"mcm","clk":"11978534131","pt":1724791398494,"mc":[{"id":"1.232352479","rc":[{"batb":[[0,3,20.2],[1,1.03,200],[2,1.02,200]],"ltp":3.05,"tv":227.18,"id":48610314}]}]}
{"op":"mcm","clk":"11978534289","pt":1724791400812,"mc":[{"id":"1.232352479","rc":[{"batb":[[0,3.05,5],[1,3,20.2],[2,1.03,200]],"ltp":3.05,"tv":227.18,"id":48610314}]}]}
{"op":"mcm","clk":"11978534548","pt":1724791404215,"mc":[{"id":"1.232352479","rc":[{"batb":[[0,3,20.2],[1,1.03,200],[2,1.02,200]],"ltp":3.05,"tv":227.18,"id":48610314}]}]}
{"op":"mcm","clk":"11978534745","pt":1724791407512,"mc":[{"id":"1.232352479","rc":[{"batb":[[0,3.05,5],[1,3,20.2],[2,1.03,200]],"ltp":3.05,"tv":227.18,"id":48610314}]}]}
{"op":"mcm","clk":"11978534996","pt":1724791410822,"mc":[{"id":"1.232352479","rc":[{"batb":[[0,3,20.2],[1,1.03,200],[2,1.02,200]],"ltp":3.05,"tv":227.18,"id":48610314}]}]}
{"op":"mcm","clk":"11978535269","pt":1724791414918,"mc":[{"id":"1.232352479","rc":[{"batb":[[0,3.05,5],[1,3,20.2],[2,1.03,200]],"ltp":3.05,"tv":227.18,"id":48610314}]}]}
{"op":"mcm","clk":"11978535456","pt":1724791418213,"mc":[{"id":"1.232352479","rc":[{"batb":[[0,3,20.2],[1,1.03,200],[2,1.02,200]],"ltp":3.05,"tv":227.18,"id":48610314}]}]}
{"op":"mcm","clk":"11978535645","pt":1724791420791,"mc":[{"id":"1.232352479","rc":[{"batb":[[0,3.05,5],[1,3,20.2],[2,1.03,200]],"ltp":3.05,"tv":227.18,"id":48610314}]}]}
{"op":"mcm","clk":"11978535855","pt":1724791424133,"mc":[{"id":"1.232352479","rc":[{"batb":[[0,3,20.2],[1,1.03,200],[2,1.02,200]],"ltp":3.05,"tv":227.18,"id":48610314}]}]}
{"op":"mcm","clk":"11978536045","pt":1724791426814,"mc":[{"id":"1.232352479","rc":[{"batb":[[0,3.05,5],[1,3,20.2],[2,1.03,200]],"ltp":3.05,"tv":227.18,"id":48610314}]}]}
{"op":"mcm","clk":"11978536264","pt":1724791430203,"mc":[{"id":"1.232352479","rc":[{"batb":[[0,3,20.2],[1,1.03,200],[2,1.02,200]],"ltp":3.05,"tv":227.18,"id":48610314}]}]}
{"op":"mcm","clk":"11978536406","pt":1724791432418,"mc":[{"id":"1.232352479","rc":[{"batb":[[0,3.05,5],[1,3,20.2],[2,1.03,200]],"ltp":3.05,"tv":227.18,"id":48610314}]}]}
{"op":"mcm","clk":"11978536656","pt":1724791436019,"mc":[{"id":"1.232352479","rc":[{"batb":[[0,3,20.2],[1,1.03,200],[2,1.02,200]],"ltp":3.05,"tv":227.18,"id":48610314}]}]}
{"op":"mcm","clk":"11978536848","pt":1724791438545,"mc":[{"id":"1.232352479","rc":[{"batb":[[0,3.05,5],[1,3,20.2],[2,1.03,200]],"ltp":3.05,"tv":227.18,"id":48610314}]}]}
{"op":"mcm","clk":"11978537091","pt":1724791442062,"mc":[{"id":"1.232352479","rc":[{"batb":[[0,3,20.2],[1,1.03,200],[2,1.02,200]],"ltp":3.05,"tv":227.18,"id":48610314}]}]}
{"op":"mcm","clk":"11978537278","pt":1724791444550,"mc":[{"id":"1.232352479","rc":[{"batb":[[0,3.05,5],[1,3,20.2],[2,1.03,200]],"ltp":3.05,"tv":227.18,"id":48610314}]}]}
{"op":"mcm","clk":"11978537547","pt":1724791448036,"mc":[{"id":"1.232352479","rc":[{"batb":[[0,3,20.2],[1,1.03,200],[2,1.02,200]],"ltp":3.05,"tv":227.18,"id":48610314}]}]}
{"op":"mcm","clk":"11978537981","pt":1724791454661,"mc":[{"id":"1.232352479","rc":[{"batb":[[0,3.05,5],[1,3,20.2],[2,1.03,200]],"ltp":3.05,"tv":227.18,"id":48610314}]}]}
{"op":"mcm","clk":"11978538227","pt":1724791458071,"mc":[{"id":"1.232352479","rc":[{"batb":[[0,3,20.2],[1,1.03,200],[2,1.02,200]],"ltp":3.05,"tv":227.18,"id":48610314}]}]}
{"op":"mcm","clk":"11978538470","pt":1724791461696,"mc":[{"id":"1.232352479","rc":[{"batb":[[0,3.05,5],[1,3,20.2],[2,1.03,200]],"ltp":3.05,"tv":227.18,"id":48610314}]}]}
{"op":"mcm","clk":"11978538711","pt":1724791464951,"mc":[{"id":"1.232352479","rc":[{"batb":[[0,3,20.2],[1,1.03,200],[2,1.02,200]],"ltp":3.05,"tv":227.18,"id":48610314}]}]}
{"op":"mcm","clk":"11978538896","pt":1724791468050,"mc":[{"id":"1.232352479","rc":[{"batb":[[0,3.05,5],[1,3,20.2],[2,1.03,200]],"ltp":3.05,"tv":227.18,"id":48610314}]}]}
{"op":"mcm","clk":"11978539157","pt":1724791471366,"mc":[{"id":"1.232352479","rc":[{"batb":[[0,3,20.2],[1,1.03,200],[2,1.02,200]],"ltp":3.05,"tv":227.18,"id":48610314}]}]}
{"op":"mcm","clk":"11978539333","pt":1724791474307,"mc":[{"id":"1.232352479","rc":[{"batb":[[0,3.05,5],[1,3,20.2],[2,1.03,200]],"ltp":3.05,"tv":227.18,"id":48610314}]}]}
{"op":"mcm","clk":"11978539649","pt":1724791477689,"mc":[{"id":"1.232352479","rc":[{"batb":[[0,3,20.2],[1,1.03,200],[2,1.02,200]],"ltp":3.05,"tv":227.18,"id":48610314}]}]}
{"op":"mcm","clk":"11978539921","pt":1724791481007,"mc":[{"id":"1.232352479","rc":[{"batb":[[0,3.05,5],[1,3,20.2],[2,1.03,200]],"ltp":3.05,"tv":227.18,"id":48610314}]}]}
{"op":"mcm","clk":"11978540182","pt":1724791484420,"mc":[{"id":"1.232352479","rc":[{"batb":[[0,3,20.2],[1,1.03,200],[2,1.02,200]],"ltp":3.05,"tv":227.18,"id":48610314}]}]}
{"op":"mcm","clk":"11978540435","pt":1724791487517,"mc":[{"id":"1.232352479","rc":[{"batb":[[0,3.05,5],[1,3,20.2],[2,1.03,200]],"ltp":3.05,"tv":227.18,"id":48610314}]}]}
{"op":"mcm","clk":"11978540731","pt":1724791490798,"mc":[{"id":"1.232352479","rc":[{"batb":[[0,3,20.2],[1,1.03,200],[2,1.02,200]],"ltp":3.05,"tv":227.18,"id":48610314}]}]}
{"op":"mcm","clk":"11978540963","pt":1724791493218,"mc":[{"id":"1.232352479","rc":[{"batb":[[0,3.05,5],[1,3,20.2],[2,1.03,200]],"ltp":3.05,"tv":227.18,"id":48610314}]}]}
{"op":"mcm","clk":"11978541292","pt":1724791496739,"mc":[{"id":"1.232352479","rc":[{"batb":[[0,3,20.2],[1,1.03,200],[2,1.02,200]],"ltp":3.05,"tv":227.18,"id":48610314}]}]}
{"op":"mcm","clk":"11978541521","pt":1724791499204,"mc":[{"id":"1.232352479","rc":[{"batb":[[0,3.05,5],[1,3,20.2],[2,1.03,200]],"ltp":3.05,"tv":227.18,"id":48610314}]}]}
{"op":"mcm","clk":"11978541824","pt":1724791502749,"mc":[{"id":"1.232352479","rc":[{"batb":[[0,3,20.2],[1,1.03,200],[2,1.02,200]],"ltp":3.05,"tv":227.18,"id":48610314}]}]}
{"op":"mcm","clk":"11978541990","pt":1724791505133,"mc":[{"id":"1.232352479","rc":[{"batb":[[0,3.05,5],[1,3,20.2],[2,1.03,200]],"ltp":3.05,"tv":227.18,"id":48610314}]}]}
{"op":"mcm","clk":"11978542211","pt":1724791508402,"mc":[{"id":"1.232352479","rc":[{"batb":[[0,3,20.2],[1,1.03,200],[2,1.02,200]],"ltp":3.05,"tv":227.18,"id":48610314}]}]}
{"op":"mcm","clk":"11978542441","pt":1724791511240,"mc":[{"id":"1.232352479","rc":[{"batb":[[0,3.05,5],[1,3,20.2],[2,1.03,200]],"ltp":3.05,"tv":227.18,"id":48610314}]}]}
{"op":"mcm","clk":"11978542730","pt":1724791514615,"mc":[{"id":"1.232352479","rc":[{"batb":[[0,3,20.2],[1,1.03,200],[2,1.02,200]],"ltp":3.05,"tv":227.18,"id":48610314}]}]}
{"op":"mcm","clk":"11978542889","pt":1724791516842,"mc":[{"id":"1.232352479","rc":[{"batb":[[0,3.05,5],[1,3,20.2],[2,1.03,200]],"ltp":3.05,"tv":227.18,"id":48610314}]}]}
{"op":"mcm","clk":"11978543163","pt":1724791520260,"mc":[{"id":"1.232352479","rc":[{"batb":[[0,3,20.2],[1,1.03,200],[2,1.02,200]],"ltp":3.05,"tv":227.18,"id":48610314}]}]}
{"op":"mcm","clk":"11978543366","pt":1724791522959,"mc":[{"id":"1.232352479","rc":[{"batb":[[0,3.05,5],[1,3,20.2],[2,1.03,200]],"ltp":3.05,"tv":227.18,"id":48610314}]}]}
{"op":"mcm","clk":"11978543605","pt":1724791526420,"mc":[{"id":"1.232352479","rc":[{"batb":[[0,3,20.2],[1,1.03,200],[2,1.02,200]],"ltp":3.05,"tv":227.18,"id":48610314}]}]}
{"op":"mcm","clk":"11978543801","pt":1724791528746,"mc":[{"id":"1.232352479","rc":[{"batb":[[0,3.05,5],[1,3,20.2],[2,1.03,200]],"ltp":3.05,"tv":227.18,"id":48610314}]}]}
{"op":"mcm","clk":"11978544083","pt":1724791532056,"mc":[{"id":"1.232352479","rc":[{"batb":[[0,3,20.2],[1,1.03,200],[2,1.02,200]],"ltp":3.05,"tv":227.18,"id":48610314}]}]}
{"op":"mcm","clk":"11978544252","pt":1724791534431,"mc":[{"id":"1.232352479","rc":[{"batb":[[0,3.05,5],[1,3,20.2],[2,1.03,200]],"ltp":3.05,"tv":227.18,"id":48610314}]}]}
{"op":"mcm","clk":"11978544511","pt":1724791537851,"mc":[{"id":"1.232352479","rc":[{"batb":[[0,3,20.2],[1,1.03,200],[2,1.02,200]],"ltp":3.05,"tv":227.18,"id":48610314}]}]}
{"op":"mcm","clk":"11978544686","pt":1724791540235,"mc":[{"id":"1.232352479","rc":[{"batb":[[0,3.05,5],[1,3,20.2],[2,1.03,200]],"ltp":3.05,"tv":227.18,"id":48610314}]}]}
{"op":"mcm","clk":"11978544953","pt":1724791543657,"mc":[{"id":"1.232352479","rc":[{"batb":[[0,3,20.2],[1,1.03,200],[2,1.02,200]],"ltp":3.05,"tv":227.18,"id":48610314}]}]}
{"op":"mcm","clk":"11978545326","pt":1724791548676,"mc":[{"id":"1.232352479","rc":[{"batb":[[0,3.05,5],[1,3,20.2],[2,1.03,200]],"ltp":3.05,"tv":227.18,"id":48610314}]}]}
{"op":"mcm","clk":"11978545598","pt":1724791552169,"mc":[{"id":"1.232352479","rc":[{"batb":[[0,3,20.2],[1,1.03,200],[2,1.02,200]],"ltp":3.05,"tv":227.18,"id":48610314}]}]}
{"op":"mcm","clk":"11978545810","pt":1724791554791,"mc":[{"id":"1.232352479","rc":[{"batb":[[0,3.05,5],[1,3,20.2],[2,1.03,200]],"ltp":3.05,"tv":227.18,"id":48610314}]}]}
{"op":"mcm","clk":"11978546094","pt":1724791558164,"mc":[{"id":"1.232352479","rc":[{"batb":[[0,3,20.2],[1,1.03,200],[2,1.02,200]],"ltp":3.05,"tv":227.18,"id":48610314}]}]}
{"op":"mcm","clk":"11978546321","pt":1724791560754,"mc":[{"id":"1.232352479","rc":[{"batb":[[0,3.05,5],[1,3,20.2],[2,1.03,200]],"ltp":3.05,"tv":227.18,"id":48610314}]}]}
{"op":"mcm","clk":"11978546566","pt":1724791564071,"mc":[{"id":"1.232352479","rc":[{"batb":[[0,3,20.2],[1,1.03,200],[2,1.02,200]],"ltp":3.05,"tv":227.18,"id":48610314}]}]}
{"op":"mcm","clk":"11978546744","pt":1724791566448,"mc":[{"id":"1.232352479","rc":[{"batb":[[0,3.05,5],[1,3,20.2],[2,1.03,200]],"ltp":3.05,"tv":227.18,"id":48610314}]}]}
{"op":"mcm","clk":"11978546992","pt":1724791569861,"mc":[{"id":"1.232352479","rc":[{"batb":[[0,3,20.2],[1,1.03,200],[2,1.02,200]],"ltp":3.05,"tv":227.18,"id":48610314}]}]}
{"op":"mcm","clk":"11978547192","pt":1724791572494,"mc":[{"id":"1.232352479","rc":[{"batb":[[0,3.05,5],[1,3,20.2],[2,1.03,200]],"ltp":3.05,"tv":227.18,"id":48610314}]}]}
{"op":"mcm","clk":"11978547408","pt":1724791575793,"mc":[{"id":"1.232352479","rc":[{"batb":[[0,3,20.2],[1,1.03,200],[2,1.02,200]],"ltp":3.05,"tv":227.18,"id":48610314}]}]}
{"op":"mcm","clk":"11978547592","pt":1724791578487,"mc":[{"id":"1.232352479","rc":[{"batb":[[0,3.05,5],[1,3,20.2],[2,1.03,200]],"ltp":3.05,"tv":227.18,"id":48610314}]}]}
{"op":"mcm","clk":"11978547814","pt":1724791581792,"mc":[{"id":"1.232352479","rc":[{"batb":[[0,3,20.2],[1,1.03,200],[2,1.02,200]],"ltp":3.05,"tv":227.18,"id":48610314}]}]}
{"op":"mcm","clk":"11978548260","pt":1724791588084,"mc":[{"id":"1.232352479","rc":[{"batb":[[0,3.05,5],[1,3,20.2],[2,1.03,200]],"ltp":3.05,"tv":227.18,"id":48610314}]}]}
{"op":"mcm","clk":"11978548506","pt":1724791591484,"mc":[{"id":"1.232352479","rc":[{"batb":[[0,3,20.2],[1,1.03,200],[2,1.02,200]],"ltp":3.05,"tv":227.18,"id":48610314}]}]}
{"op":"mcm","clk":"11978548724","pt":1724791594696,"mc":[{"id":"1.232352479","rc":[{"batb":[[0,3.05,5],[1,3,20.2],[2,1.03,200]],"ltp":3.05,"tv":227.18,"id":48610314}]}]}
{"op":"mcm","clk":"11978548948","pt":1724791598210,"mc":[{"id":"1.232352479","rc":[{"batb":[[0,3,20.2],[1,1.03,200],[2,1.02,200]],"ltp":3.05,"tv":227.18,"id":48610314}]}]}
{"op":"mcm","clk":"11978549129","pt":1724791600594,"mc":[{"id":"1.232352479","rc":[{"batb":[[0,3.05,5],[1,3,20.2],[2,1.03,200]],"ltp":3.05,"tv":227.18,"id":48610314}]}]}
{"op":"mcm","clk":"11978549350","pt":1724791603899,"mc":[{"id":"1.232352479","rc":[{"batb":[[0,3,20.2],[1,1.03,200],[2,1.02,200]],"ltp":3.05,"tv":227.18,"id":48610314}]}]}
{"op":"mcm","clk":"11978549518","pt":1724791606682,"mc":[{"id":"1.232352479","rc":[{"batb":[[0,3.05,5],[1,3,20.2],[2,1.03,200]],"ltp":3.05,"tv":227.18,"id":48610314}]}]}
{"op":"mcm","clk":"11978549792","pt":1724791610501,"mc":[{"id":"1.232352479","rc":[{"batb":[[0,3,20.2],[1,1.03,200],[2,1.02,200]],"ltp":3.05,"tv":227.18,"id":48610314}]}]}
{"op":"mcm","clk":"11978549954","pt":1724791612920,"mc":[{"id":"1.232352479","rc":[{"batb":[[0,3.05,5],[1,3,20.2],[2,1.03,200]],"ltp":3.05,"tv":227.18,"id":48610314}]}]}
{"op":"mcm","clk":"11978550204","pt":1724791616322,"mc":[{"id":"1.232352479","rc":[{"batb":[[0,3,20.2],[1,1.03,200],[2,1.02,200]],"ltp":3.05,"tv":227.18,"id":48610314}]}]}
{"op":"mcm","clk":"11978550369","pt":1724791618700,"mc":[{"id":"1.232352479","rc":[{"batb":[[0,3.05,5],[1,3,20.2],[2,1.03,200]],"ltp":3.05,"tv":227.18,"id":48610314}]}]}
{"op":"mcm","clk":"11978550607","pt":1724791622108,"mc":[{"id":"1.232352479","rc":[{"batb":[[0,3,20.2],[1,1.03,200],[2,1.02,200]],"ltp":3.05,"tv":227.18,"id":48610314}]}]}
{"op":"mcm","clk":"11978550789","pt":1724791624536,"mc":[{"id":"1.232352479","rc":[{"batb":[[0,3.05,5],[1,3,20.2],[2,1.03,200]],"ltp":3.05,"tv":227.18,"id":48610314}]}]}
{"op":"mcm","clk":"11978551033","pt":1724791627835,"mc":[{"id":"1.232352479","rc":[{"batb":[[0,3,20.2],[1,1.03,200],[2,1.02,200]],"ltp":3.05,"tv":227.18,"id":48610314}]}]}
{"op":"mcm","clk":"11978551228","pt":1724791630525,"mc":[{"id":"1.232352479","rc":[{"batb":[[0,3.05,5],[1,3,20.2],[2,1.03,200]],"ltp":3.05,"tv":227.18,"id":48610314}]}]}
{"op":"mcm","clk":"11978551425","pt":1724791634028,"mc":[{"id":"1.232352479","rc":[{"batb":[[0,3,20.2],[1,1.03,200],[2,1.02,200]],"ltp":3.05,"tv":227.18,"id":48610314}]}]}
{"op":"mcm","clk":"11978551598","pt":1724791636658,"mc":[{"id":"1.232352479","rc":[{"batb":[[0,3.05,5],[1,3,20.2],[2,1.03,200]],"ltp":3.05,"tv":227.18,"id":48610314}]}]}
{"op":"mcm","clk":"11978551804","pt":1724791640108,"mc":[{"id":"1.232352479","rc":[{"batb":[[0,3,20.2],[1,1.03,200],[2,1.02,200]],"ltp":3.05,"tv":227.18,"id":48610314}]}]}
{"op":"mcm","clk":"11978551988","pt":1724791642537,"mc":[{"id":"1.232352479","rc":[{"batb":[[0,3.05,5],[1,3,20.2],[2,1.03,200]],"ltp":3.05,"tv":227.18,"id":48610314}]}]}
{"op":"mcm","clk":"11978552223","pt":1724791645934,"mc":[{"id":"1.232352479","rc":[{"batb":[[0,3,20.2],[1,1.03,200],[2,1.02,200]],"ltp":3.05,"tv":227.18,"id":48610314}]}]}
{"op":"mcm","clk":"11978552421","pt":1724791648564,"mc":[{"id":"1.232352479","rc":[{"batb":[[0,3.05,5],[1,3,20.2],[2,1.03,200]],"ltp":3.05,"tv":227.18,"id":48610314}]}]}
{"op":"mcm","clk":"11978552628","pt":1724791651958,"mc":[{"id":"1.232352479","rc":[{"batb":[[0,3,20.2],[1,1.03,200],[2,1.02,200]],"ltp":3.05,"tv":227.18,"id":48610314}]}]}
{"op":"mcm","clk":"11978552832","pt":1724791655455,"mc":[{"id":"1.232352479","rc":[{"batb":[[0,3.05,5],[1,3,20.2],[2,1.03,200]],"ltp":3.05,"tv":227.18,"id":48610314}]}]}
{"op":"mcm","clk":"11978553086","pt":1724791658853,"mc":[{"id":"1.232352479","rc":[{"batb":[[0,3,20.2],[1,1.03,200],[2,1.02,200]],"ltp":3.05,"tv":227.18,"id":48610314}]}]}
{"op":"mcm","clk":"11978553299","pt":1724791661750,"mc":[{"id":"1.232352479","rc":[{"batb":[[0,3.05,5],[1,3,20.2],[2,1.03,200]],"ltp":3.05,"tv":227.18,"id":48610314}]}]}
{"op":"mcm","clk":"11978553507","pt":1724791665064,"mc":[{"id":"1.232352479","rc":[{"batb":[[0,3,20.2],[1,1.03,200],[2,1.02,200]],"ltp":3.05,"tv":227.18,"id":48610314}]}]}
{"op":"mcm","clk":"11978553736","pt":1724791667438,"mc":[{"id":"1.232352479","rc":[{"batb":[[0,3.05,5],[1,3,20.2],[2,1.03,200]],"ltp":3.05,"tv":227.18,"id":48610314}]}]}
{"op":"mcm","clk":"11978553935","pt":1724791670761,"mc":[{"id":"1.232352479","rc":[{"batb":[[0,3,20.2],[1,1.03,200],[2,1.02,200]],"ltp":3.05,"tv":227.18,"id":48610314}]}]}
{"op":"mcm","clk":"11978554147","pt":1724791673451,"mc":[{"id":"1.232352479","rc":[{"batb":[[0,3.05,5],[1,3,20.2],[2,1.03,200]],"ltp":3.05,"tv":227.18,"id":48610314}]}]}
{"op":"mcm","clk":"11978554383","pt":1724791676858,"mc":[{"id":"1.232352479","rc":[{"batb":[[0,3,20.2],[1,1.03,200],[2,1.02,200]],"ltp":3.05,"tv":227.18,"id":48610314}]}]}
{"op":"mcm","clk":"11978554622","pt":1724791680367,"mc":[{"id":"1.232352479","rc":[{"batb":[[0,3.05,5],[1,3,20.2],[2,1.03,200]],"ltp":3.05,"tv":227.18,"id":48610314}]}]}
{"op":"mcm","clk":"11978554937","pt":1724791683670,"mc":[{"id":"1.232352479","rc":[{"batb":[[0,3,20.2],[1,1.03,200],[2,1.02,200]],"ltp":3.05,"tv":227.18,"id":48610314}]}]}
{"op":"mcm","clk":"11978555146","pt":1724791686711,"mc":[{"id":"1.232352479","rc":[{"batb":[[0,3.05,5],[1,3,20.2],[2,1.03,200]],"ltp":3.05,"tv":227.18,"id":48610314}]}]}
{"op":"mcm","clk":"11978555391","pt":1724791690007,"mc":[{"id":"1.232352479","rc":[{"batb":[[0,3,20.2],[1,1.03,200],[2,1.02,200]],"ltp":3.05,"tv":227.18,"id":48610314}]}]}
{"op":"mcm","clk":"11978555571","pt":1724791692375,"mc":[{"id":"1.232352479","rc":[{"batb":[[0,3.05,5],[1,3,20.2],[2,1.03,200]],"ltp":3.05,"tv":227.18,"id":48610314}]}]}
{"op":"mcm","clk":"11978555814","pt":1724791695575,"mc":[{"id":"1.232352479","rc":[{"batb":[[0,3,20.2],[1,1.03,200],[2,1.02,200]],"ltp":3.05,"tv":227.18,"id":48610314}]}]}
{"op":"mcm","clk":"11978555973","pt":1724791697893,"mc":[{"id":"1.232352479","rc":[{"batb":[[0,3.05,5],[1,3,20.2],[2,1.03,200]],"ltp":3.05,"tv":227.18,"id":48610314}]}]}
{"op":"mcm","clk":"11978556194","pt":1724791701293,"mc":[{"id":"1.232352479","rc":[{"batb":[[0,3,20.2],[1,1.03,200],[2,1.02,200]],"ltp":3.05,"tv":227.18,"id":48610314}]}]}
{"op":"mcm","clk":"11978556592","pt":1724791706289,"mc":[{"id":"1.232352479","rc":[{"batb":[[0,3.05,5],[1,3,20.2],[2,1.03,200]],"ltp":3.05,"tv":227.18,"id":48610314}]}]}
{"op":"mcm","clk":"11978556833","pt":1724791709583,"mc":[{"id":"1.232352479","rc":[{"batb":[[0,3,20.2],[1,1.03,200],[2,1.02,200]],"ltp":3.05,"tv":227.18,"id":48610314}]}]}
{"op":"mcm","clk":"11978557065","pt":1724791712828,"mc":[{"id":"1.232352479","rc":[{"batb":[[0,3.05,5],[1,3,20.2],[2,1.03,200]],"ltp":3.05,"tv":227.18,"id":48610314}]}]}
{"op":"mcm","clk":"11978557273","pt":1724791716124,"mc":[{"id":"1.232352479","rc":[{"batb":[[0,3,20.2],[1,1.03,200],[2,1.02,200]],"ltp":3.05,"tv":227.18,"id":48610314}]}]}
{"op":"mcm","clk":"11978557472","pt":1724791719316,"mc":[{"id":"1.232352479","rc":[{"batb":[[0,3.05,5],[1,3,20.2],[2,1.03,200]],"ltp":3.05,"tv":227.18,"id":48610314}]}]}
{"op":"mcm","clk":"11978557721","pt":1724791722734,"mc":[{"id":"1.232352479","rc":[{"batb":[[0,3,20.2],[1,1.03,200],[2,1.02,200]],"ltp":3.05,"tv":227.18,"id":48610314}]}]}
{"op":"mcm","clk":"11978557898","pt":1724791725196,"mc":[{"id":"1.232352479","rc":[{"batb":[[0,3.05,5],[1,3,20.2],[2,1.03,200]],"ltp":3.05,"tv":227.18,"id":48610314}]}]}
{"op":"mcm","clk":"11978558149","pt":1724791728814,"mc":[{"id":"1.232352479","rc":[{"batb":[[0,3,20.2],[1,1.03,200],[2,1.02,200]],"ltp":3.05,"tv":227.18,"id":48610314}]}]}
{"op":"mcm","clk":"11978558320","pt":1724791731041,"mc":[{"id":"1.232352479","rc":[{"batb":[[0,3.05,5],[1,3,20.2],[2,1.03,200]],"ltp":3.05,"tv":227.18,"id":48610314}]}]}
