{"op":"mcm","clk":"11966373561","pt":1724622163083,"mc":[{"id":"1.232283786","marketDefinition":{"bspMarket":false,"turnInPlayEnabled":true,"persistenceEnabled":true,"marketBaseRate":5.0,"eventId":"33527252","eventTypeId":"4","numberOfWinners":1,"bettingType":"ODDS","marketType":"MATCH_ODDS","marketTime":"2024-08-31T09:30:00.000Z","suspendTime":"2024-08-31T09:30:00.000Z","bspReconciled":false,"complete":true,"inPlay":false,"crossMatching":false,"runnersVoidable":false,"numberOfActiveRunners":2,"betDelay":0,"status":"OPEN","runners":[{"status":"ACTIVE","sortPriority":1,"id":35736920,"name":"South East Stars"},{"status":"ACTIVE","sortPriority":2,"id":11445383,"name":"Western Storm"}],"regulators":["MR_INT"],"countryCode":"GB","discountAllowed":false,"timezone":"GMT","openDate":"2024-08-31T09:30:00.000Z","version":6100652997,"name":"Match Odds","eventName":"South East Stars v Western Storm"},"rc":[{"batb":[[0,1.03,200],[1,1.02,200],[2,1.01,220]],"ltp":0.0,"tv":0.0,"id":35736920},{"batb":[[0,1.03,200],[1,1.02,200],[2,1.01,220]],"ltp":0.0,"tv":0.0,"id":11445383}]}]}
{"op":"mcm","clk":"11966373725","pt":1724622165448,"mc":[{"id":"1.232283786","marketDefinition":{"bspMarket":false,"turnInPlayEnabled":true,"persistenceEnabled":true,"marketBaseRate":5.0,"eventId":"33527252","eventTypeId":"4","numberOfWinners":1,"bettingType":"ODDS","marketType":"MATCH_ODDS","marketTime":"2024-08-31T09:30:00.000Z","suspendTime":"2024-08-31T09:30:00.000Z","bspReconciled":false,"complete":true,"inPlay":false,"crossMatching":false,"runnersVoidable":false,"numberOfActiveRunners":2,"betDelay":0,"status":"OPEN","runners":[{"status":"ACTIVE","sortPriority":1,"id":35736920,"name":"South East Stars"},{"status":"ACTIVE","sortPriority":2,"id":11445383,"name":"Western Storm"}],"regulators":["MR_INT"],"countryCode":"GB","discountAllowed":true,"timezone":"GMT","openDate":"2024-08-31T09:30:00.000Z","version":6100652997,"name":"Match Odds","eventName":"South East Stars v Western Storm"}}]}
{"op":"mcm","clk":"11967145125","pt":1724640350145,"mc":[{"id":"1.232283786","rc":[{"batb":[[2,1.01,480.05]],"ltp":0.0,"tv":0.0,"id":35736920},{"batb":[[2,1.01,480.05]],"ltp":0.0,"tv":0.0,"id":11445383}]}]}
{"op":"mcm","clk":"11967225712","pt":1724643774815,"mc":[{"id":"1.232283786","rc":[{"batb":[[2,1.01,480.07]],"ltp":0.0,"tv":0.0,"id":35736920},{"batb":[[2,1.01,480.07]],"ltp":0.0,"tv":0.0,"id":11445383}]}]}
{"op":"mcm","clk":"11967339996","pt":1724649174806,"mc":[{"id":"1.232283786","rc":[{"batb":[[2,1.01,480.1]],"ltp":0.0,"tv":0.0,"id":35736920},{"batb":[[2,1.01,480.1]],"ltp":0.0,"tv":0.0,"id":11445383}]}]}
{"op":"mcm","clk":"11967476734","pt":1724654574798,"mc":[{"id":"1.232283786","rc":[{"batb":[[2,1.01,479.93]],"ltp":0.0,"tv":0.0,"id":35736920},{"batb":[[2,1.01,479.93]],"ltp":0.0,"tv":0.0,"id":11445383}]}]}
{"op":"mcm","clk":"11967639487","pt":1724659974799,"mc":[{"id":"1.232283786","rc":[{"batb":[[2,1.01,480.47]],"ltp":0.0,"tv":0.0,"id":35736920},{"batb":[[2,1.01,480.47]],"ltp":0.0,"tv":0.0,"id":11445383}]}]}
{"op":"mcm","clk":"11967848384","pt":1724664675380,"mc":[{"id":"1.232283786","rc":[{"batb":[[0,1.15,333.33],[1,1.1,1000],[2,1.03,200]],"ltp":0.0,"tv":0.0,"id":35736920},{"batb":[[0,1.15,333.33],[1,1.1,1000],[2,1.03,200]],"ltp":0.0,"tv":0.0,"id":11445383}]}]}
{"op":"mcm","clk":"11967848416","pt":1724664675992,"mc":[{"id":"1.232283786","rc":[{"batb":[[0,1.4,250],[1,1.3,333.33],[2,1.25,200]],"ltp":0.0,"tv":0.0,"id":35736920},{"batb":[[0,1.4,250],[1,1.3,333.33],[2,1.25,200]],"ltp":0.0,"tv":0.0,"id":11445383}]}]}
{"op":"mcm","clk":"11967849620","pt":1724664698811,"mc":[{"id":"1.232283786","marketDefinition":{"bspMarket":false,"turnInPlayEnabled":true,"persistenceEnabled":true,"marketBaseRate":5.0,"eventId":"33527252","eventTypeId":"4","numberOfWinners":1,"bettingType":"ODDS","marketType":"MATCH_ODDS","marketTime":"2024-08-31T09:30:00.000Z","suspendTime":"2024-08-31T09:30:00.000Z","bspReconciled":false,"complete":true,"inPlay":false,"crossMatching":true,"runnersVoidable":false,"numberOfActiveRunners":2,"betDelay":0,"status":"OPEN","runners":[{"status":"ACTIVE","sortPriority":1,"id":35736920,"name":"South East Stars"},{"status":"ACTIVE","sortPriority":2,"id":11445383,"name":"Western Storm"}],"regulators":["MR_INT"],"countryCode":"GB","discountAllowed":true,"timezone":"GMT","openDate":"2024-08-31T09:30:00.000Z","version":6100652997,"name":"Match Odds","eventName":"South East Stars v Western Storm"}}]}
{"op":"mcm","clk":"11967941453","pt":1724666026357,"mc":[{"id":"1.232283786","rc":[{"batb":[[0,1.41,12.28],[1,1.4,250],[2,1.3,333.33]],"batl":[[0,3.45,4.91]],"ltp":0.0,"tv":0.0,"id":35736920},{"batb":[[0,1.41,12.28],[1,1.4,250],[2,1.3,333.33]],"batl":[[0,3.45,4.91]],"ltp":0.0,"tv":0.0,"id":11445383}]}]}
{"op":"mcm","clk":"11968117672","pt":1724668525308,"mc":[{"id":"1.232283786","rc":[{"batb":[[0,1.41,18.96]],"ltp":0.0,"tv":0.0,"id":35736920},{"batb":[[0,1.41,19.83]],"ltp":0.0,"tv":0.0,"id":11445383}]}]}
{"op":"mcm","clk":"11968176848","pt":1724669514006,"mc":[{"id":"1.232283786","rc":[{"batb":[[1,1.03,200],[2,1.02,200]],"ltp":0.0,"tv":0.0,"id":35736920},{"batb":[[1,1.03,200],[2,1.02,200]],"ltp":0.0,"tv":0.0,"id":11445383}]}]}
{"op":"mcm","clk":"11968176960","pt":1724669515912,"mc":[{"id":"1.232283786","rc":[{"batb":[[0,1.41,6.68]],"ltp":0.0,"tv":0.0,"id":35736920},{"batb":[[0,1.41,7.55]],"ltp":0.0,"tv":0.0,"id":11445383}]}]}
{"op":"mcm","clk":"11968179584","pt":1724669566239,"mc":[{"id":"1.232283786","rc":[{"batb":[[1,1.2,125],[2,1.03,200]],"ltp":0.0,"tv":0.0,"id":35736920},{"batb":[[1,1.2,125],[2,1.03,200]],"ltp":0.0,"tv":0.0,"id":11445383}]}]}
{"op":"mcm","clk":"11968248428","pt":1724670774800,"mc":[{"id":"1.232283786","rc":[{"batb":[[0,1.41,6.67]],"ltp":0.0,"tv":0.0,"id":35736920},{"batb":[[0,1.41,7.55]],"ltp":0.0,"tv":0.0,"id":11445383}]}]}
{"op":"mcm","clk":"11968369811","pt":1724672639296,"mc":[{"id":"1.232283786","rc":[{"batb":[[0,1.21,6.67]],"ltp":0.0,"tv":0.0,"id":35736920},{"batb":[[0,1.21,7.55]],"ltp":0.0,"tv":0.0,"id":11445383}]}]}
{"op":"mcm","clk":"11968595688","pt":1724675569462,"mc":[{"id":"1.232283786","rc":[{"batb":[[0,1.22,38.68],[1,1.21,6.68],[2,1.2,125]],"ltp":0.0,"tv":0.0,"id":35736920},{"batb":[[0,1.22,38.68],[1,1.21,7.55],[2,1.2,125]],"ltp":0.0,"tv":0.0,"id":11445383}]}]}
{"op":"mcm","clk":"11968685424","pt":1724676563019,"mc":[{"id":"1.232283786","rc":[{"batb":[[0,1.23,6.68],[1,1.22,38.68]],"ltp":0.0,"tv":0.0,"id":35736920},{"batb":[[0,1.23,7.55],[1,1.22,38.68]],"ltp":0.0,"tv":0.0,"id":11445383}]}]}
{"op":"mcm","clk":"11968748239","pt":1724677371247,"mc":[{"id":"1.232283786","rc":[{"batb":[[0,1.23,6.67],[1,1.2,125],[2,1.03,200]],"ltp":0.0,"tv":0.0,"id":35736920},{"batb":[[0,1.23,7.54],[1,1.2,125],[2,1.03,200]],"ltp":0.0,"tv":0.0,"id":11445383}]}]}
{"op":"mcm","clk":"11968761783","pt":1724677523535,"mc":[{"id":"1.232283786","rc":[{"batb":[[0,1.24,35.41],[1,1.23,6.67],[2,1.2,125]],"ltp":0.0,"tv":0.0,"id":35736920},{"batb":[[0,1.24,35.41],[1,1.23,7.54],[2,1.2,125]],"ltp":0.0,"tv":0.0,"id":11445383}]}]}
{"op":"mcm","clk":"11968936468","pt":1724679328317,"mc":[{"id":"1.232283786","rc":[{"batb":[[0,1.23,7.54],[1,1.2,125],[2,1.03,200]],"ltp":0.0,"tv":0.0,"id":11445383}]}]}
{"op":"mcm","clk":"11968936489","pt":1724679328517,"mc":[{"id":"1.232283786","rc":[{"batb":[[0,1.23,6.67],[1,1.2,125],[2,1.03,200]],"ltp":0.0,"tv":0.0,"id":35736920}]}]}
{"op":"mcm","clk":"11968952424","pt":1724679476005,"mc":[{"id":"1.232283786","rc":[{"batb":[[0,1.24,35.41],[1,1.23,6.67],[2,1.2,125]],"ltp":0.0,"tv":0.0,"id":35736920},{"batb":[[0,1.24,35.41],[1,1.23,7.54],[2,1.2,125]],"ltp":0.0,"tv":0.0,"id":11445383}]}]}
{"op":"mcm","clk":"11969082644","pt":1724680728074,"mc":[{"id":"1.232283786","rc":[{"batb":[[0,1.25,6.67],[1,1.24,35.41]],"ltp":0.0,"tv":0.0,"id":35736920}]}]}
{"op":"mcm","clk":"11969082709","pt":1724680728566,"mc":[{"id":"1.232283786","rc":[{"batb":[[0,1.25,7.54],[1,1.24,35.41]],"ltp":0.0,"tv":0.0,"id":11445383}]}]}
{"op":"mcm","clk":"11969159415","pt":1724681276388,"mc":[{"id":"1.232283786","rc":[{"batb":[[0,1.25,6.68],[1,1.2,125],[2,1.03,200]],"ltp":0.0,"tv":0.0,"id":35736920},{"batb":[[0,1.25,7.55],[1,1.2,125],[2,1.03,200]],"ltp":0.0,"tv":0.0,"id":11445383}]}]}
{"op":"mcm","clk":"11969181501","pt":1724681426996,"mc":[{"id":"1.232283786","rc":[{"batb":[[0,1.26,32.72],[1,1.25,6.68],[2,1.2,125]],"ltp":0.0,"tv":0.0,"id":35736920},{"batb":[[0,1.26,32.72],[1,1.25,7.55],[2,1.2,125]],"ltp":0.0,"tv":0.0,"id":11445383}]}]}
{"op":"mcm","clk":"11969467092","pt":1724683231760,"mc":[{"id":"1.232283786","rc":[{"batb":[[0,1.25,6.68],[1,1.2,125],[2,1.03,200]],"ltp":0.0,"tv":0.0,"id":35736920},{"batb":[[0,1.25,7.55],[1,1.2,125],[2,1.03,200]],"ltp":0.0,"tv":0.0,"id":11445383}]}]}
{"op":"mcm","clk":"11969492260","pt":1724683383902,"mc":[{"id":"1.232283786","rc":[{"batb":[[0,1.26,32.72],[1,1.25,6.68],[2,1.2,125]],"ltp":0.0,"tv":0.0,"id":35736920},{"batb":[[0,1.26,32.72],[1,1.25,7.55],[2,1.2,125]],"ltp":0.0,"tv":0.0,"id":11445383}]}]}
{"op":"mcm","clk":"11969678561","pt":1724684896303,"mc":[{"id":"1.232283786","rc":[{"batb":[[0,1.27,6.67],[1,1.26,32.73]],"ltp":0.0,"tv":0.0,"id":35736920},{"batb":[[0,1.27,7.54],[1,1.26,32.73]],"ltp":0.0,"tv":0.0,"id":11445383}]}]}
{"op":"mcm","clk":"11969723586","pt":1724685187681,"mc":[{"id":"1.232283786","rc":[{"batb":[[1,1.2,125],[2,1.03,200]],"ltp":0.0,"tv":0.0,"id":35736920},{"batb":[[1,1.2,125],[2,1.03,200]],"ltp":0.0,"tv":0.0,"id":11445383}]}]}
{"op":"mcm","clk":"11969748753","pt":1724685328833,"mc":[{"id":"1.232283786","rc":[{"batb":[[0,1.28,30.39],[1,1.27,6.67],[2,1.2,125]],"ltp":0.0,"tv":0.0,"id":35736920},{"batb":[[0,1.28,30.39],[1,1.27,7.54],[2,1.2,125]],"ltp":0.0,"tv":0.0,"id":11445383}]}]}
{"op":"mcm","clk":"11969929780","pt":1724686466042,"mc":[{"id":"1.232283786","rc":[{"batb":[[2,1.03,200]],"ltp":0.0,"tv":0.0,"id":35736920},{"batb":[[2,1.03,200]],"ltp":0.0,"tv":0.0,"id":11445383}]}]}
{"op":"mcm","clk":"11969940653","pt":1724686535999,"mc":[{"id":"1.232283786","rc":[{"batb":[[2,1.2,1000]],"ltp":0.0,"tv":0.0,"id":35736920},{"batb":[[2,1.2,1000]],"ltp":0.0,"tv":0.0,"id":11445383}]}]}
{"op":"mcm","clk":"11970040773","pt":1724687130364,"mc":[{"id":"1.232283786","rc":[{"batb":[[0,1.27,6.67],[1,1.2,1000],[2,1.03,200]],"ltp":0.0,"tv":0.0,"id":35736920},{"batb":[[0,1.27,7.54],[1,1.2,1000],[2,1.03,200]],"ltp":0.0,"tv":0.0,"id":11445383}]}]}
{"op":"mcm","clk":"11970058495","pt":1724687254607,"mc":[{"id":"1.232283786","rc":[{"batb":[[0,1.28,30.39],[1,1.27,6.67],[2,1.2,1000]],"ltp":0.0,"tv":0.0,"id":35736920},{"batb":[[0,1.28,30.39],[1,1.27,7.54],[2,1.2,1000]],"ltp":0.0,"tv":0.0,"id":11445383}]}]}
{"op":"mcm","clk":"11970271803","pt":1724689058898,"mc":[{"id":"1.232283786","rc":[{"batb":[[0,1.27,6.68],[1,1.2,1000],[2,1.03,200]],"ltp":0.0,"tv":0.0,"id":35736920},{"batb":[[0,1.27,7.55],[1,1.2,1000],[2,1.03,200]],"ltp":0.0,"tv":0.0,"id":11445383}]}]}
{"op":"mcm","clk":"11970272701","pt":1724689067106,"mc":[{"id":"1.232283786","rc":[{"batl":[[0,5.9,9.92]],"ltp":0.0,"tv":0.0,"id":35736920},{"batl":[[0,5.9,9.91]],"ltp":0.0,"tv":0.0,"id":11445383}]}]}
{"op":"mcm","clk":"11970278497","pt":1724689127313,"mc":[{"id":"1.232283786","rc":[{"batb":[[0,1.28,30.4],[1,1.27,6.68],[2,1.2,1000]],"ltp":0.0,"tv":0.0,"id":35736920},{"batb":[[0,1.28,30.4],[1,1.27,7.55],[2,1.2,1000]],"ltp":0.0,"tv":0.0,"id":11445383}]}]}
{"op":"mcm","clk":"11970467880","pt":1724690877865,"mc":[{"id":"1.232283786","rc":[{"batb":[[0,1.68,6],[1,1.28,30.4],[2,1.27,6.68]],"ltp":0.0,"tv":0.0,"id":35736920},{"batb":[[0,2.34,3.04],[1,1.28,30.4],[2,1.27,7.55]],"ltp":0.0,"tv":0.0,"id":11445383}]}]}
{"op":"mcm","clk":"11970475247","pt":1724690931398,"mc":[{"id":"1.232283786","rc":[{"batb":[[1,1.27,6.68],[2,1.2,1000]],"ltp":0.0,"tv":0.0,"id":35736920},{"batb":[[1,1.27,7.55],[2,1.2,1000]],"ltp":0.0,"tv":0.0,"id":11445383}]}]}
{"op":"mcm","clk":"11970476269","pt":1724690939813,"mc":[{"id":"1.232283786","rc":[{"batl":[[0,5.9,10.12]],"ltp":0.0,"tv":0.0,"id":35736920},{"batl":[[0,5.9,10.1]],"ltp":0.0,"tv":0.0,"id":11445383}]}]}
{"op":"mcm","clk":"11970668083","pt":1724692374799,"mc":[{"id":"1.232283786","rc":[{"batb":[[1,1.27,6.67]],"batl":[[0,5.9,10.12]],"ltp":0.0,"tv":0.0,"id":35736920},{"batb":[[1,1.27,7.55]],"batl":[[0,5.9,10.1]],"ltp":0.0,"tv":0.0,"id":11445383}]}]}
{"op":"mcm","clk":"11970792455","pt":1724693095340,"mc":[{"id":"1.232283786","rc":[{"batb":[[1,1.2,1000],[2,1.03,200]],"ltp":0.0,"tv":0.0,"id":35736920}]}]}
{"op":"mcm","clk":"11970792526","pt":1724693095765,"mc":[{"id":"1.232283786","rc":[{"batb":[[1,1.2,1000],[2,1.03,200]],"ltp":0.0,"tv":0.0,"id":11445383}]}]}
{"op":"mcm","clk":"11971549954","pt":1724697774790,"mc":[{"id":"1.232283786","rc":[{"batl":[[0,5.9,10.12]],"ltp":0.0,"tv":0.0,"id":35736920},{"batl":[[0,5.9,10.1]],"ltp":0.0,"tv":0.0,"id":11445383}]}]}
{"op":"mcm","clk":"11972775163","pt":1724708574780,"mc":[{"id":"1.232283786","rc":[{"batl":[[0,5.9,10.11]],"ltp":0.0,"tv":0.0,"id":35736920},{"batl":[[0,5.9,10.1]],"ltp":0.0,"tv":0.0,"id":11445383}]}]}
{"op":"mcm","clk":"11972862300","pt":1724709960638,"mc":[{"id":"1.232283786","rc":[{"batl":[[0,5.9,10.11]],"ltp":0.0,"tv":0.0,"id":35736920},{"batl":[[0,5.9,10.1]],"ltp":0.0,"tv":0.0,"id":11445383}]}]}
{"op":"mcm","clk":"11973082770","pt":1724713974782,"mc":[{"id":"1.232283786","rc":[{"batl":[[0,5.9,10.12]],"ltp":0.0,"tv":0.0,"id":35736920},{"batl":[[0,5.9,10.1]],"ltp":0.0,"tv":0.0,"id":11445383}]}]}
{"op":"mcm","clk":"11973747654","pt":1724730174788,"mc":[{"id":"1.232283786","rc":[{"batl":[[0,5.9,10.12]],"ltp":0.0,"tv":0.0,"id":35736920},{"batl":[[0,5.9,10.1]],"ltp":0.0,"tv":0.0,"id":11445383}]}]}
{"op":"mcm","clk":"11973852446","pt":1724735574779,"mc":[{"id":"1.232283786","rc":[{"batl":[[0,5.9,10.12]],"ltp":0.0,"tv":0.0,"id":35736920},{"batl":[[0,5.9,10.1]],"ltp":0.0,"tv":0.0,"id":11445383}]}]}
{"op":"mcm","clk":"11973953551","pt":1724740974781,"mc":[{"id":"1.232283786","rc":[{"batl":[[0,5.9,10.11]],"ltp":0.0,"tv":0.0,"id":35736920},{"batl":[[0,5.9,10.1]],"ltp":0.0,"tv":0.0,"id":11445383}]}]}
{"op":"mcm","clk":"11974134325","pt":1724746374780,"mc":[{"id":"1.232283786","rc":[{"batl":[[0,5.9,10.11]],"ltp":0.0,"tv":0.0,"id":35736920},{"batl":[[0,5.9,10.09]],"ltp":0.0,"tv":0.0,"id":11445383}]}]}
{"op":"mcm","clk":"11974398525","pt":1724751774782,"mc":[{"id":"1.232283786","rc":[{"batl":[[0,5.9,10.1]],"ltp":0.0,"tv":0.0,"id":35736920},{"batl":[[0,5.9,10.08]],"ltp":0.0,"tv":0.0,"id":11445383}]}]}
{"op":"mcm","clk":"11974596141","pt":1724754624540,"mc":[{"id":"1.232283786","rc":[{"batb":[[1,1.03,200],[2,1.02,200]],"batl":[[0,5.9,10.08]],"ltp":0.0,"tv":0.0,"id":35736920},{"batb":[[1,1.03,200],[2,1.02,200]],"batl":[[0,5.9,10.07]],"ltp":0.0,"tv":0.0,"id":11445383}]}]}
{"op":"mcm","clk":"11975233047","pt":1724763617810,"mc":[{"id":"1.232283786","rc":[{"batb":[[1,1.2,1000],[2,1.03,200]],"ltp":0.0,"tv":0.0,"id":35736920},{"batb":[[1,1.2,1000],[2,1.03,200]],"ltp":0.0,"tv":0.0,"id":11445383}]}]}
{"op":"mcm","clk":"11975235100","pt":1724763647752,"mc":[{"id":"1.232283786","rc":[{"batl":[[0,5.9,10.02]],"ltp":0.0,"tv":0.0,"id":35736920},{"batl":[[0,5.9,10.02]],"ltp":0.0,"tv":0.0,"id":11445383}]}]}
{"op":"mcm","clk":"11975407616","pt":1724765715964,"mc":[{"id":"1.232283786","rc":[{"batb":[[0,1.68,5.94]],"ltp":0.0,"tv":0.0,"id":35736920},{"batb":[[0,2.34,3.01]],"ltp":0.0,"tv":0.0,"id":11445383}]}]}
{"op":"mcm","clk":"11975599946","pt":1724767974782,"mc":[{"id":"1.232283786","rc":[{"batl":[[0,5.9,10.01]],"ltp":0.0,"tv":0.0,"id":35736920},{"batl":[[0,5.9,10.01]],"ltp":0.0,"tv":0.0,"id":11445383}]}]}
{"op":"mcm","clk":"11975635669","pt":1724768239864,"mc":[{"id":"1.232283786","rc":[{"batb":[[1,1.21,6.05],[2,1.2,1000]],"ltp":0.0,"tv":0.0,"id":11445383}]}]}
{"op":"mcm","clk":"11975746727","pt":1724769469361,"mc":[{"id":"1.232283786","rc":[{"batb":[[2,1.04,1.05]],"ltp":0.0,"tv":0.0,"id":35736920}]}]}
{"op":"mcm","clk":"11976181465","pt":1724773374782,"mc":[{"id":"1.232283786","rc":[{"batl":[[0,5.9,10.01]],"ltp":0.0,"tv":0.0,"id":35736920},{"batb":[[1,1.21,6.05]],"batl":[[0,5.9,10.01]],"ltp":0.0,"tv":0.0,"id":11445383}]}]}
{"op":"mcm","clk":"11977539723","pt":1724784174786,"mc":[{"id":"1.232283786","rc":[{"batl":[[0,5.9,10.01]],"ltp":0.0,"tv":0.0,"id":35736920},{"batb":[[1,1.21,6.05]],"batl":[[0,5.9,10.01]],"ltp":0.0,"tv":0.0,"id":11445383}]}]}
{"op":"mcm","clk":"11978309414","pt":1724789574786,"mc":[{"id":"1.232283786","rc":[{"batl":[[0,5.9,10]],"ltp":0.0,"tv":0.0,"id":35736920},{"batb":[[1,1.21,6.04]],"batl":[[0,5.9,10]],"ltp":0.0,"tv":0.0,"id":11445383}]}]}
{"op":"mcm","clk":"11979258377","pt":1724805774776,"mc":[{"id":"1.232283786","rc":[{"batl":[[0,5.9,10]],"ltp":0.0,"tv":0.0,"id":35736920},{"batb":[[1,1.21,6.04]],"batl":[[0,5.9,10]],"ltp":0.0,"tv":0.0,"id":11445383}]}]}
{"op":"mcm","clk":"11979520495","pt":1724811174789,"mc":[{"id":"1.232283786","rc":[{"batb":[[1,1.21,6.05]],"ltp":0.0,"tv":0.0,"id":11445383}]}]}
{"op":"mcm","clk":"11979676511","pt":1724816574801,"mc":[{"id":"1.232283786","rc":[{"batl":[[0,5.9,10]],"ltp":0.0,"tv":0.0,"id":35736920},{"batb":[[1,1.21,6.05]],"batl":[[0,5.9,10]],"ltp":0.0,"tv":0.0,"id":11445383}]}]}
{"op":"mcm","clk":"11979826999","pt":1724821974784,"mc":[{"id":"1.232283786","rc":[{"batl":[[0,5.9,9.99]],"ltp":0.0,"tv":0.0,"id":35736920},{"batb":[[1,1.21,6.05]],"batl":[[0,5.9,9.99]],"ltp":0.0,"tv":0.0,"id":11445383}]}]}
{"op":"mcm","clk":"11980038226","pt":1724827374780,"mc":[{"id":"1.232283786","rc":[{"batl":[[0,5.9,9.99]],"ltp":0.0,"tv":0.0,"id":35736920},{"batb":[[1,1.21,6.05]],"batl":[[0,5.9,9.99]],"ltp":0.0,"tv":0.0,"id":11445383}]}]}
{"op":"mcm","clk":"11980280958","pt":1724832774794,"mc":[{"id":"1.232283786","rc":[{"batl":[[0,5.9,10]],"ltp":0.0,"tv":0.0,"id":35736920},{"batb":[[1,1.21,6.05]],"batl":[[0,5.9,10]],"ltp":0.0,"tv":0.0,"id":11445383}]}]}
{"op":"mcm","clk":"11980314948","pt":1724833246316,"mc":[{"id":"1.232283786","rc":[{"trd":[[1.68,11.88]],"batb":[[0,1.2,1000],[1,1.04,1.05],[2,1.03,200]],"batl":[[0,1.68,45.41]],"ltp":1.68,"tv":11.88,"id":35736920}],"tv":11.88}]}
{"op":"mcm","clk":"11980315172","pt":1724833250522,"mc":[{"id":"1.232283786","rc":[{"batb":[[0,1.64,6.31],[1,1.2,1000],[2,1.04,1.05]],"ltp":1.68,"tv":11.88,"id":35736920}]}]}
{"op":"mcm","clk":"11980357674","pt":1724834029124,"mc":[{"id":"1.232283786","rc":[{"batb":[[1,1.2,1000],[2,1.04,1.05]],"ltp":0.0,"tv":0.0,"id":11445383}]}]}
{"op":"mcm","clk":"11980590471","pt":1724838174784,"mc":[{"id":"1.232283786","rc":[{"trd":[[1.68,11.89]],"batl":[[0,1.68,45.44]],"ltp":1.68,"tv":11.88,"id":35736920},{"batl":[[0,5.9,9.99]],"ltp":0.0,"tv":0.0,"id":11445383}],"tv":11.88}]}
{"op":"mcm","clk":"11980957749","pt":1724843574795,"mc":[{"id":"1.232283786","rc":[{"trd":[[1.68,11.88]],"batl":[[0,1.68,45.42]],"ltp":1.68,"tv":11.88,"id":35736920},{"batl":[[0,5.9,9.98]],"ltp":0.0,"tv":0.0,"id":11445383}],"tv":11.88}]}
{"op":"mcm","clk":"11981285043","pt":1724848974794,"mc":[{"id":"1.232283786","rc":[{"trd":[[1.68,11.88]],"batl":[[0,1.68,45.38]],"ltp":1.68,"tv":11.87,"id":35736920},{"batl":[[0,5.9,9.98]],"ltp":0.0,"tv":0.0,"id":11445383}],"tv":11.87}]}
{"op":"mcm","clk":"11981456440","pt":1724852113875,"mc":[{"id":"1.232283786","rc":[{"trd":[[1.68,11.87]],"batb":[[0,1.64,6.03]],"batl":[[0,1.68,45.35]],"ltp":1.68,"tv":11.87,"id":35736920},{"batb":[[0,2.34,2.88]],"batl":[[0,5.9,9.98]],"ltp":0.0,"tv":0.0,"id":11445383}],"tv":11.87}]}
{"op":"mcm","clk":"11981460559","pt":1724852191364,"mc":[{"id":"1.232283786","rc":[{"trd":[[1.68,99.05]],"batl":[[0,1.68,1.76]],"ltp":1.68,"tv":99.04,"id":35736920}],"tv":99.04}]}
{"op":"mcm","clk":"11981460636","pt":1724852193261,"mc":[{"id":"1.232283786","rc":[{"batl":[[1,5.9,10.09]],"ltp":1.68,"tv":99.04,"id":35736920}]}]}
{"op":"mcm","clk":"11981569376","pt":1724853998420,"mc":[{"id":"1.232283786","rc":[{"trd":[[1.68,99.19]],"batl":[[0,1.68,1.76],[1,5.9,10.1]],"ltp":1.68,"tv":99.18,"id":35736920},{"batb":[[1,1.21,7.18],[2,1.2,1000]],"batl":[[0,5.9,9.99]],"ltp":0.0,"tv":0.0,"id":11445383}],"tv":99.18}]}
{"op":"mcm","clk":"11982099992","pt":1724859774801,"mc":[{"id":"1.232283786","rc":[{"trd":[[1.68,99.24]],"batl":[[0,1.68,1.76],[1,5.9,10.11]],"ltp":1.68,"tv":99.24,"id":35736920},{"batb":[[1,1.21,7.17]],"batl":[[0,5.9,9.99]],"ltp":0.0,"tv":0.0,"id":11445383}],"tv":99.24}]}
{"op":"mcm","clk":"11982806626","pt":1724865174798,"mc":[{"id":"1.232283786","rc":[{"trd":[[1.68,99.24]],"batl":[[1,5.9,10.11]],"ltp":1.68,"tv":99.23,"id":35736920},{"batb":[[1,1.21,7.18]],"batl":[[0,5.9,10]],"ltp":0.0,"tv":0.0,"id":11445383}],"tv":99.23}]}
{"op":"mcm","clk":"11982993598","pt":1724866656779,"mc":[{"id":"1.232283786","rc":[{"batb":[[0,1.2,1000],[1,1.04,1.05],[2,1.03,200]],"ltp":1.68,"tv":99.23,"id":35736920},{"batb":[[0,1.21,7.18],[1,1.2,1000],[2,1.04,1.05]],"ltp":0.0,"tv":0.0,"id":11445383}]}]}
{"op":"mcm","clk":"11983013571","pt":1724866822464,"mc":[{"id":"1.232283786","rc":[{"batb":[[0,1.21,40.36],[1,1.2,1000],[2,1.04,1.05]],"ltp":1.68,"tv":99.23,"id":35736920},{"batb":[[0,1.22,38.53],[1,1.21,7.18],[2,1.2,1000]],"ltp":0.0,"tv":0.0,"id":11445383}]}]}
{"op":"mcm","clk":"11983013815","pt":1724866824805,"mc":[{"id":"1.232283786","rc":[{"batl":[[1,5.9,0]],"ltp":1.68,"tv":99.23,"id":35736920}]}]}
{"op":"mcm","clk":"11983110536","pt":1724867615374,"mc":[{"id":"1.232283786","rc":[{"batb":[[0,1.22,6.94],[1,1.21,40.36],[2,1.2,1000]],"ltp":1.68,"tv":99.23,"id":35736920},{"batb":[[1,1.2,1000],[2,1.04,1.05]],"ltp":0.0,"tv":0.0,"id":11445383}]}]}
{"op":"mcm","clk":"11983110614","pt":1724867615995,"mc":[{"id":"1.232283786","rc":[{"batb":[[0,1.23,7.18],[1,1.22,38.53],[2,1.2,1000]],"ltp":0.0,"tv":0.0,"id":11445383}]}]}
{"op":"mcm","clk":"11983213802","pt":1724868623293,"mc":[{"id":"1.232283786","rc":[{"trd":[[1.68,99.22]],"batb":[[0,1.22,6.95],[1,1.2,1000],[2,1.04,1.05]],"ltp":1.68,"tv":99.22,"id":35736920},{"batb":[[0,1.23,7.19],[1,1.2,1000],[2,1.04,1.05]],"ltp":0.0,"tv":0.0,"id":11445383}],"tv":99.22}]}
{"op":"mcm","clk":"11983218398","pt":1724868665650,"mc":[{"id":"1.232283786","rc":[{"batl":[[1,5.9,9.98]],"ltp":1.68,"tv":99.22,"id":35736920},{"batl":[[0,5.9,9.89]],"ltp":0.0,"tv":0.0,"id":11445383}]}]}
{"op":"mcm","clk":"11983219439","pt":1724868674721,"mc":[{"id":"1.232283786","rc":[{"batb":[[0,1.23,36.87],[1,1.22,6.95],[2,1.2,1000]],"ltp":1.68,"tv":99.22,"id":35736920},{"batb":[[0,1.24,35.33],[1,1.23,7.19],[2,1.2,1000]],"ltp":0.0,"tv":0.0,"id":11445383}]}]}
{"op":"mcm","clk":"11983219608","pt":1724868676239,"mc":[{"id":"1.232283786","rc":[{"batl":[[1,5.9,0]],"ltp":1.68,"tv":99.22,"id":35736920}]}]}
{"op":"mcm","clk":"11983236202","pt":1724868831236,"mc":[{"id":"1.232283786","rc":[{"batb":[[0,2.34,2.88],[1,1.24,35.33],[2,1.23,7.19]],"ltp":0.0,"tv":0.0,"id":11445383}]}]}
{"op":"mcm","clk":"11983281549","pt":1724869266552,"mc":[{"id":"1.232283786","rc":[{"batb":[[0,1.24,200.8],[1,1.23,36.87],[2,1.22,6.95]],"ltp":1.68,"tv":99.22,"id":35736920}]}]}
{"op":"mcm","clk":"11983308926","pt":1724869523421,"mc":[{"id":"1.232283786","rc":[{"batb":[[0,1.27,196.02]],"ltp":1.68,"tv":99.22,"id":35736920}]}]}
{"op":"mcm","clk":"11983407838","pt":1724870408254,"mc":[{"id":"1.232283786","rc":[{"batb":[[0,1.28,6.95],[1,1.27,196.02],[2,1.23,36.87]],"ltp":1.68,"tv":99.22,"id":35736920}]}]}
{"op":"mcm","clk":"11983407904","pt":1724870408735,"mc":[{"id":"1.232283786","rc":[{"batb":[[1,1.25,7.19],[2,1.24,35.33]],"ltp":0.0,"tv":0.0,"id":11445383}]}]}
{"op":"mcm","clk":"11983415367","pt":1724870475414,"mc":[{"id":"1.232283786","rc":[{"batb":[[1,1.2,1000],[2,1.04,1.05]],"ltp":1.68,"tv":99.22,"id":35736920},{"batb":[[2,1.2,1000]],"ltp":0.0,"tv":0.0,"id":11445383}]}]}
{"op":"mcm","clk":"11983415379","pt":1724870475513,"mc":[{"id":"1.232283786","rc":[{"batb":[[0,1.34,185.7],[1,1.28,6.95],[2,1.2,1000]],"ltp":1.68,"tv":99.22,"id":35736920}]}]}
{"op":"mcm","clk":"11983415880","pt":1724870479798,"mc":[{"id":"1.232283786","rc":[{"batl":[[1,5.9,10.19]],"ltp":1.68,"tv":99.22,"id":35736920}]}]}
{"op":"mcm","clk":"11983736326","pt":1724873092296,"mc":[{"id":"1.232283786","rc":[{"trd":[[1.68,99.27]],"batb":[[0,1.35,6.94],[1,1.34,185.7]],"batl":[[1,5.9,10.18]],"ltp":1.68,"tv":99.26,"id":35736920},{"batb":[[1,1.21,7.18]],"ltp":0.0,"tv":0.0,"id":11445383}],"tv":99.26}]}
{"op":"mcm","clk":"11983893420","pt":1724874610170,"mc":[{"id":"1.232283786","rc":[{"batb":[[0,1.36,182.95],[1,1.35,6.94]],"ltp":1.68,"tv":99.26,"id":35736920}]}]}
{"op":"mcm","clk":"11984006505","pt":1724875696674,"mc":[{"id":"1.232283786","rc":[{"trd":[[1.68,99.31]],"batb":[[0,1.37,6.94],[1,1.36,182.95]],"batl":[[1,5.9,10.18]],"ltp":1.68,"tv":99.31,"id":35736920}],"tv":99.31}]}
{"op":"mcm","clk":"11984033886","pt":1724875963929,"mc":[{"id":"1.232283786","rc":[{"batb":[[0,1.39,91.41],[1,1.37,6.94]],"ltp":1.68,"tv":99.31,"id":35736920}]}]}
{"op":"mcm","clk":"11984235004","pt":1724878364927,"mc":[{"id":"1.232283786","rc":[{"batb":[[1,1.2,1000],[2,1.04,1.05]],"ltp":1.68,"tv":99.31,"id":35736920}]}]}
{"op":"mcm","clk":"11984374438","pt":1724881005554,"mc":[{"id":"1.232283786","rc":[{"trd":[[1.68,99.34]],"batb":[[0,1.2,1000],[1,1.04,1.05],[2,1.03,200]],"batl":[[1,5.9,10.18]],"ltp":1.68,"tv":99.33,"id":35736920},{"batb":[[1,1.21,7.18]],"ltp":0.0,"tv":0.0,"id":11445383}],"tv":99.33}]}
{"op":"mcm","clk":"11984375247","pt":1724881021381,"mc":[{"id":"1.232283786","rc":[{"batl":[[0,5.9,9.82]],"ltp":0.0,"tv":0.0,"id":11445383}]}]}
{"op":"mcm","clk":"11984376537","pt":1724881047393,"mc":[{"id":"1.232283786","rc":[{"batb":[[0,1.21,40.36],[1,1.2,1000],[2,1.04,1.05]],"ltp":1.68,"tv":99.33,"id":35736920},{"batb":[[0,2.36,6.23],[1,2.34,2.88],[2,1.21,7.18]],"ltp":0.0,"tv":0.0,"id":11445383}]}]}
{"op":"mcm","clk":"11984376576","pt":1724881048213,"mc":[{"id":"1.232283786","rc":[{"batl":[[1,5.9,0]],"ltp":1.68,"tv":99.33,"id":35736920}]}]}
{"op":"mcm","clk":"11984416518","pt":1724881609961,"mc":[{"id":"1.232283786","rc":[{"batb":[[0,1.29,4.92],[1,1.21,40.36],[2,1.2,1000]],"ltp":1.68,"tv":99.33,"id":35736920}]}]}
{"op":"mcm","clk":"11984417260","pt":1724881624648,"mc":[{"id":"1.232283786","rc":[{"batb":[[0,1.29,5.84]],"ltp":1.68,"tv":99.33,"id":35736920}]}]}
{"op":"mcm","clk":"11984458539","pt":1724882847814,"mc":[{"id":"1.232283786","rc":[{"trd":[[1.68,99.31]],"batb":[[1,1.2,1000],[2,1.04,1.05]],"ltp":1.68,"tv":99.3,"id":35736920},{"batb":[[0,2.34,2.88],[1,1.21,7.18],[2,1.2,1000]],"ltp":0.0,"tv":0.0,"id":11445383}],"tv":99.3}]}
{"op":"mcm","clk":"11984459473","pt":1724882887455,"mc":[{"id":"1.232283786","rc":[{"batl":[[1,5.9,10.17]],"ltp":1.68,"tv":99.3,"id":35736920},{"batl":[[0,5.9,9.9]],"ltp":0.0,"tv":0.0,"id":11445383}]}]}
{"op":"mcm","clk":"11984481219","pt":1724883573518,"mc":[{"id":"1.232283786","rc":[{"batb":[[1,1.21,6.49],[2,1.2,1000]],"ltp":1.68,"tv":99.3,"id":35736920}]}]}
{"op":"mcm","clk":"11984607653","pt":1724886774788,"mc":[{"id":"1.232283786","rc":[{"trd":[[1.68,99.31]],"batl":[[1,5.9,10.17]],"ltp":1.68,"tv":99.31,"id":35736920},{"batb":[[1,1.21,7.18]],"batl":[[0,5.9,9.91]],"ltp":0.0,"tv":0.0,"id":11445383}],"tv":99.31}]}
{"op":"mcm","clk":"11984953042","pt":1724892174783,"mc":[{"id":"1.232283786","rc":[{"trd":[[1.68,99.29]],"ltp":1.68,"tv":99.28,"id":35736920}],"tv":99.28}]}
{"op":"mcm","clk":"11985289257","pt":1724897574783,"mc":[{"id":"1.232283786","rc":[{"trd":[[1.68,99.32]],"batb":[[0,1.29,5.84],[1,1.21,6.48]],"batl":[[1,5.9,10.17]],"ltp":1.68,"tv":99.31,"id":35736920},{"batb":[[1,1.21,7.17]],"batl":[[0,5.9,9.9]],"ltp":0.0,"tv":0.0,"id":11445383}],"tv":99.31}]}
{"op":"mcm","clk":"11985313052","pt":1724897817892,"mc":[{"id":"1.232283786","rc":[{"batl":[[0,1.68,58.33]],"ltp":1.68,"tv":99.31,"id":35736920}]}]}
{"op":"mcm","clk":"11985313147","pt":1724897819897,"mc":[{"id":"1.232283786","rc":[{"batl":[[1,5.9,0]],"ltp":1.68,"tv":99.31,"id":35736920}]}]}
{"op":"mcm","clk":"11985395789","pt":1724899385796,"mc":[{"id":"1.232283786","rc":[{"batb":[[1,1.2,1000],[2,1.04,1.05]],"ltp":0.0,"tv":0.0,"id":11445383}]}]}
{"op":"mcm","clk":"11985568229","pt":1724902974788,"mc":[{"id":"1.232283786","rc":[{"trd":[[1.68,99.34]],"batb":[[0,1.29,5.84]],"batl":[[0,1.68,58.35]],"ltp":1.68,"tv":99.34,"id":35736920},{"batl":[[0,5.9,9.91]],"ltp":0.0,"tv":0.0,"id":11445383}],"tv":99.34}]}
{"op":"mcm","clk":"11985611063","pt":1724903843096,"mc":[{"id":"1.232283786","rc":[{"batb":[[0,1.3,53.17],[1,1.29,4.91],[2,1.21,6.48]],"ltp":1.68,"tv":99.34,"id":35736920}]}]}
{"op":"mcm","clk":"11985651021","pt":1724904762868,"mc":[{"id":"1.232283786","rc":[{"trd":[[1.68,99.39]],"batb":[[2,1.2,1000]],"batl":[[0,1.68,58.38]],"ltp":1.68,"tv":99.38,"id":35736920}],"tv":99.38}]}
{"op":"mcm","clk":"11985748042","pt":1724907836929,"mc":[{"id":"1.232283786","rc":[{"trd":[[1.68,99.44]],"batb":[[0,1.3,58.08],[1,1.2,1000],[2,1.04,1.05]],"batl":[[0,1.68,58.41]],"ltp":1.68,"tv":99.43,"id":35736920}],"tv":99.43}]}
{"op":"mcm","clk":"11985935549","pt":1724913774788,"mc":[{"id":"1.232283786","rc":[{"trd":[[1.68,99.44]],"batb":[[0,1.3,58.07]],"batl":[[0,1.68,58.41]],"ltp":1.68,"tv":99.44,"id":35736920}],"tv":99.44}]}
{"op":"mcm","clk":"11985946977","pt":1724913805467,"mc":[{"id":"1.232283786","rc":[{"batb":[[0,1.68,5.67],[1,1.3,58.07],[2,1.2,1000]],"ltp":1.68,"tv":99.44,"id":35736920}]}]}
{"op":"mcm","clk":"11985947083","pt":1724913808988,"mc":[{"id":"1.232283786","rc":[{"batl":[[0,5.9,10.01]],"ltp":1.68,"tv":99.44,"id":35736920}]}]}
{"op":"mcm","clk":"11985950974","pt":1724913935103,"mc":[{"id":"1.232283786","rc":[{"batb":[[1,1.3,5.83]],"ltp":1.68,"tv":99.44,"id":35736920}]}]}
{"op":"mcm","clk":"11985951027","pt":1724913936698,"mc":[{"id":"1.232283786","rc":[{"batl":[[0,5.9,10.09]],"ltp":0.0,"tv":0.0,"id":11445383}]}]}
{"op":"mcm","clk":"11985981672","pt":1724914800827,"mc":[{"id":"1.232283786","rc":[{"batb":[[0,1.69,5],[1,1.68,5.67],[2,1.3,5.83]],"ltp":1.68,"tv":99.44,"id":35736920}]}]}
{"op":"mcm","clk":"11985981812","pt":1724914804231,"mc":[{"id":"1.232283786","rc":[{"trd":[[1.68,99.47]],"batb":[[0,1.68,5.67],[1,1.3,5.83],[2,1.2,1000]],"batl":[[0,5.9,10]],"ltp":1.68,"tv":99.47,"id":35736920}],"tv":99.47}]}
{"op":"mcm","clk":"11985981994","pt":1724914808277,"mc":[{"id":"1.232283786","rc":[{"batb":[[0,1.69,5],[1,1.68,5.67],[2,1.3,5.83]],"ltp":1.68,"tv":99.47,"id":35736920},{"batl":[[0,5.9,10.09]],"ltp":0.0,"tv":0.0,"id":11445383}]}]}
{"op":"mcm","clk":"11985982144","pt":1724914811437,"mc":[{"id":"1.232283786","rc":[{"batb":[[0,1.68,5.67],[1,1.3,5.83],[2,1.2,1000]],"ltp":1.68,"tv":99.47,"id":35736920}]}]}
{"op":"mcm","clk":"11985982415","pt":1724914817547,"mc":[{"id":"1.232283786","rc":[{"batb":[[0,1.69,5],[1,1.68,5.67],[2,1.3,5.83]],"ltp":1.68,"tv":99.47,"id":35736920}]}]}
{"op":"mcm","clk":"11985982572","pt":1724914820949,"mc":[{"id":"1.232283786","rc":[{"batb":[[0,1.68,5.67],[1,1.3,5.83],[2,1.2,1000]],"ltp":1.68,"tv":99.47,"id":35736920}]}]}
{"op":"mcm","clk":"11985982686","pt":1724914823672,"mc":[{"id":"1.232283786","rc":[{"batb":[[0,1.69,5],[1,1.68,5.67],[2,1.3,5.83]],"ltp":1.68,"tv":99.47,"id":35736920}]}]}
{"op":"mcm","clk":"11985982810","pt":1724914826860,"mc":[{"id":"1.232283786","rc":[{"batb":[[0,1.68,5.67],[1,1.3,5.83],[2,1.2,1000]],"ltp":1.68,"tv":99.47,"id":35736920}]}]}
{"op":"mcm","clk":"11985982909","pt":1724914829380,"mc":[{"id":"1.232283786","rc":[{"batb":[[0,1.69,5],[1,1.68,5.67],[2,1.3,5.83]],"ltp":1.68,"tv":99.47,"id":35736920}]}]}
{"op":"mcm","clk":"11985983019","pt":1724914832772,"mc":[{"id":"1.232283786","rc":[{"batb":[[0,1.68,5.67],[1,1.3,5.83],[2,1.2,1000]],"ltp":1.68,"tv":99.47,"id":35736920}]}]}
{"op":"mcm","clk":"11985983102","pt":1724914835284,"mc":[{"id":"1.232283786","rc":[{"batb":[[0,1.69,5],[1,1.68,5.67],[2,1.3,5.83]],"ltp":1.68,"tv":99.47,"id":35736920}]}]}
{"op":"mcm","clk":"11985983237","pt":1724914838470,"mc":[{"id":"1.232283786","rc":[{"batb":[[0,1.68,5.67],[1,1.3,5.83],[2,1.2,1000]],"ltp":1.68,"tv":99.47,"id":35736920}]}]}
{"op":"mcm","clk":"11985983366","pt":1724914841085,"mc":[{"id":"1.232283786","rc":[{"batb":[[0,1.69,5],[1,1.68,5.67],[2,1.3,5.83]],"ltp":1.68,"tv":99.47,"id":35736920}]}]}
{"op":"mcm","clk":"11985983521","pt":1724914844464,"mc":[{"id":"1.232283786","rc":[{"batb":[[0,1.68,5.67],[1,1.3,5.83],[2,1.2,1000]],"ltp":1.68,"tv":99.47,"id":35736920}]}]}
{"op":"mcm","clk":"11985983592","pt":1724914846969,"mc":[{"id":"1.232283786","rc":[{"batb":[[0,1.69,5],[1,1.68,5.67],[2,1.3,5.83]],"ltp":1.68,"tv":99.47,"id":35736920}]}]}
{"op":"mcm","clk":"11985983721","pt":1724914850255,"mc":[{"id":"1.232283786","rc":[{"batb":[[0,1.68,5.67],[1,1.3,5.83],[2,1.2,1000]],"ltp":1.68,"tv":99.47,"id":35736920}]}]}
{"op":"mcm","clk":"11985983868","pt":1724914854866,"mc":[{"id":"1.232283786","rc":[{"batb":[[0,1.69,5],[1,1.68,5.67],[2,1.3,5.83]],"ltp":1.68,"tv":99.47,"id":35736920}]}]}
{"op":"mcm","clk":"11985983966","pt":1724914858087,"mc":[{"id":"1.232283786","rc":[{"batb":[[0,1.68,5.67],[1,1.3,5.83],[2,1.2,1000]],"ltp":1.68,"tv":99.47,"id":35736920}]}]}
{"op":"mcm","clk":"11985984062","pt":1724914861209,"mc":[{"id":"1.232283786","rc":[{"batb":[[0,1.69,5],[1,1.68,5.67],[2,1.3,5.83]],"ltp":1.68,"tv":99.47,"id":35736920}]}]}
{"op":"mcm","clk":"11985984195","pt":1724914864484,"mc":[{"id":"1.232283786","rc":[{"batb":[[0,1.68,5.67],[1,1.3,5.83],[2,1.2,1000]],"ltp":1.68,"tv":99.47,"id":35736920}]}]}
{"op":"mcm","clk":"11985984301","pt":1724914867809,"mc":[{"id":"1.232283786","rc":[{"batb":[[0,1.69,5],[1,1.68,5.67],[2,1.3,5.83]],"ltp":1.68,"tv":99.47,"id":35736920}]}]}
{"op":"mcm","clk":"11985984424","pt":1724914871094,"mc":[{"id":"1.232283786","rc":[{"batb":[[0,1.68,5.67],[1,1.3,5.83],[2,1.2,1000]],"ltp":1.68,"tv":99.47,"id":35736920}]}]}
{"op":"mcm","clk":"11985984511","pt":1724914873716,"mc":[{"id":"1.232283786","rc":[{"batb":[[0,1.69,5],[1,1.68,5.67],[2,1.3,5.83]],"ltp":1.68,"tv":99.47,"id":35736920}]}]}
{"op":"mcm","clk":"11985984622","pt":1724914877092,"mc":[{"id":"1.232283786","rc":[{"batb":[[0,1.68,5.67],[1,1.3,5.83],[2,1.2,1000]],"ltp":1.68,"tv":99.47,"id":35736920}]}]}
{"op":"mcm","clk":"11985984751","pt":1724914879912,"mc":[{"id":"1.232283786","rc":[{"batb":[[0,1.69,5],[1,1.68,5.67],[2,1.3,5.83]],"ltp":1.68,"tv":99.47,"id":35736920}]}]}
{"op":"mcm","clk":"11985984889","pt":1724914883331,"mc":[{"id":"1.232283786","rc":[{"batb":[[0,1.68,5.67],[1,1.3,5.83],[2,1.2,1000]],"ltp":1.68,"tv":99.47,"id":35736920}]}]}
{"op":"mcm","clk":"11985984991","pt":1724914885829,"mc":[{"id":"1.232283786","rc":[{"batb":[[0,1.69,5],[1,1.68,5.67],[2,1.3,5.83]],"ltp":1.68,"tv":99.47,"id":35736920}]}]}
{"op":"mcm","clk":"11985985088","pt":1724914889150,"mc":[{"id":"1.232283786","rc":[{"batb":[[0,1.68,5.67],[1,1.3,5.83],[2,1.2,1000]],"ltp":1.68,"tv":99.47,"id":35736920}]}]}
{"op":"mcm","clk":"11985985271","pt":1724914894758,"mc":[{"id":"1.232283786","rc":[{"batb":[[0,1.69,5],[1,1.68,5.67],[2,1.3,5.83]],"ltp":1.68,"tv":99.47,"id":35736920}]}]}
{"op":"mcm","clk":"11985985370","pt":1724914898127,"mc":[{"id":"1.232283786","rc":[{"batb":[[0,1.68,5.67],[1,1.3,5.83],[2,1.2,1000]],"ltp":1.68,"tv":99.47,"id":35736920}]}]}
{"op":"mcm","clk":"11985985640","pt":1724914905956,"mc":[{"id":"1.232283786","rc":[{"batb":[[0,1.69,5],[1,1.68,5.67],[2,1.3,5.83]],"ltp":1.68,"tv":99.47,"id":35736920}]}]}
{"op":"mcm","clk":"11985985747","pt":1724914909433,"mc":[{"id":"1.232283786","rc":[{"batb":[[0,1.68,5.67],[1,1.3,5.83],[2,1.2,1000]],"ltp":1.68,"tv":99.47,"id":35736920}]}]}
{"op":"mcm","clk":"11985985822","pt":1724914911837,"mc":[{"id":"1.232283786","rc":[{"batb":[[0,1.69,5],[1,1.68,5.67],[2,1.3,5.83]],"ltp":1.68,"tv":99.47,"id":35736920}]}]}
{"op":"mcm","clk":"11985985941","pt":1724914915268,"mc":[{"id":"1.232283786","rc":[{"batb":[[0,1.68,5.67],[1,1.3,5.83],[2,1.2,1000]],"ltp":1.68,"tv":99.47,"id":35736920}]}]}
{"op":"mcm","clk":"11985986020","pt":1724914917667,"mc":[{"id":"1.232283786","rc":[{"batb":[[0,1.69,5],[1,1.68,5.67],[2,1.3,5.83]],"ltp":1.68,"tv":99.47,"id":35736920}]}]}
{"op":"mcm","clk":"11985986131","pt":1724914920988,"mc":[{"id":"1.232283786","rc":[{"batb":[[0,1.68,5.67],[1,1.3,5.83],[2,1.2,1000]],"ltp":1.68,"tv":99.47,"id":35736920}]}]}
{"op":"mcm","clk":"11985986306","pt":1724914925559,"mc":[{"id":"1.232283786","rc":[{"batb":[[0,1.69,5],[1,1.68,5.67],[2,1.3,5.83]],"ltp":1.68,"tv":99.47,"id":35736920},{"batl":[[0,5.9,10.09]],"ltp":0.0,"tv":0.0,"id":11445383}]}]}
{"op":"mcm","clk":"11985986433","pt":1724914929094,"mc":[{"id":"1.232283786","rc":[{"batb":[[0,1.68,5.67],[1,1.3,5.83],[2,1.2,1000]],"ltp":1.68,"tv":99.47,"id":35736920}]}]}
{"op":"mcm","clk":"11985986522","pt":1724914931489,"mc":[{"id":"1.232283786","rc":[{"batb":[[0,1.69,5],[1,1.68,5.67],[2,1.3,5.83]],"ltp":1.68,"tv":99.47,"id":35736920}]}]}
{"op":"mcm","clk":"11985986616","pt":1724914934806,"mc":[{"id":"1.232283786","rc":[{"batb":[[0,1.68,5.67],[1,1.3,5.83],[2,1.2,1000]],"ltp":1.68,"tv":99.47,"id":35736920}]}]}
{"op":"mcm","clk":"11985986726","pt":1724914937982,"mc":[{"id":"1.232283786","rc":[{"batb":[[0,1.69,5],[1,1.68,5.67],[2,1.3,5.83]],"ltp":1.68,"tv":99.47,"id":35736920}]}]}
{"op":"mcm","clk":"11985986835","pt":1724914941295,"mc":[{"id":"1.232283786","rc":[{"batb":[[0,1.68,5.67],[1,1.3,5.83],[2,1.2,1000]],"ltp":1.68,"tv":99.47,"id":35736920}]}]}
{"op":"mcm","clk":"11985986928","pt":1724914944810,"mc":[{"id":"1.232283786","rc":[{"batb":[[0,1.69,5],[1,1.68,5.67],[2,1.3,5.83]],"ltp":1.68,"tv":99.47,"id":35736920}]}]}
{"op":"mcm","clk":"11985987032","pt":1724914948276,"mc":[{"id":"1.232283786","rc":[{"batb":[[0,1.68,5.67],[1,1.3,5.83],[2,1.2,1000]],"ltp":1.68,"tv":99.47,"id":35736920}]}]}
{"op":"mcm","clk":"11985987112","pt":1724914950780,"mc":[{"id":"1.232283786","rc":[{"batb":[[0,1.69,5],[1,1.68,5.67],[2,1.3,5.83]],"ltp":1.68,"tv":99.47,"id":35736920}]}]}
{"op":"mcm","clk":"11985987197","pt":1724914954200,"mc":[{"id":"1.232283786","rc":[{"batb":[[0,1.68,5.67],[1,1.3,5.83],[2,1.2,1000]],"ltp":1.68,"tv":99.47,"id":35736920}]}]}
{"op":"mcm","clk":"11985987289","pt":1724914957311,"mc":[{"id":"1.232283786","rc":[{"batb":[[0,1.69,5],[1,1.68,5.67],[2,1.3,5.83]],"ltp":1.68,"tv":99.47,"id":35736920}]}]}
{"op":"mcm","clk":"11985987405","pt":1724914960627,"mc":[{"id":"1.232283786","rc":[{"batb":[[0,1.68,5.67],[1,1.3,5.83],[2,1.2,1000]],"ltp":1.68,"tv":99.47,"id":35736920}]}]}
{"op":"mcm","clk":"11985987491","pt":1724914963635,"mc":[{"id":"1.232283786","rc":[{"batb":[[0,1.69,5],[1,1.68,5.67],[2,1.3,5.83]],"ltp":1.68,"tv":99.47,"id":35736920}]}]}
{"op":"mcm","clk":"11985987597","pt":1724914967020,"mc":[{"id":"1.232283786","rc":[{"batb":[[0,1.68,5.67],[1,1.3,5.83],[2,1.2,1000]],"ltp":1.68,"tv":99.47,"id":35736920}]}]}
{"op":"mcm","clk":"11985987666","pt":1724914969587,"mc":[{"id":"1.232283786","rc":[{"batb":[[0,1.69,5],[1,1.68,5.67],[2,1.3,5.83]],"ltp":1.68,"tv":99.47,"id":35736920}]}]}
{"op":"mcm","clk":"11985987767","pt":1724914972913,"mc":[{"id":"1.232283786","rc":[{"batb":[[0,1.68,5.67],[1,1.3,5.83],[2,1.2,1000]],"ltp":1.68,"tv":99.47,"id":35736920}]}]}
{"op":"mcm","clk":"11985987844","pt":1724914975517,"mc":[{"id":"1.232283786","rc":[{"batb":[[0,1.69,5],[1,1.68,5.67],[2,1.3,5.83]],"ltp":1.68,"tv":99.47,"id":35736920}]}]}
{"op":"mcm","clk":"11985987928","pt":1724914978843,"mc":[{"id":"1.232283786","rc":[{"batb":[[0,1.68,5.67],[1,1.3,5.83],[2,1.2,1000]],"ltp":1.68,"tv":99.47,"id":35736920}]}]}
{"op":"mcm","clk":"11985988034","pt":1724914982637,"mc":[{"id":"1.232283786","rc":[{"batb":[[0,1.69,5],[1,1.68,5.67],[2,1.3,5.83]],"ltp":1.68,"tv":99.47,"id":35736920}]}]}
{"op":"mcm","clk":"11985988150","pt":1724914986011,"mc":[{"id":"1.232283786","rc":[{"batb":[[0,1.68,5.67],[1,1.3,5.83],[2,1.2,1000]],"ltp":1.68,"tv":99.47,"id":35736920}]}]}
{"op":"mcm","clk":"11985988286","pt":1724914990408,"mc":[{"id":"1.232283786","rc":[{"batb":[[0,1.69,5],[1,1.68,5.67],[2,1.3,5.83]],"ltp":1.68,"tv":99.47,"id":35736920}]}]}
{"op":"mcm","clk":"11985988402","pt":1724914993823,"mc":[{"id":"1.232283786","rc":[{"batb":[[0,1.68,5.67],[1,1.3,5.83],[2,1.2,1000]],"ltp":1.68,"tv":99.47,"id":35736920}]}]}
{"op":"mcm","clk":"11985988616","pt":1724915000928,"mc":[{"id":"1.232283786","rc":[{"batb":[[0,1.69,5],[1,1.68,5.67],[2,1.3,5.83]],"ltp":1.68,"tv":99.47,"id":35736920}]}]}
{"op":"mcm","clk":"11985988712","pt":1724915004452,"mc":[{"id":"1.232283786","rc":[{"batb":[[0,1.68,5.67],[1,1.3,5.83],[2,1.2,1000]],"ltp":1.68,"tv":99.47,"id":35736920}]}]}
{"op":"mcm","clk":"11985988771","pt":1724915006857,"mc":[{"id":"1.232283786","rc":[{"batb":[[0,1.69,5],[1,1.68,5.67],[2,1.3,5.83]],"ltp":1.68,"tv":99.47,"id":35736920}]}]}
{"op":"mcm","clk":"11985988856","pt":1724915010173,"mc":[{"id":"1.232283786","rc":[{"batb":[[0,1.68,5.67],[1,1.3,5.83],[2,1.2,1000]],"ltp":1.68,"tv":99.47,"id":35736920}]}]}
{"op":"mcm","clk":"11985988934","pt":1724915012477,"mc":[{"id":"1.232283786","rc":[{"batb":[[0,1.69,5],[1,1.68,5.67],[2,1.3,5.83]],"ltp":1.68,"tv":99.47,"id":35736920}]}]}
{"op":"mcm","clk":"11985989008","pt":1724915015646,"mc":[{"id":"1.232283786","rc":[{"batb":[[0,1.68,5.67],[1,1.3,5.83],[2,1.2,1000]],"ltp":1.68,"tv":99.47,"id":35736920}]}]}
{"op":"mcm","clk":"11985989216","pt":1724915022163,"mc":[{"id":"1.232283786","rc":[{"batb":[[0,1.69,5],[1,1.68,5.67],[2,1.3,5.83]],"ltp":1.68,"tv":99.47,"id":35736920}]}]}
{"op":"mcm","clk":"11985989310","pt":1724915025588,"mc":[{"id":"1.232283786","rc":[{"batb":[[0,1.68,5.67],[1,1.3,5.83],[2,1.2,1000]],"ltp":1.68,"tv":99.47,"id":35736920}]}]}
{"op":"mcm","clk":"11985989487","pt":1724915031960,"mc":[{"id":"1.232283786","rc":[{"batb":[[0,1.69,5],[1,1.68,5.67],[2,1.3,5.83]],"ltp":1.68,"tv":99.47,"id":35736920}]}]}
{"op":"mcm","clk":"11985989586","pt":1724915035358,"mc":[{"id":"1.232283786","rc":[{"batb":[[0,1.68,5.67],[1,1.3,5.83],[2,1.2,1000]],"ltp":1.68,"tv":99.47,"id":35736920}]}]}
{"op":"mcm","clk":"11985989750","pt":1724915040066,"mc":[{"id":"1.232283786","rc":[{"batb":[[0,1.69,5],[1,1.68,5.67],[2,1.3,5.83]],"ltp":1.68,"tv":99.47,"id":35736920}]}]}
{"op":"mcm","clk":"11985989868","pt":1724915043394,"mc":[{"id":"1.232283786","rc":[{"batb":[[0,1.68,5.67],[1,1.3,5.83],[2,1.2,1000]],"ltp":1.68,"tv":99.47,"id":35736920}]}]}
{"op":"mcm","clk":"11985990007","pt":1724915047804,"mc":[{"id":"1.232283786","rc":[{"batb":[[0,1.69,5],[1,1.68,5.67],[2,1.3,5.83]],"ltp":1.68,"tv":99.47,"id":35736920}]}]}
{"op":"mcm","clk":"11985990121","pt":1724915051079,"mc":[{"id":"1.232283786","rc":[{"batb":[[0,1.68,5.67],[1,1.3,5.83],[2,1.2,1000]],"ltp":1.68,"tv":99.47,"id":35736920}]}]}
{"op":"mcm","clk":"11985990300","pt":1724915054201,"mc":[{"id":"1.232283786","rc":[{"batb":[[0,1.69,5],[1,1.68,5.67],[2,1.3,5.83]],"ltp":1.68,"tv":99.47,"id":35736920}]}]}
{"op":"mcm","clk":"11985990406","pt":1724915057621,"mc":[{"id":"1.232283786","rc":[{"batb":[[0,1.68,5.67],[1,1.3,5.83],[2,1.2,1000]],"ltp":1.68,"tv":99.47,"id":35736920}]}]}
{"op":"mcm","clk":"11985990529","pt":1724915062220,"mc":[{"id":"1.232283786","rc":[{"batb":[[0,1.69,5],[1,1.68,5.67],[2,1.3,5.83]],"ltp":1.68,"tv":99.47,"id":35736920}]}]}
{"op":"mcm","clk":"11985990635","pt":1724915065503,"mc":[{"id":"1.232283786","rc":[{"batb":[[0,1.68,5.67],[1,1.3,5.83],[2,1.2,1000]],"ltp":1.68,"tv":99.47,"id":35736920}]}]}
{"op":"mcm","clk":"11985990806","pt":1724915072005,"mc":[{"id":"1.232283786","rc":[{"batb":[[0,1.69,5],[1,1.68,5.67],[2,1.3,5.83]],"ltp":1.68,"tv":99.47,"id":35736920}]}]}
{"op":"mcm","clk":"11985990934","pt":1724915075344,"mc":[{"id":"1.232283786","rc":[{"batb":[[0,1.68,5.67],[1,1.3,5.83],[2,1.2,1000]],"ltp":1.68,"tv":99.47,"id":35736920}]}]}
{"op":"mcm","clk":"11985991000","pt":1724915077649,"mc":[{"id":"1.232283786","rc":[{"batb":[[0,1.69,5],[1,1.68,5.67],[2,1.3,5.83]],"ltp":1.68,"tv":99.47,"id":35736920}]}]}
{"op":"mcm","clk":"11985991118","pt":1724915081037,"mc":[{"id":"1.232283786","rc":[{"batb":[[0,1.68,5.67],[1,1.3,5.83],[2,1.2,1000]],"ltp":1.68,"tv":99.47,"id":35736920}]}]}
{"op":"mcm","clk":"11985991171","pt":1724915083648,"mc":[{"id":"1.232283786","rc":[{"batb":[[0,1.69,5],[1,1.68,5.67],[2,1.3,5.83]],"ltp":1.68,"tv":99.47,"id":35736920}]}]}
{"op":"mcm","clk":"11985991274","pt":1724915087144,"mc":[{"id":"1.232283786","rc":[{"batb":[[0,1.68,5.67],[1,1.3,5.83],[2,1.2,1000]],"ltp":1.68,"tv":99.47,"id":35736920}]}]}
{"op":"mcm","clk":"11985991386","pt":1724915090627,"mc":[{"id":"1.232283786","rc":[{"batb":[[0,1.69,5],[1,1.68,5.67],[2,1.3,5.83]],"ltp":1.68,"tv":99.47,"id":35736920}]}]}
{"op":"mcm","clk":"11985991506","pt":1724915093849,"mc":[{"id":"1.232283786","rc":[{"batb":[[0,1.68,5.67],[1,1.3,5.83],[2,1.2,1000]],"ltp":1.68,"tv":99.47,"id":35736920}]}]}
{"op":"mcm","clk":"11985991608","pt":1724915097026,"mc":[{"id":"1.232283786","rc":[{"batb":[[0,1.69,5],[1,1.68,5.67],[2,1.3,5.83]],"ltp":1.68,"tv":99.47,"id":35736920}]}]}
{"op":"mcm","clk":"11985991696","pt":1724915100354,"mc":[{"id":"1.232283786","rc":[{"batb":[[0,1.68,5.67],[1,1.3,5.83],[2,1.2,1000]],"ltp":1.68,"tv":99.47,"id":35736920}]}]}
{"op":"mcm","clk":"11985991790","pt":1724915103336,"mc":[{"id":"1.232283786","rc":[{"batb":[[0,1.69,5],[1,1.68,5.67],[2,1.3,5.83]],"ltp":1.68,"tv":99.47,"id":35736920},{"batl":[[0,5.9,10.09]],"ltp":0.0,"tv":0.0,"id":11445383}]}]}
{"op":"mcm","clk":"11985991902","pt":1724915106661,"mc":[{"id":"1.232283786","rc":[{"batb":[[0,1.68,5.67],[1,1.3,5.83],[2,1.2,1000]],"ltp":1.68,"tv":99.47,"id":35736920}]}]}
{"op":"mcm","clk":"11985992044","pt":1724915111983,"mc":[{"id":"1.232283786","rc":[{"batb":[[0,1.69,5],[1,1.68,5.67],[2,1.3,5.83]],"ltp":1.68,"tv":99.47,"id":35736920}]}]}
{"op":"mcm","clk":"11985992141","pt":1724915115256,"mc":[{"id":"1.232283786","rc":[{"batb":[[0,1.68,5.67],[1,1.3,5.83],[2,1.2,1000]],"ltp":1.68,"tv":99.47,"id":35736920}]}]}
{"op":"mcm","clk":"11985992210","pt":1724915118070,"mc":[{"id":"1.232283786","rc":[{"batb":[[0,1.69,5],[1,1.68,5.67],[2,1.3,5.83]],"ltp":1.68,"tv":99.47,"id":35736920}]}]}
{"op":"mcm","clk":"11985992299","pt":1724915121388,"mc":[{"id":"1.232283786","rc":[{"batb":[[0,1.68,5.67],[1,1.3,5.83],[2,1.2,1000]],"ltp":1.68,"tv":99.47,"id":35736920}]}]}
{"op":"mcm","clk":"11985992380","pt":1724915123870,"mc":[{"id":"1.232283786","rc":[{"batb":[[0,1.69,5],[1,1.68,5.67],[2,1.3,5.83]],"ltp":1.68,"tv":99.47,"id":35736920}]}]}
{"op":"mcm","clk":"11985992506","pt":1724915127166,"mc":[{"id":"1.232283786","rc":[{"batb":[[0,1.68,5.67],[1,1.3,5.83],[2,1.2,1000]],"ltp":1.68,"tv":99.47,"id":35736920}]}]}
{"op":"mcm","clk":"11985992595","pt":1724915129773,"mc":[{"id":"1.232283786","rc":[{"batb":[[0,1.69,5],[1,1.68,5.67],[2,1.3,5.83]],"ltp":1.68,"tv":99.47,"id":35736920}]}]}
{"op":"mcm","clk":"11985992686","pt":1724915133098,"mc":[{"id":"1.232283786","rc":[{"batb":[[0,1.68,5.67],[1,1.3,5.83],[2,1.2,1000]],"ltp":1.68,"tv":99.47,"id":35736920}]}]}
{"op":"mcm","clk":"11985992761","pt":1724915135599,"mc":[{"id":"1.232283786","rc":[{"batb":[[0,1.69,5],[1,1.68,5.67],[2,1.3,5.83]],"ltp":1.68,"tv":99.47,"id":35736920}]}]}
{"op":"mcm","clk":"11985992860","pt":1724915138986,"mc":[{"id":"1.232283786","rc":[{"batb":[[0,1.68,5.67],[1,1.3,5.83],[2,1.2,1000]],"ltp":1.68,"tv":99.47,"id":35736920}]}]}
{"op":"mcm","clk":"11985992975","pt":1724915141803,"mc":[{"id":"1.232283786","rc":[{"batb":[[0,1.69,5],[1,1.68,5.67],[2,1.3,5.83]],"ltp":1.68,"tv":99.47,"id":35736920}]}]}
{"op":"mcm","clk":"11985993062","pt":1724915145188,"mc":[{"id":"1.232283786","rc":[{"batb":[[0,1.68,5.67],[1,1.3,5.83],[2,1.2,1000]],"ltp":1.68,"tv":99.47,"id":35736920}]}]}
{"op":"mcm","clk":"11985993161","pt":1724915148322,"mc":[{"id":"1.232283786","rc":[{"batb":[[0,1.69,5],[1,1.68,5.67],[2,1.3,5.83]],"ltp":1.68,"tv":99.47,"id":35736920}]}]}
{"op":"mcm","clk":"11985993249","pt":1724915151498,"mc":[{"id":"1.232283786","rc":[{"batb":[[0,1.68,5.67],[1,1.3,5.83],[2,1.2,1000]],"ltp":1.68,"tv":99.47,"id":35736920}]}]}
{"op":"mcm","clk":"11985993342","pt":1724915154817,"mc":[{"id":"1.232283786","rc":[{"batb":[[0,1.69,5],[1,1.68,5.67],[2,1.3,5.83]],"ltp":1.68,"tv":99.47,"id":35736920}]}]}
{"op":"mcm","clk":"11985993440","pt":1724915158038,"mc":[{"id":"1.232283786","rc":[{"batb":[[0,1.68,5.67],[1,1.3,5.83],[2,1.2,1000]],"ltp":1.68,"tv":99.47,"id":35736920}]}]}
{"op":"mcm","clk":"11985993513","pt":1724915161110,"mc":[{"id":"1.232283786","rc":[{"batb":[[0,1.69,5],[1,1.68,5.67],[2,1.3,5.83]],"ltp":1.68,"tv":99.47,"id":35736920}]}]}
{"op":"mcm","clk":"11985993602","pt":1724915164339,"mc":[{"id":"1.232283786","rc":[{"batb":[[0,1.68,5.67],[1,1.3,5.83],[2,1.2,1000]],"ltp":1.68,"tv":99.47,"id":35736920}]}]}
{"op":"mcm","clk":"11985993674","pt":1724915166912,"mc":[{"id":"1.232283786","rc":[{"batb":[[0,1.69,5],[1,1.68,5.67],[2,1.3,5.83]],"ltp":1.68,"tv":99.47,"id":35736920}]}]}
{"op":"mcm","clk":"11985993770","pt":1724915170359,"mc":[{"id":"1.232283786","rc":[{"batb":[[0,1.68,5.67],[1,1.3,5.83],[2,1.2,1000]],"ltp":1.68,"tv":99.47,"id":35736920}]}]}
{"op":"mcm","clk":"11985993843","pt":1724915172929,"mc":[{"id":"1.232283786","rc":[{"batb":[[0,1.69,5],[1,1.68,5.67],[2,1.3,5.83]],"ltp":1.68,"tv":99.47,"id":35736920}]}]}
{"op":"mcm","clk":"11985993923","pt":1724915176311,"mc":[{"id":"1.232283786","rc":[{"batb":[[0,1.68,5.67],[1,1.3,5.83],[2,1.2,1000]],"ltp":1.68,"tv":99.47,"id":35736920}]}]}
{"op":"mcm","clk":"11985994055","pt":1724915180041,"mc":[{"id":"1.232283786","rc":[{"batb":[[0,1.69,5],[1,1.68,5.67],[2,1.3,5.83]],"ltp":1.68,"tv":99.47,"id":35736920}]}]}
{"op":"mcm","clk":"11985994168","pt":1724915183321,"mc":[{"id":"1.232283786","rc":[{"batb":[[0,1.68,5.67],[1,1.3,5.83],[2,1.2,1000]],"ltp":1.68,"tv":99.47,"id":35736920}]}]}
{"op":"mcm","clk":"11985994248","pt":1724915186745,"mc":[{"id":"1.232283786","rc":[{"batb":[[0,1.69,5],[1,1.68,5.67],[2,1.3,5.83]],"ltp":1.68,"tv":99.47,"id":35736920}]}]}
{"op":"mcm","clk":"11985994338","pt":1724915189971,"mc":[{"id":"1.232283786","rc":[{"batb":[[0,1.68,5.67],[1,1.3,5.83],[2,1.2,1000]],"ltp":1.68,"tv":99.47,"id":35736920}]}]}
{"op":"mcm","clk":"11985994445","pt":1724915192745,"mc":[{"id":"1.232283786","rc":[{"batb":[[0,1.69,5],[1,1.68,5.67],[2,1.3,5.83]],"ltp":1.68,"tv":99.47,"id":35736920}]}]}
{"op":"mcm","clk":"11985994528","pt":1724915196170,"mc":[{"id":"1.232283786","rc":[{"batb":[[0,1.68,5.67],[1,1.3,5.83],[2,1.2,1000]],"ltp":1.68,"tv":99.47,"id":35736920}]}]}
{"op":"mcm","clk":"11985994734","pt":1724915201961,"mc":[{"id":"1.232283786","rc":[{"batb":[[0,1.69,5],[1,1.68,5.67],[2,1.3,5.83]],"ltp":1.68,"tv":99.47,"id":35736920}]}]}
{"op":"mcm","clk":"11985994826","pt":1724915205345,"mc":[{"id":"1.232283786","rc":[{"batb":[[0,1.68,5.67],[1,1.3,5.83],[2,1.2,1000]],"ltp":1.68,"tv":99.47,"id":35736920}]}]}
{"op":"mcm","clk":"11985994892","pt":1724915207853,"mc":[{"id":"1.232283786","rc":[{"batb":[[0,1.69,5],[1,1.68,5.67],[2,1.3,5.83]],"ltp":1.68,"tv":99.47,"id":35736920}]}]}
{"op":"mcm","clk":"11985994975","pt":1724915211176,"mc":[{"id":"1.232283786","rc":[{"batb":[[0,1.68,5.67],[1,1.3,5.83],[2,1.2,1000]],"ltp":1.68,"tv":99.47,"id":35736920}]}]}
{"op":"mcm","clk":"11985995126","pt":1724915216089,"mc":[{"id":"1.232283786","rc":[{"batb":[[0,1.69,5],[1,1.68,5.67],[2,1.3,5.83]],"ltp":1.68,"tv":99.47,"id":35736920}]}]}
{"op":"mcm","clk":"11985995198","pt":1724915219361,"mc":[{"id":"1.232283786","rc":[{"batb":[[0,1.68,5.67],[1,1.3,5.83],[2,1.2,1000]],"ltp":1.68,"tv":99.47,"id":35736920}]}]}
{"op":"mcm","clk":"11985995429","pt":1724915225466,"mc":[{"id":"1.232283786","rc":[{"batb":[[0,1.69,5],[1,1.68,5.67],[2,1.3,5.83]],"ltp":1.68,"tv":99.47,"id":35736920}]}]}
{"op":"mcm","clk":"11985995513","pt":1724915228900,"mc":[{"id":"1.232283786","rc":[{"batb":[[0,1.68,5.67],[1,1.3,5.83],[2,1.2,1000]],"ltp":1.68,"tv":99.47,"id":35736920}]}]}
{"op":"mcm","clk":"11985995683","pt":1724915235409,"mc":[{"id":"1.232283786","rc":[{"batb":[[0,1.69,5],[1,1.68,5.67],[2,1.3,5.83]],"ltp":1.68,"tv":99.47,"id":35736920}]}]}
{"op":"mcm","clk":"11985995793","pt":1724915238999,"mc":[{"id":"1.232283786","rc":[{"batb":[[0,1.68,5.67],[1,1.3,5.83],[2,1.2,1000]],"ltp":1.68,"tv":99.47,"id":35736920}]}]}
{"op":"mcm","clk":"11985995834","pt":1724915241305,"mc":[{"id":"1.232283786","rc":[{"batb":[[0,1.69,5],[1,1.68,5.67],[2,1.3,5.83]],"ltp":1.68,"tv":99.47,"id":35736920}]}]}
{"op":"mcm","clk":"11985995921","pt":1724915244713,"mc":[{"id":"1.232283786","rc":[{"batb":[[0,1.68,5.67],[1,1.3,5.83],[2,1.2,1000]],"ltp":1.68,"tv":99.47,"id":35736920}]}]}
{"op":"mcm","clk":"11985996067","pt":1724915248218,"mc":[{"id":"1.232283786","rc":[{"batb":[[0,1.69,5],[1,1.68,5.67],[2,1.3,5.83]],"ltp":1.68,"tv":99.47,"id":35736920}]}]}
{"op":"mcm","clk":"11985996183","pt":1724915251610,"mc":[{"id":"1.232283786","rc":[{"batb":[[0,1.68,5.67],[1,1.3,5.83],[2,1.2,1000]],"ltp":1.68,"tv":99.47,"id":35736920}]}]}
{"op":"mcm","clk":"11985996273","pt":1724915255339,"mc":[{"id":"1.232283786","rc":[{"batb":[[0,1.69,5],[1,1.68,5.67],[2,1.3,5.83]],"ltp":1.68,"tv":99.47,"id":35736920}]}]}
{"op":"mcm","clk":"11985996367","pt":1724915258720,"mc":[{"id":"1.232283786","rc":[{"batb":[[0,1.68,5.67],[1,1.3,5.83],[2,1.2,1000]],"ltp":1.68,"tv":99.47,"id":35736920}]}]}
{"op":"mcm","clk":"11985996458","pt":1724915261944,"mc":[{"id":"1.232283786","rc":[{"batb":[[0,1.69,5],[1,1.68,5.67],[2,1.3,5.83]],"ltp":1.68,"tv":99.47,"id":35736920}]}]}
{"op":"mcm","clk":"11985996555","pt":1724915265333,"mc":[{"id":"1.232283786","rc":[{"batb":[[0,1.68,5.67],[1,1.3,5.83],[2,1.2,1000]],"ltp":1.68,"tv":99.47,"id":35736920}]}]}
{"op":"mcm","clk":"11985996645","pt":1724915269118,"mc":[{"id":"1.232283786","rc":[{"batb":[[0,1.69,5],[1,1.68,5.67],[2,1.3,5.83]],"ltp":1.68,"tv":99.47,"id":35736920}]}]}
{"op":"mcm","clk":"11985996724","pt":1724915272444,"mc":[{"id":"1.232283786","rc":[{"batb":[[0,1.68,5.67],[1,1.3,5.83],[2,1.2,1000]],"ltp":1.68,"tv":99.47,"id":35736920}]}]}
{"op":"mcm","clk":"11985996798","pt":1724915275144,"mc":[{"id":"1.232283786","rc":[{"batb":[[0,1.69,5],[1,1.68,5.67],[2,1.3,5.83]],"ltp":1.68,"tv":99.47,"id":35736920}]}]}
{"op":"mcm","clk":"11985996881","pt":1724915278522,"mc":[{"id":"1.232283786","rc":[{"batb":[[0,1.68,5.67],[1,1.3,5.83],[2,1.2,1000]],"ltp":1.68,"tv":99.47,"id":35736920}]}]}
{"op":"mcm","clk":"11985996974","pt":1724915282060,"mc":[{"id":"1.232283786","rc":[{"batb":[[0,1.69,5],[1,1.68,5.67],[2,1.3,5.83]],"ltp":1.68,"tv":99.47,"id":35736920}]}]}
{"op":"mcm","clk":"11985997082","pt":1724915285455,"mc":[{"id":"1.232283786","rc":[{"batb":[[0,1.68,5.67],[1,1.3,5.83],[2,1.2,1000]],"ltp":1.68,"tv":99.47,"id":35736920}]}]}
{"op":"mcm","clk":"11985997135","pt":1724915287145,"mc":[{"id":"1.232283786","rc":[{"batl":[[0,5.9,10.09]],"ltp":0.0,"tv":0.0,"id":11445383}]}]}
{"op":"mcm","clk":"11985997217","pt":1724915289348,"mc":[{"id":"1.232283786","rc":[{"batb":[[0,1.69,5],[1,1.68,5.67],[2,1.3,5.83]],"ltp":1.68,"tv":99.47,"id":35736920}]}]}
{"op":"mcm","clk":"11985997334","pt":1724915292845,"mc":[{"id":"1.232283786","rc":[{"batb":[[0,1.68,5.67],[1,1.3,5.83],[2,1.2,1000]],"ltp":1.68,"tv":99.47,"id":35736920}]}]}
{"op":"mcm","clk":"11985997451","pt":1724915296159,"mc":[{"id":"1.232283786","rc":[{"batb":[[0,1.69,5],[1,1.68,5.67],[2,1.3,5.83]],"ltp":1.68,"tv":99.47,"id":35736920}]}]}
{"op":"mcm","clk":"11985997557","pt":1724915299543,"mc":[{"id":"1.232283786","rc":[{"batb":[[0,1.68,5.67],[1,1.3,5.83],[2,1.2,1000]],"ltp":1.68,"tv":99.47,"id":35736920}]}]}
{"op":"mcm","clk":"11985997641","pt":1724915302778,"mc":[{"id":"1.232283786","rc":[{"batb":[[0,1.69,5],[1,1.68,5.67],[2,1.3,5.83]],"ltp":1.68,"tv":99.47,"id":35736920}]}]}
{"op":"mcm","clk":"11985997765","pt":1724915306179,"mc":[{"id":"1.232283786","rc":[{"batb":[[0,1.68,5.67],[1,1.3,5.83],[2,1.2,1000]],"ltp":1.68,"tv":99.47,"id":35736920}]}]}
{"op":"mcm","clk":"11985997958","pt":1724915310859,"mc":[{"id":"1.232283786","rc":[{"batb":[[0,1.69,5],[1,1.68,5.67],[2,1.3,5.83]],"ltp":1.68,"tv":99.47,"id":35736920}]}]}
{"op":"mcm","clk":"11985998051","pt":1724915314281,"mc":[{"id":"1.232283786","rc":[{"batb":[[0,1.68,5.67],[1,1.3,5.83],[2,1.2,1000]],"ltp":1.68,"tv":99.47,"id":35736920}]}]}
{"op":"mcm","clk":"11985998140","pt":1724915317559,"mc":[{"id":"1.232283786","rc":[{"batb":[[0,1.69,5],[1,1.68,5.67],[2,1.3,5.83]],"ltp":1.68,"tv":99.47,"id":35736920}]}]}
{"op":"mcm","clk":"11985998260","pt":1724915320891,"mc":[{"id":"1.232283786","rc":[{"batb":[[0,1.68,5.67],[1,1.3,5.83],[2,1.2,1000]],"ltp":1.68,"tv":99.47,"id":35736920}]}]}
{"op":"mcm","clk":"11985998374","pt":1724915323467,"mc":[{"id":"1.232283786","rc":[{"batb":[[0,1.69,5],[1,1.68,5.67],[2,1.3,5.83]],"ltp":1.68,"tv":99.47,"id":35736920}]}]}
{"op":"mcm","clk":"11985998486","pt":1724915326896,"mc":[{"id":"1.232283786","rc":[{"batb":[[0,1.68,5.67],[1,1.3,5.83],[2,1.2,1000]],"ltp":1.68,"tv":99.47,"id":35736920}]}]}
{"op":"mcm","clk":"11985998556","pt":1724915329465,"mc":[{"id":"1.232283786","rc":[{"batb":[[0,1.69,5],[1,1.68,5.67],[2,1.3,5.83]],"ltp":1.68,"tv":99.47,"id":35736920}]}]}
{"op":"mcm","clk":"11985998680","pt":1724915332907,"mc":[{"id":"1.232283786","rc":[{"batb":[[0,1.68,5.67],[1,1.3,5.83],[2,1.2,1000]],"ltp":1.68,"tv":99.47,"id":35736920}]}]}
{"op":"mcm","clk":"11985998870","pt":1724915336497,"mc":[{"id":"1.232283786","rc":[{"batb":[[0,1.69,5],[1,1.68,5.67],[2,1.3,5.83]],"ltp":1.68,"tv":99.47,"id":35736920}]}]}
{"op":"mcm","clk":"11985998991","pt":1724915339925,"mc":[{"id":"1.232283786","rc":[{"batb":[[0,1.68,5.67],[1,1.3,5.83],[2,1.2,1000]],"ltp":1.68,"tv":99.47,"id":35736920}]}]}
{"op":"mcm","clk":"11985999115","pt":1724915343586,"mc":[{"id":"1.232283786","rc":[{"batb":[[0,1.69,5],[1,1.68,5.67],[2,1.3,5.83]],"ltp":1.68,"tv":99.47,"id":35736920}]}]}
{"op":"mcm","clk":"11985999224","pt":1724915347122,"mc":[{"id":"1.232283786","rc":[{"batb":[[0,1.68,5.67],[1,1.3,5.83],[2,1.2,1000]],"ltp":1.68,"tv":99.47,"id":35736920}]}]}
{"op":"mcm","clk":"11985999314","pt":1724915349630,"mc":[{"id":"1.232283786","rc":[{"batb":[[0,1.69,5],[1,1.68,5.67],[2,1.3,5.83]],"ltp":1.68,"tv":99.47,"id":35736920}]}]}
{"op":"mcm","clk":"11985999426","pt":1724915353007,"mc":[{"id":"1.232283786","rc":[{"batb":[[0,1.68,5.67],[1,1.3,5.83],[2,1.2,1000]],"ltp":1.68,"tv":99.47,"id":35736920}]}]}
{"op":"mcm","clk":"11985999505","pt":1724915356704,"mc":[{"id":"1.232283786","rc":[{"batb":[[0,1.69,5],[1,1.68,5.67],[2,1.3,5.83]],"ltp":1.68,"tv":99.47,"id":35736920}]}]}
{"op":"mcm","clk":"11985999580","pt":1724915360140,"mc":[{"id":"1.232283786","rc":[{"batb":[[0,1.68,5.67],[1,1.3,5.83],[2,1.2,1000]],"ltp":1.68,"tv":99.47,"id":35736920}]}]}
{"op":"mcm","clk":"11985999673","pt":1724915362527,"mc":[{"id":"1.232283786","rc":[{"batb":[[0,1.69,5],[1,1.68,5.67],[2,1.3,5.83]],"ltp":1.68,"tv":99.47,"id":35736920}]}]}
{"op":"mcm","clk":"11985999806","pt":1724915366018,"mc":[{"id":"1.232283786","rc":[{"batb":[[0,1.68,5.67],[1,1.3,5.83],[2,1.2,1000]],"ltp":1.68,"tv":99.47,"id":35736920}]}]}
{"op":"mcm","clk":"11985999883","pt":1724915369241,"mc":[{"id":"1.232283786","rc":[{"batb":[[0,1.69,5],[1,1.68,5.67],[2,1.3,5.83]],"ltp":1.68,"tv":99.47,"id":35736920}]}]}
{"op":"mcm","clk":"11985999958","pt":1724915372621,"mc":[{"id":"1.232283786","rc":[{"batb":[[0,1.68,5.67],[1,1.3,5.83],[2,1.2,1000]],"ltp":1.68,"tv":99.47,"id":35736920}]}]}
{"op":"mcm","clk":"11986000077","pt":1724915376251,"mc":[{"id":"1.232283786","rc":[{"batb":[[0,1.69,5],[1,1.68,5.67],[2,1.3,5.83]],"ltp":1.68,"tv":99.47,"id":35736920}]}]}
{"op":"mcm","clk":"11986000210","pt":1724915379580,"mc":[{"id":"1.232283786","rc":[{"batb":[[0,1.68,5.67],[1,1.3,5.83],[2,1.2,1000]],"ltp":1.68,"tv":99.47,"id":35736920}]}]}
{"op":"mcm","clk":"11986000333","pt":1724915382569,"mc":[{"id":"1.232283786","rc":[{"batb":[[0,1.69,5],[1,1.68,5.67],[2,1.3,5.83]],"ltp":1.68,"tv":99.47,"id":35736920}]}]}
{"op":"mcm","clk":"11986000439","pt":1724915385844,"mc":[{"id":"1.232283786","rc":[{"batb":[[0,1.68,5.67],[1,1.3,5.83],[2,1.2,1000]],"ltp":1.68,"tv":99.47,"id":35736920}]}]}
{"op":"mcm","clk":"11986000499","pt":1724915388042,"mc":[{"id":"1.232283786","rc":[{"batb":[[0,1.69,5],[1,1.68,5.67],[2,1.3,5.83]],"ltp":1.68,"tv":99.47,"id":35736920}]}]}
{"op":"mcm","clk":"11986000607","pt":1724915391467,"mc":[{"id":"1.232283786","rc":[{"batb":[[0,1.68,5.67],[1,1.3,5.83],[2,1.2,1000]],"ltp":1.68,"tv":99.47,"id":35736920}]}]}
{"op":"mcm","clk":"11986000748","pt":1724915396173,"mc":[{"id":"1.232283786","rc":[{"batb":[[0,1.69,5],[1,1.68,5.67],[2,1.3,5.83]],"ltp":1.68,"tv":99.47,"id":35736920}]}]}
{"op":"mcm","clk":"11986000860","pt":1724915399566,"mc":[{"id":"1.232283786","rc":[{"batb":[[0,1.68,5.67],[1,1.3,5.83],[2,1.2,1000]],"ltp":1.68,"tv":99.47,"id":35736920}]}]}
{"op":"mcm","clk":"11986001016","pt":1724915403233,"mc":[{"id":"1.232283786","rc":[{"batb":[[0,1.69,5],[1,1.68,5.67],[2,1.3,5.83]],"ltp":1.68,"tv":99.47,"id":35736920}]}]}
{"op":"mcm","clk":"11986001155","pt":1724915406660,"mc":[{"id":"1.232283786","rc":[{"batb":[[0,1.68,5.67],[1,1.3,5.83],[2,1.2,1000]],"ltp":1.68,"tv":99.47,"id":35736920}]}]}
{"op":"mcm","clk":"11986001256","pt":1724915409633,"mc":[{"id":"1.232283786","rc":[{"batb":[[0,1.69,5],[1,1.68,5.67],[2,1.3,5.83]],"ltp":1.68,"tv":99.47,"id":35736920}]}]}
{"op":"mcm","clk":"11986001365","pt":1724915413155,"mc":[{"id":"1.232283786","rc":[{"batb":[[0,1.68,5.67],[1,1.3,5.83],[2,1.2,1000]],"ltp":1.68,"tv":99.47,"id":35736920}]}]}
{"op":"mcm","clk":"11986001474","pt":1724915415772,"mc":[{"id":"1.232283786","rc":[{"batb":[[0,1.69,5],[1,1.68,5.67],[2,1.3,5.83]],"ltp":1.68,"tv":99.47,"id":35736920}]}]}
{"op":"mcm","clk":"11986001628","pt":1724915419092,"mc":[{"id":"1.232283786","rc":[{"batb":[[0,1.68,5.67],[1,1.3,5.83],[2,1.2,1000]],"ltp":1.68,"tv":99.47,"id":35736920}]}]}
{"op":"mcm","clk":"11986001864","pt":1724915426294,"mc":[{"id":"1.232283786","rc":[{"batb":[[0,1.69,5],[1,1.68,5.67],[2,1.3,5.83]],"ltp":1.68,"tv":99.47,"id":35736920}]}]}
{"op":"mcm","clk":"11986001952","pt":1724915429564,"mc":[{"id":"1.232283786","rc":[{"batb":[[0,1.68,5.67],[1,1.3,5.83],[2,1.2,1000]],"ltp":1.68,"tv":99.47,"id":35736920}]}]}
{"op":"mcm","clk":"11986002072","pt":1724915432171,"mc":[{"id":"1.232283786","rc":[{"batb":[[0,1.69,5],[1,1.68,5.67],[2,1.3,5.83]],"ltp":1.68,"tv":99.47,"id":35736920}]}]}
{"op":"mcm","clk":"11986002196","pt":1724915435594,"mc":[{"id":"1.232283786","rc":[{"batb":[[0,1.68,5.67],[1,1.3,5.83],[2,1.2,1000]],"ltp":1.68,"tv":99.47,"id":35736920}]}]}
{"op":"mcm","clk":"11986002344","pt":1724915439896,"mc":[{"id":"1.232283786","rc":[{"batb":[[0,1.69,5],[1,1.68,5.67],[2,1.3,5.83]],"ltp":1.68,"tv":99.47,"id":35736920}]}]}
{"op":"mcm","clk":"11986002421","pt":1724915443414,"mc":[{"id":"1.232283786","rc":[{"batb":[[0,1.68,5.67],[1,1.3,5.83],[2,1.2,1000]],"ltp":1.68,"tv":99.47,"id":35736920}]}]}
{"op":"mcm","clk":"11986002487","pt":1724915445821,"mc":[{"id":"1.232283786","rc":[{"batb":[[0,1.69,5],[1,1.68,5.67],[2,1.3,5.83]],"ltp":1.68,"tv":99.47,"id":35736920}]}]}
{"op":"mcm","clk":"11986002589","pt":1724915449221,"mc":[{"id":"1.232283786","rc":[{"batb":[[0,1.68,5.67],[1,1.3,5.83],[2,1.2,1000]],"ltp":1.68,"tv":99.47,"id":35736920}]}]}
{"op":"mcm","clk":"11986002664","pt":1724915451721,"mc":[{"id":"1.232283786","rc":[{"batb":[[0,1.69,5],[1,1.68,5.67],[2,1.3,5.83]],"ltp":1.68,"tv":99.47,"id":35736920}]}]}
{"op":"mcm","clk":"11986002780","pt":1724915455025,"mc":[{"id":"1.232283786","rc":[{"batb":[[0,1.68,5.67],[1,1.3,5.83],[2,1.2,1000]],"ltp":1.68,"tv":99.47,"id":35736920}]}]}
{"op":"mcm","clk":"11986002854","pt":1724915457237,"mc":[{"id":"1.232283786","rc":[{"batb":[[0,1.69,5],[1,1.68,5.67],[2,1.3,5.83]],"ltp":1.68,"tv":99.47,"id":35736920}]}]}
{"op":"mcm","clk":"11986002988","pt":1724915460725,"mc":[{"id":"1.232283786","rc":[{"batb":[[0,1.68,5.67],[1,1.3,5.83],[2,1.2,1000]],"ltp":1.68,"tv":99.47,"id":35736920}]}]}
{"op":"mcm","clk":"11986003082","pt":1724915463343,"mc":[{"id":"1.232283786","rc":[{"batb":[[0,1.69,5],[1,1.68,5.67],[2,1.3,5.83]],"ltp":1.68,"tv":99.47,"id":35736920}]}]}
{"op":"mcm","clk":"11986003188","pt":1724915467046,"mc":[{"id":"1.232283786","rc":[{"batb":[[0,1.68,5.67],[1,1.3,5.83],[2,1.2,1000]],"ltp":1.68,"tv":99.47,"id":35736920},{"batl":[[0,5.9,10.09]],"ltp":0.0,"tv":0.0,"id":11445383}]}]}
{"op":"mcm","clk":"11986003259","pt":1724915469142,"mc":[{"id":"1.232283786","rc":[{"batb":[[0,1.69,5],[1,1.68,5.67],[2,1.3,5.83]],"ltp":1.68,"tv":99.47,"id":35736920}]}]}
{"op":"mcm","clk":"11986003377","pt":1724915472424,"mc":[{"id":"1.232283786","rc":[{"batb":[[0,1.68,5.67],[1,1.3,5.83],[2,1.2,1000]],"ltp":1.68,"tv":99.47,"id":35736920}]}]}
{"op":"mcm","clk":"11986003454","pt":1724915474836,"mc":[{"id":"1.232283786","rc":[{"batb":[[0,1.69,5],[1,1.68,5.67],[2,1.3,5.83]],"ltp":1.68,"tv":99.47,"id":35736920}]}]}
{"op":"mcm","clk":"11986003588","pt":1724915478164,"mc":[{"id":"1.232283786","rc":[{"batb":[[0,1.68,5.67],[1,1.3,5.83],[2,1.2,1000]],"ltp":1.68,"tv":99.47,"id":35736920}]}]}
{"op":"mcm","clk":"11986003679","pt":1724915480663,"mc":[{"id":"1.232283786","rc":[{"batb":[[0,1.69,5],[1,1.68,5.67],[2,1.3,5.83]],"ltp":1.68,"tv":99.47,"id":35736920}]}]}
{"op":"mcm","clk":"11986003813","pt":1724915484152,"mc":[{"id":"1.232283786","rc":[{"batb":[[0,1.68,5.67],[1,1.3,5.83],[2,1.2,1000]],"ltp":1.68,"tv":99.47,"id":35736920}]}]}
{"op":"mcm","clk":"11986004083","pt":1724915492187,"mc":[{"id":"1.232283786","rc":[{"batb":[[0,1.69,5],[1,1.68,5.67],[2,1.3,5.83]],"ltp":1.68,"tv":99.47,"id":35736920}]}]}
{"op":"mcm","clk":"11986004164","pt":1724915495365,"mc":[{"id":"1.232283786","rc":[{"batb":[[0,1.68,5.67],[1,1.3,5.83],[2,1.2,1000]],"ltp":1.68,"tv":99.47,"id":35736920}]}]}
{"op":"mcm","clk":"11986004266","pt":1724915497972,"mc":[{"id":"1.232283786","rc":[{"batb":[[0,1.69,5],[1,1.68,5.67],[2,1.3,5.83]],"ltp":1.68,"tv":99.47,"id":35736920}]}]}
{"op":"mcm","clk":"11986004366","pt":1724915501197,"mc":[{"id":"1.232283786","rc":[{"batb":[[0,1.68,5.67],[1,1.3,5.83],[2,1.2,1000]],"ltp":1.68,"tv":99.47,"id":35736920}]}]}
{"op":"mcm","clk":"11986004468","pt":1724915503777,"mc":[{"id":"1.232283786","rc":[{"batb":[[0,1.69,5],[1,1.68,5.67],[2,1.3,5.83]],"ltp":1.68,"tv":99.47,"id":35736920}]}]}
{"op":"mcm","clk":"11986004583","pt":1724915507203,"mc":[{"id":"1.232283786","rc":[{"batb":[[0,1.68,5.67],[1,1.3,5.83],[2,1.2,1000]],"ltp":1.68,"tv":99.47,"id":35736920}]}]}
{"op":"mcm","clk":"11986004649","pt":1724915509471,"mc":[{"id":"1.232283786","rc":[{"batb":[[0,1.69,5],[1,1.68,5.67],[2,1.3,5.83]],"ltp":1.68,"tv":99.47,"id":35736920}]}]}
{"op":"mcm","clk":"11986004758","pt":1724915512996,"mc":[{"id":"1.232283786","rc":[{"batb":[[0,1.68,5.67],[1,1.3,5.83],[2,1.2,1000]],"ltp":1.68,"tv":99.47,"id":35736920}]}]}
{"op":"mcm","clk":"11986004864","pt":1724915516180,"mc":[{"id":"1.232283786","rc":[{"batb":[[0,1.69,5],[1,1.68,5.67],[2,1.3,5.83]],"ltp":1.68,"tv":99.47,"id":35736920}]}]}
{"op":"mcm","clk":"11986004961","pt":1724915519616,"mc":[{"id":"1.232283786","rc":[{"batb":[[0,1.68,5.67],[1,1.3,5.83],[2,1.2,1000]],"ltp":1.68,"tv":99.47,"id":35736920}]}]}
{"op":"mcm","clk":"11986005027","pt":1724915521985,"mc":[{"id":"1.232283786","rc":[{"batb":[[0,1.69,5],[1,1.68,5.67],[2,1.3,5.83]],"ltp":1.68,"tv":99.47,"id":35736920}]}]}
{"op":"mcm","clk":"11986005138","pt":1724915525429,"mc":[{"id":"1.232283786","rc":[{"batb":[[0,1.68,5.67],[1,1.3,5.83],[2,1.2,1000]],"ltp":1.68,"tv":99.47,"id":35736920}]}]}
{"op":"mcm","clk":"11986005220","pt":1724915527588,"mc":[{"id":"1.232283786","rc":[{"batb":[[0,1.69,5],[1,1.68,5.67],[2,1.3,5.83]],"ltp":1.68,"tv":99.47,"id":35736920}]}]}
{"op":"mcm","clk":"11986005349","pt":1724915530921,"mc":[{"id":"1.232283786","rc":[{"batb":[[0,1.68,5.67],[1,1.3,5.83],[2,1.2,1000]],"ltp":1.68,"tv":99.47,"id":35736920}]}]}
{"op":"mcm","clk":"11986005469","pt":1724915535113,"mc":[{"id":"1.232283786","rc":[{"batb":[[0,1.69,5],[1,1.68,5.67],[2,1.3,5.83]],"ltp":1.68,"tv":99.47,"id":35736920}]}]}
{"op":"mcm","clk":"11986005597","pt":1724915538440,"mc":[{"id":"1.232283786","rc":[{"batb":[[0,1.68,5.67],[1,1.3,5.83],[2,1.2,1000]],"ltp":1.68,"tv":99.47,"id":35736920}]}]}
{"op":"mcm","clk":"11986005787","pt":1724915543410,"mc":[{"id":"1.232283786","rc":[{"batb":[[0,1.69,5],[1,1.68,5.67],[2,1.3,5.83]],"ltp":1.68,"tv":99.47,"id":35736920}]}]}
{"op":"mcm","clk":"11986005929","pt":1724915546944,"mc":[{"id":"1.232283786","rc":[{"batb":[[0,1.68,5.67],[1,1.3,5.83],[2,1.2,1000]],"ltp":1.68,"tv":99.47,"id":35736920}]}]}
{"op":"mcm","clk":"11986006081","pt":1724915551039,"mc":[{"id":"1.232283786","rc":[{"batb":[[0,1.69,5],[1,1.68,5.67],[2,1.3,5.83]],"ltp":1.68,"tv":99.47,"id":35736920}]}]}
{"op":"mcm","clk":"11986006152","pt":1724915554415,"mc":[{"id":"1.232283786","rc":[{"batb":[[0,1.68,5.67],[1,1.3,5.83],[2,1.2,1000]],"ltp":1.68,"tv":99.47,"id":35736920},{"batb":[[1,1.21,5.82],[2,1.2,1000]],"ltp":0.0,"tv":0.0,"id":11445383}]}]}
{"op":"mcm","clk":"11986006208","pt":1724915556553,"mc":[{"id":"1.232283786","rc":[{"batb":[[0,1.69,5],[1,1.68,5.67],[2,1.3,5.83]],"ltp":1.68,"tv":99.47,"id":35736920}]}]}
{"op":"mcm","clk":"11986006324","pt":1724915559828,"mc":[{"id":"1.232283786","rc":[{"batb":[[0,1.68,5.67],[1,1.3,5.83],[2,1.2,1000]],"ltp":1.68,"tv":99.47,"id":35736920}]}]}
{"op":"mcm","clk":"11986006405","pt":1724915562535,"mc":[{"id":"1.232283786","rc":[{"batb":[[0,1.69,5],[1,1.68,5.67],[2,1.3,5.83]],"ltp":1.68,"tv":99.47,"id":35736920}]}]}
{"op":"mcm","clk":"11986006547","pt":1724915565958,"mc":[{"id":"1.232283786","rc":[{"batb":[[0,1.68,5.67],[1,1.3,5.83],[2,1.2,1000]],"ltp":1.68,"tv":99.47,"id":35736920}]}]}
{"op":"mcm","clk":"11986006704","pt":1724915568941,"mc":[{"id":"1.232283786","rc":[{"batb":[[0,1.69,5],[1,1.68,5.67],[2,1.3,5.83]],"ltp":1.68,"tv":99.47,"id":35736920}]}]}
{"op":"mcm","clk":"11986006800","pt":1724915572364,"mc":[{"id":"1.232283786","rc":[{"batb":[[0,1.68,5.67],[1,1.3,5.83],[2,1.2,1000]],"ltp":1.68,"tv":99.47,"id":35736920}]}]}
{"op":"mcm","clk":"11986006881","pt":1724915575108,"mc":[{"id":"1.232283786","rc":[{"batb":[[0,1.69,5],[1,1.68,5.67],[2,1.3,5.83]],"ltp":1.68,"tv":99.47,"id":35736920}]}]}
{"op":"mcm","clk":"11986006971","pt":1724915578447,"mc":[{"id":"1.232283786","rc":[{"batb":[[0,1.68,5.67],[1,1.3,5.83],[2,1.2,1000]],"ltp":1.68,"tv":99.47,"id":35736920}]}]}
{"op":"mcm","clk":"11986007045","pt":1724915580949,"mc":[{"id":"1.232283786","rc":[{"batb":[[0,1.69,5],[1,1.68,5.67],[2,1.3,5.83]],"ltp":1.68,"tv":99.47,"id":35736920}]}]}
{"op":"mcm","clk":"11986007146","pt":1724915584378,"mc":[{"id":"1.232283786","rc":[{"batb":[[0,1.68,5.67],[1,1.3,5.83],[2,1.2,1000]],"ltp":1.68,"tv":99.47,"id":35736920}]}]}
{"op":"mcm","clk":"11986007403","pt":1724915591757,"mc":[{"id":"1.232283786","rc":[{"batb":[[0,1.69,5],[1,1.68,5.67],[2,1.3,5.83]],"ltp":1.68,"tv":99.47,"id":35736920}]}]}
{"op":"mcm","clk":"11986007512","pt":1724915595047,"mc":[{"id":"1.232283786","rc":[{"batb":[[0,1.68,5.67],[1,1.3,5.83],[2,1.2,1000]],"ltp":1.68,"tv":99.47,"id":35736920}]}]}
{"op":"mcm","clk":"11986007660","pt":1724915598886,"mc":[{"id":"1.232283786","rc":[{"batb":[[0,1.69,5],[1,1.68,5.67],[2,1.3,5.83]],"ltp":1.68,"tv":99.47,"id":35736920}]}]}
{"op":"mcm","clk":"11986007766","pt":1724915602154,"mc":[{"id":"1.232283786","rc":[{"batb":[[0,1.68,5.67],[1,1.3,5.83],[2,1.2,1000]],"ltp":1.68,"tv":99.47,"id":35736920}]}]}
{"op":"mcm","clk":"11986007879","pt":1724915605895,"mc":[{"id":"1.232283786","rc":[{"batb":[[0,1.69,5],[1,1.68,5.67],[2,1.3,5.83]],"ltp":1.68,"tv":99.47,"id":35736920}]}]}
{"op":"mcm","clk":"11986007972","pt":1724915609164,"mc":[{"id":"1.232283786","rc":[{"batb":[[0,1.68,5.67],[1,1.3,5.83],[2,1.2,1000]],"ltp":1.68,"tv":99.47,"id":35736920}]}]}
{"op":"mcm","clk":"11986008080","pt":1724915611873,"mc":[{"id":"1.232283786","rc":[{"batb":[[0,1.69,5],[1,1.68,5.67],[2,1.3,5.83]],"ltp":1.68,"tv":99.47,"id":35736920}]}]}
{"op":"mcm","clk":"11986008207","pt":1724915615275,"mc":[{"id":"1.232283786","rc":[{"batb":[[0,1.68,5.67],[1,1.3,5.83],[2,1.2,1000]],"ltp":1.68,"tv":99.47,"id":35736920}]}]}
{"op":"mcm","clk":"11986008282","pt":1724915617798,"mc":[{"id":"1.232283786","rc":[{"batb":[[0,1.69,5],[1,1.68,5.67],[2,1.3,5.83]],"ltp":1.68,"tv":99.47,"id":35736920}]}]}
{"op":"mcm","clk":"11986008378","pt":1724915621181,"mc":[{"id":"1.232283786","rc":[{"batb":[[0,1.68,5.67],[1,1.3,5.83],[2,1.2,1000]],"ltp":1.68,"tv":99.47,"id":35736920}]}]}
{"op":"mcm","clk":"11986008579","pt":1724915627491,"mc":[{"id":"1.232283786","rc":[{"batb":[[0,1.69,5],[1,1.68,5.67],[2,1.3,5.83]],"ltp":1.68,"tv":99.47,"id":35736920}]}]}
{"op":"mcm","clk":"11986008707","pt":1724915630919,"mc":[{"id":"1.232283786","rc":[{"batb":[[0,1.68,5.67],[1,1.3,5.83],[2,1.2,1000]],"ltp":1.68,"tv":99.47,"id":35736920}]}]}
{"op":"mcm","clk":"11986008838","pt":1724915634718,"mc":[{"id":"1.232283786","rc":[{"batb":[[0,1.69,5],[1,1.68,5.67],[2,1.3,5.83]],"ltp":1.68,"tv":99.47,"id":35736920}]}]}
{"op":"mcm","clk":"11986008946","pt":1724915638002,"mc":[{"id":"1.232283786","rc":[{"batb":[[0,1.68,5.67],[1,1.3,5.83],[2,1.2,1000]],"ltp":1.68,"tv":99.47,"id":35736920}]}]}
{"op":"mcm","clk":"11986009073","pt":1724915641337,"mc":[{"id":"1.232283786","rc":[{"batb":[[0,1.69,5],[1,1.68,5.67],[2,1.3,5.83]],"ltp":1.68,"tv":99.47,"id":35736920}]}]}
{"op":"mcm","clk":"11986009227","pt":1724915645036,"mc":[{"id":"1.232283786","rc":[{"batb":[[0,1.68,5.67],[1,1.3,5.83],[2,1.2,1000]],"ltp":1.68,"tv":99.47,"id":35736920}]}]}
{"op":"mcm","clk":"11986009288","pt":1724915646934,"mc":[{"id":"1.232283786","rc":[{"batl":[[0,5.9,10.09]],"ltp":0.0,"tv":0.0,"id":11445383}]}]}
{"op":"mcm","clk":"11986009317","pt":1724915648112,"mc":[{"id":"1.232283786","rc":[{"batb":[[0,1.69,5],[1,1.68,5.67],[2,1.3,5.83]],"ltp":1.68,"tv":99.47,"id":35736920}]}]}
{"op":"mcm","clk":"11986009413","pt":1724915651439,"mc":[{"id":"1.232283786","rc":[{"batb":[[0,1.68,5.67],[1,1.3,5.83],[2,1.2,1000]],"ltp":1.68,"tv":99.47,"id":35736920}]}]}
{"op":"mcm","clk":"11986009463","pt":1724915654024,"mc":[{"id":"1.232283786","rc":[{"batb":[[0,1.69,5],[1,1.68,5.67],[2,1.3,5.83]],"ltp":1.68,"tv":99.47,"id":35736920}]}]}
{"op":"mcm","clk":"11986009573","pt":1724915657454,"mc":[{"id":"1.232283786","rc":[{"batb":[[0,1.68,5.67],[1,1.3,5.83],[2,1.2,1000]],"ltp":1.68,"tv":99.47,"id":35736920}]}]}
{"op":"mcm","clk":"11986009651","pt":1724915660014,"mc":[{"id":"1.232283786","rc":[{"batb":[[0,1.69,5],[1,1.68,5.67],[2,1.3,5.83]],"ltp":1.68,"tv":99.47,"id":35736920}]}]}
{"op":"mcm","clk":"11986009729","pt":1724915663446,"mc":[{"id":"1.232283786","rc":[{"batb":[[0,1.68,5.67],[1,1.3,5.83],[2,1.2,1000]],"ltp":1.68,"tv":99.47,"id":35736920}]}]}
{"op":"mcm","clk":"11986009833","pt":1724915665961,"mc":[{"id":"1.232283786","rc":[{"batb":[[0,1.69,5],[1,1.68,5.67],[2,1.3,5.83]],"ltp":1.68,"tv":99.47,"id":35736920}]}]}
{"op":"mcm","clk":"11986009930","pt":1724915669542,"mc":[{"id":"1.232283786","rc":[{"batb":[[0,1.68,5.67],[1,1.3,5.83],[2,1.2,1000]],"ltp":1.68,"tv":99.47,"id":35736920}]}]}
{"op":"mcm","clk":"11986010039","pt":1724915672762,"mc":[{"id":"1.232283786","rc":[{"batb":[[0,1.69,5],[1,1.68,5.67],[2,1.3,5.83]],"ltp":1.68,"tv":99.47,"id":35736920}]}]}
{"op":"mcm","clk":"11986010145","pt":1724915675943,"mc":[{"id":"1.232283786","rc":[{"batb":[[0,1.68,5.67],[1,1.3,5.83],[2,1.2,1000]],"ltp":1.68,"tv":99.47,"id":35736920}]}]}
{"op":"mcm","clk":"11986010223","pt":1724915678256,"mc":[{"id":"1.232283786","rc":[{"batb":[[0,1.69,5],[1,1.68,5.67],[2,1.3,5.83]],"ltp":1.68,"tv":99.47,"id":35736920}]}]}
{"op":"mcm","clk":"11986010338","pt":1724915681652,"mc":[{"id":"1.232283786","rc":[{"batb":[[0,1.68,5.67],[1,1.3,5.83],[2,1.2,1000]],"ltp":1.68,"tv":99.47,"id":35736920}]}]}
{"op":"mcm","clk":"11986010430","pt":1724915684162,"mc":[{"id":"1.232283786","rc":[{"batb":[[0,1.69,5],[1,1.68,5.67],[2,1.3,5.83]],"ltp":1.68,"tv":99.47,"id":35736920}]}]}
{"op":"mcm","clk":"11986010538","pt":1724915687459,"mc":[{"id":"1.232283786","rc":[{"batb":[[0,1.68,5.67],[1,1.3,5.83],[2,1.2,1000]],"ltp":1.68,"tv":99.47,"id":35736920}]}]}
{"op":"mcm","clk":"11986010620","pt":1724915690394,"mc":[{"id":"1.232283786","rc":[{"batb":[[0,1.69,5],[1,1.68,5.67],[2,1.3,5.83]],"ltp":1.68,"tv":99.47,"id":35736920}]}]}
{"op":"mcm","clk":"11986010744","pt":1724915693593,"mc":[{"id":"1.232283786","rc":[{"batb":[[0,1.68,5.67],[1,1.3,5.83],[2,1.2,1000]],"ltp":1.68,"tv":99.47,"id":35736920}]}]}
{"op":"mcm","clk":"11986010849","pt":1724915696073,"mc":[{"id":"1.232283786","rc":[{"batb":[[0,1.69,5],[1,1.68,5.67],[2,1.3,5.83]],"ltp":1.68,"tv":99.47,"id":35736920}]}]}
{"op":"mcm","clk":"11986010973","pt":1724915699572,"mc":[{"id":"1.232283786","rc":[{"batb":[[0,1.68,5.67],[1,1.3,5.83],[2,1.2,1000]],"ltp":1.68,"tv":99.47,"id":35736920}]}]}
{"op":"mcm","clk":"11986011065","pt":1724915702065,"mc":[{"id":"1.232283786","rc":[{"batb":[[0,1.69,5],[1,1.68,5.67],[2,1.3,5.83]],"ltp":1.68,"tv":99.47,"id":35736920}]}]}
{"op":"mcm","clk":"11986011215","pt":1724915705410,"mc":[{"id":"1.232283786","rc":[{"batb":[[0,1.68,5.67],[1,1.3,5.83],[2,1.2,1000]],"ltp":1.68,"tv":99.47,"id":35736920}]}]}
{"op":"mcm","clk":"11986011305","pt":1724915707981,"mc":[{"id":"1.232283786","rc":[{"batb":[[0,1.69,5],[1,1.68,5.67],[2,1.3,5.83]],"ltp":1.68,"tv":99.47,"id":35736920}]}]}
{"op":"mcm","clk":"11986011429","pt":1724915711425,"mc":[{"id":"1.232283786","rc":[{"batb":[[0,1.68,5.67],[1,1.3,5.83],[2,1.2,1000]],"ltp":1.68,"tv":99.47,"id":35736920}]}]}
{"op":"mcm","clk":"11986011596","pt":1724915715117,"mc":[{"id":"1.232283786","rc":[{"batb":[[0,1.69,5],[1,1.68,5.67],[2,1.3,5.83]],"ltp":1.68,"tv":99.47,"id":35736920}]}]}
{"op":"mcm","clk":"11986011722","pt":1724915718496,"mc":[{"id":"1.232283786","rc":[{"batb":[[0,1.68,5.67],[1,1.3,5.83],[2,1.2,1000]],"ltp":1.68,"tv":99.47,"id":35736920}]}]}
{"op":"mcm","clk":"11986011867","pt":1724915723523,"mc":[{"id":"1.232283786","rc":[{"batb":[[0,1.69,5],[1,1.68,5.67],[2,1.3,5.83]],"ltp":1.68,"tv":99.47,"id":35736920}]}]}
{"op":"mcm","clk":"11986012014","pt":1724915726915,"mc":[{"id":"1.232283786","rc":[{"batb":[[0,1.68,5.67],[1,1.3,5.83],[2,1.2,1000]],"ltp":1.68,"tv":99.47,"id":35736920}]}]}
{"op":"mcm","clk":"11986012102","pt":1724915729429,"mc":[{"id":"1.232283786","rc":[{"batb":[[0,1.69,5],[1,1.68,5.67],[2,1.3,5.83]],"ltp":1.68,"tv":99.47,"id":35736920}]}]}
{"op":"mcm","clk":"11986012230","pt":1724915732926,"mc":[{"id":"1.232283786","rc":[{"batb":[[0,1.68,5.67],[1,1.3,5.83],[2,1.2,1000]],"ltp":1.68,"tv":99.47,"id":35736920}]}]}
{"op":"mcm","clk":"11986012327","pt":1724915735333,"mc":[{"id":"1.232283786","rc":[{"batb":[[0,1.69,5],[1,1.68,5.67],[2,1.3,5.83]],"ltp":1.68,"tv":99.47,"id":35736920}]}]}
{"op":"mcm","clk":"11986012452","pt":1724915738726,"mc":[{"id":"1.232283786","rc":[{"batb":[[0,1.68,5.67],[1,1.3,5.83],[2,1.2,1000]],"ltp":1.68,"tv":99.47,"id":35736920}]}]}
{"op":"mcm","clk":"11986012638","pt":1724915743253,"mc":[{"id":"1.232283786","rc":[{"batb":[[0,1.69,5],[1,1.68,5.67],[2,1.3,5.83]],"ltp":1.68,"tv":99.47,"id":35736920}]}]}
{"op":"mcm","clk":"11986012749","pt":1724915746565,"mc":[{"id":"1.232283786","rc":[{"batb":[[0,1.68,5.67],[1,1.3,5.83],[2,1.2,1000]],"ltp":1.68,"tv":99.47,"id":35736920}]}]}
{"op":"mcm","clk":"11986012940","pt":1724915752186,"mc":[{"id":"1.232283786","rc":[{"batb":[[0,1.69,5],[1,1.68,5.67],[2,1.3,5.83]],"ltp":1.68,"tv":99.47,"id":35736920}]}]}
{"op":"mcm","clk":"11986013065","pt":1724915755584,"mc":[{"id":"1.232283786","rc":[{"batb":[[0,1.68,5.67],[1,1.3,5.83],[2,1.2,1000]],"ltp":1.68,"tv":99.47,"id":35736920}]}]}
{"op":"mcm","clk":"11986013197","pt":1724915759394,"mc":[{"id":"1.232283786","rc":[{"batb":[[0,1.69,5],[1,1.68,5.67],[2,1.3,5.83]],"ltp":1.68,"tv":99.47,"id":35736920}]}]}
{"op":"mcm","clk":"11986013323","pt":1724915762898,"mc":[{"id":"1.232283786","rc":[{"batb":[[0,1.68,5.67],[1,1.3,5.83],[2,1.2,1000]],"ltp":1.68,"tv":99.47,"id":35736920}]}]}
{"op":"mcm","clk":"11986013402","pt":1724915765482,"mc":[{"id":"1.232283786","rc":[{"batb":[[0,1.69,5],[1,1.68,5.67],[2,1.3,5.83]],"ltp":1.68,"tv":99.47,"id":35736920}]}]}
{"op":"mcm","clk":"11986013517","pt":1724915768876,"mc":[{"id":"1.232283786","rc":[{"batb":[[0,1.68,5.67],[1,1.3,5.83],[2,1.2,1000]],"ltp":1.68,"tv":99.47,"id":35736920}]}]}
{"op":"mcm","clk":"11986013659","pt":1724915772386,"mc":[{"id":"1.232283786","rc":[{"batb":[[0,1.69,5],[1,1.68,5.67],[2,1.3,5.83]],"ltp":1.68,"tv":99.47,"id":35736920}]}]}
{"op":"mcm","clk":"11986013806","pt":1724915775681,"mc":[{"id":"1.232283786","rc":[{"batb":[[0,1.68,5.67],[1,1.3,5.83],[2,1.2,1000]],"ltp":1.68,"tv":99.47,"id":35736920}]}]}
{"op":"mcm","clk":"11986013934","pt":1724915778286,"mc":[{"id":"1.232283786","rc":[{"batb":[[0,1.69,5],[1,1.68,5.67],[2,1.3,5.83]],"ltp":1.68,"tv":99.47,"id":35736920}]}]}
{"op":"mcm","clk":"11986014081","pt":1724915781606,"mc":[{"id":"1.232283786","rc":[{"batb":[[0,1.68,5.67],[1,1.3,5.83],[2,1.2,1000]],"ltp":1.68,"tv":99.47,"id":35736920}]}]}
{"op":"mcm","clk":"11986014195","pt":1724915783930,"mc":[{"id":"1.232283786","rc":[{"batb":[[0,1.69,5],[1,1.68,5.67],[2,1.3,5.83]],"ltp":1.68,"tv":99.47,"id":35736920}]}]}
{"op":"mcm","clk":"11986014346","pt":1724915787216,"mc":[{"id":"1.232283786","rc":[{"batb":[[0,1.68,5.67],[1,1.3,5.83],[2,1.2,1000]],"ltp":1.68,"tv":99.47,"id":35736920}]}]}
{"op":"mcm","clk":"11986014442","pt":1724915789822,"mc":[{"id":"1.232283786","rc":[{"batb":[[0,1.69,5],[1,1.68,5.67],[2,1.3,5.83]],"ltp":1.68,"tv":99.47,"id":35736920}]}]}
{"op":"mcm","clk":"11986014564","pt":1724915793148,"mc":[{"id":"1.232283786","rc":[{"batb":[[0,1.68,5.67],[1,1.3,5.83],[2,1.2,1000]],"ltp":1.68,"tv":99.47,"id":35736920}]}]}
{"op":"mcm","clk":"11986014855","pt":1724915799762,"mc":[{"id":"1.232283786","rc":[{"batb":[[0,1.69,5],[1,1.68,5.67],[2,1.3,5.83]],"ltp":1.68,"tv":99.47,"id":35736920}]}]}
{"op":"mcm","clk":"11986014985","pt":1724915803235,"mc":[{"id":"1.232283786","rc":[{"batb":[[0,1.68,5.67],[1,1.3,5.83],[2,1.2,1000]],"ltp":1.68,"tv":99.47,"id":35736920}]}]}
{"op":"mcm","clk":"11986015114","pt":1724915806727,"mc":[{"id":"1.232283786","rc":[{"batb":[[0,1.69,5],[1,1.68,5.67],[2,1.3,5.83]],"ltp":1.68,"tv":99.47,"id":35736920}]}]}
{"op":"mcm","clk":"11986015243","pt":1724915810257,"mc":[{"id":"1.232283786","rc":[{"batb":[[0,1.68,5.67],[1,1.3,5.83],[2,1.2,1000]],"ltp":1.68,"tv":99.47,"id":35736920}]}]}
{"op":"mcm","clk":"11986015354","pt":1724915813176,"mc":[{"id":"1.232283786","rc":[{"batb":[[0,1.69,5],[1,1.68,5.67],[2,1.3,5.83]],"ltp":1.68,"tv":99.47,"id":35736920}]}]}
{"op":"mcm","clk":"11986015473","pt":1724915816567,"mc":[{"id":"1.232283786","rc":[{"batb":[[0,1.68,5.67],[1,1.3,5.83],[2,1.2,1000]],"ltp":1.68,"tv":99.47,"id":35736920}]}]}
{"op":"mcm","clk":"11986015575","pt":1724915819076,"mc":[{"id":"1.232283786","rc":[{"batb":[[0,1.69,5],[1,1.68,5.67],[2,1.3,5.83]],"ltp":1.68,"tv":99.47,"id":35736920}]}]}
{"op":"mcm","clk":"11986015751","pt":1724915822872,"mc":[{"id":"1.232283786","rc":[{"batb":[[0,1.68,5.67],[1,1.3,5.83],[2,1.2,1000]],"ltp":1.68,"tv":99.47,"id":35736920},{"batl":[[0,5.9,10.09]],"ltp":0.0,"tv":0.0,"id":11445383}]}]}
{"op":"mcm","clk":"11986015854","pt":1724915825185,"mc":[{"id":"1.232283786","rc":[{"batb":[[0,1.69,5],[1,1.68,5.67],[2,1.3,5.83]],"ltp":1.68,"tv":99.47,"id":35736920}]}]}
{"op":"mcm","clk":"11986015991","pt":1724915828768,"mc":[{"id":"1.232283786","rc":[{"batb":[[0,1.68,5.67],[1,1.3,5.83],[2,1.2,1000]],"ltp":1.68,"tv":99.47,"id":35736920}]}]}
{"op":"mcm","clk":"11986016059","pt":1724915830972,"mc":[{"id":"1.232283786","rc":[{"batb":[[0,1.69,5],[1,1.68,5.67],[2,1.3,5.83]],"ltp":1.68,"tv":99.47,"id":35736920}]}]}
{"op":"mcm","clk":"11986016202","pt":1724915834300,"mc":[{"id":"1.232283786","rc":[{"batb":[[0,1.68,5.67],[1,1.3,5.83],[2,1.2,1000]],"ltp":1.68,"tv":99.47,"id":35736920}]}]}
{"op":"mcm","clk":"11986016315","pt":1724915837681,"mc":[{"id":"1.232283786","rc":[{"batb":[[0,1.69,5],[1,1.68,5.67],[2,1.3,5.83]],"ltp":1.68,"tv":99.47,"id":35736920}]}]}
{"op":"mcm","clk":"11986016431","pt":1724915840896,"mc":[{"id":"1.232283786","rc":[{"batb":[[0,1.68,5.67],[1,1.3,5.83],[2,1.2,1000]],"ltp":1.68,"tv":99.47,"id":35736920}]}]}
{"op":"mcm","clk":"11986016522","pt":1724915843401,"mc":[{"id":"1.232283786","rc":[{"batb":[[0,1.69,5],[1,1.68,5.67],[2,1.3,5.83]],"ltp":1.68,"tv":99.47,"id":35736920}]}]}
{"op":"mcm","clk":"11986016690","pt":1724915846694,"mc":[{"id":"1.232283786","rc":[{"batb":[[0,1.68,5.67],[1,1.3,5.83],[2,1.2,1000]],"ltp":1.68,"tv":99.47,"id":35736920}]}]}
{"op":"mcm","clk":"11986016803","pt":1724915849578,"mc":[{"id":"1.232283786","rc":[{"batb":[[0,1.69,5],[1,1.68,5.67],[2,1.3,5.83]],"ltp":1.68,"tv":99.47,"id":35736920}]}]}
{"op":"mcm","clk":"11986016907","pt":1724915852912,"mc":[{"id":"1.232283786","rc":[{"batb":[[0,1.68,5.67],[1,1.3,5.83],[2,1.2,1000]],"ltp":1.68,"tv":99.47,"id":35736920}]}]}
{"op":"mcm","clk":"11986016990","pt":1724915855408,"mc":[{"id":"1.232283786","rc":[{"batb":[[0,1.69,5],[1,1.68,5.67],[2,1.3,5.83]],"ltp":1.68,"tv":99.47,"id":35736920}]}]}
{"op":"mcm","clk":"11986017143","pt":1724915858787,"mc":[{"id":"1.232283786","rc":[{"batb":[[0,1.68,5.67],[1,1.3,5.83],[2,1.2,1000]],"ltp":1.68,"tv":99.47,"id":35736920}]}]}
{"op":"mcm","clk":"11986017631","pt":1724915869131,"mc":[{"id":"1.232283786","rc":[{"batb":[[0,1.69,5],[1,1.68,5.67],[2,1.3,5.83]],"ltp":1.68,"tv":99.47,"id":35736920}]}]}
{"op":"mcm","clk":"11986017787","pt":1724915872603,"mc":[{"id":"1.232283786","rc":[{"batb":[[0,1.68,5.67],[1,1.3,5.83],[2,1.2,1000]],"ltp":1.68,"tv":99.47,"id":35736920}]}]}
{"op":"mcm","clk":"11986017880","pt":1724915874901,"mc":[{"id":"1.232283786","rc":[{"batb":[[0,1.69,5],[1,1.68,5.67],[2,1.3,5.83]],"ltp":1.68,"tv":99.47,"id":35736920}]}]}
{"op":"mcm","clk":"11986018030","pt":1724915878229,"mc":[{"id":"1.232283786","rc":[{"batb":[[0,1.68,5.67],[1,1.3,5.83],[2,1.2,1000]],"ltp":1.68,"tv":99.47,"id":35736920}]}]}
{"op":"mcm","clk":"11986021360","pt":1724915965428,"mc":[{"id":"1.232283786","rc":[{"trd":[[1.75,3.85]],"batb":[[0,1.75,1.15],[1,1.68,5.67],[2,1.3,5.83]],"ltp":1.75,"tv":103.32,"id":35736920},{"trd":[[2.34,2.88]],"batb":[[0,1.57,148.04]],"ltp":2.34,"tv":2.88,"id":11445383}],"tv":106.2}]}
{"op":"mcm","clk":"11986021538","pt":1724915970032,"mc":[{"id":"1.232283786","rc":[{"batb":[[0,2.26,3.06],[1,1.57,148.04],[2,1.21,5.82]],"ltp":2.34,"tv":2.88,"id":11445383}]}]}
{"op":"mcm","clk":"11986023031","pt":1724916007425,"mc":[{"id":"1.232283786","rc":[{"batb":[[0,1.68,5.67],[1,1.3,5.83],[2,1.2,1000]],"ltp":1.75,"tv":103.32,"id":35736920},{"batb":[[1,1.21,5.82],[2,1.2,1000]],"ltp":2.34,"tv":2.88,"id":11445383}]}]}
{"op":"mcm","clk":"11986023073","pt":1724916008401,"mc":[{"id":"1.232283786","rc":[{"batl":[[0,5.9,10.09]],"ltp":2.34,"tv":2.88,"id":11445383}]}]}
{"op":"mcm","clk":"11986027741","pt":1724916112216,"mc":[{"id":"1.232283786","rc":[{"trd":[[1.8,3.84]],"batb":[[0,1.68,6.33]],"ltp":1.8,"tv":107.16,"id":35736920},{"trd":[[2.26,3.06]],"batb":[[0,1.52,152.94],[1,1.22,5],[2,1.21,5.82]],"ltp":2.26,"tv":5.93,"id":11445383}],"tv":113.1}]}
{"op":"mcm","clk":"11986027867","pt":1724916115354,"mc":[{"id":"1.232283786","rc":[{"batb":[[1,1.21,5.82],[2,1.2,1000]],"ltp":2.26,"tv":5.93,"id":11445383}]}]}
{"op":"mcm","clk":"11986027890","pt":1724916115665,"mc":[{"id":"1.232283786","rc":[{"batb":[[0,2.18,3.27],[1,1.52,152.94],[2,1.21,5.82]],"ltp":2.26,"tv":5.93,"id":11445383}]}]}
{"op":"mcm","clk":"11986029326","pt":1724916144999,"mc":[{"id":"1.232283786","rc":[{"batb":[[1,1.21,5.82],[2,1.2,1000]],"ltp":2.26,"tv":5.93,"id":11445383}]}]}
{"op":"mcm","clk":"11986030283","pt":1724916167022,"mc":[{"id":"1.232283786","rc":[{"batb":[[0,1.68,5.67]],"ltp":1.8,"tv":107.16,"id":35736920}]}]}
{"op":"mcm","clk":"11986068527","pt":1724917089386,"mc":[{"id":"1.232283786","rc":[{"batb":[[0,1.69,5],[1,1.68,5.67],[2,1.3,5.83]],"batl":[[0,5.9,10.07]],"ltp":1.8,"tv":107.16,"id":35736920}]}]}
{"op":"mcm","clk":"11986068686","pt":1724917092668,"mc":[{"id":"1.232283786","rc":[{"batb":[[0,1.68,5.67],[1,1.3,5.83],[2,1.2,1000]],"ltp":1.8,"tv":107.16,"id":35736920}]}]}
{"op":"mcm","clk":"11986068762","pt":1724917095071,"mc":[{"id":"1.232283786","rc":[{"batb":[[0,1.69,5],[1,1.68,5.67],[2,1.3,5.83]],"ltp":1.8,"tv":107.16,"id":35736920},{"batl":[[0,5.9,10.09]],"ltp":2.26,"tv":5.93,"id":11445383}]}]}
{"op":"mcm","clk":"11986068880","pt":1724917098597,"mc":[{"id":"1.232283786","rc":[{"batb":[[0,1.68,5.67],[1,1.3,5.83],[2,1.2,1000]],"ltp":1.8,"tv":107.16,"id":35736920}]}]}
{"op":"mcm","clk":"11986069062","pt":1724917104593,"mc":[{"id":"1.232283786","rc":[{"batb":[[0,1.69,5],[1,1.68,5.67],[2,1.3,5.83]],"ltp":1.8,"tv":107.16,"id":35736920}]}]}
{"op":"mcm","clk":"11986069161","pt":1724917107979,"mc":[{"id":"1.232283786","rc":[{"batb":[[0,1.68,5.67],[1,1.3,5.83],[2,1.2,1000]],"ltp":1.8,"tv":107.16,"id":35736920}]}]}
{"op":"mcm","clk":"11986069304","pt":1724917112691,"mc":[{"id":"1.232283786","rc":[{"batb":[[0,1.69,5],[1,1.68,5.67],[2,1.3,5.83]],"ltp":1.8,"tv":107.16,"id":35736920}]}]}
{"op":"mcm","clk":"11986069409","pt":1724917115987,"mc":[{"id":"1.232283786","rc":[{"batb":[[0,1.68,5.67],[1,1.3,5.83],[2,1.2,1000]],"ltp":1.8,"tv":107.16,"id":35736920}]}]}
{"op":"mcm","clk":"11986069550","pt":1724917119624,"mc":[{"id":"1.232283786","rc":[{"batb":[[0,1.69,5],[1,1.68,5.67],[2,1.3,5.83]],"ltp":1.8,"tv":107.16,"id":35736920}]}]}
{"op":"mcm","clk":"11986069641","pt":1724917122786,"mc":[{"id":"1.232283786","rc":[{"batb":[[0,1.68,5.67],[1,1.3,5.83],[2,1.2,1000]],"ltp":1.8,"tv":107.16,"id":35736920}]}]}
{"op":"mcm","clk":"11986069726","pt":1724917125508,"mc":[{"id":"1.232283786","rc":[{"batb":[[0,1.69,5],[1,1.68,5.67],[2,1.3,5.83]],"ltp":1.8,"tv":107.16,"id":35736920}]}]}
{"op":"mcm","clk":"11986069821","pt":1724917128935,"mc":[{"id":"1.232283786","rc":[{"batb":[[0,1.68,5.67],[1,1.3,5.83],[2,1.2,1000]],"ltp":1.8,"tv":107.16,"id":35736920}]}]}
{"op":"mcm","clk":"11986069924","pt":1724917131643,"mc":[{"id":"1.232283786","rc":[{"batb":[[0,1.69,5],[1,1.68,5.67],[2,1.3,5.83]],"ltp":1.8,"tv":107.16,"id":35736920}]}]}
{"op":"mcm","clk":"11986070079","pt":1724917135025,"mc":[{"id":"1.232283786","rc":[{"batb":[[0,1.68,5.67],[1,1.3,5.83],[2,1.2,1000]],"ltp":1.8,"tv":107.16,"id":35736920}]}]}
{"op":"mcm","clk":"11986070318","pt":1724917142821,"mc":[{"id":"1.232283786","rc":[{"batb":[[0,1.69,5],[1,1.68,5.67],[2,1.3,5.83]],"ltp":1.8,"tv":107.16,"id":35736920}]}]}
{"op":"mcm","clk":"11986070423","pt":1724917146223,"mc":[{"id":"1.232283786","rc":[{"batb":[[0,1.68,5.67],[1,1.3,5.83],[2,1.2,1000]],"ltp":1.8,"tv":107.16,"id":35736920}]}]}
{"op":"mcm","clk":"11986070585","pt":1724917150436,"mc":[{"id":"1.232283786","rc":[{"batb":[[0,1.69,5],[1,1.68,5.67],[2,1.3,5.83]],"ltp":1.8,"tv":107.16,"id":35736920}]}]}
{"op":"mcm","clk":"11986070693","pt":1724917153857,"mc":[{"id":"1.232283786","rc":[{"batb":[[0,1.68,5.67],[1,1.3,5.83],[2,1.2,1000]],"ltp":1.8,"tv":107.16,"id":35736920}]}]}
{"op":"mcm","clk":"11986070768","pt":1724917156372,"mc":[{"id":"1.232283786","rc":[{"batb":[[0,1.69,5],[1,1.68,5.67],[2,1.3,5.83]],"ltp":1.8,"tv":107.16,"id":35736920}]}]}
{"op":"mcm","clk":"11986070881","pt":1724917159788,"mc":[{"id":"1.232283786","rc":[{"batb":[[0,1.68,5.67],[1,1.3,5.83],[2,1.2,1000]],"ltp":1.8,"tv":107.16,"id":35736920}]}]}
{"op":"mcm","clk":"11986071144","pt":1724917166962,"mc":[{"id":"1.232283786","rc":[{"batb":[[0,1.69,5],[1,1.68,5.67],[2,1.3,5.83]],"ltp":1.8,"tv":107.16,"id":35736920}]}]}
{"op":"mcm","clk":"11986071269","pt":1724917170288,"mc":[{"id":"1.232283786","rc":[{"batb":[[0,1.68,5.67],[1,1.3,5.83],[2,1.2,1000]],"ltp":1.8,"tv":107.16,"id":35736920}]}]}
{"op":"mcm","clk":"11986071387","pt":1724917173912,"mc":[{"id":"1.232283786","rc":[{"batb":[[0,1.69,5],[1,1.68,5.67],[2,1.3,5.83]],"ltp":1.8,"tv":107.16,"id":35736920}]}]}
{"op":"mcm","clk":"11986071538","pt":1724917177302,"mc":[{"id":"1.232283786","rc":[{"batb":[[0,1.68,5.67],[1,1.3,5.83],[2,1.2,1000]],"ltp":1.8,"tv":107.16,"id":35736920}]}]}
{"op":"mcm","clk":"11986071670","pt":1724917180795,"mc":[{"id":"1.232283786","rc":[{"batb":[[0,1.69,5],[1,1.68,5.67],[2,1.3,5.83]],"ltp":1.8,"tv":107.16,"id":35736920}]}]}
{"op":"mcm","clk":"11986071781","pt":1724917184211,"mc":[{"id":"1.232283786","rc":[{"batb":[[0,1.68,5.67],[1,1.3,5.83],[2,1.2,1000]],"ltp":1.8,"tv":107.16,"id":35736920}]}]}
{"op":"mcm","clk":"11986071847","pt":1724917186800,"mc":[{"id":"1.232283786","rc":[{"batb":[[0,1.69,5],[1,1.68,5.67],[2,1.3,5.83]],"ltp":1.8,"tv":107.16,"id":35736920}]}]}
{"op":"mcm","clk":"11986071940","pt":1724917190024,"mc":[{"id":"1.232283786","rc":[{"batb":[[0,1.68,5.67],[1,1.3,5.83],[2,1.2,1000]],"ltp":1.8,"tv":107.16,"id":35736920}]}]}
{"op":"mcm","clk":"11986072083","pt":1724917195126,"mc":[{"id":"1.232283786","rc":[{"batb":[[0,1.69,5],[1,1.68,5.67],[2,1.3,5.83]],"ltp":1.8,"tv":107.16,"id":35736920}]}]}
{"op":"mcm","clk":"11986072183","pt":1724917198496,"mc":[{"id":"1.232283786","rc":[{"batb":[[0,1.68,5.67],[1,1.3,5.83],[2,1.2,1000]],"ltp":1.8,"tv":107.16,"id":35736920}]}]}
{"op":"mcm","clk":"11986072325","pt":1724917202234,"mc":[{"id":"1.232283786","rc":[{"batb":[[0,1.69,5],[1,1.68,5.67],[2,1.3,5.83]],"ltp":1.8,"tv":107.16,"id":35736920}]}]}
{"op":"mcm","clk":"11986072437","pt":1724917205525,"mc":[{"id":"1.232283786","rc":[{"batb":[[0,1.68,5.67],[1,1.3,5.83],[2,1.2,1000]],"ltp":1.8,"tv":107.16,"id":35736920}]}]}
{"op":"mcm","clk":"11986072521","pt":1724917207932,"mc":[{"id":"1.232283786","rc":[{"batb":[[0,1.69,5],[1,1.68,5.67],[2,1.3,5.83]],"ltp":1.8,"tv":107.16,"id":35736920}]}]}
{"op":"mcm","clk":"11986072637","pt":1724917211333,"mc":[{"id":"1.232283786","rc":[{"batb":[[0,1.68,5.67],[1,1.3,5.83],[2,1.2,1000]],"ltp":1.8,"tv":107.16,"id":35736920}]}]}
{"op":"mcm","clk":"11986072816","pt":1724917216933,"mc":[{"id":"1.232283786","rc":[{"batb":[[0,1.69,5],[1,1.68,5.67],[2,1.3,5.83]],"ltp":1.8,"tv":107.16,"id":35736920}]}]}
{"op":"mcm","clk":"11986072920","pt":1724917220309,"mc":[{"id":"1.232283786","rc":[{"batb":[[0,1.68,5.67],[1,1.3,5.83],[2,1.2,1000]],"ltp":1.8,"tv":107.16,"id":35736920}]}]}
{"op":"mcm","clk":"11986073007","pt":1724917222715,"mc":[{"id":"1.232283786","rc":[{"batb":[[0,1.69,5],[1,1.68,5.67],[2,1.3,5.83]],"ltp":1.8,"tv":107.16,"id":35736920}]}]}
{"op":"mcm","clk":"11986073131","pt":1724917225944,"mc":[{"id":"1.232283786","rc":[{"batb":[[0,1.68,5.67],[1,1.3,5.83],[2,1.2,1000]],"ltp":1.8,"tv":107.16,"id":35736920}]}]}
{"op":"mcm","clk":"11986073268","pt":1724917229330,"mc":[{"id":"1.232283786","rc":[{"batb":[[0,1.69,5],[1,1.68,5.67],[2,1.3,5.83]],"ltp":1.8,"tv":107.16,"id":35736920}]}]}
{"op":"mcm","clk":"11986073379","pt":1724917232654,"mc":[{"id":"1.232283786","rc":[{"batb":[[0,1.68,5.67],[1,1.3,5.83],[2,1.2,1000]],"ltp":1.8,"tv":107.16,"id":35736920}]}]}
{"op":"mcm","clk":"11986073587","pt":1724917239733,"mc":[{"id":"1.232283786","rc":[{"batb":[[0,1.69,5],[1,1.68,5.67],[2,1.3,5.83]],"ltp":1.8,"tv":107.16,"id":35736920}]}]}
{"op":"mcm","clk":"11986073703","pt":1724917243058,"mc":[{"id":"1.232283786","rc":[{"batb":[[0,1.68,5.67],[1,1.3,5.83],[2,1.2,1000]],"ltp":1.8,"tv":107.16,"id":35736920}]}]}
{"op":"mcm","clk":"11986073905","pt":1724917247879,"mc":[{"id":"1.232283786","rc":[{"batb":[[0,1.69,5],[1,1.68,5.67],[2,1.3,5.83]],"ltp":1.8,"tv":107.16,"id":35736920}]}]}
{"op":"mcm","clk":"11986074022","pt":1724917251260,"mc":[{"id":"1.232283786","rc":[{"batb":[[0,1.68,5.67],[1,1.3,5.83],[2,1.2,1000]],"ltp":1.8,"tv":107.16,"id":35736920}]}]}
{"op":"mcm","clk":"11986074115","pt":1724917254658,"mc":[{"id":"1.232283786","rc":[{"batb":[[0,1.69,5],[1,1.68,5.67],[2,1.3,5.83]],"ltp":1.8,"tv":107.16,"id":35736920}]}]}
{"op":"mcm","clk":"11986074244","pt":1724917258052,"mc":[{"id":"1.232283786","rc":[{"batb":[[0,1.68,5.67],[1,1.3,5.83],[2,1.2,1000]],"ltp":1.8,"tv":107.16,"id":35736920}]}]}
{"op":"mcm","clk":"11986074315","pt":1724917260461,"mc":[{"id":"1.232283786","rc":[{"batb":[[0,1.69,5],[1,1.68,5.67],[2,1.3,5.83]],"ltp":1.8,"tv":107.16,"id":35736920}]}]}
{"op":"mcm","clk":"11986074408","pt":1724917263845,"mc":[{"id":"1.232283786","rc":[{"batb":[[0,1.68,5.67],[1,1.3,5.83],[2,1.2,1000]],"ltp":1.8,"tv":107.16,"id":35736920}]}]}
{"op":"mcm","clk":"11986074432","pt":1724917264868,"mc":[{"id":"1.232283786","rc":[{"batl":[[0,5.9,10.09]],"ltp":2.26,"tv":5.93,"id":11445383}]}]}
{"op":"mcm","clk":"11986074694","pt":1724917273070,"mc":[{"id":"1.232283786","rc":[{"batb":[[0,1.69,5],[1,1.68,5.67],[2,1.3,5.83]],"ltp":1.8,"tv":107.16,"id":35736920}]}]}
{"op":"mcm","clk":"11986074815","pt":1724917276359,"mc":[{"id":"1.232283786","rc":[{"batb":[[0,1.68,5.67],[1,1.3,5.83],[2,1.2,1000]],"ltp":1.8,"tv":107.16,"id":35736920}]}]}
{"op":"mcm","clk":"11986074890","pt":1724917278888,"mc":[{"id":"1.232283786","rc":[{"batb":[[0,1.69,5],[1,1.68,5.67],[2,1.3,5.83]],"ltp":1.8,"tv":107.16,"id":35736920}]}]}
{"op":"mcm","clk":"11986075001","pt":1724917282211,"mc":[{"id":"1.232283786","rc":[{"batb":[[0,1.68,5.67],[1,1.3,5.83],[2,1.2,1000]],"ltp":1.8,"tv":107.16,"id":35736920}]}]}
{"op":"mcm","clk":"11986075136","pt":1724917285919,"mc":[{"id":"1.232283786","rc":[{"batb":[[0,1.69,5],[1,1.68,5.67],[2,1.3,5.83]],"ltp":1.8,"tv":107.16,"id":35736920}]}]}
{"op":"mcm","clk":"11986075257","pt":1724917289105,"mc":[{"id":"1.232283786","rc":[{"batb":[[0,1.68,5.67],[1,1.3,5.83],[2,1.2,1000]],"ltp":1.8,"tv":107.16,"id":35736920}]}]}
{"op":"mcm","clk":"11986075413","pt":1724917292923,"mc":[{"id":"1.232283786","rc":[{"batb":[[0,1.69,5],[1,1.68,5.67],[2,1.3,5.83]],"ltp":1.8,"tv":107.16,"id":35736920}]}]}
{"op":"mcm","clk":"11986075511","pt":1724917296314,"mc":[{"id":"1.232283786","rc":[{"batb":[[0,1.68,5.67],[1,1.3,5.83],[2,1.2,1000]],"ltp":1.8,"tv":107.16,"id":35736920}]}]}
{"op":"mcm","clk":"11986075614","pt":1724917299530,"mc":[{"id":"1.232283786","rc":[{"batb":[[0,1.69,5],[1,1.68,5.67],[2,1.3,5.83]],"ltp":1.8,"tv":107.16,"id":35736920}]}]}
{"op":"mcm","clk":"11986075742","pt":1724917302853,"mc":[{"id":"1.232283786","rc":[{"batb":[[0,1.68,5.67],[1,1.3,5.83],[2,1.2,1000]],"ltp":1.8,"tv":107.16,"id":35736920}]}]}
{"op":"mcm","clk":"11986075998","pt":1724917311214,"mc":[{"id":"1.232283786","rc":[{"batb":[[0,1.69,5],[1,1.68,5.67],[2,1.3,5.83]],"ltp":1.8,"tv":107.16,"id":35736920}]}]}
{"op":"mcm","clk":"11986076096","pt":1724917314647,"mc":[{"id":"1.232283786","rc":[{"batb":[[0,1.68,5.67],[1,1.3,5.83],[2,1.2,1000]],"ltp":1.8,"tv":107.16,"id":35736920}]}]}
{"op":"mcm","clk":"11986076218","pt":1724917317731,"mc":[{"id":"1.232283786","rc":[{"batb":[[0,1.69,5],[1,1.68,5.67],[2,1.3,5.83]],"ltp":1.8,"tv":107.16,"id":35736920}]}]}
{"op":"mcm","clk":"11986076334","pt":1724917321115,"mc":[{"id":"1.232283786","rc":[{"batb":[[0,1.68,5.67],[1,1.3,5.83],[2,1.2,1000]],"ltp":1.8,"tv":107.16,"id":35736920}]}]}
{"op":"mcm","clk":"11986076460","pt":1724917324513,"mc":[{"id":"1.232283786","rc":[{"batb":[[0,1.69,5],[1,1.68,5.67],[2,1.3,5.83]],"ltp":1.8,"tv":107.16,"id":35736920}]}]}
{"op":"mcm","clk":"11986076566","pt":1724917327866,"mc":[{"id":"1.232283786","rc":[{"batb":[[0,1.68,5.67],[1,1.3,5.83],[2,1.2,1000]],"ltp":1.8,"tv":107.16,"id":35736920}]}]}
{"op":"mcm","clk":"11986076742","pt":1724917334228,"mc":[{"id":"1.232283786","rc":[{"batb":[[0,1.69,5],[1,1.68,5.67],[2,1.3,5.83]],"ltp":1.8,"tv":107.16,"id":35736920}]}]}
{"op":"mcm","clk":"11986076853","pt":1724917337569,"mc":[{"id":"1.232283786","rc":[{"batb":[[0,1.68,5.67],[1,1.3,5.83],[2,1.2,1000]],"ltp":1.8,"tv":107.16,"id":35736920}]}]}
{"op":"mcm","clk":"11986076933","pt":1724917340137,"mc":[{"id":"1.232283786","rc":[{"batb":[[0,1.69,5],[1,1.68,5.67],[2,1.3,5.83]],"ltp":1.8,"tv":107.16,"id":35736920}]}]}
{"op":"mcm","clk":"11986077038","pt":1724917343577,"mc":[{"id":"1.232283786","rc":[{"batb":[[0,1.68,5.67],[1,1.3,5.83],[2,1.2,1000]],"ltp":1.8,"tv":107.16,"id":35736920}]}]}
{"op":"mcm","clk":"11986077146","pt":1724917347085,"mc":[{"id":"1.232283786","rc":[{"batb":[[0,1.69,5],[1,1.68,5.67],[2,1.3,5.83]],"ltp":1.8,"tv":107.16,"id":35736920}]}]}
{"op":"mcm","clk":"11986077270","pt":1724917350360,"mc":[{"id":"1.232283786","rc":[{"batb":[[0,1.68,5.67],[1,1.3,5.83],[2,1.2,1000]],"ltp":1.8,"tv":107.16,"id":35736920}]}]}
{"op":"mcm","clk":"11986077523","pt":1724917357689,"mc":[{"id":"1.232283786","rc":[{"batb":[[0,1.69,5],[1,1.68,5.67],[2,1.3,5.83]],"ltp":1.8,"tv":107.16,"id":35736920}]}]}
{"op":"mcm","clk":"11986077655","pt":1724917360986,"mc":[{"id":"1.232283786","rc":[{"batb":[[0,1.68,5.67],[1,1.3,5.83],[2,1.2,1000]],"ltp":1.8,"tv":107.16,"id":35736920}]}]}
{"op":"mcm","clk":"11986077758","pt":1724917363502,"mc":[{"id":"1.232283786","rc":[{"batb":[[0,1.69,5],[1,1.68,5.67],[2,1.3,5.83]],"ltp":1.8,"tv":107.16,"id":35736920}]}]}
{"op":"mcm","clk":"11986077872","pt":1724917366899,"mc":[{"id":"1.232283786","rc":[{"batb":[[0,1.68,5.67],[1,1.3,5.83],[2,1.2,1000]],"ltp":1.8,"tv":107.16,"id":35736920}]}]}
{"op":"mcm","clk":"11986077947","pt":1724917369102,"mc":[{"id":"1.232283786","rc":[{"batb":[[0,1.69,5],[1,1.68,5.67],[2,1.3,5.83]],"ltp":1.8,"tv":107.16,"id":35736920}]}]}
{"op":"mcm","clk":"11986078053","pt":1724917372503,"mc":[{"id":"1.232283786","rc":[{"batb":[[0,1.68,5.67],[1,1.3,5.83],[2,1.2,1000]],"ltp":1.8,"tv":107.16,"id":35736920}]}]}
{"op":"mcm","clk":"11986078140","pt":1724917375163,"mc":[{"id":"1.232283786","rc":[{"batb":[[0,1.69,5],[1,1.68,5.67],[2,1.3,5.83]],"ltp":1.8,"tv":107.16,"id":35736920}]}]}
{"op":"mcm","clk":"11986078250","pt":1724917378288,"mc":[{"id":"1.232283786","rc":[{"batb":[[0,1.68,5.67],[1,1.3,5.83],[2,1.2,1000]],"ltp":1.8,"tv":107.16,"id":35736920}]}]}
{"op":"mcm","clk":"11986078377","pt":1724917381598,"mc":[{"id":"1.232283786","rc":[{"batb":[[0,1.69,5],[1,1.68,5.67],[2,1.3,5.83]],"ltp":1.8,"tv":107.16,"id":35736920}]}]}
{"op":"mcm","clk":"11986078507","pt":1724917385034,"mc":[{"id":"1.232283786","rc":[{"batb":[[0,1.68,5.67],[1,1.3,5.83],[2,1.2,1000]],"ltp":1.8,"tv":107.16,"id":35736920}]}]}
{"op":"mcm","clk":"11986078964","pt":1724917396027,"mc":[{"id":"1.232283786","rc":[{"batb":[[0,1.69,5],[1,1.68,5.67],[2,1.3,5.83]],"ltp":1.8,"tv":107.16,"id":35736920}]}]}
{"op":"mcm","clk":"11986079065","pt":1724917399326,"mc":[{"id":"1.232283786","rc":[{"batb":[[0,1.68,5.67],[1,1.3,5.83],[2,1.2,1000]],"ltp":1.8,"tv":107.16,"id":35736920}]}]}
{"op":"mcm","clk":"11986079160","pt":1724917401636,"mc":[{"id":"1.232283786","rc":[{"batb":[[0,1.69,5],[1,1.68,5.67],[2,1.3,5.83]],"ltp":1.8,"tv":107.16,"id":35736920}]}]}
{"op":"mcm","clk":"11986079280","pt":1724917404820,"mc":[{"id":"1.232283786","rc":[{"batb":[[0,1.68,5.67],[1,1.3,5.83],[2,1.2,1000]],"ltp":1.8,"tv":107.16,"id":35736920}]}]}
{"op":"mcm","clk":"11986079483","pt":1724917411425,"mc":[{"id":"1.232283786","rc":[{"batl":[[0,5.9,10.09]],"ltp":2.26,"tv":5.93,"id":11445383}]}]}
{"op":"mcm","clk":"11986079487","pt":1724917411527,"mc":[{"id":"1.232283786","rc":[{"batb":[[0,1.69,5],[1,1.68,5.67],[2,1.3,5.83]],"ltp":1.8,"tv":107.16,"id":35736920}]}]}
{"op":"mcm","clk":"11986079595","pt":1724917414759,"mc":[{"id":"1.232283786","rc":[{"batb":[[0,1.68,5.67],[1,1.3,5.83],[2,1.2,1000]],"ltp":1.8,"tv":107.16,"id":35736920}]}]}
{"op":"mcm","clk":"11986079668","pt":1724917417266,"mc":[{"id":"1.232283786","rc":[{"batb":[[0,1.69,5],[1,1.68,5.67],[2,1.3,5.83]],"ltp":1.8,"tv":107.16,"id":35736920}]}]}
{"op":"mcm","clk":"11986079792","pt":1724917420550,"mc":[{"id":"1.232283786","rc":[{"batb":[[0,1.68,5.67],[1,1.3,5.83],[2,1.2,1000]],"ltp":1.8,"tv":107.16,"id":35736920}]}]}
{"op":"mcm","clk":"11986080095","pt":1724917428450,"mc":[{"id":"1.232283786","rc":[{"batb":[[0,1.69,5],[1,1.68,5.67],[2,1.3,5.83]],"ltp":1.8,"tv":107.16,"id":35736920}]}]}
{"op":"mcm","clk":"11986080235","pt":1724917431833,"mc":[{"id":"1.232283786","rc":[{"batb":[[0,1.68,5.67],[1,1.3,5.83],[2,1.2,1000]],"ltp":1.8,"tv":107.16,"id":35736920}]}]}
{"op":"mcm","clk":"11986080355","pt":1724917434240,"mc":[{"id":"1.232283786","rc":[{"batb":[[0,1.69,5],[1,1.68,5.67],[2,1.3,5.83]],"ltp":1.8,"tv":107.16,"id":35736920}]}]}
{"op":"mcm","clk":"11986080488","pt":1724917437666,"mc":[{"id":"1.232283786","rc":[{"batb":[[0,1.68,5.67],[1,1.3,5.83],[2,1.2,1000]],"ltp":1.8,"tv":107.16,"id":35736920}]}]}
{"op":"mcm","clk":"11986080778","pt":1724917444393,"mc":[{"id":"1.232283786","rc":[{"batb":[[0,1.69,5],[1,1.68,5.67],[2,1.3,5.83]],"ltp":1.8,"tv":107.16,"id":35736920}]}]}
{"op":"mcm","clk":"11986080902","pt":1724917447784,"mc":[{"id":"1.232283786","rc":[{"batb":[[0,1.68,5.67],[1,1.3,5.83],[2,1.2,1000]],"ltp":1.8,"tv":107.16,"id":35736920}]}]}
{"op":"mcm","clk":"11986081000","pt":1724917450695,"mc":[{"id":"1.232283786","rc":[{"batb":[[0,1.69,5],[1,1.68,5.67],[2,1.3,5.83]],"ltp":1.8,"tv":107.16,"id":35736920}]}]}
{"op":"mcm","clk":"11986081155","pt":1724917453868,"mc":[{"id":"1.232283786","rc":[{"batb":[[0,1.68,5.67],[1,1.3,5.83],[2,1.2,1000]],"ltp":1.8,"tv":107.16,"id":35736920}]}]}
{"op":"mcm","clk":"11986081305","pt":1724917457608,"mc":[{"id":"1.232283786","rc":[{"batb":[[0,1.69,5],[1,1.68,5.67],[2,1.3,5.83]],"ltp":1.8,"tv":107.16,"id":35736920}]}]}
{"op":"mcm","clk":"11986081396","pt":1724917460890,"mc":[{"id":"1.232283786","rc":[{"batb":[[0,1.68,5.67],[1,1.3,5.83],[2,1.2,1000]],"ltp":1.8,"tv":107.16,"id":35736920}]}]}
{"op":"mcm","clk":"11986081483","pt":1724917463404,"mc":[{"id":"1.232283786","rc":[{"batb":[[0,1.69,5],[1,1.68,5.67],[2,1.3,5.83]],"ltp":1.8,"tv":107.16,"id":35736920}]}]}
{"op":"mcm","clk":"11986081585","pt":1724917466584,"mc":[{"id":"1.232283786","rc":[{"batb":[[0,1.68,5.67],[1,1.3,5.83],[2,1.2,1000]],"ltp":1.8,"tv":107.16,"id":35736920}]}]}
{"op":"mcm","clk":"11986081720","pt":1724917470524,"mc":[{"id":"1.232283786","rc":[{"batb":[[0,1.69,5],[1,1.68,5.67],[2,1.3,5.83]],"ltp":1.8,"tv":107.16,"id":35736920}]}]}
{"op":"mcm","clk":"11986081820","pt":1724917473810,"mc":[{"id":"1.232283786","rc":[{"batb":[[0,1.68,5.67],[1,1.3,5.83],[2,1.2,1000]],"ltp":1.8,"tv":107.16,"id":35736920}]}]}
{"op":"mcm","clk":"11986081939","pt":1724917476830,"mc":[{"id":"1.232283786","rc":[{"batb":[[0,1.69,5],[1,1.68,5.67],[2,1.3,5.83]],"ltp":1.8,"tv":107.16,"id":35736920}]}]}
{"op":"mcm","clk":"11986082085","pt":1724917480225,"mc":[{"id":"1.232283786","rc":[{"batb":[[0,1.68,5.67],[1,1.3,5.83],[2,1.2,1000]],"ltp":1.8,"tv":107.16,"id":35736920}]}]}
{"op":"mcm","clk":"11986082208","pt":1724917483315,"mc":[{"id":"1.232283786","rc":[{"batb":[[0,1.69,5],[1,1.68,5.67],[2,1.3,5.83]],"ltp":1.8,"tv":107.16,"id":35736920}]}]}
{"op":"mcm","clk":"11986082291","pt":1724917486703,"mc":[{"id":"1.232283786","rc":[{"batb":[[0,1.68,5.67],[1,1.3,5.83],[2,1.2,1000]],"ltp":1.8,"tv":107.16,"id":35736920}]}]}
{"op":"mcm","clk":"11986082674","pt":1724917497048,"mc":[{"id":"1.232283786","rc":[{"batb":[[0,1.69,5],[1,1.68,5.67],[2,1.3,5.83]],"ltp":1.8,"tv":107.16,"id":35736920}]}]}
{"op":"mcm","clk":"11986082779","pt":1724917500437,"mc":[{"id":"1.232283786","rc":[{"batb":[[0,1.68,5.67],[1,1.3,5.83],[2,1.2,1000]],"ltp":1.8,"tv":107.16,"id":35736920}]}]}
{"op":"mcm","clk":"11986083019","pt":1724917508055,"mc":[{"id":"1.232283786","rc":[{"batb":[[0,1.69,5],[1,1.68,5.67],[2,1.3,5.83]],"ltp":1.8,"tv":107.16,"id":35736920}]}]}
{"op":"mcm","clk":"11986083151","pt":1724917511260,"mc":[{"id":"1.232283786","rc":[{"batb":[[0,1.68,5.67],[1,1.3,5.83],[2,1.2,1000]],"ltp":1.8,"tv":107.16,"id":35736920}]}]}
{"op":"mcm","clk":"11986083215","pt":1724917513936,"mc":[{"id":"1.232283786","rc":[{"batb":[[0,1.69,5],[1,1.68,5.67],[2,1.3,5.83]],"ltp":1.8,"tv":107.16,"id":35736920}]}]}
{"op":"mcm","clk":"11986083331","pt":1724917517366,"mc":[{"id":"1.232283786","rc":[{"batb":[[0,1.68,5.67],[1,1.3,5.83],[2,1.2,1000]],"ltp":1.8,"tv":107.16,"id":35736920}]}]}
{"op":"mcm","clk":"11986083394","pt":1724917519777,"mc":[{"id":"1.232283786","rc":[{"batb":[[0,1.69,5],[1,1.68,5.67],[2,1.3,5.83]],"ltp":1.8,"tv":107.16,"id":35736920}]}]}
{"op":"mcm","clk":"11986083517","pt":1724917523268,"mc":[{"id":"1.232283786","rc":[{"batb":[[0,1.68,5.67],[1,1.3,5.83],[2,1.2,1000]],"ltp":1.8,"tv":107.16,"id":35736920}]}]}
{"op":"mcm","clk":"11986083615","pt":1724917525682,"mc":[{"id":"1.232283786","rc":[{"batb":[[0,1.69,5],[1,1.68,5.67],[2,1.3,5.83]],"ltp":1.8,"tv":107.16,"id":35736920}]}]}
{"op":"mcm","clk":"11986083752","pt":1724917529066,"mc":[{"id":"1.232283786","rc":[{"batb":[[0,1.68,5.67],[1,1.3,5.83],[2,1.2,1000]],"ltp":1.8,"tv":107.16,"id":35736920}]}]}
{"op":"mcm","clk":"11986083960","pt":1724917535062,"mc":[{"id":"1.232283786","rc":[{"batb":[[0,1.69,5],[1,1.68,5.67],[2,1.3,5.83]],"ltp":1.8,"tv":107.16,"id":35736920}]}]}
{"op":"mcm","clk":"11986084082","pt":1724917538493,"mc":[{"id":"1.232283786","rc":[{"batb":[[0,1.68,5.67],[1,1.3,5.83],[2,1.2,1000]],"ltp":1.8,"tv":107.16,"id":35736920}]}]}
{"op":"mcm","clk":"11986084178","pt":1724917541883,"mc":[{"id":"1.232283786","rc":[{"batb":[[0,1.69,5],[1,1.68,5.67],[2,1.3,5.83]],"ltp":1.8,"tv":107.16,"id":35736920}]}]}
{"op":"mcm","clk":"11986084284","pt":1724917545305,"mc":[{"id":"1.232283786","rc":[{"batb":[[0,1.68,5.67],[1,1.3,5.83],[2,1.2,1000]],"ltp":1.8,"tv":107.16,"id":35736920}]}]}
{"op":"mcm","clk":"11986084407","pt":1724917548907,"mc":[{"id":"1.232283786","rc":[{"batb":[[0,1.69,5],[1,1.68,5.67],[2,1.3,5.83]],"ltp":1.8,"tv":107.16,"id":35736920}]}]}
{"op":"mcm","clk":"11986084525","pt":1724917552280,"mc":[{"id":"1.232283786","rc":[{"batb":[[0,1.68,5.67],[1,1.3,5.83],[2,1.2,1000]],"ltp":1.8,"tv":107.16,"id":35736920}]}]}
{"op":"mcm","clk":"11986084613","pt":1724917554532,"mc":[{"id":"1.232283786","rc":[{"batb":[[0,1.69,5],[1,1.68,5.67],[2,1.3,5.83]],"ltp":1.8,"tv":107.16,"id":35736920}]}]}
{"op":"mcm","clk":"11986084746","pt":1724917557803,"mc":[{"id":"1.232283786","rc":[{"batb":[[0,1.68,5.67],[1,1.3,5.83],[2,1.2,1000]],"ltp":1.8,"tv":107.16,"id":35736920}]}]}
{"op":"mcm","clk":"11986084790","pt":1724917558899,"mc":[{"id":"1.232283786","rc":[{"batl":[[0,5.9,10.09]],"ltp":2.26,"tv":5.93,"id":11445383}]}]}
{"op":"mcm","clk":"11986084846","pt":1724917560027,"mc":[{"id":"1.232283786","rc":[{"batb":[[0,1.69,5],[1,1.68,5.67],[2,1.3,5.83]],"ltp":1.8,"tv":107.16,"id":35736920}]}]}
{"op":"mcm","clk":"11986084974","pt":1724917563420,"mc":[{"id":"1.232283786","rc":[{"batb":[[0,1.68,5.67],[1,1.3,5.83],[2,1.2,1000]],"ltp":1.8,"tv":107.16,"id":35736920}]}]}
{"op":"mcm","clk":"11986085623","pt":1724917578918,"mc":[{"id":"1.232283786","rc":[{"batb":[[0,1.69,5],[1,1.68,5.67],[2,1.3,5.83]],"ltp":1.8,"tv":107.16,"id":35736920}]}]}
{"op":"mcm","clk":"11986085736","pt":1724917582349,"mc":[{"id":"1.232283786","rc":[{"batb":[[0,1.68,5.67],[1,1.3,5.83],[2,1.2,1000]],"ltp":1.8,"tv":107.16,"id":35736920}]}]}
{"op":"mcm","clk":"11986085795","pt":1724917584753,"mc":[{"id":"1.232283786","rc":[{"batb":[[0,1.69,5],[1,1.68,5.67],[2,1.3,5.83]],"ltp":1.8,"tv":107.16,"id":35736920}]}]}
{"op":"mcm","clk":"11986085914","pt":1724917588043,"mc":[{"id":"1.232283786","rc":[{"batb":[[0,1.68,5.67],[1,1.3,5.83],[2,1.2,1000]],"ltp":1.8,"tv":107.16,"id":35736920}]}]}
{"op":"mcm","clk":"11986086039","pt":1724917590764,"mc":[{"id":"1.232283786","rc":[{"batb":[[0,1.69,5],[1,1.68,5.67],[2,1.3,5.83]],"ltp":1.8,"tv":107.16,"id":35736920}]}]}
{"op":"mcm","clk":"11986086145","pt":1724917594051,"mc":[{"id":"1.232283786","rc":[{"batb":[[0,1.68,5.67],[1,1.3,5.83],[2,1.2,1000]],"ltp":1.8,"tv":107.16,"id":35736920}]}]}
{"op":"mcm","clk":"11986086222","pt":1724917596483,"mc":[{"id":"1.232283786","rc":[{"batb":[[0,1.69,5],[1,1.68,5.67],[2,1.3,5.83]],"ltp":1.8,"tv":107.16,"id":35736920}]}]}
{"op":"mcm","clk":"11986086345","pt":1724917599870,"mc":[{"id":"1.232283786","rc":[{"batb":[[0,1.68,5.67],[1,1.3,5.83],[2,1.2,1000]],"ltp":1.8,"tv":107.16,"id":35736920}]}]}
{"op":"mcm","clk":"11986086450","pt":1724917603462,"mc":[{"id":"1.232283786","rc":[{"batb":[[0,1.69,5],[1,1.68,5.67],[2,1.3,5.83]],"ltp":1.8,"tv":107.16,"id":35736920}]}]}
{"op":"mcm","clk":"11986086529","pt":1724917606642,"mc":[{"id":"1.232283786","rc":[{"batb":[[0,1.68,5.67],[1,1.3,5.83],[2,1.2,1000]],"ltp":1.8,"tv":107.16,"id":35736920}]}]}
{"op":"mcm","clk":"11986086624","pt":1724917609153,"mc":[{"id":"1.232283786","rc":[{"batb":[[0,1.69,5],[1,1.68,5.67],[2,1.3,5.83]],"ltp":1.8,"tv":107.16,"id":35736920}]}]}
{"op":"mcm","clk":"11986086765","pt":1724917612355,"mc":[{"id":"1.232283786","rc":[{"batb":[[0,1.68,5.67],[1,1.3,5.83],[2,1.2,1000]],"ltp":1.8,"tv":107.16,"id":35736920}]}]}
{"op":"mcm","clk":"11986086855","pt":1724917616094,"mc":[{"id":"1.232283786","rc":[{"batb":[[0,1.69,5],[1,1.68,5.67],[2,1.3,5.83]],"ltp":1.8,"tv":107.16,"id":35736920}]}]}
{"op":"mcm","clk":"11986086976","pt":1724917619482,"mc":[{"id":"1.232283786","rc":[{"batb":[[0,1.68,5.67],[1,1.3,5.83],[2,1.2,1000]],"ltp":1.8,"tv":107.16,"id":35736920}]}]}
{"op":"mcm","clk":"11986089602","pt":1724917703278,"mc":[{"id":"1.232283786","rc":[{"batl":[[0,5.9,10.09]],"ltp":2.26,"tv":5.93,"id":11445383}]}]}
{"op":"mcm","clk":"11986115443","pt":1724918333293,"mc":[{"id":"1.232283786","rc":[{"batb":[[1,1.2,1000],[2,1.04,1.05]],"ltp":2.26,"tv":5.93,"id":11445383}]}]}
{"op":"mcm","clk":"11986118385","pt":1724918400881,"mc":[{"id":"1.232283786","rc":[{"batb":[[0,1.69,5],[1,1.68,5.67],[2,1.3,5.83]],"ltp":1.8,"tv":107.16,"id":35736920}]}]}
{"op":"mcm","clk":"11986118568","pt":1724918404271,"mc":[{"id":"1.232283786","rc":[{"batb":[[0,1.68,5.67],[1,1.3,5.83],[2,1.2,1000]],"ltp":1.8,"tv":107.16,"id":35736920}]}]}
{"op":"mcm","clk":"11986118698","pt":1724918406882,"mc":[{"id":"1.232283786","rc":[{"trd":[[1.68,99.48]],"batb":[[0,1.69,5],[1,1.68,5.67],[2,1.3,5.83]],"ltp":1.8,"tv":107.16,"id":35736920},{"batl":[[0,5.9,10.09]],"ltp":2.26,"tv":5.93,"id":11445383}],"tv":113.1}]}
{"op":"mcm","clk":"11986118843","pt":1724918410313,"mc":[{"id":"1.232283786","rc":[{"batb":[[0,1.68,5.67],[1,1.3,5.83],[2,1.2,1000]],"ltp":1.8,"tv":107.16,"id":35736920}]}]}
{"op":"mcm","clk":"11986118962","pt":1724918412672,"mc":[{"id":"1.232283786","rc":[{"batb":[[0,1.69,5],[1,1.68,5.67],[2,1.3,5.83]],"ltp":1.8,"tv":107.16,"id":35736920}]}]}
{"op":"mcm","clk":"11986119138","pt":1724918415904,"mc":[{"id":"1.232283786","rc":[{"batb":[[0,1.68,5.67],[1,1.3,5.83],[2,1.2,1000]],"ltp":1.8,"tv":107.16,"id":35736920}]}]}
{"op":"mcm","clk":"11986119315","pt":1724918418381,"mc":[{"id":"1.232283786","rc":[{"batb":[[0,1.69,5],[1,1.68,5.67],[2,1.3,5.83]],"ltp":1.8,"tv":107.16,"id":35736920}]}]}
{"op":"mcm","clk":"11986119461","pt":1724918421687,"mc":[{"id":"1.232283786","rc":[{"batb":[[0,1.68,5.67],[1,1.3,5.83],[2,1.2,1000]],"ltp":1.8,"tv":107.16,"id":35736920}]}]}
{"op":"mcm","clk":"11986119738","pt":1724918427393,"mc":[{"id":"1.232283786","rc":[{"batb":[[0,1.69,5],[1,1.68,5.67],[2,1.3,5.83]],"ltp":1.8,"tv":107.16,"id":35736920}]}]}
{"op":"mcm","clk":"11986119925","pt":1724918430830,"mc":[{"id":"1.232283786","rc":[{"batb":[[0,1.68,5.67],[1,1.3,5.83],[2,1.2,1000]],"ltp":1.8,"tv":107.16,"id":35736920}]}]}
{"op":"mcm","clk":"11986120097","pt":1724918434510,"mc":[{"id":"1.232283786","rc":[{"batb":[[0,1.69,5],[1,1.68,5.67],[2,1.3,5.83]],"ltp":1.8,"tv":107.16,"id":35736920}]}]}
{"op":"mcm","clk":"11986120243","pt":1724918437944,"mc":[{"id":"1.232283786","rc":[{"batb":[[0,1.68,5.67],[1,1.3,5.83],[2,1.2,1000]],"ltp":1.8,"tv":107.16,"id":35736920}]}]}
{"op":"mcm","clk":"11986120404","pt":1724918442136,"mc":[{"id":"1.232283786","rc":[{"batb":[[0,1.69,5],[1,1.68,5.67],[2,1.3,5.83]],"ltp":1.8,"tv":107.16,"id":35736920}]}]}
{"op":"mcm","clk":"11986120537","pt":1724918445454,"mc":[{"id":"1.232283786","rc":[{"batb":[[0,1.68,5.67],[1,1.3,5.83],[2,1.2,1000]],"ltp":1.8,"tv":107.16,"id":35736920}]}]}
{"op":"mcm","clk":"11986120680","pt":1724918448946,"mc":[{"id":"1.232283786","rc":[{"batb":[[0,1.69,5],[1,1.68,5.67],[2,1.3,5.83]],"ltp":1.8,"tv":107.16,"id":35736920}]}]}
{"op":"mcm","clk":"11986120816","pt":1724918452165,"mc":[{"id":"1.232283786","rc":[{"batb":[[0,1.68,5.67],[1,1.3,5.83],[2,1.2,1000]],"ltp":1.8,"tv":107.16,"id":35736920}]}]}
{"op":"mcm","clk":"11986120980","pt":1724918455435,"mc":[{"id":"1.232283786","rc":[{"batb":[[0,1.69,5],[1,1.68,5.67],[2,1.3,5.83]],"ltp":1.8,"tv":107.16,"id":35736920}]}]}
{"op":"mcm","clk":"11986121125","pt":1724918458762,"mc":[{"id":"1.232283786","rc":[{"batb":[[0,1.68,5.67],[1,1.3,5.83],[2,1.2,1000]],"ltp":1.8,"tv":107.16,"id":35736920}]}]}
{"op":"mcm","clk":"11986121325","pt":1724918462660,"mc":[{"id":"1.232283786","rc":[{"batb":[[0,1.69,5],[1,1.68,5.67],[2,1.3,5.83]],"ltp":1.8,"tv":107.16,"id":35736920}]}]}
{"op":"mcm","clk":"11986121479","pt":1724918465888,"mc":[{"id":"1.232283786","rc":[{"batb":[[0,1.68,5.67],[1,1.3,5.83],[2,1.2,1000]],"ltp":1.8,"tv":107.16,"id":35736920}]}]}
{"op":"mcm","clk":"11986121732","pt":1724918471991,"mc":[{"id":"1.232283786","rc":[{"batb":[[0,1.69,5],[1,1.68,5.67],[2,1.3,5.83]],"ltp":1.8,"tv":107.16,"id":35736920}]}]}
{"op":"mcm","clk":"11986121847","pt":1724918475470,"mc":[{"id":"1.232283786","rc":[{"batb":[[0,1.68,5.67],[1,1.3,5.83],[2,1.2,1000]],"ltp":1.8,"tv":107.16,"id":35736920}]}]}
{"op":"mcm","clk":"11986122035","pt":1724918478998,"mc":[{"id":"1.232283786","rc":[{"batb":[[0,1.69,5],[1,1.68,5.67],[2,1.3,5.83]],"ltp":1.8,"tv":107.16,"id":35736920}]}]}
{"op":"mcm","clk":"11986122266","pt":1724918482276,"mc":[{"id":"1.232283786","rc":[{"batb":[[0,1.68,5.67],[1,1.3,5.83],[2,1.2,1000]],"ltp":1.8,"tv":107.16,"id":35736920}]}]}
{"op":"mcm","clk":"11986122536","pt":1724918486276,"mc":[{"id":"1.232283786","rc":[{"batb":[[0,1.69,5],[1,1.68,5.67],[2,1.3,5.83]],"ltp":1.8,"tv":107.16,"id":35736920}]}]}
{"op":"mcm","clk":"11986122729","pt":1724918489711,"mc":[{"id":"1.232283786","rc":[{"batb":[[0,1.68,5.67],[1,1.3,5.83],[2,1.2,1000]],"ltp":1.8,"tv":107.16,"id":35736920}]}]}
{"op":"mcm","clk":"11986123116","pt":1724918499631,"mc":[{"id":"1.232283786","rc":[{"batb":[[0,1.69,5],[1,1.68,5.67],[2,1.3,5.83]],"ltp":1.8,"tv":107.16,"id":35736920}]}]}
{"op":"mcm","clk":"11986123259","pt":1724918502909,"mc":[{"id":"1.232283786","rc":[{"batb":[[0,1.68,5.67],[1,1.3,5.83],[2,1.2,1000]],"ltp":1.8,"tv":107.16,"id":35736920}]}]}
{"op":"mcm","clk":"11986123395","pt":1724918506646,"mc":[{"id":"1.232283786","rc":[{"batb":[[0,1.69,5],[1,1.68,5.67],[2,1.3,5.83]],"ltp":1.8,"tv":107.16,"id":35736920}]}]}
{"op":"mcm","clk":"11986123544","pt":1724918509825,"mc":[{"id":"1.232283786","rc":[{"batb":[[0,1.68,5.67],[1,1.3,5.83],[2,1.2,1000]],"ltp":1.8,"tv":107.16,"id":35736920}]}]}
{"op":"mcm","clk":"11986123693","pt":1724918513624,"mc":[{"id":"1.232283786","rc":[{"batb":[[0,1.69,5],[1,1.68,5.67],[2,1.3,5.83]],"ltp":1.8,"tv":107.16,"id":35736920}]}]}
{"op":"mcm","clk":"11986123820","pt":1724918517061,"mc":[{"id":"1.232283786","rc":[{"batb":[[0,1.68,5.67],[1,1.3,5.83],[2,1.2,1000]],"ltp":1.8,"tv":107.16,"id":35736920}]}]}
{"op":"mcm","clk":"11986123898","pt":1724918519425,"mc":[{"id":"1.232283786","rc":[{"batb":[[0,1.69,5],[1,1.68,5.67],[2,1.3,5.83]],"ltp":1.8,"tv":107.16,"id":35736920}]}]}
{"op":"mcm","clk":"11986124044","pt":1724918522746,"mc":[{"id":"1.232283786","rc":[{"batb":[[0,1.68,5.67],[1,1.3,5.83],[2,1.2,1000]],"ltp":1.8,"tv":107.16,"id":35736920}]}]}
{"op":"mcm","clk":"11986124173","pt":1724918525181,"mc":[{"id":"1.232283786","rc":[{"batb":[[0,1.69,5],[1,1.68,5.67],[2,1.3,5.83]],"ltp":1.8,"tv":107.16,"id":35736920}]}]}
{"op":"mcm","clk":"11986124336","pt":1724918528565,"mc":[{"id":"1.232283786","rc":[{"batb":[[0,1.68,5.67],[1,1.3,5.83],[2,1.2,1000]],"ltp":1.8,"tv":107.16,"id":35736920}]}]}
{"op":"mcm","clk":"11986124502","pt":1724918532268,"mc":[{"id":"1.232283786","rc":[{"batb":[[0,1.69,5],[1,1.68,5.67],[2,1.3,5.83]],"ltp":1.8,"tv":107.16,"id":35736920},{"batl":[[0,5.9,10.09]],"ltp":2.26,"tv":5.93,"id":11445383}]}]}
{"op":"mcm","clk":"11986124637","pt":1724918535594,"mc":[{"id":"1.232283786","rc":[{"batb":[[0,1.68,5.67],[1,1.3,5.83],[2,1.2,1000]],"ltp":1.8,"tv":107.16,"id":35736920}]}]}
{"op":"mcm","clk":"11986124878","pt":1724918541491,"mc":[{"id":"1.232283786","rc":[{"batb":[[0,1.69,5],[1,1.68,5.67],[2,1.3,5.83]],"ltp":1.8,"tv":107.16,"id":35736920}]}]}
{"op":"mcm","clk":"11986125007","pt":1724918544683,"mc":[{"id":"1.232283786","rc":[{"batb":[[0,1.68,5.67],[1,1.3,5.83],[2,1.2,1000]],"ltp":1.8,"tv":107.16,"id":35736920}]}]}
{"op":"mcm","clk":"11986125140","pt":1724918548186,"mc":[{"id":"1.232283786","rc":[{"batb":[[0,1.69,5],[1,1.68,5.67],[2,1.3,5.83]],"ltp":1.8,"tv":107.16,"id":35736920}]}]}
{"op":"mcm","clk":"11986125280","pt":1724918551475,"mc":[{"id":"1.232283786","rc":[{"batb":[[0,1.68,5.67],[1,1.3,5.83],[2,1.2,1000]],"ltp":1.8,"tv":107.16,"id":35736920}]}]}
{"op":"mcm","clk":"11986125395","pt":1724918554298,"mc":[{"id":"1.232283786","rc":[{"batb":[[0,1.69,5],[1,1.68,5.67],[2,1.3,5.83]],"ltp":1.8,"tv":107.16,"id":35736920}]}]}
{"op":"mcm","clk":"11986125543","pt":1724918557609,"mc":[{"id":"1.232283786","rc":[{"batb":[[0,1.68,5.67],[1,1.3,5.83],[2,1.2,1000]],"ltp":1.8,"tv":107.16,"id":35736920}]}]}
{"op":"mcm","clk":"11986125650","pt":1724918560084,"mc":[{"id":"1.232283786","rc":[{"batb":[[0,1.69,5],[1,1.68,5.67],[2,1.3,5.83]],"ltp":1.8,"tv":107.16,"id":35736920}]}]}
{"op":"mcm","clk":"11986125836","pt":1724918563594,"mc":[{"id":"1.232283786","rc":[{"batb":[[0,1.68,5.67],[1,1.3,5.83],[2,1.2,1000]],"ltp":1.8,"tv":107.16,"id":35736920}]}]}
{"op":"mcm","clk":"11986126112","pt":1724918569496,"mc":[{"id":"1.232283786","rc":[{"batb":[[0,1.69,5],[1,1.68,5.67],[2,1.3,5.83]],"ltp":1.8,"tv":107.16,"id":35736920}]}]}
{"op":"mcm","clk":"11986126241","pt":1724918572926,"mc":[{"id":"1.232283786","rc":[{"batb":[[0,1.68,5.67],[1,1.3,5.83],[2,1.2,1000]],"ltp":1.8,"tv":107.16,"id":35736920}]}]}
{"op":"mcm","clk":"11986126442","pt":1724918578403,"mc":[{"id":"1.232283786","rc":[{"batb":[[0,1.69,5],[1,1.68,5.67],[2,1.3,5.83]],"ltp":1.8,"tv":107.16,"id":35736920}]}]}
{"op":"mcm","clk":"11986126626","pt":1724918581770,"mc":[{"id":"1.232283786","rc":[{"batb":[[0,1.68,5.67],[1,1.3,5.83],[2,1.2,1000]],"ltp":1.8,"tv":107.16,"id":35736920}]}]}
{"op":"mcm","clk":"11986126740","pt":1724918584232,"mc":[{"id":"1.232283786","rc":[{"batb":[[0,1.69,5],[1,1.68,5.67],[2,1.3,5.83]],"ltp":1.8,"tv":107.16,"id":35736920}]}]}
{"op":"mcm","clk":"11986126865","pt":1724918587616,"mc":[{"id":"1.232283786","rc":[{"batb":[[0,1.68,5.67],[1,1.3,5.83],[2,1.2,1000]],"ltp":1.8,"tv":107.16,"id":35736920}]}]}
{"op":"mcm","clk":"11986126987","pt":1724918590128,"mc":[{"id":"1.232283786","rc":[{"batb":[[0,1.69,5],[1,1.68,5.67],[2,1.3,5.83]],"ltp":1.8,"tv":107.16,"id":35736920}]}]}
{"op":"mcm","clk":"11986127156","pt":1724918593559,"mc":[{"id":"1.232283786","rc":[{"batb":[[0,1.68,5.67],[1,1.3,5.83],[2,1.2,1000]],"ltp":1.8,"tv":107.16,"id":35736920}]}]}
{"op":"mcm","clk":"11986127335","pt":1724918597240,"mc":[{"id":"1.232283786","rc":[{"batb":[[0,1.69,5],[1,1.68,5.67],[2,1.3,5.83]],"ltp":1.8,"tv":107.16,"id":35736920}]}]}
{"op":"mcm","clk":"11986127478","pt":1724918600667,"mc":[{"id":"1.232283786","rc":[{"batb":[[0,1.68,5.67],[1,1.3,5.83],[2,1.2,1000]],"ltp":1.8,"tv":107.16,"id":35736920}]}]}
{"op":"mcm","clk":"11986127575","pt":1724918603865,"mc":[{"id":"1.232283786","rc":[{"batb":[[0,1.69,5],[1,1.68,5.67],[2,1.3,5.83]],"ltp":1.8,"tv":107.16,"id":35736920}]}]}
{"op":"mcm","clk":"11986127730","pt":1724918607288,"mc":[{"id":"1.232283786","rc":[{"batb":[[0,1.68,5.67],[1,1.3,5.83],[2,1.2,1000]],"ltp":1.8,"tv":107.16,"id":35736920}]}]}
{"op":"mcm","clk":"11986128058","pt":1724918614876,"mc":[{"id":"1.232283786","rc":[{"batb":[[0,1.69,5],[1,1.68,5.67],[2,1.3,5.83]],"ltp":1.8,"tv":107.16,"id":35736920}]}]}
{"op":"mcm","clk":"11986128245","pt":1724918618166,"mc":[{"id":"1.232283786","rc":[{"batb":[[0,1.68,5.67],[1,1.3,5.83],[2,1.2,1000]],"ltp":1.8,"tv":107.16,"id":35736920}]}]}
{"op":"mcm","clk":"11986128408","pt":1724918621547,"mc":[{"id":"1.232283786","rc":[{"batb":[[0,1.69,5],[1,1.68,5.67],[2,1.3,5.83]],"ltp":1.8,"tv":107.16,"id":35736920}]}]}
{"op":"mcm","clk":"11986128554","pt":1724918624977,"mc":[{"id":"1.232283786","rc":[{"batb":[[0,1.68,5.67],[1,1.3,5.83],[2,1.2,1000]],"ltp":1.8,"tv":107.16,"id":35736920}]}]}
{"op":"mcm","clk":"11986128673","pt":1724918627287,"mc":[{"id":"1.232283786","rc":[{"batb":[[0,1.69,5],[1,1.68,5.67],[2,1.3,5.83]],"ltp":1.8,"tv":107.16,"id":35736920}]}]}
{"op":"mcm","clk":"11986128886","pt":1724918630770,"mc":[{"id":"1.232283786","rc":[{"batb":[[0,1.68,5.67],[1,1.3,5.83],[2,1.2,1000]],"ltp":1.8,"tv":107.16,"id":35736920}]}]}
{"op":"mcm","clk":"11986129045","pt":1724918634865,"mc":[{"id":"1.232283786","rc":[{"batb":[[0,1.69,5],[1,1.68,5.67],[2,1.3,5.83]],"ltp":1.8,"tv":107.16,"id":35736920}]}]}
{"op":"mcm","clk":"11986129199","pt":1724918638303,"mc":[{"id":"1.232283786","rc":[{"batb":[[0,1.68,5.67],[1,1.3,5.83],[2,1.2,1000]],"ltp":1.8,"tv":107.16,"id":35736920}]}]}
{"op":"mcm","clk":"11986129343","pt":1724918641792,"mc":[{"id":"1.232283786","rc":[{"batb":[[0,1.69,5],[1,1.68,5.67],[2,1.3,5.83]],"ltp":1.8,"tv":107.16,"id":35736920}]}]}
{"op":"mcm","clk":"11986129474","pt":1724918645122,"mc":[{"id":"1.232283786","rc":[{"batb":[[0,1.68,5.67],[1,1.3,5.83],[2,1.2,1000]],"ltp":1.8,"tv":107.16,"id":35736920}]}]}
{"op":"mcm","clk":"11986129596","pt":1724918647586,"mc":[{"id":"1.232283786","rc":[{"batb":[[0,1.69,5],[1,1.68,5.67],[2,1.3,5.83]],"ltp":1.8,"tv":107.16,"id":35736920}]}]}
{"op":"mcm","clk":"11986129739","pt":1724918650896,"mc":[{"id":"1.232283786","rc":[{"batb":[[0,1.68,5.67],[1,1.3,5.83],[2,1.2,1000]],"ltp":1.8,"tv":107.16,"id":35736920}]}]}
{"op":"mcm","clk":"11986129886","pt":1724918653725,"mc":[{"id":"1.232283786","rc":[{"batb":[[0,1.69,5],[1,1.68,5.67],[2,1.3,5.83]],"ltp":1.8,"tv":107.16,"id":35736920}]}]}
{"op":"mcm","clk":"11986130054","pt":1724918656909,"mc":[{"id":"1.232283786","rc":[{"batb":[[0,1.68,5.67],[1,1.3,5.83],[2,1.2,1000]],"ltp":1.8,"tv":107.16,"id":35736920}]}]}
{"op":"mcm","clk":"11986130253","pt":1724918660496,"mc":[{"id":"1.232283786","rc":[{"batb":[[0,1.69,5],[1,1.68,5.67],[2,1.3,5.83]],"ltp":1.8,"tv":107.16,"id":35736920}]}]}
{"op":"mcm","clk":"11986130400","pt":1724918663827,"mc":[{"id":"1.232283786","rc":[{"batb":[[0,1.68,5.67],[1,1.3,5.83],[2,1.2,1000]],"ltp":1.8,"tv":107.16,"id":35736920}]}]}
{"op":"mcm","clk":"11986130625","pt":1724918668445,"mc":[{"id":"1.232283786","rc":[{"batb":[[0,1.69,5],[1,1.68,5.67],[2,1.3,5.83]],"ltp":1.8,"tv":107.16,"id":35736920}]}]}
{"op":"mcm","clk":"11986130744","pt":1724918671834,"mc":[{"id":"1.232283786","rc":[{"batb":[[0,1.68,5.67],[1,1.3,5.83],[2,1.2,1000]],"ltp":1.8,"tv":107.16,"id":35736920}]}]}
{"op":"mcm","clk":"11986131007","pt":1724918677727,"mc":[{"id":"1.232283786","rc":[{"batb":[[0,1.69,5],[1,1.68,5.67],[2,1.3,5.83]],"ltp":1.8,"tv":107.16,"id":35736920}]}]}
{"op":"mcm","clk":"11986131192","pt":1724918681014,"mc":[{"id":"1.232283786","rc":[{"batb":[[0,1.68,5.67],[1,1.3,5.83],[2,1.2,1000]],"ltp":1.8,"tv":107.16,"id":35736920}]}]}
{"op":"mcm","clk":"11986131317","pt":1724918683662,"mc":[{"id":"1.232283786","rc":[{"batb":[[0,1.69,5],[1,1.68,5.67],[2,1.3,5.83]],"ltp":1.8,"tv":107.16,"id":35736920}]}]}
{"op":"mcm","clk":"11986131502","pt":1724918687131,"mc":[{"id":"1.232283786","rc":[{"batb":[[0,1.68,5.67],[1,1.3,5.83],[2,1.2,1000]],"ltp":1.8,"tv":107.16,"id":35736920}]}]}
{"op":"mcm","clk":"11986131648","pt":1724918689447,"mc":[{"id":"1.232283786","rc":[{"batb":[[0,1.69,5],[1,1.68,5.67],[2,1.3,5.83]],"ltp":1.8,"tv":107.16,"id":35736920}]}]}
{"op":"mcm","clk":"11986131825","pt":1724918692941,"mc":[{"id":"1.232283786","rc":[{"batb":[[0,1.68,5.67],[1,1.3,5.83],[2,1.2,1000]],"ltp":1.8,"tv":107.16,"id":35736920}]}]}
{"op":"mcm","clk":"11986131981","pt":1724918696067,"mc":[{"id":"1.232283786","rc":[{"batb":[[0,1.69,5],[1,1.68,5.67],[2,1.3,5.83]],"ltp":1.8,"tv":107.16,"id":35736920}]}]}
{"op":"mcm","clk":"11986132125","pt":1724918699371,"mc":[{"id":"1.232283786","rc":[{"batb":[[0,1.68,5.67],[1,1.3,5.83],[2,1.2,1000]],"ltp":1.8,"tv":107.16,"id":35736920}]}]}
{"op":"mcm","clk":"11986132244","pt":1724918701839,"mc":[{"id":"1.232283786","rc":[{"batb":[[0,1.69,5],[1,1.68,5.67],[2,1.3,5.83]],"ltp":1.8,"tv":107.16,"id":35736920}]}]}
{"op":"mcm","clk":"11986132469","pt":1724918705289,"mc":[{"id":"1.232283786","rc":[{"batb":[[0,1.68,5.67],[1,1.3,5.83],[2,1.2,1000]],"ltp":1.8,"tv":107.16,"id":35736920}]}]}
{"op":"mcm","clk":"11986132529","pt":1724918706673,"mc":[{"id":"1.232283786","rc":[{"batl":[[0,5.9,10.09]],"ltp":2.26,"tv":5.93,"id":11445383}]}]}
{"op":"mcm","clk":"11986132677","pt":1724918710162,"mc":[{"id":"1.232283786","rc":[{"batb":[[0,1.69,5],[1,1.68,5.67],[2,1.3,5.83]],"ltp":1.8,"tv":107.16,"id":35736920}]}]}
{"op":"mcm","clk":"11986132817","pt":1724918713593,"mc":[{"id":"1.232283786","rc":[{"batb":[[0,1.68,5.67],[1,1.3,5.83],[2,1.2,1000]],"ltp":1.8,"tv":107.16,"id":35736920}]}]}
{"op":"mcm","clk":"11986132955","pt":1724918716579,"mc":[{"id":"1.232283786","rc":[{"batb":[[0,1.69,5],[1,1.68,5.67],[2,1.3,5.83]],"ltp":1.8,"tv":107.16,"id":35736920}]}]}
{"op":"mcm","clk":"11986133091","pt":1724918720014,"mc":[{"id":"1.232283786","rc":[{"batb":[[0,1.68,5.67],[1,1.3,5.83],[2,1.2,1000]],"ltp":1.8,"tv":107.16,"id":35736920}]}]}
{"op":"mcm","clk":"11986133191","pt":1724918722674,"mc":[{"id":"1.232283786","rc":[{"batb":[[0,1.69,5],[1,1.68,5.67],[2,1.3,5.83]],"ltp":1.8,"tv":107.16,"id":35736920}]}]}
{"op":"mcm","clk":"11986133345","pt":1724918726001,"mc":[{"id":"1.232283786","rc":[{"batb":[[0,1.68,5.67],[1,1.3,5.83],[2,1.2,1000]],"ltp":1.8,"tv":107.16,"id":35736920}]}]}
{"op":"mcm","clk":"11986133559","pt":1724918730808,"mc":[{"id":"1.232283786","rc":[{"batb":[[0,1.69,5],[1,1.68,5.67],[2,1.3,5.83]],"ltp":1.8,"tv":107.16,"id":35736920}]}]}
{"op":"mcm","clk":"11986133701","pt":1724918734126,"mc":[{"id":"1.232283786","rc":[{"batb":[[0,1.68,5.67],[1,1.3,5.83],[2,1.2,1000]],"ltp":1.8,"tv":107.16,"id":35736920}]}]}
{"op":"mcm","clk":"11986133825","pt":1724918736631,"mc":[{"id":"1.232283786","rc":[{"batb":[[0,1.69,5],[1,1.68,5.67],[2,1.3,5.83]],"ltp":1.8,"tv":107.16,"id":35736920}]}]}
{"op":"mcm","clk":"11986133990","pt":1724918740004,"mc":[{"id":"1.232283786","rc":[{"batb":[[0,1.68,5.67],[1,1.3,5.83],[2,1.2,1000]],"ltp":1.8,"tv":107.16,"id":35736920}]}]}
{"op":"mcm","clk":"11986134101","pt":1724918743125,"mc":[{"id":"1.232283786","rc":[{"batb":[[0,1.69,5],[1,1.68,5.67],[2,1.3,5.83]],"ltp":1.8,"tv":107.16,"id":35736920}]}]}
{"op":"mcm","clk":"11986134239","pt":1724918746636,"mc":[{"id":"1.232283786","rc":[{"batb":[[0,1.68,5.67],[1,1.3,5.83],[2,1.2,1000]],"ltp":1.8,"tv":107.16,"id":35736920}]}]}
{"op":"mcm","clk":"11986134331","pt":1724918749039,"mc":[{"id":"1.232283786","rc":[{"batb":[[0,1.69,5],[1,1.68,5.67],[2,1.3,5.83]],"ltp":1.8,"tv":107.16,"id":35736920}]}]}
{"op":"mcm","clk":"11986134514","pt":1724918752367,"mc":[{"id":"1.232283786","rc":[{"batb":[[0,1.68,5.67],[1,1.3,5.83],[2,1.2,1000]],"ltp":1.8,"tv":107.16,"id":35736920}]}]}
{"op":"mcm","clk":"11986134656","pt":1724918756046,"mc":[{"id":"1.232283786","rc":[{"batb":[[0,1.69,5],[1,1.68,5.67],[2,1.3,5.83]],"ltp":1.8,"tv":107.16,"id":35736920}]}]}
{"op":"mcm","clk":"11986134786","pt":1724918759471,"mc":[{"id":"1.232283786","rc":[{"batb":[[0,1.68,5.67],[1,1.3,5.83],[2,1.2,1000]],"ltp":1.8,"tv":107.16,"id":35736920}]}]}
{"op":"mcm","clk":"11986134910","pt":1724918761925,"mc":[{"id":"1.232283786","rc":[{"batb":[[0,1.69,5],[1,1.68,5.67],[2,1.3,5.83]],"ltp":1.8,"tv":107.16,"id":35736920}]}]}
{"op":"mcm","clk":"11986135094","pt":1724918765261,"mc":[{"id":"1.232283786","rc":[{"batb":[[0,1.68,5.67],[1,1.3,5.83],[2,1.2,1000]],"ltp":1.8,"tv":107.16,"id":35736920}]}]}
{"op":"mcm","clk":"11986135235","pt":1724918768236,"mc":[{"id":"1.232283786","rc":[{"batb":[[0,1.69,5],[1,1.68,5.67],[2,1.3,5.83]],"ltp":1.8,"tv":107.16,"id":35736920}]}]}
{"op":"mcm","clk":"11986135402","pt":1724918771466,"mc":[{"id":"1.232283786","rc":[{"batb":[[0,1.68,5.67],[1,1.3,5.83],[2,1.2,1000]],"ltp":1.8,"tv":107.16,"id":35736920}]}]}
{"op":"mcm","clk":"11986135596","pt":1724918775820,"mc":[{"id":"1.232283786","rc":[{"batb":[[0,1.69,5],[1,1.68,5.67],[2,1.3,5.83]],"ltp":1.8,"tv":107.16,"id":35736920}]}]}
{"op":"mcm","clk":"11986135743","pt":1724918779296,"mc":[{"id":"1.232283786","rc":[{"batb":[[0,1.68,5.67],[1,1.3,5.83],[2,1.2,1000]],"ltp":1.8,"tv":107.16,"id":35736920}]}]}
{"op":"mcm","clk":"11986135859","pt":1724918782265,"mc":[{"id":"1.232283786","rc":[{"batb":[[0,1.69,5],[1,1.68,5.67],[2,1.3,5.83]],"ltp":1.8,"tv":107.16,"id":35736920}]}]}
{"op":"mcm","clk":"11986136037","pt":1724918785689,"mc":[{"id":"1.232283786","rc":[{"batb":[[0,1.68,5.67],[1,1.3,5.83],[2,1.2,1000]],"ltp":1.8,"tv":107.16,"id":35736920}]}]}
{"op":"mcm","clk":"11986136147","pt":1724918788193,"mc":[{"id":"1.232283786","rc":[{"batb":[[0,1.69,5],[1,1.68,5.67],[2,1.3,5.83]],"ltp":1.8,"tv":107.16,"id":35736920}]}]}
{"op":"mcm","clk":"11986136307","pt":1724918791574,"mc":[{"id":"1.232283786","rc":[{"batb":[[0,1.68,5.67],[1,1.3,5.83],[2,1.2,1000]],"ltp":1.8,"tv":107.16,"id":35736920}]}]}
{"op":"mcm","clk":"11986136614","pt":1724918798575,"mc":[{"id":"1.232283786","rc":[{"batb":[[0,1.69,5],[1,1.68,5.67],[2,1.3,5.83]],"ltp":1.8,"tv":107.16,"id":35736920}]}]}
{"op":"mcm","clk":"11986136761","pt":1724918801906,"mc":[{"id":"1.232283786","rc":[{"batb":[[0,1.68,5.67],[1,1.3,5.83],[2,1.2,1000]],"ltp":1.8,"tv":107.16,"id":35736920}]}]}
{"op":"mcm","clk":"11986136924","pt":1724918805315,"mc":[{"id":"1.232283786","rc":[{"batb":[[0,1.69,5],[1,1.68,5.67],[2,1.3,5.83]],"ltp":1.8,"tv":107.16,"id":35736920}]}]}
{"op":"mcm","clk":"11986137068","pt":1724918808598,"mc":[{"id":"1.232283786","rc":[{"batb":[[0,1.68,5.67],[1,1.3,5.83],[2,1.2,1000]],"ltp":1.8,"tv":107.16,"id":35736920}]}]}
{"op":"mcm","clk":"11986137357","pt":1724918814644,"mc":[{"id":"1.232283786","rc":[{"batb":[[0,1.69,5],[1,1.68,5.67],[2,1.3,5.83]],"ltp":1.8,"tv":107.16,"id":35736920}]}]}
{"op":"mcm","clk":"11986137519","pt":1724918818022,"mc":[{"id":"1.232283786","rc":[{"batb":[[0,1.68,5.67],[1,1.3,5.83],[2,1.2,1000]],"ltp":1.8,"tv":107.16,"id":35736920}]}]}
{"op":"mcm","clk":"11986137747","pt":1724918822638,"mc":[{"id":"1.232283786","rc":[{"batb":[[0,1.69,5],[1,1.68,5.67],[2,1.3,5.83]],"ltp":1.8,"tv":107.16,"id":35736920}]}]}
{"op":"mcm","clk":"11986137912","pt":1724918825930,"mc":[{"id":"1.232283786","rc":[{"batb":[[0,1.68,5.67],[1,1.3,5.83],[2,1.2,1000]],"ltp":1.8,"tv":107.16,"id":35736920}]}]}
{"op":"mcm","clk":"11986138270","pt":1724918831724,"mc":[{"id":"1.232283786","rc":[{"batb":[[0,1.69,5],[1,1.68,5.67],[2,1.3,5.83]],"ltp":1.8,"tv":107.16,"id":35736920}]}]}
{"op":"mcm","clk":"11986138472","pt":1724918835259,"mc":[{"id":"1.232283786","rc":[{"batb":[[0,1.68,5.67],[1,1.3,5.83],[2,1.2,1000]],"ltp":1.8,"tv":107.16,"id":35736920}]}]}
{"op":"mcm","clk":"11986138653","pt":1724918838842,"mc":[{"id":"1.232283786","rc":[{"batb":[[0,1.69,5],[1,1.68,5.67],[2,1.3,5.83]],"ltp":1.8,"tv":107.16,"id":35736920}]}]}
{"op":"mcm","clk":"11986138808","pt":1724918842070,"mc":[{"id":"1.232283786","rc":[{"batb":[[0,1.68,5.67],[1,1.3,5.83],[2,1.2,1000]],"ltp":1.8,"tv":107.16,"id":35736920}]}]}
{"op":"mcm","clk":"11986138912","pt":1724918844677,"mc":[{"id":"1.232283786","rc":[{"batb":[[0,1.69,5],[1,1.68,5.67],[2,1.3,5.83]],"ltp":1.8,"tv":107.16,"id":35736920}]}]}
{"op":"mcm","clk":"11986139112","pt":1724918848159,"mc":[{"id":"1.232283786","rc":[{"batb":[[0,1.68,5.67],[1,1.3,5.83],[2,1.2,1000]],"ltp":1.8,"tv":107.16,"id":35736920}]}]}
{"op":"mcm","clk":"11986139213","pt":1724918850352,"mc":[{"id":"1.232283786","rc":[{"batb":[[0,1.69,5],[1,1.68,5.67],[2,1.3,5.83]],"ltp":1.8,"tv":107.16,"id":35736920}]}]}
{"op":"mcm","clk":"11986139382","pt":1724918853984,"mc":[{"id":"1.232283786","rc":[{"batb":[[0,1.68,5.67],[1,1.3,5.83],[2,1.2,1000]],"ltp":1.8,"tv":107.16,"id":35736920}]}]}
{"op":"mcm","clk":"11986140049","pt":1724918867666,"mc":[{"id":"1.232283786","rc":[{"batb":[[0,1.69,5],[1,1.68,5.67],[2,1.3,5.83]],"ltp":1.8,"tv":107.16,"id":35736920}]}]}
{"op":"mcm","clk":"11986140248","pt":1724918871203,"mc":[{"id":"1.232283786","rc":[{"batb":[[0,1.68,5.67],[1,1.3,5.83],[2,1.2,1000]],"ltp":1.8,"tv":107.16,"id":35736920}]}]}
{"op":"mcm","clk":"11986140383","pt":1724918873414,"mc":[{"id":"1.232283786","rc":[{"batb":[[0,1.69,5],[1,1.68,5.67],[2,1.3,5.83]],"ltp":1.8,"tv":107.16,"id":35736920}]}]}
{"op":"mcm","clk":"11986140542","pt":1724918876685,"mc":[{"id":"1.232283786","rc":[{"batb":[[0,1.68,5.67],[1,1.3,5.83],[2,1.2,1000]],"ltp":1.8,"tv":107.16,"id":35736920}]}]}
{"op":"mcm","clk":"11986140811","pt":1724918882926,"mc":[{"id":"1.232283786","rc":[{"batb":[[0,1.69,5],[1,1.68,5.67],[2,1.3,5.83]],"ltp":1.8,"tv":107.16,"id":35736920}]}]}
{"op":"mcm","clk":"11986140979","pt":1724918886105,"mc":[{"id":"1.232283786","rc":[{"batb":[[0,1.68,5.67],[1,1.3,5.83],[2,1.2,1000]],"ltp":1.8,"tv":107.16,"id":35736920}]}]}
{"op":"mcm","clk":"11986141081","pt":1724918888603,"mc":[{"id":"1.232283786","rc":[{"batb":[[0,1.69,5],[1,1.68,5.67],[2,1.3,5.83]],"ltp":1.8,"tv":107.16,"id":35736920},{"batl":[[0,5.9,10.09]],"ltp":2.26,"tv":5.93,"id":11445383}]}]}
{"op":"mcm","clk":"11986141241","pt":1724918891931,"mc":[{"id":"1.232283786","rc":[{"batb":[[0,1.68,5.67],[1,1.3,5.83],[2,1.2,1000]],"ltp":1.8,"tv":107.16,"id":35736920}]}]}
{"op":"mcm","clk":"11986141424","pt":1724918896220,"mc":[{"id":"1.232283786","rc":[{"batb":[[0,1.69,5],[1,1.68,5.67],[2,1.3,5.83]],"ltp":1.8,"tv":107.16,"id":35736920}]}]}
{"op":"mcm","clk":"11986141609","pt":1724918899598,"mc":[{"id":"1.232283786","rc":[{"batb":[[0,1.68,5.67],[1,1.3,5.83],[2,1.2,1000]],"ltp":1.8,"tv":107.16,"id":35736920}]}]}
{"op":"mcm","clk":"11986141800","pt":1724918903635,"mc":[{"id":"1.232283786","rc":[{"batb":[[0,1.69,5],[1,1.68,5.67],[2,1.3,5.83]],"ltp":1.8,"tv":107.16,"id":35736920}]}]}
{"op":"mcm","clk":"11986141968","pt":1724918907238,"mc":[{"id":"1.232283786","rc":[{"batb":[[0,1.68,5.67],[1,1.3,5.83],[2,1.2,1000]],"ltp":1.8,"tv":107.16,"id":35736920}]}]}
{"op":"mcm","clk":"11986142120","pt":1724918910251,"mc":[{"id":"1.232283786","rc":[{"batb":[[0,1.69,5],[1,1.68,5.67],[2,1.3,5.83]],"ltp":1.8,"tv":107.16,"id":35736920}]}]}
{"op":"mcm","clk":"11986142265","pt":1724918913539,"mc":[{"id":"1.232283786","rc":[{"batb":[[0,1.68,5.67],[1,1.3,5.83],[2,1.2,1000]],"ltp":1.8,"tv":107.16,"id":35736920}]}]}
{"op":"mcm","clk":"11986142416","pt":1724918916121,"mc":[{"id":"1.232283786","rc":[{"batb":[[0,1.69,5],[1,1.68,5.67],[2,1.3,5.83]],"ltp":1.8,"tv":107.16,"id":35736920}]}]}
{"op":"mcm","clk":"11986142563","pt":1724918919523,"mc":[{"id":"1.232283786","rc":[{"batb":[[0,1.68,5.67],[1,1.3,5.83],[2,1.2,1000]],"ltp":1.8,"tv":107.16,"id":35736920}]}]}
{"op":"mcm","clk":"11986142716","pt":1724918923251,"mc":[{"id":"1.232283786","rc":[{"batb":[[0,1.69,5],[1,1.68,5.67],[2,1.3,5.83]],"ltp":1.8,"tv":107.16,"id":35736920}]}]}
{"op":"mcm","clk":"11986142856","pt":1724918926475,"mc":[{"id":"1.232283786","rc":[{"batb":[[0,1.68,5.67],[1,1.3,5.83],[2,1.2,1000]],"ltp":1.8,"tv":107.16,"id":35736920}]}]}
{"op":"mcm","clk":"11986142997","pt":1724918929237,"mc":[{"id":"1.232283786","rc":[{"batb":[[0,1.69,5],[1,1.68,5.67],[2,1.3,5.83]],"ltp":1.8,"tv":107.16,"id":35736920}]}]}
{"op":"mcm","clk":"11986143141","pt":1724918932556,"mc":[{"id":"1.232283786","rc":[{"batb":[[0,1.68,5.67],[1,1.3,5.83],[2,1.2,1000]],"ltp":1.8,"tv":107.16,"id":35736920}]}]}
{"op":"mcm","clk":"11986143337","pt":1724918937396,"mc":[{"id":"1.232283786","rc":[{"batb":[[0,1.69,5],[1,1.68,5.67],[2,1.3,5.83]],"ltp":1.8,"tv":107.16,"id":35736920}]}]}
{"op":"mcm","clk":"11986143433","pt":1724918940559,"mc":[{"id":"1.232283786","rc":[{"batb":[[0,1.68,5.67],[1,1.3,5.83],[2,1.2,1000]],"ltp":1.8,"tv":107.16,"id":35736920}]}]}
{"op":"mcm","clk":"11986143531","pt":1724918943067,"mc":[{"id":"1.232283786","rc":[{"batb":[[0,1.69,5],[1,1.68,5.67],[2,1.3,5.83]],"ltp":1.8,"tv":107.16,"id":35736920}]}]}
{"op":"mcm","clk":"11986143654","pt":1724918946403,"mc":[{"id":"1.232283786","rc":[{"batb":[[0,1.68,5.67],[1,1.3,5.83],[2,1.2,1000]],"ltp":1.8,"tv":107.16,"id":35736920}]}]}
{"op":"mcm","clk":"11986143751","pt":1724918949008,"mc":[{"id":"1.232283786","rc":[{"batb":[[0,1.69,5],[1,1.68,5.67],[2,1.3,5.83]],"ltp":1.8,"tv":107.16,"id":35736920}]}]}
{"op":"mcm","clk":"11986143899","pt":1724918952382,"mc":[{"id":"1.232283786","rc":[{"batb":[[0,1.68,5.67],[1,1.3,5.83],[2,1.2,1000]],"ltp":1.8,"tv":107.16,"id":35736920}]}]}
{"op":"mcm","clk":"11986144010","pt":1724918955098,"mc":[{"id":"1.232283786","rc":[{"batb":[[0,1.69,5],[1,1.68,5.67],[2,1.3,5.83]],"ltp":1.8,"tv":107.16,"id":35736920}]}]}
{"op":"mcm","clk":"11986144146","pt":1724918958376,"mc":[{"id":"1.232283786","rc":[{"batb":[[0,1.68,5.67],[1,1.3,5.83],[2,1.2,1000]],"ltp":1.8,"tv":107.16,"id":35736920}]}]}
{"op":"mcm","clk":"11986144329","pt":1724918962477,"mc":[{"id":"1.232283786","rc":[{"batb":[[0,1.69,5],[1,1.68,5.67],[2,1.3,5.83]],"ltp":1.8,"tv":107.16,"id":35736920}]}]}
{"op":"mcm","clk":"11986144517","pt":1724918965702,"mc":[{"id":"1.232283786","rc":[{"batb":[[0,1.68,5.67],[1,1.3,5.83],[2,1.2,1000]],"ltp":1.8,"tv":107.16,"id":35736920}]}]}
{"op":"mcm","clk":"11986144752","pt":1724918971478,"mc":[{"id":"1.232283786","rc":[{"batb":[[0,1.69,5],[1,1.68,5.67],[2,1.3,5.83]],"ltp":1.8,"tv":107.16,"id":35736920}]}]}
{"op":"mcm","clk":"11986144897","pt":1724918974807,"mc":[{"id":"1.232283786","rc":[{"batb":[[0,1.68,5.67],[1,1.3,5.83],[2,1.2,1000]],"ltp":1.8,"tv":107.16,"id":35736920}]}]}
{"op":"mcm","clk":"11986144989","pt":1724918977214,"mc":[{"id":"1.232283786","rc":[{"batb":[[0,1.69,5],[1,1.68,5.67],[2,1.3,5.83]],"ltp":1.8,"tv":107.16,"id":35736920}]}]}
{"op":"mcm","clk":"11986145158","pt":1724918980496,"mc":[{"id":"1.232283786","rc":[{"batb":[[0,1.68,5.67],[1,1.3,5.83],[2,1.2,1000]],"ltp":1.8,"tv":107.16,"id":35736920}]}]}
{"op":"mcm","clk":"11986145273","pt":1724918983608,"mc":[{"id":"1.232283786","rc":[{"batb":[[0,1.69,5],[1,1.68,5.67],[2,1.3,5.83]],"ltp":1.8,"tv":107.16,"id":35736920}]}]}
{"op":"mcm","clk":"11986145420","pt":1724918987044,"mc":[{"id":"1.232283786","rc":[{"batb":[[0,1.68,5.67],[1,1.3,5.83],[2,1.2,1000]],"ltp":1.8,"tv":107.16,"id":35736920}]}]}
{"op":"mcm","clk":"11986145598","pt":1724918991041,"mc":[{"id":"1.232283786","rc":[{"batb":[[0,1.69,5],[1,1.68,5.67],[2,1.3,5.83]],"ltp":1.8,"tv":107.16,"id":35736920}]}]}
{"op":"mcm","clk":"11986145768","pt":1724918994320,"mc":[{"id":"1.232283786","rc":[{"batb":[[0,1.68,5.67],[1,1.3,5.83],[2,1.2,1000]],"ltp":1.8,"tv":107.16,"id":35736920}]}]}
{"op":"mcm","clk":"11986145899","pt":1724918996934,"mc":[{"id":"1.232283786","rc":[{"batb":[[0,1.69,5],[1,1.68,5.67],[2,1.3,5.83]],"ltp":1.8,"tv":107.16,"id":35736920}]}]}
{"op":"mcm","clk":"11986146066","pt":1724919000360,"mc":[{"id":"1.232283786","rc":[{"batb":[[0,1.68,5.67],[1,1.3,5.83],[2,1.2,1000]],"ltp":1.8,"tv":107.16,"id":35736920}]}]}
{"op":"mcm","clk":"11986146526","pt":1724919009559,"mc":[{"id":"1.232283786","rc":[{"batb":[[0,1.69,5],[1,1.68,5.67],[2,1.3,5.83]],"ltp":1.8,"tv":107.16,"id":35736920}]}]}
{"op":"mcm","clk":"11986146706","pt":1724919012943,"mc":[{"id":"1.232283786","rc":[{"batb":[[0,1.68,5.67],[1,1.3,5.83],[2,1.2,1000]],"ltp":1.8,"tv":107.16,"id":35736920}]}]}
{"op":"mcm","clk":"11986146853","pt":1724919016376,"mc":[{"id":"1.232283786","rc":[{"batb":[[0,1.69,5],[1,1.68,5.67],[2,1.3,5.83]],"ltp":1.8,"tv":107.16,"id":35736920}]}]}
{"op":"mcm","clk":"11986147026","pt":1724919019862,"mc":[{"id":"1.232283786","rc":[{"batb":[[0,1.68,5.67],[1,1.3,5.83],[2,1.2,1000]],"batl":[[0,1.84,10],[1,5.9,10.07]],"ltp":1.8,"tv":107.16,"id":35736920}]}]}
{"op":"mcm","clk":"11986147109","pt":1724919021752,"mc":[{"id":"1.232283786","rc":[{"batl":[[1,5.9,0]],"ltp":1.8,"tv":107.16,"id":35736920}]}]}
{"op":"mcm","clk":"11986166058","pt":1724919191769,"mc":[{"id":"1.232283786","rc":[{"batl":[[0,5.9,10.09]],"ltp":2.26,"tv":5.93,"id":11445383}]}]}
{"op":"mcm","clk":"11986396325","pt":1724923804914,"mc":[{"id":"1.232283786","rc":[{"trd":[[1.68,99.63]],"batb":[[0,1.68,56.79],[1,1.3,5.85]],"ltp":1.8,"tv":107.31,"id":35736920},{"batb":[[0,2.2,5],[1,2.18,32.72],[2,1.2,1000]],"ltp":2.26,"tv":5.93,"id":11445383}],"tv":113.25}]}
{"op":"mcm","clk":"11986396486","pt":1724923807903,"mc":[{"id":"1.232283786","rc":[{"batb":[[0,2.18,32.72],[1,1.2,1000],[2,1.04,1.05]],"ltp":2.26,"tv":5.93,"id":11445383}]}]}
{"op":"mcm","clk":"11986696378","pt":1724927577692,"mc":[{"id":"1.232283786","rc":[{"trd":[[1.68,99.81]],"batl":[[0,1.84,10.88]],"ltp":1.8,"tv":107.5,"id":35736920}],"tv":113.44}]}
{"op":"mcm","clk":"11986697122","pt":1724927586706,"mc":[{"id":"1.232283786","rc":[{"batb":[[0,1.68,57.67]],"ltp":1.8,"tv":107.5,"id":35736920}]}]}
{"op":"mcm","clk":"11986880641","pt":1724929974788,"mc":[{"id":"1.232283786","rc":[{"trd":[[1.68,99.8]],"batb":[[1,1.3,5.85]],"ltp":1.8,"tv":107.48,"id":35736920}],"tv":113.42}]}
{"op":"mcm","clk":"11987128459","pt":1724933250917,"mc":[{"id":"1.232283786","rc":[{"trd":[[1.68,99.84]],"batb":[[1,1.3,5.85],[2,1.04,1.05]],"ltp":1.8,"tv":107.53,"id":35736920},{"batb":[[1,1.04,1.05],[2,1.03,200]],"ltp":2.26,"tv":5.93,"id":11445383}],"tv":113.47}]}
{"op":"mcm","clk":"11987136429","pt":1724933358875,"mc":[{"id":"1.232283786","rc":[{"batb":[[1,1.3,712.52]],"ltp":1.8,"tv":107.53,"id":35736920}]}]}
{"op":"mcm","clk":"11987136793","pt":1724933363702,"mc":[{"id":"1.232283786","rc":[{"batb":[[1,1.21,1009.52],[2,1.04,1.05]],"ltp":2.26,"tv":5.93,"id":11445383}]}]}
{"op":"mcm","clk":"11987217294","pt":1724934330789,"mc":[{"id":"1.232283786","rc":[{"batb":[[0,1.68,56.79]],"ltp":1.8,"tv":107.53,"id":35736920}]}]}
{"op":"mcm","clk":"11987217609","pt":1724934334680,"mc":[{"id":"1.232283786","rc":[{"batl":[[0,1.84,10]],"ltp":1.8,"tv":107.53,"id":35736920}]}]}
{"op":"mcm","clk":"11987539022","pt":1724938517453,"mc":[{"id":"1.232283786","rc":[{"trd":[[1.68,99.79]],"batb":[[0,1.68,65.06],[1,1.3,712.53]],"ltp":1.8,"tv":107.47,"id":35736920},{"batb":[[0,2.18,37.49]],"ltp":2.26,"tv":5.93,"id":11445383}],"tv":113.41}]}
{"op":"mcm","clk":"11987710188","pt":1724940774793,"mc":[{"id":"1.232283786","rc":[{"trd":[[1.68,99.61]],"ltp":1.8,"tv":107.29,"id":35736920}],"tv":113.23}]}
{"op":"mcm","clk":"11987821336","pt":1724942165749,"mc":[{"id":"1.232283786","rc":[{"batb":[[1,1.3,711.6]],"ltp":1.8,"tv":107.29,"id":35736920}]}]}
{"op":"mcm","clk":"11987821660","pt":1724942169727,"mc":[{"id":"1.232283786","rc":[{"batb":[[1,1.3,706.67]],"ltp":1.8,"tv":107.29,"id":35736920}]}]}
{"op":"mcm","clk":"11988213187","pt":1724946174788,"mc":[{"id":"1.232283786","rc":[{"trd":[[1.68,99.68]],"ltp":1.8,"tv":107.36,"id":35736920}],"tv":113.3}]}
{"op":"mcm","clk":"11988920669","pt":1724951574828,"mc":[{"id":"1.232283786","rc":[{"trd":[[1.68,99.64]],"ltp":1.8,"tv":107.32,"id":35736920}],"tv":113.26}]}
{"op":"mcm","clk":"11988980107","pt":1724951887696,"mc":[{"id":"1.232283786","rc":[{"batb":[[1,1.3,707.11]],"ltp":1.8,"tv":107.32,"id":35736920}]}]}
{"op":"mcm","clk":"11988994213","pt":1724951961901,"mc":[{"id":"1.232283786","rc":[{"batb":[[1,1.3,707.3]],"ltp":1.8,"tv":107.32,"id":35736920}]}]}
{"op":"mcm","clk":"11989810188","pt":1724956974802,"mc":[{"id":"1.232283786","rc":[{"trd":[[1.68,99.71]],"ltp":1.8,"tv":107.39,"id":35736920}],"tv":113.33}]}
{"op":"mcm","clk":"11990585479","pt":1724962374817,"mc":[{"id":"1.232283786","rc":[{"trd":[[1.68,99.68]],"batb":[[1,1.3,707.31]],"ltp":1.8,"tv":107.37,"id":35736920}],"tv":113.31}]}
{"op":"mcm","clk":"11990683732","pt":1724963384352,"mc":[{"id":"1.232283786","rc":[{"batb":[[0,1.34,105.24],[1,1.3,706.67]],"ltp":1.8,"tv":107.37,"id":35736920},{"batb":[[0,1.21,1009.52],[1,1.04,1.05],[2,1.03,200]],"ltp":2.26,"tv":5.93,"id":11445383}]}]}
{"op":"mcm","clk":"11990734027","pt":1724964052267,"mc":[{"id":"1.232283786","rc":[{"batb":[[0,1.35,7.73],[1,1.34,104.6],[2,1.3,706.67]],"ltp":1.8,"tv":107.37,"id":35736920}]}]}
{"op":"mcm","clk":"11990782060","pt":1724964858400,"mc":[{"id":"1.232283786","rc":[{"batb":[[1,1.3,706.67],[2,1.04,1.05]],"ltp":1.8,"tv":107.37,"id":35736920}]}]}
{"op":"mcm","clk":"11990782065","pt":1724964858502,"mc":[{"id":"1.232283786","rc":[{"batb":[[0,1.36,103.69],[1,1.35,7.09],[2,1.3,706.67]],"ltp":1.8,"tv":107.37,"id":35736920}]}]}
{"op":"mcm","clk":"11990808353","pt":1724965390253,"mc":[{"id":"1.232283786","rc":[{"batb":[[0,1.68,65.06],[1,1.36,103.68],[2,1.35,7.09]],"ltp":1.8,"tv":107.37,"id":35736920},{"batb":[[0,2.34,33.01],[1,1.21,1009.52],[2,1.04,1.05]],"ltp":2.26,"tv":5.93,"id":11445383}]}]}
{"op":"mcm","clk":"11990815401","pt":1724965558562,"mc":[{"id":"1.232283786","rc":[{"batb":[[1,1.35,7.73],[2,1.3,706.67]],"ltp":1.8,"tv":107.37,"id":35736920}]}]}
{"op":"mcm","clk":"11990959849","pt":1724968157427,"mc":[{"id":"1.232283786","rc":[{"batb":[[1,1.3,707.3],[2,1.04,1.05]],"ltp":1.8,"tv":107.37,"id":35736920}]}]}
{"op":"mcm","clk":"11991242356","pt":1724973174816,"mc":[{"id":"1.232283786","rc":[{"trd":[[1.68,99.69]],"ltp":1.8,"tv":107.37,"id":35736920}],"tv":113.31}]}
{"op":"mcm","clk":"11991649932","pt":1724978574819,"mc":[{"id":"1.232283786","rc":[{"trd":[[1.68,99.66]],"ltp":1.8,"tv":107.35,"id":35736920}],"tv":113.29}]}
{"op":"mcm","clk":"11991991822","pt":1724983974830,"mc":[{"id":"1.232283786","rc":[{"trd":[[1.68,99.63]],"ltp":1.8,"tv":107.31,"id":35736920}],"tv":113.25}]}
{"op":"mcm","clk":"11992263044","pt":1724989374837,"mc":[{"id":"1.232283786","rc":[{"trd":[[1.68,99.74]],"ltp":1.8,"tv":107.42,"id":35736920}],"tv":113.36}]}
{"op":"mcm","clk":"11992462156","pt":1724993578420,"mc":[{"id":"1.232283786","rc":[{"trd":[[1.68,99.82],[1.75,4.85]],"ltp":1.75,"tv":108.51,"id":35736920},{"trd":[[2.34,3.63]],"batb":[[0,2.34,32.26]],"ltp":2.34,"tv":6.68,"id":11445383}],"tv":115.2}]}
{"op":"mcm","clk":"11992462283","pt":1724993582094,"mc":[{"id":"1.232283786","rc":[{"batb":[[0,2.34,33.01]],"ltp":2.34,"tv":6.68,"id":11445383}]}]}
{"op":"mcm","clk":"11992465593","pt":1724993686638,"mc":[{"id":"1.232283786","rc":[{"trd":[[1.68,101.3]],"batb":[[0,1.68,63.58]],"ltp":1.68,"tv":109.99,"id":35736920},{"trd":[[2.48,1]],"ltp":2.48,"tv":7.68,"id":11445383}],"tv":117.68}]}
{"op":"mcm","clk":"11992465623","pt":1724993687513,"mc":[{"id":"1.232283786","rc":[{"batb":[[0,1.68,65.06]],"ltp":1.68,"tv":109.99,"id":35736920}]}]}
{"op":"mcm","clk":"11992513993","pt":1724994774836,"mc":[{"id":"1.232283786","rc":[{"trd":[[1.68,101.21]],"ltp":1.68,"tv":109.9,"id":35736920}],"tv":117.59}]}
{"op":"mcm","clk":"11992783784","pt":1725000174818,"mc":[{"id":"1.232283786","rc":[{"trd":[[1.68,101.24]],"ltp":1.68,"tv":109.93,"id":35736920}],"tv":117.62}]}
{"op":"mcm","clk":"11992972704","pt":1725003779401,"mc":[{"id":"1.232283786","rc":[{"trd":[[1.68,103.16]],"batb":[[0,1.68,64.06]],"ltp":1.68,"tv":111.85,"id":35736920}],"tv":119.54}]}
{"op":"mcm","clk":"11992972725","pt":1725003779712,"mc":[{"id":"1.232283786","rc":[{"batb":[[0,1.68,65.06]],"ltp":1.68,"tv":111.85,"id":35736920}]}]}
{"op":"mcm","clk":"11993058705","pt":1725005574821,"mc":[{"id":"1.232283786","rc":[{"trd":[[1.68,103.14]],"ltp":1.68,"tv":111.82,"id":35736920}],"tv":119.51}]}
{"op":"mcm","clk":"11993410386","pt":1725010974833,"mc":[{"id":"1.232283786","rc":[{"trd":[[1.68,103.18]],"ltp":1.68,"tv":111.86,"id":35736920}],"tv":119.55}]}
{"op":"mcm","clk":"11993458697","pt":1725011475348,"mc":[{"id":"1.232283786","rc":[{"batb":[[1,1.04,1.68],[2,1.03,200]],"ltp":1.68,"tv":111.86,"id":35736920},{"batb":[[1,1.04,1.05],[2,1.03,200]],"ltp":2.48,"tv":7.68,"id":11445383}]}]}
{"op":"mcm","clk":"11993466978","pt":1725011553400,"mc":[{"id":"1.232283786","rc":[{"batb":[[1,1.2,665.63],[2,1.04,1.05]],"ltp":1.68,"tv":111.86,"id":35736920},{"batb":[[1,1.2,665],[2,1.04,1.05]],"ltp":2.48,"tv":7.68,"id":11445383}]}]}
{"op":"mcm","clk":"11993811378","pt":1725016374822,"mc":[{"id":"1.232283786","rc":[{"trd":[[1.68,103.13]],"ltp":1.68,"tv":111.82,"id":35736920}],"tv":119.51}]}
{"op":"mcm","clk":"11994285324","pt":1725021774835,"mc":[{"id":"1.232283786","rc":[{"trd":[[1.68,103.07]],"ltp":1.68,"tv":111.76,"id":35736920}],"tv":119.45}]}
{"op":"mcm","clk":"11994356292","pt":1725022339768,"mc":[{"id":"1.232283786","rc":[{"batb":[[1,1.2,665]],"ltp":1.68,"tv":111.76,"id":35736920}]}]}
{"op":"mcm","clk":"11994643877","pt":1725024913676,"mc":[{"id":"1.232283786","rc":[{"trd":[[1.68,103.05]],"batb":[[0,1.68,63.86]],"ltp":1.68,"tv":111.73,"id":35736920},{"batb":[[0,2.34,32.41]],"ltp":2.48,"tv":7.68,"id":11445383}],"tv":119.42}]}
{"op":"mcm","clk":"11994902674","pt":1725027174845,"mc":[{"id":"1.232283786","rc":[{"trd":[[1.68,103.09]],"ltp":1.68,"tv":111.77,"id":35736920}],"tv":119.46}]}
{"op":"mcm","clk":"11995023993","pt":1725028139410,"mc":[{"id":"1.232283786","rc":[{"batb":[[1,1.04,1.05],[2,1.03,200]],"ltp":1.68,"tv":111.77,"id":35736920},{"batb":[[1,1.04,1.05],[2,1.03,200]],"ltp":2.48,"tv":7.68,"id":11445383}]}]}
{"op":"mcm","clk":"11995030160","pt":1725028194272,"mc":[{"id":"1.232283786","rc":[{"batb":[[1,1.1,2000],[2,1.04,1.05]],"ltp":1.68,"tv":111.77,"id":35736920}]}]}
{"op":"mcm","clk":"11995030465","pt":1725028197590,"mc":[{"id":"1.232283786","rc":[{"batb":[[1,1.04,1.05],[2,1.03,200]],"ltp":1.68,"tv":111.77,"id":35736920}]}]}
{"op":"mcm","clk":"11995032228","pt":1725028211306,"mc":[{"id":"1.232283786","rc":[{"batb":[[2,1.03,1033.33]],"ltp":1.68,"tv":111.77,"id":35736920}]}]}
{"op":"mcm","clk":"11995032354","pt":1725028212302,"mc":[{"id":"1.232283786","rc":[{"batb":[[1,1.04,626.05]],"ltp":1.68,"tv":111.77,"id":35736920}]}]}
{"op":"mcm","clk":"11995032938","pt":1725028217012,"mc":[{"id":"1.232283786","rc":[{"batb":[[2,1.03,1033.33]],"ltp":2.48,"tv":7.68,"id":11445383}]}]}
{"op":"mcm","clk":"11995033063","pt":1725028217802,"mc":[{"id":"1.232283786","rc":[{"batb":[[1,1.04,626.05]],"ltp":2.48,"tv":7.68,"id":11445383}]}]}
{"op":"mcm","clk":"11995040885","pt":1725028282474,"mc":[{"id":"1.232283786","rc":[{"batb":[[1,1.05,1000],[2,1.04,626.05]],"ltp":1.68,"tv":111.77,"id":35736920}]}]}
{"op":"mcm","clk":"11995041076","pt":1725028284089,"mc":[{"id":"1.232283786","rc":[{"batb":[[1,1.1,500],[2,1.05,1000]],"ltp":1.68,"tv":111.77,"id":35736920}]}]}
{"op":"mcm","clk":"11995041392","pt":1725028286983,"mc":[{"id":"1.232283786","rc":[{"batb":[[1,1.05,1000],[2,1.04,626.05]],"ltp":2.48,"tv":7.68,"id":11445383}]}]}
{"op":"mcm","clk":"11995041502","pt":1725028287906,"mc":[{"id":"1.232283786","rc":[{"batb":[[1,1.1,500],[2,1.05,1000]],"ltp":2.48,"tv":7.68,"id":11445383}]}]}
{"op":"mcm","clk":"11995048452","pt":1725028341637,"mc":[{"id":"1.232283786","rc":[{"batb":[[1,1.05,1000],[2,1.04,626.05]],"ltp":1.68,"tv":111.77,"id":35736920}]}]}
{"op":"mcm","clk":"11995048610","pt":1725028342824,"mc":[{"id":"1.232283786","rc":[{"batb":[[1,1.04,626.05],[2,1.03,1033.33]],"ltp":1.68,"tv":111.77,"id":35736920}]}]}
{"op":"mcm","clk":"11995048796","pt":1725028344321,"mc":[{"id":"1.232283786","rc":[{"batb":[[1,1.05,500],[2,1.04,626.05]],"ltp":1.68,"tv":111.77,"id":35736920}]}]}
{"op":"mcm","clk":"11995048948","pt":1725028345556,"mc":[{"id":"1.232283786","rc":[{"batb":[[1,1.06,416.67],[2,1.05,500]],"ltp":1.68,"tv":111.77,"id":35736920}]}]}
{"op":"mcm","clk":"11995049082","pt":1725028346643,"mc":[{"id":"1.232283786","rc":[{"batb":[[1,1.08,312.5],[2,1.06,416.67]],"ltp":1.68,"tv":111.77,"id":35736920}]}]}
{"op":"mcm","clk":"11995049181","pt":1725028347466,"mc":[{"id":"1.232283786","rc":[{"batb":[[1,1.1,250],[2,1.08,312.5]],"ltp":1.68,"tv":111.77,"id":35736920}]}]}
{"op":"mcm","clk":"11995049665","pt":1725028351145,"mc":[{"id":"1.232283786","rc":[{"batb":[[1,1.05,1000],[2,1.04,626.05]],"ltp":2.48,"tv":7.68,"id":11445383}]}]}
{"op":"mcm","clk":"11995049808","pt":1725028352233,"mc":[{"id":"1.232283786","rc":[{"batb":[[1,1.04,626.05],[2,1.03,1033.33]],"ltp":2.48,"tv":7.68,"id":11445383}]}]}
{"op":"mcm","clk":"11995050043","pt":1725028354256,"mc":[{"id":"1.232283786","rc":[{"batb":[[1,1.06,416.67],[2,1.05,500]],"ltp":2.48,"tv":7.68,"id":11445383}]}]}
{"op":"mcm","clk":"11995050184","pt":1725028355074,"mc":[{"id":"1.232283786","rc":[{"batb":[[1,1.08,312.5],[2,1.06,416.67]],"ltp":2.48,"tv":7.68,"id":11445383}]}]}
{"op":"mcm","clk":"11995050315","pt":1725028356164,"mc":[{"id":"1.232283786","rc":[{"batb":[[1,1.1,250],[2,1.08,312.5]],"ltp":2.48,"tv":7.68,"id":11445383}]}]}
{"op":"mcm","clk":"11995051947","pt":1725028368699,"mc":[{"id":"1.232283786","rc":[{"batb":[[1,1.15,1333.33],[2,1.1,250]],"ltp":1.68,"tv":111.77,"id":35736920}]}]}
{"op":"mcm","clk":"11995052155","pt":1725028370207,"mc":[{"id":"1.232283786","rc":[{"batb":[[1,1.25,800],[2,1.15,1333.33]],"ltp":1.68,"tv":111.77,"id":35736920}]}]}
{"op":"mcm","clk":"11995052307","pt":1725028371190,"mc":[{"id":"1.232283786","rc":[{"batb":[[1,1.35,571.43],[2,1.25,800]],"ltp":1.68,"tv":111.77,"id":35736920}]}]}
{"op":"mcm","clk":"11995052755","pt":1725028374458,"mc":[{"id":"1.232283786","rc":[{"batb":[[1,1.15,1333.33],[2,1.1,250]],"ltp":2.48,"tv":7.68,"id":11445383}]}]}
{"op":"mcm","clk":"11995052931","pt":1725028375804,"mc":[{"id":"1.232283786","rc":[{"batb":[[1,1.25,800],[2,1.15,1333.33]],"ltp":2.48,"tv":7.68,"id":11445383}]}]}
{"op":"mcm","clk":"11995053066","pt":1725028376689,"mc":[{"id":"1.232283786","rc":[{"batb":[[1,1.35,571.43],[2,1.25,800]],"ltp":2.48,"tv":7.68,"id":11445383}]}]}
{"op":"mcm","clk":"11995431255","pt":1725031294011,"mc":[{"id":"1.232283786","rc":[{"trd":[[1.68,103.17]],"ltp":1.68,"tv":111.85,"id":35736920}],"tv":119.54}]}
{"op":"mcm","clk":"11995431388","pt":1725031294925,"mc":[{"id":"1.232283786","rc":[{"batb":[[2,1.1,250]],"ltp":1.68,"tv":111.85,"id":35736920}]}]}
{"op":"mcm","clk":"11995431624","pt":1725031296510,"mc":[{"id":"1.232283786","rc":[{"batb":[[1,1.1,250],[2,1.08,312.5]],"ltp":1.68,"tv":111.85,"id":35736920}]}]}
{"op":"mcm","clk":"11995431854","pt":1725031298093,"mc":[{"id":"1.232283786","rc":[{"batb":[[1,1.15,666.67],[2,1.1,250]],"ltp":1.68,"tv":111.85,"id":35736920}]}]}
{"op":"mcm","clk":"11995432162","pt":1725031300414,"mc":[{"id":"1.232283786","rc":[{"batb":[[1,1.2,500],[2,1.15,666.67]],"ltp":1.68,"tv":111.85,"id":35736920}]}]}
{"op":"mcm","clk":"11995432351","pt":1725031301828,"mc":[{"id":"1.232283786","rc":[{"batb":[[1,1.25,400],[2,1.2,500]],"ltp":1.68,"tv":111.85,"id":35736920}]}]}
{"op":"mcm","clk":"11995432604","pt":1725031303727,"mc":[{"id":"1.232283786","rc":[{"batb":[[1,1.3,333.33],[2,1.25,400]],"ltp":1.68,"tv":111.85,"id":35736920}]}]}
{"op":"mcm","clk":"11995432821","pt":1725031305326,"mc":[{"id":"1.232283786","rc":[{"batb":[[1,1.35,285.71],[2,1.3,333.33]],"ltp":1.68,"tv":111.85,"id":35736920}]}]}
{"op":"mcm","clk":"11995432971","pt":1725031306309,"mc":[{"id":"1.232283786","rc":[{"batb":[[1,1.4,250],[2,1.35,285.71]],"ltp":1.68,"tv":111.85,"id":35736920}]}]}
{"op":"mcm","clk":"11995433777","pt":1725031312037,"mc":[{"id":"1.232283786","rc":[{"batb":[[2,1.1,250]],"ltp":2.48,"tv":7.68,"id":11445383}]}]}
{"op":"mcm","clk":"11995433920","pt":1725031313030,"mc":[{"id":"1.232283786","rc":[{"batb":[[1,1.1,250],[2,1.08,312.5]],"ltp":2.48,"tv":7.68,"id":11445383}]}]}
{"op":"mcm","clk":"11995434157","pt":1725031314720,"mc":[{"id":"1.232283786","rc":[{"batb":[[1,1.15,666.67],[2,1.1,250]],"ltp":2.48,"tv":7.68,"id":11445383}]}]}
{"op":"mcm","clk":"11995434416","pt":1725031316635,"mc":[{"id":"1.232283786","rc":[{"batb":[[1,1.25,400],[2,1.15,666.67]],"ltp":2.48,"tv":7.68,"id":11445383}]}]}
{"op":"mcm","clk":"11995434604","pt":1725031317835,"mc":[{"id":"1.232283786","rc":[{"batb":[[1,1.35,285.71],[2,1.25,400]],"ltp":2.48,"tv":7.68,"id":11445383}]}]}
{"op":"mcm","clk":"11995435104","pt":1725031321738,"mc":[{"id":"1.232283786","rc":[{"batb":[[1,1.45,222.22],[2,1.35,285.71]],"ltp":2.48,"tv":7.68,"id":11445383}]}]}
{"op":"mcm","clk":"11995435274","pt":1725031322942,"mc":[{"id":"1.232283786","rc":[{"batb":[[1,1.55,181.82],[2,1.45,222.22]],"ltp":2.48,"tv":7.68,"id":11445383}]}]}
{"op":"mcm","clk":"11995435475","pt":1725031324357,"mc":[{"id":"1.232283786","rc":[{"batb":[[1,1.65,153.85],[2,1.55,181.82]],"ltp":2.48,"tv":7.68,"id":11445383}]}]}
{"op":"mcm","clk":"11996083517","pt":1725035381826,"mc":[{"id":"1.232283786","rc":[{"trd":[[1.68,102.96]],"ltp":1.68,"tv":111.64,"id":35736920}],"tv":119.33}]}
{"op":"mcm","clk":"11996503687","pt":1725037974835,"mc":[{"id":"1.232283786","rc":[{"trd":[[1.68,102.95]],"ltp":1.68,"tv":111.64,"id":35736920}],"tv":119.33}]}
{"op":"mcm","clk":"11997708140","pt":1725043374830,"mc":[{"id":"1.232283786","rc":[{"trd":[[1.68,103]],"ltp":1.68,"tv":111.69,"id":35736920}],"tv":119.38}]}
{"op":"mcm","clk":"11997810061","pt":1725043720218,"mc":[{"id":"1.232283786","rc":[{"trd":[[1.68,229.8]],"batb":[[0,1.64,67.85],[1,1.41,55.71],[2,1.4,250]],"ltp":1.68,"tv":238.48,"id":35736920}],"tv":246.17}]}
{"op":"mcm","clk":"11997812352","pt":1725043730310,"mc":[{"id":"1.232283786","rc":[{"trd":[[1.64,135.04]],"batb":[[0,1.41,56.04],[1,1.4,250],[2,1.35,285.71]],"ltp":1.64,"tv":373.52,"id":35736920}],"tv":381.21}]}
{"op":"mcm","clk":"11997813546","pt":1725043735413,"mc":[{"id":"1.232283786","rc":[{"batb":[[0,1.41,55.71]],"ltp":1.64,"tv":373.52,"id":35736920}]}]}
{"op":"mcm","clk":"11997816700","pt":1725043749445,"mc":[{"id":"1.232283786","rc":[{"batl":[[0,1.6,81.95]],"ltp":1.64,"tv":373.52,"id":35736920}]}]}
{"op":"mcm","clk":"11997906607","pt":1725044199740,"mc":[{"id":"1.232283786","rc":[{"trd":[[1.6,11.12]],"batl":[[0,1.6,76.39]],"ltp":1.6,"tv":384.65,"id":35736920}],"tv":392.34}]}
{"op":"mcm","clk":"11997957974","pt":1725044454701,"mc":[{"id":"1.232283786","rc":[{"trd":[[1.6,163.98],[1.64,135.07],[1.68,229.88]],"batb":[[0,1.6,12.69],[1,1.41,55.71],[2,1.4,250]],"ltp":1.6,"tv":537.62,"id":35736920}],"tv":545.31}]}
{"op":"mcm","clk":"11997958747","pt":1725044458695,"mc":[{"id":"1.232283786","rc":[{"batb":[[0,1.41,55.71],[1,1.4,250],[2,1.35,285.71]],"ltp":1.6,"tv":537.62,"id":35736920}]}]}
{"op":"mcm","clk":"11997977897","pt":1725044548691,"mc":[{"id":"1.232283786","rc":[{"batl":[[0,1.72,71.08]],"ltp":1.6,"tv":537.62,"id":35736920}]}]}
{"op":"mcm","clk":"11997994646","pt":1725044627320,"mc":[{"id":"1.232283786","rc":[{"batl":[[0,1.71,2],[1,1.72,71.08]],"ltp":1.6,"tv":537.62,"id":35736920}]}]}
{"op":"mcm","clk":"11998067047","pt":1725044950170,"mc":[{"id":"1.232283786","rc":[{"batb":[[0,1.43,16.76],[1,1.41,55.71],[2,1.4,250]],"ltp":1.6,"tv":537.62,"id":35736920}]}]}
{"op":"mcm","clk":"11998094337","pt":1725045065919,"mc":[{"id":"1.232283786","rc":[{"batb":[[0,1.66,1.07],[1,1.43,16.76]],"ltp":1.6,"tv":537.62,"id":35736920}]}]}
{"op":"mcm","clk":"11998097427","pt":1725045078964,"mc":[{"id":"1.232283786","rc":[{"batb":[[1,1.4,250],[2,1.35,285.71]],"ltp":1.6,"tv":537.62,"id":35736920}]}]}
{"op":"mcm","clk":"11998134057","pt":1725045235568,"mc":[{"id":"1.232283786","rc":[{"batl":[[0,1.7,233.09],[1,1.71,2],[2,1.72,71.08]],"ltp":1.6,"tv":537.62,"id":35736920}]}]}
{"op":"mcm","clk":"11998147538","pt":1725045289305,"mc":[{"id":"1.232283786","rc":[{"batb":[[0,1.41,90.1]],"ltp":1.6,"tv":537.62,"id":35736920}]}]}
{"op":"mcm","clk":"11998153141","pt":1725045312062,"mc":[{"id":"1.232283786","rc":[{"batl":[[0,3.2,8.38]],"ltp":2.48,"tv":7.68,"id":11445383}]}]}
{"op":"mcm","clk":"11998156407","pt":1725045325381,"mc":[{"id":"1.232283786","rc":[{"batb":[[0,1.42,16.76]],"ltp":1.6,"tv":537.62,"id":35736920},{"batl":[[0,3.15,40.32],[1,3.2,8.38]],"ltp":2.48,"tv":7.68,"id":11445383}]}]}
{"op":"mcm","clk":"11998176331","pt":1725045405058,"mc":[{"id":"1.232283786","rc":[{"batl":[[0,3,8.38],[1,3.15,40.32],[2,3.2,8.38]],"ltp":2.48,"tv":7.68,"id":11445383}]}]}
{"op":"mcm","clk":"11998177760","pt":1725045410771,"mc":[{"id":"1.232283786","rc":[{"batl":[[2,3.2,0]],"ltp":2.48,"tv":7.68,"id":11445383}]}]}
{"op":"mcm","clk":"11998187338","pt":1725045448943,"mc":[{"id":"1.232283786","rc":[{"batl":[[1,3.15,0]],"ltp":2.48,"tv":7.68,"id":11445383}]}]}
{"op":"mcm","clk":"11998227270","pt":1725045616074,"mc":[{"id":"1.232283786","rc":[{"batb":[[0,2.8,1.07],[1,2.34,32.41],[2,1.65,153.85]],"ltp":2.48,"tv":7.68,"id":11445383}]}]}
{"op":"mcm","clk":"11998230695","pt":1725045630807,"mc":[{"id":"1.232283786","rc":[{"trd":[[1.56,1.92]],"batb":[[0,1.56,2.54],[1,1.42,16.76],[2,1.4,250]],"ltp":1.56,"tv":539.53,"id":35736920},{"trd":[[2.8,1.07]],"batb":[[0,2.34,32.41],[1,1.65,153.85],[2,1.55,181.82]],"ltp":2.8,"tv":8.75,"id":11445383}],"tv":548.29}]}
{"op":"mcm","clk":"11998231884","pt":1725045635771,"mc":[{"id":"1.232283786","rc":[{"batb":[[0,1.42,16.76],[1,1.4,250],[2,1.35,285.71]],"ltp":1.56,"tv":539.53,"id":35736920}]}]}
{"op":"mcm","clk":"11998252601","pt":1725045723399,"mc":[{"id":"1.232283786","rc":[{"batl":[[0,1.69,2],[1,1.7,233.09]],"ltp":1.56,"tv":539.53,"id":35736920}]}]}
{"op":"mcm","clk":"11998252810","pt":1725045724293,"mc":[{"id":"1.232283786","rc":[{"trd":[[1.69,3.52]],"batl":[[0,1.7,233.33],[1,1.72,71.08],[2,1.72,0]],"ltp":1.69,"tv":543.05,"id":35736920}],"tv":551.81}]}
{"op":"mcm","clk":"11998307797","pt":1725045970575,"mc":[{"id":"1.232283786","rc":[{"batb":[[0,2.7,1.07],[1,2.34,32.41],[2,1.65,153.85]],"ltp":2.8,"tv":8.75,"id":11445383}]}]}
{"op":"mcm","clk":"11998315078","pt":1725046002938,"mc":[{"id":"1.232283786","rc":[{"batb":[[0,2.34,32.41],[1,1.65,153.85],[2,1.55,181.82]],"ltp":2.8,"tv":8.75,"id":11445383}]}]}
{"op":"mcm","clk":"11998380305","pt":1725046293235,"mc":[{"id":"1.232283786","rc":[{"batb":[[0,1.46,53.15],[1,1.42,16.76],[2,1.4,250]],"ltp":1.69,"tv":543.05,"id":35736920}]}]}
{"op":"mcm","clk":"11998384907","pt":1725046314170,"mc":[{"id":"1.232283786","rc":[{"batb":[[1,2.3,8.38],[2,1.65,153.85]],"ltp":2.8,"tv":8.75,"id":11445383}]}]}
{"op":"mcm","clk":"11998389309","pt":1725046335291,"mc":[{"id":"1.232283786","rc":[{"batb":[[0,1.48,4.19],[1,1.46,53.15],[2,1.42,16.76]],"ltp":1.69,"tv":543.05,"id":35736920}]}]}
{"op":"mcm","clk":"11998414991","pt":1725046457367,"mc":[{"id":"1.232283786","rc":[{"batb":[[1,1.42,16.76],[2,1.4,250]],"ltp":1.69,"tv":543.05,"id":35736920},{"batb":[[0,2.8,1.07],[1,2.34,32.41],[2,2.3,8.38]],"ltp":2.8,"tv":8.75,"id":11445383}]}]}
{"op":"mcm","clk":"11998415024","pt":1725046457470,"mc":[{"id":"1.232283786","rc":[{"batb":[[0,1.49,52.08],[1,1.48,4.19],[2,1.42,16.76]],"ltp":1.69,"tv":543.05,"id":35736920}]}]}
{"op":"mcm","clk":"11998423291","pt":1725046497542,"mc":[{"id":"1.232283786","rc":[{"batl":[[0,1.69,17.09],[1,1.7,233.09],[2,1.72,71.08]],"ltp":1.69,"tv":543.05,"id":35736920}]}]}
{"op":"mcm","clk":"11998425703","pt":1725046508458,"mc":[{"id":"1.232283786","rc":[{"batb":[[0,2.34,32.41],[1,2.3,8.38],[2,1.65,153.85]],"ltp":2.8,"tv":8.75,"id":11445383}]}]}
{"op":"mcm","clk":"11998429351","pt":1725046524680,"mc":[{"id":"1.232283786","rc":[{"batl":[[0,3.8,8.38]],"ltp":2.8,"tv":8.75,"id":11445383}]}]}
{"op":"mcm","clk":"11998446411","pt":1725046607436,"mc":[{"id":"1.232283786","rc":[{"batb":[[0,1.5,5.82],[1,1.49,52.08],[2,1.48,4.19]],"ltp":1.69,"tv":543.05,"id":35736920}]}]}
{"op":"mcm","clk":"11998446437","pt":1725046607595,"mc":[{"id":"1.232283786","rc":[{"batb":[[0,2.44,7.42],[1,2.34,32.41],[2,2.3,8.38]],"ltp":2.8,"tv":8.75,"id":11445383}]}]}
{"op":"mcm","clk":"11998467531","pt":1725046713997,"mc":[{"id":"1.232283786","rc":[{"batb":[[1,1.48,4.19],[2,1.42,16.76]],"ltp":1.69,"tv":543.05,"id":35736920}]}]}
{"op":"mcm","clk":"11998496684","pt":1725046862034,"mc":[{"id":"1.232283786","rc":[{"batb":[[0,1.67,1.07],[1,1.5,5.82],[2,1.48,4.19]],"ltp":1.69,"tv":543.05,"id":35736920}]}]}
{"op":"mcm","clk":"11998500007","pt":1725046878503,"mc":[{"id":"1.232283786","rc":[{"trd":[[1.67,2.14]],"batb":[[0,1.5,5.82],[1,1.48,4.19],[2,1.42,16.76]],"batl":[[0,1.69,17.42]],"ltp":1.67,"tv":545.19,"id":35736920}],"tv":553.95}]}
{"op":"mcm","clk":"11998503189","pt":1725046894518,"mc":[{"id":"1.232283786","rc":[{"batb":[[0,1.5,6.74]],"ltp":1.67,"tv":545.19,"id":35736920}]}]}
{"op":"mcm","clk":"11998519268","pt":1725046981374,"mc":[{"id":"1.232283786","rc":[{"batb":[[0,1.66,1.07],[1,1.5,6.74],[2,1.48,4.19]],"ltp":1.67,"tv":545.19,"id":35736920}]}]}
{"op":"mcm","clk":"11998526538","pt":1725047019041,"mc":[{"id":"1.232283786","rc":[{"trd":[[1.66,1.84]],"batb":[[0,1.53,1.06],[1,1.5,5.82]],"ltp":1.66,"tv":547.03,"id":35736920}],"tv":555.79}]}
{"op":"mcm","clk":"11998537938","pt":1725047080394,"mc":[{"id":"1.232283786","rc":[{"batb":[[0,1.54,2.14]],"ltp":1.66,"tv":547.03,"id":35736920}]}]}
{"op":"mcm","clk":"11998538979","pt":1725047085769,"mc":[{"id":"1.232283786","rc":[{"trd":[[1.5,0.29],[1.54,4]],"batb":[[0,1.5,5.68],[1,1.48,4.19],[2,1.42,16.76]],"ltp":1.5,"tv":551.32,"id":35736920}],"tv":560.08}]}
{"op":"mcm","clk":"11998540477","pt":1725047093576,"mc":[{"id":"1.232283786","rc":[{"batl":[[0,1.69,17.09]],"ltp":1.5,"tv":551.32,"id":35736920}]}]}
{"op":"mcm","clk":"11998542962","pt":1725047106910,"mc":[{"id":"1.232283786","rc":[{"batl":[[0,1.69,16.85]],"ltp":1.5,"tv":551.32,"id":35736920}]}]}
{"op":"mcm","clk":"11998545740","pt":1725047121518,"mc":[{"id":"1.232283786","rc":[{"batl":[[0,1.68,2],[1,1.69,16.85],[2,1.7,233.09]],"ltp":1.5,"tv":551.32,"id":35736920}]}]}
{"op":"mcm","clk":"11998546681","pt":1725047126403,"mc":[{"id":"1.232283786","rc":[{"batb":[[0,1.5,6.6]],"ltp":1.5,"tv":551.32,"id":35736920}]}]}
{"op":"mcm","clk":"11998552105","pt":1725047156049,"mc":[{"id":"1.232283786","rc":[{"batb":[[0,1.51,2.92],[1,1.5,5.68],[2,1.48,4.19]],"ltp":1.5,"tv":551.32,"id":35736920}]}]}
{"op":"mcm","clk":"11998554989","pt":1725047170837,"mc":[{"id":"1.232283786","rc":[{"batb":[[0,1.65,1.14],[1,1.51,2.92],[2,1.5,5.68]],"ltp":1.5,"tv":551.32,"id":35736920}]}]}
{"op":"mcm","clk":"11998556978","pt":1725047182236,"mc":[{"id":"1.232283786","rc":[{"trd":[[1.65,1.9]],"batb":[[0,1.52,1.11],[1,1.51,2]],"ltp":1.65,"tv":553.22,"id":35736920}],"tv":561.98}]}
{"op":"mcm","clk":"11998573309","pt":1725047277921,"mc":[{"id":"1.232283786","rc":[{"batb":[[0,1.52,1.85]],"ltp":1.65,"tv":553.22,"id":35736920}]}]}
{"op":"mcm","clk":"11998578381","pt":1725047307884,"mc":[{"id":"1.232283786","rc":[{"trd":[[1.52,0.59],[1.55,1.48]],"batb":[[0,1.51,2.63],[1,1.5,5.68],[2,1.48,4.19]],"ltp":1.52,"tv":555.29,"id":35736920}],"tv":564.05}]}
{"op":"mcm","clk":"11998582081","pt":1725047329580,"mc":[{"id":"1.232283786","rc":[{"batb":[[0,1.52,1.55],[1,1.51,2],[2,1.5,5.68]],"ltp":1.52,"tv":555.29,"id":35736920}]}]}
{"op":"mcm","clk":"11998613517","pt":1725047505945,"mc":[{"id":"1.232283786","rc":[{"batb":[[0,1.56,2.1],[1,1.52,1.55],[2,1.51,2]],"ltp":1.52,"tv":555.29,"id":35736920}]}]}
{"op":"mcm","clk":"11998613971","pt":1725047508352,"mc":[{"id":"1.232283786","rc":[{"batb":[[1,1.51,2.92],[2,1.5,5.68]],"ltp":1.52,"tv":555.29,"id":35736920}]}]}
{"op":"mcm","clk":"11998614981","pt":1725047514053,"mc":[{"id":"1.232283786","rc":[{"batb":[[1,1.51,2]],"ltp":1.52,"tv":555.29,"id":35736920}]}]}
{"op":"mcm","clk":"11998630886","pt":1725047602417,"mc":[{"id":"1.232283786","rc":[{"trd":[[1.56,2.06]],"batb":[[0,1.56,2.03],[1,1.5,5.68],[2,1.48,4.19]],"batl":[[0,1.69,16.85],[1,1.7,233.09],[2,1.72,71.08]],"ltp":1.56,"tv":555.43,"id":35736920}],"tv":564.19}]}
{"op":"mcm","clk":"11998636860","pt":1725047636646,"mc":[{"id":"1.232283786","rc":[{"batl":[[0,1.68,2],[1,1.69,16.85],[2,1.7,233.09]],"ltp":1.56,"tv":555.43,"id":35736920}]}]}
{"op":"mcm","clk":"11998639914","pt":1725047653461,"mc":[{"id":"1.232283786","rc":[{"batb":[[1,1.52,2],[2,1.5,5.68]],"ltp":1.56,"tv":555.43,"id":35736920}]}]}
{"op":"mcm","clk":"11998709824","pt":1725048114454,"mc":[{"id":"1.232283786","rc":[{"trd":[[1.54,4],[1.56,2.05],[1.6,163.86],[1.64,135.04],[1.68,229.8],[1.69,3.52]],"batb":[[0,1.58,8.38],[1,1.56,2.03],[2,1.52,2]],"batl":[[1,1.69,16.83],[2,1.7,232.97]],"ltp":1.56,"tv":555.18,"id":35736920},{"batb":[[0,2.44,7.41]],"ltp":2.8,"tv":8.75,"id":11445383}],"tv":563.94}]}
{"op":"mcm","clk":"11998717857","pt":1725048179058,"mc":[{"id":"1.232283786","rc":[{"batb":[[0,1.56,2.03],[1,1.52,2],[2,1.5,5.67]],"ltp":1.56,"tv":555.18,"id":35736920}]}]}
{"op":"mcm","clk":"11998969705","pt":1725050221731,"mc":[{"id":"1.232283786","rc":[{"batb":[[2,1.5,214.86]],"ltp":1.56,"tv":555.18,"id":35736920}]}]}
{"op":"mcm","clk":"11998971073","pt":1725050236175,"mc":[{"id":"1.232283786","rc":[{"batb":[[1,1.52,211.19]],"ltp":1.56,"tv":555.18,"id":35736920}]}]}
{"op":"mcm","clk":"11998972413","pt":1725050251051,"mc":[{"id":"1.232283786","rc":[{"batb":[[2,1.51,209.19]],"ltp":1.56,"tv":555.18,"id":35736920}]}]}
{"op":"mcm","clk":"11998987959","pt":1725050447573,"mc":[{"id":"1.232283786","rc":[{"batb":[[1,1.53,16.02],[2,1.52,211.19]],"ltp":1.56,"tv":555.18,"id":35736920}]}]}
{"op":"mcm","clk":"11998999677","pt":1725050627499,"mc":[{"id":"1.232283786","rc":[{"batl":[[0,2.92,8.2],[1,3.8,8.38]],"ltp":2.8,"tv":8.75,"id":11445383}]}]}
{"op":"mcm","clk":"11999030863","pt":1725051190220,"mc":[{"id":"1.232283786","rc":[{"batl":[[0,2.92,13.96]],"ltp":2.8,"tv":8.75,"id":11445383}]}]}
{"op":"mcm","clk":"11999050653","pt":1725051592094,"mc":[{"id":"1.232283786","rc":[{"batb":[[1,1.53,21.69]],"ltp":1.56,"tv":555.18,"id":35736920}]}]}
{"op":"mcm","clk":"11999109913","pt":1725052950473,"mc":[{"id":"1.232283786","rc":[{"trd":[[1.56,2.06],[1.6,163.89],[1.64,135.03],[1.68,229.77]],"batb":[[1,1.53,21.69]],"batl":[[1,1.69,16.83],[2,1.72,71.05]],"ltp":1.56,"tv":555.19,"id":35736920},{"batb":[[0,2.44,7.41]],"batl":[[0,2.92,13.96]],"ltp":2.8,"tv":8.75,"id":11445383}],"tv":563.95}]}
{"op":"mcm","clk":"11999109955","pt":1725052951855,"mc":[{"id":"1.232283786","rc":[{"batl":[[1,1.72,71.05],[2,1.72,0]],"ltp":1.56,"tv":555.19,"id":35736920}]}]}
{"op":"mcm","clk":"11999177034","pt":1725054367431,"mc":[{"id":"1.232283786","rc":[{"batb":[[1,1.54,138.64],[2,1.53,21.69]],"ltp":1.56,"tv":555.19,"id":35736920}]}]}
{"op":"mcm","clk":"11999177058","pt":1725054367893,"mc":[{"id":"1.232283786","rc":[{"batl":[[0,2.92,8.2]],"ltp":2.8,"tv":8.75,"id":11445383}]}]}
{"op":"mcm","clk":"11999177093","pt":1725054368510,"mc":[{"id":"1.232283786","rc":[{"batb":[[2,1.53,5.68]],"ltp":1.56,"tv":555.19,"id":35736920},{"batl":[[0,3.8,8.38],[1,3.8,0]],"ltp":2.8,"tv":8.75,"id":11445383}]}]}
{"op":"mcm","clk":"11999178195","pt":1725054392732,"mc":[{"id":"1.232283786","rc":[{"batb":[[1,1.53,144.32],[2,1.52,211.19]],"ltp":1.56,"tv":555.19,"id":35736920}]}]}
{"op":"mcm","clk":"11999185657","pt":1725054594242,"mc":[{"id":"1.232283786","rc":[{"batb":[[0,1.53,144.32],[1,1.52,211.19],[2,1.51,209.19]],"batl":[[0,1.68,2.9]],"ltp":1.56,"tv":555.19,"id":35736920}]}]}
{"op":"mcm","clk":"11999185914","pt":1725054604151,"mc":[{"id":"1.232283786","rc":[{"batb":[[0,1.54,10.84],[1,1.53,144.32],[2,1.52,211.19]],"ltp":1.56,"tv":555.19,"id":35736920}]}]}
{"op":"mcm","clk":"11999185992","pt":1725054607266,"mc":[{"id":"1.232283786","rc":[{"trd":[[1.53,11.36],[1.54,25.68]],"batb":[[0,1.53,16.52],[1,1.52,211.19],[2,1.51,209.19]],"ltp":1.53,"tv":588.23,"id":35736920}],"tv":596.98}]}
{"op":"mcm","clk":"11999186023","pt":1725054608084,"mc":[{"id":"1.232283786","rc":[{"batl":[[1,1.71,9.76],[2,1.72,71.05]],"ltp":1.53,"tv":588.23,"id":35736920}]}]}
{"op":"mcm","clk":"11999186558","pt":1725054623371,"mc":[{"id":"1.232283786","rc":[{"batl":[[0,1.68,2]],"ltp":1.53,"tv":588.23,"id":35736920}]}]}
{"op":"mcm","clk":"11999197750","pt":1725054998907,"mc":[{"id":"1.232283786","rc":[{"batl":[[0,2.92,8.2],[1,3.8,8.38]],"ltp":2.8,"tv":8.75,"id":11445383}]}]}
{"op":"mcm","clk":"11999202106","pt":1725055149368,"mc":[{"id":"1.232283786","rc":[{"batl":[[1,1.69,122.13]],"ltp":1.53,"tv":588.23,"id":35736920}]}]}
{"op":"mcm","clk":"11999202109","pt":1725055149469,"mc":[{"id":"1.232283786","rc":[{"batl":[[0,1.68,11.94]],"ltp":1.53,"tv":588.23,"id":35736920}]}]}
{"op":"mcm","clk":"11999206290","pt":1725055267786,"mc":[{"id":"1.232283786","rc":[{"trd":[[1.53,11.35],[1.54,25.68],[1.6,163.86],[1.64,135.02],[1.68,253.66]],"batb":[[0,1.53,17.13]],"batl":[[0,1.69,122.13],[1,1.72,71.02],[2,1.72,0]],"ltp":1.68,"tv":612.07,"id":35736920},{"batb":[[0,2.44,7.41]],"batl":[[0,2.92,8.2]],"ltp":2.8,"tv":8.75,"id":11445383}],"tv":620.82}]}
{"op":"mcm","clk":"11999206625","pt":1725055278911,"mc":[{"id":"1.232283786","rc":[{"batl":[[0,1.72,71.69],[1,1.72,0]],"ltp":1.68,"tv":612.07,"id":35736920}]}]}
{"op":"mcm","clk":"11999218563","pt":1725055631280,"mc":[{"id":"1.232283786","rc":[{"batl":[[0,2.92,13.96]],"ltp":2.8,"tv":8.75,"id":11445383}]}]}
{"op":"mcm","clk":"11999219879","pt":1725055672745,"mc":[{"id":"1.232283786","rc":[{"batb":[[1,2.4,4.45],[2,2.34,32.41]],"ltp":2.8,"tv":8.75,"id":11445383}]}]}
{"op":"mcm","clk":"11999219946","pt":1725055674534,"mc":[{"id":"1.232283786","rc":[{"batb":[[1,2.34,32.41],[2,2.3,8.38]],"ltp":2.8,"tv":8.75,"id":11445383}]}]}
{"op":"mcm","clk":"11999222157","pt":1725055743855,"mc":[{"id":"1.232283786","rc":[{"batb":[[1,2.4,4.45],[2,2.34,32.41]],"ltp":2.8,"tv":8.75,"id":11445383}]}]}
{"op":"mcm","clk":"11999222224","pt":1725055745747,"mc":[{"id":"1.232283786","rc":[{"batb":[[1,2.34,32.41],[2,2.3,8.38]],"ltp":2.8,"tv":8.75,"id":11445383}]}]}
{"op":"mcm","clk":"11999224410","pt":1725055815036,"mc":[{"id":"1.232283786","rc":[{"batb":[[1,2.4,4.45],[2,2.34,32.41]],"ltp":2.8,"tv":8.75,"id":11445383}]}]}
{"op":"mcm","clk":"11999224476","pt":1725055816826,"mc":[{"id":"1.232283786","rc":[{"batb":[[1,2.34,32.41],[2,2.3,8.38]],"ltp":2.8,"tv":8.75,"id":11445383}]}]}
{"op":"mcm","clk":"11999226994","pt":1725055881713,"mc":[{"id":"1.232283786","rc":[{"batb":[[1,2.4,4.45],[2,2.34,32.41]],"ltp":2.8,"tv":8.75,"id":11445383}]}]}
{"op":"mcm","clk":"11999227073","pt":1725055883655,"mc":[{"id":"1.232283786","rc":[{"batb":[[1,2.34,32.41],[2,2.3,8.38]],"ltp":2.8,"tv":8.75,"id":11445383}]}]}
{"op":"mcm","clk":"11999229673","pt":1725055948030,"mc":[{"id":"1.232283786","rc":[{"batb":[[1,2.4,4.45],[2,2.34,32.41]],"ltp":2.8,"tv":8.75,"id":11445383}]}]}
{"op":"mcm","clk":"11999229752","pt":1725055950332,"mc":[{"id":"1.232283786","rc":[{"batb":[[1,2.34,32.41],[2,2.3,8.38]],"ltp":2.8,"tv":8.75,"id":11445383}]}]}
{"op":"mcm","clk":"11999232152","pt":1725056015404,"mc":[{"id":"1.232283786","rc":[{"batb":[[1,2.4,4.45],[2,2.34,32.41]],"ltp":2.8,"tv":8.75,"id":11445383}]}]}
{"op":"mcm","clk":"11999232211","pt":1725056017194,"mc":[{"id":"1.232283786","rc":[{"batb":[[1,2.34,32.41],[2,2.3,8.38]],"ltp":2.8,"tv":8.75,"id":11445383}]}]}
{"op":"mcm","clk":"11999234670","pt":1725056084801,"mc":[{"id":"1.232283786","rc":[{"batb":[[1,2.4,4.45],[2,2.34,32.41]],"ltp":2.8,"tv":8.75,"id":11445383}]}]}
{"op":"mcm","clk":"11999234728","pt":1725056086595,"mc":[{"id":"1.232283786","rc":[{"batb":[[1,2.34,32.41],[2,2.3,8.38]],"ltp":2.8,"tv":8.75,"id":11445383}]}]}
{"op":"mcm","clk":"11999237402","pt":1725056155000,"mc":[{"id":"1.232283786","rc":[{"batb":[[1,2.4,4.45],[2,2.34,32.41]],"ltp":2.8,"tv":8.75,"id":11445383}]}]}
{"op":"mcm","clk":"11999237463","pt":1725056156583,"mc":[{"id":"1.232283786","rc":[{"batb":[[1,2.34,32.41],[2,2.3,8.38]],"ltp":2.8,"tv":8.75,"id":11445383}]}]}
{"op":"mcm","clk":"11999240099","pt":1725056224985,"mc":[{"id":"1.232283786","rc":[{"batb":[[1,2.4,4.45],[2,2.34,32.41]],"ltp":2.8,"tv":8.75,"id":11445383}]}]}
{"op":"mcm","clk":"11999240189","pt":1725056226777,"mc":[{"id":"1.232283786","rc":[{"batb":[[1,2.34,32.41],[2,2.3,8.38]],"ltp":2.8,"tv":8.75,"id":11445383}]}]}
{"op":"mcm","clk":"11999243101","pt":1725056294761,"mc":[{"id":"1.232283786","rc":[{"batb":[[1,2.4,4.45],[2,2.34,32.41]],"ltp":2.8,"tv":8.75,"id":11445383}]}]}
{"op":"mcm","clk":"11999243186","pt":1725056296703,"mc":[{"id":"1.232283786","rc":[{"batb":[[1,2.34,32.41],[2,2.3,8.38]],"ltp":2.8,"tv":8.75,"id":11445383}]}]}
{"op":"mcm","clk":"11999245763","pt":1725056361775,"mc":[{"id":"1.232283786","rc":[{"batb":[[1,2.4,4.45],[2,2.34,32.41]],"ltp":2.8,"tv":8.75,"id":11445383}]}]}
{"op":"mcm","clk":"11999245824","pt":1725056363572,"mc":[{"id":"1.232283786","rc":[{"batb":[[1,2.34,32.41],[2,2.3,8.38]],"ltp":2.8,"tv":8.75,"id":11445383}]}]}
{"op":"mcm","clk":"11999248871","pt":1725056429164,"mc":[{"id":"1.232283786","rc":[{"batb":[[1,2.4,4.45],[2,2.34,32.41]],"ltp":2.8,"tv":8.75,"id":11445383}]}]}
{"op":"mcm","clk":"11999248955","pt":1725056431170,"mc":[{"id":"1.232283786","rc":[{"batb":[[1,2.34,32.41],[2,2.3,8.38]],"ltp":2.8,"tv":8.75,"id":11445383}]}]}
{"op":"mcm","clk":"11999251269","pt":1725056497068,"mc":[{"id":"1.232283786","rc":[{"batb":[[1,2.4,4.45],[2,2.34,32.41]],"ltp":2.8,"tv":8.75,"id":11445383}]}]}
{"op":"mcm","clk":"11999251347","pt":1725056498975,"mc":[{"id":"1.232283786","rc":[{"batb":[[1,2.34,32.41],[2,2.3,8.38]],"ltp":2.8,"tv":8.75,"id":11445383}]}]}
{"op":"mcm","clk":"11999252397","pt":1725056528090,"mc":[{"id":"1.232283786","rc":[{"batb":[[0,1.53,23.66]],"ltp":1.68,"tv":612.07,"id":35736920},{"batb":[[0,2.4,7.41]],"ltp":2.8,"tv":8.75,"id":11445383}]}]}
{"op":"mcm","clk":"11999253751","pt":1725056564518,"mc":[{"id":"1.232283786","rc":[{"batb":[[0,2.4,11.86]],"ltp":2.8,"tv":8.75,"id":11445383}]}]}
{"op":"mcm","clk":"11999253833","pt":1725056566615,"mc":[{"id":"1.232283786","rc":[{"batb":[[0,2.4,7.41]],"ltp":2.8,"tv":8.75,"id":11445383}]}]}
{"op":"mcm","clk":"11999256223","pt":1725056632899,"mc":[{"id":"1.232283786","rc":[{"batb":[[0,2.4,11.86]],"ltp":2.8,"tv":8.75,"id":11445383}]}]}
{"op":"mcm","clk":"11999256304","pt":1725056635041,"mc":[{"id":"1.232283786","rc":[{"batb":[[0,2.4,7.41]],"ltp":2.8,"tv":8.75,"id":11445383}]}]}
{"op":"mcm","clk":"11999258559","pt":1725056702408,"mc":[{"id":"1.232283786","rc":[{"batb":[[0,2.4,11.86]],"ltp":2.8,"tv":8.75,"id":11445383}]}]}
{"op":"mcm","clk":"11999258632","pt":1725056704509,"mc":[{"id":"1.232283786","rc":[{"batb":[[0,2.4,7.41]],"ltp":2.8,"tv":8.75,"id":11445383}]}]}
{"op":"mcm","clk":"11999259828","pt":1725056741038,"mc":[{"id":"1.232283786","rc":[{"batl":[[0,1.71,6.83],[1,1.72,71.02]],"ltp":1.68,"tv":612.07,"id":35736920}]}]}
{"op":"mcm","clk":"11999270757","pt":1725057069528,"mc":[{"id":"1.232283786","rc":[{"batl":[[0,1.71,11.16]],"ltp":1.68,"tv":612.07,"id":35736920}]}]}
{"op":"mcm","clk":"11999270934","pt":1725057074741,"mc":[{"id":"1.232283786","rc":[{"batl":[[0,1.71,6.83]],"ltp":1.68,"tv":612.07,"id":35736920}]}]}
{"op":"mcm","clk":"11999276909","pt":1725057249462,"mc":[{"id":"1.232283786","rc":[{"batl":[[0,1.71,11.16]],"ltp":1.68,"tv":612.07,"id":35736920}]}]}
{"op":"mcm","clk":"11999277108","pt":1725057255137,"mc":[{"id":"1.232283786","rc":[{"batl":[[0,1.71,6.83]],"ltp":1.68,"tv":612.07,"id":35736920}]}]}
{"op":"mcm","clk":"11999282692","pt":1725057431114,"mc":[{"id":"1.232283786","rc":[{"batl":[[0,1.71,11.16]],"ltp":1.68,"tv":612.07,"id":35736920}]}]}
{"op":"mcm","clk":"11999282788","pt":1725057434448,"mc":[{"id":"1.232283786","rc":[{"batl":[[0,1.71,6.83]],"ltp":1.68,"tv":612.07,"id":35736920}]}]}
{"op":"mcm","clk":"11999288292","pt":1725057610630,"mc":[{"id":"1.232283786","rc":[{"batl":[[0,1.71,11.16]],"ltp":1.68,"tv":612.07,"id":35736920}]}]}
{"op":"mcm","clk":"11999288429","pt":1725057614049,"mc":[{"id":"1.232283786","rc":[{"batl":[[0,1.71,6.83]],"ltp":1.68,"tv":612.07,"id":35736920}]}]}
{"op":"mcm","clk":"11999294052","pt":1725057788776,"mc":[{"id":"1.232283786","rc":[{"batl":[[0,1.71,11.16]],"ltp":1.68,"tv":612.07,"id":35736920}]}]}
{"op":"mcm","clk":"11999294187","pt":1725057793791,"mc":[{"id":"1.232283786","rc":[{"batl":[[0,1.71,6.83]],"ltp":1.68,"tv":612.07,"id":35736920}]}]}
{"op":"mcm","clk":"11999300453","pt":1725057968926,"mc":[{"id":"1.232283786","rc":[{"batl":[[0,1.71,11.16]],"ltp":1.68,"tv":612.07,"id":35736920}]}]}
{"op":"mcm","clk":"11999300637","pt":1725057973538,"mc":[{"id":"1.232283786","rc":[{"batl":[[0,1.71,6.83]],"ltp":1.68,"tv":612.07,"id":35736920}]}]}
{"op":"mcm","clk":"11999307559","pt":1725058148577,"mc":[{"id":"1.232283786","rc":[{"batl":[[0,1.71,11.16]],"ltp":1.68,"tv":612.07,"id":35736920}]}]}
{"op":"mcm","clk":"11999307785","pt":1725058153287,"mc":[{"id":"1.232283786","rc":[{"batl":[[0,1.71,6.83]],"ltp":1.68,"tv":612.07,"id":35736920}]}]}
{"op":"mcm","clk":"11999316172","pt":1725058329260,"mc":[{"id":"1.232283786","rc":[{"batl":[[0,1.71,11.16]],"ltp":1.68,"tv":612.07,"id":35736920}]}]}
{"op":"mcm","clk":"11999316445","pt":1725058334686,"mc":[{"id":"1.232283786","rc":[{"batl":[[0,1.71,6.83]],"ltp":1.68,"tv":612.07,"id":35736920}]}]}
{"op":"mcm","clk":"11999326389","pt":1725058508907,"mc":[{"id":"1.232283786","rc":[{"batl":[[0,1.71,11.16]],"ltp":1.68,"tv":612.07,"id":35736920}]}]}
{"op":"mcm","clk":"11999326735","pt":1725058514799,"mc":[{"id":"1.232283786","rc":[{"batl":[[0,1.71,6.83]],"ltp":1.68,"tv":612.07,"id":35736920}]}]}
{"op":"mcm","clk":"11999330863","pt":1725058616434,"mc":[{"id":"1.232283786","rc":[{"batb":[[0,1.66,66.41],[1,1.53,23.05],[2,1.52,211.19]],"ltp":1.68,"tv":612.07,"id":35736920},{"batb":[[0,2.4,38.43],[1,2.3,8.38],[2,1.65,153.85]],"batl":[[0,3.8,8.38],[1,3.8,0]],"ltp":2.8,"tv":8.75,"id":11445383}]}]}
{"op":"mcm","clk":"11999333453","pt":1725058682240,"mc":[{"id":"1.232283786","rc":[{"batl":[[1,1000,0.02]],"ltp":2.8,"tv":8.75,"id":11445383}]}]}
{"op":"mcm","clk":"11999333465","pt":1725058682546,"mc":[{"id":"1.232283786","rc":[{"trd":[[1.69,3.55]],"batl":[[0,1.71,6.8]],"ltp":1.69,"tv":612.1,"id":35736920},{"trd":[[2.44,0.02]],"batl":[[1,1000,0]],"ltp":2.44,"tv":8.77,"id":11445383}],"tv":620.87}]}
{"op":"mcm","clk":"11999333741","pt":1725058689037,"mc":[{"id":"1.232283786","rc":[{"batl":[[0,1.71,13.25]],"ltp":1.69,"tv":612.1,"id":35736920}]}]}
{"op":"mcm","clk":"11999339873","pt":1725058828778,"mc":[{"id":"1.232283786","rc":[{"batb":[[0,1.67,5.6],[1,1.66,65.8],[2,1.53,23.05]],"ltp":1.69,"tv":612.1,"id":35736920}]}]}
{"op":"mcm","clk":"11999396574","pt":1725059652895,"mc":[{"id":"1.232283786","rc":[{"trd":[[1.66,133.44],[1.67,12.11],[1.68,254.87]],"batb":[[0,1.53,23.05],[1,1.52,211.19],[2,1.51,209.19]],"batl":[[0,1.66,57.42],[1,1.71,13.25],[2,1.72,71.02]],"ltp":1.66,"tv":754.89,"id":35736920}],"tv":763.67}]}
{"op":"mcm","clk":"11999396623","pt":1725059653774,"mc":[{"id":"1.232283786","rc":[{"batl":[[0,1.65,5.05],[1,1.66,57.42],[2,1.71,7.09]],"ltp":1.66,"tv":754.89,"id":35736920},{"batl":[[0,2.92,8.2],[1,3.8,8.38]],"ltp":2.44,"tv":8.77,"id":11445383}]}]}
{"op":"mcm","clk":"11999396705","pt":1725059655468,"mc":[{"id":"1.232283786","rc":[{"batb":[[0,1.62,58.12],[1,1.53,23.05],[2,1.52,211.19]],"ltp":1.66,"tv":754.89,"id":35736920}]}]}
{"op":"mcm","clk":"11999396784","pt":1725059657203,"mc":[{"id":"1.232283786","rc":[{"batl":[[2,1.72,71.66]],"ltp":1.66,"tv":754.89,"id":35736920},{"batl":[[0,3.8,8.38],[1,3.8,0]],"ltp":2.44,"tv":8.77,"id":11445383}]}]}
{"op":"mcm","clk":"11999407940","pt":1725059863643,"mc":[{"id":"1.232283786","rc":[{"batl":[[0,1.65,9.74]],"ltp":1.66,"tv":754.89,"id":35736920}]}]}
{"op":"mcm","clk":"11999414125","pt":1725059973376,"mc":[{"id":"1.232283786","rc":[{"batl":[[1,1.7,58.06],[2,1.72,71.02]],"ltp":1.66,"tv":754.89,"id":35736920}]}]}
{"op":"mcm","clk":"11999414199","pt":1725059974864,"mc":[{"id":"1.232283786","rc":[{"batl":[[0,1.69,5.57],[1,1.7,57.42]],"ltp":1.66,"tv":754.89,"id":35736920}]}]}
{"op":"mcm","clk":"11999419489","pt":1725060068275,"mc":[{"id":"1.232283786","rc":[{"trd":[[1.62,115.42]],"batb":[[0,1.53,23.46],[1,1.52,211.19],[2,1.51,209.19]],"ltp":1.62,"tv":870.31,"id":35736920}],"tv":879.09}]}
{"op":"mcm","clk":"11999419554","pt":1725060069308,"mc":[{"id":"1.232283786","rc":[{"batl":[[0,1.69,10.3]],"ltp":1.62,"tv":870.31,"id":35736920},{"batl":[[0,2.92,8.2],[1,3.8,8.38]],"ltp":2.44,"tv":8.77,"id":11445383}]}]}
{"op":"mcm","clk":"11999419755","pt":1725060072393,"mc":[{"id":"1.232283786","rc":[{"batb":[[0,1.53,23.05]],"ltp":1.62,"tv":870.31,"id":35736920}]}]}
{"op":"mcm","clk":"11999428686","pt":1725060253330,"mc":[{"id":"1.232283786","rc":[{"batl":[[0,1.65,57.42],[1,1.69,10.3]],"ltp":1.62,"tv":870.31,"id":35736920}]}]}
{"op":"mcm","clk":"11999428715","pt":1725060253944,"mc":[{"id":"1.232283786","rc":[{"batl":[[0,1.64,5.07],[1,1.65,57.42],[2,1.72,71.66]],"ltp":1.62,"tv":870.31,"id":35736920}]}]}
{"op":"mcm","clk":"11999430964","pt":1725060285016,"mc":[{"id":"1.232283786","rc":[{"batl":[[0,1.64,9.76]],"ltp":1.62,"tv":870.31,"id":35736920}]}]}
{"op":"mcm","clk":"11999458838","pt":1725060730929,"mc":[{"id":"1.232283786","rc":[{"batl":[[0,2.92,13.96]],"ltp":2.44,"tv":8.77,"id":11445383}]}]}
{"op":"mcm","clk":"11999460021","pt":1725060751869,"mc":[{"id":"1.232283786","rc":[{"batl":[[1,1.7,58.06],[2,1.72,71.02]],"ltp":1.62,"tv":870.31,"id":35736920}]}]}
{"op":"mcm","clk":"11999460094","pt":1725060753056,"mc":[{"id":"1.232283786","rc":[{"batl":[[0,1.69,5.57],[1,1.7,57.42]],"ltp":1.62,"tv":870.31,"id":35736920}]}]}
{"op":"mcm","clk":"11999461936","pt":1725060784550,"mc":[{"id":"1.232283786","rc":[{"batl":[[0,1.69,10.3]],"ltp":1.62,"tv":870.31,"id":35736920}]}]}
{"op":"mcm","clk":"11999476789","pt":1725061049425,"mc":[{"id":"1.232283786","rc":[{"batb":[[0,1.54,110.78],[1,1.53,23.05],[2,1.52,211.19]],"ltp":1.62,"tv":870.31,"id":35736920},{"batl":[[0,2.92,8.2]],"ltp":2.44,"tv":8.77,"id":11445383}]}]}
{"op":"mcm","clk":"11999476886","pt":1725061051275,"mc":[{"id":"1.232283786","rc":[{"batl":[[0,3.8,8.38],[1,3.8,0]],"ltp":2.44,"tv":8.77,"id":11445383}]}]}
{"op":"mcm","clk":"11999494160","pt":1725061341414,"mc":[{"id":"1.232283786","rc":[{"batb":[[0,1.55,6.53],[1,1.54,110.78],[2,1.53,16.52]],"ltp":1.62,"tv":870.31,"id":35736920},{"batb":[[0,2.4,31.02]],"ltp":2.44,"tv":8.77,"id":11445383}]}]}
{"op":"mcm","clk":"11999494165","pt":1725061341517,"mc":[{"id":"1.232283786","rc":[{"batb":[[0,2.44,7.41],[1,2.4,31.02],[2,2.3,8.38]],"ltp":2.44,"tv":8.77,"id":11445383}]}]}
{"op":"mcm","clk":"11999499059","pt":1725061442422,"mc":[{"id":"1.232283786","rc":[{"batl":[[0,2.84,4.75],[1,3.8,8.38]],"ltp":2.44,"tv":8.77,"id":11445383}]}]}
{"op":"mcm","clk":"11999528344","pt":1725061917693,"mc":[{"id":"1.232283786","rc":[{"trd":[[2.44,10.02]],"batb":[[0,2.44,2.41]],"ltp":2.44,"tv":18.78,"id":11445383}],"tv":889.09}]}
{"op":"mcm","clk":"11999532520","pt":1725061990678,"mc":[{"id":"1.232283786","rc":[{"batb":[[0,1.55,12.72]],"ltp":1.62,"tv":870.31,"id":35736920}]}]}
{"op":"mcm","clk":"11999583057","pt":1725062810269,"mc":[{"id":"1.232283786","rc":[{"batl":[[1,1.72,71.02],[2,1.72,0]],"ltp":1.62,"tv":870.31,"id":35736920}]}]}
{"op":"mcm","clk":"11999583125","pt":1725062811756,"mc":[{"id":"1.232283786","rc":[{"batl":[[0,1.71,5.51]],"ltp":1.62,"tv":870.31,"id":35736920}]}]}
{"op":"mcm","clk":"11999584082","pt":1725062828516,"mc":[{"id":"1.232283786","rc":[{"batl":[[0,1.71,11.12]],"ltp":1.62,"tv":870.31,"id":35736920}]}]}
{"op":"mcm","clk":"11999586743","pt":1725062872762,"mc":[{"id":"1.232283786","rc":[{"batl":[[0,1.71,19.7]],"ltp":1.62,"tv":870.31,"id":35736920}]}]}
{"op":"mcm","clk":"11999595801","pt":1725063030420,"mc":[{"id":"1.232283786","rc":[{"batb":[[1,1.53,16.52],[2,1.52,211.19]],"ltp":1.62,"tv":870.31,"id":35736920}]}]}
{"op":"mcm","clk":"11999595823","pt":1725063030727,"mc":[{"id":"1.232283786","rc":[{"batb":[[0,1.55,123.5]],"ltp":1.62,"tv":870.31,"id":35736920},{"batl":[[0,3.8,8.38],[1,3.8,0]],"ltp":2.44,"tv":18.78,"id":11445383}]}]}
{"op":"mcm","clk":"11999621690","pt":1725063423483,"mc":[{"id":"1.232283786","rc":[{"batl":[[0,2.8,5.1],[1,3.8,8.38]],"ltp":2.44,"tv":18.78,"id":11445383}]}]}
{"op":"mcm","clk":"11999638157","pt":1725063658776,"mc":[{"id":"1.232283786","rc":[{"batb":[[0,1.56,129.42],[1,1.55,123.5],[2,1.53,16.52]],"ltp":1.62,"tv":870.31,"id":35736920}]}]}
{"op":"mcm","clk":"11999638196","pt":1725063659550,"mc":[{"id":"1.232283786","rc":[{"batb":[[1,1.55,117.31]],"ltp":1.62,"tv":870.31,"id":35736920}]}]}
{"op":"mcm","clk":"11999645937","pt":1725063780487,"mc":[{"id":"1.232283786","rc":[{"batb":[[0,1.55,117.31],[1,1.53,16.52],[2,1.52,211.19]],"ltp":1.62,"tv":870.31,"id":35736920}]}]}
{"op":"mcm","clk":"11999648248","pt":1725063814314,"mc":[{"id":"1.232283786","rc":[{"batb":[[1,1.52,211.19],[2,1.51,209.19]],"batl":[[0,1.71,19.06]],"ltp":1.62,"tv":870.31,"id":35736920}]}]}
{"op":"mcm","clk":"11999663517","pt":1725064088666,"mc":[{"id":"1.232283786","rc":[{"batb":[[0,1.56,6.22],[1,1.55,117.31],[2,1.52,211.19]],"ltp":1.62,"tv":870.31,"id":35736920}]}]}
{"op":"mcm","clk":"11999667584","pt":1725064165883,"mc":[{"id":"1.232283786","rc":[{"batl":[[0,1.7,126.49],[1,1.71,19.06],[2,1.72,71.02]],"ltp":1.62,"tv":870.31,"id":35736920}]}]}
{"op":"mcm","clk":"11999667647","pt":1725064166910,"mc":[{"id":"1.232283786","rc":[{"batl":[[0,1.69,4.93],[1,1.7,126.49],[2,1.71,5.61]],"ltp":1.62,"tv":870.31,"id":35736920}]}]}
{"op":"mcm","clk":"11999667701","pt":1725064168090,"mc":[{"id":"1.232283786","rc":[{"batl":[[2,1.72,71.02]],"ltp":1.62,"tv":870.31,"id":35736920}]}]}
{"op":"mcm","clk":"11999669047","pt":1725064192101,"mc":[{"id":"1.232283786","rc":[{"batl":[[0,1.69,131.42],[1,1.72,71.02],[2,1.72,0]],"ltp":1.62,"tv":870.31,"id":35736920}]}]}
{"op":"mcm","clk":"11999671278","pt":1725064223882,"mc":[{"id":"1.232283786","rc":[{"batl":[[0,1.68,9.5],[1,1.69,131.42],[2,1.72,71.02]],"ltp":1.62,"tv":870.31,"id":35736920}]}]}
{"op":"mcm","clk":"11999672248","pt":1725064238727,"mc":[{"id":"1.232283786","rc":[{"batl":[[1,1.69,4.93]],"ltp":1.62,"tv":870.31,"id":35736920}]}]}
{"op":"mcm","clk":"11999672363","pt":1725064240423,"mc":[{"id":"1.232283786","rc":[{"batl":[[0,1.72,71.02],[1,1.69,0],[2,1.72,0]],"ltp":1.62,"tv":870.31,"id":35736920}]}]}
{"op":"mcm","clk":"11999672369","pt":1725064240527,"mc":[{"id":"1.232283786","rc":[{"batl":[[0,1.71,4.87],[1,1.72,71.02]],"ltp":1.62,"tv":870.31,"id":35736920}]}]}
{"op":"mcm","clk":"11999674452","pt":1725064270572,"mc":[{"id":"1.232283786","rc":[{"batl":[[0,1.7,126.07],[1,1.71,4.87],[2,1.72,71.02]],"ltp":1.62,"tv":870.31,"id":35736920}]}]}
{"op":"mcm","clk":"11999674588","pt":1725064272072,"mc":[{"id":"1.232283786","rc":[{"batl":[[0,1.69,4.93],[1,1.7,126.07]],"ltp":1.62,"tv":870.31,"id":35736920}]}]}
{"op":"mcm","clk":"11999676760","pt":1725064303415,"mc":[{"id":"1.232283786","rc":[{"batl":[[0,1.69,15.03]],"ltp":1.62,"tv":870.31,"id":35736920}]}]}
{"op":"mcm","clk":"11999682270","pt":1725064391369,"mc":[{"id":"1.232283786","rc":[{"trd":[[1.69,33.61]],"batl":[[0,1.7,1.37],[1,1.72,71.02],[2,1.72,0]],"ltp":1.69,"tv":900.37,"id":35736920}],"tv":919.15}]}
{"op":"mcm","clk":"11999682332","pt":1725064392350,"mc":[{"id":"1.232283786","rc":[{"batb":[[0,1.56,27.13]],"ltp":1.69,"tv":900.37,"id":35736920}]}]}
{"op":"mcm","clk":"11999685780","pt":1725064442987,"mc":[{"id":"1.232283786","rc":[{"batl":[[0,1.72,71.02],[1,1.72,0]],"ltp":1.69,"tv":900.37,"id":35736920}]}]}
{"op":"mcm","clk":"11999694798","pt":1725064571541,"mc":[{"id":"1.232283786","rc":[{"batb":[[0,1.57,33.47],[1,1.56,27.13],[2,1.55,117.31]],"ltp":1.69,"tv":900.37,"id":35736920}]}]}
{"op":"mcm","clk":"11999694996","pt":1725064574219,"mc":[{"id":"1.232283786","rc":[{"batb":[[0,1.58,10.81],[1,1.57,33.47],[2,1.56,9.97]],"ltp":1.69,"tv":900.37,"id":35736920}]}]}
{"op":"mcm","clk":"11999695181","pt":1725064576819,"mc":[{"id":"1.232283786","rc":[{"batb":[[2,1.55,117.31]],"ltp":1.69,"tv":900.37,"id":35736920},{"batl":[[0,3.8,8.38],[1,3.8,0]],"ltp":2.44,"tv":18.78,"id":11445383}]}]}
{"op":"mcm","clk":"11999713375","pt":1725064810493,"mc":[{"id":"1.232283786","rc":[{"batl":[[0,1.71,5.79],[1,1.72,71.02]],"ltp":1.69,"tv":900.37,"id":35736920}]}]}
{"op":"mcm","clk":"11999722050","pt":1725064924757,"mc":[{"id":"1.232283786","rc":[{"batb":[[1,1.55,117.31],[2,1.52,211.19]],"ltp":1.69,"tv":900.37,"id":35736920}]}]}
{"op":"mcm","clk":"11999722177","pt":1725064926425,"mc":[{"id":"1.232283786","rc":[{"batb":[[0,1.55,117.31],[1,1.52,211.19],[2,1.51,209.19]],"ltp":1.69,"tv":900.37,"id":35736920}]}]}
{"op":"mcm","clk":"11999722187","pt":1725064926521,"mc":[{"id":"1.232283786","rc":[{"batb":[[0,1.56,19.75],[1,1.55,117.31],[2,1.52,211.19]],"ltp":1.69,"tv":900.37,"id":35736920},{"batl":[[0,2.8,5.31],[1,3.8,8.38]],"ltp":2.44,"tv":18.78,"id":11445383}]}]}
{"op":"mcm","clk":"11999832246","pt":1725066222152,"mc":[{"id":"1.232283786","rc":[{"trd":[[1.6,163.85],[1.62,115.42],[1.64,135.01],[1.66,133.44],[1.68,254.86]],"batb":[[1,1.55,117.3]],"ltp":1.69,"tv":900.32,"id":35736920},{"batb":[[0,2.42,2.41]],"ltp":2.44,"tv":18.78,"id":11445383}],"tv":919.1}]}
{"op":"mcm","clk":"12000209973","pt":1725071236668,"mc":[{"id":"1.232283786","rc":[{"batb":[[0,1.57,83.35],[1,1.56,19.75],[2,1.55,117.3]],"ltp":1.69,"tv":900.32,"id":35736920}]}]}
{"op":"mcm","clk":"12000210173","pt":1725071239353,"mc":[{"id":"1.232283786","rc":[{"batb":[[0,1.58,10.81],[1,1.57,83.35]],"ltp":1.69,"tv":900.32,"id":35736920},{"batl":[[0,3.8,8.38],[1,3.8,0]],"ltp":2.44,"tv":18.78,"id":11445383}]}]}
{"op":"mcm","clk":"12000212225","pt":1725071269197,"mc":[{"id":"1.232283786","rc":[{"batb":[[0,1.58,17.06]],"ltp":1.69,"tv":900.32,"id":35736920}]}]}
{"op":"mcm","clk":"12000212840","pt":1725071278212,"mc":[{"id":"1.232283786","rc":[{"batb":[[0,1.56,10.94],[1,1.55,117.3],[2,1.52,211.19]],"ltp":1.69,"tv":900.32,"id":35736920}]}]}
{"op":"mcm","clk":"12000212952","pt":1725071280020,"mc":[{"id":"1.232283786","rc":[{"batl":[[0,2.8,5.3],[1,3.8,8.38]],"ltp":2.44,"tv":18.78,"id":11445383}]}]}
{"op":"mcm","clk":"12000214161","pt":1725071296938,"mc":[{"id":"1.232283786","rc":[{"batb":[[0,1.56,94.29]],"ltp":1.69,"tv":900.32,"id":35736920}]}]}
{"op":"mcm","clk":"12000216084","pt":1725071328698,"mc":[{"id":"1.232283786","rc":[{"batb":[[0,1.57,6.26],[1,1.56,94.29],[2,1.55,117.3]],"ltp":1.69,"tv":900.32,"id":35736920}]}]}
{"op":"mcm","clk":"12000221593","pt":1725071425425,"mc":[{"id":"1.232283786","rc":[{"batl":[[0,1.7,104.08],[1,1.71,5.79],[2,1.72,71.02]],"ltp":1.69,"tv":900.32,"id":35736920}]}]}
{"op":"mcm","clk":"12000221713","pt":1725071427322,"mc":[{"id":"1.232283786","rc":[{"batl":[[1,1.72,71.02],[2,1.72,0]],"ltp":1.69,"tv":900.32,"id":35736920},{"batb":[[0,2.44,5.67],[1,2.42,2.41],[2,2.4,31.02]],"ltp":2.44,"tv":18.78,"id":11445383}]}]}
{"op":"mcm","clk":"12000222315","pt":1725071435133,"mc":[{"id":"1.232283786","rc":[{"batb":[[1,1.56,10.94]],"ltp":1.69,"tv":900.32,"id":35736920}]}]}
{"op":"mcm","clk":"12000222408","pt":1725071436316,"mc":[{"id":"1.232283786","rc":[{"batb":[[0,1.56,10.94],[1,1.55,117.3],[2,1.52,211.19]],"ltp":1.69,"tv":900.32,"id":35736920}]}]}
{"op":"mcm","clk":"12000224294","pt":1725071467051,"mc":[{"id":"1.232283786","rc":[{"batb":[[0,1.56,20.47]],"ltp":1.69,"tv":900.32,"id":35736920}]}]}
{"op":"mcm","clk":"12000226425","pt":1725071503398,"mc":[{"id":"1.232283786","rc":[{"trd":[[1.69,117.38]],"batb":[[0,1.69,3.81],[1,1.56,20.47],[2,1.55,117.3]],"ltp":1.69,"tv":984.1,"id":35736920}],"tv":1002.88}]}
{"op":"mcm","clk":"12000226606","pt":1725071506180,"mc":[{"id":"1.232283786","rc":[{"batb":[[0,1.56,20.47],[1,1.55,117.3],[2,1.52,211.19]],"ltp":1.69,"tv":984.1,"id":35736920}]}]}
{"op":"mcm","clk":"12000229600","pt":1725071561570,"mc":[{"id":"1.232283786","rc":[{"trd":[[2.76,50.26]],"batb":[[0,2.76,2.28],[1,2.44,5.67],[2,2.42,2.41]],"ltp":2.76,"tv":69.04,"id":11445383}],"tv":1053.14}]}
{"op":"mcm","clk":"12000229763","pt":1725071564451,"mc":[{"id":"1.232283786","rc":[{"batb":[[0,2.44,5.67],[1,2.42,2.41],[2,2.4,31.02]],"ltp":2.76,"tv":69.04,"id":11445383}]}]}
{"op":"mcm","clk":"12000231778","pt":1725071602310,"mc":[{"id":"1.232283786","rc":[{"trd":[[2.76,83.79]],"batb":[[0,2.76,1.52],[1,2.44,5.67],[2,2.42,2.41]],"ltp":2.76,"tv":102.56,"id":11445383}],"tv":1086.67}]}
{"op":"mcm","clk":"12000231932","pt":1725071605201,"mc":[{"id":"1.232283786","rc":[{"batb":[[0,2.44,5.67],[1,2.42,2.41],[2,2.4,31.02]],"ltp":2.76,"tv":102.56,"id":11445383}]}]}
{"op":"mcm","clk":"12000234196","pt":1725071650357,"mc":[{"id":"1.232283786","rc":[{"trd":[[1.69,251.4]],"batb":[[0,1.69,6.11],[1,1.56,20.47],[2,1.55,117.3]],"ltp":1.69,"tv":1118.12,"id":35736920}],"tv":1220.68}]}
{"op":"mcm","clk":"12000234345","pt":1725071653184,"mc":[{"id":"1.232283786","rc":[{"batb":[[0,1.56,20.47],[1,1.55,117.3],[2,1.52,211.19]],"ltp":1.69,"tv":1118.12,"id":35736920}]}]}
{"op":"mcm","clk":"12000247939","pt":1725071879703,"mc":[{"id":"1.232283786","rc":[{"batl":[[0,1.69,6.28],[1,1.7,104.08],[2,1.72,71.02]],"ltp":1.69,"tv":1118.12,"id":35736920}]}]}
{"op":"mcm","clk":"12000248821","pt":1725071894125,"mc":[{"id":"1.232283786","rc":[{"batl":[[0,1.7,104.08],[1,1.72,71.02],[2,1.72,0]],"ltp":1.69,"tv":1118.12,"id":35736920}]}]}
{"op":"mcm","clk":"12000251015","pt":1725071929395,"mc":[{"id":"1.232283786","rc":[{"trd":[[1.57,117.28]],"batb":[[0,1.55,117.3],[1,1.52,211.19],[2,1.51,209.19]],"batl":[[0,1.57,5.34],[1,1.7,104.08],[2,1.72,71.02]],"ltp":1.57,"tv":1235.39,"id":35736920}],"tv":1337.96}]}
{"op":"mcm","clk":"12000251022","pt":1725071929502,"mc":[{"id":"1.232283786","rc":[{"trd":[[1.57,127.96]],"batb":[[0,1.58,5.47],[1,1.55,117.3],[2,1.52,211.19]],"batl":[[0,1.7,104.08],[1,1.72,71.02],[2,1.72,0]],"ltp":1.57,"tv":1246.07,"id":35736920}],"tv":1348.64}]}
{"op":"mcm","clk":"12000251240","pt":1725071932905,"mc":[{"id":"1.232283786","rc":[{"batb":[[0,1.56,5.57]],"ltp":1.57,"tv":1246.07,"id":35736920}]}]}
{"op":"mcm","clk":"12000253241","pt":1725071964017,"mc":[{"id":"1.232283786","rc":[{"batb":[[0,1.56,15.51]],"ltp":1.57,"tv":1246.07,"id":35736920}]}]}
{"op":"mcm","clk":"12000255070","pt":1725071995126,"mc":[{"id":"1.232283786","rc":[{"batb":[[0,1.57,8.38],[1,1.56,15.51],[2,1.55,117.3]],"ltp":1.57,"tv":1246.07,"id":35736920}]}]}
{"op":"mcm","clk":"12000277128","pt":1725072309410,"mc":[{"id":"1.232283786","rc":[{"trd":[[1.69,368.68]],"batb":[[0,1.69,5.34],[1,1.57,8.38],[2,1.56,15.51]],"ltp":1.69,"tv":1363.35,"id":35736920}],"tv":1465.92}]}
{"op":"mcm","clk":"12000277190","pt":1725072310231,"mc":[{"id":"1.232283786","rc":[{"batb":[[2,1.56,5.57]],"ltp":1.69,"tv":1363.35,"id":35736920}]}]}
{"op":"mcm","clk":"12000277263","pt":1725072311262,"mc":[{"id":"1.232283786","rc":[{"batb":[[0,1.57,8.38],[1,1.56,5.57],[2,1.55,117.3]],"ltp":1.69,"tv":1363.35,"id":35736920}]}]}
{"op":"mcm","clk":"12000277394","pt":1725072312756,"mc":[{"id":"1.232283786","rc":[{"batb":[[1,1.56,15.09]],"ltp":1.69,"tv":1363.35,"id":35736920}]}]}
{"op":"mcm","clk":"12000278798","pt":1725072332938,"mc":[{"id":"1.232283786","rc":[{"trd":[[1.69,381.24]],"batb":[[0,1.57,8.95]],"ltp":1.69,"tv":1375.91,"id":35736920}],"tv":1478.48}]}
{"op":"mcm","clk":"12000278879","pt":1725072334172,"mc":[{"id":"1.232283786","rc":[{"batb":[[1,1.56,5.57]],"ltp":1.69,"tv":1375.91,"id":35736920}]}]}
{"op":"mcm","clk":"12000278926","pt":1725072334942,"mc":[{"id":"1.232283786","rc":[{"batb":[[0,1.57,8.38]],"ltp":1.69,"tv":1375.91,"id":35736920}]}]}
