{"op":"mcm","clk":"11924200469","pt":1724623783774,"mc":[{"id":"1.232283868","marketDefinition":{"bspMarket":false,"turnInPlayEnabled":true,"persistenceEnabled":true,"marketBaseRate":5.0,"eventId":"33527208","eventTypeId":"4","numberOfWinners":1,"bettingType":"ODDS","marketType":"MATCH_ODDS","marketTime":"2024-08-30T06:00:00.000Z","suspendTime":"2024-08-30T06:00:00.000Z","bspReconciled":false,"complete":true,"inPlay":false,"crossMatching":false,"runnersVoidable":false,"numberOfActiveRunners":2,"betDelay":0,"status":"OPEN","runners":[{"status":"ACTIVE","sortPriority":1,"id":2857968,"name":"Malaysia"},{"status":"ACTIVE","sortPriority":2,"id":8858707,"name":"Maldives"}],"regulators":["MR_INT"],"countryCode":"GB","discountAllowed":false,"timezone":"GMT","openDate":"2024-08-30T06:00:00.000Z","version":6100693392,"name":"Match Odds","eventName":"Malaysia v Maldives"},"rc":[{"batb":[[0,1.03,200],[1,1.02,200],[2,1.01,220]],"ltp":0.0,"tv":0.0,"id":8858707},{"batb":[[0,1.03,200],[1,1.02,200],[2,1.01,220]],"ltp":0.0,"tv":0.0,"id":2857968}]}]}
{"op":"mcm","clk":"11924200566","pt":1724623785114,"mc":[{"id":"1.232283868","marketDefinition":{"bspMarket":false,"turnInPlayEnabled":true,"persistenceEnabled":true,"marketBaseRate":5.0,"eventId":"33527208","eventTypeId":"4","numberOfWinners":1,"bettingType":"ODDS","marketType":"MATCH_ODDS","marketTime":"2024-08-30T06:00:00.000Z","suspendTime":"2024-08-30T06:00:00.000Z","bspReconciled":false,"complete":true,"inPlay":false,"crossMatching":false,"runnersVoidable":false,"numberOfActiveRunners":2,"betDelay":0,"status":"OPEN","runners":[{"status":"ACTIVE","sortPriority":1,"id":2857968,"name":"Malaysia"},{"status":"ACTIVE","sortPriority":2,"id":8858707,"name":"Maldives"}],"regulators":["MR_INT"],"countryCode":"GB","discountAllowed":true,"timezone":"GMT","openDate":"2024-08-30T06:00:00.000Z","version":6100693392,"name":"Match Odds","eventName":"Malaysia v Maldives"}}]}
{"op":"mcm","clk":"11924325104","pt":1724625549002,"mc":[{"id":"1.232283868","rc":[{"batb":[[2,1.01,220.76]],"ltp":0.0,"tv":0.0,"id":8858707},{"batb":[[2,1.01,220.76]],"ltp":0.0,"tv":0.0,"id":2857968}]}]}
{"op":"mcm","clk":"11924856748","pt":1724634087673,"mc":[{"id":"1.232283868","rc":[{"batb":[[0,1.11,3.87],[1,1.03,200],[2,1.02,200]],"ltp":0.0,"tv":0.0,"id":8858707}]}]}
{"op":"mcm","clk":"11924857621","pt":1724634098152,"mc":[{"id":"1.232283868","marketDefinition":{"bspMarket":false,"turnInPlayEnabled":true,"persistenceEnabled":true,"marketBaseRate":5.0,"eventId":"33527208","eventTypeId":"4","numberOfWinners":1,"bettingType":"ODDS","marketType":"MATCH_ODDS","marketTime":"2024-08-30T06:00:00.000Z","suspendTime":"2024-08-30T06:00:00.000Z","bspReconciled":false,"complete":true,"inPlay":false,"crossMatching":true,"runnersVoidable":false,"numberOfActiveRunners":2,"betDelay":0,"status":"OPEN","runners":[{"status":"ACTIVE","sortPriority":1,"id":2857968,"name":"Malaysia"},{"status":"ACTIVE","sortPriority":2,"id":8858707,"name":"Maldives"}],"regulators":["MR_INT"],"countryCode":"GB","discountAllowed":true,"timezone":"GMT","openDate":"2024-08-30T06:00:00.000Z","version":6100693392,"name":"Match Odds","eventName":"Malaysia v Maldives"}}]}
{"op":"mcm","clk":"11925116332","pt":1724639470663,"mc":[{"id":"1.232283868","rc":[{"batb":[[0,1.11,3.87]],"ltp":0.0,"tv":0.0,"id":8858707},{"batb":[[2,1.01,480.8]],"ltp":0.0,"tv":0.0,"id":2857968}]}]}
{"op":"mcm","clk":"11925356870","pt":1724644558889,"mc":[{"id":"1.232283868","rc":[{"batb":[[0,1.11,5.99]],"ltp":0.0,"tv":0.0,"id":8858707},{"batb":[[2,1.01,480.83]],"ltp":0.0,"tv":0.0,"id":2857968}]}]}
{"op":"mcm","clk":"11925405786","pt":1724645574813,"mc":[{"id":"1.232283868","rc":[{"batb":[[0,1.11,5.99]],"ltp":0.0,"tv":0.0,"id":8858707},{"batb":[[2,1.01,480.79]],"ltp":0.0,"tv":0.0,"id":2857968}]}]}
{"op":"mcm","clk":"11925507645","pt":1724647520382,"mc":[{"id":"1.232283868","marketDefinition":{"bspMarket":false,"turnInPlayEnabled":true,"persistenceEnabled":true,"marketBaseRate":5.0,"eventId":"33527208","eventTypeId":"4","numberOfWinners":1,"bettingType":"ODDS","marketType":"MATCH_ODDS","marketTime":"2024-08-30T01:30:00.000Z","suspendTime":"2024-08-30T01:30:00.000Z","bspReconciled":false,"complete":true,"inPlay":false,"crossMatching":true,"runnersVoidable":false,"numberOfActiveRunners":2,"betDelay":0,"status":"OPEN","runners":[{"status":"ACTIVE","sortPriority":1,"id":2857968,"name":"Malaysia"},{"status":"ACTIVE","sortPriority":2,"id":8858707,"name":"Maldives"}],"regulators":["MR_INT"],"countryCode":"GB","discountAllowed":true,"timezone":"GMT","openDate":"2024-08-30T06:00:00.000Z","version":6101005059,"name":"Match Odds","eventName":"Malaysia v Maldives"}}]}
{"op":"mcm","clk":"11925507758","pt":1724647522392,"mc":[{"id":"1.232283868","marketDefinition":{"bspMarket":false,"turnInPlayEnabled":true,"persistenceEnabled":true,"marketBaseRate":5.0,"eventId":"33527208","eventTypeId":"4","numberOfWinners":1,"bettingType":"ODDS","marketType":"MATCH_ODDS","marketTime":"2024-08-30T01:30:00.000Z","suspendTime":"2024-08-30T01:30:00.000Z","bspReconciled":false,"complete":true,"inPlay":false,"crossMatching":true,"runnersVoidable":false,"numberOfActiveRunners":2,"betDelay":0,"status":"OPEN","runners":[{"status":"ACTIVE","sortPriority":1,"id":2857968,"name":"Malaysia"},{"status":"ACTIVE","sortPriority":2,"id":8858707,"name":"Maldives"}],"regulators":["MR_INT"],"countryCode":"GB","discountAllowed":true,"timezone":"GMT","openDate":"2024-08-30T01:30:00.000Z","version":6101005059,"name":"Match Odds","eventName":"Malaysia v Maldives"}}]}
{"op":"mcm","clk":"11925669353","pt":1724650974831,"mc":[{"id":"1.232283868","rc":[{"batb":[[2,1.01,480.85]],"ltp":0.0,"tv":0.0,"id":2857968}]}]}
{"op":"mcm","clk":"11925918868","pt":1724656374811,"mc":[{"id":"1.232283868","rc":[{"batb":[[2,1.01,480.71]],"ltp":0.0,"tv":0.0,"id":2857968}]}]}
{"op":"mcm","clk":"11925968215","pt":1724657292724,"mc":[{"id":"1.232283868","rc":[{"batl":[[0,34,0.7]],"ltp":0.0,"tv":0.0,"id":2857968}]}]}
{"op":"mcm","clk":"11925969254","pt":1724657312677,"mc":[{"id":"1.232283868","rc":[{"batl":[[0,34,1.37]],"ltp":0.0,"tv":0.0,"id":2857968}]}]}
{"op":"mcm","clk":"11926161128","pt":1724661774808,"mc":[{"id":"1.232283868","rc":[{"batb":[[0,1.11,5.99]],"ltp":0.0,"tv":0.0,"id":8858707},{"batb":[[2,1.01,481.23]],"ltp":0.0,"tv":0.0,"id":2857968}]}]}
{"op":"mcm","clk":"11926398749","pt":1724667174817,"mc":[{"id":"1.232283868","rc":[{"batb":[[0,1.11,6]],"ltp":0.0,"tv":0.0,"id":8858707},{"batb":[[2,1.01,480.42]],"ltp":0.0,"tv":0.0,"id":2857968}]}]}
{"op":"mcm","clk":"11926525847","pt":1724669613820,"mc":[{"id":"1.232283868","rc":[{"batb":[[1,1.05,200],[2,1.04,250]],"ltp":0.0,"tv":0.0,"id":8858707},{"batb":[[0,1.05,200],[1,1.04,250],[2,1.03,533.33]],"ltp":0.0,"tv":0.0,"id":2857968}]}]}
{"op":"mcm","clk":"11926673952","pt":1724672574817,"mc":[{"id":"1.232283868","rc":[{"batb":[[0,1.11,5.99]],"ltp":0.0,"tv":0.0,"id":8858707}]}]}
{"op":"mcm","clk":"11926823857","pt":1724674972926,"mc":[{"id":"1.232283868","rc":[{"batb":[[0,1.11,6]],"ltp":0.0,"tv":0.0,"id":8858707},{"batl":[[0,32,1.37]],"ltp":0.0,"tv":0.0,"id":2857968}]}]}
{"op":"mcm","clk":"11926824682","pt":1724674986916,"mc":[{"id":"1.232283868","rc":[{"batl":[[0,20,1.38]],"ltp":0.0,"tv":0.0,"id":2857968}]}]}
{"op":"mcm","clk":"11926857005","pt":1724675571336,"mc":[{"id":"1.232283868","rc":[{"batb":[[0,1.12,70.91],[1,1.11,6],[2,1.05,200]],"ltp":0.0,"tv":0.0,"id":8858707},{"batb":[[0,1.06,141.83],[1,1.05,200],[2,1.04,250]],"ltp":0.0,"tv":0.0,"id":2857968}]}]}
{"op":"mcm","clk":"11926959240","pt":1724677374252,"mc":[{"id":"1.232283868","rc":[{"batb":[[0,1.11,5.99],[1,1.05,200],[2,1.04,250]],"ltp":0.0,"tv":0.0,"id":8858707},{"batb":[[0,1.05,200],[1,1.04,250],[2,1.03,533.33]],"batl":[[0,20,1.37]],"ltp":0.0,"tv":0.0,"id":2857968}]}]}
{"op":"mcm","clk":"11926970467","pt":1724677525242,"mc":[{"id":"1.232283868","rc":[{"batb":[[0,1.12,70.83],[1,1.11,5.99],[2,1.05,200]],"ltp":0.0,"tv":0.0,"id":8858707},{"batb":[[0,1.06,141.65],[1,1.05,200],[2,1.04,250]],"ltp":0.0,"tv":0.0,"id":2857968}]}]}
{"op":"mcm","clk":"11926973874","pt":1724677566917,"mc":[{"id":"1.232283868","rc":[{"batb":[[0,1.12,76.81],[1,1.05,200],[2,1.04,250]],"ltp":0.0,"tv":0.0,"id":8858707}]}]}
{"op":"mcm","clk":"11927145150","pt":1724679327023,"mc":[{"id":"1.232283868","rc":[{"batb":[[0,1.12,5.99]],"ltp":0.0,"tv":0.0,"id":8858707},{"batb":[[0,1.05,200],[1,1.04,250],[2,1.03,533.33]],"ltp":0.0,"tv":0.0,"id":2857968}]}]}
{"op":"mcm","clk":"11927160664","pt":1724679477573,"mc":[{"id":"1.232283868","rc":[{"batb":[[0,1.13,65.38],[1,1.12,5.99],[2,1.05,200]],"ltp":0.0,"tv":0.0,"id":8858707},{"batb":[[0,1.06,141.65],[1,1.05,200],[2,1.04,250]],"ltp":0.0,"tv":0.0,"id":2857968}]}]}
{"op":"mcm","clk":"11927375272","pt":1724681280542,"mc":[{"id":"1.232283868","rc":[{"batb":[[0,1.12,5.99],[1,1.05,200],[2,1.04,250]],"ltp":0.0,"tv":0.0,"id":8858707},{"batb":[[0,1.05,200],[1,1.04,250],[2,1.03,533.33]],"batl":[[0,20,1.38]],"ltp":0.0,"tv":0.0,"id":2857968}]}]}
{"op":"mcm","clk":"11927402919","pt":1724681428636,"mc":[{"id":"1.232283868","rc":[{"batb":[[0,1.13,65.44],[1,1.12,5.99],[2,1.05,200]],"ltp":0.0,"tv":0.0,"id":8858707},{"batb":[[0,1.06,141.78],[1,1.05,200],[2,1.04,250]],"ltp":0.0,"tv":0.0,"id":2857968}]}]}
{"op":"mcm","clk":"11927764793","pt":1724683229963,"mc":[{"id":"1.232283868","rc":[{"batb":[[0,1.12,5.99],[1,1.05,200],[2,1.04,250]],"ltp":0.0,"tv":0.0,"id":8858707}]}]}
{"op":"mcm","clk":"11927764851","pt":1724683230278,"mc":[{"id":"1.232283868","rc":[{"batb":[[0,1.05,200],[1,1.04,250],[2,1.03,533.33]],"ltp":0.0,"tv":0.0,"id":2857968}]}]}
{"op":"mcm","clk":"11927808998","pt":1724683385467,"mc":[{"id":"1.232283868","rc":[{"batb":[[0,1.13,65.44],[1,1.12,5.99],[2,1.05,200]],"ltp":0.0,"tv":0.0,"id":8858707},{"batb":[[0,1.06,141.78],[1,1.05,200],[2,1.04,250]],"ltp":0.0,"tv":0.0,"id":2857968}]}]}
{"op":"mcm","clk":"11928096045","pt":1724685186095,"mc":[{"id":"1.232283868","rc":[{"batb":[[0,1.12,5.99],[1,1.05,200],[2,1.04,250]],"ltp":0.0,"tv":0.0,"id":8858707},{"batb":[[0,1.05,200],[1,1.04,250],[2,1.03,533.33]],"batl":[[0,20,1.37]],"ltp":0.0,"tv":0.0,"id":2857968}]}]}
{"op":"mcm","clk":"11928123435","pt":1724685330426,"mc":[{"id":"1.232283868","rc":[{"batb":[[0,1.13,65.46],[1,1.12,5.99],[2,1.05,200]],"ltp":0.0,"tv":0.0,"id":8858707},{"batb":[[0,1.06,141.82],[1,1.05,200],[2,1.04,250]],"ltp":0.0,"tv":0.0,"id":2857968}]}]}
{"op":"mcm","clk":"11928455800","pt":1724687133397,"mc":[{"id":"1.232283868","rc":[{"batb":[[0,1.12,5.99],[1,1.05,200],[2,1.04,250]],"ltp":0.0,"tv":0.0,"id":8858707},{"batb":[[0,1.05,200],[1,1.04,250],[2,1.03,533.33]],"ltp":0.0,"tv":0.0,"id":2857968}]}]}
{"op":"mcm","clk":"11928475642","pt":1724687256338,"mc":[{"id":"1.232283868","rc":[{"batb":[[0,1.13,65.46],[1,1.12,5.99],[2,1.05,200]],"ltp":0.0,"tv":0.0,"id":8858707},{"batb":[[0,1.06,141.82],[1,1.05,200],[2,1.04,250]],"ltp":0.0,"tv":0.0,"id":2857968}]}]}
{"op":"mcm","clk":"11928608181","pt":1724688334878,"mc":[{"id":"1.232283868","rc":[{"batb":[[0,1.13,65.48],[1,1.12,5.99]],"ltp":0.0,"tv":0.0,"id":8858707},{"batb":[[0,1.06,141.88]],"batl":[[0,8.6,1.32],[1,20,0.67]],"ltp":0.0,"tv":0.0,"id":2857968}]}]}
{"op":"mcm","clk":"11928703151","pt":1724689057484,"mc":[{"id":"1.232283868","rc":[{"batb":[[0,1.12,5.99],[1,1.05,200],[2,1.04,250]],"ltp":0.0,"tv":0.0,"id":8858707},{"batb":[[0,1.05,200],[1,1.04,250],[2,1.03,533.33]],"ltp":0.0,"tv":0.0,"id":2857968}]}]}
{"op":"mcm","clk":"11928711564","pt":1724689128426,"mc":[{"id":"1.232283868","rc":[{"batb":[[0,1.14,60.81],[1,1.12,5.99],[2,1.05,200]],"ltp":0.0,"tv":0.0,"id":8858707},{"batb":[[0,1.06,141.88],[1,1.05,200],[2,1.04,250]],"ltp":0.0,"tv":0.0,"id":2857968}]}]}
{"op":"mcm","clk":"11928923382","pt":1724690929818,"mc":[{"id":"1.232283868","rc":[{"batb":[[0,1.12,5.99],[1,1.05,200],[2,1.04,250]],"ltp":0.0,"tv":0.0,"id":8858707},{"batb":[[0,1.05,200],[1,1.04,250],[2,1.03,533.33]],"ltp":0.0,"tv":0.0,"id":2857968}]}]}
{"op":"mcm","clk":"11928926363","pt":1724690954655,"mc":[{"id":"1.232283868","rc":[{"batb":[[0,1.14,60.81],[1,1.12,5.99],[2,1.05,200]],"ltp":0.0,"tv":0.0,"id":8858707},{"batb":[[0,1.06,141.88],[1,1.05,200],[2,1.04,250]],"ltp":0.0,"tv":0.0,"id":2857968}]}]}
{"op":"mcm","clk":"11929124319","pt":1724692613706,"mc":[{"id":"1.232283868","rc":[{"batb":[[0,1.15,15],[1,1.14,60.78],[2,1.12,5.99]],"ltp":0.0,"tv":0.0,"id":8858707},{"batb":[[0,1.07,20],[1,1.06,141.82],[2,1.05,200]],"batl":[[0,8.6,1.32]],"ltp":0.0,"tv":0.0,"id":2857968}]}]}
{"op":"mcm","clk":"11929144126","pt":1724692756992,"mc":[{"id":"1.232283868","rc":[{"batb":[[1,1.12,5.99],[2,1.05,200]],"ltp":0.0,"tv":0.0,"id":8858707},{"batb":[[1,1.05,200],[2,1.04,250]],"ltp":0.0,"tv":0.0,"id":2857968}]}]}
{"op":"mcm","clk":"11929146542","pt":1724692775807,"mc":[{"id":"1.232283868","rc":[{"batb":[[0,1.16,53.18],[1,1.15,15],[2,1.12,5.99]],"ltp":0.0,"tv":0.0,"id":8858707},{"batb":[[0,1.08,106.37],[1,1.07,20],[2,1.05,200]],"ltp":0.0,"tv":0.0,"id":2857968}]}]}
{"op":"mcm","clk":"11929410422","pt":1724694577752,"mc":[{"id":"1.232283868","rc":[{"batb":[[0,1.15,15],[1,1.12,5.99],[2,1.05,200]],"ltp":0.0,"tv":0.0,"id":8858707},{"batb":[[0,1.07,20],[1,1.05,200],[2,1.04,250]],"ltp":0.0,"tv":0.0,"id":2857968}]}]}
{"op":"mcm","clk":"11929410758","pt":1724694580251,"mc":[{"id":"1.232283868","rc":[{"batb":[[0,1.16,53.18],[1,1.15,15],[2,1.12,5.99]],"ltp":0.0,"tv":0.0,"id":8858707},{"batb":[[0,1.08,106.37],[1,1.07,20],[2,1.05,200]],"ltp":0.0,"tv":0.0,"id":2857968}]}]}
{"op":"mcm","clk":"11929651253","pt":1724696383500,"mc":[{"id":"1.232283868","rc":[{"batb":[[0,1.15,15],[1,1.12,5.99],[2,1.05,200]],"ltp":0.0,"tv":0.0,"id":8858707},{"batb":[[0,1.07,20],[1,1.05,200],[2,1.04,250]],"ltp":0.0,"tv":0.0,"id":2857968}]}]}
{"op":"mcm","clk":"11929672461","pt":1724696543750,"mc":[{"id":"1.232283868","rc":[{"batb":[[0,1.16,53.19],[1,1.15,15],[2,1.12,5.99]],"ltp":0.0,"tv":0.0,"id":8858707},{"batb":[[0,1.08,106.38],[1,1.07,20],[2,1.05,200]],"ltp":0.0,"tv":0.0,"id":2857968}]}]}
{"op":"mcm","clk":"11929896151","pt":1724698344699,"mc":[{"id":"1.232283868","rc":[{"batb":[[0,1.15,15],[1,1.12,5.99],[2,1.05,200]],"ltp":0.0,"tv":0.0,"id":8858707},{"batb":[[0,1.07,20],[1,1.05,200],[2,1.04,250]],"ltp":0.0,"tv":0.0,"id":2857968}]}]}
{"op":"mcm","clk":"11929910893","pt":1724698473842,"mc":[{"id":"1.232283868","rc":[{"batb":[[0,1.16,53.19],[1,1.15,15],[2,1.12,5.99]],"ltp":0.0,"tv":0.0,"id":8858707},{"batb":[[0,1.08,106.38],[1,1.07,20],[2,1.05,200]],"ltp":0.0,"tv":0.0,"id":2857968}]}]}
{"op":"mcm","clk":"11930032577","pt":1724699574824,"mc":[{"id":"1.232283868","rc":[{"batb":[[0,1.16,53.18],[2,1.12,5.99]],"ltp":0.0,"tv":0.0,"id":8858707},{"batb":[[0,1.08,106.35]],"ltp":0.0,"tv":0.0,"id":2857968}]}]}
{"op":"mcm","clk":"11930129160","pt":1724700275440,"mc":[{"id":"1.232283868","rc":[{"batb":[[0,1.15,15],[1,1.12,5.99],[2,1.05,200]],"ltp":0.0,"tv":0.0,"id":8858707},{"batb":[[0,1.07,20],[1,1.05,200],[2,1.04,250]],"ltp":0.0,"tv":0.0,"id":2857968}]}]}
{"op":"mcm","clk":"11930139115","pt":1724700356023,"mc":[{"id":"1.232283868","rc":[{"batb":[[0,1.16,53.18],[1,1.15,15],[2,1.12,5.99]],"ltp":0.0,"tv":0.0,"id":8858707},{"batb":[[0,1.08,106.35],[1,1.07,20],[2,1.05,200]],"ltp":0.0,"tv":0.0,"id":2857968}]}]}
{"op":"mcm","clk":"11930326606","pt":1724702157995,"mc":[{"id":"1.232283868","rc":[{"batb":[[0,1.15,15],[1,1.12,5.99],[2,1.05,200]],"ltp":0.0,"tv":0.0,"id":8858707}]}]}
{"op":"mcm","clk":"11930326636","pt":1724702158258,"mc":[{"id":"1.232283868","rc":[{"batb":[[0,1.07,20],[1,1.05,200],[2,1.04,250]],"ltp":0.0,"tv":0.0,"id":2857968}]}]}
{"op":"mcm","clk":"11930331223","pt":1724702211754,"mc":[{"id":"1.232283868","rc":[{"batb":[[0,1.16,53.18],[1,1.15,15],[2,1.12,5.99]],"ltp":0.0,"tv":0.0,"id":8858707},{"batb":[[0,1.08,106.35],[1,1.07,20],[2,1.05,200]],"ltp":0.0,"tv":0.0,"id":2857968}]}]}
{"op":"mcm","clk":"11930495666","pt":1724704013094,"mc":[{"id":"1.232283868","rc":[{"batb":[[0,1.16,53.19],[2,1.12,6]],"ltp":0.0,"tv":0.0,"id":8858707},{"batb":[[0,1.07,20],[1,1.05,200],[2,1.04,250]],"ltp":0.0,"tv":0.0,"id":2857968}]}]}
{"op":"mcm","clk":"11930495688","pt":1724704013297,"mc":[{"id":"1.232283868","rc":[{"batb":[[0,1.15,15],[1,1.12,6],[2,1.05,200]],"ltp":0.0,"tv":0.0,"id":8858707}]}]}
{"op":"mcm","clk":"11930497156","pt":1724704027632,"mc":[{"id":"1.232283868","rc":[{"batb":[[0,1.16,53.19],[1,1.15,15],[2,1.12,6]],"ltp":0.0,"tv":0.0,"id":8858707},{"batb":[[0,1.08,106.37],[1,1.07,20],[2,1.05,200]],"ltp":0.0,"tv":0.0,"id":2857968}]}]}
{"op":"mcm","clk":"11930665169","pt":1724705829708,"mc":[{"id":"1.232283868","rc":[{"batb":[[0,1.15,15],[1,1.12,6],[2,1.05,200]],"ltp":0.0,"tv":0.0,"id":8858707},{"batb":[[0,1.07,20],[1,1.05,200],[2,1.04,250]],"ltp":0.0,"tv":0.0,"id":2857968}]}]}
{"op":"mcm","clk":"11930676171","pt":1724705985830,"mc":[{"id":"1.232283868","rc":[{"batb":[[0,1.16,53.19],[1,1.15,15],[2,1.12,6]],"ltp":0.0,"tv":0.0,"id":8858707},{"batb":[[0,1.08,106.37],[1,1.07,20],[2,1.05,200]],"ltp":0.0,"tv":0.0,"id":2857968}]}]}
{"op":"mcm","clk":"11930784042","pt":1724707787410,"mc":[{"id":"1.232283868","rc":[{"batb":[[0,1.15,15],[1,1.12,5.99],[2,1.05,200]],"ltp":0.0,"tv":0.0,"id":8858707},{"batb":[[0,1.07,20],[1,1.05,200],[2,1.04,250]],"ltp":0.0,"tv":0.0,"id":2857968}]}]}
{"op":"mcm","clk":"11930790712","pt":1724707894839,"mc":[{"id":"1.232283868","rc":[{"batb":[[0,1.16,53.18],[1,1.15,15],[2,1.12,5.99]],"ltp":0.0,"tv":0.0,"id":8858707},{"batb":[[0,1.08,106.35],[1,1.07,20],[2,1.05,200]],"ltp":0.0,"tv":0.0,"id":2857968}]}]}
{"op":"mcm","clk":"11930897691","pt":1724709696354,"mc":[{"id":"1.232283868","rc":[{"batb":[[0,1.15,15],[1,1.12,5.99],[2,1.05,200]],"ltp":0.0,"tv":0.0,"id":8858707},{"batb":[[0,1.07,20],[1,1.05,200],[2,1.04,250]],"ltp":0.0,"tv":0.0,"id":2857968}]}]}
{"op":"mcm","clk":"11930901925","pt":1724709786532,"mc":[{"id":"1.232283868","rc":[{"batb":[[0,1.16,53.17],[1,1.15,15],[2,1.12,5.99]],"ltp":0.0,"tv":0.0,"id":8858707},{"batb":[[0,1.08,106.33],[1,1.07,20],[2,1.05,200]],"ltp":0.0,"tv":0.0,"id":2857968}]}]}
{"op":"mcm","clk":"11930992733","pt":1724711587278,"mc":[{"id":"1.232283868","rc":[{"batb":[[0,1.15,15],[1,1.12,5.99],[2,1.05,200]],"ltp":0.0,"tv":0.0,"id":8858707},{"batb":[[0,1.07,20],[1,1.05,200],[2,1.04,250]],"ltp":0.0,"tv":0.0,"id":2857968}]}]}
{"op":"mcm","clk":"11930995743","pt":1724711649534,"mc":[{"id":"1.232283868","rc":[{"batb":[[0,1.16,53.17],[1,1.15,15],[2,1.12,5.99]],"ltp":0.0,"tv":0.0,"id":8858707},{"batb":[[0,1.08,106.33],[1,1.07,20],[2,1.05,200]],"ltp":0.0,"tv":0.0,"id":2857968}]}]}
{"op":"mcm","clk":"11931083558","pt":1724713450649,"mc":[{"id":"1.232283868","rc":[{"batb":[[0,1.15,15],[1,1.12,5.99],[2,1.05,200]],"ltp":0.0,"tv":0.0,"id":8858707},{"batb":[[0,1.07,20],[1,1.05,200],[2,1.04,250]],"ltp":0.0,"tv":0.0,"id":2857968}]}]}
{"op":"mcm","clk":"11931086981","pt":1724713501799,"mc":[{"id":"1.232283868","rc":[{"batb":[[0,1.16,53.18],[1,1.15,15],[2,1.12,5.99]],"ltp":0.0,"tv":0.0,"id":8858707},{"batb":[[0,1.08,106.36],[1,1.07,20],[2,1.05,200]],"ltp":0.0,"tv":0.0,"id":2857968}]}]}
{"op":"mcm","clk":"11931203792","pt":1724715303057,"mc":[{"id":"1.232283868","rc":[{"batb":[[0,1.15,15],[1,1.12,5.99],[2,1.05,200]],"ltp":0.0,"tv":0.0,"id":8858707}]}]}
{"op":"mcm","clk":"11931203805","pt":1724715303261,"mc":[{"id":"1.232283868","rc":[{"batb":[[0,1.07,20],[1,1.05,200],[2,1.04,250]],"ltp":0.0,"tv":0.0,"id":2857968}]}]}
{"op":"mcm","clk":"11931206238","pt":1724715341096,"mc":[{"id":"1.232283868","rc":[{"batb":[[0,1.16,53.18],[1,1.15,15],[2,1.12,5.99]],"ltp":0.0,"tv":0.0,"id":8858707},{"batb":[[0,1.08,106.36],[1,1.07,20],[2,1.05,200]],"ltp":0.0,"tv":0.0,"id":2857968}]}]}
{"op":"mcm","clk":"11931326124","pt":1724717142053,"mc":[{"id":"1.232283868","rc":[{"batb":[[0,1.15,15],[1,1.12,5.99],[2,1.05,200]],"ltp":0.0,"tv":0.0,"id":8858707},{"batb":[[0,1.07,20],[1,1.05,200],[2,1.04,250]],"ltp":0.0,"tv":0.0,"id":2857968}]}]}
{"op":"mcm","clk":"11931327549","pt":1724717164017,"mc":[{"id":"1.232283868","rc":[{"batb":[[0,1.16,53.17],[1,1.15,15],[2,1.12,5.99]],"ltp":0.0,"tv":0.0,"id":8858707},{"batb":[[0,1.08,106.35],[1,1.07,20],[2,1.05,200]],"ltp":0.0,"tv":0.0,"id":2857968}]}]}
{"op":"mcm","clk":"11931446930","pt":1724718965837,"mc":[{"id":"1.232283868","rc":[{"batb":[[0,1.15,15],[1,1.12,5.99],[2,1.05,200]],"ltp":0.0,"tv":0.0,"id":8858707},{"batb":[[0,1.07,20],[1,1.05,200],[2,1.04,250]],"ltp":0.0,"tv":0.0,"id":2857968}]}]}
{"op":"mcm","clk":"11931447520","pt":1724718974959,"mc":[{"id":"1.232283868","rc":[{"batb":[[0,1.16,53.17],[1,1.15,15],[2,1.12,5.99]],"ltp":0.0,"tv":0.0,"id":8858707},{"batb":[[0,1.08,106.35],[1,1.07,20],[2,1.05,200]],"ltp":0.0,"tv":0.0,"id":2857968}]}]}
{"op":"mcm","clk":"11931546187","pt":1724720777839,"mc":[{"id":"1.232283868","rc":[{"batb":[[0,1.15,15],[1,1.12,5.99],[2,1.05,200]],"ltp":0.0,"tv":0.0,"id":8858707},{"batb":[[0,1.07,20],[1,1.05,200],[2,1.04,250]],"ltp":0.0,"tv":0.0,"id":2857968}]}]}
{"op":"mcm","clk":"11931546269","pt":1724720779228,"mc":[{"id":"1.232283868","rc":[{"batb":[[0,1.16,53.19],[1,1.15,15],[2,1.12,5.99]],"ltp":0.0,"tv":0.0,"id":8858707},{"batb":[[0,1.08,106.39],[1,1.07,20],[2,1.05,200]],"ltp":0.0,"tv":0.0,"id":2857968}]}]}
{"op":"mcm","clk":"11931632808","pt":1724722490898,"mc":[{"id":"1.232283868","rc":[{"batb":[[0,1.24,5.99],[1,1.16,53.19],[2,1.15,15]],"ltp":0.0,"tv":0.0,"id":8858707}]}]}
{"op":"mcm","clk":"11931636842","pt":1724722582071,"mc":[{"id":"1.232283868","rc":[{"batb":[[1,1.15,15],[2,1.05,200]],"ltp":0.0,"tv":0.0,"id":8858707},{"batb":[[0,1.07,20],[1,1.05,200],[2,1.04,250]],"ltp":0.0,"tv":0.0,"id":2857968}]}]}
{"op":"mcm","clk":"11931643232","pt":1724722712423,"mc":[{"id":"1.232283868","rc":[{"batb":[[0,1.25,34.04],[1,1.24,5.99],[2,1.15,15]],"ltp":0.0,"tv":0.0,"id":8858707},{"batb":[[0,1.08,106.39],[1,1.07,20],[2,1.05,200]],"ltp":0.0,"tv":0.0,"id":2857968}]}]}
{"op":"mcm","clk":"11931708810","pt":1724724513583,"mc":[{"id":"1.232283868","rc":[{"batb":[[0,1.24,5.99],[1,1.15,15],[2,1.05,200]],"ltp":0.0,"tv":0.0,"id":8858707},{"batb":[[0,1.07,20],[1,1.05,200],[2,1.04,250]],"batl":[[0,8.6,1.32]],"ltp":0.0,"tv":0.0,"id":2857968}]}]}
{"op":"mcm","clk":"11931712583","pt":1724724621526,"mc":[{"id":"1.232283868","rc":[{"batb":[[0,1.25,34.04],[1,1.24,5.99],[2,1.15,15]],"ltp":0.0,"tv":0.0,"id":8858707},{"batb":[[0,1.08,106.37],[1,1.07,20],[2,1.05,200]],"ltp":0.0,"tv":0.0,"id":2857968}]}]}
{"op":"mcm","clk":"11931726654","pt":1724725023774,"mc":[{"id":"1.232283868","rc":[{"batl":[[1,20,0]],"ltp":0.0,"tv":0.0,"id":2857968}]}]}
{"op":"mcm","clk":"11931779829","pt":1724726422726,"mc":[{"id":"1.232283868","rc":[{"batb":[[0,1.24,5.99],[1,1.15,15],[2,1.05,200]],"ltp":0.0,"tv":0.0,"id":8858707},{"batb":[[0,1.07,20],[1,1.05,200],[2,1.04,250]],"ltp":0.0,"tv":0.0,"id":2857968}]}]}
{"op":"mcm","clk":"11931783224","pt":1724726513987,"mc":[{"id":"1.232283868","rc":[{"batb":[[0,1.25,34.04],[1,1.24,5.99],[2,1.15,15]],"ltp":0.0,"tv":0.0,"id":8858707},{"batb":[[0,1.08,106.37],[1,1.07,20],[2,1.05,200]],"ltp":0.0,"tv":0.0,"id":2857968}]}]}
{"op":"mcm","clk":"11931843366","pt":1724727844680,"mc":[{"id":"1.232283868","rc":[{"batb":[[0,1.25,34.04],[1,1.15,15],[2,1.05,200]],"ltp":0.0,"tv":0.0,"id":8858707},{"batb":[[0,1.08,106.39]],"ltp":0.0,"tv":0.0,"id":2857968}]}]}
{"op":"mcm","clk":"11931856714","pt":1724728314522,"mc":[{"id":"1.232283868","rc":[{"batb":[[0,1.15,15],[1,1.05,200],[2,1.04,250]],"ltp":0.0,"tv":0.0,"id":8858707},{"batb":[[0,1.07,20],[1,1.05,200],[2,1.04,250]],"ltp":0.0,"tv":0.0,"id":2857968}]}]}
{"op":"mcm","clk":"11931858799","pt":1724728380799,"mc":[{"id":"1.232283868","rc":[{"batb":[[0,1.16,53.19],[1,1.15,15],[2,1.05,200]],"ltp":0.0,"tv":0.0,"id":8858707},{"batb":[[0,1.08,106.39],[1,1.07,20],[2,1.05,200]],"ltp":0.0,"tv":0.0,"id":2857968}]}]}
{"op":"mcm","clk":"11931918193","pt":1724730182080,"mc":[{"id":"1.232283868","rc":[{"batb":[[0,1.07,20],[1,1.05,200],[2,1.04,250]],"ltp":0.0,"tv":0.0,"id":2857968}]}]}
{"op":"mcm","clk":"11931918198","pt":1724730182285,"mc":[{"id":"1.232283868","rc":[{"batb":[[0,1.15,15],[1,1.05,200],[2,1.04,250]],"ltp":0.0,"tv":0.0,"id":8858707}]}]}
{"op":"mcm","clk":"11931919679","pt":1724730231667,"mc":[{"id":"1.232283868","rc":[{"batb":[[0,1.16,53.19],[1,1.15,15],[2,1.05,200]],"ltp":0.0,"tv":0.0,"id":8858707},{"batb":[[0,1.08,106.39],[1,1.07,20],[2,1.05,200]],"ltp":0.0,"tv":0.0,"id":2857968}]}]}
{"op":"mcm","clk":"11931985819","pt":1724731974802,"mc":[{"id":"1.232283868","rc":[{"batb":[[0,1.16,53.19]],"ltp":0.0,"tv":0.0,"id":8858707},{"batb":[[0,1.08,106.38]],"ltp":0.0,"tv":0.0,"id":2857968}]}]}
{"op":"mcm","clk":"11931996753","pt":1724732032058,"mc":[{"id":"1.232283868","rc":[{"batb":[[0,1.15,15],[1,1.05,200],[2,1.04,250]],"ltp":0.0,"tv":0.0,"id":8858707}]}]}
{"op":"mcm","clk":"11931996764","pt":1724732032259,"mc":[{"id":"1.232283868","rc":[{"batb":[[0,1.07,20],[1,1.05,200],[2,1.04,250]],"ltp":0.0,"tv":0.0,"id":2857968}]}]}
{"op":"mcm","clk":"11931997934","pt":1724732071025,"mc":[{"id":"1.232283868","rc":[{"batb":[[0,1.16,53.19],[1,1.15,15],[2,1.05,200]],"ltp":0.0,"tv":0.0,"id":8858707},{"batb":[[0,1.08,106.38],[1,1.07,20],[2,1.05,200]],"ltp":0.0,"tv":0.0,"id":2857968}]}]}
{"op":"mcm","clk":"11932026718","pt":1724732882634,"mc":[{"id":"1.232283868","rc":[{"batb":[[0,1.2,1.76],[1,1.16,53.19],[2,1.15,15]],"ltp":0.0,"tv":0.0,"id":8858707}]}]}
{"op":"mcm","clk":"11932062880","pt":1724733871320,"mc":[{"id":"1.232283868","rc":[{"batb":[[1,1.15,15],[2,1.05,200]],"ltp":0.0,"tv":0.0,"id":8858707},{"batb":[[0,1.07,20],[1,1.05,200],[2,1.04,250]],"ltp":0.0,"tv":0.0,"id":2857968}]}]}
{"op":"mcm","clk":"11932063653","pt":1724733895489,"mc":[{"id":"1.232283868","rc":[{"batb":[[0,1.21,40.53],[1,1.2,1.76],[2,1.15,15]],"ltp":0.0,"tv":0.0,"id":8858707},{"batb":[[0,1.08,106.38],[1,1.07,20],[2,1.05,200]],"ltp":0.0,"tv":0.0,"id":2857968}]}]}
{"op":"mcm","clk":"11932125796","pt":1724735696049,"mc":[{"id":"1.232283868","rc":[{"batb":[[0,1.2,1.76],[1,1.15,15],[2,1.05,200]],"ltp":0.0,"tv":0.0,"id":8858707},{"batb":[[0,1.07,20],[1,1.05,200],[2,1.04,250]],"ltp":0.0,"tv":0.0,"id":2857968}]}]}
{"op":"mcm","clk":"11932126773","pt":1724735720602,"mc":[{"id":"1.232283868","rc":[{"batb":[[0,1.21,40.52],[1,1.2,1.76],[2,1.15,15]],"ltp":0.0,"tv":0.0,"id":8858707},{"batb":[[0,1.08,106.37],[1,1.07,20],[2,1.05,200]],"ltp":0.0,"tv":0.0,"id":2857968}]}]}
{"op":"mcm","clk":"11932184330","pt":1724737336703,"mc":[{"id":"1.232283868","rc":[{"batb":[[0,1.58,6.18],[1,1.21,40.52],[2,1.2,1.76]],"ltp":0.0,"tv":0.0,"id":8858707}]}]}
{"op":"mcm","clk":"11932185228","pt":1724737361721,"mc":[{"id":"1.232283868","rc":[{"batl":[[0,2.48,0.93]],"ltp":0.0,"tv":0.0,"id":2857968}]}]}
{"op":"mcm","clk":"11932196571","pt":1724737386670,"mc":[{"id":"1.232283868","rc":[{"batl":[[0,2.74,2.31]],"ltp":0.0,"tv":0.0,"id":2857968}]}]}
{"op":"mcm","clk":"11932202123","pt":1724737521442,"mc":[{"id":"1.232283868","rc":[{"batb":[[1,1.2,1.76],[2,1.15,15]],"ltp":0.0,"tv":0.0,"id":8858707},{"batb":[[0,1.07,20],[1,1.05,200],[2,1.04,250]],"ltp":0.0,"tv":0.0,"id":2857968}]}]}
{"op":"mcm","clk":"11932202644","pt":1724737533533,"mc":[{"id":"1.232283868","rc":[{"batb":[[0,1.59,14.42],[1,1.58,6.18],[2,1.2,1.76]],"ltp":0.0,"tv":0.0,"id":8858707},{"batb":[[0,1.08,106.37],[1,1.07,20],[2,1.05,200]],"ltp":0.0,"tv":0.0,"id":2857968}]}]}
{"op":"mcm","clk":"11932270643","pt":1724739334531,"mc":[{"id":"1.232283868","rc":[{"batb":[[0,1.58,6.18],[1,1.2,1.76],[2,1.15,15]],"ltp":0.0,"tv":0.0,"id":8858707},{"batb":[[0,1.07,20],[1,1.05,200],[2,1.04,250]],"ltp":0.0,"tv":0.0,"id":2857968}]}]}
{"op":"mcm","clk":"11932270999","pt":1724739343445,"mc":[{"id":"1.232283868","rc":[{"batb":[[0,1.59,14.42],[1,1.58,6.18],[2,1.2,1.76]],"ltp":0.0,"tv":0.0,"id":8858707},{"batb":[[0,1.08,106.33],[1,1.07,20],[2,1.05,200]],"ltp":0.0,"tv":0.0,"id":2857968}]}]}
{"op":"mcm","clk":"11932337673","pt":1724741144085,"mc":[{"id":"1.232283868","rc":[{"batb":[[0,1.58,6.18],[1,1.2,1.76],[2,1.15,15]],"ltp":0.0,"tv":0.0,"id":8858707},{"batb":[[0,1.07,20],[1,1.05,200],[2,1.04,250]],"ltp":0.0,"tv":0.0,"id":2857968}]}]}
{"op":"mcm","clk":"11932338072","pt":1724741154330,"mc":[{"id":"1.232283868","rc":[{"batb":[[0,1.59,14.42],[1,1.58,6.18],[2,1.2,1.76]],"ltp":0.0,"tv":0.0,"id":8858707},{"batb":[[0,1.08,106.33],[1,1.07,20],[2,1.05,200]],"ltp":0.0,"tv":0.0,"id":2857968}]}]}
{"op":"mcm","clk":"11932355234","pt":1724741517854,"mc":[{"id":"1.232283868","rc":[{"batb":[[0,1.59,20.6],[1,1.2,1.76],[2,1.15,15]],"ltp":0.0,"tv":0.0,"id":8858707}]}]}
{"op":"mcm","clk":"11932355495","pt":1724741523861,"mc":[{"id":"1.232283868","rc":[{"batl":[[0,2.7,2.31]],"ltp":0.0,"tv":0.0,"id":2857968}]}]}
{"op":"mcm","clk":"11932390630","pt":1724742336742,"mc":[{"id":"1.232283868","rc":[{"batb":[[0,1.59,20.6],[1,1.15,15],[2,1.05,200]],"ltp":0.0,"tv":0.0,"id":8858707},{"batb":[[0,1.08,106.3]],"ltp":0.0,"tv":0.0,"id":2857968}]}]}
{"op":"mcm","clk":"11932391194","pt":1724742349752,"mc":[{"id":"1.232283868","rc":[{"batb":[[0,1.59,21.48]],"ltp":0.0,"tv":0.0,"id":8858707}]}]}
{"op":"mcm","clk":"11932424264","pt":1724742955563,"mc":[{"id":"1.232283868","rc":[{"batb":[[0,1.59,7.06]],"ltp":0.0,"tv":0.0,"id":8858707},{"batb":[[0,1.07,20],[1,1.05,200],[2,1.04,250]],"ltp":0.0,"tv":0.0,"id":2857968}]}]}
{"op":"mcm","clk":"11932424527","pt":1724742963957,"mc":[{"id":"1.232283868","rc":[{"batb":[[0,1.6,15.05],[1,1.59,6.18],[2,1.15,15]],"ltp":0.0,"tv":0.0,"id":8858707},{"batb":[[0,1.08,106.3],[1,1.07,20],[2,1.05,200]],"ltp":0.0,"tv":0.0,"id":2857968}]}]}
{"op":"mcm","clk":"11932498857","pt":1724744764632,"mc":[{"id":"1.232283868","rc":[{"batb":[[0,1.59,7.06],[1,1.15,15],[2,1.05,200]],"ltp":0.0,"tv":0.0,"id":8858707},{"batb":[[0,1.07,20],[1,1.05,200],[2,1.04,250]],"ltp":0.0,"tv":0.0,"id":2857968}]}]}
{"op":"mcm","clk":"11932499315","pt":1724744774930,"mc":[{"id":"1.232283868","rc":[{"batb":[[0,1.6,15.05],[1,1.59,6.18],[2,1.15,15]],"ltp":0.0,"tv":0.0,"id":8858707},{"batb":[[0,1.08,106.3],[1,1.07,20],[2,1.05,200]],"ltp":0.0,"tv":0.0,"id":2857968}]}]}
{"op":"mcm","clk":"11932504306","pt":1724744878790,"mc":[{"id":"1.232283868","rc":[{"batb":[[1,1.15,15],[2,1.05,200]],"ltp":0.0,"tv":0.0,"id":8858707}]}]}
{"op":"mcm","clk":"11932577968","pt":1724746576087,"mc":[{"id":"1.232283868","rc":[{"batb":[[0,1.15,15.88],[1,1.05,200],[2,1.04,250]],"ltp":0.0,"tv":0.0,"id":8858707},{"batb":[[0,1.07,20],[1,1.05,200],[2,1.04,250]],"ltp":0.0,"tv":0.0,"id":2857968}]}]}
{"op":"mcm","clk":"11932578205","pt":1724746583196,"mc":[{"id":"1.232283868","rc":[{"batb":[[0,1.16,54.02],[1,1.15,15],[2,1.05,200]],"ltp":0.0,"tv":0.0,"id":8858707},{"batb":[[0,1.08,106.29],[1,1.07,20],[2,1.05,200]],"ltp":0.0,"tv":0.0,"id":2857968}]}]}
{"op":"mcm","clk":"11932659525","pt":1724748383981,"mc":[{"id":"1.232283868","rc":[{"batb":[[0,1.15,15.88],[1,1.05,200],[2,1.04,250]],"ltp":0.0,"tv":0.0,"id":8858707},{"batb":[[0,1.07,20],[1,1.05,200],[2,1.04,250]],"ltp":0.0,"tv":0.0,"id":2857968}]}]}
{"op":"mcm","clk":"11932659773","pt":1724748390293,"mc":[{"id":"1.232283868","rc":[{"batb":[[0,1.16,54.02],[1,1.15,15],[2,1.05,200]],"ltp":0.0,"tv":0.0,"id":8858707},{"batb":[[0,1.08,106.29],[1,1.07,20],[2,1.05,200]],"ltp":0.0,"tv":0.0,"id":2857968}]}]}
{"op":"mcm","clk":"11932736169","pt":1724750190799,"mc":[{"id":"1.232283868","rc":[{"batb":[[0,1.15,15.88],[1,1.05,200],[2,1.04,250]],"ltp":0.0,"tv":0.0,"id":8858707},{"batb":[[0,1.07,20],[1,1.05,200],[2,1.04,250]],"ltp":0.0,"tv":0.0,"id":2857968}]}]}
{"op":"mcm","clk":"11932736512","pt":1724750196719,"mc":[{"id":"1.232283868","rc":[{"batb":[[0,1.16,53.96],[1,1.15,15],[2,1.05,200]],"ltp":0.0,"tv":0.0,"id":8858707},{"batb":[[0,1.08,106.16],[1,1.07,20],[2,1.05,200]],"ltp":0.0,"tv":0.0,"id":2857968}]}]}
{"op":"mcm","clk":"11932833996","pt":1724751997902,"mc":[{"id":"1.232283868","rc":[{"batb":[[0,1.15,15.88],[1,1.05,200],[2,1.04,250]],"ltp":0.0,"tv":0.0,"id":8858707},{"batb":[[0,1.07,20],[1,1.05,200],[2,1.04,250]],"ltp":0.0,"tv":0.0,"id":2857968}]}]}
{"op":"mcm","clk":"11932842011","pt":1724752134442,"mc":[{"id":"1.232283868","rc":[{"batb":[[0,1.16,53.96],[1,1.15,15],[2,1.05,200]],"ltp":0.0,"tv":0.0,"id":8858707},{"batb":[[0,1.08,106.16],[1,1.07,20],[2,1.05,200]],"ltp":0.0,"tv":0.0,"id":2857968}]}]}
{"op":"mcm","clk":"11932944984","pt":1724753574807,"mc":[{"id":"1.232283868","rc":[{"batb":[[0,1.16,53.89]],"ltp":0.0,"tv":0.0,"id":8858707},{"batb":[[0,1.08,106.03]],"ltp":0.0,"tv":0.0,"id":2857968}]}]}
{"op":"mcm","clk":"11932985702","pt":1724753934875,"mc":[{"id":"1.232283868","rc":[{"batb":[[0,1.15,15.88],[1,1.05,200],[2,1.04,250]],"ltp":0.0,"tv":0.0,"id":8858707},{"batb":[[0,1.07,20],[1,1.05,200],[2,1.04,250]],"ltp":0.0,"tv":0.0,"id":2857968}]}]}
{"op":"mcm","clk":"11932995229","pt":1724754070959,"mc":[{"id":"1.232283868","rc":[{"batb":[[0,1.16,53.89],[1,1.15,15],[2,1.05,200]],"ltp":0.0,"tv":0.0,"id":8858707},{"batb":[[0,1.08,106.03],[1,1.07,20],[2,1.05,200]],"ltp":0.0,"tv":0.0,"id":2857968}]}]}
{"op":"mcm","clk":"11933132730","pt":1724755871665,"mc":[{"id":"1.232283868","rc":[{"batb":[[0,1.15,15.88],[1,1.05,200],[2,1.04,250]],"ltp":0.0,"tv":0.0,"id":8858707},{"batb":[[0,1.07,20],[1,1.05,200],[2,1.04,250]],"ltp":0.0,"tv":0.0,"id":2857968}]}]}
{"op":"mcm","clk":"11933144324","pt":1724756006243,"mc":[{"id":"1.232283868","rc":[{"batb":[[0,1.16,53.89],[1,1.15,15],[2,1.05,200]],"ltp":0.0,"tv":0.0,"id":8858707},{"batb":[[0,1.08,106.03],[1,1.07,20],[2,1.05,200]],"ltp":0.0,"tv":0.0,"id":2857968}]}]}
{"op":"mcm","clk":"11933296988","pt":1724757807056,"mc":[{"id":"1.232283868","rc":[{"batb":[[0,1.15,15.88],[1,1.05,200],[2,1.04,250]],"ltp":0.0,"tv":0.0,"id":8858707},{"batb":[[0,1.07,20],[1,1.05,200],[2,1.04,250]],"ltp":0.0,"tv":0.0,"id":2857968}]}]}
{"op":"mcm","clk":"11933307063","pt":1724757930569,"mc":[{"id":"1.232283868","rc":[{"batb":[[0,1.16,53.96],[1,1.15,15],[2,1.05,200]],"ltp":0.0,"tv":0.0,"id":8858707},{"batb":[[0,1.08,106.17],[1,1.07,20],[2,1.05,200]],"ltp":0.0,"tv":0.0,"id":2857968}]}]}
{"op":"mcm","clk":"11933445344","pt":1724759423756,"mc":[{"id":"1.232283868","rc":[{"batb":[[0,1.16,53.08]],"ltp":0.0,"tv":0.0,"id":8858707}]}]}
{"op":"mcm","clk":"11933447177","pt":1724759439676,"mc":[{"id":"1.232283868","rc":[{"batb":[[0,1.2,1.76],[1,1.16,53.08],[2,1.15,15]],"ltp":0.0,"tv":0.0,"id":8858707}]}]}
{"op":"mcm","clk":"11933472397","pt":1724759731080,"mc":[{"id":"1.232283868","rc":[{"batb":[[1,1.15,15],[2,1.05,200]],"ltp":0.0,"tv":0.0,"id":8858707}]}]}
{"op":"mcm","clk":"11933472421","pt":1724759731292,"mc":[{"id":"1.232283868","rc":[{"batb":[[0,1.07,20],[1,1.05,200],[2,1.04,250]],"ltp":0.0,"tv":0.0,"id":2857968}]}]}
{"op":"mcm","clk":"11933483246","pt":1724759843978,"mc":[{"id":"1.232283868","rc":[{"batb":[[0,1.21,40.44],[1,1.2,1.76],[2,1.15,15]],"ltp":0.0,"tv":0.0,"id":8858707},{"batb":[[0,1.08,106.17],[1,1.07,20],[2,1.05,200]],"ltp":0.0,"tv":0.0,"id":2857968}]}]}
{"op":"mcm","clk":"11933523283","pt":1724760344953,"mc":[{"id":"1.232283868","rc":[{"batb":[[0,1.22,15],[1,1.21,40.42],[2,1.2,1.76]],"ltp":0.0,"tv":0.0,"id":8858707},{"batb":[[0,1.09,20],[1,1.08,106.09]],"ltp":0.0,"tv":0.0,"id":2857968}]}]}
{"op":"mcm","clk":"11933586270","pt":1724761071765,"mc":[{"id":"1.232283868","rc":[{"batb":[[2,1.05,200]],"ltp":0.0,"tv":0.0,"id":8858707}]}]}
{"op":"mcm","clk":"11933633399","pt":1724761644680,"mc":[{"id":"1.232283868","rc":[{"batb":[[1,1.05,200],[2,1.04,250]],"ltp":0.0,"tv":0.0,"id":8858707},{"batb":[[1,1.05,200],[2,1.04,250]],"ltp":0.0,"tv":0.0,"id":2857968}]}]}
{"op":"mcm","clk":"11933641011","pt":1724761747605,"mc":[{"id":"1.232283868","rc":[{"batb":[[0,1.23,36.9],[1,1.22,15],[2,1.05,200]],"ltp":0.0,"tv":0.0,"id":8858707},{"batb":[[0,1.1,84.87],[1,1.09,20],[2,1.05,200]],"ltp":0.0,"tv":0.0,"id":2857968}]}]}
{"op":"mcm","clk":"11933786093","pt":1724763548110,"mc":[{"id":"1.232283868","rc":[{"batb":[[0,1.22,15],[1,1.05,200],[2,1.04,250]],"ltp":0.0,"tv":0.0,"id":8858707},{"batb":[[0,1.09,20],[1,1.05,200],[2,1.04,250]],"ltp":0.0,"tv":0.0,"id":2857968}]}]}
{"op":"mcm","clk":"11933792822","pt":1724763636024,"mc":[{"id":"1.232283868","rc":[{"batb":[[0,1.23,36.91],[1,1.22,15],[2,1.05,200]],"ltp":0.0,"tv":0.0,"id":8858707},{"batb":[[0,1.1,84.89],[1,1.09,20],[2,1.05,200]],"ltp":0.0,"tv":0.0,"id":2857968}]}]}
{"op":"mcm","clk":"11933798428","pt":1724763718703,"mc":[{"id":"1.232283868","rc":[{"batb":[[0,1.23,37.83]],"ltp":0.0,"tv":0.0,"id":8858707}]}]}
{"op":"mcm","clk":"11933799221","pt":1724763730723,"mc":[{"id":"1.232283868","rc":[{"batb":[[0,1.52,4.78],[1,1.23,36.91],[2,1.22,15]],"ltp":0.0,"tv":0.0,"id":8858707}]}]}
{"op":"mcm","clk":"11933893648","pt":1724764922915,"mc":[{"id":"1.232283868","rc":[{"batb":[[1,1.24,6.84],[2,1.23,36.91]],"ltp":0.0,"tv":0.0,"id":8858707}]}]}
{"op":"mcm","clk":"11933931880","pt":1724765436260,"mc":[{"id":"1.232283868","rc":[{"batb":[[2,1.22,15]],"ltp":0.0,"tv":0.0,"id":8858707},{"batb":[[0,1.09,20],[1,1.05,200],[2,1.04,250]],"ltp":0.0,"tv":0.0,"id":2857968}]}]}
{"op":"mcm","clk":"11933936801","pt":1724765493825,"mc":[{"id":"1.232283868","rc":[{"batb":[[0,1.53,16.94],[1,1.52,3.85],[2,1.24,6.84]],"ltp":0.0,"tv":0.0,"id":8858707},{"batb":[[0,1.1,84.89],[1,1.09,20],[2,1.05,200]],"ltp":0.0,"tv":0.0,"id":2857968}]}]}
{"op":"mcm","clk":"11933970428","pt":1724765952731,"mc":[{"id":"1.232283868","rc":[{"batb":[[0,1.54,2.68],[1,1.53,16.02],[2,1.52,3.85]],"ltp":0.0,"tv":0.0,"id":8858707}]}]}
{"op":"mcm","clk":"11934054660","pt":1724767294084,"mc":[{"id":"1.232283868","rc":[{"batb":[[0,1.54,2.68],[1,1.52,3.85],[2,1.24,6.83]],"ltp":0.0,"tv":0.0,"id":8858707},{"batb":[[0,1.1,84.87]],"ltp":0.0,"tv":0.0,"id":2857968}]}]}
{"op":"mcm","clk":"11934054681","pt":1724767294395,"mc":[{"id":"1.232283868","rc":[{"batb":[[0,1.09,20],[1,1.05,200],[2,1.04,250]],"ltp":0.0,"tv":0.0,"id":2857968}]}]}
{"op":"mcm","clk":"11934066519","pt":1724767447745,"mc":[{"id":"1.232283868","rc":[{"batb":[[0,1.55,16.35],[1,1.54,1.76],[2,1.52,3.85]],"ltp":0.0,"tv":0.0,"id":8858707},{"batb":[[0,1.1,84.87],[1,1.09,20],[2,1.05,200]],"ltp":0.0,"tv":0.0,"id":2857968}]}]}
{"op":"mcm","clk":"11934217713","pt":1724769247981,"mc":[{"id":"1.232283868","rc":[{"batb":[[0,1.09,20],[1,1.05,200],[2,1.04,250]],"ltp":0.0,"tv":0.0,"id":2857968}]}]}
{"op":"mcm","clk":"11934217731","pt":1724769248186,"mc":[{"id":"1.232283868","rc":[{"batb":[[0,1.54,2.68],[1,1.52,3.85],[2,1.22,15]],"ltp":0.0,"tv":0.0,"id":8858707}]}]}
{"op":"mcm","clk":"11934224416","pt":1724769322574,"mc":[{"id":"1.232283868","rc":[{"batb":[[2,1.04,251.05]],"ltp":0.0,"tv":0.0,"id":2857968}]}]}
{"op":"mcm","clk":"11934230796","pt":1724769398367,"mc":[{"id":"1.232283868","rc":[{"batb":[[0,1.55,16.35],[1,1.54,1.76],[2,1.52,3.85]],"ltp":0.0,"tv":0.0,"id":8858707},{"batb":[[0,1.1,84.87],[1,1.09,20],[2,1.05,200]],"ltp":0.0,"tv":0.0,"id":2857968}]}]}
{"op":"mcm","clk":"11934251770","pt":1724769652342,"mc":[{"id":"1.232283868","rc":[{"batb":[[0,1.22,135.87],[1,1.1,84.87],[2,1.09,20]],"ltp":0.0,"tv":0.0,"id":2857968}]}]}
{"op":"mcm","clk":"11934252800","pt":1724769664778,"mc":[{"id":"1.232283868","rc":[{"trd":[[1.22,245.78]],"batb":[[0,1.22,12.98]],"ltp":1.22,"tv":245.78,"id":2857968}],"tv":245.78}]}
{"op":"mcm","clk":"11934258109","pt":1724769710912,"mc":[{"id":"1.232283868","rc":[{"batb":[[0,1.6,67.94],[1,1.55,16.35],[2,1.54,1.76]],"ltp":0.0,"tv":0.0,"id":8858707}]}]}
{"op":"mcm","clk":"11934259867","pt":1724769722726,"mc":[{"id":"1.232283868","rc":[{"trd":[[1.6,135.87]],"batb":[[0,1.55,16.35],[1,1.54,1.76],[2,1.52,3.85]],"batl":[[0,1.6,0.88]],"ltp":1.6,"tv":135.87,"id":8858707}],"tv":381.65}]}
{"op":"mcm","clk":"11934261215","pt":1724769734744,"mc":[{"id":"1.232283868","rc":[{"trd":[[1.22,271.74]],"batb":[[0,1.1,84.87],[1,1.09,20],[2,1.05,200]],"batl":[[0,1.22,0.54]],"ltp":1.22,"tv":271.74,"id":2857968}],"tv":407.61}]}
{"op":"mcm","clk":"11934275788","pt":1724769778879,"mc":[{"id":"1.232283868","rc":[{"batb":[[0,1.61,35.33],[1,1.55,16.35],[2,1.54,1.76]],"ltp":1.6,"tv":135.87,"id":8858707}]}]}
{"op":"mcm","clk":"11934276468","pt":1724769787708,"mc":[{"id":"1.232283868","rc":[{"trd":[[1.61,70.65]],"batb":[[0,1.55,16.35],[1,1.54,1.76],[2,1.52,3.85]],"batl":[[0,1.61,0.93]],"ltp":1.61,"tv":206.52,"id":8858707}],"tv":478.27}]}
{"op":"mcm","clk":"11934376092","pt":1724770962206,"mc":[{"id":"1.232283868","rc":[{"trd":[[1.6,135.84],[1.61,70.64]],"batb":[[0,1.55,16.35]],"ltp":1.61,"tv":206.47,"id":8858707},{"trd":[[1.1,2],[1.22,271.68]],"batb":[[0,1.1,83.84]],"ltp":1.1,"tv":273.67,"id":2857968}],"tv":480.14}]}
{"op":"mcm","clk":"11934377310","pt":1724770974344,"mc":[{"id":"1.232283868","rc":[{"batb":[[0,1.11,5],[1,1.1,83.84],[2,1.09,20]],"batl":[[0,2,1]],"ltp":1.1,"tv":273.67,"id":2857968}]}]}
{"op":"mcm","clk":"11934377626","pt":1724770977516,"mc":[{"id":"1.232283868","rc":[{"batb":[[0,1.1,83.84],[1,1.09,20],[2,1.05,200]],"ltp":1.1,"tv":273.67,"id":2857968}]}]}
{"op":"mcm","clk":"11934379485","pt":1724770996318,"mc":[{"id":"1.232283868","rc":[{"batl":[[0,1.9,1]],"ltp":1.1,"tv":273.67,"id":2857968}]}]}
{"op":"mcm","clk":"11934402795","pt":1724771198717,"mc":[{"id":"1.232283868","rc":[{"batb":[[0,1.54,2.68],[1,1.52,3.85],[2,1.22,15]],"ltp":1.61,"tv":206.47,"id":8858707},{"batb":[[0,1.09,20],[1,1.05,200],[2,1.04,251.05]],"ltp":1.1,"tv":273.67,"id":2857968}]}]}
{"op":"mcm","clk":"11934419451","pt":1724771331917,"mc":[{"id":"1.232283868","rc":[{"batb":[[0,1.59,14.38],[1,1.54,2.68],[2,1.52,3.85]],"ltp":1.61,"tv":206.47,"id":8858707}]}]}
{"op":"mcm","clk":"11934597188","pt":1724772735322,"mc":[{"id":"1.232283868","rc":[{"batb":[[1,1.54,1.75],[2,1.22,15]],"ltp":1.61,"tv":206.47,"id":8858707}]}]}
{"op":"mcm","clk":"11934650345","pt":1724773132097,"mc":[{"id":"1.232283868","rc":[{"batb":[[0,1.54,1.75],[1,1.22,15],[2,1.05,201.04]],"ltp":1.61,"tv":206.47,"id":8858707}]}]}
{"op":"mcm","clk":"11934666893","pt":1724773253290,"mc":[{"id":"1.232283868","rc":[{"batb":[[0,1.55,15.42],[1,1.54,1.75],[2,1.22,15]],"ltp":1.61,"tv":206.47,"id":8858707}]}]}
{"op":"mcm","clk":"11934702821","pt":1724773554759,"mc":[{"id":"1.232283868","rc":[{"batb":[[0,2,3.16],[1,1.55,15.42],[2,1.54,1.75]],"ltp":1.61,"tv":206.47,"id":8858707}]}]}
{"op":"mcm","clk":"11934704682","pt":1724773571761,"mc":[{"id":"1.232283868","rc":[{"batl":[[0,1.9,1.92]],"ltp":1.1,"tv":273.67,"id":2857968}]}]}
{"op":"mcm","clk":"11934710984","pt":1724773625027,"mc":[{"id":"1.232283868","rc":[{"batl":[[0,1.9,3.08]],"ltp":1.1,"tv":273.67,"id":2857968}]}]}
{"op":"mcm","clk":"11934711887","pt":1724773632957,"mc":[{"id":"1.232283868","rc":[{"batb":[[0,2.1,3.16]],"ltp":1.61,"tv":206.47,"id":8858707}]}]}
{"op":"mcm","clk":"11934826489","pt":1724774582405,"mc":[{"id":"1.232283868","rc":[{"trd":[[1.6,135.85],[1.61,70.64]],"batb":[[1,1.55,15.42]],"ltp":1.61,"tv":206.49,"id":8858707},{"trd":[[1.22,271.7]],"ltp":1.1,"tv":273.69,"id":2857968}],"tv":480.19}]}
{"op":"mcm","clk":"11934827150","pt":1724774587615,"mc":[{"id":"1.232283868","rc":[{"batl":[[0,1.89,10],[1,1.9,3.08]],"ltp":1.1,"tv":273.69,"id":2857968}]}]}
{"op":"mcm","clk":"11934828411","pt":1724774597320,"mc":[{"id":"1.232283868","rc":[{"batl":[[0,1.8,10]],"ltp":1.1,"tv":273.69,"id":2857968}]}]}
{"op":"mcm","clk":"11934885003","pt":1724775053544,"mc":[{"id":"1.232283868","rc":[{"batb":[[1,1.54,1.76],[2,1.05,201.04]],"ltp":1.61,"tv":206.49,"id":8858707}]}]}
{"op":"mcm","clk":"11934898783","pt":1724775165957,"mc":[{"id":"1.232283868","rc":[{"batb":[[0,2.26,6.73],[1,2.1,3.16],[2,1.54,1.76]],"ltp":1.61,"tv":206.49,"id":8858707}]}]}
{"op":"mcm","clk":"11934932415","pt":1724775363786,"mc":[{"id":"1.232283868","rc":[{"batb":[[2,1.05,201.04]],"ltp":1.61,"tv":206.49,"id":8858707}]}]}
{"op":"mcm","clk":"11935131614","pt":1724776966241,"mc":[{"id":"1.232283868","rc":[{"batb":[[0,2.1,3.16],[1,1.05,201.04],[2,1.04,250]],"ltp":1.61,"tv":206.49,"id":8858707}]}]}
{"op":"mcm","clk":"11935143899","pt":1724777064433,"mc":[{"id":"1.232283868","rc":[{"batb":[[0,2.26,6.73],[1,2.1,3.16],[2,1.05,201.04]],"ltp":1.61,"tv":206.49,"id":8858707}]}]}
{"op":"mcm","clk":"11935375540","pt":1724778864758,"mc":[{"id":"1.232283868","rc":[{"trd":[[1.6,135.86],[1.61,70.65]],"batb":[[0,2.1,3.16],[1,1.05,201.04],[2,1.04,250]],"ltp":1.61,"tv":206.5,"id":8858707},{"trd":[[1.22,271.71]],"ltp":1.1,"tv":273.71,"id":2857968}],"tv":480.21}]}
{"op":"mcm","clk":"11935384777","pt":1724778935979,"mc":[{"id":"1.232283868","rc":[{"batb":[[0,2.26,6.73],[1,2.1,3.16],[2,1.05,201.04]],"ltp":1.61,"tv":206.5,"id":8858707}]}]}
{"op":"mcm","clk":"11935647150","pt":1724780736165,"mc":[{"id":"1.232283868","rc":[{"batb":[[0,2.1,3.16],[1,1.05,201.04],[2,1.04,250]],"ltp":1.61,"tv":206.5,"id":8858707}]}]}
{"op":"mcm","clk":"11935651557","pt":1724780768331,"mc":[{"id":"1.232283868","rc":[{"batb":[[0,2.26,6.73],[1,2.1,3.16],[2,1.05,201.04]],"ltp":1.61,"tv":206.5,"id":8858707}]}]}
{"op":"mcm","clk":"11935920621","pt":1724782568542,"mc":[{"id":"1.232283868","rc":[{"trd":[[1.6,135.68],[1.61,70.56]],"batb":[[0,2.1,3.15],[1,1.05,201.04],[2,1.04,250]],"ltp":1.61,"tv":206.23,"id":8858707},{"trd":[[1.22,271.37]],"batl":[[1,1.9,3.08]],"ltp":1.1,"tv":273.36,"id":2857968}],"tv":479.6}]}
{"op":"mcm","clk":"11935921880","pt":1724782575700,"mc":[{"id":"1.232283868","rc":[{"batb":[[0,2.26,6.73],[1,2.1,3.15],[2,1.05,201.04]],"ltp":1.61,"tv":206.23,"id":8858707}]}]}
{"op":"mcm","clk":"11936243848","pt":1724784376101,"mc":[{"id":"1.232283868","rc":[{"batb":[[0,2.1,3.15],[1,1.05,201.04],[2,1.04,250]],"ltp":1.61,"tv":206.23,"id":8858707}]}]}
{"op":"mcm","clk":"11936273158","pt":1724784539907,"mc":[{"id":"1.232283868","rc":[{"batb":[[0,2.26,6.73],[1,2.1,3.15],[2,1.05,201.04]],"ltp":1.61,"tv":206.23,"id":8858707}]}]}
{"op":"mcm","clk":"11936519267","pt":1724785974820,"mc":[{"id":"1.232283868","rc":[{"trd":[[1.6,135.57],[1.61,70.49]],"batb":[[0,2.26,6.73],[1,2.1,3.15]],"ltp":1.61,"tv":206.06,"id":8858707},{"trd":[[1.22,271.13]],"batl":[[1,1.9,3.08]],"ltp":1.1,"tv":273.13,"id":2857968}],"tv":479.19}]}
{"op":"mcm","clk":"11936593124","pt":1724786340151,"mc":[{"id":"1.232283868","rc":[{"batb":[[0,2.1,3.15],[1,1.05,201.04],[2,1.04,250]],"ltp":1.61,"tv":206.06,"id":8858707}]}]}
{"op":"mcm","clk":"11936612503","pt":1724786454466,"mc":[{"id":"1.232283868","rc":[{"batb":[[0,2.26,6.73],[1,2.1,3.15],[2,1.05,201.04]],"ltp":1.61,"tv":206.06,"id":8858707}]}]}
{"op":"mcm","clk":"11936911741","pt":1724788254948,"mc":[{"id":"1.232283868","rc":[{"batb":[[0,2.1,3.15],[1,1.05,201.04],[2,1.04,250]],"ltp":1.61,"tv":206.06,"id":8858707}]}]}
{"op":"mcm","clk":"11936926828","pt":1724788346853,"mc":[{"id":"1.232283868","rc":[{"batb":[[0,2.26,6.73],[1,2.1,3.15],[2,1.05,201.04]],"ltp":1.61,"tv":206.06,"id":8858707}]}]}
{"op":"mcm","clk":"11937192848","pt":1724790147612,"mc":[{"id":"1.232283868","rc":[{"trd":[[1.6,135.56],[1.61,70.49]],"batb":[[0,2.1,3.15],[1,1.05,201.04],[2,1.04,250]],"ltp":1.61,"tv":206.05,"id":8858707},{"trd":[[1.22,271.12]],"ltp":1.1,"tv":273.12,"id":2857968}],"tv":479.17}]}
{"op":"mcm","clk":"11937199818","pt":1724790207162,"mc":[{"id":"1.232283868","rc":[{"batb":[[0,2.26,6.73],[1,2.1,3.15],[2,1.05,201.04]],"ltp":1.61,"tv":206.05,"id":8858707}]}]}
{"op":"mcm","clk":"11937381059","pt":1724792008149,"mc":[{"id":"1.232283868","rc":[{"batb":[[0,2.1,3.15],[1,1.05,201.04],[2,1.04,250]],"ltp":1.61,"tv":206.05,"id":8858707}]}]}
{"op":"mcm","clk":"11937390274","pt":1724792164421,"mc":[{"id":"1.232283868","rc":[{"batb":[[0,2.26,6.73],[1,2.1,3.15],[2,1.05,201.04]],"ltp":1.61,"tv":206.05,"id":8858707}]}]}
{"op":"mcm","clk":"11937493331","pt":1724793964901,"mc":[{"id":"1.232283868","rc":[{"trd":[[1.6,135.56],[1.61,70.49]],"batb":[[0,2.1,3.15],[1,1.05,201.04],[2,1.04,250]],"ltp":1.61,"tv":206.04,"id":8858707},{"trd":[[1.22,271.11]],"ltp":1.1,"tv":273.11,"id":2857968}],"tv":479.16}]}
{"op":"mcm","clk":"11937498172","pt":1724794057039,"mc":[{"id":"1.232283868","rc":[{"batb":[[0,2.26,6.73],[1,2.1,3.15],[2,1.05,201.04]],"ltp":1.61,"tv":206.04,"id":8858707}]}]}
{"op":"mcm","clk":"11937582591","pt":1724795857265,"mc":[{"id":"1.232283868","rc":[{"batb":[[0,2.1,3.15],[1,1.05,201.04],[2,1.04,250]],"ltp":1.61,"tv":206.04,"id":8858707}]}]}
{"op":"mcm","clk":"11937586048","pt":1724795944817,"mc":[{"id":"1.232283868","rc":[{"batb":[[0,2.26,6.73],[1,2.1,3.15],[2,1.05,201.04]],"ltp":1.61,"tv":206.04,"id":8858707}]}]}
{"op":"mcm","clk":"11937623777","pt":1724796774786,"mc":[{"id":"1.232283868","rc":[{"trd":[[1.6,135.61],[1.61,70.51]],"batb":[[0,2.26,6.73],[1,2.1,3.15]],"ltp":1.61,"tv":206.12,"id":8858707},{"trd":[[1.22,271.21]],"ltp":1.1,"tv":273.21,"id":2857968}],"tv":479.33}]}
{"op":"mcm","clk":"11937674999","pt":1724797745347,"mc":[{"id":"1.232283868","rc":[{"batb":[[0,2.1,3.15],[1,1.05,201.04],[2,1.04,250]],"ltp":1.61,"tv":206.12,"id":8858707}]}]}
{"op":"mcm","clk":"11937677131","pt":1724797801532,"mc":[{"id":"1.232283868","rc":[{"batb":[[0,2.26,6.73],[1,2.1,3.15],[2,1.05,201.04]],"ltp":1.61,"tv":206.12,"id":8858707}]}]}
{"op":"mcm","clk":"11937752135","pt":1724799601746,"mc":[{"id":"1.232283868","rc":[{"batb":[[0,2.1,3.15],[1,1.05,201.04],[2,1.04,250]],"ltp":1.61,"tv":206.12,"id":8858707}]}]}
{"op":"mcm","clk":"11937753839","pt":1724799642483,"mc":[{"id":"1.232283868","rc":[{"trd":[[1.6,135.58],[1.61,70.5]],"batb":[[0,2.26,6.73],[1,2.1,3.15],[2,1.05,201.04]],"ltp":1.61,"tv":206.07,"id":8858707},{"trd":[[1.22,271.16]],"ltp":1.1,"tv":273.15,"id":2857968}],"tv":479.23}]}
{"op":"mcm","clk":"11937827757","pt":1724801442828,"mc":[{"id":"1.232283868","rc":[{"batb":[[0,2.1,3.15],[1,1.05,201.04],[2,1.04,250]],"ltp":1.61,"tv":206.07,"id":8858707}]}]}
{"op":"mcm","clk":"11937828778","pt":1724801467343,"mc":[{"id":"1.232283868","rc":[{"batb":[[0,2.26,6.73],[1,2.1,3.15],[2,1.05,201.04]],"ltp":1.61,"tv":206.07,"id":8858707}]}]}
{"op":"mcm","clk":"11937923841","pt":1724803267572,"mc":[{"id":"1.232283868","rc":[{"trd":[[1.6,135.61],[1.61,70.52]],"batb":[[0,2.1,3.15],[1,1.05,201.04],[2,1.04,250]],"ltp":1.61,"tv":206.12,"id":8858707},{"trd":[[1.22,271.22]],"ltp":1.1,"tv":273.21,"id":2857968}],"tv":479.33}]}
{"op":"mcm","clk":"11937924472","pt":1724803279381,"mc":[{"id":"1.232283868","rc":[{"batb":[[0,2.26,6.73],[1,2.1,3.15],[2,1.05,201.04]],"ltp":1.61,"tv":206.12,"id":8858707}]}]}
{"op":"mcm","clk":"11938008362","pt":1724805079663,"mc":[{"id":"1.232283868","rc":[{"batb":[[0,2.1,3.15],[1,1.05,201.04],[2,1.04,250]],"ltp":1.61,"tv":206.12,"id":8858707}]}]}
{"op":"mcm","clk":"11938016073","pt":1724805223205,"mc":[{"id":"1.232283868","rc":[{"batb":[[0,2.26,6.73],[1,2.1,3.15],[2,1.05,201.04]],"ltp":1.61,"tv":206.12,"id":8858707}]}]}
{"op":"mcm","clk":"11938115036","pt":1724807023498,"mc":[{"id":"1.232283868","rc":[{"trd":[[1.6,135.58],[1.61,70.5]],"batb":[[0,2.1,3.15],[1,1.05,201.04],[2,1.04,250]],"ltp":1.61,"tv":206.08,"id":8858707},{"trd":[[1.22,271.16]],"ltp":1.1,"tv":273.15,"id":2857968}],"tv":479.23}]}
{"op":"mcm","clk":"11938122134","pt":1724807147746,"mc":[{"id":"1.232283868","rc":[{"batb":[[0,2.26,6.73],[1,2.1,3.15],[2,1.05,201.04]],"ltp":1.61,"tv":206.08,"id":8858707}]}]}
{"op":"mcm","clk":"11938217193","pt":1724808947929,"mc":[{"id":"1.232283868","rc":[{"batb":[[0,2.1,3.15],[1,1.05,201.04],[2,1.04,250]],"ltp":1.61,"tv":206.08,"id":8858707}]}]}
{"op":"mcm","clk":"11938222304","pt":1724809060769,"mc":[{"id":"1.232283868","rc":[{"batb":[[0,2.26,6.73],[1,2.1,3.15],[2,1.05,201.04]],"ltp":1.61,"tv":206.08,"id":8858707}]}]}
{"op":"mcm","clk":"11938302429","pt":1724810861178,"mc":[{"id":"1.232283868","rc":[{"trd":[[1.6,135.71],[1.61,70.57]],"batb":[[0,2.1,3.15],[1,1.05,201.04],[2,1.04,250]],"ltp":1.61,"tv":206.27,"id":8858707},{"trd":[[1.22,271.42]],"batl":[[1,1.9,3.08]],"ltp":1.1,"tv":273.41,"id":2857968}],"tv":479.69}]}
{"op":"mcm","clk":"11938306610","pt":1724810955751,"mc":[{"id":"1.232283868","rc":[{"batb":[[0,2.26,6.73],[1,2.1,3.15],[2,1.05,201.04]],"ltp":1.61,"tv":206.27,"id":8858707}]}]}
{"op":"mcm","clk":"11938384137","pt":1724812756105,"mc":[{"id":"1.232283868","rc":[{"batb":[[0,2.1,3.15],[1,1.05,201.04],[2,1.04,250]],"ltp":1.61,"tv":206.27,"id":8858707}]}]}
{"op":"mcm","clk":"11938387479","pt":1724812824083,"mc":[{"id":"1.232283868","rc":[{"batb":[[0,2.26,6.73],[1,2.1,3.15],[2,1.05,201.04]],"ltp":1.61,"tv":206.27,"id":8858707}]}]}
{"op":"mcm","clk":"11938483829","pt":1724814624286,"mc":[{"id":"1.232283868","rc":[{"trd":[[1.6,135.76],[1.61,70.6]],"batb":[[0,2.1,3.15],[1,1.05,201.04],[2,1.04,250]],"ltp":1.61,"tv":206.35,"id":8858707},{"trd":[[1.22,271.52]],"ltp":1.1,"tv":273.52,"id":2857968}],"tv":479.88}]}
{"op":"mcm","clk":"11938485997","pt":1724814676839,"mc":[{"id":"1.232283868","rc":[{"batb":[[0,2.26,6.73],[1,2.1,3.15],[2,1.05,201.04]],"ltp":1.61,"tv":206.35,"id":8858707}]}]}
{"op":"mcm","clk":"11938566371","pt":1724816477232,"mc":[{"id":"1.232283868","rc":[{"batb":[[0,2.1,3.15],[1,1.05,201.04],[2,1.04,250]],"ltp":1.61,"tv":206.35,"id":8858707}]}]}
{"op":"mcm","clk":"11938567728","pt":1724816519786,"mc":[{"id":"1.232283868","rc":[{"batb":[[0,2.26,6.73],[1,2.1,3.15],[2,1.05,201.04]],"ltp":1.61,"tv":206.35,"id":8858707}]}]}
{"op":"mcm","clk":"11938573678","pt":1724816688738,"mc":[{"id":"1.232283868","rc":[{"batl":[[1,1.9,1]],"ltp":1.1,"tv":273.52,"id":2857968}]}]}
{"op":"mcm","clk":"11938573819","pt":1724816692668,"mc":[{"id":"1.232283868","rc":[{"batb":[[1,1.05,201.04],[2,1.04,250]],"ltp":1.61,"tv":206.35,"id":8858707}]}]}
{"op":"mcm","clk":"11938650892","pt":1724818320020,"mc":[{"id":"1.232283868","rc":[{"trd":[[1.6,135.74],[1.61,70.59]],"batb":[[0,1.05,201.04],[1,1.04,250],[2,1.03,533.33]],"ltp":1.61,"tv":206.32,"id":8858707},{"trd":[[1.22,271.48]],"ltp":1.1,"tv":273.48,"id":2857968}],"tv":479.8}]}
{"op":"mcm","clk":"11938652341","pt":1724818347335,"mc":[{"id":"1.232283868","rc":[{"batb":[[0,2.26,6.72],[1,1.05,201.04],[2,1.04,250]],"ltp":1.61,"tv":206.32,"id":8858707}]}]}
{"op":"mcm","clk":"11938691504","pt":1724819030988,"mc":[{"id":"1.232283868","rc":[{"batl":[[0,1.7,30],[1,1.8,10],[2,1.9,1]],"ltp":1.1,"tv":273.48,"id":2857968}]}]}
{"op":"mcm","clk":"11938735065","pt":1724820147846,"mc":[{"id":"1.232283868","rc":[{"batb":[[0,1.05,201.04],[1,1.04,250],[2,1.03,533.33]],"ltp":1.61,"tv":206.32,"id":8858707}]}]}
{"op":"mcm","clk":"11938735608","pt":1724820164751,"mc":[{"id":"1.232283868","rc":[{"batb":[[0,2.44,5.88],[1,1.05,201.04],[2,1.04,250]],"ltp":1.61,"tv":206.32,"id":8858707}]}]}
{"op":"mcm","clk":"11938797619","pt":1724821965065,"mc":[{"id":"1.232283868","rc":[{"trd":[[1.6,135.81],[1.61,70.62]],"batb":[[0,1.05,201.04],[1,1.04,250],[2,1.03,533.33]],"ltp":1.61,"tv":206.43,"id":8858707},{"trd":[[1.22,271.62]],"ltp":1.1,"tv":273.61,"id":2857968}],"tv":480.05}]}
{"op":"mcm","clk":"11938797825","pt":1724821970687,"mc":[{"id":"1.232283868","rc":[{"batb":[[0,2.44,5.88],[1,1.05,201.04],[2,1.04,250]],"ltp":1.61,"tv":206.43,"id":8858707}]}]}
{"op":"mcm","clk":"11938850981","pt":1724823770869,"mc":[{"id":"1.232283868","rc":[{"batb":[[0,1.05,201.04],[1,1.04,250],[2,1.03,533.33]],"ltp":1.61,"tv":206.43,"id":8858707}]}]}
{"op":"mcm","clk":"11938864236","pt":1724823907638,"mc":[{"id":"1.232283868","rc":[{"batb":[[0,2.44,5.88],[1,1.05,201.04],[2,1.04,250]],"ltp":1.61,"tv":206.43,"id":8858707}]}]}
{"op":"mcm","clk":"11938919547","pt":1724825567516,"mc":[{"id":"1.232283868","rc":[{"trd":[[1.6,135.93],[1.61,70.68]],"batb":[[0,2.44,5.88]],"ltp":1.61,"tv":206.61,"id":8858707},{"trd":[[1.22,271.86]],"batl":[[0,1.69,10],[1,1.7,30]],"ltp":1.1,"tv":273.85,"id":2857968}],"tv":480.46}]}
{"op":"mcm","clk":"11938923107","pt":1724825707895,"mc":[{"id":"1.232283868","rc":[{"batb":[[0,1.05,201.04],[1,1.04,250],[2,1.03,533.33]],"ltp":1.61,"tv":206.61,"id":8858707}]}]}
{"op":"mcm","clk":"11938928060","pt":1724825901212,"mc":[{"id":"1.232283868","rc":[{"batb":[[0,2.46,5.8],[1,1.05,201.04],[2,1.04,250]],"ltp":1.61,"tv":206.61,"id":8858707}]}]}
{"op":"mcm","clk":"11938975973","pt":1724827701711,"mc":[{"id":"1.232283868","rc":[{"batb":[[0,1.05,201.04],[1,1.04,250],[2,1.03,533.33]],"ltp":1.61,"tv":206.61,"id":8858707}]}]}
{"op":"mcm","clk":"11938976242","pt":1724827713730,"mc":[{"id":"1.232283868","rc":[{"batb":[[0,2.46,5.8],[1,1.05,201.04],[2,1.04,250]],"ltp":1.61,"tv":206.61,"id":8858707}]}]}
{"op":"mcm","clk":"11939021246","pt":1724829174793,"mc":[{"id":"1.232283868","rc":[{"trd":[[1.6,135.95],[1.61,70.7]],"batb":[[0,2.46,5.8]],"ltp":1.61,"tv":206.64,"id":8858707},{"trd":[[1.22,271.91]],"ltp":1.1,"tv":273.9,"id":2857968}],"tv":480.55}]}
{"op":"mcm","clk":"11939042779","pt":1724829514281,"mc":[{"id":"1.232283868","rc":[{"batb":[[0,1.05,201.04],[1,1.04,250],[2,1.03,533.33]],"ltp":1.61,"tv":206.64,"id":8858707}]}]}
{"op":"mcm","clk":"11939043246","pt":1724829528088,"mc":[{"id":"1.232283868","rc":[{"batb":[[0,2.46,5.8],[1,1.05,201.04],[2,1.04,250]],"ltp":1.61,"tv":206.64,"id":8858707}]}]}
{"op":"mcm","clk":"11939054468","pt":1724829846697,"mc":[{"id":"1.232283868","rc":[{"batl":[[0,1.68,30],[1,1.69,10]],"ltp":1.1,"tv":273.9,"id":2857968}]}]}
{"op":"mcm","clk":"11939071010","pt":1724830470758,"mc":[{"id":"1.232283868","rc":[{"batl":[[0,1.65,10],[1,1.68,30]],"ltp":1.1,"tv":273.9,"id":2857968}]}]}
{"op":"mcm","clk":"11939094374","pt":1724831328856,"mc":[{"id":"1.232283868","rc":[{"batb":[[0,1.05,201.04],[1,1.04,250],[2,1.03,533.33]],"ltp":1.61,"tv":206.64,"id":8858707}]}]}
{"op":"mcm","clk":"11939094745","pt":1724831345062,"mc":[{"id":"1.232283868","rc":[{"batb":[[0,2.54,5.5],[1,1.05,201.04],[2,1.04,250]],"ltp":1.61,"tv":206.64,"id":8858707}]}]}
{"op":"mcm","clk":"11939131313","pt":1724832547298,"mc":[{"id":"1.232283868","rc":[{"trd":[[1.6,135.89],[1.61,70.66],[2.54,11]],"batb":[[0,1.06,5]],"batl":[[0,2.54,1.5]],"ltp":2.54,"tv":217.55,"id":8858707},{"trd":[[1.22,271.78]],"ltp":1.1,"tv":273.78,"id":2857968}],"tv":491.33}]}
{"op":"mcm","clk":"11939131472","pt":1724832550807,"mc":[{"id":"1.232283868","rc":[{"batb":[[0,1.05,201.04],[1,1.04,250],[2,1.03,533.33]],"ltp":2.54,"tv":217.55,"id":8858707}]}]}
{"op":"mcm","clk":"11939131649","pt":1724832555425,"mc":[{"id":"1.232283868","rc":[{"batb":[[0,1.06,5],[1,1.05,201.04],[2,1.04,250]],"ltp":2.54,"tv":217.55,"id":8858707}]}]}
{"op":"mcm","clk":"11939131795","pt":1724832558811,"mc":[{"id":"1.232283868","rc":[{"batb":[[0,1.05,201.04],[1,1.04,250],[2,1.03,533.33]],"ltp":2.54,"tv":217.55,"id":8858707}]}]}
{"op":"mcm","clk":"11939131911","pt":1724832561901,"mc":[{"id":"1.232283868","rc":[{"batb":[[0,1.06,5],[1,1.05,201.04],[2,1.04,250]],"ltp":2.54,"tv":217.55,"id":8858707}]}]}
{"op":"mcm","clk":"11939132019","pt":1724832565901,"mc":[{"id":"1.232283868","rc":[{"batb":[[0,1.05,201.04],[1,1.04,250],[2,1.03,533.33]],"ltp":2.54,"tv":217.55,"id":8858707}]}]}
{"op":"mcm","clk":"11939132130","pt":1724832569640,"mc":[{"id":"1.232283868","rc":[{"batb":[[0,1.06,5],[1,1.05,201.04],[2,1.04,250]],"ltp":2.54,"tv":217.55,"id":8858707}]}]}
{"op":"mcm","clk":"11939132247","pt":1724832573141,"mc":[{"id":"1.232283868","rc":[{"batb":[[0,1.05,201.04],[1,1.04,250],[2,1.03,533.33]],"ltp":2.54,"tv":217.55,"id":8858707}]}]}
{"op":"mcm","clk":"11939132322","pt":1724832575348,"mc":[{"id":"1.232283868","rc":[{"batb":[[0,1.06,5],[1,1.05,201.04],[2,1.04,250]],"ltp":2.54,"tv":217.55,"id":8858707}]}]}
{"op":"mcm","clk":"11939132424","pt":1724832577807,"mc":[{"id":"1.232283868","rc":[{"trd":[[2.54,12.29]],"batl":[[0,2.54,0.21]],"ltp":2.54,"tv":218.84,"id":8858707},{"trd":[[1.64,2]],"ltp":1.64,"tv":275.78,"id":2857968}],"tv":494.62}]}
{"op":"mcm","clk":"11939132453","pt":1724832578735,"mc":[{"id":"1.232283868","rc":[{"batb":[[0,1.05,201.04],[1,1.04,250],[2,1.03,533.33]],"ltp":2.54,"tv":218.84,"id":8858707}]}]}
{"op":"mcm","clk":"11939132568","pt":1724832581457,"mc":[{"id":"1.232283868","rc":[{"batb":[[0,1.06,5],[1,1.05,201.04],[2,1.04,250]],"ltp":2.54,"tv":218.84,"id":8858707}]}]}
{"op":"mcm","clk":"11939132709","pt":1724832584961,"mc":[{"id":"1.232283868","rc":[{"batb":[[0,1.05,201.04],[1,1.04,250],[2,1.03,533.33]],"ltp":2.54,"tv":218.84,"id":8858707}]}]}
{"op":"mcm","clk":"11939132821","pt":1724832588453,"mc":[{"id":"1.232283868","rc":[{"batb":[[0,1.06,5],[1,1.05,201.04],[2,1.04,250]],"ltp":2.54,"tv":218.84,"id":8858707}]}]}
{"op":"mcm","clk":"11939132954","pt":1724832592254,"mc":[{"id":"1.232283868","rc":[{"batb":[[0,1.05,201.04],[1,1.04,250],[2,1.03,533.33]],"ltp":2.54,"tv":218.84,"id":8858707}]}]}
{"op":"mcm","clk":"11939133099","pt":1724832596465,"mc":[{"id":"1.232283868","rc":[{"batb":[[0,1.06,5],[1,1.05,201.04],[2,1.04,250]],"ltp":2.54,"tv":218.84,"id":8858707},{"batb":[[0,1.25,2],[1,1.09,20],[2,1.05,200]],"ltp":1.64,"tv":275.78,"id":2857968}]}]}
{"op":"mcm","clk":"11939133185","pt":1724832599669,"mc":[{"id":"1.232283868","rc":[{"batb":[[0,1.05,201.04],[1,1.04,250],[2,1.03,533.33]],"ltp":2.54,"tv":218.84,"id":8858707}]}]}
{"op":"mcm","clk":"11939133341","pt":1724832603848,"mc":[{"id":"1.232283868","rc":[{"batb":[[0,1.06,5],[1,1.05,201.04],[2,1.04,250]],"ltp":2.54,"tv":218.84,"id":8858707}]}]}
{"op":"mcm","clk":"11939133500","pt":1724832607389,"mc":[{"id":"1.232283868","rc":[{"batb":[[0,1.05,201.04],[1,1.04,250],[2,1.03,533.33]],"ltp":2.54,"tv":218.84,"id":8858707}]}]}
{"op":"mcm","clk":"11939133578","pt":1724832609957,"mc":[{"id":"1.232283868","rc":[{"batb":[[0,1.06,5],[1,1.05,201.04],[2,1.04,250]],"ltp":2.54,"tv":218.84,"id":8858707}]}]}
{"op":"mcm","clk":"11939133729","pt":1724832613554,"mc":[{"id":"1.232283868","rc":[{"batb":[[0,1.05,201.04],[1,1.04,250],[2,1.03,533.33]],"ltp":2.54,"tv":218.84,"id":8858707}]}]}
{"op":"mcm","clk":"11939133844","pt":1724832617456,"mc":[{"id":"1.232283868","rc":[{"batb":[[0,1.06,5],[1,1.05,201.04],[2,1.04,250]],"ltp":2.54,"tv":218.84,"id":8858707}]}]}
{"op":"mcm","clk":"11939133944","pt":1724832621088,"mc":[{"id":"1.232283868","rc":[{"batb":[[0,1.05,201.04],[1,1.04,250],[2,1.03,533.33]],"ltp":2.54,"tv":218.84,"id":8858707}]}]}
{"op":"mcm","clk":"11939134031","pt":1724832624173,"mc":[{"id":"1.232283868","rc":[{"batb":[[0,1.06,5],[1,1.05,201.04],[2,1.04,250]],"ltp":2.54,"tv":218.84,"id":8858707}]}]}
{"op":"mcm","clk":"11939134123","pt":1724832627702,"mc":[{"id":"1.232283868","rc":[{"batb":[[0,1.05,201.04],[1,1.04,250],[2,1.03,533.33]],"ltp":2.54,"tv":218.84,"id":8858707}]}]}
{"op":"mcm","clk":"11939134225","pt":1724832630213,"mc":[{"id":"1.232283868","rc":[{"batb":[[0,1.06,5],[1,1.05,201.04],[2,1.04,250]],"ltp":2.54,"tv":218.84,"id":8858707}]}]}
{"op":"mcm","clk":"11939134334","pt":1724832633711,"mc":[{"id":"1.232283868","rc":[{"batb":[[0,1.05,201.04],[1,1.04,250],[2,1.03,533.33]],"ltp":2.54,"tv":218.84,"id":8858707}]}]}
{"op":"mcm","clk":"11939134453","pt":1724832637299,"mc":[{"id":"1.232283868","rc":[{"batb":[[0,1.06,5],[1,1.05,201.04],[2,1.04,250]],"batl":[[0,2.62,0.21]],"ltp":2.54,"tv":218.84,"id":8858707}]}]}
{"op":"mcm","clk":"11939134569","pt":1724832640583,"mc":[{"id":"1.232283868","rc":[{"batb":[[0,1.05,201.04],[1,1.04,250],[2,1.03,533.33]],"ltp":2.54,"tv":218.84,"id":8858707}]}]}
{"op":"mcm","clk":"11939134699","pt":1724832644219,"mc":[{"id":"1.232283868","rc":[{"batb":[[0,1.06,5],[1,1.05,201.04],[2,1.04,250]],"ltp":2.54,"tv":218.84,"id":8858707}]}]}
{"op":"mcm","clk":"11939134818","pt":1724832647912,"mc":[{"id":"1.232283868","rc":[{"batb":[[0,1.05,201.04],[1,1.04,250],[2,1.03,533.33]],"ltp":2.54,"tv":218.84,"id":8858707}]}]}
{"op":"mcm","clk":"11939134927","pt":1724832650728,"mc":[{"id":"1.232283868","rc":[{"batb":[[0,1.06,5],[1,1.05,201.04],[2,1.04,250]],"ltp":2.54,"tv":218.84,"id":8858707}]}]}
{"op":"mcm","clk":"11939135010","pt":1724832654002,"mc":[{"id":"1.232283868","rc":[{"batb":[[0,1.05,201.04],[1,1.04,250],[2,1.03,533.33]],"ltp":2.54,"tv":218.84,"id":8858707}]}]}
{"op":"mcm","clk":"11939135103","pt":1724832657225,"mc":[{"id":"1.232283868","rc":[{"batb":[[0,1.06,5],[1,1.05,201.04],[2,1.04,250]],"ltp":2.54,"tv":218.84,"id":8858707}]}]}
{"op":"mcm","clk":"11939135241","pt":1724832660728,"mc":[{"id":"1.232283868","rc":[{"batb":[[0,1.05,201.04],[1,1.04,250],[2,1.03,533.33]],"ltp":2.54,"tv":218.84,"id":8858707}]}]}
{"op":"mcm","clk":"11939135351","pt":1724832663245,"mc":[{"id":"1.232283868","rc":[{"batb":[[0,1.06,5],[1,1.05,201.04],[2,1.04,250]],"ltp":2.54,"tv":218.84,"id":8858707}]}]}
{"op":"mcm","clk":"11939135488","pt":1724832666546,"mc":[{"id":"1.232283868","rc":[{"batb":[[0,1.05,201.04],[1,1.04,250],[2,1.03,533.33]],"ltp":2.54,"tv":218.84,"id":8858707}]}]}
{"op":"mcm","clk":"11939135628","pt":1724832670647,"mc":[{"id":"1.232283868","rc":[{"batb":[[0,1.06,5],[1,1.05,201.04],[2,1.04,250]],"ltp":2.54,"tv":218.84,"id":8858707}]}]}
{"op":"mcm","clk":"11939135888","pt":1724832676551,"mc":[{"id":"1.232283868","rc":[{"batb":[[0,1.05,201.04],[1,1.04,250],[2,1.03,533.33]],"ltp":2.54,"tv":218.84,"id":8858707}]}]}
{"op":"mcm","clk":"11939136073","pt":1724832680255,"mc":[{"id":"1.232283868","rc":[{"batb":[[0,1.06,5],[1,1.05,201.04],[2,1.04,250]],"ltp":2.54,"tv":218.84,"id":8858707}]}]}
{"op":"mcm","clk":"11939136306","pt":1724832685382,"mc":[{"id":"1.232283868","rc":[{"batb":[[0,1.05,201.04],[1,1.04,250],[2,1.03,533.33]],"ltp":2.54,"tv":218.84,"id":8858707}]}]}
{"op":"mcm","clk":"11939136425","pt":1724832687746,"mc":[{"id":"1.232283868","rc":[{"batb":[[0,1.06,5],[1,1.05,201.04],[2,1.04,250]],"ltp":2.54,"tv":218.84,"id":8858707}]}]}
{"op":"mcm","clk":"11939136543","pt":1724832691284,"mc":[{"id":"1.232283868","rc":[{"batb":[[0,1.05,201.04],[1,1.04,250],[2,1.03,533.33]],"ltp":2.54,"tv":218.84,"id":8858707}]}]}
{"op":"mcm","clk":"11939136642","pt":1724832693593,"mc":[{"id":"1.232283868","rc":[{"batb":[[0,1.06,5],[1,1.05,201.04],[2,1.04,250]],"ltp":2.54,"tv":218.84,"id":8858707}]}]}
{"op":"mcm","clk":"11939136761","pt":1724832697181,"mc":[{"id":"1.232283868","rc":[{"batb":[[0,1.05,201.04],[1,1.04,250],[2,1.03,533.33]],"ltp":2.54,"tv":218.84,"id":8858707}]}]}
{"op":"mcm","clk":"11939136889","pt":1724832700984,"mc":[{"id":"1.232283868","rc":[{"batb":[[0,1.06,5],[1,1.05,201.04],[2,1.04,250]],"ltp":2.54,"tv":218.84,"id":8858707}]}]}
{"op":"mcm","clk":"11939137049","pt":1724832704372,"mc":[{"id":"1.232283868","rc":[{"batb":[[0,1.05,201.04],[1,1.04,250],[2,1.03,533.33]],"ltp":2.54,"tv":218.84,"id":8858707}]}]}
{"op":"mcm","clk":"11939137227","pt":1724832708583,"mc":[{"id":"1.232283868","rc":[{"batb":[[0,1.06,5],[1,1.05,201.04],[2,1.04,250]],"ltp":2.54,"tv":218.84,"id":8858707}]}]}
{"op":"mcm","clk":"11939137354","pt":1724832712081,"mc":[{"id":"1.232283868","rc":[{"batb":[[0,1.05,201.04],[1,1.04,250],[2,1.03,533.33]],"ltp":2.54,"tv":218.84,"id":8858707}]}]}
{"op":"mcm","clk":"11939137458","pt":1724832715097,"mc":[{"id":"1.232283868","rc":[{"batb":[[0,1.06,5],[1,1.05,201.04],[2,1.04,250]],"ltp":2.54,"tv":218.84,"id":8858707}]}]}
{"op":"mcm","clk":"11939137551","pt":1724832718570,"mc":[{"id":"1.232283868","rc":[{"batb":[[0,1.05,201.04],[1,1.04,250],[2,1.03,533.33]],"ltp":2.54,"tv":218.84,"id":8858707}]}]}
{"op":"mcm","clk":"11939137651","pt":1724832721537,"mc":[{"id":"1.232283868","rc":[{"batb":[[0,1.06,5],[1,1.05,201.04],[2,1.04,250]],"ltp":2.54,"tv":218.84,"id":8858707}]}]}
{"op":"mcm","clk":"11939137756","pt":1724832724838,"mc":[{"id":"1.232283868","rc":[{"batb":[[0,1.05,201.04],[1,1.04,250],[2,1.03,533.33]],"ltp":2.54,"tv":218.84,"id":8858707}]}]}
{"op":"mcm","clk":"11939137926","pt":1724832728423,"mc":[{"id":"1.232283868","rc":[{"batb":[[0,1.06,5],[1,1.05,201.04],[2,1.04,250]],"ltp":2.54,"tv":218.84,"id":8858707}]}]}
{"op":"mcm","clk":"11939138059","pt":1724832732326,"mc":[{"id":"1.232283868","rc":[{"batb":[[0,1.05,201.04],[1,1.04,250],[2,1.03,533.33]],"ltp":2.54,"tv":218.84,"id":8858707}]}]}
{"op":"mcm","clk":"11939138182","pt":1724832735811,"mc":[{"id":"1.232283868","rc":[{"batb":[[0,1.06,5],[1,1.05,201.04],[2,1.04,250]],"ltp":2.54,"tv":218.84,"id":8858707}]}]}
{"op":"mcm","clk":"11939138319","pt":1724832739251,"mc":[{"id":"1.232283868","rc":[{"batb":[[0,1.05,201.04],[1,1.04,250],[2,1.03,533.33]],"ltp":2.54,"tv":218.84,"id":8858707}]}]}
{"op":"mcm","clk":"11939138441","pt":1724832742068,"mc":[{"id":"1.232283868","rc":[{"batb":[[0,1.06,5],[1,1.05,201.04],[2,1.04,250]],"ltp":2.54,"tv":218.84,"id":8858707}]}]}
{"op":"mcm","clk":"11939138541","pt":1724832745758,"mc":[{"id":"1.232283868","rc":[{"batb":[[0,1.05,201.04],[1,1.04,250],[2,1.03,533.33]],"ltp":2.54,"tv":218.84,"id":8858707}]}]}
{"op":"mcm","clk":"11939138632","pt":1724832748163,"mc":[{"id":"1.232283868","rc":[{"batb":[[0,1.06,5],[1,1.05,201.04],[2,1.04,250]],"ltp":2.54,"tv":218.84,"id":8858707}]}]}
{"op":"mcm","clk":"11939138736","pt":1724832751540,"mc":[{"id":"1.232283868","rc":[{"batb":[[0,1.05,201.04],[1,1.04,250],[2,1.03,533.33]],"ltp":2.54,"tv":218.84,"id":8858707}]}]}
{"op":"mcm","clk":"11939138912","pt":1724832756571,"mc":[{"id":"1.232283868","rc":[{"batb":[[0,1.06,5],[1,1.05,201.04],[2,1.04,250]],"ltp":2.54,"tv":218.84,"id":8858707}]}]}
{"op":"mcm","clk":"11939139088","pt":1724832761142,"mc":[{"id":"1.232283868","rc":[{"batb":[[0,1.05,201.04],[1,1.04,250],[2,1.03,533.33]],"ltp":2.54,"tv":218.84,"id":8858707}]}]}
{"op":"mcm","clk":"11939139184","pt":1724832763956,"mc":[{"id":"1.232283868","rc":[{"batb":[[0,1.06,5],[1,1.05,201.04],[2,1.04,250]],"ltp":2.54,"tv":218.84,"id":8858707}]}]}
{"op":"mcm","clk":"11939139305","pt":1724832767346,"mc":[{"id":"1.232283868","rc":[{"batb":[[0,1.05,201.04],[1,1.04,250],[2,1.03,533.33]],"ltp":2.54,"tv":218.84,"id":8858707}]}]}
{"op":"mcm","clk":"11939139413","pt":1724832770373,"mc":[{"id":"1.232283868","rc":[{"batb":[[0,1.06,5],[1,1.05,201.04],[2,1.04,250]],"ltp":2.54,"tv":218.84,"id":8858707}]}]}
{"op":"mcm","clk":"11939139530","pt":1724832773860,"mc":[{"id":"1.232283868","rc":[{"batb":[[0,1.05,201.04],[1,1.04,250],[2,1.03,533.33]],"ltp":2.54,"tv":218.84,"id":8858707}]}]}
{"op":"mcm","clk":"11939139625","pt":1724832776595,"mc":[{"id":"1.232283868","rc":[{"batb":[[0,1.06,5],[1,1.05,201.04],[2,1.04,250]],"ltp":2.54,"tv":218.84,"id":8858707}]}]}
{"op":"mcm","clk":"11939139717","pt":1724832779979,"mc":[{"id":"1.232283868","rc":[{"batb":[[0,1.05,201.04],[1,1.04,250],[2,1.03,533.33]],"ltp":2.54,"tv":218.84,"id":8858707}]}]}
{"op":"mcm","clk":"11939139820","pt":1724832782993,"mc":[{"id":"1.232283868","rc":[{"batb":[[0,1.06,5],[1,1.05,201.04],[2,1.04,250]],"ltp":2.54,"tv":218.84,"id":8858707}]}]}
{"op":"mcm","clk":"11939139970","pt":1724832786489,"mc":[{"id":"1.232283868","rc":[{"batb":[[0,1.05,201.04],[1,1.04,250],[2,1.03,533.33]],"ltp":2.54,"tv":218.84,"id":8858707}]}]}
{"op":"mcm","clk":"11939140136","pt":1724832789925,"mc":[{"id":"1.232283868","rc":[{"batb":[[0,1.06,5],[1,1.05,201.04],[2,1.04,250]],"ltp":2.54,"tv":218.84,"id":8858707}]}]}
{"op":"mcm","clk":"11939140268","pt":1724832793420,"mc":[{"id":"1.232283868","rc":[{"batb":[[0,1.05,201.04],[1,1.04,250],[2,1.03,533.33]],"ltp":2.54,"tv":218.84,"id":8858707}]}]}
{"op":"mcm","clk":"11939140411","pt":1724832797414,"mc":[{"id":"1.232283868","rc":[{"batb":[[0,1.06,5],[1,1.05,201.04],[2,1.04,250]],"ltp":2.54,"tv":218.84,"id":8858707}]}]}
{"op":"mcm","clk":"11939140550","pt":1724832800902,"mc":[{"id":"1.232283868","rc":[{"batb":[[0,1.05,201.04],[1,1.04,250],[2,1.03,533.33]],"ltp":2.54,"tv":218.84,"id":8858707}]}]}
{"op":"mcm","clk":"11939140682","pt":1724832803829,"mc":[{"id":"1.232283868","rc":[{"batb":[[0,1.06,5],[1,1.05,201.04],[2,1.04,250]],"ltp":2.54,"tv":218.84,"id":8858707}]}]}
{"op":"mcm","clk":"11939140792","pt":1724832807097,"mc":[{"id":"1.232283868","rc":[{"batb":[[0,1.05,201.04],[1,1.04,250],[2,1.03,533.33]],"ltp":2.54,"tv":218.84,"id":8858707}]}]}
{"op":"mcm","clk":"11939140967","pt":1724832811045,"mc":[{"id":"1.232283868","rc":[{"batb":[[0,1.06,5],[1,1.05,201.04],[2,1.04,250]],"ltp":2.54,"tv":218.84,"id":8858707}]}]}
{"op":"mcm","clk":"11939141126","pt":1724832814528,"mc":[{"id":"1.232283868","rc":[{"batb":[[0,1.05,201.04],[1,1.04,250],[2,1.03,533.33]],"ltp":2.54,"tv":218.84,"id":8858707}]}]}
{"op":"mcm","clk":"11939141237","pt":1724832817958,"mc":[{"id":"1.232283868","rc":[{"batb":[[0,1.06,5],[1,1.05,201.04],[2,1.04,250]],"ltp":2.54,"tv":218.84,"id":8858707}]}]}
{"op":"mcm","clk":"11939141379","pt":1724832821133,"mc":[{"id":"1.232283868","rc":[{"batb":[[0,1.05,201.04],[1,1.04,250],[2,1.03,533.33]],"ltp":2.54,"tv":218.84,"id":8858707}]}]}
{"op":"mcm","clk":"11939141556","pt":1724832825534,"mc":[{"id":"1.232283868","rc":[{"batb":[[0,1.06,5],[1,1.05,201.04],[2,1.04,250]],"ltp":2.54,"tv":218.84,"id":8858707}]}]}
{"op":"mcm","clk":"11939141703","pt":1724832829940,"mc":[{"id":"1.232283868","rc":[{"batb":[[0,1.05,201.04],[1,1.04,250],[2,1.03,533.33]],"ltp":2.54,"tv":218.84,"id":8858707}]}]}
{"op":"mcm","clk":"11939141863","pt":1724832832762,"mc":[{"id":"1.232283868","rc":[{"batb":[[0,1.06,5],[1,1.05,201.04],[2,1.04,250]],"ltp":2.54,"tv":218.84,"id":8858707}]}]}
{"op":"mcm","clk":"11939142000","pt":1724832836250,"mc":[{"id":"1.232283868","rc":[{"batb":[[0,1.05,201.04],[1,1.04,250],[2,1.03,533.33]],"ltp":2.54,"tv":218.84,"id":8858707}]}]}
{"op":"mcm","clk":"11939142085","pt":1724832838962,"mc":[{"id":"1.232283868","rc":[{"batb":[[0,1.06,5],[1,1.05,201.04],[2,1.04,250]],"ltp":2.54,"tv":218.84,"id":8858707}]}]}
{"op":"mcm","clk":"11939142182","pt":1724832842213,"mc":[{"id":"1.232283868","rc":[{"batb":[[0,1.05,201.04],[1,1.04,250],[2,1.03,533.33]],"ltp":2.54,"tv":218.84,"id":8858707}]}]}
{"op":"mcm","clk":"11939142309","pt":1724832845669,"mc":[{"id":"1.232283868","rc":[{"batb":[[0,1.06,5],[1,1.05,201.04],[2,1.04,250]],"ltp":2.54,"tv":218.84,"id":8858707}]}]}
{"op":"mcm","clk":"11939142421","pt":1724832849003,"mc":[{"id":"1.232283868","rc":[{"batb":[[0,1.05,201.04],[1,1.04,250],[2,1.03,533.33]],"ltp":2.54,"tv":218.84,"id":8858707}]}]}
{"op":"mcm","clk":"11939142547","pt":1724832853005,"mc":[{"id":"1.232283868","rc":[{"batb":[[0,1.06,5],[1,1.05,201.04],[2,1.04,250]],"ltp":2.54,"tv":218.84,"id":8858707}]}]}
{"op":"mcm","clk":"11939142661","pt":1724832856394,"mc":[{"id":"1.232283868","rc":[{"batb":[[0,1.05,201.04],[1,1.04,250],[2,1.03,533.33]],"ltp":2.54,"tv":218.84,"id":8858707}]}]}
{"op":"mcm","clk":"11939142835","pt":1724832860708,"mc":[{"id":"1.232283868","rc":[{"batb":[[0,1.06,5],[1,1.05,201.04],[2,1.04,250]],"ltp":2.54,"tv":218.84,"id":8858707}]}]}
{"op":"mcm","clk":"11939142997","pt":1724832865078,"mc":[{"id":"1.232283868","rc":[{"batb":[[0,1.05,201.04],[1,1.04,250],[2,1.03,533.33]],"ltp":2.54,"tv":218.84,"id":8858707}]}]}
{"op":"mcm","clk":"11939143092","pt":1724832869026,"mc":[{"id":"1.232283868","rc":[{"batb":[[0,1.06,5],[1,1.05,201.04],[2,1.04,250]],"ltp":2.54,"tv":218.84,"id":8858707}]}]}
{"op":"mcm","clk":"11939143224","pt":1724832872521,"mc":[{"id":"1.232283868","rc":[{"batb":[[0,1.05,201.04],[1,1.04,250],[2,1.03,533.33]],"ltp":2.54,"tv":218.84,"id":8858707}]}]}
{"op":"mcm","clk":"11939143398","pt":1724832879135,"mc":[{"id":"1.232283868","rc":[{"batb":[[0,1.06,5],[1,1.05,201.04],[2,1.04,250]],"ltp":2.54,"tv":218.84,"id":8858707}]}]}
{"op":"mcm","clk":"11939143548","pt":1724832882645,"mc":[{"id":"1.232283868","rc":[{"batb":[[0,1.05,201.04],[1,1.04,250],[2,1.03,533.33]],"ltp":2.54,"tv":218.84,"id":8858707}]}]}
{"op":"mcm","clk":"11939143645","pt":1724832885009,"mc":[{"id":"1.232283868","rc":[{"batb":[[0,1.06,5],[1,1.05,201.04],[2,1.04,250]],"ltp":2.54,"tv":218.84,"id":8858707}]}]}
{"op":"mcm","clk":"11939143796","pt":1724832888443,"mc":[{"id":"1.232283868","rc":[{"batb":[[0,1.05,201.04],[1,1.04,250],[2,1.03,533.33]],"ltp":2.54,"tv":218.84,"id":8858707}]}]}
{"op":"mcm","clk":"11939143863","pt":1724832891054,"mc":[{"id":"1.232283868","rc":[{"batb":[[0,1.06,5],[1,1.05,201.04],[2,1.04,250]],"ltp":2.54,"tv":218.84,"id":8858707}]}]}
{"op":"mcm","clk":"11939143966","pt":1724832894342,"mc":[{"id":"1.232283868","rc":[{"batb":[[0,1.05,201.04],[1,1.04,250],[2,1.03,533.33]],"ltp":2.54,"tv":218.84,"id":8858707}]}]}
{"op":"mcm","clk":"11939144022","pt":1724832896750,"mc":[{"id":"1.232283868","rc":[{"batb":[[0,1.06,5],[1,1.05,201.04],[2,1.04,250]],"ltp":2.54,"tv":218.84,"id":8858707}]}]}
{"op":"mcm","clk":"11939144125","pt":1724832900020,"mc":[{"id":"1.232283868","rc":[{"batb":[[0,1.05,201.04],[1,1.04,250],[2,1.03,533.33]],"ltp":2.54,"tv":218.84,"id":8858707}]}]}
{"op":"mcm","clk":"11939144208","pt":1724832903253,"mc":[{"id":"1.232283868","rc":[{"batb":[[0,1.06,5],[1,1.05,201.04],[2,1.04,250]],"ltp":2.54,"tv":218.84,"id":8858707}]}]}
{"op":"mcm","clk":"11939144317","pt":1724832906531,"mc":[{"id":"1.232283868","rc":[{"batb":[[0,1.05,201.04],[1,1.04,250],[2,1.03,533.33]],"ltp":2.54,"tv":218.84,"id":8858707}]}]}
{"op":"mcm","clk":"11939144455","pt":1724832910723,"mc":[{"id":"1.232283868","rc":[{"batb":[[0,1.06,5],[1,1.05,201.04],[2,1.04,250]],"ltp":2.54,"tv":218.84,"id":8858707}]}]}
{"op":"mcm","clk":"11939144567","pt":1724832914057,"mc":[{"id":"1.232283868","rc":[{"batb":[[0,1.05,201.04],[1,1.04,250],[2,1.03,533.33]],"ltp":2.54,"tv":218.84,"id":8858707}]}]}
{"op":"mcm","clk":"11939144718","pt":1724832917746,"mc":[{"id":"1.232283868","rc":[{"batb":[[0,1.06,5],[1,1.05,201.04],[2,1.04,250]],"ltp":2.54,"tv":218.84,"id":8858707}]}]}
{"op":"mcm","clk":"11939144823","pt":1724832921178,"mc":[{"id":"1.232283868","rc":[{"batb":[[0,1.05,201.04],[1,1.04,250],[2,1.03,533.33]],"ltp":2.54,"tv":218.84,"id":8858707}]}]}
{"op":"mcm","clk":"11939144908","pt":1724832923585,"mc":[{"id":"1.232283868","rc":[{"batb":[[0,1.06,5],[1,1.05,201.04],[2,1.04,250]],"ltp":2.54,"tv":218.84,"id":8858707}]}]}
{"op":"mcm","clk":"11939145010","pt":1724832926765,"mc":[{"id":"1.232283868","rc":[{"batb":[[0,1.05,201.04],[1,1.04,250],[2,1.03,533.33]],"ltp":2.54,"tv":218.84,"id":8858707}]}]}
{"op":"mcm","clk":"11939145145","pt":1724832930859,"mc":[{"id":"1.232283868","rc":[{"batb":[[0,1.06,5],[1,1.05,201.04],[2,1.04,250]],"ltp":2.54,"tv":218.84,"id":8858707}]}]}
{"op":"mcm","clk":"11939145235","pt":1724832934286,"mc":[{"id":"1.232283868","rc":[{"batb":[[0,1.05,201.04],[1,1.04,250],[2,1.03,533.33]],"ltp":2.54,"tv":218.84,"id":8858707}]}]}
{"op":"mcm","clk":"11939145354","pt":1724832937769,"mc":[{"id":"1.232283868","rc":[{"batb":[[0,1.06,5],[1,1.05,201.04],[2,1.04,250]],"ltp":2.54,"tv":218.84,"id":8858707}]}]}
{"op":"mcm","clk":"11939145481","pt":1724832941299,"mc":[{"id":"1.232283868","rc":[{"batb":[[0,1.05,201.04],[1,1.04,250],[2,1.03,533.33]],"ltp":2.54,"tv":218.84,"id":8858707}]}]}
{"op":"mcm","clk":"11939145607","pt":1724832944379,"mc":[{"id":"1.232283868","rc":[{"batb":[[0,1.06,5],[1,1.05,201.04],[2,1.04,250]],"ltp":2.54,"tv":218.84,"id":8858707}]}]}
{"op":"mcm","clk":"11939145745","pt":1724832948192,"mc":[{"id":"1.232283868","rc":[{"batb":[[0,1.05,201.04],[1,1.04,250],[2,1.03,533.33]],"ltp":2.54,"tv":218.84,"id":8858707}]}]}
{"op":"mcm","clk":"11939145862","pt":1724832951211,"mc":[{"id":"1.232283868","rc":[{"batb":[[0,1.06,5],[1,1.05,201.04],[2,1.04,250]],"ltp":2.54,"tv":218.84,"id":8858707}]}]}
{"op":"mcm","clk":"11939145982","pt":1724832954490,"mc":[{"id":"1.232283868","rc":[{"batb":[[0,1.05,201.04],[1,1.04,250],[2,1.03,533.33]],"ltp":2.54,"tv":218.84,"id":8858707}]}]}
{"op":"mcm","clk":"11939146105","pt":1724832958385,"mc":[{"id":"1.232283868","rc":[{"batb":[[0,1.06,5],[1,1.05,201.04],[2,1.04,250]],"ltp":2.54,"tv":218.84,"id":8858707}]}]}
{"op":"mcm","clk":"11939146195","pt":1724832961704,"mc":[{"id":"1.232283868","rc":[{"batb":[[0,1.05,201.04],[1,1.04,250],[2,1.03,533.33]],"ltp":2.54,"tv":218.84,"id":8858707}]}]}
{"op":"mcm","clk":"11939146292","pt":1724832964222,"mc":[{"id":"1.232283868","rc":[{"batb":[[0,1.06,5],[1,1.05,201.04],[2,1.04,250]],"ltp":2.54,"tv":218.84,"id":8858707}]}]}
{"op":"mcm","clk":"11939146391","pt":1724832967731,"mc":[{"id":"1.232283868","rc":[{"batb":[[0,1.05,201.04],[1,1.04,250],[2,1.03,533.33]],"ltp":2.54,"tv":218.84,"id":8858707}]}]}
{"op":"mcm","clk":"11939146479","pt":1724832970033,"mc":[{"id":"1.232283868","rc":[{"batb":[[0,1.06,5],[1,1.05,201.04],[2,1.04,250]],"ltp":2.54,"tv":218.84,"id":8858707}]}]}
{"op":"mcm","clk":"11939146621","pt":1724832973411,"mc":[{"id":"1.232283868","rc":[{"batb":[[0,1.05,201.04],[1,1.04,250],[2,1.03,533.33]],"ltp":2.54,"tv":218.84,"id":8858707}]}]}
{"op":"mcm","clk":"11939146690","pt":1724832976020,"mc":[{"id":"1.232283868","rc":[{"batb":[[0,1.06,5],[1,1.05,201.04],[2,1.04,250]],"ltp":2.54,"tv":218.84,"id":8858707}]}]}
{"op":"mcm","clk":"11939146786","pt":1724832979634,"mc":[{"id":"1.232283868","rc":[{"batb":[[0,1.05,201.04],[1,1.04,250],[2,1.03,533.33]],"ltp":2.54,"tv":218.84,"id":8858707}]}]}
{"op":"mcm","clk":"11939146840","pt":1724832981836,"mc":[{"id":"1.232283868","rc":[{"batb":[[0,1.06,5],[1,1.05,201.04],[2,1.04,250]],"ltp":2.54,"tv":218.84,"id":8858707}]}]}
{"op":"mcm","clk":"11939146963","pt":1724832985166,"mc":[{"id":"1.232283868","rc":[{"batb":[[0,1.05,201.04],[1,1.04,250],[2,1.03,533.33]],"ltp":2.54,"tv":218.84,"id":8858707}]}]}
{"op":"mcm","clk":"11939147057","pt":1724832988546,"mc":[{"id":"1.232283868","rc":[{"batb":[[0,1.06,5],[1,1.05,201.04],[2,1.04,250]],"ltp":2.54,"tv":218.84,"id":8858707}]}]}
{"op":"mcm","clk":"11939147185","pt":1724832991933,"mc":[{"id":"1.232283868","rc":[{"batb":[[0,1.05,201.04],[1,1.04,250],[2,1.03,533.33]],"ltp":2.54,"tv":218.84,"id":8858707}]}]}
{"op":"mcm","clk":"11939147304","pt":1724832995572,"mc":[{"id":"1.232283868","rc":[{"batb":[[0,1.06,5],[1,1.05,201.04],[2,1.04,250]],"ltp":2.54,"tv":218.84,"id":8858707}]}]}
{"op":"mcm","clk":"11939147431","pt":1724832998959,"mc":[{"id":"1.232283868","rc":[{"batb":[[0,1.05,201.04],[1,1.04,250],[2,1.03,533.33]],"ltp":2.54,"tv":218.84,"id":8858707}]}]}
{"op":"mcm","clk":"11939147563","pt":1724833003182,"mc":[{"id":"1.232283868","rc":[{"batb":[[0,1.06,5],[1,1.05,201.04],[2,1.04,250]],"ltp":2.54,"tv":218.84,"id":8858707}]}]}
{"op":"mcm","clk":"11939147667","pt":1724833006555,"mc":[{"id":"1.232283868","rc":[{"batb":[[0,1.05,201.04],[1,1.04,250],[2,1.03,533.33]],"ltp":2.54,"tv":218.84,"id":8858707}]}]}
{"op":"mcm","clk":"11939147815","pt":1724833010455,"mc":[{"id":"1.232283868","rc":[{"batb":[[0,1.06,5],[1,1.05,201.04],[2,1.04,250]],"ltp":2.54,"tv":218.84,"id":8858707}]}]}
{"op":"mcm","clk":"11939147922","pt":1724833013788,"mc":[{"id":"1.232283868","rc":[{"batb":[[0,1.05,201.04],[1,1.04,250],[2,1.03,533.33]],"ltp":2.54,"tv":218.84,"id":8858707}]}]}
{"op":"mcm","clk":"11939148011","pt":1724833016455,"mc":[{"id":"1.232283868","rc":[{"batb":[[0,1.06,5],[1,1.05,201.04],[2,1.04,250]],"ltp":2.54,"tv":218.84,"id":8858707}]}]}
{"op":"mcm","clk":"11939148100","pt":1724833019780,"mc":[{"id":"1.232283868","rc":[{"batb":[[0,1.05,201.04],[1,1.04,250],[2,1.03,533.33]],"ltp":2.54,"tv":218.84,"id":8858707}]}]}
{"op":"mcm","clk":"11939148211","pt":1724833022196,"mc":[{"id":"1.232283868","rc":[{"batb":[[0,1.06,5],[1,1.05,201.04],[2,1.04,250]],"ltp":2.54,"tv":218.84,"id":8858707}]}]}
{"op":"mcm","clk":"11939148381","pt":1724833025690,"mc":[{"id":"1.232283868","rc":[{"batb":[[0,1.05,201.04],[1,1.04,250],[2,1.03,533.33]],"ltp":2.54,"tv":218.84,"id":8858707}]}]}
{"op":"mcm","clk":"11939148500","pt":1724833027999,"mc":[{"id":"1.232283868","rc":[{"batb":[[0,1.06,5],[1,1.05,201.04],[2,1.04,250]],"ltp":2.54,"tv":218.84,"id":8858707}]}]}
{"op":"mcm","clk":"11939148609","pt":1724833031292,"mc":[{"id":"1.232283868","rc":[{"batb":[[0,1.05,201.04],[1,1.04,250],[2,1.03,533.33]],"ltp":2.54,"tv":218.84,"id":8858707}]}]}
{"op":"mcm","clk":"11939148726","pt":1724833034322,"mc":[{"id":"1.232283868","rc":[{"batb":[[0,1.06,5],[1,1.05,201.04],[2,1.04,250]],"ltp":2.54,"tv":218.84,"id":8858707}]}]}
{"op":"mcm","clk":"11939148834","pt":1724833037512,"mc":[{"id":"1.232283868","rc":[{"batb":[[0,1.05,201.04],[1,1.04,250],[2,1.03,533.33]],"ltp":2.54,"tv":218.84,"id":8858707}]}]}
{"op":"mcm","clk":"11939148941","pt":1724833040403,"mc":[{"id":"1.232283868","rc":[{"batb":[[0,1.06,5],[1,1.05,201.04],[2,1.04,250]],"ltp":2.54,"tv":218.84,"id":8858707}]}]}
{"op":"mcm","clk":"11939149077","pt":1724833043833,"mc":[{"id":"1.232283868","rc":[{"batb":[[0,1.05,201.04],[1,1.04,250],[2,1.03,533.33]],"ltp":2.54,"tv":218.84,"id":8858707}]}]}
{"op":"mcm","clk":"11939149180","pt":1724833046202,"mc":[{"id":"1.232283868","rc":[{"batb":[[0,1.06,5],[1,1.05,201.04],[2,1.04,250]],"ltp":2.54,"tv":218.84,"id":8858707}]}]}
{"op":"mcm","clk":"11939149301","pt":1724833049597,"mc":[{"id":"1.232283868","rc":[{"batb":[[0,1.05,201.04],[1,1.04,250],[2,1.03,533.33]],"ltp":2.54,"tv":218.84,"id":8858707}]}]}
{"op":"mcm","clk":"11939149414","pt":1724833052320,"mc":[{"id":"1.232283868","rc":[{"batb":[[0,1.06,5],[1,1.05,201.04],[2,1.04,250]],"ltp":2.54,"tv":218.84,"id":8858707}]}]}
{"op":"mcm","clk":"11939149541","pt":1724833055799,"mc":[{"id":"1.232283868","rc":[{"batb":[[0,1.05,201.04],[1,1.04,250],[2,1.03,533.33]],"ltp":2.54,"tv":218.84,"id":8858707}]}]}
{"op":"mcm","clk":"11939149609","pt":1724833058009,"mc":[{"id":"1.232283868","rc":[{"batb":[[0,1.06,5],[1,1.05,201.04],[2,1.04,250]],"ltp":2.54,"tv":218.84,"id":8858707}]}]}
{"op":"mcm","clk":"11939149734","pt":1724833061244,"mc":[{"id":"1.232283868","rc":[{"batb":[[0,1.05,201.04],[1,1.04,250],[2,1.03,533.33]],"ltp":2.54,"tv":218.84,"id":8858707}]}]}
{"op":"mcm","clk":"11939149928","pt":1724833065728,"mc":[{"id":"1.232283868","rc":[{"batb":[[0,1.06,5],[1,1.05,201.04],[2,1.04,250]],"ltp":2.54,"tv":218.84,"id":8858707}]}]}
{"op":"mcm","clk":"11939150058","pt":1724833069123,"mc":[{"id":"1.232283868","rc":[{"batb":[[0,1.05,201.04],[1,1.04,250],[2,1.03,533.33]],"ltp":2.54,"tv":218.84,"id":8858707}]}]}
{"op":"mcm","clk":"11939150177","pt":1724833072146,"mc":[{"id":"1.232283868","rc":[{"batb":[[0,1.06,5],[1,1.05,201.04],[2,1.04,250]],"ltp":2.54,"tv":218.84,"id":8858707}]}]}
{"op":"mcm","clk":"11939150309","pt":1724833075740,"mc":[{"id":"1.232283868","rc":[{"batb":[[0,1.05,201.04],[1,1.04,250],[2,1.03,533.33]],"ltp":2.54,"tv":218.84,"id":8858707}]}]}
{"op":"mcm","clk":"11939150399","pt":1724833078773,"mc":[{"id":"1.232283868","rc":[{"batb":[[0,1.06,5],[1,1.05,201.04],[2,1.04,250]],"ltp":2.54,"tv":218.84,"id":8858707}]}]}
{"op":"mcm","clk":"11939150529","pt":1724833082241,"mc":[{"id":"1.232283868","rc":[{"batb":[[0,1.05,201.04],[1,1.04,250],[2,1.03,533.33]],"ltp":2.54,"tv":218.84,"id":8858707}]}]}
{"op":"mcm","clk":"11939150659","pt":1724833085646,"mc":[{"id":"1.232283868","rc":[{"batb":[[0,1.06,5],[1,1.05,201.04],[2,1.04,250]],"ltp":2.54,"tv":218.84,"id":8858707}]}]}
{"op":"mcm","clk":"11939150809","pt":1724833089077,"mc":[{"id":"1.232283868","rc":[{"batb":[[0,1.05,201.04],[1,1.04,250],[2,1.03,533.33]],"ltp":2.54,"tv":218.84,"id":8858707}]}]}
{"op":"mcm","clk":"11939150967","pt":1724833093181,"mc":[{"id":"1.232283868","rc":[{"batb":[[0,1.06,5],[1,1.05,201.04],[2,1.04,250]],"ltp":2.54,"tv":218.84,"id":8858707}]}]}
{"op":"mcm","clk":"11939151143","pt":1724833096579,"mc":[{"id":"1.232283868","rc":[{"batb":[[0,1.05,201.04],[1,1.04,250],[2,1.03,533.33]],"ltp":2.54,"tv":218.84,"id":8858707}]}]}
{"op":"mcm","clk":"11939151253","pt":1724833099563,"mc":[{"id":"1.232283868","rc":[{"batb":[[0,1.06,5],[1,1.05,201.04],[2,1.04,250]],"ltp":2.54,"tv":218.84,"id":8858707}]}]}
{"op":"mcm","clk":"11939151390","pt":1724833103054,"mc":[{"id":"1.232283868","rc":[{"batb":[[0,1.05,201.04],[1,1.04,250],[2,1.03,533.33]],"ltp":2.54,"tv":218.84,"id":8858707}]}]}
{"op":"mcm","clk":"11939151498","pt":1724833105259,"mc":[{"id":"1.232283868","rc":[{"batb":[[0,1.06,5],[1,1.05,201.04],[2,1.04,250]],"ltp":2.54,"tv":218.84,"id":8858707}]}]}
{"op":"mcm","clk":"11939151654","pt":1724833109879,"mc":[{"id":"1.232283868","rc":[{"batb":[[0,1.05,201.04],[1,1.04,250],[2,1.03,533.33]],"ltp":2.54,"tv":218.84,"id":8858707}]}]}
{"op":"mcm","clk":"11939151755","pt":1724833112803,"mc":[{"id":"1.232283868","rc":[{"batb":[[0,1.06,5],[1,1.05,201.04],[2,1.04,250]],"ltp":2.54,"tv":218.84,"id":8858707}]}]}
{"op":"mcm","clk":"11939151869","pt":1724833116190,"mc":[{"id":"1.232283868","rc":[{"batb":[[0,1.05,201.04],[1,1.04,250],[2,1.03,533.33]],"ltp":2.54,"tv":218.84,"id":8858707}]}]}
{"op":"mcm","clk":"11939151982","pt":1724833119175,"mc":[{"id":"1.232283868","rc":[{"batb":[[0,1.06,5],[1,1.05,201.04],[2,1.04,250]],"ltp":2.54,"tv":218.84,"id":8858707}]}]}
{"op":"mcm","clk":"11939152138","pt":1724833122796,"mc":[{"id":"1.232283868","rc":[{"batb":[[0,1.05,201.04],[1,1.04,250],[2,1.03,533.33]],"ltp":2.54,"tv":218.84,"id":8858707}]}]}
{"op":"mcm","clk":"11939152237","pt":1724833125310,"mc":[{"id":"1.232283868","rc":[{"batb":[[0,1.06,5],[1,1.05,201.04],[2,1.04,250]],"ltp":2.54,"tv":218.84,"id":8858707}]}]}
{"op":"mcm","clk":"11939152364","pt":1724833128801,"mc":[{"id":"1.232283868","rc":[{"batb":[[0,1.05,201.04],[1,1.04,250],[2,1.03,533.33]],"ltp":2.54,"tv":218.84,"id":8858707}]}]}
{"op":"mcm","clk":"11939152485","pt":1724833132907,"mc":[{"id":"1.232283868","rc":[{"batb":[[0,1.06,5],[1,1.05,201.04],[2,1.04,250]],"ltp":2.54,"tv":218.84,"id":8858707}]}]}
{"op":"mcm","clk":"11939152601","pt":1724833136196,"mc":[{"id":"1.232283868","rc":[{"batb":[[0,1.05,201.04],[1,1.04,250],[2,1.03,533.33]],"ltp":2.54,"tv":218.84,"id":8858707}]}]}
{"op":"mcm","clk":"11939152686","pt":1724833138787,"mc":[{"id":"1.232283868","rc":[{"batb":[[0,1.06,5],[1,1.05,201.04],[2,1.04,250]],"ltp":2.54,"tv":218.84,"id":8858707}]}]}
{"op":"mcm","clk":"11939152796","pt":1724833142003,"mc":[{"id":"1.232283868","rc":[{"batb":[[0,1.05,201.04],[1,1.04,250],[2,1.03,533.33]],"ltp":2.54,"tv":218.84,"id":8858707}]}]}
{"op":"mcm","clk":"11939153011","pt":1724833147831,"mc":[{"id":"1.232283868","rc":[{"batb":[[0,1.06,5],[1,1.05,201.04],[2,1.04,250]],"ltp":2.54,"tv":218.84,"id":8858707}]}]}
{"op":"mcm","clk":"11939153123","pt":1724833151224,"mc":[{"id":"1.232283868","rc":[{"batb":[[0,1.05,201.04],[1,1.04,250],[2,1.03,533.33]],"ltp":2.54,"tv":218.84,"id":8858707}]}]}
{"op":"mcm","clk":"11939153264","pt":1724833155037,"mc":[{"id":"1.232283868","rc":[{"batb":[[0,1.06,5],[1,1.05,201.04],[2,1.04,250]],"ltp":2.54,"tv":218.84,"id":8858707}]}]}
{"op":"mcm","clk":"11939153394","pt":1724833158536,"mc":[{"id":"1.232283868","rc":[{"batb":[[0,1.05,201.04],[1,1.04,250],[2,1.03,533.33]],"ltp":2.54,"tv":218.84,"id":8858707}]}]}
{"op":"mcm","clk":"11939153498","pt":1724833161053,"mc":[{"id":"1.232283868","rc":[{"batb":[[0,1.06,5],[1,1.05,201.04],[2,1.04,250]],"ltp":2.54,"tv":218.84,"id":8858707}]}]}
{"op":"mcm","clk":"11939153632","pt":1724833164659,"mc":[{"id":"1.232283868","rc":[{"batb":[[0,1.05,201.04],[1,1.04,250],[2,1.03,533.33]],"ltp":2.54,"tv":218.84,"id":8858707}]}]}
{"op":"mcm","clk":"11939153743","pt":1724833167224,"mc":[{"id":"1.232283868","rc":[{"batb":[[0,1.06,5],[1,1.05,201.04],[2,1.04,250]],"ltp":2.54,"tv":218.84,"id":8858707}]}]}
{"op":"mcm","clk":"11939153833","pt":1724833170716,"mc":[{"id":"1.232283868","rc":[{"batb":[[0,1.05,201.04],[1,1.04,250],[2,1.03,533.33]],"ltp":2.54,"tv":218.84,"id":8858707}]}]}
{"op":"mcm","clk":"11939153927","pt":1724833173352,"mc":[{"id":"1.232283868","rc":[{"batb":[[0,1.06,5],[1,1.05,201.04],[2,1.04,250]],"ltp":2.54,"tv":218.84,"id":8858707}]}]}
{"op":"mcm","clk":"11939154066","pt":1724833176941,"mc":[{"id":"1.232283868","rc":[{"batb":[[0,1.05,201.04],[1,1.04,250],[2,1.03,533.33]],"ltp":2.54,"tv":218.84,"id":8858707}]}]}
{"op":"mcm","clk":"11939154261","pt":1724833183352,"mc":[{"id":"1.232283868","rc":[{"batb":[[0,1.06,5],[1,1.05,201.04],[2,1.04,250]],"ltp":2.54,"tv":218.84,"id":8858707}]}]}
{"op":"mcm","clk":"11939154371","pt":1724833186682,"mc":[{"id":"1.232283868","rc":[{"batb":[[0,1.05,201.04],[1,1.04,250],[2,1.03,533.33]],"ltp":2.54,"tv":218.84,"id":8858707}]}]}
{"op":"mcm","clk":"11939154460","pt":1724833189345,"mc":[{"id":"1.232283868","rc":[{"batb":[[0,1.06,5],[1,1.05,201.04],[2,1.04,250]],"ltp":2.54,"tv":218.84,"id":8858707}]}]}
{"op":"mcm","clk":"11939154578","pt":1724833192564,"mc":[{"id":"1.232283868","rc":[{"batb":[[0,1.05,201.04],[1,1.04,250],[2,1.03,533.33]],"ltp":2.54,"tv":218.84,"id":8858707}]}]}
{"op":"mcm","clk":"11939154665","pt":1724833195893,"mc":[{"id":"1.232283868","rc":[{"batb":[[0,1.06,5],[1,1.05,201.04],[2,1.04,250]],"ltp":2.54,"tv":218.84,"id":8858707}]}]}
{"op":"mcm","clk":"11939154758","pt":1724833199290,"mc":[{"id":"1.232283868","rc":[{"batb":[[0,1.05,201.04],[1,1.04,250],[2,1.03,533.33]],"ltp":2.54,"tv":218.84,"id":8858707}]}]}
{"op":"mcm","clk":"11939154852","pt":1724833202471,"mc":[{"id":"1.232283868","rc":[{"batb":[[0,1.06,5],[1,1.05,201.04],[2,1.04,250]],"ltp":2.54,"tv":218.84,"id":8858707}]}]}
{"op":"mcm","clk":"11939154970","pt":1724833205905,"mc":[{"id":"1.232283868","rc":[{"batb":[[0,1.05,201.04],[1,1.04,250],[2,1.03,533.33]],"ltp":2.54,"tv":218.84,"id":8858707}]}]}
{"op":"mcm","clk":"11939155057","pt":1724833208567,"mc":[{"id":"1.232283868","rc":[{"batb":[[0,1.06,5],[1,1.05,201.04],[2,1.04,250]],"ltp":2.54,"tv":218.84,"id":8858707}]}]}
{"op":"mcm","clk":"11939155156","pt":1724833211988,"mc":[{"id":"1.232283868","rc":[{"batb":[[0,1.05,201.04],[1,1.04,250],[2,1.03,533.33]],"ltp":2.54,"tv":218.84,"id":8858707}]}]}
{"op":"mcm","clk":"11939155429","pt":1724833219305,"mc":[{"id":"1.232283868","rc":[{"batb":[[0,1.06,5],[1,1.05,201.04],[2,1.04,250]],"ltp":2.54,"tv":218.84,"id":8858707}]}]}
{"op":"mcm","clk":"11939155555","pt":1724833222987,"mc":[{"id":"1.232283868","rc":[{"batb":[[0,1.05,201.04],[1,1.04,250],[2,1.03,533.33]],"ltp":2.54,"tv":218.84,"id":8858707}]}]}
{"op":"mcm","clk":"11939155700","pt":1724833226204,"mc":[{"id":"1.232283868","rc":[{"batb":[[0,1.06,5],[1,1.05,201.04],[2,1.04,250]],"ltp":2.54,"tv":218.84,"id":8858707}]}]}
{"op":"mcm","clk":"11939155839","pt":1724833229607,"mc":[{"id":"1.232283868","rc":[{"batb":[[0,1.05,201.04],[1,1.04,250],[2,1.03,533.33]],"ltp":2.54,"tv":218.84,"id":8858707}]}]}
{"op":"mcm","clk":"11939155923","pt":1724833232129,"mc":[{"id":"1.232283868","rc":[{"batb":[[0,1.06,5],[1,1.05,201.04],[2,1.04,250]],"ltp":2.54,"tv":218.84,"id":8858707}]}]}
{"op":"mcm","clk":"11939156113","pt":1724833235922,"mc":[{"id":"1.232283868","rc":[{"batb":[[0,1.05,201.04],[1,1.04,250],[2,1.03,533.33]],"ltp":2.54,"tv":218.84,"id":8858707}]}]}
{"op":"mcm","clk":"11939156340","pt":1724833239511,"mc":[{"id":"1.232283868","rc":[{"batb":[[0,1.06,5],[1,1.05,201.04],[2,1.04,250]],"ltp":2.54,"tv":218.84,"id":8858707}]}]}
{"op":"mcm","clk":"11939156492","pt":1724833243707,"mc":[{"id":"1.232283868","rc":[{"batb":[[0,1.05,201.04],[1,1.04,250],[2,1.03,533.33]],"ltp":2.54,"tv":218.84,"id":8858707}]}]}
{"op":"mcm","clk":"11939156583","pt":1724833245908,"mc":[{"id":"1.232283868","rc":[{"batb":[[0,1.06,5],[1,1.05,201.04],[2,1.04,250]],"ltp":2.54,"tv":218.84,"id":8858707}]}]}
{"op":"mcm","clk":"11939156730","pt":1724833249339,"mc":[{"id":"1.232283868","rc":[{"batb":[[0,1.05,201.04],[1,1.04,250],[2,1.03,533.33]],"ltp":2.54,"tv":218.84,"id":8858707}]}]}
{"op":"mcm","clk":"11939156825","pt":1724833251807,"mc":[{"id":"1.232283868","rc":[{"batb":[[0,1.06,5],[1,1.05,201.04],[2,1.04,250]],"ltp":2.54,"tv":218.84,"id":8858707}]}]}
{"op":"mcm","clk":"11939157015","pt":1724833256729,"mc":[{"id":"1.232283868","rc":[{"batb":[[0,1.05,201.04],[1,1.04,250],[2,1.03,533.33]],"ltp":2.54,"tv":218.84,"id":8858707}]}]}
{"op":"mcm","clk":"11939157211","pt":1724833262421,"mc":[{"id":"1.232283868","rc":[{"batb":[[0,1.06,5],[1,1.05,201.04],[2,1.04,250]],"ltp":2.54,"tv":218.84,"id":8858707}]}]}
{"op":"mcm","clk":"11939157352","pt":1724833265953,"mc":[{"id":"1.232283868","rc":[{"batb":[[0,1.05,201.04],[1,1.04,250],[2,1.03,533.33]],"ltp":2.54,"tv":218.84,"id":8858707}]}]}
{"op":"mcm","clk":"11939157451","pt":1724833268616,"mc":[{"id":"1.232283868","rc":[{"batb":[[0,1.06,5],[1,1.05,201.04],[2,1.04,250]],"ltp":2.54,"tv":218.84,"id":8858707}]}]}
{"op":"mcm","clk":"11939157567","pt":1724833272348,"mc":[{"id":"1.232283868","rc":[{"batb":[[0,1.05,201.04],[1,1.04,250],[2,1.03,533.33]],"ltp":2.54,"tv":218.84,"id":8858707}]}]}
{"op":"mcm","clk":"11939157673","pt":1724833275524,"mc":[{"id":"1.232283868","rc":[{"batb":[[0,1.06,5],[1,1.05,201.04],[2,1.04,250]],"ltp":2.54,"tv":218.84,"id":8858707}]}]}
{"op":"mcm","clk":"11939157857","pt":1724833279072,"mc":[{"id":"1.232283868","rc":[{"batb":[[0,1.05,201.04],[1,1.04,250],[2,1.03,533.33]],"ltp":2.54,"tv":218.84,"id":8858707}]}]}
{"op":"mcm","clk":"11939157920","pt":1724833281471,"mc":[{"id":"1.232283868","rc":[{"batb":[[0,1.06,5],[1,1.05,201.04],[2,1.04,250]],"ltp":2.54,"tv":218.84,"id":8858707}]}]}
{"op":"mcm","clk":"11939158056","pt":1724833284847,"mc":[{"id":"1.232283868","rc":[{"batb":[[0,1.05,201.04],[1,1.04,250],[2,1.03,533.33]],"ltp":2.54,"tv":218.84,"id":8858707}]}]}
{"op":"mcm","clk":"11939158155","pt":1724833287355,"mc":[{"id":"1.232283868","rc":[{"batb":[[0,1.06,5],[1,1.05,201.04],[2,1.04,250]],"ltp":2.54,"tv":218.84,"id":8858707}]}]}
{"op":"mcm","clk":"11939158303","pt":1724833291148,"mc":[{"id":"1.232283868","rc":[{"batb":[[0,1.05,201.04],[1,1.04,250],[2,1.03,533.33]],"ltp":2.54,"tv":218.84,"id":8858707}]}]}
{"op":"mcm","clk":"11939158412","pt":1724833294266,"mc":[{"id":"1.232283868","rc":[{"batb":[[0,1.06,5],[1,1.05,201.04],[2,1.04,250]],"ltp":2.54,"tv":218.84,"id":8858707}]}]}
{"op":"mcm","clk":"11939158514","pt":1724833297595,"mc":[{"id":"1.232283868","rc":[{"batb":[[0,1.05,201.04],[1,1.04,250],[2,1.03,533.33]],"ltp":2.54,"tv":218.84,"id":8858707}]}]}
{"op":"mcm","clk":"11939158678","pt":1724833303387,"mc":[{"id":"1.232283868","rc":[{"batb":[[0,1.06,5],[1,1.05,201.04],[2,1.04,250]],"ltp":2.54,"tv":218.84,"id":8858707}]}]}
{"op":"mcm","clk":"11939158811","pt":1724833306573,"mc":[{"id":"1.232283868","rc":[{"batb":[[0,1.05,201.04],[1,1.04,250],[2,1.03,533.33]],"ltp":2.54,"tv":218.84,"id":8858707}]}]}
{"op":"mcm","clk":"11939158915","pt":1724833309288,"mc":[{"id":"1.232283868","rc":[{"batb":[[0,1.06,5],[1,1.05,201.04],[2,1.04,250]],"ltp":2.54,"tv":218.84,"id":8858707}]}]}
{"op":"mcm","clk":"11939159061","pt":1724833312781,"mc":[{"id":"1.232283868","rc":[{"batb":[[0,1.05,201.04],[1,1.04,250],[2,1.03,533.33]],"ltp":2.54,"tv":218.84,"id":8858707}]}]}
{"op":"mcm","clk":"11939159228","pt":1724833316375,"mc":[{"id":"1.232283868","rc":[{"batb":[[0,1.06,5],[1,1.05,201.04],[2,1.04,250]],"ltp":2.54,"tv":218.84,"id":8858707}]}]}
{"op":"mcm","clk":"11939159374","pt":1724833320189,"mc":[{"id":"1.232283868","rc":[{"batb":[[0,1.05,201.04],[1,1.04,250],[2,1.03,533.33]],"ltp":2.54,"tv":218.84,"id":8858707}]}]}
{"op":"mcm","clk":"11939159642","pt":1724833325893,"mc":[{"id":"1.232283868","rc":[{"batb":[[0,1.06,5],[1,1.05,201.04],[2,1.04,250]],"ltp":2.54,"tv":218.84,"id":8858707}]}]}
{"op":"mcm","clk":"11939159779","pt":1724833329296,"mc":[{"id":"1.232283868","rc":[{"batb":[[0,1.05,201.04],[1,1.04,250],[2,1.03,533.33]],"ltp":2.54,"tv":218.84,"id":8858707}]}]}
{"op":"mcm","clk":"11939159930","pt":1724833333500,"mc":[{"id":"1.232283868","rc":[{"batb":[[0,1.06,5],[1,1.05,201.04],[2,1.04,250]],"ltp":2.54,"tv":218.84,"id":8858707}]}]}
{"op":"mcm","clk":"11939160038","pt":1724833337091,"mc":[{"id":"1.232283868","rc":[{"batb":[[0,1.05,201.04],[1,1.04,250],[2,1.03,533.33]],"ltp":2.54,"tv":218.84,"id":8858707}]}]}
{"op":"mcm","clk":"11939160185","pt":1724833341302,"mc":[{"id":"1.232283868","rc":[{"batb":[[0,1.06,5],[1,1.05,201.04],[2,1.04,250]],"ltp":2.54,"tv":218.84,"id":8858707}]}]}
{"op":"mcm","clk":"11939160329","pt":1724833344632,"mc":[{"id":"1.232283868","rc":[{"batb":[[0,1.05,201.04],[1,1.04,250],[2,1.03,533.33]],"ltp":2.54,"tv":218.84,"id":8858707}]}]}
{"op":"mcm","clk":"11939160442","pt":1724833348316,"mc":[{"id":"1.232283868","rc":[{"batb":[[0,1.06,5],[1,1.05,201.04],[2,1.04,250]],"ltp":2.54,"tv":218.84,"id":8858707}]}]}
{"op":"mcm","clk":"11939160580","pt":1724833351818,"mc":[{"id":"1.232283868","rc":[{"batb":[[0,1.05,201.04],[1,1.04,250],[2,1.03,533.33]],"ltp":2.54,"tv":218.84,"id":8858707}]}]}
{"op":"mcm","clk":"11939160660","pt":1724833354229,"mc":[{"id":"1.232283868","rc":[{"batb":[[0,1.06,5],[1,1.05,201.04],[2,1.04,250]],"ltp":2.54,"tv":218.84,"id":8858707}]}]}
{"op":"mcm","clk":"11939160742","pt":1724833357731,"mc":[{"id":"1.232283868","rc":[{"batb":[[0,1.05,201.04],[1,1.04,250],[2,1.03,533.33]],"ltp":2.54,"tv":218.84,"id":8858707}]}]}
{"op":"mcm","clk":"11939160859","pt":1724833360922,"mc":[{"id":"1.232283868","rc":[{"batb":[[0,1.06,5],[1,1.05,201.04],[2,1.04,250]],"ltp":2.54,"tv":218.84,"id":8858707}]}]}
{"op":"mcm","clk":"11939161026","pt":1724833364431,"mc":[{"id":"1.232283868","rc":[{"batb":[[0,1.05,201.04],[1,1.04,250],[2,1.03,533.33]],"ltp":2.54,"tv":218.84,"id":8858707}]}]}
{"op":"mcm","clk":"11939161138","pt":1724833366945,"mc":[{"id":"1.232283868","rc":[{"batb":[[0,1.06,5],[1,1.05,201.04],[2,1.04,250]],"ltp":2.54,"tv":218.84,"id":8858707}]}]}
{"op":"mcm","clk":"11939161246","pt":1724833370337,"mc":[{"id":"1.232283868","rc":[{"batb":[[0,1.05,201.04],[1,1.04,250],[2,1.03,533.33]],"ltp":2.54,"tv":218.84,"id":8858707}]}]}
{"op":"mcm","clk":"11939161385","pt":1724833374238,"mc":[{"id":"1.232283868","rc":[{"batb":[[0,1.06,5],[1,1.05,201.04],[2,1.04,250]],"ltp":2.54,"tv":218.84,"id":8858707}]}]}
{"op":"mcm","clk":"11939161503","pt":1724833377630,"mc":[{"id":"1.232283868","rc":[{"batb":[[0,1.05,201.04],[1,1.04,250],[2,1.03,533.33]],"ltp":2.54,"tv":218.84,"id":8858707}]}]}
{"op":"mcm","clk":"11939161631","pt":1724833381240,"mc":[{"id":"1.232283868","rc":[{"batb":[[0,1.06,5],[1,1.05,201.04],[2,1.04,250]],"ltp":2.54,"tv":218.84,"id":8858707}]}]}
{"op":"mcm","clk":"11939161754","pt":1724833384740,"mc":[{"id":"1.232283868","rc":[{"batb":[[0,1.05,201.04],[1,1.04,250],[2,1.03,533.33]],"ltp":2.54,"tv":218.84,"id":8858707}]}]}
{"op":"mcm","clk":"11939161849","pt":1724833387263,"mc":[{"id":"1.232283868","rc":[{"batb":[[0,1.06,5],[1,1.05,201.04],[2,1.04,250]],"ltp":2.54,"tv":218.84,"id":8858707}]}]}
{"op":"mcm","clk":"11939161966","pt":1724833390550,"mc":[{"id":"1.232283868","rc":[{"batb":[[0,1.05,201.04],[1,1.04,250],[2,1.03,533.33]],"ltp":2.54,"tv":218.84,"id":8858707}]}]}
{"op":"mcm","clk":"11939162091","pt":1724833394947,"mc":[{"id":"1.232283868","rc":[{"batb":[[0,1.06,5],[1,1.05,201.04],[2,1.04,250]],"ltp":2.54,"tv":218.84,"id":8858707}]}]}
{"op":"mcm","clk":"11939162186","pt":1724833398453,"mc":[{"id":"1.232283868","rc":[{"batb":[[0,1.05,201.04],[1,1.04,250],[2,1.03,533.33]],"ltp":2.54,"tv":218.84,"id":8858707}]}]}
{"op":"mcm","clk":"11939162269","pt":1724833401063,"mc":[{"id":"1.232283868","rc":[{"batb":[[0,1.06,5],[1,1.05,201.04],[2,1.04,250]],"ltp":2.54,"tv":218.84,"id":8858707}]}]}
{"op":"mcm","clk":"11939162345","pt":1724833404294,"mc":[{"id":"1.232283868","rc":[{"batb":[[0,1.05,201.04],[1,1.04,250],[2,1.03,533.33]],"ltp":2.54,"tv":218.84,"id":8858707}]}]}
{"op":"mcm","clk":"11939162448","pt":1724833407378,"mc":[{"id":"1.232283868","rc":[{"batb":[[0,1.06,5],[1,1.05,201.04],[2,1.04,250]],"ltp":2.54,"tv":218.84,"id":8858707}]}]}
{"op":"mcm","clk":"11939162547","pt":1724833410661,"mc":[{"id":"1.232283868","rc":[{"batb":[[0,1.05,201.04],[1,1.04,250],[2,1.03,533.33]],"ltp":2.54,"tv":218.84,"id":8858707}]}]}
{"op":"mcm","clk":"11939162630","pt":1724833413596,"mc":[{"id":"1.232283868","rc":[{"batb":[[0,1.06,5],[1,1.05,201.04],[2,1.04,250]],"ltp":2.54,"tv":218.84,"id":8858707}]}]}
{"op":"mcm","clk":"11939162729","pt":1724833417188,"mc":[{"id":"1.232283868","rc":[{"batb":[[0,1.05,201.04],[1,1.04,250],[2,1.03,533.33]],"ltp":2.54,"tv":218.84,"id":8858707}]}]}
{"op":"mcm","clk":"11939162810","pt":1724833419596,"mc":[{"id":"1.232283868","rc":[{"batb":[[0,1.06,5],[1,1.05,201.04],[2,1.04,250]],"ltp":2.54,"tv":218.84,"id":8858707}]}]}
{"op":"mcm","clk":"11939162947","pt":1724833423086,"mc":[{"id":"1.232283868","rc":[{"batb":[[0,1.05,201.04],[1,1.04,250],[2,1.03,533.33]],"ltp":2.54,"tv":218.84,"id":8858707}]}]}
{"op":"mcm","clk":"11939163027","pt":1724833425614,"mc":[{"id":"1.232283868","rc":[{"batb":[[0,1.06,5],[1,1.05,201.04],[2,1.04,250]],"ltp":2.54,"tv":218.84,"id":8858707}]}]}
{"op":"mcm","clk":"11939163108","pt":1724833428999,"mc":[{"id":"1.232283868","rc":[{"batb":[[0,1.05,201.04],[1,1.04,250],[2,1.03,533.33]],"ltp":2.54,"tv":218.84,"id":8858707}]}]}
{"op":"mcm","clk":"11939163184","pt":1724833431509,"mc":[{"id":"1.232283868","rc":[{"batb":[[0,1.06,5],[1,1.05,201.04],[2,1.04,250]],"ltp":2.54,"tv":218.84,"id":8858707}]}]}
{"op":"mcm","clk":"11939163288","pt":1724833434897,"mc":[{"id":"1.232283868","rc":[{"batb":[[0,1.05,201.04],[1,1.04,250],[2,1.03,533.33]],"ltp":2.54,"tv":218.84,"id":8858707}]}]}
{"op":"mcm","clk":"11939163354","pt":1724833437711,"mc":[{"id":"1.232283868","rc":[{"batb":[[0,1.06,5],[1,1.05,201.04],[2,1.04,250]],"ltp":2.54,"tv":218.84,"id":8858707}]}]}
{"op":"mcm","clk":"11939163455","pt":1724833441199,"mc":[{"id":"1.232283868","rc":[{"batb":[[0,1.05,201.04],[1,1.04,250],[2,1.03,533.33]],"ltp":2.54,"tv":218.84,"id":8858707}]}]}
{"op":"mcm","clk":"11939163563","pt":1724833443816,"mc":[{"id":"1.232283868","rc":[{"batb":[[0,1.06,5],[1,1.05,201.04],[2,1.04,250]],"ltp":2.54,"tv":218.84,"id":8858707}]}]}
{"op":"mcm","clk":"11939163691","pt":1724833447301,"mc":[{"id":"1.232283868","rc":[{"batb":[[0,1.05,201.04],[1,1.04,250],[2,1.03,533.33]],"ltp":2.54,"tv":218.84,"id":8858707}]}]}
{"op":"mcm","clk":"11939163758","pt":1724833449807,"mc":[{"id":"1.232283868","rc":[{"batb":[[0,1.06,5],[1,1.05,201.04],[2,1.04,250]],"ltp":2.54,"tv":218.84,"id":8858707}]}]}
{"op":"mcm","clk":"11939163848","pt":1724833453333,"mc":[{"id":"1.232283868","rc":[{"batb":[[0,1.05,201.04],[1,1.04,250],[2,1.03,533.33]],"ltp":2.54,"tv":218.84,"id":8858707}]}]}
{"op":"mcm","clk":"11939163953","pt":1724833456043,"mc":[{"id":"1.232283868","rc":[{"batb":[[0,1.06,5],[1,1.05,201.04],[2,1.04,250]],"ltp":2.54,"tv":218.84,"id":8858707}]}]}
{"op":"mcm","clk":"11939164032","pt":1724833459221,"mc":[{"id":"1.232283868","rc":[{"batb":[[0,1.05,201.04],[1,1.04,250],[2,1.03,533.33]],"ltp":2.54,"tv":218.84,"id":8858707}]}]}
{"op":"mcm","clk":"11939164187","pt":1724833464339,"mc":[{"id":"1.232283868","rc":[{"batb":[[0,1.06,5],[1,1.05,201.04],[2,1.04,250]],"ltp":2.54,"tv":218.84,"id":8858707}]}]}
{"op":"mcm","clk":"11939164287","pt":1724833467765,"mc":[{"id":"1.232283868","rc":[{"batb":[[0,1.05,201.04],[1,1.04,250],[2,1.03,533.33]],"ltp":2.54,"tv":218.84,"id":8858707}]}]}
{"op":"mcm","clk":"11939164498","pt":1724833472636,"mc":[{"id":"1.232283868","rc":[{"batb":[[0,1.06,5],[1,1.05,201.04],[2,1.04,250]],"ltp":2.54,"tv":218.84,"id":8858707}]}]}
{"op":"mcm","clk":"11939164674","pt":1724833476840,"mc":[{"id":"1.232283868","rc":[{"batb":[[0,1.05,201.04],[1,1.04,250],[2,1.03,533.33]],"ltp":2.54,"tv":218.84,"id":8858707}]}]}
{"op":"mcm","clk":"11939164998","pt":1724833486755,"mc":[{"id":"1.232283868","rc":[{"batb":[[0,1.06,5],[1,1.05,201.04],[2,1.04,250]],"ltp":2.54,"tv":218.84,"id":8858707}]}]}
{"op":"mcm","clk":"11939165083","pt":1724833490271,"mc":[{"id":"1.232283868","rc":[{"batb":[[0,1.05,201.04],[1,1.04,250],[2,1.03,533.33]],"ltp":2.54,"tv":218.84,"id":8858707}]}]}
{"op":"mcm","clk":"11939165261","pt":1724833494253,"mc":[{"id":"1.232283868","rc":[{"batb":[[0,1.06,5],[1,1.05,201.04],[2,1.04,250]],"ltp":2.54,"tv":218.84,"id":8858707}]}]}
{"op":"mcm","clk":"11939165478","pt":1724833499070,"mc":[{"id":"1.232283868","rc":[{"batb":[[0,1.05,201.04],[1,1.04,250],[2,1.03,533.33]],"ltp":2.54,"tv":218.84,"id":8858707}]}]}
{"op":"mcm","clk":"11939165561","pt":1724833502068,"mc":[{"id":"1.232283868","rc":[{"batb":[[0,1.06,5],[1,1.05,201.04],[2,1.04,250]],"ltp":2.54,"tv":218.84,"id":8858707}]}]}
{"op":"mcm","clk":"11939165639","pt":1724833505412,"mc":[{"id":"1.232283868","rc":[{"batb":[[0,1.05,201.04],[1,1.04,250],[2,1.03,533.33]],"ltp":2.54,"tv":218.84,"id":8858707}]}]}
{"op":"mcm","clk":"11939165746","pt":1724833508284,"mc":[{"id":"1.232283868","rc":[{"batb":[[0,1.06,5],[1,1.05,201.04],[2,1.04,250]],"ltp":2.54,"tv":218.84,"id":8858707}]}]}
{"op":"mcm","clk":"11939165862","pt":1724833511880,"mc":[{"id":"1.232283868","rc":[{"batb":[[0,1.05,201.04],[1,1.04,250],[2,1.03,533.33]],"ltp":2.54,"tv":218.84,"id":8858707}]}]}
{"op":"mcm","clk":"11939165998","pt":1724833515133,"mc":[{"id":"1.232283868","rc":[{"batb":[[0,1.06,5],[1,1.05,201.04],[2,1.04,250]],"ltp":2.54,"tv":218.84,"id":8858707}]}]}
{"op":"mcm","clk":"11939166136","pt":1724833518988,"mc":[{"id":"1.232283868","rc":[{"batb":[[0,1.05,201.04],[1,1.04,250],[2,1.03,533.33]],"ltp":2.54,"tv":218.84,"id":8858707}]}]}
{"op":"mcm","clk":"11939166209","pt":1724833521699,"mc":[{"id":"1.232283868","rc":[{"batb":[[0,1.06,5],[1,1.05,201.04],[2,1.04,250]],"ltp":2.54,"tv":218.84,"id":8858707}]}]}
{"op":"mcm","clk":"11939166310","pt":1724833524926,"mc":[{"id":"1.232283868","rc":[{"batb":[[0,1.05,201.04],[1,1.04,250],[2,1.03,533.33]],"ltp":2.54,"tv":218.84,"id":8858707}]}]}
{"op":"mcm","clk":"11939166530","pt":1724833532027,"mc":[{"id":"1.232283868","rc":[{"batb":[[0,1.06,5],[1,1.05,201.04],[2,1.04,250]],"ltp":2.54,"tv":218.84,"id":8858707}]}]}
{"op":"mcm","clk":"11939166652","pt":1724833535512,"mc":[{"id":"1.232283868","rc":[{"batb":[[0,1.05,201.04],[1,1.04,250],[2,1.03,533.33]],"ltp":2.54,"tv":218.84,"id":8858707}]}]}
{"op":"mcm","clk":"11939166699","pt":1724833537920,"mc":[{"id":"1.232283868","rc":[{"batb":[[0,1.06,5],[1,1.05,201.04],[2,1.04,250]],"ltp":2.54,"tv":218.84,"id":8858707}]}]}
{"op":"mcm","clk":"11939166797","pt":1724833541323,"mc":[{"id":"1.232283868","rc":[{"batb":[[0,1.05,201.04],[1,1.04,250],[2,1.03,533.33]],"ltp":2.54,"tv":218.84,"id":8858707}]}]}
{"op":"mcm","clk":"11939166897","pt":1724833543937,"mc":[{"id":"1.232283868","rc":[{"batb":[[0,1.06,5],[1,1.05,201.04],[2,1.04,250]],"ltp":2.54,"tv":218.84,"id":8858707}]}]}
{"op":"mcm","clk":"11939166983","pt":1724833547222,"mc":[{"id":"1.232283868","rc":[{"batb":[[0,1.05,201.04],[1,1.04,250],[2,1.03,533.33]],"ltp":2.54,"tv":218.84,"id":8858707}]}]}
{"op":"mcm","clk":"11939167102","pt":1724833549947,"mc":[{"id":"1.232283868","rc":[{"batb":[[0,1.06,5],[1,1.05,201.04],[2,1.04,250]],"ltp":2.54,"tv":218.84,"id":8858707}]}]}
{"op":"mcm","clk":"11939167253","pt":1724833553340,"mc":[{"id":"1.232283868","rc":[{"batb":[[0,1.05,201.04],[1,1.04,250],[2,1.03,533.33]],"ltp":2.54,"tv":218.84,"id":8858707}]}]}
{"op":"mcm","clk":"11939167336","pt":1724833555859,"mc":[{"id":"1.232283868","rc":[{"batb":[[0,1.06,5],[1,1.05,201.04],[2,1.04,250]],"ltp":2.54,"tv":218.84,"id":8858707}]}]}
{"op":"mcm","clk":"11939167432","pt":1724833559036,"mc":[{"id":"1.232283868","rc":[{"batb":[[0,1.05,201.04],[1,1.04,250],[2,1.03,533.33]],"ltp":2.54,"tv":218.84,"id":8858707}]}]}
{"op":"mcm","clk":"11939167504","pt":1724833561557,"mc":[{"id":"1.232283868","rc":[{"batb":[[0,1.06,5],[1,1.05,201.04],[2,1.04,250]],"ltp":2.54,"tv":218.84,"id":8858707}]}]}
{"op":"mcm","clk":"11939167651","pt":1724833564959,"mc":[{"id":"1.232283868","rc":[{"batb":[[0,1.05,201.04],[1,1.04,250],[2,1.03,533.33]],"ltp":2.54,"tv":218.84,"id":8858707}]}]}
{"op":"mcm","clk":"11939167757","pt":1724833567437,"mc":[{"id":"1.232283868","rc":[{"batb":[[0,1.06,5],[1,1.05,201.04],[2,1.04,250]],"ltp":2.54,"tv":218.84,"id":8858707}]}]}
{"op":"mcm","clk":"11939167878","pt":1724833571139,"mc":[{"id":"1.232283868","rc":[{"batb":[[0,1.05,201.04],[1,1.04,250],[2,1.03,533.33]],"ltp":2.54,"tv":218.84,"id":8858707}]}]}
{"op":"mcm","clk":"11939167973","pt":1724833573768,"mc":[{"id":"1.232283868","rc":[{"batb":[[0,1.06,5],[1,1.05,201.04],[2,1.04,250]],"ltp":2.54,"tv":218.84,"id":8858707}]}]}
{"op":"mcm","clk":"11939168109","pt":1724833577263,"mc":[{"id":"1.232283868","rc":[{"batb":[[0,1.05,201.04],[1,1.04,250],[2,1.03,533.33]],"ltp":2.54,"tv":218.84,"id":8858707}]}]}
{"op":"mcm","clk":"11939168204","pt":1724833580041,"mc":[{"id":"1.232283868","rc":[{"batb":[[0,1.06,5],[1,1.05,201.04],[2,1.04,250]],"ltp":2.54,"tv":218.84,"id":8858707}]}]}
{"op":"mcm","clk":"11939168319","pt":1724833583550,"mc":[{"id":"1.232283868","rc":[{"batb":[[0,1.05,201.04],[1,1.04,250],[2,1.03,533.33]],"ltp":2.54,"tv":218.84,"id":8858707}]}]}
{"op":"mcm","clk":"11939168458","pt":1724833586175,"mc":[{"id":"1.232283868","rc":[{"batb":[[0,1.06,5],[1,1.05,201.04],[2,1.04,250]],"ltp":2.54,"tv":218.84,"id":8858707}]}]}
{"op":"mcm","clk":"11939168619","pt":1724833589673,"mc":[{"id":"1.232283868","rc":[{"batb":[[0,1.05,201.04],[1,1.04,250],[2,1.03,533.33]],"ltp":2.54,"tv":218.84,"id":8858707}]}]}
{"op":"mcm","clk":"11939168713","pt":1724833592396,"mc":[{"id":"1.232283868","rc":[{"batb":[[0,1.06,5],[1,1.05,201.04],[2,1.04,250]],"ltp":2.54,"tv":218.84,"id":8858707}]}]}
{"op":"mcm","clk":"11939168807","pt":1724833595702,"mc":[{"id":"1.232283868","rc":[{"batb":[[0,1.05,201.04],[1,1.04,250],[2,1.03,533.33]],"ltp":2.54,"tv":218.84,"id":8858707}]}]}
{"op":"mcm","clk":"11939168926","pt":1724833598691,"mc":[{"id":"1.232283868","rc":[{"batb":[[0,1.06,5],[1,1.05,201.04],[2,1.04,250]],"ltp":2.54,"tv":218.84,"id":8858707}]}]}
{"op":"mcm","clk":"11939169042","pt":1724833602001,"mc":[{"id":"1.232283868","rc":[{"batb":[[0,1.05,201.04],[1,1.04,250],[2,1.03,533.33]],"ltp":2.54,"tv":218.84,"id":8858707}]}]}
{"op":"mcm","clk":"11939169141","pt":1724833604890,"mc":[{"id":"1.232283868","rc":[{"batb":[[0,1.06,5],[1,1.05,201.04],[2,1.04,250]],"ltp":2.54,"tv":218.84,"id":8858707}]}]}
{"op":"mcm","clk":"11939169269","pt":1724833608500,"mc":[{"id":"1.232283868","rc":[{"batb":[[0,1.05,201.04],[1,1.04,250],[2,1.03,533.33]],"ltp":2.54,"tv":218.84,"id":8858707}]}]}
{"op":"mcm","clk":"11939169360","pt":1724833611175,"mc":[{"id":"1.232283868","rc":[{"batb":[[0,1.06,5],[1,1.05,201.04],[2,1.04,250]],"ltp":2.54,"tv":218.84,"id":8858707}]}]}
{"op":"mcm","clk":"11939169494","pt":1724833614771,"mc":[{"id":"1.232283868","rc":[{"batb":[[0,1.05,201.04],[1,1.04,250],[2,1.03,533.33]],"ltp":2.54,"tv":218.84,"id":8858707}]}]}
{"op":"mcm","clk":"11939169598","pt":1724833617606,"mc":[{"id":"1.232283868","rc":[{"batb":[[0,1.06,5],[1,1.05,201.04],[2,1.04,250]],"ltp":2.54,"tv":218.84,"id":8858707}]}]}
{"op":"mcm","clk":"11939169724","pt":1724833621322,"mc":[{"id":"1.232283868","rc":[{"batb":[[0,1.05,201.04],[1,1.04,250],[2,1.03,533.33]],"ltp":2.54,"tv":218.84,"id":8858707}]}]}
{"op":"mcm","clk":"11939169877","pt":1724833625382,"mc":[{"id":"1.232283868","rc":[{"batb":[[0,1.06,5],[1,1.05,201.04],[2,1.04,250]],"ltp":2.54,"tv":218.84,"id":8858707}]}]}
{"op":"mcm","clk":"11939170042","pt":1724833629806,"mc":[{"id":"1.232283868","rc":[{"batb":[[0,1.05,201.04],[1,1.04,250],[2,1.03,533.33]],"ltp":2.54,"tv":218.84,"id":8858707}]}]}
{"op":"mcm","clk":"11939170231","pt":1724833633931,"mc":[{"id":"1.232283868","rc":[{"batb":[[0,1.06,5],[1,1.05,201.04],[2,1.04,250]],"ltp":2.54,"tv":218.84,"id":8858707}]}]}
{"op":"mcm","clk":"11939170367","pt":1724833637122,"mc":[{"id":"1.232283868","rc":[{"batb":[[0,1.05,201.04],[1,1.04,250],[2,1.03,533.33]],"ltp":2.54,"tv":218.84,"id":8858707}]}]}
{"op":"mcm","clk":"11939170529","pt":1724833640842,"mc":[{"id":"1.232283868","rc":[{"batb":[[0,1.06,5],[1,1.05,201.04],[2,1.04,250]],"ltp":2.54,"tv":218.84,"id":8858707}]}]}
{"op":"mcm","clk":"11939170662","pt":1724833644435,"mc":[{"id":"1.232283868","rc":[{"batb":[[0,1.05,201.04],[1,1.04,250],[2,1.03,533.33]],"ltp":2.54,"tv":218.84,"id":8858707}]}]}
{"op":"mcm","clk":"11939170746","pt":1724833647620,"mc":[{"id":"1.232283868","rc":[{"batb":[[0,1.06,5],[1,1.05,201.04],[2,1.04,250]],"ltp":2.54,"tv":218.84,"id":8858707}]}]}
{"op":"mcm","clk":"11939170858","pt":1724833651021,"mc":[{"id":"1.232283868","rc":[{"batb":[[0,1.05,201.04],[1,1.04,250],[2,1.03,533.33]],"ltp":2.54,"tv":218.84,"id":8858707}]}]}
{"op":"mcm","clk":"11939170979","pt":1724833653840,"mc":[{"id":"1.232283868","rc":[{"batb":[[0,1.06,5],[1,1.05,201.04],[2,1.04,250]],"ltp":2.54,"tv":218.84,"id":8858707}]}]}
{"op":"mcm","clk":"11939171123","pt":1724833657331,"mc":[{"id":"1.232283868","rc":[{"batb":[[0,1.05,201.04],[1,1.04,250],[2,1.03,533.33]],"ltp":2.54,"tv":218.84,"id":8858707}]}]}
{"op":"mcm","clk":"11939171293","pt":1724833661558,"mc":[{"id":"1.232283868","rc":[{"batb":[[0,1.06,5],[1,1.05,201.04],[2,1.04,250]],"ltp":2.54,"tv":218.84,"id":8858707}]}]}
{"op":"mcm","clk":"11939171429","pt":1724833665050,"mc":[{"id":"1.232283868","rc":[{"batb":[[0,1.05,201.04],[1,1.04,250],[2,1.03,533.33]],"ltp":2.54,"tv":218.84,"id":8858707}]}]}
{"op":"mcm","clk":"11939171561","pt":1724833668458,"mc":[{"id":"1.232283868","rc":[{"batb":[[0,1.06,5],[1,1.05,201.04],[2,1.04,250]],"ltp":2.54,"tv":218.84,"id":8858707}]}]}
{"op":"mcm","clk":"11939171709","pt":1724833671841,"mc":[{"id":"1.232283868","rc":[{"batb":[[0,1.05,201.04],[1,1.04,250],[2,1.03,533.33]],"ltp":2.54,"tv":218.84,"id":8858707}]}]}
{"op":"mcm","clk":"11939171798","pt":1724833674052,"mc":[{"id":"1.232283868","rc":[{"batb":[[0,1.06,5],[1,1.05,201.04],[2,1.04,250]],"ltp":2.54,"tv":218.84,"id":8858707}]}]}
{"op":"mcm","clk":"11939171899","pt":1724833677588,"mc":[{"id":"1.232283868","rc":[{"batb":[[0,1.05,201.04],[1,1.04,250],[2,1.03,533.33]],"ltp":2.54,"tv":218.84,"id":8858707}]}]}
{"op":"mcm","clk":"11939171989","pt":1724833680466,"mc":[{"id":"1.232283868","rc":[{"batb":[[0,1.06,5],[1,1.05,201.04],[2,1.04,250]],"ltp":2.54,"tv":218.84,"id":8858707}]}]}
{"op":"mcm","clk":"11939172128","pt":1724833683653,"mc":[{"id":"1.232283868","rc":[{"batb":[[0,1.05,201.04],[1,1.04,250],[2,1.03,533.33]],"ltp":2.54,"tv":218.84,"id":8858707}]}]}
{"op":"mcm","clk":"11939172226","pt":1724833686061,"mc":[{"id":"1.232283868","rc":[{"batb":[[0,1.06,5],[1,1.05,201.04],[2,1.04,250]],"ltp":2.54,"tv":218.84,"id":8858707}]}]}
{"op":"mcm","clk":"11939172347","pt":1724833689701,"mc":[{"id":"1.232283868","rc":[{"batb":[[0,1.05,201.04],[1,1.04,250],[2,1.03,533.33]],"ltp":2.54,"tv":218.84,"id":8858707}]}]}
{"op":"mcm","clk":"11939172443","pt":1724833692364,"mc":[{"id":"1.232283868","rc":[{"batb":[[0,1.06,5],[1,1.05,201.04],[2,1.04,250]],"ltp":2.54,"tv":218.84,"id":8858707}]}]}
{"op":"mcm","clk":"11939172662","pt":1724833697894,"mc":[{"id":"1.232283868","rc":[{"batb":[[0,1.05,201.04],[1,1.04,250],[2,1.03,533.33]],"ltp":2.54,"tv":218.84,"id":8858707}]}]}
{"op":"mcm","clk":"11939172877","pt":1724833703905,"mc":[{"id":"1.232283868","rc":[{"batb":[[0,1.06,5],[1,1.05,201.04],[2,1.04,250]],"ltp":2.54,"tv":218.84,"id":8858707}]}]}
{"op":"mcm","clk":"11939173050","pt":1724833707490,"mc":[{"id":"1.232283868","rc":[{"batb":[[0,1.05,201.04],[1,1.04,250],[2,1.03,533.33]],"ltp":2.54,"tv":218.84,"id":8858707}]}]}
{"op":"mcm","clk":"11939173158","pt":1724833709697,"mc":[{"id":"1.232283868","rc":[{"batb":[[0,1.06,5],[1,1.05,201.04],[2,1.04,250]],"ltp":2.54,"tv":218.84,"id":8858707}]}]}
{"op":"mcm","clk":"11939173319","pt":1724833714113,"mc":[{"id":"1.232283868","rc":[{"batb":[[0,1.05,201.04],[1,1.04,250],[2,1.03,533.33]],"ltp":2.54,"tv":218.84,"id":8858707}]}]}
{"op":"mcm","clk":"11939173513","pt":1724833720009,"mc":[{"id":"1.232283868","rc":[{"batb":[[0,1.06,5],[1,1.05,201.04],[2,1.04,250]],"ltp":2.54,"tv":218.84,"id":8858707}]}]}
{"op":"mcm","clk":"11939173667","pt":1724833723798,"mc":[{"id":"1.232283868","rc":[{"batb":[[0,1.05,201.04],[1,1.04,250],[2,1.03,533.33]],"ltp":2.54,"tv":218.84,"id":8858707}]}]}
{"op":"mcm","clk":"11939173825","pt":1724833728520,"mc":[{"id":"1.232283868","rc":[{"batb":[[0,1.06,5],[1,1.05,201.04],[2,1.04,250]],"ltp":2.54,"tv":218.84,"id":8858707}]}]}
{"op":"mcm","clk":"11939173946","pt":1724833731841,"mc":[{"id":"1.232283868","rc":[{"batb":[[0,1.05,201.04],[1,1.04,250],[2,1.03,533.33]],"ltp":2.54,"tv":218.84,"id":8858707}]}]}
{"op":"mcm","clk":"11939174062","pt":1724833735739,"mc":[{"id":"1.232283868","rc":[{"batb":[[0,1.06,5],[1,1.05,201.04],[2,1.04,250]],"ltp":2.54,"tv":218.84,"id":8858707}]}]}
{"op":"mcm","clk":"11939174190","pt":1724833739145,"mc":[{"id":"1.232283868","rc":[{"batb":[[0,1.05,201.04],[1,1.04,250],[2,1.03,533.33]],"ltp":2.54,"tv":218.84,"id":8858707}]}]}
{"op":"mcm","clk":"11939174422","pt":1724833744237,"mc":[{"id":"1.232283868","rc":[{"batb":[[0,1.06,5],[1,1.05,201.04],[2,1.04,250]],"ltp":2.54,"tv":218.84,"id":8858707}]}]}
{"op":"mcm","clk":"11939174546","pt":1724833747928,"mc":[{"id":"1.232283868","rc":[{"batb":[[0,1.05,201.04],[1,1.04,250],[2,1.03,533.33]],"ltp":2.54,"tv":218.84,"id":8858707}]}]}
{"op":"mcm","clk":"11939174644","pt":1724833750750,"mc":[{"id":"1.232283868","rc":[{"batb":[[0,1.06,5],[1,1.05,201.04],[2,1.04,250]],"ltp":2.54,"tv":218.84,"id":8858707}]}]}
{"op":"mcm","clk":"11939174761","pt":1724833754180,"mc":[{"id":"1.232283868","rc":[{"batb":[[0,1.05,201.04],[1,1.04,250],[2,1.03,533.33]],"ltp":2.54,"tv":218.84,"id":8858707}]}]}
{"op":"mcm","clk":"11939174954","pt":1724833757566,"mc":[{"id":"1.232283868","rc":[{"batb":[[0,1.06,5],[1,1.05,201.04],[2,1.04,250]],"ltp":2.54,"tv":218.84,"id":8858707}]}]}
{"op":"mcm","clk":"11939175079","pt":1724833760949,"mc":[{"id":"1.232283868","rc":[{"batb":[[0,1.05,201.04],[1,1.04,250],[2,1.03,533.33]],"ltp":2.54,"tv":218.84,"id":8858707}]}]}
{"op":"mcm","clk":"11939175184","pt":1724833763772,"mc":[{"id":"1.232283868","rc":[{"batb":[[0,1.06,5],[1,1.05,201.04],[2,1.04,250]],"ltp":2.54,"tv":218.84,"id":8858707}]}]}
{"op":"mcm","clk":"11939175322","pt":1724833767562,"mc":[{"id":"1.232283868","rc":[{"batb":[[0,1.05,201.04],[1,1.04,250],[2,1.03,533.33]],"ltp":2.54,"tv":218.84,"id":8858707}]}]}
{"op":"mcm","clk":"11939175412","pt":1724833769966,"mc":[{"id":"1.232283868","rc":[{"batb":[[0,1.06,5],[1,1.05,201.04],[2,1.04,250]],"ltp":2.54,"tv":218.84,"id":8858707}]}]}
{"op":"mcm","clk":"11939175518","pt":1724833773460,"mc":[{"id":"1.232283868","rc":[{"batb":[[0,1.05,201.04],[1,1.04,250],[2,1.03,533.33]],"ltp":2.54,"tv":218.84,"id":8858707}]}]}
{"op":"mcm","clk":"11939175632","pt":1724833777062,"mc":[{"id":"1.232283868","rc":[{"batb":[[0,1.06,5],[1,1.05,201.04],[2,1.04,250]],"ltp":2.54,"tv":218.84,"id":8858707}]}]}
{"op":"mcm","clk":"11939175776","pt":1724833780594,"mc":[{"id":"1.232283868","rc":[{"batb":[[0,1.05,201.04],[1,1.04,250],[2,1.03,533.33]],"ltp":2.54,"tv":218.84,"id":8858707}]}]}
{"op":"mcm","clk":"11939175867","pt":1724833782898,"mc":[{"id":"1.232283868","rc":[{"batb":[[0,1.06,5],[1,1.05,201.04],[2,1.04,250]],"ltp":2.54,"tv":218.84,"id":8858707}]}]}
{"op":"mcm","clk":"11939176035","pt":1724833786197,"mc":[{"id":"1.232283868","rc":[{"batb":[[0,1.05,201.04],[1,1.04,250],[2,1.03,533.33]],"ltp":2.54,"tv":218.84,"id":8858707}]}]}
{"op":"mcm","clk":"11939176222","pt":1724833790868,"mc":[{"id":"1.232283868","rc":[{"batb":[[0,1.06,5],[1,1.05,201.04],[2,1.04,250]],"ltp":2.54,"tv":218.84,"id":8858707}]}]}
{"op":"mcm","clk":"11939176338","pt":1724833794311,"mc":[{"id":"1.232283868","rc":[{"batb":[[0,1.05,201.04],[1,1.04,250],[2,1.03,533.33]],"ltp":2.54,"tv":218.84,"id":8858707}]}]}
{"op":"mcm","clk":"11939176436","pt":1724833796987,"mc":[{"id":"1.232283868","rc":[{"batb":[[0,1.06,5],[1,1.05,201.04],[2,1.04,250]],"ltp":2.54,"tv":218.84,"id":8858707}]}]}
{"op":"mcm","clk":"11939176573","pt":1724833800313,"mc":[{"id":"1.232283868","rc":[{"batb":[[0,1.05,201.04],[1,1.04,250],[2,1.03,533.33]],"ltp":2.54,"tv":218.84,"id":8858707}]}]}
{"op":"mcm","clk":"11939176805","pt":1724833803992,"mc":[{"id":"1.232283868","rc":[{"batb":[[0,1.06,5],[1,1.05,201.04],[2,1.04,250]],"ltp":2.54,"tv":218.84,"id":8858707}]}]}
{"op":"mcm","clk":"11939176977","pt":1724833807497,"mc":[{"id":"1.232283868","rc":[{"batb":[[0,1.05,201.04],[1,1.04,250],[2,1.03,533.33]],"ltp":2.54,"tv":218.84,"id":8858707}]}]}
{"op":"mcm","clk":"11939177087","pt":1724833809919,"mc":[{"id":"1.232283868","rc":[{"batb":[[0,1.06,5],[1,1.05,201.04],[2,1.04,250]],"ltp":2.54,"tv":218.84,"id":8858707}]}]}
{"op":"mcm","clk":"11939177300","pt":1724833813894,"mc":[{"id":"1.232283868","rc":[{"batb":[[0,1.05,201.04],[1,1.04,250],[2,1.03,533.33]],"ltp":2.54,"tv":218.84,"id":8858707}]}]}
{"op":"mcm","clk":"11939177407","pt":1724833816413,"mc":[{"id":"1.232283868","rc":[{"batb":[[0,1.06,5],[1,1.05,201.04],[2,1.04,250]],"ltp":2.54,"tv":218.84,"id":8858707}]}]}
{"op":"mcm","clk":"11939177572","pt":1724833819903,"mc":[{"id":"1.232283868","rc":[{"batb":[[0,1.05,201.04],[1,1.04,250],[2,1.03,533.33]],"ltp":2.54,"tv":218.84,"id":8858707}]}]}
{"op":"mcm","clk":"11939177683","pt":1724833822330,"mc":[{"id":"1.232283868","rc":[{"batb":[[0,1.06,5],[1,1.05,201.04],[2,1.04,250]],"ltp":2.54,"tv":218.84,"id":8858707}]}]}
{"op":"mcm","clk":"11939177964","pt":1724833828008,"mc":[{"id":"1.232283868","rc":[{"batb":[[0,1.05,201.04],[1,1.04,250],[2,1.03,533.33]],"ltp":2.54,"tv":218.84,"id":8858707}]}]}
{"op":"mcm","clk":"11939178141","pt":1724833831445,"mc":[{"id":"1.232283868","rc":[{"batb":[[0,1.06,5],[1,1.05,201.04],[2,1.04,250]],"ltp":2.54,"tv":218.84,"id":8858707}]}]}
{"op":"mcm","clk":"11939178337","pt":1724833834933,"mc":[{"id":"1.232283868","rc":[{"batb":[[0,1.05,201.04],[1,1.04,250],[2,1.03,533.33]],"ltp":2.54,"tv":218.84,"id":8858707}]}]}
{"op":"mcm","clk":"11939178496","pt":1724833837952,"mc":[{"id":"1.232283868","rc":[{"batb":[[0,1.06,5],[1,1.05,201.04],[2,1.04,250]],"ltp":2.54,"tv":218.84,"id":8858707}]}]}
{"op":"mcm","clk":"11939178688","pt":1724833841746,"mc":[{"id":"1.232283868","rc":[{"batb":[[0,1.05,201.04],[1,1.04,250],[2,1.03,533.33]],"ltp":2.54,"tv":218.84,"id":8858707}]}]}
{"op":"mcm","clk":"11939178822","pt":1724833844429,"mc":[{"id":"1.232283868","rc":[{"batb":[[0,1.06,5],[1,1.05,201.04],[2,1.04,250]],"ltp":2.54,"tv":218.84,"id":8858707}]}]}
{"op":"mcm","clk":"11939178971","pt":1724833848021,"mc":[{"id":"1.232283868","rc":[{"batb":[[0,1.05,201.04],[1,1.04,250],[2,1.03,533.33]],"ltp":2.54,"tv":218.84,"id":8858707}]}]}
{"op":"mcm","clk":"11939179081","pt":1724833851040,"mc":[{"id":"1.232283868","rc":[{"batb":[[0,1.06,5],[1,1.05,201.04],[2,1.04,250]],"ltp":2.54,"tv":218.84,"id":8858707}]}]}
{"op":"mcm","clk":"11939179239","pt":1724833854525,"mc":[{"id":"1.232283868","rc":[{"batb":[[0,1.05,201.04],[1,1.04,250],[2,1.03,533.33]],"ltp":2.54,"tv":218.84,"id":8858707}]}]}
{"op":"mcm","clk":"11939179396","pt":1724833857349,"mc":[{"id":"1.232283868","rc":[{"batb":[[0,1.06,5],[1,1.05,201.04],[2,1.04,250]],"ltp":2.54,"tv":218.84,"id":8858707}]}]}
{"op":"mcm","clk":"11939179565","pt":1724833860947,"mc":[{"id":"1.232283868","rc":[{"batb":[[0,1.05,201.04],[1,1.04,250],[2,1.03,533.33]],"ltp":2.54,"tv":218.84,"id":8858707}]}]}
{"op":"mcm","clk":"11939179699","pt":1724833863673,"mc":[{"id":"1.232283868","rc":[{"batb":[[0,1.06,5],[1,1.05,201.04],[2,1.04,250]],"ltp":2.54,"tv":218.84,"id":8858707}]}]}
{"op":"mcm","clk":"11939179865","pt":1724833867159,"mc":[{"id":"1.232283868","rc":[{"batb":[[0,1.05,201.04],[1,1.04,250],[2,1.03,533.33]],"ltp":2.54,"tv":218.84,"id":8858707}]}]}
{"op":"mcm","clk":"11939180053","pt":1724833871057,"mc":[{"id":"1.232283868","rc":[{"batb":[[0,1.06,5],[1,1.05,201.04],[2,1.04,250]],"ltp":2.54,"tv":218.84,"id":8858707}]}]}
{"op":"mcm","clk":"11939180220","pt":1724833874383,"mc":[{"id":"1.232283868","rc":[{"batb":[[0,1.05,201.04],[1,1.04,250],[2,1.03,533.33]],"ltp":2.54,"tv":218.84,"id":8858707}]}]}
{"op":"mcm","clk":"11939180395","pt":1724833878285,"mc":[{"id":"1.232283868","rc":[{"batb":[[0,1.06,5],[1,1.05,201.04],[2,1.04,250]],"ltp":2.54,"tv":218.84,"id":8858707}]}]}
{"op":"mcm","clk":"11939180528","pt":1724833881566,"mc":[{"id":"1.232283868","rc":[{"batb":[[0,1.05,201.04],[1,1.04,250],[2,1.03,533.33]],"ltp":2.54,"tv":218.84,"id":8858707}]}]}
{"op":"mcm","clk":"11939180661","pt":1724833884177,"mc":[{"id":"1.232283868","rc":[{"batb":[[0,1.06,5],[1,1.05,201.04],[2,1.04,250]],"ltp":2.54,"tv":218.84,"id":8858707}]}]}
{"op":"mcm","clk":"11939180832","pt":1724833887604,"mc":[{"id":"1.232283868","rc":[{"batb":[[0,1.05,201.04],[1,1.04,250],[2,1.03,533.33]],"ltp":2.54,"tv":218.84,"id":8858707}]}]}
{"op":"mcm","clk":"11939180921","pt":1724833890112,"mc":[{"id":"1.232283868","rc":[{"batb":[[0,1.06,5],[1,1.05,201.04],[2,1.04,250]],"ltp":2.54,"tv":218.84,"id":8858707}]}]}
{"op":"mcm","clk":"11939181073","pt":1724833893603,"mc":[{"id":"1.232283868","rc":[{"batb":[[0,1.05,201.04],[1,1.04,250],[2,1.03,533.33]],"ltp":2.54,"tv":218.84,"id":8858707}]}]}
{"op":"mcm","clk":"11939181219","pt":1724833896486,"mc":[{"id":"1.232283868","rc":[{"batb":[[0,1.06,5],[1,1.05,201.04],[2,1.04,250]],"ltp":2.54,"tv":218.84,"id":8858707}]}]}
{"op":"mcm","clk":"11939181354","pt":1724833900015,"mc":[{"id":"1.232283868","rc":[{"batb":[[0,1.05,201.04],[1,1.04,250],[2,1.03,533.33]],"ltp":2.54,"tv":218.84,"id":8858707}]}]}
{"op":"mcm","clk":"11939181644","pt":1724833906013,"mc":[{"id":"1.232283868","rc":[{"batb":[[0,1.06,5],[1,1.05,201.04],[2,1.04,250]],"ltp":2.54,"tv":218.84,"id":8858707}]}]}
{"op":"mcm","clk":"11939181788","pt":1724833909291,"mc":[{"id":"1.232283868","rc":[{"batb":[[0,1.05,201.04],[1,1.04,250],[2,1.03,533.33]],"ltp":2.54,"tv":218.84,"id":8858707}]}]}
{"op":"mcm","clk":"11939181884","pt":1724833911546,"mc":[{"id":"1.232283868","rc":[{"batb":[[0,1.06,5],[1,1.05,201.04],[2,1.04,250]],"ltp":2.54,"tv":218.84,"id":8858707}]}]}
{"op":"mcm","clk":"11939182042","pt":1724833915052,"mc":[{"id":"1.232283868","rc":[{"batb":[[0,1.05,201.04],[1,1.04,250],[2,1.03,533.33]],"ltp":2.54,"tv":218.84,"id":8858707}]}]}
{"op":"mcm","clk":"11939182215","pt":1724833919150,"mc":[{"id":"1.232283868","rc":[{"batb":[[0,1.06,5],[1,1.05,201.04],[2,1.04,250]],"ltp":2.54,"tv":218.84,"id":8858707}]}]}
{"op":"mcm","clk":"11939182372","pt":1724833922651,"mc":[{"id":"1.232283868","rc":[{"batb":[[0,1.05,201.04],[1,1.04,250],[2,1.03,533.33]],"ltp":2.54,"tv":218.84,"id":8858707}]}]}
{"op":"mcm","clk":"11939182513","pt":1724833925125,"mc":[{"id":"1.232283868","rc":[{"batb":[[0,1.06,5],[1,1.05,201.04],[2,1.04,250]],"ltp":2.54,"tv":218.84,"id":8858707}]}]}
{"op":"mcm","clk":"11939182648","pt":1724833928661,"mc":[{"id":"1.232283868","rc":[{"batb":[[0,1.05,201.04],[1,1.04,250],[2,1.03,533.33]],"ltp":2.54,"tv":218.84,"id":8858707}]}]}
{"op":"mcm","clk":"11939182755","pt":1724833931024,"mc":[{"id":"1.232283868","rc":[{"batb":[[0,1.06,5],[1,1.05,201.04],[2,1.04,250]],"ltp":2.54,"tv":218.84,"id":8858707}]}]}
{"op":"mcm","clk":"11939182894","pt":1724833934770,"mc":[{"id":"1.232283868","rc":[{"batb":[[0,1.05,201.04],[1,1.04,250],[2,1.03,533.33]],"ltp":2.54,"tv":218.84,"id":8858707}]}]}
{"op":"mcm","clk":"11939182995","pt":1724833937134,"mc":[{"id":"1.232283868","rc":[{"batb":[[0,1.06,5],[1,1.05,201.04],[2,1.04,250]],"ltp":2.54,"tv":218.84,"id":8858707}]}]}
{"op":"mcm","clk":"11939183174","pt":1724833940527,"mc":[{"id":"1.232283868","rc":[{"batb":[[0,1.05,201.04],[1,1.04,250],[2,1.03,533.33]],"ltp":2.54,"tv":218.84,"id":8858707}]}]}
{"op":"mcm","clk":"11939183276","pt":1724833943041,"mc":[{"id":"1.232283868","rc":[{"batb":[[0,1.06,5],[1,1.05,201.04],[2,1.04,250]],"ltp":2.54,"tv":218.84,"id":8858707}]}]}
{"op":"mcm","clk":"11939183397","pt":1724833946475,"mc":[{"id":"1.232283868","rc":[{"batb":[[0,1.05,201.04],[1,1.04,250],[2,1.03,533.33]],"ltp":2.54,"tv":218.84,"id":8858707}]}]}
{"op":"mcm","clk":"11939183503","pt":1724833948943,"mc":[{"id":"1.232283868","rc":[{"batb":[[0,1.06,5],[1,1.05,201.04],[2,1.04,250]],"ltp":2.54,"tv":218.84,"id":8858707}]}]}
{"op":"mcm","clk":"11939183676","pt":1724833952282,"mc":[{"id":"1.232283868","rc":[{"batb":[[0,1.05,201.04],[1,1.04,250],[2,1.03,533.33]],"ltp":2.54,"tv":218.84,"id":8858707}]}]}
{"op":"mcm","clk":"11939183835","pt":1724833956082,"mc":[{"id":"1.232283868","rc":[{"batb":[[0,1.06,5],[1,1.05,201.04],[2,1.04,250]],"ltp":2.54,"tv":218.84,"id":8858707}]}]}
{"op":"mcm","clk":"11939183976","pt":1724833959267,"mc":[{"id":"1.232283868","rc":[{"batb":[[0,1.05,201.04],[1,1.04,250],[2,1.03,533.33]],"ltp":2.54,"tv":218.84,"id":8858707}]}]}
{"op":"mcm","clk":"11939184107","pt":1724833962294,"mc":[{"id":"1.232283868","rc":[{"batb":[[0,1.06,5],[1,1.05,201.04],[2,1.04,250]],"ltp":2.54,"tv":218.84,"id":8858707}]}]}
{"op":"mcm","clk":"11939184226","pt":1724833965583,"mc":[{"id":"1.232283868","rc":[{"batb":[[0,1.05,201.04],[1,1.04,250],[2,1.03,533.33]],"ltp":2.54,"tv":218.84,"id":8858707}]}]}
{"op":"mcm","clk":"11939184423","pt":1724833969149,"mc":[{"id":"1.232283868","rc":[{"batb":[[0,1.06,5],[1,1.05,201.04],[2,1.04,250]],"ltp":2.54,"tv":218.84,"id":8858707}]}]}
{"op":"mcm","clk":"11939184598","pt":1724833973304,"mc":[{"id":"1.232283868","rc":[{"batb":[[0,1.05,201.04],[1,1.04,250],[2,1.03,533.33]],"ltp":2.54,"tv":218.84,"id":8858707}]}]}
{"op":"mcm","clk":"11939184704","pt":1724833976487,"mc":[{"id":"1.232283868","rc":[{"batb":[[0,1.06,5],[1,1.05,201.04],[2,1.04,250]],"ltp":2.54,"tv":218.84,"id":8858707}]}]}
{"op":"mcm","clk":"11939184829","pt":1724833979971,"mc":[{"id":"1.232283868","rc":[{"batb":[[0,1.05,201.04],[1,1.04,250],[2,1.03,533.33]],"ltp":2.54,"tv":218.84,"id":8858707}]}]}
{"op":"mcm","clk":"11939185118","pt":1724833985908,"mc":[{"id":"1.232283868","rc":[{"batb":[[0,1.06,5],[1,1.05,201.04],[2,1.04,250]],"ltp":2.54,"tv":218.84,"id":8858707}]}]}
{"op":"mcm","clk":"11939185339","pt":1724833990891,"mc":[{"id":"1.232283868","rc":[{"batb":[[0,1.05,201.04],[1,1.04,250],[2,1.03,533.33]],"ltp":2.54,"tv":218.84,"id":8858707}]}]}
{"op":"mcm","clk":"11939185432","pt":1724833993809,"mc":[{"id":"1.232283868","rc":[{"batb":[[0,1.06,5],[1,1.05,201.04],[2,1.04,250]],"ltp":2.54,"tv":218.84,"id":8858707}]}]}
{"op":"mcm","clk":"11939185571","pt":1724833997092,"mc":[{"id":"1.232283868","rc":[{"batb":[[0,1.05,201.04],[1,1.04,250],[2,1.03,533.33]],"ltp":2.54,"tv":218.84,"id":8858707}]}]}
{"op":"mcm","clk":"11939185735","pt":1724834000235,"mc":[{"id":"1.232283868","rc":[{"batb":[[0,1.06,5],[1,1.05,201.04],[2,1.04,250]],"ltp":2.54,"tv":218.84,"id":8858707}]}]}
{"op":"mcm","clk":"11939185922","pt":1724834003622,"mc":[{"id":"1.232283868","rc":[{"batb":[[0,1.05,201.04],[1,1.04,250],[2,1.03,533.33]],"ltp":2.54,"tv":218.84,"id":8858707}]}]}
{"op":"mcm","clk":"11939186075","pt":1724834007008,"mc":[{"id":"1.232283868","rc":[{"batb":[[0,1.06,5],[1,1.05,201.04],[2,1.04,250]],"ltp":2.54,"tv":218.84,"id":8858707}]}]}
{"op":"mcm","clk":"11939186204","pt":1724834010330,"mc":[{"id":"1.232283868","rc":[{"batb":[[0,1.05,201.04],[1,1.04,250],[2,1.03,533.33]],"ltp":2.54,"tv":218.84,"id":8858707}]}]}
{"op":"mcm","clk":"11939186331","pt":1724834014215,"mc":[{"id":"1.232283868","rc":[{"batb":[[0,1.06,5],[1,1.05,201.04],[2,1.04,250]],"ltp":2.54,"tv":218.84,"id":8858707}]}]}
{"op":"mcm","clk":"11939186433","pt":1724834017645,"mc":[{"id":"1.232283868","rc":[{"batb":[[0,1.05,201.04],[1,1.04,250],[2,1.03,533.33]],"ltp":2.54,"tv":218.84,"id":8858707}]}]}
{"op":"mcm","clk":"11939186571","pt":1724834021332,"mc":[{"id":"1.232283868","rc":[{"batb":[[0,1.06,5],[1,1.05,201.04],[2,1.04,250]],"ltp":2.54,"tv":218.84,"id":8858707}]}]}
{"op":"mcm","clk":"11939186730","pt":1724834024819,"mc":[{"id":"1.232283868","rc":[{"batb":[[0,1.05,201.04],[1,1.04,250],[2,1.03,533.33]],"ltp":2.54,"tv":218.84,"id":8858707}]}]}
{"op":"mcm","clk":"11939186854","pt":1724834028041,"mc":[{"id":"1.232283868","rc":[{"batb":[[0,1.06,5],[1,1.05,201.04],[2,1.04,250]],"ltp":2.54,"tv":218.84,"id":8858707}]}]}
{"op":"mcm","clk":"11939186977","pt":1724834031338,"mc":[{"id":"1.232283868","rc":[{"batb":[[0,1.05,201.04],[1,1.04,250],[2,1.03,533.33]],"ltp":2.54,"tv":218.84,"id":8858707}]}]}
{"op":"mcm","clk":"11939187069","pt":1724834033950,"mc":[{"id":"1.232283868","rc":[{"batb":[[0,1.06,5],[1,1.05,201.04],[2,1.04,250]],"ltp":2.54,"tv":218.84,"id":8858707}]}]}
{"op":"mcm","clk":"11939187210","pt":1724834037338,"mc":[{"id":"1.232283868","rc":[{"batb":[[0,1.05,201.04],[1,1.04,250],[2,1.03,533.33]],"ltp":2.54,"tv":218.84,"id":8858707}]}]}
{"op":"mcm","clk":"11939187273","pt":1724834039540,"mc":[{"id":"1.232283868","rc":[{"batb":[[0,1.06,5],[1,1.05,201.04],[2,1.04,250]],"ltp":2.54,"tv":218.84,"id":8858707}]}]}
{"op":"mcm","clk":"11939187412","pt":1724834042776,"mc":[{"id":"1.232283868","rc":[{"batb":[[0,1.05,201.04],[1,1.04,250],[2,1.03,533.33]],"ltp":2.54,"tv":218.84,"id":8858707}]}]}
{"op":"mcm","clk":"11939187558","pt":1724834045956,"mc":[{"id":"1.232283868","rc":[{"batb":[[0,1.06,5],[1,1.05,201.04],[2,1.04,250]],"ltp":2.54,"tv":218.84,"id":8858707}]}]}
{"op":"mcm","clk":"11939187705","pt":1724834049345,"mc":[{"id":"1.232283868","rc":[{"batb":[[0,1.05,201.04],[1,1.04,250],[2,1.03,533.33]],"ltp":2.54,"tv":218.84,"id":8858707}]}]}
{"op":"mcm","clk":"11939187821","pt":1724834051874,"mc":[{"id":"1.232283868","rc":[{"batb":[[0,1.06,5],[1,1.05,201.04],[2,1.04,250]],"ltp":2.54,"tv":218.84,"id":8858707}]}]}
{"op":"mcm","clk":"11939187998","pt":1724834055158,"mc":[{"id":"1.232283868","rc":[{"batb":[[0,1.05,201.04],[1,1.04,250],[2,1.03,533.33]],"ltp":2.54,"tv":218.84,"id":8858707}]}]}
{"op":"mcm","clk":"11939188179","pt":1724834059153,"mc":[{"id":"1.232283868","rc":[{"batb":[[0,1.06,5],[1,1.05,201.04],[2,1.04,250]],"ltp":2.54,"tv":218.84,"id":8858707}]}]}
{"op":"mcm","clk":"11939188326","pt":1724834062588,"mc":[{"id":"1.232283868","rc":[{"batb":[[0,1.05,201.04],[1,1.04,250],[2,1.03,533.33]],"ltp":2.54,"tv":218.84,"id":8858707}]}]}
{"op":"mcm","clk":"11939188575","pt":1724834068781,"mc":[{"id":"1.232283868","rc":[{"batb":[[0,1.06,5],[1,1.05,201.04],[2,1.04,250]],"ltp":2.54,"tv":218.84,"id":8858707}]}]}
{"op":"mcm","clk":"11939188718","pt":1724834072112,"mc":[{"id":"1.232283868","rc":[{"batb":[[0,1.05,201.04],[1,1.04,250],[2,1.03,533.33]],"ltp":2.54,"tv":218.84,"id":8858707}]}]}
{"op":"mcm","clk":"11939188883","pt":1724834075500,"mc":[{"id":"1.232283868","rc":[{"batb":[[0,1.06,5],[1,1.05,201.04],[2,1.04,250]],"ltp":2.54,"tv":218.84,"id":8858707}]}]}
{"op":"mcm","clk":"11939188996","pt":1724834078977,"mc":[{"id":"1.232283868","rc":[{"batb":[[0,1.05,201.04],[1,1.04,250],[2,1.03,533.33]],"ltp":2.54,"tv":218.84,"id":8858707}]}]}
{"op":"mcm","clk":"11939189125","pt":1724834081997,"mc":[{"id":"1.232283868","rc":[{"batb":[[0,1.06,5],[1,1.05,201.04],[2,1.04,250]],"ltp":2.54,"tv":218.84,"id":8858707}]}]}
{"op":"mcm","clk":"11939189267","pt":1724834085393,"mc":[{"id":"1.232283868","rc":[{"batb":[[0,1.05,201.04],[1,1.04,250],[2,1.03,533.33]],"ltp":2.54,"tv":218.84,"id":8858707}]}]}
{"op":"mcm","clk":"11939189366","pt":1724834087493,"mc":[{"id":"1.232283868","rc":[{"batb":[[0,1.06,5],[1,1.05,201.04],[2,1.04,250]],"ltp":2.54,"tv":218.84,"id":8858707}]}]}
{"op":"mcm","clk":"11939189547","pt":1724834091033,"mc":[{"id":"1.232283868","rc":[{"batb":[[0,1.05,201.04],[1,1.04,250],[2,1.03,533.33]],"ltp":2.54,"tv":218.84,"id":8858707}]}]}
{"op":"mcm","clk":"11939189715","pt":1724834094209,"mc":[{"id":"1.232283868","rc":[{"batb":[[0,1.06,5],[1,1.05,201.04],[2,1.04,250]],"ltp":2.54,"tv":218.84,"id":8858707}]}]}
{"op":"mcm","clk":"11939189890","pt":1724834097540,"mc":[{"id":"1.232283868","rc":[{"batb":[[0,1.05,201.04],[1,1.04,250],[2,1.03,533.33]],"ltp":2.54,"tv":218.84,"id":8858707}]}]}
{"op":"mcm","clk":"11939190062","pt":1724834100542,"mc":[{"id":"1.232283868","rc":[{"batb":[[0,1.06,5],[1,1.05,201.04],[2,1.04,250]],"ltp":2.54,"tv":218.84,"id":8858707}]}]}
{"op":"mcm","clk":"11939190384","pt":1724834105747,"mc":[{"id":"1.232283868","rc":[{"batb":[[0,1.05,201.04],[1,1.04,250],[2,1.03,533.33]],"ltp":2.54,"tv":218.84,"id":8858707}]}]}
{"op":"mcm","clk":"11939190495","pt":1724834108732,"mc":[{"id":"1.232283868","rc":[{"batb":[[0,1.06,5],[1,1.05,201.04],[2,1.04,250]],"ltp":2.54,"tv":218.84,"id":8858707}]}]}
{"op":"mcm","clk":"11939190630","pt":1724834112125,"mc":[{"id":"1.232283868","rc":[{"batb":[[0,1.05,201.04],[1,1.04,250],[2,1.03,533.33]],"ltp":2.54,"tv":218.84,"id":8858707}]}]}
{"op":"mcm","clk":"11939190742","pt":1724834114329,"mc":[{"id":"1.232283868","rc":[{"batb":[[0,1.06,5],[1,1.05,201.04],[2,1.04,250]],"ltp":2.54,"tv":218.84,"id":8858707}]}]}
{"op":"mcm","clk":"11939190869","pt":1724834117555,"mc":[{"id":"1.232283868","rc":[{"batb":[[0,1.05,201.04],[1,1.04,250],[2,1.03,533.33]],"ltp":2.54,"tv":218.84,"id":8858707}]}]}
{"op":"mcm","clk":"11939190955","pt":1724834120367,"mc":[{"id":"1.232283868","rc":[{"batb":[[0,1.06,5],[1,1.05,201.04],[2,1.04,250]],"ltp":2.54,"tv":218.84,"id":8858707}]}]}
{"op":"mcm","clk":"11939191106","pt":1724834123744,"mc":[{"id":"1.232283868","rc":[{"batb":[[0,1.05,201.04],[1,1.04,250],[2,1.03,533.33]],"ltp":2.54,"tv":218.84,"id":8858707}]}]}
{"op":"mcm","clk":"11939191384","pt":1724834129757,"mc":[{"id":"1.232283868","rc":[{"batb":[[0,1.06,5],[1,1.05,201.04],[2,1.04,250]],"ltp":2.54,"tv":218.84,"id":8858707}]}]}
{"op":"mcm","clk":"11939191552","pt":1724834133559,"mc":[{"id":"1.232283868","rc":[{"batb":[[0,1.05,201.04],[1,1.04,250],[2,1.03,533.33]],"ltp":2.54,"tv":218.84,"id":8858707}]}]}
{"op":"mcm","clk":"11939191706","pt":1724834136781,"mc":[{"id":"1.232283868","rc":[{"batb":[[0,1.06,5],[1,1.05,201.04],[2,1.04,250]],"ltp":2.54,"tv":218.84,"id":8858707}]}]}
{"op":"mcm","clk":"11939191834","pt":1724834140170,"mc":[{"id":"1.232283868","rc":[{"batb":[[0,1.05,201.04],[1,1.04,250],[2,1.03,533.33]],"ltp":2.54,"tv":218.84,"id":8858707}]}]}
{"op":"mcm","clk":"11939192000","pt":1724834143964,"mc":[{"id":"1.232283868","rc":[{"batb":[[0,1.06,5],[1,1.05,201.04],[2,1.04,250]],"ltp":2.54,"tv":218.84,"id":8858707}]}]}
{"op":"mcm","clk":"11939192152","pt":1724834147197,"mc":[{"id":"1.232283868","rc":[{"batb":[[0,1.05,201.04],[1,1.04,250],[2,1.03,533.33]],"ltp":2.54,"tv":218.84,"id":8858707}]}]}
{"op":"mcm","clk":"11939192286","pt":1724834150785,"mc":[{"id":"1.232283868","rc":[{"batb":[[0,1.06,5],[1,1.05,201.04],[2,1.04,250]],"ltp":2.54,"tv":218.84,"id":8858707}]}]}
{"op":"mcm","clk":"11939192383","pt":1724834154172,"mc":[{"id":"1.232283868","rc":[{"batb":[[0,1.05,201.04],[1,1.04,250],[2,1.03,533.33]],"ltp":2.54,"tv":218.84,"id":8858707}]}]}
{"op":"mcm","clk":"11939192501","pt":1724834156994,"mc":[{"id":"1.232283868","rc":[{"batb":[[0,1.06,5],[1,1.05,201.04],[2,1.04,250]],"ltp":2.54,"tv":218.84,"id":8858707}]}]}
{"op":"mcm","clk":"11939192670","pt":1724834160181,"mc":[{"id":"1.232283868","rc":[{"batb":[[0,1.05,201.04],[1,1.04,250],[2,1.03,533.33]],"ltp":2.54,"tv":218.84,"id":8858707}]}]}
{"op":"mcm","clk":"11939192858","pt":1724834164403,"mc":[{"id":"1.232283868","rc":[{"batb":[[0,1.06,5],[1,1.05,201.04],[2,1.04,250]],"ltp":2.54,"tv":218.84,"id":8858707}]}]}
{"op":"mcm","clk":"11939193051","pt":1724834168004,"mc":[{"id":"1.232283868","rc":[{"batb":[[0,1.05,201.04],[1,1.04,250],[2,1.03,533.33]],"ltp":2.54,"tv":218.84,"id":8858707}]}]}
{"op":"mcm","clk":"11939193138","pt":1724834170417,"mc":[{"id":"1.232283868","rc":[{"batb":[[0,1.06,5],[1,1.05,201.04],[2,1.04,250]],"ltp":2.54,"tv":218.84,"id":8858707}]}]}
{"op":"mcm","clk":"11939193266","pt":1724834173802,"mc":[{"id":"1.232283868","rc":[{"batb":[[0,1.05,201.04],[1,1.04,250],[2,1.03,533.33]],"ltp":2.54,"tv":218.84,"id":8858707}]}]}
{"op":"mcm","clk":"11939193372","pt":1724834176521,"mc":[{"id":"1.232283868","rc":[{"batb":[[0,1.06,5],[1,1.05,201.04],[2,1.04,250]],"ltp":2.54,"tv":218.84,"id":8858707}]}]}
{"op":"mcm","clk":"11939193502","pt":1724834180319,"mc":[{"id":"1.232283868","rc":[{"batb":[[0,1.05,201.04],[1,1.04,250],[2,1.03,533.33]],"ltp":2.54,"tv":218.84,"id":8858707}]}]}
{"op":"mcm","clk":"11939193696","pt":1724834184244,"mc":[{"id":"1.232283868","rc":[{"batb":[[0,1.06,5],[1,1.05,201.04],[2,1.04,250]],"ltp":2.54,"tv":218.84,"id":8858707}]}]}
{"op":"mcm","clk":"11939193855","pt":1724834187652,"mc":[{"id":"1.232283868","rc":[{"batb":[[0,1.05,201.04],[1,1.04,250],[2,1.03,533.33]],"ltp":2.54,"tv":218.84,"id":8858707}]}]}
{"op":"mcm","clk":"11939193964","pt":1724834190336,"mc":[{"id":"1.232283868","rc":[{"batb":[[0,1.06,5],[1,1.05,201.04],[2,1.04,250]],"ltp":2.54,"tv":218.84,"id":8858707}]}]}
{"op":"mcm","clk":"11939194148","pt":1724834193744,"mc":[{"id":"1.232283868","rc":[{"batb":[[0,1.05,201.04],[1,1.04,250],[2,1.03,533.33]],"ltp":2.54,"tv":218.84,"id":8858707}]}]}
{"op":"mcm","clk":"11939194276","pt":1724834196160,"mc":[{"id":"1.232283868","rc":[{"batb":[[0,1.06,5],[1,1.05,201.04],[2,1.04,250]],"ltp":2.54,"tv":218.84,"id":8858707}]}]}
{"op":"mcm","clk":"11939194430","pt":1724834199428,"mc":[{"id":"1.232283868","rc":[{"batb":[[0,1.05,201.04],[1,1.04,250],[2,1.03,533.33]],"ltp":2.54,"tv":218.84,"id":8858707}]}]}
{"op":"mcm","clk":"11939194574","pt":1724834202565,"mc":[{"id":"1.232283868","rc":[{"batb":[[0,1.06,5],[1,1.05,201.04],[2,1.04,250]],"ltp":2.54,"tv":218.84,"id":8858707}]}]}
{"op":"mcm","clk":"11939194767","pt":1724834205962,"mc":[{"id":"1.232283868","rc":[{"batb":[[0,1.05,201.04],[1,1.04,250],[2,1.03,533.33]],"ltp":2.54,"tv":218.84,"id":8858707}]}]}
{"op":"mcm","clk":"11939194906","pt":1724834208674,"mc":[{"id":"1.232283868","rc":[{"batb":[[0,1.06,5],[1,1.05,201.04],[2,1.04,250]],"ltp":2.54,"tv":218.84,"id":8858707}]}]}
{"op":"mcm","clk":"11939195042","pt":1724834211868,"mc":[{"id":"1.232283868","rc":[{"batb":[[0,1.05,201.04],[1,1.04,250],[2,1.03,533.33]],"ltp":2.54,"tv":218.84,"id":8858707}]}]}
{"op":"mcm","clk":"11939195234","pt":1724834214980,"mc":[{"id":"1.232283868","rc":[{"batb":[[0,1.06,5],[1,1.05,201.04],[2,1.04,250]],"ltp":2.54,"tv":218.84,"id":8858707}]}]}
{"op":"mcm","clk":"11939195379","pt":1724834218451,"mc":[{"id":"1.232283868","rc":[{"batb":[[0,1.05,201.04],[1,1.04,250],[2,1.03,533.33]],"ltp":2.54,"tv":218.84,"id":8858707}]}]}
{"op":"mcm","clk":"11939195657","pt":1724834224475,"mc":[{"id":"1.232283868","rc":[{"batb":[[0,1.06,5],[1,1.05,201.04],[2,1.04,250]],"ltp":2.54,"tv":218.84,"id":8858707}]}]}
{"op":"mcm","clk":"11939195826","pt":1724834228282,"mc":[{"id":"1.232283868","rc":[{"batb":[[0,1.05,201.04],[1,1.04,250],[2,1.03,533.33]],"ltp":2.54,"tv":218.84,"id":8858707}]}]}
{"op":"mcm","clk":"11939196010","pt":1724834232296,"mc":[{"id":"1.232283868","rc":[{"batb":[[0,1.06,5],[1,1.05,201.04],[2,1.04,250]],"ltp":2.54,"tv":218.84,"id":8858707}]}]}
{"op":"mcm","clk":"11939196144","pt":1724834235696,"mc":[{"id":"1.232283868","rc":[{"batb":[[0,1.05,201.04],[1,1.04,250],[2,1.03,533.33]],"ltp":2.54,"tv":218.84,"id":8858707}]}]}
{"op":"mcm","clk":"11939196380","pt":1724834240486,"mc":[{"id":"1.232283868","rc":[{"batb":[[0,1.06,5],[1,1.05,201.04],[2,1.04,250]],"ltp":2.54,"tv":218.84,"id":8858707}]}]}
{"op":"mcm","clk":"11939196600","pt":1724834245472,"mc":[{"id":"1.232283868","rc":[{"batb":[[0,1.05,201.04],[1,1.04,250],[2,1.03,533.33]],"ltp":2.54,"tv":218.84,"id":8858707}]}]}
{"op":"mcm","clk":"11939196727","pt":1724834248370,"mc":[{"id":"1.232283868","rc":[{"batb":[[0,1.06,5],[1,1.05,201.04],[2,1.04,250]],"ltp":2.54,"tv":218.84,"id":8858707}]}]}
{"op":"mcm","clk":"11939196873","pt":1724834251715,"mc":[{"id":"1.232283868","rc":[{"batb":[[0,1.05,201.04],[1,1.04,250],[2,1.03,533.33]],"ltp":2.54,"tv":218.84,"id":8858707}]}]}
{"op":"mcm","clk":"11939196995","pt":1724834254385,"mc":[{"id":"1.232283868","rc":[{"batb":[[0,1.06,5],[1,1.05,201.04],[2,1.04,250]],"ltp":2.54,"tv":218.84,"id":8858707}]}]}
{"op":"mcm","clk":"11939197147","pt":1724834258297,"mc":[{"id":"1.232283868","rc":[{"batb":[[0,1.05,201.04],[1,1.04,250],[2,1.03,533.33]],"ltp":2.54,"tv":218.84,"id":8858707}]}]}
{"op":"mcm","clk":"11939197275","pt":1724834261215,"mc":[{"id":"1.232283868","rc":[{"batb":[[0,1.06,5],[1,1.05,201.04],[2,1.04,250]],"ltp":2.54,"tv":218.84,"id":8858707}]}]}
{"op":"mcm","clk":"11939197437","pt":1724834264595,"mc":[{"id":"1.232283868","rc":[{"batb":[[0,1.05,201.04],[1,1.04,250],[2,1.03,533.33]],"ltp":2.54,"tv":218.84,"id":8858707}]}]}
{"op":"mcm","clk":"11939197689","pt":1724834270896,"mc":[{"id":"1.232283868","rc":[{"batb":[[0,1.06,5],[1,1.05,201.04],[2,1.04,250]],"ltp":2.54,"tv":218.84,"id":8858707}]}]}
{"op":"mcm","clk":"11939197833","pt":1724834274222,"mc":[{"id":"1.232283868","rc":[{"batb":[[0,1.05,201.04],[1,1.04,250],[2,1.03,533.33]],"ltp":2.54,"tv":218.84,"id":8858707}]}]}
{"op":"mcm","clk":"11939197904","pt":1724834276424,"mc":[{"id":"1.232283868","rc":[{"batb":[[0,1.06,5],[1,1.05,201.04],[2,1.04,250]],"ltp":2.54,"tv":218.84,"id":8858707}]}]}
{"op":"mcm","clk":"11939198009","pt":1724834279613,"mc":[{"id":"1.232283868","rc":[{"batb":[[0,1.05,201.04],[1,1.04,250],[2,1.03,533.33]],"ltp":2.54,"tv":218.84,"id":8858707}]}]}
{"op":"mcm","clk":"11939198221","pt":1724834283830,"mc":[{"id":"1.232283868","rc":[{"batb":[[0,1.06,5],[1,1.05,201.04],[2,1.04,250]],"ltp":2.54,"tv":218.84,"id":8858707}]}]}
{"op":"mcm","clk":"11939198380","pt":1724834287221,"mc":[{"id":"1.232283868","rc":[{"batb":[[0,1.05,201.04],[1,1.04,250],[2,1.03,533.33]],"ltp":2.54,"tv":218.84,"id":8858707}]}]}
{"op":"mcm","clk":"11939198513","pt":1724834289839,"mc":[{"id":"1.232283868","rc":[{"batb":[[0,1.06,5],[1,1.05,201.04],[2,1.04,250]],"ltp":2.54,"tv":218.84,"id":8858707}]}]}
{"op":"mcm","clk":"11939198683","pt":1724834293542,"mc":[{"id":"1.232283868","rc":[{"batb":[[0,1.05,201.04],[1,1.04,250],[2,1.03,533.33]],"ltp":2.54,"tv":218.84,"id":8858707}]}]}
{"op":"mcm","clk":"11939198776","pt":1724834296359,"mc":[{"id":"1.232283868","rc":[{"batb":[[0,1.06,5],[1,1.05,201.04],[2,1.04,250]],"ltp":2.54,"tv":218.84,"id":8858707}]}]}
{"op":"mcm","clk":"11939198927","pt":1724834299953,"mc":[{"id":"1.232283868","rc":[{"batb":[[0,1.05,201.04],[1,1.04,250],[2,1.03,533.33]],"ltp":2.54,"tv":218.84,"id":8858707}]}]}
{"op":"mcm","clk":"11939199066","pt":1724834303134,"mc":[{"id":"1.232283868","rc":[{"batb":[[0,1.06,5],[1,1.05,201.04],[2,1.04,250]],"ltp":2.54,"tv":218.84,"id":8858707}]}]}
{"op":"mcm","clk":"11939199182","pt":1724834306359,"mc":[{"id":"1.232283868","rc":[{"batb":[[0,1.05,201.04],[1,1.04,250],[2,1.03,533.33]],"ltp":2.54,"tv":218.84,"id":8858707}]}]}
{"op":"mcm","clk":"11939199490","pt":1724834314169,"mc":[{"id":"1.232283868","rc":[{"batb":[[0,1.06,5],[1,1.05,201.04],[2,1.04,250]],"ltp":2.54,"tv":218.84,"id":8858707}]}]}
{"op":"mcm","clk":"11939199653","pt":1724834317460,"mc":[{"id":"1.232283868","rc":[{"batb":[[0,1.05,201.04],[1,1.04,250],[2,1.03,533.33]],"ltp":2.54,"tv":218.84,"id":8858707}]}]}
{"op":"mcm","clk":"11939199799","pt":1724834320253,"mc":[{"id":"1.232283868","rc":[{"batb":[[0,1.06,5],[1,1.05,201.04],[2,1.04,250]],"ltp":2.54,"tv":218.84,"id":8858707}]}]}
{"op":"mcm","clk":"11939199991","pt":1724834323744,"mc":[{"id":"1.232283868","rc":[{"batb":[[0,1.05,201.04],[1,1.04,250],[2,1.03,533.33]],"ltp":2.54,"tv":218.84,"id":8858707}]}]}
{"op":"mcm","clk":"11939200094","pt":1724834326050,"mc":[{"id":"1.232283868","rc":[{"batb":[[0,1.06,5],[1,1.05,201.04],[2,1.04,250]],"ltp":2.54,"tv":218.84,"id":8858707}]}]}
{"op":"mcm","clk":"11939200241","pt":1724834329384,"mc":[{"id":"1.232283868","rc":[{"batb":[[0,1.05,201.04],[1,1.04,250],[2,1.03,533.33]],"ltp":2.54,"tv":218.84,"id":8858707}]}]}
{"op":"mcm","clk":"11939200386","pt":1724834332079,"mc":[{"id":"1.232283868","rc":[{"batb":[[0,1.06,5],[1,1.05,201.04],[2,1.04,250]],"ltp":2.54,"tv":218.84,"id":8858707}]}]}
{"op":"mcm","clk":"11939200546","pt":1724834335565,"mc":[{"id":"1.232283868","rc":[{"batb":[[0,1.05,201.04],[1,1.04,250],[2,1.03,533.33]],"ltp":2.54,"tv":218.84,"id":8858707}]}]}
{"op":"mcm","clk":"11939200684","pt":1724834338078,"mc":[{"id":"1.232283868","rc":[{"batb":[[0,1.06,5],[1,1.05,201.04],[2,1.04,250]],"ltp":2.54,"tv":218.84,"id":8858707}]}]}
{"op":"mcm","clk":"11939200835","pt":1724834341685,"mc":[{"id":"1.232283868","rc":[{"batb":[[0,1.05,201.04],[1,1.04,250],[2,1.03,533.33]],"ltp":2.54,"tv":218.84,"id":8858707}]}]}
{"op":"mcm","clk":"11939200959","pt":1724834343896,"mc":[{"id":"1.232283868","rc":[{"batb":[[0,1.06,5],[1,1.05,201.04],[2,1.04,250]],"ltp":2.54,"tv":218.84,"id":8858707}]}]}
{"op":"mcm","clk":"11939201128","pt":1724834347397,"mc":[{"id":"1.232283868","rc":[{"batb":[[0,1.05,201.04],[1,1.04,250],[2,1.03,533.33]],"ltp":2.54,"tv":218.84,"id":8858707}]}]}
{"op":"mcm","clk":"11939201244","pt":1724834349705,"mc":[{"id":"1.232283868","rc":[{"batb":[[0,1.06,5],[1,1.05,201.04],[2,1.04,250]],"ltp":2.54,"tv":218.84,"id":8858707}]}]}
{"op":"mcm","clk":"11939201390","pt":1724834353288,"mc":[{"id":"1.232283868","rc":[{"batb":[[0,1.05,201.04],[1,1.04,250],[2,1.03,533.33]],"ltp":2.54,"tv":218.84,"id":8858707}]}]}
{"op":"mcm","clk":"11939201513","pt":1724834355600,"mc":[{"id":"1.232283868","rc":[{"batb":[[0,1.06,5],[1,1.05,201.04],[2,1.04,250]],"ltp":2.54,"tv":218.84,"id":8858707}]}]}
{"op":"mcm","clk":"11939201688","pt":1724834359288,"mc":[{"id":"1.232283868","rc":[{"batb":[[0,1.05,201.04],[1,1.04,250],[2,1.03,533.33]],"ltp":2.54,"tv":218.84,"id":8858707}]}]}
{"op":"mcm","clk":"11939201778","pt":1724834361592,"mc":[{"id":"1.232283868","rc":[{"batb":[[0,1.06,5],[1,1.05,201.04],[2,1.04,250]],"ltp":2.54,"tv":218.84,"id":8858707}]}]}
{"op":"mcm","clk":"11939201933","pt":1724834365396,"mc":[{"id":"1.232283868","rc":[{"batb":[[0,1.05,201.04],[1,1.04,250],[2,1.03,533.33]],"ltp":2.54,"tv":218.84,"id":8858707}]}]}
{"op":"mcm","clk":"11939202065","pt":1724834368621,"mc":[{"id":"1.232283868","rc":[{"batb":[[0,1.06,5],[1,1.05,201.04],[2,1.04,250]],"ltp":2.54,"tv":218.84,"id":8858707}]}]}
{"op":"mcm","clk":"11939202215","pt":1724834371805,"mc":[{"id":"1.232283868","rc":[{"batb":[[0,1.05,201.04],[1,1.04,250],[2,1.03,533.33]],"ltp":2.54,"tv":218.84,"id":8858707}]}]}
{"op":"mcm","clk":"11939202494","pt":1724834377596,"mc":[{"id":"1.232283868","rc":[{"batb":[[0,1.06,5],[1,1.05,201.04],[2,1.04,250]],"ltp":2.54,"tv":218.84,"id":8858707}]}]}
{"op":"mcm","clk":"11939202691","pt":1724834381642,"mc":[{"id":"1.232283868","rc":[{"batb":[[0,1.05,201.04],[1,1.04,250],[2,1.03,533.33]],"ltp":2.54,"tv":218.84,"id":8858707}]}]}
{"op":"mcm","clk":"11939202867","pt":1724834385227,"mc":[{"id":"1.232283868","rc":[{"batb":[[0,1.06,5],[1,1.05,201.04],[2,1.04,250]],"ltp":2.54,"tv":218.84,"id":8858707}]}]}
{"op":"mcm","clk":"11939203049","pt":1724834388621,"mc":[{"id":"1.232283868","rc":[{"batb":[[0,1.05,201.04],[1,1.04,250],[2,1.03,533.33]],"ltp":2.54,"tv":218.84,"id":8858707}]}]}
{"op":"mcm","clk":"11939203181","pt":1724834391136,"mc":[{"id":"1.232283868","rc":[{"batb":[[0,1.06,5],[1,1.05,201.04],[2,1.04,250]],"ltp":2.54,"tv":218.84,"id":8858707}]}]}
{"op":"mcm","clk":"11939203343","pt":1724834394313,"mc":[{"id":"1.232283868","rc":[{"batb":[[0,1.05,201.04],[1,1.04,250],[2,1.03,533.33]],"ltp":2.54,"tv":218.84,"id":8858707}]}]}
{"op":"mcm","clk":"11939203465","pt":1724834397130,"mc":[{"id":"1.232283868","rc":[{"batb":[[0,1.06,5],[1,1.05,201.04],[2,1.04,250]],"ltp":2.54,"tv":218.84,"id":8858707}]}]}
{"op":"mcm","clk":"11939203646","pt":1724834400820,"mc":[{"id":"1.232283868","rc":[{"batb":[[0,1.05,201.04],[1,1.04,250],[2,1.03,533.33]],"ltp":2.54,"tv":218.84,"id":8858707}]}]}
{"op":"mcm","clk":"11939204065","pt":1724834408934,"mc":[{"id":"1.232283868","rc":[{"batb":[[0,1.06,5],[1,1.05,201.04],[2,1.04,250]],"ltp":2.54,"tv":218.84,"id":8858707}]}]}
{"op":"mcm","clk":"11939204209","pt":1724834412268,"mc":[{"id":"1.232283868","rc":[{"batb":[[0,1.05,201.04],[1,1.04,250],[2,1.03,533.33]],"ltp":2.54,"tv":218.84,"id":8858707}]}]}
{"op":"mcm","clk":"11939204350","pt":1724834414856,"mc":[{"id":"1.232283868","rc":[{"batb":[[0,1.06,5],[1,1.05,201.04],[2,1.04,250]],"ltp":2.54,"tv":218.84,"id":8858707}]}]}
{"op":"mcm","clk":"11939204524","pt":1724834418347,"mc":[{"id":"1.232283868","rc":[{"batb":[[0,1.05,201.04],[1,1.04,250],[2,1.03,533.33]],"ltp":2.54,"tv":218.84,"id":8858707}]}]}
{"op":"mcm","clk":"11939204781","pt":1724834423987,"mc":[{"id":"1.232283868","rc":[{"batb":[[0,1.06,5],[1,1.05,201.04],[2,1.04,250]],"ltp":2.54,"tv":218.84,"id":8858707}]}]}
{"op":"mcm","clk":"11939205133","pt":1724834430574,"mc":[{"id":"1.232283868","rc":[{"batb":[[0,1.05,201.04],[1,1.04,250],[2,1.03,533.33]],"ltp":2.54,"tv":218.84,"id":8858707}]}]}
{"op":"mcm","clk":"11939205320","pt":1724834433752,"mc":[{"id":"1.232283868","rc":[{"batb":[[0,1.06,5],[1,1.05,201.04],[2,1.04,250]],"ltp":2.54,"tv":218.84,"id":8858707}]}]}
{"op":"mcm","clk":"11939205494","pt":1724834438059,"mc":[{"id":"1.232283868","rc":[{"batb":[[0,1.05,201.04],[1,1.04,250],[2,1.03,533.33]],"ltp":2.54,"tv":218.84,"id":8858707}]}]}
{"op":"mcm","clk":"11939205577","pt":1724834440315,"mc":[{"id":"1.232283868","rc":[{"batb":[[0,1.06,5],[1,1.05,201.04],[2,1.04,250]],"ltp":2.54,"tv":218.84,"id":8858707}]}]}
{"op":"mcm","clk":"11939205801","pt":1724834443804,"mc":[{"id":"1.232283868","rc":[{"batb":[[0,1.05,201.04],[1,1.04,250],[2,1.03,533.33]],"ltp":2.54,"tv":218.84,"id":8858707}]}]}
{"op":"mcm","clk":"11939205941","pt":1724834446475,"mc":[{"id":"1.232283868","rc":[{"batb":[[0,1.06,5],[1,1.05,201.04],[2,1.04,250]],"ltp":2.54,"tv":218.84,"id":8858707}]}]}
{"op":"mcm","clk":"11939206117","pt":1724834450072,"mc":[{"id":"1.232283868","rc":[{"batb":[[0,1.05,201.04],[1,1.04,250],[2,1.03,533.33]],"ltp":2.54,"tv":218.84,"id":8858707}]}]}
{"op":"mcm","clk":"11939206287","pt":1724834453222,"mc":[{"id":"1.232283868","rc":[{"batb":[[0,1.06,5],[1,1.05,201.04],[2,1.04,250]],"ltp":2.54,"tv":218.84,"id":8858707}]}]}
{"op":"mcm","clk":"11939206493","pt":1724834456811,"mc":[{"id":"1.232283868","rc":[{"batb":[[0,1.05,201.04],[1,1.04,250],[2,1.03,533.33]],"ltp":2.54,"tv":218.84,"id":8858707}]}]}
{"op":"mcm","clk":"11939206590","pt":1724834459215,"mc":[{"id":"1.232283868","rc":[{"batb":[[0,1.06,5],[1,1.05,201.04],[2,1.04,250]],"ltp":2.54,"tv":218.84,"id":8858707}]}]}
{"op":"mcm","clk":"11939206727","pt":1724834462611,"mc":[{"id":"1.232283868","rc":[{"batb":[[0,1.05,201.04],[1,1.04,250],[2,1.03,533.33]],"ltp":2.54,"tv":218.84,"id":8858707}]}]}
{"op":"mcm","clk":"11939206879","pt":1724834465835,"mc":[{"id":"1.232283868","rc":[{"batb":[[0,1.06,5],[1,1.05,201.04],[2,1.04,250]],"ltp":2.54,"tv":218.84,"id":8858707}]}]}
{"op":"mcm","clk":"11939207042","pt":1724834469222,"mc":[{"id":"1.232283868","rc":[{"batb":[[0,1.05,201.04],[1,1.04,250],[2,1.03,533.33]],"ltp":2.54,"tv":218.84,"id":8858707}]}]}
{"op":"mcm","clk":"11939207236","pt":1724834473324,"mc":[{"id":"1.232283868","rc":[{"batb":[[0,1.06,5],[1,1.05,201.04],[2,1.04,250]],"ltp":2.54,"tv":218.84,"id":8858707}]}]}
{"op":"mcm","clk":"11939207432","pt":1724834477431,"mc":[{"id":"1.232283868","rc":[{"batb":[[0,1.05,201.04],[1,1.04,250],[2,1.03,533.33]],"ltp":2.54,"tv":218.84,"id":8858707}]}]}
{"op":"mcm","clk":"11939207572","pt":1724834480311,"mc":[{"id":"1.232283868","rc":[{"batb":[[0,1.06,5],[1,1.05,201.04],[2,1.04,250]],"ltp":2.54,"tv":218.84,"id":8858707}]}]}
{"op":"mcm","clk":"11939207727","pt":1724834483842,"mc":[{"id":"1.232283868","rc":[{"batb":[[0,1.05,201.04],[1,1.04,250],[2,1.03,533.33]],"ltp":2.54,"tv":218.84,"id":8858707}]}]}
{"op":"mcm","clk":"11939207852","pt":1724834486046,"mc":[{"id":"1.232283868","rc":[{"batb":[[0,1.06,5],[1,1.05,201.04],[2,1.04,250]],"ltp":2.54,"tv":218.84,"id":8858707}]}]}
{"op":"mcm","clk":"11939208008","pt":1724834489433,"mc":[{"id":"1.232283868","rc":[{"batb":[[0,1.05,201.04],[1,1.04,250],[2,1.03,533.33]],"ltp":2.54,"tv":218.84,"id":8858707}]}]}
{"op":"mcm","clk":"11939208169","pt":1724834492465,"mc":[{"id":"1.232283868","rc":[{"batb":[[0,1.06,5],[1,1.05,201.04],[2,1.04,250]],"ltp":2.54,"tv":218.84,"id":8858707}]}]}
{"op":"mcm","clk":"11939208333","pt":1724834495962,"mc":[{"id":"1.232283868","rc":[{"batb":[[0,1.05,201.04],[1,1.04,250],[2,1.03,533.33]],"ltp":2.54,"tv":218.84,"id":8858707}]}]}
{"op":"mcm","clk":"11939208459","pt":1724834498626,"mc":[{"id":"1.232283868","rc":[{"batb":[[0,1.06,5],[1,1.05,201.04],[2,1.04,250]],"ltp":2.54,"tv":218.84,"id":8858707}]}]}
{"op":"mcm","clk":"11939208664","pt":1724834502148,"mc":[{"id":"1.232283868","rc":[{"batb":[[0,1.05,201.04],[1,1.04,250],[2,1.03,533.33]],"ltp":2.54,"tv":218.84,"id":8858707}]}]}
{"op":"mcm","clk":"11939208993","pt":1724834508728,"mc":[{"id":"1.232283868","rc":[{"batb":[[0,1.06,5],[1,1.05,201.04],[2,1.04,250]],"ltp":2.54,"tv":218.84,"id":8858707}]}]}
{"op":"mcm","clk":"11939209168","pt":1724834512158,"mc":[{"id":"1.232283868","rc":[{"batb":[[0,1.05,201.04],[1,1.04,250],[2,1.03,533.33]],"ltp":2.54,"tv":218.84,"id":8858707}]}]}
{"op":"mcm","clk":"11939209394","pt":1724834516155,"mc":[{"id":"1.232283868","rc":[{"batb":[[0,1.06,5],[1,1.05,201.04],[2,1.04,250]],"ltp":2.54,"tv":218.84,"id":8858707}]}]}
{"op":"mcm","clk":"11939209613","pt":1724834519950,"mc":[{"id":"1.232283868","rc":[{"batb":[[0,1.05,201.04],[1,1.04,250],[2,1.03,533.33]],"ltp":2.54,"tv":218.84,"id":8858707}]}]}
{"op":"mcm","clk":"11939209708","pt":1724834522270,"mc":[{"id":"1.232283868","rc":[{"batb":[[0,1.06,5],[1,1.05,201.04],[2,1.04,250]],"ltp":2.54,"tv":218.84,"id":8858707}]}]}
{"op":"mcm","clk":"11939209925","pt":1724834525573,"mc":[{"id":"1.232283868","rc":[{"batb":[[0,1.05,201.04],[1,1.04,250],[2,1.03,533.33]],"ltp":2.54,"tv":218.84,"id":8858707}]}]}
{"op":"mcm","clk":"11939210195","pt":1724834531060,"mc":[{"id":"1.232283868","rc":[{"batb":[[0,1.06,5],[1,1.05,201.04],[2,1.04,250]],"ltp":2.54,"tv":218.84,"id":8858707}]}]}
{"op":"mcm","clk":"11939210360","pt":1724834534353,"mc":[{"id":"1.232283868","rc":[{"batb":[[0,1.05,201.04],[1,1.04,250],[2,1.03,533.33]],"ltp":2.54,"tv":218.84,"id":8858707}]}]}
{"op":"mcm","clk":"11939210508","pt":1724834537579,"mc":[{"id":"1.232283868","rc":[{"batb":[[0,1.06,5],[1,1.05,201.04],[2,1.04,250]],"ltp":2.54,"tv":218.84,"id":8858707}]}]}
{"op":"mcm","clk":"11939210654","pt":1724834540963,"mc":[{"id":"1.232283868","rc":[{"batb":[[0,1.05,201.04],[1,1.04,250],[2,1.03,533.33]],"ltp":2.54,"tv":218.84,"id":8858707}]}]}
{"op":"mcm","clk":"11939210788","pt":1724834543373,"mc":[{"id":"1.232283868","rc":[{"batb":[[0,1.06,5],[1,1.05,201.04],[2,1.04,250]],"ltp":2.54,"tv":218.84,"id":8858707}]}]}
{"op":"mcm","clk":"11939210971","pt":1724834546658,"mc":[{"id":"1.232283868","rc":[{"batb":[[0,1.05,201.04],[1,1.04,250],[2,1.03,533.33]],"ltp":2.54,"tv":218.84,"id":8858707}]}]}
{"op":"mcm","clk":"11939211127","pt":1724834549479,"mc":[{"id":"1.232283868","rc":[{"batb":[[0,1.06,5],[1,1.05,201.04],[2,1.04,250]],"ltp":2.54,"tv":218.84,"id":8858707}]}]}
{"op":"mcm","clk":"11939211293","pt":1724834552818,"mc":[{"id":"1.232283868","rc":[{"batb":[[0,1.05,201.04],[1,1.04,250],[2,1.03,533.33]],"ltp":2.54,"tv":218.84,"id":8858707}]}]}
{"op":"mcm","clk":"11939211591","pt":1724834558890,"mc":[{"id":"1.232283868","rc":[{"batb":[[0,1.06,5],[1,1.05,201.04],[2,1.04,250]],"ltp":2.54,"tv":218.84,"id":8858707}]}]}
{"op":"mcm","clk":"11939211740","pt":1724834562316,"mc":[{"id":"1.232283868","rc":[{"batb":[[0,1.05,201.04],[1,1.04,250],[2,1.03,533.33]],"ltp":2.54,"tv":218.84,"id":8858707}]}]}
{"op":"mcm","clk":"11939211866","pt":1724834565094,"mc":[{"id":"1.232283868","rc":[{"batb":[[0,1.06,5],[1,1.05,201.04],[2,1.04,250]],"ltp":2.54,"tv":218.84,"id":8858707}]}]}
{"op":"mcm","clk":"11939212026","pt":1724834568502,"mc":[{"id":"1.232283868","rc":[{"batb":[[0,1.05,201.04],[1,1.04,250],[2,1.03,533.33]],"ltp":2.54,"tv":218.84,"id":8858707}]}]}
{"op":"mcm","clk":"11939212097","pt":1724834570602,"mc":[{"id":"1.232283868","rc":[{"batb":[[0,1.06,5],[1,1.05,201.04],[2,1.04,250]],"ltp":2.54,"tv":218.84,"id":8858707}]}]}
{"op":"mcm","clk":"11939212255","pt":1724834573933,"mc":[{"id":"1.232283868","rc":[{"batb":[[0,1.05,201.04],[1,1.04,250],[2,1.03,533.33]],"ltp":2.54,"tv":218.84,"id":8858707}]}]}
{"op":"mcm","clk":"11939222558","pt":1724834578526,"mc":[{"id":"1.232283868","rc":[{"batb":[[0,1.06,5],[1,1.05,201.04],[2,1.04,250]],"ltp":2.54,"tv":218.84,"id":8858707}]}]}
{"op":"mcm","clk":"11939222738","pt":1724834581725,"mc":[{"id":"1.232283868","rc":[{"batb":[[0,1.05,201.04],[1,1.04,250],[2,1.03,533.33]],"ltp":2.54,"tv":218.84,"id":8858707}]}]}
{"op":"mcm","clk":"11939222937","pt":1724834585336,"mc":[{"id":"1.232283868","rc":[{"batb":[[0,1.06,5],[1,1.05,201.04],[2,1.04,250]],"ltp":2.54,"tv":218.84,"id":8858707}]}]}
{"op":"mcm","clk":"11939223107","pt":1724834588948,"mc":[{"id":"1.232283868","rc":[{"batb":[[0,1.05,201.04],[1,1.04,250],[2,1.03,533.33]],"ltp":2.54,"tv":218.84,"id":8858707}]}]}
{"op":"mcm","clk":"11939223270","pt":1724834591831,"mc":[{"id":"1.232283868","rc":[{"batb":[[0,1.06,5],[1,1.05,201.04],[2,1.04,250]],"ltp":2.54,"tv":218.84,"id":8858707}]}]}
{"op":"mcm","clk":"11939223419","pt":1724834595138,"mc":[{"id":"1.232283868","rc":[{"batb":[[0,1.05,201.04],[1,1.04,250],[2,1.03,533.33]],"ltp":2.54,"tv":218.84,"id":8858707}]}]}
{"op":"mcm","clk":"11939223531","pt":1724834597656,"mc":[{"id":"1.232283868","rc":[{"batb":[[0,1.06,5],[1,1.05,201.04],[2,1.04,250]],"ltp":2.54,"tv":218.84,"id":8858707}]}]}
{"op":"mcm","clk":"11939223682","pt":1724834600850,"mc":[{"id":"1.232283868","rc":[{"batb":[[0,1.05,201.04],[1,1.04,250],[2,1.03,533.33]],"ltp":2.54,"tv":218.84,"id":8858707}]}]}
{"op":"mcm","clk":"11939223912","pt":1724834604969,"mc":[{"id":"1.232283868","rc":[{"batb":[[0,1.06,5],[1,1.05,201.04],[2,1.04,250]],"ltp":2.54,"tv":218.84,"id":8858707}]}]}
{"op":"mcm","clk":"11939224075","pt":1724834608253,"mc":[{"id":"1.232283868","rc":[{"batb":[[0,1.05,201.04],[1,1.04,250],[2,1.03,533.33]],"ltp":2.54,"tv":218.84,"id":8858707}]}]}
{"op":"mcm","clk":"11939224199","pt":1724834610985,"mc":[{"id":"1.232283868","rc":[{"batb":[[0,1.06,5],[1,1.05,201.04],[2,1.04,250]],"ltp":2.54,"tv":218.84,"id":8858707}]}]}
{"op":"mcm","clk":"11939224367","pt":1724834614188,"mc":[{"id":"1.232283868","rc":[{"batb":[[0,1.05,201.04],[1,1.04,250],[2,1.03,533.33]],"ltp":2.54,"tv":218.84,"id":8858707}]}]}
{"op":"mcm","clk":"11939224532","pt":1724834617283,"mc":[{"id":"1.232283868","rc":[{"batb":[[0,1.06,5],[1,1.05,201.04],[2,1.04,250]],"ltp":2.54,"tv":218.84,"id":8858707}]}]}
{"op":"mcm","clk":"11939224685","pt":1724834620585,"mc":[{"id":"1.232283868","rc":[{"batb":[[0,1.05,201.04],[1,1.04,250],[2,1.03,533.33]],"ltp":2.54,"tv":218.84,"id":8858707}]}]}
{"op":"mcm","clk":"11939224839","pt":1724834623370,"mc":[{"id":"1.232283868","rc":[{"batb":[[0,1.06,5],[1,1.05,201.04],[2,1.04,250]],"ltp":2.54,"tv":218.84,"id":8858707}]}]}
{"op":"mcm","clk":"11939225042","pt":1724834626662,"mc":[{"id":"1.232283868","rc":[{"batb":[[0,1.05,201.04],[1,1.04,250],[2,1.03,533.33]],"ltp":2.54,"tv":218.84,"id":8858707}]}]}
{"op":"mcm","clk":"11939225197","pt":1724834629967,"mc":[{"id":"1.232283868","rc":[{"batb":[[0,1.06,5],[1,1.05,201.04],[2,1.04,250]],"ltp":2.54,"tv":218.84,"id":8858707}]}]}
{"op":"mcm","clk":"11939225376","pt":1724834633366,"mc":[{"id":"1.232283868","rc":[{"batb":[[0,1.05,201.04],[1,1.04,250],[2,1.03,533.33]],"ltp":2.54,"tv":218.84,"id":8858707}]}]}
{"op":"mcm","clk":"11939225581","pt":1724834637083,"mc":[{"id":"1.232283868","rc":[{"batb":[[0,1.06,5],[1,1.05,201.04],[2,1.04,250]],"ltp":2.54,"tv":218.84,"id":8858707}]}]}
{"op":"mcm","clk":"11939225734","pt":1724834640332,"mc":[{"id":"1.232283868","rc":[{"batb":[[0,1.05,201.04],[1,1.04,250],[2,1.03,533.33]],"ltp":2.54,"tv":218.84,"id":8858707}]}]}
{"op":"mcm","clk":"11939225907","pt":1724834643317,"mc":[{"id":"1.232283868","rc":[{"batb":[[0,1.06,5],[1,1.05,201.04],[2,1.04,250]],"ltp":2.54,"tv":218.84,"id":8858707}]}]}
{"op":"mcm","clk":"11939226088","pt":1724834646502,"mc":[{"id":"1.232283868","rc":[{"batb":[[0,1.05,201.04],[1,1.04,250],[2,1.03,533.33]],"ltp":2.54,"tv":218.84,"id":8858707}]}]}
{"op":"mcm","clk":"11939226212","pt":1724834648711,"mc":[{"id":"1.232283868","rc":[{"batb":[[0,1.06,5],[1,1.05,201.04],[2,1.04,250]],"ltp":2.54,"tv":218.84,"id":8858707}]}]}
{"op":"mcm","clk":"11939226413","pt":1724834652214,"mc":[{"id":"1.232283868","rc":[{"batb":[[0,1.05,201.04],[1,1.04,250],[2,1.03,533.33]],"ltp":2.54,"tv":218.84,"id":8858707}]}]}
{"op":"mcm","clk":"11939226577","pt":1724834655300,"mc":[{"id":"1.232283868","rc":[{"batb":[[0,1.06,5],[1,1.05,201.04],[2,1.04,250]],"ltp":2.54,"tv":218.84,"id":8858707}]}]}
{"op":"mcm","clk":"11939226759","pt":1724834658690,"mc":[{"id":"1.232283868","rc":[{"batb":[[0,1.05,201.04],[1,1.04,250],[2,1.03,533.33]],"ltp":2.54,"tv":218.84,"id":8858707}]}]}
{"op":"mcm","clk":"11939226932","pt":1724834662203,"mc":[{"id":"1.232283868","rc":[{"batb":[[0,1.06,5],[1,1.05,201.04],[2,1.04,250]],"ltp":2.54,"tv":218.84,"id":8858707}]}]}
{"op":"mcm","clk":"11939227091","pt":1724834665505,"mc":[{"id":"1.232283868","rc":[{"batb":[[0,1.05,201.04],[1,1.04,250],[2,1.03,533.33]],"ltp":2.54,"tv":218.84,"id":8858707}]}]}
{"op":"mcm","clk":"11939227389","pt":1724834670936,"mc":[{"id":"1.232283868","rc":[{"batb":[[0,1.06,5],[1,1.05,201.04],[2,1.04,250]],"ltp":2.54,"tv":218.84,"id":8858707}]}]}
{"op":"mcm","clk":"11939227566","pt":1724834674234,"mc":[{"id":"1.232283868","rc":[{"batb":[[0,1.05,201.04],[1,1.04,250],[2,1.03,533.33]],"ltp":2.54,"tv":218.84,"id":8858707}]}]}
{"op":"mcm","clk":"11939227672","pt":1724834676456,"mc":[{"id":"1.232283868","rc":[{"batb":[[0,1.06,5],[1,1.05,201.04],[2,1.04,250]],"ltp":2.54,"tv":218.84,"id":8858707}]}]}
{"op":"mcm","clk":"11939227839","pt":1724834680141,"mc":[{"id":"1.232283868","rc":[{"batb":[[0,1.05,201.04],[1,1.04,250],[2,1.03,533.33]],"ltp":2.54,"tv":218.84,"id":8858707}]}]}
{"op":"mcm","clk":"11939265118","pt":1724835600706,"mc":[{"id":"1.232283868","rc":[{"batb":[[0,1.06,5],[1,1.05,201.04],[2,1.04,250]],"ltp":2.54,"tv":218.84,"id":8858707}]}]}
{"op":"mcm","clk":"11939265267","pt":1724835603917,"mc":[{"id":"1.232283868","rc":[{"batb":[[0,1.05,201.04],[1,1.04,250],[2,1.03,533.33]],"ltp":2.54,"tv":218.84,"id":8858707}]}]}
{"op":"mcm","clk":"11939265447","pt":1724835607117,"mc":[{"id":"1.232283868","rc":[{"trd":[[1.6,135.97],[1.61,70.7],[2.54,12.29]],"batb":[[0,1.06,5],[1,1.05,201.04],[2,1.04,250]],"ltp":2.54,"tv":218.96,"id":8858707},{"trd":[[1.22,271.94]],"ltp":1.64,"tv":275.93,"id":2857968}],"tv":494.89}]}
{"op":"mcm","clk":"11939265599","pt":1724835610561,"mc":[{"id":"1.232283868","rc":[{"batb":[[0,1.05,201.04],[1,1.04,250],[2,1.03,533.33]],"ltp":2.54,"tv":218.96,"id":8858707}]}]}
{"op":"mcm","clk":"11939265856","pt":1724835615352,"mc":[{"id":"1.232283868","rc":[{"batb":[[0,1.06,5],[1,1.05,201.04],[2,1.04,250]],"ltp":2.54,"tv":218.96,"id":8858707}]}]}
{"op":"mcm","clk":"11939266056","pt":1724835619055,"mc":[{"id":"1.232283868","rc":[{"batb":[[0,1.05,201.04],[1,1.04,250],[2,1.03,533.33]],"ltp":2.54,"tv":218.96,"id":8858707}]}]}
{"op":"mcm","clk":"11939266193","pt":1724835622085,"mc":[{"id":"1.232283868","rc":[{"batb":[[0,1.06,5],[1,1.05,201.04],[2,1.04,250]],"ltp":2.54,"tv":218.96,"id":8858707}]}]}
{"op":"mcm","clk":"11939266372","pt":1724835625483,"mc":[{"id":"1.232283868","rc":[{"batb":[[0,1.05,201.04],[1,1.04,250],[2,1.03,533.33]],"ltp":2.54,"tv":218.96,"id":8858707}]}]}
{"op":"mcm","clk":"11939266566","pt":1724835629551,"mc":[{"id":"1.232283868","rc":[{"batb":[[0,1.06,5],[1,1.05,201.04],[2,1.04,250]],"ltp":2.54,"tv":218.96,"id":8858707}]}]}
{"op":"mcm","clk":"11939266734","pt":1724835633159,"mc":[{"id":"1.232283868","rc":[{"batb":[[0,1.05,201.04],[1,1.04,250],[2,1.03,533.33]],"ltp":2.54,"tv":218.96,"id":8858707}]}]}
{"op":"mcm","clk":"11939266857","pt":1724835636194,"mc":[{"id":"1.232283868","rc":[{"batb":[[0,1.06,5],[1,1.05,201.04],[2,1.04,250]],"ltp":2.54,"tv":218.96,"id":8858707}]}]}
{"op":"mcm","clk":"11939267017","pt":1724835639689,"mc":[{"id":"1.232283868","rc":[{"batb":[[0,1.05,201.04],[1,1.04,250],[2,1.03,533.33]],"ltp":2.54,"tv":218.96,"id":8858707}]}]}
{"op":"mcm","clk":"11939267140","pt":1724835642470,"mc":[{"id":"1.232283868","rc":[{"batb":[[0,1.06,5],[1,1.05,201.04],[2,1.04,250]],"ltp":2.54,"tv":218.96,"id":8858707}]}]}
{"op":"mcm","clk":"11939267291","pt":1724835645964,"mc":[{"id":"1.232283868","rc":[{"batb":[[0,1.05,201.04],[1,1.04,250],[2,1.03,533.33]],"ltp":2.54,"tv":218.96,"id":8858707}]}]}
{"op":"mcm","clk":"11939267465","pt":1724835649977,"mc":[{"id":"1.232283868","rc":[{"batb":[[0,1.06,5],[1,1.05,201.04],[2,1.04,250]],"ltp":2.54,"tv":218.96,"id":8858707}]}]}
{"op":"mcm","clk":"11939267631","pt":1724835653470,"mc":[{"id":"1.232283868","rc":[{"batb":[[0,1.05,201.04],[1,1.04,250],[2,1.03,533.33]],"ltp":2.54,"tv":218.96,"id":8858707}]}]}
{"op":"mcm","clk":"11939267811","pt":1724835657023,"mc":[{"id":"1.232283868","rc":[{"batb":[[0,1.06,5],[1,1.05,201.04],[2,1.04,250]],"ltp":2.54,"tv":218.96,"id":8858707}]}]}
{"op":"mcm","clk":"11939267970","pt":1724835660320,"mc":[{"id":"1.232283868","rc":[{"batb":[[0,1.05,201.04],[1,1.04,250],[2,1.03,533.33]],"ltp":2.54,"tv":218.96,"id":8858707}]}]}
{"op":"mcm","clk":"11939268176","pt":1724835664200,"mc":[{"id":"1.232283868","rc":[{"batb":[[0,1.06,5],[1,1.05,201.04],[2,1.04,250]],"ltp":2.54,"tv":218.96,"id":8858707}]}]}
{"op":"mcm","clk":"11939268329","pt":1724835667793,"mc":[{"id":"1.232283868","rc":[{"batb":[[0,1.05,201.04],[1,1.04,250],[2,1.03,533.33]],"ltp":2.54,"tv":218.96,"id":8858707}]}]}
{"op":"mcm","clk":"11939268547","pt":1724835671107,"mc":[{"id":"1.232283868","rc":[{"batb":[[0,1.06,5],[1,1.05,201.04],[2,1.04,250]],"ltp":2.54,"tv":218.96,"id":8858707}]}]}
{"op":"mcm","clk":"11939268772","pt":1724835675742,"mc":[{"id":"1.232283868","rc":[{"batb":[[0,1.05,201.04],[1,1.04,250],[2,1.03,533.33]],"ltp":2.54,"tv":218.96,"id":8858707}]}]}
{"op":"mcm","clk":"11939269114","pt":1724835682455,"mc":[{"id":"1.232283868","rc":[{"batb":[[0,1.06,5],[1,1.05,201.04],[2,1.04,250]],"ltp":2.54,"tv":218.96,"id":8858707}]}]}
{"op":"mcm","clk":"11939269299","pt":1724835686058,"mc":[{"id":"1.232283868","rc":[{"batb":[[0,1.05,201.04],[1,1.04,250],[2,1.03,533.33]],"ltp":2.54,"tv":218.96,"id":8858707}]}]}
{"op":"mcm","clk":"11939269407","pt":1724835688527,"mc":[{"id":"1.232283868","rc":[{"batb":[[0,1.06,5],[1,1.05,201.04],[2,1.04,250]],"ltp":2.54,"tv":218.96,"id":8858707}]}]}
{"op":"mcm","clk":"11939269597","pt":1724835692258,"mc":[{"id":"1.232283868","rc":[{"batb":[[0,1.05,201.04],[1,1.04,250],[2,1.03,533.33]],"ltp":2.54,"tv":218.96,"id":8858707}]}]}
{"op":"mcm","clk":"11939269757","pt":1724835695960,"mc":[{"id":"1.232283868","rc":[{"batb":[[0,1.06,5],[1,1.05,201.04],[2,1.04,250]],"ltp":2.54,"tv":218.96,"id":8858707}]}]}
{"op":"mcm","clk":"11939269948","pt":1724835699550,"mc":[{"id":"1.232283868","rc":[{"batb":[[0,1.05,201.04],[1,1.04,250],[2,1.03,533.33]],"ltp":2.54,"tv":218.96,"id":8858707}]}]}
{"op":"mcm","clk":"11939270072","pt":1724835701753,"mc":[{"id":"1.232283868","rc":[{"batb":[[0,1.06,5],[1,1.05,201.04],[2,1.04,250]],"ltp":2.54,"tv":218.96,"id":8858707}]}]}
{"op":"mcm","clk":"11939270347","pt":1724835706273,"mc":[{"id":"1.232283868","rc":[{"batb":[[0,1.05,201.04],[1,1.04,250],[2,1.03,533.33]],"ltp":2.54,"tv":218.96,"id":8858707}]}]}
{"op":"mcm","clk":"11939270635","pt":1724835711159,"mc":[{"id":"1.232283868","rc":[{"batb":[[0,1.06,5],[1,1.05,201.04],[2,1.04,250]],"ltp":2.54,"tv":218.96,"id":8858707}]}]}
{"op":"mcm","clk":"11939270844","pt":1724835714647,"mc":[{"id":"1.232283868","rc":[{"batb":[[0,1.05,201.04],[1,1.04,250],[2,1.03,533.33]],"ltp":2.54,"tv":218.96,"id":8858707}]}]}
{"op":"mcm","clk":"11939270991","pt":1724835718342,"mc":[{"id":"1.232283868","rc":[{"batb":[[0,1.06,5],[1,1.05,201.04],[2,1.04,250]],"ltp":2.54,"tv":218.96,"id":8858707}]}]}
{"op":"mcm","clk":"11939271141","pt":1724835721659,"mc":[{"id":"1.232283868","rc":[{"batb":[[0,1.05,201.04],[1,1.04,250],[2,1.03,533.33]],"ltp":2.54,"tv":218.96,"id":8858707}]}]}
{"op":"mcm","clk":"11939271355","pt":1724835725567,"mc":[{"id":"1.232283868","rc":[{"batb":[[0,1.06,5],[1,1.05,201.04],[2,1.04,250]],"ltp":2.54,"tv":218.96,"id":8858707}]}]}
{"op":"mcm","clk":"11939271519","pt":1724835729174,"mc":[{"id":"1.232283868","rc":[{"batb":[[0,1.05,201.04],[1,1.04,250],[2,1.03,533.33]],"ltp":2.54,"tv":218.96,"id":8858707}]}]}
{"op":"mcm","clk":"11939271918","pt":1724835736710,"mc":[{"id":"1.232283868","rc":[{"batb":[[0,1.06,5],[1,1.05,201.04],[2,1.04,250]],"ltp":2.54,"tv":218.96,"id":8858707}]}]}
{"op":"mcm","clk":"11939272109","pt":1724835740309,"mc":[{"id":"1.232283868","rc":[{"batb":[[0,1.05,201.04],[1,1.04,250],[2,1.03,533.33]],"ltp":2.54,"tv":218.96,"id":8858707}]}]}
{"op":"mcm","clk":"11939272301","pt":1724835744005,"mc":[{"id":"1.232283868","rc":[{"batb":[[0,1.06,5],[1,1.05,201.04],[2,1.04,250]],"ltp":2.54,"tv":218.96,"id":8858707}]}]}
{"op":"mcm","clk":"11939272411","pt":1724835747489,"mc":[{"id":"1.232283868","rc":[{"batb":[[0,1.05,201.04],[1,1.04,250],[2,1.03,533.33]],"ltp":2.54,"tv":218.96,"id":8858707}]}]}
{"op":"mcm","clk":"11939272550","pt":1724835750888,"mc":[{"id":"1.232283868","rc":[{"batb":[[0,1.06,5],[1,1.05,201.04],[2,1.04,250]],"ltp":2.54,"tv":218.96,"id":8858707}]}]}
{"op":"mcm","clk":"11939272705","pt":1724835754124,"mc":[{"id":"1.232283868","rc":[{"batb":[[0,1.05,201.04],[1,1.04,250],[2,1.03,533.33]],"ltp":2.54,"tv":218.96,"id":8858707}]}]}
{"op":"mcm","clk":"11939272893","pt":1724835758283,"mc":[{"id":"1.232283868","rc":[{"batb":[[0,1.06,5],[1,1.05,201.04],[2,1.04,250]],"ltp":2.54,"tv":218.96,"id":8858707}]}]}
{"op":"mcm","clk":"11939273045","pt":1724835761824,"mc":[{"id":"1.232283868","rc":[{"batb":[[0,1.05,201.04],[1,1.04,250],[2,1.03,533.33]],"ltp":2.54,"tv":218.96,"id":8858707}]}]}
{"op":"mcm","clk":"11939273217","pt":1724835765009,"mc":[{"id":"1.232283868","rc":[{"batb":[[0,1.06,5],[1,1.05,201.04],[2,1.04,250]],"ltp":2.54,"tv":218.96,"id":8858707}]}]}
{"op":"mcm","clk":"11939273390","pt":1724835768513,"mc":[{"id":"1.232283868","rc":[{"batb":[[0,1.05,201.04],[1,1.04,250],[2,1.03,533.33]],"ltp":2.54,"tv":218.96,"id":8858707}]}]}
{"op":"mcm","clk":"11939273610","pt":1724835772211,"mc":[{"id":"1.232283868","rc":[{"batb":[[0,1.06,5],[1,1.05,201.04],[2,1.04,250]],"ltp":2.54,"tv":218.96,"id":8858707}]}]}
{"op":"mcm","clk":"11939273759","pt":1724835775625,"mc":[{"id":"1.232283868","rc":[{"batb":[[0,1.05,201.04],[1,1.04,250],[2,1.03,533.33]],"ltp":2.54,"tv":218.96,"id":8858707}]}]}
{"op":"mcm","clk":"11939273930","pt":1724835778849,"mc":[{"id":"1.232283868","rc":[{"batb":[[0,1.06,5],[1,1.05,201.04],[2,1.04,250]],"ltp":2.54,"tv":218.96,"id":8858707}]}]}
{"op":"mcm","clk":"11939274111","pt":1724835782045,"mc":[{"id":"1.232283868","rc":[{"batb":[[0,1.05,201.04],[1,1.04,250],[2,1.03,533.33]],"ltp":2.54,"tv":218.96,"id":8858707}]}]}
{"op":"mcm","clk":"11939274326","pt":1724835785838,"mc":[{"id":"1.232283868","rc":[{"batb":[[0,1.06,5],[1,1.05,201.04],[2,1.04,250]],"ltp":2.54,"tv":218.96,"id":8858707}]}]}
{"op":"mcm","clk":"11939274494","pt":1724835789173,"mc":[{"id":"1.232283868","rc":[{"batb":[[0,1.05,201.04],[1,1.04,250],[2,1.03,533.33]],"ltp":2.54,"tv":218.96,"id":8858707}]}]}
{"op":"mcm","clk":"11939274706","pt":1724835793638,"mc":[{"id":"1.232283868","rc":[{"batb":[[0,1.06,5],[1,1.05,201.04],[2,1.04,250]],"ltp":2.54,"tv":218.96,"id":8858707}]}]}
{"op":"mcm","clk":"11939274861","pt":1724835797274,"mc":[{"id":"1.232283868","rc":[{"batb":[[0,1.05,201.04],[1,1.04,250],[2,1.03,533.33]],"ltp":2.54,"tv":218.96,"id":8858707}]}]}
{"op":"mcm","clk":"11939274990","pt":1724835799947,"mc":[{"id":"1.232283868","rc":[{"batb":[[0,1.06,5],[1,1.05,201.04],[2,1.04,250]],"ltp":2.54,"tv":218.96,"id":8858707}]}]}
{"op":"mcm","clk":"11939275138","pt":1724835803466,"mc":[{"id":"1.232283868","rc":[{"batb":[[0,1.05,201.04],[1,1.04,250],[2,1.03,533.33]],"ltp":2.54,"tv":218.96,"id":8858707}]}]}
{"op":"mcm","clk":"11939275276","pt":1724835806285,"mc":[{"id":"1.232283868","rc":[{"batb":[[0,1.06,5],[1,1.05,201.04],[2,1.04,250]],"ltp":2.54,"tv":218.96,"id":8858707}]}]}
{"op":"mcm","clk":"11939275434","pt":1724835809665,"mc":[{"id":"1.232283868","rc":[{"batb":[[0,1.05,201.04],[1,1.04,250],[2,1.03,533.33]],"ltp":2.54,"tv":218.96,"id":8858707}]}]}
{"op":"mcm","clk":"11939275691","pt":1724835815209,"mc":[{"id":"1.232283868","rc":[{"batb":[[0,1.06,5],[1,1.05,201.04],[2,1.04,250]],"ltp":2.54,"tv":218.96,"id":8858707}]}]}
{"op":"mcm","clk":"11939275878","pt":1724835818806,"mc":[{"id":"1.232283868","rc":[{"batb":[[0,1.05,201.04],[1,1.04,250],[2,1.03,533.33]],"ltp":2.54,"tv":218.96,"id":8858707}]}]}
{"op":"mcm","clk":"11939276010","pt":1724835821589,"mc":[{"id":"1.232283868","rc":[{"batb":[[0,1.06,5],[1,1.05,201.04],[2,1.04,250]],"ltp":2.54,"tv":218.96,"id":8858707}]}]}
{"op":"mcm","clk":"11939276179","pt":1724835825329,"mc":[{"id":"1.232283868","rc":[{"batb":[[0,1.05,201.04],[1,1.04,250],[2,1.03,533.33]],"ltp":2.54,"tv":218.96,"id":8858707}]}]}
{"op":"mcm","clk":"11939276366","pt":1724835828991,"mc":[{"id":"1.232283868","rc":[{"batb":[[0,1.06,5],[1,1.05,201.04],[2,1.04,250]],"ltp":2.54,"tv":218.96,"id":8858707}]}]}
{"op":"mcm","clk":"11939276538","pt":1724835832528,"mc":[{"id":"1.232283868","rc":[{"batb":[[0,1.05,201.04],[1,1.04,250],[2,1.03,533.33]],"ltp":2.54,"tv":218.96,"id":8858707}]}]}
{"op":"mcm","clk":"11939276663","pt":1724835835400,"mc":[{"id":"1.232283868","rc":[{"batb":[[0,1.06,5],[1,1.05,201.04],[2,1.04,250]],"ltp":2.54,"tv":218.96,"id":8858707}]}]}
{"op":"mcm","clk":"11939276814","pt":1724835838887,"mc":[{"id":"1.232283868","rc":[{"batb":[[0,1.05,201.04],[1,1.04,250],[2,1.03,533.33]],"ltp":2.54,"tv":218.96,"id":8858707}]}]}
{"op":"mcm","clk":"11939276955","pt":1724835841406,"mc":[{"id":"1.232283868","rc":[{"batb":[[0,1.06,5],[1,1.05,201.04],[2,1.04,250]],"ltp":2.54,"tv":218.96,"id":8858707}]}]}
{"op":"mcm","clk":"11939277128","pt":1724835845122,"mc":[{"id":"1.232283868","rc":[{"batb":[[0,1.05,201.04],[1,1.04,250],[2,1.03,533.33]],"ltp":2.54,"tv":218.96,"id":8858707}]}]}
{"op":"mcm","clk":"11939277263","pt":1724835847839,"mc":[{"id":"1.232283868","rc":[{"batb":[[0,1.06,5],[1,1.05,201.04],[2,1.04,250]],"ltp":2.54,"tv":218.96,"id":8858707}]}]}
{"op":"mcm","clk":"11939277423","pt":1724835851299,"mc":[{"id":"1.232283868","rc":[{"batb":[[0,1.05,201.04],[1,1.04,250],[2,1.03,533.33]],"ltp":2.54,"tv":218.96,"id":8858707}]}]}
{"op":"mcm","clk":"11939277546","pt":1724835853521,"mc":[{"id":"1.232283868","rc":[{"batb":[[0,1.06,5],[1,1.05,201.04],[2,1.04,250]],"ltp":2.54,"tv":218.96,"id":8858707}]}]}
{"op":"mcm","clk":"11939277722","pt":1724835857012,"mc":[{"id":"1.232283868","rc":[{"batb":[[0,1.05,201.04],[1,1.04,250],[2,1.03,533.33]],"ltp":2.54,"tv":218.96,"id":8858707}]}]}
{"op":"mcm","clk":"11939277850","pt":1724835860038,"mc":[{"id":"1.232283868","rc":[{"batb":[[0,1.06,5],[1,1.05,201.04],[2,1.04,250]],"ltp":2.54,"tv":218.96,"id":8858707}]}]}
{"op":"mcm","clk":"11939278014","pt":1724835863548,"mc":[{"id":"1.232283868","rc":[{"batb":[[0,1.05,201.04],[1,1.04,250],[2,1.03,533.33]],"ltp":2.54,"tv":218.96,"id":8858707}]}]}
{"op":"mcm","clk":"11939278147","pt":1724835866161,"mc":[{"id":"1.232283868","rc":[{"batb":[[0,1.06,5],[1,1.05,201.04],[2,1.04,250]],"ltp":2.54,"tv":218.96,"id":8858707}]}]}
{"op":"mcm","clk":"11939278324","pt":1724835869752,"mc":[{"id":"1.232283868","rc":[{"batb":[[0,1.05,201.04],[1,1.04,250],[2,1.03,533.33]],"ltp":2.54,"tv":218.96,"id":8858707}]}]}
{"op":"mcm","clk":"11939278480","pt":1724835872743,"mc":[{"id":"1.232283868","rc":[{"batb":[[0,1.06,5],[1,1.05,201.04],[2,1.04,250]],"ltp":2.54,"tv":218.96,"id":8858707}]}]}
{"op":"mcm","clk":"11939278625","pt":1724835876337,"mc":[{"id":"1.232283868","rc":[{"batb":[[0,1.05,201.04],[1,1.04,250],[2,1.03,533.33]],"ltp":2.54,"tv":218.96,"id":8858707}]}]}
{"op":"mcm","clk":"11939278732","pt":1724835878845,"mc":[{"id":"1.232283868","rc":[{"batb":[[0,1.06,5],[1,1.05,201.04],[2,1.04,250]],"ltp":2.54,"tv":218.96,"id":8858707}]}]}
{"op":"mcm","clk":"11939278888","pt":1724835882342,"mc":[{"id":"1.232283868","rc":[{"batb":[[0,1.05,201.04],[1,1.04,250],[2,1.03,533.33]],"ltp":2.54,"tv":218.96,"id":8858707}]}]}
{"op":"mcm","clk":"11939279001","pt":1724835884769,"mc":[{"id":"1.232283868","rc":[{"batb":[[0,1.06,5],[1,1.05,201.04],[2,1.04,250]],"ltp":2.54,"tv":218.96,"id":8858707}]}]}
{"op":"mcm","clk":"11939279166","pt":1724835887967,"mc":[{"id":"1.232283868","rc":[{"batb":[[0,1.05,201.04],[1,1.04,250],[2,1.03,533.33]],"ltp":2.54,"tv":218.96,"id":8858707}]}]}
{"op":"mcm","clk":"11939279323","pt":1724835890858,"mc":[{"id":"1.232283868","rc":[{"batb":[[0,1.06,5],[1,1.05,201.04],[2,1.04,250]],"ltp":2.54,"tv":218.96,"id":8858707}]}]}
{"op":"mcm","clk":"11939279460","pt":1724835894157,"mc":[{"id":"1.232283868","rc":[{"batb":[[0,1.05,201.04],[1,1.04,250],[2,1.03,533.33]],"ltp":2.54,"tv":218.96,"id":8858707}]}]}
{"op":"mcm","clk":"11939279647","pt":1724835897558,"mc":[{"id":"1.232283868","rc":[{"batb":[[0,1.06,5],[1,1.05,201.04],[2,1.04,250]],"ltp":2.54,"tv":218.96,"id":8858707}]}]}
{"op":"mcm","clk":"11939279812","pt":1724835901084,"mc":[{"id":"1.232283868","rc":[{"batb":[[0,1.05,201.04],[1,1.04,250],[2,1.03,533.33]],"ltp":2.54,"tv":218.96,"id":8858707}]}]}
{"op":"mcm","clk":"11939280007","pt":1724835904382,"mc":[{"id":"1.232283868","rc":[{"batb":[[0,1.06,5],[1,1.05,201.04],[2,1.04,250]],"ltp":2.54,"tv":218.96,"id":8858707}]}]}
{"op":"mcm","clk":"11939280167","pt":1724835907586,"mc":[{"id":"1.232283868","rc":[{"batb":[[0,1.05,201.04],[1,1.04,250],[2,1.03,533.33]],"ltp":2.54,"tv":218.96,"id":8858707}]}]}
{"op":"mcm","clk":"11939280317","pt":1724835911384,"mc":[{"id":"1.232283868","rc":[{"batb":[[0,1.06,5],[1,1.05,201.04],[2,1.04,250]],"ltp":2.54,"tv":218.96,"id":8858707}]}]}
{"op":"mcm","clk":"11939280497","pt":1724835914685,"mc":[{"id":"1.232283868","rc":[{"batb":[[0,1.05,201.04],[1,1.04,250],[2,1.03,533.33]],"ltp":2.54,"tv":218.96,"id":8858707}]}]}
{"op":"mcm","clk":"11939280742","pt":1724835919176,"mc":[{"id":"1.232283868","rc":[{"batb":[[0,1.06,5],[1,1.05,201.04],[2,1.04,250]],"ltp":2.54,"tv":218.96,"id":8858707}]}]}
{"op":"mcm","clk":"11939280932","pt":1724835922617,"mc":[{"id":"1.232283868","rc":[{"batb":[[0,1.05,201.04],[1,1.04,250],[2,1.03,533.33]],"ltp":2.54,"tv":218.96,"id":8858707}]}]}
{"op":"mcm","clk":"11939281109","pt":1724835926323,"mc":[{"id":"1.232283868","rc":[{"batb":[[0,1.06,5],[1,1.05,201.04],[2,1.04,250]],"ltp":2.54,"tv":218.96,"id":8858707}]}]}
{"op":"mcm","clk":"11939281257","pt":1724835929822,"mc":[{"id":"1.232283868","rc":[{"batb":[[0,1.05,201.04],[1,1.04,250],[2,1.03,533.33]],"ltp":2.54,"tv":218.96,"id":8858707}]}]}
{"op":"mcm","clk":"11939281372","pt":1724835932811,"mc":[{"id":"1.232283868","rc":[{"batb":[[0,1.06,5],[1,1.05,201.04],[2,1.04,250]],"ltp":2.54,"tv":218.96,"id":8858707}]}]}
{"op":"mcm","clk":"11939281542","pt":1724835936219,"mc":[{"id":"1.232283868","rc":[{"batb":[[0,1.05,201.04],[1,1.04,250],[2,1.03,533.33]],"ltp":2.54,"tv":218.96,"id":8858707}]}]}
{"op":"mcm","clk":"11939281698","pt":1724835939036,"mc":[{"id":"1.232283868","rc":[{"batb":[[0,1.06,5],[1,1.05,201.04],[2,1.04,250]],"ltp":2.54,"tv":218.96,"id":8858707}]}]}
{"op":"mcm","clk":"11939281852","pt":1724835942228,"mc":[{"id":"1.232283868","rc":[{"batb":[[0,1.05,201.04],[1,1.04,250],[2,1.03,533.33]],"ltp":2.54,"tv":218.96,"id":8858707}]}]}
{"op":"mcm","clk":"11939281993","pt":1724835944906,"mc":[{"id":"1.232283868","rc":[{"batb":[[0,1.06,5],[1,1.05,201.04],[2,1.04,250]],"ltp":2.54,"tv":218.96,"id":8858707}]}]}
{"op":"mcm","clk":"11939282174","pt":1724835948253,"mc":[{"id":"1.232283868","rc":[{"batb":[[0,1.05,201.04],[1,1.04,250],[2,1.03,533.33]],"ltp":2.54,"tv":218.96,"id":8858707}]}]}
{"op":"mcm","clk":"11939282466","pt":1724835953740,"mc":[{"id":"1.232283868","rc":[{"batb":[[0,1.06,5],[1,1.05,201.04],[2,1.04,250]],"ltp":2.54,"tv":218.96,"id":8858707}]}]}
{"op":"mcm","clk":"11939282585","pt":1724835957042,"mc":[{"id":"1.232283868","rc":[{"batb":[[0,1.05,201.04],[1,1.04,250],[2,1.03,533.33]],"ltp":2.54,"tv":218.96,"id":8858707}]}]}
{"op":"mcm","clk":"11939282843","pt":1724835962650,"mc":[{"id":"1.232283868","rc":[{"batb":[[0,1.06,5],[1,1.05,201.04],[2,1.04,250]],"ltp":2.54,"tv":218.96,"id":8858707}]}]}
{"op":"mcm","clk":"11939282982","pt":1724835965885,"mc":[{"id":"1.232283868","rc":[{"batb":[[0,1.05,201.04],[1,1.04,250],[2,1.03,533.33]],"ltp":2.54,"tv":218.96,"id":8858707}]}]}
{"op":"mcm","clk":"11939283131","pt":1724835968347,"mc":[{"id":"1.232283868","rc":[{"batb":[[0,1.06,5],[1,1.05,201.04],[2,1.04,250]],"ltp":2.54,"tv":218.96,"id":8858707}]}]}
{"op":"mcm","clk":"11939283287","pt":1724835971637,"mc":[{"id":"1.232283868","rc":[{"batb":[[0,1.05,201.04],[1,1.04,250],[2,1.03,533.33]],"ltp":2.54,"tv":218.96,"id":8858707}]}]}
{"op":"mcm","clk":"11939283399","pt":1724835974045,"mc":[{"id":"1.232283868","rc":[{"batb":[[0,1.06,5],[1,1.05,201.04],[2,1.04,250]],"ltp":2.54,"tv":218.96,"id":8858707}]}]}
{"op":"mcm","clk":"11939283595","pt":1724835977459,"mc":[{"id":"1.232283868","rc":[{"trd":[[2.62,0.21]],"batb":[[0,1.05,201.04],[1,1.04,250],[2,1.03,533.33]],"ltp":2.62,"tv":219.17,"id":8858707},{"trd":[[1.25,3.32],[1.61,0.34]],"batb":[[0,1.09,20.34],[1,1.05,200],[2,1.04,251.05]],"ltp":1.25,"tv":279.59,"id":2857968}],"tv":498.76}]}
{"op":"mcm","clk":"11939427571","pt":1724838666112,"mc":[{"id":"1.232283868","rc":[{"batb":[[0,1.09,20]],"ltp":1.25,"tv":279.59,"id":2857968}]}]}
{"op":"mcm","clk":"11939429472","pt":1724838706365,"mc":[{"id":"1.232283868","rc":[{"batb":[[0,1.16,1],[1,1.09,20],[2,1.05,200]],"ltp":1.25,"tv":279.59,"id":2857968}]}]}
{"op":"mcm","clk":"11939500873","pt":1724839974804,"mc":[{"id":"1.232283868","rc":[{"trd":[[1.6,135.99],[1.61,70.72],[2.54,12.29]],"ltp":2.62,"tv":219.2,"id":8858707},{"trd":[[1.22,271.99]],"ltp":1.25,"tv":279.64,"id":2857968}],"tv":498.85}]}
{"op":"mcm","clk":"11939868307","pt":1724845374803,"mc":[{"id":"1.232283868","rc":[{"trd":[[1.6,136.05],[1.61,70.74],[2.54,12.29]],"ltp":2.62,"tv":219.28,"id":8858707},{"trd":[[1.22,272.09]],"ltp":1.25,"tv":279.74,"id":2857968}],"tv":499.03}]}
{"op":"mcm","clk":"11939951920","pt":1724846311689,"mc":[{"id":"1.232283868","rc":[{"batl":[[0,1.64,30],[1,1.65,10]],"ltp":1.25,"tv":279.74,"id":2857968}]}]}
{"op":"mcm","clk":"11940323344","pt":1724850478009,"mc":[{"id":"1.232283868","rc":[{"trd":[[1.6,136.12],[1.61,70.78],[2.54,12.28]],"ltp":2.62,"tv":219.39,"id":8858707},{"trd":[[1.22,272.24]],"batl":[[0,1.63,10],[1,1.64,30]],"ltp":1.25,"tv":279.89,"id":2857968}],"tv":499.29}]}
{"op":"mcm","clk":"11940324276","pt":1724850486123,"mc":[{"id":"1.232283868","rc":[{"trd":[[1.16,2]],"batb":[[0,1.09,20],[1,1.05,200],[2,1.04,251.05]],"ltp":1.16,"tv":281.89,"id":2857968}],"tv":501.29}]}
{"op":"mcm","clk":"11940769730","pt":1724855037271,"mc":[{"id":"1.232283868","rc":[{"trd":[[1.6,136.22],[1.61,70.83],[2.54,12.29]],"ltp":2.62,"tv":219.54,"id":8858707},{"trd":[[1.1,2],[1.22,272.43]],"batl":[[0,1.62,30],[1,1.63,10]],"ltp":1.16,"tv":282.08,"id":2857968}],"tv":501.63}]}
{"op":"mcm","clk":"11941218697","pt":1724858639985,"mc":[{"id":"1.232283868","rc":[{"trd":[[1.6,136.06],[1.61,70.75],[2.54,12.29]],"ltp":2.62,"tv":219.3,"id":8858707},{"trd":[[1.22,272.11],[1.62,0.06]],"batl":[[0,1.62,29.97]],"ltp":1.62,"tv":281.83,"id":2857968}],"tv":501.13}]}
{"op":"mcm","clk":"11941310548","pt":1724859353247,"mc":[{"id":"1.232283868","rc":[{"batl":[[0,1.61,10],[1,1.62,29.97]],"ltp":1.62,"tv":281.83,"id":2857968}]}]}
{"op":"mcm","clk":"11941574124","pt":1724861057877,"mc":[{"id":"1.232283868","rc":[{"trd":[[1.6,136.22],[1.61,70.83],[2.54,12.29]],"ltp":2.62,"tv":219.55,"id":8858707},{"trd":[[1.22,272.43]],"batl":[[0,1.6,29.97],[1,1.61,10]],"ltp":1.62,"tv":282.14,"id":2857968}],"tv":501.7}]}
{"op":"mcm","clk":"11942490441","pt":1724866758245,"mc":[{"id":"1.232283868","rc":[{"trd":[[1.6,136.35],[1.61,70.9]],"ltp":2.62,"tv":219.75,"id":8858707},{"trd":[[1.22,272.7]],"batl":[[0,1.59,10],[1,1.6,29.97]],"ltp":1.62,"tv":282.41,"id":2857968}],"tv":502.17}]}
{"op":"mcm","clk":"11943361925","pt":1724872374808,"mc":[{"id":"1.232283868","rc":[{"trd":[[1.6,136.38],[1.61,70.92]],"ltp":2.62,"tv":219.79,"id":8858707},{"trd":[[1.22,272.75]],"ltp":1.62,"tv":282.47,"id":2857968}],"tv":502.26}]}
{"op":"mcm","clk":"11943517714","pt":1724873256013,"mc":[{"id":"1.232283868","rc":[{"batl":[[0,1.5,1],[1,1.59,10],[2,1.6,29.97]],"ltp":1.62,"tv":282.47,"id":2857968}]}]}
{"op":"mcm","clk":"11944107379","pt":1724877774811,"mc":[{"id":"1.232283868","rc":[{"trd":[[1.6,136.37],[1.61,70.91],[2.54,12.29]],"ltp":2.62,"tv":219.78,"id":8858707},{"trd":[[1.22,272.74]],"ltp":1.62,"tv":282.45,"id":2857968}],"tv":502.24}]}
{"op":"mcm","clk":"11944203145","pt":1724878881731,"mc":[{"id":"1.232283868","rc":[{"trd":[[1.6,136.29],[1.61,70.87],[2.54,12.29]],"ltp":2.62,"tv":219.66,"id":8858707},{"trd":[[1.22,272.58]],"batl":[[0,1.49,1],[1,1.5,1],[2,1.59,10]],"ltp":1.62,"tv":282.3,"id":2857968}],"tv":501.96}]}
{"op":"mcm","clk":"11944471564","pt":1724883174808,"mc":[{"id":"1.232283868","rc":[{"trd":[[1.6,136.29]],"ltp":2.62,"tv":219.66,"id":8858707},{"trd":[[1.22,272.58]],"ltp":1.62,"tv":282.3,"id":2857968}],"tv":501.97}]}
{"op":"mcm","clk":"11944826173","pt":1724888574819,"mc":[{"id":"1.232283868","rc":[{"trd":[[1.6,136.28],[1.61,70.86],[2.54,12.3]],"ltp":2.62,"tv":219.64,"id":8858707},{"trd":[[1.22,272.55]],"ltp":1.62,"tv":282.27,"id":2857968}],"tv":501.91}]}
{"op":"mcm","clk":"11945155440","pt":1724893974819,"mc":[{"id":"1.232283868","rc":[{"trd":[[1.6,136.16],[1.61,70.8],[2.54,12.29]],"ltp":2.62,"tv":219.45,"id":8858707},{"trd":[[1.22,272.31]],"ltp":1.62,"tv":282.03,"id":2857968}],"tv":501.49}]}
{"op":"mcm","clk":"11945439596","pt":1724899374820,"mc":[{"id":"1.232283868","rc":[{"trd":[[1.6,136.22],[1.61,70.83]],"ltp":2.62,"tv":219.55,"id":8858707},{"trd":[[1.22,272.43]],"ltp":1.62,"tv":282.14,"id":2857968}],"tv":501.7}]}
{"op":"mcm","clk":"11945484458","pt":1724900326711,"mc":[{"id":"1.232283868","rc":[{"batl":[[0,1.49,2.6]],"ltp":1.62,"tv":282.14,"id":2857968}]}]}
{"op":"mcm","clk":"11945651505","pt":1724904774820,"mc":[{"id":"1.232283868","rc":[{"trd":[[1.6,136.17],[1.61,70.81],[2.54,12.29]],"ltp":2.62,"tv":219.48,"id":8858707},{"trd":[[1.22,272.35]],"ltp":1.62,"tv":282.06,"id":2857968}],"tv":501.55}]}
{"op":"mcm","clk":"11945755321","pt":1724908211508,"mc":[{"id":"1.232283868","rc":[{"trd":[[1.6,136.12],[1.61,70.78],[2.54,12.29],[12.5,1]],"ltp":12.5,"tv":220.4,"id":8858707},{"trd":[[1.09,11.47],[1.22,272.24]],"batb":[[0,1.09,8.53]],"ltp":1.09,"tv":293.42,"id":2857968}],"tv":513.83}]}
{"op":"mcm","clk":"11945807558","pt":1724909784229,"mc":[{"id":"1.232283868","rc":[{"batl":[[0,1.49,1.6],[2,1.58,11]],"ltp":1.09,"tv":293.42,"id":2857968}]}]}
{"op":"mcm","clk":"11945884823","pt":1724911916990,"mc":[{"id":"1.232283868","rc":[{"trd":[[1.6,136.09],[1.61,70.77],[2.54,12.29]],"ltp":12.5,"tv":220.35,"id":8858707},{"trd":[[1.22,272.18]],"ltp":1.09,"tv":293.37,"id":2857968}],"tv":513.73}]}
{"op":"mcm","clk":"11945885086","pt":1724911924993,"mc":[{"id":"1.232283868","rc":[{"batl":[[0,1.49,1.7]],"ltp":1.09,"tv":293.37,"id":2857968}]}]}
{"op":"mcm","clk":"11945915224","pt":1724913074146,"mc":[{"id":"1.232283868","rc":[{"batl":[[0,1.49,1.6]],"ltp":1.09,"tv":293.37,"id":2857968}]}]}
{"op":"mcm","clk":"11945999265","pt":1724915574807,"mc":[{"id":"1.232283868","rc":[{"trd":[[1.6,136.05],[1.61,70.75],[2.54,12.29]],"ltp":12.5,"tv":220.29,"id":8858707},{"trd":[[1.22,272.11]],"ltp":1.09,"tv":293.29,"id":2857968}],"tv":513.59}]}
{"op":"mcm","clk":"11946017916","pt":1724915817846,"mc":[{"id":"1.232283868","rc":[{"batb":[[1,1.06,2],[2,1.05,200]],"batl":[[0,1.48,2],[1,1.49,1.6],[2,1.5,1]],"ltp":1.09,"tv":293.29,"id":2857968}]}]}
{"op":"mcm","clk":"11946059131","pt":1724916950725,"mc":[{"id":"1.232283868","rc":[{"trd":[[1.09,28.53]],"batb":[[0,1.06,2],[1,1.05,200],[2,1.04,251.05]],"batl":[[0,1.09,2.87],[1,1.48,2],[2,1.49,1.6]],"ltp":1.09,"tv":310.35,"id":2857968}],"tv":530.65}]}
{"op":"mcm","clk":"11946060044","pt":1724916971229,"mc":[{"id":"1.232283868","rc":[{"batl":[[0,1.48,2],[1,1.49,1.6],[2,1.5,1]],"ltp":1.09,"tv":310.35,"id":2857968}]}]}
{"op":"mcm","clk":"11946130682","pt":1724918668448,"mc":[{"id":"1.232283868","rc":[{"trd":[[1.6,136],[1.61,70.72]],"ltp":12.5,"tv":220.22,"id":8858707},{"trd":[[1.09,28.53],[1.22,272.01]],"ltp":1.09,"tv":310.24,"id":2857968}],"tv":530.46}]}
{"op":"mcm","clk":"11946131491","pt":1724918687751,"mc":[{"id":"1.232283868","rc":[{"batl":[[0,1.4,17],[1,1.48,2],[2,1.49,1.6]],"ltp":1.09,"tv":310.24,"id":2857968}]}]}
{"op":"mcm","clk":"11946243499","pt":1724921108601,"mc":[{"id":"1.232283868","rc":[{"batl":[[0,1.4,17.98]],"ltp":1.09,"tv":310.24,"id":2857968}]}]}
{"op":"mcm","clk":"11946243737","pt":1724921113689,"mc":[{"id":"1.232283868","rc":[{"batl":[[0,1.4,17]],"ltp":1.09,"tv":310.24,"id":2857968}]}]}
{"op":"mcm","clk":"11946244089","pt":1724921121889,"mc":[{"id":"1.232283868","rc":[{"batl":[[0,1.08,1.51],[1,1.4,17],[2,1.48,2]],"ltp":1.09,"tv":310.24,"id":2857968}]}]}
{"op":"mcm","clk":"11946244627","pt":1724921133701,"mc":[{"id":"1.232283868","rc":[{"batl":[[0,1.4,17],[1,1.48,2],[2,1.49,1.6]],"ltp":1.09,"tv":310.24,"id":2857968}]}]}
{"op":"mcm","clk":"11946245069","pt":1724921144948,"mc":[{"id":"1.232283868","rc":[{"batb":[[0,1.35,1.51],[1,1.06,2],[2,1.05,200]],"ltp":1.09,"tv":310.24,"id":2857968}]}]}
{"op":"mcm","clk":"11946245364","pt":1724921152255,"mc":[{"id":"1.232283868","rc":[{"batb":[[0,1.06,2],[1,1.05,200],[2,1.04,251.05]],"ltp":1.09,"tv":310.24,"id":2857968}]}]}
{"op":"mcm","clk":"11946245634","pt":1724921158525,"mc":[{"id":"1.232283868","rc":[{"batl":[[0,1.08,1.51],[1,1.4,17],[2,1.48,2]],"ltp":1.09,"tv":310.24,"id":2857968}]}]}
{"op":"mcm","clk":"11946245949","pt":1724921165865,"mc":[{"id":"1.232283868","rc":[{"batl":[[0,1.4,17],[1,1.48,2],[2,1.49,1.6]],"ltp":1.09,"tv":310.24,"id":2857968}]}]}
{"op":"mcm","clk":"11946246237","pt":1724921172493,"mc":[{"id":"1.232283868","rc":[{"batb":[[0,1.38,1.51],[1,1.06,2],[2,1.05,200]],"ltp":1.09,"tv":310.24,"id":2857968}]}]}
{"op":"mcm","clk":"11946246504","pt":1724921179569,"mc":[{"id":"1.232283868","rc":[{"batb":[[0,1.06,2],[1,1.05,200],[2,1.04,251.05]],"ltp":1.09,"tv":310.24,"id":2857968}]}]}
{"op":"mcm","clk":"11946264419","pt":1724921615660,"mc":[{"id":"1.232283868","rc":[{"batl":[[0,1.08,1.51],[1,1.4,17],[2,1.48,2]],"ltp":1.09,"tv":310.24,"id":2857968}]}]}
{"op":"mcm","clk":"11946265032","pt":1724921628536,"mc":[{"id":"1.232283868","rc":[{"batl":[[0,1.4,17],[1,1.48,2],[2,1.49,1.6]],"ltp":1.09,"tv":310.24,"id":2857968}]}]}
{"op":"mcm","clk":"11946265379","pt":1724921636681,"mc":[{"id":"1.232283868","rc":[{"batb":[[0,1.38,1.51],[1,1.06,2],[2,1.05,200]],"ltp":1.09,"tv":310.24,"id":2857968}]}]}
{"op":"mcm","clk":"11946265896","pt":1724921648799,"mc":[{"id":"1.232283868","rc":[{"batb":[[0,1.06,2],[1,1.05,200],[2,1.04,251.05]],"ltp":1.09,"tv":310.24,"id":2857968}]}]}
{"op":"mcm","clk":"11946288502","pt":1724922103316,"mc":[{"id":"1.232283868","rc":[{"trd":[[1.6,136.34],[1.61,70.9],[2.54,12.28]],"ltp":12.5,"tv":220.72,"id":8858707},{"trd":[[1.09,28.55],[1.1,2],[1.22,272.68]],"batl":[[0,1.14,180.6],[1,1.4,17],[2,1.48,2]],"ltp":1.09,"tv":310.94,"id":2857968}],"tv":531.67}]}
{"op":"mcm","clk":"11946291763","pt":1724922159164,"mc":[{"id":"1.232283868","rc":[{"batb":[[0,1.12,1.21],[1,1.06,2],[2,1.05,200]],"ltp":1.09,"tv":310.94,"id":2857968}]}]}
{"op":"mcm","clk":"11946292453","pt":1724922170571,"mc":[{"id":"1.232283868","rc":[{"batb":[[0,1.06,2],[1,1.05,200],[2,1.04,251.05]],"ltp":1.09,"tv":310.94,"id":2857968}]}]}
{"op":"mcm","clk":"11946293310","pt":1724922185191,"mc":[{"id":"1.232283868","rc":[{"batb":[[0,1.1,1.44],[1,1.06,2],[2,1.05,200]],"ltp":1.09,"tv":310.94,"id":2857968}]}]}
{"op":"mcm","clk":"11946293595","pt":1724922191437,"mc":[{"id":"1.232283868","rc":[{"batb":[[0,1.06,2],[1,1.05,200],[2,1.04,251.05]],"ltp":1.09,"tv":310.94,"id":2857968}]}]}
{"op":"mcm","clk":"11946508890","pt":1724926374801,"mc":[{"id":"1.232283868","rc":[{"trd":[[1.6,136.33],[1.61,70.89],[2.54,12.28]],"ltp":12.5,"tv":220.7,"id":8858707},{"trd":[[1.09,28.55],[1.22,272.65]],"batl":[[0,1.14,180.95]],"ltp":1.09,"tv":310.91,"id":2857968}],"tv":531.61}]}
{"op":"mcm","clk":"11946579102","pt":1724927585659,"mc":[{"id":"1.232283868","rc":[{"batl":[[0,1.14,208.4]],"ltp":1.09,"tv":310.91,"id":2857968}]}]}
{"op":"mcm","clk":"11946580952","pt":1724927621617,"mc":[{"id":"1.232283868","rc":[{"batl":[[0,1.07,1.52],[1,1.14,208.4],[2,1.4,17]],"ltp":1.09,"tv":310.91,"id":2857968}]}]}
{"op":"mcm","clk":"11946582426","pt":1724927649333,"mc":[{"id":"1.232283868","rc":[{"batl":[[0,1.14,208.4],[1,1.4,17],[2,1.48,2]],"ltp":1.09,"tv":310.91,"id":2857968}]}]}
{"op":"mcm","clk":"11946582767","pt":1724927655749,"mc":[{"id":"1.232283868","rc":[{"batl":[[0,1.13,27.44],[1,1.14,180.95],[2,1.4,17]],"ltp":1.09,"tv":310.91,"id":2857968}]}]}
{"op":"mcm","clk":"11946582984","pt":1724927660058,"mc":[{"id":"1.232283868","rc":[{"batl":[[0,1.07,3.79],[1,1.13,27.44],[2,1.14,180.95]],"ltp":1.09,"tv":310.91,"id":2857968}]}]}
{"op":"mcm","clk":"11946583381","pt":1724927667483,"mc":[{"id":"1.232283868","rc":[{"batl":[[0,1.13,27.44],[1,1.14,180.95],[2,1.4,17]],"ltp":1.09,"tv":310.91,"id":2857968}]}]}
{"op":"mcm","clk":"11946585010","pt":1724927702832,"mc":[{"id":"1.232283868","rc":[{"trd":[[1.06,4]],"batb":[[0,1.05,200],[1,1.04,251.05],[2,1.03,533.33]],"ltp":1.06,"tv":314.91,"id":2857968}],"tv":535.61}]}
{"op":"mcm","clk":"11946599847","pt":1724927981132,"mc":[{"id":"1.232283868","rc":[{"batl":[[2,1.48,2]],"ltp":1.06,"tv":314.91,"id":2857968}]}]}
{"op":"mcm","clk":"11946605743","pt":1724928078364,"mc":[{"id":"1.232283868","rc":[{"batl":[[0,1.12,1.8],[1,1.13,27.44],[2,1.14,180.95]],"ltp":1.06,"tv":314.91,"id":2857968}]}]}
{"op":"mcm","clk":"11946685821","pt":1724929690807,"mc":[{"id":"1.232283868","rc":[{"trd":[[1.6,136.38],[1.61,70.92],[2.54,12.28]],"ltp":12.5,"tv":220.78,"id":8858707},{"trd":[[1.09,28.55],[1.12,3.6],[1.22,272.76]],"batb":[[0,1.12,1.2],[1,1.05,200],[2,1.04,251.05]],"batl":[[0,1.13,27.46],[1,1.14,180.93],[2,1.48,2]],"ltp":1.12,"tv":318.62,"id":2857968}],"tv":539.41}]}
{"op":"mcm","clk":"11946686448","pt":1724929703146,"mc":[{"id":"1.232283868","rc":[{"trd":[[1.12,5.6]],"batb":[[0,1.05,200.2],[1,1.04,251.05],[2,1.03,533.33]],"ltp":1.12,"tv":320.62,"id":2857968}],"tv":541.41}]}
{"op":"mcm","clk":"11946688322","pt":1724929739677,"mc":[{"id":"1.232283868","rc":[{"batb":[[0,1.06,1.7],[1,1.05,200],[2,1.04,251.05]],"ltp":1.12,"tv":320.62,"id":2857968}]}]}
{"op":"mcm","clk":"11946700283","pt":1724929967778,"mc":[{"id":"1.232283868","rc":[{"trd":[[1.06,7],[1.09,28.95]],"batb":[[0,1.05,200],[1,1.04,251.05],[2,1.03,533.33]],"batl":[[0,1.06,2.09],[1,1.13,27.46],[2,1.14,180.93]],"ltp":1.06,"tv":324.02,"id":2857968}],"tv":544.8}]}
{"op":"mcm","clk":"11946700477","pt":1724929970687,"mc":[{"id":"1.232283868","rc":[{"batl":[[0,1.13,27.46],[1,1.14,180.93],[2,1.48,2]],"ltp":1.06,"tv":324.02,"id":2857968}]}]}
{"op":"mcm","clk":"11946701949","pt":1724929995632,"mc":[{"id":"1.232283868","rc":[{"batl":[[0,1.06,1.52],[1,1.13,27.46],[2,1.14,180.93]],"ltp":1.06,"tv":324.02,"id":2857968}]}]}
