{"op":"mcm","clk":"11789519549","pt":1723023504555,"mc":[{"id":"1.231541189","marketDefinition":{"bspMarket":false,"turnInPlayEnabled":true,"persistenceEnabled":true,"marketBaseRate":5.0,"eventId":"33475068","eventTypeId":"4","numberOfWinners":1,"bettingType":"ODDS","marketType":"MATCH_ODDS","marketTime":"2024-08-08T09:45:00.000Z","suspendTime":"2024-08-08T09:45:00.000Z","bspReconciled":false,"complete":true,"inPlay":false,"crossMatching":false,"runnersVoidable":false,"numberOfActiveRunners":2,"betDelay":0,"status":"OPEN","runners":[{"status":"ACTIVE","sortPriority":1,"id":19587212,"name":"Munster Reds"},{"status":"ACTIVE","sortPriority":2,"id":19587555,"name":"Leinster Lightning"}],"regulators":["MR_INT"],"countryCode":"GB","discountAllowed":true,"timezone":"GMT","openDate":"2024-08-08T09:45:00.000Z","version":6060481178,"name":"Match Odds","eventName":"Munster Reds v Leinster Lightning"},"rc":[{"batb":[[0,1.03,200],[1,1.02,200],[2,1.01,220]],"ltp":0.0,"tv":0.0,"id":19587212},{"batb":[[0,1.03,200],[1,1.02,200],[2,1.01,220]],"ltp":0.0,"tv":0.0,"id":19587555}]}]}
{"op":"mcm","clk":"11789758621","pt":1723026670379,"mc":[{"id":"1.231541189","rc":[{"batb":[[2,1.01,483.63]],"ltp":0.0,"tv":0.0,"id":19587212},{"batb":[[2,1.01,483.63]],"ltp":0.0,"tv":0.0,"id":19587555}]}]}
{"op":"mcm","clk":"11789796500","pt":1723027182401,"mc":[{"id":"1.231541189","rc":[{"batb":[[2,1.01,484.58]],"ltp":0.0,"tv":0.0,"id":19587212},{"batb":[[2,1.01,484.58]],"ltp":0.0,"tv":0.0,"id":19587555}]}]}
{"op":"mcm","clk":"11789797163","pt":1723027191342,"mc":[{"id":"1.231541189","rc":[{"batb":[[1,1.02,200.79]],"ltp":0.0,"tv":0.0,"id":19587212},{"batb":[[1,1.02,200.79]],"ltp":0.0,"tv":0.0,"id":19587555}]}]}
{"op":"mcm","clk":"11789797960","pt":1723027201829,"mc":[{"id":"1.231541189","rc":[{"batb":[[0,1.02,201.57],[1,1.01,484.58],[2,1.01,0]],"ltp":0.0,"tv":0.0,"id":19587212},{"batb":[[0,1.02,201.57],[1,1.01,484.58],[2,1.01,0]],"ltp":0.0,"tv":0.0,"id":19587555}]}]}
{"op":"mcm","clk":"11789798440","pt":1723027206661,"mc":[{"id":"1.231541189","marketDefinition":{"bspMarket":false,"turnInPlayEnabled":true,"persistenceEnabled":true,"marketBaseRate":5.0,"eventId":"33475068","eventTypeId":"4","numberOfWinners":1,"bettingType":"ODDS","marketType":"MATCH_ODDS","marketTime":"2024-08-08T09:45:00.000Z","suspendTime":"2024-08-08T09:45:00.000Z","bspReconciled":false,"complete":true,"inPlay":false,"crossMatching":true,"runnersVoidable":false,"numberOfActiveRunners":2,"betDelay":0,"status":"OPEN","runners":[{"status":"ACTIVE","sortPriority":1,"id":19587212,"name":"Munster Reds"},{"status":"ACTIVE","sortPriority":2,"id":19587555,"name":"Leinster Lightning"}],"regulators":["MR_INT"],"countryCode":"GB","discountAllowed":true,"timezone":"GMT","openDate":"2024-08-08T09:45:00.000Z","version":6060481178,"name":"Match Odds","eventName":"Munster Reds v Leinster Lightning"}}]}
{"op":"mcm","clk":"11789819557","pt":1723027475787,"mc":[{"id":"1.231541189","rc":[{"batb":[[0,1.25,15],[1,1.02,201.57],[2,1.01,484.58]],"ltp":0.0,"tv":0.0,"id":19587212}]}]}
{"op":"mcm","clk":"11789820165","pt":1723027483794,"mc":[{"id":"1.231541189","rc":[{"batb":[[0,1.3,12],[1,1.02,201.57],[2,1.01,484.58]],"ltp":0.0,"tv":0.0,"id":19587555}]}]}
{"op":"mcm","clk":"11789822694","pt":1723027517650,"mc":[{"id":"1.231541189","rc":[{"trd":[[1.3,0.14]],"batb":[[0,1.3,11.93]],"ltp":1.3,"tv":0.14,"id":19587555}],"tv":0.14}]}
{"op":"mcm","clk":"11789905602","pt":1723028719207,"mc":[{"id":"1.231541189","rc":[{"batb":[[2,1.01,484.71]],"ltp":0.0,"tv":0.0,"id":19587212},{"trd":[[1.3,0.28]],"batb":[[0,1.3,11.86],[2,1.01,484.71]],"ltp":1.3,"tv":0.28,"id":19587555}],"tv":0.28}]}
{"op":"mcm","clk":"11790042576","pt":1723030563126,"mc":[{"id":"1.231541189","rc":[{"batb":[[0,1.26,20],[1,1.25,15],[2,1.02,201.57]],"ltp":0.0,"tv":0.0,"id":19587212},{"batb":[[0,1.31,10],[1,1.3,11.86],[2,1.02,201.57]],"ltp":1.3,"tv":0.28,"id":19587555}]}]}
{"op":"mcm","clk":"11790211629","pt":1723033148405,"mc":[{"id":"1.231541189","rc":[{"batb":[[2,1.02,201.57]],"ltp":0.0,"tv":0.0,"id":19587212},{"batb":[[0,1.33,10],[2,1.02,201.57]],"ltp":1.3,"tv":0.28,"id":19587555}]}]}
{"op":"mcm","clk":"11790211967","pt":1723033154875,"mc":[{"id":"1.231541189","rc":[{"batb":[[0,1.31,10]],"ltp":1.3,"tv":0.28,"id":19587555}]}]}
{"op":"mcm","clk":"11790463808","pt":1723037348544,"mc":[{"id":"1.231541189","rc":[{"batb":[[0,1.55,45.95],[1,1.31,10],[2,1.3,11.86]],"ltp":1.3,"tv":0.28,"id":19587555}]}]}
{"op":"mcm","clk":"11790464660","pt":1723037362388,"mc":[{"id":"1.231541189","rc":[{"batb":[[0,1.55,45.95],[1,1.26,20],[2,1.25,15]],"ltp":0.0,"tv":0.0,"id":19587212}]}]}
{"op":"mcm","clk":"11790465273","pt":1723037372990,"mc":[{"id":"1.231541189","rc":[{"trd":[[1.55,91.89]],"batb":[[0,1.31,10],[1,1.3,11.86],[2,1.02,201.57]],"batl":[[0,1.55,1.35]],"ltp":1.55,"tv":92.17,"id":19587555}],"tv":92.17}]}
{"op":"mcm","clk":"11790466008","pt":1723037384212,"mc":[{"id":"1.231541189","rc":[{"trd":[[1.55,91.89]],"batb":[[0,1.26,20],[1,1.25,15],[2,1.02,201.57]],"batl":[[0,1.55,1.35]],"ltp":1.55,"tv":91.89,"id":19587212}],"tv":184.06}]}
{"op":"mcm","clk":"11790568074","pt":1723039237040,"mc":[{"id":"1.231541189","rc":[{"trd":[[1.55,91.93]],"batb":[[0,1.6,5],[1,1.26,20],[2,1.25,15]],"ltp":1.55,"tv":91.93,"id":19587212},{"trd":[[1.55,91.93]],"ltp":1.55,"tv":92.21,"id":19587555}],"tv":184.14}]}
{"op":"mcm","clk":"11790605373","pt":1723039808940,"mc":[{"id":"1.231541189","rc":[{"batb":[[0,1.61,14.15],[1,1.6,5],[2,1.26,20]],"ltp":1.55,"tv":91.93,"id":19587212},{"batb":[[0,1.32,26.96],[1,1.31,10],[2,1.3,11.86]],"ltp":1.55,"tv":92.21,"id":19587555}]}]}
{"op":"mcm","clk":"11790615434","pt":1723039959691,"mc":[{"id":"1.231541189","rc":[{"batb":[[0,1.62,5],[1,1.61,14.15]],"ltp":1.55,"tv":91.93,"id":19587212},{"batb":[[0,1.33,10],[1,1.32,26.96]],"ltp":1.55,"tv":92.21,"id":19587555}]}]}
{"op":"mcm","clk":"11790728298","pt":1723041609320,"mc":[{"id":"1.231541189","rc":[{"batb":[[1,1.26,20],[2,1.25,15]],"ltp":1.55,"tv":91.93,"id":19587212},{"batb":[[1,1.3,11.86],[2,1.02,201.57]],"ltp":1.55,"tv":92.21,"id":19587555}]}]}
{"op":"mcm","clk":"11790733476","pt":1723041665906,"mc":[{"id":"1.231541189","rc":[{"batb":[[0,1.63,13.7],[1,1.62,5],[2,1.26,20]],"ltp":1.55,"tv":91.93,"id":19587212},{"batb":[[0,1.34,25.38],[1,1.33,10],[2,1.3,11.86]],"ltp":1.55,"tv":92.21,"id":19587555}]}]}
{"op":"mcm","clk":"11790757307","pt":1723041837472,"mc":[{"id":"1.231541189","rc":[{"batb":[[1,1.26,20],[2,1.25,15]],"ltp":1.55,"tv":91.93,"id":19587212},{"batb":[[1,1.3,11.86],[2,1.02,201.57]],"ltp":1.55,"tv":92.21,"id":19587555}]}]}
{"op":"mcm","clk":"11790757317","pt":1723041837576,"mc":[{"id":"1.231541189","rc":[{"batb":[[0,1.64,5],[1,1.63,13.7],[2,1.26,20]],"ltp":1.55,"tv":91.93,"id":19587212},{"batb":[[0,1.35,10],[1,1.34,25.38],[2,1.3,11.86]],"ltp":1.55,"tv":92.21,"id":19587555}]}]}
{"op":"mcm","clk":"11790911526","pt":1723043468091,"mc":[{"id":"1.231541189","rc":[{"trd":[[1.55,91.87]],"batb":[[1,1.26,20],[2,1.25,15]],"ltp":1.55,"tv":91.87,"id":19587212},{"trd":[[1.55,91.87]],"batb":[[1,1.3,11.86],[2,1.02,201.57]],"ltp":1.55,"tv":92.15,"id":19587555}],"tv":184.02}]}
{"op":"mcm","clk":"11790915970","pt":1723043514676,"mc":[{"id":"1.231541189","rc":[{"batb":[[0,1.65,13.29],[1,1.64,5],[2,1.26,20]],"ltp":1.55,"tv":91.87,"id":19587212},{"batb":[[0,1.36,23.99],[1,1.35,10],[2,1.3,11.86]],"ltp":1.55,"tv":92.15,"id":19587555}]}]}
{"op":"mcm","clk":"11790955572","pt":1723043908961,"mc":[{"id":"1.231541189","rc":[{"batb":[[0,1.66,5],[1,1.65,13.29]],"ltp":1.55,"tv":91.87,"id":19587212},{"batb":[[0,1.37,10],[1,1.36,23.99]],"ltp":1.55,"tv":92.15,"id":19587555}]}]}
{"op":"mcm","clk":"11790974375","pt":1723044091259,"mc":[{"id":"1.231541189","rc":[{"batb":[[0,1.4,10.95],[1,1.37,10],[2,1.36,23.99]],"ltp":1.55,"tv":92.15,"id":19587555}]}]}
{"op":"mcm","clk":"11790996528","pt":1723044320121,"mc":[{"id":"1.231541189","rc":[{"trd":[[1.4,0.14]],"batb":[[0,1.4,10.88]],"ltp":1.4,"tv":92.29,"id":19587555}],"tv":184.16}]}
{"op":"mcm","clk":"11791093258","pt":1723045315457,"mc":[{"id":"1.231541189","rc":[{"batb":[[1,1.26,20],[2,1.25,15]],"ltp":1.55,"tv":91.87,"id":19587212},{"batb":[[2,1.3,11.86]],"ltp":1.4,"tv":92.29,"id":19587555}]}]}
{"op":"mcm","clk":"11791098586","pt":1723045361442,"mc":[{"id":"1.231541189","rc":[{"batb":[[0,1.67,12.89],[1,1.66,5],[2,1.26,20]],"ltp":1.55,"tv":91.87,"id":19587212},{"batb":[[0,1.41,21.06],[1,1.4,10.88],[2,1.37,10]],"ltp":1.4,"tv":92.29,"id":19587555}]}]}
{"op":"mcm","clk":"11791149775","pt":1723045928453,"mc":[{"id":"1.231541189","rc":[{"batb":[[0,1.68,5],[1,1.67,12.89]],"ltp":1.55,"tv":91.87,"id":19587212}]}]}
{"op":"mcm","clk":"11791231297","pt":1723046844380,"mc":[{"id":"1.231541189","rc":[{"trd":[[1.55,91.92]],"batb":[[1,1.67,12.89]],"ltp":1.55,"tv":91.92,"id":19587212},{"trd":[[1.55,91.92]],"batb":[[0,1.41,21.06],[1,1.4,10.89]],"ltp":1.4,"tv":92.34,"id":19587555}],"tv":184.26}]}
{"op":"mcm","clk":"11791244899","pt":1723047003467,"mc":[{"id":"1.231541189","rc":[{"batb":[[2,1.28,178.57]],"ltp":1.55,"tv":91.92,"id":19587212}]}]}
{"op":"mcm","clk":"11791244933","pt":1723047003881,"mc":[{"id":"1.231541189","rc":[{"batb":[[2,1.53,94.34]],"ltp":1.55,"tv":91.92,"id":19587212},{"batb":[[0,1.53,94.34],[1,1.48,104.17],[2,1.43,116.28]],"ltp":1.4,"tv":92.34,"id":19587555}]}]}
{"op":"mcm","clk":"11791245155","pt":1723047005867,"mc":[{"id":"1.231541189","rc":[{"batb":[[0,1.48,104.17],[1,1.43,116.28],[2,1.41,21.06]],"ltp":1.4,"tv":92.34,"id":19587555}]}]}
{"op":"mcm","clk":"11791245234","pt":1723047006749,"mc":[{"id":"1.231541189","rc":[{"batb":[[0,1.43,116.28],[1,1.41,21.06],[2,1.4,10.89]],"ltp":1.4,"tv":92.34,"id":19587555}]}]}
{"op":"mcm","clk":"11791245380","pt":1723047008261,"mc":[{"id":"1.231541189","rc":[{"batb":[[0,1.41,21.06],[1,1.4,10.89],[2,1.38,131.58]],"ltp":1.4,"tv":92.34,"id":19587555}]}]}
{"op":"mcm","clk":"11791253042","pt":1723047084905,"mc":[{"id":"1.231541189","rc":[{"batb":[[2,1.37,10]],"ltp":1.4,"tv":92.34,"id":19587555}]}]}
{"op":"mcm","clk":"11791256385","pt":1723047118724,"mc":[{"id":"1.231541189","rc":[{"batb":[[2,1.63,79.37]],"ltp":1.55,"tv":91.92,"id":19587212}]}]}
{"op":"mcm","clk":"11791256496","pt":1723047119821,"mc":[{"id":"1.231541189","rc":[{"batb":[[0,1.73,68.49],[1,1.68,5],[2,1.67,12.89]],"ltp":1.55,"tv":91.92,"id":19587212}]}]}
{"op":"mcm","clk":"11791256580","pt":1723047120925,"mc":[{"id":"1.231541189","rc":[{"batb":[[0,1.83,60.24],[1,1.73,68.49],[2,1.68,5]],"ltp":1.55,"tv":91.92,"id":19587212}]}]}
{"op":"mcm","clk":"11791256926","pt":1723047124667,"mc":[{"id":"1.231541189","rc":[{"batb":[[0,2,50],[1,1.83,60.24],[2,1.73,68.49]],"ltp":1.55,"tv":91.92,"id":19587212}]}]}
{"op":"mcm","clk":"11791258792","pt":1723047144394,"mc":[{"id":"1.231541189","rc":[{"batb":[[0,1.83,60.24],[1,1.73,68.49],[2,1.68,5]],"ltp":1.55,"tv":91.92,"id":19587212}]}]}
{"op":"mcm","clk":"11791258880","pt":1723047145287,"mc":[{"id":"1.231541189","rc":[{"batb":[[0,1.93,53.76],[1,1.83,60.24],[2,1.73,68.49]],"ltp":1.55,"tv":91.92,"id":19587212}]}]}
{"op":"mcm","clk":"11791260530","pt":1723047162092,"mc":[{"id":"1.231541189","rc":[{"batb":[[0,1.4,10.89],[1,1.37,10],[2,1.33,151.52]],"ltp":1.4,"tv":92.34,"id":19587555}]}]}
{"op":"mcm","clk":"11791260688","pt":1723047163613,"mc":[{"id":"1.231541189","rc":[{"batb":[[2,1.3,11.86]],"ltp":1.4,"tv":92.34,"id":19587555}]}]}
{"op":"mcm","clk":"11791305128","pt":1723047494211,"mc":[{"id":"1.231541189","rc":[{"batb":[[0,1.44,7.54],[1,1.4,10.89],[2,1.37,10]],"ltp":1.4,"tv":92.34,"id":19587555}]}]}
{"op":"mcm","clk":"11791306929","pt":1723047511012,"mc":[{"id":"1.231541189","rc":[{"batb":[[0,1.46,4],[1,1.44,7.54],[2,1.4,10.89]],"ltp":1.4,"tv":92.34,"id":19587555}]}]}
{"op":"mcm","clk":"11791308562","pt":1723047527081,"mc":[{"id":"1.231541189","rc":[{"batb":[[1,1.4,10.89],[2,1.38,7.54]],"ltp":1.4,"tv":92.34,"id":19587555}]}]}
{"op":"mcm","clk":"11791309467","pt":1723047535293,"mc":[{"id":"1.231541189","rc":[{"batb":[[0,1.4,10.89],[1,1.39,4]],"ltp":1.4,"tv":92.34,"id":19587555}]}]}
{"op":"mcm","clk":"11791311344","pt":1723047554109,"mc":[{"id":"1.231541189","rc":[{"batb":[[0,1.41,4],[1,1.4,10.89]],"ltp":1.4,"tv":92.34,"id":19587555}]}]}
{"op":"mcm","clk":"11791333309","pt":1723047767011,"mc":[{"id":"1.231541189","rc":[{"batb":[[0,2,5],[1,1.93,53.76],[2,1.83,60.24]],"ltp":1.55,"tv":91.92,"id":19587212}]}]}
{"op":"mcm","clk":"11791350419","pt":1723047965087,"mc":[{"id":"1.231541189","rc":[{"batb":[[1,1.94,7.49],[2,1.93,53.76]],"ltp":1.55,"tv":91.92,"id":19587212}]}]}
{"op":"mcm","clk":"11791412611","pt":1723048624051,"mc":[{"id":"1.231541189","rc":[{"batb":[[0,2.02,10],[1,2,5],[2,1.94,7.49]],"batl":[[0,2.2,45.67]],"ltp":1.55,"tv":91.92,"id":19587212}]}]}
{"op":"mcm","clk":"11791412976","pt":1723048627375,"mc":[{"id":"1.231541189","rc":[{"batb":[[0,2,5],[1,1.94,7.49],[2,1.93,53.76]],"ltp":1.55,"tv":91.92,"id":19587212}]}]}
{"op":"mcm","clk":"11791413989","pt":1723048637068,"mc":[{"id":"1.231541189","rc":[{"batb":[[0,2.02,10],[1,2,5],[2,1.94,7.49]],"batl":[[0,2.2,91.33]],"ltp":1.55,"tv":91.92,"id":19587212}]}]}
{"op":"mcm","clk":"11791414334","pt":1723048640196,"mc":[{"id":"1.231541189","rc":[{"batb":[[0,2,5],[1,1.94,7.49],[2,1.93,53.76]],"ltp":1.55,"tv":91.92,"id":19587212}]}]}
{"op":"mcm","clk":"11791415675","pt":1723048653888,"mc":[{"id":"1.231541189","rc":[{"trd":[[2.2,182.45]],"batb":[[0,2.02,10],[1,2,5],[2,1.94,7.49]],"batl":[[0,2.2,0.11]],"ltp":2.2,"tv":274.36,"id":19587212}],"tv":366.71}]}
{"op":"mcm","clk":"11791416049","pt":1723048657225,"mc":[{"id":"1.231541189","rc":[{"batb":[[0,2,5],[1,1.94,7.49],[2,1.93,53.76]],"ltp":2.2,"tv":274.36,"id":19587212}]}]}
{"op":"mcm","clk":"11791419167","pt":1723048685192,"mc":[{"id":"1.231541189","rc":[{"batb":[[0,2.02,10],[1,2,5],[2,1.94,7.49]],"batl":[[0,2.2,91.22]],"ltp":2.2,"tv":274.36,"id":19587212}]}]}
{"op":"mcm","clk":"11791419521","pt":1723048688485,"mc":[{"id":"1.231541189","rc":[{"batb":[[0,2,5],[1,1.94,7.49],[2,1.93,53.76]],"ltp":2.2,"tv":274.36,"id":19587212}]}]}
{"op":"mcm","clk":"11791419835","pt":1723048691286,"mc":[{"id":"1.231541189","rc":[{"trd":[[2.2,273.78]],"batb":[[0,2.02,10],[1,2,5],[2,1.94,7.49]],"batl":[[0,2.2,45.56]],"ltp":2.2,"tv":365.7,"id":19587212}],"tv":458.04}]}
{"op":"mcm","clk":"11791420037","pt":1723048692990,"mc":[{"id":"1.231541189","rc":[{"trd":[[2.2,364.89]],"batb":[[0,2.02,10.11]],"ltp":2.2,"tv":456.81,"id":19587212}],"tv":549.15}]}
{"op":"mcm","clk":"11791420217","pt":1723048694597,"mc":[{"id":"1.231541189","rc":[{"batb":[[0,2,5.11],[1,1.94,7.49],[2,1.93,53.76]],"ltp":2.2,"tv":456.81,"id":19587212}]}]}
{"op":"mcm","clk":"11791421230","pt":1723048703988,"mc":[{"id":"1.231541189","rc":[{"batb":[[0,2,5]],"ltp":2.2,"tv":456.81,"id":19587212}]}]}
{"op":"mcm","clk":"11791430338","pt":1723048795018,"mc":[{"id":"1.231541189","rc":[{"trd":[[1.41,0.34]],"batb":[[0,1.41,3.83]],"ltp":1.41,"tv":92.68,"id":19587555}],"tv":549.5}]}
{"op":"mcm","clk":"11791430882","pt":1723048801016,"mc":[{"id":"1.231541189","rc":[{"trd":[[2,0.12]],"batb":[[0,2,4.88]],"ltp":2.0,"tv":456.93,"id":19587212},{"trd":[[2,0.12]],"ltp":2.0,"tv":92.8,"id":19587555}],"tv":549.74}]}
{"op":"mcm","clk":"11791447466","pt":1723048989265,"mc":[{"id":"1.231541189","rc":[{"batb":[[0,1.41,14.72],[1,1.38,7.54],[2,1.37,10]],"ltp":2.0,"tv":92.8,"id":19587555}]}]}
{"op":"mcm","clk":"11791692179","pt":1723051120319,"mc":[{"id":"1.231541189","rc":[{"trd":[[1.55,91.99],[2.2,365.15]],"batb":[[1,1.94,7.5]],"ltp":2.0,"tv":457.26,"id":19587212},{"trd":[[1.55,91.99]],"batb":[[0,1.42,10],[1,1.41,14.73],[2,1.38,7.54]],"batl":[[0,2.06,4.64]],"ltp":2.0,"tv":92.87,"id":19587555}],"tv":550.13}]}
{"op":"mcm","clk":"11791692648","pt":1723051123597,"mc":[{"id":"1.231541189","rc":[{"batb":[[0,1.41,14.73],[1,1.38,7.54],[2,1.37,10]],"ltp":2.0,"tv":92.87,"id":19587555}]}]}
{"op":"mcm","clk":"11791699467","pt":1723051172464,"mc":[{"id":"1.231541189","rc":[{"batb":[[0,1.42,10],[1,1.41,14.73],[2,1.38,7.54]],"batl":[[0,2.06,4.64]],"ltp":2.0,"tv":92.87,"id":19587555}]}]}
{"op":"mcm","clk":"11791699997","pt":1723051175854,"mc":[{"id":"1.231541189","rc":[{"batb":[[0,1.41,14.73],[1,1.38,7.54],[2,1.37,10]],"ltp":2.0,"tv":92.87,"id":19587555}]}]}
{"op":"mcm","clk":"11791707059","pt":1723051227722,"mc":[{"id":"1.231541189","rc":[{"batb":[[0,1.42,10],[1,1.41,14.73],[2,1.38,7.54]],"batl":[[0,2.06,4.64]],"ltp":2.0,"tv":92.87,"id":19587555}]}]}
{"op":"mcm","clk":"11791707487","pt":1723051231161,"mc":[{"id":"1.231541189","rc":[{"batb":[[0,1.41,14.73],[1,1.38,7.54],[2,1.37,10]],"ltp":2.0,"tv":92.87,"id":19587555}]}]}
{"op":"mcm","clk":"11791714551","pt":1723051282195,"mc":[{"id":"1.231541189","rc":[{"batb":[[0,1.42,10],[1,1.41,14.73],[2,1.38,7.54]],"batl":[[0,2.06,4.64]],"ltp":2.0,"tv":92.87,"id":19587555}]}]}
{"op":"mcm","clk":"11791715135","pt":1723051285608,"mc":[{"id":"1.231541189","rc":[{"batb":[[0,1.41,14.73],[1,1.38,7.54],[2,1.37,10]],"ltp":2.0,"tv":92.87,"id":19587555}]}]}
{"op":"mcm","clk":"11791722252","pt":1723051335535,"mc":[{"id":"1.231541189","rc":[{"batl":[[0,2.06,4.64]],"ltp":2.0,"tv":92.87,"id":19587555}]}]}
{"op":"mcm","clk":"11791722343","pt":1723051336285,"mc":[{"id":"1.231541189","rc":[{"batb":[[0,1.42,10],[1,1.41,14.73],[2,1.38,7.54]],"ltp":2.0,"tv":92.87,"id":19587555}]}]}
{"op":"mcm","clk":"11791722726","pt":1723051338963,"mc":[{"id":"1.231541189","rc":[{"batb":[[0,1.41,14.73],[1,1.38,7.54],[2,1.37,10]],"ltp":2.0,"tv":92.87,"id":19587555}]}]}
{"op":"mcm","clk":"11791730098","pt":1723051389510,"mc":[{"id":"1.231541189","rc":[{"batb":[[0,1.42,10],[1,1.41,14.73],[2,1.38,7.54]],"batl":[[0,2.06,4.64]],"ltp":2.0,"tv":92.87,"id":19587555}]}]}
{"op":"mcm","clk":"11791730545","pt":1723051392823,"mc":[{"id":"1.231541189","rc":[{"batb":[[0,1.41,14.73],[1,1.38,7.54],[2,1.37,10]],"ltp":2.0,"tv":92.87,"id":19587555}]}]}
{"op":"mcm","clk":"11791737786","pt":1723051443689,"mc":[{"id":"1.231541189","rc":[{"batb":[[0,1.42,10],[1,1.41,14.73],[2,1.38,7.54]],"batl":[[0,2.06,4.64]],"ltp":2.0,"tv":92.87,"id":19587555}]}]}
{"op":"mcm","clk":"11791738220","pt":1723051446983,"mc":[{"id":"1.231541189","rc":[{"batb":[[0,1.41,14.73],[1,1.38,7.54],[2,1.37,10]],"ltp":2.0,"tv":92.87,"id":19587555}]}]}
{"op":"mcm","clk":"11791745403","pt":1723051496854,"mc":[{"id":"1.231541189","rc":[{"batb":[[0,1.42,10],[1,1.41,14.73],[2,1.38,7.54]],"batl":[[0,2.06,4.64]],"ltp":2.0,"tv":92.87,"id":19587555}]}]}
{"op":"mcm","clk":"11791745891","pt":1723051500149,"mc":[{"id":"1.231541189","rc":[{"batb":[[0,1.41,14.73],[1,1.38,7.54],[2,1.37,10]],"ltp":2.0,"tv":92.87,"id":19587555}]}]}
{"op":"mcm","clk":"11791753510","pt":1723051549497,"mc":[{"id":"1.231541189","rc":[{"batl":[[0,2.06,4.64]],"ltp":2.0,"tv":92.87,"id":19587555}]}]}
{"op":"mcm","clk":"11791753569","pt":1723051549971,"mc":[{"id":"1.231541189","rc":[{"batb":[[0,1.42,10],[1,1.41,14.73],[2,1.38,7.54]],"ltp":2.0,"tv":92.87,"id":19587555}]}]}
{"op":"mcm","clk":"11791753968","pt":1723051552898,"mc":[{"id":"1.231541189","rc":[{"batb":[[0,1.41,14.73],[1,1.38,7.54],[2,1.37,10]],"ltp":2.0,"tv":92.87,"id":19587555}]}]}
{"op":"mcm","clk":"11791755314","pt":1723051562077,"mc":[{"id":"1.231541189","rc":[{"batl":[[0,1.89,0.99]],"ltp":2.0,"tv":92.87,"id":19587555}]}]}
{"op":"mcm","clk":"11791761145","pt":1723051602037,"mc":[{"id":"1.231541189","rc":[{"batb":[[0,1.42,10],[1,1.41,14.73],[2,1.38,7.54]],"batl":[[0,2.06,5.7]],"ltp":2.0,"tv":92.87,"id":19587555}]}]}
{"op":"mcm","clk":"11791761605","pt":1723051605333,"mc":[{"id":"1.231541189","rc":[{"batb":[[0,1.41,14.73],[1,1.38,7.54],[2,1.37,10]],"batl":[[0,1.89,0.99]],"ltp":2.0,"tv":92.87,"id":19587555}]}]}
{"op":"mcm","clk":"11791761936","pt":1723051607571,"mc":[{"id":"1.231541189","rc":[{"batl":[[0,1.8,180],[1,1.89,0.99]],"ltp":2.0,"tv":92.87,"id":19587555}]}]}
{"op":"mcm","clk":"11791765960","pt":1723051635567,"mc":[{"id":"1.231541189","rc":[{"batl":[[0,1.78,27.05],[1,1.8,180],[2,1.89,0.99]],"ltp":2.0,"tv":92.87,"id":19587555}]}]}
{"op":"mcm","clk":"11791795161","pt":1723051821977,"mc":[{"id":"1.231541189","rc":[{"batl":[[0,1.76,27.05]],"ltp":2.0,"tv":92.87,"id":19587555}]}]}
{"op":"mcm","clk":"11791860837","pt":1723052239219,"mc":[{"id":"1.231541189","rc":[{"batl":[[0,1.76,28.04],[2,1.89,0]],"ltp":2.0,"tv":92.87,"id":19587555}]}]}
{"op":"mcm","clk":"11791876248","pt":1723052341203,"mc":[{"id":"1.231541189","rc":[{"batl":[[0,1.8,180.99],[1,1.8,0]],"ltp":2.0,"tv":92.87,"id":19587555}]}]}
{"op":"mcm","clk":"11791876463","pt":1723052342730,"mc":[{"id":"1.231541189","rc":[{"batb":[[0,2.26,10.92],[1,2,4.88],[2,1.94,7.5]],"ltp":2.0,"tv":457.26,"id":19587212},{"batl":[[0,1.79,14.58],[1,1.8,180]],"ltp":2.0,"tv":92.87,"id":19587555}]}]}
{"op":"mcm","clk":"11791877850","pt":1723052352302,"mc":[{"id":"1.231541189","rc":[{"batb":[[0,2,4.88],[1,1.94,7.5],[2,1.93,53.76]],"ltp":2.0,"tv":457.26,"id":19587212},{"batl":[[0,1.74,19.03]],"ltp":2.0,"tv":92.87,"id":19587555}]}]}
{"op":"mcm","clk":"11791882967","pt":1723052386767,"mc":[{"id":"1.231541189","rc":[{"batb":[[0,1.42,3],[1,1.41,14.73],[2,1.38,7.54]],"ltp":2.0,"tv":92.87,"id":19587555}]}]}
{"op":"mcm","clk":"11791903899","pt":1723052527378,"mc":[{"id":"1.231541189","rc":[{"batb":[[0,2.26,7.5],[1,2,4.88]],"ltp":2.0,"tv":457.26,"id":19587212}]}]}
{"op":"mcm","clk":"11791920231","pt":1723052578005,"mc":[{"id":"1.231541189","rc":[{"batl":[[0,1.8,180.99],[1,1.8,0]],"ltp":2.0,"tv":92.87,"id":19587555}]}]}
{"op":"mcm","clk":"11791920372","pt":1723052578905,"mc":[{"id":"1.231541189","rc":[{"batb":[[0,2.26,18.97]],"ltp":2.0,"tv":457.26,"id":19587212},{"batl":[[0,1.79,15.29],[1,1.8,180]],"ltp":2.0,"tv":92.87,"id":19587555}]}]}
{"op":"mcm","clk":"11791921516","pt":1723052585627,"mc":[{"id":"1.231541189","rc":[{"batl":[[0,1.79,25.3]],"ltp":2.0,"tv":92.87,"id":19587555}]}]}
{"op":"mcm","clk":"11791963348","pt":1723052853686,"mc":[{"id":"1.231541189","rc":[{"batl":[[0,1.79,24.31]],"ltp":2.0,"tv":92.87,"id":19587555}]}]}
{"op":"mcm","clk":"11791970476","pt":1723052902374,"mc":[{"id":"1.231541189","rc":[{"batl":[[0,1.78,45],[1,1.79,24.31],[2,1.8,180]],"ltp":2.0,"tv":92.87,"id":19587555}]}]}
{"op":"mcm","clk":"11791970831","pt":1723052904879,"mc":[{"id":"1.231541189","rc":[{"batl":[[1,1.79,14.3]],"ltp":2.0,"tv":92.87,"id":19587555}]}]}
{"op":"mcm","clk":"11791971040","pt":1723052906193,"mc":[{"id":"1.231541189","rc":[{"batb":[[0,2.26,7.5]],"ltp":2.0,"tv":457.26,"id":19587212},{"batl":[[1,1.8,180],[2,1.8,0]],"ltp":2.0,"tv":92.87,"id":19587555}]}]}
{"op":"mcm","clk":"11791974451","pt":1723052930081,"mc":[{"id":"1.231541189","rc":[{"batb":[[0,1.43,90],[1,1.42,3],[2,1.41,14.73]],"ltp":2.0,"tv":92.87,"id":19587555}]}]}
{"op":"mcm","clk":"11791988830","pt":1723053029792,"mc":[{"id":"1.231541189","rc":[{"batl":[[0,1.73,18.04],[1,1.78,45],[2,1.8,180]],"ltp":2.0,"tv":92.87,"id":19587555}]}]}
{"op":"mcm","clk":"11791994500","pt":1723053073431,"mc":[{"id":"1.231541189","rc":[{"batl":[[1,1.8,180],[2,1.8,0]],"ltp":2.0,"tv":92.87,"id":19587555}]}]}
{"op":"mcm","clk":"11791994527","pt":1723053073637,"mc":[{"id":"1.231541189","rc":[{"batb":[[0,1.42,3],[1,1.41,14.73],[2,1.38,7.54]],"ltp":2.0,"tv":92.87,"id":19587555}]}]}
{"op":"mcm","clk":"11791995355","pt":1723053080116,"mc":[{"id":"1.231541189","rc":[{"batb":[[0,1.44,3]],"ltp":2.0,"tv":92.87,"id":19587555}]}]}
{"op":"mcm","clk":"11792003980","pt":1723053143317,"mc":[{"id":"1.231541189","rc":[{"batl":[[1,1.8,0]],"ltp":2.0,"tv":92.87,"id":19587555}]}]}
{"op":"mcm","clk":"11792078612","pt":1723053697289,"mc":[{"id":"1.231541189","rc":[{"trd":[[1.55,92.08],[2.2,365.5]],"batb":[[0,2.26,7.51]],"ltp":2.0,"tv":457.7,"id":19587212},{"trd":[[1.55,92.08]],"batb":[[1,1.41,14.74],[2,1.38,7.55]],"ltp":2.0,"tv":92.96,"id":19587555}],"tv":550.66}]}
{"op":"mcm","clk":"11792084316","pt":1723053734508,"mc":[{"id":"1.231541189","rc":[{"batb":[[0,1.42,3]],"ltp":2.0,"tv":92.96,"id":19587555}]}]}
{"op":"mcm","clk":"11792085922","pt":1723053744851,"mc":[{"id":"1.231541189","rc":[{"batb":[[0,2.28,4.88],[1,2.26,7.51]],"ltp":2.0,"tv":457.7,"id":19587212}]}]}
{"op":"mcm","clk":"11792136494","pt":1723054039489,"mc":[{"id":"1.231541189","rc":[{"batb":[[1,1.94,7.51]],"ltp":2.0,"tv":457.7,"id":19587212}]}]}
{"op":"mcm","clk":"11792187438","pt":1723054310546,"mc":[{"id":"1.231541189","rc":[{"batl":[[0,2.06,4.74]],"ltp":2.0,"tv":92.96,"id":19587555}]}]}
{"op":"mcm","clk":"11792194548","pt":1723054351980,"mc":[{"id":"1.231541189","rc":[{"batl":[[0,1.78,178.4]],"ltp":2.0,"tv":92.96,"id":19587555}]}]}
{"op":"mcm","clk":"11792198535","pt":1723054373838,"mc":[{"id":"1.231541189","rc":[{"trd":[[1.78,356.05]],"batl":[[0,1.78,0.38]],"ltp":1.78,"tv":449.0,"id":19587555}],"tv":906.7}]}
{"op":"mcm","clk":"11792204358","pt":1723054405482,"mc":[{"id":"1.231541189","rc":[{"batl":[[0,1.79,178.4]],"ltp":1.78,"tv":449.0,"id":19587555}]}]}
{"op":"mcm","clk":"11792207457","pt":1723054422016,"mc":[{"id":"1.231541189","rc":[{"batl":[[0,1.78,178.4]],"ltp":1.78,"tv":449.0,"id":19587555}]}]}
{"op":"mcm","clk":"11792210128","pt":1723054437014,"mc":[{"id":"1.231541189","rc":[{"batl":[[0,1.78,178.02]],"ltp":1.78,"tv":449.0,"id":19587555}]}]}
{"op":"mcm","clk":"11792212919","pt":1723054452954,"mc":[{"id":"1.231541189","rc":[{"trd":[[1.78,712.09]],"batb":[[0,1.42,3.38]],"ltp":1.78,"tv":805.05,"id":19587555}],"tv":1262.75}]}
{"op":"mcm","clk":"11792214330","pt":1723054460972,"mc":[{"id":"1.231541189","rc":[{"batb":[[0,1.42,3]],"ltp":1.78,"tv":805.05,"id":19587555}]}]}
{"op":"mcm","clk":"11792220850","pt":1723054502446,"mc":[{"id":"1.231541189","rc":[{"batb":[[0,1.42,14.27],[1,1.41,3.84]],"ltp":1.78,"tv":805.05,"id":19587555}]}]}
{"op":"mcm","clk":"11792247490","pt":1723054665133,"mc":[{"id":"1.231541189","rc":[{"batb":[[0,1.43,10],[1,1.42,14.27],[2,1.41,3.84]],"batl":[[0,2.06,4.74]],"ltp":1.78,"tv":805.05,"id":19587555}]}]}
{"op":"mcm","clk":"11792248090","pt":1723054668447,"mc":[{"id":"1.231541189","rc":[{"batb":[[0,1.42,14.27],[1,1.41,3.84],[2,1.38,7.55]],"ltp":1.78,"tv":805.05,"id":19587555}]}]}
{"op":"mcm","clk":"11792251645","pt":1723054689965,"mc":[{"id":"1.231541189","rc":[{"batl":[[0,1.78,64.04]],"ltp":1.78,"tv":805.05,"id":19587555}]}]}
{"op":"mcm","clk":"11792251946","pt":1723054691991,"mc":[{"id":"1.231541189","rc":[{"batl":[[0,1.78,242.44]],"ltp":1.78,"tv":805.05,"id":19587555}]}]}
{"op":"mcm","clk":"11792252093","pt":1723054692978,"mc":[{"id":"1.231541189","rc":[{"batb":[[0,2.3,13.45],[1,2.28,4.88],[2,1.94,7.51]],"ltp":2.0,"tv":457.7,"id":19587212}]}]}
{"op":"mcm","clk":"11792263847","pt":1723054766471,"mc":[{"id":"1.231541189","rc":[{"batl":[[0,1.76,242.44]],"ltp":1.78,"tv":805.05,"id":19587555}]}]}
{"op":"mcm","clk":"11792265852","pt":1723054778564,"mc":[{"id":"1.231541189","rc":[{"trd":[[1.76,483.65]],"batl":[[0,1.76,0.62]],"ltp":1.76,"tv":1288.7,"id":19587555}],"tv":1746.4}]}
{"op":"mcm","clk":"11792266083","pt":1723054779970,"mc":[{"id":"1.231541189","rc":[{"batb":[[0,2.28,4.88],[1,1.94,7.51],[2,1.93,53.76]],"ltp":2.0,"tv":457.7,"id":19587212}]}]}
{"op":"mcm","clk":"11792271375","pt":1723054813349,"mc":[{"id":"1.231541189","rc":[{"batb":[[0,1.43,10],[1,1.42,14.27],[2,1.41,3.84]],"batl":[[0,2.06,5.4]],"ltp":1.76,"tv":1288.7,"id":19587555}]}]}
{"op":"mcm","clk":"11792271679","pt":1723054815132,"mc":[{"id":"1.231541189","rc":[{"batl":[[0,1.76,0.62]],"ltp":1.76,"tv":1288.7,"id":19587555}]}]}
{"op":"mcm","clk":"11792271923","pt":1723054816602,"mc":[{"id":"1.231541189","rc":[{"batb":[[0,1.42,14.27],[1,1.41,3.84],[2,1.38,7.55]],"ltp":1.76,"tv":1288.7,"id":19587555}]}]}
{"op":"mcm","clk":"11792276404","pt":1723054842937,"mc":[{"id":"1.231541189","rc":[{"batl":[[0,1.76,242.44]],"ltp":1.76,"tv":1288.7,"id":19587555}]}]}
{"op":"mcm","clk":"11792277285","pt":1723054848223,"mc":[{"id":"1.231541189","rc":[{"trd":[[1.76,967.31]],"ltp":1.76,"tv":1772.36,"id":19587555}],"tv":2230.06}]}
{"op":"mcm","clk":"11792282795","pt":1723054880357,"mc":[{"id":"1.231541189","rc":[{"batl":[[0,2.06,4.74]],"ltp":1.76,"tv":1772.36,"id":19587555}]}]}
{"op":"mcm","clk":"11792282822","pt":1723054880565,"mc":[{"id":"1.231541189","rc":[{"batb":[[0,1.43,10],[1,1.42,14.27],[2,1.41,3.84]],"ltp":1.76,"tv":1772.36,"id":19587555}]}]}
{"op":"mcm","clk":"11792283373","pt":1723054883877,"mc":[{"id":"1.231541189","rc":[{"batb":[[0,1.42,14.27],[1,1.41,3.84],[2,1.38,7.55]],"ltp":1.76,"tv":1772.36,"id":19587555}]}]}
{"op":"mcm","clk":"11792291864","pt":1723054936139,"mc":[{"id":"1.231541189","rc":[{"batb":[[0,1.43,10],[1,1.42,14.27],[2,1.41,3.84]],"batl":[[0,2.06,4.74]],"ltp":1.76,"tv":1772.36,"id":19587555}]}]}
{"op":"mcm","clk":"11792292388","pt":1723054939479,"mc":[{"id":"1.231541189","rc":[{"batb":[[0,1.42,14.27],[1,1.41,3.84],[2,1.38,7.55]],"ltp":1.76,"tv":1772.36,"id":19587555}]}]}
{"op":"mcm","clk":"11792300547","pt":1723054985995,"mc":[{"id":"1.231541189","rc":[{"batl":[[0,1.78,242.44]],"ltp":1.76,"tv":1772.36,"id":19587555}]}]}
{"op":"mcm","clk":"11792301860","pt":1723054993382,"mc":[{"id":"1.231541189","rc":[{"trd":[[1.78,1195.75]],"batl":[[0,1.78,0.62]],"ltp":1.78,"tv":2256.01,"id":19587555}],"tv":2713.71}]}
{"op":"mcm","clk":"11792307390","pt":1723055025441,"mc":[{"id":"1.231541189","rc":[{"batb":[[0,1.43,10],[1,1.42,14.27],[2,1.41,3.84]],"batl":[[0,2.06,4.74]],"ltp":1.78,"tv":2256.01,"id":19587555}]}]}
{"op":"mcm","clk":"11792308024","pt":1723055029048,"mc":[{"id":"1.231541189","rc":[{"batb":[[0,1.42,14.27],[1,1.41,3.84],[2,1.38,7.55]],"ltp":1.78,"tv":2256.01,"id":19587555}]}]}
{"op":"mcm","clk":"11792309988","pt":1723055040080,"mc":[{"id":"1.231541189","rc":[{"batl":[[0,1.78,241.83]],"ltp":1.78,"tv":2256.01,"id":19587555}]}]}
{"op":"mcm","clk":"11792311306","pt":1723055046995,"mc":[{"id":"1.231541189","rc":[{"trd":[[1.78,1679.4]],"batb":[[0,1.42,14.89]],"ltp":1.78,"tv":2739.67,"id":19587555}],"tv":3197.37}]}
{"op":"mcm","clk":"11792315034","pt":1723055068497,"mc":[{"id":"1.231541189","rc":[{"batb":[[0,1.42,14.27]],"ltp":1.78,"tv":2739.67,"id":19587555}]}]}
{"op":"mcm","clk":"11792315055","pt":1723055068608,"mc":[{"id":"1.231541189","rc":[{"trd":[[2.28,0.96]],"batb":[[0,2.28,4.4]],"ltp":2.28,"tv":458.66,"id":19587212}],"tv":3198.33}]}
{"op":"mcm","clk":"11792316455","pt":1723055077197,"mc":[{"id":"1.231541189","rc":[{"trd":[[1.42,1.54]],"batb":[[0,1.42,13.5]],"ltp":1.42,"tv":2741.21,"id":19587555}],"tv":3199.87}]}
{"op":"mcm","clk":"11792316904","pt":1723055080032,"mc":[{"id":"1.231541189","rc":[{"batb":[[0,1.43,10],[1,1.42,13.5],[2,1.41,3.84]],"batl":[[0,2.06,4.69]],"ltp":1.42,"tv":2741.21,"id":19587555}]}]}
{"op":"mcm","clk":"11792317456","pt":1723055083428,"mc":[{"id":"1.231541189","rc":[{"batb":[[0,1.42,13.5],[1,1.41,3.84],[2,1.38,7.55]],"ltp":1.42,"tv":2741.21,"id":19587555}]}]}
{"op":"mcm","clk":"11792326257","pt":1723055134226,"mc":[{"id":"1.231541189","rc":[{"batb":[[0,1.43,10],[1,1.42,13.5],[2,1.41,3.84]],"batl":[[0,2.06,4.69]],"ltp":1.42,"tv":2741.21,"id":19587555}]}]}
{"op":"mcm","clk":"11792326584","pt":1723055136214,"mc":[{"id":"1.231541189","rc":[{"batl":[[0,1.76,178.4]],"ltp":1.42,"tv":2741.21,"id":19587555}]}]}
{"op":"mcm","clk":"11792326803","pt":1723055137524,"mc":[{"id":"1.231541189","rc":[{"batb":[[0,1.42,13.5],[1,1.41,3.84],[2,1.38,7.55]],"batl":[[0,1.76,242.44]],"ltp":1.42,"tv":2741.21,"id":19587555}]}]}
{"op":"mcm","clk":"11792328696","pt":1723055148974,"mc":[{"id":"1.231541189","rc":[{"trd":[[1.76,1450.96]],"batl":[[0,1.76,0.62]],"ltp":1.76,"tv":3224.86,"id":19587555}],"tv":3683.52}]}
{"op":"mcm","clk":"11792335011","pt":1723055186902,"mc":[{"id":"1.231541189","rc":[{"batl":[[0,1.76,241.83]],"ltp":1.76,"tv":3224.86,"id":19587555}]}]}
{"op":"mcm","clk":"11792336041","pt":1723055192994,"mc":[{"id":"1.231541189","rc":[{"trd":[[1.76,1934.62]],"batb":[[0,1.42,14.12]],"ltp":1.76,"tv":3708.51,"id":19587555}],"tv":4167.18}]}
{"op":"mcm","clk":"11792337778","pt":1723055203105,"mc":[{"id":"1.231541189","rc":[{"batb":[[0,1.42,13.5]],"ltp":1.76,"tv":3708.51,"id":19587555}]}]}
{"op":"mcm","clk":"11792341374","pt":1723055224430,"mc":[{"id":"1.231541189","rc":[{"batl":[[0,2.06,4.69]],"ltp":1.76,"tv":3708.51,"id":19587555}]}]}
{"op":"mcm","clk":"11792341402","pt":1723055224662,"mc":[{"id":"1.231541189","rc":[{"batb":[[0,1.43,10],[1,1.42,13.5],[2,1.41,3.84]],"ltp":1.76,"tv":3708.51,"id":19587555}]}]}
{"op":"mcm","clk":"11792341961","pt":1723055227946,"mc":[{"id":"1.231541189","rc":[{"batb":[[0,1.42,13.5],[1,1.41,3.84],[2,1.38,7.55]],"ltp":1.76,"tv":3708.51,"id":19587555}]}]}
{"op":"mcm","clk":"11792346640","pt":1723055257119,"mc":[{"id":"1.231541189","rc":[{"batl":[[0,1.78,45]],"ltp":1.76,"tv":3708.51,"id":19587555}]}]}
{"op":"mcm","clk":"11792366032","pt":1723055379990,"mc":[{"id":"1.231541189","rc":[{"batl":[[0,1.75,242.44],[1,1.78,45]],"ltp":1.76,"tv":3708.51,"id":19587555}]}]}
{"op":"mcm","clk":"11792366926","pt":1723055385783,"mc":[{"id":"1.231541189","rc":[{"trd":[[1.75,483.65]],"batl":[[0,1.78,45.62],[1,1.78,0]],"ltp":1.75,"tv":4192.17,"id":19587555}],"tv":4650.83}]}
{"op":"mcm","clk":"11792368016","pt":1723055393107,"mc":[{"id":"1.231541189","rc":[{"batl":[[0,1.78,45]],"ltp":1.75,"tv":4192.17,"id":19587555}]}]}
{"op":"mcm","clk":"11792373974","pt":1723055430143,"mc":[{"id":"1.231541189","rc":[{"batl":[[0,1.75,241.83],[1,1.78,45]],"ltp":1.75,"tv":4192.17,"id":19587555}]}]}
{"op":"mcm","clk":"11792374095","pt":1723055430868,"mc":[{"id":"1.231541189","rc":[{"batl":[[0,1.74,17.21],[1,1.75,241.83],[2,1.78,45]],"ltp":1.75,"tv":4192.17,"id":19587555}]}]}
{"op":"mcm","clk":"11792374745","pt":1723055434966,"mc":[{"id":"1.231541189","rc":[{"trd":[[1.74,34.41],[1.75,934.13]],"batl":[[0,1.75,16.59],[1,1.78,45],[2,1.78,0]],"ltp":1.75,"tv":4677.06,"id":19587555}],"tv":5135.72}]}
{"op":"mcm","clk":"11792376585","pt":1723055446684,"mc":[{"id":"1.231541189","rc":[{"batl":[[0,1.78,45],[1,1.78,0]],"ltp":1.75,"tv":4677.06,"id":19587555}]}]}
{"op":"mcm","clk":"11792377340","pt":1723055451989,"mc":[{"id":"1.231541189","rc":[{"trd":[[1.42,2.82]],"batb":[[0,1.42,12.86]],"ltp":1.42,"tv":4678.33,"id":19587555}],"tv":5136.99}]}
{"op":"mcm","clk":"11792377868","pt":1723055455374,"mc":[{"id":"1.231541189","rc":[{"trd":[[1.38,7.77],[1.41,8.02],[1.42,28.54]],"batb":[[0,1.38,3.67],[1,1.37,10],[2,1.3,11.86]],"ltp":1.38,"tv":4719.5,"id":19587555}],"tv":5178.16}]}
{"op":"mcm","clk":"11792389846","pt":1723055540852,"mc":[{"id":"1.231541189","rc":[{"batb":[[0,2.3,7.51],[1,2.28,4.4]],"ltp":2.28,"tv":458.66,"id":19587212}]}]}
{"op":"mcm","clk":"11792411036","pt":1723055680141,"mc":[{"id":"1.231541189","rc":[{"batb":[[0,2.32,14],[1,2.3,7.51],[2,2.28,4.4]],"batl":[[0,3.1,64.04]],"ltp":2.28,"tv":458.66,"id":19587212}]}]}
{"op":"mcm","clk":"11792411161","pt":1723055680829,"mc":[{"id":"1.231541189","rc":[{"batb":[[0,1.48,20.23],[1,1.38,3.67],[2,1.37,10]],"ltp":1.38,"tv":4719.5,"id":19587555}]}]}
{"op":"mcm","clk":"11792411466","pt":1723055682457,"mc":[{"id":"1.231541189","rc":[{"batb":[[0,2.32,10]],"ltp":2.28,"tv":458.66,"id":19587212}]}]}
{"op":"mcm","clk":"11792411603","pt":1723055683344,"mc":[{"id":"1.231541189","rc":[{"batb":[[0,2.3,7.51],[1,2.28,4.4],[2,1.93,53.76]],"ltp":2.28,"tv":458.66,"id":19587212}]}]}
{"op":"mcm","clk":"11792412017","pt":1723055686026,"mc":[{"id":"1.231541189","rc":[{"batb":[[0,2.32,14],[1,2.3,7.51],[2,2.28,4.4]],"batl":[[0,3.1,242.44]],"ltp":2.28,"tv":458.66,"id":19587212}]}]}
{"op":"mcm","clk":"11792412408","pt":1723055688224,"mc":[{"id":"1.231541189","rc":[{"batb":[[0,2.32,10]],"ltp":2.28,"tv":458.66,"id":19587212}]}]}
{"op":"mcm","clk":"11792412581","pt":1723055689218,"mc":[{"id":"1.231541189","rc":[{"batb":[[0,2.3,7.51],[1,2.28,4.4],[2,1.93,53.76]],"ltp":2.28,"tv":458.66,"id":19587212}]}]}
{"op":"mcm","clk":"11792416433","pt":1723055712991,"mc":[{"id":"1.231541189","rc":[{"batb":[[0,2.32,14],[1,2.3,7.51],[2,2.28,4.4]],"ltp":2.28,"tv":458.66,"id":19587212},{"batb":[[0,1.48,37.43]],"ltp":1.38,"tv":4719.5,"id":19587555}]}]}
{"op":"mcm","clk":"11792416799","pt":1723055715271,"mc":[{"id":"1.231541189","rc":[{"batb":[[0,2.32,10]],"ltp":2.28,"tv":458.66,"id":19587212}]}]}
{"op":"mcm","clk":"11792416954","pt":1723055716270,"mc":[{"id":"1.231541189","rc":[{"batb":[[0,2.3,7.51],[1,2.28,4.4],[2,1.93,53.76]],"ltp":2.28,"tv":458.66,"id":19587212}]}]}
{"op":"mcm","clk":"11792419288","pt":1723055730493,"mc":[{"id":"1.231541189","rc":[{"batb":[[0,2.32,14],[1,2.3,7.51],[2,2.28,4.4]],"batl":[[0,3,178.4],[1,3.1,64.04]],"ltp":2.28,"tv":458.66,"id":19587212}]}]}
{"op":"mcm","clk":"11792419430","pt":1723055731389,"mc":[{"id":"1.231541189","rc":[{"batl":[[0,3,242.44],[1,3.1,0]],"ltp":2.28,"tv":458.66,"id":19587212},{"batb":[[0,1.51,19.83]],"ltp":1.38,"tv":4719.5,"id":19587555}]}]}
{"op":"mcm","clk":"11792419636","pt":1723055732704,"mc":[{"id":"1.231541189","rc":[{"batb":[[0,2.32,10]],"ltp":2.28,"tv":458.66,"id":19587212}]}]}
{"op":"mcm","clk":"11792419823","pt":1723055733802,"mc":[{"id":"1.231541189","rc":[{"batb":[[0,2.3,7.51],[1,2.28,4.4],[2,1.93,53.76]],"ltp":2.28,"tv":458.66,"id":19587212}]}]}
{"op":"mcm","clk":"11792421935","pt":1723055746508,"mc":[{"id":"1.231541189","rc":[{"batb":[[0,2.32,14],[1,2.3,7.51],[2,2.28,4.4]],"batl":[[0,3,64.04]],"ltp":2.28,"tv":458.66,"id":19587212}]}]}
{"op":"mcm","clk":"11792422274","pt":1723055748725,"mc":[{"id":"1.231541189","rc":[{"batb":[[0,2.32,10]],"ltp":2.28,"tv":458.66,"id":19587212}]}]}
{"op":"mcm","clk":"11792422459","pt":1723055749989,"mc":[{"id":"1.231541189","rc":[{"batb":[[0,2.3,7.51],[1,2.28,4.4],[2,1.93,53.76]],"ltp":2.28,"tv":458.66,"id":19587212}]}]}
{"op":"mcm","clk":"11792423020","pt":1723055753703,"mc":[{"id":"1.231541189","rc":[{"batb":[[0,1.38,3.67],[1,1.37,10],[2,1.3,11.86]],"ltp":1.38,"tv":4719.5,"id":19587555}]}]}
{"op":"mcm","clk":"11792645124","pt":1723057396835,"mc":[{"id":"1.231541189","rc":[{"trd":[[1.55,92.15],[2.2,365.79]],"batb":[[0,2.3,7.51]],"ltp":2.28,"tv":459.02,"id":19587212},{"trd":[[1.38,7.77],[1.41,8.03],[1.42,28.56],[1.55,92.15],[1.74,34.44],[1.75,934.86],[1.76,1936.14],[1.78,1680.72]],"batb":[[0,1.38,3.67]],"batl":[[0,1.72,26],[1,1.78,45]],"ltp":1.38,"tv":4723.21,"id":19587555}],"tv":5182.24}]}
{"op":"mcm","clk":"11792655802","pt":1723057497977,"mc":[{"id":"1.231541189","rc":[{"batl":[[0,1.7,242.63],[1,1.72,26],[2,1.78,45]],"ltp":1.38,"tv":4723.21,"id":19587555}]}]}
{"op":"mcm","clk":"11792656540","pt":1723057504166,"mc":[{"id":"1.231541189","rc":[{"trd":[[1.7,484.04]],"batl":[[0,1.72,26.61],[1,1.78,45],[2,1.78,0]],"ltp":1.7,"tv":5207.25,"id":19587555}],"tv":5666.27}]}
{"op":"mcm","clk":"11792659129","pt":1723057524970,"mc":[{"id":"1.231541189","rc":[{"batl":[[0,1.72,26]],"ltp":1.7,"tv":5207.25,"id":19587555}]}]}
{"op":"mcm","clk":"11792662388","pt":1723057551207,"mc":[{"id":"1.231541189","rc":[{"batl":[[0,1.7,9.02],[1,1.72,26],[2,1.78,45]],"ltp":1.7,"tv":5207.25,"id":19587555}]}]}
{"op":"mcm","clk":"11792663454","pt":1723057560030,"mc":[{"id":"1.231541189","rc":[{"batl":[[0,1.72,26],[1,1.78,45],[2,1.78,0]],"ltp":1.7,"tv":5207.25,"id":19587555}]}]}
{"op":"mcm","clk":"11792665630","pt":1723057577587,"mc":[{"id":"1.231541189","rc":[{"batl":[[0,1.7,242.02],[1,1.72,26],[2,1.78,45]],"ltp":1.7,"tv":5207.25,"id":19587555}]}]}
{"op":"mcm","clk":"11792666347","pt":1723057583181,"mc":[{"id":"1.231541189","rc":[{"trd":[[1.7,841.12]],"batl":[[0,1.7,63.48]],"ltp":1.7,"tv":5564.33,"id":19587555}],"tv":6023.35}]}
{"op":"mcm","clk":"11792666445","pt":1723057583966,"mc":[{"id":"1.231541189","rc":[{"trd":[[1.7,968.07]],"batb":[[0,1.38,4.28]],"batl":[[0,1.72,26],[1,1.78,45],[2,1.78,0]],"ltp":1.7,"tv":5691.29,"id":19587555}],"tv":6150.31}]}
{"op":"mcm","clk":"11792667572","pt":1723057593096,"mc":[{"id":"1.231541189","rc":[{"batb":[[0,1.38,3.67]],"ltp":1.7,"tv":5691.29,"id":19587555}]}]}
{"op":"mcm","clk":"11792687169","pt":1723057750175,"mc":[{"id":"1.231541189","rc":[{"batb":[[0,2.98,22.42],[1,2.3,7.51],[2,2.28,4.4]],"ltp":2.28,"tv":459.02,"id":19587212},{"batb":[[0,1.44,100.93],[1,1.38,3.67],[2,1.37,10]],"ltp":1.7,"tv":5691.29,"id":19587555}]}]}
{"op":"mcm","clk":"11792687488","pt":1723057752389,"mc":[{"id":"1.231541189","rc":[{"batb":[[0,1.45,20.66],[1,1.44,100.93],[2,1.38,3.67]],"ltp":1.7,"tv":5691.29,"id":19587555}]}]}
{"op":"mcm","clk":"11792688392","pt":1723057759368,"mc":[{"id":"1.231541189","rc":[{"batb":[[0,3.05,14],[1,3,4],[2,2.98,26.42]],"batl":[[0,3.25,4]],"ltp":2.28,"tv":459.02,"id":19587212},{"batb":[[0,1.45,24.66]],"batl":[[0,1.51,4],[1,1.72,26],[2,1.78,45]],"ltp":1.7,"tv":5691.29,"id":19587555}]}]}
{"op":"mcm","clk":"11792688680","pt":1723057761878,"mc":[{"id":"1.231541189","rc":[{"batb":[[0,3.05,10]],"ltp":2.28,"tv":459.02,"id":19587212}]}]}
{"op":"mcm","clk":"11792688761","pt":1723057762706,"mc":[{"id":"1.231541189","rc":[{"batb":[[0,3,4],[1,2.98,26.42],[2,2.3,7.51]],"ltp":2.28,"tv":459.02,"id":19587212}]}]}
{"op":"mcm","clk":"11792690366","pt":1723057774290,"mc":[{"id":"1.231541189","rc":[{"batb":[[0,1.46,4],[1,1.45,24.66],[2,1.44,100.93]],"batl":[[0,1.5,4],[1,1.51,4],[2,1.72,26]],"ltp":1.7,"tv":5691.29,"id":19587555}]}]}
{"op":"mcm","clk":"11792690425","pt":1723057774709,"mc":[{"id":"1.231541189","rc":[{"batb":[[0,3.05,14],[1,3,4],[2,2.98,26.42]],"ltp":2.28,"tv":459.02,"id":19587212}]}]}
{"op":"mcm","clk":"11792690708","pt":1723057776998,"mc":[{"id":"1.231541189","rc":[{"batb":[[0,3.05,10]],"ltp":2.28,"tv":459.02,"id":19587212}]}]}
{"op":"mcm","clk":"11792690831","pt":1723057777894,"mc":[{"id":"1.231541189","rc":[{"batb":[[0,3,4],[1,2.98,26.42],[2,2.3,7.51]],"ltp":2.28,"tv":459.02,"id":19587212}]}]}
{"op":"mcm","clk":"11792692315","pt":1723057789513,"mc":[{"id":"1.231541189","rc":[{"batl":[[0,3.2,4],[1,3.25,4]],"ltp":2.28,"tv":459.02,"id":19587212}]}]}
{"op":"mcm","clk":"11792692451","pt":1723057790409,"mc":[{"id":"1.231541189","rc":[{"batb":[[0,3.05,4],[1,3,4],[2,2.98,26.42]],"ltp":2.28,"tv":459.02,"id":19587212},{"batb":[[1,1.45,32.91]],"ltp":1.7,"tv":5691.29,"id":19587555}]}]}
{"op":"mcm","clk":"11792692650","pt":1723057792040,"mc":[{"id":"1.231541189","rc":[{"batb":[[0,3,4],[1,2.98,26.42],[2,2.3,7.51]],"ltp":2.28,"tv":459.02,"id":19587212}]}]}
{"op":"mcm","clk":"11792744703","pt":1723058143246,"mc":[{"id":"1.231541189","rc":[{"batb":[[0,3.05,4],[1,3,4],[2,2.98,26.42]],"ltp":2.28,"tv":459.02,"id":19587212}]}]}
{"op":"mcm","clk":"11792745095","pt":1723058146342,"mc":[{"id":"1.231541189","rc":[{"batb":[[0,3,4],[1,2.98,26.42],[2,2.3,7.51]],"ltp":2.28,"tv":459.02,"id":19587212}]}]}
{"op":"mcm","clk":"11792781837","pt":1723058482541,"mc":[{"id":"1.231541189","rc":[{"batb":[[2,2.28,4.4]],"ltp":2.28,"tv":459.02,"id":19587212}]}]}
{"op":"mcm","clk":"11792781863","pt":1723058482853,"mc":[{"id":"1.231541189","rc":[{"batb":[[0,3.05,4],[1,3,4],[2,2.98,26.42]],"ltp":2.28,"tv":459.02,"id":19587212}]}]}
{"op":"mcm","clk":"11792782042","pt":1723058484831,"mc":[{"id":"1.231541189","rc":[{"batb":[[0,3,4],[1,2.98,26.42],[2,2.28,4.4]],"ltp":2.28,"tv":459.02,"id":19587212},{"batl":[[0,1.49,4],[1,1.5,4],[2,1.51,4]],"ltp":1.7,"tv":5691.29,"id":19587555}]}]}
{"op":"mcm","clk":"11792863712","pt":1723059352406,"mc":[{"id":"1.231541189","rc":[{"batb":[[0,3.05,4],[1,3,4],[2,2.98,26.42]],"ltp":2.28,"tv":459.02,"id":19587212},{"batl":[[0,1.5,4],[1,1.51,4],[2,1.72,26]],"ltp":1.7,"tv":5691.29,"id":19587555}]}]}
{"op":"mcm","clk":"11792863864","pt":1723059354217,"mc":[{"id":"1.231541189","rc":[{"batb":[[0,3,4],[1,2.98,26.42],[2,2.28,4.4]],"ltp":2.28,"tv":459.02,"id":19587212}]}]}
{"op":"mcm","clk":"11792887050","pt":1723059603054,"mc":[{"id":"1.231541189","rc":[{"batb":[[0,3.05,4],[1,3,4],[2,2.98,26.42]],"ltp":2.28,"tv":459.02,"id":19587212}]}]}
{"op":"mcm","clk":"11792887378","pt":1723059606279,"mc":[{"id":"1.231541189","rc":[{"batb":[[0,3,4],[1,2.98,26.42],[2,2.28,4.4]],"ltp":2.28,"tv":459.02,"id":19587212}]}]}
{"op":"mcm","clk":"11792899918","pt":1723059738491,"mc":[{"id":"1.231541189","rc":[{"batb":[[0,3.1,4],[1,3.05,1],[2,3,4]],"ltp":2.28,"tv":459.02,"id":19587212}]}]}
{"op":"mcm","clk":"11792899982","pt":1723059739109,"mc":[{"id":"1.231541189","rc":[{"batb":[[2,2.98,22.42]],"ltp":2.28,"tv":459.02,"id":19587212},{"batl":[[0,1.72,26],[1,1.78,45],[2,1.72,0]],"ltp":1.7,"tv":5691.29,"id":19587555}]}]}
{"op":"mcm","clk":"11792900128","pt":1723059740921,"mc":[{"id":"1.231541189","rc":[{"batb":[[0,3.05,1],[1,2.98,22.42],[2,2.28,4.4]],"ltp":2.28,"tv":459.02,"id":19587212}]}]}
{"op":"mcm","clk":"11792900721","pt":1723059746799,"mc":[{"id":"1.231541189","rc":[{"batb":[[0,3,14],[2,1.93,53.76]],"ltp":2.28,"tv":459.02,"id":19587212},{"trd":[[1.46,4]],"batb":[[0,1.46,2]],"ltp":1.46,"tv":5695.29,"id":19587555}],"tv":6154.31}]}
{"op":"mcm","clk":"11792900945","pt":1723059748924,"mc":[{"id":"1.231541189","rc":[{"batb":[[0,3,10]],"ltp":2.28,"tv":459.02,"id":19587212}]}]}
{"op":"mcm","clk":"11792901046","pt":1723059750121,"mc":[{"id":"1.231541189","rc":[{"batb":[[0,2.98,22.42],[1,1.93,53.76],[2,1.83,60.24]],"ltp":2.28,"tv":459.02,"id":19587212}]}]}
{"op":"mcm","clk":"11792901466","pt":1723059753817,"mc":[{"id":"1.231541189","rc":[{"batb":[[0,3.05,4],[1,3,4],[2,2.98,26.42]],"ltp":2.28,"tv":459.02,"id":19587212},{"batl":[[0,1.5,4],[1,1.51,4],[2,1.72,26]],"ltp":1.46,"tv":5695.29,"id":19587555}]}]}
{"op":"mcm","clk":"11792901711","pt":1723059756147,"mc":[{"id":"1.231541189","rc":[{"batb":[[0,3,4],[1,2.98,26.42],[2,1.93,53.76]],"ltp":2.28,"tv":459.02,"id":19587212}]}]}
{"op":"mcm","clk":"11792951899","pt":1723060279565,"mc":[{"id":"1.231541189","rc":[{"batb":[[0,3.05,4],[1,3,4],[2,2.98,26.42]],"ltp":2.28,"tv":459.02,"id":19587212}]}]}
{"op":"mcm","clk":"11792952114","pt":1723060281849,"mc":[{"id":"1.231541189","rc":[{"batb":[[0,3,4],[1,2.98,26.42],[2,1.93,53.76]],"ltp":2.28,"tv":459.02,"id":19587212}]}]}
{"op":"mcm","clk":"11792996831","pt":1723060875951,"mc":[{"id":"1.231541189","rc":[{"trd":[[1.55,92.13],[2.2,365.69]],"batb":[[0,3.05,4],[1,3,4],[2,2.98,26.42]],"ltp":2.28,"tv":458.89,"id":19587212},{"trd":[[1.38,7.77],[1.41,8.02],[1.42,28.56],[1.55,92.13],[1.7,967.8],[1.74,34.43],[1.75,934.6],[1.76,1935.6],[1.78,1680.26]],"batb":[[1,1.45,32.91]],"ltp":1.46,"tv":5693.71,"id":19587555}],"tv":6152.6}]}
{"op":"mcm","clk":"11792997004","pt":1723060878227,"mc":[{"id":"1.231541189","rc":[{"batb":[[0,3,4],[1,2.98,26.42],[2,1.93,53.76]],"ltp":2.28,"tv":458.89,"id":19587212}]}]}
{"op":"mcm","clk":"11792999986","pt":1723060923781,"mc":[{"id":"1.231541189","rc":[{"batb":[[0,3.05,4],[1,3,4],[2,2.98,26.42]],"ltp":2.28,"tv":458.89,"id":19587212}]}]}
{"op":"mcm","clk":"11793000172","pt":1723060926471,"mc":[{"id":"1.231541189","rc":[{"batb":[[0,3,4],[1,2.98,26.42],[2,1.93,53.76]],"ltp":2.28,"tv":458.89,"id":19587212}]}]}
{"op":"mcm","clk":"11793039281","pt":1723061608428,"mc":[{"id":"1.231541189","rc":[{"batb":[[0,3.05,4],[1,3,4],[2,2.98,26.42]],"ltp":2.28,"tv":458.89,"id":19587212}]}]}
{"op":"mcm","clk":"11793039445","pt":1723061611324,"mc":[{"id":"1.231541189","rc":[{"batb":[[0,3,4],[1,2.98,26.42],[2,1.93,53.76]],"ltp":2.28,"tv":458.89,"id":19587212},{"batl":[[0,1.49,4],[1,1.5,4],[2,1.51,4]],"ltp":1.46,"tv":5693.71,"id":19587555}]}]}
{"op":"mcm","clk":"11793039471","pt":1723061611840,"mc":[{"id":"1.231541189","rc":[{"batl":[[0,1.5,4],[1,1.51,4],[2,1.72,26]],"ltp":1.46,"tv":5693.71,"id":19587555}]}]}
{"op":"mcm","clk":"11793058183","pt":1723061978128,"mc":[{"id":"1.231541189","rc":[{"batb":[[0,3.05,4],[1,3,4],[2,2.98,26.42]],"ltp":2.28,"tv":458.89,"id":19587212}]}]}
{"op":"mcm","clk":"11793058336","pt":1723061980709,"mc":[{"id":"1.231541189","rc":[{"batb":[[0,3,4],[1,2.98,26.42],[2,1.93,53.76]],"ltp":2.28,"tv":458.89,"id":19587212}]}]}
{"op":"mcm","clk":"11793059693","pt":1723062004850,"mc":[{"id":"1.231541189","rc":[{"batb":[[0,3.05,4],[1,3,4],[2,2.98,26.42]],"ltp":2.28,"tv":458.89,"id":19587212}]}]}
{"op":"mcm","clk":"11793059808","pt":1723062007269,"mc":[{"id":"1.231541189","rc":[{"batb":[[0,3,4],[1,2.98,26.42],[2,1.93,53.76]],"ltp":2.28,"tv":458.89,"id":19587212}]}]}
{"op":"mcm","clk":"11793061167","pt":1723062033280,"mc":[{"id":"1.231541189","rc":[{"batb":[[0,3.05,4],[1,3,4],[2,2.98,26.42]],"ltp":2.28,"tv":458.89,"id":19587212}]}]}
{"op":"mcm","clk":"11793061299","pt":1723062035505,"mc":[{"id":"1.231541189","rc":[{"batb":[[0,3,4],[1,2.98,26.42],[2,1.93,53.76]],"ltp":2.28,"tv":458.89,"id":19587212}]}]}
{"op":"mcm","clk":"11793061468","pt":1723062038807,"mc":[{"id":"1.231541189","rc":[{"batb":[[0,3.05,4],[1,3,4],[2,2.98,26.42]],"ltp":2.28,"tv":458.89,"id":19587212}]}]}
{"op":"mcm","clk":"11793061594","pt":1723062041332,"mc":[{"id":"1.231541189","rc":[{"batb":[[0,3,4],[1,2.98,26.42],[2,1.93,53.76]],"ltp":2.28,"tv":458.89,"id":19587212}]}]}
{"op":"mcm","clk":"11793061883","pt":1723062047011,"mc":[{"id":"1.231541189","rc":[{"batb":[[0,3.05,4],[1,3,4],[2,2.98,26.42]],"ltp":2.28,"tv":458.89,"id":19587212}]}]}
{"op":"mcm","clk":"11793061950","pt":1723062048511,"mc":[{"id":"1.231541189","rc":[{"batl":[[0,1.49,4],[1,1.5,4],[2,1.51,4]],"ltp":1.46,"tv":5693.71,"id":19587555}]}]}
{"op":"mcm","clk":"11793062002","pt":1723062049532,"mc":[{"id":"1.231541189","rc":[{"batb":[[0,3,4],[1,2.98,26.42],[2,1.93,53.76]],"ltp":2.28,"tv":458.89,"id":19587212},{"batl":[[0,1.5,4],[1,1.51,4],[2,1.72,26]],"ltp":1.46,"tv":5693.71,"id":19587555}]}]}
{"op":"mcm","clk":"11793062179","pt":1723062052827,"mc":[{"id":"1.231541189","rc":[{"batb":[[0,3.05,4],[1,3,4],[2,2.98,26.42]],"ltp":2.28,"tv":458.89,"id":19587212}]}]}
{"op":"mcm","clk":"11793062285","pt":1723062055447,"mc":[{"id":"1.231541189","rc":[{"batb":[[0,3,4],[1,2.98,26.42],[2,1.93,53.76]],"ltp":2.28,"tv":458.89,"id":19587212}]}]}
{"op":"mcm","clk":"11793062396","pt":1723062057813,"mc":[{"id":"1.231541189","rc":[{"batb":[[0,3.05,4],[1,3,4],[2,2.98,26.42]],"ltp":2.28,"tv":458.89,"id":19587212}]}]}
{"op":"mcm","clk":"11793062500","pt":1723062060345,"mc":[{"id":"1.231541189","rc":[{"batb":[[0,3,4],[1,2.98,26.42],[2,1.93,53.76]],"ltp":2.28,"tv":458.89,"id":19587212}]}]}
{"op":"mcm","clk":"11793062703","pt":1723062064118,"mc":[{"id":"1.231541189","rc":[{"batb":[[0,3.05,4],[1,3,4],[2,2.98,26.42]],"ltp":2.28,"tv":458.89,"id":19587212}]}]}
{"op":"mcm","clk":"11793062852","pt":1723062066743,"mc":[{"id":"1.231541189","rc":[{"batb":[[0,3,4],[1,2.98,26.42],[2,1.93,53.76]],"ltp":2.28,"tv":458.89,"id":19587212}]}]}
{"op":"mcm","clk":"11793063283","pt":1723062077054,"mc":[{"id":"1.231541189","rc":[{"batb":[[0,3.05,4],[1,3,4],[2,2.98,26.42]],"ltp":2.28,"tv":458.89,"id":19587212}]}]}
{"op":"mcm","clk":"11793063441","pt":1723062080466,"mc":[{"id":"1.231541189","rc":[{"batb":[[0,3,4],[1,2.98,26.42],[2,1.93,53.76]],"ltp":2.28,"tv":458.89,"id":19587212}]}]}
{"op":"mcm","clk":"11793063598","pt":1723062083877,"mc":[{"id":"1.231541189","rc":[{"batb":[[0,3.05,4],[1,3,4],[2,2.98,26.42]],"ltp":2.28,"tv":458.89,"id":19587212}]}]}
{"op":"mcm","clk":"11793063735","pt":1723062086248,"mc":[{"id":"1.231541189","rc":[{"batb":[[0,3,4],[1,2.98,26.42],[2,1.93,53.76]],"ltp":2.28,"tv":458.89,"id":19587212}]}]}
{"op":"mcm","clk":"11793064097","pt":1723062092588,"mc":[{"id":"1.231541189","rc":[{"batb":[[0,3.05,4],[1,3,4],[2,2.98,26.42]],"ltp":2.28,"tv":458.89,"id":19587212}]}]}
{"op":"mcm","clk":"11793064259","pt":1723062095678,"mc":[{"id":"1.231541189","rc":[{"batb":[[0,3,4],[1,2.98,26.42],[2,1.93,53.76]],"ltp":2.28,"tv":458.89,"id":19587212}]}]}
{"op":"mcm","clk":"11793064496","pt":1723062099183,"mc":[{"id":"1.231541189","rc":[{"batb":[[0,3.05,4],[1,3,4],[2,2.98,26.42]],"ltp":2.28,"tv":458.89,"id":19587212}]}]}
{"op":"mcm","clk":"11793064613","pt":1723062101715,"mc":[{"id":"1.231541189","rc":[{"batb":[[0,3,4],[1,2.98,26.42],[2,1.93,53.76]],"ltp":2.28,"tv":458.89,"id":19587212}]}]}
{"op":"mcm","clk":"11793064906","pt":1723062106883,"mc":[{"id":"1.231541189","rc":[{"batb":[[0,3.05,4],[1,3,4],[2,2.98,26.42]],"ltp":2.28,"tv":458.89,"id":19587212}]}]}
{"op":"mcm","clk":"11793065037","pt":1723062109310,"mc":[{"id":"1.231541189","rc":[{"batb":[[0,3,4],[1,2.98,26.42],[2,1.93,53.76]],"ltp":2.28,"tv":458.89,"id":19587212},{"batl":[[0,1.49,4],[1,1.5,4],[2,1.51,4]],"ltp":1.46,"tv":5693.71,"id":19587555}]}]}
{"op":"mcm","clk":"11793065059","pt":1723062109723,"mc":[{"id":"1.231541189","rc":[{"batl":[[0,1.5,4],[1,1.51,4],[2,1.72,26]],"ltp":1.46,"tv":5693.71,"id":19587555}]}]}
{"op":"mcm","clk":"11793065189","pt":1723062112312,"mc":[{"id":"1.231541189","rc":[{"batb":[[0,3.05,4],[1,3,4],[2,2.98,26.42]],"ltp":2.28,"tv":458.89,"id":19587212}]}]}
{"op":"mcm","clk":"11793065328","pt":1723062115017,"mc":[{"id":"1.231541189","rc":[{"batb":[[0,3,4],[1,2.98,26.42],[2,1.93,53.76]],"ltp":2.28,"tv":458.89,"id":19587212}]}]}
{"op":"mcm","clk":"11793065502","pt":1723062118112,"mc":[{"id":"1.231541189","rc":[{"batb":[[0,3.05,4],[1,3,4],[2,2.98,26.42]],"ltp":2.28,"tv":458.89,"id":19587212}]}]}
{"op":"mcm","clk":"11793065642","pt":1723062120326,"mc":[{"id":"1.231541189","rc":[{"batb":[[0,3,4],[1,2.98,26.42],[2,1.93,53.76]],"ltp":2.28,"tv":458.89,"id":19587212}]}]}
{"op":"mcm","clk":"11793065809","pt":1723062122727,"mc":[{"id":"1.231541189","rc":[{"batb":[[0,3.05,4],[1,3,4],[2,2.98,26.42]],"ltp":2.28,"tv":458.89,"id":19587212}]}]}
{"op":"mcm","clk":"11793065922","pt":1723062125003,"mc":[{"id":"1.231541189","rc":[{"batb":[[0,3,4],[1,2.98,26.42],[2,1.93,53.76]],"ltp":2.28,"tv":458.89,"id":19587212}]}]}
{"op":"mcm","clk":"11793066067","pt":1723062127635,"mc":[{"id":"1.231541189","rc":[{"batb":[[0,3.05,4],[1,3,4],[2,2.98,26.42]],"ltp":2.28,"tv":458.89,"id":19587212}]}]}
{"op":"mcm","clk":"11793066202","pt":1723062130020,"mc":[{"id":"1.231541189","rc":[{"batb":[[0,3,4],[1,2.98,26.42],[2,1.93,53.76]],"ltp":2.28,"tv":458.89,"id":19587212}]}]}
{"op":"mcm","clk":"11793066296","pt":1723062132230,"mc":[{"id":"1.231541189","rc":[{"batb":[[0,3.05,4],[1,3,4],[2,2.98,26.42]],"ltp":2.28,"tv":458.89,"id":19587212}]}]}
{"op":"mcm","clk":"11793066478","pt":1723062134856,"mc":[{"id":"1.231541189","rc":[{"batb":[[0,3,4],[1,2.98,26.42],[2,1.93,53.76]],"ltp":2.28,"tv":458.89,"id":19587212}]}]}
{"op":"mcm","clk":"11793066566","pt":1723062137233,"mc":[{"id":"1.231541189","rc":[{"batb":[[0,3.05,4],[1,3,4],[2,2.98,26.42]],"ltp":2.28,"tv":458.89,"id":19587212}]}]}
{"op":"mcm","clk":"11793066696","pt":1723062139463,"mc":[{"id":"1.231541189","rc":[{"batb":[[0,3,4],[1,2.98,26.42],[2,1.93,53.76]],"ltp":2.28,"tv":458.89,"id":19587212},{"batl":[[0,1.49,4],[1,1.5,4],[2,1.51,4]],"ltp":1.46,"tv":5693.71,"id":19587555}]}]}
{"op":"mcm","clk":"11793066726","pt":1723062139860,"mc":[{"id":"1.231541189","rc":[{"batl":[[0,1.5,4],[1,1.51,4],[2,1.72,26]],"ltp":1.46,"tv":5693.71,"id":19587555}]}]}
{"op":"mcm","clk":"11793066972","pt":1723062143428,"mc":[{"id":"1.231541189","rc":[{"batb":[[0,3.05,4],[1,3,4],[2,2.98,26.42]],"ltp":2.28,"tv":458.89,"id":19587212}]}]}
{"op":"mcm","clk":"11793067092","pt":1723062145956,"mc":[{"id":"1.231541189","rc":[{"batb":[[0,3,4],[1,2.98,26.42],[2,1.93,53.76]],"ltp":2.28,"tv":458.89,"id":19587212}]}]}
{"op":"mcm","clk":"11793067195","pt":1723062147865,"mc":[{"id":"1.231541189","rc":[{"batb":[[0,3.05,4],[1,3,4],[2,2.98,26.42]],"ltp":2.28,"tv":458.89,"id":19587212}]}]}
{"op":"mcm","clk":"11793067326","pt":1723062150332,"mc":[{"id":"1.231541189","rc":[{"batb":[[0,3,4],[1,2.98,26.42],[2,1.93,53.76]],"ltp":2.28,"tv":458.89,"id":19587212}]}]}
{"op":"mcm","clk":"11793067467","pt":1723062153162,"mc":[{"id":"1.231541189","rc":[{"batb":[[0,3.05,4],[1,3,4],[2,2.98,26.42]],"ltp":2.28,"tv":458.89,"id":19587212}]}]}
{"op":"mcm","clk":"11793067520","pt":1723062154140,"mc":[{"id":"1.231541189","rc":[{"batl":[[0,1.49,4],[1,1.5,4],[2,1.51,4]],"ltp":1.46,"tv":5693.71,"id":19587555}]}]}
{"op":"mcm","clk":"11793067554","pt":1723062154867,"mc":[{"id":"1.231541189","rc":[{"batl":[[0,1.5,4],[1,1.51,4],[2,1.72,26]],"ltp":1.46,"tv":5693.71,"id":19587555}]}]}
{"op":"mcm","clk":"11793067592","pt":1723062155681,"mc":[{"id":"1.231541189","rc":[{"batb":[[0,3,4],[1,2.98,26.42],[2,1.93,53.76]],"ltp":2.28,"tv":458.89,"id":19587212}]}]}
{"op":"mcm","clk":"11793067710","pt":1723062158051,"mc":[{"id":"1.231541189","rc":[{"batb":[[0,3.05,4],[1,3,4],[2,2.98,26.42]],"ltp":2.28,"tv":458.89,"id":19587212}]}]}
{"op":"mcm","clk":"11793067831","pt":1723062160682,"mc":[{"id":"1.231541189","rc":[{"batb":[[0,3,4],[1,2.98,26.42],[2,1.93,53.76]],"ltp":2.28,"tv":458.89,"id":19587212}]}]}
{"op":"mcm","clk":"11793067915","pt":1723062162955,"mc":[{"id":"1.231541189","rc":[{"batb":[[0,3.05,4],[1,3,4],[2,2.98,26.42]],"ltp":2.28,"tv":458.89,"id":19587212}]}]}
{"op":"mcm","clk":"11793068008","pt":1723062165485,"mc":[{"id":"1.231541189","rc":[{"batb":[[0,3,4],[1,2.98,26.42],[2,1.93,53.76]],"ltp":2.28,"tv":458.89,"id":19587212}]}]}
{"op":"mcm","clk":"11793068158","pt":1723062169076,"mc":[{"id":"1.231541189","rc":[{"batb":[[0,3.05,4],[1,3,4],[2,2.98,26.42]],"ltp":2.28,"tv":458.89,"id":19587212}]}]}
{"op":"mcm","clk":"11793068291","pt":1723062171495,"mc":[{"id":"1.231541189","rc":[{"batb":[[0,3,4],[1,2.98,26.42],[2,1.93,53.76]],"ltp":2.28,"tv":458.89,"id":19587212}]}]}
{"op":"mcm","clk":"11793068441","pt":1723062174792,"mc":[{"id":"1.231541189","rc":[{"batb":[[0,3.05,4],[1,3,4],[2,2.98,26.42]],"ltp":2.28,"tv":458.89,"id":19587212}]}]}
{"op":"mcm","clk":"11793068600","pt":1723062178400,"mc":[{"id":"1.231541189","rc":[{"batb":[[0,3,4],[1,2.98,26.42],[2,1.93,53.76]],"ltp":2.28,"tv":458.89,"id":19587212}]}]}
{"op":"mcm","clk":"11793068777","pt":1723062181910,"mc":[{"id":"1.231541189","rc":[{"batb":[[0,3.05,4],[1,3,4],[2,2.98,26.42]],"ltp":2.28,"tv":458.89,"id":19587212}]}]}
{"op":"mcm","clk":"11793068897","pt":1723062184294,"mc":[{"id":"1.231541189","rc":[{"batb":[[0,3,4],[1,2.98,26.42],[2,1.93,53.76]],"ltp":2.28,"tv":458.89,"id":19587212},{"batl":[[0,1.49,4],[1,1.5,4],[2,1.51,4]],"ltp":1.46,"tv":5693.71,"id":19587555}]}]}
{"op":"mcm","clk":"11793068949","pt":1723062185111,"mc":[{"id":"1.231541189","rc":[{"batl":[[0,1.5,4],[1,1.51,4],[2,1.72,26]],"ltp":1.46,"tv":5693.71,"id":19587555}]}]}
{"op":"mcm","clk":"11793069099","pt":1723062188206,"mc":[{"id":"1.231541189","rc":[{"batb":[[0,3.05,4],[1,3,4],[2,2.98,26.42]],"ltp":2.28,"tv":458.89,"id":19587212}]}]}
{"op":"mcm","clk":"11793069205","pt":1723062190521,"mc":[{"id":"1.231541189","rc":[{"batb":[[0,3,4],[1,2.98,26.42],[2,1.93,53.76]],"ltp":2.28,"tv":458.89,"id":19587212}]}]}
{"op":"mcm","clk":"11793069320","pt":1723062192838,"mc":[{"id":"1.231541189","rc":[{"batb":[[0,3.05,4],[1,3,4],[2,2.98,26.42]],"ltp":2.28,"tv":458.89,"id":19587212}]}]}
{"op":"mcm","clk":"11793069414","pt":1723062195149,"mc":[{"id":"1.231541189","rc":[{"batb":[[0,3,4],[1,2.98,26.42],[2,1.93,53.76]],"ltp":2.28,"tv":458.89,"id":19587212}]}]}
{"op":"mcm","clk":"11793069531","pt":1723062197732,"mc":[{"id":"1.231541189","rc":[{"batb":[[0,3.05,4],[1,3,4],[2,2.98,26.42]],"ltp":2.28,"tv":458.89,"id":19587212}]}]}
{"op":"mcm","clk":"11793069614","pt":1723062199434,"mc":[{"id":"1.231541189","rc":[{"batl":[[0,1.49,4],[1,1.5,4],[2,1.51,4]],"ltp":1.46,"tv":5693.71,"id":19587555}]}]}
{"op":"mcm","clk":"11793069640","pt":1723062200050,"mc":[{"id":"1.231541189","rc":[{"batb":[[0,3,4],[1,2.98,26.42],[2,1.93,53.76]],"ltp":2.28,"tv":458.89,"id":19587212},{"batl":[[0,1.5,4],[1,1.51,4],[2,1.72,26]],"ltp":1.46,"tv":5693.71,"id":19587555}]}]}
{"op":"mcm","clk":"11793069763","pt":1723062202324,"mc":[{"id":"1.231541189","rc":[{"batb":[[0,3.05,4],[1,3,4],[2,2.98,26.42]],"ltp":2.28,"tv":458.89,"id":19587212}]}]}
{"op":"mcm","clk":"11793069850","pt":1723062205309,"mc":[{"id":"1.231541189","rc":[{"batb":[[0,3,4],[1,2.98,26.42],[2,1.93,53.76]],"ltp":2.28,"tv":458.89,"id":19587212}]}]}
{"op":"mcm","clk":"11793069971","pt":1723062207153,"mc":[{"id":"1.231541189","rc":[{"batb":[[0,3.05,4],[1,3,4],[2,2.98,26.42]],"ltp":2.28,"tv":458.89,"id":19587212}]}]}
{"op":"mcm","clk":"11793070097","pt":1723062209679,"mc":[{"id":"1.231541189","rc":[{"batb":[[0,3,4],[1,2.98,26.42],[2,1.93,53.76]],"ltp":2.28,"tv":458.89,"id":19587212}]}]}
{"op":"mcm","clk":"11793070217","pt":1723062211947,"mc":[{"id":"1.231541189","rc":[{"batb":[[0,3.05,4],[1,3,4],[2,2.98,26.42]],"ltp":2.28,"tv":458.89,"id":19587212}]}]}
{"op":"mcm","clk":"11793070353","pt":1723062214373,"mc":[{"id":"1.231541189","rc":[{"batb":[[0,3,4],[1,2.98,26.42],[2,1.93,53.76]],"ltp":2.28,"tv":458.89,"id":19587212}]}]}
{"op":"mcm","clk":"11793070369","pt":1723062214582,"mc":[{"id":"1.231541189","rc":[{"batl":[[0,1.49,4],[1,1.5,4],[2,1.51,4]],"ltp":1.46,"tv":5693.71,"id":19587555}]}]}
{"op":"mcm","clk":"11793070528","pt":1723062218385,"mc":[{"id":"1.231541189","rc":[{"batb":[[0,3.05,4],[1,3,4],[2,2.98,26.42]],"ltp":2.28,"tv":458.89,"id":19587212},{"batl":[[0,1.5,4],[1,1.51,4],[2,1.72,26]],"ltp":1.46,"tv":5693.71,"id":19587555}]}]}
{"op":"mcm","clk":"11793070618","pt":1723062220390,"mc":[{"id":"1.231541189","rc":[{"batb":[[0,3,4],[1,2.98,26.42],[2,1.93,53.76]],"ltp":2.28,"tv":458.89,"id":19587212}]}]}
{"op":"mcm","clk":"11793070712","pt":1723062222703,"mc":[{"id":"1.231541189","rc":[{"batb":[[0,3.05,4],[1,3,4],[2,2.98,26.42]],"ltp":2.28,"tv":458.89,"id":19587212}]}]}
{"op":"mcm","clk":"11793070817","pt":1723062225016,"mc":[{"id":"1.231541189","rc":[{"batb":[[0,3,4],[1,2.98,26.42],[2,1.93,53.76]],"ltp":2.28,"tv":458.89,"id":19587212}]}]}
{"op":"mcm","clk":"11793070931","pt":1723062227635,"mc":[{"id":"1.231541189","rc":[{"batb":[[0,3.05,4],[1,3,4],[2,2.98,26.42]],"ltp":2.28,"tv":458.89,"id":19587212}]}]}
{"op":"mcm","clk":"11793071062","pt":1723062230308,"mc":[{"id":"1.231541189","rc":[{"trd":[[3.05,0.9]],"batb":[[0,3,4],[1,2.98,26.42],[2,1.93,53.76]],"ltp":3.05,"tv":459.79,"id":19587212}],"tv":6153.5}]}
{"op":"mcm","clk":"11793071150","pt":1723062232414,"mc":[{"id":"1.231541189","rc":[{"batb":[[0,3.05,4],[1,3,4],[2,2.98,26.42]],"ltp":3.05,"tv":459.79,"id":19587212}]}]}
{"op":"mcm","clk":"11793071247","pt":1723062234728,"mc":[{"id":"1.231541189","rc":[{"batb":[[0,3,4],[1,2.98,26.42],[2,1.93,53.76]],"ltp":3.05,"tv":459.79,"id":19587212}]}]}
{"op":"mcm","clk":"11793071344","pt":1723062236938,"mc":[{"id":"1.231541189","rc":[{"batb":[[0,3.05,4],[1,3,4],[2,2.98,26.42]],"ltp":3.05,"tv":459.79,"id":19587212}]}]}
{"op":"mcm","clk":"11793071444","pt":1723062239249,"mc":[{"id":"1.231541189","rc":[{"batb":[[0,3,4],[1,2.98,26.42],[2,1.93,53.76]],"ltp":3.05,"tv":459.79,"id":19587212}]}]}
{"op":"mcm","clk":"11793071576","pt":1723062242746,"mc":[{"id":"1.231541189","rc":[{"batb":[[0,3.05,4],[1,3,4],[2,2.98,26.42]],"ltp":3.05,"tv":459.79,"id":19587212}]}]}
{"op":"mcm","clk":"11793071718","pt":1723062245468,"mc":[{"id":"1.231541189","rc":[{"batb":[[0,3,4],[1,2.98,26.42],[2,1.93,53.76]],"ltp":3.05,"tv":459.79,"id":19587212}]}]}
{"op":"mcm","clk":"11793071830","pt":1723062248147,"mc":[{"id":"1.231541189","rc":[{"batb":[[0,3.05,4],[1,3,4],[2,2.98,26.42]],"ltp":3.05,"tv":459.79,"id":19587212}]}]}
{"op":"mcm","clk":"11793071930","pt":1723062250565,"mc":[{"id":"1.231541189","rc":[{"batb":[[0,3,4],[1,2.98,26.42],[2,1.93,53.76]],"ltp":3.05,"tv":459.79,"id":19587212}]}]}
{"op":"mcm","clk":"11793072033","pt":1723062253080,"mc":[{"id":"1.231541189","rc":[{"batb":[[0,3.05,4],[1,3,4],[2,2.98,26.42]],"ltp":3.05,"tv":459.79,"id":19587212}]}]}
{"op":"mcm","clk":"11793072124","pt":1723062255767,"mc":[{"id":"1.231541189","rc":[{"batb":[[0,3,4],[1,2.98,26.42],[2,1.93,53.76]],"ltp":3.05,"tv":459.79,"id":19587212}]}]}
{"op":"mcm","clk":"11793072252","pt":1723062258387,"mc":[{"id":"1.231541189","rc":[{"batb":[[0,3.05,4],[1,3,4],[2,2.98,26.42]],"ltp":3.05,"tv":459.79,"id":19587212}]}]}
{"op":"mcm","clk":"11793072387","pt":1723062260767,"mc":[{"id":"1.231541189","rc":[{"batb":[[0,3,4],[1,2.98,26.42],[2,1.93,53.76]],"ltp":3.05,"tv":459.79,"id":19587212}]}]}
{"op":"mcm","clk":"11793072673","pt":1723062267161,"mc":[{"id":"1.231541189","rc":[{"batb":[[0,3.05,4],[1,3,4],[2,2.98,26.42]],"ltp":3.05,"tv":459.79,"id":19587212}]}]}
{"op":"mcm","clk":"11793072787","pt":1723062269570,"mc":[{"id":"1.231541189","rc":[{"batb":[[0,3,4],[1,2.98,26.42],[2,1.93,53.76]],"ltp":3.05,"tv":459.79,"id":19587212}]}]}
{"op":"mcm","clk":"11793072930","pt":1723062272396,"mc":[{"id":"1.231541189","rc":[{"batb":[[0,3.05,4],[1,3,4],[2,2.98,26.42]],"ltp":3.05,"tv":459.79,"id":19587212}]}]}
{"op":"mcm","clk":"11793073023","pt":1723062274505,"mc":[{"id":"1.231541189","rc":[{"batb":[[0,3,4],[1,2.98,26.42],[2,1.93,53.76]],"ltp":3.05,"tv":459.79,"id":19587212}]}]}
{"op":"mcm","clk":"11793073201","pt":1723062278617,"mc":[{"id":"1.231541189","rc":[{"batb":[[0,3.05,4],[1,3,4],[2,2.98,26.42]],"ltp":3.05,"tv":459.79,"id":19587212}]}]}
{"op":"mcm","clk":"11793073311","pt":1723062280898,"mc":[{"id":"1.231541189","rc":[{"batb":[[0,3,4],[1,2.98,26.42],[2,1.93,53.76]],"ltp":3.05,"tv":459.79,"id":19587212}]}]}
{"op":"mcm","clk":"11793073453","pt":1723062284134,"mc":[{"id":"1.231541189","rc":[{"batb":[[0,3.05,4],[1,3,4],[2,2.98,26.42]],"ltp":3.05,"tv":459.79,"id":19587212}]}]}
{"op":"mcm","clk":"11793073570","pt":1723062286505,"mc":[{"id":"1.231541189","rc":[{"batb":[[0,3,4],[1,2.98,26.42],[2,1.93,53.76]],"ltp":3.05,"tv":459.79,"id":19587212}]}]}
{"op":"mcm","clk":"11793073693","pt":1723062289329,"mc":[{"id":"1.231541189","rc":[{"batb":[[0,3.05,4],[1,3,4],[2,2.98,26.42]],"ltp":3.05,"tv":459.79,"id":19587212}]}]}
{"op":"mcm","clk":"11793073799","pt":1723062291701,"mc":[{"id":"1.231541189","rc":[{"batb":[[0,3,4],[1,2.98,26.42],[2,1.93,53.76]],"ltp":3.05,"tv":459.79,"id":19587212}]}]}
{"op":"mcm","clk":"11793073929","pt":1723062294736,"mc":[{"id":"1.231541189","rc":[{"batb":[[0,3.05,4],[1,3,4],[2,2.98,26.42]],"ltp":3.05,"tv":459.79,"id":19587212}]}]}
{"op":"mcm","clk":"11793074050","pt":1723062297210,"mc":[{"id":"1.231541189","rc":[{"batb":[[0,3,4],[1,2.98,26.42],[2,1.93,53.76]],"ltp":3.05,"tv":459.79,"id":19587212}]}]}
{"op":"mcm","clk":"11793074215","pt":1723062300753,"mc":[{"id":"1.231541189","rc":[{"batb":[[0,3.05,4],[1,3,4],[2,2.98,26.42]],"ltp":3.05,"tv":459.79,"id":19587212}]}]}
{"op":"mcm","clk":"11793074320","pt":1723062303123,"mc":[{"id":"1.231541189","rc":[{"batb":[[0,3,4],[1,2.98,26.42],[2,1.93,53.76]],"ltp":3.05,"tv":459.79,"id":19587212}]}]}
{"op":"mcm","clk":"11793074439","pt":1723062306062,"mc":[{"id":"1.231541189","rc":[{"batb":[[0,3.05,4],[1,3,4],[2,2.98,26.42]],"ltp":3.05,"tv":459.79,"id":19587212}]}]}
{"op":"mcm","clk":"11793074533","pt":1723062308226,"mc":[{"id":"1.231541189","rc":[{"batb":[[0,3,4],[1,2.98,26.42],[2,1.93,53.76]],"ltp":3.05,"tv":459.79,"id":19587212}]}]}
{"op":"mcm","clk":"11793074616","pt":1723062310539,"mc":[{"id":"1.231541189","rc":[{"batb":[[0,3.05,4],[1,3,4],[2,2.98,26.42]],"ltp":3.05,"tv":459.79,"id":19587212}]}]}
{"op":"mcm","clk":"11793074650","pt":1723062311565,"mc":[{"id":"1.231541189","rc":[{"trd":[[3.05,0.93]],"batb":[[0,3.05,3.97]],"ltp":3.05,"tv":459.82,"id":19587212},{"trd":[[1.49,0.07]],"ltp":1.49,"tv":5693.78,"id":19587555}],"tv":6153.6}]}
{"op":"mcm","clk":"11793074688","pt":1723062312755,"mc":[{"id":"1.231541189","rc":[{"batb":[[0,3,4],[1,2.98,26.42],[2,1.93,53.76]],"ltp":3.05,"tv":459.82,"id":19587212}]}]}
{"op":"mcm","clk":"11793074786","pt":1723062315075,"mc":[{"id":"1.231541189","rc":[{"batb":[[0,3.05,4],[1,3,4],[2,2.98,26.42]],"ltp":3.05,"tv":459.82,"id":19587212}]}]}
{"op":"mcm","clk":"11793074877","pt":1723062317243,"mc":[{"id":"1.231541189","rc":[{"batb":[[0,3,4],[1,2.98,26.42],[2,1.93,53.76]],"ltp":3.05,"tv":459.82,"id":19587212}]}]}
{"op":"mcm","clk":"11793074986","pt":1723062319967,"mc":[{"id":"1.231541189","rc":[{"batb":[[0,3.05,4],[1,3,4],[2,2.98,26.42]],"ltp":3.05,"tv":459.82,"id":19587212}]}]}
{"op":"mcm","clk":"11793075097","pt":1723062323056,"mc":[{"id":"1.231541189","rc":[{"batb":[[0,3,4],[1,2.98,26.42],[2,1.93,53.76]],"ltp":3.05,"tv":459.82,"id":19587212}]}]}
{"op":"mcm","clk":"11793075171","pt":1723062325268,"mc":[{"id":"1.231541189","rc":[{"batb":[[0,3.05,4],[1,3,4],[2,2.98,26.42]],"ltp":3.05,"tv":459.82,"id":19587212}]}]}
{"op":"mcm","clk":"11793075274","pt":1723062327582,"mc":[{"id":"1.231541189","rc":[{"batb":[[0,3,4],[1,2.98,26.42],[2,1.93,53.76]],"ltp":3.05,"tv":459.82,"id":19587212}]}]}
{"op":"mcm","clk":"11793075362","pt":1723062329919,"mc":[{"id":"1.231541189","rc":[{"batb":[[0,3.05,4],[1,3,4],[2,2.98,26.42]],"ltp":3.05,"tv":459.82,"id":19587212}]}]}
{"op":"mcm","clk":"11793075470","pt":1723062332166,"mc":[{"id":"1.231541189","rc":[{"batb":[[0,3,4],[1,2.98,26.42],[2,1.93,53.76]],"ltp":3.05,"tv":459.82,"id":19587212}]}]}
{"op":"mcm","clk":"11793075555","pt":1723062334374,"mc":[{"id":"1.231541189","rc":[{"batb":[[0,3.05,4],[1,3,4],[2,2.98,26.42]],"ltp":3.05,"tv":459.82,"id":19587212}]}]}
{"op":"mcm","clk":"11793075593","pt":1723062335305,"mc":[{"id":"1.231541189","rc":[{"batl":[[0,1.49,4],[1,1.5,4],[2,1.51,4]],"ltp":1.49,"tv":5693.78,"id":19587555}]}]}
{"op":"mcm","clk":"11793075697","pt":1723062337420,"mc":[{"id":"1.231541189","rc":[{"batb":[[0,3,4],[1,2.98,26.42],[2,1.93,53.76]],"ltp":3.05,"tv":459.82,"id":19587212},{"batl":[[0,1.5,4],[1,1.51,4],[2,1.72,26]],"ltp":1.49,"tv":5693.78,"id":19587555}]}]}
{"op":"mcm","clk":"11793075818","pt":1723062340087,"mc":[{"id":"1.231541189","rc":[{"batb":[[0,3.05,4],[1,3,4],[2,2.98,26.42]],"ltp":3.05,"tv":459.82,"id":19587212}]}]}
{"op":"mcm","clk":"11793075901","pt":1723062342403,"mc":[{"id":"1.231541189","rc":[{"batb":[[0,3,4],[1,2.98,26.42],[2,1.93,53.76]],"ltp":3.05,"tv":459.82,"id":19587212}]}]}
{"op":"mcm","clk":"11793075994","pt":1723062344772,"mc":[{"id":"1.231541189","rc":[{"batb":[[0,3.05,4],[1,3,4],[2,2.98,26.42]],"ltp":3.05,"tv":459.82,"id":19587212}]}]}
{"op":"mcm","clk":"11793076118","pt":1723062347200,"mc":[{"id":"1.231541189","rc":[{"batb":[[0,3,4],[1,2.98,26.42],[2,1.93,53.76]],"ltp":3.05,"tv":459.82,"id":19587212}]}]}
{"op":"mcm","clk":"11793076217","pt":1723062349517,"mc":[{"id":"1.231541189","rc":[{"batb":[[0,3.05,4],[1,3,4],[2,2.98,26.42]],"ltp":3.05,"tv":459.82,"id":19587212}]}]}
{"op":"mcm","clk":"11793076258","pt":1723062350389,"mc":[{"id":"1.231541189","rc":[{"batl":[[0,1.49,4],[1,1.5,4],[2,1.51,4]],"ltp":1.49,"tv":5693.78,"id":19587555}]}]}
{"op":"mcm","clk":"11793076273","pt":1723062350697,"mc":[{"id":"1.231541189","rc":[{"batl":[[0,1.5,4],[1,1.51,4],[2,1.72,26]],"ltp":1.49,"tv":5693.78,"id":19587555}]}]}
{"op":"mcm","clk":"11793076319","pt":1723062351677,"mc":[{"id":"1.231541189","rc":[{"batb":[[0,3,4],[1,2.98,26.42],[2,1.93,53.76]],"ltp":3.05,"tv":459.82,"id":19587212}]}]}
{"op":"mcm","clk":"11793076417","pt":1723062354501,"mc":[{"id":"1.231541189","rc":[{"batb":[[0,3.05,4],[1,3,4],[2,2.98,26.42]],"ltp":3.05,"tv":459.82,"id":19587212}]}]}
{"op":"mcm","clk":"11793076550","pt":1723062357129,"mc":[{"id":"1.231541189","rc":[{"batb":[[0,3,4],[1,2.98,26.42],[2,1.93,53.76]],"ltp":3.05,"tv":459.82,"id":19587212}]}]}
{"op":"mcm","clk":"11793076670","pt":1723062359487,"mc":[{"id":"1.231541189","rc":[{"batb":[[0,3.05,4],[1,3,4],[2,2.98,26.42]],"ltp":3.05,"tv":459.82,"id":19587212}]}]}
{"op":"mcm","clk":"11793076789","pt":1723062362022,"mc":[{"id":"1.231541189","rc":[{"batb":[[0,3,4],[1,2.98,26.42],[2,1.93,53.76]],"ltp":3.05,"tv":459.82,"id":19587212}]}]}
{"op":"mcm","clk":"11793076912","pt":1723062365214,"mc":[{"id":"1.231541189","rc":[{"batb":[[0,3.05,4],[1,3,4],[2,2.98,26.42]],"ltp":3.05,"tv":459.82,"id":19587212}]}]}
{"op":"mcm","clk":"11793077007","pt":1723062367619,"mc":[{"id":"1.231541189","rc":[{"batb":[[0,3,4],[1,2.98,26.42],[2,1.93,53.76]],"ltp":3.05,"tv":459.82,"id":19587212}]}]}
{"op":"mcm","clk":"11793077112","pt":1723062370140,"mc":[{"id":"1.231541189","rc":[{"batb":[[0,3.05,4],[1,3,4],[2,2.98,26.42]],"ltp":3.05,"tv":459.82,"id":19587212}]}]}
{"op":"mcm","clk":"11793077229","pt":1723062372561,"mc":[{"id":"1.231541189","rc":[{"batb":[[0,3,4],[1,2.98,26.42],[2,1.93,53.76]],"ltp":3.05,"tv":459.82,"id":19587212}]}]}
{"op":"mcm","clk":"11793077316","pt":1723062374734,"mc":[{"id":"1.231541189","rc":[{"batb":[[0,3.05,4],[1,3,4],[2,2.98,26.42]],"ltp":3.05,"tv":459.82,"id":19587212}]}]}
{"op":"mcm","clk":"11793077432","pt":1723062377142,"mc":[{"id":"1.231541189","rc":[{"batb":[[0,3,4],[1,2.98,26.42],[2,1.93,53.76]],"ltp":3.05,"tv":459.82,"id":19587212}]}]}
{"op":"mcm","clk":"11793077606","pt":1723062381733,"mc":[{"id":"1.231541189","rc":[{"batb":[[0,3.05,4],[1,3,4],[2,2.98,26.42]],"ltp":3.05,"tv":459.82,"id":19587212}]}]}
{"op":"mcm","clk":"11793077699","pt":1723062384142,"mc":[{"id":"1.231541189","rc":[{"batb":[[0,3,4],[1,2.98,26.42],[2,1.93,53.76]],"ltp":3.05,"tv":459.82,"id":19587212}]}]}
{"op":"mcm","clk":"11793077902","pt":1723062389156,"mc":[{"id":"1.231541189","rc":[{"batb":[[0,3.05,4],[1,3,4],[2,2.98,26.42]],"ltp":3.05,"tv":459.82,"id":19587212}]}]}
{"op":"mcm","clk":"11793078008","pt":1723062391772,"mc":[{"id":"1.231541189","rc":[{"batb":[[0,3,4],[1,2.98,26.42],[2,1.93,53.76]],"ltp":3.05,"tv":459.82,"id":19587212}]}]}
{"op":"mcm","clk":"11793078159","pt":1723062395165,"mc":[{"id":"1.231541189","rc":[{"batb":[[0,3.05,4],[1,3,4],[2,2.98,26.42]],"ltp":3.05,"tv":459.82,"id":19587212}]}]}
{"op":"mcm","clk":"11793078242","pt":1723062397373,"mc":[{"id":"1.231541189","rc":[{"batb":[[0,3,4],[1,2.98,26.42],[2,1.93,53.76]],"ltp":3.05,"tv":459.82,"id":19587212}]}]}
{"op":"mcm","clk":"11793078387","pt":1723062401176,"mc":[{"id":"1.231541189","rc":[{"batb":[[0,3.05,4],[1,3,4],[2,2.98,26.42]],"ltp":3.05,"tv":459.82,"id":19587212}]}]}
{"op":"mcm","clk":"11793078498","pt":1723062403492,"mc":[{"id":"1.231541189","rc":[{"batb":[[0,3,4],[1,2.98,26.42],[2,1.93,53.76]],"ltp":3.05,"tv":459.82,"id":19587212}]}]}
{"op":"mcm","clk":"11793078651","pt":1723062405752,"mc":[{"id":"1.231541189","rc":[{"batb":[[0,3.05,4],[1,3,4],[2,2.98,26.42]],"ltp":3.05,"tv":459.82,"id":19587212}]}]}
{"op":"mcm","clk":"11793078735","pt":1723062408065,"mc":[{"id":"1.231541189","rc":[{"batb":[[0,3,4],[1,2.98,26.42],[2,1.93,53.76]],"ltp":3.05,"tv":459.82,"id":19587212}]}]}
{"op":"mcm","clk":"11793078854","pt":1723062410384,"mc":[{"id":"1.231541189","rc":[{"batb":[[0,3.05,4],[1,3,4],[2,2.98,26.42]],"ltp":3.05,"tv":459.82,"id":19587212}]}]}
{"op":"mcm","clk":"11793078954","pt":1723062413161,"mc":[{"id":"1.231541189","rc":[{"batb":[[0,3,4],[1,2.98,26.42],[2,1.93,53.76]],"ltp":3.05,"tv":459.82,"id":19587212}]}]}
{"op":"mcm","clk":"11793079073","pt":1723062415993,"mc":[{"id":"1.231541189","rc":[{"batb":[[0,3.05,4],[1,3,4],[2,2.98,26.42]],"ltp":3.05,"tv":459.82,"id":19587212}]}]}
{"op":"mcm","clk":"11793079185","pt":1723062418309,"mc":[{"id":"1.231541189","rc":[{"batb":[[0,3,4],[1,2.98,26.42],[2,1.93,53.76]],"ltp":3.05,"tv":459.82,"id":19587212}]}]}
{"op":"mcm","clk":"11793079321","pt":1723062421192,"mc":[{"id":"1.231541189","rc":[{"batb":[[0,3.05,4],[1,3,4],[2,2.98,26.42]],"ltp":3.05,"tv":459.82,"id":19587212}]}]}
{"op":"mcm","clk":"11793079405","pt":1723062423513,"mc":[{"id":"1.231541189","rc":[{"batb":[[0,3,4],[1,2.98,26.42],[2,1.93,53.76]],"ltp":3.05,"tv":459.82,"id":19587212}]}]}
{"op":"mcm","clk":"11793079673","pt":1723062428416,"mc":[{"id":"1.231541189","rc":[{"batb":[[0,3.05,4],[1,3,4],[2,2.98,26.42]],"ltp":3.05,"tv":459.82,"id":19587212}]}]}
{"op":"mcm","clk":"11793079822","pt":1723062431405,"mc":[{"id":"1.231541189","rc":[{"batb":[[0,3,4],[1,2.98,26.42],[2,1.93,53.76]],"ltp":3.05,"tv":459.82,"id":19587212}]}]}
{"op":"mcm","clk":"11793079927","pt":1723062433925,"mc":[{"id":"1.231541189","rc":[{"batb":[[0,3.05,4],[1,3,4],[2,2.98,26.42]],"ltp":3.05,"tv":459.82,"id":19587212}]}]}
{"op":"mcm","clk":"11793080043","pt":1723062436091,"mc":[{"id":"1.231541189","rc":[{"batb":[[0,3,4],[1,2.98,26.42],[2,1.93,53.76]],"ltp":3.05,"tv":459.82,"id":19587212}]}]}
{"op":"mcm","clk":"11793080151","pt":1723062438499,"mc":[{"id":"1.231541189","rc":[{"batb":[[0,3.05,4],[1,3,4],[2,2.98,26.42]],"ltp":3.05,"tv":459.82,"id":19587212}]}]}
{"op":"mcm","clk":"11793080326","pt":1723062441028,"mc":[{"id":"1.231541189","rc":[{"batb":[[0,3,4],[1,2.98,26.42],[2,1.93,53.76]],"ltp":3.05,"tv":459.82,"id":19587212},{"batl":[[0,1.49,4],[1,1.5,4],[2,1.51,4]],"ltp":1.49,"tv":5693.78,"id":19587555}]}]}
{"op":"mcm","clk":"11793080450","pt":1723062443392,"mc":[{"id":"1.231541189","rc":[{"batb":[[0,3.05,4],[1,3,4],[2,2.98,26.42]],"ltp":3.05,"tv":459.82,"id":19587212}]}]}
{"op":"mcm","clk":"11793080471","pt":1723062443812,"mc":[{"id":"1.231541189","rc":[{"batl":[[0,1.5,4],[1,1.51,4],[2,1.72,26]],"ltp":1.49,"tv":5693.78,"id":19587555}]}]}
{"op":"mcm","clk":"11793080555","pt":1723062445704,"mc":[{"id":"1.231541189","rc":[{"batb":[[0,3,4],[1,2.98,26.42],[2,1.93,53.76]],"ltp":3.05,"tv":459.82,"id":19587212}]}]}
{"op":"mcm","clk":"11793080688","pt":1723062448099,"mc":[{"id":"1.231541189","rc":[{"batb":[[0,3.05,4],[1,3,4],[2,2.98,26.42]],"ltp":3.05,"tv":459.82,"id":19587212}]}]}
{"op":"mcm","clk":"11793080815","pt":1723062450322,"mc":[{"id":"1.231541189","rc":[{"batb":[[0,3,4],[1,2.98,26.42],[2,1.93,53.76]],"ltp":3.05,"tv":459.82,"id":19587212}]}]}
{"op":"mcm","clk":"11793080934","pt":1723062452906,"mc":[{"id":"1.231541189","rc":[{"batb":[[0,3.05,4],[1,3,4],[2,2.98,26.42]],"ltp":3.05,"tv":459.82,"id":19587212}]}]}
{"op":"mcm","clk":"11793081067","pt":1723062455229,"mc":[{"id":"1.231541189","rc":[{"batb":[[0,3,4],[1,2.98,26.42],[2,1.93,53.76]],"ltp":3.05,"tv":459.82,"id":19587212}]}]}
{"op":"mcm","clk":"11793081208","pt":1723062457652,"mc":[{"id":"1.231541189","rc":[{"batb":[[0,3.05,4],[1,3,4],[2,2.98,26.42]],"ltp":3.05,"tv":459.82,"id":19587212}]}]}
{"op":"mcm","clk":"11793081345","pt":1723062460121,"mc":[{"id":"1.231541189","rc":[{"batb":[[0,3,4],[1,2.98,26.42],[2,1.93,53.76]],"ltp":3.05,"tv":459.82,"id":19587212}]}]}
{"op":"mcm","clk":"11793081420","pt":1723062462334,"mc":[{"id":"1.231541189","rc":[{"batb":[[0,3.05,4],[1,3,4],[2,2.98,26.42]],"ltp":3.05,"tv":459.82,"id":19587212}]}]}
{"op":"mcm","clk":"11793081542","pt":1723062464859,"mc":[{"id":"1.231541189","rc":[{"batb":[[0,3,4],[1,2.98,26.42],[2,1.93,53.76]],"ltp":3.05,"tv":459.82,"id":19587212}]}]}
{"op":"mcm","clk":"11793081667","pt":1723062467438,"mc":[{"id":"1.231541189","rc":[{"batb":[[0,3.05,4],[1,3,4],[2,2.98,26.42]],"ltp":3.05,"tv":459.82,"id":19587212}]}]}
{"op":"mcm","clk":"11793081780","pt":1723062469784,"mc":[{"id":"1.231541189","rc":[{"batb":[[0,3,4],[1,2.98,26.42],[2,1.93,53.76]],"ltp":3.05,"tv":459.82,"id":19587212}]}]}
{"op":"mcm","clk":"11793081955","pt":1723062473136,"mc":[{"id":"1.231541189","rc":[{"batb":[[0,3.05,4],[1,3,4],[2,2.98,26.42]],"ltp":3.05,"tv":459.82,"id":19587212}]}]}
{"op":"mcm","clk":"11793082063","pt":1723062475457,"mc":[{"id":"1.231541189","rc":[{"batb":[[0,3,4],[1,2.98,26.42],[2,1.93,53.76]],"ltp":3.05,"tv":459.82,"id":19587212}]}]}
{"op":"mcm","clk":"11793082173","pt":1723062477874,"mc":[{"id":"1.231541189","rc":[{"batb":[[0,3.05,4],[1,3,4],[2,2.98,26.42]],"ltp":3.05,"tv":459.82,"id":19587212}]}]}
{"op":"mcm","clk":"11793082272","pt":1723062480155,"mc":[{"id":"1.231541189","rc":[{"batb":[[0,3,4],[1,2.98,26.42],[2,1.93,53.76]],"ltp":3.05,"tv":459.82,"id":19587212}]}]}
{"op":"mcm","clk":"11793082433","pt":1723062483781,"mc":[{"id":"1.231541189","rc":[{"batb":[[0,3.05,4],[1,3,4],[2,2.98,26.42]],"ltp":3.05,"tv":459.82,"id":19587212}]}]}
{"op":"mcm","clk":"11793082558","pt":1723062486053,"mc":[{"id":"1.231541189","rc":[{"batb":[[0,3,4],[1,2.98,26.42],[2,1.93,53.76]],"ltp":3.05,"tv":459.82,"id":19587212}]}]}
{"op":"mcm","clk":"11793082674","pt":1723062488373,"mc":[{"id":"1.231541189","rc":[{"batb":[[0,3.05,4],[1,3,4],[2,2.98,26.42]],"ltp":3.05,"tv":459.82,"id":19587212}]}]}
{"op":"mcm","clk":"11793082805","pt":1723062490797,"mc":[{"id":"1.231541189","rc":[{"batb":[[0,3,4],[1,2.98,26.42],[2,1.93,53.76]],"ltp":3.05,"tv":459.82,"id":19587212}]}]}
{"op":"mcm","clk":"11793082937","pt":1723062493588,"mc":[{"id":"1.231541189","rc":[{"batb":[[0,3.05,4],[1,3,4],[2,2.98,26.42]],"ltp":3.05,"tv":459.82,"id":19587212}]}]}
{"op":"mcm","clk":"11793083078","pt":1723062495901,"mc":[{"id":"1.231541189","rc":[{"batb":[[0,3,4],[1,2.98,26.42],[2,1.93,53.76]],"ltp":3.05,"tv":459.82,"id":19587212}]}]}
{"op":"mcm","clk":"11793083237","pt":1723062498178,"mc":[{"id":"1.231541189","rc":[{"batb":[[0,3.05,4],[1,3,4],[2,2.98,26.42]],"ltp":3.05,"tv":459.82,"id":19587212}]}]}
{"op":"mcm","clk":"11793083356","pt":1723062500393,"mc":[{"id":"1.231541189","rc":[{"batb":[[0,3,4],[1,2.98,26.42],[2,1.93,53.76]],"ltp":3.05,"tv":459.82,"id":19587212}]}]}
{"op":"mcm","clk":"11793083544","pt":1723062503994,"mc":[{"id":"1.231541189","rc":[{"batb":[[0,3.05,4],[1,3,4],[2,2.98,26.42]],"ltp":3.05,"tv":459.82,"id":19587212}]}]}
{"op":"mcm","clk":"11793083613","pt":1723062506097,"mc":[{"id":"1.231541189","rc":[{"batb":[[0,3,4],[1,2.98,26.42],[2,1.93,53.76]],"ltp":3.05,"tv":459.82,"id":19587212}]}]}
{"op":"mcm","clk":"11793083745","pt":1723062510209,"mc":[{"id":"1.231541189","rc":[{"batb":[[0,3.05,4],[1,3,4],[2,2.98,26.42]],"ltp":3.05,"tv":459.82,"id":19587212}]}]}
{"op":"mcm","clk":"11793083838","pt":1723062512723,"mc":[{"id":"1.231541189","rc":[{"batb":[[0,3,4],[1,2.98,26.42],[2,1.93,53.76]],"ltp":3.05,"tv":459.82,"id":19587212}]}]}
{"op":"mcm","clk":"11793084058","pt":1723062517711,"mc":[{"id":"1.231541189","rc":[{"batb":[[0,3.05,4],[1,3,4],[2,2.98,26.42]],"ltp":3.05,"tv":459.82,"id":19587212}]}]}
{"op":"mcm","clk":"11793084150","pt":1723062520327,"mc":[{"id":"1.231541189","rc":[{"batb":[[0,3,4],[1,2.98,26.42],[2,1.93,53.76]],"ltp":3.05,"tv":459.82,"id":19587212}]}]}
{"op":"mcm","clk":"11793084314","pt":1723062524332,"mc":[{"id":"1.231541189","rc":[{"batb":[[0,3.05,4],[1,3,4],[2,2.98,26.42]],"ltp":3.05,"tv":459.82,"id":19587212},{"batl":[[2,1.53,21.52]],"ltp":1.49,"tv":5693.78,"id":19587555}]}]}
{"op":"mcm","clk":"11793084367","pt":1723062526223,"mc":[{"id":"1.231541189","rc":[{"batb":[[0,3,4],[1,2.98,26.42],[2,1.93,53.76]],"ltp":3.05,"tv":459.82,"id":19587212}]}]}
{"op":"mcm","clk":"11793084470","pt":1723062529159,"mc":[{"id":"1.231541189","rc":[{"batb":[[0,3.05,4],[1,3,4],[2,2.98,26.42]],"ltp":3.05,"tv":459.82,"id":19587212}]}]}
{"op":"mcm","clk":"11793084597","pt":1723062532454,"mc":[{"id":"1.231541189","rc":[{"batb":[[0,3,4],[1,2.98,26.42],[2,1.93,53.76]],"ltp":3.05,"tv":459.82,"id":19587212}]}]}
{"op":"mcm","clk":"11793084721","pt":1723062535738,"mc":[{"id":"1.231541189","rc":[{"batb":[[0,3.05,4],[1,3,4],[2,2.98,26.42]],"ltp":3.05,"tv":459.82,"id":19587212}]}]}
{"op":"mcm","clk":"11793084796","pt":1723062538255,"mc":[{"id":"1.231541189","rc":[{"batb":[[0,3,4],[1,2.98,26.42],[2,1.93,53.76]],"ltp":3.05,"tv":459.82,"id":19587212}]}]}
{"op":"mcm","clk":"11793084960","pt":1723062542460,"mc":[{"id":"1.231541189","rc":[{"batb":[[0,3.05,4],[1,3,4],[2,2.98,26.42]],"ltp":3.05,"tv":459.82,"id":19587212}]}]}
{"op":"mcm","clk":"11793085051","pt":1723062544740,"mc":[{"id":"1.231541189","rc":[{"batb":[[0,3,4],[1,2.98,26.42],[2,1.93,53.76]],"ltp":3.05,"tv":459.82,"id":19587212}]}]}
{"op":"mcm","clk":"11793085108","pt":1723062546183,"mc":[{"id":"1.231541189","rc":[{"batl":[[0,1.5,25.52],[2,1.72,26]],"ltp":1.49,"tv":5693.78,"id":19587555}]}]}
{"op":"mcm","clk":"11793085199","pt":1723062548091,"mc":[{"id":"1.231541189","rc":[{"batb":[[0,3.05,4],[1,3,4],[2,2.98,26.42]],"ltp":3.05,"tv":459.82,"id":19587212}]}]}
{"op":"mcm","clk":"11793085313","pt":1723062550666,"mc":[{"id":"1.231541189","rc":[{"batb":[[0,3,4],[1,2.98,26.42],[2,1.93,53.76]],"ltp":3.05,"tv":459.82,"id":19587212}]}]}
{"op":"mcm","clk":"11793085402","pt":1723062553081,"mc":[{"id":"1.231541189","rc":[{"batb":[[0,3.05,4],[1,3,4],[2,2.98,26.42]],"ltp":3.05,"tv":459.82,"id":19587212}]}]}
{"op":"mcm","clk":"11793085478","pt":1723062555590,"mc":[{"id":"1.231541189","rc":[{"batb":[[0,3,4],[1,2.98,26.42],[2,1.93,53.76]],"ltp":3.05,"tv":459.82,"id":19587212}]}]}
{"op":"mcm","clk":"11793085627","pt":1723062559491,"mc":[{"id":"1.231541189","rc":[{"batb":[[0,3.05,4],[1,3,4],[2,2.98,26.42]],"ltp":3.05,"tv":459.82,"id":19587212}]}]}
{"op":"mcm","clk":"11793085713","pt":1723062561904,"mc":[{"id":"1.231541189","rc":[{"batl":[[0,1.49,4],[1,1.5,25.52],[2,1.51,4]],"ltp":1.49,"tv":5693.78,"id":19587555}]}]}
{"op":"mcm","clk":"11793085812","pt":1723062564691,"mc":[{"id":"1.231541189","rc":[{"batb":[[0,3.1,4],[1,3.05,4],[2,3,4]],"ltp":3.05,"tv":459.82,"id":19587212}]}]}
{"op":"mcm","clk":"11793085920","pt":1723062567008,"mc":[{"id":"1.231541189","rc":[{"batb":[[0,3.05,4],[1,3,4],[2,2.98,26.42]],"ltp":3.05,"tv":459.82,"id":19587212}]}]}
{"op":"mcm","clk":"11793086037","pt":1723062569583,"mc":[{"id":"1.231541189","rc":[{"batb":[[0,3.1,4],[1,3.05,4],[2,3,4]],"ltp":3.05,"tv":459.82,"id":19587212}]}]}
{"op":"mcm","clk":"11793086139","pt":1723062571997,"mc":[{"id":"1.231541189","rc":[{"batb":[[0,3.05,4],[1,3,4],[2,2.98,26.42]],"ltp":3.05,"tv":459.82,"id":19587212}]}]}
{"op":"mcm","clk":"11793086269","pt":1723062574926,"mc":[{"id":"1.231541189","rc":[{"batb":[[0,3.1,4],[1,3.05,4],[2,3,4]],"ltp":3.05,"tv":459.82,"id":19587212}]}]}
{"op":"mcm","clk":"11793086384","pt":1723062577197,"mc":[{"id":"1.231541189","rc":[{"batb":[[0,3.05,4],[1,3,4],[2,2.98,26.42]],"ltp":3.05,"tv":459.82,"id":19587212},{"batl":[[0,1.48,4],[1,1.49,4],[2,1.5,25.52]],"ltp":1.49,"tv":5693.78,"id":19587555}]}]}
{"op":"mcm","clk":"11793086500","pt":1723062580019,"mc":[{"id":"1.231541189","rc":[{"batb":[[0,3.1,4],[1,3.05,4],[2,3,4]],"ltp":3.05,"tv":459.82,"id":19587212},{"batl":[[0,1.49,4],[1,1.5,25.52],[2,1.51,4]],"ltp":1.49,"tv":5693.78,"id":19587555}]}]}
{"op":"mcm","clk":"11793086565","pt":1723062582227,"mc":[{"id":"1.231541189","rc":[{"batb":[[0,3.05,4],[1,3,4],[2,2.98,26.42]],"ltp":3.05,"tv":459.82,"id":19587212}]}]}
{"op":"mcm","clk":"11793086634","pt":1723062584434,"mc":[{"id":"1.231541189","rc":[{"batb":[[0,3.1,4],[1,3.05,4],[2,3,4]],"ltp":3.05,"tv":459.82,"id":19587212}]}]}
{"op":"mcm","clk":"11793086716","pt":1723062586722,"mc":[{"id":"1.231541189","rc":[{"batb":[[0,3.05,4],[1,3,4],[2,2.98,26.42]],"ltp":3.05,"tv":459.82,"id":19587212}]}]}
{"op":"mcm","clk":"11793086879","pt":1723062590625,"mc":[{"id":"1.231541189","rc":[{"batb":[[0,3.1,4],[1,3.05,4],[2,3,4]],"ltp":3.05,"tv":459.82,"id":19587212}]}]}
{"op":"mcm","clk":"11793086933","pt":1723062592121,"mc":[{"id":"1.231541189","rc":[{"batl":[[0,1.48,4],[1,1.49,4],[2,1.5,25.52]],"ltp":1.49,"tv":5693.78,"id":19587555}]}]}
{"op":"mcm","clk":"11793086985","pt":1723062593552,"mc":[{"id":"1.231541189","rc":[{"batb":[[0,3.05,4],[1,3,4],[2,2.98,26.42]],"ltp":3.05,"tv":459.82,"id":19587212},{"batl":[[0,1.49,4],[1,1.5,25.52],[2,1.51,4]],"ltp":1.49,"tv":5693.78,"id":19587555}]}]}
{"op":"mcm","clk":"11793087074","pt":1723062596842,"mc":[{"id":"1.231541189","rc":[{"batb":[[0,3.1,4],[1,3.05,4],[2,3,4]],"ltp":3.05,"tv":459.82,"id":19587212}]}]}
{"op":"mcm","clk":"11793087164","pt":1723062599160,"mc":[{"id":"1.231541189","rc":[{"batb":[[0,3.05,4],[1,3,4],[2,2.98,26.42]],"ltp":3.05,"tv":459.82,"id":19587212}]}]}
{"op":"mcm","clk":"11793087375","pt":1723062604570,"mc":[{"id":"1.231541189","rc":[{"batb":[[0,3.1,4],[1,3.05,4],[2,3,4]],"ltp":3.05,"tv":459.82,"id":19587212}]}]}
{"op":"mcm","clk":"11793087498","pt":1723062607248,"mc":[{"id":"1.231541189","rc":[{"batb":[[0,3.05,4],[1,3,4],[2,2.98,26.42]],"ltp":3.05,"tv":459.82,"id":19587212},{"batl":[[0,1.48,4],[1,1.49,4],[2,1.5,25.52]],"ltp":1.49,"tv":5693.78,"id":19587555}]}]}
{"op":"mcm","clk":"11793087559","pt":1723062608743,"mc":[{"id":"1.231541189","rc":[{"batl":[[0,1.49,4],[1,1.5,25.52],[2,1.51,4]],"ltp":1.49,"tv":5693.78,"id":19587555}]}]}
{"op":"mcm","clk":"11793087664","pt":1723062610952,"mc":[{"id":"1.231541189","rc":[{"batb":[[0,3.1,4],[1,3.05,4],[2,3,4]],"ltp":3.05,"tv":459.82,"id":19587212}]}]}
{"op":"mcm","clk":"11793087765","pt":1723062613269,"mc":[{"id":"1.231541189","rc":[{"batb":[[0,3.05,4],[1,3,4],[2,2.98,26.42]],"ltp":3.05,"tv":459.82,"id":19587212}]}]}
{"op":"mcm","clk":"11793087848","pt":1723062615541,"mc":[{"id":"1.231541189","rc":[{"batb":[[0,3.1,4],[1,3.05,4],[2,3,4]],"ltp":3.05,"tv":459.82,"id":19587212}]}]}
{"op":"mcm","clk":"11793087919","pt":1723062617852,"mc":[{"id":"1.231541189","rc":[{"batb":[[0,3.05,4],[1,3,4],[2,2.98,26.42]],"ltp":3.05,"tv":459.82,"id":19587212}]}]}
{"op":"mcm","clk":"11793088083","pt":1723062621967,"mc":[{"id":"1.231541189","rc":[{"batb":[[0,3.1,4],[1,3.05,4],[2,3,4]],"ltp":3.05,"tv":459.82,"id":19587212}]}]}
{"op":"mcm","clk":"11793088172","pt":1723062624281,"mc":[{"id":"1.231541189","rc":[{"batb":[[0,3.05,4],[1,3,4],[2,2.98,26.42]],"ltp":3.05,"tv":459.82,"id":19587212}]}]}
{"op":"mcm","clk":"11793088256","pt":1723062626798,"mc":[{"id":"1.231541189","rc":[{"batb":[[0,3.1,4],[1,3.05,4],[2,3,4]],"ltp":3.05,"tv":459.82,"id":19587212}]}]}
{"op":"mcm","clk":"11793088326","pt":1723062629006,"mc":[{"id":"1.231541189","rc":[{"batb":[[0,3.05,4],[1,3,4],[2,2.98,26.42]],"ltp":3.05,"tv":459.82,"id":19587212}]}]}
{"op":"mcm","clk":"11793088449","pt":1723062631994,"mc":[{"id":"1.231541189","rc":[{"batb":[[0,3.1,4],[1,3.05,4],[2,3,4]],"ltp":3.05,"tv":459.82,"id":19587212}]}]}
{"op":"mcm","clk":"11793088536","pt":1723062634516,"mc":[{"id":"1.231541189","rc":[{"batb":[[0,3.05,4],[1,3,4],[2,2.98,26.42]],"ltp":3.05,"tv":459.82,"id":19587212}]}]}
{"op":"mcm","clk":"11793088711","pt":1723062638583,"mc":[{"id":"1.231541189","rc":[{"batb":[[0,3.1,4],[1,3.05,4],[2,3,4]],"ltp":3.05,"tv":459.82,"id":19587212}]}]}
{"op":"mcm","clk":"11793088793","pt":1723062640996,"mc":[{"id":"1.231541189","rc":[{"batb":[[0,3.05,4],[1,3,4],[2,2.98,26.42]],"ltp":3.05,"tv":459.82,"id":19587212}]}]}
{"op":"mcm","clk":"11793088920","pt":1723062644399,"mc":[{"id":"1.231541189","rc":[{"batb":[[0,3.1,4],[1,3.05,4],[2,3,4]],"ltp":3.05,"tv":459.82,"id":19587212}]}]}
{"op":"mcm","clk":"11793088981","pt":1723062646614,"mc":[{"id":"1.231541189","rc":[{"batb":[[0,3.05,4],[1,3,4],[2,2.98,26.42]],"ltp":3.05,"tv":459.82,"id":19587212}]}]}
{"op":"mcm","clk":"11793089051","pt":1723062649031,"mc":[{"id":"1.231541189","rc":[{"batb":[[0,3.1,4],[1,3.05,4],[2,3,4]],"ltp":3.05,"tv":459.82,"id":19587212}]}]}
{"op":"mcm","clk":"11793089155","pt":1723062651404,"mc":[{"id":"1.231541189","rc":[{"batb":[[0,3.05,4],[1,3,4],[2,2.98,26.42]],"ltp":3.05,"tv":459.82,"id":19587212}]}]}
{"op":"mcm","clk":"11793089303","pt":1723062655620,"mc":[{"id":"1.231541189","rc":[{"batb":[[0,3.1,4],[1,3.05,4],[2,3,4]],"ltp":3.05,"tv":459.82,"id":19587212}]}]}
{"op":"mcm","clk":"11793089406","pt":1723062657934,"mc":[{"id":"1.231541189","rc":[{"batb":[[0,3.05,4],[1,3,4],[2,2.98,26.42]],"ltp":3.05,"tv":459.82,"id":19587212}]}]}
{"op":"mcm","clk":"11793089542","pt":1723062660921,"mc":[{"id":"1.231541189","rc":[{"batb":[[0,3.1,4],[1,3.05,4],[2,3,4]],"ltp":3.05,"tv":459.82,"id":19587212}]}]}
{"op":"mcm","clk":"11793089641","pt":1723062663131,"mc":[{"id":"1.231541189","rc":[{"batb":[[0,3.05,4],[1,3,4],[2,2.98,26.42]],"ltp":3.05,"tv":459.82,"id":19587212}]}]}
{"op":"mcm","clk":"11793089732","pt":1723062665241,"mc":[{"id":"1.231541189","rc":[{"batb":[[0,3.1,4],[1,3.05,4],[2,3,4]],"ltp":3.05,"tv":459.82,"id":19587212}]}]}
{"op":"mcm","clk":"11793089777","pt":1723062666166,"mc":[{"id":"1.231541189","rc":[{"trd":[[1.46,7.44]],"batb":[[0,1.45,33.19],[1,1.44,100.93],[2,1.38,3.67]],"ltp":1.46,"tv":5697.22,"id":19587555}],"tv":6157.05}]}
{"op":"mcm","clk":"11793089867","pt":1723062667761,"mc":[{"id":"1.231541189","rc":[{"batb":[[0,3.05,4],[1,3,4],[2,2.98,26.42]],"ltp":3.05,"tv":459.82,"id":19587212},{"batl":[[0,1.48,4],[1,1.49,4],[2,1.5,25.52]],"ltp":1.46,"tv":5697.22,"id":19587555}]}]}
{"op":"mcm","clk":"11793089987","pt":1723062670533,"mc":[{"id":"1.231541189","rc":[{"batb":[[0,3.1,4],[1,3.05,4],[2,3,4]],"ltp":3.05,"tv":459.82,"id":19587212},{"batl":[[0,1.49,4],[1,1.5,25.52],[2,1.51,4]],"ltp":1.46,"tv":5697.22,"id":19587555}]}]}
{"op":"mcm","clk":"11793090059","pt":1723062672432,"mc":[{"id":"1.231541189","rc":[{"batb":[[0,3.05,4],[1,3,4],[2,2.98,26.42]],"ltp":3.05,"tv":459.82,"id":19587212}]}]}
{"op":"mcm","clk":"11793090146","pt":1723062674641,"mc":[{"id":"1.231541189","rc":[{"batb":[[0,3.1,4],[1,3.05,4],[2,3,4]],"ltp":3.05,"tv":459.82,"id":19587212}]}]}
{"op":"mcm","clk":"11793090259","pt":1723062677159,"mc":[{"id":"1.231541189","rc":[{"batb":[[0,3.05,4],[1,3,4],[2,2.98,26.42]],"ltp":3.05,"tv":459.82,"id":19587212}]}]}
{"op":"mcm","clk":"11793090367","pt":1723062680449,"mc":[{"id":"1.231541189","rc":[{"trd":[[3.2,3.68]],"batb":[[0,3.1,4],[1,3.05,4],[2,3,4]],"batl":[[0,3.25,4.32],[1,3.25,0]],"ltp":3.2,"tv":463.5,"id":19587212},{"trd":[[1.45,73.94],[1.46,8.01]],"batb":[[0,1.44,100.93],[1,1.38,3.67],[2,1.3,11.86]],"ltp":1.45,"tv":5771.73,"id":19587555}],"tv":6235.23}]}
{"op":"mcm","clk":"11793090392","pt":1723062681063,"mc":[{"id":"1.231541189","rc":[{"batl":[[0,3.25,4]],"ltp":3.2,"tv":463.5,"id":19587212}]}]}
{"op":"mcm","clk":"11793090435","pt":1723062682351,"mc":[{"id":"1.231541189","rc":[{"batl":[[0,1.48,8.09],[1,1.49,4],[2,1.5,25.52]],"ltp":1.45,"tv":5771.73,"id":19587555}]}]}
{"op":"mcm","clk":"11793090480","pt":1723062683172,"mc":[{"id":"1.231541189","rc":[{"batb":[[0,3.05,4],[1,3,4],[2,2.98,26.42]],"ltp":3.2,"tv":463.5,"id":19587212},{"batb":[[0,1.44,104.93]],"batl":[[0,1.48,12.09]],"ltp":1.45,"tv":5771.73,"id":19587555}]}]}
{"op":"mcm","clk":"11793090559","pt":1723062685077,"mc":[{"id":"1.231541189","rc":[{"batl":[[0,1.49,4],[1,1.5,25.52],[2,1.51,4]],"ltp":1.45,"tv":5771.73,"id":19587555}]}]}
{"op":"mcm","clk":"11793090651","pt":1723062687446,"mc":[{"id":"1.231541189","rc":[{"batb":[[0,3.1,4],[1,3.05,4],[2,3,4]],"ltp":3.2,"tv":463.5,"id":19587212}]}]}
{"op":"mcm","clk":"11793090735","pt":1723062689759,"mc":[{"id":"1.231541189","rc":[{"batb":[[0,3.05,4],[1,3,4],[2,2.98,26.42]],"ltp":3.2,"tv":463.5,"id":19587212}]}]}
{"op":"mcm","clk":"11793090866","pt":1723062692991,"mc":[{"id":"1.231541189","rc":[{"batb":[[0,3.1,4],[1,3.05,4],[2,3,4]],"ltp":3.2,"tv":463.5,"id":19587212},{"batl":[[0,1.49,12.03]],"ltp":1.45,"tv":5771.73,"id":19587555}]}]}
{"op":"mcm","clk":"11793090959","pt":1723062695258,"mc":[{"id":"1.231541189","rc":[{"batb":[[0,3.05,4],[1,3,4],[2,2.98,26.42]],"ltp":3.2,"tv":463.5,"id":19587212}]}]}
{"op":"mcm","clk":"11793091070","pt":1723062699266,"mc":[{"id":"1.231541189","rc":[{"batb":[[0,3.1,4],[1,3.05,4],[2,3,4]],"ltp":3.2,"tv":463.5,"id":19587212}]}]}
{"op":"mcm","clk":"11793091162","pt":1723062701574,"mc":[{"id":"1.231541189","rc":[{"batb":[[0,3.05,4],[1,3,4],[2,2.98,26.42]],"ltp":3.2,"tv":463.5,"id":19587212}]}]}
{"op":"mcm","clk":"11793091255","pt":1723062703889,"mc":[{"id":"1.231541189","rc":[{"batb":[[0,3.1,4],[1,3.05,4],[2,3,4]],"ltp":3.2,"tv":463.5,"id":19587212},{"trd":[[1.44,86.08]],"batb":[[0,1.44,61.89]],"batl":[[0,1.49,38.03]],"ltp":1.44,"tv":5857.8,"id":19587555}],"tv":6321.31}]}
{"op":"mcm","clk":"11793091332","pt":1723062706095,"mc":[{"id":"1.231541189","rc":[{"batb":[[0,3.05,4],[1,3,4],[2,2.98,26.42]],"ltp":3.2,"tv":463.5,"id":19587212}]}]}
{"op":"mcm","clk":"11793091388","pt":1723062707896,"mc":[{"id":"1.231541189","rc":[{"batb":[[0,1.44,104.93]],"ltp":1.44,"tv":5857.8,"id":19587555}]}]}
{"op":"mcm","clk":"11793091473","pt":1723062710167,"mc":[{"id":"1.231541189","rc":[{"batb":[[0,3.1,4],[1,3.05,4],[2,3,4]],"ltp":3.2,"tv":463.5,"id":19587212}]}]}
{"op":"mcm","clk":"11793091547","pt":1723062712377,"mc":[{"id":"1.231541189","rc":[{"batb":[[0,3.05,4],[1,3,4],[2,2.98,26.42]],"ltp":3.2,"tv":463.5,"id":19587212}]}]}
{"op":"mcm","clk":"11793091586","pt":1723062713407,"mc":[{"id":"1.231541189","rc":[{"batl":[[0,1.48,4],[1,1.49,38.03],[2,1.5,25.52]],"ltp":1.44,"tv":5857.8,"id":19587555}]}]}
{"op":"mcm","clk":"11793091650","pt":1723062715878,"mc":[{"id":"1.231541189","rc":[{"batb":[[0,3.1,4],[1,3.05,4],[2,3,4]],"ltp":3.2,"tv":463.5,"id":19587212}]}]}
{"op":"mcm","clk":"11793091726","pt":1723062718294,"mc":[{"id":"1.231541189","rc":[{"batb":[[0,3.05,4],[1,3,4],[2,2.98,26.42]],"ltp":3.2,"tv":463.5,"id":19587212}]}]}
{"op":"mcm","clk":"11793091861","pt":1723062721228,"mc":[{"id":"1.231541189","rc":[{"batb":[[0,3.1,4],[1,3.05,4],[2,3,4]],"ltp":3.2,"tv":463.5,"id":19587212}]}]}
{"op":"mcm","clk":"11793091987","pt":1723062723502,"mc":[{"id":"1.231541189","rc":[{"batb":[[0,3.05,4],[1,3,4],[2,2.98,26.42]],"ltp":3.2,"tv":463.5,"id":19587212}]}]}
{"op":"mcm","clk":"11793092129","pt":1723062726333,"mc":[{"id":"1.231541189","rc":[{"batb":[[0,3.1,4],[1,3.05,4],[2,3,4]],"ltp":3.2,"tv":463.5,"id":19587212}]}]}
{"op":"mcm","clk":"11793092231","pt":1723062728701,"mc":[{"id":"1.231541189","rc":[{"batb":[[0,3.05,4],[1,3,4],[2,2.98,26.42]],"ltp":3.2,"tv":463.5,"id":19587212}]}]}
{"op":"mcm","clk":"11793092287","pt":1723062730141,"mc":[{"id":"1.231541189","rc":[{"batb":[[2,1.36,72.22]],"ltp":1.44,"tv":5857.8,"id":19587555}]}]}
{"op":"mcm","clk":"11793092359","pt":1723062731942,"mc":[{"id":"1.231541189","rc":[{"batb":[[0,3.1,4],[1,3.05,4],[2,3,4]],"ltp":3.2,"tv":463.5,"id":19587212}]}]}
{"op":"mcm","clk":"11793092450","pt":1723062734310,"mc":[{"id":"1.231541189","rc":[{"batb":[[0,3.05,4],[1,3,4],[2,2.98,26.42]],"ltp":3.2,"tv":463.5,"id":19587212}]}]}
{"op":"mcm","clk":"11793092584","pt":1723062738226,"mc":[{"id":"1.231541189","rc":[{"batb":[[0,3.1,4],[1,3.05,4],[2,3,4]],"ltp":3.2,"tv":463.5,"id":19587212}]}]}
{"op":"mcm","clk":"11793092705","pt":1723062740851,"mc":[{"id":"1.231541189","rc":[{"batb":[[0,3.05,4],[1,3,4],[2,2.98,26.42]],"ltp":3.2,"tv":463.5,"id":19587212}]}]}
{"op":"mcm","clk":"11793092832","pt":1723062744355,"mc":[{"id":"1.231541189","rc":[{"batb":[[0,3.1,4],[1,3.05,4],[2,3,4]],"ltp":3.2,"tv":463.5,"id":19587212}]}]}
{"op":"mcm","clk":"11793092944","pt":1723062746927,"mc":[{"id":"1.231541189","rc":[{"batb":[[0,3.05,4],[1,3,4],[2,2.98,26.42]],"ltp":3.2,"tv":463.5,"id":19587212}]}]}
{"op":"mcm","clk":"11793093088","pt":1723062750528,"mc":[{"id":"1.231541189","rc":[{"batb":[[0,3.1,4],[1,3.05,4],[2,3,4]],"ltp":3.2,"tv":463.5,"id":19587212}]}]}
{"op":"mcm","clk":"11793093202","pt":1723062753251,"mc":[{"id":"1.231541189","rc":[{"batb":[[0,3.05,4],[1,3,4],[2,2.98,26.42]],"ltp":3.2,"tv":463.5,"id":19587212}]}]}
{"op":"mcm","clk":"11793093363","pt":1723062756559,"mc":[{"id":"1.231541189","rc":[{"batb":[[0,3.1,4],[1,3.05,4],[2,3,4]],"ltp":3.2,"tv":463.5,"id":19587212}]}]}
{"op":"mcm","clk":"11793093496","pt":1723062759033,"mc":[{"id":"1.231541189","rc":[{"batb":[[0,3.05,4],[1,3,4],[2,2.98,26.42]],"ltp":3.2,"tv":463.5,"id":19587212}]}]}
{"op":"mcm","clk":"11793093645","pt":1723062762780,"mc":[{"id":"1.231541189","rc":[{"batb":[[0,3.1,4],[1,3.05,4],[2,3,4]],"ltp":3.2,"tv":463.5,"id":19587212}]}]}
{"op":"mcm","clk":"11793093722","pt":1723062765047,"mc":[{"id":"1.231541189","rc":[{"batb":[[0,3.05,4],[1,3,4],[2,2.98,26.42]],"ltp":3.2,"tv":463.5,"id":19587212}]}]}
{"op":"mcm","clk":"11793093830","pt":1723062768364,"mc":[{"id":"1.231541189","rc":[{"batb":[[0,3.1,4],[1,3.05,4],[2,3,4]],"ltp":3.2,"tv":463.5,"id":19587212}]}]}
{"op":"mcm","clk":"11793093928","pt":1723062770776,"mc":[{"id":"1.231541189","rc":[{"batb":[[0,3.05,4],[1,3,4],[2,2.98,26.42]],"ltp":3.2,"tv":463.5,"id":19587212}]}]}
{"op":"mcm","clk":"11793094012","pt":1723062773090,"mc":[{"id":"1.231541189","rc":[{"batb":[[0,3.1,4],[1,3.05,4],[2,3,4]],"ltp":3.2,"tv":463.5,"id":19587212}]}]}
{"op":"mcm","clk":"11793094087","pt":1723062775296,"mc":[{"id":"1.231541189","rc":[{"batb":[[0,3.05,4],[1,3,4],[2,2.98,26.42]],"ltp":3.2,"tv":463.5,"id":19587212}]}]}
{"op":"mcm","clk":"11793094226","pt":1723062778487,"mc":[{"id":"1.231541189","rc":[{"batb":[[0,3.1,4],[1,3.05,4],[2,3,4]],"ltp":3.2,"tv":463.5,"id":19587212}]}]}
{"op":"mcm","clk":"11793094333","pt":1723062780897,"mc":[{"id":"1.231541189","rc":[{"batb":[[0,3.05,4],[1,3,4],[2,2.98,26.42]],"ltp":3.2,"tv":463.5,"id":19587212}]}]}
{"op":"mcm","clk":"11793094427","pt":1723062783275,"mc":[{"id":"1.231541189","rc":[{"batb":[[0,3.1,4],[1,3.05,4],[2,3,4]],"ltp":3.2,"tv":463.5,"id":19587212}]}]}
{"op":"mcm","clk":"11793094540","pt":1723062785594,"mc":[{"id":"1.231541189","rc":[{"batb":[[0,3.05,4],[1,3,4],[2,2.98,26.42]],"ltp":3.2,"tv":463.5,"id":19587212}]}]}
{"op":"mcm","clk":"11793094684","pt":1723062789200,"mc":[{"id":"1.231541189","rc":[{"batb":[[0,3.1,4],[1,3.05,4],[2,3,4]],"ltp":3.2,"tv":463.5,"id":19587212}]}]}
{"op":"mcm","clk":"11793094820","pt":1723062791685,"mc":[{"id":"1.231541189","rc":[{"batb":[[0,3.05,4],[1,3,4],[2,2.98,26.42]],"ltp":3.2,"tv":463.5,"id":19587212}]}]}
{"op":"mcm","clk":"11793094929","pt":1723062795600,"mc":[{"id":"1.231541189","rc":[{"batb":[[0,3.1,4],[1,3.05,4],[2,3,4]],"ltp":3.2,"tv":463.5,"id":19587212}]}]}
{"op":"mcm","clk":"11793095064","pt":1723062798191,"mc":[{"id":"1.231541189","rc":[{"batb":[[0,3.05,4],[1,3,4],[2,2.98,26.42]],"ltp":3.2,"tv":463.5,"id":19587212}]}]}
{"op":"mcm","clk":"11793095285","pt":1723062802101,"mc":[{"id":"1.231541189","rc":[{"batb":[[0,3.1,4],[1,3.05,4],[2,3,4]],"ltp":3.2,"tv":463.5,"id":19587212}]}]}
{"op":"mcm","clk":"11793095399","pt":1723062804407,"mc":[{"id":"1.231541189","rc":[{"batb":[[0,3.05,4],[1,3,4],[2,2.98,26.42]],"ltp":3.2,"tv":463.5,"id":19587212}]}]}
{"op":"mcm","clk":"11793095651","pt":1723062809910,"mc":[{"id":"1.231541189","rc":[{"batb":[[0,3.1,4],[1,3.05,4],[2,3,4]],"ltp":3.2,"tv":463.5,"id":19587212}]}]}
{"op":"mcm","clk":"11793095768","pt":1723062812327,"mc":[{"id":"1.231541189","rc":[{"batb":[[0,3.05,4],[1,3,4],[2,2.98,26.42]],"ltp":3.2,"tv":463.5,"id":19587212}]}]}
{"op":"mcm","clk":"11793095893","pt":1723062815002,"mc":[{"id":"1.231541189","rc":[{"batb":[[0,3.1,4],[1,3.05,4],[2,3,4]],"ltp":3.2,"tv":463.5,"id":19587212}]}]}
{"op":"mcm","clk":"11793095999","pt":1723062817423,"mc":[{"id":"1.231541189","rc":[{"batb":[[0,3.05,4],[1,3,4],[2,2.98,26.42]],"ltp":3.2,"tv":463.5,"id":19587212}]}]}
{"op":"mcm","clk":"11793096186","pt":1723062822099,"mc":[{"id":"1.231541189","rc":[{"batb":[[0,3.1,4],[1,3.05,4],[2,3,4]],"ltp":3.2,"tv":463.5,"id":19587212}]}]}
{"op":"mcm","clk":"11793096260","pt":1723062824519,"mc":[{"id":"1.231541189","rc":[{"batb":[[0,3.05,4],[1,3,4],[2,2.98,26.42]],"ltp":3.2,"tv":463.5,"id":19587212}]}]}
{"op":"mcm","clk":"11793096488","pt":1723062830226,"mc":[{"id":"1.231541189","rc":[{"batb":[[0,3.1,4],[1,3.05,4],[2,3,4]],"ltp":3.2,"tv":463.5,"id":19587212}]}]}
{"op":"mcm","clk":"11793096570","pt":1723062832541,"mc":[{"id":"1.231541189","rc":[{"batb":[[0,3.05,4],[1,3,4],[2,2.98,26.42]],"ltp":3.2,"tv":463.5,"id":19587212}]}]}
{"op":"mcm","clk":"11793096743","pt":1723062836148,"mc":[{"id":"1.231541189","rc":[{"batb":[[0,3.1,4],[1,3.05,4],[2,3,4]],"ltp":3.2,"tv":463.5,"id":19587212}]}]}
{"op":"mcm","clk":"11793096837","pt":1723062838717,"mc":[{"id":"1.231541189","rc":[{"batb":[[0,3.05,4],[1,3,4],[2,2.98,26.42]],"ltp":3.2,"tv":463.5,"id":19587212}]}]}
{"op":"mcm","clk":"11793096914","pt":1723062841033,"mc":[{"id":"1.231541189","rc":[{"batb":[[0,3.1,4],[1,3.05,4],[2,3,4]],"ltp":3.2,"tv":463.5,"id":19587212}]}]}
{"op":"mcm","clk":"11793097013","pt":1723062843459,"mc":[{"id":"1.231541189","rc":[{"batb":[[0,3.05,4],[1,3,4],[2,2.98,26.42]],"ltp":3.2,"tv":463.5,"id":19587212}]}]}
{"op":"mcm","clk":"11793097157","pt":1723062847323,"mc":[{"id":"1.231541189","rc":[{"batb":[[0,3.1,4],[1,3.05,4],[2,3,4]],"ltp":3.2,"tv":463.5,"id":19587212}]}]}
{"op":"mcm","clk":"11793097235","pt":1723062849946,"mc":[{"id":"1.231541189","rc":[{"batb":[[0,3.05,4],[1,3,4],[2,2.98,26.42]],"ltp":3.2,"tv":463.5,"id":19587212}]}]}
{"op":"mcm","clk":"11793097380","pt":1723062853542,"mc":[{"id":"1.231541189","rc":[{"batb":[[0,3.1,4],[1,3.05,4],[2,3,4]],"ltp":3.2,"tv":463.5,"id":19587212}]}]}
{"op":"mcm","clk":"11793097481","pt":1723062855861,"mc":[{"id":"1.231541189","rc":[{"batb":[[0,3.05,4],[1,3,4],[2,2.98,26.42]],"ltp":3.2,"tv":463.5,"id":19587212}]}]}
{"op":"mcm","clk":"11793097788","pt":1723062861109,"mc":[{"id":"1.231541189","rc":[{"batb":[[0,3.1,4],[1,3.05,4],[2,3,4]],"ltp":3.2,"tv":463.5,"id":19587212}]}]}
{"op":"mcm","clk":"11793097885","pt":1723062863383,"mc":[{"id":"1.231541189","rc":[{"batb":[[0,3.05,4],[1,3,4],[2,2.98,26.42]],"ltp":3.2,"tv":463.5,"id":19587212}]}]}
{"op":"mcm","clk":"11793098020","pt":1723062867383,"mc":[{"id":"1.231541189","rc":[{"batb":[[0,3.1,4],[1,3.05,4],[2,3,4]],"ltp":3.2,"tv":463.5,"id":19587212}]}]}
{"op":"mcm","clk":"11793098191","pt":1723062870378,"mc":[{"id":"1.231541189","rc":[{"batb":[[0,3.05,4],[1,3,4],[2,2.98,26.42]],"ltp":3.2,"tv":463.5,"id":19587212},{"batb":[[0,1.45,5.59],[1,1.44,104.93],[2,1.38,3.67]],"ltp":1.44,"tv":5857.8,"id":19587555}]}]}
{"op":"mcm","clk":"11793098272","pt":1723062872072,"mc":[{"id":"1.231541189","rc":[{"batb":[[0,3.1,4],[1,3.05,4],[2,3,4]],"ltp":3.2,"tv":463.5,"id":19587212}]}]}
{"op":"mcm","clk":"11793098364","pt":1723062874384,"mc":[{"id":"1.231541189","rc":[{"batb":[[0,3.05,4],[1,3,4],[2,2.98,26.42]],"ltp":3.2,"tv":463.5,"id":19587212}]}]}
{"op":"mcm","clk":"11793098544","pt":1723062877887,"mc":[{"id":"1.231541189","rc":[{"batb":[[0,3.1,4],[1,3.05,4],[2,3,4]],"ltp":3.2,"tv":463.5,"id":19587212}]}]}
{"op":"mcm","clk":"11793098593","pt":1723062879119,"mc":[{"id":"1.231541189","rc":[{"batb":[[0,1.45,9.59]],"ltp":1.44,"tv":5857.8,"id":19587555}]}]}
{"op":"mcm","clk":"11793098628","pt":1723062880300,"mc":[{"id":"1.231541189","rc":[{"batb":[[0,3.05,4],[1,3,4],[2,2.98,26.42]],"ltp":3.2,"tv":463.5,"id":19587212}]}]}
{"op":"mcm","clk":"11793098761","pt":1723062883734,"mc":[{"id":"1.231541189","rc":[{"batb":[[0,3.1,4],[1,3.05,4],[2,3,4]],"ltp":3.2,"tv":463.5,"id":19587212}]}]}
{"op":"mcm","clk":"11793098852","pt":1723062885937,"mc":[{"id":"1.231541189","rc":[{"batb":[[0,3.05,4],[1,3,4],[2,2.98,26.42]],"ltp":3.2,"tv":463.5,"id":19587212}]}]}
{"op":"mcm","clk":"11793098991","pt":1723062889700,"mc":[{"id":"1.231541189","rc":[{"batb":[[0,3.1,4],[1,3.05,4],[2,3,4]],"ltp":3.2,"tv":463.5,"id":19587212}]}]}
{"op":"mcm","clk":"11793099130","pt":1723062892422,"mc":[{"id":"1.231541189","rc":[{"batb":[[0,3.05,4],[1,3,4],[2,2.98,26.42]],"ltp":3.2,"tv":463.5,"id":19587212}]}]}
{"op":"mcm","clk":"11793099273","pt":1723062896124,"mc":[{"id":"1.231541189","rc":[{"batb":[[0,3.1,4],[1,3.05,4],[2,3,4]],"ltp":3.2,"tv":463.5,"id":19587212}]}]}
{"op":"mcm","clk":"11793099367","pt":1723062898808,"mc":[{"id":"1.231541189","rc":[{"batb":[[0,3.05,4],[1,3,4],[2,2.98,26.42]],"ltp":3.2,"tv":463.5,"id":19587212}]}]}
{"op":"mcm","clk":"11793099500","pt":1723062901639,"mc":[{"id":"1.231541189","rc":[{"batb":[[0,3.1,4],[1,3.05,4],[2,3,4]],"ltp":3.2,"tv":463.5,"id":19587212}]}]}
{"op":"mcm","clk":"11793099574","pt":1723062903955,"mc":[{"id":"1.231541189","rc":[{"batb":[[0,3.05,4],[1,3,4],[2,2.98,26.42]],"ltp":3.2,"tv":463.5,"id":19587212}]}]}
{"op":"mcm","clk":"11793099738","pt":1723062908428,"mc":[{"id":"1.231541189","rc":[{"batb":[[0,3.1,4],[1,3.05,4],[2,3,4]],"ltp":3.2,"tv":463.5,"id":19587212}]}]}
{"op":"mcm","clk":"11793099825","pt":1723062910737,"mc":[{"id":"1.231541189","rc":[{"batb":[[0,3.05,4],[1,3,4],[2,2.98,26.42]],"ltp":3.2,"tv":463.5,"id":19587212}]}]}
{"op":"mcm","clk":"11793099923","pt":1723062913354,"mc":[{"id":"1.231541189","rc":[{"batb":[[0,3.1,4],[1,3.05,4],[2,3,4]],"ltp":3.2,"tv":463.5,"id":19587212}]}]}
{"op":"mcm","clk":"11793100031","pt":1723062916025,"mc":[{"id":"1.231541189","rc":[{"batb":[[0,3.05,4],[1,3,4],[2,2.98,26.42]],"ltp":3.2,"tv":463.5,"id":19587212}]}]}
{"op":"mcm","clk":"11793100077","pt":1723062917823,"mc":[{"id":"1.231541189","rc":[{"batb":[[0,3.1,4],[1,3.05,4],[2,3,4]],"ltp":3.2,"tv":463.5,"id":19587212}]}]}
{"op":"mcm","clk":"11793100165","pt":1723062920236,"mc":[{"id":"1.231541189","rc":[{"batb":[[0,3.05,4],[1,3,4],[2,2.98,26.42]],"ltp":3.2,"tv":463.5,"id":19587212}]}]}
{"op":"mcm","clk":"11793100251","pt":1723062922749,"mc":[{"id":"1.231541189","rc":[{"batb":[[0,3.1,4],[1,3.05,4],[2,3,4]],"ltp":3.2,"tv":463.5,"id":19587212}]}]}
{"op":"mcm","clk":"11793100352","pt":1723062925362,"mc":[{"id":"1.231541189","rc":[{"batb":[[0,3.05,4],[1,3,4],[2,2.98,26.42]],"ltp":3.2,"tv":463.5,"id":19587212}]}]}
{"op":"mcm","clk":"11793100443","pt":1723062927933,"mc":[{"id":"1.231541189","rc":[{"batb":[[0,3.1,4],[1,3.05,4],[2,3,4]],"ltp":3.2,"tv":463.5,"id":19587212}]}]}
{"op":"mcm","clk":"11793100521","pt":1723062930247,"mc":[{"id":"1.231541189","rc":[{"batb":[[0,3.05,4],[1,3,4],[2,2.98,26.42]],"ltp":3.2,"tv":463.5,"id":19587212}]}]}
{"op":"mcm","clk":"11793100644","pt":1723062933893,"mc":[{"id":"1.231541189","rc":[{"batb":[[0,3.1,4],[1,3.05,4],[2,3,4]],"ltp":3.2,"tv":463.5,"id":19587212}]}]}
{"op":"mcm","clk":"11793100735","pt":1723062936161,"mc":[{"id":"1.231541189","rc":[{"batb":[[0,3.05,4],[1,3,4],[2,2.98,26.42]],"ltp":3.2,"tv":463.5,"id":19587212}]}]}
{"op":"mcm","clk":"11793100842","pt":1723062938781,"mc":[{"id":"1.231541189","rc":[{"batb":[[0,3.1,4],[1,3.05,4],[2,3,4]],"ltp":3.2,"tv":463.5,"id":19587212}]}]}
{"op":"mcm","clk":"11793100918","pt":1723062941091,"mc":[{"id":"1.231541189","rc":[{"batb":[[0,3.05,4],[1,3,4],[2,2.98,26.42]],"ltp":3.2,"tv":463.5,"id":19587212}]}]}
{"op":"mcm","clk":"11793100989","pt":1723062944068,"mc":[{"id":"1.231541189","rc":[{"batb":[[0,3.1,4],[1,3.05,4],[2,3,4]],"ltp":3.2,"tv":463.5,"id":19587212}]}]}
{"op":"mcm","clk":"11793101049","pt":1723062946592,"mc":[{"id":"1.231541189","rc":[{"batb":[[0,3.05,4],[1,3,4],[2,2.98,26.42]],"ltp":3.2,"tv":463.5,"id":19587212}]}]}
{"op":"mcm","clk":"11793101101","pt":1723062948852,"mc":[{"id":"1.231541189","rc":[{"batb":[[0,3.1,4],[1,3.05,4],[2,3,4]],"ltp":3.2,"tv":463.5,"id":19587212}]}]}
{"op":"mcm","clk":"11793101191","pt":1723062951168,"mc":[{"id":"1.231541189","rc":[{"batb":[[0,3.05,4],[1,3,4],[2,2.98,26.42]],"ltp":3.2,"tv":463.5,"id":19587212}]}]}
{"op":"mcm","clk":"11793101265","pt":1723062953681,"mc":[{"id":"1.231541189","rc":[{"batb":[[0,3.1,4],[1,3.05,4],[2,3,4]],"ltp":3.2,"tv":463.5,"id":19587212}]}]}
{"op":"mcm","clk":"11793101329","pt":1723062955989,"mc":[{"id":"1.231541189","rc":[{"batb":[[0,3.05,4],[1,3,4],[2,2.98,26.42]],"ltp":3.2,"tv":463.5,"id":19587212}]}]}
{"op":"mcm","clk":"11793101450","pt":1723062959482,"mc":[{"id":"1.231541189","rc":[{"batb":[[0,3.1,4],[1,3.05,4],[2,3,4]],"ltp":3.2,"tv":463.5,"id":19587212}]}]}
{"op":"mcm","clk":"11793101560","pt":1723062962273,"mc":[{"id":"1.231541189","rc":[{"batb":[[0,3.05,4],[1,3,4],[2,2.98,26.42]],"ltp":3.2,"tv":463.5,"id":19587212}]}]}
{"op":"mcm","clk":"11793101636","pt":1723062964477,"mc":[{"id":"1.231541189","rc":[{"batb":[[0,3.1,4],[1,3.05,4],[2,3,4]],"ltp":3.2,"tv":463.5,"id":19587212}]}]}
{"op":"mcm","clk":"11793101721","pt":1723062966792,"mc":[{"id":"1.231541189","rc":[{"batb":[[0,3.05,4],[1,3,4],[2,2.98,26.42]],"ltp":3.2,"tv":463.5,"id":19587212}]}]}
{"op":"mcm","clk":"11793101803","pt":1723062969414,"mc":[{"id":"1.231541189","rc":[{"batb":[[0,3.1,4],[1,3.05,4],[2,3,4]],"ltp":3.2,"tv":463.5,"id":19587212}]}]}
{"op":"mcm","clk":"11793101873","pt":1723062971691,"mc":[{"id":"1.231541189","rc":[{"batb":[[0,3.05,4],[1,3,4],[2,2.98,26.42]],"ltp":3.2,"tv":463.5,"id":19587212}]}]}
{"op":"mcm","clk":"11793101971","pt":1723062974616,"mc":[{"id":"1.231541189","rc":[{"batb":[[0,3.1,4],[1,3.05,4],[2,3,4]],"ltp":3.2,"tv":463.5,"id":19587212}]}]}
{"op":"mcm","clk":"11793102058","pt":1723062977131,"mc":[{"id":"1.231541189","rc":[{"batb":[[0,3.05,4],[1,3,4],[2,2.98,26.42]],"ltp":3.2,"tv":463.5,"id":19587212}]}]}
{"op":"mcm","clk":"11793102157","pt":1723062979194,"mc":[{"id":"1.231541189","rc":[{"batb":[[0,3.1,4],[1,3.05,4],[2,3,4]],"ltp":3.2,"tv":463.5,"id":19587212}]}]}
{"op":"mcm","clk":"11793102257","pt":1723062981515,"mc":[{"id":"1.231541189","rc":[{"batb":[[0,3.05,4],[1,3,4],[2,2.98,26.42]],"ltp":3.2,"tv":463.5,"id":19587212}]}]}
{"op":"mcm","clk":"11793102422","pt":1723062985221,"mc":[{"id":"1.231541189","rc":[{"batb":[[0,3.1,4],[1,3.05,4],[2,3,4]],"ltp":3.2,"tv":463.5,"id":19587212}]}]}
{"op":"mcm","clk":"11793102487","pt":1723062987435,"mc":[{"id":"1.231541189","rc":[{"batb":[[0,3.05,4],[1,3,4],[2,2.98,26.42]],"ltp":3.2,"tv":463.5,"id":19587212}]}]}
{"op":"mcm","clk":"11793102638","pt":1723062991399,"mc":[{"id":"1.231541189","rc":[{"batb":[[0,3.1,4],[1,3.05,4],[2,3,4]],"ltp":3.2,"tv":463.5,"id":19587212}]}]}
{"op":"mcm","clk":"11793102732","pt":1723062993915,"mc":[{"id":"1.231541189","rc":[{"batb":[[0,3.05,4],[1,3,4],[2,2.98,26.42]],"ltp":3.2,"tv":463.5,"id":19587212}]}]}
{"op":"mcm","clk":"11793102867","pt":1723062997508,"mc":[{"id":"1.231541189","rc":[{"batb":[[0,3.1,4],[1,3.05,4],[2,3,4]],"ltp":3.2,"tv":463.5,"id":19587212}]}]}
{"op":"mcm","clk":"11793102935","pt":1723062999715,"mc":[{"id":"1.231541189","rc":[{"batb":[[0,3.05,4],[1,3,4],[2,2.98,26.42]],"ltp":3.2,"tv":463.5,"id":19587212}]}]}
{"op":"mcm","clk":"11793103009","pt":1723063002023,"mc":[{"id":"1.231541189","rc":[{"batb":[[0,3.1,4],[1,3.05,4],[2,3,4]],"ltp":3.2,"tv":463.5,"id":19587212}]}]}
{"op":"mcm","clk":"11793103075","pt":1723063004430,"mc":[{"id":"1.231541189","rc":[{"batb":[[0,3.05,4],[1,3,4],[2,2.98,26.42]],"ltp":3.2,"tv":463.5,"id":19587212}]}]}
{"op":"mcm","clk":"11793103147","pt":1723063006736,"mc":[{"id":"1.231541189","rc":[{"batb":[[0,3.1,4],[1,3.05,4],[2,3,4]],"ltp":3.2,"tv":463.5,"id":19587212}]}]}
{"op":"mcm","clk":"11793103231","pt":1723063009045,"mc":[{"id":"1.231541189","rc":[{"batb":[[0,3.05,4],[1,3,4],[2,2.98,26.42]],"ltp":3.2,"tv":463.5,"id":19587212}]}]}
{"op":"mcm","clk":"11793103420","pt":1723063013619,"mc":[{"id":"1.231541189","rc":[{"batb":[[0,3.1,4],[1,3.05,4],[2,3,4]],"ltp":3.2,"tv":463.5,"id":19587212}]}]}
{"op":"mcm","clk":"11793103504","pt":1723063016034,"mc":[{"id":"1.231541189","rc":[{"batb":[[0,3.05,4],[1,3,4],[2,2.98,26.42]],"ltp":3.2,"tv":463.5,"id":19587212}]}]}
{"op":"mcm","clk":"11793103594","pt":1723063018353,"mc":[{"id":"1.231541189","rc":[{"batb":[[0,3.1,4],[1,3.05,4],[2,3,4]],"ltp":3.2,"tv":463.5,"id":19587212}]}]}
{"op":"mcm","clk":"11793103704","pt":1723063020564,"mc":[{"id":"1.231541189","rc":[{"batb":[[0,3.05,4],[1,3,4],[2,2.98,26.42]],"ltp":3.2,"tv":463.5,"id":19587212}]}]}
{"op":"mcm","clk":"11793103776","pt":1723063023037,"mc":[{"id":"1.231541189","rc":[{"batb":[[0,3.1,4],[1,3.05,4],[2,3,4]],"ltp":3.2,"tv":463.5,"id":19587212}]}]}
{"op":"mcm","clk":"11793103868","pt":1723063025461,"mc":[{"id":"1.231541189","rc":[{"batb":[[0,3.05,4],[1,3,4],[2,2.98,26.42]],"ltp":3.2,"tv":463.5,"id":19587212}]}]}
{"op":"mcm","clk":"11793103976","pt":1723063027941,"mc":[{"id":"1.231541189","rc":[{"batb":[[0,3.1,4],[1,3.05,4],[2,3,4]],"ltp":3.2,"tv":463.5,"id":19587212}]}]}
{"op":"mcm","clk":"11793104069","pt":1723063030351,"mc":[{"id":"1.231541189","rc":[{"batb":[[0,3.05,4],[1,3,4],[2,2.98,26.42]],"ltp":3.2,"tv":463.5,"id":19587212}]}]}
{"op":"mcm","clk":"11793104192","pt":1723063034571,"mc":[{"id":"1.231541189","rc":[{"batb":[[0,3.1,4],[1,3.05,4],[2,3,4]],"ltp":3.2,"tv":463.5,"id":19587212}]}]}
{"op":"mcm","clk":"11793104276","pt":1723063037091,"mc":[{"id":"1.231541189","rc":[{"batb":[[0,3.05,4],[1,3,4],[2,2.98,26.42]],"ltp":3.2,"tv":463.5,"id":19587212}]}]}
{"op":"mcm","clk":"11793104350","pt":1723063039256,"mc":[{"id":"1.231541189","rc":[{"batb":[[0,3.1,4],[1,3.05,4],[2,3,4]],"ltp":3.2,"tv":463.5,"id":19587212}]}]}
{"op":"mcm","clk":"11793104457","pt":1723063042089,"mc":[{"id":"1.231541189","rc":[{"batb":[[0,3.05,4],[1,3,4],[2,2.98,26.42]],"ltp":3.2,"tv":463.5,"id":19587212}]}]}
{"op":"mcm","clk":"11793104553","pt":1723063044863,"mc":[{"id":"1.231541189","rc":[{"batb":[[0,3.1,4],[1,3.05,4],[2,3,4]],"ltp":3.2,"tv":463.5,"id":19587212}]}]}
{"op":"mcm","clk":"11793104634","pt":1723063047178,"mc":[{"id":"1.231541189","rc":[{"batb":[[0,3.05,4],[1,3,4],[2,2.98,26.42]],"ltp":3.2,"tv":463.5,"id":19587212}]}]}
{"op":"mcm","clk":"11793104733","pt":1723063049753,"mc":[{"id":"1.231541189","rc":[{"batb":[[0,3.1,4],[1,3.05,4],[2,3,4]],"ltp":3.2,"tv":463.5,"id":19587212}]}]}
{"op":"mcm","clk":"11793104814","pt":1723063052176,"mc":[{"id":"1.231541189","rc":[{"batb":[[0,3.05,4],[1,3,4],[2,2.98,26.42]],"ltp":3.2,"tv":463.5,"id":19587212}]}]}
{"op":"mcm","clk":"11793104893","pt":1723063054381,"mc":[{"id":"1.231541189","rc":[{"batb":[[0,3.1,4],[1,3.05,4],[2,3,4]],"ltp":3.2,"tv":463.5,"id":19587212}]}]}
{"op":"mcm","clk":"11793104980","pt":1723063056691,"mc":[{"id":"1.231541189","rc":[{"batb":[[0,3.05,4],[1,3,4],[2,2.98,26.42]],"ltp":3.2,"tv":463.5,"id":19587212}]}]}
{"op":"mcm","clk":"11793105139","pt":1723063060699,"mc":[{"id":"1.231541189","rc":[{"batb":[[0,3.1,4],[1,3.05,4],[2,3,4]],"ltp":3.2,"tv":463.5,"id":19587212}]}]}
{"op":"mcm","clk":"11793105211","pt":1723063062903,"mc":[{"id":"1.231541189","rc":[{"batb":[[0,3.05,4],[1,3,4],[2,2.98,26.42]],"ltp":3.2,"tv":463.5,"id":19587212}]}]}
{"op":"mcm","clk":"11793105282","pt":1723063065269,"mc":[{"id":"1.231541189","rc":[{"batb":[[0,3.1,4],[1,3.05,4],[2,3,4]],"ltp":3.2,"tv":463.5,"id":19587212}]}]}
{"op":"mcm","clk":"11793105361","pt":1723063067884,"mc":[{"id":"1.231541189","rc":[{"batb":[[0,3.05,4],[1,3,4],[2,2.98,26.42]],"ltp":3.2,"tv":463.5,"id":19587212}]}]}
{"op":"mcm","clk":"11793105465","pt":1723063071282,"mc":[{"id":"1.231541189","rc":[{"batb":[[0,3.1,4],[1,3.05,4],[2,3,4]],"ltp":3.2,"tv":463.5,"id":19587212}]}]}
{"op":"mcm","clk":"11793105544","pt":1723063073588,"mc":[{"id":"1.231541189","rc":[{"batb":[[0,3.05,4],[1,3,4],[2,2.98,26.42]],"ltp":3.2,"tv":463.5,"id":19587212}]}]}
{"op":"mcm","clk":"11793105691","pt":1723063077085,"mc":[{"id":"1.231541189","rc":[{"batb":[[0,3.1,4],[1,3.05,4],[2,3,4]],"ltp":3.2,"tv":463.5,"id":19587212}]}]}
{"op":"mcm","clk":"11793105776","pt":1723063079290,"mc":[{"id":"1.231541189","rc":[{"batb":[[0,3.05,4],[1,3,4],[2,2.98,26.42]],"ltp":3.2,"tv":463.5,"id":19587212}]}]}
{"op":"mcm","clk":"11793105892","pt":1723063081711,"mc":[{"id":"1.231541189","rc":[{"batb":[[0,3.1,4],[1,3.05,4],[2,3,4]],"ltp":3.2,"tv":463.5,"id":19587212}]}]}
{"op":"mcm","clk":"11793105986","pt":1723063084222,"mc":[{"id":"1.231541189","rc":[{"batb":[[0,3.05,4],[1,3,4],[2,2.98,26.42]],"ltp":3.2,"tv":463.5,"id":19587212}]}]}
{"op":"mcm","clk":"11793106104","pt":1723063086428,"mc":[{"id":"1.231541189","rc":[{"batb":[[0,3.1,4],[1,3.05,4],[2,3,4]],"ltp":3.2,"tv":463.5,"id":19587212}]}]}
{"op":"mcm","clk":"11793106196","pt":1723063088694,"mc":[{"id":"1.231541189","rc":[{"batb":[[0,3.05,4],[1,3,4],[2,2.98,26.42]],"ltp":3.2,"tv":463.5,"id":19587212}]}]}
{"op":"mcm","clk":"11793106300","pt":1723063091504,"mc":[{"id":"1.231541189","rc":[{"batb":[[0,3.1,4],[1,3.05,4],[2,3,4]],"ltp":3.2,"tv":463.5,"id":19587212}]}]}
{"op":"mcm","clk":"11793106391","pt":1723063093917,"mc":[{"id":"1.231541189","rc":[{"batb":[[0,3.05,4],[1,3,4],[2,2.98,26.42]],"ltp":3.2,"tv":463.5,"id":19587212}]}]}
{"op":"mcm","clk":"11793106510","pt":1723063097216,"mc":[{"id":"1.231541189","rc":[{"batb":[[0,3.1,4],[1,3.05,4],[2,3,4]],"ltp":3.2,"tv":463.5,"id":19587212}]}]}
{"op":"mcm","clk":"11793106603","pt":1723063099815,"mc":[{"id":"1.231541189","rc":[{"batb":[[0,3.05,4],[1,3,4],[2,2.98,26.42]],"ltp":3.2,"tv":463.5,"id":19587212}]}]}
{"op":"mcm","clk":"11793106680","pt":1723063102022,"mc":[{"id":"1.231541189","rc":[{"batb":[[0,3.1,4],[1,3.05,4],[2,3,4]],"ltp":3.2,"tv":463.5,"id":19587212}]}]}
{"op":"mcm","clk":"11793106777","pt":1723063104542,"mc":[{"id":"1.231541189","rc":[{"batb":[[0,3.05,4],[1,3,4],[2,2.98,26.42]],"ltp":3.2,"tv":463.5,"id":19587212}]}]}
{"op":"mcm","clk":"11793106874","pt":1723063107621,"mc":[{"id":"1.231541189","rc":[{"batb":[[0,3.1,4],[1,3.05,4],[2,3,4]],"ltp":3.2,"tv":463.5,"id":19587212}]}]}
{"op":"mcm","clk":"11793106955","pt":1723063109926,"mc":[{"id":"1.231541189","rc":[{"batb":[[0,3.05,4],[1,3,4],[2,2.98,26.42]],"ltp":3.2,"tv":463.5,"id":19587212}]}]}
{"op":"mcm","clk":"11793107054","pt":1723063112437,"mc":[{"id":"1.231541189","rc":[{"batb":[[0,3.1,4],[1,3.05,4],[2,3,4]],"ltp":3.2,"tv":463.5,"id":19587212}]}]}
{"op":"mcm","clk":"11793107150","pt":1723063114959,"mc":[{"id":"1.231541189","rc":[{"batb":[[0,3.05,4],[1,3,4],[2,2.98,26.42]],"ltp":3.2,"tv":463.5,"id":19587212}]}]}
{"op":"mcm","clk":"11793107268","pt":1723063118334,"mc":[{"id":"1.231541189","rc":[{"batb":[[0,3.1,4],[1,3.05,4],[2,3,4]],"ltp":3.2,"tv":463.5,"id":19587212}]}]}
{"op":"mcm","clk":"11793107347","pt":1723063120656,"mc":[{"id":"1.231541189","rc":[{"batb":[[0,3.05,4],[1,3,4],[2,2.98,26.42]],"ltp":3.2,"tv":463.5,"id":19587212}]}]}
{"op":"mcm","clk":"11793107418","pt":1723063123121,"mc":[{"id":"1.231541189","rc":[{"batb":[[0,3.1,4],[1,3.05,4],[2,3,4]],"ltp":3.2,"tv":463.5,"id":19587212}]}]}
{"op":"mcm","clk":"11793107495","pt":1723063125529,"mc":[{"id":"1.231541189","rc":[{"batb":[[0,3.05,4],[1,3,4],[2,2.98,26.42]],"ltp":3.2,"tv":463.5,"id":19587212}]}]}
{"op":"mcm","clk":"11793107585","pt":1723063127836,"mc":[{"id":"1.231541189","rc":[{"batb":[[0,3.1,4],[1,3.05,4],[2,3,4]],"ltp":3.2,"tv":463.5,"id":19587212}]}]}
{"op":"mcm","clk":"11793107671","pt":1723063130244,"mc":[{"id":"1.231541189","rc":[{"batb":[[0,3.05,4],[1,3,4],[2,2.98,26.42]],"ltp":3.2,"tv":463.5,"id":19587212}]}]}
{"op":"mcm","clk":"11793107745","pt":1723063132661,"mc":[{"id":"1.231541189","rc":[{"batb":[[0,3.1,4],[1,3.05,4],[2,3,4]],"ltp":3.2,"tv":463.5,"id":19587212}]}]}
{"op":"mcm","clk":"11793107828","pt":1723063134953,"mc":[{"id":"1.231541189","rc":[{"batb":[[0,3.05,4],[1,3,4],[2,2.98,26.42]],"ltp":3.2,"tv":463.5,"id":19587212}]}]}
{"op":"mcm","clk":"11793107918","pt":1723063137360,"mc":[{"id":"1.231541189","rc":[{"batb":[[0,3.1,4],[1,3.05,4],[2,3,4]],"ltp":3.2,"tv":463.5,"id":19587212}]}]}
{"op":"mcm","clk":"11793108036","pt":1723063139874,"mc":[{"id":"1.231541189","rc":[{"batb":[[0,3.05,4],[1,3,4],[2,2.98,26.42]],"ltp":3.2,"tv":463.5,"id":19587212}]}]}
{"op":"mcm","clk":"11793108155","pt":1723063142345,"mc":[{"id":"1.231541189","rc":[{"batb":[[0,3.1,4],[1,3.05,4],[2,3,4]],"ltp":3.2,"tv":463.5,"id":19587212}]}]}
{"op":"mcm","clk":"11793108259","pt":1723063144753,"mc":[{"id":"1.231541189","rc":[{"batb":[[0,3.05,4],[1,3,4],[2,2.98,26.42]],"ltp":3.2,"tv":463.5,"id":19587212}]}]}
{"op":"mcm","clk":"11793108360","pt":1723063147269,"mc":[{"id":"1.231541189","rc":[{"batb":[[0,3.1,4],[1,3.05,4],[2,3,4]],"ltp":3.2,"tv":463.5,"id":19587212}]}]}
{"op":"mcm","clk":"11793108468","pt":1723063149577,"mc":[{"id":"1.231541189","rc":[{"batb":[[0,3.05,4],[1,3,4],[2,2.98,26.42]],"ltp":3.2,"tv":463.5,"id":19587212}]}]}
{"op":"mcm","clk":"11793108580","pt":1723063152191,"mc":[{"id":"1.231541189","rc":[{"batb":[[0,3.1,4],[1,3.05,4],[2,3,4]],"ltp":3.2,"tv":463.5,"id":19587212}]}]}
{"op":"mcm","clk":"11793108667","pt":1723063154392,"mc":[{"id":"1.231541189","rc":[{"batb":[[0,3.05,4],[1,3,4],[2,2.98,26.42]],"ltp":3.2,"tv":463.5,"id":19587212}]}]}
{"op":"mcm","clk":"11793108798","pt":1723063158188,"mc":[{"id":"1.231541189","rc":[{"batb":[[0,3.1,4],[1,3.05,4],[2,3,4]],"ltp":3.2,"tv":463.5,"id":19587212}]}]}
{"op":"mcm","clk":"11793108916","pt":1723063160675,"mc":[{"id":"1.231541189","rc":[{"batb":[[0,3.05,4],[1,3,4],[2,2.98,26.42]],"ltp":3.2,"tv":463.5,"id":19587212}]}]}
{"op":"mcm","clk":"11793109073","pt":1723063164363,"mc":[{"id":"1.231541189","rc":[{"batb":[[0,3.1,4],[1,3.05,4],[2,3,4]],"ltp":3.2,"tv":463.5,"id":19587212}]}]}
{"op":"mcm","clk":"11793109155","pt":1723063166978,"mc":[{"id":"1.231541189","rc":[{"batb":[[0,3.05,4],[1,3,4],[2,2.98,26.42]],"ltp":3.2,"tv":463.5,"id":19587212}]}]}
{"op":"mcm","clk":"11793109234","pt":1723063169394,"mc":[{"id":"1.231541189","rc":[{"batb":[[0,3.1,4],[1,3.05,4],[2,3,4]],"ltp":3.2,"tv":463.5,"id":19587212}]}]}
{"op":"mcm","clk":"11793109310","pt":1723063171696,"mc":[{"id":"1.231541189","rc":[{"batb":[[0,3.05,4],[1,3,4],[2,2.98,26.42]],"ltp":3.2,"tv":463.5,"id":19587212}]}]}
{"op":"mcm","clk":"11793109446","pt":1723063174994,"mc":[{"id":"1.231541189","rc":[{"batb":[[0,3.1,4],[1,3.05,4],[2,3,4]],"ltp":3.2,"tv":463.5,"id":19587212}]}]}
{"op":"mcm","clk":"11793109545","pt":1723063177387,"mc":[{"id":"1.231541189","rc":[{"batb":[[0,3.05,4],[1,3,4],[2,2.98,26.42]],"ltp":3.2,"tv":463.5,"id":19587212}]}]}
{"op":"mcm","clk":"11793109697","pt":1723063182107,"mc":[{"id":"1.231541189","rc":[{"batb":[[0,3.1,4],[1,3.05,4],[2,3,4]],"ltp":3.2,"tv":463.5,"id":19587212}]}]}
{"op":"mcm","clk":"11793109769","pt":1723063184514,"mc":[{"id":"1.231541189","rc":[{"batb":[[0,3.05,4],[1,3,4],[2,2.98,26.42]],"ltp":3.2,"tv":463.5,"id":19587212}]}]}
{"op":"mcm","clk":"11793109829","pt":1723063186878,"mc":[{"id":"1.231541189","rc":[{"batb":[[0,3.1,4],[1,3.05,4],[2,3,4]],"ltp":3.2,"tv":463.5,"id":19587212}]}]}
{"op":"mcm","clk":"11793109904","pt":1723063189183,"mc":[{"id":"1.231541189","rc":[{"batb":[[0,3.05,4],[1,3,4],[2,2.98,26.42]],"ltp":3.2,"tv":463.5,"id":19587212}]}]}
{"op":"mcm","clk":"11793109989","pt":1723063191797,"mc":[{"id":"1.231541189","rc":[{"batb":[[0,3.1,4],[1,3.05,4],[2,3,4]],"ltp":3.2,"tv":463.5,"id":19587212}]}]}
{"op":"mcm","clk":"11793110098","pt":1723063194614,"mc":[{"id":"1.231541189","rc":[{"batb":[[0,3.05,4],[1,3,4],[2,2.98,26.42]],"ltp":3.2,"tv":463.5,"id":19587212}]}]}
{"op":"mcm","clk":"11793110169","pt":1723063196831,"mc":[{"id":"1.231541189","rc":[{"batb":[[0,3.1,4],[1,3.05,4],[2,3,4]],"ltp":3.2,"tv":463.5,"id":19587212}]}]}
{"op":"mcm","clk":"11793110248","pt":1723063198990,"mc":[{"id":"1.231541189","rc":[{"batb":[[0,3.05,4],[1,3,4],[2,2.98,26.42]],"ltp":3.2,"tv":463.5,"id":19587212}]}]}
{"op":"mcm","clk":"11793110363","pt":1723063202021,"mc":[{"id":"1.231541189","rc":[{"batb":[[0,3.1,4],[1,3.05,4],[2,3,4]],"ltp":3.2,"tv":463.5,"id":19587212}]}]}
{"op":"mcm","clk":"11793110459","pt":1723063204330,"mc":[{"id":"1.231541189","rc":[{"batb":[[0,3.05,4],[1,3,4],[2,2.98,26.42]],"ltp":3.2,"tv":463.5,"id":19587212}]}]}
{"op":"mcm","clk":"11793110559","pt":1723063206999,"mc":[{"id":"1.231541189","rc":[{"batb":[[0,3.1,4],[1,3.05,4],[2,3,4]],"ltp":3.2,"tv":463.5,"id":19587212}]}]}
{"op":"mcm","clk":"11793110650","pt":1723063209318,"mc":[{"id":"1.231541189","rc":[{"batb":[[0,3.05,4],[1,3,4],[2,2.98,26.42]],"ltp":3.2,"tv":463.5,"id":19587212}]}]}
{"op":"mcm","clk":"11793110830","pt":1723063213731,"mc":[{"id":"1.231541189","rc":[{"batb":[[0,3.1,4],[1,3.05,4],[2,3,4]],"ltp":3.2,"tv":463.5,"id":19587212}]}]}
{"op":"mcm","clk":"11793110933","pt":1723063216343,"mc":[{"id":"1.231541189","rc":[{"batb":[[0,3.05,4],[1,3,4],[2,2.98,26.42]],"ltp":3.2,"tv":463.5,"id":19587212}]}]}
{"op":"mcm","clk":"11793111040","pt":1723063219437,"mc":[{"id":"1.231541189","rc":[{"batb":[[0,3.1,4],[1,3.05,4],[2,3,4]],"ltp":3.2,"tv":463.5,"id":19587212}]}]}
{"op":"mcm","clk":"11793111131","pt":1723063221955,"mc":[{"id":"1.231541189","rc":[{"batb":[[0,3.05,4],[1,3,4],[2,2.98,26.42]],"ltp":3.2,"tv":463.5,"id":19587212}]}]}
{"op":"mcm","clk":"11793111241","pt":1723063225038,"mc":[{"id":"1.231541189","rc":[{"batb":[[0,3.1,4],[1,3.05,4],[2,3,4]],"ltp":3.2,"tv":463.5,"id":19587212}]}]}
{"op":"mcm","clk":"11793111330","pt":1723063227348,"mc":[{"id":"1.231541189","rc":[{"batb":[[0,3.05,4],[1,3,4],[2,2.98,26.42]],"ltp":3.2,"tv":463.5,"id":19587212}]}]}
{"op":"mcm","clk":"11793111422","pt":1723063229715,"mc":[{"id":"1.231541189","rc":[{"batb":[[0,3.1,4],[1,3.05,4],[2,3,4]],"ltp":3.2,"tv":463.5,"id":19587212}]}]}
{"op":"mcm","clk":"11793111537","pt":1723063232029,"mc":[{"id":"1.231541189","rc":[{"batb":[[0,3.05,4],[1,3,4],[2,2.98,26.42]],"ltp":3.2,"tv":463.5,"id":19587212}]}]}
{"op":"mcm","clk":"11793111662","pt":1723063235524,"mc":[{"id":"1.231541189","rc":[{"batb":[[0,3.1,4],[1,3.05,4],[2,3,4]],"ltp":3.2,"tv":463.5,"id":19587212}]}]}
{"op":"mcm","clk":"11793111779","pt":1723063237742,"mc":[{"id":"1.231541189","rc":[{"batb":[[0,3.05,4],[1,3,4],[2,2.98,26.42]],"ltp":3.2,"tv":463.5,"id":19587212}]}]}
{"op":"mcm","clk":"11793111886","pt":1723063240563,"mc":[{"id":"1.231541189","rc":[{"batb":[[0,3.1,4],[1,3.05,4],[2,3,4]],"ltp":3.2,"tv":463.5,"id":19587212}]}]}
{"op":"mcm","clk":"11793112029","pt":1723063243239,"mc":[{"id":"1.231541189","rc":[{"batb":[[0,3.05,4],[1,3,4],[2,2.98,26.42]],"ltp":3.2,"tv":463.5,"id":19587212}]}]}
{"op":"mcm","clk":"11793112139","pt":1723063245547,"mc":[{"id":"1.231541189","rc":[{"batb":[[0,3.1,4],[1,3.05,4],[2,3,4]],"ltp":3.2,"tv":463.5,"id":19587212}]}]}
{"op":"mcm","clk":"11793112242","pt":1723063247963,"mc":[{"id":"1.231541189","rc":[{"batb":[[0,3.05,4],[1,3,4],[2,2.98,26.42]],"ltp":3.2,"tv":463.5,"id":19587212}]}]}
{"op":"mcm","clk":"11793112365","pt":1723063250235,"mc":[{"id":"1.231541189","rc":[{"batb":[[0,3.1,4],[1,3.05,4],[2,3,4]],"ltp":3.2,"tv":463.5,"id":19587212}]}]}
{"op":"mcm","clk":"11793112473","pt":1723063252746,"mc":[{"id":"1.231541189","rc":[{"batb":[[0,3.05,4],[1,3,4],[2,2.98,26.42]],"ltp":3.2,"tv":463.5,"id":19587212}]}]}
{"op":"mcm","clk":"11793112589","pt":1723063256548,"mc":[{"id":"1.231541189","rc":[{"batb":[[0,3.1,4],[1,3.05,4],[2,3,4]],"ltp":3.2,"tv":463.5,"id":19587212}]}]}
{"op":"mcm","clk":"11793112672","pt":1723063258755,"mc":[{"id":"1.231541189","rc":[{"batb":[[0,3.05,4],[1,3,4],[2,2.98,26.42]],"ltp":3.2,"tv":463.5,"id":19587212}]}]}
{"op":"mcm","clk":"11793112848","pt":1723063262355,"mc":[{"id":"1.231541189","rc":[{"batb":[[0,3.1,4],[1,3.05,4],[2,3,4]],"ltp":3.2,"tv":463.5,"id":19587212}]}]}
{"op":"mcm","clk":"11793112972","pt":1723063264772,"mc":[{"id":"1.231541189","rc":[{"batb":[[0,3.05,4],[1,3,4],[2,2.98,26.42]],"ltp":3.2,"tv":463.5,"id":19587212}]}]}
{"op":"mcm","clk":"11793113195","pt":1723063269864,"mc":[{"id":"1.231541189","rc":[{"batb":[[0,3.1,4],[1,3.05,4],[2,3,4]],"ltp":3.2,"tv":463.5,"id":19587212}]}]}
{"op":"mcm","clk":"11793113327","pt":1723063272484,"mc":[{"id":"1.231541189","rc":[{"batb":[[0,3.05,4],[1,3,4],[2,2.98,26.42]],"ltp":3.2,"tv":463.5,"id":19587212}]}]}
{"op":"mcm","clk":"11793113439","pt":1723063275359,"mc":[{"id":"1.231541189","rc":[{"batb":[[0,3.1,4],[1,3.05,4],[2,3,4]],"ltp":3.2,"tv":463.5,"id":19587212}]}]}
{"op":"mcm","clk":"11793113527","pt":1723063277669,"mc":[{"id":"1.231541189","rc":[{"batb":[[0,3.05,4],[1,3,4],[2,2.98,26.42]],"ltp":3.2,"tv":463.5,"id":19587212}]}]}
{"op":"mcm","clk":"11793113631","pt":1723063279980,"mc":[{"id":"1.231541189","rc":[{"batb":[[0,3.1,4],[1,3.05,4],[2,3,4]],"ltp":3.2,"tv":463.5,"id":19587212}]}]}
{"op":"mcm","clk":"11793113749","pt":1723063282601,"mc":[{"id":"1.231541189","rc":[{"batb":[[0,3.05,4],[1,3,4],[2,2.98,26.42]],"ltp":3.2,"tv":463.5,"id":19587212}]}]}
{"op":"mcm","clk":"11793113919","pt":1723063287373,"mc":[{"id":"1.231541189","rc":[{"batb":[[0,3.1,4],[1,3.05,4],[2,3,4]],"ltp":3.2,"tv":463.5,"id":19587212}]}]}
{"op":"mcm","clk":"11793114012","pt":1723063289887,"mc":[{"id":"1.231541189","rc":[{"batb":[[0,3.05,4],[1,3,4],[2,2.98,26.42]],"ltp":3.2,"tv":463.5,"id":19587212}]}]}
{"op":"mcm","clk":"11793114156","pt":1723063293285,"mc":[{"id":"1.231541189","rc":[{"batb":[[0,3.1,4],[1,3.05,4],[2,3,4]],"ltp":3.2,"tv":463.5,"id":19587212}]}]}
{"op":"mcm","clk":"11793114247","pt":1723063295496,"mc":[{"id":"1.231541189","rc":[{"batb":[[0,3.05,4],[1,3,4],[2,2.98,26.42]],"ltp":3.2,"tv":463.5,"id":19587212}]}]}
{"op":"mcm","clk":"11793114362","pt":1723063298630,"mc":[{"id":"1.231541189","rc":[{"batb":[[0,3.1,4],[1,3.05,4],[2,3,4]],"ltp":3.2,"tv":463.5,"id":19587212}]}]}
{"op":"mcm","clk":"11793114457","pt":1723063300890,"mc":[{"id":"1.231541189","rc":[{"batb":[[0,3.05,4],[1,3,4],[2,2.98,26.42]],"ltp":3.2,"tv":463.5,"id":19587212}]}]}
{"op":"mcm","clk":"11793114561","pt":1723063303606,"mc":[{"id":"1.231541189","rc":[{"batb":[[0,3.1,4],[1,3.05,4],[2,3,4]],"ltp":3.2,"tv":463.5,"id":19587212}]}]}
{"op":"mcm","clk":"11793114649","pt":1723063305910,"mc":[{"id":"1.231541189","rc":[{"batb":[[0,3.05,4],[1,3,4],[2,2.98,26.42]],"ltp":3.2,"tv":463.5,"id":19587212}]}]}
{"op":"mcm","clk":"11793114728","pt":1723063308343,"mc":[{"id":"1.231541189","rc":[{"batb":[[0,3.1,4],[1,3.05,4],[2,3,4]],"ltp":3.2,"tv":463.5,"id":19587212}]}]}
{"op":"mcm","clk":"11793114837","pt":1723063310921,"mc":[{"id":"1.231541189","rc":[{"batb":[[0,3.05,4],[1,3,4],[2,2.98,26.42]],"ltp":3.2,"tv":463.5,"id":19587212}]}]}
{"op":"mcm","clk":"11793114977","pt":1723063313946,"mc":[{"id":"1.231541189","rc":[{"batb":[[0,3.1,4],[1,3.05,4],[2,3,4]],"ltp":3.2,"tv":463.5,"id":19587212}]}]}
{"op":"mcm","clk":"11793115080","pt":1723063316208,"mc":[{"id":"1.231541189","rc":[{"batb":[[0,3.05,4],[1,3,4],[2,2.98,26.42]],"ltp":3.2,"tv":463.5,"id":19587212}]}]}
{"op":"mcm","clk":"11793161146","pt":1723064377215,"mc":[{"id":"1.231541189","rc":[{"trd":[[1.45,89.15]],"batb":[[0,1.45,1.99],[2,1.36,72.22]],"ltp":1.45,"tv":5873.01,"id":19587555}],"tv":6336.52}]}
{"op":"mcm","clk":"11793161167","pt":1723064377987,"mc":[{"id":"1.231541189","rc":[{"batl":[[0,1.48,9.47]],"ltp":1.45,"tv":5873.01,"id":19587555}]}]}
{"op":"mcm","clk":"11793161805","pt":1723064400762,"mc":[{"id":"1.231541189","rc":[{"batb":[[0,3.1,4],[1,3.05,4],[2,3,4]],"ltp":3.2,"tv":463.5,"id":19587212}]}]}
{"op":"mcm","clk":"11793161954","pt":1723064403444,"mc":[{"id":"1.231541189","rc":[{"trd":[[1.55,92.1],[2.2,365.57]],"batb":[[0,3.05,4],[1,3,4],[2,2.98,26.42]],"ltp":3.2,"tv":463.36,"id":19587212},{"trd":[[1.38,7.77],[1.41,8.02],[1.42,28.55],[1.44,86.07],[1.45,89.14],[1.55,92.1],[1.7,967.5],[1.74,34.42],[1.75,934.31],[1.76,1934.99],[1.78,1679.73]],"batl":[[0,1.47,8.14],[1,1.48,9.47],[2,1.49,38.03]],"ltp":1.45,"tv":5871.21,"id":19587555}],"tv":6334.58}]}
{"op":"mcm","clk":"11793161989","pt":1723064404264,"mc":[{"id":"1.231541189","rc":[{"batl":[[0,1.47,12.14]],"ltp":1.45,"tv":5871.21,"id":19587555}]}]}
{"op":"mcm","clk":"11793162072","pt":1723064406168,"mc":[{"id":"1.231541189","rc":[{"batb":[[0,3.1,4],[1,3.05,4],[2,3,4]],"ltp":3.2,"tv":463.36,"id":19587212},{"batl":[[0,1.47,4]],"ltp":1.45,"tv":5871.21,"id":19587555}]}]}
{"op":"mcm","clk":"11793162134","pt":1723064408367,"mc":[{"id":"1.231541189","rc":[{"batb":[[0,3.05,4],[1,3,4],[2,2.98,26.42]],"ltp":3.2,"tv":463.36,"id":19587212}]}]}
{"op":"mcm","clk":"11793162145","pt":1723064408728,"mc":[{"id":"1.231541189","rc":[{"batl":[[0,1.48,9.47],[1,1.49,38.03],[2,1.5,25.52]],"ltp":1.45,"tv":5871.21,"id":19587555}]}]}
{"op":"mcm","clk":"11793162343","pt":1723064414572,"mc":[{"id":"1.231541189","rc":[{"batb":[[0,3.1,4],[1,3.05,4],[2,3,4]],"ltp":3.2,"tv":463.36,"id":19587212}]}]}
{"op":"mcm","clk":"11793162412","pt":1723064416853,"mc":[{"id":"1.231541189","rc":[{"batb":[[0,3.05,4],[1,3,4],[2,2.98,26.42]],"ltp":3.2,"tv":463.36,"id":19587212}]}]}
{"op":"mcm","clk":"11793162577","pt":1723064421370,"mc":[{"id":"1.231541189","rc":[{"batb":[[0,3.1,4],[1,3.05,4],[2,3,4]],"ltp":3.2,"tv":463.36,"id":19587212}]}]}
{"op":"mcm","clk":"11793162657","pt":1723064423778,"mc":[{"id":"1.231541189","rc":[{"batb":[[0,3.05,4],[1,3,4],[2,2.98,26.42]],"ltp":3.2,"tv":463.36,"id":19587212}]}]}
{"op":"mcm","clk":"11793162708","pt":1723064426387,"mc":[{"id":"1.231541189","rc":[{"batb":[[0,3.1,4],[1,3.05,4],[2,3,4]],"ltp":3.2,"tv":463.36,"id":19587212}]}]}
{"op":"mcm","clk":"11793162799","pt":1723064428599,"mc":[{"id":"1.231541189","rc":[{"batb":[[0,3.05,4],[1,3,4],[2,2.98,26.42]],"ltp":3.2,"tv":463.36,"id":19587212}]}]}
{"op":"mcm","clk":"11793162933","pt":1723064432964,"mc":[{"id":"1.231541189","rc":[{"batb":[[0,3.1,4],[1,3.05,4],[2,3,4]],"ltp":3.2,"tv":463.36,"id":19587212}]}]}
{"op":"mcm","clk":"11793162975","pt":1723064434394,"mc":[{"id":"1.231541189","rc":[{"batl":[[0,1.47,4],[1,1.48,9.47],[2,1.49,38.03]],"ltp":1.45,"tv":5871.21,"id":19587555}]}]}
{"op":"mcm","clk":"11793163001","pt":1723064435268,"mc":[{"id":"1.231541189","rc":[{"batb":[[0,3.05,4],[1,3,4],[2,2.98,26.42]],"ltp":3.2,"tv":463.36,"id":19587212}]}]}
{"op":"mcm","clk":"11793163027","pt":1723064435986,"mc":[{"id":"1.231541189","rc":[{"batl":[[0,1.48,9.47],[1,1.49,38.03],[2,1.5,25.52]],"ltp":1.45,"tv":5871.21,"id":19587555}]}]}
{"op":"mcm","clk":"11793163127","pt":1723064438906,"mc":[{"id":"1.231541189","rc":[{"batb":[[0,3.1,4],[1,3.05,4],[2,3,4]],"ltp":3.2,"tv":463.36,"id":19587212}]}]}
{"op":"mcm","clk":"11793163219","pt":1723064441210,"mc":[{"id":"1.231541189","rc":[{"batb":[[0,3.05,4],[1,3,4],[2,2.98,26.42]],"ltp":3.2,"tv":463.36,"id":19587212}]}]}
{"op":"mcm","clk":"11793163336","pt":1723064444798,"mc":[{"id":"1.231541189","rc":[{"batb":[[0,3.1,4],[1,3.05,4],[2,3,4]],"ltp":3.2,"tv":463.36,"id":19587212}]}]}
{"op":"mcm","clk":"11793163372","pt":1723064446024,"mc":[{"id":"1.231541189","rc":[{"batl":[[0,1.47,8.14],[1,1.48,9.47],[2,1.49,38.03]],"ltp":1.45,"tv":5871.21,"id":19587555}]}]}
{"op":"mcm","clk":"11793163413","pt":1723064447097,"mc":[{"id":"1.231541189","rc":[{"batb":[[0,3.05,4],[1,3,4],[2,2.98,26.42]],"ltp":3.2,"tv":463.36,"id":19587212}]}]}
{"op":"mcm","clk":"11793163484","pt":1723064449501,"mc":[{"id":"1.231541189","rc":[{"batb":[[0,3.1,4],[1,3.05,4],[2,3,4]],"ltp":3.2,"tv":463.36,"id":19587212},{"batl":[[0,1.47,12.14]],"ltp":1.45,"tv":5871.21,"id":19587555}]}]}
{"op":"mcm","clk":"11793163552","pt":1723064451498,"mc":[{"id":"1.231541189","rc":[{"batb":[[0,3.05,4],[1,3,4],[2,2.98,26.42]],"ltp":3.2,"tv":463.36,"id":19587212}]}]}
{"op":"mcm","clk":"11793163566","pt":1723064452112,"mc":[{"id":"1.231541189","rc":[{"batl":[[0,1.48,9.47],[1,1.49,38.03],[2,1.5,25.52]],"ltp":1.45,"tv":5871.21,"id":19587555}]}]}
{"op":"mcm","clk":"11793163654","pt":1723064455234,"mc":[{"id":"1.231541189","rc":[{"batb":[[0,3.1,4],[1,3.05,4],[2,3,4]],"ltp":3.2,"tv":463.36,"id":19587212}]}]}
{"op":"mcm","clk":"11793163725","pt":1723064457698,"mc":[{"id":"1.231541189","rc":[{"batb":[[0,3.05,4],[1,3,4],[2,2.98,26.42]],"ltp":3.2,"tv":463.36,"id":19587212}]}]}
{"op":"mcm","clk":"11793163858","pt":1723064461699,"mc":[{"id":"1.231541189","rc":[{"batb":[[0,3.1,4],[1,3.05,4],[2,3,4]],"ltp":3.2,"tv":463.36,"id":19587212}]}]}
{"op":"mcm","clk":"11793163953","pt":1723064464733,"mc":[{"id":"1.231541189","rc":[{"batb":[[0,3.05,4],[1,3,4],[2,2.98,26.42]],"ltp":3.2,"tv":463.36,"id":19587212},{"batl":[[0,1.47,4],[1,1.48,9.47],[2,1.49,38.03]],"ltp":1.45,"tv":5871.21,"id":19587555}]}]}
{"op":"mcm","clk":"11793164076","pt":1723064467910,"mc":[{"id":"1.231541189","rc":[{"batb":[[0,3.1,4],[1,3.05,4],[2,3,4]],"ltp":3.2,"tv":463.36,"id":19587212}]}]}
{"op":"mcm","clk":"11793164161","pt":1723064470325,"mc":[{"id":"1.231541189","rc":[{"batb":[[0,3.05,4],[1,3,4],[2,2.98,26.42]],"ltp":3.2,"tv":463.36,"id":19587212}]}]}
{"op":"mcm","clk":"11793164175","pt":1723064470939,"mc":[{"id":"1.231541189","rc":[{"batl":[[0,1.48,9.47],[1,1.49,38.03],[2,1.5,25.52]],"ltp":1.45,"tv":5871.21,"id":19587555}]}]}
{"op":"mcm","clk":"11793164275","pt":1723064473621,"mc":[{"id":"1.231541189","rc":[{"batb":[[0,3.1,4],[1,3.05,4],[2,3,4]],"ltp":3.2,"tv":463.36,"id":19587212}]}]}
{"op":"mcm","clk":"11793164350","pt":1723064475924,"mc":[{"id":"1.231541189","rc":[{"batb":[[0,3.05,4],[1,3,4],[2,2.98,26.42]],"ltp":3.2,"tv":463.36,"id":19587212}]}]}
{"op":"mcm","clk":"11793164493","pt":1723064480043,"mc":[{"id":"1.231541189","rc":[{"batb":[[0,3.1,4],[1,3.05,4],[2,3,4]],"ltp":3.2,"tv":463.36,"id":19587212}]}]}
{"op":"mcm","clk":"11793164605","pt":1723064482660,"mc":[{"id":"1.231541189","rc":[{"batb":[[0,3.05,4],[1,3,4],[2,2.98,26.42]],"ltp":3.2,"tv":463.36,"id":19587212}]}]}
{"op":"mcm","clk":"11793164724","pt":1723064485644,"mc":[{"id":"1.231541189","rc":[{"batb":[[0,3.1,4],[1,3.05,4],[2,3,4]],"ltp":3.2,"tv":463.36,"id":19587212}]}]}
{"op":"mcm","clk":"11793164825","pt":1723064488058,"mc":[{"id":"1.231541189","rc":[{"batb":[[0,3.05,4],[1,3,4],[2,2.98,26.42]],"ltp":3.2,"tv":463.36,"id":19587212}]}]}
{"op":"mcm","clk":"11793164997","pt":1723064491334,"mc":[{"id":"1.231541189","rc":[{"batb":[[0,3.1,4],[1,3.05,4],[2,3,4]],"ltp":3.2,"tv":463.36,"id":19587212}]}]}
{"op":"mcm","clk":"11793165118","pt":1723064493854,"mc":[{"id":"1.231541189","rc":[{"batb":[[0,3.05,4],[1,3,4],[2,2.98,26.42]],"ltp":3.2,"tv":463.36,"id":19587212}]}]}
{"op":"mcm","clk":"11793165233","pt":1723064496267,"mc":[{"id":"1.231541189","rc":[{"batb":[[0,3.1,4],[1,3.05,4],[2,3,4]],"ltp":3.2,"tv":463.36,"id":19587212}]}]}
{"op":"mcm","clk":"11793165262","pt":1723064496884,"mc":[{"id":"1.231541189","rc":[{"batl":[[0,1.47,8.14],[1,1.48,9.47],[2,1.49,38.03]],"ltp":1.45,"tv":5871.21,"id":19587555}]}]}
{"op":"mcm","clk":"11793165346","pt":1723064498678,"mc":[{"id":"1.231541189","rc":[{"batb":[[0,3.05,4],[1,3,4],[2,2.98,26.42]],"ltp":3.2,"tv":463.36,"id":19587212}]}]}
{"op":"mcm","clk":"11793165588","pt":1723064503665,"mc":[{"id":"1.231541189","rc":[{"batb":[[0,3.1,4],[1,3.05,4],[2,3,4]],"ltp":3.2,"tv":463.36,"id":19587212}]}]}
{"op":"mcm","clk":"11793165699","pt":1723064506067,"mc":[{"id":"1.231541189","rc":[{"batb":[[0,3.05,4],[1,3,4],[2,2.98,26.42]],"ltp":3.2,"tv":463.36,"id":19587212}]}]}
{"op":"mcm","clk":"11793165884","pt":1723064510075,"mc":[{"id":"1.231541189","rc":[{"batb":[[0,3.1,4],[1,3.05,4],[2,3,4]],"ltp":3.2,"tv":463.36,"id":19587212},{"batl":[[0,1.47,12.14]],"ltp":1.45,"tv":5871.21,"id":19587555}]}]}
{"op":"mcm","clk":"11793165970","pt":1723064512385,"mc":[{"id":"1.231541189","rc":[{"batb":[[0,3.05,4],[1,3,4],[2,2.98,26.42]],"ltp":3.2,"tv":463.36,"id":19587212}]}]}
{"op":"mcm","clk":"11793165996","pt":1723064512999,"mc":[{"id":"1.231541189","rc":[{"batl":[[0,1.47,8.14]],"ltp":1.45,"tv":5871.21,"id":19587555}]}]}
{"op":"mcm","clk":"11793166112","pt":1723064515769,"mc":[{"id":"1.231541189","rc":[{"batb":[[0,3.1,4],[1,3.05,4],[2,3,4]],"ltp":3.2,"tv":463.36,"id":19587212}]}]}
{"op":"mcm","clk":"11793166229","pt":1723064518384,"mc":[{"id":"1.231541189","rc":[{"batb":[[0,3.05,4],[1,3,4],[2,2.98,26.42]],"ltp":3.2,"tv":463.36,"id":19587212}]}]}
{"op":"mcm","clk":"11793166413","pt":1723064522284,"mc":[{"id":"1.231541189","rc":[{"batb":[[0,3.1,4],[1,3.05,4],[2,3,4]],"ltp":3.2,"tv":463.36,"id":19587212}]}]}
{"op":"mcm","clk":"11793166551","pt":1723064525210,"mc":[{"id":"1.231541189","rc":[{"batb":[[0,3.05,4],[1,3,4],[2,2.98,26.42]],"ltp":3.2,"tv":463.36,"id":19587212},{"batl":[[0,1.47,12.14]],"ltp":1.45,"tv":5871.21,"id":19587555}]}]}
{"op":"mcm","clk":"11793166664","pt":1723064527723,"mc":[{"id":"1.231541189","rc":[{"batb":[[0,3.1,4],[1,3.05,4],[2,3,4]],"ltp":3.2,"tv":463.36,"id":19587212},{"batl":[[0,1.47,4]],"ltp":1.45,"tv":5871.21,"id":19587555}]}]}
{"op":"mcm","clk":"11793166771","pt":1723064530492,"mc":[{"id":"1.231541189","rc":[{"batb":[[0,3.05,4],[1,3,4],[2,2.98,26.42]],"ltp":3.2,"tv":463.36,"id":19587212},{"batl":[[0,1.48,9.47],[1,1.49,38.03],[2,1.5,25.52]],"ltp":1.45,"tv":5871.21,"id":19587555}]}]}
{"op":"mcm","clk":"11793166849","pt":1723064532335,"mc":[{"id":"1.231541189","rc":[{"batb":[[0,3.1,4],[1,3.05,4],[2,3,4]],"ltp":3.2,"tv":463.36,"id":19587212}]}]}
{"op":"mcm","clk":"11793166964","pt":1723064534746,"mc":[{"id":"1.231541189","rc":[{"batb":[[0,3.05,4],[1,3,4],[2,2.98,26.42]],"ltp":3.2,"tv":463.36,"id":19587212}]}]}
{"op":"mcm","clk":"11793167175","pt":1723064538337,"mc":[{"id":"1.231541189","rc":[{"batb":[[0,3.1,4],[1,3.05,4],[2,3,4]],"ltp":3.2,"tv":463.36,"id":19587212}]}]}
{"op":"mcm","clk":"11793167253","pt":1723064540338,"mc":[{"id":"1.231541189","rc":[{"batl":[[0,1.47,4],[1,1.48,9.47],[2,1.49,38.03]],"ltp":1.45,"tv":5871.21,"id":19587555}]}]}
{"op":"mcm","clk":"11793167266","pt":1723064540646,"mc":[{"id":"1.231541189","rc":[{"batb":[[0,3.05,4],[1,3,4],[2,2.98,26.42]],"ltp":3.2,"tv":463.36,"id":19587212}]}]}
{"op":"mcm","clk":"11793167392","pt":1723064543525,"mc":[{"id":"1.231541189","rc":[{"batb":[[0,3.1,4],[1,3.05,4],[2,3,4]],"ltp":3.2,"tv":463.36,"id":19587212}]}]}
{"op":"mcm","clk":"11793167506","pt":1723064546137,"mc":[{"id":"1.231541189","rc":[{"batb":[[0,3.05,4],[1,3,4],[2,2.98,26.42]],"ltp":3.2,"tv":463.36,"id":19587212},{"batl":[[0,1.48,9.47],[1,1.49,38.03],[2,1.5,25.52]],"ltp":1.45,"tv":5871.21,"id":19587555}]}]}
{"op":"mcm","clk":"11793167586","pt":1723064548338,"mc":[{"id":"1.231541189","rc":[{"batb":[[0,3.1,4],[1,3.05,4],[2,3,4]],"ltp":3.2,"tv":463.36,"id":19587212}]}]}
{"op":"mcm","clk":"11793167658","pt":1723064549425,"mc":[{"id":"1.231541189","rc":[{"batl":[[0,1.47,8.14],[1,1.48,9.47],[2,1.49,38.03]],"ltp":1.45,"tv":5871.21,"id":19587555}]}]}
{"op":"mcm","clk":"11793167704","pt":1723064550557,"mc":[{"id":"1.231541189","rc":[{"batb":[[0,3.05,4],[1,3,4],[2,2.98,26.42]],"ltp":3.2,"tv":463.36,"id":19587212}]}]}
{"op":"mcm","clk":"11793167798","pt":1723064553221,"mc":[{"id":"1.231541189","rc":[{"batb":[[0,3.1,4],[1,3.05,4],[2,3,4]],"ltp":3.2,"tv":463.36,"id":19587212}]}]}
{"op":"mcm","clk":"11793167891","pt":1723064555539,"mc":[{"id":"1.231541189","rc":[{"batb":[[0,3.05,4],[1,3,4],[2,2.98,26.42]],"ltp":3.2,"tv":463.36,"id":19587212},{"batl":[[0,1.47,12.14]],"ltp":1.45,"tv":5871.21,"id":19587555}]}]}
{"op":"mcm","clk":"11793168004","pt":1723064558052,"mc":[{"id":"1.231541189","rc":[{"batb":[[0,3.1,4],[1,3.05,4],[2,3,4]],"ltp":3.2,"tv":463.36,"id":19587212},{"batl":[[0,1.48,9.47],[1,1.49,38.03],[2,1.5,25.52]],"ltp":1.45,"tv":5871.21,"id":19587555}]}]}
{"op":"mcm","clk":"11793168077","pt":1723064560364,"mc":[{"id":"1.231541189","rc":[{"batb":[[0,3.05,4],[1,3,4],[2,2.98,26.42]],"ltp":3.2,"tv":463.36,"id":19587212}]}]}
{"op":"mcm","clk":"11793168303","pt":1723064566837,"mc":[{"id":"1.231541189","rc":[{"batb":[[0,3.1,4],[1,3.05,4],[2,3,4]],"ltp":3.2,"tv":463.36,"id":19587212}]}]}
{"op":"mcm","clk":"11793168383","pt":1723064569041,"mc":[{"id":"1.231541189","rc":[{"batb":[[0,3.05,4],[1,3,4],[2,2.98,26.42]],"ltp":3.2,"tv":463.36,"id":19587212}]}]}
{"op":"mcm","clk":"11793168546","pt":1723064572694,"mc":[{"id":"1.231541189","rc":[{"batb":[[0,3.1,4],[1,3.05,4],[2,3,4]],"ltp":3.2,"tv":463.36,"id":19587212}]}]}
{"op":"mcm","clk":"11793168645","pt":1723064575058,"mc":[{"id":"1.231541189","rc":[{"batb":[[0,3.05,4],[1,3,4],[2,2.98,26.42]],"ltp":3.2,"tv":463.36,"id":19587212}]}]}
{"op":"mcm","clk":"11793168803","pt":1723064578702,"mc":[{"id":"1.231541189","rc":[{"batb":[[0,3.1,4],[1,3.05,4],[2,3,4]],"ltp":3.2,"tv":463.36,"id":19587212}]}]}
{"op":"mcm","clk":"11793168939","pt":1723064581169,"mc":[{"id":"1.231541189","rc":[{"batb":[[0,3.05,4],[1,3,4],[2,2.98,26.42]],"ltp":3.2,"tv":463.36,"id":19587212}]}]}
{"op":"mcm","clk":"11793169120","pt":1723064585669,"mc":[{"id":"1.231541189","rc":[{"batb":[[0,3.1,4],[1,3.05,4],[2,3,4]],"ltp":3.2,"tv":463.36,"id":19587212}]}]}
{"op":"mcm","clk":"11793169203","pt":1723064588284,"mc":[{"id":"1.231541189","rc":[{"batb":[[0,3.05,4],[1,3,4],[2,2.98,26.42]],"ltp":3.2,"tv":463.36,"id":19587212}]}]}
{"op":"mcm","clk":"11793169282","pt":1723064590485,"mc":[{"id":"1.231541189","rc":[{"batb":[[0,3.1,4],[1,3.05,4],[2,3,4]],"ltp":3.2,"tv":463.36,"id":19587212}]}]}
{"op":"mcm","clk":"11793169346","pt":1723064592797,"mc":[{"id":"1.231541189","rc":[{"batb":[[0,3.05,4],[1,3,4],[2,2.98,26.42]],"ltp":3.2,"tv":463.36,"id":19587212}]}]}
{"op":"mcm","clk":"11793169477","pt":1723064596394,"mc":[{"id":"1.231541189","rc":[{"batb":[[0,3.1,4],[1,3.05,4],[2,3,4]],"ltp":3.2,"tv":463.36,"id":19587212}]}]}
{"op":"mcm","clk":"11793169545","pt":1723064598703,"mc":[{"id":"1.231541189","rc":[{"batb":[[0,3.05,4],[1,3,4],[2,2.98,26.42]],"ltp":3.2,"tv":463.36,"id":19587212}]}]}
{"op":"mcm","clk":"11793169691","pt":1723064604507,"mc":[{"id":"1.231541189","rc":[{"batb":[[0,3.1,4],[1,3.05,4],[2,3,4]],"ltp":3.2,"tv":463.36,"id":19587212}]}]}
{"op":"mcm","clk":"11793169784","pt":1723064606807,"mc":[{"id":"1.231541189","rc":[{"batb":[[0,3.05,4],[1,3,4],[2,2.98,26.42]],"ltp":3.2,"tv":463.36,"id":19587212}]}]}
{"op":"mcm","clk":"11793169970","pt":1723064610811,"mc":[{"id":"1.231541189","rc":[{"batb":[[0,3.1,4],[1,3.05,4],[2,3,4]],"ltp":3.2,"tv":463.36,"id":19587212}]}]}
{"op":"mcm","clk":"11793170058","pt":1723064613222,"mc":[{"id":"1.231541189","rc":[{"batl":[[0,1.47,8.14],[1,1.48,9.47],[2,1.49,38.03]],"ltp":1.45,"tv":5871.21,"id":19587555}]}]}
{"op":"mcm","clk":"11793170149","pt":1723064615325,"mc":[{"id":"1.231541189","rc":[{"batb":[[0,3.05,4],[1,3,4],[2,2.98,26.42]],"ltp":3.2,"tv":463.36,"id":19587212}]}]}
{"op":"mcm","clk":"11793170186","pt":1723064616142,"mc":[{"id":"1.231541189","rc":[{"batl":[[0,1.47,12.14]],"ltp":1.45,"tv":5871.21,"id":19587555}]}]}
{"op":"mcm","clk":"11793170235","pt":1723064617629,"mc":[{"id":"1.231541189","rc":[{"batb":[[0,3.1,4],[1,3.05,4],[2,3,4]],"ltp":3.2,"tv":463.36,"id":19587212}]}]}
{"op":"mcm","clk":"11793170351","pt":1723064620446,"mc":[{"id":"1.231541189","rc":[{"batb":[[0,3.05,4],[1,3,4],[2,2.98,26.42]],"ltp":3.2,"tv":463.36,"id":19587212},{"batl":[[0,1.47,8.14]],"ltp":1.45,"tv":5871.21,"id":19587555}]}]}
{"op":"mcm","clk":"11793170435","pt":1723064622342,"mc":[{"id":"1.231541189","rc":[{"batb":[[0,3.1,4],[1,3.05,4],[2,3,4]],"ltp":3.2,"tv":463.36,"id":19587212}]}]}
{"op":"mcm","clk":"11793170549","pt":1723064624753,"mc":[{"id":"1.231541189","rc":[{"batb":[[0,3.05,4],[1,3,4],[2,2.98,26.42]],"ltp":3.2,"tv":463.36,"id":19587212}]}]}
{"op":"mcm","clk":"11793170667","pt":1723064627056,"mc":[{"id":"1.231541189","rc":[{"batb":[[0,3.1,4],[1,3.05,4],[2,3,4]],"ltp":3.2,"tv":463.36,"id":19587212}]}]}
{"op":"mcm","clk":"11793170750","pt":1723064629315,"mc":[{"id":"1.231541189","rc":[{"batb":[[0,3.05,4],[1,3,4],[2,2.98,26.42]],"ltp":3.2,"tv":463.36,"id":19587212}]}]}
{"op":"mcm","clk":"11793170832","pt":1723064631519,"mc":[{"id":"1.231541189","rc":[{"batb":[[0,3.1,4],[1,3.05,4],[2,3,4]],"ltp":3.2,"tv":463.36,"id":19587212},{"batl":[[0,1.47,12.14]],"ltp":1.45,"tv":5871.21,"id":19587555}]}]}
{"op":"mcm","clk":"11793170934","pt":1723064634440,"mc":[{"id":"1.231541189","rc":[{"batb":[[0,3.05,4],[1,3,4],[2,2.98,26.42]],"ltp":3.2,"tv":463.36,"id":19587212},{"batl":[[0,1.47,8.14]],"ltp":1.45,"tv":5871.21,"id":19587555}]}]}
{"op":"mcm","clk":"11793171025","pt":1723064636748,"mc":[{"id":"1.231541189","rc":[{"batb":[[0,3.1,4],[1,3.05,4],[2,3,4]],"ltp":3.2,"tv":463.36,"id":19587212}]}]}
{"op":"mcm","clk":"11793171113","pt":1723064638953,"mc":[{"id":"1.231541189","rc":[{"batb":[[0,3.05,4],[1,3,4],[2,2.98,26.42]],"ltp":3.2,"tv":463.36,"id":19587212}]}]}
{"op":"mcm","clk":"11793171253","pt":1723064642548,"mc":[{"id":"1.231541189","rc":[{"batb":[[0,3.1,4],[1,3.05,4],[2,3,4]],"ltp":3.2,"tv":463.36,"id":19587212}]}]}
{"op":"mcm","clk":"11793171355","pt":1723064644862,"mc":[{"id":"1.231541189","rc":[{"batb":[[0,3.05,4],[1,3,4],[2,2.98,26.42]],"ltp":3.2,"tv":463.36,"id":19587212}]}]}
{"op":"mcm","clk":"11793171402","pt":1723064646357,"mc":[{"id":"1.231541189","rc":[{"batl":[[0,1.47,12.14]],"ltp":1.45,"tv":5871.21,"id":19587555}]}]}
{"op":"mcm","clk":"11793171464","pt":1723064648058,"mc":[{"id":"1.231541189","rc":[{"batb":[[0,3.1,4],[1,3.05,4],[2,3,4]],"ltp":3.2,"tv":463.36,"id":19587212},{"batl":[[0,1.48,9.47],[1,1.49,38.03],[2,1.5,25.52]],"ltp":1.45,"tv":5871.21,"id":19587555}]}]}
{"op":"mcm","clk":"11793171538","pt":1723064650478,"mc":[{"id":"1.231541189","rc":[{"batb":[[0,3.05,4],[1,3,4],[2,2.98,26.42]],"ltp":3.2,"tv":463.36,"id":19587212}]}]}
{"op":"mcm","clk":"11793171664","pt":1723064654896,"mc":[{"id":"1.231541189","rc":[{"batb":[[0,3.1,4],[1,3.05,4],[2,3,4]],"ltp":3.2,"tv":463.36,"id":19587212}]}]}
{"op":"mcm","clk":"11793171751","pt":1723064657672,"mc":[{"id":"1.231541189","rc":[{"batb":[[0,3.05,4],[1,3,4],[2,2.98,26.42]],"ltp":3.2,"tv":463.36,"id":19587212}]}]}
{"op":"mcm","clk":"11793171862","pt":1723064661206,"mc":[{"id":"1.231541189","rc":[{"batb":[[0,3.1,4],[1,3.05,4],[2,3,4]],"ltp":3.2,"tv":463.36,"id":19587212}]}]}
{"op":"mcm","clk":"11793171934","pt":1723064663716,"mc":[{"id":"1.231541189","rc":[{"batb":[[0,3.05,4],[1,3,4],[2,2.98,26.42]],"ltp":3.2,"tv":463.36,"id":19587212}]}]}
{"op":"mcm","clk":"11793172055","pt":1723064667409,"mc":[{"id":"1.231541189","rc":[{"batb":[[0,3.1,4],[1,3.05,4],[2,3,4]],"ltp":3.2,"tv":463.36,"id":19587212}]}]}
{"op":"mcm","clk":"11793172135","pt":1723064669821,"mc":[{"id":"1.231541189","rc":[{"batb":[[0,3.05,4],[1,3,4],[2,2.98,26.42]],"ltp":3.2,"tv":463.36,"id":19587212}]}]}
{"op":"mcm","clk":"11793172211","pt":1723064672232,"mc":[{"id":"1.231541189","rc":[{"batb":[[0,3.1,4],[1,3.05,4],[2,3,4]],"ltp":3.2,"tv":463.36,"id":19587212}]}]}
{"op":"mcm","clk":"11793172246","pt":1723064673009,"mc":[{"id":"1.231541189","rc":[{"batl":[[0,1.47,8.14],[1,1.48,9.47],[2,1.49,38.03]],"ltp":1.45,"tv":5871.21,"id":19587555}]}]}
{"op":"mcm","clk":"11793172305","pt":1723064674702,"mc":[{"id":"1.231541189","rc":[{"batb":[[0,3.05,4],[1,3,4],[2,2.98,26.42]],"ltp":3.2,"tv":463.36,"id":19587212}]}]}
{"op":"mcm","clk":"11793172408","pt":1723064676913,"mc":[{"id":"1.231541189","rc":[{"batb":[[0,3.1,4],[1,3.05,4],[2,3,4]],"ltp":3.2,"tv":463.36,"id":19587212},{"batl":[[0,1.47,12.14]],"ltp":1.45,"tv":5871.21,"id":19587555}]}]}
{"op":"mcm","clk":"11793172494","pt":1723064679327,"mc":[{"id":"1.231541189","rc":[{"batb":[[0,3.05,4],[1,3,4],[2,2.98,26.42]],"ltp":3.2,"tv":463.36,"id":19587212}]}]}
{"op":"mcm","clk":"11793172501","pt":1723064679940,"mc":[{"id":"1.231541189","rc":[{"batl":[[0,1.47,8.14]],"ltp":1.45,"tv":5871.21,"id":19587555}]}]}
{"op":"mcm","clk":"11793172589","pt":1723064682818,"mc":[{"id":"1.231541189","rc":[{"batb":[[0,3.1,4],[1,3.05,4],[2,3,4]],"ltp":3.2,"tv":463.36,"id":19587212}]}]}
{"op":"mcm","clk":"11793172669","pt":1723064685335,"mc":[{"id":"1.231541189","rc":[{"batb":[[0,3.05,4],[1,3,4],[2,2.98,26.42]],"ltp":3.2,"tv":463.36,"id":19587212}]}]}
{"op":"mcm","clk":"11793172773","pt":1723064689736,"mc":[{"id":"1.231541189","rc":[{"batb":[[0,3.1,4],[1,3.05,4],[2,3,4]],"ltp":3.2,"tv":463.36,"id":19587212}]}]}
{"op":"mcm","clk":"11793172850","pt":1723064692356,"mc":[{"id":"1.231541189","rc":[{"batb":[[0,3.05,4],[1,3,4],[2,2.98,26.42]],"ltp":3.2,"tv":463.36,"id":19587212},{"batl":[[0,1.47,12.14]],"ltp":1.45,"tv":5871.21,"id":19587555}]}]}
{"op":"mcm","clk":"11793172868","pt":1723064693127,"mc":[{"id":"1.231541189","rc":[{"batl":[[0,1.48,9.47],[1,1.49,38.03],[2,1.5,25.52]],"ltp":1.45,"tv":5871.21,"id":19587555}]}]}
{"op":"mcm","clk":"11793172937","pt":1723064695332,"mc":[{"id":"1.231541189","rc":[{"batb":[[0,3.1,4],[1,3.05,4],[2,3,4]],"ltp":3.2,"tv":463.36,"id":19587212}]}]}
{"op":"mcm","clk":"11793173016","pt":1723064697847,"mc":[{"id":"1.231541189","rc":[{"batb":[[0,3.05,4],[1,3,4],[2,2.98,26.42]],"ltp":3.2,"tv":463.36,"id":19587212}]}]}
{"op":"mcm","clk":"11793173112","pt":1723064701141,"mc":[{"id":"1.231541189","rc":[{"batb":[[0,3.1,4],[1,3.05,4],[2,3,4]],"ltp":3.2,"tv":463.36,"id":19587212}]}]}
{"op":"mcm","clk":"11793173208","pt":1723064703868,"mc":[{"id":"1.231541189","rc":[{"batb":[[0,3.05,4],[1,3,4],[2,2.98,26.42]],"ltp":3.2,"tv":463.36,"id":19587212}]}]}
{"op":"mcm","clk":"11793173307","pt":1723064706492,"mc":[{"id":"1.231541189","rc":[{"batb":[[0,3.1,4],[1,3.05,4],[2,3,4]],"ltp":3.2,"tv":463.36,"id":19587212}]}]}
{"op":"mcm","clk":"11793173373","pt":1723064708859,"mc":[{"id":"1.231541189","rc":[{"batb":[[0,3.05,4],[1,3,4],[2,2.98,26.42]],"ltp":3.2,"tv":463.36,"id":19587212}]}]}
{"op":"mcm","clk":"11793173441","pt":1723064711162,"mc":[{"id":"1.231541189","rc":[{"batb":[[0,3.1,4],[1,3.05,4],[2,3,4]],"ltp":3.2,"tv":463.36,"id":19587212}]}]}
{"op":"mcm","clk":"11793173531","pt":1723064713476,"mc":[{"id":"1.231541189","rc":[{"batb":[[0,3.05,4],[1,3,4],[2,2.98,26.42]],"ltp":3.2,"tv":463.36,"id":19587212}]}]}
{"op":"mcm","clk":"11793173616","pt":1723064716355,"mc":[{"id":"1.231541189","rc":[{"batb":[[0,3.1,4],[1,3.05,4],[2,3,4]],"ltp":3.2,"tv":463.36,"id":19587212}]}]}
{"op":"mcm","clk":"11793173677","pt":1723064718561,"mc":[{"id":"1.231541189","rc":[{"batb":[[0,3.05,4],[1,3,4],[2,2.98,26.42]],"ltp":3.2,"tv":463.36,"id":19587212}]}]}
{"op":"mcm","clk":"11793173736","pt":1723064721078,"mc":[{"id":"1.231541189","rc":[{"batb":[[0,3.1,4],[1,3.05,4],[2,3,4]],"ltp":3.2,"tv":463.36,"id":19587212}]}]}
{"op":"mcm","clk":"11793173758","pt":1723064721998,"mc":[{"id":"1.231541189","rc":[{"batl":[[0,1.47,4],[1,1.48,9.47],[2,1.49,38.03]],"ltp":1.45,"tv":5871.21,"id":19587555}]}]}
{"op":"mcm","clk":"11793173845","pt":1723064724461,"mc":[{"id":"1.231541189","rc":[{"batb":[[0,3.05,4],[1,3,4],[2,2.98,26.42]],"ltp":3.2,"tv":463.36,"id":19587212},{"batl":[[0,1.48,9.47],[1,1.49,38.03],[2,1.5,25.52]],"ltp":1.45,"tv":5871.21,"id":19587555}]}]}
{"op":"mcm","clk":"11793173870","pt":1723064725192,"mc":[{"id":"1.231541189","rc":[{"trd":[[3.25,0.1]],"batl":[[0,3.25,3.95]],"ltp":3.25,"tv":463.46,"id":19587212}],"tv":6334.68}]}
{"op":"mcm","clk":"11793173894","pt":1723064726267,"mc":[{"id":"1.231541189","rc":[{"batb":[[0,3.1,4],[1,3.05,4],[2,3,4]],"ltp":3.25,"tv":463.46,"id":19587212}]}]}
{"op":"mcm","clk":"11793173990","pt":1723064728581,"mc":[{"id":"1.231541189","rc":[{"batb":[[0,3.05,4],[1,3,4],[2,2.98,26.42]],"ltp":3.25,"tv":463.46,"id":19587212}]}]}
{"op":"mcm","clk":"11793174091","pt":1723064731912,"mc":[{"id":"1.231541189","rc":[{"batb":[[0,3.1,4],[1,3.05,4],[2,3,4]],"ltp":3.25,"tv":463.46,"id":19587212}]}]}
{"op":"mcm","clk":"11793174182","pt":1723064734419,"mc":[{"id":"1.231541189","rc":[{"batb":[[0,3.05,4],[1,3,4],[2,2.98,26.42]],"ltp":3.25,"tv":463.46,"id":19587212},{"batl":[[0,1.47,8.14],[1,1.48,9.47],[2,1.49,38.03]],"ltp":1.45,"tv":5871.21,"id":19587555}]}]}
{"op":"mcm","clk":"11793174270","pt":1723064737082,"mc":[{"id":"1.231541189","rc":[{"batb":[[0,3.1,4],[1,3.05,4],[2,3,4]],"ltp":3.25,"tv":463.46,"id":19587212},{"batl":[[0,1.47,12.14]],"ltp":1.45,"tv":5871.21,"id":19587555}]}]}
{"op":"mcm","clk":"11793174349","pt":1723064739386,"mc":[{"id":"1.231541189","rc":[{"batb":[[0,3.05,4],[1,3,4],[2,2.98,26.42]],"ltp":3.25,"tv":463.46,"id":19587212}]}]}
{"op":"mcm","clk":"11793174371","pt":1723064740002,"mc":[{"id":"1.231541189","rc":[{"batl":[[0,1.47,8.14]],"ltp":1.45,"tv":5871.21,"id":19587555}]}]}
{"op":"mcm","clk":"11793174492","pt":1723064742638,"mc":[{"id":"1.231541189","rc":[{"batb":[[0,3.1,4],[1,3.05,4],[2,3,4]],"ltp":3.25,"tv":463.46,"id":19587212}]}]}
{"op":"mcm","clk":"11793174600","pt":1723064745009,"mc":[{"id":"1.231541189","rc":[{"batb":[[0,3.05,4],[1,3,4],[2,2.98,26.42]],"ltp":3.25,"tv":463.46,"id":19587212}]}]}
{"op":"mcm","clk":"11793174732","pt":1723064748046,"mc":[{"id":"1.231541189","rc":[{"batb":[[0,3.1,4],[1,3.05,4],[2,3,4]],"ltp":3.25,"tv":463.46,"id":19587212}]}]}
{"op":"mcm","clk":"11793174820","pt":1723064750416,"mc":[{"id":"1.231541189","rc":[{"batb":[[0,3.05,4],[1,3,4],[2,2.98,26.42]],"ltp":3.25,"tv":463.46,"id":19587212}]}]}
{"op":"mcm","clk":"11793174894","pt":1723064752309,"mc":[{"id":"1.231541189","rc":[{"batl":[[0,1.47,12.14]],"ltp":1.45,"tv":5871.21,"id":19587555}]}]}
{"op":"mcm","clk":"11793174928","pt":1723064753037,"mc":[{"id":"1.231541189","rc":[{"batb":[[0,3.1,4],[1,3.05,4],[2,3,4]],"ltp":3.25,"tv":463.46,"id":19587212},{"batl":[[0,1.47,4]],"ltp":1.45,"tv":5871.21,"id":19587555}]}]}
{"op":"mcm","clk":"11793175034","pt":1723064755320,"mc":[{"id":"1.231541189","rc":[{"batb":[[0,3.05,4],[1,3,4],[2,2.98,26.42]],"ltp":3.25,"tv":463.46,"id":19587212}]}]}
{"op":"mcm","clk":"11793175053","pt":1723064756033,"mc":[{"id":"1.231541189","rc":[{"batl":[[0,1.48,9.47],[1,1.49,38.03],[2,1.5,25.52]],"ltp":1.45,"tv":5871.21,"id":19587555}]}]}
{"op":"mcm","clk":"11793175262","pt":1723064761948,"mc":[{"id":"1.231541189","rc":[{"batb":[[0,3.1,4],[1,3.05,4],[2,3,4]],"ltp":3.25,"tv":463.46,"id":19587212}]}]}
{"op":"mcm","clk":"11793175340","pt":1723064764564,"mc":[{"id":"1.231541189","rc":[{"batb":[[0,3.05,4],[1,3,4],[2,2.98,26.42]],"ltp":3.25,"tv":463.46,"id":19587212}]}]}
{"op":"mcm","clk":"11793175427","pt":1723064767333,"mc":[{"id":"1.231541189","rc":[{"batb":[[0,3.1,4],[1,3.05,4],[2,3,4]],"ltp":3.25,"tv":463.46,"id":19587212}]}]}
{"op":"mcm","clk":"11793175511","pt":1723064769744,"mc":[{"id":"1.231541189","rc":[{"batb":[[0,3.05,4],[1,3,4],[2,2.98,26.42]],"ltp":3.25,"tv":463.46,"id":19587212}]}]}
{"op":"mcm","clk":"11793175635","pt":1723064773586,"mc":[{"id":"1.231541189","rc":[{"batb":[[0,3.1,4],[1,3.05,4],[2,3,4]],"ltp":3.25,"tv":463.46,"id":19587212}]}]}
{"op":"mcm","clk":"11793175715","pt":1723064776050,"mc":[{"id":"1.231541189","rc":[{"batb":[[0,3.05,4],[1,3,4],[2,2.98,26.42]],"ltp":3.25,"tv":463.46,"id":19587212}]}]}
{"op":"mcm","clk":"11793175867","pt":1723064779692,"mc":[{"id":"1.231541189","rc":[{"batb":[[0,3.1,4],[1,3.05,4],[2,3,4]],"ltp":3.25,"tv":463.46,"id":19587212}]}]}
{"op":"mcm","clk":"11793175953","pt":1723064782156,"mc":[{"id":"1.231541189","rc":[{"batb":[[0,3.05,4],[1,3,4],[2,2.98,26.42]],"ltp":3.25,"tv":463.46,"id":19587212}]}]}
{"op":"mcm","clk":"11793176030","pt":1723064784559,"mc":[{"id":"1.231541189","rc":[{"batb":[[0,3.1,4],[1,3.05,4],[2,3,4]],"ltp":3.25,"tv":463.46,"id":19587212}]}]}
{"op":"mcm","clk":"11793176112","pt":1723064786973,"mc":[{"id":"1.231541189","rc":[{"batb":[[0,3.05,4],[1,3,4],[2,2.98,26.42]],"ltp":3.25,"tv":463.46,"id":19587212}]}]}
{"op":"mcm","clk":"11793176262","pt":1723064790401,"mc":[{"id":"1.231541189","rc":[{"batb":[[0,3.1,4],[1,3.05,4],[2,3,4]],"ltp":3.25,"tv":463.46,"id":19587212}]}]}
{"op":"mcm","clk":"11793176316","pt":1723064791894,"mc":[{"id":"1.231541189","rc":[{"batl":[[0,1.47,8.14],[1,1.48,9.47],[2,1.49,38.03]],"ltp":1.45,"tv":5871.21,"id":19587555}]}]}
{"op":"mcm","clk":"11793176341","pt":1723064792916,"mc":[{"id":"1.231541189","rc":[{"batb":[[0,3.05,4],[1,3,4],[2,2.98,26.42]],"ltp":3.25,"tv":463.46,"id":19587212}]}]}
{"op":"mcm","clk":"11793176421","pt":1723064795170,"mc":[{"id":"1.231541189","rc":[{"batb":[[0,3.1,4],[1,3.05,4],[2,3,4]],"ltp":3.25,"tv":463.46,"id":19587212}]}]}
{"op":"mcm","clk":"11793176517","pt":1723064797999,"mc":[{"id":"1.231541189","rc":[{"batb":[[0,3.05,4],[1,3,4],[2,2.98,26.42]],"ltp":3.25,"tv":463.46,"id":19587212},{"batl":[[0,1.47,4]],"ltp":1.45,"tv":5871.21,"id":19587555}]}]}
{"op":"mcm","clk":"11793176665","pt":1723064802412,"mc":[{"id":"1.231541189","rc":[{"batb":[[0,3.1,4],[1,3.05,4],[2,3,4]],"ltp":3.25,"tv":463.46,"id":19587212}]}]}
{"op":"mcm","clk":"11793176763","pt":1723064805121,"mc":[{"id":"1.231541189","rc":[{"batb":[[0,3.05,4],[1,3,4],[2,2.98,26.42]],"ltp":3.25,"tv":463.46,"id":19587212},{"batl":[[0,1.48,9.47],[1,1.49,38.03],[2,1.5,25.52]],"ltp":1.45,"tv":5871.21,"id":19587555}]}]}
{"op":"mcm","clk":"11793176842","pt":1723064808200,"mc":[{"id":"1.231541189","rc":[{"batb":[[0,3.1,4],[1,3.05,4],[2,3,4]],"ltp":3.25,"tv":463.46,"id":19587212}]}]}
{"op":"mcm","clk":"11793176905","pt":1723064810610,"mc":[{"id":"1.231541189","rc":[{"batb":[[0,3.05,4],[1,3,4],[2,2.98,26.42]],"ltp":3.25,"tv":463.46,"id":19587212}]}]}
{"op":"mcm","clk":"11793177101","pt":1723064817415,"mc":[{"id":"1.231541189","rc":[{"batb":[[0,3.1,4],[1,3.05,4],[2,3,4]],"ltp":3.25,"tv":463.46,"id":19587212}]}]}
{"op":"mcm","clk":"11793177183","pt":1723064819825,"mc":[{"id":"1.231541189","rc":[{"batb":[[0,3.05,4],[1,3,4],[2,2.98,26.42]],"ltp":3.25,"tv":463.46,"id":19587212}]}]}
{"op":"mcm","clk":"11793177241","pt":1723064822330,"mc":[{"id":"1.231541189","rc":[{"batb":[[0,3.1,4],[1,3.05,4],[2,3,4]],"ltp":3.25,"tv":463.46,"id":19587212}]}]}
{"op":"mcm","clk":"11793177322","pt":1723064824742,"mc":[{"id":"1.231541189","rc":[{"batb":[[0,3.05,4],[1,3,4],[2,2.98,26.42]],"ltp":3.25,"tv":463.46,"id":19587212}]}]}
{"op":"mcm","clk":"11793177475","pt":1723064829715,"mc":[{"id":"1.231541189","rc":[{"batb":[[0,3.1,4],[1,3.05,4],[2,3,4]],"ltp":3.25,"tv":463.46,"id":19587212}]}]}
{"op":"mcm","clk":"11793177571","pt":1723064832236,"mc":[{"id":"1.231541189","rc":[{"batb":[[0,3.05,4],[1,3,4],[2,2.98,26.42]],"ltp":3.25,"tv":463.46,"id":19587212}]}]}
{"op":"mcm","clk":"11793177708","pt":1723064834852,"mc":[{"id":"1.231541189","rc":[{"batb":[[0,3.1,4],[1,3.05,4],[2,3,4]],"ltp":3.25,"tv":463.46,"id":19587212}]}]}
{"op":"mcm","clk":"11793177791","pt":1723064837153,"mc":[{"id":"1.231541189","rc":[{"batb":[[0,3.05,4],[1,3,4],[2,2.98,26.42]],"ltp":3.25,"tv":463.46,"id":19587212}]}]}
{"op":"mcm","clk":"11793177880","pt":1723064839358,"mc":[{"id":"1.231541189","rc":[{"batb":[[0,3.1,4],[1,3.05,4],[2,3,4]],"ltp":3.25,"tv":463.46,"id":19587212}]}]}
{"op":"mcm","clk":"11793177974","pt":1723064841661,"mc":[{"id":"1.231541189","rc":[{"batb":[[0,3.05,4],[1,3,4],[2,2.98,26.42]],"ltp":3.25,"tv":463.46,"id":19587212}]}]}
{"op":"mcm","clk":"11793178081","pt":1723064844231,"mc":[{"id":"1.231541189","rc":[{"batb":[[0,3.1,4],[1,3.05,4],[2,3,4]],"ltp":3.25,"tv":463.46,"id":19587212}]}]}
{"op":"mcm","clk":"11793178161","pt":1723064846433,"mc":[{"id":"1.231541189","rc":[{"batb":[[0,3.05,4],[1,3,4],[2,2.98,26.42]],"ltp":3.25,"tv":463.46,"id":19587212}]}]}
{"op":"mcm","clk":"11793178303","pt":1723064849541,"mc":[{"id":"1.231541189","rc":[{"batb":[[0,3.1,4],[1,3.05,4],[2,3,4]],"ltp":3.25,"tv":463.46,"id":19587212},{"batl":[[0,1.47,8.14],[1,1.48,9.47],[2,1.49,38.03]],"ltp":1.45,"tv":5871.21,"id":19587555}]}]}
{"op":"mcm","clk":"11793178369","pt":1723064851342,"mc":[{"id":"1.231541189","rc":[{"batb":[[0,3.05,4],[1,3,4],[2,2.98,26.42]],"ltp":3.25,"tv":463.46,"id":19587212}]}]}
{"op":"mcm","clk":"11793178459","pt":1723064853752,"mc":[{"id":"1.231541189","rc":[{"batb":[[0,3.1,4],[1,3.05,4],[2,3,4]],"ltp":3.25,"tv":463.46,"id":19587212}]}]}
{"op":"mcm","clk":"11793178535","pt":1723064855969,"mc":[{"id":"1.231541189","rc":[{"batb":[[0,3.05,4],[1,3,4],[2,2.98,26.42]],"ltp":3.25,"tv":463.46,"id":19587212}]}]}
{"op":"mcm","clk":"11793178602","pt":1723064857973,"mc":[{"id":"1.231541189","rc":[{"batl":[[0,1.47,12.14]],"ltp":1.45,"tv":5871.21,"id":19587555}]}]}
{"op":"mcm","clk":"11793178652","pt":1723064859666,"mc":[{"id":"1.231541189","rc":[{"batb":[[0,3.1,4],[1,3.05,4],[2,3,4]],"ltp":3.25,"tv":463.46,"id":19587212}]}]}
{"op":"mcm","clk":"11793178736","pt":1723064861976,"mc":[{"id":"1.231541189","rc":[{"batb":[[0,3.05,4],[1,3,4],[2,2.98,26.42]],"ltp":3.25,"tv":463.46,"id":19587212}]}]}
{"op":"mcm","clk":"11793178759","pt":1723064862587,"mc":[{"id":"1.231541189","rc":[{"batl":[[0,1.47,8.14]],"ltp":1.45,"tv":5871.21,"id":19587555}]}]}
{"op":"mcm","clk":"11793178826","pt":1723064864176,"mc":[{"id":"1.231541189","rc":[{"batb":[[0,3.1,4],[1,3.05,4],[2,3,4]],"ltp":3.25,"tv":463.46,"id":19587212}]}]}
{"op":"mcm","clk":"11793178900","pt":1723064866485,"mc":[{"id":"1.231541189","rc":[{"batb":[[0,3.05,4],[1,3,4],[2,2.98,26.42]],"ltp":3.25,"tv":463.46,"id":19587212}]}]}
{"op":"mcm","clk":"11793179013","pt":1723064870273,"mc":[{"id":"1.231541189","rc":[{"batb":[[0,3.1,4],[1,3.05,4],[2,3,4]],"ltp":3.25,"tv":463.46,"id":19587212}]}]}
{"op":"mcm","clk":"11793179122","pt":1723064873196,"mc":[{"id":"1.231541189","rc":[{"batb":[[0,3.05,4],[1,3,4],[2,2.98,26.42]],"ltp":3.25,"tv":463.46,"id":19587212},{"batl":[[0,1.47,12.14]],"ltp":1.45,"tv":5871.21,"id":19587555}]}]}
{"op":"mcm","clk":"11793179181","pt":1723064874984,"mc":[{"id":"1.231541189","rc":[{"batb":[[0,3.1,4],[1,3.05,4],[2,3,4]],"ltp":3.25,"tv":463.46,"id":19587212},{"batl":[[0,1.47,4]],"ltp":1.45,"tv":5871.21,"id":19587555}]}]}
{"op":"mcm","clk":"11793179258","pt":1723064877193,"mc":[{"id":"1.231541189","rc":[{"batb":[[0,3.05,4],[1,3,4],[2,2.98,26.42]],"ltp":3.25,"tv":463.46,"id":19587212}]}]}
{"op":"mcm","clk":"11793179285","pt":1723064877909,"mc":[{"id":"1.231541189","rc":[{"batl":[[0,1.48,9.47],[1,1.49,38.03],[2,1.5,25.52]],"ltp":1.45,"tv":5871.21,"id":19587555}]}]}
{"op":"mcm","clk":"11793179356","pt":1723064879394,"mc":[{"id":"1.231541189","rc":[{"batb":[[0,3.1,4],[1,3.05,4],[2,3,4]],"ltp":3.25,"tv":463.46,"id":19587212}]}]}
{"op":"mcm","clk":"11793179447","pt":1723064881802,"mc":[{"id":"1.231541189","rc":[{"batb":[[0,3.05,4],[1,3,4],[2,2.98,26.42]],"ltp":3.25,"tv":463.46,"id":19587212}]}]}
{"op":"mcm","clk":"11793179527","pt":1723064884318,"mc":[{"id":"1.231541189","rc":[{"batb":[[0,3.1,4],[1,3.05,4],[2,3,4]],"ltp":3.25,"tv":463.46,"id":19587212}]}]}
{"op":"mcm","clk":"11793179626","pt":1723064887029,"mc":[{"id":"1.231541189","rc":[{"batb":[[0,3.05,4],[1,3,4],[2,2.98,26.42]],"ltp":3.25,"tv":463.46,"id":19587212}]}]}
{"op":"mcm","clk":"11793179721","pt":1723064889493,"mc":[{"id":"1.231541189","rc":[{"batb":[[0,3.1,4],[1,3.05,4],[2,3,4]],"ltp":3.25,"tv":463.46,"id":19587212}]}]}
{"op":"mcm","clk":"11793179791","pt":1723064891799,"mc":[{"id":"1.231541189","rc":[{"batb":[[0,3.05,4],[1,3,4],[2,2.98,26.42]],"ltp":3.25,"tv":463.46,"id":19587212}]}]}
{"op":"mcm","clk":"11793179900","pt":1723064895030,"mc":[{"id":"1.231541189","rc":[{"batb":[[0,3.1,4],[1,3.05,4],[2,3,4]],"ltp":3.25,"tv":463.46,"id":19587212}]}]}
{"op":"mcm","clk":"11793179992","pt":1723064897601,"mc":[{"id":"1.231541189","rc":[{"batb":[[0,3.05,4],[1,3,4],[2,2.98,26.42]],"ltp":3.25,"tv":463.46,"id":19587212}]}]}
{"op":"mcm","clk":"11793180097","pt":1723064900829,"mc":[{"id":"1.231541189","rc":[{"batb":[[0,3.1,4],[1,3.05,4],[2,3,4]],"ltp":3.25,"tv":463.46,"id":19587212}]}]}
{"op":"mcm","clk":"11793180181","pt":1723064903140,"mc":[{"id":"1.231541189","rc":[{"batb":[[0,3.05,4],[1,3,4],[2,2.98,26.42]],"ltp":3.25,"tv":463.46,"id":19587212}]}]}
{"op":"mcm","clk":"11793180242","pt":1723064904626,"mc":[{"id":"1.231541189","rc":[{"batl":[[0,1.47,4],[1,1.48,9.47],[2,1.49,38.03]],"ltp":1.45,"tv":5871.21,"id":19587555}]}]}
{"op":"mcm","clk":"11793180282","pt":1723064905853,"mc":[{"id":"1.231541189","rc":[{"batb":[[0,3.1,4],[1,3.05,4],[2,3,4]],"ltp":3.25,"tv":463.46,"id":19587212}]}]}
{"op":"mcm","clk":"11793180385","pt":1723064908368,"mc":[{"id":"1.231541189","rc":[{"batb":[[0,3.05,4],[1,3,4],[2,2.98,26.42]],"ltp":3.25,"tv":463.46,"id":19587212},{"batl":[[0,1.47,8.14]],"ltp":1.45,"tv":5871.21,"id":19587555}]}]}
{"op":"mcm","clk":"11793180479","pt":1723064910622,"mc":[{"id":"1.231541189","rc":[{"batb":[[0,3.1,4],[1,3.05,4],[2,3,4]],"ltp":3.25,"tv":463.46,"id":19587212}]}]}
{"op":"mcm","clk":"11793180544","pt":1723064913030,"mc":[{"id":"1.231541189","rc":[{"batb":[[0,3.05,4],[1,3,4],[2,2.98,26.42]],"ltp":3.25,"tv":463.46,"id":19587212}]}]}
{"op":"mcm","clk":"11793180617","pt":1723064915233,"mc":[{"id":"1.231541189","rc":[{"batb":[[0,3.1,4],[1,3.05,4],[2,3,4]],"ltp":3.25,"tv":463.46,"id":19587212}]}]}
{"op":"mcm","clk":"11793180718","pt":1723064917747,"mc":[{"id":"1.231541189","rc":[{"batb":[[0,3.05,4],[1,3,4],[2,2.98,26.42]],"ltp":3.25,"tv":463.46,"id":19587212}]}]}
{"op":"mcm","clk":"11793180796","pt":1723064919751,"mc":[{"id":"1.231541189","rc":[{"batl":[[0,1.47,12.14]],"ltp":1.45,"tv":5871.21,"id":19587555}]}]}
{"op":"mcm","clk":"11793180828","pt":1723064920875,"mc":[{"id":"1.231541189","rc":[{"batb":[[0,3.1,4],[1,3.05,4],[2,3,4]],"ltp":3.25,"tv":463.46,"id":19587212},{"batl":[[0,1.48,9.47],[1,1.49,38.03],[2,1.5,25.52]],"ltp":1.45,"tv":5871.21,"id":19587555}]}]}
{"op":"mcm","clk":"11793180908","pt":1723064923075,"mc":[{"id":"1.231541189","rc":[{"batb":[[0,3.05,4],[1,3,4],[2,2.98,26.42]],"ltp":3.25,"tv":463.46,"id":19587212}]}]}
{"op":"mcm","clk":"11793180994","pt":1723064925480,"mc":[{"id":"1.231541189","rc":[{"batb":[[0,3.1,4],[1,3.05,4],[2,3,4]],"ltp":3.25,"tv":463.46,"id":19587212}]}]}
{"op":"mcm","clk":"11793181078","pt":1723064927783,"mc":[{"id":"1.231541189","rc":[{"batb":[[0,3.05,4],[1,3,4],[2,2.98,26.42]],"ltp":3.25,"tv":463.46,"id":19587212}]}]}
{"op":"mcm","clk":"11793181196","pt":1723064930350,"mc":[{"id":"1.231541189","rc":[{"batb":[[0,3.1,4],[1,3.05,4],[2,3,4]],"ltp":3.25,"tv":463.46,"id":19587212}]}]}
{"op":"mcm","clk":"11793181287","pt":1723064932759,"mc":[{"id":"1.231541189","rc":[{"batb":[[0,3.05,4],[1,3,4],[2,2.98,26.42]],"ltp":3.25,"tv":463.46,"id":19587212}]}]}
{"op":"mcm","clk":"11793181368","pt":1723064935191,"mc":[{"id":"1.231541189","rc":[{"batb":[[0,3.1,4],[1,3.05,4],[2,3,4]],"ltp":3.25,"tv":463.46,"id":19587212}]}]}
{"op":"mcm","clk":"11793181422","pt":1723064936475,"mc":[{"id":"1.231541189","rc":[{"batb":[[2,3,26.09]],"ltp":3.25,"tv":463.46,"id":19587212},{"batb":[[2,1.36,121.53]],"ltp":1.45,"tv":5871.21,"id":19587555}]}]}
{"op":"mcm","clk":"11793181461","pt":1723064937391,"mc":[{"id":"1.231541189","rc":[{"batb":[[0,3.05,4],[1,3,26.09],[2,2.98,26.42]],"ltp":3.25,"tv":463.46,"id":19587212}]}]}
{"op":"mcm","clk":"11793181629","pt":1723064940894,"mc":[{"id":"1.231541189","rc":[{"batb":[[0,3.1,4],[1,3.05,4],[2,3,26.09]],"ltp":3.25,"tv":463.46,"id":19587212}]}]}
{"op":"mcm","clk":"11793181777","pt":1723064943365,"mc":[{"id":"1.231541189","rc":[{"batb":[[0,3.05,4],[1,3,26.09],[2,2.98,26.42]],"ltp":3.25,"tv":463.46,"id":19587212}]}]}
{"op":"mcm","clk":"11793181917","pt":1723064946809,"mc":[{"id":"1.231541189","rc":[{"batb":[[0,3.1,4],[1,3.05,4],[2,3,26.09]],"ltp":3.25,"tv":463.46,"id":19587212}]}]}
{"op":"mcm","clk":"11793182028","pt":1723064949483,"mc":[{"id":"1.231541189","rc":[{"batb":[[0,3.05,4],[1,3,26.09],[2,2.98,26.42]],"ltp":3.25,"tv":463.46,"id":19587212}]}]}
{"op":"mcm","clk":"11793182043","pt":1723064949997,"mc":[{"id":"1.231541189","rc":[{"batl":[[0,1.47,4],[1,1.48,9.47],[2,1.49,38.03]],"ltp":1.45,"tv":5871.21,"id":19587555}]}]}
{"op":"mcm","clk":"11793182133","pt":1723064952721,"mc":[{"id":"1.231541189","rc":[{"batb":[[0,3.1,4],[1,3.05,4],[2,3,26.09]],"ltp":3.25,"tv":463.46,"id":19587212}]}]}
{"op":"mcm","clk":"11793182254","pt":1723064955504,"mc":[{"id":"1.231541189","rc":[{"batb":[[0,3.05,4],[1,3,26.09],[2,2.98,26.42]],"ltp":3.25,"tv":463.46,"id":19587212},{"batl":[[0,1.48,9.47],[1,1.49,38.03],[2,1.5,25.52]],"ltp":1.45,"tv":5871.21,"id":19587555}]}]}
{"op":"mcm","clk":"11793182309","pt":1723064957197,"mc":[{"id":"1.231541189","rc":[{"batb":[[0,3.1,4],[1,3.05,4],[2,3,26.09]],"ltp":3.25,"tv":463.46,"id":19587212}]}]}
{"op":"mcm","clk":"11793182419","pt":1723064959609,"mc":[{"id":"1.231541189","rc":[{"batb":[[0,3.05,4],[1,3,26.09],[2,2.98,26.42]],"ltp":3.25,"tv":463.46,"id":19587212}]}]}
{"op":"mcm","clk":"11793182548","pt":1723064963214,"mc":[{"id":"1.231541189","rc":[{"batb":[[0,3.1,4],[1,3.05,4],[2,3,26.09]],"ltp":3.25,"tv":463.46,"id":19587212}]}]}
{"op":"mcm","clk":"11793182570","pt":1723064963727,"mc":[{"id":"1.231541189","rc":[{"batl":[[0,1.47,8.14],[1,1.48,9.47],[2,1.49,38.03]],"ltp":1.45,"tv":5871.21,"id":19587555}]}]}
{"op":"mcm","clk":"11793182639","pt":1723064965114,"mc":[{"id":"1.231541189","rc":[{"batl":[[0,1.47,12.14]],"ltp":1.45,"tv":5871.21,"id":19587555}]}]}
{"op":"mcm","clk":"11793182686","pt":1723064966296,"mc":[{"id":"1.231541189","rc":[{"batb":[[0,3.05,4],[1,3,26.09],[2,2.98,26.42]],"ltp":3.25,"tv":463.46,"id":19587212},{"batl":[[0,1.47,8.14]],"ltp":1.45,"tv":5871.21,"id":19587555}]}]}
{"op":"mcm","clk":"11793182770","pt":1723064968809,"mc":[{"id":"1.231541189","rc":[{"batb":[[0,3.1,4],[1,3.05,4],[2,3,26.09]],"ltp":3.25,"tv":463.46,"id":19587212}]}]}
{"op":"mcm","clk":"11793182863","pt":1723064971123,"mc":[{"id":"1.231541189","rc":[{"batb":[[0,3.05,4],[1,3,26.09],[2,2.98,26.42]],"ltp":3.25,"tv":463.46,"id":19587212}]}]}
{"op":"mcm","clk":"11793182966","pt":1723064973741,"mc":[{"id":"1.231541189","rc":[{"batb":[[0,3.1,4],[1,3.05,4],[2,3,26.09]],"ltp":3.25,"tv":463.46,"id":19587212}]}]}
{"op":"mcm","clk":"11793183064","pt":1723064976255,"mc":[{"id":"1.231541189","rc":[{"batb":[[0,3.05,4],[1,3,26.09],[2,2.98,26.42]],"ltp":3.25,"tv":463.46,"id":19587212}]}]}
{"op":"mcm","clk":"11793183190","pt":1723064979339,"mc":[{"id":"1.231541189","rc":[{"batb":[[0,3.1,4],[1,3.05,4],[2,3,26.09]],"ltp":3.25,"tv":463.46,"id":19587212}]}]}
{"op":"mcm","clk":"11793183225","pt":1723064980262,"mc":[{"id":"1.231541189","rc":[{"batl":[[0,1.47,12.14]],"ltp":1.45,"tv":5871.21,"id":19587555}]}]}
{"op":"mcm","clk":"11793183284","pt":1723064981542,"mc":[{"id":"1.231541189","rc":[{"batb":[[0,3.05,4],[1,3,26.09],[2,2.98,26.42]],"ltp":3.25,"tv":463.46,"id":19587212}]}]}
{"op":"mcm","clk":"11793183293","pt":1723064981748,"mc":[{"id":"1.231541189","rc":[{"batl":[[0,1.47,8.14]],"ltp":1.45,"tv":5871.21,"id":19587555}]}]}
{"op":"mcm","clk":"11793183390","pt":1723064983851,"mc":[{"id":"1.231541189","rc":[{"batb":[[0,3.1,4],[1,3.05,4],[2,3,26.09]],"ltp":3.25,"tv":463.46,"id":19587212}]}]}
{"op":"mcm","clk":"11793183486","pt":1723064986162,"mc":[{"id":"1.231541189","rc":[{"batb":[[0,3.05,4],[1,3,26.09],[2,2.98,26.42]],"ltp":3.25,"tv":463.46,"id":19587212}]}]}
{"op":"mcm","clk":"11793183607","pt":1723064989240,"mc":[{"id":"1.231541189","rc":[{"batb":[[0,3.1,4],[1,3.05,4],[2,3,26.09]],"ltp":3.25,"tv":463.46,"id":19587212}]}]}
{"op":"mcm","clk":"11793183708","pt":1723064991551,"mc":[{"id":"1.231541189","rc":[{"batb":[[0,3.05,4],[1,3,26.09],[2,2.98,26.42]],"ltp":3.25,"tv":463.46,"id":19587212}]}]}
{"op":"mcm","clk":"11793183870","pt":1723064995247,"mc":[{"id":"1.231541189","rc":[{"batb":[[0,3.1,4],[1,3.05,4],[2,3,26.09]],"ltp":3.25,"tv":463.46,"id":19587212},{"batl":[[0,1.47,12.14]],"ltp":1.45,"tv":5871.21,"id":19587555}]}]}
{"op":"mcm","clk":"11793183942","pt":1723064997247,"mc":[{"id":"1.231541189","rc":[{"batb":[[0,3.05,4],[1,3,26.09],[2,2.98,26.42]],"ltp":3.25,"tv":463.46,"id":19587212}]}]}
{"op":"mcm","clk":"11793183962","pt":1723064997759,"mc":[{"id":"1.231541189","rc":[{"batl":[[0,1.47,8.14]],"ltp":1.45,"tv":5871.21,"id":19587555}]}]}
{"op":"mcm","clk":"11793184052","pt":1723064999656,"mc":[{"id":"1.231541189","rc":[{"batb":[[0,3.1,4],[1,3.05,4],[2,3,26.09]],"ltp":3.25,"tv":463.46,"id":19587212}]}]}
{"op":"mcm","clk":"11793184156","pt":1723065002070,"mc":[{"id":"1.231541189","rc":[{"batb":[[0,3.05,4],[1,3,26.09],[2,2.98,26.42]],"ltp":3.25,"tv":463.46,"id":19587212}]}]}
{"op":"mcm","clk":"11793184319","pt":1723065005876,"mc":[{"id":"1.231541189","rc":[{"batb":[[0,3.1,4],[1,3.05,4],[2,3,26.09]],"ltp":3.25,"tv":463.46,"id":19587212}]}]}
{"op":"mcm","clk":"11793184434","pt":1723065008292,"mc":[{"id":"1.231541189","rc":[{"batb":[[0,3.05,4],[1,3,26.09],[2,2.98,26.42]],"ltp":3.25,"tv":463.46,"id":19587212}]}]}
{"op":"mcm","clk":"11793184524","pt":1723065010456,"mc":[{"id":"1.231541189","rc":[{"batl":[[0,1.47,12.14]],"ltp":1.45,"tv":5871.21,"id":19587555}]}]}
{"op":"mcm","clk":"11793184538","pt":1723065010662,"mc":[{"id":"1.231541189","rc":[{"batb":[[0,3.1,4],[1,3.05,4],[2,3,26.09]],"ltp":3.25,"tv":463.46,"id":19587212}]}]}
{"op":"mcm","clk":"11793184652","pt":1723065013287,"mc":[{"id":"1.231541189","rc":[{"batb":[[0,3.05,4],[1,3,26.09],[2,2.98,26.42]],"ltp":3.25,"tv":463.46,"id":19587212},{"batl":[[0,1.47,8.14]],"ltp":1.45,"tv":5871.21,"id":19587555}]}]}
{"op":"mcm","clk":"11793184752","pt":1723065015605,"mc":[{"id":"1.231541189","rc":[{"batb":[[0,3.1,4],[1,3.05,4],[2,3,26.09]],"ltp":3.25,"tv":463.46,"id":19587212}]}]}
{"op":"mcm","clk":"11793184836","pt":1723065017764,"mc":[{"id":"1.231541189","rc":[{"batb":[[0,3.05,4],[1,3,26.09],[2,2.98,26.42]],"ltp":3.25,"tv":463.46,"id":19587212}]}]}
{"op":"mcm","clk":"11793184937","pt":1723065020379,"mc":[{"id":"1.231541189","rc":[{"batb":[[0,3.1,4],[1,3.05,4],[2,3,26.09]],"ltp":3.25,"tv":463.46,"id":19587212}]}]}
{"op":"mcm","clk":"11793185071","pt":1723065022796,"mc":[{"id":"1.231541189","rc":[{"batb":[[0,3.05,4],[1,3,26.09],[2,2.98,26.42]],"ltp":3.25,"tv":463.46,"id":19587212}]}]}
{"op":"mcm","clk":"11793185172","pt":1723065025109,"mc":[{"id":"1.231541189","rc":[{"batb":[[0,3.1,4],[1,3.05,4],[2,3,26.09]],"ltp":3.25,"tv":463.46,"id":19587212}]}]}
{"op":"mcm","clk":"11793185196","pt":1723065025579,"mc":[{"id":"1.231541189","rc":[{"batl":[[0,1.47,12.14]],"ltp":1.45,"tv":5871.21,"id":19587555}]}]}
{"op":"mcm","clk":"11793185268","pt":1723065027476,"mc":[{"id":"1.231541189","rc":[{"batb":[[0,3.05,4],[1,3,26.09],[2,2.98,26.42]],"ltp":3.25,"tv":463.46,"id":19587212}]}]}
{"op":"mcm","clk":"11793185278","pt":1723065027883,"mc":[{"id":"1.231541189","rc":[{"batl":[[0,1.47,8.14]],"ltp":1.45,"tv":5871.21,"id":19587555}]}]}
{"op":"mcm","clk":"11793185431","pt":1723065031785,"mc":[{"id":"1.231541189","rc":[{"batb":[[0,3.1,4],[1,3.05,4],[2,3,26.09]],"ltp":3.25,"tv":463.46,"id":19587212}]}]}
{"op":"mcm","clk":"11793185523","pt":1723065034096,"mc":[{"id":"1.231541189","rc":[{"batb":[[0,3.05,4],[1,3,26.09],[2,2.98,26.42]],"ltp":3.25,"tv":463.46,"id":19587212}]}]}
{"op":"mcm","clk":"11793185620","pt":1723065036868,"mc":[{"id":"1.231541189","rc":[{"batb":[[0,3.1,4],[1,3.05,4],[2,3,26.09]],"ltp":3.25,"tv":463.46,"id":19587212}]}]}
{"op":"mcm","clk":"11793185711","pt":1723065039021,"mc":[{"id":"1.231541189","rc":[{"batb":[[0,3.05,4],[1,3,26.09],[2,2.98,26.42]],"ltp":3.25,"tv":463.46,"id":19587212}]}]}
{"op":"mcm","clk":"11793185777","pt":1723065040712,"mc":[{"id":"1.231541189","rc":[{"batl":[[0,1.47,12.14]],"ltp":1.45,"tv":5871.21,"id":19587555}]}]}
{"op":"mcm","clk":"11793185811","pt":1723065041840,"mc":[{"id":"1.231541189","rc":[{"batb":[[0,3.1,4],[1,3.05,4],[2,3,26.09]],"ltp":3.25,"tv":463.46,"id":19587212},{"batl":[[0,1.47,4]],"ltp":1.45,"tv":5871.21,"id":19587555}]}]}
{"op":"mcm","clk":"11793185882","pt":1723065044317,"mc":[{"id":"1.231541189","rc":[{"batb":[[0,3.05,4],[1,3,26.09],[2,2.98,26.42]],"ltp":3.25,"tv":463.46,"id":19587212},{"batl":[[0,1.47,8.14]],"ltp":1.45,"tv":5871.21,"id":19587555}]}]}
{"op":"mcm","clk":"11793185955","pt":1723065046626,"mc":[{"id":"1.231541189","rc":[{"batb":[[0,3.1,4],[1,3.05,4],[2,3,26.09]],"ltp":3.25,"tv":463.46,"id":19587212}]}]}
{"op":"mcm","clk":"11793186060","pt":1723065049037,"mc":[{"id":"1.231541189","rc":[{"batb":[[0,3.05,4],[1,3,26.09],[2,2.98,26.42]],"ltp":3.25,"tv":463.46,"id":19587212}]}]}
{"op":"mcm","clk":"11793186155","pt":1723065051347,"mc":[{"id":"1.231541189","rc":[{"batb":[[0,3.1,4],[1,3.05,4],[2,3,26.09]],"ltp":3.25,"tv":463.46,"id":19587212}]}]}
{"op":"mcm","clk":"11793186245","pt":1723065053551,"mc":[{"id":"1.231541189","rc":[{"batb":[[0,3.05,4],[1,3,26.09],[2,2.98,26.42]],"ltp":3.25,"tv":463.46,"id":19587212}]}]}
{"op":"mcm","clk":"11793186314","pt":1723065055957,"mc":[{"id":"1.231541189","rc":[{"batb":[[0,3.1,4],[1,3.05,4],[2,3,26.09]],"ltp":3.25,"tv":463.46,"id":19587212},{"batl":[[0,1.47,12.14]],"ltp":1.45,"tv":5871.21,"id":19587555}]}]}
{"op":"mcm","clk":"11793186403","pt":1723065058264,"mc":[{"id":"1.231541189","rc":[{"batb":[[0,3.05,4],[1,3,26.09],[2,2.98,26.42]],"ltp":3.25,"tv":463.46,"id":19587212}]}]}
{"op":"mcm","clk":"11793186426","pt":1723065058828,"mc":[{"id":"1.231541189","rc":[{"batl":[[0,1.47,8.14]],"ltp":1.45,"tv":5871.21,"id":19587555}]}]}
{"op":"mcm","clk":"11793186521","pt":1723065061235,"mc":[{"id":"1.231541189","rc":[{"batb":[[0,3.1,4],[1,3.05,4],[2,3,26.09]],"ltp":3.25,"tv":463.46,"id":19587212}]}]}
{"op":"mcm","clk":"11793186609","pt":1723065063439,"mc":[{"id":"1.231541189","rc":[{"batb":[[0,3.05,4],[1,3,26.09],[2,2.98,26.42]],"ltp":3.25,"tv":463.46,"id":19587212}]}]}
{"op":"mcm","clk":"11793186702","pt":1723065065640,"mc":[{"id":"1.231541189","rc":[{"batb":[[0,3.1,4],[1,3.05,4],[2,3,26.09]],"ltp":3.25,"tv":463.46,"id":19587212}]}]}
{"op":"mcm","clk":"11793186775","pt":1723065067944,"mc":[{"id":"1.231541189","rc":[{"batb":[[0,3.05,4],[1,3,26.09],[2,2.98,26.42]],"ltp":3.25,"tv":463.46,"id":19587212}]}]}
{"op":"mcm","clk":"11793186856","pt":1723065071074,"mc":[{"id":"1.231541189","rc":[{"batb":[[0,3.1,4],[1,3.05,4],[2,3,26.09]],"ltp":3.25,"tv":463.46,"id":19587212},{"batl":[[0,1.47,12.14]],"ltp":1.45,"tv":5871.21,"id":19587555}]}]}
{"op":"mcm","clk":"11793186934","pt":1723065073376,"mc":[{"id":"1.231541189","rc":[{"batb":[[0,3.05,4],[1,3,26.09],[2,2.98,26.42]],"ltp":3.25,"tv":463.46,"id":19587212}]}]}
{"op":"mcm","clk":"11793186955","pt":1723065073851,"mc":[{"id":"1.231541189","rc":[{"batl":[[0,1.47,8.14]],"ltp":1.45,"tv":5871.21,"id":19587555}]}]}
{"op":"mcm","clk":"11793187073","pt":1723065077598,"mc":[{"id":"1.231541189","rc":[{"batb":[[0,3.1,4],[1,3.05,4],[2,3,26.09]],"ltp":3.25,"tv":463.46,"id":19587212}]}]}
{"op":"mcm","clk":"11793187179","pt":1723065079955,"mc":[{"id":"1.231541189","rc":[{"batb":[[0,3.05,4],[1,3,26.09],[2,2.98,26.42]],"ltp":3.25,"tv":463.46,"id":19587212}]}]}
{"op":"mcm","clk":"11793187357","pt":1723065084271,"mc":[{"id":"1.231541189","rc":[{"batb":[[0,3.1,4],[1,3.05,4],[2,3,26.09]],"ltp":3.25,"tv":463.46,"id":19587212}]}]}
{"op":"mcm","clk":"11793187427","pt":1723065086010,"mc":[{"id":"1.231541189","rc":[{"batl":[[0,1.47,12.14]],"ltp":1.45,"tv":5871.21,"id":19587555}]}]}
{"op":"mcm","clk":"11793187449","pt":1723065086577,"mc":[{"id":"1.231541189","rc":[{"batb":[[0,3.05,4],[1,3,26.09],[2,2.98,26.42]],"ltp":3.25,"tv":463.46,"id":19587212}]}]}
{"op":"mcm","clk":"11793187527","pt":1723065088272,"mc":[{"id":"1.231541189","rc":[{"batl":[[0,1.48,9.47],[1,1.49,38.03],[2,1.5,25.52]],"ltp":1.45,"tv":5871.21,"id":19587555}]}]}
{"op":"mcm","clk":"11793187627","pt":1723065090422,"mc":[{"id":"1.231541189","rc":[{"batb":[[0,3.1,4],[1,3.05,4],[2,3,26.09]],"ltp":3.25,"tv":463.46,"id":19587212}]}]}
{"op":"mcm","clk":"11793187731","pt":1723065092992,"mc":[{"id":"1.231541189","rc":[{"batb":[[0,3.05,4],[1,3,26.09],[2,2.98,26.42]],"ltp":3.25,"tv":463.46,"id":19587212}]}]}
{"op":"mcm","clk":"11793187833","pt":1723065096317,"mc":[{"id":"1.231541189","rc":[{"batb":[[0,3.1,4],[1,3.05,4],[2,3,26.09]],"ltp":3.25,"tv":463.46,"id":19587212}]}]}
{"op":"mcm","clk":"11793187877","pt":1723065097394,"mc":[{"id":"1.231541189","rc":[{"batl":[[0,1.47,8.14],[1,1.48,9.47],[2,1.49,38.03]],"ltp":1.45,"tv":5871.21,"id":19587555}]}]}
{"op":"mcm","clk":"11793187925","pt":1723065098894,"mc":[{"id":"1.231541189","rc":[{"batb":[[0,3.05,4],[1,3,26.09],[2,2.98,26.42]],"ltp":3.25,"tv":463.46,"id":19587212}]}]}
{"op":"mcm","clk":"11793187999","pt":1723065101299,"mc":[{"id":"1.231541189","rc":[{"batb":[[0,3.1,4],[1,3.05,4],[2,3,26.09]],"ltp":3.25,"tv":463.46,"id":19587212},{"batl":[[0,1.47,12.14]],"ltp":1.45,"tv":5871.21,"id":19587555}]}]}
{"op":"mcm","clk":"11793188064","pt":1723065103511,"mc":[{"id":"1.231541189","rc":[{"batb":[[0,3.05,4],[1,3,26.09],[2,2.98,26.42]],"ltp":3.25,"tv":463.46,"id":19587212}]}]}
{"op":"mcm","clk":"11793188076","pt":1723065103919,"mc":[{"id":"1.231541189","rc":[{"batl":[[0,1.47,8.14]],"ltp":1.45,"tv":5871.21,"id":19587555}]}]}
{"op":"mcm","clk":"11793188136","pt":1723065106123,"mc":[{"id":"1.231541189","rc":[{"batb":[[0,3.1,4],[1,3.05,4],[2,3,26.09]],"ltp":3.25,"tv":463.46,"id":19587212}]}]}
{"op":"mcm","clk":"11793188199","pt":1723065108641,"mc":[{"id":"1.231541189","rc":[{"batb":[[0,3.05,4],[1,3,26.09],[2,2.98,26.42]],"ltp":3.25,"tv":463.46,"id":19587212}]}]}
{"op":"mcm","clk":"11793188387","pt":1723065111052,"mc":[{"id":"1.231541189","rc":[{"batb":[[0,3.1,4],[1,3.05,4],[2,3,26.09]],"ltp":3.25,"tv":463.46,"id":19587212}]}]}
{"op":"mcm","clk":"11793188612","pt":1723065113516,"mc":[{"id":"1.231541189","rc":[{"batb":[[0,3.05,4],[1,3,26.09],[2,2.98,26.42]],"ltp":3.25,"tv":463.46,"id":19587212}]}]}
{"op":"mcm","clk":"11793188721","pt":1723065116347,"mc":[{"id":"1.231541189","rc":[{"batb":[[0,3.1,4],[1,3.05,4],[2,3,26.09]],"ltp":3.25,"tv":463.46,"id":19587212},{"batl":[[0,1.47,12.14]],"ltp":1.45,"tv":5871.21,"id":19587555}]}]}
{"op":"mcm","clk":"11793188802","pt":1723065118855,"mc":[{"id":"1.231541189","rc":[{"batb":[[0,3.05,4],[1,3,26.09],[2,2.98,26.42]],"ltp":3.25,"tv":463.46,"id":19587212},{"batl":[[0,1.47,8.14]],"ltp":1.45,"tv":5871.21,"id":19587555}]}]}
{"op":"mcm","clk":"11793188900","pt":1723065121934,"mc":[{"id":"1.231541189","rc":[{"batb":[[0,3.1,4],[1,3.05,4],[2,3,26.09]],"ltp":3.25,"tv":463.46,"id":19587212}]}]}
{"op":"mcm","clk":"11793188984","pt":1723065124343,"mc":[{"id":"1.231541189","rc":[{"batb":[[0,3.05,4],[1,3,26.09],[2,2.98,26.42]],"ltp":3.25,"tv":463.46,"id":19587212}]}]}
{"op":"mcm","clk":"11793189050","pt":1723065126548,"mc":[{"id":"1.231541189","rc":[{"batb":[[0,3.1,4],[1,3.05,4],[2,3,26.09]],"ltp":3.25,"tv":463.46,"id":19587212}]}]}
{"op":"mcm","clk":"11793189118","pt":1723065129062,"mc":[{"id":"1.231541189","rc":[{"batb":[[0,3.05,4],[1,3,26.09],[2,2.98,26.42]],"ltp":3.25,"tv":463.46,"id":19587212}]}]}
{"op":"mcm","clk":"11793189178","pt":1723065131473,"mc":[{"id":"1.231541189","rc":[{"batb":[[0,3.1,4],[1,3.05,4],[2,3,26.09]],"ltp":3.25,"tv":463.46,"id":19587212},{"batl":[[0,1.47,12.14]],"ltp":1.45,"tv":5871.21,"id":19587555}]}]}
{"op":"mcm","clk":"11793189186","pt":1723065131777,"mc":[{"id":"1.231541189","rc":[{"batl":[[0,1.47,4]],"ltp":1.45,"tv":5871.21,"id":19587555}]}]}
{"op":"mcm","clk":"11793189261","pt":1723065134448,"mc":[{"id":"1.231541189","rc":[{"batb":[[0,3.05,4],[1,3,26.09],[2,2.98,26.42]],"ltp":3.25,"tv":463.46,"id":19587212},{"batl":[[0,1.48,9.47],[1,1.49,38.03],[2,1.5,25.52]],"ltp":1.45,"tv":5871.21,"id":19587555}]}]}
{"op":"mcm","clk":"11793189353","pt":1723065136857,"mc":[{"id":"1.231541189","rc":[{"batb":[[0,3.1,4],[1,3.05,4],[2,3,26.09]],"ltp":3.25,"tv":463.46,"id":19587212}]}]}
{"op":"mcm","clk":"11793189428","pt":1723065139178,"mc":[{"id":"1.231541189","rc":[{"batb":[[0,3.05,4],[1,3,26.09],[2,2.98,26.42]],"ltp":3.25,"tv":463.46,"id":19587212}]}]}
{"op":"mcm","clk":"11793189521","pt":1723065141591,"mc":[{"id":"1.231541189","rc":[{"batb":[[0,3.1,4],[1,3.05,4],[2,3,26.09]],"ltp":3.25,"tv":463.46,"id":19587212}]}]}
{"op":"mcm","clk":"11793189606","pt":1723065143791,"mc":[{"id":"1.231541189","rc":[{"batb":[[0,3.05,4],[1,3,26.09],[2,2.98,26.42]],"ltp":3.25,"tv":463.46,"id":19587212}]}]}
{"op":"mcm","clk":"11793189674","pt":1723065146152,"mc":[{"id":"1.231541189","rc":[{"batb":[[0,3.1,4],[1,3.05,4],[2,3,26.09]],"ltp":3.25,"tv":463.46,"id":19587212}]}]}
{"op":"mcm","clk":"11793189760","pt":1723065148357,"mc":[{"id":"1.231541189","rc":[{"batb":[[0,3.05,8.34],[1,3,26.09],[2,2.98,26.42]],"ltp":3.25,"tv":463.46,"id":19587212}]}]}
{"op":"mcm","clk":"11793189854","pt":1723065150887,"mc":[{"id":"1.231541189","rc":[{"batb":[[0,3.1,4],[1,3.05,8.34],[2,3,26.09]],"ltp":3.25,"tv":463.46,"id":19587212}]}]}
{"op":"mcm","clk":"11793189898","pt":1723065152501,"mc":[{"id":"1.231541189","rc":[{"batl":[[0,1.47,8.14],[1,1.48,9.47],[2,1.49,38.03]],"ltp":1.45,"tv":5871.21,"id":19587555}]}]}
{"op":"mcm","clk":"11793189927","pt":1723065153276,"mc":[{"id":"1.231541189","rc":[{"batb":[[0,3.05,8.34],[1,3,26.09],[2,2.98,26.42]],"ltp":3.25,"tv":463.46,"id":19587212}]}]}
{"op":"mcm","clk":"11793190045","pt":1723065157072,"mc":[{"id":"1.231541189","rc":[{"batb":[[0,3.1,4],[1,3.05,8.34],[2,3,26.09]],"ltp":3.25,"tv":463.46,"id":19587212}]}]}
{"op":"mcm","clk":"11793190125","pt":1723065159689,"mc":[{"id":"1.231541189","rc":[{"batb":[[0,3.05,8.34],[1,3,26.09],[2,2.98,26.42]],"ltp":3.25,"tv":463.46,"id":19587212}]}]}
{"op":"mcm","clk":"11793190187","pt":1723065161491,"mc":[{"id":"1.231541189","rc":[{"batb":[[0,3.1,4],[1,3.05,8.34],[2,3,26.09]],"ltp":3.25,"tv":463.46,"id":19587212},{"batl":[[0,1.47,12.14]],"ltp":1.45,"tv":5871.21,"id":19587555}]}]}
{"op":"mcm","clk":"11793190224","pt":1723065162404,"mc":[{"id":"1.231541189","rc":[{"batl":[[0,1.47,4]],"ltp":1.45,"tv":5871.21,"id":19587555}]}]}
{"op":"mcm","clk":"11793190289","pt":1723065164513,"mc":[{"id":"1.231541189","rc":[{"batb":[[0,3.05,8.34],[1,3,26.09],[2,2.98,26.42]],"ltp":3.25,"tv":463.46,"id":19587212}]}]}
{"op":"mcm","clk":"11793190308","pt":1723065165025,"mc":[{"id":"1.231541189","rc":[{"batl":[[0,1.48,9.47],[1,1.49,38.03],[2,1.5,25.52]],"ltp":1.45,"tv":5871.21,"id":19587555}]}]}
{"op":"mcm","clk":"11793190393","pt":1723065167390,"mc":[{"id":"1.231541189","rc":[{"batb":[[0,3.1,4],[1,3.05,8.34],[2,3,26.09]],"ltp":3.25,"tv":463.46,"id":19587212}]}]}
{"op":"mcm","clk":"11793190470","pt":1723065169593,"mc":[{"id":"1.231541189","rc":[{"batb":[[0,3.05,8.34],[1,3,26.09],[2,2.98,26.42]],"ltp":3.25,"tv":463.46,"id":19587212}]}]}
{"op":"mcm","clk":"11793190565","pt":1723065172006,"mc":[{"id":"1.231541189","rc":[{"batb":[[0,3.1,4],[1,3.05,8.34],[2,3,26.09]],"ltp":3.25,"tv":463.46,"id":19587212}]}]}
{"op":"mcm","clk":"11793190656","pt":1723065174517,"mc":[{"id":"1.231541189","rc":[{"batb":[[0,3.05,8.34],[1,3,26.09],[2,2.98,26.42]],"ltp":3.25,"tv":463.46,"id":19587212}]}]}
{"op":"mcm","clk":"11793190769","pt":1723065177742,"mc":[{"id":"1.231541189","rc":[{"batb":[[0,3.1,4],[1,3.05,8.34],[2,3,26.09]],"ltp":3.25,"tv":463.46,"id":19587212}]}]}
{"op":"mcm","clk":"11793190880","pt":1723065180518,"mc":[{"id":"1.231541189","rc":[{"batb":[[0,3.05,8.34],[1,3,26.09],[2,2.98,26.42]],"ltp":3.25,"tv":463.46,"id":19587212}]}]}
{"op":"mcm","clk":"11793190997","pt":1723065183438,"mc":[{"id":"1.231541189","rc":[{"batb":[[0,3.1,4],[1,3.05,8.34],[2,3,26.09]],"ltp":3.25,"tv":463.46,"id":19587212}]}]}
{"op":"mcm","clk":"11793191072","pt":1723065185855,"mc":[{"id":"1.231541189","rc":[{"batb":[[0,3.05,8.34],[1,3,26.09],[2,2.98,26.42]],"ltp":3.25,"tv":463.46,"id":19587212}]}]}
{"op":"mcm","clk":"11793191204","pt":1723065189436,"mc":[{"id":"1.231541189","rc":[{"batb":[[0,3.1,4],[1,3.05,8.34],[2,3,26.09]],"ltp":3.25,"tv":463.46,"id":19587212}]}]}
{"op":"mcm","clk":"11793191300","pt":1723065191845,"mc":[{"id":"1.231541189","rc":[{"batl":[[0,1.47,4],[1,1.48,9.47],[2,1.49,38.03]],"ltp":1.45,"tv":5871.21,"id":19587555}]}]}
{"op":"mcm","clk":"11793191376","pt":1723065193441,"mc":[{"id":"1.231541189","rc":[{"batb":[[1,3.05,30.42],[2,3,4]],"ltp":3.25,"tv":463.46,"id":19587212}]}]}
{"op":"mcm","clk":"11793191405","pt":1723065194158,"mc":[{"id":"1.231541189","rc":[{"batb":[[0,3.15,4],[1,3.1,4],[2,3.05,30.42]],"ltp":3.25,"tv":463.46,"id":19587212}]}]}
{"op":"mcm","clk":"11793191436","pt":1723065195135,"mc":[{"id":"1.231541189","rc":[{"batb":[[2,3.05,26.09]],"ltp":3.25,"tv":463.46,"id":19587212}]}]}
{"op":"mcm","clk":"11793191481","pt":1723065196675,"mc":[{"id":"1.231541189","rc":[{"batb":[[0,3.1,4],[1,3.05,26.09],[2,3,4]],"ltp":3.25,"tv":463.46,"id":19587212}]}]}
{"op":"mcm","clk":"11793191536","pt":1723065198879,"mc":[{"id":"1.231541189","rc":[{"batb":[[0,3.15,4],[1,3.1,4],[2,3.05,26.09]],"ltp":3.25,"tv":463.46,"id":19587212}]}]}
{"op":"mcm","clk":"11793191604","pt":1723065201239,"mc":[{"id":"1.231541189","rc":[{"batb":[[0,3.1,4],[1,3.05,26.09],[2,3,4]],"ltp":3.25,"tv":463.46,"id":19587212}]}]}
{"op":"mcm","clk":"11793191724","pt":1723065204586,"mc":[{"id":"1.231541189","rc":[{"batb":[[0,3.15,4],[1,3.1,4],[2,3.05,26.09]],"ltp":3.25,"tv":463.46,"id":19587212}]}]}
{"op":"mcm","clk":"11793191833","pt":1723065207981,"mc":[{"id":"1.231541189","rc":[{"batb":[[0,3.1,4],[1,3.05,26.09],[2,3,4]],"ltp":3.25,"tv":463.46,"id":19587212}]}]}
{"op":"mcm","clk":"11793191905","pt":1723065210294,"mc":[{"id":"1.231541189","rc":[{"batb":[[0,3.15,4],[1,3.1,4],[2,3.05,26.09]],"ltp":3.25,"tv":463.46,"id":19587212}]}]}
{"op":"mcm","clk":"11793191929","pt":1723065210861,"mc":[{"id":"1.231541189","rc":[{"batl":[[0,1.47,12.14]],"ltp":1.45,"tv":5871.21,"id":19587555}]}]}
{"op":"mcm","clk":"11793191982","pt":1723065212449,"mc":[{"id":"1.231541189","rc":[{"batl":[[0,1.46,5.55],[1,1.47,12.14],[2,1.48,4]],"ltp":1.45,"tv":5871.21,"id":19587555}]}]}
{"op":"mcm","clk":"11793192003","pt":1723065212963,"mc":[{"id":"1.231541189","rc":[{"batb":[[0,3.1,4],[1,3.05,26.09],[2,3,4]],"ltp":3.25,"tv":463.46,"id":19587212},{"batl":[[1,1.47,8.14],[2,1.49,34.03]],"ltp":1.45,"tv":5871.21,"id":19587555}]}]}
{"op":"mcm","clk":"11793192063","pt":1723065214551,"mc":[{"id":"1.231541189","rc":[{"batl":[[0,1.47,8.14],[1,1.48,5.47]],"ltp":1.45,"tv":5871.21,"id":19587555}]}]}
{"op":"mcm","clk":"11793192154","pt":1723065217676,"mc":[{"id":"1.231541189","rc":[{"batb":[[0,3.15,4],[1,3.1,4],[2,3.05,26.09]],"ltp":3.25,"tv":463.46,"id":19587212}]}]}
{"op":"mcm","clk":"11793192234","pt":1723065220088,"mc":[{"id":"1.231541189","rc":[{"batb":[[0,3.1,4],[1,3.05,26.09],[2,3,4]],"ltp":3.25,"tv":463.46,"id":19587212}]}]}
{"op":"mcm","clk":"11793192284","pt":1723065221984,"mc":[{"id":"1.231541189","rc":[{"batl":[[0,1.47,12.14]],"ltp":1.45,"tv":5871.21,"id":19587555}]}]}
{"op":"mcm","clk":"11793192312","pt":1723065223167,"mc":[{"id":"1.231541189","rc":[{"batb":[[0,3.15,4],[1,3.1,4],[2,3.05,26.09]],"ltp":3.25,"tv":463.46,"id":19587212}]}]}
{"op":"mcm","clk":"11793192345","pt":1723065224193,"mc":[{"id":"1.231541189","rc":[{"batl":[[1,1.49,34.03],[2,1.5,21.52]],"ltp":1.45,"tv":5871.21,"id":19587555}]}]}
{"op":"mcm","clk":"11793192380","pt":1723065225478,"mc":[{"id":"1.231541189","rc":[{"batb":[[0,3.1,4],[1,3.05,26.09],[2,3,4]],"ltp":3.25,"tv":463.46,"id":19587212}]}]}
{"op":"mcm","clk":"11793192393","pt":1723065226089,"mc":[{"id":"1.231541189","rc":[{"batl":[[0,1.49,34.03],[1,1.5,21.52],[2,1.78,45]],"ltp":1.45,"tv":5871.21,"id":19587555}]}]}
{"op":"mcm","clk":"11793192457","pt":1723065228301,"mc":[{"id":"1.231541189","rc":[{"batb":[[0,3.15,4],[1,3.1,4],[2,3.05,26.09]],"ltp":3.25,"tv":463.46,"id":19587212}]}]}
{"op":"mcm","clk":"11793192517","pt":1723065230609,"mc":[{"id":"1.231541189","rc":[{"batb":[[0,3.1,4],[1,3.05,26.09],[2,3,4]],"ltp":3.25,"tv":463.46,"id":19587212}]}]}
{"op":"mcm","clk":"11793192605","pt":1723065233279,"mc":[{"id":"1.231541189","rc":[{"batb":[[0,3.15,4],[1,3.1,4],[2,3.05,26.09]],"ltp":3.25,"tv":463.46,"id":19587212}]}]}
{"op":"mcm","clk":"11793192677","pt":1723065235484,"mc":[{"id":"1.231541189","rc":[{"batb":[[0,3.1,4],[1,3.05,26.09],[2,3,4]],"ltp":3.25,"tv":463.46,"id":19587212}]}]}
{"op":"mcm","clk":"11793192723","pt":1723065237224,"mc":[{"id":"1.231541189","rc":[{"batl":[[0,1.48,4],[1,1.49,34.03],[2,1.5,21.52]],"ltp":1.45,"tv":5871.21,"id":19587555}]}]}
{"op":"mcm","clk":"11793192758","pt":1723065238301,"mc":[{"id":"1.231541189","rc":[{"batb":[[0,3.15,4],[1,3.1,4],[2,3.05,26.09]],"ltp":3.25,"tv":463.46,"id":19587212}]}]}
{"op":"mcm","clk":"11793192809","pt":1723065239631,"mc":[{"id":"1.231541189","rc":[{"batl":[[0,1.47,5.52],[1,1.48,4],[2,1.49,34.03]],"ltp":1.45,"tv":5871.21,"id":19587555}]}]}
{"op":"mcm","clk":"11793192843","pt":1723065240707,"mc":[{"id":"1.231541189","rc":[{"batb":[[0,3.1,4],[1,3.05,26.09],[2,3,4]],"ltp":3.25,"tv":463.46,"id":19587212}]}]}
{"op":"mcm","clk":"11793192903","pt":1723065243017,"mc":[{"id":"1.231541189","rc":[{"batb":[[0,3.15,4],[1,3.1,4],[2,3.05,26.09]],"ltp":3.25,"tv":463.46,"id":19587212}]}]}
{"op":"mcm","clk":"11793192974","pt":1723065245323,"mc":[{"id":"1.231541189","rc":[{"batb":[[0,3.1,4],[1,3.05,26.09],[2,3,4]],"ltp":3.25,"tv":463.46,"id":19587212}]}]}
{"op":"mcm","clk":"11793193022","pt":1723065247426,"mc":[{"id":"1.231541189","rc":[{"batb":[[0,3.15,4],[1,3.1,4],[2,3.05,26.09]],"ltp":3.25,"tv":463.46,"id":19587212}]}]}
{"op":"mcm","clk":"11793193076","pt":1723065249831,"mc":[{"id":"1.231541189","rc":[{"batb":[[0,3.1,4],[1,3.05,26.09],[2,3,4]],"ltp":3.25,"tv":463.46,"id":19587212}]}]}
{"op":"mcm","clk":"11793193158","pt":1723065252340,"mc":[{"id":"1.231541189","rc":[{"batb":[[0,3.15,4],[1,3.1,4],[2,3.05,26.09]],"ltp":3.25,"tv":463.46,"id":19587212},{"batl":[[0,1.47,9.52]],"ltp":1.45,"tv":5871.21,"id":19587555}]}]}
{"op":"mcm","clk":"11793193240","pt":1723065254546,"mc":[{"id":"1.231541189","rc":[{"batb":[[0,3.1,4],[1,3.05,26.09],[2,3,4]],"ltp":3.25,"tv":463.46,"id":19587212},{"batl":[[0,1.46,8.19],[1,1.47,9.52],[2,1.48,4]],"ltp":1.45,"tv":5871.21,"id":19587555}]}]}
{"op":"mcm","clk":"11793193272","pt":1723065255522,"mc":[{"id":"1.231541189","rc":[{"batb":[[0,1.44,104.93],[1,1.36,121.53],[2,1.25,200]],"batl":[[1,1.49,34.03],[2,1.5,21.52]],"ltp":1.45,"tv":5871.21,"id":19587555}]}]}
{"op":"mcm","clk":"11793193305","pt":1723065256542,"mc":[{"id":"1.231541189","rc":[{"batl":[[0,1.49,34.03],[1,1.5,21.52],[2,1.78,45]],"ltp":1.45,"tv":5871.21,"id":19587555}]}]}
{"op":"mcm","clk":"11793193311","pt":1723065256849,"mc":[{"id":"1.231541189","rc":[{"batb":[[0,3.15,4],[1,3.1,4],[2,3.05,26.09]],"ltp":3.25,"tv":463.46,"id":19587212}]}]}
{"op":"mcm","clk":"11793193362","pt":1723065259261,"mc":[{"id":"1.231541189","rc":[{"batb":[[0,3.1,4],[1,3.05,26.09],[2,3,4]],"ltp":3.25,"tv":463.46,"id":19587212},{"batl":[[0,1.48,5.96],[1,1.49,34.03],[2,1.5,21.52]],"ltp":1.45,"tv":5871.21,"id":19587555}]}]}
{"op":"mcm","clk":"11793193494","pt":1723065263625,"mc":[{"id":"1.231541189","rc":[{"batb":[[0,3.15,4],[1,3.1,4],[2,3.05,26.09]],"ltp":3.25,"tv":463.46,"id":19587212}]}]}
{"op":"mcm","clk":"11793193580","pt":1723065266133,"mc":[{"id":"1.231541189","rc":[{"batb":[[0,3.1,4],[1,3.05,26.09],[2,3,4]],"ltp":3.25,"tv":463.46,"id":19587212}]}]}
{"op":"mcm","clk":"11793193618","pt":1723065267366,"mc":[{"id":"1.231541189","rc":[{"batl":[[0,1.48,9.96]],"ltp":1.45,"tv":5871.21,"id":19587555}]}]}
{"op":"mcm","clk":"11793193656","pt":1723065268341,"mc":[{"id":"1.231541189","rc":[{"batb":[[0,3.15,4],[1,3.1,4],[2,3.05,26.09]],"ltp":3.25,"tv":463.46,"id":19587212}]}]}
{"op":"mcm","clk":"11793193730","pt":1723065270441,"mc":[{"id":"1.231541189","rc":[{"batb":[[1,2.98,22.42],[2,1.93,53.76]],"ltp":3.25,"tv":463.46,"id":19587212},{"batl":[[0,1.48,5.96]],"ltp":1.45,"tv":5871.21,"id":19587555}]}]}
{"op":"mcm","clk":"11793193753","pt":1723065271157,"mc":[{"id":"1.231541189","rc":[{"batb":[[0,3,10]],"ltp":3.25,"tv":463.46,"id":19587212}]}]}
{"op":"mcm","clk":"11793193824","pt":1723065273360,"mc":[{"id":"1.231541189","rc":[{"batb":[[0,3.05,4],[1,3,10],[2,2.98,22.42]],"ltp":3.25,"tv":463.46,"id":19587212},{"batl":[[0,1.49,34.03],[1,1.5,21.52],[2,1.78,45]],"ltp":1.45,"tv":5871.21,"id":19587555}]}]}
{"op":"mcm","clk":"11793193853","pt":1723065274691,"mc":[{"id":"1.231541189","rc":[{"batb":[[1,2.98,22.42],[2,1.93,53.76]],"ltp":3.25,"tv":463.46,"id":19587212}]}]}
{"op":"mcm","clk":"11793193897","pt":1723065275766,"mc":[{"id":"1.231541189","rc":[{"batb":[[0,2.98,22.42],[1,1.93,53.76],[2,1.83,60.24]],"ltp":3.25,"tv":463.46,"id":19587212}]}]}
{"op":"mcm","clk":"11793193940","pt":1723065277046,"mc":[{"id":"1.231541189","rc":[{"batb":[[0,3,10],[1,2.98,22.42],[2,1.93,53.76]],"ltp":3.25,"tv":463.46,"id":19587212}]}]}
{"op":"mcm","clk":"11793194006","pt":1723065279151,"mc":[{"id":"1.231541189","rc":[{"batb":[[0,3.05,4],[1,3,10],[2,2.98,22.42]],"ltp":3.25,"tv":463.46,"id":19587212}]}]}
{"op":"mcm","clk":"11793194038","pt":1723065280276,"mc":[{"id":"1.231541189","rc":[{"batb":[[1,2.98,22.42],[2,1.93,53.76]],"ltp":3.25,"tv":463.46,"id":19587212}]}]}
{"op":"mcm","clk":"11793194130","pt":1723065282481,"mc":[{"id":"1.231541189","rc":[{"batb":[[1,3,4],[2,2.98,22.42]],"ltp":3.25,"tv":463.46,"id":19587212}]}]}
{"op":"mcm","clk":"11793194205","pt":1723065283763,"mc":[{"id":"1.231541189","rc":[{"batb":[[0,3.1,4],[1,3.05,4],[2,3,4]],"ltp":3.25,"tv":463.46,"id":19587212}]}]}
{"op":"mcm","clk":"11793194295","pt":1723065286169,"mc":[{"id":"1.231541189","rc":[{"batb":[[0,3.05,4],[1,3,4],[2,2.98,22.42]],"ltp":3.25,"tv":463.46,"id":19587212}]}]}
{"op":"mcm","clk":"11793194444","pt":1723065290576,"mc":[{"id":"1.231541189","rc":[{"batb":[[0,3.1,4],[1,3.05,4],[2,3,4]],"ltp":3.25,"tv":463.46,"id":19587212}]}]}
