{"op":"mcm","clk":"11742909413","pt":1722418986203,"mc":[{"id":"1.231282919","marketDefinition":{"bspMarket":false,"turnInPlayEnabled":true,"persistenceEnabled":true,"marketBaseRate":5.0,"eventId":"33458013","eventTypeId":"4","numberOfWinners":1,"bettingType":"ODDS","marketType":"MATCH_ODDS","marketTime":"2024-08-02T10:00:00.000Z","suspendTime":"2024-08-02T10:00:00.000Z","bspReconciled":false,"complete":true,"inPlay":false,"crossMatching":false,"runnersVoidable":false,"numberOfActiveRunners":2,"betDelay":0,"status":"OPEN","runners":[{"status":"ACTIVE","sortPriority":1,"id":31375,"name":"Derbyshire"},{"status":"ACTIVE","sortPriority":2,"id":31372,"name":"Worcestershire"}],"regulators":["MR_INT"],"countryCode":"GB","discountAllowed":false,"timezone":"GMT","openDate":"2024-08-02T10:00:00.000Z","version":6048567924,"name":"Match Odds","eventName":"Derbyshire v Worcestershire"},"rc":[{"batb":[[0,1.03,200],[1,1.02,200],[2,1.01,220]],"ltp":0.0,"tv":0.0,"id":31372},{"batb":[[0,1.03,200],[1,1.02,200],[2,1.01,220]],"ltp":0.0,"tv":0.0,"id":31375}]}]}
{"op":"mcm","clk":"11742909510","pt":1722418987721,"mc":[{"id":"1.231282919","marketDefinition":{"bspMarket":false,"turnInPlayEnabled":true,"persistenceEnabled":true,"marketBaseRate":5.0,"eventId":"33458013","eventTypeId":"4","numberOfWinners":1,"bettingType":"ODDS","marketType":"MATCH_ODDS","marketTime":"2024-08-02T10:00:00.000Z","suspendTime":"2024-08-02T10:00:00.000Z","bspReconciled":false,"complete":true,"inPlay":false,"crossMatching":false,"runnersVoidable":false,"numberOfActiveRunners":2,"betDelay":0,"status":"OPEN","runners":[{"status":"ACTIVE","sortPriority":1,"id":31375,"name":"Derbyshire"},{"status":"ACTIVE","sortPriority":2,"id":31372,"name":"Worcestershire"}],"regulators":["MR_INT"],"countryCode":"GB","discountAllowed":true,"timezone":"GMT","openDate":"2024-08-02T10:00:00.000Z","version":6048567924,"name":"Match Odds","eventName":"Derbyshire v Worcestershire"}}]}
{"op":"mcm","clk":"11743157276","pt":1722422924037,"mc":[{"id":"1.231282919","rc":[{"batl":[[0,1.58,100]],"ltp":0.0,"tv":0.0,"id":31372}]}]}
{"op":"mcm","clk":"11743157716","pt":1722422931654,"mc":[{"id":"1.231282919","rc":[{"batl":[[0,1.89,100]],"ltp":0.0,"tv":0.0,"id":31372}]}]}
{"op":"mcm","clk":"11743157774","pt":1722422932572,"mc":[{"id":"1.231282919","rc":[{"batl":[[0,1.79,100],[1,1.82,100],[2,1.84,100]],"ltp":0.0,"tv":0.0,"id":31372}]}]}
{"op":"mcm","clk":"11743189391","pt":1722423629805,"mc":[{"id":"1.231282919","rc":[{"batb":[[0,2.28,6.23],[1,1.03,200],[2,1.02,200]],"ltp":0.0,"tv":0.0,"id":31375}]}]}
{"op":"mcm","clk":"11743189755","pt":1722423636948,"mc":[{"id":"1.231282919","marketDefinition":{"bspMarket":false,"turnInPlayEnabled":true,"persistenceEnabled":true,"marketBaseRate":5.0,"eventId":"33458013","eventTypeId":"4","numberOfWinners":1,"bettingType":"ODDS","marketType":"MATCH_ODDS","marketTime":"2024-08-02T10:00:00.000Z","suspendTime":"2024-08-02T10:00:00.000Z","bspReconciled":false,"complete":true,"inPlay":false,"crossMatching":true,"runnersVoidable":false,"numberOfActiveRunners":2,"betDelay":0,"status":"OPEN","runners":[{"status":"ACTIVE","sortPriority":1,"id":31375,"name":"Derbyshire"},{"status":"ACTIVE","sortPriority":2,"id":31372,"name":"Worcestershire"}],"regulators":["MR_INT"],"countryCode":"GB","discountAllowed":true,"timezone":"GMT","openDate":"2024-08-02T10:00:00.000Z","version":6048567924,"name":"Match Odds","eventName":"Derbyshire v Worcestershire"}}]}
{"op":"mcm","clk":"11743221239","pt":1722424257396,"mc":[{"id":"1.231282919","rc":[{"trd":[[1.79,8]],"batl":[[0,1.79,96]],"ltp":1.79,"tv":8.0,"id":31372}],"tv":8.0}]}
{"op":"mcm","clk":"11743221450","pt":1722424262303,"mc":[{"id":"1.231282919","rc":[{"batl":[[0,1.78,5.1],[1,1.79,96],[2,1.82,100]],"ltp":1.79,"tv":8.0,"id":31372}]}]}
{"op":"mcm","clk":"11743361608","pt":1722426652114,"mc":[{"id":"1.231282919","rc":[{"trd":[[2.28,2.18]],"batb":[[0,2.28,5.14]],"ltp":2.28,"tv":2.18,"id":31375}],"tv":10.18}]}
{"op":"mcm","clk":"11743368089","pt":1722426789987,"mc":[{"id":"1.231282919","rc":[{"trd":[[2.28,9.64]],"batb":[[0,2.28,1.41]],"ltp":2.28,"tv":9.64,"id":31375}],"tv":17.64}]}
{"op":"mcm","clk":"11743428433","pt":1722427911504,"mc":[{"id":"1.231282919","rc":[{"batl":[[0,1.78,5.1]],"ltp":1.79,"tv":8.0,"id":31372},{"batb":[[0,1.03,200],[1,1.02,200],[2,1.01,220]],"ltp":2.28,"tv":9.64,"id":31375}]}]}
{"op":"mcm","clk":"11743538924","pt":1722429911548,"mc":[{"id":"1.231282919","rc":[{"batb":[[0,1.26,400],[1,1.03,200],[2,1.02,200]],"ltp":1.79,"tv":8.0,"id":31372}]}]}
{"op":"mcm","clk":"11743540472","pt":1722429942311,"mc":[{"id":"1.231282919","rc":[{"batb":[[0,1.03,200],[1,1.02,200],[2,1.01,220]],"ltp":1.79,"tv":8.0,"id":31372}]}]}
{"op":"mcm","clk":"11743630261","pt":1722431574798,"mc":[{"id":"1.231282919","rc":[{"batl":[[0,1.78,5.11]],"ltp":1.79,"tv":8.0,"id":31372},{"trd":[[2.28,9.64]],"ltp":2.28,"tv":9.63,"id":31375}],"tv":17.63}]}
{"op":"mcm","clk":"11743974702","pt":1722436974798,"mc":[{"id":"1.231282919","rc":[{"batl":[[0,1.78,5.11]],"ltp":1.79,"tv":8.0,"id":31372},{"trd":[[2.28,9.64]],"ltp":2.28,"tv":9.64,"id":31375}],"tv":17.64}]}
{"op":"mcm","clk":"11744150600","pt":1722438862304,"mc":[{"id":"1.231282919","rc":[{"trd":[[1.78,5.1]],"batl":[[0,1.79,96],[1,1.82,100],[2,1.84,100]],"ltp":1.78,"tv":13.09,"id":31372},{"trd":[[2.28,13.62]],"batl":[[0,2.28,8.02]],"ltp":2.28,"tv":13.62,"id":31375}],"tv":26.71}]}
{"op":"mcm","clk":"11744150776","pt":1722438864488,"mc":[{"id":"1.231282919","rc":[{"batb":[[0,1.04,8.73],[1,1.03,200],[2,1.02,200]],"ltp":1.78,"tv":13.09,"id":31372}]}]}
{"op":"mcm","clk":"11744204786","pt":1722439401236,"mc":[{"id":"1.231282919","rc":[{"trd":[[1.79,18.13]],"batl":[[0,1.79,85.87]],"ltp":1.79,"tv":23.22,"id":31372},{"trd":[[2.26,8.02]],"ltp":2.26,"tv":21.64,"id":31375}],"tv":44.86}]}
{"op":"mcm","clk":"11744458515","pt":1722441871863,"mc":[{"id":"1.231282919","rc":[{"trd":[[1.78,5.1]],"batb":[[0,1.35,5.64],[1,1.04,8.73],[2,1.03,200]],"ltp":1.79,"tv":23.22,"id":31372},{"trd":[[2.28,13.62]],"ltp":2.26,"tv":21.64,"id":31375}],"tv":44.87}]}
{"op":"mcm","clk":"11744934660","pt":1722446037613,"mc":[{"id":"1.231282919","rc":[{"trd":[[1.78,5.09]],"batb":[[0,1.35,5.64],[1,1.23,217.39],[2,1.18,277.78]],"ltp":1.79,"tv":23.22,"id":31372},{"trd":[[2.28,13.62]],"batb":[[0,1.23,217.39],[1,1.18,277.78],[2,1.13,384.62]],"ltp":2.26,"tv":21.64,"id":31375}],"tv":44.86}]}
{"op":"mcm","clk":"11744934723","pt":1722446038034,"mc":[{"id":"1.231282919","rc":[{"batb":[[0,1.43,116.28],[1,1.38,131.58],[2,1.35,5.64]],"ltp":1.79,"tv":23.22,"id":31372},{"batb":[[0,1.43,116.28],[1,1.38,131.58],[2,1.33,151.52]],"ltp":2.26,"tv":21.64,"id":31375}]}]}
{"op":"mcm","clk":"11744934888","pt":1722446039035,"mc":[{"id":"1.231282919","rc":[{"batb":[[0,1.44,6.3],[1,1.43,116.28],[2,1.38,131.58]],"ltp":1.79,"tv":23.22,"id":31372}]}]}
{"op":"mcm","clk":"11745053116","pt":1722446760457,"mc":[{"id":"1.231282919","rc":[{"batb":[[0,1.44,12.32]],"ltp":1.79,"tv":23.22,"id":31372}]}]}
{"op":"mcm","clk":"11745221375","pt":1722447674685,"mc":[{"id":"1.231282919","rc":[{"batb":[[0,1.45,7.58],[1,1.44,12.32],[2,1.43,116.28]],"ltp":1.79,"tv":23.22,"id":31372}]}]}
{"op":"mcm","clk":"11745352060","pt":1722448354038,"mc":[{"id":"1.231282919","rc":[{"batb":[[0,1.6,900],[1,1.45,7.58],[2,1.44,12.32]],"ltp":1.79,"tv":23.22,"id":31372}]}]}
{"op":"mcm","clk":"11745352428","pt":1722448356114,"mc":[{"id":"1.231282919","rc":[{"batb":[[0,1.61,5.63],[1,1.6,900],[2,1.45,7.58]],"ltp":1.79,"tv":23.22,"id":31372}]}]}
{"op":"mcm","clk":"11745353041","pt":1722448359930,"mc":[{"id":"1.231282919","rc":[{"batb":[[0,1.68,900],[1,1.61,5.63]],"ltp":1.79,"tv":23.22,"id":31372}]}]}
{"op":"mcm","clk":"11745353253","pt":1722448361318,"mc":[{"id":"1.231282919","rc":[{"batb":[[1,1.45,7.58],[2,1.43,116.28]],"ltp":1.79,"tv":23.22,"id":31372}]}]}
{"op":"mcm","clk":"11745354167","pt":1722448367437,"mc":[{"id":"1.231282919","rc":[{"batb":[[0,1.45,7.58],[1,1.43,116.28],[2,1.38,131.58]],"ltp":1.79,"tv":23.22,"id":31372}]}]}
{"op":"mcm","clk":"11745354317","pt":1722448368437,"mc":[{"id":"1.231282919","rc":[{"batb":[[1,1.44,6.3],[2,1.43,116.28]],"ltp":1.79,"tv":23.22,"id":31372}]}]}
{"op":"mcm","clk":"11745359118","pt":1722448400117,"mc":[{"id":"1.231282919","rc":[{"trd":[[1.79,41.87]],"batl":[[0,1.79,74]],"ltp":1.79,"tv":46.96,"id":31372}],"tv":68.6}]}
{"op":"mcm","clk":"11745363225","pt":1722448424847,"mc":[{"id":"1.231282919","rc":[{"batb":[[0,1.92,40.17],[1,1.43,116.28],[2,1.38,131.58]],"ltp":2.26,"tv":21.64,"id":31375}]}]}
{"op":"mcm","clk":"11745365414","pt":1722448436171,"mc":[{"id":"1.231282919","rc":[{"trd":[[1.79,48.61]],"batl":[[0,1.79,70.63]],"ltp":1.79,"tv":53.7,"id":31372}],"tv":75.34}]}
{"op":"mcm","clk":"11745367317","pt":1722448446962,"mc":[{"id":"1.231282919","rc":[{"trd":[[1.79,53.66]],"batl":[[0,1.79,68.1]],"ltp":1.79,"tv":58.75,"id":31372}],"tv":80.4}]}
{"op":"mcm","clk":"11745367563","pt":1722448448478,"mc":[{"id":"1.231282919","rc":[{"trd":[[1.79,172.91]],"batl":[[0,1.79,8.48]],"ltp":1.79,"tv":178.0,"id":31372}],"tv":199.64}]}
{"op":"mcm","clk":"11745370810","pt":1722448467279,"mc":[{"id":"1.231282919","rc":[{"trd":[[1.79,174.59]],"batl":[[0,1.79,7.64]],"ltp":1.79,"tv":179.68,"id":31372}],"tv":201.32}]}
{"op":"mcm","clk":"11745377802","pt":1722448509550,"mc":[{"id":"1.231282919","rc":[{"trd":[[1.79,183.99]],"batl":[[0,1.79,2.94]],"ltp":1.79,"tv":189.08,"id":31372}],"tv":210.72}]}
{"op":"mcm","clk":"11745378105","pt":1722448511351,"mc":[{"id":"1.231282919","rc":[{"trd":[[1.79,189.87]],"batb":[[0,1.79,1.12],[1,1.45,7.58],[2,1.44,6.3]],"batl":[[0,1.82,100],[1,1.84,100],[2,1.85,100]],"ltp":1.79,"tv":194.96,"id":31372}],"tv":216.6}]}
{"op":"mcm","clk":"11745378969","pt":1722448516560,"mc":[{"id":"1.231282919","rc":[{"trd":[[1.82,2.24]],"batb":[[0,1.45,7.58],[1,1.44,6.3],[2,1.43,116.28]],"batl":[[0,1.82,98.88]],"ltp":1.82,"tv":197.2,"id":31372}],"tv":218.84}]}
{"op":"mcm","clk":"11745381406","pt":1722448530358,"mc":[{"id":"1.231282919","rc":[{"trd":[[1.82,3.93]],"batl":[[0,1.82,98.04]],"ltp":1.82,"tv":198.88,"id":31372}],"tv":220.53}]}
{"op":"mcm","clk":"11745386758","pt":1722448561697,"mc":[{"id":"1.231282919","rc":[{"batb":[[0,1.79,11.87],[1,1.45,7.58],[2,1.44,6.3]],"ltp":1.82,"tv":198.88,"id":31372}]}]}
{"op":"mcm","clk":"11745390471","pt":1722448583228,"mc":[{"id":"1.231282919","rc":[{"trd":[[1.82,63.21]],"batl":[[0,1.82,68.4]],"ltp":1.82,"tv":258.17,"id":31372}],"tv":279.81}]}
{"op":"mcm","clk":"11745391509","pt":1722448588801,"mc":[{"id":"1.231282919","rc":[{"trd":[[1.82,83.05]],"batl":[[0,1.82,58.48]],"ltp":1.82,"tv":278.01,"id":31372}],"tv":299.65}]}
{"op":"mcm","clk":"11745409928","pt":1722448693397,"mc":[{"id":"1.231282919","rc":[{"trd":[[1.82,116.99]],"batl":[[0,1.82,41.51]],"ltp":1.82,"tv":311.95,"id":31372}],"tv":333.59}]}
{"op":"mcm","clk":"11745417150","pt":1722448734164,"mc":[{"id":"1.231282919","rc":[{"trd":[[1.82,138.41]],"batl":[[0,1.82,30.8]],"ltp":1.82,"tv":333.37,"id":31372}],"tv":355.01}]}
{"op":"mcm","clk":"11745447426","pt":1722448890437,"mc":[{"id":"1.231282919","rc":[{"trd":[[1.78,5.1],[1.79,189.85],[1.82,139.8]],"batb":[[2,1.44,6.3]],"batl":[[0,1.82,30.11]],"ltp":1.82,"tv":334.75,"id":31372}],"tv":356.39}]}
{"op":"mcm","clk":"11745511892","pt":1722449186436,"mc":[{"id":"1.231282919","rc":[{"batb":[[0,1.43,116.28],[1,1.38,131.58],[2,1.33,151.52]],"ltp":2.26,"tv":21.64,"id":31375}]}]}
{"op":"mcm","clk":"11745512324","pt":1722449187934,"mc":[{"id":"1.231282919","rc":[{"batb":[[0,1.92,40.17],[1,1.43,116.28],[2,1.38,131.58]],"ltp":2.26,"tv":21.64,"id":31375}]}]}
{"op":"mcm","clk":"11745598981","pt":1722449567531,"mc":[{"id":"1.231282919","rc":[{"trd":[[1.82,169.91],[1.84,100],[1.85,100]],"batl":[[0,1.87,100],[1,1.89,100],[2,1.85,0]],"ltp":1.85,"tv":564.86,"id":31372},{"trd":[[2.16,85.65],[2.18,84.4],[2.2,24.91]],"batl":[[0,2.16,5.04]],"ltp":2.16,"tv":216.6,"id":31375}],"tv":781.46}]}
{"op":"mcm","clk":"11745599204","pt":1722449568547,"mc":[{"id":"1.231282919","rc":[{"batb":[[1,1.78,5.1],[2,1.45,7.58]],"ltp":1.85,"tv":564.86,"id":31372},{"batb":[[0,1.93,10],[1,1.92,40.17],[2,1.43,116.28]],"ltp":2.16,"tv":216.6,"id":31375}]}]}
{"op":"mcm","clk":"11745599735","pt":1722449571030,"mc":[{"id":"1.231282919","rc":[{"batb":[[0,1.92,40.17],[1,1.43,116.28],[2,1.38,131.58]],"ltp":2.16,"tv":216.6,"id":31375}]}]}
{"op":"mcm","clk":"11745609886","pt":1722449614416,"mc":[{"id":"1.231282919","rc":[{"trd":[[1.87,200]],"batb":[[0,1.88,80],[1,1.79,11.87],[2,1.78,5.1]],"batl":[[0,1.89,100],[1,1.89,0]],"ltp":1.87,"tv":764.86,"id":31372},{"batb":[[0,1.93,10],[1,1.92,40.17],[2,1.43,116.28]],"batl":[[0,2.14,87],[1,2.16,5.04]],"ltp":2.16,"tv":216.6,"id":31375}],"tv":981.46}]}
{"op":"mcm","clk":"11745610638","pt":1722449617844,"mc":[{"id":"1.231282919","rc":[{"batb":[[0,1.92,40.17],[1,1.43,116.28],[2,1.38,131.58]],"ltp":2.16,"tv":216.6,"id":31375}]}]}
{"op":"mcm","clk":"11745613611","pt":1722449630338,"mc":[{"id":"1.231282919","rc":[{"trd":[[1.89,180]],"batl":[[0,1.89,10]],"ltp":1.89,"tv":944.86,"id":31372},{"batb":[[0,1.93,10],[1,1.92,40.17],[2,1.43,116.28]],"ltp":2.16,"tv":216.6,"id":31375}],"tv":1161.46}]}
{"op":"mcm","clk":"11745614386","pt":1722449633661,"mc":[{"id":"1.231282919","rc":[{"batb":[[0,1.92,40.17],[1,1.43,116.28],[2,1.38,131.58]],"ltp":2.16,"tv":216.6,"id":31375}]}]}
{"op":"mcm","clk":"11745615305","pt":1722449637350,"mc":[{"id":"1.231282919","rc":[{"batb":[[0,1.79,11.87],[1,1.78,5.1],[2,1.45,7.58]],"ltp":1.89,"tv":944.86,"id":31372},{"batb":[[0,1.93,10],[1,1.92,40.17],[2,1.43,116.28]],"ltp":2.16,"tv":216.6,"id":31375}]}]}
{"op":"mcm","clk":"11745616072","pt":1722449640596,"mc":[{"id":"1.231282919","rc":[{"batb":[[0,1.92,40.17],[1,1.43,116.28],[2,1.38,131.58]],"ltp":2.16,"tv":216.6,"id":31375}]}]}
{"op":"mcm","clk":"11745622737","pt":1722449669110,"mc":[{"id":"1.231282919","rc":[{"batb":[[2,1.43,116.28]],"ltp":1.89,"tv":944.86,"id":31372},{"batb":[[0,1.93,10],[1,1.92,40.17],[2,1.43,116.28]],"ltp":2.16,"tv":216.6,"id":31375}]}]}
{"op":"mcm","clk":"11745623514","pt":1722449672492,"mc":[{"id":"1.231282919","rc":[{"batb":[[0,1.92,40.17],[1,1.43,116.28],[2,1.38,131.58]],"ltp":2.16,"tv":216.6,"id":31375}]}]}
{"op":"mcm","clk":"11745637901","pt":1722449737239,"mc":[{"id":"1.231282919","rc":[{"batb":[[0,1.93,10],[1,1.92,40.17],[2,1.43,116.28]],"ltp":2.16,"tv":216.6,"id":31375}]}]}
{"op":"mcm","clk":"11745638733","pt":1722449740690,"mc":[{"id":"1.231282919","rc":[{"batb":[[0,1.92,40.17],[1,1.43,116.28],[2,1.38,131.58]],"ltp":2.16,"tv":216.6,"id":31375}]}]}
{"op":"mcm","clk":"11745656976","pt":1722449824904,"mc":[{"id":"1.231282919","rc":[{"batb":[[0,1.93,10],[1,1.92,40.17],[2,1.43,116.28]],"ltp":2.16,"tv":216.6,"id":31375}]}]}
{"op":"mcm","clk":"11745658013","pt":1722449829641,"mc":[{"id":"1.231282919","rc":[{"batb":[[0,1.92,40.17],[1,1.43,116.28],[2,1.38,131.58]],"ltp":2.16,"tv":216.6,"id":31375}]}]}
{"op":"mcm","clk":"11745668058","pt":1722449879620,"mc":[{"id":"1.231282919","rc":[{"batb":[[1,1.43,116.28],[2,1.38,131.58]],"ltp":1.89,"tv":944.86,"id":31372}]}]}
{"op":"mcm","clk":"11745668130","pt":1722449879947,"mc":[{"id":"1.231282919","rc":[{"batb":[[0,1.88,9.72],[1,1.79,11.87],[2,1.43,116.28]],"ltp":1.89,"tv":944.86,"id":31372},{"batb":[[0,1.93,10],[1,1.92,40.17],[2,1.43,116.28]],"ltp":2.16,"tv":216.6,"id":31375}]}]}
{"op":"mcm","clk":"11745668818","pt":1722449883263,"mc":[{"id":"1.231282919","rc":[{"batb":[[0,1.92,40.17],[1,1.43,116.28],[2,1.38,131.58]],"ltp":2.16,"tv":216.6,"id":31375}]}]}
{"op":"mcm","clk":"11745701682","pt":1722450037053,"mc":[{"id":"1.231282919","rc":[{"trd":[[1.89,200]],"batb":[[0,1.89,25],[1,1.88,9.72],[2,1.79,11.87]],"ltp":1.89,"tv":964.86,"id":31372},{"batb":[[0,1.93,10],[1,1.92,40.17],[2,1.43,116.28]],"ltp":2.16,"tv":216.6,"id":31375}],"tv":1181.46}]}
{"op":"mcm","clk":"11745701928","pt":1722450038225,"mc":[{"id":"1.231282919","rc":[{"batb":[[1,1.79,11.87],[2,1.78,5.1]],"ltp":1.89,"tv":964.86,"id":31372}]}]}
{"op":"mcm","clk":"11745702406","pt":1722450040347,"mc":[{"id":"1.231282919","rc":[{"batb":[[0,1.92,40.17],[1,1.43,116.28],[2,1.38,131.58]],"ltp":2.16,"tv":216.6,"id":31375}]}]}
{"op":"mcm","clk":"11745702612","pt":1722450041240,"mc":[{"id":"1.231282919","rc":[{"batb":[[0,1.99,37.33],[1,1.89,25],[2,1.79,11.87]],"ltp":1.89,"tv":964.86,"id":31372}]}]}
{"op":"mcm","clk":"11745728434","pt":1722450168624,"mc":[{"id":"1.231282919","rc":[{"trd":[[1.99,0.9]],"batb":[[0,1.99,36.88]],"ltp":1.99,"tv":965.76,"id":31372}],"tv":1182.36}]}
{"op":"mcm","clk":"11745728451","pt":1722450168726,"mc":[{"id":"1.231282919","rc":[{"batb":[[0,1.93,10],[1,1.92,40.17],[2,1.43,116.28]],"ltp":2.16,"tv":216.6,"id":31375}]}]}
{"op":"mcm","clk":"11745729151","pt":1722450172061,"mc":[{"id":"1.231282919","rc":[{"batb":[[0,1.99,37.33]],"ltp":1.99,"tv":965.76,"id":31372},{"batb":[[0,1.92,40.17],[1,1.43,116.28],[2,1.38,131.58]],"ltp":2.16,"tv":216.6,"id":31375}]}]}
{"op":"mcm","clk":"11745751364","pt":1722450283460,"mc":[{"id":"1.231282919","rc":[{"batb":[[0,2,4.53],[1,1.99,37.33],[2,1.89,25]],"ltp":1.99,"tv":965.76,"id":31372}]}]}
{"op":"mcm","clk":"11745751428","pt":1722450283765,"mc":[{"id":"1.231282919","rc":[{"batb":[[0,1.93,10],[1,1.92,40.17],[2,1.43,116.28]],"ltp":2.16,"tv":216.6,"id":31375}]}]}
{"op":"mcm","clk":"11745752115","pt":1722450287063,"mc":[{"id":"1.231282919","rc":[{"batb":[[0,1.92,40.17],[1,1.43,116.28],[2,1.38,131.58]],"ltp":2.16,"tv":216.6,"id":31375}]}]}
{"op":"mcm","clk":"11745778728","pt":1722450423558,"mc":[{"id":"1.231282919","rc":[{"batb":[[0,1.93,10],[1,1.92,40.17],[2,1.43,116.28]],"ltp":2.16,"tv":216.6,"id":31375}]}]}
{"op":"mcm","clk":"11745779479","pt":1722450426920,"mc":[{"id":"1.231282919","rc":[{"batb":[[0,1.92,40.17],[1,1.43,116.28],[2,1.38,131.58]],"ltp":2.16,"tv":216.6,"id":31375}]}]}
{"op":"mcm","clk":"11745851942","pt":1722450766732,"mc":[{"id":"1.231282919","rc":[{"batb":[[0,1.93,10],[1,1.92,40.17],[2,1.43,116.28]],"ltp":2.16,"tv":216.6,"id":31375}]}]}
{"op":"mcm","clk":"11745852793","pt":1722450770416,"mc":[{"id":"1.231282919","rc":[{"batb":[[0,1.92,40.17],[1,1.43,116.28],[2,1.38,131.58]],"ltp":2.16,"tv":216.6,"id":31375}]}]}
{"op":"mcm","clk":"11746011523","pt":1722451476181,"mc":[{"id":"1.231282919","rc":[{"batb":[[0,1.93,10],[1,1.92,40.17],[2,1.43,116.28]],"ltp":2.16,"tv":216.6,"id":31375}]}]}
{"op":"mcm","clk":"11746012234","pt":1722451479470,"mc":[{"id":"1.231282919","rc":[{"batb":[[0,1.92,40.17],[1,1.43,116.28],[2,1.38,131.58]],"ltp":2.16,"tv":216.6,"id":31375}]}]}
{"op":"mcm","clk":"11746033210","pt":1722451571989,"mc":[{"id":"1.231282919","rc":[{"batb":[[0,1.93,10],[1,1.92,40.17],[2,1.43,116.28]],"ltp":2.16,"tv":216.6,"id":31375}]}]}
{"op":"mcm","clk":"11746034009","pt":1722451575690,"mc":[{"id":"1.231282919","rc":[{"batb":[[0,1.92,40.17],[1,1.43,116.28],[2,1.38,131.58]],"ltp":2.16,"tv":216.6,"id":31375}]}]}
{"op":"mcm","clk":"11746037487","pt":1722451591224,"mc":[{"id":"1.231282919","rc":[{"batb":[[0,1.93,10],[1,1.92,40.17],[2,1.43,116.28]],"ltp":2.16,"tv":216.6,"id":31375}]}]}
{"op":"mcm","clk":"11746038274","pt":1722451594726,"mc":[{"id":"1.231282919","rc":[{"batb":[[0,1.92,40.17],[1,1.43,116.28],[2,1.38,131.58]],"ltp":2.16,"tv":216.6,"id":31375}]}]}
{"op":"mcm","clk":"11746038863","pt":1722451597444,"mc":[{"id":"1.231282919","rc":[{"batb":[[0,1.93,10],[1,1.92,40.17],[2,1.43,116.28]],"ltp":2.16,"tv":216.6,"id":31375}]}]}
{"op":"mcm","clk":"11746039589","pt":1722451600652,"mc":[{"id":"1.231282919","rc":[{"batb":[[0,1.92,40.17],[1,1.43,116.28],[2,1.38,131.58]],"ltp":2.16,"tv":216.6,"id":31375}]}]}
{"op":"mcm","clk":"11746046293","pt":1722451630885,"mc":[{"id":"1.231282919","rc":[{"batb":[[0,1.93,10],[1,1.92,40.17],[2,1.43,116.28]],"ltp":2.16,"tv":216.6,"id":31375}]}]}
{"op":"mcm","clk":"11746047070","pt":1722451634291,"mc":[{"id":"1.231282919","rc":[{"batb":[[0,1.92,40.17],[1,1.43,116.28],[2,1.38,131.58]],"ltp":2.16,"tv":216.6,"id":31375}]}]}
{"op":"mcm","clk":"11746047855","pt":1722451638104,"mc":[{"id":"1.231282919","rc":[{"batb":[[0,1.93,10],[1,1.92,40.17],[2,1.43,116.28]],"ltp":2.16,"tv":216.6,"id":31375}]}]}
{"op":"mcm","clk":"11746048613","pt":1722451641469,"mc":[{"id":"1.231282919","rc":[{"batb":[[0,1.92,40.17],[1,1.43,116.28],[2,1.38,131.58]],"ltp":2.16,"tv":216.6,"id":31375}]}]}
{"op":"mcm","clk":"11746050406","pt":1722451649984,"mc":[{"id":"1.231282919","rc":[{"batb":[[0,1.93,10],[1,1.92,40.17],[2,1.43,116.28]],"ltp":2.16,"tv":216.6,"id":31375}]}]}
{"op":"mcm","clk":"11746051186","pt":1722451653427,"mc":[{"id":"1.231282919","rc":[{"batb":[[0,1.92,40.17],[1,1.43,116.28],[2,1.38,131.58]],"ltp":2.16,"tv":216.6,"id":31375}]}]}
{"op":"mcm","clk":"11746054768","pt":1722451670126,"mc":[{"id":"1.231282919","rc":[{"batb":[[0,1.93,10],[1,1.92,40.17],[2,1.43,116.28]],"ltp":2.16,"tv":216.6,"id":31375}]}]}
{"op":"mcm","clk":"11746055550","pt":1722451673813,"mc":[{"id":"1.231282919","rc":[{"batb":[[0,1.92,40.17],[1,1.43,116.28],[2,1.38,131.58]],"ltp":2.16,"tv":216.6,"id":31375}]}]}
{"op":"mcm","clk":"11746057181","pt":1722451680953,"mc":[{"id":"1.231282919","rc":[{"batb":[[0,1.93,10],[1,1.92,40.17],[2,1.43,116.28]],"ltp":2.16,"tv":216.6,"id":31375}]}]}
{"op":"mcm","clk":"11746057952","pt":1722451684531,"mc":[{"id":"1.231282919","rc":[{"batb":[[0,1.92,40.17],[1,1.43,116.28],[2,1.38,131.58]],"ltp":2.16,"tv":216.6,"id":31375}]}]}
{"op":"mcm","clk":"11746061383","pt":1722451700065,"mc":[{"id":"1.231282919","rc":[{"batb":[[0,1.93,10],[1,1.92,40.17],[2,1.43,116.28]],"ltp":2.16,"tv":216.6,"id":31375}]}]}
{"op":"mcm","clk":"11746062121","pt":1722451703471,"mc":[{"id":"1.231282919","rc":[{"batb":[[0,1.92,40.17],[1,1.43,116.28],[2,1.38,131.58]],"ltp":2.16,"tv":216.6,"id":31375}]}]}
{"op":"mcm","clk":"11746067928","pt":1722451730792,"mc":[{"id":"1.231282919","rc":[{"batb":[[0,1.93,10],[1,1.92,40.17],[2,1.43,116.28]],"ltp":2.16,"tv":216.6,"id":31375}]}]}
{"op":"mcm","clk":"11746068621","pt":1722451733997,"mc":[{"id":"1.231282919","rc":[{"batb":[[0,1.92,40.17],[1,1.43,116.28],[2,1.38,131.58]],"ltp":2.16,"tv":216.6,"id":31375}]}]}
{"op":"mcm","clk":"11746071407","pt":1722451747392,"mc":[{"id":"1.231282919","rc":[{"batb":[[0,1.93,10],[1,1.92,40.17],[2,1.43,116.28]],"ltp":2.16,"tv":216.6,"id":31375}]}]}
{"op":"mcm","clk":"11746072180","pt":1722451750826,"mc":[{"id":"1.231282919","rc":[{"batb":[[0,1.92,40.17],[1,1.43,116.28],[2,1.38,131.58]],"ltp":2.16,"tv":216.6,"id":31375}]}]}
{"op":"mcm","clk":"11746073733","pt":1722451758027,"mc":[{"id":"1.231282919","rc":[{"batb":[[0,1.93,10],[1,1.92,40.17],[2,1.43,116.28]],"ltp":2.16,"tv":216.6,"id":31375}]}]}
{"op":"mcm","clk":"11746074461","pt":1722451761327,"mc":[{"id":"1.231282919","rc":[{"batb":[[0,1.92,40.17],[1,1.43,116.28],[2,1.38,131.58]],"ltp":2.16,"tv":216.6,"id":31375}]}]}
{"op":"mcm","clk":"11746076773","pt":1722451771942,"mc":[{"id":"1.231282919","rc":[{"batb":[[0,1.93,10],[1,1.92,40.17],[2,1.43,116.28]],"ltp":2.16,"tv":216.6,"id":31375}]}]}
{"op":"mcm","clk":"11746077485","pt":1722451775266,"mc":[{"id":"1.231282919","rc":[{"batb":[[0,1.92,40.17],[1,1.43,116.28],[2,1.38,131.58]],"ltp":2.16,"tv":216.6,"id":31375}]}]}
{"op":"mcm","clk":"11746079185","pt":1722451782925,"mc":[{"id":"1.231282919","rc":[{"batb":[[0,1.93,10],[1,1.92,40.17],[2,1.43,116.28]],"ltp":2.16,"tv":216.6,"id":31375}]}]}
{"op":"mcm","clk":"11746079883","pt":1722451786238,"mc":[{"id":"1.231282919","rc":[{"batb":[[0,1.92,40.17],[1,1.43,116.28],[2,1.38,131.58]],"ltp":2.16,"tv":216.6,"id":31375}]}]}
{"op":"mcm","clk":"11746081423","pt":1722451793341,"mc":[{"id":"1.231282919","rc":[{"batb":[[0,1.93,10],[1,1.92,40.17],[2,1.43,116.28]],"ltp":2.16,"tv":216.6,"id":31375}]}]}
{"op":"mcm","clk":"11746082153","pt":1722451796742,"mc":[{"id":"1.231282919","rc":[{"batb":[[0,1.92,40.17],[1,1.43,116.28],[2,1.38,131.58]],"ltp":2.16,"tv":216.6,"id":31375}]}]}
{"op":"mcm","clk":"11746087198","pt":1722451820475,"mc":[{"id":"1.231282919","rc":[{"batb":[[0,1.93,10],[1,1.92,40.17],[2,1.43,116.28]],"ltp":2.16,"tv":216.6,"id":31375}]}]}
{"op":"mcm","clk":"11746087881","pt":1722451823796,"mc":[{"id":"1.231282919","rc":[{"batb":[[0,1.92,40.17],[1,1.43,116.28],[2,1.38,131.58]],"ltp":2.16,"tv":216.6,"id":31375}]}]}
{"op":"mcm","clk":"11746091478","pt":1722451843189,"mc":[{"id":"1.231282919","rc":[{"batb":[[0,1.93,10],[1,1.92,40.17],[2,1.43,116.28]],"ltp":2.16,"tv":216.6,"id":31375}]}]}
{"op":"mcm","clk":"11746092082","pt":1722451846601,"mc":[{"id":"1.231282919","rc":[{"batb":[[0,1.92,40.17],[1,1.43,116.28],[2,1.38,131.58]],"ltp":2.16,"tv":216.6,"id":31375}]}]}
{"op":"mcm","clk":"11746094928","pt":1722451861708,"mc":[{"id":"1.231282919","rc":[{"trd":[[2,9.06]],"batb":[[0,1.99,37.33],[1,1.89,25],[2,1.79,11.87]],"batl":[[0,2,195.47]],"ltp":2.0,"tv":974.82,"id":31372}],"tv":1191.43}]}
{"op":"mcm","clk":"11746094949","pt":1722451861815,"mc":[{"id":"1.231282919","rc":[{"batb":[[0,1.93,10],[1,1.92,40.17],[2,1.43,116.28]],"ltp":2.16,"tv":216.6,"id":31375}]}]}
{"op":"mcm","clk":"11746095564","pt":1722451865211,"mc":[{"id":"1.231282919","rc":[{"batb":[[0,1.92,40.17],[1,1.43,116.28],[2,1.38,131.58]],"ltp":2.16,"tv":216.6,"id":31375}]}]}
{"op":"mcm","clk":"11746096108","pt":1722451868119,"mc":[{"id":"1.231282919","rc":[{"batb":[[0,1.93,10],[1,1.92,40.17],[2,1.43,116.28]],"ltp":2.16,"tv":216.6,"id":31375}]}]}
{"op":"mcm","clk":"11746096718","pt":1722451871432,"mc":[{"id":"1.231282919","rc":[{"batb":[[0,1.92,40.17],[1,1.43,116.28],[2,1.38,131.58]],"ltp":2.16,"tv":216.6,"id":31375}]}]}
{"op":"mcm","clk":"11746097733","pt":1722451877217,"mc":[{"id":"1.231282919","rc":[{"batb":[[0,1.93,10],[1,1.92,40.17],[2,1.43,116.28]],"ltp":2.16,"tv":216.6,"id":31375}]}]}
{"op":"mcm","clk":"11746098313","pt":1722451880532,"mc":[{"id":"1.231282919","rc":[{"batb":[[0,1.92,40.17],[1,1.43,116.28],[2,1.38,131.58]],"ltp":2.16,"tv":216.6,"id":31375}]}]}
{"op":"mcm","clk":"11746099019","pt":1722451884219,"mc":[{"id":"1.231282919","rc":[{"batb":[[0,1.93,10],[1,1.92,40.17],[2,1.43,116.28]],"ltp":2.16,"tv":216.6,"id":31375}]}]}
{"op":"mcm","clk":"11746099633","pt":1722451887668,"mc":[{"id":"1.231282919","rc":[{"batb":[[0,1.92,40.17],[1,1.43,116.28],[2,1.38,131.58]],"ltp":2.16,"tv":216.6,"id":31375}]}]}
{"op":"mcm","clk":"11746100783","pt":1722451893863,"mc":[{"id":"1.231282919","rc":[{"batb":[[0,1.93,10],[1,1.92,40.17],[2,1.43,116.28]],"ltp":2.16,"tv":216.6,"id":31375}]}]}
{"op":"mcm","clk":"11746101387","pt":1722451897237,"mc":[{"id":"1.231282919","rc":[{"batb":[[0,1.92,40.17],[1,1.43,116.28],[2,1.38,131.58]],"ltp":2.16,"tv":216.6,"id":31375}]}]}
{"op":"mcm","clk":"11746105151","pt":1722451917554,"mc":[{"id":"1.231282919","rc":[{"trd":[[1.99,75.56]],"batb":[[0,1.89,25],[1,1.79,11.87],[2,1.43,116.28]],"batl":[[0,1.99,262.67],[1,2,195.47]],"ltp":1.99,"tv":1049.48,"id":31372},{"batb":[[0,1.93,10],[1,1.92,40.17],[2,1.43,116.28]],"ltp":2.16,"tv":216.6,"id":31375}],"tv":1266.09}]}
{"op":"mcm","clk":"11746105334","pt":1722451918654,"mc":[{"id":"1.231282919","rc":[{"batb":[[0,1.95,38.9],[1,1.89,25],[2,1.79,11.87]],"ltp":1.99,"tv":1049.48,"id":31372}]}]}
{"op":"mcm","clk":"11746105748","pt":1722451921013,"mc":[{"id":"1.231282919","rc":[{"batb":[[0,1.92,40.17],[1,1.43,116.28],[2,1.38,131.58]],"ltp":2.16,"tv":216.6,"id":31375}]}]}
{"op":"mcm","clk":"11746110662","pt":1722451949131,"mc":[{"id":"1.231282919","rc":[{"batl":[[0,1.98,16.85],[1,1.99,262.67],[2,2,195.47]],"ltp":1.99,"tv":1049.48,"id":31372},{"batb":[[0,1.93,10],[1,1.92,40.17],[2,1.43,116.28]],"ltp":2.16,"tv":216.6,"id":31375}]}]}
{"op":"mcm","clk":"11746111221","pt":1722451952437,"mc":[{"id":"1.231282919","rc":[{"batb":[[0,1.92,40.17],[1,1.43,116.28],[2,1.38,131.58]],"ltp":2.16,"tv":216.6,"id":31375}]}]}
{"op":"mcm","clk":"11746115651","pt":1722451978558,"mc":[{"id":"1.231282919","rc":[{"batb":[[0,1.93,10],[1,1.92,40.17],[2,1.43,116.28]],"ltp":2.16,"tv":216.6,"id":31375}]}]}
{"op":"mcm","clk":"11746116245","pt":1722451982040,"mc":[{"id":"1.231282919","rc":[{"batb":[[0,1.92,40.17],[1,1.43,116.28],[2,1.38,131.58]],"ltp":2.16,"tv":216.6,"id":31375}]}]}
{"op":"mcm","clk":"11746118414","pt":1722451993435,"mc":[{"id":"1.231282919","rc":[{"batb":[[0,1.93,10],[1,1.92,40.17],[2,1.43,116.28]],"ltp":2.16,"tv":216.6,"id":31375}]}]}
{"op":"mcm","clk":"11746119016","pt":1722451996639,"mc":[{"id":"1.231282919","rc":[{"batb":[[0,1.92,40.17],[1,1.43,116.28],[2,1.38,131.58]],"ltp":2.16,"tv":216.6,"id":31375}]}]}
{"op":"mcm","clk":"11746119664","pt":1722452000127,"mc":[{"id":"1.231282919","rc":[{"batb":[[0,1.93,10],[1,1.92,40.17],[2,1.43,116.28]],"ltp":2.16,"tv":216.6,"id":31375}]}]}
{"op":"mcm","clk":"11746120262","pt":1722452003333,"mc":[{"id":"1.231282919","rc":[{"batb":[[0,1.92,40.17],[1,1.43,116.28],[2,1.38,131.58]],"ltp":2.16,"tv":216.6,"id":31375}]}]}
{"op":"mcm","clk":"11746123784","pt":1722452023066,"mc":[{"id":"1.231282919","rc":[{"batb":[[0,1.93,10],[1,1.92,40.17],[2,1.43,116.28]],"ltp":2.16,"tv":216.6,"id":31375}]}]}
{"op":"mcm","clk":"11746124286","pt":1722452026266,"mc":[{"id":"1.231282919","rc":[{"batb":[[0,1.92,40.17],[1,1.43,116.28],[2,1.38,131.58]],"ltp":2.16,"tv":216.6,"id":31375}]}]}
{"op":"mcm","clk":"11746124930","pt":1722452030150,"mc":[{"id":"1.231282919","rc":[{"batb":[[0,1.93,10],[1,1.92,40.17],[2,1.43,116.28]],"ltp":2.16,"tv":216.6,"id":31375}]}]}
{"op":"mcm","clk":"11746125528","pt":1722452033771,"mc":[{"id":"1.231282919","rc":[{"batb":[[0,1.92,40.17],[1,1.43,116.28],[2,1.38,131.58]],"ltp":2.16,"tv":216.6,"id":31375}]}]}
{"op":"mcm","clk":"11746126229","pt":1722452037976,"mc":[{"id":"1.231282919","rc":[{"batb":[[0,1.93,10],[1,1.92,40.17],[2,1.43,116.28]],"ltp":2.16,"tv":216.6,"id":31375}]}]}
{"op":"mcm","clk":"11746126822","pt":1722452041388,"mc":[{"id":"1.231282919","rc":[{"batb":[[0,1.92,40.17],[1,1.43,116.28],[2,1.38,131.58]],"ltp":2.16,"tv":216.6,"id":31375}]}]}
{"op":"mcm","clk":"11746129821","pt":1722452059082,"mc":[{"id":"1.231282919","rc":[{"batb":[[0,1.93,10],[1,1.92,40.17],[2,1.43,116.28]],"ltp":2.16,"tv":216.6,"id":31375}]}]}
{"op":"mcm","clk":"11746130394","pt":1722452062606,"mc":[{"id":"1.231282919","rc":[{"batb":[[0,1.92,40.17],[1,1.43,116.28],[2,1.38,131.58]],"ltp":2.16,"tv":216.6,"id":31375}]}]}
{"op":"mcm","clk":"11746132105","pt":1722452072718,"mc":[{"id":"1.231282919","rc":[{"batb":[[0,1.93,10],[1,1.92,40.17],[2,1.43,116.28]],"ltp":2.16,"tv":216.6,"id":31375}]}]}
{"op":"mcm","clk":"11746132719","pt":1722452076219,"mc":[{"id":"1.231282919","rc":[{"batb":[[0,1.92,40.17],[1,1.43,116.28],[2,1.38,131.58]],"ltp":2.16,"tv":216.6,"id":31375}]}]}
{"op":"mcm","clk":"11746134412","pt":1722452086222,"mc":[{"id":"1.231282919","rc":[{"batb":[[0,1.93,10],[1,1.92,40.17],[2,1.43,116.28]],"ltp":2.16,"tv":216.6,"id":31375}]}]}
{"op":"mcm","clk":"11746134961","pt":1722452089676,"mc":[{"id":"1.231282919","rc":[{"batb":[[0,1.92,40.17],[1,1.43,116.28],[2,1.38,131.58]],"ltp":2.16,"tv":216.6,"id":31375}]}]}
{"op":"mcm","clk":"11746137373","pt":1722452103969,"mc":[{"id":"1.231282919","rc":[{"batb":[[0,1.93,10],[1,1.92,40.17],[2,1.43,116.28]],"ltp":2.16,"tv":216.6,"id":31375}]}]}
{"op":"mcm","clk":"11746138120","pt":1722452107561,"mc":[{"id":"1.231282919","rc":[{"batb":[[0,1.92,40.17],[1,1.43,116.28],[2,1.38,131.58]],"ltp":2.16,"tv":216.6,"id":31375}]}]}
{"op":"mcm","clk":"11746149576","pt":1722452171725,"mc":[{"id":"1.231282919","rc":[{"batb":[[0,1.93,10],[1,1.92,40.17],[2,1.43,116.28]],"ltp":2.16,"tv":216.6,"id":31375}]}]}
{"op":"mcm","clk":"11746150238","pt":1722452175536,"mc":[{"id":"1.231282919","rc":[{"batb":[[0,1.92,40.17],[1,1.43,116.28],[2,1.38,131.58]],"ltp":2.16,"tv":216.6,"id":31375}]}]}
{"op":"mcm","clk":"11746152691","pt":1722452189561,"mc":[{"id":"1.231282919","rc":[{"batb":[[0,2.02,16.85],[1,1.92,40.17],[2,1.43,116.28]],"ltp":2.16,"tv":216.6,"id":31375}]}]}
{"op":"mcm","clk":"11746152726","pt":1722452189762,"mc":[{"id":"1.231282919","rc":[{"batb":[[0,2.04,10],[1,2.02,16.85],[2,1.92,40.17]],"ltp":2.16,"tv":216.6,"id":31375}]}]}
{"op":"mcm","clk":"11746153325","pt":1722452192963,"mc":[{"id":"1.231282919","rc":[{"batb":[[0,2.02,16.85],[1,1.92,40.17],[2,1.43,116.28]],"ltp":2.16,"tv":216.6,"id":31375}]}]}
{"op":"mcm","clk":"11746157044","pt":1722452215598,"mc":[{"id":"1.231282919","rc":[{"trd":[[1.95,77.8]],"batb":[[0,1.89,25],[1,1.79,11.87],[2,1.43,116.28]],"batl":[[0,1.95,261.1]],"ltp":1.95,"tv":1127.28,"id":31372},{"batb":[[0,2.04,10]],"batl":[[0,2.12,8.19],[1,2.14,87],[2,2.16,5.04]],"ltp":2.16,"tv":216.6,"id":31375}],"tv":1343.89}]}
{"op":"mcm","clk":"11746157515","pt":1722452218379,"mc":[{"id":"1.231282919","rc":[{"batb":[[0,1.92,40.17],[1,1.43,116.28],[2,1.38,131.58]],"ltp":2.16,"tv":216.6,"id":31375}]}]}
{"op":"mcm","clk":"11746157848","pt":1722452220415,"mc":[{"id":"1.231282919","rc":[{"batb":[[0,1.91,40.61],[1,1.89,25],[2,1.79,11.87]],"ltp":1.95,"tv":1127.28,"id":31372},{"batl":[[0,2.14,87],[1,2.16,5.04],[2,2.16,0]],"ltp":2.16,"tv":216.6,"id":31375}]}]}
{"op":"mcm","clk":"11746159243","pt":1722452228012,"mc":[{"id":"1.231282919","rc":[{"batb":[[1,1.79,11.87],[2,1.43,116.28]],"ltp":1.95,"tv":1127.28,"id":31372},{"batb":[[0,1.93,10],[1,1.92,40.17],[2,1.43,116.28]],"ltp":2.16,"tv":216.6,"id":31375}]}]}
{"op":"mcm","clk":"11746159882","pt":1722452231729,"mc":[{"id":"1.231282919","rc":[{"batb":[[0,1.92,40.17],[1,1.43,116.28],[2,1.38,131.58]],"ltp":2.16,"tv":216.6,"id":31375}]}]}
{"op":"mcm","clk":"11746162440","pt":1722452245621,"mc":[{"id":"1.231282919","rc":[{"batl":[[0,1.94,16.85],[1,1.95,261.1],[2,1.99,262.67]],"ltp":1.95,"tv":1127.28,"id":31372}]}]}
{"op":"mcm","clk":"11746162452","pt":1722452245720,"mc":[{"id":"1.231282919","rc":[{"batb":[[0,1.93,10],[1,1.92,40.17],[2,1.43,116.28]],"ltp":2.16,"tv":216.6,"id":31375}]}]}
{"op":"mcm","clk":"11746163083","pt":1722452249143,"mc":[{"id":"1.231282919","rc":[{"batb":[[0,1.92,40.17],[1,1.43,116.28],[2,1.38,131.58]],"ltp":2.16,"tv":216.6,"id":31375}]}]}
{"op":"mcm","clk":"11746201975","pt":1722452469443,"mc":[{"id":"1.231282919","rc":[{"trd":[[1.78,5.1],[1.79,189.9],[1.82,169.9],[2,9.06]],"batb":[[0,1.79,11.87],[1,1.43,116.28],[2,1.38,131.58]],"batl":[[0,1.94,16.84]],"ltp":1.95,"tv":1127.31,"id":31372},{"trd":[[2.28,13.62]],"batb":[[0,1.44,10]],"ltp":2.16,"tv":216.59,"id":31375}],"tv":1343.91}]}
{"op":"mcm","clk":"11746202611","pt":1722452472354,"mc":[{"id":"1.231282919","rc":[{"batl":[[0,2.12,6.54],[1,2.14,87],[2,2.16,5.04]],"ltp":2.16,"tv":216.59,"id":31375}]}]}
{"op":"mcm","clk":"11746202782","pt":1722452473035,"mc":[{"id":"1.231282919","rc":[{"batb":[[0,1.43,116.28],[1,1.38,131.58],[2,1.33,151.52]],"ltp":2.16,"tv":216.59,"id":31375}]}]}
{"op":"mcm","clk":"11746205315","pt":1722452486468,"mc":[{"id":"1.231282919","rc":[{"batb":[[0,2.06,16.2],[1,1.43,116.28],[2,1.38,131.58]],"ltp":2.16,"tv":216.59,"id":31375}]}]}
{"op":"mcm","clk":"11746206940","pt":1722452495671,"mc":[{"id":"1.231282919","rc":[{"batb":[[0,1.88,4.69],[1,1.79,11.87],[2,1.43,116.28]],"ltp":1.95,"tv":1127.31,"id":31372},{"batl":[[0,2.12,11.13]],"ltp":2.16,"tv":216.59,"id":31375}]}]}
{"op":"mcm","clk":"11746208351","pt":1722452503364,"mc":[{"id":"1.231282919","rc":[{"batb":[[0,1.88,7.83]],"ltp":1.95,"tv":1127.31,"id":31372}]}]}
{"op":"mcm","clk":"11746226945","pt":1722452603768,"mc":[{"id":"1.231282919","rc":[{"trd":[[1.94,8.42]],"batl":[[0,1.94,12.63]],"ltp":1.94,"tv":1135.73,"id":31372}],"tv":1352.33}]}
{"op":"mcm","clk":"11746227283","pt":1722452605494,"mc":[{"id":"1.231282919","rc":[{"batl":[[0,1.94,25.73]],"ltp":1.94,"tv":1135.73,"id":31372}]}]}
{"op":"mcm","clk":"11746227614","pt":1722452607193,"mc":[{"id":"1.231282919","rc":[{"batb":[[0,1.88,12.55]],"ltp":1.94,"tv":1135.73,"id":31372}]}]}
{"op":"mcm","clk":"11746228041","pt":1722452609376,"mc":[{"id":"1.231282919","rc":[{"batb":[[0,1.88,7.83]],"ltp":1.94,"tv":1135.73,"id":31372}]}]}
{"op":"mcm","clk":"11746251310","pt":1722452727299,"mc":[{"id":"1.231282919","rc":[{"batb":[[0,1.88,12.55]],"ltp":1.94,"tv":1135.73,"id":31372}]}]}
{"op":"mcm","clk":"11746251777","pt":1722452729420,"mc":[{"id":"1.231282919","rc":[{"batb":[[0,1.88,7.83]],"ltp":1.94,"tv":1135.73,"id":31372}]}]}
{"op":"mcm","clk":"11746271755","pt":1722452832184,"mc":[{"id":"1.231282919","rc":[{"batb":[[0,1.88,12.55]],"ltp":1.94,"tv":1135.73,"id":31372}]}]}
{"op":"mcm","clk":"11746272066","pt":1722452833761,"mc":[{"id":"1.231282919","rc":[{"batb":[[0,1.88,7.83]],"ltp":1.94,"tv":1135.73,"id":31372}]}]}
{"op":"mcm","clk":"11746290405","pt":1722452924560,"mc":[{"id":"1.231282919","rc":[{"batb":[[0,1.88,12.55]],"ltp":1.94,"tv":1135.73,"id":31372}]}]}
{"op":"mcm","clk":"11746290759","pt":1722452926519,"mc":[{"id":"1.231282919","rc":[{"batb":[[0,1.88,7.83]],"ltp":1.94,"tv":1135.73,"id":31372}]}]}
{"op":"mcm","clk":"11746309102","pt":1722453022028,"mc":[{"id":"1.231282919","rc":[{"batb":[[0,1.88,12.55]],"ltp":1.94,"tv":1135.73,"id":31372}]}]}
{"op":"mcm","clk":"11746309410","pt":1722453023623,"mc":[{"id":"1.231282919","rc":[{"batb":[[0,1.88,7.83]],"ltp":1.94,"tv":1135.73,"id":31372}]}]}
{"op":"mcm","clk":"11746326230","pt":1722453112230,"mc":[{"id":"1.231282919","rc":[{"batb":[[0,1.88,12.55]],"ltp":1.94,"tv":1135.73,"id":31372}]}]}
{"op":"mcm","clk":"11746326642","pt":1722453114224,"mc":[{"id":"1.231282919","rc":[{"batb":[[0,1.88,7.83]],"ltp":1.94,"tv":1135.73,"id":31372}]}]}
{"op":"mcm","clk":"11746351745","pt":1722453201844,"mc":[{"id":"1.231282919","rc":[{"batb":[[0,1.88,12.55]],"ltp":1.94,"tv":1135.73,"id":31372}]}]}
{"op":"mcm","clk":"11746352124","pt":1722453203826,"mc":[{"id":"1.231282919","rc":[{"batb":[[0,1.88,7.83]],"ltp":1.94,"tv":1135.73,"id":31372}]}]}
{"op":"mcm","clk":"11746367601","pt":1722453285522,"mc":[{"id":"1.231282919","rc":[{"batb":[[0,1.88,12.55]],"ltp":1.94,"tv":1135.73,"id":31372}]}]}
{"op":"mcm","clk":"11746367854","pt":1722453287011,"mc":[{"id":"1.231282919","rc":[{"batb":[[0,1.88,7.83]],"ltp":1.94,"tv":1135.73,"id":31372}]}]}
{"op":"mcm","clk":"11746384756","pt":1722453373313,"mc":[{"id":"1.231282919","rc":[{"batb":[[0,1.88,12.55]],"ltp":1.94,"tv":1135.73,"id":31372}]}]}
{"op":"mcm","clk":"11746385033","pt":1722453374726,"mc":[{"id":"1.231282919","rc":[{"batb":[[0,1.88,7.83]],"ltp":1.94,"tv":1135.73,"id":31372}]}]}
{"op":"mcm","clk":"11746400853","pt":1722453459695,"mc":[{"id":"1.231282919","rc":[{"batb":[[0,1.88,12.55]],"ltp":1.94,"tv":1135.73,"id":31372}]}]}
{"op":"mcm","clk":"11746401130","pt":1722453461490,"mc":[{"id":"1.231282919","rc":[{"batb":[[0,1.88,7.83]],"ltp":1.94,"tv":1135.73,"id":31372}]}]}
{"op":"mcm","clk":"11746416251","pt":1722453546695,"mc":[{"id":"1.231282919","rc":[{"batb":[[0,1.88,12.55]],"ltp":1.94,"tv":1135.73,"id":31372}]}]}
{"op":"mcm","clk":"11746416623","pt":1722453548591,"mc":[{"id":"1.231282919","rc":[{"batb":[[0,1.88,7.83]],"ltp":1.94,"tv":1135.73,"id":31372}]}]}
{"op":"mcm","clk":"11746430937","pt":1722453628961,"mc":[{"id":"1.231282919","rc":[{"batb":[[0,1.88,12.55]],"ltp":1.94,"tv":1135.73,"id":31372}]}]}
{"op":"mcm","clk":"11746431199","pt":1722453630587,"mc":[{"id":"1.231282919","rc":[{"batb":[[0,1.88,7.83]],"ltp":1.94,"tv":1135.73,"id":31372}]}]}
{"op":"mcm","clk":"11746445021","pt":1722453714680,"mc":[{"id":"1.231282919","rc":[{"batb":[[0,1.88,12.55]],"ltp":1.94,"tv":1135.73,"id":31372}]}]}
{"op":"mcm","clk":"11746445331","pt":1722453716460,"mc":[{"id":"1.231282919","rc":[{"batb":[[0,1.88,7.83]],"ltp":1.94,"tv":1135.73,"id":31372}]}]}
{"op":"mcm","clk":"11746460868","pt":1722453803948,"mc":[{"id":"1.231282919","rc":[{"batb":[[0,1.88,12.55]],"ltp":1.94,"tv":1135.73,"id":31372}]}]}
{"op":"mcm","clk":"11746461205","pt":1722453805941,"mc":[{"id":"1.231282919","rc":[{"batb":[[0,1.88,7.83]],"ltp":1.94,"tv":1135.73,"id":31372}]}]}
{"op":"mcm","clk":"11746475371","pt":1722453890382,"mc":[{"id":"1.231282919","rc":[{"batb":[[0,1.88,12.55]],"ltp":1.94,"tv":1135.73,"id":31372}]}]}
{"op":"mcm","clk":"11746475646","pt":1722453891960,"mc":[{"id":"1.231282919","rc":[{"batb":[[0,1.88,7.83]],"ltp":1.94,"tv":1135.73,"id":31372}]}]}
{"op":"mcm","clk":"11746488921","pt":1722453976852,"mc":[{"id":"1.231282919","rc":[{"batb":[[0,1.88,12.55]],"ltp":1.94,"tv":1135.73,"id":31372}]}]}
{"op":"mcm","clk":"11746489126","pt":1722453978365,"mc":[{"id":"1.231282919","rc":[{"batb":[[0,1.88,7.83]],"ltp":1.94,"tv":1135.73,"id":31372}]}]}
{"op":"mcm","clk":"11746502372","pt":1722454061402,"mc":[{"id":"1.231282919","rc":[{"batb":[[0,1.88,12.55]],"ltp":1.94,"tv":1135.73,"id":31372}]}]}
{"op":"mcm","clk":"11746502602","pt":1722454063007,"mc":[{"id":"1.231282919","rc":[{"batb":[[0,1.88,7.83]],"ltp":1.94,"tv":1135.73,"id":31372}]}]}
{"op":"mcm","clk":"11746516125","pt":1722454148409,"mc":[{"id":"1.231282919","rc":[{"batb":[[0,1.88,12.55]],"ltp":1.94,"tv":1135.73,"id":31372}]}]}
{"op":"mcm","clk":"11746516424","pt":1722454150220,"mc":[{"id":"1.231282919","rc":[{"batb":[[0,1.88,7.83]],"ltp":1.94,"tv":1135.73,"id":31372}]}]}
{"op":"mcm","clk":"11746530938","pt":1722454234102,"mc":[{"id":"1.231282919","rc":[{"batb":[[0,1.88,12.55]],"ltp":1.94,"tv":1135.73,"id":31372}]}]}
{"op":"mcm","clk":"11746531209","pt":1722454235687,"mc":[{"id":"1.231282919","rc":[{"batb":[[0,1.88,7.83]],"ltp":1.94,"tv":1135.73,"id":31372}]}]}
{"op":"mcm","clk":"11746544482","pt":1722454321597,"mc":[{"id":"1.231282919","rc":[{"batb":[[0,1.88,12.55]],"ltp":1.94,"tv":1135.73,"id":31372}]}]}
{"op":"mcm","clk":"11746544790","pt":1722454323577,"mc":[{"id":"1.231282919","rc":[{"batb":[[0,1.88,7.83]],"ltp":1.94,"tv":1135.73,"id":31372}]}]}
{"op":"mcm","clk":"11746548055","pt":1722454347414,"mc":[{"id":"1.231282919","rc":[{"trd":[[1.89,212.48]],"batl":[[0,1.89,287.52],[1,1.94,25.73],[2,1.95,261.1]],"ltp":1.89,"tv":1148.21,"id":31372},{"trd":[[2.12,11.13]],"batl":[[0,2.14,87],[1,2.16,5.04],[2,2.16,0]],"ltp":2.12,"tv":227.72,"id":31375}],"tv":1375.93}]}
{"op":"mcm","clk":"11746548198","pt":1722454348307,"mc":[{"id":"1.231282919","rc":[{"batb":[[0,1.79,11.87],[1,1.43,116.28],[2,1.38,131.58]],"batl":[[1,1.95,261.1],[2,1.99,262.67]],"ltp":1.89,"tv":1148.21,"id":31372},{"batb":[[0,2.12,11.13],[1,1.44,10],[2,1.43,116.28]],"ltp":2.12,"tv":227.72,"id":31375}]}]}
{"op":"mcm","clk":"11746548523","pt":1722454350303,"mc":[{"id":"1.231282919","rc":[{"trd":[[1.88,8.7]],"batl":[[0,1.88,295.65],[1,1.89,287.52],[2,1.95,261.1]],"ltp":1.88,"tv":1156.91,"id":31372}],"tv":1384.63}]}
{"op":"mcm","clk":"11746548675","pt":1722454351363,"mc":[{"id":"1.231282919","rc":[{"batb":[[1,1.43,116.28],[2,1.38,131.58]],"ltp":2.12,"tv":227.72,"id":31375}]}]}
{"op":"mcm","clk":"11746549130","pt":1722454354251,"mc":[{"id":"1.231282919","rc":[{"trd":[[1.87,299.56]],"batl":[[0,1.87,200.44],[1,1.88,295.65],[2,1.89,287.52]],"ltp":1.87,"tv":1256.47,"id":31372},{"trd":[[2.14,87]],"batb":[[0,2.12,4.59]],"batl":[[0,2.16,5.04],[1,2.16,0]],"ltp":2.14,"tv":314.72,"id":31375}],"tv":1571.19}]}
{"op":"mcm","clk":"11746549280","pt":1722454355243,"mc":[{"id":"1.231282919","rc":[{"batb":[[0,1.44,10]],"ltp":2.14,"tv":314.72,"id":31375}]}]}
{"op":"mcm","clk":"11746549782","pt":1722454358652,"mc":[{"id":"1.231282919","rc":[{"trd":[[2.16,95.73]],"batb":[[0,2.16,1.38]],"ltp":2.16,"tv":324.79,"id":31375}],"tv":1581.26}]}
{"op":"mcm","clk":"11746551045","pt":1722454366524,"mc":[{"id":"1.231282919","rc":[{"batb":[[0,2.16,5.89]],"ltp":2.16,"tv":324.79,"id":31375}]}]}
{"op":"mcm","clk":"11746554036","pt":1722454386042,"mc":[{"id":"1.231282919","rc":[{"batl":[[0,1.86,15.56],[1,1.87,200.44],[2,1.88,295.65]],"ltp":1.87,"tv":1256.47,"id":31372}]}]}
{"op":"mcm","clk":"11746587015","pt":1722454594961,"mc":[{"id":"1.231282919","rc":[{"batl":[[0,1.86,25.17]],"ltp":1.87,"tv":1256.47,"id":31372}]}]}
{"op":"mcm","clk":"11746601782","pt":1722454689860,"mc":[{"id":"1.231282919","rc":[{"batb":[[1,1.92,40.17],[2,1.43,116.28]],"ltp":2.16,"tv":324.79,"id":31375}]}]}
{"op":"mcm","clk":"11746662493","pt":1722455053526,"mc":[{"id":"1.231282919","rc":[{"trd":[[1.86,25.17],[1.87,382.45]],"batl":[[0,1.87,117.55],[1,1.88,295.65],[2,1.89,287.52]],"ltp":1.87,"tv":1364.53,"id":31372},{"trd":[[2.14,159.43],[2.16,129.18]],"batb":[[0,2.16,7.59]],"ltp":2.14,"tv":430.68,"id":31375}],"tv":1795.21}]}
{"op":"mcm","clk":"11746662673","pt":1722455054634,"mc":[{"id":"1.231282919","rc":[{"batb":[[1,1.44,12.41],[2,1.43,116.28]],"ltp":1.87,"tv":1364.53,"id":31372},{"batb":[[0,2.16,12.92]],"ltp":2.14,"tv":430.68,"id":31375}]}]}
{"op":"mcm","clk":"11746667294","pt":1722455084205,"mc":[{"id":"1.231282919","rc":[{"trd":[[1.87,404.43]],"batl":[[0,1.87,106.56]],"ltp":1.87,"tv":1386.51,"id":31372}],"tv":1817.19}]}
{"op":"mcm","clk":"11746668202","pt":1722455089392,"mc":[{"id":"1.231282919","rc":[{"batl":[[0,2.2,100]],"ltp":2.14,"tv":430.68,"id":31375}]}]}
{"op":"mcm","clk":"11746668541","pt":1722455091281,"mc":[{"id":"1.231282919","rc":[{"batb":[[0,1.84,9.72],[1,1.79,11.87]],"ltp":1.87,"tv":1386.51,"id":31372}]}]}
{"op":"mcm","clk":"11746668658","pt":1722455092003,"mc":[{"id":"1.231282919","rc":[{"batb":[[0,1.84,25.45]],"ltp":1.87,"tv":1386.51,"id":31372},{"batb":[[1,1.43,116.28],[2,1.38,131.58]],"ltp":2.14,"tv":430.68,"id":31375}]}]}
{"op":"mcm","clk":"11746673672","pt":1722455122999,"mc":[{"id":"1.231282919","rc":[{"batb":[[0,1.84,34.48]],"ltp":1.87,"tv":1386.51,"id":31372}]}]}
{"op":"mcm","clk":"11746701793","pt":1722455301608,"mc":[{"id":"1.231282919","rc":[{"batl":[[0,2.18,9.56],[1,2.2,100]],"ltp":2.14,"tv":430.68,"id":31375}]}]}
{"op":"mcm","clk":"11746719459","pt":1722455416531,"mc":[{"id":"1.231282919","rc":[{"trd":[[2.16,155.02]],"batb":[[0,1.43,116.28],[1,1.38,131.58],[2,1.33,151.52]],"batl":[[0,2.16,87.08],[1,2.18,9.56],[2,2.2,100]],"ltp":2.16,"tv":456.52,"id":31375}],"tv":1843.03}]}
{"op":"mcm","clk":"11746719598","pt":1722455417418,"mc":[{"id":"1.231282919","rc":[{"batb":[[0,1.86,9.61],[1,1.84,24.76],[2,1.79,11.87]],"ltp":1.87,"tv":1386.51,"id":31372},{"batb":[[0,1.44,10],[1,1.43,116.28],[2,1.38,131.58]],"batl":[[0,2.16,92.41]],"ltp":2.16,"tv":456.52,"id":31375}]}]}
{"op":"mcm","clk":"11746719798","pt":1722455418706,"mc":[{"id":"1.231282919","rc":[{"batb":[[0,1.86,25.17],[1,1.79,11.87],[2,1.43,116.28]],"ltp":1.87,"tv":1386.51,"id":31372},{"batb":[[0,1.92,40.17],[1,1.44,10],[2,1.43,116.28]],"ltp":2.16,"tv":456.52,"id":31375}]}]}
{"op":"mcm","clk":"11746720007","pt":1722455420229,"mc":[{"id":"1.231282919","rc":[{"batb":[[1,1.43,116.28],[2,1.38,131.58]],"ltp":2.16,"tv":456.52,"id":31375}]}]}
{"op":"mcm","clk":"11746721979","pt":1722455432660,"mc":[{"id":"1.231282919","rc":[{"batl":[[0,2.16,5.33]],"ltp":2.16,"tv":456.52,"id":31375}]}]}
{"op":"mcm","clk":"11746722065","pt":1722455433137,"mc":[{"id":"1.231282919","rc":[{"trd":[[1.87,504.08]],"batb":[[0,1.86,9.61],[1,1.85,15.65],[2,1.79,11.87]],"batl":[[0,1.87,6.91]],"ltp":1.87,"tv":1486.16,"id":31372},{"trd":[[2.14,246.51]],"batb":[[0,1.93,10],[1,1.92,40.17],[2,1.43,116.28]],"ltp":2.14,"tv":543.6,"id":31375}],"tv":2029.76}]}
{"op":"mcm","clk":"11746722535","pt":1722455435954,"mc":[{"id":"1.231282919","rc":[{"batb":[[0,1.92,40.17],[1,1.43,116.28],[2,1.38,131.58]],"ltp":2.14,"tv":543.6,"id":31375}]}]}
{"op":"mcm","clk":"11746724496","pt":1722455448557,"mc":[{"id":"1.231282919","rc":[{"batb":[[1,1.79,11.87],[2,1.43,116.28]],"ltp":1.87,"tv":1486.16,"id":31372},{"batb":[[0,1.93,10],[1,1.92,40.17],[2,1.43,116.28]],"batl":[[0,2.16,105.33],[1,2.2,100],[2,2.2,0]],"ltp":2.14,"tv":543.6,"id":31375}]}]}
{"op":"mcm","clk":"11746724632","pt":1722455449344,"mc":[{"id":"1.231282919","rc":[{"trd":[[1.87,510.99]],"batb":[[0,1.87,25.04]],"batl":[[0,1.88,295.65],[1,1.89,287.52],[2,1.95,261.1]],"ltp":1.87,"tv":1493.07,"id":31372},{"trd":[[2.14,252.55]],"batl":[[0,2.14,1.63],[1,2.16,105.33],[2,2.2,100]],"ltp":2.14,"tv":549.64,"id":31375}],"tv":2042.71}]}
{"op":"mcm","clk":"11746724962","pt":1722455451380,"mc":[{"id":"1.231282919","rc":[{"batb":[[0,1.92,40.17],[1,1.43,116.28],[2,1.38,131.58]],"ltp":2.14,"tv":549.64,"id":31375}]}]}
{"op":"mcm","clk":"11746735179","pt":1722455514178,"mc":[{"id":"1.231282919","rc":[{"trd":[[1.88,182.18]],"batl":[[0,1.88,208.91]],"ltp":1.88,"tv":1666.55,"id":31372},{"batb":[[0,1.93,10],[1,1.92,40.17],[2,1.43,116.28]],"ltp":2.14,"tv":549.64,"id":31375}],"tv":2216.2}]}
{"op":"mcm","clk":"11746735684","pt":1722455517463,"mc":[{"id":"1.231282919","rc":[{"batb":[[0,1.92,40.17],[1,1.43,116.28],[2,1.38,131.58]],"ltp":2.14,"tv":549.64,"id":31375}]}]}
{"op":"mcm","clk":"11746786338","pt":1722455908200,"mc":[{"id":"1.231282919","rc":[{"batb":[[0,1.93,10],[1,1.92,40.17],[2,1.43,116.28]],"ltp":2.14,"tv":549.64,"id":31375}]}]}
{"op":"mcm","clk":"11746786847","pt":1722455911461,"mc":[{"id":"1.231282919","rc":[{"batb":[[0,1.92,40.17],[1,1.43,116.28],[2,1.38,131.58]],"ltp":2.14,"tv":549.64,"id":31375}]}]}
{"op":"mcm","clk":"11746807362","pt":1722456071936,"mc":[{"id":"1.231282919","rc":[{"trd":[[1.78,5.09],[1.79,189.83],[1.82,169.89],[1.86,25.17],[1.88,294.93],[1.94,8.42],[2,9.06]],"batb":[[0,1.87,25.03]],"batl":[[0,1.88,96.14]],"ltp":1.88,"tv":1779.21,"id":31372},{"trd":[[2.12,111.12],[2.14,252.55],[2.16,155.02]],"batb":[[0,1.93,10],[1,1.92,40.17],[2,1.43,116.28]],"batl":[[1,2.16,105.33]],"ltp":2.12,"tv":649.63,"id":31375}],"tv":2428.84}]}
{"op":"mcm","clk":"11746807789","pt":1722456075359,"mc":[{"id":"1.231282919","rc":[{"batb":[[0,1.92,40.17],[1,1.43,116.28],[2,1.38,131.58]],"ltp":2.12,"tv":649.63,"id":31375}]}]}
{"op":"mcm","clk":"11746813332","pt":1722456120305,"mc":[{"id":"1.231282919","rc":[{"trd":[[1.88,299.45]],"batl":[[0,1.88,93.88]],"ltp":1.88,"tv":1783.73,"id":31372},{"batb":[[0,1.93,10],[1,1.92,40.17],[2,1.43,116.28]],"ltp":2.12,"tv":649.63,"id":31375}],"tv":2433.36}]}
{"op":"mcm","clk":"11746813779","pt":1722456123824,"mc":[{"id":"1.231282919","rc":[{"batb":[[0,1.92,40.17],[1,1.43,116.28],[2,1.38,131.58]],"ltp":2.12,"tv":649.63,"id":31375}]}]}
{"op":"mcm","clk":"11746821505","pt":1722456189996,"mc":[{"id":"1.231282919","rc":[{"trd":[[1.88,305.45]],"batl":[[0,1.88,90.88]],"ltp":1.88,"tv":1789.73,"id":31372},{"batb":[[0,1.93,10],[1,1.92,40.17],[2,1.43,116.28]],"ltp":2.12,"tv":649.63,"id":31375}],"tv":2439.36}]}
{"op":"mcm","clk":"11746821967","pt":1722456193279,"mc":[{"id":"1.231282919","rc":[{"batb":[[0,1.92,40.17],[1,1.43,116.28],[2,1.38,131.58]],"ltp":2.12,"tv":649.63,"id":31375}]}]}
{"op":"mcm","clk":"11746877391","pt":1722456673876,"mc":[{"id":"1.231282919","rc":[{"batb":[[0,1.93,10],[1,1.92,40.17],[2,1.43,116.28]],"ltp":2.12,"tv":649.63,"id":31375}]}]}
{"op":"mcm","clk":"11746877794","pt":1722456677363,"mc":[{"id":"1.231282919","rc":[{"batb":[[0,1.92,40.17],[1,1.43,116.28],[2,1.38,131.58]],"ltp":2.12,"tv":649.63,"id":31375}]}]}
{"op":"mcm","clk":"11746880375","pt":1722456700107,"mc":[{"id":"1.231282919","rc":[{"batb":[[0,1.93,10],[1,1.92,40.17],[2,1.43,116.28]],"ltp":2.12,"tv":649.63,"id":31375}]}]}
{"op":"mcm","clk":"11746880782","pt":1722456703580,"mc":[{"id":"1.231282919","rc":[{"batb":[[0,1.92,40.17],[1,1.43,116.28],[2,1.38,131.58]],"ltp":2.12,"tv":649.63,"id":31375}]}]}
{"op":"mcm","clk":"11746883068","pt":1722456724309,"mc":[{"id":"1.231282919","rc":[{"batb":[[0,1.93,10],[1,1.92,40.17],[2,1.43,116.28]],"ltp":2.12,"tv":649.63,"id":31375}]}]}
{"op":"mcm","clk":"11746883547","pt":1722456726941,"mc":[{"id":"1.231282919","rc":[{"batb":[[0,1.92,40.17],[1,1.43,116.28],[2,1.38,131.58]],"ltp":2.12,"tv":649.63,"id":31375}]}]}
{"op":"mcm","clk":"11746884408","pt":1722456734299,"mc":[{"id":"1.231282919","rc":[{"batb":[[0,1.93,10],[1,1.92,40.17],[2,1.43,116.28]],"ltp":2.12,"tv":649.63,"id":31375}]}]}
{"op":"mcm","clk":"11746884795","pt":1722456737631,"mc":[{"id":"1.231282919","rc":[{"batb":[[0,1.92,40.17],[1,1.43,116.28],[2,1.38,131.58]],"ltp":2.12,"tv":649.63,"id":31375}]}]}
{"op":"mcm","clk":"11746904297","pt":1722456887579,"mc":[{"id":"1.231282919","rc":[{"trd":[[1.88,396.33],[1.89,234.25]],"batl":[[0,1.89,265.75],[1,1.95,261.1],[2,1.99,262.67]],"ltp":1.89,"tv":1902.38,"id":31372},{"trd":[[2.12,211.12]],"batb":[[0,1.93,10],[1,1.92,40.17],[2,1.43,116.28]],"ltp":2.12,"tv":749.63,"id":31375}],"tv":2652.01}]}
{"op":"mcm","clk":"11746904750","pt":1722456890794,"mc":[{"id":"1.231282919","rc":[{"batb":[[0,1.92,40.17],[1,1.43,116.28],[2,1.38,131.58]],"ltp":2.12,"tv":749.63,"id":31375}]}]}
{"op":"mcm","clk":"11746909161","pt":1722456921448,"mc":[{"id":"1.231282919","rc":[{"batb":[[0,1.87,34.22]],"ltp":1.89,"tv":1902.38,"id":31372},{"batb":[[0,1.93,10],[1,1.92,40.17],[2,1.43,116.28]],"ltp":2.12,"tv":749.63,"id":31375}]}]}
{"op":"mcm","clk":"11746909622","pt":1722456924823,"mc":[{"id":"1.231282919","rc":[{"batb":[[0,1.92,40.17],[1,1.43,116.28],[2,1.38,131.58]],"ltp":2.12,"tv":749.63,"id":31375}]}]}
{"op":"mcm","clk":"11746912638","pt":1722456946641,"mc":[{"id":"1.231282919","rc":[{"trd":[[1.89,255.65]],"batl":[[0,1.89,255.05]],"ltp":1.89,"tv":1923.78,"id":31372},{"batb":[[0,1.93,10],[1,1.92,40.17],[2,1.43,116.28]],"ltp":2.12,"tv":749.63,"id":31375}],"tv":2673.41}]}
{"op":"mcm","clk":"11746913074","pt":1722456949972,"mc":[{"id":"1.231282919","rc":[{"batb":[[0,1.92,40.17],[1,1.43,116.28],[2,1.38,131.58]],"ltp":2.12,"tv":749.63,"id":31375}]}]}
{"op":"mcm","clk":"11746917280","pt":1722456982287,"mc":[{"id":"1.231282919","rc":[{"trd":[[1.89,278.13]],"batl":[[0,1.89,243.81]],"ltp":1.89,"tv":1946.26,"id":31372},{"batb":[[0,1.93,10],[1,1.92,40.17],[2,1.43,116.28]],"ltp":2.12,"tv":749.63,"id":31375}],"tv":2695.89}]}
{"op":"mcm","clk":"11746917652","pt":1722456985615,"mc":[{"id":"1.231282919","rc":[{"batb":[[0,1.92,40.17],[1,1.43,116.28],[2,1.38,131.58]],"ltp":2.12,"tv":749.63,"id":31375}]}]}
{"op":"mcm","clk":"11746921830","pt":1722457021823,"mc":[{"id":"1.231282919","rc":[{"batb":[[0,1.93,10],[1,1.92,40.17],[2,1.43,116.28]],"ltp":2.12,"tv":749.63,"id":31375}]}]}
{"op":"mcm","clk":"11746922274","pt":1722457025453,"mc":[{"id":"1.231282919","rc":[{"batb":[[0,1.92,40.17],[1,1.43,116.28],[2,1.38,131.58]],"ltp":2.12,"tv":749.63,"id":31375}]}]}
{"op":"mcm","clk":"11746925513","pt":1722457054107,"mc":[{"id":"1.231282919","rc":[{"batb":[[0,1.93,10],[1,1.92,40.17],[2,1.43,116.28]],"ltp":2.12,"tv":749.63,"id":31375}]}]}
{"op":"mcm","clk":"11746925871","pt":1722457057367,"mc":[{"id":"1.231282919","rc":[{"batb":[[0,1.92,40.17],[1,1.43,116.28],[2,1.38,131.58]],"ltp":2.12,"tv":749.63,"id":31375}]}]}
{"op":"mcm","clk":"11746934369","pt":1722457131988,"mc":[{"id":"1.231282919","rc":[{"batb":[[0,1.93,10],[1,1.92,40.17],[2,1.43,116.28]],"ltp":2.12,"tv":749.63,"id":31375}]}]}
{"op":"mcm","clk":"11746934740","pt":1722457135157,"mc":[{"id":"1.231282919","rc":[{"batb":[[0,1.92,40.17],[1,1.43,116.28],[2,1.38,131.58]],"ltp":2.12,"tv":749.63,"id":31375}]}]}
{"op":"mcm","clk":"11746939217","pt":1722457172227,"mc":[{"id":"1.231282919","rc":[{"batb":[[0,1.93,10],[1,1.92,40.17],[2,1.43,116.28]],"ltp":2.12,"tv":749.63,"id":31375}]}]}
{"op":"mcm","clk":"11746939647","pt":1722457175811,"mc":[{"id":"1.231282919","rc":[{"batb":[[0,1.92,40.17],[1,1.43,116.28],[2,1.38,131.58]],"ltp":2.12,"tv":749.63,"id":31375}]}]}
{"op":"mcm","clk":"11746941829","pt":1722457195480,"mc":[{"id":"1.231282919","rc":[{"batb":[[0,1.93,10],[1,1.92,40.17],[2,1.43,116.28]],"ltp":2.12,"tv":749.63,"id":31375}]}]}
{"op":"mcm","clk":"11746942177","pt":1722457199057,"mc":[{"id":"1.231282919","rc":[{"batb":[[0,1.92,40.17],[1,1.43,116.28],[2,1.38,131.58]],"ltp":2.12,"tv":749.63,"id":31375}]}]}
{"op":"mcm","clk":"11746953358","pt":1722457298596,"mc":[{"id":"1.231282919","rc":[{"batb":[[0,1.93,10],[1,1.92,40.17],[2,1.43,116.28]],"ltp":2.12,"tv":749.63,"id":31375}]}]}
{"op":"mcm","clk":"11746953779","pt":1722457302029,"mc":[{"id":"1.231282919","rc":[{"batb":[[0,1.92,40.17],[1,1.43,116.28],[2,1.38,131.58]],"ltp":2.12,"tv":749.63,"id":31375}]}]}
{"op":"mcm","clk":"11746954962","pt":1722457311633,"mc":[{"id":"1.231282919","rc":[{"batb":[[0,1.93,10],[1,1.92,40.17],[2,1.43,116.28]],"ltp":2.12,"tv":749.63,"id":31375}]}]}
{"op":"mcm","clk":"11746955361","pt":1722457315230,"mc":[{"id":"1.231282919","rc":[{"batb":[[0,1.92,40.17],[1,1.43,116.28],[2,1.38,131.58]],"ltp":2.12,"tv":749.63,"id":31375}]}]}
{"op":"mcm","clk":"11746990957","pt":1722457663313,"mc":[{"id":"1.231282919","rc":[{"batb":[[0,1.93,10],[1,1.92,40.17],[2,1.43,116.28]],"ltp":2.12,"tv":749.63,"id":31375}]}]}
{"op":"mcm","clk":"11746991225","pt":1722457666628,"mc":[{"id":"1.231282919","rc":[{"batb":[[0,1.92,40.17],[1,1.43,116.28],[2,1.38,131.58]],"ltp":2.12,"tv":749.63,"id":31375}]}]}
{"op":"mcm","clk":"11747006225","pt":1722457838392,"mc":[{"id":"1.231282919","rc":[{"batb":[[0,1.93,10],[1,1.92,40.17],[2,1.43,116.28]],"ltp":2.12,"tv":749.63,"id":31375}]}]}
{"op":"mcm","clk":"11747006493","pt":1722457841794,"mc":[{"id":"1.231282919","rc":[{"batb":[[0,1.92,40.17],[1,1.43,116.28],[2,1.38,131.58]],"ltp":2.12,"tv":749.63,"id":31375}]}]}
{"op":"mcm","clk":"11747008467","pt":1722457864967,"mc":[{"id":"1.231282919","rc":[{"batb":[[0,1.93,10],[1,1.92,40.17],[2,1.43,116.28]],"ltp":2.12,"tv":749.63,"id":31375}]}]}
{"op":"mcm","clk":"11747008770","pt":1722457868237,"mc":[{"id":"1.231282919","rc":[{"batb":[[0,1.92,40.17],[1,1.43,116.28],[2,1.38,131.58]],"ltp":2.12,"tv":749.63,"id":31375}]}]}
{"op":"mcm","clk":"11747018847","pt":1722457991954,"mc":[{"id":"1.231282919","rc":[{"batb":[[0,1.93,10],[1,1.92,40.17],[2,1.43,116.28]],"ltp":2.12,"tv":749.63,"id":31375}]}]}
{"op":"mcm","clk":"11747019137","pt":1722457995372,"mc":[{"id":"1.231282919","rc":[{"batb":[[0,1.92,40.17],[1,1.43,116.28],[2,1.38,131.58]],"ltp":2.12,"tv":749.63,"id":31375}]}]}
{"op":"mcm","clk":"11747024120","pt":1722458052657,"mc":[{"id":"1.231282919","rc":[{"batb":[[0,1.93,10],[1,1.92,40.17],[2,1.43,116.28]],"ltp":2.12,"tv":749.63,"id":31375}]}]}
{"op":"mcm","clk":"11747024607","pt":1722458058049,"mc":[{"id":"1.231282919","rc":[{"batb":[[0,1.92,40.17],[1,1.43,116.28],[2,1.38,131.58]],"ltp":2.12,"tv":749.63,"id":31375}]}]}
{"op":"mcm","clk":"11747034799","pt":1722458175684,"mc":[{"id":"1.231282919","rc":[{"batb":[[0,1.93,10],[1,1.92,40.17],[2,1.43,116.28]],"ltp":2.12,"tv":749.63,"id":31375}]}]}
{"op":"mcm","clk":"11747035091","pt":1722458179100,"mc":[{"id":"1.231282919","rc":[{"batb":[[0,1.92,40.17],[1,1.43,116.28],[2,1.38,131.58]],"ltp":2.12,"tv":749.63,"id":31375}]}]}
{"op":"mcm","clk":"11747038498","pt":1722458221718,"mc":[{"id":"1.231282919","rc":[{"batb":[[0,1.93,10],[1,1.92,40.17],[2,1.43,116.28]],"ltp":2.12,"tv":749.63,"id":31375}]}]}
{"op":"mcm","clk":"11747038853","pt":1722458225516,"mc":[{"id":"1.231282919","rc":[{"batb":[[0,1.92,40.17],[1,1.43,116.28],[2,1.38,131.58]],"ltp":2.12,"tv":749.63,"id":31375}]}]}
{"op":"mcm","clk":"11747040124","pt":1722458239931,"mc":[{"id":"1.231282919","rc":[{"batb":[[0,1.93,10],[1,1.92,40.17],[2,1.43,116.28]],"ltp":2.12,"tv":749.63,"id":31375}]}]}
{"op":"mcm","clk":"11747040393","pt":1722458243539,"mc":[{"id":"1.231282919","rc":[{"batb":[[0,1.92,40.17],[1,1.43,116.28],[2,1.38,131.58]],"ltp":2.12,"tv":749.63,"id":31375}]}]}
{"op":"mcm","clk":"11747043627","pt":1722458281483,"mc":[{"id":"1.231282919","rc":[{"batb":[[0,1.93,10],[1,1.92,40.17],[2,1.43,116.28]],"ltp":2.12,"tv":749.63,"id":31375}]}]}
{"op":"mcm","clk":"11747043941","pt":1722458285197,"mc":[{"id":"1.231282919","rc":[{"batb":[[0,1.92,40.17],[1,1.43,116.28],[2,1.38,131.58]],"ltp":2.12,"tv":749.63,"id":31375}]}]}
{"op":"mcm","clk":"11747044364","pt":1722458290254,"mc":[{"id":"1.231282919","rc":[{"trd":[[1.89,706.13]],"batl":[[0,1.89,29.81]],"ltp":1.89,"tv":2374.26,"id":31372},{"batb":[[0,1.93,10],[1,1.92,40.17],[2,1.43,116.28]],"ltp":2.12,"tv":749.63,"id":31375}],"tv":3123.89}]}
{"op":"mcm","clk":"11747044622","pt":1722458293601,"mc":[{"id":"1.231282919","rc":[{"batb":[[0,1.92,40.17],[1,1.43,116.28],[2,1.38,131.58]],"ltp":2.12,"tv":749.63,"id":31375}]}]}
{"op":"mcm","clk":"11747045786","pt":1722458308108,"mc":[{"id":"1.231282919","rc":[{"batb":[[0,1.93,10],[1,1.92,40.17],[2,1.43,116.28]],"ltp":2.12,"tv":749.63,"id":31375}]}]}
{"op":"mcm","clk":"11747046076","pt":1722458311618,"mc":[{"id":"1.231282919","rc":[{"batb":[[0,1.92,40.17],[1,1.43,116.28],[2,1.38,131.58]],"ltp":2.12,"tv":749.63,"id":31375}]}]}
{"op":"mcm","clk":"11747047304","pt":1722458326321,"mc":[{"id":"1.231282919","rc":[{"batb":[[0,1.93,10],[1,1.92,40.17],[2,1.43,116.28]],"ltp":2.12,"tv":749.63,"id":31375}]}]}
{"op":"mcm","clk":"11747047592","pt":1722458329920,"mc":[{"id":"1.231282919","rc":[{"batb":[[0,1.92,40.17],[1,1.43,116.28],[2,1.38,131.58]],"ltp":2.12,"tv":749.63,"id":31375}]}]}
{"op":"mcm","clk":"11747047862","pt":1722458333009,"mc":[{"id":"1.231282919","rc":[{"batb":[[0,1.93,10],[1,1.92,40.17],[2,1.43,116.28]],"ltp":2.12,"tv":749.63,"id":31375}]}]}
{"op":"mcm","clk":"11747048150","pt":1722458336514,"mc":[{"id":"1.231282919","rc":[{"batb":[[0,1.92,40.17],[1,1.43,116.28],[2,1.38,131.58]],"ltp":2.12,"tv":749.63,"id":31375}]}]}
{"op":"mcm","clk":"11747048730","pt":1722458344016,"mc":[{"id":"1.231282919","rc":[{"batb":[[0,1.93,10],[1,1.92,40.17],[2,1.43,116.28]],"ltp":2.12,"tv":749.63,"id":31375}]}]}
{"op":"mcm","clk":"11747049024","pt":1722458347628,"mc":[{"id":"1.231282919","rc":[{"batb":[[0,1.92,40.17],[1,1.43,116.28],[2,1.38,131.58]],"ltp":2.12,"tv":749.63,"id":31375}]}]}
{"op":"mcm","clk":"11747051226","pt":1722458372850,"mc":[{"id":"1.231282919","rc":[{"batb":[[0,1.93,10],[1,1.92,40.17],[2,1.43,116.28]],"ltp":2.12,"tv":749.63,"id":31375}]}]}
{"op":"mcm","clk":"11747051519","pt":1722458376360,"mc":[{"id":"1.231282919","rc":[{"batb":[[0,1.92,40.17],[1,1.43,116.28],[2,1.38,131.58]],"ltp":2.12,"tv":749.63,"id":31375}]}]}
{"op":"mcm","clk":"11747053622","pt":1722458402626,"mc":[{"id":"1.231282919","rc":[{"batb":[[0,1.93,10],[1,1.92,40.17],[2,1.43,116.28]],"ltp":2.12,"tv":749.63,"id":31375}]}]}
{"op":"mcm","clk":"11747053927","pt":1722458406094,"mc":[{"id":"1.231282919","rc":[{"batb":[[0,1.92,40.17],[1,1.43,116.28],[2,1.38,131.58]],"ltp":2.12,"tv":749.63,"id":31375}]}]}
{"op":"mcm","clk":"11747054266","pt":1722458410105,"mc":[{"id":"1.231282919","rc":[{"batb":[[0,1.93,10],[1,1.92,40.17],[2,1.43,116.28]],"ltp":2.12,"tv":749.63,"id":31375}]}]}
{"op":"mcm","clk":"11747054525","pt":1722458413715,"mc":[{"id":"1.231282919","rc":[{"batb":[[0,1.92,40.17],[1,1.43,116.28],[2,1.38,131.58]],"ltp":2.12,"tv":749.63,"id":31375}]}]}
{"op":"mcm","clk":"11747055690","pt":1722458428844,"mc":[{"id":"1.231282919","rc":[{"batb":[[0,1.93,10],[1,1.92,40.17],[2,1.43,116.28]],"ltp":2.12,"tv":749.63,"id":31375}]}]}
{"op":"mcm","clk":"11747055927","pt":1722458432243,"mc":[{"id":"1.231282919","rc":[{"batb":[[0,1.92,40.17],[1,1.43,116.28],[2,1.38,131.58]],"ltp":2.12,"tv":749.63,"id":31375}]}]}
{"op":"mcm","clk":"11747056159","pt":1722458434827,"mc":[{"id":"1.231282919","rc":[{"batb":[[0,1.93,10],[1,1.92,40.17],[2,1.43,116.28]],"ltp":2.12,"tv":749.63,"id":31375}]}]}
{"op":"mcm","clk":"11747056450","pt":1722458438305,"mc":[{"id":"1.231282919","rc":[{"batb":[[0,1.92,40.17],[1,1.43,116.28],[2,1.38,131.58]],"ltp":2.12,"tv":749.63,"id":31375}]}]}
{"op":"mcm","clk":"11747057146","pt":1722458446453,"mc":[{"id":"1.231282919","rc":[{"batb":[[0,1.93,10],[1,1.92,40.17],[2,1.43,116.28]],"ltp":2.12,"tv":749.63,"id":31375}]}]}
{"op":"mcm","clk":"11747057413","pt":1722458449914,"mc":[{"id":"1.231282919","rc":[{"batb":[[0,1.92,40.17],[1,1.43,116.28],[2,1.38,131.58]],"ltp":2.12,"tv":749.63,"id":31375}]}]}
{"op":"mcm","clk":"11747059688","pt":1722458476259,"mc":[{"id":"1.231282919","rc":[{"batb":[[0,1.93,10],[1,1.92,40.17],[2,1.43,116.28]],"ltp":2.12,"tv":749.63,"id":31375}]}]}
{"op":"mcm","clk":"11747059960","pt":1722458479664,"mc":[{"id":"1.231282919","rc":[{"batb":[[0,1.92,40.17],[1,1.43,116.28],[2,1.38,131.58]],"ltp":2.12,"tv":749.63,"id":31375}]}]}
{"op":"mcm","clk":"11747060461","pt":1722458486064,"mc":[{"id":"1.231282919","rc":[{"batb":[[0,1.93,10],[1,1.92,40.17],[2,1.43,116.28]],"ltp":2.12,"tv":749.63,"id":31375}]}]}
{"op":"mcm","clk":"11747060787","pt":1722458489672,"mc":[{"id":"1.231282919","rc":[{"batb":[[0,1.92,40.17],[1,1.43,116.28],[2,1.38,131.58]],"ltp":2.12,"tv":749.63,"id":31375}]}]}
{"op":"mcm","clk":"11747061365","pt":1722458496596,"mc":[{"id":"1.231282919","rc":[{"batb":[[0,1.93,10],[1,1.92,40.17],[2,1.43,116.28]],"ltp":2.12,"tv":749.63,"id":31375}]}]}
{"op":"mcm","clk":"11747061669","pt":1722458500013,"mc":[{"id":"1.231282919","rc":[{"batb":[[0,1.92,40.17],[1,1.43,116.28],[2,1.38,131.58]],"ltp":2.12,"tv":749.63,"id":31375}]}]}
{"op":"mcm","clk":"11747089408","pt":1722458748399,"mc":[{"id":"1.231282919","rc":[{"trd":[[1.89,727.53]],"batl":[[0,1.89,19.11]],"ltp":1.89,"tv":2395.66,"id":31372},{"batb":[[0,1.93,10],[1,1.92,40.17],[2,1.43,116.28]],"ltp":2.12,"tv":749.63,"id":31375}],"tv":3145.29}]}
{"op":"mcm","clk":"11747089618","pt":1722458751711,"mc":[{"id":"1.231282919","rc":[{"batb":[[0,1.92,40.17],[1,1.43,116.28],[2,1.38,131.58]],"ltp":2.12,"tv":749.63,"id":31375}]}]}
{"op":"mcm","clk":"11747105366","pt":1722458967858,"mc":[{"id":"1.231282919","rc":[{"batb":[[0,1.93,10],[1,1.92,40.17],[2,1.43,116.28]],"ltp":2.12,"tv":749.63,"id":31375}]}]}
{"op":"mcm","clk":"11747105608","pt":1722458971255,"mc":[{"id":"1.231282919","rc":[{"batb":[[0,1.92,40.17],[1,1.43,116.28],[2,1.38,131.58]],"ltp":2.12,"tv":749.63,"id":31375}]}]}
{"op":"mcm","clk":"11747112658","pt":1722459071399,"mc":[{"id":"1.231282919","rc":[{"batb":[[0,1.93,10],[1,1.92,40.17],[2,1.43,116.28]],"ltp":2.12,"tv":749.63,"id":31375}]}]}
{"op":"mcm","clk":"11747112911","pt":1722459074896,"mc":[{"id":"1.231282919","rc":[{"batb":[[0,1.92,40.17],[1,1.43,116.28],[2,1.38,131.58]],"ltp":2.12,"tv":749.63,"id":31375}]}]}
{"op":"mcm","clk":"11747114383","pt":1722459094707,"mc":[{"id":"1.231282919","rc":[{"batb":[[0,1.93,10],[1,1.92,40.17],[2,1.43,116.28]],"ltp":2.12,"tv":749.63,"id":31375}]}]}
{"op":"mcm","clk":"11747114640","pt":1722459098303,"mc":[{"id":"1.231282919","rc":[{"batb":[[0,1.92,40.17],[1,1.43,116.28],[2,1.38,131.58]],"ltp":2.12,"tv":749.63,"id":31375}]}]}
{"op":"mcm","clk":"11747114831","pt":1722459101532,"mc":[{"id":"1.231282919","rc":[{"batb":[[0,1.93,10],[1,1.92,40.17],[2,1.43,116.28]],"ltp":2.12,"tv":749.63,"id":31375}]}]}
{"op":"mcm","clk":"11747115072","pt":1722459104924,"mc":[{"id":"1.231282919","rc":[{"batb":[[0,1.92,40.17],[1,1.43,116.28],[2,1.38,131.58]],"ltp":2.12,"tv":749.63,"id":31375}]}]}
{"op":"mcm","clk":"11747115254","pt":1722459107908,"mc":[{"id":"1.231282919","rc":[{"batb":[[0,1.93,10],[1,1.92,40.17],[2,1.43,116.28]],"ltp":2.12,"tv":749.63,"id":31375}]}]}
{"op":"mcm","clk":"11747115447","pt":1722459111348,"mc":[{"id":"1.231282919","rc":[{"batb":[[0,1.92,40.17],[1,1.43,116.28],[2,1.38,131.58]],"ltp":2.12,"tv":749.63,"id":31375}]}]}
{"op":"mcm","clk":"11747115885","pt":1722459118433,"mc":[{"id":"1.231282919","rc":[{"batb":[[0,1.93,10],[1,1.92,40.17],[2,1.43,116.28]],"ltp":2.12,"tv":749.63,"id":31375}]}]}
{"op":"mcm","clk":"11747116096","pt":1722459122145,"mc":[{"id":"1.231282919","rc":[{"batb":[[0,1.92,40.17],[1,1.43,116.28],[2,1.38,131.58]],"ltp":2.12,"tv":749.63,"id":31375}]}]}
{"op":"mcm","clk":"11747116477","pt":1722459129266,"mc":[{"id":"1.231282919","rc":[{"batb":[[0,1.93,10],[1,1.92,40.17],[2,1.43,116.28]],"ltp":2.12,"tv":749.63,"id":31375}]}]}
{"op":"mcm","clk":"11747116685","pt":1722459132553,"mc":[{"id":"1.231282919","rc":[{"batb":[[0,1.92,40.17],[1,1.43,116.28],[2,1.38,131.58]],"ltp":2.12,"tv":749.63,"id":31375}]}]}
{"op":"mcm","clk":"11747117211","pt":1722459141384,"mc":[{"id":"1.231282919","rc":[{"batb":[[0,1.93,10],[1,1.92,40.17],[2,1.43,116.28]],"ltp":2.12,"tv":749.63,"id":31375}]}]}
{"op":"mcm","clk":"11747117398","pt":1722459144776,"mc":[{"id":"1.231282919","rc":[{"batb":[[0,1.92,40.17],[1,1.43,116.28],[2,1.38,131.58]],"ltp":2.12,"tv":749.63,"id":31375}]}]}
{"op":"mcm","clk":"11747119263","pt":1722459178227,"mc":[{"id":"1.231282919","rc":[{"batb":[[0,1.93,10],[1,1.92,40.17],[2,1.43,116.28]],"ltp":2.12,"tv":749.63,"id":31375}]}]}
{"op":"mcm","clk":"11747119436","pt":1722459181820,"mc":[{"id":"1.231282919","rc":[{"batb":[[0,1.92,40.17],[1,1.43,116.28],[2,1.38,131.58]],"ltp":2.12,"tv":749.63,"id":31375}]}]}
{"op":"mcm","clk":"11747119890","pt":1722459190032,"mc":[{"id":"1.231282919","rc":[{"batb":[[0,1.93,10],[1,1.92,40.17],[2,1.43,116.28]],"ltp":2.12,"tv":749.63,"id":31375}]}]}
{"op":"mcm","clk":"11747120092","pt":1722459193424,"mc":[{"id":"1.231282919","rc":[{"batb":[[0,1.92,40.17],[1,1.43,116.28],[2,1.38,131.58]],"ltp":2.12,"tv":749.63,"id":31375}]}]}
{"op":"mcm","clk":"11747120230","pt":1722459196715,"mc":[{"id":"1.231282919","rc":[{"batb":[[0,1.93,10],[1,1.92,40.17],[2,1.43,116.28]],"ltp":2.12,"tv":749.63,"id":31375}]}]}
{"op":"mcm","clk":"11747120394","pt":1722459200023,"mc":[{"id":"1.231282919","rc":[{"batb":[[0,1.92,40.17],[1,1.43,116.28],[2,1.38,131.58]],"ltp":2.12,"tv":749.63,"id":31375}]}]}
{"op":"mcm","clk":"11747121125","pt":1722459214131,"mc":[{"id":"1.231282919","rc":[{"batb":[[0,1.93,10],[1,1.92,40.17],[2,1.43,116.28]],"ltp":2.12,"tv":749.63,"id":31375}]}]}
{"op":"mcm","clk":"11747121331","pt":1722459217565,"mc":[{"id":"1.231282919","rc":[{"batb":[[0,1.92,40.17],[1,1.43,116.28],[2,1.38,131.58]],"ltp":2.12,"tv":749.63,"id":31375}]}]}
{"op":"mcm","clk":"11747121557","pt":1722459221570,"mc":[{"id":"1.231282919","rc":[{"batb":[[0,1.93,10],[1,1.92,40.17],[2,1.43,116.28]],"ltp":2.12,"tv":749.63,"id":31375}]}]}
{"op":"mcm","clk":"11747121769","pt":1722459225062,"mc":[{"id":"1.231282919","rc":[{"batb":[[0,1.92,40.17],[1,1.43,116.28],[2,1.38,131.58]],"ltp":2.12,"tv":749.63,"id":31375}]}]}
{"op":"mcm","clk":"11747122475","pt":1722459236392,"mc":[{"id":"1.231282919","rc":[{"batb":[[0,1.93,10],[1,1.92,40.17],[2,1.43,116.28]],"ltp":2.12,"tv":749.63,"id":31375}]}]}
{"op":"mcm","clk":"11747122680","pt":1722459239682,"mc":[{"id":"1.231282919","rc":[{"batb":[[0,1.92,40.17],[1,1.43,116.28],[2,1.38,131.58]],"ltp":2.12,"tv":749.63,"id":31375}]}]}
{"op":"mcm","clk":"11747123431","pt":1722459250279,"mc":[{"id":"1.231282919","rc":[{"trd":[[1.89,758.81]],"batl":[[0,1.89,3.47]],"ltp":1.89,"tv":2426.94,"id":31372},{"batb":[[0,1.93,10],[1,1.92,40.17],[2,1.43,116.28]],"ltp":2.12,"tv":749.63,"id":31375}],"tv":3176.57}]}
{"op":"mcm","clk":"11747123664","pt":1722459253675,"mc":[{"id":"1.231282919","rc":[{"batb":[[0,1.92,40.17],[1,1.43,116.28],[2,1.38,131.58]],"ltp":2.12,"tv":749.63,"id":31375}]}]}
{"op":"mcm","clk":"11747124800","pt":1722459270429,"mc":[{"id":"1.231282919","rc":[{"batb":[[0,1.93,10],[1,1.92,40.17],[2,1.43,116.28]],"ltp":2.12,"tv":749.63,"id":31375}]}]}
{"op":"mcm","clk":"11747125021","pt":1722459273919,"mc":[{"id":"1.231282919","rc":[{"batb":[[0,1.92,40.17],[1,1.43,116.28],[2,1.38,131.58]],"ltp":2.12,"tv":749.63,"id":31375}]}]}
{"op":"mcm","clk":"11747125659","pt":1722459283723,"mc":[{"id":"1.231282919","rc":[{"batb":[[0,1.93,10],[1,1.92,40.17],[2,1.43,116.28]],"ltp":2.12,"tv":749.63,"id":31375}]}]}
{"op":"mcm","clk":"11747125914","pt":1722459287314,"mc":[{"id":"1.231282919","rc":[{"batb":[[0,1.92,40.17],[1,1.43,116.28],[2,1.38,131.58]],"ltp":2.12,"tv":749.63,"id":31375}]}]}
{"op":"mcm","clk":"11747126652","pt":1722459299432,"mc":[{"id":"1.231282919","rc":[{"batb":[[0,1.93,10],[1,1.92,40.17],[2,1.43,116.28]],"ltp":2.12,"tv":749.63,"id":31375}]}]}
{"op":"mcm","clk":"11747126860","pt":1722459302866,"mc":[{"id":"1.231282919","rc":[{"batb":[[0,1.92,40.17],[1,1.43,116.28],[2,1.38,131.58]],"ltp":2.12,"tv":749.63,"id":31375}]}]}
{"op":"mcm","clk":"11747127911","pt":1722459318786,"mc":[{"id":"1.231282919","rc":[{"batb":[[0,1.93,10],[1,1.92,40.17],[2,1.43,116.28]],"ltp":2.12,"tv":749.63,"id":31375}]}]}
{"op":"mcm","clk":"11747128117","pt":1722459322270,"mc":[{"id":"1.231282919","rc":[{"batb":[[0,1.92,40.17],[1,1.43,116.28],[2,1.38,131.58]],"ltp":2.12,"tv":749.63,"id":31375}]}]}
{"op":"mcm","clk":"11747128389","pt":1722459326986,"mc":[{"id":"1.231282919","rc":[{"batb":[[0,1.93,10],[1,1.92,40.17],[2,1.43,116.28]],"ltp":2.12,"tv":749.63,"id":31375}]}]}
{"op":"mcm","clk":"11747128693","pt":1722459331768,"mc":[{"id":"1.231282919","rc":[{"batb":[[0,1.92,40.17],[1,1.43,116.28],[2,1.38,131.58]],"ltp":2.12,"tv":749.63,"id":31375}]}]}
{"op":"mcm","clk":"11747136899","pt":1722459463436,"mc":[{"id":"1.231282919","rc":[{"batb":[[0,1.93,10],[1,1.92,40.17],[2,1.43,116.28]],"batl":[[0,2.14,11.88]],"ltp":2.12,"tv":749.63,"id":31375}]}]}
{"op":"mcm","clk":"11747137122","pt":1722459466767,"mc":[{"id":"1.231282919","rc":[{"batb":[[0,1.92,40.17],[1,1.43,116.28],[2,1.38,131.58]],"ltp":2.12,"tv":749.63,"id":31375}]}]}
{"op":"mcm","clk":"11747137353","pt":1722459470266,"mc":[{"id":"1.231282919","rc":[{"batl":[[1,1.9,300],[2,1.95,261.1]],"ltp":1.89,"tv":2426.94,"id":31372},{"batb":[[0,1.93,10],[1,1.92,40.17],[2,1.43,116.28]],"ltp":2.12,"tv":749.63,"id":31375}]}]}
{"op":"mcm","clk":"11747137596","pt":1722459473647,"mc":[{"id":"1.231282919","rc":[{"batl":[[0,1.89,303.47]],"ltp":1.89,"tv":2426.94,"id":31372},{"batb":[[0,1.92,40.17],[1,1.43,116.28],[2,1.38,131.58]],"ltp":2.12,"tv":749.63,"id":31375}]}]}
{"op":"mcm","clk":"11747137699","pt":1722459475131,"mc":[{"id":"1.231282919","rc":[{"batl":[[0,2.14,1.62]],"ltp":2.12,"tv":749.63,"id":31375}]}]}
{"op":"mcm","clk":"11747137784","pt":1722459476569,"mc":[{"id":"1.231282919","rc":[{"batl":[[0,1.88,400],[1,1.89,303.47],[2,1.9,300]],"ltp":1.89,"tv":2426.94,"id":31372}]}]}
{"op":"mcm","clk":"11747137816","pt":1722459476932,"mc":[{"id":"1.231282919","rc":[{"batb":[[0,1.87,25.03]],"ltp":1.89,"tv":2426.94,"id":31372},{"batb":[[0,1.93,10],[1,1.92,40.17],[2,1.43,116.28]],"ltp":2.12,"tv":749.63,"id":31375}]}]}
{"op":"mcm","clk":"11747137941","pt":1722459479138,"mc":[{"id":"1.231282919","rc":[{"trd":[[1.87,562.92]],"batb":[[0,1.79,11.87],[1,1.43,116.28],[2,1.38,131.58]],"batl":[[0,1.87,573.1],[1,1.88,400],[2,1.89,303.47]],"ltp":1.87,"tv":2478.87,"id":31372},{"trd":[[2.14,254.17]],"batl":[[0,2.16,105.33],[1,2.2,100],[2,2.2,0]],"ltp":2.14,"tv":751.25,"id":31375}],"tv":3230.13}]}
{"op":"mcm","clk":"11747138009","pt":1722459480373,"mc":[{"id":"1.231282919","rc":[{"batb":[[0,1.92,40.17],[1,1.43,116.28],[2,1.38,131.58]],"ltp":2.14,"tv":751.25,"id":31375}]}]}
{"op":"mcm","clk":"11747138178","pt":1722459483653,"mc":[{"id":"1.231282919","rc":[{"trd":[[1.86,147.49]],"batl":[[0,1.86,277.68],[1,1.87,573.1],[2,1.88,400]],"ltp":1.86,"tv":2601.19,"id":31372},{"trd":[[2.16,260.35]],"batl":[[0,2.2,100],[1,2.2,0]],"ltp":2.16,"tv":856.58,"id":31375}],"tv":3457.78}]}
{"op":"mcm","clk":"11747138250","pt":1722459484582,"mc":[{"id":"1.231282919","rc":[{"batb":[[0,1.84,5.3],[1,1.79,11.87],[2,1.43,116.28]],"ltp":1.86,"tv":2601.19,"id":31372},{"batb":[[0,1.93,10],[1,1.92,40.17],[2,1.43,116.28]],"ltp":2.16,"tv":856.58,"id":31375}]}]}
{"op":"mcm","clk":"11747138436","pt":1722459487661,"mc":[{"id":"1.231282919","rc":[{"batl":[[0,1.85,600],[1,1.86,277.68],[2,1.87,573.1]],"ltp":1.86,"tv":2601.19,"id":31372},{"batb":[[0,1.92,40.17],[1,1.43,116.28],[2,1.38,131.58]],"ltp":2.16,"tv":856.58,"id":31375}]}]}
{"op":"mcm","clk":"11747138453","pt":1722459487969,"mc":[{"id":"1.231282919","rc":[{"batb":[[0,1.79,11.87],[1,1.43,116.28],[2,1.38,131.58]],"ltp":1.86,"tv":2601.19,"id":31372}]}]}
{"op":"mcm","clk":"11747139937","pt":1722459513803,"mc":[{"id":"1.231282919","rc":[{"batb":[[0,1.93,10],[1,1.92,40.17],[2,1.43,116.28]],"ltp":2.16,"tv":856.58,"id":31375}]}]}
{"op":"mcm","clk":"11747140109","pt":1722459516984,"mc":[{"id":"1.231282919","rc":[{"batb":[[0,1.92,40.17],[1,1.43,116.28],[2,1.38,131.58]],"ltp":2.16,"tv":856.58,"id":31375}]}]}
{"op":"mcm","clk":"11747141827","pt":1722459547624,"mc":[{"id":"1.231282919","rc":[{"batb":[[0,1.93,10],[1,1.92,40.17],[2,1.43,116.28]],"ltp":2.16,"tv":856.58,"id":31375}]}]}
{"op":"mcm","clk":"11747142017","pt":1722459551157,"mc":[{"id":"1.231282919","rc":[{"batb":[[0,1.92,40.17],[1,1.43,116.28],[2,1.38,131.58]],"ltp":2.16,"tv":856.58,"id":31375}]}]}
{"op":"mcm","clk":"11747142222","pt":1722459555262,"mc":[{"id":"1.231282919","rc":[{"batb":[[0,1.93,10],[1,1.92,40.17],[2,1.43,116.28]],"ltp":2.16,"tv":856.58,"id":31375}]}]}
{"op":"mcm","clk":"11747142415","pt":1722459558769,"mc":[{"id":"1.231282919","rc":[{"batb":[[0,1.92,40.17],[1,1.43,116.28],[2,1.38,131.58]],"ltp":2.16,"tv":856.58,"id":31375}]}]}
{"op":"mcm","clk":"11747142794","pt":1722459566773,"mc":[{"id":"1.231282919","rc":[{"batb":[[0,1.93,10],[1,1.92,40.17],[2,1.43,116.28]],"ltp":2.16,"tv":856.58,"id":31375}]}]}
{"op":"mcm","clk":"11747142981","pt":1722459570160,"mc":[{"id":"1.231282919","rc":[{"batb":[[0,1.92,40.17],[1,1.43,116.28],[2,1.38,131.58]],"ltp":2.16,"tv":856.58,"id":31375}]}]}
{"op":"mcm","clk":"11747143336","pt":1722459576581,"mc":[{"id":"1.231282919","rc":[{"batb":[[0,1.93,10],[1,1.92,40.17],[2,1.43,116.28]],"ltp":2.16,"tv":856.58,"id":31375}]}]}
{"op":"mcm","clk":"11747143498","pt":1722459580169,"mc":[{"id":"1.231282919","rc":[{"batb":[[0,1.92,40.17],[1,1.43,116.28],[2,1.38,131.58]],"ltp":2.16,"tv":856.58,"id":31375}]}]}
{"op":"mcm","clk":"11747143656","pt":1722459583352,"mc":[{"id":"1.231282919","rc":[{"batb":[[0,1.93,10],[1,1.92,40.17],[2,1.43,116.28]],"ltp":2.16,"tv":856.58,"id":31375}]}]}
{"op":"mcm","clk":"11747143885","pt":1722459586998,"mc":[{"id":"1.231282919","rc":[{"batb":[[0,1.92,40.17],[1,1.43,116.28],[2,1.38,131.58]],"ltp":2.16,"tv":856.58,"id":31375}]}]}
{"op":"mcm","clk":"11747144176","pt":1722459592283,"mc":[{"id":"1.231282919","rc":[{"batb":[[0,1.93,10],[1,1.92,40.17],[2,1.43,116.28]],"ltp":2.16,"tv":856.58,"id":31375}]}]}
{"op":"mcm","clk":"11747144392","pt":1722459595772,"mc":[{"id":"1.231282919","rc":[{"batb":[[0,1.92,40.17],[1,1.43,116.28],[2,1.38,131.58]],"ltp":2.16,"tv":856.58,"id":31375}]}]}
{"op":"mcm","clk":"11747145954","pt":1722459619090,"mc":[{"id":"1.231282919","rc":[{"trd":[[1.78,5.1],[1.79,189.85],[1.82,169.9],[1.86,147.49],[1.87,562.93],[1.88,396.35],[1.94,8.42],[2,9.06]],"ltp":1.86,"tv":2601.26,"id":31372},{"trd":[[2.12,211.13],[2.14,254.17],[2.16,260.35]],"batb":[[0,1.93,10],[1,1.92,40.17],[2,1.43,116.28]],"ltp":2.16,"tv":856.59,"id":31375}],"tv":3457.86}]}
{"op":"mcm","clk":"11747146145","pt":1722459622737,"mc":[{"id":"1.231282919","rc":[{"batb":[[0,1.92,40.17],[1,1.43,116.28],[2,1.38,131.58]],"ltp":2.16,"tv":856.59,"id":31375}]}]}
{"op":"mcm","clk":"11747146449","pt":1722459628029,"mc":[{"id":"1.231282919","rc":[{"batb":[[0,1.93,10],[1,1.92,40.17],[2,1.43,116.28]],"ltp":2.16,"tv":856.59,"id":31375}]}]}
{"op":"mcm","clk":"11747146650","pt":1722459631639,"mc":[{"id":"1.231282919","rc":[{"batb":[[0,1.92,40.17],[1,1.43,116.28],[2,1.38,131.58]],"ltp":2.16,"tv":856.59,"id":31375}]}]}
{"op":"mcm","clk":"11747147016","pt":1722459637938,"mc":[{"id":"1.231282919","rc":[{"batb":[[0,1.93,10],[1,1.92,40.17],[2,1.43,116.28]],"ltp":2.16,"tv":856.59,"id":31375}]}]}
{"op":"mcm","clk":"11747147208","pt":1722459641552,"mc":[{"id":"1.231282919","rc":[{"batb":[[0,1.92,40.17],[1,1.43,116.28],[2,1.38,131.58]],"ltp":2.16,"tv":856.59,"id":31375}]}]}
{"op":"mcm","clk":"11747147649","pt":1722459648924,"mc":[{"id":"1.231282919","rc":[{"batb":[[0,1.93,10],[1,1.92,40.17],[2,1.43,116.28]],"ltp":2.16,"tv":856.59,"id":31375}]}]}
{"op":"mcm","clk":"11747147878","pt":1722459652531,"mc":[{"id":"1.231282919","rc":[{"batb":[[0,1.92,40.17],[1,1.43,116.28],[2,1.38,131.58]],"ltp":2.16,"tv":856.59,"id":31375}]}]}
{"op":"mcm","clk":"11747153797","pt":1722459753150,"mc":[{"id":"1.231282919","rc":[{"trd":[[1.85,537.16]],"batl":[[0,1.85,381.42]],"ltp":1.85,"tv":3038.42,"id":31372},{"batb":[[0,1.93,10],[1,1.92,40.17],[2,1.43,116.28]],"ltp":2.16,"tv":856.59,"id":31375}],"tv":3895.02}]}
{"op":"mcm","clk":"11747153982","pt":1722459756541,"mc":[{"id":"1.231282919","rc":[{"batb":[[0,1.92,40.17],[1,1.43,116.28],[2,1.38,131.58]],"ltp":2.16,"tv":856.59,"id":31375}]}]}
{"op":"mcm","clk":"11747155474","pt":1722459784676,"mc":[{"id":"1.231282919","rc":[{"batb":[[0,1.93,10],[1,1.92,40.17],[2,1.43,116.28]],"ltp":2.16,"tv":856.59,"id":31375}]}]}
{"op":"mcm","clk":"11747155648","pt":1722459788165,"mc":[{"id":"1.231282919","rc":[{"batb":[[0,1.92,40.17],[1,1.43,116.28],[2,1.38,131.58]],"ltp":2.16,"tv":856.59,"id":31375}]}]}
{"op":"mcm","clk":"11747156174","pt":1722459797090,"mc":[{"id":"1.231282919","rc":[{"batb":[[0,1.93,10],[1,1.92,40.17],[2,1.43,116.28]],"ltp":2.16,"tv":856.59,"id":31375}]}]}
{"op":"mcm","clk":"11747156381","pt":1722459800478,"mc":[{"id":"1.231282919","rc":[{"batb":[[0,1.92,40.17],[1,1.43,116.28],[2,1.38,131.58]],"ltp":2.16,"tv":856.59,"id":31375}]}]}
{"op":"mcm","clk":"11747156902","pt":1722459808896,"mc":[{"id":"1.231282919","rc":[{"batb":[[0,1.93,10],[1,1.92,40.17],[2,1.43,116.28]],"ltp":2.16,"tv":856.59,"id":31375}]}]}
{"op":"mcm","clk":"11747157104","pt":1722459812430,"mc":[{"id":"1.231282919","rc":[{"batb":[[0,1.92,40.17],[1,1.43,116.28],[2,1.38,131.58]],"ltp":2.16,"tv":856.59,"id":31375}]}]}
{"op":"mcm","clk":"11747158392","pt":1722459834428,"mc":[{"id":"1.231282919","rc":[{"batb":[[0,1.93,10],[1,1.92,40.17],[2,1.43,116.28]],"ltp":2.16,"tv":856.59,"id":31375}]}]}
{"op":"mcm","clk":"11747158571","pt":1722459837864,"mc":[{"id":"1.231282919","rc":[{"batb":[[0,1.92,40.17],[1,1.43,116.28],[2,1.38,131.58]],"ltp":2.16,"tv":856.59,"id":31375}]}]}
{"op":"mcm","clk":"11747158998","pt":1722459844953,"mc":[{"id":"1.231282919","rc":[{"batb":[[0,1.93,10],[1,1.92,40.17],[2,1.43,116.28]],"ltp":2.16,"tv":856.59,"id":31375}]}]}
{"op":"mcm","clk":"11747159215","pt":1722459848346,"mc":[{"id":"1.231282919","rc":[{"batb":[[0,1.92,40.17],[1,1.43,116.28],[2,1.38,131.58]],"ltp":2.16,"tv":856.59,"id":31375}]}]}
{"op":"mcm","clk":"11747159624","pt":1722459854974,"mc":[{"id":"1.231282919","rc":[{"batb":[[0,1.93,10],[1,1.92,40.17],[2,1.43,116.28]],"ltp":2.16,"tv":856.59,"id":31375}]}]}
{"op":"mcm","clk":"11747159826","pt":1722459858158,"mc":[{"id":"1.231282919","rc":[{"batb":[[0,1.92,40.17],[1,1.43,116.28],[2,1.38,131.58]],"ltp":2.16,"tv":856.59,"id":31375}]}]}
{"op":"mcm","clk":"11747161888","pt":1722459890471,"mc":[{"id":"1.231282919","rc":[{"batb":[[0,1.93,10],[1,1.92,40.17],[2,1.43,116.28]],"ltp":2.16,"tv":856.59,"id":31375}]}]}
{"op":"mcm","clk":"11747162128","pt":1722459893917,"mc":[{"id":"1.231282919","rc":[{"batb":[[0,1.92,40.17],[1,1.43,116.28],[2,1.38,131.58]],"ltp":2.16,"tv":856.59,"id":31375}]}]}
{"op":"mcm","clk":"11747172593","pt":1722460055657,"mc":[{"id":"1.231282919","rc":[{"batb":[[0,1.93,10],[1,1.92,40.17],[2,1.43,116.28]],"ltp":2.16,"tv":856.59,"id":31375}]}]}
{"op":"mcm","clk":"11747172812","pt":1722460059092,"mc":[{"id":"1.231282919","rc":[{"batb":[[0,1.92,40.17],[1,1.43,116.28],[2,1.38,131.58]],"ltp":2.16,"tv":856.59,"id":31375}]}]}
{"op":"mcm","clk":"11747173621","pt":1722460072893,"mc":[{"id":"1.231282919","rc":[{"batb":[[0,1.93,10],[1,1.92,40.17],[2,1.43,116.28]],"ltp":2.16,"tv":856.59,"id":31375}]}]}
{"op":"mcm","clk":"11747173862","pt":1722460076591,"mc":[{"id":"1.231282919","rc":[{"batb":[[0,1.92,40.17],[1,1.43,116.28],[2,1.38,131.58]],"ltp":2.16,"tv":856.59,"id":31375}]}]}
{"op":"mcm","clk":"11747175328","pt":1722460099204,"mc":[{"id":"1.231282919","rc":[{"trd":[[1.85,976]],"batl":[[0,1.85,162]],"ltp":1.85,"tv":3477.26,"id":31372},{"batb":[[0,1.93,10],[1,1.92,40.17],[2,1.43,116.28]],"ltp":2.16,"tv":856.59,"id":31375}],"tv":4333.86}]}
{"op":"mcm","clk":"11747175502","pt":1722460102442,"mc":[{"id":"1.231282919","rc":[{"batb":[[0,1.92,40.17],[1,1.43,116.28],[2,1.38,131.58]],"ltp":2.16,"tv":856.59,"id":31375}]}]}
{"op":"mcm","clk":"11747175870","pt":1722460109526,"mc":[{"id":"1.231282919","rc":[{"batb":[[0,1.93,10],[1,1.92,40.17],[2,1.43,116.28]],"ltp":2.16,"tv":856.59,"id":31375}]}]}
{"op":"mcm","clk":"11747176057","pt":1722460113063,"mc":[{"id":"1.231282919","rc":[{"batb":[[0,1.92,40.17],[1,1.43,116.28],[2,1.38,131.58]],"ltp":2.16,"tv":856.59,"id":31375}]}]}
{"op":"mcm","clk":"11747176229","pt":1722460116042,"mc":[{"id":"1.231282919","rc":[{"batb":[[0,1.93,10],[1,1.92,40.17],[2,1.43,116.28]],"ltp":2.16,"tv":856.59,"id":31375}]}]}
{"op":"mcm","clk":"11747176445","pt":1722460119632,"mc":[{"id":"1.231282919","rc":[{"batb":[[0,1.92,40.17],[1,1.43,116.28],[2,1.38,131.58]],"ltp":2.16,"tv":856.59,"id":31375}]}]}
{"op":"mcm","clk":"11747176880","pt":1722460126979,"mc":[{"id":"1.231282919","rc":[{"batb":[[0,1.93,10],[1,1.92,40.17],[2,1.43,116.28]],"ltp":2.16,"tv":856.59,"id":31375}]}]}
{"op":"mcm","clk":"11747177085","pt":1722460130369,"mc":[{"id":"1.231282919","rc":[{"batb":[[0,1.92,40.17],[1,1.43,116.28],[2,1.38,131.58]],"ltp":2.16,"tv":856.59,"id":31375}]}]}
{"op":"mcm","clk":"11747177451","pt":1722460137408,"mc":[{"id":"1.231282919","rc":[{"batb":[[0,1.93,10],[1,1.92,40.17],[2,1.43,116.28]],"ltp":2.16,"tv":856.59,"id":31375}]}]}
{"op":"mcm","clk":"11747177601","pt":1722460140993,"mc":[{"id":"1.231282919","rc":[{"batb":[[0,1.92,40.17],[1,1.43,116.28],[2,1.38,131.58]],"ltp":2.16,"tv":856.59,"id":31375}]}]}
{"op":"mcm","clk":"11747177727","pt":1722460143399,"mc":[{"id":"1.231282919","rc":[{"batb":[[0,1.93,10],[1,1.92,40.17],[2,1.43,116.28]],"ltp":2.16,"tv":856.59,"id":31375}]}]}
{"op":"mcm","clk":"11747177912","pt":1722460146886,"mc":[{"id":"1.231282919","rc":[{"batb":[[0,1.92,40.17],[1,1.43,116.28],[2,1.38,131.58]],"ltp":2.16,"tv":856.59,"id":31375}]}]}
{"op":"mcm","clk":"11747178102","pt":1722460150171,"mc":[{"id":"1.231282919","rc":[{"batb":[[0,1.93,10],[1,1.92,40.17],[2,1.43,116.28]],"ltp":2.16,"tv":856.59,"id":31375}]}]}
{"op":"mcm","clk":"11747178281","pt":1722460153606,"mc":[{"id":"1.231282919","rc":[{"batb":[[0,1.92,40.17],[1,1.43,116.28],[2,1.38,131.58]],"ltp":2.16,"tv":856.59,"id":31375}]}]}
{"op":"mcm","clk":"11747178410","pt":1722460156582,"mc":[{"id":"1.231282919","rc":[{"batb":[[0,1.93,10],[1,1.92,40.17],[2,1.43,116.28]],"ltp":2.16,"tv":856.59,"id":31375}]}]}
{"op":"mcm","clk":"11747178593","pt":1722460160124,"mc":[{"id":"1.231282919","rc":[{"batb":[[0,1.92,40.17],[1,1.43,116.28],[2,1.38,131.58]],"ltp":2.16,"tv":856.59,"id":31375}]}]}
{"op":"mcm","clk":"11747182078","pt":1722460223360,"mc":[{"id":"1.231282919","rc":[{"batb":[[0,1.93,10],[1,1.92,40.17],[2,1.43,116.28]],"ltp":2.16,"tv":856.59,"id":31375}]}]}
{"op":"mcm","clk":"11747182281","pt":1722460226968,"mc":[{"id":"1.231282919","rc":[{"batb":[[0,1.92,40.17],[1,1.43,116.28],[2,1.38,131.58]],"ltp":2.16,"tv":856.59,"id":31375}]}]}
{"op":"mcm","clk":"11747183327","pt":1722460247094,"mc":[{"id":"1.231282919","rc":[{"batb":[[0,1.93,10],[1,1.92,40.17],[2,1.43,116.28]],"ltp":2.16,"tv":856.59,"id":31375}]}]}
{"op":"mcm","clk":"11747183459","pt":1722460250530,"mc":[{"id":"1.231282919","rc":[{"batb":[[0,1.92,40.17],[1,1.43,116.28],[2,1.38,131.58]],"ltp":2.16,"tv":856.59,"id":31375}]}]}
{"op":"mcm","clk":"11747184253","pt":1722460265235,"mc":[{"id":"1.231282919","rc":[{"batb":[[0,1.93,10],[1,1.92,40.17],[2,1.43,116.28]],"ltp":2.16,"tv":856.59,"id":31375}]}]}
{"op":"mcm","clk":"11747184392","pt":1722460268625,"mc":[{"id":"1.231282919","rc":[{"batb":[[0,1.92,40.17],[1,1.43,116.28],[2,1.38,131.58]],"ltp":2.16,"tv":856.59,"id":31375}]}]}
{"op":"mcm","clk":"11747184905","pt":1722460278954,"mc":[{"id":"1.231282919","rc":[{"batb":[[0,1.93,10],[1,1.92,40.17],[2,1.43,116.28]],"ltp":2.16,"tv":856.59,"id":31375}]}]}
{"op":"mcm","clk":"11747185097","pt":1722460282550,"mc":[{"id":"1.231282919","rc":[{"batb":[[0,1.92,40.17],[1,1.43,116.28],[2,1.38,131.58]],"ltp":2.16,"tv":856.59,"id":31375}]}]}
{"op":"mcm","clk":"11747186503","pt":1722460309671,"mc":[{"id":"1.231282919","rc":[{"batb":[[0,1.93,10],[1,1.92,40.17],[2,1.43,116.28]],"ltp":2.16,"tv":856.59,"id":31375}]}]}
{"op":"mcm","clk":"11747186573","pt":1722460311413,"mc":[{"id":"1.231282919","rc":[{"trd":[[1.85,1019.34]],"batl":[[0,1.85,140.33]],"ltp":1.85,"tv":3520.6,"id":31372}],"tv":4377.2}]}
{"op":"mcm","clk":"11747186667","pt":1722460313407,"mc":[{"id":"1.231282919","rc":[{"batb":[[0,1.92,40.17],[1,1.43,116.28],[2,1.38,131.58]],"ltp":2.16,"tv":856.59,"id":31375}]}]}
{"op":"mcm","clk":"11747186820","pt":1722460316595,"mc":[{"id":"1.231282919","rc":[{"batb":[[0,1.93,10],[1,1.92,40.17],[2,1.43,116.28]],"ltp":2.16,"tv":856.59,"id":31375}]}]}
{"op":"mcm","clk":"11747187001","pt":1722460319980,"mc":[{"id":"1.231282919","rc":[{"batb":[[0,1.92,40.17],[1,1.43,116.28],[2,1.38,131.58]],"ltp":2.16,"tv":856.59,"id":31375}]}]}
{"op":"mcm","clk":"11747187672","pt":1722460331497,"mc":[{"id":"1.231282919","rc":[{"trd":[[1.85,1130.46]],"batl":[[0,1.85,84.77]],"ltp":1.85,"tv":3631.72,"id":31372}],"tv":4488.32}]}
{"op":"mcm","clk":"11747187719","pt":1722460332421,"mc":[{"id":"1.231282919","rc":[{"batb":[[0,1.93,10],[1,1.92,40.17],[2,1.43,116.28]],"ltp":2.16,"tv":856.59,"id":31375}]}]}
{"op":"mcm","clk":"11747187898","pt":1722460335809,"mc":[{"id":"1.231282919","rc":[{"batb":[[0,1.92,40.17],[1,1.43,116.28],[2,1.38,131.58]],"ltp":2.16,"tv":856.59,"id":31375}]}]}
{"op":"mcm","clk":"11747188079","pt":1722460339347,"mc":[{"id":"1.231282919","rc":[{"batb":[[0,1.93,10],[1,1.92,40.17],[2,1.43,116.28]],"ltp":2.16,"tv":856.59,"id":31375}]}]}
{"op":"mcm","clk":"11747188279","pt":1722460342739,"mc":[{"id":"1.231282919","rc":[{"batb":[[0,1.92,40.17],[1,1.43,116.28],[2,1.38,131.58]],"ltp":2.16,"tv":856.59,"id":31375}]}]}
{"op":"mcm","clk":"11747188479","pt":1722460346742,"mc":[{"id":"1.231282919","rc":[{"batb":[[0,1.93,10],[1,1.92,40.17],[2,1.43,116.28]],"ltp":2.16,"tv":856.59,"id":31375}]}]}
{"op":"mcm","clk":"11747188646","pt":1722460350124,"mc":[{"id":"1.231282919","rc":[{"batb":[[0,1.92,40.17],[1,1.43,116.28],[2,1.38,131.58]],"ltp":2.16,"tv":856.59,"id":31375}]}]}
{"op":"mcm","clk":"11747188838","pt":1722460353564,"mc":[{"id":"1.231282919","rc":[{"batb":[[0,1.93,10],[1,1.92,40.17],[2,1.43,116.28]],"ltp":2.16,"tv":856.59,"id":31375}]}]}
{"op":"mcm","clk":"11747189049","pt":1722460356843,"mc":[{"id":"1.231282919","rc":[{"batb":[[0,1.92,40.17],[1,1.43,116.28],[2,1.38,131.58]],"ltp":2.16,"tv":856.59,"id":31375}]}]}
{"op":"mcm","clk":"11747201843","pt":1722460594804,"mc":[{"id":"1.231282919","rc":[{"batb":[[0,1.93,10],[1,1.92,40.17],[2,1.43,116.28]],"ltp":2.16,"tv":856.59,"id":31375}]}]}
{"op":"mcm","clk":"11747202092","pt":1722460599169,"mc":[{"id":"1.231282919","rc":[{"batb":[[0,1.92,40.17],[1,1.43,116.28],[2,1.38,131.58]],"ltp":2.16,"tv":856.59,"id":31375}]}]}
{"op":"mcm","clk":"11747203710","pt":1722460628328,"mc":[{"id":"1.231282919","rc":[{"trd":[[1.85,1173.8]],"batl":[[0,1.85,63.1]],"ltp":1.85,"tv":3675.06,"id":31372},{"batb":[[0,1.93,10],[1,1.92,40.17],[2,1.43,116.28]],"ltp":2.16,"tv":856.59,"id":31375}],"tv":4531.66}]}
{"op":"mcm","clk":"11747203895","pt":1722460631821,"mc":[{"id":"1.231282919","rc":[{"batb":[[0,1.92,40.17],[1,1.43,116.28],[2,1.38,131.58]],"ltp":2.16,"tv":856.59,"id":31375}]}]}
{"op":"mcm","clk":"11747213018","pt":1722460796885,"mc":[{"id":"1.231282919","rc":[{"batb":[[0,1.93,10],[1,1.92,40.17],[2,1.43,116.28]],"ltp":2.16,"tv":856.59,"id":31375}]}]}
{"op":"mcm","clk":"11747213180","pt":1722460800263,"mc":[{"id":"1.231282919","rc":[{"batb":[[0,1.92,40.17],[1,1.43,116.28],[2,1.38,131.58]],"ltp":2.16,"tv":856.59,"id":31375}]}]}
{"op":"mcm","clk":"11747213448","pt":1722460805384,"mc":[{"id":"1.231282919","rc":[{"batb":[[0,1.93,10],[1,1.92,40.17],[2,1.43,116.28]],"ltp":2.16,"tv":856.59,"id":31375}]}]}
{"op":"mcm","clk":"11747213604","pt":1722460808767,"mc":[{"id":"1.231282919","rc":[{"batb":[[0,1.92,40.17],[1,1.43,116.28],[2,1.38,131.58]],"ltp":2.16,"tv":856.59,"id":31375}]}]}
{"op":"mcm","clk":"11747213843","pt":1722460814298,"mc":[{"id":"1.231282919","rc":[{"batb":[[0,1.93,10],[1,1.92,40.17],[2,1.43,116.28]],"ltp":2.16,"tv":856.59,"id":31375}]}]}
{"op":"mcm","clk":"11747213989","pt":1722460817579,"mc":[{"id":"1.231282919","rc":[{"batb":[[0,1.92,40.17],[1,1.43,116.28],[2,1.38,131.58]],"ltp":2.16,"tv":856.59,"id":31375}]}]}
{"op":"mcm","clk":"11747214481","pt":1722460827423,"mc":[{"id":"1.231282919","rc":[{"batb":[[0,1.93,10],[1,1.92,40.17],[2,1.43,116.28]],"ltp":2.16,"tv":856.59,"id":31375}]}]}
{"op":"mcm","clk":"11747214667","pt":1722460830694,"mc":[{"id":"1.231282919","rc":[{"batb":[[0,1.92,40.17],[1,1.43,116.28],[2,1.38,131.58]],"ltp":2.16,"tv":856.59,"id":31375}]}]}
{"op":"mcm","clk":"11747214825","pt":1722460833715,"mc":[{"id":"1.231282919","rc":[{"batb":[[0,1.93,10],[1,1.92,40.17],[2,1.43,116.28]],"ltp":2.16,"tv":856.59,"id":31375}]}]}
{"op":"mcm","clk":"11747215046","pt":1722460837612,"mc":[{"id":"1.231282919","rc":[{"batb":[[0,1.92,40.17],[1,1.43,116.28],[2,1.38,131.58]],"ltp":2.16,"tv":856.59,"id":31375}]}]}
{"op":"mcm","clk":"11747215311","pt":1722460843249,"mc":[{"id":"1.231282919","rc":[{"batb":[[0,1.93,10],[1,1.92,40.17],[2,1.43,116.28]],"ltp":2.16,"tv":856.59,"id":31375}]}]}
{"op":"mcm","clk":"11747215453","pt":1722460846731,"mc":[{"id":"1.231282919","rc":[{"batb":[[0,1.92,40.17],[1,1.43,116.28],[2,1.38,131.58]],"ltp":2.16,"tv":856.59,"id":31375}]}]}
{"op":"mcm","clk":"11747215893","pt":1722460854477,"mc":[{"id":"1.231282919","rc":[{"trd":[[1.85,1195.66]],"batl":[[0,1.85,52.17]],"ltp":1.85,"tv":3696.92,"id":31372},{"batb":[[0,1.93,10],[1,1.92,40.17],[2,1.43,116.28]],"ltp":2.16,"tv":856.59,"id":31375}],"tv":4553.52}]}
{"op":"mcm","clk":"11747216069","pt":1722460857757,"mc":[{"id":"1.231282919","rc":[{"batb":[[0,1.92,40.17],[1,1.43,116.28],[2,1.38,131.58]],"ltp":2.16,"tv":856.59,"id":31375}]}]}
{"op":"mcm","clk":"11747216429","pt":1722460864876,"mc":[{"id":"1.231282919","rc":[{"batb":[[0,1.93,10],[1,1.92,40.17],[2,1.43,116.28]],"ltp":2.16,"tv":856.59,"id":31375}]}]}
{"op":"mcm","clk":"11747216620","pt":1722460868159,"mc":[{"id":"1.231282919","rc":[{"batb":[[0,1.92,40.17],[1,1.43,116.28],[2,1.38,131.58]],"ltp":2.16,"tv":856.59,"id":31375}]}]}
{"op":"mcm","clk":"11747217316","pt":1722460880885,"mc":[{"id":"1.231282919","rc":[{"batb":[[0,1.93,10],[1,1.92,40.17],[2,1.43,116.28]],"ltp":2.16,"tv":856.59,"id":31375}]}]}
{"op":"mcm","clk":"11747217526","pt":1722460884384,"mc":[{"id":"1.231282919","rc":[{"batb":[[0,1.92,40.17],[1,1.43,116.28],[2,1.38,131.58]],"ltp":2.16,"tv":856.59,"id":31375}]}]}
{"op":"mcm","clk":"11747218372","pt":1722460900523,"mc":[{"id":"1.231282919","rc":[{"batb":[[0,1.93,10],[1,1.92,40.17],[2,1.43,116.28]],"ltp":2.16,"tv":856.59,"id":31375}]}]}
{"op":"mcm","clk":"11747218541","pt":1722460903800,"mc":[{"id":"1.231282919","rc":[{"batb":[[0,1.92,40.17],[1,1.43,116.28],[2,1.38,131.58]],"ltp":2.16,"tv":856.59,"id":31375}]}]}
{"op":"mcm","clk":"11747218980","pt":1722460912058,"mc":[{"id":"1.231282919","rc":[{"batb":[[0,1.93,10],[1,1.92,40.17],[2,1.43,116.28]],"ltp":2.16,"tv":856.59,"id":31375}]}]}
{"op":"mcm","clk":"11747219180","pt":1722460915342,"mc":[{"id":"1.231282919","rc":[{"batb":[[0,1.92,40.17],[1,1.43,116.28],[2,1.38,131.58]],"ltp":2.16,"tv":856.59,"id":31375}]}]}
{"op":"mcm","clk":"11747219497","pt":1722460920639,"mc":[{"id":"1.231282919","rc":[{"batb":[[0,1.93,10],[1,1.92,40.17],[2,1.43,116.28]],"ltp":2.16,"tv":856.59,"id":31375}]}]}
{"op":"mcm","clk":"11747219715","pt":1722460924075,"mc":[{"id":"1.231282919","rc":[{"batb":[[0,1.92,40.17],[1,1.43,116.28],[2,1.38,131.58]],"ltp":2.16,"tv":856.59,"id":31375}]}]}
{"op":"mcm","clk":"11747221896","pt":1722460960589,"mc":[{"id":"1.231282919","rc":[{"batb":[[0,1.93,10],[1,1.92,40.17],[2,1.43,116.28]],"ltp":2.16,"tv":856.59,"id":31375}]}]}
{"op":"mcm","clk":"11747222111","pt":1722460964127,"mc":[{"id":"1.231282919","rc":[{"batb":[[0,1.92,40.17],[1,1.43,116.28],[2,1.38,131.58]],"ltp":2.16,"tv":856.59,"id":31375}]}]}
{"op":"mcm","clk":"11747239514","pt":1722461253423,"mc":[{"id":"1.231282919","rc":[{"trd":[[1.85,1238.28]],"batl":[[0,1.85,30.86]],"ltp":1.85,"tv":3739.54,"id":31372},{"batb":[[0,1.93,10],[1,1.92,40.17],[2,1.43,116.28]],"ltp":2.16,"tv":856.59,"id":31375}],"tv":4596.14}]}
{"op":"mcm","clk":"11747239758","pt":1722461256754,"mc":[{"id":"1.231282919","rc":[{"batb":[[0,1.92,40.17],[1,1.43,116.28],[2,1.38,131.58]],"ltp":2.16,"tv":856.59,"id":31375}]}]}
{"op":"mcm","clk":"11747247962","pt":1722461395401,"mc":[{"id":"1.231282919","rc":[{"batb":[[0,1.93,10],[1,1.92,40.17],[2,1.43,116.28]],"ltp":2.16,"tv":856.59,"id":31375}]}]}
{"op":"mcm","clk":"11747248195","pt":1722461399091,"mc":[{"id":"1.231282919","rc":[{"batb":[[0,1.92,40.17],[1,1.43,116.28],[2,1.38,131.58]],"ltp":2.16,"tv":856.59,"id":31375}]}]}
{"op":"mcm","clk":"11747249094","pt":1722461413196,"mc":[{"id":"1.231282919","rc":[{"batb":[[0,1.93,10],[1,1.92,40.17],[2,1.43,116.28]],"ltp":2.16,"tv":856.59,"id":31375}]}]}
{"op":"mcm","clk":"11747249299","pt":1722461416529,"mc":[{"id":"1.231282919","rc":[{"batb":[[0,1.92,40.17],[1,1.43,116.28],[2,1.38,131.58]],"ltp":2.16,"tv":856.59,"id":31375}]}]}
{"op":"mcm","clk":"11747250913","pt":1722461440859,"mc":[{"id":"1.231282919","rc":[{"batb":[[0,1.93,10],[1,1.92,40.17],[2,1.43,116.28]],"ltp":2.16,"tv":856.59,"id":31375}]}]}
{"op":"mcm","clk":"11747251116","pt":1722461444351,"mc":[{"id":"1.231282919","rc":[{"batb":[[0,1.92,40.17],[1,1.43,116.28],[2,1.38,131.58]],"ltp":2.16,"tv":856.59,"id":31375}]}]}
{"op":"mcm","clk":"11747253230","pt":1722461479593,"mc":[{"id":"1.231282919","rc":[{"batb":[[0,1.93,10],[1,1.92,40.17],[2,1.43,116.28]],"ltp":2.16,"tv":856.59,"id":31375}]}]}
{"op":"mcm","clk":"11747253415","pt":1722461482906,"mc":[{"id":"1.231282919","rc":[{"batb":[[0,1.92,40.17],[1,1.43,116.28],[2,1.38,131.58]],"ltp":2.16,"tv":856.59,"id":31375}]}]}
{"op":"mcm","clk":"11747254443","pt":1722461500632,"mc":[{"id":"1.231282919","rc":[{"batb":[[0,1.93,10],[1,1.92,40.17],[2,1.43,116.28]],"ltp":2.16,"tv":856.59,"id":31375}]}]}
{"op":"mcm","clk":"11747254630","pt":1722461503815,"mc":[{"id":"1.231282919","rc":[{"batb":[[0,1.92,40.17],[1,1.43,116.28],[2,1.38,131.58]],"ltp":2.16,"tv":856.59,"id":31375}]}]}
{"op":"mcm","clk":"11747254787","pt":1722461506343,"mc":[{"id":"1.231282919","rc":[{"batb":[[0,1.93,10],[1,1.92,40.17],[2,1.43,116.28]],"ltp":2.16,"tv":856.59,"id":31375}]}]}
{"op":"mcm","clk":"11747255010","pt":1722461509745,"mc":[{"id":"1.231282919","rc":[{"batb":[[0,1.92,40.17],[1,1.43,116.28],[2,1.38,131.58]],"ltp":2.16,"tv":856.59,"id":31375}]}]}
{"op":"mcm","clk":"11747255219","pt":1722461513240,"mc":[{"id":"1.231282919","rc":[{"batb":[[0,1.93,10],[1,1.92,40.17],[2,1.43,116.28]],"ltp":2.16,"tv":856.59,"id":31375}]}]}
{"op":"mcm","clk":"11747255407","pt":1722461516528,"mc":[{"id":"1.231282919","rc":[{"batb":[[0,1.92,40.17],[1,1.43,116.28],[2,1.38,131.58]],"ltp":2.16,"tv":856.59,"id":31375}]}]}
{"op":"mcm","clk":"11747255763","pt":1722461522531,"mc":[{"id":"1.231282919","rc":[{"batb":[[0,1.93,10],[1,1.92,40.17],[2,1.43,116.28]],"ltp":2.16,"tv":856.59,"id":31375}]}]}
{"op":"mcm","clk":"11747255925","pt":1722461525968,"mc":[{"id":"1.231282919","rc":[{"batb":[[0,1.92,40.17],[1,1.43,116.28],[2,1.38,131.58]],"ltp":2.16,"tv":856.59,"id":31375}]}]}
{"op":"mcm","clk":"11747256224","pt":1722461531367,"mc":[{"id":"1.231282919","rc":[{"batb":[[0,1.93,10],[1,1.92,40.17],[2,1.43,116.28]],"ltp":2.16,"tv":856.59,"id":31375}]}]}
{"op":"mcm","clk":"11747256402","pt":1722461534756,"mc":[{"id":"1.231282919","rc":[{"batb":[[0,1.92,40.17],[1,1.43,116.28],[2,1.38,131.58]],"ltp":2.16,"tv":856.59,"id":31375}]}]}
{"op":"mcm","clk":"11747256915","pt":1722461544358,"mc":[{"id":"1.231282919","rc":[{"batb":[[0,1.93,10],[1,1.92,40.17],[2,1.43,116.28]],"ltp":2.16,"tv":856.59,"id":31375}]}]}
{"op":"mcm","clk":"11747257130","pt":1722461547803,"mc":[{"id":"1.231282919","rc":[{"batb":[[0,1.92,40.17],[1,1.43,116.28],[2,1.38,131.58]],"ltp":2.16,"tv":856.59,"id":31375}]}]}
{"op":"mcm","clk":"11747257341","pt":1722461551776,"mc":[{"id":"1.231282919","rc":[{"batb":[[0,1.93,10],[1,1.92,40.17],[2,1.43,116.28]],"ltp":2.16,"tv":856.59,"id":31375}]}]}
{"op":"mcm","clk":"11747257548","pt":1722461555211,"mc":[{"id":"1.231282919","rc":[{"batb":[[0,1.92,40.17],[1,1.43,116.28],[2,1.38,131.58]],"ltp":2.16,"tv":856.59,"id":31375}]}]}
{"op":"mcm","clk":"11747257891","pt":1722461562291,"mc":[{"id":"1.231282919","rc":[{"batb":[[0,1.93,10],[1,1.92,40.17],[2,1.43,116.28]],"ltp":2.16,"tv":856.59,"id":31375}]}]}
{"op":"mcm","clk":"11747258069","pt":1722461565796,"mc":[{"id":"1.231282919","rc":[{"batb":[[0,1.92,40.17],[1,1.43,116.28],[2,1.38,131.58]],"ltp":2.16,"tv":856.59,"id":31375}]}]}
{"op":"mcm","clk":"11747260158","pt":1722461607026,"mc":[{"id":"1.231282919","rc":[{"batb":[[0,1.93,10],[1,1.92,40.17],[2,1.43,116.28]],"ltp":2.16,"tv":856.59,"id":31375}]}]}
{"op":"mcm","clk":"11747260351","pt":1722461610429,"mc":[{"id":"1.231282919","rc":[{"batb":[[0,1.92,40.17],[1,1.43,116.28],[2,1.38,131.58]],"ltp":2.16,"tv":856.59,"id":31375}]}]}
{"op":"mcm","clk":"11747260479","pt":1722461612638,"mc":[{"id":"1.231282919","rc":[{"batb":[[0,1.93,10],[1,1.92,40.17],[2,1.43,116.28]],"ltp":2.16,"tv":856.59,"id":31375}]}]}
{"op":"mcm","clk":"11747260689","pt":1722461616038,"mc":[{"id":"1.231282919","rc":[{"batb":[[0,1.92,40.17],[1,1.43,116.28],[2,1.38,131.58]],"ltp":2.16,"tv":856.59,"id":31375}]}]}
{"op":"mcm","clk":"11747260918","pt":1722461620053,"mc":[{"id":"1.231282919","rc":[{"batb":[[0,1.93,10],[1,1.92,40.17],[2,1.43,116.28]],"ltp":2.16,"tv":856.59,"id":31375}]}]}
{"op":"mcm","clk":"11747261123","pt":1722461623558,"mc":[{"id":"1.231282919","rc":[{"batb":[[0,1.92,40.17],[1,1.43,116.28],[2,1.38,131.58]],"ltp":2.16,"tv":856.59,"id":31375}]}]}
{"op":"mcm","clk":"11747261341","pt":1722461627465,"mc":[{"id":"1.231282919","rc":[{"batb":[[0,1.93,10],[1,1.92,40.17],[2,1.43,116.28]],"ltp":2.16,"tv":856.59,"id":31375}]}]}
{"op":"mcm","clk":"11747261529","pt":1722461631070,"mc":[{"id":"1.231282919","rc":[{"batb":[[0,1.92,40.17],[1,1.43,116.28],[2,1.38,131.58]],"ltp":2.16,"tv":856.59,"id":31375}]}]}
{"op":"mcm","clk":"11747261803","pt":1722461636508,"mc":[{"id":"1.231282919","rc":[{"batb":[[0,1.93,10],[1,1.92,40.17],[2,1.43,116.28]],"ltp":2.16,"tv":856.59,"id":31375}]}]}
{"op":"mcm","clk":"11747261979","pt":1722461640102,"mc":[{"id":"1.231282919","rc":[{"batb":[[0,1.92,40.17],[1,1.43,116.28],[2,1.38,131.58]],"ltp":2.16,"tv":856.59,"id":31375}]}]}
{"op":"mcm","clk":"11747263255","pt":1722461664605,"mc":[{"id":"1.231282919","rc":[{"batb":[[0,1.93,10],[1,1.92,40.17],[2,1.43,116.28]],"ltp":2.16,"tv":856.59,"id":31375}]}]}
{"op":"mcm","clk":"11747263432","pt":1722461667935,"mc":[{"id":"1.231282919","rc":[{"batb":[[0,1.92,40.17],[1,1.43,116.28],[2,1.38,131.58]],"ltp":2.16,"tv":856.59,"id":31375}]}]}
{"op":"mcm","clk":"11747263585","pt":1722461670911,"mc":[{"id":"1.231282919","rc":[{"batb":[[0,1.93,10],[1,1.92,40.17],[2,1.43,116.28]],"ltp":2.16,"tv":856.59,"id":31375}]}]}
{"op":"mcm","clk":"11747263777","pt":1722461674098,"mc":[{"id":"1.231282919","rc":[{"batb":[[0,1.92,40.17],[1,1.43,116.28],[2,1.38,131.58]],"ltp":2.16,"tv":856.59,"id":31375}]}]}
{"op":"mcm","clk":"11747264003","pt":1722461677799,"mc":[{"id":"1.231282919","rc":[{"batb":[[0,1.93,10],[1,1.92,40.17],[2,1.43,116.28]],"ltp":2.16,"tv":856.59,"id":31375}]}]}
{"op":"mcm","clk":"11747264191","pt":1722461681240,"mc":[{"id":"1.231282919","rc":[{"batb":[[0,1.92,40.17],[1,1.43,116.28],[2,1.38,131.58]],"ltp":2.16,"tv":856.59,"id":31375}]}]}
{"op":"mcm","clk":"11747265425","pt":1722461702516,"mc":[{"id":"1.231282919","rc":[{"batb":[[0,1.93,10],[1,1.92,40.17],[2,1.43,116.28]],"ltp":2.16,"tv":856.59,"id":31375}]}]}
{"op":"mcm","clk":"11747265613","pt":1722461705954,"mc":[{"id":"1.231282919","rc":[{"batb":[[0,1.92,40.17],[1,1.43,116.28],[2,1.38,131.58]],"ltp":2.16,"tv":856.59,"id":31375}]}]}
{"op":"mcm","clk":"11747266933","pt":1722461728047,"mc":[{"id":"1.231282919","rc":[{"batb":[[0,1.93,10],[1,1.92,40.17],[2,1.43,116.28]],"ltp":2.16,"tv":856.59,"id":31375}]}]}
{"op":"mcm","clk":"11747267116","pt":1722461731439,"mc":[{"id":"1.231282919","rc":[{"batb":[[0,1.92,40.17],[1,1.43,116.28],[2,1.38,131.58]],"ltp":2.16,"tv":856.59,"id":31375}]}]}
{"op":"mcm","clk":"11747267446","pt":1722461736574,"mc":[{"id":"1.231282919","rc":[{"batb":[[0,2.08,10],[1,2.06,34.87],[2,1.43,116.28]],"ltp":2.16,"tv":856.59,"id":31375}]}]}
{"op":"mcm","clk":"11747267634","pt":1722461739861,"mc":[{"id":"1.231282919","rc":[{"batb":[[0,2.06,34.87],[1,1.43,116.28],[2,1.38,131.58]],"ltp":2.16,"tv":856.59,"id":31375}]}]}
{"op":"mcm","clk":"11747269653","pt":1722461773311,"mc":[{"id":"1.231282919","rc":[{"batb":[[0,2.08,10],[1,2.06,34.87],[2,1.43,116.28]],"ltp":2.16,"tv":856.59,"id":31375}]}]}
{"op":"mcm","clk":"11747269874","pt":1722461776607,"mc":[{"id":"1.231282919","rc":[{"batb":[[0,2.06,34.87],[1,1.43,116.28],[2,1.38,131.58]],"ltp":2.16,"tv":856.59,"id":31375}]}]}
{"op":"mcm","clk":"11747270377","pt":1722461784996,"mc":[{"id":"1.231282919","rc":[{"batb":[[0,2.08,10],[1,2.06,34.87],[2,1.43,116.28]],"ltp":2.16,"tv":856.59,"id":31375}]}]}
{"op":"mcm","clk":"11747270573","pt":1722461788400,"mc":[{"id":"1.231282919","rc":[{"batb":[[0,2.06,34.87],[1,1.43,116.28],[2,1.38,131.58]],"ltp":2.16,"tv":856.59,"id":31375}]}]}
{"op":"mcm","clk":"11747270898","pt":1722461793692,"mc":[{"id":"1.231282919","rc":[{"batb":[[0,2.08,10],[1,2.06,34.87],[2,1.43,116.28]],"ltp":2.16,"tv":856.59,"id":31375}]}]}
{"op":"mcm","clk":"11747271115","pt":1722461797094,"mc":[{"id":"1.231282919","rc":[{"batb":[[0,2.06,34.87],[1,1.43,116.28],[2,1.38,131.58]],"ltp":2.16,"tv":856.59,"id":31375}]}]}
{"op":"mcm","clk":"11747271450","pt":1722461803002,"mc":[{"id":"1.231282919","rc":[{"batb":[[0,2.08,10],[1,2.06,34.87],[2,1.43,116.28]],"ltp":2.16,"tv":856.59,"id":31375}]}]}
{"op":"mcm","clk":"11747271628","pt":1722461806496,"mc":[{"id":"1.231282919","rc":[{"batb":[[0,2.06,34.87],[1,1.43,116.28],[2,1.38,131.58]],"ltp":2.16,"tv":856.59,"id":31375}]}]}
{"op":"mcm","clk":"11747271805","pt":1722461809730,"mc":[{"id":"1.231282919","rc":[{"batb":[[0,2.08,10],[1,2.06,34.87],[2,1.43,116.28]],"ltp":2.16,"tv":856.59,"id":31375}]}]}
{"op":"mcm","clk":"11747272011","pt":1722461813121,"mc":[{"id":"1.231282919","rc":[{"batb":[[0,2.06,34.87],[1,1.43,116.28],[2,1.38,131.58]],"ltp":2.16,"tv":856.59,"id":31375}]}]}
{"op":"mcm","clk":"11747273144","pt":1722461832256,"mc":[{"id":"1.231282919","rc":[{"batb":[[0,2.08,10],[1,2.06,34.87],[2,1.43,116.28]],"ltp":2.16,"tv":856.59,"id":31375}]}]}
{"op":"mcm","clk":"11747273337","pt":1722461835748,"mc":[{"id":"1.231282919","rc":[{"batb":[[0,2.06,34.87],[1,1.43,116.28],[2,1.38,131.58]],"ltp":2.16,"tv":856.59,"id":31375}]}]}
{"op":"mcm","clk":"11747273786","pt":1722461844437,"mc":[{"id":"1.231282919","rc":[{"batb":[[0,2.08,10],[1,2.06,34.87],[2,1.43,116.28]],"ltp":2.16,"tv":856.59,"id":31375}]}]}
{"op":"mcm","clk":"11747273997","pt":1722461847867,"mc":[{"id":"1.231282919","rc":[{"batb":[[0,2.06,34.87],[1,1.43,116.28],[2,1.38,131.58]],"ltp":2.16,"tv":856.59,"id":31375}]}]}
{"op":"mcm","clk":"11747274348","pt":1722461853051,"mc":[{"id":"1.231282919","rc":[{"batb":[[0,2.08,10],[1,2.06,34.87],[2,1.43,116.28]],"ltp":2.16,"tv":856.59,"id":31375}]}]}
{"op":"mcm","clk":"11747274545","pt":1722461856489,"mc":[{"id":"1.231282919","rc":[{"batb":[[0,2.06,34.87],[1,1.43,116.28],[2,1.38,131.58]],"ltp":2.16,"tv":856.59,"id":31375}]}]}
{"op":"mcm","clk":"11747274950","pt":1722461863166,"mc":[{"id":"1.231282919","rc":[{"batb":[[0,2.08,10],[1,2.06,34.87],[2,1.43,116.28]],"ltp":2.16,"tv":856.59,"id":31375}]}]}
{"op":"mcm","clk":"11747275159","pt":1722461866679,"mc":[{"id":"1.231282919","rc":[{"batb":[[0,2.06,34.87],[1,1.43,116.28],[2,1.38,131.58]],"ltp":2.16,"tv":856.59,"id":31375}]}]}
{"op":"mcm","clk":"11747275532","pt":1722461872079,"mc":[{"id":"1.231282919","rc":[{"batb":[[0,2.08,10],[1,2.06,34.87],[2,1.43,116.28]],"ltp":2.16,"tv":856.59,"id":31375}]}]}
{"op":"mcm","clk":"11747275741","pt":1722461875513,"mc":[{"id":"1.231282919","rc":[{"batb":[[0,2.06,34.87],[1,1.43,116.28],[2,1.38,131.58]],"ltp":2.16,"tv":856.59,"id":31375}]}]}
{"op":"mcm","clk":"11747276227","pt":1722461883278,"mc":[{"id":"1.231282919","rc":[{"batb":[[0,2.08,10],[1,2.06,34.87],[2,1.43,116.28]],"ltp":2.16,"tv":856.59,"id":31375}]}]}
{"op":"mcm","clk":"11747276416","pt":1722461886676,"mc":[{"id":"1.231282919","rc":[{"batb":[[0,2.06,34.87],[1,1.43,116.28],[2,1.38,131.58]],"ltp":2.16,"tv":856.59,"id":31375}]}]}
{"op":"mcm","clk":"11747276717","pt":1722461891910,"mc":[{"id":"1.231282919","rc":[{"batb":[[0,2.08,10],[1,2.06,34.87],[2,1.43,116.28]],"ltp":2.16,"tv":856.59,"id":31375}]}]}
{"op":"mcm","clk":"11747276882","pt":1722461895303,"mc":[{"id":"1.231282919","rc":[{"batb":[[0,2.06,34.87],[1,1.43,116.28],[2,1.38,131.58]],"ltp":2.16,"tv":856.59,"id":31375}]}]}
{"op":"mcm","clk":"11747277380","pt":1722461904193,"mc":[{"id":"1.231282919","rc":[{"batb":[[0,2.08,10],[1,2.06,34.87],[2,1.43,116.28]],"ltp":2.16,"tv":856.59,"id":31375}]}]}
{"op":"mcm","clk":"11747277552","pt":1722461907534,"mc":[{"id":"1.231282919","rc":[{"batb":[[0,2.06,34.87],[1,1.43,116.28],[2,1.38,131.58]],"ltp":2.16,"tv":856.59,"id":31375}]}]}
{"op":"mcm","clk":"11747277966","pt":1722461915235,"mc":[{"id":"1.231282919","rc":[{"batb":[[0,2.08,10],[1,2.06,34.87],[2,1.43,116.28]],"ltp":2.16,"tv":856.59,"id":31375}]}]}
{"op":"mcm","clk":"11747278177","pt":1722461918523,"mc":[{"id":"1.231282919","rc":[{"batb":[[0,2.06,34.87],[1,1.43,116.28],[2,1.38,131.58]],"ltp":2.16,"tv":856.59,"id":31375}]}]}
{"op":"mcm","clk":"11747278645","pt":1722461927049,"mc":[{"id":"1.231282919","rc":[{"batb":[[0,2.08,10],[1,2.06,34.87],[2,1.43,116.28]],"ltp":2.16,"tv":856.59,"id":31375}]}]}
{"op":"mcm","clk":"11747278819","pt":1722461930229,"mc":[{"id":"1.231282919","rc":[{"batb":[[0,2.06,34.87],[1,1.43,116.28],[2,1.38,131.58]],"ltp":2.16,"tv":856.59,"id":31375}]}]}
{"op":"mcm","clk":"11747279358","pt":1722461938966,"mc":[{"id":"1.231282919","rc":[{"batb":[[0,2.08,10],[1,2.06,34.87],[2,1.43,116.28]],"ltp":2.16,"tv":856.59,"id":31375}]}]}
{"op":"mcm","clk":"11747279545","pt":1722461942463,"mc":[{"id":"1.231282919","rc":[{"batb":[[0,2.06,34.87],[1,1.43,116.28],[2,1.38,131.58]],"ltp":2.16,"tv":856.59,"id":31375}]}]}
{"op":"mcm","clk":"11747279771","pt":1722461945756,"mc":[{"id":"1.231282919","rc":[{"batb":[[0,2.08,10],[1,2.06,34.87],[2,1.43,116.28]],"ltp":2.16,"tv":856.59,"id":31375}]}]}
{"op":"mcm","clk":"11747279980","pt":1722461949194,"mc":[{"id":"1.231282919","rc":[{"batb":[[0,2.06,34.87],[1,1.43,116.28],[2,1.38,131.58]],"ltp":2.16,"tv":856.59,"id":31375}]}]}
{"op":"mcm","clk":"11747280231","pt":1722461953759,"mc":[{"id":"1.231282919","rc":[{"batb":[[0,2.08,10],[1,2.06,34.87],[2,1.43,116.28]],"ltp":2.16,"tv":856.59,"id":31375}]}]}
{"op":"mcm","clk":"11747280439","pt":1722461957195,"mc":[{"id":"1.231282919","rc":[{"batb":[[0,2.06,34.87],[1,1.43,116.28],[2,1.38,131.58]],"ltp":2.16,"tv":856.59,"id":31375}]}]}
{"op":"mcm","clk":"11747280551","pt":1722461959397,"mc":[{"id":"1.231282919","rc":[{"batb":[[0,2.08,10],[1,2.06,34.87],[2,1.43,116.28]],"ltp":2.16,"tv":856.59,"id":31375}]}]}
{"op":"mcm","clk":"11747280740","pt":1722461962788,"mc":[{"id":"1.231282919","rc":[{"batb":[[0,2.06,34.87],[1,1.43,116.28],[2,1.38,131.58]],"ltp":2.16,"tv":856.59,"id":31375}]}]}
{"op":"mcm","clk":"11747281591","pt":1722461978115,"mc":[{"id":"1.231282919","rc":[{"batb":[[0,2.08,10],[1,2.06,34.87],[2,1.43,116.28]],"ltp":2.16,"tv":856.59,"id":31375}]}]}
{"op":"mcm","clk":"11747281778","pt":1722461981507,"mc":[{"id":"1.231282919","rc":[{"batb":[[0,2.06,34.87],[1,1.43,116.28],[2,1.38,131.58]],"ltp":2.16,"tv":856.59,"id":31375}]}]}
{"op":"mcm","clk":"11747282077","pt":1722461986491,"mc":[{"id":"1.231282919","rc":[{"batb":[[0,2.08,10],[1,2.06,34.87],[2,1.43,116.28]],"ltp":2.16,"tv":856.59,"id":31375}]}]}
{"op":"mcm","clk":"11747282261","pt":1722461989928,"mc":[{"id":"1.231282919","rc":[{"batb":[[0,2.06,34.87],[1,1.43,116.28],[2,1.38,131.58]],"ltp":2.16,"tv":856.59,"id":31375}]}]}
{"op":"mcm","clk":"11747282457","pt":1722461993314,"mc":[{"id":"1.231282919","rc":[{"batb":[[0,2.08,10],[1,2.06,34.87],[2,1.43,116.28]],"ltp":2.16,"tv":856.59,"id":31375}]}]}
{"op":"mcm","clk":"11747282658","pt":1722461996810,"mc":[{"id":"1.231282919","rc":[{"batb":[[0,2.06,34.87],[1,1.43,116.28],[2,1.38,131.58]],"ltp":2.16,"tv":856.59,"id":31375}]}]}
{"op":"mcm","clk":"11747282828","pt":1722461999994,"mc":[{"id":"1.231282919","rc":[{"batb":[[0,2.08,10],[1,2.06,34.87],[2,1.43,116.28]],"ltp":2.16,"tv":856.59,"id":31375}]}]}
{"op":"mcm","clk":"11747283070","pt":1722462003538,"mc":[{"id":"1.231282919","rc":[{"batb":[[0,2.06,34.87],[1,1.43,116.28],[2,1.38,131.58]],"ltp":2.16,"tv":856.59,"id":31375}]}]}
{"op":"mcm","clk":"11747283418","pt":1722462009237,"mc":[{"id":"1.231282919","rc":[{"batb":[[0,2.08,10],[1,2.06,34.87],[2,1.43,116.28]],"ltp":2.16,"tv":856.59,"id":31375}]}]}
{"op":"mcm","clk":"11747283617","pt":1722462012826,"mc":[{"id":"1.231282919","rc":[{"batb":[[0,2.06,34.87],[1,1.43,116.28],[2,1.38,131.58]],"ltp":2.16,"tv":856.59,"id":31375}]}]}
{"op":"mcm","clk":"11747283800","pt":1722462016110,"mc":[{"id":"1.231282919","rc":[{"batb":[[0,2.08,10],[1,2.06,34.87],[2,1.43,116.28]],"ltp":2.16,"tv":856.59,"id":31375}]}]}
{"op":"mcm","clk":"11747283987","pt":1722462019453,"mc":[{"id":"1.231282919","rc":[{"batb":[[0,2.06,34.87],[1,1.43,116.28],[2,1.38,131.58]],"ltp":2.16,"tv":856.59,"id":31375}]}]}
{"op":"mcm","clk":"11747284185","pt":1722462023824,"mc":[{"id":"1.231282919","rc":[{"batb":[[0,2.08,10],[1,2.06,34.87],[2,1.43,116.28]],"ltp":2.16,"tv":856.59,"id":31375}]}]}
{"op":"mcm","clk":"11747284361","pt":1722462027224,"mc":[{"id":"1.231282919","rc":[{"batb":[[0,2.06,34.87],[1,1.43,116.28],[2,1.38,131.58]],"ltp":2.16,"tv":856.59,"id":31375}]}]}
{"op":"mcm","clk":"11747284475","pt":1722462029528,"mc":[{"id":"1.231282919","rc":[{"batb":[[0,2.08,10],[1,2.06,34.87],[2,1.43,116.28]],"ltp":2.16,"tv":856.59,"id":31375}]}]}
{"op":"mcm","clk":"11747284649","pt":1722462032924,"mc":[{"id":"1.231282919","rc":[{"batb":[[0,2.06,34.87],[1,1.43,116.28],[2,1.38,131.58]],"ltp":2.16,"tv":856.59,"id":31375}]}]}
{"op":"mcm","clk":"11747284803","pt":1722462035542,"mc":[{"id":"1.231282919","rc":[{"batb":[[0,2.08,10],[1,2.06,34.87],[2,1.43,116.28]],"ltp":2.16,"tv":856.59,"id":31375}]}]}
{"op":"mcm","clk":"11747284995","pt":1722462038837,"mc":[{"id":"1.231282919","rc":[{"batb":[[0,2.06,34.87],[1,1.43,116.28],[2,1.38,131.58]],"ltp":2.16,"tv":856.59,"id":31375}]}]}
{"op":"mcm","clk":"11747285325","pt":1722462044073,"mc":[{"id":"1.231282919","rc":[{"batb":[[0,2.08,10],[1,2.06,34.87],[2,1.43,116.28]],"ltp":2.16,"tv":856.59,"id":31375}]}]}
{"op":"mcm","clk":"11747285511","pt":1722462047468,"mc":[{"id":"1.231282919","rc":[{"batb":[[0,2.06,34.87],[1,1.43,116.28],[2,1.38,131.58]],"ltp":2.16,"tv":856.59,"id":31375}]}]}
{"op":"mcm","clk":"11747285753","pt":1722462052394,"mc":[{"id":"1.231282919","rc":[{"batb":[[0,2.08,10],[1,2.06,34.87],[2,1.43,116.28]],"ltp":2.16,"tv":856.59,"id":31375}]}]}
{"op":"mcm","clk":"11747285926","pt":1722462055675,"mc":[{"id":"1.231282919","rc":[{"batb":[[0,2.06,34.87],[1,1.43,116.28],[2,1.38,131.58]],"ltp":2.16,"tv":856.59,"id":31375}]}]}
{"op":"mcm","clk":"11747286085","pt":1722462058661,"mc":[{"id":"1.231282919","rc":[{"batb":[[0,2.08,10],[1,2.06,34.87],[2,1.43,116.28]],"ltp":2.16,"tv":856.59,"id":31375}]}]}
{"op":"mcm","clk":"11747286278","pt":1722462062104,"mc":[{"id":"1.231282919","rc":[{"batb":[[0,2.06,34.87],[1,1.43,116.28],[2,1.38,131.58]],"ltp":2.16,"tv":856.59,"id":31375}]}]}
{"op":"mcm","clk":"11747286422","pt":1722462064469,"mc":[{"id":"1.231282919","rc":[{"batb":[[0,2.08,10],[1,2.06,34.87],[2,1.43,116.28]],"ltp":2.16,"tv":856.59,"id":31375}]}]}
{"op":"mcm","clk":"11747286632","pt":1722462067864,"mc":[{"id":"1.231282919","rc":[{"batb":[[0,2.06,34.87],[1,1.43,116.28],[2,1.38,131.58]],"ltp":2.16,"tv":856.59,"id":31375}]}]}
{"op":"mcm","clk":"11747286840","pt":1722462072374,"mc":[{"id":"1.231282919","rc":[{"batb":[[0,2.08,10],[1,2.06,34.87],[2,1.43,116.28]],"ltp":2.16,"tv":856.59,"id":31375}]}]}
{"op":"mcm","clk":"11747287030","pt":1722462075805,"mc":[{"id":"1.231282919","rc":[{"batb":[[0,2.06,34.87],[1,1.43,116.28],[2,1.38,131.58]],"ltp":2.16,"tv":856.59,"id":31375}]}]}
{"op":"mcm","clk":"11747287247","pt":1722462079817,"mc":[{"id":"1.231282919","rc":[{"batb":[[0,2.08,10],[1,2.06,34.87],[2,1.43,116.28]],"ltp":2.16,"tv":856.59,"id":31375}]}]}
{"op":"mcm","clk":"11747287456","pt":1722462083414,"mc":[{"id":"1.231282919","rc":[{"batb":[[0,2.06,34.87],[1,1.43,116.28],[2,1.38,131.58]],"ltp":2.16,"tv":856.59,"id":31375}]}]}
{"op":"mcm","clk":"11747287751","pt":1722462088799,"mc":[{"id":"1.231282919","rc":[{"batb":[[0,2.08,10],[1,2.06,34.87],[2,1.43,116.28]],"ltp":2.16,"tv":856.59,"id":31375}]}]}
{"op":"mcm","clk":"11747287836","pt":1722462090495,"mc":[{"id":"1.231282919","rc":[{"trd":[[1.85,1300],[1.86,183.59]],"batb":[[0,1.84,9.03],[1,1.79,11.87],[2,1.43,116.28]],"batl":[[0,1.85,16.84],[1,1.86,259.63]],"ltp":1.86,"tv":3837.36,"id":31372}],"tv":4693.96}]}
{"op":"mcm","clk":"11747287930","pt":1722462092136,"mc":[{"id":"1.231282919","rc":[{"batb":[[0,2.06,34.87],[1,1.43,116.28],[2,1.38,131.58]],"ltp":2.16,"tv":856.59,"id":31375}]}]}
{"op":"mcm","clk":"11747288075","pt":1722462094343,"mc":[{"id":"1.231282919","rc":[{"batb":[[0,2.08,10],[1,2.06,34.87],[2,1.43,116.28]],"ltp":2.16,"tv":856.59,"id":31375}]}]}
{"op":"mcm","clk":"11747288243","pt":1722462097732,"mc":[{"id":"1.231282919","rc":[{"batb":[[0,2.06,34.87],[1,1.43,116.28],[2,1.38,131.58]],"ltp":2.16,"tv":856.59,"id":31375}]}]}
{"op":"mcm","clk":"11747288353","pt":1722462100049,"mc":[{"id":"1.231282919","rc":[{"batb":[[0,2.08,10],[1,2.06,34.87],[2,1.43,116.28]],"ltp":2.16,"tv":856.59,"id":31375}]}]}
{"op":"mcm","clk":"11747288524","pt":1722462103346,"mc":[{"id":"1.231282919","rc":[{"batb":[[0,2.06,34.87],[1,1.43,116.28],[2,1.38,131.58]],"ltp":2.16,"tv":856.59,"id":31375}]}]}
{"op":"mcm","clk":"11747288710","pt":1722462106531,"mc":[{"id":"1.231282919","rc":[{"batb":[[0,2.08,10],[1,2.06,34.87],[2,1.43,116.28]],"ltp":2.16,"tv":856.59,"id":31375}]}]}
{"op":"mcm","clk":"11747288926","pt":1722462109921,"mc":[{"id":"1.231282919","rc":[{"batb":[[0,2.06,34.87],[1,1.43,116.28],[2,1.38,131.58]],"ltp":2.16,"tv":856.59,"id":31375}]}]}
{"op":"mcm","clk":"11747289218","pt":1722462114446,"mc":[{"id":"1.231282919","rc":[{"batb":[[0,2.08,10],[1,2.06,34.87],[2,1.43,116.28]],"ltp":2.16,"tv":856.59,"id":31375}]}]}
{"op":"mcm","clk":"11747289440","pt":1722462117837,"mc":[{"id":"1.231282919","rc":[{"batb":[[0,2.06,34.87],[1,1.43,116.28],[2,1.38,131.58]],"ltp":2.16,"tv":856.59,"id":31375}]}]}
{"op":"mcm","clk":"11747289617","pt":1722462120361,"mc":[{"id":"1.231282919","rc":[{"batb":[[0,2.08,10],[1,2.06,34.87],[2,1.43,116.28]],"ltp":2.16,"tv":856.59,"id":31375}]}]}
{"op":"mcm","clk":"11747289868","pt":1722462123766,"mc":[{"id":"1.231282919","rc":[{"batb":[[0,2.06,34.87],[1,1.43,116.28],[2,1.38,131.58]],"ltp":2.16,"tv":856.59,"id":31375}]}]}
{"op":"mcm","clk":"11747289999","pt":1722462125873,"mc":[{"id":"1.231282919","rc":[{"batb":[[0,2.08,10],[1,2.06,34.87],[2,1.43,116.28]],"ltp":2.16,"tv":856.59,"id":31375}]}]}
{"op":"mcm","clk":"11747290193","pt":1722462129263,"mc":[{"id":"1.231282919","rc":[{"batb":[[0,2.06,34.87],[1,1.43,116.28],[2,1.38,131.58]],"ltp":2.16,"tv":856.59,"id":31375}]}]}
{"op":"mcm","clk":"11747290371","pt":1722462132757,"mc":[{"id":"1.231282919","rc":[{"batb":[[0,2.08,10],[1,2.06,34.87],[2,1.43,116.28]],"ltp":2.16,"tv":856.59,"id":31375}]}]}
{"op":"mcm","clk":"11747290568","pt":1722462136153,"mc":[{"id":"1.231282919","rc":[{"batb":[[0,2.06,34.87],[1,1.43,116.28],[2,1.38,131.58]],"ltp":2.16,"tv":856.59,"id":31375}]}]}
{"op":"mcm","clk":"11747290763","pt":1722462139387,"mc":[{"id":"1.231282919","rc":[{"batb":[[0,2.08,10],[1,2.06,34.87],[2,1.43,116.28]],"ltp":2.16,"tv":856.59,"id":31375}]}]}
{"op":"mcm","clk":"11747290940","pt":1722462142787,"mc":[{"id":"1.231282919","rc":[{"batb":[[0,2.06,34.87],[1,1.43,116.28],[2,1.38,131.58]],"ltp":2.16,"tv":856.59,"id":31375}]}]}
{"op":"mcm","clk":"11747291091","pt":1722462145099,"mc":[{"id":"1.231282919","rc":[{"batb":[[0,2.08,10],[1,2.06,34.87],[2,1.43,116.28]],"ltp":2.16,"tv":856.59,"id":31375}]}]}
{"op":"mcm","clk":"11747291283","pt":1722462148487,"mc":[{"id":"1.231282919","rc":[{"batb":[[0,2.06,34.87],[1,1.43,116.28],[2,1.38,131.58]],"ltp":2.16,"tv":856.59,"id":31375}]}]}
{"op":"mcm","clk":"11747291628","pt":1722462155005,"mc":[{"id":"1.231282919","rc":[{"batb":[[0,2.08,10],[1,2.06,34.87],[2,1.43,116.28]],"ltp":2.16,"tv":856.59,"id":31375}]}]}
{"op":"mcm","clk":"11747291818","pt":1722462158201,"mc":[{"id":"1.231282919","rc":[{"batb":[[0,2.06,34.87],[1,1.43,116.28],[2,1.38,131.58]],"ltp":2.16,"tv":856.59,"id":31375}]}]}
{"op":"mcm","clk":"11747292457","pt":1722462169890,"mc":[{"id":"1.231282919","rc":[{"batb":[[0,2.08,10],[1,2.06,34.87],[2,1.43,116.28]],"ltp":2.16,"tv":856.59,"id":31375}]}]}
{"op":"mcm","clk":"11747292651","pt":1722462173587,"mc":[{"id":"1.231282919","rc":[{"batb":[[0,2.06,34.87],[1,1.43,116.28],[2,1.38,131.58]],"ltp":2.16,"tv":856.59,"id":31375}]}]}
{"op":"mcm","clk":"11747292811","pt":1722462176203,"mc":[{"id":"1.231282919","rc":[{"batb":[[0,2.08,10],[1,2.06,34.87],[2,1.43,116.28]],"ltp":2.16,"tv":856.59,"id":31375}]}]}
{"op":"mcm","clk":"11747292984","pt":1722462179590,"mc":[{"id":"1.231282919","rc":[{"batb":[[0,2.06,34.87],[1,1.43,116.28],[2,1.38,131.58]],"ltp":2.16,"tv":856.59,"id":31375}]}]}
{"op":"mcm","clk":"11747293298","pt":1722462185026,"mc":[{"id":"1.231282919","rc":[{"batb":[[0,2.08,10],[1,2.06,34.87],[2,1.43,116.28]],"ltp":2.16,"tv":856.59,"id":31375}]}]}
{"op":"mcm","clk":"11747293519","pt":1722462189404,"mc":[{"id":"1.231282919","rc":[{"batb":[[0,2.06,34.87],[1,1.43,116.28],[2,1.38,131.58]],"ltp":2.16,"tv":856.59,"id":31375}]}]}
{"op":"mcm","clk":"11747293794","pt":1722462194336,"mc":[{"id":"1.231282919","rc":[{"batb":[[0,2.08,10],[1,2.06,34.87],[2,1.43,116.28]],"ltp":2.16,"tv":856.59,"id":31375}]}]}
{"op":"mcm","clk":"11747293996","pt":1722462197718,"mc":[{"id":"1.231282919","rc":[{"batb":[[0,2.06,34.87],[1,1.43,116.28],[2,1.38,131.58]],"ltp":2.16,"tv":856.59,"id":31375}]}]}
{"op":"mcm","clk":"11747294358","pt":1722462203825,"mc":[{"id":"1.231282919","rc":[{"batb":[[0,2.08,10],[1,2.06,34.87],[2,1.43,116.28]],"ltp":2.16,"tv":856.59,"id":31375}]}]}
{"op":"mcm","clk":"11747294568","pt":1722462207212,"mc":[{"id":"1.231282919","rc":[{"batb":[[0,2.06,34.87],[1,1.43,116.28],[2,1.38,131.58]],"ltp":2.16,"tv":856.59,"id":31375}]}]}
{"op":"mcm","clk":"11747294697","pt":1722462210035,"mc":[{"id":"1.231282919","rc":[{"batb":[[0,2.08,10],[1,2.06,34.87],[2,1.43,116.28]],"ltp":2.16,"tv":856.59,"id":31375}]}]}
{"op":"mcm","clk":"11747294906","pt":1722462213531,"mc":[{"id":"1.231282919","rc":[{"batb":[[0,2.06,34.87],[1,1.43,116.28],[2,1.38,131.58]],"ltp":2.16,"tv":856.59,"id":31375}]}]}
{"op":"mcm","clk":"11747295058","pt":1722462215840,"mc":[{"id":"1.231282919","rc":[{"batb":[[0,2.08,10],[1,2.06,34.87],[2,1.43,116.28]],"ltp":2.16,"tv":856.59,"id":31375}]}]}
{"op":"mcm","clk":"11747295247","pt":1722462219431,"mc":[{"id":"1.231282919","rc":[{"batb":[[0,2.06,34.87],[1,1.43,116.28],[2,1.38,131.58]],"ltp":2.16,"tv":856.59,"id":31375}]}]}
{"op":"mcm","clk":"11747295533","pt":1722462224728,"mc":[{"id":"1.231282919","rc":[{"batb":[[0,2.08,10],[1,2.06,34.87],[2,1.43,116.28]],"ltp":2.16,"tv":856.59,"id":31375}]}]}
{"op":"mcm","clk":"11747295716","pt":1722462228262,"mc":[{"id":"1.231282919","rc":[{"batb":[[0,2.06,34.87],[1,1.43,116.28],[2,1.38,131.58]],"ltp":2.16,"tv":856.59,"id":31375}]}]}
{"op":"mcm","clk":"11747295944","pt":1722462232472,"mc":[{"id":"1.231282919","rc":[{"batb":[[0,2.08,10],[1,2.06,34.87],[2,1.43,116.28]],"ltp":2.16,"tv":856.59,"id":31375}]}]}
{"op":"mcm","clk":"11747296120","pt":1722462235868,"mc":[{"id":"1.231282919","rc":[{"batb":[[0,2.06,34.87],[1,1.43,116.28],[2,1.38,131.58]],"ltp":2.16,"tv":856.59,"id":31375}]}]}
{"op":"mcm","clk":"11747296229","pt":1722462238077,"mc":[{"id":"1.231282919","rc":[{"batb":[[0,2.08,10],[1,2.06,34.87],[2,1.43,116.28]],"ltp":2.16,"tv":856.59,"id":31375}]}]}
{"op":"mcm","clk":"11747296491","pt":1722462242143,"mc":[{"id":"1.231282919","rc":[{"batb":[[0,2.06,34.87],[1,1.43,116.28],[2,1.38,131.58]],"ltp":2.16,"tv":856.59,"id":31375}]}]}
{"op":"mcm","clk":"11747296809","pt":1722462247349,"mc":[{"id":"1.231282919","rc":[{"batb":[[0,2.08,10],[1,2.06,34.87],[2,1.43,116.28]],"ltp":2.16,"tv":856.59,"id":31375}]}]}
{"op":"mcm","clk":"11747297009","pt":1722462250785,"mc":[{"id":"1.231282919","rc":[{"batb":[[0,2.06,34.87],[1,1.43,116.28],[2,1.38,131.58]],"ltp":2.16,"tv":856.59,"id":31375}]}]}
{"op":"mcm","clk":"11747297262","pt":1722462255660,"mc":[{"id":"1.231282919","rc":[{"batb":[[0,2.08,10],[1,2.06,34.87],[2,1.43,116.28]],"ltp":2.16,"tv":856.59,"id":31375}]}]}
{"op":"mcm","clk":"11747297462","pt":1722462259253,"mc":[{"id":"1.231282919","rc":[{"batb":[[0,2.06,34.87],[1,1.43,116.28],[2,1.38,131.58]],"ltp":2.16,"tv":856.59,"id":31375}]}]}
{"op":"mcm","clk":"11747297717","pt":1722462263569,"mc":[{"id":"1.231282919","rc":[{"batb":[[0,2.08,10],[1,2.06,34.87],[2,1.43,116.28]],"ltp":2.16,"tv":856.59,"id":31375}]}]}
{"op":"mcm","clk":"11747297951","pt":1722462267265,"mc":[{"id":"1.231282919","rc":[{"batb":[[0,2.06,34.87],[1,1.43,116.28],[2,1.38,131.58]],"ltp":2.16,"tv":856.59,"id":31375}]}]}
{"op":"mcm","clk":"11747298155","pt":1722462270692,"mc":[{"id":"1.231282919","rc":[{"batb":[[0,2.08,10],[1,2.06,34.87],[2,1.43,116.28]],"ltp":2.16,"tv":856.59,"id":31375}]}]}
{"op":"mcm","clk":"11747298357","pt":1722462274180,"mc":[{"id":"1.231282919","rc":[{"batb":[[0,2.06,34.87],[1,1.43,116.28],[2,1.38,131.58]],"ltp":2.16,"tv":856.59,"id":31375}]}]}
{"op":"mcm","clk":"11747298726","pt":1722462280470,"mc":[{"id":"1.231282919","rc":[{"batb":[[0,2.08,10],[1,2.06,34.87],[2,1.43,116.28]],"ltp":2.16,"tv":856.59,"id":31375}]}]}
{"op":"mcm","clk":"11747298970","pt":1722462284070,"mc":[{"id":"1.231282919","rc":[{"batb":[[0,2.06,34.87],[1,1.43,116.28],[2,1.38,131.58]],"ltp":2.16,"tv":856.59,"id":31375}]}]}
{"op":"mcm","clk":"11747299383","pt":1722462292006,"mc":[{"id":"1.231282919","rc":[{"batb":[[0,2.08,10],[1,2.06,34.87],[2,1.43,116.28]],"ltp":2.16,"tv":856.59,"id":31375}]}]}
{"op":"mcm","clk":"11747299600","pt":1722462295804,"mc":[{"id":"1.231282919","rc":[{"batb":[[0,2.06,34.87],[1,1.43,116.28],[2,1.38,131.58]],"ltp":2.16,"tv":856.59,"id":31375}]}]}
{"op":"mcm","clk":"11747299701","pt":1722462298116,"mc":[{"id":"1.231282919","rc":[{"batb":[[0,2.08,10],[1,2.06,34.87],[2,1.43,116.28]],"ltp":2.16,"tv":856.59,"id":31375}]}]}
{"op":"mcm","clk":"11747299879","pt":1722462301414,"mc":[{"id":"1.231282919","rc":[{"batb":[[0,2.06,34.87],[1,1.43,116.28],[2,1.38,131.58]],"ltp":2.16,"tv":856.59,"id":31375}]}]}
{"op":"mcm","clk":"11747300057","pt":1722462304197,"mc":[{"id":"1.231282919","rc":[{"batb":[[0,2.08,10],[1,2.06,34.87],[2,1.43,116.28]],"ltp":2.16,"tv":856.59,"id":31375}]}]}
{"op":"mcm","clk":"11747300239","pt":1722462307733,"mc":[{"id":"1.231282919","rc":[{"batb":[[0,2.06,34.87],[1,1.43,116.28],[2,1.38,131.58]],"ltp":2.16,"tv":856.59,"id":31375}]}]}
{"op":"mcm","clk":"11747300348","pt":1722462310303,"mc":[{"id":"1.231282919","rc":[{"batb":[[0,2.08,10],[1,2.06,34.87],[2,1.43,116.28]],"ltp":2.16,"tv":856.59,"id":31375}]}]}
{"op":"mcm","clk":"11747300555","pt":1722462313899,"mc":[{"id":"1.231282919","rc":[{"batb":[[0,2.06,34.87],[1,1.43,116.28],[2,1.38,131.58]],"ltp":2.16,"tv":856.59,"id":31375}]}]}
{"op":"mcm","clk":"11747300663","pt":1722462316420,"mc":[{"id":"1.231282919","rc":[{"batb":[[0,2.08,10],[1,2.06,34.87],[2,1.43,116.28]],"ltp":2.16,"tv":856.59,"id":31375}]}]}
{"op":"mcm","clk":"11747300866","pt":1722462320006,"mc":[{"id":"1.231282919","rc":[{"batb":[[0,2.06,34.87],[1,1.43,116.28],[2,1.38,131.58]],"ltp":2.16,"tv":856.59,"id":31375}]}]}
{"op":"mcm","clk":"11747301037","pt":1722462323446,"mc":[{"id":"1.231282919","rc":[{"batb":[[0,2.08,10],[1,2.06,34.87],[2,1.43,116.28]],"ltp":2.16,"tv":856.59,"id":31375}]}]}
{"op":"mcm","clk":"11747301230","pt":1722462326837,"mc":[{"id":"1.231282919","rc":[{"batb":[[0,2.06,34.87],[1,1.43,116.28],[2,1.38,131.58]],"ltp":2.16,"tv":856.59,"id":31375}]}]}
{"op":"mcm","clk":"11747301340","pt":1722462329044,"mc":[{"id":"1.231282919","rc":[{"batb":[[0,2.08,10],[1,2.06,34.87],[2,1.43,116.28]],"ltp":2.16,"tv":856.59,"id":31375}]}]}
{"op":"mcm","clk":"11747301512","pt":1722462332538,"mc":[{"id":"1.231282919","rc":[{"batb":[[0,2.06,34.87],[1,1.43,116.28],[2,1.38,131.58]],"ltp":2.16,"tv":856.59,"id":31375}]}]}
{"op":"mcm","clk":"11747301859","pt":1722462338548,"mc":[{"id":"1.231282919","rc":[{"batb":[[0,2.08,10],[1,2.06,34.87],[2,1.43,116.28]],"ltp":2.16,"tv":856.59,"id":31375}]}]}
{"op":"mcm","clk":"11747302083","pt":1722462342142,"mc":[{"id":"1.231282919","rc":[{"batb":[[0,2.06,34.87],[1,1.43,116.28],[2,1.38,131.58]],"ltp":2.16,"tv":856.59,"id":31375}]}]}
{"op":"mcm","clk":"11747302227","pt":1722462344347,"mc":[{"id":"1.231282919","rc":[{"batb":[[0,2.08,10],[1,2.06,34.87],[2,1.43,116.28]],"ltp":2.16,"tv":856.59,"id":31375}]}]}
{"op":"mcm","clk":"11747302423","pt":1722462347855,"mc":[{"id":"1.231282919","rc":[{"batb":[[0,2.06,34.87],[1,1.43,116.28],[2,1.38,131.58]],"ltp":2.16,"tv":856.59,"id":31375}]}]}
{"op":"mcm","clk":"11747303366","pt":1722462363363,"mc":[{"id":"1.231282919","rc":[{"batb":[[0,2.08,10],[1,2.06,34.87],[2,1.43,116.28]],"ltp":2.16,"tv":856.59,"id":31375}]}]}
{"op":"mcm","clk":"11747303586","pt":1722462366769,"mc":[{"id":"1.231282919","rc":[{"batb":[[0,2.06,34.87],[1,1.43,116.28],[2,1.38,131.58]],"ltp":2.16,"tv":856.59,"id":31375}]}]}
{"op":"mcm","clk":"11747303758","pt":1722462369884,"mc":[{"id":"1.231282919","rc":[{"batb":[[0,2.08,10],[1,2.06,34.87],[2,1.43,116.28]],"ltp":2.16,"tv":856.59,"id":31375}]}]}
{"op":"mcm","clk":"11747303937","pt":1722462373074,"mc":[{"id":"1.231282919","rc":[{"batb":[[0,2.06,34.87],[1,1.43,116.28],[2,1.38,131.58]],"ltp":2.16,"tv":856.59,"id":31375}]}]}
{"op":"mcm","clk":"11747304088","pt":1722462375802,"mc":[{"id":"1.231282919","rc":[{"batb":[[0,2.08,10],[1,2.06,34.87],[2,1.43,116.28]],"ltp":2.16,"tv":856.59,"id":31375}]}]}
{"op":"mcm","clk":"11747304256","pt":1722462379193,"mc":[{"id":"1.231282919","rc":[{"batb":[[0,2.06,34.87],[1,1.43,116.28],[2,1.38,131.58]],"ltp":2.16,"tv":856.59,"id":31375}]}]}
{"op":"mcm","clk":"11747304599","pt":1722462386344,"mc":[{"id":"1.231282919","rc":[{"batb":[[0,2.08,10],[1,2.06,34.87],[2,1.43,116.28]],"ltp":2.16,"tv":856.59,"id":31375}]}]}
{"op":"mcm","clk":"11747304737","pt":1722462389732,"mc":[{"id":"1.231282919","rc":[{"batb":[[0,2.06,34.87],[1,1.43,116.28],[2,1.38,131.58]],"ltp":2.16,"tv":856.59,"id":31375}]}]}
{"op":"mcm","clk":"11747305371","pt":1722462400939,"mc":[{"id":"1.231282919","rc":[{"batb":[[0,2.08,10],[1,2.06,34.87],[2,1.43,116.28]],"ltp":2.16,"tv":856.59,"id":31375}]}]}
{"op":"mcm","clk":"11747305568","pt":1722462404644,"mc":[{"id":"1.231282919","rc":[{"batb":[[0,2.06,34.87],[1,1.43,116.28],[2,1.38,131.58]],"ltp":2.16,"tv":856.59,"id":31375}]}]}
{"op":"mcm","clk":"11747305952","pt":1722462410807,"mc":[{"id":"1.231282919","rc":[{"batb":[[0,2.08,10],[1,2.06,34.87],[2,1.43,116.28]],"ltp":2.16,"tv":856.59,"id":31375}]}]}
{"op":"mcm","clk":"11747306196","pt":1722462414295,"mc":[{"id":"1.231282919","rc":[{"batb":[[0,2.06,34.87],[1,1.43,116.28],[2,1.38,131.58]],"ltp":2.16,"tv":856.59,"id":31375}]}]}
{"op":"mcm","clk":"11747307620","pt":1722462438914,"mc":[{"id":"1.231282919","rc":[{"batb":[[0,2.08,10],[1,2.06,34.87],[2,1.43,116.28]],"ltp":2.16,"tv":856.59,"id":31375}]}]}
{"op":"mcm","clk":"11747307781","pt":1722462442399,"mc":[{"id":"1.231282919","rc":[{"batb":[[0,2.06,34.87],[1,1.43,116.28],[2,1.38,131.58]],"ltp":2.16,"tv":856.59,"id":31375}]}]}
{"op":"mcm","clk":"11747308666","pt":1722462458442,"mc":[{"id":"1.231282919","rc":[{"batb":[[0,2.08,10],[1,2.06,34.87],[2,1.43,116.28]],"ltp":2.16,"tv":856.59,"id":31375}]}]}
{"op":"mcm","clk":"11747308847","pt":1722462461729,"mc":[{"id":"1.231282919","rc":[{"batb":[[0,2.06,34.87],[1,1.43,116.28],[2,1.38,131.58]],"ltp":2.16,"tv":856.59,"id":31375}]}]}
{"op":"mcm","clk":"11747309077","pt":1722462465944,"mc":[{"id":"1.231282919","rc":[{"batb":[[0,2.08,10],[1,2.06,34.87],[2,1.43,116.28]],"ltp":2.16,"tv":856.59,"id":31375}]}]}
{"op":"mcm","clk":"11747309262","pt":1722462469379,"mc":[{"id":"1.231282919","rc":[{"batb":[[0,2.06,34.87],[1,1.43,116.28],[2,1.38,131.58]],"ltp":2.16,"tv":856.59,"id":31375}]}]}
{"op":"mcm","clk":"11747309425","pt":1722462472369,"mc":[{"id":"1.231282919","rc":[{"batb":[[0,2.08,10],[1,2.06,34.87],[2,1.43,116.28]],"ltp":2.16,"tv":856.59,"id":31375}]}]}
{"op":"mcm","clk":"11747309624","pt":1722462475970,"mc":[{"id":"1.231282919","rc":[{"batb":[[0,2.06,34.87],[1,1.43,116.28],[2,1.38,131.58]],"ltp":2.16,"tv":856.59,"id":31375}]}]}
{"op":"mcm","clk":"11747310301","pt":1722462488381,"mc":[{"id":"1.231282919","rc":[{"batb":[[0,2.08,10],[1,2.06,34.87],[2,1.43,116.28]],"ltp":2.16,"tv":856.59,"id":31375}]}]}
{"op":"mcm","clk":"11747310495","pt":1722462491878,"mc":[{"id":"1.231282919","rc":[{"batb":[[0,2.06,34.87],[1,1.43,116.28],[2,1.38,131.58]],"ltp":2.16,"tv":856.59,"id":31375}]}]}
{"op":"mcm","clk":"11747310777","pt":1722462496865,"mc":[{"id":"1.231282919","rc":[{"batb":[[0,2.08,10],[1,2.06,34.87],[2,1.43,116.28]],"ltp":2.16,"tv":856.59,"id":31375}]}]}
{"op":"mcm","clk":"11747310953","pt":1722462500412,"mc":[{"id":"1.231282919","rc":[{"batb":[[0,2.06,34.87],[1,1.43,116.28],[2,1.38,131.58]],"ltp":2.16,"tv":856.59,"id":31375}]}]}
{"op":"mcm","clk":"11747311291","pt":1722462507518,"mc":[{"id":"1.231282919","rc":[{"batb":[[0,2.08,10],[1,2.06,34.87],[2,1.43,116.28]],"ltp":2.16,"tv":856.59,"id":31375}]}]}
{"op":"mcm","clk":"11747311480","pt":1722462511109,"mc":[{"id":"1.231282919","rc":[{"batb":[[0,2.06,34.87],[1,1.43,116.28],[2,1.38,131.58]],"ltp":2.16,"tv":856.59,"id":31375}]}]}
{"op":"mcm","clk":"11747313116","pt":1722462540620,"mc":[{"id":"1.231282919","rc":[{"batb":[[0,2.08,10],[1,2.06,34.87],[2,1.43,116.28]],"ltp":2.16,"tv":856.59,"id":31375}]}]}
{"op":"mcm","clk":"11747313331","pt":1722462544118,"mc":[{"id":"1.231282919","rc":[{"batb":[[0,2.06,34.87],[1,1.43,116.28],[2,1.38,131.58]],"ltp":2.16,"tv":856.59,"id":31375}]}]}
{"op":"mcm","clk":"11747313520","pt":1722462547054,"mc":[{"id":"1.231282919","rc":[{"batb":[[0,2.08,10],[1,2.06,34.87],[2,1.43,116.28]],"ltp":2.16,"tv":856.59,"id":31375}]}]}
{"op":"mcm","clk":"11747313729","pt":1722462550655,"mc":[{"id":"1.231282919","rc":[{"batb":[[0,2.06,34.87],[1,1.43,116.28],[2,1.38,131.58]],"ltp":2.16,"tv":856.59,"id":31375}]}]}
{"op":"mcm","clk":"11747314780","pt":1722462570967,"mc":[{"id":"1.231282919","rc":[{"batb":[[0,2.08,10],[1,2.06,34.87],[2,1.43,116.28]],"ltp":2.16,"tv":856.59,"id":31375}]}]}
{"op":"mcm","clk":"11747314944","pt":1722462574448,"mc":[{"id":"1.231282919","rc":[{"batb":[[0,2.06,34.87],[1,1.43,116.28],[2,1.38,131.58]],"ltp":2.16,"tv":856.59,"id":31375}]}]}
{"op":"mcm","clk":"11747315114","pt":1722462577783,"mc":[{"id":"1.231282919","rc":[{"batb":[[0,2.08,10],[1,2.06,34.87],[2,1.43,116.28]],"ltp":2.16,"tv":856.59,"id":31375}]}]}
{"op":"mcm","clk":"11747315260","pt":1722462581159,"mc":[{"id":"1.231282919","rc":[{"batb":[[0,2.06,34.87],[1,1.43,116.28],[2,1.38,131.58]],"ltp":2.16,"tv":856.59,"id":31375}]}]}
{"op":"mcm","clk":"11747315349","pt":1722462583366,"mc":[{"id":"1.231282919","rc":[{"batb":[[0,2.08,10],[1,2.06,34.87],[2,1.43,116.28]],"ltp":2.16,"tv":856.59,"id":31375}]}]}
{"op":"mcm","clk":"11747315490","pt":1722462586902,"mc":[{"id":"1.231282919","rc":[{"batb":[[0,2.06,34.87],[1,1.43,116.28],[2,1.38,131.58]],"ltp":2.16,"tv":856.59,"id":31375}]}]}
{"op":"mcm","clk":"11747323863","pt":1722462725776,"mc":[{"id":"1.231282919","rc":[{"batb":[[0,2.08,10],[1,2.06,34.87],[2,1.43,116.28]],"ltp":2.16,"tv":856.59,"id":31375}]}]}
{"op":"mcm","clk":"11747324077","pt":1722462729400,"mc":[{"id":"1.231282919","rc":[{"batb":[[0,2.06,34.87],[1,1.43,116.28],[2,1.38,131.58]],"ltp":2.16,"tv":856.59,"id":31375}]}]}
{"op":"mcm","clk":"11747327341","pt":1722462785059,"mc":[{"id":"1.231282919","rc":[{"batb":[[0,2.08,10],[1,2.06,34.87],[2,1.43,116.28]],"ltp":2.16,"tv":856.59,"id":31375}]}]}
{"op":"mcm","clk":"11747327561","pt":1722462788550,"mc":[{"id":"1.231282919","rc":[{"batb":[[0,2.06,34.87],[1,1.43,116.28],[2,1.38,131.58]],"ltp":2.16,"tv":856.59,"id":31375}]}]}
{"op":"mcm","clk":"11747337466","pt":1722462944729,"mc":[{"id":"1.231282919","rc":[{"batb":[[0,2.08,10],[1,2.06,34.87],[2,1.43,116.28]],"ltp":2.16,"tv":856.59,"id":31375}]}]}
{"op":"mcm","clk":"11747337648","pt":1722462948012,"mc":[{"id":"1.231282919","rc":[{"batb":[[0,2.06,34.87],[1,1.43,116.28],[2,1.38,131.58]],"ltp":2.16,"tv":856.59,"id":31375}]}]}
{"op":"mcm","clk":"11747341445","pt":1722463006510,"mc":[{"id":"1.231282919","rc":[{"batb":[[0,2.08,10],[1,2.06,34.87],[2,1.43,116.28]],"ltp":2.16,"tv":856.59,"id":31375}]}]}
{"op":"mcm","clk":"11747341661","pt":1722463009950,"mc":[{"id":"1.231282919","rc":[{"batb":[[0,2.06,34.87],[1,1.43,116.28],[2,1.38,131.58]],"ltp":2.16,"tv":856.59,"id":31375}]}]}
{"op":"mcm","clk":"11747345038","pt":1722463062786,"mc":[{"id":"1.231282919","rc":[{"batb":[[0,2.08,10],[1,2.06,34.87],[2,1.43,116.28]],"ltp":2.16,"tv":856.59,"id":31375}]}]}
{"op":"mcm","clk":"11747345238","pt":1722463066176,"mc":[{"id":"1.231282919","rc":[{"batb":[[0,2.06,34.87],[1,1.43,116.28],[2,1.38,131.58]],"ltp":2.16,"tv":856.59,"id":31375}]}]}
{"op":"mcm","clk":"11747345476","pt":1722463070221,"mc":[{"id":"1.231282919","rc":[{"batb":[[0,2.08,10],[1,2.06,34.87],[2,1.43,116.28]],"ltp":2.16,"tv":856.59,"id":31375}]}]}
{"op":"mcm","clk":"11747345706","pt":1722463073717,"mc":[{"id":"1.231282919","rc":[{"batb":[[0,2.06,34.87],[1,1.43,116.28],[2,1.38,131.58]],"ltp":2.16,"tv":856.59,"id":31375}]}]}
{"op":"mcm","clk":"11747346051","pt":1722463079923,"mc":[{"id":"1.231282919","rc":[{"batb":[[0,2.08,10],[1,2.06,34.87],[2,1.43,116.28]],"ltp":2.16,"tv":856.59,"id":31375}]}]}
{"op":"mcm","clk":"11747346271","pt":1722463083426,"mc":[{"id":"1.231282919","rc":[{"batb":[[0,2.06,34.87],[1,1.43,116.28],[2,1.38,131.58]],"ltp":2.16,"tv":856.59,"id":31375}]}]}
{"op":"mcm","clk":"11747346454","pt":1722463086920,"mc":[{"id":"1.231282919","rc":[{"batb":[[0,2.08,10],[1,2.06,34.87],[2,1.43,116.28]],"ltp":2.16,"tv":856.59,"id":31375}]}]}
{"op":"mcm","clk":"11747346663","pt":1722463090343,"mc":[{"id":"1.231282919","rc":[{"batb":[[0,2.06,34.87],[1,1.43,116.28],[2,1.38,131.58]],"ltp":2.16,"tv":856.59,"id":31375}]}]}
{"op":"mcm","clk":"11747346980","pt":1722463095226,"mc":[{"id":"1.231282919","rc":[{"batb":[[0,2.08,10],[1,2.06,34.87],[2,1.43,116.28]],"ltp":2.16,"tv":856.59,"id":31375}]}]}
{"op":"mcm","clk":"11747347186","pt":1722463098972,"mc":[{"id":"1.231282919","rc":[{"batb":[[0,2.06,34.87],[1,1.43,116.28],[2,1.38,131.58]],"ltp":2.16,"tv":856.59,"id":31375}]}]}
{"op":"mcm","clk":"11747347486","pt":1722463103854,"mc":[{"id":"1.231282919","rc":[{"batb":[[0,2.08,10],[1,2.06,34.87],[2,1.43,116.28]],"ltp":2.16,"tv":856.59,"id":31375}]}]}
{"op":"mcm","clk":"11747347701","pt":1722463107386,"mc":[{"id":"1.231282919","rc":[{"batb":[[0,2.06,34.87],[1,1.43,116.28],[2,1.38,131.58]],"ltp":2.16,"tv":856.59,"id":31375}]}]}
{"op":"mcm","clk":"11747348139","pt":1722463114383,"mc":[{"id":"1.231282919","rc":[{"batb":[[0,2.08,10],[1,2.06,34.87],[2,1.43,116.28]],"ltp":2.16,"tv":856.59,"id":31375}]}]}
{"op":"mcm","clk":"11747348365","pt":1722463118076,"mc":[{"id":"1.231282919","rc":[{"batb":[[0,2.06,34.87],[1,1.43,116.28],[2,1.38,131.58]],"ltp":2.16,"tv":856.59,"id":31375}]}]}
{"op":"mcm","clk":"11747348803","pt":1722463125873,"mc":[{"id":"1.231282919","rc":[{"batb":[[0,2.08,10],[1,2.06,34.87],[2,1.43,116.28]],"ltp":2.16,"tv":856.59,"id":31375}]}]}
{"op":"mcm","clk":"11747349015","pt":1722463129407,"mc":[{"id":"1.231282919","rc":[{"batb":[[0,2.06,34.87],[1,1.43,116.28],[2,1.38,131.58]],"ltp":2.16,"tv":856.59,"id":31375}]}]}
{"op":"mcm","clk":"11747349177","pt":1722463132486,"mc":[{"id":"1.231282919","rc":[{"batb":[[0,2.08,10],[1,2.06,34.87],[2,1.43,116.28]],"ltp":2.16,"tv":856.59,"id":31375}]}]}
{"op":"mcm","clk":"11747349384","pt":1722463135924,"mc":[{"id":"1.231282919","rc":[{"batb":[[0,2.06,34.87],[1,1.43,116.28],[2,1.38,131.58]],"ltp":2.16,"tv":856.59,"id":31375}]}]}
{"op":"mcm","clk":"11747349605","pt":1722463139214,"mc":[{"id":"1.231282919","rc":[{"batb":[[0,2.08,10],[1,2.06,34.87],[2,1.43,116.28]],"ltp":2.16,"tv":856.59,"id":31375}]}]}
{"op":"mcm","clk":"11747349838","pt":1722463142715,"mc":[{"id":"1.231282919","rc":[{"batb":[[0,2.06,34.87],[1,1.43,116.28],[2,1.38,131.58]],"ltp":2.16,"tv":856.59,"id":31375}]}]}
{"op":"mcm","clk":"11747350332","pt":1722463150704,"mc":[{"id":"1.231282919","rc":[{"batb":[[0,2.08,10],[1,2.06,34.87],[2,1.43,116.28]],"ltp":2.16,"tv":856.59,"id":31375}]}]}
{"op":"mcm","clk":"11747350558","pt":1722463154205,"mc":[{"id":"1.231282919","rc":[{"batb":[[0,2.06,34.87],[1,1.43,116.28],[2,1.38,131.58]],"ltp":2.16,"tv":856.59,"id":31375}]}]}
{"op":"mcm","clk":"11747352379","pt":1722463182841,"mc":[{"id":"1.231282919","rc":[{"batb":[[0,2.08,10],[1,2.06,34.87],[2,1.43,116.28]],"ltp":2.16,"tv":856.59,"id":31375}]}]}
{"op":"mcm","clk":"11747352601","pt":1722463186331,"mc":[{"id":"1.231282919","rc":[{"batb":[[0,2.06,34.87],[1,1.43,116.28],[2,1.38,131.58]],"ltp":2.16,"tv":856.59,"id":31375}]}]}
{"op":"mcm","clk":"11747354569","pt":1722463214866,"mc":[{"id":"1.231282919","rc":[{"trd":[[1.79,189.85],[1.82,169.89],[1.86,183.59],[1.87,562.92],[1.88,396.33],[1.94,8.42]],"batb":[[0,1.84,9.03]],"batl":[[0,1.85,16.84]],"ltp":1.86,"tv":3837.33,"id":31372},{"trd":[[2.12,211.12],[2.14,254.17],[2.16,260.35],[2.28,13.61]],"batb":[[0,2.08,10],[1,2.06,34.87],[2,1.43,116.28]],"ltp":2.16,"tv":856.58,"id":31375}],"tv":4693.91}]}
{"op":"mcm","clk":"11747354790","pt":1722463218468,"mc":[{"id":"1.231282919","rc":[{"batb":[[0,2.06,34.87],[1,1.43,116.28],[2,1.38,131.58]],"ltp":2.16,"tv":856.58,"id":31375}]}]}
{"op":"mcm","clk":"11747355590","pt":1722463230212,"mc":[{"id":"1.231282919","rc":[{"batb":[[0,2.08,10],[1,2.06,34.87],[2,1.43,116.28]],"ltp":2.16,"tv":856.58,"id":31375}]}]}
{"op":"mcm","clk":"11747355822","pt":1722463233706,"mc":[{"id":"1.231282919","rc":[{"batb":[[0,2.06,34.87],[1,1.43,116.28],[2,1.38,131.58]],"ltp":2.16,"tv":856.58,"id":31375}]}]}
{"op":"mcm","clk":"11747355877","pt":1722463234586,"mc":[{"id":"1.231282919","rc":[{"batl":[[0,1.85,20.84]],"ltp":1.86,"tv":3837.33,"id":31372},{"batb":[[0,2.16,4],[1,2.06,34.87],[2,1.43,116.28]],"ltp":2.16,"tv":856.58,"id":31375}]}]}
{"op":"mcm","clk":"11747697190","pt":1722469374798,"mc":[{"id":"1.231282919","rc":[{"trd":[[1.79,189.88],[1.82,169.89],[1.86,183.58],[1.87,562.92],[1.88,396.32],[1.94,8.42]],"batb":[[0,1.84,9.03]],"batl":[[0,1.85,20.84]],"ltp":1.86,"tv":3837.32,"id":31372},{"trd":[[2.12,211.12],[2.14,254.17],[2.16,260.34]],"ltp":2.16,"tv":856.58,"id":31375}],"tv":4693.9}]}
{"op":"mcm","clk":"11747983555","pt":1722474774800,"mc":[{"id":"1.231282919","rc":[{"trd":[[1.78,5.1],[1.79,189.84],[1.82,169.9],[1.86,183.6],[1.87,562.93],[1.88,396.37],[1.94,8.42],[2,9.06]],"batb":[[0,1.84,9.03]],"batl":[[0,1.85,20.85]],"ltp":1.86,"tv":3837.39,"id":31372},{"trd":[[2.12,211.13],[2.14,254.18],[2.16,260.36],[2.28,13.62]],"ltp":2.16,"tv":856.6,"id":31375}],"tv":4694.0}]}
{"op":"mcm","clk":"11748146447","pt":1722478399963,"mc":[{"id":"1.231282919","rc":[{"trd":[[1.79,189.78],[1.82,169.9],[1.85,1320.85],[1.86,369.59],[1.87,562.93],[1.88,396.37]],"batb":[[0,1.84,18.06]],"batl":[[0,1.86,73.64],[1,1.87,573.1],[2,1.88,400]],"ltp":1.86,"tv":4044.16,"id":31372},{"trd":[[2.16,446.37]],"batb":[[0,2.08,10]],"ltp":2.16,"tv":1042.61,"id":31375}],"tv":5086.78}]}
{"op":"mcm","clk":"11748146595","pt":1722478403169,"mc":[{"id":"1.231282919","rc":[{"batb":[[0,2.06,34.87],[1,1.43,116.28],[2,1.38,131.58]],"ltp":2.16,"tv":1042.61,"id":31375}]}]}
{"op":"mcm","clk":"11748146712","pt":1722478405652,"mc":[{"id":"1.231282919","rc":[{"batb":[[0,2.08,10],[1,2.06,34.87],[2,1.43,116.28]],"ltp":2.16,"tv":1042.61,"id":31375}]}]}
{"op":"mcm","clk":"11748146892","pt":1722478409068,"mc":[{"id":"1.231282919","rc":[{"batb":[[0,2.06,34.87],[1,1.43,116.28],[2,1.38,131.58]],"ltp":2.16,"tv":1042.61,"id":31375}]}]}
{"op":"mcm","clk":"11748146923","pt":1722478409750,"mc":[{"id":"1.231282919","rc":[{"trd":[[1.86,443.23]],"batl":[[0,1.87,573.1],[1,1.88,400],[2,1.89,303.47]],"ltp":1.86,"tv":4117.8,"id":31372},{"trd":[[2.16,509.78]],"batl":[[0,2.16,9.39],[1,2.2,100]],"ltp":2.16,"tv":1106.02,"id":31375}],"tv":5223.83}]}
{"op":"mcm","clk":"11748146995","pt":1722478411663,"mc":[{"id":"1.231282919","rc":[{"batb":[[0,1.84,9.03]],"ltp":1.86,"tv":4117.8,"id":31372},{"batb":[[0,2.14,4],[1,2.08,10],[2,2.06,34.87]],"ltp":2.16,"tv":1106.02,"id":31375}]}]}
{"op":"mcm","clk":"11748147011","pt":1722478411864,"mc":[{"id":"1.231282919","rc":[{"batb":[[0,1.86,42.98],[1,1.84,9.03],[2,1.79,11.87]],"batl":[[0,1.87,577.1]],"ltp":1.86,"tv":4117.8,"id":31372}]}]}
{"op":"mcm","clk":"11748147115","pt":1722478413633,"mc":[{"id":"1.231282919","rc":[{"batb":[[1,1.79,11.87],[2,1.43,116.28]],"ltp":1.86,"tv":4117.8,"id":31372}]}]}
{"op":"mcm","clk":"11748147169","pt":1722478414664,"mc":[{"id":"1.231282919","rc":[{"batb":[[0,1.86,59.73]],"ltp":1.86,"tv":4117.8,"id":31372},{"batb":[[1,2.06,34.87],[2,1.43,116.28]],"ltp":2.16,"tv":1106.02,"id":31375}]}]}
{"op":"mcm","clk":"11748147819","pt":1722478427970,"mc":[{"id":"1.231282919","rc":[{"batb":[[1,1.83,36.09],[2,1.79,11.87]],"ltp":1.86,"tv":4117.8,"id":31372},{"batb":[[0,2.14,35]],"ltp":2.16,"tv":1106.02,"id":31375}]}]}
{"op":"mcm","clk":"11748148034","pt":1722478432084,"mc":[{"id":"1.231282919","rc":[{"batb":[[0,1.86,16.75]],"ltp":1.86,"tv":4117.8,"id":31372},{"batb":[[1,1.43,116.28],[2,1.38,131.58]],"ltp":2.16,"tv":1106.02,"id":31375}]}]}
{"op":"mcm","clk":"11748148119","pt":1722478434097,"mc":[{"id":"1.231282919","rc":[{"batb":[[0,1.84,16.94]],"ltp":1.86,"tv":4117.8,"id":31372}]}]}
{"op":"mcm","clk":"11748148314","pt":1722478437664,"mc":[{"id":"1.231282919","rc":[{"batb":[[0,1.86,42.98]],"ltp":1.86,"tv":4117.8,"id":31372},{"batb":[[1,2.06,34.87],[2,1.43,116.28]],"ltp":2.16,"tv":1106.02,"id":31375}]}]}
{"op":"mcm","clk":"11748148679","pt":1722478446017,"mc":[{"id":"1.231282919","rc":[{"trd":[[1.87,637.43]],"batl":[[0,1.87,502.6]],"ltp":1.87,"tv":4192.3,"id":31372},{"trd":[[2.14,389.28]],"batb":[[0,2.08,10]],"ltp":2.14,"tv":1241.13,"id":31375}],"tv":5433.44}]}
{"op":"mcm","clk":"11748148769","pt":1722478447990,"mc":[{"id":"1.231282919","rc":[{"batb":[[0,1.86,59.73]],"ltp":1.87,"tv":4192.3,"id":31372}]}]}
{"op":"mcm","clk":"11748148837","pt":1722478449399,"mc":[{"id":"1.231282919","rc":[{"batb":[[0,2.06,34.87],[1,1.43,116.28],[2,1.38,131.58]],"ltp":2.14,"tv":1241.13,"id":31375}]}]}
{"op":"mcm","clk":"11748148972","pt":1722478451718,"mc":[{"id":"1.231282919","rc":[{"batb":[[0,2.08,10],[1,2.06,34.87],[2,1.43,116.28]],"ltp":2.14,"tv":1241.13,"id":31375}]}]}
{"op":"mcm","clk":"11748149133","pt":1722478454985,"mc":[{"id":"1.231282919","rc":[{"batb":[[0,2.06,34.87],[1,1.43,116.28],[2,1.38,131.58]],"ltp":2.14,"tv":1241.13,"id":31375}]}]}
{"op":"mcm","clk":"11748149224","pt":1722478457006,"mc":[{"id":"1.231282919","rc":[{"batb":[[0,2.14,4],[1,2.06,34.87],[2,1.43,116.28]],"ltp":2.14,"tv":1241.13,"id":31375}]}]}
{"op":"mcm","clk":"11748149684","pt":1722478467110,"mc":[{"id":"1.231282919","rc":[{"trd":[[1.87,643.6]],"batl":[[0,1.87,496.43]],"ltp":1.87,"tv":4198.47,"id":31372},{"trd":[[2.14,402.67]],"batb":[[0,2.08,10]],"batl":[[0,2.2,100],[1,2.2,0]],"ltp":2.14,"tv":1254.52,"id":31375}],"tv":5453.0}]}
{"op":"mcm","clk":"11748149890","pt":1722478470636,"mc":[{"id":"1.231282919","rc":[{"batb":[[0,2.06,34.87],[1,1.43,116.28],[2,1.38,131.58]],"ltp":2.14,"tv":1254.52,"id":31375}]}]}
{"op":"mcm","clk":"11748149963","pt":1722478472137,"mc":[{"id":"1.231282919","rc":[{"batb":[[0,2.14,4],[1,2.06,34.87],[2,1.43,116.28]],"ltp":2.14,"tv":1254.52,"id":31375}]}]}
{"op":"mcm","clk":"11748181776","pt":1722479117934,"mc":[{"id":"1.231282919","rc":[{"trd":[[1.87,899.38]],"batl":[[0,1.87,240.65]],"ltp":1.87,"tv":4454.25,"id":31372},{"trd":[[2.14,634.18]],"batb":[[0,2.08,10]],"ltp":2.14,"tv":1486.03,"id":31375}],"tv":5940.29}]}
{"op":"mcm","clk":"11748181953","pt":1722479121218,"mc":[{"id":"1.231282919","rc":[{"batb":[[0,2.14,4]],"ltp":2.14,"tv":1486.03,"id":31375}]}]}
{"op":"mcm","clk":"11748212944","pt":1722479901437,"mc":[{"id":"1.231282919","rc":[{"trd":[[1.86,522.89]],"batb":[[0,1.86,19.9]],"ltp":1.86,"tv":4533.91,"id":31372}],"tv":6019.95}]}
{"op":"mcm","clk":"11748212990","pt":1722479902625,"mc":[{"id":"1.231282919","rc":[{"batb":[[0,1.86,3.15],[1,1.84,28.68],[2,1.83,36.09]],"ltp":1.86,"tv":4533.91,"id":31372}]}]}
{"op":"mcm","clk":"11748213018","pt":1722479903442,"mc":[{"id":"1.231282919","rc":[{"batb":[[0,1.84,28.68],[1,1.83,36.09],[2,1.82,45.07]],"batl":[[0,1.86,11.2],[1,1.87,240.65],[2,1.88,400]],"ltp":1.86,"tv":4533.91,"id":31372},{"batb":[[0,2.16,10.44],[1,2.14,4],[2,2.06,34.87]],"ltp":2.14,"tv":1486.03,"id":31375}]}]}
{"op":"mcm","clk":"11748213073","pt":1722479904931,"mc":[{"id":"1.231282919","rc":[{"batb":[[0,1.84,32.68]],"batl":[[0,1.86,15.2]],"ltp":1.86,"tv":4533.91,"id":31372},{"batb":[[0,2.16,14.44]],"ltp":2.14,"tv":1486.03,"id":31375}]}]}
{"op":"mcm","clk":"11748213115","pt":1722479906217,"mc":[{"id":"1.231282919","rc":[{"batb":[[0,2.16,4]],"ltp":2.14,"tv":1486.03,"id":31375}]}]}
{"op":"mcm","clk":"11748403806","pt":1722484806710,"mc":[{"id":"1.231282919","rc":[{"trd":[[1.78,5.1],[1.79,189.74],[1.82,169.92],[1.85,1320.86],[1.86,522.91],[1.87,899.4],[1.88,396.42],[1.94,8.43],[2,9.06]],"batb":[[0,1.85,180.32],[1,1.84,32.7],[2,1.83,36.06]],"batl":[[0,1.86,11.21]],"ltp":1.86,"tv":4534.0,"id":31372},{"trd":[[2.12,211.13],[2.14,634.21],[2.16,509.83]],"batb":[[0,2.14,4],[1,2.06,34.87],[2,1.43,116.28]],"ltp":2.14,"tv":1486.12,"id":31375}],"tv":6020.12}]}
{"op":"mcm","clk":"11748403832","pt":1722484807532,"mc":[{"id":"1.231282919","rc":[{"batb":[[1,1.84,4]],"batl":[[0,1.87,240.65],[1,1.88,400],[2,1.89,303.47]],"ltp":1.86,"tv":4534.0,"id":31372}]}]}
{"op":"mcm","clk":"11748403991","pt":1722484813026,"mc":[{"id":"1.231282919","rc":[{"batb":[[0,1.86,16.76],[1,1.85,180.32],[2,1.84,4]],"ltp":1.86,"tv":4534.0,"id":31372}]}]}
{"op":"mcm","clk":"11748404017","pt":1722484814050,"mc":[{"id":"1.231282919","rc":[{"batb":[[2,1.83,36.06]],"ltp":1.86,"tv":4534.0,"id":31372}]}]}
{"op":"mcm","clk":"11748404224","pt":1722484821028,"mc":[{"id":"1.231282919","rc":[{"batl":[[0,2.18,4],[1,2.2,100]],"ltp":2.14,"tv":1486.12,"id":31375}]}]}
{"op":"mcm","clk":"11748404290","pt":1722484823439,"mc":[{"id":"1.231282919","rc":[{"batb":[[1,1.83,36.06],[2,1.82,45.07]],"ltp":1.86,"tv":4534.0,"id":31372},{"batl":[[0,2.2,100],[1,2.2,0]],"ltp":2.14,"tv":1486.12,"id":31375}]}]}
{"op":"mcm","clk":"11748404308","pt":1722484823950,"mc":[{"id":"1.231282919","rc":[{"batb":[[0,1.84,28.69]],"ltp":1.86,"tv":4534.0,"id":31372},{"batb":[[0,2.16,14.59],[1,2.14,4],[2,2.06,34.87]],"ltp":2.14,"tv":1486.12,"id":31375}]}]}
{"op":"mcm","clk":"11748404424","pt":1722484828563,"mc":[{"id":"1.231282919","rc":[{"batl":[[0,1.86,12.03],[1,1.87,240.65],[2,1.88,400]],"ltp":1.86,"tv":4534.0,"id":31372},{"batb":[[0,2.16,25.02]],"batl":[[0,2.18,6],[1,2.2,100]],"ltp":2.14,"tv":1486.12,"id":31375}]}]}
{"op":"mcm","clk":"11748404443","pt":1722484828972,"mc":[{"id":"1.231282919","rc":[{"batb":[[2,1.79,11.87]],"ltp":1.86,"tv":4534.0,"id":31372},{"batb":[[2,1.43,116.28]],"ltp":2.14,"tv":1486.12,"id":31375}]}]}
{"op":"mcm","clk":"11748404498","pt":1722484830871,"mc":[{"id":"1.231282919","rc":[{"batb":[[0,2.16,14.59]],"batl":[[0,2.2,100],[1,2.2,0]],"ltp":2.14,"tv":1486.12,"id":31375}]}]}
{"op":"mcm","clk":"11748404668","pt":1722484836061,"mc":[{"id":"1.231282919","rc":[{"batb":[[0,1.84,32.69]],"batl":[[0,1.86,16.03]],"ltp":1.86,"tv":4534.0,"id":31372},{"batb":[[0,2.16,18.59]],"ltp":2.14,"tv":1486.12,"id":31375}]}]}
{"op":"mcm","clk":"11748405853","pt":1722484865703,"mc":[{"id":"1.231282919","rc":[{"batb":[[0,1.85,180.32],[1,1.84,32.69],[2,1.83,36.06]],"ltp":1.86,"tv":4534.0,"id":31372}]}]}
{"op":"mcm","clk":"11748405883","pt":1722484866282,"mc":[{"id":"1.231282919","rc":[{"batb":[[0,1.85,184.32]],"batl":[[0,1.87,240.65],[1,1.88,400],[2,1.89,303.47]],"ltp":1.86,"tv":4534.0,"id":31372},{"batb":[[0,2.16,14.59]],"batl":[[0,2.18,4],[1,2.2,100]],"ltp":2.14,"tv":1486.12,"id":31375}]}]}
{"op":"mcm","clk":"11748405938","pt":1722484867606,"mc":[{"id":"1.231282919","rc":[{"batb":[[1,1.84,4]],"ltp":1.86,"tv":4534.0,"id":31372},{"batb":[[0,2.14,4],[1,1.43,116.28],[2,1.38,131.58]],"ltp":2.14,"tv":1486.12,"id":31375}]}]}
{"op":"mcm","clk":"11748405957","pt":1722484868020,"mc":[{"id":"1.231282919","rc":[{"batb":[[0,1.86,16.76],[1,1.85,180.32]],"ltp":1.86,"tv":4534.0,"id":31372}]}]}
{"op":"mcm","clk":"11748406019","pt":1722484869001,"mc":[{"id":"1.231282919","rc":[{"batb":[[1,2.06,34.87],[2,1.43,116.28]],"ltp":2.14,"tv":1486.12,"id":31375}]}]}
{"op":"mcm","clk":"11748407023","pt":1722484898536,"mc":[{"id":"1.231282919","rc":[{"batb":[[1,1.83,36.06],[2,1.82,45.07]],"ltp":1.86,"tv":4534.0,"id":31372},{"batl":[[0,2.2,100],[1,2.2,0]],"ltp":2.14,"tv":1486.12,"id":31375}]}]}
{"op":"mcm","clk":"11748407067","pt":1722484899633,"mc":[{"id":"1.231282919","rc":[{"batb":[[0,1.83,36.06],[1,1.82,45.07],[2,1.79,11.87]],"ltp":1.86,"tv":4534.0,"id":31372}]}]}
{"op":"mcm","clk":"11748407075","pt":1722484899739,"mc":[{"id":"1.231282919","rc":[{"batb":[[0,1.84,28.69],[1,1.83,36.06],[2,1.82,45.07]],"ltp":1.86,"tv":4534.0,"id":31372},{"batb":[[0,2.16,14.59],[1,2.14,4],[2,2.06,34.87]],"batl":[[0,2.18,7.32],[1,2.2,100]],"ltp":2.14,"tv":1486.12,"id":31375}]}]}
{"op":"mcm","clk":"11748407213","pt":1722484904223,"mc":[{"id":"1.231282919","rc":[{"batb":[[2,1.79,11.87]],"ltp":1.86,"tv":4534.0,"id":31372},{"batb":[[2,1.43,116.28]],"ltp":2.14,"tv":1486.12,"id":31375}]}]}
{"op":"mcm","clk":"11748407460","pt":1722484911676,"mc":[{"id":"1.231282919","rc":[{"batb":[[0,2.16,18.59]],"ltp":2.14,"tv":1486.12,"id":31375}]}]}
{"op":"mcm","clk":"11748408355","pt":1722484939397,"mc":[{"id":"1.231282919","rc":[{"trd":[[1.87,1402.17],[1.88,683.64]],"batb":[[2,1.82,45.07]],"batl":[[0,1.88,256.39],[1,1.89,303.47],[2,1.9,300]],"ltp":1.88,"tv":5323.99,"id":31372},{"trd":[[2.16,528.42]],"batb":[[0,2.14,4],[1,2.06,34.87]],"ltp":2.16,"tv":1504.71,"id":31375}],"tv":6828.7}]}
{"op":"mcm","clk":"11748408380","pt":1722484940165,"mc":[{"id":"1.231282919","rc":[{"batl":[[0,2.18,17.18]],"ltp":2.16,"tv":1504.71,"id":31375}]}]}
{"op":"mcm","clk":"11748408437","pt":1722484942377,"mc":[{"id":"1.231282919","rc":[{"batb":[[0,1.84,32.69]],"batl":[[0,1.88,260.39]],"ltp":1.88,"tv":5323.99,"id":31372}]}]}
{"op":"mcm","clk":"11748410063","pt":1722484987340,"mc":[{"id":"1.231282919","rc":[{"batl":[[0,2.16,4],[1,2.18,17.18],[2,2.2,100]],"ltp":2.16,"tv":1504.71,"id":31375}]}]}
{"op":"mcm","clk":"11748410092","pt":1722484987955,"mc":[{"id":"1.231282919","rc":[{"batb":[[0,1.84,28.69]],"ltp":1.88,"tv":5323.99,"id":31372}]}]}
{"op":"mcm","clk":"11748414513","pt":1722485123627,"mc":[{"id":"1.231282919","rc":[{"batl":[[0,1.87,12.4],[1,1.88,260.39],[2,1.89,303.47]],"ltp":1.88,"tv":5323.99,"id":31372},{"batl":[[0,2.18,17.18],[1,2.2,100],[2,2.2,0]],"ltp":2.16,"tv":1504.71,"id":31375}]}]}
{"op":"mcm","clk":"11748414999","pt":1722485137980,"mc":[{"id":"1.231282919","rc":[{"batb":[[0,1.85,4],[1,1.84,32.69],[2,1.83,36.06]],"batl":[[0,1.87,16.4]],"ltp":1.88,"tv":5323.99,"id":31372},{"batl":[[0,2.18,21.18]],"ltp":2.16,"tv":1504.71,"id":31375}]}]}
{"op":"mcm","clk":"11748587057","pt":1722490974780,"mc":[{"id":"1.231282919","rc":[{"trd":[[1.78,5.1],[1.79,189.76],[1.82,169.91],[1.85,1320.85],[1.86,522.9],[1.87,1402.16],[1.88,683.61],[1.94,8.43],[2,9.06]],"batb":[[1,1.84,32.68],[2,1.83,36.07]],"batl":[[0,1.87,16.39]],"ltp":1.88,"tv":5323.94,"id":31372},{"trd":[[2.12,211.13],[2.14,634.26],[2.16,528.43],[2.28,13.62]],"batl":[[0,2.18,21.17]],"ltp":2.16,"tv":1504.76,"id":31375}],"tv":6828.71}]}
{"op":"mcm","clk":"11748595847","pt":1722491079508,"mc":[{"id":"1.231282919","rc":[{"batb":[[0,1.85,94]],"ltp":1.88,"tv":5323.94,"id":31372}]}]}
{"op":"mcm","clk":"11748595899","pt":1722491081606,"mc":[{"id":"1.231282919","rc":[{"batb":[[1,1.84,4]],"ltp":1.88,"tv":5323.94,"id":31372}]}]}
{"op":"mcm","clk":"11748595922","pt":1722491082423,"mc":[{"id":"1.231282919","rc":[{"batb":[[0,1.86,16.76],[1,1.85,90]],"ltp":1.88,"tv":5323.94,"id":31372}]}]}
{"op":"mcm","clk":"11748596160","pt":1722491094708,"mc":[{"id":"1.231282919","rc":[{"batl":[[0,2.16,4],[1,2.18,21.17],[2,2.2,100]],"ltp":2.16,"tv":1504.76,"id":31375}]}]}
{"op":"mcm","clk":"11748596195","pt":1722491096617,"mc":[{"id":"1.231282919","rc":[{"batl":[[0,1.87,4]],"ltp":1.88,"tv":5323.94,"id":31372}]}]}
{"op":"mcm","clk":"11748596200","pt":1722491096904,"mc":[{"id":"1.231282919","rc":[{"batl":[[0,1.88,260.39],[1,1.89,303.47],[2,1.9,300]],"ltp":1.88,"tv":5323.94,"id":31372}]}]}
{"op":"mcm","clk":"11748596229","pt":1722491098436,"mc":[{"id":"1.231282919","rc":[{"batb":[[0,2.14,19.11]],"ltp":2.16,"tv":1504.76,"id":31375}]}]}
{"op":"mcm","clk":"11748596238","pt":1722491098903,"mc":[{"id":"1.231282919","rc":[{"batb":[[1,1.43,116.28],[2,1.38,131.58]],"ltp":2.16,"tv":1504.76,"id":31375}]}]}
{"op":"mcm","clk":"11748596588","pt":1722491112546,"mc":[{"id":"1.231282919","rc":[{"batb":[[0,1.86,23.52]],"ltp":1.88,"tv":5323.94,"id":31372}]}]}
{"op":"mcm","clk":"11748597074","pt":1722491134565,"mc":[{"id":"1.231282919","rc":[{"trd":[[1.88,1214]],"batl":[[0,1.89,303.47],[1,1.9,300],[2,1.95,261.1]],"ltp":1.88,"tv":5854.33,"id":31372},{"trd":[[2.14,642.7]],"batb":[[0,2.14,10.67]],"ltp":2.14,"tv":1513.2,"id":31375}],"tv":7367.54}]}
{"op":"mcm","clk":"11748597092","pt":1722491135339,"mc":[{"id":"1.231282919","rc":[{"batl":[[0,1.88,14.29],[1,1.89,303.47],[2,1.9,300]],"ltp":1.88,"tv":5854.33,"id":31372}]}]}
{"op":"mcm","clk":"11748597112","pt":1722491136567,"mc":[{"id":"1.231282919","rc":[{"batb":[[1,1.83,36.07],[2,1.79,11.87]],"ltp":1.88,"tv":5854.33,"id":31372}]}]}
{"op":"mcm","clk":"11748597140","pt":1722491137849,"mc":[{"id":"1.231282919","rc":[{"batb":[[0,1.86,6.76],[1,1.85,16.85],[2,1.83,36.07]],"ltp":1.88,"tv":5854.33,"id":31372}]}]}
{"op":"mcm","clk":"11748597176","pt":1722491139856,"mc":[{"id":"1.231282919","rc":[{"batb":[[2,1.84,36.07]],"batl":[[0,1.88,18.29]],"ltp":1.88,"tv":5854.33,"id":31372},{"batb":[[0,2.14,14.67]],"ltp":2.14,"tv":1513.2,"id":31375}]}]}
{"op":"mcm","clk":"11748598501","pt":1722491205035,"mc":[{"id":"1.231282919","rc":[{"batb":[[1,1.85,106.85]],"ltp":1.88,"tv":5854.33,"id":31372}]}]}
{"op":"mcm","clk":"11748598593","pt":1722491210328,"mc":[{"id":"1.231282919","rc":[{"batb":[[1,1.85,142.41],[2,1.79,11.87]],"ltp":1.88,"tv":5854.33,"id":31372}]}]}
{"op":"mcm","clk":"11748598707","pt":1722491215362,"mc":[{"id":"1.231282919","rc":[{"batb":[[0,1.86,10.76]],"ltp":1.88,"tv":5854.33,"id":31372}]}]}
{"op":"mcm","clk":"11748600940","pt":1722491321350,"mc":[{"id":"1.231282919","rc":[{"batb":[[0,1.86,17.14]],"ltp":1.88,"tv":5854.33,"id":31372}]}]}
{"op":"mcm","clk":"11748601310","pt":1722491339488,"mc":[{"id":"1.231282919","rc":[{"batl":[[0,2.16,11.89]],"ltp":2.14,"tv":1513.2,"id":31375}]}]}
{"op":"mcm","clk":"11748601343","pt":1722491341289,"mc":[{"id":"1.231282919","rc":[{"batb":[[0,1.86,10.76]],"batl":[[0,1.88,4]],"ltp":1.88,"tv":5854.33,"id":31372}]}]}
{"op":"mcm","clk":"11748601634","pt":1722491354692,"mc":[{"id":"1.231282919","rc":[{"trd":[[1.88,1238.69],[1.89,897.43]],"batb":[[2,1.82,45.07]],"batl":[[0,1.89,234.16],[1,1.9,300],[2,1.95,261.1]],"ltp":1.89,"tv":6017.64,"id":31372},{"trd":[[2.14,657.36]],"batb":[[0,2.06,34.87]],"ltp":2.14,"tv":1527.87,"id":31375}],"tv":7545.51}]}
{"op":"mcm","clk":"11748601652","pt":1722491355201,"mc":[{"id":"1.231282919","rc":[{"batb":[[0,1.86,6.76]],"batl":[[0,1.88,10.89],[1,1.89,234.16],[2,1.9,300]],"ltp":1.89,"tv":6017.64,"id":31372}]}]}
{"op":"mcm","clk":"11748601869","pt":1722491366243,"mc":[{"id":"1.231282919","rc":[{"batb":[[0,1.86,10.76]],"batl":[[0,1.88,14.89]],"ltp":1.89,"tv":6017.64,"id":31372},{"batb":[[0,2.12,4],[1,2.06,34.87],[2,1.43,116.28]],"ltp":2.14,"tv":1527.87,"id":31375}]}]}
{"op":"mcm","clk":"11748603162","pt":1722491426679,"mc":[{"id":"1.231282919","rc":[{"batl":[[0,2.16,19.31]],"ltp":2.14,"tv":1527.87,"id":31375}]}]}
{"op":"mcm","clk":"11748603213","pt":1722491428381,"mc":[{"id":"1.231282919","rc":[{"batl":[[0,2.14,14.72],[1,2.16,19.31],[2,2.18,11.31]],"ltp":2.14,"tv":1527.87,"id":31375}]}]}
{"op":"mcm","clk":"11748603278","pt":1722491430383,"mc":[{"id":"1.231282919","rc":[{"batl":[[0,2.14,15.11],[1,2.16,14.36]],"ltp":2.14,"tv":1527.87,"id":31375}]}]}
{"op":"mcm","clk":"11748603336","pt":1722491432287,"mc":[{"id":"1.231282919","rc":[{"batl":[[0,1.88,4]],"ltp":1.89,"tv":6017.64,"id":31372},{"batl":[[0,2.16,29.33],[1,2.18,11.31],[2,2.2,100]],"ltp":2.14,"tv":1527.87,"id":31375}]}]}
{"op":"mcm","clk":"11748603352","pt":1722491432898,"mc":[{"id":"1.231282919","rc":[{"batb":[[1,1.85,125.56]],"ltp":1.89,"tv":6017.64,"id":31372}]}]}
{"op":"mcm","clk":"11748603543","pt":1722491441688,"mc":[{"id":"1.231282919","rc":[{"batb":[[0,1.87,4],[1,1.86,10.76],[2,1.85,125.56]],"ltp":1.89,"tv":6017.64,"id":31372}]}]}
{"op":"mcm","clk":"11748603572","pt":1722491443017,"mc":[{"id":"1.231282919","rc":[{"batl":[[0,1.88,15.08]],"ltp":1.89,"tv":6017.64,"id":31372}]}]}
{"op":"mcm","clk":"11748621776","pt":1722492178487,"mc":[{"id":"1.231282919","rc":[{"trd":[[1.79,189.83],[1.82,169.91],[1.85,1320.85],[1.86,522.91],[1.87,1402.16],[1.88,1238.7],[1.94,8.43]],"batb":[[0,1.87,144.09],[1,1.86,10.76],[2,1.85,125.6]],"batl":[[0,1.88,15.08]],"ltp":1.89,"tv":6017.75,"id":31372},{"trd":[[2.12,211.13],[2.14,657.46],[2.16,528.48]],"batb":[[0,2.12,36.25]],"batl":[[0,2.16,60.99],[1,2.18,11.31]],"ltp":2.14,"tv":1528.02,"id":31375}],"tv":7545.77}]}
{"op":"mcm","clk":"11748621789","pt":1722492179100,"mc":[{"id":"1.231282919","rc":[{"batl":[[0,1.89,234.16],[1,1.9,300],[2,1.95,261.1]],"ltp":1.89,"tv":6017.75,"id":31372}]}]}
{"op":"mcm","clk":"11748621829","pt":1722492180698,"mc":[{"id":"1.231282919","rc":[{"batb":[[0,1.88,16.58],[1,1.87,144.09],[2,1.86,4]],"batl":[[0,1.89,238.16]],"ltp":1.89,"tv":6017.75,"id":31372},{"batl":[[1,2.18,4]],"ltp":2.14,"tv":1528.02,"id":31375}]}]}
{"op":"mcm","clk":"11748621878","pt":1722492182693,"mc":[{"id":"1.231282919","rc":[{"batb":[[1,1.43,116.28],[2,1.38,131.58]],"batl":[[0,2.16,46.02]],"ltp":2.14,"tv":1528.02,"id":31375}]}]}
{"op":"mcm","clk":"11748621880","pt":1722492182797,"mc":[{"id":"1.231282919","rc":[{"batl":[[0,2.14,15.11],[1,2.16,46.02],[2,2.18,4]],"ltp":2.14,"tv":1528.02,"id":31375}]}]}
{"op":"mcm","clk":"11748622210","pt":1722492196404,"mc":[{"id":"1.231282919","rc":[{"batb":[[1,1.87,4]],"ltp":1.89,"tv":6017.75,"id":31372}]}]}
{"op":"mcm","clk":"11748622254","pt":1722492197585,"mc":[{"id":"1.231282919","rc":[{"batb":[[1,1.85,125.6],[2,1.79,11.87]],"ltp":1.89,"tv":6017.75,"id":31372},{"batl":[[1,2.16,42.02],[2,2.2,100]],"ltp":2.14,"tv":1528.02,"id":31375}]}]}
{"op":"mcm","clk":"11748622609","pt":1722492213635,"mc":[{"id":"1.231282919","rc":[{"trd":[[1.88,1271.4]],"batb":[[0,1.85,125.6],[1,1.79,11.87],[2,1.43,116.28]],"ltp":1.88,"tv":6050.44,"id":31372}],"tv":7578.47}]}
{"op":"mcm","clk":"11748622690","pt":1722492217627,"mc":[{"id":"1.231282919","rc":[{"batb":[[1,1.82,45.07],[2,1.79,11.87]],"ltp":1.88,"tv":6050.44,"id":31372},{"batb":[[1,2.06,34.87],[2,1.43,116.28]],"ltp":2.14,"tv":1528.02,"id":31375}]}]}
{"op":"mcm","clk":"11748622694","pt":1722492217731,"mc":[{"id":"1.231282919","rc":[{"batl":[[1,2.16,10.36]],"ltp":2.14,"tv":1528.02,"id":31375}]}]}
{"op":"mcm","clk":"11748622744","pt":1722492219635,"mc":[{"id":"1.231282919","rc":[{"batl":[[0,2.16,30.56],[1,2.2,100],[2,2.2,0]],"ltp":2.14,"tv":1528.02,"id":31375}]}]}
{"op":"mcm","clk":"11748622760","pt":1722492220134,"mc":[{"id":"1.231282919","rc":[{"batl":[[0,1.88,16.4],[1,1.89,238.16],[2,1.9,300]],"ltp":1.88,"tv":6050.44,"id":31372}]}]}
{"op":"mcm","clk":"11748622798","pt":1722492221931,"mc":[{"id":"1.231282919","rc":[{"batl":[[0,1.88,27.48]],"ltp":1.88,"tv":6050.44,"id":31372}]}]}
{"op":"mcm","clk":"11748622853","pt":1722492225211,"mc":[{"id":"1.231282919","rc":[{"batb":[[0,1.87,140.09],[1,1.85,125.6],[2,1.82,45.07]],"ltp":1.88,"tv":6050.44,"id":31372},{"batl":[[0,2.16,60.5]],"ltp":2.14,"tv":1528.02,"id":31375}]}]}
{"op":"mcm","clk":"11748622898","pt":1722492226608,"mc":[{"id":"1.231282919","rc":[{"batb":[[0,1.87,144.09]],"batl":[[0,1.89,238.16],[1,1.9,300],[2,1.95,261.1]],"ltp":1.88,"tv":6050.44,"id":31372},{"batl":[[0,2.16,49.54]],"ltp":2.14,"tv":1528.02,"id":31375}]}]}
{"op":"mcm","clk":"11748622910","pt":1722492227836,"mc":[{"id":"1.231282919","rc":[{"batb":[[2,1.79,11.87]],"ltp":1.88,"tv":6050.44,"id":31372},{"batb":[[1,1.43,116.28],[2,1.38,131.58]],"ltp":2.14,"tv":1528.02,"id":31375}]}]}
{"op":"mcm","clk":"11748623021","pt":1722492232644,"mc":[{"id":"1.231282919","rc":[{"trd":[[1.87,1682.34]],"batb":[[0,1.87,4]],"ltp":1.87,"tv":6330.62,"id":31372},{"batl":[[0,2.16,19.6]],"ltp":2.14,"tv":1528.02,"id":31375}],"tv":7858.64}]}
{"op":"mcm","clk":"11748623029","pt":1722492232855,"mc":[{"id":"1.231282919","rc":[{"batb":[[0,1.85,125.6],[1,1.82,45.07]],"ltp":1.87,"tv":6330.62,"id":31372},{"batb":[[1,2.06,34.87],[2,1.43,116.28]],"ltp":2.14,"tv":1528.02,"id":31375}]}]}
{"op":"mcm","clk":"11748623053","pt":1722492233930,"mc":[{"id":"1.231282919","rc":[{"batl":[[0,2.16,27.6]],"ltp":2.14,"tv":1528.02,"id":31375}]}]}
{"op":"mcm","clk":"11748623169","pt":1722492241029,"mc":[{"id":"1.231282919","rc":[{"batb":[[0,1.86,4],[1,1.85,125.6],[2,1.82,45.07]],"ltp":1.87,"tv":6330.62,"id":31372}]}]}
{"op":"mcm","clk":"11748623737","pt":1722492262863,"mc":[{"id":"1.231282919","rc":[{"batb":[[0,1.87,263.06],[1,1.86,4],[2,1.85,125.6]],"ltp":1.87,"tv":6330.62,"id":31372},{"batl":[[0,2.16,65.56]],"ltp":2.14,"tv":1528.02,"id":31375}]}]}
{"op":"mcm","clk":"11748623792","pt":1722492264967,"mc":[{"id":"1.231282919","rc":[{"trd":[[1.87,2208.45]],"batb":[[0,1.86,4],[1,1.85,125.6],[2,1.82,45.07]],"ltp":1.87,"tv":6856.73,"id":31372},{"batl":[[0,2.16,27.6]],"ltp":2.14,"tv":1528.02,"id":31375}],"tv":8384.75}]}
{"op":"mcm","clk":"11748623817","pt":1722492265988,"mc":[{"id":"1.231282919","rc":[{"batl":[[0,1.88,16.4],[1,1.89,238.16],[2,1.9,300]],"ltp":1.87,"tv":6856.73,"id":31372}]}]}
{"op":"mcm","clk":"11748623926","pt":1722492271161,"mc":[{"id":"1.231282919","rc":[{"batl":[[0,1.88,20.4]],"ltp":1.87,"tv":6856.73,"id":31372}]}]}
{"op":"mcm","clk":"11748625213","pt":1722492331460,"mc":[{"id":"1.231282919","rc":[{"batb":[[0,1.87,267.06],[1,1.86,4],[2,1.85,125.6]],"batl":[[0,1.88,16.4]],"ltp":1.87,"tv":6856.73,"id":31372}]}]}
{"op":"mcm","clk":"11748625217","pt":1722492331767,"mc":[{"id":"1.231282919","rc":[{"batl":[[0,1.89,238.16],[1,1.9,300],[2,1.95,261.1]],"ltp":1.87,"tv":6856.73,"id":31372}]}]}
{"op":"mcm","clk":"11748625248","pt":1722492333252,"mc":[{"id":"1.231282919","rc":[{"batb":[[1,1.43,116.28],[2,1.38,131.58]],"ltp":2.14,"tv":1528.02,"id":31375}]}]}
{"op":"mcm","clk":"11748625274","pt":1722492334378,"mc":[{"id":"1.231282919","rc":[{"trd":[[1.87,2734.56]],"batb":[[0,1.85,125.6],[1,1.79,11.87],[2,1.43,116.28]],"batl":[[0,1.88,16.4],[1,1.89,238.16],[2,1.9,300]],"ltp":1.87,"tv":7382.84,"id":31372}],"tv":8910.87}]}
{"op":"mcm","clk":"11748625282","pt":1722492334946,"mc":[{"id":"1.231282919","rc":[{"batl":[[0,1.88,27.48]],"ltp":1.87,"tv":7382.84,"id":31372}]}]}
{"op":"mcm","clk":"11748625327","pt":1722492338268,"mc":[{"id":"1.231282919","rc":[{"batb":[[1,1.82,45.07],[2,1.79,11.87]],"ltp":1.87,"tv":7382.84,"id":31372},{"batb":[[1,2.06,34.87],[2,1.43,116.28]],"ltp":2.14,"tv":1528.02,"id":31375}]}]}
{"op":"mcm","clk":"11748625415","pt":1722492343384,"mc":[{"id":"1.231282919","rc":[{"batb":[[0,1.87,263.06],[1,1.85,125.6]],"ltp":1.87,"tv":7382.84,"id":31372},{"batb":[[1,1.43,116.28],[2,1.38,131.58]],"ltp":2.14,"tv":1528.02,"id":31375}]}]}
{"op":"mcm","clk":"11748625426","pt":1722492343953,"mc":[{"id":"1.231282919","rc":[{"batl":[[0,1.88,16.4]],"ltp":1.87,"tv":7382.84,"id":31372}]}]}
{"op":"mcm","clk":"11748625440","pt":1722492344773,"mc":[{"id":"1.231282919","rc":[{"batl":[[0,1.89,238.16],[1,1.9,300],[2,1.95,261.1]],"ltp":1.87,"tv":7382.84,"id":31372}]}]}
{"op":"mcm","clk":"11748625487","pt":1722492346582,"mc":[{"id":"1.231282919","rc":[{"trd":[[1.87,3260.67]],"batb":[[0,1.87,4]],"ltp":1.87,"tv":7908.95,"id":31372}],"tv":9436.98}]}
{"op":"mcm","clk":"11748625498","pt":1722492347047,"mc":[{"id":"1.231282919","rc":[{"batb":[[0,1.85,125.6],[1,1.79,11.87],[2,1.43,116.28]],"ltp":1.87,"tv":7908.95,"id":31372}]}]}
{"op":"mcm","clk":"11748625517","pt":1722492348280,"mc":[{"id":"1.231282919","rc":[{"batb":[[1,1.82,45.07],[2,1.79,11.87]],"ltp":1.87,"tv":7908.95,"id":31372},{"batb":[[1,2.06,34.87],[2,1.43,116.28]],"ltp":2.14,"tv":1528.02,"id":31375}]}]}
{"op":"mcm","clk":"11748625572","pt":1722492353262,"mc":[{"id":"1.231282919","rc":[{"batb":[[0,1.87,263.06],[1,1.85,125.6],[2,1.82,45.07]],"ltp":1.87,"tv":7908.95,"id":31372}]}]}
{"op":"mcm","clk":"11748625646","pt":1722492357356,"mc":[{"id":"1.231282919","rc":[{"trd":[[1.87,3786.78]],"batb":[[0,1.85,125.6],[1,1.82,45.07],[2,1.79,11.87]],"ltp":1.87,"tv":8435.06,"id":31372}],"tv":9963.09}]}
{"op":"mcm","clk":"11748625787","pt":1722492361709,"mc":[{"id":"1.231282919","rc":[{"batb":[[0,1.86,4],[1,1.85,125.6],[2,1.82,45.07]],"ltp":1.87,"tv":8435.06,"id":31372}]}]}
{"op":"mcm","clk":"11748625819","pt":1722492363502,"mc":[{"id":"1.231282919","rc":[{"batb":[[0,1.87,263.06],[1,1.86,4],[2,1.85,125.6]],"ltp":1.87,"tv":8435.06,"id":31372},{"batl":[[0,2.16,65.56]],"ltp":2.14,"tv":1528.02,"id":31375}]}]}
{"op":"mcm","clk":"11748625838","pt":1722492364480,"mc":[{"id":"1.231282919","rc":[{"batb":[[0,1.87,298.66],[2,1.85,90]],"ltp":1.87,"tv":8435.06,"id":31372}]}]}
{"op":"mcm","clk":"11748625882","pt":1722492367299,"mc":[{"id":"1.231282919","rc":[{"trd":[[1.87,4312.9]],"batb":[[0,1.87,35.6]],"ltp":1.87,"tv":8961.18,"id":31372},{"batl":[[0,2.16,27.6]],"ltp":2.14,"tv":1528.02,"id":31375}],"tv":10489.2}]}
{"op":"mcm","clk":"11748625911","pt":1722492368521,"mc":[{"id":"1.231282919","rc":[{"batb":[[1,1.85,90],[2,1.79,11.87]],"ltp":1.87,"tv":8961.18,"id":31372},{"batb":[[1,1.43,116.28],[2,1.38,131.58]],"ltp":2.14,"tv":1528.02,"id":31375}]}]}
{"op":"mcm","clk":"11748626009","pt":1722492373097,"mc":[{"id":"1.231282919","rc":[{"batb":[[0,1.87,298.66]],"ltp":1.87,"tv":8961.18,"id":31372},{"batl":[[0,2.16,62.48]],"ltp":2.14,"tv":1528.02,"id":31375}]}]}
{"op":"mcm","clk":"11748626135","pt":1722492376996,"mc":[{"id":"1.231282919","rc":[{"batb":[[0,1.87,35.6]],"ltp":1.87,"tv":8961.18,"id":31372}]}]}
{"op":"mcm","clk":"11748626747","pt":1722492407542,"mc":[{"id":"1.231282919","rc":[{"batb":[[0,1.88,260.72],[1,1.87,35.6],[2,1.85,90]],"ltp":1.87,"tv":8961.18,"id":31372},{"batl":[[0,2.16,54.48]],"ltp":2.14,"tv":1528.02,"id":31375}]}]}
{"op":"mcm","clk":"11748626781","pt":1722492408875,"mc":[{"id":"1.231282919","rc":[{"batl":[[0,2.14,15.11],[1,2.16,49.24],[2,2.2,100]],"ltp":2.14,"tv":1528.02,"id":31375}]}]}
{"op":"mcm","clk":"11748626861","pt":1722492411960,"mc":[{"id":"1.231282919","rc":[{"trd":[[1.87,4317.56],[1.88,1792.84]],"batb":[[0,1.87,33.27],[1,1.85,90],[2,1.79,11.87]],"ltp":1.87,"tv":9487.29,"id":31372}],"tv":11015.31}]}
{"op":"mcm","clk":"11748626881","pt":1722492412781,"mc":[{"id":"1.231282919","rc":[{"batl":[[1,2.16,45.24]],"ltp":2.14,"tv":1528.02,"id":31375}]}]}
{"op":"mcm","clk":"11748627052","pt":1722492421579,"mc":[{"id":"1.231282919","rc":[{"batb":[[0,1.88,263.06],[1,1.87,33.27],[2,1.85,90]],"ltp":1.87,"tv":9487.29,"id":31372}]}]}
{"op":"mcm","clk":"11748627314","pt":1722492432960,"mc":[{"id":"1.231282919","rc":[{"trd":[[1.88,2314.28]],"batb":[[0,1.88,2.33]],"ltp":1.88,"tv":10008.73,"id":31372}],"tv":11536.75}]}
{"op":"mcm","clk":"11748627393","pt":1722492436401,"mc":[{"id":"1.231282919","rc":[{"batb":[[0,1.87,33.27],[1,1.85,90],[2,1.79,11.87]],"ltp":1.88,"tv":10008.73,"id":31372}]}]}
{"op":"mcm","clk":"11748627471","pt":1722492439273,"mc":[{"id":"1.231282919","rc":[{"batb":[[0,1.85,123.57],[1,1.79,11.87],[2,1.43,116.28]],"ltp":1.88,"tv":10008.73,"id":31372},{"batl":[[1,2.16,10.36]],"ltp":2.14,"tv":1528.02,"id":31375}]}]}
{"op":"mcm","clk":"11748627522","pt":1722492441474,"mc":[{"id":"1.231282919","rc":[{"batl":[[0,1.88,16.4],[1,1.89,238.16],[2,1.9,300]],"ltp":1.88,"tv":10008.73,"id":31372},{"batl":[[0,2.16,30.48],[1,2.2,100],[2,2.2,0]],"ltp":2.14,"tv":1528.02,"id":31375}]}]}
{"op":"mcm","clk":"11748627576","pt":1722492443013,"mc":[{"id":"1.231282919","rc":[{"batl":[[0,1.88,27.48]],"ltp":1.88,"tv":10008.73,"id":31372}]}]}
{"op":"mcm","clk":"11748627587","pt":1722492443778,"mc":[{"id":"1.231282919","rc":[{"batb":[[1,1.82,45.07],[2,1.79,11.87]],"ltp":1.88,"tv":10008.73,"id":31372},{"batb":[[1,2.06,34.87],[2,1.43,116.28]],"ltp":2.14,"tv":1528.02,"id":31375}]}]}
{"op":"mcm","clk":"11748627785","pt":1722492452093,"mc":[{"id":"1.231282919","rc":[{"batb":[[0,1.86,4],[1,1.85,123.57],[2,1.82,45.07]],"batl":[[0,1.88,31.48]],"ltp":1.88,"tv":10008.73,"id":31372},{"batl":[[0,2.16,34.48]],"ltp":2.14,"tv":1528.02,"id":31375}]}]}
{"op":"mcm","clk":"11748627819","pt":1722492453796,"mc":[{"id":"1.231282919","rc":[{"batl":[[0,1.88,20.4]],"ltp":1.88,"tv":10008.73,"id":31372}]}]}
{"op":"mcm","clk":"11748628014","pt":1722492463318,"mc":[{"id":"1.231282919","rc":[{"trd":[[1.88,2355.07]],"batb":[[0,1.88,256.96],[1,1.86,4],[2,1.85,123.57]],"batl":[[0,1.89,238.16],[1,1.9,300],[2,1.95,261.1]],"ltp":1.88,"tv":10049.52,"id":31372},{"batl":[[0,2.16,71.43]],"ltp":2.14,"tv":1528.02,"id":31375}],"tv":11577.55}]}
{"op":"mcm","clk":"11748628028","pt":1722492463831,"mc":[{"id":"1.231282919","rc":[{"batb":[[1,1.43,116.28],[2,1.38,131.58]],"ltp":2.14,"tv":1528.02,"id":31375}]}]}
{"op":"mcm","clk":"11748628066","pt":1722492464754,"mc":[{"id":"1.231282919","rc":[{"batl":[[0,2.16,51.31]],"ltp":2.14,"tv":1528.02,"id":31375}]}]}
{"op":"mcm","clk":"11748628130","pt":1722492467215,"mc":[{"id":"1.231282919","rc":[{"batb":[[0,1.88,260.96]],"ltp":1.88,"tv":10049.52,"id":31372}]}]}
{"op":"mcm","clk":"11748628192","pt":1722492470236,"mc":[{"id":"1.231282919","rc":[{"trd":[[1.86,527.12],[1.88,2876.99]],"batb":[[0,1.86,1.9],[1,1.85,123.57],[2,1.79,11.87]],"ltp":1.86,"tv":10575.64,"id":31372},{"batl":[[0,2.16,14.36]],"ltp":2.14,"tv":1528.02,"id":31375}],"tv":12103.66}]}
{"op":"mcm","clk":"11748628208","pt":1722492471260,"mc":[{"id":"1.231282919","rc":[{"batl":[[0,2.16,22.36]],"ltp":2.14,"tv":1528.02,"id":31375}]}]}
{"op":"mcm","clk":"11748628278","pt":1722492473867,"mc":[{"id":"1.231282919","rc":[{"batb":[[2,1.82,45.07]],"ltp":1.86,"tv":10575.64,"id":31372},{"batb":[[1,2.06,34.87],[2,1.43,116.28]],"ltp":2.14,"tv":1528.02,"id":31375}]}]}
{"op":"mcm","clk":"11748628557","pt":1722492484157,"mc":[{"id":"1.231282919","rc":[{"batb":[[0,1.87,263.06],[1,1.86,1.9],[2,1.85,123.57]],"ltp":1.86,"tv":10575.64,"id":31372},{"batl":[[0,2.16,59.66]],"ltp":2.14,"tv":1528.02,"id":31375}]}]}
{"op":"mcm","clk":"11748628666","pt":1722492488963,"mc":[{"id":"1.231282919","rc":[{"batb":[[1,1.43,116.28],[2,1.38,131.58]],"ltp":2.14,"tv":1528.02,"id":31375}]}]}
{"op":"mcm","clk":"11748628866","pt":1722492497658,"mc":[{"id":"1.231282919","rc":[{"trd":[[1.87,4831.22]],"batb":[[0,1.87,10.23]],"ltp":1.87,"tv":11089.3,"id":31372}],"tv":12617.32}]}
{"op":"mcm","clk":"11748628882","pt":1722492498374,"mc":[{"id":"1.231282919","rc":[{"batb":[[0,1.85,123.57],[1,1.79,11.87],[2,1.43,116.28]],"batl":[[0,1.88,16.63],[1,1.89,238.16],[2,1.9,300]],"ltp":1.87,"tv":11089.3,"id":31372},{"batl":[[0,2.16,22.36]],"ltp":2.14,"tv":1528.02,"id":31375}]}]}
{"op":"mcm","clk":"11748628891","pt":1722492498987,"mc":[{"id":"1.231282919","rc":[{"batb":[[1,1.82,45.07],[2,1.79,11.87]],"ltp":1.87,"tv":11089.3,"id":31372},{"batb":[[1,2.06,34.87],[2,1.43,116.28]],"ltp":2.14,"tv":1528.02,"id":31375}]}]}
{"op":"mcm","clk":"11748629134","pt":1722492508582,"mc":[{"id":"1.231282919","rc":[{"batl":[[0,2.14,15.11],[1,2.16,22.36],[2,2.2,100]],"ltp":2.14,"tv":1528.02,"id":31375}]}]}
{"op":"mcm","clk":"11748629152","pt":1722492509298,"mc":[{"id":"1.231282919","rc":[{"batl":[[1,2.16,18.36]],"ltp":2.14,"tv":1528.02,"id":31375}]}]}
{"op":"mcm","clk":"11748629174","pt":1722492510521,"mc":[{"id":"1.231282919","rc":[{"batl":[[0,1.89,238.16],[1,1.9,300],[2,1.95,261.1]],"ltp":1.87,"tv":11089.3,"id":31372},{"batl":[[1,2.16,10.36]],"ltp":2.14,"tv":1528.02,"id":31375}]}]}
{"op":"mcm","clk":"11748629192","pt":1722492511595,"mc":[{"id":"1.231282919","rc":[{"batl":[[0,2.16,10.36],[1,2.2,100],[2,2.2,0]],"ltp":2.14,"tv":1528.02,"id":31375}]}]}
{"op":"mcm","clk":"11748629220","pt":1722492512620,"mc":[{"id":"1.231282919","rc":[{"batb":[[0,1.87,256.83],[1,1.86,4],[2,1.85,123.57]],"ltp":1.87,"tv":11089.3,"id":31372},{"batl":[[0,2.16,22.5]],"ltp":2.14,"tv":1528.02,"id":31375}]}]}
{"op":"mcm","clk":"11748629225","pt":1722492512720,"mc":[{"id":"1.231282919","rc":[{"batl":[[0,2.16,59.54]],"ltp":2.14,"tv":1528.02,"id":31375}]}]}
{"op":"mcm","clk":"11748629256","pt":1722492514101,"mc":[{"id":"1.231282919","rc":[{"batb":[[1,1.43,116.28],[2,1.38,131.58]],"ltp":2.14,"tv":1528.02,"id":31375}]}]}
{"op":"mcm","clk":"11748629321","pt":1722492517681,"mc":[{"id":"1.231282919","rc":[{"trd":[[1.87,5344.88]],"batb":[[0,1.86,4],[1,1.85,123.57],[2,1.79,11.87]],"ltp":1.87,"tv":11602.95,"id":31372},{"batl":[[0,2.16,22.5]],"ltp":2.14,"tv":1528.02,"id":31375}],"tv":13130.98}]}
{"op":"mcm","clk":"11748629343","pt":1722492519118,"mc":[{"id":"1.231282919","rc":[{"batb":[[2,1.82,45.07]],"ltp":1.87,"tv":11602.95,"id":31372},{"batb":[[1,2.06,34.87],[2,1.43,116.28]],"ltp":2.14,"tv":1528.02,"id":31375}]}]}
{"op":"mcm","clk":"11748629473","pt":1722492524234,"mc":[{"id":"1.231282919","rc":[{"batb":[[0,1.87,256.83],[1,1.86,4],[2,1.85,123.57]],"ltp":1.87,"tv":11602.95,"id":31372},{"batb":[[1,1.43,116.28],[2,1.38,131.58]],"batl":[[0,2.16,59.54]],"ltp":2.14,"tv":1528.02,"id":31375}]}]}
{"op":"mcm","clk":"11748629539","pt":1722492527610,"mc":[{"id":"1.231282919","rc":[{"batb":[[0,1.87,260.83]],"ltp":1.87,"tv":11602.95,"id":31372}]}]}
{"op":"mcm","clk":"11748629553","pt":1722492528528,"mc":[{"id":"1.231282919","rc":[{"trd":[[1.87,5858.54]],"batb":[[0,1.87,4]],"ltp":1.87,"tv":12116.61,"id":31372}],"tv":13644.64}]}
{"op":"mcm","clk":"11748629558","pt":1722492529191,"mc":[{"id":"1.231282919","rc":[{"batb":[[0,1.85,123.57],[1,1.79,11.87],[2,1.43,116.28]],"ltp":1.87,"tv":12116.61,"id":31372},{"batl":[[0,2.16,22.5]],"ltp":2.14,"tv":1528.02,"id":31375}]}]}
{"op":"mcm","clk":"11748629667","pt":1722492534099,"mc":[{"id":"1.231282919","rc":[{"batb":[[1,1.82,45.07],[2,1.79,11.87]],"ltp":1.87,"tv":12116.61,"id":31372},{"batb":[[1,2.06,34.87],[2,1.43,116.28]],"ltp":2.14,"tv":1528.02,"id":31375}]}]}
{"op":"mcm","clk":"11748629835","pt":1722492542033,"mc":[{"id":"1.231282919","rc":[{"batl":[[0,1.88,27.72],[1,1.89,238.16],[2,1.9,300]],"ltp":1.87,"tv":12116.61,"id":31372}]}]}
{"op":"mcm","clk":"11748629854","pt":1722492542754,"mc":[{"id":"1.231282919","rc":[{"batb":[[0,1.86,4],[1,1.85,123.57],[2,1.82,45.07]],"batl":[[0,1.88,31.72]],"ltp":1.87,"tv":12116.61,"id":31372}]}]}
{"op":"mcm","clk":"11748629904","pt":1722492544234,"mc":[{"id":"1.231282919","rc":[{"batl":[[0,1.88,20.63]],"ltp":1.87,"tv":12116.61,"id":31372}]}]}
{"op":"mcm","clk":"11748629951","pt":1722492546230,"mc":[{"id":"1.231282919","rc":[{"batb":[[0,1.87,256.83],[1,1.86,4],[2,1.85,123.57]],"ltp":1.87,"tv":12116.61,"id":31372},{"batl":[[0,2.16,59.54]],"ltp":2.14,"tv":1528.02,"id":31375}]}]}
{"op":"mcm","clk":"11748629987","pt":1722492547666,"mc":[{"id":"1.231282919","rc":[{"batl":[[0,1.89,238.16],[1,1.9,300],[2,1.95,261.1]],"ltp":1.87,"tv":12116.61,"id":31372}]}]}
{"op":"mcm","clk":"11748630034","pt":1722492549364,"mc":[{"id":"1.231282919","rc":[{"batb":[[1,1.43,116.28],[2,1.38,131.58]],"ltp":2.14,"tv":1528.02,"id":31375}]}]}
{"op":"mcm","clk":"11748630049","pt":1722492550131,"mc":[{"id":"1.231282919","rc":[{"trd":[[1.87,6372.2]],"batb":[[0,1.86,4],[1,1.85,123.57],[2,1.79,11.87]],"ltp":1.87,"tv":12630.27,"id":31372},{"batl":[[0,2.16,22.5]],"ltp":2.14,"tv":1528.02,"id":31375}],"tv":14158.29}]}
{"op":"mcm","clk":"11748630125","pt":1722492554223,"mc":[{"id":"1.231282919","rc":[{"batb":[[2,1.82,45.07]],"ltp":1.87,"tv":12630.27,"id":31372},{"batb":[[1,2.06,34.87],[2,1.43,116.28]],"ltp":2.14,"tv":1528.02,"id":31375}]}]}
{"op":"mcm","clk":"11748630163","pt":1722492556065,"mc":[{"id":"1.231282919","rc":[{"batb":[[0,1.87,256.83],[1,1.86,4],[2,1.85,123.57]],"ltp":1.87,"tv":12630.27,"id":31372},{"batl":[[0,2.16,59.54]],"ltp":2.14,"tv":1528.02,"id":31375}]}]}
{"op":"mcm","clk":"11748630207","pt":1722492557753,"mc":[{"id":"1.231282919","rc":[{"batb":[[0,1.87,260.83]],"ltp":1.87,"tv":12630.27,"id":31372}]}]}
{"op":"mcm","clk":"11748630241","pt":1722492559338,"mc":[{"id":"1.231282919","rc":[{"batb":[[1,1.43,116.28],[2,1.38,131.58]],"ltp":2.14,"tv":1528.02,"id":31375}]}]}
{"op":"mcm","clk":"11748630264","pt":1722492560466,"mc":[{"id":"1.231282919","rc":[{"trd":[[1.87,6885.86]],"batb":[[0,1.85,123.57],[1,1.79,11.87],[2,1.43,116.28]],"ltp":1.87,"tv":13143.93,"id":31372},{"batl":[[0,2.16,22.5]],"ltp":2.14,"tv":1528.02,"id":31375}],"tv":14671.95}]}
{"op":"mcm","clk":"11748630376","pt":1722492564249,"mc":[{"id":"1.231282919","rc":[{"batb":[[1,1.82,45.07],[2,1.79,11.87]],"ltp":1.87,"tv":13143.93,"id":31372},{"batb":[[1,2.06,34.87],[2,1.43,116.28]],"ltp":2.14,"tv":1528.02,"id":31375}]}]}
{"op":"mcm","clk":"11748630567","pt":1722492572895,"mc":[{"id":"1.231282919","rc":[{"batb":[[0,1.86,4],[1,1.85,123.57],[2,1.82,45.07]],"ltp":1.87,"tv":13143.93,"id":31372}]}]}
{"op":"mcm","clk":"11748630828","pt":1722492583585,"mc":[{"id":"1.231282919","rc":[{"batl":[[0,1.88,16.63],[1,1.89,238.16],[2,1.9,300]],"ltp":1.87,"tv":13143.93,"id":31372}]}]}
{"op":"mcm","clk":"11748630980","pt":1722492587998,"mc":[{"id":"1.231282919","rc":[{"batl":[[0,1.88,20.63]],"ltp":1.87,"tv":13143.93,"id":31372}]}]}
{"op":"mcm","clk":"11748631294","pt":1722492602376,"mc":[{"id":"1.231282919","rc":[{"batl":[[0,2.14,15.11],[1,2.16,22.5],[2,2.2,100]],"ltp":2.14,"tv":1528.02,"id":31375}]}]}
{"op":"mcm","clk":"11748631355","pt":1722492604271,"mc":[{"id":"1.231282919","rc":[{"batl":[[0,1.88,4]],"ltp":1.87,"tv":13143.93,"id":31372}]}]}
{"op":"mcm","clk":"11748631389","pt":1722492605401,"mc":[{"id":"1.231282919","rc":[{"batb":[[0,1.85,123.57],[1,1.82,45.07],[2,1.79,11.87]],"batl":[[0,1.89,238.16],[1,1.9,300],[2,1.95,261.1]],"ltp":1.87,"tv":13143.93,"id":31372}]}]}
{"op":"mcm","clk":"11748632217","pt":1722492637409,"mc":[{"id":"1.231282919","rc":[{"trd":[[1.87,6889.75]],"ltp":1.87,"tv":13147.82,"id":31372},{"trd":[[2.14,660.86]],"batl":[[0,2.14,11.7]],"ltp":2.14,"tv":1531.42,"id":31375}],"tv":14679.25}]}
{"op":"mcm","clk":"11748632283","pt":1722492639611,"mc":[{"id":"1.231282919","rc":[{"batl":[[0,1.88,27.72],[1,1.89,238.16],[2,1.9,300]],"ltp":1.87,"tv":13147.82,"id":31372},{"batl":[[1,2.16,18.5]],"ltp":2.14,"tv":1531.42,"id":31375}]}]}
{"op":"mcm","clk":"11748632355","pt":1722492641711,"mc":[{"id":"1.231282919","rc":[{"batl":[[0,2.16,10.36],[1,2.2,100],[2,2.2,0]],"ltp":2.14,"tv":1531.42,"id":31375}]}]}
{"op":"mcm","clk":"11748632359","pt":1722492641814,"mc":[{"id":"1.231282919","rc":[{"batl":[[0,2.16,27.11]],"ltp":2.14,"tv":1531.42,"id":31375}]}]}
{"op":"mcm","clk":"11748632407","pt":1722492643511,"mc":[{"id":"1.231282919","rc":[{"batl":[[0,2.16,34.99]],"ltp":2.14,"tv":1531.42,"id":31375}]}]}
{"op":"mcm","clk":"11748632452","pt":1722492645587,"mc":[{"id":"1.231282919","rc":[{"batb":[[0,1.87,256.83],[1,1.85,123.57],[2,1.82,45.07]],"ltp":1.87,"tv":13147.82,"id":31372}]}]}
{"op":"mcm","clk":"11748632465","pt":1722492646016,"mc":[{"id":"1.231282919","rc":[{"batl":[[0,1.88,11.08]],"ltp":1.87,"tv":13147.82,"id":31372},{"batl":[[0,2.16,67.56]],"ltp":2.14,"tv":1531.42,"id":31375}]}]}
{"op":"mcm","clk":"11748632495","pt":1722492647450,"mc":[{"id":"1.231282919","rc":[{"batl":[[0,1.89,238.16],[1,1.9,300],[2,1.95,261.1]],"ltp":1.87,"tv":13147.82,"id":31372}]}]}
{"op":"mcm","clk":"11748632517","pt":1722492648322,"mc":[{"id":"1.231282919","rc":[{"batb":[[0,1.87,260.83]],"ltp":1.87,"tv":13147.82,"id":31372},{"batl":[[0,2.16,71.56]],"ltp":2.14,"tv":1531.42,"id":31375}]}]}
{"op":"mcm","clk":"11748632544","pt":1722492649549,"mc":[{"id":"1.231282919","rc":[{"trd":[[1.87,7403.41]],"batb":[[0,1.87,4]],"ltp":1.87,"tv":13661.48,"id":31372}],"tv":15192.91}]}
{"op":"mcm","clk":"11748632550","pt":1722492649856,"mc":[{"id":"1.231282919","rc":[{"batb":[[0,1.85,123.57],[1,1.82,45.07],[2,1.79,11.87]],"ltp":1.87,"tv":13661.48,"id":31372},{"batl":[[0,2.16,33.84]],"ltp":2.14,"tv":1531.42,"id":31375}]}]}
{"op":"mcm","clk":"11748632634","pt":1722492653853,"mc":[{"id":"1.231282919","rc":[{"batb":[[0,1.87,256.83],[1,1.85,123.57],[2,1.82,45.07]],"ltp":1.87,"tv":13661.48,"id":31372},{"batl":[[0,2.16,71.47]],"ltp":2.14,"tv":1531.42,"id":31375}]}]}
{"op":"mcm","clk":"11748632655","pt":1722492654931,"mc":[{"id":"1.231282919","rc":[{"batb":[[2,1.79,11.87]],"ltp":1.87,"tv":13661.48,"id":31372},{"batb":[[1,1.43,116.28],[2,1.38,131.58]],"ltp":2.14,"tv":1531.42,"id":31375}]}]}
{"op":"mcm","clk":"11748632731","pt":1722492658562,"mc":[{"id":"1.231282919","rc":[{"trd":[[1.87,7917.07]],"batb":[[0,1.85,123.57],[1,1.79,11.87],[2,1.43,116.28]],"ltp":1.87,"tv":14175.14,"id":31372},{"batl":[[0,2.16,33.84]],"ltp":2.14,"tv":1531.42,"id":31375}],"tv":15706.57}]}
{"op":"mcm","clk":"11748632763","pt":1722492659840,"mc":[{"id":"1.231282919","rc":[{"batb":[[1,1.82,45.07],[2,1.79,11.87]],"ltp":1.87,"tv":14175.14,"id":31372},{"batb":[[1,2.06,34.87],[2,1.43,116.28]],"ltp":2.14,"tv":1531.42,"id":31375}]}]}
{"op":"mcm","clk":"11748632859","pt":1722492663483,"mc":[{"id":"1.231282919","rc":[{"batb":[[0,1.86,4],[1,1.85,123.57],[2,1.82,45.07]],"ltp":1.87,"tv":14175.14,"id":31372}]}]}
{"op":"mcm","clk":"11748632872","pt":1722492664048,"mc":[{"id":"1.231282919","rc":[{"batb":[[0,1.87,256.83],[1,1.86,4],[2,1.85,123.57]],"ltp":1.87,"tv":14175.14,"id":31372},{"batl":[[0,2.16,71.73]],"ltp":2.14,"tv":1531.42,"id":31375}]}]}
{"op":"mcm","clk":"11748632899","pt":1722492664975,"mc":[{"id":"1.231282919","rc":[{"batb":[[1,1.43,116.28],[2,1.38,131.58]],"ltp":2.14,"tv":1531.42,"id":31375}]}]}
{"op":"mcm","clk":"11748632943","pt":1722492666570,"mc":[{"id":"1.231282919","rc":[{"batb":[[0,1.87,289.89],[2,1.85,90]],"ltp":1.87,"tv":14175.14,"id":31372}]}]}
{"op":"mcm","clk":"11748632952","pt":1722492666983,"mc":[{"id":"1.231282919","rc":[{"trd":[[1.87,8430.72]],"batb":[[0,1.87,33.06]],"ltp":1.87,"tv":14688.8,"id":31372}],"tv":16220.22}]}
{"op":"mcm","clk":"11748633070","pt":1722492671956,"mc":[{"id":"1.231282919","rc":[{"batb":[[0,1.87,289.89]],"ltp":1.87,"tv":14688.8,"id":31372}]}]}
{"op":"mcm","clk":"11748633188","pt":1722492675798,"mc":[{"id":"1.231282919","rc":[{"batb":[[0,1.87,33.06]],"ltp":1.87,"tv":14688.8,"id":31372}]}]}
{"op":"mcm","clk":"11748633267","pt":1722492678469,"mc":[{"id":"1.231282919","rc":[{"batb":[[0,1.87,37.06]],"ltp":1.87,"tv":14688.8,"id":31372}]}]}
{"op":"mcm","clk":"11748633372","pt":1722492681178,"mc":[{"id":"1.231282919","rc":[{"batb":[[0,1.88,256.83],[1,1.87,37.06],[2,1.86,4]],"ltp":1.87,"tv":14688.8,"id":31372}]}]}
{"op":"mcm","clk":"11748633386","pt":1722492681996,"mc":[{"id":"1.231282919","rc":[{"batl":[[0,2.16,61.36]],"ltp":2.14,"tv":1531.42,"id":31375}]}]}
{"op":"mcm","clk":"11748633409","pt":1722492682763,"mc":[{"id":"1.231282919","rc":[{"batl":[[0,2.16,49.77]],"ltp":2.14,"tv":1531.42,"id":31375}]}]}
{"op":"mcm","clk":"11748633478","pt":1722492685684,"mc":[{"id":"1.231282919","rc":[{"trd":[[1.88,3390.64]],"batb":[[0,1.87,33.06],[1,1.85,90],[2,1.79,11.87]],"ltp":1.88,"tv":15202.46,"id":31372}],"tv":16733.88}]}
{"op":"mcm","clk":"11748633632","pt":1722492690901,"mc":[{"id":"1.231282919","rc":[{"batb":[[0,1.88,256.83],[1,1.87,33.06],[2,1.85,90]],"ltp":1.88,"tv":15202.46,"id":31372}]}]}
{"op":"mcm","clk":"11748633730","pt":1722492693571,"mc":[{"id":"1.231282919","rc":[{"batb":[[0,1.88,260.83]],"ltp":1.88,"tv":15202.46,"id":31372}]}]}
{"op":"mcm","clk":"11748633805","pt":1722492696393,"mc":[{"id":"1.231282919","rc":[{"trd":[[1.88,3904.3]],"batb":[[0,1.87,33.06],[1,1.85,90],[2,1.79,11.87]],"ltp":1.88,"tv":15716.11,"id":31372},{"batl":[[0,2.16,45.77]],"ltp":2.14,"tv":1531.42,"id":31375}],"tv":17247.54}]}
{"op":"mcm","clk":"11748633936","pt":1722492700696,"mc":[{"id":"1.231282919","rc":[{"batl":[[0,2.14,11.7],[1,2.16,45.77],[2,2.2,100]],"ltp":2.14,"tv":1531.42,"id":31375}]}]}
{"op":"mcm","clk":"11748633952","pt":1722492701310,"mc":[{"id":"1.231282919","rc":[{"batb":[[0,1.88,256.83],[1,1.87,33.06],[2,1.85,90]],"ltp":1.88,"tv":15716.11,"id":31372}]}]}
{"op":"mcm","clk":"11748634046","pt":1722492704591,"mc":[{"id":"1.231282919","rc":[{"trd":[[1.88,4417.96]],"batb":[[0,1.87,33.06],[1,1.85,90],[2,1.79,11.87]],"ltp":1.88,"tv":16229.77,"id":31372}],"tv":17761.2}]}
{"op":"mcm","clk":"11748634238","pt":1722492710230,"mc":[{"id":"1.231282919","rc":[{"batb":[[0,1.88,256.83],[1,1.87,33.06],[2,1.85,90]],"ltp":1.88,"tv":16229.77,"id":31372}]}]}
{"op":"mcm","clk":"11748634301","pt":1722492713100,"mc":[{"id":"1.231282919","rc":[{"trd":[[1.88,4931.62]],"batb":[[0,1.87,33.06],[1,1.85,90],[2,1.79,11.87]],"ltp":1.88,"tv":16743.43,"id":31372}],"tv":18274.86}]}
{"op":"mcm","clk":"11748634430","pt":1722492717736,"mc":[{"id":"1.231282919","rc":[{"batb":[[0,1.88,256.83],[1,1.87,33.06],[2,1.85,90]],"ltp":1.88,"tv":16743.43,"id":31372}]}]}
{"op":"mcm","clk":"11748634544","pt":1722492720831,"mc":[{"id":"1.231282919","rc":[{"trd":[[1.88,5445.28]],"batb":[[0,1.87,33.06],[1,1.85,90],[2,1.79,11.87]],"ltp":1.88,"tv":17257.09,"id":31372}],"tv":18788.52}]}
{"op":"mcm","clk":"11748634726","pt":1722492726533,"mc":[{"id":"1.231282919","rc":[{"batb":[[0,1.88,256.83],[1,1.87,33.06],[2,1.85,90]],"ltp":1.88,"tv":17257.09,"id":31372}]}]}
{"op":"mcm","clk":"11748634806","pt":1722492729008,"mc":[{"id":"1.231282919","rc":[{"trd":[[1.88,5958.94]],"batb":[[0,1.87,33.06],[1,1.85,90],[2,1.79,11.87]],"ltp":1.88,"tv":17770.75,"id":31372}],"tv":19302.18}]}
{"op":"mcm","clk":"11748634930","pt":1722492733606,"mc":[{"id":"1.231282919","rc":[{"batb":[[0,1.88,256.83],[1,1.87,33.06],[2,1.85,90]],"ltp":1.88,"tv":17770.75,"id":31372}]}]}
{"op":"mcm","clk":"11748635009","pt":1722492736621,"mc":[{"id":"1.231282919","rc":[{"trd":[[1.88,6472.6]],"batb":[[0,1.87,33.06],[1,1.85,90],[2,1.79,11.87]],"ltp":1.88,"tv":18284.41,"id":31372}],"tv":19815.83}]}
{"op":"mcm","clk":"11748635031","pt":1722492737437,"mc":[{"id":"1.231282919","rc":[{"batb":[[0,1.85,123.57],[1,1.79,11.87],[2,1.43,116.28]],"batl":[[0,1.88,11.08],[1,1.89,238.16],[2,1.9,300]],"ltp":1.88,"tv":18284.41,"id":31372},{"batl":[[1,2.16,7.88]],"ltp":2.14,"tv":1531.42,"id":31375}]}]}
{"op":"mcm","clk":"11748635095","pt":1722492738152,"mc":[{"id":"1.231282919","rc":[{"batl":[[0,1.88,27.72]],"ltp":1.88,"tv":18284.41,"id":31372}]}]}
{"op":"mcm","clk":"11748635130","pt":1722492739636,"mc":[{"id":"1.231282919","rc":[{"batl":[[0,1.88,20.63]],"ltp":1.88,"tv":18284.41,"id":31372},{"batl":[[0,2.16,25.01],[1,2.2,100],[2,2.2,0]],"ltp":2.14,"tv":1531.42,"id":31375}]}]}
{"op":"mcm","clk":"11748635148","pt":1722492740249,"mc":[{"id":"1.231282919","rc":[{"batb":[[1,1.82,45.07],[2,1.79,11.87]],"ltp":1.88,"tv":18284.41,"id":31372},{"batb":[[1,2.06,34.87],[2,1.43,116.28]],"ltp":2.14,"tv":1531.42,"id":31375}]}]}
{"op":"mcm","clk":"11748635250","pt":1722492743627,"mc":[{"id":"1.231282919","rc":[{"trd":[[1.88,6513.86]],"batb":[[0,1.88,252.83],[1,1.85,123.57],[2,1.82,45.07]],"batl":[[0,1.89,238.16],[1,1.9,300],[2,1.95,261.1]],"ltp":1.88,"tv":18325.67,"id":31372},{"batl":[[0,2.16,60.72]],"ltp":2.14,"tv":1531.42,"id":31375}],"tv":19857.1}]}
{"op":"mcm","clk":"11748635311","pt":1722492745366,"mc":[{"id":"1.231282919","rc":[{"batb":[[2,1.79,11.87]],"ltp":1.88,"tv":18325.67,"id":31372},{"batb":[[1,1.43,116.28],[2,1.38,131.58]],"batl":[[0,2.16,43.59]],"ltp":2.14,"tv":1531.42,"id":31375}]}]}
{"op":"mcm","clk":"11748635389","pt":1722492747627,"mc":[{"id":"1.231282919","rc":[{"trd":[[1.88,7019.52]],"batb":[[0,1.85,123.57],[1,1.79,11.87],[2,1.43,116.28]],"batl":[[0,1.88,4],[1,1.89,238.16],[2,1.9,300]],"ltp":1.88,"tv":18831.33,"id":31372}],"tv":20362.76}]}
{"op":"mcm","clk":"11748635421","pt":1722492748642,"mc":[{"id":"1.231282919","rc":[{"batb":[[0,1.86,5.46],[1,1.85,123.57],[2,1.79,11.87]],"ltp":1.88,"tv":18831.33,"id":31372},{"batl":[[0,2.16,7.88]],"ltp":2.14,"tv":1531.42,"id":31375}]}]}
{"op":"mcm","clk":"11748635471","pt":1722492750640,"mc":[{"id":"1.231282919","rc":[{"batb":[[0,1.86,14.52]],"ltp":1.88,"tv":18831.33,"id":31372},{"batl":[[0,2.16,16.69]],"ltp":2.14,"tv":1531.42,"id":31375}]}]}
{"op":"mcm","clk":"11748635557","pt":1722492754025,"mc":[{"id":"1.231282919","rc":[{"batb":[[0,1.87,4],[1,1.86,18.52],[2,1.85,123.57]],"batl":[[0,1.88,8]],"ltp":1.88,"tv":18831.33,"id":31372},{"batl":[[0,2.16,20.69]],"ltp":2.14,"tv":1531.42,"id":31375}]}]}
{"op":"mcm","clk":"11748636219","pt":1722492781361,"mc":[{"id":"1.231282919","rc":[{"batl":[[0,1.88,4]],"ltp":1.88,"tv":18831.33,"id":31372}]}]}
{"op":"mcm","clk":"11748636297","pt":1722492783886,"mc":[{"id":"1.231282919","rc":[{"batl":[[0,1.88,20.63]],"ltp":1.88,"tv":18831.33,"id":31372}]}]}
{"op":"mcm","clk":"11748636332","pt":1722492785173,"mc":[{"id":"1.231282919","rc":[{"batb":[[1,1.86,13.06]],"ltp":1.88,"tv":18831.33,"id":31372}]}]}
{"op":"mcm","clk":"11748636764","pt":1722492799289,"mc":[{"id":"1.231282919","rc":[{"batl":[[0,2.14,11.7],[1,2.16,20.69],[2,2.2,100]],"ltp":2.14,"tv":1531.42,"id":31375}]}]}
{"op":"mcm","clk":"11748636797","pt":1722492800512,"mc":[{"id":"1.231282919","rc":[{"trd":[[2.14,684.27]],"batb":[[0,2.14,182.86],[1,2.12,36.25],[2,1.43,116.28]],"batl":[[0,2.16,16.69],[1,2.2,100],[2,2.2,0]],"ltp":2.14,"tv":1554.83,"id":31375}],"tv":20386.17}]}
{"op":"mcm","clk":"11748636809","pt":1722492800875,"mc":[{"id":"1.231282919","rc":[{"batb":[[0,1.86,9.06],[1,1.85,123.57],[2,1.79,11.87]],"ltp":1.88,"tv":18831.33,"id":31372},{"batl":[[0,2.16,7.88]],"ltp":2.14,"tv":1554.83,"id":31375}]}]}
{"op":"mcm","clk":"11748636898","pt":1722492804513,"mc":[{"id":"1.231282919","rc":[{"trd":[[2.12,234.54],[2.14,1050]],"batb":[[0,2.12,24.55],[1,1.43,116.28],[2,1.38,131.58]],"ltp":2.12,"tv":1943.96,"id":31375}],"tv":20775.3}]}
{"op":"mcm","clk":"11748636921","pt":1722492805386,"mc":[{"id":"1.231282919","rc":[{"batb":[[2,1.82,45.07]],"ltp":1.88,"tv":18831.33,"id":31372},{"batb":[[0,2.06,34.87],[1,1.44,10],[2,1.43,116.28]],"batl":[[0,2.16,16.93]],"ltp":2.12,"tv":1943.96,"id":31375}]}]}
{"op":"mcm","clk":"11748636979","pt":1722492807998,"mc":[{"id":"1.231282919","rc":[{"batb":[[1,1.43,116.28],[2,1.38,131.58]],"ltp":2.12,"tv":1943.96,"id":31375}]}]}
{"op":"mcm","clk":"11748637046","pt":1722492810302,"mc":[{"id":"1.231282919","rc":[{"batb":[[0,2.08,10],[1,2.06,34.87],[2,1.43,116.28]],"ltp":2.12,"tv":1943.96,"id":31375}]}]}
{"op":"mcm","clk":"11748637181","pt":1722492813597,"mc":[{"id":"1.231282919","rc":[{"batb":[[0,2.06,34.87],[1,1.43,116.28],[2,1.38,131.58]],"ltp":2.12,"tv":1943.96,"id":31375}]}]}
{"op":"mcm","clk":"11748637218","pt":1722492814314,"mc":[{"id":"1.231282919","rc":[{"batb":[[0,1.86,13.06]],"ltp":1.88,"tv":18831.33,"id":31372},{"batb":[[0,2.12,4],[1,2.06,34.87],[2,1.43,116.28]],"batl":[[0,2.16,20.93]],"ltp":2.12,"tv":1943.96,"id":31375}]}]}
{"op":"mcm","clk":"11748637261","pt":1722492815602,"mc":[{"id":"1.231282919","rc":[{"batb":[[2,1.79,11.87]],"ltp":1.88,"tv":18831.33,"id":31372},{"batb":[[0,2.14,194.57],[1,2.12,4]],"ltp":2.12,"tv":1943.96,"id":31375}]}]}
{"op":"mcm","clk":"11748637282","pt":1722492816416,"mc":[{"id":"1.231282919","rc":[{"batl":[[0,2.16,13.05]],"ltp":2.12,"tv":1943.96,"id":31375}]}]}
{"op":"mcm","clk":"11748637329","pt":1722492818325,"mc":[{"id":"1.231282919","rc":[{"trd":[[2.14,1439.13]],"batb":[[0,2.12,4],[1,1.43,116.28],[2,1.38,131.58]],"ltp":2.14,"tv":2333.1,"id":31375}],"tv":21164.44}]}
{"op":"mcm","clk":"11748637387","pt":1722492820500,"mc":[{"id":"1.231282919","rc":[{"batb":[[2,1.82,45.07]],"ltp":1.88,"tv":18831.33,"id":31372},{"batb":[[0,2.14,11.44],[1,2.12,4],[2,2.06,34.87]],"ltp":2.14,"tv":2333.1,"id":31375}]}]}
{"op":"mcm","clk":"11748637483","pt":1722492824648,"mc":[{"id":"1.231282919","rc":[{"batb":[[0,2.14,206]],"ltp":2.14,"tv":2333.1,"id":31375}]}]}
{"op":"mcm","clk":"11748637501","pt":1722492825642,"mc":[{"id":"1.231282919","rc":[{"batb":[[2,1.79,11.87]],"ltp":1.88,"tv":18831.33,"id":31372},{"batb":[[2,1.43,116.28]],"ltp":2.14,"tv":2333.1,"id":31375}]}]}
{"op":"mcm","clk":"11748637505","pt":1722492825746,"mc":[{"id":"1.231282919","rc":[{"batb":[[0,2.14,194.57]],"ltp":2.14,"tv":2333.1,"id":31375}]}]}
{"op":"mcm","clk":"11748637562","pt":1722492827516,"mc":[{"id":"1.231282919","rc":[{"batb":[[0,2.12,4],[1,1.43,116.28],[2,1.38,131.58]],"ltp":2.14,"tv":2333.1,"id":31375}]}]}
{"op":"mcm","clk":"11748637663","pt":1722492830548,"mc":[{"id":"1.231282919","rc":[{"batb":[[2,1.82,45.07]],"ltp":1.88,"tv":18831.33,"id":31372},{"batb":[[1,2.06,34.87],[2,1.43,116.28]],"ltp":2.14,"tv":2333.1,"id":31375}]}]}
{"op":"mcm","clk":"11748637814","pt":1722492836416,"mc":[{"id":"1.231282919","rc":[{"batb":[[0,2.14,194.57],[1,2.12,4],[2,2.06,34.87]],"ltp":2.14,"tv":2333.1,"id":31375}]}]}
{"op":"mcm","clk":"11748637911","pt":1722492839549,"mc":[{"id":"1.231282919","rc":[{"trd":[[2.14,1828.27]],"batb":[[0,2.12,4],[1,2.06,34.87],[2,1.43,116.28]],"ltp":2.14,"tv":2722.23,"id":31375}],"tv":21553.57}]}
{"op":"mcm","clk":"11748638053","pt":1722492844553,"mc":[{"id":"1.231282919","rc":[{"batb":[[0,2.14,194.57],[1,2.12,4],[2,2.06,34.87]],"batl":[[0,2.16,18.66]],"ltp":2.14,"tv":2722.23,"id":31375}]}]}
{"op":"mcm","clk":"11748638073","pt":1722492845537,"mc":[{"id":"1.231282919","rc":[{"batl":[[0,2.16,13.05]],"ltp":2.14,"tv":2722.23,"id":31375}]}]}
{"op":"mcm","clk":"11748638076","pt":1722492845738,"mc":[{"id":"1.231282919","rc":[{"batb":[[2,1.79,11.87]],"ltp":1.88,"tv":18831.33,"id":31372},{"batb":[[2,1.43,116.28]],"ltp":2.14,"tv":2722.23,"id":31375}]}]}
{"op":"mcm","clk":"11748638138","pt":1722492847855,"mc":[{"id":"1.231282919","rc":[{"trd":[[2.14,2217.41]],"batb":[[0,2.12,4],[1,1.43,116.28],[2,1.38,131.58]],"ltp":2.14,"tv":3111.37,"id":31375}],"tv":21942.71}]}
{"op":"mcm","clk":"11748638173","pt":1722492848937,"mc":[{"id":"1.231282919","rc":[{"batl":[[0,2.16,21.76]],"ltp":2.14,"tv":3111.37,"id":31375}]}]}
{"op":"mcm","clk":"11748638213","pt":1722492850673,"mc":[{"id":"1.231282919","rc":[{"batb":[[2,1.82,45.07]],"ltp":1.88,"tv":18831.33,"id":31372},{"batb":[[1,2.06,34.87],[2,1.43,116.28]],"ltp":2.14,"tv":3111.37,"id":31375}]}]}
{"op":"mcm","clk":"11748638280","pt":1722492853137,"mc":[{"id":"1.231282919","rc":[{"batb":[[0,2.14,194.57],[1,2.12,4],[2,2.06,34.87]],"ltp":2.14,"tv":3111.37,"id":31375}]}]}
{"op":"mcm","clk":"11748638336","pt":1722492855452,"mc":[{"id":"1.231282919","rc":[{"batl":[[0,2.16,13.05]],"ltp":2.14,"tv":3111.37,"id":31375}]}]}
{"op":"mcm","clk":"11748638350","pt":1722492856165,"mc":[{"id":"1.231282919","rc":[{"batb":[[2,1.79,11.87]],"ltp":1.88,"tv":18831.33,"id":31372},{"trd":[[2.14,2606.54]],"batb":[[0,2.12,4],[1,1.43,116.28],[2,1.38,131.58]],"ltp":2.14,"tv":3500.5,"id":31375}],"tv":22331.84}]}
{"op":"mcm","clk":"11748638453","pt":1722492860671,"mc":[{"id":"1.231282919","rc":[{"batb":[[2,1.82,45.07]],"ltp":1.88,"tv":18831.33,"id":31372},{"batb":[[1,2.06,34.87],[2,1.43,116.28]],"ltp":2.14,"tv":3500.5,"id":31375}]}]}
{"op":"mcm","clk":"11748638461","pt":1722492860876,"mc":[{"id":"1.231282919","rc":[{"batb":[[0,2.14,194.57],[1,2.12,4],[2,2.06,34.87]],"ltp":2.14,"tv":3500.5,"id":31375}]}]}
{"op":"mcm","clk":"11748638536","pt":1722492864069,"mc":[{"id":"1.231282919","rc":[{"trd":[[2.14,2995.68]],"batb":[[0,2.12,4],[1,2.06,34.87],[2,1.43,116.28]],"ltp":2.14,"tv":3889.64,"id":31375}],"tv":22720.98}]}
{"op":"mcm","clk":"11748638681","pt":1722492868790,"mc":[{"id":"1.231282919","rc":[{"batb":[[0,2.14,194.57],[1,2.12,4],[2,2.06,34.87]],"ltp":2.14,"tv":3889.64,"id":31375}]}]}
{"op":"mcm","clk":"11748638730","pt":1722492870789,"mc":[{"id":"1.231282919","rc":[{"batb":[[2,1.79,11.87]],"ltp":1.88,"tv":18831.33,"id":31372},{"batb":[[2,1.43,116.28]],"ltp":2.14,"tv":3889.64,"id":31375}]}]}
{"op":"mcm","clk":"11748638760","pt":1722492871872,"mc":[{"id":"1.231282919","rc":[{"trd":[[2.14,3384.81]],"batb":[[0,2.12,4],[1,1.43,116.28],[2,1.38,131.58]],"ltp":2.14,"tv":4278.77,"id":31375}],"tv":23110.11}]}
{"op":"mcm","clk":"11748638886","pt":1722492876296,"mc":[{"id":"1.231282919","rc":[{"batb":[[2,1.82,45.07]],"ltp":1.88,"tv":18831.33,"id":31372},{"batb":[[0,2.14,194.57],[1,2.12,4],[2,2.06,34.87]],"ltp":2.14,"tv":4278.77,"id":31375}]}]}
{"op":"mcm","clk":"11748638970","pt":1722492880200,"mc":[{"id":"1.231282919","rc":[{"trd":[[2.14,3773.95]],"batb":[[0,2.12,4],[1,2.06,34.87],[2,1.43,116.28]],"ltp":2.14,"tv":4667.91,"id":31375}],"tv":23499.25}]}
{"op":"mcm","clk":"11748639104","pt":1722492886106,"mc":[{"id":"1.231282919","rc":[{"batb":[[0,2.14,194.57],[1,2.12,4],[2,2.06,34.87]],"ltp":2.14,"tv":4667.91,"id":31375}]}]}
{"op":"mcm","clk":"11748639203","pt":1722492889993,"mc":[{"id":"1.231282919","rc":[{"trd":[[2.14,4163.08]],"batb":[[0,2.14,4]],"ltp":2.14,"tv":5057.04,"id":31375}],"tv":23888.38}]}
{"op":"mcm","clk":"11748639231","pt":1722492890916,"mc":[{"id":"1.231282919","rc":[{"batb":[[2,1.79,11.87]],"ltp":1.88,"tv":18831.33,"id":31372},{"batb":[[2,1.43,116.28]],"ltp":2.14,"tv":5057.04,"id":31375}]}]}
{"op":"mcm","clk":"11748639334","pt":1722492895523,"mc":[{"id":"1.231282919","rc":[{"batb":[[0,2.12,4],[1,1.43,116.28],[2,1.38,131.58]],"batl":[[0,2.16,21.76]],"ltp":2.14,"tv":5057.04,"id":31375}]}]}
