{"op":"mcm","clk":"11803150154","pt":1723108868511,"mc":[{"id":"1.231582261","marketDefinition":{"bspMarket":false,"turnInPlayEnabled":true,"persistenceEnabled":true,"marketBaseRate":5.0,"eventId":"33477736","eventTypeId":"4","numberOfWinners":1,"bettingType":"ODDS","marketType":"MATCH_ODDS","marketTime":"2024-08-11T10:00:00.000Z","suspendTime":"2024-08-11T10:00:00.000Z","bspReconciled":false,"complete":true,"inPlay":false,"crossMatching":false,"runnersVoidable":false,"numberOfActiveRunners":2,"betDelay":0,"status":"OPEN","runners":[{"status":"ACTIVE","sortPriority":1,"id":2120,"name":"Warwickshire"},{"status":"ACTIVE","sortPriority":2,"id":655,"name":"Yorkshire"}],"regulators":["MR_INT"],"countryCode":"GB","discountAllowed":false,"timezone":"GMT","openDate":"2024-08-11T10:00:00.000Z","version":6061697140,"name":"Match Odds","eventName":"Warwickshire v Yorkshire"},"rc":[{"batb":[[0,1.01,20]],"ltp":0.0,"tv":0.0,"id":655},{"batb":[[0,1.01,20]],"ltp":0.0,"tv":0.0,"id":2120}]}]}
{"op":"mcm","clk":"11803150196","pt":1723108868920,"mc":[{"id":"1.231582261","marketDefinition":{"bspMarket":false,"turnInPlayEnabled":true,"persistenceEnabled":true,"marketBaseRate":5.0,"eventId":"33477736","eventTypeId":"4","numberOfWinners":1,"bettingType":"ODDS","marketType":"MATCH_ODDS","marketTime":"2024-08-11T10:00:00.000Z","suspendTime":"2024-08-11T10:00:00.000Z","bspReconciled":false,"complete":true,"inPlay":false,"crossMatching":false,"runnersVoidable":false,"numberOfActiveRunners":2,"betDelay":0,"status":"OPEN","runners":[{"status":"ACTIVE","sortPriority":1,"id":2120,"name":"Warwickshire"},{"status":"ACTIVE","sortPriority":2,"id":655,"name":"Yorkshire"}],"regulators":["MR_INT"],"countryCode":"GB","discountAllowed":true,"timezone":"GMT","openDate":"2024-08-11T10:00:00.000Z","version":6061697140,"name":"Match Odds","eventName":"Warwickshire v Yorkshire"},"rc":[{"batb":[[0,1.03,200],[1,1.02,200],[2,1.01,220]],"ltp":0.0,"tv":0.0,"id":655},{"batb":[[0,1.03,200],[1,1.02,200],[2,1.01,220]],"ltp":0.0,"tv":0.0,"id":2120}]}]}
{"op":"mcm","clk":"11803470454","pt":1723114469005,"mc":[{"id":"1.231582261","rc":[{"batb":[[2,1.01,227.89]],"ltp":0.0,"tv":0.0,"id":655},{"batb":[[2,1.01,227.89]],"ltp":0.0,"tv":0.0,"id":2120}]}]}
{"op":"mcm","clk":"11803471058","pt":1723114480657,"mc":[{"id":"1.231582261","rc":[{"batb":[[1,1.02,207.89]],"ltp":0.0,"tv":0.0,"id":655},{"batb":[[1,1.02,207.89]],"ltp":0.0,"tv":0.0,"id":2120}]}]}
{"op":"mcm","clk":"11803471691","pt":1723114492136,"mc":[{"id":"1.231582261","rc":[{"batb":[[1,1.02,247.34]],"ltp":0.0,"tv":0.0,"id":655},{"batb":[[1,1.02,247.34]],"ltp":0.0,"tv":0.0,"id":2120}]}]}
{"op":"mcm","clk":"11803472319","pt":1723114503569,"mc":[{"id":"1.231582261","rc":[{"batb":[[0,1.03,207.89]],"ltp":0.0,"tv":0.0,"id":655},{"batb":[[0,1.03,207.89]],"ltp":0.0,"tv":0.0,"id":2120}]}]}
{"op":"mcm","clk":"11803473341","pt":1723114522015,"mc":[{"id":"1.231582261","rc":[{"batb":[[0,1.04,7.89],[1,1.03,207.89],[2,1.02,247.34]],"ltp":0.0,"tv":0.0,"id":655},{"batb":[[0,1.04,7.89],[1,1.03,207.89],[2,1.02,247.34]],"ltp":0.0,"tv":0.0,"id":2120}]}]}
{"op":"mcm","clk":"11803473851","pt":1723114532445,"mc":[{"id":"1.231582261","rc":[{"batb":[[0,1.05,7.89],[1,1.04,7.89],[2,1.03,207.89]],"ltp":0.0,"tv":0.0,"id":655},{"batb":[[0,1.05,7.89],[1,1.04,7.89],[2,1.03,207.89]],"ltp":0.0,"tv":0.0,"id":2120}]}]}
{"op":"mcm","clk":"11803474462","pt":1723114543718,"mc":[{"id":"1.231582261","rc":[{"batb":[[0,1.06,7.89],[1,1.05,7.89],[2,1.04,7.89]],"ltp":0.0,"tv":0.0,"id":655},{"batb":[[0,1.06,7.89],[1,1.05,7.89],[2,1.04,7.89]],"ltp":0.0,"tv":0.0,"id":2120}]}]}
{"op":"mcm","clk":"11803475080","pt":1723114555872,"mc":[{"id":"1.231582261","rc":[{"batb":[[0,1.07,7.89],[1,1.06,7.89],[2,1.05,7.89]],"ltp":0.0,"tv":0.0,"id":655},{"batb":[[0,1.07,7.89],[1,1.06,7.89],[2,1.05,7.89]],"ltp":0.0,"tv":0.0,"id":2120}]}]}
{"op":"mcm","clk":"11803475883","pt":1723114569387,"mc":[{"id":"1.231582261","rc":[{"batb":[[0,1.08,7.89],[1,1.07,7.89],[2,1.06,7.89]],"ltp":0.0,"tv":0.0,"id":655},{"batb":[[0,1.08,7.89],[1,1.07,7.89],[2,1.06,7.89]],"ltp":0.0,"tv":0.0,"id":2120}]}]}
{"op":"mcm","clk":"11803588872","pt":1723116647208,"mc":[{"id":"1.231582261","rc":[{"batb":[[0,1.08,7.88],[1,1.07,7.88],[2,1.06,7.88]],"ltp":0.0,"tv":0.0,"id":655},{"batb":[[0,1.08,7.88],[1,1.07,7.88],[2,1.06,7.88]],"ltp":0.0,"tv":0.0,"id":2120}]}]}
{"op":"mcm","clk":"11803589949","pt":1723116666859,"mc":[{"id":"1.231582261","marketDefinition":{"bspMarket":false,"turnInPlayEnabled":true,"persistenceEnabled":true,"marketBaseRate":5.0,"eventId":"33477736","eventTypeId":"4","numberOfWinners":1,"bettingType":"ODDS","marketType":"MATCH_ODDS","marketTime":"2024-08-11T10:00:00.000Z","suspendTime":"2024-08-11T10:00:00.000Z","bspReconciled":false,"complete":true,"inPlay":false,"crossMatching":true,"runnersVoidable":false,"numberOfActiveRunners":2,"betDelay":0,"status":"OPEN","runners":[{"status":"ACTIVE","sortPriority":1,"id":2120,"name":"Warwickshire"},{"status":"ACTIVE","sortPriority":2,"id":655,"name":"Yorkshire"}],"regulators":["MR_INT"],"countryCode":"GB","discountAllowed":true,"timezone":"GMT","openDate":"2024-08-11T10:00:00.000Z","version":6061697140,"name":"Match Odds","eventName":"Warwickshire v Yorkshire"}}]}
{"op":"mcm","clk":"11803735019","pt":1723119175117,"mc":[{"id":"1.231582261","rc":[{"batb":[[0,1.08,7.88],[1,1.07,7.88],[2,1.06,7.88]],"ltp":0.0,"tv":0.0,"id":655},{"batb":[[0,1.08,7.88],[1,1.07,7.88],[2,1.06,7.88]],"ltp":0.0,"tv":0.0,"id":2120}]}]}
{"op":"mcm","clk":"11804049600","pt":1723124575111,"mc":[{"id":"1.231582261","rc":[{"batb":[[0,1.08,7.89],[1,1.07,7.89],[2,1.06,7.89]],"ltp":0.0,"tv":0.0,"id":655},{"batb":[[0,1.08,7.89],[1,1.07,7.89],[2,1.06,7.89]],"ltp":0.0,"tv":0.0,"id":2120}]}]}
{"op":"mcm","clk":"11804455338","pt":1723129859276,"mc":[{"id":"1.231582261","rc":[{"batb":[[0,1.25,100],[1,1.08,7.86],[2,1.07,7.86]],"ltp":0.0,"tv":0.0,"id":655},{"batb":[[0,1.25,100],[1,1.08,7.86],[2,1.07,7.86]],"ltp":0.0,"tv":0.0,"id":2120}]}]}
{"op":"mcm","clk":"11805072775","pt":1723135375181,"mc":[{"id":"1.231582261","rc":[{"batb":[[1,1.08,7.85],[2,1.07,7.85]],"ltp":0.0,"tv":0.0,"id":655},{"batb":[[1,1.08,7.85],[2,1.07,7.85]],"ltp":0.0,"tv":0.0,"id":2120}]}]}
{"op":"mcm","clk":"11805685095","pt":1723140775197,"mc":[{"id":"1.231582261","rc":[{"batb":[[1,1.08,7.85],[2,1.07,7.85]],"ltp":0.0,"tv":0.0,"id":655},{"batb":[[1,1.08,7.85],[2,1.07,7.85]],"ltp":0.0,"tv":0.0,"id":2120}]}]}
{"op":"mcm","clk":"11806375594","pt":1723146175165,"mc":[{"id":"1.231582261","rc":[{"batb":[[1,1.08,7.84],[2,1.07,7.84]],"ltp":0.0,"tv":0.0,"id":655},{"batb":[[1,1.08,7.84],[2,1.07,7.84]],"ltp":0.0,"tv":0.0,"id":2120}]}]}
{"op":"mcm","clk":"11807354913","pt":1723162375168,"mc":[{"id":"1.231582261","rc":[{"batb":[[1,1.08,7.84],[2,1.07,7.84]],"ltp":0.0,"tv":0.0,"id":655},{"batb":[[1,1.08,7.84],[2,1.07,7.84]],"ltp":0.0,"tv":0.0,"id":2120}]}]}
{"op":"mcm","clk":"11807689692","pt":1723167775171,"mc":[{"id":"1.231582261","rc":[{"batb":[[1,1.08,7.85],[2,1.07,7.85]],"ltp":0.0,"tv":0.0,"id":655},{"batb":[[1,1.08,7.85],[2,1.07,7.85]],"ltp":0.0,"tv":0.0,"id":2120}]}]}
{"op":"mcm","clk":"11807977562","pt":1723173175240,"mc":[{"id":"1.231582261","rc":[{"batb":[[1,1.08,7.84],[2,1.07,7.84]],"ltp":0.0,"tv":0.0,"id":655},{"batb":[[1,1.08,7.84],[2,1.07,7.84]],"ltp":0.0,"tv":0.0,"id":2120}]}]}
{"op":"mcm","clk":"11808232882","pt":1723178575227,"mc":[{"id":"1.231582261","rc":[{"batb":[[1,1.08,7.84],[2,1.07,7.84]],"ltp":0.0,"tv":0.0,"id":655},{"batb":[[1,1.08,7.84],[2,1.07,7.84]],"ltp":0.0,"tv":0.0,"id":2120}]}]}
{"op":"mcm","clk":"11808494670","pt":1723183975194,"mc":[{"id":"1.231582261","rc":[{"batb":[[1,1.08,7.84],[2,1.07,7.84]],"ltp":0.0,"tv":0.0,"id":655},{"batb":[[1,1.08,7.84],[2,1.07,7.84]],"ltp":0.0,"tv":0.0,"id":2120}]}]}
{"op":"mcm","clk":"11808788332","pt":1723189375252,"mc":[{"id":"1.231582261","rc":[{"batb":[[1,1.08,7.83],[2,1.07,7.83]],"ltp":0.0,"tv":0.0,"id":655},{"batb":[[1,1.08,7.83],[2,1.07,7.83]],"ltp":0.0,"tv":0.0,"id":2120}]}]}
{"op":"mcm","clk":"11808800517","pt":1723189566388,"mc":[{"id":"1.231582261","rc":[{"batl":[[0,1000,0.02]],"ltp":0.0,"tv":0.0,"id":655},{"batl":[[0,1000,0.02]],"ltp":0.0,"tv":0.0,"id":2120}]}]}
{"op":"mcm","clk":"11809024522","pt":1723194165358,"mc":[{"id":"1.231582261","rc":[{"batb":[[0,1.26,2.02],[1,1.25,100],[2,1.08,7.83]],"ltp":0.0,"tv":0.0,"id":655},{"batb":[[1,1.08,7.83],[2,1.07,7.83]],"ltp":0.0,"tv":0.0,"id":2120}]}]}
{"op":"mcm","clk":"11809024950","pt":1723194174642,"mc":[{"id":"1.231582261","rc":[{"batb":[[0,1.26,2.98]],"ltp":0.0,"tv":0.0,"id":655}]}]}
{"op":"mcm","clk":"11809025372","pt":1723194185665,"mc":[{"id":"1.231582261","rc":[{"batb":[[0,1.28,2.13],[1,1.25,100],[2,1.08,7.83]],"ltp":0.0,"tv":0.0,"id":2120}]}]}
{"op":"mcm","clk":"11809026218","pt":1723194203378,"mc":[{"id":"1.231582261","rc":[{"batb":[[0,1.28,3.09]],"ltp":0.0,"tv":0.0,"id":2120}]}]}
{"op":"mcm","clk":"11809402463","pt":1723200175287,"mc":[{"id":"1.231582261","rc":[{"batb":[[2,1.08,7.84]],"ltp":0.0,"tv":0.0,"id":655},{"batb":[[2,1.08,7.84]],"ltp":0.0,"tv":0.0,"id":2120}]}]}
{"op":"mcm","clk":"11809832756","pt":1723205575285,"mc":[{"id":"1.231582261","rc":[{"batb":[[0,1.26,2.98],[2,1.08,7.85]],"ltp":0.0,"tv":0.0,"id":655},{"batb":[[0,1.28,3.1],[2,1.08,7.85]],"ltp":0.0,"tv":0.0,"id":2120}]}]}
{"op":"mcm","clk":"11810349689","pt":1723210975257,"mc":[{"id":"1.231582261","rc":[{"batb":[[0,1.26,2.98],[2,1.08,7.85]],"ltp":0.0,"tv":0.0,"id":655},{"batb":[[0,1.28,3.1],[2,1.08,7.85]],"ltp":0.0,"tv":0.0,"id":2120}]}]}
{"op":"mcm","clk":"11810913422","pt":1723216375309,"mc":[{"id":"1.231582261","rc":[{"batb":[[0,1.26,2.98],[2,1.08,7.84]],"ltp":0.0,"tv":0.0,"id":655},{"batb":[[0,1.28,3.09],[2,1.08,7.84]],"ltp":0.0,"tv":0.0,"id":2120}]}]}
{"op":"mcm","clk":"11811542511","pt":1723221507263,"mc":[{"id":"1.231582261","rc":[{"batb":[[1,1.08,7.84],[2,1.07,7.84]],"ltp":0.0,"tv":0.0,"id":655},{"batb":[[1,1.08,7.84],[2,1.07,7.84]],"ltp":0.0,"tv":0.0,"id":2120}]}]}
{"op":"mcm","clk":"11811551702","pt":1723221560497,"mc":[{"id":"1.231582261","rc":[{"batb":[[0,1.28,90.25],[1,1.26,2.02],[2,1.23,108.7]],"ltp":0.0,"tv":0.0,"id":655},{"batb":[[0,1.33,75.76],[1,1.28,92.38],[2,1.23,108.7]],"ltp":0.0,"tv":0.0,"id":2120}]}]}
{"op":"mcm","clk":"11811551773","pt":1723221560932,"mc":[{"id":"1.231582261","rc":[{"batb":[[0,1.48,52.08],[1,1.43,58.14],[2,1.38,65.79]],"ltp":0.0,"tv":0.0,"id":655},{"batb":[[0,1.48,52.08],[1,1.43,58.14],[2,1.38,65.79]],"ltp":0.0,"tv":0.0,"id":2120}]}]}
{"op":"mcm","clk":"11811706253","pt":1723222458125,"mc":[{"id":"1.231582261","rc":[{"batb":[[0,1.49,6.78],[1,1.48,52.08],[2,1.43,58.14]],"ltp":0.0,"tv":0.0,"id":655},{"batb":[[0,1.49,6.05],[1,1.48,52.08],[2,1.43,58.14]],"ltp":0.0,"tv":0.0,"id":2120}]}]}
{"op":"mcm","clk":"11811952921","pt":1723223796584,"mc":[{"id":"1.231582261","rc":[{"batb":[[0,2.34,31.18],[1,1.49,6.78],[2,1.48,52.08]],"ltp":0.0,"tv":0.0,"id":655},{"batb":[[0,1.68,61.45],[1,1.49,6.05],[2,1.48,52.08]],"ltp":0.0,"tv":0.0,"id":2120}]}]}
{"op":"mcm","clk":"11812405537","pt":1723226039968,"mc":[{"id":"1.231582261","rc":[{"batb":[[1,1.48,52.08],[2,1.43,58.14]],"ltp":0.0,"tv":0.0,"id":655},{"batb":[[1,1.48,52.08],[2,1.43,58.14]],"ltp":0.0,"tv":0.0,"id":2120}]}]}
{"op":"mcm","clk":"11817088367","pt":1723277741577,"mc":[{"id":"1.231582261","rc":[{"trd":[[1.68,2]],"batb":[[0,1.68,60.45]],"ltp":1.68,"tv":2.0,"id":2120}],"tv":2.0}]}
{"op":"mcm","clk":"11817088485","pt":1723277743078,"mc":[{"id":"1.231582261","rc":[{"batb":[[0,1.68,61.45]],"ltp":1.68,"tv":2.0,"id":2120}]}]}
{"op":"mcm","clk":"11817162967","pt":1723278734601,"mc":[{"id":"1.231582261","rc":[{"batb":[[1,1.08,7.85],[2,1.07,7.85]],"ltp":0.0,"tv":0.0,"id":655},{"batb":[[1,1.08,7.85],[2,1.07,7.85]],"ltp":1.68,"tv":2.0,"id":2120}]}]}
{"op":"mcm","clk":"11817179327","pt":1723278978956,"mc":[{"id":"1.231582261","rc":[{"batb":[[1,1.25,1200],[2,1.08,7.85]],"ltp":0.0,"tv":0.0,"id":655},{"batb":[[1,1.25,1200],[2,1.08,7.85]],"ltp":1.68,"tv":2.0,"id":2120}]}]}
{"op":"mcm","clk":"11817184259","pt":1723279056452,"mc":[{"id":"1.231582261","rc":[{"batb":[[1,1.08,7.85],[2,1.07,7.85]],"ltp":0.0,"tv":0.0,"id":655},{"batb":[[1,1.08,7.85],[2,1.07,7.85]],"ltp":1.68,"tv":2.0,"id":2120}]}]}
{"op":"mcm","clk":"11817184469","pt":1723279059860,"mc":[{"id":"1.231582261","rc":[{"batb":[[1,1.3,1000],[2,1.08,7.85]],"ltp":0.0,"tv":0.0,"id":655},{"batb":[[1,1.3,1000],[2,1.08,7.85]],"ltp":1.68,"tv":2.0,"id":2120}]}]}
{"op":"mcm","clk":"11820587878","pt":1723299707792,"mc":[{"id":"1.231582261","rc":[{"batb":[[0,2.34,29.13]],"ltp":0.0,"tv":0.0,"id":655},{"batb":[[0,1.68,57.41]],"ltp":1.68,"tv":2.0,"id":2120}]}]}
{"op":"mcm","clk":"11821840644","pt":1723304690291,"mc":[{"id":"1.231582261","rc":[{"batl":[[0,1.7,100],[1,1000,0.02]],"ltp":1.68,"tv":2.0,"id":2120}]}]}
{"op":"mcm","clk":"11821841475","pt":1723304693718,"mc":[{"id":"1.231582261","rc":[{"batl":[[1,1.71,200],[2,1000,0.02]],"ltp":1.68,"tv":2.0,"id":2120}]}]}
{"op":"mcm","clk":"11821842323","pt":1723304697288,"mc":[{"id":"1.231582261","rc":[{"batl":[[2,1.72,300]],"ltp":1.68,"tv":2.0,"id":2120}]}]}
{"op":"mcm","clk":"11822609764","pt":1723308506126,"mc":[{"id":"1.231582261","rc":[{"trd":[[1.68,62]],"batb":[[0,1.68,27.41]],"ltp":1.68,"tv":62.0,"id":2120}],"tv":62.0}]}
{"op":"mcm","clk":"11822610156","pt":1723308507994,"mc":[{"id":"1.231582261","rc":[{"batb":[[0,1.68,57.41]],"ltp":1.68,"tv":62.0,"id":2120}]}]}
{"op":"mcm","clk":"11823744388","pt":1723314074652,"mc":[{"id":"1.231582261","rc":[{"batl":[[0,2.8,5],[1,1000,0.02]],"ltp":0.0,"tv":0.0,"id":655}]}]}
{"op":"mcm","clk":"11824761226","pt":1723319610678,"mc":[{"id":"1.231582261","rc":[{"batb":[[1,1.56,4.56],[2,1.3,1000]],"ltp":1.68,"tv":62.0,"id":2120}]}]}
{"op":"mcm","clk":"11824762810","pt":1723319620413,"mc":[{"id":"1.231582261","rc":[{"batb":[[1,1.57,4.56],[2,1.56,4.56]],"ltp":1.68,"tv":62.0,"id":2120}]}]}
{"op":"mcm","clk":"11825526177","pt":1723325097773,"mc":[{"id":"1.231582261","rc":[{"trd":[[1.68,65.5]],"batb":[[0,1.68,55.66]],"ltp":1.68,"tv":65.5,"id":2120}],"tv":65.5}]}
{"op":"mcm","clk":"11825526357","pt":1723325099781,"mc":[{"id":"1.231582261","rc":[{"batb":[[0,1.68,57.41]],"ltp":1.68,"tv":65.5,"id":2120}]}]}
{"op":"mcm","clk":"11825868358","pt":1723330383410,"mc":[{"id":"1.231582261","rc":[{"trd":[[1.7,17.14]],"batl":[[0,1.7,91.43]],"ltp":1.7,"tv":82.64,"id":2120}],"tv":82.64}]}
{"op":"mcm","clk":"11827100210","pt":1723348522115,"mc":[{"id":"1.231582261","rc":[{"batb":[[1,1.63,21],[2,1.57,4.56]],"ltp":1.7,"tv":82.64,"id":2120}]}]}
{"op":"mcm","clk":"11827369255","pt":1723354980066,"mc":[{"id":"1.231582261","rc":[{"trd":[[1.68,65.56]],"batb":[[0,1.68,57.38]],"ltp":1.68,"tv":82.7,"id":2120}],"tv":82.7}]}
{"op":"mcm","clk":"11827369435","pt":1723354984413,"mc":[{"id":"1.231582261","rc":[{"batb":[[0,1.68,114.79]],"ltp":1.68,"tv":82.7,"id":2120}]}]}
{"op":"mcm","clk":"11827369438","pt":1723354984515,"mc":[{"id":"1.231582261","rc":[{"batb":[[0,1.68,57.41]],"ltp":1.68,"tv":82.7,"id":2120}]}]}
{"op":"mcm","clk":"11827570412","pt":1723360100964,"mc":[{"id":"1.231582261","rc":[{"trd":[[1.68,180.38]],"batb":[[0,1.63,21],[1,1.57,4.56],[2,1.56,4.56]],"batl":[[0,1.67,142.59],[1,1.7,91.43],[2,1.71,200]],"ltp":1.68,"tv":197.51,"id":2120}],"tv":197.51}]}
{"op":"mcm","clk":"11827570473","pt":1723360102460,"mc":[{"id":"1.231582261","rc":[{"batb":[[0,1.64,61],[1,1.63,21],[2,1.57,4.56]],"ltp":1.68,"tv":197.51,"id":2120}]}]}
{"op":"mcm","clk":"11827594314","pt":1723360836050,"mc":[{"id":"1.231582261","rc":[{"trd":[[2.48,2]],"ltp":2.48,"tv":2.0,"id":655},{"trd":[[1.67,2.97]],"batl":[[0,1.67,139.62]],"ltp":1.67,"tv":200.49,"id":2120}],"tv":202.49}]}
{"op":"mcm","clk":"11827594334","pt":1723360836561,"mc":[{"id":"1.231582261","rc":[{"batb":[[0,2.36,14],[1,2.34,29.13],[2,1.3,1000]],"ltp":2.48,"tv":2.0,"id":655}]}]}
{"op":"mcm","clk":"11827594415","pt":1723360839132,"mc":[{"id":"1.231582261","rc":[{"batb":[[0,2.36,10]],"ltp":2.48,"tv":2.0,"id":655}]}]}
{"op":"mcm","clk":"11827594441","pt":1723360840260,"mc":[{"id":"1.231582261","rc":[{"batb":[[0,2.34,29.13],[1,1.3,1000],[2,1.08,7.85]],"ltp":2.48,"tv":2.0,"id":655}]}]}
{"op":"mcm","clk":"11827594503","pt":1723360842464,"mc":[{"id":"1.231582261","rc":[{"batb":[[0,2.38,10],[1,2.36,4],[2,2.34,29.13]],"ltp":2.48,"tv":2.0,"id":655}]}]}
{"op":"mcm","clk":"11827594579","pt":1723360844566,"mc":[{"id":"1.231582261","rc":[{"batb":[[1,2.34,29.13],[2,1.3,1000]],"ltp":2.48,"tv":2.0,"id":655}]}]}
{"op":"mcm","clk":"11827594611","pt":1723360845655,"mc":[{"id":"1.231582261","rc":[{"batb":[[0,2.34,29.13],[1,1.3,1000],[2,1.08,7.85]],"ltp":2.48,"tv":2.0,"id":655}]}]}
{"op":"mcm","clk":"11827594719","pt":1723360847830,"mc":[{"id":"1.231582261","rc":[{"batb":[[0,2.36,14],[1,2.34,29.13],[2,1.3,1000]],"ltp":2.48,"tv":2.0,"id":655}]}]}
{"op":"mcm","clk":"11827594791","pt":1723360850243,"mc":[{"id":"1.231582261","rc":[{"batb":[[0,2.36,10]],"ltp":2.48,"tv":2.0,"id":655}]}]}
{"op":"mcm","clk":"11827594831","pt":1723360851374,"mc":[{"id":"1.231582261","rc":[{"batb":[[0,2.34,29.13],[1,1.3,1000],[2,1.08,7.85]],"ltp":2.48,"tv":2.0,"id":655}]}]}
{"op":"mcm","clk":"11827594889","pt":1723360853171,"mc":[{"id":"1.231582261","rc":[{"batb":[[0,2.36,4],[1,2.34,29.13],[2,1.3,1000]],"ltp":2.48,"tv":2.0,"id":655}]}]}
{"op":"mcm","clk":"11827594913","pt":1723360854251,"mc":[{"id":"1.231582261","rc":[{"batb":[[0,2.38,10],[1,2.36,4],[2,2.34,29.13]],"ltp":2.48,"tv":2.0,"id":655}]}]}
{"op":"mcm","clk":"11827594949","pt":1723360855483,"mc":[{"id":"1.231582261","rc":[{"batb":[[1,2.34,29.13],[2,1.3,1000]],"ltp":2.48,"tv":2.0,"id":655}]}]}
{"op":"mcm","clk":"11827595015","pt":1723360857853,"mc":[{"id":"1.231582261","rc":[{"batb":[[0,2.36,4]],"ltp":2.48,"tv":2.0,"id":655}]}]}
{"op":"mcm","clk":"11827595082","pt":1723360860262,"mc":[{"id":"1.231582261","rc":[{"batb":[[0,2.38,10]],"ltp":2.48,"tv":2.0,"id":655}]}]}
{"op":"mcm","clk":"11827595179","pt":1723360863457,"mc":[{"id":"1.231582261","rc":[{"batb":[[0,2.36,4]],"ltp":2.48,"tv":2.0,"id":655}]}]}
{"op":"mcm","clk":"11827595267","pt":1723360865984,"mc":[{"id":"1.231582261","rc":[{"batb":[[0,2.38,10]],"ltp":2.48,"tv":2.0,"id":655}]}]}
{"op":"mcm","clk":"11827595327","pt":1723360868095,"mc":[{"id":"1.231582261","rc":[{"batb":[[0,2.4,4],[1,2.38,10],[2,2.34,29.13]],"ltp":2.48,"tv":2.0,"id":655}]}]}
{"op":"mcm","clk":"11827595363","pt":1723360869380,"mc":[{"id":"1.231582261","rc":[{"batb":[[1,2.34,29.13],[2,1.3,1000]],"ltp":2.48,"tv":2.0,"id":655}]}]}
{"op":"mcm","clk":"11827595398","pt":1723360870459,"mc":[{"id":"1.231582261","rc":[{"batb":[[0,2.34,29.13],[1,1.3,1000],[2,1.08,7.85]],"ltp":2.48,"tv":2.0,"id":655}]}]}
{"op":"mcm","clk":"11827595437","pt":1723360871587,"mc":[{"id":"1.231582261","rc":[{"batb":[[0,2.36,10],[1,2.34,29.13],[2,1.3,1000]],"ltp":2.48,"tv":2.0,"id":655}]}]}
{"op":"mcm","clk":"11827595502","pt":1723360873179,"mc":[{"id":"1.231582261","rc":[{"batb":[[0,2.38,4],[1,2.36,10],[2,2.34,29.13]],"ltp":2.48,"tv":2.0,"id":655}]}]}
{"op":"mcm","clk":"11827595571","pt":1723360874974,"mc":[{"id":"1.231582261","rc":[{"batb":[[1,2.34,29.13],[2,1.3,1000]],"ltp":2.48,"tv":2.0,"id":655}]}]}
{"op":"mcm","clk":"11827595593","pt":1723360875697,"mc":[{"id":"1.231582261","rc":[{"batb":[[0,2.34,29.13],[1,1.3,1000],[2,1.08,7.85]],"ltp":2.48,"tv":2.0,"id":655}]}]}
{"op":"mcm","clk":"11827595662","pt":1723360878268,"mc":[{"id":"1.231582261","rc":[{"batb":[[0,2.36,14],[1,2.34,29.13],[2,1.3,1000]],"ltp":2.48,"tv":2.0,"id":655}]}]}
{"op":"mcm","clk":"11827595754","pt":1723360881208,"mc":[{"id":"1.231582261","rc":[{"batb":[[0,2.36,10]],"ltp":2.48,"tv":2.0,"id":655}]}]}
{"op":"mcm","clk":"11827595787","pt":1723360882292,"mc":[{"id":"1.231582261","rc":[{"batb":[[0,2.34,29.13],[1,1.3,1000],[2,1.08,7.85]],"ltp":2.48,"tv":2.0,"id":655}]}]}
{"op":"mcm","clk":"11827595848","pt":1723360883892,"mc":[{"id":"1.231582261","rc":[{"batb":[[0,2.36,4],[1,2.34,29.13],[2,1.3,1000]],"ltp":2.48,"tv":2.0,"id":655}]}]}
{"op":"mcm","clk":"11827595927","pt":1723360886293,"mc":[{"id":"1.231582261","rc":[{"batb":[[0,2.38,10]],"ltp":2.48,"tv":2.0,"id":655}]}]}
{"op":"mcm","clk":"11827596011","pt":1723360889210,"mc":[{"id":"1.231582261","rc":[{"batb":[[0,2.36,4]],"ltp":2.48,"tv":2.0,"id":655}]}]}
{"op":"mcm","clk":"11827596092","pt":1723360891832,"mc":[{"id":"1.231582261","rc":[{"batb":[[0,2.36,10]],"ltp":2.48,"tv":2.0,"id":655}]}]}
{"op":"mcm","clk":"11827596222","pt":1723360895424,"mc":[{"id":"1.231582261","rc":[{"batb":[[0,2.38,4]],"ltp":2.48,"tv":2.0,"id":655}]}]}
{"op":"mcm","clk":"11827596277","pt":1723360897015,"mc":[{"id":"1.231582261","rc":[{"batb":[[0,2.34,29.13],[1,1.3,1000],[2,1.08,7.85]],"ltp":2.48,"tv":2.0,"id":655}]}]}
{"op":"mcm","clk":"11827596308","pt":1723360898139,"mc":[{"id":"1.231582261","rc":[{"batb":[[0,2.36,10],[1,2.34,29.13],[2,1.3,1000]],"ltp":2.48,"tv":2.0,"id":655}]}]}
{"op":"mcm","clk":"11827596393","pt":1723360900711,"mc":[{"id":"1.231582261","rc":[{"batb":[[0,2.38,4],[1,2.36,10],[2,2.34,29.13]],"ltp":2.48,"tv":2.0,"id":655}]}]}
{"op":"mcm","clk":"11827596419","pt":1723360901533,"mc":[{"id":"1.231582261","rc":[{"batb":[[1,2.34,29.13],[2,1.3,1000]],"ltp":2.48,"tv":2.0,"id":655}]}]}
{"op":"mcm","clk":"11827596467","pt":1723360903131,"mc":[{"id":"1.231582261","rc":[{"batb":[[0,2.34,29.13],[1,1.3,1000],[2,1.08,7.85]],"ltp":2.48,"tv":2.0,"id":655}]}]}
{"op":"mcm","clk":"11827596622","pt":1723360906938,"mc":[{"id":"1.231582261","rc":[{"batb":[[0,2.36,14],[1,2.34,29.13],[2,1.3,1000]],"ltp":2.48,"tv":2.0,"id":655}]}]}
{"op":"mcm","clk":"11827596695","pt":1723360909353,"mc":[{"id":"1.231582261","rc":[{"batb":[[0,2.36,10]],"ltp":2.48,"tv":2.0,"id":655}]}]}
{"op":"mcm","clk":"11827596722","pt":1723360910227,"mc":[{"id":"1.231582261","rc":[{"batb":[[0,2.34,29.13],[1,1.3,1000],[2,1.08,7.85]],"ltp":2.48,"tv":2.0,"id":655}]}]}
{"op":"mcm","clk":"11827596788","pt":1723360912133,"mc":[{"id":"1.231582261","rc":[{"batb":[[0,2.36,4],[1,2.34,29.13],[2,1.3,1000]],"ltp":2.48,"tv":2.0,"id":655}]}]}
{"op":"mcm","clk":"11827596818","pt":1723360913320,"mc":[{"id":"1.231582261","rc":[{"batb":[[0,2.38,10],[1,2.36,4],[2,2.34,29.13]],"ltp":2.48,"tv":2.0,"id":655}]}]}
{"op":"mcm","clk":"11827596850","pt":1723360914453,"mc":[{"id":"1.231582261","rc":[{"batb":[[1,2.34,29.13],[2,1.3,1000]],"ltp":2.48,"tv":2.0,"id":655}]}]}
{"op":"mcm","clk":"11827596921","pt":1723360917230,"mc":[{"id":"1.231582261","rc":[{"batb":[[0,2.36,4]],"ltp":2.48,"tv":2.0,"id":655}]}]}
{"op":"mcm","clk":"11827596977","pt":1723360918924,"mc":[{"id":"1.231582261","rc":[{"batb":[[0,2.38,10],[1,2.36,4],[2,2.34,29.13]],"ltp":2.48,"tv":2.0,"id":655}]}]}
{"op":"mcm","clk":"11827596998","pt":1723360919541,"mc":[{"id":"1.231582261","rc":[{"batb":[[1,2.34,29.13],[2,1.3,1000]],"ltp":2.48,"tv":2.0,"id":655}]}]}
{"op":"mcm","clk":"11827597094","pt":1723360922331,"mc":[{"id":"1.231582261","rc":[{"batb":[[0,2.36,4]],"ltp":2.48,"tv":2.0,"id":655}]}]}
{"op":"mcm","clk":"11827597168","pt":1723360924742,"mc":[{"id":"1.231582261","rc":[{"batb":[[0,2.36,10]],"ltp":2.48,"tv":2.0,"id":655}]}]}
{"op":"mcm","clk":"11827597285","pt":1723360928240,"mc":[{"id":"1.231582261","rc":[{"batb":[[0,2.38,4]],"ltp":2.48,"tv":2.0,"id":655}]}]}
{"op":"mcm","clk":"11827597334","pt":1723360930343,"mc":[{"id":"1.231582261","rc":[{"batb":[[0,2.4,10],[1,2.38,4],[2,2.34,29.13]],"ltp":2.48,"tv":2.0,"id":655}]}]}
{"op":"mcm","clk":"11827597346","pt":1723360930546,"mc":[{"id":"1.231582261","rc":[{"batb":[[1,2.34,29.13],[2,1.3,1000]],"ltp":2.48,"tv":2.0,"id":655}]}]}
{"op":"mcm","clk":"11827597398","pt":1723360932653,"mc":[{"id":"1.231582261","rc":[{"batb":[[0,2.42,4],[1,2.4,10],[2,2.34,29.13]],"ltp":2.48,"tv":2.0,"id":655}]}]}
{"op":"mcm","clk":"11827597431","pt":1723360933682,"mc":[{"id":"1.231582261","rc":[{"batb":[[1,2.34,29.13],[2,1.3,1000]],"ltp":2.48,"tv":2.0,"id":655}]}]}
{"op":"mcm","clk":"11827597461","pt":1723360934965,"mc":[{"id":"1.231582261","rc":[{"batb":[[0,2.34,29.13],[1,1.3,1000],[2,1.08,7.85]],"ltp":2.48,"tv":2.0,"id":655}]}]}
{"op":"mcm","clk":"11827597483","pt":1723360936091,"mc":[{"id":"1.231582261","rc":[{"batb":[[0,2.36,10],[1,2.34,29.13],[2,1.3,1000]],"ltp":2.48,"tv":2.0,"id":655}]}]}
{"op":"mcm","clk":"11827597513","pt":1723360937374,"mc":[{"id":"1.231582261","rc":[{"batb":[[0,2.38,4],[1,2.36,10],[2,2.34,29.13]],"ltp":2.48,"tv":2.0,"id":655}]}]}
{"op":"mcm","clk":"11827597585","pt":1723360939747,"mc":[{"id":"1.231582261","rc":[{"batb":[[0,2.34,29.13],[1,1.3,1000],[2,1.08,7.85]],"ltp":2.48,"tv":2.0,"id":655}]}]}
{"op":"mcm","clk":"11827597680","pt":1723360942872,"mc":[{"id":"1.231582261","rc":[{"batb":[[0,2.36,14],[1,2.34,29.13],[2,1.3,1000]],"ltp":2.48,"tv":2.0,"id":655}]}]}
{"op":"mcm","clk":"11827597748","pt":1723360945496,"mc":[{"id":"1.231582261","rc":[{"batb":[[0,2.36,10]],"ltp":2.48,"tv":2.0,"id":655}]}]}
{"op":"mcm","clk":"11827597784","pt":1723360946467,"mc":[{"id":"1.231582261","rc":[{"batb":[[0,2.34,29.13],[1,1.3,1000],[2,1.08,7.85]],"ltp":2.48,"tv":2.0,"id":655}]}]}
{"op":"mcm","clk":"11827597823","pt":1723360947603,"mc":[{"id":"1.231582261","rc":[{"batb":[[0,2.36,4],[1,2.34,29.13],[2,1.3,1000]],"ltp":2.48,"tv":2.0,"id":655}]}]}
{"op":"mcm","clk":"11827597902","pt":1723360949964,"mc":[{"id":"1.231582261","rc":[{"batb":[[0,2.38,10]],"ltp":2.48,"tv":2.0,"id":655}]}]}
{"op":"mcm","clk":"11827597986","pt":1723360952286,"mc":[{"id":"1.231582261","rc":[{"batb":[[0,2.4,4],[1,2.38,10],[2,2.34,29.13]],"ltp":2.48,"tv":2.0,"id":655}]}]}
{"op":"mcm","clk":"11827598033","pt":1723360953464,"mc":[{"id":"1.231582261","rc":[{"batb":[[1,2.34,29.13],[2,1.3,1000]],"ltp":2.48,"tv":2.0,"id":655}]}]}
{"op":"mcm","clk":"11827598070","pt":1723360954589,"mc":[{"id":"1.231582261","rc":[{"batb":[[0,2.34,29.13],[1,1.3,1000],[2,1.08,7.85]],"ltp":2.48,"tv":2.0,"id":655}]}]}
{"op":"mcm","clk":"11827598118","pt":1723360955671,"mc":[{"id":"1.231582261","rc":[{"batb":[[0,2.36,10],[1,2.34,29.13],[2,1.3,1000]],"ltp":2.48,"tv":2.0,"id":655}]}]}
{"op":"mcm","clk":"11827598162","pt":1723360956977,"mc":[{"id":"1.231582261","rc":[{"batb":[[0,2.38,4],[1,2.36,10],[2,2.34,29.13]],"ltp":2.48,"tv":2.0,"id":655}]}]}
{"op":"mcm","clk":"11827598229","pt":1723360958881,"mc":[{"id":"1.231582261","rc":[{"batb":[[1,2.34,29.13],[2,1.3,1000]],"ltp":2.48,"tv":2.0,"id":655}]}]}
{"op":"mcm","clk":"11827598256","pt":1723360959603,"mc":[{"id":"1.231582261","rc":[{"batb":[[0,2.34,29.13],[1,1.3,1000],[2,1.08,7.85]],"ltp":2.48,"tv":2.0,"id":655}]}]}
{"op":"mcm","clk":"11827598331","pt":1723360962011,"mc":[{"id":"1.231582261","rc":[{"batb":[[0,2.38,4],[1,2.36,10],[2,2.34,29.13]],"ltp":2.48,"tv":2.0,"id":655}]}]}
{"op":"mcm","clk":"11827598405","pt":1723360964311,"mc":[{"id":"1.231582261","rc":[{"batb":[[0,2.36,10],[1,2.34,29.13],[2,1.3,1000]],"ltp":2.48,"tv":2.0,"id":655}]}]}
{"op":"mcm","clk":"11827598423","pt":1723360965085,"mc":[{"id":"1.231582261","rc":[{"batb":[[0,2.34,29.13],[1,1.3,1000],[2,1.08,7.85]],"ltp":2.48,"tv":2.0,"id":655}]}]}
{"op":"mcm","clk":"11827598469","pt":1723360966721,"mc":[{"id":"1.231582261","rc":[{"batb":[[0,2.36,4],[1,2.34,29.13],[2,1.3,1000]],"ltp":2.48,"tv":2.0,"id":655}]}]}
{"op":"mcm","clk":"11827598544","pt":1723360969184,"mc":[{"id":"1.231582261","rc":[{"batb":[[0,2.38,10]],"ltp":2.48,"tv":2.0,"id":655}]}]}
{"op":"mcm","clk":"11827598638","pt":1723360972392,"mc":[{"id":"1.231582261","rc":[{"batb":[[0,2.4,4]],"ltp":2.48,"tv":2.0,"id":655}]}]}
{"op":"mcm","clk":"11827598699","pt":1723360974231,"mc":[{"id":"1.231582261","rc":[{"batb":[[0,2.34,29.13],[1,1.3,1000],[2,1.08,7.85]],"ltp":2.48,"tv":2.0,"id":655}]}]}
{"op":"mcm","clk":"11827598721","pt":1723360975411,"mc":[{"id":"1.231582261","rc":[{"batb":[[0,2.36,10],[1,2.34,29.13],[2,1.3,1000]],"ltp":2.48,"tv":2.0,"id":655}]}]}
{"op":"mcm","clk":"11827598764","pt":1723360976692,"mc":[{"id":"1.231582261","rc":[{"batb":[[0,2.38,4],[1,2.36,10],[2,2.34,29.13]],"ltp":2.48,"tv":2.0,"id":655}]}]}
{"op":"mcm","clk":"11827598825","pt":1723360978737,"mc":[{"id":"1.231582261","rc":[{"batb":[[1,2.34,29.13],[2,1.3,1000]],"ltp":2.48,"tv":2.0,"id":655}]}]}
{"op":"mcm","clk":"11827598849","pt":1723360979812,"mc":[{"id":"1.231582261","rc":[{"batb":[[0,2.34,29.13],[1,1.3,1000],[2,1.08,7.85]],"ltp":2.48,"tv":2.0,"id":655}]}]}
{"op":"mcm","clk":"11827598912","pt":1723360981416,"mc":[{"id":"1.231582261","rc":[{"batb":[[0,2.36,10],[1,2.34,29.13],[2,1.3,1000]],"ltp":2.48,"tv":2.0,"id":655}]}]}
{"op":"mcm","clk":"11827598969","pt":1723360982645,"mc":[{"id":"1.231582261","rc":[{"batb":[[0,2.38,4],[1,2.36,10],[2,2.34,29.13]],"ltp":2.48,"tv":2.0,"id":655}]}]}
{"op":"mcm","clk":"11827599062","pt":1723360984807,"mc":[{"id":"1.231582261","rc":[{"batb":[[0,2.34,29.13],[1,1.3,1000],[2,1.08,7.85]],"ltp":2.48,"tv":2.0,"id":655}]}]}
{"op":"mcm","clk":"11827599156","pt":1723360987316,"mc":[{"id":"1.231582261","rc":[{"batb":[[0,2.36,14],[1,2.34,29.13],[2,1.3,1000]],"ltp":2.48,"tv":2.0,"id":655}]}]}
{"op":"mcm","clk":"11827599224","pt":1723360989830,"mc":[{"id":"1.231582261","rc":[{"batb":[[0,2.36,10]],"ltp":2.48,"tv":2.0,"id":655}]}]}
{"op":"mcm","clk":"11827599246","pt":1723360990808,"mc":[{"id":"1.231582261","rc":[{"batb":[[0,2.34,29.13],[1,1.3,1000],[2,1.08,7.85]],"ltp":2.48,"tv":2.0,"id":655}]}]}
{"op":"mcm","clk":"11827599340","pt":1723360993227,"mc":[{"id":"1.231582261","rc":[{"batb":[[0,2.36,14],[1,2.34,29.13],[2,1.3,1000]],"ltp":2.48,"tv":2.0,"id":655}]}]}
{"op":"mcm","clk":"11827599395","pt":1723360995940,"mc":[{"id":"1.231582261","rc":[{"batb":[[0,2.36,10]],"ltp":2.48,"tv":2.0,"id":655}]}]}
{"op":"mcm","clk":"11827599412","pt":1723360996658,"mc":[{"id":"1.231582261","rc":[{"batb":[[0,2.34,29.13],[1,1.3,1000],[2,1.08,7.85]],"ltp":2.48,"tv":2.0,"id":655}]}]}
{"op":"mcm","clk":"11827599477","pt":1723360998819,"mc":[{"id":"1.231582261","rc":[{"batb":[[0,2.36,14],[1,2.34,29.13],[2,1.3,1000]],"ltp":2.48,"tv":2.0,"id":655}]}]}
{"op":"mcm","clk":"11827599540","pt":1723361001443,"mc":[{"id":"1.231582261","rc":[{"batb":[[0,2.36,10]],"ltp":2.48,"tv":2.0,"id":655}]}]}
{"op":"mcm","clk":"11827599569","pt":1723361002268,"mc":[{"id":"1.231582261","rc":[{"batb":[[0,2.34,29.13],[1,1.3,1000],[2,1.08,7.85]],"ltp":2.48,"tv":2.0,"id":655}]}]}
{"op":"mcm","clk":"11827599633","pt":1723361004630,"mc":[{"id":"1.231582261","rc":[{"batb":[[0,2.36,14],[1,2.34,29.13],[2,1.3,1000]],"ltp":2.48,"tv":2.0,"id":655}]}]}
{"op":"mcm","clk":"11827599693","pt":1723361006936,"mc":[{"id":"1.231582261","rc":[{"batb":[[0,2.36,10]],"ltp":2.48,"tv":2.0,"id":655}]}]}
{"op":"mcm","clk":"11827599718","pt":1723361007962,"mc":[{"id":"1.231582261","rc":[{"batb":[[0,2.34,29.13],[1,1.3,1000],[2,1.08,7.85]],"ltp":2.48,"tv":2.0,"id":655}]}]}
{"op":"mcm","clk":"11827599776","pt":1723361010276,"mc":[{"id":"1.231582261","rc":[{"batb":[[0,2.36,14],[1,2.34,29.13],[2,1.3,1000]],"ltp":2.48,"tv":2.0,"id":655}]}]}
{"op":"mcm","clk":"11827599873","pt":1723361012549,"mc":[{"id":"1.231582261","rc":[{"batb":[[0,2.36,10]],"ltp":2.48,"tv":2.0,"id":655}]}]}
{"op":"mcm","clk":"11827599902","pt":1723361013575,"mc":[{"id":"1.231582261","rc":[{"batb":[[0,2.34,29.13],[1,1.3,1000],[2,1.08,7.85]],"ltp":2.48,"tv":2.0,"id":655}]}]}
{"op":"mcm","clk":"11827599980","pt":1723361016458,"mc":[{"id":"1.231582261","rc":[{"batb":[[0,2.36,14],[1,2.34,29.13],[2,1.3,1000]],"ltp":2.48,"tv":2.0,"id":655}]}]}
{"op":"mcm","clk":"11827600058","pt":1723361018870,"mc":[{"id":"1.231582261","rc":[{"batb":[[0,2.36,10]],"ltp":2.48,"tv":2.0,"id":655}]}]}
{"op":"mcm","clk":"11827600082","pt":1723361020054,"mc":[{"id":"1.231582261","rc":[{"batb":[[0,2.34,29.13],[1,1.3,1000],[2,1.08,7.85]],"ltp":2.48,"tv":2.0,"id":655}]}]}
{"op":"mcm","clk":"11827600404","pt":1723361028798,"mc":[{"id":"1.231582261","rc":[{"batb":[[0,2.36,14],[1,2.34,29.13],[2,1.3,1000]],"ltp":2.48,"tv":2.0,"id":655}]}]}
{"op":"mcm","clk":"11827600502","pt":1723361031364,"mc":[{"id":"1.231582261","rc":[{"batb":[[0,2.36,10]],"ltp":2.48,"tv":2.0,"id":655}]}]}
{"op":"mcm","clk":"11827600543","pt":1723361032494,"mc":[{"id":"1.231582261","rc":[{"batb":[[0,2.34,29.13],[1,1.3,1000],[2,1.08,7.85]],"ltp":2.48,"tv":2.0,"id":655}]}]}
{"op":"mcm","clk":"11827600589","pt":1723361033876,"mc":[{"id":"1.231582261","rc":[{"batb":[[0,2.36,4],[1,2.34,29.13],[2,1.3,1000]],"ltp":2.48,"tv":2.0,"id":655}]}]}
{"op":"mcm","clk":"11827600631","pt":1723361035005,"mc":[{"id":"1.231582261","rc":[{"batb":[[0,2.38,10],[1,2.36,4],[2,2.34,29.13]],"ltp":2.48,"tv":2.0,"id":655}]}]}
{"op":"mcm","clk":"11827600678","pt":1723361036385,"mc":[{"id":"1.231582261","rc":[{"batb":[[1,2.34,29.13],[2,1.3,1000]],"ltp":2.48,"tv":2.0,"id":655}]}]}
{"op":"mcm","clk":"11827600750","pt":1723361038486,"mc":[{"id":"1.231582261","rc":[{"batb":[[0,2.34,29.13],[1,1.3,1000],[2,1.08,7.85]],"ltp":2.48,"tv":2.0,"id":655}]}]}
{"op":"mcm","clk":"11827600751","pt":1723361038588,"mc":[{"id":"1.231582261","rc":[{"batb":[[0,2.36,4],[1,2.34,29.13],[2,1.3,1000]],"ltp":2.48,"tv":2.0,"id":655}]}]}
{"op":"mcm","clk":"11827600822","pt":1723361041202,"mc":[{"id":"1.231582261","rc":[{"batb":[[0,2.38,10]],"ltp":2.48,"tv":2.0,"id":655}]}]}
{"op":"mcm","clk":"11827600938","pt":1723361044387,"mc":[{"id":"1.231582261","rc":[{"batb":[[0,2.4,4]],"ltp":2.48,"tv":2.0,"id":655}]}]}
{"op":"mcm","clk":"11827601009","pt":1723361046182,"mc":[{"id":"1.231582261","rc":[{"batb":[[0,2.34,29.13],[1,1.3,1000],[2,1.08,7.85]],"ltp":2.48,"tv":2.0,"id":655}]}]}
{"op":"mcm","clk":"11827601041","pt":1723361047313,"mc":[{"id":"1.231582261","rc":[{"batb":[[0,2.36,10],[1,2.34,29.13],[2,1.3,1000]],"ltp":2.48,"tv":2.0,"id":655}]}]}
{"op":"mcm","clk":"11827601114","pt":1723361049820,"mc":[{"id":"1.231582261","rc":[{"batb":[[0,2.38,4],[1,2.36,10],[2,2.34,29.13]],"ltp":2.48,"tv":2.0,"id":655}]}]}
{"op":"mcm","clk":"11827601148","pt":1723361050696,"mc":[{"id":"1.231582261","rc":[{"batb":[[1,2.34,29.13],[2,1.3,1000]],"ltp":2.48,"tv":2.0,"id":655}]}]}
{"op":"mcm","clk":"11827601197","pt":1723361052089,"mc":[{"id":"1.231582261","rc":[{"batb":[[0,2.34,29.13],[1,1.3,1000],[2,1.08,7.85]],"ltp":2.48,"tv":2.0,"id":655}]}]}
{"op":"mcm","clk":"11827601245","pt":1723361053317,"mc":[{"id":"1.231582261","rc":[{"batb":[[0,2.36,10],[1,2.34,29.13],[2,1.3,1000]],"ltp":2.48,"tv":2.0,"id":655}]}]}
{"op":"mcm","clk":"11827601360","pt":1723361056803,"mc":[{"id":"1.231582261","rc":[{"batb":[[0,2.36,4]],"ltp":2.48,"tv":2.0,"id":655}]}]}
{"op":"mcm","clk":"11827601425","pt":1723361059306,"mc":[{"id":"1.231582261","rc":[{"batb":[[0,2.34,29.13],[1,1.3,1000],[2,1.08,7.85]],"ltp":2.48,"tv":2.0,"id":655}]}]}
{"op":"mcm","clk":"11827601437","pt":1723361059715,"mc":[{"id":"1.231582261","rc":[{"batb":[[0,2.36,10],[1,2.34,29.13],[2,1.3,1000]],"ltp":2.48,"tv":2.0,"id":655}]}]}
{"op":"mcm","clk":"11827601487","pt":1723361062435,"mc":[{"id":"1.231582261","rc":[{"batb":[[0,2.38,4],[1,2.36,10],[2,2.34,29.13]],"ltp":2.48,"tv":2.0,"id":655}]}]}
{"op":"mcm","clk":"11827601515","pt":1723361063203,"mc":[{"id":"1.231582261","rc":[{"batb":[[1,2.34,29.13],[2,1.3,1000]],"ltp":2.48,"tv":2.0,"id":655}]}]}
{"op":"mcm","clk":"11827601549","pt":1723361064741,"mc":[{"id":"1.231582261","rc":[{"batb":[[0,2.34,29.13],[1,1.3,1000],[2,1.08,7.85]],"ltp":2.48,"tv":2.0,"id":655}]}]}
{"op":"mcm","clk":"11827601652","pt":1723361068322,"mc":[{"id":"1.231582261","rc":[{"batb":[[0,2.36,14],[1,2.34,29.13],[2,1.3,1000]],"ltp":2.48,"tv":2.0,"id":655}]}]}
{"op":"mcm","clk":"11827601731","pt":1723361070624,"mc":[{"id":"1.231582261","rc":[{"batb":[[0,2.36,10]],"ltp":2.48,"tv":2.0,"id":655}]}]}
{"op":"mcm","clk":"11827601764","pt":1723361071618,"mc":[{"id":"1.231582261","rc":[{"batb":[[0,2.34,29.13],[1,1.3,1000],[2,1.08,7.85]],"ltp":2.48,"tv":2.0,"id":655}]}]}
{"op":"mcm","clk":"11827601833","pt":1723361074237,"mc":[{"id":"1.231582261","rc":[{"batb":[[0,2.36,14],[1,2.34,29.13],[2,1.3,1000]],"ltp":2.48,"tv":2.0,"id":655}]}]}
{"op":"mcm","clk":"11827601902","pt":1723361076706,"mc":[{"id":"1.231582261","rc":[{"batb":[[0,2.36,10]],"ltp":2.48,"tv":2.0,"id":655}]}]}
{"op":"mcm","clk":"11827601927","pt":1723361077835,"mc":[{"id":"1.231582261","rc":[{"batb":[[0,2.34,29.13],[1,1.3,1000],[2,1.08,7.85]],"ltp":2.48,"tv":2.0,"id":655}]}]}
{"op":"mcm","clk":"11827601985","pt":1723361080150,"mc":[{"id":"1.231582261","rc":[{"batb":[[0,2.36,14],[1,2.34,29.13],[2,1.3,1000]],"ltp":2.48,"tv":2.0,"id":655}]}]}
{"op":"mcm","clk":"11827602077","pt":1723361083127,"mc":[{"id":"1.231582261","rc":[{"batb":[[0,2.36,10]],"ltp":2.48,"tv":2.0,"id":655}]}]}
{"op":"mcm","clk":"11827602113","pt":1723361083949,"mc":[{"id":"1.231582261","rc":[{"batb":[[0,2.34,29.13],[1,1.3,1000],[2,1.08,7.85]],"ltp":2.48,"tv":2.0,"id":655}]}]}
{"op":"mcm","clk":"11827602153","pt":1723361085228,"mc":[{"id":"1.231582261","rc":[{"batb":[[0,2.36,4],[1,2.34,29.13],[2,1.3,1000]],"ltp":2.48,"tv":2.0,"id":655}]}]}
{"op":"mcm","clk":"11827602204","pt":1723361086459,"mc":[{"id":"1.231582261","rc":[{"batb":[[0,2.38,10],[1,2.36,4],[2,2.34,29.13]],"ltp":2.48,"tv":2.0,"id":655}]}]}
{"op":"mcm","clk":"11827602248","pt":1723361087644,"mc":[{"id":"1.231582261","rc":[{"batb":[[1,2.34,29.13],[2,1.3,1000]],"ltp":2.48,"tv":2.0,"id":655}]}]}
{"op":"mcm","clk":"11827602338","pt":1723361090151,"mc":[{"id":"1.231582261","rc":[{"batb":[[0,2.36,4]],"ltp":2.48,"tv":2.0,"id":655}]}]}
{"op":"mcm","clk":"11827602402","pt":1723361092467,"mc":[{"id":"1.231582261","rc":[{"batb":[[0,2.34,29.13],[1,1.3,1000],[2,1.08,7.85]],"ltp":2.48,"tv":2.0,"id":655}]}]}
{"op":"mcm","clk":"11827602411","pt":1723361092668,"mc":[{"id":"1.231582261","rc":[{"batb":[[0,2.36,10],[1,2.34,29.13],[2,1.3,1000]],"ltp":2.48,"tv":2.0,"id":655}]}]}
{"op":"mcm","clk":"11827602506","pt":1723361095953,"mc":[{"id":"1.231582261","rc":[{"batb":[[0,2.38,4]],"ltp":2.48,"tv":2.0,"id":655}]}]}
{"op":"mcm","clk":"11827602569","pt":1723361098256,"mc":[{"id":"1.231582261","rc":[{"batb":[[0,2.34,29.13],[1,1.3,1000],[2,1.08,7.85]],"ltp":2.48,"tv":2.0,"id":655}]}]}
{"op":"mcm","clk":"11827602579","pt":1723361098564,"mc":[{"id":"1.231582261","rc":[{"batb":[[0,2.36,10],[1,2.34,29.13],[2,1.3,1000]],"ltp":2.48,"tv":2.0,"id":655}]}]}
{"op":"mcm","clk":"11827602678","pt":1723361102068,"mc":[{"id":"1.231582261","rc":[{"batb":[[0,2.38,4]],"ltp":2.48,"tv":2.0,"id":655}]}]}
{"op":"mcm","clk":"11827602760","pt":1723361104851,"mc":[{"id":"1.231582261","rc":[{"batb":[[0,2.36,10]],"ltp":2.48,"tv":2.0,"id":655}]}]}
{"op":"mcm","clk":"11827602876","pt":1723361108204,"mc":[{"id":"1.231582261","rc":[{"batb":[[0,2.38,4]],"ltp":2.48,"tv":2.0,"id":655}]}]}
{"op":"mcm","clk":"11827602966","pt":1723361110464,"mc":[{"id":"1.231582261","rc":[{"batb":[[0,2.36,10]],"ltp":2.48,"tv":2.0,"id":655}]}]}
{"op":"mcm","clk":"11827603071","pt":1723361113083,"mc":[{"id":"1.231582261","rc":[{"batb":[[0,2.38,4],[1,2.36,10],[2,2.34,29.13]],"ltp":2.48,"tv":2.0,"id":655}]}]}
{"op":"mcm","clk":"11827603090","pt":1723361113902,"mc":[{"id":"1.231582261","rc":[{"batb":[[1,2.34,29.13],[2,1.3,1000]],"ltp":2.48,"tv":2.0,"id":655}]}]}
{"op":"mcm","clk":"11827603194","pt":1723361116084,"mc":[{"id":"1.231582261","rc":[{"batb":[[0,2.36,10]],"ltp":2.48,"tv":2.0,"id":655}]}]}
{"op":"mcm","clk":"11827603337","pt":1723361119485,"mc":[{"id":"1.231582261","rc":[{"batb":[[0,2.38,4]],"ltp":2.48,"tv":2.0,"id":655}]}]}
{"op":"mcm","clk":"11827603416","pt":1723361121291,"mc":[{"id":"1.231582261","rc":[{"batb":[[0,2.34,29.13],[1,1.3,1000],[2,1.08,7.85]],"ltp":2.48,"tv":2.0,"id":655}]}]}
{"op":"mcm","clk":"11827603572","pt":1723361124995,"mc":[{"id":"1.231582261","rc":[{"batb":[[0,2.36,14],[1,2.34,29.13],[2,1.3,1000]],"ltp":2.48,"tv":2.0,"id":655}]}]}
{"op":"mcm","clk":"11827603648","pt":1723361127407,"mc":[{"id":"1.231582261","rc":[{"batb":[[0,2.36,10]],"ltp":2.48,"tv":2.0,"id":655}]}]}
{"op":"mcm","clk":"11827603672","pt":1723361128278,"mc":[{"id":"1.231582261","rc":[{"batb":[[0,2.34,29.13],[1,1.3,1000],[2,1.08,7.85]],"ltp":2.48,"tv":2.0,"id":655}]}]}
{"op":"mcm","clk":"11827603784","pt":1723361130810,"mc":[{"id":"1.231582261","rc":[{"batb":[[0,2.36,14],[1,2.34,29.13],[2,1.3,1000]],"ltp":2.48,"tv":2.0,"id":655}]}]}
{"op":"mcm","clk":"11827603867","pt":1723361133024,"mc":[{"id":"1.231582261","rc":[{"batb":[[0,2.36,10]],"ltp":2.48,"tv":2.0,"id":655}]}]}
{"op":"mcm","clk":"11827603916","pt":1723361134101,"mc":[{"id":"1.231582261","rc":[{"batb":[[0,2.34,29.13],[1,1.3,1000],[2,1.08,7.85]],"ltp":2.48,"tv":2.0,"id":655}]}]}
{"op":"mcm","clk":"11827603966","pt":1723361135384,"mc":[{"id":"1.231582261","rc":[{"batb":[[0,2.36,4],[1,2.34,29.13],[2,1.3,1000]],"ltp":2.48,"tv":2.0,"id":655}]}]}
{"op":"mcm","clk":"11827604010","pt":1723361136788,"mc":[{"id":"1.231582261","rc":[{"batb":[[0,2.38,10],[1,2.36,4],[2,2.34,29.13]],"ltp":2.48,"tv":2.0,"id":655}]}]}
{"op":"mcm","clk":"11827604041","pt":1723361137713,"mc":[{"id":"1.231582261","rc":[{"batb":[[1,2.34,29.13],[2,1.3,1000]],"ltp":2.48,"tv":2.0,"id":655}]}]}
{"op":"mcm","clk":"11827604163","pt":1723361140414,"mc":[{"id":"1.231582261","rc":[{"batb":[[0,2.34,29.13],[1,1.3,1000],[2,1.08,7.85]],"ltp":2.48,"tv":2.0,"id":655}]}]}
{"op":"mcm","clk":"11827604185","pt":1723361140827,"mc":[{"id":"1.231582261","rc":[{"batb":[[0,2.36,4],[1,2.34,29.13],[2,1.3,1000]],"ltp":2.48,"tv":2.0,"id":655}]}]}
{"op":"mcm","clk":"11827604284","pt":1723361143239,"mc":[{"id":"1.231582261","rc":[{"batb":[[0,2.36,10]],"ltp":2.48,"tv":2.0,"id":655}]}]}
{"op":"mcm","clk":"11827604461","pt":1723361146499,"mc":[{"id":"1.231582261","rc":[{"batb":[[0,2.38,4]],"ltp":2.48,"tv":2.0,"id":655}]}]}
{"op":"mcm","clk":"11827604565","pt":1723361148808,"mc":[{"id":"1.231582261","rc":[{"batb":[[0,2.36,10]],"ltp":2.48,"tv":2.0,"id":655}]}]}
{"op":"mcm","clk":"11827604694","pt":1723361151422,"mc":[{"id":"1.231582261","rc":[{"batb":[[0,2.38,4],[1,2.36,10],[2,2.34,29.13]],"ltp":2.48,"tv":2.0,"id":655}]}]}
{"op":"mcm","clk":"11827604720","pt":1723361152143,"mc":[{"id":"1.231582261","rc":[{"batb":[[1,2.34,29.13],[2,1.3,1000]],"ltp":2.48,"tv":2.0,"id":655}]}]}
{"op":"mcm","clk":"11827604803","pt":1723361153735,"mc":[{"id":"1.231582261","rc":[{"batb":[[0,2.34,29.13],[1,1.3,1000],[2,1.08,7.85]],"ltp":2.48,"tv":2.0,"id":655}]}]}
{"op":"mcm","clk":"11827604877","pt":1723361155222,"mc":[{"id":"1.231582261","rc":[{"batb":[[0,2.36,10],[1,2.34,29.13],[2,1.3,1000]],"ltp":2.48,"tv":2.0,"id":655}]}]}
{"op":"mcm","clk":"11827604932","pt":1723361156302,"mc":[{"id":"1.231582261","rc":[{"batb":[[0,2.38,4],[1,2.36,10],[2,2.34,29.13]],"ltp":2.48,"tv":2.0,"id":655}]}]}
{"op":"mcm","clk":"11827605039","pt":1723361158914,"mc":[{"id":"1.231582261","rc":[{"batb":[[0,2.34,29.13],[1,1.3,1000],[2,1.08,7.85]],"ltp":2.48,"tv":2.0,"id":655}]}]}
{"op":"mcm","clk":"11827605133","pt":1723361161514,"mc":[{"id":"1.231582261","rc":[{"batb":[[0,2.36,14],[1,2.34,29.13],[2,1.3,1000]],"ltp":2.48,"tv":2.0,"id":655}]}]}
{"op":"mcm","clk":"11827605201","pt":1723361163931,"mc":[{"id":"1.231582261","rc":[{"batb":[[0,2.36,10]],"ltp":2.48,"tv":2.0,"id":655}]}]}
{"op":"mcm","clk":"11827605228","pt":1723361164911,"mc":[{"id":"1.231582261","rc":[{"batb":[[0,2.34,29.13],[1,1.3,1000],[2,1.08,7.85]],"ltp":2.48,"tv":2.0,"id":655}]}]}
{"op":"mcm","clk":"11827605439","pt":1723361169838,"mc":[{"id":"1.231582261","rc":[{"batb":[[0,2.36,14],[1,2.34,29.13],[2,1.3,1000]],"ltp":2.48,"tv":2.0,"id":655}]}]}
{"op":"mcm","clk":"11827605570","pt":1723361172124,"mc":[{"id":"1.231582261","rc":[{"batb":[[0,2.36,10]],"ltp":2.48,"tv":2.0,"id":655}]}]}
{"op":"mcm","clk":"11827605622","pt":1723361173153,"mc":[{"id":"1.231582261","rc":[{"batb":[[0,2.34,29.13],[1,1.3,1000],[2,1.08,7.85]],"ltp":2.48,"tv":2.0,"id":655}]}]}
{"op":"mcm","clk":"11827605666","pt":1723361174330,"mc":[{"id":"1.231582261","rc":[{"batb":[[0,2.36,4],[1,2.34,29.13],[2,1.3,1000]],"ltp":2.48,"tv":2.0,"id":655}]}]}
{"op":"mcm","clk":"11827605720","pt":1723361175717,"mc":[{"id":"1.231582261","rc":[{"batb":[[0,2.38,10],[1,2.36,4],[2,2.34,29.13]],"ltp":2.48,"tv":2.0,"id":655}]}]}
{"op":"mcm","clk":"11827605754","pt":1723361176637,"mc":[{"id":"1.231582261","rc":[{"batb":[[1,2.34,29.13],[2,1.3,1000]],"ltp":2.48,"tv":2.0,"id":655}]}]}
{"op":"mcm","clk":"11827605856","pt":1723361179150,"mc":[{"id":"1.231582261","rc":[{"batb":[[0,2.4,4]],"ltp":2.48,"tv":2.0,"id":655}]}]}
{"op":"mcm","clk":"11827605937","pt":1723361181455,"mc":[{"id":"1.231582261","rc":[{"batb":[[0,2.42,10]],"ltp":2.48,"tv":2.0,"id":655}]}]}
{"op":"mcm","clk":"11827606021","pt":1723361183663,"mc":[{"id":"1.231582261","rc":[{"batb":[[0,2.44,4],[1,2.42,10],[2,2.34,29.13]],"ltp":2.48,"tv":2.0,"id":655}]}]}
{"op":"mcm","clk":"11827606061","pt":1723361184665,"mc":[{"id":"1.231582261","rc":[{"batb":[[1,2.34,29.13],[2,1.3,1000]],"ltp":2.48,"tv":2.0,"id":655}]}]}
{"op":"mcm","clk":"11827606104","pt":1723361185842,"mc":[{"id":"1.231582261","rc":[{"batb":[[0,2.34,29.13],[1,1.3,1000],[2,1.08,7.85]],"ltp":2.48,"tv":2.0,"id":655}]}]}
{"op":"mcm","clk":"11827606178","pt":1723361188040,"mc":[{"id":"1.231582261","rc":[{"batb":[[0,2.38,4],[1,2.36,10],[2,2.34,29.13]],"ltp":2.48,"tv":2.0,"id":655}]}]}
{"op":"mcm","clk":"11827606337","pt":1723361191468,"mc":[{"id":"1.231582261","rc":[{"trd":[[2.48,7]],"batb":[[0,2.34,29.13],[1,1.3,1000],[2,1.08,7.85]],"ltp":2.48,"tv":7.0,"id":655},{"trd":[[1.67,10.4]],"batl":[[0,1.67,132.19]],"ltp":1.67,"tv":207.92,"id":2120}],"tv":214.92}]}
{"op":"mcm","clk":"11827606436","pt":1723361194076,"mc":[{"id":"1.231582261","rc":[{"batb":[[0,2.36,14],[1,2.34,29.13],[2,1.3,1000]],"ltp":2.48,"tv":7.0,"id":655}]}]}
{"op":"mcm","clk":"11827606522","pt":1723361196755,"mc":[{"id":"1.231582261","rc":[{"batb":[[0,2.36,10]],"ltp":2.48,"tv":7.0,"id":655}]}]}
{"op":"mcm","clk":"11827606556","pt":1723361197577,"mc":[{"id":"1.231582261","rc":[{"batb":[[0,2.34,29.13],[1,1.3,1000],[2,1.08,7.85]],"ltp":2.48,"tv":7.0,"id":655}]}]}
{"op":"mcm","clk":"11827606600","pt":1723361198956,"mc":[{"id":"1.231582261","rc":[{"batb":[[0,2.36,4],[1,2.34,29.13],[2,1.3,1000]],"ltp":2.48,"tv":7.0,"id":655}]}]}
{"op":"mcm","clk":"11827606676","pt":1723361201260,"mc":[{"id":"1.231582261","rc":[{"batb":[[0,2.34,29.13],[1,1.3,1000],[2,1.08,7.85]],"ltp":2.48,"tv":7.0,"id":655}]}]}
{"op":"mcm","clk":"11827606688","pt":1723361201567,"mc":[{"id":"1.231582261","rc":[{"batb":[[0,2.38,10],[1,2.34,29.13],[2,1.3,1000]],"ltp":2.48,"tv":7.0,"id":655}]}]}
{"op":"mcm","clk":"11827606785","pt":1723361204074,"mc":[{"id":"1.231582261","rc":[{"batb":[[0,2.4,4],[1,2.38,10],[2,2.34,29.13]],"ltp":2.48,"tv":7.0,"id":655}]}]}
{"op":"mcm","clk":"11827606837","pt":1723361205355,"mc":[{"id":"1.231582261","rc":[{"batb":[[1,2.34,29.13],[2,1.3,1000]],"ltp":2.48,"tv":7.0,"id":655}]}]}
{"op":"mcm","clk":"11827606885","pt":1723361206683,"mc":[{"id":"1.231582261","rc":[{"batb":[[0,2.34,29.13],[1,1.3,1000],[2,1.08,7.85]],"ltp":2.48,"tv":7.0,"id":655}]}]}
{"op":"mcm","clk":"11827607007","pt":1723361209758,"mc":[{"id":"1.231582261","rc":[{"batb":[[0,2.36,14],[1,2.34,29.13],[2,1.3,1000]],"ltp":2.48,"tv":7.0,"id":655}]}]}
{"op":"mcm","clk":"11827607076","pt":1723361212061,"mc":[{"id":"1.231582261","rc":[{"batb":[[0,2.36,10]],"ltp":2.48,"tv":7.0,"id":655}]}]}
{"op":"mcm","clk":"11827607115","pt":1723361213286,"mc":[{"id":"1.231582261","rc":[{"batb":[[0,2.34,29.13],[1,1.3,1000],[2,1.08,7.85]],"ltp":2.48,"tv":7.0,"id":655}]}]}
{"op":"mcm","clk":"11827607185","pt":1723361215076,"mc":[{"id":"1.231582261","rc":[{"batb":[[0,2.36,4],[1,2.34,29.13],[2,1.3,1000]],"ltp":2.48,"tv":7.0,"id":655}]}]}
{"op":"mcm","clk":"11827607259","pt":1723361217483,"mc":[{"id":"1.231582261","rc":[{"batb":[[0,2.38,10]],"ltp":2.48,"tv":7.0,"id":655}]}]}
{"op":"mcm","clk":"11827607363","pt":1723361220360,"mc":[{"id":"1.231582261","rc":[{"batb":[[0,2.36,4]],"ltp":2.48,"tv":7.0,"id":655}]}]}
{"op":"mcm","clk":"11827607455","pt":1723361222777,"mc":[{"id":"1.231582261","rc":[{"batb":[[0,2.36,10]],"ltp":2.48,"tv":7.0,"id":655}]}]}
{"op":"mcm","clk":"11827607589","pt":1723361225972,"mc":[{"id":"1.231582261","rc":[{"batb":[[0,2.38,4]],"ltp":2.48,"tv":7.0,"id":655}]}]}
{"op":"mcm","clk":"11827607694","pt":1723361228309,"mc":[{"id":"1.231582261","rc":[{"batb":[[0,2.34,29.13],[1,1.3,1000],[2,1.08,7.85]],"ltp":2.48,"tv":7.0,"id":655}]}]}
{"op":"mcm","clk":"11827607733","pt":1723361228984,"mc":[{"id":"1.231582261","rc":[{"batb":[[0,2.36,10],[1,2.34,29.13],[2,1.3,1000]],"ltp":2.48,"tv":7.0,"id":655}]}]}
{"op":"mcm","clk":"11827607844","pt":1723361231473,"mc":[{"id":"1.231582261","rc":[{"batb":[[0,2.38,4],[1,2.36,10],[2,2.34,29.13]],"ltp":2.48,"tv":7.0,"id":655}]}]}
{"op":"mcm","clk":"11827607882","pt":1723361232491,"mc":[{"id":"1.231582261","rc":[{"batb":[[1,2.34,29.13],[2,1.3,1000]],"ltp":2.48,"tv":7.0,"id":655}]}]}
{"op":"mcm","clk":"11827607954","pt":1723361234286,"mc":[{"id":"1.231582261","rc":[{"batb":[[0,2.34,29.13],[1,1.3,1000],[2,1.08,7.85]],"ltp":2.48,"tv":7.0,"id":655}]}]}
{"op":"mcm","clk":"11827608066","pt":1723361237317,"mc":[{"id":"1.231582261","rc":[{"batb":[[0,2.36,14],[1,2.34,29.13],[2,1.3,1000]],"ltp":2.48,"tv":7.0,"id":655}]}]}
{"op":"mcm","clk":"11827608172","pt":1723361240489,"mc":[{"id":"1.231582261","rc":[{"batb":[[0,2.34,29.13],[1,1.3,1000],[2,1.08,7.85]],"ltp":2.48,"tv":7.0,"id":655}]}]}
{"op":"mcm","clk":"11827608200","pt":1723361241920,"mc":[{"id":"1.231582261","rc":[{"batb":[[0,2.36,4],[1,2.34,29.13],[2,1.3,1000]],"ltp":2.48,"tv":7.0,"id":655}]}]}
{"op":"mcm","clk":"11827608272","pt":1723361244321,"mc":[{"id":"1.231582261","rc":[{"batb":[[0,2.38,10]],"ltp":2.48,"tv":7.0,"id":655}]}]}
{"op":"mcm","clk":"11827608401","pt":1723361247497,"mc":[{"id":"1.231582261","rc":[{"batb":[[0,2.34,29.13],[1,1.3,1000],[2,1.08,7.85]],"ltp":2.48,"tv":7.0,"id":655}]}]}
{"op":"mcm","clk":"11827608404","pt":1723361247597,"mc":[{"id":"1.231582261","rc":[{"batb":[[0,2.4,4],[1,2.34,29.13],[2,1.3,1000]],"ltp":2.48,"tv":7.0,"id":655}]}]}
{"op":"mcm","clk":"11827608489","pt":1723361250103,"mc":[{"id":"1.231582261","rc":[{"batb":[[0,2.36,10]],"ltp":2.48,"tv":7.0,"id":655}]}]}
{"op":"mcm","clk":"11827608568","pt":1723361252502,"mc":[{"id":"1.231582261","rc":[{"batb":[[0,2.38,4],[1,2.36,10],[2,2.34,29.13]],"ltp":2.48,"tv":7.0,"id":655}]}]}
{"op":"mcm","clk":"11827608609","pt":1723361253422,"mc":[{"id":"1.231582261","rc":[{"batb":[[1,2.34,29.13],[2,1.3,1000]],"ltp":2.48,"tv":7.0,"id":655}]}]}
{"op":"mcm","clk":"11827608656","pt":1723361255007,"mc":[{"id":"1.231582261","rc":[{"batb":[[0,2.34,29.13],[1,1.3,1000],[2,1.08,7.85]],"ltp":2.48,"tv":7.0,"id":655}]}]}
{"op":"mcm","clk":"11827608685","pt":1723361256235,"mc":[{"id":"1.231582261","rc":[{"batb":[[0,2.36,10],[1,2.34,29.13],[2,1.3,1000]],"ltp":2.48,"tv":7.0,"id":655}]}]}
{"op":"mcm","clk":"11827608720","pt":1723361257309,"mc":[{"id":"1.231582261","rc":[{"batb":[[0,2.38,4],[1,2.36,10],[2,2.34,29.13]],"ltp":2.48,"tv":7.0,"id":655}]}]}
{"op":"mcm","clk":"11827608797","pt":1723361259507,"mc":[{"id":"1.231582261","rc":[{"batb":[[1,2.34,29.13],[2,1.3,1000]],"ltp":2.48,"tv":7.0,"id":655}]}]}
{"op":"mcm","clk":"11827608802","pt":1723361259710,"mc":[{"id":"1.231582261","rc":[{"batb":[[0,2.34,29.13],[1,1.3,1000],[2,1.08,7.85]],"ltp":2.48,"tv":7.0,"id":655}]}]}
{"op":"mcm","clk":"11827608873","pt":1723361262219,"mc":[{"id":"1.231582261","rc":[{"batb":[[0,2.36,14],[1,2.34,29.13],[2,1.3,1000]],"ltp":2.48,"tv":7.0,"id":655}]}]}
{"op":"mcm","clk":"11827608965","pt":1723361264632,"mc":[{"id":"1.231582261","rc":[{"batb":[[0,2.36,10]],"ltp":2.48,"tv":7.0,"id":655}]}]}
{"op":"mcm","clk":"11827609004","pt":1723361265607,"mc":[{"id":"1.231582261","rc":[{"batb":[[0,2.34,29.13],[1,1.3,1000],[2,1.08,7.85]],"ltp":2.48,"tv":7.0,"id":655}]}]}
{"op":"mcm","clk":"11827609053","pt":1723361267552,"mc":[{"id":"1.231582261","rc":[{"batb":[[0,2.36,4],[1,2.34,29.13],[2,1.3,1000]],"ltp":2.48,"tv":7.0,"id":655}]}]}
{"op":"mcm","clk":"11827609090","pt":1723361268752,"mc":[{"id":"1.231582261","rc":[{"batb":[[0,2.38,10],[1,2.36,4],[2,2.34,29.13]],"ltp":2.48,"tv":7.0,"id":655}]}]}
{"op":"mcm","clk":"11827609134","pt":1723361270029,"mc":[{"id":"1.231582261","rc":[{"batb":[[1,2.34,29.13],[2,1.3,1000]],"ltp":2.48,"tv":7.0,"id":655}]}]}
{"op":"mcm","clk":"11827609201","pt":1723361272029,"mc":[{"id":"1.231582261","rc":[{"batb":[[0,2.34,29.13],[1,1.3,1000],[2,1.08,7.85]],"ltp":2.48,"tv":7.0,"id":655}]}]}
{"op":"mcm","clk":"11827609242","pt":1723361273109,"mc":[{"id":"1.231582261","rc":[{"batb":[[0,2.36,4],[1,2.34,29.13],[2,1.3,1000]],"ltp":2.48,"tv":7.0,"id":655}]}]}
{"op":"mcm","clk":"11827609274","pt":1723361274336,"mc":[{"id":"1.231582261","rc":[{"batb":[[0,2.38,10],[1,2.36,4],[2,2.34,29.13]],"ltp":2.48,"tv":7.0,"id":655}]}]}
{"op":"mcm","clk":"11827609334","pt":1723361275522,"mc":[{"id":"1.231582261","rc":[{"batb":[[1,2.34,29.13],[2,1.3,1000]],"ltp":2.48,"tv":7.0,"id":655}]}]}
{"op":"mcm","clk":"11827609437","pt":1723361277743,"mc":[{"id":"1.231582261","rc":[{"batb":[[0,2.34,29.13],[1,1.3,1000],[2,1.08,7.85]],"ltp":2.48,"tv":7.0,"id":655}]}]}
{"op":"mcm","clk":"11827609497","pt":1723361278934,"mc":[{"id":"1.231582261","rc":[{"batb":[[0,2.36,4],[1,2.34,29.13],[2,1.3,1000]],"ltp":2.48,"tv":7.0,"id":655}]}]}
{"op":"mcm","clk":"11827609534","pt":1723361280069,"mc":[{"id":"1.231582261","rc":[{"batb":[[0,2.38,10],[1,2.36,4],[2,2.34,29.13]],"ltp":2.48,"tv":7.0,"id":655}]}]}
{"op":"mcm","clk":"11827609597","pt":1723361281353,"mc":[{"id":"1.231582261","rc":[{"batb":[[1,2.34,29.13],[2,1.3,1000]],"ltp":2.48,"tv":7.0,"id":655}]}]}
{"op":"mcm","clk":"11827609676","pt":1723361283331,"mc":[{"id":"1.231582261","rc":[{"batb":[[0,2.34,29.13],[1,1.3,1000],[2,1.08,7.85]],"ltp":2.48,"tv":7.0,"id":655}]}]}
{"op":"mcm","clk":"11827609801","pt":1723361286259,"mc":[{"id":"1.231582261","rc":[{"batb":[[0,2.36,14],[1,2.34,29.13],[2,1.3,1000]],"ltp":2.48,"tv":7.0,"id":655}]}]}
{"op":"mcm","clk":"11827609934","pt":1723361288472,"mc":[{"id":"1.231582261","rc":[{"batb":[[0,2.36,10]],"ltp":2.48,"tv":7.0,"id":655}]}]}
{"op":"mcm","clk":"11827609985","pt":1723361289551,"mc":[{"id":"1.231582261","rc":[{"batb":[[0,2.34,29.13],[1,1.3,1000],[2,1.08,7.85]],"ltp":2.48,"tv":7.0,"id":655}]}]}
{"op":"mcm","clk":"11827610057","pt":1723361291553,"mc":[{"id":"1.231582261","rc":[{"batb":[[0,2.36,4],[1,2.34,29.13],[2,1.3,1000]],"ltp":2.48,"tv":7.0,"id":655}]}]}
{"op":"mcm","clk":"11827610142","pt":1723361293454,"mc":[{"id":"1.231582261","rc":[{"batb":[[0,2.38,10],[1,2.36,4],[2,2.34,29.13]],"ltp":2.48,"tv":7.0,"id":655}]}]}
{"op":"mcm","clk":"11827610154","pt":1723361293863,"mc":[{"id":"1.231582261","rc":[{"batb":[[1,2.34,29.13],[2,1.3,1000]],"ltp":2.48,"tv":7.0,"id":655}]}]}
{"op":"mcm","clk":"11827610237","pt":1723361296275,"mc":[{"id":"1.231582261","rc":[{"batb":[[0,2.4,4],[1,2.38,10],[2,2.34,29.13]],"ltp":2.48,"tv":7.0,"id":655}]}]}
{"op":"mcm","clk":"11827610273","pt":1723361297148,"mc":[{"id":"1.231582261","rc":[{"batb":[[1,2.34,29.13],[2,1.3,1000]],"ltp":2.48,"tv":7.0,"id":655}]}]}
{"op":"mcm","clk":"11827610372","pt":1723361299050,"mc":[{"id":"1.231582261","rc":[{"batb":[[0,2.34,29.13],[1,1.3,1000],[2,1.08,7.85]],"ltp":2.48,"tv":7.0,"id":655}]}]}
{"op":"mcm","clk":"11827610421","pt":1723361300284,"mc":[{"id":"1.231582261","rc":[{"batb":[[0,2.36,10],[1,2.34,29.13],[2,1.3,1000]],"ltp":2.48,"tv":7.0,"id":655}]}]}
{"op":"mcm","clk":"11827610492","pt":1723361301972,"mc":[{"id":"1.231582261","rc":[{"batb":[[0,2.38,4],[1,2.36,10],[2,2.34,29.13]],"ltp":2.48,"tv":7.0,"id":655}]}]}
{"op":"mcm","clk":"11827610604","pt":1723361304391,"mc":[{"id":"1.231582261","rc":[{"batb":[[0,2.34,29.13],[1,1.3,1000],[2,1.08,7.85]],"ltp":2.48,"tv":7.0,"id":655}]}]}
{"op":"mcm","clk":"11827610720","pt":1723361306963,"mc":[{"id":"1.231582261","rc":[{"batb":[[0,2.36,14],[1,2.34,29.13],[2,1.3,1000]],"ltp":2.48,"tv":7.0,"id":655}]}]}
{"op":"mcm","clk":"11827610820","pt":1723361309988,"mc":[{"id":"1.231582261","rc":[{"batb":[[0,2.36,10]],"ltp":2.48,"tv":7.0,"id":655}]}]}
{"op":"mcm","clk":"11827610874","pt":1723361311061,"mc":[{"id":"1.231582261","rc":[{"batb":[[0,2.34,29.13],[1,1.3,1000],[2,1.08,7.85]],"ltp":2.48,"tv":7.0,"id":655}]}]}
{"op":"mcm","clk":"11827610974","pt":1723361313363,"mc":[{"id":"1.231582261","rc":[{"batb":[[0,2.38,10],[1,2.36,4],[2,2.34,29.13]],"ltp":2.48,"tv":7.0,"id":655}]}]}
{"op":"mcm","clk":"11827611077","pt":1723361315467,"mc":[{"id":"1.231582261","rc":[{"batb":[[1,2.34,29.13],[2,1.3,1000]],"ltp":2.48,"tv":7.0,"id":655}]}]}
{"op":"mcm","clk":"11827611139","pt":1723361316706,"mc":[{"id":"1.231582261","rc":[{"batb":[[0,2.34,29.13],[1,1.3,1000],[2,1.08,7.85]],"ltp":2.48,"tv":7.0,"id":655}]}]}
{"op":"mcm","clk":"11827611185","pt":1723361318088,"mc":[{"id":"1.231582261","rc":[{"batb":[[0,2.36,4],[1,2.34,29.13],[2,1.3,1000]],"ltp":2.48,"tv":7.0,"id":655}]}]}
{"op":"mcm","clk":"11827611217","pt":1723361319268,"mc":[{"id":"1.231582261","rc":[{"batb":[[0,2.38,10],[1,2.36,4],[2,2.34,29.13]],"ltp":2.48,"tv":7.0,"id":655}]}]}
{"op":"mcm","clk":"11827611255","pt":1723361320390,"mc":[{"id":"1.231582261","rc":[{"batb":[[1,2.34,29.13],[2,1.3,1000]],"ltp":2.48,"tv":7.0,"id":655}]}]}
{"op":"mcm","clk":"11827611369","pt":1723361322903,"mc":[{"id":"1.231582261","rc":[{"batb":[[0,2.4,4]],"ltp":2.48,"tv":7.0,"id":655}]}]}
{"op":"mcm","clk":"11827611476","pt":1723361326793,"mc":[{"id":"1.231582261","rc":[{"batb":[[0,2.34,29.13],[1,1.3,1000],[2,1.08,7.85]],"ltp":2.48,"tv":7.0,"id":655}]}]}
{"op":"mcm","clk":"11827611531","pt":1723361327819,"mc":[{"id":"1.231582261","rc":[{"batb":[[0,2.36,10],[1,2.34,29.13],[2,1.3,1000]],"ltp":2.48,"tv":7.0,"id":655}]}]}
{"op":"mcm","clk":"11827611575","pt":1723361329303,"mc":[{"id":"1.231582261","rc":[{"batb":[[0,2.38,4],[1,2.36,10],[2,2.34,29.13]],"ltp":2.48,"tv":7.0,"id":655}]}]}
{"op":"mcm","clk":"11827611666","pt":1723361331505,"mc":[{"id":"1.231582261","rc":[{"batb":[[0,2.36,10],[1,2.34,29.13],[2,1.3,1000]],"ltp":2.48,"tv":7.0,"id":655}]}]}
{"op":"mcm","clk":"11827611692","pt":1723361332219,"mc":[{"id":"1.231582261","rc":[{"batb":[[0,2.34,29.13],[1,1.3,1000],[2,1.08,7.85]],"ltp":2.48,"tv":7.0,"id":655}]}]}
{"op":"mcm","clk":"11827611743","pt":1723361334379,"mc":[{"id":"1.231582261","rc":[{"batb":[[0,2.38,10],[1,2.36,4],[2,2.34,29.13]],"ltp":2.48,"tv":7.0,"id":655}]}]}
{"op":"mcm","clk":"11827611835","pt":1723361336594,"mc":[{"id":"1.231582261","rc":[{"batb":[[1,2.34,29.13],[2,1.3,1000]],"ltp":2.48,"tv":7.0,"id":655}]}]}
{"op":"mcm","clk":"11827611860","pt":1723361337721,"mc":[{"id":"1.231582261","rc":[{"batb":[[0,2.34,29.13],[1,1.3,1000],[2,1.08,7.85]],"ltp":2.48,"tv":7.0,"id":655}]}]}
{"op":"mcm","clk":"11827611969","pt":1723361340895,"mc":[{"id":"1.231582261","rc":[{"batb":[[0,2.36,14],[1,2.34,29.13],[2,1.3,1000]],"ltp":2.48,"tv":7.0,"id":655}]}]}
{"op":"mcm","clk":"11827612101","pt":1723361344406,"mc":[{"id":"1.231582261","rc":[{"batb":[[0,2.34,29.13],[1,1.3,1000],[2,1.08,7.85]],"ltp":2.48,"tv":7.0,"id":655}]}]}
{"op":"mcm","clk":"11827612158","pt":1723361345738,"mc":[{"id":"1.231582261","rc":[{"batb":[[0,2.36,4],[1,2.34,29.13],[2,1.3,1000]],"ltp":2.48,"tv":7.0,"id":655}]}]}
{"op":"mcm","clk":"11827612200","pt":1723361346919,"mc":[{"id":"1.231582261","rc":[{"batb":[[0,2.38,10],[1,2.36,4],[2,2.34,29.13]],"ltp":2.48,"tv":7.0,"id":655}]}]}
{"op":"mcm","clk":"11827612248","pt":1723361348098,"mc":[{"id":"1.231582261","rc":[{"batb":[[1,2.34,29.13],[2,1.3,1000]],"ltp":2.48,"tv":7.0,"id":655}]}]}
{"op":"mcm","clk":"11827612348","pt":1723361350306,"mc":[{"id":"1.231582261","rc":[{"batb":[[0,2.36,4]],"ltp":2.48,"tv":7.0,"id":655}]}]}
{"op":"mcm","clk":"11827612430","pt":1723361352619,"mc":[{"id":"1.231582261","rc":[{"batb":[[0,2.38,10]],"ltp":2.48,"tv":7.0,"id":655}]}]}
{"op":"mcm","clk":"11827612553","pt":1723361355914,"mc":[{"id":"1.231582261","rc":[{"batb":[[0,2.4,4]],"ltp":2.48,"tv":7.0,"id":655}]}]}
{"op":"mcm","clk":"11827612671","pt":1723361358328,"mc":[{"id":"1.231582261","rc":[{"batb":[[0,2.36,10]],"ltp":2.48,"tv":7.0,"id":655}]}]}
{"op":"mcm","clk":"11827612831","pt":1723361361919,"mc":[{"id":"1.231582261","rc":[{"batb":[[0,2.36,4]],"ltp":2.48,"tv":7.0,"id":655}]}]}
{"op":"mcm","clk":"11827612918","pt":1723361364329,"mc":[{"id":"1.231582261","rc":[{"batb":[[0,2.38,10],[1,2.36,4],[2,2.34,29.13]],"ltp":2.48,"tv":7.0,"id":655}]}]}
{"op":"mcm","clk":"11827612923","pt":1723361364534,"mc":[{"id":"1.231582261","rc":[{"batb":[[1,2.34,29.13],[2,1.3,1000]],"ltp":2.48,"tv":7.0,"id":655}]}]}
{"op":"mcm","clk":"11827613032","pt":1723361367762,"mc":[{"id":"1.231582261","rc":[{"batb":[[0,2.4,4]],"ltp":2.48,"tv":7.0,"id":655}]}]}
{"op":"mcm","clk":"11827613152","pt":1723361370442,"mc":[{"id":"1.231582261","rc":[{"batb":[[0,2.36,10]],"ltp":2.48,"tv":7.0,"id":655}]}]}
{"op":"mcm","clk":"11827613220","pt":1723361372242,"mc":[{"id":"1.231582261","rc":[{"batb":[[0,2.38,4],[1,2.36,10],[2,2.34,29.13]],"ltp":2.48,"tv":7.0,"id":655}]}]}
{"op":"mcm","clk":"11827613310","pt":1723361373939,"mc":[{"id":"1.231582261","rc":[{"batb":[[1,2.34,29.13],[2,1.3,1000]],"ltp":2.48,"tv":7.0,"id":655}]}]}
{"op":"mcm","clk":"11827613328","pt":1723361374662,"mc":[{"id":"1.231582261","rc":[{"batb":[[0,2.34,29.13],[1,1.3,1000],[2,1.08,7.85]],"ltp":2.48,"tv":7.0,"id":655}]}]}
{"op":"mcm","clk":"11827613379","pt":1723361376165,"mc":[{"id":"1.231582261","rc":[{"batb":[[0,2.36,10],[1,2.34,29.13],[2,1.3,1000]],"ltp":2.48,"tv":7.0,"id":655}]}]}
{"op":"mcm","clk":"11827613442","pt":1723361377765,"mc":[{"id":"1.231582261","rc":[{"batb":[[0,2.38,4],[1,2.36,10],[2,2.34,29.13]],"ltp":2.48,"tv":7.0,"id":655}]}]}
{"op":"mcm","clk":"11827613534","pt":1723361380071,"mc":[{"id":"1.231582261","rc":[{"batb":[[0,2.34,29.13],[1,1.3,1000],[2,1.08,7.85]],"ltp":2.48,"tv":7.0,"id":655}]}]}
{"op":"mcm","clk":"11827613609","pt":1723361382374,"mc":[{"id":"1.231582261","rc":[{"batb":[[0,2.36,14],[1,2.34,29.13],[2,1.3,1000]],"ltp":2.48,"tv":7.0,"id":655}]}]}
{"op":"mcm","clk":"11827613724","pt":1723361384795,"mc":[{"id":"1.231582261","rc":[{"batb":[[0,2.36,10]],"ltp":2.48,"tv":7.0,"id":655}]}]}
{"op":"mcm","clk":"11827613755","pt":1723361385873,"mc":[{"id":"1.231582261","rc":[{"batb":[[0,2.34,29.13],[1,1.3,1000],[2,1.08,7.85]],"ltp":2.48,"tv":7.0,"id":655}]}]}
{"op":"mcm","clk":"11827613779","pt":1723361387151,"mc":[{"id":"1.231582261","rc":[{"batb":[[0,2.36,4],[1,2.34,29.13],[2,1.3,1000]],"ltp":2.48,"tv":7.0,"id":655}]}]}
{"op":"mcm","clk":"11827613823","pt":1723361388583,"mc":[{"id":"1.231582261","rc":[{"batb":[[0,2.38,10],[1,2.36,4],[2,2.34,29.13]],"ltp":2.48,"tv":7.0,"id":655}]}]}
{"op":"mcm","clk":"11827613843","pt":1723361389656,"mc":[{"id":"1.231582261","rc":[{"batb":[[1,2.34,29.13],[2,1.3,1000]],"ltp":2.48,"tv":7.0,"id":655}]}]}
{"op":"mcm","clk":"11827613929","pt":1723361392278,"mc":[{"id":"1.231582261","rc":[{"batb":[[0,2.36,4]],"ltp":2.48,"tv":7.0,"id":655}]}]}
{"op":"mcm","clk":"11827613995","pt":1723361394681,"mc":[{"id":"1.231582261","rc":[{"batb":[[0,2.38,10]],"ltp":2.48,"tv":7.0,"id":655}]}]}
{"op":"mcm","clk":"11827614049","pt":1723361397188,"mc":[{"id":"1.231582261","rc":[{"batb":[[0,2.4,4],[1,2.38,10],[2,2.34,29.13]],"ltp":2.48,"tv":7.0,"id":655}]}]}
{"op":"mcm","clk":"11827614087","pt":1723361398109,"mc":[{"id":"1.231582261","rc":[{"batb":[[1,2.34,29.13],[2,1.3,1000]],"ltp":2.48,"tv":7.0,"id":655}]}]}
{"op":"mcm","clk":"11827614137","pt":1723361399491,"mc":[{"id":"1.231582261","rc":[{"batb":[[0,2.34,29.13],[1,1.3,1000],[2,1.08,7.85]],"ltp":2.48,"tv":7.0,"id":655}]}]}
{"op":"mcm","clk":"11827614200","pt":1723361400887,"mc":[{"id":"1.231582261","rc":[{"batb":[[0,2.36,10],[1,2.34,29.13],[2,1.3,1000]],"ltp":2.48,"tv":7.0,"id":655}]}]}
{"op":"mcm","clk":"11827614279","pt":1723361402074,"mc":[{"id":"1.231582261","rc":[{"batb":[[0,2.38,4],[1,2.36,10],[2,2.34,29.13]],"ltp":2.48,"tv":7.0,"id":655}]}]}
{"op":"mcm","clk":"11827614440","pt":1723361404396,"mc":[{"id":"1.231582261","rc":[{"batb":[[0,2.36,10],[1,2.34,29.13],[2,1.3,1000]],"ltp":2.48,"tv":7.0,"id":655}]}]}
{"op":"mcm","clk":"11827614454","pt":1723361404661,"mc":[{"id":"1.231582261","rc":[{"batb":[[0,2.34,29.13],[1,1.3,1000],[2,1.08,7.85]],"ltp":2.48,"tv":7.0,"id":655}]}]}
{"op":"mcm","clk":"11827614571","pt":1723361406914,"mc":[{"id":"1.231582261","rc":[{"batb":[[0,2.36,14],[1,2.34,29.13],[2,1.3,1000]],"ltp":2.48,"tv":7.0,"id":655}]}]}
{"op":"mcm","clk":"11827614662","pt":1723361409322,"mc":[{"id":"1.231582261","rc":[{"batb":[[0,2.36,10]],"ltp":2.48,"tv":7.0,"id":655}]}]}
{"op":"mcm","clk":"11827614716","pt":1723361410298,"mc":[{"id":"1.231582261","rc":[{"batb":[[0,2.34,29.13],[1,1.3,1000],[2,1.08,7.85]],"ltp":2.48,"tv":7.0,"id":655}]}]}
{"op":"mcm","clk":"11827614775","pt":1723361411630,"mc":[{"id":"1.231582261","rc":[{"batb":[[0,2.36,4],[1,2.34,29.13],[2,1.3,1000]],"ltp":2.48,"tv":7.0,"id":655}]}]}
{"op":"mcm","clk":"11827614836","pt":1723361412811,"mc":[{"id":"1.231582261","rc":[{"batb":[[0,2.38,10],[1,2.36,4],[2,2.34,29.13]],"ltp":2.48,"tv":7.0,"id":655}]}]}
{"op":"mcm","clk":"11827614905","pt":1723361414094,"mc":[{"id":"1.231582261","rc":[{"batb":[[1,2.34,29.13],[2,1.3,1000]],"ltp":2.48,"tv":7.0,"id":655}]}]}
{"op":"mcm","clk":"11827615036","pt":1723361416508,"mc":[{"id":"1.231582261","rc":[{"batb":[[0,2.36,4]],"ltp":2.48,"tv":7.0,"id":655}]}]}
{"op":"mcm","clk":"11827615147","pt":1723361419326,"mc":[{"id":"1.231582261","rc":[{"batb":[[0,2.36,10]],"ltp":2.48,"tv":7.0,"id":655}]}]}
{"op":"mcm","clk":"11827615274","pt":1723361422773,"mc":[{"id":"1.231582261","rc":[{"batb":[[0,2.36,4]],"ltp":2.48,"tv":7.0,"id":655}]}]}
{"op":"mcm","clk":"11827615365","pt":1723361425200,"mc":[{"id":"1.231582261","rc":[{"batb":[[0,2.38,10]],"ltp":2.48,"tv":7.0,"id":655}]}]}
{"op":"mcm","clk":"11827615489","pt":1723361428319,"mc":[{"id":"1.231582261","rc":[{"batb":[[0,2.34,29.13],[1,1.3,1000],[2,1.08,7.85]],"ltp":2.48,"tv":7.0,"id":655}]}]}
{"op":"mcm","clk":"11827615511","pt":1723361428832,"mc":[{"id":"1.231582261","rc":[{"batb":[[0,2.36,4],[1,2.34,29.13],[2,1.3,1000]],"ltp":2.48,"tv":7.0,"id":655}]}]}
{"op":"mcm","clk":"11827615621","pt":1723361431346,"mc":[{"id":"1.231582261","rc":[{"batb":[[0,2.38,10]],"ltp":2.48,"tv":7.0,"id":655}]}]}
{"op":"mcm","clk":"11827615755","pt":1723361434749,"mc":[{"id":"1.231582261","rc":[{"batb":[[0,2.4,4]],"ltp":2.48,"tv":7.0,"id":655}]}]}
{"op":"mcm","clk":"11827615870","pt":1723361437010,"mc":[{"id":"1.231582261","rc":[{"batb":[[0,2.42,10]],"ltp":2.48,"tv":7.0,"id":655}]}]}
{"op":"mcm","clk":"11827616001","pt":1723361440446,"mc":[{"id":"1.231582261","rc":[{"batb":[[0,2.44,4],[1,2.42,10],[2,2.34,29.13]],"ltp":2.48,"tv":7.0,"id":655}]}]}
{"op":"mcm","clk":"11827616010","pt":1723361440650,"mc":[{"id":"1.231582261","rc":[{"batb":[[1,2.34,29.13],[2,1.3,1000]],"ltp":2.48,"tv":7.0,"id":655}]}]}
{"op":"mcm","clk":"11827616115","pt":1723361443364,"mc":[{"id":"1.231582261","rc":[{"batb":[[0,2.46,10]],"ltp":2.48,"tv":7.0,"id":655}]}]}
{"op":"mcm","clk":"11827616254","pt":1723361446757,"mc":[{"id":"1.231582261","rc":[{"batb":[[0,2.48,4]],"ltp":2.48,"tv":7.0,"id":655}]}]}
{"op":"mcm","clk":"11827616328","pt":1723361449267,"mc":[{"id":"1.231582261","rc":[{"batb":[[0,2.36,10]],"ltp":2.48,"tv":7.0,"id":655}]}]}
{"op":"mcm","clk":"11827616444","pt":1723361451939,"mc":[{"id":"1.231582261","rc":[{"batb":[[0,2.38,4],[1,2.36,10],[2,2.34,29.13]],"ltp":2.48,"tv":7.0,"id":655}]}]}
{"op":"mcm","clk":"11827616486","pt":1723361452967,"mc":[{"id":"1.231582261","rc":[{"batb":[[1,2.34,29.13],[2,1.3,1000]],"ltp":2.48,"tv":7.0,"id":655}]}]}
{"op":"mcm","clk":"11827616545","pt":1723361454348,"mc":[{"id":"1.231582261","rc":[{"batb":[[0,2.34,29.13],[1,1.3,1000],[2,1.08,7.85]],"ltp":2.48,"tv":7.0,"id":655}]}]}
{"op":"mcm","clk":"11827616611","pt":1723361455844,"mc":[{"id":"1.231582261","rc":[{"batb":[[0,2.36,10],[1,2.34,29.13],[2,1.3,1000]],"ltp":2.48,"tv":7.0,"id":655}]}]}
{"op":"mcm","clk":"11827616668","pt":1723361457445,"mc":[{"id":"1.231582261","rc":[{"batb":[[0,2.38,4],[1,2.36,10],[2,2.34,29.13]],"ltp":2.48,"tv":7.0,"id":655}]}]}
{"op":"mcm","clk":"11827616737","pt":1723361459087,"mc":[{"id":"1.231582261","rc":[{"batb":[[1,2.34,29.13],[2,1.3,1000]],"ltp":2.48,"tv":7.0,"id":655}]}]}
{"op":"mcm","clk":"11827616786","pt":1723361459860,"mc":[{"id":"1.231582261","rc":[{"batb":[[0,2.34,29.13],[1,1.3,1000],[2,1.08,7.85]],"ltp":2.48,"tv":7.0,"id":655}]}]}
{"op":"mcm","clk":"11827616894","pt":1723361462274,"mc":[{"id":"1.231582261","rc":[{"batb":[[0,2.36,14],[1,2.34,29.13],[2,1.3,1000]],"ltp":2.48,"tv":7.0,"id":655}]}]}
{"op":"mcm","clk":"11827617053","pt":1723361465460,"mc":[{"id":"1.231582261","rc":[{"batb":[[0,2.34,29.13],[1,1.3,1000],[2,1.08,7.85]],"ltp":2.48,"tv":7.0,"id":655}]}]}
{"op":"mcm","clk":"11827617102","pt":1723361466797,"mc":[{"id":"1.231582261","rc":[{"batb":[[0,2.36,4],[1,2.34,29.13],[2,1.3,1000]],"ltp":2.48,"tv":7.0,"id":655}]}]}
{"op":"mcm","clk":"11827617195","pt":1723361469087,"mc":[{"id":"1.231582261","rc":[{"batb":[[0,2.38,10]],"ltp":2.48,"tv":7.0,"id":655}]}]}
{"op":"mcm","clk":"11827617329","pt":1723361472474,"mc":[{"id":"1.231582261","rc":[{"batb":[[0,2.36,4]],"ltp":2.48,"tv":7.0,"id":655}]}]}
{"op":"mcm","clk":"11827617440","pt":1723361474993,"mc":[{"id":"1.231582261","rc":[{"batb":[[0,2.38,10]],"ltp":2.48,"tv":7.0,"id":655}]}]}
{"op":"mcm","clk":"11827617547","pt":1723361477209,"mc":[{"id":"1.231582261","rc":[{"batb":[[0,2.4,4],[1,2.38,10],[2,2.34,29.13]],"ltp":2.48,"tv":7.0,"id":655}]}]}
{"op":"mcm","clk":"11827617599","pt":1723361478595,"mc":[{"id":"1.231582261","rc":[{"batb":[[1,2.34,29.13],[2,1.3,1000]],"ltp":2.48,"tv":7.0,"id":655}]}]}
{"op":"mcm","clk":"11827617646","pt":1723361479803,"mc":[{"id":"1.231582261","rc":[{"batb":[[0,2.34,29.13],[1,1.3,1000],[2,1.08,7.85]],"ltp":2.48,"tv":7.0,"id":655}]}]}
{"op":"mcm","clk":"11827617740","pt":1723361482185,"mc":[{"id":"1.231582261","rc":[{"batb":[[0,2.36,14],[1,2.34,29.13],[2,1.3,1000]],"ltp":2.48,"tv":7.0,"id":655}]}]}
{"op":"mcm","clk":"11827617859","pt":1723361484495,"mc":[{"id":"1.231582261","rc":[{"batb":[[0,2.36,10]],"ltp":2.48,"tv":7.0,"id":655}]}]}
{"op":"mcm","clk":"11827617893","pt":1723361485414,"mc":[{"id":"1.231582261","rc":[{"batb":[[0,2.34,29.13],[1,1.3,1000],[2,1.08,7.85]],"ltp":2.48,"tv":7.0,"id":655}]}]}
{"op":"mcm","clk":"11827617952","pt":1723361486796,"mc":[{"id":"1.231582261","rc":[{"batb":[[0,2.36,4],[1,2.34,29.13],[2,1.3,1000]],"ltp":2.48,"tv":7.0,"id":655}]}]}
{"op":"mcm","clk":"11827618024","pt":1723361488490,"mc":[{"id":"1.231582261","rc":[{"batb":[[0,2.38,10],[1,2.36,4],[2,2.34,29.13]],"ltp":2.48,"tv":7.0,"id":655}]}]}
{"op":"mcm","clk":"11827618063","pt":1723361489313,"mc":[{"id":"1.231582261","rc":[{"batb":[[1,2.34,29.13],[2,1.3,1000]],"ltp":2.48,"tv":7.0,"id":655}]}]}
{"op":"mcm","clk":"11827618198","pt":1723361492312,"mc":[{"id":"1.231582261","rc":[{"batb":[[0,2.36,4]],"ltp":2.48,"tv":7.0,"id":655}]}]}
{"op":"mcm","clk":"11827618311","pt":1723361495038,"mc":[{"id":"1.231582261","rc":[{"batb":[[0,2.36,10]],"ltp":2.48,"tv":7.0,"id":655}]}]}
{"op":"mcm","clk":"11827618448","pt":1723361498335,"mc":[{"id":"1.231582261","rc":[{"batb":[[0,2.34,29.13],[1,1.3,1000],[2,1.08,7.85]],"ltp":2.48,"tv":7.0,"id":655}]}]}
{"op":"mcm","clk":"11827618466","pt":1723361498645,"mc":[{"id":"1.231582261","rc":[{"batb":[[0,2.36,4],[1,2.34,29.13],[2,1.3,1000]],"ltp":2.48,"tv":7.0,"id":655}]}]}
{"op":"mcm","clk":"11827618565","pt":1723361500812,"mc":[{"id":"1.231582261","rc":[{"batb":[[0,2.38,10]],"ltp":2.48,"tv":7.0,"id":655}]}]}
{"op":"mcm","clk":"11827618730","pt":1723361504001,"mc":[{"id":"1.231582261","rc":[{"batb":[[0,2.36,4]],"ltp":2.48,"tv":7.0,"id":655}]}]}
{"op":"mcm","clk":"11827618847","pt":1723361506411,"mc":[{"id":"1.231582261","rc":[{"batb":[[0,2.38,10]],"ltp":2.48,"tv":7.0,"id":655}]}]}
{"op":"mcm","clk":"11827618960","pt":1723361509131,"mc":[{"id":"1.231582261","rc":[{"batb":[[0,2.4,4],[1,2.38,10],[2,2.34,29.13]],"ltp":2.48,"tv":7.0,"id":655}]}]}
{"op":"mcm","clk":"11827618980","pt":1723361509746,"mc":[{"id":"1.231582261","rc":[{"batb":[[1,2.34,29.13],[2,1.3,1000]],"ltp":2.48,"tv":7.0,"id":655}]}]}
{"op":"mcm","clk":"11827619046","pt":1723361511447,"mc":[{"id":"1.231582261","rc":[{"batb":[[0,2.34,29.13],[1,1.3,1000],[2,1.08,7.85]],"ltp":2.48,"tv":7.0,"id":655}]}]}
{"op":"mcm","clk":"11827619116","pt":1723361512839,"mc":[{"id":"1.231582261","rc":[{"batb":[[0,2.36,10],[1,2.34,29.13],[2,1.3,1000]],"ltp":2.48,"tv":7.0,"id":655}]}]}
{"op":"mcm","clk":"11827619218","pt":1723361514935,"mc":[{"id":"1.231582261","rc":[{"batb":[[0,2.38,4],[1,2.36,10],[2,2.34,29.13]],"ltp":2.48,"tv":7.0,"id":655}]}]}
{"op":"mcm","clk":"11827619276","pt":1723361516218,"mc":[{"id":"1.231582261","rc":[{"batb":[[1,2.34,29.13],[2,1.3,1000]],"ltp":2.48,"tv":7.0,"id":655}]}]}
{"op":"mcm","clk":"11827619316","pt":1723361517140,"mc":[{"id":"1.231582261","rc":[{"batb":[[0,2.34,29.13],[1,1.3,1000],[2,1.08,7.85]],"ltp":2.48,"tv":7.0,"id":655}]}]}
{"op":"mcm","clk":"11827619369","pt":1723361518729,"mc":[{"id":"1.231582261","rc":[{"batb":[[0,2.36,10],[1,2.34,29.13],[2,1.3,1000]],"ltp":2.48,"tv":7.0,"id":655}]}]}
{"op":"mcm","clk":"11827619443","pt":1723361520831,"mc":[{"id":"1.231582261","rc":[{"batb":[[0,2.38,4],[1,2.36,10],[2,2.34,29.13]],"ltp":2.48,"tv":7.0,"id":655}]}]}
{"op":"mcm","clk":"11827619541","pt":1723361522231,"mc":[{"id":"1.231582261","rc":[{"batb":[[1,2.34,29.13],[2,1.3,1000]],"ltp":2.48,"tv":7.0,"id":655}]}]}
{"op":"mcm","clk":"11827619590","pt":1723361523156,"mc":[{"id":"1.231582261","rc":[{"batb":[[0,2.34,29.13],[1,1.3,1000],[2,1.08,7.85]],"ltp":2.48,"tv":7.0,"id":655}]}]}
{"op":"mcm","clk":"11827619739","pt":1723361526276,"mc":[{"id":"1.231582261","rc":[{"batb":[[0,2.36,14],[1,2.34,29.13],[2,1.3,1000]],"ltp":2.48,"tv":7.0,"id":655}]}]}
{"op":"mcm","clk":"11827619844","pt":1723361528537,"mc":[{"id":"1.231582261","rc":[{"batb":[[0,2.36,10]],"ltp":2.48,"tv":7.0,"id":655}]}]}
{"op":"mcm","clk":"11827619882","pt":1723361529568,"mc":[{"id":"1.231582261","rc":[{"batb":[[0,2.34,29.13],[1,1.3,1000],[2,1.08,7.85]],"ltp":2.48,"tv":7.0,"id":655}]}]}
{"op":"mcm","clk":"11827619938","pt":1723361530749,"mc":[{"id":"1.231582261","rc":[{"batb":[[0,2.36,4],[1,2.34,29.13],[2,1.3,1000]],"ltp":2.48,"tv":7.0,"id":655}]}]}
{"op":"mcm","clk":"11827619995","pt":1723361531885,"mc":[{"id":"1.231582261","rc":[{"batb":[[0,2.38,10],[1,2.36,4],[2,2.34,29.13]],"ltp":2.48,"tv":7.0,"id":655}]}]}
{"op":"mcm","clk":"11827620057","pt":1723361532965,"mc":[{"id":"1.231582261","rc":[{"batb":[[1,2.34,29.13],[2,1.3,1000]],"ltp":2.48,"tv":7.0,"id":655}]}]}
{"op":"mcm","clk":"11827620185","pt":1723361535486,"mc":[{"id":"1.231582261","rc":[{"batb":[[0,2.36,4]],"ltp":2.48,"tv":7.0,"id":655}]}]}
{"op":"mcm","clk":"11827620302","pt":1723361537856,"mc":[{"id":"1.231582261","rc":[{"batb":[[0,2.38,10]],"ltp":2.48,"tv":7.0,"id":655}]}]}
{"op":"mcm","clk":"11827620450","pt":1723361541092,"mc":[{"id":"1.231582261","rc":[{"batb":[[0,2.4,4]],"ltp":2.48,"tv":7.0,"id":655}]}]}
{"op":"mcm","clk":"11827620563","pt":1723361543456,"mc":[{"id":"1.231582261","rc":[{"batb":[[0,2.34,29.13],[1,1.3,1000],[2,1.08,7.85]],"ltp":2.48,"tv":7.0,"id":655}]}]}
{"op":"mcm","clk":"11827620571","pt":1723361543660,"mc":[{"id":"1.231582261","rc":[{"batb":[[0,2.36,10],[1,2.34,29.13],[2,1.3,1000]],"ltp":2.48,"tv":7.0,"id":655}]}]}
{"op":"mcm","clk":"11827620657","pt":1723361545886,"mc":[{"id":"1.231582261","rc":[{"batb":[[0,2.38,4],[1,2.36,10],[2,2.34,29.13]],"ltp":2.48,"tv":7.0,"id":655}]}]}
{"op":"mcm","clk":"11827620693","pt":1723361547002,"mc":[{"id":"1.231582261","rc":[{"batb":[[1,2.34,29.13],[2,1.3,1000]],"ltp":2.48,"tv":7.0,"id":655}]}]}
{"op":"mcm","clk":"11827620751","pt":1723361548084,"mc":[{"id":"1.231582261","rc":[{"batb":[[0,2.34,29.13],[1,1.3,1000],[2,1.08,7.85]],"ltp":2.48,"tv":7.0,"id":655}]}]}
{"op":"mcm","clk":"11827620838","pt":1723361550390,"mc":[{"id":"1.231582261","rc":[{"batb":[[0,2.38,4],[1,2.36,10],[2,2.34,29.13]],"ltp":2.48,"tv":7.0,"id":655}]}]}
{"op":"mcm","clk":"11827620975","pt":1723361553362,"mc":[{"id":"1.231582261","rc":[{"batb":[[0,2.34,29.13],[1,1.3,1000],[2,1.08,7.85]],"ltp":2.48,"tv":7.0,"id":655}]}]}
{"op":"mcm","clk":"11827621091","pt":1723361555875,"mc":[{"id":"1.231582261","rc":[{"batb":[[0,2.36,14],[1,2.34,29.13],[2,1.3,1000]],"ltp":2.48,"tv":7.0,"id":655}]}]}
{"op":"mcm","clk":"11827621219","pt":1723361558193,"mc":[{"id":"1.231582261","rc":[{"batb":[[0,2.36,10]],"ltp":2.48,"tv":7.0,"id":655}]}]}
{"op":"mcm","clk":"11827621276","pt":1723361559373,"mc":[{"id":"1.231582261","rc":[{"batb":[[0,2.34,29.13],[1,1.3,1000],[2,1.08,7.85]],"ltp":2.48,"tv":7.0,"id":655}]}]}
{"op":"mcm","clk":"11827625989","pt":1723361671713,"mc":[{"id":"1.231582261","rc":[{"batl":[[1,1.7,96.43]],"ltp":1.67,"tv":207.92,"id":2120}]}]}
{"op":"mcm","clk":"11827660519","pt":1723362216455,"mc":[{"id":"1.231582261","rc":[{"batb":[[2,1.51,4.56]],"ltp":1.67,"tv":207.92,"id":2120}]}]}
{"op":"mcm","clk":"11827660583","pt":1723362218343,"mc":[{"id":"1.231582261","rc":[{"batb":[[2,1.37,8.76]],"ltp":1.67,"tv":207.92,"id":2120}]}]}
{"op":"mcm","clk":"11827699788","pt":1723363176295,"mc":[{"id":"1.231582261","rc":[{"batl":[[0,1.7,96.43],[1,1.71,200],[2,1.72,300]],"ltp":1.67,"tv":207.92,"id":2120}]}]}
{"op":"mcm","clk":"11827701129","pt":1723363202031,"mc":[{"id":"1.231582261","rc":[{"batb":[[0,2.4,12.86],[1,2.34,29.13],[2,1.3,1000]],"ltp":2.48,"tv":7.0,"id":655},{"batb":[[1,1.63,49.58]],"ltp":1.67,"tv":207.92,"id":2120}]}]}
{"op":"mcm","clk":"11827701244","pt":1723363203331,"mc":[{"id":"1.231582261","rc":[{"batb":[[0,2.42,14],[1,2.4,12.86],[2,2.34,29.13]],"ltp":2.48,"tv":7.0,"id":655}]}]}
{"op":"mcm","clk":"11827701526","pt":1723363206564,"mc":[{"id":"1.231582261","rc":[{"batb":[[0,2.42,10]],"ltp":2.48,"tv":7.0,"id":655}]}]}
{"op":"mcm","clk":"11827701578","pt":1723363207549,"mc":[{"id":"1.231582261","rc":[{"batb":[[0,2.4,12.86],[1,2.34,29.13],[2,1.3,1000]],"ltp":2.48,"tv":7.0,"id":655}]}]}
{"op":"mcm","clk":"11827701726","pt":1723363210169,"mc":[{"id":"1.231582261","rc":[{"batb":[[0,2.42,14],[1,2.4,12.86],[2,2.34,29.13]],"ltp":2.48,"tv":7.0,"id":655}]}]}
{"op":"mcm","clk":"11827701835","pt":1723363212541,"mc":[{"id":"1.231582261","rc":[{"batb":[[0,2.42,10]],"ltp":2.48,"tv":7.0,"id":655}]}]}
{"op":"mcm","clk":"11827701887","pt":1723363213564,"mc":[{"id":"1.231582261","rc":[{"batb":[[0,2.4,12.86],[1,2.34,29.13],[2,1.3,1000]],"ltp":2.48,"tv":7.0,"id":655}]}]}
{"op":"mcm","clk":"11827701982","pt":1723363215176,"mc":[{"id":"1.231582261","rc":[{"batb":[[0,2.42,4],[1,2.4,12.86],[2,2.34,29.13]],"ltp":2.48,"tv":7.0,"id":655}]}]}
{"op":"mcm","clk":"11827702083","pt":1723363217059,"mc":[{"id":"1.231582261","rc":[{"batb":[[0,2.44,10],[1,2.42,16.68],[2,2.4,12.86]],"ltp":2.48,"tv":7.0,"id":655}]}]}
{"op":"mcm","clk":"11827702174","pt":1723363218565,"mc":[{"id":"1.231582261","rc":[{"batb":[[1,2.42,12.68]],"ltp":2.48,"tv":7.0,"id":655}]}]}
{"op":"mcm","clk":"11827702330","pt":1723363221069,"mc":[{"id":"1.231582261","rc":[{"batb":[[0,2.42,12.68],[1,2.4,12.86],[2,2.34,29.13]],"ltp":2.48,"tv":7.0,"id":655}]}]}
{"op":"mcm","clk":"11827702394","pt":1723363222207,"mc":[{"id":"1.231582261","rc":[{"batb":[[0,2.44,4],[1,2.42,12.68],[2,2.4,12.86]],"ltp":2.48,"tv":7.0,"id":655}]}]}
{"op":"mcm","clk":"11827702469","pt":1723363223292,"mc":[{"id":"1.231582261","rc":[{"batb":[[0,2.46,10],[1,2.44,4],[2,2.42,12.68]],"ltp":2.48,"tv":7.0,"id":655}]}]}
{"op":"mcm","clk":"11827702580","pt":1723363225382,"mc":[{"id":"1.231582261","rc":[{"batb":[[1,2.42,12.68],[2,2.4,12.86]],"ltp":2.48,"tv":7.0,"id":655}]}]}
{"op":"mcm","clk":"11827702696","pt":1723363227025,"mc":[{"id":"1.231582261","rc":[{"batb":[[0,2.42,12.68],[1,2.4,12.86],[2,2.34,29.13]],"ltp":2.48,"tv":7.0,"id":655}]}]}
{"op":"mcm","clk":"11827702768","pt":1723363228108,"mc":[{"id":"1.231582261","rc":[{"batb":[[0,2.44,4],[1,2.42,12.68],[2,2.4,12.86]],"ltp":2.48,"tv":7.0,"id":655}]}]}
{"op":"mcm","clk":"11827702877","pt":1723363230109,"mc":[{"id":"1.231582261","rc":[{"batb":[[0,2.46,10],[1,2.44,4],[2,2.42,12.68]],"ltp":2.48,"tv":7.0,"id":655}]}]}
{"op":"mcm","clk":"11827702918","pt":1723363230730,"mc":[{"id":"1.231582261","rc":[{"batb":[[1,2.42,12.68],[2,2.4,12.86]],"ltp":2.48,"tv":7.0,"id":655}]}]}
{"op":"mcm","clk":"11827703090","pt":1723363233117,"mc":[{"id":"1.231582261","rc":[{"batb":[[0,2.48,4],[1,2.46,10],[2,2.42,12.68]],"ltp":2.48,"tv":7.0,"id":655}]}]}
{"op":"mcm","clk":"11827703132","pt":1723363233635,"mc":[{"id":"1.231582261","rc":[{"batb":[[1,2.42,12.68],[2,2.4,12.86]],"ltp":2.48,"tv":7.0,"id":655}]}]}
{"op":"mcm","clk":"11827703300","pt":1723363236319,"mc":[{"id":"1.231582261","rc":[{"batb":[[0,2.44,10]],"ltp":2.48,"tv":7.0,"id":655}]}]}
{"op":"mcm","clk":"11827703449","pt":1723363238804,"mc":[{"id":"1.231582261","rc":[{"batb":[[0,2.46,4],[1,2.44,10],[2,2.42,12.68]],"ltp":2.48,"tv":7.0,"id":655}]}]}
{"op":"mcm","clk":"11827703508","pt":1723363239628,"mc":[{"id":"1.231582261","rc":[{"batb":[[1,2.42,12.68],[2,2.4,12.86]],"ltp":2.48,"tv":7.0,"id":655}]}]}
{"op":"mcm","clk":"11827703593","pt":1723363241121,"mc":[{"id":"1.231582261","rc":[{"batb":[[0,2.42,12.68],[1,2.4,12.86],[2,2.34,29.13]],"ltp":2.48,"tv":7.0,"id":655}]}]}
{"op":"mcm","clk":"11827704240","pt":1723363252358,"mc":[{"id":"1.231582261","rc":[{"batb":[[0,2.44,14],[1,2.42,12.68],[2,2.4,12.86]],"ltp":2.48,"tv":7.0,"id":655}]}]}
{"op":"mcm","clk":"11827704381","pt":1723363254834,"mc":[{"id":"1.231582261","rc":[{"batb":[[0,2.44,10]],"ltp":2.48,"tv":7.0,"id":655}]}]}
{"op":"mcm","clk":"11827704441","pt":1723363255663,"mc":[{"id":"1.231582261","rc":[{"batb":[[0,2.42,12.68],[1,2.4,12.86],[2,2.34,29.13]],"ltp":2.48,"tv":7.0,"id":655}]}]}
{"op":"mcm","clk":"11827704521","pt":1723363257156,"mc":[{"id":"1.231582261","rc":[{"batb":[[0,2.44,4],[1,2.42,12.68],[2,2.4,12.86]],"ltp":2.48,"tv":7.0,"id":655}]}]}
{"op":"mcm","clk":"11827704672","pt":1723363260067,"mc":[{"id":"1.231582261","rc":[{"batb":[[0,2.44,10]],"ltp":2.48,"tv":7.0,"id":655}]}]}
{"op":"mcm","clk":"11827704888","pt":1723363263350,"mc":[{"id":"1.231582261","rc":[{"batb":[[0,2.42,12.68],[1,2.4,12.86],[2,2.34,29.13]],"ltp":2.48,"tv":7.0,"id":655}]}]}
{"op":"mcm","clk":"11827704954","pt":1723363264437,"mc":[{"id":"1.231582261","rc":[{"batb":[[0,2.44,4],[1,2.42,12.68],[2,2.4,12.86]],"ltp":2.48,"tv":7.0,"id":655}]}]}
{"op":"mcm","clk":"11827705116","pt":1723363267175,"mc":[{"id":"1.231582261","rc":[{"batb":[[0,2.44,10]],"ltp":2.48,"tv":7.0,"id":655}]}]}
{"op":"mcm","clk":"11827705295","pt":1723363270479,"mc":[{"id":"1.231582261","rc":[{"batb":[[0,2.46,4]],"ltp":2.48,"tv":7.0,"id":655}]}]}
{"op":"mcm","clk":"11827705425","pt":1723363272338,"mc":[{"id":"1.231582261","rc":[{"batb":[[0,2.42,12.68],[1,2.4,12.86],[2,2.34,29.13]],"ltp":2.48,"tv":7.0,"id":655}]}]}
{"op":"mcm","clk":"11827705452","pt":1723363272751,"mc":[{"id":"1.231582261","rc":[{"batb":[[0,2.48,10],[1,2.42,12.68],[2,2.4,12.86]],"ltp":2.48,"tv":7.0,"id":655}]}]}
{"op":"mcm","clk":"11827705591","pt":1723363275176,"mc":[{"id":"1.231582261","rc":[{"batb":[[0,2.5,4],[1,2.48,10],[2,2.42,12.68]],"ltp":2.48,"tv":7.0,"id":655}]}]}
{"op":"mcm","clk":"11827705653","pt":1723363276578,"mc":[{"id":"1.231582261","rc":[{"batb":[[1,2.42,12.68],[2,2.4,12.86]],"ltp":2.48,"tv":7.0,"id":655}]}]}
{"op":"mcm","clk":"11827705740","pt":1723363277764,"mc":[{"id":"1.231582261","rc":[{"batb":[[0,2.42,12.68],[1,2.4,12.86],[2,2.34,29.13]],"ltp":2.48,"tv":7.0,"id":655}]}]}
{"op":"mcm","clk":"11827705839","pt":1723363279575,"mc":[{"id":"1.231582261","rc":[{"batb":[[0,2.44,10],[1,2.42,12.68],[2,2.4,12.86]],"ltp":2.48,"tv":7.0,"id":655}]}]}
{"op":"mcm","clk":"11827706061","pt":1723363283282,"mc":[{"id":"1.231582261","rc":[{"batb":[[0,2.44,4]],"ltp":2.48,"tv":7.0,"id":655}]}]}
{"op":"mcm","clk":"11827706200","pt":1723363285803,"mc":[{"id":"1.231582261","rc":[{"batb":[[0,2.44,10]],"ltp":2.48,"tv":7.0,"id":655}]}]}
{"op":"mcm","clk":"11827706388","pt":1723363289307,"mc":[{"id":"1.231582261","rc":[{"batb":[[0,2.44,4]],"ltp":2.48,"tv":7.0,"id":655}]}]}
{"op":"mcm","clk":"11827706557","pt":1723363292197,"mc":[{"id":"1.231582261","rc":[{"batb":[[0,2.44,10]],"ltp":2.48,"tv":7.0,"id":655}]}]}
{"op":"mcm","clk":"11827706722","pt":1723363295405,"mc":[{"id":"1.231582261","rc":[{"batb":[[0,2.46,4]],"ltp":2.48,"tv":7.0,"id":655}]}]}
{"op":"mcm","clk":"11827706880","pt":1723363298103,"mc":[{"id":"1.231582261","rc":[{"batb":[[0,2.44,10]],"ltp":2.48,"tv":7.0,"id":655}]}]}
{"op":"mcm","clk":"11827707049","pt":1723363301314,"mc":[{"id":"1.231582261","rc":[{"batb":[[0,2.42,12.68],[1,2.4,12.86],[2,2.34,29.13]],"ltp":2.48,"tv":7.0,"id":655}]}]}
{"op":"mcm","clk":"11827707079","pt":1723363301786,"mc":[{"id":"1.231582261","rc":[{"batb":[[0,2.44,4],[1,2.42,12.68],[2,2.4,12.86]],"ltp":2.48,"tv":7.0,"id":655}]}]}
{"op":"mcm","clk":"11827707235","pt":1723363304423,"mc":[{"id":"1.231582261","rc":[{"batb":[[0,2.44,10]],"ltp":2.48,"tv":7.0,"id":655}]}]}
{"op":"mcm","clk":"11827707380","pt":1723363306698,"mc":[{"id":"1.231582261","rc":[{"batb":[[0,2.46,4],[1,2.44,10],[2,2.42,12.68]],"ltp":2.48,"tv":7.0,"id":655}]}]}
{"op":"mcm","clk":"11827707447","pt":1723363307990,"mc":[{"id":"1.231582261","rc":[{"batb":[[1,2.42,12.68],[2,2.4,12.86]],"ltp":2.48,"tv":7.0,"id":655}]}]}
{"op":"mcm","clk":"11827707520","pt":1723363309124,"mc":[{"id":"1.231582261","rc":[{"batb":[[0,2.42,12.68],[1,2.4,12.86],[2,2.34,29.13]],"ltp":2.48,"tv":7.0,"id":655}]}]}
{"op":"mcm","clk":"11827707588","pt":1723363310313,"mc":[{"id":"1.231582261","rc":[{"batb":[[0,2.44,10],[1,2.42,12.68],[2,2.4,12.86]],"ltp":2.48,"tv":7.0,"id":655}]}]}
{"op":"mcm","clk":"11827707657","pt":1723363311506,"mc":[{"id":"1.231582261","rc":[{"batb":[[0,2.46,4],[1,2.44,10],[2,2.42,12.68]],"ltp":2.48,"tv":7.0,"id":655}]}]}
{"op":"mcm","clk":"11827707775","pt":1723363313491,"mc":[{"id":"1.231582261","rc":[{"batb":[[1,2.42,12.68],[2,2.4,12.86]],"ltp":2.48,"tv":7.0,"id":655}]}]}
{"op":"mcm","clk":"11827707798","pt":1723363313909,"mc":[{"id":"1.231582261","rc":[{"batb":[[0,2.42,12.68],[1,2.4,12.86],[2,2.34,29.13]],"ltp":2.48,"tv":7.0,"id":655}]}]}
{"op":"mcm","clk":"11827708118","pt":1723363318802,"mc":[{"id":"1.231582261","rc":[{"batb":[[0,2.44,14],[1,2.42,12.68],[2,2.4,12.86]],"ltp":2.48,"tv":7.0,"id":655}]}]}
{"op":"mcm","clk":"11827708289","pt":1723363321402,"mc":[{"id":"1.231582261","rc":[{"batb":[[0,2.44,10]],"ltp":2.48,"tv":7.0,"id":655}]}]}
{"op":"mcm","clk":"11827708351","pt":1723363322404,"mc":[{"id":"1.231582261","rc":[{"batb":[[0,2.42,12.68],[1,2.4,12.86],[2,2.34,29.13]],"ltp":2.48,"tv":7.0,"id":655}]}]}
{"op":"mcm","clk":"11827708509","pt":1723363325007,"mc":[{"id":"1.231582261","rc":[{"batb":[[0,2.44,14],[1,2.42,12.68],[2,2.4,12.86]],"ltp":2.48,"tv":7.0,"id":655}]}]}
{"op":"mcm","clk":"11827708657","pt":1723363327235,"mc":[{"id":"1.231582261","rc":[{"batb":[[0,2.44,10]],"ltp":2.48,"tv":7.0,"id":655}]}]}
{"op":"mcm","clk":"11827708721","pt":1723363328217,"mc":[{"id":"1.231582261","rc":[{"batb":[[0,2.42,12.68],[1,2.4,12.86],[2,2.34,29.13]],"ltp":2.48,"tv":7.0,"id":655}]}]}
{"op":"mcm","clk":"11827708786","pt":1723363329505,"mc":[{"id":"1.231582261","rc":[{"batb":[[0,2.44,4],[1,2.42,12.68],[2,2.4,12.86]],"ltp":2.48,"tv":7.0,"id":655}]}]}
{"op":"mcm","clk":"11827708968","pt":1723363332137,"mc":[{"id":"1.231582261","rc":[{"batb":[[0,2.44,10]],"ltp":2.48,"tv":7.0,"id":655}]}]}
{"op":"mcm","clk":"11827709112","pt":1723363334458,"mc":[{"id":"1.231582261","rc":[{"batb":[[0,2.46,4],[1,2.44,10],[2,2.42,12.68]],"ltp":2.48,"tv":7.0,"id":655}]}]}
{"op":"mcm","clk":"11827709178","pt":1723363335551,"mc":[{"id":"1.231582261","rc":[{"batb":[[1,2.42,12.68],[2,2.4,12.86]],"ltp":2.48,"tv":7.0,"id":655}]}]}
{"op":"mcm","clk":"11827709268","pt":1723363336944,"mc":[{"id":"1.231582261","rc":[{"batb":[[0,2.42,12.68],[1,2.4,12.86],[2,2.34,29.13]],"ltp":2.48,"tv":7.0,"id":655}]}]}
{"op":"mcm","clk":"11827709379","pt":1723363338572,"mc":[{"id":"1.231582261","rc":[{"batb":[[0,2.44,10],[1,2.42,12.68],[2,2.4,12.86]],"ltp":2.48,"tv":7.0,"id":655}]}]}
{"op":"mcm","clk":"11827709586","pt":1723363342142,"mc":[{"id":"1.231582261","rc":[{"batb":[[0,2.44,4]],"ltp":2.48,"tv":7.0,"id":655}]}]}
{"op":"mcm","clk":"11827709745","pt":1723363344480,"mc":[{"id":"1.231582261","rc":[{"batb":[[0,2.46,10]],"ltp":2.48,"tv":7.0,"id":655}]}]}
{"op":"mcm","clk":"11827710008","pt":1723363348467,"mc":[{"id":"1.231582261","rc":[{"batb":[[0,2.42,12.68],[1,2.4,12.86],[2,2.34,29.13]],"ltp":2.48,"tv":7.0,"id":655}]}]}
{"op":"mcm","clk":"11827710019","pt":1723363348675,"mc":[{"id":"1.231582261","rc":[{"batb":[[0,2.44,4],[1,2.42,12.68],[2,2.4,12.86]],"ltp":2.48,"tv":7.0,"id":655}]}]}
{"op":"mcm","clk":"11827710181","pt":1723363351060,"mc":[{"id":"1.231582261","rc":[{"batb":[[0,2.46,10]],"ltp":2.48,"tv":7.0,"id":655}]}]}
{"op":"mcm","clk":"11827710409","pt":1723363354359,"mc":[{"id":"1.231582261","rc":[{"batb":[[0,2.42,12.68],[1,2.4,12.86],[2,2.34,29.13]],"ltp":2.48,"tv":7.0,"id":655}]}]}
{"op":"mcm","clk":"11827710419","pt":1723363354568,"mc":[{"id":"1.231582261","rc":[{"batb":[[0,2.44,4],[1,2.42,12.68],[2,2.4,12.86]],"ltp":2.48,"tv":7.0,"id":655}]}]}
{"op":"mcm","clk":"11827710549","pt":1723363357059,"mc":[{"id":"1.231582261","rc":[{"batb":[[0,2.44,10]],"ltp":2.48,"tv":7.0,"id":655}]}]}
{"op":"mcm","clk":"11827710806","pt":1723363361457,"mc":[{"id":"1.231582261","rc":[{"batb":[[0,2.44,4]],"ltp":2.48,"tv":7.0,"id":655}]}]}
{"op":"mcm","clk":"11827710971","pt":1723363364293,"mc":[{"id":"1.231582261","rc":[{"batb":[[0,2.44,10]],"ltp":2.48,"tv":7.0,"id":655}]}]}
{"op":"mcm","clk":"11827711131","pt":1723363367458,"mc":[{"id":"1.231582261","rc":[{"batb":[[0,2.42,12.68],[1,2.4,12.86],[2,2.34,29.13]],"ltp":2.48,"tv":7.0,"id":655}]}]}
{"op":"mcm","clk":"11827711140","pt":1723363367690,"mc":[{"id":"1.231582261","rc":[{"batb":[[0,2.44,4],[1,2.42,12.68],[2,2.4,12.86]],"ltp":2.48,"tv":7.0,"id":655}]}]}
{"op":"mcm","clk":"11827711271","pt":1723363369986,"mc":[{"id":"1.231582261","rc":[{"batb":[[0,2.46,10]],"ltp":2.48,"tv":7.0,"id":655}]}]}
{"op":"mcm","clk":"11827711451","pt":1723363373286,"mc":[{"id":"1.231582261","rc":[{"batb":[[0,2.44,4]],"ltp":2.48,"tv":7.0,"id":655}]}]}
{"op":"mcm","clk":"11827711595","pt":1723363375992,"mc":[{"id":"1.231582261","rc":[{"batb":[[0,2.44,10]],"ltp":2.48,"tv":7.0,"id":655}]}]}
{"op":"mcm","clk":"11827711715","pt":1723363378406,"mc":[{"id":"1.231582261","rc":[{"batb":[[0,2.46,4],[1,2.44,10],[2,2.42,12.68]],"ltp":2.48,"tv":7.0,"id":655}]}]}
{"op":"mcm","clk":"11827711754","pt":1723363379277,"mc":[{"id":"1.231582261","rc":[{"batb":[[1,2.42,12.68],[2,2.4,12.86]],"ltp":2.48,"tv":7.0,"id":655}]}]}
{"op":"mcm","clk":"11827711812","pt":1723363380730,"mc":[{"id":"1.231582261","rc":[{"batb":[[0,2.42,12.68],[1,2.4,12.86],[2,2.34,29.13]],"ltp":2.48,"tv":7.0,"id":655}]}]}
{"op":"mcm","clk":"11827711892","pt":1723363381965,"mc":[{"id":"1.231582261","rc":[{"batb":[[0,2.44,10],[1,2.42,12.68],[2,2.4,12.86]],"ltp":2.48,"tv":7.0,"id":655}]}]}
{"op":"mcm","clk":"11827711973","pt":1723363383426,"mc":[{"id":"1.231582261","rc":[{"batb":[[0,2.46,4],[1,2.44,10],[2,2.42,12.68]],"ltp":2.48,"tv":7.0,"id":655}]}]}
{"op":"mcm","clk":"11827712089","pt":1723363385738,"mc":[{"id":"1.231582261","rc":[{"batb":[[0,2.42,12.68],[1,2.4,12.86],[2,2.34,29.13]],"ltp":2.48,"tv":7.0,"id":655}]}]}
{"op":"mcm","clk":"11827712231","pt":1723363388742,"mc":[{"id":"1.231582261","rc":[{"batb":[[0,2.44,14],[1,2.42,12.68],[2,2.4,12.86]],"ltp":2.48,"tv":7.0,"id":655}]}]}
{"op":"mcm","clk":"11827712385","pt":1723363391888,"mc":[{"id":"1.231582261","rc":[{"batb":[[0,2.44,10]],"ltp":2.48,"tv":7.0,"id":655}]}]}
{"op":"mcm","clk":"11827712440","pt":1723363392771,"mc":[{"id":"1.231582261","rc":[{"batb":[[0,2.42,12.68],[1,2.4,12.86],[2,2.34,29.13]],"ltp":2.48,"tv":7.0,"id":655}]}]}
{"op":"mcm","clk":"11827712680","pt":1723363397859,"mc":[{"id":"1.231582261","rc":[{"batb":[[0,2.44,14],[1,2.42,12.68],[2,2.4,12.86]],"ltp":2.48,"tv":7.0,"id":655}]}]}
{"op":"mcm","clk":"11827712810","pt":1723363400273,"mc":[{"id":"1.231582261","rc":[{"batb":[[0,2.44,10]],"ltp":2.48,"tv":7.0,"id":655}]}]}
{"op":"mcm","clk":"11827712854","pt":1723363401297,"mc":[{"id":"1.231582261","rc":[{"batb":[[0,2.42,12.68],[1,2.4,12.86],[2,2.34,29.13]],"ltp":2.48,"tv":7.0,"id":655}]}]}
{"op":"mcm","clk":"11827712990","pt":1723363404177,"mc":[{"id":"1.231582261","rc":[{"batb":[[0,2.44,14],[1,2.42,12.68],[2,2.4,12.86]],"ltp":2.48,"tv":7.0,"id":655}]}]}
{"op":"mcm","clk":"11827713125","pt":1723363406795,"mc":[{"id":"1.231582261","rc":[{"batb":[[0,2.44,10]],"ltp":2.48,"tv":7.0,"id":655}]}]}
{"op":"mcm","clk":"11827713182","pt":1723363407775,"mc":[{"id":"1.231582261","rc":[{"batb":[[0,2.42,12.68],[1,2.4,12.86],[2,2.34,29.13]],"ltp":2.48,"tv":7.0,"id":655}]}]}
{"op":"mcm","clk":"11827713248","pt":1723363409058,"mc":[{"id":"1.231582261","rc":[{"batb":[[0,2.44,4],[1,2.42,12.68],[2,2.4,12.86]],"ltp":2.48,"tv":7.0,"id":655}]}]}
{"op":"mcm","clk":"11827713289","pt":1723363410184,"mc":[{"id":"1.231582261","rc":[{"batb":[[0,2.46,10],[1,2.44,4],[2,2.42,12.68]],"ltp":2.48,"tv":7.0,"id":655}]}]}
{"op":"mcm","clk":"11827713343","pt":1723363411485,"mc":[{"id":"1.231582261","rc":[{"batb":[[1,2.42,12.68],[2,2.4,12.86]],"ltp":2.48,"tv":7.0,"id":655}]}]}
{"op":"mcm","clk":"11827713457","pt":1723363413864,"mc":[{"id":"1.231582261","rc":[{"batb":[[0,2.44,4]],"ltp":2.48,"tv":7.0,"id":655}]}]}
{"op":"mcm","clk":"11827713558","pt":1723363416173,"mc":[{"id":"1.231582261","rc":[{"batb":[[0,2.42,12.68],[1,2.4,12.86],[2,2.34,29.13]],"ltp":2.48,"tv":7.0,"id":655}]}]}
{"op":"mcm","clk":"11827713591","pt":1723363416687,"mc":[{"id":"1.231582261","rc":[{"batb":[[0,2.44,10],[1,2.42,12.68],[2,2.4,12.86]],"ltp":2.48,"tv":7.0,"id":655}]}]}
{"op":"mcm","clk":"11827713765","pt":1723363420194,"mc":[{"id":"1.231582261","rc":[{"batb":[[0,2.42,12.68],[1,2.4,12.86],[2,2.34,29.13]],"ltp":2.48,"tv":7.0,"id":655}]}]}
{"op":"mcm","clk":"11827713779","pt":1723363420599,"mc":[{"id":"1.231582261","rc":[{"batb":[[0,2.44,4],[1,2.42,12.68],[2,2.4,12.86]],"ltp":2.48,"tv":7.0,"id":655}]}]}
{"op":"mcm","clk":"11827713893","pt":1723363423016,"mc":[{"id":"1.231582261","rc":[{"batb":[[0,2.44,10]],"ltp":2.48,"tv":7.0,"id":655}]}]}
{"op":"mcm","clk":"11827714041","pt":1723363426403,"mc":[{"id":"1.231582261","rc":[{"batb":[[0,2.44,4]],"ltp":2.48,"tv":7.0,"id":655}]}]}
{"op":"mcm","clk":"11827714090","pt":1723363427379,"mc":[{"id":"1.231582261","rc":[{"trd":[[1.64,2]],"ltp":1.64,"tv":209.92,"id":2120}],"tv":216.92}]}
{"op":"mcm","clk":"11827714163","pt":1723363429020,"mc":[{"id":"1.231582261","rc":[{"batb":[[0,2.46,10]],"ltp":2.48,"tv":7.0,"id":655}]}]}
{"op":"mcm","clk":"11827714334","pt":1723363432686,"mc":[{"id":"1.231582261","rc":[{"batb":[[0,2.42,12.68],[1,2.4,12.86],[2,2.34,29.13]],"ltp":2.48,"tv":7.0,"id":655}]}]}
{"op":"mcm","clk":"11827714382","pt":1723363433608,"mc":[{"id":"1.231582261","rc":[{"batb":[[0,2.44,4],[1,2.42,12.68],[2,2.4,12.86]],"ltp":2.48,"tv":7.0,"id":655}]}]}
{"op":"mcm","clk":"11827714480","pt":1723363436348,"mc":[{"id":"1.231582261","rc":[{"batb":[[0,2.46,10]],"ltp":2.48,"tv":7.0,"id":655}]}]}
{"op":"mcm","clk":"11827714608","pt":1723363439300,"mc":[{"id":"1.231582261","rc":[{"batb":[[0,2.42,12.68],[1,2.4,12.86],[2,2.34,29.13]],"ltp":2.48,"tv":7.0,"id":655}]}]}
{"op":"mcm","clk":"11827714640","pt":1723363439813,"mc":[{"id":"1.231582261","rc":[{"batb":[[0,2.44,4],[1,2.42,12.68],[2,2.4,12.86]],"ltp":2.48,"tv":7.0,"id":655}]}]}
{"op":"mcm","clk":"11827714768","pt":1723363442241,"mc":[{"id":"1.231582261","rc":[{"batb":[[0,2.46,10]],"ltp":2.48,"tv":7.0,"id":655}]}]}
{"op":"mcm","clk":"11827714938","pt":1723363445446,"mc":[{"id":"1.231582261","rc":[{"batb":[[0,2.48,4]],"ltp":2.48,"tv":7.0,"id":655}]}]}
{"op":"mcm","clk":"11827715029","pt":1723363447507,"mc":[{"id":"1.231582261","rc":[{"batb":[[0,2.42,12.68],[1,2.4,12.86],[2,2.34,29.13]],"ltp":2.48,"tv":7.0,"id":655}]}]}
{"op":"mcm","clk":"11827715058","pt":1723363448636,"mc":[{"id":"1.231582261","rc":[{"batb":[[0,2.44,10],[1,2.42,12.68],[2,2.4,12.86]],"ltp":2.48,"tv":7.0,"id":655}]}]}
{"op":"mcm","clk":"11827715125","pt":1723363450238,"mc":[{"id":"1.231582261","rc":[{"batb":[[0,2.46,4],[1,2.44,10],[2,2.42,12.68]],"ltp":2.48,"tv":7.0,"id":655}]}]}
{"op":"mcm","clk":"11827715264","pt":1723363452823,"mc":[{"id":"1.231582261","rc":[{"batb":[[0,2.42,12.68],[1,2.4,12.86],[2,2.34,29.13]],"ltp":2.48,"tv":7.0,"id":655}]}]}
{"op":"mcm","clk":"11827715462","pt":1723363456426,"mc":[{"id":"1.231582261","rc":[{"batb":[[0,2.44,14],[1,2.42,12.68],[2,2.4,12.86]],"ltp":2.48,"tv":7.0,"id":655}]}]}
{"op":"mcm","clk":"11827715591","pt":1723363458954,"mc":[{"id":"1.231582261","rc":[{"batb":[[0,2.44,10]],"ltp":2.48,"tv":7.0,"id":655}]}]}
{"op":"mcm","clk":"11827715647","pt":1723363459862,"mc":[{"id":"1.231582261","rc":[{"batb":[[0,2.42,12.68],[1,2.4,12.86],[2,2.34,29.13]],"ltp":2.48,"tv":7.0,"id":655}]}]}
{"op":"mcm","clk":"11827715821","pt":1723363463547,"mc":[{"id":"1.231582261","rc":[{"batb":[[0,2.44,14],[1,2.42,12.68],[2,2.4,12.86]],"ltp":2.48,"tv":7.0,"id":655}]}]}
{"op":"mcm","clk":"11827715952","pt":1723363466125,"mc":[{"id":"1.231582261","rc":[{"batb":[[0,2.44,10]],"ltp":2.48,"tv":7.0,"id":655}]}]}
{"op":"mcm","clk":"11827715992","pt":1723363467256,"mc":[{"id":"1.231582261","rc":[{"batb":[[0,2.42,12.68],[1,2.4,12.86],[2,2.34,29.13]],"ltp":2.48,"tv":7.0,"id":655}]}]}
{"op":"mcm","clk":"11827716067","pt":1723363468753,"mc":[{"id":"1.231582261","rc":[{"batb":[[0,2.44,4],[1,2.42,12.68],[2,2.4,12.86]],"ltp":2.48,"tv":7.0,"id":655}]}]}
{"op":"mcm","clk":"11827716190","pt":1723363471442,"mc":[{"id":"1.231582261","rc":[{"batb":[[0,2.44,10]],"ltp":2.48,"tv":7.0,"id":655}]}]}
{"op":"mcm","clk":"11827716325","pt":1723363474337,"mc":[{"id":"1.231582261","rc":[{"batb":[[0,2.46,4],[1,2.44,10],[2,2.42,12.68]],"ltp":2.48,"tv":7.0,"id":655}]}]}
{"op":"mcm","clk":"11827716352","pt":1723363474950,"mc":[{"id":"1.231582261","rc":[{"batb":[[1,2.42,12.68],[2,2.4,12.86]],"ltp":2.48,"tv":7.0,"id":655}]}]}
{"op":"mcm","clk":"11827716472","pt":1723363477145,"mc":[{"id":"1.231582261","rc":[{"batb":[[0,2.42,12.68],[1,2.4,12.86],[2,2.34,29.13]],"ltp":2.48,"tv":7.0,"id":655}]}]}
{"op":"mcm","clk":"11827716517","pt":1723363477968,"mc":[{"id":"1.231582261","rc":[{"batb":[[0,2.44,10],[1,2.42,12.68],[2,2.4,12.86]],"ltp":2.48,"tv":7.0,"id":655}]}]}
{"op":"mcm","clk":"11827716641","pt":1723363480248,"mc":[{"id":"1.231582261","rc":[{"batb":[[0,2.46,4],[1,2.44,10],[2,2.42,12.68]],"ltp":2.48,"tv":7.0,"id":655}]}]}
{"op":"mcm","clk":"11827716704","pt":1723363481639,"mc":[{"id":"1.231582261","rc":[{"batb":[[1,2.42,12.68],[2,2.4,12.86]],"ltp":2.48,"tv":7.0,"id":655}]}]}
{"op":"mcm","clk":"11827716735","pt":1723363482566,"mc":[{"id":"1.231582261","rc":[{"batb":[[0,2.42,12.68],[1,2.4,12.86],[2,2.34,29.13]],"ltp":2.48,"tv":7.0,"id":655}]}]}
{"op":"mcm","clk":"11827716830","pt":1723363484483,"mc":[{"id":"1.231582261","rc":[{"batb":[[0,2.44,10],[1,2.42,12.68],[2,2.4,12.86]],"ltp":2.48,"tv":7.0,"id":655}]}]}
{"op":"mcm","clk":"11827716862","pt":1723363485058,"mc":[{"id":"1.231582261","rc":[{"batb":[[0,2.46,4],[1,2.44,10],[2,2.42,12.68]],"ltp":2.48,"tv":7.0,"id":655}]}]}
{"op":"mcm","clk":"11827717040","pt":1723363488281,"mc":[{"id":"1.231582261","rc":[{"batb":[[0,2.42,12.68],[1,2.4,12.86],[2,2.34,29.13]],"ltp":2.48,"tv":7.0,"id":655}]}]}
{"op":"mcm","clk":"11827717262","pt":1723363493188,"mc":[{"id":"1.231582261","rc":[{"batb":[[0,2.44,14],[1,2.42,12.68],[2,2.4,12.86]],"ltp":2.48,"tv":7.0,"id":655}]}]}
{"op":"mcm","clk":"11827717343","pt":1723363495375,"mc":[{"id":"1.231582261","rc":[{"batb":[[0,2.44,10]],"ltp":2.48,"tv":7.0,"id":655}]}]}
{"op":"mcm","clk":"11827717385","pt":1723363496554,"mc":[{"id":"1.231582261","rc":[{"batb":[[0,2.42,12.68],[1,2.4,12.86],[2,2.34,29.13]],"ltp":2.48,"tv":7.0,"id":655}]}]}
{"op":"mcm","clk":"11827717481","pt":1723363498166,"mc":[{"id":"1.231582261","rc":[{"batb":[[0,2.44,4],[1,2.42,12.68],[2,2.4,12.86]],"ltp":2.48,"tv":7.0,"id":655}]}]}
{"op":"mcm","clk":"11827717533","pt":1723363499254,"mc":[{"id":"1.231582261","rc":[{"batb":[[0,2.46,10],[1,2.44,4],[2,2.42,12.68]],"ltp":2.48,"tv":7.0,"id":655}]}]}
{"op":"mcm","clk":"11827717608","pt":1723363500705,"mc":[{"id":"1.231582261","rc":[{"batb":[[1,2.42,12.68],[2,2.4,12.86]],"ltp":2.48,"tv":7.0,"id":655}]}]}
{"op":"mcm","clk":"11827717742","pt":1723363502787,"mc":[{"id":"1.231582261","rc":[{"batb":[[0,2.44,4]],"ltp":2.48,"tv":7.0,"id":655}]}]}
{"op":"mcm","clk":"11827717871","pt":1723363505192,"mc":[{"id":"1.231582261","rc":[{"batb":[[0,2.42,12.68],[1,2.4,12.86],[2,2.34,29.13]],"ltp":2.48,"tv":7.0,"id":655}]}]}
{"op":"mcm","clk":"11827717904","pt":1723363505860,"mc":[{"id":"1.231582261","rc":[{"batb":[[0,2.44,10],[1,2.42,12.68],[2,2.4,12.86]],"ltp":2.48,"tv":7.0,"id":655}]}]}
{"op":"mcm","clk":"11827717998","pt":1723363507571,"mc":[{"id":"1.231582261","rc":[{"batb":[[0,2.46,4],[1,2.44,10],[2,2.42,12.68]],"ltp":2.48,"tv":7.0,"id":655}]}]}
{"op":"mcm","clk":"11827718078","pt":1723363509269,"mc":[{"id":"1.231582261","rc":[{"batb":[[1,2.42,12.68],[2,2.4,12.86]],"ltp":2.48,"tv":7.0,"id":655}]}]}
{"op":"mcm","clk":"11827718122","pt":1723363509885,"mc":[{"id":"1.231582261","rc":[{"batb":[[0,2.42,12.68],[1,2.4,12.86],[2,2.34,29.13]],"ltp":2.48,"tv":7.0,"id":655}]}]}
{"op":"mcm","clk":"11827718208","pt":1723363511512,"mc":[{"id":"1.231582261","rc":[{"batb":[[0,2.44,10],[1,2.42,12.68],[2,2.4,12.86]],"ltp":2.48,"tv":7.0,"id":655}]}]}
{"op":"mcm","clk":"11827718269","pt":1723363512696,"mc":[{"id":"1.231582261","rc":[{"batb":[[0,2.46,4],[1,2.44,10],[2,2.42,12.68]],"ltp":2.48,"tv":7.0,"id":655}]}]}
{"op":"mcm","clk":"11827718381","pt":1723363514971,"mc":[{"id":"1.231582261","rc":[{"batb":[[0,2.42,12.68],[1,2.4,12.86],[2,2.34,29.13]],"ltp":2.48,"tv":7.0,"id":655}]}]}
{"op":"mcm","clk":"11827718565","pt":1723363518111,"mc":[{"id":"1.231582261","rc":[{"batb":[[0,2.44,14],[1,2.42,12.68],[2,2.4,12.86]],"ltp":2.48,"tv":7.0,"id":655}]}]}
{"op":"mcm","clk":"11827718691","pt":1723363520593,"mc":[{"id":"1.231582261","rc":[{"batb":[[0,2.44,10]],"ltp":2.48,"tv":7.0,"id":655}]}]}
{"op":"mcm","clk":"11827718728","pt":1723363521517,"mc":[{"id":"1.231582261","rc":[{"batb":[[0,2.42,12.68],[1,2.4,12.86],[2,2.34,29.13]],"ltp":2.48,"tv":7.0,"id":655}]}]}
{"op":"mcm","clk":"11827718801","pt":1723363522907,"mc":[{"id":"1.231582261","rc":[{"batb":[[0,2.44,4],[1,2.42,12.68],[2,2.4,12.86]],"ltp":2.48,"tv":7.0,"id":655}]}]}
{"op":"mcm","clk":"11827718842","pt":1723363524200,"mc":[{"id":"1.231582261","rc":[{"batb":[[0,2.46,10],[1,2.44,4],[2,2.42,12.68]],"ltp":2.48,"tv":7.0,"id":655}]}]}
{"op":"mcm","clk":"11827718887","pt":1723363525088,"mc":[{"id":"1.231582261","rc":[{"batb":[[1,2.42,12.68],[2,2.4,12.86]],"ltp":2.48,"tv":7.0,"id":655}]}]}
{"op":"mcm","clk":"11827719063","pt":1723363528198,"mc":[{"id":"1.231582261","rc":[{"batb":[[0,2.44,4]],"ltp":2.48,"tv":7.0,"id":655}]}]}
{"op":"mcm","clk":"11827719151","pt":1723363530430,"mc":[{"id":"1.231582261","rc":[{"batb":[[0,2.42,12.68],[1,2.4,12.86],[2,2.34,29.13]],"ltp":2.48,"tv":7.0,"id":655}]}]}
{"op":"mcm","clk":"11827719160","pt":1723363530635,"mc":[{"id":"1.231582261","rc":[{"batb":[[0,2.44,10],[1,2.42,12.68],[2,2.4,12.86]],"ltp":2.48,"tv":7.0,"id":655}]}]}
{"op":"mcm","clk":"11827719330","pt":1723363534114,"mc":[{"id":"1.231582261","rc":[{"batb":[[0,2.44,4]],"ltp":2.48,"tv":7.0,"id":655}]}]}
{"op":"mcm","clk":"11827719424","pt":1723363536494,"mc":[{"id":"1.231582261","rc":[{"batb":[[0,2.42,12.68],[1,2.4,12.86],[2,2.34,29.13]],"ltp":2.48,"tv":7.0,"id":655}]}]}
{"op":"mcm","clk":"11827719428","pt":1723363536595,"mc":[{"id":"1.231582261","rc":[{"batb":[[0,2.44,10],[1,2.42,12.68],[2,2.4,12.86]],"ltp":2.48,"tv":7.0,"id":655}]}]}
{"op":"mcm","clk":"11827719582","pt":1723363539903,"mc":[{"id":"1.231582261","rc":[{"batb":[[0,2.46,4]],"ltp":2.48,"tv":7.0,"id":655}]}]}
{"op":"mcm","clk":"11827719700","pt":1723363542335,"mc":[{"id":"1.231582261","rc":[{"batb":[[0,2.44,10]],"ltp":2.48,"tv":7.0,"id":655}]}]}
{"op":"mcm","clk":"11827719885","pt":1723363545022,"mc":[{"id":"1.231582261","rc":[{"batb":[[0,2.46,4],[1,2.44,10],[2,2.42,12.68]],"ltp":2.48,"tv":7.0,"id":655}]}]}
{"op":"mcm","clk":"11827719925","pt":1723363545745,"mc":[{"id":"1.231582261","rc":[{"batb":[[1,2.42,12.68],[2,2.4,12.86]],"ltp":2.48,"tv":7.0,"id":655}]}]}
{"op":"mcm","clk":"11827720000","pt":1723363547340,"mc":[{"id":"1.231582261","rc":[{"batb":[[0,2.42,12.68],[1,2.4,12.86],[2,2.34,29.13]],"ltp":2.48,"tv":7.0,"id":655}]}]}
{"op":"mcm","clk":"11827720046","pt":1723363548421,"mc":[{"id":"1.231582261","rc":[{"batb":[[0,2.44,10],[1,2.42,12.68],[2,2.4,12.86]],"ltp":2.48,"tv":7.0,"id":655}]}]}
{"op":"mcm","clk":"11827720092","pt":1723363549609,"mc":[{"id":"1.231582261","rc":[{"batb":[[0,2.46,4],[1,2.44,10],[2,2.42,12.68]],"ltp":2.48,"tv":7.0,"id":655}]}]}
{"op":"mcm","clk":"11827720231","pt":1723363551933,"mc":[{"id":"1.231582261","rc":[{"batb":[[0,2.42,12.68],[1,2.4,12.86],[2,2.34,29.13]],"ltp":2.48,"tv":7.0,"id":655}]}]}
{"op":"mcm","clk":"11827720370","pt":1723363554720,"mc":[{"id":"1.231582261","rc":[{"batb":[[0,2.44,14],[1,2.42,12.68],[2,2.4,12.86]],"ltp":2.48,"tv":7.0,"id":655}]}]}
{"op":"mcm","clk":"11827720540","pt":1723363558320,"mc":[{"id":"1.231582261","rc":[{"batb":[[0,2.44,10]],"ltp":2.48,"tv":7.0,"id":655}]}]}
{"op":"mcm","clk":"11827720604","pt":1723363559242,"mc":[{"id":"1.231582261","rc":[{"batb":[[0,2.42,12.68],[1,2.4,12.86],[2,2.34,29.13]],"ltp":2.48,"tv":7.0,"id":655}]}]}
{"op":"mcm","clk":"11827720736","pt":1723363561617,"mc":[{"id":"1.231582261","rc":[{"batb":[[0,2.44,14],[1,2.42,12.68],[2,2.4,12.86]],"ltp":2.48,"tv":7.0,"id":655}]}]}
{"op":"mcm","clk":"11827720903","pt":1723363563944,"mc":[{"id":"1.231582261","rc":[{"batb":[[0,2.44,10]],"ltp":2.48,"tv":7.0,"id":655}]}]}
{"op":"mcm","clk":"11827720968","pt":1723363564929,"mc":[{"id":"1.231582261","rc":[{"batb":[[0,2.42,12.68],[1,2.4,12.86],[2,2.34,29.13]],"ltp":2.48,"tv":7.0,"id":655}]}]}
{"op":"mcm","clk":"11827721052","pt":1723363566628,"mc":[{"id":"1.231582261","rc":[{"batb":[[0,2.44,4],[1,2.42,12.68],[2,2.4,12.86]],"ltp":2.48,"tv":7.0,"id":655}]}]}
{"op":"mcm","clk":"11827721288","pt":1723363571375,"mc":[{"id":"1.231582261","rc":[{"batb":[[0,2.44,10]],"ltp":2.48,"tv":7.0,"id":655}]}]}
{"op":"mcm","clk":"11827721349","pt":1723363572974,"mc":[{"id":"1.231582261","rc":[{"batb":[[0,2.46,4],[1,2.44,10],[2,2.42,12.68]],"ltp":2.48,"tv":7.0,"id":655}]}]}
{"op":"mcm","clk":"11827721475","pt":1723363575855,"mc":[{"id":"1.231582261","rc":[{"batb":[[0,2.42,12.68],[1,2.4,12.86],[2,2.34,29.13]],"ltp":2.48,"tv":7.0,"id":655}]}]}
{"op":"mcm","clk":"11827721621","pt":1723363578076,"mc":[{"id":"1.231582261","rc":[{"batb":[[0,2.46,10],[1,2.44,4],[2,2.42,12.68]],"ltp":2.48,"tv":7.0,"id":655}]}]}
{"op":"mcm","clk":"11827721722","pt":1723363580184,"mc":[{"id":"1.231582261","rc":[{"batb":[[1,2.42,12.68],[2,2.4,12.86]],"ltp":2.48,"tv":7.0,"id":655}]}]}
{"op":"mcm","clk":"11827721793","pt":1723363581370,"mc":[{"id":"1.231582261","rc":[{"batb":[[0,2.42,12.68],[1,2.4,12.86],[2,2.34,29.13]],"ltp":2.48,"tv":7.0,"id":655}]}]}
{"op":"mcm","clk":"11827721935","pt":1723363583683,"mc":[{"id":"1.231582261","rc":[{"batb":[[0,2.44,14],[1,2.42,12.68],[2,2.4,12.86]],"ltp":2.48,"tv":7.0,"id":655}]}]}
{"op":"mcm","clk":"11827722063","pt":1723363585992,"mc":[{"id":"1.231582261","rc":[{"batb":[[0,2.44,10]],"ltp":2.48,"tv":7.0,"id":655}]}]}
{"op":"mcm","clk":"11827722136","pt":1723363587171,"mc":[{"id":"1.231582261","rc":[{"batb":[[0,2.42,12.68],[1,2.4,12.86],[2,2.34,29.13]],"ltp":2.48,"tv":7.0,"id":655}]}]}
{"op":"mcm","clk":"11827722220","pt":1723363588564,"mc":[{"id":"1.231582261","rc":[{"batb":[[0,2.44,4],[1,2.42,12.68],[2,2.4,12.86]],"ltp":2.48,"tv":7.0,"id":655}]}]}
{"op":"mcm","clk":"11827722290","pt":1723363590057,"mc":[{"id":"1.231582261","rc":[{"batb":[[0,2.46,10],[1,2.44,4],[2,2.42,12.68]],"ltp":2.48,"tv":7.0,"id":655}]}]}
{"op":"mcm","clk":"11827722340","pt":1723363591082,"mc":[{"id":"1.231582261","rc":[{"batb":[[1,2.42,12.68],[2,2.4,12.86]],"ltp":2.48,"tv":7.0,"id":655}]}]}
{"op":"mcm","clk":"11827722460","pt":1723363593501,"mc":[{"id":"1.231582261","rc":[{"batb":[[0,2.44,4]],"ltp":2.48,"tv":7.0,"id":655}]}]}
{"op":"mcm","clk":"11827722548","pt":1723363595874,"mc":[{"id":"1.231582261","rc":[{"batb":[[0,2.44,10]],"ltp":2.48,"tv":7.0,"id":655}]}]}
{"op":"mcm","clk":"11827722720","pt":1723363599173,"mc":[{"id":"1.231582261","rc":[{"batb":[[0,2.46,4]],"ltp":2.48,"tv":7.0,"id":655}]}]}
{"op":"mcm","clk":"11827722834","pt":1723363601375,"mc":[{"id":"1.231582261","rc":[{"batb":[[0,2.44,10]],"ltp":2.48,"tv":7.0,"id":655}]}]}
{"op":"mcm","clk":"11827722949","pt":1723363603680,"mc":[{"id":"1.231582261","rc":[{"batb":[[0,2.46,4],[1,2.44,10],[2,2.42,12.68]],"ltp":2.48,"tv":7.0,"id":655}]}]}
{"op":"mcm","clk":"11827723008","pt":1723363604812,"mc":[{"id":"1.231582261","rc":[{"batb":[[1,2.42,12.68],[2,2.4,12.86]],"ltp":2.48,"tv":7.0,"id":655}]}]}
{"op":"mcm","clk":"11827723073","pt":1723363606404,"mc":[{"id":"1.231582261","rc":[{"batb":[[0,2.42,12.68],[1,2.4,12.86],[2,2.34,29.13]],"ltp":2.48,"tv":7.0,"id":655}]}]}
{"op":"mcm","clk":"11827723191","pt":1723363608586,"mc":[{"id":"1.231582261","rc":[{"batb":[[0,2.44,14],[1,2.42,12.68],[2,2.4,12.86]],"ltp":2.48,"tv":7.0,"id":655}]}]}
{"op":"mcm","clk":"11827723317","pt":1723363611099,"mc":[{"id":"1.231582261","rc":[{"batb":[[0,2.44,10]],"ltp":2.48,"tv":7.0,"id":655}]}]}
{"op":"mcm","clk":"11827723368","pt":1723363611973,"mc":[{"id":"1.231582261","rc":[{"batb":[[0,2.42,12.68],[1,2.4,12.86],[2,2.34,29.13]],"ltp":2.48,"tv":7.0,"id":655}]}]}
{"op":"mcm","clk":"11827723529","pt":1723363614701,"mc":[{"id":"1.231582261","rc":[{"batb":[[0,2.44,14],[1,2.42,12.68],[2,2.4,12.86]],"ltp":2.48,"tv":7.0,"id":655}]}]}
{"op":"mcm","clk":"11827723634","pt":1723363616907,"mc":[{"id":"1.231582261","rc":[{"batb":[[0,2.44,10]],"ltp":2.48,"tv":7.0,"id":655}]}]}
{"op":"mcm","clk":"11827723691","pt":1723363617993,"mc":[{"id":"1.231582261","rc":[{"batb":[[0,2.42,12.68],[1,2.4,12.86],[2,2.34,29.13]],"ltp":2.48,"tv":7.0,"id":655}]}]}
{"op":"mcm","clk":"11827723763","pt":1723363619378,"mc":[{"id":"1.231582261","rc":[{"batb":[[0,2.44,4],[1,2.42,12.68],[2,2.4,12.86]],"ltp":2.48,"tv":7.0,"id":655}]}]}
{"op":"mcm","clk":"11827723826","pt":1723363620719,"mc":[{"id":"1.231582261","rc":[{"batb":[[0,2.46,10],[1,2.44,4],[2,2.42,12.68]],"ltp":2.48,"tv":7.0,"id":655}]}]}
{"op":"mcm","clk":"11827723887","pt":1723363621805,"mc":[{"id":"1.231582261","rc":[{"batb":[[1,2.42,12.68],[2,2.4,12.86]],"ltp":2.48,"tv":7.0,"id":655}]}]}
{"op":"mcm","clk":"11827724051","pt":1723363624187,"mc":[{"id":"1.231582261","rc":[{"batb":[[0,2.44,4]],"ltp":2.48,"tv":7.0,"id":655}]}]}
{"op":"mcm","clk":"11827724175","pt":1723363626710,"mc":[{"id":"1.231582261","rc":[{"batb":[[0,2.46,10]],"ltp":2.48,"tv":7.0,"id":655}]}]}
{"op":"mcm","clk":"11827724333","pt":1723363630210,"mc":[{"id":"1.231582261","rc":[{"batb":[[0,2.48,4]],"ltp":2.48,"tv":7.0,"id":655}]}]}
{"op":"mcm","clk":"11827724469","pt":1723363632328,"mc":[{"id":"1.231582261","rc":[{"batb":[[0,2.44,10]],"ltp":2.48,"tv":7.0,"id":655}]}]}
{"op":"mcm","clk":"11827724674","pt":1723363636042,"mc":[{"id":"1.231582261","rc":[{"batb":[[0,2.44,4]],"ltp":2.48,"tv":7.0,"id":655}]}]}
{"op":"mcm","clk":"11827724810","pt":1723363638428,"mc":[{"id":"1.231582261","rc":[{"batb":[[0,2.44,10]],"ltp":2.48,"tv":7.0,"id":655}]}]}
{"op":"mcm","clk":"11827724928","pt":1723363640918,"mc":[{"id":"1.231582261","rc":[{"batb":[[0,2.46,4],[1,2.44,10],[2,2.42,12.68]],"ltp":2.48,"tv":7.0,"id":655}]}]}
{"op":"mcm","clk":"11827724967","pt":1723363641641,"mc":[{"id":"1.231582261","rc":[{"batb":[[1,2.42,12.68],[2,2.4,12.86]],"ltp":2.48,"tv":7.0,"id":655}]}]}
{"op":"mcm","clk":"11827725039","pt":1723363643035,"mc":[{"id":"1.231582261","rc":[{"batb":[[0,2.42,12.68],[1,2.4,12.86],[2,2.34,29.13]],"ltp":2.48,"tv":7.0,"id":655}]}]}
{"op":"mcm","clk":"11827725158","pt":1723363645361,"mc":[{"id":"1.231582261","rc":[{"batb":[[0,2.46,4],[1,2.44,10],[2,2.42,12.68]],"ltp":2.48,"tv":7.0,"id":655}]}]}
{"op":"mcm","clk":"11827725352","pt":1723363648450,"mc":[{"id":"1.231582261","rc":[{"batb":[[0,2.42,12.68],[1,2.4,12.86],[2,2.34,29.13]],"ltp":2.48,"tv":7.0,"id":655}]}]}
{"op":"mcm","clk":"11827725456","pt":1723363650149,"mc":[{"id":"1.231582261","rc":[{"batb":[[0,2.44,4],[1,2.42,12.68],[2,2.4,12.86]],"ltp":2.48,"tv":7.0,"id":655}]}]}
{"op":"mcm","clk":"11827725575","pt":1723363652469,"mc":[{"id":"1.231582261","rc":[{"batb":[[0,2.44,10]],"ltp":2.48,"tv":7.0,"id":655}]}]}
{"op":"mcm","clk":"11827725727","pt":1723363654863,"mc":[{"id":"1.231582261","rc":[{"batb":[[0,2.46,4],[1,2.44,10],[2,2.42,12.68]],"ltp":2.48,"tv":7.0,"id":655}]}]}
{"op":"mcm","clk":"11827725777","pt":1723363655843,"mc":[{"id":"1.231582261","rc":[{"batb":[[1,2.42,12.68],[2,2.4,12.86]],"ltp":2.48,"tv":7.0,"id":655}]}]}
{"op":"mcm","clk":"11827725840","pt":1723363657182,"mc":[{"id":"1.231582261","rc":[{"batb":[[0,2.42,12.68],[1,2.4,12.86],[2,2.34,29.13]],"ltp":2.48,"tv":7.0,"id":655}]}]}
{"op":"mcm","clk":"11827725928","pt":1723363658575,"mc":[{"id":"1.231582261","rc":[{"batb":[[0,2.44,10],[1,2.42,12.68],[2,2.4,12.86]],"ltp":2.48,"tv":7.0,"id":655}]}]}
{"op":"mcm","clk":"11827725989","pt":1723363659762,"mc":[{"id":"1.231582261","rc":[{"batb":[[0,2.46,4],[1,2.44,10],[2,2.42,12.68]],"ltp":2.48,"tv":7.0,"id":655}]}]}
{"op":"mcm","clk":"11827726134","pt":1723363661979,"mc":[{"id":"1.231582261","rc":[{"batb":[[0,2.42,12.68],[1,2.4,12.86],[2,2.34,29.13]],"ltp":2.48,"tv":7.0,"id":655}]}]}
{"op":"mcm","clk":"11827726312","pt":1723363664771,"mc":[{"id":"1.231582261","rc":[{"batb":[[0,2.44,14],[1,2.42,12.68],[2,2.4,12.86]],"ltp":2.48,"tv":7.0,"id":655}]}]}
{"op":"mcm","clk":"11827726452","pt":1723363667358,"mc":[{"id":"1.231582261","rc":[{"batb":[[0,2.44,10]],"ltp":2.48,"tv":7.0,"id":655}]}]}
{"op":"mcm","clk":"11827726499","pt":1723363668385,"mc":[{"id":"1.231582261","rc":[{"batb":[[0,2.42,12.68],[1,2.4,12.86],[2,2.34,29.13]],"ltp":2.48,"tv":7.0,"id":655}]}]}
{"op":"mcm","clk":"11827726591","pt":1723363670393,"mc":[{"id":"1.231582261","rc":[{"batb":[[0,2.44,4],[1,2.42,12.68],[2,2.4,12.86]],"ltp":2.48,"tv":7.0,"id":655}]}]}
{"op":"mcm","clk":"11827726734","pt":1723363672662,"mc":[{"id":"1.231582261","rc":[{"batb":[[0,2.46,10]],"ltp":2.48,"tv":7.0,"id":655}]}]}
{"op":"mcm","clk":"11827726947","pt":1723363675968,"mc":[{"id":"1.231582261","rc":[{"batb":[[0,2.48,4]],"ltp":2.48,"tv":7.0,"id":655}]}]}
{"op":"mcm","clk":"11827727095","pt":1723363678389,"mc":[{"id":"1.231582261","rc":[{"batb":[[0,2.42,12.68],[1,2.4,12.86],[2,2.34,29.13]],"ltp":2.48,"tv":7.0,"id":655}]}]}
{"op":"mcm","clk":"11827727115","pt":1723363678697,"mc":[{"id":"1.231582261","rc":[{"batb":[[0,2.44,10],[1,2.42,12.68],[2,2.4,12.86]],"ltp":2.48,"tv":7.0,"id":655}]}]}
{"op":"mcm","clk":"11827727230","pt":1723363681290,"mc":[{"id":"1.231582261","rc":[{"batb":[[0,2.46,4],[1,2.44,10],[2,2.42,12.68]],"ltp":2.48,"tv":7.0,"id":655}]}]}
{"op":"mcm","clk":"11827727286","pt":1723363682278,"mc":[{"id":"1.231582261","rc":[{"batb":[[1,2.42,12.68],[2,2.4,12.86]],"ltp":2.48,"tv":7.0,"id":655}]}]}
{"op":"mcm","clk":"11827727371","pt":1723363683696,"mc":[{"id":"1.231582261","rc":[{"batb":[[0,2.42,12.68],[1,2.4,12.86],[2,2.34,29.13]],"ltp":2.48,"tv":7.0,"id":655}]}]}
{"op":"mcm","clk":"11827727454","pt":1723363684891,"mc":[{"id":"1.231582261","rc":[{"batb":[[0,2.44,10],[1,2.42,12.68],[2,2.4,12.86]],"ltp":2.48,"tv":7.0,"id":655}]}]}
{"op":"mcm","clk":"11827727616","pt":1723363687114,"mc":[{"id":"1.231582261","rc":[{"batb":[[0,2.46,4],[1,2.44,10],[2,2.42,12.68]],"ltp":2.48,"tv":7.0,"id":655}]}]}
{"op":"mcm","clk":"11827727684","pt":1723363688093,"mc":[{"id":"1.231582261","rc":[{"batb":[[1,2.42,12.68],[2,2.4,12.86]],"ltp":2.48,"tv":7.0,"id":655}]}]}
{"op":"mcm","clk":"11827727781","pt":1723363689392,"mc":[{"id":"1.231582261","rc":[{"batb":[[0,2.42,12.68],[1,2.4,12.86],[2,2.34,29.13]],"ltp":2.48,"tv":7.0,"id":655}]}]}
{"op":"mcm","clk":"11827727828","pt":1723363690526,"mc":[{"id":"1.231582261","rc":[{"batb":[[0,2.44,10],[1,2.42,12.68],[2,2.4,12.86]],"ltp":2.48,"tv":7.0,"id":655}]}]}
{"op":"mcm","clk":"11827727894","pt":1723363691914,"mc":[{"id":"1.231582261","rc":[{"batb":[[0,2.46,4],[1,2.44,10],[2,2.42,12.68]],"ltp":2.48,"tv":7.0,"id":655}]}]}
{"op":"mcm","clk":"11827727999","pt":1723363694079,"mc":[{"id":"1.231582261","rc":[{"batb":[[0,2.42,12.68],[1,2.4,12.86],[2,2.34,29.13]],"ltp":2.48,"tv":7.0,"id":655}]}]}
{"op":"mcm","clk":"11827728136","pt":1723363696816,"mc":[{"id":"1.231582261","rc":[{"batb":[[0,2.44,14],[1,2.42,12.68],[2,2.4,12.86]],"ltp":2.48,"tv":7.0,"id":655}]}]}
{"op":"mcm","clk":"11827728265","pt":1723363699201,"mc":[{"id":"1.231582261","rc":[{"batb":[[0,2.44,10]],"ltp":2.48,"tv":7.0,"id":655}]}]}
{"op":"mcm","clk":"11827728317","pt":1723363700230,"mc":[{"id":"1.231582261","rc":[{"batb":[[0,2.42,12.68],[1,2.4,12.86],[2,2.34,29.13]],"ltp":2.48,"tv":7.0,"id":655}]}]}
{"op":"mcm","clk":"11827728416","pt":1723363702189,"mc":[{"id":"1.231582261","rc":[{"batb":[[0,2.44,4],[1,2.42,12.68],[2,2.4,12.86]],"ltp":2.48,"tv":7.0,"id":655}]}]}
{"op":"mcm","clk":"11827728436","pt":1723363702601,"mc":[{"id":"1.231582261","rc":[{"batb":[[0,2.46,10],[1,2.44,4],[2,2.42,12.68]],"ltp":2.48,"tv":7.0,"id":655}]}]}
{"op":"mcm","clk":"11827728553","pt":1723363704714,"mc":[{"id":"1.231582261","rc":[{"batb":[[1,2.42,12.68],[2,2.4,12.86]],"ltp":2.48,"tv":7.0,"id":655}]}]}
{"op":"mcm","clk":"11827728632","pt":1723363706109,"mc":[{"id":"1.231582261","rc":[{"batb":[[0,2.42,12.68],[1,2.4,12.86],[2,2.34,29.13]],"ltp":2.48,"tv":7.0,"id":655}]}]}
{"op":"mcm","clk":"11827728728","pt":1723363707612,"mc":[{"id":"1.231582261","rc":[{"batb":[[0,2.44,4],[1,2.42,12.68],[2,2.4,12.86]],"ltp":2.48,"tv":7.0,"id":655}]}]}
{"op":"mcm","clk":"11827728898","pt":1723363710246,"mc":[{"id":"1.231582261","rc":[{"batb":[[0,2.46,10]],"ltp":2.48,"tv":7.0,"id":655}]}]}
{"op":"mcm","clk":"11827729004","pt":1723363711808,"mc":[{"id":"1.231582261","rc":[{"trd":[[2.46,1.72]],"batb":[[0,2.46,8.28]],"ltp":2.46,"tv":8.72,"id":655},{"trd":[[1.69,2.5]],"ltp":1.69,"tv":212.42,"id":2120}],"tv":221.14}]}
{"op":"mcm","clk":"11827729086","pt":1723363713402,"mc":[{"id":"1.231582261","rc":[{"batb":[[0,2.48,4]],"ltp":2.46,"tv":8.72,"id":655}]}]}
{"op":"mcm","clk":"11827729181","pt":1723363715311,"mc":[{"id":"1.231582261","rc":[{"batb":[[0,2.42,12.68],[1,2.4,12.86],[2,2.34,29.13]],"ltp":2.46,"tv":8.72,"id":655}]}]}
{"op":"mcm","clk":"11827729193","pt":1723363715616,"mc":[{"id":"1.231582261","rc":[{"batb":[[0,2.44,10],[1,2.42,12.68],[2,2.4,12.86]],"ltp":2.46,"tv":8.72,"id":655}]}]}
{"op":"mcm","clk":"11827729374","pt":1723363719226,"mc":[{"id":"1.231582261","rc":[{"batb":[[0,2.44,4]],"ltp":2.46,"tv":8.72,"id":655}]}]}
{"op":"mcm","clk":"11827729481","pt":1723363722009,"mc":[{"id":"1.231582261","rc":[{"batb":[[0,2.44,10]],"ltp":2.46,"tv":8.72,"id":655}]}]}
{"op":"mcm","clk":"11827729630","pt":1723363725422,"mc":[{"id":"1.231582261","rc":[{"batb":[[0,2.44,4]],"ltp":2.46,"tv":8.72,"id":655}]}]}
{"op":"mcm","clk":"11827729746","pt":1723363728146,"mc":[{"id":"1.231582261","rc":[{"batb":[[0,2.44,10]],"ltp":2.46,"tv":8.72,"id":655}]}]}
{"op":"mcm","clk":"11827729833","pt":1723363729742,"mc":[{"id":"1.231582261","rc":[{"batb":[[0,2.46,4],[1,2.44,10],[2,2.42,12.68]],"ltp":2.46,"tv":8.72,"id":655}]}]}
{"op":"mcm","clk":"11827729956","pt":1723363732327,"mc":[{"id":"1.231582261","rc":[{"batb":[[0,2.42,12.68],[1,2.4,12.86],[2,2.34,29.13]],"ltp":2.46,"tv":8.72,"id":655}]}]}
{"op":"mcm","clk":"11827730050","pt":1723363734642,"mc":[{"id":"1.231582261","rc":[{"batb":[[0,2.44,14],[1,2.42,12.68],[2,2.4,12.86]],"ltp":2.46,"tv":8.72,"id":655}]}]}
{"op":"mcm","clk":"11827730168","pt":1723363737049,"mc":[{"id":"1.231582261","rc":[{"batb":[[0,2.44,10]],"ltp":2.46,"tv":8.72,"id":655}]}]}
{"op":"mcm","clk":"11827730215","pt":1723363738132,"mc":[{"id":"1.231582261","rc":[{"batb":[[0,2.42,12.68],[1,2.4,12.86],[2,2.34,29.13]],"ltp":2.46,"tv":8.72,"id":655}]}]}
{"op":"mcm","clk":"11827730283","pt":1723363739422,"mc":[{"id":"1.231582261","rc":[{"batb":[[0,2.44,4],[1,2.42,12.68],[2,2.4,12.86]],"ltp":2.46,"tv":8.72,"id":655}]}]}
{"op":"mcm","clk":"11827730445","pt":1723363742249,"mc":[{"id":"1.231582261","rc":[{"batb":[[0,2.46,10]],"ltp":2.46,"tv":8.72,"id":655}]}]}
{"op":"mcm","clk":"11827730574","pt":1723363744926,"mc":[{"id":"1.231582261","rc":[{"batb":[[0,2.48,4],[1,2.46,10],[2,2.42,12.68]],"ltp":2.46,"tv":8.72,"id":655}]}]}
{"op":"mcm","clk":"11827730614","pt":1723363745647,"mc":[{"id":"1.231582261","rc":[{"batb":[[1,2.42,12.68],[2,2.4,12.86]],"ltp":2.46,"tv":8.72,"id":655}]}]}
{"op":"mcm","clk":"11827730705","pt":1723363747432,"mc":[{"id":"1.231582261","rc":[{"batb":[[0,2.42,12.68],[1,2.4,12.86],[2,2.34,29.13]],"ltp":2.46,"tv":8.72,"id":655}]}]}
{"op":"mcm","clk":"11827730759","pt":1723363748666,"mc":[{"id":"1.231582261","rc":[{"batb":[[0,2.44,10],[1,2.42,12.68],[2,2.4,12.86]],"ltp":2.46,"tv":8.72,"id":655}]}]}
{"op":"mcm","clk":"11827730902","pt":1723363750839,"mc":[{"id":"1.231582261","rc":[{"batb":[[0,2.46,4],[1,2.44,10],[2,2.42,12.68]],"ltp":2.46,"tv":8.72,"id":655}]}]}
{"op":"mcm","clk":"11827730956","pt":1723363751923,"mc":[{"id":"1.231582261","rc":[{"batb":[[1,2.42,12.68],[2,2.4,12.86]],"ltp":2.46,"tv":8.72,"id":655}]}]}
{"op":"mcm","clk":"11827731022","pt":1723363753466,"mc":[{"id":"1.231582261","rc":[{"batb":[[0,2.42,12.68],[1,2.4,12.86],[2,2.34,29.13]],"ltp":2.46,"tv":8.72,"id":655}]}]}
{"op":"mcm","clk":"11827731067","pt":1723363754753,"mc":[{"id":"1.231582261","rc":[{"batb":[[0,2.44,10],[1,2.42,12.68],[2,2.4,12.86]],"ltp":2.46,"tv":8.72,"id":655}]}]}
{"op":"mcm","clk":"11827731118","pt":1723363755949,"mc":[{"id":"1.231582261","rc":[{"batb":[[0,2.46,4],[1,2.44,10],[2,2.42,12.68]],"ltp":2.46,"tv":8.72,"id":655}]}]}
{"op":"mcm","clk":"11827731224","pt":1723363758357,"mc":[{"id":"1.231582261","rc":[{"batb":[[0,2.42,12.68],[1,2.4,12.86],[2,2.34,29.13]],"ltp":2.46,"tv":8.72,"id":655}]}]}
{"op":"mcm","clk":"11827731361","pt":1723363760567,"mc":[{"id":"1.231582261","rc":[{"batb":[[0,2.44,14],[1,2.42,12.68],[2,2.4,12.86]],"ltp":2.46,"tv":8.72,"id":655}]}]}
{"op":"mcm","clk":"11827731465","pt":1723363763051,"mc":[{"id":"1.231582261","rc":[{"batb":[[0,2.44,10]],"ltp":2.46,"tv":8.72,"id":655}]}]}
{"op":"mcm","clk":"11827731516","pt":1723363763938,"mc":[{"id":"1.231582261","rc":[{"batb":[[0,2.42,12.68],[1,2.4,12.86],[2,2.34,29.13]],"ltp":2.46,"tv":8.72,"id":655}]}]}
{"op":"mcm","clk":"11827731582","pt":1723363765279,"mc":[{"id":"1.231582261","rc":[{"batb":[[0,2.44,4],[1,2.42,12.68],[2,2.4,12.86]],"ltp":2.46,"tv":8.72,"id":655}]}]}
{"op":"mcm","clk":"11827731662","pt":1723363767447,"mc":[{"id":"1.231582261","rc":[{"batb":[[0,2.42,12.68],[1,2.4,12.86],[2,2.34,29.13]],"ltp":2.46,"tv":8.72,"id":655}]}]}
{"op":"mcm","clk":"11827731676","pt":1723363767656,"mc":[{"id":"1.231582261","rc":[{"batb":[[0,2.46,10],[1,2.42,12.68],[2,2.4,12.86]],"ltp":2.46,"tv":8.72,"id":655}]}]}
{"op":"mcm","clk":"11827731882","pt":1723363771364,"mc":[{"id":"1.231582261","rc":[{"batb":[[0,2.48,4]],"ltp":2.46,"tv":8.72,"id":655}]}]}
{"op":"mcm","clk":"11827732012","pt":1723363773273,"mc":[{"id":"1.231582261","rc":[{"batb":[[0,2.42,12.68],[1,2.4,12.86],[2,2.34,29.13]],"ltp":2.46,"tv":8.72,"id":655}]}]}
{"op":"mcm","clk":"11827732037","pt":1723363773685,"mc":[{"id":"1.231582261","rc":[{"batb":[[0,2.44,10],[1,2.42,12.68],[2,2.4,12.86]],"ltp":2.46,"tv":8.72,"id":655}]}]}
{"op":"mcm","clk":"11827732120","pt":1723363775442,"mc":[{"id":"1.231582261","rc":[{"batb":[[0,2.46,4],[1,2.44,10],[2,2.42,12.68]],"ltp":2.46,"tv":8.72,"id":655}]}]}
{"op":"mcm","clk":"11827732200","pt":1723363776955,"mc":[{"id":"1.231582261","rc":[{"batb":[[1,2.42,12.68],[2,2.4,12.86]],"ltp":2.46,"tv":8.72,"id":655}]}]}
{"op":"mcm","clk":"11827732263","pt":1723363777883,"mc":[{"id":"1.231582261","rc":[{"batb":[[0,2.42,12.68],[1,2.4,12.86],[2,2.34,29.13]],"ltp":2.46,"tv":8.72,"id":655}]}]}
{"op":"mcm","clk":"11827732356","pt":1723363779483,"mc":[{"id":"1.231582261","rc":[{"batb":[[0,2.44,10],[1,2.42,12.68],[2,2.4,12.86]],"ltp":2.46,"tv":8.72,"id":655}]}]}
{"op":"mcm","clk":"11827732429","pt":1723363780674,"mc":[{"id":"1.231582261","rc":[{"batb":[[0,2.46,4],[1,2.44,10],[2,2.42,12.68]],"ltp":2.46,"tv":8.72,"id":655}]}]}
{"op":"mcm","clk":"11827732553","pt":1723363783055,"mc":[{"id":"1.231582261","rc":[{"batb":[[0,2.42,12.68],[1,2.4,12.86],[2,2.34,29.13]],"ltp":2.46,"tv":8.72,"id":655}]}]}
{"op":"mcm","clk":"11827732640","pt":1723363785274,"mc":[{"id":"1.231582261","rc":[{"batb":[[0,2.44,14],[1,2.42,12.68],[2,2.4,12.86]],"ltp":2.46,"tv":8.72,"id":655}]}]}
{"op":"mcm","clk":"11827732798","pt":1723363788463,"mc":[{"id":"1.231582261","rc":[{"batb":[[0,2.42,12.68],[1,2.4,12.86],[2,2.34,29.13]],"ltp":2.46,"tv":8.72,"id":655}]}]}
{"op":"mcm","clk":"11827733163","pt":1723363796193,"mc":[{"id":"1.231582261","rc":[{"batb":[[0,2.44,14],[1,2.42,12.68],[2,2.4,12.86]],"ltp":2.46,"tv":8.72,"id":655}]}]}
{"op":"mcm","clk":"11827733300","pt":1723363798779,"mc":[{"id":"1.231582261","rc":[{"batb":[[0,2.44,10]],"ltp":2.46,"tv":8.72,"id":655}]}]}
{"op":"mcm","clk":"11827733351","pt":1723363799704,"mc":[{"id":"1.231582261","rc":[{"batb":[[0,2.42,12.68],[1,2.4,12.86],[2,2.34,29.13]],"ltp":2.46,"tv":8.72,"id":655}]}]}
{"op":"mcm","clk":"11827733599","pt":1723363803503,"mc":[{"id":"1.231582261","rc":[{"batb":[[0,2.44,14],[1,2.42,12.68],[2,2.4,12.86]],"ltp":2.46,"tv":8.72,"id":655}]}]}
{"op":"mcm","clk":"11827733778","pt":1723363806106,"mc":[{"id":"1.231582261","rc":[{"batb":[[0,2.44,10]],"ltp":2.46,"tv":8.72,"id":655}]}]}
{"op":"mcm","clk":"11827733846","pt":1723363807191,"mc":[{"id":"1.231582261","rc":[{"batb":[[0,2.42,12.68],[1,2.4,12.86],[2,2.34,29.13]],"ltp":2.46,"tv":8.72,"id":655}]}]}
{"op":"mcm","clk":"11827734090","pt":1723363810805,"mc":[{"id":"1.231582261","rc":[{"batb":[[0,2.44,14],[1,2.42,12.68],[2,2.4,12.86]],"ltp":2.46,"tv":8.72,"id":655}]}]}
{"op":"mcm","clk":"11827734223","pt":1723363813285,"mc":[{"id":"1.231582261","rc":[{"batb":[[0,2.44,10]],"ltp":2.46,"tv":8.72,"id":655}]}]}
{"op":"mcm","clk":"11827734274","pt":1723363814408,"mc":[{"id":"1.231582261","rc":[{"batb":[[0,2.42,12.68],[1,2.4,12.86],[2,2.34,29.13]],"ltp":2.46,"tv":8.72,"id":655}]}]}
{"op":"mcm","clk":"11827734342","pt":1723363815592,"mc":[{"id":"1.231582261","rc":[{"batb":[[0,2.44,4],[1,2.42,12.68],[2,2.4,12.86]],"ltp":2.46,"tv":8.72,"id":655}]}]}
{"op":"mcm","clk":"11827734433","pt":1723363817035,"mc":[{"id":"1.231582261","rc":[{"batb":[[0,2.46,10],[1,2.44,4],[2,2.42,12.68]],"ltp":2.46,"tv":8.72,"id":655}]}]}
{"op":"mcm","clk":"11827734502","pt":1723363818121,"mc":[{"id":"1.231582261","rc":[{"batb":[[1,2.42,12.68],[2,2.4,12.86]],"ltp":2.46,"tv":8.72,"id":655}]}]}
{"op":"mcm","clk":"11827734621","pt":1723363820399,"mc":[{"id":"1.231582261","rc":[{"batb":[[0,2.44,4]],"ltp":2.46,"tv":8.72,"id":655}]}]}
{"op":"mcm","clk":"11827734736","pt":1723363823020,"mc":[{"id":"1.231582261","rc":[{"batb":[[0,2.44,10]],"ltp":2.46,"tv":8.72,"id":655}]}]}
{"op":"mcm","clk":"11827734875","pt":1723363826323,"mc":[{"id":"1.231582261","rc":[{"batb":[[0,2.46,4]],"ltp":2.46,"tv":8.72,"id":655}]}]}
{"op":"mcm","clk":"11827734997","pt":1723363829007,"mc":[{"id":"1.231582261","rc":[{"batb":[[0,2.42,12.68],[1,2.4,12.86],[2,2.34,29.13]],"ltp":2.46,"tv":8.72,"id":655}]}]}
{"op":"mcm","clk":"11827735012","pt":1723363829523,"mc":[{"id":"1.231582261","rc":[{"batb":[[0,2.48,10],[1,2.42,12.68],[2,2.4,12.86]],"ltp":2.46,"tv":8.72,"id":655}]}]}
{"op":"mcm","clk":"11827735158","pt":1723363833139,"mc":[{"id":"1.231582261","rc":[{"batb":[[0,2.44,4]],"ltp":2.46,"tv":8.72,"id":655}]}]}
{"op":"mcm","clk":"11827735225","pt":1723363835412,"mc":[{"id":"1.231582261","rc":[{"batb":[[0,2.42,12.68],[1,2.4,12.86],[2,2.34,29.13]],"ltp":2.46,"tv":8.72,"id":655}]}]}
{"op":"mcm","clk":"11827735235","pt":1723363835619,"mc":[{"id":"1.231582261","rc":[{"batb":[[0,2.44,10],[1,2.42,12.68],[2,2.4,12.86]],"ltp":2.46,"tv":8.72,"id":655}]}]}
{"op":"mcm","clk":"11827735359","pt":1723363839231,"mc":[{"id":"1.231582261","rc":[{"batb":[[0,2.44,4]],"ltp":2.46,"tv":8.72,"id":655}]}]}
{"op":"mcm","clk":"11827735543","pt":1723363842212,"mc":[{"id":"1.231582261","rc":[{"batb":[[0,2.44,10]],"ltp":2.46,"tv":8.72,"id":655}]}]}
{"op":"mcm","clk":"11827735628","pt":1723363844024,"mc":[{"id":"1.231582261","rc":[{"batb":[[0,2.46,4],[1,2.44,10],[2,2.42,12.68]],"ltp":2.46,"tv":8.72,"id":655}]}]}
{"op":"mcm","clk":"11827735734","pt":1723363846231,"mc":[{"id":"1.231582261","rc":[{"batb":[[0,2.42,12.68],[1,2.4,12.86],[2,2.34,29.13]],"ltp":2.46,"tv":8.72,"id":655}]}]}
{"op":"mcm","clk":"11827736068","pt":1723363853733,"mc":[{"id":"1.231582261","rc":[{"batb":[[0,2.44,14],[1,2.42,12.68],[2,2.4,12.86]],"ltp":2.46,"tv":8.72,"id":655}]}]}
{"op":"mcm","clk":"11827736164","pt":1723363856145,"mc":[{"id":"1.231582261","rc":[{"batb":[[0,2.44,10]],"ltp":2.46,"tv":8.72,"id":655}]}]}
{"op":"mcm","clk":"11827736206","pt":1723363856971,"mc":[{"id":"1.231582261","rc":[{"batb":[[0,2.42,12.68],[1,2.4,12.86],[2,2.34,29.13]],"ltp":2.46,"tv":8.72,"id":655}]}]}
{"op":"mcm","clk":"11827736270","pt":1723363858373,"mc":[{"id":"1.231582261","rc":[{"batb":[[0,2.44,4],[1,2.42,12.68],[2,2.4,12.86]],"ltp":2.46,"tv":8.72,"id":655}]}]}
{"op":"mcm","clk":"11827736372","pt":1723363860849,"mc":[{"id":"1.231582261","rc":[{"batb":[[0,2.44,10]],"ltp":2.46,"tv":8.72,"id":655}]}]}
{"op":"mcm","clk":"11827736537","pt":1723363864390,"mc":[{"id":"1.231582261","rc":[{"batb":[[0,2.44,4]],"ltp":2.46,"tv":8.72,"id":655}]}]}
{"op":"mcm","clk":"11827736633","pt":1723363866770,"mc":[{"id":"1.231582261","rc":[{"batb":[[0,2.44,10]],"ltp":2.46,"tv":8.72,"id":655}]}]}
{"op":"mcm","clk":"11827736789","pt":1723363870388,"mc":[{"id":"1.231582261","rc":[{"batb":[[0,2.46,4]],"ltp":2.46,"tv":8.72,"id":655}]}]}
{"op":"mcm","clk":"11827736879","pt":1723363872776,"mc":[{"id":"1.231582261","rc":[{"batb":[[0,2.42,12.68],[1,2.4,12.86],[2,2.34,29.13]],"ltp":2.46,"tv":8.72,"id":655}]}]}
{"op":"mcm","clk":"11827736902","pt":1723363873600,"mc":[{"id":"1.231582261","rc":[{"batb":[[0,2.44,10],[1,2.42,12.68],[2,2.4,12.86]],"ltp":2.46,"tv":8.72,"id":655}]}]}
{"op":"mcm","clk":"11827737001","pt":1723363876380,"mc":[{"id":"1.231582261","rc":[{"batb":[[0,2.46,4],[1,2.44,10],[2,2.42,12.68]],"ltp":2.46,"tv":8.72,"id":655}]}]}
{"op":"mcm","clk":"11827737034","pt":1723363877096,"mc":[{"id":"1.231582261","rc":[{"batb":[[1,2.42,12.68],[2,2.4,12.86]],"ltp":2.46,"tv":8.72,"id":655}]}]}
{"op":"mcm","clk":"11827737174","pt":1723363879487,"mc":[{"id":"1.231582261","rc":[{"batb":[[0,2.44,10]],"ltp":2.46,"tv":8.72,"id":655}]}]}
{"op":"mcm","clk":"11827737289","pt":1723363882212,"mc":[{"id":"1.231582261","rc":[{"batb":[[0,2.46,4],[1,2.44,10],[2,2.42,12.68]],"ltp":2.46,"tv":8.72,"id":655}]}]}
{"op":"mcm","clk":"11827737322","pt":1723363882783,"mc":[{"id":"1.231582261","rc":[{"batb":[[1,2.42,12.68],[2,2.4,12.86]],"ltp":2.46,"tv":8.72,"id":655}]}]}
{"op":"mcm","clk":"11827737421","pt":1723363885095,"mc":[{"id":"1.231582261","rc":[{"batb":[[0,2.44,10]],"ltp":2.46,"tv":8.72,"id":655}]}]}
{"op":"mcm","clk":"11827737497","pt":1723363887100,"mc":[{"id":"1.231582261","rc":[{"batb":[[0,2.46,4],[1,2.44,10],[2,2.42,12.68]],"ltp":2.46,"tv":8.72,"id":655}]}]}
{"op":"mcm","clk":"11827737554","pt":1723363888286,"mc":[{"id":"1.231582261","rc":[{"batb":[[1,2.42,12.68],[2,2.4,12.86]],"ltp":2.46,"tv":8.72,"id":655}]}]}
{"op":"mcm","clk":"11827737601","pt":1723363889477,"mc":[{"id":"1.231582261","rc":[{"batb":[[0,2.42,12.68],[1,2.4,12.86],[2,2.34,29.13]],"ltp":2.46,"tv":8.72,"id":655}]}]}
{"op":"mcm","clk":"11827737752","pt":1723363892679,"mc":[{"id":"1.231582261","rc":[{"batb":[[0,2.44,14],[1,2.42,12.68],[2,2.4,12.86]],"ltp":2.46,"tv":8.72,"id":655}]}]}
{"op":"mcm","clk":"11827737873","pt":1723363895300,"mc":[{"id":"1.231582261","rc":[{"batb":[[0,2.44,10]],"ltp":2.46,"tv":8.72,"id":655}]}]}
{"op":"mcm","clk":"11827737921","pt":1723363896284,"mc":[{"id":"1.231582261","rc":[{"batb":[[0,2.42,12.68],[1,2.4,12.86],[2,2.34,29.13]],"ltp":2.46,"tv":8.72,"id":655}]}]}
{"op":"mcm","clk":"11827737974","pt":1723363897415,"mc":[{"id":"1.231582261","rc":[{"batb":[[0,2.44,4],[1,2.42,12.68],[2,2.4,12.86]],"ltp":2.46,"tv":8.72,"id":655}]}]}
{"op":"mcm","clk":"11827738055","pt":1723363899298,"mc":[{"id":"1.231582261","rc":[{"batb":[[0,2.46,10],[1,2.44,4],[2,2.42,12.68]],"ltp":2.46,"tv":8.72,"id":655}]}]}
{"op":"mcm","clk":"11827738089","pt":1723363900121,"mc":[{"id":"1.231582261","rc":[{"batb":[[1,2.42,12.68],[2,2.4,12.86]],"ltp":2.46,"tv":8.72,"id":655}]}]}
{"op":"mcm","clk":"11827738210","pt":1723363902397,"mc":[{"id":"1.231582261","rc":[{"batb":[[0,2.48,4],[1,2.46,10],[2,2.42,12.68]],"ltp":2.46,"tv":8.72,"id":655}]}]}
{"op":"mcm","clk":"11827738221","pt":1723363902602,"mc":[{"id":"1.231582261","rc":[{"batb":[[1,2.42,12.68],[2,2.4,12.86]],"ltp":2.46,"tv":8.72,"id":655}]}]}
{"op":"mcm","clk":"11827738354","pt":1723363905304,"mc":[{"id":"1.231582261","rc":[{"batb":[[0,2.44,10]],"ltp":2.46,"tv":8.72,"id":655}]}]}
{"op":"mcm","clk":"11827738535","pt":1723363908717,"mc":[{"id":"1.231582261","rc":[{"batb":[[0,2.46,4]],"ltp":2.46,"tv":8.72,"id":655}]}]}
{"op":"mcm","clk":"11827738674","pt":1723363911405,"mc":[{"id":"1.231582261","rc":[{"batb":[[0,2.44,10]],"ltp":2.46,"tv":8.72,"id":655}]}]}
{"op":"mcm","clk":"11827738856","pt":1723363914820,"mc":[{"id":"1.231582261","rc":[{"batb":[[0,2.44,4]],"ltp":2.46,"tv":8.72,"id":655}]}]}
{"op":"mcm","clk":"11827738943","pt":1723363917136,"mc":[{"id":"1.231582261","rc":[{"batb":[[0,2.42,12.68],[1,2.4,12.86],[2,2.34,29.13]],"ltp":2.46,"tv":8.72,"id":655}]}]}
{"op":"mcm","clk":"11827738979","pt":1723363917807,"mc":[{"id":"1.231582261","rc":[{"batb":[[0,2.44,10],[1,2.42,12.68],[2,2.4,12.86]],"ltp":2.46,"tv":8.72,"id":655}]}]}
{"op":"mcm","clk":"11827739141","pt":1723363921137,"mc":[{"id":"1.231582261","rc":[{"batb":[[0,2.46,4]],"ltp":2.46,"tv":8.72,"id":655}]}]}
{"op":"mcm","clk":"11827739327","pt":1723363923854,"mc":[{"id":"1.231582261","rc":[{"batb":[[0,2.44,10]],"ltp":2.46,"tv":8.72,"id":655}]}]}
{"op":"mcm","clk":"11827739634","pt":1723363929347,"mc":[{"id":"1.231582261","rc":[{"batb":[[0,2.46,4]],"ltp":2.46,"tv":8.72,"id":655}]}]}
{"op":"mcm","clk":"11827739768","pt":1723363931348,"mc":[{"id":"1.231582261","rc":[{"batb":[[0,2.48,10],[1,2.46,4],[2,2.42,12.68]],"ltp":2.46,"tv":8.72,"id":655}]}]}
{"op":"mcm","clk":"11827739825","pt":1723363932130,"mc":[{"id":"1.231582261","rc":[{"batb":[[1,2.42,12.68],[2,2.4,12.86]],"ltp":2.46,"tv":8.72,"id":655}]}]}
{"op":"mcm","clk":"11827740084","pt":1723363935359,"mc":[{"id":"1.231582261","rc":[{"batb":[[0,2.42,12.68],[1,2.4,12.86],[2,2.34,29.13]],"ltp":2.46,"tv":8.72,"id":655}]}]}
{"op":"mcm","clk":"11827740106","pt":1723363935627,"mc":[{"id":"1.231582261","rc":[{"batb":[[0,2.44,4],[1,2.42,12.68],[2,2.4,12.86]],"ltp":2.46,"tv":8.72,"id":655}]}]}
{"op":"mcm","clk":"11827740262","pt":1723363937945,"mc":[{"id":"1.231582261","rc":[{"batb":[[0,2.42,12.68],[1,2.4,12.86],[2,2.34,29.13]],"ltp":2.46,"tv":8.72,"id":655}]}]}
{"op":"mcm","clk":"11827740290","pt":1723363938516,"mc":[{"id":"1.231582261","rc":[{"batb":[[0,2.44,10],[1,2.42,12.68],[2,2.4,12.86]],"ltp":2.46,"tv":8.72,"id":655}]}]}
{"op":"mcm","clk":"11827740494","pt":1723363941335,"mc":[{"id":"1.231582261","rc":[{"batb":[[0,2.46,4],[1,2.44,10],[2,2.42,12.68]],"ltp":2.46,"tv":8.72,"id":655}]}]}
{"op":"mcm","clk":"11827740573","pt":1723363942127,"mc":[{"id":"1.231582261","rc":[{"batb":[[1,2.42,12.68],[2,2.4,12.86]],"ltp":2.46,"tv":8.72,"id":655}]}]}
{"op":"mcm","clk":"11827740687","pt":1723363943845,"mc":[{"id":"1.231582261","rc":[{"batb":[[0,2.42,12.68],[1,2.4,12.86],[2,2.34,29.13]],"ltp":2.46,"tv":8.72,"id":655}]}]}
{"op":"mcm","clk":"11827740730","pt":1723363945032,"mc":[{"id":"1.231582261","rc":[{"batb":[[0,2.44,10],[1,2.42,12.68],[2,2.4,12.86]],"ltp":2.46,"tv":8.72,"id":655}]}]}
{"op":"mcm","clk":"11827740824","pt":1723363947142,"mc":[{"id":"1.231582261","rc":[{"batb":[[0,2.46,4],[1,2.44,10],[2,2.42,12.68]],"ltp":2.46,"tv":8.72,"id":655}]}]}
{"op":"mcm","clk":"11827740901","pt":1723363948428,"mc":[{"id":"1.231582261","rc":[{"batb":[[1,2.42,12.68],[2,2.4,12.86]],"ltp":2.46,"tv":8.72,"id":655}]}]}
{"op":"mcm","clk":"11827740960","pt":1723363949559,"mc":[{"id":"1.231582261","rc":[{"batb":[[0,2.42,12.68],[1,2.4,12.86],[2,2.34,29.13]],"ltp":2.46,"tv":8.72,"id":655}]}]}
{"op":"mcm","clk":"11827741125","pt":1723363952452,"mc":[{"id":"1.231582261","rc":[{"batb":[[0,2.44,14],[1,2.42,12.68],[2,2.4,12.86]],"ltp":2.46,"tv":8.72,"id":655}]}]}
{"op":"mcm","clk":"11827741250","pt":1723363954778,"mc":[{"id":"1.231582261","rc":[{"batb":[[0,2.44,10]],"ltp":2.46,"tv":8.72,"id":655}]}]}
{"op":"mcm","clk":"11827741292","pt":1723363955653,"mc":[{"id":"1.231582261","rc":[{"batb":[[0,2.42,12.68],[1,2.4,12.86],[2,2.34,29.13]],"ltp":2.46,"tv":8.72,"id":655}]}]}
{"op":"mcm","clk":"11827741375","pt":1723363957450,"mc":[{"id":"1.231582261","rc":[{"batb":[[0,2.44,4],[1,2.42,12.68],[2,2.4,12.86]],"ltp":2.46,"tv":8.72,"id":655}]}]}
{"op":"mcm","clk":"11827741547","pt":1723363960445,"mc":[{"id":"1.231582261","rc":[{"batb":[[0,2.44,10]],"ltp":2.46,"tv":8.72,"id":655}]}]}
{"op":"mcm","clk":"11827741668","pt":1723363962772,"mc":[{"id":"1.231582261","rc":[{"batb":[[0,2.46,4],[1,2.44,10],[2,2.42,12.68]],"ltp":2.46,"tv":8.72,"id":655}]}]}
{"op":"mcm","clk":"11827741718","pt":1723363963858,"mc":[{"id":"1.231582261","rc":[{"batb":[[1,2.42,12.68],[2,2.4,12.86]],"ltp":2.46,"tv":8.72,"id":655}]}]}
{"op":"mcm","clk":"11827741785","pt":1723363965139,"mc":[{"id":"1.231582261","rc":[{"batb":[[0,2.42,12.68],[1,2.4,12.86],[2,2.34,29.13]],"ltp":2.46,"tv":8.72,"id":655}]}]}
{"op":"mcm","clk":"11827741901","pt":1723363967564,"mc":[{"id":"1.231582261","rc":[{"batb":[[0,2.44,14],[1,2.42,12.68],[2,2.4,12.86]],"ltp":2.46,"tv":8.72,"id":655}]}]}
{"op":"mcm","clk":"11827742034","pt":1723363969895,"mc":[{"id":"1.231582261","rc":[{"batb":[[0,2.44,10]],"ltp":2.46,"tv":8.72,"id":655}]}]}
{"op":"mcm","clk":"11827742077","pt":1723363970979,"mc":[{"id":"1.231582261","rc":[{"batb":[[0,2.42,12.68],[1,2.4,12.86],[2,2.34,29.13]],"ltp":2.46,"tv":8.72,"id":655}]}]}
{"op":"mcm","clk":"11827742131","pt":1723363972167,"mc":[{"id":"1.231582261","rc":[{"batb":[[0,2.44,4],[1,2.42,12.68],[2,2.4,12.86]],"ltp":2.46,"tv":8.72,"id":655}]}]}
{"op":"mcm","clk":"11827742240","pt":1723363973966,"mc":[{"id":"1.231582261","rc":[{"batb":[[0,2.46,10],[1,2.44,4],[2,2.42,12.68]],"ltp":2.46,"tv":8.72,"id":655}]}]}
{"op":"mcm","clk":"11827742268","pt":1723363974684,"mc":[{"id":"1.231582261","rc":[{"batb":[[1,2.42,12.68],[2,2.4,12.86]],"ltp":2.46,"tv":8.72,"id":655}]}]}
{"op":"mcm","clk":"11827742399","pt":1723363977411,"mc":[{"id":"1.231582261","rc":[{"batb":[[0,2.44,4]],"ltp":2.46,"tv":8.72,"id":655}]}]}
{"op":"mcm","clk":"11827742536","pt":1723363979774,"mc":[{"id":"1.231582261","rc":[{"batb":[[0,2.44,10]],"ltp":2.46,"tv":8.72,"id":655}]}]}
{"op":"mcm","clk":"11827742669","pt":1723363982270,"mc":[{"id":"1.231582261","rc":[{"batb":[[0,2.46,4],[1,2.44,10],[2,2.42,12.68]],"ltp":2.46,"tv":8.72,"id":655}]}]}
{"op":"mcm","clk":"11827742703","pt":1723363982992,"mc":[{"id":"1.231582261","rc":[{"batb":[[1,2.42,12.68],[2,2.4,12.86]],"ltp":2.46,"tv":8.72,"id":655}]}]}
{"op":"mcm","clk":"11827742796","pt":1723363984488,"mc":[{"id":"1.231582261","rc":[{"batb":[[0,2.42,12.68],[1,2.4,12.86],[2,2.34,29.13]],"ltp":2.46,"tv":8.72,"id":655}]}]}
{"op":"mcm","clk":"11827743113","pt":1723363990400,"mc":[{"id":"1.231582261","rc":[{"batb":[[0,2.44,14],[1,2.42,12.68],[2,2.4,12.86]],"ltp":2.46,"tv":8.72,"id":655}]}]}
{"op":"mcm","clk":"11827743243","pt":1723363992989,"mc":[{"id":"1.231582261","rc":[{"batb":[[0,2.44,10]],"ltp":2.46,"tv":8.72,"id":655}]}]}
{"op":"mcm","clk":"11827743278","pt":1723363993910,"mc":[{"id":"1.231582261","rc":[{"batb":[[0,2.42,12.68],[1,2.4,12.86],[2,2.34,29.13]],"ltp":2.46,"tv":8.72,"id":655}]}]}
{"op":"mcm","clk":"11827743413","pt":1723363996383,"mc":[{"id":"1.231582261","rc":[{"batb":[[0,2.44,14],[1,2.42,12.68],[2,2.4,12.86]],"ltp":2.46,"tv":8.72,"id":655}]}]}
{"op":"mcm","clk":"11827743578","pt":1723363998911,"mc":[{"id":"1.231582261","rc":[{"batb":[[0,2.44,10]],"ltp":2.46,"tv":8.72,"id":655}]}]}
{"op":"mcm","clk":"11827743626","pt":1723363999899,"mc":[{"id":"1.231582261","rc":[{"batb":[[0,2.42,12.68],[1,2.4,12.86],[2,2.34,29.13]],"ltp":2.46,"tv":8.72,"id":655}]}]}
{"op":"mcm","clk":"11827743770","pt":1723364002109,"mc":[{"id":"1.231582261","rc":[{"batb":[[0,2.44,14],[1,2.42,12.68],[2,2.4,12.86]],"ltp":2.46,"tv":8.72,"id":655}]}]}
{"op":"mcm","clk":"11827743915","pt":1723364004494,"mc":[{"id":"1.231582261","rc":[{"batb":[[0,2.44,10]],"ltp":2.46,"tv":8.72,"id":655}]}]}
{"op":"mcm","clk":"11827743960","pt":1723364005416,"mc":[{"id":"1.231582261","rc":[{"batb":[[0,2.42,12.68],[1,2.4,12.86],[2,2.34,29.13]],"ltp":2.46,"tv":8.72,"id":655}]}]}
{"op":"mcm","clk":"11827744064","pt":1723364007628,"mc":[{"id":"1.231582261","rc":[{"batb":[[0,2.44,14],[1,2.42,12.68],[2,2.4,12.86]],"ltp":2.46,"tv":8.72,"id":655}]}]}
{"op":"mcm","clk":"11827744188","pt":1723364010210,"mc":[{"id":"1.231582261","rc":[{"batb":[[0,2.44,10]],"ltp":2.46,"tv":8.72,"id":655}]}]}
{"op":"mcm","clk":"11827744246","pt":1723364011337,"mc":[{"id":"1.231582261","rc":[{"batb":[[0,2.42,12.68],[1,2.4,12.86],[2,2.34,29.13]],"ltp":2.46,"tv":8.72,"id":655}]}]}
{"op":"mcm","clk":"11827744337","pt":1723364013240,"mc":[{"id":"1.231582261","rc":[{"batb":[[0,2.44,4],[1,2.42,12.68],[2,2.4,12.86]],"ltp":2.46,"tv":8.72,"id":655}]}]}
{"op":"mcm","clk":"11827744363","pt":1723364013707,"mc":[{"id":"1.231582261","rc":[{"batb":[[0,2.46,10],[1,2.44,4],[2,2.42,12.68]],"ltp":2.46,"tv":8.72,"id":655}]}]}
{"op":"mcm","clk":"11827744480","pt":1723364015829,"mc":[{"id":"1.231582261","rc":[{"batb":[[1,2.42,12.68],[2,2.4,12.86]],"ltp":2.46,"tv":8.72,"id":655}]}]}
{"op":"mcm","clk":"11827744560","pt":1723364017122,"mc":[{"id":"1.231582261","rc":[{"batb":[[0,2.42,12.68],[1,2.4,12.86],[2,2.34,29.13]],"ltp":2.46,"tv":8.72,"id":655}]}]}
{"op":"mcm","clk":"11827744723","pt":1723364019806,"mc":[{"id":"1.231582261","rc":[{"batb":[[0,2.44,14],[1,2.42,12.68],[2,2.4,12.86]],"ltp":2.46,"tv":8.72,"id":655}]}]}
{"op":"mcm","clk":"11827744938","pt":1723364023506,"mc":[{"id":"1.231582261","rc":[{"batb":[[0,2.42,12.68],[1,2.4,12.86],[2,2.34,29.13]],"ltp":2.46,"tv":8.72,"id":655}]}]}
{"op":"mcm","clk":"11827745013","pt":1723364025039,"mc":[{"id":"1.231582261","rc":[{"batb":[[0,2.44,4],[1,2.42,12.68],[2,2.4,12.86]],"ltp":2.46,"tv":8.72,"id":655}]}]}
{"op":"mcm","clk":"11827745151","pt":1723364027414,"mc":[{"id":"1.231582261","rc":[{"batb":[[0,2.42,12.68],[1,2.4,12.86],[2,2.34,29.13]],"ltp":2.46,"tv":8.72,"id":655}]}]}
{"op":"mcm","clk":"11827745178","pt":1723364027823,"mc":[{"id":"1.231582261","rc":[{"batb":[[0,2.44,10],[1,2.42,12.68],[2,2.4,12.86]],"ltp":2.46,"tv":8.72,"id":655}]}]}
{"op":"mcm","clk":"11827745386","pt":1723364030709,"mc":[{"id":"1.231582261","rc":[{"batb":[[0,2.46,4],[1,2.44,10],[2,2.42,12.68]],"ltp":2.46,"tv":8.72,"id":655}]}]}
{"op":"mcm","clk":"11827745455","pt":1723364031943,"mc":[{"id":"1.231582261","rc":[{"batb":[[1,2.42,12.68],[2,2.4,12.86]],"ltp":2.46,"tv":8.72,"id":655}]}]}
{"op":"mcm","clk":"11827745531","pt":1723364033022,"mc":[{"id":"1.231582261","rc":[{"batb":[[0,2.42,12.68],[1,2.4,12.86],[2,2.34,29.13]],"ltp":2.46,"tv":8.72,"id":655}]}]}
{"op":"mcm","clk":"11827745621","pt":1723364034560,"mc":[{"id":"1.231582261","rc":[{"batb":[[0,2.44,10],[1,2.42,12.68],[2,2.4,12.86]],"ltp":2.46,"tv":8.72,"id":655}]}]}
{"op":"mcm","clk":"11827745760","pt":1723364036846,"mc":[{"id":"1.231582261","rc":[{"batb":[[0,2.46,4],[1,2.44,10],[2,2.42,12.68]],"ltp":2.46,"tv":8.72,"id":655}]}]}
{"op":"mcm","clk":"11827745809","pt":1723364037828,"mc":[{"id":"1.231582261","rc":[{"batb":[[1,2.42,12.68],[2,2.4,12.86]],"ltp":2.46,"tv":8.72,"id":655}]}]}
{"op":"mcm","clk":"11827745875","pt":1723364039360,"mc":[{"id":"1.231582261","rc":[{"trd":[[1.64,6]],"batb":[[0,1.64,59]],"ltp":1.64,"tv":216.42,"id":2120}],"tv":225.14}]}
{"op":"mcm","clk":"11827745924","pt":1723364040459,"mc":[{"id":"1.231582261","rc":[{"batb":[[0,2.42,12.68],[1,2.4,12.86],[2,2.34,29.13]],"ltp":2.46,"tv":8.72,"id":655},{"batb":[[0,1.64,61]],"ltp":1.64,"tv":216.42,"id":2120}]}]}
{"op":"mcm","clk":"11827745942","pt":1723364040666,"mc":[{"id":"1.231582261","rc":[{"batb":[[0,2.44,10],[1,2.42,12.68],[2,2.4,12.86]],"ltp":2.46,"tv":8.72,"id":655}]}]}
{"op":"mcm","clk":"11827746059","pt":1723364042427,"mc":[{"id":"1.231582261","rc":[{"batb":[[0,2.46,4],[1,2.44,10],[2,2.42,12.68]],"ltp":2.46,"tv":8.72,"id":655}]}]}
{"op":"mcm","clk":"11827746195","pt":1723364044245,"mc":[{"id":"1.231582261","rc":[{"batb":[[1,2.42,12.68],[2,2.4,12.86]],"ltp":2.46,"tv":8.72,"id":655}]}]}
{"op":"mcm","clk":"11827746222","pt":1723364044770,"mc":[{"id":"1.231582261","rc":[{"batb":[[0,2.42,12.68],[1,2.4,12.86],[2,2.34,29.13]],"ltp":2.46,"tv":8.72,"id":655}]}]}
{"op":"mcm","clk":"11827746664","pt":1723364052528,"mc":[{"id":"1.231582261","rc":[{"batb":[[0,2.44,14],[1,2.42,12.68],[2,2.4,12.86]],"ltp":2.46,"tv":8.72,"id":655}]}]}
{"op":"mcm","clk":"11827746799","pt":1723364054951,"mc":[{"id":"1.231582261","rc":[{"batb":[[0,2.44,10]],"ltp":2.46,"tv":8.72,"id":655}]}]}
{"op":"mcm","clk":"11827746865","pt":1723364055972,"mc":[{"id":"1.231582261","rc":[{"batb":[[0,2.42,12.68],[1,2.4,12.86],[2,2.34,29.13]],"ltp":2.46,"tv":8.72,"id":655}]}]}
{"op":"mcm","clk":"11827746964","pt":1723364057474,"mc":[{"id":"1.231582261","rc":[{"batb":[[0,2.44,4],[1,2.42,12.68],[2,2.4,12.86]],"ltp":2.46,"tv":8.72,"id":655}]}]}
{"op":"mcm","clk":"11827747073","pt":1723364058982,"mc":[{"id":"1.231582261","rc":[{"batb":[[0,2.46,10],[1,2.44,4],[2,2.42,12.68]],"ltp":2.46,"tv":8.72,"id":655}]}]}
{"op":"mcm","clk":"11827747124","pt":1723364059959,"mc":[{"id":"1.231582261","rc":[{"batb":[[1,2.42,12.68],[2,2.4,12.86]],"ltp":2.46,"tv":8.72,"id":655}]}]}
{"op":"mcm","clk":"11827747263","pt":1723364062477,"mc":[{"id":"1.231582261","rc":[{"batb":[[0,2.42,12.68],[1,2.4,12.86],[2,2.34,29.13]],"ltp":2.46,"tv":8.72,"id":655}]}]}
{"op":"mcm","clk":"11827747299","pt":1723364063045,"mc":[{"id":"1.231582261","rc":[{"batb":[[0,2.44,4],[1,2.42,12.68],[2,2.4,12.86]],"ltp":2.46,"tv":8.72,"id":655}]}]}
{"op":"mcm","clk":"11827747432","pt":1723364065365,"mc":[{"id":"1.231582261","rc":[{"batb":[[0,2.46,10],[1,2.44,4],[2,2.42,12.68]],"ltp":2.46,"tv":8.72,"id":655}]}]}
{"op":"mcm","clk":"11827747447","pt":1723364065672,"mc":[{"id":"1.231582261","rc":[{"batb":[[1,2.42,12.68],[2,2.4,12.86]],"ltp":2.46,"tv":8.72,"id":655}]}]}
{"op":"mcm","clk":"11827747649","pt":1723364069464,"mc":[{"id":"1.231582261","rc":[{"batb":[[0,2.44,4]],"ltp":2.46,"tv":8.72,"id":655}]}]}
{"op":"mcm","clk":"11827747816","pt":1723364072393,"mc":[{"id":"1.231582261","rc":[{"batb":[[0,2.44,10]],"ltp":2.46,"tv":8.72,"id":655}]}]}
{"op":"mcm","clk":"11827747992","pt":1723364075283,"mc":[{"id":"1.231582261","rc":[{"batb":[[0,2.46,4],[1,2.44,10],[2,2.42,12.68]],"ltp":2.46,"tv":8.72,"id":655}]}]}
{"op":"mcm","clk":"11827748046","pt":1723364076164,"mc":[{"id":"1.231582261","rc":[{"batb":[[1,2.42,12.68],[2,2.4,12.86]],"ltp":2.46,"tv":8.72,"id":655}]}]}
{"op":"mcm","clk":"11827748134","pt":1723364077866,"mc":[{"id":"1.231582261","rc":[{"batb":[[0,2.42,12.68],[1,2.4,12.86],[2,2.34,29.13]],"ltp":2.46,"tv":8.72,"id":655}]}]}
{"op":"mcm","clk":"11827748265","pt":1723364080587,"mc":[{"id":"1.231582261","rc":[{"batb":[[0,2.44,14],[1,2.42,12.68],[2,2.4,12.86]],"ltp":2.46,"tv":8.72,"id":655}]}]}
{"op":"mcm","clk":"11827748393","pt":1723364083001,"mc":[{"id":"1.231582261","rc":[{"batb":[[0,2.44,10]],"ltp":2.46,"tv":8.72,"id":655}]}]}
{"op":"mcm","clk":"11827748445","pt":1723364083989,"mc":[{"id":"1.231582261","rc":[{"batb":[[0,2.42,12.68],[1,2.4,12.86],[2,2.34,29.13]],"ltp":2.46,"tv":8.72,"id":655}]}]}
{"op":"mcm","clk":"11827748499","pt":1723364085172,"mc":[{"id":"1.231582261","rc":[{"batb":[[0,2.44,4],[1,2.42,12.68],[2,2.4,12.86]],"ltp":2.46,"tv":8.72,"id":655}]}]}
{"op":"mcm","clk":"11827748615","pt":1723364087478,"mc":[{"id":"1.231582261","rc":[{"batb":[[0,2.44,10]],"ltp":2.46,"tv":8.72,"id":655}]}]}
{"op":"mcm","clk":"11827748735","pt":1723364089897,"mc":[{"id":"1.231582261","rc":[{"batb":[[0,2.46,4],[1,2.44,10],[2,2.42,12.68]],"ltp":2.46,"tv":8.72,"id":655}]}]}
{"op":"mcm","clk":"11827748805","pt":1723364090880,"mc":[{"id":"1.231582261","rc":[{"batb":[[1,2.42,12.68],[2,2.4,12.86]],"ltp":2.46,"tv":8.72,"id":655}]}]}
{"op":"mcm","clk":"11827748895","pt":1723364092398,"mc":[{"id":"1.231582261","rc":[{"batb":[[0,2.42,12.68],[1,2.4,12.86],[2,2.34,29.13]],"ltp":2.46,"tv":8.72,"id":655}]}]}
{"op":"mcm","clk":"11827749020","pt":1723364094694,"mc":[{"id":"1.231582261","rc":[{"batb":[[0,2.44,14],[1,2.42,12.68],[2,2.4,12.86]],"ltp":2.46,"tv":8.72,"id":655}]}]}
{"op":"mcm","clk":"11827749146","pt":1723364097107,"mc":[{"id":"1.231582261","rc":[{"batb":[[0,2.44,10]],"ltp":2.46,"tv":8.72,"id":655}]}]}
{"op":"mcm","clk":"11827749194","pt":1723364097876,"mc":[{"id":"1.231582261","rc":[{"batb":[[0,2.42,12.68],[1,2.4,12.86],[2,2.34,29.13]],"ltp":2.46,"tv":8.72,"id":655}]}]}
{"op":"mcm","clk":"11827749696","pt":1723364104796,"mc":[{"id":"1.231582261","rc":[{"batb":[[0,2.44,14],[1,2.42,12.68],[2,2.4,12.86]],"ltp":2.46,"tv":8.72,"id":655}]}]}
{"op":"mcm","clk":"11827749864","pt":1723364107292,"mc":[{"id":"1.231582261","rc":[{"batb":[[0,2.44,10]],"ltp":2.46,"tv":8.72,"id":655}]}]}
{"op":"mcm","clk":"11827749943","pt":1723364108334,"mc":[{"id":"1.231582261","rc":[{"batb":[[0,2.42,12.68],[1,2.4,12.86],[2,2.34,29.13]],"ltp":2.46,"tv":8.72,"id":655}]}]}
{"op":"mcm","clk":"11827750031","pt":1723364109792,"mc":[{"id":"1.231582261","rc":[{"batb":[[0,2.44,4],[1,2.42,12.68],[2,2.4,12.86]],"ltp":2.46,"tv":8.72,"id":655}]}]}
{"op":"mcm","clk":"11827750179","pt":1723364112221,"mc":[{"id":"1.231582261","rc":[{"batb":[[0,2.46,10]],"ltp":2.46,"tv":8.72,"id":655}]}]}
{"op":"mcm","clk":"11827750376","pt":1723364115110,"mc":[{"id":"1.231582261","rc":[{"batb":[[0,2.48,4]],"ltp":2.46,"tv":8.72,"id":655}]}]}
{"op":"mcm","clk":"11827750580","pt":1723364117697,"mc":[{"id":"1.231582261","rc":[{"batb":[[0,2.5,10]],"ltp":2.46,"tv":8.72,"id":655}]}]}
{"op":"mcm","clk":"11827750775","pt":1723364121039,"mc":[{"id":"1.231582261","rc":[{"batb":[[0,2.52,4]],"ltp":2.46,"tv":8.72,"id":655}]}]}
{"op":"mcm","clk":"11827750874","pt":1723364122840,"mc":[{"id":"1.231582261","rc":[{"batb":[[0,2.42,12.68],[1,2.4,12.86],[2,2.34,29.13]],"ltp":2.46,"tv":8.72,"id":655}]}]}
{"op":"mcm","clk":"11827751007","pt":1723364124806,"mc":[{"id":"1.231582261","rc":[{"batb":[[0,2.44,10],[1,2.42,12.68],[2,2.4,12.86]],"ltp":2.46,"tv":8.72,"id":655}]}]}
{"op":"mcm","clk":"11827751075","pt":1723364126149,"mc":[{"id":"1.231582261","rc":[{"batb":[[0,2.46,4],[1,2.44,10],[2,2.42,12.68]],"ltp":2.46,"tv":8.72,"id":655}]}]}
{"op":"mcm","clk":"11827751178","pt":1723364128110,"mc":[{"id":"1.231582261","rc":[{"batb":[[1,2.42,12.68],[2,2.4,12.86]],"ltp":2.46,"tv":8.72,"id":655}]}]}
{"op":"mcm","clk":"11827751202","pt":1723364128625,"mc":[{"id":"1.231582261","rc":[{"batb":[[0,2.42,12.68],[1,2.4,12.86],[2,2.34,29.13]],"ltp":2.46,"tv":8.72,"id":655}]}]}
{"op":"mcm","clk":"11827751323","pt":1723364130914,"mc":[{"id":"1.231582261","rc":[{"batb":[[0,2.46,4],[1,2.44,10],[2,2.42,12.68]],"ltp":2.46,"tv":8.72,"id":655}]}]}
{"op":"mcm","clk":"11827751464","pt":1723364133349,"mc":[{"id":"1.231582261","rc":[{"batb":[[0,2.44,10],[1,2.42,12.68],[2,2.4,12.86]],"ltp":2.46,"tv":8.72,"id":655}]}]}
{"op":"mcm","clk":"11827751522","pt":1723364134124,"mc":[{"id":"1.231582261","rc":[{"batb":[[0,2.42,12.68],[1,2.4,12.86],[2,2.34,29.13]],"ltp":2.46,"tv":8.72,"id":655}]}]}
{"op":"mcm","clk":"11827751615","pt":1723364135728,"mc":[{"id":"1.231582261","rc":[{"batb":[[0,2.44,4],[1,2.42,12.68],[2,2.4,12.86]],"ltp":2.46,"tv":8.72,"id":655}]}]}
{"op":"mcm","clk":"11827751722","pt":1723364137438,"mc":[{"id":"1.231582261","rc":[{"batb":[[0,2.46,10],[1,2.44,4],[2,2.42,12.68]],"ltp":2.46,"tv":8.72,"id":655}]}]}
{"op":"mcm","clk":"11827751765","pt":1723364138217,"mc":[{"id":"1.231582261","rc":[{"batb":[[1,2.42,12.68],[2,2.4,12.86]],"ltp":2.46,"tv":8.72,"id":655}]}]}
{"op":"mcm","clk":"11827751935","pt":1723364141322,"mc":[{"id":"1.231582261","rc":[{"batb":[[0,2.44,4]],"ltp":2.46,"tv":8.72,"id":655}]}]}
{"op":"mcm","clk":"11827752098","pt":1723364143954,"mc":[{"id":"1.231582261","rc":[{"batb":[[0,2.46,10]],"ltp":2.46,"tv":8.72,"id":655}]}]}
{"op":"mcm","clk":"11827752316","pt":1723364147355,"mc":[{"id":"1.231582261","rc":[{"batb":[[0,2.44,4]],"ltp":2.46,"tv":8.72,"id":655}]}]}
{"op":"mcm","clk":"11827752460","pt":1723364150253,"mc":[{"id":"1.231582261","rc":[{"batb":[[0,2.44,10]],"ltp":2.46,"tv":8.72,"id":655}]}]}
{"op":"mcm","clk":"11827752630","pt":1723364153448,"mc":[{"id":"1.231582261","rc":[{"batb":[[0,2.42,12.68],[1,2.4,12.86],[2,2.34,29.13]],"ltp":2.46,"tv":8.72,"id":655}]}]}
{"op":"mcm","clk":"11827752650","pt":1723364153765,"mc":[{"id":"1.231582261","rc":[{"batb":[[0,2.44,4],[1,2.42,12.68],[2,2.4,12.86]],"ltp":2.46,"tv":8.72,"id":655}]}]}
{"op":"mcm","clk":"11827752815","pt":1723364156344,"mc":[{"id":"1.231582261","rc":[{"batb":[[0,2.46,10]],"ltp":2.46,"tv":8.72,"id":655}]}]}
{"op":"mcm","clk":"11827753050","pt":1723364160265,"mc":[{"id":"1.231582261","rc":[{"batb":[[0,2.44,4]],"ltp":2.46,"tv":8.72,"id":655}]}]}
{"op":"mcm","clk":"11827753257","pt":1723364162764,"mc":[{"id":"1.231582261","rc":[{"batb":[[0,2.44,10]],"ltp":2.46,"tv":8.72,"id":655}]}]}
{"op":"mcm","clk":"11827753461","pt":1723364166084,"mc":[{"id":"1.231582261","rc":[{"batb":[[0,2.46,4]],"ltp":2.46,"tv":8.72,"id":655}]}]}
{"op":"mcm","clk":"11827753558","pt":1723364167885,"mc":[{"id":"1.231582261","rc":[{"batb":[[0,2.42,12.68],[1,2.4,12.86],[2,2.34,29.13]],"ltp":2.46,"tv":8.72,"id":655}]}]}
{"op":"mcm","clk":"11827753750","pt":1723364171488,"mc":[{"id":"1.231582261","rc":[{"batb":[[0,2.44,10],[1,2.42,12.68],[2,2.4,12.86]],"ltp":2.46,"tv":8.72,"id":655}]}]}
{"op":"mcm","clk":"11827753759","pt":1723364171591,"mc":[{"id":"1.231582261","rc":[{"batb":[[0,2.44,14]],"ltp":2.46,"tv":8.72,"id":655}]}]}
{"op":"mcm","clk":"11827753912","pt":1723364174282,"mc":[{"id":"1.231582261","rc":[{"batb":[[0,2.44,10]],"ltp":2.46,"tv":8.72,"id":655}]}]}
{"op":"mcm","clk":"11827753957","pt":1723364175059,"mc":[{"id":"1.231582261","rc":[{"batb":[[0,2.42,12.68],[1,2.4,12.86],[2,2.34,29.13]],"ltp":2.46,"tv":8.72,"id":655}]}]}
{"op":"mcm","clk":"11827754059","pt":1723364176664,"mc":[{"id":"1.231582261","rc":[{"batb":[[0,2.44,4],[1,2.42,12.68],[2,2.4,12.86]],"ltp":2.46,"tv":8.72,"id":655}]}]}
{"op":"mcm","clk":"11827754150","pt":1723364177950,"mc":[{"id":"1.231582261","rc":[{"batb":[[0,2.46,10],[1,2.44,4],[2,2.42,12.68]],"ltp":2.46,"tv":8.72,"id":655}]}]}
{"op":"mcm","clk":"11827754215","pt":1723364179164,"mc":[{"id":"1.231582261","rc":[{"batb":[[1,2.42,12.68],[2,2.4,12.86]],"ltp":2.46,"tv":8.72,"id":655}]}]}
{"op":"mcm","clk":"11827754328","pt":1723364181372,"mc":[{"id":"1.231582261","rc":[{"batb":[[0,2.44,4]],"ltp":2.46,"tv":8.72,"id":655}]}]}
{"op":"mcm","clk":"11827754508","pt":1723364184155,"mc":[{"id":"1.231582261","rc":[{"batb":[[0,2.44,10]],"ltp":2.46,"tv":8.72,"id":655}]}]}
{"op":"mcm","clk":"11827754645","pt":1723364186470,"mc":[{"id":"1.231582261","rc":[{"batb":[[0,2.46,4],[1,2.44,10],[2,2.42,12.68]],"ltp":2.46,"tv":8.72,"id":655}]}]}
{"op":"mcm","clk":"11827754698","pt":1723364187395,"mc":[{"id":"1.231582261","rc":[{"batb":[[1,2.42,12.68],[2,2.4,12.86]],"ltp":2.46,"tv":8.72,"id":655}]}]}
{"op":"mcm","clk":"11827754797","pt":1723364188689,"mc":[{"id":"1.231582261","rc":[{"batb":[[0,2.42,12.68],[1,2.4,12.86],[2,2.34,29.13]],"ltp":2.46,"tv":8.72,"id":655}]}]}
{"op":"mcm","clk":"11827754959","pt":1723364191077,"mc":[{"id":"1.231582261","rc":[{"batb":[[0,2.46,4],[1,2.44,10],[2,2.42,12.68]],"ltp":2.46,"tv":8.72,"id":655}]}]}
{"op":"mcm","clk":"11827755103","pt":1723364193502,"mc":[{"id":"1.231582261","rc":[{"batb":[[0,2.44,10],[1,2.42,12.68],[2,2.4,12.86]],"ltp":2.46,"tv":8.72,"id":655}]}]}
{"op":"mcm","clk":"11827755154","pt":1723364194381,"mc":[{"id":"1.231582261","rc":[{"batb":[[0,2.42,12.68],[1,2.4,12.86],[2,2.34,29.13]],"ltp":2.46,"tv":8.72,"id":655}]}]}
{"op":"mcm","clk":"11827755233","pt":1723364195981,"mc":[{"id":"1.231582261","rc":[{"batb":[[0,2.44,4],[1,2.42,12.68],[2,2.4,12.86]],"ltp":2.46,"tv":8.72,"id":655}]}]}
{"op":"mcm","clk":"11827755369","pt":1723364198405,"mc":[{"id":"1.231582261","rc":[{"batb":[[0,2.46,10]],"ltp":2.46,"tv":8.72,"id":655}]}]}
{"op":"mcm","clk":"11827755564","pt":1723364201273,"mc":[{"id":"1.231582261","rc":[{"batb":[[0,2.42,12.68],[1,2.4,12.86],[2,2.34,29.13]],"ltp":2.46,"tv":8.72,"id":655}]}]}
{"op":"mcm","clk":"11827755585","pt":1723364201590,"mc":[{"id":"1.231582261","rc":[{"batb":[[0,2.44,4],[1,2.42,12.68],[2,2.4,12.86]],"ltp":2.46,"tv":8.72,"id":655}]}]}
{"op":"mcm","clk":"11827755743","pt":1723364203917,"mc":[{"id":"1.231582261","rc":[{"batb":[[0,2.44,10]],"ltp":2.46,"tv":8.72,"id":655}]}]}
{"op":"mcm","clk":"11827755945","pt":1723364207317,"mc":[{"id":"1.231582261","rc":[{"batb":[[0,2.42,12.68],[1,2.4,12.86],[2,2.34,29.13]],"ltp":2.46,"tv":8.72,"id":655}]}]}
{"op":"mcm","clk":"11827755962","pt":1723364207578,"mc":[{"id":"1.231582261","rc":[{"batb":[[0,2.44,4],[1,2.42,12.68],[2,2.4,12.86]],"ltp":2.46,"tv":8.72,"id":655}]}]}
{"op":"mcm","clk":"11827756115","pt":1723364210003,"mc":[{"id":"1.231582261","rc":[{"batb":[[0,2.44,10]],"ltp":2.46,"tv":8.72,"id":655}]}]}
{"op":"mcm","clk":"11827756268","pt":1723364212333,"mc":[{"id":"1.231582261","rc":[{"batb":[[0,2.46,4],[1,2.44,10],[2,2.42,12.68]],"ltp":2.46,"tv":8.72,"id":655}]}]}
{"op":"mcm","clk":"11827756336","pt":1723364213212,"mc":[{"id":"1.231582261","rc":[{"batb":[[1,2.42,12.68],[2,2.4,12.86]],"ltp":2.46,"tv":8.72,"id":655}]}]}
{"op":"mcm","clk":"11827756453","pt":1723364214549,"mc":[{"id":"1.231582261","rc":[{"batb":[[0,2.42,12.68],[1,2.4,12.86],[2,2.34,29.13]],"ltp":2.46,"tv":8.72,"id":655}]}]}
{"op":"mcm","clk":"11827756698","pt":1723364217555,"mc":[{"id":"1.231582261","rc":[{"batb":[[0,2.44,14],[1,2.42,12.68],[2,2.4,12.86]],"ltp":2.46,"tv":8.72,"id":655}]}]}
{"op":"mcm","clk":"11827756888","pt":1723364220447,"mc":[{"id":"1.231582261","rc":[{"batb":[[0,2.44,10]],"ltp":2.46,"tv":8.72,"id":655}]}]}
{"op":"mcm","clk":"11827756949","pt":1723364221437,"mc":[{"id":"1.231582261","rc":[{"batb":[[0,2.42,12.68],[1,2.4,12.86],[2,2.34,29.13]],"ltp":2.46,"tv":8.72,"id":655}]}]}
{"op":"mcm","clk":"11827757461","pt":1723364229655,"mc":[{"id":"1.231582261","rc":[{"batb":[[0,2.44,14],[1,2.42,12.68],[2,2.4,12.86]],"ltp":2.46,"tv":8.72,"id":655}]}]}
{"op":"mcm","clk":"11827757640","pt":1723364232033,"mc":[{"id":"1.231582261","rc":[{"batb":[[0,2.44,10]],"ltp":2.46,"tv":8.72,"id":655}]}]}
{"op":"mcm","clk":"11827757712","pt":1723364233062,"mc":[{"id":"1.231582261","rc":[{"batb":[[0,2.42,12.68],[1,2.4,12.86],[2,2.34,29.13]],"ltp":2.46,"tv":8.72,"id":655}]}]}
{"op":"mcm","clk":"11827758106","pt":1723364239364,"mc":[{"id":"1.231582261","rc":[{"batb":[[0,2.44,14],[1,2.42,12.68],[2,2.4,12.86]],"ltp":2.46,"tv":8.72,"id":655}]}]}
{"op":"mcm","clk":"11827758262","pt":1723364241737,"mc":[{"id":"1.231582261","rc":[{"batb":[[0,2.44,10]],"ltp":2.46,"tv":8.72,"id":655}]}]}
{"op":"mcm","clk":"11827758317","pt":1723364242561,"mc":[{"id":"1.231582261","rc":[{"batb":[[0,2.42,12.68],[1,2.4,12.86],[2,2.34,29.13]],"ltp":2.46,"tv":8.72,"id":655}]}]}
{"op":"mcm","clk":"11827758693","pt":1723364247991,"mc":[{"id":"1.231582261","rc":[{"batb":[[0,2.44,14],[1,2.42,12.68],[2,2.4,12.86]],"ltp":2.46,"tv":8.72,"id":655}]}]}
{"op":"mcm","clk":"11827758843","pt":1723364250253,"mc":[{"id":"1.231582261","rc":[{"batb":[[0,2.44,10]],"ltp":2.46,"tv":8.72,"id":655}]}]}
{"op":"mcm","clk":"11827758907","pt":1723364251264,"mc":[{"id":"1.231582261","rc":[{"batb":[[0,2.42,12.68],[1,2.4,12.86],[2,2.34,29.13]],"ltp":2.46,"tv":8.72,"id":655}]}]}
{"op":"mcm","clk":"11827759110","pt":1723364254287,"mc":[{"id":"1.231582261","rc":[{"batb":[[0,2.44,14],[1,2.42,12.68],[2,2.4,12.86]],"ltp":2.46,"tv":8.72,"id":655}]}]}
{"op":"mcm","clk":"11827759318","pt":1723364257388,"mc":[{"id":"1.231582261","rc":[{"batb":[[0,2.42,12.68],[1,2.4,12.86],[2,2.34,29.13]],"ltp":2.46,"tv":8.72,"id":655}]}]}
{"op":"mcm","clk":"11827759497","pt":1723364259658,"mc":[{"id":"1.231582261","rc":[{"batb":[[0,2.44,14],[1,2.42,12.68],[2,2.4,12.86]],"ltp":2.46,"tv":8.72,"id":655}]}]}
{"op":"mcm","clk":"11827759675","pt":1723364262180,"mc":[{"id":"1.231582261","rc":[{"batb":[[0,2.44,10]],"ltp":2.46,"tv":8.72,"id":655}]}]}
{"op":"mcm","clk":"11827759739","pt":1723364263161,"mc":[{"id":"1.231582261","rc":[{"batb":[[0,2.42,12.68],[1,2.4,12.86],[2,2.34,29.13]],"ltp":2.46,"tv":8.72,"id":655}]}]}
{"op":"mcm","clk":"11827759856","pt":1723364265066,"mc":[{"id":"1.231582261","rc":[{"batb":[[0,2.44,4],[1,2.42,12.68],[2,2.4,12.86]],"ltp":2.46,"tv":8.72,"id":655}]}]}
{"op":"mcm","clk":"11827760084","pt":1723364267869,"mc":[{"id":"1.231582261","rc":[{"batb":[[0,2.44,10]],"ltp":2.46,"tv":8.72,"id":655}]}]}
{"op":"mcm","clk":"11827760343","pt":1723364271088,"mc":[{"id":"1.231582261","rc":[{"batb":[[0,2.46,4]],"ltp":2.46,"tv":8.72,"id":655}]}]}
{"op":"mcm","clk":"11827760558","pt":1723364273494,"mc":[{"id":"1.231582261","rc":[{"batb":[[0,2.44,10]],"ltp":2.46,"tv":8.72,"id":655}]}]}
{"op":"mcm","clk":"11827760812","pt":1723364277324,"mc":[{"id":"1.231582261","rc":[{"batb":[[0,2.44,4]],"ltp":2.46,"tv":8.72,"id":655}]}]}
{"op":"mcm","clk":"11827760964","pt":1723364279494,"mc":[{"id":"1.231582261","rc":[{"batb":[[0,2.42,12.68],[1,2.4,12.86],[2,2.34,29.13]],"ltp":2.46,"tv":8.72,"id":655}]}]}
{"op":"mcm","clk":"11827760974","pt":1723364279598,"mc":[{"id":"1.231582261","rc":[{"batb":[[0,2.44,10],[1,2.42,12.68],[2,2.4,12.86]],"ltp":2.46,"tv":8.72,"id":655}]}]}
{"op":"mcm","clk":"11827761218","pt":1723364283016,"mc":[{"id":"1.231582261","rc":[{"batb":[[0,2.44,4]],"ltp":2.46,"tv":8.72,"id":655}]}]}
{"op":"mcm","clk":"11827761397","pt":1723364285394,"mc":[{"id":"1.231582261","rc":[{"batb":[[0,2.42,12.68],[1,2.4,12.86],[2,2.34,29.13]],"ltp":2.46,"tv":8.72,"id":655}]}]}
{"op":"mcm","clk":"11827761421","pt":1723364285704,"mc":[{"id":"1.231582261","rc":[{"batb":[[0,2.44,10],[1,2.42,12.68],[2,2.4,12.86]],"ltp":2.46,"tv":8.72,"id":655}]}]}
{"op":"mcm","clk":"11827761593","pt":1723364287825,"mc":[{"id":"1.231582261","rc":[{"batb":[[0,2.46,4],[1,2.44,10],[2,2.42,12.68]],"ltp":2.46,"tv":8.72,"id":655}]}]}
{"op":"mcm","clk":"11827761677","pt":1723364289119,"mc":[{"id":"1.231582261","rc":[{"batb":[[1,2.42,12.68],[2,2.4,12.86]],"ltp":2.46,"tv":8.72,"id":655}]}]}
{"op":"mcm","clk":"11827761757","pt":1723364290310,"mc":[{"id":"1.231582261","rc":[{"batb":[[0,2.42,12.68],[1,2.4,12.86],[2,2.34,29.13]],"ltp":2.46,"tv":8.72,"id":655}]}]}
{"op":"mcm","clk":"11827762034","pt":1723364294331,"mc":[{"id":"1.231582261","rc":[{"batb":[[0,2.44,14],[1,2.42,12.68],[2,2.4,12.86]],"ltp":2.46,"tv":8.72,"id":655}]}]}
{"op":"mcm","clk":"11827762247","pt":1723364297050,"mc":[{"id":"1.231582261","rc":[{"batb":[[0,2.44,10]],"ltp":2.46,"tv":8.72,"id":655}]}]}
{"op":"mcm","clk":"11827762335","pt":1723364298011,"mc":[{"id":"1.231582261","rc":[{"batb":[[0,2.42,12.68],[1,2.4,12.86],[2,2.34,29.13]],"ltp":2.46,"tv":8.72,"id":655}]}]}
{"op":"mcm","clk":"11827762464","pt":1723364299617,"mc":[{"id":"1.231582261","rc":[{"batb":[[0,2.44,4],[1,2.42,12.68],[2,2.4,12.86]],"ltp":2.46,"tv":8.72,"id":655}]}]}
{"op":"mcm","clk":"11827762568","pt":1723364301010,"mc":[{"id":"1.231582261","rc":[{"batb":[[0,2.46,10],[1,2.44,4],[2,2.42,12.68]],"ltp":2.46,"tv":8.72,"id":655}]}]}
{"op":"mcm","clk":"11827762641","pt":1723364301940,"mc":[{"id":"1.231582261","rc":[{"batb":[[1,2.42,12.68],[2,2.4,12.86]],"ltp":2.46,"tv":8.72,"id":655}]}]}
{"op":"mcm","clk":"11827762870","pt":1723364304937,"mc":[{"id":"1.231582261","rc":[{"batb":[[0,2.48,4]],"ltp":2.46,"tv":8.72,"id":655}]}]}
{"op":"mcm","clk":"11827763077","pt":1723364308042,"mc":[{"id":"1.231582261","rc":[{"batb":[[0,2.44,10]],"ltp":2.46,"tv":8.72,"id":655}]}]}
{"op":"mcm","clk":"11827763238","pt":1723364310316,"mc":[{"id":"1.231582261","rc":[{"batb":[[0,2.46,4],[1,2.44,10],[2,2.42,12.68]],"ltp":2.46,"tv":8.72,"id":655}]}]}
{"op":"mcm","clk":"11827763301","pt":1723364311345,"mc":[{"id":"1.231582261","rc":[{"batb":[[1,2.42,12.68],[2,2.4,12.86]],"ltp":2.46,"tv":8.72,"id":655}]}]}
{"op":"mcm","clk":"11827763420","pt":1723364313363,"mc":[{"id":"1.231582261","rc":[{"batb":[[0,2.42,12.68],[1,2.4,12.86],[2,2.34,29.13]],"ltp":2.46,"tv":8.72,"id":655}]}]}
{"op":"mcm","clk":"11827763628","pt":1723364316252,"mc":[{"id":"1.231582261","rc":[{"batb":[[0,2.44,14],[1,2.42,12.68],[2,2.4,12.86]],"ltp":2.46,"tv":8.72,"id":655}]}]}
{"op":"mcm","clk":"11827763825","pt":1723364318836,"mc":[{"id":"1.231582261","rc":[{"batb":[[0,2.44,10]],"ltp":2.46,"tv":8.72,"id":655}]}]}
{"op":"mcm","clk":"11827763880","pt":1723364319563,"mc":[{"id":"1.231582261","rc":[{"batb":[[0,2.42,12.68],[1,2.4,12.86],[2,2.34,29.13]],"ltp":2.46,"tv":8.72,"id":655}]}]}
{"op":"mcm","clk":"11827764063","pt":1723364322149,"mc":[{"id":"1.231582261","rc":[{"batb":[[0,2.44,14],[1,2.42,12.68],[2,2.4,12.86]],"ltp":2.46,"tv":8.72,"id":655}]}]}
{"op":"mcm","clk":"11827764220","pt":1723364324442,"mc":[{"id":"1.231582261","rc":[{"batb":[[0,2.44,10]],"ltp":2.46,"tv":8.72,"id":655}]}]}
{"op":"mcm","clk":"11827764293","pt":1723364325680,"mc":[{"id":"1.231582261","rc":[{"batb":[[0,2.42,12.68],[1,2.4,12.86],[2,2.34,29.13]],"ltp":2.46,"tv":8.72,"id":655}]}]}
{"op":"mcm","clk":"11827764393","pt":1723364326876,"mc":[{"id":"1.231582261","rc":[{"batb":[[0,2.44,4],[1,2.42,12.68],[2,2.4,12.86]],"ltp":2.46,"tv":8.72,"id":655}]}]}
{"op":"mcm","clk":"11827764495","pt":1723364328280,"mc":[{"id":"1.231582261","rc":[{"batb":[[0,2.46,10],[1,2.44,4],[2,2.42,12.68]],"ltp":2.46,"tv":8.72,"id":655}]}]}
{"op":"mcm","clk":"11827764559","pt":1723364329374,"mc":[{"id":"1.231582261","rc":[{"batb":[[1,2.42,12.68],[2,2.4,12.86]],"ltp":2.46,"tv":8.72,"id":655}]}]}
{"op":"mcm","clk":"11827764696","pt":1723364331489,"mc":[{"id":"1.231582261","rc":[{"batb":[[0,2.42,12.68],[1,2.4,12.86],[2,2.34,29.13]],"ltp":2.46,"tv":8.72,"id":655}]}]}
{"op":"mcm","clk":"11827764704","pt":1723364331541,"mc":[{"id":"1.231582261","rc":[{"batb":[[0,2.48,4],[1,2.42,12.68],[2,2.4,12.86]],"ltp":2.46,"tv":8.72,"id":655}]}]}
{"op":"mcm","clk":"11827765012","pt":1723364335870,"mc":[{"id":"1.231582261","rc":[{"batb":[[0,2.5,10],[1,2.48,4],[2,2.42,12.68]],"ltp":2.46,"tv":8.72,"id":655}]}]}
{"op":"mcm","clk":"11827765136","pt":1723364337885,"mc":[{"id":"1.231582261","rc":[{"batb":[[1,2.42,12.68],[2,2.4,12.86]],"ltp":2.46,"tv":8.72,"id":655}]}]}
{"op":"mcm","clk":"11827765316","pt":1723364340354,"mc":[{"id":"1.231582261","rc":[{"batb":[[0,2.44,4]],"ltp":2.46,"tv":8.72,"id":655}]}]}
{"op":"mcm","clk":"11827765548","pt":1723364343163,"mc":[{"id":"1.231582261","rc":[{"batb":[[0,2.42,12.68],[1,2.4,12.86],[2,2.34,29.13]],"ltp":2.46,"tv":8.72,"id":655}]}]}
{"op":"mcm","clk":"11827765583","pt":1723364343569,"mc":[{"id":"1.231582261","rc":[{"batb":[[0,2.44,10],[1,2.42,12.68],[2,2.4,12.86]],"ltp":2.46,"tv":8.72,"id":655}]}]}
{"op":"mcm","clk":"11827765724","pt":1723364345645,"mc":[{"id":"1.231582261","rc":[{"batb":[[0,2.46,4],[1,2.44,10],[2,2.42,12.68]],"ltp":2.46,"tv":8.72,"id":655}]}]}
{"op":"mcm","clk":"11827765806","pt":1723364346876,"mc":[{"id":"1.231582261","rc":[{"batb":[[1,2.42,12.68],[2,2.4,12.86]],"ltp":2.46,"tv":8.72,"id":655}]}]}
{"op":"mcm","clk":"11827765876","pt":1723364347859,"mc":[{"id":"1.231582261","rc":[{"batb":[[0,2.42,12.68],[1,2.4,12.86],[2,2.34,29.13]],"ltp":2.46,"tv":8.72,"id":655}]}]}
{"op":"mcm","clk":"11827766048","pt":1723364350503,"mc":[{"id":"1.231582261","rc":[{"batb":[[0,2.44,14],[1,2.42,12.68],[2,2.4,12.86]],"ltp":2.46,"tv":8.72,"id":655}]}]}
{"op":"mcm","clk":"11827766250","pt":1723364352989,"mc":[{"id":"1.231582261","rc":[{"batb":[[0,2.44,10]],"ltp":2.46,"tv":8.72,"id":655}]}]}
{"op":"mcm","clk":"11827766310","pt":1723364353917,"mc":[{"id":"1.231582261","rc":[{"batb":[[0,2.42,12.68],[1,2.4,12.86],[2,2.34,29.13]],"ltp":2.46,"tv":8.72,"id":655}]}]}
{"op":"mcm","clk":"11827766516","pt":1723364356194,"mc":[{"id":"1.231582261","rc":[{"batb":[[0,2.46,10],[1,2.44,4],[2,2.42,12.68]],"ltp":2.46,"tv":8.72,"id":655}]}]}
{"op":"mcm","clk":"11827766675","pt":1723364358519,"mc":[{"id":"1.231582261","rc":[{"batb":[[1,2.42,12.68],[2,2.4,12.86]],"ltp":2.46,"tv":8.72,"id":655}]}]}
{"op":"mcm","clk":"11827766796","pt":1723364360176,"mc":[{"id":"1.231582261","rc":[{"batb":[[0,2.42,12.68],[1,2.4,12.86],[2,2.34,29.13]],"ltp":2.46,"tv":8.72,"id":655}]}]}
{"op":"mcm","clk":"11827766915","pt":1723364361922,"mc":[{"id":"1.231582261","rc":[{"batb":[[0,2.44,4],[1,2.42,12.68],[2,2.4,12.86]],"ltp":2.46,"tv":8.72,"id":655}]}]}
{"op":"mcm","clk":"11827767011","pt":1723364363281,"mc":[{"id":"1.231582261","rc":[{"batb":[[0,2.46,10],[1,2.44,4],[2,2.42,12.68]],"ltp":2.46,"tv":8.72,"id":655}]}]}
{"op":"mcm","clk":"11827767086","pt":1723364364217,"mc":[{"id":"1.231582261","rc":[{"batb":[[1,2.42,12.68],[2,2.4,12.86]],"ltp":2.46,"tv":8.72,"id":655}]}]}
{"op":"mcm","clk":"11827767303","pt":1723364367116,"mc":[{"id":"1.231582261","rc":[{"batb":[[0,2.44,4]],"ltp":2.46,"tv":8.72,"id":655}]}]}
{"op":"mcm","clk":"11827767474","pt":1723364369394,"mc":[{"id":"1.231582261","rc":[{"batb":[[0,2.42,12.68],[1,2.4,12.86],[2,2.34,29.13]],"ltp":2.46,"tv":8.72,"id":655}]}]}
{"op":"mcm","clk":"11827767503","pt":1723364369805,"mc":[{"id":"1.231582261","rc":[{"batb":[[0,2.44,10],[1,2.42,12.68],[2,2.4,12.86]],"ltp":2.46,"tv":8.72,"id":655}]}]}
{"op":"mcm","clk":"11827767675","pt":1723364372305,"mc":[{"id":"1.231582261","rc":[{"batb":[[0,2.46,4],[1,2.44,10],[2,2.42,12.68]],"ltp":2.46,"tv":8.72,"id":655}]}]}
{"op":"mcm","clk":"11827767752","pt":1723364373336,"mc":[{"id":"1.231582261","rc":[{"batb":[[1,2.42,12.68],[2,2.4,12.86]],"ltp":2.46,"tv":8.72,"id":655}]}]}
{"op":"mcm","clk":"11827767883","pt":1723364374994,"mc":[{"id":"1.231582261","rc":[{"batb":[[0,2.42,12.68],[1,2.4,12.86],[2,2.34,29.13]],"ltp":2.46,"tv":8.72,"id":655}]}]}
{"op":"mcm","clk":"11827768036","pt":1723364377226,"mc":[{"id":"1.231582261","rc":[{"batb":[[0,2.44,14],[1,2.42,12.68],[2,2.4,12.86]],"ltp":2.46,"tv":8.72,"id":655}]}]}
{"op":"mcm","clk":"11827768185","pt":1723364379600,"mc":[{"id":"1.231582261","rc":[{"batb":[[0,2.44,10]],"ltp":2.46,"tv":8.72,"id":655}]}]}
{"op":"mcm","clk":"11827768270","pt":1723364380633,"mc":[{"id":"1.231582261","rc":[{"batb":[[0,2.42,12.68],[1,2.4,12.86],[2,2.34,29.13]],"ltp":2.46,"tv":8.72,"id":655}]}]}
{"op":"mcm","clk":"11827768374","pt":1723364381922,"mc":[{"id":"1.231582261","rc":[{"batb":[[0,2.44,4],[1,2.42,12.68],[2,2.4,12.86]],"ltp":2.46,"tv":8.72,"id":655}]}]}
{"op":"mcm","clk":"11827768552","pt":1723364384254,"mc":[{"id":"1.231582261","rc":[{"batb":[[0,2.46,10],[1,2.44,4],[2,2.42,12.68]],"ltp":2.46,"tv":8.72,"id":655}]}]}
{"op":"mcm","clk":"11827768618","pt":1723364384720,"mc":[{"id":"1.231582261","rc":[{"batb":[[1,2.42,12.68],[2,2.4,12.86]],"ltp":2.46,"tv":8.72,"id":655}]}]}
{"op":"mcm","clk":"11827768850","pt":1723364388132,"mc":[{"id":"1.231582261","rc":[{"batb":[[0,2.44,4]],"ltp":2.46,"tv":8.72,"id":655}]}]}
{"op":"mcm","clk":"11827769066","pt":1723364390935,"mc":[{"id":"1.231582261","rc":[{"batb":[[0,2.44,10]],"ltp":2.46,"tv":8.72,"id":655}]}]}
{"op":"mcm","clk":"11827769300","pt":1723364394127,"mc":[{"id":"1.231582261","rc":[{"batb":[[0,2.46,4]],"ltp":2.46,"tv":8.72,"id":655}]}]}
{"op":"mcm","clk":"11827769418","pt":1723364396035,"mc":[{"id":"1.231582261","rc":[{"batb":[[0,2.42,12.68],[1,2.4,12.86],[2,2.34,29.13]],"ltp":2.46,"tv":8.72,"id":655}]}]}
{"op":"mcm","clk":"11827769454","pt":1723364396550,"mc":[{"id":"1.231582261","rc":[{"batb":[[0,2.44,10],[1,2.42,12.68],[2,2.4,12.86]],"ltp":2.46,"tv":8.72,"id":655}]}]}
{"op":"mcm","clk":"11827769639","pt":1723364399048,"mc":[{"id":"1.231582261","rc":[{"batb":[[0,2.46,4],[1,2.44,10],[2,2.42,12.68]],"ltp":2.46,"tv":8.72,"id":655}]}]}
{"op":"mcm","clk":"11827769712","pt":1723364399935,"mc":[{"id":"1.231582261","rc":[{"batb":[[1,2.42,12.68],[2,2.4,12.86]],"ltp":2.46,"tv":8.72,"id":655}]}]}
{"op":"mcm","clk":"11827769895","pt":1723364402162,"mc":[{"id":"1.231582261","rc":[{"batb":[[0,2.44,10]],"ltp":2.46,"tv":8.72,"id":655}]}]}
{"op":"mcm","clk":"11827770113","pt":1723364404461,"mc":[{"id":"1.231582261","rc":[{"batb":[[0,2.46,4],[1,2.44,10],[2,2.42,12.68]],"ltp":2.46,"tv":8.72,"id":655}]}]}
{"op":"mcm","clk":"11827770216","pt":1723364405446,"mc":[{"id":"1.231582261","rc":[{"batb":[[1,2.42,12.68],[2,2.4,12.86]],"ltp":2.46,"tv":8.72,"id":655}]}]}
{"op":"mcm","clk":"11827770321","pt":1723364406735,"mc":[{"id":"1.231582261","rc":[{"batb":[[0,2.42,12.68],[1,2.4,12.86],[2,2.34,29.13]],"ltp":2.46,"tv":8.72,"id":655}]}]}
{"op":"mcm","clk":"11827770553","pt":1723364409340,"mc":[{"id":"1.231582261","rc":[{"batb":[[0,2.44,14],[1,2.42,12.68],[2,2.4,12.86]],"ltp":2.46,"tv":8.72,"id":655}]}]}
{"op":"mcm","clk":"11827770783","pt":1723364411867,"mc":[{"id":"1.231582261","rc":[{"batb":[[0,2.44,10]],"ltp":2.46,"tv":8.72,"id":655}]}]}
{"op":"mcm","clk":"11827770869","pt":1723364412747,"mc":[{"id":"1.231582261","rc":[{"batb":[[0,2.42,12.68],[1,2.4,12.86],[2,2.34,29.13]],"ltp":2.46,"tv":8.72,"id":655}]}]}
{"op":"mcm","clk":"11827770971","pt":1723364414089,"mc":[{"id":"1.231582261","rc":[{"batb":[[0,2.44,4],[1,2.42,12.68],[2,2.4,12.86]],"ltp":2.46,"tv":8.72,"id":655}]}]}
{"op":"mcm","clk":"11827771221","pt":1723364416878,"mc":[{"id":"1.231582261","rc":[{"batb":[[0,2.44,10]],"ltp":2.46,"tv":8.72,"id":655}]}]}
{"op":"mcm","clk":"11827771514","pt":1723364420491,"mc":[{"id":"1.231582261","rc":[{"batb":[[0,2.42,12.68],[1,2.4,12.86],[2,2.34,29.13]],"ltp":2.46,"tv":8.72,"id":655}]}]}
{"op":"mcm","clk":"11827771545","pt":1723364420853,"mc":[{"id":"1.231582261","rc":[{"batb":[[0,2.44,4],[1,2.42,12.68],[2,2.4,12.86]],"ltp":2.46,"tv":8.72,"id":655}]}]}
{"op":"mcm","clk":"11827771731","pt":1723364423481,"mc":[{"id":"1.231582261","rc":[{"batb":[[0,2.44,10]],"ltp":2.46,"tv":8.72,"id":655}]}]}
{"op":"mcm","clk":"11827772017","pt":1723364427194,"mc":[{"id":"1.231582261","rc":[{"batb":[[0,2.46,4]],"ltp":2.46,"tv":8.72,"id":655}]}]}
{"op":"mcm","clk":"11827772160","pt":1723364429100,"mc":[{"id":"1.231582261","rc":[{"batb":[[0,2.48,10],[1,2.46,4],[2,2.42,12.68]],"ltp":2.46,"tv":8.72,"id":655}]}]}
{"op":"mcm","clk":"11827772210","pt":1723364429978,"mc":[{"id":"1.231582261","rc":[{"batb":[[1,2.42,12.68],[2,2.4,12.86]],"ltp":2.46,"tv":8.72,"id":655}]}]}
{"op":"mcm","clk":"11827772456","pt":1723364433086,"mc":[{"id":"1.231582261","rc":[{"batb":[[0,2.44,4]],"ltp":2.46,"tv":8.72,"id":655}]}]}
{"op":"mcm","clk":"11827772670","pt":1723364436094,"mc":[{"id":"1.231582261","rc":[{"batb":[[0,2.44,10]],"ltp":2.46,"tv":8.72,"id":655}]}]}
{"op":"mcm","clk":"11827772992","pt":1723364440322,"mc":[{"id":"1.231582261","rc":[{"batb":[[0,2.44,4]],"ltp":2.46,"tv":8.72,"id":655}]}]}
{"op":"mcm","clk":"11827773208","pt":1723364443304,"mc":[{"id":"1.231582261","rc":[{"batb":[[0,2.44,10]],"ltp":2.46,"tv":8.72,"id":655}]}]}
{"op":"mcm","clk":"11827773336","pt":1723364445216,"mc":[{"id":"1.231582261","rc":[{"batb":[[0,2.46,4],[1,2.44,10],[2,2.42,12.68]],"ltp":2.46,"tv":8.72,"id":655}]}]}
{"op":"mcm","clk":"11827773477","pt":1723364447487,"mc":[{"id":"1.231582261","rc":[{"batb":[[0,2.42,12.68],[1,2.4,12.86],[2,2.34,29.13]],"ltp":2.46,"tv":8.72,"id":655}]}]}
{"op":"mcm","clk":"11827773659","pt":1723364450019,"mc":[{"id":"1.231582261","rc":[{"batb":[[0,2.44,14],[1,2.42,12.68],[2,2.4,12.86]],"ltp":2.46,"tv":8.72,"id":655}]}]}
{"op":"mcm","clk":"11827773846","pt":1723364452441,"mc":[{"id":"1.231582261","rc":[{"batb":[[0,2.44,10]],"ltp":2.46,"tv":8.72,"id":655}]}]}
{"op":"mcm","clk":"11827773928","pt":1723364453424,"mc":[{"id":"1.231582261","rc":[{"batb":[[0,2.42,12.68],[1,2.4,12.86],[2,2.34,29.13]],"ltp":2.46,"tv":8.72,"id":655}]}]}
{"op":"mcm","clk":"11827774119","pt":1723364455900,"mc":[{"id":"1.231582261","rc":[{"batb":[[0,2.44,14],[1,2.42,12.68],[2,2.4,12.86]],"ltp":2.46,"tv":8.72,"id":655}]}]}
{"op":"mcm","clk":"11827774287","pt":1723364458536,"mc":[{"id":"1.231582261","rc":[{"batb":[[0,2.44,10]],"ltp":2.46,"tv":8.72,"id":655}]}]}
{"op":"mcm","clk":"11827774343","pt":1723364459513,"mc":[{"id":"1.231582261","rc":[{"batb":[[0,2.42,12.68],[1,2.4,12.86],[2,2.34,29.13]],"ltp":2.46,"tv":8.72,"id":655}]}]}
{"op":"mcm","clk":"11827774443","pt":1723364460910,"mc":[{"id":"1.231582261","rc":[{"batb":[[0,2.44,4],[1,2.42,12.68],[2,2.4,12.86]],"ltp":2.46,"tv":8.72,"id":655}]}]}
{"op":"mcm","clk":"11827774537","pt":1723364462097,"mc":[{"id":"1.231582261","rc":[{"batb":[[0,2.46,10],[1,2.44,4],[2,2.42,12.68]],"ltp":2.46,"tv":8.72,"id":655}]}]}
{"op":"mcm","clk":"11827774650","pt":1723364463498,"mc":[{"id":"1.231582261","rc":[{"batb":[[1,2.42,12.68],[2,2.4,12.86]],"ltp":2.46,"tv":8.72,"id":655}]}]}
{"op":"mcm","clk":"11827774789","pt":1723364465410,"mc":[{"id":"1.231582261","rc":[{"batb":[[0,2.42,12.68],[1,2.4,12.86],[2,2.34,29.13]],"ltp":2.46,"tv":8.72,"id":655}]}]}
{"op":"mcm","clk":"11827774945","pt":1723364467826,"mc":[{"id":"1.231582261","rc":[{"batb":[[0,2.44,14],[1,2.42,12.68],[2,2.4,12.86]],"ltp":2.46,"tv":8.72,"id":655}]}]}
{"op":"mcm","clk":"11827775122","pt":1723364470510,"mc":[{"id":"1.231582261","rc":[{"batb":[[0,2.44,10]],"ltp":2.46,"tv":8.72,"id":655}]}]}
{"op":"mcm","clk":"11827775178","pt":1723364471543,"mc":[{"id":"1.231582261","rc":[{"batb":[[0,2.42,12.68],[1,2.4,12.86],[2,2.34,29.13]],"ltp":2.46,"tv":8.72,"id":655}]}]}
{"op":"mcm","clk":"11827775361","pt":1723364474243,"mc":[{"id":"1.231582261","rc":[{"batb":[[0,2.44,14],[1,2.42,12.68],[2,2.4,12.86]],"ltp":2.46,"tv":8.72,"id":655}]}]}
{"op":"mcm","clk":"11827775529","pt":1723364476715,"mc":[{"id":"1.231582261","rc":[{"batb":[[0,2.44,10]],"ltp":2.46,"tv":8.72,"id":655}]}]}
{"op":"mcm","clk":"11827775574","pt":1723364477540,"mc":[{"id":"1.231582261","rc":[{"batb":[[0,2.42,12.68],[1,2.4,12.86],[2,2.34,29.13]],"ltp":2.46,"tv":8.72,"id":655}]}]}
{"op":"mcm","clk":"11827775914","pt":1723364482151,"mc":[{"id":"1.231582261","rc":[{"batb":[[0,2.44,14],[1,2.42,12.68],[2,2.4,12.86]],"ltp":2.46,"tv":8.72,"id":655}]}]}
{"op":"mcm","clk":"11827776123","pt":1723364484839,"mc":[{"id":"1.231582261","rc":[{"batb":[[0,2.44,10]],"ltp":2.46,"tv":8.72,"id":655}]}]}
{"op":"mcm","clk":"11827776193","pt":1723364485867,"mc":[{"id":"1.231582261","rc":[{"batb":[[0,2.42,12.68],[1,2.4,12.86],[2,2.34,29.13]],"ltp":2.46,"tv":8.72,"id":655}]}]}
{"op":"mcm","clk":"11827776310","pt":1723364487366,"mc":[{"id":"1.231582261","rc":[{"batb":[[0,2.44,4],[1,2.42,12.68],[2,2.4,12.86]],"ltp":2.46,"tv":8.72,"id":655}]}]}
{"op":"mcm","clk":"11827776461","pt":1723364489432,"mc":[{"id":"1.231582261","rc":[{"batb":[[0,2.46,10],[1,2.44,4],[2,2.42,12.68]],"ltp":2.46,"tv":8.72,"id":655}]}]}
{"op":"mcm","clk":"11827776488","pt":1723364489836,"mc":[{"id":"1.231582261","rc":[{"batb":[[1,2.42,12.68],[2,2.4,12.86]],"ltp":2.46,"tv":8.72,"id":655}]}]}
{"op":"mcm","clk":"11827776712","pt":1723364493075,"mc":[{"id":"1.231582261","rc":[{"batb":[[0,2.44,4]],"ltp":2.46,"tv":8.72,"id":655}]}]}
{"op":"mcm","clk":"11827776908","pt":1723364495355,"mc":[{"id":"1.231582261","rc":[{"batb":[[0,2.42,12.68],[1,2.4,12.86],[2,2.34,29.13]],"ltp":2.46,"tv":8.72,"id":655}]}]}
{"op":"mcm","clk":"11827776922","pt":1723364495563,"mc":[{"id":"1.231582261","rc":[{"batb":[[0,2.46,10],[1,2.42,12.68],[2,2.4,12.86]],"ltp":2.46,"tv":8.72,"id":655}]}]}
{"op":"mcm","clk":"11827777233","pt":1723364499384,"mc":[{"id":"1.231582261","rc":[{"batb":[[0,2.44,4]],"ltp":2.46,"tv":8.72,"id":655}]}]}
{"op":"mcm","clk":"11827777427","pt":1723364502075,"mc":[{"id":"1.231582261","rc":[{"batb":[[0,2.44,10]],"ltp":2.46,"tv":8.72,"id":655}]}]}
{"op":"mcm","clk":"11827777706","pt":1723364505381,"mc":[{"id":"1.231582261","rc":[{"batb":[[0,2.42,12.68],[1,2.4,12.86],[2,2.34,29.13]],"ltp":2.46,"tv":8.72,"id":655}]}]}
{"op":"mcm","clk":"11827777719","pt":1723364505586,"mc":[{"id":"1.231582261","rc":[{"batb":[[0,2.44,4],[1,2.42,12.68],[2,2.4,12.86]],"ltp":2.46,"tv":8.72,"id":655}]}]}
{"op":"mcm","clk":"11827777890","pt":1723364508024,"mc":[{"id":"1.231582261","rc":[{"batb":[[0,2.44,10]],"ltp":2.46,"tv":8.72,"id":655}]}]}
{"op":"mcm","clk":"11827778263","pt":1723364512469,"mc":[{"id":"1.231582261","rc":[{"batb":[[0,2.44,4]],"ltp":2.46,"tv":8.72,"id":655}]}]}
{"op":"mcm","clk":"11827778396","pt":1723364514076,"mc":[{"id":"1.231582261","rc":[{"batb":[[0,2.46,10],[1,2.44,4],[2,2.42,12.68]],"ltp":2.46,"tv":8.72,"id":655}]}]}
{"op":"mcm","clk":"11827778464","pt":1723364514802,"mc":[{"id":"1.231582261","rc":[{"batb":[[1,2.42,12.68],[2,2.4,12.86]],"ltp":2.46,"tv":8.72,"id":655}]}]}
{"op":"mcm","clk":"11827778658","pt":1723364517284,"mc":[{"id":"1.231582261","rc":[{"batb":[[0,2.42,12.68],[1,2.4,12.86],[2,2.34,29.13]],"ltp":2.46,"tv":8.72,"id":655}]}]}
{"op":"mcm","clk":"11827778680","pt":1723364517591,"mc":[{"id":"1.231582261","rc":[{"batb":[[0,2.44,4],[1,2.42,12.68],[2,2.4,12.86]],"ltp":2.46,"tv":8.72,"id":655}]}]}
{"op":"mcm","clk":"11827778902","pt":1723364520482,"mc":[{"id":"1.231582261","rc":[{"batb":[[0,2.46,10]],"ltp":2.46,"tv":8.72,"id":655}]}]}
{"op":"mcm","clk":"11827779059","pt":1723364522400,"mc":[{"id":"1.231582261","rc":[{"batb":[[0,2.48,4],[1,2.46,10],[2,2.42,12.68]],"ltp":2.46,"tv":8.72,"id":655}]}]}
{"op":"mcm","clk":"11827779169","pt":1723364523996,"mc":[{"id":"1.231582261","rc":[{"batb":[[1,2.42,12.68],[2,2.4,12.86]],"ltp":2.46,"tv":8.72,"id":655}]}]}
{"op":"mcm","clk":"11827779217","pt":1723364524718,"mc":[{"id":"1.231582261","rc":[{"batb":[[0,2.42,12.68],[1,2.4,12.86],[2,2.34,29.13]],"ltp":2.46,"tv":8.72,"id":655}]}]}
{"op":"mcm","clk":"11827779537","pt":1723364529324,"mc":[{"id":"1.231582261","rc":[{"batb":[[0,2.44,14],[1,2.42,12.68],[2,2.4,12.86]],"ltp":2.46,"tv":8.72,"id":655}]}]}
{"op":"mcm","clk":"11827779721","pt":1723364531717,"mc":[{"id":"1.231582261","rc":[{"batb":[[0,2.44,10]],"ltp":2.46,"tv":8.72,"id":655}]}]}
{"op":"mcm","clk":"11827779782","pt":1723364532601,"mc":[{"id":"1.231582261","rc":[{"batb":[[0,2.42,12.68],[1,2.4,12.86],[2,2.34,29.13]],"ltp":2.46,"tv":8.72,"id":655}]}]}
{"op":"mcm","clk":"11827779999","pt":1723364536110,"mc":[{"id":"1.231582261","rc":[{"batb":[[0,2.44,14],[1,2.42,12.68],[2,2.4,12.86]],"ltp":2.46,"tv":8.72,"id":655}]}]}
{"op":"mcm","clk":"11827780161","pt":1723364538533,"mc":[{"id":"1.231582261","rc":[{"batb":[[0,2.44,10]],"ltp":2.46,"tv":8.72,"id":655}]}]}
{"op":"mcm","clk":"11827780223","pt":1723364539513,"mc":[{"id":"1.231582261","rc":[{"batb":[[0,2.42,12.68],[1,2.4,12.86],[2,2.34,29.13]],"ltp":2.46,"tv":8.72,"id":655}]}]}
{"op":"mcm","clk":"11827780529","pt":1723364543517,"mc":[{"id":"1.231582261","rc":[{"batb":[[0,2.44,14],[1,2.42,12.68],[2,2.4,12.86]],"ltp":2.46,"tv":8.72,"id":655}]}]}
{"op":"mcm","clk":"11827780725","pt":1723364545949,"mc":[{"id":"1.231582261","rc":[{"batb":[[0,2.44,10]],"ltp":2.46,"tv":8.72,"id":655}]}]}
{"op":"mcm","clk":"11827780795","pt":1723364547023,"mc":[{"id":"1.231582261","rc":[{"batb":[[0,2.42,12.68],[1,2.4,12.86],[2,2.34,29.13]],"ltp":2.46,"tv":8.72,"id":655}]}]}
{"op":"mcm","clk":"11827780876","pt":1723364548251,"mc":[{"id":"1.231582261","rc":[{"batb":[[0,2.44,4],[1,2.42,12.68],[2,2.4,12.86]],"ltp":2.46,"tv":8.72,"id":655}]}]}
{"op":"mcm","clk":"11827780955","pt":1723364549334,"mc":[{"id":"1.231582261","rc":[{"batb":[[0,2.46,10],[1,2.44,4],[2,2.42,12.68]],"ltp":2.46,"tv":8.72,"id":655}]}]}
{"op":"mcm","clk":"11827781050","pt":1723364550623,"mc":[{"id":"1.231582261","rc":[{"batb":[[1,2.42,12.68],[2,2.4,12.86]],"ltp":2.46,"tv":8.72,"id":655}]}]}
{"op":"mcm","clk":"11827781185","pt":1723364552639,"mc":[{"id":"1.231582261","rc":[{"batb":[[0,2.42,12.68],[1,2.4,12.86],[2,2.34,29.13]],"ltp":2.46,"tv":8.72,"id":655}]}]}
{"op":"mcm","clk":"11827781300","pt":1723364554340,"mc":[{"id":"1.231582261","rc":[{"batb":[[0,2.44,4],[1,2.42,12.68],[2,2.4,12.86]],"ltp":2.46,"tv":8.72,"id":655}]}]}
{"op":"mcm","clk":"11827781444","pt":1723364556144,"mc":[{"id":"1.231582261","rc":[{"batb":[[0,2.46,10],[1,2.44,4],[2,2.42,12.68]],"ltp":2.46,"tv":8.72,"id":655}]}]}
{"op":"mcm","clk":"11827781512","pt":1723364557030,"mc":[{"id":"1.231582261","rc":[{"batb":[[1,2.42,12.68],[2,2.4,12.86]],"ltp":2.46,"tv":8.72,"id":655}]}]}
{"op":"mcm","clk":"11827781745","pt":1723364560036,"mc":[{"id":"1.231582261","rc":[{"batb":[[0,2.44,4]],"ltp":2.46,"tv":8.72,"id":655}]}]}
{"op":"mcm","clk":"11827781935","pt":1723364562865,"mc":[{"id":"1.231582261","rc":[{"batb":[[0,2.46,10]],"ltp":2.46,"tv":8.72,"id":655}]}]}
{"op":"mcm","clk":"11827782139","pt":1723364565964,"mc":[{"id":"1.231582261","rc":[{"batb":[[0,2.48,4]],"ltp":2.46,"tv":8.72,"id":655}]}]}
{"op":"mcm","clk":"11827782303","pt":1723364568133,"mc":[{"id":"1.231582261","rc":[{"batb":[[0,2.44,10]],"ltp":2.46,"tv":8.72,"id":655}]}]}
{"op":"mcm","clk":"11827782506","pt":1723364571379,"mc":[{"id":"1.231582261","rc":[{"batb":[[0,2.46,4]],"ltp":2.46,"tv":8.72,"id":655}]}]}
{"op":"mcm","clk":"11827782723","pt":1723364574064,"mc":[{"id":"1.231582261","rc":[{"batb":[[0,2.44,10]],"ltp":2.46,"tv":8.72,"id":655}]}]}
{"op":"mcm","clk":"11827782899","pt":1723364576388,"mc":[{"id":"1.231582261","rc":[{"batb":[[0,2.46,4],[1,2.44,10],[2,2.42,12.68]],"ltp":2.46,"tv":8.72,"id":655}]}]}
{"op":"mcm","clk":"11827782982","pt":1723364577463,"mc":[{"id":"1.231582261","rc":[{"batb":[[1,2.42,12.68],[2,2.4,12.86]],"ltp":2.46,"tv":8.72,"id":655}]}]}
{"op":"mcm","clk":"11827783074","pt":1723364579074,"mc":[{"id":"1.231582261","rc":[{"batb":[[0,2.42,12.68],[1,2.4,12.86],[2,2.34,29.13]],"ltp":2.46,"tv":8.72,"id":655}]}]}
{"op":"mcm","clk":"11827783212","pt":1723364581050,"mc":[{"id":"1.231582261","rc":[{"batb":[[0,2.44,10],[1,2.42,12.68],[2,2.4,12.86]],"ltp":2.46,"tv":8.72,"id":655}]}]}
{"op":"mcm","clk":"11827783252","pt":1723364581570,"mc":[{"id":"1.231582261","rc":[{"batb":[[0,2.46,4],[1,2.44,10],[2,2.42,12.68]],"ltp":2.46,"tv":8.72,"id":655}]}]}
{"op":"mcm","clk":"11827783440","pt":1723364583891,"mc":[{"id":"1.231582261","rc":[{"batb":[[0,2.44,10],[1,2.42,12.68],[2,2.4,12.86]],"ltp":2.46,"tv":8.72,"id":655}]}]}
{"op":"mcm","clk":"11827783498","pt":1723364584568,"mc":[{"id":"1.231582261","rc":[{"batb":[[0,2.42,12.68],[1,2.4,12.86],[2,2.34,29.13]],"ltp":2.46,"tv":8.72,"id":655}]}]}
{"op":"mcm","clk":"11827783672","pt":1723364587455,"mc":[{"id":"1.231582261","rc":[{"batb":[[0,2.44,14],[1,2.42,12.68],[2,2.4,12.86]],"ltp":2.46,"tv":8.72,"id":655}]}]}
{"op":"mcm","clk":"11827783822","pt":1723364589988,"mc":[{"id":"1.231582261","rc":[{"batb":[[0,2.44,10]],"ltp":2.46,"tv":8.72,"id":655}]}]}
{"op":"mcm","clk":"11827783899","pt":1723364590864,"mc":[{"id":"1.231582261","rc":[{"batb":[[0,2.42,12.68],[1,2.4,12.86],[2,2.34,29.13]],"ltp":2.46,"tv":8.72,"id":655}]}]}
{"op":"mcm","clk":"11827784072","pt":1723364592978,"mc":[{"id":"1.231582261","rc":[{"batb":[[0,2.44,4],[1,2.42,12.68],[2,2.4,12.86]],"ltp":2.46,"tv":8.72,"id":655}]}]}
{"op":"mcm","clk":"11827784103","pt":1723364593593,"mc":[{"id":"1.231582261","rc":[{"batb":[[0,2.46,10],[1,2.44,4],[2,2.42,12.68]],"ltp":2.46,"tv":8.72,"id":655}]}]}
{"op":"mcm","clk":"11827784204","pt":1723364595498,"mc":[{"id":"1.231582261","rc":[{"batb":[[1,2.42,12.68],[2,2.4,12.86]],"ltp":2.46,"tv":8.72,"id":655}]}]}
{"op":"mcm","clk":"11827784301","pt":1723364597096,"mc":[{"id":"1.231582261","rc":[{"batb":[[0,2.42,12.68],[1,2.4,12.86],[2,2.34,29.13]],"ltp":2.46,"tv":8.72,"id":655}]}]}
{"op":"mcm","clk":"11827784456","pt":1723364599200,"mc":[{"id":"1.231582261","rc":[{"batb":[[0,2.44,4],[1,2.42,12.68],[2,2.4,12.86]],"ltp":2.46,"tv":8.72,"id":655}]}]}
{"op":"mcm","clk":"11827784480","pt":1723364599714,"mc":[{"id":"1.231582261","rc":[{"batb":[[0,2.46,10],[1,2.44,4],[2,2.42,12.68]],"ltp":2.46,"tv":8.72,"id":655}]}]}
{"op":"mcm","clk":"11827784607","pt":1723364601792,"mc":[{"id":"1.231582261","rc":[{"batb":[[1,2.42,12.68],[2,2.4,12.86]],"ltp":2.46,"tv":8.72,"id":655}]}]}
{"op":"mcm","clk":"11827784707","pt":1723364603378,"mc":[{"id":"1.231582261","rc":[{"batb":[[0,2.42,12.68],[1,2.4,12.86],[2,2.34,29.13]],"ltp":2.46,"tv":8.72,"id":655},{"batb":[[0,1.65,7.3],[1,1.64,61],[2,1.63,49.58]],"ltp":1.64,"tv":216.42,"id":2120}]}]}
{"op":"mcm","clk":"11827784748","pt":1723364603997,"mc":[{"id":"1.231582261","rc":[{"batb":[[0,2.44,4],[1,2.42,12.68],[2,2.4,12.86]],"ltp":2.46,"tv":8.72,"id":655},{"batb":[[1,1.64,89.14]],"ltp":1.64,"tv":216.42,"id":2120}]}]}
{"op":"mcm","clk":"11827784882","pt":1723364606317,"mc":[{"id":"1.231582261","rc":[{"batb":[[0,2.42,12.68],[1,2.4,12.86],[2,2.34,29.13]],"ltp":2.46,"tv":8.72,"id":655}]}]}
{"op":"mcm","clk":"11827784919","pt":1723364606884,"mc":[{"id":"1.231582261","rc":[{"batb":[[0,2.46,10],[1,2.42,12.68],[2,2.4,12.86]],"ltp":2.46,"tv":8.72,"id":655}]}]}
{"op":"mcm","clk":"11827785018","pt":1723364608632,"mc":[{"id":"1.231582261","rc":[{"batb":[[0,2.48,4],[1,2.46,10],[2,2.42,12.68]],"ltp":2.46,"tv":8.72,"id":655}]}]}
{"op":"mcm","clk":"11827785161","pt":1723364611013,"mc":[{"id":"1.231582261","rc":[{"batb":[[0,2.42,12.68],[1,2.4,12.86],[2,2.34,29.13]],"ltp":2.46,"tv":8.72,"id":655}]}]}
{"op":"mcm","clk":"11827785351","pt":1723364613829,"mc":[{"id":"1.231582261","rc":[{"batb":[[0,2.44,14],[1,2.42,12.68],[2,2.4,12.86]],"ltp":2.46,"tv":8.72,"id":655}]}]}
{"op":"mcm","clk":"11827785528","pt":1723364616499,"mc":[{"id":"1.231582261","rc":[{"batb":[[0,2.44,10]],"ltp":2.46,"tv":8.72,"id":655}]}]}
{"op":"mcm","clk":"11827785581","pt":1723364617630,"mc":[{"id":"1.231582261","rc":[{"batb":[[0,2.42,12.68],[1,2.4,12.86],[2,2.34,29.13]],"ltp":2.46,"tv":8.72,"id":655}]}]}
{"op":"mcm","clk":"11827785654","pt":1723364618719,"mc":[{"id":"1.231582261","rc":[{"batb":[[0,2.44,4],[1,2.42,12.68],[2,2.4,12.86]],"ltp":2.46,"tv":8.72,"id":655}]}]}
{"op":"mcm","clk":"11827785777","pt":1723364620318,"mc":[{"id":"1.231582261","rc":[{"batb":[[0,2.46,10],[1,2.44,4],[2,2.42,12.68]],"ltp":2.46,"tv":8.72,"id":655}]}]}
{"op":"mcm","clk":"11827785816","pt":1723364621143,"mc":[{"id":"1.231582261","rc":[{"batb":[[1,2.42,12.68],[2,2.4,12.86]],"ltp":2.46,"tv":8.72,"id":655}]}]}
{"op":"mcm","clk":"11827785949","pt":1723364623728,"mc":[{"id":"1.231582261","rc":[{"batb":[[0,2.44,4]],"ltp":2.46,"tv":8.72,"id":655}]}]}
{"op":"mcm","clk":"11827786110","pt":1723364626351,"mc":[{"id":"1.231582261","rc":[{"batb":[[0,2.44,10]],"ltp":2.46,"tv":8.72,"id":655}]}]}
{"op":"mcm","clk":"11827786307","pt":1723364629816,"mc":[{"id":"1.231582261","rc":[{"batb":[[0,2.42,12.68],[1,2.4,12.86],[2,2.34,29.13]],"ltp":2.46,"tv":8.72,"id":655}]}]}
{"op":"mcm","clk":"11827786354","pt":1723364630738,"mc":[{"id":"1.231582261","rc":[{"batb":[[0,2.44,4],[1,2.42,12.68],[2,2.4,12.86]],"ltp":2.46,"tv":8.72,"id":655}]}]}
{"op":"mcm","clk":"11827786479","pt":1723364633417,"mc":[{"id":"1.231582261","rc":[{"batb":[[0,2.44,10]],"ltp":2.46,"tv":8.72,"id":655}]}]}
{"op":"mcm","clk":"11827786706","pt":1723364636873,"mc":[{"id":"1.231582261","rc":[{"batb":[[0,2.44,4]],"ltp":2.46,"tv":8.72,"id":655}]}]}
{"op":"mcm","clk":"11827786857","pt":1723364639242,"mc":[{"id":"1.231582261","rc":[{"batb":[[0,2.46,10]],"ltp":2.46,"tv":8.72,"id":655}]}]}
{"op":"mcm","clk":"11827787115","pt":1723364642861,"mc":[{"id":"1.231582261","rc":[{"batb":[[0,2.44,4]],"ltp":2.46,"tv":8.72,"id":655}]}]}
{"op":"mcm","clk":"11827787272","pt":1723364645042,"mc":[{"id":"1.231582261","rc":[{"batb":[[0,2.42,12.68],[1,2.4,12.86],[2,2.34,29.13]],"ltp":2.46,"tv":8.72,"id":655}]}]}
{"op":"mcm","clk":"11827787332","pt":1723364645873,"mc":[{"id":"1.231582261","rc":[{"batb":[[0,2.44,10],[1,2.42,12.68],[2,2.4,12.86]],"ltp":2.46,"tv":8.72,"id":655}]}]}
{"op":"mcm","clk":"11827787574","pt":1723364649285,"mc":[{"id":"1.231582261","rc":[{"batb":[[0,2.46,4]],"ltp":2.46,"tv":8.72,"id":655}]}]}
{"op":"mcm","clk":"11827787749","pt":1723364651760,"mc":[{"id":"1.231582261","rc":[{"batb":[[0,2.44,10]],"ltp":2.46,"tv":8.72,"id":655}]}]}
{"op":"mcm","clk":"11827787983","pt":1723364655274,"mc":[{"id":"1.231582261","rc":[{"batb":[[0,2.46,4]],"ltp":2.46,"tv":8.72,"id":655}]}]}
{"op":"mcm","clk":"11827788138","pt":1723364657446,"mc":[{"id":"1.231582261","rc":[{"batb":[[0,2.42,12.68],[1,2.4,12.86],[2,2.34,29.13]],"ltp":2.46,"tv":8.72,"id":655}]}]}
{"op":"mcm","clk":"11827788145","pt":1723364657597,"mc":[{"id":"1.231582261","rc":[{"batb":[[0,2.48,10],[1,2.42,12.68],[2,2.4,12.86]],"ltp":2.46,"tv":8.72,"id":655}]}]}
{"op":"mcm","clk":"11827788275","pt":1723364659355,"mc":[{"id":"1.231582261","rc":[{"batb":[[1,1.63,21],[2,1.37,8.76]],"ltp":1.64,"tv":216.42,"id":2120}]}]}
{"op":"mcm","clk":"11827788331","pt":1723364659982,"mc":[{"id":"1.231582261","rc":[{"batb":[[0,2.5,4],[1,2.48,10],[2,2.42,12.68]],"ltp":2.46,"tv":8.72,"id":655},{"batb":[[2,1.55,32.74]],"ltp":1.64,"tv":216.42,"id":2120}]}]}
{"op":"mcm","clk":"11827788412","pt":1723364660952,"mc":[{"id":"1.231582261","rc":[{"batb":[[1,2.42,12.68],[2,2.4,12.86]],"ltp":2.46,"tv":8.72,"id":655}]}]}
{"op":"mcm","clk":"11827788499","pt":1723364662294,"mc":[{"id":"1.231582261","rc":[{"batb":[[0,2.42,12.68],[1,2.4,12.86],[2,1.3,1000]],"ltp":2.46,"tv":8.72,"id":655}]}]}
{"op":"mcm","clk":"11827788539","pt":1723364662869,"mc":[{"id":"1.231582261","rc":[{"batb":[[0,2.4,12.86],[1,1.3,1000],[2,1.08,7.85]],"ltp":2.46,"tv":8.72,"id":655}]}]}
{"op":"mcm","clk":"11827788611","pt":1723364663859,"mc":[{"id":"1.231582261","rc":[{"batb":[[0,2.42,10],[1,2.4,12.86],[2,2.34,29.13]],"ltp":2.46,"tv":8.72,"id":655},{"batb":[[1,1.64,61],[2,1.63,21]],"ltp":1.64,"tv":216.42,"id":2120}]}]}
{"op":"mcm","clk":"11827788712","pt":1723364665363,"mc":[{"id":"1.231582261","rc":[{"batb":[[0,2.44,4],[1,2.42,10],[2,2.4,12.86]],"ltp":2.46,"tv":8.72,"id":655}]}]}
{"op":"mcm","clk":"11827788747","pt":1723364665881,"mc":[{"id":"1.231582261","rc":[{"batb":[[1,2.42,22.68]],"ltp":2.46,"tv":8.72,"id":655},{"batb":[[1,1.64,89.14]],"ltp":1.64,"tv":216.42,"id":2120}]}]}
{"op":"mcm","clk":"11827788845","pt":1723364667298,"mc":[{"id":"1.231582261","rc":[{"batb":[[1,2.42,12.68]],"ltp":2.46,"tv":8.72,"id":655}]}]}
{"op":"mcm","clk":"11827788888","pt":1723364667863,"mc":[{"id":"1.231582261","rc":[{"batb":[[0,2.42,12.68],[1,2.4,12.86],[2,2.34,29.13]],"ltp":2.46,"tv":8.72,"id":655}]}]}
{"op":"mcm","clk":"11827789132","pt":1723364671075,"mc":[{"id":"1.231582261","rc":[{"batb":[[0,2.44,14],[1,2.42,12.68],[2,2.4,12.86]],"ltp":2.46,"tv":8.72,"id":655}]}]}
{"op":"mcm","clk":"11827789296","pt":1723364673498,"mc":[{"id":"1.231582261","rc":[{"batb":[[0,2.44,10]],"ltp":2.46,"tv":8.72,"id":655}]}]}
{"op":"mcm","clk":"11827789362","pt":1723364674376,"mc":[{"id":"1.231582261","rc":[{"batb":[[0,2.42,12.68],[1,2.4,12.86],[2,2.34,29.13]],"ltp":2.46,"tv":8.72,"id":655}]}]}
{"op":"mcm","clk":"11827789473","pt":1723364675920,"mc":[{"id":"1.231582261","rc":[{"batb":[[0,2.44,4],[1,2.42,12.68],[2,2.4,12.86]],"ltp":2.46,"tv":8.72,"id":655}]}]}
{"op":"mcm","clk":"11827789637","pt":1723364678400,"mc":[{"id":"1.231582261","rc":[{"batb":[[0,2.44,10]],"ltp":2.46,"tv":8.72,"id":655}]}]}
{"op":"mcm","clk":"11827789817","pt":1723364681143,"mc":[{"id":"1.231582261","rc":[{"batb":[[0,2.46,4],[1,2.44,10],[2,2.42,12.68]],"ltp":2.46,"tv":8.72,"id":655}]}]}
{"op":"mcm","clk":"11827789852","pt":1723364681612,"mc":[{"id":"1.231582261","rc":[{"batb":[[1,2.42,12.68],[2,2.4,12.86]],"ltp":2.46,"tv":8.72,"id":655}]}]}
{"op":"mcm","clk":"11827789986","pt":1723364683418,"mc":[{"id":"1.231582261","rc":[{"batb":[[0,2.42,12.68],[1,2.4,12.86],[2,2.34,29.13]],"ltp":2.46,"tv":8.72,"id":655}]}]}
{"op":"mcm","clk":"11827790028","pt":1723364683929,"mc":[{"id":"1.231582261","rc":[{"batb":[[0,2.44,10],[1,2.42,12.68],[2,2.4,12.86]],"ltp":2.46,"tv":8.72,"id":655}]}]}
{"op":"mcm","clk":"11827790170","pt":1723364685738,"mc":[{"id":"1.231582261","rc":[{"batb":[[0,2.46,4],[1,2.44,10],[2,2.42,12.68]],"ltp":2.46,"tv":8.72,"id":655}]}]}
{"op":"mcm","clk":"11827790290","pt":1723364687197,"mc":[{"id":"1.231582261","rc":[{"batb":[[1,2.42,12.68],[2,2.4,12.86]],"ltp":2.46,"tv":8.72,"id":655}]}]}
{"op":"mcm","clk":"11827790354","pt":1723364688225,"mc":[{"id":"1.231582261","rc":[{"batb":[[0,2.42,12.68],[1,2.4,12.86],[2,2.34,29.13]],"ltp":2.46,"tv":8.72,"id":655}]}]}
{"op":"mcm","clk":"11827790533","pt":1723364690510,"mc":[{"id":"1.231582261","rc":[{"batb":[[0,2.46,4],[1,2.44,10],[2,2.42,12.68]],"ltp":2.46,"tv":8.72,"id":655}]}]}
{"op":"mcm","clk":"11827790725","pt":1723364693034,"mc":[{"id":"1.231582261","rc":[{"batb":[[0,2.44,10],[1,2.42,12.68],[2,2.4,12.86]],"ltp":2.46,"tv":8.72,"id":655}]}]}
{"op":"mcm","clk":"11827790770","pt":1723364693701,"mc":[{"id":"1.231582261","rc":[{"batb":[[0,2.42,12.68],[1,2.4,12.86],[2,2.34,29.13]],"ltp":2.46,"tv":8.72,"id":655}]}]}
{"op":"mcm","clk":"11827790957","pt":1723364696745,"mc":[{"id":"1.231582261","rc":[{"batb":[[0,2.44,14],[1,2.42,12.68],[2,2.4,12.86]],"ltp":2.46,"tv":8.72,"id":655}]}]}
{"op":"mcm","clk":"11827791107","pt":1723364699225,"mc":[{"id":"1.231582261","rc":[{"batb":[[0,2.44,10]],"ltp":2.46,"tv":8.72,"id":655}]}]}
{"op":"mcm","clk":"11827791185","pt":1723364700256,"mc":[{"id":"1.231582261","rc":[{"batb":[[0,2.42,12.68],[1,2.4,12.86],[2,2.34,29.13]],"ltp":2.46,"tv":8.72,"id":655}]}]}
{"op":"mcm","clk":"11827791338","pt":1723364702045,"mc":[{"id":"1.231582261","rc":[{"batb":[[0,2.44,4],[1,2.42,12.68],[2,2.4,12.86]],"ltp":2.46,"tv":8.72,"id":655}]}]}
{"op":"mcm","clk":"11827791440","pt":1723364703255,"mc":[{"id":"1.231582261","rc":[{"batb":[[0,2.46,10],[1,2.44,4],[2,2.42,12.68]],"ltp":2.46,"tv":8.72,"id":655}]}]}
{"op":"mcm","clk":"11827791542","pt":1723364704531,"mc":[{"id":"1.231582261","rc":[{"batb":[[1,2.42,12.68],[2,2.4,12.86]],"ltp":2.46,"tv":8.72,"id":655}]}]}
{"op":"mcm","clk":"11827791802","pt":1723364707439,"mc":[{"id":"1.231582261","rc":[{"batb":[[0,2.44,4]],"ltp":2.46,"tv":8.72,"id":655}]}]}
{"op":"mcm","clk":"11827792053","pt":1723364710237,"mc":[{"id":"1.231582261","rc":[{"batb":[[0,2.44,10]],"ltp":2.46,"tv":8.72,"id":655}]}]}
{"op":"mcm","clk":"11827792236","pt":1723364712662,"mc":[{"id":"1.231582261","rc":[{"batb":[[0,2.46,4],[1,2.44,10],[2,2.42,12.68]],"ltp":2.46,"tv":8.72,"id":655}]}]}
{"op":"mcm","clk":"11827792293","pt":1723364713542,"mc":[{"id":"1.231582261","rc":[{"batb":[[1,2.42,12.68],[2,2.4,12.86]],"ltp":2.46,"tv":8.72,"id":655}]}]}
{"op":"mcm","clk":"11827792423","pt":1723364715043,"mc":[{"id":"1.231582261","rc":[{"batb":[[0,2.42,12.68],[1,2.4,12.86],[2,2.34,29.13]],"ltp":2.46,"tv":8.72,"id":655}]}]}
{"op":"mcm","clk":"11827792677","pt":1723364717758,"mc":[{"id":"1.231582261","rc":[{"batb":[[0,2.44,14],[1,2.42,12.68],[2,2.4,12.86]],"ltp":2.46,"tv":8.72,"id":655}]}]}
{"op":"mcm","clk":"11827792886","pt":1723364720248,"mc":[{"id":"1.231582261","rc":[{"batb":[[0,2.44,10]],"ltp":2.46,"tv":8.72,"id":655}]}]}
{"op":"mcm","clk":"11827792978","pt":1723364721380,"mc":[{"id":"1.231582261","rc":[{"batb":[[0,2.42,12.68],[1,2.4,12.86],[2,2.34,29.13]],"ltp":2.46,"tv":8.72,"id":655}]}]}
{"op":"mcm","clk":"11827793180","pt":1723364724077,"mc":[{"id":"1.231582261","rc":[{"batb":[[0,2.44,14],[1,2.42,12.68],[2,2.4,12.86]],"ltp":2.46,"tv":8.72,"id":655}]}]}
{"op":"mcm","clk":"11827793368","pt":1723364726460,"mc":[{"id":"1.231582261","rc":[{"batb":[[0,2.44,10]],"ltp":2.46,"tv":8.72,"id":655}]}]}
{"op":"mcm","clk":"11827793433","pt":1723364727604,"mc":[{"id":"1.231582261","rc":[{"batb":[[0,2.42,12.68],[1,2.4,12.86],[2,2.34,29.13]],"ltp":2.46,"tv":8.72,"id":655}]}]}
{"op":"mcm","clk":"11827793797","pt":1723364732063,"mc":[{"id":"1.231582261","rc":[{"batb":[[0,2.44,14],[1,2.42,12.68],[2,2.4,12.86]],"ltp":2.46,"tv":8.72,"id":655}]}]}
{"op":"mcm","clk":"11827794009","pt":1723364735102,"mc":[{"id":"1.231582261","rc":[{"batb":[[0,2.44,10]],"ltp":2.46,"tv":8.72,"id":655}]}]}
{"op":"mcm","clk":"11827794057","pt":1723364735618,"mc":[{"id":"1.231582261","rc":[{"batb":[[0,2.42,12.68],[1,2.4,12.86],[2,2.34,29.13]],"ltp":2.46,"tv":8.72,"id":655}]}]}
{"op":"mcm","clk":"11827794309","pt":1723364738782,"mc":[{"id":"1.231582261","rc":[{"batb":[[0,2.44,14],[1,2.42,12.68],[2,2.4,12.86]],"ltp":2.46,"tv":8.72,"id":655}]}]}
{"op":"mcm","clk":"11827794491","pt":1723364741421,"mc":[{"id":"1.231582261","rc":[{"batb":[[0,2.44,10]],"ltp":2.46,"tv":8.72,"id":655}]}]}
{"op":"mcm","clk":"11827794533","pt":1723364742187,"mc":[{"id":"1.231582261","rc":[{"batb":[[0,2.42,12.68],[1,2.4,12.86],[2,2.34,29.13]],"ltp":2.46,"tv":8.72,"id":655}]}]}
{"op":"mcm","clk":"11827794769","pt":1723364746201,"mc":[{"id":"1.231582261","rc":[{"batb":[[0,2.44,14],[1,2.42,12.68],[2,2.4,12.86]],"ltp":2.46,"tv":8.72,"id":655}]}]}
{"op":"mcm","clk":"11827794942","pt":1723364748583,"mc":[{"id":"1.231582261","rc":[{"batb":[[0,2.44,10]],"ltp":2.46,"tv":8.72,"id":655}]}]}
{"op":"mcm","clk":"11827795008","pt":1723364749708,"mc":[{"id":"1.231582261","rc":[{"batb":[[0,2.42,12.68],[1,2.4,12.86],[2,2.34,29.13]],"ltp":2.46,"tv":8.72,"id":655}]}]}
{"op":"mcm","clk":"11827795129","pt":1723364751308,"mc":[{"id":"1.231582261","rc":[{"batb":[[0,2.44,4],[1,2.42,12.68],[2,2.4,12.86]],"ltp":2.46,"tv":8.72,"id":655}]}]}
{"op":"mcm","clk":"11827795433","pt":1723364756240,"mc":[{"id":"1.231582261","rc":[{"batb":[[0,2.46,10]],"ltp":2.46,"tv":8.72,"id":655}]}]}
{"op":"mcm","clk":"11827795796","pt":1723364761320,"mc":[{"id":"1.231582261","rc":[{"batb":[[0,2.44,4]],"ltp":2.46,"tv":8.72,"id":655}]}]}
