{"op":"mcm","clk":"11883939470","pt":1724078118821,"mc":[{"id":"1.232019056","marketDefinition":{"bspMarket":false,"turnInPlayEnabled":true,"persistenceEnabled":true,"marketBaseRate":5.0,"eventId":"33508297","eventTypeId":"4","numberOfWinners":1,"bettingType":"ODDS","marketType":"MATCH_ODDS","marketTime":"2024-08-20T18:00:00.000Z","suspendTime":"2024-08-20T18:00:00.000Z","bspReconciled":false,"complete":true,"inPlay":false,"crossMatching":true,"runnersVoidable":false,"numberOfActiveRunners":2,"betDelay":0,"status":"OPEN","runners":[{"status":"ACTIVE","sortPriority":1,"id":72857117,"name":"Caribbean Giants"},{"status":"ACTIVE","sortPriority":2,"id":72857114,"name":"Boca Raton Trailblazers"}],"regulators":["MR_INT"],"countryCode":"GB","discountAllowed":false,"timezone":"GMT","openDate":"2024-08-20T18:00:00.000Z","version":6086446832,"name":"Match Odds","eventName":"Caribbean Giants v Boca Raton Trailblazers"},"rc":[{"batb":[[0,1.03,200],[1,1.02,200],[2,1.01,220]],"ltp":0.0,"tv":0.0,"id":72857114},{"batb":[[0,1.03,200],[1,1.02,200],[2,1.01,220]],"ltp":0.0,"tv":0.0,"id":72857117}]}]}
{"op":"mcm","clk":"11883939523","pt":1724078119824,"mc":[{"id":"1.232019056","marketDefinition":{"bspMarket":false,"turnInPlayEnabled":true,"persistenceEnabled":true,"marketBaseRate":5.0,"eventId":"33508297","eventTypeId":"4","numberOfWinners":1,"bettingType":"ODDS","marketType":"MATCH_ODDS","marketTime":"2024-08-20T18:00:00.000Z","suspendTime":"2024-08-20T18:00:00.000Z","bspReconciled":false,"complete":true,"inPlay":false,"crossMatching":true,"runnersVoidable":false,"numberOfActiveRunners":2,"betDelay":0,"status":"OPEN","runners":[{"status":"ACTIVE","sortPriority":1,"id":72857117,"name":"Caribbean Giants"},{"status":"ACTIVE","sortPriority":2,"id":72857114,"name":"Boca Raton Trailblazers"}],"regulators":["MR_INT"],"countryCode":"GB","discountAllowed":true,"timezone":"GMT","openDate":"2024-08-20T18:00:00.000Z","version":6086446832,"name":"Match Odds","eventName":"Caribbean Giants v Boca Raton Trailblazers"}}]}
{"op":"mcm","clk":"11884014931","pt":1724079835908,"mc":[{"id":"1.232019056","rc":[{"batl":[[0,34,3.58]],"ltp":0.0,"tv":0.0,"id":72857114}]}]}
{"op":"mcm","clk":"11884016039","pt":1724079859840,"mc":[{"id":"1.232019056","rc":[{"batl":[[1,36,5.71]],"ltp":0.0,"tv":0.0,"id":72857114}]}]}
{"op":"mcm","clk":"11884030495","pt":1724080144925,"mc":[{"id":"1.232019056","rc":[{"batl":[[0,36,5.71],[1,36,0]],"ltp":0.0,"tv":0.0,"id":72857114}]}]}
{"op":"mcm","clk":"11884131223","pt":1724081458702,"mc":[{"id":"1.232019056","rc":[{"batb":[[2,1.01,480.89]],"ltp":0.0,"tv":0.0,"id":72857117}]}]}
{"op":"mcm","clk":"11884131240","pt":1724081458962,"mc":[{"id":"1.232019056","rc":[{"batb":[[2,1.01,480.89]],"ltp":0.0,"tv":0.0,"id":72857114}]}]}
{"op":"mcm","clk":"11884175691","pt":1724082066422,"mc":[{"id":"1.232019056","rc":[{"batb":[[0,1.11,24.82],[1,1.03,200],[2,1.02,200]],"ltp":0.0,"tv":0.0,"id":72857117}]}]}
{"op":"mcm","clk":"11884176426","pt":1724082074836,"mc":[{"id":"1.232019056","rc":[{"batb":[[0,1.12,71.37],[1,1.11,24.82],[2,1.03,200]],"ltp":0.0,"tv":0.0,"id":72857117}]}]}
{"op":"mcm","clk":"11884176897","pt":1724082080439,"mc":[{"id":"1.232019056","rc":[{"batb":[[0,1.11,24.82],[1,1.03,200],[2,1.02,200]],"ltp":0.0,"tv":0.0,"id":72857114}]}]}
{"op":"mcm","clk":"11884187138","pt":1724082226743,"mc":[{"id":"1.232019056","rc":[{"batb":[[0,1.12,71.37],[1,1.11,24.82],[2,1.03,200]],"ltp":0.0,"tv":0.0,"id":72857114}]}]}
{"op":"mcm","clk":"11884236263","pt":1724082942446,"mc":[{"id":"1.232019056","rc":[{"batb":[[0,1.2,250],[1,1.12,71.37],[2,1.11,24.82]],"ltp":0.0,"tv":0.0,"id":72857114},{"batb":[[0,1.2,250],[1,1.12,71.37],[2,1.11,24.82]],"ltp":0.0,"tv":0.0,"id":72857117}]}]}
{"op":"mcm","clk":"11884306881","pt":1724083875581,"mc":[{"id":"1.232019056","rc":[{"batb":[[1,1.12,71.42],[2,1.11,24.83]],"ltp":0.0,"tv":0.0,"id":72857114},{"batb":[[1,1.11,24.83],[2,1.03,200]],"ltp":0.0,"tv":0.0,"id":72857117}]}]}
{"op":"mcm","clk":"11884309775","pt":1724083913491,"mc":[{"id":"1.232019056","rc":[{"batb":[[0,1.21,40.81],[1,1.2,250],[2,1.11,24.83]],"ltp":0.0,"tv":0.0,"id":72857117}]}]}
{"op":"mcm","clk":"11884316139","pt":1724083996786,"mc":[{"id":"1.232019056","rc":[{"batb":[[0,1.21,6.02],[1,1.2,250],[2,1.12,71.42]],"ltp":0.0,"tv":0.0,"id":72857114},{"batb":[[0,1.22,7.12],[1,1.21,40.81],[2,1.2,250]],"ltp":0.0,"tv":0.0,"id":72857117}]}]}
{"op":"mcm","clk":"11884318670","pt":1724084026936,"mc":[{"id":"1.232019056","rc":[{"batb":[[2,1.11,24.83]],"ltp":0.0,"tv":0.0,"id":72857114}]}]}
{"op":"mcm","clk":"11884322942","pt":1724084082006,"mc":[{"id":"1.232019056","rc":[{"batb":[[0,1.22,38.96],[1,1.21,6.02],[2,1.2,250]],"ltp":0.0,"tv":0.0,"id":72857114}]}]}
{"op":"mcm","clk":"11884334484","pt":1724084214906,"mc":[{"id":"1.232019056","rc":[{"batb":[[0,1.22,7.65]],"ltp":0.0,"tv":0.0,"id":72857117}]}]}
{"op":"mcm","clk":"11884335434","pt":1724084226520,"mc":[{"id":"1.232019056","rc":[{"batb":[[0,1.22,39.49]],"ltp":0.0,"tv":0.0,"id":72857114}]}]}
{"op":"mcm","clk":"11884455039","pt":1724085714418,"mc":[{"id":"1.232019056","rc":[{"batb":[[1,1.2,250],[2,1.11,24.83]],"ltp":0.0,"tv":0.0,"id":72857117}]}]}
{"op":"mcm","clk":"11884457840","pt":1724085755376,"mc":[{"id":"1.232019056","rc":[{"batb":[[0,1.23,37.8],[1,1.22,7.12],[2,1.2,250]],"ltp":0.0,"tv":0.0,"id":72857117}]}]}
{"op":"mcm","clk":"11884476427","pt":1724085882087,"mc":[{"id":"1.232019056","rc":[{"batb":[[0,1.21,6.56],[1,1.2,250],[2,1.11,24.83]],"ltp":0.0,"tv":0.0,"id":72857114}]}]}
{"op":"mcm","clk":"11884479360","pt":1724085921224,"mc":[{"id":"1.232019056","rc":[{"batb":[[0,1.22,39.49],[1,1.21,6.02],[2,1.2,250]],"ltp":0.0,"tv":0.0,"id":72857114}]}]}
{"op":"mcm","clk":"11884539171","pt":1724086768546,"mc":[{"id":"1.232019056","rc":[{"batb":[[0,1.23,6.56],[1,1.22,38.96]],"ltp":0.0,"tv":0.0,"id":72857114},{"batb":[[0,1.24,7.65],[1,1.23,37.26]],"ltp":0.0,"tv":0.0,"id":72857117}]}]}
{"op":"mcm","clk":"11884618956","pt":1724087555706,"mc":[{"id":"1.232019056","rc":[{"batb":[[1,1.22,38.97]],"ltp":0.0,"tv":0.0,"id":72857114},{"batb":[[1,1.2,250],[2,1.11,24.84]],"ltp":0.0,"tv":0.0,"id":72857117}]}]}
{"op":"mcm","clk":"11884620853","pt":1724087575766,"mc":[{"id":"1.232019056","rc":[{"batb":[[0,1.25,34.83],[1,1.24,7.12],[2,1.2,250]],"ltp":0.0,"tv":0.0,"id":72857117}]}]}
{"op":"mcm","clk":"11884635192","pt":1724087721490,"mc":[{"id":"1.232019056","rc":[{"batb":[[1,1.2,250],[2,1.11,24.84]],"ltp":0.0,"tv":0.0,"id":72857114}]}]}
{"op":"mcm","clk":"11884637089","pt":1724087740213,"mc":[{"id":"1.232019056","rc":[{"batb":[[0,1.24,36.26],[1,1.23,6.02],[2,1.2,250]],"ltp":0.0,"tv":0.0,"id":72857114}]}]}
{"op":"mcm","clk":"11884821631","pt":1724089376040,"mc":[{"id":"1.232019056","rc":[{"batb":[[0,1.24,7.65],[1,1.2,250],[2,1.11,24.84]],"ltp":0.0,"tv":0.0,"id":72857117}]}]}
{"op":"mcm","clk":"11884831338","pt":1724089462770,"mc":[{"id":"1.232019056","rc":[{"batb":[[0,1.25,6.56],[1,1.24,35.72]],"ltp":0.0,"tv":0.0,"id":72857114},{"batb":[[0,1.21,7.65]],"ltp":0.0,"tv":0.0,"id":72857117}]}]}
{"op":"mcm","clk":"11884838583","pt":1724089530318,"mc":[{"id":"1.232019056","rc":[{"batb":[[0,1.4,27.86],[1,1.25,6.02],[2,1.24,35.72]],"ltp":0.0,"tv":0.0,"id":72857114}]}]}
{"op":"mcm","clk":"11884839258","pt":1724089536803,"mc":[{"id":"1.232019056","rc":[{"batb":[[0,1.22,39.51],[1,1.21,7.12],[2,1.2,250]],"ltp":0.0,"tv":0.0,"id":72857117}]}]}
{"op":"mcm","clk":"11884839640","pt":1724089540433,"mc":[{"id":"1.232019056","rc":[{"batb":[[2,1.2,250]],"ltp":0.0,"tv":0.0,"id":72857114}]}]}
{"op":"mcm","clk":"11884842080","pt":1724089566751,"mc":[{"id":"1.232019056","rc":[{"batb":[[0,1.25,6.56],[1,1.2,250],[2,1.11,24.84]],"ltp":0.0,"tv":0.0,"id":72857114}]}]}
{"op":"mcm","clk":"11884855990","pt":1724089698908,"mc":[{"id":"1.232019056","rc":[{"batb":[[0,1.26,33.51],[1,1.25,6.02],[2,1.2,250]],"ltp":0.0,"tv":0.0,"id":72857114}]}]}
{"op":"mcm","clk":"11884886142","pt":1724090006395,"mc":[{"id":"1.232019056","rc":[{"batl":[[0,4,0.77]],"ltp":0.0,"tv":0.0,"id":72857114},{"batl":[[0,4,0.77]],"ltp":0.0,"tv":0.0,"id":72857117}]}]}
{"op":"mcm","clk":"11884887141","pt":1724090015001,"mc":[{"id":"1.232019056","rc":[{"batl":[[0,5,1.54]],"ltp":0.0,"tv":0.0,"id":72857114},{"batl":[[0,5,1.54]],"ltp":0.0,"tv":0.0,"id":72857117}]}]}
{"op":"mcm","clk":"11884887657","pt":1724090023125,"mc":[{"id":"1.232019056","rc":[{"batl":[[1,6,0.77]],"ltp":0.0,"tv":0.0,"id":72857114},{"batl":[[1,6,0.77]],"ltp":0.0,"tv":0.0,"id":72857117}]}]}
{"op":"mcm","clk":"11884888292","pt":1724090033012,"mc":[{"id":"1.232019056","rc":[{"batl":[[1,9,1.54]],"ltp":0.0,"tv":0.0,"id":72857114},{"batl":[[1,9,1.54]],"ltp":0.0,"tv":0.0,"id":72857117}]}]}
{"op":"mcm","clk":"11885003390","pt":1724091174935,"mc":[{"id":"1.232019056","rc":[{"batb":[[0,1.26,33.5],[1,1.25,6.02]],"ltp":0.0,"tv":0.0,"id":72857114},{"batb":[[0,1.22,39.49],[1,1.21,7.11]],"ltp":0.0,"tv":0.0,"id":72857117}]}]}
{"op":"mcm","clk":"11885026330","pt":1724091337179,"mc":[{"id":"1.232019056","rc":[{"batb":[[0,1.21,7.65],[1,1.2,250],[2,1.11,24.84]],"ltp":0.0,"tv":0.0,"id":72857117}]}]}
{"op":"mcm","clk":"11885041639","pt":1724091468539,"mc":[{"id":"1.232019056","rc":[{"batb":[[0,1.34,25.74],[1,1.21,7.11],[2,1.2,250]],"ltp":0.0,"tv":0.0,"id":72857117}]}]}
{"op":"mcm","clk":"11885045184","pt":1724091499061,"mc":[{"id":"1.232019056","rc":[{"batb":[[0,1.25,6.56],[1,1.2,250],[2,1.11,24.84]],"ltp":0.0,"tv":0.0,"id":72857114}]}]}
{"op":"mcm","clk":"11885060226","pt":1724091627072,"mc":[{"id":"1.232019056","rc":[{"batb":[[0,1.34,25.74],[1,1.25,6.02],[2,1.2,250]],"ltp":0.0,"tv":0.0,"id":72857114}]}]}
{"op":"mcm","clk":"11885083298","pt":1724091806515,"mc":[{"id":"1.232019056","rc":[{"batb":[[0,1.34,25.2]],"ltp":0.0,"tv":0.0,"id":72857117}]}]}
{"op":"mcm","clk":"11885083887","pt":1724091810921,"mc":[{"id":"1.232019056","rc":[{"batb":[[0,1.34,25.2]],"ltp":0.0,"tv":0.0,"id":72857114}]}]}
{"op":"mcm","clk":"11885093570","pt":1724091886132,"mc":[{"id":"1.232019056","rc":[{"batb":[[1,1.2,250],[2,1.11,24.84]],"ltp":0.0,"tv":0.0,"id":72857114},{"batb":[[1,1.2,250],[2,1.11,24.84]],"ltp":0.0,"tv":0.0,"id":72857117}]}]}
{"op":"mcm","clk":"11885214487","pt":1724092821214,"mc":[{"id":"1.232019056","rc":[{"batb":[[1,1.11,24.84],[2,1.03,200]],"ltp":0.0,"tv":0.0,"id":72857114},{"batb":[[1,1.11,24.84],[2,1.03,200]],"ltp":0.0,"tv":0.0,"id":72857117}]}]}
{"op":"mcm","clk":"11885246030","pt":1724093061742,"mc":[{"id":"1.232019056","rc":[{"batb":[[1,1.13,384.62],[2,1.11,24.84]],"ltp":0.0,"tv":0.0,"id":72857114},{"batb":[[1,1.13,384.62],[2,1.11,24.84]],"ltp":0.0,"tv":0.0,"id":72857117}]}]}
{"op":"mcm","clk":"11885246105","pt":1724093062363,"mc":[{"id":"1.232019056","rc":[{"batb":[[0,1.43,116.28],[1,1.38,131.58],[2,1.34,25.2]],"ltp":0.0,"tv":0.0,"id":72857114},{"batb":[[0,1.43,116.28],[1,1.38,131.58],[2,1.34,25.2]],"ltp":0.0,"tv":0.0,"id":72857117}]}]}
{"op":"mcm","clk":"11885270770","pt":1724093269000,"mc":[{"id":"1.232019056","rc":[{"batb":[[2,1.33,151.52]],"ltp":0.0,"tv":0.0,"id":72857117}]}]}
{"op":"mcm","clk":"11885280686","pt":1724093362825,"mc":[{"id":"1.232019056","rc":[{"batb":[[0,1.44,19.48],[1,1.43,116.28],[2,1.38,131.58]],"ltp":0.0,"tv":0.0,"id":72857117}]}]}
{"op":"mcm","clk":"11885288382","pt":1724093427266,"mc":[{"id":"1.232019056","rc":[{"batb":[[2,1.33,151.52]],"ltp":0.0,"tv":0.0,"id":72857114}]}]}
{"op":"mcm","clk":"11885297075","pt":1724093509470,"mc":[{"id":"1.232019056","rc":[{"batb":[[0,1.43,116.82]],"ltp":0.0,"tv":0.0,"id":72857114}]}]}
{"op":"mcm","clk":"11885298117","pt":1724093519676,"mc":[{"id":"1.232019056","rc":[{"batb":[[0,1.44,20.01],[1,1.43,116.28],[2,1.38,131.58]],"ltp":0.0,"tv":0.0,"id":72857114}]}]}
{"op":"mcm","clk":"11885298368","pt":1724093521867,"mc":[{"id":"1.232019056","rc":[{"batb":[[0,1.44,20.01]],"ltp":0.0,"tv":0.0,"id":72857117}]}]}
{"op":"mcm","clk":"11885392612","pt":1724094484424,"mc":[{"id":"1.232019056","rc":[{"batb":[[0,1.44,26.34]],"ltp":0.0,"tv":0.0,"id":72857114},{"batb":[[0,1.44,26.28]],"ltp":0.0,"tv":0.0,"id":72857117}]}]}
{"op":"mcm","clk":"11885470918","pt":1724095163181,"mc":[{"id":"1.232019056","rc":[{"batb":[[0,1.44,6.79]],"ltp":0.0,"tv":0.0,"id":72857117}]}]}
{"op":"mcm","clk":"11885472396","pt":1724095177804,"mc":[{"id":"1.232019056","rc":[{"batb":[[0,1.44,12.83]],"ltp":0.0,"tv":0.0,"id":72857117}]}]}
{"op":"mcm","clk":"11885476202","pt":1724095214924,"mc":[{"id":"1.232019056","rc":[{"batb":[[0,1.45,19.59],[1,1.44,12.3],[2,1.43,116.28]],"ltp":0.0,"tv":0.0,"id":72857117}]}]}
{"op":"mcm","clk":"11885476304","pt":1724095215953,"mc":[{"id":"1.232019056","rc":[{"batb":[[1,1.44,6.26]],"ltp":0.0,"tv":0.0,"id":72857117}]}]}
{"op":"mcm","clk":"11885487248","pt":1724095320161,"mc":[{"id":"1.232019056","rc":[{"batb":[[0,1.44,12.9]],"ltp":0.0,"tv":0.0,"id":72857114}]}]}
{"op":"mcm","clk":"11885492449","pt":1724095367338,"mc":[{"id":"1.232019056","rc":[{"batb":[[0,1.45,19.59],[1,1.44,12.37],[2,1.43,116.28]],"ltp":0.0,"tv":0.0,"id":72857114}]}]}
{"op":"mcm","clk":"11885492623","pt":1724095369054,"mc":[{"id":"1.232019056","rc":[{"batb":[[1,1.44,6.32]],"ltp":0.0,"tv":0.0,"id":72857114}]}]}
{"op":"mcm","clk":"11885666935","pt":1724097015093,"mc":[{"id":"1.232019056","rc":[{"batb":[[0,1.44,6.79],[1,1.43,116.28],[2,1.38,131.58]],"ltp":0.0,"tv":0.0,"id":72857117}]}]}
{"op":"mcm","clk":"11885667767","pt":1724097023901,"mc":[{"id":"1.232019056","rc":[{"batb":[[0,1.44,12.83]],"ltp":0.0,"tv":0.0,"id":72857117}]}]}
{"op":"mcm","clk":"11885675609","pt":1724097104408,"mc":[{"id":"1.232019056","rc":[{"batb":[[0,1.45,19.59],[1,1.44,6.26],[2,1.43,116.28]],"ltp":0.0,"tv":0.0,"id":72857117}]}]}
{"op":"mcm","clk":"11885675779","pt":1724097106282,"mc":[{"id":"1.232019056","rc":[{"trd":[[1.54,0.54]],"batb":[[0,1.45,19.05]],"ltp":1.54,"tv":0.53,"id":72857114},{"trd":[[2.86,0.29]],"batb":[[0,1.55,1.4],[1,1.45,19.05],[2,1.44,6.26]],"ltp":2.86,"tv":0.29,"id":72857117}],"tv":0.82}]}
{"op":"mcm","clk":"11885676268","pt":1724097110981,"mc":[{"id":"1.232019056","rc":[{"batb":[[0,1.45,19.59],[1,1.44,6.26],[2,1.43,116.28]],"ltp":2.86,"tv":0.29,"id":72857117}]}]}
{"op":"mcm","clk":"11885676848","pt":1724097117003,"mc":[{"id":"1.232019056","rc":[{"batb":[[0,3,1.15],[1,1.45,19.59],[2,1.44,6.26]],"ltp":2.86,"tv":0.29,"id":72857117}]}]}
{"op":"mcm","clk":"11885677121","pt":1724097119815,"mc":[{"id":"1.232019056","rc":[{"trd":[[1.5,2.31]],"batb":[[0,1.5,1.27],[1,1.45,19.05],[2,1.44,6.32]],"ltp":1.5,"tv":2.84,"id":72857114},{"trd":[[3,1.15]],"batb":[[0,1.45,19.59],[1,1.44,6.26],[2,1.43,116.28]],"ltp":3.0,"tv":1.44,"id":72857117}],"tv":4.29}]}
{"op":"mcm","clk":"11885678124","pt":1724097130534,"mc":[{"id":"1.232019056","rc":[{"batb":[[0,1.45,19.05],[1,1.44,6.32],[2,1.43,116.28]],"ltp":1.5,"tv":2.84,"id":72857114}]}]}
{"op":"mcm","clk":"11885681789","pt":1724097167486,"mc":[{"id":"1.232019056","rc":[{"batb":[[0,1.44,6.32],[1,1.43,116.28],[2,1.38,131.58]],"ltp":1.5,"tv":2.84,"id":72857114}]}]}
{"op":"mcm","clk":"11885682698","pt":1724097176492,"mc":[{"id":"1.232019056","rc":[{"batb":[[0,1.44,12.34]],"ltp":1.5,"tv":2.84,"id":72857114}]}]}
{"op":"mcm","clk":"11885691295","pt":1724097262526,"mc":[{"id":"1.232019056","rc":[{"batb":[[0,1.45,19.05],[1,1.44,12.34],[2,1.43,116.28]],"ltp":1.5,"tv":2.84,"id":72857114}]}]}
{"op":"mcm","clk":"11885691344","pt":1724097263199,"mc":[{"id":"1.232019056","rc":[{"batb":[[1,1.44,6.32]],"ltp":1.5,"tv":2.84,"id":72857114}]}]}
{"op":"mcm","clk":"11885742997","pt":1724098010481,"mc":[{"id":"1.232019056","rc":[{"batb":[[0,1.5,4.48],[1,1.45,19.06],[2,1.44,6.32]],"ltp":1.5,"tv":2.84,"id":72857114},{"batb":[[0,1.45,19.59]],"ltp":3.0,"tv":1.44,"id":72857117}]}]}
{"op":"mcm","clk":"11885747077","pt":1724098062437,"mc":[{"id":"1.232019056","rc":[{"batb":[[0,1.45,19.06],[1,1.44,6.32],[2,1.43,116.28]],"ltp":1.5,"tv":2.84,"id":72857114}]}]}
{"op":"mcm","clk":"11885771066","pt":1724098341702,"mc":[{"id":"1.232019056","rc":[{"batl":[[0,1.49,1.15],[1,5,1.54],[2,9,1.54]],"ltp":1.5,"tv":2.84,"id":72857114}]}]}
{"op":"mcm","clk":"11885771223","pt":1724098343682,"mc":[{"id":"1.232019056","rc":[{"batl":[[0,5,1.54],[1,9,1.54],[2,9,0]],"ltp":1.5,"tv":2.84,"id":72857114}]}]}
{"op":"mcm","clk":"11885774064","pt":1724098382386,"mc":[{"id":"1.232019056","rc":[{"trd":[[1.55,1.08]],"batb":[[0,1.45,19.06]],"batl":[[0,4,1.39],[1,6,1.54],[2,9,0.77]],"ltp":1.55,"tv":2.52,"id":72857117}],"tv":5.36}]}
{"op":"mcm","clk":"11885774195","pt":1724098383889,"mc":[{"id":"1.232019056","rc":[{"batl":[[0,5,1.54],[1,9,1.54],[2,9,0]],"ltp":1.55,"tv":2.52,"id":72857117}]}]}
{"op":"mcm","clk":"11885776528","pt":1724098411800,"mc":[{"id":"1.232019056","rc":[{"batl":[[0,1.49,1.15],[1,5,1.54],[2,9,1.54]],"ltp":1.5,"tv":2.84,"id":72857114}]}]}
{"op":"mcm","clk":"11885776727","pt":1724098413518,"mc":[{"id":"1.232019056","rc":[{"batl":[[0,5,1.54],[1,9,1.54],[2,9,0]],"ltp":1.5,"tv":2.84,"id":72857114}]}]}
{"op":"mcm","clk":"11885778341","pt":1724098435051,"mc":[{"id":"1.232019056","rc":[{"batl":[[0,1.49,1.15],[1,5,1.54],[2,9,1.54]],"ltp":1.55,"tv":2.52,"id":72857117}]}]}
{"op":"mcm","clk":"11885778491","pt":1724098436760,"mc":[{"id":"1.232019056","rc":[{"batl":[[0,5,1.54],[1,9,1.54],[2,9,0]],"ltp":1.55,"tv":2.52,"id":72857117}]}]}
{"op":"mcm","clk":"11885780413","pt":1724098462565,"mc":[{"id":"1.232019056","rc":[{"batl":[[0,1.49,1.15],[1,5,1.54],[2,9,1.54]],"ltp":1.5,"tv":2.84,"id":72857114}]}]}
{"op":"mcm","clk":"11885780519","pt":1724098464061,"mc":[{"id":"1.232019056","rc":[{"batl":[[0,5,1.54],[1,9,1.54],[2,9,0]],"ltp":1.5,"tv":2.84,"id":72857114}]}]}
{"op":"mcm","clk":"11885781650","pt":1724098477380,"mc":[{"id":"1.232019056","rc":[{"batl":[[0,1.49,1.15],[1,5,1.54],[2,9,1.54]],"ltp":1.5,"tv":2.84,"id":72857114}]}]}
{"op":"mcm","clk":"11885781870","pt":1724098480113,"mc":[{"id":"1.232019056","rc":[{"batl":[[0,5,1.54],[1,9,1.54],[2,9,0]],"ltp":1.5,"tv":2.84,"id":72857114}]}]}
{"op":"mcm","clk":"11885784056","pt":1724098505638,"mc":[{"id":"1.232019056","rc":[{"batl":[[0,1.49,1.15],[1,5,1.54],[2,9,1.54]],"ltp":1.55,"tv":2.52,"id":72857117}]}]}
{"op":"mcm","clk":"11885784268","pt":1724098508139,"mc":[{"id":"1.232019056","rc":[{"batl":[[0,5,1.54],[1,9,1.54],[2,9,0]],"ltp":1.55,"tv":2.52,"id":72857117}]}]}
{"op":"mcm","clk":"11885786242","pt":1724098532267,"mc":[{"id":"1.232019056","rc":[{"batl":[[0,1.49,1.15],[1,5,1.54],[2,9,1.54]],"ltp":1.5,"tv":2.84,"id":72857114}]}]}
{"op":"mcm","clk":"11885786415","pt":1724098534130,"mc":[{"id":"1.232019056","rc":[{"batl":[[0,5,1.54],[1,9,1.54],[2,9,0]],"ltp":1.5,"tv":2.84,"id":72857114}]}]}
{"op":"mcm","clk":"11885788152","pt":1724098555694,"mc":[{"id":"1.232019056","rc":[{"batl":[[0,1.49,1.15],[1,5,1.54],[2,9,1.54]],"ltp":1.55,"tv":2.52,"id":72857117}]}]}
{"op":"mcm","clk":"11885788293","pt":1724098557404,"mc":[{"id":"1.232019056","rc":[{"batl":[[0,5,1.54],[1,9,1.54],[2,9,0]],"ltp":1.55,"tv":2.52,"id":72857117}]}]}
{"op":"mcm","clk":"11885789962","pt":1724098576311,"mc":[{"id":"1.232019056","rc":[{"batl":[[0,1.49,1.15],[1,5,1.54],[2,9,1.54]],"ltp":1.5,"tv":2.84,"id":72857114}]}]}
{"op":"mcm","clk":"11885790098","pt":1724098577911,"mc":[{"id":"1.232019056","rc":[{"batl":[[0,5,1.54],[1,9,1.54],[2,9,0]],"ltp":1.5,"tv":2.84,"id":72857114}]}]}
{"op":"mcm","clk":"11885791222","pt":1724098590734,"mc":[{"id":"1.232019056","rc":[{"batl":[[0,1.49,1.15],[1,5,1.54],[2,9,1.54]],"ltp":1.5,"tv":2.84,"id":72857114}]}]}
{"op":"mcm","clk":"11885791364","pt":1724098592543,"mc":[{"id":"1.232019056","rc":[{"batl":[[0,5,1.54],[1,9,1.54],[2,9,0]],"ltp":1.5,"tv":2.84,"id":72857114}]}]}
{"op":"mcm","clk":"11885792810","pt":1724098611335,"mc":[{"id":"1.232019056","rc":[{"batl":[[0,1.49,1.15],[1,5,1.54],[2,9,1.54]],"ltp":1.55,"tv":2.52,"id":72857117}]}]}
{"op":"mcm","clk":"11885792957","pt":1724098613140,"mc":[{"id":"1.232019056","rc":[{"batl":[[0,5,1.54],[1,9,1.54],[2,9,0]],"ltp":1.55,"tv":2.52,"id":72857117}]}]}
{"op":"mcm","clk":"11885795450","pt":1724098643991,"mc":[{"id":"1.232019056","rc":[{"batl":[[0,1.49,1.15],[1,5,1.54],[2,9,1.54]],"ltp":1.5,"tv":2.84,"id":72857114}]}]}
{"op":"mcm","clk":"11885795653","pt":1724098646511,"mc":[{"id":"1.232019056","rc":[{"batl":[[0,5,1.54],[1,9,1.54],[2,9,0]],"ltp":1.5,"tv":2.84,"id":72857114}]}]}
{"op":"mcm","clk":"11885817695","pt":1724098904085,"mc":[{"id":"1.232019056","rc":[{"batb":[[0,1.44,6.26],[1,1.43,116.28],[2,1.38,131.58]],"ltp":1.55,"tv":2.52,"id":72857117}]}]}
{"op":"mcm","clk":"11885819226","pt":1724098922570,"mc":[{"id":"1.232019056","rc":[{"batb":[[0,1.44,12.27]],"ltp":1.55,"tv":2.52,"id":72857117}]}]}
{"op":"mcm","clk":"11885823001","pt":1724098966739,"mc":[{"id":"1.232019056","rc":[{"batb":[[0,1.45,19.06],[1,1.44,6.26],[2,1.43,116.28]],"ltp":1.55,"tv":2.52,"id":72857117}]}]}
{"op":"mcm","clk":"11885831732","pt":1724099062774,"mc":[{"id":"1.232019056","rc":[{"batb":[[0,1.44,6.32],[1,1.43,116.28],[2,1.38,131.58]],"ltp":1.5,"tv":2.84,"id":72857114}]}]}
{"op":"mcm","clk":"11885832745","pt":1724099074350,"mc":[{"id":"1.232019056","rc":[{"batb":[[0,1.44,12.34]],"ltp":1.5,"tv":2.84,"id":72857114}]}]}
{"op":"mcm","clk":"11885851992","pt":1724099273003,"mc":[{"id":"1.232019056","rc":[{"batb":[[0,1.45,19.06],[1,1.44,12.34],[2,1.43,116.28]],"ltp":1.5,"tv":2.84,"id":72857114}]}]}
{"op":"mcm","clk":"11885852161","pt":1724099274767,"mc":[{"id":"1.232019056","rc":[{"batb":[[1,1.44,6.32]],"ltp":1.5,"tv":2.84,"id":72857114}]}]}
{"op":"mcm","clk":"11885950314","pt":1724100580920,"mc":[{"id":"1.232019056","rc":[{"batb":[[0,1.55,102.39],[1,1.45,19.06],[2,1.44,6.26]],"ltp":1.55,"tv":2.52,"id":72857117}]}]}
{"op":"mcm","clk":"11885950881","pt":1724100591946,"mc":[{"id":"1.232019056","rc":[{"batb":[[0,1.51,69.28],[1,1.45,19.06],[2,1.44,6.32]],"ltp":1.5,"tv":2.84,"id":72857114}]}]}
{"op":"mcm","clk":"11885959557","pt":1724100766656,"mc":[{"id":"1.232019056","rc":[{"batb":[[1,1.44,6.26],[2,1.43,116.28]],"ltp":1.55,"tv":2.52,"id":72857117}]}]}
{"op":"mcm","clk":"11885960626","pt":1724100789500,"mc":[{"id":"1.232019056","rc":[{"batb":[[0,1.56,15.31],[1,1.55,102.39],[2,1.44,6.26]],"ltp":1.55,"tv":2.52,"id":72857117}]}]}
{"op":"mcm","clk":"11885964313","pt":1724100861526,"mc":[{"id":"1.232019056","rc":[{"batb":[[0,1.52,15],[1,1.51,69.28],[2,1.45,19.06]],"ltp":1.5,"tv":2.84,"id":72857114},{"batb":[[0,1.57,12],[1,1.56,15.31],[2,1.55,102.39]],"ltp":1.55,"tv":2.52,"id":72857117}]}]}
{"op":"mcm","clk":"11885973659","pt":1724101073191,"mc":[{"id":"1.232019056","rc":[{"batb":[[2,1.44,6.32]],"ltp":1.5,"tv":2.84,"id":72857114}]}]}
{"op":"mcm","clk":"11885974292","pt":1724101089628,"mc":[{"id":"1.232019056","rc":[{"batb":[[0,1.53,16.18],[1,1.52,15],[2,1.51,69.28]],"ltp":1.5,"tv":2.84,"id":72857114}]}]}
{"op":"mcm","clk":"11885998078","pt":1724101656816,"mc":[{"id":"1.232019056","rc":[{"batb":[[0,1.53,16.18]],"ltp":1.5,"tv":2.84,"id":72857114},{"batb":[[1,1.56,21.57]],"ltp":1.55,"tv":2.52,"id":72857117}]}]}
{"op":"mcm","clk":"11885998100","pt":1724101657226,"mc":[{"id":"1.232019056","rc":[{"batb":[[1,1.52,21.32]],"ltp":1.5,"tv":2.84,"id":72857114}]}]}
{"op":"mcm","clk":"11886005810","pt":1724101860569,"mc":[{"id":"1.232019056","rc":[{"batb":[[0,1.55,69.28],[1,1.53,16.18],[2,1.52,21.32]],"ltp":1.5,"tv":2.84,"id":72857114}]}]}
{"op":"mcm","clk":"11886006155","pt":1724101869342,"mc":[{"id":"1.232019056","rc":[{"batb":[[2,1.45,102.39]],"ltp":1.55,"tv":2.52,"id":72857117}]}]}
{"op":"mcm","clk":"11886047371","pt":1724102589717,"mc":[{"id":"1.232019056","rc":[{"batb":[[1,1.56,6.26]],"ltp":1.55,"tv":2.52,"id":72857117}]}]}
{"op":"mcm","clk":"11886053790","pt":1724102729095,"mc":[{"id":"1.232019056","rc":[{"batb":[[0,1.58,14.79],[1,1.57,12],[2,1.56,6.26]],"ltp":1.55,"tv":2.52,"id":72857117}]}]}
{"op":"mcm","clk":"11886061181","pt":1724102889888,"mc":[{"id":"1.232019056","rc":[{"batb":[[1,1.52,21.32],[2,1.43,116.28]],"ltp":1.5,"tv":2.84,"id":72857114}]}]}
{"op":"mcm","clk":"11886066542","pt":1724103024962,"mc":[{"id":"1.232019056","rc":[{"batb":[[0,1.56,15.31],[1,1.55,69.28],[2,1.52,21.32]],"ltp":1.5,"tv":2.84,"id":72857114}]}]}
{"op":"mcm","clk":"11886076017","pt":1724103262920,"mc":[{"id":"1.232019056","rc":[{"batb":[[1,1.52,21.32],[2,1.43,116.28]],"ltp":1.5,"tv":2.84,"id":72857114}]}]}
{"op":"mcm","clk":"11886102407","pt":1724103881196,"mc":[{"id":"1.232019056","rc":[{"trd":[[1.58,5.44]],"batb":[[0,1.58,12.07]],"ltp":1.58,"tv":7.95,"id":72857117}],"tv":10.8}]}
{"op":"mcm","clk":"11886105272","pt":1724103934772,"mc":[{"id":"1.232019056","rc":[{"batb":[[1,1.52,15],[2,1.44,6.32]],"ltp":1.5,"tv":2.84,"id":72857114},{"batb":[[2,1.44,6.26]],"ltp":1.58,"tv":7.95,"id":72857117}]}]}
{"op":"mcm","clk":"11886120030","pt":1724104220941,"mc":[{"id":"1.232019056","rc":[{"batb":[[0,1.8,129.83],[1,1.56,15.31],[2,1.52,15]],"ltp":1.5,"tv":2.84,"id":72857114}]}]}
{"op":"mcm","clk":"11886134320","pt":1724104529269,"mc":[{"id":"1.232019056","rc":[{"batb":[[0,1.57,12],[1,1.44,6.26],[2,1.43,116.28]],"ltp":1.58,"tv":7.95,"id":72857117}]}]}
{"op":"mcm","clk":"11886138338","pt":1724104619693,"mc":[{"id":"1.232019056","rc":[{"batb":[[1,1.45,259.67],[2,1.44,6.26]],"ltp":1.58,"tv":7.95,"id":72857117}]}]}
{"op":"mcm","clk":"11886138897","pt":1724104632093,"mc":[{"id":"1.232019056","rc":[{"batb":[[0,1.6,129.83],[1,1.57,12],[2,1.45,259.67]],"ltp":1.58,"tv":7.95,"id":72857117}]}]}
{"op":"mcm","clk":"11886140076","pt":1724104656627,"mc":[{"id":"1.232019056","rc":[{"batb":[[2,1.44,6.26]],"ltp":1.58,"tv":7.95,"id":72857117}]}]}
{"op":"mcm","clk":"11886140532","pt":1724104666957,"mc":[{"id":"1.232019056","rc":[{"batb":[[2,1.5,129.83]],"ltp":1.58,"tv":7.95,"id":72857117}]}]}
{"op":"mcm","clk":"11886147851","pt":1724104825218,"mc":[{"id":"1.232019056","rc":[{"batb":[[1,1.52,15],[2,1.44,6.32]],"ltp":1.5,"tv":2.84,"id":72857114}],"tv":10.8}]}
{"op":"mcm","clk":"11886153505","pt":1724104952178,"mc":[{"id":"1.232019056","rc":[{"batb":[[0,1.81,6.37],[1,1.8,129.83],[2,1.52,15]],"ltp":1.5,"tv":2.84,"id":72857114},{"batl":[[0,2.24,5.08],[1,5,1.54],[2,9,1.54]],"ltp":1.58,"tv":7.95,"id":72857117}]}]}
{"op":"mcm","clk":"11886173332","pt":1724105416138,"mc":[{"id":"1.232019056","rc":[{"batb":[[0,1.61,6.37],[1,1.6,129.83],[2,1.57,12]],"ltp":1.58,"tv":7.95,"id":72857117}]}]}
{"op":"mcm","clk":"11886205325","pt":1724106226625,"mc":[{"id":"1.232019056","rc":[{"batb":[[0,1.61,12.63]],"ltp":1.58,"tv":7.95,"id":72857117}]}]}
{"op":"mcm","clk":"11886205336","pt":1724106227033,"mc":[{"id":"1.232019056","rc":[{"batb":[[0,1.81,12.7]],"ltp":1.5,"tv":2.84,"id":72857114}]}]}
{"op":"mcm","clk":"11886233987","pt":1724107035027,"mc":[{"id":"1.232019056","rc":[{"batb":[[0,1.62,4.27],[1,1.61,12.63],[2,1.6,129.83]],"ltp":1.58,"tv":7.95,"id":72857117}]}]}
{"op":"mcm","clk":"11886234015","pt":1724107035896,"mc":[{"id":"1.232019056","rc":[{"batb":[[0,1.62,8.53]],"ltp":1.58,"tv":7.95,"id":72857117}]}]}
{"op":"mcm","clk":"11886408400","pt":1724111204047,"mc":[{"id":"1.232019056","rc":[{"batb":[[0,2.14,38.31],[1,1.81,12.7],[2,1.8,129.83]],"ltp":1.5,"tv":2.84,"id":72857114},{"batb":[[0,1.8,54.6],[1,1.62,8.53],[2,1.61,12.63]],"ltp":1.58,"tv":7.95,"id":72857117}]}]}
{"op":"mcm","clk":"11886408459","pt":1724111205537,"mc":[{"id":"1.232019056","rc":[{"batb":[[1,1.81,6.32]],"ltp":1.5,"tv":2.84,"id":72857114},{"batb":[[2,1.61,6.26]],"batl":[[0,5,1.54],[1,9,1.54],[2,9,0]],"ltp":1.58,"tv":7.95,"id":72857117}]}]}
{"op":"mcm","clk":"11886408852","pt":1724111214943,"mc":[{"id":"1.232019056","rc":[{"batb":[[1,2.02,7.8],[2,1.81,6.32]],"ltp":1.5,"tv":2.84,"id":72857114},{"batb":[[1,1.7,9.27],[2,1.62,8.53]],"ltp":1.58,"tv":7.95,"id":72857117}]}]}
{"op":"mcm","clk":"11886483030","pt":1724112774988,"mc":[{"id":"1.232019056","tv":10.8}]}
{"op":"mcm","clk":"11886494206","pt":1724112920075,"mc":[{"id":"1.232019056","marketDefinition":{"bspMarket":false,"turnInPlayEnabled":true,"persistenceEnabled":true,"marketBaseRate":5.0,"eventId":"33508297","eventTypeId":"4","numberOfWinners":1,"bettingType":"ODDS","marketType":"MATCH_ODDS","marketTime":"2024-08-20T18:30:00.000Z","suspendTime":"2024-08-20T18:30:00.000Z","bspReconciled":false,"complete":true,"inPlay":false,"crossMatching":true,"runnersVoidable":false,"numberOfActiveRunners":2,"betDelay":0,"status":"OPEN","runners":[{"status":"ACTIVE","sortPriority":1,"id":72857117,"name":"Caribbean Giants"},{"status":"ACTIVE","sortPriority":2,"id":72857114,"name":"Boca Raton Trailblazers"}],"regulators":["MR_INT"],"countryCode":"GB","discountAllowed":true,"timezone":"GMT","openDate":"2024-08-20T18:00:00.000Z","version":6087177596,"name":"Match Odds","eventName":"Caribbean Giants v Boca Raton Trailblazers"}}]}
{"op":"mcm","clk":"11886494313","pt":1724112922072,"mc":[{"id":"1.232019056","marketDefinition":{"bspMarket":false,"turnInPlayEnabled":true,"persistenceEnabled":true,"marketBaseRate":5.0,"eventId":"33508297","eventTypeId":"4","numberOfWinners":1,"bettingType":"ODDS","marketType":"MATCH_ODDS","marketTime":"2024-08-20T18:30:00.000Z","suspendTime":"2024-08-20T18:30:00.000Z","bspReconciled":false,"complete":true,"inPlay":false,"crossMatching":true,"runnersVoidable":false,"numberOfActiveRunners":2,"betDelay":0,"status":"OPEN","runners":[{"status":"ACTIVE","sortPriority":1,"id":72857117,"name":"Caribbean Giants"},{"status":"ACTIVE","sortPriority":2,"id":72857114,"name":"Boca Raton Trailblazers"}],"regulators":["MR_INT"],"countryCode":"GB","discountAllowed":true,"timezone":"GMT","openDate":"2024-08-20T18:30:00.000Z","version":6087177596,"name":"Match Odds","eventName":"Caribbean Giants v Boca Raton Trailblazers"}}]}
{"op":"mcm","clk":"11886495083","pt":1724112937529,"mc":[{"id":"1.232019056","rc":[{"batb":[[1,1.81,6.32],[2,1.8,129.83]],"ltp":1.5,"tv":2.84,"id":72857114},{"batb":[[1,1.62,8.53],[2,1.61,6.26]],"ltp":1.58,"tv":7.95,"id":72857117}]}]}
{"op":"mcm","clk":"11886501709","pt":1724113081813,"mc":[{"id":"1.232019056","rc":[{"batb":[[2,1.6,129.83]],"ltp":1.58,"tv":7.95,"id":72857117}]}]}
{"op":"mcm","clk":"11886501728","pt":1724113082121,"mc":[{"id":"1.232019056","rc":[{"batb":[[1,1.8,129.83],[2,1.52,15]],"ltp":1.5,"tv":2.84,"id":72857114}]}]}
{"op":"mcm","clk":"11886533900","pt":1724113766815,"mc":[{"id":"1.232019056","rc":[{"trd":[[2.14,0.2]],"batb":[[0,2.14,38.21]],"ltp":2.14,"tv":3.04,"id":72857114}],"tv":11.0}]}
{"op":"mcm","clk":"11886533987","pt":1724113769019,"mc":[{"id":"1.232019056","rc":[{"batb":[[0,2.14,38.31]],"ltp":2.14,"tv":3.04,"id":72857114}]}]}
{"op":"mcm","clk":"11886540899","pt":1724113927001,"mc":[{"id":"1.232019056","rc":[{"trd":[[2.26,0.1]],"ltp":2.26,"tv":3.14,"id":72857114},{"trd":[[1.8,0.12]],"batb":[[0,1.8,54.48]],"ltp":1.8,"tv":8.07,"id":72857117}],"tv":11.22}]}
{"op":"mcm","clk":"11886541020","pt":1724113929484,"mc":[{"id":"1.232019056","rc":[{"batb":[[0,1.8,54.6]],"ltp":1.8,"tv":8.07,"id":72857117}]}]}
{"op":"mcm","clk":"11886548260","pt":1724114097420,"mc":[{"id":"1.232019056","rc":[{"trd":[[2.14,0.4]],"batb":[[0,2.14,38.21]],"ltp":2.14,"tv":3.34,"id":72857114}],"tv":11.42}]}
{"op":"mcm","clk":"11886548386","pt":1724114100096,"mc":[{"id":"1.232019056","rc":[{"batb":[[0,2.14,38.31]],"ltp":2.14,"tv":3.34,"id":72857114}]}]}
{"op":"mcm","clk":"11886555735","pt":1724114258180,"mc":[{"id":"1.232019056","rc":[{"trd":[[2.26,0.2]],"ltp":2.26,"tv":3.44,"id":72857114},{"trd":[[1.8,0.24]],"batb":[[0,1.8,54.48]],"ltp":1.8,"tv":8.19,"id":72857117}],"tv":11.64}]}
{"op":"mcm","clk":"11886555825","pt":1724114260336,"mc":[{"id":"1.232019056","rc":[{"batb":[[0,1.8,54.6]],"ltp":1.8,"tv":8.19,"id":72857117}]}]}
{"op":"mcm","clk":"11886579152","pt":1724114771929,"mc":[{"id":"1.232019056","rc":[{"trd":[[2.14,0.6]],"batb":[[0,2.14,38.21]],"ltp":2.14,"tv":3.64,"id":72857114}],"tv":11.83}]}
{"op":"mcm","clk":"11886579330","pt":1724114776351,"mc":[{"id":"1.232019056","rc":[{"batb":[[0,2.14,38.31]],"ltp":2.14,"tv":3.64,"id":72857114}]}]}
{"op":"mcm","clk":"11886579900","pt":1724114789679,"mc":[{"id":"1.232019056","rc":[{"batl":[[2,11,0.1]],"ltp":2.14,"tv":3.64,"id":72857114}]}]}
{"op":"mcm","clk":"11886581331","pt":1724114827325,"mc":[{"id":"1.232019056","rc":[{"batl":[[2,11,0]],"ltp":2.14,"tv":3.64,"id":72857114}]}]}
{"op":"mcm","clk":"11886585605","pt":1724114932084,"mc":[{"id":"1.232019056","rc":[{"trd":[[2.26,0.3]],"ltp":2.26,"tv":3.73,"id":72857114},{"trd":[[1.8,0.36]],"batb":[[0,1.8,54.48]],"ltp":1.8,"tv":8.31,"id":72857117}],"tv":12.05}]}
{"op":"mcm","clk":"11886585796","pt":1724114936683,"mc":[{"id":"1.232019056","rc":[{"batb":[[0,1.8,54.6]],"ltp":1.8,"tv":8.31,"id":72857117}]}]}
{"op":"mcm","clk":"11886586132","pt":1724114945112,"mc":[{"id":"1.232019056","rc":[{"batl":[[2,11,0.1]],"ltp":2.26,"tv":3.73,"id":72857114}]}]}
{"op":"mcm","clk":"11886586760","pt":1724114962198,"mc":[{"id":"1.232019056","rc":[{"batl":[[2,11,0.2]],"ltp":2.26,"tv":3.73,"id":72857114}]}]}
{"op":"mcm","clk":"11886588546","pt":1724115003351,"mc":[{"id":"1.232019056","rc":[{"batl":[[2,11,0]],"ltp":2.26,"tv":3.73,"id":72857114}]}]}
{"op":"mcm","clk":"11886592220","pt":1724115089771,"mc":[{"id":"1.232019056","rc":[{"trd":[[2.14,0.8]],"batb":[[0,2.14,38.21]],"ltp":2.14,"tv":3.93,"id":72857114}],"tv":12.25}]}
{"op":"mcm","clk":"11886592342","pt":1724115092088,"mc":[{"id":"1.232019056","rc":[{"batb":[[0,2.14,38.31]],"ltp":2.14,"tv":3.93,"id":72857114}]}]}
{"op":"mcm","clk":"11886599675","pt":1724115250677,"mc":[{"id":"1.232019056","rc":[{"trd":[[2.26,0.4]],"ltp":2.26,"tv":4.03,"id":72857114},{"trd":[[1.8,0.48]],"batb":[[0,1.8,54.48]],"ltp":1.8,"tv":8.43,"id":72857117}],"tv":12.47}]}
{"op":"mcm","clk":"11886599770","pt":1724115252477,"mc":[{"id":"1.232019056","rc":[{"batb":[[0,1.8,54.6]],"ltp":1.8,"tv":8.43,"id":72857117}]}]}
{"op":"mcm","clk":"11886623891","pt":1724115776885,"mc":[{"id":"1.232019056","rc":[{"batl":[[2,11,0.1]],"ltp":2.26,"tv":4.03,"id":72857114}]}]}
{"op":"mcm","clk":"11886625682","pt":1724115814035,"mc":[{"id":"1.232019056","rc":[{"batl":[[2,11,0]],"ltp":2.26,"tv":4.03,"id":72857114}]}]}
{"op":"mcm","clk":"11886631232","pt":1724115931455,"mc":[{"id":"1.232019056","rc":[{"batl":[[2,11,0.1]],"ltp":2.26,"tv":4.03,"id":72857114}]}]}
{"op":"mcm","clk":"11886635821","pt":1724116031833,"mc":[{"id":"1.232019056","rc":[{"batl":[[2,11,0]],"ltp":2.26,"tv":4.03,"id":72857114}]}]}
{"op":"mcm","clk":"11886718432","pt":1724117939927,"mc":[{"id":"1.232019056","rc":[{"batl":[[0,5,1.64]],"ltp":1.8,"tv":8.43,"id":72857117}]}]}
{"op":"mcm","clk":"11886718994","pt":1724117957266,"mc":[{"id":"1.232019056","rc":[{"batl":[[0,5,1.54]],"ltp":1.8,"tv":8.43,"id":72857117}]}]}
{"op":"mcm","clk":"11886721043","pt":1724118020833,"mc":[{"id":"1.232019056","rc":[{"trd":[[2.14,0.89]],"batb":[[0,2.14,38.22]],"ltp":2.14,"tv":4.12,"id":72857114},{"trd":[[1.88,0.1]],"ltp":1.88,"tv":8.53,"id":72857117}],"tv":12.66}]}
{"op":"mcm","clk":"11886721119","pt":1724118022620,"mc":[{"id":"1.232019056","rc":[{"trd":[[2.14,39.11]],"batb":[[0,1.81,10]],"ltp":2.14,"tv":42.34,"id":72857114},{"trd":[[1.88,43.61]],"batb":[[0,1.89,10],[1,1.88,44.49],[2,1.8,54.6]],"ltp":1.88,"tv":52.04,"id":72857117}],"tv":94.39}]}
{"op":"mcm","clk":"11886721153","pt":1724118023235,"mc":[{"id":"1.232019056","rc":[{"batb":[[0,2.06,41.2],[1,1.81,10],[2,1.8,129.83]],"ltp":2.14,"tv":42.34,"id":72857114}]}]}
{"op":"mcm","clk":"11886721279","pt":1724118025447,"mc":[{"id":"1.232019056","rc":[{"batb":[[1,1.8,54.6],[2,1.62,8.53]],"ltp":1.88,"tv":52.04,"id":72857117}]}]}
{"op":"mcm","clk":"11886721293","pt":1724118025858,"mc":[{"id":"1.232019056","rc":[{"batb":[[1,1.8,129.83],[2,1.52,15]],"ltp":2.14,"tv":42.34,"id":72857114},{"batb":[[0,1.8,54.6],[1,1.62,8.53],[2,1.6,129.83]],"ltp":1.88,"tv":52.04,"id":72857117}]}]}
{"op":"mcm","clk":"11886721379","pt":1724118028022,"mc":[{"id":"1.232019056","rc":[{"batb":[[0,2.08,10],[1,2.06,41.2],[2,1.8,129.83]],"ltp":2.14,"tv":42.34,"id":72857114},{"batb":[[0,1.81,10],[1,1.8,54.6],[2,1.62,8.53]],"ltp":1.88,"tv":52.04,"id":72857117}]}]}
{"op":"mcm","clk":"11886721502","pt":1724118031255,"mc":[{"id":"1.232019056","rc":[{"batb":[[0,2.06,41.2],[1,1.8,129.83],[2,1.52,15]],"ltp":2.14,"tv":42.34,"id":72857114},{"batb":[[0,1.8,54.6],[1,1.62,8.53],[2,1.6,129.83]],"ltp":1.88,"tv":52.04,"id":72857117}]}]}
{"op":"mcm","clk":"11886721613","pt":1724118034344,"mc":[{"id":"1.232019056","rc":[{"trd":[[2.06,31.45],[2.08,10]],"batb":[[0,2.06,9.75]],"ltp":2.06,"tv":83.79,"id":72857114},{"trd":[[1.93,10.78],[1.95,33.22]],"batb":[[0,1.81,10],[1,1.8,54.6],[2,1.62,8.53]],"ltp":1.95,"tv":96.04,"id":72857117}],"tv":179.84}]}
{"op":"mcm","clk":"11886721743","pt":1724118037461,"mc":[{"id":"1.232019056","rc":[{"batb":[[0,2.08,10],[1,2.06,9.75],[2,1.8,129.83]],"ltp":2.06,"tv":83.79,"id":72857114},{"batb":[[0,1.8,54.6],[1,1.62,8.53],[2,1.6,129.83]],"ltp":1.95,"tv":96.04,"id":72857117}]}]}
{"op":"mcm","clk":"11886721785","pt":1724118038336,"mc":[{"id":"1.232019056","rc":[{"batb":[[1,1.8,129.83],[2,1.52,15]],"ltp":2.06,"tv":83.79,"id":72857114}]}]}
{"op":"mcm","clk":"11886721850","pt":1724118039574,"mc":[{"id":"1.232019056","rc":[{"batb":[[0,1.81,10],[1,1.8,54.6],[2,1.62,8.53]],"ltp":1.95,"tv":96.04,"id":72857117}]}]}
{"op":"mcm","clk":"11886721903","pt":1724118040661,"mc":[{"id":"1.232019056","rc":[{"batb":[[0,1.8,129.83],[1,1.52,15],[2,1.43,116.28]],"ltp":2.06,"tv":83.79,"id":72857114}]}]}
{"op":"mcm","clk":"11886721982","pt":1724118043180,"mc":[{"id":"1.232019056","rc":[{"batb":[[0,1.81,10],[1,1.8,129.83],[2,1.52,15]],"ltp":2.06,"tv":83.79,"id":72857114},{"batb":[[0,1.8,54.6],[1,1.62,8.53],[2,1.6,129.83]],"ltp":1.95,"tv":96.04,"id":72857117}]}]}
{"op":"mcm","clk":"11886722051","pt":1724118045455,"mc":[{"id":"1.232019056","rc":[{"batb":[[0,1.81,10],[1,1.8,54.6],[2,1.62,8.53]],"ltp":1.95,"tv":96.04,"id":72857117}]}]}
{"op":"mcm","clk":"11886722073","pt":1724118046475,"mc":[{"id":"1.232019056","rc":[{"batb":[[0,1.8,129.83],[1,1.52,15],[2,1.43,116.28]],"ltp":2.06,"tv":83.79,"id":72857114}]}]}
{"op":"mcm","clk":"11886722154","pt":1724118048944,"mc":[{"id":"1.232019056","rc":[{"batb":[[0,1.81,10],[1,1.8,129.83],[2,1.52,15]],"ltp":2.06,"tv":83.79,"id":72857114},{"batb":[[0,1.8,54.6],[1,1.62,8.53],[2,1.6,129.83]],"ltp":1.95,"tv":96.04,"id":72857117}]}]}
{"op":"mcm","clk":"11886722223","pt":1724118051094,"mc":[{"id":"1.232019056","rc":[{"batb":[[0,1.81,16.37]],"ltp":2.06,"tv":83.79,"id":72857114},{"batb":[[0,1.81,10],[1,1.8,54.6],[2,1.62,8.53]],"batl":[[0,2.24,5.47],[1,5,1.54],[2,9,1.54]],"ltp":1.95,"tv":96.04,"id":72857117}]}]}
{"op":"mcm","clk":"11886722264","pt":1724118052280,"mc":[{"id":"1.232019056","rc":[{"batb":[[0,1.81,6.37]],"ltp":2.06,"tv":83.79,"id":72857114}]}]}
{"op":"mcm","clk":"11886722360","pt":1724118054800,"mc":[{"id":"1.232019056","rc":[{"batb":[[0,1.82,10],[1,1.81,6.37],[2,1.8,129.83]],"ltp":2.06,"tv":83.79,"id":72857114},{"batb":[[0,1.8,54.6],[1,1.62,8.53],[2,1.6,129.83]],"ltp":1.95,"tv":96.04,"id":72857117}]}]}
{"op":"mcm","clk":"11886722448","pt":1724118057205,"mc":[{"id":"1.232019056","rc":[{"batb":[[0,1.81,10],[1,1.8,54.6],[2,1.62,8.53]],"ltp":1.95,"tv":96.04,"id":72857117}]}]}
{"op":"mcm","clk":"11886722498","pt":1724118058183,"mc":[{"id":"1.232019056","rc":[{"batb":[[0,1.81,6.37],[1,1.8,129.83],[2,1.52,15]],"ltp":2.06,"tv":83.79,"id":72857114}]}]}
{"op":"mcm","clk":"11886722591","pt":1724118060489,"mc":[{"id":"1.232019056","rc":[{"batb":[[0,1.82,10],[1,1.81,6.37],[2,1.8,129.83]],"ltp":2.06,"tv":83.79,"id":72857114},{"batb":[[0,1.8,54.6],[1,1.62,8.53],[2,1.6,129.83]],"ltp":1.95,"tv":96.04,"id":72857117}]}]}
{"op":"mcm","clk":"11886722610","pt":1724118061000,"mc":[{"id":"1.232019056","rc":[{"batb":[[0,1.92,8.21],[1,1.82,10],[2,1.81,6.37]],"ltp":2.06,"tv":83.79,"id":72857114},{"batb":[[1,1.78,8.86],[2,1.62,8.53]],"ltp":1.95,"tv":96.04,"id":72857117}]}]}
{"op":"mcm","clk":"11886722658","pt":1724118062180,"mc":[{"id":"1.232019056","rc":[{"batb":[[2,1.8,129.83]],"ltp":2.06,"tv":83.79,"id":72857114},{"batl":[[0,5,1.54],[1,9,1.54],[2,9,0]],"ltp":1.95,"tv":96.04,"id":72857117}]}]}
{"op":"mcm","clk":"11886722701","pt":1724118063814,"mc":[{"id":"1.232019056","rc":[{"batb":[[1,1.8,129.83],[2,1.52,15]],"ltp":2.06,"tv":83.79,"id":72857114},{"batb":[[0,1.81,10],[1,1.8,54.6],[2,1.78,8.86]],"ltp":1.95,"tv":96.04,"id":72857117}]}]}
{"op":"mcm","clk":"11886722842","pt":1724118066796,"mc":[{"id":"1.232019056","rc":[{"batb":[[0,1.93,10],[1,1.92,8.21],[2,1.8,129.83]],"ltp":2.06,"tv":83.79,"id":72857114},{"batb":[[0,1.8,54.6],[1,1.78,8.86],[2,1.62,8.53]],"ltp":1.95,"tv":96.04,"id":72857117}]}]}
{"op":"mcm","clk":"11886722905","pt":1724118068797,"mc":[{"id":"1.232019056","rc":[{"batb":[[0,1.81,10],[1,1.8,54.6],[2,1.78,8.86]],"ltp":1.95,"tv":96.04,"id":72857117}]}]}
{"op":"mcm","clk":"11886722946","pt":1724118070023,"mc":[{"id":"1.232019056","rc":[{"batb":[[0,1.92,8.21],[1,1.8,129.83],[2,1.52,15]],"ltp":2.06,"tv":83.79,"id":72857114}]}]}
{"op":"mcm","clk":"11886723030","pt":1724118072426,"mc":[{"id":"1.232019056","rc":[{"batb":[[0,1.93,10],[1,1.92,8.21],[2,1.8,129.83]],"ltp":2.06,"tv":83.79,"id":72857114},{"batb":[[0,1.8,54.6],[1,1.78,8.86],[2,1.62,8.53]],"ltp":1.95,"tv":96.04,"id":72857117}]}]}
{"op":"mcm","clk":"11886723129","pt":1724118074693,"mc":[{"id":"1.232019056","rc":[{"batb":[[0,1.81,10],[1,1.8,54.6],[2,1.78,8.86]],"ltp":1.95,"tv":96.04,"id":72857117}]}]}
{"op":"mcm","clk":"11886723165","pt":1724118075712,"mc":[{"id":"1.232019056","rc":[{"batb":[[0,1.92,8.21],[1,1.8,129.83],[2,1.52,15]],"ltp":2.06,"tv":83.79,"id":72857114}]}]}
{"op":"mcm","clk":"11886723227","pt":1724118078427,"mc":[{"id":"1.232019056","rc":[{"batb":[[0,1.93,10],[1,1.92,8.21],[2,1.8,129.83]],"ltp":2.06,"tv":83.79,"id":72857114},{"batb":[[0,1.8,54.6],[1,1.78,8.86],[2,1.62,8.53]],"ltp":1.95,"tv":96.04,"id":72857117}]}]}
{"op":"mcm","clk":"11886723245","pt":1724118079040,"mc":[{"id":"1.232019056","rc":[{"batb":[[0,1.96,8.05],[1,1.93,10]],"ltp":2.06,"tv":83.79,"id":72857114},{"batb":[[1,1.75,9.02]],"ltp":1.95,"tv":96.04,"id":72857117}]}]}
{"op":"mcm","clk":"11886723348","pt":1724118081812,"mc":[{"id":"1.232019056","rc":[{"batb":[[1,1.8,129.83],[2,1.52,15]],"ltp":2.06,"tv":83.79,"id":72857114},{"batb":[[0,1.81,10],[1,1.8,54.6],[2,1.75,9.02]],"ltp":1.95,"tv":96.04,"id":72857117}]}]}
{"op":"mcm","clk":"11886723457","pt":1724118084797,"mc":[{"id":"1.232019056","rc":[{"batb":[[0,1.97,10],[1,1.96,8.05],[2,1.8,129.83]],"ltp":2.06,"tv":83.79,"id":72857114}]}]}
{"op":"mcm","clk":"11886723475","pt":1724118085192,"mc":[{"id":"1.232019056","rc":[{"batb":[[0,1.8,54.6],[1,1.75,9.02],[2,1.62,8.53]],"ltp":1.95,"tv":96.04,"id":72857117}]}]}
{"op":"mcm","clk":"11886723637","pt":1724118088275,"mc":[{"id":"1.232019056","rc":[{"batb":[[0,1.96,8.05],[1,1.8,129.83],[2,1.52,15]],"ltp":2.06,"tv":83.79,"id":72857114},{"batb":[[0,1.81,10],[1,1.8,54.6],[2,1.75,9.02]],"ltp":1.95,"tv":96.04,"id":72857117}]}]}
{"op":"mcm","clk":"11886723732","pt":1724118090594,"mc":[{"id":"1.232019056","rc":[{"batb":[[0,1.97,10],[1,1.96,8.05],[2,1.8,129.83]],"ltp":2.06,"tv":83.79,"id":72857114}]}]}
{"op":"mcm","clk":"11886723772","pt":1724118091570,"mc":[{"id":"1.232019056","rc":[{"batb":[[0,1.8,54.6],[1,1.75,9.02],[2,1.62,8.53]],"ltp":1.95,"tv":96.04,"id":72857117}]}]}
{"op":"mcm","clk":"11886723949","pt":1724118093994,"mc":[{"id":"1.232019056","rc":[{"batb":[[0,1.96,8.05],[1,1.8,129.83],[2,1.52,15]],"ltp":2.06,"tv":83.79,"id":72857114},{"batb":[[0,1.81,10],[1,1.8,54.6],[2,1.75,9.02]],"ltp":1.95,"tv":96.04,"id":72857117}]}]}
{"op":"mcm","clk":"11886724030","pt":1724118096199,"mc":[{"id":"1.232019056","rc":[{"batb":[[0,1.97,10],[1,1.96,8.05],[2,1.8,129.83]],"ltp":2.06,"tv":83.79,"id":72857114}]}]}
{"op":"mcm","clk":"11886724077","pt":1724118097486,"mc":[{"id":"1.232019056","rc":[{"batb":[[0,1.8,54.6],[1,1.75,9.02],[2,1.62,8.53]],"ltp":1.95,"tv":96.04,"id":72857117}]}]}
{"op":"mcm","clk":"11886724158","pt":1724118099700,"mc":[{"id":"1.232019056","rc":[{"batb":[[0,1.96,8.05],[1,1.8,129.83],[2,1.52,15]],"ltp":2.06,"tv":83.79,"id":72857114},{"batb":[[0,1.81,10],[1,1.8,54.6],[2,1.75,9.02]],"ltp":1.95,"tv":96.04,"id":72857117}]}]}
{"op":"mcm","clk":"11886724263","pt":1724118102375,"mc":[{"id":"1.232019056","rc":[{"batb":[[0,1.97,10],[1,1.96,8.05],[2,1.8,129.83]],"ltp":2.06,"tv":83.79,"id":72857114}]}]}
{"op":"mcm","clk":"11886724285","pt":1724118102991,"mc":[{"id":"1.232019056","rc":[{"batb":[[0,1.8,54.6],[1,1.75,9.02],[2,1.62,8.53]],"ltp":1.95,"tv":96.04,"id":72857117}]}]}
{"op":"mcm","clk":"11886724378","pt":1724118105666,"mc":[{"id":"1.232019056","rc":[{"batb":[[0,1.96,8.05],[1,1.8,129.83],[2,1.52,15]],"ltp":2.06,"tv":83.79,"id":72857114},{"batb":[[0,1.81,10],[1,1.8,54.6],[2,1.75,9.02]],"ltp":1.95,"tv":96.04,"id":72857117}]}]}
{"op":"mcm","clk":"11886724493","pt":1724118108692,"mc":[{"id":"1.232019056","rc":[{"batb":[[0,1.97,10],[1,1.96,8.05],[2,1.8,129.83]],"ltp":2.06,"tv":83.79,"id":72857114},{"batb":[[0,1.8,54.6],[1,1.75,9.02],[2,1.62,8.53]],"ltp":1.95,"tv":96.04,"id":72857117}]}]}
{"op":"mcm","clk":"11886724594","pt":1724118111107,"mc":[{"id":"1.232019056","rc":[{"batb":[[0,1.96,8.05],[1,1.8,129.83],[2,1.52,15]],"ltp":2.06,"tv":83.79,"id":72857114},{"batb":[[0,1.81,10],[1,1.8,54.6],[2,1.75,9.02]],"ltp":1.95,"tv":96.04,"id":72857117}]}]}
{"op":"mcm","clk":"11886724675","pt":1724118113519,"mc":[{"id":"1.232019056","rc":[{"batb":[[0,1.97,10],[1,1.96,8.05],[2,1.8,129.83]],"ltp":2.06,"tv":83.79,"id":72857114}]}]}
{"op":"mcm","clk":"11886724700","pt":1724118114494,"mc":[{"id":"1.232019056","rc":[{"batb":[[0,1.8,54.6],[1,1.75,9.02],[2,1.62,8.53]],"ltp":1.95,"tv":96.04,"id":72857117}]}]}
{"op":"mcm","clk":"11886724810","pt":1724118116697,"mc":[{"id":"1.232019056","rc":[{"batb":[[0,1.96,8.05],[1,1.8,129.83],[2,1.52,15]],"ltp":2.06,"tv":83.79,"id":72857114}]}]}
{"op":"mcm","clk":"11886724816","pt":1724118116903,"mc":[{"id":"1.232019056","rc":[{"batb":[[0,1.81,10],[1,1.8,54.6],[2,1.75,9.02]],"ltp":1.95,"tv":96.04,"id":72857117}]}]}
{"op":"mcm","clk":"11886724901","pt":1724118119326,"mc":[{"id":"1.232019056","rc":[{"batb":[[0,1.97,10],[1,1.96,8.05],[2,1.8,129.83]],"ltp":2.06,"tv":83.79,"id":72857114}]}]}
{"op":"mcm","clk":"11886724945","pt":1724118120315,"mc":[{"id":"1.232019056","rc":[{"batb":[[0,1.8,54.6],[1,1.75,9.02],[2,1.62,8.53]],"ltp":1.95,"tv":96.04,"id":72857117}]}]}
{"op":"mcm","clk":"11886725066","pt":1724118122731,"mc":[{"id":"1.232019056","rc":[{"batb":[[0,1.96,8.05],[1,1.8,129.83],[2,1.52,15]],"ltp":2.06,"tv":83.79,"id":72857114},{"batb":[[0,1.81,10],[1,1.8,54.6],[2,1.75,9.02]],"ltp":1.95,"tv":96.04,"id":72857117}]}]}
{"op":"mcm","clk":"11886725150","pt":1724118124938,"mc":[{"id":"1.232019056","rc":[{"batb":[[0,1.97,10],[1,1.96,8.05],[2,1.8,129.83]],"ltp":2.06,"tv":83.79,"id":72857114}]}]}
{"op":"mcm","clk":"11886725202","pt":1724118126021,"mc":[{"id":"1.232019056","rc":[{"batb":[[0,1.8,54.6],[1,1.75,9.02],[2,1.62,8.53]],"ltp":1.95,"tv":96.04,"id":72857117}]}]}
{"op":"mcm","clk":"11886725290","pt":1724118128628,"mc":[{"id":"1.232019056","rc":[{"batb":[[0,1.96,8.05],[1,1.8,129.83],[2,1.52,15]],"ltp":2.06,"tv":83.79,"id":72857114},{"batb":[[0,1.81,10],[1,1.8,54.6],[2,1.75,9.02]],"ltp":1.95,"tv":96.04,"id":72857117}]}]}
{"op":"mcm","clk":"11886725381","pt":1724118131041,"mc":[{"id":"1.232019056","rc":[{"batb":[[0,1.97,10],[1,1.96,8.05],[2,1.8,129.83]],"ltp":2.06,"tv":83.79,"id":72857114}]}]}
{"op":"mcm","clk":"11886725418","pt":1724118132018,"mc":[{"id":"1.232019056","rc":[{"batb":[[0,1.8,54.6],[1,1.75,9.02],[2,1.62,8.53]],"ltp":1.95,"tv":96.04,"id":72857117}]}]}
{"op":"mcm","clk":"11886725515","pt":1724118134534,"mc":[{"id":"1.232019056","rc":[{"batb":[[0,1.96,8.05],[1,1.8,129.83],[2,1.52,15]],"ltp":2.06,"tv":83.79,"id":72857114},{"batb":[[0,1.81,10],[1,1.8,54.6],[2,1.75,9.02]],"ltp":1.95,"tv":96.04,"id":72857117}]}]}
{"op":"mcm","clk":"11886725583","pt":1724118136743,"mc":[{"id":"1.232019056","rc":[{"batb":[[0,1.97,10],[1,1.96,8.05],[2,1.8,129.83]],"ltp":2.06,"tv":83.79,"id":72857114}]}]}
{"op":"mcm","clk":"11886725629","pt":1724118137919,"mc":[{"id":"1.232019056","rc":[{"batb":[[0,1.8,54.6],[1,1.75,9.02],[2,1.62,8.53]],"ltp":1.95,"tv":96.04,"id":72857117}]}]}
{"op":"mcm","clk":"11886725710","pt":1724118140223,"mc":[{"id":"1.232019056","rc":[{"batb":[[0,1.96,8.05],[1,1.8,129.83],[2,1.52,15]],"ltp":2.06,"tv":83.79,"id":72857114},{"batb":[[0,1.81,10],[1,1.8,54.6],[2,1.75,9.02]],"ltp":1.95,"tv":96.04,"id":72857117}]}]}
{"op":"mcm","clk":"11886725805","pt":1724118142744,"mc":[{"id":"1.232019056","rc":[{"batb":[[0,1.97,10],[1,1.96,8.05],[2,1.8,129.83]],"ltp":2.06,"tv":83.79,"id":72857114}]}]}
{"op":"mcm","clk":"11886725829","pt":1724118143560,"mc":[{"id":"1.232019056","rc":[{"batb":[[0,1.8,54.6],[1,1.75,9.02],[2,1.62,8.53]],"ltp":1.95,"tv":96.04,"id":72857117}]}]}
{"op":"mcm","clk":"11886725931","pt":1724118146124,"mc":[{"id":"1.232019056","rc":[{"batb":[[0,1.96,8.05],[1,1.8,129.83],[2,1.52,15]],"ltp":2.06,"tv":83.79,"id":72857114},{"batb":[[0,1.81,10],[1,1.8,54.6],[2,1.75,9.02]],"ltp":1.95,"tv":96.04,"id":72857117}]}]}
{"op":"mcm","clk":"11886726022","pt":1724118148326,"mc":[{"id":"1.232019056","rc":[{"batb":[[0,1.97,10],[1,1.96,8.05],[2,1.8,129.83]],"ltp":2.06,"tv":83.79,"id":72857114}]}]}
{"op":"mcm","clk":"11886726048","pt":1724118149045,"mc":[{"id":"1.232019056","rc":[{"batb":[[0,1.8,54.6],[1,1.75,9.02],[2,1.62,8.53]],"ltp":1.95,"tv":96.04,"id":72857117}]}]}
{"op":"mcm","clk":"11886726164","pt":1724118151632,"mc":[{"id":"1.232019056","rc":[{"batb":[[0,1.96,8.05],[1,1.8,129.83],[2,1.52,15]],"ltp":2.06,"tv":83.79,"id":72857114},{"batb":[[0,1.81,10],[1,1.8,54.6],[2,1.75,9.02]],"ltp":1.95,"tv":96.04,"id":72857117}]}]}
{"op":"mcm","clk":"11886726216","pt":1724118153740,"mc":[{"id":"1.232019056","rc":[{"batb":[[0,1.97,10],[1,1.96,8.05],[2,1.8,129.83]],"ltp":2.06,"tv":83.79,"id":72857114}]}]}
{"op":"mcm","clk":"11886726244","pt":1724118154762,"mc":[{"id":"1.232019056","rc":[{"batb":[[0,1.8,54.6],[1,1.75,9.02],[2,1.62,8.53]],"ltp":1.95,"tv":96.04,"id":72857117}]}]}
{"op":"mcm","clk":"11886726318","pt":1724118157175,"mc":[{"id":"1.232019056","rc":[{"batb":[[0,1.96,8.05],[1,1.8,129.83],[2,1.52,15]],"ltp":2.06,"tv":83.79,"id":72857114},{"batb":[[0,1.81,10],[1,1.8,54.6],[2,1.75,9.02]],"ltp":1.95,"tv":96.04,"id":72857117}]}]}
{"op":"mcm","clk":"11886726399","pt":1724118159543,"mc":[{"id":"1.232019056","rc":[{"batb":[[0,1.97,10],[1,1.96,8.05],[2,1.8,129.83]],"ltp":2.06,"tv":83.79,"id":72857114}]}]}
{"op":"mcm","clk":"11886726441","pt":1724118160570,"mc":[{"id":"1.232019056","rc":[{"batb":[[0,1.8,54.6],[1,1.75,9.02],[2,1.62,8.53]],"ltp":1.95,"tv":96.04,"id":72857117}]}]}
{"op":"mcm","clk":"11886726528","pt":1724118163080,"mc":[{"id":"1.232019056","rc":[{"batb":[[0,1.96,8.05],[1,1.8,129.83],[2,1.52,15]],"ltp":2.06,"tv":83.79,"id":72857114},{"batb":[[0,1.81,10],[1,1.8,54.6],[2,1.75,9.02]],"ltp":1.95,"tv":96.04,"id":72857117}]}]}
{"op":"mcm","clk":"11886726608","pt":1724118165648,"mc":[{"id":"1.232019056","rc":[{"batb":[[0,1.97,10],[1,1.96,8.05],[2,1.8,129.83]],"ltp":2.06,"tv":83.79,"id":72857114}]}]}
{"op":"mcm","clk":"11886726632","pt":1724118166256,"mc":[{"id":"1.232019056","rc":[{"batb":[[0,1.8,54.6],[1,1.75,9.02],[2,1.62,8.53]],"ltp":1.95,"tv":96.04,"id":72857117}]}]}
{"op":"mcm","clk":"11886726710","pt":1724118169087,"mc":[{"id":"1.232019056","rc":[{"batb":[[0,1.96,8.05],[1,1.8,129.83],[2,1.52,15]],"ltp":2.06,"tv":83.79,"id":72857114},{"batb":[[0,1.81,10],[1,1.8,54.6],[2,1.75,9.02]],"ltp":1.95,"tv":96.04,"id":72857117}]}]}
{"op":"mcm","clk":"11886726787","pt":1724118171446,"mc":[{"id":"1.232019056","rc":[{"batb":[[0,1.97,10],[1,1.96,8.05],[2,1.8,129.83]],"ltp":2.06,"tv":83.79,"id":72857114}]}]}
{"op":"mcm","clk":"11886726817","pt":1724118172471,"mc":[{"id":"1.232019056","rc":[{"batb":[[0,1.8,54.6],[1,1.75,9.02],[2,1.62,8.53]],"ltp":1.95,"tv":96.04,"id":72857117}]}]}
{"op":"mcm","clk":"11886735418","pt":1724118175179,"mc":[{"id":"1.232019056","rc":[{"batb":[[0,1.96,8.05],[1,1.8,129.83],[2,1.52,15]],"ltp":2.06,"tv":83.79,"id":72857114},{"batb":[[0,1.81,10],[1,1.8,54.6],[2,1.75,9.02]],"ltp":1.95,"tv":96.04,"id":72857117}]}]}
{"op":"mcm","clk":"11886735473","pt":1724118177093,"mc":[{"id":"1.232019056","rc":[{"batb":[[0,1.97,10],[1,1.96,8.05],[2,1.8,129.83]],"ltp":2.06,"tv":83.79,"id":72857114}]}]}
{"op":"mcm","clk":"11886735516","pt":1724118178289,"mc":[{"id":"1.232019056","rc":[{"batb":[[0,1.8,54.6],[1,1.75,9.02],[2,1.62,8.53]],"ltp":1.95,"tv":96.04,"id":72857117}]}]}
{"op":"mcm","clk":"11886735594","pt":1724118180479,"mc":[{"id":"1.232019056","rc":[{"batb":[[0,1.96,8.05],[1,1.8,129.83],[2,1.52,15]],"ltp":2.06,"tv":83.79,"id":72857114},{"batb":[[0,1.81,10],[1,1.8,54.6],[2,1.75,9.02]],"ltp":1.95,"tv":96.04,"id":72857117}]}]}
{"op":"mcm","clk":"11886735661","pt":1724118182648,"mc":[{"id":"1.232019056","rc":[{"batb":[[0,1.97,10],[1,1.96,8.05],[2,1.8,129.83]],"ltp":2.06,"tv":83.79,"id":72857114}]}]}
{"op":"mcm","clk":"11886735706","pt":1724118183983,"mc":[{"id":"1.232019056","rc":[{"batb":[[0,1.8,54.6],[1,1.75,9.02],[2,1.62,8.53]],"ltp":1.95,"tv":96.04,"id":72857117}]}]}
{"op":"mcm","clk":"11886735791","pt":1724118186194,"mc":[{"id":"1.232019056","rc":[{"batb":[[0,1.96,8.05],[1,1.8,129.83],[2,1.52,15]],"ltp":2.06,"tv":83.79,"id":72857114},{"batb":[[0,1.81,10],[1,1.8,54.6],[2,1.75,9.02]],"ltp":1.95,"tv":96.04,"id":72857117}]}]}
{"op":"mcm","clk":"11886735888","pt":1724118188771,"mc":[{"id":"1.232019056","rc":[{"batb":[[0,1.97,10],[1,1.96,8.05],[2,1.8,129.83]],"ltp":2.06,"tv":83.79,"id":72857114}]}]}
{"op":"mcm","clk":"11886735924","pt":1724118189495,"mc":[{"id":"1.232019056","rc":[{"batb":[[2,1.81,6.77]],"ltp":2.06,"tv":83.79,"id":72857114},{"batb":[[0,1.8,54.6],[1,1.75,9.02],[2,1.62,8.53]],"batl":[[0,2.24,5.45],[1,5,1.54],[2,9,1.54]],"ltp":1.95,"tv":96.04,"id":72857117}]}]}
{"op":"mcm","clk":"11886735972","pt":1724118190886,"mc":[{"id":"1.232019056","rc":[{"batb":[[2,1.8,129.83]],"ltp":2.06,"tv":83.79,"id":72857114},{"batl":[[0,5,1.54],[1,9,1.54],[2,9,0]],"ltp":1.95,"tv":96.04,"id":72857117}]}]}
{"op":"mcm","clk":"11886736006","pt":1724118192170,"mc":[{"id":"1.232019056","rc":[{"batb":[[0,1.96,8.05],[1,1.8,129.83],[2,1.52,15]],"ltp":2.06,"tv":83.79,"id":72857114},{"batb":[[0,1.81,10],[1,1.8,54.6],[2,1.75,9.02]],"ltp":1.95,"tv":96.04,"id":72857117}]}]}
{"op":"mcm","clk":"11886736088","pt":1724118194381,"mc":[{"id":"1.232019056","rc":[{"batb":[[0,1.97,10],[1,1.96,8.05],[2,1.8,129.83]],"ltp":2.06,"tv":83.79,"id":72857114}]}]}
{"op":"mcm","clk":"11886736133","pt":1724118195509,"mc":[{"id":"1.232019056","rc":[{"batb":[[0,1.8,54.6],[1,1.75,9.02],[2,1.62,8.53]],"ltp":1.95,"tv":96.04,"id":72857117}]}]}
{"op":"mcm","clk":"11886736218","pt":1724118197672,"mc":[{"id":"1.232019056","rc":[{"batb":[[0,1.96,8.05],[1,1.8,129.83],[2,1.52,15]],"ltp":2.06,"tv":83.79,"id":72857114},{"batb":[[0,1.81,10],[1,1.8,54.6],[2,1.75,9.02]],"ltp":1.95,"tv":96.04,"id":72857117}]}]}
{"op":"mcm","clk":"11886736323","pt":1724118200189,"mc":[{"id":"1.232019056","rc":[{"batb":[[0,1.97,10],[1,1.96,8.05],[2,1.8,129.83]],"ltp":2.06,"tv":83.79,"id":72857114}]}]}
{"op":"mcm","clk":"11886736361","pt":1724118201015,"mc":[{"id":"1.232019056","rc":[{"batb":[[0,1.8,54.6],[1,1.75,9.02],[2,1.62,8.53]],"ltp":1.95,"tv":96.04,"id":72857117}]}]}
{"op":"mcm","clk":"11886736505","pt":1724118203493,"mc":[{"id":"1.232019056","rc":[{"batb":[[0,1.96,8.05],[1,1.8,129.83],[2,1.52,15]],"ltp":2.06,"tv":83.79,"id":72857114},{"batb":[[0,1.81,10],[1,1.8,54.6],[2,1.75,9.02]],"ltp":1.95,"tv":96.04,"id":72857117}]}]}
{"op":"mcm","clk":"11886736627","pt":1724118205803,"mc":[{"id":"1.232019056","rc":[{"batb":[[0,1.97,10],[1,1.96,8.05],[2,1.8,129.83]],"ltp":2.06,"tv":83.79,"id":72857114}]}]}
{"op":"mcm","clk":"11886736685","pt":1724118206884,"mc":[{"id":"1.232019056","rc":[{"batb":[[0,1.8,54.6],[1,1.75,9.02],[2,1.62,8.53]],"ltp":1.95,"tv":96.04,"id":72857117}]}]}
{"op":"mcm","clk":"11886736772","pt":1724118209205,"mc":[{"id":"1.232019056","rc":[{"batb":[[0,1.96,8.05],[1,1.8,129.83],[2,1.52,15]],"ltp":2.06,"tv":83.79,"id":72857114},{"batb":[[0,1.81,10],[1,1.8,54.6],[2,1.75,9.02]],"ltp":1.95,"tv":96.04,"id":72857117}]}]}
{"op":"mcm","clk":"11886736868","pt":1724118211617,"mc":[{"id":"1.232019056","rc":[{"batb":[[0,1.97,10],[1,1.96,8.05],[2,1.8,129.83]],"ltp":2.06,"tv":83.79,"id":72857114}]}]}
{"op":"mcm","clk":"11886736925","pt":1724118212697,"mc":[{"id":"1.232019056","rc":[{"batb":[[0,1.8,54.6],[1,1.75,9.02],[2,1.62,8.53]],"ltp":1.95,"tv":96.04,"id":72857117}]}]}
{"op":"mcm","clk":"11886737023","pt":1724118215018,"mc":[{"id":"1.232019056","rc":[{"batb":[[0,1.96,8.05],[1,1.8,129.83],[2,1.52,15]],"ltp":2.06,"tv":83.79,"id":72857114},{"batb":[[0,1.81,10],[1,1.8,54.6],[2,1.75,9.02]],"ltp":1.95,"tv":96.04,"id":72857117}]}]}
{"op":"mcm","clk":"11886737112","pt":1724118217233,"mc":[{"id":"1.232019056","rc":[{"batb":[[0,1.97,10],[1,1.96,8.05],[2,1.8,129.83]],"ltp":2.06,"tv":83.79,"id":72857114}]}]}
{"op":"mcm","clk":"11886737149","pt":1724118218214,"mc":[{"id":"1.232019056","rc":[{"batb":[[0,1.8,54.6],[1,1.75,9.02],[2,1.62,8.53]],"ltp":1.95,"tv":96.04,"id":72857117}]}]}
{"op":"mcm","clk":"11886737240","pt":1724118220438,"mc":[{"id":"1.232019056","rc":[{"batb":[[0,1.96,8.05],[1,1.8,129.83],[2,1.52,15]],"ltp":2.06,"tv":83.79,"id":72857114},{"batb":[[0,1.81,10],[1,1.8,54.6],[2,1.75,9.02]],"ltp":1.95,"tv":96.04,"id":72857117}]}]}
{"op":"mcm","clk":"11886737354","pt":1724118223697,"mc":[{"id":"1.232019056","rc":[{"batb":[[0,1.8,54.6],[1,1.75,9.02],[2,1.62,8.53]],"ltp":1.95,"tv":96.04,"id":72857117}]}]}
{"op":"mcm","clk":"11886737364","pt":1724118223904,"mc":[{"id":"1.232019056","rc":[{"batb":[[0,1.97,10],[1,1.96,8.05],[2,1.8,129.83]],"ltp":2.06,"tv":83.79,"id":72857114}]}]}
{"op":"mcm","clk":"11886737465","pt":1724118226314,"mc":[{"id":"1.232019056","rc":[{"batb":[[0,1.81,10],[1,1.8,54.6],[2,1.75,9.02]],"ltp":1.95,"tv":96.04,"id":72857117}]}]}
{"op":"mcm","clk":"11886737495","pt":1724118227240,"mc":[{"id":"1.232019056","rc":[{"batb":[[0,1.96,8.05],[1,1.8,129.83],[2,1.52,15]],"ltp":2.06,"tv":83.79,"id":72857114}]}]}
{"op":"mcm","clk":"11886737605","pt":1724118229736,"mc":[{"id":"1.232019056","rc":[{"batb":[[0,1.97,10],[1,1.96,8.05],[2,1.8,129.83]],"ltp":2.06,"tv":83.79,"id":72857114},{"batb":[[0,1.8,54.6],[1,1.75,9.02],[2,1.62,8.53]],"ltp":1.95,"tv":96.04,"id":72857117}]}]}
{"op":"mcm","clk":"11886737672","pt":1724118231943,"mc":[{"id":"1.232019056","rc":[{"batb":[[0,1.81,10],[1,1.8,54.6],[2,1.75,9.02]],"ltp":1.95,"tv":96.04,"id":72857117}]}]}
{"op":"mcm","clk":"11886737722","pt":1724118233125,"mc":[{"id":"1.232019056","rc":[{"batb":[[0,1.96,8.05],[1,1.8,129.83],[2,1.52,15]],"ltp":2.06,"tv":83.79,"id":72857114}]}]}
{"op":"mcm","clk":"11886737814","pt":1724118235342,"mc":[{"id":"1.232019056","rc":[{"batb":[[0,1.97,10],[1,1.96,8.05],[2,1.8,129.83]],"ltp":2.06,"tv":83.79,"id":72857114},{"batb":[[0,1.8,54.6],[1,1.75,9.02],[2,1.62,8.53]],"ltp":1.95,"tv":96.04,"id":72857117}]}]}
{"op":"mcm","clk":"11886737946","pt":1724118238734,"mc":[{"id":"1.232019056","rc":[{"batb":[[0,1.96,8.05],[1,1.8,129.83],[2,1.52,15]],"ltp":2.06,"tv":83.79,"id":72857114},{"batb":[[0,1.81,10],[1,1.8,54.6],[2,1.75,9.02]],"ltp":1.95,"tv":96.04,"id":72857117}]}]}
{"op":"mcm","clk":"11886738047","pt":1724118241364,"mc":[{"id":"1.232019056","rc":[{"batb":[[0,1.97,10],[1,1.96,8.05],[2,1.8,129.83]],"ltp":2.06,"tv":83.79,"id":72857114},{"batb":[[0,1.8,54.6],[1,1.75,9.02],[2,1.62,8.53]],"ltp":1.95,"tv":96.04,"id":72857117}]}]}
{"op":"mcm","clk":"11886738160","pt":1724118243528,"mc":[{"id":"1.232019056","rc":[{"batb":[[0,1.81,10],[1,1.8,54.6],[2,1.75,9.02]],"ltp":1.95,"tv":96.04,"id":72857117}]}]}
{"op":"mcm","clk":"11886738191","pt":1724118244451,"mc":[{"id":"1.232019056","rc":[{"batb":[[0,1.96,8.05],[1,1.8,129.83],[2,1.52,15]],"ltp":2.06,"tv":83.79,"id":72857114}]}]}
{"op":"mcm","clk":"11886738271","pt":1724118246972,"mc":[{"id":"1.232019056","rc":[{"batb":[[0,1.97,10],[1,1.96,8.05],[2,1.8,129.83]],"ltp":2.06,"tv":83.79,"id":72857114},{"batb":[[0,1.8,54.6],[1,1.75,9.02],[2,1.62,8.53]],"ltp":1.95,"tv":96.04,"id":72857117}]}]}
{"op":"mcm","clk":"11886738364","pt":1724118249132,"mc":[{"id":"1.232019056","rc":[{"batb":[[0,1.81,10],[1,1.8,54.6],[2,1.75,9.02]],"ltp":1.95,"tv":96.04,"id":72857117}]}]}
{"op":"mcm","clk":"11886738396","pt":1724118250360,"mc":[{"id":"1.232019056","rc":[{"batb":[[0,1.96,8.05],[1,1.8,129.83],[2,1.52,15]],"ltp":2.06,"tv":83.79,"id":72857114}]}]}
{"op":"mcm","clk":"11886738490","pt":1724118252778,"mc":[{"id":"1.232019056","rc":[{"batb":[[0,1.97,10],[1,1.96,8.05],[2,1.8,129.83]],"ltp":2.06,"tv":83.79,"id":72857114},{"batb":[[0,1.8,54.6],[1,1.75,9.02],[2,1.62,8.53]],"ltp":1.95,"tv":96.04,"id":72857117}]}]}
{"op":"mcm","clk":"11886738588","pt":1724118255359,"mc":[{"id":"1.232019056","rc":[{"batb":[[0,1.81,10],[1,1.8,54.6],[2,1.75,9.02]],"ltp":1.95,"tv":96.04,"id":72857117}]}]}
{"op":"mcm","clk":"11886738610","pt":1724118256177,"mc":[{"id":"1.232019056","rc":[{"batb":[[0,1.96,8.05],[1,1.8,129.83],[2,1.52,15]],"ltp":2.06,"tv":83.79,"id":72857114}]}]}
{"op":"mcm","clk":"11886738711","pt":1724118258752,"mc":[{"id":"1.232019056","rc":[{"batb":[[0,1.97,10],[1,1.96,8.05],[2,1.8,129.83]],"ltp":2.06,"tv":83.79,"id":72857114},{"batb":[[0,1.8,54.6],[1,1.75,9.02],[2,1.62,8.53]],"ltp":1.95,"tv":96.04,"id":72857117}]}]}
{"op":"mcm","clk":"11886738773","pt":1724118260860,"mc":[{"id":"1.232019056","rc":[{"batb":[[0,1.81,10],[1,1.8,54.6],[2,1.75,9.02]],"ltp":1.95,"tv":96.04,"id":72857117}]}]}
{"op":"mcm","clk":"11886738804","pt":1724118262092,"mc":[{"id":"1.232019056","rc":[{"batb":[[0,1.96,8.05],[1,1.8,129.83],[2,1.52,15]],"ltp":2.06,"tv":83.79,"id":72857114}]}]}
{"op":"mcm","clk":"11886738895","pt":1724118264461,"mc":[{"id":"1.232019056","rc":[{"batb":[[0,1.97,10],[1,1.96,8.05],[2,1.8,129.83]],"ltp":2.06,"tv":83.79,"id":72857114},{"batb":[[0,1.8,54.6],[1,1.75,9.02],[2,1.62,8.53]],"ltp":1.95,"tv":96.04,"id":72857117}]}]}
{"op":"mcm","clk":"11886739022","pt":1724118267698,"mc":[{"id":"1.232019056","rc":[{"batb":[[0,1.96,8.05],[1,1.8,129.83],[2,1.52,15]],"ltp":2.06,"tv":83.79,"id":72857114},{"batb":[[0,1.81,10],[1,1.8,54.6],[2,1.75,9.02]],"ltp":1.95,"tv":96.04,"id":72857117}]}]}
{"op":"mcm","clk":"11886739100","pt":1724118270374,"mc":[{"id":"1.232019056","rc":[{"batb":[[0,1.97,10],[1,1.96,8.05],[2,1.8,129.83]],"ltp":2.06,"tv":83.79,"id":72857114},{"batb":[[0,1.8,54.6],[1,1.75,9.02],[2,1.62,8.53]],"ltp":1.95,"tv":96.04,"id":72857117}]}]}
{"op":"mcm","clk":"11886739193","pt":1724118272801,"mc":[{"id":"1.232019056","rc":[{"batb":[[0,1.81,10],[1,1.8,54.6],[2,1.75,9.02]],"ltp":1.95,"tv":96.04,"id":72857117}]}]}
{"op":"mcm","clk":"11886739218","pt":1724118273680,"mc":[{"id":"1.232019056","rc":[{"batb":[[0,1.96,8.05],[1,1.8,129.83],[2,1.52,15]],"ltp":2.06,"tv":83.79,"id":72857114}]}]}
{"op":"mcm","clk":"11886739316","pt":1724118276303,"mc":[{"id":"1.232019056","rc":[{"batb":[[0,1.97,10],[1,1.96,8.05],[2,1.8,129.83]],"ltp":2.06,"tv":83.79,"id":72857114},{"batb":[[0,1.8,54.6],[1,1.75,9.02],[2,1.62,8.53]],"ltp":1.95,"tv":96.04,"id":72857117}]}]}
{"op":"mcm","clk":"11886739456","pt":1724118279807,"mc":[{"id":"1.232019056","rc":[{"batb":[[0,1.96,8.05],[1,1.8,129.83],[2,1.52,15]],"ltp":2.06,"tv":83.79,"id":72857114},{"batb":[[0,1.81,10],[1,1.8,54.6],[2,1.75,9.02]],"ltp":1.95,"tv":96.04,"id":72857117}]}]}
{"op":"mcm","clk":"11886739568","pt":1724118282084,"mc":[{"id":"1.232019056","rc":[{"batb":[[0,1.97,10],[1,1.96,8.05],[2,1.8,129.83]],"ltp":2.06,"tv":83.79,"id":72857114}]}]}
{"op":"mcm","clk":"11886739626","pt":1724118283212,"mc":[{"id":"1.232019056","rc":[{"batb":[[0,1.8,54.6],[1,1.75,9.02],[2,1.62,8.53]],"ltp":1.95,"tv":96.04,"id":72857117}]}]}
{"op":"mcm","clk":"11886739726","pt":1724118285521,"mc":[{"id":"1.232019056","rc":[{"batb":[[0,1.96,8.05],[1,1.8,129.83],[2,1.52,15]],"ltp":2.06,"tv":83.79,"id":72857114},{"batb":[[0,1.81,10],[1,1.8,54.6],[2,1.75,9.02]],"ltp":1.95,"tv":96.04,"id":72857117}]}]}
{"op":"mcm","clk":"11886739814","pt":1724118288094,"mc":[{"id":"1.232019056","rc":[{"batb":[[0,1.97,10],[1,1.96,8.05],[2,1.8,129.83]],"ltp":2.06,"tv":83.79,"id":72857114}]}]}
{"op":"mcm","clk":"11886739845","pt":1724118288921,"mc":[{"id":"1.232019056","rc":[{"batb":[[0,1.8,54.6],[1,1.75,9.02],[2,1.62,8.53]],"ltp":1.95,"tv":96.04,"id":72857117}]}]}
{"op":"mcm","clk":"11886739928","pt":1724118291422,"mc":[{"id":"1.232019056","rc":[{"batb":[[0,1.96,8.05],[1,1.8,129.83],[2,1.52,15]],"ltp":2.06,"tv":83.79,"id":72857114},{"batb":[[0,1.81,10],[1,1.8,54.6],[2,1.75,9.02]],"ltp":1.95,"tv":96.04,"id":72857117}]}]}
{"op":"mcm","clk":"11886740003","pt":1724118293603,"mc":[{"id":"1.232019056","rc":[{"batb":[[0,1.97,10],[1,1.96,8.05],[2,1.8,129.83]],"ltp":2.06,"tv":83.79,"id":72857114}]}]}
{"op":"mcm","clk":"11886740040","pt":1724118294832,"mc":[{"id":"1.232019056","rc":[{"batb":[[0,1.8,54.6],[1,1.75,9.02],[2,1.62,8.53]],"ltp":1.95,"tv":96.04,"id":72857117}]}]}
{"op":"mcm","clk":"11886740138","pt":1724118297117,"mc":[{"id":"1.232019056","rc":[{"batb":[[0,1.96,8.05],[1,1.8,129.83],[2,1.52,15]],"ltp":2.06,"tv":83.79,"id":72857114},{"batb":[[0,1.81,10],[1,1.8,54.6],[2,1.75,9.02]],"ltp":1.95,"tv":96.04,"id":72857117}]}]}
{"op":"mcm","clk":"11886740238","pt":1724118299635,"mc":[{"id":"1.232019056","rc":[{"batb":[[0,1.97,10],[1,1.96,8.05],[2,1.8,129.83]],"ltp":2.06,"tv":83.79,"id":72857114}]}]}
{"op":"mcm","clk":"11886740277","pt":1724118300416,"mc":[{"id":"1.232019056","rc":[{"batb":[[0,1.8,54.6],[1,1.75,9.02],[2,1.62,8.53]],"ltp":1.95,"tv":96.04,"id":72857117}]}]}
{"op":"mcm","clk":"11886740396","pt":1724118303040,"mc":[{"id":"1.232019056","rc":[{"batb":[[0,1.96,8.05],[1,1.8,129.83],[2,1.52,15]],"ltp":2.06,"tv":83.79,"id":72857114},{"batb":[[0,1.81,10],[1,1.8,54.6],[2,1.75,9.02]],"ltp":1.95,"tv":96.04,"id":72857117}]}]}
{"op":"mcm","clk":"11886740475","pt":1724118305150,"mc":[{"id":"1.232019056","rc":[{"batb":[[0,1.97,10],[1,1.96,8.05],[2,1.8,129.83]],"ltp":2.06,"tv":83.79,"id":72857114}]}]}
{"op":"mcm","clk":"11886740520","pt":1724118306437,"mc":[{"id":"1.232019056","rc":[{"batb":[[0,1.8,54.6],[1,1.75,9.02],[2,1.62,8.53]],"ltp":1.95,"tv":96.04,"id":72857117}]}]}
{"op":"mcm","clk":"11886740606","pt":1724118308748,"mc":[{"id":"1.232019056","rc":[{"batb":[[0,1.96,8.05],[1,1.8,129.83],[2,1.52,15]],"ltp":2.06,"tv":83.79,"id":72857114},{"batb":[[0,1.81,10],[1,1.8,54.6],[2,1.75,9.02]],"ltp":1.95,"tv":96.04,"id":72857117}]}]}
{"op":"mcm","clk":"11886740702","pt":1724118311032,"mc":[{"id":"1.232019056","rc":[{"batb":[[0,1.97,10],[1,1.96,8.05],[2,1.8,129.83]],"ltp":2.06,"tv":83.79,"id":72857114}]}]}
{"op":"mcm","clk":"11886740752","pt":1724118312057,"mc":[{"id":"1.232019056","rc":[{"batb":[[0,1.8,54.6],[1,1.75,9.02],[2,1.62,8.53]],"ltp":1.95,"tv":96.04,"id":72857117}]}]}
{"op":"mcm","clk":"11886740830","pt":1724118314424,"mc":[{"id":"1.232019056","rc":[{"batb":[[0,1.96,8.05],[1,1.8,129.83],[2,1.52,15]],"ltp":2.06,"tv":83.79,"id":72857114},{"batb":[[0,1.81,10],[1,1.8,54.6],[2,1.75,9.02]],"ltp":1.95,"tv":96.04,"id":72857117}]}]}
{"op":"mcm","clk":"11886740957","pt":1724118317661,"mc":[{"id":"1.232019056","rc":[{"batb":[[0,1.97,10],[1,1.96,8.05],[2,1.8,129.83]],"ltp":2.06,"tv":83.79,"id":72857114},{"batb":[[0,1.8,54.6],[1,1.75,9.02],[2,1.62,8.53]],"ltp":1.95,"tv":96.04,"id":72857117}]}]}
{"op":"mcm","clk":"11886741091","pt":1724118320641,"mc":[{"id":"1.232019056","rc":[{"batb":[[0,1.96,8.05],[1,1.8,129.83],[2,1.52,15]],"ltp":2.06,"tv":83.79,"id":72857114}]}]}
{"op":"mcm","clk":"11886741101","pt":1724118320844,"mc":[{"id":"1.232019056","rc":[{"batb":[[0,1.81,10],[1,1.8,54.6],[2,1.75,9.02]],"ltp":1.95,"tv":96.04,"id":72857117}]}]}
{"op":"mcm","clk":"11886741201","pt":1724118323265,"mc":[{"id":"1.232019056","rc":[{"batb":[[0,1.97,10],[1,1.96,8.05],[2,1.8,129.83]],"ltp":2.06,"tv":83.79,"id":72857114}]}]}
{"op":"mcm","clk":"11886741240","pt":1724118324245,"mc":[{"id":"1.232019056","rc":[{"batb":[[0,1.8,54.6],[1,1.75,9.02],[2,1.62,8.53]],"ltp":1.95,"tv":96.04,"id":72857117}]}]}
{"op":"mcm","clk":"11886741324","pt":1724118326560,"mc":[{"id":"1.232019056","rc":[{"batb":[[0,1.96,8.05],[1,1.8,129.83],[2,1.52,15]],"ltp":2.06,"tv":83.79,"id":72857114},{"batb":[[0,1.81,10],[1,1.8,54.6],[2,1.75,9.02]],"ltp":1.95,"tv":96.04,"id":72857117}]}]}
{"op":"mcm","clk":"11886741405","pt":1724118328970,"mc":[{"id":"1.232019056","rc":[{"batb":[[0,1.97,10],[1,1.96,8.05],[2,1.8,129.83]],"ltp":2.06,"tv":83.79,"id":72857114}]}]}
{"op":"mcm","clk":"11886741435","pt":1724118329951,"mc":[{"id":"1.232019056","rc":[{"batb":[[0,1.8,54.6],[1,1.75,9.02],[2,1.62,8.53]],"ltp":1.95,"tv":96.04,"id":72857117}]}]}
{"op":"mcm","clk":"11886741522","pt":1724118332267,"mc":[{"id":"1.232019056","rc":[{"batb":[[0,1.96,8.05],[1,1.8,129.83],[2,1.52,15]],"ltp":2.06,"tv":83.79,"id":72857114},{"batb":[[0,1.81,10],[1,1.8,54.6],[2,1.75,9.02]],"ltp":1.95,"tv":96.04,"id":72857117}]}]}
{"op":"mcm","clk":"11886741671","pt":1724118334560,"mc":[{"id":"1.232019056","rc":[{"batb":[[0,1.97,10],[1,1.96,8.05],[2,1.8,129.83]],"ltp":2.06,"tv":83.79,"id":72857114}]}]}
{"op":"mcm","clk":"11886741729","pt":1724118335586,"mc":[{"id":"1.232019056","rc":[{"batb":[[0,1.8,54.6],[1,1.75,9.02],[2,1.62,8.53]],"ltp":1.95,"tv":96.04,"id":72857117}]}]}
{"op":"mcm","clk":"11886741827","pt":1724118338164,"mc":[{"id":"1.232019056","rc":[{"batb":[[0,1.96,8.05],[1,1.8,129.83],[2,1.52,15]],"ltp":2.06,"tv":83.79,"id":72857114},{"batb":[[0,1.81,10],[1,1.8,54.6],[2,1.75,9.02]],"ltp":1.95,"tv":96.04,"id":72857117}]}]}
{"op":"mcm","clk":"11886741927","pt":1724118340493,"mc":[{"id":"1.232019056","rc":[{"batb":[[0,1.97,10],[1,1.96,8.05],[2,1.8,129.83]],"ltp":2.06,"tv":83.79,"id":72857114}]}]}
{"op":"mcm","clk":"11886741968","pt":1724118341471,"mc":[{"id":"1.232019056","rc":[{"batb":[[0,1.8,54.6],[1,1.75,9.02],[2,1.62,8.53]],"ltp":1.95,"tv":96.04,"id":72857117}]}]}
{"op":"mcm","clk":"11886742076","pt":1724118344085,"mc":[{"id":"1.232019056","rc":[{"batb":[[0,1.96,8.05],[1,1.8,129.83],[2,1.52,15]],"ltp":2.06,"tv":83.79,"id":72857114},{"batb":[[0,1.81,10],[1,1.8,54.6],[2,1.75,9.02]],"ltp":1.95,"tv":96.04,"id":72857117}]}]}
{"op":"mcm","clk":"11886742169","pt":1724118346497,"mc":[{"id":"1.232019056","rc":[{"batb":[[0,1.97,10],[1,1.96,8.05],[2,1.8,129.83]],"ltp":2.06,"tv":83.79,"id":72857114}]}]}
{"op":"mcm","clk":"11886742201","pt":1724118347480,"mc":[{"id":"1.232019056","rc":[{"batb":[[0,1.8,54.6],[1,1.75,9.02],[2,1.62,8.53]],"ltp":1.95,"tv":96.04,"id":72857117}]}]}
{"op":"mcm","clk":"11886742318","pt":1724118349793,"mc":[{"id":"1.232019056","rc":[{"batb":[[0,1.96,8.05],[1,1.8,129.83],[2,1.52,15]],"ltp":2.06,"tv":83.79,"id":72857114}]}]}
{"op":"mcm","clk":"11886742327","pt":1724118349896,"mc":[{"id":"1.232019056","rc":[{"batb":[[0,1.81,10],[1,1.8,54.6],[2,1.75,9.02]],"ltp":1.95,"tv":96.04,"id":72857117}]}]}
{"op":"mcm","clk":"11886742430","pt":1724118352066,"mc":[{"id":"1.232019056","rc":[{"batb":[[0,1.97,10],[1,1.96,8.05],[2,1.8,129.83]],"ltp":2.06,"tv":83.79,"id":72857114}]}]}
{"op":"mcm","clk":"11886742479","pt":1724118353402,"mc":[{"id":"1.232019056","rc":[{"batb":[[0,1.8,54.6],[1,1.75,9.02],[2,1.62,8.53]],"ltp":1.95,"tv":96.04,"id":72857117}]}]}
{"op":"mcm","clk":"11886742603","pt":1724118355574,"mc":[{"id":"1.232019056","rc":[{"batb":[[0,1.96,8.05],[1,1.8,129.83],[2,1.52,15]],"ltp":2.06,"tv":83.79,"id":72857114},{"batb":[[0,1.81,10],[1,1.8,54.6],[2,1.75,9.02]],"ltp":1.95,"tv":96.04,"id":72857117}]}]}
{"op":"mcm","clk":"11886742721","pt":1724118358196,"mc":[{"id":"1.232019056","rc":[{"batb":[[0,1.97,10],[1,1.96,8.05],[2,1.8,129.83]],"ltp":2.06,"tv":83.79,"id":72857114}]}]}
{"op":"mcm","clk":"11886742754","pt":1724118358964,"mc":[{"id":"1.232019056","rc":[{"batb":[[0,1.8,54.6],[1,1.75,9.02],[2,1.62,8.53]],"ltp":1.95,"tv":96.04,"id":72857117}]}]}
{"op":"mcm","clk":"11886742864","pt":1724118361499,"mc":[{"id":"1.232019056","rc":[{"batb":[[0,1.96,8.05],[1,1.8,129.83],[2,1.52,15]],"ltp":2.06,"tv":83.79,"id":72857114},{"batb":[[0,1.81,10],[1,1.8,54.6],[2,1.75,9.02]],"ltp":1.95,"tv":96.04,"id":72857117}]}]}
{"op":"mcm","clk":"11886742914","pt":1724118362387,"mc":[{"id":"1.232019056","rc":[{"batb":[[1,1.81,6.77],[2,1.8,129.83]],"ltp":2.06,"tv":83.79,"id":72857114},{"batl":[[0,2.24,5.45],[1,5,1.54],[2,9,1.54]],"ltp":1.95,"tv":96.04,"id":72857117}]}]}
{"op":"mcm","clk":"11886742976","pt":1724118363673,"mc":[{"id":"1.232019056","rc":[{"batb":[[0,1.97,10],[1,1.96,8.05],[2,1.81,6.77]],"ltp":2.06,"tv":83.79,"id":72857114}]}]}
{"op":"mcm","clk":"11886743022","pt":1724118364699,"mc":[{"id":"1.232019056","rc":[{"batb":[[2,1.8,129.83]],"ltp":2.06,"tv":83.79,"id":72857114},{"batb":[[0,1.8,54.6],[1,1.75,9.02],[2,1.62,8.53]],"batl":[[0,5,1.54],[1,9,1.54],[2,9,0]],"ltp":1.95,"tv":96.04,"id":72857117}]}]}
{"op":"mcm","clk":"11886743134","pt":1724118367117,"mc":[{"id":"1.232019056","rc":[{"batb":[[0,1.96,8.05],[1,1.8,129.83],[2,1.52,15]],"ltp":2.06,"tv":83.79,"id":72857114},{"batb":[[0,1.81,10],[1,1.8,54.6],[2,1.75,9.02]],"ltp":1.95,"tv":96.04,"id":72857117}]}]}
{"op":"mcm","clk":"11886743220","pt":1724118369483,"mc":[{"id":"1.232019056","rc":[{"batb":[[0,1.97,10],[1,1.96,8.05],[2,1.8,129.83]],"ltp":2.06,"tv":83.79,"id":72857114}]}]}
{"op":"mcm","clk":"11886743253","pt":1724118370411,"mc":[{"id":"1.232019056","rc":[{"batb":[[0,1.8,54.6],[1,1.75,9.02],[2,1.62,8.53]],"ltp":1.95,"tv":96.04,"id":72857117}]}]}
{"op":"mcm","clk":"11886743389","pt":1724118372723,"mc":[{"id":"1.232019056","rc":[{"batb":[[0,1.96,8.05],[1,1.8,129.83],[2,1.52,15]],"ltp":2.06,"tv":83.79,"id":72857114},{"batb":[[0,1.81,10],[1,1.8,54.6],[2,1.75,9.02]],"ltp":1.95,"tv":96.04,"id":72857117}]}]}
{"op":"mcm","clk":"11886743479","pt":1724118375302,"mc":[{"id":"1.232019056","rc":[{"batb":[[0,1.97,10],[1,1.96,8.05],[2,1.8,129.83]],"ltp":2.06,"tv":83.79,"id":72857114}]}]}
{"op":"mcm","clk":"11886743512","pt":1724118376022,"mc":[{"id":"1.232019056","rc":[{"batb":[[0,1.8,54.6],[1,1.75,9.02],[2,1.62,8.53]],"ltp":1.95,"tv":96.04,"id":72857117}]}]}
{"op":"mcm","clk":"11886743616","pt":1724118378497,"mc":[{"id":"1.232019056","rc":[{"batb":[[0,1.96,8.05],[1,1.8,129.83],[2,1.52,15]],"ltp":2.06,"tv":83.79,"id":72857114},{"batb":[[0,1.81,10],[1,1.8,54.6],[2,1.75,9.02]],"ltp":1.95,"tv":96.04,"id":72857117}]}]}
{"op":"mcm","clk":"11886743700","pt":1724118380814,"mc":[{"id":"1.232019056","rc":[{"batb":[[0,1.97,10],[1,1.96,8.05],[2,1.8,129.83]],"ltp":2.06,"tv":83.79,"id":72857114}]}]}
{"op":"mcm","clk":"11886743720","pt":1724118381631,"mc":[{"id":"1.232019056","rc":[{"batb":[[0,1.8,54.6],[1,1.75,9.02],[2,1.62,8.53]],"ltp":1.95,"tv":96.04,"id":72857117}]}]}
{"op":"mcm","clk":"11886743805","pt":1724118384305,"mc":[{"id":"1.232019056","rc":[{"batb":[[0,1.96,8.05],[1,1.8,129.83],[2,1.52,15]],"ltp":2.06,"tv":83.79,"id":72857114},{"batb":[[0,1.81,10],[1,1.8,54.6],[2,1.75,9.02]],"ltp":1.95,"tv":96.04,"id":72857117}]}]}
{"op":"mcm","clk":"11886743911","pt":1724118386517,"mc":[{"id":"1.232019056","rc":[{"batb":[[0,1.97,10],[1,1.96,8.05],[2,1.8,129.83]],"ltp":2.06,"tv":83.79,"id":72857114}]}]}
{"op":"mcm","clk":"11886743949","pt":1724118387336,"mc":[{"id":"1.232019056","rc":[{"batb":[[0,1.8,54.6],[1,1.75,9.02],[2,1.62,8.53]],"ltp":1.95,"tv":96.04,"id":72857117}]}]}
{"op":"mcm","clk":"11886744025","pt":1724118389711,"mc":[{"id":"1.232019056","rc":[{"batb":[[0,1.96,8.05],[1,1.8,129.83],[2,1.52,15]],"ltp":2.06,"tv":83.79,"id":72857114},{"batb":[[0,1.81,10],[1,1.8,54.6],[2,1.75,9.02]],"ltp":1.95,"tv":96.04,"id":72857117}]}]}
{"op":"mcm","clk":"11886744115","pt":1724118392140,"mc":[{"id":"1.232019056","rc":[{"batb":[[0,1.97,10],[1,1.96,8.05],[2,1.8,129.83]],"ltp":2.06,"tv":83.79,"id":72857114}]}]}
{"op":"mcm","clk":"11886744153","pt":1724118392955,"mc":[{"id":"1.232019056","rc":[{"batb":[[0,1.8,54.6],[1,1.75,9.02],[2,1.62,8.53]],"ltp":1.95,"tv":96.04,"id":72857117}]}]}
{"op":"mcm","clk":"11886744278","pt":1724118395329,"mc":[{"id":"1.232019056","rc":[{"batb":[[0,1.96,8.05],[1,1.8,129.83],[2,1.52,15]],"ltp":2.06,"tv":83.79,"id":72857114},{"batb":[[0,1.81,10],[1,1.8,54.6],[2,1.75,9.02]],"ltp":1.95,"tv":96.04,"id":72857117}]}]}
{"op":"mcm","clk":"11886744382","pt":1724118397742,"mc":[{"id":"1.232019056","rc":[{"batb":[[0,1.97,10],[1,1.96,8.05],[2,1.8,129.83]],"ltp":2.06,"tv":83.79,"id":72857114}]}]}
{"op":"mcm","clk":"11886744409","pt":1724118398615,"mc":[{"id":"1.232019056","rc":[{"batb":[[0,1.8,54.6],[1,1.75,9.02],[2,1.62,8.53]],"ltp":1.95,"tv":96.04,"id":72857117}]}]}
{"op":"mcm","clk":"11886744523","pt":1724118401049,"mc":[{"id":"1.232019056","rc":[{"batb":[[0,1.96,8.05],[1,1.8,129.83],[2,1.52,15]],"ltp":2.06,"tv":83.79,"id":72857114},{"batb":[[0,1.81,10],[1,1.8,54.6],[2,1.75,9.02]],"ltp":1.95,"tv":96.04,"id":72857117}]}]}
{"op":"mcm","clk":"11886744649","pt":1724118403565,"mc":[{"id":"1.232019056","rc":[{"batb":[[0,1.97,10],[1,1.96,8.05],[2,1.8,129.83]],"ltp":2.06,"tv":83.79,"id":72857114}]}]}
{"op":"mcm","clk":"11886744689","pt":1724118404446,"mc":[{"id":"1.232019056","rc":[{"batb":[[0,1.8,54.6],[1,1.75,9.02],[2,1.62,8.53]],"ltp":1.95,"tv":96.04,"id":72857117}]}]}
{"op":"mcm","clk":"11886744797","pt":1724118406921,"mc":[{"id":"1.232019056","rc":[{"batb":[[0,1.96,8.05],[1,1.8,129.83],[2,1.52,15]],"ltp":2.06,"tv":83.79,"id":72857114},{"batb":[[0,1.81,10],[1,1.8,54.6],[2,1.75,9.02]],"ltp":1.95,"tv":96.04,"id":72857117}]}]}
{"op":"mcm","clk":"11886744916","pt":1724118409437,"mc":[{"id":"1.232019056","rc":[{"batb":[[0,1.97,10],[1,1.96,8.05],[2,1.8,129.83]],"ltp":2.06,"tv":83.79,"id":72857114}]}]}
{"op":"mcm","clk":"11886744953","pt":1724118410254,"mc":[{"id":"1.232019056","rc":[{"batb":[[0,1.8,54.6],[1,1.75,9.02],[2,1.62,8.53]],"ltp":1.95,"tv":96.04,"id":72857117}]}]}
{"op":"mcm","clk":"11886745048","pt":1724118412664,"mc":[{"id":"1.232019056","rc":[{"batb":[[0,1.96,8.05],[1,1.8,129.83],[2,1.52,15]],"ltp":2.06,"tv":83.79,"id":72857114},{"batb":[[0,1.81,10],[1,1.8,54.6],[2,1.75,9.02]],"ltp":1.95,"tv":96.04,"id":72857117}]}]}
{"op":"mcm","clk":"11886745139","pt":1724118415041,"mc":[{"id":"1.232019056","rc":[{"batb":[[0,1.97,10],[1,1.96,8.05],[2,1.8,129.83]],"ltp":2.06,"tv":83.79,"id":72857114}]}]}
{"op":"mcm","clk":"11886745181","pt":1724118416026,"mc":[{"id":"1.232019056","rc":[{"batb":[[0,1.8,54.6],[1,1.75,9.02],[2,1.62,8.53]],"ltp":1.95,"tv":96.04,"id":72857117}]}]}
{"op":"mcm","clk":"11886745272","pt":1724118418344,"mc":[{"id":"1.232019056","rc":[{"batb":[[0,1.96,8.05],[1,1.8,129.83],[2,1.52,15]],"ltp":2.06,"tv":83.79,"id":72857114},{"batb":[[0,1.81,10],[1,1.8,54.6],[2,1.75,9.02]],"ltp":1.95,"tv":96.04,"id":72857117}]}]}
{"op":"mcm","clk":"11886745356","pt":1724118420628,"mc":[{"id":"1.232019056","rc":[{"batb":[[0,1.97,10],[1,1.96,8.05],[2,1.8,129.83]],"ltp":2.06,"tv":83.79,"id":72857114}]}]}
{"op":"mcm","clk":"11886745385","pt":1724118421654,"mc":[{"id":"1.232019056","rc":[{"batb":[[0,1.8,54.6],[1,1.75,9.02],[2,1.62,8.53]],"ltp":1.95,"tv":96.04,"id":72857117}]}]}
{"op":"mcm","clk":"11886745482","pt":1724118423978,"mc":[{"id":"1.232019056","rc":[{"batb":[[0,1.96,8.05],[1,1.8,129.83],[2,1.52,15]],"ltp":2.06,"tv":83.79,"id":72857114},{"batb":[[0,1.81,10],[1,1.8,54.6],[2,1.75,9.02]],"ltp":1.95,"tv":96.04,"id":72857117}]}]}
{"op":"mcm","clk":"11886745559","pt":1724118426351,"mc":[{"id":"1.232019056","rc":[{"batb":[[0,1.97,10],[1,1.96,8.05],[2,1.8,129.83]],"ltp":2.06,"tv":83.79,"id":72857114}]}]}
{"op":"mcm","clk":"11886745599","pt":1724118427485,"mc":[{"id":"1.232019056","rc":[{"batb":[[0,1.8,54.6],[1,1.75,9.02],[2,1.62,8.53]],"ltp":1.95,"tv":96.04,"id":72857117}]}]}
{"op":"mcm","clk":"11886745687","pt":1724118430065,"mc":[{"id":"1.232019056","rc":[{"batb":[[0,1.96,8.05],[1,1.8,129.83],[2,1.52,15]],"ltp":2.06,"tv":83.79,"id":72857114},{"batb":[[0,1.81,10],[1,1.8,54.6],[2,1.75,9.02]],"ltp":1.95,"tv":96.04,"id":72857117}]}]}
{"op":"mcm","clk":"11886745766","pt":1724118432394,"mc":[{"id":"1.232019056","rc":[{"batb":[[0,1.97,10],[1,1.96,8.05],[2,1.8,129.83]],"ltp":2.06,"tv":83.79,"id":72857114}]}]}
{"op":"mcm","clk":"11886745801","pt":1724118433393,"mc":[{"id":"1.232019056","rc":[{"batb":[[0,1.8,54.6],[1,1.75,9.02],[2,1.62,8.53]],"ltp":1.95,"tv":96.04,"id":72857117}]}]}
{"op":"mcm","clk":"11886745888","pt":1724118435785,"mc":[{"id":"1.232019056","rc":[{"batb":[[0,1.96,8.05],[1,1.8,129.83],[2,1.52,15]],"ltp":2.06,"tv":83.79,"id":72857114},{"batb":[[0,1.81,10],[1,1.8,54.6],[2,1.75,9.02]],"ltp":1.95,"tv":96.04,"id":72857117}]}]}
{"op":"mcm","clk":"11886745962","pt":1724118438100,"mc":[{"id":"1.232019056","rc":[{"batb":[[0,1.97,10],[1,1.96,8.05],[2,1.8,129.83]],"ltp":2.06,"tv":83.79,"id":72857114}]}]}
{"op":"mcm","clk":"11886745997","pt":1724118439084,"mc":[{"id":"1.232019056","rc":[{"batb":[[0,1.8,54.6],[1,1.75,9.02],[2,1.62,8.53]],"ltp":1.95,"tv":96.04,"id":72857117}]}]}
{"op":"mcm","clk":"11886746116","pt":1724118441475,"mc":[{"id":"1.232019056","rc":[{"batb":[[0,1.96,8.05],[1,1.8,129.83],[2,1.52,15]],"ltp":2.06,"tv":83.79,"id":72857114},{"batb":[[0,1.81,10],[1,1.8,54.6],[2,1.75,9.02]],"ltp":1.95,"tv":96.04,"id":72857117}]}]}
{"op":"mcm","clk":"11886746235","pt":1724118443906,"mc":[{"id":"1.232019056","rc":[{"batb":[[0,1.97,10],[1,1.96,8.05],[2,1.8,129.83]],"ltp":2.06,"tv":83.79,"id":72857114}]}]}
{"op":"mcm","clk":"11886746273","pt":1724118444877,"mc":[{"id":"1.232019056","rc":[{"batb":[[0,1.8,54.6],[1,1.75,9.02],[2,1.62,8.53]],"ltp":1.95,"tv":96.04,"id":72857117}]}]}
{"op":"mcm","clk":"11886746358","pt":1724118447198,"mc":[{"id":"1.232019056","rc":[{"batb":[[0,1.96,8.05],[1,1.8,129.83],[2,1.52,15]],"ltp":2.06,"tv":83.79,"id":72857114},{"batb":[[0,1.81,10],[1,1.8,54.6],[2,1.75,9.02]],"ltp":1.95,"tv":96.04,"id":72857117}]}]}
{"op":"mcm","clk":"11886746428","pt":1724118449512,"mc":[{"id":"1.232019056","rc":[{"batb":[[0,1.97,10],[1,1.96,8.05],[2,1.8,129.83]],"ltp":2.06,"tv":83.79,"id":72857114}]}]}
{"op":"mcm","clk":"11886746470","pt":1724118450599,"mc":[{"id":"1.232019056","rc":[{"batb":[[0,1.8,54.6],[1,1.75,9.02],[2,1.62,8.53]],"ltp":1.95,"tv":96.04,"id":72857117}]}]}
{"op":"mcm","clk":"11886746565","pt":1724118453016,"mc":[{"id":"1.232019056","rc":[{"batb":[[0,1.96,8.05],[1,1.8,129.83],[2,1.52,15]],"ltp":2.06,"tv":83.79,"id":72857114},{"batb":[[0,1.81,10],[1,1.8,54.6],[2,1.75,9.02]],"ltp":1.95,"tv":96.04,"id":72857117}]}]}
{"op":"mcm","clk":"11886746644","pt":1724118455325,"mc":[{"id":"1.232019056","rc":[{"batb":[[0,1.97,10],[1,1.96,8.05],[2,1.8,129.83]],"ltp":2.06,"tv":83.79,"id":72857114}]}]}
{"op":"mcm","clk":"11886746678","pt":1724118456400,"mc":[{"id":"1.232019056","rc":[{"batb":[[0,1.8,54.6],[1,1.75,9.02],[2,1.62,8.53]],"ltp":1.95,"tv":96.04,"id":72857117}]}]}
{"op":"mcm","clk":"11886746771","pt":1724118458810,"mc":[{"id":"1.232019056","rc":[{"batb":[[0,1.96,8.05],[1,1.8,129.83],[2,1.52,15]],"ltp":2.06,"tv":83.79,"id":72857114},{"batb":[[0,1.81,10],[1,1.8,54.6],[2,1.75,9.02]],"ltp":1.95,"tv":96.04,"id":72857117}]}]}
{"op":"mcm","clk":"11886746864","pt":1724118461387,"mc":[{"id":"1.232019056","rc":[{"batb":[[0,1.97,10],[1,1.96,8.05],[2,1.8,129.83]],"ltp":2.06,"tv":83.79,"id":72857114}]}]}
{"op":"mcm","clk":"11886746890","pt":1724118462000,"mc":[{"id":"1.232019056","rc":[{"batb":[[0,1.8,54.6],[1,1.75,9.02],[2,1.62,8.53]],"ltp":1.95,"tv":96.04,"id":72857117}]}]}
{"op":"mcm","clk":"11886747019","pt":1724118464937,"mc":[{"id":"1.232019056","rc":[{"batb":[[0,1.96,8.05],[1,1.8,129.83],[2,1.52,15]],"ltp":2.06,"tv":83.79,"id":72857114},{"batb":[[0,1.81,10],[1,1.8,54.6],[2,1.75,9.02]],"ltp":1.95,"tv":96.04,"id":72857117}]}]}
{"op":"mcm","clk":"11886747146","pt":1724118468109,"mc":[{"id":"1.232019056","rc":[{"batb":[[0,1.97,10],[1,1.96,8.05],[2,1.8,129.83]],"ltp":2.06,"tv":83.79,"id":72857114},{"batb":[[0,1.8,54.6],[1,1.75,9.02],[2,1.62,8.53]],"ltp":1.95,"tv":96.04,"id":72857117}]}]}
{"op":"mcm","clk":"11886747257","pt":1724118471442,"mc":[{"id":"1.232019056","rc":[{"batb":[[0,1.96,8.05],[1,1.8,129.83],[2,1.52,15]],"ltp":2.06,"tv":83.79,"id":72857114},{"batb":[[0,1.81,10],[1,1.8,54.6],[2,1.75,9.02]],"ltp":1.95,"tv":96.04,"id":72857117}]}]}
{"op":"mcm","clk":"11886747338","pt":1724118473704,"mc":[{"id":"1.232019056","rc":[{"batb":[[0,1.97,10],[1,1.96,8.05],[2,1.8,129.83]],"ltp":2.06,"tv":83.79,"id":72857114}]}]}
{"op":"mcm","clk":"11886747363","pt":1724118474835,"mc":[{"id":"1.232019056","rc":[{"batb":[[0,1.8,54.6],[1,1.75,9.02],[2,1.62,8.53]],"ltp":1.95,"tv":96.04,"id":72857117}]}]}
{"op":"mcm","clk":"11886747442","pt":1724118477244,"mc":[{"id":"1.232019056","rc":[{"batb":[[0,1.96,8.05],[1,1.8,129.83],[2,1.52,15]],"ltp":2.06,"tv":83.79,"id":72857114},{"batb":[[0,1.81,10],[1,1.8,54.6],[2,1.75,9.02]],"ltp":1.95,"tv":96.04,"id":72857117}]}]}
{"op":"mcm","clk":"11886747541","pt":1724118479610,"mc":[{"id":"1.232019056","rc":[{"batb":[[0,1.97,10],[1,1.96,8.05],[2,1.8,129.83]],"ltp":2.06,"tv":83.79,"id":72857114}]}]}
{"op":"mcm","clk":"11886747576","pt":1724118480639,"mc":[{"id":"1.232019056","rc":[{"batb":[[0,1.8,54.6],[1,1.75,9.02],[2,1.62,8.53]],"ltp":1.95,"tv":96.04,"id":72857117}]}]}
{"op":"mcm","clk":"11886747672","pt":1724118483049,"mc":[{"id":"1.232019056","rc":[{"batb":[[0,1.96,8.05],[1,1.8,129.83],[2,1.52,15]],"ltp":2.06,"tv":83.79,"id":72857114},{"batb":[[0,1.81,10],[1,1.8,54.6],[2,1.75,9.02]],"ltp":1.95,"tv":96.04,"id":72857117}]}]}
{"op":"mcm","clk":"11886747762","pt":1724118485363,"mc":[{"id":"1.232019056","rc":[{"batb":[[0,1.97,10],[1,1.96,8.05],[2,1.8,129.83]],"ltp":2.06,"tv":83.79,"id":72857114}]}]}
{"op":"mcm","clk":"11886747802","pt":1724118486338,"mc":[{"id":"1.232019056","rc":[{"batb":[[0,1.8,54.6],[1,1.75,9.02],[2,1.62,8.53]],"ltp":1.95,"tv":96.04,"id":72857117}]}]}
{"op":"mcm","clk":"11886747882","pt":1724118488647,"mc":[{"id":"1.232019056","rc":[{"batb":[[0,1.96,8.05],[1,1.8,129.83],[2,1.52,15]],"ltp":2.06,"tv":83.79,"id":72857114},{"batb":[[0,1.81,10],[1,1.8,54.6],[2,1.75,9.02]],"ltp":1.95,"tv":96.04,"id":72857117}]}]}
{"op":"mcm","clk":"11886747954","pt":1724118490953,"mc":[{"id":"1.232019056","rc":[{"batb":[[0,1.97,10],[1,1.96,8.05],[2,1.8,129.83]],"ltp":2.06,"tv":83.79,"id":72857114}]}]}
{"op":"mcm","clk":"11886748006","pt":1724118491975,"mc":[{"id":"1.232019056","rc":[{"batb":[[0,1.8,54.6],[1,1.75,9.02],[2,1.62,8.53]],"ltp":1.95,"tv":96.04,"id":72857117}]}]}
{"op":"mcm","clk":"11886748105","pt":1724118494541,"mc":[{"id":"1.232019056","rc":[{"batb":[[0,1.96,8.05],[1,1.8,129.83],[2,1.52,15]],"ltp":2.06,"tv":83.79,"id":72857114},{"batb":[[0,1.81,10],[1,1.8,54.6],[2,1.75,9.02]],"ltp":1.95,"tv":96.04,"id":72857117}]}]}
{"op":"mcm","clk":"11886748179","pt":1724118496861,"mc":[{"id":"1.232019056","rc":[{"batb":[[0,1.97,10],[1,1.96,8.05],[2,1.8,129.83]],"ltp":2.06,"tv":83.79,"id":72857114}]}]}
{"op":"mcm","clk":"11886748228","pt":1724118497988,"mc":[{"id":"1.232019056","rc":[{"batb":[[0,1.8,54.6],[1,1.75,9.02],[2,1.62,8.53]],"ltp":1.95,"tv":96.04,"id":72857117}]}]}
{"op":"mcm","clk":"11886748338","pt":1724118500397,"mc":[{"id":"1.232019056","rc":[{"batb":[[0,1.96,8.05],[1,1.8,129.83],[2,1.52,15]],"ltp":2.06,"tv":83.79,"id":72857114},{"batb":[[0,1.81,10],[1,1.8,54.6],[2,1.75,9.02]],"ltp":1.95,"tv":96.04,"id":72857117}]}]}
{"op":"mcm","clk":"11886748473","pt":1724118502570,"mc":[{"id":"1.232019056","rc":[{"batb":[[0,1.97,10],[1,1.96,8.05],[2,1.8,129.83]],"ltp":2.06,"tv":83.79,"id":72857114}]}]}
{"op":"mcm","clk":"11886748555","pt":1724118503952,"mc":[{"id":"1.232019056","rc":[{"batb":[[0,1.8,54.6],[1,1.75,9.02],[2,1.62,8.53]],"ltp":1.95,"tv":96.04,"id":72857117}]}]}
{"op":"mcm","clk":"11886748629","pt":1724118505796,"mc":[{"id":"1.232019056","rc":[{"batb":[[0,1.96,8.05],[1,1.8,129.83],[2,1.52,15]],"ltp":2.06,"tv":83.79,"id":72857114}]}]}
{"op":"mcm","clk":"11886748667","pt":1724118506946,"mc":[{"id":"1.232019056","rc":[{"batb":[[0,1.81,10],[1,1.8,54.6],[2,1.75,9.02]],"ltp":1.95,"tv":96.04,"id":72857117}]}]}
{"op":"mcm","clk":"11886748826","pt":1724118510385,"mc":[{"id":"1.232019056","rc":[{"batb":[[0,1.97,10],[1,1.96,8.05],[2,1.8,129.83]],"ltp":2.06,"tv":83.79,"id":72857114},{"batb":[[0,1.8,54.6],[1,1.75,9.02],[2,1.62,8.53]],"ltp":1.95,"tv":96.04,"id":72857117}]}]}
{"op":"mcm","clk":"11886748988","pt":1724118513572,"mc":[{"id":"1.232019056","rc":[{"batb":[[0,1.96,8.05],[1,1.8,129.83],[2,1.52,15]],"ltp":2.06,"tv":83.79,"id":72857114},{"batb":[[0,1.81,10],[1,1.8,54.6],[2,1.75,9.02]],"ltp":1.95,"tv":96.04,"id":72857117}]}]}
{"op":"mcm","clk":"11886749022","pt":1724118514188,"mc":[{"id":"1.232019056","rc":[{"batb":[[1,1.81,6.77],[2,1.8,129.83]],"ltp":2.06,"tv":83.79,"id":72857114},{"batl":[[0,2.24,5.45],[1,5,1.54],[2,9,1.54]],"ltp":1.95,"tv":96.04,"id":72857117}]}]}
{"op":"mcm","clk":"11886749140","pt":1724118516502,"mc":[{"id":"1.232019056","rc":[{"batb":[[0,1.97,10],[1,1.96,8.05],[2,1.81,6.77]],"ltp":2.06,"tv":83.79,"id":72857114}]}]}
{"op":"mcm","clk":"11886749181","pt":1724118517478,"mc":[{"id":"1.232019056","rc":[{"batb":[[2,1.8,129.83]],"ltp":2.06,"tv":83.79,"id":72857114},{"batb":[[0,1.8,54.6],[1,1.75,9.02],[2,1.62,8.53]],"batl":[[0,5,1.54],[1,9,1.54],[2,9,0]],"ltp":1.95,"tv":96.04,"id":72857117}]}]}
{"op":"mcm","clk":"11886749272","pt":1724118520087,"mc":[{"id":"1.232019056","rc":[{"batb":[[0,1.96,8.05],[1,1.8,129.83],[2,1.52,15]],"ltp":2.06,"tv":83.79,"id":72857114},{"batb":[[0,1.81,10],[1,1.8,54.6],[2,1.75,9.02]],"ltp":1.95,"tv":96.04,"id":72857117}]}]}
{"op":"mcm","clk":"11886749378","pt":1724118522293,"mc":[{"id":"1.232019056","rc":[{"batb":[[0,1.97,10],[1,1.96,8.05],[2,1.8,129.83]],"ltp":2.06,"tv":83.79,"id":72857114}]}]}
{"op":"mcm","clk":"11886749420","pt":1724118523266,"mc":[{"id":"1.232019056","rc":[{"batb":[[0,1.8,54.6],[1,1.75,9.02],[2,1.62,8.53]],"ltp":1.95,"tv":96.04,"id":72857117}]}]}
{"op":"mcm","clk":"11886749516","pt":1724118525579,"mc":[{"id":"1.232019056","rc":[{"batb":[[0,1.96,8.05],[1,1.8,129.83],[2,1.52,15]],"ltp":2.06,"tv":83.79,"id":72857114},{"batb":[[0,1.81,10],[1,1.8,54.6],[2,1.75,9.02]],"ltp":1.95,"tv":96.04,"id":72857117}]}]}
{"op":"mcm","clk":"11886749635","pt":1724118527680,"mc":[{"id":"1.232019056","rc":[{"batb":[[0,1.97,10],[1,1.96,8.05],[2,1.8,129.83]],"ltp":2.06,"tv":83.79,"id":72857114}]}]}
{"op":"mcm","clk":"11886749703","pt":1724118528913,"mc":[{"id":"1.232019056","rc":[{"batb":[[0,1.8,54.6],[1,1.75,9.02],[2,1.62,8.53]],"ltp":1.95,"tv":96.04,"id":72857117}]}]}
{"op":"mcm","clk":"11886749833","pt":1724118531226,"mc":[{"id":"1.232019056","rc":[{"batb":[[0,1.96,8.05],[1,1.8,129.83],[2,1.52,15]],"ltp":2.06,"tv":83.79,"id":72857114},{"batb":[[0,1.81,10],[1,1.8,54.6],[2,1.75,9.02]],"ltp":1.95,"tv":96.04,"id":72857117}]}]}
{"op":"mcm","clk":"11886749941","pt":1724118533487,"mc":[{"id":"1.232019056","rc":[{"batb":[[0,1.97,10],[1,1.96,8.05],[2,1.8,129.83]],"ltp":2.06,"tv":83.79,"id":72857114}]}]}
{"op":"mcm","clk":"11886750004","pt":1724118534716,"mc":[{"id":"1.232019056","rc":[{"batb":[[0,1.8,54.6],[1,1.75,9.02],[2,1.62,8.53]],"ltp":1.95,"tv":96.04,"id":72857117}]}]}
{"op":"mcm","clk":"11886750085","pt":1724118536815,"mc":[{"id":"1.232019056","rc":[{"batb":[[0,1.96,8.05],[1,1.8,129.83],[2,1.52,15]],"ltp":2.06,"tv":83.79,"id":72857114}]}]}
{"op":"mcm","clk":"11886750093","pt":1724118536917,"mc":[{"id":"1.232019056","rc":[{"batb":[[0,1.81,10],[1,1.8,54.6],[2,1.75,9.02]],"ltp":1.95,"tv":96.04,"id":72857117}]}]}
{"op":"mcm","clk":"11886750195","pt":1724118539328,"mc":[{"id":"1.232019056","rc":[{"batb":[[0,1.97,10],[1,1.96,8.05],[2,1.8,129.83]],"ltp":2.06,"tv":83.79,"id":72857114}]}]}
{"op":"mcm","clk":"11886750236","pt":1724118540319,"mc":[{"id":"1.232019056","rc":[{"batb":[[0,1.8,54.6],[1,1.75,9.02],[2,1.62,8.53]],"ltp":1.95,"tv":96.04,"id":72857117}]}]}
{"op":"mcm","clk":"11886750325","pt":1724118542728,"mc":[{"id":"1.232019056","rc":[{"batb":[[0,1.96,8.05],[1,1.8,129.83],[2,1.52,15]],"ltp":2.06,"tv":83.79,"id":72857114},{"batb":[[0,1.81,10],[1,1.8,54.6],[2,1.75,9.02]],"ltp":1.95,"tv":96.04,"id":72857117}]}]}
{"op":"mcm","clk":"11886750412","pt":1724118544834,"mc":[{"id":"1.232019056","rc":[{"batb":[[0,1.97,10],[1,1.96,8.05],[2,1.8,129.83]],"ltp":2.06,"tv":83.79,"id":72857114}]}]}
{"op":"mcm","clk":"11886750453","pt":1724118546012,"mc":[{"id":"1.232019056","rc":[{"batb":[[0,1.8,54.6],[1,1.75,9.02],[2,1.62,8.53]],"ltp":1.95,"tv":96.04,"id":72857117}]}]}
{"op":"mcm","clk":"11886750572","pt":1724118548544,"mc":[{"id":"1.232019056","rc":[{"batb":[[0,1.96,8.05],[1,1.8,129.83],[2,1.52,15]],"ltp":2.06,"tv":83.79,"id":72857114},{"batb":[[0,1.81,10],[1,1.8,54.6],[2,1.75,9.02]],"ltp":1.95,"tv":96.04,"id":72857117}]}]}
{"op":"mcm","clk":"11886750677","pt":1724118550854,"mc":[{"id":"1.232019056","rc":[{"batb":[[0,1.97,10],[1,1.96,8.05],[2,1.8,129.83]],"ltp":2.06,"tv":83.79,"id":72857114}]}]}
{"op":"mcm","clk":"11886750720","pt":1724118551932,"mc":[{"id":"1.232019056","rc":[{"batb":[[0,1.8,54.6],[1,1.75,9.02],[2,1.62,8.53]],"ltp":1.95,"tv":96.04,"id":72857117}]}]}
{"op":"mcm","clk":"11886750832","pt":1724118554342,"mc":[{"id":"1.232019056","rc":[{"batb":[[0,1.96,8.05],[1,1.8,129.83],[2,1.52,15]],"ltp":2.06,"tv":83.79,"id":72857114},{"batb":[[0,1.81,10],[1,1.8,54.6],[2,1.75,9.02]],"ltp":1.95,"tv":96.04,"id":72857117}]}]}
{"op":"mcm","clk":"11886750984","pt":1724118557735,"mc":[{"id":"1.232019056","rc":[{"batb":[[0,1.97,10],[1,1.96,8.05],[2,1.8,129.83]],"ltp":2.06,"tv":83.79,"id":72857114},{"batb":[[0,1.8,54.6],[1,1.75,9.02],[2,1.62,8.53]],"ltp":1.95,"tv":96.04,"id":72857117}]}]}
{"op":"mcm","clk":"11886751076","pt":1724118560139,"mc":[{"id":"1.232019056","rc":[{"batb":[[0,1.96,8.05],[1,1.8,129.83],[2,1.52,15]],"ltp":2.06,"tv":83.79,"id":72857114},{"batb":[[0,1.81,10],[1,1.8,54.6],[2,1.75,9.02]],"ltp":1.95,"tv":96.04,"id":72857117}]}]}
{"op":"mcm","clk":"11886751190","pt":1724118562346,"mc":[{"id":"1.232019056","rc":[{"batb":[[0,1.97,10],[1,1.96,8.05],[2,1.8,129.83]],"ltp":2.06,"tv":83.79,"id":72857114}]}]}
{"op":"mcm","clk":"11886751254","pt":1724118563428,"mc":[{"id":"1.232019056","rc":[{"batb":[[0,1.8,54.6],[1,1.75,9.02],[2,1.62,8.53]],"ltp":1.95,"tv":96.04,"id":72857117}]}]}
{"op":"mcm","clk":"11886751353","pt":1724118565636,"mc":[{"id":"1.232019056","rc":[{"batb":[[0,1.96,8.05],[1,1.8,129.83],[2,1.52,15]],"ltp":2.06,"tv":83.79,"id":72857114},{"batb":[[0,1.81,10],[1,1.8,54.6],[2,1.75,9.02]],"ltp":1.95,"tv":96.04,"id":72857117}]}]}
{"op":"mcm","clk":"11886751444","pt":1724118568055,"mc":[{"id":"1.232019056","rc":[{"batb":[[0,1.97,10],[1,1.96,8.05],[2,1.8,129.83]],"ltp":2.06,"tv":83.79,"id":72857114}]}]}
{"op":"mcm","clk":"11886751469","pt":1724118569068,"mc":[{"id":"1.232019056","rc":[{"batb":[[0,1.8,54.6],[1,1.75,9.02],[2,1.62,8.53]],"ltp":1.95,"tv":96.04,"id":72857117}]}]}
{"op":"mcm","clk":"11886751555","pt":1724118571375,"mc":[{"id":"1.232019056","rc":[{"batb":[[0,1.96,8.05],[1,1.8,129.83],[2,1.52,15]],"ltp":2.06,"tv":83.79,"id":72857114},{"batb":[[0,1.81,10],[1,1.8,54.6],[2,1.75,9.02]],"ltp":1.95,"tv":96.04,"id":72857117}]}]}
{"op":"mcm","clk":"11886751666","pt":1724118573637,"mc":[{"id":"1.232019056","rc":[{"batb":[[0,1.97,10],[1,1.96,8.05],[2,1.8,129.83]],"ltp":2.06,"tv":83.79,"id":72857114}]}]}
{"op":"mcm","clk":"11886751720","pt":1724118574772,"mc":[{"id":"1.232019056","rc":[{"batb":[[0,1.8,54.6],[1,1.75,9.02],[2,1.62,8.53]],"ltp":1.95,"tv":96.04,"id":72857117}]}]}
{"op":"mcm","clk":"11886751870","pt":1724118577300,"mc":[{"id":"1.232019056","rc":[{"batb":[[0,1.96,8.05],[1,1.8,129.83],[2,1.52,15]],"ltp":2.06,"tv":83.79,"id":72857114},{"batb":[[0,1.81,10],[1,1.8,54.6],[2,1.75,9.02]],"ltp":1.95,"tv":96.04,"id":72857117}]}]}
{"op":"mcm","clk":"11886752003","pt":1724118579571,"mc":[{"id":"1.232019056","rc":[{"batb":[[0,1.97,10],[1,1.96,8.05],[2,1.8,129.83]],"ltp":2.06,"tv":83.79,"id":72857114}]}]}
{"op":"mcm","clk":"11886752057","pt":1724118580650,"mc":[{"id":"1.232019056","rc":[{"batb":[[0,1.8,54.6],[1,1.75,9.02],[2,1.62,8.53]],"ltp":1.95,"tv":96.04,"id":72857117}]}]}
{"op":"mcm","clk":"11886752178","pt":1724118583164,"mc":[{"id":"1.232019056","rc":[{"batb":[[0,1.96,8.05],[1,1.8,129.83],[2,1.52,15]],"ltp":2.06,"tv":83.79,"id":72857114},{"batb":[[0,1.81,10],[1,1.8,54.6],[2,1.75,9.02]],"ltp":1.95,"tv":96.04,"id":72857117}]}]}
{"op":"mcm","clk":"11886752288","pt":1724118585485,"mc":[{"id":"1.232019056","rc":[{"batb":[[0,1.97,10],[1,1.96,8.05],[2,1.8,129.83]],"ltp":2.06,"tv":83.79,"id":72857114}]}]}
{"op":"mcm","clk":"11886752326","pt":1724118586562,"mc":[{"id":"1.232019056","rc":[{"batb":[[0,1.8,54.6],[1,1.75,9.02],[2,1.62,8.53]],"ltp":1.95,"tv":96.04,"id":72857117}]}]}
{"op":"mcm","clk":"11886752416","pt":1724118589077,"mc":[{"id":"1.232019056","rc":[{"batb":[[0,1.96,8.05],[1,1.8,129.83],[2,1.52,15]],"ltp":2.06,"tv":83.79,"id":72857114},{"batb":[[0,1.81,10],[1,1.8,54.6],[2,1.75,9.02]],"ltp":1.95,"tv":96.04,"id":72857117}]}]}
{"op":"mcm","clk":"11886752488","pt":1724118591353,"mc":[{"id":"1.232019056","rc":[{"batb":[[0,1.97,10],[1,1.96,8.05],[2,1.8,129.83]],"ltp":2.06,"tv":83.79,"id":72857114}]}]}
{"op":"mcm","clk":"11886752536","pt":1724118592380,"mc":[{"id":"1.232019056","rc":[{"batb":[[0,1.8,54.6],[1,1.75,9.02],[2,1.62,8.53]],"ltp":1.95,"tv":96.04,"id":72857117}]}]}
{"op":"mcm","clk":"11886752644","pt":1724118594791,"mc":[{"id":"1.232019056","rc":[{"batb":[[0,1.96,8.05],[1,1.8,129.83],[2,1.52,15]],"ltp":2.06,"tv":83.79,"id":72857114},{"batb":[[0,1.81,10],[1,1.8,54.6],[2,1.75,9.02]],"ltp":1.95,"tv":96.04,"id":72857117}]}]}
{"op":"mcm","clk":"11886752749","pt":1724118597057,"mc":[{"id":"1.232019056","rc":[{"batb":[[0,1.97,10],[1,1.96,8.05],[2,1.8,129.83]],"ltp":2.06,"tv":83.79,"id":72857114}]}]}
{"op":"mcm","clk":"11886752787","pt":1724118598088,"mc":[{"id":"1.232019056","rc":[{"batb":[[0,1.8,54.6],[1,1.75,9.02],[2,1.62,8.53]],"ltp":1.95,"tv":96.04,"id":72857117}]}]}
{"op":"mcm","clk":"11886752879","pt":1724118600401,"mc":[{"id":"1.232019056","rc":[{"batb":[[0,1.96,8.05],[1,1.8,129.83],[2,1.52,15]],"ltp":2.06,"tv":83.79,"id":72857114},{"batb":[[0,1.81,10],[1,1.8,54.6],[2,1.75,9.02]],"ltp":1.95,"tv":96.04,"id":72857117}]}]}
{"op":"mcm","clk":"11886753027","pt":1724118602793,"mc":[{"id":"1.232019056","rc":[{"batb":[[0,1.97,10],[1,1.96,8.05],[2,1.8,129.83]],"ltp":2.06,"tv":83.79,"id":72857114}]}]}
{"op":"mcm","clk":"11886753152","pt":1724118603772,"mc":[{"id":"1.232019056","rc":[{"batb":[[0,1.8,54.6],[1,1.75,9.02],[2,1.62,8.53]],"ltp":1.95,"tv":96.04,"id":72857117}]}]}
{"op":"mcm","clk":"11886753389","pt":1724118606187,"mc":[{"id":"1.232019056","rc":[{"batb":[[0,1.96,8.05],[1,1.8,129.83],[2,1.52,15]],"ltp":2.06,"tv":83.79,"id":72857114},{"batb":[[0,1.81,10],[1,1.8,54.6],[2,1.75,9.02]],"ltp":1.95,"tv":96.04,"id":72857117}]}]}
{"op":"mcm","clk":"11886753493","pt":1724118608305,"mc":[{"id":"1.232019056","rc":[{"batb":[[0,1.97,10],[1,1.96,8.05],[2,1.8,129.83]],"ltp":2.06,"tv":83.79,"id":72857114}]}]}
{"op":"mcm","clk":"11886753555","pt":1724118609491,"mc":[{"id":"1.232019056","rc":[{"batb":[[0,1.8,54.6],[1,1.75,9.02],[2,1.62,8.53]],"ltp":1.95,"tv":96.04,"id":72857117}]}]}
{"op":"mcm","clk":"11886753658","pt":1724118611792,"mc":[{"id":"1.232019056","rc":[{"batb":[[0,1.96,8.05],[1,1.8,129.83],[2,1.52,15]],"ltp":2.06,"tv":83.79,"id":72857114}]}]}
{"op":"mcm","clk":"11886753666","pt":1724118611895,"mc":[{"id":"1.232019056","rc":[{"batb":[[0,1.81,10],[1,1.8,54.6],[2,1.75,9.02]],"ltp":1.95,"tv":96.04,"id":72857117}]}]}
{"op":"mcm","clk":"11886753815","pt":1724118615388,"mc":[{"id":"1.232019056","rc":[{"batb":[[0,1.97,10],[1,1.96,8.05],[2,1.8,129.83]],"ltp":2.06,"tv":83.79,"id":72857114},{"batb":[[0,1.8,54.6],[1,1.75,9.02],[2,1.62,8.53]],"ltp":1.95,"tv":96.04,"id":72857117}]}]}
{"op":"mcm","clk":"11886753906","pt":1724118617693,"mc":[{"id":"1.232019056","rc":[{"batb":[[0,1.81,10],[1,1.8,54.6],[2,1.75,9.02]],"ltp":1.95,"tv":96.04,"id":72857117}]}]}
{"op":"mcm","clk":"11886753940","pt":1724118618516,"mc":[{"id":"1.232019056","rc":[{"batb":[[0,1.96,8.05],[1,1.8,129.83],[2,1.52,15]],"ltp":2.06,"tv":83.79,"id":72857114}]}]}
{"op":"mcm","clk":"11886754080","pt":1724118621314,"mc":[{"id":"1.232019056","rc":[{"batb":[[0,1.97,10],[1,1.96,8.05],[2,1.8,129.83]],"ltp":2.06,"tv":83.79,"id":72857114},{"batb":[[0,1.8,54.6],[1,1.75,9.02],[2,1.62,8.53]],"ltp":1.95,"tv":96.04,"id":72857117}]}]}
{"op":"mcm","clk":"11886754200","pt":1724118623616,"mc":[{"id":"1.232019056","rc":[{"batb":[[0,1.81,10],[1,1.8,54.6],[2,1.75,9.02]],"ltp":1.95,"tv":96.04,"id":72857117}]}]}
{"op":"mcm","clk":"11886754243","pt":1724118624639,"mc":[{"id":"1.232019056","rc":[{"batb":[[0,1.96,8.05],[1,1.8,129.83],[2,1.52,15]],"ltp":2.06,"tv":83.79,"id":72857114}]}]}
{"op":"mcm","clk":"11886754355","pt":1724118627110,"mc":[{"id":"1.232019056","rc":[{"batb":[[0,1.97,10],[1,1.96,8.05],[2,1.8,129.83]],"ltp":2.06,"tv":83.79,"id":72857114},{"batb":[[0,1.8,54.6],[1,1.75,9.02],[2,1.62,8.53]],"ltp":1.95,"tv":96.04,"id":72857117}]}]}
{"op":"mcm","clk":"11886754466","pt":1724118629330,"mc":[{"id":"1.232019056","rc":[{"batb":[[0,1.81,10],[1,1.8,54.6],[2,1.75,9.02]],"ltp":1.95,"tv":96.04,"id":72857117}]}]}
{"op":"mcm","clk":"11886754512","pt":1724118630612,"mc":[{"id":"1.232019056","rc":[{"batb":[[0,1.96,8.05],[1,1.8,129.83],[2,1.52,15]],"ltp":2.06,"tv":83.79,"id":72857114}]}]}
{"op":"mcm","clk":"11886754588","pt":1724118632514,"mc":[{"id":"1.232019056","rc":[{"batb":[[0,1.8,54.6],[1,1.75,9.02],[2,1.62,8.53]],"ltp":1.95,"tv":96.04,"id":72857117}]}]}
{"op":"mcm","clk":"11886754637","pt":1724118633640,"mc":[{"id":"1.232019056","rc":[{"batb":[[0,1.97,10],[1,1.96,8.05],[2,1.8,129.83]],"ltp":2.06,"tv":83.79,"id":72857114}]}]}
{"op":"mcm","clk":"11886754713","pt":1724118635337,"mc":[{"id":"1.232019056","rc":[{"batb":[[0,1.81,10],[1,1.8,54.6],[2,1.75,9.02]],"ltp":1.95,"tv":96.04,"id":72857117}]}]}
{"op":"mcm","clk":"11886754787","pt":1724118636932,"mc":[{"id":"1.232019056","rc":[{"batb":[[0,1.96,8.05],[1,1.8,129.83],[2,1.52,15]],"ltp":2.06,"tv":83.79,"id":72857114}]}]}
{"op":"mcm","clk":"11886754863","pt":1724118638522,"mc":[{"id":"1.232019056","rc":[{"batb":[[0,1.8,54.6],[1,1.75,9.02],[2,1.62,8.53]],"ltp":1.95,"tv":96.04,"id":72857117}]}]}
{"op":"mcm","clk":"11886754936","pt":1724118640113,"mc":[{"id":"1.232019056","rc":[{"batb":[[0,1.97,10],[1,1.96,8.05],[2,1.8,129.83]],"ltp":2.06,"tv":83.79,"id":72857114}]}]}
{"op":"mcm","clk":"11886754986","pt":1724118641340,"mc":[{"id":"1.232019056","rc":[{"batb":[[0,1.81,10],[1,1.8,54.6],[2,1.75,9.02]],"ltp":1.95,"tv":96.04,"id":72857117}]}]}
{"op":"mcm","clk":"11886755077","pt":1724118643445,"mc":[{"id":"1.232019056","rc":[{"batb":[[0,1.96,8.05],[1,1.8,129.83],[2,1.52,15]],"ltp":2.06,"tv":83.79,"id":72857114}]}]}
{"op":"mcm","clk":"11886755139","pt":1724118645033,"mc":[{"id":"1.232019056","rc":[{"batb":[[0,1.8,54.6],[1,1.75,9.02],[2,1.62,8.53]],"ltp":1.95,"tv":96.04,"id":72857117}]}]}
{"op":"mcm","clk":"11886755180","pt":1724118646260,"mc":[{"id":"1.232019056","rc":[{"batb":[[0,1.97,10],[1,1.96,8.05],[2,1.8,129.83]],"ltp":2.06,"tv":83.79,"id":72857114}]}]}
{"op":"mcm","clk":"11886755220","pt":1724118647341,"mc":[{"id":"1.232019056","rc":[{"batb":[[0,1.81,10],[1,1.8,54.6],[2,1.75,9.02]],"ltp":1.95,"tv":96.04,"id":72857117}]}]}
{"op":"mcm","clk":"11886755309","pt":1724118649623,"mc":[{"id":"1.232019056","rc":[{"batb":[[0,1.96,8.05],[1,1.8,129.83],[2,1.52,15]],"ltp":2.06,"tv":83.79,"id":72857114}]}]}
{"op":"mcm","clk":"11886755347","pt":1724118650542,"mc":[{"id":"1.232019056","rc":[{"batb":[[0,1.8,54.6],[1,1.75,9.02],[2,1.62,8.53]],"ltp":1.95,"tv":96.04,"id":72857117}]}]}
{"op":"mcm","clk":"11886755433","pt":1724118652853,"mc":[{"id":"1.232019056","rc":[{"batb":[[0,1.97,10],[1,1.96,8.05],[2,1.8,129.83]],"ltp":2.06,"tv":83.79,"id":72857114},{"batb":[[0,1.81,10],[1,1.8,54.6],[2,1.75,9.02]],"ltp":1.95,"tv":96.04,"id":72857117}]}]}
{"op":"mcm","clk":"11886755604","pt":1724118656041,"mc":[{"id":"1.232019056","rc":[{"batb":[[0,1.96,8.05],[1,1.8,129.83],[2,1.52,15]],"ltp":2.06,"tv":83.79,"id":72857114},{"batb":[[0,1.8,54.6],[1,1.75,9.02],[2,1.62,8.53]],"ltp":1.95,"tv":96.04,"id":72857117}]}]}
{"op":"mcm","clk":"11886755713","pt":1724118658346,"mc":[{"id":"1.232019056","rc":[{"batb":[[0,1.97,10],[1,1.96,8.05],[2,1.8,129.83]],"ltp":2.06,"tv":83.79,"id":72857114},{"batb":[[0,1.81,10],[1,1.8,54.6],[2,1.75,9.02]],"ltp":1.95,"tv":96.04,"id":72857117}]}]}
{"op":"mcm","clk":"11886755863","pt":1724118661585,"mc":[{"id":"1.232019056","rc":[{"batb":[[0,1.96,8.05],[1,1.8,129.83],[2,1.52,15]],"ltp":2.06,"tv":83.79,"id":72857114},{"batb":[[0,1.8,54.6],[1,1.75,9.02],[2,1.62,8.53]],"ltp":1.95,"tv":96.04,"id":72857117}]}]}
{"op":"mcm","clk":"11886755973","pt":1724118663845,"mc":[{"id":"1.232019056","rc":[{"batb":[[0,1.97,10],[1,1.96,8.05],[2,1.8,129.83]],"ltp":2.06,"tv":83.79,"id":72857114},{"batb":[[0,1.81,10],[1,1.8,54.6],[2,1.75,9.02]],"ltp":1.95,"tv":96.04,"id":72857117}]}]}
{"op":"mcm","clk":"11886756118","pt":1724118667184,"mc":[{"id":"1.232019056","rc":[{"batb":[[0,1.96,8.05],[1,1.8,129.83],[2,1.52,15]],"ltp":2.06,"tv":83.79,"id":72857114},{"batb":[[0,1.8,54.6],[1,1.75,9.02],[2,1.62,8.53]],"ltp":1.95,"tv":96.04,"id":72857117}]}]}
{"op":"mcm","clk":"11886756231","pt":1724118669491,"mc":[{"id":"1.232019056","rc":[{"batb":[[0,1.97,10],[1,1.96,8.05],[2,1.8,129.83]],"ltp":2.06,"tv":83.79,"id":72857114},{"batb":[[0,1.81,10],[1,1.8,54.6],[2,1.75,9.02]],"ltp":1.95,"tv":96.04,"id":72857117}]}]}
{"op":"mcm","clk":"11886756391","pt":1724118672980,"mc":[{"id":"1.232019056","rc":[{"batb":[[0,1.96,8.05],[1,1.8,129.83],[2,1.52,15]],"ltp":2.06,"tv":83.79,"id":72857114},{"batb":[[0,1.8,54.6],[1,1.75,9.02],[2,1.62,8.53]],"ltp":1.95,"tv":96.04,"id":72857117}]}]}
{"op":"mcm","clk":"11886756502","pt":1724118675300,"mc":[{"id":"1.232019056","rc":[{"batb":[[0,1.97,10],[1,1.96,8.05],[2,1.8,129.83]],"ltp":2.06,"tv":83.79,"id":72857114},{"batb":[[0,1.81,10],[1,1.8,54.6],[2,1.75,9.02]],"ltp":1.95,"tv":96.04,"id":72857117}]}]}
{"op":"mcm","clk":"11886757015","pt":1724118678627,"mc":[{"id":"1.232019056","rc":[{"batb":[[0,1.96,8.05],[1,1.8,129.83],[2,1.52,15]],"ltp":2.06,"tv":83.79,"id":72857114},{"batb":[[0,1.8,54.6],[1,1.75,9.02],[2,1.62,8.53]],"ltp":1.95,"tv":96.04,"id":72857117}]}]}
{"op":"mcm","clk":"11886757436","pt":1724118681027,"mc":[{"id":"1.232019056","rc":[{"batb":[[0,1.97,10],[1,1.96,8.05],[2,1.8,129.83]],"ltp":2.06,"tv":83.79,"id":72857114},{"batb":[[0,1.81,10],[1,1.8,54.6],[2,1.75,9.02]],"ltp":1.95,"tv":96.04,"id":72857117}]}]}
{"op":"mcm","clk":"11886757973","pt":1724118684320,"mc":[{"id":"1.232019056","rc":[{"batb":[[0,1.96,8.05],[1,1.8,129.83],[2,1.52,15]],"ltp":2.06,"tv":83.79,"id":72857114},{"batb":[[0,1.8,54.6],[1,1.75,9.02],[2,1.62,8.53]],"ltp":1.95,"tv":96.04,"id":72857117}]}]}
{"op":"mcm","clk":"11886758117","pt":1724118686589,"mc":[{"id":"1.232019056","rc":[{"batb":[[0,1.97,10],[1,1.96,8.05],[2,1.8,129.83]],"ltp":2.06,"tv":83.79,"id":72857114},{"batb":[[0,1.81,10],[1,1.8,54.6],[2,1.75,9.02]],"ltp":1.95,"tv":96.04,"id":72857117}]}]}
{"op":"mcm","clk":"11886758358","pt":1724118689931,"mc":[{"id":"1.232019056","rc":[{"batb":[[0,1.96,8.05],[1,1.8,129.83],[2,1.52,15]],"ltp":2.06,"tv":83.79,"id":72857114},{"batb":[[0,1.8,54.6],[1,1.75,9.02],[2,1.62,8.53]],"ltp":1.95,"tv":96.04,"id":72857117}]}]}
{"op":"mcm","clk":"11886758512","pt":1724118692294,"mc":[{"id":"1.232019056","rc":[{"batb":[[0,1.97,10],[1,1.96,8.05],[2,1.8,129.83]],"ltp":2.06,"tv":83.79,"id":72857114},{"batb":[[0,1.81,10],[1,1.8,54.6],[2,1.75,9.02]],"ltp":1.95,"tv":96.04,"id":72857117}]}]}
{"op":"mcm","clk":"11886758690","pt":1724118695621,"mc":[{"id":"1.232019056","rc":[{"batb":[[0,1.96,8.05],[1,1.8,129.83],[2,1.52,15]],"ltp":2.06,"tv":83.79,"id":72857114},{"batb":[[0,1.8,54.6],[1,1.75,9.02],[2,1.62,8.53]],"ltp":1.95,"tv":96.04,"id":72857117}]}]}
{"op":"mcm","clk":"11886758813","pt":1724118698028,"mc":[{"id":"1.232019056","rc":[{"batb":[[0,1.97,10],[1,1.96,8.05],[2,1.8,129.83]],"ltp":2.06,"tv":83.79,"id":72857114},{"batb":[[0,1.81,10],[1,1.8,54.6],[2,1.75,9.02]],"ltp":1.95,"tv":96.04,"id":72857117}]}]}
{"op":"mcm","clk":"11886758948","pt":1724118701521,"mc":[{"id":"1.232019056","rc":[{"batb":[[0,1.96,8.05],[1,1.8,129.83],[2,1.52,15]],"ltp":2.06,"tv":83.79,"id":72857114},{"batb":[[0,1.8,54.6],[1,1.75,9.02],[2,1.62,8.53]],"ltp":1.95,"tv":96.04,"id":72857117}]}]}
{"op":"mcm","clk":"11886759034","pt":1724118703456,"mc":[{"id":"1.232019056","rc":[{"batb":[[1,1.81,6.77],[2,1.8,129.83]],"ltp":2.06,"tv":83.79,"id":72857114},{"batl":[[0,2.24,5.45],[1,5,1.54],[2,9,1.54]],"ltp":1.95,"tv":96.04,"id":72857117}]}]}
{"op":"mcm","clk":"11886759103","pt":1724118704840,"mc":[{"id":"1.232019056","rc":[{"batb":[[0,1.97,10],[1,1.96,8.05],[2,1.81,6.77]],"ltp":2.06,"tv":83.79,"id":72857114},{"batb":[[0,1.81,10],[1,1.8,54.6],[2,1.75,9.02]],"ltp":1.95,"tv":96.04,"id":72857117}]}]}
{"op":"mcm","clk":"11886759221","pt":1724118708125,"mc":[{"id":"1.232019056","rc":[{"batb":[[0,1.96,8.05],[1,1.81,6.77],[2,1.8,129.83]],"ltp":2.06,"tv":83.79,"id":72857114},{"batb":[[0,1.8,54.6],[1,1.75,9.02],[2,1.62,8.53]],"ltp":1.95,"tv":96.04,"id":72857117}]}]}
{"op":"mcm","clk":"11886759346","pt":1724118710634,"mc":[{"id":"1.232019056","rc":[{"batb":[[0,1.97,10],[1,1.96,8.05],[2,1.81,6.77]],"ltp":2.06,"tv":83.79,"id":72857114},{"batb":[[0,1.81,10],[1,1.8,54.6],[2,1.75,9.02]],"ltp":1.95,"tv":96.04,"id":72857117}]}]}
{"op":"mcm","clk":"11886759503","pt":1724118714168,"mc":[{"id":"1.232019056","rc":[{"batb":[[0,1.96,8.05],[1,1.81,6.77],[2,1.8,129.83]],"ltp":2.06,"tv":83.79,"id":72857114},{"batb":[[0,1.8,54.6],[1,1.75,9.02],[2,1.62,8.53]],"ltp":1.95,"tv":96.04,"id":72857117}]}]}
{"op":"mcm","clk":"11886759585","pt":1724118716474,"mc":[{"id":"1.232019056","rc":[{"batb":[[0,1.97,10],[1,1.96,8.05],[2,1.81,6.77]],"ltp":2.06,"tv":83.79,"id":72857114},{"batb":[[0,1.81,10],[1,1.8,54.6],[2,1.75,9.02]],"ltp":1.95,"tv":96.04,"id":72857117}]}]}
{"op":"mcm","clk":"11886759701","pt":1724118719757,"mc":[{"id":"1.232019056","rc":[{"batb":[[0,1.96,8.05],[1,1.81,6.77],[2,1.8,129.83]],"ltp":2.06,"tv":83.79,"id":72857114},{"batb":[[0,1.8,54.6],[1,1.75,9.02],[2,1.62,8.53]],"ltp":1.95,"tv":96.04,"id":72857117}]}]}
{"op":"mcm","clk":"11886759795","pt":1724118722062,"mc":[{"id":"1.232019056","rc":[{"batb":[[0,1.97,10],[1,1.96,8.05],[2,1.81,6.77]],"ltp":2.06,"tv":83.79,"id":72857114},{"batb":[[0,1.81,10],[1,1.8,54.6],[2,1.75,9.02]],"ltp":1.95,"tv":96.04,"id":72857117}]}]}
{"op":"mcm","clk":"11886759947","pt":1724118725292,"mc":[{"id":"1.232019056","rc":[{"batb":[[0,1.96,8.05],[1,1.81,6.77],[2,1.8,129.83]],"ltp":2.06,"tv":83.79,"id":72857114},{"batb":[[0,1.8,54.6],[1,1.75,9.02],[2,1.62,8.53]],"ltp":1.95,"tv":96.04,"id":72857117}]}]}
{"op":"mcm","clk":"11886760071","pt":1724118727655,"mc":[{"id":"1.232019056","rc":[{"batb":[[0,1.97,10],[1,1.96,8.05],[2,1.81,6.77]],"ltp":2.06,"tv":83.79,"id":72857114},{"batb":[[0,1.81,10],[1,1.8,54.6],[2,1.75,9.02]],"ltp":1.95,"tv":96.04,"id":72857117}]}]}
{"op":"mcm","clk":"11886760223","pt":1724118731086,"mc":[{"id":"1.232019056","rc":[{"batb":[[0,1.96,8.05],[1,1.81,6.77],[2,1.8,129.83]],"ltp":2.06,"tv":83.79,"id":72857114},{"batb":[[0,1.8,54.6],[1,1.75,9.02],[2,1.62,8.53]],"ltp":1.95,"tv":96.04,"id":72857117}]}]}
{"op":"mcm","clk":"11886760318","pt":1724118733387,"mc":[{"id":"1.232019056","rc":[{"batb":[[0,1.97,10],[1,1.96,8.05],[2,1.81,6.77]],"ltp":2.06,"tv":83.79,"id":72857114},{"batb":[[0,1.81,10],[1,1.8,54.6],[2,1.75,9.02]],"ltp":1.95,"tv":96.04,"id":72857117}]}]}
{"op":"mcm","clk":"11886760344","pt":1724118734004,"mc":[{"id":"1.232019056","rc":[{"batb":[[2,1.8,129.83]],"ltp":2.06,"tv":83.79,"id":72857114},{"batl":[[0,5,1.54],[1,9,1.54],[2,9,0]],"ltp":1.95,"tv":96.04,"id":72857117}]}]}
{"op":"mcm","clk":"11886760479","pt":1724118736663,"mc":[{"id":"1.232019056","rc":[{"batb":[[0,1.96,8.05],[1,1.8,129.83],[2,1.52,15]],"ltp":2.06,"tv":83.79,"id":72857114},{"batb":[[0,1.8,54.6],[1,1.75,9.02],[2,1.62,8.53]],"ltp":1.95,"tv":96.04,"id":72857117}]}]}
{"op":"mcm","clk":"11886760603","pt":1724118738976,"mc":[{"id":"1.232019056","rc":[{"batb":[[0,1.97,10],[1,1.96,8.05],[2,1.8,129.83]],"ltp":2.06,"tv":83.79,"id":72857114},{"batb":[[0,1.81,10],[1,1.8,54.6],[2,1.75,9.02]],"ltp":1.95,"tv":96.04,"id":72857117}]}]}
{"op":"mcm","clk":"11886760778","pt":1724118742509,"mc":[{"id":"1.232019056","rc":[{"batb":[[0,1.96,8.05],[1,1.8,129.83],[2,1.52,15]],"ltp":2.06,"tv":83.79,"id":72857114},{"batb":[[0,1.8,54.6],[1,1.75,9.02],[2,1.62,8.53]],"ltp":1.95,"tv":96.04,"id":72857117}]}]}
{"op":"mcm","clk":"11886760893","pt":1724118744870,"mc":[{"id":"1.232019056","rc":[{"batb":[[0,1.97,10],[1,1.96,8.05],[2,1.8,129.83]],"ltp":2.06,"tv":83.79,"id":72857114},{"batb":[[0,1.81,10],[1,1.8,54.6],[2,1.75,9.02]],"ltp":1.95,"tv":96.04,"id":72857117}]}]}
{"op":"mcm","clk":"11886761029","pt":1724118748104,"mc":[{"id":"1.232019056","rc":[{"batb":[[0,1.96,8.05],[1,1.8,129.83],[2,1.52,15]],"ltp":2.06,"tv":83.79,"id":72857114},{"batb":[[0,1.8,54.6],[1,1.75,9.02],[2,1.62,8.53]],"ltp":1.95,"tv":96.04,"id":72857117}]}]}
{"op":"mcm","clk":"11886761124","pt":1724118750413,"mc":[{"id":"1.232019056","rc":[{"batb":[[0,1.97,10],[1,1.96,8.05],[2,1.8,129.83]],"ltp":2.06,"tv":83.79,"id":72857114},{"batb":[[0,1.81,10],[1,1.8,54.6],[2,1.75,9.02]],"ltp":1.95,"tv":96.04,"id":72857117}]}]}
{"op":"mcm","clk":"11886761276","pt":1724118753609,"mc":[{"id":"1.232019056","rc":[{"batb":[[0,1.96,8.05],[1,1.8,129.83],[2,1.52,15]],"ltp":2.06,"tv":83.79,"id":72857114},{"batb":[[0,1.8,54.6],[1,1.75,9.02],[2,1.62,8.53]],"ltp":1.95,"tv":96.04,"id":72857117}]}]}
{"op":"mcm","clk":"11886761384","pt":1724118756019,"mc":[{"id":"1.232019056","rc":[{"batb":[[0,1.97,10],[1,1.96,8.05],[2,1.8,129.83]],"ltp":2.06,"tv":83.79,"id":72857114},{"batb":[[0,1.81,10],[1,1.8,54.6],[2,1.75,9.02]],"ltp":1.95,"tv":96.04,"id":72857117}]}]}
{"op":"mcm","clk":"11886761533","pt":1724118759298,"mc":[{"id":"1.232019056","rc":[{"batb":[[0,1.96,8.05],[1,1.8,129.83],[2,1.52,15]],"ltp":2.06,"tv":83.79,"id":72857114},{"batb":[[0,1.8,54.6],[1,1.75,9.02],[2,1.62,8.53]],"ltp":1.95,"tv":96.04,"id":72857117}]}]}
{"op":"mcm","clk":"11886761635","pt":1724118761511,"mc":[{"id":"1.232019056","rc":[{"batb":[[0,1.97,10],[1,1.96,8.05],[2,1.8,129.83]],"ltp":2.06,"tv":83.79,"id":72857114},{"batb":[[0,1.81,10],[1,1.8,54.6],[2,1.75,9.02]],"ltp":1.95,"tv":96.04,"id":72857117}]}]}
{"op":"mcm","clk":"11886761796","pt":1724118764745,"mc":[{"id":"1.232019056","rc":[{"batb":[[0,1.96,8.05],[1,1.8,129.83],[2,1.52,15]],"ltp":2.06,"tv":83.79,"id":72857114},{"batb":[[0,1.8,54.6],[1,1.75,9.02],[2,1.62,8.53]],"ltp":1.95,"tv":96.04,"id":72857117}]}]}
{"op":"mcm","clk":"11886761951","pt":1724118767627,"mc":[{"id":"1.232019056","rc":[{"batb":[[0,1.97,10],[1,1.96,8.05],[2,1.8,129.83]],"ltp":2.06,"tv":83.79,"id":72857114},{"batb":[[0,1.81,10],[1,1.8,54.6],[2,1.75,9.02]],"ltp":1.95,"tv":96.04,"id":72857117}]}]}
{"op":"mcm","clk":"11886762119","pt":1724118770943,"mc":[{"id":"1.232019056","rc":[{"batb":[[0,1.96,8.05],[1,1.8,129.83],[2,1.52,15]],"ltp":2.06,"tv":83.79,"id":72857114},{"batb":[[0,1.8,54.6],[1,1.75,9.02],[2,1.62,8.53]],"ltp":1.95,"tv":96.04,"id":72857117}]}]}
{"op":"mcm","clk":"11886762260","pt":1724118773406,"mc":[{"id":"1.232019056","rc":[{"batb":[[0,1.97,10],[1,1.96,8.05],[2,1.8,129.83]],"ltp":2.06,"tv":83.79,"id":72857114},{"batb":[[0,1.81,10],[1,1.8,54.6],[2,1.75,9.02]],"ltp":1.95,"tv":96.04,"id":72857117}]}]}
{"op":"mcm","clk":"11886762450","pt":1724118776945,"mc":[{"id":"1.232019056","rc":[{"batb":[[0,1.96,8.05],[1,1.8,129.83],[2,1.52,15]],"ltp":2.06,"tv":83.79,"id":72857114},{"batb":[[0,1.8,54.6],[1,1.75,9.02],[2,1.62,8.53]],"ltp":1.95,"tv":96.04,"id":72857117}]}]}
{"op":"mcm","clk":"11886762569","pt":1724118779356,"mc":[{"id":"1.232019056","rc":[{"batb":[[0,1.97,10],[1,1.96,8.05],[2,1.8,129.83]],"ltp":2.06,"tv":83.79,"id":72857114},{"batb":[[0,1.81,10],[1,1.8,54.6],[2,1.75,9.02]],"ltp":1.95,"tv":96.04,"id":72857117}]}]}
{"op":"mcm","clk":"11886762747","pt":1724118782546,"mc":[{"id":"1.232019056","rc":[{"batb":[[0,1.96,8.05],[1,1.8,129.83],[2,1.52,15]],"ltp":2.06,"tv":83.79,"id":72857114},{"batb":[[0,1.8,54.6],[1,1.75,9.02],[2,1.62,8.53]],"ltp":1.95,"tv":96.04,"id":72857117}]}]}
{"op":"mcm","clk":"11886762901","pt":1724118785117,"mc":[{"id":"1.232019056","rc":[{"batb":[[0,1.97,10],[1,1.96,8.05],[2,1.8,129.83]],"ltp":2.06,"tv":83.79,"id":72857114},{"batb":[[0,1.81,10],[1,1.8,54.6],[2,1.75,9.02]],"ltp":1.95,"tv":96.04,"id":72857117}]}]}
{"op":"mcm","clk":"11886763063","pt":1724118788447,"mc":[{"id":"1.232019056","rc":[{"batb":[[0,1.96,8.05],[1,1.8,129.83],[2,1.52,15]],"ltp":2.06,"tv":83.79,"id":72857114},{"batb":[[0,1.8,54.6],[1,1.75,9.02],[2,1.62,8.53]],"ltp":1.95,"tv":96.04,"id":72857117}]}]}
{"op":"mcm","clk":"11886763168","pt":1724118790852,"mc":[{"id":"1.232019056","rc":[{"batb":[[0,1.97,10],[1,1.96,8.05],[2,1.8,129.83]],"ltp":2.06,"tv":83.79,"id":72857114},{"batb":[[0,1.81,10],[1,1.8,54.6],[2,1.75,9.02]],"ltp":1.95,"tv":96.04,"id":72857117}]}]}
{"op":"mcm","clk":"11886763301","pt":1724118794132,"mc":[{"id":"1.232019056","rc":[{"batb":[[0,1.96,8.05],[1,1.8,129.83],[2,1.52,15]],"ltp":2.06,"tv":83.79,"id":72857114},{"batb":[[0,1.8,54.6],[1,1.75,9.02],[2,1.62,8.53]],"ltp":1.95,"tv":96.04,"id":72857117}]}]}
{"op":"mcm","clk":"11886763466","pt":1724118797983,"mc":[{"id":"1.232019056","rc":[{"batb":[[0,1.97,10],[1,1.96,8.05],[2,1.8,129.83]],"ltp":2.06,"tv":83.79,"id":72857114},{"batb":[[0,1.81,10],[1,1.8,54.6],[2,1.75,9.02]],"ltp":1.95,"tv":96.04,"id":72857117}]}]}
{"op":"mcm","clk":"11886763621","pt":1724118801276,"mc":[{"id":"1.232019056","rc":[{"batb":[[0,1.96,8.05],[1,1.8,129.83],[2,1.52,15]],"ltp":2.06,"tv":83.79,"id":72857114},{"batb":[[0,1.8,54.6],[1,1.75,9.02],[2,1.62,8.53]],"ltp":1.95,"tv":96.04,"id":72857117}]}]}
{"op":"mcm","clk":"11886763745","pt":1724118803945,"mc":[{"id":"1.232019056","rc":[{"batb":[[0,1.97,10],[1,1.96,8.05],[2,1.8,129.83]],"ltp":2.06,"tv":83.79,"id":72857114},{"batb":[[0,1.81,10],[1,1.8,54.6],[2,1.75,9.02]],"ltp":1.95,"tv":96.04,"id":72857117}]}]}
{"op":"mcm","clk":"11886763897","pt":1724118807375,"mc":[{"id":"1.232019056","rc":[{"batb":[[0,1.96,8.05],[1,1.8,129.83],[2,1.52,15]],"ltp":2.06,"tv":83.79,"id":72857114},{"batb":[[0,1.8,54.6],[1,1.75,9.02],[2,1.62,8.53]],"ltp":1.95,"tv":96.04,"id":72857117}]}]}
{"op":"mcm","clk":"11886763997","pt":1724118809995,"mc":[{"id":"1.232019056","rc":[{"batb":[[0,1.97,10],[1,1.96,8.05],[2,1.8,129.83]],"ltp":2.06,"tv":83.79,"id":72857114},{"batb":[[0,1.81,10],[1,1.8,54.6],[2,1.75,9.02]],"ltp":1.95,"tv":96.04,"id":72857117}]}]}
{"op":"mcm","clk":"11886764158","pt":1724118813274,"mc":[{"id":"1.232019056","rc":[{"batb":[[0,1.96,8.05],[1,1.8,129.83],[2,1.52,15]],"ltp":2.06,"tv":83.79,"id":72857114},{"batb":[[0,1.8,54.6],[1,1.75,9.02],[2,1.62,8.53]],"ltp":1.95,"tv":96.04,"id":72857117}]}]}
{"op":"mcm","clk":"11886764280","pt":1724118816509,"mc":[{"id":"1.232019056","rc":[{"batb":[[0,1.97,10],[1,1.96,8.05],[2,1.8,129.83]],"ltp":2.06,"tv":83.79,"id":72857114},{"batb":[[0,1.81,10],[1,1.8,54.6],[2,1.75,9.02]],"ltp":1.95,"tv":96.04,"id":72857117}]}]}
{"op":"mcm","clk":"11886764407","pt":1724118819778,"mc":[{"id":"1.232019056","rc":[{"batb":[[0,1.96,8.05],[1,1.8,129.83],[2,1.52,15]],"ltp":2.06,"tv":83.79,"id":72857114},{"batb":[[0,1.8,54.6],[1,1.75,9.02],[2,1.62,8.53]],"ltp":1.95,"tv":96.04,"id":72857117}]}]}
{"op":"mcm","clk":"11886764499","pt":1724118822181,"mc":[{"id":"1.232019056","rc":[{"batb":[[0,1.97,10],[1,1.96,8.05],[2,1.8,129.83]],"ltp":2.06,"tv":83.79,"id":72857114},{"batb":[[0,1.81,10],[1,1.8,54.6],[2,1.75,9.02]],"ltp":1.95,"tv":96.04,"id":72857117}]}]}
{"op":"mcm","clk":"11886764597","pt":1724118825505,"mc":[{"id":"1.232019056","rc":[{"batb":[[0,1.96,8.05],[1,1.8,129.83],[2,1.52,15]],"ltp":2.06,"tv":83.79,"id":72857114},{"batb":[[0,1.8,54.6],[1,1.75,9.02],[2,1.62,8.53]],"ltp":1.95,"tv":96.04,"id":72857117}]}]}
{"op":"mcm","clk":"11886764692","pt":1724118827906,"mc":[{"id":"1.232019056","rc":[{"batb":[[0,1.97,10],[1,1.96,8.05],[2,1.8,129.83]],"ltp":2.06,"tv":83.79,"id":72857114},{"batb":[[0,1.81,10],[1,1.8,54.6],[2,1.75,9.02]],"ltp":1.95,"tv":96.04,"id":72857117}]}]}
{"op":"mcm","clk":"11886764811","pt":1724118831229,"mc":[{"id":"1.232019056","rc":[{"batb":[[0,1.96,8.05],[1,1.8,129.83],[2,1.52,15]],"ltp":2.06,"tv":83.79,"id":72857114},{"batb":[[0,1.8,54.6],[1,1.75,9.02],[2,1.62,8.53]],"ltp":1.95,"tv":96.04,"id":72857117}]}]}
{"op":"mcm","clk":"11886764894","pt":1724118833536,"mc":[{"id":"1.232019056","rc":[{"batb":[[0,1.97,10],[1,1.96,8.05],[2,1.8,129.83]],"ltp":2.06,"tv":83.79,"id":72857114},{"batb":[[0,1.81,10],[1,1.8,54.6],[2,1.75,9.02]],"ltp":1.95,"tv":96.04,"id":72857117}]}]}
{"op":"mcm","clk":"11886764997","pt":1724118836811,"mc":[{"id":"1.232019056","rc":[{"batb":[[0,1.96,8.05],[1,1.8,129.83],[2,1.52,15]],"ltp":2.06,"tv":83.79,"id":72857114},{"batb":[[0,1.8,54.6],[1,1.75,9.02],[2,1.62,8.53]],"ltp":1.95,"tv":96.04,"id":72857117}]}]}
{"op":"mcm","clk":"11886765122","pt":1724118839626,"mc":[{"id":"1.232019056","rc":[{"batb":[[0,1.97,10],[1,1.96,8.05],[2,1.8,129.83]],"ltp":2.06,"tv":83.79,"id":72857114},{"batb":[[0,1.81,10],[1,1.8,54.6],[2,1.75,9.02]],"ltp":1.95,"tv":96.04,"id":72857117}]}]}
{"op":"mcm","clk":"11886765273","pt":1724118842800,"mc":[{"id":"1.232019056","rc":[{"batb":[[0,1.96,8.05],[1,1.8,129.83],[2,1.52,15]],"ltp":2.06,"tv":83.79,"id":72857114},{"batb":[[0,1.8,54.6],[1,1.75,9.02],[2,1.62,8.53]],"ltp":1.95,"tv":96.04,"id":72857117}]}]}
{"op":"mcm","clk":"11886765386","pt":1724118845412,"mc":[{"id":"1.232019056","rc":[{"batb":[[0,1.97,10],[1,1.96,8.05],[2,1.8,129.83]],"ltp":2.06,"tv":83.79,"id":72857114},{"batb":[[0,1.81,10],[1,1.8,54.6],[2,1.75,9.02]],"ltp":1.95,"tv":96.04,"id":72857117}]}]}
{"op":"mcm","clk":"11886765579","pt":1724118849611,"mc":[{"id":"1.232019056","rc":[{"batb":[[0,1.96,8.05],[1,1.81,6.77]],"ltp":2.06,"tv":83.79,"id":72857114},{"batb":[[0,1.8,54.6],[1,1.75,9.02],[2,1.62,8.53]],"batl":[[0,2.24,5.45],[1,5,1.54],[2,9,1.54]],"ltp":1.95,"tv":96.04,"id":72857117}]}]}
{"op":"mcm","clk":"11886765678","pt":1724118851962,"mc":[{"id":"1.232019056","rc":[{"batb":[[0,1.97,10],[1,1.96,8.05],[2,1.81,6.77]],"ltp":2.06,"tv":83.79,"id":72857114},{"batb":[[0,1.81,10],[1,1.8,54.6],[2,1.75,9.02]],"ltp":1.95,"tv":96.04,"id":72857117}]}]}
{"op":"mcm","clk":"11886765717","pt":1724118852932,"mc":[{"id":"1.232019056","rc":[{"batb":[[2,1.8,129.83]],"ltp":2.06,"tv":83.79,"id":72857114},{"batl":[[0,5,1.54],[1,9,1.54],[2,9,0]],"ltp":1.95,"tv":96.04,"id":72857117}]}]}
{"op":"mcm","clk":"11886765828","pt":1724118855340,"mc":[{"id":"1.232019056","rc":[{"batb":[[0,1.96,8.05],[1,1.8,129.83],[2,1.52,15]],"ltp":2.06,"tv":83.79,"id":72857114},{"batb":[[0,1.8,54.6],[1,1.75,9.02],[2,1.62,8.53]],"ltp":1.95,"tv":96.04,"id":72857117}]}]}
{"op":"mcm","clk":"11886765930","pt":1724118857741,"mc":[{"id":"1.232019056","rc":[{"batb":[[0,1.97,10],[1,1.96,8.05],[2,1.8,129.83]],"ltp":2.06,"tv":83.79,"id":72857114},{"batb":[[0,1.81,10],[1,1.8,54.6],[2,1.75,9.02]],"ltp":1.95,"tv":96.04,"id":72857117}]}]}
{"op":"mcm","clk":"11886766063","pt":1724118861053,"mc":[{"id":"1.232019056","rc":[{"batb":[[0,1.96,8.05],[1,1.8,129.83],[2,1.52,15]],"ltp":2.06,"tv":83.79,"id":72857114},{"batb":[[0,1.8,54.6],[1,1.75,9.02],[2,1.62,8.53]],"ltp":1.95,"tv":96.04,"id":72857117}]}]}
{"op":"mcm","clk":"11886766182","pt":1724118863666,"mc":[{"id":"1.232019056","rc":[{"batb":[[0,1.97,10],[1,1.96,8.05],[2,1.8,129.83]],"ltp":2.06,"tv":83.79,"id":72857114},{"batb":[[0,1.81,10],[1,1.8,54.6],[2,1.75,9.02]],"ltp":1.95,"tv":96.04,"id":72857117}]}]}
{"op":"mcm","clk":"11886766310","pt":1724118867050,"mc":[{"id":"1.232019056","rc":[{"batb":[[0,1.96,8.05],[1,1.8,129.83],[2,1.52,15]],"ltp":2.06,"tv":83.79,"id":72857114},{"batb":[[0,1.8,54.6],[1,1.75,9.02],[2,1.62,8.53]],"ltp":1.95,"tv":96.04,"id":72857117}]}]}
{"op":"mcm","clk":"11886766389","pt":1724118869553,"mc":[{"id":"1.232019056","rc":[{"batb":[[0,1.97,10],[1,1.96,8.05],[2,1.8,129.83]],"ltp":2.06,"tv":83.79,"id":72857114},{"batb":[[0,1.81,10],[1,1.8,54.6],[2,1.75,9.02]],"ltp":1.95,"tv":96.04,"id":72857117}]}]}
{"op":"mcm","clk":"11886766538","pt":1724118873037,"mc":[{"id":"1.232019056","rc":[{"batb":[[0,1.96,8.05],[1,1.8,129.83],[2,1.52,15]],"ltp":2.06,"tv":83.79,"id":72857114},{"batb":[[0,1.8,54.6],[1,1.75,9.02],[2,1.62,8.53]],"ltp":1.95,"tv":96.04,"id":72857117}]}]}
{"op":"mcm","clk":"11886766619","pt":1724118875342,"mc":[{"id":"1.232019056","rc":[{"batb":[[0,1.97,10],[1,1.96,8.05],[2,1.8,129.83]],"ltp":2.06,"tv":83.79,"id":72857114},{"batb":[[0,1.81,10],[1,1.8,54.6],[2,1.75,9.02]],"ltp":1.95,"tv":96.04,"id":72857117}]}]}
{"op":"mcm","clk":"11886766788","pt":1724118878779,"mc":[{"id":"1.232019056","rc":[{"batb":[[0,1.96,8.05],[1,1.8,129.83],[2,1.52,15]],"ltp":2.06,"tv":83.79,"id":72857114},{"batb":[[0,1.8,54.6],[1,1.75,9.02],[2,1.62,8.53]],"ltp":1.95,"tv":96.04,"id":72857117}]}]}
{"op":"mcm","clk":"11886766889","pt":1724118881043,"mc":[{"id":"1.232019056","rc":[{"batb":[[0,1.97,10],[1,1.96,8.05],[2,1.8,129.83]],"ltp":2.06,"tv":83.79,"id":72857114},{"batb":[[0,1.81,10],[1,1.8,54.6],[2,1.75,9.02]],"ltp":1.95,"tv":96.04,"id":72857117}]}]}
{"op":"mcm","clk":"11886767031","pt":1724118884377,"mc":[{"id":"1.232019056","rc":[{"batb":[[0,1.96,8.05],[1,1.8,129.83],[2,1.52,15]],"ltp":2.06,"tv":83.79,"id":72857114},{"batb":[[0,1.8,54.6],[1,1.75,9.02],[2,1.62,8.53]],"ltp":1.95,"tv":96.04,"id":72857117}]}]}
{"op":"mcm","clk":"11886767120","pt":1724118886692,"mc":[{"id":"1.232019056","rc":[{"batb":[[0,1.97,10],[1,1.96,8.05],[2,1.8,129.83]],"ltp":2.06,"tv":83.79,"id":72857114},{"batb":[[0,1.81,10],[1,1.8,54.6],[2,1.75,9.02]],"ltp":1.95,"tv":96.04,"id":72857117}]}]}
{"op":"mcm","clk":"11886767429","pt":1724118889984,"mc":[{"id":"1.232019056","rc":[{"batb":[[0,1.96,8.05],[1,1.8,129.83],[2,1.52,15]],"ltp":2.06,"tv":83.79,"id":72857114},{"batb":[[0,1.8,54.6],[1,1.75,9.02],[2,1.62,8.53]],"ltp":1.95,"tv":96.04,"id":72857117}]}]}
{"op":"mcm","clk":"11886767587","pt":1724118892399,"mc":[{"id":"1.232019056","rc":[{"batb":[[0,1.97,10],[1,1.96,8.05],[2,1.8,129.83]],"ltp":2.06,"tv":83.79,"id":72857114},{"batb":[[0,1.81,10],[1,1.8,54.6],[2,1.75,9.02]],"ltp":1.95,"tv":96.04,"id":72857117}]}]}
{"op":"mcm","clk":"11886767732","pt":1724118895583,"mc":[{"id":"1.232019056","rc":[{"batb":[[0,1.96,8.05],[1,1.8,129.83],[2,1.52,15]],"ltp":2.06,"tv":83.79,"id":72857114},{"batb":[[0,1.8,54.6],[1,1.75,9.02],[2,1.62,8.53]],"ltp":1.95,"tv":96.04,"id":72857117}]}]}
{"op":"mcm","clk":"11886767833","pt":1724118897989,"mc":[{"id":"1.232019056","rc":[{"batb":[[0,1.97,10],[1,1.96,8.05],[2,1.8,129.83]],"ltp":2.06,"tv":83.79,"id":72857114},{"batb":[[0,1.81,10],[1,1.8,54.6],[2,1.75,9.02]],"ltp":1.95,"tv":96.04,"id":72857117}]}]}
{"op":"mcm","clk":"11886767986","pt":1724118901293,"mc":[{"id":"1.232019056","rc":[{"batb":[[0,1.96,8.05],[1,1.8,129.83],[2,1.52,15]],"ltp":2.06,"tv":83.79,"id":72857114},{"batb":[[0,1.8,54.6],[1,1.75,9.02],[2,1.62,8.53]],"ltp":1.95,"tv":96.04,"id":72857117}]}]}
{"op":"mcm","clk":"11886768091","pt":1724118903705,"mc":[{"id":"1.232019056","rc":[{"batb":[[0,1.97,10],[1,1.96,8.05],[2,1.8,129.83]],"ltp":2.06,"tv":83.79,"id":72857114},{"batb":[[0,1.81,10],[1,1.8,54.6],[2,1.75,9.02]],"ltp":1.95,"tv":96.04,"id":72857117}]}]}
{"op":"mcm","clk":"11886768238","pt":1724118906902,"mc":[{"id":"1.232019056","rc":[{"batb":[[0,1.96,8.05],[1,1.8,129.83],[2,1.52,15]],"ltp":2.06,"tv":83.79,"id":72857114},{"batb":[[0,1.8,54.6],[1,1.75,9.02],[2,1.62,8.53]],"ltp":1.95,"tv":96.04,"id":72857117}]}]}
{"op":"mcm","clk":"11886768350","pt":1724118909218,"mc":[{"id":"1.232019056","rc":[{"batb":[[0,1.97,10],[1,1.96,8.05],[2,1.8,129.83]],"ltp":2.06,"tv":83.79,"id":72857114},{"batb":[[0,1.81,10],[1,1.8,54.6],[2,1.75,9.02]],"ltp":1.95,"tv":96.04,"id":72857117}]}]}
{"op":"mcm","clk":"11886768529","pt":1724118912613,"mc":[{"id":"1.232019056","rc":[{"batb":[[0,1.96,8.05],[1,1.8,129.83],[2,1.52,15]],"ltp":2.06,"tv":83.79,"id":72857114},{"batb":[[0,1.8,54.6],[1,1.75,9.02],[2,1.62,8.53]],"ltp":1.95,"tv":96.04,"id":72857117}]}]}
{"op":"mcm","clk":"11886768621","pt":1724118914920,"mc":[{"id":"1.232019056","rc":[{"batb":[[0,1.97,10],[1,1.96,8.05],[2,1.8,129.83]],"ltp":2.06,"tv":83.79,"id":72857114},{"batb":[[0,1.81,10],[1,1.8,54.6],[2,1.75,9.02]],"ltp":1.95,"tv":96.04,"id":72857117}]}]}
{"op":"mcm","clk":"11886768756","pt":1724118918419,"mc":[{"id":"1.232019056","rc":[{"batb":[[0,1.96,8.05],[1,1.8,129.83],[2,1.52,15]],"ltp":2.06,"tv":83.79,"id":72857114},{"batb":[[0,1.8,54.6],[1,1.75,9.02],[2,1.62,8.53]],"ltp":1.95,"tv":96.04,"id":72857117}]}]}
{"op":"mcm","clk":"11886768892","pt":1724118921903,"mc":[{"id":"1.232019056","rc":[{"batb":[[0,1.97,10],[1,1.96,8.05],[2,1.8,129.83]],"ltp":2.06,"tv":83.79,"id":72857114},{"batb":[[0,1.81,10],[1,1.8,54.6],[2,1.75,9.02]],"ltp":1.95,"tv":96.04,"id":72857117}]}]}
{"op":"mcm","clk":"11886769036","pt":1724118925442,"mc":[{"id":"1.232019056","rc":[{"batb":[[0,1.96,8.05],[1,1.8,129.83],[2,1.52,15]],"ltp":2.06,"tv":83.79,"id":72857114},{"batb":[[0,1.8,54.6],[1,1.75,9.02],[2,1.62,8.53]],"ltp":1.95,"tv":96.04,"id":72857117}]}]}
{"op":"mcm","clk":"11886769144","pt":1724118927653,"mc":[{"id":"1.232019056","rc":[{"batb":[[0,1.97,10],[1,1.96,8.05],[2,1.8,129.83]],"ltp":2.06,"tv":83.79,"id":72857114},{"batb":[[0,1.81,10],[1,1.8,54.6],[2,1.75,9.02]],"ltp":1.95,"tv":96.04,"id":72857117}]}]}
{"op":"mcm","clk":"11886769321","pt":1724118931041,"mc":[{"id":"1.232019056","rc":[{"batb":[[0,1.96,8.05],[1,1.8,129.83],[2,1.52,15]],"ltp":2.06,"tv":83.79,"id":72857114},{"batb":[[0,1.8,54.6],[1,1.75,9.02],[2,1.62,8.53]],"ltp":1.95,"tv":96.04,"id":72857117}]}]}
{"op":"mcm","clk":"11886769445","pt":1724118933654,"mc":[{"id":"1.232019056","rc":[{"batb":[[0,1.97,10],[1,1.96,8.05],[2,1.8,129.83]],"ltp":2.06,"tv":83.79,"id":72857114},{"batb":[[0,1.81,10],[1,1.8,54.6],[2,1.75,9.02]],"ltp":1.95,"tv":96.04,"id":72857117}]}]}
{"op":"mcm","clk":"11886769551","pt":1724118937030,"mc":[{"id":"1.232019056","rc":[{"batb":[[0,1.96,8.05],[1,1.8,129.83],[2,1.52,15]],"ltp":2.06,"tv":83.79,"id":72857114},{"batb":[[0,1.8,54.6],[1,1.75,9.02],[2,1.62,8.53]],"ltp":1.95,"tv":96.04,"id":72857117}]}]}
{"op":"mcm","clk":"11886769630","pt":1724118939540,"mc":[{"id":"1.232019056","rc":[{"batb":[[0,1.97,10],[1,1.96,8.05],[2,1.8,129.83]],"ltp":2.06,"tv":83.79,"id":72857114},{"batb":[[0,1.81,10],[1,1.8,54.6],[2,1.75,9.02]],"ltp":1.95,"tv":96.04,"id":72857117}]}]}
{"op":"mcm","clk":"11886769724","pt":1724118942880,"mc":[{"id":"1.232019056","rc":[{"batb":[[0,1.96,8.05],[1,1.8,129.83],[2,1.52,15]],"ltp":2.06,"tv":83.79,"id":72857114},{"batb":[[0,1.8,54.6],[1,1.75,9.02],[2,1.62,8.53]],"ltp":1.95,"tv":96.04,"id":72857117}]}]}
{"op":"mcm","clk":"11886769814","pt":1724118945081,"mc":[{"id":"1.232019056","rc":[{"batb":[[0,1.97,10],[1,1.96,8.05],[2,1.8,129.83]],"ltp":2.06,"tv":83.79,"id":72857114},{"batb":[[0,1.81,10],[1,1.8,54.6],[2,1.75,9.02]],"ltp":1.95,"tv":96.04,"id":72857117}]}]}
{"op":"mcm","clk":"11886769940","pt":1724118948359,"mc":[{"id":"1.232019056","rc":[{"batb":[[0,1.96,8.05],[1,1.8,129.83],[2,1.52,15]],"ltp":2.06,"tv":83.79,"id":72857114},{"batb":[[0,1.8,54.6],[1,1.75,9.02],[2,1.62,8.53]],"ltp":1.95,"tv":96.04,"id":72857117}]}]}
{"op":"mcm","clk":"11886770061","pt":1724118951086,"mc":[{"id":"1.232019056","rc":[{"batb":[[0,1.97,10],[1,1.96,8.05],[2,1.8,129.83]],"ltp":2.06,"tv":83.79,"id":72857114},{"batb":[[0,1.81,10],[1,1.8,54.6],[2,1.75,9.02]],"ltp":1.95,"tv":96.04,"id":72857117}]}]}
{"op":"mcm","clk":"11886770177","pt":1724118954360,"mc":[{"id":"1.232019056","rc":[{"batb":[[0,1.96,8.05],[1,1.8,129.83],[2,1.52,15]],"ltp":2.06,"tv":83.79,"id":72857114},{"batb":[[0,1.8,54.6],[1,1.75,9.02],[2,1.62,8.53]],"ltp":1.95,"tv":96.04,"id":72857117}]}]}
{"op":"mcm","clk":"11886770269","pt":1724118956869,"mc":[{"id":"1.232019056","rc":[{"batb":[[0,1.97,10],[1,1.96,8.05],[2,1.8,129.83]],"ltp":2.06,"tv":83.79,"id":72857114},{"batb":[[0,1.81,10],[1,1.8,54.6],[2,1.75,9.02]],"ltp":1.95,"tv":96.04,"id":72857117}]}]}
{"op":"mcm","clk":"11886770368","pt":1724118960201,"mc":[{"id":"1.232019056","rc":[{"batb":[[0,1.96,8.05],[1,1.8,129.83],[2,1.52,15]],"ltp":2.06,"tv":83.79,"id":72857114},{"batb":[[0,1.8,54.6],[1,1.75,9.02],[2,1.62,8.53]],"ltp":1.95,"tv":96.04,"id":72857117}]}]}
{"op":"mcm","clk":"11886770464","pt":1724118962396,"mc":[{"id":"1.232019056","rc":[{"batb":[[0,1.97,10],[1,1.96,8.05],[2,1.8,129.83]],"ltp":2.06,"tv":83.79,"id":72857114},{"batb":[[0,1.81,10],[1,1.8,54.6],[2,1.75,9.02]],"ltp":1.95,"tv":96.04,"id":72857117}]}]}
{"op":"mcm","clk":"11886770601","pt":1724118965775,"mc":[{"id":"1.232019056","rc":[{"batb":[[0,1.96,8.05],[1,1.8,129.83],[2,1.52,15]],"ltp":2.06,"tv":83.79,"id":72857114},{"batb":[[0,1.8,54.6],[1,1.75,9.02],[2,1.62,8.53]],"ltp":1.95,"tv":96.04,"id":72857117}]}]}
{"op":"mcm","clk":"11886770792","pt":1724118970496,"mc":[{"id":"1.232019056","rc":[{"batb":[[0,1.97,10],[1,1.96,8.05],[2,1.8,129.83]],"ltp":2.06,"tv":83.79,"id":72857114},{"batb":[[0,1.81,10],[1,1.8,54.6],[2,1.75,9.02]],"ltp":1.95,"tv":96.04,"id":72857117}]}]}
{"op":"mcm","clk":"11886770914","pt":1724118973773,"mc":[{"id":"1.232019056","rc":[{"batb":[[0,1.96,8.05],[1,1.8,129.83],[2,1.52,15]],"ltp":2.06,"tv":83.79,"id":72857114},{"batb":[[0,1.8,54.6],[1,1.75,9.02],[2,1.62,8.53]],"ltp":1.95,"tv":96.04,"id":72857117}]}]}
{"op":"mcm","clk":"11886771019","pt":1724118976280,"mc":[{"id":"1.232019056","rc":[{"batb":[[0,1.97,10],[1,1.96,8.05],[2,1.8,129.83]],"ltp":2.06,"tv":83.79,"id":72857114},{"batb":[[0,1.81,10],[1,1.8,54.6],[2,1.75,9.02]],"ltp":1.95,"tv":96.04,"id":72857117}]}]}
{"op":"mcm","clk":"11886771170","pt":1724118979778,"mc":[{"id":"1.232019056","rc":[{"batb":[[0,1.96,8.05],[1,1.8,129.83],[2,1.52,15]],"ltp":2.06,"tv":83.79,"id":72857114},{"batb":[[0,1.8,54.6],[1,1.75,9.02],[2,1.62,8.53]],"ltp":1.95,"tv":96.04,"id":72857117}]}]}
{"op":"mcm","clk":"11886771263","pt":1724118982177,"mc":[{"id":"1.232019056","rc":[{"batb":[[0,1.97,10],[1,1.96,8.05],[2,1.8,129.83]],"ltp":2.06,"tv":83.79,"id":72857114},{"batb":[[0,1.81,10],[1,1.8,54.6],[2,1.75,9.02]],"ltp":1.95,"tv":96.04,"id":72857117}]}]}
{"op":"mcm","clk":"11886771382","pt":1724118985417,"mc":[{"id":"1.232019056","rc":[{"batb":[[0,1.96,8.05],[1,1.8,129.83],[2,1.52,15]],"ltp":2.06,"tv":83.79,"id":72857114},{"batb":[[0,1.8,54.6],[1,1.75,9.02],[2,1.62,8.53]],"ltp":1.95,"tv":96.04,"id":72857117}]}]}
{"op":"mcm","clk":"11886771470","pt":1724118987673,"mc":[{"id":"1.232019056","rc":[{"batb":[[0,1.97,10],[1,1.96,8.05],[2,1.8,129.83]],"ltp":2.06,"tv":83.79,"id":72857114},{"batb":[[0,1.81,10],[1,1.8,54.6],[2,1.75,9.02]],"ltp":1.95,"tv":96.04,"id":72857117}]}]}
{"op":"mcm","clk":"11886771608","pt":1724118991483,"mc":[{"id":"1.232019056","rc":[{"batb":[[0,1.96,8.05],[1,1.81,6.77]],"ltp":2.06,"tv":83.79,"id":72857114},{"batb":[[0,1.8,54.6],[1,1.75,9.02],[2,1.62,8.53]],"batl":[[0,2.24,5.45],[1,5,1.54],[2,9,1.54]],"ltp":1.95,"tv":96.04,"id":72857117}]}]}
{"op":"mcm","clk":"11886771708","pt":1724118993801,"mc":[{"id":"1.232019056","rc":[{"batb":[[0,1.97,10],[1,1.96,8.05],[2,1.81,6.77]],"ltp":2.06,"tv":83.79,"id":72857114},{"batb":[[0,1.81,10],[1,1.8,54.6],[2,1.75,9.02]],"ltp":1.95,"tv":96.04,"id":72857117}]}]}
{"op":"mcm","clk":"11886771759","pt":1724118994725,"mc":[{"id":"1.232019056","rc":[{"batb":[[2,1.8,129.83]],"ltp":2.06,"tv":83.79,"id":72857114},{"batl":[[0,5,1.54],[1,9,1.54],[2,9,0]],"ltp":1.95,"tv":96.04,"id":72857117}]}]}
{"op":"mcm","clk":"11886771851","pt":1724118997000,"mc":[{"id":"1.232019056","rc":[{"batb":[[0,1.96,8.05],[1,1.8,129.83],[2,1.52,15]],"ltp":2.06,"tv":83.79,"id":72857114},{"batb":[[0,1.8,54.6],[1,1.75,9.02],[2,1.62,8.53]],"ltp":1.95,"tv":96.04,"id":72857117}]}]}
{"op":"mcm","clk":"11886771970","pt":1724118999320,"mc":[{"id":"1.232019056","rc":[{"batb":[[0,1.97,10],[1,1.96,8.05],[2,1.8,129.83]],"ltp":2.06,"tv":83.79,"id":72857114},{"batb":[[0,1.81,10],[1,1.8,54.6],[2,1.75,9.02]],"ltp":1.95,"tv":96.04,"id":72857117}]}]}
{"op":"mcm","clk":"11886772122","pt":1724119002619,"mc":[{"id":"1.232019056","rc":[{"batb":[[0,1.96,8.05],[1,1.8,129.83],[2,1.52,15]],"ltp":2.06,"tv":83.79,"id":72857114},{"batb":[[0,1.8,54.6],[1,1.75,9.02],[2,1.62,8.53]],"ltp":1.95,"tv":96.04,"id":72857117}]}]}
{"op":"mcm","clk":"11886772241","pt":1724119005022,"mc":[{"id":"1.232019056","rc":[{"batb":[[0,1.97,10],[1,1.96,8.05],[2,1.8,129.83]],"ltp":2.06,"tv":83.79,"id":72857114},{"batb":[[0,1.81,10],[1,1.8,54.6],[2,1.75,9.02]],"ltp":1.95,"tv":96.04,"id":72857117}]}]}
{"op":"mcm","clk":"11886772393","pt":1724119008432,"mc":[{"id":"1.232019056","rc":[{"batb":[[0,1.96,8.05],[1,1.8,129.83],[2,1.52,15]],"ltp":2.06,"tv":83.79,"id":72857114},{"batb":[[0,1.8,54.6],[1,1.75,9.02],[2,1.62,8.53]],"ltp":1.95,"tv":96.04,"id":72857117}]}]}
{"op":"mcm","clk":"11886772547","pt":1724119012017,"mc":[{"id":"1.232019056","rc":[{"batb":[[0,1.97,10],[1,1.96,8.05],[2,1.8,129.83]],"ltp":2.06,"tv":83.79,"id":72857114},{"batb":[[0,1.81,10],[1,1.8,54.6],[2,1.75,9.02]],"ltp":1.95,"tv":96.04,"id":72857117}]}]}
{"op":"mcm","clk":"11886772718","pt":1724119015358,"mc":[{"id":"1.232019056","rc":[{"batb":[[0,1.96,8.05],[1,1.8,129.83],[2,1.52,15]],"ltp":2.06,"tv":83.79,"id":72857114},{"batb":[[0,1.8,54.6],[1,1.75,9.02],[2,1.62,8.53]],"ltp":1.95,"tv":96.04,"id":72857117}]}]}
{"op":"mcm","clk":"11886772817","pt":1724119017738,"mc":[{"id":"1.232019056","rc":[{"batb":[[0,1.97,10],[1,1.96,8.05],[2,1.8,129.83]],"ltp":2.06,"tv":83.79,"id":72857114},{"batb":[[0,1.81,10],[1,1.8,54.6],[2,1.75,9.02]],"ltp":1.95,"tv":96.04,"id":72857117}]}]}
{"op":"mcm","clk":"11886772936","pt":1724119021031,"mc":[{"id":"1.232019056","rc":[{"batb":[[0,1.96,8.05],[1,1.8,129.83],[2,1.52,15]],"ltp":2.06,"tv":83.79,"id":72857114},{"batb":[[0,1.8,54.6],[1,1.75,9.02],[2,1.62,8.53]],"ltp":1.95,"tv":96.04,"id":72857117}]}]}
{"op":"mcm","clk":"11886773044","pt":1724119023557,"mc":[{"id":"1.232019056","rc":[{"batb":[[0,1.97,10],[1,1.96,8.05],[2,1.8,129.83]],"ltp":2.06,"tv":83.79,"id":72857114},{"batb":[[0,1.81,10],[1,1.8,54.6],[2,1.75,9.02]],"ltp":1.95,"tv":96.04,"id":72857117}]}]}
{"op":"mcm","clk":"11886773183","pt":1724119027052,"mc":[{"id":"1.232019056","rc":[{"batb":[[0,1.96,8.05],[1,1.8,129.83],[2,1.52,15]],"ltp":2.06,"tv":83.79,"id":72857114},{"batb":[[0,1.8,54.6],[1,1.75,9.02],[2,1.62,8.53]],"ltp":1.95,"tv":96.04,"id":72857117}]}]}
{"op":"mcm","clk":"11886773293","pt":1724119029327,"mc":[{"id":"1.232019056","rc":[{"batb":[[0,1.97,10],[1,1.96,8.05],[2,1.8,129.83]],"ltp":2.06,"tv":83.79,"id":72857114},{"batb":[[0,1.81,10],[1,1.8,54.6],[2,1.75,9.02]],"ltp":1.95,"tv":96.04,"id":72857117}]}]}
{"op":"mcm","clk":"11886773421","pt":1724119032729,"mc":[{"id":"1.232019056","rc":[{"batb":[[0,1.96,8.05],[1,1.8,129.83],[2,1.52,15]],"ltp":2.06,"tv":83.79,"id":72857114},{"batb":[[0,1.8,54.6],[1,1.75,9.02],[2,1.62,8.53]],"ltp":1.95,"tv":96.04,"id":72857117}]}]}
{"op":"mcm","clk":"11886773498","pt":1724119035048,"mc":[{"id":"1.232019056","rc":[{"batb":[[0,1.97,10],[1,1.96,8.05],[2,1.8,129.83]],"ltp":2.06,"tv":83.79,"id":72857114},{"batb":[[0,1.81,10],[1,1.8,54.6],[2,1.75,9.02]],"ltp":1.95,"tv":96.04,"id":72857117}]}]}
{"op":"mcm","clk":"11886773650","pt":1724119038230,"mc":[{"id":"1.232019056","rc":[{"batb":[[0,1.96,8.05],[1,1.8,129.83],[2,1.52,15]],"ltp":2.06,"tv":83.79,"id":72857114},{"batb":[[0,1.8,54.6],[1,1.75,9.02],[2,1.62,8.53]],"ltp":1.95,"tv":96.04,"id":72857117}]}]}
{"op":"mcm","clk":"11886773737","pt":1724119040673,"mc":[{"id":"1.232019056","rc":[{"batb":[[0,1.97,10],[1,1.96,8.05],[2,1.8,129.83]],"ltp":2.06,"tv":83.79,"id":72857114},{"batb":[[0,1.81,10],[1,1.8,54.6],[2,1.75,9.02]],"ltp":1.95,"tv":96.04,"id":72857117}]}]}
{"op":"mcm","clk":"11886773856","pt":1724119044165,"mc":[{"id":"1.232019056","rc":[{"batb":[[0,1.96,8.05],[1,1.8,129.83],[2,1.52,15]],"ltp":2.06,"tv":83.79,"id":72857114},{"batb":[[0,1.8,54.6],[1,1.75,9.02],[2,1.62,8.53]],"ltp":1.95,"tv":96.04,"id":72857117}]}]}
{"op":"mcm","clk":"11886773940","pt":1724119046889,"mc":[{"id":"1.232019056","rc":[{"batb":[[0,1.97,10],[1,1.96,8.05],[2,1.8,129.83]],"ltp":2.06,"tv":83.79,"id":72857114},{"batb":[[0,1.81,10],[1,1.8,54.6],[2,1.75,9.02]],"ltp":1.95,"tv":96.04,"id":72857117}]}]}
{"op":"mcm","clk":"11886774082","pt":1724119050277,"mc":[{"id":"1.232019056","rc":[{"batb":[[0,1.96,8.05],[1,1.8,129.83],[2,1.52,15]],"ltp":2.06,"tv":83.79,"id":72857114},{"batb":[[0,1.8,54.6],[1,1.75,9.02],[2,1.62,8.53]],"ltp":1.95,"tv":96.04,"id":72857117}]}]}
{"op":"mcm","clk":"11886774183","pt":1724119052490,"mc":[{"id":"1.232019056","rc":[{"batb":[[0,1.97,10],[1,1.96,8.05],[2,1.8,129.83]],"ltp":2.06,"tv":83.79,"id":72857114},{"batb":[[0,1.81,10],[1,1.8,54.6],[2,1.75,9.02]],"ltp":1.95,"tv":96.04,"id":72857117}]}]}
{"op":"mcm","clk":"11886774326","pt":1724119055682,"mc":[{"id":"1.232019056","rc":[{"batb":[[0,1.96,8.05],[1,1.8,129.83],[2,1.52,15]],"ltp":2.06,"tv":83.79,"id":72857114}]}]}
{"op":"mcm","clk":"11886774345","pt":1724119055993,"mc":[{"id":"1.232019056","rc":[{"batb":[[0,1.8,54.6],[1,1.75,9.02],[2,1.62,8.53]],"ltp":1.95,"tv":96.04,"id":72857117}]}]}
{"op":"mcm","clk":"11886774437","pt":1724119058207,"mc":[{"id":"1.232019056","rc":[{"batb":[[0,1.97,10],[1,1.96,8.05],[2,1.8,129.83]],"ltp":2.06,"tv":83.79,"id":72857114},{"batb":[[0,1.81,10],[1,1.8,54.6],[2,1.75,9.02]],"ltp":1.95,"tv":96.04,"id":72857117}]}]}
{"op":"mcm","clk":"11886774594","pt":1724119061713,"mc":[{"id":"1.232019056","rc":[{"batb":[[0,1.96,8.05],[1,1.8,129.83],[2,1.52,15]],"ltp":2.06,"tv":83.79,"id":72857114},{"batb":[[0,1.8,54.6],[1,1.75,9.02],[2,1.62,8.53]],"ltp":1.95,"tv":96.04,"id":72857117}]}]}
{"op":"mcm","clk":"11886774736","pt":1724119064694,"mc":[{"id":"1.232019056","rc":[{"batb":[[0,1.97,10],[1,1.96,8.05],[2,1.8,129.83]],"ltp":2.06,"tv":83.79,"id":72857114},{"batb":[[0,1.81,10],[1,1.8,54.6],[2,1.75,9.02]],"ltp":1.95,"tv":96.04,"id":72857117}]}]}
{"op":"mcm","clk":"11886774897","pt":1724119067899,"mc":[{"id":"1.232019056","rc":[{"batb":[[0,1.96,8.05],[1,1.8,129.83],[2,1.52,15]],"ltp":2.06,"tv":83.79,"id":72857114},{"batb":[[0,1.8,54.6],[1,1.75,9.02],[2,1.62,8.53]],"ltp":1.95,"tv":96.04,"id":72857117}]}]}
{"op":"mcm","clk":"11886775007","pt":1724119070311,"mc":[{"id":"1.232019056","rc":[{"batb":[[0,1.97,10],[1,1.96,8.05],[2,1.8,129.83]],"ltp":2.06,"tv":83.79,"id":72857114},{"batb":[[0,1.81,10],[1,1.8,54.6],[2,1.75,9.02]],"ltp":1.95,"tv":96.04,"id":72857117}]}]}
{"op":"mcm","clk":"11886775160","pt":1724119073593,"mc":[{"id":"1.232019056","rc":[{"batb":[[0,1.96,8.05],[1,1.8,129.83],[2,1.52,15]],"ltp":2.06,"tv":83.79,"id":72857114},{"batb":[[0,1.8,54.6],[1,1.75,9.02],[2,1.62,8.53]],"ltp":1.95,"tv":96.04,"id":72857117}]}]}
{"op":"mcm","clk":"11886775279","pt":1724119076210,"mc":[{"id":"1.232019056","rc":[{"batb":[[0,1.97,10],[1,1.96,8.05],[2,1.8,129.83]],"ltp":2.06,"tv":83.79,"id":72857114},{"batb":[[0,1.81,10],[1,1.8,54.6],[2,1.75,9.02]],"ltp":1.95,"tv":96.04,"id":72857117}]}]}
{"op":"mcm","clk":"11886775416","pt":1724119079402,"mc":[{"id":"1.232019056","rc":[{"batb":[[0,1.96,8.05],[1,1.8,129.83],[2,1.52,15]],"ltp":2.06,"tv":83.79,"id":72857114},{"batb":[[0,1.8,54.6],[1,1.75,9.02],[2,1.62,8.53]],"ltp":1.95,"tv":96.04,"id":72857117}]}]}
{"op":"mcm","clk":"11886775519","pt":1724119081830,"mc":[{"id":"1.232019056","rc":[{"batb":[[0,1.97,10],[1,1.96,8.05],[2,1.8,129.83]],"ltp":2.06,"tv":83.79,"id":72857114},{"batb":[[0,1.81,10],[1,1.8,54.6],[2,1.75,9.02]],"ltp":1.95,"tv":96.04,"id":72857117}]}]}
{"op":"mcm","clk":"11886775681","pt":1724119085214,"mc":[{"id":"1.232019056","rc":[{"batb":[[0,1.96,8.05],[1,1.8,129.83],[2,1.52,15]],"ltp":2.06,"tv":83.79,"id":72857114},{"batb":[[0,1.8,54.6],[1,1.75,9.02],[2,1.62,8.53]],"ltp":1.95,"tv":96.04,"id":72857117}]}]}
{"op":"mcm","clk":"11886775803","pt":1724119087738,"mc":[{"id":"1.232019056","rc":[{"batb":[[0,1.97,10],[1,1.96,8.05],[2,1.8,129.83]],"ltp":2.06,"tv":83.79,"id":72857114},{"batb":[[0,1.81,10],[1,1.8,54.6],[2,1.75,9.02]],"ltp":1.95,"tv":96.04,"id":72857117}]}]}
{"op":"mcm","clk":"11886775939","pt":1724119091131,"mc":[{"id":"1.232019056","rc":[{"batb":[[0,1.96,8.05],[1,1.8,129.83],[2,1.52,15]],"ltp":2.06,"tv":83.79,"id":72857114},{"batb":[[0,1.8,54.6],[1,1.75,9.02],[2,1.62,8.53]],"ltp":1.95,"tv":96.04,"id":72857117}]}]}
{"op":"mcm","clk":"11886776014","pt":1724119093343,"mc":[{"id":"1.232019056","rc":[{"batb":[[0,1.97,10],[1,1.96,8.05],[2,1.8,129.83]],"ltp":2.06,"tv":83.79,"id":72857114},{"batb":[[0,1.81,10],[1,1.8,54.6],[2,1.75,9.02]],"ltp":1.95,"tv":96.04,"id":72857117}]}]}
{"op":"mcm","clk":"11886776166","pt":1724119096742,"mc":[{"id":"1.232019056","rc":[{"batb":[[0,1.96,8.05],[1,1.8,129.83],[2,1.52,15]],"ltp":2.06,"tv":83.79,"id":72857114},{"batb":[[0,1.8,54.6],[1,1.75,9.02],[2,1.62,8.53]],"ltp":1.95,"tv":96.04,"id":72857117}]}]}
{"op":"mcm","clk":"11886776265","pt":1724119099007,"mc":[{"id":"1.232019056","rc":[{"batb":[[0,1.97,10],[1,1.96,8.05],[2,1.8,129.83]],"ltp":2.06,"tv":83.79,"id":72857114},{"batb":[[0,1.81,10],[1,1.8,54.6],[2,1.75,9.02]],"ltp":1.95,"tv":96.04,"id":72857117}]}]}
{"op":"mcm","clk":"11886776438","pt":1724119102511,"mc":[{"id":"1.232019056","rc":[{"batb":[[0,1.96,8.05],[1,1.8,129.83],[2,1.52,15]],"ltp":2.06,"tv":83.79,"id":72857114},{"batb":[[0,1.8,54.6],[1,1.75,9.02],[2,1.62,8.53]],"ltp":1.95,"tv":96.04,"id":72857117}]}]}
{"op":"mcm","clk":"11886776558","pt":1724119104932,"mc":[{"id":"1.232019056","rc":[{"batb":[[0,1.97,10],[1,1.96,8.05],[2,1.8,129.83]],"ltp":2.06,"tv":83.79,"id":72857114},{"batb":[[0,1.81,10],[1,1.8,54.6],[2,1.75,9.02]],"ltp":1.95,"tv":96.04,"id":72857117}]}]}
{"op":"mcm","clk":"11886776727","pt":1724119108349,"mc":[{"id":"1.232019056","rc":[{"batb":[[0,1.96,8.05],[1,1.8,129.83],[2,1.52,15]],"ltp":2.06,"tv":83.79,"id":72857114},{"batb":[[0,1.8,54.6],[1,1.75,9.02],[2,1.62,8.53]],"ltp":1.95,"tv":96.04,"id":72857117}]}]}
{"op":"mcm","clk":"11886776868","pt":1724119110970,"mc":[{"id":"1.232019056","rc":[{"batb":[[0,1.97,10],[1,1.96,8.05],[2,1.8,129.83]],"ltp":2.06,"tv":83.79,"id":72857114},{"batb":[[0,1.81,10],[1,1.8,54.6],[2,1.75,9.02]],"ltp":1.95,"tv":96.04,"id":72857117}]}]}
{"op":"mcm","clk":"11886777034","pt":1724119114368,"mc":[{"id":"1.232019056","rc":[{"batb":[[0,1.96,8.05],[1,1.8,129.83],[2,1.52,15]],"ltp":2.06,"tv":83.79,"id":72857114},{"batb":[[0,1.8,54.6],[1,1.75,9.02],[2,1.62,8.53]],"ltp":1.95,"tv":96.04,"id":72857117}]}]}
{"op":"mcm","clk":"11886777198","pt":1724119117862,"mc":[{"id":"1.232019056","rc":[{"batb":[[0,1.97,10],[1,1.96,8.05],[2,1.8,129.83]],"ltp":2.06,"tv":83.79,"id":72857114},{"batb":[[0,1.81,10],[1,1.8,54.6],[2,1.75,9.02]],"ltp":1.95,"tv":96.04,"id":72857117}]}]}
{"op":"mcm","clk":"11886777349","pt":1724119121276,"mc":[{"id":"1.232019056","rc":[{"batb":[[0,1.96,8.05],[1,1.8,129.83],[2,1.52,15]],"ltp":2.06,"tv":83.79,"id":72857114},{"batb":[[0,1.8,54.6],[1,1.75,9.02],[2,1.62,8.53]],"ltp":1.95,"tv":96.04,"id":72857117}]}]}
{"op":"mcm","clk":"11886777474","pt":1724119123852,"mc":[{"id":"1.232019056","rc":[{"batb":[[0,1.97,10],[1,1.96,8.05],[2,1.8,129.83]],"ltp":2.06,"tv":83.79,"id":72857114},{"batb":[[0,1.81,10],[1,1.8,54.6],[2,1.75,9.02]],"ltp":1.95,"tv":96.04,"id":72857117}]}]}
{"op":"mcm","clk":"11886777642","pt":1724119127150,"mc":[{"id":"1.232019056","rc":[{"batb":[[0,1.96,8.05],[1,1.8,129.83],[2,1.52,15]],"ltp":2.06,"tv":83.79,"id":72857114},{"batb":[[0,1.8,54.6],[1,1.75,9.02],[2,1.62,8.53]],"ltp":1.95,"tv":96.04,"id":72857117}]}]}
{"op":"mcm","clk":"11886777751","pt":1724119129491,"mc":[{"id":"1.232019056","rc":[{"batb":[[0,1.97,10],[1,1.96,8.05],[2,1.8,129.83]],"ltp":2.06,"tv":83.79,"id":72857114},{"batb":[[0,1.81,10],[1,1.8,54.6],[2,1.75,9.02]],"ltp":1.95,"tv":96.04,"id":72857117}]}]}
{"op":"mcm","clk":"11886777912","pt":1724119132880,"mc":[{"id":"1.232019056","rc":[{"batb":[[0,1.96,8.05],[1,1.8,129.83],[2,1.52,15]],"ltp":2.06,"tv":83.79,"id":72857114},{"batb":[[0,1.8,54.6],[1,1.75,9.02],[2,1.62,8.53]],"ltp":1.95,"tv":96.04,"id":72857117}]}]}
{"op":"mcm","clk":"11886778105","pt":1724119136589,"mc":[{"id":"1.232019056","rc":[{"batb":[[0,1.97,10],[1,1.96,8.05],[2,1.8,129.83]],"ltp":2.06,"tv":83.79,"id":72857114},{"batb":[[0,1.81,10],[1,1.8,54.6],[2,1.75,9.02]],"ltp":1.95,"tv":96.04,"id":72857117}]}]}
{"op":"mcm","clk":"11886778261","pt":1724119139985,"mc":[{"id":"1.232019056","rc":[{"batb":[[0,1.96,8.05],[1,1.8,129.83],[2,1.52,15]],"ltp":2.06,"tv":83.79,"id":72857114},{"batb":[[0,1.8,54.6],[1,1.75,9.02],[2,1.62,8.53]],"ltp":1.95,"tv":96.04,"id":72857117}]}]}
{"op":"mcm","clk":"11886778361","pt":1724119142405,"mc":[{"id":"1.232019056","rc":[{"batb":[[0,1.97,10],[1,1.96,8.05],[2,1.8,129.83]],"ltp":2.06,"tv":83.79,"id":72857114},{"batb":[[0,1.81,10],[1,1.8,54.6],[2,1.75,9.02]],"ltp":1.95,"tv":96.04,"id":72857117}]}]}
{"op":"mcm","clk":"11886778528","pt":1724119145706,"mc":[{"id":"1.232019056","rc":[{"batb":[[0,1.96,8.05],[1,1.8,129.83],[2,1.52,15]],"ltp":2.06,"tv":83.79,"id":72857114},{"batb":[[0,1.8,54.6],[1,1.75,9.02],[2,1.62,8.53]],"ltp":1.95,"tv":96.04,"id":72857117}]}]}
{"op":"mcm","clk":"11886778639","pt":1724119147984,"mc":[{"id":"1.232019056","rc":[{"batb":[[0,1.97,10],[1,1.96,8.05],[2,1.8,129.83]],"ltp":2.06,"tv":83.79,"id":72857114},{"batb":[[0,1.81,10],[1,1.8,54.6],[2,1.75,9.02]],"ltp":1.95,"tv":96.04,"id":72857117}]}]}
{"op":"mcm","clk":"11886778809","pt":1724119151403,"mc":[{"id":"1.232019056","rc":[{"batb":[[0,1.96,8.05],[1,1.8,129.83],[2,1.52,15]],"ltp":2.06,"tv":83.79,"id":72857114},{"batb":[[0,1.8,54.6],[1,1.75,9.02],[2,1.62,8.53]],"ltp":1.95,"tv":96.04,"id":72857117}]}]}
{"op":"mcm","clk":"11886778933","pt":1724119153819,"mc":[{"id":"1.232019056","rc":[{"batb":[[0,1.97,10],[1,1.96,8.05],[2,1.8,129.83]],"ltp":2.06,"tv":83.79,"id":72857114},{"batb":[[0,1.81,10],[1,1.8,54.6],[2,1.75,9.02]],"ltp":1.95,"tv":96.04,"id":72857117}]}]}
{"op":"mcm","clk":"11886779084","pt":1724119157132,"mc":[{"id":"1.232019056","rc":[{"batb":[[0,1.96,8.05],[1,1.8,129.83],[2,1.52,15]],"ltp":2.06,"tv":83.79,"id":72857114},{"batb":[[0,1.8,54.6],[1,1.75,9.02],[2,1.62,8.53]],"ltp":1.95,"tv":96.04,"id":72857117}]}]}
{"op":"mcm","clk":"11886779227","pt":1724119160835,"mc":[{"id":"1.232019056","rc":[{"batb":[[0,1.97,10],[1,1.96,8.05],[2,1.8,129.83]],"ltp":2.06,"tv":83.79,"id":72857114},{"batb":[[0,1.81,10],[1,1.8,54.6],[2,1.75,9.02]],"ltp":1.95,"tv":96.04,"id":72857117}]}]}
{"op":"mcm","clk":"11886779359","pt":1724119164336,"mc":[{"id":"1.232019056","rc":[{"batb":[[0,1.96,8.05],[1,1.8,129.83],[2,1.52,15]],"ltp":2.06,"tv":83.79,"id":72857114},{"batb":[[0,1.8,54.6],[1,1.75,9.02],[2,1.62,8.53]],"ltp":1.95,"tv":96.04,"id":72857117}]}]}
{"op":"mcm","clk":"11886779446","pt":1724119166752,"mc":[{"id":"1.232019056","rc":[{"batb":[[0,1.97,10],[1,1.96,8.05],[2,1.8,129.83]],"ltp":2.06,"tv":83.79,"id":72857114},{"batb":[[0,1.81,10],[1,1.8,54.6],[2,1.75,9.02]],"ltp":1.95,"tv":96.04,"id":72857117}]}]}
{"op":"mcm","clk":"11886779594","pt":1724119170250,"mc":[{"id":"1.232019056","rc":[{"batb":[[0,1.96,8.05],[1,1.8,129.83],[2,1.52,15]],"ltp":2.06,"tv":83.79,"id":72857114},{"batb":[[0,1.8,54.6],[1,1.75,9.02],[2,1.62,8.53]],"ltp":1.95,"tv":96.04,"id":72857117}]}]}
{"op":"mcm","clk":"11886779634","pt":1724119171124,"mc":[{"id":"1.232019056","rc":[{"batb":[[1,1.81,6.77],[2,1.8,129.83]],"ltp":2.06,"tv":83.79,"id":72857114},{"batl":[[0,2.24,5.45],[1,5,1.54],[2,9,1.54]],"ltp":1.95,"tv":96.04,"id":72857117}]}]}
{"op":"mcm","clk":"11886779728","pt":1724119173437,"mc":[{"id":"1.232019056","rc":[{"batb":[[0,1.97,10],[1,1.96,8.05],[2,1.81,6.77]],"ltp":2.06,"tv":83.79,"id":72857114},{"batb":[[0,1.81,10],[1,1.8,54.6],[2,1.75,9.02]],"ltp":1.95,"tv":96.04,"id":72857117}]}]}
{"op":"mcm","clk":"11886779747","pt":1724119173844,"mc":[{"id":"1.232019056","rc":[{"batb":[[2,1.8,129.83]],"ltp":2.06,"tv":83.79,"id":72857114},{"batl":[[0,5,1.54],[1,9,1.54],[2,9,0]],"ltp":1.95,"tv":96.04,"id":72857117}]}]}
{"op":"mcm","clk":"11886779842","pt":1724119176720,"mc":[{"id":"1.232019056","rc":[{"batb":[[0,1.96,8.05],[1,1.8,129.83],[2,1.52,15]],"ltp":2.06,"tv":83.79,"id":72857114},{"batb":[[0,1.8,54.6],[1,1.75,9.02],[2,1.62,8.53]],"ltp":1.95,"tv":96.04,"id":72857117}]}]}
{"op":"mcm","clk":"11886779907","pt":1724119179030,"mc":[{"id":"1.232019056","rc":[{"batb":[[0,1.97,10],[1,1.96,8.05],[2,1.8,129.83]],"ltp":2.06,"tv":83.79,"id":72857114},{"batb":[[0,1.81,10],[1,1.8,54.6],[2,1.75,9.02]],"ltp":1.95,"tv":96.04,"id":72857117}]}]}
{"op":"mcm","clk":"11886780054","pt":1724119182438,"mc":[{"id":"1.232019056","rc":[{"batb":[[0,1.96,8.05],[1,1.8,129.83],[2,1.52,15]],"ltp":2.06,"tv":83.79,"id":72857114},{"batb":[[0,1.8,54.6],[1,1.75,9.02],[2,1.62,8.53]],"ltp":1.95,"tv":96.04,"id":72857117}]}]}
{"op":"mcm","clk":"11886780182","pt":1724119185471,"mc":[{"id":"1.232019056","rc":[{"batb":[[0,1.97,10],[1,1.96,8.05],[2,1.8,129.83]],"ltp":2.06,"tv":83.79,"id":72857114},{"batb":[[0,1.81,10],[1,1.8,54.6],[2,1.75,9.02]],"ltp":1.95,"tv":96.04,"id":72857117}]}]}
{"op":"mcm","clk":"11886780340","pt":1724119188853,"mc":[{"id":"1.232019056","rc":[{"batb":[[0,1.96,8.05],[1,1.8,129.83],[2,1.52,15]],"ltp":2.06,"tv":83.79,"id":72857114},{"batb":[[0,1.8,54.6],[1,1.75,9.02],[2,1.62,8.53]],"ltp":1.95,"tv":96.04,"id":72857117}]}]}
{"op":"mcm","clk":"11886780432","pt":1724119191157,"mc":[{"id":"1.232019056","rc":[{"batb":[[0,1.97,10],[1,1.96,8.05],[2,1.8,129.83]],"ltp":2.06,"tv":83.79,"id":72857114},{"batb":[[0,1.81,10],[1,1.8,54.6],[2,1.75,9.02]],"ltp":1.95,"tv":96.04,"id":72857117}]}]}
{"op":"mcm","clk":"11886780550","pt":1724119194456,"mc":[{"id":"1.232019056","rc":[{"batb":[[0,1.96,8.05],[1,1.8,129.83],[2,1.52,15]],"ltp":2.06,"tv":83.79,"id":72857114},{"batb":[[0,1.8,54.6],[1,1.75,9.02],[2,1.62,8.53]],"ltp":1.95,"tv":96.04,"id":72857117}]}]}
{"op":"mcm","clk":"11886780680","pt":1724119197335,"mc":[{"id":"1.232019056","rc":[{"batb":[[0,1.97,10],[1,1.96,8.05],[2,1.8,129.83]],"ltp":2.06,"tv":83.79,"id":72857114},{"batb":[[0,1.81,10],[1,1.8,54.6],[2,1.75,9.02]],"ltp":1.95,"tv":96.04,"id":72857117}]}]}
{"op":"mcm","clk":"11886780813","pt":1724119200566,"mc":[{"id":"1.232019056","rc":[{"batb":[[0,1.96,8.05],[1,1.8,129.83],[2,1.52,15]],"ltp":2.06,"tv":83.79,"id":72857114},{"batb":[[0,1.8,54.6],[1,1.75,9.02],[2,1.62,8.53]],"ltp":1.95,"tv":96.04,"id":72857117}]}]}
{"op":"mcm","clk":"11886780913","pt":1724119203184,"mc":[{"id":"1.232019056","rc":[{"trd":[[1.5,2.31]],"batb":[[0,1.97,10],[1,1.96,8.05],[2,1.8,129.83]],"ltp":2.06,"tv":83.79,"id":72857114},{"trd":[[1.58,5.44]],"batb":[[0,1.81,10],[1,1.8,54.6],[2,1.75,9.02]],"ltp":1.95,"tv":96.05,"id":72857117}],"tv":179.84}]}
{"op":"mcm","clk":"11886781076","pt":1724119206683,"mc":[{"id":"1.232019056","rc":[{"batb":[[0,1.96,8.05],[1,1.8,129.83],[2,1.52,15]],"ltp":2.06,"tv":83.79,"id":72857114},{"batb":[[0,1.8,54.6],[1,1.75,9.02],[2,1.62,8.54]],"ltp":1.95,"tv":96.05,"id":72857117}]}]}
{"op":"mcm","clk":"11886781179","pt":1724119208993,"mc":[{"id":"1.232019056","rc":[{"batb":[[0,1.97,10],[1,1.96,8.05],[2,1.8,129.83]],"ltp":2.06,"tv":83.79,"id":72857114},{"batb":[[0,1.81,10],[1,1.8,54.6],[2,1.75,9.02]],"ltp":1.95,"tv":96.05,"id":72857117}]}]}
{"op":"mcm","clk":"11886781338","pt":1724119212387,"mc":[{"id":"1.232019056","rc":[{"batb":[[0,1.96,8.05],[1,1.8,129.83],[2,1.52,15]],"ltp":2.06,"tv":83.79,"id":72857114},{"batb":[[0,1.8,54.6],[1,1.75,9.02],[2,1.62,8.54]],"ltp":1.95,"tv":96.05,"id":72857117}]}]}
{"op":"mcm","clk":"11886781427","pt":1724119214861,"mc":[{"id":"1.232019056","rc":[{"batb":[[0,1.97,10],[1,1.96,8.05],[2,1.8,129.83]],"ltp":2.06,"tv":83.79,"id":72857114},{"batb":[[0,1.81,10],[1,1.8,54.6],[2,1.75,9.02]],"ltp":1.95,"tv":96.05,"id":72857117}]}]}
{"op":"mcm","clk":"11886781539","pt":1724119218296,"mc":[{"id":"1.232019056","rc":[{"batb":[[0,1.96,8.05],[1,1.8,129.83],[2,1.52,15]],"ltp":2.06,"tv":83.79,"id":72857114},{"batb":[[0,1.8,54.6],[1,1.75,9.02],[2,1.62,8.54]],"ltp":1.95,"tv":96.05,"id":72857117}]}]}
{"op":"mcm","clk":"11886781648","pt":1724119220913,"mc":[{"id":"1.232019056","rc":[{"batb":[[0,1.97,10],[1,1.96,8.05],[2,1.8,129.83]],"ltp":2.06,"tv":83.79,"id":72857114},{"batb":[[0,1.81,10],[1,1.8,54.6],[2,1.75,9.02]],"ltp":1.95,"tv":96.05,"id":72857117}]}]}
{"op":"mcm","clk":"11886781784","pt":1724119224394,"mc":[{"id":"1.232019056","rc":[{"batb":[[0,1.96,8.05],[1,1.8,129.83],[2,1.52,15]],"ltp":2.06,"tv":83.79,"id":72857114},{"batb":[[0,1.8,54.6],[1,1.75,9.02],[2,1.62,8.54]],"ltp":1.95,"tv":96.05,"id":72857117}]}]}
{"op":"mcm","clk":"11886781877","pt":1724119227062,"mc":[{"id":"1.232019056","rc":[{"batb":[[0,1.97,10],[1,1.96,8.05],[2,1.8,129.83]],"ltp":2.06,"tv":83.79,"id":72857114},{"batb":[[0,1.81,10],[1,1.8,54.6],[2,1.75,9.02]],"ltp":1.95,"tv":96.05,"id":72857117}]}]}
{"op":"mcm","clk":"11886782004","pt":1724119230402,"mc":[{"id":"1.232019056","rc":[{"batb":[[0,1.96,8.05],[1,1.8,129.83],[2,1.52,15]],"ltp":2.06,"tv":83.79,"id":72857114},{"batb":[[0,1.8,54.6],[1,1.75,9.02],[2,1.62,8.54]],"ltp":1.95,"tv":96.05,"id":72857117}]}]}
{"op":"mcm","clk":"11886782094","pt":1724119233019,"mc":[{"id":"1.232019056","rc":[{"batb":[[0,1.97,10],[1,1.96,8.05],[2,1.8,129.83]],"ltp":2.06,"tv":83.79,"id":72857114},{"batb":[[0,1.81,10],[1,1.8,54.6],[2,1.75,9.02]],"ltp":1.95,"tv":96.05,"id":72857117}]}]}
{"op":"mcm","clk":"11886782251","pt":1724119236410,"mc":[{"id":"1.232019056","rc":[{"batb":[[0,1.96,8.05],[1,1.8,129.83],[2,1.52,15]],"ltp":2.06,"tv":83.79,"id":72857114},{"batb":[[0,1.8,54.6],[1,1.75,9.02],[2,1.62,8.54]],"ltp":1.95,"tv":96.05,"id":72857117}]}]}
{"op":"mcm","clk":"11886782347","pt":1724119238713,"mc":[{"id":"1.232019056","rc":[{"batb":[[0,1.97,10],[1,1.96,8.05],[2,1.8,129.83]],"ltp":2.06,"tv":83.79,"id":72857114},{"batb":[[0,1.81,10],[1,1.8,54.6],[2,1.75,9.02]],"ltp":1.95,"tv":96.05,"id":72857117}]}]}
{"op":"mcm","clk":"11886782469","pt":1724119242011,"mc":[{"id":"1.232019056","rc":[{"batb":[[0,1.96,8.05],[1,1.8,129.83],[2,1.52,15]],"ltp":2.06,"tv":83.79,"id":72857114},{"batb":[[0,1.8,54.6],[1,1.75,9.02],[2,1.62,8.54]],"ltp":1.95,"tv":96.05,"id":72857117}]}]}
{"op":"mcm","clk":"11886782586","pt":1724119244582,"mc":[{"id":"1.232019056","rc":[{"batb":[[0,1.97,10],[1,1.96,8.05],[2,1.8,129.83]],"ltp":2.06,"tv":83.79,"id":72857114},{"batb":[[0,1.81,10],[1,1.8,54.6],[2,1.75,9.02]],"ltp":1.95,"tv":96.05,"id":72857117}]}]}
{"op":"mcm","clk":"11886782747","pt":1724119248027,"mc":[{"id":"1.232019056","rc":[{"batb":[[0,1.96,8.05],[1,1.8,129.83],[2,1.52,15]],"ltp":2.06,"tv":83.79,"id":72857114},{"batb":[[0,1.8,54.6],[1,1.75,9.02],[2,1.62,8.54]],"ltp":1.95,"tv":96.05,"id":72857117}]}]}
{"op":"mcm","clk":"11886782848","pt":1724119250443,"mc":[{"id":"1.232019056","rc":[{"batb":[[0,1.97,10],[1,1.96,8.05],[2,1.8,129.83]],"ltp":2.06,"tv":83.79,"id":72857114},{"batb":[[0,1.81,10],[1,1.8,54.6],[2,1.75,9.02]],"ltp":1.95,"tv":96.05,"id":72857117}]}]}
{"op":"mcm","clk":"11886782971","pt":1724119253708,"mc":[{"id":"1.232019056","rc":[{"batb":[[0,1.96,8.05],[1,1.8,129.83],[2,1.52,15]],"ltp":2.06,"tv":83.79,"id":72857114},{"batb":[[0,1.8,54.6],[1,1.75,9.02],[2,1.62,8.54]],"ltp":1.95,"tv":96.05,"id":72857117}]}]}
{"op":"mcm","clk":"11886783040","pt":1724119256226,"mc":[{"id":"1.232019056","rc":[{"batb":[[0,1.97,10],[1,1.96,8.05],[2,1.8,129.83]],"ltp":2.06,"tv":83.79,"id":72857114},{"batb":[[0,1.81,10],[1,1.8,54.6],[2,1.75,9.02]],"ltp":1.95,"tv":96.05,"id":72857117}]}]}
{"op":"mcm","clk":"11886783180","pt":1724119259709,"mc":[{"id":"1.232019056","rc":[{"batb":[[0,1.96,8.05],[1,1.8,129.83],[2,1.52,15]],"ltp":2.06,"tv":83.79,"id":72857114},{"batb":[[0,1.8,54.6],[1,1.75,9.02],[2,1.62,8.54]],"ltp":1.95,"tv":96.05,"id":72857117}]}]}
{"op":"mcm","clk":"11886783290","pt":1724119262336,"mc":[{"id":"1.232019056","rc":[{"batb":[[0,1.97,10],[1,1.96,8.05],[2,1.8,129.83]],"ltp":2.06,"tv":83.79,"id":72857114},{"batb":[[0,1.81,10],[1,1.8,54.6],[2,1.75,9.02]],"ltp":1.95,"tv":96.05,"id":72857117}]}]}
{"op":"mcm","clk":"11886783428","pt":1724119265921,"mc":[{"id":"1.232019056","rc":[{"batb":[[0,1.96,8.05],[1,1.8,129.83],[2,1.52,15]],"ltp":2.06,"tv":83.79,"id":72857114},{"batb":[[0,1.8,54.6],[1,1.75,9.02],[2,1.62,8.54]],"ltp":1.95,"tv":96.05,"id":72857117}]}]}
{"op":"mcm","clk":"11886783565","pt":1724119269216,"mc":[{"id":"1.232019056","rc":[{"batb":[[0,1.97,10],[1,1.96,8.05],[2,1.8,129.83]],"ltp":2.06,"tv":83.79,"id":72857114},{"batb":[[0,1.81,10],[1,1.8,54.6],[2,1.75,9.02]],"ltp":1.95,"tv":96.05,"id":72857117}]}]}
{"op":"mcm","clk":"11886783682","pt":1724119272443,"mc":[{"id":"1.232019056","rc":[{"batb":[[0,1.96,8.05],[1,1.8,129.83],[2,1.52,15]],"ltp":2.06,"tv":83.79,"id":72857114},{"batb":[[0,1.8,54.6],[1,1.75,9.02],[2,1.62,8.54]],"ltp":1.95,"tv":96.05,"id":72857117}]}]}
{"op":"mcm","clk":"11886783780","pt":1724119275423,"mc":[{"id":"1.232019056","rc":[{"batb":[[0,1.97,10],[1,1.96,8.05],[2,1.8,129.83]],"ltp":2.06,"tv":83.79,"id":72857114},{"batb":[[0,1.81,10],[1,1.8,54.6],[2,1.75,9.02]],"ltp":1.95,"tv":96.05,"id":72857117}]}]}
{"op":"mcm","clk":"11886783877","pt":1724119278865,"mc":[{"id":"1.232019056","rc":[{"batb":[[0,1.96,8.05],[1,1.8,129.83],[2,1.52,15]],"ltp":2.06,"tv":83.79,"id":72857114},{"batb":[[0,1.8,54.6],[1,1.75,9.02],[2,1.62,8.54]],"ltp":1.95,"tv":96.05,"id":72857117}]}]}
{"op":"mcm","clk":"11886783936","pt":1724119281337,"mc":[{"id":"1.232019056","rc":[{"batb":[[0,1.97,10],[1,1.96,8.05],[2,1.8,129.83]],"ltp":2.06,"tv":83.79,"id":72857114},{"batb":[[0,1.81,10],[1,1.8,54.6],[2,1.75,9.02]],"ltp":1.95,"tv":96.05,"id":72857117}]}]}
{"op":"mcm","clk":"11886784035","pt":1724119284622,"mc":[{"id":"1.232019056","rc":[{"batb":[[0,1.96,8.05],[1,1.8,129.83],[2,1.52,15]],"ltp":2.06,"tv":83.79,"id":72857114},{"batb":[[0,1.8,54.6],[1,1.75,9.02],[2,1.62,8.54]],"ltp":1.95,"tv":96.05,"id":72857117}]}]}
{"op":"mcm","clk":"11886784067","pt":1724119285347,"mc":[{"id":"1.232019056","rc":[{"batb":[[1,1.81,6.77],[2,1.8,129.83]],"ltp":2.06,"tv":83.79,"id":72857114},{"batl":[[0,2.24,5.46],[1,5,1.54],[2,9,1.54]],"ltp":1.95,"tv":96.05,"id":72857117}]}]}
{"op":"mcm","clk":"11886784139","pt":1724119287768,"mc":[{"id":"1.232019056","rc":[{"batb":[[0,1.97,10],[1,1.96,8.05],[2,1.81,6.77]],"ltp":2.06,"tv":83.79,"id":72857114},{"batb":[[0,1.81,10],[1,1.8,54.6],[2,1.75,9.02]],"ltp":1.95,"tv":96.05,"id":72857117}]}]}
{"op":"mcm","clk":"11886784200","pt":1724119289934,"mc":[{"id":"1.232019056","rc":[{"batb":[[2,1.8,129.83]],"ltp":2.06,"tv":83.79,"id":72857114},{"batl":[[0,5,1.54],[1,9,1.54],[2,9,0]],"ltp":1.95,"tv":96.05,"id":72857117}]}]}
{"op":"mcm","clk":"11886784245","pt":1724119291160,"mc":[{"id":"1.232019056","rc":[{"batb":[[0,1.96,8.05],[1,1.8,129.83],[2,1.52,15]],"ltp":2.06,"tv":83.79,"id":72857114},{"batb":[[0,1.8,54.6],[1,1.75,9.02],[2,1.62,8.54]],"ltp":1.95,"tv":96.05,"id":72857117}]}]}
{"op":"mcm","clk":"11886784322","pt":1724119293474,"mc":[{"id":"1.232019056","rc":[{"batb":[[0,1.97,10],[1,1.96,8.05],[2,1.8,129.83]],"ltp":2.06,"tv":83.79,"id":72857114},{"batb":[[0,1.81,10],[1,1.8,54.6],[2,1.75,9.02]],"ltp":1.95,"tv":96.05,"id":72857117}]}]}
{"op":"mcm","clk":"11886784416","pt":1724119296876,"mc":[{"id":"1.232019056","rc":[{"batb":[[0,1.96,8.05],[1,1.8,129.83],[2,1.52,15]],"ltp":2.06,"tv":83.79,"id":72857114},{"batb":[[0,1.8,54.6],[1,1.75,9.02],[2,1.62,8.54]],"ltp":1.95,"tv":96.05,"id":72857117}]}]}
{"op":"mcm","clk":"11886784471","pt":1724119299238,"mc":[{"id":"1.232019056","rc":[{"batb":[[0,1.97,10],[1,1.96,8.05],[2,1.8,129.83]],"ltp":2.06,"tv":83.79,"id":72857114},{"batb":[[0,1.81,10],[1,1.8,54.6],[2,1.75,9.02]],"ltp":1.95,"tv":96.05,"id":72857117}]}]}
{"op":"mcm","clk":"11886784563","pt":1724119302644,"mc":[{"id":"1.232019056","rc":[{"batb":[[0,1.96,8.05],[1,1.8,129.83],[2,1.52,15]],"ltp":2.06,"tv":83.79,"id":72857114},{"batb":[[0,1.8,54.6],[1,1.75,9.02],[2,1.62,8.54]],"ltp":1.95,"tv":96.05,"id":72857117}]}]}
{"op":"mcm","clk":"11886784642","pt":1724119305169,"mc":[{"id":"1.232019056","rc":[{"batb":[[0,1.97,10],[1,1.96,8.05],[2,1.8,129.83]],"ltp":2.06,"tv":83.79,"id":72857114},{"batb":[[0,1.81,10],[1,1.8,54.6],[2,1.75,9.02]],"ltp":1.95,"tv":96.05,"id":72857117}]}]}
{"op":"mcm","clk":"11886784741","pt":1724119308651,"mc":[{"id":"1.232019056","rc":[{"batb":[[0,1.96,8.05],[1,1.8,129.83],[2,1.52,15]],"ltp":2.06,"tv":83.79,"id":72857114},{"batb":[[0,1.8,54.6],[1,1.75,9.02],[2,1.62,8.54]],"ltp":1.95,"tv":96.05,"id":72857117}]}]}
{"op":"mcm","clk":"11886784805","pt":1724119311066,"mc":[{"id":"1.232019056","rc":[{"batb":[[0,1.97,10],[1,1.96,8.05],[2,1.8,129.83]],"ltp":2.06,"tv":83.79,"id":72857114},{"batb":[[0,1.81,10],[1,1.8,54.6],[2,1.75,9.02]],"ltp":1.95,"tv":96.05,"id":72857117}]}]}
{"op":"mcm","clk":"11886784876","pt":1724119314451,"mc":[{"id":"1.232019056","rc":[{"batb":[[0,1.96,8.05],[1,1.8,129.83],[2,1.52,15]],"ltp":2.06,"tv":83.79,"id":72857114},{"batb":[[0,1.8,54.6],[1,1.75,9.02],[2,1.62,8.54]],"ltp":1.95,"tv":96.05,"id":72857117}]}]}
{"op":"mcm","clk":"11886784959","pt":1724119316863,"mc":[{"id":"1.232019056","rc":[{"batb":[[0,1.97,10],[1,1.96,8.05],[2,1.8,129.83]],"ltp":2.06,"tv":83.79,"id":72857114},{"batb":[[0,1.81,10],[1,1.8,54.6],[2,1.75,9.02]],"ltp":1.95,"tv":96.05,"id":72857117}]}]}
{"op":"mcm","clk":"11886785083","pt":1724119320162,"mc":[{"id":"1.232019056","rc":[{"batb":[[0,1.96,8.05],[1,1.8,129.83],[2,1.52,15]],"ltp":2.06,"tv":83.79,"id":72857114},{"batb":[[0,1.8,54.6],[1,1.75,9.02],[2,1.62,8.54]],"ltp":1.95,"tv":96.05,"id":72857117}]}]}
{"op":"mcm","clk":"11886785151","pt":1724119322573,"mc":[{"id":"1.232019056","rc":[{"batb":[[0,1.97,10],[1,1.96,8.05],[2,1.8,129.83]],"ltp":2.06,"tv":83.79,"id":72857114},{"batb":[[0,1.81,10],[1,1.8,54.6],[2,1.75,9.02]],"ltp":1.95,"tv":96.05,"id":72857117}]}]}
{"op":"mcm","clk":"11886785267","pt":1724119326018,"mc":[{"id":"1.232019056","rc":[{"batb":[[0,1.96,8.05],[1,1.8,129.83],[2,1.52,15]],"ltp":2.06,"tv":83.79,"id":72857114},{"batb":[[0,1.8,54.6],[1,1.75,9.02],[2,1.62,8.54]],"ltp":1.95,"tv":96.05,"id":72857117}]}]}
{"op":"mcm","clk":"11886785328","pt":1724119328383,"mc":[{"id":"1.232019056","rc":[{"batb":[[0,1.97,10],[1,1.96,8.05],[2,1.8,129.83]],"ltp":2.06,"tv":83.79,"id":72857114},{"batb":[[0,1.81,10],[1,1.8,54.6],[2,1.75,9.02]],"ltp":1.95,"tv":96.05,"id":72857117}]}]}
{"op":"mcm","clk":"11886785444","pt":1724119331816,"mc":[{"id":"1.232019056","rc":[{"batb":[[0,1.96,8.05],[1,1.8,129.83],[2,1.52,15]],"ltp":2.06,"tv":83.79,"id":72857114},{"batb":[[0,1.8,54.6],[1,1.75,9.02],[2,1.62,8.54]],"ltp":1.95,"tv":96.05,"id":72857117}]}]}
{"op":"mcm","clk":"11886785565","pt":1724119335611,"mc":[{"id":"1.232019056","rc":[{"batb":[[0,1.97,10],[1,1.96,8.05],[2,1.8,129.83]],"ltp":2.06,"tv":83.79,"id":72857114},{"batb":[[0,1.81,10],[1,1.8,54.6],[2,1.75,9.02]],"ltp":1.95,"tv":96.05,"id":72857117}]}]}
{"op":"mcm","clk":"11886785645","pt":1724119338889,"mc":[{"id":"1.232019056","rc":[{"batb":[[0,1.96,8.05],[1,1.8,129.83],[2,1.52,15]],"ltp":2.06,"tv":83.79,"id":72857114},{"batb":[[0,1.8,54.6],[1,1.75,9.02],[2,1.62,8.54]],"ltp":1.95,"tv":96.05,"id":72857117}]}]}
{"op":"mcm","clk":"11886785717","pt":1724119341099,"mc":[{"id":"1.232019056","rc":[{"batb":[[0,1.97,10],[1,1.96,8.05],[2,1.8,129.83]],"ltp":2.06,"tv":83.79,"id":72857114},{"batb":[[0,1.81,10],[1,1.8,54.6],[2,1.75,9.02]],"ltp":1.95,"tv":96.05,"id":72857117}]}]}
{"op":"mcm","clk":"11886785821","pt":1724119344332,"mc":[{"id":"1.232019056","rc":[{"batb":[[0,1.96,8.05],[1,1.8,129.83],[2,1.52,15]],"ltp":2.06,"tv":83.79,"id":72857114},{"batb":[[0,1.8,54.6],[1,1.75,9.02],[2,1.62,8.54]],"ltp":1.95,"tv":96.05,"id":72857117}]}]}
{"op":"mcm","clk":"11886785908","pt":1724119346899,"mc":[{"id":"1.232019056","rc":[{"batb":[[0,1.97,10],[1,1.96,8.05],[2,1.8,129.83]],"ltp":2.06,"tv":83.79,"id":72857114},{"batb":[[0,1.81,10],[1,1.8,54.6],[2,1.75,9.02]],"ltp":1.95,"tv":96.05,"id":72857117}]}]}
{"op":"mcm","clk":"11886786024","pt":1724119350432,"mc":[{"id":"1.232019056","rc":[{"batb":[[0,1.96,8.05],[1,1.8,129.83],[2,1.52,15]],"ltp":2.06,"tv":83.79,"id":72857114},{"batb":[[0,1.8,54.6],[1,1.75,9.02],[2,1.62,8.54]],"ltp":1.95,"tv":96.05,"id":72857117}]}]}
{"op":"mcm","clk":"11886786069","pt":1724119352711,"mc":[{"id":"1.232019056","rc":[{"batb":[[0,1.97,10],[1,1.96,8.05],[2,1.8,129.83]],"ltp":2.06,"tv":83.79,"id":72857114},{"batb":[[0,1.81,10],[1,1.8,54.6],[2,1.75,9.02]],"ltp":1.95,"tv":96.05,"id":72857117}]}]}
{"op":"mcm","clk":"11886786187","pt":1724119356321,"mc":[{"id":"1.232019056","rc":[{"batb":[[0,1.96,8.05],[1,1.8,129.83],[2,1.52,15]],"ltp":2.06,"tv":83.79,"id":72857114},{"batb":[[0,1.8,54.6],[1,1.75,9.02],[2,1.62,8.54]],"ltp":1.95,"tv":96.05,"id":72857117}]}]}
{"op":"mcm","clk":"11886786272","pt":1724119358733,"mc":[{"id":"1.232019056","rc":[{"batb":[[0,1.97,10],[1,1.96,8.05],[2,1.8,129.83]],"ltp":2.06,"tv":83.79,"id":72857114},{"batb":[[0,1.81,10],[1,1.8,54.6],[2,1.75,9.02]],"ltp":1.95,"tv":96.05,"id":72857117}]}]}
{"op":"mcm","clk":"11886786361","pt":1724119362115,"mc":[{"id":"1.232019056","rc":[{"batb":[[0,1.96,8.05],[1,1.8,129.83],[2,1.52,15]],"ltp":2.06,"tv":83.79,"id":72857114},{"batb":[[0,1.8,54.6],[1,1.75,9.02],[2,1.62,8.54]],"ltp":1.95,"tv":96.05,"id":72857117}]}]}
{"op":"mcm","clk":"11886786416","pt":1724119364435,"mc":[{"id":"1.232019056","rc":[{"batb":[[0,1.97,10],[1,1.96,8.05],[2,1.8,129.83]],"ltp":2.06,"tv":83.79,"id":72857114},{"batb":[[0,1.81,10],[1,1.8,54.6],[2,1.75,9.02]],"ltp":1.95,"tv":96.05,"id":72857117}]}]}
{"op":"mcm","clk":"11886786467","pt":1724119367718,"mc":[{"id":"1.232019056","rc":[{"batb":[[0,1.96,8.05],[1,1.8,129.83],[2,1.52,15]],"ltp":2.06,"tv":83.79,"id":72857114},{"batb":[[0,1.8,54.6],[1,1.75,9.02],[2,1.62,8.54]],"ltp":1.95,"tv":96.05,"id":72857117}]}]}
{"op":"mcm","clk":"11886786502","pt":1724119370132,"mc":[{"id":"1.232019056","rc":[{"batb":[[0,1.97,10],[1,1.96,8.05],[2,1.8,129.83]],"ltp":2.06,"tv":83.79,"id":72857114},{"batb":[[0,1.81,10],[1,1.8,54.6],[2,1.75,9.02]],"ltp":1.95,"tv":96.05,"id":72857117}]}]}
{"op":"mcm","clk":"11886786566","pt":1724119373571,"mc":[{"id":"1.232019056","rc":[{"batb":[[0,1.96,8.05],[1,1.8,129.83],[2,1.52,15]],"ltp":2.06,"tv":83.79,"id":72857114},{"batb":[[0,1.8,54.6],[1,1.75,9.02],[2,1.62,8.54]],"ltp":1.95,"tv":96.05,"id":72857117}]}]}
{"op":"mcm","clk":"11886786634","pt":1724119376241,"mc":[{"id":"1.232019056","rc":[{"batb":[[0,1.97,10],[1,1.96,8.05],[2,1.8,129.83]],"ltp":2.06,"tv":83.79,"id":72857114},{"batb":[[0,1.81,10],[1,1.8,54.6],[2,1.75,9.02]],"ltp":1.95,"tv":96.05,"id":72857117}]}]}
{"op":"mcm","clk":"11886786715","pt":1724119379480,"mc":[{"id":"1.232019056","rc":[{"batb":[[0,1.96,8.05],[1,1.8,129.83],[2,1.52,15]],"ltp":2.06,"tv":83.79,"id":72857114},{"batb":[[0,1.8,54.6],[1,1.75,9.02],[2,1.62,8.54]],"ltp":1.95,"tv":96.05,"id":72857117}]}]}
{"op":"mcm","clk":"11886786795","pt":1724119382159,"mc":[{"id":"1.232019056","rc":[{"batb":[[0,1.97,10],[1,1.96,8.05],[2,1.8,129.83]],"ltp":2.06,"tv":83.79,"id":72857114},{"batb":[[0,1.81,10],[1,1.8,54.6],[2,1.75,9.02]],"ltp":1.95,"tv":96.05,"id":72857117}]}]}
{"op":"mcm","clk":"11886786902","pt":1724119385671,"mc":[{"id":"1.232019056","rc":[{"batb":[[0,1.96,8.05],[1,1.8,129.83],[2,1.52,15]],"ltp":2.06,"tv":83.79,"id":72857114},{"batb":[[0,1.8,54.6],[1,1.75,9.02],[2,1.62,8.54]],"ltp":1.95,"tv":96.05,"id":72857117}]}]}
{"op":"mcm","clk":"11886786986","pt":1724119388056,"mc":[{"id":"1.232019056","rc":[{"batb":[[0,1.97,10],[1,1.96,8.05],[2,1.8,129.83]],"ltp":2.06,"tv":83.79,"id":72857114},{"batb":[[0,1.81,10],[1,1.8,54.6],[2,1.75,9.02]],"ltp":1.95,"tv":96.05,"id":72857117}]}]}
{"op":"mcm","clk":"11886787121","pt":1724119391372,"mc":[{"id":"1.232019056","rc":[{"batb":[[0,1.96,8.05],[1,1.8,129.83],[2,1.52,15]],"ltp":2.06,"tv":83.79,"id":72857114},{"batb":[[0,1.8,54.6],[1,1.75,9.02],[2,1.62,8.54]],"ltp":1.95,"tv":96.05,"id":72857117}]}]}
{"op":"mcm","clk":"11886787217","pt":1724119393681,"mc":[{"id":"1.232019056","rc":[{"batb":[[0,1.97,10],[1,1.96,8.05],[2,1.8,129.83]],"ltp":2.06,"tv":83.79,"id":72857114},{"batb":[[0,1.81,10],[1,1.8,54.6],[2,1.75,9.02]],"ltp":1.95,"tv":96.05,"id":72857117}]}]}
{"op":"mcm","clk":"11886787329","pt":1724119397065,"mc":[{"id":"1.232019056","rc":[{"batb":[[0,1.96,8.05],[1,1.8,129.83],[2,1.52,15]],"ltp":2.06,"tv":83.79,"id":72857114},{"batb":[[0,1.8,54.6],[1,1.75,9.02],[2,1.62,8.54]],"ltp":1.95,"tv":96.05,"id":72857117}]}]}
{"op":"mcm","clk":"11886787398","pt":1724119399388,"mc":[{"id":"1.232019056","rc":[{"batb":[[0,1.97,10],[1,1.96,8.05],[2,1.8,129.83]],"ltp":2.06,"tv":83.79,"id":72857114},{"batb":[[0,1.81,10],[1,1.8,54.6],[2,1.75,9.02]],"ltp":1.95,"tv":96.05,"id":72857117}]}]}
{"op":"mcm","clk":"11886787526","pt":1724119402776,"mc":[{"id":"1.232019056","rc":[{"batb":[[0,1.96,8.05],[1,1.8,129.83],[2,1.52,15]],"ltp":2.06,"tv":83.79,"id":72857114},{"batb":[[0,1.8,54.6],[1,1.75,9.02],[2,1.62,8.54]],"ltp":1.95,"tv":96.05,"id":72857117}]}]}
{"op":"mcm","clk":"11886787603","pt":1724119405189,"mc":[{"id":"1.232019056","rc":[{"batb":[[0,1.97,10],[1,1.96,8.05],[2,1.8,129.83]],"ltp":2.06,"tv":83.79,"id":72857114},{"batb":[[0,1.81,10],[1,1.8,54.6],[2,1.75,9.02]],"ltp":1.95,"tv":96.05,"id":72857117}]}]}
{"op":"mcm","clk":"11886787709","pt":1724119408489,"mc":[{"id":"1.232019056","rc":[{"batb":[[0,1.96,8.05],[1,1.8,129.83],[2,1.52,15]],"ltp":2.06,"tv":83.79,"id":72857114},{"batb":[[0,1.8,54.6],[1,1.75,9.02],[2,1.62,8.54]],"ltp":1.95,"tv":96.05,"id":72857117}]}]}
{"op":"mcm","clk":"11886787827","pt":1724119411121,"mc":[{"id":"1.232019056","rc":[{"batb":[[0,1.97,10],[1,1.96,8.05],[2,1.8,129.83]],"ltp":2.06,"tv":83.79,"id":72857114},{"batb":[[0,1.81,10],[1,1.8,54.6],[2,1.75,9.02]],"ltp":1.95,"tv":96.05,"id":72857117}]}]}
{"op":"mcm","clk":"11886787935","pt":1724119414418,"mc":[{"id":"1.232019056","rc":[{"batb":[[0,1.96,8.05],[1,1.8,129.83],[2,1.52,15]],"ltp":2.06,"tv":83.79,"id":72857114},{"batb":[[0,1.8,54.6],[1,1.75,9.02],[2,1.62,8.54]],"ltp":1.95,"tv":96.05,"id":72857117}]}]}
{"op":"mcm","clk":"11886788009","pt":1724119416724,"mc":[{"id":"1.232019056","rc":[{"batb":[[0,1.97,10],[1,1.96,8.05],[2,1.8,129.83]],"ltp":2.06,"tv":83.79,"id":72857114},{"batb":[[0,1.81,10],[1,1.8,54.6],[2,1.75,9.02]],"ltp":1.95,"tv":96.05,"id":72857117}]}]}
{"op":"mcm","clk":"11886788094","pt":1724119420107,"mc":[{"id":"1.232019056","rc":[{"batb":[[0,1.96,8.05],[1,1.8,129.83],[2,1.52,15]],"ltp":2.06,"tv":83.79,"id":72857114},{"batb":[[0,1.8,54.6],[1,1.75,9.02],[2,1.62,8.54]],"ltp":1.95,"tv":96.05,"id":72857117}]}]}
{"op":"mcm","clk":"11886788186","pt":1724119422512,"mc":[{"id":"1.232019056","rc":[{"batb":[[0,1.97,10],[1,1.96,8.05],[2,1.8,129.83]],"ltp":2.06,"tv":83.79,"id":72857114},{"batb":[[0,1.81,10],[1,1.8,54.6],[2,1.75,9.02]],"ltp":1.95,"tv":96.05,"id":72857117}]}]}
{"op":"mcm","clk":"11886788297","pt":1724119425929,"mc":[{"id":"1.232019056","rc":[{"batb":[[0,1.96,8.05],[1,1.8,129.83],[2,1.52,15]],"ltp":2.06,"tv":83.79,"id":72857114},{"batb":[[0,1.8,54.6],[1,1.75,9.02],[2,1.62,8.54]],"ltp":1.95,"tv":96.05,"id":72857117}]}]}
{"op":"mcm","clk":"11886788377","pt":1724119428306,"mc":[{"id":"1.232019056","rc":[{"batb":[[0,1.97,10],[1,1.96,8.05],[2,1.8,129.83]],"ltp":2.06,"tv":83.79,"id":72857114},{"batb":[[0,1.81,10],[1,1.8,54.6],[2,1.75,9.02]],"ltp":1.95,"tv":96.05,"id":72857117}]}]}
{"op":"mcm","clk":"11886788456","pt":1724119431445,"mc":[{"id":"1.232019056","rc":[{"batb":[[0,1.96,8.05],[1,1.8,129.83],[2,1.52,15]],"ltp":2.06,"tv":83.79,"id":72857114},{"batb":[[0,1.8,54.6],[1,1.75,9.02],[2,1.62,8.54]],"ltp":1.95,"tv":96.05,"id":72857117}]}]}
{"op":"mcm","clk":"11886788528","pt":1724119433612,"mc":[{"id":"1.232019056","rc":[{"batb":[[0,1.97,10],[1,1.96,8.05],[2,1.8,129.83]],"ltp":2.06,"tv":83.79,"id":72857114},{"batb":[[0,1.81,10],[1,1.8,54.6],[2,1.75,9.02]],"ltp":1.95,"tv":96.05,"id":72857117}]}]}
{"op":"mcm","clk":"11886788628","pt":1724119437109,"mc":[{"id":"1.232019056","rc":[{"batb":[[0,1.96,8.05],[1,1.8,129.83],[2,1.52,15]],"ltp":2.06,"tv":83.79,"id":72857114},{"batb":[[0,1.8,54.6],[1,1.75,9.02],[2,1.62,8.54]],"ltp":1.95,"tv":96.05,"id":72857117}]}]}
{"op":"mcm","clk":"11886788727","pt":1724119439528,"mc":[{"id":"1.232019056","rc":[{"batb":[[0,1.97,10],[1,1.96,8.05],[2,1.8,129.83]],"ltp":2.06,"tv":83.79,"id":72857114},{"batb":[[0,1.81,10],[1,1.8,54.6],[2,1.75,9.02]],"ltp":1.95,"tv":96.05,"id":72857117}]}]}
{"op":"mcm","clk":"11886788875","pt":1724119442830,"mc":[{"id":"1.232019056","rc":[{"batb":[[0,1.96,8.05],[1,1.8,129.83],[2,1.52,15]],"ltp":2.06,"tv":83.79,"id":72857114},{"batb":[[0,1.8,54.6],[1,1.75,9.02],[2,1.62,8.54]],"ltp":1.95,"tv":96.05,"id":72857117}]}]}
{"op":"mcm","clk":"11886788970","pt":1724119445252,"mc":[{"id":"1.232019056","rc":[{"batb":[[0,1.97,10],[1,1.96,8.05],[2,1.8,129.83]],"ltp":2.06,"tv":83.79,"id":72857114},{"batb":[[0,1.81,10],[1,1.8,54.6],[2,1.75,9.02]],"ltp":1.95,"tv":96.05,"id":72857117}]}]}
{"op":"mcm","clk":"11886789136","pt":1724119448552,"mc":[{"id":"1.232019056","rc":[{"batb":[[0,1.96,8.05],[1,1.8,129.83],[2,1.52,15]],"ltp":2.06,"tv":83.79,"id":72857114},{"batb":[[0,1.8,54.6],[1,1.75,9.02],[2,1.62,8.54]],"ltp":1.95,"tv":96.05,"id":72857117}]}]}
{"op":"mcm","clk":"11886789228","pt":1724119450968,"mc":[{"id":"1.232019056","rc":[{"batb":[[0,1.97,10],[1,1.96,8.05],[2,1.8,129.83]],"ltp":2.06,"tv":83.79,"id":72857114},{"batb":[[0,1.81,10],[1,1.8,54.6],[2,1.75,9.02]],"ltp":1.95,"tv":96.05,"id":72857117}]}]}
{"op":"mcm","clk":"11886789337","pt":1724119454364,"mc":[{"id":"1.232019056","rc":[{"batb":[[0,1.96,8.05],[1,1.8,129.83],[2,1.52,15]],"ltp":2.06,"tv":83.79,"id":72857114},{"batb":[[0,1.8,54.6],[1,1.75,9.02],[2,1.62,8.54]],"ltp":1.95,"tv":96.05,"id":72857117}]}]}
{"op":"mcm","clk":"11886789416","pt":1724119456647,"mc":[{"id":"1.232019056","rc":[{"batb":[[0,1.97,10],[1,1.96,8.05],[2,1.8,129.83]],"ltp":2.06,"tv":83.79,"id":72857114},{"batb":[[0,1.81,10],[1,1.8,54.6],[2,1.75,9.02]],"ltp":1.95,"tv":96.05,"id":72857117}]}]}
{"op":"mcm","clk":"11886789546","pt":1724119459843,"mc":[{"id":"1.232019056","rc":[{"batb":[[0,1.96,8.05],[1,1.8,129.83],[2,1.52,15]],"ltp":2.06,"tv":83.79,"id":72857114},{"batb":[[0,1.8,54.6],[1,1.75,9.02],[2,1.62,8.54]],"ltp":1.95,"tv":96.05,"id":72857117}]}]}
{"op":"mcm","clk":"11886789648","pt":1724119462263,"mc":[{"id":"1.232019056","rc":[{"batb":[[0,1.97,10],[1,1.96,8.05],[2,1.8,129.83]],"ltp":2.06,"tv":83.79,"id":72857114},{"batb":[[0,1.81,10],[1,1.8,54.6],[2,1.75,9.02]],"ltp":1.95,"tv":96.05,"id":72857117}]}]}
{"op":"mcm","clk":"11886789748","pt":1724119465466,"mc":[{"id":"1.232019056","rc":[{"batb":[[0,1.96,8.05],[1,1.8,129.83],[2,1.52,15]],"ltp":2.06,"tv":83.79,"id":72857114},{"batb":[[0,1.8,54.6],[1,1.75,9.02],[2,1.62,8.54]],"ltp":1.95,"tv":96.05,"id":72857117}]}]}
{"op":"mcm","clk":"11886789815","pt":1724119467891,"mc":[{"id":"1.232019056","rc":[{"batb":[[0,1.97,10],[1,1.96,8.05],[2,1.8,129.83]],"ltp":2.06,"tv":83.79,"id":72857114},{"batb":[[0,1.81,10],[1,1.8,54.6],[2,1.75,9.02]],"ltp":1.95,"tv":96.05,"id":72857117}]}]}
{"op":"mcm","clk":"11886789937","pt":1724119471080,"mc":[{"id":"1.232019056","rc":[{"batb":[[0,1.96,8.05],[1,1.8,129.83],[2,1.52,15]],"ltp":2.06,"tv":83.79,"id":72857114},{"batb":[[0,1.8,54.6],[1,1.75,9.02],[2,1.62,8.54]],"ltp":1.95,"tv":96.05,"id":72857117}]}]}
{"op":"mcm","clk":"11886790020","pt":1724119473494,"mc":[{"id":"1.232019056","rc":[{"batb":[[0,1.97,10],[1,1.96,8.05],[2,1.8,129.83]],"ltp":2.06,"tv":83.79,"id":72857114},{"batb":[[0,1.81,10],[1,1.8,54.6],[2,1.75,9.02]],"ltp":1.95,"tv":96.05,"id":72857117}]}]}
{"op":"mcm","clk":"11886790143","pt":1724119476802,"mc":[{"id":"1.232019056","rc":[{"batb":[[0,1.96,8.05],[1,1.8,129.83],[2,1.52,15]],"ltp":2.06,"tv":83.79,"id":72857114},{"batb":[[0,1.8,54.6],[1,1.75,9.02],[2,1.62,8.54]],"ltp":1.95,"tv":96.05,"id":72857117}]}]}
{"op":"mcm","clk":"11886790253","pt":1724119479280,"mc":[{"id":"1.232019056","rc":[{"batb":[[0,1.97,10],[1,1.96,8.05],[2,1.8,129.83]],"ltp":2.06,"tv":83.79,"id":72857114},{"batb":[[0,1.81,10],[1,1.8,54.6],[2,1.75,9.02]],"ltp":1.95,"tv":96.05,"id":72857117}]}]}
{"op":"mcm","clk":"11886790391","pt":1724119482699,"mc":[{"id":"1.232019056","rc":[{"batb":[[0,1.96,8.05],[1,1.8,129.83],[2,1.52,15]],"ltp":2.06,"tv":83.79,"id":72857114},{"batb":[[0,1.8,54.6],[1,1.75,9.02],[2,1.62,8.54]],"ltp":1.95,"tv":96.05,"id":72857117}]}]}
{"op":"mcm","clk":"11886790484","pt":1724119484912,"mc":[{"id":"1.232019056","rc":[{"batb":[[0,1.97,10],[1,1.96,8.05],[2,1.8,129.83]],"ltp":2.06,"tv":83.79,"id":72857114},{"batb":[[0,1.81,10],[1,1.8,54.6],[2,1.75,9.02]],"ltp":1.95,"tv":96.05,"id":72857117}]}]}
{"op":"mcm","clk":"11886790614","pt":1724119488199,"mc":[{"id":"1.232019056","rc":[{"batb":[[0,1.96,8.05],[1,1.8,129.83],[2,1.52,15]],"ltp":2.06,"tv":83.79,"id":72857114},{"batb":[[0,1.8,54.6],[1,1.75,9.02],[2,1.62,8.54]],"ltp":1.95,"tv":96.05,"id":72857117}]}]}
{"op":"mcm","clk":"11886790696","pt":1724119490971,"mc":[{"id":"1.232019056","rc":[{"batb":[[0,1.97,10],[1,1.96,8.05],[2,1.8,129.83]],"ltp":2.06,"tv":83.79,"id":72857114},{"batb":[[0,1.81,10],[1,1.8,54.6],[2,1.75,9.02]],"ltp":1.95,"tv":96.05,"id":72857117}]}]}
{"op":"mcm","clk":"11886790818","pt":1724119494202,"mc":[{"id":"1.232019056","rc":[{"batb":[[0,1.96,8.05],[1,1.8,129.83],[2,1.52,15]],"ltp":2.06,"tv":83.79,"id":72857114},{"batb":[[0,1.8,54.6],[1,1.75,9.02],[2,1.62,8.54]],"ltp":1.95,"tv":96.05,"id":72857117}]}]}
{"op":"mcm","clk":"11886790927","pt":1724119496783,"mc":[{"id":"1.232019056","rc":[{"batb":[[0,1.97,10],[1,1.96,8.05],[2,1.8,129.83]],"ltp":2.06,"tv":83.79,"id":72857114},{"batb":[[0,1.81,10],[1,1.8,54.6],[2,1.75,9.02]],"ltp":1.95,"tv":96.05,"id":72857117}]}]}
{"op":"mcm","clk":"11886791075","pt":1724119500222,"mc":[{"id":"1.232019056","rc":[{"batb":[[0,1.96,8.05],[1,1.8,129.83],[2,1.52,15]],"ltp":2.06,"tv":83.79,"id":72857114},{"batb":[[0,1.8,54.6],[1,1.75,9.02],[2,1.62,8.54]],"ltp":1.95,"tv":96.05,"id":72857117}]}]}
{"op":"mcm","clk":"11886791175","pt":1724119502391,"mc":[{"id":"1.232019056","rc":[{"batb":[[0,1.97,10],[1,1.96,8.05],[2,1.8,129.83]],"ltp":2.06,"tv":83.79,"id":72857114},{"batb":[[0,1.81,10],[1,1.8,54.6],[2,1.75,9.02]],"ltp":1.95,"tv":96.05,"id":72857117}]}]}
{"op":"mcm","clk":"11886791323","pt":1724119505802,"mc":[{"id":"1.232019056","rc":[{"batb":[[0,1.96,8.05],[1,1.8,129.83],[2,1.52,15]],"ltp":2.06,"tv":83.79,"id":72857114},{"batb":[[0,1.8,54.6],[1,1.75,9.02],[2,1.62,8.54]],"ltp":1.95,"tv":96.05,"id":72857117}]}]}
{"op":"mcm","clk":"11886791429","pt":1724119508325,"mc":[{"id":"1.232019056","rc":[{"batb":[[0,1.97,10],[1,1.96,8.05],[2,1.8,129.83]],"ltp":2.06,"tv":83.79,"id":72857114},{"batb":[[0,1.81,10],[1,1.8,54.6],[2,1.75,9.02]],"ltp":1.95,"tv":96.05,"id":72857117}]}]}
{"op":"mcm","clk":"11886791546","pt":1724119511612,"mc":[{"id":"1.232019056","rc":[{"batb":[[0,1.96,8.05],[1,1.8,129.83],[2,1.52,15]],"ltp":2.06,"tv":83.79,"id":72857114},{"batb":[[0,1.8,54.6],[1,1.75,9.02],[2,1.62,8.54]],"ltp":1.95,"tv":96.05,"id":72857117}]}]}
{"op":"mcm","clk":"11886791640","pt":1724119514124,"mc":[{"id":"1.232019056","rc":[{"batb":[[0,1.97,10],[1,1.96,8.05],[2,1.8,129.83]],"ltp":2.06,"tv":83.79,"id":72857114},{"batb":[[0,1.81,10],[1,1.8,54.6],[2,1.75,9.02]],"ltp":1.95,"tv":96.05,"id":72857117}]}]}
{"op":"mcm","clk":"11886791798","pt":1724119517311,"mc":[{"id":"1.232019056","rc":[{"batb":[[0,1.96,8.05],[1,1.8,129.83],[2,1.52,15]],"ltp":2.06,"tv":83.79,"id":72857114},{"batb":[[0,1.8,54.6],[1,1.75,9.02],[2,1.62,8.54]],"ltp":1.95,"tv":96.05,"id":72857117}]}]}
{"op":"mcm","clk":"11886791891","pt":1724119519850,"mc":[{"id":"1.232019056","rc":[{"batb":[[0,1.97,10],[1,1.96,8.05],[2,1.8,129.83]],"ltp":2.06,"tv":83.79,"id":72857114},{"batb":[[0,1.81,10],[1,1.8,54.6],[2,1.75,9.02]],"ltp":1.95,"tv":96.05,"id":72857117}]}]}
{"op":"mcm","clk":"11886792013","pt":1724119523136,"mc":[{"id":"1.232019056","rc":[{"batb":[[0,1.96,8.05],[1,1.8,129.83],[2,1.52,15]],"ltp":2.06,"tv":83.79,"id":72857114},{"batb":[[0,1.8,54.6],[1,1.75,9.02],[2,1.62,8.54]],"ltp":1.95,"tv":96.05,"id":72857117}]}]}
{"op":"mcm","clk":"11886792100","pt":1724119525645,"mc":[{"id":"1.232019056","rc":[{"batb":[[0,1.97,10],[1,1.96,8.05],[2,1.8,129.83]],"ltp":2.06,"tv":83.79,"id":72857114},{"batb":[[0,1.81,10],[1,1.8,54.6],[2,1.75,9.02]],"ltp":1.95,"tv":96.05,"id":72857117}]}]}
{"op":"mcm","clk":"11886792193","pt":1724119528844,"mc":[{"id":"1.232019056","rc":[{"batb":[[0,1.96,8.05],[1,1.8,129.83],[2,1.52,15]],"ltp":2.06,"tv":83.79,"id":72857114},{"batb":[[0,1.8,54.6],[1,1.75,9.02],[2,1.62,8.54]],"ltp":1.95,"tv":96.05,"id":72857117}]}]}
{"op":"mcm","clk":"11886792286","pt":1724119531660,"mc":[{"id":"1.232019056","rc":[{"batb":[[0,1.97,10],[1,1.96,8.05],[2,1.8,129.83]],"ltp":2.06,"tv":83.79,"id":72857114},{"batb":[[0,1.81,10],[1,1.8,54.6],[2,1.75,9.02]],"ltp":1.95,"tv":96.05,"id":72857117}]}]}
{"op":"mcm","clk":"11886792375","pt":1724119535057,"mc":[{"id":"1.232019056","rc":[{"batb":[[0,1.96,8.05],[1,1.8,129.83],[2,1.52,15]],"ltp":2.06,"tv":83.79,"id":72857114},{"batb":[[0,1.8,54.6],[1,1.75,9.02],[2,1.62,8.54]],"ltp":1.95,"tv":96.05,"id":72857117}]}]}
{"op":"mcm","clk":"11886792459","pt":1724119537468,"mc":[{"id":"1.232019056","rc":[{"batb":[[0,1.97,10],[1,1.96,8.05],[2,1.8,129.83]],"ltp":2.06,"tv":83.79,"id":72857114},{"batb":[[0,1.81,10],[1,1.8,54.6],[2,1.75,9.02]],"ltp":1.95,"tv":96.05,"id":72857117}]}]}
{"op":"mcm","clk":"11886792556","pt":1724119540698,"mc":[{"id":"1.232019056","rc":[{"batb":[[0,1.96,8.05],[1,1.8,129.83],[2,1.52,15]],"ltp":2.06,"tv":83.79,"id":72857114},{"batb":[[0,1.8,54.6],[1,1.75,9.02],[2,1.62,8.54]],"ltp":1.95,"tv":96.05,"id":72857117}]}]}
{"op":"mcm","clk":"11886792639","pt":1724119543107,"mc":[{"id":"1.232019056","rc":[{"batb":[[0,1.97,10],[1,1.96,8.05],[2,1.8,129.83]],"ltp":2.06,"tv":83.79,"id":72857114},{"batb":[[0,1.81,10],[1,1.8,54.6],[2,1.75,9.02]],"ltp":1.95,"tv":96.05,"id":72857117}]}]}
{"op":"mcm","clk":"11886792783","pt":1724119547106,"mc":[{"id":"1.232019056","rc":[{"batb":[[0,1.96,8.05],[1,1.8,129.83],[2,1.52,15]],"ltp":2.06,"tv":83.79,"id":72857114},{"batb":[[0,1.8,54.6],[1,1.75,9.02],[2,1.62,8.54]],"ltp":1.95,"tv":96.05,"id":72857117}]}]}
{"op":"mcm","clk":"11886792881","pt":1724119550548,"mc":[{"id":"1.232019056","rc":[{"batb":[[0,1.97,10],[1,1.96,8.05],[2,1.8,129.83]],"ltp":2.06,"tv":83.79,"id":72857114},{"batb":[[0,1.81,10],[1,1.8,54.6],[2,1.75,9.02]],"ltp":1.95,"tv":96.05,"id":72857117}]}]}
{"op":"mcm","clk":"11886792971","pt":1724119553847,"mc":[{"id":"1.232019056","rc":[{"batb":[[0,1.96,8.05],[1,1.8,129.83],[2,1.52,15]],"ltp":2.06,"tv":83.79,"id":72857114},{"batb":[[0,1.8,54.6],[1,1.75,9.02],[2,1.62,8.54]],"ltp":1.95,"tv":96.05,"id":72857117}]}]}
{"op":"mcm","clk":"11886793049","pt":1724119556616,"mc":[{"id":"1.232019056","rc":[{"batb":[[0,1.97,10],[1,1.96,8.05],[2,1.8,129.83]],"ltp":2.06,"tv":83.79,"id":72857114},{"batb":[[0,1.81,10],[1,1.8,54.6],[2,1.75,9.02]],"ltp":1.95,"tv":96.05,"id":72857117}]}]}
{"op":"mcm","clk":"11886793154","pt":1724119560052,"mc":[{"id":"1.232019056","rc":[{"batb":[[0,1.96,8.05],[1,1.8,129.83],[2,1.52,15]],"ltp":2.06,"tv":83.79,"id":72857114},{"batb":[[0,1.8,54.6],[1,1.75,9.02],[2,1.62,8.54]],"ltp":1.95,"tv":96.05,"id":72857117}]}]}
{"op":"mcm","clk":"11886793235","pt":1724119562626,"mc":[{"id":"1.232019056","rc":[{"batb":[[0,1.97,10],[1,1.96,8.05],[2,1.8,129.83]],"ltp":2.06,"tv":83.79,"id":72857114},{"batb":[[0,1.81,10],[1,1.8,54.6],[2,1.75,9.02]],"ltp":1.95,"tv":96.05,"id":72857117}]}]}
{"op":"mcm","clk":"11886793326","pt":1724119565960,"mc":[{"id":"1.232019056","rc":[{"batb":[[0,1.96,8.05],[1,1.8,129.83],[2,1.52,15]],"ltp":2.06,"tv":83.79,"id":72857114},{"batb":[[0,1.8,54.6],[1,1.75,9.02],[2,1.62,8.54]],"ltp":1.95,"tv":96.05,"id":72857117}]}]}
{"op":"mcm","clk":"11886793380","pt":1724119568220,"mc":[{"id":"1.232019056","rc":[{"batb":[[0,1.97,10],[1,1.96,8.05],[2,1.8,129.83]],"ltp":2.06,"tv":83.79,"id":72857114},{"batb":[[0,1.81,10],[1,1.8,54.6],[2,1.75,9.02]],"ltp":1.95,"tv":96.05,"id":72857117}]}]}
{"op":"mcm","clk":"11886793494","pt":1724119571456,"mc":[{"id":"1.232019056","rc":[{"batb":[[0,1.96,8.05],[1,1.8,129.83],[2,1.52,15]],"ltp":2.06,"tv":83.79,"id":72857114},{"batb":[[0,1.8,54.6],[1,1.75,9.02],[2,1.62,8.54]],"ltp":1.95,"tv":96.05,"id":72857117}]}]}
{"op":"mcm","clk":"11886793571","pt":1724119573765,"mc":[{"id":"1.232019056","rc":[{"batb":[[0,1.97,10],[1,1.96,8.05],[2,1.8,129.83]],"ltp":2.06,"tv":83.79,"id":72857114},{"batb":[[0,1.81,10],[1,1.8,54.6],[2,1.75,9.02]],"ltp":1.95,"tv":96.05,"id":72857117}]}]}
{"op":"mcm","clk":"11886793667","pt":1724119577047,"mc":[{"id":"1.232019056","rc":[{"batb":[[0,1.96,8.05],[1,1.8,129.83],[2,1.52,15]],"ltp":2.06,"tv":83.79,"id":72857114},{"batb":[[0,1.8,54.6],[1,1.75,9.02],[2,1.62,8.54]],"ltp":1.95,"tv":96.05,"id":72857117}]}]}
{"op":"mcm","clk":"11886793774","pt":1724119579353,"mc":[{"id":"1.232019056","rc":[{"batb":[[0,1.97,10],[1,1.96,8.05],[2,1.8,129.83]],"ltp":2.06,"tv":83.79,"id":72857114},{"batb":[[0,1.81,10],[1,1.8,54.6],[2,1.75,9.02]],"ltp":1.95,"tv":96.05,"id":72857117}]}]}
{"op":"mcm","clk":"11886793947","pt":1724119582650,"mc":[{"id":"1.232019056","rc":[{"batb":[[0,1.96,8.05],[1,1.8,129.83],[2,1.52,15]],"ltp":2.06,"tv":83.79,"id":72857114},{"batb":[[0,1.8,54.6],[1,1.75,9.02],[2,1.62,8.54]],"ltp":1.95,"tv":96.05,"id":72857117}]}]}
{"op":"mcm","clk":"11886794027","pt":1724119585058,"mc":[{"id":"1.232019056","rc":[{"batb":[[0,1.97,10],[1,1.96,8.05],[2,1.8,129.83]],"ltp":2.06,"tv":83.79,"id":72857114},{"batb":[[0,1.81,10],[1,1.8,54.6],[2,1.75,9.02]],"ltp":1.95,"tv":96.05,"id":72857117}]}]}
{"op":"mcm","clk":"11886794116","pt":1724119588385,"mc":[{"id":"1.232019056","rc":[{"batb":[[0,1.96,8.05],[1,1.8,129.83],[2,1.52,15]],"ltp":2.06,"tv":83.79,"id":72857114},{"batb":[[0,1.8,54.6],[1,1.75,9.02],[2,1.62,8.54]],"ltp":1.95,"tv":96.05,"id":72857117}]}]}
{"op":"mcm","clk":"11886794170","pt":1724119590548,"mc":[{"id":"1.232019056","rc":[{"batb":[[0,1.97,10],[1,1.96,8.05],[2,1.8,129.83]],"ltp":2.06,"tv":83.79,"id":72857114},{"batb":[[0,1.81,10],[1,1.8,54.6],[2,1.75,9.02]],"ltp":1.95,"tv":96.05,"id":72857117}]}]}
{"op":"mcm","clk":"11886794265","pt":1724119593880,"mc":[{"id":"1.232019056","rc":[{"batb":[[0,1.96,8.05],[1,1.8,129.83],[2,1.52,15]],"ltp":2.06,"tv":83.79,"id":72857114},{"batb":[[0,1.8,54.6],[1,1.75,9.02],[2,1.62,8.54]],"ltp":1.95,"tv":96.05,"id":72857117}]}]}
{"op":"mcm","clk":"11886794332","pt":1724119596289,"mc":[{"id":"1.232019056","rc":[{"batb":[[0,1.97,10],[1,1.96,8.05],[2,1.8,129.83]],"ltp":2.06,"tv":83.79,"id":72857114},{"batb":[[0,1.81,10],[1,1.8,54.6],[2,1.75,9.02]],"ltp":1.95,"tv":96.05,"id":72857117}]}]}
{"op":"mcm","clk":"11886794429","pt":1724119599581,"mc":[{"id":"1.232019056","rc":[{"batb":[[0,1.96,8.05],[1,1.8,129.83],[2,1.52,15]],"ltp":2.06,"tv":83.79,"id":72857114},{"batb":[[0,1.8,54.6],[1,1.75,9.02],[2,1.62,8.54]],"ltp":1.95,"tv":96.05,"id":72857117}]}]}
{"op":"mcm","clk":"11886794503","pt":1724119601899,"mc":[{"id":"1.232019056","rc":[{"batb":[[0,1.97,10],[1,1.96,8.05],[2,1.8,129.83]],"ltp":2.06,"tv":83.79,"id":72857114},{"batb":[[0,1.81,10],[1,1.8,54.6],[2,1.75,9.02]],"ltp":1.95,"tv":96.05,"id":72857117}]}]}
{"op":"mcm","clk":"11886794624","pt":1724119605065,"mc":[{"id":"1.232019056","rc":[{"batb":[[0,1.96,8.05],[1,1.8,129.83],[2,1.52,15]],"ltp":2.06,"tv":83.79,"id":72857114},{"batb":[[0,1.8,54.6],[1,1.75,9.02],[2,1.62,8.54]],"ltp":1.95,"tv":96.05,"id":72857117}]}]}
{"op":"mcm","clk":"11886794710","pt":1724119607392,"mc":[{"id":"1.232019056","rc":[{"batb":[[0,1.97,10],[1,1.96,8.05],[2,1.8,129.83]],"ltp":2.06,"tv":83.79,"id":72857114},{"batb":[[0,1.81,10],[1,1.8,54.6],[2,1.75,9.02]],"ltp":1.95,"tv":96.05,"id":72857117}]}]}
{"op":"mcm","clk":"11886794805","pt":1724119610573,"mc":[{"id":"1.232019056","rc":[{"batb":[[0,1.96,8.05],[1,1.8,129.83],[2,1.52,15]],"ltp":2.06,"tv":83.79,"id":72857114},{"batb":[[0,1.8,54.6],[1,1.75,9.02],[2,1.62,8.54]],"ltp":1.95,"tv":96.05,"id":72857117}]}]}
{"op":"mcm","clk":"11886794909","pt":1724119613705,"mc":[{"id":"1.232019056","rc":[{"batb":[[0,1.97,10],[1,1.96,8.05],[2,1.8,129.83]],"ltp":2.06,"tv":83.79,"id":72857114},{"batb":[[0,1.81,10],[1,1.8,54.6],[2,1.75,9.02]],"ltp":1.95,"tv":96.05,"id":72857117}]}]}
{"op":"mcm","clk":"11886795024","pt":1724119617103,"mc":[{"id":"1.232019056","rc":[{"batb":[[0,1.96,8.05],[1,1.8,129.83],[2,1.52,15]],"ltp":2.06,"tv":83.79,"id":72857114},{"batb":[[0,1.8,54.6],[1,1.75,9.02],[2,1.62,8.54]],"ltp":1.95,"tv":96.05,"id":72857117}]}]}
{"op":"mcm","clk":"11886795095","pt":1724119619774,"mc":[{"id":"1.232019056","rc":[{"batb":[[0,1.97,10],[1,1.96,8.05],[2,1.8,129.83]],"ltp":2.06,"tv":83.79,"id":72857114},{"batb":[[0,1.81,10],[1,1.8,54.6],[2,1.75,9.02]],"ltp":1.95,"tv":96.05,"id":72857117}]}]}
{"op":"mcm","clk":"11886795240","pt":1724119623088,"mc":[{"id":"1.232019056","rc":[{"batb":[[0,1.96,8.05],[1,1.8,129.83],[2,1.52,15]],"ltp":2.06,"tv":83.79,"id":72857114},{"batb":[[0,1.8,54.6],[1,1.75,9.02],[2,1.62,8.54]],"ltp":1.95,"tv":96.05,"id":72857117}]}]}
{"op":"mcm","clk":"11886795390","pt":1724119626484,"mc":[{"id":"1.232019056","rc":[{"batb":[[0,1.97,10],[1,1.96,8.05],[2,1.8,129.83]],"ltp":2.06,"tv":83.79,"id":72857114},{"batb":[[0,1.81,10],[1,1.8,54.6],[2,1.75,9.02]],"ltp":1.95,"tv":96.05,"id":72857117}]}]}
{"op":"mcm","clk":"11886795529","pt":1724119629727,"mc":[{"id":"1.232019056","rc":[{"batb":[[0,1.96,8.05],[1,1.8,129.83],[2,1.52,15]],"ltp":2.06,"tv":83.79,"id":72857114},{"batb":[[0,1.8,54.6],[1,1.75,9.02],[2,1.62,8.54]],"ltp":1.95,"tv":96.05,"id":72857117}]}]}
{"op":"mcm","clk":"11886795639","pt":1724119632500,"mc":[{"id":"1.232019056","rc":[{"batb":[[0,1.97,10],[1,1.96,8.05],[2,1.8,129.83]],"ltp":2.06,"tv":83.79,"id":72857114},{"batb":[[0,1.81,10],[1,1.8,54.6],[2,1.75,9.02]],"ltp":1.95,"tv":96.05,"id":72857117}]}]}
{"op":"mcm","clk":"11886795735","pt":1724119635793,"mc":[{"id":"1.232019056","rc":[{"batb":[[0,1.96,8.05],[1,1.8,129.83],[2,1.52,15]],"ltp":2.06,"tv":83.79,"id":72857114},{"batb":[[0,1.8,54.6],[1,1.75,9.02],[2,1.62,8.54]],"ltp":1.95,"tv":96.05,"id":72857117}]}]}
{"op":"mcm","clk":"11886795822","pt":1724119638206,"mc":[{"id":"1.232019056","rc":[{"batb":[[0,1.97,10],[1,1.96,8.05],[2,1.8,129.83]],"ltp":2.06,"tv":83.79,"id":72857114},{"batb":[[0,1.81,10],[1,1.8,54.6],[2,1.75,9.02]],"ltp":1.95,"tv":96.05,"id":72857117}]}]}
{"op":"mcm","clk":"11886795933","pt":1724119641644,"mc":[{"id":"1.232019056","rc":[{"batb":[[0,1.96,8.05],[1,1.8,129.83],[2,1.52,15]],"ltp":2.06,"tv":83.79,"id":72857114},{"batb":[[0,1.8,54.6],[1,1.75,9.02],[2,1.62,8.54]],"ltp":1.95,"tv":96.05,"id":72857117}]}]}
{"op":"mcm","clk":"11886796022","pt":1724119644112,"mc":[{"id":"1.232019056","rc":[{"batb":[[0,1.97,10],[1,1.96,8.05],[2,1.8,129.83]],"ltp":2.06,"tv":83.79,"id":72857114},{"batb":[[0,1.81,10],[1,1.8,54.6],[2,1.75,9.02]],"ltp":1.95,"tv":96.05,"id":72857117}]}]}
{"op":"mcm","clk":"11886796141","pt":1724119647519,"mc":[{"id":"1.232019056","rc":[{"batb":[[0,1.96,8.05],[1,1.8,129.83],[2,1.52,15]],"ltp":2.06,"tv":83.79,"id":72857114},{"batb":[[0,1.8,54.6],[1,1.75,9.02],[2,1.62,8.54]],"ltp":1.95,"tv":96.05,"id":72857117}]}]}
{"op":"mcm","clk":"11886796237","pt":1724119650146,"mc":[{"id":"1.232019056","rc":[{"batb":[[0,1.97,10],[1,1.96,8.05],[2,1.8,129.83]],"ltp":2.06,"tv":83.79,"id":72857114},{"batb":[[0,1.81,10],[1,1.8,54.6],[2,1.75,9.02]],"ltp":1.95,"tv":96.05,"id":72857117}]}]}
{"op":"mcm","clk":"11886796338","pt":1724119653547,"mc":[{"id":"1.232019056","rc":[{"batb":[[0,1.96,8.05],[1,1.8,129.83],[2,1.52,15]],"ltp":2.06,"tv":83.79,"id":72857114},{"batb":[[0,1.8,54.6],[1,1.75,9.02],[2,1.62,8.54]],"ltp":1.95,"tv":96.05,"id":72857117}]}]}
{"op":"mcm","clk":"11886796420","pt":1724119656014,"mc":[{"id":"1.232019056","rc":[{"batb":[[0,1.97,10],[1,1.96,8.05],[2,1.8,129.83]],"ltp":2.06,"tv":83.79,"id":72857114},{"batb":[[0,1.81,10],[1,1.8,54.6],[2,1.75,9.02]],"ltp":1.95,"tv":96.05,"id":72857117}]}]}
{"op":"mcm","clk":"11886796522","pt":1724119659251,"mc":[{"id":"1.232019056","rc":[{"batb":[[0,1.96,8.05],[1,1.8,129.83],[2,1.52,15]],"ltp":2.06,"tv":83.79,"id":72857114},{"batb":[[0,1.8,54.6],[1,1.75,9.02],[2,1.62,8.54]],"ltp":1.95,"tv":96.05,"id":72857117}]}]}
{"op":"mcm","clk":"11886796611","pt":1724119661627,"mc":[{"id":"1.232019056","rc":[{"batb":[[0,1.97,10],[1,1.96,8.05],[2,1.8,129.83]],"ltp":2.06,"tv":83.79,"id":72857114},{"batb":[[0,1.81,10],[1,1.8,54.6],[2,1.75,9.02]],"ltp":1.95,"tv":96.05,"id":72857117}]}]}
{"op":"mcm","clk":"11886796706","pt":1724119664867,"mc":[{"id":"1.232019056","rc":[{"batb":[[0,1.96,8.05],[1,1.8,129.83],[2,1.52,15]],"ltp":2.06,"tv":83.79,"id":72857114},{"batb":[[0,1.8,54.6],[1,1.75,9.02],[2,1.62,8.54]],"ltp":1.95,"tv":96.05,"id":72857117}]}]}
{"op":"mcm","clk":"11886796781","pt":1724119667230,"mc":[{"id":"1.232019056","rc":[{"batb":[[0,1.97,10],[1,1.96,8.05],[2,1.8,129.83]],"ltp":2.06,"tv":83.79,"id":72857114},{"batb":[[0,1.81,10],[1,1.8,54.6],[2,1.75,9.02]],"ltp":1.95,"tv":96.05,"id":72857117}]}]}
{"op":"mcm","clk":"11886796878","pt":1724119670676,"mc":[{"id":"1.232019056","rc":[{"batb":[[0,1.96,8.05],[1,1.8,129.83],[2,1.52,15]],"ltp":2.06,"tv":83.79,"id":72857114},{"batb":[[0,1.8,54.6],[1,1.75,9.02],[2,1.62,8.54]],"ltp":1.95,"tv":96.05,"id":72857117}]}]}
{"op":"mcm","clk":"11886796956","pt":1724119672939,"mc":[{"id":"1.232019056","rc":[{"batb":[[0,1.97,10],[1,1.96,8.05],[2,1.8,129.83]],"ltp":2.06,"tv":83.79,"id":72857114},{"batb":[[0,1.81,10],[1,1.8,54.6],[2,1.75,9.02]],"ltp":1.95,"tv":96.05,"id":72857117}]}]}
{"op":"mcm","clk":"11886797086","pt":1724119676139,"mc":[{"id":"1.232019056","rc":[{"batb":[[0,1.96,8.05],[1,1.8,129.83],[2,1.52,15]],"ltp":2.06,"tv":83.79,"id":72857114},{"batb":[[0,1.8,54.6],[1,1.75,9.02],[2,1.62,8.54]],"ltp":1.95,"tv":96.05,"id":72857117}]}]}
{"op":"mcm","clk":"11886797199","pt":1724119678455,"mc":[{"id":"1.232019056","rc":[{"batb":[[0,1.97,10],[1,1.96,8.05],[2,1.8,129.83]],"ltp":2.06,"tv":83.79,"id":72857114},{"batb":[[0,1.81,10],[1,1.8,54.6],[2,1.75,9.02]],"ltp":1.95,"tv":96.05,"id":72857117}]}]}
{"op":"mcm","clk":"11886797304","pt":1724119681855,"mc":[{"id":"1.232019056","rc":[{"batb":[[0,1.96,8.05],[1,1.8,129.83],[2,1.52,15]],"ltp":2.06,"tv":83.79,"id":72857114},{"batb":[[0,1.8,54.6],[1,1.75,9.02],[2,1.62,8.54]],"ltp":1.95,"tv":96.05,"id":72857117}]}]}
{"op":"mcm","clk":"11886797389","pt":1724119684181,"mc":[{"id":"1.232019056","rc":[{"batb":[[0,1.97,10],[1,1.96,8.05],[2,1.8,129.83]],"ltp":2.06,"tv":83.79,"id":72857114},{"batb":[[0,1.81,10],[1,1.8,54.6],[2,1.75,9.02]],"ltp":1.95,"tv":96.05,"id":72857117}]}]}
{"op":"mcm","clk":"11886797526","pt":1724119687605,"mc":[{"id":"1.232019056","rc":[{"batb":[[0,1.96,8.05],[1,1.8,129.83],[2,1.52,15]],"ltp":2.06,"tv":83.79,"id":72857114},{"batb":[[0,1.8,54.6],[1,1.75,9.02],[2,1.62,8.54]],"ltp":1.95,"tv":96.05,"id":72857117}]}]}
{"op":"mcm","clk":"11886797639","pt":1724119690807,"mc":[{"id":"1.232019056","rc":[{"batb":[[0,1.97,10],[1,1.96,8.05],[2,1.8,129.83]],"ltp":2.06,"tv":83.79,"id":72857114},{"batb":[[0,1.81,10],[1,1.8,54.6],[2,1.75,9.02]],"ltp":1.95,"tv":96.05,"id":72857117}]}]}
{"op":"mcm","clk":"11886797748","pt":1724119694112,"mc":[{"id":"1.232019056","rc":[{"batb":[[0,1.96,8.05],[1,1.8,129.83],[2,1.52,15]],"ltp":2.06,"tv":83.79,"id":72857114},{"batb":[[0,1.8,54.6],[1,1.75,9.02],[2,1.62,8.54]],"ltp":1.95,"tv":96.05,"id":72857117}]}]}
{"op":"mcm","clk":"11886797843","pt":1724119696591,"mc":[{"id":"1.232019056","rc":[{"batb":[[0,1.97,10],[1,1.96,8.05],[2,1.8,129.83]],"ltp":2.06,"tv":83.79,"id":72857114},{"batb":[[0,1.81,10],[1,1.8,54.6],[2,1.75,9.02]],"ltp":1.95,"tv":96.05,"id":72857117}]}]}
{"op":"mcm","clk":"11886797957","pt":1724119699787,"mc":[{"id":"1.232019056","rc":[{"batb":[[0,1.96,8.05],[1,1.8,129.83],[2,1.52,15]],"ltp":2.06,"tv":83.79,"id":72857114},{"batb":[[0,1.8,54.6],[1,1.75,9.02],[2,1.62,8.54]],"ltp":1.95,"tv":96.05,"id":72857117}]}]}
{"op":"mcm","clk":"11886798062","pt":1724119702513,"mc":[{"id":"1.232019056","rc":[{"batb":[[0,1.97,10],[1,1.96,8.05],[2,1.8,129.83]],"ltp":2.06,"tv":83.79,"id":72857114},{"batb":[[0,1.81,10],[1,1.8,54.6],[2,1.75,9.02]],"ltp":1.95,"tv":96.05,"id":72857117}]}]}
{"op":"mcm","clk":"11886798159","pt":1724119705594,"mc":[{"id":"1.232019056","rc":[{"batb":[[0,1.96,8.05],[1,1.8,129.83],[2,1.52,15]],"ltp":2.06,"tv":83.79,"id":72857114},{"batb":[[0,1.8,54.6],[1,1.75,9.02],[2,1.62,8.54]],"ltp":1.95,"tv":96.05,"id":72857117}]}]}
{"op":"mcm","clk":"11886798261","pt":1724119708728,"mc":[{"id":"1.232019056","rc":[{"batb":[[0,1.97,10],[1,1.96,8.05],[2,1.8,129.83]],"ltp":2.06,"tv":83.79,"id":72857114},{"batb":[[0,1.81,10],[1,1.8,54.6],[2,1.75,9.02]],"ltp":1.95,"tv":96.05,"id":72857117}]}]}
{"op":"mcm","clk":"11886798398","pt":1724119712113,"mc":[{"id":"1.232019056","rc":[{"batb":[[0,1.96,8.05],[1,1.8,129.83],[2,1.52,15]],"ltp":2.06,"tv":83.79,"id":72857114},{"batb":[[0,1.8,54.6],[1,1.75,9.02],[2,1.62,8.54]],"ltp":1.95,"tv":96.05,"id":72857117}]}]}
{"op":"mcm","clk":"11886798526","pt":1724119715104,"mc":[{"id":"1.232019056","rc":[{"batb":[[0,1.97,10],[1,1.96,8.05],[2,1.8,129.83]],"ltp":2.06,"tv":83.79,"id":72857114},{"batb":[[0,1.81,10],[1,1.8,54.6],[2,1.75,9.02]],"ltp":1.95,"tv":96.05,"id":72857117}]}]}
{"op":"mcm","clk":"11886798630","pt":1724119718330,"mc":[{"id":"1.232019056","rc":[{"batb":[[0,1.96,8.05],[1,1.8,129.83],[2,1.52,15]],"ltp":2.06,"tv":83.79,"id":72857114},{"batb":[[0,1.8,54.6],[1,1.75,9.02],[2,1.62,8.54]],"ltp":1.95,"tv":96.05,"id":72857117}]}]}
{"op":"mcm","clk":"11886798754","pt":1724119721830,"mc":[{"id":"1.232019056","rc":[{"batb":[[0,1.97,10],[1,1.96,8.05],[2,1.8,129.83]],"ltp":2.06,"tv":83.79,"id":72857114},{"batb":[[0,1.81,10],[1,1.8,54.6],[2,1.75,9.02]],"ltp":1.95,"tv":96.05,"id":72857117}]}]}
{"op":"mcm","clk":"11886798873","pt":1724119725227,"mc":[{"id":"1.232019056","rc":[{"batb":[[0,1.96,8.05],[1,1.8,129.83],[2,1.52,15]],"ltp":2.06,"tv":83.79,"id":72857114},{"batb":[[0,1.8,54.6],[1,1.75,9.02],[2,1.62,8.54]],"ltp":1.95,"tv":96.05,"id":72857117}]}]}
