{"op":"mcm","clk":"11846534428","pt":1723279942878,"mc":[{"id":"1.231652082","marketDefinition":{"bspMarket":false,"turnInPlayEnabled":true,"persistenceEnabled":true,"marketBaseRate":5.0,"eventId":"33482825","eventTypeId":"4","numberOfWinners":1,"bettingType":"ODDS","marketType":"MATCH_ODDS","marketTime":"2024-08-14T14:30:00.000Z","suspendTime":"2024-08-14T14:30:00.000Z","bspReconciled":false,"complete":true,"inPlay":false,"crossMatching":false,"runnersVoidable":false,"numberOfActiveRunners":2,"betDelay":0,"status":"OPEN","runners":[{"status":"ACTIVE","sortPriority":1,"id":25651861,"name":"North-West Warriors"},{"status":"ACTIVE","sortPriority":2,"id":6847357,"name":"Northern Knights"}],"regulators":["MR_INT"],"countryCode":"GB","discountAllowed":false,"timezone":"GMT","openDate":"2024-08-14T14:30:00.000Z","version":6065055358,"name":"Match Odds","eventName":"North-West Warriors v Northern Knights"},"rc":[{"batb":[[0,1.03,200],[1,1.02,200],[2,1.01,220]],"ltp":0.0,"tv":0.0,"id":6847357},{"batb":[[0,1.03,200],[1,1.02,200],[2,1.01,220]],"ltp":0.0,"tv":0.0,"id":25651861}]}]}
{"op":"mcm","clk":"11846534632","pt":1723279945178,"mc":[{"id":"1.231652082","marketDefinition":{"bspMarket":false,"turnInPlayEnabled":true,"persistenceEnabled":true,"marketBaseRate":5.0,"eventId":"33482825","eventTypeId":"4","numberOfWinners":1,"bettingType":"ODDS","marketType":"MATCH_ODDS","marketTime":"2024-08-14T14:30:00.000Z","suspendTime":"2024-08-14T14:30:00.000Z","bspReconciled":false,"complete":true,"inPlay":false,"crossMatching":false,"runnersVoidable":false,"numberOfActiveRunners":2,"betDelay":0,"status":"OPEN","runners":[{"status":"ACTIVE","sortPriority":1,"id":25651861,"name":"North-West Warriors"},{"status":"ACTIVE","sortPriority":2,"id":6847357,"name":"Northern Knights"}],"regulators":["MR_INT"],"countryCode":"GB","discountAllowed":true,"timezone":"GMT","openDate":"2024-08-14T14:30:00.000Z","version":6065055358,"name":"Match Odds","eventName":"North-West Warriors v Northern Knights"}}]}
{"op":"mcm","clk":"11846801509","pt":1723282292051,"mc":[{"id":"1.231652082","rc":[{"batb":[[2,1.01,480.71]],"ltp":0.0,"tv":0.0,"id":25651861}]}]}
{"op":"mcm","clk":"11846801530","pt":1723282292257,"mc":[{"id":"1.231652082","rc":[{"batb":[[2,1.01,480.71]],"ltp":0.0,"tv":0.0,"id":6847357}]}]}
{"op":"mcm","clk":"11846968384","pt":1723283398399,"mc":[{"id":"1.231652082","rc":[{"batb":[[0,1.3,6.81],[1,1.03,200],[2,1.02,200]],"ltp":0.0,"tv":0.0,"id":25651861}]}]}
{"op":"mcm","clk":"11846969495","pt":1723283406585,"mc":[{"id":"1.231652082","marketDefinition":{"bspMarket":false,"turnInPlayEnabled":true,"persistenceEnabled":true,"marketBaseRate":5.0,"eventId":"33482825","eventTypeId":"4","numberOfWinners":1,"bettingType":"ODDS","marketType":"MATCH_ODDS","marketTime":"2024-08-14T14:30:00.000Z","suspendTime":"2024-08-14T14:30:00.000Z","bspReconciled":false,"complete":true,"inPlay":false,"crossMatching":true,"runnersVoidable":false,"numberOfActiveRunners":2,"betDelay":0,"status":"OPEN","runners":[{"status":"ACTIVE","sortPriority":1,"id":25651861,"name":"North-West Warriors"},{"status":"ACTIVE","sortPriority":2,"id":6847357,"name":"Northern Knights"}],"regulators":["MR_INT"],"countryCode":"GB","discountAllowed":true,"timezone":"GMT","openDate":"2024-08-14T14:30:00.000Z","version":6065055358,"name":"Match Odds","eventName":"North-West Warriors v Northern Knights"}}]}
{"op":"mcm","clk":"11846969921","pt":1723283410315,"mc":[{"id":"1.231652082","rc":[{"batb":[[0,1.32,6.78],[1,1.03,200],[2,1.02,200]],"ltp":0.0,"tv":0.0,"id":6847357}]}]}
{"op":"mcm","clk":"11846972055","pt":1723283429327,"mc":[{"id":"1.231652082","rc":[{"batb":[[0,1.33,6.93],[1,1.3,6.81],[2,1.03,200]],"ltp":0.0,"tv":0.0,"id":25651861}]}]}
{"op":"mcm","clk":"11846973696","pt":1723283443736,"mc":[{"id":"1.231652082","rc":[{"batb":[[0,1.35,7.17],[1,1.32,6.78],[2,1.03,200]],"ltp":0.0,"tv":0.0,"id":6847357}]}]}
{"op":"mcm","clk":"11847203700","pt":1723284997195,"mc":[{"id":"1.231652082","rc":[{"batb":[[0,1.37,14],[1,1.35,7.17],[2,1.32,6.78]],"ltp":0.0,"tv":0.0,"id":6847357},{"batb":[[0,1.35,15],[1,1.33,6.93],[2,1.3,6.81]],"ltp":0.0,"tv":0.0,"id":25651861}]}]}
{"op":"mcm","clk":"11847214743","pt":1723285067753,"mc":[{"id":"1.231652082","rc":[{"batb":[[1,1.3,6.81],[2,1.03,200]],"ltp":0.0,"tv":0.0,"id":25651861}]}]}
{"op":"mcm","clk":"11847215209","pt":1723285070751,"mc":[{"id":"1.231652082","rc":[{"batb":[[1,1.03,200],[2,1.02,200]],"ltp":0.0,"tv":0.0,"id":25651861}]}]}
{"op":"mcm","clk":"11847215667","pt":1723285073750,"mc":[{"id":"1.231652082","rc":[{"batb":[[1,1.32,6.78],[2,1.03,200]],"ltp":0.0,"tv":0.0,"id":6847357}]}]}
{"op":"mcm","clk":"11847216104","pt":1723285076470,"mc":[{"id":"1.231652082","rc":[{"batb":[[1,1.03,200],[2,1.02,200]],"ltp":0.0,"tv":0.0,"id":6847357}]}]}
{"op":"mcm","clk":"11847218359","pt":1723285091385,"mc":[{"id":"1.231652082","rc":[{"batl":[[0,3.5,0.96]],"ltp":0.0,"tv":0.0,"id":25651861}]}]}
{"op":"mcm","clk":"11847220374","pt":1723285104744,"mc":[{"id":"1.231652082","rc":[{"batl":[[0,3.6,0.96]],"ltp":0.0,"tv":0.0,"id":6847357}]}]}
{"op":"mcm","clk":"11854097874","pt":1723321649319,"mc":[{"id":"1.231652082","rc":[{"batb":[[0,1.37,14.55]],"ltp":0.0,"tv":0.0,"id":6847357}]}]}
{"op":"mcm","clk":"11854099363","pt":1723321659334,"mc":[{"id":"1.231652082","rc":[{"batb":[[0,1.35,15.55]],"ltp":0.0,"tv":0.0,"id":25651861}]}]}
{"op":"mcm","clk":"11854147390","pt":1723321988690,"mc":[{"id":"1.231652082","rc":[{"batb":[[0,1.37,14]],"ltp":0.0,"tv":0.0,"id":6847357}]}]}
{"op":"mcm","clk":"11854147962","pt":1723321992413,"mc":[{"id":"1.231652082","rc":[{"batb":[[0,1.35,15]],"ltp":0.0,"tv":0.0,"id":25651861}]}]}
{"op":"mcm","clk":"11854321669","pt":1723323336716,"mc":[{"id":"1.231652082","rc":[{"batb":[[1,1.25,100],[2,1.03,200]],"ltp":0.0,"tv":0.0,"id":6847357},{"batb":[[1,1.25,100],[2,1.03,200]],"ltp":0.0,"tv":0.0,"id":25651861}]}]}
{"op":"mcm","clk":"11854342463","pt":1723323592350,"mc":[{"id":"1.231652082","rc":[{"batb":[[0,1.37,14.55]],"ltp":0.0,"tv":0.0,"id":6847357}]}]}
{"op":"mcm","clk":"11854343252","pt":1723323602331,"mc":[{"id":"1.231652082","rc":[{"batb":[[0,1.35,15.55]],"ltp":0.0,"tv":0.0,"id":25651861}]}]}
{"op":"mcm","clk":"11854947272","pt":1723332411758,"mc":[{"id":"1.231652082","rc":[{"batb":[[0,1.41,14.55]],"ltp":0.0,"tv":0.0,"id":6847357},{"batb":[[0,1.4,15.55]],"ltp":0.0,"tv":0.0,"id":25651861}]}]}
{"op":"mcm","clk":"11856147150","pt":1723350416477,"mc":[{"id":"1.231652082","rc":[{"batb":[[0,1.41,14]],"ltp":0.0,"tv":0.0,"id":6847357},{"batb":[[0,1.4,15]],"ltp":0.0,"tv":0.0,"id":25651861}]}]}
{"op":"mcm","clk":"11856571847","pt":1723358956332,"mc":[{"id":"1.231652082","rc":[{"batb":[[0,1.41,14.55]],"ltp":0.0,"tv":0.0,"id":6847357}]}]}
{"op":"mcm","clk":"11856572268","pt":1723358966339,"mc":[{"id":"1.231652082","rc":[{"batb":[[0,1.4,15.55]],"ltp":0.0,"tv":0.0,"id":25651861}]}]}
{"op":"mcm","clk":"11858084507","pt":1723374127355,"mc":[{"id":"1.231652082","rc":[{"batb":[[0,1.5,28.8],[1,1.41,14],[2,1.25,100]],"ltp":0.0,"tv":0.0,"id":6847357}]}]}
{"op":"mcm","clk":"11858084887","pt":1723374130641,"mc":[{"id":"1.231652082","rc":[{"batb":[[0,1.41,14.55],[1,1.25,100],[2,1.03,200]],"ltp":0.0,"tv":0.0,"id":6847357}]}]}
{"op":"mcm","clk":"11858086440","pt":1723374142659,"mc":[{"id":"1.231652082","rc":[{"batb":[[0,1.5,57.04],[1,1.4,15],[2,1.25,100]],"ltp":0.0,"tv":0.0,"id":25651861}]}]}
{"op":"mcm","clk":"11858087900","pt":1723374154205,"mc":[{"id":"1.231652082","rc":[{"batb":[[0,1.5,57.04],[1,1.41,14],[2,1.25,100]],"ltp":0.0,"tv":0.0,"id":6847357}]}]}
{"op":"mcm","clk":"11858090055","pt":1723374171409,"mc":[{"id":"1.231652082","rc":[{"trd":[[1.5,98.31]],"batb":[[0,1.5,7.89]],"ltp":1.5,"tv":98.31,"id":6847357}],"tv":98.31}]}
{"op":"mcm","clk":"11858090923","pt":1723374178338,"mc":[{"id":"1.231652082","rc":[{"trd":[[1.5,98.31]],"batb":[[0,1.5,7.89]],"ltp":1.5,"tv":98.31,"id":25651861}],"tv":196.62}]}
{"op":"mcm","clk":"11858092715","pt":1723374192442,"mc":[{"id":"1.231652082","rc":[{"batb":[[0,1.5,64.38]],"ltp":1.5,"tv":98.31,"id":6847357}]}]}
{"op":"mcm","clk":"11858094053","pt":1723374203016,"mc":[{"id":"1.231652082","rc":[{"batb":[[0,1.5,64.38]],"ltp":1.5,"tv":98.31,"id":25651861}]}]}
{"op":"mcm","clk":"11858096178","pt":1723374219310,"mc":[{"id":"1.231652082","rc":[{"trd":[[1.5,146.83]],"batb":[[0,1.5,40.13]],"ltp":1.5,"tv":146.83,"id":6847357}],"tv":245.14}]}
{"op":"mcm","clk":"11858097029","pt":1723374225702,"mc":[{"id":"1.231652082","rc":[{"trd":[[1.5,146.83]],"batb":[[0,1.5,40.13]],"ltp":1.5,"tv":146.83,"id":25651861}],"tv":293.66}]}
{"op":"mcm","clk":"11858098203","pt":1723374234335,"mc":[{"id":"1.231652082","rc":[{"trd":[[1.5,171.09]],"batb":[[0,1.5,28]],"ltp":1.5,"tv":171.09,"id":25651861}],"tv":317.92}]}
{"op":"mcm","clk":"11858099267","pt":1723374241722,"mc":[{"id":"1.231652082","rc":[{"trd":[[1.5,171.09]],"batb":[[0,1.5,28]],"ltp":1.5,"tv":171.09,"id":6847357}],"tv":342.18}]}
{"op":"mcm","clk":"11858101261","pt":1723374256346,"mc":[{"id":"1.231652082","rc":[{"trd":[[1.5,183.86]],"batb":[[0,1.5,21.61]],"ltp":1.5,"tv":183.85,"id":25651861}],"tv":354.94}]}
{"op":"mcm","clk":"11858102338","pt":1723374264373,"mc":[{"id":"1.231652082","rc":[{"trd":[[1.5,183.86]],"batb":[[0,1.5,21.61]],"ltp":1.5,"tv":183.85,"id":6847357}],"tv":367.71}]}
{"op":"mcm","clk":"11858103862","pt":1723374276682,"mc":[{"id":"1.231652082","rc":[{"trd":[[1.5,190.24]],"batb":[[0,1.5,18.42]],"ltp":1.5,"tv":190.24,"id":25651861}],"tv":374.1}]}
{"op":"mcm","clk":"11858104715","pt":1723374283395,"mc":[{"id":"1.231652082","rc":[{"trd":[[1.5,190.24]],"batb":[[0,1.5,18.42]],"ltp":1.5,"tv":190.24,"id":6847357}],"tv":380.48}]}
{"op":"mcm","clk":"11858105947","pt":1723374293369,"mc":[{"id":"1.231652082","rc":[{"trd":[[1.5,193.95]],"batb":[[0,1.5,16.57]],"ltp":1.5,"tv":193.94,"id":6847357}],"tv":384.18}]}
{"op":"mcm","clk":"11858107006","pt":1723374301390,"mc":[{"id":"1.231652082","rc":[{"trd":[[1.5,193.95]],"batb":[[0,1.5,16.57]],"ltp":1.5,"tv":193.94,"id":25651861}],"tv":387.89}]}
{"op":"mcm","clk":"11858108745","pt":1723374314312,"mc":[{"id":"1.231652082","rc":[{"batb":[[0,1.4,15],[1,1.25,100],[2,1.03,200]],"ltp":1.5,"tv":193.94,"id":25651861}]}]}
{"op":"mcm","clk":"11858109128","pt":1723374317127,"mc":[{"id":"1.231652082","rc":[{"batb":[[0,1.41,14],[1,1.25,100],[2,1.03,200]],"ltp":1.5,"tv":193.94,"id":6847357}]}]}
{"op":"mcm","clk":"11859015191","pt":1723380977326,"mc":[{"id":"1.231652082","rc":[{"batb":[[0,1.41,14.55]],"ltp":1.5,"tv":193.94,"id":6847357}]}]}
{"op":"mcm","clk":"11859016903","pt":1723380991347,"mc":[{"id":"1.231652082","rc":[{"batb":[[0,1.4,15.55]],"ltp":1.5,"tv":193.94,"id":25651861}]}]}
{"op":"mcm","clk":"11860857991","pt":1723392491586,"mc":[{"id":"1.231652082","rc":[{"batb":[[0,1.42,21.02],[1,1.41,14],[2,1.25,100]],"ltp":1.5,"tv":193.94,"id":6847357},{"batb":[[0,1.41,21.52],[1,1.4,15],[2,1.25,100]],"ltp":1.5,"tv":193.94,"id":25651861}]}]}
{"op":"mcm","clk":"11861165374","pt":1723394292121,"mc":[{"id":"1.231652082","rc":[{"batb":[[0,1.41,14.55],[1,1.25,100],[2,1.03,200]],"ltp":1.5,"tv":193.94,"id":6847357},{"batb":[[0,1.4,15.55],[1,1.25,100],[2,1.03,200]],"ltp":1.5,"tv":193.94,"id":25651861}]}]}
{"op":"mcm","clk":"11861174894","pt":1723394344496,"mc":[{"id":"1.231652082","rc":[{"batb":[[0,1.42,21.02],[1,1.41,14],[2,1.25,100]],"ltp":1.5,"tv":193.94,"id":6847357},{"batb":[[0,1.41,21.52],[1,1.4,15],[2,1.25,100]],"ltp":1.5,"tv":193.94,"id":25651861}]}]}
{"op":"mcm","clk":"11861450660","pt":1723396146087,"mc":[{"id":"1.231652082","rc":[{"batb":[[0,1.41,14.55],[1,1.25,100],[2,1.03,200]],"ltp":1.5,"tv":193.94,"id":6847357},{"batb":[[0,1.4,15.55],[1,1.25,100],[2,1.03,200]],"ltp":1.5,"tv":193.94,"id":25651861}]}]}
{"op":"mcm","clk":"11861456399","pt":1723396178917,"mc":[{"id":"1.231652082","rc":[{"batb":[[0,1.42,21.02],[1,1.41,14],[2,1.25,100]],"ltp":1.5,"tv":193.94,"id":6847357},{"batb":[[0,1.41,21.52],[1,1.4,15],[2,1.25,100]],"ltp":1.5,"tv":193.94,"id":25651861}]}]}
{"op":"mcm","clk":"11861734756","pt":1723397761911,"mc":[{"id":"1.231652082","rc":[{"batb":[[2,1.25,200]],"ltp":1.5,"tv":193.94,"id":6847357},{"batb":[[2,1.25,200]],"ltp":1.5,"tv":193.94,"id":25651861}]}]}
{"op":"mcm","clk":"11861735830","pt":1723397767519,"mc":[{"id":"1.231652082","rc":[{"batb":[[2,1.03,200]],"ltp":1.5,"tv":193.94,"id":6847357},{"batb":[[2,1.03,200]],"ltp":1.5,"tv":193.94,"id":25651861}]}]}
{"op":"mcm","clk":"11861737760","pt":1723397776937,"mc":[{"id":"1.231652082","rc":[{"batb":[[2,1.25,100]],"ltp":1.5,"tv":193.94,"id":6847357},{"batb":[[2,1.25,100]],"ltp":1.5,"tv":193.94,"id":25651861}]}]}
{"op":"mcm","clk":"11861774318","pt":1723397979649,"mc":[{"id":"1.231652082","rc":[{"batb":[[0,1.41,14.55],[1,1.25,100],[2,1.03,200]],"ltp":1.5,"tv":193.94,"id":6847357},{"batb":[[0,1.4,15.55],[1,1.25,100],[2,1.03,200]],"ltp":1.5,"tv":193.94,"id":25651861}]}]}
{"op":"mcm","clk":"11861787319","pt":1723398057469,"mc":[{"id":"1.231652082","rc":[{"batb":[[0,1.42,21.02],[1,1.41,14],[2,1.25,100]],"ltp":1.5,"tv":193.94,"id":6847357},{"batb":[[0,1.41,21.52],[1,1.4,15],[2,1.25,100]],"ltp":1.5,"tv":193.94,"id":25651861}]}]}
{"op":"mcm","clk":"11862070084","pt":1723399858070,"mc":[{"id":"1.231652082","rc":[{"batb":[[0,1.41,14.55],[1,1.25,100],[2,1.03,200]],"ltp":1.5,"tv":193.94,"id":6847357},{"batb":[[0,1.4,15.55],[1,1.25,100],[2,1.03,200]],"ltp":1.5,"tv":193.94,"id":25651861}]}]}
{"op":"mcm","clk":"11862080950","pt":1723399929684,"mc":[{"id":"1.231652082","rc":[{"batb":[[0,1.42,21.02],[1,1.41,14],[2,1.25,100]],"ltp":1.5,"tv":193.94,"id":6847357},{"batb":[[0,1.41,21.52],[1,1.4,15],[2,1.25,100]],"ltp":1.5,"tv":193.94,"id":25651861}]}]}
{"op":"mcm","clk":"11862392349","pt":1723401730091,"mc":[{"id":"1.231652082","rc":[{"batb":[[0,1.41,14.55],[1,1.25,100],[2,1.03,200]],"ltp":1.5,"tv":193.94,"id":6847357},{"batb":[[0,1.4,15.55],[1,1.25,100],[2,1.03,200]],"ltp":1.5,"tv":193.94,"id":25651861}]}]}
{"op":"mcm","clk":"11862395528","pt":1723401746809,"mc":[{"id":"1.231652082","rc":[{"batb":[[0,1.42,21.02],[1,1.41,14],[2,1.25,100]],"ltp":1.5,"tv":193.94,"id":6847357},{"batb":[[0,1.41,21.52],[1,1.4,15],[2,1.25,100]],"ltp":1.5,"tv":193.94,"id":25651861}]}]}
{"op":"mcm","clk":"11862729081","pt":1723403547667,"mc":[{"id":"1.231652082","rc":[{"batb":[[0,1.41,14.55],[1,1.25,100],[2,1.03,200]],"ltp":1.5,"tv":193.94,"id":6847357},{"batb":[[0,1.4,15.55],[1,1.25,100],[2,1.03,200]],"ltp":1.5,"tv":193.94,"id":25651861}]}]}
{"op":"mcm","clk":"11862753948","pt":1723403666642,"mc":[{"id":"1.231652082","rc":[{"batb":[[0,1.42,21.02],[1,1.41,14],[2,1.25,100]],"ltp":1.5,"tv":193.94,"id":6847357},{"batb":[[0,1.41,21.52],[1,1.4,15],[2,1.25,100]],"ltp":1.5,"tv":193.94,"id":25651861}]}]}
{"op":"mcm","clk":"11863137657","pt":1723405467055,"mc":[{"id":"1.231652082","rc":[{"batb":[[0,1.41,14.55],[1,1.25,100],[2,1.03,200]],"ltp":1.5,"tv":193.94,"id":6847357},{"batb":[[0,1.4,15.55],[1,1.25,100],[2,1.03,200]],"ltp":1.5,"tv":193.94,"id":25651861}]}]}
{"op":"mcm","clk":"11863159476","pt":1723405575648,"mc":[{"id":"1.231652082","rc":[{"batb":[[0,1.42,21.02],[1,1.41,14],[2,1.25,100]],"ltp":1.5,"tv":193.94,"id":6847357},{"batb":[[0,1.41,21.52],[1,1.4,15],[2,1.25,100]],"ltp":1.5,"tv":193.94,"id":25651861}]}]}
{"op":"mcm","clk":"11863408551","pt":1723407174792,"mc":[{"id":"1.231652082","rc":[{"batb":[[0,1.42,21.02]],"ltp":1.5,"tv":193.94,"id":6847357},{"batb":[[0,1.41,21.52]],"ltp":1.5,"tv":193.94,"id":25651861}]}]}
{"op":"mcm","clk":"11863448399","pt":1723407376066,"mc":[{"id":"1.231652082","rc":[{"batb":[[0,1.41,14.55],[1,1.25,100],[2,1.03,200]],"ltp":1.5,"tv":193.94,"id":6847357},{"batb":[[0,1.4,15.55],[1,1.25,100],[2,1.03,200]],"ltp":1.5,"tv":193.94,"id":25651861}]}]}
{"op":"mcm","clk":"11863454586","pt":1723407419304,"mc":[{"id":"1.231652082","rc":[{"batb":[[0,1.42,21.02],[1,1.41,14],[2,1.25,100]],"ltp":1.5,"tv":193.94,"id":6847357},{"batb":[[0,1.41,21.52],[1,1.4,15],[2,1.25,100]],"ltp":1.5,"tv":193.94,"id":25651861}]}]}
{"op":"mcm","clk":"11863739677","pt":1723409219868,"mc":[{"id":"1.231652082","rc":[{"batb":[[0,1.41,14.55],[1,1.25,100],[2,1.03,200]],"ltp":1.5,"tv":193.94,"id":6847357},{"batb":[[0,1.4,15.55],[1,1.25,100],[2,1.03,200]],"ltp":1.5,"tv":193.94,"id":25651861}]}]}
{"op":"mcm","clk":"11863751886","pt":1723409298489,"mc":[{"id":"1.231652082","rc":[{"batb":[[0,1.42,21.02],[1,1.41,14],[2,1.25,100]],"ltp":1.5,"tv":193.94,"id":6847357},{"batb":[[0,1.41,21.52],[1,1.4,15],[2,1.25,100]],"ltp":1.5,"tv":193.94,"id":25651861}]}]}
{"op":"mcm","clk":"11863948256","pt":1723411062160,"mc":[{"id":"1.231652082","rc":[{"trd":[[1.5,193.47]],"batb":[[0,1.42,21.01]],"ltp":1.5,"tv":193.46,"id":6847357},{"trd":[[1.5,193.47]],"batb":[[0,1.41,21.51]],"ltp":1.5,"tv":193.46,"id":25651861}],"tv":386.93}]}
{"op":"mcm","clk":"11863952007","pt":1723411098920,"mc":[{"id":"1.231652082","rc":[{"batb":[[0,1.41,14.55],[1,1.25,100],[2,1.03,200]],"ltp":1.5,"tv":193.46,"id":6847357},{"batb":[[0,1.4,15.55],[1,1.25,100],[2,1.03,200]],"ltp":1.5,"tv":193.46,"id":25651861}]}]}
{"op":"mcm","clk":"11863959810","pt":1723411177705,"mc":[{"id":"1.231652082","rc":[{"batb":[[0,1.42,21.01],[1,1.41,14],[2,1.25,100]],"ltp":1.5,"tv":193.46,"id":6847357},{"batb":[[0,1.41,21.51],[1,1.4,15],[2,1.25,100]],"ltp":1.5,"tv":193.46,"id":25651861}]}]}
{"op":"mcm","clk":"11864157574","pt":1723412978067,"mc":[{"id":"1.231652082","rc":[{"batb":[[0,1.41,14.55],[1,1.25,100],[2,1.03,200]],"ltp":1.5,"tv":193.46,"id":6847357},{"batb":[[0,1.4,15.55],[1,1.25,100],[2,1.03,200]],"ltp":1.5,"tv":193.46,"id":25651861}]}]}
{"op":"mcm","clk":"11864166517","pt":1723413070707,"mc":[{"id":"1.231652082","rc":[{"batb":[[0,1.42,21.01],[1,1.41,14],[2,1.25,100]],"ltp":1.5,"tv":193.46,"id":6847357},{"batb":[[0,1.41,21.51],[1,1.4,15],[2,1.25,100]],"ltp":1.5,"tv":193.46,"id":25651861}]}]}
{"op":"mcm","clk":"11864323640","pt":1723414870998,"mc":[{"id":"1.231652082","rc":[{"trd":[[1.5,193.59]],"batb":[[0,1.42,21.03]],"ltp":1.5,"tv":193.59,"id":6847357},{"trd":[[1.5,193.59]],"batb":[[0,1.4,15.55],[1,1.25,100],[2,1.03,200]],"ltp":1.5,"tv":193.59,"id":25651861}],"tv":387.18}]}
{"op":"mcm","clk":"11864323657","pt":1723414871186,"mc":[{"id":"1.231652082","rc":[{"batb":[[0,1.41,14.55],[1,1.25,100],[2,1.03,200]],"ltp":1.5,"tv":193.59,"id":6847357}]}]}
{"op":"mcm","clk":"11864326751","pt":1723414911590,"mc":[{"id":"1.231652082","rc":[{"batb":[[0,1.42,21.03],[1,1.41,14],[2,1.25,100]],"ltp":1.5,"tv":193.59,"id":6847357},{"batb":[[0,1.41,21.53],[1,1.4,15],[2,1.25,100]],"ltp":1.5,"tv":193.59,"id":25651861}]}]}
{"op":"mcm","clk":"11864452370","pt":1723416712063,"mc":[{"id":"1.231652082","rc":[{"batb":[[0,1.41,14.55],[1,1.25,100],[2,1.03,200]],"ltp":1.5,"tv":193.59,"id":6847357},{"batb":[[0,1.4,15.55],[1,1.25,100],[2,1.03,200]],"ltp":1.5,"tv":193.59,"id":25651861}]}]}
{"op":"mcm","clk":"11864459062","pt":1723416805367,"mc":[{"id":"1.231652082","rc":[{"batb":[[0,1.42,21.03],[1,1.41,14],[2,1.25,100]],"ltp":1.5,"tv":193.59,"id":6847357},{"batb":[[0,1.41,21.53],[1,1.4,15],[2,1.25,100]],"ltp":1.5,"tv":193.59,"id":25651861}]}]}
{"op":"mcm","clk":"11864536926","pt":1723417974792,"mc":[{"id":"1.231652082","rc":[{"trd":[[1.5,193.66]],"ltp":1.5,"tv":193.66,"id":6847357},{"trd":[[1.5,193.66]],"batb":[[0,1.41,21.52]],"ltp":1.5,"tv":193.66,"id":25651861}],"tv":387.32}]}
{"op":"mcm","clk":"11864584758","pt":1723418605802,"mc":[{"id":"1.231652082","rc":[{"batb":[[0,1.41,14.55],[1,1.25,100],[2,1.03,200]],"ltp":1.5,"tv":193.66,"id":6847357},{"batb":[[0,1.4,15.55],[1,1.25,100],[2,1.03,200]],"ltp":1.5,"tv":193.66,"id":25651861}]}]}
{"op":"mcm","clk":"11864588605","pt":1723418666443,"mc":[{"id":"1.231652082","rc":[{"batb":[[0,1.42,21.02],[1,1.41,14],[2,1.25,100]],"ltp":1.5,"tv":193.66,"id":6847357},{"batb":[[0,1.41,21.52],[1,1.4,15],[2,1.25,100]],"ltp":1.5,"tv":193.66,"id":25651861}]}]}
{"op":"mcm","clk":"11864689791","pt":1723420466886,"mc":[{"id":"1.231652082","rc":[{"batb":[[0,1.41,14.55],[1,1.25,100],[2,1.03,200]],"ltp":1.5,"tv":193.66,"id":6847357},{"batb":[[0,1.4,15.55],[1,1.25,100],[2,1.03,200]],"ltp":1.5,"tv":193.66,"id":25651861}]}]}
{"op":"mcm","clk":"11864691155","pt":1723420495323,"mc":[{"id":"1.231652082","rc":[{"batb":[[0,1.42,21.02],[1,1.41,14],[2,1.25,100]],"ltp":1.5,"tv":193.66,"id":6847357},{"batb":[[0,1.41,21.52],[1,1.4,15],[2,1.25,100]],"ltp":1.5,"tv":193.66,"id":25651861}]}]}
{"op":"mcm","clk":"11864771052","pt":1723422296122,"mc":[{"id":"1.231652082","rc":[{"trd":[[1.5,193.7]],"batb":[[0,1.41,14.55],[1,1.25,100],[2,1.03,200]],"ltp":1.5,"tv":193.7,"id":6847357},{"trd":[[1.5,193.7]],"batb":[[0,1.41,21.53]],"ltp":1.5,"tv":193.7,"id":25651861}],"tv":387.4}]}
{"op":"mcm","clk":"11864771059","pt":1723422296278,"mc":[{"id":"1.231652082","rc":[{"batb":[[0,1.4,15.55],[1,1.25,100],[2,1.03,200]],"ltp":1.5,"tv":193.7,"id":25651861}]}]}
{"op":"mcm","clk":"11864774510","pt":1723422376658,"mc":[{"id":"1.231652082","rc":[{"batb":[[0,1.42,21.03],[1,1.41,14],[2,1.25,100]],"ltp":1.5,"tv":193.7,"id":6847357},{"batb":[[0,1.41,21.53],[1,1.4,15],[2,1.25,100]],"ltp":1.5,"tv":193.7,"id":25651861}]}]}
{"op":"mcm","clk":"11864853576","pt":1723424177128,"mc":[{"id":"1.231652082","rc":[{"batb":[[0,1.41,14.55],[1,1.25,100],[2,1.03,200]],"ltp":1.5,"tv":193.7,"id":6847357},{"batb":[[0,1.4,15.55],[1,1.25,100],[2,1.03,200]],"ltp":1.5,"tv":193.7,"id":25651861}]}]}
{"op":"mcm","clk":"11864855517","pt":1723424241192,"mc":[{"id":"1.231652082","rc":[{"batb":[[0,1.42,21.03],[1,1.41,14],[2,1.25,100]],"ltp":1.5,"tv":193.7,"id":6847357},{"batb":[[0,1.41,21.53],[1,1.4,15],[2,1.25,100]],"ltp":1.5,"tv":193.7,"id":25651861}]}]}
{"op":"mcm","clk":"11864916711","pt":1723426041662,"mc":[{"id":"1.231652082","rc":[{"trd":[[1.5,193.56]],"batb":[[0,1.41,14.55],[1,1.25,100],[2,1.03,200]],"ltp":1.5,"tv":193.56,"id":6847357},{"trd":[[1.5,193.56]],"batb":[[0,1.4,15.55],[1,1.25,100],[2,1.03,200]],"ltp":1.5,"tv":193.56,"id":25651861}],"tv":387.12}]}
{"op":"mcm","clk":"11864918247","pt":1723426080892,"mc":[{"id":"1.231652082","rc":[{"batb":[[0,1.42,21.02],[1,1.41,14],[2,1.25,100]],"ltp":1.5,"tv":193.56,"id":6847357},{"batb":[[0,1.41,21.52],[1,1.4,15],[2,1.25,100]],"ltp":1.5,"tv":193.56,"id":25651861}]}]}
{"op":"mcm","clk":"11864949917","pt":1723427144149,"mc":[{"id":"1.231652082","rc":[{"batb":[[0,1.42,1.46],[1,1.41,20.98],[2,1.4,15]],"ltp":1.5,"tv":193.56,"id":25651861}]}]}
{"op":"mcm","clk":"11864950282","pt":1723427158163,"mc":[{"id":"1.231652082","rc":[{"batb":[[0,1.43,1.46],[1,1.42,20.48],[2,1.41,14]],"ltp":1.5,"tv":193.56,"id":6847357}]}]}
{"op":"mcm","clk":"11864969593","pt":1723427881481,"mc":[{"id":"1.231652082","rc":[{"batb":[[1,1.41,14],[2,1.25,100]],"ltp":1.5,"tv":193.56,"id":6847357},{"batb":[[1,1.4,15],[2,1.25,100]],"ltp":1.5,"tv":193.56,"id":25651861}]}]}
{"op":"mcm","clk":"11864970189","pt":1723427905816,"mc":[{"id":"1.231652082","rc":[{"batb":[[1,1.42,20.48],[2,1.41,14]],"ltp":1.5,"tv":193.56,"id":6847357},{"batb":[[1,1.41,20.98],[2,1.4,15]],"ltp":1.5,"tv":193.56,"id":25651861}]}]}
{"op":"mcm","clk":"11864992136","pt":1723428774787,"mc":[{"id":"1.231652082","rc":[{"trd":[[1.5,193.54]],"ltp":1.5,"tv":193.53,"id":6847357},{"trd":[[1.5,193.54]],"ltp":1.5,"tv":193.53,"id":25651861}],"tv":387.07}]}
{"op":"mcm","clk":"11865001225","pt":1723428879330,"mc":[{"id":"1.231652082","rc":[{"batb":[[0,1.44,1.46]],"ltp":1.5,"tv":193.53,"id":25651861}]}]}
{"op":"mcm","clk":"11865023139","pt":1723429706108,"mc":[{"id":"1.231652082","rc":[{"batb":[[1,1.4,15],[2,1.25,100]],"ltp":1.5,"tv":193.53,"id":25651861}]}]}
{"op":"mcm","clk":"11865023144","pt":1723429706313,"mc":[{"id":"1.231652082","rc":[{"batb":[[1,1.41,14],[2,1.25,100]],"ltp":1.5,"tv":193.53,"id":6847357}]}]}
{"op":"mcm","clk":"11865023476","pt":1723429716477,"mc":[{"id":"1.231652082","rc":[{"batb":[[1,1.42,20.48],[2,1.41,14]],"ltp":1.5,"tv":193.53,"id":6847357},{"batb":[[1,1.41,20.98],[2,1.4,15]],"ltp":1.5,"tv":193.53,"id":25651861}]}]}
{"op":"mcm","clk":"11865074030","pt":1723431516972,"mc":[{"id":"1.231652082","rc":[{"batb":[[1,1.41,14],[2,1.25,100]],"ltp":1.5,"tv":193.53,"id":6847357},{"batb":[[1,1.4,15],[2,1.25,100]],"ltp":1.5,"tv":193.53,"id":25651861}]}]}
{"op":"mcm","clk":"11865074232","pt":1723431526066,"mc":[{"id":"1.231652082","rc":[{"batb":[[1,1.42,20.48],[2,1.41,14]],"ltp":1.5,"tv":193.53,"id":6847357},{"batb":[[1,1.41,20.98],[2,1.4,15]],"ltp":1.5,"tv":193.53,"id":25651861}]}]}
{"op":"mcm","clk":"11865088678","pt":1723432008229,"mc":[{"id":"1.231652082","rc":[{"trd":[[1.5,193.5]],"batb":[[0,1.42,21.38],[1,1.41,14],[2,1.25,100]],"ltp":1.5,"tv":193.49,"id":6847357},{"trd":[[1.5,193.5]],"batb":[[1,1.41,20.97]],"ltp":1.5,"tv":193.49,"id":25651861}],"tv":386.99}]}
{"op":"mcm","clk":"11865088773","pt":1723432012161,"mc":[{"id":"1.231652082","rc":[{"batb":[[0,1.41,21.88],[1,1.4,15],[2,1.25,100]],"ltp":1.5,"tv":193.49,"id":25651861}]}]}
{"op":"mcm","clk":"11865128402","pt":1723433326648,"mc":[{"id":"1.231652082","rc":[{"batb":[[0,1.41,14.91],[1,1.25,100],[2,1.03,200]],"ltp":1.5,"tv":193.49,"id":6847357},{"batb":[[0,1.4,15.91],[1,1.25,100],[2,1.03,200]],"ltp":1.5,"tv":193.49,"id":25651861}]}]}
{"op":"mcm","clk":"11865128469","pt":1723433329153,"mc":[{"id":"1.231652082","rc":[{"batb":[[0,1.42,21.38],[1,1.41,14],[2,1.25,100]],"ltp":1.5,"tv":193.49,"id":6847357},{"batb":[[0,1.41,21.88],[1,1.4,15],[2,1.25,100]],"ltp":1.5,"tv":193.49,"id":25651861}]}]}
{"op":"mcm","clk":"11865188480","pt":1723435129580,"mc":[{"id":"1.231652082","rc":[{"batb":[[0,1.41,14.91],[1,1.25,100],[2,1.03,200]],"ltp":1.5,"tv":193.49,"id":6847357},{"batb":[[0,1.4,15.91],[1,1.25,100],[2,1.03,200]],"ltp":1.5,"tv":193.49,"id":25651861}]}]}
{"op":"mcm","clk":"11865191600","pt":1723435225057,"mc":[{"id":"1.231652082","rc":[{"trd":[[1.5,193.57]],"batb":[[0,1.42,21.38],[1,1.41,14],[2,1.25,100]],"ltp":1.5,"tv":193.56,"id":6847357},{"trd":[[1.5,193.57]],"batb":[[0,1.41,21.88],[1,1.4,15],[2,1.25,100]],"ltp":1.5,"tv":193.56,"id":25651861}],"tv":387.13}]}
{"op":"mcm","clk":"11865311173","pt":1723438826358,"mc":[{"id":"1.231652082","rc":[{"trd":[[1.5,193.49]],"batb":[[0,1.41,14.91],[1,1.25,100],[2,1.03,200]],"ltp":1.5,"tv":193.49,"id":6847357},{"trd":[[1.5,193.49]],"batb":[[0,1.4,15.91],[1,1.25,100],[2,1.03,200]],"ltp":1.5,"tv":193.49,"id":25651861}],"tv":386.98}]}
{"op":"mcm","clk":"11865311222","pt":1723438827992,"mc":[{"id":"1.231652082","rc":[{"batb":[[0,1.42,21.38],[1,1.41,14],[2,1.25,100]],"ltp":1.5,"tv":193.49,"id":6847357},{"batb":[[0,1.41,21.88],[1,1.4,15],[2,1.25,100]],"ltp":1.5,"tv":193.49,"id":25651861}]}]}
{"op":"mcm","clk":"11865368701","pt":1723440628446,"mc":[{"id":"1.231652082","rc":[{"batb":[[0,1.41,14.91],[1,1.25,100],[2,1.03,200]],"ltp":1.5,"tv":193.49,"id":6847357},{"batb":[[0,1.4,15.91],[1,1.25,100],[2,1.03,200]],"ltp":1.5,"tv":193.49,"id":25651861}]}]}
{"op":"mcm","clk":"11865368740","pt":1723440630128,"mc":[{"id":"1.231652082","rc":[{"batb":[[0,1.42,21.38],[1,1.41,14],[2,1.25,100]],"ltp":1.5,"tv":193.49,"id":6847357},{"batb":[[0,1.41,21.88],[1,1.4,15],[2,1.25,100]],"ltp":1.5,"tv":193.49,"id":25651861}]}]}
{"op":"mcm","clk":"11865389798","pt":1723441502900,"mc":[{"id":"1.231652082","rc":[{"batb":[[0,1.43,14.91],[1,1.42,20.47]],"ltp":1.5,"tv":193.49,"id":6847357},{"batb":[[0,1.43,15.91],[1,1.41,20.97]],"ltp":1.5,"tv":193.49,"id":25651861}]}]}
{"op":"mcm","clk":"11865414054","pt":1723442430594,"mc":[{"id":"1.231652082","rc":[{"trd":[[1.5,193.43]],"batb":[[1,1.25,100],[2,1.03,200]],"ltp":1.5,"tv":193.42,"id":6847357},{"trd":[[1.5,193.43]],"batb":[[1,1.25,100],[2,1.03,200]],"ltp":1.5,"tv":193.42,"id":25651861}],"tv":386.85}]}
{"op":"mcm","clk":"11865417051","pt":1723442513592,"mc":[{"id":"1.231652082","rc":[{"batb":[[0,1.44,19.53],[1,1.43,14.91],[2,1.25,100]],"ltp":1.5,"tv":193.42,"id":6847357},{"batb":[[0,1.44,20.44],[1,1.43,15],[2,1.25,100]],"ltp":1.5,"tv":193.42,"id":25651861}]}]}
{"op":"mcm","clk":"11865470481","pt":1723444314094,"mc":[{"id":"1.231652082","rc":[{"batb":[[0,1.43,14.91],[1,1.25,100],[2,1.03,200]],"ltp":1.5,"tv":193.42,"id":6847357},{"batb":[[0,1.43,15.91],[1,1.25,100],[2,1.03,200]],"ltp":1.5,"tv":193.42,"id":25651861}]}]}
{"op":"mcm","clk":"11865473319","pt":1723444399315,"mc":[{"id":"1.231652082","rc":[{"batb":[[0,1.44,19.53],[1,1.43,14.91],[2,1.25,100]],"ltp":1.5,"tv":193.42,"id":6847357},{"batb":[[0,1.44,20.44],[1,1.43,15],[2,1.25,100]],"ltp":1.5,"tv":193.42,"id":25651861}]}]}
{"op":"mcm","clk":"11865537365","pt":1723446199687,"mc":[{"id":"1.231652082","rc":[{"trd":[[1.5,193.39]],"batb":[[0,1.43,14.91],[1,1.25,100],[2,1.03,200]],"ltp":1.5,"tv":193.38,"id":6847357},{"trd":[[1.5,193.39]],"batb":[[0,1.43,15.91],[1,1.25,100],[2,1.03,200]],"ltp":1.5,"tv":193.38,"id":25651861}],"tv":386.77}]}
{"op":"mcm","clk":"11865540118","pt":1723446283183,"mc":[{"id":"1.231652082","rc":[{"batb":[[0,1.44,19.54],[1,1.43,14.91],[2,1.25,100]],"ltp":1.5,"tv":193.38,"id":6847357},{"batb":[[0,1.44,20.45],[1,1.43,15],[2,1.25,100]],"ltp":1.5,"tv":193.38,"id":25651861}]}]}
{"op":"mcm","clk":"11865588429","pt":1723448083477,"mc":[{"id":"1.231652082","rc":[{"batb":[[0,1.43,14.91],[1,1.25,100],[2,1.03,200]],"ltp":1.5,"tv":193.38,"id":6847357},{"batb":[[0,1.43,15.91],[1,1.25,100],[2,1.03,200]],"ltp":1.5,"tv":193.38,"id":25651861}]}]}
{"op":"mcm","clk":"11865591201","pt":1723448169159,"mc":[{"id":"1.231652082","rc":[{"batb":[[0,1.44,19.54],[1,1.43,14.91],[2,1.25,100]],"ltp":1.5,"tv":193.38,"id":6847357},{"batb":[[0,1.44,20.45],[1,1.43,15],[2,1.25,100]],"ltp":1.5,"tv":193.38,"id":25651861}]}]}
{"op":"mcm","clk":"11865638584","pt":1723449969612,"mc":[{"id":"1.231652082","rc":[{"trd":[[1.5,193.41]],"batb":[[0,1.43,14.91],[1,1.25,100],[2,1.03,200]],"ltp":1.5,"tv":193.4,"id":6847357},{"trd":[[1.5,193.41]],"batb":[[0,1.43,15.91],[1,1.25,100],[2,1.03,200]],"ltp":1.5,"tv":193.4,"id":25651861}],"tv":386.81}]}
{"op":"mcm","clk":"11865641040","pt":1723450050682,"mc":[{"id":"1.231652082","rc":[{"batb":[[0,1.44,19.53],[1,1.43,14.91],[2,1.25,100]],"ltp":1.5,"tv":193.4,"id":6847357},{"batb":[[0,1.44,20.44],[1,1.43,15],[2,1.25,100]],"ltp":1.5,"tv":193.4,"id":25651861}]}]}
{"op":"mcm","clk":"11865705904","pt":1723451851172,"mc":[{"id":"1.231652082","rc":[{"batb":[[0,1.43,14.91],[1,1.25,100],[2,1.03,200]],"ltp":1.5,"tv":193.4,"id":6847357},{"batb":[[0,1.43,15.91],[1,1.25,100],[2,1.03,200]],"ltp":1.5,"tv":193.4,"id":25651861}]}]}
{"op":"mcm","clk":"11865708448","pt":1723451926777,"mc":[{"id":"1.231652082","rc":[{"batb":[[0,1.44,19.53],[1,1.43,14.91],[2,1.25,100]],"ltp":1.5,"tv":193.4,"id":6847357},{"batb":[[0,1.44,20.44],[1,1.43,15],[2,1.25,100]],"ltp":1.5,"tv":193.4,"id":25651861}]}]}
{"op":"mcm","clk":"11865791784","pt":1723453727042,"mc":[{"id":"1.231652082","rc":[{"trd":[[1.5,193.51]],"batb":[[0,1.43,14.91],[1,1.25,100],[2,1.03,200]],"ltp":1.5,"tv":193.5,"id":6847357},{"trd":[[1.5,193.51]],"batb":[[0,1.43,15.91],[1,1.25,100],[2,1.03,200]],"ltp":1.5,"tv":193.5,"id":25651861}],"tv":387.01}]}
{"op":"mcm","clk":"11865795724","pt":1723453799091,"mc":[{"id":"1.231652082","rc":[{"batb":[[0,1.44,19.54],[1,1.43,14.91],[2,1.25,100]],"ltp":1.5,"tv":193.5,"id":6847357},{"batb":[[0,1.44,20.45],[1,1.43,15],[2,1.25,100]],"ltp":1.5,"tv":193.5,"id":25651861}]}]}
{"op":"mcm","clk":"11865854767","pt":1723454982053,"mc":[{"id":"1.231652082","rc":[{"batl":[[0,1.45,1.57]],"ltp":1.5,"tv":193.5,"id":6847357}]}]}
{"op":"mcm","clk":"11865885676","pt":1723455599451,"mc":[{"id":"1.231652082","rc":[{"batb":[[0,1.43,14.91],[1,1.25,100],[2,1.03,200]],"ltp":1.5,"tv":193.5,"id":6847357},{"batb":[[0,1.43,15.91],[1,1.25,100],[2,1.03,200]],"ltp":1.5,"tv":193.5,"id":25651861}]}]}
{"op":"mcm","clk":"11865888694","pt":1723455668342,"mc":[{"id":"1.231652082","rc":[{"batb":[[0,1.44,19.54],[1,1.43,14.91],[2,1.25,100]],"ltp":1.5,"tv":193.5,"id":6847357},{"batb":[[0,1.44,20.45],[1,1.43,15],[2,1.25,100]],"ltp":1.5,"tv":193.5,"id":25651861}]}]}
{"op":"mcm","clk":"11865917136","pt":1723456070861,"mc":[{"id":"1.231652082","rc":[{"batb":[[0,1.45,14],[1,1.44,19.54],[2,1.25,100.91]],"ltp":1.5,"tv":193.5,"id":6847357},{"batb":[[0,1.45,15],[1,1.44,20.45]],"ltp":1.5,"tv":193.5,"id":25651861}]}]}
{"op":"mcm","clk":"11865997760","pt":1723457468637,"mc":[{"id":"1.231652082","rc":[{"trd":[[1.5,193.65]],"batb":[[1,1.25,100.91],[2,1.03,200]],"ltp":1.5,"tv":193.64,"id":6847357},{"trd":[[1.5,193.65]],"batb":[[1,1.25,100.91],[2,1.03,200]],"ltp":1.5,"tv":193.64,"id":25651861}],"tv":387.29}]}
{"op":"mcm","clk":"11866005244","pt":1723457574330,"mc":[{"id":"1.231652082","rc":[{"batb":[[0,1.46,18.71],[1,1.45,14],[2,1.25,100.91]],"ltp":1.5,"tv":193.64,"id":6847357},{"batb":[[0,1.46,18.71],[1,1.45,15],[2,1.25,100.91]],"ltp":1.5,"tv":193.64,"id":25651861}]}]}
{"op":"mcm","clk":"11866008418","pt":1723457625352,"mc":[{"id":"1.231652082","rc":[{"batb":[[0,1.46,19.62],[2,1.25,100]],"ltp":1.5,"tv":193.64,"id":6847357}]}]}
{"op":"mcm","clk":"11866008974","pt":1723457635410,"mc":[{"id":"1.231652082","rc":[{"batb":[[0,1.46,19.62],[2,1.25,100]],"ltp":1.5,"tv":193.64,"id":25651861}]}]}
{"op":"mcm","clk":"11866106746","pt":1723459374749,"mc":[{"id":"1.231652082","rc":[{"batb":[[0,1.45,14.91],[1,1.25,100],[2,1.03,200]],"ltp":1.5,"tv":193.64,"id":6847357},{"batb":[[0,1.45,15.91],[1,1.25,100],[2,1.03,200]],"ltp":1.5,"tv":193.64,"id":25651861}]}]}
{"op":"mcm","clk":"11866112631","pt":1723459487569,"mc":[{"id":"1.231652082","rc":[{"batb":[[0,1.46,19.62],[1,1.45,14],[2,1.25,100]],"ltp":1.5,"tv":193.64,"id":6847357},{"batb":[[0,1.46,19.62],[1,1.45,15],[2,1.25,100]],"ltp":1.5,"tv":193.64,"id":25651861}]}]}
{"op":"mcm","clk":"11866205664","pt":1723461174798,"mc":[{"id":"1.231652082","rc":[{"trd":[[1.5,193.61]],"batb":[[0,1.46,19.62]],"ltp":1.5,"tv":193.61,"id":6847357},{"trd":[[1.5,193.61]],"batb":[[0,1.46,19.62]],"ltp":1.5,"tv":193.61,"id":25651861}],"tv":387.22}]}
{"op":"mcm","clk":"11866218383","pt":1723461287779,"mc":[{"id":"1.231652082","rc":[{"batb":[[0,1.45,14.91],[1,1.25,100],[2,1.03,200]],"ltp":1.5,"tv":193.61,"id":6847357},{"batb":[[0,1.45,15.91],[1,1.25,100],[2,1.03,200]],"ltp":1.5,"tv":193.61,"id":25651861}]}]}
{"op":"mcm","clk":"11866221510","pt":1723461343374,"mc":[{"id":"1.231652082","rc":[{"batb":[[0,1.46,19.62],[1,1.45,14],[2,1.25,100]],"ltp":1.5,"tv":193.61,"id":6847357},{"batb":[[0,1.46,19.62],[1,1.45,15],[2,1.25,100]],"ltp":1.5,"tv":193.61,"id":25651861}]}]}
{"op":"mcm","clk":"11866325254","pt":1723463143664,"mc":[{"id":"1.231652082","rc":[{"batb":[[0,1.45,14.91],[1,1.25,100],[2,1.03,200]],"ltp":1.5,"tv":193.61,"id":6847357},{"batb":[[0,1.45,15.91],[1,1.25,100],[2,1.03,200]],"ltp":1.5,"tv":193.61,"id":25651861}]}]}
{"op":"mcm","clk":"11866327572","pt":1723463182589,"mc":[{"id":"1.231652082","rc":[{"batb":[[0,1.46,19.62],[1,1.45,14],[2,1.25,100]],"ltp":1.5,"tv":193.61,"id":6847357},{"batb":[[0,1.46,19.62],[1,1.45,15],[2,1.25,100]],"ltp":1.5,"tv":193.61,"id":25651861}]}]}
{"op":"mcm","clk":"11866423819","pt":1723464983043,"mc":[{"id":"1.231652082","rc":[{"trd":[[1.5,193.48]],"batb":[[0,1.45,14.91],[1,1.25,100],[2,1.03,200]],"ltp":1.5,"tv":193.48,"id":6847357},{"trd":[[1.5,193.48]],"batb":[[0,1.45,15.91],[1,1.25,100],[2,1.03,200]],"ltp":1.5,"tv":193.48,"id":25651861}],"tv":386.96}]}
{"op":"mcm","clk":"11866425305","pt":1723465007641,"mc":[{"id":"1.231652082","rc":[{"batb":[[0,1.46,19.6],[1,1.45,14],[2,1.25,100]],"ltp":1.5,"tv":193.48,"id":6847357},{"batb":[[0,1.46,19.6],[1,1.45,15],[2,1.25,100]],"ltp":1.5,"tv":193.48,"id":25651861}]}]}
{"op":"mcm","clk":"11866522508","pt":1723466808101,"mc":[{"id":"1.231652082","rc":[{"batb":[[0,1.45,14.91],[1,1.25,100],[2,1.03,200]],"ltp":1.5,"tv":193.48,"id":6847357},{"batb":[[0,1.45,15.91],[1,1.25,100],[2,1.03,200]],"ltp":1.5,"tv":193.48,"id":25651861}]}]}
{"op":"mcm","clk":"11866522974","pt":1723466821946,"mc":[{"id":"1.231652082","rc":[{"batb":[[0,1.46,19.6],[1,1.45,14],[2,1.25,100]],"ltp":1.5,"tv":193.48,"id":6847357},{"batb":[[0,1.46,19.6],[1,1.45,15],[2,1.25,100]],"ltp":1.5,"tv":193.48,"id":25651861}]}]}
{"op":"mcm","clk":"11866614984","pt":1723468622133,"mc":[{"id":"1.231652082","rc":[{"trd":[[1.5,193.62]],"batb":[[0,1.46,19.6]],"ltp":1.5,"tv":193.61,"id":6847357},{"trd":[[1.5,193.62]],"batb":[[0,1.45,15.91],[1,1.25,100],[2,1.03,200]],"ltp":1.5,"tv":193.61,"id":25651861}],"tv":387.23}]}
{"op":"mcm","clk":"11866615000","pt":1723468622343,"mc":[{"id":"1.231652082","rc":[{"batb":[[0,1.45,14.91],[1,1.25,100],[2,1.03,200]],"ltp":1.5,"tv":193.61,"id":6847357}]}]}
{"op":"mcm","clk":"11866615307","pt":1723468626962,"mc":[{"id":"1.231652082","rc":[{"batb":[[0,1.46,19.6],[1,1.45,14],[2,1.25,100]],"ltp":1.5,"tv":193.61,"id":6847357},{"batb":[[0,1.46,19.6],[1,1.45,15],[2,1.25,100]],"ltp":1.5,"tv":193.61,"id":25651861}]}]}
{"op":"mcm","clk":"11866724941","pt":1723470427129,"mc":[{"id":"1.231652082","rc":[{"batb":[[0,1.45,15.91],[1,1.25,100],[2,1.03,200]],"ltp":1.5,"tv":193.61,"id":25651861}]}]}
{"op":"mcm","clk":"11866724946","pt":1723470427230,"mc":[{"id":"1.231652082","rc":[{"batb":[[0,1.45,14.91],[1,1.25,100],[2,1.03,200]],"ltp":1.5,"tv":193.61,"id":6847357}]}]}
{"op":"mcm","clk":"11866728425","pt":1723470485572,"mc":[{"id":"1.231652082","rc":[{"batb":[[0,1.46,19.6],[1,1.45,14],[2,1.25,100]],"ltp":1.5,"tv":193.61,"id":6847357},{"batb":[[0,1.46,19.6],[1,1.45,15],[2,1.25,100]],"ltp":1.5,"tv":193.61,"id":25651861}]}]}
{"op":"mcm","clk":"11866813071","pt":1723471974794,"mc":[{"id":"1.231652082","rc":[{"trd":[[1.5,193.6]],"batb":[[0,1.46,19.6]],"ltp":1.5,"tv":193.59,"id":6847357},{"trd":[[1.5,193.6]],"batb":[[0,1.46,19.6]],"ltp":1.5,"tv":193.59,"id":25651861}],"tv":387.19}]}
{"op":"mcm","clk":"11866838943","pt":1723472285845,"mc":[{"id":"1.231652082","rc":[{"batb":[[0,1.45,14.91],[1,1.25,100],[2,1.03,200]],"ltp":1.5,"tv":193.59,"id":6847357},{"batb":[[0,1.45,15.91],[1,1.25,100],[2,1.03,200]],"ltp":1.5,"tv":193.59,"id":25651861}]}]}
{"op":"mcm","clk":"11866843548","pt":1723472358725,"mc":[{"id":"1.231652082","rc":[{"batb":[[0,1.46,19.6],[1,1.45,14],[2,1.25,100]],"ltp":1.5,"tv":193.59,"id":6847357},{"batb":[[0,1.46,19.6],[1,1.45,15],[2,1.25,100]],"ltp":1.5,"tv":193.59,"id":25651861}]}]}
{"op":"mcm","clk":"11866942523","pt":1723474046153,"mc":[{"id":"1.231652082","rc":[{"trd":[[1.5,194.19]],"batb":[[0,1.46,19.31]],"ltp":1.5,"tv":194.18,"id":25651861}],"tv":387.78}]}
{"op":"mcm","clk":"11866949185","pt":1723474159104,"mc":[{"id":"1.231652082","rc":[{"batb":[[0,1.45,14.91],[1,1.25,100],[2,1.03,200]],"ltp":1.5,"tv":193.59,"id":6847357},{"batb":[[0,1.45,15.61],[1,1.25,100],[2,1.03,200]],"ltp":1.5,"tv":194.18,"id":25651861}]}]}
{"op":"mcm","clk":"11866952515","pt":1723474222584,"mc":[{"id":"1.231652082","rc":[{"batb":[[0,1.46,19.6],[1,1.45,14],[2,1.25,100]],"ltp":1.5,"tv":193.59,"id":6847357},{"batb":[[0,1.46,19.31],[1,1.45,15],[2,1.25,100]],"ltp":1.5,"tv":194.18,"id":25651861}]}]}
{"op":"mcm","clk":"11867071229","pt":1723476022804,"mc":[{"id":"1.231652082","rc":[{"trd":[[1.5,193.33]],"batb":[[0,1.45,14.91],[1,1.25,100],[2,1.03,200]],"ltp":1.5,"tv":193.32,"id":6847357},{"trd":[[1.5,193.92]],"batb":[[0,1.45,15.61],[1,1.25,100],[2,1.03,200]],"ltp":1.5,"tv":193.91,"id":25651861}],"tv":387.24}]}
{"op":"mcm","clk":"11867075443","pt":1723476081982,"mc":[{"id":"1.231652082","rc":[{"batb":[[0,1.46,19.59],[1,1.45,14],[2,1.25,100]],"ltp":1.5,"tv":193.32,"id":6847357},{"batb":[[0,1.46,19.29],[1,1.45,15],[2,1.25,100]],"ltp":1.5,"tv":193.91,"id":25651861}]}]}
{"op":"mcm","clk":"11867217647","pt":1723477882309,"mc":[{"id":"1.231652082","rc":[{"batb":[[0,1.45,14.91],[1,1.25,100],[2,1.03,200]],"ltp":1.5,"tv":193.32,"id":6847357},{"batb":[[0,1.45,15.61],[1,1.25,100],[2,1.03,200]],"ltp":1.5,"tv":193.91,"id":25651861}]}]}
{"op":"mcm","clk":"11867221239","pt":1723477931646,"mc":[{"id":"1.231652082","rc":[{"batb":[[0,1.46,19.59],[1,1.45,14],[2,1.25,100]],"ltp":1.5,"tv":193.32,"id":6847357},{"batb":[[0,1.46,19.29],[1,1.45,15],[2,1.25,100]],"ltp":1.5,"tv":193.91,"id":25651861}]}]}
{"op":"mcm","clk":"11867356191","pt":1723479732004,"mc":[{"id":"1.231652082","rc":[{"trd":[[1.5,193.53]],"batb":[[0,1.45,14.91],[1,1.25,100],[2,1.03,200]],"ltp":1.5,"tv":193.52,"id":6847357},{"trd":[[1.5,194.12]],"batb":[[0,1.45,15.61],[1,1.25,100],[2,1.03,200]],"ltp":1.5,"tv":194.12,"id":25651861}],"tv":387.64}]}
{"op":"mcm","clk":"11867358210","pt":1723479764692,"mc":[{"id":"1.231652082","rc":[{"batb":[[0,1.46,19.6],[1,1.45,14],[2,1.25,100]],"ltp":1.5,"tv":193.52,"id":6847357},{"batb":[[0,1.46,19.31],[1,1.45,15],[2,1.25,100]],"ltp":1.5,"tv":194.12,"id":25651861}]}]}
{"op":"mcm","clk":"11867496282","pt":1723481565001,"mc":[{"id":"1.231652082","rc":[{"batb":[[0,1.45,14.91],[1,1.25,100],[2,1.03,200]],"ltp":1.5,"tv":193.52,"id":6847357},{"batb":[[0,1.45,15.61],[1,1.25,100],[2,1.03,200]],"ltp":1.5,"tv":194.12,"id":25651861}]}]}
{"op":"mcm","clk":"11867497571","pt":1723481584635,"mc":[{"id":"1.231652082","rc":[{"batb":[[0,1.46,19.6],[1,1.45,14],[2,1.25,100]],"ltp":1.5,"tv":193.52,"id":6847357},{"batb":[[0,1.46,19.31],[1,1.45,15],[2,1.25,100]],"ltp":1.5,"tv":194.12,"id":25651861}]}]}
{"op":"mcm","clk":"11867587851","pt":1723482775340,"mc":[{"id":"1.231652082","rc":[{"trd":[[1.5,193.73]],"batb":[[0,1.46,19.62]],"ltp":1.5,"tv":193.73,"id":6847357},{"trd":[[1.5,194.33]],"batb":[[0,1.46,19.32]],"ltp":1.5,"tv":194.32,"id":25651861}],"tv":388.05}]}
{"op":"mcm","clk":"11867648523","pt":1723483385070,"mc":[{"id":"1.231652082","rc":[{"batb":[[0,1.45,14.91],[1,1.25,100],[2,1.03,200]],"ltp":1.5,"tv":193.73,"id":6847357},{"batb":[[0,1.45,15.61],[1,1.25,100],[2,1.03,200]],"ltp":1.5,"tv":194.32,"id":25651861}]}]}
{"op":"mcm","clk":"11867660062","pt":1723483510869,"mc":[{"id":"1.231652082","rc":[{"batb":[[0,1.46,19.62],[1,1.45,14],[2,1.25,100]],"ltp":1.5,"tv":193.73,"id":6847357},{"batb":[[0,1.46,19.32],[1,1.45,15],[2,1.25,100]],"ltp":1.5,"tv":194.32,"id":25651861}]}]}
{"op":"mcm","clk":"11867804579","pt":1723485311119,"mc":[{"id":"1.231652082","rc":[{"batb":[[0,1.45,14.91],[1,1.25,100],[2,1.03,200]],"ltp":1.5,"tv":193.73,"id":6847357},{"batb":[[0,1.45,15.61],[1,1.25,100],[2,1.03,200]],"ltp":1.5,"tv":194.32,"id":25651861}]}]}
{"op":"mcm","clk":"11867810562","pt":1723485402740,"mc":[{"id":"1.231652082","rc":[{"batb":[[0,1.46,19.62],[1,1.45,14],[2,1.25,100]],"ltp":1.5,"tv":193.73,"id":6847357},{"batb":[[0,1.46,19.32],[1,1.45,15],[2,1.25,100]],"ltp":1.5,"tv":194.32,"id":25651861}]}]}
{"op":"mcm","clk":"11867965486","pt":1723487202985,"mc":[{"id":"1.231652082","rc":[{"trd":[[1.5,193.63]],"batb":[[0,1.45,14.91],[1,1.25,100],[2,1.03,200]],"ltp":1.5,"tv":193.62,"id":6847357},{"trd":[[1.5,194.22]],"batb":[[0,1.45,15.61],[1,1.25,100],[2,1.03,200]],"ltp":1.5,"tv":194.22,"id":25651861}],"tv":387.85}]}
{"op":"mcm","clk":"11867969786","pt":1723487249649,"mc":[{"id":"1.231652082","rc":[{"batb":[[0,1.46,19.62],[1,1.45,14],[2,1.25,100]],"ltp":1.5,"tv":193.62,"id":6847357},{"batb":[[0,1.46,19.33],[1,1.45,15],[2,1.25,100]],"ltp":1.5,"tv":194.22,"id":25651861}]}]}
{"op":"mcm","clk":"11868138755","pt":1723489050143,"mc":[{"id":"1.231652082","rc":[{"batb":[[0,1.45,14.91],[1,1.25,100],[2,1.03,200]],"ltp":1.5,"tv":193.62,"id":6847357},{"batb":[[0,1.45,15.61],[1,1.25,100],[2,1.03,200]],"ltp":1.5,"tv":194.22,"id":25651861}]}]}
{"op":"mcm","clk":"11868146453","pt":1723489154790,"mc":[{"id":"1.231652082","rc":[{"batb":[[0,1.46,19.62],[1,1.45,14],[2,1.25,100]],"ltp":1.5,"tv":193.62,"id":6847357},{"batb":[[0,1.46,19.33],[1,1.45,15],[2,1.25,100]],"ltp":1.5,"tv":194.22,"id":25651861}]}]}
{"op":"mcm","clk":"11868280623","pt":1723490955161,"mc":[{"id":"1.231652082","rc":[{"trd":[[1.5,193.57]],"batb":[[0,1.45,14.91],[1,1.25,100],[2,1.03,200]],"ltp":1.5,"tv":193.57,"id":6847357},{"trd":[[1.5,194.16]],"batb":[[0,1.45,15.61],[1,1.25,100],[2,1.03,200]],"ltp":1.5,"tv":194.16,"id":25651861}],"tv":387.73}]}
{"op":"mcm","clk":"11868291320","pt":1723491082622,"mc":[{"id":"1.231652082","rc":[{"batb":[[0,1.46,19.61],[1,1.45,14],[2,1.25,100]],"ltp":1.5,"tv":193.57,"id":6847357},{"batb":[[0,1.46,19.31],[1,1.45,15],[2,1.25,100]],"ltp":1.5,"tv":194.16,"id":25651861}]}]}
{"op":"mcm","clk":"11868304289","pt":1723491261150,"mc":[{"id":"1.231652082","rc":[{"batb":[[0,1.5,1.46],[1,1.46,18.7],[2,1.45,14]],"ltp":1.5,"tv":193.57,"id":6847357}]}]}
{"op":"mcm","clk":"11868306082","pt":1723491290147,"mc":[{"id":"1.231652082","rc":[{"batb":[[0,1.5,1.16],[1,1.46,18.7],[2,1.45,15]],"ltp":1.5,"tv":194.16,"id":25651861}]}]}
{"op":"mcm","clk":"11868306819","pt":1723491301166,"mc":[{"id":"1.231652082","rc":[{"batb":[[0,1.46,19.31],[1,1.45,15],[2,1.25,100]],"ltp":1.5,"tv":194.16,"id":25651861}]}]}
{"op":"mcm","clk":"11868306827","pt":1723491301273,"mc":[{"id":"1.231652082","rc":[{"batb":[[0,1.5,1.12],[1,1.46,18.7],[2,1.45,15]],"ltp":1.5,"tv":194.16,"id":25651861}]}]}
{"op":"mcm","clk":"11868307473","pt":1723491311292,"mc":[{"id":"1.231652082","rc":[{"batb":[[0,1.5,1.42]],"ltp":1.5,"tv":193.57,"id":6847357}]}]}
{"op":"mcm","clk":"11868419196","pt":1723492883088,"mc":[{"id":"1.231652082","rc":[{"trd":[[1.5,193.63]],"batb":[[1,1.45,14],[2,1.25,100]],"ltp":1.5,"tv":193.62,"id":6847357},{"trd":[[1.5,194.22]],"batb":[[1,1.45,15],[2,1.25,100]],"ltp":1.5,"tv":194.21,"id":25651861}],"tv":387.84}]}
{"op":"mcm","clk":"11868420267","pt":1723492899293,"mc":[{"id":"1.231652082","rc":[{"batb":[[1,1.46,18.7],[2,1.45,14]],"ltp":1.5,"tv":193.62,"id":6847357},{"batb":[[1,1.46,18.7],[2,1.45,15]],"ltp":1.5,"tv":194.21,"id":25651861}]}]}
{"op":"mcm","clk":"11868536202","pt":1723494699596,"mc":[{"id":"1.231652082","rc":[{"batb":[[1,1.45,14],[2,1.25,100]],"ltp":1.5,"tv":193.62,"id":6847357},{"batb":[[1,1.45,15],[2,1.25,100]],"ltp":1.5,"tv":194.21,"id":25651861}]}]}
{"op":"mcm","clk":"11868536661","pt":1723494707590,"mc":[{"id":"1.231652082","rc":[{"batb":[[1,1.46,18.7],[2,1.45,14]],"ltp":1.5,"tv":193.62,"id":6847357},{"batb":[[1,1.46,18.7],[2,1.45,15]],"ltp":1.5,"tv":194.21,"id":25651861}]}]}
{"op":"mcm","clk":"11868627869","pt":1723496507890,"mc":[{"id":"1.231652082","rc":[{"trd":[[1.5,193.63]],"batb":[[1,1.45,14],[2,1.25,100]],"ltp":1.5,"tv":193.62,"id":6847357},{"trd":[[1.5,194.22]],"batb":[[1,1.45,15],[2,1.25,100]],"ltp":1.5,"tv":194.22,"id":25651861}],"tv":387.85}]}
{"op":"mcm","clk":"11868634515","pt":1723496627196,"mc":[{"id":"1.231652082","rc":[{"batb":[[1,1.46,18.71],[2,1.45,14]],"ltp":1.5,"tv":193.62,"id":6847357},{"batb":[[1,1.46,18.71],[2,1.45,15]],"ltp":1.5,"tv":194.22,"id":25651861}]}]}
{"op":"mcm","clk":"11868639496","pt":1723496719556,"mc":[{"id":"1.231652082","rc":[{"trd":[[1.53,0.14]],"batb":[[0,1.5,1.05]],"ltp":1.53,"tv":194.36,"id":25651861}],"tv":387.99}]}
{"op":"mcm","clk":"11868712363","pt":1723498427583,"mc":[{"id":"1.231652082","rc":[{"batb":[[1,1.45,14],[2,1.25,100]],"ltp":1.5,"tv":193.62,"id":6847357},{"batb":[[1,1.45,15],[2,1.25,100]],"ltp":1.53,"tv":194.36,"id":25651861}]}]}
{"op":"mcm","clk":"11868716110","pt":1723498517340,"mc":[{"id":"1.231652082","rc":[{"batb":[[1,1.46,18.71],[2,1.45,14]],"ltp":1.5,"tv":193.62,"id":6847357},{"batb":[[1,1.46,18.71],[2,1.45,15]],"ltp":1.53,"tv":194.36,"id":25651861}]}]}
{"op":"mcm","clk":"11868798473","pt":1723500317871,"mc":[{"id":"1.231652082","rc":[{"trd":[[1.5,193.6]],"batb":[[1,1.45,14],[2,1.25,100]],"ltp":1.5,"tv":193.6,"id":6847357},{"trd":[[1.5,194.2]],"batb":[[1,1.45,15],[2,1.25,100]],"ltp":1.53,"tv":194.33,"id":25651861}],"tv":387.94}]}
{"op":"mcm","clk":"11868802368","pt":1723500393366,"mc":[{"id":"1.231652082","rc":[{"batb":[[1,1.46,18.71],[2,1.45,14]],"ltp":1.5,"tv":193.6,"id":6847357},{"batb":[[1,1.46,18.71],[2,1.45,15]],"ltp":1.53,"tv":194.33,"id":25651861}]}]}
{"op":"mcm","clk":"11868886223","pt":1723502193655,"mc":[{"id":"1.231652082","rc":[{"batb":[[1,1.45,14],[2,1.25,100]],"ltp":1.5,"tv":193.6,"id":6847357},{"batb":[[1,1.45,15],[2,1.25,100]],"ltp":1.53,"tv":194.33,"id":25651861}]}]}
{"op":"mcm","clk":"11868889587","pt":1723502259134,"mc":[{"id":"1.231652082","rc":[{"batb":[[1,1.46,18.71],[2,1.45,14]],"ltp":1.5,"tv":193.6,"id":6847357},{"batb":[[1,1.46,18.71],[2,1.45,15]],"ltp":1.53,"tv":194.33,"id":25651861}]}]}
{"op":"mcm","clk":"11868966853","pt":1723504059634,"mc":[{"id":"1.231652082","rc":[{"trd":[[1.5,193.59]],"batb":[[1,1.45,14],[2,1.25,100]],"ltp":1.5,"tv":193.58,"id":6847357},{"trd":[[1.5,194.18]],"batb":[[1,1.45,15],[2,1.25,100]],"ltp":1.53,"tv":194.32,"id":25651861}],"tv":387.91}]}
{"op":"mcm","clk":"11868969437","pt":1723504112583,"mc":[{"id":"1.231652082","rc":[{"batb":[[1,1.46,18.71],[2,1.45,14]],"ltp":1.5,"tv":193.58,"id":6847357},{"batb":[[1,1.46,18.71],[2,1.45,15]],"ltp":1.53,"tv":194.32,"id":25651861}]}]}
{"op":"mcm","clk":"11869070711","pt":1723505913007,"mc":[{"id":"1.231652082","rc":[{"batb":[[1,1.45,14],[2,1.25,100]],"ltp":1.5,"tv":193.58,"id":6847357},{"batb":[[1,1.45,15],[2,1.25,100]],"ltp":1.53,"tv":194.32,"id":25651861}]}]}
{"op":"mcm","clk":"11869072912","pt":1723505953615,"mc":[{"id":"1.231652082","rc":[{"batb":[[1,1.46,18.71],[2,1.45,14]],"ltp":1.5,"tv":193.58,"id":6847357},{"batb":[[1,1.46,18.71],[2,1.45,15]],"ltp":1.53,"tv":194.32,"id":25651861}]}]}
{"op":"mcm","clk":"11869167435","pt":1723507754076,"mc":[{"id":"1.231652082","rc":[{"trd":[[1.5,193.53]],"batb":[[1,1.45,14],[2,1.25,100]],"ltp":1.5,"tv":193.52,"id":6847357},{"trd":[[1.5,194.12]],"batb":[[1,1.45,15],[2,1.25,100]],"ltp":1.53,"tv":194.25,"id":25651861}],"tv":387.78}]}
{"op":"mcm","clk":"11869168384","pt":1723507770392,"mc":[{"id":"1.231652082","rc":[{"batb":[[1,1.46,18.71],[2,1.45,14]],"ltp":1.5,"tv":193.52,"id":6847357},{"batb":[[1,1.46,18.71],[2,1.45,15]],"ltp":1.53,"tv":194.25,"id":25651861}]}]}
{"op":"mcm","clk":"11869269969","pt":1723509570864,"mc":[{"id":"1.231652082","rc":[{"batb":[[1,1.45,14],[2,1.25,100]],"ltp":1.5,"tv":193.52,"id":6847357},{"batb":[[1,1.45,15],[2,1.25,100]],"ltp":1.53,"tv":194.25,"id":25651861}]}]}
{"op":"mcm","clk":"11869270023","pt":1723509571938,"mc":[{"id":"1.231652082","rc":[{"batb":[[1,1.46,18.71],[2,1.45,14]],"ltp":1.5,"tv":193.52,"id":6847357},{"batb":[[1,1.46,18.71],[2,1.45,15]],"ltp":1.53,"tv":194.25,"id":25651861}]}]}
{"op":"mcm","clk":"11869365509","pt":1723511372383,"mc":[{"id":"1.231652082","rc":[{"trd":[[1.5,193.59]],"batb":[[1,1.45,14],[2,1.25,100]],"ltp":1.5,"tv":193.59,"id":6847357},{"trd":[[1.5,194.19]],"batb":[[1,1.45,15],[2,1.25,100]],"ltp":1.53,"tv":194.32,"id":25651861}],"tv":387.92}]}
{"op":"mcm","clk":"11869371494","pt":1723511486446,"mc":[{"id":"1.231652082","rc":[{"batb":[[1,1.46,18.7],[2,1.45,14]],"ltp":1.5,"tv":193.59,"id":6847357},{"batb":[[1,1.46,18.7],[2,1.45,15]],"ltp":1.53,"tv":194.32,"id":25651861}]}]}
{"op":"mcm","clk":"11869455095","pt":1723513286902,"mc":[{"id":"1.231652082","rc":[{"batb":[[1,1.45,14],[2,1.25,100]],"ltp":1.5,"tv":193.59,"id":6847357},{"batb":[[1,1.45,15],[2,1.25,100]],"ltp":1.53,"tv":194.32,"id":25651861}]}]}
{"op":"mcm","clk":"11869459246","pt":1723513371453,"mc":[{"id":"1.231652082","rc":[{"batb":[[1,1.46,18.7],[2,1.45,14]],"ltp":1.5,"tv":193.59,"id":6847357},{"batb":[[1,1.46,18.7],[2,1.45,15]],"ltp":1.53,"tv":194.32,"id":25651861}]}]}
{"op":"mcm","clk":"11869542120","pt":1723515171915,"mc":[{"id":"1.231652082","rc":[{"trd":[[1.5,193.5]],"batb":[[1,1.45,14],[2,1.25,100]],"ltp":1.5,"tv":193.49,"id":6847357},{"trd":[[1.5,194.09]],"batb":[[1,1.45,15],[2,1.25,100]],"ltp":1.53,"tv":194.23,"id":25651861}],"tv":387.73}]}
{"op":"mcm","clk":"11869553209","pt":1723515245839,"mc":[{"id":"1.231652082","rc":[{"batb":[[1,1.46,18.7],[2,1.45,14]],"ltp":1.5,"tv":193.49,"id":6847357},{"batb":[[1,1.46,18.7],[2,1.45,15]],"ltp":1.53,"tv":194.23,"id":25651861}]}]}
{"op":"mcm","clk":"11869621935","pt":1723517046138,"mc":[{"id":"1.231652082","rc":[{"batb":[[1,1.45,15],[2,1.25,100]],"ltp":1.53,"tv":194.23,"id":25651861}]}]}
{"op":"mcm","clk":"11869621944","pt":1723517046345,"mc":[{"id":"1.231652082","rc":[{"batb":[[1,1.45,14],[2,1.25,100]],"ltp":1.5,"tv":193.49,"id":6847357}]}]}
{"op":"mcm","clk":"11869623903","pt":1723517098617,"mc":[{"id":"1.231652082","rc":[{"batb":[[1,1.46,18.7],[2,1.45,14]],"ltp":1.5,"tv":193.49,"id":6847357},{"batb":[[1,1.46,18.7],[2,1.45,15]],"ltp":1.53,"tv":194.23,"id":25651861}]}]}
{"op":"mcm","clk":"11869698659","pt":1723518899036,"mc":[{"id":"1.231652082","rc":[{"trd":[[1.5,193.57]],"batb":[[1,1.45,14],[2,1.25,100]],"ltp":1.5,"tv":193.57,"id":6847357},{"trd":[[1.5,194.16]],"batb":[[1,1.45,15],[2,1.25,100]],"ltp":1.53,"tv":194.3,"id":25651861}],"tv":387.87}]}
{"op":"mcm","clk":"11869700455","pt":1723518940991,"mc":[{"id":"1.231652082","rc":[{"batb":[[1,1.46,18.71],[2,1.45,14]],"ltp":1.5,"tv":193.57,"id":6847357},{"batb":[[1,1.46,18.71],[2,1.45,15]],"ltp":1.53,"tv":194.3,"id":25651861}]}]}
{"op":"mcm","clk":"11869769220","pt":1723520741482,"mc":[{"id":"1.231652082","rc":[{"batb":[[1,1.45,14],[2,1.25,100]],"ltp":1.5,"tv":193.57,"id":6847357},{"batb":[[1,1.45,15],[2,1.25,100]],"ltp":1.53,"tv":194.3,"id":25651861}]}]}
{"op":"mcm","clk":"11869770035","pt":1723520766709,"mc":[{"id":"1.231652082","rc":[{"batb":[[1,1.46,18.71],[2,1.45,14]],"ltp":1.5,"tv":193.57,"id":6847357},{"batb":[[1,1.46,18.71],[2,1.45,15]],"ltp":1.53,"tv":194.3,"id":25651861}]}]}
{"op":"mcm","clk":"11869812506","pt":1723521956114,"mc":[{"id":"1.231652082","rc":[{"trd":[[1.5,193.55]],"batb":[[1,1.46,18.71]],"ltp":1.5,"tv":193.55,"id":6847357},{"trd":[[1.5,194.14]],"batb":[[1,1.46,18.71]],"batl":[[0,3.05,0.73]],"ltp":1.53,"tv":194.28,"id":25651861}],"tv":387.83}]}
{"op":"mcm","clk":"11869814045","pt":1723521994128,"mc":[{"id":"1.231652082","rc":[{"batl":[[0,2.98,1.23]],"ltp":1.53,"tv":194.28,"id":25651861}]}]}
{"op":"mcm","clk":"11869814056","pt":1723521994435,"mc":[{"id":"1.231652082","rc":[{"batb":[[0,1.52,10.44],[1,1.51,4],[2,1.46,19.32]],"ltp":1.53,"tv":194.28,"id":25651861}]}]}
{"op":"mcm","clk":"11869814143","pt":1723521996533,"mc":[{"id":"1.231652082","rc":[{"batb":[[1,1.46,19.32],[2,1.45,15]],"ltp":1.53,"tv":194.28,"id":25651861}]}]}
{"op":"mcm","clk":"11869814203","pt":1723521997864,"mc":[{"id":"1.231652082","rc":[{"batb":[[0,1.5,1.05],[1,1.46,18.71]],"ltp":1.53,"tv":194.28,"id":25651861}]}]}
{"op":"mcm","clk":"11869814250","pt":1723521998942,"mc":[{"id":"1.231652082","rc":[{"batb":[[0,1.51,4.44],[1,1.46,19.32]],"ltp":1.53,"tv":194.28,"id":25651861}]}]}
{"op":"mcm","clk":"11869814306","pt":1723522000077,"mc":[{"id":"1.231652082","rc":[{"batb":[[0,1.52,10.44],[1,1.51,4],[2,1.46,19.32]],"ltp":1.53,"tv":194.28,"id":25651861}]}]}
{"op":"mcm","clk":"11869814355","pt":1723522001267,"mc":[{"id":"1.231652082","rc":[{"batb":[[1,1.46,19.32],[2,1.45,15]],"ltp":1.53,"tv":194.28,"id":25651861}]}]}
{"op":"mcm","clk":"11869814462","pt":1723522003724,"mc":[{"id":"1.231652082","rc":[{"batb":[[0,1.53,4.44]],"ltp":1.53,"tv":194.28,"id":25651861}]}]}
{"op":"mcm","clk":"11869814561","pt":1723522006027,"mc":[{"id":"1.231652082","rc":[{"batb":[[0,1.54,10],[1,1.5,1.05],[2,1.46,18.71]],"ltp":1.53,"tv":194.28,"id":25651861}]}]}
{"op":"mcm","clk":"11869814679","pt":1723522008343,"mc":[{"id":"1.231652082","rc":[{"batb":[[0,1.55,4],[1,1.54,10],[2,1.5,1.05]],"ltp":1.53,"tv":194.28,"id":25651861}]}]}
{"op":"mcm","clk":"11869814715","pt":1723522009367,"mc":[{"id":"1.231652082","rc":[{"batb":[[1,1.5,1.05],[2,1.46,18.71]],"ltp":1.53,"tv":194.28,"id":25651861}]}]}
{"op":"mcm","clk":"11869814792","pt":1723522010546,"mc":[{"id":"1.231652082","rc":[{"batb":[[0,1.5,1.05],[1,1.46,18.71],[2,1.45,15]],"ltp":1.53,"tv":194.28,"id":25651861}]}]}
{"op":"mcm","clk":"11869814905","pt":1723522013052,"mc":[{"id":"1.231652082","rc":[{"batb":[[0,1.52,10.44],[1,1.51,4],[2,1.46,19.32]],"ltp":1.53,"tv":194.28,"id":25651861}]}]}
{"op":"mcm","clk":"11869815006","pt":1723522015252,"mc":[{"id":"1.231652082","rc":[{"batb":[[1,1.46,19.32],[2,1.45,15]],"ltp":1.53,"tv":194.28,"id":25651861}]}]}
{"op":"mcm","clk":"11869815044","pt":1723522016275,"mc":[{"id":"1.231652082","rc":[{"batb":[[0,1.5,1.05],[1,1.46,18.71]],"ltp":1.53,"tv":194.28,"id":25651861}]}]}
{"op":"mcm","clk":"11869815150","pt":1723522018833,"mc":[{"id":"1.231652082","rc":[{"batb":[[0,1.52,10.44],[1,1.51,4],[2,1.46,19.32]],"ltp":1.53,"tv":194.28,"id":25651861}]}]}
{"op":"mcm","clk":"11869815264","pt":1723522020956,"mc":[{"id":"1.231652082","rc":[{"batb":[[1,1.46,19.32],[2,1.45,15]],"ltp":1.53,"tv":194.28,"id":25651861}]}]}
{"op":"mcm","clk":"11869815330","pt":1723522022143,"mc":[{"id":"1.231652082","rc":[{"batb":[[0,1.5,1.05],[1,1.46,18.71]],"ltp":1.53,"tv":194.28,"id":25651861}]}]}
{"op":"mcm","clk":"11869815408","pt":1723522023780,"mc":[{"id":"1.231652082","rc":[{"batb":[[0,1.51,4.44],[1,1.46,19.32]],"ltp":1.53,"tv":194.28,"id":25651861}]}]}
{"op":"mcm","clk":"11869815465","pt":1723522024856,"mc":[{"id":"1.231652082","rc":[{"batb":[[0,1.52,10.44],[1,1.51,4],[2,1.46,19.32]],"ltp":1.53,"tv":194.28,"id":25651861}]}]}
{"op":"mcm","clk":"11869815515","pt":1723522026085,"mc":[{"id":"1.231652082","rc":[{"batb":[[1,1.46,19.32],[2,1.45,15]],"ltp":1.53,"tv":194.28,"id":25651861}]}]}
{"op":"mcm","clk":"11869815602","pt":1723522028080,"mc":[{"id":"1.231652082","rc":[{"batb":[[0,1.5,1.05],[1,1.46,18.71]],"ltp":1.53,"tv":194.28,"id":25651861}]}]}
{"op":"mcm","clk":"11869815665","pt":1723522029165,"mc":[{"id":"1.231652082","rc":[{"batb":[[0,1.51,4.44],[1,1.46,19.32]],"ltp":1.53,"tv":194.28,"id":25651861}]}]}
{"op":"mcm","clk":"11869815715","pt":1723522030291,"mc":[{"id":"1.231652082","rc":[{"batb":[[0,1.52,10.44],[1,1.51,4],[2,1.46,19.32]],"ltp":1.53,"tv":194.28,"id":25651861}]}]}
{"op":"mcm","clk":"11869815777","pt":1723522031568,"mc":[{"id":"1.231652082","rc":[{"batb":[[1,1.46,19.32],[2,1.45,15]],"ltp":1.53,"tv":194.28,"id":25651861}]}]}
{"op":"mcm","clk":"11869815868","pt":1723522033565,"mc":[{"id":"1.231652082","rc":[{"batb":[[0,1.5,1.05],[1,1.46,18.71]],"ltp":1.53,"tv":194.28,"id":25651861}]}]}
{"op":"mcm","clk":"11869815922","pt":1723522034689,"mc":[{"id":"1.231652082","rc":[{"batb":[[0,1.51,4.44],[1,1.46,19.32]],"ltp":1.53,"tv":194.28,"id":25651861}]}]}
{"op":"mcm","clk":"11869815984","pt":1723522035787,"mc":[{"id":"1.231652082","rc":[{"batb":[[0,1.52,10.44],[1,1.51,4],[2,1.46,19.32]],"ltp":1.53,"tv":194.28,"id":25651861}]}]}
{"op":"mcm","clk":"11869816052","pt":1723522036963,"mc":[{"id":"1.231652082","rc":[{"batb":[[1,1.46,19.32],[2,1.45,15]],"ltp":1.53,"tv":194.28,"id":25651861}]}]}
{"op":"mcm","clk":"11869816150","pt":1723522038959,"mc":[{"id":"1.231652082","rc":[{"batb":[[0,1.5,1.05],[1,1.46,18.71]],"ltp":1.53,"tv":194.28,"id":25651861}]}]}
{"op":"mcm","clk":"11869816209","pt":1723522040086,"mc":[{"id":"1.231652082","rc":[{"batb":[[0,1.51,4.44],[1,1.46,19.32]],"ltp":1.53,"tv":194.28,"id":25651861}]}]}
{"op":"mcm","clk":"11869816262","pt":1723522041212,"mc":[{"id":"1.231652082","rc":[{"batb":[[0,1.52,10.44],[1,1.51,4],[2,1.46,19.32]],"ltp":1.53,"tv":194.28,"id":25651861}]}]}
{"op":"mcm","clk":"11869816306","pt":1723522042490,"mc":[{"id":"1.231652082","rc":[{"batb":[[1,1.46,19.32],[2,1.45,15]],"ltp":1.53,"tv":194.28,"id":25651861}]}]}
{"op":"mcm","clk":"11869816415","pt":1723522044689,"mc":[{"id":"1.231652082","rc":[{"batb":[[0,1.51,4.44]],"ltp":1.53,"tv":194.28,"id":25651861}]}]}
{"op":"mcm","clk":"11869816518","pt":1723522046889,"mc":[{"id":"1.231652082","rc":[{"batb":[[0,1.52,10.44]],"ltp":1.53,"tv":194.28,"id":25651861}]}]}
{"op":"mcm","clk":"11869816654","pt":1723522050116,"mc":[{"id":"1.231652082","rc":[{"batb":[[0,1.53,4.44]],"ltp":1.53,"tv":194.28,"id":25651861}]}]}
{"op":"mcm","clk":"11869816782","pt":1723522052628,"mc":[{"id":"1.231652082","rc":[{"batb":[[0,1.54,10],[1,1.5,1.05],[2,1.46,18.71]],"ltp":1.53,"tv":194.28,"id":25651861}]}]}
{"op":"mcm","clk":"11869816889","pt":1723522054823,"mc":[{"id":"1.231652082","rc":[{"batb":[[0,1.55,4],[1,1.54,10],[2,1.5,1.05]],"ltp":1.53,"tv":194.28,"id":25651861}]}]}
{"op":"mcm","clk":"11869816924","pt":1723522055490,"mc":[{"id":"1.231652082","rc":[{"batb":[[1,1.5,1.05],[2,1.46,18.71]],"ltp":1.53,"tv":194.28,"id":25651861}]}]}
{"op":"mcm","clk":"11869817018","pt":1723522057135,"mc":[{"id":"1.231652082","rc":[{"batb":[[0,1.5,1.05],[1,1.46,18.71],[2,1.45,15]],"ltp":1.53,"tv":194.28,"id":25651861}]}]}
{"op":"mcm","clk":"11869817108","pt":1723522059433,"mc":[{"id":"1.231652082","rc":[{"batb":[[0,1.52,10.44],[1,1.51,4],[2,1.46,19.32]],"ltp":1.53,"tv":194.28,"id":25651861}]}]}
{"op":"mcm","clk":"11869817196","pt":1723522061733,"mc":[{"id":"1.231652082","rc":[{"batb":[[1,1.46,19.32],[2,1.45,15]],"ltp":1.53,"tv":194.28,"id":25651861}]}]}
{"op":"mcm","clk":"11869817241","pt":1723522062706,"mc":[{"id":"1.231652082","rc":[{"batb":[[0,1.5,1.05],[1,1.46,18.71]],"ltp":1.53,"tv":194.28,"id":25651861}]}]}
{"op":"mcm","clk":"11869817291","pt":1723522063934,"mc":[{"id":"1.231652082","rc":[{"batb":[[0,1.51,4.44],[1,1.46,19.32]],"ltp":1.53,"tv":194.28,"id":25651861}]}]}
{"op":"mcm","clk":"11869817326","pt":1723522065106,"mc":[{"id":"1.231652082","rc":[{"batb":[[0,1.52,10.44],[1,1.51,4],[2,1.46,19.32]],"ltp":1.53,"tv":194.28,"id":25651861}]}]}
{"op":"mcm","clk":"11869817394","pt":1723522066233,"mc":[{"id":"1.231652082","rc":[{"batb":[[1,1.46,19.32],[2,1.45,15]],"ltp":1.53,"tv":194.28,"id":25651861}]}]}
{"op":"mcm","clk":"11869817536","pt":1723522068639,"mc":[{"id":"1.231652082","rc":[{"batb":[[0,1.51,4.44]],"ltp":1.53,"tv":194.28,"id":25651861}]}]}
{"op":"mcm","clk":"11869817659","pt":1723522071053,"mc":[{"id":"1.231652082","rc":[{"batb":[[0,1.52,10.44]],"ltp":1.53,"tv":194.28,"id":25651861}]}]}
{"op":"mcm","clk":"11869817736","pt":1723522073248,"mc":[{"id":"1.231652082","rc":[{"batb":[[0,1.53,4.44],[1,1.52,10],[2,1.46,19.32]],"ltp":1.53,"tv":194.28,"id":25651861}]}]}
{"op":"mcm","clk":"11869817777","pt":1723522074422,"mc":[{"id":"1.231652082","rc":[{"batb":[[1,1.46,19.32],[2,1.45,15]],"ltp":1.53,"tv":194.28,"id":25651861}]}]}
{"op":"mcm","clk":"11869817823","pt":1723522075651,"mc":[{"id":"1.231652082","rc":[{"batb":[[0,1.5,1.05],[1,1.46,18.71]],"ltp":1.53,"tv":194.28,"id":25651861}]}]}
{"op":"mcm","clk":"11869817899","pt":1723522077350,"mc":[{"id":"1.231652082","rc":[{"batb":[[0,1.47,10.61]],"ltp":1.53,"tv":194.28,"id":25651861}]}]}
{"op":"mcm","clk":"11869817952","pt":1723522078422,"mc":[{"id":"1.231652082","rc":[{"batb":[[0,1.48,4.61],[1,1.47,10],[2,1.46,18.71]],"ltp":1.53,"tv":194.28,"id":25651861}]}]}
{"op":"mcm","clk":"11869818024","pt":1723522080822,"mc":[{"id":"1.231652082","rc":[{"batb":[[0,1.46,19.32],[1,1.45,15],[2,1.25,100]],"ltp":1.53,"tv":194.28,"id":25651861}]}]}
{"op":"mcm","clk":"11869818110","pt":1723522083028,"mc":[{"id":"1.231652082","rc":[{"batb":[[0,1.47,14.61],[1,1.46,18.71],[2,1.45,15]],"ltp":1.53,"tv":194.28,"id":25651861}]}]}
{"op":"mcm","clk":"11869818229","pt":1723522085330,"mc":[{"id":"1.231652082","rc":[{"batb":[[0,1.47,10.61]],"ltp":1.53,"tv":194.28,"id":25651861}]}]}
{"op":"mcm","clk":"11869818263","pt":1723522086353,"mc":[{"id":"1.231652082","rc":[{"batb":[[0,1.46,19.32],[1,1.45,15],[2,1.25,100]],"ltp":1.53,"tv":194.28,"id":25651861}]}]}
{"op":"mcm","clk":"11869818321","pt":1723522087539,"mc":[{"id":"1.231652082","rc":[{"batb":[[0,1.47,4.61],[1,1.46,18.71],[2,1.45,15]],"ltp":1.53,"tv":194.28,"id":25651861}]}]}
{"op":"mcm","clk":"11869818369","pt":1723522088663,"mc":[{"id":"1.231652082","rc":[{"batb":[[0,1.48,10.61],[1,1.47,4],[2,1.46,18.71]],"ltp":1.53,"tv":194.28,"id":25651861}]}]}
{"op":"mcm","clk":"11869818420","pt":1723522090145,"mc":[{"id":"1.231652082","rc":[{"batb":[[0,1.5,1.16],[1,1.48,10]],"ltp":1.53,"tv":194.28,"id":25651861}]}]}
{"op":"mcm","clk":"11869818478","pt":1723522091936,"mc":[{"id":"1.231652082","rc":[{"batb":[[1,1.46,18.71],[2,1.45,15]],"ltp":1.53,"tv":194.28,"id":25651861}]}]}
{"op":"mcm","clk":"11869818520","pt":1723522093067,"mc":[{"id":"1.231652082","rc":[{"batb":[[0,1.51,4.55],[1,1.46,19.32]],"ltp":1.53,"tv":194.28,"id":25651861}]}]}
{"op":"mcm","clk":"11869818582","pt":1723522094294,"mc":[{"id":"1.231652082","rc":[{"batb":[[0,1.52,10.55],[1,1.51,4],[2,1.46,19.32]],"ltp":1.53,"tv":194.28,"id":25651861}]}]}
{"op":"mcm","clk":"11869818648","pt":1723522095470,"mc":[{"id":"1.231652082","rc":[{"batb":[[1,1.46,19.32],[2,1.45,15]],"ltp":1.53,"tv":194.28,"id":25651861}]}]}
{"op":"mcm","clk":"11869818736","pt":1723522097565,"mc":[{"id":"1.231652082","rc":[{"batb":[[0,1.5,1.16],[1,1.46,18.71]],"ltp":1.53,"tv":194.28,"id":25651861}]}]}
{"op":"mcm","clk":"11869835866","pt":1723522566961,"mc":[{"id":"1.231652082","rc":[{"batb":[[1,1.45,14],[2,1.25,100]],"ltp":1.5,"tv":193.55,"id":6847357},{"batb":[[1,1.45,15],[2,1.25,100]],"ltp":1.53,"tv":194.28,"id":25651861}]}]}
{"op":"mcm","clk":"11869836667","pt":1723522587893,"mc":[{"id":"1.231652082","rc":[{"batb":[[1,1.46,18.71],[2,1.45,14]],"ltp":1.5,"tv":193.55,"id":6847357},{"batb":[[1,1.46,18.71],[2,1.45,15]],"ltp":1.53,"tv":194.28,"id":25651861}]}]}
{"op":"mcm","clk":"11869888662","pt":1723524133210,"mc":[{"id":"1.231652082","rc":[{"batb":[[0,1.46,19.22],[1,1.45,14],[2,1.25,100]],"ltp":1.5,"tv":193.55,"id":6847357}]}]}
{"op":"mcm","clk":"11869888769","pt":1723524136182,"mc":[{"id":"1.231652082","rc":[{"batb":[[0,1.46,19.25],[1,1.45,15],[2,1.25,100]],"ltp":1.53,"tv":194.28,"id":25651861}]}]}
{"op":"mcm","clk":"11869899507","pt":1723524388000,"mc":[{"id":"1.231652082","rc":[{"batb":[[0,1.45,14.51],[1,1.25,100],[2,1.03,200]],"ltp":1.5,"tv":193.55,"id":6847357}]}]}
{"op":"mcm","clk":"11869899511","pt":1723524388205,"mc":[{"id":"1.231652082","rc":[{"batb":[[0,1.45,15.55],[1,1.25,100],[2,1.03,200]],"ltp":1.53,"tv":194.28,"id":25651861}]}]}
{"op":"mcm","clk":"11869899672","pt":1723524394634,"mc":[{"id":"1.231652082","rc":[{"batb":[[0,1.46,19.22],[1,1.45,14],[2,1.25,100]],"ltp":1.5,"tv":193.55,"id":6847357},{"batb":[[0,1.46,19.25],[1,1.45,15],[2,1.25,100]],"ltp":1.53,"tv":194.28,"id":25651861}]}]}
{"op":"mcm","clk":"11869951204","pt":1723525974803,"mc":[{"id":"1.231652082","rc":[{"trd":[[1.5,193.5]],"batb":[[0,1.46,19.21]],"ltp":1.5,"tv":193.49,"id":6847357},{"trd":[[1.5,194.09]],"batb":[[0,1.46,19.25]],"ltp":1.53,"tv":194.23,"id":25651861}],"tv":387.73}]}
{"op":"mcm","clk":"11869964247","pt":1723526195002,"mc":[{"id":"1.231652082","rc":[{"batb":[[0,1.45,14.51],[1,1.25,100],[2,1.03,200]],"ltp":1.5,"tv":193.49,"id":6847357},{"batb":[[0,1.45,15.55],[1,1.25,100],[2,1.03,200]],"ltp":1.53,"tv":194.23,"id":25651861}]}]}
{"op":"mcm","clk":"11869964274","pt":1723526195992,"mc":[{"id":"1.231652082","rc":[{"batb":[[0,1.46,19.21],[1,1.45,14],[2,1.25,100]],"ltp":1.5,"tv":193.49,"id":6847357},{"batb":[[0,1.46,19.25],[1,1.45,15],[2,1.25,100]],"ltp":1.53,"tv":194.23,"id":25651861}]}]}
{"op":"mcm","clk":"11870009427","pt":1723527996347,"mc":[{"id":"1.231652082","rc":[{"batb":[[0,1.45,14.51],[1,1.25,100],[2,1.03,200]],"ltp":1.5,"tv":193.49,"id":6847357},{"batb":[[0,1.45,15.55],[1,1.25,100],[2,1.03,200]],"ltp":1.53,"tv":194.23,"id":25651861}]}]}
{"op":"mcm","clk":"11870012531","pt":1723528115398,"mc":[{"id":"1.231652082","rc":[{"batb":[[0,1.46,19.21],[1,1.45,14],[2,1.25,100]],"ltp":1.5,"tv":193.49,"id":6847357},{"batb":[[0,1.46,19.25],[1,1.45,15],[2,1.25,100]],"ltp":1.53,"tv":194.23,"id":25651861}]}]}
{"op":"mcm","clk":"11870028982","pt":1723528909665,"mc":[{"id":"1.231652082","rc":[{"trd":[[1.5,193.5]],"batb":[[0,1.47,14.51],[1,1.46,18.7]],"ltp":1.5,"tv":193.49,"id":6847357},{"trd":[[1.5,194.09]],"batb":[[0,1.47,15.55],[1,1.46,18.7]],"ltp":1.53,"tv":194.22,"id":25651861}],"tv":387.72}]}
{"op":"mcm","clk":"11870056823","pt":1723529915751,"mc":[{"id":"1.231652082","rc":[{"batb":[[1,1.25,100],[2,1.03,200]],"ltp":1.5,"tv":193.49,"id":6847357},{"batb":[[1,1.25,100],[2,1.03,200]],"ltp":1.53,"tv":194.22,"id":25651861}]}]}
{"op":"mcm","clk":"11870058860","pt":1723530034975,"mc":[{"id":"1.231652082","rc":[{"batb":[[0,1.48,18.43],[1,1.47,14],[2,1.25,100]],"ltp":1.5,"tv":193.49,"id":6847357},{"batb":[[0,1.48,18.47],[1,1.47,15],[2,1.25,100]],"ltp":1.53,"tv":194.22,"id":25651861}]}]}
{"op":"mcm","clk":"11870114170","pt":1723531835109,"mc":[{"id":"1.231652082","rc":[{"batb":[[0,1.47,14.51],[1,1.25,100],[2,1.03,200]],"ltp":1.5,"tv":193.49,"id":6847357}]}]}
{"op":"mcm","clk":"11870114175","pt":1723531835315,"mc":[{"id":"1.231652082","rc":[{"batb":[[0,1.47,15.55],[1,1.25,100],[2,1.03,200]],"ltp":1.53,"tv":194.22,"id":25651861}]}]}
{"op":"mcm","clk":"11870117306","pt":1723531955777,"mc":[{"id":"1.231652082","rc":[{"batb":[[0,1.48,18.43],[1,1.47,14],[2,1.25,100]],"ltp":1.5,"tv":193.49,"id":6847357},{"batb":[[0,1.48,18.47],[1,1.47,15],[2,1.25,100]],"ltp":1.53,"tv":194.22,"id":25651861}]}]}
{"op":"mcm","clk":"11870164483","pt":1723533756022,"mc":[{"id":"1.231652082","rc":[{"trd":[[1.5,193.11]],"batb":[[0,1.47,14.51],[1,1.25,100],[2,1.03,200]],"ltp":1.5,"tv":193.11,"id":6847357},{"trd":[[1.5,193.7]],"batb":[[0,1.48,18.42]],"ltp":1.53,"tv":193.84,"id":25651861}],"tv":386.95}]}
{"op":"mcm","clk":"11870164487","pt":1723533756227,"mc":[{"id":"1.231652082","rc":[{"batb":[[0,1.47,15.54],[1,1.25,100],[2,1.03,200]],"ltp":1.53,"tv":193.84,"id":25651861}]}]}
{"op":"mcm","clk":"11870166361","pt":1723533823861,"mc":[{"id":"1.231652082","rc":[{"batb":[[0,1.48,18.39],[1,1.47,14],[2,1.25,100]],"ltp":1.5,"tv":193.11,"id":6847357},{"batb":[[0,1.48,18.42],[1,1.47,15],[2,1.25,100]],"ltp":1.53,"tv":193.84,"id":25651861}]}]}
{"op":"mcm","clk":"11870207532","pt":1723535624050,"mc":[{"id":"1.231652082","rc":[{"batb":[[0,1.47,15.54],[1,1.25,100],[2,1.03,200]],"ltp":1.53,"tv":193.84,"id":25651861}]}]}
{"op":"mcm","clk":"11870207538","pt":1723535624256,"mc":[{"id":"1.231652082","rc":[{"batb":[[0,1.47,14.51],[1,1.25,100],[2,1.03,200]],"ltp":1.5,"tv":193.11,"id":6847357}]}]}
{"op":"mcm","clk":"11870208481","pt":1723535672678,"mc":[{"id":"1.231652082","rc":[{"batb":[[0,1.48,18.39],[1,1.47,14],[2,1.25,100]],"ltp":1.5,"tv":193.11,"id":6847357},{"batb":[[0,1.48,18.42],[1,1.47,15],[2,1.25,100]],"ltp":1.53,"tv":193.84,"id":25651861}]}]}
{"op":"mcm","clk":"11870214870","pt":1723536040244,"mc":[{"id":"1.231652082","rc":[{"trd":[[1.5,193.02]],"batb":[[0,1.48,18.38]],"ltp":1.5,"tv":193.02,"id":6847357},{"trd":[[1.5,193.62],[1.56,0.24]],"batb":[[0,1.48,18.29]],"ltp":1.56,"tv":194.0,"id":25651861}],"tv":387.02}]}
{"op":"mcm","clk":"11870215329","pt":1723536060817,"mc":[{"id":"1.231652082","rc":[{"trd":[[1.56,0.86]],"batb":[[0,1.48,17.98]],"ltp":1.56,"tv":194.61,"id":25651861}],"tv":387.63}]}
{"op":"mcm","clk":"11870215909","pt":1723536084758,"mc":[{"id":"1.231652082","rc":[{"trd":[[1.48,0.99],[1.56,1.09]],"batb":[[0,1.48,17.37]],"ltp":1.48,"tv":195.83,"id":25651861}],"tv":388.85}]}
{"op":"mcm","clk":"11870216155","pt":1723536095223,"mc":[{"id":"1.231652082","rc":[{"trd":[[1.48,2.21]],"batb":[[0,1.48,16.76]],"ltp":1.48,"tv":197.05,"id":25651861}],"tv":390.08}]}
{"op":"mcm","clk":"11870216568","pt":1723536111076,"mc":[{"id":"1.231652082","rc":[{"trd":[[1.48,5.52]],"batb":[[0,1.48,15.11]],"ltp":1.48,"tv":200.35,"id":25651861}],"tv":393.38}]}
{"op":"mcm","clk":"11870219383","pt":1723536220028,"mc":[{"id":"1.231652082","rc":[{"trd":[[1.53,0.12]],"batb":[[0,1.48,18.31]],"ltp":1.53,"tv":193.14,"id":6847357}],"tv":393.5}]}
{"op":"mcm","clk":"11870219598","pt":1723536229127,"mc":[{"id":"1.231652082","rc":[{"trd":[[1.53,0.24]],"batb":[[0,1.48,18.25]],"ltp":1.53,"tv":193.26,"id":6847357}],"tv":393.62}]}
{"op":"mcm","clk":"11870227169","pt":1723536499162,"mc":[{"id":"1.231652082","rc":[{"batb":[[0,1.48,15.65]],"ltp":1.48,"tv":200.35,"id":25651861}]}]}
{"op":"mcm","clk":"11870243713","pt":1723536812224,"mc":[{"id":"1.231652082","rc":[{"batb":[[0,1.48,15.11]],"ltp":1.48,"tv":200.35,"id":25651861}]}]}
{"op":"mcm","clk":"11870259869","pt":1723537473016,"mc":[{"id":"1.231652082","rc":[{"batb":[[0,1.47,14.39],[1,1.25,100],[2,1.03,200]],"ltp":1.53,"tv":193.26,"id":6847357},{"batb":[[0,1.47,15],[1,1.25,100],[2,1.03,200]],"ltp":1.48,"tv":200.35,"id":25651861}]}]}
{"op":"mcm","clk":"11870261322","pt":1723537524269,"mc":[{"id":"1.231652082","rc":[{"batb":[[0,1.48,18.25],[1,1.47,14],[2,1.25,100]],"ltp":1.53,"tv":193.26,"id":6847357}]}]}
{"op":"mcm","clk":"11870280508","pt":1723538227145,"mc":[{"id":"1.231652082","rc":[{"batb":[[0,1.53,1.34],[1,1.48,17.87],[2,1.47,14]],"ltp":1.53,"tv":193.26,"id":6847357}]}]}
{"op":"mcm","clk":"11870280778","pt":1723538239162,"mc":[{"id":"1.231652082","rc":[{"batb":[[0,1.47,15.95]],"ltp":1.48,"tv":200.35,"id":25651861}]}]}
{"op":"mcm","clk":"11870313394","pt":1723539324454,"mc":[{"id":"1.231652082","rc":[{"batb":[[1,1.47,14],[2,1.25,100]],"ltp":1.53,"tv":193.26,"id":6847357}]}]}
{"op":"mcm","clk":"11870314778","pt":1723539372832,"mc":[{"id":"1.231652082","rc":[{"batb":[[1,1.48,17.87],[2,1.47,14]],"ltp":1.53,"tv":193.26,"id":6847357}]}]}
{"op":"mcm","clk":"11870326451","pt":1723539735709,"mc":[{"id":"1.231652082","rc":[{"trd":[[1.5,193.17],[2.82,0.06]],"batb":[[0,1.53,1.34],[1,1.48,17.87]],"ltp":2.82,"tv":193.47,"id":6847357},{"trd":[[1.48,5.52],[1.5,193.76],[1.55,0.11]],"batb":[[0,1.47,15.84]],"ltp":1.55,"tv":200.61,"id":25651861}],"tv":394.09}]}
{"op":"mcm","clk":"11870377522","pt":1723541172964,"mc":[{"id":"1.231652082","rc":[{"batb":[[1,1.47,14],[2,1.25,100]],"ltp":2.82,"tv":193.47,"id":6847357}]}]}
{"op":"mcm","clk":"11870379268","pt":1723541217290,"mc":[{"id":"1.231652082","rc":[{"batb":[[1,1.48,17.87],[2,1.47,14]],"ltp":2.82,"tv":193.47,"id":6847357}]}]}
{"op":"mcm","clk":"11870398631","pt":1723541704157,"mc":[{"id":"1.231652082","rc":[{"batb":[[0,1.48,18.26],[1,1.47,14],[2,1.25,100]],"ltp":2.82,"tv":193.47,"id":6847357}]}]}
{"op":"mcm","clk":"11870398634","pt":1723541704211,"mc":[{"id":"1.231652082","rc":[{"batb":[[0,1.53,1.34],[1,1.48,17.87],[2,1.47,14]],"ltp":2.82,"tv":193.47,"id":6847357}]}]}
{"op":"mcm","clk":"11870457382","pt":1723543017523,"mc":[{"id":"1.231652082","rc":[{"batb":[[1,1.47,14],[2,1.25,100]],"ltp":2.82,"tv":193.47,"id":6847357}]}]}
{"op":"mcm","clk":"11870458604","pt":1723543047756,"mc":[{"id":"1.231652082","rc":[{"batb":[[1,1.48,17.87],[2,1.47,14]],"ltp":2.82,"tv":193.47,"id":6847357}]}]}
{"op":"mcm","clk":"11870541375","pt":1723544847858,"mc":[{"id":"1.231652082","rc":[{"trd":[[1.5,193.26]],"batb":[[1,1.47,14],[2,1.25,100]],"ltp":2.82,"tv":193.57,"id":6847357},{"trd":[[1.48,5.52],[1.5,193.86]],"ltp":1.55,"tv":200.71,"id":25651861}],"tv":394.28}]}
{"op":"mcm","clk":"11870541739","pt":1723544856195,"mc":[{"id":"1.231652082","rc":[{"batb":[[1,1.48,17.87],[2,1.47,14]],"ltp":2.82,"tv":193.57,"id":6847357}]}]}
{"op":"mcm","clk":"11870613586","pt":1723546656404,"mc":[{"id":"1.231652082","rc":[{"batb":[[1,1.47,14],[2,1.25,100]],"ltp":2.82,"tv":193.57,"id":6847357}]}]}
{"op":"mcm","clk":"11870614468","pt":1723546682024,"mc":[{"id":"1.231652082","rc":[{"batb":[[1,1.48,17.87],[2,1.47,14]],"ltp":2.82,"tv":193.57,"id":6847357}]}]}
{"op":"mcm","clk":"11870650758","pt":1723547420837,"mc":[{"id":"1.231652082","rc":[{"trd":[[1.5,193.41]],"batb":[[0,1.74,17.32],[1,1.53,1.34],[2,1.48,17.89]],"ltp":2.82,"tv":193.71,"id":6847357},{"trd":[[1.48,5.52],[1.5,194]],"batb":[[0,1.74,17.32],[1,1.47,15.84],[2,1.25,100]],"ltp":1.55,"tv":200.87,"id":25651861}],"tv":394.58}]}
{"op":"mcm","clk":"11870701801","pt":1723548482163,"mc":[{"id":"1.231652082","rc":[{"batb":[[2,1.47,14]],"ltp":2.82,"tv":193.71,"id":6847357}]}]}
{"op":"mcm","clk":"11870750474","pt":1723549742132,"mc":[{"id":"1.231652082","rc":[{"batb":[[1,1.47,14.39],[2,1.25,100]],"ltp":2.82,"tv":193.71,"id":6847357},{"batb":[[1,1.47,15]],"ltp":1.55,"tv":200.87,"id":25651861}]}]}
{"op":"mcm","clk":"11870750478","pt":1723549742337,"mc":[{"id":"1.231652082","rc":[{"trd":[[1.74,0.2]],"batb":[[0,1.74,17.22]],"ltp":1.74,"tv":201.07,"id":25651861}],"tv":394.78}]}
{"op":"mcm","clk":"11870895839","pt":1723552974792,"mc":[{"id":"1.231652082","rc":[{"trd":[[1.5,193.3]],"ltp":2.82,"tv":193.61,"id":6847357},{"trd":[[1.48,5.52],[1.5,193.9]],"ltp":1.74,"tv":200.96,"id":25651861}],"tv":394.57}]}
{"op":"mcm","clk":"11870969792","pt":1723554688228,"mc":[{"id":"1.231652082","rc":[{"trd":[[1.5,193.06]],"batb":[[1,1.47,14]],"ltp":2.82,"tv":193.36,"id":6847357},{"trd":[[1.48,5.52],[1.5,193.65],[1.56,1.09]],"ltp":1.74,"tv":200.71,"id":25651861}],"tv":394.07}]}
{"op":"mcm","clk":"11870969924","pt":1723554692190,"mc":[{"id":"1.231652082","rc":[{"trd":[[1.74,1.08]],"batb":[[0,1.74,16.78]],"ltp":1.74,"tv":201.59,"id":25651861}],"tv":394.95}]}
{"op":"mcm","clk":"11871151519","pt":1723558374795,"mc":[{"id":"1.231652082","rc":[{"trd":[[1.5,192.88]],"ltp":2.82,"tv":193.18,"id":6847357},{"trd":[[1.5,193.47],[1.56,1.09]],"ltp":1.74,"tv":201.4,"id":25651861}],"tv":394.58}]}
{"op":"mcm","clk":"11871321295","pt":1723561311082,"mc":[{"id":"1.231652082","rc":[{"trd":[[1.5,192.82]],"batb":[[0,1.81,8.89],[1,1.74,17.32],[2,1.47,14]],"ltp":2.82,"tv":193.12,"id":6847357},{"trd":[[1.48,5.52],[1.5,193.41]],"batb":[[0,1.96,8.2],[1,1.74,16.78],[2,1.47,15]],"ltp":1.74,"tv":201.34,"id":25651861}],"tv":394.46}]}
{"op":"mcm","clk":"11871322202","pt":1723561325999,"mc":[{"id":"1.231652082","rc":[{"batb":[[0,1.79,8.97]],"ltp":2.82,"tv":193.12,"id":6847357},{"batb":[[0,1.98,8.12]],"ltp":1.74,"tv":201.34,"id":25651861}]}]}
{"op":"mcm","clk":"11871456373","pt":1723563456448,"mc":[{"id":"1.231652082","rc":[{"batb":[[0,1.74,17.32],[1,1.47,14],[2,1.25,100]],"ltp":2.82,"tv":193.12,"id":6847357},{"batb":[[0,1.74,16.78],[1,1.47,15],[2,1.25,100]],"ltp":1.74,"tv":201.34,"id":25651861}]}]}
{"op":"mcm","clk":"11871719501","pt":1723566672124,"mc":[{"id":"1.231652082","rc":[{"trd":[[1.5,192.77]],"batb":[[0,1.81,8.88],[1,1.74,17.32],[2,1.47,14]],"ltp":2.82,"tv":193.07,"id":6847357},{"trd":[[1.48,5.51],[1.5,193.36]],"ltp":1.74,"tv":201.29,"id":25651861}],"tv":394.37}]}
{"op":"mcm","clk":"11871719512","pt":1723566672228,"mc":[{"id":"1.231652082","rc":[{"batb":[[0,1.96,8.2],[1,1.74,16.78],[2,1.47,15]],"ltp":1.74,"tv":201.29,"id":25651861}]}]}
{"op":"mcm","clk":"11871720482","pt":1723566685237,"mc":[{"id":"1.231652082","rc":[{"batb":[[0,1.79,8.99]],"ltp":2.82,"tv":193.07,"id":6847357},{"batb":[[0,1.99,8.09]],"ltp":1.74,"tv":201.29,"id":25651861}]}]}
{"op":"mcm","clk":"11871855190","pt":1723568385116,"mc":[{"id":"1.231652082","rc":[{"batb":[[0,1.81,46.84],[1,1.79,8.99],[2,1.74,17.32]],"ltp":2.82,"tv":193.07,"id":6847357},{"batb":[[0,2.14,33.28],[1,1.99,8.09],[2,1.74,16.78]],"ltp":1.74,"tv":201.29,"id":25651861}]}]}
{"op":"mcm","clk":"11871857149","pt":1723568406530,"mc":[{"id":"1.231652082","rc":[{"trd":[[1.5,192.45]],"batb":[[1,1.77,9.06]],"ltp":2.82,"tv":192.75,"id":6847357},{"trd":[[1.48,5.51],[1.5,193.04],[1.56,1.09]],"batb":[[1,1.99,8.09]],"ltp":1.74,"tv":200.97,"id":25651861}],"tv":393.73}]}
{"op":"mcm","clk":"11871871516","pt":1723568556498,"mc":[{"id":"1.231652082","rc":[{"batb":[[1,2.02,7.95]],"ltp":1.74,"tv":200.97,"id":25651861}]}]}
{"op":"mcm","clk":"11871874256","pt":1723568586325,"mc":[{"id":"1.231652082","rc":[{"batb":[[1,1.74,17.32],[2,1.47,14]],"ltp":2.82,"tv":192.75,"id":6847357},{"batb":[[1,1.74,16.78],[2,1.47,15]],"ltp":1.74,"tv":200.97,"id":25651861}]}]}
{"op":"mcm","clk":"11872396290","pt":1723573236004,"mc":[{"id":"1.231652082","rc":[{"trd":[[1.5,192.36]],"ltp":2.82,"tv":192.66,"id":6847357},{"trd":[[1.48,5.51],[1.5,192.95]],"ltp":1.74,"tv":200.87,"id":25651861}],"tv":393.53}]}
{"op":"mcm","clk":"11872427566","pt":1723573454101,"mc":[{"id":"1.231652082","rc":[{"trd":[[2.14,0.42]],"batb":[[0,2.14,33.07]],"ltp":2.14,"tv":201.28,"id":25651861}],"tv":393.95}]}
{"op":"mcm","clk":"11872428208","pt":1723573458937,"mc":[{"id":"1.231652082","rc":[{"batb":[[0,2.14,33.28]],"ltp":2.14,"tv":201.28,"id":25651861}]}]}
{"op":"mcm","clk":"11873302484","pt":1723578498160,"mc":[{"id":"1.231652082","rc":[{"trd":[[1.5,192.13]],"batl":[[0,1.83,328.72]],"ltp":2.82,"tv":192.43,"id":6847357},{"trd":[[1.5,192.72],[1.56,1.08]],"ltp":2.14,"tv":201.05,"id":25651861}],"tv":393.49}]}
{"op":"mcm","clk":"11873303297","pt":1723578503147,"mc":[{"id":"1.231652082","rc":[{"trd":[[1.83,657.44]],"ltp":1.83,"tv":849.88,"id":6847357}],"tv":1050.94}]}
{"op":"mcm","clk":"11873306620","pt":1723578524987,"mc":[{"id":"1.231652082","rc":[{"batl":[[0,1.83,328.72]],"ltp":1.83,"tv":849.88,"id":6847357}]}]}
{"op":"mcm","clk":"11873307098","pt":1723578528167,"mc":[{"id":"1.231652082","rc":[{"trd":[[1.83,1313.34]],"batl":[[0,1.83,0.78]],"ltp":1.83,"tv":1505.77,"id":6847357}],"tv":1706.83}]}
{"op":"mcm","clk":"11873309119","pt":1723578540989,"mc":[{"id":"1.231652082","rc":[{"trd":[[1.81,1.56]],"batb":[[0,1.81,46.06]],"ltp":1.81,"tv":1507.33,"id":6847357}],"tv":1708.39}]}
{"op":"mcm","clk":"11873309584","pt":1723578543786,"mc":[{"id":"1.231652082","rc":[{"batb":[[0,1.81,46.84]],"ltp":1.81,"tv":1507.33,"id":6847357}]}]}
{"op":"mcm","clk":"11873309987","pt":1723578546112,"mc":[{"id":"1.231652082","rc":[{"trd":[[1.88,0.75]],"ltp":1.88,"tv":1508.09,"id":6847357},{"trd":[[2.14,1.08]],"batb":[[0,2.14,32.62]],"ltp":2.14,"tv":201.71,"id":25651861}],"tv":1709.81}]}
{"op":"mcm","clk":"11873310430","pt":1723578548735,"mc":[{"id":"1.231652082","rc":[{"batb":[[0,2.14,33.28]],"ltp":2.14,"tv":201.71,"id":25651861}]}]}
{"op":"mcm","clk":"11873315423","pt":1723578576551,"mc":[{"id":"1.231652082","rc":[{"batl":[[0,1.85,328.72]],"ltp":1.88,"tv":1508.09,"id":6847357}]}]}
{"op":"mcm","clk":"11873316575","pt":1723578583237,"mc":[{"id":"1.231652082","rc":[{"trd":[[1.85,657.44]],"ltp":1.85,"tv":2165.53,"id":6847357}],"tv":2367.25}]}
{"op":"mcm","clk":"11873320380","pt":1723578606181,"mc":[{"id":"1.231652082","rc":[{"batl":[[0,1.85,328.72]],"ltp":1.85,"tv":2165.53,"id":6847357}]}]}
{"op":"mcm","clk":"11873321538","pt":1723578612683,"mc":[{"id":"1.231652082","rc":[{"trd":[[1.85,1314.89]],"ltp":1.85,"tv":2822.98,"id":6847357}],"tv":3024.7}]}
{"op":"mcm","clk":"11873326580","pt":1723578641545,"mc":[{"id":"1.231652082","rc":[{"batl":[[0,1.84,328.72]],"ltp":1.85,"tv":2822.98,"id":6847357}]}]}
{"op":"mcm","clk":"11873327111","pt":1723578644539,"mc":[{"id":"1.231652082","rc":[{"batl":[[0,1.84,332.72]],"ltp":1.85,"tv":2822.98,"id":6847357},{"batb":[[0,2.2,4],[1,2.18,4],[2,2.14,33.28]],"ltp":2.14,"tv":201.71,"id":25651861}]}]}
{"op":"mcm","clk":"11873329404","pt":1723578657635,"mc":[{"id":"1.231652082","rc":[{"batl":[[0,1.83,328.72],[1,1.84,4]],"ltp":1.85,"tv":2822.98,"id":6847357}]}]}
{"op":"mcm","clk":"11873329770","pt":1723578659522,"mc":[{"id":"1.231652082","rc":[{"batl":[[0,1.83,332.72]],"ltp":1.85,"tv":2822.98,"id":6847357}]}]}
{"op":"mcm","clk":"11873330683","pt":1723578664677,"mc":[{"id":"1.231652082","rc":[{"batl":[[0,1.83,4]],"ltp":1.85,"tv":2822.98,"id":6847357}]}]}
{"op":"mcm","clk":"11873330808","pt":1723578665356,"mc":[{"id":"1.231652082","rc":[{"batb":[[0,2.14,33.28],[1,1.74,16.78],[2,1.47,15]],"ltp":2.14,"tv":201.71,"id":25651861}]}]}
{"op":"mcm","clk":"11873332485","pt":1723578674656,"mc":[{"id":"1.231652082","rc":[{"batb":[[0,2.14,37.28]],"batl":[[0,2.24,4]],"ltp":2.14,"tv":201.71,"id":25651861}]}]}
{"op":"mcm","clk":"11873332595","pt":1723578675272,"mc":[{"id":"1.231652082","rc":[{"batb":[[0,2.16,10],[1,2.14,37.28],[2,1.74,16.78]],"ltp":2.14,"tv":201.71,"id":25651861}]}]}
{"op":"mcm","clk":"11873333309","pt":1723578679246,"mc":[{"id":"1.231652082","rc":[{"batb":[[0,2.14,37.28],[1,1.74,16.78],[2,1.47,15]],"ltp":2.14,"tv":201.71,"id":25651861}]}]}
{"op":"mcm","clk":"11873335310","pt":1723578690591,"mc":[{"id":"1.231652082","rc":[{"batb":[[0,2.16,10],[1,2.14,37.28],[2,1.74,16.78]],"ltp":2.14,"tv":201.71,"id":25651861}]}]}
{"op":"mcm","clk":"11873335990","pt":1723578694676,"mc":[{"id":"1.231652082","rc":[{"batb":[[0,2.14,37.28],[1,1.74,16.78],[2,1.47,15]],"ltp":2.14,"tv":201.71,"id":25651861}]}]}
{"op":"mcm","clk":"11873336575","pt":1723578697778,"mc":[{"id":"1.231652082","rc":[{"batb":[[0,2.16,10],[1,2.14,37.28],[2,1.74,16.78]],"ltp":2.14,"tv":201.71,"id":25651861}]}]}
{"op":"mcm","clk":"11873337253","pt":1723578701625,"mc":[{"id":"1.231652082","rc":[{"batb":[[0,2.14,37.28],[1,1.74,16.78],[2,1.47,15]],"ltp":2.14,"tv":201.71,"id":25651861}]}]}
{"op":"mcm","clk":"11873337956","pt":1723578705332,"mc":[{"id":"1.231652082","rc":[{"batb":[[0,2.16,10],[1,2.14,37.28],[2,1.74,16.78]],"ltp":2.14,"tv":201.71,"id":25651861}]}]}
{"op":"mcm","clk":"11873338611","pt":1723578709032,"mc":[{"id":"1.231652082","rc":[{"batb":[[0,2.14,37.28],[1,1.74,16.78],[2,1.47,15]],"ltp":2.14,"tv":201.71,"id":25651861}]}]}
{"op":"mcm","clk":"11873339034","pt":1723578711462,"mc":[{"id":"1.231652082","rc":[{"batb":[[0,2.16,10],[1,2.14,37.28],[2,1.74,16.78]],"ltp":2.14,"tv":201.71,"id":25651861}]}]}
{"op":"mcm","clk":"11873339611","pt":1723578714941,"mc":[{"id":"1.231652082","rc":[{"batb":[[0,2.14,37.28],[1,1.74,16.78],[2,1.47,15]],"ltp":2.14,"tv":201.71,"id":25651861}]}]}
{"op":"mcm","clk":"11873340235","pt":1723578718428,"mc":[{"id":"1.231652082","rc":[{"batb":[[0,2.16,10],[1,2.14,37.28],[2,1.74,16.78]],"ltp":2.14,"tv":201.71,"id":25651861}]}]}
{"op":"mcm","clk":"11873340501","pt":1723578720160,"mc":[{"id":"1.231652082","rc":[{"batb":[[0,1.82,4],[1,1.81,50.84],[2,1.74,17.32]],"batl":[[0,1.87,4]],"ltp":1.85,"tv":2822.98,"id":6847357},{"batb":[[0,2.16,14]],"ltp":2.14,"tv":201.71,"id":25651861}]}]}
{"op":"mcm","clk":"11873340907","pt":1723578722446,"mc":[{"id":"1.231652082","rc":[{"batb":[[0,2.16,4]],"ltp":2.14,"tv":201.71,"id":25651861}]}]}
{"op":"mcm","clk":"11873343219","pt":1723578735262,"mc":[{"id":"1.231652082","rc":[{"batl":[[0,2.22,4],[1,2.24,4]],"ltp":2.14,"tv":201.71,"id":25651861}]}]}
{"op":"mcm","clk":"11873503673","pt":1723579844077,"mc":[{"id":"1.231652082","rc":[{"trd":[[1.5,192.18],[1.83,1313.54],[1.85,1315.09]],"batl":[[0,1.86,2],[1,1.87,4]],"ltp":1.85,"tv":2823.43,"id":6847357},{"trd":[[1.5,192.77]],"ltp":2.14,"tv":201.76,"id":25651861}],"tv":3025.2}]}
{"op":"mcm","clk":"11873573910","pt":1723580271132,"mc":[{"id":"1.231652082","rc":[{"batb":[[0,1.82,8.49]],"ltp":1.85,"tv":2823.43,"id":6847357}]}]}
{"op":"mcm","clk":"11873730831","pt":1723582025904,"mc":[{"id":"1.231652082","rc":[{"trd":[[1.82,15.38]],"batb":[[0,1.81,51.63],[1,1.74,17.32],[2,1.47,14]],"ltp":1.82,"tv":2838.82,"id":6847357}],"tv":3040.59}]}
{"op":"mcm","clk":"11873730942","pt":1723582028009,"mc":[{"id":"1.231652082","rc":[{"batb":[[0,1.81,50.84]],"ltp":1.82,"tv":2838.82,"id":6847357}]}]}
{"op":"mcm","clk":"11873731074","pt":1723582030220,"mc":[{"id":"1.231652082","rc":[{"batl":[[1,1.87,7.59]],"ltp":1.82,"tv":2838.82,"id":6847357}]}]}
{"op":"mcm","clk":"11873731468","pt":1723582037019,"mc":[{"id":"1.231652082","rc":[{"batl":[[0,1.86,6]],"ltp":1.82,"tv":2838.82,"id":6847357}]}]}
{"op":"mcm","clk":"11873731814","pt":1723582043139,"mc":[{"id":"1.231652082","rc":[{"trd":[[1.81,107.96]],"batb":[[0,1.74,17.32],[1,1.47,14],[2,1.45,57.31]],"batl":[[0,1.86,2]],"ltp":1.81,"tv":2945.21,"id":6847357},{"trd":[[2.22,3.84]],"ltp":2.22,"tv":205.6,"id":25651861}],"tv":3150.82}]}
{"op":"mcm","clk":"11873732049","pt":1723582046912,"mc":[{"id":"1.231652082","rc":[{"batb":[[0,1.77,49.27],[1,1.74,17.32],[2,1.47,14]],"ltp":1.81,"tv":2945.21,"id":6847357}]}]}
{"op":"mcm","clk":"11873744960","pt":1723582273868,"mc":[{"id":"1.231652082","rc":[{"batb":[[2,1.45,57.31]],"ltp":1.81,"tv":2945.21,"id":6847357}]}]}
{"op":"mcm","clk":"11873907710","pt":1723585374802,"mc":[{"id":"1.231652082","rc":[{"trd":[[1.5,192.21],[1.83,1313.85],[1.85,1315.4]],"batb":[[2,1.45,57.3]],"ltp":1.81,"tv":2945.85,"id":6847357},{"trd":[[1.5,192.8]],"ltp":2.22,"tv":205.64,"id":25651861}],"tv":3151.5}]}
{"op":"mcm","clk":"11874290688","pt":1723590774801,"mc":[{"id":"1.231652082","rc":[{"trd":[[1.5,192.19],[1.81,107.97],[1.82,15.39]],"batb":[[2,1.45,57.31]],"ltp":1.81,"tv":2945.84,"id":6847357},{"trd":[[1.5,192.77]],"ltp":2.22,"tv":205.61,"id":25651861}],"tv":3151.46}]}
{"op":"mcm","clk":"11874398149","pt":1723591990664,"mc":[{"id":"1.231652082","rc":[{"trd":[[1.77,90.16]],"batb":[[0,1.74,17.32],[1,1.73,51.97]],"ltp":1.77,"tv":3036.0,"id":6847357}],"tv":3241.62}]}
{"op":"mcm","clk":"11874406421","pt":1723592093798,"mc":[{"id":"1.231652082","rc":[{"batb":[[0,1.75,141.1],[1,1.74,17.32],[2,1.73,51.97]],"ltp":1.77,"tv":3036.0,"id":6847357}]}]}
{"op":"mcm","clk":"11874407397","pt":1723592105974,"mc":[{"id":"1.231652082","rc":[{"batb":[[0,1.76,38.17],[1,1.75,141.1],[2,1.74,17.32]],"ltp":1.77,"tv":3036.0,"id":6847357}]}]}
{"op":"mcm","clk":"11874408600","pt":1723592121341,"mc":[{"id":"1.231652082","rc":[{"batb":[[1,1.74,17.32],[2,1.73,51.97]],"ltp":1.77,"tv":3036.0,"id":6847357}]}]}
{"op":"mcm","clk":"11874411266","pt":1723592153841,"mc":[{"id":"1.231652082","rc":[{"batb":[[0,1.74,17.32],[1,1.73,51.97],[2,1.45,57.31]],"ltp":1.77,"tv":3036.0,"id":6847357}]}]}
{"op":"mcm","clk":"11874412146","pt":1723592164499,"mc":[{"id":"1.231652082","rc":[{"batb":[[0,1.77,143.63],[1,1.74,17.32],[2,1.73,51.97]],"ltp":1.77,"tv":3036.0,"id":6847357}]}]}
{"op":"mcm","clk":"11874412811","pt":1723592172572,"mc":[{"id":"1.231652082","rc":[{"batb":[[0,1.74,17.32],[1,1.73,51.97],[2,1.45,57.31]],"ltp":1.77,"tv":3036.0,"id":6847357}]}]}
{"op":"mcm","clk":"11874414530","pt":1723592196026,"mc":[{"id":"1.231652082","rc":[{"batb":[[0,1.74,140.4]],"batl":[[1,1.87,3.59]],"ltp":1.77,"tv":3036.0,"id":6847357}]}]}
{"op":"mcm","clk":"11874414780","pt":1723592199714,"mc":[{"id":"1.231652082","rc":[{"batb":[[0,1.75,38.17],[1,1.74,140.4],[2,1.73,51.97]],"ltp":1.77,"tv":3036.0,"id":6847357}]}]}
{"op":"mcm","clk":"11874415755","pt":1723592212506,"mc":[{"id":"1.231652082","rc":[{"batb":[[0,1.76,123.08],[1,1.75,38.17],[2,1.74,17.32]],"ltp":1.77,"tv":3036.0,"id":6847357}]}]}
{"op":"mcm","clk":"11874418536","pt":1723592247867,"mc":[{"id":"1.231652082","rc":[{"batb":[[0,1.77,37.65],[1,1.76,123.08]],"ltp":1.77,"tv":3036.0,"id":6847357}]}]}
{"op":"mcm","clk":"11874420156","pt":1723592268796,"mc":[{"id":"1.231652082","rc":[{"batb":[[1,1.74,17.32],[2,1.73,51.97]],"ltp":1.77,"tv":3036.0,"id":6847357}]}]}
{"op":"mcm","clk":"11874422166","pt":1723592293753,"mc":[{"id":"1.231652082","rc":[{"batb":[[0,1.74,17.32],[1,1.73,51.97],[2,1.45,57.31]],"ltp":1.77,"tv":3036.0,"id":6847357}]}]}
{"op":"mcm","clk":"11874424821","pt":1723592324637,"mc":[{"id":"1.231652082","rc":[{"batb":[[0,1.74,128.76]],"ltp":1.77,"tv":3036.0,"id":6847357}]}]}
{"op":"mcm","clk":"11874425992","pt":1723592339679,"mc":[{"id":"1.231652082","rc":[{"batb":[[0,1.75,38.17],[1,1.74,128.76],[2,1.73,51.97]],"ltp":1.77,"tv":3036.0,"id":6847357}]}]}
{"op":"mcm","clk":"11874427696","pt":1723592361087,"mc":[{"id":"1.231652082","rc":[{"batb":[[1,1.74,17.32]],"ltp":1.77,"tv":3036.0,"id":6847357}]}]}
{"op":"mcm","clk":"11874427703","pt":1723592361192,"mc":[{"id":"1.231652082","rc":[{"batb":[[0,1.76,111.44],[1,1.75,38.17],[2,1.74,17.32]],"ltp":1.77,"tv":3036.0,"id":6847357}]}]}
{"op":"mcm","clk":"11874429654","pt":1723592384925,"mc":[{"id":"1.231652082","rc":[{"batb":[[0,1.77,37.65],[1,1.76,111.44]],"ltp":1.77,"tv":3036.0,"id":6847357}]}]}
{"op":"mcm","clk":"11874430478","pt":1723592395877,"mc":[{"id":"1.231652082","rc":[{"batb":[[1,1.74,17.32],[2,1.73,51.97]],"ltp":1.77,"tv":3036.0,"id":6847357}]}]}
{"op":"mcm","clk":"11874433575","pt":1723592430855,"mc":[{"id":"1.231652082","rc":[{"batb":[[0,1.74,17.32],[1,1.73,51.97],[2,1.45,57.31]],"ltp":1.77,"tv":3036.0,"id":6847357}]}]}
{"op":"mcm","clk":"11874437442","pt":1723592480477,"mc":[{"id":"1.231652082","rc":[{"batl":[[0,1.75,18.31],[1,1.86,2],[2,1.87,3.59]],"ltp":1.77,"tv":3036.0,"id":6847357}]}]}
{"op":"mcm","clk":"11874437618","pt":1723592482843,"mc":[{"id":"1.231652082","rc":[{"batl":[[0,1.75,22.15],[2,1.87,0]],"ltp":1.77,"tv":3036.0,"id":6847357}]}]}
{"op":"mcm","clk":"11874437972","pt":1723592487382,"mc":[{"id":"1.231652082","rc":[{"batb":[[0,2.32,4],[1,2.16,4],[2,2.14,37.28]],"batl":[[0,2.36,4]],"ltp":2.22,"tv":205.61,"id":25651861}]}]}
{"op":"mcm","clk":"11874442610","pt":1723592545034,"mc":[{"id":"1.231652082","rc":[{"batl":[[0,1.75,4.11]],"ltp":1.77,"tv":3036.0,"id":6847357}]}]}
{"op":"mcm","clk":"11874442640","pt":1723592545342,"mc":[{"id":"1.231652082","rc":[{"batb":[[0,2.16,4],[1,2.14,37.28],[2,1.74,16.78]],"ltp":2.22,"tv":205.61,"id":25651861}]}]}
{"op":"mcm","clk":"11874442798","pt":1723592547049,"mc":[{"id":"1.231652082","rc":[{"batl":[[0,1.86,2.27],[1,1.86,0]],"ltp":1.77,"tv":3036.0,"id":6847357}]}]}
{"op":"mcm","clk":"11874442814","pt":1723592547250,"mc":[{"id":"1.231652082","rc":[{"batl":[[1,1.87,3.59]],"ltp":1.77,"tv":3036.0,"id":6847357}]}]}
{"op":"mcm","clk":"11874443949","pt":1723592562467,"mc":[{"id":"1.231652082","rc":[{"batl":[[0,1.86,2]],"ltp":1.77,"tv":3036.0,"id":6847357}]}]}
{"op":"mcm","clk":"11874465997","pt":1723592845994,"mc":[{"id":"1.231652082","rc":[{"batb":[[0,1.74,106.13]],"ltp":1.77,"tv":3036.0,"id":6847357}]}]}
{"op":"mcm","clk":"11874466435","pt":1723592850834,"mc":[{"id":"1.231652082","rc":[{"batb":[[0,1.75,38.17],[1,1.74,106.13],[2,1.73,51.97]],"ltp":1.77,"tv":3036.0,"id":6847357}]}]}
{"op":"mcm","clk":"11874467339","pt":1723592860322,"mc":[{"id":"1.231652082","rc":[{"batb":[[1,1.74,17.32]],"ltp":1.77,"tv":3036.0,"id":6847357}]}]}
{"op":"mcm","clk":"11874470504","pt":1723592898777,"mc":[{"id":"1.231652082","rc":[{"batb":[[0,1.74,17.32],[1,1.73,51.97],[2,1.45,57.31]],"ltp":1.77,"tv":3036.0,"id":6847357}]}]}
{"op":"mcm","clk":"11874472336","pt":1723592921803,"mc":[{"id":"1.231652082","rc":[{"batl":[[0,1.75,88.81],[1,1.86,2],[2,1.87,3.59]],"ltp":1.77,"tv":3036.0,"id":6847357}]}]}
{"op":"mcm","clk":"11874472458","pt":1723592923599,"mc":[{"id":"1.231652082","rc":[{"batl":[[0,1.75,92.65],[2,1.87,0]],"ltp":1.77,"tv":3036.0,"id":6847357}]}]}
{"op":"mcm","clk":"11874472712","pt":1723592926782,"mc":[{"id":"1.231652082","rc":[{"batl":[[0,1.75,96.65]],"ltp":1.77,"tv":3036.0,"id":6847357},{"batb":[[0,2.34,4],[1,2.32,4],[2,2.16,4]],"ltp":2.22,"tv":205.61,"id":25651861}]}]}
{"op":"mcm","clk":"11874472885","pt":1723592928997,"mc":[{"id":"1.231652082","rc":[{"batb":[[1,1.45,57.31],[2,1.38,131.58]],"ltp":1.77,"tv":3036.0,"id":6847357}]}]}
{"op":"mcm","clk":"11874477292","pt":1723592979752,"mc":[{"id":"1.231652082","rc":[{"trd":[[1.75,6.3]],"batl":[[0,1.75,4.69]],"ltp":1.75,"tv":3042.3,"id":6847357}],"tv":3247.91}]}
{"op":"mcm","clk":"11874477350","pt":1723592980469,"mc":[{"id":"1.231652082","rc":[{"batl":[[0,1.86,2.69],[1,1.86,0]],"ltp":1.75,"tv":3042.3,"id":6847357},{"batb":[[0,1.74,16.78],[1,1.45,57.31],[2,1.38,131.58]],"ltp":2.22,"tv":205.61,"id":25651861}]}]}
{"op":"mcm","clk":"11874477462","pt":1723592982067,"mc":[{"id":"1.231652082","rc":[{"batl":[[0,1.86,2]],"ltp":1.75,"tv":3042.3,"id":6847357}]}]}
{"op":"mcm","clk":"11874477617","pt":1723592984035,"mc":[{"id":"1.231652082","rc":[{"batb":[[1,1.73,51.97],[2,1.45,57.31]],"ltp":1.75,"tv":3042.3,"id":6847357},{"batb":[[0,2.14,33.28],[1,1.74,16.78],[2,1.45,57.31]],"ltp":2.22,"tv":205.61,"id":25651861}]}]}
{"op":"mcm","clk":"11874512064","pt":1723593461771,"mc":[{"id":"1.231652082","rc":[{"batb":[[0,1.76,9.14],[1,1.74,17.32],[2,1.73,51.97]],"ltp":1.75,"tv":3042.3,"id":6847357},{"batb":[[1,2.02,7.96],[2,1.74,16.78]],"ltp":2.22,"tv":205.61,"id":25651861}]}]}
{"op":"mcm","clk":"11874513255","pt":1723593479833,"mc":[{"id":"1.231652082","rc":[{"batb":[[0,1.74,17.32],[1,1.73,51.97],[2,1.45,57.31]],"ltp":1.75,"tv":3042.3,"id":6847357},{"batb":[[1,1.74,16.78],[2,1.45,57.31]],"ltp":2.22,"tv":205.61,"id":25651861}]}]}
{"op":"mcm","clk":"11874514723","pt":1723593502171,"mc":[{"id":"1.231652082","rc":[{"batl":[[1,1.87,100.98]],"ltp":1.75,"tv":3042.3,"id":6847357}]}]}
{"op":"mcm","clk":"11874516671","pt":1723593532517,"mc":[{"id":"1.231652082","rc":[{"batl":[[0,1.86,9.74]],"ltp":1.75,"tv":3042.3,"id":6847357}]}]}
{"op":"mcm","clk":"11874520889","pt":1723593601011,"mc":[{"id":"1.231652082","rc":[{"batb":[[0,2.16,10],[1,2.14,33.28],[2,1.74,16.78]],"ltp":2.22,"tv":205.61,"id":25651861}]}]}
{"op":"mcm","clk":"11874521242","pt":1723593605993,"mc":[{"id":"1.231652082","rc":[{"trd":[[1.5,192.18],[1.81,107.96],[1.82,15.38],[1.83,1313.54],[1.85,1315.09]],"batb":[[2,1.45,57.32]],"batl":[[0,1.86,9.74]],"ltp":1.75,"tv":3041.66,"id":6847357},{"trd":[[1.5,192.77]],"batb":[[0,2.14,33.28],[1,1.74,16.78],[2,1.45,57.32]],"ltp":2.22,"tv":205.6,"id":25651861}],"tv":3247.27}]}
{"op":"mcm","clk":"11874521412","pt":1723593608623,"mc":[{"id":"1.231652082","rc":[{"batb":[[0,2.16,10],[1,2.14,33.28],[2,1.74,16.78]],"ltp":2.22,"tv":205.6,"id":25651861}]}]}
{"op":"mcm","clk":"11874521634","pt":1723593612126,"mc":[{"id":"1.231652082","rc":[{"batb":[[0,2.14,33.28],[1,1.74,16.78],[2,1.45,57.32]],"ltp":2.22,"tv":205.6,"id":25651861}]}]}
{"op":"mcm","clk":"11874521766","pt":1723593614503,"mc":[{"id":"1.231652082","rc":[{"batb":[[0,2.16,10],[1,2.14,33.28],[2,1.74,16.78]],"ltp":2.22,"tv":205.6,"id":25651861}]}]}
{"op":"mcm","clk":"11874522030","pt":1723593618005,"mc":[{"id":"1.231652082","rc":[{"batb":[[0,2.14,33.28],[1,1.74,16.78],[2,1.45,57.32]],"ltp":2.22,"tv":205.6,"id":25651861}]}]}
{"op":"mcm","clk":"11874522201","pt":1723593620324,"mc":[{"id":"1.231652082","rc":[{"batb":[[0,2.16,10],[1,2.14,33.28],[2,1.74,16.78]],"ltp":2.22,"tv":205.6,"id":25651861}]}]}
{"op":"mcm","clk":"11874522405","pt":1723593623922,"mc":[{"id":"1.231652082","rc":[{"batb":[[0,2.14,33.28],[1,1.74,16.78],[2,1.45,57.32]],"ltp":2.22,"tv":205.6,"id":25651861}]}]}
{"op":"mcm","clk":"11874522550","pt":1723593626226,"mc":[{"id":"1.231652082","rc":[{"batb":[[0,2.16,10],[1,2.14,33.28],[2,1.74,16.78]],"ltp":2.22,"tv":205.6,"id":25651861}]}]}
{"op":"mcm","clk":"11874522745","pt":1723593629743,"mc":[{"id":"1.231652082","rc":[{"batb":[[0,2.14,33.28],[1,1.74,16.78],[2,1.45,57.32]],"ltp":2.22,"tv":205.6,"id":25651861}]}]}
{"op":"mcm","clk":"11874522913","pt":1723593632417,"mc":[{"id":"1.231652082","rc":[{"batb":[[0,2.16,10],[1,2.14,33.28],[2,1.74,16.78]],"ltp":2.22,"tv":205.6,"id":25651861}]}]}
{"op":"mcm","clk":"11874523120","pt":1723593636059,"mc":[{"id":"1.231652082","rc":[{"batb":[[0,2.14,33.28],[1,1.74,16.78],[2,1.45,57.32]],"ltp":2.22,"tv":205.6,"id":25651861}]}]}
{"op":"mcm","clk":"11874523280","pt":1723593639559,"mc":[{"id":"1.231652082","rc":[{"batb":[[0,2.16,10],[1,2.14,33.28],[2,1.74,16.78]],"ltp":2.22,"tv":205.6,"id":25651861}]}]}
{"op":"mcm","clk":"11874523346","pt":1723593640845,"mc":[{"id":"1.231652082","rc":[{"batb":[[0,2.18,30.95],[1,2.16,10],[2,2.14,33.28]],"ltp":2.22,"tv":205.6,"id":25651861}]}]}
{"op":"mcm","clk":"11874523394","pt":1723593641870,"mc":[{"id":"1.231652082","rc":[{"batl":[[0,1.86,2]],"ltp":1.75,"tv":3041.66,"id":6847357}]}]}
{"op":"mcm","clk":"11874523460","pt":1723593643257,"mc":[{"id":"1.231652082","rc":[{"batb":[[1,2.14,33.28],[2,1.74,16.78]],"ltp":2.22,"tv":205.6,"id":25651861}]}]}
{"op":"mcm","clk":"11874523602","pt":1723593647069,"mc":[{"id":"1.231652082","rc":[{"batb":[[0,2.2,10],[1,2.18,30.95],[2,2.14,33.28]],"ltp":2.22,"tv":205.6,"id":25651861}]}]}
{"op":"mcm","clk":"11874523755","pt":1723593650674,"mc":[{"id":"1.231652082","rc":[{"batb":[[0,2.18,30.95],[1,2.14,33.28],[2,1.74,16.78]],"ltp":2.22,"tv":205.6,"id":25651861}]}]}
{"op":"mcm","clk":"11874523834","pt":1723593652943,"mc":[{"id":"1.231652082","rc":[{"batb":[[0,2.2,10],[1,2.18,30.95],[2,2.14,33.28]],"ltp":2.22,"tv":205.6,"id":25651861}]}]}
{"op":"mcm","clk":"11874524037","pt":1723593656545,"mc":[{"id":"1.231652082","rc":[{"batb":[[0,2.18,30.95],[1,2.14,33.28],[2,1.74,16.78]],"ltp":2.22,"tv":205.6,"id":25651861}]}]}
{"op":"mcm","clk":"11874524194","pt":1723593659175,"mc":[{"id":"1.231652082","rc":[{"batb":[[0,2.2,10],[1,2.18,30.95],[2,2.14,33.28]],"ltp":2.22,"tv":205.6,"id":25651861}]}]}
{"op":"mcm","clk":"11874524375","pt":1723593662673,"mc":[{"id":"1.231652082","rc":[{"batb":[[0,2.18,30.95],[1,2.14,33.28],[2,1.74,16.78]],"ltp":2.22,"tv":205.6,"id":25651861}]}]}
{"op":"mcm","clk":"11874524604","pt":1723593666863,"mc":[{"id":"1.231652082","rc":[{"batb":[[0,2.2,10],[1,2.18,30.95],[2,2.14,33.28]],"ltp":2.22,"tv":205.6,"id":25651861}]}]}
{"op":"mcm","clk":"11874524788","pt":1723593670165,"mc":[{"id":"1.231652082","rc":[{"batb":[[0,2.18,30.95],[1,2.14,33.28],[2,1.74,16.78]],"ltp":2.22,"tv":205.6,"id":25651861}]}]}
{"op":"mcm","clk":"11874524947","pt":1723593673707,"mc":[{"id":"1.231652082","rc":[{"batb":[[0,2.2,10],[1,2.18,30.95],[2,2.14,33.28]],"ltp":2.22,"tv":205.6,"id":25651861}]}]}
{"op":"mcm","clk":"11874525109","pt":1723593677205,"mc":[{"id":"1.231652082","rc":[{"batb":[[0,2.18,30.95],[1,2.14,33.28],[2,1.74,16.78]],"ltp":2.22,"tv":205.6,"id":25651861}]}]}
{"op":"mcm","clk":"11874525183","pt":1723593678491,"mc":[{"id":"1.231652082","rc":[{"batl":[[1,1.87,0]],"ltp":1.75,"tv":3041.66,"id":6847357}]}]}
{"op":"mcm","clk":"11874525272","pt":1723593680297,"mc":[{"id":"1.231652082","rc":[{"batb":[[0,2.2,10],[1,2.18,30.95],[2,2.14,33.28]],"ltp":2.22,"tv":205.6,"id":25651861}]}]}
{"op":"mcm","clk":"11874525456","pt":1723593683998,"mc":[{"id":"1.231652082","rc":[{"batb":[[0,2.18,30.95],[1,2.14,33.28],[2,1.74,16.78]],"ltp":2.22,"tv":205.6,"id":25651861}]}]}
{"op":"mcm","clk":"11874525612","pt":1723593687118,"mc":[{"id":"1.231652082","rc":[{"batb":[[0,2.14,33.28],[1,1.74,16.78],[2,1.45,57.32]],"ltp":2.22,"tv":205.6,"id":25651861}]}]}
{"op":"mcm","clk":"11874525616","pt":1723593687218,"mc":[{"id":"1.231652082","rc":[{"batb":[[0,2.16,10],[1,2.14,33.28],[2,1.74,16.78]],"ltp":2.22,"tv":205.6,"id":25651861}]}]}
{"op":"mcm","clk":"11874525794","pt":1723593690593,"mc":[{"id":"1.231652082","rc":[{"batb":[[0,2.14,33.28],[1,1.74,16.78],[2,1.45,57.32]],"ltp":2.22,"tv":205.6,"id":25651861}]}]}
{"op":"mcm","clk":"11874525940","pt":1723593693415,"mc":[{"id":"1.231652082","rc":[{"batb":[[0,2.16,10],[1,2.14,33.28],[2,1.74,16.78]],"ltp":2.22,"tv":205.6,"id":25651861}]}]}
{"op":"mcm","clk":"11874526130","pt":1723593696911,"mc":[{"id":"1.231652082","rc":[{"batb":[[0,2.14,33.28],[1,1.74,16.78],[2,1.45,57.32]],"ltp":2.22,"tv":205.6,"id":25651861}]}]}
{"op":"mcm","clk":"11874526260","pt":1723593699936,"mc":[{"id":"1.231652082","rc":[{"batb":[[0,2.16,10],[1,2.14,33.28],[2,1.74,16.78]],"ltp":2.22,"tv":205.6,"id":25651861}]}]}
{"op":"mcm","clk":"11874526462","pt":1723593703327,"mc":[{"id":"1.231652082","rc":[{"batb":[[0,2.14,33.28],[1,1.74,16.78],[2,1.45,57.32]],"ltp":2.22,"tv":205.6,"id":25651861}]}]}
{"op":"mcm","clk":"11874526762","pt":1723593707911,"mc":[{"id":"1.231652082","rc":[{"batb":[[0,2.16,10],[1,2.14,33.28],[2,1.74,16.78]],"ltp":2.22,"tv":205.6,"id":25651861}]}]}
{"op":"mcm","clk":"11874526975","pt":1723593711410,"mc":[{"id":"1.231652082","rc":[{"batb":[[0,2.14,33.28],[1,1.74,16.78],[2,1.45,57.32]],"ltp":2.22,"tv":205.6,"id":25651861}]}]}
{"op":"mcm","clk":"11874527095","pt":1723593713831,"mc":[{"id":"1.231652082","rc":[{"batb":[[0,2.16,10],[1,2.14,33.28],[2,1.74,16.78]],"ltp":2.22,"tv":205.6,"id":25651861}]}]}
{"op":"mcm","clk":"11874527236","pt":1723593717114,"mc":[{"id":"1.231652082","rc":[{"batb":[[0,2.14,33.28],[1,1.74,16.78],[2,1.45,57.32]],"ltp":2.22,"tv":205.6,"id":25651861}]}]}
{"op":"mcm","clk":"11874527360","pt":1723593719635,"mc":[{"id":"1.231652082","rc":[{"batb":[[0,2.16,10],[1,2.14,33.28],[2,1.74,16.78]],"ltp":2.22,"tv":205.6,"id":25651861}]}]}
{"op":"mcm","clk":"11874527523","pt":1723593723032,"mc":[{"id":"1.231652082","rc":[{"batb":[[0,2.14,33.28],[1,1.74,16.78],[2,1.45,57.32]],"ltp":2.22,"tv":205.6,"id":25651861}]}]}
{"op":"mcm","clk":"11874527724","pt":1723593727245,"mc":[{"id":"1.231652082","rc":[{"batb":[[0,2.16,10],[1,2.14,33.28],[2,1.74,16.78]],"ltp":2.22,"tv":205.6,"id":25651861}]}]}
{"op":"mcm","clk":"11874527941","pt":1723593730537,"mc":[{"id":"1.231652082","rc":[{"batb":[[0,2.14,33.28],[1,1.74,16.78],[2,1.45,57.32]],"ltp":2.22,"tv":205.6,"id":25651861}]}]}
{"op":"mcm","clk":"11874528135","pt":1723593733886,"mc":[{"id":"1.231652082","rc":[{"batl":[[0,1.86,102.98]],"ltp":1.75,"tv":3041.66,"id":6847357},{"batb":[[0,2.16,10],[1,2.14,33.28],[2,1.74,16.78]],"ltp":2.22,"tv":205.6,"id":25651861}]}]}
{"op":"mcm","clk":"11874528313","pt":1723593736875,"mc":[{"id":"1.231652082","rc":[{"batb":[[0,2.14,33.28],[1,1.74,16.78],[2,1.45,57.32]],"ltp":2.22,"tv":205.6,"id":25651861}]}]}
{"op":"mcm","clk":"11874528443","pt":1723593739189,"mc":[{"id":"1.231652082","rc":[{"batb":[[0,2.16,10],[1,2.14,33.28],[2,1.74,16.78]],"ltp":2.22,"tv":205.6,"id":25651861}]}]}
{"op":"mcm","clk":"11874528617","pt":1723593742890,"mc":[{"id":"1.231652082","rc":[{"batb":[[0,2.14,33.28],[1,1.74,16.78],[2,1.45,57.32]],"ltp":2.22,"tv":205.6,"id":25651861}]}]}
{"op":"mcm","clk":"11874528737","pt":1723593745096,"mc":[{"id":"1.231652082","rc":[{"batb":[[0,2.16,10],[1,2.14,33.28],[2,1.74,16.78]],"ltp":2.22,"tv":205.6,"id":25651861}]}]}
{"op":"mcm","clk":"11874528909","pt":1723593748382,"mc":[{"id":"1.231652082","rc":[{"batb":[[0,2.14,33.28],[1,1.74,16.78],[2,1.45,57.32]],"ltp":2.22,"tv":205.6,"id":25651861}]}]}
{"op":"mcm","clk":"11874529047","pt":1723593750897,"mc":[{"id":"1.231652082","rc":[{"batb":[[0,2.16,10],[1,2.14,33.28],[2,1.74,16.78]],"ltp":2.22,"tv":205.6,"id":25651861}]}]}
{"op":"mcm","clk":"11874529221","pt":1723593754482,"mc":[{"id":"1.231652082","rc":[{"batb":[[0,2.14,33.28],[1,1.74,16.78],[2,1.45,57.32]],"ltp":2.22,"tv":205.6,"id":25651861}]}]}
{"op":"mcm","clk":"11874529376","pt":1723593756794,"mc":[{"id":"1.231652082","rc":[{"batb":[[0,2.16,10],[1,2.14,33.28],[2,1.74,16.78]],"ltp":2.22,"tv":205.6,"id":25651861}]}]}
{"op":"mcm","clk":"11874529556","pt":1723593760395,"mc":[{"id":"1.231652082","rc":[{"batb":[[0,2.14,33.28],[1,1.74,16.78],[2,1.45,57.32]],"ltp":2.22,"tv":205.6,"id":25651861}]}]}
{"op":"mcm","clk":"11874529726","pt":1723593762907,"mc":[{"id":"1.231652082","rc":[{"batb":[[0,2.16,10],[1,2.14,33.28],[2,1.74,16.78]],"ltp":2.22,"tv":205.6,"id":25651861}]}]}
{"op":"mcm","clk":"11874529868","pt":1723593765075,"mc":[{"id":"1.231652082","rc":[{"batl":[[0,1.85,7.74],[1,1.86,102.98]],"ltp":1.75,"tv":3041.66,"id":6847357}]}]}
{"op":"mcm","clk":"11874529955","pt":1723593766510,"mc":[{"id":"1.231652082","rc":[{"batb":[[0,2.14,33.28],[1,1.74,16.78],[2,1.45,57.32]],"ltp":2.22,"tv":205.6,"id":25651861}]}]}
{"op":"mcm","clk":"11874530123","pt":1723593769901,"mc":[{"id":"1.231652082","rc":[{"batb":[[0,2.16,10],[1,2.14,33.28],[2,1.74,16.78]],"ltp":2.22,"tv":205.6,"id":25651861}]}]}
{"op":"mcm","clk":"11874530317","pt":1723593773408,"mc":[{"id":"1.231652082","rc":[{"batb":[[0,2.14,33.28],[1,1.74,16.78],[2,1.45,57.32]],"ltp":2.22,"tv":205.6,"id":25651861}]}]}
{"op":"mcm","clk":"11874530467","pt":1723593776129,"mc":[{"id":"1.231652082","rc":[{"batb":[[0,2.16,10],[1,2.14,33.28],[2,1.74,16.78]],"ltp":2.22,"tv":205.6,"id":25651861}]}]}
{"op":"mcm","clk":"11874530567","pt":1723593777627,"mc":[{"id":"1.231652082","rc":[{"batb":[[0,2.18,30.95],[1,2.16,10],[2,2.14,33.28]],"ltp":2.22,"tv":205.6,"id":25651861}]}]}
{"op":"mcm","clk":"11874530694","pt":1723593779535,"mc":[{"id":"1.231652082","rc":[{"batb":[[1,2.14,33.28],[2,1.74,16.78]],"ltp":2.22,"tv":205.6,"id":25651861}]}]}
{"op":"mcm","clk":"11874530844","pt":1723593781804,"mc":[{"id":"1.231652082","rc":[{"batb":[[0,2.2,10],[1,2.18,30.95],[2,2.14,33.28]],"ltp":2.22,"tv":205.6,"id":25651861}]}]}
{"op":"mcm","clk":"11874531029","pt":1723593785403,"mc":[{"id":"1.231652082","rc":[{"batb":[[0,2.18,30.95],[1,2.14,33.28],[2,1.74,16.78]],"ltp":2.22,"tv":205.6,"id":25651861}]}]}
{"op":"mcm","clk":"11874531155","pt":1723593787916,"mc":[{"id":"1.231652082","rc":[{"batb":[[0,2.2,10],[1,2.18,30.95],[2,2.14,33.28]],"ltp":2.22,"tv":205.6,"id":25651861}]}]}
{"op":"mcm","clk":"11874531252","pt":1723593789611,"mc":[{"id":"1.231652082","rc":[{"batl":[[1,1.86,2]],"ltp":1.75,"tv":3041.66,"id":6847357}]}]}
{"op":"mcm","clk":"11874531337","pt":1723593791715,"mc":[{"id":"1.231652082","rc":[{"batl":[[0,1.86,2],[1,1.86,0]],"ltp":1.75,"tv":3041.66,"id":6847357},{"batb":[[0,2.18,30.95],[1,2.14,33.28],[2,1.74,16.78]],"ltp":2.22,"tv":205.6,"id":25651861}]}]}
{"op":"mcm","clk":"11874531486","pt":1723593794126,"mc":[{"id":"1.231652082","rc":[{"batb":[[0,2.2,10],[1,2.18,30.95],[2,2.14,33.28]],"ltp":2.22,"tv":205.6,"id":25651861}]}]}
{"op":"mcm","clk":"11874531694","pt":1723593797623,"mc":[{"id":"1.231652082","rc":[{"batb":[[0,2.18,30.95],[1,2.14,33.28],[2,1.74,16.78]],"ltp":2.22,"tv":205.6,"id":25651861}]}]}
{"op":"mcm","clk":"11874531840","pt":1723593800344,"mc":[{"id":"1.231652082","rc":[{"batb":[[0,2.2,10],[1,2.18,30.95],[2,2.14,33.28]],"ltp":2.22,"tv":205.6,"id":25651861}]}]}
{"op":"mcm","clk":"11874532022","pt":1723593803751,"mc":[{"id":"1.231652082","rc":[{"batb":[[0,2.18,30.95],[1,2.14,33.28],[2,1.74,16.78]],"ltp":2.22,"tv":205.6,"id":25651861}]}]}
{"op":"mcm","clk":"11874532251","pt":1723593807551,"mc":[{"id":"1.231652082","rc":[{"batb":[[0,2.2,10],[1,2.18,30.95],[2,2.14,33.28]],"ltp":2.22,"tv":205.6,"id":25651861}]}]}
{"op":"mcm","clk":"11874532467","pt":1723593810944,"mc":[{"id":"1.231652082","rc":[{"batb":[[0,2.18,30.95],[1,2.14,33.28],[2,1.74,16.78]],"ltp":2.22,"tv":205.6,"id":25651861}]}]}
{"op":"mcm","clk":"11874532640","pt":1723593814238,"mc":[{"id":"1.231652082","rc":[{"batb":[[0,2.2,10],[1,2.18,30.95],[2,2.14,33.28]],"ltp":2.22,"tv":205.6,"id":25651861}]}]}
{"op":"mcm","clk":"11874532821","pt":1723593817889,"mc":[{"id":"1.231652082","rc":[{"batb":[[0,2.18,30.95],[1,2.14,33.28],[2,1.74,16.78]],"ltp":2.22,"tv":205.6,"id":25651861}]}]}
{"op":"mcm","clk":"11874533004","pt":1723593820564,"mc":[{"id":"1.231652082","rc":[{"batb":[[0,2.2,10],[1,2.18,30.95],[2,2.14,33.28]],"ltp":2.22,"tv":205.6,"id":25651861}]}]}
{"op":"mcm","clk":"11874533251","pt":1723593824084,"mc":[{"id":"1.231652082","rc":[{"batb":[[0,2.18,30.95],[1,2.14,33.28],[2,1.74,16.78]],"ltp":2.22,"tv":205.6,"id":25651861}]}]}
{"op":"mcm","clk":"11874533408","pt":1723593826863,"mc":[{"id":"1.231652082","rc":[{"batb":[[0,2.16,10]],"ltp":2.22,"tv":205.6,"id":25651861}]}]}
{"op":"mcm","clk":"11874533597","pt":1723593830200,"mc":[{"id":"1.231652082","rc":[{"batb":[[0,2.14,33.28],[1,1.74,16.78],[2,1.45,57.32]],"ltp":2.22,"tv":205.6,"id":25651861}]}]}
{"op":"mcm","clk":"11874533821","pt":1723593833697,"mc":[{"id":"1.231652082","rc":[{"batb":[[0,2.16,10],[1,2.14,33.28],[2,1.74,16.78]],"ltp":2.22,"tv":205.6,"id":25651861}]}]}
{"op":"mcm","clk":"11874534033","pt":1723593837091,"mc":[{"id":"1.231652082","rc":[{"batb":[[0,2.14,33.28],[1,1.74,16.78],[2,1.45,57.32]],"ltp":2.22,"tv":205.6,"id":25651861}]}]}
{"op":"mcm","clk":"11874534173","pt":1723593839609,"mc":[{"id":"1.231652082","rc":[{"batb":[[0,2.16,10],[1,2.14,33.28],[2,1.74,16.78]],"ltp":2.22,"tv":205.6,"id":25651861}]}]}
{"op":"mcm","clk":"11874534362","pt":1723593843010,"mc":[{"id":"1.231652082","rc":[{"batb":[[0,2.14,33.28],[1,1.74,16.78],[2,1.45,57.32]],"ltp":2.22,"tv":205.6,"id":25651861}]}]}
{"op":"mcm","clk":"11874534506","pt":1723593845379,"mc":[{"id":"1.231652082","rc":[{"batb":[[0,2.16,10],[1,2.14,33.28],[2,1.74,16.78]],"ltp":2.22,"tv":205.6,"id":25651861}]}]}
{"op":"mcm","clk":"11874534673","pt":1723593848723,"mc":[{"id":"1.231652082","rc":[{"batb":[[0,2.14,33.28],[1,1.74,16.78],[2,1.45,57.32]],"ltp":2.22,"tv":205.6,"id":25651861}]}]}
{"op":"mcm","clk":"11874534850","pt":1723593851497,"mc":[{"id":"1.231652082","rc":[{"batb":[[0,2.16,10],[1,2.14,33.28],[2,1.74,16.78]],"ltp":2.22,"tv":205.6,"id":25651861}]}]}
{"op":"mcm","clk":"11874535025","pt":1723593854890,"mc":[{"id":"1.231652082","rc":[{"batb":[[0,2.14,33.28],[1,1.74,16.78],[2,1.45,57.32]],"ltp":2.22,"tv":205.6,"id":25651861}]}]}
{"op":"mcm","clk":"11874535217","pt":1723593858796,"mc":[{"id":"1.231652082","rc":[{"batb":[[0,2.16,10],[1,2.14,33.28],[2,1.74,16.78]],"ltp":2.22,"tv":205.6,"id":25651861}]}]}
{"op":"mcm","clk":"11874535405","pt":1723593862298,"mc":[{"id":"1.231652082","rc":[{"batb":[[0,2.14,33.28],[1,1.74,16.78],[2,1.45,57.32]],"ltp":2.22,"tv":205.6,"id":25651861}]}]}
{"op":"mcm","clk":"11874535569","pt":1723593864818,"mc":[{"id":"1.231652082","rc":[{"batb":[[0,2.16,10],[1,2.14,33.28],[2,1.74,16.78]],"ltp":2.22,"tv":205.6,"id":25651861}]}]}
{"op":"mcm","clk":"11874535725","pt":1723593868330,"mc":[{"id":"1.231652082","rc":[{"batb":[[0,2.14,33.28],[1,1.74,16.78],[2,1.45,57.32]],"ltp":2.22,"tv":205.6,"id":25651861}]}]}
{"op":"mcm","clk":"11874535861","pt":1723593870952,"mc":[{"id":"1.231652082","rc":[{"batb":[[0,2.16,10],[1,2.14,33.28],[2,1.74,16.78]],"ltp":2.22,"tv":205.6,"id":25651861}]}]}
{"op":"mcm","clk":"11874536072","pt":1723593874654,"mc":[{"id":"1.231652082","rc":[{"batb":[[0,2.14,33.28],[1,1.74,16.78],[2,1.45,57.32]],"ltp":2.22,"tv":205.6,"id":25651861}]}]}
{"op":"mcm","clk":"11874536198","pt":1723593877222,"mc":[{"id":"1.231652082","rc":[{"batb":[[0,2.16,10],[1,2.14,33.28],[2,1.74,16.78]],"ltp":2.22,"tv":205.6,"id":25651861}]}]}
{"op":"mcm","clk":"11874536452","pt":1723593880930,"mc":[{"id":"1.231652082","rc":[{"batb":[[0,2.14,33.28],[1,1.74,16.78],[2,1.45,57.32]],"ltp":2.22,"tv":205.6,"id":25651861}]}]}
{"op":"mcm","clk":"11874536616","pt":1723593883829,"mc":[{"id":"1.231652082","rc":[{"batb":[[0,2.16,10],[1,2.14,33.28],[2,1.74,16.78]],"ltp":2.22,"tv":205.6,"id":25651861}]}]}
{"op":"mcm","clk":"11874536803","pt":1723593887265,"mc":[{"id":"1.231652082","rc":[{"batb":[[0,2.14,33.28],[1,1.74,16.78],[2,1.45,57.32]],"ltp":2.22,"tv":205.6,"id":25651861}]}]}
{"op":"mcm","clk":"11874536987","pt":1723593890452,"mc":[{"id":"1.231652082","rc":[{"trd":[[1.86,3.6]],"batl":[[0,1.86,0.2]],"ltp":1.86,"tv":3045.26,"id":6847357},{"batb":[[0,2.16,10],[1,2.14,33.28],[2,1.74,16.78]],"ltp":2.22,"tv":205.6,"id":25651861}],"tv":3250.87}]}
{"op":"mcm","clk":"11874537199","pt":1723593894161,"mc":[{"id":"1.231652082","rc":[{"batb":[[0,2.14,33.28],[1,1.74,16.78],[2,1.45,57.32]],"ltp":2.22,"tv":205.6,"id":25651861}]}]}
{"op":"mcm","clk":"11874537333","pt":1723593896544,"mc":[{"id":"1.231652082","rc":[{"batb":[[0,2.16,10],[1,2.14,33.28],[2,1.74,16.78]],"ltp":2.22,"tv":205.6,"id":25651861}]}]}
{"op":"mcm","clk":"11874537526","pt":1723593900290,"mc":[{"id":"1.231652082","rc":[{"batb":[[0,2.14,33.28],[1,1.74,16.78],[2,1.45,57.32]],"ltp":2.22,"tv":205.6,"id":25651861}]}]}
{"op":"mcm","clk":"11874537719","pt":1723593903698,"mc":[{"id":"1.231652082","rc":[{"batb":[[0,2.16,10],[1,2.14,33.28],[2,1.74,16.78]],"ltp":2.22,"tv":205.6,"id":25651861}]}]}
{"op":"mcm","clk":"11874537928","pt":1723593907150,"mc":[{"id":"1.231652082","rc":[{"batb":[[0,2.14,33.28],[1,1.74,16.78],[2,1.45,57.32]],"ltp":2.22,"tv":205.6,"id":25651861}]}]}
{"op":"mcm","clk":"11874538075","pt":1723593909591,"mc":[{"id":"1.231652082","rc":[{"batb":[[0,2.16,10],[1,2.14,33.28],[2,1.74,16.78]],"ltp":2.22,"tv":205.6,"id":25651861}]}]}
{"op":"mcm","clk":"11874538281","pt":1723593912893,"mc":[{"id":"1.231652082","rc":[{"batb":[[0,2.14,33.28],[1,1.74,16.78],[2,1.45,57.32]],"ltp":2.22,"tv":205.6,"id":25651861}]}]}
{"op":"mcm","clk":"11874538412","pt":1723593915465,"mc":[{"id":"1.231652082","rc":[{"batb":[[0,2.16,10],[1,2.14,33.28],[2,1.74,16.78]],"ltp":2.22,"tv":205.6,"id":25651861}]}]}
{"op":"mcm","clk":"11874538615","pt":1723593919075,"mc":[{"id":"1.231652082","rc":[{"batb":[[0,2.14,33.28],[1,1.74,16.78],[2,1.45,57.32]],"ltp":2.22,"tv":205.6,"id":25651861}]}]}
{"op":"mcm","clk":"11874538771","pt":1723593921910,"mc":[{"id":"1.231652082","rc":[{"batb":[[0,2.16,10],[1,2.14,33.28],[2,1.74,16.78]],"ltp":2.22,"tv":205.6,"id":25651861}]}]}
{"op":"mcm","clk":"11874538864","pt":1723593923779,"mc":[{"id":"1.231652082","rc":[{"batl":[[0,1.87,101.18]],"ltp":1.86,"tv":3045.26,"id":6847357}]}]}
{"op":"mcm","clk":"11874538931","pt":1723593925272,"mc":[{"id":"1.231652082","rc":[{"batb":[[0,2.14,33.28],[1,1.74,16.78],[2,1.45,57.32]],"ltp":2.22,"tv":205.6,"id":25651861}]}]}
{"op":"mcm","clk":"11874539075","pt":1723593927789,"mc":[{"id":"1.231652082","rc":[{"batb":[[0,2.16,10],[1,2.14,33.28],[2,1.74,16.78]],"ltp":2.22,"tv":205.6,"id":25651861}]}]}
{"op":"mcm","clk":"11874539275","pt":1723593931295,"mc":[{"id":"1.231652082","rc":[{"batb":[[0,2.14,33.28],[1,1.74,16.78],[2,1.45,57.32]],"ltp":2.22,"tv":205.6,"id":25651861}]}]}
{"op":"mcm","clk":"11874539417","pt":1723593933618,"mc":[{"id":"1.231652082","rc":[{"batb":[[0,2.16,10],[1,2.14,33.28],[2,1.74,16.78]],"ltp":2.22,"tv":205.6,"id":25651861}]}]}
{"op":"mcm","clk":"11874539643","pt":1723593936938,"mc":[{"id":"1.231652082","rc":[{"batb":[[0,2.14,33.28],[1,1.74,16.78],[2,1.45,57.32]],"ltp":2.22,"tv":205.6,"id":25651861}]}]}
{"op":"mcm","clk":"11874539816","pt":1723593939604,"mc":[{"id":"1.231652082","rc":[{"batb":[[0,2.16,10],[1,2.14,33.28],[2,1.74,16.78]],"ltp":2.22,"tv":205.6,"id":25651861}]}]}
{"op":"mcm","clk":"11874540027","pt":1723593943320,"mc":[{"id":"1.231652082","rc":[{"batb":[[0,2.14,33.28],[1,1.74,16.78],[2,1.45,57.32]],"ltp":2.22,"tv":205.6,"id":25651861}]}]}
{"op":"mcm","clk":"11874540152","pt":1723593945632,"mc":[{"id":"1.231652082","rc":[{"batb":[[0,2.16,10],[1,2.14,33.28],[2,1.74,16.78]],"ltp":2.22,"tv":205.6,"id":25651861}]}]}
{"op":"mcm","clk":"11874540348","pt":1723593949222,"mc":[{"id":"1.231652082","rc":[{"batb":[[0,2.14,33.28],[1,1.74,16.78],[2,1.45,57.32]],"ltp":2.22,"tv":205.6,"id":25651861}]}]}
{"op":"mcm","clk":"11874540523","pt":1723593951744,"mc":[{"id":"1.231652082","rc":[{"batb":[[0,2.16,10],[1,2.14,33.28],[2,1.74,16.78]],"ltp":2.22,"tv":205.6,"id":25651861}]}]}
{"op":"mcm","clk":"11874540774","pt":1723593955250,"mc":[{"id":"1.231652082","rc":[{"batl":[[0,1.86,8.67],[1,1.87,100.98]],"ltp":1.86,"tv":3045.26,"id":6847357},{"batb":[[0,2.14,33.28],[1,1.74,16.78],[2,1.45,57.32]],"ltp":2.22,"tv":205.6,"id":25651861}]}]}
{"op":"mcm","clk":"11874540906","pt":1723593957668,"mc":[{"id":"1.231652082","rc":[{"batb":[[0,2.16,10],[1,2.14,33.28],[2,1.74,16.78]],"ltp":2.22,"tv":205.6,"id":25651861}]}]}
{"op":"mcm","clk":"11874541073","pt":1723593961058,"mc":[{"id":"1.231652082","rc":[{"batb":[[0,2.14,33.28],[1,1.74,16.78],[2,1.45,57.32]],"ltp":2.22,"tv":205.6,"id":25651861}]}]}
{"op":"mcm","clk":"11874541191","pt":1723593963267,"mc":[{"id":"1.231652082","rc":[{"batb":[[0,2.16,10],[1,2.14,33.28],[2,1.74,16.78]],"ltp":2.22,"tv":205.6,"id":25651861}]}]}
{"op":"mcm","clk":"11874541399","pt":1723593966761,"mc":[{"id":"1.231652082","rc":[{"batb":[[0,2.14,33.28],[1,1.74,16.78],[2,1.45,57.32]],"ltp":2.22,"tv":205.6,"id":25651861}]}]}
{"op":"mcm","clk":"11874541621","pt":1723593969843,"mc":[{"id":"1.231652082","rc":[{"batb":[[0,2.16,10],[1,2.14,33.28],[2,1.74,16.78]],"ltp":2.22,"tv":205.6,"id":25651861}]}]}
{"op":"mcm","clk":"11874541859","pt":1723593973495,"mc":[{"id":"1.231652082","rc":[{"batb":[[0,2.14,33.28],[1,1.74,16.78],[2,1.45,57.32]],"ltp":2.22,"tv":205.6,"id":25651861}]}]}
{"op":"mcm","clk":"11874542052","pt":1723593976882,"mc":[{"id":"1.231652082","rc":[{"batb":[[0,2.16,10],[1,2.14,33.28],[2,1.74,16.78]],"ltp":2.22,"tv":205.6,"id":25651861}]}]}
{"op":"mcm","clk":"11874542189","pt":1723593979091,"mc":[{"id":"1.231652082","rc":[{"trd":[[1.86,20.94]],"batb":[[0,1.75,8.31],[1,1.74,17.32],[2,1.73,51.97]],"batl":[[0,1.87,98.83],[1,1.87,0]],"ltp":1.86,"tv":3062.6,"id":6847357}],"tv":3268.21}]}
{"op":"mcm","clk":"11874542257","pt":1723593980270,"mc":[{"id":"1.231652082","rc":[{"batb":[[0,2.14,33.28],[1,1.74,16.78],[2,1.45,57.32]],"ltp":2.22,"tv":205.6,"id":25651861}]}]}
{"op":"mcm","clk":"11874542408","pt":1723593982689,"mc":[{"id":"1.231652082","rc":[{"batb":[[0,2.16,10],[1,2.14,33.28],[2,1.74,16.78]],"ltp":2.22,"tv":205.6,"id":25651861}]}]}
{"op":"mcm","clk":"11874542617","pt":1723593985987,"mc":[{"id":"1.231652082","rc":[{"batb":[[0,2.14,33.28],[1,1.74,16.78],[2,1.45,57.32]],"ltp":2.22,"tv":205.6,"id":25651861}]}]}
{"op":"mcm","clk":"11874542788","pt":1723593988567,"mc":[{"id":"1.231652082","rc":[{"batb":[[0,2.16,10],[1,2.14,33.28],[2,1.74,16.78]],"ltp":2.22,"tv":205.6,"id":25651861}]}]}
{"op":"mcm","clk":"11874542993","pt":1723593991976,"mc":[{"id":"1.231652082","rc":[{"batb":[[0,2.14,33.28],[1,1.74,16.78],[2,1.45,57.32]],"ltp":2.22,"tv":205.6,"id":25651861}]}]}
{"op":"mcm","clk":"11874543136","pt":1723593994382,"mc":[{"id":"1.231652082","rc":[{"batb":[[0,2.16,10],[1,2.14,33.28],[2,1.74,16.78]],"ltp":2.22,"tv":205.6,"id":25651861}]}]}
{"op":"mcm","clk":"11874543337","pt":1723593998083,"mc":[{"id":"1.231652082","rc":[{"batb":[[0,2.14,33.28],[1,1.74,16.78],[2,1.45,57.32]],"ltp":2.22,"tv":205.6,"id":25651861}]}]}
{"op":"mcm","clk":"11874543525","pt":1723594001417,"mc":[{"id":"1.231652082","rc":[{"batb":[[0,2.16,10],[1,2.14,33.28],[2,1.74,16.78]],"ltp":2.22,"tv":205.6,"id":25651861}]}]}
{"op":"mcm","clk":"11874543688","pt":1723594004600,"mc":[{"id":"1.231652082","rc":[{"batb":[[0,2.14,33.28],[1,1.74,16.78],[2,1.45,57.32]],"ltp":2.22,"tv":205.6,"id":25651861}]}]}
{"op":"mcm","clk":"11874543832","pt":1723594007724,"mc":[{"id":"1.231652082","rc":[{"batb":[[0,2.16,10],[1,2.14,33.28],[2,1.74,16.78]],"ltp":2.22,"tv":205.6,"id":25651861}]}]}
{"op":"mcm","clk":"11874543891","pt":1723594008602,"mc":[{"id":"1.231652082","rc":[{"batb":[[0,1.75,46.49]],"ltp":1.86,"tv":3062.6,"id":6847357}]}]}
{"op":"mcm","clk":"11874544027","pt":1723594011014,"mc":[{"id":"1.231652082","rc":[{"batb":[[0,2.14,33.28],[1,1.74,16.78],[2,1.45,57.32]],"ltp":2.22,"tv":205.6,"id":25651861}]}]}
{"op":"mcm","clk":"11874544228","pt":1723594014207,"mc":[{"id":"1.231652082","rc":[{"batb":[[0,2.16,10],[1,2.14,33.28],[2,1.74,16.78]],"ltp":2.22,"tv":205.6,"id":25651861}]}]}
{"op":"mcm","clk":"11874544466","pt":1723594017804,"mc":[{"id":"1.231652082","rc":[{"batb":[[0,2.14,33.28],[1,1.74,16.78],[2,1.45,57.32]],"ltp":2.22,"tv":205.6,"id":25651861}]}]}
{"op":"mcm","clk":"11874544625","pt":1723594020524,"mc":[{"id":"1.231652082","rc":[{"batb":[[0,2.16,10],[1,2.14,33.28],[2,1.74,16.78]],"ltp":2.22,"tv":205.6,"id":25651861}]}]}
{"op":"mcm","clk":"11874544831","pt":1723594024230,"mc":[{"id":"1.231652082","rc":[{"batb":[[0,2.14,33.28],[1,1.74,16.78],[2,1.45,57.32]],"ltp":2.22,"tv":205.6,"id":25651861}]}]}
{"op":"mcm","clk":"11874544978","pt":1723594026541,"mc":[{"id":"1.231652082","rc":[{"batb":[[0,2.16,10],[1,2.14,33.28],[2,1.74,16.78]],"ltp":2.22,"tv":205.6,"id":25651861}]}]}
{"op":"mcm","clk":"11874545212","pt":1723594029929,"mc":[{"id":"1.231652082","rc":[{"batb":[[0,2.14,33.28],[1,1.74,16.78],[2,1.45,57.32]],"ltp":2.22,"tv":205.6,"id":25651861}]}]}
{"op":"mcm","clk":"11874545386","pt":1723594032653,"mc":[{"id":"1.231652082","rc":[{"batb":[[0,2.16,10],[1,2.14,33.28],[2,1.74,16.78]],"ltp":2.22,"tv":205.6,"id":25651861}]}]}
{"op":"mcm","clk":"11874545590","pt":1723594036142,"mc":[{"id":"1.231652082","rc":[{"batb":[[0,2.14,33.28],[1,1.74,16.78],[2,1.45,57.32]],"ltp":2.22,"tv":205.6,"id":25651861}]}]}
{"op":"mcm","clk":"11874545705","pt":1723594038350,"mc":[{"id":"1.231652082","rc":[{"batb":[[0,2.16,10],[1,2.14,33.28],[2,1.74,16.78]],"ltp":2.22,"tv":205.6,"id":25651861}]}]}
{"op":"mcm","clk":"11874545908","pt":1723594041851,"mc":[{"id":"1.231652082","rc":[{"batb":[[0,2.14,33.28],[1,1.74,16.78],[2,1.45,57.32]],"ltp":2.22,"tv":205.6,"id":25651861}]}]}
{"op":"mcm","clk":"11874546064","pt":1723594044474,"mc":[{"id":"1.231652082","rc":[{"batb":[[0,2.16,10],[1,2.14,33.28],[2,1.74,16.78]],"ltp":2.22,"tv":205.6,"id":25651861}]}]}
{"op":"mcm","clk":"11874546279","pt":1723594048079,"mc":[{"id":"1.231652082","rc":[{"batb":[[0,2.14,33.28],[1,1.74,16.78],[2,1.45,57.32]],"ltp":2.22,"tv":205.6,"id":25651861}]}]}
{"op":"mcm","clk":"11874546314","pt":1723594048744,"mc":[{"id":"1.231652082","rc":[{"batb":[[0,1.87,11.62],[1,1.75,46.49],[2,1.74,17.32]],"ltp":1.86,"tv":3062.6,"id":6847357}]}]}
{"op":"mcm","clk":"11874546476","pt":1723594051675,"mc":[{"id":"1.231652082","rc":[{"trd":[[1.87,11.55]],"batb":[[0,1.75,46.56],[1,1.74,17.32],[2,1.73,51.97]],"ltp":1.87,"tv":3074.15,"id":6847357},{"trd":[[2.16,10]],"ltp":2.16,"tv":215.6,"id":25651861}],"tv":3289.76}]}
{"op":"mcm","clk":"11874546643","pt":1723594054864,"mc":[{"id":"1.231652082","rc":[{"trd":[[1.87,11.62]],"batb":[[0,1.75,46.49]],"ltp":1.87,"tv":3074.22,"id":6847357},{"trd":[[2.16,10.06]],"batb":[[0,2.16,9.94],[1,2.14,33.28],[2,1.74,16.78]],"ltp":2.16,"tv":215.66,"id":25651861}],"tv":3289.89}]}
{"op":"mcm","clk":"11874546828","pt":1723594058151,"mc":[{"id":"1.231652082","rc":[{"batb":[[0,2.14,33.28],[1,1.74,16.78],[2,1.45,57.32]],"ltp":2.16,"tv":215.66,"id":25651861}]}]}
{"op":"mcm","clk":"11874546997","pt":1723594060664,"mc":[{"id":"1.231652082","rc":[{"batb":[[0,2.16,10],[1,2.14,33.28],[2,1.74,16.78]],"ltp":2.16,"tv":215.66,"id":25651861}]}]}
{"op":"mcm","clk":"11874547198","pt":1723594063950,"mc":[{"id":"1.231652082","rc":[{"batb":[[0,2.14,33.28],[1,1.74,16.78],[2,1.45,57.32]],"ltp":2.16,"tv":215.66,"id":25651861}]}]}
{"op":"mcm","clk":"11874547340","pt":1723594066675,"mc":[{"id":"1.231652082","rc":[{"batb":[[0,2.16,10],[1,2.14,33.28],[2,1.74,16.78]],"ltp":2.16,"tv":215.66,"id":25651861}]}]}
{"op":"mcm","clk":"11874547534","pt":1723594069968,"mc":[{"id":"1.231652082","rc":[{"batb":[[0,2.14,33.28],[1,1.74,16.78],[2,1.45,57.32]],"ltp":2.16,"tv":215.66,"id":25651861}]}]}
{"op":"mcm","clk":"11874547674","pt":1723594072479,"mc":[{"id":"1.231652082","rc":[{"batb":[[0,2.16,10],[1,2.14,33.28],[2,1.74,16.78]],"ltp":2.16,"tv":215.66,"id":25651861}]}]}
{"op":"mcm","clk":"11874547900","pt":1723594075971,"mc":[{"id":"1.231652082","rc":[{"batb":[[0,2.14,33.28],[1,1.74,16.78],[2,1.45,57.32]],"ltp":2.16,"tv":215.66,"id":25651861}]}]}
{"op":"mcm","clk":"11874548069","pt":1723594078500,"mc":[{"id":"1.231652082","rc":[{"batb":[[0,2.16,10],[1,2.14,33.28],[2,1.74,16.78]],"ltp":2.16,"tv":215.66,"id":25651861}]}]}
{"op":"mcm","clk":"11874548258","pt":1723594081886,"mc":[{"id":"1.231652082","rc":[{"batb":[[0,2.14,33.28],[1,1.74,16.78],[2,1.45,57.32]],"ltp":2.16,"tv":215.66,"id":25651861}]}]}
{"op":"mcm","clk":"11874548416","pt":1723594085124,"mc":[{"id":"1.231652082","rc":[{"batb":[[0,2.16,10],[1,2.14,33.28],[2,1.74,16.78]],"ltp":2.16,"tv":215.66,"id":25651861}]}]}
{"op":"mcm","clk":"11874548613","pt":1723594088626,"mc":[{"id":"1.231652082","rc":[{"batb":[[0,2.14,33.28],[1,1.74,16.78],[2,1.45,57.32]],"ltp":2.16,"tv":215.66,"id":25651861}]}]}
{"op":"mcm","clk":"11874548817","pt":1723594092124,"mc":[{"id":"1.231652082","rc":[{"batb":[[0,2.16,10],[1,2.14,33.28],[2,1.74,16.78]],"ltp":2.16,"tv":215.66,"id":25651861}]}]}
{"op":"mcm","clk":"11874549033","pt":1723594095528,"mc":[{"id":"1.231652082","rc":[{"batb":[[0,2.14,33.28],[1,1.74,16.78],[2,1.45,57.32]],"ltp":2.16,"tv":215.66,"id":25651861}]}]}
{"op":"mcm","clk":"11874549179","pt":1723594098097,"mc":[{"id":"1.231652082","rc":[{"batb":[[0,2.16,10],[1,2.14,33.28],[2,1.74,16.78]],"ltp":2.16,"tv":215.66,"id":25651861}]}]}
{"op":"mcm","clk":"11874549354","pt":1723594101534,"mc":[{"id":"1.231652082","rc":[{"batb":[[0,2.14,33.28],[1,1.74,16.78],[2,1.45,57.32]],"ltp":2.16,"tv":215.66,"id":25651861}]}]}
{"op":"mcm","clk":"11874549485","pt":1723594104150,"mc":[{"id":"1.231652082","rc":[{"batb":[[0,2.16,10],[1,2.14,33.28],[2,1.74,16.78]],"ltp":2.16,"tv":215.66,"id":25651861}]}]}
{"op":"mcm","clk":"11874549654","pt":1723594107651,"mc":[{"id":"1.231652082","rc":[{"batb":[[0,2.14,33.28],[1,1.74,16.78],[2,1.45,57.32]],"ltp":2.16,"tv":215.66,"id":25651861}]}]}
{"op":"mcm","clk":"11874549768","pt":1723594110159,"mc":[{"id":"1.231652082","rc":[{"batb":[[0,2.16,10],[1,2.14,33.28],[2,1.74,16.78]],"ltp":2.16,"tv":215.66,"id":25651861}]}]}
{"op":"mcm","clk":"11874549985","pt":1723594113763,"mc":[{"id":"1.231652082","rc":[{"batb":[[0,2.14,33.28],[1,1.74,16.78],[2,1.45,57.32]],"ltp":2.16,"tv":215.66,"id":25651861}]}]}
{"op":"mcm","clk":"11874550128","pt":1723594116136,"mc":[{"id":"1.231652082","rc":[{"batb":[[0,2.16,10],[1,2.14,33.28],[2,1.74,16.78]],"ltp":2.16,"tv":215.66,"id":25651861}]}]}
{"op":"mcm","clk":"11874550323","pt":1723594119632,"mc":[{"id":"1.231652082","rc":[{"batb":[[0,2.14,33.28],[1,1.74,16.78],[2,1.45,57.32]],"ltp":2.16,"tv":215.66,"id":25651861}]}]}
{"op":"mcm","clk":"11874550459","pt":1723594122044,"mc":[{"id":"1.231652082","rc":[{"batb":[[0,2.16,10],[1,2.14,33.28],[2,1.74,16.78]],"ltp":2.16,"tv":215.66,"id":25651861}]}]}
{"op":"mcm","clk":"11874550614","pt":1723594125380,"mc":[{"id":"1.231652082","rc":[{"batb":[[0,2.14,33.28],[1,1.74,16.78],[2,1.45,57.32]],"ltp":2.16,"tv":215.66,"id":25651861}]}]}
{"op":"mcm","clk":"11874550788","pt":1723594128479,"mc":[{"id":"1.231652082","rc":[{"batb":[[0,2.16,10],[1,2.14,33.28],[2,1.74,16.78]],"ltp":2.16,"tv":215.66,"id":25651861}]}]}
{"op":"mcm","clk":"11874550958","pt":1723594131772,"mc":[{"id":"1.231652082","rc":[{"batb":[[0,2.14,33.28],[1,1.74,16.78],[2,1.45,57.32]],"ltp":2.16,"tv":215.66,"id":25651861}]}]}
{"op":"mcm","clk":"11874551115","pt":1723594134543,"mc":[{"id":"1.231652082","rc":[{"batb":[[0,2.16,10],[1,2.14,33.28],[2,1.74,16.78]],"ltp":2.16,"tv":215.66,"id":25651861}]}]}
{"op":"mcm","clk":"11874551292","pt":1723594137988,"mc":[{"id":"1.231652082","rc":[{"batb":[[0,2.14,33.28],[1,1.74,16.78],[2,1.45,57.32]],"ltp":2.16,"tv":215.66,"id":25651861}]}]}
{"op":"mcm","clk":"11874551478","pt":1723594141895,"mc":[{"id":"1.231652082","rc":[{"batb":[[0,2.16,10],[1,2.14,33.28],[2,1.74,16.78]],"ltp":2.16,"tv":215.66,"id":25651861}]}]}
{"op":"mcm","clk":"11874551666","pt":1723594145290,"mc":[{"id":"1.231652082","rc":[{"batb":[[0,2.14,33.28],[1,1.74,16.78],[2,1.45,57.32]],"ltp":2.16,"tv":215.66,"id":25651861}]}]}
{"op":"mcm","clk":"11874551824","pt":1723594147705,"mc":[{"id":"1.231652082","rc":[{"batb":[[0,2.16,10],[1,2.14,33.28],[2,1.74,16.78]],"ltp":2.16,"tv":215.66,"id":25651861}]}]}
{"op":"mcm","clk":"11874552061","pt":1723594150997,"mc":[{"id":"1.231652082","rc":[{"batb":[[0,2.14,33.28],[1,1.74,16.78],[2,1.45,57.32]],"ltp":2.16,"tv":215.66,"id":25651861}]}]}
{"op":"mcm","clk":"11874552252","pt":1723594153680,"mc":[{"id":"1.231652082","rc":[{"batb":[[0,2.16,10],[1,2.14,33.28],[2,1.74,16.78]],"ltp":2.16,"tv":215.66,"id":25651861}]}]}
{"op":"mcm","clk":"11874552454","pt":1723594157023,"mc":[{"id":"1.231652082","rc":[{"batb":[[0,2.14,33.28],[1,1.74,16.78],[2,1.45,57.32]],"ltp":2.16,"tv":215.66,"id":25651861}]}]}
{"op":"mcm","clk":"11874552579","pt":1723594159600,"mc":[{"id":"1.231652082","rc":[{"batb":[[0,2.16,10],[1,2.14,33.28],[2,1.74,16.78]],"ltp":2.16,"tv":215.66,"id":25651861}]}]}
{"op":"mcm","clk":"11874552805","pt":1723594163094,"mc":[{"id":"1.231652082","rc":[{"batb":[[0,2.14,33.28],[1,1.74,16.78],[2,1.45,57.32]],"ltp":2.16,"tv":215.66,"id":25651861}]}]}
{"op":"mcm","clk":"11874552981","pt":1723594165512,"mc":[{"id":"1.231652082","rc":[{"batb":[[0,2.16,10],[1,2.14,33.28],[2,1.74,16.78]],"ltp":2.16,"tv":215.66,"id":25651861}]}]}
{"op":"mcm","clk":"11874553210","pt":1723594168907,"mc":[{"id":"1.231652082","rc":[{"batb":[[0,2.14,33.28],[1,1.74,16.78],[2,1.45,57.32]],"ltp":2.16,"tv":215.66,"id":25651861}]}]}
{"op":"mcm","clk":"11874553334","pt":1723594171317,"mc":[{"id":"1.231652082","rc":[{"batb":[[0,2.16,10],[1,2.14,33.28],[2,1.74,16.78]],"ltp":2.16,"tv":215.66,"id":25651861}]}]}
{"op":"mcm","clk":"11874553531","pt":1723594174827,"mc":[{"id":"1.231652082","rc":[{"batb":[[0,2.14,33.28],[1,1.74,16.78],[2,1.45,57.32]],"ltp":2.16,"tv":215.66,"id":25651861}]}]}
{"op":"mcm","clk":"11874553710","pt":1723594177720,"mc":[{"id":"1.231652082","rc":[{"batb":[[0,2.16,10],[1,2.14,33.28],[2,1.74,16.78]],"ltp":2.16,"tv":215.66,"id":25651861}]}]}
{"op":"mcm","clk":"11874553881","pt":1723594181264,"mc":[{"id":"1.231652082","rc":[{"batb":[[0,2.14,33.28],[1,1.74,16.78],[2,1.45,57.32]],"ltp":2.16,"tv":215.66,"id":25651861}]}]}
{"op":"mcm","clk":"11874554088","pt":1723594184611,"mc":[{"id":"1.231652082","rc":[{"batb":[[0,2.16,10],[1,2.14,33.28],[2,1.74,16.78]],"ltp":2.16,"tv":215.66,"id":25651861}]}]}
{"op":"mcm","clk":"11874554267","pt":1723594187918,"mc":[{"id":"1.231652082","rc":[{"batb":[[0,2.14,33.28],[1,1.74,16.78],[2,1.45,57.32]],"ltp":2.16,"tv":215.66,"id":25651861}]}]}
{"op":"mcm","clk":"11874554467","pt":1723594191057,"mc":[{"id":"1.231652082","rc":[{"batb":[[0,2.16,10],[1,2.14,33.28],[2,1.74,16.78]],"ltp":2.16,"tv":215.66,"id":25651861}]}]}
{"op":"mcm","clk":"11874554641","pt":1723594194348,"mc":[{"id":"1.231652082","rc":[{"batb":[[0,2.14,33.28],[1,1.74,16.78],[2,1.45,57.32]],"ltp":2.16,"tv":215.66,"id":25651861}]}]}
{"op":"mcm","clk":"11874554881","pt":1723594197841,"mc":[{"id":"1.231652082","rc":[{"batb":[[0,2.16,10],[1,2.14,33.28],[2,1.74,16.78]],"ltp":2.16,"tv":215.66,"id":25651861}]}]}
{"op":"mcm","clk":"11874555140","pt":1723594201283,"mc":[{"id":"1.231652082","rc":[{"batb":[[0,2.14,33.28],[1,1.74,16.78],[2,1.45,57.32]],"ltp":2.16,"tv":215.66,"id":25651861}]}]}
{"op":"mcm","clk":"11874555293","pt":1723594203656,"mc":[{"id":"1.231652082","rc":[{"batb":[[0,2.16,10],[1,2.14,33.28],[2,1.74,16.78]],"ltp":2.16,"tv":215.66,"id":25651861}]}]}
{"op":"mcm","clk":"11874555482","pt":1723594206988,"mc":[{"id":"1.231652082","rc":[{"batb":[[0,2.14,33.28],[1,1.74,16.78],[2,1.45,57.32]],"ltp":2.16,"tv":215.66,"id":25651861}]}]}
{"op":"mcm","clk":"11874555655","pt":1723594209661,"mc":[{"id":"1.231652082","rc":[{"batb":[[0,2.16,10],[1,2.14,33.28],[2,1.74,16.78]],"ltp":2.16,"tv":215.66,"id":25651861}]}]}
{"op":"mcm","clk":"11874555844","pt":1723594213156,"mc":[{"id":"1.231652082","rc":[{"batb":[[0,2.14,33.28],[1,1.74,16.78],[2,1.45,57.32]],"ltp":2.16,"tv":215.66,"id":25651861}]}]}
{"op":"mcm","clk":"11874555972","pt":1723594215669,"mc":[{"id":"1.231652082","rc":[{"batb":[[0,2.16,10],[1,2.14,33.28],[2,1.74,16.78]],"ltp":2.16,"tv":215.66,"id":25651861}]}]}
{"op":"mcm","clk":"11874556163","pt":1723594219276,"mc":[{"id":"1.231652082","rc":[{"batb":[[0,2.14,33.28],[1,1.74,16.78],[2,1.45,57.32]],"ltp":2.16,"tv":215.66,"id":25651861}]}]}
{"op":"mcm","clk":"11874556295","pt":1723594221587,"mc":[{"id":"1.231652082","rc":[{"batb":[[0,2.16,10],[1,2.14,33.28],[2,1.74,16.78]],"ltp":2.16,"tv":215.66,"id":25651861}]}]}
{"op":"mcm","clk":"11874556504","pt":1723594224975,"mc":[{"id":"1.231652082","rc":[{"batb":[[0,2.14,33.28],[1,1.74,16.78],[2,1.45,57.32]],"ltp":2.16,"tv":215.66,"id":25651861}]}]}
{"op":"mcm","clk":"11874556668","pt":1723594227594,"mc":[{"id":"1.231652082","rc":[{"batb":[[0,2.16,10],[1,2.14,33.28],[2,1.74,16.78]],"ltp":2.16,"tv":215.66,"id":25651861}]}]}
{"op":"mcm","clk":"11874556885","pt":1723594231092,"mc":[{"id":"1.231652082","rc":[{"batb":[[0,2.14,33.28],[1,1.74,16.78],[2,1.45,57.32]],"ltp":2.16,"tv":215.66,"id":25651861}]}]}
{"op":"mcm","clk":"11874557039","pt":1723594233608,"mc":[{"id":"1.231652082","rc":[{"batb":[[0,2.16,10],[1,2.14,33.28],[2,1.74,16.78]],"ltp":2.16,"tv":215.66,"id":25651861}]}]}
{"op":"mcm","clk":"11874557263","pt":1723594237003,"mc":[{"id":"1.231652082","rc":[{"batb":[[0,2.14,33.28],[1,1.74,16.78],[2,1.45,57.32]],"ltp":2.16,"tv":215.66,"id":25651861}]}]}
{"op":"mcm","clk":"11874557437","pt":1723594239588,"mc":[{"id":"1.231652082","rc":[{"batb":[[0,2.16,10],[1,2.14,33.28],[2,1.74,16.78]],"ltp":2.16,"tv":215.66,"id":25651861}]}]}
{"op":"mcm","clk":"11874557644","pt":1723594243125,"mc":[{"id":"1.231652082","rc":[{"batb":[[0,2.14,33.28],[1,1.74,16.78],[2,1.45,57.32]],"ltp":2.16,"tv":215.66,"id":25651861}]}]}
{"op":"mcm","clk":"11874557768","pt":1723594245392,"mc":[{"id":"1.231652082","rc":[{"batb":[[0,2.16,10],[1,2.14,33.28],[2,1.74,16.78]],"ltp":2.16,"tv":215.66,"id":25651861}]}]}
{"op":"mcm","clk":"11874557948","pt":1723594248791,"mc":[{"id":"1.231652082","rc":[{"batb":[[0,2.14,33.28],[1,1.74,16.78],[2,1.45,57.32]],"ltp":2.16,"tv":215.66,"id":25651861}]}]}
{"op":"mcm","clk":"11874558079","pt":1723594251023,"mc":[{"id":"1.231652082","rc":[{"batb":[[0,2.16,10],[1,2.14,33.28],[2,1.74,16.78]],"ltp":2.16,"tv":215.66,"id":25651861}]}]}
{"op":"mcm","clk":"11874558316","pt":1723594254422,"mc":[{"id":"1.231652082","rc":[{"batb":[[0,2.14,33.28],[1,1.74,16.78],[2,1.45,57.32]],"ltp":2.16,"tv":215.66,"id":25651861}]}]}
{"op":"mcm","clk":"11874558508","pt":1723594257926,"mc":[{"id":"1.231652082","rc":[{"batb":[[0,2.16,10],[1,2.14,33.28],[2,1.74,16.78]],"ltp":2.16,"tv":215.66,"id":25651861}]}]}
{"op":"mcm","clk":"11874558727","pt":1723594261125,"mc":[{"id":"1.231652082","rc":[{"batb":[[0,2.14,33.28],[1,1.74,16.78],[2,1.45,57.32]],"ltp":2.16,"tv":215.66,"id":25651861}]}]}
{"op":"mcm","clk":"11874558946","pt":1723594263916,"mc":[{"id":"1.231652082","rc":[{"batb":[[0,2.16,10],[1,2.14,33.28],[2,1.74,16.78]],"ltp":2.16,"tv":215.66,"id":25651861}]}]}
{"op":"mcm","clk":"11874559159","pt":1723594267424,"mc":[{"id":"1.231652082","rc":[{"batb":[[0,2.14,33.28],[1,1.74,16.78],[2,1.45,57.32]],"ltp":2.16,"tv":215.66,"id":25651861}]}]}
{"op":"mcm","clk":"11874559316","pt":1723594270126,"mc":[{"id":"1.231652082","rc":[{"batb":[[0,2.16,10],[1,2.14,33.28],[2,1.74,16.78]],"ltp":2.16,"tv":215.66,"id":25651861}]}]}
{"op":"mcm","clk":"11874559535","pt":1723594273571,"mc":[{"id":"1.231652082","rc":[{"batb":[[0,2.14,33.28],[1,1.74,16.78],[2,1.45,57.32]],"ltp":2.16,"tv":215.66,"id":25651861}]}]}
{"op":"mcm","clk":"11874559655","pt":1723594275841,"mc":[{"id":"1.231652082","rc":[{"batb":[[0,2.16,10],[1,2.14,33.28],[2,1.74,16.78]],"ltp":2.16,"tv":215.66,"id":25651861}]}]}
{"op":"mcm","clk":"11874559851","pt":1723594279036,"mc":[{"id":"1.231652082","rc":[{"batb":[[0,2.14,33.28],[1,1.74,16.78],[2,1.45,57.32]],"ltp":2.16,"tv":215.66,"id":25651861}]}]}
{"op":"mcm","clk":"11874560099","pt":1723594283318,"mc":[{"id":"1.231652082","rc":[{"batb":[[0,2.16,10],[1,2.14,33.28],[2,1.74,16.78]],"ltp":2.16,"tv":215.66,"id":25651861}]}]}
{"op":"mcm","clk":"11874560313","pt":1723594286766,"mc":[{"id":"1.231652082","rc":[{"batb":[[0,2.14,33.28],[1,1.74,16.78],[2,1.45,57.32]],"ltp":2.16,"tv":215.66,"id":25651861}]}]}
{"op":"mcm","clk":"11874560472","pt":1723594289190,"mc":[{"id":"1.231652082","rc":[{"batb":[[0,2.16,10],[1,2.14,33.28],[2,1.74,16.78]],"ltp":2.16,"tv":215.66,"id":25651861}]}]}
{"op":"mcm","clk":"11874560649","pt":1723594292584,"mc":[{"id":"1.231652082","rc":[{"batb":[[0,2.14,33.28],[1,1.74,16.78],[2,1.45,57.32]],"ltp":2.16,"tv":215.66,"id":25651861}]}]}
{"op":"mcm","clk":"11874560807","pt":1723594295061,"mc":[{"id":"1.231652082","rc":[{"batb":[[0,2.16,10],[1,2.14,33.28],[2,1.74,16.78]],"ltp":2.16,"tv":215.66,"id":25651861}]}]}
{"op":"mcm","clk":"11874561023","pt":1723594298605,"mc":[{"id":"1.231652082","rc":[{"batb":[[0,2.14,33.28],[1,1.74,16.78],[2,1.45,57.32]],"ltp":2.16,"tv":215.66,"id":25651861}]}]}
{"op":"mcm","clk":"11874561179","pt":1723594301079,"mc":[{"id":"1.231652082","rc":[{"batb":[[0,2.16,10],[1,2.14,33.28],[2,1.74,16.78]],"ltp":2.16,"tv":215.66,"id":25651861}]}]}
{"op":"mcm","clk":"11874561406","pt":1723594304498,"mc":[{"id":"1.231652082","rc":[{"batb":[[0,2.14,33.28],[1,1.74,16.78],[2,1.45,57.32]],"ltp":2.16,"tv":215.66,"id":25651861}]}]}
{"op":"mcm","clk":"11874561537","pt":1723594306720,"mc":[{"id":"1.231652082","rc":[{"batb":[[0,2.16,10],[1,2.14,33.28],[2,1.74,16.78]],"ltp":2.16,"tv":215.66,"id":25651861}]}]}
{"op":"mcm","clk":"11874561797","pt":1723594310592,"mc":[{"id":"1.231652082","rc":[{"batb":[[0,2.14,33.28],[1,1.74,16.78],[2,1.45,57.32]],"ltp":2.16,"tv":215.66,"id":25651861}]}]}
{"op":"mcm","clk":"11874561981","pt":1723594313588,"mc":[{"id":"1.231652082","rc":[{"batb":[[0,2.16,10],[1,2.14,33.28],[2,1.74,16.78]],"ltp":2.16,"tv":215.66,"id":25651861}]}]}
{"op":"mcm","clk":"11874562173","pt":1723594317088,"mc":[{"id":"1.231652082","rc":[{"batb":[[0,2.14,33.28],[1,1.74,16.78],[2,1.45,57.32]],"ltp":2.16,"tv":215.66,"id":25651861}]}]}
{"op":"mcm","clk":"11874562292","pt":1723594319321,"mc":[{"id":"1.231652082","rc":[{"batb":[[0,2.16,10],[1,2.14,33.28],[2,1.74,16.78]],"ltp":2.16,"tv":215.66,"id":25651861}]}]}
{"op":"mcm","clk":"11874562505","pt":1723594322825,"mc":[{"id":"1.231652082","rc":[{"batb":[[0,2.14,33.28],[1,1.74,16.78],[2,1.45,57.32]],"ltp":2.16,"tv":215.66,"id":25651861}]}]}
{"op":"mcm","clk":"11874562685","pt":1723594325297,"mc":[{"id":"1.231652082","rc":[{"batb":[[0,2.16,10],[1,2.14,33.28],[2,1.74,16.78]],"ltp":2.16,"tv":215.66,"id":25651861}]}]}
{"op":"mcm","clk":"11874562924","pt":1723594328743,"mc":[{"id":"1.231652082","rc":[{"batb":[[0,2.14,33.28],[1,1.74,16.78],[2,1.45,57.32]],"ltp":2.16,"tv":215.66,"id":25651861}]}]}
{"op":"mcm","clk":"11874563097","pt":1723594331118,"mc":[{"id":"1.231652082","rc":[{"batb":[[0,2.16,10],[1,2.14,33.28],[2,1.74,16.78]],"ltp":2.16,"tv":215.66,"id":25651861}]}]}
{"op":"mcm","clk":"11874563326","pt":1723594334827,"mc":[{"id":"1.231652082","rc":[{"batb":[[0,2.14,33.28],[1,1.74,16.78],[2,1.45,57.32]],"ltp":2.16,"tv":215.66,"id":25651861}]}]}
{"op":"mcm","clk":"11874563500","pt":1723594337350,"mc":[{"id":"1.231652082","rc":[{"batb":[[0,2.16,10],[1,2.14,33.28],[2,1.74,16.78]],"ltp":2.16,"tv":215.66,"id":25651861}]}]}
{"op":"mcm","clk":"11874563720","pt":1723594340847,"mc":[{"id":"1.231652082","rc":[{"batb":[[0,2.14,33.28],[1,1.74,16.78],[2,1.45,57.32]],"ltp":2.16,"tv":215.66,"id":25651861}]}]}
{"op":"mcm","clk":"11874563855","pt":1723594343119,"mc":[{"id":"1.231652082","rc":[{"batb":[[0,2.16,10],[1,2.14,33.28],[2,1.74,16.78]],"ltp":2.16,"tv":215.66,"id":25651861}]}]}
{"op":"mcm","clk":"11874564091","pt":1723594346618,"mc":[{"id":"1.231652082","rc":[{"batb":[[0,2.14,33.28],[1,1.74,16.78],[2,1.45,57.32]],"ltp":2.16,"tv":215.66,"id":25651861}]}]}
{"op":"mcm","clk":"11874564241","pt":1723594348990,"mc":[{"id":"1.231652082","rc":[{"batb":[[0,2.16,10],[1,2.14,33.28],[2,1.74,16.78]],"ltp":2.16,"tv":215.66,"id":25651861}]}]}
{"op":"mcm","clk":"11874564483","pt":1723594352632,"mc":[{"id":"1.231652082","rc":[{"batb":[[0,1.76,150.12],[1,1.75,46.49],[2,1.74,17.32]],"ltp":1.87,"tv":3074.22,"id":6847357},{"batb":[[0,2.14,33.28],[1,1.74,16.78],[2,1.45,57.32]],"ltp":2.16,"tv":215.66,"id":25651861}]}]}
{"op":"mcm","clk":"11874564574","pt":1723594354021,"mc":[{"id":"1.231652082","rc":[{"batb":[[0,1.77,8.21],[1,1.76,150.12],[2,1.75,38.18]],"ltp":1.87,"tv":3074.22,"id":6847357}]}]}
{"op":"mcm","clk":"11874564629","pt":1723594354851,"mc":[{"id":"1.231652082","rc":[{"batb":[[0,1.77,15.99]],"ltp":1.87,"tv":3074.22,"id":6847357},{"batb":[[0,2.16,10],[1,2.14,33.28],[2,1.74,16.78]],"ltp":2.16,"tv":215.66,"id":25651861}]}]}
{"op":"mcm","clk":"11874564837","pt":1723594358258,"mc":[{"id":"1.231652082","rc":[{"batb":[[0,2.14,33.28],[1,1.74,16.78],[2,1.45,57.32]],"ltp":2.16,"tv":215.66,"id":25651861}]}]}
{"op":"mcm","clk":"11874564999","pt":1723594361035,"mc":[{"id":"1.231652082","rc":[{"batb":[[0,2.16,10],[1,2.14,33.28],[2,1.74,16.78]],"ltp":2.16,"tv":215.66,"id":25651861}]}]}
{"op":"mcm","clk":"11874565193","pt":1723594364449,"mc":[{"id":"1.231652082","rc":[{"batb":[[0,2.14,33.28],[1,1.74,16.78],[2,1.45,57.32]],"ltp":2.16,"tv":215.66,"id":25651861}]}]}
{"op":"mcm","clk":"11874565340","pt":1723594366877,"mc":[{"id":"1.231652082","rc":[{"batb":[[0,2.16,10],[1,2.14,33.28],[2,1.74,16.78]],"ltp":2.16,"tv":215.66,"id":25651861}]}]}
{"op":"mcm","clk":"11874565547","pt":1723594369973,"mc":[{"id":"1.231652082","rc":[{"batb":[[0,1.77,53.65],[2,1.74,17.32]],"ltp":1.87,"tv":3074.22,"id":6847357}]}]}
{"op":"mcm","clk":"11874565587","pt":1723594370484,"mc":[{"id":"1.231652082","rc":[{"batb":[[0,2.14,33.28],[1,1.74,16.78],[2,1.45,57.32]],"ltp":2.16,"tv":215.66,"id":25651861}]}]}
{"op":"mcm","clk":"11874565751","pt":1723594372847,"mc":[{"id":"1.231652082","rc":[{"batb":[[0,2.16,10],[1,2.14,33.28],[2,1.74,16.78]],"ltp":2.16,"tv":215.66,"id":25651861}]}]}
{"op":"mcm","clk":"11874565958","pt":1723594376451,"mc":[{"id":"1.231652082","rc":[{"batb":[[0,2.14,33.28],[1,1.74,16.78],[2,1.45,57.32]],"ltp":2.16,"tv":215.66,"id":25651861}]}]}
{"op":"mcm","clk":"11874566065","pt":1723594378351,"mc":[{"id":"1.231652082","rc":[{"batb":[[1,1.74,17.32],[2,1.73,51.97]],"ltp":1.87,"tv":3074.22,"id":6847357}]}]}
{"op":"mcm","clk":"11874566135","pt":1723594379587,"mc":[{"id":"1.231652082","rc":[{"batb":[[0,1.77,45.88]],"ltp":1.87,"tv":3074.22,"id":6847357},{"batb":[[0,2.16,10],[1,2.14,33.28],[2,1.74,16.78]],"ltp":2.16,"tv":215.66,"id":25651861}]}]}
{"op":"mcm","clk":"11874566340","pt":1723594382784,"mc":[{"id":"1.231652082","rc":[{"batb":[[0,2.14,33.28],[1,1.74,16.78],[2,1.45,57.32]],"ltp":2.16,"tv":215.66,"id":25651861}]}]}
{"op":"mcm","clk":"11874566508","pt":1723594385362,"mc":[{"id":"1.231652082","rc":[{"batb":[[0,2.16,10],[1,2.14,33.28],[2,1.74,16.78]],"ltp":2.16,"tv":215.66,"id":25651861}]}]}
{"op":"mcm","clk":"11874566721","pt":1723594388768,"mc":[{"id":"1.231652082","rc":[{"batb":[[0,2.14,33.28],[1,1.74,16.78],[2,1.45,57.32]],"ltp":2.16,"tv":215.66,"id":25651861}]}]}
{"op":"mcm","clk":"11874566914","pt":1723594391596,"mc":[{"id":"1.231652082","rc":[{"batb":[[0,2.16,10],[1,2.14,33.28],[2,1.74,16.78]],"ltp":2.16,"tv":215.66,"id":25651861}]}]}
{"op":"mcm","clk":"11874567157","pt":1723594395201,"mc":[{"id":"1.231652082","rc":[{"batb":[[0,2.14,33.28],[1,1.74,16.78],[2,1.45,57.32]],"ltp":2.16,"tv":215.66,"id":25651861}]}]}
{"op":"mcm","clk":"11874567289","pt":1723594397415,"mc":[{"id":"1.231652082","rc":[{"batb":[[0,2.16,10],[1,2.14,33.28],[2,1.74,16.78]],"ltp":2.16,"tv":215.66,"id":25651861}]}]}
{"op":"mcm","clk":"11874567535","pt":1723594401014,"mc":[{"id":"1.231652082","rc":[{"batb":[[0,2.14,33.28],[1,1.74,16.78],[2,1.45,57.32]],"ltp":2.16,"tv":215.66,"id":25651861}]}]}
{"op":"mcm","clk":"11874567690","pt":1723594403279,"mc":[{"id":"1.231652082","rc":[{"batb":[[0,2.16,10],[1,2.14,33.28],[2,1.74,16.78]],"ltp":2.16,"tv":215.66,"id":25651861}]}]}
{"op":"mcm","clk":"11874567900","pt":1723594406621,"mc":[{"id":"1.231652082","rc":[{"batb":[[0,2.14,33.28],[1,1.74,16.78],[2,1.45,57.32]],"ltp":2.16,"tv":215.66,"id":25651861}]}]}
{"op":"mcm","clk":"11874568151","pt":1723594409400,"mc":[{"id":"1.231652082","rc":[{"batb":[[0,2.16,10],[1,2.14,33.28],[2,1.74,16.78]],"ltp":2.16,"tv":215.66,"id":25651861}]}]}
{"op":"mcm","clk":"11874568485","pt":1723594412788,"mc":[{"id":"1.231652082","rc":[{"batb":[[0,1.77,8.21],[1,1.75,38.18],[2,1.74,17.32]],"ltp":1.87,"tv":3074.22,"id":6847357},{"batb":[[0,2.14,33.28],[1,1.74,16.78],[2,1.45,57.32]],"ltp":2.16,"tv":215.66,"id":25651861}]}]}
{"op":"mcm","clk":"11874568566","pt":1723594414127,"mc":[{"id":"1.231652082","rc":[{"batb":[[0,1.75,38.18],[1,1.74,17.32],[2,1.73,51.97]],"ltp":1.87,"tv":3074.22,"id":6847357}]}]}
{"op":"mcm","clk":"11874568571","pt":1723594414230,"mc":[{"id":"1.231652082","rc":[{"batb":[[0,1.76,8.26],[1,1.75,38.18],[2,1.74,17.32]],"ltp":1.87,"tv":3074.22,"id":6847357}]}]}
{"op":"mcm","clk":"11874568668","pt":1723594415619,"mc":[{"id":"1.231652082","rc":[{"batb":[[0,2.16,10],[1,2.14,33.28],[2,1.74,16.78]],"ltp":2.16,"tv":215.66,"id":25651861}]}]}
{"op":"mcm","clk":"11874568865","pt":1723594419009,"mc":[{"id":"1.231652082","rc":[{"batb":[[0,2.14,33.28],[1,1.74,16.78],[2,1.45,57.32]],"ltp":2.16,"tv":215.66,"id":25651861}]}]}
{"op":"mcm","clk":"11874569053","pt":1723594422141,"mc":[{"id":"1.231652082","rc":[{"batb":[[0,2.16,10],[1,2.14,33.28],[2,1.74,16.78]],"ltp":2.16,"tv":215.66,"id":25651861}]}]}
{"op":"mcm","clk":"11874569250","pt":1723594425540,"mc":[{"id":"1.231652082","rc":[{"batb":[[0,2.14,33.28],[1,1.74,16.78],[2,1.45,57.32]],"ltp":2.16,"tv":215.66,"id":25651861}]}]}
{"op":"mcm","clk":"11874569404","pt":1723594428010,"mc":[{"id":"1.231652082","rc":[{"batb":[[0,2.16,10],[1,2.14,33.28],[2,1.74,16.78]],"ltp":2.16,"tv":215.66,"id":25651861}]}]}
{"op":"mcm","clk":"11874569607","pt":1723594431354,"mc":[{"id":"1.231652082","rc":[{"batb":[[0,2.14,33.28],[1,1.74,16.78],[2,1.45,57.32]],"ltp":2.16,"tv":215.66,"id":25651861}]}]}
{"op":"mcm","clk":"11874569840","pt":1723594435056,"mc":[{"id":"1.231652082","rc":[{"batb":[[0,2.16,10],[1,2.14,33.28],[2,1.74,16.78]],"ltp":2.16,"tv":215.66,"id":25651861}]}]}
{"op":"mcm","clk":"11874570104","pt":1723594438447,"mc":[{"id":"1.231652082","rc":[{"batb":[[0,2.14,33.28],[1,1.74,16.78],[2,1.45,57.32]],"ltp":2.16,"tv":215.66,"id":25651861}]}]}
{"op":"mcm","clk":"11874570268","pt":1723594440918,"mc":[{"id":"1.231652082","rc":[{"batb":[[0,2.16,10],[1,2.14,33.28],[2,1.74,16.78]],"ltp":2.16,"tv":215.66,"id":25651861}]}]}
{"op":"mcm","clk":"11874570478","pt":1723594444431,"mc":[{"id":"1.231652082","rc":[{"batb":[[0,2.14,33.28],[1,1.74,16.78],[2,1.45,57.32]],"ltp":2.16,"tv":215.66,"id":25651861}]}]}
{"op":"mcm","clk":"11874570615","pt":1723594447158,"mc":[{"id":"1.231652082","rc":[{"trd":[[1.76,16.52]],"batb":[[0,1.75,38.18],[1,1.74,17.32],[2,1.73,51.97]],"batl":[[0,1.76,0.76]],"ltp":1.76,"tv":3090.74,"id":6847357},{"batb":[[0,2.16,10],[1,2.14,33.28],[2,1.74,16.78]],"ltp":2.16,"tv":215.66,"id":25651861}],"tv":3306.4}]}
{"op":"mcm","clk":"11874570831","pt":1723594450762,"mc":[{"id":"1.231652082","rc":[{"batb":[[0,2.14,33.28],[1,1.74,16.78],[2,1.45,57.32]],"ltp":2.16,"tv":215.66,"id":25651861}]}]}
{"op":"mcm","clk":"11874571020","pt":1723594453033,"mc":[{"id":"1.231652082","rc":[{"batb":[[0,2.16,10],[1,2.14,33.28],[2,1.74,16.78]],"ltp":2.16,"tv":215.66,"id":25651861}]}]}
{"op":"mcm","clk":"11874571253","pt":1723594456436,"mc":[{"id":"1.231652082","rc":[{"batb":[[0,2.14,33.28],[1,1.74,16.78],[2,1.45,57.32]],"ltp":2.16,"tv":215.66,"id":25651861}]}]}
{"op":"mcm","clk":"11874571330","pt":1723594457774,"mc":[{"id":"1.231652082","rc":[{"batb":[[0,1.74,17.32],[1,1.73,51.97],[2,1.45,57.32]],"ltp":1.76,"tv":3090.74,"id":6847357}]}]}
{"op":"mcm","clk":"11874571407","pt":1723594458963,"mc":[{"id":"1.231652082","rc":[{"batb":[[0,2.16,10],[1,2.14,33.28],[2,1.74,16.78]],"ltp":2.16,"tv":215.66,"id":25651861}]}]}
{"op":"mcm","clk":"11874571620","pt":1723594462358,"mc":[{"id":"1.231652082","rc":[{"batb":[[0,2.14,33.28],[1,1.74,16.78],[2,1.45,57.32]],"ltp":2.16,"tv":215.66,"id":25651861}]}]}
{"op":"mcm","clk":"11874571788","pt":1723594464984,"mc":[{"id":"1.231652082","rc":[{"batb":[[0,2.16,10],[1,2.14,33.28],[2,1.74,16.78]],"ltp":2.16,"tv":215.66,"id":25651861}]}]}
{"op":"mcm","clk":"11874571996","pt":1723594468488,"mc":[{"id":"1.231652082","rc":[{"batb":[[0,2.14,33.28],[1,1.74,16.78],[2,1.45,57.32]],"ltp":2.16,"tv":215.66,"id":25651861}]}]}
{"op":"mcm","clk":"11874572163","pt":1723594470860,"mc":[{"id":"1.231652082","rc":[{"batb":[[0,2.16,10],[1,2.14,33.28],[2,1.74,16.78]],"ltp":2.16,"tv":215.66,"id":25651861}]}]}
{"op":"mcm","clk":"11874572390","pt":1723594474573,"mc":[{"id":"1.231652082","rc":[{"batb":[[0,2.14,33.28],[1,1.74,16.78],[2,1.45,57.32]],"ltp":2.16,"tv":215.66,"id":25651861}]}]}
{"op":"mcm","clk":"11874572527","pt":1723594476880,"mc":[{"id":"1.231652082","rc":[{"batb":[[0,2.16,10],[1,2.14,33.28],[2,1.74,16.78]],"ltp":2.16,"tv":215.66,"id":25651861}]}]}
{"op":"mcm","clk":"11874572736","pt":1723594480384,"mc":[{"id":"1.231652082","rc":[{"batb":[[0,2.14,33.28],[1,1.74,16.78],[2,1.45,57.32]],"ltp":2.16,"tv":215.66,"id":25651861}]}]}
{"op":"mcm","clk":"11874572903","pt":1723594482964,"mc":[{"id":"1.231652082","rc":[{"batb":[[0,2.16,10],[1,2.14,33.28],[2,1.74,16.78]],"ltp":2.16,"tv":215.66,"id":25651861}]}]}
{"op":"mcm","clk":"11874573170","pt":1723594486574,"mc":[{"id":"1.231652082","rc":[{"batb":[[0,2.14,33.28],[1,1.74,16.78],[2,1.45,57.32]],"ltp":2.16,"tv":215.66,"id":25651861}]}]}
{"op":"mcm","clk":"11874573358","pt":1723594489701,"mc":[{"id":"1.231652082","rc":[{"batb":[[0,2.16,10],[1,2.14,33.28],[2,1.74,16.78]],"ltp":2.16,"tv":215.66,"id":25651861}]}]}
{"op":"mcm","clk":"11874573876","pt":1723594497381,"mc":[{"id":"1.231652082","rc":[{"batb":[[0,2.14,33.28],[1,1.74,16.78],[2,1.45,57.32]],"ltp":2.16,"tv":215.66,"id":25651861}]}]}
{"op":"mcm","clk":"11874574231","pt":1723594502500,"mc":[{"id":"1.231652082","rc":[{"batb":[[0,2.16,10],[1,2.14,33.28],[2,1.74,16.78]],"ltp":2.16,"tv":215.66,"id":25651861}]}]}
{"op":"mcm","clk":"11874574462","pt":1723594506008,"mc":[{"id":"1.231652082","rc":[{"batb":[[0,1.74,166.54]],"ltp":1.76,"tv":3090.74,"id":6847357}]}]}
{"op":"mcm","clk":"11874574553","pt":1723594507402,"mc":[{"id":"1.231652082","rc":[{"batb":[[0,2.14,33.28],[1,1.74,16.78],[2,1.45,57.32]],"ltp":2.16,"tv":215.66,"id":25651861}]}]}
{"op":"mcm","clk":"11874574687","pt":1723594509713,"mc":[{"id":"1.231652082","rc":[{"batb":[[0,2.16,10],[1,2.14,33.28],[2,1.74,16.78]],"ltp":2.16,"tv":215.66,"id":25651861}]}]}
{"op":"mcm","clk":"11874574901","pt":1723594513027,"mc":[{"id":"1.231652082","rc":[{"batb":[[0,2.14,33.28],[1,1.74,16.78],[2,1.45,57.32]],"ltp":2.16,"tv":215.66,"id":25651861}]}]}
{"op":"mcm","clk":"11874575122","pt":1723594515921,"mc":[{"id":"1.231652082","rc":[{"batb":[[0,2.16,10],[1,2.14,33.28],[2,1.74,16.78]],"ltp":2.16,"tv":215.66,"id":25651861}]}]}
{"op":"mcm","clk":"11874575338","pt":1723594519420,"mc":[{"id":"1.231652082","rc":[{"batb":[[0,2.14,33.28],[1,1.74,16.78],[2,1.45,57.32]],"ltp":2.16,"tv":215.66,"id":25651861}]}]}
{"op":"mcm","clk":"11874575483","pt":1723594521847,"mc":[{"id":"1.231652082","rc":[{"batb":[[0,2.16,10],[1,2.14,33.28],[2,1.74,16.78]],"ltp":2.16,"tv":215.66,"id":25651861}]}]}
{"op":"mcm","clk":"11874575741","pt":1723594525319,"mc":[{"id":"1.231652082","rc":[{"batb":[[0,2.14,33.28],[1,1.74,16.78],[2,1.45,57.32]],"ltp":2.16,"tv":215.66,"id":25651861}]}]}
{"op":"mcm","clk":"11874575911","pt":1723594527945,"mc":[{"id":"1.231652082","rc":[{"batb":[[0,2.16,10],[1,2.14,33.28],[2,1.74,16.78]],"ltp":2.16,"tv":215.66,"id":25651861}]}]}
{"op":"mcm","clk":"11874576142","pt":1723594531550,"mc":[{"id":"1.231652082","rc":[{"batb":[[0,2.14,33.28],[1,1.74,16.78],[2,1.45,57.32]],"ltp":2.16,"tv":215.66,"id":25651861}]}]}
{"op":"mcm","clk":"11874576307","pt":1723594533965,"mc":[{"id":"1.231652082","rc":[{"batb":[[0,2.16,10],[1,2.14,33.28],[2,1.74,16.78]],"ltp":2.16,"tv":215.66,"id":25651861}]}]}
{"op":"mcm","clk":"11874576524","pt":1723594537060,"mc":[{"id":"1.231652082","rc":[{"batb":[[0,1.75,12.5],[1,1.74,166.54],[2,1.73,51.97]],"ltp":1.76,"tv":3090.74,"id":6847357}]}]}
{"op":"mcm","clk":"11874576561","pt":1723594537627,"mc":[{"id":"1.231652082","rc":[{"batb":[[0,2.14,33.28],[1,1.74,16.78],[2,1.45,57.32]],"ltp":2.16,"tv":215.66,"id":25651861}]}]}
{"op":"mcm","clk":"11874576721","pt":1723594539944,"mc":[{"id":"1.231652082","rc":[{"batb":[[0,2.16,10],[1,2.14,33.28],[2,1.74,16.78]],"ltp":2.16,"tv":215.66,"id":25651861}]}]}
{"op":"mcm","clk":"11874576919","pt":1723594543540,"mc":[{"id":"1.231652082","rc":[{"batb":[[0,2.14,33.28],[1,1.74,16.78],[2,1.45,57.32]],"ltp":2.16,"tv":215.66,"id":25651861}]}]}
{"op":"mcm","clk":"11874577108","pt":1723594546475,"mc":[{"id":"1.231652082","rc":[{"batb":[[0,2.16,10],[1,2.14,33.28],[2,1.74,16.78]],"ltp":2.16,"tv":215.66,"id":25651861}]}]}
{"op":"mcm","clk":"11874577309","pt":1723594550071,"mc":[{"id":"1.231652082","rc":[{"batb":[[0,2.14,33.28],[1,1.74,16.78],[2,1.45,57.32]],"ltp":2.16,"tv":215.66,"id":25651861}]}]}
{"op":"mcm","clk":"11874577465","pt":1723594552846,"mc":[{"id":"1.231652082","rc":[{"batb":[[0,2.16,10],[1,2.14,33.28],[2,1.74,16.78]],"ltp":2.16,"tv":215.66,"id":25651861}]}]}
{"op":"mcm","clk":"11874577696","pt":1723594556549,"mc":[{"id":"1.231652082","rc":[{"batb":[[0,2.14,33.28],[1,1.74,16.78],[2,1.45,57.32]],"ltp":2.16,"tv":215.66,"id":25651861}]}]}
{"op":"mcm","clk":"11874577935","pt":1723594560106,"mc":[{"id":"1.231652082","rc":[{"batb":[[0,2.16,10],[1,2.14,33.28],[2,1.74,16.78]],"ltp":2.16,"tv":215.66,"id":25651861}]}]}
{"op":"mcm","clk":"11874578184","pt":1723594563468,"mc":[{"id":"1.231652082","rc":[{"batb":[[0,2.14,33.28],[1,1.74,16.78],[2,1.45,57.32]],"ltp":2.16,"tv":215.66,"id":25651861}]}]}
{"op":"mcm","clk":"11874578329","pt":1723594565997,"mc":[{"id":"1.231652082","rc":[{"batb":[[0,2.16,10],[1,2.14,33.28],[2,1.74,16.78]],"ltp":2.16,"tv":215.66,"id":25651861}]}]}
{"op":"mcm","clk":"11874578523","pt":1723594569288,"mc":[{"id":"1.231652082","rc":[{"batb":[[0,2.14,33.28],[1,1.74,16.78],[2,1.45,57.32]],"ltp":2.16,"tv":215.66,"id":25651861}]}]}
{"op":"mcm","clk":"11874578684","pt":1723594571660,"mc":[{"id":"1.231652082","rc":[{"batb":[[0,2.16,10],[1,2.14,33.28],[2,1.74,16.78]],"ltp":2.16,"tv":215.66,"id":25651861}]}]}
{"op":"mcm","clk":"11874578897","pt":1723594575167,"mc":[{"id":"1.231652082","rc":[{"batb":[[0,2.14,33.28],[1,1.74,16.78],[2,1.45,57.32]],"ltp":2.16,"tv":215.66,"id":25651861}]}]}
{"op":"mcm","clk":"11874579050","pt":1723594577479,"mc":[{"id":"1.231652082","rc":[{"batb":[[0,2.16,10],[1,2.14,33.28],[2,1.74,16.78]],"ltp":2.16,"tv":215.66,"id":25651861}]}]}
{"op":"mcm","clk":"11874579231","pt":1723594580981,"mc":[{"id":"1.231652082","rc":[{"batb":[[0,2.14,33.28],[1,1.74,16.78],[2,1.45,57.32]],"ltp":2.16,"tv":215.66,"id":25651861}]}]}
{"op":"mcm","clk":"11874579365","pt":1723594583296,"mc":[{"id":"1.231652082","rc":[{"batb":[[0,2.16,10],[1,2.14,33.28],[2,1.74,16.78]],"ltp":2.16,"tv":215.66,"id":25651861}]}]}
{"op":"mcm","clk":"11874579572","pt":1723594586689,"mc":[{"id":"1.231652082","rc":[{"batb":[[0,2.14,33.28],[1,1.74,16.78],[2,1.45,57.32]],"ltp":2.16,"tv":215.66,"id":25651861}]}]}
{"op":"mcm","clk":"11874579759","pt":1723594589623,"mc":[{"id":"1.231652082","rc":[{"batb":[[0,2.16,10],[1,2.14,33.28],[2,1.74,16.78]],"ltp":2.16,"tv":215.66,"id":25651861}]}]}
{"op":"mcm","clk":"11874579901","pt":1723594592191,"mc":[{"id":"1.231652082","rc":[{"trd":[[1.74,34.64],[1.75,31.3]],"batb":[[0,1.74,27.12],[1,1.73,51.97],[2,1.45,57.32]],"ltp":1.74,"tv":3150.38,"id":6847357}],"tv":3366.05}]}
{"op":"mcm","clk":"11874579996","pt":1723594594093,"mc":[{"id":"1.231652082","rc":[{"batl":[[0,1.87,12.46]],"ltp":1.74,"tv":3150.38,"id":6847357},{"batb":[[0,2.14,33.28],[1,1.74,16.78],[2,1.45,57.32]],"ltp":2.16,"tv":215.66,"id":25651861}]}]}
{"op":"mcm","clk":"11874580175","pt":1723594597035,"mc":[{"id":"1.231652082","rc":[{"batb":[[0,2.16,10],[1,2.14,33.28],[2,1.74,16.78]],"ltp":2.16,"tv":215.66,"id":25651861}]}]}
{"op":"mcm","clk":"11874580402","pt":1723594600230,"mc":[{"id":"1.231652082","rc":[{"batb":[[0,2.14,33.28],[1,1.74,16.78],[2,1.45,57.32]],"ltp":2.16,"tv":215.66,"id":25651861}]}]}
{"op":"mcm","clk":"11874580578","pt":1723594602908,"mc":[{"id":"1.231652082","rc":[{"batb":[[0,2.16,10],[1,2.14,33.28],[2,1.74,16.78]],"ltp":2.16,"tv":215.66,"id":25651861}]}]}
{"op":"mcm","clk":"11874580782","pt":1723594606616,"mc":[{"id":"1.231652082","rc":[{"batb":[[0,2.14,33.28],[1,1.74,16.78],[2,1.45,57.32]],"ltp":2.16,"tv":215.66,"id":25651861}]}]}
{"op":"mcm","clk":"11874580946","pt":1723594609355,"mc":[{"id":"1.231652082","rc":[{"batb":[[0,2.16,10],[1,2.14,33.28],[2,1.74,16.78]],"ltp":2.16,"tv":215.66,"id":25651861}]}]}
{"op":"mcm","clk":"11874581166","pt":1723594612816,"mc":[{"id":"1.231652082","rc":[{"batb":[[0,2.14,33.28],[1,1.74,16.78],[2,1.45,57.32]],"ltp":2.16,"tv":215.66,"id":25651861}]}]}
{"op":"mcm","clk":"11874581344","pt":1723594615143,"mc":[{"id":"1.231652082","rc":[{"batb":[[0,2.16,10],[1,2.14,33.28],[2,1.74,16.78]],"ltp":2.16,"tv":215.66,"id":25651861}]}]}
{"op":"mcm","clk":"11874581565","pt":1723594618439,"mc":[{"id":"1.231652082","rc":[{"batb":[[0,2.14,33.28],[1,1.74,16.78],[2,1.45,57.32]],"ltp":2.16,"tv":215.66,"id":25651861}]}]}
{"op":"mcm","clk":"11874581740","pt":1723594621221,"mc":[{"id":"1.231652082","rc":[{"batb":[[0,2.16,10],[1,2.14,33.28],[2,1.74,16.78]],"ltp":2.16,"tv":215.66,"id":25651861}]}]}
{"op":"mcm","clk":"11874581985","pt":1723594624735,"mc":[{"id":"1.231652082","rc":[{"batb":[[0,2.14,33.28],[1,1.74,16.78],[2,1.45,57.32]],"ltp":2.16,"tv":215.66,"id":25651861}]}]}
{"op":"mcm","clk":"11874582230","pt":1723594628133,"mc":[{"id":"1.231652082","rc":[{"batb":[[0,2.16,10],[1,2.14,33.28],[2,1.74,16.78]],"ltp":2.16,"tv":215.66,"id":25651861}]}]}
{"op":"mcm","clk":"11874582443","pt":1723594631572,"mc":[{"id":"1.231652082","rc":[{"batb":[[0,2.14,33.28],[1,1.74,16.78],[2,1.45,57.32]],"ltp":2.16,"tv":215.66,"id":25651861}]}]}
{"op":"mcm","clk":"11874582634","pt":1723594634562,"mc":[{"id":"1.231652082","rc":[{"batb":[[0,2.16,10],[1,2.14,33.28],[2,1.74,16.78]],"ltp":2.16,"tv":215.66,"id":25651861}]}]}
{"op":"mcm","clk":"11874582857","pt":1723594637960,"mc":[{"id":"1.231652082","rc":[{"batb":[[0,2.14,33.28],[1,1.74,16.78],[2,1.45,57.32]],"ltp":2.16,"tv":215.66,"id":25651861}]}]}
{"op":"mcm","clk":"11874583022","pt":1723594640588,"mc":[{"id":"1.231652082","rc":[{"batb":[[0,2.16,10],[1,2.14,33.28],[2,1.74,16.78]],"ltp":2.16,"tv":215.66,"id":25651861}]}]}
{"op":"mcm","clk":"11874583236","pt":1723594644182,"mc":[{"id":"1.231652082","rc":[{"batb":[[0,2.14,33.28],[1,1.74,16.78],[2,1.45,57.32]],"ltp":2.16,"tv":215.66,"id":25651861}]}]}
{"op":"mcm","clk":"11874583404","pt":1723594646864,"mc":[{"id":"1.231652082","rc":[{"batb":[[0,2.16,10],[1,2.14,33.28],[2,1.74,16.78]],"ltp":2.16,"tv":215.66,"id":25651861}]}]}
{"op":"mcm","clk":"11874583619","pt":1723594650366,"mc":[{"id":"1.231652082","rc":[{"batb":[[0,2.14,33.28],[1,1.74,16.78],[2,1.45,57.32]],"ltp":2.16,"tv":215.66,"id":25651861}]}]}
{"op":"mcm","clk":"11874583873","pt":1723594653767,"mc":[{"id":"1.231652082","rc":[{"batb":[[0,2.16,10],[1,2.14,33.28],[2,1.74,16.78]],"ltp":2.16,"tv":215.66,"id":25651861}]}]}
{"op":"mcm","clk":"11874584114","pt":1723594657280,"mc":[{"id":"1.231652082","rc":[{"batb":[[0,2.14,33.28],[1,1.74,16.78],[2,1.45,57.32]],"ltp":2.16,"tv":215.66,"id":25651861}]}]}
{"op":"mcm","clk":"11874584269","pt":1723594660105,"mc":[{"id":"1.231652082","rc":[{"batb":[[0,2.16,10],[1,2.14,33.28],[2,1.74,16.78]],"ltp":2.16,"tv":215.66,"id":25651861}]}]}
{"op":"mcm","clk":"11874584480","pt":1723594663703,"mc":[{"id":"1.231652082","rc":[{"batb":[[0,2.14,33.28],[1,1.74,16.78],[2,1.45,57.32]],"ltp":2.16,"tv":215.66,"id":25651861}]}]}
{"op":"mcm","clk":"11874584641","pt":1723594666604,"mc":[{"id":"1.231652082","rc":[{"batb":[[0,2.16,10],[1,2.14,33.28],[2,1.74,16.78]],"ltp":2.16,"tv":215.66,"id":25651861}]}]}
{"op":"mcm","clk":"11874584859","pt":1723594670113,"mc":[{"id":"1.231652082","rc":[{"batb":[[0,2.14,33.28],[1,1.74,16.78],[2,1.45,57.32]],"ltp":2.16,"tv":215.66,"id":25651861}]}]}
{"op":"mcm","clk":"11874585007","pt":1723594672480,"mc":[{"id":"1.231652082","rc":[{"batb":[[0,2.16,10],[1,2.14,33.28],[2,1.74,16.78]],"ltp":2.16,"tv":215.66,"id":25651861}]}]}
{"op":"mcm","clk":"11874585190","pt":1723594675922,"mc":[{"id":"1.231652082","rc":[{"batb":[[0,2.14,33.28],[1,1.74,16.78],[2,1.45,57.32]],"ltp":2.16,"tv":215.66,"id":25651861}]}]}
{"op":"mcm","clk":"11874585352","pt":1723594678695,"mc":[{"id":"1.231652082","rc":[{"batb":[[0,2.16,10],[1,2.14,33.28],[2,1.74,16.78]],"ltp":2.16,"tv":215.66,"id":25651861}]}]}
{"op":"mcm","clk":"11874585569","pt":1723594682095,"mc":[{"id":"1.231652082","rc":[{"batb":[[0,2.14,33.28],[1,1.74,16.78],[2,1.45,57.32]],"ltp":2.16,"tv":215.66,"id":25651861}]}]}
{"op":"mcm","clk":"11874585727","pt":1723594684513,"mc":[{"id":"1.231652082","rc":[{"batb":[[0,2.16,10],[1,2.14,33.28],[2,1.74,16.78]],"ltp":2.16,"tv":215.66,"id":25651861}]}]}
{"op":"mcm","clk":"11874585943","pt":1723594687806,"mc":[{"id":"1.231652082","rc":[{"batb":[[0,2.14,33.28],[1,1.74,16.78],[2,1.45,57.32]],"ltp":2.16,"tv":215.66,"id":25651861}]}]}
{"op":"mcm","clk":"11874586090","pt":1723594690326,"mc":[{"id":"1.231652082","rc":[{"batb":[[0,2.16,10],[1,2.14,33.28],[2,1.74,16.78]],"ltp":2.16,"tv":215.66,"id":25651861}]}]}
{"op":"mcm","clk":"11874586367","pt":1723594693819,"mc":[{"id":"1.231652082","rc":[{"batb":[[0,2.14,33.28],[1,1.74,16.78],[2,1.45,57.32]],"ltp":2.16,"tv":215.66,"id":25651861}]}]}
{"op":"mcm","clk":"11874586545","pt":1723594696439,"mc":[{"id":"1.231652082","rc":[{"batb":[[0,2.16,10],[1,2.14,33.28],[2,1.74,16.78]],"ltp":2.16,"tv":215.66,"id":25651861}]}]}
{"op":"mcm","clk":"11874586746","pt":1723594699933,"mc":[{"id":"1.231652082","rc":[{"batb":[[0,2.14,33.28],[1,1.74,16.78],[2,1.45,57.32]],"ltp":2.16,"tv":215.66,"id":25651861}]}]}
{"op":"mcm","clk":"11874586901","pt":1723594702455,"mc":[{"id":"1.231652082","rc":[{"batb":[[0,2.16,10],[1,2.14,33.28],[2,1.74,16.78]],"ltp":2.16,"tv":215.66,"id":25651861}]}]}
{"op":"mcm","clk":"11874587169","pt":1723594705950,"mc":[{"id":"1.231652082","rc":[{"batb":[[0,2.14,33.28],[1,1.74,16.78],[2,1.45,57.32]],"ltp":2.16,"tv":215.66,"id":25651861}]}]}
{"op":"mcm","clk":"11874587333","pt":1723594708263,"mc":[{"id":"1.231652082","rc":[{"batb":[[0,2.16,10],[1,2.14,33.28],[2,1.74,16.78]],"ltp":2.16,"tv":215.66,"id":25651861}]}]}
{"op":"mcm","clk":"11874587581","pt":1723594711555,"mc":[{"id":"1.231652082","rc":[{"batb":[[0,2.14,33.28],[1,1.74,16.78],[2,1.45,57.32]],"ltp":2.16,"tv":215.66,"id":25651861}]}]}
{"op":"mcm","clk":"11874587758","pt":1723594714238,"mc":[{"id":"1.231652082","rc":[{"batb":[[0,2.16,10],[1,2.14,33.28],[2,1.74,16.78]],"ltp":2.16,"tv":215.66,"id":25651861}]}]}
{"op":"mcm","clk":"11874587985","pt":1723594717631,"mc":[{"id":"1.231652082","rc":[{"batb":[[0,2.14,33.28],[1,1.74,16.78],[2,1.45,57.32]],"ltp":2.16,"tv":215.66,"id":25651861}]}]}
{"op":"mcm","clk":"11874588191","pt":1723594720868,"mc":[{"id":"1.231652082","rc":[{"batb":[[0,2.16,10],[1,2.14,33.28],[2,1.74,16.78]],"ltp":2.16,"tv":215.66,"id":25651861}]}]}
{"op":"mcm","clk":"11874588412","pt":1723594724469,"mc":[{"id":"1.231652082","rc":[{"batb":[[0,2.14,33.28],[1,1.74,16.78],[2,1.45,57.32]],"ltp":2.16,"tv":215.66,"id":25651861}]}]}
{"op":"mcm","clk":"11874588597","pt":1723594726842,"mc":[{"id":"1.231652082","rc":[{"batb":[[0,2.16,10],[1,2.14,33.28],[2,1.74,16.78]],"ltp":2.16,"tv":215.66,"id":25651861}]}]}
{"op":"mcm","clk":"11874588814","pt":1723594730290,"mc":[{"id":"1.231652082","rc":[{"batb":[[0,2.14,33.28],[1,1.74,16.78],[2,1.45,57.32]],"ltp":2.16,"tv":215.66,"id":25651861}]}]}
{"op":"mcm","clk":"11874588971","pt":1723594732856,"mc":[{"id":"1.231652082","rc":[{"batb":[[0,2.16,10],[1,2.14,33.28],[2,1.74,16.78]],"ltp":2.16,"tv":215.66,"id":25651861}]}]}
{"op":"mcm","clk":"11874589202","pt":1723594736272,"mc":[{"id":"1.231652082","rc":[{"batb":[[0,2.14,33.28],[1,1.74,16.78],[2,1.45,57.32]],"ltp":2.16,"tv":215.66,"id":25651861}]}]}
{"op":"mcm","clk":"11874589353","pt":1723594738687,"mc":[{"id":"1.231652082","rc":[{"batb":[[0,2.16,10],[1,2.14,33.28],[2,1.74,16.78]],"ltp":2.16,"tv":215.66,"id":25651861}]}]}
{"op":"mcm","clk":"11874589512","pt":1723594740895,"mc":[{"id":"1.231652082","rc":[{"batb":[[0,1.73,51.97],[1,1.45,57.32],[2,1.38,131.58]],"ltp":1.74,"tv":3150.38,"id":6847357}]}]}
{"op":"mcm","clk":"11874589570","pt":1723594742078,"mc":[{"id":"1.231652082","rc":[{"batb":[[0,2.14,33.28],[1,1.74,16.78],[2,1.45,57.32]],"ltp":2.16,"tv":215.66,"id":25651861}]}]}
{"op":"mcm","clk":"11874589738","pt":1723594744702,"mc":[{"id":"1.231652082","rc":[{"batb":[[0,2.16,10],[1,2.14,33.28],[2,1.74,16.78]],"ltp":2.16,"tv":215.66,"id":25651861}]}]}
{"op":"mcm","clk":"11874589961","pt":1723594748107,"mc":[{"id":"1.231652082","rc":[{"batb":[[0,2.14,33.28],[1,1.74,16.78],[2,1.45,57.32]],"ltp":2.16,"tv":215.66,"id":25651861}]}]}
{"op":"mcm","clk":"11874590097","pt":1723594750472,"mc":[{"id":"1.231652082","rc":[{"batb":[[0,2.16,10],[1,2.14,33.28],[2,1.74,16.78]],"ltp":2.16,"tv":215.66,"id":25651861}]}]}
{"op":"mcm","clk":"11874590298","pt":1723594753889,"mc":[{"id":"1.231652082","rc":[{"batb":[[0,2.14,33.28],[1,1.74,16.78],[2,1.45,57.32]],"ltp":2.16,"tv":215.66,"id":25651861}]}]}
{"op":"mcm","clk":"11874590640","pt":1723594758783,"mc":[{"id":"1.231652082","rc":[{"batb":[[0,2.16,10],[1,2.14,33.28],[2,1.74,16.78]],"ltp":2.16,"tv":215.66,"id":25651861}]}]}
{"op":"mcm","clk":"11874590853","pt":1723594761919,"mc":[{"id":"1.231652082","rc":[{"batl":[[0,1.87,11.7]],"ltp":1.74,"tv":3150.38,"id":6847357}]}]}
{"op":"mcm","clk":"11874590971","pt":1723594763790,"mc":[{"id":"1.231652082","rc":[{"batb":[[0,1.76,9.14],[1,1.73,51.97],[2,1.45,57.32]],"ltp":1.74,"tv":3150.38,"id":6847357},{"batb":[[0,2.14,33.28],[1,2.02,7.96]],"ltp":2.16,"tv":215.66,"id":25651861}]}]}
{"op":"mcm","clk":"11874591127","pt":1723594766006,"mc":[{"id":"1.231652082","rc":[{"batb":[[0,2.16,10],[1,2.14,33.28],[2,2.02,7.96]],"ltp":2.16,"tv":215.66,"id":25651861}]}]}
{"op":"mcm","clk":"11874591344","pt":1723594769403,"mc":[{"id":"1.231652082","rc":[{"batb":[[0,2.14,33.28],[1,2.02,7.96],[2,1.74,16.78]],"ltp":2.16,"tv":215.66,"id":25651861}]}]}
{"op":"mcm","clk":"11874591509","pt":1723594771621,"mc":[{"id":"1.231652082","rc":[{"batb":[[0,2.16,10],[1,2.14,33.28],[2,2.02,7.96]],"ltp":2.16,"tv":215.66,"id":25651861}]}]}
{"op":"mcm","clk":"11874591732","pt":1723594775030,"mc":[{"id":"1.231652082","rc":[{"batb":[[0,2.14,33.28],[1,2.02,7.96],[2,1.74,16.78]],"ltp":2.16,"tv":215.66,"id":25651861}]}]}
{"op":"mcm","clk":"11874591884","pt":1723594777232,"mc":[{"id":"1.231652082","rc":[{"batb":[[0,2.16,10],[1,2.14,33.28],[2,2.02,7.96]],"ltp":2.16,"tv":215.66,"id":25651861}]}]}
{"op":"mcm","clk":"11874592018","pt":1723594779503,"mc":[{"id":"1.231652082","rc":[{"batb":[[0,1.73,51.97],[1,1.45,57.32],[2,1.38,131.58]],"ltp":1.74,"tv":3150.38,"id":6847357},{"batb":[[2,1.74,16.78]],"ltp":2.16,"tv":215.66,"id":25651861}]}]}
{"op":"mcm","clk":"11874592086","pt":1723594780633,"mc":[{"id":"1.231652082","rc":[{"batb":[[0,2.14,33.28],[1,1.74,16.78],[2,1.45,57.32]],"ltp":2.16,"tv":215.66,"id":25651861}]}]}
{"op":"mcm","clk":"11874592223","pt":1723594782804,"mc":[{"id":"1.231652082","rc":[{"batb":[[0,2.16,10],[1,2.14,33.28],[2,1.74,16.78]],"ltp":2.16,"tv":215.66,"id":25651861}]}]}
{"op":"mcm","clk":"11874592415","pt":1723594786146,"mc":[{"id":"1.231652082","rc":[{"batb":[[0,2.14,33.28],[1,1.74,16.78],[2,1.45,57.32]],"ltp":2.16,"tv":215.66,"id":25651861}]}]}
{"op":"mcm","clk":"11874592592","pt":1723594789045,"mc":[{"id":"1.231652082","rc":[{"batb":[[0,2.16,10],[1,2.14,33.28],[2,1.74,16.78]],"ltp":2.16,"tv":215.66,"id":25651861}]}]}
{"op":"mcm","clk":"11874592801","pt":1723594792604,"mc":[{"id":"1.231652082","rc":[{"batb":[[0,2.14,33.28],[1,1.74,16.78],[2,1.45,57.32]],"ltp":2.16,"tv":215.66,"id":25651861}]}]}
{"op":"mcm","clk":"11874592949","pt":1723594794964,"mc":[{"id":"1.231652082","rc":[{"batb":[[0,2.16,10],[1,2.14,33.28],[2,1.74,16.78]],"ltp":2.16,"tv":215.66,"id":25651861}]}]}
{"op":"mcm","clk":"11874593195","pt":1723594798357,"mc":[{"id":"1.231652082","rc":[{"batb":[[0,2.14,33.28],[1,1.74,16.78],[2,1.45,57.32]],"ltp":2.16,"tv":215.66,"id":25651861}]}]}
{"op":"mcm","clk":"11874593414","pt":1723594801552,"mc":[{"id":"1.231652082","rc":[{"batb":[[0,2.16,10],[1,2.14,33.28],[2,1.74,16.78]],"ltp":2.16,"tv":215.66,"id":25651861}]}]}
{"op":"mcm","clk":"11874593656","pt":1723594804957,"mc":[{"id":"1.231652082","rc":[{"batb":[[0,2.14,33.28],[1,1.74,16.78],[2,1.45,57.32]],"ltp":2.16,"tv":215.66,"id":25651861}]}]}
{"op":"mcm","clk":"11874593885","pt":1723594808657,"mc":[{"id":"1.231652082","rc":[{"batb":[[0,2.16,10],[1,2.14,33.28],[2,1.74,16.78]],"ltp":2.16,"tv":215.66,"id":25651861}]}]}
{"op":"mcm","clk":"11874594130","pt":1723594812052,"mc":[{"id":"1.231652082","rc":[{"batb":[[0,2.14,33.28],[1,1.74,16.78],[2,1.45,57.32]],"ltp":2.16,"tv":215.66,"id":25651861}]}]}
{"op":"mcm","clk":"11874594210","pt":1723594813236,"mc":[{"id":"1.231652082","rc":[{"batb":[[0,1.76,9.14],[1,1.73,51.97],[2,1.45,57.32]],"ltp":1.74,"tv":3150.38,"id":6847357},{"batb":[[1,2.02,7.96],[2,1.74,16.78]],"ltp":2.16,"tv":215.66,"id":25651861}]}]}
{"op":"mcm","clk":"11874594277","pt":1723594814470,"mc":[{"id":"1.231652082","rc":[{"batb":[[0,2.16,10],[1,2.14,33.28],[2,2.02,7.96]],"ltp":2.16,"tv":215.66,"id":25651861}]}]}
{"op":"mcm","clk":"11874594493","pt":1723594817973,"mc":[{"id":"1.231652082","rc":[{"batb":[[0,2.14,33.28],[1,2.02,7.96],[2,1.74,16.78]],"ltp":2.16,"tv":215.66,"id":25651861}]}]}
{"op":"mcm","clk":"11874594706","pt":1723594821480,"mc":[{"id":"1.231652082","rc":[{"batb":[[0,2.16,10],[1,2.14,33.28],[2,2.02,7.96]],"ltp":2.16,"tv":215.66,"id":25651861}]}]}
{"op":"mcm","clk":"11874594927","pt":1723594825103,"mc":[{"id":"1.231652082","rc":[{"batb":[[0,2.14,33.28],[1,2.02,7.96],[2,1.74,16.78]],"ltp":2.16,"tv":215.66,"id":25651861}]}]}
{"op":"mcm","clk":"11874595128","pt":1723594828494,"mc":[{"id":"1.231652082","rc":[{"batb":[[0,2.16,10],[1,2.14,33.28],[2,2.02,7.96]],"ltp":2.16,"tv":215.66,"id":25651861}]}]}
{"op":"mcm","clk":"11874595287","pt":1723594831172,"mc":[{"id":"1.231652082","rc":[{"batl":[[0,1.86,128.03]],"ltp":1.74,"tv":3150.38,"id":6847357}]}]}
{"op":"mcm","clk":"11874595345","pt":1723594832093,"mc":[{"id":"1.231652082","rc":[{"batl":[[0,1.85,11.82],[1,1.86,128.03]],"ltp":1.74,"tv":3150.38,"id":6847357},{"batb":[[0,2.14,33.28],[1,2.02,7.96],[2,1.74,16.78]],"ltp":2.16,"tv":215.66,"id":25651861}]}]}
{"op":"mcm","clk":"11874595511","pt":1723594835180,"mc":[{"id":"1.231652082","rc":[{"batb":[[0,2.16,10],[1,2.14,33.28],[2,2.02,7.96]],"ltp":2.16,"tv":215.66,"id":25651861}]}]}
{"op":"mcm","clk":"11874595699","pt":1723594838575,"mc":[{"id":"1.231652082","rc":[{"batb":[[0,2.14,33.28],[1,2.02,7.96],[2,1.74,16.78]],"ltp":2.16,"tv":215.66,"id":25651861}]}]}
{"op":"mcm","clk":"11874595778","pt":1723594840110,"mc":[{"id":"1.231652082","rc":[{"batb":[[0,1.73,51.97],[1,1.45,57.32],[2,1.38,131.58]],"batl":[[1,1.86,0]],"ltp":1.74,"tv":3150.38,"id":6847357},{"batb":[[1,1.74,16.78],[2,1.45,57.32]],"ltp":2.16,"tv":215.66,"id":25651861}]}]}
{"op":"mcm","clk":"11874595837","pt":1723594841083,"mc":[{"id":"1.231652082","rc":[{"batl":[[0,1.86,11.76],[1,1.87,128.03]],"ltp":1.74,"tv":3150.38,"id":6847357},{"batb":[[0,2.16,10],[1,2.14,33.28],[2,1.74,16.78]],"ltp":2.16,"tv":215.66,"id":25651861}]}]}
{"op":"mcm","clk":"11874596019","pt":1723594844338,"mc":[{"id":"1.231652082","rc":[{"batb":[[0,2.14,33.28],[1,1.74,16.78],[2,1.45,57.32]],"ltp":2.16,"tv":215.66,"id":25651861}]}]}
{"op":"mcm","clk":"11874596201","pt":1723594847211,"mc":[{"id":"1.231652082","rc":[{"batb":[[0,2.16,10],[1,2.14,33.28],[2,1.74,16.78]],"ltp":2.16,"tv":215.66,"id":25651861}]}]}
{"op":"mcm","clk":"11874596409","pt":1723594850705,"mc":[{"id":"1.231652082","rc":[{"batb":[[0,2.18,30.95]],"ltp":2.16,"tv":215.66,"id":25651861}]}]}
{"op":"mcm","clk":"11874596496","pt":1723594851990,"mc":[{"id":"1.231652082","rc":[{"batl":[[0,1.87,128.03],[1,1.87,0]],"ltp":1.74,"tv":3150.38,"id":6847357}]}]}
{"op":"mcm","clk":"11874596506","pt":1723594852192,"mc":[{"id":"1.231652082","rc":[{"batl":[[0,1.84,11.89],[1,1.87,128.03]],"ltp":1.74,"tv":3150.38,"id":6847357}]}]}
{"op":"mcm","clk":"11874596579","pt":1723594853426,"mc":[{"id":"1.231652082","rc":[{"batb":[[0,2.2,10],[1,2.18,30.95],[2,2.14,33.28]],"ltp":2.16,"tv":215.66,"id":25651861}]}]}
{"op":"mcm","clk":"11874596767","pt":1723594856718,"mc":[{"id":"1.231652082","rc":[{"batb":[[0,2.18,30.95],[1,2.14,33.28],[2,1.74,16.78]],"ltp":2.16,"tv":215.66,"id":25651861}]}]}
{"op":"mcm","clk":"11874596939","pt":1723594859397,"mc":[{"id":"1.231652082","rc":[{"batb":[[0,2.2,10],[1,2.18,30.95],[2,2.14,33.28]],"ltp":2.16,"tv":215.66,"id":25651861}]}]}
{"op":"mcm","clk":"11874597139","pt":1723594862842,"mc":[{"id":"1.231652082","rc":[{"batb":[[0,2.18,30.95],[1,2.14,33.28],[2,1.74,16.78]],"ltp":2.16,"tv":215.66,"id":25651861}]}]}
{"op":"mcm","clk":"11874597287","pt":1723594865113,"mc":[{"id":"1.231652082","rc":[{"batb":[[0,2.2,10],[1,2.18,30.95],[2,2.14,33.28]],"ltp":2.16,"tv":215.66,"id":25651861}]}]}
{"op":"mcm","clk":"11874597549","pt":1723594868616,"mc":[{"id":"1.231652082","rc":[{"batl":[[1,1.87,0]],"ltp":1.74,"tv":3150.38,"id":6847357},{"batb":[[0,2.18,30.95],[1,2.14,33.28],[2,1.74,16.78]],"ltp":2.16,"tv":215.66,"id":25651861}]}]}
{"op":"mcm","clk":"11874597748","pt":1723594871408,"mc":[{"id":"1.231652082","rc":[{"batb":[[0,2.2,10],[1,2.18,30.95],[2,2.14,33.28]],"ltp":2.16,"tv":215.66,"id":25651861}]}]}
{"op":"mcm","clk":"11874597960","pt":1723594874862,"mc":[{"id":"1.231652082","rc":[{"batb":[[0,2.18,30.95],[1,2.14,33.28],[2,1.74,16.78]],"ltp":2.16,"tv":215.66,"id":25651861}]}]}
{"op":"mcm","clk":"11874598080","pt":1723594877218,"mc":[{"id":"1.231652082","rc":[{"batb":[[0,2.2,10],[1,2.18,30.95],[2,2.14,33.28]],"ltp":2.16,"tv":215.66,"id":25651861}]}]}
{"op":"mcm","clk":"11874598280","pt":1723594880526,"mc":[{"id":"1.231652082","rc":[{"batb":[[0,2.18,30.95],[1,2.14,33.28],[2,1.74,16.78]],"ltp":2.16,"tv":215.66,"id":25651861}]}]}
{"op":"mcm","clk":"11874598471","pt":1723594883020,"mc":[{"id":"1.231652082","rc":[{"batb":[[0,2.2,10],[1,2.18,30.95],[2,2.14,33.28]],"ltp":2.16,"tv":215.66,"id":25651861}]}]}
{"op":"mcm","clk":"11874598710","pt":1723594886426,"mc":[{"id":"1.231652082","rc":[{"batb":[[0,2.18,30.95],[1,2.14,33.28],[2,1.74,16.78]],"ltp":2.16,"tv":215.66,"id":25651861}]}]}
{"op":"mcm","clk":"11874598928","pt":1723594889565,"mc":[{"id":"1.231652082","rc":[{"batb":[[0,2.2,10],[1,2.18,30.95],[2,2.14,33.28]],"ltp":2.16,"tv":215.66,"id":25651861}]}]}
{"op":"mcm","clk":"11874599155","pt":1723594892859,"mc":[{"id":"1.231652082","rc":[{"batb":[[0,2.18,30.95],[1,2.14,33.28],[2,1.74,16.78]],"ltp":2.16,"tv":215.66,"id":25651861}]}]}
{"op":"mcm","clk":"11874599233","pt":1723594894053,"mc":[{"id":"1.231652082","rc":[{"batb":[[0,2.14,33.28],[1,1.74,16.78],[2,1.45,57.32]],"ltp":2.16,"tv":215.66,"id":25651861}]}]}
{"op":"mcm","clk":"11874599380","pt":1723594896472,"mc":[{"id":"1.231652082","rc":[{"batl":[[0,1.87,11.7]],"ltp":1.74,"tv":3150.38,"id":6847357},{"batb":[[0,2.16,10],[1,2.14,33.28],[2,1.74,16.78]],"ltp":2.16,"tv":215.66,"id":25651861}]}]}
{"op":"mcm","clk":"11874599590","pt":1723594899970,"mc":[{"id":"1.231652082","rc":[{"batb":[[0,2.14,33.28],[1,1.74,16.78],[2,1.45,57.32]],"ltp":2.16,"tv":215.66,"id":25651861}]}]}
{"op":"mcm","clk":"11874599740","pt":1723594902552,"mc":[{"id":"1.231652082","rc":[{"batb":[[0,2.16,10],[1,2.14,33.28],[2,1.74,16.78]],"ltp":2.16,"tv":215.66,"id":25651861}]}]}
{"op":"mcm","clk":"11874599926","pt":1723594905802,"mc":[{"id":"1.231652082","rc":[{"batb":[[0,2.14,33.28],[1,1.74,16.78],[2,1.45,57.32]],"ltp":2.16,"tv":215.66,"id":25651861}]}]}
{"op":"mcm","clk":"11874600113","pt":1723594908486,"mc":[{"id":"1.231652082","rc":[{"batb":[[0,2.16,10],[1,2.14,33.28],[2,1.74,16.78]],"ltp":2.16,"tv":215.66,"id":25651861}]}]}
{"op":"mcm","clk":"11874600353","pt":1723594911783,"mc":[{"id":"1.231652082","rc":[{"batb":[[0,2.14,33.28],[1,1.74,16.78],[2,1.45,57.32]],"ltp":2.16,"tv":215.66,"id":25651861}]}]}
{"op":"mcm","clk":"11874600534","pt":1723594914368,"mc":[{"id":"1.231652082","rc":[{"batb":[[0,2.16,10],[1,2.14,33.28],[2,1.74,16.78]],"ltp":2.16,"tv":215.66,"id":25651861}]}]}
{"op":"mcm","clk":"11874600742","pt":1723594917779,"mc":[{"id":"1.231652082","rc":[{"batb":[[0,2.14,33.28],[1,1.74,16.78],[2,1.45,57.32]],"ltp":2.16,"tv":215.66,"id":25651861}]}]}
{"op":"mcm","clk":"11874600869","pt":1723594919983,"mc":[{"id":"1.231652082","rc":[{"batb":[[0,2.16,10],[1,2.14,33.28],[2,1.74,16.78]],"ltp":2.16,"tv":215.66,"id":25651861}]}]}
{"op":"mcm","clk":"11874601084","pt":1723594923302,"mc":[{"id":"1.231652082","rc":[{"batb":[[0,2.14,33.28],[1,1.74,16.78],[2,1.45,57.32]],"ltp":2.16,"tv":215.66,"id":25651861}]}]}
{"op":"mcm","clk":"11874601348","pt":1723594927278,"mc":[{"id":"1.231652082","rc":[{"batb":[[0,2.16,10],[1,2.14,33.28],[2,1.74,16.78]],"ltp":2.16,"tv":215.66,"id":25651861}]}]}
{"op":"mcm","clk":"11874601571","pt":1723594930822,"mc":[{"id":"1.231652082","rc":[{"batb":[[0,2.14,33.28],[1,1.74,16.78],[2,1.45,57.32]],"ltp":2.16,"tv":215.66,"id":25651861}]}]}
{"op":"mcm","clk":"11874601712","pt":1723594933304,"mc":[{"id":"1.231652082","rc":[{"batb":[[0,2.16,10],[1,2.14,33.28],[2,1.74,16.78]],"ltp":2.16,"tv":215.66,"id":25651861}]}]}
{"op":"mcm","clk":"11874601872","pt":1723594936598,"mc":[{"id":"1.231652082","rc":[{"batb":[[0,2.14,33.28],[1,1.74,16.78],[2,1.45,57.32]],"ltp":2.16,"tv":215.66,"id":25651861}]}]}
{"op":"mcm","clk":"11874602047","pt":1723594939521,"mc":[{"id":"1.231652082","rc":[{"batb":[[0,2.16,10],[1,2.14,33.28],[2,1.74,16.78]],"ltp":2.16,"tv":215.66,"id":25651861}]}]}
{"op":"mcm","clk":"11874602249","pt":1723594943123,"mc":[{"id":"1.231652082","rc":[{"batb":[[0,2.14,33.28],[1,1.74,16.78],[2,1.45,57.32]],"ltp":2.16,"tv":215.66,"id":25651861}]}]}
{"op":"mcm","clk":"11874602381","pt":1723594945592,"mc":[{"id":"1.231652082","rc":[{"batb":[[0,2.16,10],[1,2.14,33.28],[2,1.74,16.78]],"ltp":2.16,"tv":215.66,"id":25651861}]}]}
{"op":"mcm","clk":"11874602555","pt":1723594949094,"mc":[{"id":"1.231652082","rc":[{"batb":[[0,2.14,33.28],[1,1.74,16.78],[2,1.45,57.32]],"ltp":2.16,"tv":215.66,"id":25651861}]}]}
{"op":"mcm","clk":"11874602656","pt":1723594951430,"mc":[{"id":"1.231652082","rc":[{"batb":[[0,2.16,10],[1,2.14,33.28],[2,1.74,16.78]],"ltp":2.16,"tv":215.66,"id":25651861}]}]}
{"op":"mcm","clk":"11874602783","pt":1723594953602,"mc":[{"id":"1.231652082","rc":[{"batb":[[0,1.86,9.02],[1,1.73,51.97],[2,1.45,57.32]],"ltp":1.74,"tv":3150.38,"id":6847357}]}]}
{"op":"mcm","clk":"11874602866","pt":1723594954839,"mc":[{"id":"1.231652082","rc":[{"batb":[[0,2.14,33.28],[1,1.74,16.78],[2,1.45,57.32]],"ltp":2.16,"tv":215.66,"id":25651861}]}]}
{"op":"mcm","clk":"11874603011","pt":1723594957008,"mc":[{"id":"1.231652082","rc":[{"batb":[[0,2.16,10],[1,2.14,33.28],[2,1.74,16.78]],"ltp":2.16,"tv":215.66,"id":25651861}]}]}
{"op":"mcm","clk":"11874603198","pt":1723594960345,"mc":[{"id":"1.231652082","rc":[{"batb":[[0,2.14,33.28],[1,1.74,16.78],[2,1.45,57.32]],"ltp":2.16,"tv":215.66,"id":25651861}]}]}
{"op":"mcm","clk":"11874603350","pt":1723594963019,"mc":[{"id":"1.231652082","rc":[{"batb":[[0,2.16,10],[1,2.14,33.28],[2,1.74,16.78]],"ltp":2.16,"tv":215.66,"id":25651861}]}]}
{"op":"mcm","clk":"11874603507","pt":1723594965960,"mc":[{"id":"1.231652082","rc":[{"batb":[[1,1.45,57.32],[2,1.38,131.58]],"ltp":1.74,"tv":3150.38,"id":6847357},{"batb":[[1,1.74,16.78],[2,1.45,57.32]],"ltp":2.16,"tv":215.66,"id":25651861}]}]}
{"op":"mcm","clk":"11874603575","pt":1723594967026,"mc":[{"id":"1.231652082","rc":[{"batb":[[0,1.74,16.78],[1,1.45,57.32],[2,1.38,131.58]],"ltp":2.16,"tv":215.66,"id":25651861}]}]}
{"op":"mcm","clk":"11874603830","pt":1723594970871,"mc":[{"id":"1.231652082","rc":[{"batb":[[1,1.73,51.97],[2,1.45,57.32]],"ltp":1.74,"tv":3150.38,"id":6847357},{"batb":[[0,2.14,33.28],[1,1.74,16.78],[2,1.45,57.32]],"ltp":2.16,"tv":215.66,"id":25651861}]}]}
{"op":"mcm","clk":"11874603965","pt":1723594972569,"mc":[{"id":"1.231652082","rc":[{"batl":[[0,1.87,11.7]],"ltp":1.74,"tv":3150.38,"id":6847357}]}]}
{"op":"mcm","clk":"11874604582","pt":1723594982659,"mc":[{"id":"1.231652082","rc":[{"batl":[[0,1.87,15.7]],"ltp":1.74,"tv":3150.38,"id":6847357},{"batb":[[0,2.16,4],[1,2.14,37.28],[2,1.74,16.78]],"ltp":2.16,"tv":215.66,"id":25651861}]}]}
{"op":"mcm","clk":"11874604788","pt":1723594985991,"mc":[{"id":"1.231652082","rc":[{"batb":[[1,1.45,57.32],[2,1.38,131.58]],"ltp":1.74,"tv":3150.38,"id":6847357},{"batb":[[1,2.14,4]],"ltp":2.16,"tv":215.66,"id":25651861}]}]}
{"op":"mcm","clk":"11874604821","pt":1723594986460,"mc":[{"id":"1.231652082","rc":[{"batl":[[0,1.87,11.7]],"ltp":1.74,"tv":3150.38,"id":6847357}]}]}
{"op":"mcm","clk":"11874604945","pt":1723594988465,"mc":[{"id":"1.231652082","rc":[{"batb":[[0,1.74,16.78],[1,1.45,57.32],[2,1.38,131.58]],"ltp":2.16,"tv":215.66,"id":25651861}]}]}
{"op":"mcm","clk":"11874605064","pt":1723594990983,"mc":[{"id":"1.231652082","rc":[{"batb":[[1,1.73,51.97],[2,1.45,57.32]],"ltp":1.74,"tv":3150.38,"id":6847357},{"batb":[[0,2.14,33.28],[1,1.74,16.78],[2,1.45,57.32]],"ltp":2.16,"tv":215.66,"id":25651861}]}]}
{"op":"mcm","clk":"11874605441","pt":1723594997792,"mc":[{"id":"1.231652082","rc":[{"batb":[[0,1.86,13.02]],"batl":[[0,1.87,4],[1,1.88,4]],"ltp":1.74,"tv":3150.38,"id":6847357},{"batb":[[0,2.16,4],[1,2.14,37.28],[2,1.74,16.78]],"ltp":2.16,"tv":215.66,"id":25651861}]}]}
{"op":"mcm","clk":"11874605634","pt":1723595001082,"mc":[{"id":"1.231652082","rc":[{"batb":[[1,1.45,57.32],[2,1.38,131.58]],"ltp":1.74,"tv":3150.38,"id":6847357},{"batb":[[1,2.14,4]],"ltp":2.16,"tv":215.66,"id":25651861}]}]}
{"op":"mcm","clk":"11874605658","pt":1723595001494,"mc":[{"id":"1.231652082","rc":[{"batb":[[0,1.74,16.78],[1,1.45,57.32],[2,1.38,131.58]],"ltp":2.16,"tv":215.66,"id":25651861}]}]}
{"op":"mcm","clk":"11874605898","pt":1723595005978,"mc":[{"id":"1.231652082","rc":[{"batb":[[1,1.73,51.97],[2,1.45,57.32]],"ltp":1.74,"tv":3150.38,"id":6847357},{"batb":[[0,2.14,33.28],[1,1.74,16.78],[2,1.45,57.32]],"ltp":2.16,"tv":215.66,"id":25651861}]}]}
{"op":"mcm","clk":"11874606290","pt":1723595013020,"mc":[{"id":"1.231652082","rc":[{"batl":[[0,1.87,11.7],[1,1.88,4]],"ltp":1.74,"tv":3150.38,"id":6847357},{"batb":[[0,2.14,37.28]],"batl":[[0,2.18,4]],"ltp":2.16,"tv":215.66,"id":25651861}]}]}
{"op":"mcm","clk":"11874607030","pt":1723595028012,"mc":[{"id":"1.231652082","rc":[{"batb":[[0,2.16,4],[1,2.14,37.28],[2,1.74,16.78]],"ltp":2.16,"tv":215.66,"id":25651861}]}]}
{"op":"mcm","clk":"11874607243","pt":1723595031708,"mc":[{"id":"1.231652082","rc":[{"batb":[[1,1.45,57.32],[2,1.38,131.58]],"ltp":1.74,"tv":3150.38,"id":6847357},{"batb":[[0,1.75,10],[1,1.74,16.78],[2,1.45,57.32]],"ltp":2.16,"tv":215.66,"id":25651861}]}]}
{"op":"mcm","clk":"11874607385","pt":1723595034123,"mc":[{"id":"1.231652082","rc":[{"batl":[[0,2.34,9.35],[1,1.88,0]],"ltp":1.74,"tv":3150.38,"id":6847357}]}]}
{"op":"mcm","clk":"11874607452","pt":1723595035047,"mc":[{"id":"1.231652082","rc":[{"batb":[[0,1.87,10],[1,1.86,13.02],[2,1.45,57.32]],"ltp":1.74,"tv":3150.38,"id":6847357},{"batb":[[0,1.74,16.78],[1,1.45,57.32],[2,1.38,131.58]],"ltp":2.16,"tv":215.66,"id":25651861}]}]}
{"op":"mcm","clk":"11874607511","pt":1723595036123,"mc":[{"id":"1.231652082","rc":[{"batb":[[2,1.73,51.97]],"ltp":1.74,"tv":3150.38,"id":6847357},{"batb":[[0,2.14,33.28],[1,1.74,16.78],[2,1.45,57.32]],"ltp":2.16,"tv":215.66,"id":25651861}]}]}
{"op":"mcm","clk":"11874607597","pt":1723595037713,"mc":[{"id":"1.231652082","rc":[{"batb":[[0,1.86,13.02],[1,1.8,8.93]],"ltp":1.74,"tv":3150.38,"id":6847357},{"batb":[[1,1.97,8.16],[2,1.74,16.78]],"ltp":2.16,"tv":215.66,"id":25651861}]}]}
{"op":"mcm","clk":"11874607895","pt":1723595043159,"mc":[{"id":"1.231652082","rc":[{"batl":[[0,1.88,4]],"ltp":1.74,"tv":3150.38,"id":6847357},{"batb":[[0,2.14,37.28]],"ltp":2.16,"tv":215.66,"id":25651861}]}]}
{"op":"mcm","clk":"11874608645","pt":1723595054858,"mc":[{"id":"1.231652082","rc":[{"batl":[[0,1.87,11.7],[1,1.88,4]],"ltp":1.74,"tv":3150.38,"id":6847357}]}]}
{"op":"mcm","clk":"11874608723","pt":1723595056041,"mc":[{"id":"1.231652082","rc":[{"batb":[[1,1.73,51.97],[2,1.45,57.32]],"ltp":1.74,"tv":3150.38,"id":6847357},{"batb":[[1,1.74,16.78],[2,1.45,57.32]],"ltp":2.16,"tv":215.66,"id":25651861}]}]}
{"op":"mcm","clk":"11874608904","pt":1723595058250,"mc":[{"id":"1.231652082","rc":[{"batb":[[0,2.16,4],[1,2.14,37.28],[2,1.74,16.78]],"ltp":2.16,"tv":215.66,"id":25651861}]}]}
{"op":"mcm","clk":"11874609137","pt":1723595062054,"mc":[{"id":"1.231652082","rc":[{"batb":[[1,1.45,57.32],[2,1.38,131.58]],"ltp":1.74,"tv":3150.38,"id":6847357},{"batb":[[0,1.75,10],[1,1.74,16.78],[2,1.45,57.32]],"ltp":2.16,"tv":215.66,"id":25651861}]}]}
{"op":"mcm","clk":"11874609350","pt":1723595065565,"mc":[{"id":"1.231652082","rc":[{"batb":[[0,1.74,16.78],[1,1.45,57.32],[2,1.38,131.58]],"ltp":2.16,"tv":215.66,"id":25651861}]}]}
{"op":"mcm","clk":"11874609398","pt":1723595066272,"mc":[{"id":"1.231652082","rc":[{"batb":[[1,1.73,51.97],[2,1.45,57.32]],"ltp":1.74,"tv":3150.38,"id":6847357},{"batb":[[0,2.14,33.28],[1,1.74,16.78],[2,1.45,57.32]],"ltp":2.16,"tv":215.66,"id":25651861}]}]}
{"op":"mcm","clk":"11874609909","pt":1723595073262,"mc":[{"id":"1.231652082","rc":[{"batl":[[0,1.88,4]],"ltp":1.74,"tv":3150.38,"id":6847357},{"batb":[[0,2.14,37.28]],"ltp":2.16,"tv":215.66,"id":25651861}]}]}
{"op":"mcm","clk":"11874610028","pt":1723595075273,"mc":[{"id":"1.231652082","rc":[{"batb":[[0,1.86,66.66]],"ltp":1.74,"tv":3150.38,"id":6847357}]}]}
{"op":"mcm","clk":"11874611418","pt":1723595095783,"mc":[{"id":"1.231652082","rc":[{"batl":[[0,1.87,11.7],[1,1.88,4]],"ltp":1.74,"tv":3150.38,"id":6847357}]}]}
{"op":"mcm","clk":"11874612337","pt":1723595110644,"mc":[{"id":"1.231652082","rc":[{"trd":[[1.86,28.94]],"batb":[[0,1.86,3.99]],"ltp":1.86,"tv":3158.38,"id":6847357}],"tv":3374.05}]}
{"op":"mcm","clk":"11874612777","pt":1723595118615,"mc":[{"id":"1.231652082","rc":[{"batl":[[0,1.87,15.7]],"ltp":1.86,"tv":3158.38,"id":6847357},{"batb":[[0,2.16,4],[1,2.14,37.28],[2,1.74,16.78]],"ltp":2.16,"tv":215.66,"id":25651861}]}]}
{"op":"mcm","clk":"11874629358","pt":1723595398212,"mc":[{"id":"1.231652082","rc":[{"batb":[[0,1.86,71.62]],"ltp":1.86,"tv":3158.38,"id":6847357}]}]}
{"op":"mcm","clk":"11874629635","pt":1723595403047,"mc":[{"id":"1.231652082","rc":[{"batb":[[1,1.45,57.32],[2,1.38,131.58]],"batl":[[0,1.87,11.7],[1,1.88,0]],"ltp":1.86,"tv":3158.38,"id":6847357},{"batb":[[0,1.74,16.78],[1,1.45,57.32],[2,1.38,131.58]],"ltp":2.16,"tv":215.66,"id":25651861}]}]}
{"op":"mcm","clk":"11874629897","pt":1723595407357,"mc":[{"id":"1.231652082","rc":[{"batb":[[1,1.73,51.97],[2,1.45,57.32]],"ltp":1.86,"tv":3158.38,"id":6847357},{"batb":[[0,2.14,33.28],[1,1.74,16.78],[2,1.45,57.32]],"ltp":2.16,"tv":215.66,"id":25651861}]}]}
{"op":"mcm","clk":"11874630023","pt":1723595409539,"mc":[{"id":"1.231652082","rc":[{"batl":[[0,1.87,11.7]],"ltp":1.86,"tv":3158.38,"id":6847357}]}]}
{"op":"mcm","clk":"11874630727","pt":1723595420580,"mc":[{"id":"1.231652082","rc":[{"batb":[[0,1.86,75.62]],"ltp":1.86,"tv":3158.38,"id":6847357},{"batb":[[0,2.14,37.28]],"batl":[[0,2.18,4]],"ltp":2.16,"tv":215.66,"id":25651861}]}]}
{"op":"mcm","clk":"11874633364","pt":1723595463017,"mc":[{"id":"1.231652082","rc":[{"batb":[[0,1.86,4.39]],"ltp":1.86,"tv":3158.38,"id":6847357}]}]}
{"op":"mcm","clk":"11874633395","pt":1723595463634,"mc":[{"id":"1.231652082","rc":[{"batb":[[0,1.73,52.36],[1,1.45,57.32],[2,1.38,131.58]],"ltp":1.86,"tv":3158.38,"id":6847357}]}]}
{"op":"mcm","clk":"11874637005","pt":1723595528570,"mc":[{"id":"1.231652082","rc":[{"batb":[[0,1.73,51.97]],"ltp":1.86,"tv":3158.38,"id":6847357}]}]}
{"op":"mcm","clk":"11874648362","pt":1723595711255,"mc":[{"id":"1.231652082","rc":[{"batb":[[0,1.74,149.94],[1,1.73,51.97],[2,1.45,57.32]],"ltp":1.86,"tv":3158.38,"id":6847357}]}]}
{"op":"mcm","clk":"11874648618","pt":1723595715741,"mc":[{"id":"1.231652082","rc":[{"batb":[[0,1.75,7.36],[1,1.74,149.94],[2,1.73,51.97]],"ltp":1.86,"tv":3158.38,"id":6847357},{"batb":[[0,2.16,10],[1,2.14,37.28],[2,1.74,16.78]],"batl":[[0,2.34,5.43]],"ltp":2.16,"tv":215.66,"id":25651861}]}]}
{"op":"mcm","clk":"11874648819","pt":1723595719143,"mc":[{"id":"1.231652082","rc":[{"batb":[[0,2.14,37.28],[1,1.74,16.78],[2,1.45,57.32]],"ltp":2.16,"tv":215.66,"id":25651861}]}]}
{"op":"mcm","clk":"11874648946","pt":1723595721362,"mc":[{"id":"1.231652082","rc":[{"batb":[[0,2.16,10],[1,2.14,37.28],[2,1.74,16.78]],"ltp":2.16,"tv":215.66,"id":25651861}]}]}
{"op":"mcm","clk":"11874649166","pt":1723595725070,"mc":[{"id":"1.231652082","rc":[{"batb":[[0,2.14,37.28],[1,1.74,16.78],[2,1.45,57.32]],"ltp":2.16,"tv":215.66,"id":25651861}]}]}
{"op":"mcm","clk":"11874649307","pt":1723595727455,"mc":[{"id":"1.231652082","rc":[{"batb":[[0,2.16,10],[1,2.14,37.28],[2,1.74,16.78]],"ltp":2.16,"tv":215.66,"id":25651861}]}]}
{"op":"mcm","clk":"11874649526","pt":1723595730966,"mc":[{"id":"1.231652082","rc":[{"batb":[[0,2.14,37.28],[1,1.74,16.78],[2,1.45,57.32]],"ltp":2.16,"tv":215.66,"id":25651861}]}]}
{"op":"mcm","clk":"11874649667","pt":1723595733073,"mc":[{"id":"1.231652082","rc":[{"batb":[[0,1.75,45.54]],"ltp":1.86,"tv":3158.38,"id":6847357},{"batb":[[0,2.16,10],[1,2.14,37.28],[2,1.74,16.78]],"ltp":2.16,"tv":215.66,"id":25651861}]}]}
{"op":"mcm","clk":"11874649893","pt":1723595736587,"mc":[{"id":"1.231652082","rc":[{"batb":[[0,2.14,37.28],[1,1.74,16.78],[2,1.45,57.32]],"ltp":2.16,"tv":215.66,"id":25651861}]}]}
{"op":"mcm","clk":"11874650063","pt":1723595739172,"mc":[{"id":"1.231652082","rc":[{"batb":[[0,2.16,10],[1,2.14,37.28],[2,1.74,16.78]],"ltp":2.16,"tv":215.66,"id":25651861}]}]}
{"op":"mcm","clk":"11874650254","pt":1723595742471,"mc":[{"id":"1.231652082","rc":[{"batb":[[0,2.14,37.28],[1,1.74,16.78],[2,1.45,57.32]],"ltp":2.16,"tv":215.66,"id":25651861}]}]}
{"op":"mcm","clk":"11874650387","pt":1723595744786,"mc":[{"id":"1.231652082","rc":[{"batb":[[1,1.73,51.97],[2,1.45,57.32]],"ltp":1.86,"tv":3158.38,"id":6847357},{"batb":[[0,2.16,10],[1,2.14,37.28],[2,1.74,16.78]],"ltp":2.16,"tv":215.66,"id":25651861}]}]}
{"op":"mcm","clk":"11874650488","pt":1723595746384,"mc":[{"id":"1.231652082","rc":[{"batb":[[0,1.75,38.18]],"ltp":1.86,"tv":3158.38,"id":6847357}]}]}
{"op":"mcm","clk":"11874650590","pt":1723595747984,"mc":[{"id":"1.231652082","rc":[{"batb":[[0,2.14,37.28],[1,1.74,16.78],[2,1.45,57.32]],"ltp":2.16,"tv":215.66,"id":25651861}]}]}
{"op":"mcm","clk":"11874652466","pt":1723595778812,"mc":[{"id":"1.231652082","rc":[{"batb":[[0,1.73,51.97],[1,1.45,57.32],[2,1.38,131.58]],"ltp":1.86,"tv":3158.38,"id":6847357}]}]}
{"op":"mcm","clk":"11874922634","pt":1723601574799,"mc":[{"id":"1.231652082","rc":[{"trd":[[1.5,192.25],[1.75,31.3],[1.76,16.51],[1.81,107.95],[1.82,15.38],[1.83,1313.85],[1.85,1315.4],[1.86,28.94]],"batb":[[1,1.45,57.33]],"batl":[[0,1.87,11.7]],"ltp":1.86,"tv":3159.06,"id":6847357},{"trd":[[1.5,192.84]],"batb":[[2,1.45,57.33]],"ltp":2.16,"tv":215.73,"id":25651861}],"tv":3374.8}]}
{"op":"mcm","clk":"11875041480","pt":1723604473778,"mc":[{"id":"1.231652082","rc":[{"trd":[[1.5,192.32],[1.75,31.3],[1.76,16.52],[1.81,107.97],[1.82,15.39],[1.83,1314.36],[1.85,1315.91],[1.86,28.94]],"batb":[[0,1.86,44.11],[1,1.45,57.28]],"batl":[[0,1.87,11.7]],"ltp":1.86,"tv":3160.18,"id":6847357},{"trd":[[1.48,5.51],[1.5,192.91]],"batb":[[0,2.14,4],[1,2.06,35.79],[2,1.74,16.78]],"ltp":2.16,"tv":215.81,"id":25651861}],"tv":3376.0}]}
{"op":"mcm","clk":"11875041524","pt":1723604475109,"mc":[{"id":"1.231652082","rc":[{"batl":[[0,1.94,11.28]],"ltp":1.86,"tv":3160.18,"id":6847357},{"batb":[[0,2.06,35.79],[1,1.74,16.78],[2,1.45,57.28]],"ltp":2.16,"tv":215.81,"id":25651861}]}]}
{"op":"mcm","clk":"11875041901","pt":1723604485096,"mc":[{"id":"1.231652082","rc":[{"batb":[[0,2.1,10],[1,2.08,4],[2,2.06,39.79]],"batl":[[0,2.18,4]],"ltp":2.16,"tv":215.81,"id":25651861}]}]}
{"op":"mcm","clk":"11875042032","pt":1723604488631,"mc":[{"id":"1.231652082","rc":[{"batb":[[0,2.08,4],[1,2.06,39.79],[2,1.74,16.78]],"ltp":2.16,"tv":215.81,"id":25651861}]}]}
{"op":"mcm","clk":"11875042182","pt":1723604492935,"mc":[{"id":"1.231652082","rc":[{"batb":[[0,2.1,10],[1,2.08,4],[2,2.06,39.79]],"ltp":2.16,"tv":215.81,"id":25651861}]}]}
{"op":"mcm","clk":"11875042285","pt":1723604496210,"mc":[{"id":"1.231652082","rc":[{"batb":[[0,2.08,4],[1,2.06,39.79],[2,1.74,16.78]],"ltp":2.16,"tv":215.81,"id":25651861}]}]}
{"op":"mcm","clk":"11875042383","pt":1723604499944,"mc":[{"id":"1.231652082","rc":[{"batb":[[0,2.1,10],[1,2.08,4],[2,2.06,39.79]],"ltp":2.16,"tv":215.81,"id":25651861}]}]}
{"op":"mcm","clk":"11875042506","pt":1723604503228,"mc":[{"id":"1.231652082","rc":[{"batb":[[0,2.08,4],[1,2.06,39.79],[2,1.74,16.78]],"ltp":2.16,"tv":215.81,"id":25651861}]}]}
{"op":"mcm","clk":"11875042618","pt":1723604506451,"mc":[{"id":"1.231652082","rc":[{"batb":[[0,2.1,10],[1,2.08,4],[2,2.06,39.79]],"ltp":2.16,"tv":215.81,"id":25651861}]}]}
{"op":"mcm","clk":"11875042736","pt":1723604509829,"mc":[{"id":"1.231652082","rc":[{"batb":[[0,2.08,4],[1,2.06,39.79],[2,1.74,16.78]],"ltp":2.16,"tv":215.81,"id":25651861}]}]}
{"op":"mcm","clk":"11875042846","pt":1723604512541,"mc":[{"id":"1.231652082","rc":[{"batb":[[0,2.1,10],[1,2.08,4],[2,2.06,39.79]],"ltp":2.16,"tv":215.81,"id":25651861}]}]}
{"op":"mcm","clk":"11875042937","pt":1723604515151,"mc":[{"id":"1.231652082","rc":[{"batb":[[0,1.86,48.11]],"batl":[[0,1.91,4],[1,1.94,11.28]],"ltp":1.86,"tv":3160.18,"id":6847357},{"batb":[[0,2.1,14]],"ltp":2.16,"tv":215.81,"id":25651861}]}]}
{"op":"mcm","clk":"11875042958","pt":1723604516022,"mc":[{"id":"1.231652082","rc":[{"batb":[[0,2.1,4]],"ltp":2.16,"tv":215.81,"id":25651861}]}]}
{"op":"mcm","clk":"11875042966","pt":1723604516328,"mc":[{"id":"1.231652082","rc":[{"batl":[[0,1.94,11.28],[1,1.94,0]],"ltp":1.86,"tv":3160.18,"id":6847357},{"batb":[[0,2.08,4],[1,2.06,39.79],[2,1.74,16.78]],"ltp":2.16,"tv":215.81,"id":25651861}]}]}
{"op":"mcm","clk":"11875043047","pt":1723604518629,"mc":[{"id":"1.231652082","rc":[{"batb":[[0,1.87,36.08],[1,1.86,48.11],[2,1.45,57.28]],"ltp":1.86,"tv":3160.18,"id":6847357},{"batb":[[0,2.1,10],[1,2.08,4],[2,2.06,39.79]],"ltp":2.16,"tv":215.81,"id":25651861}]}]}
{"op":"mcm","clk":"11875043175","pt":1723604521674,"mc":[{"id":"1.231652082","rc":[{"batb":[[0,2.08,4],[1,2.06,39.79],[2,1.74,16.78]],"ltp":2.16,"tv":215.81,"id":25651861}]}]}
{"op":"mcm","clk":"11875043254","pt":1723604523877,"mc":[{"id":"1.231652082","rc":[{"batb":[[0,2.1,10],[1,2.08,4],[2,2.06,39.79]],"ltp":2.16,"tv":215.81,"id":25651861}]}]}
{"op":"mcm","clk":"11875043493","pt":1723604529170,"mc":[{"id":"1.231652082","rc":[{"batb":[[0,2.08,4],[1,2.06,39.79],[2,1.74,16.78]],"ltp":2.16,"tv":215.81,"id":25651861}]}]}
{"op":"mcm","clk":"11875043530","pt":1723604530245,"mc":[{"id":"1.231652082","rc":[{"batb":[[0,1.87,40.08]],"batl":[[0,1.93,4],[1,1.94,11.28]],"ltp":1.86,"tv":3160.18,"id":6847357},{"batl":[[0,2.16,4],[1,2.18,4]],"ltp":2.16,"tv":215.81,"id":25651861}]}]}
{"op":"mcm","clk":"11875043566","pt":1723604531472,"mc":[{"id":"1.231652082","rc":[{"batb":[[0,2.1,10],[1,2.08,4],[2,2.06,39.79]],"ltp":2.16,"tv":215.81,"id":25651861}]}]}
{"op":"mcm","clk":"11875043688","pt":1723604535163,"mc":[{"id":"1.231652082","rc":[{"batb":[[0,2.08,4],[1,2.06,39.79],[2,1.74,16.78]],"ltp":2.16,"tv":215.81,"id":25651861}]}]}
{"op":"mcm","clk":"11875054215","pt":1723604801878,"mc":[{"id":"1.231652082","rc":[{"batb":[[0,2.08,8.37]],"ltp":2.16,"tv":215.81,"id":25651861}]}]}
{"op":"mcm","clk":"11875281673","pt":1723611938312,"mc":[{"id":"1.231652082","rc":[{"trd":[[1.5,192.27],[1.83,1314.25],[1.85,1315.81]],"batb":[[0,1.87,40.06],[2,1.85,2.01]],"ltp":1.86,"tv":3159.93,"id":6847357},{"trd":[[1.5,192.86]],"ltp":2.16,"tv":215.75,"id":25651861}],"tv":3375.68}]}
{"op":"mcm","clk":"11875338311","pt":1723613455382,"mc":[{"id":"1.231652082","rc":[{"trd":[[1.87,39.24]],"batb":[[0,1.87,26.25]],"ltp":1.87,"tv":3187.55,"id":6847357}],"tv":3403.3}]}
{"op":"mcm","clk":"11875357375","pt":1723614023094,"mc":[{"id":"1.231652082","rc":[{"trd":[[1.87,47.24]],"batb":[[0,1.87,22.25]],"ltp":1.87,"tv":3195.55,"id":6847357}],"tv":3411.3}]}
{"op":"mcm","clk":"11875430170","pt":1723616721369,"mc":[{"id":"1.231652082","rc":[{"trd":[[1.5,192.28],[1.75,31.3],[1.81,107.97],[1.83,1314.36],[1.85,1315.91],[1.87,52.74]],"batb":[[0,1.87,19.56]],"ltp":1.87,"tv":3201.25,"id":6847357},{"trd":[[1.5,192.87]],"ltp":2.16,"tv":215.76,"id":25651861}],"tv":3417.02}]}
{"op":"mcm","clk":"11875551778","pt":1723620847101,"mc":[{"id":"1.231652082","rc":[{"trd":[[1.5,192.6],[1.75,31.34],[1.76,16.54],[1.81,108.11],[1.82,15.42],[1.83,1316.71],[1.85,1318.27],[1.86,28.96],[1.87,52.77],[1.88,0.76]],"batb":[[0,1.91,5],[1,1.87,19.58],[2,1.86,48.11]],"batl":[[1,1.94,11.3]],"ltp":1.87,"tv":3206.58,"id":6847357},{"trd":[[1.48,5.52],[1.5,193.19],[1.56,1.09]],"batb":[[0,2.08,8.38]],"ltp":2.16,"tv":216.1,"id":25651861}],"tv":3422.69}]}
{"op":"mcm","clk":"11875551828","pt":1723620849096,"mc":[{"id":"1.231652082","rc":[{"batb":[[2,1.86,4]],"ltp":1.87,"tv":3206.58,"id":6847357},{"batb":[[1,2.06,4]],"ltp":2.16,"tv":216.1,"id":25651861}]}]}
{"op":"mcm","clk":"11875551869","pt":1723620850992,"mc":[{"id":"1.231652082","rc":[{"batl":[[1,1.94,0]],"ltp":1.87,"tv":3206.58,"id":6847357},{"batb":[[0,2.08,4]],"ltp":2.16,"tv":216.1,"id":25651861}]}]}
{"op":"mcm","clk":"11875551888","pt":1723620851806,"mc":[{"id":"1.231652082","rc":[{"batb":[[0,1.75,36.67],[1,1.74,16.78],[2,1.45,57.44]],"ltp":2.16,"tv":216.1,"id":25651861}]}]}
{"op":"mcm","clk":"11875551920","pt":1723620853089,"mc":[{"id":"1.231652082","rc":[{"batl":[[0,2.32,9.45]],"ltp":1.87,"tv":3206.58,"id":6847357}]}]}
{"op":"mcm","clk":"11875551937","pt":1723620854009,"mc":[{"id":"1.231652082","rc":[{"batb":[[2,1.86,48.11]],"ltp":1.87,"tv":3206.58,"id":6847357},{"batb":[[0,2.06,35.79],[1,1.75,36.67],[2,1.74,16.78]],"ltp":2.16,"tv":216.1,"id":25651861}]}]}
{"op":"mcm","clk":"11875551967","pt":1723620855702,"mc":[{"id":"1.231652082","rc":[{"batl":[[0,1.94,11.3]],"ltp":1.87,"tv":3206.58,"id":6847357}]}]}
{"op":"mcm","clk":"11875552069","pt":1723620860799,"mc":[{"id":"1.231652082","rc":[{"batl":[[0,1.93,4],[1,1.94,15.3]],"ltp":1.87,"tv":3206.58,"id":6847357},{"batb":[[0,2.08,4],[1,2.06,39.79],[2,1.75,36.67]],"ltp":2.16,"tv":216.1,"id":25651861}]}]}
{"op":"mcm","clk":"11875552115","pt":1723620862431,"mc":[{"id":"1.231652082","rc":[{"batb":[[0,2.08,8.65]],"ltp":2.16,"tv":216.1,"id":25651861}]}]}
{"op":"mcm","clk":"11875552164","pt":1723620864121,"mc":[{"id":"1.231652082","rc":[{"batb":[[2,1.86,4]],"ltp":1.87,"tv":3206.58,"id":6847357},{"batb":[[1,2.06,4]],"ltp":2.16,"tv":216.1,"id":25651861}]}]}
{"op":"mcm","clk":"11875552168","pt":1723620864325,"mc":[{"id":"1.231652082","rc":[{"batb":[[2,1.74,16.78]],"ltp":2.16,"tv":216.1,"id":25651861}]}]}
{"op":"mcm","clk":"11875552220","pt":1723620866533,"mc":[{"id":"1.231652082","rc":[{"batb":[[0,2.08,4]],"ltp":2.16,"tv":216.1,"id":25651861}]}]}
{"op":"mcm","clk":"11875552285","pt":1723620869009,"mc":[{"id":"1.231652082","rc":[{"batl":[[1,1.94,4]],"ltp":1.87,"tv":3206.58,"id":6847357}]}]}
{"op":"mcm","clk":"11875552320","pt":1723620870026,"mc":[{"id":"1.231652082","rc":[{"batb":[[0,1.75,36.67],[1,1.74,16.78],[2,1.45,57.44]],"ltp":2.16,"tv":216.1,"id":25651861}]}]}
{"op":"mcm","clk":"11875552406","pt":1723620874012,"mc":[{"id":"1.231652082","rc":[{"batb":[[2,1.86,48.11]],"ltp":1.87,"tv":3206.58,"id":6847357},{"batb":[[0,2.06,35.79],[1,1.75,36.67],[2,1.74,16.78]],"ltp":2.16,"tv":216.1,"id":25651861}]}]}
{"op":"mcm","clk":"11875552437","pt":1723620875951,"mc":[{"id":"1.231652082","rc":[{"batl":[[0,1.94,4],[1,1.95,4]],"ltp":1.87,"tv":3206.58,"id":6847357},{"batb":[[0,2.08,4],[1,2.06,39.79],[2,1.75,36.67]],"ltp":2.16,"tv":216.1,"id":25651861}]}]}
{"op":"mcm","clk":"11875552528","pt":1723620879131,"mc":[{"id":"1.231652082","rc":[{"batb":[[2,1.86,4]],"ltp":1.87,"tv":3206.58,"id":6847357},{"batb":[[1,2.06,4]],"ltp":2.16,"tv":216.1,"id":25651861}]}]}
{"op":"mcm","clk":"11875552555","pt":1723620879914,"mc":[{"id":"1.231652082","rc":[{"batb":[[0,1.75,36.67],[1,1.74,16.78],[2,1.45,57.44]],"ltp":2.16,"tv":216.1,"id":25651861}]}]}
