{"op":"mcm","clk":"11933681820","pt":1724628335203,"mc":[{"id":"1.232283631","marketDefinition":{"bspMarket":false,"turnInPlayEnabled":true,"persistenceEnabled":true,"marketBaseRate":5.0,"eventId":"33527290","eventTypeId":"4","numberOfWinners":1,"bettingType":"ODDS","marketType":"MATCH_ODDS","marketTime":"2024-08-27T19:00:00.000Z","suspendTime":"2024-08-27T19:00:00.000Z","bspReconciled":false,"complete":true,"inPlay":false,"crossMatching":true,"runnersVoidable":false,"numberOfActiveRunners":2,"betDelay":0,"status":"OPEN","runners":[{"status":"ACTIVE","sortPriority":1,"id":235,"name":"West Indies"},{"status":"ACTIVE","sortPriority":2,"id":349,"name":"South Africa"}],"regulators":["MR_INT"],"countryCode":"GB","discountAllowed":false,"timezone":"GMT","openDate":"2024-08-27T19:00:00.000Z","version":6100792092,"name":"Match Odds","eventName":"West Indies v South Africa"},"rc":[{"batb":[[0,1.01,20]],"ltp":0.0,"tv":0.0,"id":349},{"batb":[[0,1.01,20]],"ltp":0.0,"tv":0.0,"id":235}]}]}
{"op":"mcm","clk":"11933681826","pt":1724628335299,"mc":[{"id":"1.232283631","rc":[{"batb":[[0,1.06,100],[1,1.05,100],[2,1.04,100]],"ltp":0.0,"tv":0.0,"id":349},{"batb":[[0,1.06,100],[1,1.05,100],[2,1.04,100]],"ltp":0.0,"tv":0.0,"id":235}]}]}
{"op":"mcm","clk":"11933681933","pt":1724628337286,"mc":[{"id":"1.232283631","marketDefinition":{"bspMarket":false,"turnInPlayEnabled":true,"persistenceEnabled":true,"marketBaseRate":5.0,"eventId":"33527290","eventTypeId":"4","numberOfWinners":1,"bettingType":"ODDS","marketType":"MATCH_ODDS","marketTime":"2024-08-27T19:00:00.000Z","suspendTime":"2024-08-27T19:00:00.000Z","bspReconciled":false,"complete":true,"inPlay":false,"crossMatching":true,"runnersVoidable":false,"numberOfActiveRunners":2,"betDelay":0,"status":"OPEN","runners":[{"status":"ACTIVE","sortPriority":1,"id":235,"name":"West Indies"},{"status":"ACTIVE","sortPriority":2,"id":349,"name":"South Africa"}],"regulators":["MR_INT"],"countryCode":"GB","discountAllowed":true,"timezone":"GMT","openDate":"2024-08-27T19:00:00.000Z","version":6100792092,"name":"Match Odds","eventName":"West Indies v South Africa"}}]}
{"op":"mcm","clk":"11933683781","pt":1724628374148,"mc":[{"id":"1.232283631","rc":[{"batb":[[2,1.04,1715.55]],"ltp":0.0,"tv":0.0,"id":235}]}]}
{"op":"mcm","clk":"11933683789","pt":1724628374353,"mc":[{"id":"1.232283631","rc":[{"batb":[[2,1.04,1715.55]],"ltp":0.0,"tv":0.0,"id":349}]}]}
{"op":"mcm","clk":"11933719535","pt":1724629241022,"mc":[{"id":"1.232283631","rc":[{"batb":[[0,2.44,26.69],[1,1.06,100],[2,1.05,100]],"ltp":0.0,"tv":0.0,"id":349},{"batb":[[0,1.63,61.02],[1,1.06,100],[2,1.05,100]],"ltp":0.0,"tv":0.0,"id":235}]}]}
{"op":"mcm","clk":"11933887329","pt":1724632834852,"mc":[{"id":"1.232283631","rc":[{"batl":[[0,1.8,276.92]],"ltp":0.0,"tv":0.0,"id":235}]}]}
{"op":"mcm","clk":"11933887650","pt":1724632841060,"mc":[{"id":"1.232283631","rc":[{"batl":[[0,1.75,138.46],[1,1.8,276.92]],"ltp":0.0,"tv":0.0,"id":235}]}]}
{"op":"mcm","clk":"11933888114","pt":1724632849279,"mc":[{"id":"1.232283631","rc":[{"batl":[[2,1.88,276.92]],"ltp":0.0,"tv":0.0,"id":235}]}]}
{"op":"mcm","clk":"11934063810","pt":1724636846291,"mc":[{"id":"1.232283631","rc":[{"batb":[[1,1.52,276.92],[2,1.06,100]],"ltp":0.0,"tv":0.0,"id":235}]}]}
{"op":"mcm","clk":"11934063962","pt":1724636851825,"mc":[{"id":"1.232283631","rc":[{"batb":[[1,1.56,276.92],[2,1.52,276.92]],"ltp":0.0,"tv":0.0,"id":235}]}]}
{"op":"mcm","clk":"11934064118","pt":1724636856536,"mc":[{"id":"1.232283631","rc":[{"batb":[[1,1.52,276.92],[2,1.06,100]],"ltp":0.0,"tv":0.0,"id":235}]}]}
{"op":"mcm","clk":"11934064294","pt":1724636861936,"mc":[{"id":"1.232283631","rc":[{"batb":[[2,1.45,276.92]],"ltp":0.0,"tv":0.0,"id":235}]}]}
{"op":"mcm","clk":"11934078297","pt":1724637325410,"mc":[{"id":"1.232283631","rc":[{"batb":[[1,1.9,1230.77],[2,1.06,100]],"ltp":0.0,"tv":0.0,"id":349}]}]}
{"op":"mcm","clk":"11934137199","pt":1724639083329,"mc":[{"id":"1.232283631","rc":[{"trd":[[2.44,10.28]],"batb":[[0,2.44,21.55]],"ltp":2.44,"tv":10.27,"id":349}],"tv":10.27}]}
{"op":"mcm","clk":"11934137319","pt":1724639086752,"mc":[{"id":"1.232283631","rc":[{"batb":[[0,2.44,26.69]],"ltp":2.44,"tv":10.27,"id":349}]}]}
{"op":"mcm","clk":"11934187543","pt":1724640308177,"mc":[{"id":"1.232283631","rc":[{"batb":[[1,1.58,276.92],[2,1.52,276.92]],"ltp":0.0,"tv":0.0,"id":235}]}]}
{"op":"mcm","clk":"11934414578","pt":1724646163469,"mc":[{"id":"1.232283631","rc":[{"trd":[[2.44,10.27]],"ltp":2.44,"tv":10.27,"id":349}],"tv":10.27}]}
{"op":"mcm","clk":"11934421028","pt":1724646393031,"mc":[{"id":"1.232283631","rc":[{"batl":[[0,1.7,1013.46],[1,1.75,138.46],[2,1.8,276.92]],"ltp":0.0,"tv":0.0,"id":235}]}]}
{"op":"mcm","clk":"11934421186","pt":1724646398011,"mc":[{"id":"1.232283631","rc":[{"batl":[[0,1.75,138.46],[1,1.8,276.92],[2,1.88,276.92]],"ltp":0.0,"tv":0.0,"id":235}]}]}
{"op":"mcm","clk":"11934438694","pt":1724646898165,"mc":[{"id":"1.232283631","rc":[{"batl":[[0,1.7,1013.46],[1,1.75,138.46],[2,1.8,276.92]],"ltp":0.0,"tv":0.0,"id":235}]}]}
{"op":"mcm","clk":"11934489623","pt":1724648237978,"mc":[{"id":"1.232283631","rc":[{"batl":[[0,1.69,17.03],[1,1.7,1013.46],[2,1.75,138.46]],"ltp":0.0,"tv":0.0,"id":235}]}]}
{"op":"mcm","clk":"11934491707","pt":1724648297060,"mc":[{"id":"1.232283631","rc":[{"batl":[[0,1.75,138.46],[1,1.8,276.92],[2,1.88,276.92]],"ltp":0.0,"tv":0.0,"id":235}]}]}
{"op":"mcm","clk":"11934661498","pt":1724652774837,"mc":[{"id":"1.232283631","rc":[{"trd":[[2.44,10.27]],"ltp":2.44,"tv":10.27,"id":349}],"tv":10.27}]}
{"op":"mcm","clk":"11934793484","pt":1724655750589,"mc":[{"id":"1.232283631","rc":[{"trd":[[2.44,14.47]],"batb":[[0,2.44,24.59]],"ltp":2.44,"tv":14.47,"id":349}],"tv":14.47}]}
{"op":"mcm","clk":"11934793601","pt":1724655753102,"mc":[{"id":"1.232283631","rc":[{"batb":[[0,2.44,26.69]],"ltp":2.44,"tv":14.47,"id":349}]}]}
{"op":"mcm","clk":"11934841769","pt":1724656858092,"mc":[{"id":"1.232283631","rc":[{"batl":[[0,3.2,15.09]],"ltp":2.44,"tv":14.47,"id":349}]}]}
{"op":"mcm","clk":"11934857465","pt":1724657314421,"mc":[{"id":"1.232283631","rc":[{"batb":[[1,1.59,98.46],[2,1.58,276.92]],"ltp":0.0,"tv":0.0,"id":235}]}]}
{"op":"mcm","clk":"11934939666","pt":1724658939150,"mc":[{"id":"1.232283631","rc":[{"batb":[[0,1.64,262.54],[1,1.63,61.02],[2,1.59,98.46]],"ltp":0.0,"tv":0.0,"id":235}]}]}
{"op":"mcm","clk":"11934979390","pt":1724659712621,"mc":[{"id":"1.232283631","rc":[{"trd":[[2.44,14.47]],"batl":[[0,2.56,8.19],[1,3.2,15.1]],"ltp":2.44,"tv":14.47,"id":349}],"tv":14.47}]}
{"op":"mcm","clk":"11934984207","pt":1724659819718,"mc":[{"id":"1.232283631","rc":[{"batb":[[2,1.58,276.92]],"ltp":0.0,"tv":0.0,"id":235}]}]}
{"op":"mcm","clk":"11935008857","pt":1724660270055,"mc":[{"id":"1.232283631","rc":[{"batb":[[0,1.65,13.52],[1,1.64,262.54],[2,1.63,61.02]],"ltp":0.0,"tv":0.0,"id":235}]}]}
{"op":"mcm","clk":"11935009028","pt":1724660273075,"mc":[{"id":"1.232283631","rc":[{"batl":[[0,3.2,15.1],[1,3.2,0]],"ltp":2.44,"tv":14.47,"id":349}]}]}
{"op":"mcm","clk":"11935049285","pt":1724660988315,"mc":[{"id":"1.232283631","rc":[{"trd":[[2.44,18]],"batb":[[0,2.44,23.16]],"ltp":2.44,"tv":18.0,"id":349},{"trd":[[1.7,5.06]],"ltp":1.7,"tv":5.06,"id":235}],"tv":23.06}]}
{"op":"mcm","clk":"11935049542","pt":1724660993135,"mc":[{"id":"1.232283631","rc":[{"batb":[[0,2.44,26.69]],"ltp":2.44,"tv":18.0,"id":349}]}]}
{"op":"mcm","clk":"11935196362","pt":1724663574819,"mc":[{"id":"1.232283631","rc":[{"batb":[[0,1.65,13.52]],"ltp":1.7,"tv":5.06,"id":235}]}]}
{"op":"mcm","clk":"11935255569","pt":1724664330622,"mc":[{"id":"1.232283631","rc":[{"batb":[[2,1.1,25000]],"ltp":2.44,"tv":18.0,"id":349}]}]}
{"op":"mcm","clk":"11935318240","pt":1724665121110,"mc":[{"id":"1.232283631","rc":[{"trd":[[2.44,71.38]],"batb":[[0,1.9,1230.77],[1,1.1,25000],[2,1.09,25000]],"batl":[[0,2.44,50.31],[1,3.2,15.1]],"ltp":2.44,"tv":71.38,"id":349}],"tv":76.44}]}
{"op":"mcm","clk":"11935318252","pt":1724665121318,"mc":[{"id":"1.232283631","rc":[{"batb":[[0,2.36,28.26],[1,1.9,1230.77],[2,1.1,25000]],"ltp":2.44,"tv":71.38,"id":349}]}]}
{"op":"mcm","clk":"11935318365","pt":1724665123012,"mc":[{"id":"1.232283631","rc":[{"batb":[[0,1.64,262.54],[1,1.63,61.02],[2,1.58,276.92]],"ltp":1.7,"tv":5.06,"id":235}]}]}
{"op":"mcm","clk":"11935459017","pt":1724666846407,"mc":[{"id":"1.232283631","rc":[{"trd":[[2.44,71.4]],"batl":[[0,2.44,50.33],[1,3.2,15.1]],"ltp":2.44,"tv":71.39,"id":349},{"batl":[[0,1.72,246.15],[1,1.75,138.46],[2,1.8,276.92]],"ltp":1.7,"tv":5.06,"id":235}],"tv":76.45}]}
{"op":"mcm","clk":"11935476971","pt":1724667039648,"mc":[{"id":"1.232283631","rc":[{"trd":[[2.44,121.73]],"batl":[[0,3.2,15.1],[1,3.2,0]],"ltp":2.44,"tv":121.72,"id":349},{"trd":[[1.69,72.67]],"batl":[[0,1.69,12637.04],[1,1.72,246.15],[2,1.75,138.46]],"ltp":1.69,"tv":77.73,"id":235}],"tv":199.46}]}
{"op":"mcm","clk":"11935477789","pt":1724667049739,"mc":[{"id":"1.232283631","rc":[{"batl":[[0,2.56,8.19],[1,3.2,15.1]],"ltp":2.44,"tv":121.72,"id":349},{"batb":[[0,1.65,12.89],[1,1.64,262.54],[2,1.63,61.02]],"ltp":1.69,"tv":77.73,"id":235}]}]}
{"op":"mcm","clk":"11935512321","pt":1724667443295,"mc":[{"id":"1.232283631","rc":[{"batl":[[0,1.72,246.15],[1,1.75,138.46],[2,1.8,276.92]],"ltp":1.69,"tv":77.73,"id":235}]}]}
{"op":"mcm","clk":"11935512672","pt":1724667447181,"mc":[{"id":"1.232283631","rc":[{"batl":[[0,1.71,12709.71],[1,1.72,246.15],[2,1.75,138.46]],"ltp":1.69,"tv":77.73,"id":235}]}]}
{"op":"mcm","clk":"11935513512","pt":1724667456574,"mc":[{"id":"1.232283631","rc":[{"batl":[[0,1.7,276.92],[1,1.71,12709.71],[2,1.72,246.15]],"ltp":1.69,"tv":77.73,"id":235}]}]}
{"op":"mcm","clk":"11935515512","pt":1724667479398,"mc":[{"id":"1.232283631","rc":[{"batl":[[0,1.71,12709.71],[1,1.72,246.15],[2,1.75,138.46]],"ltp":1.69,"tv":77.73,"id":235}]}]}
{"op":"mcm","clk":"11935532229","pt":1724667662926,"mc":[{"id":"1.232283631","rc":[{"batb":[[0,1.65,16.89]],"ltp":1.69,"tv":77.73,"id":235}]}]}
{"op":"mcm","clk":"11935536403","pt":1724667715669,"mc":[{"id":"1.232283631","rc":[{"batb":[[0,2.38,5],[1,2.36,28.26],[2,1.9,1230.77]],"ltp":2.44,"tv":121.72,"id":349}]}]}
{"op":"mcm","clk":"11935536658","pt":1724667719070,"mc":[{"id":"1.232283631","rc":[{"batb":[[0,2.36,28.26],[1,1.9,1230.77],[2,1.1,25000]],"ltp":2.44,"tv":121.72,"id":349}]}]}
{"op":"mcm","clk":"11935536915","pt":1724667722055,"mc":[{"id":"1.232283631","rc":[{"batb":[[0,2.38,5],[1,2.36,28.26],[2,1.9,1230.77]],"ltp":2.44,"tv":121.72,"id":349}]}]}
{"op":"mcm","clk":"11935537215","pt":1724667725258,"mc":[{"id":"1.232283631","rc":[{"batb":[[0,2.36,28.26],[1,1.9,1230.77],[2,1.1,25000]],"ltp":2.44,"tv":121.72,"id":349}]}]}
{"op":"mcm","clk":"11935538597","pt":1724667741285,"mc":[{"id":"1.232283631","rc":[{"batb":[[0,2.38,5],[1,2.36,28.26],[2,1.9,1230.77]],"ltp":2.44,"tv":121.72,"id":349}]}]}
{"op":"mcm","clk":"11935581262","pt":1724668202406,"mc":[{"id":"1.232283631","rc":[{"batb":[[0,2.42,12.13],[1,2.38,5],[2,2.36,28.26]],"ltp":2.44,"tv":121.72,"id":349},{"batl":[[0,1.7,16.97],[1,1.71,12709.71],[2,1.72,246.15]],"ltp":1.69,"tv":77.73,"id":235}]}]}
{"op":"mcm","clk":"11935607076","pt":1724668499132,"mc":[{"id":"1.232283631","rc":[{"batb":[[1,2.36,28.26],[2,1.9,1230.77]],"ltp":2.44,"tv":121.72,"id":349}]}]}
{"op":"mcm","clk":"11935809879","pt":1724670801497,"mc":[{"id":"1.232283631","rc":[{"trd":[[2.44,121.71]],"batb":[[0,2.42,12.11]],"batl":[[0,2.56,8.18],[1,3.2,15.1]],"ltp":2.44,"tv":121.7,"id":349},{"trd":[[1.69,72.59],[1.7,25.46]],"batb":[[0,1.65,16.87]],"batl":[[0,1.7,6.75],[1,1.71,12695.73]],"ltp":1.7,"tv":98.05,"id":235}],"tv":219.76}]}
{"op":"mcm","clk":"11935810789","pt":1724670813152,"mc":[{"id":"1.232283631","rc":[{"batl":[[2,5,51.34]],"ltp":2.44,"tv":121.7,"id":349}]}]}
{"op":"mcm","clk":"11935852727","pt":1724671342800,"mc":[{"id":"1.232283631","rc":[{"trd":[[2.42,0.07]],"batb":[[0,2.42,12.08]],"ltp":2.42,"tv":121.77,"id":349}],"tv":219.82}]}
{"op":"mcm","clk":"11935853081","pt":1724671348015,"mc":[{"id":"1.232283631","rc":[{"trd":[[2.42,0.13]],"batb":[[0,2.42,12.04]],"ltp":2.42,"tv":121.84,"id":349}],"tv":219.89}]}
{"op":"mcm","clk":"11935853538","pt":1724671354214,"mc":[{"id":"1.232283631","rc":[{"trd":[[2.42,0.2]],"batb":[[0,2.42,12.01]],"ltp":2.42,"tv":121.9,"id":349}],"tv":219.96}]}
{"op":"mcm","clk":"11935853891","pt":1724671359624,"mc":[{"id":"1.232283631","rc":[{"trd":[[2.42,0.27]],"batb":[[0,2.42,11.98]],"ltp":2.42,"tv":121.97,"id":349}],"tv":220.02}]}
{"op":"mcm","clk":"11935854527","pt":1724671369114,"mc":[{"id":"1.232283631","rc":[{"trd":[[2.42,0.33]],"batb":[[0,2.42,11.94]],"ltp":2.42,"tv":122.04,"id":349}],"tv":220.09}]}
{"op":"mcm","clk":"11935855216","pt":1724671380131,"mc":[{"id":"1.232283631","rc":[{"trd":[[2.42,0.4]],"batb":[[0,2.42,11.91]],"ltp":2.42,"tv":122.1,"id":349}],"tv":220.16}]}
{"op":"mcm","clk":"11935886750","pt":1724671779073,"mc":[{"id":"1.232283631","rc":[{"trd":[[1.7,38.96],[1.71,6.98]],"batl":[[0,1.71,12692.24],[1,1.72,246.15],[2,1.75,138.46]],"ltp":1.71,"tv":118.53,"id":235}],"tv":240.64}]}
{"op":"mcm","clk":"11935886911","pt":1724671780727,"mc":[{"id":"1.232283631","rc":[{"batb":[[0,1.65,31.52]],"ltp":1.71,"tv":118.53,"id":235}]}]}
{"op":"mcm","clk":"11935887092","pt":1724671782885,"mc":[{"id":"1.232283631","rc":[{"batb":[[0,2.44,4],[1,2.42,11.91],[2,2.36,28.26]],"batl":[[0,3.2,15.1],[1,5,51.34],[2,10,51.34]],"ltp":2.42,"tv":122.1,"id":349}]}]}
{"op":"mcm","clk":"11935887261","pt":1724671785056,"mc":[{"id":"1.232283631","rc":[{"batb":[[0,2.42,11.91],[1,2.36,28.26],[2,1.9,1230.77]],"ltp":2.42,"tv":122.1,"id":349}]}]}
{"op":"mcm","clk":"11935887717","pt":1724671791796,"mc":[{"id":"1.232283631","rc":[{"batb":[[0,2.44,4],[1,2.42,11.91],[2,2.36,28.26]],"ltp":2.42,"tv":122.1,"id":349}]}]}
{"op":"mcm","clk":"11935887893","pt":1724671793950,"mc":[{"id":"1.232283631","rc":[{"batb":[[0,2.42,11.91],[1,2.36,28.26],[2,1.9,1230.77]],"ltp":2.42,"tv":122.1,"id":349}]}]}
{"op":"mcm","clk":"11935888493","pt":1724671801776,"mc":[{"id":"1.232283631","rc":[{"batb":[[0,2.44,4],[1,2.42,11.91],[2,2.36,28.26]],"ltp":2.42,"tv":122.1,"id":349}]}]}
{"op":"mcm","clk":"11935888693","pt":1724671804097,"mc":[{"id":"1.232283631","rc":[{"batb":[[0,2.42,11.91],[1,2.36,28.26],[2,1.9,1230.77]],"ltp":2.42,"tv":122.1,"id":349}]}]}
{"op":"mcm","clk":"11935888900","pt":1724671806260,"mc":[{"id":"1.232283631","rc":[{"batb":[[0,2.44,4],[1,2.42,11.91],[2,2.36,28.26]],"ltp":2.42,"tv":122.1,"id":349}]}]}
{"op":"mcm","clk":"11935889120","pt":1724671808577,"mc":[{"id":"1.232283631","rc":[{"batb":[[0,2.42,11.91],[1,2.36,28.26],[2,1.9,1230.77]],"ltp":2.42,"tv":122.1,"id":349}]}]}
{"op":"mcm","clk":"11935889678","pt":1724671814737,"mc":[{"id":"1.232283631","rc":[{"batb":[[0,2.44,4],[1,2.42,11.91],[2,2.36,28.26]],"ltp":2.42,"tv":122.1,"id":349}]}]}
{"op":"mcm","clk":"11935889863","pt":1724671817109,"mc":[{"id":"1.232283631","rc":[{"batb":[[0,2.42,11.91],[1,2.36,28.26],[2,1.9,1230.77]],"ltp":2.42,"tv":122.1,"id":349}]}]}
{"op":"mcm","clk":"11935890072","pt":1724671819992,"mc":[{"id":"1.232283631","rc":[{"batb":[[0,2.44,4],[1,2.42,11.91],[2,2.36,28.26]],"ltp":2.42,"tv":122.1,"id":349}]}]}
{"op":"mcm","clk":"11935890263","pt":1724671822322,"mc":[{"id":"1.232283631","rc":[{"batb":[[0,2.42,11.91],[1,2.36,28.26],[2,1.9,1230.77]],"ltp":2.42,"tv":122.1,"id":349}]}]}
{"op":"mcm","clk":"11935890445","pt":1724671824497,"mc":[{"id":"1.232283631","rc":[{"batb":[[0,2.44,4],[1,2.42,11.91],[2,2.36,28.26]],"ltp":2.42,"tv":122.1,"id":349}]}]}
{"op":"mcm","clk":"11935890614","pt":1724671826706,"mc":[{"id":"1.232283631","rc":[{"batb":[[0,2.42,11.91],[1,2.36,28.26],[2,1.9,1230.77]],"ltp":2.42,"tv":122.1,"id":349}]}]}
{"op":"mcm","clk":"11935891108","pt":1724671831820,"mc":[{"id":"1.232283631","rc":[{"batb":[[0,2.44,4],[1,2.42,11.91],[2,2.36,28.26]],"ltp":2.42,"tv":122.1,"id":349}]}]}
{"op":"mcm","clk":"11935891303","pt":1724671833939,"mc":[{"id":"1.232283631","rc":[{"batb":[[0,2.42,11.91],[1,2.36,28.26],[2,1.9,1230.77]],"ltp":2.42,"tv":122.1,"id":349}]}]}
{"op":"mcm","clk":"11935891529","pt":1724671836414,"mc":[{"id":"1.232283631","rc":[{"batb":[[0,2.44,4],[1,2.42,11.91],[2,2.36,28.26]],"ltp":2.42,"tv":122.1,"id":349}]}]}
{"op":"mcm","clk":"11935891720","pt":1724671838628,"mc":[{"id":"1.232283631","rc":[{"batb":[[0,2.42,11.91],[1,2.36,28.26],[2,1.9,1230.77]],"ltp":2.42,"tv":122.1,"id":349}]}]}
{"op":"mcm","clk":"11935891945","pt":1724671841106,"mc":[{"id":"1.232283631","rc":[{"batb":[[0,2.44,4],[1,2.42,11.91],[2,2.36,28.26]],"ltp":2.42,"tv":122.1,"id":349}]}]}
{"op":"mcm","clk":"11935892153","pt":1724671843321,"mc":[{"id":"1.232283631","rc":[{"batb":[[0,2.42,11.91],[1,2.36,28.26],[2,1.9,1230.77]],"ltp":2.42,"tv":122.1,"id":349}]}]}
{"op":"mcm","clk":"11935893111","pt":1724671854355,"mc":[{"id":"1.232283631","rc":[{"batb":[[0,2.44,4],[1,2.42,11.91],[2,2.36,28.26]],"ltp":2.42,"tv":122.1,"id":349}]}]}
{"op":"mcm","clk":"11935893339","pt":1724671856630,"mc":[{"id":"1.232283631","rc":[{"batb":[[0,2.42,11.91],[1,2.36,28.26],[2,1.9,1230.77]],"ltp":2.42,"tv":122.1,"id":349}]}]}
{"op":"mcm","clk":"11935894407","pt":1724671867435,"mc":[{"id":"1.232283631","rc":[{"batb":[[0,2.44,4],[1,2.42,11.91],[2,2.36,28.26]],"ltp":2.42,"tv":122.1,"id":349}]}]}
{"op":"mcm","clk":"11935894599","pt":1724671869649,"mc":[{"id":"1.232283631","rc":[{"batb":[[0,2.42,11.91],[1,2.36,28.26],[2,1.9,1230.77]],"ltp":2.42,"tv":122.1,"id":349}]}]}
{"op":"mcm","clk":"11935894955","pt":1724671873167,"mc":[{"id":"1.232283631","rc":[{"batb":[[0,2.44,4],[1,2.42,11.91],[2,2.36,28.26]],"ltp":2.42,"tv":122.1,"id":349}]}]}
{"op":"mcm","clk":"11935895185","pt":1724671875449,"mc":[{"id":"1.232283631","rc":[{"batb":[[0,2.42,11.91],[1,2.36,28.26],[2,1.9,1230.77]],"ltp":2.42,"tv":122.1,"id":349}]}]}
{"op":"mcm","clk":"11935895627","pt":1724671880052,"mc":[{"id":"1.232283631","rc":[{"batb":[[0,2.44,4],[1,2.42,11.91],[2,2.36,28.26]],"ltp":2.42,"tv":122.1,"id":349}]}]}
{"op":"mcm","clk":"11935895847","pt":1724671882363,"mc":[{"id":"1.232283631","rc":[{"batb":[[0,2.42,11.91],[1,2.36,28.26],[2,1.9,1230.77]],"ltp":2.42,"tv":122.1,"id":349}]}]}
{"op":"mcm","clk":"11935896540","pt":1724671890784,"mc":[{"id":"1.232283631","rc":[{"batb":[[0,2.44,4],[1,2.42,11.91],[2,2.36,28.26]],"ltp":2.42,"tv":122.1,"id":349}]}]}
{"op":"mcm","clk":"11935896756","pt":1724671893090,"mc":[{"id":"1.232283631","rc":[{"batb":[[0,2.42,11.91],[1,2.36,28.26],[2,1.9,1230.77]],"ltp":2.42,"tv":122.1,"id":349}]}]}
{"op":"mcm","clk":"11935897135","pt":1724671897671,"mc":[{"id":"1.232283631","rc":[{"batb":[[0,2.44,4],[1,2.42,11.91],[2,2.36,28.26]],"ltp":2.42,"tv":122.1,"id":349}]}]}
{"op":"mcm","clk":"11935897313","pt":1724671899981,"mc":[{"id":"1.232283631","rc":[{"batb":[[0,2.42,11.91],[1,2.36,28.26],[2,1.9,1230.77]],"ltp":2.42,"tv":122.1,"id":349}]}]}
{"op":"mcm","clk":"11935897511","pt":1724671902392,"mc":[{"id":"1.232283631","rc":[{"batb":[[0,2.44,4],[1,2.42,11.91],[2,2.36,28.26]],"ltp":2.42,"tv":122.1,"id":349}]}]}
{"op":"mcm","clk":"11935897689","pt":1724671904701,"mc":[{"id":"1.232283631","rc":[{"batb":[[0,2.42,11.91],[1,2.36,28.26],[2,1.9,1230.77]],"ltp":2.42,"tv":122.1,"id":349}]}]}
{"op":"mcm","clk":"11935898220","pt":1724671911285,"mc":[{"id":"1.232283631","rc":[{"batb":[[0,2.44,4],[1,2.42,11.91],[2,2.36,28.26]],"ltp":2.42,"tv":122.1,"id":349}]}]}
{"op":"mcm","clk":"11935898414","pt":1724671913595,"mc":[{"id":"1.232283631","rc":[{"batb":[[0,2.42,11.91],[1,2.36,28.26],[2,1.9,1230.77]],"ltp":2.42,"tv":122.1,"id":349}]}]}
{"op":"mcm","clk":"11935898665","pt":1724671916791,"mc":[{"id":"1.232283631","rc":[{"batb":[[0,2.44,4],[1,2.42,11.91],[2,2.36,28.26]],"ltp":2.42,"tv":122.1,"id":349}]}]}
{"op":"mcm","clk":"11935898880","pt":1724671919101,"mc":[{"id":"1.232283631","rc":[{"batb":[[0,2.42,11.91],[1,2.36,28.26],[2,1.9,1230.77]],"ltp":2.42,"tv":122.1,"id":349}]}]}
{"op":"mcm","clk":"11935899208","pt":1724671923030,"mc":[{"id":"1.232283631","rc":[{"batb":[[0,2.44,4],[1,2.42,11.91],[2,2.36,28.26]],"ltp":2.42,"tv":122.1,"id":349}]}]}
{"op":"mcm","clk":"11935899442","pt":1724671925320,"mc":[{"id":"1.232283631","rc":[{"batb":[[0,2.42,11.91],[1,2.36,28.26],[2,1.9,1230.77]],"ltp":2.42,"tv":122.1,"id":349}]}]}
{"op":"mcm","clk":"11935899868","pt":1724671929799,"mc":[{"id":"1.232283631","rc":[{"batb":[[0,2.44,4],[1,2.42,11.91],[2,2.36,28.26]],"ltp":2.42,"tv":122.1,"id":349}]}]}
{"op":"mcm","clk":"11935900084","pt":1724671932101,"mc":[{"id":"1.232283631","rc":[{"batb":[[0,2.42,11.91],[1,2.36,28.26],[2,1.9,1230.77]],"ltp":2.42,"tv":122.1,"id":349}]}]}
{"op":"mcm","clk":"11935900410","pt":1724671936203,"mc":[{"id":"1.232283631","rc":[{"batb":[[0,2.44,4],[1,2.42,11.91],[2,2.36,28.26]],"ltp":2.42,"tv":122.1,"id":349}]}]}
{"op":"mcm","clk":"11935900623","pt":1724671938614,"mc":[{"id":"1.232283631","rc":[{"batb":[[0,2.42,11.91],[1,2.36,28.26],[2,1.9,1230.77]],"ltp":2.42,"tv":122.1,"id":349}]}]}
{"op":"mcm","clk":"11935900971","pt":1724671942316,"mc":[{"id":"1.232283631","rc":[{"batb":[[0,2.44,4],[1,2.42,11.91],[2,2.36,28.26]],"ltp":2.42,"tv":122.1,"id":349}]}]}
{"op":"mcm","clk":"11935901168","pt":1724671944628,"mc":[{"id":"1.232283631","rc":[{"batb":[[0,2.42,11.91],[1,2.36,28.26],[2,1.9,1230.77]],"ltp":2.42,"tv":122.1,"id":349}]}]}
{"op":"mcm","clk":"11935901370","pt":1724671946741,"mc":[{"id":"1.232283631","rc":[{"batb":[[0,2.44,4],[1,2.42,11.91],[2,2.36,28.26]],"ltp":2.42,"tv":122.1,"id":349}]}]}
{"op":"mcm","clk":"11935901564","pt":1724671949113,"mc":[{"id":"1.232283631","rc":[{"batb":[[0,2.42,11.91],[1,2.36,28.26],[2,1.9,1230.77]],"ltp":2.42,"tv":122.1,"id":349}]}]}
{"op":"mcm","clk":"11935901964","pt":1724671953651,"mc":[{"id":"1.232283631","rc":[{"batb":[[0,2.44,4],[1,2.42,11.91],[2,2.36,28.26]],"ltp":2.42,"tv":122.1,"id":349}]}]}
{"op":"mcm","clk":"11935902152","pt":1724671955763,"mc":[{"id":"1.232283631","rc":[{"batb":[[0,2.42,11.91],[1,2.36,28.26],[2,1.9,1230.77]],"ltp":2.42,"tv":122.1,"id":349}]}]}
{"op":"mcm","clk":"11935902601","pt":1724671961164,"mc":[{"id":"1.232283631","rc":[{"batb":[[0,2.44,4],[1,2.42,11.91],[2,2.36,28.26]],"ltp":2.42,"tv":122.1,"id":349}]}]}
{"op":"mcm","clk":"11935902778","pt":1724671963370,"mc":[{"id":"1.232283631","rc":[{"batb":[[0,2.42,11.91],[1,2.36,28.26],[2,1.9,1230.77]],"ltp":2.42,"tv":122.1,"id":349}]}]}
{"op":"mcm","clk":"11935903260","pt":1724671968864,"mc":[{"id":"1.232283631","rc":[{"batb":[[0,2.44,4],[1,2.42,11.91],[2,2.36,28.26]],"ltp":2.42,"tv":122.1,"id":349}]}]}
{"op":"mcm","clk":"11935903429","pt":1724671971176,"mc":[{"id":"1.232283631","rc":[{"batb":[[0,2.42,11.91],[1,2.36,28.26],[2,1.9,1230.77]],"ltp":2.42,"tv":122.1,"id":349}]}]}
{"op":"mcm","clk":"11935904488","pt":1724671984196,"mc":[{"id":"1.232283631","rc":[{"batb":[[0,2.44,4],[1,2.42,11.91],[2,2.36,28.26]],"ltp":2.42,"tv":122.1,"id":349}]}]}
{"op":"mcm","clk":"11935904697","pt":1724671986356,"mc":[{"id":"1.232283631","rc":[{"batb":[[0,2.42,11.91],[1,2.36,28.26],[2,1.9,1230.77]],"ltp":2.42,"tv":122.1,"id":349}]}]}
{"op":"mcm","clk":"11935905068","pt":1724671990369,"mc":[{"id":"1.232283631","rc":[{"batb":[[0,2.44,4],[1,2.42,11.91],[2,2.36,28.26]],"ltp":2.42,"tv":122.1,"id":349}]}]}
{"op":"mcm","clk":"11935905281","pt":1724671992581,"mc":[{"id":"1.232283631","rc":[{"batb":[[0,2.42,11.91],[1,2.36,28.26],[2,1.9,1230.77]],"ltp":2.42,"tv":122.1,"id":349}]}]}
{"op":"mcm","clk":"11935905568","pt":1724671995867,"mc":[{"id":"1.232283631","rc":[{"batb":[[0,2.44,4],[1,2.42,11.91],[2,2.36,28.26]],"ltp":2.42,"tv":122.1,"id":349}]}]}
{"op":"mcm","clk":"11935905761","pt":1724671998247,"mc":[{"id":"1.232283631","rc":[{"batb":[[0,2.42,11.91],[1,2.36,28.26],[2,1.9,1230.77]],"ltp":2.42,"tv":122.1,"id":349}]}]}
{"op":"mcm","clk":"11935906355","pt":1724672004768,"mc":[{"id":"1.232283631","rc":[{"batb":[[0,2.44,4],[1,2.42,11.91],[2,2.36,28.26]],"ltp":2.42,"tv":122.1,"id":349}]}]}
{"op":"mcm","clk":"11935906561","pt":1724672007197,"mc":[{"id":"1.232283631","rc":[{"batb":[[0,2.42,11.91],[1,2.36,28.26],[2,1.9,1230.77]],"ltp":2.42,"tv":122.1,"id":349}]}]}
{"op":"mcm","clk":"11935906866","pt":1724672011270,"mc":[{"id":"1.232283631","rc":[{"batb":[[0,2.44,4],[1,2.42,11.91],[2,2.36,28.26]],"ltp":2.42,"tv":122.1,"id":349}]}]}
{"op":"mcm","clk":"11935907097","pt":1724672013486,"mc":[{"id":"1.232283631","rc":[{"batb":[[0,2.42,11.91],[1,2.36,28.26],[2,1.9,1230.77]],"ltp":2.42,"tv":122.1,"id":349}]}]}
{"op":"mcm","clk":"11935907394","pt":1724672016475,"mc":[{"id":"1.232283631","rc":[{"batb":[[0,2.44,4],[1,2.42,11.91],[2,2.36,28.26]],"ltp":2.42,"tv":122.1,"id":349}]}]}
{"op":"mcm","clk":"11935907612","pt":1724672018893,"mc":[{"id":"1.232283631","rc":[{"batb":[[0,2.42,11.91],[1,2.36,28.26],[2,1.9,1230.77]],"ltp":2.42,"tv":122.1,"id":349}]}]}
{"op":"mcm","clk":"11935907957","pt":1724672022469,"mc":[{"id":"1.232283631","rc":[{"batb":[[0,2.44,4],[1,2.42,11.91],[2,2.36,28.26]],"ltp":2.42,"tv":122.1,"id":349}]}]}
{"op":"mcm","clk":"11935908166","pt":1724672024786,"mc":[{"id":"1.232283631","rc":[{"batb":[[0,2.42,11.91],[1,2.36,28.26],[2,1.9,1230.77]],"ltp":2.42,"tv":122.1,"id":349}]}]}
{"op":"mcm","clk":"11935908347","pt":1724672026901,"mc":[{"id":"1.232283631","rc":[{"batb":[[0,2.44,4],[1,2.42,11.91],[2,2.36,28.26]],"ltp":2.42,"tv":122.1,"id":349}]}]}
{"op":"mcm","clk":"11935908554","pt":1724672029169,"mc":[{"id":"1.232283631","rc":[{"batb":[[0,2.42,11.91],[1,2.36,28.26],[2,1.9,1230.77]],"ltp":2.42,"tv":122.1,"id":349}]}]}
{"op":"mcm","clk":"11935909433","pt":1724672040210,"mc":[{"id":"1.232283631","rc":[{"batb":[[0,2.44,4],[1,2.42,11.91],[2,2.36,28.26]],"ltp":2.42,"tv":122.1,"id":349}]}]}
{"op":"mcm","clk":"11935909633","pt":1724672042591,"mc":[{"id":"1.232283631","rc":[{"batb":[[0,2.42,11.91],[1,2.36,28.26],[2,1.9,1230.77]],"ltp":2.42,"tv":122.1,"id":349}]}]}
{"op":"mcm","clk":"11935910046","pt":1724672046394,"mc":[{"id":"1.232283631","rc":[{"batb":[[0,2.44,4],[1,2.42,11.91],[2,2.36,28.26]],"ltp":2.42,"tv":122.1,"id":349}]}]}
{"op":"mcm","clk":"11935910289","pt":1724672048814,"mc":[{"id":"1.232283631","rc":[{"batb":[[0,2.42,11.91],[1,2.36,28.26],[2,1.9,1230.77]],"ltp":2.42,"tv":122.1,"id":349}]}]}
{"op":"mcm","clk":"11935910618","pt":1724672052417,"mc":[{"id":"1.232283631","rc":[{"batb":[[0,2.44,4],[1,2.42,11.91],[2,2.36,28.26]],"ltp":2.42,"tv":122.1,"id":349}]}]}
{"op":"mcm","clk":"11935910849","pt":1724672054732,"mc":[{"id":"1.232283631","rc":[{"batb":[[0,2.42,11.91],[1,2.36,28.26],[2,1.9,1230.77]],"ltp":2.42,"tv":122.1,"id":349}]}]}
{"op":"mcm","clk":"11935911202","pt":1724672059123,"mc":[{"id":"1.232283631","rc":[{"batb":[[0,2.44,4],[1,2.42,11.91],[2,2.36,28.26]],"ltp":2.42,"tv":122.1,"id":349}]}]}
{"op":"mcm","clk":"11935911406","pt":1724672061432,"mc":[{"id":"1.232283631","rc":[{"batb":[[0,2.42,11.91],[1,2.36,28.26],[2,1.9,1230.77]],"ltp":2.42,"tv":122.1,"id":349}]}]}
{"op":"mcm","clk":"11935911907","pt":1724672067814,"mc":[{"id":"1.232283631","rc":[{"batb":[[0,2.44,4],[1,2.42,11.91],[2,2.36,28.26]],"ltp":2.42,"tv":122.1,"id":349}]}]}
{"op":"mcm","clk":"11935912072","pt":1724672070133,"mc":[{"id":"1.232283631","rc":[{"batb":[[0,2.42,11.91],[1,2.36,28.26],[2,1.9,1230.77]],"ltp":2.42,"tv":122.1,"id":349}]}]}
{"op":"mcm","clk":"11935912397","pt":1724672074550,"mc":[{"id":"1.232283631","rc":[{"batb":[[0,2.44,4],[1,2.42,11.91],[2,2.36,28.26]],"ltp":2.42,"tv":122.1,"id":349}]}]}
{"op":"mcm","clk":"11935912618","pt":1724672076914,"mc":[{"id":"1.232283631","rc":[{"batb":[[0,2.42,11.91],[1,2.36,28.26],[2,1.9,1230.77]],"ltp":2.42,"tv":122.1,"id":349}]}]}
{"op":"mcm","clk":"11935912839","pt":1724672079749,"mc":[{"id":"1.232283631","rc":[{"batb":[[0,2.44,4],[1,2.42,11.91],[2,2.36,28.26]],"ltp":2.42,"tv":122.1,"id":349}]}]}
{"op":"mcm","clk":"11935913037","pt":1724672082056,"mc":[{"id":"1.232283631","rc":[{"batb":[[0,2.42,11.91],[1,2.36,28.26],[2,1.9,1230.77]],"ltp":2.42,"tv":122.1,"id":349}]}]}
{"op":"mcm","clk":"11935913363","pt":1724672085549,"mc":[{"id":"1.232283631","rc":[{"batb":[[0,2.44,4],[1,2.42,11.91],[2,2.36,28.26]],"ltp":2.42,"tv":122.1,"id":349}]}]}
{"op":"mcm","clk":"11935913545","pt":1724672087770,"mc":[{"id":"1.232283631","rc":[{"batb":[[0,2.42,11.91],[1,2.36,28.26],[2,1.9,1230.77]],"ltp":2.42,"tv":122.1,"id":349}]}]}
{"op":"mcm","clk":"11935913731","pt":1724672090150,"mc":[{"id":"1.232283631","rc":[{"batb":[[0,2.44,4],[1,2.42,11.91],[2,2.36,28.26]],"ltp":2.42,"tv":122.1,"id":349}]}]}
{"op":"mcm","clk":"11935913957","pt":1724672092262,"mc":[{"id":"1.232283631","rc":[{"batb":[[0,2.42,11.91],[1,2.36,28.26],[2,1.9,1230.77]],"ltp":2.42,"tv":122.1,"id":349}]}]}
{"op":"mcm","clk":"11935914167","pt":1724672094470,"mc":[{"id":"1.232283631","rc":[{"batb":[[0,2.44,4],[1,2.42,11.91],[2,2.36,28.26]],"ltp":2.42,"tv":122.1,"id":349}]}]}
{"op":"mcm","clk":"11935914329","pt":1724672096667,"mc":[{"id":"1.232283631","rc":[{"batb":[[0,2.42,11.91],[1,2.36,28.26],[2,1.9,1230.77]],"ltp":2.42,"tv":122.1,"id":349}]}]}
{"op":"mcm","clk":"11935914666","pt":1724672101383,"mc":[{"id":"1.232283631","rc":[{"batb":[[0,2.44,4],[1,2.42,11.91],[2,2.36,28.26]],"ltp":2.42,"tv":122.1,"id":349}]}]}
{"op":"mcm","clk":"11935914875","pt":1724672103751,"mc":[{"id":"1.232283631","rc":[{"batb":[[0,2.42,11.91],[1,2.36,28.26],[2,1.9,1230.77]],"ltp":2.42,"tv":122.1,"id":349}]}]}
{"op":"mcm","clk":"11935915169","pt":1724672107548,"mc":[{"id":"1.232283631","rc":[{"batb":[[0,2.44,4],[1,2.42,11.91],[2,2.36,28.26]],"ltp":2.42,"tv":122.1,"id":349}]}]}
{"op":"mcm","clk":"11935915355","pt":1724672110068,"mc":[{"id":"1.232283631","rc":[{"batb":[[0,2.42,11.91],[1,2.36,28.26],[2,1.9,1230.77]],"ltp":2.42,"tv":122.1,"id":349}]}]}
{"op":"mcm","clk":"11935915527","pt":1724672112270,"mc":[{"id":"1.232283631","rc":[{"batb":[[0,2.44,4],[1,2.42,11.91],[2,2.36,28.26]],"ltp":2.42,"tv":122.1,"id":349}]}]}
{"op":"mcm","clk":"11935915709","pt":1724672114578,"mc":[{"id":"1.232283631","rc":[{"batb":[[0,2.42,11.91],[1,2.36,28.26],[2,1.9,1230.77]],"ltp":2.42,"tv":122.1,"id":349}]}]}
{"op":"mcm","clk":"11935916001","pt":1724672118600,"mc":[{"id":"1.232283631","rc":[{"batb":[[0,2.44,4],[1,2.42,11.91],[2,2.36,28.26]],"ltp":2.42,"tv":122.1,"id":349}]}]}
{"op":"mcm","clk":"11935916158","pt":1724672120811,"mc":[{"id":"1.232283631","rc":[{"batb":[[0,2.42,11.91],[1,2.36,28.26],[2,1.9,1230.77]],"ltp":2.42,"tv":122.1,"id":349}]}]}
{"op":"mcm","clk":"11935916578","pt":1724672126723,"mc":[{"id":"1.232283631","rc":[{"batb":[[0,2.44,4],[1,2.42,11.91],[2,2.36,28.26]],"ltp":2.42,"tv":122.1,"id":349}]}]}
{"op":"mcm","clk":"11935916768","pt":1724672128991,"mc":[{"id":"1.232283631","rc":[{"batb":[[0,2.42,11.91],[1,2.36,28.26],[2,1.9,1230.77]],"ltp":2.42,"tv":122.1,"id":349}]}]}
{"op":"mcm","clk":"11935917690","pt":1724672142437,"mc":[{"id":"1.232283631","rc":[{"batb":[[0,2.44,4],[1,2.42,11.91],[2,2.36,28.26]],"ltp":2.42,"tv":122.1,"id":349}]}]}
{"op":"mcm","clk":"11935917821","pt":1724672144637,"mc":[{"id":"1.232283631","rc":[{"batb":[[0,2.42,11.91],[1,2.36,28.26],[2,1.9,1230.77]],"ltp":2.42,"tv":122.1,"id":349}]}]}
{"op":"mcm","clk":"11935918012","pt":1724672147129,"mc":[{"id":"1.232283631","rc":[{"batb":[[0,2.44,4],[1,2.42,11.91],[2,2.36,28.26]],"ltp":2.42,"tv":122.1,"id":349}]}]}
{"op":"mcm","clk":"11935918160","pt":1724672149326,"mc":[{"id":"1.232283631","rc":[{"batb":[[0,2.42,11.91],[1,2.36,28.26],[2,1.9,1230.77]],"ltp":2.42,"tv":122.1,"id":349}]}]}
{"op":"mcm","clk":"11935918399","pt":1724672152806,"mc":[{"id":"1.232283631","rc":[{"batb":[[0,2.44,4],[1,2.42,11.91],[2,2.36,28.26]],"ltp":2.42,"tv":122.1,"id":349}]}]}
{"op":"mcm","clk":"11935918586","pt":1724672155011,"mc":[{"id":"1.232283631","rc":[{"batb":[[0,2.42,11.91],[1,2.36,28.26],[2,1.9,1230.77]],"ltp":2.42,"tv":122.1,"id":349}]}]}
{"op":"mcm","clk":"11935918739","pt":1724672157219,"mc":[{"id":"1.232283631","rc":[{"batb":[[0,2.44,4],[1,2.42,11.91],[2,2.36,28.26]],"ltp":2.42,"tv":122.1,"id":349}]}]}
{"op":"mcm","clk":"11935918865","pt":1724672159428,"mc":[{"id":"1.232283631","rc":[{"batb":[[0,2.42,11.91],[1,2.36,28.26],[2,1.9,1230.77]],"ltp":2.42,"tv":122.1,"id":349}]}]}
{"op":"mcm","clk":"11935919122","pt":1724672162813,"mc":[{"id":"1.232283631","rc":[{"batb":[[0,2.44,4],[1,2.42,11.91],[2,2.36,28.26]],"ltp":2.42,"tv":122.1,"id":349}]}]}
{"op":"mcm","clk":"11935919302","pt":1724672165229,"mc":[{"id":"1.232283631","rc":[{"batb":[[0,2.42,11.91],[1,2.36,28.26],[2,1.9,1230.77]],"ltp":2.42,"tv":122.1,"id":349}]}]}
{"op":"mcm","clk":"11935919677","pt":1724672170051,"mc":[{"id":"1.232283631","rc":[{"batb":[[0,2.44,4],[1,2.42,11.91],[2,2.36,28.26]],"ltp":2.42,"tv":122.1,"id":349}]}]}
{"op":"mcm","clk":"11935919854","pt":1724672172280,"mc":[{"id":"1.232283631","rc":[{"batb":[[0,2.42,11.91],[1,2.36,28.26],[2,1.9,1230.77]],"ltp":2.42,"tv":122.1,"id":349}]}]}
{"op":"mcm","clk":"11935920021","pt":1724672174539,"mc":[{"id":"1.232283631","rc":[{"batb":[[0,2.44,4],[1,2.42,11.91],[2,2.36,28.26]],"ltp":2.42,"tv":122.1,"id":349}]}]}
{"op":"mcm","clk":"11935920207","pt":1724672176963,"mc":[{"id":"1.232283631","rc":[{"batb":[[0,2.42,11.91],[1,2.36,28.26],[2,1.9,1230.77]],"ltp":2.42,"tv":122.1,"id":349}]}]}
{"op":"mcm","clk":"11935920571","pt":1724672181684,"mc":[{"id":"1.232283631","rc":[{"batb":[[0,2.44,4],[1,2.42,11.91],[2,2.36,28.26]],"ltp":2.42,"tv":122.1,"id":349}]}]}
{"op":"mcm","clk":"11935920732","pt":1724672183946,"mc":[{"id":"1.232283631","rc":[{"batb":[[0,2.42,11.91],[1,2.36,28.26],[2,1.9,1230.77]],"ltp":2.42,"tv":122.1,"id":349}]}]}
{"op":"mcm","clk":"11935921313","pt":1724672191403,"mc":[{"id":"1.232283631","rc":[{"batb":[[0,2.44,4],[1,2.42,11.91],[2,2.36,28.26]],"ltp":2.42,"tv":122.1,"id":349}]}]}
{"op":"mcm","clk":"11935921504","pt":1724672193672,"mc":[{"id":"1.232283631","rc":[{"batb":[[0,2.42,11.91],[1,2.36,28.26],[2,1.9,1230.77]],"ltp":2.42,"tv":122.1,"id":349}]}]}
{"op":"mcm","clk":"11935922002","pt":1724672199786,"mc":[{"id":"1.232283631","rc":[{"batb":[[0,2.44,4],[1,2.42,11.91],[2,2.36,28.26]],"ltp":2.42,"tv":122.1,"id":349}]}]}
{"op":"mcm","clk":"11935922178","pt":1724672202298,"mc":[{"id":"1.232283631","rc":[{"batb":[[0,2.42,11.91],[1,2.36,28.26],[2,1.9,1230.77]],"ltp":2.42,"tv":122.1,"id":349}]}]}
{"op":"mcm","clk":"11935922760","pt":1724672209601,"mc":[{"id":"1.232283631","rc":[{"batb":[[0,2.44,4],[1,2.42,11.91],[2,2.36,28.26]],"ltp":2.42,"tv":122.1,"id":349}]}]}
{"op":"mcm","clk":"11935922966","pt":1724672212011,"mc":[{"id":"1.232283631","rc":[{"batb":[[0,2.42,11.91],[1,2.36,28.26],[2,1.9,1230.77]],"ltp":2.42,"tv":122.1,"id":349}]}]}
{"op":"mcm","clk":"11935923283","pt":1724672215870,"mc":[{"id":"1.232283631","rc":[{"batb":[[0,2.44,4],[1,2.42,11.91],[2,2.36,28.26]],"ltp":2.42,"tv":122.1,"id":349}]}]}
{"op":"mcm","clk":"11935923453","pt":1724672218082,"mc":[{"id":"1.232283631","rc":[{"batb":[[0,2.42,11.91],[1,2.36,28.26],[2,1.9,1230.77]],"ltp":2.42,"tv":122.1,"id":349}]}]}
{"op":"mcm","clk":"11935923713","pt":1724672221791,"mc":[{"id":"1.232283631","rc":[{"batb":[[0,2.44,4],[1,2.42,11.91],[2,2.36,28.26]],"ltp":2.42,"tv":122.1,"id":349}]}]}
{"op":"mcm","clk":"11935923904","pt":1724672224418,"mc":[{"id":"1.232283631","rc":[{"batb":[[0,2.42,11.91],[1,2.36,28.26],[2,1.9,1230.77]],"ltp":2.42,"tv":122.1,"id":349}]}]}
{"op":"mcm","clk":"11935924698","pt":1724672235192,"mc":[{"id":"1.232283631","rc":[{"batb":[[0,2.44,4],[1,2.42,11.91],[2,2.36,28.26]],"ltp":2.42,"tv":122.1,"id":349}]}]}
{"op":"mcm","clk":"11935924855","pt":1724672237411,"mc":[{"id":"1.232283631","rc":[{"batb":[[0,2.42,11.91],[1,2.36,28.26],[2,1.9,1230.77]],"ltp":2.42,"tv":122.1,"id":349}]}]}
{"op":"mcm","clk":"11935925037","pt":1724672239826,"mc":[{"id":"1.232283631","rc":[{"batb":[[0,2.44,4],[1,2.42,11.91],[2,2.36,28.26]],"ltp":2.42,"tv":122.1,"id":349}]}]}
{"op":"mcm","clk":"11935925217","pt":1724672242031,"mc":[{"id":"1.232283631","rc":[{"batb":[[0,2.42,11.91],[1,2.36,28.26],[2,1.9,1230.77]],"ltp":2.42,"tv":122.1,"id":349}]}]}
{"op":"mcm","clk":"11935925441","pt":1724672244618,"mc":[{"id":"1.232283631","rc":[{"batb":[[0,2.44,4],[1,2.42,11.91],[2,2.36,28.26]],"ltp":2.42,"tv":122.1,"id":349}]}]}
{"op":"mcm","clk":"11935925648","pt":1724672246939,"mc":[{"id":"1.232283631","rc":[{"batb":[[0,2.42,11.91],[1,2.36,28.26],[2,1.9,1230.77]],"ltp":2.42,"tv":122.1,"id":349}]}]}
{"op":"mcm","clk":"11935925893","pt":1724672249748,"mc":[{"id":"1.232283631","rc":[{"batb":[[0,2.44,4],[1,2.42,11.91],[2,2.36,28.26]],"ltp":2.42,"tv":122.1,"id":349}]}]}
{"op":"mcm","clk":"11935926057","pt":1724672251963,"mc":[{"id":"1.232283631","rc":[{"batb":[[0,2.42,11.91],[1,2.36,28.26],[2,1.9,1230.77]],"ltp":2.42,"tv":122.1,"id":349}]}]}
{"op":"mcm","clk":"11935926342","pt":1724672255419,"mc":[{"id":"1.232283631","rc":[{"batb":[[0,2.44,4],[1,2.42,11.91],[2,2.36,28.26]],"ltp":2.42,"tv":122.1,"id":349}]}]}
{"op":"mcm","clk":"11935926531","pt":1724672257645,"mc":[{"id":"1.232283631","rc":[{"batb":[[0,2.42,11.91],[1,2.36,28.26],[2,1.9,1230.77]],"ltp":2.42,"tv":122.1,"id":349}]}]}
{"op":"mcm","clk":"11935927432","pt":1724672268244,"mc":[{"id":"1.232283631","rc":[{"batb":[[0,2.44,4],[1,2.42,11.91],[2,2.36,28.26]],"ltp":2.42,"tv":122.1,"id":349}]}]}
{"op":"mcm","clk":"11935927589","pt":1724672270462,"mc":[{"id":"1.232283631","rc":[{"batb":[[0,2.42,11.91],[1,2.36,28.26],[2,1.9,1230.77]],"ltp":2.42,"tv":122.1,"id":349}]}]}
{"op":"mcm","clk":"11935927771","pt":1724672272759,"mc":[{"id":"1.232283631","rc":[{"batb":[[0,2.44,4],[1,2.42,11.91],[2,2.36,28.26]],"ltp":2.42,"tv":122.1,"id":349}]}]}
{"op":"mcm","clk":"11935927931","pt":1724672275083,"mc":[{"id":"1.232283631","rc":[{"batb":[[0,2.42,11.91],[1,2.36,28.26],[2,1.9,1230.77]],"ltp":2.42,"tv":122.1,"id":349}]}]}
{"op":"mcm","clk":"11935928233","pt":1724672278694,"mc":[{"id":"1.232283631","rc":[{"batb":[[0,2.44,4],[1,2.42,11.91],[2,2.36,28.26]],"ltp":2.42,"tv":122.1,"id":349}]}]}
{"op":"mcm","clk":"11935928442","pt":1724672281036,"mc":[{"id":"1.232283631","rc":[{"batb":[[0,2.42,11.91],[1,2.36,28.26],[2,1.9,1230.77]],"ltp":2.42,"tv":122.1,"id":349}]}]}
{"op":"mcm","clk":"11935928976","pt":1724672287002,"mc":[{"id":"1.232283631","rc":[{"batb":[[0,2.44,4],[1,2.42,11.91],[2,2.36,28.26]],"ltp":2.42,"tv":122.1,"id":349},{"batl":[[0,1.7,2903.24],[1,1.71,12692.24],[2,1.72,246.15]],"ltp":1.71,"tv":118.53,"id":235}]}]}
{"op":"mcm","clk":"11935929164","pt":1724672289178,"mc":[{"id":"1.232283631","rc":[{"batb":[[0,2.42,11.91],[1,2.36,28.26],[2,1.9,1230.77]],"ltp":2.42,"tv":122.1,"id":349}]}]}
{"op":"mcm","clk":"11935929360","pt":1724672291568,"mc":[{"id":"1.232283631","rc":[{"batb":[[0,2.44,4],[1,2.42,11.91],[2,2.36,28.26]],"ltp":2.42,"tv":122.1,"id":349}]}]}
{"op":"mcm","clk":"11935929509","pt":1724672293788,"mc":[{"id":"1.232283631","rc":[{"batb":[[0,2.42,11.91],[1,2.36,28.26],[2,1.9,1230.77]],"ltp":2.42,"tv":122.1,"id":349}]}]}
{"op":"mcm","clk":"11935929885","pt":1724672298484,"mc":[{"id":"1.232283631","rc":[{"batb":[[0,2.44,4],[1,2.42,11.91],[2,2.36,28.26]],"ltp":2.42,"tv":122.1,"id":349}]}]}
{"op":"mcm","clk":"11935930090","pt":1724672300691,"mc":[{"id":"1.232283631","rc":[{"batb":[[0,2.42,11.91],[1,2.36,28.26],[2,1.9,1230.77]],"ltp":2.42,"tv":122.1,"id":349}]}]}
{"op":"mcm","clk":"11935930193","pt":1724672302083,"mc":[{"id":"1.232283631","rc":[{"batb":[[0,2.42,945.13]],"ltp":2.42,"tv":122.1,"id":349}]}]}
{"op":"mcm","clk":"11935930422","pt":1724672304879,"mc":[{"id":"1.232283631","rc":[{"batb":[[0,2.44,4],[1,2.42,945.13],[2,2.36,28.26]],"ltp":2.42,"tv":122.1,"id":349}]}]}
{"op":"mcm","clk":"11935930605","pt":1724672307196,"mc":[{"id":"1.232283631","rc":[{"batb":[[0,2.42,945.13],[1,2.36,28.26],[2,1.9,1230.77]],"ltp":2.42,"tv":122.1,"id":349}]}]}
{"op":"mcm","clk":"11935930960","pt":1724672311007,"mc":[{"id":"1.232283631","rc":[{"batb":[[0,2.44,4],[1,2.42,945.13],[2,2.36,28.26]],"ltp":2.42,"tv":122.1,"id":349}]}]}
{"op":"mcm","clk":"11935931177","pt":1724672313428,"mc":[{"id":"1.232283631","rc":[{"batb":[[0,2.42,945.13],[1,2.36,28.26],[2,1.9,1230.77]],"ltp":2.42,"tv":122.1,"id":349}]}]}
{"op":"mcm","clk":"11935931734","pt":1724672319812,"mc":[{"id":"1.232283631","rc":[{"batb":[[0,2.44,4],[1,2.42,945.13],[2,2.36,28.26]],"ltp":2.42,"tv":122.1,"id":349}]}]}
{"op":"mcm","clk":"11935931927","pt":1724672322266,"mc":[{"id":"1.232283631","rc":[{"batb":[[0,2.42,945.13],[1,2.36,28.26],[2,1.9,1230.77]],"ltp":2.42,"tv":122.1,"id":349}]}]}
{"op":"mcm","clk":"11935932125","pt":1724672324897,"mc":[{"id":"1.232283631","rc":[{"batb":[[0,2.44,4],[1,2.42,945.13],[2,2.36,28.26]],"ltp":2.42,"tv":122.1,"id":349}]}]}
{"op":"mcm","clk":"11935932265","pt":1724672326797,"mc":[{"id":"1.232283631","rc":[{"batb":[[0,1.66,933.22],[1,1.65,31.52],[2,1.64,262.54]],"ltp":1.71,"tv":118.53,"id":235}]}]}
{"op":"mcm","clk":"11935932319","pt":1724672327513,"mc":[{"id":"1.232283631","rc":[{"batb":[[0,2.42,945.13],[1,2.36,28.26],[2,1.9,1230.77]],"ltp":2.42,"tv":122.1,"id":349},{"batb":[[0,1.67,17.26],[1,1.66,933.22],[2,1.65,4]],"ltp":1.71,"tv":118.53,"id":235}]}]}
{"op":"mcm","clk":"11935932482","pt":1724672329516,"mc":[{"id":"1.232283631","rc":[{"batb":[[0,2.44,4],[1,2.42,945.13],[2,2.36,28.26]],"ltp":2.42,"tv":122.1,"id":349}]}]}
{"op":"mcm","clk":"11935932625","pt":1724672331820,"mc":[{"id":"1.232283631","rc":[{"batb":[[0,2.42,945.13],[1,2.36,28.26],[2,1.9,1230.77]],"ltp":2.42,"tv":122.1,"id":349}]}]}
{"op":"mcm","clk":"11935932826","pt":1724672334642,"mc":[{"id":"1.232283631","rc":[{"batb":[[0,2.44,4],[1,2.42,945.13],[2,2.36,28.26]],"ltp":2.42,"tv":122.1,"id":349}]}]}
{"op":"mcm","clk":"11935932980","pt":1724672336906,"mc":[{"id":"1.232283631","rc":[{"batb":[[0,2.42,945.13],[1,2.36,28.26],[2,1.9,1230.77]],"ltp":2.42,"tv":122.1,"id":349}]}]}
{"op":"mcm","clk":"11935933330","pt":1724672340853,"mc":[{"id":"1.232283631","rc":[{"batb":[[0,2.44,4],[1,2.42,945.13],[2,2.36,28.26]],"ltp":2.42,"tv":122.1,"id":349},{"batb":[[2,1.65,937.22]],"ltp":1.71,"tv":118.53,"id":235}]}]}
{"op":"mcm","clk":"11935933524","pt":1724672343029,"mc":[{"id":"1.232283631","rc":[{"batb":[[0,2.42,945.13],[1,2.36,28.26],[2,1.9,1230.77]],"ltp":2.42,"tv":122.1,"id":349}]}]}
{"op":"mcm","clk":"11935933749","pt":1724672345654,"mc":[{"id":"1.232283631","rc":[{"batb":[[0,2.44,4],[1,2.42,945.13],[2,2.36,28.26]],"ltp":2.42,"tv":122.1,"id":349}]}]}
{"op":"mcm","clk":"11935933927","pt":1724672347827,"mc":[{"id":"1.232283631","rc":[{"batb":[[0,2.42,945.13],[1,2.36,28.26],[2,1.9,1230.77]],"ltp":2.42,"tv":122.1,"id":349}]}]}
{"op":"mcm","clk":"11935934344","pt":1724672352759,"mc":[{"id":"1.232283631","rc":[{"batb":[[0,2.44,4],[1,2.42,945.13],[2,2.36,28.26]],"ltp":2.42,"tv":122.1,"id":349}]}]}
{"op":"mcm","clk":"11935934499","pt":1724672354860,"mc":[{"id":"1.232283631","rc":[{"batb":[[0,2.42,945.13],[1,2.36,28.26],[2,1.9,1230.77]],"ltp":2.42,"tv":122.1,"id":349}]}]}
{"op":"mcm","clk":"11935934658","pt":1724672357030,"mc":[{"id":"1.232283631","rc":[{"batb":[[0,2.44,4],[1,2.42,945.13],[2,2.36,28.26]],"ltp":2.42,"tv":122.1,"id":349}]}]}
{"op":"mcm","clk":"11935934851","pt":1724672359348,"mc":[{"id":"1.232283631","rc":[{"batb":[[0,2.42,945.13],[1,2.36,28.26],[2,1.9,1230.77]],"ltp":2.42,"tv":122.1,"id":349}]}]}
{"op":"mcm","clk":"11935935116","pt":1724672362635,"mc":[{"id":"1.232283631","rc":[{"batb":[[0,2.44,4],[1,2.42,945.13],[2,2.36,28.26]],"ltp":2.42,"tv":122.1,"id":349}]}]}
{"op":"mcm","clk":"11935935281","pt":1724672364745,"mc":[{"id":"1.232283631","rc":[{"batb":[[0,2.42,945.13],[1,2.36,28.26],[2,1.9,1230.77]],"ltp":2.42,"tv":122.1,"id":349}]}]}
{"op":"mcm","clk":"11935935565","pt":1724672368480,"mc":[{"id":"1.232283631","rc":[{"batb":[[0,2.44,4],[1,2.42,945.13],[2,2.36,28.26]],"ltp":2.42,"tv":122.1,"id":349}]}]}
{"op":"mcm","clk":"11935935721","pt":1724672370745,"mc":[{"id":"1.232283631","rc":[{"batb":[[0,2.42,945.13],[1,2.36,28.26],[2,1.9,1230.77]],"ltp":2.42,"tv":122.1,"id":349}]}]}
{"op":"mcm","clk":"11935935978","pt":1724672374186,"mc":[{"id":"1.232283631","rc":[{"batb":[[0,2.44,4],[1,2.42,945.13],[2,2.36,28.26]],"ltp":2.42,"tv":122.1,"id":349}]}]}
{"op":"mcm","clk":"11935936178","pt":1724672376556,"mc":[{"id":"1.232283631","rc":[{"batb":[[0,2.42,945.13],[1,2.36,28.26],[2,1.9,1230.77]],"ltp":2.42,"tv":122.1,"id":349}]}]}
{"op":"mcm","clk":"11935936595","pt":1724672381866,"mc":[{"id":"1.232283631","rc":[{"batb":[[0,2.44,4],[1,2.42,945.13],[2,2.36,28.26]],"ltp":2.42,"tv":122.1,"id":349}]}]}
{"op":"mcm","clk":"11935936790","pt":1724672384184,"mc":[{"id":"1.232283631","rc":[{"batb":[[0,2.42,945.13],[1,2.36,28.26],[2,1.9,1230.77]],"ltp":2.42,"tv":122.1,"id":349}]}]}
{"op":"mcm","clk":"11935937027","pt":1724672387267,"mc":[{"id":"1.232283631","rc":[{"batb":[[0,2.44,4],[1,2.42,945.13],[2,2.36,28.26]],"ltp":2.42,"tv":122.1,"id":349}]}]}
{"op":"mcm","clk":"11935937173","pt":1724672389377,"mc":[{"id":"1.232283631","rc":[{"batb":[[0,2.42,945.13],[1,2.36,28.26],[2,1.9,1230.77]],"ltp":2.42,"tv":122.1,"id":349}]}]}
{"op":"mcm","clk":"11935937461","pt":1724672394011,"mc":[{"id":"1.232283631","rc":[{"batb":[[0,2.44,4],[1,2.42,945.13],[2,2.36,28.26]],"ltp":2.42,"tv":122.1,"id":349}]}]}
{"op":"mcm","clk":"11935937624","pt":1724672396285,"mc":[{"id":"1.232283631","rc":[{"batb":[[0,2.42,945.13],[1,2.36,28.26],[2,1.9,1230.77]],"ltp":2.42,"tv":122.1,"id":349}]}]}
{"op":"mcm","clk":"11935937919","pt":1724672400312,"mc":[{"id":"1.232283631","rc":[{"batb":[[0,2.44,4],[1,2.42,945.13],[2,2.36,28.26]],"ltp":2.42,"tv":122.1,"id":349}]}]}
{"op":"mcm","clk":"11935938074","pt":1724672402489,"mc":[{"id":"1.232283631","rc":[{"batb":[[0,2.42,945.13],[1,2.36,28.26],[2,1.9,1230.77]],"ltp":2.42,"tv":122.1,"id":349}]}]}
{"op":"mcm","clk":"11935938463","pt":1724672407489,"mc":[{"id":"1.232283631","rc":[{"batb":[[0,2.44,4],[1,2.42,945.13],[2,2.36,28.26]],"ltp":2.42,"tv":122.1,"id":349}]}]}
{"op":"mcm","clk":"11935938656","pt":1724672409905,"mc":[{"id":"1.232283631","rc":[{"batb":[[0,2.42,945.13],[1,2.36,28.26],[2,1.9,1230.77]],"ltp":2.42,"tv":122.1,"id":349}]}]}
{"op":"mcm","clk":"11935939520","pt":1724672421432,"mc":[{"id":"1.232283631","rc":[{"batb":[[0,2.44,4],[1,2.42,945.13],[2,2.36,28.26]],"ltp":2.42,"tv":122.1,"id":349}]}]}
{"op":"mcm","clk":"11935939712","pt":1724672423807,"mc":[{"id":"1.232283631","rc":[{"batb":[[0,2.42,945.13],[1,2.36,28.26],[2,1.9,1230.77]],"ltp":2.42,"tv":122.1,"id":349}]}]}
{"op":"mcm","clk":"11935940129","pt":1724672429837,"mc":[{"id":"1.232283631","rc":[{"batb":[[0,2.44,4],[1,2.42,945.13],[2,2.36,28.26]],"ltp":2.42,"tv":122.1,"id":349}]}]}
{"op":"mcm","clk":"11935940263","pt":1724672432113,"mc":[{"id":"1.232283631","rc":[{"batb":[[0,2.42,945.13],[1,2.36,28.26],[2,1.9,1230.77]],"ltp":2.42,"tv":122.1,"id":349}]}]}
{"op":"mcm","clk":"11935940421","pt":1724672434631,"mc":[{"id":"1.232283631","rc":[{"batb":[[0,2.44,4],[1,2.42,945.13],[2,2.36,28.26]],"ltp":2.42,"tv":122.1,"id":349}]}]}
{"op":"mcm","clk":"11935940561","pt":1724672436841,"mc":[{"id":"1.232283631","rc":[{"batb":[[0,2.42,945.13],[1,2.36,28.26],[2,1.9,1230.77]],"ltp":2.42,"tv":122.1,"id":349}]}]}
{"op":"mcm","clk":"11935940720","pt":1724672439329,"mc":[{"id":"1.232283631","rc":[{"batb":[[0,2.44,4],[1,2.42,945.13],[2,2.36,28.26]],"ltp":2.42,"tv":122.1,"id":349}]}]}
{"op":"mcm","clk":"11935940899","pt":1724672441652,"mc":[{"id":"1.232283631","rc":[{"batb":[[0,2.42,945.13],[1,2.36,28.26],[2,1.9,1230.77]],"ltp":2.42,"tv":122.1,"id":349}]}]}
{"op":"mcm","clk":"11935941099","pt":1724672443850,"mc":[{"id":"1.232283631","rc":[{"batb":[[0,2.44,4],[1,2.42,945.13],[2,2.36,28.26]],"ltp":2.42,"tv":122.1,"id":349}]}]}
{"op":"mcm","clk":"11935941295","pt":1724672446130,"mc":[{"id":"1.232283631","rc":[{"batb":[[0,2.42,945.13],[1,2.36,28.26],[2,1.9,1230.77]],"ltp":2.42,"tv":122.1,"id":349}]}]}
{"op":"mcm","clk":"11935941775","pt":1724672452148,"mc":[{"id":"1.232283631","rc":[{"batb":[[0,2.44,4],[1,2.42,945.13],[2,2.36,28.26]],"ltp":2.42,"tv":122.1,"id":349}]}]}
{"op":"mcm","clk":"11935941934","pt":1724672454360,"mc":[{"id":"1.232283631","rc":[{"batb":[[0,2.42,945.13],[1,2.36,28.26],[2,1.9,1230.77]],"ltp":2.42,"tv":122.1,"id":349}]}]}
{"op":"mcm","clk":"11935942660","pt":1724672463672,"mc":[{"id":"1.232283631","rc":[{"batb":[[0,2.44,4],[1,2.42,945.13],[2,2.36,28.26]],"ltp":2.42,"tv":122.1,"id":349}]}]}
{"op":"mcm","clk":"11935942848","pt":1724672465855,"mc":[{"id":"1.232283631","rc":[{"batb":[[0,2.42,945.13],[1,2.36,28.26],[2,1.9,1230.77]],"ltp":2.42,"tv":122.1,"id":349}]}]}
{"op":"mcm","clk":"11935943792","pt":1724672478077,"mc":[{"id":"1.232283631","rc":[{"batb":[[0,2.44,4],[1,2.42,945.13],[2,2.36,28.26]],"ltp":2.42,"tv":122.1,"id":349}]}]}
{"op":"mcm","clk":"11935943942","pt":1724672480286,"mc":[{"id":"1.232283631","rc":[{"batb":[[0,2.42,945.13],[1,2.36,28.26],[2,1.9,1230.77]],"ltp":2.42,"tv":122.1,"id":349}]}]}
{"op":"mcm","clk":"11935944092","pt":1724672482566,"mc":[{"id":"1.232283631","rc":[{"batb":[[0,2.44,4],[1,2.42,945.13],[2,2.36,28.26]],"ltp":2.42,"tv":122.1,"id":349}]}]}
{"op":"mcm","clk":"11935944227","pt":1724672484984,"mc":[{"id":"1.232283631","rc":[{"batb":[[0,2.42,945.13],[1,2.36,28.26],[2,1.9,1230.77]],"ltp":2.42,"tv":122.1,"id":349}]}]}
{"op":"mcm","clk":"11935944471","pt":1724672488587,"mc":[{"id":"1.232283631","rc":[{"batb":[[0,2.44,4],[1,2.42,945.13],[2,2.36,28.26]],"ltp":2.42,"tv":122.1,"id":349}]}]}
{"op":"mcm","clk":"11935944641","pt":1724672490806,"mc":[{"id":"1.232283631","rc":[{"batb":[[0,2.42,945.13],[1,2.36,28.26],[2,1.9,1230.77]],"ltp":2.42,"tv":122.1,"id":349}]}]}
{"op":"mcm","clk":"11935944960","pt":1724672495397,"mc":[{"id":"1.232283631","rc":[{"batb":[[0,2.44,4],[1,2.42,945.13],[2,2.36,28.26]],"ltp":2.42,"tv":122.1,"id":349}]}]}
{"op":"mcm","clk":"11935945135","pt":1724672497711,"mc":[{"id":"1.232283631","rc":[{"batb":[[0,2.42,945.13],[1,2.36,28.26],[2,1.9,1230.77]],"ltp":2.42,"tv":122.1,"id":349}]}]}
{"op":"mcm","clk":"11935945737","pt":1724672505289,"mc":[{"id":"1.232283631","rc":[{"batb":[[0,2.44,4],[1,2.42,945.13],[2,2.36,28.26]],"ltp":2.42,"tv":122.1,"id":349}]}]}
{"op":"mcm","clk":"11935945929","pt":1724672507723,"mc":[{"id":"1.232283631","rc":[{"batb":[[0,2.42,945.13],[1,2.36,28.26],[2,1.9,1230.77]],"ltp":2.42,"tv":122.1,"id":349}]}]}
{"op":"mcm","clk":"11935946200","pt":1724672511121,"mc":[{"id":"1.232283631","rc":[{"batb":[[0,2.44,4],[1,2.42,945.13],[2,2.36,28.26]],"ltp":2.42,"tv":122.1,"id":349}]}]}
{"op":"mcm","clk":"11935946415","pt":1724672513505,"mc":[{"id":"1.232283631","rc":[{"batb":[[0,2.42,945.13],[1,2.36,28.26],[2,1.9,1230.77]],"ltp":2.42,"tv":122.1,"id":349}]}]}
{"op":"mcm","clk":"11935947015","pt":1724672520843,"mc":[{"id":"1.232283631","rc":[{"batb":[[0,2.44,4],[1,2.42,945.13],[2,2.36,28.26]],"ltp":2.42,"tv":122.1,"id":349}]}]}
{"op":"mcm","clk":"11935947183","pt":1724672523012,"mc":[{"id":"1.232283631","rc":[{"batb":[[0,2.42,945.13],[1,2.36,28.26],[2,1.9,1230.77]],"ltp":2.42,"tv":122.1,"id":349}]}]}
{"op":"mcm","clk":"11935947473","pt":1724672526686,"mc":[{"id":"1.232283631","rc":[{"batb":[[0,2.44,4],[1,2.42,945.13],[2,2.36,28.26]],"ltp":2.42,"tv":122.1,"id":349}]}]}
{"op":"mcm","clk":"11935947621","pt":1724672528819,"mc":[{"id":"1.232283631","rc":[{"batb":[[0,2.42,945.13],[1,2.36,28.26],[2,1.9,1230.77]],"ltp":2.42,"tv":122.1,"id":349}]}]}
{"op":"mcm","clk":"11935947781","pt":1724672531336,"mc":[{"id":"1.232283631","rc":[{"batb":[[0,2.44,4],[1,2.42,945.13],[2,2.36,28.26]],"ltp":2.42,"tv":122.1,"id":349}]}]}
{"op":"mcm","clk":"11935947970","pt":1724672533852,"mc":[{"id":"1.232283631","rc":[{"batb":[[0,2.42,945.13],[1,2.36,28.26],[2,1.9,1230.77]],"ltp":2.42,"tv":122.1,"id":349}]}]}
{"op":"mcm","clk":"11935948107","pt":1724672536113,"mc":[{"id":"1.232283631","rc":[{"batb":[[0,2.44,4],[1,2.42,945.13],[2,2.36,28.26]],"ltp":2.42,"tv":122.1,"id":349}]}]}
{"op":"mcm","clk":"11935948273","pt":1724672538528,"mc":[{"id":"1.232283631","rc":[{"batb":[[0,2.42,945.13],[1,2.36,28.26],[2,1.9,1230.77]],"ltp":2.42,"tv":122.1,"id":349}]}]}
{"op":"mcm","clk":"11935948532","pt":1724672542256,"mc":[{"id":"1.232283631","rc":[{"batb":[[0,2.44,4],[1,2.42,945.13],[2,2.36,28.26]],"ltp":2.42,"tv":122.1,"id":349}]}]}
{"op":"mcm","clk":"11935948704","pt":1724672544629,"mc":[{"id":"1.232283631","rc":[{"batb":[[0,2.42,945.13],[1,2.36,28.26],[2,1.9,1230.77]],"ltp":2.42,"tv":122.1,"id":349}]}]}
{"op":"mcm","clk":"11935949194","pt":1724672552156,"mc":[{"id":"1.232283631","rc":[{"batb":[[0,2.44,4],[1,2.42,945.13],[2,2.36,28.26]],"ltp":2.42,"tv":122.1,"id":349}]}]}
{"op":"mcm","clk":"11935949347","pt":1724672554468,"mc":[{"id":"1.232283631","rc":[{"batb":[[0,2.42,945.13],[1,2.36,28.26],[2,1.9,1230.77]],"ltp":2.42,"tv":122.1,"id":349}]}]}
{"op":"mcm","clk":"11935949782","pt":1724672560639,"mc":[{"id":"1.232283631","rc":[{"batb":[[0,2.44,4],[1,2.42,945.13],[2,2.36,28.26]],"ltp":2.42,"tv":122.1,"id":349}]}]}
{"op":"mcm","clk":"11935949949","pt":1724672563153,"mc":[{"id":"1.232283631","rc":[{"batb":[[0,2.42,945.13],[1,2.36,28.26],[2,1.9,1230.77]],"ltp":2.42,"tv":122.1,"id":349}]}]}
{"op":"mcm","clk":"11935950218","pt":1724672566650,"mc":[{"id":"1.232283631","rc":[{"batb":[[0,2.44,4],[1,2.42,945.13],[2,2.36,28.26]],"ltp":2.42,"tv":122.1,"id":349}]}]}
{"op":"mcm","clk":"11935950367","pt":1724672568964,"mc":[{"id":"1.232283631","rc":[{"batb":[[0,2.42,945.13],[1,2.36,28.26],[2,1.9,1230.77]],"ltp":2.42,"tv":122.1,"id":349}]}]}
{"op":"mcm","clk":"11935950587","pt":1724672572195,"mc":[{"id":"1.232283631","rc":[{"batb":[[0,2.44,4],[1,2.42,945.13],[2,2.36,28.26]],"ltp":2.42,"tv":122.1,"id":349}]}]}
{"op":"mcm","clk":"11935950746","pt":1724672574558,"mc":[{"id":"1.232283631","rc":[{"batb":[[0,2.42,945.13],[1,2.36,28.26],[2,1.9,1230.77]],"ltp":2.42,"tv":122.1,"id":349}]}]}
{"op":"mcm","clk":"11935951491","pt":1724672584572,"mc":[{"id":"1.232283631","rc":[{"batb":[[0,2.44,4],[1,2.42,945.13],[2,2.36,28.26]],"ltp":2.42,"tv":122.1,"id":349}]}]}
{"op":"mcm","clk":"11935951664","pt":1724672586782,"mc":[{"id":"1.232283631","rc":[{"batb":[[0,2.42,945.13],[1,2.36,28.26],[2,1.9,1230.77]],"ltp":2.42,"tv":122.1,"id":349}]}]}
{"op":"mcm","clk":"11935951892","pt":1724672589098,"mc":[{"id":"1.232283631","rc":[{"batb":[[0,2.44,4],[1,2.42,945.13],[2,2.36,28.26]],"ltp":2.42,"tv":122.1,"id":349}]}]}
{"op":"mcm","clk":"11935952085","pt":1724672591466,"mc":[{"id":"1.232283631","rc":[{"batb":[[0,2.42,945.13],[1,2.36,28.26],[2,1.9,1230.77]],"ltp":2.42,"tv":122.1,"id":349}]}]}
{"op":"mcm","clk":"11935952327","pt":1724672594807,"mc":[{"id":"1.232283631","rc":[{"batb":[[0,2.44,4],[1,2.42,945.13],[2,2.36,28.26]],"ltp":2.42,"tv":122.1,"id":349}]}]}
{"op":"mcm","clk":"11935952531","pt":1724672597275,"mc":[{"id":"1.232283631","rc":[{"batb":[[0,2.42,945.13],[1,2.36,28.26],[2,1.9,1230.77]],"ltp":2.42,"tv":122.1,"id":349}]}]}
{"op":"mcm","clk":"11935952797","pt":1724672600522,"mc":[{"id":"1.232283631","rc":[{"batb":[[0,2.44,4],[1,2.42,945.13],[2,2.36,28.26]],"ltp":2.42,"tv":122.1,"id":349}]}]}
{"op":"mcm","clk":"11935952988","pt":1724672602994,"mc":[{"id":"1.232283631","rc":[{"batb":[[0,2.42,945.13],[1,2.36,28.26],[2,1.9,1230.77]],"ltp":2.42,"tv":122.1,"id":349}]}]}
{"op":"mcm","clk":"11935953441","pt":1724672608987,"mc":[{"id":"1.232283631","rc":[{"batb":[[0,2.44,4],[1,2.42,945.13],[2,2.36,28.26]],"ltp":2.42,"tv":122.1,"id":349}]}]}
{"op":"mcm","clk":"11935953600","pt":1724672611294,"mc":[{"id":"1.232283631","rc":[{"batb":[[0,2.42,945.13],[1,2.36,28.26],[2,1.9,1230.77]],"ltp":2.42,"tv":122.1,"id":349}]}]}
{"op":"mcm","clk":"11935953751","pt":1724672613604,"mc":[{"id":"1.232283631","rc":[{"batb":[[0,2.44,4],[1,2.42,945.13],[2,2.36,28.26]],"ltp":2.42,"tv":122.1,"id":349}]}]}
{"op":"mcm","clk":"11935953886","pt":1724672615820,"mc":[{"id":"1.232283631","rc":[{"batb":[[0,2.42,945.13],[1,2.36,28.26],[2,1.9,1230.77]],"ltp":2.42,"tv":122.1,"id":349}]}]}
{"op":"mcm","clk":"11935954161","pt":1724672618700,"mc":[{"id":"1.232283631","rc":[{"batb":[[0,2.44,4],[1,2.42,945.13],[2,2.36,28.26]],"ltp":2.42,"tv":122.1,"id":349}]}]}
{"op":"mcm","clk":"11935954341","pt":1724672621027,"mc":[{"id":"1.232283631","rc":[{"batb":[[0,2.42,945.13],[1,2.36,28.26],[2,1.9,1230.77]],"ltp":2.42,"tv":122.1,"id":349}]}]}
{"op":"mcm","clk":"11935954843","pt":1724672627929,"mc":[{"id":"1.232283631","rc":[{"batb":[[0,2.44,4],[1,2.42,945.13],[2,2.36,28.26]],"ltp":2.42,"tv":122.1,"id":349}]}]}
{"op":"mcm","clk":"11935955000","pt":1724672630145,"mc":[{"id":"1.232283631","rc":[{"batb":[[0,2.42,945.13],[1,2.36,28.26],[2,1.9,1230.77]],"ltp":2.42,"tv":122.1,"id":349}]}]}
{"op":"mcm","clk":"11935955303","pt":1724672633815,"mc":[{"id":"1.232283631","rc":[{"batb":[[0,2.44,4],[1,2.42,945.13],[2,2.36,28.26]],"ltp":2.42,"tv":122.1,"id":349}]}]}
{"op":"mcm","clk":"11935955462","pt":1724672636235,"mc":[{"id":"1.232283631","rc":[{"batb":[[0,2.42,945.13],[1,2.36,28.26],[2,1.9,1230.77]],"ltp":2.42,"tv":122.1,"id":349}]}]}
{"op":"mcm","clk":"11935956142","pt":1724672644372,"mc":[{"id":"1.232283631","rc":[{"batb":[[0,2.44,4],[1,2.42,945.13],[2,2.36,28.26]],"ltp":2.42,"tv":122.1,"id":349}]}]}
{"op":"mcm","clk":"11935956365","pt":1724672647055,"mc":[{"id":"1.232283631","rc":[{"batb":[[0,2.42,945.13],[1,2.36,28.26],[2,1.9,1230.77]],"ltp":2.42,"tv":122.1,"id":349}]}]}
{"op":"mcm","clk":"11935956675","pt":1724672650413,"mc":[{"id":"1.232283631","rc":[{"batb":[[0,2.44,4],[1,2.42,945.13],[2,2.36,28.26]],"ltp":2.42,"tv":122.1,"id":349}]}]}
{"op":"mcm","clk":"11935956838","pt":1724672652672,"mc":[{"id":"1.232283631","rc":[{"batb":[[0,2.42,945.13],[1,2.36,28.26],[2,1.9,1230.77]],"ltp":2.42,"tv":122.1,"id":349}]}]}
{"op":"mcm","clk":"11935957506","pt":1724672661873,"mc":[{"id":"1.232283631","rc":[{"batb":[[0,2.44,4],[1,2.42,945.13],[2,2.36,28.26]],"ltp":2.42,"tv":122.1,"id":349}]}]}
{"op":"mcm","clk":"11935957674","pt":1724672664187,"mc":[{"id":"1.232283631","rc":[{"batb":[[0,2.42,945.13],[1,2.36,28.26],[2,1.9,1230.77]],"ltp":2.42,"tv":122.1,"id":349}]}]}
{"op":"mcm","clk":"11935958127","pt":1724672670790,"mc":[{"id":"1.232283631","rc":[{"batb":[[0,2.44,4],[1,2.42,945.13],[2,2.36,28.26]],"ltp":2.42,"tv":122.1,"id":349}]}]}
{"op":"mcm","clk":"11935958345","pt":1724672673160,"mc":[{"id":"1.232283631","rc":[{"batb":[[0,2.42,945.13],[1,2.36,28.26],[2,1.9,1230.77]],"ltp":2.42,"tv":122.1,"id":349}]}]}
{"op":"mcm","clk":"11935960299","pt":1724672696911,"mc":[{"id":"1.232283631","rc":[{"batb":[[0,2.44,4],[1,2.42,945.13],[2,2.36,28.26]],"ltp":2.42,"tv":122.1,"id":349}]}]}
{"op":"mcm","clk":"11935960488","pt":1724672699430,"mc":[{"id":"1.232283631","rc":[{"batb":[[0,2.42,945.13],[1,2.36,28.26],[2,1.9,1230.77]],"ltp":2.42,"tv":122.1,"id":349}]}]}
{"op":"mcm","clk":"11935960707","pt":1724672701810,"mc":[{"id":"1.232283631","rc":[{"batb":[[0,2.44,4],[1,2.42,945.13],[2,2.36,28.26]],"ltp":2.42,"tv":122.1,"id":349}]}]}
{"op":"mcm","clk":"11935960923","pt":1724672704127,"mc":[{"id":"1.232283631","rc":[{"batb":[[0,2.42,945.13],[1,2.36,28.26],[2,1.9,1230.77]],"ltp":2.42,"tv":122.1,"id":349}]}]}
{"op":"mcm","clk":"11935961548","pt":1724672712110,"mc":[{"id":"1.232283631","rc":[{"batb":[[0,2.44,4],[1,2.42,945.13],[2,2.36,28.26]],"ltp":2.42,"tv":122.1,"id":349}]}]}
{"op":"mcm","clk":"11935961777","pt":1724672714539,"mc":[{"id":"1.232283631","rc":[{"batb":[[0,2.42,945.13],[1,2.36,28.26],[2,1.9,1230.77]],"ltp":2.42,"tv":122.1,"id":349}]}]}
{"op":"mcm","clk":"11935962021","pt":1724672717048,"mc":[{"id":"1.232283631","rc":[{"batb":[[0,2.44,4],[1,2.42,945.13],[2,2.36,28.26]],"ltp":2.42,"tv":122.1,"id":349}]}]}
{"op":"mcm","clk":"11935962328","pt":1724672719417,"mc":[{"id":"1.232283631","rc":[{"batb":[[0,2.42,945.13],[1,2.36,28.26],[2,1.9,1230.77]],"ltp":2.42,"tv":122.1,"id":349}]}]}
{"op":"mcm","clk":"11935962615","pt":1724672722420,"mc":[{"id":"1.232283631","rc":[{"batb":[[0,2.44,4],[1,2.42,945.13],[2,2.36,28.26]],"ltp":2.42,"tv":122.1,"id":349}]}]}
{"op":"mcm","clk":"11935962844","pt":1724672724663,"mc":[{"id":"1.232283631","rc":[{"batb":[[0,2.42,945.13],[1,2.36,28.26],[2,1.9,1230.77]],"ltp":2.42,"tv":122.1,"id":349}]}]}
{"op":"mcm","clk":"11935963222","pt":1724672729321,"mc":[{"id":"1.232283631","rc":[{"batb":[[0,2.44,4],[1,2.42,945.13],[2,2.36,28.26]],"ltp":2.42,"tv":122.1,"id":349}]}]}
{"op":"mcm","clk":"11935963410","pt":1724672731686,"mc":[{"id":"1.232283631","rc":[{"batb":[[0,2.42,945.13],[1,2.36,28.26],[2,1.9,1230.77]],"ltp":2.42,"tv":122.1,"id":349}]}]}
{"op":"mcm","clk":"11935964013","pt":1724672739138,"mc":[{"id":"1.232283631","rc":[{"batb":[[0,2.44,4],[1,2.42,945.13],[2,2.36,28.26]],"ltp":2.42,"tv":122.1,"id":349}]}]}
{"op":"mcm","clk":"11935964169","pt":1724672741550,"mc":[{"id":"1.232283631","rc":[{"batb":[[0,2.42,945.13],[1,2.36,28.26],[2,1.9,1230.77]],"ltp":2.42,"tv":122.1,"id":349}]}]}
{"op":"mcm","clk":"11935964657","pt":1724672748753,"mc":[{"id":"1.232283631","rc":[{"batb":[[0,2.44,4],[1,2.42,945.13],[2,2.36,28.26]],"ltp":2.42,"tv":122.1,"id":349}]}]}
{"op":"mcm","clk":"11935964832","pt":1724672751167,"mc":[{"id":"1.232283631","rc":[{"batb":[[0,2.42,945.13],[1,2.36,28.26],[2,1.9,1230.77]],"ltp":2.42,"tv":122.1,"id":349}]}]}
{"op":"mcm","clk":"11935965244","pt":1724672757171,"mc":[{"id":"1.232283631","rc":[{"batb":[[0,2.44,4],[1,2.42,945.13],[2,2.36,28.26]],"ltp":2.42,"tv":122.1,"id":349}]}]}
{"op":"mcm","clk":"11935965414","pt":1724672759484,"mc":[{"id":"1.232283631","rc":[{"batb":[[0,2.42,945.13],[1,2.36,28.26],[2,1.9,1230.77]],"ltp":2.42,"tv":122.1,"id":349}]}]}
{"op":"mcm","clk":"11935967021","pt":1724672779796,"mc":[{"id":"1.232283631","rc":[{"batb":[[0,2.44,4],[1,2.42,945.13],[2,2.36,28.26]],"ltp":2.42,"tv":122.1,"id":349}]}]}
{"op":"mcm","clk":"11935967162","pt":1724672782008,"mc":[{"id":"1.232283631","rc":[{"batb":[[0,2.42,945.13],[1,2.36,28.26],[2,1.9,1230.77]],"ltp":2.42,"tv":122.1,"id":349}]}]}
{"op":"mcm","clk":"11935968299","pt":1724672797134,"mc":[{"id":"1.232283631","rc":[{"batb":[[0,2.44,4],[1,2.42,945.13],[2,2.36,28.26]],"ltp":2.42,"tv":122.1,"id":349}]}]}
{"op":"mcm","clk":"11935968448","pt":1724672799344,"mc":[{"id":"1.232283631","rc":[{"batb":[[0,2.42,945.13],[1,2.36,28.26],[2,1.9,1230.77]],"ltp":2.42,"tv":122.1,"id":349}]}]}
{"op":"mcm","clk":"11935974380","pt":1724672870662,"mc":[{"id":"1.232283631","rc":[{"batb":[[0,2.44,4],[1,2.42,945.13],[2,2.36,28.26]],"ltp":2.42,"tv":122.1,"id":349}]}]}
{"op":"mcm","clk":"11935974621","pt":1724672872974,"mc":[{"id":"1.232283631","rc":[{"batb":[[0,2.42,945.13],[1,2.36,28.26],[2,1.9,1230.77]],"ltp":2.42,"tv":122.1,"id":349}]}]}
{"op":"mcm","clk":"11935976321","pt":1724672892089,"mc":[{"id":"1.232283631","rc":[{"batb":[[0,2.44,4],[1,2.42,945.13],[2,2.36,28.26]],"ltp":2.42,"tv":122.1,"id":349}]}]}
{"op":"mcm","clk":"11935976644","pt":1724672894356,"mc":[{"id":"1.232283631","rc":[{"batb":[[0,2.42,945.13],[1,2.36,28.26],[2,1.9,1230.77]],"ltp":2.42,"tv":122.1,"id":349}]}]}
{"op":"mcm","clk":"11935977352","pt":1724672901465,"mc":[{"id":"1.232283631","rc":[{"batb":[[0,2.44,4],[1,2.42,945.13],[2,2.36,28.26]],"ltp":2.42,"tv":122.1,"id":349}]}]}
{"op":"mcm","clk":"11935977537","pt":1724672903677,"mc":[{"id":"1.232283631","rc":[{"batb":[[0,2.42,945.13],[1,2.36,28.26],[2,1.9,1230.77]],"ltp":2.42,"tv":122.1,"id":349}]}]}
{"op":"mcm","clk":"11935977732","pt":1724672905895,"mc":[{"id":"1.232283631","rc":[{"batb":[[0,2.44,4],[1,2.42,945.13],[2,2.36,28.26]],"ltp":2.42,"tv":122.1,"id":349}]}]}
{"op":"mcm","clk":"11935977907","pt":1724672908001,"mc":[{"id":"1.232283631","rc":[{"batb":[[0,2.42,945.13],[1,2.36,28.26],[2,1.9,1230.77]],"ltp":2.42,"tv":122.1,"id":349}]}]}
{"op":"mcm","clk":"11935979962","pt":1724672930214,"mc":[{"id":"1.232283631","rc":[{"batb":[[0,2.44,4],[1,2.42,945.13],[2,2.36,28.26]],"ltp":2.42,"tv":122.1,"id":349}]}]}
{"op":"mcm","clk":"11935980142","pt":1724672932643,"mc":[{"id":"1.232283631","rc":[{"batb":[[0,2.42,945.13],[1,2.36,28.26],[2,1.9,1230.77]],"ltp":2.42,"tv":122.1,"id":349}]}]}
{"op":"mcm","clk":"11935980425","pt":1724672934810,"mc":[{"id":"1.232283631","rc":[{"batb":[[0,2.44,4],[1,2.42,945.13],[2,2.36,28.26]],"ltp":2.42,"tv":122.1,"id":349}]}]}
{"op":"mcm","clk":"11935980608","pt":1724672937027,"mc":[{"id":"1.232283631","rc":[{"batb":[[0,2.42,945.13],[1,2.36,28.26],[2,1.9,1230.77]],"ltp":2.42,"tv":122.1,"id":349}]}]}
{"op":"mcm","clk":"11935982832","pt":1724672960684,"mc":[{"id":"1.232283631","rc":[{"batb":[[0,2.44,4],[1,2.42,945.13],[2,2.36,28.26]],"ltp":2.42,"tv":122.1,"id":349}]}]}
{"op":"mcm","clk":"11935983022","pt":1724672962888,"mc":[{"id":"1.232283631","rc":[{"batb":[[0,2.42,945.13],[1,2.36,28.26],[2,1.9,1230.77]],"ltp":2.42,"tv":122.1,"id":349}]}]}
{"op":"mcm","clk":"11935984639","pt":1724672980274,"mc":[{"id":"1.232283631","rc":[{"batb":[[0,2.44,4],[1,2.42,945.13],[2,2.36,28.26]],"ltp":2.42,"tv":122.1,"id":349}]}]}
{"op":"mcm","clk":"11935984823","pt":1724672982487,"mc":[{"id":"1.232283631","rc":[{"batb":[[0,2.42,945.13],[1,2.36,28.26],[2,1.9,1230.77]],"ltp":2.42,"tv":122.1,"id":349}]}]}
{"op":"mcm","clk":"11935987387","pt":1724673006590,"mc":[{"id":"1.232283631","rc":[{"batb":[[0,2.44,4],[1,2.42,945.13],[2,2.36,28.26]],"ltp":2.42,"tv":122.1,"id":349}]}]}
{"op":"mcm","clk":"11935987604","pt":1724673008905,"mc":[{"id":"1.232283631","rc":[{"batb":[[0,2.42,945.13],[1,2.36,28.26],[2,1.9,1230.77]],"ltp":2.42,"tv":122.1,"id":349}]}]}
{"op":"mcm","clk":"11935988333","pt":1724673016985,"mc":[{"id":"1.232283631","rc":[{"batb":[[0,2.44,4],[1,2.42,945.13],[2,2.36,28.26]],"ltp":2.42,"tv":122.1,"id":349}]}]}
{"op":"mcm","clk":"11935988541","pt":1724673019182,"mc":[{"id":"1.232283631","rc":[{"batb":[[0,2.42,945.13],[1,2.36,28.26],[2,1.9,1230.77]],"ltp":2.42,"tv":122.1,"id":349}]}]}
{"op":"mcm","clk":"11935989279","pt":1724673027008,"mc":[{"id":"1.232283631","rc":[{"batb":[[0,2.44,4],[1,2.42,945.13],[2,2.36,28.26]],"ltp":2.42,"tv":122.1,"id":349}]}]}
{"op":"mcm","clk":"11935989498","pt":1724673029322,"mc":[{"id":"1.232283631","rc":[{"batb":[[0,2.42,945.13],[1,2.36,28.26],[2,1.9,1230.77]],"ltp":2.42,"tv":122.1,"id":349}]}]}
{"op":"mcm","clk":"11935989762","pt":1724673031898,"mc":[{"id":"1.232283631","rc":[{"batb":[[0,2.44,4],[1,2.42,945.13],[2,2.36,28.26]],"ltp":2.42,"tv":122.1,"id":349}]}]}
{"op":"mcm","clk":"11935990010","pt":1724673034216,"mc":[{"id":"1.232283631","rc":[{"batb":[[0,2.42,945.13],[1,2.36,28.26],[2,1.9,1230.77]],"ltp":2.42,"tv":122.1,"id":349}]}]}
{"op":"mcm","clk":"11935990248","pt":1724673037105,"mc":[{"id":"1.232283631","rc":[{"batb":[[0,2.44,4],[1,2.42,945.13],[2,2.36,28.26]],"ltp":2.42,"tv":122.1,"id":349}]}]}
{"op":"mcm","clk":"11935990482","pt":1724673039535,"mc":[{"id":"1.232283631","rc":[{"batb":[[0,2.42,945.13],[1,2.36,28.26],[2,1.9,1230.77]],"ltp":2.42,"tv":122.1,"id":349}]}]}
{"op":"mcm","clk":"11935991018","pt":1724673043405,"mc":[{"id":"1.232283631","rc":[{"batb":[[0,2.44,4],[1,2.42,945.13],[2,2.36,28.26]],"ltp":2.42,"tv":122.1,"id":349}]}]}
{"op":"mcm","clk":"11935991270","pt":1724673045612,"mc":[{"id":"1.232283631","rc":[{"batb":[[0,2.42,945.13],[1,2.36,28.26],[2,1.9,1230.77]],"ltp":2.42,"tv":122.1,"id":349}]}]}
{"op":"mcm","clk":"11935991463","pt":1724673047720,"mc":[{"id":"1.232283631","rc":[{"batb":[[0,2.44,4],[1,2.42,945.13],[2,2.36,28.26]],"ltp":2.42,"tv":122.1,"id":349}]}]}
{"op":"mcm","clk":"11935991613","pt":1724673049111,"mc":[{"id":"1.232283631","rc":[{"batl":[[0,2.5,17.19],[1,3.2,15.1],[2,5,51.34]],"ltp":2.42,"tv":122.1,"id":349},{"batb":[[0,1.67,34.45]],"ltp":1.71,"tv":118.53,"id":235}]}]}
{"op":"mcm","clk":"11935991693","pt":1724673050035,"mc":[{"id":"1.232283631","rc":[{"batb":[[0,2.42,945.13],[1,2.36,28.26],[2,1.9,1230.77]],"ltp":2.42,"tv":122.1,"id":349}]}]}
{"op":"mcm","clk":"11936025587","pt":1724673427555,"mc":[{"id":"1.232283631","rc":[{"trd":[[1.7,58.84]],"batl":[[0,1.7,2893.3]],"ltp":1.7,"tv":138.41,"id":235}],"tv":260.52}]}
{"op":"mcm","clk":"11936086597","pt":1724674205400,"mc":[{"id":"1.232283631","rc":[{"trd":[[2.44,121.68]],"batb":[[0,2.42,945.13]],"batl":[[0,2.5,17.19],[1,3.2,15.09],[2,5,51.32]],"ltp":2.42,"tv":122.07,"id":349},{"trd":[[1.69,72.61],[1.7,58.85]],"batb":[[0,1.68,10.27],[1,1.67,34.45],[2,1.66,933.22]],"batl":[[1,1.71,12694.39]],"ltp":1.7,"tv":138.43,"id":235}],"tv":260.5}]}
{"op":"mcm","clk":"11936086784","pt":1724674207924,"mc":[{"id":"1.232283631","rc":[{"batb":[[1,1.67,17.26]],"ltp":1.7,"tv":138.43,"id":235}]}]}
{"op":"mcm","clk":"11936086882","pt":1724674209108,"mc":[{"id":"1.232283631","rc":[{"batb":[[1,1.9,1230.77],[2,1.1,25000]],"ltp":2.42,"tv":122.07,"id":349}]}]}
{"op":"mcm","clk":"11936141262","pt":1724674803167,"mc":[{"id":"1.232283631","rc":[{"batb":[[2,1.45,57.03]],"ltp":2.42,"tv":122.07,"id":349}]}]}
{"op":"mcm","clk":"11936142225","pt":1724674815671,"mc":[{"id":"1.232283631","rc":[{"batb":[[2,1.65,4]],"ltp":1.7,"tv":138.43,"id":235}]}]}
{"op":"mcm","clk":"11936142348","pt":1724674817064,"mc":[{"id":"1.232283631","rc":[{"batb":[[0,2.44,4],[1,2.42,945.13],[2,1.9,1230.77]],"batl":[[0,3.2,15.09],[1,5,51.32],[2,10,51.32]],"ltp":2.42,"tv":122.07,"id":349}]}]}
{"op":"mcm","clk":"11936142428","pt":1724674818049,"mc":[{"id":"1.232283631","rc":[{"batb":[[1,2.42,11.91]],"ltp":2.42,"tv":122.07,"id":349}]}]}
{"op":"mcm","clk":"11936142513","pt":1724674818976,"mc":[{"id":"1.232283631","rc":[{"batb":[[1,1.65,21.47],[2,1.64,262.54]],"ltp":1.7,"tv":138.43,"id":235}]}]}
{"op":"mcm","clk":"11936142558","pt":1724674819489,"mc":[{"id":"1.232283631","rc":[{"batb":[[0,2.42,11.91],[1,1.9,1230.77],[2,1.45,57.03]],"ltp":2.42,"tv":122.07,"id":349},{"batl":[[0,1.71,12694.39],[1,1.72,246.15],[2,1.75,138.46]],"ltp":1.7,"tv":138.43,"id":235}]}]}
{"op":"mcm","clk":"11936142981","pt":1724674825170,"mc":[{"id":"1.232283631","rc":[{"batb":[[0,2.44,4],[1,2.42,11.91],[2,1.9,1230.77]],"ltp":2.42,"tv":122.07,"id":349}]}]}
{"op":"mcm","clk":"11936143141","pt":1724674827597,"mc":[{"id":"1.232283631","rc":[{"batb":[[0,2.42,11.91],[1,1.9,1230.77],[2,1.45,57.03]],"ltp":2.42,"tv":122.07,"id":349}]}]}
{"op":"mcm","clk":"11936144142","pt":1724674841976,"mc":[{"id":"1.232283631","rc":[{"batb":[[0,2.44,4],[1,2.42,11.91],[2,1.9,1230.77]],"ltp":2.42,"tv":122.07,"id":349}]}]}
{"op":"mcm","clk":"11936144321","pt":1724674844199,"mc":[{"id":"1.232283631","rc":[{"batb":[[0,2.42,11.91],[1,1.9,1230.77],[2,1.45,57.03]],"ltp":2.42,"tv":122.07,"id":349}]}]}
{"op":"mcm","clk":"11936144515","pt":1724674847023,"mc":[{"id":"1.232283631","rc":[{"batb":[[0,2.44,4],[1,2.42,11.91],[2,1.9,1230.77]],"ltp":2.42,"tv":122.07,"id":349}]}]}
{"op":"mcm","clk":"11936144685","pt":1724674849231,"mc":[{"id":"1.232283631","rc":[{"batb":[[0,2.42,11.91],[1,1.9,1230.77],[2,1.45,57.03]],"ltp":2.42,"tv":122.07,"id":349}]}]}
{"op":"mcm","clk":"11936145793","pt":1724674863734,"mc":[{"id":"1.232283631","rc":[{"batb":[[0,2.44,4],[1,2.42,11.91],[2,1.9,1230.77]],"ltp":2.42,"tv":122.07,"id":349}]}]}
{"op":"mcm","clk":"11936145926","pt":1724674865942,"mc":[{"id":"1.232283631","rc":[{"batb":[[0,2.42,11.91],[1,1.9,1230.77],[2,1.45,57.03]],"ltp":2.42,"tv":122.07,"id":349}]}]}
{"op":"mcm","clk":"11936156204","pt":1724674999789,"mc":[{"id":"1.232283631","rc":[{"batb":[[0,2.44,4],[1,2.42,11.91],[2,1.9,1230.77]],"ltp":2.42,"tv":122.07,"id":349}]}]}
{"op":"mcm","clk":"11936156404","pt":1724675001999,"mc":[{"id":"1.232283631","rc":[{"batb":[[0,2.42,11.91],[1,1.9,1230.77],[2,1.45,57.03]],"ltp":2.42,"tv":122.07,"id":349}]}]}
{"op":"mcm","clk":"11936158301","pt":1724675024988,"mc":[{"id":"1.232283631","rc":[{"batb":[[0,2.44,4],[1,2.42,11.91],[2,1.9,1230.77]],"ltp":2.42,"tv":122.07,"id":349}]}]}
{"op":"mcm","clk":"11936158443","pt":1724675027299,"mc":[{"id":"1.232283631","rc":[{"batb":[[0,2.42,11.91],[1,1.9,1230.77],[2,1.45,57.03]],"ltp":2.42,"tv":122.07,"id":349}]}]}
{"op":"mcm","clk":"11936162996","pt":1724675083992,"mc":[{"id":"1.232283631","rc":[{"batb":[[0,2.44,4],[1,2.42,11.91],[2,1.9,1230.77]],"ltp":2.42,"tv":122.07,"id":349}]}]}
{"op":"mcm","clk":"11936163185","pt":1724675086374,"mc":[{"id":"1.232283631","rc":[{"batb":[[0,2.42,11.91],[1,1.9,1230.77],[2,1.45,57.03]],"ltp":2.42,"tv":122.07,"id":349}]}]}
{"op":"mcm","clk":"11936165385","pt":1724675111715,"mc":[{"id":"1.232283631","rc":[{"batb":[[0,2.44,4],[1,2.42,11.91],[2,1.9,1230.77]],"ltp":2.42,"tv":122.07,"id":349}]}]}
{"op":"mcm","clk":"11936165571","pt":1724675113993,"mc":[{"id":"1.232283631","rc":[{"batb":[[0,2.42,11.91],[1,1.9,1230.77],[2,1.45,57.03]],"ltp":2.42,"tv":122.07,"id":349}]}]}
{"op":"mcm","clk":"11936165810","pt":1724675116822,"mc":[{"id":"1.232283631","rc":[{"batb":[[0,2.44,4],[1,2.42,11.91],[2,1.9,1230.77]],"ltp":2.42,"tv":122.07,"id":349}]}]}
{"op":"mcm","clk":"11936166019","pt":1724675119141,"mc":[{"id":"1.232283631","rc":[{"batb":[[0,2.42,11.91],[1,1.9,1230.77],[2,1.45,57.03]],"ltp":2.42,"tv":122.07,"id":349}]}]}
{"op":"mcm","clk":"11936171623","pt":1724675188584,"mc":[{"id":"1.232283631","rc":[{"batb":[[0,2.44,4],[1,2.42,11.91],[2,1.9,1230.77]],"ltp":2.42,"tv":122.07,"id":349}]}]}
{"op":"mcm","clk":"11936171789","pt":1724675190805,"mc":[{"id":"1.232283631","rc":[{"batb":[[0,2.42,11.91],[1,1.9,1230.77],[2,1.45,57.03]],"ltp":2.42,"tv":122.07,"id":349}]}]}
{"op":"mcm","clk":"11936172552","pt":1724675201708,"mc":[{"id":"1.232283631","rc":[{"batb":[[0,2.44,4],[1,2.42,11.91],[2,1.9,1230.77]],"ltp":2.42,"tv":122.07,"id":349}]}]}
{"op":"mcm","clk":"11936172704","pt":1724675204028,"mc":[{"id":"1.232283631","rc":[{"batb":[[0,2.42,11.91],[1,1.9,1230.77],[2,1.45,57.03]],"ltp":2.42,"tv":122.07,"id":349}]}]}
{"op":"mcm","clk":"11936176505","pt":1724675257690,"mc":[{"id":"1.232283631","rc":[{"batb":[[0,2.44,4],[1,2.42,11.91],[2,1.9,1230.77]],"ltp":2.42,"tv":122.07,"id":349}]}]}
{"op":"mcm","clk":"11936176693","pt":1724675259965,"mc":[{"id":"1.232283631","rc":[{"batb":[[0,2.42,11.91],[1,1.9,1230.77],[2,1.45,57.03]],"ltp":2.42,"tv":122.07,"id":349}]}]}
{"op":"mcm","clk":"11936187150","pt":1724675392212,"mc":[{"id":"1.232283631","rc":[{"batb":[[0,2.44,4],[1,2.42,11.91],[2,1.9,1230.77]],"ltp":2.42,"tv":122.07,"id":349}]}]}
{"op":"mcm","clk":"11936187307","pt":1724675394502,"mc":[{"id":"1.232283631","rc":[{"batb":[[0,2.42,11.91],[1,1.9,1230.77],[2,1.45,57.03]],"ltp":2.42,"tv":122.07,"id":349}]}]}
{"op":"mcm","clk":"11936192491","pt":1724675464481,"mc":[{"id":"1.232283631","rc":[{"batb":[[0,2.44,4],[1,2.42,11.91],[2,1.9,1230.77]],"ltp":2.42,"tv":122.07,"id":349}]}]}
{"op":"mcm","clk":"11936192657","pt":1724675467003,"mc":[{"id":"1.232283631","rc":[{"batb":[[0,2.42,11.91],[1,1.9,1230.77],[2,1.45,57.03]],"ltp":2.42,"tv":122.07,"id":349}]}]}
{"op":"mcm","clk":"11936194181","pt":1724675487979,"mc":[{"id":"1.232283631","rc":[{"batb":[[0,2.44,4],[1,2.42,11.91],[2,1.9,1230.77]],"ltp":2.42,"tv":122.07,"id":349}]}]}
{"op":"mcm","clk":"11936194359","pt":1724675490394,"mc":[{"id":"1.232283631","rc":[{"batb":[[0,2.42,11.91],[1,1.9,1230.77],[2,1.45,57.03]],"ltp":2.42,"tv":122.07,"id":349}]}]}
{"op":"mcm","clk":"11936194760","pt":1724675495801,"mc":[{"id":"1.232283631","rc":[{"batb":[[0,2.44,4],[1,2.42,11.91],[2,1.9,1230.77]],"ltp":2.42,"tv":122.07,"id":349}]}]}
{"op":"mcm","clk":"11936194948","pt":1724675498217,"mc":[{"id":"1.232283631","rc":[{"batb":[[0,2.42,11.91],[1,1.9,1230.77],[2,1.45,57.03]],"ltp":2.42,"tv":122.07,"id":349}]}]}
{"op":"mcm","clk":"11936195800","pt":1724675510823,"mc":[{"id":"1.232283631","rc":[{"batb":[[0,2.44,4],[1,2.42,11.91],[2,1.9,1230.77]],"ltp":2.42,"tv":122.07,"id":349}]}]}
{"op":"mcm","clk":"11936195933","pt":1724675513141,"mc":[{"id":"1.232283631","rc":[{"batb":[[0,2.42,11.91],[1,1.9,1230.77],[2,1.45,57.03]],"ltp":2.42,"tv":122.07,"id":349}]}]}
{"op":"mcm","clk":"11936196421","pt":1724675520711,"mc":[{"id":"1.232283631","rc":[{"batb":[[0,2.44,4],[1,2.42,11.91],[2,1.9,1230.77]],"ltp":2.42,"tv":122.07,"id":349}]}]}
{"op":"mcm","clk":"11936196590","pt":1724675522939,"mc":[{"id":"1.232283631","rc":[{"batb":[[0,2.42,11.91],[1,1.9,1230.77],[2,1.45,57.03]],"ltp":2.42,"tv":122.07,"id":349}]}]}
{"op":"mcm","clk":"11936199685","pt":1724675565897,"mc":[{"id":"1.232283631","rc":[{"batb":[[0,2.44,4],[1,2.42,11.91],[2,1.9,1230.77]],"ltp":2.42,"tv":122.07,"id":349}]}]}
{"op":"mcm","clk":"11936199852","pt":1724675568272,"mc":[{"id":"1.232283631","rc":[{"batb":[[0,2.42,11.91],[1,1.9,1230.77],[2,1.45,57.03]],"ltp":2.42,"tv":122.07,"id":349}]}]}
{"op":"mcm","clk":"11936200770","pt":1724675581712,"mc":[{"id":"1.232283631","rc":[{"batb":[[0,2.44,4],[1,2.42,11.91],[2,1.9,1230.77]],"ltp":2.42,"tv":122.07,"id":349}]}]}
{"op":"mcm","clk":"11936200956","pt":1724675584101,"mc":[{"id":"1.232283631","rc":[{"batb":[[0,2.42,11.91],[1,1.9,1230.77],[2,1.45,57.03]],"ltp":2.42,"tv":122.07,"id":349}]}]}
{"op":"mcm","clk":"11936202136","pt":1724675600243,"mc":[{"id":"1.232283631","rc":[{"batb":[[0,2.44,4],[1,2.42,11.91],[2,1.9,1230.77]],"ltp":2.42,"tv":122.07,"id":349}]}]}
{"op":"mcm","clk":"11936202304","pt":1724675602506,"mc":[{"id":"1.232283631","rc":[{"batb":[[0,2.42,11.91],[1,1.9,1230.77],[2,1.45,57.03]],"ltp":2.42,"tv":122.07,"id":349}]}]}
{"op":"mcm","clk":"11936202756","pt":1724675608326,"mc":[{"id":"1.232283631","rc":[{"batb":[[0,2.44,4],[1,2.42,11.91],[2,1.9,1230.77]],"ltp":2.42,"tv":122.07,"id":349}]}]}
{"op":"mcm","clk":"11936202943","pt":1724675610649,"mc":[{"id":"1.232283631","rc":[{"batb":[[0,2.42,11.91],[1,1.9,1230.77],[2,1.45,57.03]],"ltp":2.42,"tv":122.07,"id":349}]}]}
{"op":"mcm","clk":"11936203156","pt":1724675613123,"mc":[{"id":"1.232283631","rc":[{"batb":[[0,2.44,4],[1,2.42,11.91],[2,1.9,1230.77]],"ltp":2.42,"tv":122.07,"id":349}]}]}
{"op":"mcm","clk":"11936203349","pt":1724675615520,"mc":[{"id":"1.232283631","rc":[{"batb":[[0,2.42,11.91],[1,1.9,1230.77],[2,1.45,57.03]],"ltp":2.42,"tv":122.07,"id":349}]}]}
{"op":"mcm","clk":"11936203760","pt":1724675620358,"mc":[{"id":"1.232283631","rc":[{"batb":[[0,2.44,4],[1,2.42,11.91],[2,1.9,1230.77]],"ltp":2.42,"tv":122.07,"id":349}]}]}
{"op":"mcm","clk":"11936203951","pt":1724675622563,"mc":[{"id":"1.232283631","rc":[{"batb":[[0,2.42,11.91],[1,1.9,1230.77],[2,1.45,57.03]],"ltp":2.42,"tv":122.07,"id":349}]}]}
{"op":"mcm","clk":"11936206462","pt":1724675655086,"mc":[{"id":"1.232283631","rc":[{"batb":[[0,2.44,4],[1,2.42,11.91],[2,1.9,1230.77]],"ltp":2.42,"tv":122.07,"id":349}]}]}
{"op":"mcm","clk":"11936206632","pt":1724675657501,"mc":[{"id":"1.232283631","rc":[{"batb":[[0,2.42,11.91],[1,1.9,1230.77],[2,1.45,57.03]],"ltp":2.42,"tv":122.07,"id":349}]}]}
{"op":"mcm","clk":"11936206998","pt":1724675662970,"mc":[{"id":"1.232283631","rc":[{"batb":[[0,2.44,4],[1,2.42,11.91],[2,1.9,1230.77]],"ltp":2.42,"tv":122.07,"id":349}]}]}
{"op":"mcm","clk":"11936207167","pt":1724675665175,"mc":[{"id":"1.232283631","rc":[{"batb":[[0,2.42,11.91],[1,1.9,1230.77],[2,1.45,57.03]],"ltp":2.42,"tv":122.07,"id":349}]}]}
{"op":"mcm","clk":"11936207593","pt":1724675671088,"mc":[{"id":"1.232283631","rc":[{"batb":[[0,2.44,4],[1,2.42,11.91],[2,1.9,1230.77]],"ltp":2.42,"tv":122.07,"id":349},{"batb":[[0,1.65,21.47],[1,1.64,262.54],[2,1.6,950]],"ltp":1.7,"tv":138.43,"id":235}]}]}
{"op":"mcm","clk":"11936207790","pt":1724675673400,"mc":[{"id":"1.232283631","rc":[{"batb":[[0,2.42,11.91],[1,1.9,1230.77],[2,1.45,57.03]],"ltp":2.42,"tv":122.07,"id":349}]}]}
{"op":"mcm","clk":"11936207879","pt":1724675674377,"mc":[{"id":"1.232283631","rc":[{"batb":[[1,2.36,28.26],[2,1.9,1230.77]],"ltp":2.42,"tv":122.07,"id":349},{"batb":[[2,1.63,61.02]],"ltp":1.7,"tv":138.43,"id":235}]}]}
{"op":"mcm","clk":"11936210443","pt":1724675705541,"mc":[{"id":"1.232283631","rc":[{"batb":[[0,2.44,4],[1,2.42,11.91],[2,2.36,28.26]],"ltp":2.42,"tv":122.07,"id":349}]}]}
{"op":"mcm","clk":"11936210646","pt":1724675707807,"mc":[{"id":"1.232283631","rc":[{"batb":[[0,2.42,11.91],[1,2.36,28.26],[2,1.9,1230.77]],"ltp":2.42,"tv":122.07,"id":349}]}]}
{"op":"mcm","clk":"11936210944","pt":1724675711049,"mc":[{"id":"1.232283631","rc":[{"batb":[[0,2.44,4],[1,2.42,11.91],[2,2.36,28.26]],"ltp":2.42,"tv":122.07,"id":349}]}]}
{"op":"mcm","clk":"11936211153","pt":1724675713415,"mc":[{"id":"1.232283631","rc":[{"batb":[[0,2.42,11.91],[1,2.36,28.26],[2,1.9,1230.77]],"ltp":2.42,"tv":122.07,"id":349}]}]}
{"op":"mcm","clk":"11936213747","pt":1724675744357,"mc":[{"id":"1.232283631","rc":[{"batb":[[0,2.44,4],[1,2.42,11.91],[2,2.36,28.26]],"ltp":2.42,"tv":122.07,"id":349}]}]}
{"op":"mcm","clk":"11936213940","pt":1724675746670,"mc":[{"id":"1.232283631","rc":[{"batb":[[0,2.42,11.91],[1,2.36,28.26],[2,1.9,1230.77]],"ltp":2.42,"tv":122.07,"id":349}]}]}
{"op":"mcm","clk":"11936215125","pt":1724675761992,"mc":[{"id":"1.232283631","rc":[{"batb":[[0,2.44,4],[1,2.42,11.91],[2,2.36,28.26]],"ltp":2.42,"tv":122.07,"id":349}]}]}
{"op":"mcm","clk":"11936215308","pt":1724675764368,"mc":[{"id":"1.232283631","rc":[{"batb":[[0,2.42,11.91],[1,2.36,28.26],[2,1.9,1230.77]],"ltp":2.42,"tv":122.07,"id":349}]}]}
{"op":"mcm","clk":"11936215476","pt":1724675766787,"mc":[{"id":"1.232283631","rc":[{"batb":[[0,2.44,4],[1,2.42,11.91],[2,2.36,28.26]],"ltp":2.42,"tv":122.07,"id":349}]}]}
{"op":"mcm","clk":"11936215642","pt":1724675769214,"mc":[{"id":"1.232283631","rc":[{"batb":[[0,2.42,11.91],[1,2.36,28.26],[2,1.9,1230.77]],"ltp":2.42,"tv":122.07,"id":349}]}]}
{"op":"mcm","clk":"11936215844","pt":1724675771801,"mc":[{"id":"1.232283631","rc":[{"batb":[[0,2.44,4],[1,2.42,11.91],[2,2.36,28.26]],"ltp":2.42,"tv":122.07,"id":349}]}]}
{"op":"mcm","clk":"11936216070","pt":1724675774325,"mc":[{"id":"1.232283631","rc":[{"batb":[[0,2.42,11.91],[1,2.36,28.26],[2,1.9,1230.77]],"ltp":2.42,"tv":122.07,"id":349}]}]}
{"op":"mcm","clk":"11936217389","pt":1724675788728,"mc":[{"id":"1.232283631","rc":[{"batb":[[0,2.44,4],[1,2.42,11.91],[2,2.36,28.26]],"ltp":2.42,"tv":122.07,"id":349}]}]}
{"op":"mcm","clk":"11936217608","pt":1724675791113,"mc":[{"id":"1.232283631","rc":[{"batb":[[0,2.42,11.91],[1,2.36,28.26],[2,1.9,1230.77]],"ltp":2.42,"tv":122.07,"id":349}]}]}
{"op":"mcm","clk":"11936220564","pt":1724675828533,"mc":[{"id":"1.232283631","rc":[{"batb":[[0,2.44,4],[1,2.42,11.91],[2,2.36,28.26]],"ltp":2.42,"tv":122.07,"id":349}]}]}
{"op":"mcm","clk":"11936220766","pt":1724675830862,"mc":[{"id":"1.232283631","rc":[{"batb":[[0,2.42,11.91],[1,2.36,28.26],[2,1.9,1230.77]],"ltp":2.42,"tv":122.07,"id":349}]}]}
{"op":"mcm","clk":"11936223998","pt":1724675872973,"mc":[{"id":"1.232283631","rc":[{"batb":[[0,2.44,4],[1,2.42,11.91],[2,2.36,28.26]],"ltp":2.42,"tv":122.07,"id":349}]}]}
{"op":"mcm","clk":"11936224149","pt":1724675875389,"mc":[{"id":"1.232283631","rc":[{"batb":[[0,2.42,11.91],[1,2.36,28.26],[2,1.9,1230.77]],"ltp":2.42,"tv":122.07,"id":349}]}]}
{"op":"mcm","clk":"11936228887","pt":1724675933251,"mc":[{"id":"1.232283631","rc":[{"batb":[[0,2.44,4],[1,2.42,11.91],[2,2.36,28.26]],"ltp":2.42,"tv":122.07,"id":349}]}]}
{"op":"mcm","clk":"11936229055","pt":1724675935462,"mc":[{"id":"1.232283631","rc":[{"batb":[[0,2.42,11.91],[1,2.36,28.26],[2,1.9,1230.77]],"ltp":2.42,"tv":122.07,"id":349}]}]}
{"op":"mcm","clk":"11936229459","pt":1724675940082,"mc":[{"id":"1.232283631","rc":[{"batb":[[0,2.44,4],[1,2.42,11.91],[2,2.36,28.26]],"ltp":2.42,"tv":122.07,"id":349}]}]}
{"op":"mcm","clk":"11936229685","pt":1724675942475,"mc":[{"id":"1.232283631","rc":[{"batb":[[0,2.42,11.91],[1,2.36,28.26],[2,1.9,1230.77]],"ltp":2.42,"tv":122.07,"id":349}]}]}
{"op":"mcm","clk":"11936230952","pt":1724675956981,"mc":[{"id":"1.232283631","rc":[{"batb":[[0,2.44,4],[1,2.42,11.91],[2,2.36,28.26]],"ltp":2.42,"tv":122.07,"id":349}]}]}
{"op":"mcm","clk":"11936231119","pt":1724675959193,"mc":[{"id":"1.232283631","rc":[{"batb":[[0,2.42,11.91],[1,2.36,28.26],[2,1.9,1230.77]],"ltp":2.42,"tv":122.07,"id":349}]}]}
{"op":"mcm","clk":"11936233812","pt":1724675993626,"mc":[{"id":"1.232283631","rc":[{"batb":[[0,2.44,4],[1,2.42,11.91],[2,2.36,28.26]],"ltp":2.42,"tv":122.07,"id":349}]}]}
{"op":"mcm","clk":"11936234000","pt":1724675995939,"mc":[{"id":"1.232283631","rc":[{"batb":[[0,2.42,11.91],[1,2.36,28.26],[2,1.9,1230.77]],"ltp":2.42,"tv":122.07,"id":349}]}]}
{"op":"mcm","clk":"11936237281","pt":1724676036082,"mc":[{"id":"1.232283631","rc":[{"batb":[[0,2.44,4],[1,2.42,11.91],[2,2.36,28.26]],"ltp":2.42,"tv":122.07,"id":349}]}]}
{"op":"mcm","clk":"11936237443","pt":1724676038396,"mc":[{"id":"1.232283631","rc":[{"batb":[[0,2.42,11.91],[1,2.36,28.26],[2,1.9,1230.77]],"ltp":2.42,"tv":122.07,"id":349}]}]}
{"op":"mcm","clk":"11936240949","pt":1724676084229,"mc":[{"id":"1.232283631","rc":[{"batb":[[0,2.44,4],[1,2.42,11.91],[2,2.36,28.26]],"ltp":2.42,"tv":122.07,"id":349}]}]}
{"op":"mcm","clk":"11936241144","pt":1724676086512,"mc":[{"id":"1.232283631","rc":[{"batb":[[0,2.42,11.91],[1,2.36,28.26],[2,1.9,1230.77]],"ltp":2.42,"tv":122.07,"id":349}]}]}
{"op":"mcm","clk":"11936255370","pt":1724676278851,"mc":[{"id":"1.232283631","rc":[{"batb":[[0,2.44,4],[1,2.42,11.91],[2,2.36,28.26]],"ltp":2.42,"tv":122.07,"id":349}]}]}
{"op":"mcm","clk":"11936255519","pt":1724676281116,"mc":[{"id":"1.232283631","rc":[{"batb":[[0,2.42,11.91],[1,2.36,28.26],[2,1.9,1230.77]],"ltp":2.42,"tv":122.07,"id":349}]}]}
{"op":"mcm","clk":"11936256022","pt":1724676287850,"mc":[{"id":"1.232283631","rc":[{"batb":[[0,2.44,4],[1,2.42,11.91],[2,2.36,28.26]],"ltp":2.42,"tv":122.07,"id":349}]}]}
{"op":"mcm","clk":"11936256163","pt":1724676290164,"mc":[{"id":"1.232283631","rc":[{"batb":[[0,2.42,11.91],[1,2.36,28.26],[2,1.9,1230.77]],"ltp":2.42,"tv":122.07,"id":349}]}]}
{"op":"mcm","clk":"11936257456","pt":1724676307454,"mc":[{"id":"1.232283631","rc":[{"batb":[[0,2.44,4],[1,2.42,11.91],[2,2.36,28.26]],"ltp":2.42,"tv":122.07,"id":349}]}]}
{"op":"mcm","clk":"11936257642","pt":1724676309771,"mc":[{"id":"1.232283631","rc":[{"batb":[[0,2.42,11.91],[1,2.36,28.26],[2,1.9,1230.77]],"ltp":2.42,"tv":122.07,"id":349}]}]}
{"op":"mcm","clk":"11936260297","pt":1724676344124,"mc":[{"id":"1.232283631","rc":[{"batb":[[0,2.44,4],[1,2.42,11.91],[2,2.36,28.26]],"ltp":2.42,"tv":122.07,"id":349}]}]}
{"op":"mcm","clk":"11936260500","pt":1724676346503,"mc":[{"id":"1.232283631","rc":[{"batb":[[0,2.42,11.91],[1,2.36,28.26],[2,1.9,1230.77]],"ltp":2.42,"tv":122.07,"id":349}]}]}
{"op":"mcm","clk":"11936262205","pt":1724676368220,"mc":[{"id":"1.232283631","rc":[{"batb":[[0,2.44,4],[1,2.42,11.91],[2,2.36,28.26]],"ltp":2.42,"tv":122.07,"id":349}]}]}
{"op":"mcm","clk":"11936262405","pt":1724676370651,"mc":[{"id":"1.232283631","rc":[{"batb":[[0,2.42,11.91],[1,2.36,28.26],[2,1.9,1230.77]],"ltp":2.42,"tv":122.07,"id":349}]}]}
{"op":"mcm","clk":"11936262718","pt":1724676374369,"mc":[{"id":"1.232283631","rc":[{"batb":[[0,2.44,4],[1,2.42,11.91],[2,2.36,28.26]],"ltp":2.42,"tv":122.07,"id":349}]}]}
{"op":"mcm","clk":"11936262921","pt":1724676376740,"mc":[{"id":"1.232283631","rc":[{"batb":[[0,2.42,11.91],[1,2.36,28.26],[2,1.9,1230.77]],"ltp":2.42,"tv":122.07,"id":349}]}]}
{"op":"mcm","clk":"11936263817","pt":1724676387976,"mc":[{"id":"1.232283631","rc":[{"batb":[[0,2.44,4],[1,2.42,11.91],[2,2.36,28.26]],"ltp":2.42,"tv":122.07,"id":349}]}]}
{"op":"mcm","clk":"11936264009","pt":1724676390255,"mc":[{"id":"1.232283631","rc":[{"batb":[[0,2.42,11.91],[1,2.36,28.26],[2,1.9,1230.77]],"ltp":2.42,"tv":122.07,"id":349}]}]}
{"op":"mcm","clk":"11936264257","pt":1724676392983,"mc":[{"id":"1.232283631","rc":[{"batb":[[0,2.44,4],[1,2.42,11.91],[2,2.36,28.26]],"ltp":2.42,"tv":122.07,"id":349},{"batb":[[0,1.65,34.36]],"ltp":1.7,"tv":138.43,"id":235}]}]}
{"op":"mcm","clk":"11936264487","pt":1724676395361,"mc":[{"id":"1.232283631","rc":[{"batb":[[0,2.42,11.91],[1,2.36,28.26],[2,1.9,1230.77]],"ltp":2.42,"tv":122.07,"id":349}]}]}
{"op":"mcm","clk":"11936266109","pt":1724676415976,"mc":[{"id":"1.232283631","rc":[{"batb":[[0,2.44,4],[1,2.42,11.91],[2,2.36,28.26]],"ltp":2.42,"tv":122.07,"id":349}]}]}
{"op":"mcm","clk":"11936266260","pt":1724676418295,"mc":[{"id":"1.232283631","rc":[{"batb":[[0,2.42,11.91],[1,2.36,28.26],[2,1.9,1230.77]],"ltp":2.42,"tv":122.07,"id":349}]}]}
{"op":"mcm","clk":"11936266556","pt":1724676421908,"mc":[{"id":"1.232283631","rc":[{"batb":[[0,2.44,4],[1,2.42,11.91],[2,2.36,28.26]],"ltp":2.42,"tv":122.07,"id":349}]}]}
{"op":"mcm","clk":"11936266736","pt":1724676424384,"mc":[{"id":"1.232283631","rc":[{"batb":[[0,2.42,11.91],[1,2.36,28.26],[2,1.9,1230.77]],"ltp":2.42,"tv":122.07,"id":349}]}]}
{"op":"mcm","clk":"11936270447","pt":1724676470473,"mc":[{"id":"1.232283631","rc":[{"batb":[[0,2.44,4],[1,2.42,11.91],[2,2.36,28.26]],"ltp":2.42,"tv":122.07,"id":349}]}]}
{"op":"mcm","clk":"11936270634","pt":1724676472738,"mc":[{"id":"1.232283631","rc":[{"batb":[[0,2.42,11.91],[1,2.36,28.26],[2,1.9,1230.77]],"ltp":2.42,"tv":122.07,"id":349}]}]}
{"op":"mcm","clk":"11936272740","pt":1724676498304,"mc":[{"id":"1.232283631","rc":[{"batb":[[0,2.44,4],[1,2.42,11.91],[2,2.36,28.26]],"ltp":2.42,"tv":122.07,"id":349}]}]}
{"op":"mcm","clk":"11936272937","pt":1724676500714,"mc":[{"id":"1.232283631","rc":[{"batb":[[0,2.42,11.91],[1,2.36,28.26],[2,1.9,1230.77]],"ltp":2.42,"tv":122.07,"id":349}]}]}
{"op":"mcm","clk":"11936274117","pt":1724676514932,"mc":[{"id":"1.232283631","rc":[{"batb":[[0,2.44,4],[1,2.42,11.91],[2,2.36,28.26]],"ltp":2.42,"tv":122.07,"id":349}]}]}
{"op":"mcm","clk":"11936274342","pt":1724676517427,"mc":[{"id":"1.232283631","rc":[{"batb":[[0,2.42,11.91],[1,2.36,28.26],[2,1.9,1230.77]],"ltp":2.42,"tv":122.07,"id":349}]}]}
{"op":"mcm","clk":"11936275107","pt":1724676526142,"mc":[{"id":"1.232283631","rc":[{"batb":[[0,2.44,4],[1,2.42,11.91],[2,2.36,28.26]],"ltp":2.42,"tv":122.07,"id":349}]}]}
{"op":"mcm","clk":"11936275308","pt":1724676528642,"mc":[{"id":"1.232283631","rc":[{"batb":[[0,2.42,11.91],[1,2.36,28.26],[2,1.9,1230.77]],"ltp":2.42,"tv":122.07,"id":349}]}]}
{"op":"mcm","clk":"11936275862","pt":1724676535027,"mc":[{"id":"1.232283631","rc":[{"batb":[[0,2.44,4],[1,2.42,11.91],[2,2.36,28.26]],"ltp":2.42,"tv":122.07,"id":349}]}]}
{"op":"mcm","clk":"11936276011","pt":1724676537324,"mc":[{"id":"1.232283631","rc":[{"batb":[[0,2.42,11.91],[1,2.36,28.26],[2,1.9,1230.77]],"ltp":2.42,"tv":122.07,"id":349}]}]}
{"op":"mcm","clk":"11936277960","pt":1724676562362,"mc":[{"id":"1.232283631","rc":[{"batb":[[0,2.44,4],[1,2.42,11.91],[2,2.36,28.26]],"ltp":2.42,"tv":122.07,"id":349}]}]}
{"op":"mcm","clk":"11936278145","pt":1724676564765,"mc":[{"id":"1.232283631","rc":[{"batb":[[0,2.42,11.91],[1,2.36,28.26],[2,1.9,1230.77]],"ltp":2.42,"tv":122.07,"id":349}]}]}
{"op":"mcm","clk":"11936278633","pt":1724676571179,"mc":[{"id":"1.232283631","rc":[{"batb":[[0,2.44,4],[1,2.42,11.91],[2,2.36,28.26]],"ltp":2.42,"tv":122.07,"id":349}]}]}
{"op":"mcm","clk":"11936278822","pt":1724676573570,"mc":[{"id":"1.232283631","rc":[{"batb":[[0,2.42,11.91],[1,2.36,28.26],[2,1.9,1230.77]],"ltp":2.42,"tv":122.07,"id":349}]}]}
{"op":"mcm","clk":"11936279520","pt":1724676582578,"mc":[{"id":"1.232283631","rc":[{"batb":[[0,2.44,4],[1,2.42,11.91],[2,2.36,28.26]],"ltp":2.42,"tv":122.07,"id":349}]}]}
{"op":"mcm","clk":"11936279714","pt":1724676584871,"mc":[{"id":"1.232283631","rc":[{"batb":[[0,2.42,11.91],[1,2.36,28.26],[2,1.9,1230.77]],"ltp":2.42,"tv":122.07,"id":349}]}]}
{"op":"mcm","clk":"11936279922","pt":1724676587368,"mc":[{"id":"1.232283631","rc":[{"batb":[[0,2.44,4],[1,2.42,11.91],[2,2.36,28.26]],"ltp":2.42,"tv":122.07,"id":349}]}]}
{"op":"mcm","clk":"11936280130","pt":1724676589756,"mc":[{"id":"1.232283631","rc":[{"batb":[[0,2.42,11.91],[1,2.36,28.26],[2,1.9,1230.77]],"ltp":2.42,"tv":122.07,"id":349}]}]}
{"op":"mcm","clk":"11936284957","pt":1724676648238,"mc":[{"id":"1.232283631","rc":[{"batb":[[0,2.44,4],[1,2.42,11.91],[2,2.36,28.26]],"ltp":2.42,"tv":122.07,"id":349}]}]}
{"op":"mcm","clk":"11936285126","pt":1724676650721,"mc":[{"id":"1.232283631","rc":[{"batb":[[0,2.42,11.91],[1,2.36,28.26],[2,1.9,1230.77]],"ltp":2.42,"tv":122.07,"id":349}]}]}
{"op":"mcm","clk":"11936285599","pt":1724676656823,"mc":[{"id":"1.232283631","rc":[{"batb":[[0,2.44,4],[1,2.42,11.91],[2,2.36,28.26]],"ltp":2.42,"tv":122.07,"id":349}]}]}
{"op":"mcm","clk":"11936285773","pt":1724676659226,"mc":[{"id":"1.232283631","rc":[{"batb":[[0,2.42,11.91],[1,2.36,28.26],[2,1.9,1230.77]],"ltp":2.42,"tv":122.07,"id":349}]}]}
{"op":"mcm","clk":"11936286676","pt":1724676671258,"mc":[{"id":"1.232283631","rc":[{"batb":[[0,2.44,4],[1,2.42,11.91],[2,2.36,28.26]],"ltp":2.42,"tv":122.07,"id":349}]}]}
{"op":"mcm","clk":"11936286852","pt":1724676673754,"mc":[{"id":"1.232283631","rc":[{"batb":[[0,2.42,11.91],[1,2.36,28.26],[2,1.9,1230.77]],"ltp":2.42,"tv":122.07,"id":349}]}]}
{"op":"mcm","clk":"11936290554","pt":1724676723110,"mc":[{"id":"1.232283631","rc":[{"batb":[[0,2.44,4],[1,2.42,11.91],[2,2.36,28.26]],"ltp":2.42,"tv":122.07,"id":349}]}]}
{"op":"mcm","clk":"11936290757","pt":1724676725534,"mc":[{"id":"1.232283631","rc":[{"batb":[[0,2.42,11.91],[1,2.36,28.26],[2,1.9,1230.77]],"ltp":2.42,"tv":122.07,"id":349}]}]}
{"op":"mcm","clk":"11936293103","pt":1724676755240,"mc":[{"id":"1.232283631","rc":[{"batb":[[0,2.44,4],[1,2.42,11.91],[2,2.36,28.26]],"ltp":2.42,"tv":122.07,"id":349}]}]}
{"op":"mcm","clk":"11936293280","pt":1724676757575,"mc":[{"id":"1.232283631","rc":[{"batb":[[0,2.42,11.91],[1,2.36,28.26],[2,1.9,1230.77]],"ltp":2.42,"tv":122.07,"id":349}]}]}
{"op":"mcm","clk":"11936296297","pt":1724676797894,"mc":[{"id":"1.232283631","rc":[{"batb":[[0,2.44,4],[1,2.42,11.91],[2,2.36,28.26]],"ltp":2.42,"tv":122.07,"id":349}]}]}
{"op":"mcm","clk":"11936296462","pt":1724676800122,"mc":[{"id":"1.232283631","rc":[{"batb":[[0,2.42,11.91],[1,2.36,28.26],[2,1.9,1230.77]],"ltp":2.42,"tv":122.07,"id":349}]}]}
{"op":"mcm","clk":"11936296712","pt":1724676803700,"mc":[{"id":"1.232283631","rc":[{"batb":[[0,2.44,4],[1,2.42,11.91],[2,2.36,28.26]],"ltp":2.42,"tv":122.07,"id":349}]}]}
{"op":"mcm","clk":"11936296857","pt":1724676806033,"mc":[{"id":"1.232283631","rc":[{"batb":[[0,2.42,11.91],[1,2.36,28.26],[2,1.9,1230.77]],"ltp":2.42,"tv":122.07,"id":349}]}]}
{"op":"mcm","clk":"11936299515","pt":1724676841535,"mc":[{"id":"1.232283631","rc":[{"batb":[[0,2.44,4],[1,2.42,11.91],[2,2.36,28.26]],"ltp":2.42,"tv":122.07,"id":349}]}]}
{"op":"mcm","clk":"11936299696","pt":1724676844030,"mc":[{"id":"1.232283631","rc":[{"batb":[[0,2.42,11.91],[1,2.36,28.26],[2,1.9,1230.77]],"ltp":2.42,"tv":122.07,"id":349}]}]}
{"op":"mcm","clk":"11936300626","pt":1724676856346,"mc":[{"id":"1.232283631","rc":[{"batb":[[0,2.44,4],[1,2.42,11.91],[2,2.36,28.26]],"ltp":2.42,"tv":122.07,"id":349}]}]}
{"op":"mcm","clk":"11936300791","pt":1724676858793,"mc":[{"id":"1.232283631","rc":[{"batb":[[0,2.42,11.91],[1,2.36,28.26],[2,1.9,1230.77]],"ltp":2.42,"tv":122.07,"id":349}]}]}
{"op":"mcm","clk":"11936302008","pt":1724676875987,"mc":[{"id":"1.232283631","rc":[{"batb":[[0,2.44,4],[1,2.42,11.91],[2,2.36,28.26]],"ltp":2.42,"tv":122.07,"id":349}]}]}
{"op":"mcm","clk":"11936302183","pt":1724676878409,"mc":[{"id":"1.232283631","rc":[{"batb":[[0,2.42,11.91],[1,2.36,28.26],[2,1.9,1230.77]],"ltp":2.42,"tv":122.07,"id":349}]}]}
{"op":"mcm","clk":"11936302810","pt":1724676886392,"mc":[{"id":"1.232283631","rc":[{"batb":[[0,2.44,4],[1,2.42,11.91],[2,2.36,28.26]],"ltp":2.42,"tv":122.07,"id":349}]}]}
{"op":"mcm","clk":"11936302978","pt":1724676888700,"mc":[{"id":"1.232283631","rc":[{"batb":[[0,2.42,11.91],[1,2.36,28.26],[2,1.9,1230.77]],"ltp":2.42,"tv":122.07,"id":349}]}]}
{"op":"mcm","clk":"11936303425","pt":1724676894899,"mc":[{"id":"1.232283631","rc":[{"batb":[[0,2.44,4],[1,2.42,11.91],[2,2.36,28.26]],"ltp":2.42,"tv":122.07,"id":349}]}]}
{"op":"mcm","clk":"11936303591","pt":1724676897231,"mc":[{"id":"1.232283631","rc":[{"batb":[[0,2.42,11.91],[1,2.36,28.26],[2,1.9,1230.77]],"ltp":2.42,"tv":122.07,"id":349}]}]}
{"op":"mcm","clk":"11936304711","pt":1724676911943,"mc":[{"id":"1.232283631","rc":[{"batb":[[0,2.44,4],[1,2.42,11.91],[2,2.36,28.26]],"ltp":2.42,"tv":122.07,"id":349}]}]}
{"op":"mcm","clk":"11936304912","pt":1724676914317,"mc":[{"id":"1.232283631","rc":[{"batb":[[0,2.42,11.91],[1,2.36,28.26],[2,1.9,1230.77]],"ltp":2.42,"tv":122.07,"id":349}]}]}
{"op":"mcm","clk":"11936306342","pt":1724676934141,"mc":[{"id":"1.232283631","rc":[{"batb":[[0,2.44,4],[1,2.42,11.91],[2,2.36,28.26]],"ltp":2.42,"tv":122.07,"id":349}]}]}
{"op":"mcm","clk":"11936306521","pt":1724676936455,"mc":[{"id":"1.232283631","rc":[{"batb":[[0,2.42,11.91],[1,2.36,28.26],[2,1.9,1230.77]],"ltp":2.42,"tv":122.07,"id":349}]}]}
{"op":"mcm","clk":"11936306727","pt":1724676938957,"mc":[{"id":"1.232283631","rc":[{"batb":[[0,2.44,4],[1,2.42,11.91],[2,2.36,28.26]],"ltp":2.42,"tv":122.07,"id":349}]}]}
{"op":"mcm","clk":"11936306905","pt":1724676941550,"mc":[{"id":"1.232283631","rc":[{"batb":[[0,2.42,11.91],[1,2.36,28.26],[2,1.9,1230.77]],"ltp":2.42,"tv":122.07,"id":349}]}]}
{"op":"mcm","clk":"11936307875","pt":1724676953768,"mc":[{"id":"1.232283631","rc":[{"batb":[[0,2.44,4],[1,2.42,11.91],[2,2.36,28.26]],"ltp":2.42,"tv":122.07,"id":349},{"batl":[[0,1.7,276.92],[1,1.71,12694.39],[2,1.72,246.15]],"ltp":1.7,"tv":138.43,"id":235}]}]}
{"op":"mcm","clk":"11936308038","pt":1724676955995,"mc":[{"id":"1.232283631","rc":[{"batb":[[0,2.42,11.91],[1,2.36,28.26],[2,1.9,1230.77]],"ltp":2.42,"tv":122.07,"id":349}]}]}
{"op":"mcm","clk":"11936308949","pt":1724676966589,"mc":[{"id":"1.232283631","rc":[{"batb":[[0,2.44,4],[1,2.42,11.91],[2,2.36,28.26]],"ltp":2.42,"tv":122.07,"id":349}]}]}
{"op":"mcm","clk":"11936309106","pt":1724676968902,"mc":[{"id":"1.232283631","rc":[{"batb":[[0,2.42,11.91],[1,2.36,28.26],[2,1.9,1230.77]],"ltp":2.42,"tv":122.07,"id":349}]}]}
{"op":"mcm","clk":"11936316327","pt":1724677060009,"mc":[{"id":"1.232283631","rc":[{"batb":[[0,2.44,4],[1,2.42,11.91],[2,2.36,28.26]],"ltp":2.42,"tv":122.07,"id":349}]}]}
{"op":"mcm","clk":"11936316499","pt":1724677062186,"mc":[{"id":"1.232283631","rc":[{"batb":[[0,2.42,11.91],[1,2.36,28.26],[2,1.9,1230.77]],"ltp":2.42,"tv":122.07,"id":349}]}]}
{"op":"mcm","clk":"11936317003","pt":1724677068136,"mc":[{"id":"1.232283631","rc":[{"batb":[[0,2.44,4],[1,2.42,11.91],[2,2.36,28.26]],"ltp":2.42,"tv":122.07,"id":349}]}]}
{"op":"mcm","clk":"11936317144","pt":1724677070443,"mc":[{"id":"1.232283631","rc":[{"batb":[[0,2.42,11.91],[1,2.36,28.26],[2,1.9,1230.77]],"ltp":2.42,"tv":122.07,"id":349}]}]}
{"op":"mcm","clk":"11936318462","pt":1724677086935,"mc":[{"id":"1.232283631","rc":[{"batb":[[0,2.44,4],[1,2.42,11.91],[2,2.36,28.26]],"ltp":2.42,"tv":122.07,"id":349}]}]}
{"op":"mcm","clk":"11936318647","pt":1724677089159,"mc":[{"id":"1.232283631","rc":[{"batb":[[0,2.42,11.91],[1,2.36,28.26],[2,1.9,1230.77]],"ltp":2.42,"tv":122.07,"id":349}]}]}
{"op":"mcm","clk":"11936319500","pt":1724677099153,"mc":[{"id":"1.232283631","rc":[{"batb":[[0,2.44,4],[1,2.42,11.91],[2,2.36,28.26]],"ltp":2.42,"tv":122.07,"id":349}]}]}
{"op":"mcm","clk":"11936319689","pt":1724677101345,"mc":[{"id":"1.232283631","rc":[{"batb":[[0,2.42,11.91],[1,2.36,28.26],[2,1.9,1230.77]],"ltp":2.42,"tv":122.07,"id":349}]}]}
{"op":"mcm","clk":"11936322337","pt":1724677133784,"mc":[{"id":"1.232283631","rc":[{"batb":[[0,2.44,4],[1,2.42,11.91],[2,2.36,28.26]],"ltp":2.42,"tv":122.07,"id":349}]}]}
{"op":"mcm","clk":"11936322539","pt":1724677136222,"mc":[{"id":"1.232283631","rc":[{"batb":[[0,2.42,11.91],[1,2.36,28.26],[2,1.9,1230.77]],"ltp":2.42,"tv":122.07,"id":349}]}]}
{"op":"mcm","clk":"11936323451","pt":1724677147289,"mc":[{"id":"1.232283631","rc":[{"batb":[[0,2.44,4],[1,2.42,11.91],[2,2.36,28.26]],"ltp":2.42,"tv":122.07,"id":349}]}]}
{"op":"mcm","clk":"11936323637","pt":1724677149724,"mc":[{"id":"1.232283631","rc":[{"batb":[[0,2.42,11.91],[1,2.36,28.26],[2,1.9,1230.77]],"ltp":2.42,"tv":122.07,"id":349}]}]}
{"op":"mcm","clk":"11936325387","pt":1724677173137,"mc":[{"id":"1.232283631","rc":[{"batb":[[0,2.44,4],[1,2.42,11.91],[2,2.36,28.26]],"ltp":2.42,"tv":122.07,"id":349}]}]}
{"op":"mcm","clk":"11936325558","pt":1724677175406,"mc":[{"id":"1.232283631","rc":[{"batb":[[0,2.42,11.91],[1,2.36,28.26],[2,1.9,1230.77]],"ltp":2.42,"tv":122.07,"id":349}]}]}
{"op":"mcm","clk":"11936326427","pt":1724677188720,"mc":[{"id":"1.232283631","rc":[{"batb":[[0,2.44,4],[1,2.42,11.91],[2,2.36,28.26]],"ltp":2.42,"tv":122.07,"id":349}]}]}
{"op":"mcm","clk":"11936326586","pt":1724677191167,"mc":[{"id":"1.232283631","rc":[{"batb":[[0,2.42,11.91],[1,2.36,28.26],[2,1.9,1230.77]],"ltp":2.42,"tv":122.07,"id":349}]}]}
{"op":"mcm","clk":"11936328349","pt":1724677210827,"mc":[{"id":"1.232283631","rc":[{"trd":[[2.44,121.67]],"batb":[[0,2.44,4],[1,2.42,11.9],[2,2.36,28.26]],"batl":[[1,5,51.32],[2,10,51.32]],"ltp":2.42,"tv":122.07,"id":349},{"trd":[[1.69,72.52],[1.7,58.83],[1.71,6.97]],"batb":[[0,1.65,34.33]],"batl":[[1,1.71,12679.36]],"ltp":1.7,"tv":138.31,"id":235}],"tv":260.39}]}
{"op":"mcm","clk":"11936328546","pt":1724677213199,"mc":[{"id":"1.232283631","rc":[{"batb":[[0,2.42,11.9],[1,2.36,28.26],[2,1.9,1230.77]],"ltp":2.42,"tv":122.07,"id":349}]}]}
{"op":"mcm","clk":"11936330814","pt":1724677239916,"mc":[{"id":"1.232283631","rc":[{"batb":[[0,2.44,4],[1,2.42,11.9],[2,2.36,28.26]],"ltp":2.42,"tv":122.07,"id":349}]}]}
{"op":"mcm","clk":"11936331020","pt":1724677242127,"mc":[{"id":"1.232283631","rc":[{"batb":[[0,2.42,11.9],[1,2.36,28.26],[2,1.9,1230.77]],"ltp":2.42,"tv":122.07,"id":349}]}]}
{"op":"mcm","clk":"11936332507","pt":1724677260826,"mc":[{"id":"1.232283631","rc":[{"batb":[[0,2.44,4],[1,2.42,11.9],[2,2.36,28.26]],"ltp":2.42,"tv":122.07,"id":349}]}]}
{"op":"mcm","clk":"11936332724","pt":1724677263350,"mc":[{"id":"1.232283631","rc":[{"batb":[[0,2.42,11.9],[1,2.36,28.26],[2,1.9,1230.77]],"ltp":2.42,"tv":122.07,"id":349}]}]}
{"op":"mcm","clk":"11936334831","pt":1724677287872,"mc":[{"id":"1.232283631","rc":[{"batb":[[0,2.44,4],[1,2.42,11.9],[2,2.36,28.26]],"ltp":2.42,"tv":122.07,"id":349}]}]}
{"op":"mcm","clk":"11936335051","pt":1724677290357,"mc":[{"id":"1.232283631","rc":[{"batb":[[0,2.42,11.9],[1,2.36,28.26],[2,1.9,1230.77]],"ltp":2.42,"tv":122.07,"id":349}]}]}
{"op":"mcm","clk":"11936335362","pt":1724677293565,"mc":[{"id":"1.232283631","rc":[{"batb":[[0,2.44,4],[1,2.42,11.9],[2,2.36,28.26]],"ltp":2.42,"tv":122.07,"id":349}]}]}
{"op":"mcm","clk":"11936335568","pt":1724677295985,"mc":[{"id":"1.232283631","rc":[{"batb":[[0,2.42,11.9],[1,2.36,28.26],[2,1.9,1230.77]],"ltp":2.42,"tv":122.07,"id":349}]}]}
{"op":"mcm","clk":"11936336666","pt":1724677307787,"mc":[{"id":"1.232283631","rc":[{"batb":[[0,2.44,4],[1,2.42,11.9],[2,2.36,28.26]],"ltp":2.42,"tv":122.07,"id":349}]}]}
{"op":"mcm","clk":"11936336864","pt":1724677310274,"mc":[{"id":"1.232283631","rc":[{"batb":[[0,2.42,11.9],[1,2.36,28.26],[2,1.9,1230.77]],"ltp":2.42,"tv":122.07,"id":349}]}]}
{"op":"mcm","clk":"11936340850","pt":1724677358018,"mc":[{"id":"1.232283631","rc":[{"batb":[[0,2.44,4],[1,2.42,11.9],[2,2.36,28.26]],"ltp":2.42,"tv":122.07,"id":349}]}]}
{"op":"mcm","clk":"11936341050","pt":1724677360561,"mc":[{"id":"1.232283631","rc":[{"batb":[[0,2.42,11.9],[1,2.36,28.26],[2,1.9,1230.77]],"ltp":2.42,"tv":122.07,"id":349}]}]}
{"op":"mcm","clk":"11936345523","pt":1724677413277,"mc":[{"id":"1.232283631","rc":[{"batb":[[0,2.44,4],[1,2.42,11.9],[2,2.36,28.26]],"ltp":2.42,"tv":122.07,"id":349}]}]}
{"op":"mcm","clk":"11936345730","pt":1724677415506,"mc":[{"id":"1.232283631","rc":[{"batb":[[0,2.42,11.9],[1,2.36,28.26],[2,1.9,1230.77]],"ltp":2.42,"tv":122.07,"id":349}]}]}
{"op":"mcm","clk":"11936345946","pt":1724677417895,"mc":[{"id":"1.232283631","rc":[{"batb":[[0,2.44,4],[1,2.42,11.9],[2,2.36,28.26]],"ltp":2.42,"tv":122.07,"id":349}]}]}
{"op":"mcm","clk":"11936346171","pt":1724677420274,"mc":[{"id":"1.232283631","rc":[{"batb":[[0,2.42,11.9],[1,2.36,28.26],[2,1.9,1230.77]],"ltp":2.42,"tv":122.07,"id":349}]}]}
{"op":"mcm","clk":"11936346814","pt":1724677427506,"mc":[{"id":"1.232283631","rc":[{"batb":[[0,2.44,4],[1,2.42,11.9],[2,2.36,28.26]],"ltp":2.42,"tv":122.07,"id":349}]}]}
{"op":"mcm","clk":"11936347043","pt":1724677429892,"mc":[{"id":"1.232283631","rc":[{"batb":[[0,2.42,11.9],[1,2.36,28.26],[2,1.9,1230.77]],"ltp":2.42,"tv":122.07,"id":349}]}]}
{"op":"mcm","clk":"11936351950","pt":1724677486289,"mc":[{"id":"1.232283631","rc":[{"batb":[[0,2.44,4],[1,2.42,11.9],[2,2.36,28.26]],"ltp":2.42,"tv":122.07,"id":349}]}]}
{"op":"mcm","clk":"11936352127","pt":1724677488675,"mc":[{"id":"1.232283631","rc":[{"batb":[[0,2.42,11.9],[1,2.36,28.26],[2,1.9,1230.77]],"ltp":2.42,"tv":122.07,"id":349}]}]}
{"op":"mcm","clk":"11936357505","pt":1724677551062,"mc":[{"id":"1.232283631","rc":[{"batb":[[0,2.44,4],[1,2.42,11.9],[2,2.36,28.26]],"ltp":2.42,"tv":122.07,"id":349}]}]}
{"op":"mcm","clk":"11936357698","pt":1724677553234,"mc":[{"id":"1.232283631","rc":[{"batb":[[0,2.42,11.9],[1,2.36,28.26],[2,1.9,1230.77]],"ltp":2.42,"tv":122.07,"id":349}]}]}
{"op":"mcm","clk":"11936358358","pt":1724677560765,"mc":[{"id":"1.232283631","rc":[{"batb":[[0,2.44,4],[1,2.42,11.9],[2,2.36,28.26]],"ltp":2.42,"tv":122.07,"id":349}]}]}
{"op":"mcm","clk":"11936358609","pt":1724677563269,"mc":[{"id":"1.232283631","rc":[{"batb":[[0,2.42,11.9],[1,2.36,28.26],[2,1.9,1230.77]],"ltp":2.42,"tv":122.07,"id":349}]}]}
{"op":"mcm","clk":"11936359209","pt":1724677569561,"mc":[{"id":"1.232283631","rc":[{"batb":[[0,2.44,4],[1,2.42,11.9],[2,2.36,28.26]],"ltp":2.42,"tv":122.07,"id":349}]}]}
{"op":"mcm","clk":"11936359415","pt":1724677571948,"mc":[{"id":"1.232283631","rc":[{"batb":[[0,2.42,11.9],[1,2.36,28.26],[2,1.9,1230.77]],"ltp":2.42,"tv":122.07,"id":349}]}]}
{"op":"mcm","clk":"11936360158","pt":1724677579764,"mc":[{"id":"1.232283631","rc":[{"batb":[[0,2.44,4],[1,2.42,11.9],[2,2.36,28.26]],"ltp":2.42,"tv":122.07,"id":349}]}]}
{"op":"mcm","clk":"11936360396","pt":1724677582091,"mc":[{"id":"1.232283631","rc":[{"batb":[[0,2.42,11.9],[1,2.36,28.26],[2,1.9,1230.77]],"ltp":2.42,"tv":122.07,"id":349}]}]}
{"op":"mcm","clk":"11936360668","pt":1724677584967,"mc":[{"id":"1.232283631","rc":[{"batb":[[0,2.44,4],[1,2.42,11.9],[2,2.36,28.26]],"ltp":2.42,"tv":122.07,"id":349}]}]}
{"op":"mcm","clk":"11936360886","pt":1724677587296,"mc":[{"id":"1.232283631","rc":[{"batb":[[0,2.42,11.9],[1,2.36,28.26],[2,1.9,1230.77]],"ltp":2.42,"tv":122.07,"id":349}]}]}
{"op":"mcm","clk":"11936364181","pt":1724677623647,"mc":[{"id":"1.232283631","rc":[{"batb":[[0,2.44,4],[1,2.42,11.9],[2,2.36,28.26]],"ltp":2.42,"tv":122.07,"id":349}]}]}
{"op":"mcm","clk":"11936364374","pt":1724677625936,"mc":[{"id":"1.232283631","rc":[{"batb":[[0,2.42,11.9],[1,2.36,28.26],[2,1.9,1230.77]],"ltp":2.42,"tv":122.07,"id":349}]}]}
{"op":"mcm","clk":"11936366118","pt":1724677646475,"mc":[{"id":"1.232283631","rc":[{"batb":[[0,2.44,4],[1,2.42,11.9],[2,2.36,28.26]],"ltp":2.42,"tv":122.07,"id":349}]}]}
{"op":"mcm","clk":"11936366319","pt":1724677648755,"mc":[{"id":"1.232283631","rc":[{"batb":[[0,2.42,11.9],[1,2.36,28.26],[2,1.9,1230.77]],"ltp":2.42,"tv":122.07,"id":349}]}]}
{"op":"mcm","clk":"11936366509","pt":1724677650955,"mc":[{"id":"1.232283631","rc":[{"batb":[[0,2.44,4],[1,2.42,11.9],[2,2.36,28.26]],"ltp":2.42,"tv":122.07,"id":349}]}]}
{"op":"mcm","clk":"11936366719","pt":1724677653172,"mc":[{"id":"1.232283631","rc":[{"batb":[[0,2.42,11.9],[1,2.36,28.26],[2,1.9,1230.77]],"ltp":2.42,"tv":122.07,"id":349}]}]}
{"op":"mcm","clk":"11936367800","pt":1724677664182,"mc":[{"id":"1.232283631","rc":[{"batb":[[0,2.44,4],[1,2.42,11.9],[2,2.36,28.26]],"ltp":2.42,"tv":122.07,"id":349}]}]}
{"op":"mcm","clk":"11936368002","pt":1724677666564,"mc":[{"id":"1.232283631","rc":[{"batb":[[0,2.42,11.9],[1,2.36,28.26],[2,1.9,1230.77]],"ltp":2.42,"tv":122.07,"id":349}]}]}
{"op":"mcm","clk":"11936368661","pt":1724677673321,"mc":[{"id":"1.232283631","rc":[{"batb":[[0,2.44,4],[1,2.42,11.9],[2,2.36,28.26]],"ltp":2.42,"tv":122.07,"id":349}]}]}
{"op":"mcm","clk":"11936368847","pt":1724677675476,"mc":[{"id":"1.232283631","rc":[{"batb":[[0,2.42,11.9],[1,2.36,28.26],[2,1.9,1230.77]],"ltp":2.42,"tv":122.07,"id":349}]}]}
{"op":"mcm","clk":"11936369054","pt":1724677677908,"mc":[{"id":"1.232283631","rc":[{"batb":[[0,2.44,4],[1,2.42,11.9],[2,2.36,28.26]],"ltp":2.42,"tv":122.07,"id":349}]}]}
{"op":"mcm","clk":"11936369254","pt":1724677680099,"mc":[{"id":"1.232283631","rc":[{"batb":[[0,2.42,11.9],[1,2.36,28.26],[2,1.9,1230.77]],"ltp":2.42,"tv":122.07,"id":349}]}]}
{"op":"mcm","clk":"11936369807","pt":1724677686388,"mc":[{"id":"1.232283631","rc":[{"batb":[[0,2.44,4],[1,2.42,11.9],[2,2.36,28.26]],"ltp":2.42,"tv":122.07,"id":349}]}]}
{"op":"mcm","clk":"11936370023","pt":1724677688776,"mc":[{"id":"1.232283631","rc":[{"batb":[[0,2.42,11.9],[1,2.36,28.26],[2,1.9,1230.77]],"ltp":2.42,"tv":122.07,"id":349}]}]}
{"op":"mcm","clk":"11936372262","pt":1724677714384,"mc":[{"id":"1.232283631","rc":[{"batb":[[0,2.44,4],[1,2.42,11.9],[2,2.36,28.26]],"ltp":2.42,"tv":122.07,"id":349}]}]}
{"op":"mcm","clk":"11936372463","pt":1724677716829,"mc":[{"id":"1.232283631","rc":[{"batb":[[0,2.42,11.9],[1,2.36,28.26],[2,1.9,1230.77]],"ltp":2.42,"tv":122.07,"id":349}]}]}
{"op":"mcm","clk":"11936376656","pt":1724677766784,"mc":[{"id":"1.232283631","rc":[{"batb":[[0,2.44,4],[1,2.42,11.9],[2,2.36,28.26]],"ltp":2.42,"tv":122.07,"id":349}]}]}
{"op":"mcm","clk":"11936376909","pt":1724677769172,"mc":[{"id":"1.232283631","rc":[{"batb":[[0,2.42,11.9],[1,2.36,28.26],[2,1.9,1230.77]],"ltp":2.42,"tv":122.07,"id":349}]}]}
{"op":"mcm","clk":"11936380660","pt":1724677809552,"mc":[{"id":"1.232283631","rc":[{"batb":[[0,2.44,4],[1,2.42,11.9],[2,2.36,28.26]],"ltp":2.42,"tv":122.07,"id":349}]}]}
{"op":"mcm","clk":"11936380908","pt":1724677811954,"mc":[{"id":"1.232283631","rc":[{"batb":[[0,2.42,11.9],[1,2.36,28.26],[2,1.9,1230.77]],"ltp":2.42,"tv":122.07,"id":349}]}]}
{"op":"mcm","clk":"11936383397","pt":1724677837487,"mc":[{"id":"1.232283631","rc":[{"batb":[[0,2.44,4],[1,2.42,11.9],[2,2.36,28.26]],"ltp":2.42,"tv":122.07,"id":349}]}]}
{"op":"mcm","clk":"11936383593","pt":1724677839780,"mc":[{"id":"1.232283631","rc":[{"batb":[[0,2.42,11.9],[1,2.36,28.26],[2,1.9,1230.77]],"ltp":2.42,"tv":122.07,"id":349}]}]}
{"op":"mcm","clk":"11936418334","pt":1724678198882,"mc":[{"id":"1.232283631","rc":[{"trd":[[2.54,0.04]],"batb":[[0,2.44,4],[1,2.42,11.9],[2,2.36,28.26]],"ltp":2.54,"tv":122.11,"id":349},{"trd":[[1.65,0.07]],"batb":[[0,1.65,34.26]],"ltp":1.65,"tv":138.38,"id":235}],"tv":260.5}]}
{"op":"mcm","clk":"11936418540","pt":1724678201075,"mc":[{"id":"1.232283631","rc":[{"batb":[[0,2.42,11.9],[1,2.36,28.26],[2,1.9,1230.77]],"ltp":2.54,"tv":122.11,"id":349}]}]}
{"op":"mcm","clk":"11936418682","pt":1724678202481,"mc":[{"id":"1.232283631","rc":[{"trd":[[2.54,0.09]],"ltp":2.54,"tv":122.16,"id":349},{"trd":[[1.65,0.14]],"batb":[[0,1.65,34.19]],"ltp":1.65,"tv":138.45,"id":235}],"tv":260.62}]}
{"op":"mcm","clk":"11936419228","pt":1724678209674,"mc":[{"id":"1.232283631","rc":[{"trd":[[2.54,0.13]],"batb":[[0,2.44,4],[1,2.42,11.9],[2,2.36,28.26]],"ltp":2.54,"tv":122.2,"id":349},{"trd":[[1.65,0.21]],"batb":[[0,1.65,34.12]],"ltp":1.65,"tv":138.52,"id":235}],"tv":260.73}]}
{"op":"mcm","clk":"11936419374","pt":1724678211979,"mc":[{"id":"1.232283631","rc":[{"batb":[[0,2.42,11.9],[1,2.36,28.26],[2,1.9,1230.77]],"ltp":2.54,"tv":122.2,"id":349}]}]}
{"op":"mcm","clk":"11936419693","pt":1724678215860,"mc":[{"id":"1.232283631","rc":[{"trd":[[2.54,0.17]],"batb":[[0,2.44,4],[1,2.42,11.9],[2,2.36,28.26]],"ltp":2.54,"tv":122.24,"id":349},{"trd":[[1.65,0.28]],"batb":[[0,1.65,34.05]],"ltp":1.65,"tv":138.59,"id":235}],"tv":260.84}]}
{"op":"mcm","clk":"11936419857","pt":1724678218202,"mc":[{"id":"1.232283631","rc":[{"batb":[[0,2.42,11.9],[1,2.36,28.26],[2,1.9,1230.77]],"ltp":2.54,"tv":122.24,"id":349}]}]}
{"op":"mcm","clk":"11936419908","pt":1724678218984,"mc":[{"id":"1.232283631","rc":[{"batb":[[0,2.46,26.33],[1,2.42,11.9]],"ltp":2.54,"tv":122.24,"id":349}]}]}
{"op":"mcm","clk":"11936419987","pt":1724678219974,"mc":[{"id":"1.232283631","rc":[{"batb":[[1,1.9,1230.77],[2,1.45,57.02]],"ltp":2.54,"tv":122.24,"id":349}]}]}
{"op":"mcm","clk":"11936425035","pt":1724678282265,"mc":[{"id":"1.232283631","rc":[{"batb":[[0,2.48,4],[1,2.46,26.33],[2,1.9,1230.77]],"ltp":2.54,"tv":122.24,"id":349},{"batl":[[0,1.71,12679.36],[1,1.72,246.15],[2,1.75,138.46]],"ltp":1.65,"tv":138.59,"id":235}]}]}
{"op":"mcm","clk":"11936425235","pt":1724678284547,"mc":[{"id":"1.232283631","rc":[{"batb":[[0,2.46,26.33],[1,1.9,1230.77],[2,1.45,57.02]],"ltp":2.54,"tv":122.24,"id":349}]}]}
{"op":"mcm","clk":"11936431320","pt":1724678358955,"mc":[{"id":"1.232283631","rc":[{"batb":[[0,2.48,4],[1,2.46,26.33],[2,1.9,1230.77]],"ltp":2.54,"tv":122.24,"id":349}]}]}
{"op":"mcm","clk":"11936431524","pt":1724678361233,"mc":[{"id":"1.232283631","rc":[{"batb":[[0,2.46,26.33],[1,1.9,1230.77],[2,1.45,57.02]],"ltp":2.54,"tv":122.24,"id":349}]}]}
{"op":"mcm","clk":"11936444133","pt":1724678501786,"mc":[{"id":"1.232283631","rc":[{"batb":[[0,2.48,4],[1,2.46,26.33],[2,1.9,1230.77]],"ltp":2.54,"tv":122.24,"id":349}]}]}
{"op":"mcm","clk":"11936444335","pt":1724678504010,"mc":[{"id":"1.232283631","rc":[{"batb":[[0,2.46,26.33],[1,1.9,1230.77],[2,1.45,57.02]],"ltp":2.54,"tv":122.24,"id":349}]}]}
{"op":"mcm","clk":"11936445995","pt":1724678522238,"mc":[{"id":"1.232283631","rc":[{"batb":[[0,2.48,4],[1,2.46,26.33],[2,1.9,1230.77]],"ltp":2.54,"tv":122.24,"id":349}]}]}
{"op":"mcm","clk":"11936446212","pt":1724678524630,"mc":[{"id":"1.232283631","rc":[{"batb":[[0,2.46,26.33],[1,1.9,1230.77],[2,1.45,57.02]],"ltp":2.54,"tv":122.24,"id":349}]}]}
{"op":"mcm","clk":"11936446679","pt":1724678529734,"mc":[{"id":"1.232283631","rc":[{"batb":[[0,2.48,4],[1,2.46,26.33],[2,1.9,1230.77]],"ltp":2.54,"tv":122.24,"id":349}]}]}
{"op":"mcm","clk":"11936446907","pt":1724678532151,"mc":[{"id":"1.232283631","rc":[{"batb":[[0,2.46,26.33],[1,1.9,1230.77],[2,1.45,57.02]],"ltp":2.54,"tv":122.24,"id":349}]}]}
{"op":"mcm","clk":"11936447344","pt":1724678536837,"mc":[{"id":"1.232283631","rc":[{"batb":[[0,2.48,4],[1,2.46,26.33],[2,1.9,1230.77]],"ltp":2.54,"tv":122.24,"id":349}]}]}
{"op":"mcm","clk":"11936447559","pt":1724678539325,"mc":[{"id":"1.232283631","rc":[{"batb":[[0,2.46,26.33],[1,1.9,1230.77],[2,1.45,57.02]],"ltp":2.54,"tv":122.24,"id":349}]}]}
{"op":"mcm","clk":"11936448055","pt":1724678545743,"mc":[{"id":"1.232283631","rc":[{"batb":[[0,2.48,4],[1,2.46,26.33],[2,1.9,1230.77]],"ltp":2.54,"tv":122.24,"id":349}]}]}
{"op":"mcm","clk":"11936448267","pt":1724678548061,"mc":[{"id":"1.232283631","rc":[{"batb":[[0,2.46,26.33],[1,1.9,1230.77],[2,1.45,57.02]],"ltp":2.54,"tv":122.24,"id":349}]}]}
{"op":"mcm","clk":"11936448879","pt":1724678554976,"mc":[{"id":"1.232283631","rc":[{"batb":[[0,2.48,4],[1,2.46,26.33],[2,1.9,1230.77]],"ltp":2.54,"tv":122.24,"id":349}]}]}
{"op":"mcm","clk":"11936449078","pt":1724678557379,"mc":[{"id":"1.232283631","rc":[{"batb":[[0,2.46,26.33],[1,1.9,1230.77],[2,1.45,57.02]],"ltp":2.54,"tv":122.24,"id":349}]}]}
{"op":"mcm","clk":"11936450220","pt":1724678570495,"mc":[{"id":"1.232283631","rc":[{"batb":[[0,2.48,4],[1,2.46,26.33],[2,1.9,1230.77]],"ltp":2.54,"tv":122.24,"id":349}]}]}
{"op":"mcm","clk":"11936450435","pt":1724678572802,"mc":[{"id":"1.232283631","rc":[{"batb":[[0,2.46,26.33],[1,1.9,1230.77],[2,1.45,57.02]],"ltp":2.54,"tv":122.24,"id":349}]}]}
{"op":"mcm","clk":"11936451654","pt":1724678585901,"mc":[{"id":"1.232283631","rc":[{"batb":[[0,2.48,4],[1,2.46,26.33],[2,1.9,1230.77]],"ltp":2.54,"tv":122.24,"id":349}]}]}
{"op":"mcm","clk":"11936451861","pt":1724678588122,"mc":[{"id":"1.232283631","rc":[{"batb":[[0,2.46,26.33],[1,1.9,1230.77],[2,1.45,57.02]],"ltp":2.54,"tv":122.24,"id":349}]}]}
{"op":"mcm","clk":"11936453455","pt":1724678605523,"mc":[{"id":"1.232283631","rc":[{"batb":[[0,2.48,4],[1,2.46,26.33],[2,1.9,1230.77]],"ltp":2.54,"tv":122.24,"id":349}]}]}
{"op":"mcm","clk":"11936453681","pt":1724678607742,"mc":[{"id":"1.232283631","rc":[{"batb":[[0,2.46,26.33],[1,1.9,1230.77],[2,1.45,57.02]],"ltp":2.54,"tv":122.24,"id":349}]}]}
{"op":"mcm","clk":"11936455449","pt":1724678626452,"mc":[{"id":"1.232283631","rc":[{"batb":[[0,2.48,4],[1,2.46,26.33],[2,1.9,1230.77]],"ltp":2.54,"tv":122.24,"id":349}]}]}
{"op":"mcm","clk":"11936455680","pt":1724678628956,"mc":[{"id":"1.232283631","rc":[{"batb":[[0,2.46,26.33],[1,1.9,1230.77],[2,1.45,57.02]],"ltp":2.54,"tv":122.24,"id":349}]}]}
{"op":"mcm","clk":"11936457841","pt":1724678653159,"mc":[{"id":"1.232283631","rc":[{"batb":[[0,2.48,4],[1,2.46,26.33],[2,1.9,1230.77]],"ltp":2.54,"tv":122.24,"id":349}]}]}
{"op":"mcm","clk":"11936458038","pt":1724678655484,"mc":[{"id":"1.232283631","rc":[{"batb":[[0,2.46,26.33],[1,1.9,1230.77],[2,1.45,57.02]],"ltp":2.54,"tv":122.24,"id":349}]}]}
{"op":"mcm","clk":"11936458884","pt":1724678663964,"mc":[{"id":"1.232283631","rc":[{"batb":[[0,2.48,4],[1,2.46,26.33],[2,1.9,1230.77]],"ltp":2.54,"tv":122.24,"id":349}]}]}
{"op":"mcm","clk":"11936459121","pt":1724678666179,"mc":[{"id":"1.232283631","rc":[{"batb":[[0,2.46,26.33],[1,1.9,1230.77],[2,1.45,57.02]],"ltp":2.54,"tv":122.24,"id":349}]}]}
{"op":"mcm","clk":"11936465276","pt":1724678730245,"mc":[{"id":"1.232283631","rc":[{"batb":[[0,2.48,4],[1,2.46,26.33],[2,1.9,1230.77]],"ltp":2.54,"tv":122.24,"id":349}]}]}
{"op":"mcm","clk":"11936465521","pt":1724678732651,"mc":[{"id":"1.232283631","rc":[{"batb":[[0,2.46,26.33],[1,1.9,1230.77],[2,1.45,57.02]],"ltp":2.54,"tv":122.24,"id":349}]}]}
{"op":"mcm","clk":"11936478026","pt":1724678865989,"mc":[{"id":"1.232283631","rc":[{"batb":[[0,2.48,4],[1,2.46,26.33],[2,1.9,1230.77]],"ltp":2.54,"tv":122.24,"id":349}]}]}
{"op":"mcm","clk":"11936478261","pt":1724678868282,"mc":[{"id":"1.232283631","rc":[{"batb":[[0,2.46,26.33],[1,1.9,1230.77],[2,1.45,57.02]],"ltp":2.54,"tv":122.24,"id":349}]}]}
{"op":"mcm","clk":"11936492026","pt":1724679009853,"mc":[{"id":"1.232283631","rc":[{"batb":[[0,2.48,4],[1,2.46,26.33],[2,1.9,1230.77]],"ltp":2.54,"tv":122.24,"id":349}]}]}
{"op":"mcm","clk":"11936492290","pt":1724679012312,"mc":[{"id":"1.232283631","rc":[{"batb":[[0,2.46,26.33],[1,1.9,1230.77],[2,1.45,57.02]],"ltp":2.54,"tv":122.24,"id":349}]}]}
{"op":"mcm","clk":"11936494000","pt":1724679028158,"mc":[{"id":"1.232283631","rc":[{"batb":[[0,2.48,4],[1,2.46,26.33],[2,1.9,1230.77]],"ltp":2.54,"tv":122.24,"id":349},{"batb":[[0,1.66,10.27],[1,1.65,34.05],[2,1.64,262.54]],"ltp":1.65,"tv":138.59,"id":235}]}]}
{"op":"mcm","clk":"11936494242","pt":1724679030332,"mc":[{"id":"1.232283631","rc":[{"batb":[[0,2.46,26.33],[1,1.9,1230.77],[2,1.45,57.02]],"ltp":2.54,"tv":122.24,"id":349}]}]}
{"op":"mcm","clk":"11936494588","pt":1724679033671,"mc":[{"id":"1.232283631","rc":[{"batb":[[0,2.48,4],[1,2.46,26.33],[2,1.9,1230.77]],"ltp":2.54,"tv":122.24,"id":349}]}]}
{"op":"mcm","clk":"11936494855","pt":1724679036053,"mc":[{"id":"1.232283631","rc":[{"batb":[[0,2.46,26.33],[1,1.9,1230.77],[2,1.45,57.02]],"ltp":2.54,"tv":122.24,"id":349}]}]}
{"op":"mcm","clk":"11936498417","pt":1724679069604,"mc":[{"id":"1.232283631","rc":[{"batb":[[0,2.48,4],[1,2.46,26.33],[2,1.9,1230.77]],"ltp":2.54,"tv":122.24,"id":349}]}]}
{"op":"mcm","clk":"11936498690","pt":1724679071914,"mc":[{"id":"1.232283631","rc":[{"batb":[[0,2.46,26.33],[1,1.9,1230.77],[2,1.45,57.02]],"ltp":2.54,"tv":122.24,"id":349}]}]}
{"op":"mcm","clk":"11936502983","pt":1724679112250,"mc":[{"id":"1.232283631","rc":[{"trd":[[2.46,0.1]],"batb":[[0,2.48,4],[1,2.46,52.61],[2,1.9,1230.77]],"ltp":2.46,"tv":122.34,"id":349}],"tv":260.94}]}
{"op":"mcm","clk":"11936502997","pt":1724679112353,"mc":[{"id":"1.232283631","rc":[{"batb":[[1,2.46,26.33]],"ltp":2.46,"tv":122.34,"id":349}]}]}
{"op":"mcm","clk":"11936503154","pt":1724679113863,"mc":[{"id":"1.232283631","rc":[{"batb":[[0,2.46,26.33],[1,1.9,1230.77],[2,1.45,57.02]],"ltp":2.46,"tv":122.34,"id":349}]}]}
{"op":"mcm","clk":"11936503586","pt":1724679118065,"mc":[{"id":"1.232283631","rc":[{"batb":[[0,2.48,4],[1,2.46,26.33],[2,1.9,1230.77]],"ltp":2.46,"tv":122.34,"id":349}]}]}
{"op":"mcm","clk":"11936503822","pt":1724679120352,"mc":[{"id":"1.232283631","rc":[{"batb":[[0,2.46,26.33],[1,1.9,1230.77],[2,1.45,57.02]],"ltp":2.46,"tv":122.34,"id":349}]}]}
{"op":"mcm","clk":"11936504458","pt":1724679125732,"mc":[{"id":"1.232283631","rc":[{"trd":[[2.46,0.2]],"batb":[[0,2.48,4],[1,2.46,26.28],[2,1.9,1230.77]],"ltp":2.46,"tv":122.44,"id":349}],"tv":261.04}]}
{"op":"mcm","clk":"11936504632","pt":1724679127249,"mc":[{"id":"1.232283631","rc":[{"batb":[[1,2.46,26.33]],"ltp":2.46,"tv":122.44,"id":349}]}]}
{"op":"mcm","clk":"11936504733","pt":1724679128145,"mc":[{"id":"1.232283631","rc":[{"batb":[[0,2.46,26.33],[1,1.9,1230.77],[2,1.45,57.02]],"ltp":2.46,"tv":122.44,"id":349}]}]}
{"op":"mcm","clk":"11936505320","pt":1724679132743,"mc":[{"id":"1.232283631","rc":[{"trd":[[2.46,0.3]],"batb":[[0,2.48,4],[1,2.46,26.28],[2,1.9,1230.77]],"ltp":2.46,"tv":122.55,"id":349}],"tv":261.15}]}
{"op":"mcm","clk":"11936505573","pt":1724679134870,"mc":[{"id":"1.232283631","rc":[{"batb":[[0,2.46,26.28],[1,1.9,1230.77],[2,1.45,57.02]],"ltp":2.46,"tv":122.55,"id":349}]}]}
{"op":"mcm","clk":"11936505863","pt":1724679137484,"mc":[{"id":"1.232283631","rc":[{"batb":[[0,2.48,4],[1,2.46,26.33],[2,1.9,1230.77]],"ltp":2.46,"tv":122.55,"id":349}]}]}
{"op":"mcm","clk":"11936506144","pt":1724679139871,"mc":[{"id":"1.232283631","rc":[{"batb":[[0,2.46,26.33],[1,1.9,1230.77],[2,1.45,57.02]],"ltp":2.46,"tv":122.55,"id":349}]}]}
{"op":"mcm","clk":"11936506699","pt":1724679145075,"mc":[{"id":"1.232283631","rc":[{"trd":[[2.46,0.34]],"batb":[[0,2.48,4],[1,2.46,26.31],[2,1.9,1230.77]],"ltp":2.46,"tv":122.58,"id":349}],"tv":261.18}]}
{"op":"mcm","clk":"11936506945","pt":1724679147373,"mc":[{"id":"1.232283631","rc":[{"batb":[[0,2.46,26.33],[1,1.9,1230.77],[2,1.45,57.02]],"ltp":2.46,"tv":122.58,"id":349}]}]}
{"op":"mcm","clk":"11936508638","pt":1724679164003,"mc":[{"id":"1.232283631","rc":[{"trd":[[2.46,0.4]],"batb":[[0,2.48,4],[1,2.46,26.3],[2,1.9,1230.77]],"ltp":2.46,"tv":122.64,"id":349}],"tv":261.24}]}
{"op":"mcm","clk":"11936508872","pt":1724679166204,"mc":[{"id":"1.232283631","rc":[{"batb":[[0,2.46,26.3],[1,1.9,1230.77],[2,1.45,57.02]],"ltp":2.46,"tv":122.64,"id":349}]}]}
{"op":"mcm","clk":"11936509003","pt":1724679167506,"mc":[{"id":"1.232283631","rc":[{"batb":[[0,2.46,26.33]],"ltp":2.46,"tv":122.64,"id":349}]}]}
{"op":"mcm","clk":"11936512037","pt":1724679194626,"mc":[{"id":"1.232283631","rc":[{"batb":[[0,2.48,4],[1,2.46,26.33],[2,1.9,1230.77]],"ltp":2.46,"tv":122.64,"id":349}]}]}
{"op":"mcm","clk":"11936512289","pt":1724679196815,"mc":[{"id":"1.232283631","rc":[{"batb":[[0,2.46,26.33],[1,1.9,1230.77],[2,1.45,57.02]],"ltp":2.46,"tv":122.64,"id":349}]}]}
{"op":"mcm","clk":"11936515200","pt":1724679222848,"mc":[{"id":"1.232283631","rc":[{"batb":[[0,2.48,4],[1,2.46,26.33],[2,1.9,1230.77]],"ltp":2.46,"tv":122.64,"id":349}]}]}
{"op":"mcm","clk":"11936515441","pt":1724679225043,"mc":[{"id":"1.232283631","rc":[{"batb":[[0,2.46,26.33],[1,1.9,1230.77],[2,1.45,57.02]],"ltp":2.46,"tv":122.64,"id":349}]}]}
{"op":"mcm","clk":"11936518850","pt":1724679256407,"mc":[{"id":"1.232283631","rc":[{"batb":[[0,2.48,4],[1,2.46,26.33],[2,1.9,1230.77]],"ltp":2.46,"tv":122.64,"id":349}]}]}
{"op":"mcm","clk":"11936519117","pt":1724679258580,"mc":[{"id":"1.232283631","rc":[{"batb":[[0,2.46,26.33],[1,1.9,1230.77],[2,1.45,57.02]],"ltp":2.46,"tv":122.64,"id":349}]}]}
{"op":"mcm","clk":"11936521440","pt":1724679280229,"mc":[{"id":"1.232283631","rc":[{"batb":[[0,2.48,4],[1,2.46,26.33],[2,1.9,1230.77]],"ltp":2.46,"tv":122.64,"id":349}]}]}
{"op":"mcm","clk":"11936521684","pt":1724679282618,"mc":[{"id":"1.232283631","rc":[{"batb":[[0,2.46,26.33],[1,1.9,1230.77],[2,1.45,57.02]],"ltp":2.46,"tv":122.64,"id":349}]}]}
{"op":"mcm","clk":"11936522972","pt":1724679294241,"mc":[{"id":"1.232283631","rc":[{"batb":[[0,2.48,4],[1,2.46,26.33],[2,1.9,1230.77]],"ltp":2.46,"tv":122.64,"id":349}]}]}
{"op":"mcm","clk":"11936523217","pt":1724679296557,"mc":[{"id":"1.232283631","rc":[{"batb":[[0,2.46,26.33],[1,1.9,1230.77],[2,1.45,57.02]],"ltp":2.46,"tv":122.64,"id":349}]}]}
{"op":"mcm","clk":"11936523506","pt":1724679298847,"mc":[{"id":"1.232283631","rc":[{"batb":[[0,2.48,4],[1,2.46,26.33],[2,1.9,1230.77]],"ltp":2.46,"tv":122.64,"id":349}]}]}
{"op":"mcm","clk":"11936523759","pt":1724679301013,"mc":[{"id":"1.232283631","rc":[{"batb":[[0,2.46,26.33],[1,1.9,1230.77],[2,1.45,57.02]],"ltp":2.46,"tv":122.64,"id":349}]}]}
{"op":"mcm","clk":"11936525106","pt":1724679313051,"mc":[{"id":"1.232283631","rc":[{"batb":[[0,2.48,4],[1,2.46,27.95],[2,1.9,1230.77]],"ltp":2.46,"tv":122.64,"id":349}]}]}
{"op":"mcm","clk":"11936525363","pt":1724679315279,"mc":[{"id":"1.232283631","rc":[{"batb":[[0,2.46,27.95],[1,1.9,1230.77],[2,1.45,57.02]],"ltp":2.46,"tv":122.64,"id":349}]}]}
{"op":"mcm","clk":"11936543433","pt":1724679497749,"mc":[{"id":"1.232283631","rc":[{"batb":[[0,2.48,4],[1,2.46,27.95],[2,1.9,1230.77]],"ltp":2.46,"tv":122.64,"id":349}]}]}
{"op":"mcm","clk":"11936543646","pt":1724679499938,"mc":[{"id":"1.232283631","rc":[{"batb":[[0,2.46,27.95],[1,1.9,1230.77],[2,1.45,57.02]],"ltp":2.46,"tv":122.64,"id":349}]}]}
{"op":"mcm","clk":"11936550959","pt":1724679578811,"mc":[{"id":"1.232283631","rc":[{"batb":[[0,2.48,4],[1,2.46,27.95],[2,1.9,1230.77]],"ltp":2.46,"tv":122.64,"id":349}]}]}
{"op":"mcm","clk":"11936551122","pt":1724679580841,"mc":[{"id":"1.232283631","rc":[{"trd":[[2.52,0.01]],"ltp":2.52,"tv":122.66,"id":349},{"trd":[[1.66,0.02]],"batb":[[0,1.66,10.25]],"ltp":1.66,"tv":138.61,"id":235}],"tv":261.28}]}
{"op":"mcm","clk":"11936551182","pt":1724679581313,"mc":[{"id":"1.232283631","rc":[{"batb":[[0,2.46,27.95],[1,1.9,1230.77],[2,1.45,57.02]],"ltp":2.52,"tv":122.66,"id":349}]}]}
{"op":"mcm","clk":"11936551546","pt":1724679585525,"mc":[{"id":"1.232283631","rc":[{"trd":[[2.52,0.03]],"batb":[[0,2.48,4],[1,2.46,27.95],[2,1.9,1230.77]],"ltp":2.52,"tv":122.67,"id":349},{"trd":[[1.66,0.04]],"batb":[[0,1.66,10.23]],"ltp":1.66,"tv":138.63,"id":235}],"tv":261.31}]}
{"op":"mcm","clk":"11936551757","pt":1724679587854,"mc":[{"id":"1.232283631","rc":[{"batb":[[0,2.46,27.95],[1,1.9,1230.77],[2,1.45,57.02]],"ltp":2.52,"tv":122.67,"id":349}]}]}
{"op":"mcm","clk":"11936551819","pt":1724679588578,"mc":[{"id":"1.232283631","rc":[{"trd":[[2.52,0.04]],"ltp":2.52,"tv":122.68,"id":349},{"trd":[[1.66,0.06]],"batb":[[0,1.66,10.21]],"ltp":1.66,"tv":138.65,"id":235}],"tv":261.34}]}
{"op":"mcm","clk":"11936552152","pt":1724679591957,"mc":[{"id":"1.232283631","rc":[{"trd":[[2.52,0.05]],"batb":[[0,2.48,4],[1,2.46,27.95],[2,1.9,1230.77]],"ltp":2.52,"tv":122.7,"id":349},{"trd":[[1.66,0.08]],"batb":[[0,1.66,10.19]],"ltp":1.66,"tv":138.67,"id":235}],"tv":261.38}]}
{"op":"mcm","clk":"11936552378","pt":1724679594541,"mc":[{"id":"1.232283631","rc":[{"trd":[[2.46,3.31],[2.48,4],[2.52,0.07]],"batb":[[0,2.46,25.04],[1,1.9,1230.77],[2,1.45,57.02]],"ltp":2.52,"tv":129.62,"id":349},{"trd":[[1.66,0.1],[1.68,5.9],[1.69,76.76]],"batb":[[0,1.66,10.17]],"ltp":1.66,"tv":148.83,"id":235}],"tv":278.46}]}
{"op":"mcm","clk":"11936552630","pt":1724679597741,"mc":[{"id":"1.232283631","rc":[{"trd":[[2.52,0.08]],"batb":[[0,2.48,4],[1,2.46,25.04],[2,1.9,1230.77]],"ltp":2.52,"tv":129.63,"id":349},{"trd":[[1.66,0.12]],"batb":[[0,1.66,10.15]],"ltp":1.66,"tv":148.85,"id":235}],"tv":278.49}]}
{"op":"mcm","clk":"11936552758","pt":1724679599039,"mc":[{"id":"1.232283631","rc":[{"batb":[[1,2.46,27.95]],"ltp":2.52,"tv":129.63,"id":349}]}]}
{"op":"mcm","clk":"11936552862","pt":1724679600065,"mc":[{"id":"1.232283631","rc":[{"batb":[[0,2.46,27.95],[1,1.9,1230.77],[2,1.45,57.02]],"ltp":2.52,"tv":129.63,"id":349}]}]}
{"op":"mcm","clk":"11936552938","pt":1724679600744,"mc":[{"id":"1.232283631","rc":[{"trd":[[2.52,0.09]],"ltp":2.52,"tv":129.64,"id":349},{"trd":[[1.66,0.14]],"batb":[[0,1.66,10.13]],"ltp":1.66,"tv":148.87,"id":235}],"tv":278.52}]}
{"op":"mcm","clk":"11936553586","pt":1724679607152,"mc":[{"id":"1.232283631","rc":[{"batb":[[0,2.48,4],[1,2.46,27.95],[2,1.9,1230.77]],"ltp":2.52,"tv":129.64,"id":349}]}]}
{"op":"mcm","clk":"11936553740","pt":1724679608560,"mc":[{"id":"1.232283631","rc":[{"trd":[[2.52,0.1]],"ltp":2.52,"tv":129.66,"id":349},{"trd":[[1.66,0.16]],"batb":[[0,1.66,10.11]],"ltp":1.66,"tv":148.89,"id":235}],"tv":278.56}]}
{"op":"mcm","clk":"11936553822","pt":1724679609349,"mc":[{"id":"1.232283631","rc":[{"batb":[[0,2.46,27.95],[1,1.9,1230.77],[2,1.45,57.02]],"ltp":2.52,"tv":129.66,"id":349}]}]}
{"op":"mcm","clk":"11936554242","pt":1724679613175,"mc":[{"id":"1.232283631","rc":[{"trd":[[2.52,0.12]],"ltp":2.52,"tv":129.67,"id":349},{"trd":[[1.66,0.18]],"batb":[[0,1.66,10.09]],"ltp":1.66,"tv":148.91,"id":235}],"tv":278.59}]}
{"op":"mcm","clk":"11936554256","pt":1724679613270,"mc":[{"id":"1.232283631","rc":[{"batb":[[0,2.48,4],[1,2.46,27.95],[2,1.9,1230.77]],"ltp":2.52,"tv":129.67,"id":349}]}]}
{"op":"mcm","clk":"11936554458","pt":1724679615474,"mc":[{"id":"1.232283631","rc":[{"batb":[[0,2.46,27.95],[1,1.9,1230.77],[2,1.45,57.02]],"ltp":2.52,"tv":129.67,"id":349}]}]}
{"op":"mcm","clk":"11936554696","pt":1724679617876,"mc":[{"id":"1.232283631","rc":[{"trd":[[2.52,0.13]],"batb":[[0,2.48,4],[1,2.46,27.95],[2,1.9,1230.77]],"ltp":2.52,"tv":129.68,"id":349},{"trd":[[1.66,0.2]],"batb":[[0,1.66,10.07]],"ltp":1.66,"tv":148.93,"id":235}],"tv":278.62}]}
{"op":"mcm","clk":"11936554951","pt":1724679620358,"mc":[{"id":"1.232283631","rc":[{"batb":[[0,2.46,27.95],[1,1.9,1230.77],[2,1.45,57.02]],"ltp":2.52,"tv":129.68,"id":349}]}]}
{"op":"mcm","clk":"11936555533","pt":1724679626984,"mc":[{"id":"1.232283631","rc":[{"trd":[[2.52,0.14]],"batb":[[0,2.48,4],[1,2.46,27.95],[2,1.9,1230.77]],"ltp":2.52,"tv":129.69,"id":349},{"trd":[[1.66,0.22]],"batb":[[0,1.66,10.05]],"ltp":1.66,"tv":148.95,"id":235}],"tv":278.65}]}
{"op":"mcm","clk":"11936555837","pt":1724679629969,"mc":[{"id":"1.232283631","rc":[{"trd":[[2.52,0.15]],"batb":[[0,2.46,27.95],[1,1.9,1230.77],[2,1.45,57.02]],"ltp":2.52,"tv":129.71,"id":349},{"trd":[[1.66,0.24]],"batb":[[0,1.66,10.03]],"ltp":1.66,"tv":148.97,"id":235}],"tv":278.69}]}
{"op":"mcm","clk":"11936556112","pt":1724679632935,"mc":[{"id":"1.232283631","rc":[{"trd":[[2.52,0.17]],"batb":[[0,2.48,4],[1,2.46,27.95],[2,1.9,1230.77]],"ltp":2.52,"tv":129.72,"id":349},{"trd":[[1.66,0.26]],"batb":[[0,1.66,10.01]],"ltp":1.66,"tv":148.99,"id":235}],"tv":278.72}]}
{"op":"mcm","clk":"11936556339","pt":1724679635236,"mc":[{"id":"1.232283631","rc":[{"batb":[[0,2.46,27.95],[1,1.9,1230.77],[2,1.45,57.02]],"ltp":2.52,"tv":129.72,"id":349}]}]}
{"op":"mcm","clk":"11936556446","pt":1724679636379,"mc":[{"id":"1.232283631","rc":[{"trd":[[2.52,0.18]],"ltp":2.52,"tv":129.73,"id":349},{"trd":[[1.66,0.27]],"batb":[[0,1.66,10]],"ltp":1.66,"tv":149.0,"id":235}],"tv":278.74}]}
{"op":"mcm","clk":"11936565792","pt":1724679732038,"mc":[{"id":"1.232283631","rc":[{"batb":[[0,2.48,4],[1,2.46,27.95],[2,1.9,1230.77]],"ltp":2.52,"tv":129.73,"id":349}]}]}
{"op":"mcm","clk":"11936566039","pt":1724679734363,"mc":[{"id":"1.232283631","rc":[{"batb":[[0,2.46,27.95],[1,1.9,1230.77],[2,1.45,57.02]],"ltp":2.52,"tv":129.73,"id":349}]}]}
{"op":"mcm","clk":"11936567392","pt":1724679747072,"mc":[{"id":"1.232283631","rc":[{"batb":[[0,2.48,4],[1,2.46,27.95],[2,1.9,1230.77]],"ltp":2.52,"tv":129.73,"id":349}]}]}
{"op":"mcm","clk":"11936567655","pt":1724679749569,"mc":[{"id":"1.232283631","rc":[{"batb":[[0,2.46,27.95],[1,1.9,1230.77],[2,1.45,57.02]],"ltp":2.52,"tv":129.73,"id":349}]}]}
{"op":"mcm","clk":"11936568513","pt":1724679758883,"mc":[{"id":"1.232283631","rc":[{"batb":[[0,2.48,4],[1,2.46,27.95],[2,1.9,1230.77]],"ltp":2.52,"tv":129.73,"id":349}]}]}
{"op":"mcm","clk":"11936568739","pt":1724679761183,"mc":[{"id":"1.232283631","rc":[{"batb":[[0,2.46,27.95],[1,1.9,1230.77],[2,1.45,57.02]],"ltp":2.52,"tv":129.73,"id":349}]}]}
{"op":"mcm","clk":"11936582491","pt":1724679789628,"mc":[{"id":"1.232283631","rc":[{"batb":[[0,2.48,4],[1,2.46,27.95],[2,1.9,1230.77]],"ltp":2.52,"tv":129.73,"id":349}]}]}
{"op":"mcm","clk":"11936582727","pt":1724679791855,"mc":[{"id":"1.232283631","rc":[{"batb":[[0,2.46,27.95],[1,1.9,1230.77],[2,1.45,57.02]],"ltp":2.52,"tv":129.73,"id":349}]}]}
{"op":"mcm","clk":"11936583749","pt":1724679801644,"mc":[{"id":"1.232283631","rc":[{"batb":[[0,2.48,4],[1,2.46,27.95],[2,1.9,1230.77]],"ltp":2.52,"tv":129.73,"id":349}]}]}
{"op":"mcm","clk":"11936583979","pt":1724679804066,"mc":[{"id":"1.232283631","rc":[{"batb":[[0,2.46,27.95],[1,1.9,1230.77],[2,1.45,57.02]],"ltp":2.52,"tv":129.73,"id":349}]}]}
{"op":"mcm","clk":"11936591750","pt":1724679887739,"mc":[{"id":"1.232283631","rc":[{"batb":[[0,2.48,4],[1,2.46,27.95],[2,1.9,1230.77]],"ltp":2.52,"tv":129.73,"id":349}]}]}
{"op":"mcm","clk":"11936592010","pt":1724679890025,"mc":[{"id":"1.232283631","rc":[{"batb":[[0,2.46,27.95],[1,1.9,1230.77],[2,1.45,57.02]],"ltp":2.52,"tv":129.73,"id":349}]}]}
{"op":"mcm","clk":"11936596418","pt":1724679930745,"mc":[{"id":"1.232283631","rc":[{"batb":[[0,2.48,4],[1,2.46,27.95],[2,1.9,1230.77]],"ltp":2.52,"tv":129.73,"id":349}]}]}
{"op":"mcm","clk":"11936596703","pt":1724679933213,"mc":[{"id":"1.232283631","rc":[{"batb":[[0,2.46,27.95],[1,1.9,1230.77],[2,1.45,57.02]],"ltp":2.52,"tv":129.73,"id":349}]}]}
{"op":"mcm","clk":"11936599301","pt":1724679957384,"mc":[{"id":"1.232283631","rc":[{"batb":[[0,2.48,4],[1,2.46,27.95],[2,1.9,1230.77]],"ltp":2.52,"tv":129.73,"id":349}]}]}
{"op":"mcm","clk":"11936599514","pt":1724679959680,"mc":[{"id":"1.232283631","rc":[{"batb":[[0,2.46,27.95],[1,1.9,1230.77],[2,1.45,57.02]],"ltp":2.52,"tv":129.73,"id":349}]}]}
{"op":"mcm","clk":"11936601235","pt":1724679975588,"mc":[{"id":"1.232283631","rc":[{"batb":[[0,2.48,4],[1,2.46,27.95],[2,1.9,1230.77]],"ltp":2.52,"tv":129.73,"id":349}]}]}
{"op":"mcm","clk":"11936601475","pt":1724679977998,"mc":[{"id":"1.232283631","rc":[{"batb":[[0,2.46,27.95],[1,1.9,1230.77],[2,1.45,57.02]],"ltp":2.52,"tv":129.73,"id":349}]}]}
{"op":"mcm","clk":"11936601725","pt":1724679980415,"mc":[{"id":"1.232283631","rc":[{"batb":[[0,2.48,4],[1,2.46,27.95],[2,1.9,1230.77]],"ltp":2.52,"tv":129.73,"id":349}]}]}
{"op":"mcm","clk":"11936601937","pt":1724679982723,"mc":[{"id":"1.232283631","rc":[{"batb":[[0,2.46,27.95],[1,1.9,1230.77],[2,1.45,57.02]],"ltp":2.52,"tv":129.73,"id":349}]}]}
{"op":"mcm","clk":"11936602294","pt":1724679986217,"mc":[{"id":"1.232283631","rc":[{"batb":[[0,2.48,4],[1,2.46,27.95],[2,1.9,1230.77]],"ltp":2.52,"tv":129.73,"id":349}]}]}
{"op":"mcm","clk":"11936602540","pt":1724679988517,"mc":[{"id":"1.232283631","rc":[{"batb":[[0,2.46,27.95],[1,1.9,1230.77],[2,1.45,57.02]],"ltp":2.52,"tv":129.73,"id":349}]}]}
{"op":"mcm","clk":"11936605475","pt":1724680019546,"mc":[{"id":"1.232283631","rc":[{"batb":[[0,2.48,4],[1,2.46,27.95],[2,1.9,1230.77]],"ltp":2.52,"tv":129.73,"id":349}]}]}
{"op":"mcm","clk":"11936605679","pt":1724680021779,"mc":[{"id":"1.232283631","rc":[{"batb":[[0,2.46,27.95],[1,1.9,1230.77],[2,1.45,57.02]],"ltp":2.52,"tv":129.73,"id":349}]}]}
{"op":"mcm","clk":"11936611990","pt":1724680084917,"mc":[{"id":"1.232283631","rc":[{"batb":[[0,2.48,4],[1,2.46,27.95],[2,1.9,1230.77]],"ltp":2.52,"tv":129.73,"id":349}]}]}
{"op":"mcm","clk":"11936612221","pt":1724680087251,"mc":[{"id":"1.232283631","rc":[{"batb":[[0,2.46,27.95],[1,1.9,1230.77],[2,1.45,57.02]],"ltp":2.52,"tv":129.73,"id":349}]}]}
{"op":"mcm","clk":"11936620921","pt":1724680172717,"mc":[{"id":"1.232283631","rc":[{"batb":[[0,2.48,4],[1,2.46,27.95],[2,1.9,1230.77]],"ltp":2.52,"tv":129.73,"id":349}]}]}
{"op":"mcm","clk":"11936621182","pt":1724680175134,"mc":[{"id":"1.232283631","rc":[{"batb":[[0,2.46,27.95],[1,1.9,1230.77],[2,1.45,57.02]],"ltp":2.52,"tv":129.73,"id":349}]}]}
{"op":"mcm","clk":"11936624129","pt":1724680200029,"mc":[{"id":"1.232283631","rc":[{"batb":[[0,2.48,4],[1,2.46,27.95],[2,1.9,1230.77]],"ltp":2.52,"tv":129.73,"id":349}]}]}
{"op":"mcm","clk":"11936624455","pt":1724680202464,"mc":[{"id":"1.232283631","rc":[{"batb":[[0,2.46,27.95],[1,1.9,1230.77],[2,1.45,57.02]],"ltp":2.52,"tv":129.73,"id":349}]}]}
{"op":"mcm","clk":"11936629407","pt":1724680249201,"mc":[{"id":"1.232283631","rc":[{"batb":[[0,2.48,4],[1,2.46,27.95],[2,1.9,1230.77]],"ltp":2.52,"tv":129.73,"id":349}]}]}
{"op":"mcm","clk":"11936629678","pt":1724680251824,"mc":[{"id":"1.232283631","rc":[{"batb":[[0,2.46,27.95],[1,1.9,1230.77],[2,1.45,57.02]],"ltp":2.52,"tv":129.73,"id":349}]}]}
{"op":"mcm","clk":"11936645598","pt":1724680409193,"mc":[{"id":"1.232283631","rc":[{"trd":[[2.46,10.3]],"batb":[[0,2.46,20.96]],"ltp":2.46,"tv":136.72,"id":349},{"trd":[[1.69,86.94]],"ltp":1.69,"tv":159.18,"id":235}],"tv":295.91}]}
{"op":"mcm","clk":"11936645616","pt":1724680409402,"mc":[{"id":"1.232283631","rc":[{"batb":[[0,2.48,4],[1,2.46,20.96],[2,1.9,1230.77]],"ltp":2.46,"tv":136.72,"id":349}]}]}
{"op":"mcm","clk":"11936645848","pt":1724680411896,"mc":[{"id":"1.232283631","rc":[{"batb":[[0,2.46,27.95],[1,1.9,1230.77],[2,1.45,57.02]],"ltp":2.46,"tv":136.72,"id":349}]}]}
{"op":"mcm","clk":"11936673891","pt":1724680731712,"mc":[{"id":"1.232283631","rc":[{"trd":[[2.46,17.29]],"batb":[[0,2.48,4],[1,2.46,20.96],[2,1.9,1230.77]],"ltp":2.46,"tv":143.71,"id":349},{"trd":[[1.69,97.12]],"ltp":1.69,"tv":169.36,"id":235}],"tv":313.08}]}
{"op":"mcm","clk":"11936673999","pt":1724680733037,"mc":[{"id":"1.232283631","rc":[{"batb":[[1,2.46,27.95]],"ltp":2.46,"tv":143.71,"id":349}]}]}
{"op":"mcm","clk":"11936674083","pt":1724680733919,"mc":[{"id":"1.232283631","rc":[{"batb":[[0,2.46,27.95],[1,1.9,1230.77],[2,1.45,57.02]],"ltp":2.46,"tv":143.71,"id":349}]}]}
{"op":"mcm","clk":"11936678131","pt":1724680775474,"mc":[{"id":"1.232283631","rc":[{"batb":[[0,2.48,4],[1,2.46,27.95],[2,1.9,1230.77]],"ltp":2.46,"tv":143.71,"id":349},{"batl":[[2,1.77,900]],"ltp":1.69,"tv":169.36,"id":235}]}]}
{"op":"mcm","clk":"11936678390","pt":1724680777878,"mc":[{"id":"1.232283631","rc":[{"batb":[[0,2.46,27.95],[1,1.9,1230.77],[2,1.45,57.02]],"ltp":2.46,"tv":143.71,"id":349}]}]}
{"op":"mcm","clk":"11936723751","pt":1724681117146,"mc":[{"id":"1.232283631","rc":[{"trd":[[2.44,121.8]],"batb":[[0,2.48,4],[1,2.46,27.95],[2,1.9,1230.77]],"batl":[[0,3.2,15.12],[1,5,51.4],[2,10,51.4]],"ltp":2.46,"tv":143.83,"id":349},{"trd":[[1.69,97.18],[1.7,58.84],[1.71,6.98]],"batb":[[1,1.65,34.07]],"batl":[[0,1.71,12690.09]],"ltp":1.69,"tv":169.44,"id":235}],"tv":313.28}]}
{"op":"mcm","clk":"11936724110","pt":1724681119615,"mc":[{"id":"1.232283631","rc":[{"batb":[[0,2.46,27.95],[1,1.9,1230.77],[2,1.45,57.11]],"ltp":2.46,"tv":143.83,"id":349}]}]}
{"op":"mcm","clk":"11936733158","pt":1724681178303,"mc":[{"id":"1.232283631","rc":[{"batb":[[0,2.48,4],[1,2.46,27.95],[2,1.9,1230.77]],"ltp":2.46,"tv":143.83,"id":349}]}]}
{"op":"mcm","clk":"11936733511","pt":1724681180731,"mc":[{"id":"1.232283631","rc":[{"batb":[[0,2.46,27.95],[1,1.9,1230.77],[2,1.45,57.11]],"ltp":2.46,"tv":143.83,"id":349}]}]}
{"op":"mcm","clk":"11936776127","pt":1724681442483,"mc":[{"id":"1.232283631","rc":[{"batb":[[0,2.48,4],[1,2.46,27.95],[2,1.9,1230.77]],"ltp":2.46,"tv":143.83,"id":349}]}]}
{"op":"mcm","clk":"11936776524","pt":1724681444915,"mc":[{"id":"1.232283631","rc":[{"batb":[[0,2.46,27.95],[1,1.9,1230.77],[2,1.45,57.11]],"ltp":2.46,"tv":143.83,"id":349}]}]}
{"op":"mcm","clk":"11936834405","pt":1724681816325,"mc":[{"id":"1.232283631","rc":[{"batb":[[0,2.48,4],[1,2.46,27.95],[2,1.9,1230.77]],"ltp":2.46,"tv":143.83,"id":349}]}]}
{"op":"mcm","clk":"11936834743","pt":1724681818815,"mc":[{"id":"1.232283631","rc":[{"batb":[[0,2.46,27.95],[1,1.9,1230.77],[2,1.45,57.11]],"ltp":2.46,"tv":143.83,"id":349}]}]}
{"op":"mcm","clk":"11936875977","pt":1724682079787,"mc":[{"id":"1.232283631","rc":[{"batb":[[0,2.48,4],[1,2.46,27.95]],"ltp":2.46,"tv":143.83,"id":349}]}]}
{"op":"mcm","clk":"11936876345","pt":1724682082067,"mc":[{"id":"1.232283631","rc":[{"batb":[[0,2.46,27.95],[1,1.45,57.11],[2,1.1,25000]],"ltp":2.46,"tv":143.83,"id":349}]}]}
{"op":"mcm","clk":"11936886770","pt":1724682147964,"mc":[{"id":"1.232283631","rc":[{"batb":[[0,2.48,4],[1,2.46,27.95],[2,1.45,57.11]],"ltp":2.46,"tv":143.83,"id":349}]}]}
{"op":"mcm","clk":"11936887123","pt":1724682150142,"mc":[{"id":"1.232283631","rc":[{"batb":[[0,2.46,27.95],[1,1.45,57.11],[2,1.1,25000]],"ltp":2.46,"tv":143.83,"id":349}]}]}
{"op":"mcm","clk":"11936888256","pt":1724682157362,"mc":[{"id":"1.232283631","rc":[{"batb":[[0,2.48,4],[1,2.46,27.95],[2,1.45,57.11]],"ltp":2.46,"tv":143.83,"id":349}]}]}
{"op":"mcm","clk":"11936888579","pt":1724682159529,"mc":[{"id":"1.232283631","rc":[{"batb":[[0,2.46,27.95],[1,1.45,57.11],[2,1.1,25000]],"ltp":2.46,"tv":143.83,"id":349}]}]}
{"op":"mcm","clk":"11936895114","pt":1724682200608,"mc":[{"id":"1.232283631","rc":[{"batb":[[0,2.48,4],[1,2.46,27.95],[2,1.45,57.11]],"ltp":2.46,"tv":143.83,"id":349}]}]}
{"op":"mcm","clk":"11936895474","pt":1724682202915,"mc":[{"id":"1.232283631","rc":[{"batb":[[0,2.46,27.95],[1,1.45,57.11],[2,1.1,25000]],"ltp":2.46,"tv":143.83,"id":349}]}]}
{"op":"mcm","clk":"11936973361","pt":1724682668718,"mc":[{"id":"1.232283631","rc":[{"batb":[[0,2.48,4],[1,2.46,27.95],[2,1.45,57.11]],"ltp":2.46,"tv":143.83,"id":349}]}]}
{"op":"mcm","clk":"11936973723","pt":1724682670930,"mc":[{"id":"1.232283631","rc":[{"batb":[[0,2.46,27.95],[1,1.45,57.11],[2,1.1,25000]],"ltp":2.46,"tv":143.83,"id":349}]}]}
{"op":"mcm","clk":"11936983288","pt":1724682728455,"mc":[{"id":"1.232283631","rc":[{"batb":[[0,2.48,4],[1,2.46,27.95],[2,1.45,57.11]],"ltp":2.46,"tv":143.83,"id":349}]}]}
{"op":"mcm","clk":"11936983666","pt":1724682730891,"mc":[{"id":"1.232283631","rc":[{"batb":[[0,2.46,27.95],[1,1.45,57.11],[2,1.1,25000]],"ltp":2.46,"tv":143.83,"id":349}]}]}
{"op":"mcm","clk":"11937190511","pt":1724684066876,"mc":[{"id":"1.232283631","rc":[{"batb":[[0,2.48,4],[1,2.46,27.95],[2,1.45,57.11]],"ltp":2.46,"tv":143.83,"id":349}]}]}
{"op":"mcm","clk":"11937190800","pt":1724684068986,"mc":[{"id":"1.232283631","rc":[{"batb":[[0,2.46,27.95],[1,1.45,57.11],[2,1.1,25000]],"ltp":2.46,"tv":143.83,"id":349}]}]}
{"op":"mcm","clk":"11937254712","pt":1724684602165,"mc":[{"id":"1.232283631","rc":[{"trd":[[2.44,121.74]],"batb":[[0,2.48,4],[1,2.46,27.95],[2,1.45,57.07]],"batl":[[0,3.2,15.11],[1,5,51.36],[2,10,51.36]],"ltp":2.46,"tv":143.77,"id":349},{"trd":[[1.69,97.2],[1.7,58.84]],"batb":[[1,1.65,34.08]],"batl":[[0,1.71,12693.31]],"ltp":1.69,"tv":169.47,"id":235}],"tv":313.25}]}
{"op":"mcm","clk":"11937255015","pt":1724684604509,"mc":[{"id":"1.232283631","rc":[{"batb":[[0,2.46,27.95],[1,1.45,57.07],[2,1.1,25000]],"ltp":2.46,"tv":143.77,"id":349}]}]}
{"op":"mcm","clk":"11937255507","pt":1724684608292,"mc":[{"id":"1.232283631","rc":[{"batb":[[0,2.48,4],[1,2.46,27.95],[2,1.45,57.07]],"ltp":2.46,"tv":143.77,"id":349}]}]}
{"op":"mcm","clk":"11937255781","pt":1724684610466,"mc":[{"id":"1.232283631","rc":[{"batb":[[0,2.46,27.95],[1,1.45,57.07],[2,1.1,25000]],"ltp":2.46,"tv":143.77,"id":349}]}]}
{"op":"mcm","clk":"11937292494","pt":1724684862204,"mc":[{"id":"1.232283631","rc":[{"batb":[[0,2.48,4],[1,2.46,27.95],[2,1.45,57.07]],"ltp":2.46,"tv":143.77,"id":349}]}]}
{"op":"mcm","clk":"11937292856","pt":1724684864506,"mc":[{"id":"1.232283631","rc":[{"batb":[[0,2.46,27.95],[1,1.45,57.07],[2,1.1,25000]],"ltp":2.46,"tv":143.77,"id":349}]}]}
{"op":"mcm","clk":"11937335347","pt":1724685132803,"mc":[{"id":"1.232283631","rc":[{"batb":[[0,2.48,4],[1,2.46,27.95],[2,1.45,57.07]],"ltp":2.46,"tv":143.77,"id":349}]}]}
{"op":"mcm","clk":"11937335821","pt":1724685135343,"mc":[{"id":"1.232283631","rc":[{"batb":[[0,2.46,27.95],[1,1.45,57.07],[2,1.1,25000]],"ltp":2.46,"tv":143.77,"id":349}]}]}
{"op":"mcm","clk":"11937336727","pt":1724685140525,"mc":[{"id":"1.232283631","rc":[{"batb":[[0,2.48,4],[1,2.46,27.95],[2,1.45,57.07]],"ltp":2.46,"tv":143.77,"id":349}]}]}
{"op":"mcm","clk":"11937337095","pt":1724685142823,"mc":[{"id":"1.232283631","rc":[{"batb":[[0,2.46,27.95],[1,1.45,57.07],[2,1.1,25000]],"ltp":2.46,"tv":143.77,"id":349}]}]}
{"op":"mcm","clk":"11937338540","pt":1724685151026,"mc":[{"id":"1.232283631","rc":[{"batb":[[0,2.48,4],[1,2.46,27.95],[2,1.45,57.07]],"ltp":2.46,"tv":143.77,"id":349}]}]}
{"op":"mcm","clk":"11937338988","pt":1724685153625,"mc":[{"id":"1.232283631","rc":[{"batb":[[0,2.46,27.95],[1,1.45,57.07],[2,1.1,25000]],"ltp":2.46,"tv":143.77,"id":349}]}]}
{"op":"mcm","clk":"11937339873","pt":1724685158542,"mc":[{"id":"1.232283631","rc":[{"batb":[[0,2.48,4],[1,2.46,27.95],[2,1.45,57.07]],"ltp":2.46,"tv":143.77,"id":349}]}]}
{"op":"mcm","clk":"11937340340","pt":1724685160987,"mc":[{"id":"1.232283631","rc":[{"batb":[[0,2.46,27.95],[1,1.45,57.07],[2,1.1,25000]],"ltp":2.46,"tv":143.77,"id":349}]}]}
{"op":"mcm","clk":"11937341699","pt":1724685169006,"mc":[{"id":"1.232283631","rc":[{"trd":[[2.46,24.41]],"batb":[[0,2.48,4],[1,2.46,27.95],[2,1.45,57.07]],"ltp":2.46,"tv":150.89,"id":349},{"trd":[[1.69,107.57]],"ltp":1.69,"tv":179.84,"id":235}],"tv":330.74}]}
{"op":"mcm","clk":"11937341970","pt":1724685170705,"mc":[{"id":"1.232283631","rc":[{"batb":[[0,2.46,27.95],[1,1.45,57.07],[2,1.1,25000]],"ltp":2.46,"tv":150.89,"id":349}]}]}
{"op":"mcm","clk":"11937356959","pt":1724685193554,"mc":[{"id":"1.232283631","rc":[{"batb":[[0,2.48,4],[1,2.46,27.95],[2,1.45,57.07]],"ltp":2.46,"tv":150.89,"id":349}]}]}
{"op":"mcm","clk":"11937357350","pt":1724685195939,"mc":[{"id":"1.232283631","rc":[{"batb":[[0,2.46,27.95],[1,1.45,57.07],[2,1.1,25000]],"ltp":2.46,"tv":150.89,"id":349}]}]}
{"op":"mcm","clk":"11937357962","pt":1724685199137,"mc":[{"id":"1.232283631","rc":[{"batb":[[0,2.48,4],[1,2.46,27.95],[2,1.45,57.07]],"ltp":2.46,"tv":150.89,"id":349}]}]}
{"op":"mcm","clk":"11937358345","pt":1724685201355,"mc":[{"id":"1.232283631","rc":[{"batb":[[0,2.46,27.95],[1,1.45,57.07],[2,1.1,25000]],"ltp":2.46,"tv":150.89,"id":349}]}]}
{"op":"mcm","clk":"11937359510","pt":1724685208546,"mc":[{"id":"1.232283631","rc":[{"batb":[[0,2.48,4],[1,2.46,27.95],[2,1.45,57.07]],"ltp":2.46,"tv":150.89,"id":349}]}]}
{"op":"mcm","clk":"11937359893","pt":1724685210966,"mc":[{"id":"1.232283631","rc":[{"batb":[[0,2.46,27.95],[1,1.45,57.07],[2,1.1,25000]],"ltp":2.46,"tv":150.89,"id":349}]}]}
{"op":"mcm","clk":"11937362765","pt":1724685227989,"mc":[{"id":"1.232283631","rc":[{"batb":[[0,2.48,4],[1,2.46,27.95],[2,1.45,57.07]],"ltp":2.46,"tv":150.89,"id":349}]}]}
{"op":"mcm","clk":"11937363208","pt":1724685230469,"mc":[{"id":"1.232283631","rc":[{"batb":[[0,2.46,27.95],[1,1.45,57.07],[2,1.1,25000]],"ltp":2.46,"tv":150.89,"id":349}]}]}
{"op":"mcm","clk":"11937367086","pt":1724685253016,"mc":[{"id":"1.232283631","rc":[{"batb":[[0,2.48,4],[1,2.46,27.95],[2,1.45,57.07]],"ltp":2.46,"tv":150.89,"id":349}]}]}
{"op":"mcm","clk":"11937367497","pt":1724685255211,"mc":[{"id":"1.232283631","rc":[{"batb":[[0,2.46,27.95],[1,1.45,57.07],[2,1.1,25000]],"ltp":2.46,"tv":150.89,"id":349}]}]}
{"op":"mcm","clk":"11937369636","pt":1724685268151,"mc":[{"id":"1.232283631","rc":[{"batb":[[0,2.48,4],[1,2.46,27.95],[2,1.45,57.07]],"ltp":2.46,"tv":150.89,"id":349}]}]}
{"op":"mcm","clk":"11937370046","pt":1724685270434,"mc":[{"id":"1.232283631","rc":[{"batb":[[0,2.46,27.95],[1,1.45,57.07],[2,1.1,25000]],"ltp":2.46,"tv":150.89,"id":349}]}]}
{"op":"mcm","clk":"11937371102","pt":1724685276348,"mc":[{"id":"1.232283631","rc":[{"batb":[[0,2.48,4],[1,2.46,27.95],[2,1.45,57.07]],"ltp":2.46,"tv":150.89,"id":349}]}]}
{"op":"mcm","clk":"11937371642","pt":1724685279259,"mc":[{"id":"1.232283631","rc":[{"trd":[[2.46,27.23],[2.48,8]],"batb":[[0,2.46,53.08],[1,1.45,57.07],[2,1.1,25000]],"ltp":2.46,"tv":157.71,"id":349},{"trd":[[1.68,11.8],[1.69,111.67]],"ltp":1.69,"tv":189.84,"id":235}],"tv":347.56}]}
{"op":"mcm","clk":"11937371657","pt":1724685279319,"mc":[{"id":"1.232283631","rc":[{"batb":[[0,2.46,27.95]],"ltp":2.46,"tv":157.71,"id":349}]}]}
{"op":"mcm","clk":"11937372858","pt":1724685286244,"mc":[{"id":"1.232283631","rc":[{"batb":[[0,2.48,4],[1,2.46,27.95],[2,1.45,57.07]],"ltp":2.46,"tv":157.71,"id":349}]}]}
{"op":"mcm","clk":"11937373297","pt":1724685288635,"mc":[{"id":"1.232283631","rc":[{"batb":[[0,2.46,27.95],[1,1.45,57.07],[2,1.1,25000]],"ltp":2.46,"tv":157.71,"id":349}]}]}
{"op":"mcm","clk":"11937374183","pt":1724685293636,"mc":[{"id":"1.232283631","rc":[{"batb":[[0,2.48,4],[1,2.46,27.95],[2,1.45,57.07]],"ltp":2.46,"tv":157.71,"id":349}]}]}
{"op":"mcm","clk":"11937374704","pt":1724685296129,"mc":[{"id":"1.232283631","rc":[{"batb":[[0,2.46,27.95],[1,1.45,57.07],[2,1.1,25000]],"ltp":2.46,"tv":157.71,"id":349}]}]}
{"op":"mcm","clk":"11937375752","pt":1724685301874,"mc":[{"id":"1.232283631","rc":[{"batb":[[0,2.48,4],[1,2.46,27.95],[2,1.45,57.07]],"ltp":2.46,"tv":157.71,"id":349}]}]}
{"op":"mcm","clk":"11937376306","pt":1724685304542,"mc":[{"id":"1.232283631","rc":[{"batb":[[0,2.46,27.95],[1,1.45,57.07],[2,1.1,25000]],"ltp":2.46,"tv":157.71,"id":349}]}]}
{"op":"mcm","clk":"11937376756","pt":1724685306944,"mc":[{"id":"1.232283631","rc":[{"batb":[[0,2.48,4],[1,2.46,27.95],[2,1.45,57.07]],"ltp":2.46,"tv":157.71,"id":349}]}]}
{"op":"mcm","clk":"11937377158","pt":1724685309273,"mc":[{"id":"1.232283631","rc":[{"batb":[[0,2.46,27.95],[1,1.45,57.07],[2,1.1,25000]],"ltp":2.46,"tv":157.71,"id":349}]}]}
{"op":"mcm","clk":"11937379172","pt":1724685320680,"mc":[{"id":"1.232283631","rc":[{"batb":[[0,2.48,4],[1,2.46,27.95],[2,1.45,57.07]],"ltp":2.46,"tv":157.71,"id":349}]}]}
{"op":"mcm","clk":"11937379567","pt":1724685322980,"mc":[{"id":"1.232283631","rc":[{"batb":[[0,2.46,27.95],[1,1.45,57.07],[2,1.1,25000]],"ltp":2.46,"tv":157.71,"id":349}]}]}
{"op":"mcm","clk":"11937381161","pt":1724685332082,"mc":[{"id":"1.232283631","rc":[{"batb":[[0,2.48,4],[1,2.46,27.95],[2,1.45,57.07]],"ltp":2.46,"tv":157.71,"id":349}]}]}
{"op":"mcm","clk":"11937381581","pt":1724685334404,"mc":[{"id":"1.232283631","rc":[{"batb":[[0,2.46,27.95],[1,1.45,57.07],[2,1.1,25000]],"ltp":2.46,"tv":157.71,"id":349}]}]}
{"op":"mcm","clk":"11937382228","pt":1724685338285,"mc":[{"id":"1.232283631","rc":[{"batb":[[0,2.48,4],[1,2.46,27.95],[2,1.45,57.07]],"ltp":2.46,"tv":157.71,"id":349}]}]}
{"op":"mcm","clk":"11937382654","pt":1724685340679,"mc":[{"id":"1.232283631","rc":[{"batb":[[0,2.46,27.95],[1,1.45,57.07],[2,1.1,25000]],"ltp":2.46,"tv":157.71,"id":349}]}]}
{"op":"mcm","clk":"11937383684","pt":1724685346729,"mc":[{"id":"1.232283631","rc":[{"batb":[[0,2.48,4],[1,2.46,27.95],[2,1.45,57.07]],"ltp":2.46,"tv":157.71,"id":349}]}]}
{"op":"mcm","clk":"11937384101","pt":1724685349129,"mc":[{"id":"1.232283631","rc":[{"batb":[[0,2.46,27.95],[1,1.45,57.07],[2,1.1,25000]],"ltp":2.46,"tv":157.71,"id":349}]}]}
{"op":"mcm","clk":"11937385148","pt":1724685355733,"mc":[{"id":"1.232283631","rc":[{"batb":[[0,2.48,4],[1,2.46,27.95],[2,1.45,57.07]],"ltp":2.46,"tv":157.71,"id":349}]}]}
{"op":"mcm","clk":"11937385544","pt":1724685358137,"mc":[{"id":"1.232283631","rc":[{"batb":[[0,2.46,27.95],[1,1.45,57.07],[2,1.1,25000]],"ltp":2.46,"tv":157.71,"id":349}]}]}
{"op":"mcm","clk":"11937386045","pt":1724685361043,"mc":[{"id":"1.232283631","rc":[{"batb":[[0,2.48,4],[1,2.46,27.95],[2,1.45,57.07]],"ltp":2.46,"tv":157.71,"id":349}]}]}
{"op":"mcm","clk":"11937386443","pt":1724685363248,"mc":[{"id":"1.232283631","rc":[{"batb":[[0,2.46,27.95],[1,1.45,57.07],[2,1.1,25000]],"ltp":2.46,"tv":157.71,"id":349}]}]}
{"op":"mcm","clk":"11937386895","pt":1724685366006,"mc":[{"id":"1.232283631","rc":[{"batb":[[0,2.48,4],[1,2.46,27.95],[2,1.45,57.07]],"ltp":2.46,"tv":157.71,"id":349}]}]}
{"op":"mcm","clk":"11937387267","pt":1724685368344,"mc":[{"id":"1.232283631","rc":[{"batb":[[0,2.46,27.95],[1,1.45,57.07],[2,1.1,25000]],"ltp":2.46,"tv":157.71,"id":349}]}]}
{"op":"mcm","clk":"11937388082","pt":1724685373345,"mc":[{"id":"1.232283631","rc":[{"batb":[[0,2.48,4],[1,2.46,27.95],[2,1.45,57.07]],"ltp":2.46,"tv":157.71,"id":349}]}]}
{"op":"mcm","clk":"11937388418","pt":1724685375558,"mc":[{"id":"1.232283631","rc":[{"batb":[[0,2.46,27.95],[1,1.45,57.07],[2,1.1,25000]],"ltp":2.46,"tv":157.71,"id":349}]}]}
{"op":"mcm","clk":"11937389668","pt":1724685382734,"mc":[{"id":"1.232283631","rc":[{"batb":[[0,2.48,4],[1,2.46,27.95],[2,1.45,57.07]],"ltp":2.46,"tv":157.71,"id":349}]}]}
{"op":"mcm","clk":"11937390100","pt":1724685385071,"mc":[{"id":"1.232283631","rc":[{"batb":[[0,2.46,27.95],[1,1.45,57.07],[2,1.1,25000]],"ltp":2.46,"tv":157.71,"id":349}]}]}
{"op":"mcm","clk":"11937395308","pt":1724685414276,"mc":[{"id":"1.232283631","rc":[{"batb":[[0,2.48,4],[1,2.46,27.95],[2,1.45,57.07]],"ltp":2.46,"tv":157.71,"id":349}]}]}
{"op":"mcm","clk":"11937395721","pt":1724685416488,"mc":[{"id":"1.232283631","rc":[{"batb":[[0,2.46,27.95],[1,1.45,57.07],[2,1.1,25000]],"ltp":2.46,"tv":157.71,"id":349}]}]}
{"op":"mcm","clk":"11937398068","pt":1724685428276,"mc":[{"id":"1.232283631","rc":[{"batb":[[0,2.48,4],[1,2.46,27.95],[2,1.45,57.07]],"ltp":2.46,"tv":157.71,"id":349}]}]}
{"op":"mcm","clk":"11937398538","pt":1724685430716,"mc":[{"id":"1.232283631","rc":[{"batb":[[0,2.46,27.95],[1,1.45,57.07],[2,1.1,25000]],"ltp":2.46,"tv":157.71,"id":349}]}]}
{"op":"mcm","clk":"11937405224","pt":1724685465909,"mc":[{"id":"1.232283631","rc":[{"batb":[[0,2.48,4],[1,2.46,27.95],[2,1.45,57.07]],"ltp":2.46,"tv":157.71,"id":349}]}]}
{"op":"mcm","clk":"11937405633","pt":1724685468243,"mc":[{"id":"1.232283631","rc":[{"batb":[[0,2.46,27.95],[1,1.45,57.07],[2,1.1,25000]],"ltp":2.46,"tv":157.71,"id":349}]}]}
{"op":"mcm","clk":"11937406332","pt":1724685472340,"mc":[{"id":"1.232283631","rc":[{"batb":[[0,2.48,4],[1,2.46,27.95],[2,1.45,57.07]],"ltp":2.46,"tv":157.71,"id":349}]}]}
{"op":"mcm","clk":"11937406735","pt":1724685474639,"mc":[{"id":"1.232283631","rc":[{"batb":[[0,2.46,27.95],[1,1.45,57.07],[2,1.1,25000]],"ltp":2.46,"tv":157.71,"id":349}]}]}
{"op":"mcm","clk":"11937407178","pt":1724685477228,"mc":[{"id":"1.232283631","rc":[{"batb":[[0,2.48,4],[1,2.46,27.95],[2,1.45,57.07]],"ltp":2.46,"tv":157.71,"id":349}]}]}
{"op":"mcm","clk":"11937407575","pt":1724685479759,"mc":[{"id":"1.232283631","rc":[{"batb":[[0,2.46,27.95],[1,1.45,57.07],[2,1.1,25000]],"ltp":2.46,"tv":157.71,"id":349}]}]}
{"op":"mcm","clk":"11937408149","pt":1724685482651,"mc":[{"id":"1.232283631","rc":[{"batb":[[0,2.48,4],[1,2.46,27.95],[2,1.45,57.07]],"ltp":2.46,"tv":157.71,"id":349}]}]}
{"op":"mcm","clk":"11937408614","pt":1724685485089,"mc":[{"id":"1.232283631","rc":[{"batb":[[0,2.46,27.95],[1,1.45,57.07],[2,1.1,25000]],"ltp":2.46,"tv":157.71,"id":349}]}]}
{"op":"mcm","clk":"11937410012","pt":1724685492564,"mc":[{"id":"1.232283631","rc":[{"batb":[[0,2.48,4],[1,2.46,27.95],[2,1.45,57.07]],"ltp":2.46,"tv":157.71,"id":349}]}]}
{"op":"mcm","clk":"11937410457","pt":1724685494961,"mc":[{"id":"1.232283631","rc":[{"batb":[[0,2.46,27.95],[1,1.45,57.07],[2,1.1,25000]],"ltp":2.46,"tv":157.71,"id":349}]}]}
{"op":"mcm","clk":"11937414408","pt":1724685516857,"mc":[{"id":"1.232283631","rc":[{"batb":[[0,2.48,4],[1,2.46,27.95],[2,1.45,57.07]],"ltp":2.46,"tv":157.71,"id":349}]}]}
{"op":"mcm","clk":"11937414820","pt":1724685519192,"mc":[{"id":"1.232283631","rc":[{"batb":[[0,2.46,27.95],[1,1.45,57.07],[2,1.1,25000]],"ltp":2.46,"tv":157.71,"id":349}]}]}
{"op":"mcm","clk":"11937415633","pt":1724685523283,"mc":[{"id":"1.232283631","rc":[{"batb":[[0,2.48,4],[1,2.46,27.95],[2,1.45,57.07]],"ltp":2.46,"tv":157.71,"id":349}]}]}
{"op":"mcm","clk":"11937416080","pt":1724685525679,"mc":[{"id":"1.232283631","rc":[{"batb":[[0,2.46,27.95],[1,1.45,57.07],[2,1.1,25000]],"ltp":2.46,"tv":157.71,"id":349}]}]}
{"op":"mcm","clk":"11937416483","pt":1724685527899,"mc":[{"id":"1.232283631","rc":[{"batb":[[0,2.48,4],[1,2.46,27.95],[2,1.45,57.07]],"ltp":2.46,"tv":157.71,"id":349}]}]}
{"op":"mcm","clk":"11937416908","pt":1724685530102,"mc":[{"id":"1.232283631","rc":[{"batb":[[0,2.46,27.95],[1,1.45,57.07],[2,1.1,25000]],"ltp":2.46,"tv":157.71,"id":349}]}]}
{"op":"mcm","clk":"11937418218","pt":1724685537378,"mc":[{"id":"1.232283631","rc":[{"batb":[[0,2.48,4],[1,2.46,27.95],[2,1.45,57.07]],"ltp":2.46,"tv":157.71,"id":349}]}]}
{"op":"mcm","clk":"11937418594","pt":1724685539688,"mc":[{"id":"1.232283631","rc":[{"batb":[[0,2.46,27.95],[1,1.45,57.07],[2,1.1,25000]],"ltp":2.46,"tv":157.71,"id":349}]}]}
{"op":"mcm","clk":"11937419979","pt":1724685547327,"mc":[{"id":"1.232283631","rc":[{"batb":[[0,2.48,4],[1,2.46,27.95],[2,1.45,57.07]],"ltp":2.46,"tv":157.71,"id":349}]}]}
{"op":"mcm","clk":"11937420392","pt":1724685549637,"mc":[{"id":"1.232283631","rc":[{"batb":[[0,2.46,27.95],[1,1.45,57.07],[2,1.1,25000]],"ltp":2.46,"tv":157.71,"id":349}]}]}
{"op":"mcm","clk":"11937421682","pt":1724685557067,"mc":[{"id":"1.232283631","rc":[{"batb":[[0,2.48,4],[1,2.46,27.95],[2,1.45,57.07]],"ltp":2.46,"tv":157.71,"id":349}]}]}
{"op":"mcm","clk":"11937422121","pt":1724685559444,"mc":[{"id":"1.232283631","rc":[{"batb":[[0,2.46,27.95],[1,1.45,57.07],[2,1.1,25000]],"ltp":2.46,"tv":157.71,"id":349}]}]}
{"op":"mcm","clk":"11937422763","pt":1724685562649,"mc":[{"id":"1.232283631","rc":[{"batb":[[0,2.48,4],[1,2.46,27.95],[2,1.45,57.07]],"ltp":2.46,"tv":157.71,"id":349}]}]}
{"op":"mcm","clk":"11937423209","pt":1724685565172,"mc":[{"id":"1.232283631","rc":[{"batb":[[0,2.46,27.95],[1,1.45,57.07],[2,1.1,25000]],"ltp":2.46,"tv":157.71,"id":349}]}]}
{"op":"mcm","clk":"11937423653","pt":1724685567660,"mc":[{"id":"1.232283631","rc":[{"batb":[[0,2.48,4],[1,2.46,27.95],[2,1.45,57.07]],"ltp":2.46,"tv":157.71,"id":349}]}]}
{"op":"mcm","clk":"11937424126","pt":1724685570371,"mc":[{"id":"1.232283631","rc":[{"batb":[[0,2.46,27.95],[1,1.45,57.07],[2,1.1,25000]],"ltp":2.46,"tv":157.71,"id":349}]}]}
{"op":"mcm","clk":"11937425584","pt":1724685578195,"mc":[{"id":"1.232283631","rc":[{"batb":[[0,2.48,4],[1,2.46,27.95],[2,1.45,57.07]],"ltp":2.46,"tv":157.71,"id":349}]}]}
{"op":"mcm","clk":"11937426034","pt":1724685580370,"mc":[{"id":"1.232283631","rc":[{"batb":[[0,2.46,27.95],[1,1.45,57.07],[2,1.1,25000]],"ltp":2.46,"tv":157.71,"id":349}]}]}
{"op":"mcm","clk":"11937426729","pt":1724685584381,"mc":[{"id":"1.232283631","rc":[{"batb":[[0,2.48,4],[1,2.46,27.95],[2,1.45,57.07]],"ltp":2.46,"tv":157.71,"id":349}]}]}
{"op":"mcm","clk":"11937427134","pt":1724685586778,"mc":[{"id":"1.232283631","rc":[{"batb":[[0,2.46,27.95],[1,1.45,57.07],[2,1.1,25000]],"ltp":2.46,"tv":157.71,"id":349}]}]}
{"op":"mcm","clk":"11937427653","pt":1724685589583,"mc":[{"id":"1.232283631","rc":[{"batb":[[0,2.48,4],[1,2.46,27.95],[2,1.45,57.07]],"ltp":2.46,"tv":157.71,"id":349}]}]}
{"op":"mcm","clk":"11937428055","pt":1724685591792,"mc":[{"id":"1.232283631","rc":[{"batb":[[0,2.46,27.95],[1,1.45,57.07],[2,1.1,25000]],"ltp":2.46,"tv":157.71,"id":349}]}]}
{"op":"mcm","clk":"11937429915","pt":1724685601899,"mc":[{"id":"1.232283631","rc":[{"batb":[[0,2.48,4],[1,2.46,27.95],[2,1.45,57.07]],"ltp":2.46,"tv":157.71,"id":349}]}]}
{"op":"mcm","clk":"11937430394","pt":1724685604504,"mc":[{"id":"1.232283631","rc":[{"batb":[[0,2.46,27.95],[1,1.45,57.07],[2,1.1,25000]],"ltp":2.46,"tv":157.71,"id":349}]}]}
{"op":"mcm","clk":"11937430841","pt":1724685606991,"mc":[{"id":"1.232283631","rc":[{"batb":[[0,2.48,4],[1,2.46,27.95],[2,1.45,57.07]],"ltp":2.46,"tv":157.71,"id":349}]}]}
{"op":"mcm","clk":"11937431283","pt":1724685609504,"mc":[{"id":"1.232283631","rc":[{"batb":[[0,2.46,27.95],[1,1.45,57.07],[2,1.1,25000]],"ltp":2.46,"tv":157.71,"id":349}]}]}
{"op":"mcm","clk":"11937431724","pt":1724685612093,"mc":[{"id":"1.232283631","rc":[{"batb":[[0,2.48,4],[1,2.46,27.95],[2,1.45,57.07]],"ltp":2.46,"tv":157.71,"id":349}]}]}
{"op":"mcm","clk":"11937432177","pt":1724685614485,"mc":[{"id":"1.232283631","rc":[{"batb":[[0,2.46,27.95],[1,1.45,57.07],[2,1.1,25000]],"ltp":2.46,"tv":157.71,"id":349}]}]}
{"op":"mcm","clk":"11937432854","pt":1724685618421,"mc":[{"id":"1.232283631","rc":[{"batb":[[0,2.48,4],[1,2.46,27.95],[2,1.45,57.07]],"ltp":2.46,"tv":157.71,"id":349}]}]}
{"op":"mcm","clk":"11937433262","pt":1724685620703,"mc":[{"id":"1.232283631","rc":[{"batb":[[0,2.46,27.95],[1,1.45,57.07],[2,1.1,25000]],"ltp":2.46,"tv":157.71,"id":349}]}]}
{"op":"mcm","clk":"11937433919","pt":1724685624488,"mc":[{"id":"1.232283631","rc":[{"batb":[[0,2.48,4],[1,2.46,27.95],[2,1.45,57.07]],"ltp":2.46,"tv":157.71,"id":349}]}]}
{"op":"mcm","clk":"11937434362","pt":1724685626823,"mc":[{"id":"1.232283631","rc":[{"batb":[[0,2.46,27.95],[1,1.45,57.07],[2,1.1,25000]],"ltp":2.46,"tv":157.71,"id":349}]}]}
{"op":"mcm","clk":"11937434872","pt":1724685629733,"mc":[{"id":"1.232283631","rc":[{"batb":[[0,2.48,4],[1,2.46,27.95],[2,1.45,57.07]],"ltp":2.46,"tv":157.71,"id":349}]}]}
{"op":"mcm","clk":"11937435309","pt":1724685632014,"mc":[{"id":"1.232283631","rc":[{"batb":[[0,2.46,27.95],[1,1.45,57.07],[2,1.1,25000]],"ltp":2.46,"tv":157.71,"id":349}]}]}
{"op":"mcm","clk":"11937436074","pt":1724685636126,"mc":[{"id":"1.232283631","rc":[{"batb":[[0,2.48,4],[1,2.46,27.95],[2,1.45,57.07]],"ltp":2.46,"tv":157.71,"id":349}]}]}
{"op":"mcm","clk":"11937436470","pt":1724685638296,"mc":[{"id":"1.232283631","rc":[{"batb":[[0,2.46,27.95],[1,1.45,57.07],[2,1.1,25000]],"ltp":2.46,"tv":157.71,"id":349}]}]}
{"op":"mcm","clk":"11937438291","pt":1724685647726,"mc":[{"id":"1.232283631","rc":[{"batb":[[0,2.48,4],[1,2.46,27.95],[2,1.45,57.07]],"ltp":2.46,"tv":157.71,"id":349}]}]}
{"op":"mcm","clk":"11937438746","pt":1724685650125,"mc":[{"id":"1.232283631","rc":[{"batb":[[0,2.46,27.95],[1,1.45,57.07],[2,1.1,25000]],"ltp":2.46,"tv":157.71,"id":349}]}]}
{"op":"mcm","clk":"11937440180","pt":1724685657855,"mc":[{"id":"1.232283631","rc":[{"batb":[[0,2.48,4],[1,2.46,27.95],[2,1.45,57.07]],"ltp":2.46,"tv":157.71,"id":349}]}]}
{"op":"mcm","clk":"11937440637","pt":1724685660602,"mc":[{"id":"1.232283631","rc":[{"batb":[[0,2.46,27.95],[1,1.45,57.07],[2,1.1,25000]],"ltp":2.46,"tv":157.71,"id":349}]}]}
{"op":"mcm","clk":"11937441224","pt":1724685663239,"mc":[{"id":"1.232283631","rc":[{"batb":[[0,2.48,4],[1,2.46,27.95],[2,1.45,57.07]],"ltp":2.46,"tv":157.71,"id":349}]}]}
{"op":"mcm","clk":"11937441618","pt":1724685665444,"mc":[{"id":"1.232283631","rc":[{"batb":[[0,2.46,27.95],[1,1.45,57.07],[2,1.1,25000]],"ltp":2.46,"tv":157.71,"id":349}]}]}
{"op":"mcm","clk":"11937442347","pt":1724685669549,"mc":[{"id":"1.232283631","rc":[{"batb":[[0,2.48,4],[1,2.46,27.95],[2,1.45,57.07]],"ltp":2.46,"tv":157.71,"id":349}]}]}
{"op":"mcm","clk":"11937442763","pt":1724685671854,"mc":[{"id":"1.232283631","rc":[{"batb":[[0,2.46,27.95],[1,1.45,57.07],[2,1.1,25000]],"ltp":2.46,"tv":157.71,"id":349}]}]}
{"op":"mcm","clk":"11937443207","pt":1724685674551,"mc":[{"id":"1.232283631","rc":[{"batb":[[0,2.48,4],[1,2.46,27.95],[2,1.45,57.07]],"ltp":2.46,"tv":157.71,"id":349}]}]}
{"op":"mcm","clk":"11937443665","pt":1724685677064,"mc":[{"id":"1.232283631","rc":[{"batb":[[0,2.46,27.95],[1,1.45,57.07],[2,1.1,25000]],"ltp":2.46,"tv":157.71,"id":349}]}]}
{"op":"mcm","clk":"11937444599","pt":1724685682345,"mc":[{"id":"1.232283631","rc":[{"batb":[[0,2.48,4],[1,2.46,27.95],[2,1.45,57.07]],"ltp":2.46,"tv":157.71,"id":349}]}]}
{"op":"mcm","clk":"11937445000","pt":1724685684653,"mc":[{"id":"1.232283631","rc":[{"batb":[[0,2.46,27.95],[1,1.45,57.07],[2,1.1,25000]],"ltp":2.46,"tv":157.71,"id":349}]}]}
{"op":"mcm","clk":"11937446651","pt":1724685693554,"mc":[{"id":"1.232283631","rc":[{"batb":[[0,2.48,4],[1,2.46,27.95],[2,1.45,57.07]],"ltp":2.46,"tv":157.71,"id":349}]}]}
{"op":"mcm","clk":"11937447102","pt":1724685696069,"mc":[{"id":"1.232283631","rc":[{"batb":[[0,2.46,27.95],[1,1.45,57.07],[2,1.1,25000]],"ltp":2.46,"tv":157.71,"id":349}]}]}
{"op":"mcm","clk":"11937447686","pt":1724685699086,"mc":[{"id":"1.232283631","rc":[{"batb":[[0,2.48,4],[1,2.46,27.95],[2,1.45,57.07]],"ltp":2.46,"tv":157.71,"id":349}]}]}
{"op":"mcm","clk":"11937448096","pt":1724685701270,"mc":[{"id":"1.232283631","rc":[{"batb":[[0,2.46,27.95],[1,1.45,57.07],[2,1.1,25000]],"ltp":2.46,"tv":157.71,"id":349}]}]}
{"op":"mcm","clk":"11937449292","pt":1724685707498,"mc":[{"id":"1.232283631","rc":[{"batb":[[0,2.48,4],[1,2.46,27.95],[2,1.45,57.07]],"ltp":2.46,"tv":157.71,"id":349}]}]}
{"op":"mcm","clk":"11937449666","pt":1724685709779,"mc":[{"id":"1.232283631","rc":[{"batb":[[0,2.46,27.95],[1,1.45,57.07],[2,1.1,25000]],"ltp":2.46,"tv":157.71,"id":349}]}]}
{"op":"mcm","clk":"11937450613","pt":1724685715318,"mc":[{"id":"1.232283631","rc":[{"batb":[[0,2.48,4],[1,2.46,27.95],[2,1.45,57.07]],"ltp":2.46,"tv":157.71,"id":349}]}]}
{"op":"mcm","clk":"11937450994","pt":1724685717586,"mc":[{"id":"1.232283631","rc":[{"batb":[[0,2.46,27.95],[1,1.45,57.07],[2,1.1,25000]],"ltp":2.46,"tv":157.71,"id":349}]}]}
{"op":"mcm","clk":"11937451636","pt":1724685721613,"mc":[{"id":"1.232283631","rc":[{"batb":[[0,2.48,4],[1,2.46,27.95],[2,1.45,57.07]],"ltp":2.46,"tv":157.71,"id":349}]}]}
{"op":"mcm","clk":"11937452057","pt":1724685723907,"mc":[{"id":"1.232283631","rc":[{"batb":[[0,2.46,27.95],[1,1.45,57.07],[2,1.1,25000]],"ltp":2.46,"tv":157.71,"id":349}]}]}
{"op":"mcm","clk":"11937452478","pt":1724685726327,"mc":[{"id":"1.232283631","rc":[{"batb":[[0,2.48,4],[1,2.46,27.95],[2,1.45,57.07]],"ltp":2.46,"tv":157.71,"id":349}]}]}
{"op":"mcm","clk":"11937452864","pt":1724685728535,"mc":[{"id":"1.232283631","rc":[{"batb":[[0,2.46,27.95],[1,1.45,57.07],[2,1.1,25000]],"ltp":2.46,"tv":157.71,"id":349}]}]}
{"op":"mcm","clk":"11937454295","pt":1724685736627,"mc":[{"id":"1.232283631","rc":[{"batb":[[0,2.48,4],[1,2.46,27.95],[2,1.45,57.07]],"ltp":2.46,"tv":157.71,"id":349}]}]}
{"op":"mcm","clk":"11937454668","pt":1724685738832,"mc":[{"id":"1.232283631","rc":[{"batb":[[0,2.46,27.95],[1,1.45,57.07],[2,1.1,25000]],"ltp":2.46,"tv":157.71,"id":349}]}]}
{"op":"mcm","clk":"11937456488","pt":1724685749057,"mc":[{"id":"1.232283631","rc":[{"batb":[[0,2.48,4],[1,2.46,27.95],[2,1.45,57.07]],"ltp":2.46,"tv":157.71,"id":349}]}]}
{"op":"mcm","clk":"11937456918","pt":1724685751170,"mc":[{"id":"1.232283631","rc":[{"batb":[[0,2.46,27.95],[1,1.45,57.07],[2,1.1,25000]],"ltp":2.46,"tv":157.71,"id":349}]}]}
{"op":"mcm","clk":"11937459175","pt":1724685763137,"mc":[{"id":"1.232283631","rc":[{"batb":[[0,2.48,4],[1,2.46,27.95],[2,1.45,57.07]],"ltp":2.46,"tv":157.71,"id":349}]}]}
{"op":"mcm","clk":"11937459583","pt":1724685765530,"mc":[{"id":"1.232283631","rc":[{"batb":[[0,2.46,27.95],[1,1.45,57.07],[2,1.1,25000]],"ltp":2.46,"tv":157.71,"id":349}]}]}
{"op":"mcm","clk":"11937460594","pt":1724685771381,"mc":[{"id":"1.232283631","rc":[{"batb":[[0,2.48,4],[1,2.46,27.95],[2,1.45,57.07]],"ltp":2.46,"tv":157.71,"id":349}]}]}
{"op":"mcm","clk":"11937461019","pt":1724685773748,"mc":[{"id":"1.232283631","rc":[{"batb":[[0,2.46,27.95],[1,1.45,57.07],[2,1.1,25000]],"ltp":2.46,"tv":157.71,"id":349}]}]}
{"op":"mcm","clk":"11937462525","pt":1724685782282,"mc":[{"id":"1.232283631","rc":[{"batb":[[0,2.48,4],[1,2.46,27.95],[2,1.45,57.07]],"ltp":2.46,"tv":157.71,"id":349}]}]}
{"op":"mcm","clk":"11937462965","pt":1724685784494,"mc":[{"id":"1.232283631","rc":[{"batb":[[0,2.46,27.95],[1,1.45,57.07],[2,1.1,25000]],"ltp":2.46,"tv":157.71,"id":349}]}]}
{"op":"mcm","clk":"11937463434","pt":1724685786783,"mc":[{"id":"1.232283631","rc":[{"batb":[[0,2.48,4],[1,2.46,27.95],[2,1.45,57.07]],"ltp":2.46,"tv":157.71,"id":349}]}]}
{"op":"mcm","clk":"11937463826","pt":1724685789024,"mc":[{"id":"1.232283631","rc":[{"batb":[[0,2.46,27.95],[1,1.45,57.07],[2,1.1,25000]],"ltp":2.46,"tv":157.71,"id":349}]}]}
{"op":"mcm","clk":"11937464566","pt":1724685792789,"mc":[{"id":"1.232283631","rc":[{"batb":[[0,2.48,4],[1,2.46,27.95],[2,1.45,57.07]],"ltp":2.46,"tv":157.71,"id":349}]}]}
{"op":"mcm","clk":"11937464999","pt":1724685795167,"mc":[{"id":"1.232283631","rc":[{"batb":[[0,2.46,27.95],[1,1.45,57.07],[2,1.1,25000]],"ltp":2.46,"tv":157.71,"id":349}]}]}
{"op":"mcm","clk":"11937466518","pt":1724685803077,"mc":[{"id":"1.232283631","rc":[{"batb":[[0,2.48,4],[1,2.46,27.95],[2,1.45,57.07]],"ltp":2.46,"tv":157.71,"id":349}]}]}
{"op":"mcm","clk":"11937466921","pt":1724685805504,"mc":[{"id":"1.232283631","rc":[{"batb":[[0,2.46,27.95],[1,1.45,57.07],[2,1.1,25000]],"ltp":2.46,"tv":157.71,"id":349}]}]}
{"op":"mcm","clk":"11937467332","pt":1724685807774,"mc":[{"id":"1.232283631","rc":[{"batb":[[0,2.48,4],[1,2.46,27.95],[2,1.45,57.07]],"ltp":2.46,"tv":157.71,"id":349}]}]}
{"op":"mcm","clk":"11937467761","pt":1724685810103,"mc":[{"id":"1.232283631","rc":[{"batb":[[0,2.46,27.95],[1,1.45,57.07],[2,1.1,25000]],"ltp":2.46,"tv":157.71,"id":349}]}]}
{"op":"mcm","clk":"11937468439","pt":1724685813914,"mc":[{"id":"1.232283631","rc":[{"batb":[[0,2.48,4],[1,2.46,27.95],[2,1.45,57.07]],"ltp":2.46,"tv":157.71,"id":349}]}]}
{"op":"mcm","clk":"11937468872","pt":1724685816234,"mc":[{"id":"1.232283631","rc":[{"batb":[[0,2.46,27.95],[1,1.45,57.07],[2,1.1,25000]],"ltp":2.46,"tv":157.71,"id":349}]}]}
{"op":"mcm","clk":"11937470338","pt":1724685824210,"mc":[{"id":"1.232283631","rc":[{"batb":[[0,2.48,4],[1,2.46,27.95],[2,1.45,57.07]],"ltp":2.46,"tv":157.71,"id":349}]}]}
{"op":"mcm","clk":"11937470703","pt":1724685826389,"mc":[{"id":"1.232283631","rc":[{"batb":[[0,2.46,27.95],[1,1.45,57.07],[2,1.1,25000]],"ltp":2.46,"tv":157.71,"id":349}]}]}
{"op":"mcm","clk":"11937471466","pt":1724685830742,"mc":[{"id":"1.232283631","rc":[{"batb":[[0,2.48,4],[1,2.46,27.95],[2,1.45,57.07]],"ltp":2.46,"tv":157.71,"id":349}]}]}
{"op":"mcm","clk":"11937471881","pt":1724685833039,"mc":[{"id":"1.232283631","rc":[{"batb":[[0,2.46,27.95],[1,1.45,57.07],[2,1.1,25000]],"ltp":2.46,"tv":157.71,"id":349}]}]}
{"op":"mcm","clk":"11937473418","pt":1724685841946,"mc":[{"id":"1.232283631","rc":[{"batb":[[0,2.48,4],[1,2.46,27.95],[2,1.45,57.07]],"ltp":2.46,"tv":157.71,"id":349}]}]}
{"op":"mcm","clk":"11937473843","pt":1724685844218,"mc":[{"id":"1.232283631","rc":[{"batb":[[0,2.46,27.95],[1,1.45,57.07],[2,1.1,25000]],"ltp":2.46,"tv":157.71,"id":349}]}]}
{"op":"mcm","clk":"11937474497","pt":1724685847841,"mc":[{"id":"1.232283631","rc":[{"batb":[[0,2.48,4],[1,2.46,27.95],[2,1.45,57.07]],"ltp":2.46,"tv":157.71,"id":349}]}]}
{"op":"mcm","clk":"11937474881","pt":1724685850055,"mc":[{"id":"1.232283631","rc":[{"batb":[[0,2.46,27.95],[1,1.45,57.07],[2,1.1,25000]],"ltp":2.46,"tv":157.71,"id":349}]}]}
{"op":"mcm","clk":"11937476133","pt":1724685856353,"mc":[{"id":"1.232283631","rc":[{"batb":[[0,2.48,4],[1,2.46,27.95],[2,1.45,57.07]],"ltp":2.46,"tv":157.71,"id":349}]}]}
{"op":"mcm","clk":"11937476557","pt":1724685858577,"mc":[{"id":"1.232283631","rc":[{"batb":[[0,2.46,27.95],[1,1.45,57.07],[2,1.1,25000]],"ltp":2.46,"tv":157.71,"id":349}]}]}
{"op":"mcm","clk":"11937477032","pt":1724685860964,"mc":[{"id":"1.232283631","rc":[{"batb":[[0,2.48,4],[1,2.46,27.95],[2,1.45,57.07]],"ltp":2.46,"tv":157.71,"id":349}]}]}
{"op":"mcm","clk":"11937477440","pt":1724685863336,"mc":[{"id":"1.232283631","rc":[{"batb":[[0,2.46,27.95],[1,1.45,57.07],[2,1.1,25000]],"ltp":2.46,"tv":157.71,"id":349}]}]}
{"op":"mcm","clk":"11937478283","pt":1724685868247,"mc":[{"id":"1.232283631","rc":[{"batb":[[0,2.48,4],[1,2.46,27.95],[2,1.45,57.07]],"ltp":2.46,"tv":157.71,"id":349}]}]}
{"op":"mcm","clk":"11937478642","pt":1724685870456,"mc":[{"id":"1.232283631","rc":[{"batb":[[0,2.46,27.95],[1,1.45,57.07],[2,1.1,25000]],"ltp":2.46,"tv":157.71,"id":349}]}]}
{"op":"mcm","clk":"11937479317","pt":1724685874273,"mc":[{"id":"1.232283631","rc":[{"batb":[[0,2.48,4],[1,2.46,27.95],[2,1.45,57.07]],"ltp":2.46,"tv":157.71,"id":349}]}]}
{"op":"mcm","clk":"11937479722","pt":1724685876548,"mc":[{"id":"1.232283631","rc":[{"batb":[[0,2.46,27.95],[1,1.45,57.07],[2,1.1,25000]],"ltp":2.46,"tv":157.71,"id":349}]}]}
{"op":"mcm","clk":"11937480283","pt":1724685879666,"mc":[{"id":"1.232283631","rc":[{"batb":[[0,2.48,4],[1,2.46,27.95],[2,1.45,57.07]],"ltp":2.46,"tv":157.71,"id":349}]}]}
{"op":"mcm","clk":"11937480719","pt":1724685882051,"mc":[{"id":"1.232283631","rc":[{"batb":[[0,2.46,27.95],[1,1.45,57.07],[2,1.1,25000]],"ltp":2.46,"tv":157.71,"id":349}]}]}
{"op":"mcm","clk":"11937482709","pt":1724685893170,"mc":[{"id":"1.232283631","rc":[{"batb":[[0,2.48,4],[1,2.46,27.95],[2,1.45,57.07]],"ltp":2.46,"tv":157.71,"id":349}]}]}
{"op":"mcm","clk":"11937483135","pt":1724685895485,"mc":[{"id":"1.232283631","rc":[{"batb":[[0,2.46,27.95],[1,1.45,57.07],[2,1.1,25000]],"ltp":2.46,"tv":157.71,"id":349}]}]}
{"op":"mcm","clk":"11937483814","pt":1724685899188,"mc":[{"id":"1.232283631","rc":[{"batb":[[0,2.48,4],[1,2.46,27.95],[2,1.45,57.07]],"ltp":2.46,"tv":157.71,"id":349}]}]}
{"op":"mcm","clk":"11937484222","pt":1724685901413,"mc":[{"id":"1.232283631","rc":[{"batb":[[0,2.46,27.95],[1,1.45,57.07],[2,1.1,25000]],"ltp":2.46,"tv":157.71,"id":349}]}]}
{"op":"mcm","clk":"11937484920","pt":1724685904968,"mc":[{"id":"1.232283631","rc":[{"batb":[[0,2.48,4],[1,2.46,27.95],[2,1.45,57.07]],"ltp":2.46,"tv":157.71,"id":349}]}]}
{"op":"mcm","clk":"11937485398","pt":1724685907358,"mc":[{"id":"1.232283631","rc":[{"batb":[[0,2.46,27.95],[1,1.45,57.07],[2,1.1,25000]],"ltp":2.46,"tv":157.71,"id":349}]}]}
{"op":"mcm","clk":"11937486422","pt":1724685912617,"mc":[{"id":"1.232283631","rc":[{"batb":[[0,2.48,4],[1,2.46,27.95],[2,1.45,57.07]],"ltp":2.46,"tv":157.71,"id":349}]}]}
{"op":"mcm","clk":"11937486894","pt":1724685914802,"mc":[{"id":"1.232283631","rc":[{"batb":[[0,2.46,27.95],[1,1.45,57.07],[2,1.1,25000]],"ltp":2.46,"tv":157.71,"id":349}]}]}
{"op":"mcm","clk":"11937487696","pt":1724685918796,"mc":[{"id":"1.232283631","rc":[{"batb":[[0,2.48,4],[1,2.46,27.95],[2,1.45,57.07]],"ltp":2.46,"tv":157.71,"id":349}]}]}
{"op":"mcm","clk":"11937488134","pt":1724685921024,"mc":[{"id":"1.232283631","rc":[{"batb":[[0,2.46,27.95],[1,1.45,57.07],[2,1.1,25000]],"ltp":2.46,"tv":157.71,"id":349}]}]}
{"op":"mcm","clk":"11937488976","pt":1724685924995,"mc":[{"id":"1.232283631","rc":[{"batb":[[0,2.48,4],[1,2.46,27.95],[2,1.45,57.07]],"ltp":2.46,"tv":157.71,"id":349}]}]}
{"op":"mcm","clk":"11937489391","pt":1724685927211,"mc":[{"id":"1.232283631","rc":[{"batb":[[0,2.46,27.95],[1,1.45,57.07],[2,1.1,25000]],"ltp":2.46,"tv":157.71,"id":349}]}]}
{"op":"mcm","clk":"11937489876","pt":1724685929629,"mc":[{"id":"1.232283631","rc":[{"batb":[[0,2.48,4],[1,2.46,27.95],[2,1.45,57.07]],"ltp":2.46,"tv":157.71,"id":349}]}]}
{"op":"mcm","clk":"11937490396","pt":1724685932125,"mc":[{"id":"1.232283631","rc":[{"batb":[[0,2.46,27.95],[1,1.45,57.07],[2,1.1,25000]],"ltp":2.46,"tv":157.71,"id":349}]}]}
{"op":"mcm","clk":"11937491421","pt":1724685937414,"mc":[{"id":"1.232283631","rc":[{"batb":[[0,2.48,4],[1,2.46,27.95],[2,1.45,57.07]],"ltp":2.46,"tv":157.71,"id":349}]}]}
{"op":"mcm","clk":"11937491889","pt":1724685939706,"mc":[{"id":"1.232283631","rc":[{"batb":[[0,2.46,27.95],[1,1.45,57.07],[2,1.1,25000]],"ltp":2.46,"tv":157.71,"id":349}]}]}
{"op":"mcm","clk":"11937492598","pt":1724685943119,"mc":[{"id":"1.232283631","rc":[{"batb":[[0,2.48,4],[1,2.46,27.95],[2,1.45,57.07]],"ltp":2.46,"tv":157.71,"id":349}]}]}
{"op":"mcm","clk":"11937493022","pt":1724685945334,"mc":[{"id":"1.232283631","rc":[{"batb":[[0,2.46,27.95],[1,1.45,57.07],[2,1.1,25000]],"ltp":2.46,"tv":157.71,"id":349}]}]}
{"op":"mcm","clk":"11937493556","pt":1724685948199,"mc":[{"id":"1.232283631","rc":[{"batb":[[0,2.48,4],[1,2.46,27.95],[2,1.45,57.07]],"ltp":2.46,"tv":157.71,"id":349}]}]}
{"op":"mcm","clk":"11937494030","pt":1724685950729,"mc":[{"id":"1.232283631","rc":[{"batb":[[0,2.46,27.95],[1,1.45,57.07],[2,1.1,25000]],"ltp":2.46,"tv":157.71,"id":349}]}]}
{"op":"mcm","clk":"11937494701","pt":1724685954020,"mc":[{"id":"1.232283631","rc":[{"batb":[[0,2.48,4],[1,2.46,27.95],[2,1.45,57.07]],"ltp":2.46,"tv":157.71,"id":349}]}]}
{"op":"mcm","clk":"11937495188","pt":1724685956546,"mc":[{"id":"1.232283631","rc":[{"batb":[[0,2.46,27.95],[1,1.45,57.07],[2,1.1,25000]],"ltp":2.46,"tv":157.71,"id":349}]}]}
{"op":"mcm","clk":"11937496325","pt":1724685962555,"mc":[{"id":"1.232283631","rc":[{"batb":[[0,2.48,4],[1,2.46,27.95],[2,1.45,57.07]],"ltp":2.46,"tv":157.71,"id":349}]}]}
{"op":"mcm","clk":"11937496790","pt":1724685964938,"mc":[{"id":"1.232283631","rc":[{"batb":[[0,2.46,27.95],[1,1.45,57.07],[2,1.1,25000]],"ltp":2.46,"tv":157.71,"id":349}]}]}
{"op":"mcm","clk":"11937497493","pt":1724685968443,"mc":[{"id":"1.232283631","rc":[{"batb":[[0,2.48,4],[1,2.46,27.95],[2,1.45,57.07]],"ltp":2.46,"tv":157.71,"id":349}]}]}
{"op":"mcm","clk":"11937498064","pt":1724685971471,"mc":[{"id":"1.232283631","rc":[{"batb":[[0,2.46,27.95],[1,1.45,57.07],[2,1.1,25000]],"ltp":2.46,"tv":157.71,"id":349}]}]}
{"op":"mcm","clk":"11937498452","pt":1724685973676,"mc":[{"id":"1.232283631","rc":[{"batb":[[0,2.48,4],[1,2.46,27.95],[2,1.45,57.07]],"ltp":2.46,"tv":157.71,"id":349}]}]}
{"op":"mcm","clk":"11937498900","pt":1724685975961,"mc":[{"id":"1.232283631","rc":[{"batb":[[0,2.46,27.95],[1,1.45,57.07],[2,1.1,25000]],"ltp":2.46,"tv":157.71,"id":349}]}]}
{"op":"mcm","clk":"11937500016","pt":1724685982172,"mc":[{"id":"1.232283631","rc":[{"batb":[[0,2.48,4],[1,2.46,27.95],[2,1.45,57.07]],"ltp":2.46,"tv":157.71,"id":349}]}]}
{"op":"mcm","clk":"11937500441","pt":1724685984479,"mc":[{"id":"1.232283631","rc":[{"batb":[[0,2.46,27.95],[1,1.45,57.07],[2,1.1,25000]],"ltp":2.46,"tv":157.71,"id":349}]}]}
{"op":"mcm","clk":"11937500882","pt":1724685986785,"mc":[{"id":"1.232283631","rc":[{"batb":[[0,2.48,4],[1,2.46,27.95],[2,1.45,57.07]],"ltp":2.46,"tv":157.71,"id":349}]}]}
{"op":"mcm","clk":"11937501342","pt":1724685989177,"mc":[{"id":"1.232283631","rc":[{"batb":[[0,2.46,27.95],[1,1.45,57.07],[2,1.1,25000]],"ltp":2.46,"tv":157.71,"id":349}]}]}
{"op":"mcm","clk":"11937502530","pt":1724685995777,"mc":[{"id":"1.232283631","rc":[{"batb":[[0,2.48,4],[1,2.46,27.95],[2,1.45,57.07]],"ltp":2.46,"tv":157.71,"id":349}]}]}
{"op":"mcm","clk":"11937502920","pt":1724685998096,"mc":[{"id":"1.232283631","rc":[{"batb":[[0,2.46,27.95],[1,1.45,57.07],[2,1.1,25000]],"ltp":2.46,"tv":157.71,"id":349}]}]}
{"op":"mcm","clk":"11937505154","pt":1724686010785,"mc":[{"id":"1.232283631","rc":[{"batb":[[0,2.48,4],[1,2.46,27.95],[2,1.45,57.07]],"ltp":2.46,"tv":157.71,"id":349}]}]}
{"op":"mcm","clk":"11937505533","pt":1724686013105,"mc":[{"id":"1.232283631","rc":[{"batb":[[0,2.46,27.95],[1,1.45,57.07],[2,1.1,25000]],"ltp":2.46,"tv":157.71,"id":349}]}]}
{"op":"mcm","clk":"11937505996","pt":1724686015722,"mc":[{"id":"1.232283631","rc":[{"batb":[[0,2.48,4],[1,2.46,27.95],[2,1.45,57.07]],"ltp":2.46,"tv":157.71,"id":349}]}]}
{"op":"mcm","clk":"11937506370","pt":1724686017911,"mc":[{"id":"1.232283631","rc":[{"batb":[[0,2.46,27.95],[1,1.45,57.07],[2,1.1,25000]],"ltp":2.46,"tv":157.71,"id":349}]}]}
{"op":"mcm","clk":"11937507698","pt":1724686025230,"mc":[{"id":"1.232283631","rc":[{"batb":[[0,2.48,4],[1,2.46,27.95],[2,1.45,57.07]],"ltp":2.46,"tv":157.71,"id":349}]}]}
{"op":"mcm","clk":"11937508098","pt":1724686027544,"mc":[{"id":"1.232283631","rc":[{"batb":[[0,2.46,27.95],[1,1.45,57.07],[2,1.1,25000]],"ltp":2.46,"tv":157.71,"id":349}]}]}
{"op":"mcm","clk":"11937509023","pt":1724686032419,"mc":[{"id":"1.232283631","rc":[{"batb":[[0,2.48,4],[1,2.46,27.95],[2,1.45,57.07]],"ltp":2.46,"tv":157.71,"id":349}]}]}
{"op":"mcm","clk":"11937509484","pt":1724686034733,"mc":[{"id":"1.232283631","rc":[{"batb":[[0,2.46,27.95],[1,1.45,57.07],[2,1.1,25000]],"ltp":2.46,"tv":157.71,"id":349}]}]}
{"op":"mcm","clk":"11937510453","pt":1724686039833,"mc":[{"id":"1.232283631","rc":[{"batb":[[0,2.48,4],[1,2.46,27.95],[2,1.45,57.07]],"ltp":2.46,"tv":157.71,"id":349}]}]}
{"op":"mcm","clk":"11937510890","pt":1724686042259,"mc":[{"id":"1.232283631","rc":[{"batb":[[0,2.46,27.95],[1,1.45,57.07],[2,1.1,25000]],"ltp":2.46,"tv":157.71,"id":349}]}]}
{"op":"mcm","clk":"11937511633","pt":1724686046335,"mc":[{"id":"1.232283631","rc":[{"batb":[[0,2.48,4],[1,2.46,27.95],[2,1.45,57.07]],"ltp":2.46,"tv":157.71,"id":349}]}]}
{"op":"mcm","clk":"11937512020","pt":1724686048537,"mc":[{"id":"1.232283631","rc":[{"batb":[[0,2.46,27.95],[1,1.45,57.07],[2,1.1,25000]],"ltp":2.46,"tv":157.71,"id":349}]}]}
{"op":"mcm","clk":"11937512448","pt":1724686051047,"mc":[{"id":"1.232283631","rc":[{"batb":[[0,2.48,4],[1,2.46,27.95],[2,1.45,57.07]],"ltp":2.46,"tv":157.71,"id":349}]}]}
{"op":"mcm","clk":"11937512852","pt":1724686053266,"mc":[{"id":"1.232283631","rc":[{"batb":[[0,2.46,27.95],[1,1.45,57.07],[2,1.1,25000]],"ltp":2.46,"tv":157.71,"id":349}]}]}
{"op":"mcm","clk":"11937513680","pt":1724686057864,"mc":[{"id":"1.232283631","rc":[{"batb":[[0,2.48,4],[1,2.46,27.95],[2,1.45,57.07]],"ltp":2.46,"tv":157.71,"id":349}]}]}
{"op":"mcm","clk":"11937514173","pt":1724686060268,"mc":[{"id":"1.232283631","rc":[{"batb":[[0,2.46,27.95],[1,1.45,57.07],[2,1.1,25000]],"ltp":2.46,"tv":157.71,"id":349}]}]}
{"op":"mcm","clk":"11937515006","pt":1724686064470,"mc":[{"id":"1.232283631","rc":[{"batb":[[0,2.48,4],[1,2.46,27.95],[2,1.45,57.07]],"ltp":2.46,"tv":157.71,"id":349}]}]}
{"op":"mcm","clk":"11937515421","pt":1724686066787,"mc":[{"id":"1.232283631","rc":[{"batb":[[0,2.46,27.95],[1,1.45,57.07],[2,1.1,25000]],"ltp":2.46,"tv":157.71,"id":349}]}]}
{"op":"mcm","clk":"11937516268","pt":1724686071372,"mc":[{"id":"1.232283631","rc":[{"batb":[[0,2.48,4],[1,2.46,27.95],[2,1.45,57.07]],"ltp":2.46,"tv":157.71,"id":349}]}]}
{"op":"mcm","clk":"11937516665","pt":1724686073576,"mc":[{"id":"1.232283631","rc":[{"batb":[[0,2.46,27.95],[1,1.45,57.07],[2,1.1,25000]],"ltp":2.46,"tv":157.71,"id":349}]}]}
{"op":"mcm","clk":"11937517129","pt":1724686076077,"mc":[{"id":"1.232283631","rc":[{"batb":[[0,2.48,4],[1,2.46,27.95],[2,1.45,57.07]],"ltp":2.46,"tv":157.71,"id":349}]}]}
{"op":"mcm","clk":"11937517541","pt":1724686078497,"mc":[{"id":"1.232283631","rc":[{"batb":[[0,2.46,27.95],[1,1.45,57.07],[2,1.1,25000]],"ltp":2.46,"tv":157.71,"id":349}]}]}
{"op":"mcm","clk":"11937519157","pt":1724686086905,"mc":[{"id":"1.232283631","rc":[{"batb":[[0,2.48,4],[1,2.46,27.95],[2,1.45,57.07]],"ltp":2.46,"tv":157.71,"id":349}]}]}
{"op":"mcm","clk":"11937519597","pt":1724686089308,"mc":[{"id":"1.232283631","rc":[{"batb":[[0,2.46,27.95],[1,1.45,57.07],[2,1.1,25000]],"ltp":2.46,"tv":157.71,"id":349}]}]}
{"op":"mcm","clk":"11937520479","pt":1724686094211,"mc":[{"id":"1.232283631","rc":[{"batb":[[0,2.48,4],[1,2.46,27.95],[2,1.45,57.07]],"ltp":2.46,"tv":157.71,"id":349}]}]}
{"op":"mcm","clk":"11937521005","pt":1724686097413,"mc":[{"id":"1.232283631","rc":[{"batb":[[0,2.46,27.95],[1,1.45,57.07],[2,1.1,25000]],"ltp":2.46,"tv":157.71,"id":349}]}]}
{"op":"mcm","clk":"11937521440","pt":1724686099917,"mc":[{"id":"1.232283631","rc":[{"batb":[[0,2.48,4],[1,2.46,27.95],[2,1.45,57.07]],"ltp":2.46,"tv":157.71,"id":349}]}]}
{"op":"mcm","clk":"11937521809","pt":1724686102214,"mc":[{"id":"1.232283631","rc":[{"batb":[[0,2.46,27.95],[1,1.45,57.07],[2,1.1,25000]],"ltp":2.46,"tv":157.71,"id":349}]}]}
{"op":"mcm","clk":"11937522908","pt":1724686108833,"mc":[{"id":"1.232283631","rc":[{"batb":[[0,2.48,4],[1,2.46,27.95],[2,1.45,57.07]],"ltp":2.46,"tv":157.71,"id":349}]}]}
{"op":"mcm","clk":"11937523251","pt":1724686111022,"mc":[{"id":"1.232283631","rc":[{"batb":[[0,2.46,27.95],[1,1.45,57.07],[2,1.1,25000]],"ltp":2.46,"tv":157.71,"id":349}]}]}
{"op":"mcm","clk":"11937524065","pt":1724686116313,"mc":[{"id":"1.232283631","rc":[{"batb":[[0,2.48,4],[1,2.46,27.95],[2,1.45,57.07]],"ltp":2.46,"tv":157.71,"id":349}]}]}
{"op":"mcm","clk":"11937524447","pt":1724686118834,"mc":[{"id":"1.232283631","rc":[{"batb":[[0,2.46,27.95],[1,1.45,57.07],[2,1.1,25000]],"ltp":2.46,"tv":157.71,"id":349}]}]}
{"op":"mcm","clk":"11937524987","pt":1724686122523,"mc":[{"id":"1.232283631","rc":[{"batb":[[0,2.48,4],[1,2.46,27.95],[2,1.45,57.07]],"ltp":2.46,"tv":157.71,"id":349}]}]}
{"op":"mcm","clk":"11937525327","pt":1724686124848,"mc":[{"id":"1.232283631","rc":[{"batb":[[0,2.46,27.95],[1,1.45,57.07],[2,1.1,25000]],"ltp":2.46,"tv":157.71,"id":349}]}]}
{"op":"mcm","clk":"11937525802","pt":1724686127945,"mc":[{"id":"1.232283631","rc":[{"batb":[[0,2.48,4],[1,2.46,27.95],[2,1.45,57.07]],"ltp":2.46,"tv":157.71,"id":349}]}]}
{"op":"mcm","clk":"11937526201","pt":1724686130330,"mc":[{"id":"1.232283631","rc":[{"batb":[[0,2.46,27.95],[1,1.45,57.07],[2,1.1,25000]],"ltp":2.46,"tv":157.71,"id":349}]}]}
{"op":"mcm","clk":"11937527273","pt":1724686137158,"mc":[{"id":"1.232283631","rc":[{"batb":[[0,2.48,4],[1,2.46,27.95],[2,1.45,57.07]],"ltp":2.46,"tv":157.71,"id":349}]}]}
{"op":"mcm","clk":"11937527621","pt":1724686139334,"mc":[{"id":"1.232283631","rc":[{"batb":[[0,2.46,27.95],[1,1.45,57.07],[2,1.1,25000]],"ltp":2.46,"tv":157.71,"id":349}]}]}
{"op":"mcm","clk":"11937528401","pt":1724686143862,"mc":[{"id":"1.232283631","rc":[{"batb":[[0,2.48,4],[1,2.46,27.95],[2,1.45,57.07]],"ltp":2.46,"tv":157.71,"id":349}]}]}
{"op":"mcm","clk":"11937528818","pt":1724686146161,"mc":[{"id":"1.232283631","rc":[{"batb":[[0,2.46,27.95],[1,1.45,57.07],[2,1.1,25000]],"ltp":2.46,"tv":157.71,"id":349}]}]}
{"op":"mcm","clk":"11937529754","pt":1724686151667,"mc":[{"id":"1.232283631","rc":[{"batb":[[0,2.48,4],[1,2.46,27.95],[2,1.45,57.07]],"ltp":2.46,"tv":157.71,"id":349}]}]}
{"op":"mcm","clk":"11937530198","pt":1724686154188,"mc":[{"id":"1.232283631","rc":[{"batb":[[0,2.46,27.95],[1,1.45,57.07],[2,1.1,25000]],"ltp":2.46,"tv":157.71,"id":349}]}]}
{"op":"mcm","clk":"11937530555","pt":1724686156360,"mc":[{"id":"1.232283631","rc":[{"batb":[[0,2.48,4],[1,2.46,27.95],[2,1.45,57.07]],"ltp":2.46,"tv":157.71,"id":349}]}]}
{"op":"mcm","clk":"11937530892","pt":1724686158571,"mc":[{"id":"1.232283631","rc":[{"batb":[[0,2.46,27.95],[1,1.45,57.07],[2,1.1,25000]],"ltp":2.46,"tv":157.71,"id":349}]}]}
{"op":"mcm","clk":"11937532908","pt":1724686170597,"mc":[{"id":"1.232283631","rc":[{"batb":[[0,2.48,4],[1,2.46,27.95],[2,1.45,57.07]],"ltp":2.46,"tv":157.71,"id":349}]}]}
{"op":"mcm","clk":"11937533291","pt":1724686172784,"mc":[{"id":"1.232283631","rc":[{"batb":[[0,2.46,27.95],[1,1.45,57.07],[2,1.1,25000]],"ltp":2.46,"tv":157.71,"id":349}]}]}
{"op":"mcm","clk":"11937536894","pt":1724686193815,"mc":[{"id":"1.232283631","rc":[{"batb":[[0,2.48,4],[1,2.46,27.95],[2,1.45,57.07]],"ltp":2.46,"tv":157.71,"id":349}]}]}
{"op":"mcm","clk":"11937537304","pt":1724686196124,"mc":[{"id":"1.232283631","rc":[{"batb":[[0,2.46,27.95],[1,1.45,57.07],[2,1.1,25000]],"ltp":2.46,"tv":157.71,"id":349}]}]}
{"op":"mcm","clk":"11937539242","pt":1724686206220,"mc":[{"id":"1.232283631","rc":[{"batb":[[0,2.48,4],[1,2.46,27.95],[2,1.45,57.07]],"ltp":2.46,"tv":157.71,"id":349}]}]}
{"op":"mcm","clk":"11937539693","pt":1724686208513,"mc":[{"id":"1.232283631","rc":[{"batb":[[0,2.46,27.95],[1,1.45,57.07],[2,1.1,25000]],"ltp":2.46,"tv":157.71,"id":349}]}]}
{"op":"mcm","clk":"11937540394","pt":1724686212420,"mc":[{"id":"1.232283631","rc":[{"batb":[[0,2.48,4],[1,2.46,27.95],[2,1.45,57.07]],"ltp":2.46,"tv":157.71,"id":349}]}]}
{"op":"mcm","clk":"11937540831","pt":1724686214730,"mc":[{"id":"1.232283631","rc":[{"batb":[[0,2.46,27.95],[1,1.45,57.07],[2,1.1,25000]],"ltp":2.46,"tv":157.71,"id":349}]}]}
{"op":"mcm","clk":"11937541886","pt":1724686220741,"mc":[{"id":"1.232283631","rc":[{"batb":[[0,2.48,4],[1,2.46,27.95],[2,1.45,57.07]],"ltp":2.46,"tv":157.71,"id":349}]}]}
{"op":"mcm","clk":"11937542304","pt":1724686223141,"mc":[{"id":"1.232283631","rc":[{"batb":[[0,2.46,27.95],[1,1.45,57.07],[2,1.1,25000]],"ltp":2.46,"tv":157.71,"id":349}]}]}
{"op":"mcm","clk":"11937542803","pt":1724686226145,"mc":[{"id":"1.232283631","rc":[{"batb":[[0,2.48,4],[1,2.46,27.95],[2,1.45,57.07]],"ltp":2.46,"tv":157.71,"id":349}]}]}
{"op":"mcm","clk":"11937543201","pt":1724686228553,"mc":[{"id":"1.232283631","rc":[{"batb":[[0,2.46,27.95],[1,1.45,57.07],[2,1.1,25000]],"ltp":2.46,"tv":157.71,"id":349}]}]}
{"op":"mcm","clk":"11937543901","pt":1724686232559,"mc":[{"id":"1.232283631","rc":[{"batb":[[0,2.48,4],[1,2.46,27.95],[2,1.45,57.07]],"ltp":2.46,"tv":157.71,"id":349}]}]}
{"op":"mcm","clk":"11937544280","pt":1724686234748,"mc":[{"id":"1.232283631","rc":[{"batb":[[0,2.46,27.95],[1,1.45,57.07],[2,1.1,25000]],"ltp":2.46,"tv":157.71,"id":349}]}]}
{"op":"mcm","clk":"11937545861","pt":1724686243879,"mc":[{"id":"1.232283631","rc":[{"batb":[[0,2.48,4],[1,2.46,27.95],[2,1.45,57.07]],"ltp":2.46,"tv":157.71,"id":349}]}]}
{"op":"mcm","clk":"11937546295","pt":1724686246080,"mc":[{"id":"1.232283631","rc":[{"batb":[[0,2.46,27.95],[1,1.45,57.07],[2,1.1,25000]],"ltp":2.46,"tv":157.71,"id":349}]}]}
{"op":"mcm","clk":"11937547708","pt":1724686254366,"mc":[{"id":"1.232283631","rc":[{"batb":[[0,2.48,4],[1,2.46,27.95],[2,1.45,57.07]],"ltp":2.46,"tv":157.71,"id":349}]}]}
{"op":"mcm","clk":"11937548145","pt":1724686256779,"mc":[{"id":"1.232283631","rc":[{"batb":[[0,2.46,27.95],[1,1.45,57.07],[2,1.1,25000]],"ltp":2.46,"tv":157.71,"id":349}]}]}
{"op":"mcm","clk":"11937549035","pt":1724686261993,"mc":[{"id":"1.232283631","rc":[{"trd":[[2.46,34.22]],"batb":[[0,2.48,4],[1,2.46,20.96],[2,1.45,57.07]],"ltp":2.46,"tv":164.7,"id":349},{"trd":[[1.69,121.85]],"ltp":1.69,"tv":200.02,"id":235}],"tv":364.73}]}
{"op":"mcm","clk":"11937549124","pt":1724686262465,"mc":[{"id":"1.232283631","rc":[{"batb":[[1,2.46,27.95]],"ltp":2.46,"tv":164.7,"id":349}]}]}
{"op":"mcm","clk":"11937549442","pt":1724686264357,"mc":[{"id":"1.232283631","rc":[{"batb":[[0,2.46,27.95],[1,1.45,57.07],[2,1.1,25000]],"ltp":2.46,"tv":164.7,"id":349}]}]}
{"op":"mcm","clk":"11937550254","pt":1724686269192,"mc":[{"id":"1.232283631","rc":[{"batb":[[0,2.48,4],[1,2.46,27.95],[2,1.45,57.07]],"ltp":2.46,"tv":164.7,"id":349}]}]}
{"op":"mcm","clk":"11937550718","pt":1724686271610,"mc":[{"id":"1.232283631","rc":[{"batb":[[0,2.46,27.95],[1,1.45,57.07],[2,1.1,25000]],"ltp":2.46,"tv":164.7,"id":349}]}]}
{"op":"mcm","clk":"11937551195","pt":1724686274267,"mc":[{"id":"1.232283631","rc":[{"batb":[[0,2.48,4],[1,2.46,27.95],[2,1.45,57.07]],"ltp":2.46,"tv":164.7,"id":349}]}]}
{"op":"mcm","clk":"11937551576","pt":1724686276567,"mc":[{"id":"1.232283631","rc":[{"batb":[[0,2.46,27.95],[1,1.45,57.07],[2,1.1,25000]],"ltp":2.46,"tv":164.7,"id":349}]}]}
{"op":"mcm","clk":"11937551948","pt":1724686278778,"mc":[{"id":"1.232283631","rc":[{"batb":[[0,2.48,4],[1,2.46,27.95],[2,1.45,57.07]],"ltp":2.46,"tv":164.7,"id":349}]}]}
{"op":"mcm","clk":"11937552325","pt":1724686281103,"mc":[{"id":"1.232283631","rc":[{"batb":[[0,2.46,27.95],[1,1.45,57.07],[2,1.1,25000]],"ltp":2.46,"tv":164.7,"id":349}]}]}
{"op":"mcm","clk":"11937553298","pt":1724686286792,"mc":[{"id":"1.232283631","rc":[{"batb":[[0,2.48,4],[1,2.46,27.95],[2,1.45,57.07]],"ltp":2.46,"tv":164.7,"id":349}]}]}
{"op":"mcm","clk":"11937553743","pt":1724686289070,"mc":[{"id":"1.232283631","rc":[{"batb":[[0,2.46,27.95],[1,1.45,57.07],[2,1.1,25000]],"ltp":2.46,"tv":164.7,"id":349}]}]}
{"op":"mcm","clk":"11937554592","pt":1724686293480,"mc":[{"id":"1.232283631","rc":[{"batb":[[0,2.48,4],[1,2.46,27.95],[2,1.45,57.07]],"ltp":2.46,"tv":164.7,"id":349}]}]}
{"op":"mcm","clk":"11937555032","pt":1724686296008,"mc":[{"id":"1.232283631","rc":[{"batb":[[0,2.46,27.95],[1,1.45,57.07],[2,1.1,25000]],"ltp":2.46,"tv":164.7,"id":349}]}]}
{"op":"mcm","clk":"11937556258","pt":1724686302996,"mc":[{"id":"1.232283631","rc":[{"batb":[[0,2.48,4],[1,2.46,27.95],[2,1.45,57.07]],"ltp":2.46,"tv":164.7,"id":349}]}]}
{"op":"mcm","clk":"11937556669","pt":1724686305317,"mc":[{"id":"1.232283631","rc":[{"batb":[[0,2.46,27.95],[1,1.45,57.07],[2,1.1,25000]],"ltp":2.46,"tv":164.7,"id":349}]}]}
{"op":"mcm","clk":"11937557227","pt":1724686308633,"mc":[{"id":"1.232283631","rc":[{"batb":[[0,2.48,4],[1,2.46,27.95],[2,1.45,57.07]],"ltp":2.46,"tv":164.7,"id":349}]}]}
{"op":"mcm","clk":"11937557620","pt":1724686310818,"mc":[{"id":"1.232283631","rc":[{"batb":[[0,2.46,27.95],[1,1.45,57.07],[2,1.1,25000]],"ltp":2.46,"tv":164.7,"id":349}]}]}
{"op":"mcm","clk":"11937558152","pt":1724686313841,"mc":[{"id":"1.232283631","rc":[{"batb":[[0,2.48,4],[1,2.46,27.95],[2,1.45,57.07]],"ltp":2.46,"tv":164.7,"id":349}]}]}
{"op":"mcm","clk":"11937558602","pt":1724686316330,"mc":[{"id":"1.232283631","rc":[{"batb":[[0,2.46,27.95],[1,1.45,57.07],[2,1.1,25000]],"ltp":2.46,"tv":164.7,"id":349}]}]}
{"op":"mcm","clk":"11937559823","pt":1724686323242,"mc":[{"id":"1.232283631","rc":[{"batb":[[0,2.48,4],[1,2.46,27.95],[2,1.45,57.07]],"ltp":2.46,"tv":164.7,"id":349}]}]}
{"op":"mcm","clk":"11937560284","pt":1724686325651,"mc":[{"id":"1.232283631","rc":[{"batb":[[0,2.46,27.95],[1,1.45,57.07],[2,1.1,25000]],"ltp":2.46,"tv":164.7,"id":349}]}]}
{"op":"mcm","clk":"11937561893","pt":1724686334321,"mc":[{"id":"1.232283631","rc":[{"batb":[[0,2.48,4],[1,2.46,27.95],[2,1.45,57.07]],"ltp":2.46,"tv":164.7,"id":349}]}]}
{"op":"mcm","clk":"11937562313","pt":1724686336756,"mc":[{"id":"1.232283631","rc":[{"batb":[[0,2.46,27.95],[1,1.45,57.07],[2,1.1,25000]],"ltp":2.46,"tv":164.7,"id":349}]}]}
{"op":"mcm","clk":"11937562769","pt":1724686339324,"mc":[{"id":"1.232283631","rc":[{"batb":[[0,2.48,4],[1,2.46,27.95],[2,1.45,57.07]],"ltp":2.46,"tv":164.7,"id":349}]}]}
{"op":"mcm","clk":"11937563187","pt":1724686341736,"mc":[{"id":"1.232283631","rc":[{"batb":[[0,2.46,27.95],[1,1.45,57.07],[2,1.1,25000]],"ltp":2.46,"tv":164.7,"id":349}]}]}
{"op":"mcm","clk":"11937564230","pt":1724686347458,"mc":[{"id":"1.232283631","rc":[{"batb":[[0,2.48,4],[1,2.46,27.95],[2,1.45,57.07]],"ltp":2.46,"tv":164.7,"id":349}]}]}
{"op":"mcm","clk":"11937564622","pt":1724686349835,"mc":[{"id":"1.232283631","rc":[{"batb":[[0,2.46,27.95],[1,1.45,57.07],[2,1.1,25000]],"ltp":2.46,"tv":164.7,"id":349}]}]}
{"op":"mcm","clk":"11937565385","pt":1724686354346,"mc":[{"id":"1.232283631","rc":[{"batb":[[0,2.48,4],[1,2.46,27.95],[2,1.45,57.07]],"ltp":2.46,"tv":164.7,"id":349}]}]}
{"op":"mcm","clk":"11937565773","pt":1724686356773,"mc":[{"id":"1.232283631","rc":[{"batb":[[0,2.46,27.95],[1,1.45,57.07],[2,1.1,25000]],"ltp":2.46,"tv":164.7,"id":349}]}]}
{"op":"mcm","clk":"11937566766","pt":1724686362575,"mc":[{"id":"1.232283631","rc":[{"batb":[[0,2.48,4],[1,2.46,27.95],[2,1.45,57.07]],"ltp":2.46,"tv":164.7,"id":349}]}]}
{"op":"mcm","clk":"11937567136","pt":1724686364888,"mc":[{"id":"1.232283631","rc":[{"batb":[[0,2.46,27.95],[1,1.45,57.07],[2,1.1,25000]],"ltp":2.46,"tv":164.7,"id":349}]}]}
{"op":"mcm","clk":"11937567754","pt":1724686368464,"mc":[{"id":"1.232283631","rc":[{"batb":[[0,2.48,4],[1,2.46,27.95],[2,1.45,57.07]],"ltp":2.46,"tv":164.7,"id":349}]}]}
{"op":"mcm","clk":"11937568186","pt":1724686370876,"mc":[{"id":"1.232283631","rc":[{"batb":[[0,2.46,27.95],[1,1.45,57.07],[2,1.1,25000]],"ltp":2.46,"tv":164.7,"id":349}]}]}
{"op":"mcm","clk":"11937569216","pt":1724686376670,"mc":[{"id":"1.232283631","rc":[{"batb":[[0,2.48,4],[1,2.46,27.95],[2,1.45,57.07]],"ltp":2.46,"tv":164.7,"id":349}]}]}
{"op":"mcm","clk":"11937569636","pt":1724686379077,"mc":[{"id":"1.232283631","rc":[{"batb":[[0,2.46,27.95],[1,1.45,57.07],[2,1.1,25000]],"ltp":2.46,"tv":164.7,"id":349}]}]}
{"op":"mcm","clk":"11937570415","pt":1724686383577,"mc":[{"id":"1.232283631","rc":[{"batb":[[0,2.48,4],[1,2.46,27.95],[2,1.45,57.07]],"ltp":2.46,"tv":164.7,"id":349}]}]}
{"op":"mcm","clk":"11937570854","pt":1724686385986,"mc":[{"id":"1.232283631","rc":[{"batb":[[0,2.46,27.95],[1,1.45,57.07],[2,1.1,25000]],"ltp":2.46,"tv":164.7,"id":349}]}]}
{"op":"mcm","clk":"11937571275","pt":1724686388784,"mc":[{"id":"1.232283631","rc":[{"batb":[[0,2.48,4],[1,2.46,27.95],[2,1.45,57.07]],"ltp":2.46,"tv":164.7,"id":349}]}]}
{"op":"mcm","clk":"11937571836","pt":1724686391490,"mc":[{"id":"1.232283631","rc":[{"batb":[[0,2.46,27.95],[1,1.45,57.07],[2,1.1,25000]],"ltp":2.46,"tv":164.7,"id":349}]}]}
{"op":"mcm","clk":"11937572416","pt":1724686394792,"mc":[{"id":"1.232283631","rc":[{"batb":[[0,2.48,4],[1,2.46,27.95],[2,1.45,57.07]],"ltp":2.46,"tv":164.7,"id":349}]}]}
{"op":"mcm","clk":"11937572822","pt":1724686397090,"mc":[{"id":"1.232283631","rc":[{"batb":[[0,2.46,27.95],[1,1.45,57.07],[2,1.1,25000]],"ltp":2.46,"tv":164.7,"id":349}]}]}
{"op":"mcm","clk":"11937573323","pt":1724686399902,"mc":[{"id":"1.232283631","rc":[{"batb":[[0,2.48,4],[1,2.46,27.95],[2,1.45,57.07]],"ltp":2.46,"tv":164.7,"id":349}]}]}
{"op":"mcm","clk":"11937573800","pt":1724686402388,"mc":[{"id":"1.232283631","rc":[{"batb":[[0,2.46,27.95],[1,1.45,57.07],[2,1.1,25000]],"ltp":2.46,"tv":164.7,"id":349}]}]}
{"op":"mcm","clk":"11937574318","pt":1724686405203,"mc":[{"id":"1.232283631","rc":[{"batb":[[0,2.48,4],[1,2.46,27.95],[2,1.45,57.07]],"ltp":2.46,"tv":164.7,"id":349}]}]}
{"op":"mcm","clk":"11937574762","pt":1724686407724,"mc":[{"id":"1.232283631","rc":[{"batb":[[0,2.46,27.95],[1,1.45,57.07],[2,1.1,25000]],"ltp":2.46,"tv":164.7,"id":349}]}]}
{"op":"mcm","clk":"11937576334","pt":1724686416110,"mc":[{"id":"1.232283631","rc":[{"batb":[[0,2.48,4],[1,2.46,27.95],[2,1.45,57.07]],"ltp":2.46,"tv":164.7,"id":349}]}]}
{"op":"mcm","clk":"11937576804","pt":1724686418505,"mc":[{"id":"1.232283631","rc":[{"batb":[[0,2.46,27.95],[1,1.45,57.07],[2,1.1,25000]],"ltp":2.46,"tv":164.7,"id":349}]}]}
{"op":"mcm","clk":"11937577368","pt":1724686421818,"mc":[{"id":"1.232283631","rc":[{"batb":[[0,2.48,4],[1,2.46,27.95],[2,1.45,57.07]],"ltp":2.46,"tv":164.7,"id":349}]}]}
{"op":"mcm","clk":"11937577736","pt":1724686424123,"mc":[{"id":"1.232283631","rc":[{"batb":[[0,2.46,27.95],[1,1.45,57.07],[2,1.1,25000]],"ltp":2.46,"tv":164.7,"id":349}]}]}
{"op":"mcm","clk":"11937578226","pt":1724686426923,"mc":[{"id":"1.232283631","rc":[{"batb":[[0,2.48,4],[1,2.46,27.95],[2,1.45,57.07]],"ltp":2.46,"tv":164.7,"id":349}]}]}
{"op":"mcm","clk":"11937578632","pt":1724686429346,"mc":[{"id":"1.232283631","rc":[{"batb":[[0,2.46,27.95],[1,1.45,57.07],[2,1.1,25000]],"ltp":2.46,"tv":164.7,"id":349}]}]}
{"op":"mcm","clk":"11937579534","pt":1724686434219,"mc":[{"id":"1.232283631","rc":[{"batb":[[0,2.48,4],[1,2.46,27.95],[2,1.45,57.07]],"ltp":2.46,"tv":164.7,"id":349}]}]}
{"op":"mcm","clk":"11937579915","pt":1724686436532,"mc":[{"id":"1.232283631","rc":[{"batb":[[0,2.46,27.95],[1,1.45,57.07],[2,1.1,25000]],"ltp":2.46,"tv":164.7,"id":349}]}]}
{"op":"mcm","clk":"11937580462","pt":1724686439852,"mc":[{"id":"1.232283631","rc":[{"batb":[[0,2.48,4],[1,2.46,27.95],[2,1.45,57.07]],"ltp":2.46,"tv":164.7,"id":349}]}]}
{"op":"mcm","clk":"11937580913","pt":1724686442361,"mc":[{"id":"1.232283631","rc":[{"batb":[[0,2.46,27.95],[1,1.45,57.07],[2,1.1,25000]],"ltp":2.46,"tv":164.7,"id":349}]}]}
{"op":"mcm","clk":"11937581316","pt":1724686444533,"mc":[{"id":"1.232283631","rc":[{"batb":[[0,2.48,4],[1,2.46,27.95],[2,1.45,57.07]],"ltp":2.46,"tv":164.7,"id":349}]}]}
{"op":"mcm","clk":"11937581723","pt":1724686446852,"mc":[{"id":"1.232283631","rc":[{"batb":[[0,2.46,27.95],[1,1.45,57.07],[2,1.1,25000]],"ltp":2.46,"tv":164.7,"id":349}]}]}
{"op":"mcm","clk":"11937583217","pt":1724686455655,"mc":[{"id":"1.232283631","rc":[{"batb":[[0,2.48,4],[1,2.46,27.95],[2,1.45,57.07]],"ltp":2.46,"tv":164.7,"id":349}]}]}
{"op":"mcm","clk":"11937583615","pt":1724686457979,"mc":[{"id":"1.232283631","rc":[{"batb":[[0,2.46,27.95],[1,1.45,57.07],[2,1.1,25000]],"ltp":2.46,"tv":164.7,"id":349}]}]}
{"op":"mcm","clk":"11937585009","pt":1724686465988,"mc":[{"id":"1.232283631","rc":[{"batb":[[0,2.48,4],[1,2.46,27.95],[2,1.45,57.07]],"ltp":2.46,"tv":164.7,"id":349}]}]}
{"op":"mcm","clk":"11937585413","pt":1724686468253,"mc":[{"id":"1.232283631","rc":[{"batb":[[0,2.46,27.95],[1,1.45,57.07],[2,1.1,25000]],"ltp":2.46,"tv":164.7,"id":349}]}]}
{"op":"mcm","clk":"11937586074","pt":1724686472179,"mc":[{"id":"1.232283631","rc":[{"batb":[[0,2.48,4],[1,2.46,27.95],[2,1.45,57.07]],"ltp":2.46,"tv":164.7,"id":349}]}]}
{"op":"mcm","clk":"11937586500","pt":1724686474594,"mc":[{"id":"1.232283631","rc":[{"batb":[[0,2.46,27.95],[1,1.45,57.07],[2,1.1,25000]],"ltp":2.46,"tv":164.7,"id":349}]}]}
{"op":"mcm","clk":"11937587603","pt":1724686480292,"mc":[{"id":"1.232283631","rc":[{"batb":[[0,2.48,4],[1,2.46,27.95],[2,1.45,57.07]],"ltp":2.46,"tv":164.7,"id":349}]}]}
{"op":"mcm","clk":"11937588010","pt":1724686482570,"mc":[{"id":"1.232283631","rc":[{"batb":[[0,2.46,27.95],[1,1.45,57.07],[2,1.1,25000]],"ltp":2.46,"tv":164.7,"id":349}]}]}
{"op":"mcm","clk":"11937588587","pt":1724686485676,"mc":[{"id":"1.232283631","rc":[{"batb":[[0,2.48,4],[1,2.46,27.95],[2,1.45,57.07]],"ltp":2.46,"tv":164.7,"id":349}]}]}
{"op":"mcm","clk":"11937589049","pt":1724686488191,"mc":[{"id":"1.232283631","rc":[{"batb":[[0,2.46,27.95],[1,1.45,57.07],[2,1.1,25000]],"ltp":2.46,"tv":164.7,"id":349}]}]}
{"op":"mcm","clk":"11937589747","pt":1724686492178,"mc":[{"id":"1.232283631","rc":[{"batb":[[0,2.48,4],[1,2.46,27.95],[2,1.45,57.07]],"ltp":2.46,"tv":164.7,"id":349}]}]}
{"op":"mcm","clk":"11937590169","pt":1724686494480,"mc":[{"id":"1.232283631","rc":[{"batb":[[0,2.46,27.95],[1,1.45,57.07],[2,1.1,25000]],"ltp":2.46,"tv":164.7,"id":349}]}]}
{"op":"mcm","clk":"11937590628","pt":1724686496720,"mc":[{"id":"1.232283631","rc":[{"batb":[[0,2.48,4],[1,2.46,27.95],[2,1.45,57.07]],"ltp":2.46,"tv":164.7,"id":349}]}]}
{"op":"mcm","clk":"11937591024","pt":1724686498917,"mc":[{"id":"1.232283631","rc":[{"batb":[[0,2.46,27.95],[1,1.45,57.07],[2,1.1,25000]],"ltp":2.46,"tv":164.7,"id":349}]}]}
{"op":"mcm","clk":"11937591532","pt":1724686501694,"mc":[{"id":"1.232283631","rc":[{"batb":[[0,2.48,4],[1,2.46,27.95],[2,1.45,57.07]],"ltp":2.46,"tv":164.7,"id":349}]}]}
{"op":"mcm","clk":"11937591940","pt":1724686504121,"mc":[{"id":"1.232283631","rc":[{"batb":[[0,2.46,27.95],[1,1.45,57.07],[2,1.1,25000]],"ltp":2.46,"tv":164.7,"id":349}]}]}
{"op":"mcm","clk":"11937592404","pt":1724686506697,"mc":[{"id":"1.232283631","rc":[{"batb":[[0,2.48,4],[1,2.46,27.95],[2,1.45,57.07]],"ltp":2.46,"tv":164.7,"id":349}]}]}
{"op":"mcm","clk":"11937592821","pt":1724686509121,"mc":[{"id":"1.232283631","rc":[{"batb":[[0,2.46,27.95],[1,1.45,57.07],[2,1.1,25000]],"ltp":2.46,"tv":164.7,"id":349}]}]}
{"op":"mcm","clk":"11937593310","pt":1724686511821,"mc":[{"id":"1.232283631","rc":[{"batb":[[0,2.48,4],[1,2.46,27.95],[2,1.45,57.07]],"ltp":2.46,"tv":164.7,"id":349}]}]}
{"op":"mcm","clk":"11937593735","pt":1724686514230,"mc":[{"id":"1.232283631","rc":[{"batb":[[0,2.46,27.95],[1,1.45,57.07],[2,1.1,25000]],"ltp":2.46,"tv":164.7,"id":349}]}]}
{"op":"mcm","clk":"11937594432","pt":1724686518020,"mc":[{"id":"1.232283631","rc":[{"batb":[[0,2.48,4],[1,2.46,27.95],[2,1.45,57.07]],"ltp":2.46,"tv":164.7,"id":349}]}]}
{"op":"mcm","clk":"11937594889","pt":1724686520403,"mc":[{"id":"1.232283631","rc":[{"batb":[[0,2.46,27.95],[1,1.45,57.07],[2,1.1,25000]],"ltp":2.46,"tv":164.7,"id":349}]}]}
