{"op":"mcm","clk":"11833142888","pt":1723108868530,"mc":[{"id":"1.231582255","marketDefinition":{"bspMarket":false,"turnInPlayEnabled":true,"persistenceEnabled":true,"marketBaseRate":5.0,"eventId":"33477755","eventTypeId":"4","numberOfWinners":1,"bettingType":"ODDS","marketType":"MATCH_ODDS","marketTime":"2024-08-11T10:00:00.000Z","suspendTime":"2024-08-11T10:00:00.000Z","bspReconciled":false,"complete":true,"inPlay":false,"crossMatching":false,"runnersVoidable":false,"numberOfActiveRunners":2,"betDelay":0,"status":"OPEN","runners":[{"status":"ACTIVE","sortPriority":1,"id":31379,"name":"Sussex"},{"status":"ACTIVE","sortPriority":2,"id":424676,"name":"Surrey"}],"regulators":["MR_INT"],"countryCode":"GB","discountAllowed":false,"timezone":"GMT","openDate":"2024-08-11T10:00:00.000Z","version":6061697196,"name":"Match Odds","eventName":"Sussex v Surrey"},"rc":[{"batb":[[0,1.01,20]],"ltp":0.0,"tv":0.0,"id":31379},{"batb":[[0,1.01,20]],"ltp":0.0,"tv":0.0,"id":424676}]}]}
{"op":"mcm","clk":"11833142894","pt":1723108868545,"mc":[{"id":"1.231582255","marketDefinition":{"bspMarket":false,"turnInPlayEnabled":true,"persistenceEnabled":true,"marketBaseRate":5.0,"eventId":"33477755","eventTypeId":"4","numberOfWinners":1,"bettingType":"ODDS","marketType":"MATCH_ODDS","marketTime":"2024-08-11T10:00:00.000Z","suspendTime":"2024-08-11T10:00:00.000Z","bspReconciled":false,"complete":true,"inPlay":false,"crossMatching":false,"runnersVoidable":false,"numberOfActiveRunners":2,"betDelay":0,"status":"OPEN","runners":[{"status":"ACTIVE","sortPriority":1,"id":31379,"name":"Sussex"},{"status":"ACTIVE","sortPriority":2,"id":424676,"name":"Surrey"}],"regulators":["MR_INT"],"countryCode":"GB","discountAllowed":true,"timezone":"GMT","openDate":"2024-08-11T10:00:00.000Z","version":6061697196,"name":"Match Odds","eventName":"Sussex v Surrey"}}]}
{"op":"mcm","clk":"11833142960","pt":1723108869693,"mc":[{"id":"1.231582255","rc":[{"batb":[[0,1.03,200],[1,1.02,200],[2,1.01,220]],"ltp":0.0,"tv":0.0,"id":31379},{"batb":[[0,1.03,200],[1,1.02,200],[2,1.01,220]],"ltp":0.0,"tv":0.0,"id":424676}]}]}
{"op":"mcm","clk":"11833438015","pt":1723114190768,"mc":[{"id":"1.231582255","rc":[{"batb":[[2,1.01,227.89]],"ltp":0.0,"tv":0.0,"id":31379},{"batb":[[2,1.01,227.89]],"ltp":0.0,"tv":0.0,"id":424676}]}]}
{"op":"mcm","clk":"11833438907","pt":1723114206409,"mc":[{"id":"1.231582255","rc":[{"batb":[[1,1.02,207.89]],"ltp":0.0,"tv":0.0,"id":31379},{"batb":[[1,1.02,207.89]],"ltp":0.0,"tv":0.0,"id":424676}]}]}
{"op":"mcm","clk":"11833439755","pt":1723114220928,"mc":[{"id":"1.231582255","rc":[{"batb":[[1,1.02,247.34]],"ltp":0.0,"tv":0.0,"id":31379},{"batb":[[1,1.02,247.34]],"ltp":0.0,"tv":0.0,"id":424676}]}]}
{"op":"mcm","clk":"11833441650","pt":1723114252923,"mc":[{"id":"1.231582255","rc":[{"batb":[[0,1.03,207.89]],"ltp":0.0,"tv":0.0,"id":31379},{"batb":[[0,1.03,207.89]],"ltp":0.0,"tv":0.0,"id":424676}]}]}
{"op":"mcm","clk":"11833442596","pt":1723114270140,"mc":[{"id":"1.231582255","rc":[{"batb":[[0,1.04,7.89],[1,1.03,207.89],[2,1.02,247.34]],"ltp":0.0,"tv":0.0,"id":31379},{"batb":[[0,1.04,7.89],[1,1.03,207.89],[2,1.02,247.34]],"ltp":0.0,"tv":0.0,"id":424676}]}]}
{"op":"mcm","clk":"11833443293","pt":1723114285078,"mc":[{"id":"1.231582255","rc":[{"batb":[[0,1.05,7.89],[1,1.04,7.89],[2,1.03,207.89]],"ltp":0.0,"tv":0.0,"id":31379},{"batb":[[0,1.05,7.89],[1,1.04,7.89],[2,1.03,207.89]],"ltp":0.0,"tv":0.0,"id":424676}]}]}
{"op":"mcm","clk":"11833443990","pt":1723114299308,"mc":[{"id":"1.231582255","rc":[{"batb":[[0,1.06,7.89],[1,1.05,7.89],[2,1.04,7.89]],"ltp":0.0,"tv":0.0,"id":31379},{"batb":[[0,1.06,7.89],[1,1.05,7.89],[2,1.04,7.89]],"ltp":0.0,"tv":0.0,"id":424676}]}]}
{"op":"mcm","clk":"11833445507","pt":1723114328528,"mc":[{"id":"1.231582255","rc":[{"batb":[[0,1.07,7.89],[1,1.06,7.89],[2,1.05,7.89]],"ltp":0.0,"tv":0.0,"id":31379},{"batb":[[0,1.07,7.89],[1,1.06,7.89],[2,1.05,7.89]],"ltp":0.0,"tv":0.0,"id":424676}]}]}
{"op":"mcm","clk":"11833446200","pt":1723114343852,"mc":[{"id":"1.231582255","rc":[{"batb":[[0,1.08,7.89],[1,1.07,7.89],[2,1.06,7.89]],"ltp":0.0,"tv":0.0,"id":31379},{"batb":[[0,1.08,7.89],[1,1.07,7.89],[2,1.06,7.89]],"ltp":0.0,"tv":0.0,"id":424676}]}]}
{"op":"mcm","clk":"11833528295","pt":1723115575130,"mc":[{"id":"1.231582255","rc":[{"batb":[[0,1.08,7.88],[1,1.07,7.88],[2,1.06,7.88]],"ltp":0.0,"tv":0.0,"id":31379},{"batb":[[0,1.08,7.88],[1,1.07,7.88],[2,1.06,7.88]],"ltp":0.0,"tv":0.0,"id":424676}]}]}
{"op":"mcm","clk":"11833544998","pt":1723115827172,"mc":[{"id":"1.231582255","marketDefinition":{"bspMarket":false,"turnInPlayEnabled":true,"persistenceEnabled":true,"marketBaseRate":5.0,"eventId":"33477755","eventTypeId":"4","numberOfWinners":1,"bettingType":"ODDS","marketType":"MATCH_ODDS","marketTime":"2024-08-11T10:00:00.000Z","suspendTime":"2024-08-11T10:00:00.000Z","bspReconciled":false,"complete":true,"inPlay":false,"crossMatching":true,"runnersVoidable":false,"numberOfActiveRunners":2,"betDelay":0,"status":"OPEN","runners":[{"status":"ACTIVE","sortPriority":1,"id":31379,"name":"Sussex"},{"status":"ACTIVE","sortPriority":2,"id":424676,"name":"Surrey"}],"regulators":["MR_INT"],"countryCode":"GB","discountAllowed":true,"timezone":"GMT","openDate":"2024-08-11T10:00:00.000Z","version":6061697196,"name":"Match Odds","eventName":"Sussex v Surrey"}}]}
{"op":"mcm","clk":"11833845917","pt":1723120975151,"mc":[{"id":"1.231582255","rc":[{"batb":[[0,1.08,7.88],[1,1.07,7.88],[2,1.06,7.88]],"ltp":0.0,"tv":0.0,"id":31379},{"batb":[[0,1.08,7.88],[1,1.07,7.88],[2,1.06,7.88]],"ltp":0.0,"tv":0.0,"id":424676}]}]}
{"op":"mcm","clk":"11834135118","pt":1723126375162,"mc":[{"id":"1.231582255","rc":[{"batb":[[0,1.08,7.87],[1,1.07,7.87],[2,1.06,7.87]],"ltp":0.0,"tv":0.0,"id":31379},{"batb":[[0,1.08,7.87],[1,1.07,7.87],[2,1.06,7.87]],"ltp":0.0,"tv":0.0,"id":424676}]}]}
{"op":"mcm","clk":"11834342121","pt":1723129859692,"mc":[{"id":"1.231582255","rc":[{"batb":[[0,1.25,100],[1,1.08,7.86],[2,1.07,7.86]],"ltp":0.0,"tv":0.0,"id":31379},{"batb":[[0,1.25,100],[1,1.08,7.86],[2,1.07,7.86]],"ltp":0.0,"tv":0.0,"id":424676}]}]}
{"op":"mcm","clk":"11835137458","pt":1723137175161,"mc":[{"id":"1.231582255","rc":[{"batb":[[1,1.08,7.85],[2,1.07,7.85]],"ltp":0.0,"tv":0.0,"id":31379},{"batb":[[1,1.08,7.85],[2,1.07,7.85]],"ltp":0.0,"tv":0.0,"id":424676}]}]}
{"op":"mcm","clk":"11836035590","pt":1723142575215,"mc":[{"id":"1.231582255","rc":[{"batb":[[1,1.08,7.85],[2,1.07,7.85]],"ltp":0.0,"tv":0.0,"id":31379},{"batb":[[1,1.08,7.85],[2,1.07,7.85]],"ltp":0.0,"tv":0.0,"id":424676}]}]}
{"op":"mcm","clk":"11836849993","pt":1723151765720,"mc":[{"id":"1.231582255","rc":[{"batb":[[1,1.08,7.84],[2,1.07,7.84]],"ltp":0.0,"tv":0.0,"id":31379},{"batb":[[1,1.08,7.84],[2,1.07,7.84]],"ltp":0.0,"tv":0.0,"id":424676}]}]}
{"op":"mcm","clk":"11837125212","pt":1723158775153,"mc":[{"id":"1.231582255","rc":[{"batb":[[1,1.08,7.85],[2,1.07,7.85]],"ltp":0.0,"tv":0.0,"id":31379},{"batb":[[1,1.08,7.85],[2,1.07,7.85]],"ltp":0.0,"tv":0.0,"id":424676}]}]}
{"op":"mcm","clk":"11837359238","pt":1723164175161,"mc":[{"id":"1.231582255","rc":[{"batb":[[1,1.08,7.84],[2,1.07,7.84]],"ltp":0.0,"tv":0.0,"id":31379},{"batb":[[1,1.08,7.84],[2,1.07,7.84]],"ltp":0.0,"tv":0.0,"id":424676}]}]}
{"op":"mcm","clk":"11837583773","pt":1723169575176,"mc":[{"id":"1.231582255","rc":[{"batb":[[1,1.08,7.84],[2,1.07,7.84]],"ltp":0.0,"tv":0.0,"id":31379},{"batb":[[1,1.08,7.84],[2,1.07,7.84]],"ltp":0.0,"tv":0.0,"id":424676}]}]}
{"op":"mcm","clk":"11837805808","pt":1723174975193,"mc":[{"id":"1.231582255","rc":[{"batb":[[1,1.08,7.84],[2,1.07,7.84]],"ltp":0.0,"tv":0.0,"id":31379},{"batb":[[1,1.08,7.84],[2,1.07,7.84]],"ltp":0.0,"tv":0.0,"id":424676}]}]}
{"op":"mcm","clk":"11838036850","pt":1723180375191,"mc":[{"id":"1.231582255","rc":[{"batb":[[1,1.08,7.84],[2,1.07,7.84]],"ltp":0.0,"tv":0.0,"id":31379},{"batb":[[1,1.08,7.84],[2,1.07,7.84]],"ltp":0.0,"tv":0.0,"id":424676}]}]}
{"op":"mcm","clk":"11838271897","pt":1723185775238,"mc":[{"id":"1.231582255","rc":[{"batb":[[1,1.08,7.84],[2,1.07,7.84]],"ltp":0.0,"tv":0.0,"id":31379},{"batb":[[1,1.08,7.84],[2,1.07,7.84]],"ltp":0.0,"tv":0.0,"id":424676}]}]}
{"op":"mcm","clk":"11838479488","pt":1723189566757,"mc":[{"id":"1.231582255","rc":[{"batb":[[1,1.08,7.83],[2,1.07,7.83]],"batl":[[0,1000,0.02]],"ltp":0.0,"tv":0.0,"id":31379},{"batb":[[1,1.08,7.83],[2,1.07,7.83]],"batl":[[0,1000,0.02]],"ltp":0.0,"tv":0.0,"id":424676}]}]}
{"op":"mcm","clk":"11838577617","pt":1723191175229,"mc":[{"id":"1.231582255","rc":[{"batb":[[1,1.08,7.84],[2,1.07,7.84]],"ltp":0.0,"tv":0.0,"id":31379},{"batb":[[1,1.08,7.84],[2,1.07,7.84]],"ltp":0.0,"tv":0.0,"id":424676}]}]}
{"op":"mcm","clk":"11838864819","pt":1723196575234,"mc":[{"id":"1.231582255","rc":[{"batb":[[1,1.08,7.83],[2,1.07,7.83]],"ltp":0.0,"tv":0.0,"id":31379},{"batb":[[1,1.08,7.83],[2,1.07,7.83]],"ltp":0.0,"tv":0.0,"id":424676}]}]}
{"op":"mcm","clk":"11839231197","pt":1723201975231,"mc":[{"id":"1.231582255","rc":[{"batb":[[1,1.08,7.85],[2,1.07,7.85]],"ltp":0.0,"tv":0.0,"id":31379},{"batb":[[1,1.08,7.85],[2,1.07,7.85]],"ltp":0.0,"tv":0.0,"id":424676}]}]}
{"op":"mcm","clk":"11839689292","pt":1723207375276,"mc":[{"id":"1.231582255","rc":[{"batb":[[1,1.08,7.85],[2,1.07,7.85]],"ltp":0.0,"tv":0.0,"id":31379},{"batb":[[1,1.08,7.85],[2,1.07,7.85]],"ltp":0.0,"tv":0.0,"id":424676}]}]}
{"op":"mcm","clk":"11840173705","pt":1723212775293,"mc":[{"id":"1.231582255","rc":[{"batb":[[1,1.08,7.85],[2,1.07,7.85]],"ltp":0.0,"tv":0.0,"id":31379},{"batb":[[1,1.08,7.85],[2,1.07,7.85]],"ltp":0.0,"tv":0.0,"id":424676}]}]}
{"op":"mcm","clk":"11840729751","pt":1723218175294,"mc":[{"id":"1.231582255","rc":[{"batb":[[1,1.08,7.84],[2,1.07,7.84]],"ltp":0.0,"tv":0.0,"id":31379},{"batb":[[1,1.08,7.84],[2,1.07,7.84]],"ltp":0.0,"tv":0.0,"id":424676}]}]}
{"op":"mcm","clk":"11840938090","pt":1723219990386,"mc":[{"id":"1.231582255","rc":[{"batb":[[0,1.25,100.96]],"ltp":0.0,"tv":0.0,"id":424676}]}]}
{"op":"mcm","clk":"11840939283","pt":1723219998926,"mc":[{"id":"1.231582255","rc":[{"batb":[[0,1.26,3.14],[1,1.25,100],[2,1.08,7.84]],"ltp":0.0,"tv":0.0,"id":424676}]}]}
{"op":"mcm","clk":"11840940610","pt":1723220009296,"mc":[{"id":"1.231582255","rc":[{"batb":[[0,1.26,4.1]],"ltp":0.0,"tv":0.0,"id":424676}]}]}
{"op":"mcm","clk":"11840942460","pt":1723220023709,"mc":[{"id":"1.231582255","rc":[{"batb":[[0,1.26,3.6],[1,1.25,100],[2,1.08,7.84]],"ltp":0.0,"tv":0.0,"id":31379}]}]}
{"op":"mcm","clk":"11840943914","pt":1723220034781,"mc":[{"id":"1.231582255","rc":[{"batb":[[0,1.26,4.56]],"ltp":0.0,"tv":0.0,"id":31379}]}]}
{"op":"mcm","clk":"11840944760","pt":1723220041468,"mc":[{"id":"1.231582255","rc":[{"batb":[[0,1.25,100.96],[1,1.08,7.84],[2,1.07,7.84]],"ltp":0.0,"tv":0.0,"id":31379}]}]}
{"op":"mcm","clk":"11840944771","pt":1723220041572,"mc":[{"id":"1.231582255","rc":[{"batb":[[0,1.28,4.56],[1,1.25,100],[2,1.08,7.84]],"ltp":0.0,"tv":0.0,"id":31379}]}]}
{"op":"mcm","clk":"11841163615","pt":1723221507272,"mc":[{"id":"1.231582255","rc":[{"batb":[[1,1.08,7.84],[2,1.07,7.84]],"ltp":0.0,"tv":0.0,"id":31379},{"batb":[[1,1.08,7.84],[2,1.07,7.84]],"ltp":0.0,"tv":0.0,"id":424676}]}]}
{"op":"mcm","clk":"11841172317","pt":1723221562253,"mc":[{"id":"1.231582255","rc":[{"batb":[[0,1.48,52.08],[1,1.43,58.14],[2,1.38,65.79]],"ltp":0.0,"tv":0.0,"id":31379},{"batb":[[0,1.48,52.08],[1,1.43,58.14],[2,1.38,65.79]],"ltp":0.0,"tv":0.0,"id":424676}]}]}
{"op":"mcm","clk":"11841173076","pt":1723221566954,"mc":[{"id":"1.231582255","rc":[{"batb":[[0,1.43,58.14],[1,1.38,65.79],[2,1.33,75.76]],"ltp":0.0,"tv":0.0,"id":424676}]}]}
{"op":"mcm","clk":"11841173254","pt":1723221568056,"mc":[{"id":"1.231582255","rc":[{"batb":[[0,1.38,65.79],[1,1.33,75.76],[2,1.28,90.25]],"ltp":0.0,"tv":0.0,"id":424676}]}]}
{"op":"mcm","clk":"11841173613","pt":1723221570272,"mc":[{"id":"1.231582255","rc":[{"batb":[[0,1.33,75.76],[1,1.28,90.25],[2,1.26,3.14]],"ltp":0.0,"tv":0.0,"id":424676}]}]}
{"op":"mcm","clk":"11841177711","pt":1723221595312,"mc":[{"id":"1.231582255","rc":[{"batb":[[2,1.33,76.72]],"ltp":0.0,"tv":0.0,"id":31379}]}]}
{"op":"mcm","clk":"11841178402","pt":1723221599807,"mc":[{"id":"1.231582255","rc":[{"batb":[[0,1.43,58.14],[1,1.33,76.72],[2,1.28,3.6]],"ltp":0.0,"tv":0.0,"id":31379}]}]}
{"op":"mcm","clk":"11841178817","pt":1723221602643,"mc":[{"id":"1.231582255","rc":[{"batb":[[0,1.53,47.17],[1,1.43,58.14],[2,1.33,76.72]],"ltp":0.0,"tv":0.0,"id":31379}]}]}
{"op":"mcm","clk":"11841179061","pt":1723221604244,"mc":[{"id":"1.231582255","rc":[{"batb":[[0,1.63,39.68],[1,1.53,47.17],[2,1.43,58.14]],"ltp":0.0,"tv":0.0,"id":31379}]}]}
{"op":"mcm","clk":"11841179333","pt":1723221606051,"mc":[{"id":"1.231582255","rc":[{"batb":[[0,1.73,34.25],[1,1.63,39.68],[2,1.53,47.17]],"ltp":0.0,"tv":0.0,"id":31379}]}]}
{"op":"mcm","clk":"11841179700","pt":1723221608339,"mc":[{"id":"1.231582255","rc":[{"batb":[[0,1.83,30.12],[1,1.73,34.25],[2,1.63,39.68]],"ltp":0.0,"tv":0.0,"id":31379}]}]}
{"op":"mcm","clk":"11841184229","pt":1723221637387,"mc":[{"id":"1.231582255","rc":[{"batb":[[1,1.28,89.29]],"ltp":0.0,"tv":0.0,"id":424676}]}]}
{"op":"mcm","clk":"11841184257","pt":1723221637566,"mc":[{"id":"1.231582255","rc":[{"batb":[[0,1.47,8.24],[1,1.33,75.76],[2,1.28,89.29]],"ltp":0.0,"tv":0.0,"id":424676}]}]}
{"op":"mcm","clk":"11841186242","pt":1723221650474,"mc":[{"id":"1.231582255","rc":[{"batb":[[0,1.33,75.76],[1,1.28,89.29],[2,1.26,3.14]],"ltp":0.0,"tv":0.0,"id":424676}]}]}
{"op":"mcm","clk":"11841186280","pt":1723221650702,"mc":[{"id":"1.231582255","rc":[{"batb":[[0,1.42,7.88],[1,1.33,75.76],[2,1.28,89.29]],"ltp":0.0,"tv":0.0,"id":424676}]}]}
{"op":"mcm","clk":"11841230198","pt":1723221947382,"mc":[{"id":"1.231582255","rc":[{"batb":[[0,1.33,75.76],[1,1.28,89.29],[2,1.23,108.7]],"ltp":0.0,"tv":0.0,"id":424676}]}]}
{"op":"mcm","clk":"11841306738","pt":1723222457390,"mc":[{"id":"1.231582255","rc":[{"batb":[[0,1.84,6.53],[1,1.83,30.12],[2,1.73,34.25]],"ltp":0.0,"tv":0.0,"id":31379}]}]}
{"op":"mcm","clk":"11841306780","pt":1723222457660,"mc":[{"id":"1.231582255","rc":[{"batb":[[0,1.34,7.65],[1,1.33,75.76],[2,1.28,89.29]],"ltp":0.0,"tv":0.0,"id":424676}]}]}
{"op":"mcm","clk":"11841507185","pt":1723223575378,"mc":[{"id":"1.231582255","rc":[{"batb":[[0,1.84,6.53]],"ltp":0.0,"tv":0.0,"id":31379},{"batb":[[0,1.34,7.65]],"ltp":0.0,"tv":0.0,"id":424676}]}]}
{"op":"mcm","clk":"11841736536","pt":1723224821304,"mc":[{"id":"1.231582255","rc":[{"batb":[[0,2.28,32.64],[1,1.84,6.53],[2,1.83,30.12]],"ltp":0.0,"tv":0.0,"id":31379},{"batb":[[0,1.72,58.04],[1,1.34,7.65],[2,1.33,75.76]],"ltp":0.0,"tv":0.0,"id":424676}]}]}
{"op":"mcm","clk":"11841962396","pt":1723226039491,"mc":[{"id":"1.231582255","rc":[{"batb":[[1,1.83,30.12],[2,1.73,34.25]],"ltp":0.0,"tv":0.0,"id":31379},{"batb":[[1,1.33,75.76],[2,1.28,89.29]],"ltp":0.0,"tv":0.0,"id":424676}]}]}
{"op":"mcm","clk":"11846331475","pt":1723277747100,"mc":[{"id":"1.231582255","rc":[{"trd":[[2.4,1]],"ltp":2.4,"tv":1.0,"id":31379},{"trd":[[1.72,1.4]],"batb":[[0,1.72,56.64]],"ltp":1.72,"tv":1.4,"id":424676}],"tv":2.4}]}
{"op":"mcm","clk":"11846331563","pt":1723277748032,"mc":[{"id":"1.231582255","rc":[{"batb":[[0,1.72,58.04]],"ltp":1.72,"tv":1.4,"id":424676}]}]}
{"op":"mcm","clk":"11846418812","pt":1723278734713,"mc":[{"id":"1.231582255","rc":[{"batb":[[1,1.08,7.85],[2,1.07,7.85]],"ltp":2.4,"tv":1.0,"id":31379},{"batb":[[1,1.08,7.85],[2,1.07,7.85]],"ltp":1.72,"tv":1.4,"id":424676}]}]}
{"op":"mcm","clk":"11846442283","pt":1723278978967,"mc":[{"id":"1.231582255","rc":[{"batb":[[1,1.25,1200],[2,1.08,7.85]],"ltp":2.4,"tv":1.0,"id":31379},{"batb":[[1,1.25,1200],[2,1.08,7.85]],"ltp":1.72,"tv":1.4,"id":424676}]}]}
{"op":"mcm","clk":"11846449838","pt":1723279056139,"mc":[{"id":"1.231582255","rc":[{"batb":[[1,1.08,7.85],[2,1.07,7.85]],"ltp":2.4,"tv":1.0,"id":31379},{"batb":[[1,1.08,7.85],[2,1.07,7.85]],"ltp":1.72,"tv":1.4,"id":424676}]}]}
{"op":"mcm","clk":"11846450193","pt":1723279059854,"mc":[{"id":"1.231582255","rc":[{"batb":[[1,1.3,1000],[2,1.08,7.85]],"ltp":2.4,"tv":1.0,"id":31379},{"batb":[[1,1.3,1000],[2,1.08,7.85]],"ltp":1.72,"tv":1.4,"id":424676}]}]}
{"op":"mcm","clk":"11849802090","pt":1723299707856,"mc":[{"id":"1.231582255","rc":[{"batb":[[0,2.28,30.5]],"ltp":2.4,"tv":1.0,"id":31379},{"batb":[[0,1.72,54.22]],"ltp":1.72,"tv":1.4,"id":424676}]}]}
{"op":"mcm","clk":"11851081784","pt":1723304626715,"mc":[{"id":"1.231582255","rc":[{"batl":[[0,1.75,100],[1,1000,0.02]],"ltp":1.72,"tv":1.4,"id":424676}]}]}
{"op":"mcm","clk":"11851082524","pt":1723304629899,"mc":[{"id":"1.231582255","rc":[{"batl":[[1,1.76,200],[2,1000,0.02]],"ltp":1.72,"tv":1.4,"id":424676}]}]}
{"op":"mcm","clk":"11851083454","pt":1723304633888,"mc":[{"id":"1.231582255","rc":[{"batl":[[2,1.77,300]],"ltp":1.72,"tv":1.4,"id":424676}]}]}
{"op":"mcm","clk":"11851225923","pt":1723305386065,"mc":[{"id":"1.231582255","rc":[{"batl":[[0,1.74,4.91],[1,1.75,100],[2,1.76,200]],"ltp":1.72,"tv":1.4,"id":424676}]}]}
{"op":"mcm","clk":"11852822243","pt":1723313862935,"mc":[{"id":"1.231582255","rc":[{"batl":[[0,2.8,5],[1,1000,0.02]],"ltp":2.4,"tv":1.0,"id":31379}]}]}
{"op":"mcm","clk":"11853669673","pt":1723318828042,"mc":[{"id":"1.231582255","rc":[{"trd":[[2.34,2]],"ltp":2.34,"tv":3.0,"id":31379},{"trd":[[1.74,2.69]],"batl":[[0,1.74,2.22]],"ltp":1.74,"tv":4.09,"id":424676}],"tv":7.09}]}
{"op":"mcm","clk":"11853844254","pt":1723320138436,"mc":[{"id":"1.231582255","rc":[{"batb":[[1,1.61,4.56],[2,1.3,1000]],"ltp":1.74,"tv":4.09,"id":424676}]}]}
{"op":"mcm","clk":"11853845950","pt":1723320150432,"mc":[{"id":"1.231582255","rc":[{"batb":[[2,1.56,4.56]],"ltp":1.74,"tv":4.09,"id":424676}]}]}
{"op":"mcm","clk":"11854289445","pt":1723323013435,"mc":[{"id":"1.231582255","rc":[{"trd":[[2.34,3.65]],"batl":[[0,2.34,5.35],[1,2.8,5],[2,1000,0.02]],"ltp":2.34,"tv":4.65,"id":31379},{"trd":[[1.74,4.91]],"batb":[[0,1.73,4.94],[1,1.72,54.22],[2,1.61,4.56]],"batl":[[0,1.75,100],[1,1.76,200],[2,1.77,300]],"ltp":1.74,"tv":6.31,"id":424676}],"tv":10.96}]}
{"op":"mcm","clk":"11854470782","pt":1723325032707,"mc":[{"id":"1.231582255","rc":[{"trd":[[2.34,4.39]],"batl":[[0,2.34,4.61]],"ltp":2.34,"tv":5.39,"id":31379},{"trd":[[1.74,5.91]],"ltp":1.74,"tv":7.31,"id":424676}],"tv":12.7}]}
{"op":"mcm","clk":"11855434494","pt":1723338836250,"mc":[{"id":"1.231582255","rc":[{"trd":[[1.75,2]],"batl":[[0,1.75,99]],"ltp":1.75,"tv":9.31,"id":424676}],"tv":14.7}]}
{"op":"mcm","clk":"11855435059","pt":1723338844560,"mc":[{"id":"1.231582255","rc":[{"trd":[[1.75,4]],"batl":[[0,1.75,98]],"ltp":1.75,"tv":11.31,"id":424676}],"tv":16.7}]}
{"op":"mcm","clk":"11856045380","pt":1723348431237,"mc":[{"id":"1.231582255","rc":[{"batb":[[2,1.67,20]],"ltp":1.75,"tv":11.31,"id":424676}]}]}
{"op":"mcm","clk":"11856150601","pt":1723350477738,"mc":[{"id":"1.231582255","rc":[{"trd":[[2.32,0.09]],"ltp":2.32,"tv":5.48,"id":31379},{"trd":[[1.75,4.12]],"batl":[[0,1.75,97.88]],"ltp":1.75,"tv":11.43,"id":424676}],"tv":16.91}]}
{"op":"mcm","clk":"11856150942","pt":1723350483397,"mc":[{"id":"1.231582255","rc":[{"trd":[[2.34,4.57]],"batl":[[0,2.34,4.52]],"ltp":2.34,"tv":5.66,"id":31379}],"tv":17.09}]}
{"op":"mcm","clk":"11856183241","pt":1723351166061,"mc":[{"id":"1.231582255","rc":[{"trd":[[2.34,5.31]],"batl":[[0,2.34,3.78]],"ltp":2.34,"tv":6.4,"id":31379},{"trd":[[1.74,6.91]],"ltp":1.74,"tv":12.43,"id":424676}],"tv":18.83}]}
{"op":"mcm","clk":"11856604050","pt":1723359539554,"mc":[{"id":"1.231582255","rc":[{"batb":[[1,1.74,6.7],[2,1.3,1000]],"batl":[[2,3.1,3.61]],"ltp":2.34,"tv":6.4,"id":31379}]}]}
{"op":"mcm","clk":"11856604484","pt":1723359546846,"mc":[{"id":"1.231582255","rc":[{"batl":[[2,2.98,3.61]],"ltp":2.34,"tv":6.4,"id":31379}]}]}
{"op":"mcm","clk":"11856700647","pt":1723361019952,"mc":[{"id":"1.231582255","rc":[{"batb":[[1,1.3,1000],[2,1.08,7.85]],"batl":[[2,1000,0.02]],"ltp":2.34,"tv":6.4,"id":31379}]}]}
{"op":"mcm","clk":"11856700766","pt":1723361021964,"mc":[{"id":"1.231582255","rc":[{"batb":[[1,1.74,6.7],[2,1.3,1000]],"batl":[[2,3.1,3.61]],"ltp":2.34,"tv":6.4,"id":31379}]}]}
{"op":"mcm","clk":"11856701167","pt":1723361029259,"mc":[{"id":"1.231582255","rc":[{"batl":[[2,2.98,3.61]],"ltp":2.34,"tv":6.4,"id":31379}]}]}
{"op":"mcm","clk":"11856709308","pt":1723361185124,"mc":[{"id":"1.231582255","rc":[{"trd":[[2.34,9.03]],"batl":[[0,2.8,5.06],[1,2.98,3.61],[2,1000,0.02]],"ltp":2.34,"tv":10.12,"id":31379},{"trd":[[1.74,11.91]],"ltp":1.74,"tv":17.43,"id":424676}],"tv":27.55}]}
{"op":"mcm","clk":"11856731638","pt":1723361572929,"mc":[{"id":"1.231582255","rc":[{"batl":[[0,1.75,102.88]],"ltp":1.74,"tv":17.43,"id":424676}]}]}
{"op":"mcm","clk":"11856833216","pt":1723363201717,"mc":[{"id":"1.231582255","rc":[{"batb":[[0,2.3,13.85],[1,2.28,30.5],[2,1.74,6.7]],"ltp":2.34,"tv":10.12,"id":31379},{"batb":[[1,1.72,79.24]],"ltp":1.74,"tv":17.43,"id":424676}]}]}
{"op":"mcm","clk":"11856874330","pt":1723363746332,"mc":[{"id":"1.231582255","rc":[{"trd":[[1.75,9.12]],"batl":[[0,1.75,100.38]],"ltp":1.75,"tv":22.43,"id":424676}],"tv":32.55}]}
{"op":"mcm","clk":"11856876114","pt":1723363769458,"mc":[{"id":"1.231582255","rc":[{"trd":[[2.34,9.09]],"batl":[[0,2.8,5]],"ltp":2.34,"tv":10.18,"id":31379},{"trd":[[1.73,4.99],[1.74,12]],"batb":[[0,1.73,2.44]],"ltp":1.73,"tv":27.5,"id":424676}],"tv":37.68}]}
{"op":"mcm","clk":"11857037496","pt":1723365567335,"mc":[{"id":"1.231582255","rc":[{"batb":[[0,1.73,4.44]],"ltp":1.73,"tv":27.5,"id":424676}]}]}
{"op":"mcm","clk":"11857150799","pt":1723366741789,"mc":[{"id":"1.231582255","rc":[{"batb":[[2,1.3,1000]],"batl":[[1,1000,0.02],[2,1000,0]],"ltp":2.34,"tv":10.18,"id":31379}]}]}
{"op":"mcm","clk":"11857151024","pt":1723366743779,"mc":[{"id":"1.231582255","rc":[{"batb":[[2,1.74,6.7]],"batl":[[1,3.1,3.61],[2,1000,0.02]],"ltp":2.34,"tv":10.18,"id":31379}]}]}
{"op":"mcm","clk":"11857156851","pt":1723366802475,"mc":[{"id":"1.231582255","rc":[{"batb":[[1,2.28,5]],"ltp":2.34,"tv":10.18,"id":31379},{"batb":[[1,1.72,5]],"ltp":1.73,"tv":27.5,"id":424676}]}]}
{"op":"mcm","clk":"11857166110","pt":1723366884732,"mc":[{"id":"1.231582255","rc":[{"batl":[[0,2.34,50],[1,2.8,5],[2,3.1,3.61]],"ltp":2.34,"tv":10.18,"id":31379}]}]}
{"op":"mcm","clk":"11857166278","pt":1723366886456,"mc":[{"id":"1.231582255","rc":[{"batb":[[0,1.73,2]],"ltp":1.73,"tv":27.5,"id":424676}]}]}
{"op":"mcm","clk":"11857166323","pt":1723366886981,"mc":[{"id":"1.231582255","rc":[{"batb":[[0,1.74,2.44],[1,1.73,26.67],[2,1.72,5]],"ltp":1.73,"tv":27.5,"id":424676}]}]}
{"op":"mcm","clk":"11857166619","pt":1723366889746,"mc":[{"id":"1.231582255","rc":[{"trd":[[2.32,10.09]],"ltp":2.32,"tv":20.18,"id":31379},{"trd":[[1.75,22.38]],"batl":[[0,1.75,87.12]],"ltp":1.75,"tv":40.76,"id":424676}],"tv":60.94}]}
{"op":"mcm","clk":"11857167235","pt":1723366896028,"mc":[{"id":"1.231582255","rc":[{"trd":[[2.32,60.09]],"batl":[[0,2.8,5],[1,3.1,3.61],[2,1000,0.02]],"ltp":2.32,"tv":70.18,"id":31379},{"trd":[[1.75,88.67]],"batb":[[1,1.73,2]],"batl":[[0,1.75,20.83]],"ltp":1.75,"tv":107.05,"id":424676}],"tv":177.23}]}
{"op":"mcm","clk":"11857167295","pt":1723366896649,"mc":[{"id":"1.231582255","rc":[{"batb":[[0,2.32,14],[1,2.3,13.85],[2,2.28,5]],"ltp":2.32,"tv":70.18,"id":31379}]}]}
{"op":"mcm","clk":"11857167399","pt":1723366897650,"mc":[{"id":"1.231582255","rc":[{"batb":[[2,1.74,6.7]],"ltp":2.32,"tv":70.18,"id":31379},{"batb":[[0,1.73,4.45],[1,1.72,5],[2,1.67,20]],"ltp":1.75,"tv":107.05,"id":424676}]}]}
{"op":"mcm","clk":"11857167574","pt":1723366899061,"mc":[{"id":"1.231582255","rc":[{"batb":[[0,2.32,10]],"ltp":2.32,"tv":70.18,"id":31379}]}]}
{"op":"mcm","clk":"11857167692","pt":1723366900154,"mc":[{"id":"1.231582255","rc":[{"batb":[[0,2.3,13.85],[1,1.74,6.7],[2,1.3,1000]],"ltp":2.32,"tv":70.18,"id":31379}]}]}
{"op":"mcm","clk":"11857167955","pt":1723366902527,"mc":[{"id":"1.231582255","rc":[{"batb":[[1,2.28,5],[2,1.74,6.7]],"ltp":2.32,"tv":70.18,"id":31379}]}]}
{"op":"mcm","clk":"11857167992","pt":1723366902836,"mc":[{"id":"1.231582255","rc":[{"batb":[[0,2.32,14],[1,2.3,13.85],[2,2.28,5]],"ltp":2.32,"tv":70.18,"id":31379}]}]}
{"op":"mcm","clk":"11857168273","pt":1723366905380,"mc":[{"id":"1.231582255","rc":[{"batb":[[0,2.32,10]],"ltp":2.32,"tv":70.18,"id":31379}]}]}
{"op":"mcm","clk":"11857168364","pt":1723366906167,"mc":[{"id":"1.231582255","rc":[{"batb":[[0,2.3,13.85],[1,2.28,5],[2,1.74,6.7]],"ltp":2.32,"tv":70.18,"id":31379}]}]}
{"op":"mcm","clk":"11857171163","pt":1723366935700,"mc":[{"id":"1.231582255","rc":[{"batb":[[0,2.32,14],[1,2.3,13.85],[2,2.28,5]],"ltp":2.32,"tv":70.18,"id":31379}]}]}
{"op":"mcm","clk":"11857171405","pt":1723366937981,"mc":[{"id":"1.231582255","rc":[{"batb":[[0,2.32,10],[2,1.74,6.7]],"ltp":2.32,"tv":70.18,"id":31379}]}]}
{"op":"mcm","clk":"11857171518","pt":1723366939077,"mc":[{"id":"1.231582255","rc":[{"batb":[[0,2.3,13.85],[1,1.74,6.7],[2,1.3,1000]],"ltp":2.32,"tv":70.18,"id":31379}]}]}
{"op":"mcm","clk":"11857171902","pt":1723366942912,"mc":[{"id":"1.231582255","rc":[{"batb":[[0,2.32,14],[1,2.3,13.85],[2,2.28,5]],"ltp":2.32,"tv":70.18,"id":31379}]}]}
{"op":"mcm","clk":"11857172150","pt":1723366945214,"mc":[{"id":"1.231582255","rc":[{"batb":[[0,2.32,10]],"ltp":2.32,"tv":70.18,"id":31379}]}]}
{"op":"mcm","clk":"11857172244","pt":1723366946197,"mc":[{"id":"1.231582255","rc":[{"batb":[[0,2.3,13.85],[1,2.28,5],[2,1.74,6.7]],"ltp":2.32,"tv":70.18,"id":31379}]}]}
{"op":"mcm","clk":"11857172721","pt":1723366951213,"mc":[{"id":"1.231582255","rc":[{"batb":[[0,2.32,14],[1,2.3,13.85],[2,2.28,5]],"ltp":2.32,"tv":70.18,"id":31379}]}]}
{"op":"mcm","clk":"11857172944","pt":1723366953494,"mc":[{"id":"1.231582255","rc":[{"batb":[[0,2.32,10],[2,1.74,6.7]],"ltp":2.32,"tv":70.18,"id":31379},{"trd":[[1.73,6.99]],"batb":[[0,1.73,3.45]],"ltp":1.73,"tv":109.05,"id":424676}],"tv":179.23}]}
{"op":"mcm","clk":"11857173038","pt":1723366954484,"mc":[{"id":"1.231582255","rc":[{"batb":[[0,2.3,13.85],[1,1.74,6.7],[2,1.3,1000]],"ltp":2.32,"tv":70.18,"id":31379}]}]}
{"op":"mcm","clk":"11857173141","pt":1723366955524,"mc":[{"id":"1.231582255","rc":[{"batb":[[0,1.73,1],[2,1.68,2.52]],"ltp":1.73,"tv":109.05,"id":424676}]}]}
{"op":"mcm","clk":"11857173157","pt":1723366955682,"mc":[{"id":"1.231582255","rc":[{"batb":[[0,2.32,4],[1,2.3,13.85],[2,1.74,6.7]],"ltp":2.32,"tv":70.18,"id":31379}]}]}
{"op":"mcm","clk":"11857173437","pt":1723366958223,"mc":[{"id":"1.231582255","rc":[{"batb":[[0,2.34,10],[2,2.28,5]],"ltp":2.32,"tv":70.18,"id":31379}]}]}
{"op":"mcm","clk":"11857173519","pt":1723366959008,"mc":[{"id":"1.231582255","rc":[{"batb":[[1,2.32,13.64],[2,2.3,13.85]],"ltp":2.32,"tv":70.18,"id":31379}]}]}
{"op":"mcm","clk":"11857173780","pt":1723366961510,"mc":[{"id":"1.231582255","rc":[{"batb":[[0,2.32,13.64],[1,2.3,13.85],[2,2.28,5]],"ltp":2.32,"tv":70.18,"id":31379}]}]}
{"op":"mcm","clk":"11857173800","pt":1723366961716,"mc":[{"id":"1.231582255","rc":[{"batb":[[0,2.34,4],[1,2.32,13.64],[2,2.3,13.85]],"ltp":2.32,"tv":70.18,"id":31379}]}]}
{"op":"mcm","clk":"11857174049","pt":1723366964208,"mc":[{"id":"1.231582255","rc":[{"batb":[[0,2.34,10]],"ltp":2.32,"tv":70.18,"id":31379}]}]}
{"op":"mcm","clk":"11857174412","pt":1723366967621,"mc":[{"id":"1.231582255","rc":[{"batb":[[0,2.36,4]],"ltp":2.32,"tv":70.18,"id":31379}]}]}
{"op":"mcm","clk":"11857174657","pt":1723366970522,"mc":[{"id":"1.231582255","rc":[{"batb":[[0,2.3,13.85],[1,1.74,6.7],[2,1.3,1000]],"ltp":2.32,"tv":70.18,"id":31379}]}]}
{"op":"mcm","clk":"11857174687","pt":1723366970832,"mc":[{"id":"1.231582255","rc":[{"batb":[[0,2.34,10],[1,2.3,13.85],[2,1.74,6.7]],"ltp":2.32,"tv":70.18,"id":31379}]}]}
{"op":"mcm","clk":"11857174923","pt":1723366973010,"mc":[{"id":"1.231582255","rc":[{"batb":[[0,2.36,4],[1,2.34,10],[2,2.32,13.64]],"ltp":2.32,"tv":70.18,"id":31379}]}]}
{"op":"mcm","clk":"11857175052","pt":1723366974208,"mc":[{"id":"1.231582255","rc":[{"batb":[[1,2.32,13.64],[2,2.3,13.85]],"ltp":2.32,"tv":70.18,"id":31379}]}]}
{"op":"mcm","clk":"11857175189","pt":1723366975354,"mc":[{"id":"1.231582255","rc":[{"batb":[[0,2.32,13.64],[1,2.3,13.85],[2,2.28,5]],"ltp":2.32,"tv":70.18,"id":31379}]}]}
{"op":"mcm","clk":"11857175250","pt":1723366976028,"mc":[{"id":"1.231582255","rc":[{"batb":[[0,2.3,13.85],[1,2.28,5],[2,1.74,6.7]],"ltp":2.32,"tv":70.18,"id":31379}]}]}
{"op":"mcm","clk":"11857175675","pt":1723366980238,"mc":[{"id":"1.231582255","rc":[{"batb":[[0,2.32,14],[1,2.3,13.85],[2,2.28,5]],"ltp":2.32,"tv":70.18,"id":31379}]}]}
{"op":"mcm","clk":"11857175985","pt":1723366982671,"mc":[{"id":"1.231582255","rc":[{"batb":[[0,2.32,10]],"ltp":2.32,"tv":70.18,"id":31379}]}]}
{"op":"mcm","clk":"11857176159","pt":1723366984056,"mc":[{"id":"1.231582255","rc":[{"batb":[[0,2.3,13.85],[1,2.28,5],[2,1.74,6.7]],"ltp":2.32,"tv":70.18,"id":31379}]}]}
{"op":"mcm","clk":"11857176272","pt":1723366984958,"mc":[{"id":"1.231582255","rc":[{"batb":[[0,2.32,4],[1,2.3,13.85],[2,2.28,5]],"ltp":2.32,"tv":70.18,"id":31379}]}]}
{"op":"mcm","clk":"11857176592","pt":1723366987458,"mc":[{"id":"1.231582255","rc":[{"batb":[[0,2.3,13.85],[1,2.28,5],[2,1.74,6.7]],"ltp":2.32,"tv":70.18,"id":31379}]}]}
{"op":"mcm","clk":"11857176655","pt":1723366987931,"mc":[{"id":"1.231582255","rc":[{"batb":[[0,2.32,10],[1,2.3,13.85],[2,2.28,5]],"ltp":2.32,"tv":70.18,"id":31379}]}]}
{"op":"mcm","clk":"11857176890","pt":1723366990066,"mc":[{"id":"1.231582255","rc":[{"batb":[[0,2.34,4],[1,2.32,23.64],[2,2.3,13.85]],"ltp":2.32,"tv":70.18,"id":31379}]}]}
{"op":"mcm","clk":"11857177040","pt":1723366991471,"mc":[{"id":"1.231582255","rc":[{"batb":[[1,2.32,13.64]],"ltp":2.32,"tv":70.18,"id":31379}]}]}
{"op":"mcm","clk":"11857177145","pt":1723366992467,"mc":[{"id":"1.231582255","rc":[{"batb":[[0,2.32,13.64],[1,2.3,13.85],[2,2.28,5]],"ltp":2.32,"tv":70.18,"id":31379}]}]}
{"op":"mcm","clk":"11857177230","pt":1723366993041,"mc":[{"id":"1.231582255","rc":[{"batb":[[0,2.3,13.85],[1,1.74,6.7],[2,1.3,1000]],"ltp":2.32,"tv":70.18,"id":31379}]}]}
{"op":"mcm","clk":"11857177796","pt":1723366998076,"mc":[{"id":"1.231582255","rc":[{"batb":[[1,2.28,5],[2,1.74,6.7]],"ltp":2.32,"tv":70.18,"id":31379}]}]}
{"op":"mcm","clk":"11857177893","pt":1723366998965,"mc":[{"id":"1.231582255","rc":[{"batb":[[0,2.32,14],[1,2.3,13.85],[2,2.28,5]],"ltp":2.32,"tv":70.18,"id":31379}]}]}
{"op":"mcm","clk":"11857178215","pt":1723367001552,"mc":[{"id":"1.231582255","rc":[{"batb":[[0,2.32,10]],"ltp":2.32,"tv":70.18,"id":31379}]}]}
{"op":"mcm","clk":"11857178343","pt":1723367002545,"mc":[{"id":"1.231582255","rc":[{"batb":[[0,2.3,13.85],[1,2.28,5],[2,1.74,6.7]],"ltp":2.32,"tv":70.18,"id":31379}]}]}
{"op":"mcm","clk":"11857178590","pt":1723367004674,"mc":[{"id":"1.231582255","rc":[{"batb":[[0,2.34,10],[1,2.32,4],[2,2.3,13.85]],"ltp":2.32,"tv":70.18,"id":31379}]}]}
{"op":"mcm","clk":"11857178838","pt":1723367007160,"mc":[{"id":"1.231582255","rc":[{"batb":[[1,2.32,13.64]],"ltp":2.32,"tv":70.18,"id":31379}]}]}
{"op":"mcm","clk":"11857178943","pt":1723367008363,"mc":[{"id":"1.231582255","rc":[{"batb":[[0,2.32,13.64],[1,2.3,13.85],[2,1.74,6.7]],"ltp":2.32,"tv":70.18,"id":31379}]}]}
{"op":"mcm","clk":"11857179004","pt":1723367009092,"mc":[{"id":"1.231582255","rc":[{"batb":[[0,2.3,13.85],[1,1.74,6.7],[2,1.3,1000]],"ltp":2.32,"tv":70.18,"id":31379}]}]}
{"op":"mcm","clk":"11857179114","pt":1723367010277,"mc":[{"id":"1.231582255","rc":[{"batb":[[0,2.32,4],[1,2.3,13.85],[2,1.74,6.7]],"ltp":2.32,"tv":70.18,"id":31379}]}]}
{"op":"mcm","clk":"11857179165","pt":1723367010750,"mc":[{"id":"1.231582255","rc":[{"batb":[[0,2.34,10],[1,2.32,4],[2,2.3,13.85]],"ltp":2.32,"tv":70.18,"id":31379}]}]}
{"op":"mcm","clk":"11857179287","pt":1723367011969,"mc":[{"id":"1.231582255","rc":[{"batb":[[1,2.32,17.64]],"ltp":2.32,"tv":70.18,"id":31379}]}]}
{"op":"mcm","clk":"11857179358","pt":1723367012691,"mc":[{"id":"1.231582255","rc":[{"batb":[[1,2.32,13.64]],"ltp":2.32,"tv":70.18,"id":31379}]}]}
{"op":"mcm","clk":"11857179517","pt":1723367014478,"mc":[{"id":"1.231582255","rc":[{"batb":[[0,2.3,13.85],[1,1.74,6.7],[2,1.3,1000]],"ltp":2.32,"tv":70.18,"id":31379}]}]}
{"op":"mcm","clk":"11857179938","pt":1723367018380,"mc":[{"id":"1.231582255","rc":[{"batb":[[0,2.32,14],[1,2.3,13.85],[2,2.28,5]],"ltp":2.32,"tv":70.18,"id":31379}]}]}
{"op":"mcm","clk":"11857180205","pt":1723367020629,"mc":[{"id":"1.231582255","rc":[{"batb":[[0,2.32,10]],"ltp":2.32,"tv":70.18,"id":31379}]}]}
{"op":"mcm","clk":"11857180352","pt":1723367021708,"mc":[{"id":"1.231582255","rc":[{"batb":[[0,2.3,13.85],[1,2.28,5],[2,1.74,6.7]],"ltp":2.32,"tv":70.18,"id":31379}]}]}
{"op":"mcm","clk":"11857180647","pt":1723367024698,"mc":[{"id":"1.231582255","rc":[{"batb":[[0,2.32,14],[1,2.3,13.85],[2,2.28,5]],"ltp":2.32,"tv":70.18,"id":31379}]}]}
{"op":"mcm","clk":"11857180872","pt":1723367026997,"mc":[{"id":"1.231582255","rc":[{"batb":[[0,2.32,10]],"ltp":2.32,"tv":70.18,"id":31379}]}]}
{"op":"mcm","clk":"11857181002","pt":1723367027973,"mc":[{"id":"1.231582255","rc":[{"batb":[[0,2.3,13.85],[1,2.28,5],[2,1.74,6.7]],"ltp":2.32,"tv":70.18,"id":31379}]}]}
{"op":"mcm","clk":"11857181384","pt":1723367031726,"mc":[{"id":"1.231582255","rc":[{"batb":[[0,2.32,14],[1,2.3,13.85],[2,2.28,5]],"ltp":2.32,"tv":70.18,"id":31379}]}]}
{"op":"mcm","clk":"11857181578","pt":1723367033301,"mc":[{"id":"1.231582255","rc":[{"batb":[[2,1.74,6.7]],"ltp":2.32,"tv":70.18,"id":31379}]}]}
{"op":"mcm","clk":"11857181664","pt":1723367034209,"mc":[{"id":"1.231582255","rc":[{"batb":[[0,2.32,10]],"ltp":2.32,"tv":70.18,"id":31379}]}]}
{"op":"mcm","clk":"11857181776","pt":1723367035302,"mc":[{"id":"1.231582255","rc":[{"batb":[[0,2.3,13.85],[1,1.74,6.7],[2,1.3,1000]],"ltp":2.32,"tv":70.18,"id":31379}]}]}
{"op":"mcm","clk":"11857181989","pt":1723367037380,"mc":[{"id":"1.231582255","rc":[{"batb":[[0,2.32,4],[1,2.3,13.85],[2,1.74,6.7]],"ltp":2.32,"tv":70.18,"id":31379}]}]}
{"op":"mcm","clk":"11857182006","pt":1723367037587,"mc":[{"id":"1.231582255","rc":[{"batb":[[0,2.34,10],[1,2.32,4],[2,2.3,13.85]],"ltp":2.32,"tv":70.18,"id":31379}]}]}
{"op":"mcm","clk":"11857182239","pt":1723367040007,"mc":[{"id":"1.231582255","rc":[{"batb":[[1,2.32,13.64]],"ltp":2.32,"tv":70.18,"id":31379}]}]}
{"op":"mcm","clk":"11857182450","pt":1723367042103,"mc":[{"id":"1.231582255","rc":[{"batb":[[0,2.3,13.85],[1,1.74,6.7],[2,1.3,1000]],"ltp":2.32,"tv":70.18,"id":31379}]}]}
{"op":"mcm","clk":"11857182575","pt":1723367043313,"mc":[{"id":"1.231582255","rc":[{"batb":[[0,2.34,4],[1,2.3,13.85],[2,2.28,5]],"ltp":2.32,"tv":70.18,"id":31379}]}]}
{"op":"mcm","clk":"11857182633","pt":1723367043833,"mc":[{"id":"1.231582255","rc":[{"batb":[[0,2.36,10],[1,2.34,4],[2,2.3,13.85]],"ltp":2.32,"tv":70.18,"id":31379}]}]}
{"op":"mcm","clk":"11857182749","pt":1723367045028,"mc":[{"id":"1.231582255","rc":[{"batb":[[2,2.32,13.64]],"ltp":2.32,"tv":70.18,"id":31379}]}]}
{"op":"mcm","clk":"11857182827","pt":1723367045807,"mc":[{"id":"1.231582255","rc":[{"batb":[[1,2.32,13.64],[2,2.3,13.85]],"ltp":2.32,"tv":70.18,"id":31379}]}]}
{"op":"mcm","clk":"11857183014","pt":1723367047520,"mc":[{"id":"1.231582255","rc":[{"batb":[[0,2.32,13.64],[1,2.3,13.85],[2,2.28,5]],"ltp":2.32,"tv":70.18,"id":31379}]}]}
{"op":"mcm","clk":"11857183084","pt":1723367048099,"mc":[{"id":"1.231582255","rc":[{"batb":[[0,2.3,13.85],[1,2.28,5],[2,1.74,6.7]],"ltp":2.32,"tv":70.18,"id":31379}]}]}
{"op":"mcm","clk":"11857183140","pt":1723367048622,"mc":[{"id":"1.231582255","rc":[{"batb":[[0,2.34,4],[1,2.3,13.85],[2,2.28,5]],"ltp":2.32,"tv":70.18,"id":31379}]}]}
{"op":"mcm","clk":"11857183264","pt":1723367049724,"mc":[{"id":"1.231582255","rc":[{"batb":[[0,2.36,10],[1,2.34,4],[2,2.3,13.85]],"ltp":2.32,"tv":70.18,"id":31379}]}]}
{"op":"mcm","clk":"11857183401","pt":1723367050996,"mc":[{"id":"1.231582255","rc":[{"batb":[[2,2.32,13.64]],"ltp":2.32,"tv":70.18,"id":31379}]}]}
{"op":"mcm","clk":"11857183488","pt":1723367051721,"mc":[{"id":"1.231582255","rc":[{"batb":[[1,2.32,13.64],[2,2.3,13.85]],"ltp":2.32,"tv":70.18,"id":31379}]}]}
{"op":"mcm","clk":"11857183738","pt":1723367054126,"mc":[{"id":"1.231582255","rc":[{"batb":[[0,2.34,4],[1,2.3,13.85],[2,1.74,6.7]],"ltp":2.32,"tv":70.18,"id":31379}]}]}
{"op":"mcm","clk":"11857183946","pt":1723367056307,"mc":[{"id":"1.231582255","rc":[{"batb":[[0,2.32,13.64]],"ltp":2.32,"tv":70.18,"id":31379}]}]}
{"op":"mcm","clk":"11857184025","pt":1723367057029,"mc":[{"id":"1.231582255","rc":[{"batb":[[0,2.36,10]],"ltp":2.32,"tv":70.18,"id":31379}]}]}
{"op":"mcm","clk":"11857184196","pt":1723367058394,"mc":[{"id":"1.231582255","rc":[{"batb":[[2,2.28,5]],"ltp":2.32,"tv":70.18,"id":31379}]}]}
{"op":"mcm","clk":"11857184264","pt":1723367059017,"mc":[{"id":"1.231582255","rc":[{"batb":[[1,2.32,13.64],[2,2.3,13.85]],"ltp":2.32,"tv":70.18,"id":31379}]}]}
{"op":"mcm","clk":"11857184495","pt":1723367061006,"mc":[{"id":"1.231582255","rc":[{"batb":[[0,2.34,4],[1,2.3,13.85],[2,2.28,5]],"ltp":2.32,"tv":70.18,"id":31379}]}]}
{"op":"mcm","clk":"11857184775","pt":1723367063509,"mc":[{"id":"1.231582255","rc":[{"batb":[[0,2.36,10],[1,2.32,13.64],[2,2.3,13.85]],"ltp":2.32,"tv":70.18,"id":31379}]}]}
{"op":"mcm","clk":"11857184786","pt":1723367063614,"mc":[{"id":"1.231582255","rc":[{"batb":[[1,2.3,13.85],[2,1.74,6.7]],"ltp":2.32,"tv":70.18,"id":31379}]}]}
{"op":"mcm","clk":"11857185039","pt":1723367066009,"mc":[{"id":"1.231582255","rc":[{"batb":[[1,2.32,13.64],[2,2.3,13.85]],"ltp":2.32,"tv":70.18,"id":31379}]}]}
{"op":"mcm","clk":"11857185152","pt":1723367067205,"mc":[{"id":"1.231582255","rc":[{"batb":[[0,2.34,4]],"ltp":2.32,"tv":70.18,"id":31379}]}]}
{"op":"mcm","clk":"11857185359","pt":1723367069434,"mc":[{"id":"1.231582255","rc":[{"batb":[[0,2.32,13.64],[1,2.3,13.85],[2,1.74,6.7]],"ltp":2.32,"tv":70.18,"id":31379}]}]}
{"op":"mcm","clk":"11857185396","pt":1723367069806,"mc":[{"id":"1.231582255","rc":[{"batb":[[0,2.34,10],[1,2.32,13.64],[2,2.3,13.85]],"ltp":2.32,"tv":70.18,"id":31379}]}]}
{"op":"mcm","clk":"11857185716","pt":1723367073243,"mc":[{"id":"1.231582255","rc":[{"batb":[[0,2.34,4]],"ltp":2.32,"tv":70.18,"id":31379}]}]}
{"op":"mcm","clk":"11857185996","pt":1723367075529,"mc":[{"id":"1.231582255","rc":[{"batb":[[0,2.34,10]],"ltp":2.32,"tv":70.18,"id":31379}]}]}
{"op":"mcm","clk":"11857186306","pt":1723367078527,"mc":[{"id":"1.231582255","rc":[{"batb":[[0,2.36,4],[1,2.34,10],[2,2.32,13.64]],"ltp":2.32,"tv":70.18,"id":31379}]}]}
{"op":"mcm","clk":"11857186351","pt":1723367078838,"mc":[{"id":"1.231582255","rc":[{"batb":[[1,2.32,13.64],[2,2.3,13.85]],"ltp":2.32,"tv":70.18,"id":31379}]}]}
{"op":"mcm","clk":"11857186615","pt":1723367081135,"mc":[{"id":"1.231582255","rc":[{"batb":[[0,2.34,10],[1,2.3,13.85],[2,1.74,6.7]],"ltp":2.32,"tv":70.18,"id":31379}]}]}
{"op":"mcm","clk":"11857186840","pt":1723367083159,"mc":[{"id":"1.231582255","rc":[{"batb":[[0,2.36,4],[1,2.34,10],[2,2.32,13.64]],"ltp":2.32,"tv":70.18,"id":31379}]}]}
{"op":"mcm","clk":"11857186967","pt":1723367084462,"mc":[{"id":"1.231582255","rc":[{"batb":[[1,2.32,13.64],[2,2.3,13.85]],"ltp":2.32,"tv":70.18,"id":31379}]}]}
{"op":"mcm","clk":"11857187072","pt":1723367085446,"mc":[{"id":"1.231582255","rc":[{"batb":[[0,2.32,13.64],[1,2.3,13.85],[2,1.74,6.7]],"ltp":2.32,"tv":70.18,"id":31379}]}]}
{"op":"mcm","clk":"11857187157","pt":1723367086129,"mc":[{"id":"1.231582255","rc":[{"batb":[[0,2.3,13.85],[1,1.74,6.7],[2,1.3,1000]],"ltp":2.32,"tv":70.18,"id":31379}]}]}
{"op":"mcm","clk":"11857187411","pt":1723367088550,"mc":[{"id":"1.231582255","rc":[{"batb":[[1,2.28,5],[2,1.74,6.7]],"ltp":2.32,"tv":70.18,"id":31379}]}]}
{"op":"mcm","clk":"11857187536","pt":1723367089943,"mc":[{"id":"1.231582255","rc":[{"batb":[[0,2.32,14],[1,2.3,13.85],[2,2.28,5]],"ltp":2.32,"tv":70.18,"id":31379}]}]}
{"op":"mcm","clk":"11857187879","pt":1723367093173,"mc":[{"id":"1.231582255","rc":[{"batb":[[0,2.32,10]],"ltp":2.32,"tv":70.18,"id":31379}]}]}
{"op":"mcm","clk":"11857187975","pt":1723367094213,"mc":[{"id":"1.231582255","rc":[{"batb":[[0,2.3,13.85],[1,2.28,5],[2,1.74,6.7]],"ltp":2.32,"tv":70.18,"id":31379}]}]}
{"op":"mcm","clk":"11857190155","pt":1723367113788,"mc":[{"id":"1.231582255","rc":[{"batb":[[0,2.32,14],[1,2.3,13.85],[2,2.28,5]],"ltp":2.32,"tv":70.18,"id":31379}]}]}
{"op":"mcm","clk":"11857190425","pt":1723367116287,"mc":[{"id":"1.231582255","rc":[{"batb":[[0,2.32,10]],"ltp":2.32,"tv":70.18,"id":31379}]}]}
{"op":"mcm","clk":"11857190532","pt":1723367117290,"mc":[{"id":"1.231582255","rc":[{"batb":[[0,2.3,13.85],[1,2.28,5],[2,1.74,6.7]],"ltp":2.32,"tv":70.18,"id":31379}]}]}
{"op":"mcm","clk":"11857192061","pt":1723367131416,"mc":[{"id":"1.231582255","rc":[{"batb":[[0,2.32,14],[1,2.3,13.85],[2,2.28,5]],"ltp":2.32,"tv":70.18,"id":31379}]}]}
{"op":"mcm","clk":"11857192337","pt":1723367133921,"mc":[{"id":"1.231582255","rc":[{"batb":[[0,2.32,10],[2,1.74,6.7]],"ltp":2.32,"tv":70.18,"id":31379}]}]}
{"op":"mcm","clk":"11857192480","pt":1723367135222,"mc":[{"id":"1.231582255","rc":[{"batb":[[0,2.3,13.85],[1,1.74,6.7],[2,1.3,1000]],"ltp":2.32,"tv":70.18,"id":31379}]}]}
{"op":"mcm","clk":"11857192903","pt":1723367139096,"mc":[{"id":"1.231582255","rc":[{"batb":[[0,2.32,14],[1,2.3,13.85],[2,2.28,5]],"ltp":2.32,"tv":70.18,"id":31379}]}]}
{"op":"mcm","clk":"11857193144","pt":1723367141306,"mc":[{"id":"1.231582255","rc":[{"batb":[[0,2.32,10]],"ltp":2.32,"tv":70.18,"id":31379}]}]}
{"op":"mcm","clk":"11857193241","pt":1723367142317,"mc":[{"id":"1.231582255","rc":[{"batb":[[0,2.3,13.85],[1,2.28,5],[2,1.74,6.7]],"ltp":2.32,"tv":70.18,"id":31379}]}]}
{"op":"mcm","clk":"11857194966","pt":1723367156797,"mc":[{"id":"1.231582255","rc":[{"batb":[[0,2.32,14],[1,2.3,13.85],[2,2.28,5]],"ltp":2.32,"tv":70.18,"id":31379}]}]}
{"op":"mcm","clk":"11857195251","pt":1723367159345,"mc":[{"id":"1.231582255","rc":[{"batb":[[0,2.32,10],[2,1.74,6.7]],"ltp":2.32,"tv":70.18,"id":31379}]}]}
{"op":"mcm","clk":"11857195366","pt":1723367160238,"mc":[{"id":"1.231582255","rc":[{"batb":[[0,2.3,13.85],[1,1.74,6.7],[2,1.3,1000]],"ltp":2.32,"tv":70.18,"id":31379}]}]}
{"op":"mcm","clk":"11857195877","pt":1723367164424,"mc":[{"id":"1.231582255","rc":[{"batb":[[0,2.32,14],[1,2.3,13.85],[2,2.28,5]],"ltp":2.32,"tv":70.18,"id":31379}]}]}
{"op":"mcm","clk":"11857196227","pt":1723367167518,"mc":[{"id":"1.231582255","rc":[{"batb":[[0,2.32,10]],"ltp":2.32,"tv":70.18,"id":31379}]}]}
{"op":"mcm","clk":"11857196336","pt":1723367168553,"mc":[{"id":"1.231582255","rc":[{"batb":[[0,2.3,13.85],[1,2.28,5],[2,1.74,6.7]],"ltp":2.32,"tv":70.18,"id":31379}]}]}
{"op":"mcm","clk":"11857196600","pt":1723367170714,"mc":[{"id":"1.231582255","rc":[{"batb":[[0,2.32,14],[1,2.3,13.85],[2,2.28,5]],"ltp":2.32,"tv":70.18,"id":31379}]}]}
{"op":"mcm","clk":"11857196921","pt":1723367173468,"mc":[{"id":"1.231582255","rc":[{"batb":[[0,2.32,10]],"ltp":2.32,"tv":70.18,"id":31379}]}]}
{"op":"mcm","clk":"11857197041","pt":1723367174352,"mc":[{"id":"1.231582255","rc":[{"batb":[[0,2.3,13.85],[1,2.28,5],[2,1.74,6.7]],"ltp":2.32,"tv":70.18,"id":31379}]}]}
{"op":"mcm","clk":"11857197776","pt":1723367180743,"mc":[{"id":"1.231582255","rc":[{"batb":[[0,2.32,14],[1,2.3,13.85],[2,2.28,5]],"ltp":2.32,"tv":70.18,"id":31379}]}]}
{"op":"mcm","clk":"11857198077","pt":1723367183542,"mc":[{"id":"1.231582255","rc":[{"batb":[[0,2.32,10]],"ltp":2.32,"tv":70.18,"id":31379}]}]}
{"op":"mcm","clk":"11857198182","pt":1723367184633,"mc":[{"id":"1.231582255","rc":[{"batb":[[0,2.3,13.85],[1,2.28,5],[2,1.74,6.7]],"ltp":2.32,"tv":70.18,"id":31379}]}]}
{"op":"mcm","clk":"11857199354","pt":1723367195469,"mc":[{"id":"1.231582255","rc":[{"batb":[[0,2.32,14],[1,2.3,13.85],[2,2.28,5]],"ltp":2.32,"tv":70.18,"id":31379}]}]}
{"op":"mcm","clk":"11857199671","pt":1723367198076,"mc":[{"id":"1.231582255","rc":[{"batb":[[0,2.32,10]],"ltp":2.32,"tv":70.18,"id":31379}]}]}
{"op":"mcm","clk":"11857199786","pt":1723367199171,"mc":[{"id":"1.231582255","rc":[{"batb":[[0,2.3,13.85],[1,2.28,5],[2,1.74,6.7]],"ltp":2.32,"tv":70.18,"id":31379}]}]}
{"op":"mcm","clk":"11857200964","pt":1723367209382,"mc":[{"id":"1.231582255","rc":[{"batb":[[0,2.32,14],[1,2.3,13.85]],"ltp":2.32,"tv":70.18,"id":31379}]}]}
{"op":"mcm","clk":"11857201247","pt":1723367211672,"mc":[{"id":"1.231582255","rc":[{"batb":[[0,2.32,10]],"ltp":2.32,"tv":70.18,"id":31379}]}]}
{"op":"mcm","clk":"11857201405","pt":1723367212871,"mc":[{"id":"1.231582255","rc":[{"batb":[[0,2.3,13.85],[1,1.74,6.7],[2,1.3,1000]],"ltp":2.32,"tv":70.18,"id":31379}]}]}
{"op":"mcm","clk":"11857201579","pt":1723367214371,"mc":[{"id":"1.231582255","rc":[{"batb":[[1,2.28,5],[2,1.74,6.7]],"ltp":2.32,"tv":70.18,"id":31379}]}]}
{"op":"mcm","clk":"11857201667","pt":1723367215103,"mc":[{"id":"1.231582255","rc":[{"batb":[[0,2.34,10],[1,2.32,4],[2,2.3,13.85]],"ltp":2.32,"tv":70.18,"id":31379}]}]}
{"op":"mcm","clk":"11857201901","pt":1723367217186,"mc":[{"id":"1.231582255","rc":[{"batb":[[1,2.32,13.64]],"ltp":2.32,"tv":70.18,"id":31379}]}]}
{"op":"mcm","clk":"11857202024","pt":1723367218381,"mc":[{"id":"1.231582255","rc":[{"batb":[[0,2.32,13.64],[1,2.3,13.85],[2,2.28,5]],"ltp":2.32,"tv":70.18,"id":31379}]}]}
{"op":"mcm","clk":"11857202055","pt":1723367218693,"mc":[{"id":"1.231582255","rc":[{"batb":[[0,2.3,13.85],[1,2.28,5],[2,1.74,6.7]],"ltp":2.32,"tv":70.18,"id":31379}]}]}
{"op":"mcm","clk":"11857202246","pt":1723367220373,"mc":[{"id":"1.231582255","rc":[{"batb":[[0,2.32,4],[1,2.3,13.85],[2,2.28,5]],"ltp":2.32,"tv":70.18,"id":31379}]}]}
{"op":"mcm","clk":"11857202322","pt":1723367220997,"mc":[{"id":"1.231582255","rc":[{"batb":[[0,2.34,10],[1,2.32,4],[2,2.3,13.85]],"ltp":2.32,"tv":70.18,"id":31379}]}]}
{"op":"mcm","clk":"11857202462","pt":1723367222207,"mc":[{"id":"1.231582255","rc":[{"batb":[[1,2.32,17.64]],"ltp":2.32,"tv":70.18,"id":31379}]}]}
{"op":"mcm","clk":"11857202565","pt":1723367222889,"mc":[{"id":"1.231582255","rc":[{"batb":[[1,2.32,13.64]],"ltp":2.32,"tv":70.18,"id":31379}]}]}
{"op":"mcm","clk":"11857202758","pt":1723367224504,"mc":[{"id":"1.231582255","rc":[{"batb":[[0,2.32,13.64],[1,2.3,13.85],[2,1.74,6.7]],"ltp":2.32,"tv":70.18,"id":31379}]}]}
{"op":"mcm","clk":"11857202784","pt":1723367224663,"mc":[{"id":"1.231582255","rc":[{"batb":[[0,2.3,13.85],[1,1.74,6.7],[2,1.3,1000]],"ltp":2.32,"tv":70.18,"id":31379}]}]}
{"op":"mcm","clk":"11857202943","pt":1723367225977,"mc":[{"id":"1.231582255","rc":[{"batb":[[0,2.34,4],[1,2.3,13.85],[2,1.74,6.7]],"ltp":2.32,"tv":70.18,"id":31379}]}]}
{"op":"mcm","clk":"11857203202","pt":1723367228174,"mc":[{"id":"1.231582255","rc":[{"batb":[[0,2.36,10],[1,2.34,4],[2,2.32,13.64]],"ltp":2.32,"tv":70.18,"id":31379}]}]}
{"op":"mcm","clk":"11857203463","pt":1723367230176,"mc":[{"id":"1.231582255","rc":[{"batb":[[1,2.32,13.64],[2,2.3,13.85]],"ltp":2.32,"tv":70.18,"id":31379}]}]}
{"op":"mcm","clk":"11857203778","pt":1723367232780,"mc":[{"id":"1.231582255","rc":[{"batb":[[0,2.34,4]],"ltp":2.32,"tv":70.18,"id":31379}]}]}
{"op":"mcm","clk":"11857204099","pt":1723367235383,"mc":[{"id":"1.231582255","rc":[{"batb":[[0,2.34,10],[1,2.3,13.85],[2,1.74,6.7]],"ltp":2.32,"tv":70.18,"id":31379}]}]}
{"op":"mcm","clk":"11857204315","pt":1723367237207,"mc":[{"id":"1.231582255","rc":[{"batb":[[1,2.32,13.64],[2,2.3,13.85]],"ltp":2.32,"tv":70.18,"id":31379}]}]}
{"op":"mcm","clk":"11857204379","pt":1723367237795,"mc":[{"id":"1.231582255","rc":[{"batb":[[0,2.36,4],[1,2.34,10],[2,2.32,13.64]],"ltp":2.32,"tv":70.18,"id":31379}]}]}
{"op":"mcm","clk":"11857204478","pt":1723367238582,"mc":[{"id":"1.231582255","rc":[{"batb":[[1,2.32,13.64],[2,2.3,13.85]],"ltp":2.32,"tv":70.18,"id":31379}]}]}
{"op":"mcm","clk":"11857204668","pt":1723367240296,"mc":[{"id":"1.231582255","rc":[{"batb":[[0,2.32,13.64],[1,2.3,13.85],[2,1.74,6.7]],"ltp":2.32,"tv":70.18,"id":31379}]}]}
{"op":"mcm","clk":"11857204723","pt":1723367240811,"mc":[{"id":"1.231582255","rc":[{"batb":[[0,2.32,10]],"ltp":2.32,"tv":70.18,"id":31379}]}]}
{"op":"mcm","clk":"11857205180","pt":1723367244513,"mc":[{"id":"1.231582255","rc":[{"batb":[[0,2.32,4]],"ltp":2.32,"tv":70.18,"id":31379}]}]}
{"op":"mcm","clk":"11857205192","pt":1723367244610,"mc":[{"id":"1.231582255","rc":[{"batb":[[2,2.28,5]],"ltp":2.32,"tv":70.18,"id":31379}]}]}
{"op":"mcm","clk":"11857205489","pt":1723367247101,"mc":[{"id":"1.231582255","rc":[{"batb":[[0,2.34,10]],"ltp":2.32,"tv":70.18,"id":31379}]}]}
{"op":"mcm","clk":"11857205608","pt":1723367248195,"mc":[{"id":"1.231582255","rc":[{"batb":[[1,2.32,13.64],[2,2.3,13.85]],"ltp":2.32,"tv":70.18,"id":31379}]}]}
{"op":"mcm","clk":"11857205759","pt":1723367249494,"mc":[{"id":"1.231582255","rc":[{"batb":[[0,2.36,4],[1,2.34,10],[2,2.32,13.64]],"ltp":2.32,"tv":70.18,"id":31379}]}]}
{"op":"mcm","clk":"11857205929","pt":1723367250999,"mc":[{"id":"1.231582255","rc":[{"batb":[[1,2.32,13.64],[2,2.3,13.85]],"ltp":2.32,"tv":70.18,"id":31379}]}]}
{"op":"mcm","clk":"11857206068","pt":1723367252099,"mc":[{"id":"1.231582255","rc":[{"batb":[[0,2.32,13.64],[1,2.3,13.85],[2,1.74,6.7]],"ltp":2.32,"tv":70.18,"id":31379}]}]}
{"op":"mcm","clk":"11857206150","pt":1723367252713,"mc":[{"id":"1.231582255","rc":[{"batb":[[0,2.3,13.85],[1,1.74,6.7],[2,1.3,1000]],"ltp":2.32,"tv":70.18,"id":31379}]}]}
{"op":"mcm","clk":"11857206420","pt":1723367254835,"mc":[{"id":"1.231582255","rc":[{"batb":[[0,2.32,14],[1,2.3,13.85],[2,2.28,5]],"ltp":2.32,"tv":70.18,"id":31379}]}]}
{"op":"mcm","clk":"11857206653","pt":1723367257017,"mc":[{"id":"1.231582255","rc":[{"batb":[[0,2.32,10]],"ltp":2.32,"tv":70.18,"id":31379}]}]}
{"op":"mcm","clk":"11857206776","pt":1723367258106,"mc":[{"id":"1.231582255","rc":[{"batb":[[0,2.3,13.85],[1,2.28,5],[2,1.74,6.7]],"ltp":2.32,"tv":70.18,"id":31379}]}]}
{"op":"mcm","clk":"11857207440","pt":1723367263533,"mc":[{"id":"1.231582255","rc":[{"batb":[[0,2.32,14],[1,2.3,13.85],[2,2.28,5]],"ltp":2.32,"tv":70.18,"id":31379}]}]}
{"op":"mcm","clk":"11857207560","pt":1723367264637,"mc":[{"id":"1.231582255","rc":[{"batb":[[2,1.74,6.7]],"ltp":2.32,"tv":70.18,"id":31379}]}]}
{"op":"mcm","clk":"11857207969","pt":1723367268337,"mc":[{"id":"1.231582255","rc":[{"batb":[[0,2.32,10]],"ltp":2.32,"tv":70.18,"id":31379}]}]}
{"op":"mcm","clk":"11857208080","pt":1723367269386,"mc":[{"id":"1.231582255","rc":[{"batb":[[0,2.3,13.85],[1,1.74,6.7],[2,1.3,1000]],"ltp":2.32,"tv":70.18,"id":31379}]}]}
{"op":"mcm","clk":"11857208133","pt":1723367269754,"mc":[{"id":"1.231582255","rc":[{"batb":[[1,2.28,5],[2,1.74,6.7]],"ltp":2.32,"tv":70.18,"id":31379}]}]}
{"op":"mcm","clk":"11857208276","pt":1723367271146,"mc":[{"id":"1.231582255","rc":[{"batb":[[0,2.32,4],[1,2.3,13.85],[2,2.28,5]],"ltp":2.32,"tv":70.18,"id":31379}]}]}
{"op":"mcm","clk":"11857208372","pt":1723367272032,"mc":[{"id":"1.231582255","rc":[{"batb":[[0,2.34,10],[1,2.32,4],[2,2.3,13.85]],"ltp":2.32,"tv":70.18,"id":31379}]}]}
{"op":"mcm","clk":"11857208486","pt":1723367273163,"mc":[{"id":"1.231582255","rc":[{"batb":[[1,2.32,17.64]],"ltp":2.32,"tv":70.18,"id":31379}]}]}
{"op":"mcm","clk":"11857208604","pt":1723367274155,"mc":[{"id":"1.231582255","rc":[{"batb":[[1,2.32,13.64]],"ltp":2.32,"tv":70.18,"id":31379}]}]}
{"op":"mcm","clk":"11857208940","pt":1723367276967,"mc":[{"id":"1.231582255","rc":[{"batb":[[0,2.34,4]],"ltp":2.32,"tv":70.18,"id":31379}]}]}
{"op":"mcm","clk":"11857209210","pt":1723367279362,"mc":[{"id":"1.231582255","rc":[{"batb":[[0,2.34,10]],"ltp":2.32,"tv":70.18,"id":31379}]}]}
{"op":"mcm","clk":"11857209253","pt":1723367279667,"mc":[{"id":"1.231582255","rc":[{"batb":[[1,2.3,13.85],[2,1.74,6.7]],"ltp":2.32,"tv":70.18,"id":31379}]}]}
{"op":"mcm","clk":"11857209537","pt":1723367282273,"mc":[{"id":"1.231582255","rc":[{"batb":[[0,2.36,4],[1,2.34,10],[2,2.32,13.64]],"ltp":2.32,"tv":70.18,"id":31379}]}]}
{"op":"mcm","clk":"11857209611","pt":1723367282953,"mc":[{"id":"1.231582255","rc":[{"batb":[[1,2.32,13.64],[2,2.3,13.85]],"ltp":2.32,"tv":70.18,"id":31379}]}]}
{"op":"mcm","clk":"11857209901","pt":1723367285381,"mc":[{"id":"1.231582255","rc":[{"batb":[[0,2.32,10],[1,2.3,13.85],[2,1.74,6.7]],"ltp":2.32,"tv":70.18,"id":31379}]}]}
{"op":"mcm","clk":"11857210307","pt":1723367288759,"mc":[{"id":"1.231582255","rc":[{"batb":[[0,2.3,13.85],[1,1.74,6.7],[2,1.3,1000]],"ltp":2.32,"tv":70.18,"id":31379}]}]}
{"op":"mcm","clk":"11857210441","pt":1723367289863,"mc":[{"id":"1.231582255","rc":[{"batb":[[1,2.28,5],[2,1.74,6.7]],"ltp":2.32,"tv":70.18,"id":31379}]}]}
{"op":"mcm","clk":"11857210649","pt":1723367291474,"mc":[{"id":"1.231582255","rc":[{"batb":[[0,2.32,14],[1,2.3,13.85],[2,2.28,5]],"ltp":2.32,"tv":70.18,"id":31379}]}]}
{"op":"mcm","clk":"11857211068","pt":1723367295166,"mc":[{"id":"1.231582255","rc":[{"batb":[[0,2.32,10],[2,1.74,6.7]],"ltp":2.32,"tv":70.18,"id":31379}]}]}
{"op":"mcm","clk":"11857211304","pt":1723367297293,"mc":[{"id":"1.231582255","rc":[{"batb":[[0,2.3,13.85],[1,1.74,6.7],[2,1.3,1000]],"ltp":2.32,"tv":70.18,"id":31379}]}]}
{"op":"mcm","clk":"11857211417","pt":1723367298287,"mc":[{"id":"1.231582255","rc":[{"batb":[[0,2.32,4],[1,2.3,13.85],[2,1.74,6.7]],"ltp":2.32,"tv":70.18,"id":31379}]}]}
{"op":"mcm","clk":"11857211587","pt":1723367299908,"mc":[{"id":"1.231582255","rc":[{"batb":[[2,2.28,5]],"ltp":2.32,"tv":70.18,"id":31379}]}]}
{"op":"mcm","clk":"11857211757","pt":1723367301211,"mc":[{"id":"1.231582255","rc":[{"batb":[[0,2.34,10],[1,2.32,13.64],[2,2.3,13.85]],"ltp":2.32,"tv":70.18,"id":31379}]}]}
{"op":"mcm","clk":"11857212187","pt":1723367304895,"mc":[{"id":"1.231582255","rc":[{"batb":[[0,2.34,4]],"ltp":2.32,"tv":70.18,"id":31379}]}]}
{"op":"mcm","clk":"11857212487","pt":1723367307388,"mc":[{"id":"1.231582255","rc":[{"batb":[[0,2.36,10]],"ltp":2.32,"tv":70.18,"id":31379}]}]}
{"op":"mcm","clk":"11857212927","pt":1723367311230,"mc":[{"id":"1.231582255","rc":[{"batb":[[0,2.32,13.64],[1,2.3,13.85],[2,1.74,6.7]],"ltp":2.32,"tv":70.18,"id":31379}]}]}
{"op":"mcm","clk":"11857213036","pt":1723367312204,"mc":[{"id":"1.231582255","rc":[{"batb":[[0,2.34,4]],"ltp":2.32,"tv":70.18,"id":31379}]}]}
{"op":"mcm","clk":"11857213288","pt":1723367314387,"mc":[{"id":"1.231582255","rc":[{"batb":[[0,2.36,10],[1,2.34,4],[2,2.32,13.64]],"ltp":2.32,"tv":70.18,"id":31379}]}]}
{"op":"mcm","clk":"11857213328","pt":1723367314698,"mc":[{"id":"1.231582255","rc":[{"batb":[[1,2.32,13.64],[2,2.3,13.85]],"ltp":2.32,"tv":70.18,"id":31379}]}]}
{"op":"mcm","clk":"11857213725","pt":1723367318290,"mc":[{"id":"1.231582255","rc":[{"batb":[[0,2.34,4],[1,2.3,13.85],[2,1.74,6.7]],"ltp":2.32,"tv":70.18,"id":31379}]}]}
{"op":"mcm","clk":"11857213985","pt":1723367320378,"mc":[{"id":"1.231582255","rc":[{"batb":[[0,2.36,10],[1,2.34,4],[2,2.32,13.64]],"ltp":2.32,"tv":70.18,"id":31379}]}]}
{"op":"mcm","clk":"11857214027","pt":1723367320686,"mc":[{"id":"1.231582255","rc":[{"batb":[[1,2.32,13.64],[2,2.3,13.85]],"ltp":2.32,"tv":70.18,"id":31379}]}]}
{"op":"mcm","clk":"11857214443","pt":1723367323998,"mc":[{"id":"1.231582255","rc":[{"batb":[[0,2.34,4]],"ltp":2.32,"tv":70.18,"id":31379}]}]}
{"op":"mcm","clk":"11857214706","pt":1723367326282,"mc":[{"id":"1.231582255","rc":[{"batb":[[0,2.32,13.64],[1,2.3,13.85],[2,1.74,6.7]],"ltp":2.32,"tv":70.18,"id":31379}]}]}
{"op":"mcm","clk":"11857214752","pt":1723367326688,"mc":[{"id":"1.231582255","rc":[{"batb":[[0,2.34,10]],"ltp":2.32,"tv":70.18,"id":31379}]}]}
{"op":"mcm","clk":"11857215087","pt":1723367329486,"mc":[{"id":"1.231582255","rc":[{"batb":[[0,2.36,4],[1,2.34,10],[2,2.32,13.64]],"ltp":2.32,"tv":70.18,"id":31379}]}]}
{"op":"mcm","clk":"11857215177","pt":1723367330210,"mc":[{"id":"1.231582255","rc":[{"batb":[[1,2.32,13.64],[2,2.3,13.85]],"ltp":2.32,"tv":70.18,"id":31379}]}]}
{"op":"mcm","clk":"11857215417","pt":1723367332187,"mc":[{"id":"1.231582255","rc":[{"batb":[[0,2.3,13.85],[1,1.74,6.7],[2,1.3,1000]],"ltp":2.32,"tv":70.18,"id":31379}]}]}
{"op":"mcm","clk":"11857215469","pt":1723367332809,"mc":[{"id":"1.231582255","rc":[{"batb":[[0,2.34,10],[1,2.3,13.85],[2,1.74,6.7]],"ltp":2.32,"tv":70.18,"id":31379}]}]}
{"op":"mcm","clk":"11857215718","pt":1723367335204,"mc":[{"id":"1.231582255","rc":[{"batb":[[0,2.36,4],[1,2.34,10],[2,2.32,13.64]],"ltp":2.32,"tv":70.18,"id":31379}]}]}
{"op":"mcm","clk":"11857215840","pt":1723367336288,"mc":[{"id":"1.231582255","rc":[{"batb":[[1,2.32,13.64],[2,2.3,13.85]],"ltp":2.32,"tv":70.18,"id":31379}]}]}
{"op":"mcm","clk":"11857216016","pt":1723367338209,"mc":[{"id":"1.231582255","rc":[{"batb":[[0,2.3,13.85],[1,2.28,5],[2,1.74,6.7]],"ltp":2.32,"tv":70.18,"id":31379}]}]}
{"op":"mcm","clk":"11857216075","pt":1723367338725,"mc":[{"id":"1.231582255","rc":[{"batb":[[0,2.32,10],[1,2.3,13.85],[2,2.28,5]],"ltp":2.32,"tv":70.18,"id":31379}]}]}
{"op":"mcm","clk":"11857216472","pt":1723367342217,"mc":[{"id":"1.231582255","rc":[{"batb":[[0,2.32,4]],"ltp":2.32,"tv":70.18,"id":31379}]}]}
{"op":"mcm","clk":"11857216711","pt":1723367344397,"mc":[{"id":"1.231582255","rc":[{"batb":[[0,2.3,13.85],[1,2.28,5],[2,1.74,6.7]],"ltp":2.32,"tv":70.18,"id":31379}]}]}
{"op":"mcm","clk":"11857216763","pt":1723367344812,"mc":[{"id":"1.231582255","rc":[{"batb":[[0,2.32,10],[1,2.3,13.85],[2,2.28,5]],"ltp":2.32,"tv":70.18,"id":31379}]}]}
{"op":"mcm","clk":"11857217064","pt":1723367347216,"mc":[{"id":"1.231582255","rc":[{"batb":[[0,2.34,4],[1,2.32,10],[2,2.3,13.85]],"ltp":2.32,"tv":70.18,"id":31379}]}]}
{"op":"mcm","clk":"11857217189","pt":1723367348306,"mc":[{"id":"1.231582255","rc":[{"batb":[[1,2.32,13.64]],"ltp":2.32,"tv":70.18,"id":31379}]}]}
{"op":"mcm","clk":"11857217410","pt":1723367350241,"mc":[{"id":"1.231582255","rc":[{"batb":[[0,2.3,13.85],[1,1.74,6.7],[2,1.3,1000]],"ltp":2.32,"tv":70.18,"id":31379}]}]}
{"op":"mcm","clk":"11857217454","pt":1723367350601,"mc":[{"id":"1.231582255","rc":[{"batb":[[0,2.32,10],[1,2.3,13.85],[2,1.74,6.7]],"ltp":2.32,"tv":70.18,"id":31379}]}]}
{"op":"mcm","clk":"11857217854","pt":1723367353926,"mc":[{"id":"1.231582255","rc":[{"batb":[[0,2.3,13.85],[1,1.74,6.7],[2,1.3,1000]],"ltp":2.32,"tv":70.18,"id":31379}]}]}
{"op":"mcm","clk":"11857218003","pt":1723367355224,"mc":[{"id":"1.231582255","rc":[{"batb":[[0,2.32,4],[1,2.3,13.85],[2,2.28,5]],"ltp":2.32,"tv":70.18,"id":31379}]}]}
{"op":"mcm","clk":"11857218213","pt":1723367356939,"mc":[{"id":"1.231582255","rc":[{"batb":[[0,2.3,13.85],[1,2.28,5],[2,1.74,6.7]],"ltp":2.32,"tv":70.18,"id":31379}]}]}
{"op":"mcm","clk":"11857218303","pt":1723367357745,"mc":[{"id":"1.231582255","rc":[{"batb":[[0,2.32,10],[1,2.3,13.85],[2,2.28,5]],"ltp":2.32,"tv":70.18,"id":31379}]}]}
{"op":"mcm","clk":"11857218742","pt":1723367361337,"mc":[{"id":"1.231582255","rc":[{"batb":[[0,2.3,13.85],[1,2.28,5],[2,1.74,6.7]],"ltp":2.32,"tv":70.18,"id":31379}]}]}
{"op":"mcm","clk":"11857218863","pt":1723367362335,"mc":[{"id":"1.231582255","rc":[{"batb":[[0,2.32,4],[1,2.3,13.85],[2,2.28,5]],"ltp":2.32,"tv":70.18,"id":31379}]}]}
{"op":"mcm","clk":"11857219098","pt":1723367364285,"mc":[{"id":"1.231582255","rc":[{"batb":[[0,2.34,10],[1,2.32,17.64],[2,2.3,13.85]],"ltp":2.32,"tv":70.18,"id":31379}]}]}
{"op":"mcm","clk":"11857219222","pt":1723367365226,"mc":[{"id":"1.231582255","rc":[{"batb":[[1,2.32,13.64]],"ltp":2.32,"tv":70.18,"id":31379}]}]}
{"op":"mcm","clk":"11857219482","pt":1723367367450,"mc":[{"id":"1.231582255","rc":[{"batb":[[0,2.34,4]],"ltp":2.32,"tv":70.18,"id":31379}]}]}
{"op":"mcm","clk":"11857219750","pt":1723367369844,"mc":[{"id":"1.231582255","rc":[{"batb":[[0,2.34,10]],"ltp":2.32,"tv":70.18,"id":31379}]}]}
{"op":"mcm","clk":"11857220005","pt":1723367372132,"mc":[{"id":"1.231582255","rc":[{"batb":[[0,2.36,4],[1,2.34,10],[2,2.32,13.64]],"ltp":2.32,"tv":70.18,"id":31379}]}]}
{"op":"mcm","clk":"11857220162","pt":1723367373445,"mc":[{"id":"1.231582255","rc":[{"batb":[[1,2.32,13.64],[2,2.3,13.85]],"ltp":2.32,"tv":70.18,"id":31379}]}]}
{"op":"mcm","clk":"11857220376","pt":1723367375278,"mc":[{"id":"1.231582255","rc":[{"batb":[[0,2.3,13.85],[1,1.74,6.7],[2,1.3,1000]],"ltp":2.32,"tv":70.18,"id":31379}]}]}
{"op":"mcm","clk":"11857220658","pt":1723367377456,"mc":[{"id":"1.231582255","rc":[{"batb":[[0,2.32,14],[1,2.3,13.85],[2,1.74,6.7]],"ltp":2.32,"tv":70.18,"id":31379}]}]}
{"op":"mcm","clk":"11857221089","pt":1723367381199,"mc":[{"id":"1.231582255","rc":[{"batb":[[0,2.3,13.85],[1,1.74,6.7],[2,1.3,1000]],"ltp":2.32,"tv":70.18,"id":31379}]}]}
{"op":"mcm","clk":"11857221376","pt":1723367383481,"mc":[{"id":"1.231582255","rc":[{"batb":[[0,2.34,14],[1,2.3,13.85],[2,1.74,6.7]],"ltp":2.32,"tv":70.18,"id":31379}]}]}
{"op":"mcm","clk":"11857221583","pt":1723367385304,"mc":[{"id":"1.231582255","rc":[{"batb":[[1,2.32,13.64],[2,2.3,13.85]],"ltp":2.32,"tv":70.18,"id":31379}]}]}
{"op":"mcm","clk":"11857221815","pt":1723367387380,"mc":[{"id":"1.231582255","rc":[{"batb":[[0,2.34,10]],"ltp":2.32,"tv":70.18,"id":31379}]}]}
{"op":"mcm","clk":"11857221946","pt":1723367388370,"mc":[{"id":"1.231582255","rc":[{"batb":[[0,2.32,13.64],[1,2.3,13.85],[2,1.74,6.7]],"ltp":2.32,"tv":70.18,"id":31379}]}]}
{"op":"mcm","clk":"11857221999","pt":1723367388781,"mc":[{"id":"1.231582255","rc":[{"batb":[[0,2.3,13.85],[1,1.74,6.7],[2,1.3,1000]],"ltp":2.32,"tv":70.18,"id":31379}]}]}
{"op":"mcm","clk":"11857222173","pt":1723367390384,"mc":[{"id":"1.231582255","rc":[{"batb":[[1,2.28,5],[2,1.74,6.7]],"ltp":2.32,"tv":70.18,"id":31379}]}]}
{"op":"mcm","clk":"11857222198","pt":1723367390591,"mc":[{"id":"1.231582255","rc":[{"batb":[[0,2.32,14],[1,2.3,13.85],[2,2.28,5]],"ltp":2.32,"tv":70.18,"id":31379}]}]}
{"op":"mcm","clk":"11857222501","pt":1723367392984,"mc":[{"id":"1.231582255","rc":[{"batb":[[0,2.32,10]],"ltp":2.32,"tv":70.18,"id":31379}]}]}
{"op":"mcm","clk":"11857222615","pt":1723367393815,"mc":[{"id":"1.231582255","rc":[{"batb":[[0,2.3,13.85],[1,2.28,5],[2,1.74,6.7]],"ltp":2.32,"tv":70.18,"id":31379}]}]}
{"op":"mcm","clk":"11857224084","pt":1723367406109,"mc":[{"id":"1.231582255","rc":[{"batb":[[0,2.32,14],[1,2.3,13.85],[2,2.28,5]],"ltp":2.32,"tv":70.18,"id":31379}]}]}
{"op":"mcm","clk":"11857224393","pt":1723367408597,"mc":[{"id":"1.231582255","rc":[{"batb":[[0,2.32,10]],"ltp":2.32,"tv":70.18,"id":31379}]}]}
{"op":"mcm","clk":"11857224514","pt":1723367409582,"mc":[{"id":"1.231582255","rc":[{"batb":[[0,2.3,13.85],[1,2.28,5],[2,1.74,6.7]],"ltp":2.32,"tv":70.18,"id":31379}]}]}
{"op":"mcm","clk":"11857226855","pt":1723367430436,"mc":[{"id":"1.231582255","rc":[{"batb":[[0,2.32,14],[1,2.3,13.85],[2,2.28,5]],"ltp":2.32,"tv":70.18,"id":31379}]}]}
{"op":"mcm","clk":"11857226870","pt":1723367430640,"mc":[{"id":"1.231582255","rc":[{"batb":[[2,1.74,6.7]],"ltp":2.32,"tv":70.18,"id":31379}]}]}
{"op":"mcm","clk":"11857227189","pt":1723367433356,"mc":[{"id":"1.231582255","rc":[{"batb":[[0,2.32,10]],"ltp":2.32,"tv":70.18,"id":31379}]}]}
{"op":"mcm","clk":"11857227291","pt":1723367434250,"mc":[{"id":"1.231582255","rc":[{"batb":[[0,2.3,13.85],[1,1.74,6.7],[2,1.3,1000]],"ltp":2.32,"tv":70.18,"id":31379}]}]}
{"op":"mcm","clk":"11857227519","pt":1723367436335,"mc":[{"id":"1.231582255","rc":[{"batb":[[0,2.32,4],[1,2.3,13.85],[2,2.28,5]],"ltp":2.32,"tv":70.18,"id":31379}]}]}
{"op":"mcm","clk":"11857227604","pt":1723367437166,"mc":[{"id":"1.231582255","rc":[{"batb":[[0,2.34,10],[1,2.32,4],[2,2.3,13.85]],"ltp":2.32,"tv":70.18,"id":31379}]}]}
{"op":"mcm","clk":"11857227718","pt":1723367438252,"mc":[{"id":"1.231582255","rc":[{"batb":[[1,2.32,17.64]],"ltp":2.32,"tv":70.18,"id":31379}]}]}
{"op":"mcm","clk":"11857227829","pt":1723367439136,"mc":[{"id":"1.231582255","rc":[{"batb":[[1,2.32,13.64]],"ltp":2.32,"tv":70.18,"id":31379}]}]}
{"op":"mcm","clk":"11857228029","pt":1723367440863,"mc":[{"id":"1.231582255","rc":[{"batb":[[0,2.3,13.85],[1,1.74,6.7],[2,1.3,1000]],"ltp":2.32,"tv":70.18,"id":31379}]}]}
{"op":"mcm","clk":"11857228111","pt":1723367441541,"mc":[{"id":"1.231582255","rc":[{"batb":[[0,2.34,4],[1,2.3,13.85],[2,1.74,6.7]],"ltp":2.32,"tv":70.18,"id":31379}]}]}
{"op":"mcm","clk":"11857228334","pt":1723367443462,"mc":[{"id":"1.231582255","rc":[{"batb":[[0,2.36,10],[1,2.34,4],[2,2.32,13.64]],"ltp":2.32,"tv":70.18,"id":31379}]}]}
{"op":"mcm","clk":"11857228429","pt":1723367444140,"mc":[{"id":"1.231582255","rc":[{"batb":[[1,2.32,13.64],[2,2.3,13.85]],"ltp":2.32,"tv":70.18,"id":31379}]}]}
{"op":"mcm","clk":"11857228737","pt":1723367446779,"mc":[{"id":"1.231582255","rc":[{"batb":[[0,2.34,4]],"ltp":2.32,"tv":70.18,"id":31379}]}]}
{"op":"mcm","clk":"11857229051","pt":1723367449365,"mc":[{"id":"1.231582255","rc":[{"batb":[[0,2.34,10],[1,2.3,13.85],[2,1.74,6.7]],"ltp":2.32,"tv":70.18,"id":31379}]}]}
{"op":"mcm","clk":"11857229274","pt":1723367451437,"mc":[{"id":"1.231582255","rc":[{"batb":[[0,2.36,4],[1,2.34,10],[2,2.32,13.64]],"ltp":2.32,"tv":70.18,"id":31379}]}]}
{"op":"mcm","clk":"11857229419","pt":1723367452777,"mc":[{"id":"1.231582255","rc":[{"batb":[[1,2.32,13.64],[2,2.3,13.85]],"ltp":2.32,"tv":70.18,"id":31379}]}]}
{"op":"mcm","clk":"11857229580","pt":1723367454232,"mc":[{"id":"1.231582255","rc":[{"batb":[[0,2.3,13.85],[1,2.28,5],[2,1.74,6.7]],"ltp":2.32,"tv":70.18,"id":31379}]}]}
{"op":"mcm","clk":"11857229806","pt":1723367456366,"mc":[{"id":"1.231582255","rc":[{"batb":[[0,2.32,14],[1,2.3,13.85],[2,2.28,5]],"ltp":2.32,"tv":70.18,"id":31379}]}]}
{"op":"mcm","clk":"11857230115","pt":1723367459173,"mc":[{"id":"1.231582255","rc":[{"batb":[[0,2.32,10]],"ltp":2.32,"tv":70.18,"id":31379}]}]}
{"op":"mcm","clk":"11857230205","pt":1723367460061,"mc":[{"id":"1.231582255","rc":[{"batb":[[0,2.3,13.85],[1,2.28,5],[2,1.74,6.7]],"ltp":2.32,"tv":70.18,"id":31379}]}]}
{"op":"mcm","clk":"11857230371","pt":1723367461467,"mc":[{"id":"1.231582255","rc":[{"batb":[[0,2.32,4],[1,2.3,13.85],[2,2.28,5]],"ltp":2.32,"tv":70.18,"id":31379}]}]}
{"op":"mcm","clk":"11857230623","pt":1723367463287,"mc":[{"id":"1.231582255","rc":[{"batb":[[0,2.34,10],[1,2.32,17.64],[2,2.3,13.85]],"ltp":2.32,"tv":70.18,"id":31379}]}]}
{"op":"mcm","clk":"11857230761","pt":1723367464376,"mc":[{"id":"1.231582255","rc":[{"batb":[[1,2.32,13.64]],"ltp":2.32,"tv":70.18,"id":31379}]}]}
{"op":"mcm","clk":"11857231057","pt":1723367466867,"mc":[{"id":"1.231582255","rc":[{"batb":[[0,2.34,4],[1,2.3,13.85],[2,1.74,6.7]],"ltp":2.32,"tv":70.18,"id":31379}]}]}
{"op":"mcm","clk":"11857231333","pt":1723367469264,"mc":[{"id":"1.231582255","rc":[{"batb":[[0,2.32,13.64]],"ltp":2.32,"tv":70.18,"id":31379}]}]}
{"op":"mcm","clk":"11857231456","pt":1723367470299,"mc":[{"id":"1.231582255","rc":[{"batb":[[0,2.34,10]],"ltp":2.32,"tv":70.18,"id":31379}]}]}
{"op":"mcm","clk":"11857231517","pt":1723367470869,"mc":[{"id":"1.231582255","rc":[{"batb":[[2,2.28,5]],"ltp":2.32,"tv":70.18,"id":31379}]}]}
{"op":"mcm","clk":"11857231654","pt":1723367472269,"mc":[{"id":"1.231582255","rc":[{"batb":[[1,2.32,13.64],[2,2.3,13.85]],"ltp":2.32,"tv":70.18,"id":31379}]}]}
{"op":"mcm","clk":"11857231683","pt":1723367472576,"mc":[{"id":"1.231582255","rc":[{"batb":[[0,2.36,4],[1,2.34,10],[2,2.32,13.64]],"ltp":2.32,"tv":70.18,"id":31379}]}]}
{"op":"mcm","clk":"11857231834","pt":1723367473872,"mc":[{"id":"1.231582255","rc":[{"batb":[[1,2.32,13.64],[2,2.3,13.85]],"ltp":2.32,"tv":70.18,"id":31379}]}]}
{"op":"mcm","clk":"11857232000","pt":1723367475295,"mc":[{"id":"1.231582255","rc":[{"batb":[[0,2.3,13.85],[1,2.28,5],[2,1.74,6.7]],"ltp":2.32,"tv":70.18,"id":31379}]}]}
{"op":"mcm","clk":"11857232266","pt":1723367477494,"mc":[{"id":"1.231582255","rc":[{"batb":[[0,2.32,14],[1,2.3,13.85],[2,2.28,5]],"ltp":2.32,"tv":70.18,"id":31379}]}]}
{"op":"mcm","clk":"11857232557","pt":1723367479990,"mc":[{"id":"1.231582255","rc":[{"batb":[[0,2.32,10]],"ltp":2.32,"tv":70.18,"id":31379}]}]}
{"op":"mcm","clk":"11857232709","pt":1723367481185,"mc":[{"id":"1.231582255","rc":[{"batb":[[0,2.3,13.85],[1,2.28,5],[2,1.74,6.7]],"ltp":2.32,"tv":70.18,"id":31379}]}]}
{"op":"mcm","clk":"11857233327","pt":1723367487307,"mc":[{"id":"1.231582255","rc":[{"batb":[[0,2.32,14],[1,2.3,13.85],[2,2.28,5]],"ltp":2.32,"tv":70.18,"id":31379}]}]}
{"op":"mcm","clk":"11857233577","pt":1723367489695,"mc":[{"id":"1.231582255","rc":[{"batb":[[0,2.32,10]],"ltp":2.32,"tv":70.18,"id":31379}]}]}
{"op":"mcm","clk":"11857233673","pt":1723367490682,"mc":[{"id":"1.231582255","rc":[{"batb":[[0,2.3,13.85],[1,2.28,5],[2,1.74,6.7]],"ltp":2.32,"tv":70.18,"id":31379}]}]}
{"op":"mcm","clk":"11857233816","pt":1723367492088,"mc":[{"id":"1.231582255","rc":[{"batb":[[0,2.32,4],[1,2.3,13.85],[2,2.28,5]],"ltp":2.32,"tv":70.18,"id":31379}]}]}
{"op":"mcm","clk":"11857234152","pt":1723367495086,"mc":[{"id":"1.231582255","rc":[{"batb":[[0,2.32,10]],"ltp":2.32,"tv":70.18,"id":31379}]}]}
{"op":"mcm","clk":"11857234628","pt":1723367499440,"mc":[{"id":"1.231582255","rc":[{"batb":[[0,2.32,4]],"ltp":2.32,"tv":70.18,"id":31379}]}]}
{"op":"mcm","clk":"11857235002","pt":1723367502412,"mc":[{"id":"1.231582255","rc":[{"batb":[[0,2.32,10]],"ltp":2.32,"tv":70.18,"id":31379}]}]}
{"op":"mcm","clk":"11857235492","pt":1723367506357,"mc":[{"id":"1.231582255","rc":[{"batb":[[0,2.34,4],[1,2.32,13.64],[2,2.3,13.85]],"ltp":2.32,"tv":70.18,"id":31379}]}]}
{"op":"mcm","clk":"11857235717","pt":1723367508228,"mc":[{"id":"1.231582255","rc":[{"batb":[[0,2.32,13.64],[1,2.3,13.85],[2,2.28,5]],"ltp":2.32,"tv":70.18,"id":31379}]}]}
{"op":"mcm","clk":"11857235753","pt":1723367508537,"mc":[{"id":"1.231582255","rc":[{"batb":[[0,2.34,10],[1,2.32,13.64],[2,2.3,13.85]],"ltp":2.32,"tv":70.18,"id":31379}]}]}
{"op":"mcm","clk":"11857236063","pt":1723367511238,"mc":[{"id":"1.231582255","rc":[{"batb":[[0,2.36,4],[1,2.34,10],[2,2.32,13.64]],"ltp":2.32,"tv":70.18,"id":31379}]}]}
{"op":"mcm","clk":"11857236134","pt":1723367511914,"mc":[{"id":"1.231582255","rc":[{"batb":[[1,2.32,13.64],[2,2.3,13.85]],"ltp":2.32,"tv":70.18,"id":31379}]}]}
{"op":"mcm","clk":"11857236316","pt":1723367513519,"mc":[{"id":"1.231582255","rc":[{"batb":[[0,2.32,13.64],[1,2.3,13.85],[2,1.74,6.7]],"ltp":2.32,"tv":70.18,"id":31379}]}]}
{"op":"mcm","clk":"11857236361","pt":1723367513934,"mc":[{"id":"1.231582255","rc":[{"batb":[[0,2.3,13.85],[1,1.74,6.7],[2,1.3,1000]],"ltp":2.32,"tv":70.18,"id":31379}]}]}
{"op":"mcm","clk":"11857236608","pt":1723367516364,"mc":[{"id":"1.231582255","rc":[{"batb":[[0,2.32,14],[1,2.3,13.85],[2,2.28,5]],"ltp":2.32,"tv":70.18,"id":31379}]}]}
{"op":"mcm","clk":"11857236861","pt":1723367518643,"mc":[{"id":"1.231582255","rc":[{"batb":[[0,2.32,10]],"ltp":2.32,"tv":70.18,"id":31379}]}]}
{"op":"mcm","clk":"11857236973","pt":1723367519630,"mc":[{"id":"1.231582255","rc":[{"batb":[[0,2.3,13.85],[1,2.28,5],[2,1.74,6.7]],"ltp":2.32,"tv":70.18,"id":31379}]}]}
{"op":"mcm","clk":"11857237490","pt":1723367523950,"mc":[{"id":"1.231582255","rc":[{"batb":[[0,2.32,14],[1,2.3,13.85],[2,2.28,5]],"ltp":2.32,"tv":70.18,"id":31379}]}]}
{"op":"mcm","clk":"11857237798","pt":1723367526344,"mc":[{"id":"1.231582255","rc":[{"batb":[[2,1.74,6.7]],"ltp":2.32,"tv":70.18,"id":31379}]}]}
{"op":"mcm","clk":"11857237848","pt":1723367526765,"mc":[{"id":"1.231582255","rc":[{"batb":[[0,2.32,10]],"ltp":2.32,"tv":70.18,"id":31379}]}]}
{"op":"mcm","clk":"11857238009","pt":1723367528038,"mc":[{"id":"1.231582255","rc":[{"batb":[[0,2.3,13.85],[1,1.74,6.7],[2,1.3,1000]],"ltp":2.32,"tv":70.18,"id":31379}]}]}
{"op":"mcm","clk":"11857238464","pt":1723367531436,"mc":[{"id":"1.231582255","rc":[{"batb":[[0,2.32,14],[1,2.3,13.85],[2,2.28,5]],"ltp":2.32,"tv":70.18,"id":31379}]}]}
{"op":"mcm","clk":"11857238758","pt":1723367533863,"mc":[{"id":"1.231582255","rc":[{"batb":[[0,2.32,10]],"ltp":2.32,"tv":70.18,"id":31379}]}]}
{"op":"mcm","clk":"11857238869","pt":1723367534848,"mc":[{"id":"1.231582255","rc":[{"batb":[[0,2.3,13.85],[1,2.28,5],[2,1.74,6.7]],"ltp":2.32,"tv":70.18,"id":31379}]}]}
{"op":"mcm","clk":"11857238995","pt":1723367536137,"mc":[{"id":"1.231582255","rc":[{"batb":[[0,2.32,4],[1,2.3,13.85],[2,2.28,5]],"ltp":2.32,"tv":70.18,"id":31379}]}]}
{"op":"mcm","clk":"11857239284","pt":1723367538751,"mc":[{"id":"1.231582255","rc":[{"batb":[[0,2.3,13.85],[1,2.28,5],[2,1.74,6.7]],"ltp":2.32,"tv":70.18,"id":31379}]}]}
{"op":"mcm","clk":"11857239458","pt":1723367540143,"mc":[{"id":"1.231582255","rc":[{"batb":[[0,2.32,10],[1,2.3,13.85],[2,2.28,5]],"ltp":2.32,"tv":70.18,"id":31379}]}]}
{"op":"mcm","clk":"11857239603","pt":1723367541385,"mc":[{"id":"1.231582255","rc":[{"batb":[[0,2.34,4],[1,2.32,10],[2,2.3,13.85]],"ltp":2.32,"tv":70.18,"id":31379}]}]}
{"op":"mcm","clk":"11857239743","pt":1723367542368,"mc":[{"id":"1.231582255","rc":[{"batb":[[1,2.32,23.64]],"ltp":2.32,"tv":70.18,"id":31379}]}]}
{"op":"mcm","clk":"11857240011","pt":1723367544385,"mc":[{"id":"1.231582255","rc":[{"batb":[[0,2.3,13.85],[1,1.74,6.7],[2,1.3,1000]],"ltp":2.32,"tv":70.18,"id":31379}]}]}
{"op":"mcm","clk":"11857240210","pt":1723367546348,"mc":[{"id":"1.231582255","rc":[{"batb":[[1,2.28,5],[2,1.74,6.7]],"ltp":2.32,"tv":70.18,"id":31379}]}]}
{"op":"mcm","clk":"11857240237","pt":1723367546561,"mc":[{"id":"1.231582255","rc":[{"batb":[[0,2.32,14],[1,2.3,13.85],[2,2.28,5]],"ltp":2.32,"tv":70.18,"id":31379}]}]}
{"op":"mcm","clk":"11857240485","pt":1723367548844,"mc":[{"id":"1.231582255","rc":[{"batb":[[0,2.32,10]],"ltp":2.32,"tv":70.18,"id":31379}]}]}
{"op":"mcm","clk":"11857240603","pt":1723367549985,"mc":[{"id":"1.231582255","rc":[{"batb":[[0,2.3,13.85],[1,2.28,5],[2,1.74,6.7]],"ltp":2.32,"tv":70.18,"id":31379}]}]}
{"op":"mcm","clk":"11857241041","pt":1723367553884,"mc":[{"id":"1.231582255","rc":[{"batb":[[0,2.32,14],[1,2.3,13.85],[2,2.28,5]],"ltp":2.32,"tv":70.18,"id":31379}]}]}
{"op":"mcm","clk":"11857241356","pt":1723367556478,"mc":[{"id":"1.231582255","rc":[{"batb":[[0,2.32,10],[2,1.74,6.7]],"ltp":2.32,"tv":70.18,"id":31379}]}]}
{"op":"mcm","clk":"11857241463","pt":1723367557303,"mc":[{"id":"1.231582255","rc":[{"batb":[[0,2.3,13.85],[1,1.74,6.7],[2,1.3,1000]],"ltp":2.32,"tv":70.18,"id":31379}]}]}
{"op":"mcm","clk":"11857241855","pt":1723367560706,"mc":[{"id":"1.231582255","rc":[{"batb":[[0,2.32,14],[1,2.3,13.85],[2,1.74,6.7]],"ltp":2.32,"tv":70.18,"id":31379}]}]}
{"op":"mcm","clk":"11857242178","pt":1723367563420,"mc":[{"id":"1.231582255","rc":[{"batb":[[0,2.32,10]],"ltp":2.32,"tv":70.18,"id":31379}]}]}
{"op":"mcm","clk":"11857242272","pt":1723367564197,"mc":[{"id":"1.231582255","rc":[{"batb":[[0,2.3,13.85],[1,1.74,6.7],[2,1.3,1000]],"ltp":2.32,"tv":70.18,"id":31379}]}]}
{"op":"mcm","clk":"11857242500","pt":1723367566488,"mc":[{"id":"1.231582255","rc":[{"batb":[[1,2.28,5],[2,1.74,6.7]],"ltp":2.32,"tv":70.18,"id":31379}]}]}
{"op":"mcm","clk":"11857242547","pt":1723367566897,"mc":[{"id":"1.231582255","rc":[{"batb":[[0,2.32,14],[1,2.3,13.85],[2,2.28,5]],"ltp":2.32,"tv":70.18,"id":31379}]}]}
{"op":"mcm","clk":"11857242829","pt":1723367569390,"mc":[{"id":"1.231582255","rc":[{"batb":[[0,2.32,10]],"ltp":2.32,"tv":70.18,"id":31379}]}]}
{"op":"mcm","clk":"11857242940","pt":1723367570418,"mc":[{"id":"1.231582255","rc":[{"batb":[[0,2.3,13.85],[1,2.28,5],[2,1.74,6.7]],"ltp":2.32,"tv":70.18,"id":31379}]}]}
{"op":"mcm","clk":"11857244185","pt":1723367580308,"mc":[{"id":"1.231582255","rc":[{"batb":[[0,2.32,14],[1,2.3,13.85],[2,2.28,5]],"ltp":2.32,"tv":70.18,"id":31379}]}]}
{"op":"mcm","clk":"11857244361","pt":1723367581627,"mc":[{"id":"1.231582255","rc":[{"batb":[[2,1.74,6.7]],"ltp":2.32,"tv":70.18,"id":31379}]}]}
{"op":"mcm","clk":"11857244593","pt":1723367583440,"mc":[{"id":"1.231582255","rc":[{"batb":[[0,2.32,10]],"ltp":2.32,"tv":70.18,"id":31379}]}]}
{"op":"mcm","clk":"11857244738","pt":1723367584532,"mc":[{"id":"1.231582255","rc":[{"batb":[[0,2.3,13.85],[1,1.74,6.7],[2,1.3,1000]],"ltp":2.32,"tv":70.18,"id":31379}]}]}
{"op":"mcm","clk":"11857244874","pt":1723367585645,"mc":[{"id":"1.231582255","rc":[{"batb":[[0,2.32,4],[1,2.3,13.85],[2,1.74,6.7]],"ltp":2.32,"tv":70.18,"id":31379}]}]}
{"op":"mcm","clk":"11857245079","pt":1723367587436,"mc":[{"id":"1.231582255","rc":[{"batb":[[0,2.34,10],[1,2.32,17.64],[2,2.3,13.85]],"ltp":2.32,"tv":70.18,"id":31379}]}]}
{"op":"mcm","clk":"11857245182","pt":1723367588317,"mc":[{"id":"1.231582255","rc":[{"batb":[[1,2.32,13.64]],"ltp":2.32,"tv":70.18,"id":31379}]}]}
{"op":"mcm","clk":"11857245427","pt":1723367590506,"mc":[{"id":"1.231582255","rc":[{"batb":[[0,2.34,4],[1,2.3,13.85],[2,2.28,5]],"ltp":2.32,"tv":70.18,"id":31379}]}]}
{"op":"mcm","clk":"11857245638","pt":1723367592320,"mc":[{"id":"1.231582255","rc":[{"batb":[[1,2.32,13.64],[2,2.3,13.85]],"ltp":2.32,"tv":70.18,"id":31379}]}]}
{"op":"mcm","clk":"11857245764","pt":1723367593251,"mc":[{"id":"1.231582255","rc":[{"batb":[[0,2.36,10]],"ltp":2.32,"tv":70.18,"id":31379}]}]}
{"op":"mcm","clk":"11857246348","pt":1723367598444,"mc":[{"id":"1.231582255","rc":[{"batb":[[0,2.34,4],[1,2.3,13.85],[2,1.74,6.7]],"ltp":2.32,"tv":70.18,"id":31379}]}]}
{"op":"mcm","clk":"11857246559","pt":1723367600361,"mc":[{"id":"1.231582255","rc":[{"batb":[[0,2.36,10],[1,2.34,4],[2,2.32,13.64]],"ltp":2.32,"tv":70.18,"id":31379}]}]}
{"op":"mcm","clk":"11857246741","pt":1723367601838,"mc":[{"id":"1.231582255","rc":[{"batb":[[1,2.32,13.64],[2,2.3,13.85]],"ltp":2.32,"tv":70.18,"id":31379}]}]}
{"op":"mcm","clk":"11857247054","pt":1723367604263,"mc":[{"id":"1.231582255","rc":[{"batb":[[0,2.32,13.64],[1,2.3,13.85],[2,1.74,6.7]],"ltp":2.32,"tv":70.18,"id":31379}]}]}
{"op":"mcm","clk":"11857247126","pt":1723367604835,"mc":[{"id":"1.231582255","rc":[{"batb":[[0,2.3,13.85],[1,1.74,6.7],[2,1.3,1000]],"ltp":2.32,"tv":70.18,"id":31379}]}]}
{"op":"mcm","clk":"11857247216","pt":1723367605558,"mc":[{"id":"1.231582255","rc":[{"batb":[[0,2.34,4],[1,2.3,13.85],[2,1.74,6.7]],"ltp":2.32,"tv":70.18,"id":31379}]}]}
{"op":"mcm","clk":"11857247418","pt":1723367607323,"mc":[{"id":"1.231582255","rc":[{"batb":[[0,2.36,10],[1,2.34,4],[2,2.32,13.64]],"ltp":2.32,"tv":70.18,"id":31379}]}]}
{"op":"mcm","clk":"11857247622","pt":1723367609344,"mc":[{"id":"1.231582255","rc":[{"batb":[[1,2.32,13.64],[2,2.3,13.85]],"ltp":2.32,"tv":70.18,"id":31379}]}]}
{"op":"mcm","clk":"11857247885","pt":1723367611467,"mc":[{"id":"1.231582255","rc":[{"batb":[[0,2.3,13.85],[1,2.28,5],[2,1.74,6.7]],"ltp":2.32,"tv":70.18,"id":31379}]}]}
{"op":"mcm","clk":"11857247936","pt":1723367611833,"mc":[{"id":"1.231582255","rc":[{"batb":[[0,2.34,4],[1,2.3,13.85],[2,2.28,5]],"ltp":2.32,"tv":70.18,"id":31379}]}]}
{"op":"mcm","clk":"11857248273","pt":1723367614382,"mc":[{"id":"1.231582255","rc":[{"batb":[[0,2.36,10],[1,2.34,4],[2,2.32,13.64]],"ltp":2.32,"tv":70.18,"id":31379}]}]}
{"op":"mcm","clk":"11857248323","pt":1723367614747,"mc":[{"id":"1.231582255","rc":[{"batb":[[1,2.32,13.64],[2,2.3,13.85]],"ltp":2.32,"tv":70.18,"id":31379}]}]}
{"op":"mcm","clk":"11857248711","pt":1723367618176,"mc":[{"id":"1.231582255","rc":[{"batb":[[0,2.34,4]],"ltp":2.32,"tv":70.18,"id":31379}]}]}
{"op":"mcm","clk":"11857249056","pt":1723367621093,"mc":[{"id":"1.231582255","rc":[{"batb":[[0,2.34,10]],"ltp":2.32,"tv":70.18,"id":31379}]}]}
{"op":"mcm","clk":"11857249562","pt":1723367625264,"mc":[{"id":"1.231582255","rc":[{"batb":[[0,2.32,13.64],[1,2.3,13.85],[2,1.74,6.7]],"ltp":2.32,"tv":70.18,"id":31379}]}]}
{"op":"mcm","clk":"11857249627","pt":1723367625889,"mc":[{"id":"1.231582255","rc":[{"batb":[[0,2.34,4]],"ltp":2.32,"tv":70.18,"id":31379}]}]}
{"op":"mcm","clk":"11857249725","pt":1723367626768,"mc":[{"id":"1.231582255","rc":[{"batb":[[2,2.28,5]],"ltp":2.32,"tv":70.18,"id":31379}]}]}
{"op":"mcm","clk":"11857249910","pt":1723367628386,"mc":[{"id":"1.231582255","rc":[{"batb":[[0,2.36,10],[1,2.32,13.64],[2,2.3,13.85]],"ltp":2.32,"tv":70.18,"id":31379}]}]}
{"op":"mcm","clk":"11857250200","pt":1723367631148,"mc":[{"id":"1.231582255","rc":[{"batb":[[0,2.32,13.64],[1,2.3,13.85],[2,2.28,5]],"ltp":2.32,"tv":70.18,"id":31379}]}]}
{"op":"mcm","clk":"11857250292","pt":1723367631990,"mc":[{"id":"1.231582255","rc":[{"batb":[[0,2.34,4],[2,1.74,6.7]],"ltp":2.32,"tv":70.18,"id":31379}]}]}
{"op":"mcm","clk":"11857250563","pt":1723367634454,"mc":[{"id":"1.231582255","rc":[{"batb":[[0,2.36,10],[1,2.34,4],[2,2.32,13.64]],"ltp":2.32,"tv":70.18,"id":31379}]}]}
{"op":"mcm","clk":"11857250576","pt":1723367634557,"mc":[{"id":"1.231582255","rc":[{"batb":[[1,2.32,13.64],[2,2.3,13.85]],"ltp":2.32,"tv":70.18,"id":31379}]}]}
{"op":"mcm","clk":"11857250992","pt":1723367638390,"mc":[{"id":"1.231582255","rc":[{"batb":[[0,2.3,13.85],[1,1.74,6.7],[2,1.3,1000]],"ltp":2.32,"tv":70.18,"id":31379}]}]}
{"op":"mcm","clk":"11857251027","pt":1723367638651,"mc":[{"id":"1.231582255","rc":[{"batb":[[0,2.34,4],[1,2.3,13.85],[2,1.74,6.7]],"ltp":2.32,"tv":70.18,"id":31379}]}]}
{"op":"mcm","clk":"11857251228","pt":1723367640357,"mc":[{"id":"1.231582255","rc":[{"batb":[[0,2.36,10],[1,2.34,4],[2,2.32,13.64]],"ltp":2.32,"tv":70.18,"id":31379}]}]}
{"op":"mcm","clk":"11857251325","pt":1723367641190,"mc":[{"id":"1.231582255","rc":[{"batb":[[1,2.32,13.64],[2,2.3,13.85]],"ltp":2.32,"tv":70.18,"id":31379}]}]}
{"op":"mcm","clk":"11857251721","pt":1723367644303,"mc":[{"id":"1.231582255","rc":[{"batb":[[0,2.32,13.64],[1,2.3,13.85],[2,1.74,6.7]],"ltp":2.32,"tv":70.18,"id":31379}]}]}
{"op":"mcm","clk":"11857251817","pt":1723367645181,"mc":[{"id":"1.231582255","rc":[{"batb":[[0,2.34,4]],"ltp":2.32,"tv":70.18,"id":31379}]}]}
{"op":"mcm","clk":"11857252097","pt":1723367647475,"mc":[{"id":"1.231582255","rc":[{"batb":[[0,2.36,10],[1,2.32,13.64],[2,2.3,13.85]],"ltp":2.32,"tv":70.18,"id":31379}]}]}
{"op":"mcm","clk":"11857252457","pt":1723367650497,"mc":[{"id":"1.231582255","rc":[{"batb":[[0,2.34,4]],"ltp":2.32,"tv":70.18,"id":31379}]}]}
{"op":"mcm","clk":"11857252726","pt":1723367652976,"mc":[{"id":"1.231582255","rc":[{"batb":[[0,2.34,10]],"ltp":2.32,"tv":70.18,"id":31379}]}]}
{"op":"mcm","clk":"11857253135","pt":1723367656506,"mc":[{"id":"1.231582255","rc":[{"batb":[[0,2.34,4],[1,2.3,13.85],[2,1.74,6.7]],"ltp":2.32,"tv":70.18,"id":31379}]}]}
{"op":"mcm","clk":"11857253198","pt":1723367656975,"mc":[{"id":"1.231582255","rc":[{"batb":[[2,2.28,5]],"ltp":2.32,"tv":70.18,"id":31379}]}]}
{"op":"mcm","clk":"11857253373","pt":1723367658482,"mc":[{"id":"1.231582255","rc":[{"batb":[[0,2.36,10],[1,2.34,4],[2,2.32,13.64]],"ltp":2.32,"tv":70.18,"id":31379}]}]}
{"op":"mcm","clk":"11857253385","pt":1723367658585,"mc":[{"id":"1.231582255","rc":[{"batb":[[1,2.32,13.64],[2,2.3,13.85]],"ltp":2.32,"tv":70.18,"id":31379}]}]}
{"op":"mcm","clk":"11857253795","pt":1723367662012,"mc":[{"id":"1.231582255","rc":[{"batb":[[0,2.34,4],[1,2.3,13.85],[2,1.74,6.7]],"ltp":2.32,"tv":70.18,"id":31379}]}]}
{"op":"mcm","clk":"11857254098","pt":1723367664400,"mc":[{"id":"1.231582255","rc":[{"batb":[[0,2.32,13.64]],"ltp":2.32,"tv":70.18,"id":31379}]}]}
{"op":"mcm","clk":"11857254176","pt":1723367665021,"mc":[{"id":"1.231582255","rc":[{"batb":[[0,2.34,10]],"ltp":2.32,"tv":70.18,"id":31379}]}]}
{"op":"mcm","clk":"11857254471","pt":1723367667515,"mc":[{"id":"1.231582255","rc":[{"batb":[[0,2.36,4],[1,2.34,10],[2,2.32,13.64]],"ltp":2.32,"tv":70.18,"id":31379}]}]}
{"op":"mcm","clk":"11857254582","pt":1723367668507,"mc":[{"id":"1.231582255","rc":[{"batb":[[1,2.32,13.64],[2,2.3,13.85]],"ltp":2.32,"tv":70.18,"id":31379}]}]}
{"op":"mcm","clk":"11857254785","pt":1723367670428,"mc":[{"id":"1.231582255","rc":[{"batb":[[0,2.3,13.85],[1,2.28,5],[2,1.74,6.7]],"ltp":2.32,"tv":70.18,"id":31379}]}]}
{"op":"mcm","clk":"11857254951","pt":1723367671939,"mc":[{"id":"1.231582255","rc":[{"batb":[[0,2.32,10],[1,2.3,13.85],[2,2.28,5]],"ltp":2.32,"tv":70.18,"id":31379}]}]}
{"op":"mcm","clk":"11857255087","pt":1723367672927,"mc":[{"id":"1.231582255","rc":[{"batb":[[0,2.34,4],[1,2.32,10],[2,2.3,13.85]],"ltp":2.32,"tv":70.18,"id":31379}]}]}
{"op":"mcm","clk":"11857255273","pt":1723367674381,"mc":[{"id":"1.231582255","rc":[{"batb":[[1,2.32,23.64]],"ltp":2.32,"tv":70.18,"id":31379}]}]}
{"op":"mcm","clk":"11857255522","pt":1723367676519,"mc":[{"id":"1.231582255","rc":[{"batb":[[0,2.3,13.85],[1,2.28,5],[2,1.74,6.7]],"ltp":2.32,"tv":70.18,"id":31379}]}]}
{"op":"mcm","clk":"11857255858","pt":1723367679633,"mc":[{"id":"1.231582255","rc":[{"batb":[[0,2.32,14],[1,2.3,13.85],[2,2.28,5]],"ltp":2.32,"tv":70.18,"id":31379}]}]}
{"op":"mcm","clk":"11857256178","pt":1723367682347,"mc":[{"id":"1.231582255","rc":[{"batb":[[0,2.32,10],[2,1.74,6.7]],"ltp":2.32,"tv":70.18,"id":31379}]}]}
{"op":"mcm","clk":"11857256312","pt":1723367683335,"mc":[{"id":"1.231582255","rc":[{"batb":[[0,2.3,13.85],[1,1.74,6.7],[2,1.3,1000]],"ltp":2.32,"tv":70.18,"id":31379}]}]}
{"op":"mcm","clk":"11857256726","pt":1723367687318,"mc":[{"id":"1.231582255","rc":[{"batb":[[0,2.32,14],[1,2.3,13.85],[2,2.28,5]],"ltp":2.32,"tv":70.18,"id":31379}]}]}
{"op":"mcm","clk":"11857257020","pt":1723367690039,"mc":[{"id":"1.231582255","rc":[{"batb":[[0,2.32,10]],"ltp":2.32,"tv":70.18,"id":31379}]}]}
{"op":"mcm","clk":"11857257129","pt":1723367690922,"mc":[{"id":"1.231582255","rc":[{"batb":[[0,2.3,13.85],[1,2.28,5],[2,1.74,6.7]],"ltp":2.32,"tv":70.18,"id":31379}]}]}
{"op":"mcm","clk":"11857257405","pt":1723367693458,"mc":[{"id":"1.231582255","rc":[{"batb":[[0,2.32,14],[1,2.3,13.85],[2,2.28,5]],"ltp":2.32,"tv":70.18,"id":31379}]}]}
{"op":"mcm","clk":"11857257715","pt":1723367696255,"mc":[{"id":"1.231582255","rc":[{"batb":[[0,2.32,10]],"ltp":2.32,"tv":70.18,"id":31379}]}]}
{"op":"mcm","clk":"11857257824","pt":1723367697237,"mc":[{"id":"1.231582255","rc":[{"batb":[[0,2.3,13.85],[1,2.28,5],[2,1.74,6.7]],"ltp":2.32,"tv":70.18,"id":31379}]}]}
{"op":"mcm","clk":"11857259068","pt":1723367707248,"mc":[{"id":"1.231582255","rc":[{"batb":[[0,2.32,14],[1,2.3,13.85],[2,2.28,5]],"ltp":2.32,"tv":70.18,"id":31379}]}]}
{"op":"mcm","clk":"11857259396","pt":1723367709759,"mc":[{"id":"1.231582255","rc":[{"batb":[[0,2.32,10]],"ltp":2.32,"tv":70.18,"id":31379}]}]}
{"op":"mcm","clk":"11857259562","pt":1723367710850,"mc":[{"id":"1.231582255","rc":[{"batb":[[0,2.3,13.85],[1,2.28,5],[2,1.74,6.7]],"ltp":2.32,"tv":70.18,"id":31379}]}]}
{"op":"mcm","clk":"11857260469","pt":1723367717548,"mc":[{"id":"1.231582255","rc":[{"batb":[[0,2.32,14],[1,2.3,13.85],[2,2.28,5]],"ltp":2.32,"tv":70.18,"id":31379}]}]}
{"op":"mcm","clk":"11857261095","pt":1723367722361,"mc":[{"id":"1.231582255","rc":[{"batb":[[2,1.74,6.7]],"ltp":2.32,"tv":70.18,"id":31379}]}]}
{"op":"mcm","clk":"11857261120","pt":1723367722569,"mc":[{"id":"1.231582255","rc":[{"batb":[[0,2.32,10]],"ltp":2.32,"tv":70.18,"id":31379}]}]}
{"op":"mcm","clk":"11857261293","pt":1723367723670,"mc":[{"id":"1.231582255","rc":[{"batb":[[0,2.3,13.85],[1,1.74,6.7],[2,1.3,1000]],"ltp":2.32,"tv":70.18,"id":31379}]}]}
{"op":"mcm","clk":"11857261585","pt":1723367725634,"mc":[{"id":"1.231582255","rc":[{"batb":[[0,2.32,4],[1,2.3,13.85],[2,1.74,6.7]],"ltp":2.32,"tv":70.18,"id":31379}]}]}
{"op":"mcm","clk":"11857261809","pt":1723367727452,"mc":[{"id":"1.231582255","rc":[{"batb":[[0,2.34,10],[1,2.32,17.64],[2,2.3,13.85]],"ltp":2.32,"tv":70.18,"id":31379}]}]}
{"op":"mcm","clk":"11857261996","pt":1723367728959,"mc":[{"id":"1.231582255","rc":[{"batb":[[1,2.32,13.64]],"ltp":2.32,"tv":70.18,"id":31379}]}]}
{"op":"mcm","clk":"11857262281","pt":1723367731488,"mc":[{"id":"1.231582255","rc":[{"batb":[[0,2.34,4],[1,2.3,13.85],[2,1.74,6.7]],"ltp":2.32,"tv":70.18,"id":31379}]}]}
{"op":"mcm","clk":"11857262391","pt":1723367732375,"mc":[{"id":"1.231582255","rc":[{"batb":[[2,2.28,5]],"ltp":2.32,"tv":70.18,"id":31379}]}]}
{"op":"mcm","clk":"11857262548","pt":1723367733463,"mc":[{"id":"1.231582255","rc":[{"batb":[[1,2.32,13.64],[2,2.3,13.85]],"ltp":2.32,"tv":70.18,"id":31379}]}]}
{"op":"mcm","clk":"11857262630","pt":1723367734090,"mc":[{"id":"1.231582255","rc":[{"batb":[[0,2.36,10],[1,2.3,13.85],[2,2.28,5]],"ltp":2.32,"tv":70.18,"id":31379}]}]}
{"op":"mcm","clk":"11857262893","pt":1723367736478,"mc":[{"id":"1.231582255","rc":[{"batb":[[1,2.32,13.64],[2,2.3,13.85]],"ltp":2.32,"tv":70.18,"id":31379}]}]}
{"op":"mcm","clk":"11857263014","pt":1723367737459,"mc":[{"id":"1.231582255","rc":[{"batb":[[0,2.32,13.64],[1,2.3,13.85],[2,1.74,6.7]],"ltp":2.32,"tv":70.18,"id":31379}]}]}
{"op":"mcm","clk":"11857263119","pt":1723367738293,"mc":[{"id":"1.231582255","rc":[{"batb":[[0,2.34,4]],"ltp":2.32,"tv":70.18,"id":31379}]}]}
{"op":"mcm","clk":"11857263360","pt":1723367740475,"mc":[{"id":"1.231582255","rc":[{"batb":[[1,2.32,13.64],[2,2.3,13.85]],"ltp":2.32,"tv":70.18,"id":31379}]}]}
{"op":"mcm","clk":"11857263453","pt":1723367741199,"mc":[{"id":"1.231582255","rc":[{"batb":[[0,2.36,10]],"ltp":2.32,"tv":70.18,"id":31379}]}]}
{"op":"mcm","clk":"11857263837","pt":1723367744461,"mc":[{"id":"1.231582255","rc":[{"batb":[[0,2.3,13.85],[1,1.74,6.7],[2,1.3,1000]],"ltp":2.32,"tv":70.18,"id":31379}]}]}
{"op":"mcm","clk":"11857263865","pt":1723367744668,"mc":[{"id":"1.231582255","rc":[{"batb":[[0,2.34,4],[1,2.3,13.85],[2,1.74,6.7]],"ltp":2.32,"tv":70.18,"id":31379}]}]}
{"op":"mcm","clk":"11857264089","pt":1723367746484,"mc":[{"id":"1.231582255","rc":[{"batb":[[0,2.36,10],[1,2.34,4],[2,2.32,13.64]],"ltp":2.32,"tv":70.18,"id":31379}]}]}
{"op":"mcm","clk":"11857264313","pt":1723367748276,"mc":[{"id":"1.231582255","rc":[{"batb":[[1,2.32,13.64],[2,2.3,13.85]],"ltp":2.32,"tv":70.18,"id":31379}]}]}
{"op":"mcm","clk":"11857264582","pt":1723367750499,"mc":[{"id":"1.231582255","rc":[{"batb":[[0,2.3,13.85],[1,1.74,6.7],[2,1.3,1000]],"ltp":2.32,"tv":70.18,"id":31379}]}]}
{"op":"mcm","clk":"11857264668","pt":1723367751281,"mc":[{"id":"1.231582255","rc":[{"batb":[[0,2.34,4],[1,2.3,13.85],[2,1.74,6.7]],"ltp":2.32,"tv":70.18,"id":31379}]}]}
{"op":"mcm","clk":"11857264789","pt":1723367752497,"mc":[{"id":"1.231582255","rc":[{"batb":[[2,2.28,5]],"ltp":2.32,"tv":70.18,"id":31379}]}]}
{"op":"mcm","clk":"11857264919","pt":1723367753502,"mc":[{"id":"1.231582255","rc":[{"batb":[[0,2.36,10],[1,2.34,4],[2,2.32,13.64]],"ltp":2.32,"tv":70.18,"id":31379}]}]}
{"op":"mcm","clk":"11857264977","pt":1723367753918,"mc":[{"id":"1.231582255","rc":[{"batb":[[1,2.32,13.64],[2,2.3,13.85]],"ltp":2.32,"tv":70.18,"id":31379}]}]}
{"op":"mcm","clk":"11857265287","pt":1723367756520,"mc":[{"id":"1.231582255","rc":[{"batb":[[0,2.3,13.85],[1,2.28,5],[2,1.74,6.7]],"ltp":2.32,"tv":70.18,"id":31379}]}]}
{"op":"mcm","clk":"11857265295","pt":1723367756624,"mc":[{"id":"1.231582255","rc":[{"batb":[[0,2.34,4],[1,2.3,13.85],[2,2.28,5]],"ltp":2.32,"tv":70.18,"id":31379}]}]}
{"op":"mcm","clk":"11857265520","pt":1723367758498,"mc":[{"id":"1.231582255","rc":[{"batb":[[1,2.32,13.64],[2,2.3,13.85]],"ltp":2.32,"tv":70.18,"id":31379}]}]}
{"op":"mcm","clk":"11857265590","pt":1723367759075,"mc":[{"id":"1.231582255","rc":[{"batb":[[0,2.36,10]],"ltp":2.32,"tv":70.18,"id":31379}]}]}
{"op":"mcm","clk":"11857266070","pt":1723367763489,"mc":[{"id":"1.231582255","rc":[{"batb":[[0,2.3,13.85],[1,1.74,6.7],[2,1.3,1000]],"ltp":2.32,"tv":70.18,"id":31379}]}]}
{"op":"mcm","clk":"11857266081","pt":1723367763595,"mc":[{"id":"1.231582255","rc":[{"batb":[[0,2.34,4],[1,2.3,13.85],[2,1.74,6.7]],"ltp":2.32,"tv":70.18,"id":31379}]}]}
{"op":"mcm","clk":"11857266321","pt":1723367765514,"mc":[{"id":"1.231582255","rc":[{"batb":[[1,2.32,13.64],[2,2.3,13.85]],"ltp":2.32,"tv":70.18,"id":31379}]}]}
{"op":"mcm","clk":"11857266374","pt":1723367766032,"mc":[{"id":"1.231582255","rc":[{"batb":[[0,2.36,10],[1,2.3,13.85],[2,1.74,6.7]],"ltp":2.32,"tv":70.18,"id":31379}]}]}
{"op":"mcm","clk":"11857266656","pt":1723367768522,"mc":[{"id":"1.231582255","rc":[{"batb":[[1,2.32,13.64],[2,2.3,13.85]],"ltp":2.32,"tv":70.18,"id":31379}]}]}
{"op":"mcm","clk":"11857266760","pt":1723367769511,"mc":[{"id":"1.231582255","rc":[{"batb":[[0,2.3,13.85],[1,2.28,5],[2,1.74,6.7]],"ltp":2.32,"tv":70.18,"id":31379}]}]}
{"op":"mcm","clk":"11857266781","pt":1723367769716,"mc":[{"id":"1.231582255","rc":[{"batb":[[0,2.34,4],[1,2.3,13.85],[2,2.28,5]],"ltp":2.32,"tv":70.18,"id":31379}]}]}
{"op":"mcm","clk":"11857266986","pt":1723367771529,"mc":[{"id":"1.231582255","rc":[{"batb":[[1,2.32,13.64],[2,2.3,13.85]],"ltp":2.32,"tv":70.18,"id":31379}]}]}
{"op":"mcm","clk":"11857267043","pt":1723367772120,"mc":[{"id":"1.231582255","rc":[{"batb":[[0,2.36,10]],"ltp":2.32,"tv":70.18,"id":31379}]}]}
{"op":"mcm","clk":"11857267471","pt":1723367775503,"mc":[{"id":"1.231582255","rc":[{"batb":[[0,2.3,13.85],[1,1.74,6.7],[2,1.3,1000]],"ltp":2.32,"tv":70.18,"id":31379}]}]}
{"op":"mcm","clk":"11857267558","pt":1723367776430,"mc":[{"id":"1.231582255","rc":[{"batb":[[0,2.34,4],[1,2.3,13.85],[2,1.74,6.7]],"ltp":2.32,"tv":70.18,"id":31379}]}]}
{"op":"mcm","clk":"11857267793","pt":1723367778492,"mc":[{"id":"1.231582255","rc":[{"batb":[[0,2.36,10],[1,2.34,4],[2,2.32,13.64]],"ltp":2.32,"tv":70.18,"id":31379}]}]}
{"op":"mcm","clk":"11857267937","pt":1723367779843,"mc":[{"id":"1.231582255","rc":[{"batb":[[1,2.32,13.64],[2,2.3,13.85]],"ltp":2.32,"tv":70.18,"id":31379}]}]}
{"op":"mcm","clk":"11857268178","pt":1723367782018,"mc":[{"id":"1.231582255","rc":[{"batb":[[0,2.34,4],[1,2.3,13.85],[2,2.28,5]],"ltp":2.32,"tv":70.18,"id":31379}]}]}
{"op":"mcm","clk":"11857268473","pt":1723367784512,"mc":[{"id":"1.231582255","rc":[{"batb":[[0,2.32,10]],"ltp":2.32,"tv":70.18,"id":31379}]}]}
{"op":"mcm","clk":"11857268877","pt":1723367788040,"mc":[{"id":"1.231582255","rc":[{"batb":[[0,2.34,4]],"ltp":2.32,"tv":70.18,"id":31379}]}]}
{"op":"mcm","clk":"11857268944","pt":1723367788559,"mc":[{"id":"1.231582255","rc":[{"batb":[[1,2.32,13.64],[2,2.3,13.85]],"ltp":2.32,"tv":70.18,"id":31379}]}]}
{"op":"mcm","clk":"11857269163","pt":1723367790518,"mc":[{"id":"1.231582255","rc":[{"batb":[[0,2.3,13.85],[1,2.28,5],[2,1.74,6.7]],"ltp":2.32,"tv":70.18,"id":31379}]}]}
{"op":"mcm","clk":"11857269195","pt":1723367790826,"mc":[{"id":"1.231582255","rc":[{"batb":[[0,2.34,10],[1,2.3,13.85],[2,2.28,5]],"ltp":2.32,"tv":70.18,"id":31379}]}]}
{"op":"mcm","clk":"11857269402","pt":1723367792955,"mc":[{"id":"1.231582255","rc":[{"batb":[[0,2.36,4],[1,2.34,10],[2,2.32,13.64]],"ltp":2.32,"tv":70.18,"id":31379}]}]}
{"op":"mcm","clk":"11857269536","pt":1723367794147,"mc":[{"id":"1.231582255","rc":[{"batb":[[1,2.32,13.64],[2,2.3,13.85]],"ltp":2.32,"tv":70.18,"id":31379}]}]}
{"op":"mcm","clk":"11857269649","pt":1723367795128,"mc":[{"id":"1.231582255","rc":[{"batb":[[0,2.32,13.64],[1,2.3,13.85],[2,1.74,6.7]],"ltp":2.32,"tv":70.18,"id":31379}]}]}
{"op":"mcm","clk":"11857269796","pt":1723367796424,"mc":[{"id":"1.231582255","rc":[{"batb":[[0,2.34,10]],"ltp":2.32,"tv":70.18,"id":31379}]}]}
{"op":"mcm","clk":"11857269996","pt":1723367798132,"mc":[{"id":"1.231582255","rc":[{"batb":[[0,2.36,4],[1,2.34,10],[2,2.3,13.85]],"ltp":2.32,"tv":70.18,"id":31379}]}]}
{"op":"mcm","clk":"11857270041","pt":1723367798542,"mc":[{"id":"1.231582255","rc":[{"batb":[[2,2.32,13.64]],"ltp":2.32,"tv":70.18,"id":31379}]}]}
{"op":"mcm","clk":"11857270248","pt":1723367800458,"mc":[{"id":"1.231582255","rc":[{"batb":[[0,2.32,13.64],[1,2.3,13.85],[2,2.28,5]],"ltp":2.32,"tv":70.18,"id":31379}]}]}
{"op":"mcm","clk":"11857270313","pt":1723367801029,"mc":[{"id":"1.231582255","rc":[{"batb":[[0,2.3,13.85],[1,2.28,5],[2,1.74,6.7]],"ltp":2.32,"tv":70.18,"id":31379}]}]}
{"op":"mcm","clk":"11857270601","pt":1723367803514,"mc":[{"id":"1.231582255","rc":[{"batb":[[0,2.32,14],[1,2.3,13.85],[2,2.28,5]],"ltp":2.32,"tv":70.18,"id":31379}]}]}
{"op":"mcm","clk":"11857271013","pt":1723367807068,"mc":[{"id":"1.231582255","rc":[{"batb":[[0,2.32,10]],"ltp":2.32,"tv":70.18,"id":31379}]}]}
{"op":"mcm","clk":"11857271143","pt":1723367808159,"mc":[{"id":"1.231582255","rc":[{"batb":[[0,2.3,13.85],[1,2.28,5],[2,1.74,6.7]],"ltp":2.32,"tv":70.18,"id":31379}]}]}
{"op":"mcm","clk":"11857271844","pt":1723367814371,"mc":[{"id":"1.231582255","rc":[{"batb":[[0,2.32,14],[1,2.3,13.85],[2,2.28,5]],"ltp":2.32,"tv":70.18,"id":31379}]}]}
{"op":"mcm","clk":"11857272161","pt":1723367816961,"mc":[{"id":"1.231582255","rc":[{"batb":[[0,2.32,10]],"ltp":2.32,"tv":70.18,"id":31379}]}]}
{"op":"mcm","clk":"11857272289","pt":1723367817842,"mc":[{"id":"1.231582255","rc":[{"batb":[[0,2.3,13.85],[1,2.28,5],[2,1.74,6.7]],"ltp":2.32,"tv":70.18,"id":31379}]}]}
{"op":"mcm","clk":"11857273667","pt":1723367829562,"mc":[{"id":"1.231582255","rc":[{"batb":[[0,2.32,14],[1,2.3,13.85],[2,2.28,5]],"ltp":2.32,"tv":70.18,"id":31379}]}]}
{"op":"mcm","clk":"11857273953","pt":1723367831960,"mc":[{"id":"1.231582255","rc":[{"batb":[[0,2.32,10]],"ltp":2.32,"tv":70.18,"id":31379}]}]}
{"op":"mcm","clk":"11857274100","pt":1723367833055,"mc":[{"id":"1.231582255","rc":[{"batb":[[0,2.3,13.85],[1,2.28,5],[2,1.74,6.7]],"ltp":2.32,"tv":70.18,"id":31379}]}]}
{"op":"mcm","clk":"11857276660","pt":1723367855984,"mc":[{"id":"1.231582255","rc":[{"batb":[[0,2.32,14],[1,2.3,13.85],[2,2.28,5]],"ltp":2.32,"tv":70.18,"id":31379}]}]}
{"op":"mcm","clk":"11857276914","pt":1723367858470,"mc":[{"id":"1.231582255","rc":[{"batb":[[0,2.32,10],[2,1.74,6.7]],"ltp":2.32,"tv":70.18,"id":31379}]}]}
{"op":"mcm","clk":"11857277036","pt":1723367859506,"mc":[{"id":"1.231582255","rc":[{"batb":[[0,2.3,13.85],[1,1.74,6.7],[2,1.3,1000]],"ltp":2.32,"tv":70.18,"id":31379}]}]}
{"op":"mcm","clk":"11857277540","pt":1723367863514,"mc":[{"id":"1.231582255","rc":[{"batb":[[0,2.32,14],[1,2.3,13.85],[2,2.28,5]],"ltp":2.32,"tv":70.18,"id":31379}]}]}
{"op":"mcm","clk":"11857277832","pt":1723367866103,"mc":[{"id":"1.231582255","rc":[{"batb":[[0,2.32,10]],"ltp":2.32,"tv":70.18,"id":31379}]}]}
{"op":"mcm","clk":"11857277952","pt":1723367867295,"mc":[{"id":"1.231582255","rc":[{"batb":[[0,2.3,13.85],[1,2.28,5],[2,1.74,6.7]],"ltp":2.32,"tv":70.18,"id":31379}]}]}
{"op":"mcm","clk":"11857278194","pt":1723367869882,"mc":[{"id":"1.231582255","rc":[{"batb":[[0,2.32,14],[1,2.3,13.85],[2,2.28,5]],"ltp":2.32,"tv":70.18,"id":31379},{"trd":[[1.75,96.67]],"batl":[[0,1.75,16.83]],"ltp":1.75,"tv":117.05,"id":424676}],"tv":187.23}]}
{"op":"mcm","clk":"11857278474","pt":1723367872427,"mc":[{"id":"1.231582255","rc":[{"batb":[[0,2.32,10]],"ltp":2.32,"tv":70.18,"id":31379}]}]}
{"op":"mcm","clk":"11857278565","pt":1723367873304,"mc":[{"id":"1.231582255","rc":[{"batb":[[0,2.3,13.85],[1,2.28,5],[2,1.74,6.7]],"ltp":2.32,"tv":70.18,"id":31379}]}]}
{"op":"mcm","clk":"11857279020","pt":1723367877192,"mc":[{"id":"1.231582255","rc":[{"batb":[[0,2.32,14],[1,2.3,13.85],[2,2.28,5]],"ltp":2.32,"tv":70.18,"id":31379}]}]}
{"op":"mcm","clk":"11857279127","pt":1723367878232,"mc":[{"id":"1.231582255","rc":[{"batb":[[2,1.74,6.7]],"ltp":2.32,"tv":70.18,"id":31379}]}]}
{"op":"mcm","clk":"11857279338","pt":1723367880148,"mc":[{"id":"1.231582255","rc":[{"batb":[[0,2.32,10]],"ltp":2.32,"tv":70.18,"id":31379}]}]}
{"op":"mcm","clk":"11857279445","pt":1723367881033,"mc":[{"id":"1.231582255","rc":[{"batb":[[0,2.3,13.85],[1,1.74,6.7],[2,1.3,1000]],"ltp":2.32,"tv":70.18,"id":31379}]}]}
{"op":"mcm","clk":"11857279693","pt":1723367883200,"mc":[{"id":"1.231582255","rc":[{"batb":[[1,2.28,5],[2,1.74,6.7]],"ltp":2.32,"tv":70.18,"id":31379}]}]}
{"op":"mcm","clk":"11857279772","pt":1723367883931,"mc":[{"id":"1.231582255","rc":[{"batb":[[0,2.32,14],[1,2.3,13.85],[2,2.28,5]],"ltp":2.32,"tv":70.18,"id":31379}]}]}
{"op":"mcm","clk":"11857280077","pt":1723367887042,"mc":[{"id":"1.231582255","rc":[{"batb":[[0,2.32,10]],"ltp":2.32,"tv":70.18,"id":31379}]}]}
{"op":"mcm","clk":"11857280171","pt":1723367887821,"mc":[{"id":"1.231582255","rc":[{"batb":[[0,2.3,13.85],[1,2.28,5],[2,1.74,6.7]],"ltp":2.32,"tv":70.18,"id":31379}]}]}
{"op":"mcm","clk":"11857280420","pt":1723367890212,"mc":[{"id":"1.231582255","rc":[{"batb":[[0,2.34,10],[1,2.32,4],[2,2.3,13.85]],"ltp":2.32,"tv":70.18,"id":31379}]}]}
{"op":"mcm","clk":"11857280548","pt":1723367891498,"mc":[{"id":"1.231582255","rc":[{"batb":[[1,2.32,17.64]],"ltp":2.32,"tv":70.18,"id":31379}]}]}
{"op":"mcm","clk":"11857280625","pt":1723367892220,"mc":[{"id":"1.231582255","rc":[{"batb":[[1,2.32,13.64]],"ltp":2.32,"tv":70.18,"id":31379}]}]}
{"op":"mcm","clk":"11857280809","pt":1723367894028,"mc":[{"id":"1.231582255","rc":[{"batb":[[0,2.3,13.85],[1,1.74,6.7],[2,1.3,1000]],"ltp":2.32,"tv":70.18,"id":31379}]}]}
{"op":"mcm","clk":"11857281037","pt":1723367896347,"mc":[{"id":"1.231582255","rc":[{"batb":[[0,2.32,14],[1,2.3,13.85],[2,1.74,6.7]],"ltp":2.32,"tv":70.18,"id":31379}]}]}
{"op":"mcm","clk":"11857281400","pt":1723367899918,"mc":[{"id":"1.231582255","rc":[{"batb":[[0,2.32,10]],"ltp":2.32,"tv":70.18,"id":31379}]}]}
{"op":"mcm","clk":"11857281506","pt":1723367900845,"mc":[{"id":"1.231582255","rc":[{"batb":[[0,2.3,13.85],[1,1.74,6.7],[2,1.3,1000]],"ltp":2.32,"tv":70.18,"id":31379}]}]}
{"op":"mcm","clk":"11857281792","pt":1723367903331,"mc":[{"id":"1.231582255","rc":[{"batb":[[0,2.32,14],[1,2.3,13.85],[2,2.28,5]],"ltp":2.32,"tv":70.18,"id":31379}]}]}
{"op":"mcm","clk":"11857282112","pt":1723367906231,"mc":[{"id":"1.231582255","rc":[{"batb":[[0,2.32,10]],"ltp":2.32,"tv":70.18,"id":31379}]}]}
{"op":"mcm","clk":"11857282222","pt":1723367907225,"mc":[{"id":"1.231582255","rc":[{"batb":[[0,2.3,13.85],[1,2.28,5],[2,1.74,6.7]],"ltp":2.32,"tv":70.18,"id":31379}]}]}
{"op":"mcm","clk":"11857283162","pt":1723367915934,"mc":[{"id":"1.231582255","rc":[{"batb":[[0,2.32,14],[1,2.3,13.85],[2,2.28,5]],"ltp":2.32,"tv":70.18,"id":31379}]}]}
{"op":"mcm","clk":"11857283445","pt":1723367918379,"mc":[{"id":"1.231582255","rc":[{"batb":[[2,1.74,6.7]],"ltp":2.32,"tv":70.18,"id":31379}]}]}
{"op":"mcm","clk":"11857283576","pt":1723367919473,"mc":[{"id":"1.231582255","rc":[{"batb":[[0,2.32,10]],"ltp":2.32,"tv":70.18,"id":31379}]}]}
{"op":"mcm","clk":"11857283694","pt":1723367920558,"mc":[{"id":"1.231582255","rc":[{"batb":[[0,2.3,13.85],[1,1.74,6.7],[2,1.3,1000]],"ltp":2.32,"tv":70.18,"id":31379}]}]}
{"op":"mcm","clk":"11857283993","pt":1723367923456,"mc":[{"id":"1.231582255","rc":[{"batb":[[0,2.32,4],[1,2.3,13.85],[2,2.28,5]],"ltp":2.32,"tv":70.18,"id":31379}]}]}
{"op":"mcm","clk":"11857284000","pt":1723367923554,"mc":[{"id":"1.231582255","rc":[{"batb":[[0,2.32,14]],"ltp":2.32,"tv":70.18,"id":31379}]}]}
{"op":"mcm","clk":"11857284261","pt":1723367925988,"mc":[{"id":"1.231582255","rc":[{"batb":[[0,2.32,10]],"ltp":2.32,"tv":70.18,"id":31379}]}]}
{"op":"mcm","clk":"11857284396","pt":1723367927185,"mc":[{"id":"1.231582255","rc":[{"batb":[[0,2.3,13.85],[1,2.28,5],[2,1.74,6.7]],"ltp":2.32,"tv":70.18,"id":31379}]}]}
{"op":"mcm","clk":"11857285107","pt":1723367933747,"mc":[{"id":"1.231582255","rc":[{"batb":[[0,2.32,14],[1,2.3,13.85],[2,2.28,5]],"ltp":2.32,"tv":70.18,"id":31379}]}]}
{"op":"mcm","clk":"11857285351","pt":1723367936175,"mc":[{"id":"1.231582255","rc":[{"batb":[[0,2.32,10]],"ltp":2.32,"tv":70.18,"id":31379}]}]}
{"op":"mcm","clk":"11857285472","pt":1723367937367,"mc":[{"id":"1.231582255","rc":[{"batb":[[0,2.3,13.85],[1,2.28,5],[2,1.74,6.7]],"ltp":2.32,"tv":70.18,"id":31379}]}]}
{"op":"mcm","clk":"11857285926","pt":1723367941871,"mc":[{"id":"1.231582255","rc":[{"batb":[[0,2.32,14],[1,2.3,13.85],[2,2.28,5]],"ltp":2.32,"tv":70.18,"id":31379}]}]}
{"op":"mcm","clk":"11857286114","pt":1723367943481,"mc":[{"id":"1.231582255","rc":[{"batb":[[2,1.74,6.7]],"ltp":2.32,"tv":70.18,"id":31379}]}]}
{"op":"mcm","clk":"11857286352","pt":1723367945458,"mc":[{"id":"1.231582255","rc":[{"batb":[[0,2.3,13.85],[1,1.74,6.7],[2,1.3,1000]],"ltp":2.32,"tv":70.18,"id":31379}]}]}
{"op":"mcm","clk":"11857286667","pt":1723367948462,"mc":[{"id":"1.231582255","rc":[{"batb":[[1,2.28,5],[2,1.74,6.7]],"ltp":2.32,"tv":70.18,"id":31379}]}]}
{"op":"mcm","clk":"11857286677","pt":1723367948564,"mc":[{"id":"1.231582255","rc":[{"batb":[[0,2.32,14],[1,2.3,13.85],[2,2.28,5]],"ltp":2.32,"tv":70.18,"id":31379}]}]}
{"op":"mcm","clk":"11857286987","pt":1723367951584,"mc":[{"id":"1.231582255","rc":[{"batb":[[0,2.32,10]],"ltp":2.32,"tv":70.18,"id":31379}]}]}
{"op":"mcm","clk":"11857287099","pt":1723367952619,"mc":[{"id":"1.231582255","rc":[{"batb":[[0,2.3,13.85],[1,2.28,5],[2,1.74,6.7]],"ltp":2.32,"tv":70.18,"id":31379}]}]}
{"op":"mcm","clk":"11857287289","pt":1723367954274,"mc":[{"id":"1.231582255","rc":[{"batb":[[0,2.32,4],[1,2.3,13.85],[2,2.28,5]],"ltp":2.32,"tv":70.18,"id":31379}]}]}
{"op":"mcm","clk":"11857287485","pt":1723367955778,"mc":[{"id":"1.231582255","rc":[{"batb":[[0,2.34,10],[1,2.32,4],[2,2.3,13.85]],"ltp":2.32,"tv":70.18,"id":31379}]}]}
{"op":"mcm","clk":"11857287587","pt":1723367956603,"mc":[{"id":"1.231582255","rc":[{"batb":[[1,2.32,17.64]],"ltp":2.32,"tv":70.18,"id":31379}]}]}
{"op":"mcm","clk":"11857287707","pt":1723367957684,"mc":[{"id":"1.231582255","rc":[{"batb":[[1,2.32,13.64]],"ltp":2.32,"tv":70.18,"id":31379}]}]}
{"op":"mcm","clk":"11857287968","pt":1723367959976,"mc":[{"id":"1.231582255","rc":[{"batb":[[0,2.36,4]],"ltp":2.32,"tv":70.18,"id":31379}]}]}
{"op":"mcm","clk":"11857288331","pt":1723367963095,"mc":[{"id":"1.231582255","rc":[{"batb":[[0,2.32,13.64],[1,2.3,13.85],[2,1.74,6.7]],"ltp":2.32,"tv":70.18,"id":31379}]}]}
{"op":"mcm","clk":"11857288394","pt":1723367963612,"mc":[{"id":"1.231582255","rc":[{"batb":[[0,2.3,13.85],[1,1.74,6.7],[2,1.3,1000]],"ltp":2.32,"tv":70.18,"id":31379}]}]}
{"op":"mcm","clk":"11857288528","pt":1723367964809,"mc":[{"id":"1.231582255","rc":[{"batb":[[0,2.34,10],[1,2.3,13.85],[2,1.74,6.7]],"ltp":2.32,"tv":70.18,"id":31379}]}]}
{"op":"mcm","clk":"11857288664","pt":1723367966000,"mc":[{"id":"1.231582255","rc":[{"batb":[[0,2.36,4],[1,2.34,10],[2,2.3,13.85]],"ltp":2.32,"tv":70.18,"id":31379}]}]}
{"op":"mcm","clk":"11857288744","pt":1723367966630,"mc":[{"id":"1.231582255","rc":[{"batb":[[2,2.32,13.64]],"ltp":2.32,"tv":70.18,"id":31379}]}]}
{"op":"mcm","clk":"11857289138","pt":1723367970393,"mc":[{"id":"1.231582255","rc":[{"batb":[[1,2.32,13.64],[2,2.3,13.85]],"ltp":2.32,"tv":70.18,"id":31379}]}]}
{"op":"mcm","clk":"11857289441","pt":1723367973102,"mc":[{"id":"1.231582255","rc":[{"batb":[[0,2.32,13.64],[1,2.3,13.85],[2,1.74,6.7]],"ltp":2.32,"tv":70.18,"id":31379}]}]}
{"op":"mcm","clk":"11857289560","pt":1723367974034,"mc":[{"id":"1.231582255","rc":[{"trd":[[2.38,0.73]],"batb":[[0,2.38,9.27]],"ltp":2.38,"tv":70.91,"id":31379},{"trd":[[1.73,7.99]],"batb":[[0,1.72,5],[1,1.68,2.52],[2,1.67,20]],"ltp":1.73,"tv":118.05,"id":424676}],"tv":188.96}]}
{"op":"mcm","clk":"11857289864","pt":1723367976638,"mc":[{"id":"1.231582255","rc":[{"batb":[[1,2.32,13.64],[2,2.3,13.85]],"ltp":2.38,"tv":70.91,"id":31379}]}]}
{"op":"mcm","clk":"11857290061","pt":1723367978306,"mc":[{"id":"1.231582255","rc":[{"batb":[[0,2.32,13.64],[1,2.3,13.85],[2,1.74,6.7]],"ltp":2.38,"tv":70.91,"id":31379}]}]}
{"op":"mcm","clk":"11857290101","pt":1723367978620,"mc":[{"id":"1.231582255","rc":[{"batb":[[0,2.3,13.85],[1,1.74,6.7],[2,1.3,1000]],"ltp":2.38,"tv":70.91,"id":31379}]}]}
{"op":"mcm","clk":"11857290262","pt":1723367980221,"mc":[{"id":"1.231582255","rc":[{"batb":[[0,2.34,4],[1,2.3,13.85],[2,1.74,6.7]],"ltp":2.38,"tv":70.91,"id":31379}]}]}
{"op":"mcm","clk":"11857290309","pt":1723367980636,"mc":[{"id":"1.231582255","rc":[{"batb":[[1,2.32,10],[2,2.3,13.85]],"ltp":2.38,"tv":70.91,"id":31379}]}]}
{"op":"mcm","clk":"11857290518","pt":1723367982613,"mc":[{"id":"1.231582255","rc":[{"batb":[[1,2.32,23.64]],"ltp":2.38,"tv":70.91,"id":31379}]}]}
{"op":"mcm","clk":"11857290696","pt":1723367984124,"mc":[{"id":"1.231582255","rc":[{"batb":[[0,2.32,23.64],[1,2.3,13.85],[2,1.74,6.7]],"ltp":2.38,"tv":70.91,"id":31379}]}]}
{"op":"mcm","clk":"11857290840","pt":1723367985424,"mc":[{"id":"1.231582255","rc":[{"batb":[[0,2.3,13.85],[1,1.74,6.7],[2,1.3,1000]],"ltp":2.38,"tv":70.91,"id":31379}]}]}
{"op":"mcm","clk":"11857291244","pt":1723367988847,"mc":[{"id":"1.231582255","rc":[{"batb":[[0,2.32,14],[1,2.3,13.85],[2,2.28,5]],"ltp":2.38,"tv":70.91,"id":31379}]}]}
{"op":"mcm","clk":"11857291526","pt":1723367991446,"mc":[{"id":"1.231582255","rc":[{"batb":[[0,2.32,10]],"ltp":2.38,"tv":70.91,"id":31379}]}]}
{"op":"mcm","clk":"11857291624","pt":1723367992333,"mc":[{"id":"1.231582255","rc":[{"batb":[[0,2.3,13.85],[1,2.28,5],[2,1.74,6.7]],"ltp":2.38,"tv":70.91,"id":31379}]}]}
{"op":"mcm","clk":"11857291998","pt":1723367995646,"mc":[{"id":"1.231582255","rc":[{"batb":[[0,2.32,14],[1,2.3,13.85],[2,2.28,5]],"ltp":2.38,"tv":70.91,"id":31379}]}]}
{"op":"mcm","clk":"11857292257","pt":1723367998028,"mc":[{"id":"1.231582255","rc":[{"batb":[[0,2.32,10]],"ltp":2.38,"tv":70.91,"id":31379}]}]}
{"op":"mcm","clk":"11857292381","pt":1723367999121,"mc":[{"id":"1.231582255","rc":[{"batb":[[0,2.3,13.85],[1,2.28,5],[2,1.74,6.7]],"ltp":2.38,"tv":70.91,"id":31379}]}]}
{"op":"mcm","clk":"11857292581","pt":1723368000866,"mc":[{"id":"1.231582255","rc":[{"batb":[[0,2.32,4],[1,2.3,13.85],[2,2.28,5]],"ltp":2.38,"tv":70.91,"id":31379}]}]}
{"op":"mcm","clk":"11857292652","pt":1723368001539,"mc":[{"id":"1.231582255","rc":[{"batb":[[0,2.34,10],[1,2.32,4],[2,2.3,13.85]],"ltp":2.38,"tv":70.91,"id":31379}]}]}
{"op":"mcm","clk":"11857292864","pt":1723368003358,"mc":[{"id":"1.231582255","rc":[{"batb":[[1,2.3,13.85],[2,2.28,5]],"ltp":2.38,"tv":70.91,"id":31379}]}]}
{"op":"mcm","clk":"11857292905","pt":1723368003670,"mc":[{"id":"1.231582255","rc":[{"batb":[[1,2.32,13.64],[2,2.3,13.85]],"ltp":2.38,"tv":70.91,"id":31379}]}]}
{"op":"mcm","clk":"11857293103","pt":1723368005274,"mc":[{"id":"1.231582255","rc":[{"batb":[[0,2.32,13.64],[1,2.3,13.85],[2,2.28,5]],"ltp":2.38,"tv":70.91,"id":31379}]}]}
{"op":"mcm","clk":"11857293199","pt":1723368006058,"mc":[{"id":"1.231582255","rc":[{"batb":[[0,2.34,4]],"ltp":2.38,"tv":70.91,"id":31379}]}]}
{"op":"mcm","clk":"11857293389","pt":1723368007859,"mc":[{"id":"1.231582255","rc":[{"batb":[[1,2.32,10],[2,2.3,13.85]],"ltp":2.38,"tv":70.91,"id":31379}]}]}
{"op":"mcm","clk":"11857293486","pt":1723368008787,"mc":[{"id":"1.231582255","rc":[{"batb":[[1,2.32,23.64]],"ltp":2.38,"tv":70.91,"id":31379}]}]}
{"op":"mcm","clk":"11857293746","pt":1723368011065,"mc":[{"id":"1.231582255","rc":[{"batb":[[0,2.32,23.64],[1,2.3,13.85],[2,1.74,6.7]],"ltp":2.38,"tv":70.91,"id":31379}]}]}
{"op":"mcm","clk":"11857293808","pt":1723368011684,"mc":[{"id":"1.231582255","rc":[{"batb":[[0,2.32,10]],"ltp":2.38,"tv":70.91,"id":31379}]}]}
{"op":"mcm","clk":"11857294142","pt":1723368014495,"mc":[{"id":"1.231582255","rc":[{"batb":[[0,2.34,4],[2,2.28,5]],"ltp":2.38,"tv":70.91,"id":31379}]}]}
{"op":"mcm","clk":"11857294317","pt":1723368015991,"mc":[{"id":"1.231582255","rc":[{"batb":[[1,2.32,10],[2,2.3,13.85]],"ltp":2.38,"tv":70.91,"id":31379}]}]}
{"op":"mcm","clk":"11857294392","pt":1723368016669,"mc":[{"id":"1.231582255","rc":[{"batb":[[1,2.32,23.64]],"ltp":2.38,"tv":70.91,"id":31379}]}]}
{"op":"mcm","clk":"11857294600","pt":1723368018496,"mc":[{"id":"1.231582255","rc":[{"batb":[[0,2.32,23.64],[1,2.3,13.85],[2,2.28,5]],"ltp":2.38,"tv":70.91,"id":31379}]}]}
{"op":"mcm","clk":"11857294683","pt":1723368019171,"mc":[{"id":"1.231582255","rc":[{"batb":[[0,2.32,10],[2,1.74,6.7]],"ltp":2.38,"tv":70.91,"id":31379}]}]}
{"op":"mcm","clk":"11857294896","pt":1723368020878,"mc":[{"id":"1.231582255","rc":[{"batb":[[0,2.3,13.85],[1,1.74,6.7],[2,1.3,1000]],"ltp":2.38,"tv":70.91,"id":31379}]}]}
{"op":"mcm","clk":"11857295053","pt":1723368022583,"mc":[{"id":"1.231582255","rc":[{"batb":[[0,2.32,4],[1,2.3,13.85],[2,1.74,6.7]],"ltp":2.38,"tv":70.91,"id":31379}]}]}
{"op":"mcm","clk":"11857295220","pt":1723368023881,"mc":[{"id":"1.231582255","rc":[{"batb":[[0,2.34,10],[1,2.32,4],[2,2.3,13.85]],"ltp":2.38,"tv":70.91,"id":31379}]}]}
{"op":"mcm","clk":"11857295301","pt":1723368024600,"mc":[{"id":"1.231582255","rc":[{"batb":[[1,2.32,17.64]],"ltp":2.38,"tv":70.91,"id":31379}]}]}
{"op":"mcm","clk":"11857295443","pt":1723368025797,"mc":[{"id":"1.231582255","rc":[{"batb":[[1,2.32,13.64]],"ltp":2.38,"tv":70.91,"id":31379}]}]}
{"op":"mcm","clk":"11857295735","pt":1723368028241,"mc":[{"id":"1.231582255","rc":[{"batb":[[0,2.3,13.85],[1,1.74,6.7],[2,1.3,1000]],"ltp":2.38,"tv":70.91,"id":31379}]}]}
{"op":"mcm","clk":"11857295848","pt":1723368029120,"mc":[{"id":"1.231582255","rc":[{"batb":[[1,2.28,5],[2,1.74,6.7]],"ltp":2.38,"tv":70.91,"id":31379}]}]}
{"op":"mcm","clk":"11857295978","pt":1723368030515,"mc":[{"id":"1.231582255","rc":[{"batb":[[0,2.34,14],[1,2.3,13.85],[2,2.28,5]],"ltp":2.38,"tv":70.91,"id":31379}]}]}
{"op":"mcm","clk":"11857296192","pt":1723368032637,"mc":[{"id":"1.231582255","rc":[{"batb":[[1,2.32,13.64],[2,2.3,13.85]],"ltp":2.38,"tv":70.91,"id":31379}]}]}
{"op":"mcm","clk":"11857296348","pt":1723368034141,"mc":[{"id":"1.231582255","rc":[{"batb":[[0,2.34,10]],"ltp":2.38,"tv":70.91,"id":31379}]}]}
{"op":"mcm","clk":"11857296453","pt":1723368035137,"mc":[{"id":"1.231582255","rc":[{"batb":[[0,2.3,13.85],[1,1.74,6.7],[2,1.3,1000]],"ltp":2.38,"tv":70.91,"id":31379}]}]}
{"op":"mcm","clk":"11857296621","pt":1723368036533,"mc":[{"id":"1.231582255","rc":[{"batb":[[0,2.34,4],[1,2.3,13.85],[2,1.74,6.7]],"ltp":2.38,"tv":70.91,"id":31379}]}]}
{"op":"mcm","clk":"11857296929","pt":1723368039030,"mc":[{"id":"1.231582255","rc":[{"batb":[[1,2.32,23.64],[2,2.3,13.85]],"ltp":2.38,"tv":70.91,"id":31379}]}]}
{"op":"mcm","clk":"11857297310","pt":1723368042113,"mc":[{"id":"1.231582255","rc":[{"batb":[[0,2.32,10],[1,2.3,13.85],[2,1.74,6.7]],"ltp":2.38,"tv":70.91,"id":31379}]}]}
{"op":"mcm","clk":"11857297548","pt":1723368044194,"mc":[{"id":"1.231582255","rc":[{"batb":[[2,2.28,5]],"ltp":2.38,"tv":70.91,"id":31379}]}]}
{"op":"mcm","clk":"11857297677","pt":1723368045232,"mc":[{"id":"1.231582255","rc":[{"batb":[[0,2.36,4]],"ltp":2.38,"tv":70.91,"id":31379}]}]}
{"op":"mcm","clk":"11857297889","pt":1723368047461,"mc":[{"id":"1.231582255","rc":[{"batb":[[1,2.32,10],[2,2.3,13.85]],"ltp":2.38,"tv":70.91,"id":31379}]}]}
{"op":"mcm","clk":"11857297911","pt":1723368047663,"mc":[{"id":"1.231582255","rc":[{"batb":[[1,2.32,23.64]],"ltp":2.38,"tv":70.91,"id":31379}]}]}
{"op":"mcm","clk":"11857298159","pt":1723368050166,"mc":[{"id":"1.231582255","rc":[{"batb":[[0,2.32,10],[1,2.3,13.85],[2,1.74,6.7]],"ltp":2.38,"tv":70.91,"id":31379}]}]}
{"op":"mcm","clk":"11857298439","pt":1723368052756,"mc":[{"id":"1.231582255","rc":[{"batb":[[0,2.38,4],[1,2.32,10],[2,2.3,13.85]],"ltp":2.38,"tv":70.91,"id":31379}]}]}
{"op":"mcm","clk":"11857298546","pt":1723368053642,"mc":[{"id":"1.231582255","rc":[{"batb":[[1,2.32,13.64]],"ltp":2.38,"tv":70.91,"id":31379}]}]}
{"op":"mcm","clk":"11857298921","pt":1723368057466,"mc":[{"id":"1.231582255","rc":[{"trd":[[2.4,4.58]],"batb":[[0,2.4,6.42],[1,2.38,4],[2,2.32,13.64]],"ltp":2.4,"tv":74.49,"id":31379},{"trd":[[1.72,6.4]],"batb":[[0,1.68,2.52],[1,1.67,20],[2,1.55,32.74]],"ltp":1.72,"tv":123.05,"id":424676}],"tv":197.54}]}
{"op":"mcm","clk":"11857298945","pt":1723368057675,"mc":[{"id":"1.231582255","rc":[{"batb":[[1,2.32,13.64],[2,2.3,13.85]],"ltp":2.4,"tv":74.49,"id":31379},{"batb":[[2,1.47,38.32]],"ltp":1.72,"tv":123.05,"id":424676}]}]}
{"op":"mcm","clk":"11857299266","pt":1723368060688,"mc":[{"id":"1.231582255","rc":[{"batb":[[0,2.42,4],[1,2.4,6.42],[2,2.32,13.64]],"ltp":2.4,"tv":74.49,"id":31379}]}]}
{"op":"mcm","clk":"11857299595","pt":1723368063664,"mc":[{"id":"1.231582255","rc":[{"batb":[[1,2.32,13.64],[2,2.3,13.85]],"ltp":2.4,"tv":74.49,"id":31379}]}]}
{"op":"mcm","clk":"11857299809","pt":1723368065469,"mc":[{"id":"1.231582255","rc":[{"batb":[[0,2.32,13.64],[1,2.3,13.85],[2,1.74,6.7]],"ltp":2.4,"tv":74.49,"id":31379}]}]}
{"op":"mcm","clk":"11857299848","pt":1723368065776,"mc":[{"id":"1.231582255","rc":[{"batb":[[0,2.3,13.85],[1,1.74,6.7],[2,1.3,1000]],"ltp":2.4,"tv":74.49,"id":31379}]}]}
{"op":"mcm","clk":"11857299940","pt":1723368066556,"mc":[{"id":"1.231582255","rc":[{"batb":[[0,2.44,10],[1,2.3,13.85],[2,1.74,6.7]],"ltp":2.4,"tv":74.49,"id":31379}]}]}
{"op":"mcm","clk":"11857300075","pt":1723368067794,"mc":[{"id":"1.231582255","rc":[{"batb":[[1,2.34,4],[2,2.3,13.85]],"ltp":2.4,"tv":74.49,"id":31379}]}]}
{"op":"mcm","clk":"11857300167","pt":1723368068674,"mc":[{"id":"1.231582255","rc":[{"batb":[[2,2.32,13.64]],"ltp":2.4,"tv":74.49,"id":31379}]}]}
{"op":"mcm","clk":"11857300574","pt":1723368072397,"mc":[{"id":"1.231582255","rc":[{"batb":[[0,2.32,13.64],[1,2.3,13.85],[2,1.74,6.7]],"ltp":2.4,"tv":74.49,"id":31379}]}]}
{"op":"mcm","clk":"11857300603","pt":1723368072658,"mc":[{"id":"1.231582255","rc":[{"batb":[[0,2.3,13.85],[1,1.74,6.7],[2,1.3,1000]],"ltp":2.4,"tv":74.49,"id":31379}]}]}
{"op":"mcm","clk":"11857300822","pt":1723368074369,"mc":[{"id":"1.231582255","rc":[{"batb":[[1,2.28,5],[2,1.74,6.7]],"ltp":2.4,"tv":74.49,"id":31379}]}]}
{"op":"mcm","clk":"11857300855","pt":1723368074685,"mc":[{"id":"1.231582255","rc":[{"batb":[[0,2.34,14],[1,2.3,13.85],[2,2.28,5]],"ltp":2.4,"tv":74.49,"id":31379}]}]}
{"op":"mcm","clk":"11857301044","pt":1723368076701,"mc":[{"id":"1.231582255","rc":[{"batb":[[1,2.32,13.64],[2,2.3,13.85]],"ltp":2.4,"tv":74.49,"id":31379}]}]}
{"op":"mcm","clk":"11857301374","pt":1723368079406,"mc":[{"id":"1.231582255","rc":[{"batb":[[0,2.34,10]],"ltp":2.4,"tv":74.49,"id":31379}]}]}
{"op":"mcm","clk":"11857301491","pt":1723368080186,"mc":[{"id":"1.231582255","rc":[{"batb":[[0,2.3,13.85],[1,1.74,6.7],[2,1.3,1000]],"ltp":2.4,"tv":74.49,"id":31379}]}]}
{"op":"mcm","clk":"11857301783","pt":1723368082893,"mc":[{"id":"1.231582255","rc":[{"batb":[[0,2.36,14],[1,2.3,13.85],[2,1.74,6.7]],"ltp":2.4,"tv":74.49,"id":31379}]}]}
{"op":"mcm","clk":"11857301983","pt":1723368084705,"mc":[{"id":"1.231582255","rc":[{"batb":[[1,2.32,13.64],[2,2.3,13.85]],"ltp":2.4,"tv":74.49,"id":31379}]}]}
{"op":"mcm","clk":"11857302364","pt":1723368088487,"mc":[{"id":"1.231582255","rc":[{"batb":[[0,2.36,10]],"ltp":2.4,"tv":74.49,"id":31379}]}]}
{"op":"mcm","clk":"11857302452","pt":1723368089413,"mc":[{"id":"1.231582255","rc":[{"batb":[[0,2.32,13.64],[1,2.3,13.85],[2,1.74,6.7]],"ltp":2.4,"tv":74.49,"id":31379}]}]}
{"op":"mcm","clk":"11857302484","pt":1723368089678,"mc":[{"id":"1.231582255","rc":[{"batb":[[0,2.3,13.85],[1,1.74,6.7],[2,1.3,1000]],"ltp":2.4,"tv":74.49,"id":31379}]}]}
{"op":"mcm","clk":"11857302590","pt":1723368090816,"mc":[{"id":"1.231582255","rc":[{"batb":[[0,2.38,4],[1,2.3,13.85],[2,1.74,6.7]],"ltp":2.4,"tv":74.49,"id":31379}]}]}
{"op":"mcm","clk":"11857302671","pt":1723368091726,"mc":[{"id":"1.231582255","rc":[{"batb":[[0,2.38,14]],"ltp":2.4,"tv":74.49,"id":31379}]}]}
{"op":"mcm","clk":"11857302763","pt":1723368092680,"mc":[{"id":"1.231582255","rc":[{"batb":[[1,2.32,13.64],[2,2.3,13.85]],"ltp":2.4,"tv":74.49,"id":31379}]}]}
{"op":"mcm","clk":"11857303131","pt":1723368096313,"mc":[{"id":"1.231582255","rc":[{"batb":[[0,2.38,10]],"ltp":2.4,"tv":74.49,"id":31379}]}]}
{"op":"mcm","clk":"11857303355","pt":1723368098429,"mc":[{"id":"1.231582255","rc":[{"batb":[[0,2.32,13.64],[1,2.3,13.85],[2,1.74,6.7]],"ltp":2.4,"tv":74.49,"id":31379}]}]}
{"op":"mcm","clk":"11857303468","pt":1723368099518,"mc":[{"id":"1.231582255","rc":[{"batb":[[0,2.3,13.85],[1,2.28,5]],"ltp":2.4,"tv":74.49,"id":31379}]}]}
{"op":"mcm","clk":"11857303628","pt":1723368100920,"mc":[{"id":"1.231582255","rc":[{"batb":[[0,2.34,14],[1,2.3,13.85],[2,2.28,5]],"ltp":2.4,"tv":74.49,"id":31379}]}]}
{"op":"mcm","clk":"11857303824","pt":1723368102728,"mc":[{"id":"1.231582255","rc":[{"batb":[[1,2.32,13.64],[2,2.3,13.85]],"ltp":2.4,"tv":74.49,"id":31379}]}]}
{"op":"mcm","clk":"11857304013","pt":1723368104495,"mc":[{"id":"1.231582255","rc":[{"batb":[[0,2.34,10]],"ltp":2.4,"tv":74.49,"id":31379}]}]}
{"op":"mcm","clk":"11857304089","pt":1723368105333,"mc":[{"id":"1.231582255","rc":[{"batb":[[0,2.32,13.64],[1,2.3,13.85],[2,1.74,6.7]],"ltp":2.4,"tv":74.49,"id":31379}]}]}
{"op":"mcm","clk":"11857304123","pt":1723368105706,"mc":[{"id":"1.231582255","rc":[{"batb":[[0,2.3,13.85],[1,1.74,6.7],[2,1.3,1000]],"ltp":2.4,"tv":74.49,"id":31379}]}]}
{"op":"mcm","clk":"11857304236","pt":1723368106599,"mc":[{"id":"1.231582255","rc":[{"batb":[[0,2.36,4],[1,2.3,13.85],[2,1.74,6.7]],"ltp":2.4,"tv":74.49,"id":31379}]}]}
{"op":"mcm","clk":"11857304369","pt":1723368107630,"mc":[{"id":"1.231582255","rc":[{"batb":[[1,2.32,10],[2,2.3,13.85]],"ltp":2.4,"tv":74.49,"id":31379}]}]}
{"op":"mcm","clk":"11857304486","pt":1723368108712,"mc":[{"id":"1.231582255","rc":[{"batb":[[1,2.32,23.64]],"ltp":2.4,"tv":74.49,"id":31379}]}]}
{"op":"mcm","clk":"11857304634","pt":1723368110210,"mc":[{"id":"1.231582255","rc":[{"batb":[[0,2.32,10],[1,2.3,13.85],[2,1.74,6.7]],"ltp":2.4,"tv":74.49,"id":31379}]}]}
{"op":"mcm","clk":"11857304810","pt":1723368112031,"mc":[{"id":"1.231582255","rc":[{"batb":[[0,2.3,13.85],[1,1.74,6.7],[2,1.3,1000]],"ltp":2.4,"tv":74.49,"id":31379}]}]}
{"op":"mcm","clk":"11857304896","pt":1723368112706,"mc":[{"id":"1.231582255","rc":[{"batb":[[0,2.32,4],[1,2.3,13.85],[2,1.74,6.7]],"ltp":2.4,"tv":74.49,"id":31379}]}]}
{"op":"mcm","clk":"11857305072","pt":1723368114514,"mc":[{"id":"1.231582255","rc":[{"batb":[[2,2.28,5]],"ltp":2.4,"tv":74.49,"id":31379}]}]}
{"op":"mcm","clk":"11857305174","pt":1723368115437,"mc":[{"id":"1.231582255","rc":[{"batb":[[0,2.3,13.85],[1,2.28,5],[2,1.74,6.7]],"ltp":2.4,"tv":74.49,"id":31379}]}]}
{"op":"mcm","clk":"11857305211","pt":1723368115700,"mc":[{"id":"1.231582255","rc":[{"batb":[[0,2.34,10],[1,2.3,13.85],[2,2.28,5]],"ltp":2.4,"tv":74.49,"id":31379}]}]}
{"op":"mcm","clk":"11857305402","pt":1723368117725,"mc":[{"id":"1.231582255","rc":[{"batb":[[1,2.32,13.64],[2,2.3,13.85]],"ltp":2.4,"tv":74.49,"id":31379}]}]}
{"op":"mcm","clk":"11857305611","pt":1723368119531,"mc":[{"id":"1.231582255","rc":[{"batb":[[0,2.36,4]],"ltp":2.4,"tv":74.49,"id":31379}]}]}
{"op":"mcm","clk":"11857305764","pt":1723368121199,"mc":[{"id":"1.231582255","rc":[{"batb":[[0,2.32,13.64],[1,2.3,13.85],[2,1.74,6.7]],"ltp":2.4,"tv":74.49,"id":31379}]}]}
{"op":"mcm","clk":"11857305835","pt":1723368121928,"mc":[{"id":"1.231582255","rc":[{"batb":[[0,2.32,10]],"ltp":2.4,"tv":74.49,"id":31379}]}]}
{"op":"mcm","clk":"11857306250","pt":1723368125431,"mc":[{"id":"1.231582255","rc":[{"batb":[[0,2.3,13.85],[1,2.28,5]],"ltp":2.4,"tv":74.49,"id":31379}]}]}
{"op":"mcm","clk":"11857306293","pt":1723368125847,"mc":[{"id":"1.231582255","rc":[{"batb":[[0,2.34,4],[1,2.3,13.85],[2,2.28,5]],"ltp":2.4,"tv":74.49,"id":31379}]}]}
{"op":"mcm","clk":"11857306518","pt":1723368127825,"mc":[{"id":"1.231582255","rc":[{"batb":[[0,2.36,10],[1,2.34,4],[2,2.32,13.64]],"ltp":2.4,"tv":74.49,"id":31379}]}]}
{"op":"mcm","clk":"11857306725","pt":1723368129842,"mc":[{"id":"1.231582255","rc":[{"batb":[[1,2.32,13.64],[2,2.3,13.85]],"ltp":2.4,"tv":74.49,"id":31379}]}]}
{"op":"mcm","clk":"11857306983","pt":1723368132513,"mc":[{"id":"1.231582255","rc":[{"batb":[[0,2.38,4],[1,2.36,10],[2,2.32,13.64]],"ltp":2.4,"tv":74.49,"id":31379}]}]}
{"op":"mcm","clk":"11857307100","pt":1723368133750,"mc":[{"id":"1.231582255","rc":[{"batb":[[1,2.32,13.64],[2,2.3,13.85]],"ltp":2.4,"tv":74.49,"id":31379}]}]}
{"op":"mcm","clk":"11857307357","pt":1723368136434,"mc":[{"id":"1.231582255","rc":[{"batb":[[0,2.4,10],[1,2.38,4],[2,2.32,13.64]],"ltp":2.4,"tv":74.49,"id":31379}]}]}
{"op":"mcm","clk":"11857307480","pt":1723368137622,"mc":[{"id":"1.231582255","rc":[{"batb":[[1,2.32,13.64],[2,2.3,13.85]],"ltp":2.4,"tv":74.49,"id":31379}]}]}
{"op":"mcm","clk":"11857307859","pt":1723368141448,"mc":[{"id":"1.231582255","rc":[{"batb":[[0,2.32,13.64],[1,2.3,13.85],[2,1.74,6.7]],"ltp":2.4,"tv":74.49,"id":31379}]}]}
{"op":"mcm","clk":"11857307891","pt":1723368141760,"mc":[{"id":"1.231582255","rc":[{"batb":[[0,2.3,13.85],[1,1.74,6.7],[2,1.3,1000]],"ltp":2.4,"tv":74.49,"id":31379}]}]}
{"op":"mcm","clk":"11857308055","pt":1723368143418,"mc":[{"id":"1.231582255","rc":[{"batb":[[0,2.34,4],[1,2.3,13.85],[2,1.74,6.7]],"ltp":2.4,"tv":74.49,"id":31379}]}]}
{"op":"mcm","clk":"11857308197","pt":1723368144762,"mc":[{"id":"1.231582255","rc":[{"batb":[[0,2.36,10],[1,2.34,4],[2,2.3,13.85]],"ltp":2.4,"tv":74.49,"id":31379}]}]}
{"op":"mcm","clk":"11857308313","pt":1723368145752,"mc":[{"id":"1.231582255","rc":[{"batb":[[2,2.32,13.64]],"ltp":2.4,"tv":74.49,"id":31379}]}]}
{"op":"mcm","clk":"11857308407","pt":1723368146732,"mc":[{"id":"1.231582255","rc":[{"batb":[[1,2.32,13.64],[2,2.3,13.85]],"ltp":2.4,"tv":74.49,"id":31379}]}]}
{"op":"mcm","clk":"11857308621","pt":1723368148952,"mc":[{"id":"1.231582255","rc":[{"batb":[[0,2.38,4],[1,2.36,10],[2,2.32,13.64]],"ltp":2.4,"tv":74.49,"id":31379}]}]}
{"op":"mcm","clk":"11857308708","pt":1723368149733,"mc":[{"id":"1.231582255","rc":[{"batb":[[1,2.32,13.64],[2,2.3,13.85]],"ltp":2.4,"tv":74.49,"id":31379}]}]}
{"op":"mcm","clk":"11857309018","pt":1723368152442,"mc":[{"id":"1.231582255","rc":[{"batb":[[0,2.4,10],[1,2.38,4],[2,2.32,13.64]],"ltp":2.4,"tv":74.49,"id":31379}]}]}
{"op":"mcm","clk":"11857309065","pt":1723368152971,"mc":[{"id":"1.231582255","rc":[{"batb":[[1,2.32,13.64],[2,2.3,13.85]],"ltp":2.4,"tv":74.49,"id":31379}]}]}
{"op":"mcm","clk":"11857309547","pt":1723368157231,"mc":[{"id":"1.231582255","rc":[{"batb":[[0,2.3,13.85],[1,1.74,6.7],[2,1.3,1000]],"ltp":2.4,"tv":74.49,"id":31379}]}]}
{"op":"mcm","clk":"11857309595","pt":1723368157660,"mc":[{"id":"1.231582255","rc":[{"batb":[[0,2.34,4],[1,2.3,13.85],[2,1.74,6.7]],"ltp":2.4,"tv":74.49,"id":31379}]}]}
{"op":"mcm","clk":"11857309856","pt":1723368160168,"mc":[{"id":"1.231582255","rc":[{"batb":[[0,2.32,13.64],[2,2.28,5]],"ltp":2.4,"tv":74.49,"id":31379}]}]}
{"op":"mcm","clk":"11857309952","pt":1723368160983,"mc":[{"id":"1.231582255","rc":[{"batb":[[0,2.36,10]],"ltp":2.4,"tv":74.49,"id":31379}]}]}
{"op":"mcm","clk":"11857310181","pt":1723368162955,"mc":[{"id":"1.231582255","rc":[{"batb":[[0,2.38,4],[1,2.36,10],[2,2.32,13.64]],"ltp":2.4,"tv":74.49,"id":31379}]}]}
{"op":"mcm","clk":"11857310451","pt":1723368165485,"mc":[{"id":"1.231582255","rc":[{"batb":[[0,2.32,13.64],[1,2.3,13.85],[2,1.74,6.7]],"ltp":2.4,"tv":74.49,"id":31379}]}]}
{"op":"mcm","clk":"11857310520","pt":1723368166259,"mc":[{"id":"1.231582255","rc":[{"batb":[[0,2.3,13.85],[1,1.74,6.7],[2,1.3,1000]],"ltp":2.4,"tv":74.49,"id":31379}]}]}
{"op":"mcm","clk":"11857310724","pt":1723368168183,"mc":[{"id":"1.231582255","rc":[{"batb":[[0,2.32,14],[1,2.3,13.85],[2,1.74,6.7]],"ltp":2.4,"tv":74.49,"id":31379}]}]}
{"op":"mcm","clk":"11857310978","pt":1723368170547,"mc":[{"id":"1.231582255","rc":[{"batb":[[0,2.32,10]],"ltp":2.4,"tv":74.49,"id":31379}]}]}
{"op":"mcm","clk":"11857311076","pt":1723368171579,"mc":[{"id":"1.231582255","rc":[{"batb":[[0,2.3,13.85],[1,1.74,6.7],[2,1.3,1000]],"ltp":2.4,"tv":74.49,"id":31379}]}]}
{"op":"mcm","clk":"11857311345","pt":1723368174276,"mc":[{"id":"1.231582255","rc":[{"batb":[[0,2.32,14],[1,2.3,13.85],[2,1.74,6.7]],"ltp":2.4,"tv":74.49,"id":31379}]}]}
{"op":"mcm","clk":"11857311590","pt":1723368176761,"mc":[{"id":"1.231582255","rc":[{"batb":[[0,2.32,10]],"ltp":2.4,"tv":74.49,"id":31379}]}]}
{"op":"mcm","clk":"11857311672","pt":1723368177790,"mc":[{"id":"1.231582255","rc":[{"batb":[[0,2.3,13.85],[1,1.74,6.7],[2,1.3,1000]],"ltp":2.4,"tv":74.49,"id":31379}]}]}
{"op":"mcm","clk":"11857311974","pt":1723368180071,"mc":[{"id":"1.231582255","rc":[{"batb":[[0,2.32,14],[1,2.3,13.85],[2,2.28,5]],"ltp":2.4,"tv":74.49,"id":31379}]}]}
{"op":"mcm","clk":"11857312346","pt":1723368183175,"mc":[{"id":"1.231582255","rc":[{"batb":[[0,2.32,10]],"ltp":2.4,"tv":74.49,"id":31379}]}]}
{"op":"mcm","clk":"11857312446","pt":1723368184103,"mc":[{"id":"1.231582255","rc":[{"batb":[[0,2.3,13.85],[1,2.28,5],[2,1.74,6.7]],"ltp":2.4,"tv":74.49,"id":31379}]}]}
{"op":"mcm","clk":"11857312784","pt":1723368187272,"mc":[{"id":"1.231582255","rc":[{"batb":[[0,2.32,14],[1,2.3,13.85],[2,2.28,5]],"ltp":2.4,"tv":74.49,"id":31379}]}]}
{"op":"mcm","clk":"11857313091","pt":1723368190168,"mc":[{"id":"1.231582255","rc":[{"batb":[[0,2.32,10],[2,1.74,6.7]],"ltp":2.4,"tv":74.49,"id":31379}]}]}
{"op":"mcm","clk":"11857313163","pt":1723368190891,"mc":[{"id":"1.231582255","rc":[{"batb":[[0,2.3,13.85],[1,1.74,6.7],[2,1.3,1000]],"ltp":2.4,"tv":74.49,"id":31379}]}]}
{"op":"mcm","clk":"11857313600","pt":1723368195189,"mc":[{"id":"1.231582255","rc":[{"batb":[[1,2.28,5],[2,1.74,6.7]],"ltp":2.4,"tv":74.49,"id":31379}]}]}
{"op":"mcm","clk":"11857313753","pt":1723368196682,"mc":[{"id":"1.231582255","rc":[{"batb":[[0,2.32,14],[1,2.3,13.85],[2,2.28,5]],"ltp":2.4,"tv":74.49,"id":31379}]}]}
{"op":"mcm","clk":"11857314112","pt":1723368199804,"mc":[{"id":"1.231582255","rc":[{"batb":[[0,2.32,10]],"ltp":2.4,"tv":74.49,"id":31379}]}]}
{"op":"mcm","clk":"11857314257","pt":1723368200894,"mc":[{"id":"1.231582255","rc":[{"batb":[[0,2.3,13.85],[1,2.28,5],[2,1.74,6.7]],"ltp":2.4,"tv":74.49,"id":31379}]}]}
{"op":"mcm","clk":"11857314417","pt":1723368202391,"mc":[{"id":"1.231582255","rc":[{"batb":[[0,2.32,4],[1,2.3,13.85],[2,2.28,5]],"ltp":2.4,"tv":74.49,"id":31379}]}]}
{"op":"mcm","clk":"11857314560","pt":1723368203684,"mc":[{"id":"1.231582255","rc":[{"batb":[[0,2.34,10],[1,2.32,4],[2,2.3,13.85]],"ltp":2.4,"tv":74.49,"id":31379}]}]}
{"op":"mcm","clk":"11857314746","pt":1723368205585,"mc":[{"id":"1.231582255","rc":[{"batb":[[1,2.3,13.85],[2,1.74,6.7]],"ltp":2.4,"tv":74.49,"id":31379}]}]}
{"op":"mcm","clk":"11857315037","pt":1723368208228,"mc":[{"id":"1.231582255","rc":[{"batb":[[0,2.32,13.64]],"ltp":2.4,"tv":74.49,"id":31379}]}]}
{"op":"mcm","clk":"11857315099","pt":1723368208802,"mc":[{"id":"1.231582255","rc":[{"batb":[[0,2.36,4]],"ltp":2.4,"tv":74.49,"id":31379}]}]}
{"op":"mcm","clk":"11857315262","pt":1723368210209,"mc":[{"id":"1.231582255","rc":[{"batb":[[2,2.28,5]],"ltp":2.4,"tv":74.49,"id":31379}]}]}
{"op":"mcm","clk":"11857315388","pt":1723368211193,"mc":[{"id":"1.231582255","rc":[{"batb":[[0,2.38,10],[1,2.36,4],[2,2.32,13.64]],"ltp":2.4,"tv":74.49,"id":31379}]}]}
{"op":"mcm","clk":"11857315428","pt":1723368211605,"mc":[{"id":"1.231582255","rc":[{"batb":[[1,2.32,13.64],[2,2.3,13.85]],"ltp":2.4,"tv":74.49,"id":31379}]}]}
{"op":"mcm","clk":"11857315830","pt":1723368215296,"mc":[{"id":"1.231582255","rc":[{"batb":[[0,2.34,4]],"ltp":2.4,"tv":74.49,"id":31379}]}]}
{"op":"mcm","clk":"11857316099","pt":1723368217735,"mc":[{"id":"1.231582255","rc":[{"batb":[[0,2.34,10],[1,2.3,13.85],[2,1.74,6.7]],"ltp":2.4,"tv":74.49,"id":31379}]}]}
{"op":"mcm","clk":"11857316307","pt":1723368219821,"mc":[{"id":"1.231582255","rc":[{"batb":[[0,2.36,4],[1,2.34,10],[2,2.32,13.64]],"ltp":2.4,"tv":74.49,"id":31379}]}]}
{"op":"mcm","clk":"11857316436","pt":1723368221119,"mc":[{"id":"1.231582255","rc":[{"batb":[[1,2.32,13.64],[2,2.3,13.85]],"ltp":2.4,"tv":74.49,"id":31379}]}]}
{"op":"mcm","clk":"11857316556","pt":1723368222212,"mc":[{"id":"1.231582255","rc":[{"batb":[[0,2.32,13.64],[1,2.3,13.85],[2,1.74,6.7]],"ltp":2.4,"tv":74.49,"id":31379}]}]}
{"op":"mcm","clk":"11857316606","pt":1723368222729,"mc":[{"id":"1.231582255","rc":[{"batb":[[0,2.3,13.85],[1,1.74,6.7],[2,1.3,1000]],"ltp":2.4,"tv":74.49,"id":31379}]}]}
{"op":"mcm","clk":"11857316867","pt":1723368225117,"mc":[{"id":"1.231582255","rc":[{"batb":[[0,2.32,14],[1,2.3,13.85],[2,1.74,6.7]],"ltp":2.4,"tv":74.49,"id":31379}]}]}
{"op":"mcm","clk":"11857317171","pt":1723368228334,"mc":[{"id":"1.231582255","rc":[{"batb":[[0,2.32,10]],"ltp":2.4,"tv":74.49,"id":31379}]}]}
{"op":"mcm","clk":"11857317220","pt":1723368228801,"mc":[{"id":"1.231582255","rc":[{"batb":[[0,2.3,13.85],[1,1.74,6.7],[2,1.3,1000]],"ltp":2.4,"tv":74.49,"id":31379}]}]}
{"op":"mcm","clk":"11857317376","pt":1723368230358,"mc":[{"id":"1.231582255","rc":[{"batb":[[1,2.28,5],[2,1.74,6.7]],"ltp":2.4,"tv":74.49,"id":31379}]}]}
{"op":"mcm","clk":"11857317455","pt":1723368231059,"mc":[{"id":"1.231582255","rc":[{"batb":[[0,2.34,10],[1,2.32,4],[2,2.3,13.85]],"ltp":2.4,"tv":74.49,"id":31379}]}]}
{"op":"mcm","clk":"11857317680","pt":1723368233144,"mc":[{"id":"1.231582255","rc":[{"batb":[[1,2.32,13.64]],"ltp":2.4,"tv":74.49,"id":31379}]}]}
{"op":"mcm","clk":"11857317822","pt":1723368234715,"mc":[{"id":"1.231582255","rc":[{"batb":[[0,2.3,13.85],[1,2.28,5],[2,1.74,6.7]],"ltp":2.4,"tv":74.49,"id":31379}]}]}
{"op":"mcm","clk":"11857318607","pt":1723368242034,"mc":[{"id":"1.231582255","rc":[{"batb":[[0,2.32,14],[1,2.3,13.85],[2,2.28,5]],"ltp":2.4,"tv":74.49,"id":31379}]}]}
{"op":"mcm","clk":"11857318917","pt":1723368244431,"mc":[{"id":"1.231582255","rc":[{"batb":[[0,2.32,10]],"ltp":2.4,"tv":74.49,"id":31379}]}]}
{"op":"mcm","clk":"11857319017","pt":1723368245467,"mc":[{"id":"1.231582255","rc":[{"batb":[[0,2.3,13.85],[1,2.28,5],[2,1.74,6.7]],"ltp":2.4,"tv":74.49,"id":31379}]}]}
{"op":"mcm","clk":"11857319142","pt":1723368246666,"mc":[{"id":"1.231582255","rc":[{"batb":[[0,2.32,4],[1,2.3,13.85],[2,2.28,5]],"ltp":2.4,"tv":74.49,"id":31379}]}]}
{"op":"mcm","clk":"11857319274","pt":1723368247759,"mc":[{"id":"1.231582255","rc":[{"batb":[[0,2.34,10],[1,2.32,4],[2,2.3,13.85]],"ltp":2.4,"tv":74.49,"id":31379}]}]}
{"op":"mcm","clk":"11857319412","pt":1723368248759,"mc":[{"id":"1.231582255","rc":[{"batb":[[1,2.32,17.64]],"ltp":2.4,"tv":74.49,"id":31379}]}]}
{"op":"mcm","clk":"11857319588","pt":1723368250466,"mc":[{"id":"1.231582255","rc":[{"batb":[[1,2.32,13.64]],"ltp":2.4,"tv":74.49,"id":31379}]}]}
{"op":"mcm","clk":"11857319770","pt":1723368252274,"mc":[{"id":"1.231582255","rc":[{"batb":[[0,2.3,13.85],[1,1.74,6.7],[2,1.3,1000]],"ltp":2.4,"tv":74.49,"id":31379}]}]}
{"op":"mcm","clk":"11857319889","pt":1723368253476,"mc":[{"id":"1.231582255","rc":[{"batb":[[0,2.34,4],[1,2.3,13.85],[2,1.74,6.7]],"ltp":2.4,"tv":74.49,"id":31379}]}]}
{"op":"mcm","clk":"11857320065","pt":1723368255139,"mc":[{"id":"1.231582255","rc":[{"batb":[[0,2.36,10],[1,2.34,4],[2,2.3,13.85]],"ltp":2.4,"tv":74.49,"id":31379}]}]}
{"op":"mcm","clk":"11857320127","pt":1723368255759,"mc":[{"id":"1.231582255","rc":[{"batb":[[2,2.32,13.64]],"ltp":2.4,"tv":74.49,"id":31379}]}]}
{"op":"mcm","clk":"11857320287","pt":1723368257161,"mc":[{"id":"1.231582255","rc":[{"batb":[[1,2.32,13.64],[2,2.3,13.85]],"ltp":2.4,"tv":74.49,"id":31379}]}]}
{"op":"mcm","clk":"11857320539","pt":1723368259346,"mc":[{"id":"1.231582255","rc":[{"batb":[[0,2.38,4],[1,2.36,10],[2,2.32,13.64]],"ltp":2.4,"tv":74.49,"id":31379}]}]}
{"op":"mcm","clk":"11857320778","pt":1723368261676,"mc":[{"id":"1.231582255","rc":[{"batb":[[1,2.32,13.64],[2,2.3,13.85]],"ltp":2.4,"tv":74.49,"id":31379}]}]}
{"op":"mcm","clk":"11857321072","pt":1723368264385,"mc":[{"id":"1.231582255","rc":[{"batb":[[0,2.3,13.85],[1,1.74,6.7],[2,1.3,1000]],"ltp":2.4,"tv":74.49,"id":31379}]}]}
{"op":"mcm","clk":"11857321144","pt":1723368265046,"mc":[{"id":"1.231582255","rc":[{"batb":[[0,2.4,10],[1,2.3,13.85],[2,1.74,6.7]],"ltp":2.4,"tv":74.49,"id":31379}]}]}
{"op":"mcm","clk":"11857321287","pt":1723368266455,"mc":[{"id":"1.231582255","rc":[{"batb":[[1,2.34,4],[2,2.3,13.85]],"ltp":2.4,"tv":74.49,"id":31379}]}]}
{"op":"mcm","clk":"11857321316","pt":1723368266762,"mc":[{"id":"1.231582255","rc":[{"batb":[[2,2.32,13.64]],"ltp":2.4,"tv":74.49,"id":31379}]}]}
{"op":"mcm","clk":"11857321629","pt":1723368270445,"mc":[{"id":"1.231582255","rc":[{"batb":[[0,2.34,4],[1,2.32,13.64],[2,2.3,13.85]],"ltp":2.4,"tv":74.49,"id":31379}]}]}
{"op":"mcm","clk":"11857321784","pt":1723368272259,"mc":[{"id":"1.231582255","rc":[{"batb":[[0,2.3,13.85],[1,1.74,6.7],[2,1.3,1000]],"ltp":2.4,"tv":74.49,"id":31379}]}]}
{"op":"mcm","clk":"11857321842","pt":1723368272879,"mc":[{"id":"1.231582255","rc":[{"batb":[[0,2.36,10],[1,2.3,13.85],[2,1.74,6.7]],"ltp":2.4,"tv":74.49,"id":31379}]}]}
{"op":"mcm","clk":"11857321972","pt":1723368274485,"mc":[{"id":"1.231582255","rc":[{"batb":[[1,2.34,4],[2,2.3,13.85]],"ltp":2.4,"tv":74.49,"id":31379}]}]}
{"op":"mcm","clk":"11857322003","pt":1723368274746,"mc":[{"id":"1.231582255","rc":[{"batb":[[2,2.32,13.64]],"ltp":2.4,"tv":74.49,"id":31379}]}]}
{"op":"mcm","clk":"11857322345","pt":1723368278460,"mc":[{"id":"1.231582255","rc":[{"batb":[[0,2.34,4],[1,2.32,13.64],[2,2.3,13.85]],"ltp":2.4,"tv":74.49,"id":31379}]}]}
{"op":"mcm","clk":"11857322376","pt":1723368278771,"mc":[{"id":"1.231582255","rc":[{"batb":[[0,2.3,13.85],[1,1.74,6.7],[2,1.3,1000]],"ltp":2.4,"tv":74.49,"id":31379}]}]}
{"op":"mcm","clk":"11857322594","pt":1723368280854,"mc":[{"id":"1.231582255","rc":[{"batb":[[0,2.32,14],[1,2.3,13.85],[2,2.28,5]],"ltp":2.4,"tv":74.49,"id":31379}]}]}
{"op":"mcm","clk":"11857322990","pt":1723368285078,"mc":[{"id":"1.231582255","rc":[{"batb":[[0,2.32,10]],"ltp":2.4,"tv":74.49,"id":31379}]}]}
{"op":"mcm","clk":"11857323090","pt":1723368286071,"mc":[{"id":"1.231582255","rc":[{"batb":[[0,2.3,13.85],[1,2.28,5],[2,1.74,6.7]],"ltp":2.4,"tv":74.49,"id":31379}]}]}
{"op":"mcm","clk":"11857323270","pt":1723368287795,"mc":[{"id":"1.231582255","rc":[{"batb":[[0,2.34,4],[1,2.3,13.85],[2,2.28,5]],"ltp":2.4,"tv":74.49,"id":31379}]}]}
{"op":"mcm","clk":"11857323388","pt":1723368289301,"mc":[{"id":"1.231582255","rc":[{"batb":[[0,2.34,14]],"ltp":2.4,"tv":74.49,"id":31379}]}]}
{"op":"mcm","clk":"11857323431","pt":1723368289768,"mc":[{"id":"1.231582255","rc":[{"batb":[[1,2.32,13.64],[2,2.3,13.85]],"ltp":2.4,"tv":74.49,"id":31379}]}]}
{"op":"mcm","clk":"11857323863","pt":1723368294500,"mc":[{"id":"1.231582255","rc":[{"batb":[[0,2.34,10]],"ltp":2.4,"tv":74.49,"id":31379}]}]}
{"op":"mcm","clk":"11857324104","pt":1723368297398,"mc":[{"id":"1.231582255","rc":[{"batb":[[0,2.32,13.64],[1,2.3,13.85],[2,1.74,6.7]],"ltp":2.4,"tv":74.49,"id":31379}]}]}
{"op":"mcm","clk":"11857324136","pt":1723368297816,"mc":[{"id":"1.231582255","rc":[{"batb":[[0,2.36,4]],"ltp":2.4,"tv":74.49,"id":31379}]}]}
{"op":"mcm","clk":"11857324316","pt":1723368299793,"mc":[{"id":"1.231582255","rc":[{"batb":[[1,2.32,13.64],[2,2.3,13.85]],"ltp":2.4,"tv":74.49,"id":31379}]}]}
{"op":"mcm","clk":"11857324429","pt":1723368301207,"mc":[{"id":"1.231582255","rc":[{"batb":[[0,2.36,14]],"ltp":2.4,"tv":74.49,"id":31379}]}]}
{"op":"mcm","clk":"11857324730","pt":1723368304192,"mc":[{"id":"1.231582255","rc":[{"batb":[[0,2.36,10]],"ltp":2.4,"tv":74.49,"id":31379}]}]}
{"op":"mcm","clk":"11857325112","pt":1723368308408,"mc":[{"id":"1.231582255","rc":[{"batb":[[0,2.38,4],[1,2.36,10],[2,2.32,13.64]],"ltp":2.4,"tv":74.49,"id":31379}]}]}
{"op":"mcm","clk":"11857325153","pt":1723368308828,"mc":[{"id":"1.231582255","rc":[{"batb":[[1,2.32,13.64],[2,2.3,13.85]],"ltp":2.4,"tv":74.49,"id":31379}]}]}
{"op":"mcm","clk":"11857325460","pt":1723368311596,"mc":[{"id":"1.231582255","rc":[{"batb":[[0,2.4,10],[1,2.38,4],[2,2.32,13.64]],"ltp":2.4,"tv":74.49,"id":31379}]}]}
{"op":"mcm","clk":"11857325657","pt":1723368313734,"mc":[{"id":"1.231582255","rc":[{"batb":[[1,2.32,13.64],[2,2.3,13.85]],"ltp":2.4,"tv":74.49,"id":31379}]}]}
{"op":"mcm","clk":"11857325935","pt":1723368316648,"mc":[{"id":"1.231582255","rc":[{"batb":[[0,2.42,4],[1,2.4,10],[2,2.32,13.64]],"ltp":2.4,"tv":74.49,"id":31379}]}]}
{"op":"mcm","clk":"11857326251","pt":1723368319931,"mc":[{"id":"1.231582255","rc":[{"batb":[[1,2.32,13.64],[2,2.3,13.85]],"ltp":2.4,"tv":74.49,"id":31379}]}]}
{"op":"mcm","clk":"11857326712","pt":1723368324348,"mc":[{"id":"1.231582255","rc":[{"batb":[[0,2.3,13.85],[1,1.74,6.7],[2,1.3,1000]],"ltp":2.4,"tv":74.49,"id":31379}]}]}
{"op":"mcm","clk":"11857326837","pt":1723368325843,"mc":[{"id":"1.231582255","rc":[{"batb":[[1,2.28,5],[2,1.74,6.7]],"ltp":2.4,"tv":74.49,"id":31379}]}]}
{"op":"mcm","clk":"11857326989","pt":1723368327824,"mc":[{"id":"1.231582255","rc":[{"batb":[[0,2.44,14],[1,2.3,13.85],[2,2.28,5]],"ltp":2.4,"tv":74.49,"id":31379}]}]}
{"op":"mcm","clk":"11857327170","pt":1723368329848,"mc":[{"id":"1.231582255","rc":[{"batb":[[1,2.32,13.64],[2,2.3,13.85]],"ltp":2.4,"tv":74.49,"id":31379}]}]}
{"op":"mcm","clk":"11857327778","pt":1723368336542,"mc":[{"id":"1.231582255","rc":[{"batb":[[0,2.44,10]],"ltp":2.4,"tv":74.49,"id":31379}]}]}
{"op":"mcm","clk":"11857327953","pt":1723368338377,"mc":[{"id":"1.231582255","rc":[{"batb":[[0,2.3,13.85],[1,1.74,6.7],[2,1.3,1000]],"ltp":2.4,"tv":74.49,"id":31379}]}]}
{"op":"mcm","clk":"11857328040","pt":1723368339259,"mc":[{"id":"1.231582255","rc":[{"batb":[[0,2.46,4],[1,2.3,13.85],[2,1.74,6.7]],"ltp":2.4,"tv":74.49,"id":31379}]}]}
{"op":"mcm","clk":"11857328197","pt":1723368341050,"mc":[{"id":"1.231582255","rc":[{"batb":[[2,2.28,5]],"ltp":2.4,"tv":74.49,"id":31379}]}]}
{"op":"mcm","clk":"11857328267","pt":1723368341880,"mc":[{"id":"1.231582255","rc":[{"batb":[[1,2.32,13.64],[2,2.3,13.85]],"ltp":2.4,"tv":74.49,"id":31379}]}]}
{"op":"mcm","clk":"11857328370","pt":1723368343068,"mc":[{"id":"1.231582255","rc":[{"batb":[[0,2.46,14]],"ltp":2.4,"tv":74.49,"id":31379}]}]}
{"op":"mcm","clk":"11857328881","pt":1723368348256,"mc":[{"id":"1.231582255","rc":[{"batb":[[0,2.46,10]],"ltp":2.4,"tv":74.49,"id":31379}]}]}
{"op":"mcm","clk":"11857329322","pt":1723368353386,"mc":[{"id":"1.231582255","rc":[{"batb":[[0,2.3,13.85],[1,1.74,6.7],[2,1.3,1000]],"ltp":2.4,"tv":74.49,"id":31379}]}]}
{"op":"mcm","clk":"11857329550","pt":1723368356188,"mc":[{"id":"1.231582255","rc":[{"batb":[[1,2.28,5],[2,1.74,6.7]],"ltp":2.4,"tv":74.49,"id":31379}]}]}
{"op":"mcm","clk":"11857329654","pt":1723368357594,"mc":[{"id":"1.231582255","rc":[{"batb":[[0,2.34,14],[1,2.3,13.85],[2,2.28,5]],"ltp":2.4,"tv":74.49,"id":31379}]}]}
{"op":"mcm","clk":"11857329847","pt":1723368359902,"mc":[{"id":"1.231582255","rc":[{"batb":[[1,2.32,13.64],[2,2.3,13.85]],"ltp":2.4,"tv":74.49,"id":31379}]}]}
{"op":"mcm","clk":"11857330345","pt":1723368364676,"mc":[{"id":"1.231582255","rc":[{"batb":[[0,2.34,10]],"ltp":2.4,"tv":74.49,"id":31379}]}]}
{"op":"mcm","clk":"11857330521","pt":1723368366282,"mc":[{"id":"1.231582255","rc":[{"batb":[[0,2.3,13.85],[1,2.28,5],[2,1.74,6.7]],"ltp":2.4,"tv":74.49,"id":31379}]}]}
{"op":"mcm","clk":"11857330852","pt":1723368369219,"mc":[{"id":"1.231582255","rc":[{"batb":[[0,2.36,14],[1,2.3,13.85],[2,2.28,5]],"ltp":2.4,"tv":74.49,"id":31379}]}]}
{"op":"mcm","clk":"11857331007","pt":1723368371338,"mc":[{"id":"1.231582255","rc":[{"batb":[[2,1.74,6.7]],"ltp":2.4,"tv":74.49,"id":31379}]}]}
{"op":"mcm","clk":"11857331051","pt":1723368371807,"mc":[{"id":"1.231582255","rc":[{"batb":[[1,2.32,13.64],[2,2.3,13.85]],"ltp":2.4,"tv":74.49,"id":31379}]}]}
{"op":"mcm","clk":"11857331570","pt":1723368377329,"mc":[{"id":"1.231582255","rc":[{"batb":[[0,2.36,10]],"ltp":2.4,"tv":74.49,"id":31379}]}]}
{"op":"mcm","clk":"11857331652","pt":1723368378212,"mc":[{"id":"1.231582255","rc":[{"batb":[[0,2.32,13.64],[1,2.3,13.85],[2,1.74,6.7]],"ltp":2.4,"tv":74.49,"id":31379}]}]}
{"op":"mcm","clk":"11857331708","pt":1723368378934,"mc":[{"id":"1.231582255","rc":[{"batb":[[0,2.3,13.85],[1,1.74,6.7],[2,1.3,1000]],"ltp":2.4,"tv":74.49,"id":31379}]}]}
{"op":"mcm","clk":"11857331897","pt":1723368381322,"mc":[{"id":"1.231582255","rc":[{"batb":[[1,2.28,5],[2,1.74,6.7]],"ltp":2.4,"tv":74.49,"id":31379}]}]}
{"op":"mcm","clk":"11857332093","pt":1723368383736,"mc":[{"id":"1.231582255","rc":[{"batb":[[0,2.38,14],[1,2.3,13.85],[2,2.28,5]],"ltp":2.4,"tv":74.49,"id":31379}]}]}
{"op":"mcm","clk":"11857332311","pt":1723368386330,"mc":[{"id":"1.231582255","rc":[{"batb":[[1,2.32,13.64],[2,2.3,13.85]],"ltp":2.4,"tv":74.49,"id":31379}]}]}
{"op":"mcm","clk":"11857332946","pt":1723368394139,"mc":[{"id":"1.231582255","rc":[{"batb":[[0,2.38,10]],"ltp":2.4,"tv":74.49,"id":31379}]}]}
{"op":"mcm","clk":"11857333031","pt":1723368395330,"mc":[{"id":"1.231582255","rc":[{"batb":[[0,2.3,13.85],[1,1.74,6.7],[2,1.3,1000]],"ltp":2.4,"tv":74.49,"id":31379}]}]}
{"op":"mcm","clk":"11857333101","pt":1723368396459,"mc":[{"id":"1.231582255","rc":[{"batb":[[1,2.28,5],[2,1.74,6.7]],"ltp":2.4,"tv":74.49,"id":31379}]}]}
{"op":"mcm","clk":"11857333566","pt":1723368401967,"mc":[{"id":"1.231582255","rc":[{"batb":[[0,2.4,14],[1,2.3,13.85],[2,2.28,5]],"ltp":2.4,"tv":74.49,"id":31379}]}]}
{"op":"mcm","clk":"11857333747","pt":1723368403857,"mc":[{"id":"1.231582255","rc":[{"batb":[[1,2.32,13.64],[2,2.3,13.85]],"ltp":2.4,"tv":74.49,"id":31379}]}]}
{"op":"mcm","clk":"11857334417","pt":1723368410849,"mc":[{"id":"1.231582255","rc":[{"batb":[[0,2.4,10]],"ltp":2.4,"tv":74.49,"id":31379}]}]}
{"op":"mcm","clk":"11857334546","pt":1723368412452,"mc":[{"id":"1.231582255","rc":[{"batb":[[0,2.3,13.85],[1,1.74,6.7],[2,1.3,1000]],"ltp":2.4,"tv":74.49,"id":31379}]}]}
{"op":"mcm","clk":"11857334817","pt":1723368415560,"mc":[{"id":"1.231582255","rc":[{"batb":[[0,2.42,14],[1,2.3,13.85],[2,1.74,6.7]],"ltp":2.4,"tv":74.49,"id":31379}]}]}
{"op":"mcm","clk":"11857334984","pt":1723368417883,"mc":[{"id":"1.231582255","rc":[{"batb":[[1,2.32,13.64],[2,2.3,13.85]],"ltp":2.4,"tv":74.49,"id":31379}]}]}
{"op":"mcm","clk":"11857343549","pt":1723368516132,"mc":[{"id":"1.231582255","rc":[{"batl":[[1,1000,0.02],[2,1000,0]],"ltp":2.4,"tv":74.49,"id":31379}]}]}
{"op":"mcm","clk":"11857343591","pt":1723368516553,"mc":[{"id":"1.231582255","rc":[{"batb":[[2,1.3,1000]],"ltp":1.72,"tv":123.05,"id":424676}]}]}
{"op":"mcm","clk":"11857350202","pt":1723368596936,"mc":[{"id":"1.231582255","rc":[{"batl":[[0,1.75,5],[1,1.8,13.4],[2,1000,0.02]],"ltp":1.72,"tv":123.05,"id":424676}]}]}
{"op":"mcm","clk":"11857351616","pt":1723368609495,"mc":[{"id":"1.231582255","rc":[{"batb":[[1,1.3,1000],[2,1.08,7.85]],"batl":[[1,1000,0.02],[2,1000,0]],"ltp":1.72,"tv":123.05,"id":424676}]}]}
{"op":"mcm","clk":"11857351732","pt":1723368610532,"mc":[{"id":"1.231582255","rc":[{"batb":[[1,1.3,1060.03]],"ltp":1.72,"tv":123.05,"id":424676}]}]}
{"op":"mcm","clk":"11857351859","pt":1723368611527,"mc":[{"id":"1.231582255","rc":[{"batb":[[1,1.3,1000],[2,1.08,7.85]],"ltp":2.4,"tv":74.49,"id":31379},{"batb":[[0,1.56,2.72]],"ltp":1.72,"tv":123.05,"id":424676}]}]}
{"op":"mcm","clk":"11857351982","pt":1723368612424,"mc":[{"id":"1.231582255","rc":[{"batb":[[1,2.28,5],[2,1.3,1000]],"ltp":2.4,"tv":74.49,"id":31379},{"batb":[[1,1.3,1000]],"ltp":1.72,"tv":123.05,"id":424676}]}]}
{"op":"mcm","clk":"11857352208","pt":1723368614558,"mc":[{"id":"1.231582255","rc":[{"batb":[[1,1.3,1060.03]],"ltp":1.72,"tv":123.05,"id":424676}]}]}
{"op":"mcm","clk":"11857388417","pt":1723368959362,"mc":[{"id":"1.231582255","rc":[{"batb":[[0,1.56,3.63]],"ltp":1.72,"tv":123.05,"id":424676}]}]}
{"op":"mcm","clk":"11857388637","pt":1723368961282,"mc":[{"id":"1.231582255","rc":[{"trd":[[2.42,28]],"batb":[[0,2.28,5],[1,1.3,1000],[2,1.08,7.85]],"batl":[[0,2.42,36],[1,2.8,5],[2,1000,0.02]],"ltp":2.42,"tv":102.49,"id":31379},{"batb":[[1,1.3,1000]],"ltp":1.72,"tv":123.05,"id":424676}],"tv":225.54}]}
{"op":"mcm","clk":"11857388802","pt":1723368962898,"mc":[{"id":"1.231582255","rc":[{"batb":[[0,1.71,2.48],[1,1.3,1000.91]],"ltp":1.72,"tv":123.05,"id":424676}]}]}
{"op":"mcm","clk":"11857389752","pt":1723368972425,"mc":[{"id":"1.231582255","rc":[{"trd":[[1.71,3.65]],"batb":[[0,1.58,1.56],[1,1.3,1000]],"ltp":1.71,"tv":126.7,"id":424676}],"tv":229.19}]}
{"op":"mcm","clk":"11857389958","pt":1723368974303,"mc":[{"id":"1.231582255","rc":[{"batb":[[0,1.3,1000.91],[1,1.08,7.85],[2,1.07,7.85]],"ltp":1.71,"tv":126.7,"id":424676}]}]}
{"op":"mcm","clk":"11857392708","pt":1723368999435,"mc":[{"id":"1.231582255","rc":[{"batb":[[0,1.3,1000]],"ltp":1.71,"tv":126.7,"id":424676}]}]}
{"op":"mcm","clk":"11857392718","pt":1723368999537,"mc":[{"id":"1.231582255","rc":[{"batb":[[0,1.66,1.87],[1,1.3,1000],[2,1.08,7.85]],"ltp":1.71,"tv":126.7,"id":424676}]}]}
{"op":"mcm","clk":"11857406890","pt":1723369132475,"mc":[{"id":"1.231582255","rc":[{"trd":[[2.32,156.32]],"ltp":2.32,"tv":198.72,"id":31379},{"trd":[[1.75,101.67]],"batl":[[0,1000,0.02],[1,1000,0]],"ltp":1.75,"tv":131.7,"id":424676}],"tv":330.42}]}
{"op":"mcm","clk":"11857407054","pt":1723369133757,"mc":[{"id":"1.231582255","rc":[{"batb":[[1,1.38,21.99],[2,1.3,1000]],"ltp":2.32,"tv":198.72,"id":31379}]}]}
{"op":"mcm","clk":"11857407548","pt":1723369138686,"mc":[{"id":"1.231582255","rc":[{"batb":[[1,1.52,9.43],[2,1.38,21.99]],"ltp":2.32,"tv":198.72,"id":31379}]}]}
{"op":"mcm","clk":"11857408599","pt":1723369147965,"mc":[{"id":"1.231582255","rc":[{"batl":[[0,2.32,50],[1,2.42,36],[2,2.8,5]],"ltp":2.32,"tv":198.72,"id":31379}]}]}
{"op":"mcm","clk":"11857408820","pt":1723369149782,"mc":[{"id":"1.231582255","rc":[{"batb":[[1,1.58,6.28],[2,1.52,9.43]],"ltp":2.32,"tv":198.72,"id":31379}]}]}
{"op":"mcm","clk":"11857410166","pt":1723369162090,"mc":[{"id":"1.231582255","rc":[{"batl":[[0,2.42,36],[1,2.8,5],[2,1000,0.02]],"ltp":2.32,"tv":198.72,"id":31379},{"batb":[[1,1.32,11],[2,1.3,1000]],"ltp":1.75,"tv":131.7,"id":424676}]}]}
{"op":"mcm","clk":"11857411232","pt":1723369172415,"mc":[{"id":"1.231582255","rc":[{"batb":[[0,1.66,2.78]],"ltp":1.75,"tv":131.7,"id":424676}]}]}
{"op":"mcm","clk":"11857411651","pt":1723369176702,"mc":[{"id":"1.231582255","rc":[{"batb":[[0,1.32,11.91],[1,1.3,1000],[2,1.08,7.85]],"ltp":1.75,"tv":131.7,"id":424676}]}]}
{"op":"mcm","clk":"11857412548","pt":1723369185524,"mc":[{"id":"1.231582255","rc":[{"batb":[[1,1.76,6.18],[2,1.58,6.28]],"batl":[[2,3.2,3.61]],"ltp":2.32,"tv":198.72,"id":31379},{"batb":[[0,1.55,7.2],[1,1.32,11],[2,1.3,1000]],"ltp":1.75,"tv":131.7,"id":424676}]}]}
{"op":"mcm","clk":"11857412983","pt":1723369190034,"mc":[{"id":"1.231582255","rc":[{"batb":[[1,1.76,6.97]],"ltp":2.32,"tv":198.72,"id":31379}]}]}
{"op":"mcm","clk":"11857413986","pt":1723369200442,"mc":[{"id":"1.231582255","rc":[{"batb":[[0,2.28,61]],"ltp":2.32,"tv":198.72,"id":31379},{"batb":[[0,1.68,115.73],[1,1.55,6.28],[2,1.32,11]],"ltp":1.75,"tv":131.7,"id":424676}]}]}
{"op":"mcm","clk":"11857414163","pt":1723369202023,"mc":[{"id":"1.231582255","rc":[{"batb":[[2,1.46,7.85]],"ltp":1.75,"tv":131.7,"id":424676}]}]}
{"op":"mcm","clk":"11857414252","pt":1723369202821,"mc":[{"id":"1.231582255","rc":[{"batb":[[1,2.26,14.3],[2,1.76,6.97]],"ltp":2.32,"tv":198.72,"id":31379},{"batb":[[0,1.69,27.01],[1,1.68,114.82],[2,1.55,6.28]],"ltp":1.75,"tv":131.7,"id":424676}]}]}
{"op":"mcm","clk":"11857415624","pt":1723369216548,"mc":[{"id":"1.231582255","rc":[{"batb":[[2,1.78,2.36]],"ltp":2.32,"tv":198.72,"id":31379}]}]}
{"op":"mcm","clk":"11857415759","pt":1723369217849,"mc":[{"id":"1.231582255","rc":[{"batb":[[2,1.78,8.54]],"ltp":2.32,"tv":198.72,"id":31379}]}]}
{"op":"mcm","clk":"11857416098","pt":1723369221436,"mc":[{"id":"1.231582255","rc":[{"batb":[[2,1.78,3.14]],"ltp":2.32,"tv":198.72,"id":31379}]}]}
{"op":"mcm","clk":"11857416107","pt":1723369221545,"mc":[{"id":"1.231582255","rc":[{"batb":[[2,1.82,6.97]],"ltp":2.32,"tv":198.72,"id":31379}]}]}
{"op":"mcm","clk":"11857417858","pt":1723369238197,"mc":[{"id":"1.231582255","rc":[{"batl":[[0,2.36,15],[1,2.42,36],[2,2.8,5]],"ltp":2.32,"tv":198.72,"id":31379}]}]}
{"op":"mcm","clk":"11857417923","pt":1723369238871,"mc":[{"id":"1.231582255","rc":[{"batb":[[0,1.7,26.64],[1,1.69,26.1],[2,1.68,114.82]],"ltp":1.75,"tv":131.7,"id":424676}]}]}
{"op":"mcm","clk":"11857418431","pt":1723369243565,"mc":[{"id":"1.231582255","rc":[{"trd":[[2.28,24]],"batb":[[0,2.28,49]],"ltp":2.28,"tv":222.72,"id":31379}],"tv":354.42}]}
{"op":"mcm","clk":"11857418644","pt":1723369245791,"mc":[{"id":"1.231582255","rc":[{"batb":[[0,2.28,61]],"ltp":2.28,"tv":222.72,"id":31379}]}]}
{"op":"mcm","clk":"11857420742","pt":1723369264510,"mc":[{"id":"1.231582255","rc":[{"trd":[[2.28,144]],"batb":[[0,2.28,1]],"ltp":2.28,"tv":342.72,"id":31379}],"tv":474.42}]}
{"op":"mcm","clk":"11857420788","pt":1723369264888,"mc":[{"id":"1.231582255","rc":[{"batb":[[1,1.82,6.97],[2,1.78,2.36]],"ltp":2.28,"tv":342.72,"id":31379},{"batb":[[0,1.68,115.73],[1,1.55,6.28],[2,1.46,7.85]],"ltp":1.75,"tv":131.7,"id":424676}]}]}
{"op":"mcm","clk":"11857420888","pt":1723369265870,"mc":[{"id":"1.231582255","rc":[{"batb":[[0,1.82,6.97],[1,1.78,2.36],[2,1.58,6.28]],"ltp":2.28,"tv":342.72,"id":31379}]}]}
{"op":"mcm","clk":"11857422034","pt":1723369276317,"mc":[{"id":"1.231582255","rc":[{"batb":[[0,1.86,13.25],[1,1.78,3.14]],"ltp":2.28,"tv":342.72,"id":31379}]}]}
{"op":"mcm","clk":"11857423026","pt":1723369285429,"mc":[{"id":"1.231582255","rc":[{"batb":[[0,1.68,114.82]],"ltp":1.75,"tv":131.7,"id":424676}]}]}
{"op":"mcm","clk":"11857423048","pt":1723369285593,"mc":[{"id":"1.231582255","rc":[{"batb":[[0,1.68,115.73]],"ltp":1.75,"tv":131.7,"id":424676}]}]}
{"op":"mcm","clk":"11857423710","pt":1723369292039,"mc":[{"id":"1.231582255","rc":[{"batb":[[0,1.9,6.97],[1,1.86,7.07],[2,1.78,3.14]],"ltp":2.28,"tv":342.72,"id":31379}]}]}
{"op":"mcm","clk":"11857424161","pt":1723369296207,"mc":[{"id":"1.231582255","rc":[{"batb":[[0,1.92,4.71],[1,1.9,6.97],[2,1.86,7.07]],"ltp":2.28,"tv":342.72,"id":31379}]}]}
{"op":"mcm","clk":"11857424259","pt":1723369297038,"mc":[{"id":"1.231582255","rc":[{"batb":[[0,1.92,10.89],[1,1.86,7.85],[2,1.78,3.14]],"ltp":2.28,"tv":342.72,"id":31379},{"batb":[[0,1.7,26.64],[1,1.68,114.82],[2,1.55,6.28]],"ltp":1.75,"tv":131.7,"id":424676}]}]}
{"op":"mcm","clk":"11857424335","pt":1723369297720,"mc":[{"id":"1.231582255","rc":[{"batb":[[1,1.9,1.7],[2,1.86,7.07]],"ltp":2.28,"tv":342.72,"id":31379}]}]}
{"op":"mcm","clk":"11857425141","pt":1723369305441,"mc":[{"id":"1.231582255","rc":[{"batb":[[0,1.92,11.81],[1,1.86,7.85],[2,1.78,3.14]],"ltp":2.28,"tv":342.72,"id":31379}]}]}
{"op":"mcm","clk":"11857426013","pt":1723369313267,"mc":[{"id":"1.231582255","rc":[{"batb":[[1,1.86,1.57]],"ltp":2.28,"tv":342.72,"id":31379}]}]}
{"op":"mcm","clk":"11857426703","pt":1723369319271,"mc":[{"id":"1.231582255","rc":[{"batb":[[0,1.75,20],[1,1.7,26.64],[2,1.68,114.82]],"ltp":1.75,"tv":131.7,"id":424676}]}]}
{"op":"mcm","clk":"11857426795","pt":1723369320164,"mc":[{"id":"1.231582255","rc":[{"batb":[[0,1.75,70]],"ltp":1.75,"tv":131.7,"id":424676}]}]}
{"op":"mcm","clk":"11857426871","pt":1723369320886,"mc":[{"id":"1.231582255","rc":[{"batb":[[1,1.73,25.59],[2,1.7,25.73]],"ltp":1.75,"tv":131.7,"id":424676}]}]}
{"op":"mcm","clk":"11857426993","pt":1723369321881,"mc":[{"id":"1.231582255","rc":[{"batb":[[1,1.74,25.25],[2,1.73,24.67]],"ltp":1.75,"tv":131.7,"id":424676}]}]}
{"op":"mcm","clk":"11857428881","pt":1723369337736,"mc":[{"id":"1.231582255","rc":[{"batl":[[0,1.9,1],[1,1000,0.02]],"ltp":1.75,"tv":131.7,"id":424676}]}]}
{"op":"mcm","clk":"11857430490","pt":1723369351307,"mc":[{"id":"1.231582255","rc":[{"batb":[[0,2,4],[1,1.92,11.81],[2,1.86,1.57]],"ltp":2.28,"tv":342.72,"id":31379}]}]}
{"op":"mcm","clk":"11857431148","pt":1723369357503,"mc":[{"id":"1.231582255","rc":[{"batb":[[0,1.75,70.91],[1,1.74,24.34]],"ltp":1.75,"tv":131.7,"id":424676}]}]}
{"op":"mcm","clk":"11857444915","pt":1723369375146,"mc":[{"id":"1.231582255","rc":[{"batb":[[0,1.92,11.81],[1,1.86,1.57],[2,1.78,3.14]],"ltp":2.28,"tv":342.72,"id":31379}]}]}
{"op":"mcm","clk":"11857448145","pt":1723369404162,"mc":[{"id":"1.231582255","rc":[{"batl":[[1,2.8,5],[2,3.2,3.61]],"ltp":2.28,"tv":342.72,"id":31379}]}]}
{"op":"mcm","clk":"11857449068","pt":1723369412482,"mc":[{"id":"1.231582255","rc":[{"batl":[[0,2.32,50],[1,2.36,15],[2,2.8,5]],"ltp":2.28,"tv":342.72,"id":31379}]}]}
{"op":"mcm","clk":"11857455245","pt":1723369472117,"mc":[{"id":"1.231582255","rc":[{"batb":[[0,2.3,3.14],[1,1.92,11.81],[2,1.86,1.57]],"ltp":2.28,"tv":342.72,"id":31379}]}]}
{"op":"mcm","clk":"11857456942","pt":1723369487056,"mc":[{"id":"1.231582255","rc":[{"batb":[[0,1.92,11.81],[1,1.86,1.57],[2,1.78,3.14]],"ltp":2.28,"tv":342.72,"id":31379}]}]}
{"op":"mcm","clk":"11857460792","pt":1723369522214,"mc":[{"id":"1.231582255","rc":[{"trd":[[1.89,4.72]],"ltp":1.89,"tv":136.42,"id":424676}],"tv":479.14}]}
{"op":"mcm","clk":"11857462585","pt":1723369539432,"mc":[{"id":"1.231582255","rc":[{"trd":[[1.89,9.43]],"ltp":1.89,"tv":141.13,"id":424676}],"tv":483.86}]}
{"op":"mcm","clk":"11857462771","pt":1723369541318,"mc":[{"id":"1.231582255","rc":[{"batl":[[1,2.8,5],[2,3.2,3.61]],"ltp":2.28,"tv":342.72,"id":31379}]}]}
{"op":"mcm","clk":"11857463080","pt":1723369544720,"mc":[{"id":"1.231582255","rc":[{"batb":[[0,2.04,4],[1,1.92,11.81],[2,1.86,1.57]],"ltp":2.28,"tv":342.72,"id":31379}]}]}
{"op":"mcm","clk":"11857464606","pt":1723369560015,"mc":[{"id":"1.231582255","rc":[{"batb":[[0,1.88,3.93],[1,1.75,70.91],[2,1.74,24.34]],"ltp":1.89,"tv":141.13,"id":424676}]}]}
{"op":"mcm","clk":"11857464711","pt":1723369561055,"mc":[{"id":"1.231582255","rc":[{"batb":[[1,1.75,94.93]],"ltp":1.89,"tv":141.13,"id":424676}]}]}
{"op":"mcm","clk":"11857465497","pt":1723369568431,"mc":[{"id":"1.231582255","rc":[{"batb":[[0,1.92,11.81],[1,1.86,1.57],[2,1.78,3.14]],"ltp":2.28,"tv":342.72,"id":31379}]}]}
{"op":"mcm","clk":"11857465511","pt":1723369568540,"mc":[{"id":"1.231582255","rc":[{"batb":[[0,2.06,4],[1,1.92,11.81],[2,1.86,1.57]],"ltp":2.28,"tv":342.72,"id":31379}]}]}
{"op":"mcm","clk":"11857466741","pt":1723369579681,"mc":[{"id":"1.231582255","rc":[{"trd":[[2.14,3]],"ltp":2.14,"tv":345.72,"id":31379},{"trd":[[1.88,3.42]],"batb":[[0,1.76,1.42],[1,1.75,94.01]],"ltp":1.88,"tv":144.55,"id":424676}],"tv":490.27}]}
{"op":"mcm","clk":"11857467181","pt":1723369584096,"mc":[{"id":"1.231582255","rc":[{"batb":[[0,1.75,70.91],[1,1.74,24.34],[2,1.73,24.67]],"ltp":1.88,"tv":144.55,"id":424676}]}]}
{"op":"mcm","clk":"11857467477","pt":1723369586897,"mc":[{"id":"1.231582255","rc":[{"batb":[[0,1.92,11.81],[1,1.86,1.57],[2,1.78,3.14]],"ltp":2.14,"tv":345.72,"id":31379}]}]}
{"op":"mcm","clk":"11857469194","pt":1723369603079,"mc":[{"id":"1.231582255","rc":[{"batl":[[0,2.3,20],[1,2.32,50],[2,2.8,5]],"ltp":2.14,"tv":345.72,"id":31379},{"batb":[[0,1.75,94.93]],"ltp":1.88,"tv":144.55,"id":424676}]}]}
{"op":"mcm","clk":"11857469341","pt":1723369604390,"mc":[{"id":"1.231582255","rc":[{"batl":[[1,1000,0.12]],"ltp":1.88,"tv":144.55,"id":424676}]}]}
{"op":"mcm","clk":"11857471069","pt":1723369620232,"mc":[{"id":"1.231582255","rc":[{"batl":[[0,2.3,20.1]],"ltp":2.14,"tv":345.72,"id":31379}]}]}
{"op":"mcm","clk":"11857472571","pt":1723369633299,"mc":[{"id":"1.231582255","rc":[{"batl":[[1,1000,0.22]],"ltp":1.88,"tv":144.55,"id":424676}]}]}
{"op":"mcm","clk":"11857473510","pt":1723369641303,"mc":[{"id":"1.231582255","rc":[{"batl":[[0,2.3,23.75]],"ltp":2.14,"tv":345.72,"id":31379}]}]}
{"op":"mcm","clk":"11857473840","pt":1723369644128,"mc":[{"id":"1.231582255","rc":[{"batb":[[0,1.88,3.14],[1,1.75,94.93],[2,1.74,24.34]],"ltp":1.88,"tv":144.55,"id":424676}]}]}
{"op":"mcm","clk":"11857473955","pt":1723369645121,"mc":[{"id":"1.231582255","rc":[{"batb":[[1,1.76,24.61],[2,1.75,94.01]],"ltp":1.88,"tv":144.55,"id":424676}]}]}
{"op":"mcm","clk":"11857474523","pt":1723369650127,"mc":[{"id":"1.231582255","rc":[{"batl":[[0,2.3,3.75]],"ltp":2.14,"tv":345.72,"id":31379}]}]}
{"op":"mcm","clk":"11857474589","pt":1723369650646,"mc":[{"id":"1.231582255","rc":[{"batb":[[1,1.75,94.93],[2,1.74,24.34]],"ltp":1.88,"tv":144.55,"id":424676}]}]}
{"op":"mcm","clk":"11857475014","pt":1723369654416,"mc":[{"id":"1.231582255","rc":[{"batl":[[0,2.3,3.65]],"ltp":2.14,"tv":345.72,"id":31379},{"batl":[[1,1000,0.02]],"ltp":1.88,"tv":144.55,"id":424676}]}]}
{"op":"mcm","clk":"11857475093","pt":1723369655356,"mc":[{"id":"1.231582255","rc":[{"batb":[[0,2.1,2],[1,1.92,11.81],[2,1.86,1.57]],"ltp":2.14,"tv":345.72,"id":31379}]}]}
{"op":"mcm","clk":"11857475523","pt":1723369658739,"mc":[{"id":"1.231582255","rc":[{"batb":[[0,1.75,94.93],[1,1.74,24.34],[2,1.73,24.67]],"ltp":1.88,"tv":144.55,"id":424676}]}]}
{"op":"mcm","clk":"11857476206","pt":1723369665397,"mc":[{"id":"1.231582255","rc":[{"batb":[[0,1.92,11.81],[1,1.86,1.57],[2,1.78,3.14]],"ltp":2.14,"tv":345.72,"id":31379}]}]}
{"op":"mcm","clk":"11857477400","pt":1723369676098,"mc":[{"id":"1.231582255","rc":[{"batl":[[1,1000,0.12]],"ltp":1.88,"tv":144.55,"id":424676}]}]}
{"op":"mcm","clk":"11857478777","pt":1723369687608,"mc":[{"id":"1.231582255","rc":[{"batb":[[0,2.28,3.14],[1,1.92,11.81],[2,1.86,1.57]],"ltp":2.14,"tv":345.72,"id":31379}]}]}
{"op":"mcm","clk":"11857479065","pt":1723369690143,"mc":[{"id":"1.231582255","rc":[{"batl":[[1,1000,0.22]],"ltp":1.88,"tv":144.55,"id":424676}]}]}
{"op":"mcm","clk":"11857479984","pt":1723369697790,"mc":[{"id":"1.231582255","rc":[{"batb":[[1,1.95,1.7],[2,1.92,10.89]],"ltp":2.14,"tv":345.72,"id":31379}]}]}
{"op":"mcm","clk":"11857480637","pt":1723369703505,"mc":[{"id":"1.231582255","rc":[{"trd":[[2.28,147.41]],"batb":[[0,1.95,1.7],[1,1.92,10.89],[2,1.82,1.57]],"ltp":2.28,"tv":349.13,"id":31379},{"trd":[[1.79,3.65]],"ltp":1.79,"tv":148.2,"id":424676}],"tv":497.33}]}
{"op":"mcm","clk":"11857481256","pt":1723369708414,"mc":[{"id":"1.231582255","rc":[{"batb":[[0,1.92,11.68],[1,1.82,1.57],[2,1.78,2.36]],"ltp":2.28,"tv":349.13,"id":31379}]}]}
{"op":"mcm","clk":"11857481755","pt":1723369712785,"mc":[{"id":"1.231582255","rc":[{"batb":[[0,1.75,94.01]],"ltp":1.79,"tv":148.2,"id":424676}]}]}
{"op":"mcm","clk":"11857482591","pt":1723369720904,"mc":[{"id":"1.231582255","rc":[{"trd":[[2.1,0.1]],"ltp":2.1,"tv":349.23,"id":31379},{"trd":[[1.9,0.11]],"batl":[[0,2.06,1.09],[1,1000,0.02]],"ltp":1.9,"tv":148.31,"id":424676}],"tv":497.54}]}
{"op":"mcm","clk":"11857482882","pt":1723369723770,"mc":[{"id":"1.231582255","rc":[{"batb":[[0,2.22,64],[1,1.92,11.68],[2,1.82,1.57]],"ltp":2.1,"tv":349.23,"id":31379},{"batb":[[0,1.75,198.12]],"ltp":1.9,"tv":148.31,"id":424676}]}]}
{"op":"mcm","clk":"11857483099","pt":1723369726136,"mc":[{"id":"1.231582255","rc":[{"batb":[[1,2.2,15.01],[2,1.92,11.68]],"ltp":2.1,"tv":349.23,"id":31379}]}]}
{"op":"mcm","clk":"11857484230","pt":1723369736711,"mc":[{"id":"1.231582255","rc":[{"batl":[[0,1.92,2.66],[1,1000,0.22]],"ltp":1.9,"tv":148.31,"id":424676}]}]}
{"op":"mcm","clk":"11857485049","pt":1723369744337,"mc":[{"id":"1.231582255","rc":[{"batl":[[0,2.06,1.09],[1,1000,0.02]],"ltp":1.9,"tv":148.31,"id":424676}]}]}
{"op":"mcm","clk":"11857485071","pt":1723369744544,"mc":[{"id":"1.231582255","rc":[{"batl":[[0,1.92,2.66],[1,1000,0.22]],"ltp":1.9,"tv":148.31,"id":424676}]}]}
{"op":"mcm","clk":"11857486558","pt":1723369759254,"mc":[{"id":"1.231582255","rc":[{"batl":[[1,1000,0.02]],"ltp":1.9,"tv":148.31,"id":424676}]}]}
{"op":"mcm","clk":"11857486652","pt":1723369760183,"mc":[{"id":"1.231582255","rc":[{"trd":[[2.22,1.29]],"batb":[[0,2.22,62.71]],"ltp":2.22,"tv":350.52,"id":31379},{"trd":[[1.82,1.57]],"ltp":1.82,"tv":149.88,"id":424676}],"tv":500.41}]}
{"op":"mcm","clk":"11857487087","pt":1723369763967,"mc":[{"id":"1.231582255","rc":[{"batb":[[0,2.22,64]],"ltp":2.22,"tv":350.52,"id":31379}]}]}
{"op":"mcm","clk":"11857488821","pt":1723369780198,"mc":[{"id":"1.231582255","rc":[{"batl":[[1,1000,0.31]],"ltp":1.82,"tv":149.88,"id":424676}]}]}
{"op":"mcm","clk":"11857505862","pt":1723369930304,"mc":[{"id":"1.231582255","rc":[{"batb":[[0,1.92,11.68],[1,1.82,1.57],[2,1.78,2.36]],"ltp":2.22,"tv":350.52,"id":31379},{"batb":[[0,1.75,94.01]],"ltp":1.82,"tv":149.88,"id":424676}]}]}
{"op":"mcm","clk":"11857506419","pt":1723369934958,"mc":[{"id":"1.231582255","rc":[{"trd":[[2.3,0.2]],"batl":[[0,2.3,3.55]],"ltp":2.3,"tv":350.72,"id":31379}],"tv":500.61}]}
{"op":"mcm","clk":"11857507358","pt":1723369942441,"mc":[{"id":"1.231582255","rc":[{"batb":[[0,1.88,3.14],[1,1.75,94.01],[2,1.74,24.34]],"ltp":1.82,"tv":149.88,"id":424676}]}]}
{"op":"mcm","clk":"11857507371","pt":1723369942545,"mc":[{"id":"1.231582255","rc":[{"trd":[[1.88,9.7]],"batb":[[0,1.75,94.01],[1,1.74,24.34],[2,1.73,24.67]],"ltp":1.88,"tv":156.16,"id":424676}],"tv":506.89}]}
{"op":"mcm","clk":"11857508393","pt":1723369950533,"mc":[{"id":"1.231582255","rc":[{"batb":[[0,1.92,11.78]],"ltp":2.3,"tv":350.72,"id":31379}]}]}
{"op":"mcm","clk":"11857510033","pt":1723369963876,"mc":[{"id":"1.231582255","rc":[{"trd":[[1.87,6.28]],"ltp":1.87,"tv":162.44,"id":424676}],"tv":513.17}]}
{"op":"mcm","clk":"11857512145","pt":1723369981365,"mc":[{"id":"1.231582255","rc":[{"trd":[[2.3,7.3],[2.32,168.94]],"batl":[[0,2.32,43.69],[1,2.8,5],[2,3.2,3.61]],"ltp":2.32,"tv":370.44,"id":31379},{"batb":[[0,1.75,70]],"ltp":1.87,"tv":162.44,"id":424676}],"tv":532.89}]}
{"op":"mcm","clk":"11857512662","pt":1723369985471,"mc":[{"id":"1.231582255","rc":[{"batb":[[0,2.3,60.06],[1,1.92,11.78],[2,1.82,1.57]],"ltp":2.32,"tv":370.44,"id":31379}]}]}
{"op":"mcm","clk":"11857512885","pt":1723369987302,"mc":[{"id":"1.231582255","rc":[{"batb":[[1,2.28,14.07],[2,1.92,11.78]],"ltp":2.32,"tv":370.44,"id":31379}]}]}
{"op":"mcm","clk":"11857520050","pt":1723370047484,"mc":[{"id":"1.231582255","rc":[{"trd":[[2.3,8.51]],"batb":[[0,2.3,58.85]],"ltp":2.3,"tv":371.65,"id":31379},{"trd":[[1.77,1.57]],"ltp":1.77,"tv":164.01,"id":424676}],"tv":535.67}]}
{"op":"mcm","clk":"11857520404","pt":1723370050871,"mc":[{"id":"1.231582255","rc":[{"batb":[[0,2.3,60.06]],"ltp":2.3,"tv":371.65,"id":31379}]}]}
{"op":"mcm","clk":"11857523252","pt":1723370077422,"mc":[{"id":"1.231582255","rc":[{"trd":[[2.24,56.84],[2.28,175.56],[2.3,128.63]],"batb":[[0,1.92,11.78],[1,1.82,1.57],[2,1.78,2.36]],"batl":[[0,2.24,885.11],[1,2.32,43.69],[2,2.8,5]],"ltp":2.24,"tv":576.76,"id":31379},{"batb":[[0,1.75,94.01]],"ltp":1.77,"tv":164.01,"id":424676}],"tv":740.78}]}
{"op":"mcm","clk":"11857523451","pt":1723370079395,"mc":[{"id":"1.231582255","rc":[{"batb":[[0,1.79,22.8],[1,1.75,94.01],[2,1.74,24.34]],"ltp":1.77,"tv":164.01,"id":424676}]}]}
{"op":"mcm","clk":"11857524031","pt":1723370084492,"mc":[{"id":"1.231582255","rc":[{"batb":[[0,1.88,3.14],[1,1.79,22.8],[2,1.75,94.01]],"ltp":1.77,"tv":164.01,"id":424676}]}]}
{"op":"mcm","clk":"11857524096","pt":1723370085221,"mc":[{"id":"1.231582255","rc":[{"batb":[[0,1.92,11]],"ltp":2.24,"tv":576.76,"id":31379},{"trd":[[1.88,15.98]],"batb":[[0,1.79,22.8],[1,1.75,94.01],[2,1.74,24.34]],"ltp":1.88,"tv":170.3,"id":424676}],"tv":747.06}]}
{"op":"mcm","clk":"11857524264","pt":1723370086932,"mc":[{"id":"1.231582255","rc":[{"batb":[[0,1.92,6.28]],"ltp":2.24,"tv":576.76,"id":31379}]}]}
{"op":"mcm","clk":"11857525561","pt":1723370098531,"mc":[{"id":"1.231582255","rc":[{"trd":[[1.89,17.29]],"ltp":1.89,"tv":178.15,"id":424676}],"tv":754.92}]}
{"op":"mcm","clk":"11857526300","pt":1723370104321,"mc":[{"id":"1.231582255","rc":[{"trd":[[2.08,0.18],[2.1,0.91]],"batb":[[1,1.89,11.35],[2,1.82,1.57]],"ltp":2.08,"tv":577.75,"id":31379},{"trd":[[1.9,1],[1.92,0.2]],"batl":[[0,1.92,1.57]],"ltp":1.92,"tv":179.24,"id":424676}],"tv":756.99}]}
{"op":"mcm","clk":"11857526792","pt":1723370108252,"mc":[{"id":"1.231582255","rc":[{"batl":[[0,1.92,1.67]],"ltp":1.92,"tv":179.24,"id":424676}]}]}
{"op":"mcm","clk":"11857527406","pt":1723370113329,"mc":[{"id":"1.231582255","rc":[{"batl":[[0,1.92,1.57]],"ltp":1.92,"tv":179.24,"id":424676}]}]}
{"op":"mcm","clk":"11857528761","pt":1723370124087,"mc":[{"id":"1.231582255","rc":[{"batl":[[1,1000,0.41]],"ltp":1.92,"tv":179.24,"id":424676}]}]}
{"op":"mcm","clk":"11857529976","pt":1723370134681,"mc":[{"id":"1.231582255","rc":[{"trd":[[1.91,4.72]],"ltp":1.91,"tv":183.96,"id":424676}],"tv":761.71}]}
{"op":"mcm","clk":"11857530359","pt":1723370138262,"mc":[{"id":"1.231582255","rc":[{"batl":[[2,2.8,17.01]],"ltp":2.08,"tv":577.75,"id":31379},{"batl":[[1,3.55,13.8],[2,1000,0.02]],"ltp":1.91,"tv":183.96,"id":424676}]}]}
{"op":"mcm","clk":"11857531120","pt":1723370145377,"mc":[{"id":"1.231582255","rc":[{"trd":[[1.91,17.28]],"ltp":1.91,"tv":196.52,"id":424676}],"tv":774.27}]}
{"op":"mcm","clk":"11857533152","pt":1723370165605,"mc":[{"id":"1.231582255","rc":[{"batb":[[0,1.92,6.38]],"ltp":2.08,"tv":577.75,"id":31379}]}]}
{"op":"mcm","clk":"11857534058","pt":1723370174705,"mc":[{"id":"1.231582255","rc":[{"trd":[[2.24,64.88]],"batl":[[0,2.24,877.08]],"ltp":2.24,"tv":585.78,"id":31379},{"trd":[[1.8,10]],"ltp":1.8,"tv":206.52,"id":424676}],"tv":792.31}]}
{"op":"mcm","clk":"11857534739","pt":1723370181201,"mc":[{"id":"1.231582255","rc":[{"batl":[[0,1.91,45.08],[1,1.92,1.57],[2,3.55,13.8]],"ltp":1.8,"tv":206.52,"id":424676}]}]}
{"op":"mcm","clk":"11857534790","pt":1723370181622,"mc":[{"id":"1.231582255","rc":[{"trd":[[1.91,75.4]],"batl":[[0,1.91,16.02]],"ltp":1.91,"tv":264.64,"id":424676}],"tv":850.43}]}
{"op":"mcm","clk":"11857535003","pt":1723370183533,"mc":[{"id":"1.231582255","rc":[{"trd":[[2.24,94.01]],"batb":[[0,1.92,25.96]],"batl":[[0,2.24,862.51]],"ltp":2.24,"tv":614.91,"id":31379}],"tv":879.56}]}
{"op":"mcm","clk":"11857536141","pt":1723370194485,"mc":[{"id":"1.231582255","rc":[{"batl":[[0,1.92,1.57],[1,3.55,13.8],[2,1000,0.02]],"ltp":1.91,"tv":264.64,"id":424676}]}]}
{"op":"mcm","clk":"11857536229","pt":1723370195473,"mc":[{"id":"1.231582255","rc":[{"trd":[[2.22,4.43]],"batb":[[0,1.92,6.38]],"ltp":2.22,"tv":618.05,"id":31379}],"tv":882.7}]}
{"op":"mcm","clk":"11857536547","pt":1723370198852,"mc":[{"id":"1.231582255","rc":[{"batl":[[1,2.8,17.01],[2,3.2,3.61]],"ltp":2.22,"tv":618.05,"id":31379}]}]}
{"op":"mcm","clk":"11857536615","pt":1723370199680,"mc":[{"id":"1.231582255","rc":[{"batb":[[0,2,3.82],[1,1.92,6.38],[2,1.89,11.35]],"ltp":2.22,"tv":618.05,"id":31379}]}]}
{"op":"mcm","clk":"11857536804","pt":1723370201453,"mc":[{"id":"1.231582255","rc":[{"batb":[[2,1.89,31.59]],"ltp":2.22,"tv":618.05,"id":31379}]}]}
{"op":"mcm","clk":"11857537224","pt":1723370205465,"mc":[{"id":"1.231582255","rc":[{"batb":[[0,1.92,6.38],[1,1.89,11.35],[2,1.82,1.57]],"ltp":2.22,"tv":618.05,"id":31379}]}]}
{"op":"mcm","clk":"11857537583","pt":1723370208888,"mc":[{"id":"1.231582255","rc":[{"batb":[[0,1.92,6.48]],"ltp":2.22,"tv":618.05,"id":31379}]}]}
{"op":"mcm","clk":"11857537985","pt":1723370212888,"mc":[{"id":"1.231582255","rc":[{"batb":[[0,1.92,6.38]],"ltp":2.22,"tv":618.05,"id":31379}]}]}
{"op":"mcm","clk":"11857539153","pt":1723370224518,"mc":[{"id":"1.231582255","rc":[{"trd":[[2.24,101.25]],"batl":[[0,2.24,855.26]],"ltp":2.24,"tv":625.3,"id":31379},{"trd":[[1.8,19.02]],"ltp":1.8,"tv":273.66,"id":424676}],"tv":898.97}]}
{"op":"mcm","clk":"11857540192","pt":1723370234601,"mc":[{"id":"1.231582255","rc":[{"batl":[[0,1.89,9.02],[1,1.92,1.57],[2,3.55,13.8]],"ltp":1.8,"tv":273.66,"id":424676}]}]}
{"op":"mcm","clk":"11857540381","pt":1723370236522,"mc":[{"id":"1.231582255","rc":[{"batb":[[1,1.89,31.59]],"ltp":2.24,"tv":625.3,"id":31379}]}]}
{"op":"mcm","clk":"11857541481","pt":1723370247497,"mc":[{"id":"1.231582255","rc":[{"batb":[[1,1.89,11.35]],"ltp":2.24,"tv":625.3,"id":31379},{"batl":[[0,1.92,1.57],[1,3.55,13.8],[2,1000,0.02]],"ltp":1.8,"tv":273.66,"id":424676}]}]}
{"op":"mcm","clk":"11857542155","pt":1723370254513,"mc":[{"id":"1.231582255","rc":[{"batl":[[0,2.22,24.98],[1,2.24,855.26],[2,2.8,17.01]],"ltp":2.24,"tv":625.3,"id":31379},{"batb":[[0,1.8,22.51],[1,1.79,22.8],[2,1.75,94.01]],"ltp":1.8,"tv":273.66,"id":424676}]}]}
{"op":"mcm","clk":"11857542240","pt":1723370255400,"mc":[{"id":"1.231582255","rc":[{"trd":[[2.22,54.71]],"batl":[[0,2.24,855.26],[1,2.8,17.01],[2,3.2,3.61]],"ltp":2.22,"tv":675.57,"id":31379}],"tv":949.24}]}
{"op":"mcm","clk":"11857542292","pt":1723370256023,"mc":[{"id":"1.231582255","rc":[{"batb":[[0,1.79,22.8],[1,1.75,94.01],[2,1.74,24.34]],"ltp":1.8,"tv":273.66,"id":424676}]}]}
{"op":"mcm","clk":"11857542899","pt":1723370263259,"mc":[{"id":"1.231582255","rc":[{"batl":[[0,1.91,18],[1,1.92,1.57],[2,3.55,13.8]],"ltp":1.8,"tv":273.66,"id":424676}]}]}
{"op":"mcm","clk":"11857543129","pt":1723370265561,"mc":[{"id":"1.231582255","rc":[{"batb":[[0,1.92,25.96]],"ltp":2.22,"tv":675.57,"id":31379}]}]}
{"op":"mcm","clk":"11857544943","pt":1723370283980,"mc":[{"id":"1.231582255","rc":[{"batl":[[0,1.91,18.1]],"ltp":1.8,"tv":273.66,"id":424676}]}]}
{"op":"mcm","clk":"11857545314","pt":1723370287989,"mc":[{"id":"1.231582255","rc":[{"batb":[[0,1.92,25.86]],"ltp":2.22,"tv":675.57,"id":31379}]}]}
{"op":"mcm","clk":"11857545943","pt":1723370294596,"mc":[{"id":"1.231582255","rc":[{"batb":[[0,1.92,25.76]],"ltp":2.22,"tv":675.57,"id":31379}]}]}
{"op":"mcm","clk":"11857547176","pt":1723370307701,"mc":[{"id":"1.231582255","rc":[{"batb":[[0,1.92,25.86]],"ltp":2.22,"tv":675.57,"id":31379}]}]}
{"op":"mcm","clk":"11857550799","pt":1723370344533,"mc":[{"id":"1.231582255","rc":[{"batb":[[0,1.92,6.28],[1,1.89,31.59]],"ltp":2.22,"tv":675.57,"id":31379},{"trd":[[1.9,1.2],[1.91,95.25]],"batl":[[0,1.91,8.08]],"ltp":1.91,"tv":293.72,"id":424676}],"tv":969.3}]}
{"op":"mcm","clk":"11857550830","pt":1723370344848,"mc":[{"id":"1.231582255","rc":[{"trd":[[1.91,98.55]],"batl":[[0,1.91,6.43]],"ltp":1.91,"tv":297.01,"id":424676}],"tv":972.59}]}
{"op":"mcm","clk":"11857550939","pt":1723370345941,"mc":[{"id":"1.231582255","rc":[{"trd":[[1.91,101.27]],"batl":[[0,1.91,5.07]],"ltp":1.91,"tv":299.74,"id":424676}],"tv":975.32}]}
{"op":"mcm","clk":"11857551037","pt":1723370346935,"mc":[{"id":"1.231582255","rc":[{"trd":[[1.91,103.54]],"batl":[[0,1.91,3.94]],"ltp":1.91,"tv":302.0,"id":424676}],"tv":977.58}]}
{"op":"mcm","clk":"11857551146","pt":1723370347916,"mc":[{"id":"1.231582255","rc":[{"trd":[[1.91,105.4]],"batl":[[0,1.91,3.01]],"ltp":1.91,"tv":303.86,"id":424676}],"tv":979.44}]}
{"op":"mcm","clk":"11857551216","pt":1723370348645,"mc":[{"id":"1.231582255","rc":[{"batb":[[1,1.89,11.35],[2,1.82,23.53]],"ltp":2.22,"tv":675.57,"id":31379}]}]}
{"op":"mcm","clk":"11857551386","pt":1723370350426,"mc":[{"id":"1.231582255","rc":[{"batb":[[1,1.75,24.01]],"ltp":1.91,"tv":303.86,"id":424676}]}]}
{"op":"mcm","clk":"11857551583","pt":1723370352236,"mc":[{"id":"1.231582255","rc":[{"trd":[[2.1,1.01]],"batb":[[0,1.92,6.18]],"ltp":2.1,"tv":675.68,"id":31379},{"trd":[[1.91,111.53]],"batl":[[0,1.92,1.57],[1,3.55,13.8],[2,1000,0.02]],"ltp":1.91,"tv":310.0,"id":424676}],"tv":985.68}]}
{"op":"mcm","clk":"11857551688","pt":1723370353230,"mc":[{"id":"1.231582255","rc":[{"batb":[[2,1.82,1.57]],"ltp":2.1,"tv":675.68,"id":31379}]}]}
{"op":"mcm","clk":"11857553469","pt":1723370370867,"mc":[{"id":"1.231582255","rc":[{"batb":[[0,1.89,3.14],[1,1.79,22.8],[2,1.75,24.01]],"ltp":1.91,"tv":310.0,"id":424676}]}]}
{"op":"mcm","clk":"11857553630","pt":1723370372376,"mc":[{"id":"1.231582255","rc":[{"trd":[[2.02,0.1],[2.08,1.63]],"batl":[[0,2.02,186.65],[1,2.24,855.26],[2,2.8,17.01]],"ltp":2.02,"tv":677.23,"id":31379},{"trd":[[1.92,1.77],[1.98,0.1]],"batb":[[1,1.8,22.51],[2,1.79,22.8]],"batl":[[0,3.55,13.7],[1,1000,0.02],[2,1000,0]],"ltp":1.98,"tv":311.67,"id":424676}],"tv":988.9}]}
{"op":"mcm","clk":"11857553837","pt":1723370374551,"mc":[{"id":"1.231582255","rc":[{"batb":[[0,1.97,18.57],[1,1.89,3.14],[2,1.8,22.51]],"ltp":1.98,"tv":311.67,"id":424676}]}]}
{"op":"mcm","clk":"11857554102","pt":1723370377562,"mc":[{"id":"1.231582255","rc":[{"batb":[[2,1.8,22.61]],"ltp":1.98,"tv":311.67,"id":424676}]}]}
{"op":"mcm","clk":"11857554347","pt":1723370380098,"mc":[{"id":"1.231582255","rc":[{"trd":[[1.92,12.36]],"batb":[[0,1.89,11.35],[1,1.82,1.57],[2,1.78,2.36]],"ltp":1.92,"tv":689.59,"id":31379}],"tv":1001.27}]}
{"op":"mcm","clk":"11857555375","pt":1723370390476,"mc":[{"id":"1.231582255","rc":[{"batb":[[0,1.92,270.49],[1,1.89,11.35],[2,1.82,1.57]],"ltp":1.92,"tv":689.59,"id":31379}]}]}
{"op":"mcm","clk":"11857555451","pt":1723370391209,"mc":[{"id":"1.231582255","rc":[{"trd":[[1.92,12.88]],"batb":[[0,1.92,270.23]],"ltp":1.92,"tv":690.11,"id":31379}],"tv":1001.79}]}
{"op":"mcm","clk":"11857555508","pt":1723370391790,"mc":[{"id":"1.231582255","rc":[{"trd":[[1.92,210.12]],"batb":[[0,1.92,171.61]],"ltp":1.92,"tv":887.35,"id":31379},{"batb":[[2,1.8,22.51]],"ltp":1.98,"tv":311.67,"id":424676}],"tv":1199.03}]}
{"op":"mcm","clk":"11857555595","pt":1723370392633,"mc":[{"id":"1.231582255","rc":[{"batb":[[1,1.91,19.79],[2,1.89,11.35]],"ltp":1.92,"tv":887.35,"id":31379}]}]}
{"op":"mcm","clk":"11857555877","pt":1723370395162,"mc":[{"id":"1.231582255","rc":[{"batb":[[1,1.8,22.51],[2,1.79,22.8]],"ltp":1.98,"tv":311.67,"id":424676}]}]}
{"op":"mcm","clk":"11857557128","pt":1723370404139,"mc":[{"id":"1.231582255","marketDefinition":{"bspMarket":false,"turnInPlayEnabled":true,"persistenceEnabled":true,"marketBaseRate":5.0,"eventId":"33477755","eventTypeId":"4","numberOfWinners":1,"bettingType":"ODDS","marketType":"MATCH_ODDS","marketTime":"2024-08-11T10:00:00.000Z","suspendTime":"2024-08-11T10:00:00.000Z","bspReconciled":false,"complete":true,"inPlay":false,"crossMatching":true,"runnersVoidable":false,"numberOfActiveRunners":2,"betDelay":0,"status":"SUSPENDED","runners":[{"status":"ACTIVE","sortPriority":1,"id":31379,"name":"Sussex"},{"status":"ACTIVE","sortPriority":2,"id":424676,"name":"Surrey"}],"regulators":["MR_INT"],"countryCode":"GB","discountAllowed":true,"timezone":"GMT","openDate":"2024-08-11T10:00:00.000Z","version":6068983184,"name":"Match Odds","eventName":"Sussex v Surrey"},"rc":[{"batb":[[1,1.89,11.35],[2,1.82,1.57]],"ltp":1.92,"tv":887.35,"id":31379},{"batb":[[0,1.72,108.45],[1,1.7,15.6],[2,1.55,6.46]],"ltp":1.98,"tv":311.67,"id":424676}]}]}
{"op":"mcm","clk":"11857557754","pt":1723370408151,"mc":[{"id":"1.231582255","marketDefinition":{"bspMarket":false,"turnInPlayEnabled":true,"persistenceEnabled":true,"marketBaseRate":5.0,"eventId":"33477755","eventTypeId":"4","numberOfWinners":1,"bettingType":"ODDS","marketType":"MATCH_ODDS","marketTime":"2024-08-11T10:00:00.000Z","suspendTime":"2024-08-11T10:00:00.000Z","bspReconciled":false,"complete":true,"inPlay":true,"crossMatching":true,"runnersVoidable":false,"numberOfActiveRunners":2,"betDelay":5,"status":"OPEN","runners":[{"status":"ACTIVE","sortPriority":1,"id":31379,"name":"Sussex"},{"status":"ACTIVE","sortPriority":2,"id":424676,"name":"Surrey"}],"regulators":["MR_INT"],"countryCode":"GB","discountAllowed":true,"timezone":"GMT","openDate":"2024-08-11T10:00:00.000Z","version":6068985074,"name":"Match Odds","eventName":"Sussex v Surrey"},"rc":[{"batb":[[0,1.82,1.57],[1,1.78,2.36],[2,1.7,3]],"batl":[[0,2.8,5],[1,3.2,3.61],[2,1000,0.25]],"ltp":1.92,"tv":887.35,"id":31379},{"batb":[[0,1.7,3],[1,1.55,6.46],[2,1.46,7.85]],"batl":[[0,1000,0.31],[1,1000,0]],"ltp":1.98,"tv":311.67,"id":424676}]}]}
{"op":"mcm","clk":"11857560240","pt":1723370425103,"mc":[{"id":"1.231582255","rc":[{"batl":[[2,1000,0.35]],"ltp":1.92,"tv":887.35,"id":31379},{"batl":[[0,1000,0.41]],"ltp":1.98,"tv":311.67,"id":424676}]}]}
{"op":"mcm","clk":"11857560385","pt":1723370425930,"mc":[{"id":"1.231582255","rc":[{"batb":[[0,1.7,3.19]],"ltp":1.98,"tv":311.67,"id":424676}]}]}
{"op":"mcm","clk":"11857560562","pt":1723370427315,"mc":[{"id":"1.231582255","rc":[{"trd":[[2.18,0.16]],"batb":[[0,2.4,2.98],[1,1.92,135.24],[2,1.82,1.57]],"ltp":2.18,"tv":887.51,"id":31379},{"trd":[[1.85,0.19]],"batb":[[0,1.7,3]],"ltp":1.85,"tv":311.86,"id":424676}],"tv":1199.37}]}
{"op":"mcm","clk":"11857560854","pt":1723370429929,"mc":[{"id":"1.231582255","rc":[{"batl":[[1,1000,0.35],[2,1000,0]],"ltp":2.18,"tv":887.51,"id":31379}]}]}
{"op":"mcm","clk":"11857561599","pt":1723370436210,"mc":[{"id":"1.231582255","rc":[{"trd":[[2.4,7.31]],"batb":[[0,1.92,135.49],[1,1.82,1.57],[2,1.78,2.36]],"ltp":2.4,"tv":890.24,"id":31379},{"trd":[[1.72,10.22]],"ltp":1.72,"tv":315.68,"id":424676}],"tv":1205.92}]}
{"op":"mcm","clk":"11857562238","pt":1723370441304,"mc":[{"id":"1.231582255","rc":[{"batl":[[0,1000,0.42]],"ltp":1.72,"tv":315.68,"id":424676}]}]}
{"op":"mcm","clk":"11857562579","pt":1723370443822,"mc":[{"id":"1.231582255","rc":[{"batb":[[0,1.92,135.24]],"ltp":2.4,"tv":890.24,"id":31379}]}]}
{"op":"mcm","clk":"11857563652","pt":1723370452829,"mc":[{"id":"1.231582255","rc":[{"batl":[[0,1.84,3.82],[1,1000,0.42]],"ltp":1.72,"tv":315.68,"id":424676}]}]}
{"op":"mcm","clk":"11857563837","pt":1723370454244,"mc":[{"id":"1.231582255","rc":[{"batl":[[1,1000,0.52]],"ltp":1.72,"tv":315.68,"id":424676}]}]}
{"op":"mcm","clk":"11857565741","pt":1723370468781,"mc":[{"id":"1.231582255","rc":[{"batl":[[0,1.73,3.82],[1,1.84,3.82],[2,1000,0.52]],"ltp":1.72,"tv":315.68,"id":424676}]}]}
{"op":"mcm","clk":"11857566341","pt":1723370473012,"mc":[{"id":"1.231582255","rc":[{"batb":[[0,1.82,1.57],[1,1.78,2.36],[2,1.7,3]],"ltp":2.4,"tv":890.24,"id":31379}]}]}
{"op":"mcm","clk":"11857566448","pt":1723370473897,"mc":[{"id":"1.231582255","rc":[{"batl":[[0,1000,0.52],[1,1.84,0],[2,1000,0]],"ltp":1.72,"tv":315.68,"id":424676}]}]}
{"op":"mcm","clk":"11857566626","pt":1723370474989,"mc":[{"id":"1.231582255","rc":[{"batl":[[1,1000,0.7]],"ltp":2.4,"tv":890.24,"id":31379}]}]}
{"op":"mcm","clk":"11857566741","pt":1723370475876,"mc":[{"id":"1.231582255","rc":[{"batb":[[0,1.71,10.5],[1,1.7,3],[2,1.55,6.46]],"ltp":1.72,"tv":315.68,"id":424676}]}]}
{"op":"mcm","clk":"11857567111","pt":1723370478996,"mc":[{"id":"1.231582255","rc":[{"batb":[[1,1.79,6.18],[2,1.78,2.36]],"batl":[[1,3.25,3.61],[2,1000,0.7]],"ltp":2.4,"tv":890.24,"id":31379},{"batl":[[0,1000,0.42]],"ltp":1.72,"tv":315.68,"id":424676}]}]}
{"op":"mcm","clk":"11857567287","pt":1723370480199,"mc":[{"id":"1.231582255","rc":[{"batl":[[2,1000,0.35]],"ltp":2.4,"tv":890.24,"id":31379},{"batl":[[0,1000,0.77]],"ltp":1.72,"tv":315.68,"id":424676}]}]}
{"op":"mcm","clk":"11857567437","pt":1723370481297,"mc":[{"id":"1.231582255","rc":[{"batb":[[1,1.78,2.36],[2,1.7,3]],"batl":[[1,1000,0.35],[2,1000,0]],"ltp":2.4,"tv":890.24,"id":31379}]}]}
{"op":"mcm","clk":"11857567650","pt":1723370483212,"mc":[{"id":"1.231582255","rc":[{"batl":[[0,1.72,3.82],[1,1000,0.77]],"ltp":1.72,"tv":315.68,"id":424676}]}]}
{"op":"mcm","clk":"11857567881","pt":1723370485295,"mc":[{"id":"1.231582255","rc":[{"batb":[[0,1.82,2]],"batl":[[1,1000,0.7]],"ltp":2.4,"tv":890.24,"id":31379}]}]}
{"op":"mcm","clk":"11857568499","pt":1723370490503,"mc":[{"id":"1.231582255","rc":[{"trd":[[1.7,6],[1.71,24.65]],"batb":[[0,1.55,6.46],[1,1.46,7.85],[2,1.37,172.33]],"batl":[[0,1.7,486.5],[1,1.72,3.82],[2,1000,0.87]],"ltp":1.7,"tv":342.68,"id":424676}],"tv":1232.92}]}
{"op":"mcm","clk":"11857568569","pt":1723370491127,"mc":[{"id":"1.231582255","rc":[{"batl":[[0,1.72,3.82],[1,1000,0.87],[2,1000,0]],"ltp":1.7,"tv":342.68,"id":424676}]}]}
{"op":"mcm","clk":"11857568924","pt":1723370494094,"mc":[{"id":"1.231582255","rc":[{"batb":[[0,1.82,2.19]],"ltp":2.4,"tv":890.24,"id":31379}]}]}
{"op":"mcm","clk":"11857569730","pt":1723370500016,"mc":[{"id":"1.231582255","rc":[{"batl":[[0,1000,0.87],[1,1000,0]],"ltp":1.7,"tv":342.68,"id":424676}]}]}
{"op":"mcm","clk":"11857570986","pt":1723370509841,"mc":[{"id":"1.231582255","rc":[{"trd":[[2.7,0.1]],"batb":[[0,2.76,3.04],[1,1.82,2.19],[2,1.78,2.36]],"ltp":2.7,"tv":890.34,"id":31379},{"trd":[[1.59,0.17]],"batb":[[0,1.55,6.28]],"ltp":1.59,"tv":342.85,"id":424676}],"tv":1233.2}]}
{"op":"mcm","clk":"11857571220","pt":1723370511818,"mc":[{"id":"1.231582255","rc":[{"trd":[[2.76,0.05]],"batb":[[0,2.76,2.98]],"ltp":2.76,"tv":890.4,"id":31379},{"trd":[[1.57,0.1]],"ltp":1.57,"tv":342.95,"id":424676}],"tv":1233.35}]}
{"op":"mcm","clk":"11857571367","pt":1723370513219,"mc":[{"id":"1.231582255","rc":[{"batl":[[0,1.72,3.82],[1,1000,0.87]],"ltp":1.57,"tv":342.95,"id":424676}]}]}
{"op":"mcm","clk":"11857571564","pt":1723370514978,"mc":[{"id":"1.231582255","rc":[{"trd":[[2.76,6.02]],"batb":[[0,1.82,2.19],[1,1.78,2.36],[2,1.7,3]],"ltp":2.76,"tv":896.36,"id":31379},{"batl":[[0,1000,0.87],[1,1000,0]],"ltp":1.57,"tv":342.95,"id":424676}],"tv":1239.32}]}
{"op":"mcm","clk":"11857572217","pt":1723370520234,"mc":[{"id":"1.231582255","rc":[{"batb":[[0,1.82,8.37]],"batl":[[1,3.35,3.96],[2,1000,0.35]],"ltp":2.76,"tv":896.36,"id":31379}]}]}
{"op":"mcm","clk":"11857572246","pt":1723370520545,"mc":[{"id":"1.231582255","rc":[{"batb":[[0,1.82,2.19]],"batl":[[1,1000,0.7],[2,1000,0]],"ltp":2.76,"tv":896.36,"id":31379}]}]}
{"op":"mcm","clk":"11857572648","pt":1723370523442,"mc":[{"id":"1.231582255","rc":[{"batl":[[1,1000,1.05]],"ltp":2.76,"tv":896.36,"id":31379}]}]}
{"op":"mcm","clk":"11857573342","pt":1723370528530,"mc":[{"id":"1.231582255","rc":[{"batl":[[0,3.55,1.09],[1,1000,0.13]],"ltp":1.57,"tv":342.95,"id":424676}]}]}
{"op":"mcm","clk":"11857573396","pt":1723370529001,"mc":[{"id":"1.231582255","rc":[{"batl":[[1,1000,0.7]],"ltp":2.76,"tv":896.36,"id":31379},{"trd":[[1.7,7]],"batl":[[0,1.7,3.32],[1,3.55,1.09],[2,1000,0.13]],"ltp":1.7,"tv":343.95,"id":424676}],"tv":1240.32}]}
{"op":"mcm","clk":"11857574115","pt":1723370534481,"mc":[{"id":"1.231582255","rc":[{"batb":[[0,1.86,1.32],[1,1.82,1.4],[2,1.78,2.36]],"batl":[[0,2.8,5.35]],"ltp":2.76,"tv":896.36,"id":31379},{"batb":[[0,1.62,90.16],[1,1.55,6.28],[2,1.46,7.85]],"ltp":1.7,"tv":343.95,"id":424676}]}]}
{"op":"mcm","clk":"11857574568","pt":1723370537846,"mc":[{"id":"1.231582255","rc":[{"trd":[[2.5,0.7],[2.62,2.79]],"batl":[[0,2.8,5]],"ltp":2.62,"tv":899.85,"id":31379},{"trd":[[1.62,4.51]],"batb":[[0,1.62,85.65]],"ltp":1.62,"tv":348.46,"id":424676}],"tv":1248.32}]}
{"op":"mcm","clk":"11857574804","pt":1723370539567,"mc":[{"id":"1.231582255","rc":[{"batl":[[1,2.2,1.25],[2,1000,0.42]],"ltp":1.62,"tv":348.46,"id":424676}]}]}
{"op":"mcm","clk":"11857575501","pt":1723370544683,"mc":[{"id":"1.231582255","rc":[{"batb":[[0,1.63,10.5],[1,1.62,85.65],[2,1.55,6.28]],"ltp":1.62,"tv":348.46,"id":424676}]}]}
{"op":"mcm","clk":"11857575643","pt":1723370545684,"mc":[{"id":"1.231582255","rc":[{"batb":[[0,1.63,33.92]],"ltp":1.62,"tv":348.46,"id":424676}]}]}
{"op":"mcm","clk":"11857575914","pt":1723370547772,"mc":[{"id":"1.231582255","rc":[{"batb":[[2,1.81,6.18]],"batl":[[1,3.35,3.96],[2,1000,0.35]],"ltp":2.62,"tv":899.85,"id":31379}]}]}
{"op":"mcm","clk":"11857576062","pt":1723370548868,"mc":[{"id":"1.231582255","rc":[{"batb":[[0,1.86,1.74]],"ltp":2.62,"tv":899.85,"id":31379}]}]}
{"op":"mcm","clk":"11857576269","pt":1723370550280,"mc":[{"id":"1.231582255","rc":[{"batb":[[2,1.78,2.36]],"batl":[[1,9.6,1.12],[2,1000,0.12]],"ltp":2.62,"tv":899.85,"id":31379}]}]}
{"op":"mcm","clk":"11857578508","pt":1723370566395,"mc":[{"id":"1.231582255","rc":[{"batl":[[1,3.55,1.19],[2,1000,0.13]],"ltp":1.62,"tv":348.46,"id":424676}]}]}
{"op":"mcm","clk":"11857579407","pt":1723370573172,"mc":[{"id":"1.231582255","rc":[{"batb":[[1,1.78,3.33],[2,1.7,3]],"batl":[[1,1000,0.89],[2,1000,0]],"ltp":2.62,"tv":899.85,"id":31379},{"batl":[[0,3.55,1.19],[1,1000,0.13],[2,1000,0]],"ltp":1.62,"tv":348.46,"id":424676}]}]}
{"op":"mcm","clk":"11857580631","pt":1723370582930,"mc":[{"id":"1.231582255","rc":[{"batb":[[1,1.82,7.16],[2,1.78,2.36]],"batl":[[1,3.4,3.61],[2,1000,0.89]],"ltp":2.62,"tv":899.85,"id":31379}]}]}
{"op":"mcm","clk":"11857580937","pt":1723370585313,"mc":[{"id":"1.231582255","rc":[{"batb":[[1,1.78,3.33],[2,1.7,3]],"batl":[[1,1000,0.89],[2,1000,0]],"ltp":2.62,"tv":899.85,"id":31379}]}]}
{"op":"mcm","clk":"11857581706","pt":1723370590529,"mc":[{"id":"1.231582255","rc":[{"batb":[[0,1.86,7.93]],"ltp":2.62,"tv":899.85,"id":31379},{"batl":[[0,1.69,3.25],[1,3.55,1.19],[2,1000,0.13]],"ltp":1.62,"tv":348.46,"id":424676}]}]}
{"op":"mcm","clk":"11857581765","pt":1723370590828,"mc":[{"id":"1.231582255","rc":[{"batb":[[0,1.86,1.74],[1,1.78,3.14]],"ltp":2.62,"tv":899.85,"id":31379}]}]}
{"op":"mcm","clk":"11857582303","pt":1723370594337,"mc":[{"id":"1.231582255","rc":[{"batl":[[1,1.93,2.27],[2,1000,0.87]],"ltp":1.62,"tv":348.46,"id":424676}]}]}
{"op":"mcm","clk":"11857583257","pt":1723370601349,"mc":[{"id":"1.231582255","rc":[{"trd":[[1.69,6.49]],"batb":[[0,1.69,1.77],[1,1.63,33.92],[2,1.62,85.65]],"batl":[[0,1.93,2.27],[1,1000,0.87],[2,1000,0]],"ltp":1.69,"tv":354.95,"id":424676}],"tv":1254.81}]}
{"op":"mcm","clk":"11857583305","pt":1723370601766,"mc":[{"id":"1.231582255","rc":[{"batb":[[1,1.63,23.42]],"ltp":1.69,"tv":354.95,"id":424676}]}]}
{"op":"mcm","clk":"11857583424","pt":1723370602696,"mc":[{"id":"1.231582255","rc":[{"batl":[[0,1.9,27.5],[1,1.93,1.82],[2,1000,0.87]],"ltp":1.69,"tv":354.95,"id":424676}]}]}
{"op":"mcm","clk":"11857583670","pt":1723370604390,"mc":[{"id":"1.231582255","rc":[{"batb":[[0,1.69,5.42]],"ltp":1.69,"tv":354.95,"id":424676}]}]}
{"op":"mcm","clk":"11857583980","pt":1723370606768,"mc":[{"id":"1.231582255","rc":[{"batl":[[0,2.44,2.1],[1,2.8,5],[2,1000,0.89]],"ltp":2.62,"tv":899.85,"id":31379},{"batb":[[0,1.7,10.5],[1,1.69,5.42],[2,1.63,23.42]],"ltp":1.69,"tv":354.95,"id":424676}]}]}
{"op":"mcm","clk":"11857584393","pt":1723370609856,"mc":[{"id":"1.231582255","rc":[{"batb":[[0,2.26,12.49],[1,1.86,1.74],[2,1.78,3.14]],"ltp":2.62,"tv":899.85,"id":31379}]}]}
{"op":"mcm","clk":"11857584985","pt":1723370614316,"mc":[{"id":"1.231582255","rc":[{"batb":[[2,1.82,1.21]],"batl":[[2,9.6,1.12]],"ltp":2.62,"tv":899.85,"id":31379},{"batl":[[2,3.55,1.09]],"ltp":1.69,"tv":354.95,"id":424676}]}]}
{"op":"mcm","clk":"11857585150","pt":1723370615366,"mc":[{"id":"1.231582255","rc":[{"batb":[[1,1.69,1.77]],"ltp":1.69,"tv":354.95,"id":424676}]}]}
{"op":"mcm","clk":"11857585441","pt":1723370617470,"mc":[{"id":"1.231582255","rc":[{"trd":[[2.26,2.5]],"batb":[[0,2.26,9.98]],"ltp":2.26,"tv":902.36,"id":31379},{"trd":[[1.8,22.16]],"ltp":1.8,"tv":358.09,"id":424676}],"tv":1260.46}]}
{"op":"mcm","clk":"11857585688","pt":1723370619396,"mc":[{"id":"1.231582255","rc":[{"batl":[[1,3.55,1.09],[2,1000,0.13]],"ltp":1.8,"tv":358.09,"id":424676}]}]}
{"op":"mcm","clk":"11857586028","pt":1723370621764,"mc":[{"id":"1.231582255","rc":[{"batl":[[0,1.9,27.6]],"ltp":1.8,"tv":358.09,"id":424676}]}]}
{"op":"mcm","clk":"11857586164","pt":1723370622761,"mc":[{"id":"1.231582255","rc":[{"batb":[[1,2.1,5.57],[2,1.86,1.32]],"batl":[[2,3.4,3.96]],"ltp":2.26,"tv":902.36,"id":31379}]}]}
{"op":"mcm","clk":"11857586363","pt":1723370624388,"mc":[{"id":"1.231582255","rc":[{"batl":[[0,1.87,18.04],[1,1.9,27.6],[2,3.55,1.09]],"ltp":1.8,"tv":358.09,"id":424676}]}]}
{"op":"mcm","clk":"11857586491","pt":1723370625386,"mc":[{"id":"1.231582255","rc":[{"batl":[[2,9.6,1.12]],"ltp":2.26,"tv":902.36,"id":31379},{"batb":[[0,1.72,23.42],[1,1.7,10.5],[2,1.69,1.77]],"ltp":1.8,"tv":358.09,"id":424676}]}]}
{"op":"mcm","clk":"11857586517","pt":1723370625596,"mc":[{"id":"1.231582255","rc":[{"batb":[[1,1.69,1.77],[2,1.63,23.42]],"ltp":1.8,"tv":358.09,"id":424676}]}]}
{"op":"mcm","clk":"11857586869","pt":1723370628182,"mc":[{"id":"1.231582255","rc":[{"batb":[[0,2.28,2.39],[1,2.26,9.98],[2,2.1,5.57]],"ltp":2.26,"tv":902.36,"id":31379}]}]}
{"op":"mcm","clk":"11857586947","pt":1723370628762,"mc":[{"id":"1.231582255","rc":[{"batl":[[0,1.87,18.15]],"ltp":1.8,"tv":358.09,"id":424676}]}]}
{"op":"mcm","clk":"11857587143","pt":1723370630277,"mc":[{"id":"1.231582255","rc":[{"batb":[[0,2.1,5.57],[1,1.86,7.51],[2,1.82,1.21]],"batl":[[2,3.2,3.96]],"ltp":2.26,"tv":902.36,"id":31379}]}]}
{"op":"mcm","clk":"11857587181","pt":1723370630585,"mc":[{"id":"1.231582255","rc":[{"trd":[[1.73,8.21]],"batb":[[0,1.73,10.39],[1,1.72,23.42],[2,1.69,1.77]],"batl":[[0,1.87,18.04]],"ltp":1.73,"tv":358.32,"id":424676}],"tv":1260.68}]}
{"op":"mcm","clk":"11857587396","pt":1723370632306,"mc":[{"id":"1.231582255","rc":[{"batl":[[2,1000,0.87]],"ltp":1.73,"tv":358.32,"id":424676}]}]}
{"op":"mcm","clk":"11857587597","pt":1723370633685,"mc":[{"id":"1.231582255","rc":[{"batb":[[1,1.69,1.77],[2,1.63,23.42]],"ltp":1.73,"tv":358.32,"id":424676}]}]}
{"op":"mcm","clk":"11857587918","pt":1723370636201,"mc":[{"id":"1.231582255","rc":[{"batb":[[0,2.26,12.49],[1,2.1,5.57],[2,1.86,7.51]],"ltp":2.26,"tv":902.36,"id":31379}]}]}
{"op":"mcm","clk":"11857588189","pt":1723370638403,"mc":[{"id":"1.231582255","rc":[{"batb":[[0,2.1,5.57],[1,1.86,7.16],[2,1.82,1.21]],"ltp":2.26,"tv":902.36,"id":31379}]}]}
{"op":"mcm","clk":"11857588334","pt":1723370639406,"mc":[{"id":"1.231582255","rc":[{"batb":[[1,1.63,23.42],[2,1.62,85.65]],"ltp":1.73,"tv":358.32,"id":424676}]}]}
{"op":"mcm","clk":"11857588569","pt":1723370640992,"mc":[{"id":"1.231582255","rc":[{"trd":[[2.14,3.1]],"ltp":2.14,"tv":902.46,"id":31379},{"trd":[[1.87,6.4]],"batl":[[0,1.87,17.92]],"ltp":1.87,"tv":358.44,"id":424676}],"tv":1260.9}]}
{"op":"mcm","clk":"11857589021","pt":1723370643987,"mc":[{"id":"1.231582255","rc":[{"batb":[[0,2.26,12.49],[1,2.1,5.57],[2,1.86,7.16]],"ltp":2.14,"tv":902.46,"id":31379}]}]}
{"op":"mcm","clk":"11857589232","pt":1723370645503,"mc":[{"id":"1.231582255","rc":[{"trd":[[2.26,27.48]],"batb":[[0,2.1,5.57],[1,1.86,7.16],[2,1.82,1.21]],"batl":[[0,2.24,487.51],[1,2.44,2.1],[2,2.8,5]],"ltp":2.26,"tv":927.44,"id":31379},{"batb":[[0,1.63,23.42],[1,1.62,85.65],[2,1.55,6.28]],"ltp":1.87,"tv":358.44,"id":424676}],"tv":1285.88}]}
{"op":"mcm","clk":"11857590964","pt":1723370658797,"mc":[{"id":"1.231582255","rc":[{"batb":[[0,1.86,1.39],[1,1.82,1.21],[2,1.78,2.36]],"ltp":2.26,"tv":927.44,"id":31379}]}]}
{"op":"mcm","clk":"11857591257","pt":1723370661440,"mc":[{"id":"1.231582255","rc":[{"trd":[[2.24,109.32]],"batl":[[0,2.24,479.44]],"ltp":2.24,"tv":935.51,"id":31379},{"trd":[[1.8,32.2]],"ltp":1.8,"tv":368.48,"id":424676}],"tv":1303.99}]}
{"op":"mcm","clk":"11857591407","pt":1723370662811,"mc":[{"id":"1.231582255","rc":[{"trd":[[2.24,116.57]],"batl":[[0,2.24,472.19]],"ltp":2.24,"tv":942.76,"id":31379},{"trd":[[1.8,41.22]],"ltp":1.8,"tv":377.5,"id":424676}],"tv":1320.26}]}
{"op":"mcm","clk":"11857591702","pt":1723370665193,"mc":[{"id":"1.231582255","rc":[{"batl":[[0,1.83,3.82],[1,1.87,17.92],[2,1.9,27.6]],"ltp":1.8,"tv":377.5,"id":424676}]}]}
{"op":"mcm","clk":"11857591858","pt":1723370666391,"mc":[{"id":"1.231582255","rc":[{"batl":[[2,1.9,27.5]],"ltp":1.8,"tv":377.5,"id":424676}]}]}
{"op":"mcm","clk":"11857592037","pt":1723370667908,"mc":[{"id":"1.231582255","rc":[{"trd":[[2.24,135.71]],"batl":[[0,2.24,462.62]],"ltp":2.24,"tv":961.9,"id":31379}],"tv":1339.4}]}
{"op":"mcm","clk":"11857592382","pt":1723370670422,"mc":[{"id":"1.231582255","rc":[{"batb":[[0,1.62,85.65],[1,1.55,6.28],[2,1.46,8.55]],"ltp":1.8,"tv":377.5,"id":424676}]}]}
{"op":"mcm","clk":"11857592458","pt":1723370671004,"mc":[{"id":"1.231582255","rc":[{"batl":[[2,3.55,1.19]],"ltp":1.8,"tv":377.5,"id":424676}]}]}
{"op":"mcm","clk":"11857592562","pt":1723370671843,"mc":[{"id":"1.231582255","rc":[{"batb":[[0,1.86,1.21]],"ltp":2.24,"tv":961.9,"id":31379}]}]}
{"op":"mcm","clk":"11857593234","pt":1723370676525,"mc":[{"id":"1.231582255","rc":[{"batl":[[1,3.55,1.19],[2,1000,0.13]],"ltp":1.8,"tv":377.5,"id":424676}]}]}
{"op":"mcm","clk":"11857593316","pt":1723370677153,"mc":[{"id":"1.231582255","rc":[{"batb":[[0,1.83,1.21],[1,1.78,3.14],[2,1.7,3]],"ltp":2.24,"tv":961.9,"id":31379},{"batl":[[1,1000,0.87],[2,1000,0]],"ltp":1.8,"tv":377.5,"id":424676}]}]}
{"op":"mcm","clk":"11857593518","pt":1723370678522,"mc":[{"id":"1.231582255","rc":[{"batb":[[0,1.82,1.57],[1,1.78,2.36]],"ltp":2.24,"tv":961.9,"id":31379},{"batb":[[2,1.46,7.85]],"batl":[[1,1000,0.52]],"ltp":1.8,"tv":377.5,"id":424676}]}]}
{"op":"mcm","clk":"11857593646","pt":1723370679407,"mc":[{"id":"1.231582255","rc":[{"batb":[[0,1.82,7.75]],"ltp":2.24,"tv":961.9,"id":31379},{"batl":[[1,1000,0.42]],"ltp":1.8,"tv":377.5,"id":424676}]}]}
{"op":"mcm","clk":"11857594097","pt":1723370682474,"mc":[{"id":"1.231582255","rc":[{"batb":[[0,1.82,1.57]],"ltp":2.24,"tv":961.9,"id":31379}]}]}
{"op":"mcm","clk":"11857594319","pt":1723370684156,"mc":[{"id":"1.231582255","rc":[{"batb":[[2,1.7,3.49]],"ltp":2.24,"tv":961.9,"id":31379},{"batl":[[1,1000,0.77]],"ltp":1.8,"tv":377.5,"id":424676}]}]}
{"op":"mcm","clk":"11857594781","pt":1723370687348,"mc":[{"id":"1.231582255","rc":[{"trd":[[2.24,136.09]],"batl":[[0,2.24,462.24]],"ltp":2.24,"tv":962.28,"id":31379},{"trd":[[1.8,41.69]],"ltp":1.8,"tv":377.97,"id":424676}],"tv":1340.25}]}
{"op":"mcm","clk":"11857594806","pt":1723370687563,"mc":[{"id":"1.231582255","rc":[{"trd":[[2.24,136.87]],"batl":[[0,2.24,461.85]],"ltp":2.24,"tv":963.06,"id":31379}],"tv":1341.03}]}
{"op":"mcm","clk":"11857595093","pt":1723370689459,"mc":[{"id":"1.231582255","rc":[{"trd":[[2.24,145.89]],"batl":[[0,2.24,457.34]],"ltp":2.24,"tv":972.08,"id":31379}],"tv":1350.05}]}
{"op":"mcm","clk":"11857597097","pt":1723370703741,"mc":[{"id":"1.231582255","rc":[{"trd":[[2.24,299.05]],"batl":[[0,2.24,380.76]],"ltp":2.24,"tv":1125.24,"id":31379}],"tv":1503.21}]}
{"op":"mcm","clk":"11857597634","pt":1723370707469,"mc":[{"id":"1.231582255","rc":[{"batl":[[0,1000,0.77],[1,1000,0]],"ltp":1.8,"tv":377.97,"id":424676}]}]}
{"op":"mcm","clk":"11857598252","pt":1723370711661,"mc":[{"id":"1.231582255","rc":[{"trd":[[2.24,301.57]],"batl":[[0,2.24,378.24]],"ltp":2.24,"tv":1127.76,"id":31379},{"trd":[[1.8,44.83]],"ltp":1.8,"tv":381.11,"id":424676}],"tv":1508.87}]}
{"op":"mcm","clk":"11857598482","pt":1723370713355,"mc":[{"id":"1.231582255","rc":[{"trd":[[2.24,310.59]],"batl":[[0,2.24,373.73]],"ltp":2.24,"tv":1136.78,"id":31379}],"tv":1517.89}]}
{"op":"mcm","clk":"11857600996","pt":1723370730386,"mc":[{"id":"1.231582255","rc":[{"batb":[[0,1.84,5.8],[1,1.78,3.14]],"ltp":2.24,"tv":1136.78,"id":31379},{"batl":[[0,1.98,27.05],[1,1000,0.77]],"ltp":1.8,"tv":381.11,"id":424676}]}]}
{"op":"mcm","clk":"11857601154","pt":1723370731493,"mc":[{"id":"1.231582255","rc":[{"batb":[[1,1.78,3.33]],"ltp":2.24,"tv":1136.78,"id":31379}]}]}
{"op":"mcm","clk":"11857601856","pt":1723370736474,"mc":[{"id":"1.231582255","rc":[{"batb":[[0,1.55,6.28],[1,1.46,7.85],[2,1.37,172.34]],"ltp":1.8,"tv":381.11,"id":424676}]}]}
{"op":"mcm","clk":"11857602827","pt":1723370743375,"mc":[{"id":"1.231582255","rc":[{"trd":[[2.24,325.09]],"batl":[[0,2.24,359.23]],"ltp":2.24,"tv":1151.28,"id":31379},{"trd":[[1.8,62.87]],"ltp":1.8,"tv":399.15,"id":424676}],"tv":1550.43}]}
{"op":"mcm","clk":"11857603403","pt":1723370747080,"mc":[{"id":"1.231582255","rc":[{"batl":[[0,1.89,9.02],[1,1.98,27.05],[2,1000,0.77]],"ltp":1.8,"tv":399.15,"id":424676}]}]}
{"op":"mcm","clk":"11857603770","pt":1723370749488,"mc":[{"id":"1.231582255","rc":[{"batl":[[1,1.98,27.15]],"ltp":1.8,"tv":399.15,"id":424676}]}]}
{"op":"mcm","clk":"11857604061","pt":1723370751381,"mc":[{"id":"1.231582255","rc":[{"batb":[[0,2.04,23.42],[1,1.84,5.8],[2,1.78,3.33]],"ltp":2.24,"tv":1151.28,"id":31379}]}]}
{"op":"mcm","clk":"11857606104","pt":1723370764219,"mc":[{"id":"1.231582255","rc":[{"batb":[[0,1.63,86.46],[1,1.55,6.28],[2,1.46,7.85]],"ltp":1.8,"tv":399.15,"id":424676}]}]}
{"op":"mcm","clk":"11857606379","pt":1723370766005,"mc":[{"id":"1.231582255","rc":[{"batb":[[1,2.02,10.82],[2,1.84,5.8]],"ltp":2.24,"tv":1151.28,"id":31379}]}]}
{"op":"mcm","clk":"11857606743","pt":1723370768517,"mc":[{"id":"1.231582255","rc":[{"batl":[[2,1000,1.12]],"ltp":1.8,"tv":399.15,"id":424676}]}]}
{"op":"mcm","clk":"11857606794","pt":1723370768900,"mc":[{"id":"1.231582255","rc":[{"batl":[[2,1000,0.77]],"ltp":1.8,"tv":399.15,"id":424676}]}]}
{"op":"mcm","clk":"11857607002","pt":1723370770137,"mc":[{"id":"1.231582255","rc":[{"batl":[[1,2.8,5],[2,9.6,1.12]],"ltp":2.24,"tv":1151.28,"id":31379},{"batl":[[0,1.89,9.12]],"ltp":1.8,"tv":399.15,"id":424676}]}]}
{"op":"mcm","clk":"11857607471","pt":1723370773227,"mc":[{"id":"1.231582255","rc":[{"batl":[[2,3.2,3.96]],"ltp":2.24,"tv":1151.28,"id":31379}]}]}
{"op":"mcm","clk":"11857607596","pt":1723370774133,"mc":[{"id":"1.231582255","rc":[{"batl":[[2,3.2,4.31]],"ltp":2.24,"tv":1151.28,"id":31379},{"batb":[[2,1.46,8.56]],"batl":[[1,3.55,1.19],[2,1000,0.03]],"ltp":1.8,"tv":399.15,"id":424676}]}]}
{"op":"mcm","clk":"11857608201","pt":1723370777918,"mc":[{"id":"1.231582255","rc":[{"trd":[[2.24,332.31]],"batl":[[0,2.24,355.62]],"ltp":2.24,"tv":1158.5,"id":31379}],"tv":1557.65}]}
{"op":"mcm","clk":"11857608546","pt":1723370780014,"mc":[{"id":"1.231582255","rc":[{"batb":[[1,1.84,5.8],[2,1.78,3.33]],"batl":[[2,9.6,1.47]],"ltp":2.24,"tv":1158.5,"id":31379}]}]}
{"op":"mcm","clk":"11857611169","pt":1723370797341,"mc":[{"id":"1.231582255","rc":[{"batl":[[0,1.88,16.83],[1,1.89,9.02],[2,3.55,1.19]],"ltp":1.8,"tv":399.15,"id":424676}]}]}
{"op":"mcm","clk":"11857611928","pt":1723370802340,"mc":[{"id":"1.231582255","rc":[{"batb":[[0,1.84,5.8],[1,1.78,3.33],[2,1.7,3.98]],"ltp":2.24,"tv":1158.5,"id":31379}]}]}
{"op":"mcm","clk":"11857612022","pt":1723370803070,"mc":[{"id":"1.231582255","rc":[{"batl":[[2,9.6,1.12]],"ltp":2.24,"tv":1158.5,"id":31379},{"batl":[[2,1000,0.87]],"ltp":1.8,"tv":399.15,"id":424676}]}]}
{"op":"mcm","clk":"11857612674","pt":1723370807491,"mc":[{"id":"1.231582255","rc":[{"batb":[[2,1.7,3.49]],"ltp":2.24,"tv":1158.5,"id":31379}]}]}
{"op":"mcm","clk":"11857612768","pt":1723370808064,"mc":[{"id":"1.231582255","rc":[{"trd":[[2.24,332.67]],"batl":[[0,2.24,355.26]],"ltp":2.24,"tv":1158.86,"id":31379},{"trd":[[1.8,63.32]],"ltp":1.8,"tv":399.6,"id":424676}],"tv":1558.46}]}
{"op":"mcm","clk":"11857613715","pt":1723370814664,"mc":[{"id":"1.231582255","rc":[{"batb":[[0,1.82,10.5],[1,1.63,86.46],[2,1.55,6.28]],"ltp":1.8,"tv":399.6,"id":424676}]}]}
{"op":"mcm","clk":"11857614205","pt":1723370818082,"mc":[{"id":"1.231582255","rc":[{"batb":[[0,1.84,11.99]],"batl":[[2,3.45,3.96]],"ltp":2.24,"tv":1158.86,"id":31379}]}]}
{"op":"mcm","clk":"11857614472","pt":1723370820196,"mc":[{"id":"1.231582255","rc":[{"batb":[[0,1.84,5.8]],"batl":[[2,9.6,1.12]],"ltp":2.24,"tv":1158.86,"id":31379}]}]}
{"op":"mcm","clk":"11857614920","pt":1723370823226,"mc":[{"id":"1.231582255","rc":[{"batb":[[2,1.7,3.98]],"batl":[[2,9.6,1.47]],"ltp":2.24,"tv":1158.86,"id":31379},{"batl":[[0,1.88,16.73],[2,3.55,1.19]],"ltp":1.8,"tv":399.6,"id":424676}]}]}
{"op":"mcm","clk":"11857615225","pt":1723370825317,"mc":[{"id":"1.231582255","rc":[{"batb":[[0,1.86,6.97],[1,1.84,5.02],[2,1.78,3.33]],"batl":[[2,3.2,4.31]],"ltp":2.24,"tv":1158.86,"id":31379}]}]}
{"op":"mcm","clk":"11857615701","pt":1723370828481,"mc":[{"id":"1.231582255","rc":[{"batb":[[0,1.84,5.8],[1,1.78,3.33],[2,1.7,3.98]],"batl":[[2,9.6,1.47]],"ltp":2.24,"tv":1158.86,"id":31379}]}]}
{"op":"mcm","clk":"11857616152","pt":1723370831391,"mc":[{"id":"1.231582255","rc":[{"trd":[[2.22,63.32],[2.24,1043.19]],"batb":[[0,2.24,136.13],[1,1.84,5.8],[2,1.78,3.33]],"batl":[[0,2.8,5],[1,9.6,1.47],[2,1000,0.02]],"ltp":2.24,"tv":1877.99,"id":31379},{"trd":[[1.82,12.07]],"batb":[[0,1.63,86.46],[1,1.55,6.28],[2,1.48,1.44]],"ltp":1.82,"tv":410.1,"id":424676}],"tv":2288.09}]}
{"op":"mcm","clk":"11857616753","pt":1723370835825,"mc":[{"id":"1.231582255","rc":[{"batl":[[1,3.55,1.19],[2,1000,0.03]],"ltp":1.82,"tv":410.1,"id":424676}]}]}
{"op":"mcm","clk":"11857616948","pt":1723370836989,"mc":[{"id":"1.231582255","rc":[{"batb":[[0,1.84,5.8],[1,1.78,3.33],[2,1.7,3.98]],"ltp":2.24,"tv":1877.99,"id":31379}]}]}
{"op":"mcm","clk":"11857617592","pt":1723370841725,"mc":[{"id":"1.231582255","rc":[{"batl":[[0,3.55,1.19],[1,1000,0.03],[2,1000,0]],"ltp":1.82,"tv":410.1,"id":424676}]}]}
{"op":"mcm","clk":"11857618344","pt":1723370847022,"mc":[{"id":"1.231582255","rc":[{"batb":[[2,1.7,3.49]],"batl":[[1,9.6,1.12]],"ltp":2.24,"tv":1877.99,"id":31379},{"batb":[[2,1.46,8.58]],"batl":[[0,1000,0.87],[1,1000,0]],"ltp":1.82,"tv":410.1,"id":424676}]}]}
{"op":"mcm","clk":"11857618841","pt":1723370850935,"mc":[{"id":"1.231582255","rc":[{"batb":[[0,1.63,86.56]],"ltp":1.82,"tv":410.1,"id":424676}]}]}
{"op":"mcm","clk":"11857619529","pt":1723370855724,"mc":[{"id":"1.231582255","rc":[{"batb":[[0,1.87,6.18],[1,1.84,5.8],[2,1.78,3.33]],"batl":[[1,3.45,3.96],[2,1000,0.79]],"ltp":2.24,"tv":1877.99,"id":31379}]}]}
