{"op":"mcm","clk":"11915943527","pt":1724070015554,"mc":[{"id":"1.232012908","marketDefinition":{"bspMarket":false,"turnInPlayEnabled":true,"persistenceEnabled":true,"marketBaseRate":5.0,"eventId":"33508010","eventTypeId":"4","numberOfWinners":1,"bettingType":"ODDS","marketType":"MATCH_ODDS","marketTime":"2024-08-26T09:30:00.000Z","suspendTime":"2024-08-26T09:30:00.000Z","bspReconciled":false,"complete":true,"inPlay":false,"crossMatching":false,"runnersVoidable":false,"numberOfActiveRunners":2,"betDelay":0,"status":"OPEN","runners":[{"status":"ACTIVE","sortPriority":1,"id":23387705,"name":"Sunrisers"},{"status":"ACTIVE","sortPriority":2,"id":35736916,"name":"Northern Diamonds"}],"regulators":["MR_INT"],"countryCode":"GB","discountAllowed":false,"timezone":"GMT","openDate":"2024-08-26T09:30:00.000Z","version":6086370636,"name":"Match Odds","eventName":"Sunrisers v Northern Diamonds"},"rc":[{"batb":[[0,1.03,200],[1,1.02,200],[2,1.01,220]],"ltp":0.0,"tv":0.0,"id":35736916},{"batb":[[0,1.03,200],[1,1.02,200],[2,1.01,220]],"ltp":0.0,"tv":0.0,"id":23387705}]}]}
{"op":"mcm","clk":"11915943632","pt":1724070017418,"mc":[{"id":"1.232012908","marketDefinition":{"bspMarket":false,"turnInPlayEnabled":true,"persistenceEnabled":true,"marketBaseRate":5.0,"eventId":"33508010","eventTypeId":"4","numberOfWinners":1,"bettingType":"ODDS","marketType":"MATCH_ODDS","marketTime":"2024-08-26T09:30:00.000Z","suspendTime":"2024-08-26T09:30:00.000Z","bspReconciled":false,"complete":true,"inPlay":false,"crossMatching":false,"runnersVoidable":false,"numberOfActiveRunners":2,"betDelay":0,"status":"OPEN","runners":[{"status":"ACTIVE","sortPriority":1,"id":23387705,"name":"Sunrisers"},{"status":"ACTIVE","sortPriority":2,"id":35736916,"name":"Northern Diamonds"}],"regulators":["MR_INT"],"countryCode":"GB","discountAllowed":true,"timezone":"GMT","openDate":"2024-08-26T09:30:00.000Z","version":6086370636,"name":"Match Odds","eventName":"Sunrisers v Northern Diamonds"}}]}
{"op":"mcm","clk":"11915998387","pt":1724071020428,"mc":[{"id":"1.232012908","rc":[{"batb":[[2,1.01,221.11]],"ltp":0.0,"tv":0.0,"id":23387705}]}]}
{"op":"mcm","clk":"11916113843","pt":1724073029249,"mc":[{"id":"1.232012908","rc":[{"batb":[[0,1.2,250],[1,1.03,200],[2,1.02,200]],"ltp":0.0,"tv":0.0,"id":23387705}]}]}
{"op":"mcm","clk":"11916113883","pt":1724073030163,"mc":[{"id":"1.232012908","rc":[{"batb":[[0,1.2,250],[1,1.03,200],[2,1.02,200]],"ltp":0.0,"tv":0.0,"id":35736916}]}]}
{"op":"mcm","clk":"11916114335","pt":1724073038070,"mc":[{"id":"1.232012908","marketDefinition":{"bspMarket":false,"turnInPlayEnabled":true,"persistenceEnabled":true,"marketBaseRate":5.0,"eventId":"33508010","eventTypeId":"4","numberOfWinners":1,"bettingType":"ODDS","marketType":"MATCH_ODDS","marketTime":"2024-08-26T09:30:00.000Z","suspendTime":"2024-08-26T09:30:00.000Z","bspReconciled":false,"complete":true,"inPlay":false,"crossMatching":true,"runnersVoidable":false,"numberOfActiveRunners":2,"betDelay":0,"status":"OPEN","runners":[{"status":"ACTIVE","sortPriority":1,"id":23387705,"name":"Sunrisers"},{"status":"ACTIVE","sortPriority":2,"id":35736916,"name":"Northern Diamonds"}],"regulators":["MR_INT"],"countryCode":"GB","discountAllowed":true,"timezone":"GMT","openDate":"2024-08-26T09:30:00.000Z","version":6086370636,"name":"Match Odds","eventName":"Sunrisers v Northern Diamonds"}}]}
{"op":"mcm","clk":"11916138995","pt":1724073411237,"mc":[{"id":"1.232012908","rc":[{"batb":[[0,1.21,6.59],[1,1.2,250],[2,1.03,200]],"ltp":0.0,"tv":0.0,"id":23387705}]}]}
{"op":"mcm","clk":"11916139026","pt":1724073411544,"mc":[{"id":"1.232012908","rc":[{"batb":[[0,1.21,5.89],[1,1.2,250],[2,1.03,200]],"ltp":0.0,"tv":0.0,"id":35736916}]}]}
{"op":"mcm","clk":"11916361928","pt":1724076775000,"mc":[{"id":"1.232012908","rc":[{"batb":[[0,1.21,5.89]],"ltp":0.0,"tv":0.0,"id":35736916},{"batb":[[0,1.21,6.59]],"ltp":0.0,"tv":0.0,"id":23387705}]}]}
{"op":"mcm","clk":"11916807954","pt":1724082174975,"mc":[{"id":"1.232012908","rc":[{"batb":[[0,1.21,5.88]],"ltp":0.0,"tv":0.0,"id":35736916},{"batb":[[0,1.21,6.58]],"ltp":0.0,"tv":0.0,"id":23387705}]}]}
{"op":"mcm","clk":"11917492109","pt":1724087574966,"mc":[{"id":"1.232012908","rc":[{"batb":[[0,1.21,5.88]],"ltp":0.0,"tv":0.0,"id":35736916},{"batb":[[0,1.21,6.58]],"ltp":0.0,"tv":0.0,"id":23387705}]}]}
{"op":"mcm","clk":"11918306261","pt":1724092975018,"mc":[{"id":"1.232012908","rc":[{"batb":[[0,1.21,5.87]],"ltp":0.0,"tv":0.0,"id":35736916},{"batb":[[0,1.21,6.57]],"ltp":0.0,"tv":0.0,"id":23387705}]}]}
{"op":"mcm","clk":"11919925592","pt":1724114574987,"mc":[{"id":"1.232012908","rc":[{"batb":[[0,1.21,6.57]],"ltp":0.0,"tv":0.0,"id":23387705}]}]}
{"op":"mcm","clk":"11920194906","pt":1724119975028,"mc":[{"id":"1.232012908","rc":[{"batb":[[0,1.21,5.88]],"ltp":0.0,"tv":0.0,"id":35736916},{"batb":[[0,1.21,6.58]],"ltp":0.0,"tv":0.0,"id":23387705}]}]}
{"op":"mcm","clk":"11920388017","pt":1724125374999,"mc":[{"id":"1.232012908","rc":[{"batb":[[0,1.21,5.88]],"ltp":0.0,"tv":0.0,"id":35736916},{"batb":[[0,1.21,6.58]],"ltp":0.0,"tv":0.0,"id":23387705}]}]}
{"op":"mcm","clk":"11920514866","pt":1724129287349,"mc":[{"id":"1.232012908","rc":[{"batb":[[0,1.22,38.99],[1,1.21,5.88],[2,1.2,250]],"ltp":0.0,"tv":0.0,"id":35736916},{"batb":[[0,1.22,38.99],[1,1.21,6.58],[2,1.2,250]],"ltp":0.0,"tv":0.0,"id":23387705}]}]}
{"op":"mcm","clk":"11920578390","pt":1724130774996,"mc":[{"id":"1.232012908","rc":[{"batb":[[1,1.21,6.58]],"ltp":0.0,"tv":0.0,"id":23387705}]}]}
{"op":"mcm","clk":"11920593296","pt":1724131087767,"mc":[{"id":"1.232012908","rc":[{"batb":[[0,1.21,5.88],[1,1.2,250],[2,1.03,200]],"ltp":0.0,"tv":0.0,"id":35736916},{"batb":[[0,1.21,6.58],[1,1.2,250],[2,1.03,200]],"ltp":0.0,"tv":0.0,"id":23387705}]}]}
{"op":"mcm","clk":"11920595067","pt":1724131154426,"mc":[{"id":"1.232012908","rc":[{"batb":[[0,1.22,38.99],[1,1.21,5.88],[2,1.2,250]],"ltp":0.0,"tv":0.0,"id":35736916},{"batb":[[0,1.22,38.99],[1,1.21,6.58],[2,1.2,250]],"ltp":0.0,"tv":0.0,"id":23387705}]}]}
{"op":"mcm","clk":"11920603231","pt":1724131424053,"mc":[{"id":"1.232012908","rc":[{"batb":[[0,1.23,5.88],[1,1.22,38.99]],"ltp":0.0,"tv":0.0,"id":35736916},{"batb":[[0,1.23,6.58],[1,1.22,38.99]],"ltp":0.0,"tv":0.0,"id":23387705}]}]}
{"op":"mcm","clk":"11920658761","pt":1724132954782,"mc":[{"id":"1.232012908","rc":[{"batb":[[1,1.2,250],[2,1.03,200]],"ltp":0.0,"tv":0.0,"id":35736916},{"batb":[[1,1.2,250],[2,1.03,200]],"ltp":0.0,"tv":0.0,"id":23387705}]}]}
{"op":"mcm","clk":"11920661885","pt":1724133021233,"mc":[{"id":"1.232012908","rc":[{"batb":[[0,1.24,35.74],[1,1.23,5.88],[2,1.2,250]],"ltp":0.0,"tv":0.0,"id":35736916},{"batb":[[0,1.24,35.74],[1,1.23,6.58],[2,1.2,250]],"ltp":0.0,"tv":0.0,"id":23387705}]}]}
{"op":"mcm","clk":"11920686582","pt":1724133705385,"mc":[{"id":"1.232012908","rc":[{"batb":[[0,1.24,35.73],[1,1.2,250],[2,1.03,200]],"ltp":0.0,"tv":0.0,"id":35736916},{"batb":[[0,1.25,6.58],[1,1.24,35.73]],"ltp":0.0,"tv":0.0,"id":23387705}]}]}
{"op":"mcm","clk":"11920686588","pt":1724133705484,"mc":[{"id":"1.232012908","rc":[{"batb":[[0,1.25,5.88],[1,1.24,35.73],[2,1.2,250]],"ltp":0.0,"tv":0.0,"id":35736916}]}]}
{"op":"mcm","clk":"11920716409","pt":1724134821731,"mc":[{"id":"1.232012908","rc":[{"batb":[[1,1.2,250],[2,1.03,200]],"ltp":0.0,"tv":0.0,"id":35736916},{"batb":[[1,1.2,250],[2,1.03,200]],"ltp":0.0,"tv":0.0,"id":23387705}]}]}
{"op":"mcm","clk":"11920718078","pt":1724134886883,"mc":[{"id":"1.232012908","rc":[{"batb":[[0,1.26,32.98],[1,1.25,5.88],[2,1.2,250]],"ltp":0.0,"tv":0.0,"id":35736916},{"batb":[[0,1.26,32.98],[1,1.25,6.58],[2,1.2,250]],"ltp":0.0,"tv":0.0,"id":23387705}]}]}
{"op":"mcm","clk":"11920756163","pt":1724136015406,"mc":[{"id":"1.232012908","rc":[{"batb":[[0,1.27,6.58],[1,1.26,32.98]],"ltp":0.0,"tv":0.0,"id":23387705}]}]}
{"op":"mcm","clk":"11920756176","pt":1724136015920,"mc":[{"id":"1.232012908","rc":[{"batb":[[0,1.27,5.88],[1,1.26,32.98]],"ltp":0.0,"tv":0.0,"id":35736916}]}]}
{"op":"mcm","clk":"11920782704","pt":1724136688121,"mc":[{"id":"1.232012908","rc":[{"batb":[[1,1.2,250],[2,1.03,200]],"ltp":0.0,"tv":0.0,"id":35736916},{"batb":[[1,1.2,250],[2,1.03,200]],"ltp":0.0,"tv":0.0,"id":23387705}]}]}
{"op":"mcm","clk":"11920784559","pt":1724136751090,"mc":[{"id":"1.232012908","rc":[{"batb":[[0,1.28,30.63],[1,1.27,5.88],[2,1.2,250]],"ltp":0.0,"tv":0.0,"id":35736916},{"batb":[[0,1.28,30.63],[1,1.27,6.58],[2,1.2,250]],"ltp":0.0,"tv":0.0,"id":23387705}]}]}
{"op":"mcm","clk":"11920845614","pt":1724138551687,"mc":[{"id":"1.232012908","rc":[{"batb":[[0,1.27,5.87],[1,1.2,250],[2,1.03,200]],"ltp":0.0,"tv":0.0,"id":35736916},{"batb":[[0,1.27,6.57],[1,1.2,250],[2,1.03,200]],"ltp":0.0,"tv":0.0,"id":23387705}]}]}
{"op":"mcm","clk":"11920847570","pt":1724138613835,"mc":[{"id":"1.232012908","rc":[{"batb":[[0,1.28,30.61],[1,1.27,5.87],[2,1.2,250]],"ltp":0.0,"tv":0.0,"id":35736916},{"batb":[[0,1.28,30.61],[1,1.27,6.57],[2,1.2,250]],"ltp":0.0,"tv":0.0,"id":23387705}]}]}
{"op":"mcm","clk":"11920901767","pt":1724140415171,"mc":[{"id":"1.232012908","rc":[{"batb":[[0,1.27,5.87],[1,1.2,250],[2,1.03,200]],"ltp":0.0,"tv":0.0,"id":35736916},{"batb":[[0,1.27,6.57],[1,1.2,250],[2,1.03,200]],"ltp":0.0,"tv":0.0,"id":23387705}]}]}
{"op":"mcm","clk":"11920903947","pt":1724140477865,"mc":[{"id":"1.232012908","rc":[{"batb":[[0,1.28,30.61],[1,1.27,5.87],[2,1.2,250]],"ltp":0.0,"tv":0.0,"id":35736916},{"batb":[[0,1.28,30.61],[1,1.27,6.57],[2,1.2,250]],"ltp":0.0,"tv":0.0,"id":23387705}]}]}
{"op":"mcm","clk":"11920942116","pt":1724141575032,"mc":[{"id":"1.232012908","rc":[{"batb":[[0,1.28,30.61],[1,1.27,5.87]],"ltp":0.0,"tv":0.0,"id":35736916},{"batb":[[0,1.28,30.61],[1,1.27,6.57]],"ltp":0.0,"tv":0.0,"id":23387705}]}]}
{"op":"mcm","clk":"11920965062","pt":1724142278411,"mc":[{"id":"1.232012908","rc":[{"batb":[[0,1.27,5.87],[1,1.2,250],[2,1.03,200]],"ltp":0.0,"tv":0.0,"id":35736916},{"batb":[[0,1.27,6.57],[1,1.2,250],[2,1.03,200]],"ltp":0.0,"tv":0.0,"id":23387705}]}]}
{"op":"mcm","clk":"11920968848","pt":1724142402007,"mc":[{"id":"1.232012908","rc":[{"batb":[[0,1.28,30.61],[1,1.27,5.87],[2,1.2,250]],"ltp":0.0,"tv":0.0,"id":35736916},{"batb":[[0,1.28,30.61],[1,1.27,6.57],[2,1.2,250]],"ltp":0.0,"tv":0.0,"id":23387705}]}]}
{"op":"mcm","clk":"11921032107","pt":1724144202343,"mc":[{"id":"1.232012908","rc":[{"batb":[[0,1.27,5.87],[1,1.2,250],[2,1.03,200]],"ltp":0.0,"tv":0.0,"id":35736916}]}]}
{"op":"mcm","clk":"11921032116","pt":1724144202549,"mc":[{"id":"1.232012908","rc":[{"batb":[[0,1.27,6.57],[1,1.2,250],[2,1.03,200]],"ltp":0.0,"tv":0.0,"id":23387705}]}]}
{"op":"mcm","clk":"11921033834","pt":1724144245598,"mc":[{"id":"1.232012908","rc":[{"batb":[[0,1.28,30.61],[1,1.27,5.87],[2,1.2,250]],"ltp":0.0,"tv":0.0,"id":35736916},{"batb":[[0,1.28,30.61],[1,1.27,6.57],[2,1.2,250]],"ltp":0.0,"tv":0.0,"id":23387705}]}]}
{"op":"mcm","clk":"11921097036","pt":1724146046807,"mc":[{"id":"1.232012908","rc":[{"batb":[[0,1.27,5.87],[1,1.2,250],[2,1.03,200]],"ltp":0.0,"tv":0.0,"id":35736916},{"batb":[[0,1.27,6.57],[1,1.2,250],[2,1.03,200]],"ltp":0.0,"tv":0.0,"id":23387705}]}]}
{"op":"mcm","clk":"11921099775","pt":1724146082693,"mc":[{"id":"1.232012908","rc":[{"batb":[[0,1.28,30.59],[1,1.27,5.87],[2,1.2,250]],"ltp":0.0,"tv":0.0,"id":35736916},{"batb":[[0,1.28,30.59],[1,1.27,6.57],[2,1.2,250]],"ltp":0.0,"tv":0.0,"id":23387705}]}]}
{"op":"mcm","clk":"11921184097","pt":1724147883814,"mc":[{"id":"1.232012908","rc":[{"batb":[[0,1.27,5.87],[1,1.2,250],[2,1.03,200]],"ltp":0.0,"tv":0.0,"id":35736916},{"batb":[[0,1.27,6.57],[1,1.2,250],[2,1.03,200]],"ltp":0.0,"tv":0.0,"id":23387705}]}]}
{"op":"mcm","clk":"11921185470","pt":1724147915155,"mc":[{"id":"1.232012908","rc":[{"batb":[[0,1.28,30.59],[1,1.27,5.87],[2,1.2,250]],"ltp":0.0,"tv":0.0,"id":35736916},{"batb":[[0,1.28,30.59],[1,1.27,6.57],[2,1.2,250]],"ltp":0.0,"tv":0.0,"id":23387705}]}]}
{"op":"mcm","clk":"11921269494","pt":1724149715329,"mc":[{"id":"1.232012908","rc":[{"batb":[[0,1.27,5.87],[1,1.2,250],[2,1.03,200]],"ltp":0.0,"tv":0.0,"id":35736916},{"batb":[[0,1.28,30.57]],"ltp":0.0,"tv":0.0,"id":23387705}]}]}
{"op":"mcm","clk":"11921269503","pt":1724149715431,"mc":[{"id":"1.232012908","rc":[{"batb":[[0,1.27,6.57],[1,1.2,250],[2,1.03,200]],"ltp":0.0,"tv":0.0,"id":23387705}]}]}
{"op":"mcm","clk":"11921270729","pt":1724149746860,"mc":[{"id":"1.232012908","rc":[{"batb":[[0,1.28,30.57],[1,1.27,5.87],[2,1.2,250]],"ltp":0.0,"tv":0.0,"id":35736916},{"batb":[[0,1.28,30.57],[1,1.27,6.57],[2,1.2,250]],"ltp":0.0,"tv":0.0,"id":23387705}]}]}
{"op":"mcm","clk":"11921347758","pt":1724151547868,"mc":[{"id":"1.232012908","rc":[{"batb":[[0,1.27,5.87],[1,1.2,250],[2,1.04,1.53]],"ltp":0.0,"tv":0.0,"id":35736916},{"batb":[[0,1.27,6.57],[1,1.2,250],[2,1.04,1.53]],"ltp":0.0,"tv":0.0,"id":23387705}]}]}
{"op":"mcm","clk":"11921348495","pt":1724151563195,"mc":[{"id":"1.232012908","rc":[{"batb":[[0,1.28,30.57],[1,1.27,5.87],[2,1.2,250]],"ltp":0.0,"tv":0.0,"id":35736916},{"batb":[[0,1.28,30.57],[1,1.27,6.57],[2,1.2,250]],"ltp":0.0,"tv":0.0,"id":23387705}]}]}
{"op":"mcm","clk":"11921390003","pt":1724152374979,"mc":[{"id":"1.232012908","rc":[{"batb":[[0,1.28,30.59]],"ltp":0.0,"tv":0.0,"id":35736916},{"batb":[[0,1.28,30.59],[1,1.27,6.57]],"ltp":0.0,"tv":0.0,"id":23387705}]}]}
{"op":"mcm","clk":"11921436632","pt":1724153364117,"mc":[{"id":"1.232012908","rc":[{"batb":[[0,1.27,5.87],[1,1.2,250],[2,1.04,1.53]],"ltp":0.0,"tv":0.0,"id":35736916},{"batb":[[0,1.27,6.57],[1,1.2,250],[2,1.04,1.53]],"ltp":0.0,"tv":0.0,"id":23387705}]}]}
{"op":"mcm","clk":"11921436679","pt":1724153365297,"mc":[{"id":"1.232012908","rc":[{"batb":[[0,1.28,30.59],[1,1.27,5.87],[2,1.2,250]],"ltp":0.0,"tv":0.0,"id":35736916},{"batb":[[0,1.28,30.59],[1,1.27,6.57],[2,1.2,250]],"ltp":0.0,"tv":0.0,"id":23387705}]}]}
{"op":"mcm","clk":"11921515587","pt":1724155165626,"mc":[{"id":"1.232012908","rc":[{"batb":[[0,1.27,5.87],[1,1.2,250],[2,1.04,1.53]],"ltp":0.0,"tv":0.0,"id":35736916},{"batb":[[0,1.27,6.57],[1,1.2,250],[2,1.04,1.53]],"ltp":0.0,"tv":0.0,"id":23387705}]}]}
{"op":"mcm","clk":"11921521897","pt":1724155300483,"mc":[{"id":"1.232012908","rc":[{"batb":[[0,1.28,30.57],[1,1.27,5.86],[2,1.2,250]],"ltp":0.0,"tv":0.0,"id":35736916},{"batb":[[0,1.28,30.57],[1,1.27,6.56],[2,1.2,250]],"ltp":0.0,"tv":0.0,"id":23387705}]}]}
{"op":"mcm","clk":"11921609333","pt":1724157101405,"mc":[{"id":"1.232012908","rc":[{"batb":[[0,1.27,6.56],[1,1.2,250],[2,1.04,1.53]],"ltp":0.0,"tv":0.0,"id":23387705}]}]}
{"op":"mcm","clk":"11921609344","pt":1724157101611,"mc":[{"id":"1.232012908","rc":[{"batb":[[0,1.27,5.86],[1,1.2,250],[2,1.04,1.53]],"ltp":0.0,"tv":0.0,"id":35736916}]}]}
{"op":"mcm","clk":"11921611149","pt":1724157135424,"mc":[{"id":"1.232012908","rc":[{"batb":[[0,1.28,30.57],[1,1.27,5.86],[2,1.2,250]],"ltp":0.0,"tv":0.0,"id":35736916},{"batb":[[0,1.28,30.57],[1,1.27,6.56],[2,1.2,250]],"ltp":0.0,"tv":0.0,"id":23387705}]}]}
{"op":"mcm","clk":"11921712122","pt":1724158936192,"mc":[{"id":"1.232012908","rc":[{"batb":[[0,1.27,5.86],[1,1.2,250],[2,1.04,1.53]],"ltp":0.0,"tv":0.0,"id":35736916},{"batb":[[0,1.27,6.55],[1,1.2,250],[2,1.04,1.53]],"ltp":0.0,"tv":0.0,"id":23387705}]}]}
{"op":"mcm","clk":"11921713336","pt":1724158958720,"mc":[{"id":"1.232012908","rc":[{"batb":[[0,1.28,30.57],[1,1.27,5.86],[2,1.2,250]],"ltp":0.0,"tv":0.0,"id":35736916},{"batb":[[0,1.28,30.57],[1,1.27,6.55],[2,1.2,250]],"ltp":0.0,"tv":0.0,"id":23387705}]}]}
{"op":"mcm","clk":"11921812968","pt":1724160758930,"mc":[{"id":"1.232012908","rc":[{"batb":[[0,1.27,5.86],[1,1.2,250],[2,1.04,1.53]],"ltp":0.0,"tv":0.0,"id":35736916},{"batb":[[0,1.27,6.55],[1,1.2,250],[2,1.04,1.53]],"ltp":0.0,"tv":0.0,"id":23387705}]}]}
{"op":"mcm","clk":"11921813722","pt":1724160770365,"mc":[{"id":"1.232012908","rc":[{"batb":[[0,1.28,30.57],[1,1.27,5.86],[2,1.2,250]],"ltp":0.0,"tv":0.0,"id":35736916},{"batb":[[0,1.28,30.57],[1,1.27,6.55],[2,1.2,250]],"ltp":0.0,"tv":0.0,"id":23387705}]}]}
{"op":"mcm","clk":"11921909356","pt":1724162570825,"mc":[{"id":"1.232012908","rc":[{"batb":[[0,1.27,5.86],[1,1.2,250],[2,1.04,1.53]],"ltp":0.0,"tv":0.0,"id":35736916},{"batb":[[0,1.27,6.56],[1,1.2,250],[2,1.04,1.53]],"ltp":0.0,"tv":0.0,"id":23387705}]}]}
{"op":"mcm","clk":"11921909668","pt":1724162575403,"mc":[{"id":"1.232012908","rc":[{"batb":[[0,1.28,30.59],[1,1.27,5.86],[2,1.2,250]],"ltp":0.0,"tv":0.0,"id":35736916},{"batb":[[0,1.28,30.59],[1,1.27,6.56],[2,1.2,250]],"ltp":0.0,"tv":0.0,"id":23387705}]}]}
{"op":"mcm","clk":"11922021140","pt":1724164375811,"mc":[{"id":"1.232012908","rc":[{"batb":[[0,1.27,5.86],[1,1.2,250],[2,1.04,1.53]],"ltp":0.0,"tv":0.0,"id":35736916},{"batb":[[0,1.27,6.56],[1,1.2,250],[2,1.04,1.53]],"ltp":0.0,"tv":0.0,"id":23387705}]}]}
{"op":"mcm","clk":"11922030605","pt":1724164533323,"mc":[{"id":"1.232012908","rc":[{"batb":[[0,1.28,30.59],[1,1.27,5.86],[2,1.2,250]],"ltp":0.0,"tv":0.0,"id":35736916},{"batb":[[0,1.28,30.59],[1,1.27,6.56],[2,1.2,250]],"ltp":0.0,"tv":0.0,"id":23387705}]}]}
{"op":"mcm","clk":"11922132743","pt":1724166334216,"mc":[{"id":"1.232012908","rc":[{"batb":[[0,1.27,5.86],[1,1.2,250],[2,1.04,1.53]],"ltp":0.0,"tv":0.0,"id":35736916},{"batb":[[0,1.27,6.55],[1,1.2,250],[2,1.04,1.53]],"ltp":0.0,"tv":0.0,"id":23387705}]}]}
{"op":"mcm","clk":"11922142837","pt":1724166473934,"mc":[{"id":"1.232012908","rc":[{"batb":[[0,1.28,30.61],[1,1.27,5.86],[2,1.2,250]],"ltp":0.0,"tv":0.0,"id":35736916},{"batb":[[0,1.28,30.61],[1,1.27,6.55],[2,1.2,250]],"ltp":0.0,"tv":0.0,"id":23387705}]}]}
{"op":"mcm","clk":"11922277735","pt":1724168275204,"mc":[{"id":"1.232012908","rc":[{"batb":[[0,1.27,5.86],[1,1.2,250],[2,1.04,1.53]],"ltp":0.0,"tv":0.0,"id":35736916},{"batb":[[0,1.27,6.55],[1,1.2,250],[2,1.04,1.53]],"ltp":0.0,"tv":0.0,"id":23387705}]}]}
{"op":"mcm","clk":"11922289613","pt":1724168404621,"mc":[{"id":"1.232012908","rc":[{"batb":[[0,1.28,30.61],[1,1.27,5.86],[2,1.2,250]],"ltp":0.0,"tv":0.0,"id":35736916},{"batb":[[0,1.28,30.61],[1,1.27,6.55],[2,1.2,250]],"ltp":0.0,"tv":0.0,"id":23387705}]}]}
{"op":"mcm","clk":"11922468126","pt":1724170205959,"mc":[{"id":"1.232012908","rc":[{"batb":[[0,1.27,5.86],[1,1.2,250],[2,1.04,1.53]],"ltp":0.0,"tv":0.0,"id":35736916},{"batb":[[0,1.27,6.56],[1,1.2,250],[2,1.04,1.53]],"ltp":0.0,"tv":0.0,"id":23387705}]}]}
{"op":"mcm","clk":"11922481386","pt":1724170323081,"mc":[{"id":"1.232012908","rc":[{"batb":[[0,1.28,30.61],[1,1.27,5.86],[2,1.2,250]],"ltp":0.0,"tv":0.0,"id":35736916},{"batb":[[0,1.28,30.61],[1,1.27,6.56],[2,1.2,250]],"ltp":0.0,"tv":0.0,"id":23387705}]}]}
{"op":"mcm","clk":"11922677949","pt":1724172123326,"mc":[{"id":"1.232012908","rc":[{"batb":[[0,1.27,6.56],[1,1.2,250],[2,1.04,1.53]],"ltp":0.0,"tv":0.0,"id":23387705}]}]}
{"op":"mcm","clk":"11922677970","pt":1724172123537,"mc":[{"id":"1.232012908","rc":[{"batb":[[0,1.27,5.86],[1,1.2,250],[2,1.04,1.53]],"ltp":0.0,"tv":0.0,"id":35736916}]}]}
{"op":"mcm","clk":"11922687803","pt":1724172217167,"mc":[{"id":"1.232012908","rc":[{"batb":[[0,1.28,30.61],[1,1.27,5.86],[2,1.2,250]],"ltp":0.0,"tv":0.0,"id":35736916},{"batb":[[0,1.28,30.61],[1,1.27,6.56],[2,1.2,250]],"ltp":0.0,"tv":0.0,"id":23387705}]}]}
{"op":"mcm","clk":"11922879850","pt":1724173974980,"mc":[{"id":"1.232012908","rc":[{"batb":[[0,1.28,30.63]],"ltp":0.0,"tv":0.0,"id":35736916},{"batb":[[0,1.28,30.63],[1,1.27,6.56]],"ltp":0.0,"tv":0.0,"id":23387705}]}]}
{"op":"mcm","clk":"11922888111","pt":1724174018369,"mc":[{"id":"1.232012908","rc":[{"batb":[[0,1.27,6.56],[1,1.2,250],[2,1.04,1.53]],"ltp":0.0,"tv":0.0,"id":23387705}]}]}
{"op":"mcm","clk":"11922888135","pt":1724174018576,"mc":[{"id":"1.232012908","rc":[{"batb":[[0,1.27,5.86],[1,1.2,250],[2,1.04,1.53]],"ltp":0.0,"tv":0.0,"id":35736916}]}]}
{"op":"mcm","clk":"11922896181","pt":1724174088366,"mc":[{"id":"1.232012908","rc":[{"batb":[[0,1.28,30.63],[1,1.27,5.86],[2,1.2,250]],"ltp":0.0,"tv":0.0,"id":35736916},{"batb":[[0,1.28,30.63],[1,1.27,6.56],[2,1.2,250]],"ltp":0.0,"tv":0.0,"id":23387705}]}]}
{"op":"mcm","clk":"11923099364","pt":1724175888810,"mc":[{"id":"1.232012908","rc":[{"batb":[[0,1.27,5.86],[1,1.2,250],[2,1.04,1.53]],"ltp":0.0,"tv":0.0,"id":35736916},{"batb":[[0,1.27,6.56],[1,1.2,250],[2,1.04,1.53]],"ltp":0.0,"tv":0.0,"id":23387705}]}]}
{"op":"mcm","clk":"11923103373","pt":1724175925371,"mc":[{"id":"1.232012908","rc":[{"batb":[[0,1.28,30.63],[1,1.27,5.86],[2,1.2,250]],"ltp":0.0,"tv":0.0,"id":35736916},{"batb":[[0,1.28,30.63],[1,1.27,6.56],[2,1.2,250]],"ltp":0.0,"tv":0.0,"id":23387705}]}]}
{"op":"mcm","clk":"11923314486","pt":1724177725974,"mc":[{"id":"1.232012908","rc":[{"batb":[[0,1.27,5.86],[1,1.2,250],[2,1.04,1.53]],"ltp":0.0,"tv":0.0,"id":35736916},{"batb":[[0,1.27,6.56],[1,1.2,250],[2,1.04,1.53]],"ltp":0.0,"tv":0.0,"id":23387705}]}]}
{"op":"mcm","clk":"11923315534","pt":1724177734282,"mc":[{"id":"1.232012908","rc":[{"batb":[[0,1.28,30.65],[1,1.27,5.86],[2,1.2,250]],"ltp":0.0,"tv":0.0,"id":35736916},{"batb":[[0,1.28,30.65],[1,1.27,6.56],[2,1.2,250]],"ltp":0.0,"tv":0.0,"id":23387705}]}]}
{"op":"mcm","clk":"11923569575","pt":1724179535370,"mc":[{"id":"1.232012908","rc":[{"batb":[[0,1.27,5.86],[1,1.2,250],[2,1.04,1.53]],"ltp":0.0,"tv":0.0,"id":35736916},{"batb":[[0,1.27,6.56],[1,1.2,250],[2,1.04,1.53]],"ltp":0.0,"tv":0.0,"id":23387705}]}]}
{"op":"mcm","clk":"11923587606","pt":1724179640083,"mc":[{"id":"1.232012908","rc":[{"batb":[[0,1.28,30.65],[1,1.27,5.86],[2,1.2,250]],"ltp":0.0,"tv":0.0,"id":35736916},{"batb":[[0,1.28,30.65],[1,1.27,6.56],[2,1.2,250]],"ltp":0.0,"tv":0.0,"id":23387705}]}]}
{"op":"mcm","clk":"11923882686","pt":1724181441393,"mc":[{"id":"1.232012908","rc":[{"batb":[[0,1.27,5.86],[1,1.2,250],[2,1.04,1.53]],"ltp":0.0,"tv":0.0,"id":35736916},{"batb":[[0,1.28,30.64],[1,1.27,6.55]],"ltp":0.0,"tv":0.0,"id":23387705}]}]}
{"op":"mcm","clk":"11923882718","pt":1724181441560,"mc":[{"id":"1.232012908","rc":[{"batb":[[0,1.27,6.55],[1,1.2,250],[2,1.04,1.53]],"ltp":0.0,"tv":0.0,"id":23387705}]}]}
{"op":"mcm","clk":"11923893113","pt":1724181500698,"mc":[{"id":"1.232012908","rc":[{"batb":[[0,1.28,30.64],[1,1.27,5.86],[2,1.2,250]],"ltp":0.0,"tv":0.0,"id":35736916},{"batb":[[0,1.28,30.64],[1,1.27,6.55],[2,1.2,250]],"ltp":0.0,"tv":0.0,"id":23387705}]}]}
{"op":"mcm","clk":"11924154059","pt":1724183302011,"mc":[{"id":"1.232012908","rc":[{"batb":[[0,1.27,5.86],[1,1.2,250],[2,1.04,1.53]],"ltp":0.0,"tv":0.0,"id":35736916},{"batb":[[0,1.27,6.55],[1,1.2,250],[2,1.04,1.53]],"ltp":0.0,"tv":0.0,"id":23387705}]}]}
{"op":"mcm","clk":"11924159172","pt":1724183341252,"mc":[{"id":"1.232012908","rc":[{"batb":[[0,1.28,30.64],[1,1.27,5.86],[2,1.2,250]],"ltp":0.0,"tv":0.0,"id":35736916},{"batb":[[0,1.28,30.64],[1,1.27,6.55],[2,1.2,250]],"ltp":0.0,"tv":0.0,"id":23387705}]}]}
{"op":"mcm","clk":"11924351813","pt":1724184774990,"mc":[{"id":"1.232012908","rc":[{"batb":[[0,1.28,30.64],[1,1.27,5.85]],"ltp":0.0,"tv":0.0,"id":35736916},{"batb":[[0,1.28,30.64],[1,1.27,6.55]],"ltp":0.0,"tv":0.0,"id":23387705}]}]}
{"op":"mcm","clk":"11924397843","pt":1724185141751,"mc":[{"id":"1.232012908","rc":[{"batb":[[0,1.27,5.85],[1,1.2,250],[2,1.04,1.53]],"ltp":0.0,"tv":0.0,"id":35736916},{"batb":[[0,1.27,6.55],[1,1.2,250],[2,1.04,1.53]],"ltp":0.0,"tv":0.0,"id":23387705}]}]}
{"op":"mcm","clk":"11924413142","pt":1724185270370,"mc":[{"id":"1.232012908","rc":[{"batb":[[0,1.28,30.64],[1,1.27,5.85],[2,1.2,250]],"ltp":0.0,"tv":0.0,"id":35736916},{"batb":[[0,1.28,30.64],[1,1.27,6.55],[2,1.2,250]],"ltp":0.0,"tv":0.0,"id":23387705}]}]}
{"op":"mcm","clk":"11924561641","pt":1724187070801,"mc":[{"id":"1.232012908","rc":[{"batb":[[0,1.27,5.85],[1,1.2,250],[2,1.04,1.53]],"ltp":0.0,"tv":0.0,"id":35736916},{"batb":[[0,1.27,6.55],[1,1.2,250],[2,1.04,1.53]],"ltp":0.0,"tv":0.0,"id":23387705}]}]}
{"op":"mcm","clk":"11924563889","pt":1724187130263,"mc":[{"id":"1.232012908","rc":[{"batb":[[0,1.28,30.64],[1,1.27,5.85],[2,1.2,250]],"ltp":0.0,"tv":0.0,"id":35736916},{"batb":[[0,1.28,30.64],[1,1.27,6.55],[2,1.2,250]],"ltp":0.0,"tv":0.0,"id":23387705}]}]}
{"op":"mcm","clk":"11924633465","pt":1724188930706,"mc":[{"id":"1.232012908","rc":[{"batb":[[0,1.27,5.85],[1,1.2,250],[2,1.04,1.53]],"ltp":0.0,"tv":0.0,"id":35736916},{"batb":[[0,1.27,6.55],[1,1.2,250],[2,1.04,1.53]],"ltp":0.0,"tv":0.0,"id":23387705}]}]}
{"op":"mcm","clk":"11924636876","pt":1724189022299,"mc":[{"id":"1.232012908","rc":[{"batb":[[0,1.28,30.65],[1,1.27,5.85],[2,1.2,250]],"ltp":0.0,"tv":0.0,"id":35736916},{"batb":[[0,1.28,30.65],[1,1.27,6.55],[2,1.2,250]],"ltp":0.0,"tv":0.0,"id":23387705}]}]}
{"op":"mcm","clk":"11924728551","pt":1724190822716,"mc":[{"id":"1.232012908","rc":[{"batb":[[0,1.27,5.85],[1,1.2,250],[2,1.04,1.53]],"ltp":0.0,"tv":0.0,"id":35736916},{"batb":[[0,1.27,6.55],[1,1.2,250],[2,1.04,1.53]],"ltp":0.0,"tv":0.0,"id":23387705}]}]}
{"op":"mcm","clk":"11924730859","pt":1724190874959,"mc":[{"id":"1.232012908","rc":[{"batb":[[0,1.28,30.65],[1,1.27,5.85],[2,1.2,250]],"ltp":0.0,"tv":0.0,"id":35736916},{"batb":[[0,1.28,30.65],[1,1.27,6.55],[2,1.2,250]],"ltp":0.0,"tv":0.0,"id":23387705}]}]}
{"op":"mcm","clk":"11924831569","pt":1724192675256,"mc":[{"id":"1.232012908","rc":[{"batb":[[0,1.28,30.65]],"ltp":0.0,"tv":0.0,"id":35736916},{"batb":[[0,1.27,6.55],[1,1.2,250],[2,1.04,1.53]],"ltp":0.0,"tv":0.0,"id":23387705}]}]}
{"op":"mcm","clk":"11924831581","pt":1724192675460,"mc":[{"id":"1.232012908","rc":[{"batb":[[0,1.27,5.85],[1,1.2,250],[2,1.04,1.53]],"ltp":0.0,"tv":0.0,"id":35736916}]}]}
{"op":"mcm","clk":"11924833566","pt":1724192713880,"mc":[{"id":"1.232012908","rc":[{"batb":[[0,1.28,30.65],[1,1.27,5.85],[2,1.2,250]],"ltp":0.0,"tv":0.0,"id":35736916},{"batb":[[0,1.28,30.65],[1,1.27,6.55],[2,1.2,250]],"ltp":0.0,"tv":0.0,"id":23387705}]}]}
{"op":"mcm","clk":"11924938391","pt":1724194515095,"mc":[{"id":"1.232012908","rc":[{"batb":[[0,1.27,5.85],[1,1.2,250],[2,1.04,1.53]],"ltp":0.0,"tv":0.0,"id":35736916},{"batb":[[0,1.27,6.55],[1,1.2,250],[2,1.04,1.53]],"ltp":0.0,"tv":0.0,"id":23387705}]}]}
{"op":"mcm","clk":"11924939579","pt":1724194536113,"mc":[{"id":"1.232012908","rc":[{"batb":[[0,1.28,30.65],[1,1.27,5.85],[2,1.2,250]],"ltp":0.0,"tv":0.0,"id":35736916},{"batb":[[0,1.28,30.65],[1,1.27,6.55],[2,1.2,250]],"ltp":0.0,"tv":0.0,"id":23387705}]}]}
{"op":"mcm","clk":"11924995630","pt":1724195575059,"mc":[{"id":"1.232012908","rc":[{"batb":[[0,1.28,30.66]],"ltp":0.0,"tv":0.0,"id":35736916},{"batb":[[0,1.28,30.66]],"ltp":0.0,"tv":0.0,"id":23387705}]}]}
{"op":"mcm","clk":"11925038470","pt":1724196336394,"mc":[{"id":"1.232012908","rc":[{"batb":[[0,1.27,6.55],[1,1.2,250],[2,1.04,1.53]],"ltp":0.0,"tv":0.0,"id":23387705}]}]}
{"op":"mcm","clk":"11925038485","pt":1724196336601,"mc":[{"id":"1.232012908","rc":[{"batb":[[0,1.27,5.86],[1,1.2,250],[2,1.04,1.53]],"ltp":0.0,"tv":0.0,"id":35736916}]}]}
{"op":"mcm","clk":"11925045522","pt":1724196454937,"mc":[{"id":"1.232012908","rc":[{"batb":[[0,1.28,30.66],[1,1.27,5.86],[2,1.2,250]],"ltp":0.0,"tv":0.0,"id":35736916},{"batb":[[0,1.28,30.66],[1,1.27,6.55],[2,1.2,250]],"ltp":0.0,"tv":0.0,"id":23387705}]}]}
{"op":"mcm","clk":"11925133861","pt":1724198255225,"mc":[{"id":"1.232012908","rc":[{"batb":[[0,1.27,5.86],[1,1.2,250],[2,1.04,1.53]],"ltp":0.0,"tv":0.0,"id":35736916}]}]}
{"op":"mcm","clk":"11925133873","pt":1724198255428,"mc":[{"id":"1.232012908","rc":[{"batb":[[0,1.27,6.55],[1,1.2,250],[2,1.04,1.53]],"ltp":0.0,"tv":0.0,"id":23387705}]}]}
{"op":"mcm","clk":"11925138973","pt":1724198351717,"mc":[{"id":"1.232012908","rc":[{"batb":[[0,1.28,30.66],[1,1.27,5.86],[2,1.2,250]],"ltp":0.0,"tv":0.0,"id":35736916},{"batb":[[0,1.28,30.66],[1,1.27,6.55],[2,1.2,250]],"ltp":0.0,"tv":0.0,"id":23387705}]}]}
{"op":"mcm","clk":"11925230453","pt":1724200152132,"mc":[{"id":"1.232012908","rc":[{"batb":[[0,1.27,5.85],[1,1.2,250],[2,1.04,1.53]],"ltp":0.0,"tv":0.0,"id":35736916},{"batb":[[0,1.27,6.55],[1,1.2,250],[2,1.04,1.53]],"ltp":0.0,"tv":0.0,"id":23387705}]}]}
{"op":"mcm","clk":"11925230925","pt":1724200161043,"mc":[{"id":"1.232012908","rc":[{"batb":[[0,1.21,5.85]],"ltp":0.0,"tv":0.0,"id":35736916},{"batb":[[0,1.21,6.55]],"ltp":0.0,"tv":0.0,"id":23387705}]}]}
{"op":"mcm","clk":"11925233828","pt":1724200209032,"mc":[{"id":"1.232012908","rc":[{"batb":[[0,1.22,39],[1,1.21,5.85],[2,1.2,250]],"ltp":0.0,"tv":0.0,"id":35736916},{"batb":[[0,1.22,39],[1,1.21,6.55],[2,1.2,250]],"ltp":0.0,"tv":0.0,"id":23387705}]}]}
{"op":"mcm","clk":"11925375303","pt":1724202010282,"mc":[{"id":"1.232012908","rc":[{"batb":[[0,1.21,5.85],[1,1.2,250],[2,1.04,1.53]],"ltp":0.0,"tv":0.0,"id":35736916},{"batb":[[0,1.21,6.55],[1,1.2,250],[2,1.04,1.53]],"ltp":0.0,"tv":0.0,"id":23387705}]}]}
{"op":"mcm","clk":"11925377472","pt":1724202041088,"mc":[{"id":"1.232012908","rc":[{"batb":[[0,1.22,39],[1,1.21,5.85],[2,1.2,250]],"ltp":0.0,"tv":0.0,"id":35736916},{"batb":[[0,1.22,39],[1,1.21,6.55],[2,1.2,250]],"ltp":0.0,"tv":0.0,"id":23387705}]}]}
{"op":"mcm","clk":"11925382912","pt":1724202119331,"mc":[{"id":"1.232012908","rc":[{"batb":[[1,1.2,250],[2,1.04,1.53]],"ltp":0.0,"tv":0.0,"id":35736916},{"batb":[[0,1.23,6.55],[1,1.22,39]],"ltp":0.0,"tv":0.0,"id":23387705}]}]}
{"op":"mcm","clk":"11925382921","pt":1724202119432,"mc":[{"id":"1.232012908","rc":[{"batb":[[0,1.23,5.85],[1,1.22,39],[2,1.2,250]],"ltp":0.0,"tv":0.0,"id":35736916}]}]}
{"op":"mcm","clk":"11925494756","pt":1724203842269,"mc":[{"id":"1.232012908","rc":[{"batb":[[1,1.2,250],[2,1.04,1.53]],"ltp":0.0,"tv":0.0,"id":35736916},{"batb":[[1,1.2,250],[2,1.04,1.53]],"ltp":0.0,"tv":0.0,"id":23387705}]}]}
{"op":"mcm","clk":"11925495318","pt":1724203851249,"mc":[{"id":"1.232012908","rc":[{"batb":[[0,1.24,35.75],[1,1.23,5.85],[2,1.2,250]],"ltp":0.0,"tv":0.0,"id":35736916},{"batb":[[0,1.24,35.75],[1,1.23,6.55],[2,1.2,250]],"ltp":0.0,"tv":0.0,"id":23387705}]}]}
{"op":"mcm","clk":"11925514148","pt":1724204121006,"mc":[{"id":"1.232012908","rc":[{"batb":[[0,1.25,5.85],[1,1.24,35.75]],"ltp":0.0,"tv":0.0,"id":35736916},{"batb":[[0,1.25,6.55],[1,1.24,35.75]],"ltp":0.0,"tv":0.0,"id":23387705}]}]}
{"op":"mcm","clk":"11925632298","pt":1724205651697,"mc":[{"id":"1.232012908","rc":[{"batb":[[0,1.25,5.86],[1,1.2,250],[2,1.04,1.53]],"ltp":0.0,"tv":0.0,"id":35736916},{"batb":[[0,1.25,6.56],[1,1.2,250],[2,1.04,1.53]],"ltp":0.0,"tv":0.0,"id":23387705}]}]}
{"op":"mcm","clk":"11925640197","pt":1724205748920,"mc":[{"id":"1.232012908","rc":[{"batb":[[0,1.26,33.01],[1,1.25,5.86],[2,1.2,250]],"ltp":0.0,"tv":0.0,"id":35736916},{"batb":[[0,1.26,33.01],[1,1.25,6.56],[2,1.2,250]],"ltp":0.0,"tv":0.0,"id":23387705}]}]}
{"op":"mcm","clk":"11925670707","pt":1724206150047,"mc":[{"id":"1.232012908","rc":[{"batb":[[0,1.27,5.86],[1,1.26,33.01]],"ltp":0.0,"tv":0.0,"id":35736916},{"batb":[[0,1.27,6.56],[1,1.26,33.01]],"ltp":0.0,"tv":0.0,"id":23387705}]}]}
{"op":"mcm","clk":"11925759256","pt":1724207549260,"mc":[{"id":"1.232012908","rc":[{"batb":[[1,1.2,250],[2,1.04,1.53]],"ltp":0.0,"tv":0.0,"id":35736916},{"batb":[[1,1.2,250],[2,1.04,1.53]],"ltp":0.0,"tv":0.0,"id":23387705}]}]}
{"op":"mcm","clk":"11925762071","pt":1724207617933,"mc":[{"id":"1.232012908","rc":[{"batb":[[0,1.28,30.65],[1,1.27,5.86],[2,1.2,250]],"ltp":0.0,"tv":0.0,"id":35736916},{"batb":[[0,1.28,30.65],[1,1.27,6.56],[2,1.2,250]],"ltp":0.0,"tv":0.0,"id":23387705}]}]}
{"op":"mcm","clk":"11925838927","pt":1724209418311,"mc":[{"id":"1.232012908","rc":[{"batb":[[0,1.27,5.86],[1,1.2,250],[2,1.04,1.53]],"ltp":0.0,"tv":0.0,"id":35736916},{"batb":[[0,1.27,6.56],[1,1.2,250],[2,1.04,1.53]],"ltp":0.0,"tv":0.0,"id":23387705}]}]}
{"op":"mcm","clk":"11925840420","pt":1724209456154,"mc":[{"id":"1.232012908","rc":[{"batb":[[0,1.28,30.64],[1,1.27,5.86],[2,1.2,250]],"ltp":0.0,"tv":0.0,"id":35736916},{"batb":[[0,1.28,30.64],[1,1.27,6.56],[2,1.2,250]],"ltp":0.0,"tv":0.0,"id":23387705}]}]}
{"op":"mcm","clk":"11925905346","pt":1724211256745,"mc":[{"id":"1.232012908","rc":[{"batb":[[0,1.27,5.86],[1,1.2,250],[2,1.04,1.53]],"ltp":0.0,"tv":0.0,"id":35736916},{"batb":[[0,1.27,6.56],[1,1.2,250],[2,1.04,1.53]],"ltp":0.0,"tv":0.0,"id":23387705}]}]}
{"op":"mcm","clk":"11925905983","pt":1724211279073,"mc":[{"id":"1.232012908","rc":[{"batb":[[0,1.28,30.64],[1,1.27,5.86],[2,1.2,250]],"ltp":0.0,"tv":0.0,"id":35736916},{"batb":[[0,1.28,30.64],[1,1.27,6.56],[2,1.2,250]],"ltp":0.0,"tv":0.0,"id":23387705}]}]}
{"op":"mcm","clk":"11925976467","pt":1724213079305,"mc":[{"id":"1.232012908","rc":[{"batb":[[0,1.28,30.64]],"ltp":0.0,"tv":0.0,"id":35736916},{"batb":[[0,1.27,6.56],[1,1.2,250],[2,1.04,1.53]],"ltp":0.0,"tv":0.0,"id":23387705}]}]}
{"op":"mcm","clk":"11925976473","pt":1724213079508,"mc":[{"id":"1.232012908","rc":[{"batb":[[0,1.27,5.86],[1,1.2,250],[2,1.04,1.53]],"ltp":0.0,"tv":0.0,"id":35736916}]}]}
{"op":"mcm","clk":"11925976968","pt":1724213093623,"mc":[{"id":"1.232012908","rc":[{"batb":[[0,1.28,30.64],[1,1.27,5.86],[2,1.2,250]],"ltp":0.0,"tv":0.0,"id":35736916},{"batb":[[0,1.28,30.64],[1,1.27,6.56],[2,1.2,250]],"ltp":0.0,"tv":0.0,"id":23387705}]}]}
{"op":"mcm","clk":"11926032104","pt":1724214894125,"mc":[{"id":"1.232012908","rc":[{"batb":[[0,1.27,5.86],[1,1.2,250],[2,1.04,1.53]],"ltp":0.0,"tv":0.0,"id":35736916},{"batb":[[0,1.27,6.56],[1,1.2,250],[2,1.04,1.53]],"ltp":0.0,"tv":0.0,"id":23387705}]}]}
{"op":"mcm","clk":"11926035041","pt":1724214989121,"mc":[{"id":"1.232012908","rc":[{"batb":[[0,1.28,30.64],[1,1.27,5.86],[2,1.2,250]],"ltp":0.0,"tv":0.0,"id":35736916},{"batb":[[0,1.28,30.64],[1,1.27,6.56],[2,1.2,250]],"ltp":0.0,"tv":0.0,"id":23387705}]}]}
{"op":"mcm","clk":"11926110920","pt":1724216789266,"mc":[{"id":"1.232012908","rc":[{"batb":[[0,1.27,5.86],[1,1.2,250],[2,1.04,1.53]],"ltp":0.0,"tv":0.0,"id":35736916},{"batb":[[0,1.28,30.64]],"ltp":0.0,"tv":0.0,"id":23387705}]}]}
{"op":"mcm","clk":"11926110931","pt":1724216789472,"mc":[{"id":"1.232012908","rc":[{"batb":[[0,1.27,6.56],[1,1.2,250],[2,1.04,1.53]],"ltp":0.0,"tv":0.0,"id":23387705}]}]}
{"op":"mcm","clk":"11926115167","pt":1724216874256,"mc":[{"id":"1.232012908","rc":[{"batb":[[0,1.28,30.64],[1,1.27,5.86],[2,1.2,250]],"ltp":0.0,"tv":0.0,"id":35736916},{"batb":[[0,1.28,30.64],[1,1.27,6.56],[2,1.2,250]],"ltp":0.0,"tv":0.0,"id":23387705}]}]}
{"op":"mcm","clk":"11926198341","pt":1724218674794,"mc":[{"id":"1.232012908","rc":[{"batb":[[0,1.27,5.86],[1,1.2,250],[2,1.04,1.53]],"ltp":0.0,"tv":0.0,"id":35736916},{"batb":[[0,1.27,6.56],[1,1.2,250],[2,1.04,1.53]],"ltp":0.0,"tv":0.0,"id":23387705}]}]}
{"op":"mcm","clk":"11926201486","pt":1724218753504,"mc":[{"id":"1.232012908","rc":[{"batb":[[0,1.28,30.64],[1,1.27,5.86],[2,1.2,250]],"ltp":0.0,"tv":0.0,"id":35736916},{"batb":[[0,1.28,30.64],[1,1.27,6.56],[2,1.2,250]],"ltp":0.0,"tv":0.0,"id":23387705}]}]}
{"op":"mcm","clk":"11926253201","pt":1724219988869,"mc":[{"id":"1.232012908","rc":[{"batb":[[0,1.28,31.18]],"ltp":0.0,"tv":0.0,"id":23387705}]}]}
{"op":"mcm","clk":"11926253480","pt":1724219997885,"mc":[{"id":"1.232012908","rc":[{"batb":[[0,1.28,31.18]],"ltp":0.0,"tv":0.0,"id":35736916}]}]}
{"op":"mcm","clk":"11926277115","pt":1724220553740,"mc":[{"id":"1.232012908","rc":[{"batb":[[0,1.27,6.4],[1,1.2,250],[2,1.04,1.53]],"ltp":0.0,"tv":0.0,"id":35736916},{"batb":[[0,1.28,31.18],[1,1.27,6.56]],"ltp":0.0,"tv":0.0,"id":23387705}]}]}
{"op":"mcm","clk":"11926277148","pt":1724220554712,"mc":[{"id":"1.232012908","rc":[{"batb":[[0,1.27,7.09],[1,1.2,250],[2,1.04,1.53]],"ltp":0.0,"tv":0.0,"id":23387705}]}]}
{"op":"mcm","clk":"11926279895","pt":1724220628413,"mc":[{"id":"1.232012908","rc":[{"batb":[[0,1.28,31.18],[1,1.27,5.86],[2,1.2,250]],"ltp":0.0,"tv":0.0,"id":35736916},{"batb":[[0,1.28,31.18],[1,1.27,6.56],[2,1.2,250]],"ltp":0.0,"tv":0.0,"id":23387705}]}]}
{"op":"mcm","clk":"11926353371","pt":1724222429281,"mc":[{"id":"1.232012908","rc":[{"batb":[[0,1.27,7.09],[1,1.2,250],[2,1.04,1.53]],"ltp":0.0,"tv":0.0,"id":23387705}]}]}
{"op":"mcm","clk":"11926353377","pt":1724222429442,"mc":[{"id":"1.232012908","rc":[{"batb":[[0,1.27,6.4],[1,1.2,250],[2,1.04,1.53]],"ltp":0.0,"tv":0.0,"id":35736916}]}]}
{"op":"mcm","clk":"11926355788","pt":1724222499404,"mc":[{"id":"1.232012908","rc":[{"batb":[[0,1.28,31.18],[1,1.27,5.86],[2,1.2,250]],"ltp":0.0,"tv":0.0,"id":35736916},{"batb":[[0,1.28,31.18],[1,1.27,6.56],[2,1.2,250]],"ltp":0.0,"tv":0.0,"id":23387705}]}]}
{"op":"mcm","clk":"11926440150","pt":1724224300391,"mc":[{"id":"1.232012908","rc":[{"batb":[[0,1.27,6.4],[1,1.2,250],[2,1.04,1.53]],"ltp":0.0,"tv":0.0,"id":35736916},{"batb":[[0,1.28,31.19],[1,1.27,6.56]],"ltp":0.0,"tv":0.0,"id":23387705}]}]}
{"op":"mcm","clk":"11926440156","pt":1724224300495,"mc":[{"id":"1.232012908","rc":[{"batb":[[0,1.27,7.1],[1,1.2,250],[2,1.04,1.53]],"ltp":0.0,"tv":0.0,"id":23387705}]}]}
{"op":"mcm","clk":"11926442828","pt":1724224367554,"mc":[{"id":"1.232012908","rc":[{"batb":[[0,1.28,31.19],[1,1.27,5.86],[2,1.2,250]],"ltp":0.0,"tv":0.0,"id":35736916},{"batb":[[0,1.28,31.19],[1,1.27,6.56],[2,1.2,250]],"ltp":0.0,"tv":0.0,"id":23387705}]}]}
{"op":"mcm","clk":"11926509123","pt":1724226167953,"mc":[{"id":"1.232012908","rc":[{"batb":[[0,1.27,6.4],[1,1.2,250],[2,1.04,1.53]],"ltp":0.0,"tv":0.0,"id":35736916},{"batb":[[0,1.27,7.1],[1,1.2,250],[2,1.04,1.53]],"ltp":0.0,"tv":0.0,"id":23387705}]}]}
{"op":"mcm","clk":"11926511990","pt":1724226227523,"mc":[{"id":"1.232012908","rc":[{"batb":[[0,1.28,31.19],[1,1.27,5.86],[2,1.2,250]],"ltp":0.0,"tv":0.0,"id":35736916},{"batb":[[0,1.28,31.19],[1,1.27,6.56],[2,1.2,250]],"ltp":0.0,"tv":0.0,"id":23387705}]}]}
{"op":"mcm","clk":"11926601452","pt":1724227974995,"mc":[{"id":"1.232012908","rc":[{"batb":[[0,1.28,31.19]],"ltp":0.0,"tv":0.0,"id":35736916},{"batb":[[0,1.28,31.19],[1,1.27,6.56]],"ltp":0.0,"tv":0.0,"id":23387705}]}]}
{"op":"mcm","clk":"11926606662","pt":1724228028008,"mc":[{"id":"1.232012908","rc":[{"batb":[[0,1.27,6.4],[1,1.2,250],[2,1.04,1.53]],"ltp":0.0,"tv":0.0,"id":35736916},{"batb":[[0,1.27,7.1],[1,1.2,250],[2,1.04,1.53]],"ltp":0.0,"tv":0.0,"id":23387705}]}]}
{"op":"mcm","clk":"11926609821","pt":1724228093691,"mc":[{"id":"1.232012908","rc":[{"batb":[[0,1.28,31.19],[1,1.27,5.86],[2,1.2,250]],"ltp":0.0,"tv":0.0,"id":35736916},{"batb":[[0,1.28,31.19],[1,1.27,6.56],[2,1.2,250]],"ltp":0.0,"tv":0.0,"id":23387705}]}]}
{"op":"mcm","clk":"11926701934","pt":1724229894080,"mc":[{"id":"1.232012908","rc":[{"batb":[[0,1.27,6.4],[1,1.2,250],[2,1.04,1.53]],"ltp":0.0,"tv":0.0,"id":35736916},{"batb":[[0,1.27,7.1],[1,1.2,250],[2,1.04,1.53]],"ltp":0.0,"tv":0.0,"id":23387705}]}]}
{"op":"mcm","clk":"11926703873","pt":1724229933111,"mc":[{"id":"1.232012908","rc":[{"batb":[[0,1.28,31.19],[1,1.27,5.86],[2,1.2,250]],"ltp":0.0,"tv":0.0,"id":35736916},{"batb":[[0,1.28,31.19],[1,1.27,6.56],[2,1.2,250]],"ltp":0.0,"tv":0.0,"id":23387705}]}]}
{"op":"mcm","clk":"11926797985","pt":1724231734214,"mc":[{"id":"1.232012908","rc":[{"batb":[[0,1.27,6.4],[1,1.2,250],[2,1.04,1.53]],"ltp":0.0,"tv":0.0,"id":35736916},{"batb":[[0,1.27,7.1],[1,1.2,250],[2,1.04,1.53]],"ltp":0.0,"tv":0.0,"id":23387705}]}]}
{"op":"mcm","clk":"11926801208","pt":1724231781148,"mc":[{"id":"1.232012908","rc":[{"batb":[[0,1.28,31.2],[1,1.27,5.86],[2,1.2,250]],"ltp":0.0,"tv":0.0,"id":35736916},{"batb":[[0,1.28,31.2],[1,1.27,6.56],[2,1.2,250]],"ltp":0.0,"tv":0.0,"id":23387705}]}]}
{"op":"mcm","clk":"11926889663","pt":1724233154232,"mc":[{"id":"1.232012908","rc":[{"batb":[[2,1.04,1.53]],"ltp":0.0,"tv":0.0,"id":35736916},{"batb":[[2,1.04,1.53]],"ltp":0.0,"tv":0.0,"id":23387705}]}]}
{"op":"mcm","clk":"11926894751","pt":1724233232971,"mc":[{"id":"1.232012908","rc":[{"batb":[[2,1.2,1105]],"ltp":0.0,"tv":0.0,"id":35736916},{"batb":[[2,1.2,1105]],"ltp":0.0,"tv":0.0,"id":23387705}]}]}
{"op":"mcm","clk":"11926928414","pt":1724233582120,"mc":[{"id":"1.232012908","rc":[{"batb":[[0,1.27,6.4],[1,1.2,1105],[2,1.04,1.53]],"ltp":0.0,"tv":0.0,"id":35736916},{"batb":[[0,1.27,7.1],[1,1.2,1105],[2,1.04,1.53]],"ltp":0.0,"tv":0.0,"id":23387705}]}]}
{"op":"mcm","clk":"11926931570","pt":1724233626467,"mc":[{"id":"1.232012908","rc":[{"batb":[[0,1.28,31.2],[1,1.27,5.86],[2,1.2,1105]],"ltp":0.0,"tv":0.0,"id":35736916},{"batb":[[0,1.28,31.2],[1,1.27,6.56],[2,1.2,1105]],"ltp":0.0,"tv":0.0,"id":23387705}]}]}
{"op":"mcm","clk":"11927083903","pt":1724235427150,"mc":[{"id":"1.232012908","rc":[{"batb":[[0,1.27,6.39],[1,1.2,1105],[2,1.04,1.53]],"ltp":0.0,"tv":0.0,"id":35736916},{"batb":[[0,1.27,7.09],[1,1.2,1105],[2,1.04,1.53]],"ltp":0.0,"tv":0.0,"id":23387705}]}]}
{"op":"mcm","clk":"11927084168","pt":1724235429959,"mc":[{"id":"1.232012908","rc":[{"batl":[[0,5.9,10.95]],"ltp":0.0,"tv":0.0,"id":35736916},{"batl":[[0,5.9,10.94]],"ltp":0.0,"tv":0.0,"id":23387705}]}]}
{"op":"mcm","clk":"11927087386","pt":1724235461704,"mc":[{"id":"1.232012908","rc":[{"batb":[[0,1.28,31.17],[1,1.27,5.86],[2,1.2,1105]],"ltp":0.0,"tv":0.0,"id":35736916},{"batb":[[0,1.28,31.17],[1,1.27,6.56],[2,1.2,1105]],"ltp":0.0,"tv":0.0,"id":23387705}]}]}
{"op":"mcm","clk":"11927263577","pt":1724237262296,"mc":[{"id":"1.232012908","rc":[{"batb":[[0,1.27,6.39],[1,1.2,1105],[2,1.04,1.53]],"ltp":0.0,"tv":0.0,"id":35736916},{"batb":[[0,1.27,7.09],[1,1.2,1105],[2,1.04,1.53]],"ltp":0.0,"tv":0.0,"id":23387705}]}]}
{"op":"mcm","clk":"11927264391","pt":1724237270166,"mc":[{"id":"1.232012908","rc":[{"batl":[[0,5.9,10.95]],"ltp":0.0,"tv":0.0,"id":35736916},{"batl":[[0,5.9,10.94]],"ltp":0.0,"tv":0.0,"id":23387705}]}]}
{"op":"mcm","clk":"11927266375","pt":1724237289515,"mc":[{"id":"1.232012908","rc":[{"batb":[[0,1.28,31.17],[1,1.27,5.86],[2,1.2,1105]],"ltp":0.0,"tv":0.0,"id":35736916},{"batb":[[0,1.28,31.17],[1,1.27,6.56],[2,1.2,1105]],"ltp":0.0,"tv":0.0,"id":23387705}]}]}
{"op":"mcm","clk":"11927404887","pt":1724238775007,"mc":[{"id":"1.232012908","rc":[{"batb":[[0,1.28,31.16],[1,1.27,5.85]],"ltp":0.0,"tv":0.0,"id":35736916},{"batb":[[0,1.28,31.16],[1,1.27,6.55]],"ltp":0.0,"tv":0.0,"id":23387705}]}]}
{"op":"mcm","clk":"11927442458","pt":1724239089998,"mc":[{"id":"1.232012908","rc":[{"batb":[[0,1.27,6.38],[1,1.2,1105],[2,1.04,1.53]],"ltp":0.0,"tv":0.0,"id":35736916},{"batb":[[0,1.27,7.08],[1,1.2,1105],[2,1.04,1.53]],"ltp":0.0,"tv":0.0,"id":23387705}]}]}
{"op":"mcm","clk":"11927442807","pt":1724239092875,"mc":[{"id":"1.232012908","rc":[{"batl":[[0,5.9,10.94]],"ltp":0.0,"tv":0.0,"id":35736916},{"batl":[[0,5.9,10.93]],"ltp":0.0,"tv":0.0,"id":23387705}]}]}
{"op":"mcm","clk":"11927444823","pt":1724239111597,"mc":[{"id":"1.232012908","rc":[{"batb":[[0,1.28,31.16],[1,1.27,5.85],[2,1.2,1105]],"ltp":0.0,"tv":0.0,"id":35736916},{"batb":[[0,1.28,31.16],[1,1.27,6.55],[2,1.2,1105]],"ltp":0.0,"tv":0.0,"id":23387705}]}]}
{"op":"mcm","clk":"11927612234","pt":1724240912011,"mc":[{"id":"1.232012908","rc":[{"batb":[[0,1.27,6.38],[1,1.2,1105],[2,1.04,1.53]],"ltp":0.0,"tv":0.0,"id":35736916},{"batb":[[0,1.27,7.08],[1,1.2,1105],[2,1.04,1.53]],"ltp":0.0,"tv":0.0,"id":23387705}]}]}
{"op":"mcm","clk":"11927613139","pt":1724240922332,"mc":[{"id":"1.232012908","rc":[{"batl":[[0,5.9,10.94]],"ltp":0.0,"tv":0.0,"id":35736916},{"batl":[[0,5.9,10.93]],"ltp":0.0,"tv":0.0,"id":23387705}]}]}
{"op":"mcm","clk":"11927621649","pt":1724241017117,"mc":[{"id":"1.232012908","rc":[{"batb":[[0,1.28,31.16],[1,1.27,5.85],[2,1.2,1105]],"ltp":0.0,"tv":0.0,"id":35736916},{"batb":[[0,1.28,31.16],[1,1.27,6.55],[2,1.2,1105]],"ltp":0.0,"tv":0.0,"id":23387705}]}]}
{"op":"mcm","clk":"11927625944","pt":1724241071606,"mc":[{"id":"1.232012908","rc":[{"batb":[[0,1.28,30.62]],"ltp":0.0,"tv":0.0,"id":23387705}]}]}
{"op":"mcm","clk":"11927626220","pt":1724241075598,"mc":[{"id":"1.232012908","rc":[{"batb":[[0,1.28,30.62]],"ltp":0.0,"tv":0.0,"id":35736916}]}]}
{"op":"mcm","clk":"11927749284","pt":1724242818355,"mc":[{"id":"1.232012908","rc":[{"batb":[[0,1.27,5.85],[1,1.2,1105],[2,1.04,1.53]],"ltp":0.0,"tv":0.0,"id":35736916},{"batb":[[0,1.27,6.55],[1,1.2,1105],[2,1.04,1.53]],"ltp":0.0,"tv":0.0,"id":23387705}]}]}
{"op":"mcm","clk":"11927750077","pt":1724242827969,"mc":[{"id":"1.232012908","rc":[{"batl":[[0,5.9,10.93]],"ltp":0.0,"tv":0.0,"id":35736916},{"batl":[[0,5.9,10.93]],"ltp":0.0,"tv":0.0,"id":23387705}]}]}
{"op":"mcm","clk":"11927755202","pt":1724242899352,"mc":[{"id":"1.232012908","rc":[{"batb":[[0,1.28,30.62],[1,1.27,5.85],[2,1.2,1105]],"ltp":0.0,"tv":0.0,"id":35736916},{"batb":[[0,1.28,30.62],[1,1.27,6.55],[2,1.2,1105]],"ltp":0.0,"tv":0.0,"id":23387705}]}]}
{"op":"mcm","clk":"11927875173","pt":1724244699706,"mc":[{"id":"1.232012908","rc":[{"batb":[[0,1.27,5.85],[1,1.2,1105],[2,1.04,1.53]],"ltp":0.0,"tv":0.0,"id":35736916},{"batb":[[0,1.27,6.55],[1,1.2,1105],[2,1.04,1.53]],"ltp":0.0,"tv":0.0,"id":23387705}]}]}
{"op":"mcm","clk":"11927875917","pt":1724244713618,"mc":[{"id":"1.232012908","rc":[{"batl":[[0,5.9,10.93]],"ltp":0.0,"tv":0.0,"id":35736916},{"batl":[[0,5.9,10.93]],"ltp":0.0,"tv":0.0,"id":23387705}]}]}
{"op":"mcm","clk":"11927878604","pt":1724244756288,"mc":[{"id":"1.232012908","rc":[{"batb":[[0,1.28,30.62],[1,1.27,5.85],[2,1.2,1105]],"ltp":0.0,"tv":0.0,"id":35736916},{"batb":[[0,1.28,30.62],[1,1.27,6.55],[2,1.2,1105]],"ltp":0.0,"tv":0.0,"id":23387705}]}]}
{"op":"mcm","clk":"11928003291","pt":1724246557232,"mc":[{"id":"1.232012908","rc":[{"batb":[[0,1.27,5.85],[1,1.2,1105],[2,1.04,1.53]],"ltp":0.0,"tv":0.0,"id":35736916},{"batb":[[0,1.27,6.55],[1,1.2,1105],[2,1.04,1.53]],"ltp":0.0,"tv":0.0,"id":23387705}]}]}
{"op":"mcm","clk":"11928003711","pt":1724246564627,"mc":[{"id":"1.232012908","rc":[{"batl":[[0,5.9,10.93]],"ltp":0.0,"tv":0.0,"id":35736916},{"batl":[[0,5.9,10.92]],"ltp":0.0,"tv":0.0,"id":23387705}]}]}
{"op":"mcm","clk":"11928006001","pt":1724246602498,"mc":[{"id":"1.232012908","rc":[{"batb":[[0,1.28,30.61],[1,1.27,5.85],[2,1.2,1105]],"ltp":0.0,"tv":0.0,"id":35736916},{"batb":[[0,1.28,30.61],[1,1.27,6.55],[2,1.2,1105]],"ltp":0.0,"tv":0.0,"id":23387705}]}]}
{"op":"mcm","clk":"11928123571","pt":1724248403402,"mc":[{"id":"1.232012908","rc":[{"batb":[[0,1.27,5.85],[1,1.2,1105],[2,1.04,1.53]],"ltp":0.0,"tv":0.0,"id":35736916}]}]}
{"op":"mcm","clk":"11928123596","pt":1724248403875,"mc":[{"id":"1.232012908","rc":[{"batl":[[0,5.9,10.93]],"ltp":0.0,"tv":0.0,"id":35736916},{"batb":[[0,1.27,6.55],[1,1.2,1105],[2,1.04,1.53]],"batl":[[0,5.9,10.92]],"ltp":0.0,"tv":0.0,"id":23387705}]}]}
{"op":"mcm","clk":"11928125339","pt":1724248434532,"mc":[{"id":"1.232012908","rc":[{"batb":[[0,1.28,30.61],[1,1.27,5.85],[2,1.2,1105]],"ltp":0.0,"tv":0.0,"id":35736916},{"batb":[[0,1.28,30.61],[1,1.27,6.55],[2,1.2,1105]],"ltp":0.0,"tv":0.0,"id":23387705}]}]}
{"op":"mcm","clk":"11928200043","pt":1724249574995,"mc":[{"id":"1.232012908","rc":[{"batb":[[0,1.28,30.57]],"ltp":0.0,"tv":0.0,"id":35736916},{"batb":[[0,1.28,30.57],[1,1.27,6.55]],"ltp":0.0,"tv":0.0,"id":23387705}]}]}
{"op":"mcm","clk":"11928243106","pt":1724250235310,"mc":[{"id":"1.232012908","rc":[{"batb":[[0,1.27,5.85],[1,1.2,1105],[2,1.04,1.53]],"ltp":0.0,"tv":0.0,"id":35736916}]}]}
{"op":"mcm","clk":"11928243121","pt":1724250235515,"mc":[{"id":"1.232012908","rc":[{"batb":[[0,1.27,6.55],[1,1.2,1105],[2,1.04,1.53]],"ltp":0.0,"tv":0.0,"id":23387705}]}]}
{"op":"mcm","clk":"11928243548","pt":1724250241399,"mc":[{"id":"1.232012908","rc":[{"batl":[[0,5.9,10.94]],"ltp":0.0,"tv":0.0,"id":35736916},{"batl":[[0,5.9,10.93]],"ltp":0.0,"tv":0.0,"id":23387705}]}]}
{"op":"mcm","clk":"11928244480","pt":1724250254227,"mc":[{"id":"1.232012908","rc":[{"batb":[[0,1.28,30.57],[1,1.27,5.85],[2,1.2,1105]],"ltp":0.0,"tv":0.0,"id":35736916},{"batb":[[0,1.28,30.57],[1,1.27,6.55],[2,1.2,1105]],"ltp":0.0,"tv":0.0,"id":23387705}]}]}
{"op":"mcm","clk":"11928349715","pt":1724252055346,"mc":[{"id":"1.232012908","rc":[{"batb":[[0,1.27,5.85],[1,1.2,1105],[2,1.04,1.53]],"batl":[[0,5.9,10.94]],"ltp":0.0,"tv":0.0,"id":35736916},{"batb":[[0,1.27,6.55],[1,1.2,1105],[2,1.04,1.53]],"batl":[[0,5.9,10.93]],"ltp":0.0,"tv":0.0,"id":23387705}]}]}
{"op":"mcm","clk":"11928355942","pt":1724252167902,"mc":[{"id":"1.232012908","rc":[{"batb":[[0,1.28,30.57],[1,1.27,5.85],[2,1.2,1105]],"ltp":0.0,"tv":0.0,"id":35736916},{"batb":[[0,1.28,30.57],[1,1.27,6.55],[2,1.2,1105]],"ltp":0.0,"tv":0.0,"id":23387705}]}]}
{"op":"mcm","clk":"11928525901","pt":1724253968100,"mc":[{"id":"1.232012908","rc":[{"batb":[[1,1.27,5.84]],"ltp":0.0,"tv":0.0,"id":35736916},{"batb":[[0,1.27,6.54],[1,1.2,1105],[2,1.04,1.53]],"ltp":0.0,"tv":0.0,"id":23387705}]}]}
{"op":"mcm","clk":"11928526010","pt":1724253969096,"mc":[{"id":"1.232012908","rc":[{"batb":[[0,1.27,5.84],[1,1.2,1105],[2,1.04,1.53]],"ltp":0.0,"tv":0.0,"id":35736916}]}]}
{"op":"mcm","clk":"11928527291","pt":1724253981011,"mc":[{"id":"1.232012908","rc":[{"batl":[[0,5.9,10.94]],"ltp":0.0,"tv":0.0,"id":35736916},{"batl":[[0,5.9,10.93]],"ltp":0.0,"tv":0.0,"id":23387705}]}]}
{"op":"mcm","clk":"11928542882","pt":1724254136521,"mc":[{"id":"1.232012908","rc":[{"batb":[[0,1.28,30.57],[1,1.27,5.84],[2,1.2,1105]],"ltp":0.0,"tv":0.0,"id":35736916},{"batb":[[0,1.28,30.57],[1,1.27,6.54],[2,1.2,1105]],"ltp":0.0,"tv":0.0,"id":23387705}]}]}
{"op":"mcm","clk":"11928773393","pt":1724255937095,"mc":[{"id":"1.232012908","rc":[{"batb":[[0,1.27,5.84],[1,1.2,1105],[2,1.04,1.53]],"ltp":0.0,"tv":0.0,"id":35736916},{"batb":[[0,1.27,6.54],[1,1.2,1105],[2,1.04,1.53]],"ltp":0.0,"tv":0.0,"id":23387705}]}]}
{"op":"mcm","clk":"11928774035","pt":1724255942613,"mc":[{"id":"1.232012908","rc":[{"batl":[[0,5.9,10.94]],"ltp":0.0,"tv":0.0,"id":35736916},{"batl":[[0,5.9,10.93]],"ltp":0.0,"tv":0.0,"id":23387705}]}]}
{"op":"mcm","clk":"11928793595","pt":1724256102256,"mc":[{"id":"1.232012908","rc":[{"batb":[[0,1.28,30.58],[1,1.27,5.83],[2,1.2,1105]],"batl":[[0,5.9,10.94]],"ltp":0.0,"tv":0.0,"id":35736916},{"batb":[[0,1.28,30.58],[1,1.27,6.53],[2,1.2,1105]],"batl":[[0,5.9,10.93]],"ltp":0.0,"tv":0.0,"id":23387705}]}]}
{"op":"mcm","clk":"11929046962","pt":1724257903377,"mc":[{"id":"1.232012908","rc":[{"batb":[[0,1.27,6.53],[1,1.2,1105],[2,1.04,1.53]],"ltp":0.0,"tv":0.0,"id":23387705}]}]}
{"op":"mcm","clk":"11929046988","pt":1724257903589,"mc":[{"id":"1.232012908","rc":[{"batb":[[0,1.27,5.83],[1,1.2,1105],[2,1.04,1.53]],"ltp":0.0,"tv":0.0,"id":35736916}]}]}
{"op":"mcm","clk":"11929048148","pt":1724257911081,"mc":[{"id":"1.232012908","rc":[{"batl":[[0,5.9,10.93]],"ltp":0.0,"tv":0.0,"id":35736916},{"batl":[[0,5.9,10.92]],"ltp":0.0,"tv":0.0,"id":23387705}]}]}
{"op":"mcm","clk":"11929069049","pt":1724258048936,"mc":[{"id":"1.232012908","rc":[{"batb":[[0,1.28,30.58],[1,1.27,5.83],[2,1.2,1105]],"ltp":0.0,"tv":0.0,"id":35736916},{"batb":[[0,1.28,30.58],[1,1.27,6.53],[2,1.2,1105]],"ltp":0.0,"tv":0.0,"id":23387705}]}]}
{"op":"mcm","clk":"11929356653","pt":1724259850074,"mc":[{"id":"1.232012908","rc":[{"batb":[[0,1.27,5.83],[1,1.2,1105],[2,1.04,1.53]],"ltp":0.0,"tv":0.0,"id":35736916},{"batb":[[0,1.27,6.52],[1,1.2,1105],[2,1.04,1.53]],"ltp":0.0,"tv":0.0,"id":23387705}]}]}
{"op":"mcm","clk":"11929357008","pt":1724259851902,"mc":[{"id":"1.232012908","rc":[{"batl":[[0,5.9,10.93]],"ltp":0.0,"tv":0.0,"id":35736916},{"batl":[[0,5.9,10.92]],"ltp":0.0,"tv":0.0,"id":23387705}]}]}
{"op":"mcm","clk":"11929385520","pt":1724260003203,"mc":[{"id":"1.232012908","rc":[{"batb":[[0,1.28,30.56],[1,1.27,5.83],[2,1.2,1105]],"ltp":0.0,"tv":0.0,"id":35736916},{"batb":[[0,1.28,30.56],[1,1.27,6.52],[2,1.2,1105]],"ltp":0.0,"tv":0.0,"id":23387705}]}]}
{"op":"mcm","clk":"11929693752","pt":1724261804283,"mc":[{"id":"1.232012908","rc":[{"batb":[[0,1.27,5.83],[1,1.2,1105],[2,1.04,1.53]],"ltp":0.0,"tv":0.0,"id":35736916}]}]}
{"op":"mcm","clk":"11929693790","pt":1724261804440,"mc":[{"id":"1.232012908","rc":[{"batb":[[0,1.27,6.52],[1,1.2,1105],[2,1.04,1.53]],"ltp":0.0,"tv":0.0,"id":23387705}]}]}
{"op":"mcm","clk":"11929694806","pt":1724261810879,"mc":[{"id":"1.232012908","rc":[{"batl":[[0,5.9,10.93]],"ltp":0.0,"tv":0.0,"id":35736916},{"batl":[[0,5.9,10.92]],"ltp":0.0,"tv":0.0,"id":23387705}]}]}
{"op":"mcm","clk":"11929713591","pt":1724261923168,"mc":[{"id":"1.232012908","rc":[{"batb":[[0,1.28,30.56],[1,1.27,5.83],[2,1.2,1105]],"ltp":0.0,"tv":0.0,"id":35736916},{"batb":[[0,1.28,30.56],[1,1.27,6.52],[2,1.2,1105]],"ltp":0.0,"tv":0.0,"id":23387705}]}]}
{"op":"mcm","clk":"11929985562","pt":1724263723297,"mc":[{"id":"1.232012908","rc":[{"batb":[[0,1.28,30.57],[1,1.27,5.83]],"ltp":0.0,"tv":0.0,"id":35736916},{"batb":[[0,1.27,6.52],[1,1.2,1105],[2,1.04,1.53]],"ltp":0.0,"tv":0.0,"id":23387705}]}]}
{"op":"mcm","clk":"11929985809","pt":1724263724620,"mc":[{"id":"1.232012908","rc":[{"batb":[[0,1.27,5.83],[1,1.2,1105],[2,1.04,1.53]],"ltp":0.0,"tv":0.0,"id":35736916}]}]}
{"op":"mcm","clk":"11929988026","pt":1724263736518,"mc":[{"id":"1.232012908","rc":[{"batl":[[0,5.9,10.94]],"ltp":0.0,"tv":0.0,"id":35736916},{"batl":[[0,5.9,10.93]],"ltp":0.0,"tv":0.0,"id":23387705}]}]}
{"op":"mcm","clk":"11929996212","pt":1724263782805,"mc":[{"id":"1.232012908","rc":[{"batb":[[0,1.28,30.57],[1,1.27,5.83],[2,1.2,1105]],"ltp":0.0,"tv":0.0,"id":35736916},{"batb":[[0,1.28,30.57],[1,1.27,6.52],[2,1.2,1105]],"ltp":0.0,"tv":0.0,"id":23387705}]}]}
{"op":"mcm","clk":"11930307785","pt":1724265583271,"mc":[{"id":"1.232012908","rc":[{"batb":[[0,1.27,5.83],[1,1.2,1105],[2,1.04,1.53]],"ltp":0.0,"tv":0.0,"id":35736916}]}]}
{"op":"mcm","clk":"11930307845","pt":1724265583543,"mc":[{"id":"1.232012908","rc":[{"batb":[[0,1.27,6.52],[1,1.2,1105],[2,1.04,1.53]],"ltp":0.0,"tv":0.0,"id":23387705}]}]}
{"op":"mcm","clk":"11930308615","pt":1724265587572,"mc":[{"id":"1.232012908","rc":[{"batl":[[0,5.9,10.94]],"ltp":0.0,"tv":0.0,"id":35736916},{"batl":[[0,5.9,10.93]],"ltp":0.0,"tv":0.0,"id":23387705}]}]}
{"op":"mcm","clk":"11930312956","pt":1724265611910,"mc":[{"id":"1.232012908","rc":[{"batb":[[0,1.28,30.57],[1,1.27,5.83],[2,1.2,1105]],"ltp":0.0,"tv":0.0,"id":35736916},{"batb":[[0,1.28,30.57],[1,1.27,6.52],[2,1.2,1105]],"ltp":0.0,"tv":0.0,"id":23387705}]}]}
{"op":"mcm","clk":"11930571561","pt":1724267413270,"mc":[{"id":"1.232012908","rc":[{"batb":[[0,1.27,5.82],[1,1.2,1105],[2,1.04,1.53]],"ltp":0.0,"tv":0.0,"id":35736916},{"batb":[[0,1.27,6.52],[1,1.2,1105],[2,1.04,1.53]],"ltp":0.0,"tv":0.0,"id":23387705}]}]}
{"op":"mcm","clk":"11930573032","pt":1724267425590,"mc":[{"id":"1.232012908","rc":[{"batl":[[0,5.9,10.93]],"ltp":0.0,"tv":0.0,"id":35736916},{"batl":[[0,5.9,10.93]],"ltp":0.0,"tv":0.0,"id":23387705}]}]}
{"op":"mcm","clk":"11930593613","pt":1724267586196,"mc":[{"id":"1.232012908","rc":[{"batb":[[0,1.28,30.56],[1,1.27,5.82],[2,1.2,1105]],"ltp":0.0,"tv":0.0,"id":35736916},{"batb":[[0,1.28,30.56],[1,1.27,6.52],[2,1.2,1105]],"ltp":0.0,"tv":0.0,"id":23387705}]}]}
{"op":"mcm","clk":"11930812114","pt":1724269386660,"mc":[{"id":"1.232012908","rc":[{"batb":[[0,1.27,5.82],[1,1.2,1105],[2,1.04,1.53]],"ltp":0.0,"tv":0.0,"id":35736916},{"batb":[[0,1.27,6.52],[1,1.2,1105],[2,1.04,1.53]],"ltp":0.0,"tv":0.0,"id":23387705}]}]}
{"op":"mcm","clk":"11930813089","pt":1724269395457,"mc":[{"id":"1.232012908","rc":[{"batl":[[0,5.9,10.93]],"ltp":0.0,"tv":0.0,"id":35736916},{"batl":[[0,5.9,10.93]],"ltp":0.0,"tv":0.0,"id":23387705}]}]}
{"op":"mcm","clk":"11930823721","pt":1724269493253,"mc":[{"id":"1.232012908","rc":[{"batb":[[0,1.28,30.56],[1,1.27,5.82],[2,1.2,1105]],"ltp":0.0,"tv":0.0,"id":35736916},{"batb":[[0,1.28,30.56],[1,1.27,6.52],[2,1.2,1105]],"ltp":0.0,"tv":0.0,"id":23387705}]}]}
{"op":"mcm","clk":"11931001527","pt":1724271175054,"mc":[{"id":"1.232012908","rc":[{"batb":[[0,1.28,30.58],[1,1.27,5.83]],"ltp":0.0,"tv":0.0,"id":35736916},{"batb":[[0,1.28,30.58],[1,1.27,6.52]],"ltp":0.0,"tv":0.0,"id":23387705}]}]}
{"op":"mcm","clk":"11931016012","pt":1724271293610,"mc":[{"id":"1.232012908","rc":[{"batb":[[0,1.27,5.83],[1,1.2,1105],[2,1.04,1.53]],"ltp":0.0,"tv":0.0,"id":35736916},{"batb":[[0,1.27,6.52],[1,1.2,1105],[2,1.04,1.53]],"ltp":0.0,"tv":0.0,"id":23387705}]}]}
{"op":"mcm","clk":"11931016548","pt":1724271299410,"mc":[{"id":"1.232012908","rc":[{"batl":[[0,5.9,10.94]],"ltp":0.0,"tv":0.0,"id":35736916},{"batl":[[0,5.9,10.92]],"ltp":0.0,"tv":0.0,"id":23387705}]}]}
{"op":"mcm","clk":"11931028218","pt":1724271426043,"mc":[{"id":"1.232012908","rc":[{"batb":[[0,1.28,30.58],[1,1.27,5.83],[2,1.2,1105]],"ltp":0.0,"tv":0.0,"id":35736916},{"batb":[[0,1.28,30.58],[1,1.27,6.52],[2,1.2,1105]],"ltp":0.0,"tv":0.0,"id":23387705}]}]}
{"op":"mcm","clk":"11931188789","pt":1724273228047,"mc":[{"id":"1.232012908","rc":[{"batb":[[0,1.27,5.83],[1,1.2,1105],[2,1.04,1.53]],"ltp":0.0,"tv":0.0,"id":35736916},{"batb":[[0,1.27,6.52],[1,1.2,1105],[2,1.04,1.53]],"ltp":0.0,"tv":0.0,"id":23387705}]}]}
{"op":"mcm","clk":"11931189224","pt":1724273232850,"mc":[{"id":"1.232012908","rc":[{"batl":[[0,5.9,10.94]],"ltp":0.0,"tv":0.0,"id":35736916},{"batl":[[0,5.9,10.92]],"ltp":0.0,"tv":0.0,"id":23387705}]}]}
{"op":"mcm","clk":"11931194069","pt":1724273288513,"mc":[{"id":"1.232012908","rc":[{"batb":[[0,1.28,30.58],[1,1.27,5.83],[2,1.2,1105]],"ltp":0.0,"tv":0.0,"id":35736916},{"batb":[[0,1.28,30.58],[1,1.27,6.52],[2,1.2,1105]],"ltp":0.0,"tv":0.0,"id":23387705}]}]}
{"op":"mcm","clk":"11931335788","pt":1724275088898,"mc":[{"id":"1.232012908","rc":[{"batb":[[0,1.27,5.83],[1,1.2,1105],[2,1.04,1.53]],"ltp":0.0,"tv":0.0,"id":35736916},{"batb":[[0,1.27,6.52],[1,1.2,1105],[2,1.04,1.53]],"ltp":0.0,"tv":0.0,"id":23387705}]}]}
{"op":"mcm","clk":"11931335897","pt":1724275090226,"mc":[{"id":"1.232012908","rc":[{"batl":[[0,5.9,10.94]],"ltp":0.0,"tv":0.0,"id":35736916},{"batl":[[0,5.9,10.93]],"ltp":0.0,"tv":0.0,"id":23387705}]}]}
{"op":"mcm","clk":"11931337635","pt":1724275111639,"mc":[{"id":"1.232012908","rc":[{"batb":[[0,1.28,30.57],[1,1.27,5.83],[2,1.2,1105]],"ltp":0.0,"tv":0.0,"id":35736916},{"batb":[[0,1.28,30.57],[1,1.27,6.52],[2,1.2,1105]],"ltp":0.0,"tv":0.0,"id":23387705}]}]}
{"op":"mcm","clk":"11931480416","pt":1724276912191,"mc":[{"id":"1.232012908","rc":[{"batb":[[0,1.27,5.83],[1,1.2,1105],[2,1.04,1.53]],"ltp":0.0,"tv":0.0,"id":35736916},{"batb":[[0,1.27,6.52],[1,1.2,1105],[2,1.04,1.53]],"ltp":0.0,"tv":0.0,"id":23387705}]}]}
{"op":"mcm","clk":"11931481140","pt":1724276921376,"mc":[{"id":"1.232012908","rc":[{"batl":[[0,5.9,10.94]],"ltp":0.0,"tv":0.0,"id":35736916},{"batl":[[0,5.9,10.93]],"ltp":0.0,"tv":0.0,"id":23387705}]}]}
{"op":"mcm","clk":"11931494224","pt":1724277090071,"mc":[{"id":"1.232012908","rc":[{"batb":[[0,1.28,30.57],[1,1.27,5.83],[2,1.2,1105]],"ltp":0.0,"tv":0.0,"id":35736916},{"batb":[[0,1.28,30.57],[1,1.27,6.52],[2,1.2,1105]],"ltp":0.0,"tv":0.0,"id":23387705}]}]}
{"op":"mcm","clk":"11931612511","pt":1724278891191,"mc":[{"id":"1.232012908","rc":[{"batb":[[0,1.28,30.56]],"ltp":0.0,"tv":0.0,"id":35736916},{"batb":[[0,1.27,6.52],[1,1.2,1105],[2,1.04,1.53]],"ltp":0.0,"tv":0.0,"id":23387705}]}]}
{"op":"mcm","clk":"11931612559","pt":1724278892010,"mc":[{"id":"1.232012908","rc":[{"batb":[[0,1.27,5.83],[1,1.2,1105],[2,1.04,1.53]],"batl":[[0,5.9,10.93]],"ltp":0.0,"tv":0.0,"id":35736916},{"batl":[[0,5.9,10.92]],"ltp":0.0,"tv":0.0,"id":23387705}]}]}
{"op":"mcm","clk":"11931620623","pt":1724279031340,"mc":[{"id":"1.232012908","rc":[{"batb":[[0,1.28,30.56],[1,1.27,5.83],[2,1.2,1105]],"ltp":0.0,"tv":0.0,"id":35736916},{"batb":[[0,1.28,30.56],[1,1.27,6.52],[2,1.2,1105]],"ltp":0.0,"tv":0.0,"id":23387705}]}]}
{"op":"mcm","clk":"11931730575","pt":1724280831683,"mc":[{"id":"1.232012908","rc":[{"batb":[[0,1.27,5.83],[1,1.2,1105],[2,1.04,1.53]],"ltp":0.0,"tv":0.0,"id":35736916},{"batb":[[0,1.27,6.52],[1,1.2,1105],[2,1.04,1.53]],"ltp":0.0,"tv":0.0,"id":23387705}]}]}
{"op":"mcm","clk":"11931730959","pt":1724280838743,"mc":[{"id":"1.232012908","rc":[{"batl":[[0,5.9,10.93]],"ltp":0.0,"tv":0.0,"id":35736916},{"batl":[[0,5.9,10.92]],"ltp":0.0,"tv":0.0,"id":23387705}]}]}
{"op":"mcm","clk":"11931737422","pt":1724280949075,"mc":[{"id":"1.232012908","rc":[{"batb":[[0,1.28,30.56],[1,1.27,5.83],[2,1.2,1105]],"ltp":0.0,"tv":0.0,"id":35736916},{"batb":[[0,1.28,30.56],[1,1.27,6.52],[2,1.2,1105]],"ltp":0.0,"tv":0.0,"id":23387705}]}]}
{"op":"mcm","clk":"11931816094","pt":1724281975072,"mc":[{"id":"1.232012908","rc":[{"batb":[[0,1.28,30.58]],"ltp":0.0,"tv":0.0,"id":35736916},{"batb":[[0,1.28,30.58]],"ltp":0.0,"tv":0.0,"id":23387705}]}]}
{"op":"mcm","clk":"11931884948","pt":1724282750011,"mc":[{"id":"1.232012908","rc":[{"batb":[[0,1.27,5.83],[1,1.2,1105],[2,1.04,1.53]],"ltp":0.0,"tv":0.0,"id":35736916},{"batb":[[0,1.27,6.52],[1,1.2,1105],[2,1.04,1.53]],"ltp":0.0,"tv":0.0,"id":23387705}]}]}
{"op":"mcm","clk":"11931885115","pt":1724282752324,"mc":[{"id":"1.232012908","rc":[{"batl":[[0,5.9,10.93]],"ltp":0.0,"tv":0.0,"id":35736916},{"batl":[[0,5.9,10.92]],"ltp":0.0,"tv":0.0,"id":23387705}]}]}
{"op":"mcm","clk":"11931892219","pt":1724282843920,"mc":[{"id":"1.232012908","rc":[{"batb":[[0,1.28,30.58],[1,1.27,5.83],[2,1.2,1105]],"ltp":0.0,"tv":0.0,"id":35736916},{"batb":[[0,1.28,30.58],[1,1.27,6.52],[2,1.2,1105]],"ltp":0.0,"tv":0.0,"id":23387705}]}]}
{"op":"mcm","clk":"11932044230","pt":1724284644275,"mc":[{"id":"1.232012908","rc":[{"batb":[[0,1.27,6.52],[1,1.2,1105],[2,1.04,1.53]],"ltp":0.0,"tv":0.0,"id":23387705}]}]}
{"op":"mcm","clk":"11932044246","pt":1724284644483,"mc":[{"id":"1.232012908","rc":[{"batb":[[0,1.27,5.83],[1,1.2,1105],[2,1.04,1.53]],"ltp":0.0,"tv":0.0,"id":35736916}]}]}
{"op":"mcm","clk":"11932044969","pt":1724284653953,"mc":[{"id":"1.232012908","rc":[{"batl":[[0,5.9,10.93]],"ltp":0.0,"tv":0.0,"id":35736916},{"batl":[[0,5.9,10.92]],"ltp":0.0,"tv":0.0,"id":23387705}]}]}
{"op":"mcm","clk":"11932049456","pt":1724284721035,"mc":[{"id":"1.232012908","rc":[{"batb":[[0,1.28,30.58],[1,1.27,5.83],[2,1.2,1105]],"ltp":0.0,"tv":0.0,"id":35736916},{"batb":[[0,1.28,30.58],[1,1.27,6.52],[2,1.2,1105]],"ltp":0.0,"tv":0.0,"id":23387705}]}]}
{"op":"mcm","clk":"11932187323","pt":1724286521636,"mc":[{"id":"1.232012908","rc":[{"batb":[[0,1.27,5.83],[1,1.2,1105],[2,1.04,1.53]],"ltp":0.0,"tv":0.0,"id":35736916},{"batb":[[0,1.27,6.52],[1,1.2,1105],[2,1.04,1.53]],"ltp":0.0,"tv":0.0,"id":23387705}]}]}
{"op":"mcm","clk":"11932187812","pt":1724286528627,"mc":[{"id":"1.232012908","rc":[{"batl":[[0,5.9,10.94]],"ltp":0.0,"tv":0.0,"id":35736916},{"batl":[[0,5.9,10.93]],"ltp":0.0,"tv":0.0,"id":23387705}]}]}
{"op":"mcm","clk":"11932191218","pt":1724286573492,"mc":[{"id":"1.232012908","rc":[{"batb":[[0,1.28,30.58],[1,1.27,5.83],[2,1.2,1105]],"ltp":0.0,"tv":0.0,"id":35736916},{"batb":[[0,1.28,30.58],[1,1.27,6.52],[2,1.2,1105]],"ltp":0.0,"tv":0.0,"id":23387705}]}]}
{"op":"mcm","clk":"11932346741","pt":1724288373986,"mc":[{"id":"1.232012908","rc":[{"batb":[[0,1.27,5.83],[1,1.2,1105],[2,1.04,1.53]],"ltp":0.0,"tv":0.0,"id":35736916},{"batb":[[0,1.27,6.52],[1,1.2,1105],[2,1.04,1.53]],"ltp":0.0,"tv":0.0,"id":23387705}]}]}
{"op":"mcm","clk":"11932347431","pt":1724288385509,"mc":[{"id":"1.232012908","rc":[{"batl":[[0,5.9,10.94]],"ltp":0.0,"tv":0.0,"id":35736916},{"batl":[[0,5.9,10.93]],"ltp":0.0,"tv":0.0,"id":23387705}]}]}
{"op":"mcm","clk":"11932349131","pt":1724288407446,"mc":[{"id":"1.232012908","rc":[{"batb":[[0,1.28,30.56],[1,1.27,5.83],[2,1.2,1105]],"batl":[[0,5.9,10.93]],"ltp":0.0,"tv":0.0,"id":35736916},{"batb":[[0,1.28,30.56],[1,1.27,6.52],[2,1.2,1105]],"batl":[[0,5.9,10.93]],"ltp":0.0,"tv":0.0,"id":23387705}]}]}
{"op":"mcm","clk":"11932471129","pt":1724290207933,"mc":[{"id":"1.232012908","rc":[{"batb":[[0,1.27,5.83],[1,1.2,1105],[2,1.04,1.53]],"ltp":0.0,"tv":0.0,"id":35736916},{"batb":[[0,1.27,6.52],[1,1.2,1105],[2,1.04,1.53]],"ltp":0.0,"tv":0.0,"id":23387705}]}]}
{"op":"mcm","clk":"11932471730","pt":1724290216776,"mc":[{"id":"1.232012908","rc":[{"batl":[[0,5.9,10.93]],"ltp":0.0,"tv":0.0,"id":35736916},{"batl":[[0,5.9,10.93]],"ltp":0.0,"tv":0.0,"id":23387705}]}]}
{"op":"mcm","clk":"11932472004","pt":1724290221494,"mc":[{"id":"1.232012908","rc":[{"batb":[[0,1.28,30.56],[1,1.27,5.83],[2,1.2,1105]],"ltp":0.0,"tv":0.0,"id":35736916},{"batb":[[0,1.28,30.56],[1,1.27,6.52],[2,1.2,1105]],"ltp":0.0,"tv":0.0,"id":23387705}]}]}
{"op":"mcm","clk":"11932581784","pt":1724292022561,"mc":[{"id":"1.232012908","rc":[{"batb":[[0,1.27,5.83],[1,1.2,1105],[2,1.04,1.53]],"ltp":0.0,"tv":0.0,"id":35736916},{"batb":[[0,1.27,6.53],[1,1.2,1105],[2,1.04,1.53]],"ltp":0.0,"tv":0.0,"id":23387705}]}]}
{"op":"mcm","clk":"11932582005","pt":1724292025900,"mc":[{"id":"1.232012908","rc":[{"batl":[[0,5.9,10.93]],"ltp":0.0,"tv":0.0,"id":35736916},{"batl":[[0,5.9,10.93]],"ltp":0.0,"tv":0.0,"id":23387705}]}]}
{"op":"mcm","clk":"11932591532","pt":1724292181051,"mc":[{"id":"1.232012908","rc":[{"batb":[[0,1.28,30.56],[1,1.27,5.83],[2,1.2,1105]],"ltp":0.0,"tv":0.0,"id":35736916},{"batb":[[0,1.28,30.56],[1,1.27,6.53],[2,1.2,1105]],"ltp":0.0,"tv":0.0,"id":23387705}]}]}
{"op":"mcm","clk":"11932711080","pt":1724293981222,"mc":[{"id":"1.232012908","rc":[{"batb":[[0,1.27,6.53],[1,1.2,1105],[2,1.04,1.53]],"ltp":0.0,"tv":0.0,"id":23387705}]}]}
{"op":"mcm","clk":"11932711127","pt":1724293982350,"mc":[{"id":"1.232012908","rc":[{"batb":[[0,1.27,5.83],[1,1.2,1105],[2,1.04,1.53]],"ltp":0.0,"tv":0.0,"id":35736916}]}]}
{"op":"mcm","clk":"11932711183","pt":1724293983640,"mc":[{"id":"1.232012908","rc":[{"batl":[[0,5.9,10.93]],"ltp":0.0,"tv":0.0,"id":35736916},{"batl":[[0,5.9,10.93]],"ltp":0.0,"tv":0.0,"id":23387705}]}]}
{"op":"mcm","clk":"11932716647","pt":1724294116286,"mc":[{"id":"1.232012908","rc":[{"batb":[[0,1.28,30.56],[1,1.27,5.83],[2,1.2,1105]],"ltp":0.0,"tv":0.0,"id":35736916},{"batb":[[0,1.28,30.56],[1,1.27,6.53],[2,1.2,1105]],"ltp":0.0,"tv":0.0,"id":23387705}]}]}
{"op":"mcm","clk":"11932807643","pt":1724295917172,"mc":[{"id":"1.232012908","rc":[{"batb":[[0,1.27,5.83],[1,1.2,1105],[2,1.04,1.53]],"ltp":0.0,"tv":0.0,"id":35736916},{"batb":[[0,1.27,6.53],[1,1.2,1105],[2,1.04,1.53]],"ltp":0.0,"tv":0.0,"id":23387705}]}]}
{"op":"mcm","clk":"11932808143","pt":1724295928418,"mc":[{"id":"1.232012908","rc":[{"batl":[[0,5.9,10.93]],"ltp":0.0,"tv":0.0,"id":35736916},{"batl":[[0,5.9,10.93]],"ltp":0.0,"tv":0.0,"id":23387705}]}]}
{"op":"mcm","clk":"11932812741","pt":1724296027891,"mc":[{"id":"1.232012908","rc":[{"batb":[[0,1.28,30.56],[1,1.27,5.83],[2,1.2,1105]],"ltp":0.0,"tv":0.0,"id":35736916},{"batb":[[0,1.28,30.56],[1,1.27,6.53],[2,1.2,1105]],"ltp":0.0,"tv":0.0,"id":23387705}]}]}
{"op":"mcm","clk":"11932905385","pt":1724297828117,"mc":[{"id":"1.232012908","rc":[{"batb":[[0,1.27,5.83],[1,1.2,1105],[2,1.04,1.53]],"ltp":0.0,"tv":0.0,"id":35736916},{"batb":[[0,1.27,6.53],[1,1.2,1105],[2,1.04,1.53]],"ltp":0.0,"tv":0.0,"id":23387705}]}]}
{"op":"mcm","clk":"11932905797","pt":1724297834023,"mc":[{"id":"1.232012908","rc":[{"batl":[[0,5.9,10.93]],"ltp":0.0,"tv":0.0,"id":35736916},{"batl":[[0,5.9,10.93]],"ltp":0.0,"tv":0.0,"id":23387705}]}]}
{"op":"mcm","clk":"11932911063","pt":1724297927094,"mc":[{"id":"1.232012908","rc":[{"batb":[[0,1.28,30.56],[1,1.27,5.83],[2,1.2,1105]],"ltp":0.0,"tv":0.0,"id":35736916},{"batb":[[0,1.28,30.56],[1,1.27,6.53],[2,1.2,1105]],"ltp":0.0,"tv":0.0,"id":23387705}]}]}
{"op":"mcm","clk":"11933017391","pt":1724299727266,"mc":[{"id":"1.232012908","rc":[{"batb":[[0,1.27,5.83],[1,1.2,1105],[2,1.04,1.53]],"ltp":0.0,"tv":0.0,"id":35736916},{"batb":[[0,1.28,30.56]],"ltp":0.0,"tv":0.0,"id":23387705}]}]}
{"op":"mcm","clk":"11933017404","pt":1724299727424,"mc":[{"id":"1.232012908","rc":[{"batb":[[0,1.27,6.53],[1,1.2,1105],[2,1.04,1.53]],"ltp":0.0,"tv":0.0,"id":23387705}]}]}
{"op":"mcm","clk":"11933018596","pt":1724299748389,"mc":[{"id":"1.232012908","rc":[{"batl":[[0,5.9,10.94]],"ltp":0.0,"tv":0.0,"id":35736916},{"batl":[[0,5.9,10.93]],"ltp":0.0,"tv":0.0,"id":23387705}]}]}
{"op":"mcm","clk":"11933022473","pt":1724299814140,"mc":[{"id":"1.232012908","rc":[{"batb":[[0,1.28,30.56],[1,1.27,5.83],[2,1.2,1105]],"ltp":0.0,"tv":0.0,"id":35736916},{"batb":[[0,1.28,30.56],[1,1.27,6.53],[2,1.2,1105]],"ltp":0.0,"tv":0.0,"id":23387705}]}]}
{"op":"mcm","clk":"11933115309","pt":1724301614703,"mc":[{"id":"1.232012908","rc":[{"batb":[[0,1.27,5.83],[1,1.2,1105],[2,1.04,1.53]],"ltp":0.0,"tv":0.0,"id":35736916},{"batb":[[0,1.27,6.53],[1,1.2,1105],[2,1.04,1.53]],"ltp":0.0,"tv":0.0,"id":23387705}]}]}
{"op":"mcm","clk":"11933116015","pt":1724301629332,"mc":[{"id":"1.232012908","rc":[{"batl":[[0,5.9,10.94]],"ltp":0.0,"tv":0.0,"id":35736916},{"batl":[[0,5.9,10.93]],"ltp":0.0,"tv":0.0,"id":23387705}]}]}
{"op":"mcm","clk":"11933118953","pt":1724301691619,"mc":[{"id":"1.232012908","rc":[{"batb":[[0,1.28,30.56],[1,1.27,5.83],[2,1.2,1105]],"ltp":0.0,"tv":0.0,"id":35736916},{"batb":[[0,1.28,30.56],[1,1.27,6.53],[2,1.2,1105]],"ltp":0.0,"tv":0.0,"id":23387705}]}]}
{"op":"mcm","clk":"11933222542","pt":1724303491973,"mc":[{"id":"1.232012908","rc":[{"batb":[[0,1.27,5.83],[1,1.2,1105],[2,1.04,1.53]],"ltp":0.0,"tv":0.0,"id":35736916},{"batb":[[0,1.27,6.53],[1,1.2,1105],[2,1.04,1.53]],"ltp":0.0,"tv":0.0,"id":23387705}]}]}
{"op":"mcm","clk":"11933222721","pt":1724303496575,"mc":[{"id":"1.232012908","rc":[{"batl":[[0,5.9,10.94]],"ltp":0.0,"tv":0.0,"id":35736916},{"batl":[[0,5.9,10.93]],"ltp":0.0,"tv":0.0,"id":23387705}]}]}
{"op":"mcm","clk":"11933225941","pt":1724303568561,"mc":[{"id":"1.232012908","rc":[{"batb":[[0,1.28,30.57],[1,1.27,5.83],[2,1.2,1105]],"ltp":0.0,"tv":0.0,"id":35736916},{"batb":[[0,1.28,30.57],[1,1.27,6.53],[2,1.2,1105]],"ltp":0.0,"tv":0.0,"id":23387705}]}]}
{"op":"mcm","clk":"11933325939","pt":1724305368990,"mc":[{"id":"1.232012908","rc":[{"batb":[[0,1.27,5.83],[1,1.2,1105],[2,1.04,1.53]],"ltp":0.0,"tv":0.0,"id":35736916},{"batb":[[0,1.27,6.53],[1,1.2,1105],[2,1.04,1.53]],"ltp":0.0,"tv":0.0,"id":23387705}]}]}
{"op":"mcm","clk":"11933326162","pt":1724305374363,"mc":[{"id":"1.232012908","rc":[{"batl":[[0,5.9,10.94]],"ltp":0.0,"tv":0.0,"id":35736916},{"batl":[[0,5.9,10.93]],"ltp":0.0,"tv":0.0,"id":23387705}]}]}
{"op":"mcm","clk":"11933330213","pt":1724305473689,"mc":[{"id":"1.232012908","rc":[{"batb":[[0,1.28,30.57],[1,1.27,5.83],[2,1.2,1105]],"ltp":0.0,"tv":0.0,"id":35736916},{"batb":[[0,1.28,30.57],[1,1.27,6.53],[2,1.2,1105]],"ltp":0.0,"tv":0.0,"id":23387705}]}]}
{"op":"mcm","clk":"11933411404","pt":1724307274159,"mc":[{"id":"1.232012908","rc":[{"batb":[[0,1.27,5.83],[1,1.2,1105],[2,1.04,1.53]],"ltp":0.0,"tv":0.0,"id":35736916},{"batb":[[0,1.27,6.53],[1,1.2,1105],[2,1.04,1.53]],"ltp":0.0,"tv":0.0,"id":23387705}]}]}
{"op":"mcm","clk":"11933411612","pt":1724307280549,"mc":[{"id":"1.232012908","rc":[{"batl":[[0,5.9,10.94]],"ltp":0.0,"tv":0.0,"id":35736916},{"batl":[[0,5.9,10.93]],"ltp":0.0,"tv":0.0,"id":23387705}]}]}
{"op":"mcm","clk":"11933416472","pt":1724307403419,"mc":[{"id":"1.232012908","rc":[{"batb":[[0,1.28,30.57],[1,1.27,5.83],[2,1.2,1105]],"ltp":0.0,"tv":0.0,"id":35736916},{"batb":[[0,1.28,30.57],[1,1.27,6.53],[2,1.2,1105]],"ltp":0.0,"tv":0.0,"id":23387705}]}]}
{"op":"mcm","clk":"11933500878","pt":1724309204224,"mc":[{"id":"1.232012908","rc":[{"batb":[[0,1.27,5.83],[1,1.2,1105],[2,1.04,1.53]],"ltp":0.0,"tv":0.0,"id":35736916},{"batb":[[0,1.27,6.53],[1,1.2,1105],[2,1.04,1.53]],"ltp":0.0,"tv":0.0,"id":23387705}]}]}
{"op":"mcm","clk":"11933501485","pt":1724309218503,"mc":[{"id":"1.232012908","rc":[{"batl":[[0,5.9,10.94]],"ltp":0.0,"tv":0.0,"id":35736916},{"batl":[[0,5.9,10.93]],"ltp":0.0,"tv":0.0,"id":23387705}]}]}
{"op":"mcm","clk":"11933505581","pt":1724309329991,"mc":[{"id":"1.232012908","rc":[{"batb":[[0,1.28,30.57],[1,1.27,5.83],[2,1.2,1105]],"ltp":0.0,"tv":0.0,"id":35736916},{"batb":[[0,1.28,30.57],[1,1.27,6.53],[2,1.2,1105]],"ltp":0.0,"tv":0.0,"id":23387705}]}]}
{"op":"mcm","clk":"11933565330","pt":1724311131234,"mc":[{"id":"1.232012908","rc":[{"batb":[[0,1.27,5.83],[1,1.2,1105],[2,1.04,1.53]],"ltp":0.0,"tv":0.0,"id":35736916},{"batb":[[0,1.27,6.52],[1,1.2,1105],[2,1.04,1.53]],"ltp":0.0,"tv":0.0,"id":23387705}]}]}
{"op":"mcm","clk":"11933565429","pt":1724311132714,"mc":[{"id":"1.232012908","rc":[{"batl":[[0,5.9,10.93]],"ltp":0.0,"tv":0.0,"id":23387705}]}]}
{"op":"mcm","clk":"11933570127","pt":1724311254936,"mc":[{"id":"1.232012908","rc":[{"batb":[[0,1.28,30.57],[1,1.27,5.83],[2,1.2,1105]],"ltp":0.0,"tv":0.0,"id":35736916},{"batb":[[0,1.28,30.57],[1,1.27,6.52],[2,1.2,1105]],"ltp":0.0,"tv":0.0,"id":23387705}]}]}
{"op":"mcm","clk":"11933629350","pt":1724313055253,"mc":[{"id":"1.232012908","rc":[{"batb":[[0,1.27,6.52],[1,1.2,1105],[2,1.04,1.53]],"ltp":0.0,"tv":0.0,"id":23387705}]}]}
{"op":"mcm","clk":"11933629357","pt":1724313055453,"mc":[{"id":"1.232012908","rc":[{"batb":[[0,1.27,5.83],[1,1.2,1105],[2,1.04,1.53]],"ltp":0.0,"tv":0.0,"id":35736916}]}]}
{"op":"mcm","clk":"11933629459","pt":1724313058548,"mc":[{"id":"1.232012908","rc":[{"batl":[[0,5.9,10.93]],"ltp":0.0,"tv":0.0,"id":35736916},{"batl":[[0,5.9,10.93]],"ltp":0.0,"tv":0.0,"id":23387705}]}]}
{"op":"mcm","clk":"11933633734","pt":1724313180777,"mc":[{"id":"1.232012908","rc":[{"batb":[[0,1.28,30.57],[1,1.27,5.83],[2,1.2,1105]],"ltp":0.0,"tv":0.0,"id":35736916},{"batb":[[0,1.28,30.57],[1,1.27,6.52],[2,1.2,1105]],"ltp":0.0,"tv":0.0,"id":23387705}]}]}
{"op":"mcm","clk":"11933650843","pt":1724313622727,"mc":[{"id":"1.232012908","rc":[{"batb":[[0,1.28,30.52],[1,1.27,5.83]],"batl":[[0,5.9,10.94]],"ltp":0.0,"tv":0.0,"id":35736916},{"batb":[[0,1.28,30.52],[1,1.27,6.52]],"batl":[[0,5.9,10.93]],"ltp":0.0,"tv":0.0,"id":23387705}]}]}
{"op":"mcm","clk":"11933709518","pt":1724314982042,"mc":[{"id":"1.232012908","rc":[{"batb":[[0,1.27,5.83],[1,1.2,1105],[2,1.04,1.53]],"ltp":0.0,"tv":0.0,"id":35736916},{"batb":[[0,1.27,6.52],[1,1.2,1105],[2,1.04,1.53]],"ltp":0.0,"tv":0.0,"id":23387705}]}]}
{"op":"mcm","clk":"11933709932","pt":1724314992838,"mc":[{"id":"1.232012908","rc":[{"batl":[[0,5.9,10.94]],"ltp":0.0,"tv":0.0,"id":35736916},{"batl":[[0,5.9,10.93]],"ltp":0.0,"tv":0.0,"id":23387705}]}]}
{"op":"mcm","clk":"11933714007","pt":1724315109306,"mc":[{"id":"1.232012908","rc":[{"batb":[[0,1.28,30.52],[1,1.27,5.83],[2,1.2,1105]],"ltp":0.0,"tv":0.0,"id":35736916},{"batb":[[0,1.28,30.52],[1,1.27,6.52],[2,1.2,1105]],"ltp":0.0,"tv":0.0,"id":23387705}]}]}
{"op":"mcm","clk":"11933781837","pt":1724316909794,"mc":[{"id":"1.232012908","rc":[{"batb":[[0,1.27,5.83],[1,1.2,1105],[2,1.04,1.53]],"ltp":0.0,"tv":0.0,"id":35736916},{"batb":[[0,1.27,6.52],[1,1.2,1105],[2,1.04,1.53]],"ltp":0.0,"tv":0.0,"id":23387705}]}]}
{"op":"mcm","clk":"11933782125","pt":1724316916529,"mc":[{"id":"1.232012908","rc":[{"batl":[[0,5.9,10.94]],"ltp":0.0,"tv":0.0,"id":35736916},{"batl":[[0,5.9,10.93]],"ltp":0.0,"tv":0.0,"id":23387705}]}]}
{"op":"mcm","clk":"11933786599","pt":1724317035827,"mc":[{"id":"1.232012908","rc":[{"batb":[[0,1.28,30.52],[1,1.27,5.83],[2,1.2,1105]],"ltp":0.0,"tv":0.0,"id":35736916},{"batb":[[0,1.28,30.52],[1,1.27,6.52],[2,1.2,1105]],"ltp":0.0,"tv":0.0,"id":23387705}]}]}
{"op":"mcm","clk":"11933858914","pt":1724318836817,"mc":[{"id":"1.232012908","rc":[{"batb":[[0,1.27,5.82],[1,1.2,1105],[2,1.04,1.53]],"ltp":0.0,"tv":0.0,"id":35736916},{"batb":[[0,1.27,6.51],[1,1.2,1105],[2,1.04,1.53]],"ltp":0.0,"tv":0.0,"id":23387705}]}]}
{"op":"mcm","clk":"11933859036","pt":1724318839325,"mc":[{"id":"1.232012908","rc":[{"batl":[[0,5.9,10.93]],"ltp":0.0,"tv":0.0,"id":35736916},{"batl":[[0,5.9,10.93]],"ltp":0.0,"tv":0.0,"id":23387705}]}]}
{"op":"mcm","clk":"11933860209","pt":1724318866139,"mc":[{"id":"1.232012908","rc":[{"batb":[[0,1.28,30.5],[1,1.27,5.82],[2,1.2,1105]],"ltp":0.0,"tv":0.0,"id":35736916},{"batb":[[0,1.28,30.5],[1,1.27,6.51],[2,1.2,1105]],"ltp":0.0,"tv":0.0,"id":23387705}]}]}
{"op":"mcm","clk":"11933950063","pt":1724320666391,"mc":[{"id":"1.232012908","rc":[{"batb":[[0,1.27,6.51],[1,1.2,1105],[2,1.04,1.53]],"ltp":0.0,"tv":0.0,"id":23387705}]}]}
{"op":"mcm","clk":"11933950068","pt":1724320666600,"mc":[{"id":"1.232012908","rc":[{"batb":[[0,1.27,5.82],[1,1.2,1105],[2,1.04,1.53]],"ltp":0.0,"tv":0.0,"id":35736916}]}]}
{"op":"mcm","clk":"11933950692","pt":1724320682603,"mc":[{"id":"1.232012908","rc":[{"batl":[[0,5.9,10.93]],"ltp":0.0,"tv":0.0,"id":35736916},{"batl":[[0,5.9,10.93]],"ltp":0.0,"tv":0.0,"id":23387705}]}]}
{"op":"mcm","clk":"11933951802","pt":1724320706243,"mc":[{"id":"1.232012908","rc":[{"batb":[[0,1.28,30.5],[1,1.27,5.82],[2,1.2,1105]],"ltp":0.0,"tv":0.0,"id":35736916},{"batb":[[0,1.28,30.5],[1,1.27,6.51],[2,1.2,1105]],"ltp":0.0,"tv":0.0,"id":23387705}]}]}
{"op":"mcm","clk":"11934034897","pt":1724322506743,"mc":[{"id":"1.232012908","rc":[{"batb":[[0,1.27,5.81],[1,1.2,1105],[2,1.04,1.53]],"ltp":0.0,"tv":0.0,"id":35736916},{"batb":[[0,1.27,6.51],[1,1.2,1105],[2,1.04,1.53]],"ltp":0.0,"tv":0.0,"id":23387705}]}]}
{"op":"mcm","clk":"11934035377","pt":1724322518020,"mc":[{"id":"1.232012908","rc":[{"batl":[[0,5.9,10.93]],"ltp":0.0,"tv":0.0,"id":35736916},{"batl":[[0,5.9,10.92]],"ltp":0.0,"tv":0.0,"id":23387705}]}]}
{"op":"mcm","clk":"11934036306","pt":1724322537658,"mc":[{"id":"1.232012908","rc":[{"batb":[[0,1.28,30.47],[1,1.27,5.81],[2,1.2,1105]],"ltp":0.0,"tv":0.0,"id":35736916},{"batb":[[0,1.28,30.47],[1,1.27,6.51],[2,1.2,1105]],"ltp":0.0,"tv":0.0,"id":23387705}]}]}
{"op":"mcm","clk":"11934122194","pt":1724324338272,"mc":[{"id":"1.232012908","rc":[{"batb":[[0,1.27,5.81],[1,1.2,1105],[2,1.04,1.53]],"ltp":0.0,"tv":0.0,"id":35736916}]}]}
{"op":"mcm","clk":"11934122200","pt":1724324338477,"mc":[{"id":"1.232012908","rc":[{"batb":[[0,1.27,6.51],[1,1.2,1105],[2,1.04,1.53]],"ltp":0.0,"tv":0.0,"id":23387705}]}]}
{"op":"mcm","clk":"11934122896","pt":1724324352481,"mc":[{"id":"1.232012908","rc":[{"batl":[[0,5.9,10.93]],"ltp":0.0,"tv":0.0,"id":35736916},{"batl":[[0,5.9,10.92]],"ltp":0.0,"tv":0.0,"id":23387705}]}]}
{"op":"mcm","clk":"11934123283","pt":1724324360207,"mc":[{"id":"1.232012908","rc":[{"batb":[[0,1.28,30.47],[1,1.27,5.81],[2,1.2,1105]],"ltp":0.0,"tv":0.0,"id":35736916},{"batb":[[0,1.28,30.47],[1,1.27,6.51],[2,1.2,1105]],"ltp":0.0,"tv":0.0,"id":23387705}]}]}
{"op":"mcm","clk":"11934172494","pt":1724325175000,"mc":[{"id":"1.232012908","rc":[{"batb":[[0,1.28,30.49],[1,1.27,5.82]],"ltp":0.0,"tv":0.0,"id":35736916},{"batb":[[0,1.28,30.49],[1,1.27,6.51]],"ltp":0.0,"tv":0.0,"id":23387705}]}]}
{"op":"mcm","clk":"11934229497","pt":1724326161243,"mc":[{"id":"1.232012908","rc":[{"batb":[[0,1.27,6.51],[1,1.2,1105],[2,1.04,1.53]],"ltp":0.0,"tv":0.0,"id":23387705}]}]}
{"op":"mcm","clk":"11934229509","pt":1724326161513,"mc":[{"id":"1.232012908","rc":[{"batb":[[0,1.27,5.82],[1,1.2,1105],[2,1.04,1.53]],"ltp":0.0,"tv":0.0,"id":35736916}]}]}
{"op":"mcm","clk":"11934230032","pt":1724326175152,"mc":[{"id":"1.232012908","rc":[{"batl":[[0,5.9,10.93]],"ltp":0.0,"tv":0.0,"id":35736916},{"batl":[[0,5.9,10.93]],"ltp":0.0,"tv":0.0,"id":23387705}]}]}
{"op":"mcm","clk":"11934230062","pt":1724326175952,"mc":[{"id":"1.232012908","rc":[{"batb":[[0,1.28,30.49],[1,1.27,5.82],[2,1.2,1105]],"ltp":0.0,"tv":0.0,"id":35736916},{"batb":[[0,1.28,30.49],[1,1.27,6.51],[2,1.2,1105]],"ltp":0.0,"tv":0.0,"id":23387705}]}]}
{"op":"mcm","clk":"11934325146","pt":1724327976375,"mc":[{"id":"1.232012908","rc":[{"batb":[[0,1.27,5.82],[1,1.2,1105],[2,1.04,1.53]],"ltp":0.0,"tv":0.0,"id":35736916},{"batb":[[0,1.27,6.51],[1,1.2,1105],[2,1.04,1.53]],"ltp":0.0,"tv":0.0,"id":23387705}]}]}
{"op":"mcm","clk":"11934325529","pt":1724327983180,"mc":[{"id":"1.232012908","rc":[{"batb":[[0,1.28,30.49],[1,1.27,5.82],[2,1.2,1105]],"ltp":0.0,"tv":0.0,"id":35736916},{"batb":[[0,1.28,30.49],[1,1.27,6.51],[2,1.2,1105]],"ltp":0.0,"tv":0.0,"id":23387705}]}]}
{"op":"mcm","clk":"11934420026","pt":1724329783635,"mc":[{"id":"1.232012908","rc":[{"batb":[[0,1.27,5.82],[1,1.2,1105],[2,1.04,1.53]],"ltp":0.0,"tv":0.0,"id":35736916},{"batb":[[0,1.27,6.51],[1,1.2,1105],[2,1.04,1.53]],"ltp":0.0,"tv":0.0,"id":23387705}]}]}
{"op":"mcm","clk":"11934420100","pt":1724329785333,"mc":[{"id":"1.232012908","rc":[{"batb":[[0,1.28,30.49],[1,1.27,5.82],[2,1.2,1105]],"ltp":0.0,"tv":0.0,"id":35736916},{"batb":[[0,1.28,30.49],[1,1.27,6.51],[2,1.2,1105]],"ltp":0.0,"tv":0.0,"id":23387705}]}]}
{"op":"mcm","clk":"11934516073","pt":1724331585833,"mc":[{"id":"1.232012908","rc":[{"batb":[[0,1.27,5.82],[1,1.2,1105],[2,1.04,1.53]],"ltp":0.0,"tv":0.0,"id":35736916},{"batb":[[0,1.27,6.51],[1,1.2,1105],[2,1.04,1.53]],"ltp":0.0,"tv":0.0,"id":23387705}]}]}
{"op":"mcm","clk":"11934516469","pt":1724331594417,"mc":[{"id":"1.232012908","rc":[{"batl":[[0,5.9,10.94]],"ltp":0.0,"tv":0.0,"id":35736916},{"batl":[[0,5.9,10.93]],"ltp":0.0,"tv":0.0,"id":23387705}]}]}
{"op":"mcm","clk":"11934527510","pt":1724331775843,"mc":[{"id":"1.232012908","rc":[{"batb":[[0,1.28,30.48],[1,1.27,5.82],[2,1.2,1105]],"batl":[[0,5.9,10.94]],"ltp":0.0,"tv":0.0,"id":35736916},{"batb":[[0,1.28,30.48],[1,1.27,6.51],[2,1.2,1105]],"batl":[[0,5.9,10.93]],"ltp":0.0,"tv":0.0,"id":23387705}]}]}
{"op":"mcm","clk":"11934636638","pt":1724333576208,"mc":[{"id":"1.232012908","rc":[{"batb":[[0,1.27,6.51],[1,1.2,1105],[2,1.04,1.53]],"ltp":0.0,"tv":0.0,"id":23387705}]}]}
{"op":"mcm","clk":"11934636656","pt":1724333576517,"mc":[{"id":"1.232012908","rc":[{"batb":[[0,1.27,5.82],[1,1.2,1105],[2,1.04,1.53]],"ltp":0.0,"tv":0.0,"id":35736916}]}]}
{"op":"mcm","clk":"11934637045","pt":1724333581705,"mc":[{"id":"1.232012908","rc":[{"batl":[[0,5.9,10.94]],"ltp":0.0,"tv":0.0,"id":35736916},{"batl":[[0,5.9,10.93]],"ltp":0.0,"tv":0.0,"id":23387705}]}]}
{"op":"mcm","clk":"11934650080","pt":1724333750260,"mc":[{"id":"1.232012908","rc":[{"batb":[[0,1.28,30.48],[1,1.27,5.82],[2,1.2,1105]],"ltp":0.0,"tv":0.0,"id":35736916},{"batb":[[0,1.28,30.48],[1,1.27,6.51],[2,1.2,1105]],"ltp":0.0,"tv":0.0,"id":23387705}]}]}
{"op":"mcm","clk":"11934771560","pt":1724335433652,"mc":[{"id":"1.232012908","rc":[{"batb":[[0,1.28,30.46],[1,1.27,5.82],[2,1.04,1.53]],"ltp":0.0,"tv":0.0,"id":35736916},{"batb":[[0,1.28,30.46],[1,1.27,6.52],[2,1.04,1.53]],"ltp":0.0,"tv":0.0,"id":23387705}]}]}
{"op":"mcm","clk":"11934771691","pt":1724335435567,"mc":[{"id":"1.232012908","rc":[{"batb":[[0,1.28,744.75]],"ltp":0.0,"tv":0.0,"id":35736916}]}]}
{"op":"mcm","clk":"11934771835","pt":1724335437383,"mc":[{"id":"1.232012908","rc":[{"batb":[[0,1.28,744.75]],"ltp":0.0,"tv":0.0,"id":23387705}]}]}
{"op":"mcm","clk":"11934780404","pt":1724335550780,"mc":[{"id":"1.232012908","rc":[{"batb":[[0,1.28,714.29]],"ltp":0.0,"tv":0.0,"id":35736916},{"batb":[[0,1.28,714.29]],"ltp":0.0,"tv":0.0,"id":23387705}]}]}
{"op":"mcm","clk":"11934792685","pt":1724335706447,"mc":[{"id":"1.232012908","rc":[{"batb":[[0,1.29,29.41],[1,1.28,714.29],[2,1.27,5.82]],"ltp":0.0,"tv":0.0,"id":35736916},{"batb":[[0,1.29,29.41],[1,1.28,714.29],[2,1.27,6.52]],"ltp":0.0,"tv":0.0,"id":23387705}]}]}
{"op":"mcm","clk":"11934886263","pt":1724336766329,"mc":[{"id":"1.232012908","rc":[{"batb":[[2,1.04,1.53]],"ltp":0.0,"tv":0.0,"id":23387705}]}]}
{"op":"mcm","clk":"11934886312","pt":1724336766903,"mc":[{"id":"1.232012908","rc":[{"batb":[[0,1.3,5.82],[1,1.29,29.41],[2,1.28,714.29]],"ltp":0.0,"tv":0.0,"id":35736916},{"batb":[[0,1.3,6.52],[1,1.29,29.41],[2,1.28,714.29]],"ltp":0.0,"tv":0.0,"id":23387705}]}]}
{"op":"mcm","clk":"11934944719","pt":1724337506754,"mc":[{"id":"1.232012908","rc":[{"batb":[[1,1.28,714.29],[2,1.04,1.53]],"ltp":0.0,"tv":0.0,"id":35736916},{"batb":[[1,1.28,714.29],[2,1.04,1.53]],"ltp":0.0,"tv":0.0,"id":23387705}]}]}
{"op":"mcm","clk":"11934956458","pt":1724337645256,"mc":[{"id":"1.232012908","rc":[{"batb":[[0,1.31,27.51],[1,1.3,5.82],[2,1.28,714.29]],"ltp":0.0,"tv":0.0,"id":35736916},{"batb":[[0,1.31,27.51],[1,1.3,6.52],[2,1.28,714.29]],"ltp":0.0,"tv":0.0,"id":23387705}]}]}
{"op":"mcm","clk":"11935106187","pt":1724339414323,"mc":[{"id":"1.232012908","rc":[{"batb":[[0,1.31,27.5],[1,1.3,5.82]],"ltp":0.0,"tv":0.0,"id":35736916},{"batb":[[0,1.32,6.52],[1,1.31,27.5]],"ltp":0.0,"tv":0.0,"id":23387705}]}]}
{"op":"mcm","clk":"11935106236","pt":1724339414741,"mc":[{"id":"1.232012908","rc":[{"batb":[[0,1.32,5.82],[1,1.31,27.5]],"ltp":0.0,"tv":0.0,"id":35736916}]}]}
{"op":"mcm","clk":"11935109181","pt":1724339445660,"mc":[{"id":"1.232012908","rc":[{"batb":[[1,1.28,714.29],[2,1.04,1.53]],"ltp":0.0,"tv":0.0,"id":35736916},{"batb":[[1,1.28,714.29],[2,1.04,1.53]],"ltp":0.0,"tv":0.0,"id":23387705}]}]}
{"op":"mcm","clk":"11935122730","pt":1724339574714,"mc":[{"id":"1.232012908","rc":[{"batb":[[0,1.33,25.83],[1,1.32,5.82],[2,1.28,714.29]],"ltp":0.0,"tv":0.0,"id":35736916},{"batb":[[0,1.33,25.83],[1,1.32,6.52],[2,1.28,714.29]],"ltp":0.0,"tv":0.0,"id":23387705}]}]}
{"op":"mcm","clk":"11935262061","pt":1724340916963,"mc":[{"id":"1.232012908","rc":[{"batb":[[2,1.04,1.53]],"ltp":0.0,"tv":0.0,"id":35736916},{"batb":[[2,1.04,1.53]],"ltp":0.0,"tv":0.0,"id":23387705}]}]}
{"op":"mcm","clk":"11935268538","pt":1724340981526,"mc":[{"id":"1.232012908","rc":[{"batb":[[0,1.33,934.92]],"ltp":0.0,"tv":0.0,"id":23387705}]}]}
{"op":"mcm","clk":"11935268959","pt":1724340986036,"mc":[{"id":"1.232012908","rc":[{"batb":[[0,1.33,934.92]],"ltp":0.0,"tv":0.0,"id":35736916}]}]}
{"op":"mcm","clk":"11935307627","pt":1724341348571,"mc":[{"id":"1.232012908","rc":[{"batb":[[2,1.21,82.79]],"ltp":0.0,"tv":0.0,"id":23387705}]}]}
{"op":"mcm","clk":"11935322261","pt":1724341375265,"mc":[{"id":"1.232012908","rc":[{"batb":[[0,1.33,909.09]],"ltp":0.0,"tv":0.0,"id":35736916},{"batb":[[0,1.33,909.09]],"ltp":0.0,"tv":0.0,"id":23387705}]}]}
{"op":"mcm","clk":"11935324745","pt":1724341399492,"mc":[{"id":"1.232012908","rc":[{"batb":[[2,1.21,82.79]],"ltp":0.0,"tv":0.0,"id":35736916}]}]}
{"op":"mcm","clk":"11935335576","pt":1724341500301,"mc":[{"id":"1.232012908","rc":[{"batb":[[0,1.34,25.08],[1,1.33,909.09],[2,1.32,5.82]],"ltp":0.0,"tv":0.0,"id":35736916},{"batb":[[0,1.34,25.08],[1,1.33,909.09],[2,1.32,6.52]],"ltp":0.0,"tv":0.0,"id":23387705}]}]}
{"op":"mcm","clk":"11935401169","pt":1724342110153,"mc":[{"id":"1.232012908","rc":[{"batb":[[0,1.35,5.82],[1,1.34,25.08],[2,1.33,909.09]],"ltp":0.0,"tv":0.0,"id":35736916},{"batb":[[0,1.35,6.52],[1,1.34,25.08],[2,1.33,909.09]],"ltp":0.0,"tv":0.0,"id":23387705}]}]}
{"op":"mcm","clk":"11935544909","pt":1724343301168,"mc":[{"id":"1.232012908","rc":[{"batb":[[0,1.35,5.83],[1,1.33,909.09],[2,1.21,82.85]],"ltp":0.0,"tv":0.0,"id":35736916},{"batb":[[0,1.35,6.52],[1,1.33,909.09],[2,1.21,82.85]],"ltp":0.0,"tv":0.0,"id":23387705}]}]}
{"op":"mcm","clk":"11935560354","pt":1724343414085,"mc":[{"id":"1.232012908","rc":[{"batb":[[0,1.36,23.7],[1,1.35,5.83],[2,1.33,909.09]],"ltp":0.0,"tv":0.0,"id":35736916},{"batb":[[0,1.36,23.7],[1,1.35,6.52],[2,1.33,909.09]],"ltp":0.0,"tv":0.0,"id":23387705}]}]}
{"op":"mcm","clk":"11935791641","pt":1724345033976,"mc":[{"id":"1.232012908","rc":[{"batb":[[1,1.34,5.83]],"ltp":0.0,"tv":0.0,"id":35736916},{"batb":[[1,1.34,6.52]],"ltp":0.0,"tv":0.0,"id":23387705}]}]}
{"op":"mcm","clk":"11935819343","pt":1724345215058,"mc":[{"id":"1.232012908","rc":[{"batb":[[0,1.34,5.83],[1,1.33,909.09],[2,1.21,82.85]],"ltp":0.0,"tv":0.0,"id":35736916},{"batb":[[0,1.34,6.52],[1,1.33,909.09],[2,1.21,82.85]],"ltp":0.0,"tv":0.0,"id":23387705}]}]}
{"op":"mcm","clk":"11935834875","pt":1724345313259,"mc":[{"id":"1.232012908","rc":[{"batb":[[0,1.35,24.38],[1,1.34,5.83],[2,1.33,909.09]],"ltp":0.0,"tv":0.0,"id":35736916},{"batb":[[0,1.35,24.38],[1,1.34,6.52],[2,1.33,909.09]],"ltp":0.0,"tv":0.0,"id":23387705}]}]}
{"op":"mcm","clk":"11936086504","pt":1724346775085,"mc":[{"id":"1.232012908","rc":[{"batb":[[0,1.35,24.39],[1,1.34,5.83]],"ltp":0.0,"tv":0.0,"id":35736916},{"batb":[[0,1.35,24.39],[1,1.34,6.53]],"ltp":0.0,"tv":0.0,"id":23387705}]}]}
{"op":"mcm","clk":"11936148814","pt":1724347113629,"mc":[{"id":"1.232012908","rc":[{"batb":[[0,1.34,5.83],[1,1.33,909.09],[2,1.21,82.85]],"ltp":0.0,"tv":0.0,"id":35736916},{"batb":[[0,1.34,6.53],[1,1.33,909.09],[2,1.21,82.85]],"ltp":0.0,"tv":0.0,"id":23387705}]}]}
{"op":"mcm","clk":"11936161025","pt":1724347186388,"mc":[{"id":"1.232012908","rc":[{"batb":[[0,1.35,24.39],[1,1.34,5.83],[2,1.33,909.09]],"ltp":0.0,"tv":0.0,"id":35736916},{"batb":[[0,1.35,24.39],[1,1.34,6.53],[2,1.33,909.09]],"ltp":0.0,"tv":0.0,"id":23387705}]}]}
{"op":"mcm","clk":"11936460275","pt":1724348987251,"mc":[{"id":"1.232012908","rc":[{"batb":[[0,1.34,5.83],[1,1.33,909.09],[2,1.21,82.85]],"ltp":0.0,"tv":0.0,"id":35736916},{"batb":[[0,1.34,6.53],[1,1.33,909.09],[2,1.21,82.85]],"ltp":0.0,"tv":0.0,"id":23387705}]}]}
{"op":"mcm","clk":"11936468960","pt":1724349044217,"mc":[{"id":"1.232012908","rc":[{"batb":[[0,1.35,24.39],[1,1.34,5.83],[2,1.33,909.09]],"ltp":0.0,"tv":0.0,"id":35736916},{"batb":[[0,1.35,24.39],[1,1.34,6.53],[2,1.33,909.09]],"ltp":0.0,"tv":0.0,"id":23387705}]}]}
{"op":"mcm","clk":"11936731912","pt":1724350844781,"mc":[{"id":"1.232012908","rc":[{"batb":[[0,1.34,5.83],[1,1.33,909.09],[2,1.21,82.81]],"ltp":0.0,"tv":0.0,"id":35736916},{"batb":[[0,1.34,6.53],[1,1.33,909.09],[2,1.21,82.81]],"ltp":0.0,"tv":0.0,"id":23387705}]}]}
{"op":"mcm","clk":"11936735150","pt":1724350868301,"mc":[{"id":"1.232012908","rc":[{"batb":[[0,1.35,24.38],[1,1.34,5.83],[2,1.33,909.09]],"ltp":0.0,"tv":0.0,"id":35736916},{"batb":[[0,1.35,24.38],[1,1.34,6.53],[2,1.33,909.09]],"ltp":0.0,"tv":0.0,"id":23387705}]}]}
{"op":"mcm","clk":"11937014594","pt":1724352669149,"mc":[{"id":"1.232012908","rc":[{"batb":[[0,1.34,5.83],[1,1.33,909.09],[2,1.21,82.81]],"ltp":0.0,"tv":0.0,"id":35736916},{"batb":[[0,1.34,6.53],[1,1.33,909.09],[2,1.21,82.81]],"ltp":0.0,"tv":0.0,"id":23387705}]}]}
{"op":"mcm","clk":"11937024718","pt":1724352735745,"mc":[{"id":"1.232012908","rc":[{"batb":[[0,1.35,24.38],[1,1.34,5.83],[2,1.33,909.09]],"ltp":0.0,"tv":0.0,"id":35736916},{"batb":[[0,1.35,24.38],[1,1.34,6.53],[2,1.33,909.09]],"ltp":0.0,"tv":0.0,"id":23387705}]}]}
{"op":"mcm","clk":"11937226576","pt":1724354536250,"mc":[{"id":"1.232012908","rc":[{"batb":[[0,1.35,24.37],[1,1.34,5.83]],"ltp":0.0,"tv":0.0,"id":35736916},{"batb":[[0,1.34,6.52],[1,1.33,909.09],[2,1.21,82.8]],"ltp":0.0,"tv":0.0,"id":23387705}]}]}
{"op":"mcm","clk":"11937226600","pt":1724354536460,"mc":[{"id":"1.232012908","rc":[{"batb":[[0,1.34,5.83],[1,1.33,909.09],[2,1.21,82.8]],"ltp":0.0,"tv":0.0,"id":35736916}]}]}
{"op":"mcm","clk":"11937230642","pt":1724354577486,"mc":[{"id":"1.232012908","rc":[{"batb":[[0,1.35,24.37],[1,1.34,5.83],[2,1.33,909.09]],"ltp":0.0,"tv":0.0,"id":35736916},{"batb":[[0,1.35,24.37],[1,1.34,6.52],[2,1.33,909.09]],"ltp":0.0,"tv":0.0,"id":23387705}]}]}
{"op":"mcm","clk":"11937400470","pt":1724356378054,"mc":[{"id":"1.232012908","rc":[{"batb":[[0,1.34,5.83],[1,1.33,909.09],[2,1.21,82.8]],"ltp":0.0,"tv":0.0,"id":35736916},{"batb":[[0,1.34,6.52],[1,1.33,909.09],[2,1.21,82.8]],"ltp":0.0,"tv":0.0,"id":23387705}]}]}
{"op":"mcm","clk":"11937402839","pt":1724356404613,"mc":[{"id":"1.232012908","rc":[{"batb":[[0,1.35,24.37],[1,1.34,5.83],[2,1.33,909.09]],"ltp":0.0,"tv":0.0,"id":35736916},{"batb":[[0,1.35,24.37],[1,1.34,6.52],[2,1.33,909.09]],"ltp":0.0,"tv":0.0,"id":23387705}]}]}
{"op":"mcm","clk":"11937510679","pt":1724357575114,"mc":[{"id":"1.232012908","rc":[{"batb":[[0,1.35,24.38],[1,1.34,5.83]],"ltp":0.0,"tv":0.0,"id":35736916},{"batb":[[0,1.35,24.38],[1,1.34,6.53]],"ltp":0.0,"tv":0.0,"id":23387705}]}]}
{"op":"mcm","clk":"11937559350","pt":1724358205397,"mc":[{"id":"1.232012908","rc":[{"batb":[[0,1.34,5.83],[1,1.33,909.09],[2,1.21,82.83]],"ltp":0.0,"tv":0.0,"id":35736916},{"batb":[[0,1.34,6.53],[1,1.33,909.09],[2,1.21,82.83]],"ltp":0.0,"tv":0.0,"id":23387705}]}]}
{"op":"mcm","clk":"11937562202","pt":1724358248363,"mc":[{"id":"1.232012908","rc":[{"batb":[[0,1.35,24.38],[1,1.34,5.83],[2,1.33,909.09]],"ltp":0.0,"tv":0.0,"id":35736916},{"batb":[[0,1.35,24.38],[1,1.34,6.53],[2,1.33,909.09]],"ltp":0.0,"tv":0.0,"id":23387705}]}]}
{"op":"mcm","clk":"11937677234","pt":1724360048834,"mc":[{"id":"1.232012908","rc":[{"batb":[[0,1.34,5.83],[1,1.33,909.09],[2,1.21,82.83]],"ltp":0.0,"tv":0.0,"id":35736916},{"batb":[[0,1.34,6.53],[1,1.33,909.09],[2,1.21,82.83]],"ltp":0.0,"tv":0.0,"id":23387705}]}]}
{"op":"mcm","clk":"11937679313","pt":1724360087802,"mc":[{"id":"1.232012908","rc":[{"batb":[[0,1.35,24.38],[1,1.34,5.83],[2,1.33,909.09]],"ltp":0.0,"tv":0.0,"id":35736916},{"batb":[[0,1.35,24.38],[1,1.34,6.53],[2,1.33,909.09]],"ltp":0.0,"tv":0.0,"id":23387705}]}]}
{"op":"mcm","clk":"11937774520","pt":1724361888688,"mc":[{"id":"1.232012908","rc":[{"batb":[[0,1.34,5.83],[1,1.33,909.09],[2,1.21,82.83]],"ltp":0.0,"tv":0.0,"id":35736916},{"batb":[[0,1.34,6.52],[1,1.33,909.09],[2,1.21,82.83]],"ltp":0.0,"tv":0.0,"id":23387705}]}]}
{"op":"mcm","clk":"11937775441","pt":1724361903398,"mc":[{"id":"1.232012908","rc":[{"batb":[[0,1.35,24.38],[1,1.34,6.52],[2,1.33,909.09]],"ltp":0.0,"tv":0.0,"id":23387705}]}]}
{"op":"mcm","clk":"11937775448","pt":1724361903500,"mc":[{"id":"1.232012908","rc":[{"batb":[[0,1.35,24.38],[1,1.34,5.83],[2,1.33,909.09]],"ltp":0.0,"tv":0.0,"id":35736916}]}]}
{"op":"mcm","clk":"11937883128","pt":1724363703935,"mc":[{"id":"1.232012908","rc":[{"batb":[[0,1.34,5.83],[1,1.33,909.09],[2,1.21,82.83]],"ltp":0.0,"tv":0.0,"id":35736916},{"batb":[[0,1.34,6.52],[1,1.33,909.09],[2,1.21,82.83]],"ltp":0.0,"tv":0.0,"id":23387705}]}]}
{"op":"mcm","clk":"11937884560","pt":1724363730075,"mc":[{"id":"1.232012908","rc":[{"batb":[[0,1.35,24.38],[1,1.34,5.83],[2,1.33,909.09]],"ltp":0.0,"tv":0.0,"id":35736916},{"batb":[[0,1.35,24.38],[1,1.34,6.52],[2,1.33,909.09]],"ltp":0.0,"tv":0.0,"id":23387705}]}]}
{"op":"mcm","clk":"11937982702","pt":1724365530648,"mc":[{"id":"1.232012908","rc":[{"batb":[[0,1.34,5.83],[1,1.33,909.09],[2,1.21,82.81]],"ltp":0.0,"tv":0.0,"id":35736916},{"batb":[[0,1.34,6.52],[1,1.33,909.09],[2,1.21,82.81]],"ltp":0.0,"tv":0.0,"id":23387705}]}]}
{"op":"mcm","clk":"11937984183","pt":1724365559863,"mc":[{"id":"1.232012908","rc":[{"batb":[[0,1.35,24.38],[1,1.34,5.83],[2,1.33,909.09]],"ltp":0.0,"tv":0.0,"id":35736916},{"batb":[[0,1.35,24.38],[1,1.34,6.52],[2,1.33,909.09]],"ltp":0.0,"tv":0.0,"id":23387705}]}]}
{"op":"mcm","clk":"11938078020","pt":1724367360270,"mc":[{"id":"1.232012908","rc":[{"batb":[[0,1.34,5.83],[1,1.33,909.09],[2,1.21,82.81]],"ltp":0.0,"tv":0.0,"id":35736916}]}]}
{"op":"mcm","clk":"11938078033","pt":1724367360477,"mc":[{"id":"1.232012908","rc":[{"batb":[[0,1.34,6.52],[1,1.33,909.09],[2,1.21,82.81]],"ltp":0.0,"tv":0.0,"id":23387705}]}]}
{"op":"mcm","clk":"11938079147","pt":1724367380053,"mc":[{"id":"1.232012908","rc":[{"batb":[[0,1.35,24.38],[1,1.34,5.83],[2,1.33,909.09]],"ltp":0.0,"tv":0.0,"id":35736916},{"batb":[[0,1.35,24.38],[1,1.34,6.52],[2,1.33,909.09]],"ltp":0.0,"tv":0.0,"id":23387705}]}]}
{"op":"mcm","clk":"11938142670","pt":1724368375064,"mc":[{"id":"1.232012908","rc":[{"batb":[[0,1.35,24.38]],"ltp":0.0,"tv":0.0,"id":35736916},{"batb":[[0,1.35,24.38]],"ltp":0.0,"tv":0.0,"id":23387705}]}]}
{"op":"mcm","clk":"11938192999","pt":1724369180727,"mc":[{"id":"1.232012908","rc":[{"batb":[[0,1.34,5.83],[1,1.33,909.09],[2,1.21,82.85]],"ltp":0.0,"tv":0.0,"id":35736916},{"batb":[[0,1.34,6.52],[1,1.33,909.09],[2,1.21,82.85]],"ltp":0.0,"tv":0.0,"id":23387705}]}]}
{"op":"mcm","clk":"11938193507","pt":1724369190445,"mc":[{"id":"1.232012908","rc":[{"batb":[[0,1.35,24.38],[1,1.34,5.83],[2,1.33,909.09]],"ltp":0.0,"tv":0.0,"id":35736916},{"batb":[[0,1.35,24.38],[1,1.34,6.52],[2,1.33,909.09]],"ltp":0.0,"tv":0.0,"id":23387705}]}]}
{"op":"mcm","clk":"11938297132","pt":1724370991106,"mc":[{"id":"1.232012908","rc":[{"batb":[[0,1.34,5.83],[1,1.33,909.09],[2,1.21,82.85]],"ltp":0.0,"tv":0.0,"id":35736916},{"batb":[[0,1.34,6.52],[1,1.33,909.09],[2,1.21,82.85]],"ltp":0.0,"tv":0.0,"id":23387705}]}]}
{"op":"mcm","clk":"11938297696","pt":1724371000745,"mc":[{"id":"1.232012908","rc":[{"batb":[[0,1.35,24.38],[1,1.34,5.83],[2,1.33,909.09]],"ltp":0.0,"tv":0.0,"id":35736916},{"batb":[[0,1.35,24.38],[1,1.34,6.52],[2,1.33,909.09]],"ltp":0.0,"tv":0.0,"id":23387705}]}]}
{"op":"mcm","clk":"11938431247","pt":1724372801693,"mc":[{"id":"1.232012908","rc":[{"batb":[[0,1.34,5.83],[1,1.33,909.09],[2,1.21,82.85]],"ltp":0.0,"tv":0.0,"id":35736916},{"batb":[[0,1.34,6.52],[1,1.33,909.09],[2,1.21,82.85]],"ltp":0.0,"tv":0.0,"id":23387705}]}]}
{"op":"mcm","clk":"11938452241","pt":1724373055427,"mc":[{"id":"1.232012908","rc":[{"batb":[[0,1.35,24.38],[1,1.34,5.83],[2,1.33,909.09]],"ltp":0.0,"tv":0.0,"id":35736916},{"batb":[[0,1.35,24.38],[1,1.34,6.52],[2,1.33,909.09]],"ltp":0.0,"tv":0.0,"id":23387705}]}]}
{"op":"mcm","clk":"11938583464","pt":1724374855820,"mc":[{"id":"1.232012908","rc":[{"batb":[[0,1.34,5.83],[1,1.33,909.09],[2,1.21,82.86]],"ltp":0.0,"tv":0.0,"id":35736916},{"batb":[[0,1.34,6.52],[1,1.33,909.09],[2,1.21,82.86]],"ltp":0.0,"tv":0.0,"id":23387705}]}]}
{"op":"mcm","clk":"11938597211","pt":1724375102686,"mc":[{"id":"1.232012908","rc":[{"batb":[[0,1.35,24.38],[1,1.34,5.83],[2,1.33,909.09]],"ltp":0.0,"tv":0.0,"id":35736916},{"batb":[[0,1.35,24.38],[1,1.34,6.52],[2,1.33,909.09]],"ltp":0.0,"tv":0.0,"id":23387705}]}]}
{"op":"mcm","clk":"11938697174","pt":1724376903328,"mc":[{"id":"1.232012908","rc":[{"batb":[[0,1.34,5.83],[1,1.33,909.09],[2,1.21,82.86]],"ltp":0.0,"tv":0.0,"id":35736916}]}]}
{"op":"mcm","clk":"11938697187","pt":1724376903533,"mc":[{"id":"1.232012908","rc":[{"batb":[[0,1.34,6.52],[1,1.33,909.09],[2,1.21,82.86]],"ltp":0.0,"tv":0.0,"id":23387705}]}]}
{"op":"mcm","clk":"11938709123","pt":1724377145829,"mc":[{"id":"1.232012908","rc":[{"batb":[[0,1.35,24.38],[1,1.34,5.83],[2,1.33,909.09]],"ltp":0.0,"tv":0.0,"id":35736916},{"batb":[[0,1.35,24.38],[1,1.34,6.52],[2,1.33,909.09]],"ltp":0.0,"tv":0.0,"id":23387705}]}]}
{"op":"mcm","clk":"11938774086","pt":1724378946859,"mc":[{"id":"1.232012908","rc":[{"batb":[[0,1.34,5.82],[1,1.33,909.09],[2,1.21,82.88]],"ltp":0.0,"tv":0.0,"id":35736916},{"batb":[[0,1.34,6.52],[1,1.33,909.09],[2,1.21,82.88]],"ltp":0.0,"tv":0.0,"id":23387705}]}]}
{"op":"mcm","clk":"11938791660","pt":1724379175132,"mc":[{"id":"1.232012908","rc":[{"batb":[[0,1.35,24.39],[1,1.34,5.82],[2,1.33,909.09]],"ltp":0.0,"tv":0.0,"id":35736916},{"batb":[[0,1.35,24.39],[1,1.34,6.52],[2,1.33,909.09]],"ltp":0.0,"tv":0.0,"id":23387705}]}]}
{"op":"mcm","clk":"11938851359","pt":1724380975185,"mc":[{"id":"1.232012908","rc":[{"batb":[[0,1.34,5.82],[1,1.33,909.09],[2,1.21,82.88]],"ltp":0.0,"tv":0.0,"id":35736916},{"batb":[[0,1.34,6.52],[1,1.33,909.09],[2,1.21,82.88]],"ltp":0.0,"tv":0.0,"id":23387705}]}]}
{"op":"mcm","clk":"11938857786","pt":1724381190188,"mc":[{"id":"1.232012908","rc":[{"batb":[[0,1.35,24.39],[1,1.34,5.82],[2,1.33,909.09]],"ltp":0.0,"tv":0.0,"id":35736916},{"batb":[[0,1.35,24.39],[1,1.34,6.52],[2,1.33,909.09]],"ltp":0.0,"tv":0.0,"id":23387705}]}]}
{"op":"mcm","clk":"11938875201","pt":1724382162723,"mc":[{"id":"1.232012908","rc":[{"batb":[[0,1.35,24.38],[1,1.34,5.82]],"ltp":0.0,"tv":0.0,"id":35736916},{"batb":[[0,1.35,24.38],[1,1.34,6.52]],"batl":[[0,3.35,0.93]],"ltp":0.0,"tv":0.0,"id":23387705}]}]}
{"op":"mcm","clk":"11938875413","pt":1724382172640,"mc":[{"id":"1.232012908","rc":[{"batl":[[0,3.3,0.93]],"ltp":0.0,"tv":0.0,"id":35736916}]}]}
{"op":"mcm","clk":"11938891224","pt":1724382990888,"mc":[{"id":"1.232012908","rc":[{"batb":[[0,1.34,5.82],[1,1.33,909.09],[2,1.21,82.87]],"ltp":0.0,"tv":0.0,"id":35736916},{"batb":[[0,1.34,6.52],[1,1.33,909.09],[2,1.21,82.87]],"ltp":0.0,"tv":0.0,"id":23387705}]}]}
{"op":"mcm","clk":"11938895907","pt":1724383196310,"mc":[{"id":"1.232012908","rc":[{"batb":[[0,1.43,19.85],[1,1.34,5.82],[2,1.33,909.09]],"ltp":0.0,"tv":0.0,"id":35736916},{"batb":[[0,1.44,19.39],[1,1.34,6.52],[2,1.33,909.09]],"ltp":0.0,"tv":0.0,"id":23387705}]}]}
{"op":"mcm","clk":"11938946748","pt":1724384997203,"mc":[{"id":"1.232012908","rc":[{"batb":[[0,1.34,5.82],[1,1.33,909.09],[2,1.21,82.87]],"ltp":0.0,"tv":0.0,"id":35736916},{"batb":[[0,1.34,6.52],[1,1.33,909.09],[2,1.21,82.87]],"ltp":0.0,"tv":0.0,"id":23387705}]}]}
{"op":"mcm","clk":"11938951538","pt":1724385196347,"mc":[{"id":"1.232012908","rc":[{"batb":[[0,1.43,19.85],[1,1.34,5.82],[2,1.33,909.09]],"ltp":0.0,"tv":0.0,"id":35736916},{"batb":[[0,1.44,19.39],[1,1.34,6.52],[2,1.33,909.09]],"ltp":0.0,"tv":0.0,"id":23387705}]}]}
{"op":"mcm","clk":"11938991139","pt":1724386996878,"mc":[{"id":"1.232012908","rc":[{"batb":[[0,1.34,5.82],[1,1.33,909.09],[2,1.21,82.88]],"ltp":0.0,"tv":0.0,"id":35736916},{"batb":[[0,1.34,6.52],[1,1.33,909.09],[2,1.21,82.88]],"ltp":0.0,"tv":0.0,"id":23387705}]}]}
{"op":"mcm","clk":"11938995498","pt":1724387191264,"mc":[{"id":"1.232012908","rc":[{"batb":[[0,1.43,19.85],[1,1.34,5.82],[2,1.33,909.09]],"ltp":0.0,"tv":0.0,"id":35736916},{"batb":[[0,1.44,19.4],[1,1.34,6.52],[2,1.33,909.09]],"ltp":0.0,"tv":0.0,"id":23387705}]}]}
{"op":"mcm","clk":"11939034568","pt":1724388991787,"mc":[{"id":"1.232012908","rc":[{"batb":[[0,1.34,5.82],[1,1.33,909.09],[2,1.21,82.88]],"ltp":0.0,"tv":0.0,"id":35736916},{"batb":[[0,1.34,6.52],[1,1.33,909.09],[2,1.21,82.88]],"ltp":0.0,"tv":0.0,"id":23387705}]}]}
{"op":"mcm","clk":"11939042594","pt":1724389173740,"mc":[{"id":"1.232012908","rc":[{"batb":[[0,1.43,19.85],[1,1.34,5.82],[2,1.33,909.09]],"ltp":0.0,"tv":0.0,"id":35736916},{"batb":[[0,1.44,19.4],[1,1.34,6.52],[2,1.33,909.09]],"ltp":0.0,"tv":0.0,"id":23387705}]}]}
{"op":"mcm","clk":"11939087130","pt":1724389975128,"mc":[{"id":"1.232012908","rc":[{"batb":[[0,1.43,19.84],[1,1.34,5.82]],"ltp":0.0,"tv":0.0,"id":35736916},{"batb":[[0,1.44,19.39],[1,1.34,6.51]],"ltp":0.0,"tv":0.0,"id":23387705}]}]}
{"op":"mcm","clk":"11939123662","pt":1724390974399,"mc":[{"id":"1.232012908","rc":[{"batb":[[0,1.34,6.51],[1,1.33,909.09],[2,1.21,82.86]],"ltp":0.0,"tv":0.0,"id":23387705}]}]}
{"op":"mcm","clk":"11939123665","pt":1724390974500,"mc":[{"id":"1.232012908","rc":[{"batb":[[0,1.34,5.82],[1,1.33,909.09],[2,1.21,82.86]],"ltp":0.0,"tv":0.0,"id":35736916}]}]}
{"op":"mcm","clk":"11939130788","pt":1724391158595,"mc":[{"id":"1.232012908","rc":[{"batb":[[0,1.43,19.84],[1,1.34,5.82],[2,1.33,909.09]],"ltp":0.0,"tv":0.0,"id":35736916},{"batb":[[0,1.44,19.39],[1,1.34,6.51],[2,1.33,909.09]],"ltp":0.0,"tv":0.0,"id":23387705}]}]}
{"op":"mcm","clk":"11939198903","pt":1724392959329,"mc":[{"id":"1.232012908","rc":[{"batb":[[0,1.34,5.82],[1,1.33,909.09],[2,1.21,82.85]],"ltp":0.0,"tv":0.0,"id":35736916},{"batb":[[0,1.34,6.51],[1,1.33,909.09],[2,1.21,82.85]],"ltp":0.0,"tv":0.0,"id":23387705}]}]}
{"op":"mcm","clk":"11939206153","pt":1724393135041,"mc":[{"id":"1.232012908","rc":[{"batb":[[0,1.43,19.84],[1,1.34,5.82],[2,1.33,909.09]],"ltp":0.0,"tv":0.0,"id":35736916},{"batb":[[0,1.44,19.39],[1,1.34,6.51],[2,1.33,909.09]],"ltp":0.0,"tv":0.0,"id":23387705}]}]}
{"op":"mcm","clk":"11939285136","pt":1724394935376,"mc":[{"id":"1.232012908","rc":[{"batb":[[0,1.34,5.82],[1,1.33,909.09],[2,1.21,82.85]],"ltp":0.0,"tv":0.0,"id":35736916},{"batb":[[0,1.34,6.51],[1,1.33,909.09],[2,1.21,82.85]],"ltp":0.0,"tv":0.0,"id":23387705}]}]}
{"op":"mcm","clk":"11939292041","pt":1724395112008,"mc":[{"id":"1.232012908","rc":[{"batb":[[0,1.43,19.84],[1,1.34,5.82],[2,1.33,909.09]],"ltp":0.0,"tv":0.0,"id":35736916},{"batb":[[0,1.44,19.39],[1,1.34,6.51],[2,1.33,909.09]],"ltp":0.0,"tv":0.0,"id":23387705}]}]}
{"op":"mcm","clk":"11939391960","pt":1724396912360,"mc":[{"id":"1.232012908","rc":[{"batb":[[0,1.34,5.81],[1,1.33,909.09],[2,1.21,82.84]],"batl":[[0,3.3,0.93]],"ltp":0.0,"tv":0.0,"id":35736916},{"batb":[[0,1.34,6.51],[1,1.33,909.09],[2,1.21,82.84]],"batl":[[0,3.35,0.93]],"ltp":0.0,"tv":0.0,"id":23387705}]}]}
{"op":"mcm","clk":"11939400425","pt":1724397087720,"mc":[{"id":"1.232012908","rc":[{"batb":[[0,1.43,19.82],[1,1.34,5.81],[2,1.33,909.09]],"ltp":0.0,"tv":0.0,"id":35736916},{"batb":[[0,1.44,19.37],[1,1.34,6.51],[2,1.33,909.09]],"ltp":0.0,"tv":0.0,"id":23387705}]}]}
{"op":"mcm","clk":"11939501407","pt":1724398888223,"mc":[{"id":"1.232012908","rc":[{"batb":[[0,1.34,5.81],[1,1.33,909.09],[2,1.21,82.84]],"ltp":0.0,"tv":0.0,"id":35736916},{"batb":[[0,1.34,6.51],[1,1.33,909.09],[2,1.21,82.84]],"ltp":0.0,"tv":0.0,"id":23387705}]}]}
{"op":"mcm","clk":"11939510209","pt":1724399067325,"mc":[{"id":"1.232012908","rc":[{"batb":[[0,1.43,19.82],[1,1.34,5.81],[2,1.33,909.09]],"ltp":0.0,"tv":0.0,"id":35736916},{"batb":[[0,1.44,19.37],[1,1.34,6.51],[2,1.33,909.09]],"ltp":0.0,"tv":0.0,"id":23387705}]}]}
{"op":"mcm","clk":"11939629258","pt":1724400775129,"mc":[{"id":"1.232012908","rc":[{"batb":[[0,1.43,19.82],[1,1.34,5.82]],"ltp":0.0,"tv":0.0,"id":35736916},{"batb":[[0,1.44,19.36],[1,1.34,6.51]],"ltp":0.0,"tv":0.0,"id":23387705}]}]}
{"op":"mcm","clk":"11939640690","pt":1724400868075,"mc":[{"id":"1.232012908","rc":[{"batb":[[0,1.34,5.82],[1,1.33,909.09],[2,1.21,82.51]],"ltp":0.0,"tv":0.0,"id":35736916},{"batb":[[0,1.34,6.51],[1,1.33,909.09],[2,1.21,82.51]],"ltp":0.0,"tv":0.0,"id":23387705}]}]}
{"op":"mcm","clk":"11939652987","pt":1724401042542,"mc":[{"id":"1.232012908","rc":[{"batb":[[0,1.43,19.82],[1,1.34,5.82],[2,1.33,909.09]],"ltp":0.0,"tv":0.0,"id":35736916},{"batb":[[0,1.44,19.36],[1,1.34,6.51],[2,1.33,909.09]],"ltp":0.0,"tv":0.0,"id":23387705}]}]}
{"op":"mcm","clk":"11939771385","pt":1724402843102,"mc":[{"id":"1.232012908","rc":[{"batb":[[0,1.34,5.82],[1,1.33,909.09],[2,1.21,82.51]],"ltp":0.0,"tv":0.0,"id":35736916},{"batb":[[0,1.34,6.51],[1,1.33,909.09],[2,1.21,82.51]],"ltp":0.0,"tv":0.0,"id":23387705}]}]}
{"op":"mcm","clk":"11939780972","pt":1724402984263,"mc":[{"id":"1.232012908","rc":[{"batb":[[0,1.43,19.82],[1,1.34,5.82],[2,1.33,909.09]],"ltp":0.0,"tv":0.0,"id":35736916},{"batb":[[0,1.44,19.36],[1,1.34,6.51],[2,1.33,909.09]],"ltp":0.0,"tv":0.0,"id":23387705}]}]}
{"op":"mcm","clk":"11939932553","pt":1724404784569,"mc":[{"id":"1.232012908","rc":[{"batb":[[0,1.34,5.81],[1,1.33,909.09],[2,1.21,82.41]],"ltp":0.0,"tv":0.0,"id":35736916},{"batb":[[0,1.34,6.51],[1,1.33,909.09],[2,1.21,82.41]],"ltp":0.0,"tv":0.0,"id":23387705}]}]}
{"op":"mcm","clk":"11939952651","pt":1724405016426,"mc":[{"id":"1.232012908","rc":[{"batb":[[0,1.43,19.8],[1,1.34,5.81],[2,1.33,909.09]],"ltp":0.0,"tv":0.0,"id":35736916},{"batb":[[0,1.44,19.35],[1,1.34,6.51],[2,1.33,909.09]],"ltp":0.0,"tv":0.0,"id":23387705}]}]}
{"op":"mcm","clk":"11940105491","pt":1724406816929,"mc":[{"id":"1.232012908","rc":[{"batb":[[0,1.34,5.81],[1,1.33,909.09],[2,1.21,82.41]],"ltp":0.0,"tv":0.0,"id":35736916},{"batb":[[0,1.34,6.51],[1,1.33,909.09],[2,1.21,82.41]],"ltp":0.0,"tv":0.0,"id":23387705}]}]}
{"op":"mcm","clk":"11940125886","pt":1724407061081,"mc":[{"id":"1.232012908","rc":[{"batb":[[0,1.43,19.8],[1,1.34,5.81],[2,1.33,909.09]],"ltp":0.0,"tv":0.0,"id":35736916},{"batb":[[0,1.44,19.35],[1,1.34,6.51],[2,1.33,909.09]],"ltp":0.0,"tv":0.0,"id":23387705}]}]}
{"op":"mcm","clk":"11940274491","pt":1724408861625,"mc":[{"id":"1.232012908","rc":[{"batb":[[0,1.34,5.81],[1,1.33,909.09],[2,1.21,82.35]],"ltp":0.0,"tv":0.0,"id":35736916},{"batb":[[0,1.34,6.5],[1,1.33,909.09],[2,1.21,82.35]],"ltp":0.0,"tv":0.0,"id":23387705}]}]}
{"op":"mcm","clk":"11940295402","pt":1724409105270,"mc":[{"id":"1.232012908","rc":[{"batb":[[0,1.43,19.79],[1,1.34,5.81],[2,1.33,909.09]],"ltp":0.0,"tv":0.0,"id":35736916},{"batb":[[0,1.44,19.34],[1,1.34,6.5],[2,1.33,909.09]],"ltp":0.0,"tv":0.0,"id":23387705}]}]}
{"op":"mcm","clk":"11940405429","pt":1724410480932,"mc":[{"id":"1.232012908","rc":[{"batb":[[2,1.21,82.35]],"ltp":0.0,"tv":0.0,"id":35736916},{"batb":[[2,1.21,82.35]],"ltp":0.0,"tv":0.0,"id":23387705}]}]}
{"op":"mcm","clk":"11940429862","pt":1724410755036,"mc":[{"id":"1.232012908","rc":[{"batb":[[2,1.22,909.09]],"ltp":0.0,"tv":0.0,"id":23387705}]}]}
{"op":"mcm","clk":"11940430006","pt":1724410756949,"mc":[{"id":"1.232012908","rc":[{"batb":[[2,1.22,909.09]],"ltp":0.0,"tv":0.0,"id":35736916}]}]}
{"op":"mcm","clk":"11940442139","pt":1724410905682,"mc":[{"id":"1.232012908","rc":[{"batb":[[0,1.34,5.82],[1,1.22,909.09],[2,1.21,82.35]],"ltp":0.0,"tv":0.0,"id":35736916},{"batb":[[0,1.34,6.51],[1,1.22,909.09],[2,1.21,82.35]],"ltp":0.0,"tv":0.0,"id":23387705}]}]}
{"op":"mcm","clk":"11940463266","pt":1724411144468,"mc":[{"id":"1.232012908","rc":[{"batb":[[0,1.43,19.81],[1,1.34,5.82],[2,1.22,909.09]],"ltp":0.0,"tv":0.0,"id":35736916},{"batb":[[0,1.44,19.36],[1,1.34,6.51],[2,1.22,909.09]],"ltp":0.0,"tv":0.0,"id":23387705}]}]}
{"op":"mcm","clk":"11940469843","pt":1724411211336,"mc":[{"id":"1.232012908","rc":[{"batb":[[1,1.22,909.09],[2,1.21,82.35]],"ltp":0.0,"tv":0.0,"id":23387705}]}]}
{"op":"mcm","clk":"11940469894","pt":1724411211843,"mc":[{"id":"1.232012908","rc":[{"batb":[[1,1.23,5.82]],"ltp":0.0,"tv":0.0,"id":35736916},{"batb":[[1,1.23,6.51],[2,1.22,909.09]],"ltp":0.0,"tv":0.0,"id":23387705}]}]}
{"op":"mcm","clk":"11940635005","pt":1724412944971,"mc":[{"id":"1.232012908","rc":[{"batb":[[0,1.23,5.82],[1,1.22,909.09],[2,1.21,82.35]],"ltp":0.0,"tv":0.0,"id":35736916},{"batb":[[0,1.23,6.51],[1,1.22,909.09],[2,1.21,82.35]],"ltp":0.0,"tv":0.0,"id":23387705}]}]}
{"op":"mcm","clk":"11940659086","pt":1724413182239,"mc":[{"id":"1.232012908","rc":[{"batb":[[0,1.43,19.81],[1,1.23,5.82],[2,1.22,909.09]],"ltp":0.0,"tv":0.0,"id":35736916},{"batb":[[0,1.44,19.36],[1,1.23,6.51],[2,1.22,909.09]],"ltp":0.0,"tv":0.0,"id":23387705}]}]}
{"op":"mcm","clk":"11940835726","pt":1724414982523,"mc":[{"id":"1.232012908","rc":[{"batb":[[0,1.23,5.81],[1,1.22,909.09],[2,1.21,82.42]],"ltp":0.0,"tv":0.0,"id":35736916},{"batb":[[0,1.23,6.51],[1,1.22,909.09],[2,1.21,82.42]],"ltp":0.0,"tv":0.0,"id":23387705}]}]}
{"op":"mcm","clk":"11940845091","pt":1724415073830,"mc":[{"id":"1.232012908","rc":[{"batl":[[0,5.5,10.78]],"ltp":0.0,"tv":0.0,"id":35736916},{"batl":[[0,5.5,10.77]],"ltp":0.0,"tv":0.0,"id":23387705}]}]}
{"op":"mcm","clk":"11940859107","pt":1724415205496,"mc":[{"id":"1.232012908","rc":[{"batb":[[0,1.43,19.81],[1,1.23,5.81],[2,1.22,909.09]],"ltp":0.0,"tv":0.0,"id":35736916},{"batb":[[0,1.44,19.36],[1,1.23,6.51],[2,1.22,909.09]],"ltp":0.0,"tv":0.0,"id":23387705}]}]}
{"op":"mcm","clk":"11940859239","pt":1724415206794,"mc":[{"id":"1.232012908","rc":[{"batl":[[0,3.3,0.93]],"ltp":0.0,"tv":0.0,"id":35736916},{"batl":[[0,3.35,0.93]],"ltp":0.0,"tv":0.0,"id":23387705}]}]}
{"op":"mcm","clk":"11941056495","pt":1724417005897,"mc":[{"id":"1.232012908","rc":[{"batb":[[0,1.23,5.81],[1,1.22,909.09],[2,1.21,82.42]],"ltp":0.0,"tv":0.0,"id":35736916},{"batb":[[0,1.23,6.51],[1,1.22,909.09],[2,1.21,82.42]],"ltp":0.0,"tv":0.0,"id":23387705}]}]}
{"op":"mcm","clk":"11941070255","pt":1724417173385,"mc":[{"id":"1.232012908","rc":[{"batl":[[0,5.5,10.78]],"ltp":0.0,"tv":0.0,"id":35736916},{"batl":[[0,5.5,10.77]],"ltp":0.0,"tv":0.0,"id":23387705}]}]}
{"op":"mcm","clk":"11941073958","pt":1724417216428,"mc":[{"id":"1.232012908","rc":[{"batb":[[0,1.43,19.81],[1,1.23,5.81],[2,1.22,909.09]],"ltp":0.0,"tv":0.0,"id":35736916},{"batb":[[0,1.44,19.36],[1,1.23,6.51],[2,1.22,909.09]],"ltp":0.0,"tv":0.0,"id":23387705}]}]}
{"op":"mcm","clk":"11941074132","pt":1724417218343,"mc":[{"id":"1.232012908","rc":[{"batl":[[0,3.3,0.93]],"ltp":0.0,"tv":0.0,"id":35736916},{"batl":[[0,3.35,0.93]],"ltp":0.0,"tv":0.0,"id":23387705}]}]}
{"op":"mcm","clk":"11941233951","pt":1724419016905,"mc":[{"id":"1.232012908","rc":[{"batb":[[0,1.23,5.81],[1,1.22,909.09],[2,1.21,82.31]],"ltp":0.0,"tv":0.0,"id":35736916},{"batb":[[0,1.23,6.51],[1,1.22,909.09],[2,1.21,82.31]],"ltp":0.0,"tv":0.0,"id":23387705}]}]}
{"op":"mcm","clk":"11941254265","pt":1724419225285,"mc":[{"id":"1.232012908","rc":[{"batb":[[0,1.43,19.8],[1,1.23,5.81],[2,1.22,909.09]],"ltp":0.0,"tv":0.0,"id":35736916},{"batb":[[0,1.44,19.35],[1,1.23,6.51],[2,1.22,909.09]],"ltp":0.0,"tv":0.0,"id":23387705}]}]}
{"op":"mcm","clk":"11941426698","pt":1724421026013,"mc":[{"id":"1.232012908","rc":[{"batb":[[0,1.23,5.81],[1,1.22,909.09],[2,1.21,82.31]],"ltp":0.0,"tv":0.0,"id":35736916},{"batb":[[0,1.23,6.51],[1,1.22,909.09],[2,1.21,82.31]],"ltp":0.0,"tv":0.0,"id":23387705}]}]}
{"op":"mcm","clk":"11941444629","pt":1724421222740,"mc":[{"id":"1.232012908","rc":[{"batb":[[0,1.43,19.8],[1,1.23,5.81],[2,1.22,909.09]],"ltp":0.0,"tv":0.0,"id":35736916},{"batb":[[0,1.44,19.35],[1,1.23,6.51],[2,1.22,909.09]],"ltp":0.0,"tv":0.0,"id":23387705}]}]}
{"op":"mcm","clk":"11941557199","pt":1724422375189,"mc":[{"id":"1.232012908","rc":[{"batb":[[1,1.23,5.82]],"ltp":0.0,"tv":0.0,"id":35736916},{"batb":[[1,1.23,6.51]],"ltp":0.0,"tv":0.0,"id":23387705}]}]}
{"op":"mcm","clk":"11941613257","pt":1724423023355,"mc":[{"id":"1.232012908","rc":[{"batb":[[0,1.23,5.82],[1,1.22,909.09],[2,1.21,82.31]],"ltp":0.0,"tv":0.0,"id":35736916}]}]}
{"op":"mcm","clk":"11941613274","pt":1724423023517,"mc":[{"id":"1.232012908","rc":[{"batb":[[0,1.23,6.51],[1,1.22,909.09],[2,1.21,82.31]],"ltp":0.0,"tv":0.0,"id":23387705}]}]}
{"op":"mcm","clk":"11941627529","pt":1724423206441,"mc":[{"id":"1.232012908","rc":[{"batb":[[0,1.43,19.8],[1,1.23,5.82],[2,1.22,909.09]],"ltp":0.0,"tv":0.0,"id":35736916},{"batb":[[0,1.44,19.35],[1,1.23,6.51],[2,1.22,909.09]],"ltp":0.0,"tv":0.0,"id":23387705}]}]}
{"op":"mcm","clk":"11941759595","pt":1724425006986,"mc":[{"id":"1.232012908","rc":[{"batb":[[0,1.23,5.82],[1,1.22,909.09],[2,1.21,82.31]],"ltp":0.0,"tv":0.0,"id":35736916},{"batb":[[0,1.23,6.51],[1,1.22,909.09],[2,1.21,82.31]],"ltp":0.0,"tv":0.0,"id":23387705}]}]}
{"op":"mcm","clk":"11941770228","pt":1724425177509,"mc":[{"id":"1.232012908","rc":[{"batb":[[0,1.43,19.8],[1,1.23,5.82],[2,1.22,909.09]],"ltp":0.0,"tv":0.0,"id":35736916},{"batb":[[0,1.44,19.35],[1,1.23,6.51],[2,1.22,909.09]],"ltp":0.0,"tv":0.0,"id":23387705}]}]}
{"op":"mcm","clk":"11941905815","pt":1724426978092,"mc":[{"id":"1.232012908","rc":[{"batb":[[0,1.23,5.78],[1,1.22,909.09],[2,1.21,82.62]],"batl":[[0,3.3,0.93]],"ltp":0.0,"tv":0.0,"id":35736916},{"batb":[[0,1.23,6.47],[1,1.22,909.09],[2,1.21,82.62]],"batl":[[0,3.35,0.93]],"ltp":0.0,"tv":0.0,"id":23387705}]}]}
{"op":"mcm","clk":"11941918811","pt":1724427141983,"mc":[{"id":"1.232012908","rc":[{"batb":[[0,1.43,19.81],[1,1.23,5.78],[2,1.22,909.09]],"ltp":0.0,"tv":0.0,"id":35736916},{"batb":[[0,1.44,19.36],[1,1.23,6.47],[2,1.22,909.09]],"ltp":0.0,"tv":0.0,"id":23387705}]}]}
{"op":"mcm","clk":"11942082580","pt":1724428942242,"mc":[{"id":"1.232012908","rc":[{"batb":[[0,1.23,5.78],[1,1.22,909.09],[2,1.21,82.67]],"ltp":0.0,"tv":0.0,"id":35736916},{"batb":[[0,1.44,19.35]],"ltp":0.0,"tv":0.0,"id":23387705}]}]}
{"op":"mcm","clk":"11942082608","pt":1724428942454,"mc":[{"id":"1.232012908","rc":[{"batb":[[0,1.23,6.47],[1,1.22,909.09],[2,1.21,82.67]],"ltp":0.0,"tv":0.0,"id":23387705}]}]}
{"op":"mcm","clk":"11942098559","pt":1724429102936,"mc":[{"id":"1.232012908","rc":[{"batb":[[0,1.43,19.8],[1,1.23,5.78],[2,1.22,909.09]],"ltp":0.0,"tv":0.0,"id":35736916},{"batb":[[0,1.44,19.35],[1,1.23,6.47],[2,1.22,909.09]],"ltp":0.0,"tv":0.0,"id":23387705}]}]}
{"op":"mcm","clk":"11942318411","pt":1724430903391,"mc":[{"id":"1.232012908","rc":[{"batb":[[0,1.23,6.47],[1,1.22,909.09],[2,1.21,82.67]],"ltp":0.0,"tv":0.0,"id":23387705}]}]}
{"op":"mcm","clk":"11942318494","pt":1724430903872,"mc":[{"id":"1.232012908","rc":[{"batb":[[0,1.23,5.78],[1,1.22,909.09],[2,1.21,82.67]],"ltp":0.0,"tv":0.0,"id":35736916}]}]}
{"op":"mcm","clk":"11942327773","pt":1724430970978,"mc":[{"id":"1.232012908","rc":[{"batl":[[0,5.5,10.77]],"ltp":0.0,"tv":0.0,"id":35736916},{"batl":[[0,5.5,10.76]],"ltp":0.0,"tv":0.0,"id":23387705}]}]}
{"op":"mcm","clk":"11942339350","pt":1724431058204,"mc":[{"id":"1.232012908","rc":[{"batb":[[0,1.43,19.8],[1,1.23,5.78],[2,1.22,909.09]],"ltp":0.0,"tv":0.0,"id":35736916},{"batb":[[0,1.44,19.35],[1,1.23,6.47],[2,1.22,909.09]],"ltp":0.0,"tv":0.0,"id":23387705}]}]}
{"op":"mcm","clk":"11942339502","pt":1724431059306,"mc":[{"id":"1.232012908","rc":[{"batl":[[0,3.3,0.93]],"ltp":0.0,"tv":0.0,"id":35736916},{"batl":[[0,3.35,0.93]],"ltp":0.0,"tv":0.0,"id":23387705}]}]}
{"op":"mcm","clk":"11942562733","pt":1724432859019,"mc":[{"id":"1.232012908","rc":[{"batb":[[0,1.23,5.78],[1,1.22,909.09],[2,1.21,82.61]],"ltp":0.0,"tv":0.0,"id":35736916},{"batb":[[0,1.23,6.47],[1,1.22,909.09],[2,1.21,82.61]],"ltp":0.0,"tv":0.0,"id":23387705}]}]}
{"op":"mcm","clk":"11942586762","pt":1724433006856,"mc":[{"id":"1.232012908","rc":[{"batb":[[0,1.43,19.8],[1,1.23,5.78],[2,1.22,909.09]],"ltp":0.0,"tv":0.0,"id":35736916},{"batb":[[0,1.44,19.35],[1,1.23,6.47],[2,1.22,909.09]],"ltp":0.0,"tv":0.0,"id":23387705}]}]}
{"op":"mcm","clk":"11942927922","pt":1724434827401,"mc":[{"id":"1.232012908","rc":[{"batb":[[0,1.23,6.47],[1,1.22,909.09],[2,1.04,1.53]],"ltp":0.0,"tv":0.0,"id":23387705}]}]}
{"op":"mcm","clk":"11942927963","pt":1724434827573,"mc":[{"id":"1.232012908","rc":[{"batb":[[0,1.23,5.78],[1,1.22,909.09],[2,1.04,1.53]],"ltp":0.0,"tv":0.0,"id":35736916}]}]}
{"op":"mcm","clk":"11942948063","pt":1724434934761,"mc":[{"id":"1.232012908","rc":[{"batl":[[0,5.5,10.77]],"ltp":0.0,"tv":0.0,"id":35736916},{"batl":[[0,5.5,10.76]],"ltp":0.0,"tv":0.0,"id":23387705}]}]}
{"op":"mcm","clk":"11942949459","pt":1724434942268,"mc":[{"id":"1.232012908","rc":[{"batb":[[0,1.43,19.8],[1,1.23,5.78],[2,1.22,909.09]],"ltp":0.0,"tv":0.0,"id":35736916},{"batb":[[0,1.44,19.35],[1,1.23,6.47],[2,1.22,909.09]],"ltp":0.0,"tv":0.0,"id":23387705}]}]}
{"op":"mcm","clk":"11942949668","pt":1724434943436,"mc":[{"id":"1.232012908","rc":[{"batl":[[0,3.3,0.93]],"ltp":0.0,"tv":0.0,"id":35736916},{"batl":[[0,3.35,0.93]],"ltp":0.0,"tv":0.0,"id":23387705}]}]}
{"op":"mcm","clk":"11943264813","pt":1724436742892,"mc":[{"id":"1.232012908","rc":[{"batb":[[0,1.23,5.78],[1,1.22,909.09],[2,1.04,1.53]],"batl":[[0,3.3,0.93]],"ltp":0.0,"tv":0.0,"id":35736916},{"batb":[[0,1.23,6.46],[1,1.22,909.09],[2,1.04,1.53]],"batl":[[0,3.35,0.93]],"ltp":0.0,"tv":0.0,"id":23387705}]}]}
{"op":"mcm","clk":"11943288549","pt":1724436858698,"mc":[{"id":"1.232012908","rc":[{"batb":[[0,1.43,19.81],[1,1.23,5.78],[2,1.22,909.09]],"ltp":0.0,"tv":0.0,"id":35736916},{"batb":[[0,1.44,19.36],[1,1.23,6.46],[2,1.22,909.09]],"ltp":0.0,"tv":0.0,"id":23387705}]}]}
{"op":"mcm","clk":"11943683214","pt":1724438659207,"mc":[{"id":"1.232012908","rc":[{"batb":[[0,1.23,5.78],[1,1.22,909.09],[2,1.04,1.53]],"ltp":0.0,"tv":0.0,"id":35736916},{"batb":[[0,1.23,6.46],[1,1.22,909.09],[2,1.04,1.53]],"ltp":0.0,"tv":0.0,"id":23387705}]}]}
{"op":"mcm","clk":"11943698964","pt":1724438744371,"mc":[{"id":"1.232012908","rc":[{"batb":[[0,1.43,19.81],[1,1.23,5.78],[2,1.22,909.09]],"ltp":0.0,"tv":0.0,"id":35736916},{"batb":[[0,1.44,19.36],[1,1.23,6.46],[2,1.22,909.09]],"ltp":0.0,"tv":0.0,"id":23387705}]}]}
{"op":"mcm","clk":"11944027609","pt":1724440544867,"mc":[{"id":"1.232012908","rc":[{"batb":[[0,1.23,5.78],[1,1.22,909.09],[2,1.04,1.53]],"ltp":0.0,"tv":0.0,"id":35736916},{"batb":[[0,1.23,6.47],[1,1.22,909.09],[2,1.04,1.53]],"ltp":0.0,"tv":0.0,"id":23387705}]}]}
{"op":"mcm","clk":"11944038944","pt":1724440602323,"mc":[{"id":"1.232012908","rc":[{"batb":[[0,1.43,19.81],[1,1.23,5.78],[2,1.22,909.09]],"ltp":0.0,"tv":0.0,"id":35736916},{"batb":[[0,1.44,19.36],[1,1.23,6.47],[2,1.22,909.09]],"ltp":0.0,"tv":0.0,"id":23387705}]}]}
{"op":"mcm","clk":"11944342529","pt":1724442402676,"mc":[{"id":"1.232012908","rc":[{"batb":[[0,1.23,5.78],[1,1.22,909.09],[2,1.04,1.53]],"ltp":0.0,"tv":0.0,"id":35736916},{"batb":[[0,1.23,6.47],[1,1.22,909.09],[2,1.04,1.53]],"ltp":0.0,"tv":0.0,"id":23387705}]}]}
{"op":"mcm","clk":"11944345321","pt":1724442422002,"mc":[{"id":"1.232012908","rc":[{"batb":[[0,1.43,19.81],[1,1.23,5.78],[2,1.22,909.09]],"ltp":0.0,"tv":0.0,"id":35736916},{"batb":[[0,1.44,19.36],[1,1.23,6.47],[2,1.22,909.09]],"ltp":0.0,"tv":0.0,"id":23387705}]}]}
{"op":"mcm","clk":"11944544051","pt":1724443975245,"mc":[{"id":"1.232012908","rc":[{"batb":[[0,1.43,19.8],[1,1.23,5.78]],"ltp":0.0,"tv":0.0,"id":35736916},{"batb":[[0,1.44,19.35],[1,1.23,6.46]],"ltp":0.0,"tv":0.0,"id":23387705}]}]}
{"op":"mcm","clk":"11944577022","pt":1724444222251,"mc":[{"id":"1.232012908","rc":[{"batb":[[0,1.23,6.46],[1,1.22,909.09],[2,1.04,1.53]],"ltp":0.0,"tv":0.0,"id":23387705}]}]}
{"op":"mcm","clk":"11944577055","pt":1724444222529,"mc":[{"id":"1.232012908","rc":[{"batb":[[0,1.23,5.78],[1,1.22,909.09],[2,1.04,1.53]],"ltp":0.0,"tv":0.0,"id":35736916}]}]}
{"op":"mcm","clk":"11944601915","pt":1724444438185,"mc":[{"id":"1.232012908","rc":[{"batb":[[0,1.43,19.8],[1,1.23,5.78],[2,1.22,909.09]],"ltp":0.0,"tv":0.0,"id":35736916},{"batb":[[0,1.44,19.35],[1,1.23,6.46],[2,1.22,909.09]],"ltp":0.0,"tv":0.0,"id":23387705}]}]}
{"op":"mcm","clk":"11944766025","pt":1724446238411,"mc":[{"id":"1.232012908","rc":[{"batb":[[0,1.23,6.46],[1,1.22,909.09],[2,1.04,1.53]],"ltp":0.0,"tv":0.0,"id":23387705}]}]}
{"op":"mcm","clk":"11944766044","pt":1724446238615,"mc":[{"id":"1.232012908","rc":[{"batb":[[0,1.23,5.78],[1,1.22,909.09],[2,1.04,1.53]],"ltp":0.0,"tv":0.0,"id":35736916}]}]}
{"op":"mcm","clk":"11944778568","pt":1724446397680,"mc":[{"id":"1.232012908","rc":[{"batb":[[0,1.43,19.8],[1,1.23,5.78],[2,1.22,909.09]],"ltp":0.0,"tv":0.0,"id":35736916},{"batb":[[0,1.44,19.35],[1,1.23,6.46],[2,1.22,909.09]],"ltp":0.0,"tv":0.0,"id":23387705}]}]}
{"op":"mcm","clk":"11944921304","pt":1724448197915,"mc":[{"id":"1.232012908","rc":[{"batb":[[0,1.23,5.77],[1,1.22,909.09],[2,1.04,1.53]],"ltp":0.0,"tv":0.0,"id":35736916},{"batb":[[0,1.23,6.46],[1,1.22,909.09],[2,1.04,1.53]],"ltp":0.0,"tv":0.0,"id":23387705}]}]}
{"op":"mcm","clk":"11944929590","pt":1724448299218,"mc":[{"id":"1.232012908","rc":[{"batb":[[0,1.43,19.8],[1,1.23,5.77],[2,1.22,909.09]],"ltp":0.0,"tv":0.0,"id":35736916},{"batb":[[0,1.44,19.35],[1,1.23,6.46],[2,1.22,909.09]],"ltp":0.0,"tv":0.0,"id":23387705}]}]}
{"op":"mcm","clk":"11945075611","pt":1724450099627,"mc":[{"id":"1.232012908","rc":[{"batb":[[0,1.23,5.77],[1,1.22,909.09],[2,1.04,1.53]],"ltp":0.0,"tv":0.0,"id":35736916},{"batb":[[0,1.23,6.46],[1,1.22,909.09],[2,1.04,1.53]],"ltp":0.0,"tv":0.0,"id":23387705}]}]}
{"op":"mcm","clk":"11945082600","pt":1724450195146,"mc":[{"id":"1.232012908","rc":[{"batb":[[0,1.43,19.8],[1,1.23,5.77],[2,1.22,909.09]],"ltp":0.0,"tv":0.0,"id":35736916},{"batb":[[0,1.44,19.35],[1,1.23,6.46],[2,1.22,909.09]],"ltp":0.0,"tv":0.0,"id":23387705}]}]}
{"op":"mcm","clk":"11945202493","pt":1724451995627,"mc":[{"id":"1.232012908","rc":[{"batb":[[0,1.23,5.78],[1,1.22,909.09],[2,1.04,1.53]],"ltp":0.0,"tv":0.0,"id":35736916},{"batb":[[0,1.23,6.46],[1,1.22,909.09],[2,1.04,1.53]],"ltp":0.0,"tv":0.0,"id":23387705}]}]}
{"op":"mcm","clk":"11945207994","pt":1724452078715,"mc":[{"id":"1.232012908","rc":[{"batb":[[0,1.43,19.8],[1,1.23,5.78],[2,1.22,909.09]],"ltp":0.0,"tv":0.0,"id":35736916},{"batb":[[0,1.44,19.35],[1,1.23,6.46],[2,1.22,909.09]],"ltp":0.0,"tv":0.0,"id":23387705}]}]}
{"op":"mcm","clk":"11945313952","pt":1724453879279,"mc":[{"id":"1.232012908","rc":[{"batb":[[0,1.23,5.78],[1,1.22,909.09],[2,1.04,1.53]],"ltp":0.0,"tv":0.0,"id":35736916},{"batb":[[0,1.23,6.46],[1,1.22,909.09],[2,1.04,1.53]],"ltp":0.0,"tv":0.0,"id":23387705}]}]}
{"op":"mcm","clk":"11945318895","pt":1724453958804,"mc":[{"id":"1.232012908","rc":[{"batb":[[0,1.43,19.8],[1,1.23,5.78],[2,1.22,909.09]],"ltp":0.0,"tv":0.0,"id":35736916},{"batb":[[0,1.44,19.35],[1,1.23,6.46],[2,1.22,909.09]],"ltp":0.0,"tv":0.0,"id":23387705}]}]}
{"op":"mcm","clk":"11945448280","pt":1724455759316,"mc":[{"id":"1.232012908","rc":[{"batb":[[0,1.23,5.78],[1,1.22,909.09],[2,1.04,1.53]],"ltp":0.0,"tv":0.0,"id":35736916},{"batb":[[0,1.23,6.46],[1,1.22,909.09],[2,1.04,1.53]],"ltp":0.0,"tv":0.0,"id":23387705}]}]}
{"op":"mcm","clk":"11945453465","pt":1724455839417,"mc":[{"id":"1.232012908","rc":[{"batb":[[0,1.43,19.8],[1,1.23,5.78],[2,1.22,909.09]],"ltp":0.0,"tv":0.0,"id":35736916},{"batb":[[0,1.44,19.35],[1,1.23,6.46],[2,1.22,909.09]],"ltp":0.0,"tv":0.0,"id":23387705}]}]}
{"op":"mcm","clk":"11945566851","pt":1724457639656,"mc":[{"id":"1.232012908","rc":[{"batb":[[0,1.23,5.78],[1,1.22,909.09],[2,1.04,1.53]],"ltp":0.0,"tv":0.0,"id":35736916},{"batb":[[0,1.23,6.46],[1,1.22,909.09],[2,1.04,1.53]],"ltp":0.0,"tv":0.0,"id":23387705}]}]}
{"op":"mcm","clk":"11945571513","pt":1724457716358,"mc":[{"id":"1.232012908","rc":[{"batb":[[0,1.43,19.8],[1,1.23,5.78],[2,1.22,909.09]],"ltp":0.0,"tv":0.0,"id":35736916},{"batb":[[0,1.44,19.35],[1,1.23,6.46],[2,1.22,909.09]],"ltp":0.0,"tv":0.0,"id":23387705}]}]}
{"op":"mcm","clk":"11945683805","pt":1724459516832,"mc":[{"id":"1.232012908","rc":[{"batb":[[0,1.23,5.78],[1,1.22,909.09],[2,1.04,1.53]],"ltp":0.0,"tv":0.0,"id":35736916},{"batb":[[0,1.23,6.46],[1,1.22,909.09],[2,1.04,1.53]],"ltp":0.0,"tv":0.0,"id":23387705}]}]}
{"op":"mcm","clk":"11945689948","pt":1724459590484,"mc":[{"id":"1.232012908","rc":[{"batb":[[0,1.24,35.48],[1,1.23,5.78],[2,1.22,909.09]],"ltp":0.0,"tv":0.0,"id":35736916},{"batb":[[0,1.24,35.48],[1,1.23,6.46],[2,1.22,909.09]],"ltp":0.0,"tv":0.0,"id":23387705}]}]}
{"op":"mcm","clk":"11945724266","pt":1724460038330,"mc":[{"id":"1.232012908","rc":[{"batb":[[0,1.25,5.78],[1,1.24,35.48]],"ltp":0.0,"tv":0.0,"id":35736916},{"batb":[[0,1.25,6.46],[1,1.24,35.48]],"ltp":0.0,"tv":0.0,"id":23387705}]}]}
{"op":"mcm","clk":"11945843794","pt":1724461390935,"mc":[{"id":"1.232012908","rc":[{"batb":[[1,1.22,909.09],[2,1.04,1.53]],"ltp":0.0,"tv":0.0,"id":35736916},{"batb":[[1,1.22,909.09],[2,1.04,1.53]],"ltp":0.0,"tv":0.0,"id":23387705}]}]}
{"op":"mcm","clk":"11945848174","pt":1724461458901,"mc":[{"id":"1.232012908","rc":[{"batb":[[0,1.26,32.75],[1,1.25,5.78],[2,1.22,909.09]],"ltp":0.0,"tv":0.0,"id":35736916},{"batb":[[0,1.26,32.75],[1,1.25,6.46],[2,1.22,909.09]],"ltp":0.0,"tv":0.0,"id":23387705}]}]}
{"op":"mcm","clk":"11945955626","pt":1724463259303,"mc":[{"id":"1.232012908","rc":[{"batb":[[0,1.25,5.78],[1,1.22,909.09],[2,1.04,1.53]],"ltp":0.0,"tv":0.0,"id":35736916},{"batb":[[0,1.25,6.46],[1,1.22,909.09],[2,1.04,1.53]],"ltp":0.0,"tv":0.0,"id":23387705}]}]}
{"op":"mcm","clk":"11945960158","pt":1724463323855,"mc":[{"id":"1.232012908","rc":[{"batb":[[0,1.26,32.75],[1,1.25,5.78],[2,1.22,909.09]],"ltp":0.0,"tv":0.0,"id":35736916},{"batb":[[0,1.26,32.75],[1,1.25,6.46],[2,1.22,909.09]],"ltp":0.0,"tv":0.0,"id":23387705}]}]}
{"op":"mcm","clk":"11946064178","pt":1724465124272,"mc":[{"id":"1.232012908","rc":[{"batb":[[0,1.25,5.78],[1,1.22,909.09],[2,1.04,1.53]],"ltp":0.0,"tv":0.0,"id":35736916},{"batb":[[0,1.25,6.46],[1,1.22,909.09],[2,1.04,1.53]],"ltp":0.0,"tv":0.0,"id":23387705}]}]}
{"op":"mcm","clk":"11946067638","pt":1724465179533,"mc":[{"id":"1.232012908","rc":[{"batb":[[0,1.26,32.75],[1,1.25,5.78],[2,1.22,909.09]],"ltp":0.0,"tv":0.0,"id":35736916},{"batb":[[0,1.26,32.75],[1,1.25,6.46],[2,1.22,909.09]],"ltp":0.0,"tv":0.0,"id":23387705}]}]}
{"op":"mcm","clk":"11946145684","pt":1724466141353,"mc":[{"id":"1.232012908","rc":[{"batb":[[1,1.22,909.09],[2,1.04,1.53]],"ltp":0.0,"tv":0.0,"id":23387705}]}]}
{"op":"mcm","clk":"11946145716","pt":1724466141919,"mc":[{"id":"1.232012908","rc":[{"batb":[[0,1.27,5.78],[1,1.26,32.75]],"ltp":0.0,"tv":0.0,"id":35736916},{"batb":[[0,1.27,6.46],[1,1.26,32.75],[2,1.22,909.09]],"ltp":0.0,"tv":0.0,"id":23387705}]}]}
{"op":"mcm","clk":"11946186267","pt":1724466980044,"mc":[{"id":"1.232012908","rc":[{"batb":[[1,1.22,909.09],[2,1.04,1.53]],"ltp":0.0,"tv":0.0,"id":35736916},{"batb":[[1,1.22,909.09],[2,1.04,1.53]],"ltp":0.0,"tv":0.0,"id":23387705}]}]}
{"op":"mcm","clk":"11946187897","pt":1724467017086,"mc":[{"id":"1.232012908","rc":[{"batb":[[0,1.28,30.41],[1,1.27,5.78],[2,1.22,909.09]],"ltp":0.0,"tv":0.0,"id":35736916},{"batb":[[0,1.28,30.41],[1,1.27,6.46],[2,1.22,909.09]],"ltp":0.0,"tv":0.0,"id":23387705}]}]}
{"op":"mcm","clk":"11946204029","pt":1724467354866,"mc":[{"id":"1.232012908","rc":[{"batb":[[2,1.04,1.53]],"ltp":0.0,"tv":0.0,"id":35736916},{"batb":[[2,1.04,1.53]],"ltp":0.0,"tv":0.0,"id":23387705}]}]}
{"op":"mcm","clk":"11946270601","pt":1724468817368,"mc":[{"id":"1.232012908","rc":[{"batb":[[0,1.27,5.78],[1,1.04,1.53],[2,1.03,200]],"ltp":0.0,"tv":0.0,"id":35736916},{"batb":[[0,1.27,6.46],[1,1.04,1.53],[2,1.03,200]],"ltp":0.0,"tv":0.0,"id":23387705}]}]}
{"op":"mcm","clk":"11946271847","pt":1724468845398,"mc":[{"id":"1.232012908","rc":[{"batb":[[0,1.28,30.41],[1,1.27,5.78],[2,1.04,1.53]],"ltp":0.0,"tv":0.0,"id":35736916},{"batb":[[0,1.28,30.41],[1,1.27,6.46],[2,1.04,1.53]],"ltp":0.0,"tv":0.0,"id":23387705}]}]}
{"op":"mcm","clk":"11946345193","pt":1724470310689,"mc":[{"id":"1.232012908","rc":[{"batl":[[0,3.5,0.93]],"ltp":0.0,"tv":0.0,"id":35736916}]}]}
{"op":"mcm","clk":"11946345645","pt":1724470321711,"mc":[{"id":"1.232012908","rc":[{"batl":[[0,3.4,0.93]],"ltp":0.0,"tv":0.0,"id":23387705}]}]}
{"op":"mcm","clk":"11946359914","pt":1724470645773,"mc":[{"id":"1.232012908","rc":[{"batb":[[0,1.27,5.78],[1,1.04,1.53],[2,1.03,200]],"ltp":0.0,"tv":0.0,"id":35736916},{"batb":[[0,1.27,6.46],[1,1.04,1.53],[2,1.03,200]],"ltp":0.0,"tv":0.0,"id":23387705}]}]}
{"op":"mcm","clk":"11946360579","pt":1724470661821,"mc":[{"id":"1.232012908","rc":[{"batb":[[0,1.42,20.27],[1,1.27,5.78],[2,1.04,1.53]],"ltp":0.0,"tv":0.0,"id":35736916},{"batb":[[0,1.41,20.77],[1,1.27,6.46],[2,1.04,1.53]],"ltp":0.0,"tv":0.0,"id":23387705}]}]}
{"op":"mcm","clk":"11946460058","pt":1724472261235,"mc":[{"id":"1.232012908","rc":[{"batb":[[1,1.04,1.53],[2,1.03,200]],"ltp":0.0,"tv":0.0,"id":23387705}]}]}
{"op":"mcm","clk":"11946460075","pt":1724472261541,"mc":[{"id":"1.232012908","rc":[{"batb":[[1,1.04,1.53],[2,1.03,200]],"ltp":0.0,"tv":0.0,"id":35736916}]}]}
{"op":"mcm","clk":"11946471733","pt":1724472462348,"mc":[{"id":"1.232012908","rc":[{"batb":[[0,1.04,1.53],[1,1.03,200],[2,1.02,200]],"ltp":0.0,"tv":0.0,"id":35736916},{"batb":[[0,1.04,1.53],[1,1.03,200],[2,1.02,200]],"ltp":0.0,"tv":0.0,"id":23387705}]}]}
{"op":"mcm","clk":"11946472198","pt":1724472472983,"mc":[{"id":"1.232012908","rc":[{"batb":[[0,1.42,20.27],[1,1.04,1.53],[2,1.03,200]],"ltp":0.0,"tv":0.0,"id":35736916},{"batb":[[0,1.41,20.77],[1,1.04,1.53],[2,1.03,200]],"ltp":0.0,"tv":0.0,"id":23387705}]}]}
{"op":"mcm","clk":"11946524102","pt":1724473788192,"mc":[{"id":"1.232012908","rc":[{"batb":[[1,1.25,864],[2,1.04,1.53]],"ltp":0.0,"tv":0.0,"id":35736916},{"batb":[[1,1.25,864],[2,1.04,1.53]],"ltp":0.0,"tv":0.0,"id":23387705}]}]}
{"op":"mcm","clk":"11946544232","pt":1724474273263,"mc":[{"id":"1.232012908","rc":[{"batb":[[0,1.25,864],[1,1.04,1.53],[2,1.03,200]],"ltp":0.0,"tv":0.0,"id":23387705}]}]}
{"op":"mcm","clk":"11946544240","pt":1724474273467,"mc":[{"id":"1.232012908","rc":[{"batb":[[0,1.25,864],[1,1.04,1.53],[2,1.03,200]],"ltp":0.0,"tv":0.0,"id":35736916}]}]}
{"op":"mcm","clk":"11946544409","pt":1724474277869,"mc":[{"id":"1.232012908","rc":[{"batb":[[0,1.42,20.27],[1,1.25,864],[2,1.04,1.53]],"ltp":0.0,"tv":0.0,"id":35736916},{"batb":[[0,1.41,20.77],[1,1.25,864],[2,1.04,1.53]],"ltp":0.0,"tv":0.0,"id":23387705}]}]}
{"op":"mcm","clk":"11946616446","pt":1724476078298,"mc":[{"id":"1.232012908","rc":[{"batb":[[0,1.25,864],[1,1.04,1.53],[2,1.03,200]],"ltp":0.0,"tv":0.0,"id":35736916},{"batb":[[0,1.25,864],[1,1.04,1.53],[2,1.03,200]],"ltp":0.0,"tv":0.0,"id":23387705}]}]}
{"op":"mcm","clk":"11946629111","pt":1724476301386,"mc":[{"id":"1.232012908","rc":[{"batb":[[0,1.42,20.27],[1,1.25,864],[2,1.04,1.53]],"ltp":0.0,"tv":0.0,"id":35736916},{"batb":[[0,1.41,20.77],[1,1.25,864],[2,1.04,1.53]],"ltp":0.0,"tv":0.0,"id":23387705}]}]}
{"op":"mcm","clk":"11946744858","pt":1724478101687,"mc":[{"id":"1.232012908","rc":[{"batb":[[0,1.25,864],[1,1.04,1.53],[2,1.03,200]],"ltp":0.0,"tv":0.0,"id":35736916},{"batb":[[0,1.25,864],[1,1.04,1.53],[2,1.03,200]],"ltp":0.0,"tv":0.0,"id":23387705}]}]}
{"op":"mcm","clk":"11946755261","pt":1724478324371,"mc":[{"id":"1.232012908","rc":[{"batb":[[0,1.41,20.77],[1,1.25,864],[2,1.04,1.53]],"ltp":0.0,"tv":0.0,"id":23387705}]}]}
{"op":"mcm","clk":"11946755268","pt":1724478324476,"mc":[{"id":"1.232012908","rc":[{"batb":[[0,1.42,20.27],[1,1.25,864],[2,1.04,1.53]],"ltp":0.0,"tv":0.0,"id":35736916}]}]}
{"op":"mcm","clk":"11946765781","pt":1724478547134,"mc":[{"id":"1.232012908","rc":[{"batb":[[1,1.26,6.3],[2,1.25,864]],"ltp":0.0,"tv":0.0,"id":23387705}]}]}
{"op":"mcm","clk":"11946765796","pt":1724478547440,"mc":[{"id":"1.232012908","rc":[{"batb":[[1,1.26,6.06],[2,1.25,864]],"ltp":0.0,"tv":0.0,"id":35736916}]}]}
{"op":"mcm","clk":"11946838136","pt":1724480124833,"mc":[{"id":"1.232012908","rc":[{"batb":[[0,1.26,6.06],[1,1.25,864],[2,1.04,1.53]],"ltp":0.0,"tv":0.0,"id":35736916},{"batb":[[0,1.26,6.3],[1,1.25,864],[2,1.04,1.53]],"ltp":0.0,"tv":0.0,"id":23387705}]}]}
{"op":"mcm","clk":"11946849904","pt":1724480335495,"mc":[{"id":"1.232012908","rc":[{"batb":[[0,1.42,20.27],[1,1.26,6.06],[2,1.25,864]],"ltp":0.0,"tv":0.0,"id":35736916},{"batb":[[0,1.41,20.77],[1,1.26,6.3],[2,1.25,864]],"ltp":0.0,"tv":0.0,"id":23387705}]}]}
{"op":"mcm","clk":"11946967682","pt":1724482136664,"mc":[{"id":"1.232012908","rc":[{"batb":[[0,1.26,6.06],[1,1.25,864],[2,1.04,1.53]],"ltp":0.0,"tv":0.0,"id":35736916},{"batb":[[0,1.26,6.3],[1,1.25,864],[2,1.04,1.53]],"ltp":0.0,"tv":0.0,"id":23387705}]}]}
{"op":"mcm","clk":"11946978553","pt":1724482338072,"mc":[{"id":"1.232012908","rc":[{"batb":[[0,1.42,20.27],[1,1.26,6.06],[2,1.25,864]],"ltp":0.0,"tv":0.0,"id":35736916},{"batb":[[0,1.41,20.77],[1,1.26,6.3],[2,1.25,864]],"ltp":0.0,"tv":0.0,"id":23387705}]}]}
{"op":"mcm","clk":"11947099154","pt":1724484138384,"mc":[{"id":"1.232012908","rc":[{"batb":[[0,1.26,6.3],[1,1.25,864],[2,1.04,1.53]],"ltp":0.0,"tv":0.0,"id":23387705}]}]}
{"op":"mcm","clk":"11947099168","pt":1724484138590,"mc":[{"id":"1.232012908","rc":[{"batb":[[0,1.26,6.06],[1,1.25,864],[2,1.04,1.53]],"ltp":0.0,"tv":0.0,"id":35736916}]}]}
{"op":"mcm","clk":"11947113058","pt":1724484341068,"mc":[{"id":"1.232012908","rc":[{"batb":[[0,1.42,20.27],[1,1.26,6.06],[2,1.25,864]],"ltp":0.0,"tv":0.0,"id":35736916},{"batb":[[0,1.41,20.77],[1,1.26,6.3],[2,1.25,864]],"ltp":0.0,"tv":0.0,"id":23387705}]}]}
{"op":"mcm","clk":"11947253710","pt":1724486141275,"mc":[{"id":"1.232012908","rc":[{"batb":[[0,1.26,6.06],[1,1.25,864],[2,1.04,1.53]],"ltp":0.0,"tv":0.0,"id":35736916}]}]}
{"op":"mcm","clk":"11947253725","pt":1724486141479,"mc":[{"id":"1.232012908","rc":[{"batb":[[0,1.26,6.3],[1,1.25,864],[2,1.04,1.53]],"ltp":0.0,"tv":0.0,"id":23387705}]}]}
{"op":"mcm","clk":"11947272250","pt":1724486348299,"mc":[{"id":"1.232012908","rc":[{"batb":[[0,1.42,20.27],[1,1.26,6.06],[2,1.25,864]],"ltp":0.0,"tv":0.0,"id":35736916},{"batb":[[0,1.41,20.77],[1,1.26,6.3],[2,1.25,864]],"ltp":0.0,"tv":0.0,"id":23387705}]}]}
{"op":"mcm","clk":"11947464307","pt":1724488148535,"mc":[{"id":"1.232012908","rc":[{"batb":[[0,1.26,6.06],[1,1.25,864],[2,1.04,1.53]],"ltp":0.0,"tv":0.0,"id":35736916},{"batb":[[0,1.26,6.31],[1,1.25,864],[2,1.04,1.53]],"ltp":0.0,"tv":0.0,"id":23387705}]}]}
{"op":"mcm","clk":"11947489157","pt":1724488348952,"mc":[{"id":"1.232012908","rc":[{"batb":[[0,1.42,20.27],[1,1.26,6.06],[2,1.25,864]],"ltp":0.0,"tv":0.0,"id":35736916},{"batb":[[0,1.41,20.77],[1,1.26,6.31],[2,1.25,864]],"ltp":0.0,"tv":0.0,"id":23387705}]}]}
{"op":"mcm","clk":"11947718109","pt":1724490149315,"mc":[{"id":"1.232012908","rc":[{"batb":[[0,1.26,6.06],[1,1.25,864],[2,1.04,1.53]],"ltp":0.0,"tv":0.0,"id":35736916},{"batb":[[0,1.26,6.31],[1,1.25,864],[2,1.04,1.53]],"ltp":0.0,"tv":0.0,"id":23387705}]}]}
{"op":"mcm","clk":"11947745983","pt":1724490351065,"mc":[{"id":"1.232012908","rc":[{"batb":[[0,1.42,20.27],[1,1.26,6.06],[2,1.25,864]],"ltp":0.0,"tv":0.0,"id":35736916},{"batb":[[0,1.41,20.77],[1,1.26,6.31],[2,1.25,864]],"ltp":0.0,"tv":0.0,"id":23387705}]}]}
{"op":"mcm","clk":"11948015615","pt":1724492151327,"mc":[{"id":"1.232012908","rc":[{"batb":[[0,1.26,6.06],[1,1.25,864],[2,1.04,1.53]],"ltp":0.0,"tv":0.0,"id":35736916},{"batb":[[0,1.26,6.31],[1,1.25,864],[2,1.04,1.53]],"ltp":0.0,"tv":0.0,"id":23387705}]}]}
{"op":"mcm","clk":"11948045453","pt":1724492346947,"mc":[{"id":"1.232012908","rc":[{"batb":[[0,1.42,20.27],[1,1.26,6.06],[2,1.25,864]],"ltp":0.0,"tv":0.0,"id":35736916},{"batb":[[0,1.41,20.77],[1,1.26,6.31],[2,1.25,864]],"ltp":0.0,"tv":0.0,"id":23387705}]}]}
{"op":"mcm","clk":"11948199315","pt":1724493187022,"mc":[{"id":"1.232012908","rc":[{"batl":[[0,3.4,3.39]],"ltp":0.0,"tv":0.0,"id":23387705}]}]}
{"op":"mcm","clk":"11948200543","pt":1724493196850,"mc":[{"id":"1.232012908","rc":[{"batl":[[0,3.45,3.39]],"ltp":0.0,"tv":0.0,"id":35736916}]}]}
{"op":"mcm","clk":"11948357493","pt":1724494147348,"mc":[{"id":"1.232012908","rc":[{"batb":[[0,1.26,6.06],[1,1.25,864],[2,1.04,1.53]],"ltp":0.0,"tv":0.0,"id":35736916},{"batb":[[0,1.26,6.31],[1,1.25,864],[2,1.04,1.53]],"ltp":0.0,"tv":0.0,"id":23387705}]}]}
{"op":"mcm","clk":"11948399260","pt":1724494342083,"mc":[{"id":"1.232012908","rc":[{"batb":[[0,1.42,20.27],[1,1.26,6.06],[2,1.25,864]],"ltp":0.0,"tv":0.0,"id":35736916},{"batb":[[0,1.41,20.77],[1,1.26,6.31],[2,1.25,864]],"ltp":0.0,"tv":0.0,"id":23387705}]}]}
{"op":"mcm","clk":"11948755739","pt":1724496142307,"mc":[{"id":"1.232012908","rc":[{"batb":[[0,1.26,6.06],[1,1.25,864],[2,1.04,1.53]],"ltp":0.0,"tv":0.0,"id":35736916}]}]}
{"op":"mcm","clk":"11948755779","pt":1724496142470,"mc":[{"id":"1.232012908","rc":[{"batb":[[0,1.26,6.31],[1,1.25,864],[2,1.04,1.53]],"ltp":0.0,"tv":0.0,"id":23387705}]}]}
{"op":"mcm","clk":"11948792383","pt":1724496324813,"mc":[{"id":"1.232012908","rc":[{"batb":[[0,1.42,20.27],[1,1.26,6.06],[2,1.25,864]],"ltp":0.0,"tv":0.0,"id":35736916},{"batb":[[0,1.41,20.77],[1,1.26,6.31],[2,1.25,864]],"ltp":0.0,"tv":0.0,"id":23387705}]}]}
{"op":"mcm","clk":"11949156795","pt":1724498125199,"mc":[{"id":"1.232012908","rc":[{"batb":[[0,1.26,6.06],[1,1.25,864],[2,1.04,1.53]],"ltp":0.0,"tv":0.0,"id":35736916},{"batb":[[0,1.26,6.31],[1,1.25,864],[2,1.04,1.53]],"ltp":0.0,"tv":0.0,"id":23387705}]}]}
{"op":"mcm","clk":"11949179298","pt":1724498235020,"mc":[{"id":"1.232012908","rc":[{"batl":[[1,4.9,10.86]],"ltp":0.0,"tv":0.0,"id":35736916},{"batl":[[1,4.9,10.85]],"ltp":0.0,"tv":0.0,"id":23387705}]}]}
{"op":"mcm","clk":"11949192661","pt":1724498302346,"mc":[{"id":"1.232012908","rc":[{"batb":[[0,1.42,20.27],[1,1.26,6.06],[2,1.25,864]],"ltp":0.0,"tv":0.0,"id":35736916},{"batb":[[0,1.41,20.77],[1,1.26,6.31],[2,1.25,864]],"ltp":0.0,"tv":0.0,"id":23387705}]}]}
{"op":"mcm","clk":"11949193422","pt":1724498306305,"mc":[{"id":"1.232012908","rc":[{"batl":[[1,4.9,0]],"ltp":0.0,"tv":0.0,"id":35736916},{"batl":[[1,4.9,0]],"ltp":0.0,"tv":0.0,"id":23387705}]}]}
{"op":"mcm","clk":"11949592933","pt":1724500102682,"mc":[{"id":"1.232012908","rc":[{"batb":[[0,1.26,6.06],[1,1.25,864],[2,1.04,1.53]],"ltp":0.0,"tv":0.0,"id":35736916},{"batb":[[0,1.26,6.31],[1,1.25,864],[2,1.04,1.53]],"ltp":0.0,"tv":0.0,"id":23387705}]}]}
{"op":"mcm","clk":"11949624512","pt":1724500263692,"mc":[{"id":"1.232012908","rc":[{"batb":[[0,1.42,20.27],[1,1.26,6.06],[2,1.25,864]],"ltp":0.0,"tv":0.0,"id":35736916},{"batb":[[0,1.41,20.77],[1,1.26,6.31],[2,1.25,864]],"ltp":0.0,"tv":0.0,"id":23387705}]}]}
{"op":"mcm","clk":"11949713064","pt":1724500808572,"mc":[{"id":"1.232012908","rc":[{"batb":[[0,2.02,38.11],[1,1.42,20.27],[2,1.26,6.06]],"ltp":0.0,"tv":0.0,"id":35736916},{"batb":[[0,1.9,43.19],[1,1.41,20.77],[2,1.26,6.31]],"ltp":0.0,"tv":0.0,"id":23387705}]}]}
{"op":"mcm","clk":"11949945754","pt":1724502064097,"mc":[{"id":"1.232012908","rc":[{"batb":[[1,1.26,6.06],[2,1.25,864]],"ltp":0.0,"tv":0.0,"id":35736916},{"batb":[[1,1.26,6.31],[2,1.25,864]],"ltp":0.0,"tv":0.0,"id":23387705}]}]}
{"op":"mcm","clk":"11950158858","pt":1724503231999,"mc":[{"id":"1.232012908","rc":[{"batb":[[1,1.25,864],[2,1.04,1.53]],"ltp":0.0,"tv":0.0,"id":35736916},{"batb":[[1,1.25,864],[2,1.04,1.53]],"ltp":0.0,"tv":0.0,"id":23387705}]}]}
{"op":"mcm","clk":"11950794494","pt":1724506515849,"mc":[{"id":"1.232012908","rc":[{"batb":[[0,2.02,42.1]],"ltp":0.0,"tv":0.0,"id":35736916},{"batb":[[0,1.9,47.72]],"ltp":0.0,"tv":0.0,"id":23387705}]}]}
{"op":"mcm","clk":"11958068373","pt":1724568634236,"mc":[{"id":"1.232012908","rc":[{"trd":[[1.9,4.3]],"batb":[[0,1.9,45.57]],"ltp":1.9,"tv":4.3,"id":23387705}],"tv":4.3}]}
{"op":"mcm","clk":"11958068649","pt":1724568638028,"mc":[{"id":"1.232012908","rc":[{"batb":[[0,1.9,47.72]],"ltp":1.9,"tv":4.3,"id":23387705}]}]}
{"op":"mcm","clk":"11958989970","pt":1724578498500,"mc":[{"id":"1.232012908","rc":[{"batb":[[1,1.74,17.32],[2,1.25,864]],"ltp":0.0,"tv":0.0,"id":35736916},{"batb":[[1,1.74,17.32],[2,1.25,864]],"ltp":1.9,"tv":4.3,"id":23387705}]}]}
{"op":"mcm","clk":"11959195999","pt":1724580033164,"mc":[{"id":"1.232012908","rc":[{"trd":[[2.02,84.2]],"batb":[[0,1.97,44.27],[1,1.75,29],[2,1.74,17.32]],"batl":[[0,2.02,157.9]],"ltp":2.02,"tv":84.2,"id":35736916}],"tv":88.5}]}
{"op":"mcm","clk":"11959196398","pt":1724580036178,"mc":[{"id":"1.232012908","rc":[{"batb":[[1,1.75,24]],"ltp":2.02,"tv":84.2,"id":35736916}]}]}
{"op":"mcm","clk":"11959196492","pt":1724580036858,"mc":[{"id":"1.232012908","rc":[{"trd":[[1.97,88.54]],"batb":[[0,1.75,24],[1,1.74,17.32],[2,1.25,864]],"batl":[[0,1.97,155.73],[1,2.02,157.9]],"ltp":1.97,"tv":172.74,"id":35736916}],"tv":177.04}]}
{"op":"mcm","clk":"11959197685","pt":1724580046173,"mc":[{"id":"1.232012908","rc":[{"batl":[[0,1.9,300],[1,1.97,155.73],[2,2.02,157.9]],"ltp":1.97,"tv":172.74,"id":35736916}]}]}
{"op":"mcm","clk":"11959198724","pt":1724580053680,"mc":[{"id":"1.232012908","rc":[{"trd":[[1.9,195.84]],"batl":[[0,1.9,104.16]],"ltp":1.9,"tv":368.58,"id":35736916},{"trd":[[2.1,177.19]],"ltp":2.1,"tv":181.48,"id":23387705}],"tv":550.06}]}
{"op":"mcm","clk":"11959199506","pt":1724580060701,"mc":[{"id":"1.232012908","rc":[{"trd":[[1.9,293.76]],"batl":[[0,1.9,6.24]],"ltp":1.9,"tv":466.5,"id":35736916},{"trd":[[2.1,265.78]],"ltp":2.1,"tv":270.08,"id":23387705}],"tv":736.58}]}
{"op":"mcm","clk":"11959259818","pt":1724580510151,"mc":[{"id":"1.232012908","rc":[{"trd":[[1.9,306.24],[1.97,91.44]],"batl":[[0,1.97,154.28],[1,2.02,157.9],[2,2.02,0]],"ltp":1.97,"tv":481.88,"id":35736916}],"tv":751.96}]}
{"op":"mcm","clk":"11959361346","pt":1724581172916,"mc":[{"id":"1.232012908","rc":[{"batl":[[0,1.96,11.59],[1,1.97,154.28],[2,2.02,157.9]],"ltp":1.97,"tv":481.88,"id":35736916}]}]}
{"op":"mcm","clk":"11959370564","pt":1724581232089,"mc":[{"id":"1.232012908","rc":[{"batb":[[0,2.04,11.3],[1,1.9,47.72],[2,1.74,17.32]],"ltp":2.1,"tv":270.08,"id":23387705}]}]}
{"op":"mcm","clk":"11959412449","pt":1724581504102,"mc":[{"id":"1.232012908","rc":[{"trd":[[1.75,4]],"batb":[[0,1.74,17.32],[1,1.25,864],[2,1.04,1.53]],"ltp":1.75,"tv":485.88,"id":35736916}],"tv":755.96}]}
{"op":"mcm","clk":"11959518780","pt":1724582179918,"mc":[{"id":"1.232012908","rc":[{"batl":[[0,1.96,19.74]],"ltp":1.75,"tv":485.88,"id":35736916}]}]}
{"op":"mcm","clk":"11959697159","pt":1724583355829,"mc":[{"id":"1.232012908","rc":[{"batb":[[0,2.04,18]],"ltp":2.1,"tv":270.08,"id":23387705}]}]}
{"op":"mcm","clk":"11959807055","pt":1724584018771,"mc":[{"id":"1.232012908","rc":[{"trd":[[1.96,20.62]],"batl":[[0,1.96,9.42]],"ltp":1.96,"tv":506.5,"id":35736916}],"tv":776.58}]}
{"op":"mcm","clk":"11959941792","pt":1724584637223,"mc":[{"id":"1.232012908","rc":[{"trd":[[1.74,33.52]],"batb":[[0,1.36,141.41]],"ltp":1.74,"tv":540.02,"id":35736916}],"tv":810.1}]}
{"op":"mcm","clk":"11959948410","pt":1724584671154,"mc":[{"id":"1.232012908","rc":[{"batb":[[0,1.38,156.37],[1,1.36,140.85],[2,1.25,864]],"ltp":1.74,"tv":540.02,"id":35736916}]}]}
{"op":"mcm","clk":"11959991400","pt":1724584882817,"mc":[{"id":"1.232012908","rc":[{"trd":[[1.74,34.64]],"batb":[[0,1.36,141.41],[1,1.25,864],[2,1.04,1.53]],"ltp":1.74,"tv":541.14,"id":35736916}],"tv":811.22}]}
{"op":"mcm","clk":"11959998671","pt":1724584916867,"mc":[{"id":"1.232012908","rc":[{"batb":[[0,1.36,140.85]],"ltp":1.74,"tv":541.14,"id":35736916}]}]}
{"op":"mcm","clk":"11960295530","pt":1724586418626,"mc":[{"id":"1.232012908","rc":[{"batb":[[0,1.38,16.76],[1,1.36,140.85],[2,1.25,864]],"ltp":1.74,"tv":541.14,"id":35736916}]}]}
{"op":"mcm","clk":"11960303096","pt":1724586463295,"mc":[{"id":"1.232012908","rc":[{"trd":[[1.96,36.94]],"batb":[[1,1.25,864],[2,1.04,1.53]],"batl":[[0,1.96,1.26]],"ltp":1.96,"tv":557.46,"id":35736916}],"tv":827.54}]}
{"op":"mcm","clk":"11960303121","pt":1724586463460,"mc":[{"id":"1.232012908","rc":[{"batb":[[0,1.4,136.77],[1,1.38,16.76],[2,1.25,864]],"ltp":1.96,"tv":557.46,"id":35736916}]}]}
{"op":"mcm","clk":"11960303456","pt":1724586465456,"mc":[{"id":"1.232012908","rc":[{"batb":[[0,1.41,16.11],[1,1.4,136.77],[2,1.38,16.76]],"ltp":1.96,"tv":557.46,"id":35736916}]}]}
{"op":"mcm","clk":"11960337720","pt":1724586676290,"mc":[{"id":"1.232012908","rc":[{"batb":[[0,1.41,26.38],[1,1.38,16.76],[2,1.25,864]],"ltp":1.96,"tv":557.46,"id":35736916}]}]}
{"op":"mcm","clk":"11960337756","pt":1724586676456,"mc":[{"id":"1.232012908","rc":[{"batb":[[0,1.42,134.82],[1,1.41,26.38],[2,1.38,16.76]],"ltp":1.96,"tv":557.46,"id":35736916}]}]}
{"op":"mcm","clk":"11960337999","pt":1724586678282,"mc":[{"id":"1.232012908","rc":[{"batb":[[1,1.38,16.76],[2,1.25,864]],"ltp":1.96,"tv":557.46,"id":35736916}]}]}
{"op":"mcm","clk":"11960338023","pt":1724586678493,"mc":[{"id":"1.232012908","rc":[{"batb":[[0,1.43,15.88],[1,1.42,134.82],[2,1.38,16.76]],"ltp":1.96,"tv":557.46,"id":35736916}]}]}
{"op":"mcm","clk":"11960345054","pt":1724586722101,"mc":[{"id":"1.232012908","rc":[{"batb":[[0,1.52,125.83],[1,1.43,15.88]],"ltp":1.96,"tv":557.46,"id":35736916}]}]}
{"op":"mcm","clk":"11960345225","pt":1724586723137,"mc":[{"id":"1.232012908","rc":[{"batb":[[0,1.53,14.84],[1,1.52,125.83]],"ltp":1.96,"tv":557.46,"id":35736916}]}]}
{"op":"mcm","clk":"11960377175","pt":1724586933818,"mc":[{"id":"1.232012908","rc":[{"batb":[[0,1.54,124.17],[1,1.53,24.29]],"ltp":1.96,"tv":557.46,"id":35736916}]}]}
{"op":"mcm","clk":"11960377530","pt":1724586936326,"mc":[{"id":"1.232012908","rc":[{"batb":[[0,1.55,14.65],[1,1.54,124.17]],"ltp":1.96,"tv":557.46,"id":35736916}]}]}
{"op":"mcm","clk":"11960381397","pt":1724586960360,"mc":[{"id":"1.232012908","rc":[{"batb":[[0,1.56,122.56],[1,1.55,14.65]],"ltp":1.96,"tv":557.46,"id":35736916}]}]}
{"op":"mcm","clk":"11960381775","pt":1724586962392,"mc":[{"id":"1.232012908","rc":[{"batb":[[1,1.38,16.76],[2,1.25,864]],"ltp":1.96,"tv":557.46,"id":35736916}]}]}
{"op":"mcm","clk":"11960381793","pt":1724586962445,"mc":[{"id":"1.232012908","rc":[{"batb":[[0,1.57,14.46],[1,1.56,122.56],[2,1.38,16.76]],"ltp":1.96,"tv":557.46,"id":35736916}]}]}
{"op":"mcm","clk":"11960413106","pt":1724587173389,"mc":[{"id":"1.232012908","rc":[{"batb":[[0,1.57,23.66],[1,1.38,16.76],[2,1.25,864]],"ltp":1.96,"tv":557.46,"id":35736916}]}]}
{"op":"mcm","clk":"11960413136","pt":1724587173592,"mc":[{"id":"1.232012908","rc":[{"batb":[[0,1.58,120.99],[1,1.57,23.66],[2,1.38,16.76]],"ltp":1.96,"tv":557.46,"id":35736916}]}]}
{"op":"mcm","clk":"11960413319","pt":1724587174877,"mc":[{"id":"1.232012908","rc":[{"batb":[[0,1.59,14.28],[1,1.58,120.99]],"ltp":1.96,"tv":557.46,"id":35736916}]}]}
{"op":"mcm","clk":"11960415176","pt":1724587187692,"mc":[{"id":"1.232012908","rc":[{"batb":[[0,1.6,119.46],[1,1.59,14.28]],"ltp":1.96,"tv":557.46,"id":35736916}]}]}
{"op":"mcm","clk":"11960415312","pt":1724587188733,"mc":[{"id":"1.232012908","rc":[{"batb":[[1,1.38,16.76],[2,1.25,864]],"ltp":1.96,"tv":557.46,"id":35736916}]}]}
{"op":"mcm","clk":"11960416694","pt":1724587198105,"mc":[{"id":"1.232012908","rc":[{"batb":[[0,1.61,14.1],[1,1.6,119.46],[2,1.38,16.76]],"ltp":1.96,"tv":557.46,"id":35736916}]}]}
{"op":"mcm","clk":"11960451199","pt":1724587399361,"mc":[{"id":"1.232012908","rc":[{"batb":[[0,1.61,23.08]],"ltp":1.96,"tv":557.46,"id":35736916}]}]}
{"op":"mcm","clk":"11960451274","pt":1724587399764,"mc":[{"id":"1.232012908","rc":[{"batb":[[0,1.62,92.82],[1,1.61,23.08]],"ltp":1.96,"tv":557.46,"id":35736916}]}]}
{"op":"mcm","clk":"11960451701","pt":1724587401957,"mc":[{"id":"1.232012908","rc":[{"batb":[[0,1.63,13.93],[1,1.62,92.82]],"ltp":1.96,"tv":557.46,"id":35736916}]}]}
{"op":"mcm","clk":"11960454699","pt":1724587419111,"mc":[{"id":"1.232012908","rc":[{"batb":[[0,1.64,68.39],[1,1.63,13.93]],"ltp":1.96,"tv":557.46,"id":35736916}]}]}
{"op":"mcm","clk":"11960455161","pt":1724587421901,"mc":[{"id":"1.232012908","rc":[{"batb":[[0,1.65,13.76],[1,1.64,68.39]],"ltp":1.96,"tv":557.46,"id":35736916}]}]}
{"op":"mcm","clk":"11960494243","pt":1724587633024,"mc":[{"id":"1.232012908","rc":[{"batb":[[0,1.66,67.56],[1,1.65,18.9]],"ltp":1.96,"tv":557.46,"id":35736916}]}]}
{"op":"mcm","clk":"11960494783","pt":1724587635321,"mc":[{"id":"1.232012908","rc":[{"batb":[[0,1.67,13.6],[1,1.66,67.56]],"ltp":1.96,"tv":557.46,"id":35736916}]}]}
{"op":"mcm","clk":"11960498680","pt":1724587654172,"mc":[{"id":"1.232012908","rc":[{"batb":[[0,1.68,44.22],[1,1.67,13.6]],"ltp":1.96,"tv":557.46,"id":35736916}]}]}
{"op":"mcm","clk":"11960498931","pt":1724587655238,"mc":[{"id":"1.232012908","rc":[{"batb":[[0,1.69,13.43],[1,1.68,44.22]],"ltp":1.96,"tv":557.46,"id":35736916}]}]}
{"op":"mcm","clk":"11960536418","pt":1724587852216,"mc":[{"id":"1.232012908","rc":[{"batb":[[0,1.7,236.03],[1,1.69,13.43]],"ltp":1.96,"tv":557.46,"id":35736916}]}]}
{"op":"mcm","clk":"11960536594","pt":1724587853045,"mc":[{"id":"1.232012908","rc":[{"batb":[[0,1.71,13.28],[1,1.7,236.03]],"ltp":1.96,"tv":557.46,"id":35736916}]}]}
{"op":"mcm","clk":"11960540767","pt":1724587874915,"mc":[{"id":"1.232012908","rc":[{"batb":[[1,1.7,215.81]],"ltp":1.96,"tv":557.46,"id":35736916}]}]}
{"op":"mcm","clk":"11960542088","pt":1724587881323,"mc":[{"id":"1.232012908","rc":[{"batb":[[0,1.72,215.81],[1,1.38,16.76],[2,1.25,864]],"ltp":1.96,"tv":557.46,"id":35736916}]}]}
{"op":"mcm","clk":"11960542110","pt":1724587881432,"mc":[{"id":"1.232012908","rc":[{"batb":[[0,1.73,13.13],[1,1.72,215.81],[2,1.38,16.76]],"ltp":1.96,"tv":557.46,"id":35736916}]}]}
{"op":"mcm","clk":"11960551657","pt":1724587925843,"mc":[{"id":"1.232012908","rc":[{"batb":[[0,1.75,215.81],[1,1.73,13.13]],"ltp":1.96,"tv":557.46,"id":35736916}]}]}
{"op":"mcm","clk":"11960551991","pt":1724587926951,"mc":[{"id":"1.232012908","rc":[{"batb":[[0,1.76,12.9],[1,1.75,215.81]],"ltp":1.96,"tv":557.46,"id":35736916}]}]}
{"op":"mcm","clk":"11960563904","pt":1724587972927,"mc":[{"id":"1.232012908","rc":[{"batb":[[0,1.8,215.81],[1,1.76,12.9]],"ltp":1.96,"tv":557.46,"id":35736916}]}]}
{"op":"mcm","clk":"11960564241","pt":1724587974715,"mc":[{"id":"1.232012908","rc":[{"batb":[[0,1.81,12.54],[1,1.8,215.81]],"ltp":1.96,"tv":557.46,"id":35736916}]}]}
{"op":"mcm","clk":"11960569083","pt":1724588001259,"mc":[{"id":"1.232012908","rc":[{"batb":[[0,1.38,16.76],[1,1.25,864],[2,1.04,1.53]],"ltp":1.96,"tv":557.46,"id":35736916}]}]}
{"op":"mcm","clk":"11960569114","pt":1724588001466,"mc":[{"id":"1.232012908","rc":[{"batb":[[0,1.4,136.77],[1,1.38,16.76],[2,1.25,864]],"ltp":1.96,"tv":557.46,"id":35736916}]}]}
{"op":"mcm","clk":"11960569403","pt":1724588002954,"mc":[{"id":"1.232012908","rc":[{"batb":[[0,1.41,16.11],[1,1.4,136.77],[2,1.38,16.76]],"ltp":1.96,"tv":557.46,"id":35736916}]}]}
{"op":"mcm","clk":"11960573357","pt":1724588024849,"mc":[{"id":"1.232012908","rc":[{"batb":[[0,1.8,197.31],[1,1.41,16.11]],"ltp":1.96,"tv":557.46,"id":35736916}]}]}
{"op":"mcm","clk":"11960573457","pt":1724588025584,"mc":[{"id":"1.232012908","rc":[{"batb":[[1,1.38,16.76],[2,1.25,864]],"ltp":1.96,"tv":557.46,"id":35736916}]}]}
{"op":"mcm","clk":"11960578554","pt":1724588054213,"mc":[{"id":"1.232012908","rc":[{"batb":[[0,1.81,12.54],[1,1.8,197.31],[2,1.38,16.76]],"ltp":1.96,"tv":557.46,"id":35736916}]}]}
{"op":"mcm","clk":"11960585515","pt":1724588092224,"mc":[{"id":"1.232012908","rc":[{"batb":[[0,1.44,132.92],[1,1.38,16.76],[2,1.25,864]],"ltp":1.96,"tv":557.46,"id":35736916}]}]}
{"op":"mcm","clk":"11960585898","pt":1724588094271,"mc":[{"id":"1.232012908","rc":[{"batb":[[0,1.45,15.66],[1,1.44,132.92],[2,1.38,16.76]],"ltp":1.96,"tv":557.46,"id":35736916}]}]}
{"op":"mcm","clk":"11960588768","pt":1724588110679,"mc":[{"id":"1.232012908","rc":[{"batb":[[0,1.5,127.53],[1,1.45,15.66]],"ltp":1.96,"tv":557.46,"id":35736916}]}]}
{"op":"mcm","clk":"11960589024","pt":1724588112397,"mc":[{"id":"1.232012908","rc":[{"batb":[[0,1.51,15.04],[1,1.5,127.53]],"ltp":1.96,"tv":557.46,"id":35736916}]}]}
{"op":"mcm","clk":"11960594757","pt":1724588143030,"mc":[{"id":"1.232012908","rc":[{"batb":[[0,1.52,125.83],[1,1.51,21.54]],"ltp":1.96,"tv":557.46,"id":35736916}]}]}
{"op":"mcm","clk":"11960594917","pt":1724588143851,"mc":[{"id":"1.232012908","rc":[{"batb":[[0,1.53,14.84],[1,1.52,125.83],[2,1.51,6.51]],"ltp":1.96,"tv":557.46,"id":35736916}]}]}
{"op":"mcm","clk":"11960622681","pt":1724588297263,"mc":[{"id":"1.232012908","rc":[{"batb":[[1,1.51,6.51],[2,1.38,16.76]],"ltp":1.96,"tv":557.46,"id":35736916}]}]}
{"op":"mcm","clk":"11960622800","pt":1724588297896,"mc":[{"id":"1.232012908","rc":[{"batb":[[0,1.55,14.65],[1,1.54,124.17],[2,1.51,6.51]],"ltp":1.96,"tv":557.46,"id":35736916}]}]}
{"op":"mcm","clk":"11960628978","pt":1724588334219,"mc":[{"id":"1.232012908","rc":[{"batb":[[0,1.57,14.46],[1,1.56,122.56]],"ltp":1.96,"tv":557.46,"id":35736916}]}]}
{"op":"mcm","clk":"11960659240","pt":1724588501403,"mc":[{"id":"1.232012908","rc":[{"batb":[[0,1.59,120.22],[1,1.58,41.84],[2,1.57,14.46]],"ltp":1.96,"tv":557.46,"id":35736916}]}]}
{"op":"mcm","clk":"11960659603","pt":1724588503407,"mc":[{"id":"1.232012908","rc":[{"batb":[[2,1.51,6.51]],"ltp":1.96,"tv":557.46,"id":35736916}]}]}
{"op":"mcm","clk":"11960659641","pt":1724588503609,"mc":[{"id":"1.232012908","rc":[{"batb":[[0,1.6,14.19],[1,1.59,120.22],[2,1.58,41.84]],"ltp":1.96,"tv":557.46,"id":35736916}]}]}
{"op":"mcm","clk":"11960663474","pt":1724588524323,"mc":[{"id":"1.232012908","rc":[{"batb":[[2,1.51,6.51]],"ltp":1.96,"tv":557.46,"id":35736916}]}]}
{"op":"mcm","clk":"11960663529","pt":1724588524644,"mc":[{"id":"1.232012908","rc":[{"batb":[[0,1.62,92.82],[1,1.6,14.19]],"ltp":1.96,"tv":557.46,"id":35736916}]}]}
{"op":"mcm","clk":"11960663824","pt":1724588526119,"mc":[{"id":"1.232012908","rc":[{"batb":[[0,1.63,13.93],[1,1.62,92.82]],"ltp":1.96,"tv":557.46,"id":35736916}]}]}
{"op":"mcm","clk":"11960665751","pt":1724588536770,"mc":[{"id":"1.232012908","rc":[{"batb":[[0,1.64,91.68],[1,1.63,13.93]],"ltp":1.96,"tv":557.46,"id":35736916}]}]}
{"op":"mcm","clk":"11960665980","pt":1724588538078,"mc":[{"id":"1.232012908","rc":[{"batb":[[0,1.65,13.76],[1,1.64,91.68]],"ltp":1.96,"tv":557.46,"id":35736916}]}]}
{"op":"mcm","clk":"11960668053","pt":1724588549382,"mc":[{"id":"1.232012908","rc":[{"batb":[[0,1.66,67.56],[1,1.51,6.51],[2,1.5,20.92]],"ltp":1.96,"tv":557.46,"id":35736916}]}]}
{"op":"mcm","clk":"11960668081","pt":1724588549580,"mc":[{"id":"1.232012908","rc":[{"batb":[[1,1.51,21.54]],"ltp":1.96,"tv":557.46,"id":35736916}]}]}
{"op":"mcm","clk":"11960668412","pt":1724588551358,"mc":[{"id":"1.232012908","rc":[{"batb":[[1,1.51,6.51]],"ltp":1.96,"tv":557.46,"id":35736916}]}]}
{"op":"mcm","clk":"11960668445","pt":1724588551561,"mc":[{"id":"1.232012908","rc":[{"batb":[[0,1.67,13.6],[1,1.66,67.56],[2,1.51,6.51]],"ltp":1.96,"tv":557.46,"id":35736916}]}]}
{"op":"mcm","clk":"11960670593","pt":1724588564265,"mc":[{"id":"1.232012908","rc":[{"batb":[[0,1.68,44.22],[1,1.51,6.51],[2,1.5,20.92]],"ltp":1.96,"tv":557.46,"id":35736916}]}]}
{"op":"mcm","clk":"11960670638","pt":1724588564471,"mc":[{"id":"1.232012908","rc":[{"batb":[[0,1.69,13.43],[1,1.68,44.22],[2,1.51,6.51]],"ltp":1.96,"tv":557.46,"id":35736916}]}]}
{"op":"mcm","clk":"11960710597","pt":1724588789546,"mc":[{"id":"1.232012908","rc":[{"batb":[[0,1.7,20.22],[1,1.69,13.43]],"ltp":1.96,"tv":557.46,"id":35736916}]}]}
{"op":"mcm","clk":"11960710920","pt":1724588791343,"mc":[{"id":"1.232012908","rc":[{"batb":[[0,1.71,13.28],[1,1.7,20.22]],"ltp":1.96,"tv":557.46,"id":35736916}]}]}
{"op":"mcm","clk":"11960754753","pt":1724589021106,"mc":[{"id":"1.232012908","rc":[{"batb":[[1,1.51,6.51],[2,1.5,20.92]],"ltp":1.96,"tv":557.46,"id":35736916}]}]}
{"op":"mcm","clk":"11960755016","pt":1724589022322,"mc":[{"id":"1.232012908","rc":[{"batb":[[0,1.51,21.54],[1,1.5,20.92],[2,1.38,16.76]],"ltp":1.96,"tv":557.46,"id":35736916}]}]}
{"op":"mcm","clk":"11960755033","pt":1724589022421,"mc":[{"id":"1.232012908","rc":[{"batb":[[0,1.55,123.36],[1,1.51,21.54],[2,1.5,20.92]],"ltp":1.96,"tv":557.46,"id":35736916}]}]}
{"op":"mcm","clk":"11960755551","pt":1724589024726,"mc":[{"id":"1.232012908","rc":[{"batb":[[1,1.51,6.51]],"ltp":1.96,"tv":557.46,"id":35736916}]}]}
{"op":"mcm","clk":"11960758826","pt":1724589039805,"mc":[{"id":"1.232012908","rc":[{"batb":[[0,1.56,14.55],[1,1.55,123.36],[2,1.51,6.51]],"ltp":1.96,"tv":557.46,"id":35736916}]}]}
{"op":"mcm","clk":"11960795868","pt":1724589235322,"mc":[{"id":"1.232012908","rc":[{"batb":[[0,1.56,23.81],[1,1.51,6.51],[2,1.5,20.92]],"ltp":1.96,"tv":557.46,"id":35736916}]}]}
{"op":"mcm","clk":"11960795888","pt":1724589235430,"mc":[{"id":"1.232012908","rc":[{"batb":[[0,1.57,121.77],[1,1.56,23.81],[2,1.51,6.51]],"ltp":1.96,"tv":557.46,"id":35736916}]}]}
{"op":"mcm","clk":"11960796163","pt":1724589236900,"mc":[{"id":"1.232012908","rc":[{"batb":[[0,1.58,14.38],[1,1.57,121.77]],"ltp":1.96,"tv":557.46,"id":35736916}]}]}
{"op":"mcm","clk":"11960834433","pt":1724589449987,"mc":[{"id":"1.232012908","rc":[{"batb":[[0,1.6,119.46],[1,1.58,23.52]],"ltp":1.96,"tv":557.46,"id":35736916}]}]}
{"op":"mcm","clk":"11960834712","pt":1724589451720,"mc":[{"id":"1.232012908","rc":[{"batb":[[0,1.61,14.1],[1,1.6,119.46]],"ltp":1.96,"tv":557.46,"id":35736916}]}]}
{"op":"mcm","clk":"11960838948","pt":1724589477222,"mc":[{"id":"1.232012908","rc":[{"batb":[[0,1.63,13.93],[1,1.62,92.82]],"ltp":1.96,"tv":557.46,"id":35736916}]}]}
{"op":"mcm","clk":"11960878433","pt":1724589688878,"mc":[{"id":"1.232012908","rc":[{"batb":[[0,1.64,68.39],[1,1.63,20.91]],"ltp":1.96,"tv":557.46,"id":35736916}]}]}
{"op":"mcm","clk":"11960878781","pt":1724589690769,"mc":[{"id":"1.232012908","rc":[{"batb":[[0,1.65,13.76],[1,1.64,68.39]],"ltp":1.96,"tv":557.46,"id":35736916}]}]}
{"op":"mcm","clk":"11960882112","pt":1724589709184,"mc":[{"id":"1.232012908","rc":[{"batb":[[0,1.67,67.15],[1,1.65,13.76]],"ltp":1.96,"tv":557.46,"id":35736916}]}]}
{"op":"mcm","clk":"11960882354","pt":1724589710483,"mc":[{"id":"1.232012908","rc":[{"batb":[[0,1.68,13.52],[1,1.67,67.15]],"ltp":1.96,"tv":557.46,"id":35736916}]}]}
{"op":"mcm","clk":"11960936948","pt":1724589920775,"mc":[{"id":"1.232012908","rc":[{"batb":[[0,1.68,62.79],[1,1.51,6.51],[2,1.5,20.92]],"ltp":1.96,"tv":557.46,"id":35736916}]}]}
{"op":"mcm","clk":"11960937188","pt":1724589922066,"mc":[{"id":"1.232012908","rc":[{"batb":[[0,1.68,57.74]],"ltp":1.96,"tv":557.46,"id":35736916}]}]}
{"op":"mcm","clk":"11961294869","pt":1724592068066,"mc":[{"id":"1.232012908","rc":[{"batl":[[0,1.95,8.38],[1,1.96,1.26],[2,1.97,154.28]],"ltp":1.96,"tv":557.46,"id":35736916}]}]}
{"op":"mcm","clk":"11961295865","pt":1724592074285,"mc":[{"id":"1.232012908","rc":[{"batl":[[0,1.96,1.26],[1,1.97,154.28],[2,2.02,157.9]],"ltp":1.96,"tv":557.46,"id":35736916}]}]}
{"op":"mcm","clk":"11961408803","pt":1724592763198,"mc":[{"id":"1.232012908","rc":[{"batb":[[1,1.5,20.92],[2,1.2,1250]],"ltp":1.96,"tv":557.46,"id":35736916}]}]}
{"op":"mcm","clk":"11961433890","pt":1724592914238,"mc":[{"id":"1.232012908","rc":[{"batb":[[1,1.9,42.71]],"ltp":2.1,"tv":270.08,"id":23387705}]}]}
{"op":"mcm","clk":"11961477804","pt":1724593172233,"mc":[{"id":"1.232012908","rc":[{"batl":[[0,2.22,47.35]],"ltp":2.1,"tv":270.08,"id":23387705}]}]}
{"op":"mcm","clk":"11961477875","pt":1724593172720,"mc":[{"id":"1.232012908","rc":[{"batb":[[0,1.82,12.48],[1,1.68,44.22],[2,1.5,20.92]],"ltp":1.96,"tv":557.46,"id":35736916},{"batb":[[0,2.06,5],[1,2.04,18],[2,1.9,42.71]],"ltp":2.1,"tv":270.08,"id":23387705}]}]}
{"op":"mcm","clk":"11961478425","pt":1724593175929,"mc":[{"id":"1.232012908","rc":[{"batb":[[0,2.04,18],[1,1.9,42.71],[2,1.74,17.32]],"ltp":2.1,"tv":270.08,"id":23387705}]}]}
{"op":"mcm","clk":"11961478799","pt":1724593178121,"mc":[{"id":"1.232012908","rc":[{"batb":[[0,2.06,5],[1,2.04,18],[2,1.9,42.71]],"ltp":2.1,"tv":270.08,"id":23387705}]}]}
{"op":"mcm","clk":"11961479312","pt":1724593181340,"mc":[{"id":"1.232012908","rc":[{"batb":[[0,2.04,18],[1,1.9,42.71],[2,1.74,17.32]],"ltp":2.1,"tv":270.08,"id":23387705}]}]}
{"op":"mcm","clk":"11961479981","pt":1724593185185,"mc":[{"id":"1.232012908","rc":[{"batb":[[1,1.5,20.92],[2,1.2,1250]],"ltp":1.96,"tv":557.46,"id":35736916},{"batb":[[0,2.06,5],[1,2.04,18],[2,1.9,42.71]],"ltp":2.1,"tv":270.08,"id":23387705}]}]}
{"op":"mcm","clk":"11961480542","pt":1724593188339,"mc":[{"id":"1.232012908","rc":[{"batb":[[0,2.04,18],[1,1.9,42.71],[2,1.74,17.32]],"ltp":2.1,"tv":270.08,"id":23387705}]}]}
{"op":"mcm","clk":"11961480910","pt":1724593191170,"mc":[{"id":"1.232012908","rc":[{"batb":[[0,2.06,5],[1,2.04,18],[2,1.9,42.71]],"ltp":2.1,"tv":270.08,"id":23387705}]}]}
{"op":"mcm","clk":"11961481419","pt":1724593194356,"mc":[{"id":"1.232012908","rc":[{"batb":[[0,2.04,18],[1,1.9,42.71],[2,1.74,17.32]],"ltp":2.1,"tv":270.08,"id":23387705}]}]}
{"op":"mcm","clk":"11961482079","pt":1724593198452,"mc":[{"id":"1.232012908","rc":[{"batb":[[0,2.06,5],[1,2.04,18],[2,1.9,42.71]],"ltp":2.1,"tv":270.08,"id":23387705}]}]}
{"op":"mcm","clk":"11961482647","pt":1724593201991,"mc":[{"id":"1.232012908","rc":[{"batb":[[0,2.04,18],[1,1.9,42.71],[2,1.74,17.32]],"ltp":2.1,"tv":270.08,"id":23387705}]}]}
{"op":"mcm","clk":"11961483180","pt":1724593205188,"mc":[{"id":"1.232012908","rc":[{"batb":[[0,2.06,5],[1,2.04,18],[2,1.9,42.71]],"ltp":2.1,"tv":270.08,"id":23387705}]}]}
{"op":"mcm","clk":"11961483817","pt":1724593208715,"mc":[{"id":"1.232012908","rc":[{"batb":[[0,2.04,18],[1,1.9,42.71],[2,1.74,17.32]],"ltp":2.1,"tv":270.08,"id":23387705}]}]}
{"op":"mcm","clk":"11961484335","pt":1724593211884,"mc":[{"id":"1.232012908","rc":[{"batb":[[0,2.06,5],[1,2.04,18],[2,1.9,42.71]],"ltp":2.1,"tv":270.08,"id":23387705}]}]}
{"op":"mcm","clk":"11961484892","pt":1724593215107,"mc":[{"id":"1.232012908","rc":[{"batb":[[0,2.04,18],[1,1.9,42.71],[2,1.74,17.32]],"ltp":2.1,"tv":270.08,"id":23387705}]}]}
{"op":"mcm","clk":"11961485452","pt":1724593218408,"mc":[{"id":"1.232012908","rc":[{"batb":[[0,2.06,5],[1,2.04,18],[2,1.9,42.71]],"ltp":2.1,"tv":270.08,"id":23387705}]}]}
{"op":"mcm","clk":"11961486025","pt":1724593221830,"mc":[{"id":"1.232012908","rc":[{"batb":[[0,2.04,18],[1,1.9,42.71],[2,1.74,17.32]],"ltp":2.1,"tv":270.08,"id":23387705}]}]}
{"op":"mcm","clk":"11961486635","pt":1724593225339,"mc":[{"id":"1.232012908","rc":[{"batb":[[0,2.06,5],[1,2.04,18],[2,1.9,42.71]],"ltp":2.1,"tv":270.08,"id":23387705}]}]}
{"op":"mcm","clk":"11961487226","pt":1724593228730,"mc":[{"id":"1.232012908","rc":[{"batb":[[0,2.04,18],[1,1.9,42.71],[2,1.74,17.32]],"ltp":2.1,"tv":270.08,"id":23387705}]}]}
{"op":"mcm","clk":"11961488994","pt":1724593238941,"mc":[{"id":"1.232012908","rc":[{"batb":[[0,2.06,5],[1,2.04,18],[2,1.9,42.71]],"ltp":2.1,"tv":270.08,"id":23387705}]}]}
{"op":"mcm","clk":"11961489541","pt":1724593242247,"mc":[{"id":"1.232012908","rc":[{"batb":[[0,2.04,18],[1,1.9,42.71],[2,1.74,17.32]],"ltp":2.1,"tv":270.08,"id":23387705}]}]}
{"op":"mcm","clk":"11961490143","pt":1724593246259,"mc":[{"id":"1.232012908","rc":[{"batb":[[0,2.06,5],[1,2.04,18],[2,1.9,42.71]],"ltp":2.1,"tv":270.08,"id":23387705}]}]}
{"op":"mcm","clk":"11961490707","pt":1724593249749,"mc":[{"id":"1.232012908","rc":[{"batb":[[0,2.04,18],[1,1.9,42.71],[2,1.74,17.32]],"ltp":2.1,"tv":270.08,"id":23387705}]}]}
{"op":"mcm","clk":"11961491290","pt":1724593253299,"mc":[{"id":"1.232012908","rc":[{"batb":[[0,2.06,5],[1,2.04,18],[2,1.9,42.71]],"ltp":2.1,"tv":270.08,"id":23387705}]}]}
{"op":"mcm","clk":"11961491778","pt":1724593256683,"mc":[{"id":"1.232012908","rc":[{"batb":[[0,2.04,18],[1,1.9,42.71],[2,1.74,17.32]],"ltp":2.1,"tv":270.08,"id":23387705}]}]}
{"op":"mcm","clk":"11961492389","pt":1724593260483,"mc":[{"id":"1.232012908","rc":[{"batb":[[0,2.06,5],[1,2.04,18],[2,1.9,42.71]],"ltp":2.1,"tv":270.08,"id":23387705}]}]}
{"op":"mcm","clk":"11961492979","pt":1724593264300,"mc":[{"id":"1.232012908","rc":[{"batb":[[0,2.04,18],[1,1.9,42.71],[2,1.74,17.32]],"ltp":2.1,"tv":270.08,"id":23387705}]}]}
{"op":"mcm","clk":"11961493417","pt":1724593266000,"mc":[{"id":"1.232012908","rc":[{"batb":[[0,2.06,5],[1,2.04,18],[2,1.9,42.71]],"ltp":2.1,"tv":270.08,"id":23387705}]}]}
{"op":"mcm","clk":"11961493956","pt":1724593269319,"mc":[{"id":"1.232012908","rc":[{"batb":[[0,2.04,18],[1,1.9,42.71],[2,1.74,17.32]],"ltp":2.1,"tv":270.08,"id":23387705}]}]}
{"op":"mcm","clk":"11961494352","pt":1724593271907,"mc":[{"id":"1.232012908","rc":[{"batb":[[0,2.06,5],[1,2.04,18],[2,1.9,42.71]],"ltp":2.1,"tv":270.08,"id":23387705}]}]}
{"op":"mcm","clk":"11961494862","pt":1724593275089,"mc":[{"id":"1.232012908","rc":[{"batb":[[0,2.04,18],[1,1.9,42.71],[2,1.74,17.32]],"ltp":2.1,"tv":270.08,"id":23387705}]}]}
{"op":"mcm","clk":"11961495458","pt":1724593278526,"mc":[{"id":"1.232012908","rc":[{"batb":[[0,2.06,5],[1,2.04,18],[2,1.9,42.71]],"ltp":2.1,"tv":270.08,"id":23387705}]}]}
{"op":"mcm","clk":"11961495996","pt":1724593281843,"mc":[{"id":"1.232012908","rc":[{"batb":[[0,2.04,18],[1,1.9,42.71],[2,1.74,17.32]],"ltp":2.1,"tv":270.08,"id":23387705}]}]}
{"op":"mcm","clk":"11961496668","pt":1724593286039,"mc":[{"id":"1.232012908","rc":[{"batb":[[0,2.06,5],[1,2.04,18],[2,1.9,42.71]],"ltp":2.1,"tv":270.08,"id":23387705}]}]}
{"op":"mcm","clk":"11961497240","pt":1724593289405,"mc":[{"id":"1.232012908","rc":[{"batb":[[0,2.04,18],[1,1.9,42.71],[2,1.74,17.32]],"ltp":2.1,"tv":270.08,"id":23387705}]}]}
{"op":"mcm","clk":"11961497603","pt":1724593291625,"mc":[{"id":"1.232012908","rc":[{"batb":[[0,2.06,5],[1,2.04,18],[2,1.9,42.71]],"ltp":2.1,"tv":270.08,"id":23387705}]}]}
{"op":"mcm","clk":"11961498134","pt":1724593294829,"mc":[{"id":"1.232012908","rc":[{"batb":[[0,2.04,18],[1,1.9,42.71],[2,1.74,17.32]],"ltp":2.1,"tv":270.08,"id":23387705}]}]}
{"op":"mcm","clk":"11961499833","pt":1724593304633,"mc":[{"id":"1.232012908","rc":[{"batb":[[0,2.06,5],[1,2.04,18],[2,1.9,42.71]],"ltp":2.1,"tv":270.08,"id":23387705}]}]}
{"op":"mcm","clk":"11961500382","pt":1724593308113,"mc":[{"id":"1.232012908","rc":[{"batb":[[0,2.04,18],[1,1.9,42.71],[2,1.74,17.32]],"ltp":2.1,"tv":270.08,"id":23387705}]}]}
{"op":"mcm","clk":"11961500970","pt":1724593311828,"mc":[{"id":"1.232012908","rc":[{"batb":[[0,2.06,5],[1,2.04,18],[2,1.9,42.71]],"ltp":2.1,"tv":270.08,"id":23387705}]}]}
{"op":"mcm","clk":"11961501507","pt":1724593315331,"mc":[{"id":"1.232012908","rc":[{"batb":[[0,2.04,18],[1,1.9,42.71],[2,1.74,17.32]],"ltp":2.1,"tv":270.08,"id":23387705}]}]}
{"op":"mcm","clk":"11961502193","pt":1724593319256,"mc":[{"id":"1.232012908","rc":[{"batb":[[0,2.06,5],[1,2.04,18],[2,1.9,42.71]],"ltp":2.1,"tv":270.08,"id":23387705}]}]}
{"op":"mcm","clk":"11961502798","pt":1724593322539,"mc":[{"id":"1.232012908","rc":[{"batb":[[0,2.04,18],[1,1.9,42.71],[2,1.74,17.32]],"ltp":2.1,"tv":270.08,"id":23387705}]}]}
{"op":"mcm","clk":"11961503906","pt":1724593328146,"mc":[{"id":"1.232012908","rc":[{"batb":[[0,2.06,5],[1,2.04,18],[2,1.9,42.71]],"ltp":2.1,"tv":270.08,"id":23387705}]}]}
{"op":"mcm","clk":"11961504550","pt":1724593331455,"mc":[{"id":"1.232012908","rc":[{"batb":[[0,2.04,18],[1,1.9,42.71],[2,1.74,17.32]],"ltp":2.1,"tv":270.08,"id":23387705}]}]}
{"op":"mcm","clk":"11961505377","pt":1724593336097,"mc":[{"id":"1.232012908","rc":[{"batb":[[0,2.06,5],[1,2.04,18],[2,1.9,42.71]],"ltp":2.1,"tv":270.08,"id":23387705}]}]}
{"op":"mcm","clk":"11961505971","pt":1724593339582,"mc":[{"id":"1.232012908","rc":[{"batb":[[0,2.04,18],[1,1.9,42.71],[2,1.74,17.32]],"ltp":2.1,"tv":270.08,"id":23387705}]}]}
{"op":"mcm","clk":"11961506808","pt":1724593344496,"mc":[{"id":"1.232012908","rc":[{"batb":[[0,2.06,5],[1,2.04,18],[2,1.9,42.71]],"ltp":2.1,"tv":270.08,"id":23387705}]}]}
{"op":"mcm","clk":"11961507408","pt":1724593347897,"mc":[{"id":"1.232012908","rc":[{"batb":[[0,2.04,18],[1,1.9,42.71],[2,1.74,17.32]],"ltp":2.1,"tv":270.08,"id":23387705}]}]}
{"op":"mcm","clk":"11961508016","pt":1724593351376,"mc":[{"id":"1.232012908","rc":[{"batb":[[0,2.06,5],[1,2.04,18],[2,1.9,42.71]],"ltp":2.1,"tv":270.08,"id":23387705}]}]}
{"op":"mcm","clk":"11961508579","pt":1724593354603,"mc":[{"id":"1.232012908","rc":[{"batb":[[0,2.04,18],[1,1.9,42.71],[2,1.74,17.32]],"ltp":2.1,"tv":270.08,"id":23387705}]}]}
{"op":"mcm","clk":"11961509685","pt":1724593361297,"mc":[{"id":"1.232012908","rc":[{"batb":[[0,2.06,5],[1,2.04,18],[2,1.9,42.71]],"ltp":2.1,"tv":270.08,"id":23387705}]}]}
{"op":"mcm","clk":"11961510244","pt":1724593364587,"mc":[{"id":"1.232012908","rc":[{"batb":[[0,2.04,18],[1,1.9,42.71],[2,1.74,17.32]],"ltp":2.1,"tv":270.08,"id":23387705}]}]}
{"op":"mcm","clk":"11961510893","pt":1724593368597,"mc":[{"id":"1.232012908","rc":[{"batb":[[0,2.06,5],[1,2.04,18],[2,1.9,42.71]],"ltp":2.1,"tv":270.08,"id":23387705}]}]}
{"op":"mcm","clk":"11961511461","pt":1724593372100,"mc":[{"id":"1.232012908","rc":[{"batb":[[0,2.04,18],[1,1.9,42.71],[2,1.74,17.32]],"ltp":2.1,"tv":270.08,"id":23387705}]}]}
{"op":"mcm","clk":"11961512019","pt":1724593375217,"mc":[{"id":"1.232012908","rc":[{"batb":[[0,2.06,5],[1,2.04,18],[2,1.9,42.71]],"ltp":2.1,"tv":270.08,"id":23387705}]}]}
{"op":"mcm","clk":"11961512593","pt":1724593378349,"mc":[{"id":"1.232012908","rc":[{"batb":[[0,2.04,18],[1,1.9,42.71],[2,1.74,17.32]],"ltp":2.1,"tv":270.08,"id":23387705}]}]}
{"op":"mcm","clk":"11961513272","pt":1724593382148,"mc":[{"id":"1.232012908","rc":[{"batb":[[0,2.06,5],[1,2.04,18],[2,1.9,42.71]],"ltp":2.1,"tv":270.08,"id":23387705}]}]}
{"op":"mcm","clk":"11961513452","pt":1724593383185,"mc":[{"id":"1.232012908","rc":[{"batb":[[0,1.82,16.83]],"ltp":1.96,"tv":557.46,"id":35736916}]}]}
{"op":"mcm","clk":"11961513901","pt":1724593385573,"mc":[{"id":"1.232012908","rc":[{"batb":[[0,2.04,18],[1,1.9,42.71],[2,1.74,17.32]],"ltp":2.1,"tv":270.08,"id":23387705}]}]}
{"op":"mcm","clk":"11961515190","pt":1724593393288,"mc":[{"id":"1.232012908","rc":[{"batb":[[0,2.06,5],[1,2.04,18],[2,1.9,42.71]],"ltp":2.1,"tv":270.08,"id":23387705}]}]}
{"op":"mcm","clk":"11961515713","pt":1724593396702,"mc":[{"id":"1.232012908","rc":[{"batb":[[0,2.04,18],[1,1.9,42.71],[2,1.74,17.32]],"ltp":2.1,"tv":270.08,"id":23387705}]}]}
{"op":"mcm","clk":"11961516108","pt":1724593398888,"mc":[{"id":"1.232012908","rc":[{"batb":[[0,2.06,5],[1,2.04,18],[2,1.9,42.71]],"ltp":2.1,"tv":270.08,"id":23387705}]}]}
{"op":"mcm","clk":"11961516693","pt":1724593402213,"mc":[{"id":"1.232012908","rc":[{"batb":[[0,2.04,18],[1,1.9,42.71],[2,1.74,17.32]],"ltp":2.1,"tv":270.08,"id":23387705}]}]}
{"op":"mcm","clk":"11961517088","pt":1724593404616,"mc":[{"id":"1.232012908","rc":[{"batb":[[0,2.06,5],[1,2.04,18],[2,1.9,42.71]],"ltp":2.1,"tv":270.08,"id":23387705}]}]}
{"op":"mcm","clk":"11961517659","pt":1724593408097,"mc":[{"id":"1.232012908","rc":[{"batb":[[0,2.04,18],[1,1.9,42.71],[2,1.74,17.32]],"ltp":2.1,"tv":270.08,"id":23387705}]}]}
{"op":"mcm","clk":"11961518073","pt":1724593410524,"mc":[{"id":"1.232012908","rc":[{"batb":[[0,2.06,5],[1,2.04,18],[2,1.9,42.71]],"ltp":2.1,"tv":270.08,"id":23387705}]}]}
{"op":"mcm","clk":"11961518730","pt":1724593413935,"mc":[{"id":"1.232012908","rc":[{"batb":[[0,2.04,18],[1,1.9,42.71],[2,1.74,17.32]],"ltp":2.1,"tv":270.08,"id":23387705}]}]}
{"op":"mcm","clk":"11961519306","pt":1724593417439,"mc":[{"id":"1.232012908","rc":[{"batb":[[0,2.06,5],[1,2.04,18],[2,1.9,42.71]],"ltp":2.1,"tv":270.08,"id":23387705}]}]}
{"op":"mcm","clk":"11961519806","pt":1724593420741,"mc":[{"id":"1.232012908","rc":[{"batb":[[0,2.04,18],[1,1.9,42.71],[2,1.74,17.32]],"ltp":2.1,"tv":270.08,"id":23387705}]}]}
{"op":"mcm","clk":"11961520463","pt":1724593424644,"mc":[{"id":"1.232012908","rc":[{"batb":[[0,2.06,5],[1,2.04,18],[2,1.9,42.71]],"ltp":2.1,"tv":270.08,"id":23387705}]}]}
{"op":"mcm","clk":"11961521034","pt":1724593428161,"mc":[{"id":"1.232012908","rc":[{"batb":[[0,2.04,18],[1,1.9,42.71],[2,1.74,17.32]],"ltp":2.1,"tv":270.08,"id":23387705}]}]}
{"op":"mcm","clk":"11961521433","pt":1724593430652,"mc":[{"id":"1.232012908","rc":[{"batb":[[0,2.06,5],[1,2.04,18],[2,1.9,42.71]],"ltp":2.1,"tv":270.08,"id":23387705}]}]}
{"op":"mcm","clk":"11961521988","pt":1724593434055,"mc":[{"id":"1.232012908","rc":[{"batb":[[0,2.04,18],[1,1.9,42.71],[2,1.74,17.32]],"ltp":2.1,"tv":270.08,"id":23387705}]}]}
{"op":"mcm","clk":"11961522439","pt":1724593436936,"mc":[{"id":"1.232012908","rc":[{"batb":[[0,2.06,5],[1,2.04,18],[2,1.9,42.71]],"ltp":2.1,"tv":270.08,"id":23387705}]}]}
{"op":"mcm","clk":"11961522973","pt":1724593440461,"mc":[{"id":"1.232012908","rc":[{"batb":[[0,2.04,18],[1,1.9,42.71],[2,1.74,17.32]],"ltp":2.1,"tv":270.08,"id":23387705}]}]}
{"op":"mcm","clk":"11961523337","pt":1724593442662,"mc":[{"id":"1.232012908","rc":[{"batb":[[0,2.06,5],[1,2.04,18],[2,1.9,42.71]],"ltp":2.1,"tv":270.08,"id":23387705}]}]}
{"op":"mcm","clk":"11961523936","pt":1724593446198,"mc":[{"id":"1.232012908","rc":[{"batb":[[0,2.04,18],[1,1.9,42.71],[2,1.74,17.32]],"batl":[[0,2.2,4.59],[1,2.22,47.35]],"ltp":2.1,"tv":270.08,"id":23387705}]}]}
{"op":"mcm","clk":"11961524348","pt":1724593448569,"mc":[{"id":"1.232012908","rc":[{"batb":[[0,2.06,5],[1,2.04,18],[2,1.9,42.71]],"ltp":2.1,"tv":270.08,"id":23387705}]}]}
{"op":"mcm","clk":"11961524830","pt":1724593451767,"mc":[{"id":"1.232012908","rc":[{"batb":[[0,2.04,18],[1,1.9,42.71],[2,1.74,17.32]],"ltp":2.1,"tv":270.08,"id":23387705}]}]}
{"op":"mcm","clk":"11961525823","pt":1724593458028,"mc":[{"id":"1.232012908","rc":[{"batb":[[0,2.06,5],[1,2.04,18],[2,1.9,42.71]],"ltp":2.1,"tv":270.08,"id":23387705}]}]}
{"op":"mcm","clk":"11961526534","pt":1724593462015,"mc":[{"id":"1.232012908","rc":[{"batb":[[0,2.04,18],[1,1.9,42.71],[2,1.74,17.32]],"ltp":2.1,"tv":270.08,"id":23387705}]}]}
{"op":"mcm","clk":"11961527574","pt":1724593467622,"mc":[{"id":"1.232012908","rc":[{"batb":[[0,2.06,5],[1,2.04,18],[2,1.9,42.71]],"ltp":2.1,"tv":270.08,"id":23387705}]}]}
{"op":"mcm","clk":"11961528166","pt":1724593471047,"mc":[{"id":"1.232012908","rc":[{"batb":[[0,2.04,18],[1,1.9,42.71],[2,1.74,17.32]],"ltp":2.1,"tv":270.08,"id":23387705}]}]}
{"op":"mcm","clk":"11961528677","pt":1724593473955,"mc":[{"id":"1.232012908","rc":[{"batb":[[0,2.06,5],[1,2.04,18],[2,1.9,42.71]],"ltp":2.1,"tv":270.08,"id":23387705}]}]}
{"op":"mcm","clk":"11961529275","pt":1724593477386,"mc":[{"id":"1.232012908","rc":[{"batb":[[0,2.04,18],[1,1.9,42.71],[2,1.74,17.32]],"ltp":2.1,"tv":270.08,"id":23387705}]}]}
{"op":"mcm","clk":"11961530192","pt":1724593483046,"mc":[{"id":"1.232012908","rc":[{"batb":[[0,2.06,5],[1,2.04,18],[2,1.9,42.71]],"ltp":2.1,"tv":270.08,"id":23387705}]}]}
{"op":"mcm","clk":"11961530740","pt":1724593486570,"mc":[{"id":"1.232012908","rc":[{"batb":[[0,2.04,18],[1,1.9,42.71],[2,1.74,17.32]],"ltp":2.1,"tv":270.08,"id":23387705}]}]}
{"op":"mcm","clk":"11961531374","pt":1724593490456,"mc":[{"id":"1.232012908","rc":[{"batb":[[0,2.06,5],[1,2.04,18],[2,1.9,42.71]],"ltp":2.1,"tv":270.08,"id":23387705}]}]}
{"op":"mcm","clk":"11961531908","pt":1724593493774,"mc":[{"id":"1.232012908","rc":[{"batb":[[0,2.04,18],[1,1.9,42.71],[2,1.74,17.32]],"ltp":2.1,"tv":270.08,"id":23387705}]}]}
{"op":"mcm","clk":"11961532633","pt":1724593498082,"mc":[{"id":"1.232012908","rc":[{"batb":[[0,2.06,5],[1,2.04,18],[2,1.9,42.71]],"ltp":2.1,"tv":270.08,"id":23387705}]}]}
{"op":"mcm","clk":"11961533247","pt":1724593501414,"mc":[{"id":"1.232012908","rc":[{"batb":[[0,2.04,18],[1,1.9,42.71],[2,1.74,17.32]],"ltp":2.1,"tv":270.08,"id":23387705}]}]}
{"op":"mcm","clk":"11961533668","pt":1724593503579,"mc":[{"id":"1.232012908","rc":[{"batb":[[0,2.06,5],[1,2.04,18],[2,1.9,42.71]],"ltp":2.1,"tv":270.08,"id":23387705}]}]}
{"op":"mcm","clk":"11961534321","pt":1724593506767,"mc":[{"id":"1.232012908","rc":[{"batb":[[0,2.04,18],[1,1.9,42.71],[2,1.74,17.32]],"ltp":2.1,"tv":270.08,"id":23387705}]}]}
{"op":"mcm","clk":"11961534699","pt":1724593509179,"mc":[{"id":"1.232012908","rc":[{"batb":[[0,2.06,5],[1,2.04,18],[2,1.9,42.71]],"ltp":2.1,"tv":270.08,"id":23387705}]}]}
{"op":"mcm","clk":"11961535248","pt":1724593512596,"mc":[{"id":"1.232012908","rc":[{"batb":[[0,2.04,18],[1,1.9,42.71],[2,1.74,17.32]],"ltp":2.1,"tv":270.08,"id":23387705}]}]}
{"op":"mcm","clk":"11961535722","pt":1724593515895,"mc":[{"id":"1.232012908","rc":[{"batb":[[0,2.06,5],[1,2.04,18],[2,1.9,42.71]],"ltp":2.1,"tv":270.08,"id":23387705}]}]}
{"op":"mcm","clk":"11961536221","pt":1724593519207,"mc":[{"id":"1.232012908","rc":[{"batb":[[0,2.04,18],[1,1.9,42.71],[2,1.74,17.32]],"ltp":2.1,"tv":270.08,"id":23387705}]}]}
{"op":"mcm","clk":"11961536994","pt":1724593523605,"mc":[{"id":"1.232012908","rc":[{"batb":[[0,2.06,5],[1,2.04,18],[2,1.9,42.71]],"ltp":2.1,"tv":270.08,"id":23387705}]}]}
{"op":"mcm","clk":"11961537543","pt":1724593526924,"mc":[{"id":"1.232012908","rc":[{"batb":[[0,2.04,18],[1,1.9,42.71],[2,1.74,17.32]],"ltp":2.1,"tv":270.08,"id":23387705}]}]}
{"op":"mcm","clk":"11961538637","pt":1724593532922,"mc":[{"id":"1.232012908","rc":[{"batb":[[0,2.06,5],[1,2.04,18],[2,1.9,42.71]],"ltp":2.1,"tv":270.08,"id":23387705}]}]}
{"op":"mcm","clk":"11961539204","pt":1724593536421,"mc":[{"id":"1.232012908","rc":[{"batb":[[0,2.04,18],[1,1.9,42.71],[2,1.74,17.32]],"ltp":2.1,"tv":270.08,"id":23387705}]}]}
{"op":"mcm","clk":"11961540746","pt":1724593545034,"mc":[{"id":"1.232012908","rc":[{"batb":[[0,2.06,5],[1,2.04,18],[2,1.9,42.71]],"ltp":2.1,"tv":270.08,"id":23387705}]}]}
{"op":"mcm","clk":"11961541393","pt":1724593548569,"mc":[{"id":"1.232012908","rc":[{"batb":[[0,2.04,18],[1,1.9,42.71],[2,1.74,17.32]],"ltp":2.1,"tv":270.08,"id":23387705}]}]}
{"op":"mcm","clk":"11961541883","pt":1724593551458,"mc":[{"id":"1.232012908","rc":[{"batb":[[0,2.06,5],[1,2.04,18],[2,1.9,42.71]],"ltp":2.1,"tv":270.08,"id":23387705}]}]}
{"op":"mcm","clk":"11961542491","pt":1724593554938,"mc":[{"id":"1.232012908","rc":[{"batb":[[0,2.04,18],[1,1.9,42.71],[2,1.74,17.32]],"ltp":2.1,"tv":270.08,"id":23387705}]}]}
{"op":"mcm","clk":"11961542904","pt":1724593557254,"mc":[{"id":"1.232012908","rc":[{"batb":[[0,2.06,5],[1,2.04,18],[2,1.9,42.71]],"ltp":2.1,"tv":270.08,"id":23387705}]}]}
{"op":"mcm","clk":"11961543486","pt":1724593560563,"mc":[{"id":"1.232012908","rc":[{"batb":[[0,2.04,18],[1,1.9,42.71],[2,1.74,17.32]],"ltp":2.1,"tv":270.08,"id":23387705}]}]}
{"op":"mcm","clk":"11961544029","pt":1724593563569,"mc":[{"id":"1.232012908","rc":[{"batb":[[0,2.06,5],[1,2.04,18],[2,1.9,42.71]],"ltp":2.1,"tv":270.08,"id":23387705}]}]}
{"op":"mcm","clk":"11961544596","pt":1724593566887,"mc":[{"id":"1.232012908","rc":[{"batb":[[0,2.04,18],[1,1.9,42.71],[2,1.74,17.32]],"ltp":2.1,"tv":270.08,"id":23387705}]}]}
{"op":"mcm","clk":"11961545290","pt":1724593570959,"mc":[{"id":"1.232012908","rc":[{"batb":[[0,2.06,5],[1,2.04,18],[2,1.9,42.71]],"ltp":2.1,"tv":270.08,"id":23387705}]}]}
{"op":"mcm","clk":"11961545888","pt":1724593574380,"mc":[{"id":"1.232012908","rc":[{"batb":[[0,2.04,18],[1,1.9,42.71],[2,1.74,17.32]],"ltp":2.1,"tv":270.08,"id":23387705}]}]}
{"op":"mcm","clk":"11961546427","pt":1724593577690,"mc":[{"id":"1.232012908","rc":[{"batb":[[0,2.06,5],[1,2.04,18],[2,1.9,42.71]],"ltp":2.1,"tv":270.08,"id":23387705}]}]}
{"op":"mcm","clk":"11961547012","pt":1724593581093,"mc":[{"id":"1.232012908","rc":[{"batb":[[0,2.04,18],[1,1.9,42.71],[2,1.74,17.32]],"ltp":2.1,"tv":270.08,"id":23387705}]}]}
{"op":"mcm","clk":"11961547430","pt":1724593583411,"mc":[{"id":"1.232012908","rc":[{"batb":[[0,2.06,5],[1,2.04,18],[2,1.9,42.71]],"ltp":2.1,"tv":270.08,"id":23387705}]}]}
{"op":"mcm","clk":"11961548001","pt":1724593586784,"mc":[{"id":"1.232012908","rc":[{"batb":[[0,2.04,18],[1,1.9,42.71],[2,1.74,17.32]],"ltp":2.1,"tv":270.08,"id":23387705}]}]}
{"op":"mcm","clk":"11961548744","pt":1724593590887,"mc":[{"id":"1.232012908","rc":[{"batb":[[0,2.06,5],[1,2.04,18],[2,1.9,42.71]],"ltp":2.1,"tv":270.08,"id":23387705}]}]}
{"op":"mcm","clk":"11961549342","pt":1724593594167,"mc":[{"id":"1.232012908","rc":[{"batb":[[0,2.04,18],[1,1.9,42.71],[2,1.74,17.32]],"ltp":2.1,"tv":270.08,"id":23387705}]}]}
{"op":"mcm","clk":"11961550271","pt":1724593599503,"mc":[{"id":"1.232012908","rc":[{"batb":[[0,2.06,5],[1,2.04,18],[2,1.9,42.71]],"ltp":2.1,"tv":270.08,"id":23387705}]}]}
{"op":"mcm","clk":"11961550822","pt":1724593602796,"mc":[{"id":"1.232012908","rc":[{"batb":[[0,2.04,18],[1,1.9,42.71],[2,1.74,17.32]],"ltp":2.1,"tv":270.08,"id":23387705}]}]}
{"op":"mcm","clk":"11961551896","pt":1724593608998,"mc":[{"id":"1.232012908","rc":[{"batb":[[0,2.06,5],[1,2.04,18],[2,1.9,42.71]],"ltp":2.1,"tv":270.08,"id":23387705}]}]}
{"op":"mcm","clk":"11961552484","pt":1724593612420,"mc":[{"id":"1.232012908","rc":[{"batb":[[0,2.04,18],[1,1.9,42.71],[2,1.74,17.32]],"ltp":2.1,"tv":270.08,"id":23387705}]}]}
{"op":"mcm","clk":"11961553101","pt":1724593616207,"mc":[{"id":"1.232012908","rc":[{"batb":[[0,2.06,5],[1,2.04,18],[2,1.9,42.71]],"ltp":2.1,"tv":270.08,"id":23387705}]}]}
{"op":"mcm","clk":"11961553718","pt":1724593619963,"mc":[{"id":"1.232012908","rc":[{"batb":[[0,2.04,18],[1,1.9,42.71],[2,1.74,17.32]],"ltp":2.1,"tv":270.08,"id":23387705}]}]}
{"op":"mcm","clk":"11961554429","pt":1724593624079,"mc":[{"id":"1.232012908","rc":[{"batb":[[0,2.06,5],[1,2.04,18],[2,1.9,42.71]],"ltp":2.1,"tv":270.08,"id":23387705}]}]}
{"op":"mcm","clk":"11961554951","pt":1724593627279,"mc":[{"id":"1.232012908","rc":[{"batb":[[0,2.04,18],[1,1.9,42.71],[2,1.74,17.32]],"ltp":2.1,"tv":270.08,"id":23387705}]}]}
{"op":"mcm","clk":"11961555576","pt":1724593630855,"mc":[{"id":"1.232012908","rc":[{"batb":[[0,2.06,5],[1,2.04,18],[2,1.9,42.71]],"ltp":2.1,"tv":270.08,"id":23387705}]}]}
{"op":"mcm","clk":"11961556118","pt":1724593634173,"mc":[{"id":"1.232012908","rc":[{"batb":[[0,2.04,18],[1,1.9,42.71],[2,1.74,17.32]],"ltp":2.1,"tv":270.08,"id":23387705}]}]}
{"op":"mcm","clk":"11961556503","pt":1724593636490,"mc":[{"id":"1.232012908","rc":[{"batb":[[0,2.06,5],[1,2.04,18],[2,1.9,42.71]],"ltp":2.1,"tv":270.08,"id":23387705}]}]}
{"op":"mcm","clk":"11961557104","pt":1724593640094,"mc":[{"id":"1.232012908","rc":[{"batb":[[0,2.04,18],[1,1.9,42.71],[2,1.74,17.32]],"ltp":2.1,"tv":270.08,"id":23387705}]}]}
{"op":"mcm","clk":"11961557525","pt":1724593642622,"mc":[{"id":"1.232012908","rc":[{"batb":[[0,2.06,5],[1,2.04,18],[2,1.9,42.71]],"ltp":2.1,"tv":270.08,"id":23387705}]}]}
{"op":"mcm","clk":"11961558212","pt":1724593646353,"mc":[{"id":"1.232012908","rc":[{"batb":[[0,2.04,18],[1,1.9,42.71],[2,1.74,17.32]],"ltp":2.1,"tv":270.08,"id":23387705}]}]}
{"op":"mcm","clk":"11961558611","pt":1724593648565,"mc":[{"id":"1.232012908","rc":[{"batb":[[0,2.06,5],[1,2.04,18],[2,1.9,42.71]],"ltp":2.1,"tv":270.08,"id":23387705}]}]}
{"op":"mcm","clk":"11961559215","pt":1724593651740,"mc":[{"id":"1.232012908","rc":[{"batb":[[0,2.04,18],[1,1.9,42.71],[2,1.74,17.32]],"ltp":2.1,"tv":270.08,"id":23387705}]}]}
{"op":"mcm","clk":"11961559797","pt":1724593655069,"mc":[{"id":"1.232012908","rc":[{"batb":[[0,2.06,5],[1,2.04,18],[2,1.9,42.71]],"ltp":2.1,"tv":270.08,"id":23387705}]}]}
{"op":"mcm","clk":"11961560386","pt":1724593658477,"mc":[{"id":"1.232012908","rc":[{"batb":[[0,2.04,18],[1,1.9,42.71],[2,1.74,17.32]],"ltp":2.1,"tv":270.08,"id":23387705}]}]}
{"op":"mcm","clk":"11961560787","pt":1724593660756,"mc":[{"id":"1.232012908","rc":[{"batb":[[0,2.06,5],[1,2.04,18],[2,1.9,42.71]],"ltp":2.1,"tv":270.08,"id":23387705}]}]}
{"op":"mcm","clk":"11961561367","pt":1724593664174,"mc":[{"id":"1.232012908","rc":[{"batb":[[0,2.04,18],[1,1.9,42.71],[2,1.74,17.32]],"ltp":2.1,"tv":270.08,"id":23387705}]}]}
{"op":"mcm","clk":"11961561754","pt":1724593666348,"mc":[{"id":"1.232012908","rc":[{"batb":[[0,2.06,5],[1,2.04,18],[2,1.9,42.71]],"ltp":2.1,"tv":270.08,"id":23387705}]}]}
{"op":"mcm","clk":"11961562302","pt":1724593669762,"mc":[{"id":"1.232012908","rc":[{"batb":[[0,2.04,18],[1,1.9,42.71],[2,1.74,17.32]],"ltp":2.1,"tv":270.08,"id":23387705}]}]}
{"op":"mcm","clk":"11961562814","pt":1724593672875,"mc":[{"id":"1.232012908","rc":[{"batb":[[0,2.06,5],[1,2.04,18],[2,1.9,42.71]],"ltp":2.1,"tv":270.08,"id":23387705}]}]}
{"op":"mcm","clk":"11961563375","pt":1724593676387,"mc":[{"id":"1.232012908","rc":[{"batb":[[0,2.04,18],[1,1.9,42.71],[2,1.74,17.32]],"ltp":2.1,"tv":270.08,"id":23387705}]}]}
{"op":"mcm","clk":"11961563752","pt":1724593678568,"mc":[{"id":"1.232012908","rc":[{"batb":[[0,2.06,5],[1,2.04,18],[2,1.9,42.71]],"ltp":2.1,"tv":270.08,"id":23387705}]}]}
{"op":"mcm","clk":"11961564324","pt":1724593682065,"mc":[{"id":"1.232012908","rc":[{"batb":[[0,2.04,18],[1,1.9,42.71],[2,1.74,17.32]],"ltp":2.1,"tv":270.08,"id":23387705}]}]}
{"op":"mcm","clk":"11961564763","pt":1724593684585,"mc":[{"id":"1.232012908","rc":[{"batb":[[0,2.06,5],[1,2.04,18],[2,1.9,42.71]],"ltp":2.1,"tv":270.08,"id":23387705}]}]}
{"op":"mcm","clk":"11961565357","pt":1724593688104,"mc":[{"id":"1.232012908","rc":[{"batb":[[0,2.04,18],[1,1.9,42.71],[2,1.74,17.32]],"ltp":2.1,"tv":270.08,"id":23387705}]}]}
{"op":"mcm","clk":"11961565682","pt":1724593690270,"mc":[{"id":"1.232012908","rc":[{"batb":[[0,2.06,5],[1,2.04,18],[2,1.9,42.71]],"ltp":2.1,"tv":270.08,"id":23387705}]}]}
{"op":"mcm","clk":"11961566221","pt":1724593693699,"mc":[{"id":"1.232012908","rc":[{"batb":[[0,2.04,18],[1,1.9,42.71],[2,1.74,17.32]],"ltp":2.1,"tv":270.08,"id":23387705}]}]}
{"op":"mcm","clk":"11961566623","pt":1724593695979,"mc":[{"id":"1.232012908","rc":[{"batb":[[0,2.06,5],[1,2.04,18],[2,1.9,42.71]],"ltp":2.1,"tv":270.08,"id":23387705}]}]}
{"op":"mcm","clk":"11961567252","pt":1724593699469,"mc":[{"id":"1.232012908","rc":[{"batb":[[0,2.04,18],[1,1.9,42.71],[2,1.74,17.32]],"ltp":2.1,"tv":270.08,"id":23387705}]}]}
{"op":"mcm","clk":"11961567613","pt":1724593701601,"mc":[{"id":"1.232012908","rc":[{"batb":[[0,2.06,5],[1,2.04,18],[2,1.9,42.71]],"ltp":2.1,"tv":270.08,"id":23387705}]}]}
{"op":"mcm","clk":"11961568198","pt":1724593705013,"mc":[{"id":"1.232012908","rc":[{"batb":[[0,2.04,18],[1,1.9,42.71],[2,1.74,17.32]],"ltp":2.1,"tv":270.08,"id":23387705}]}]}
{"op":"mcm","clk":"11961568577","pt":1724593707375,"mc":[{"id":"1.232012908","rc":[{"batb":[[0,2.06,5],[1,2.04,18],[2,1.9,42.71]],"ltp":2.1,"tv":270.08,"id":23387705}]}]}
{"op":"mcm","clk":"11961569178","pt":1724593710907,"mc":[{"id":"1.232012908","rc":[{"batb":[[0,2.04,18],[1,1.9,42.71],[2,1.74,17.32]],"ltp":2.1,"tv":270.08,"id":23387705}]}]}
{"op":"mcm","clk":"11961569638","pt":1724593713809,"mc":[{"id":"1.232012908","rc":[{"batb":[[0,2.06,5],[1,2.04,18],[2,1.9,42.71]],"ltp":2.1,"tv":270.08,"id":23387705}]}]}
{"op":"mcm","clk":"11961570124","pt":1724593717100,"mc":[{"id":"1.232012908","rc":[{"batb":[[0,2.04,18],[1,1.9,42.71],[2,1.74,17.32]],"ltp":2.1,"tv":270.08,"id":23387705}]}]}
{"op":"mcm","clk":"11961570815","pt":1724593721400,"mc":[{"id":"1.232012908","rc":[{"batb":[[0,2.06,5],[1,2.04,18],[2,1.9,42.71]],"ltp":2.1,"tv":270.08,"id":23387705}]}]}
{"op":"mcm","clk":"11961571311","pt":1724593724722,"mc":[{"id":"1.232012908","rc":[{"batb":[[0,2.04,18],[1,1.9,42.71],[2,1.74,17.32]],"ltp":2.1,"tv":270.08,"id":23387705}]}]}
{"op":"mcm","clk":"11961571686","pt":1724593727091,"mc":[{"id":"1.232012908","rc":[{"batb":[[0,2.06,5],[1,2.04,18],[2,1.9,42.71]],"ltp":2.1,"tv":270.08,"id":23387705}]}]}
{"op":"mcm","clk":"11961572181","pt":1724593730348,"mc":[{"id":"1.232012908","rc":[{"batb":[[0,2.04,18],[1,1.9,42.71],[2,1.74,17.32]],"ltp":2.1,"tv":270.08,"id":23387705}]}]}
{"op":"mcm","clk":"11961572590","pt":1724593732916,"mc":[{"id":"1.232012908","rc":[{"batb":[[0,2.06,5],[1,2.04,18],[2,1.9,42.71]],"ltp":2.1,"tv":270.08,"id":23387705}]}]}
{"op":"mcm","clk":"11961573090","pt":1724593736122,"mc":[{"id":"1.232012908","rc":[{"batb":[[0,2.04,18],[1,1.9,42.71],[2,1.74,17.32]],"ltp":2.1,"tv":270.08,"id":23387705}]}]}
{"op":"mcm","clk":"11961573469","pt":1724593738495,"mc":[{"id":"1.232012908","rc":[{"batb":[[0,2.06,5],[1,2.04,18],[2,1.9,42.71]],"ltp":2.1,"tv":270.08,"id":23387705}]}]}
{"op":"mcm","clk":"11961573968","pt":1724593741728,"mc":[{"id":"1.232012908","rc":[{"batb":[[0,2.04,18],[1,1.9,42.71],[2,1.74,17.32]],"ltp":2.1,"tv":270.08,"id":23387705}]}]}
{"op":"mcm","clk":"11961574454","pt":1724593744748,"mc":[{"id":"1.232012908","rc":[{"batb":[[0,2.06,5],[1,2.04,18],[2,1.9,42.71]],"ltp":2.1,"tv":270.08,"id":23387705}]}]}
{"op":"mcm","clk":"11961575019","pt":1724593748129,"mc":[{"id":"1.232012908","rc":[{"batb":[[0,2.04,18],[1,1.9,42.71],[2,1.74,17.32]],"ltp":2.1,"tv":270.08,"id":23387705}]}]}
{"op":"mcm","clk":"11961575479","pt":1724593750931,"mc":[{"id":"1.232012908","rc":[{"batb":[[0,2.06,5],[1,2.04,18],[2,1.9,42.71]],"ltp":2.1,"tv":270.08,"id":23387705}]}]}
{"op":"mcm","clk":"11961576008","pt":1724593754155,"mc":[{"id":"1.232012908","rc":[{"batb":[[0,2.04,18],[1,1.9,42.71],[2,1.74,17.32]],"ltp":2.1,"tv":270.08,"id":23387705}]}]}
{"op":"mcm","clk":"11961576432","pt":1724593756934,"mc":[{"id":"1.232012908","rc":[{"batb":[[0,2.06,5],[1,2.04,18],[2,1.9,42.71]],"ltp":2.1,"tv":270.08,"id":23387705}]}]}
{"op":"mcm","clk":"11961576941","pt":1724593760350,"mc":[{"id":"1.232012908","rc":[{"batb":[[0,2.04,18],[1,1.9,42.71],[2,1.74,17.32]],"ltp":2.1,"tv":270.08,"id":23387705}]}]}
{"op":"mcm","clk":"11961577711","pt":1724593765125,"mc":[{"id":"1.232012908","rc":[{"batb":[[0,2.06,5],[1,2.04,18],[2,1.9,42.71]],"ltp":2.1,"tv":270.08,"id":23387705}]}]}
{"op":"mcm","clk":"11961578251","pt":1724593768436,"mc":[{"id":"1.232012908","rc":[{"batb":[[0,2.04,18],[1,1.9,42.71],[2,1.74,17.32]],"ltp":2.1,"tv":270.08,"id":23387705}]}]}
{"op":"mcm","clk":"11961579213","pt":1724593774068,"mc":[{"id":"1.232012908","rc":[{"batb":[[0,2.06,5],[1,2.04,18],[2,1.9,42.71]],"ltp":2.1,"tv":270.08,"id":23387705}]}]}
{"op":"mcm","clk":"11961579697","pt":1724593777277,"mc":[{"id":"1.232012908","rc":[{"batb":[[0,2.04,18],[1,1.9,42.71],[2,1.74,17.32]],"ltp":2.1,"tv":270.08,"id":23387705}]}]}
{"op":"mcm","clk":"11961580607","pt":1724593783692,"mc":[{"id":"1.232012908","rc":[{"batb":[[0,2.06,5],[1,2.04,18],[2,1.9,42.71]],"ltp":2.1,"tv":270.08,"id":23387705}]}]}
{"op":"mcm","clk":"11961581086","pt":1724593786987,"mc":[{"id":"1.232012908","rc":[{"batb":[[0,2.04,18],[1,1.9,42.71],[2,1.74,17.32]],"ltp":2.1,"tv":270.08,"id":23387705}]}]}
{"op":"mcm","clk":"11961581794","pt":1724593791046,"mc":[{"id":"1.232012908","rc":[{"batb":[[0,2.06,5],[1,2.04,18],[2,1.9,42.71]],"ltp":2.1,"tv":270.08,"id":23387705}]}]}
{"op":"mcm","clk":"11961582313","pt":1724593794433,"mc":[{"id":"1.232012908","rc":[{"batb":[[0,2.04,18],[1,1.9,42.71],[2,1.74,17.32]],"ltp":2.1,"tv":270.08,"id":23387705}]}]}
{"op":"mcm","clk":"11961582673","pt":1724593796904,"mc":[{"id":"1.232012908","rc":[{"batb":[[0,2.06,5],[1,2.04,18],[2,1.9,42.71]],"ltp":2.1,"tv":270.08,"id":23387705}]}]}
{"op":"mcm","clk":"11961583232","pt":1724593800384,"mc":[{"id":"1.232012908","rc":[{"batb":[[0,2.04,18],[1,1.9,42.71],[2,1.74,17.32]],"ltp":2.1,"tv":270.08,"id":23387705}]}]}
{"op":"mcm","clk":"11961583851","pt":1724593804350,"mc":[{"id":"1.232012908","rc":[{"batb":[[0,2.06,5],[1,2.04,18],[2,1.9,42.71]],"ltp":2.1,"tv":270.08,"id":23387705}]}]}
{"op":"mcm","clk":"11961584350","pt":1724593807582,"mc":[{"id":"1.232012908","rc":[{"batb":[[0,2.04,18],[1,1.9,42.71],[2,1.74,17.32]],"ltp":2.1,"tv":270.08,"id":23387705}]}]}
{"op":"mcm","clk":"11961584793","pt":1724593809901,"mc":[{"id":"1.232012908","rc":[{"batb":[[0,2.06,5],[1,2.04,18],[2,1.9,42.71]],"ltp":2.1,"tv":270.08,"id":23387705}]}]}
{"op":"mcm","clk":"11961585361","pt":1724593813622,"mc":[{"id":"1.232012908","rc":[{"batb":[[0,2.04,18],[1,1.9,42.71],[2,1.74,17.32]],"ltp":2.1,"tv":270.08,"id":23387705}]}]}
{"op":"mcm","clk":"11961585782","pt":1724593816320,"mc":[{"id":"1.232012908","rc":[{"batb":[[0,2.06,5],[1,2.04,18],[2,1.9,42.71]],"ltp":2.1,"tv":270.08,"id":23387705}]}]}
{"op":"mcm","clk":"11961586226","pt":1724593819604,"mc":[{"id":"1.232012908","rc":[{"batb":[[0,2.04,18],[1,1.9,42.71],[2,1.74,17.32]],"ltp":2.1,"tv":270.08,"id":23387705}]}]}
{"op":"mcm","clk":"11961587490","pt":1724593828400,"mc":[{"id":"1.232012908","rc":[{"batb":[[0,2.06,5],[1,2.04,18],[2,1.9,42.71]],"ltp":2.1,"tv":270.08,"id":23387705}]}]}
{"op":"mcm","clk":"11961588023","pt":1724593831838,"mc":[{"id":"1.232012908","rc":[{"batb":[[0,2.04,18],[1,1.9,42.71],[2,1.74,17.32]],"ltp":2.1,"tv":270.08,"id":23387705}]}]}
{"op":"mcm","clk":"11961588344","pt":1724593834039,"mc":[{"id":"1.232012908","rc":[{"batb":[[0,2.06,5],[1,2.04,18],[2,1.9,42.71]],"ltp":2.1,"tv":270.08,"id":23387705}]}]}
{"op":"mcm","clk":"11961588851","pt":1724593837236,"mc":[{"id":"1.232012908","rc":[{"batb":[[0,2.04,18],[1,1.9,42.71],[2,1.74,17.32]],"ltp":2.1,"tv":270.08,"id":23387705}]}]}
{"op":"mcm","clk":"11961589482","pt":1724593841357,"mc":[{"id":"1.232012908","rc":[{"batb":[[0,2.06,5],[1,2.04,18],[2,1.9,42.71]],"ltp":2.1,"tv":270.08,"id":23387705}]}]}
{"op":"mcm","clk":"11961590088","pt":1724593844669,"mc":[{"id":"1.232012908","rc":[{"batb":[[0,2.04,18],[1,1.9,42.71],[2,1.74,17.32]],"ltp":2.1,"tv":270.08,"id":23387705}]}]}
{"op":"mcm","clk":"11961590669","pt":1724593848649,"mc":[{"id":"1.232012908","rc":[{"batb":[[0,2.06,5],[1,2.04,18],[2,1.9,42.71]],"ltp":2.1,"tv":270.08,"id":23387705}]}]}
{"op":"mcm","clk":"11961591175","pt":1724593852115,"mc":[{"id":"1.232012908","rc":[{"batb":[[0,2.04,18],[1,1.9,42.71],[2,1.74,17.32]],"ltp":2.1,"tv":270.08,"id":23387705}]}]}
{"op":"mcm","clk":"11961591625","pt":1724593855164,"mc":[{"id":"1.232012908","rc":[{"batb":[[0,2.06,5],[1,2.04,18],[2,1.9,42.71]],"ltp":2.1,"tv":270.08,"id":23387705}]}]}
{"op":"mcm","clk":"11961592116","pt":1724593858423,"mc":[{"id":"1.232012908","rc":[{"batb":[[0,2.04,18],[1,1.9,42.71],[2,1.74,17.32]],"ltp":2.1,"tv":270.08,"id":23387705}]}]}
{"op":"mcm","clk":"11961592551","pt":1724593861262,"mc":[{"id":"1.232012908","rc":[{"batb":[[0,2.06,5],[1,2.04,18],[2,1.9,42.71]],"ltp":2.1,"tv":270.08,"id":23387705}]}]}
{"op":"mcm","clk":"11961593075","pt":1724593864693,"mc":[{"id":"1.232012908","rc":[{"batb":[[0,2.04,18],[1,1.9,42.71],[2,1.74,17.32]],"ltp":2.1,"tv":270.08,"id":23387705}]}]}
{"op":"mcm","clk":"11961593872","pt":1724593869871,"mc":[{"id":"1.232012908","rc":[{"batb":[[0,2.06,5],[1,2.04,18],[2,1.9,42.71]],"ltp":2.1,"tv":270.08,"id":23387705}]}]}
{"op":"mcm","clk":"11961594335","pt":1724593873127,"mc":[{"id":"1.232012908","rc":[{"batb":[[0,2.04,18],[1,1.9,42.71],[2,1.74,17.32]],"ltp":2.1,"tv":270.08,"id":23387705}]}]}
{"op":"mcm","clk":"11961594728","pt":1724593875744,"mc":[{"id":"1.232012908","rc":[{"batb":[[0,2.06,5],[1,2.04,18],[2,1.9,42.71]],"ltp":2.1,"tv":270.08,"id":23387705}]}]}
{"op":"mcm","clk":"11961595336","pt":1724593879220,"mc":[{"id":"1.232012908","rc":[{"batb":[[0,2.04,18],[1,1.9,42.71],[2,1.74,17.32]],"ltp":2.1,"tv":270.08,"id":23387705}]}]}
{"op":"mcm","clk":"11961595671","pt":1724593881477,"mc":[{"id":"1.232012908","rc":[{"batb":[[0,2.06,5],[1,2.04,18],[2,1.9,42.71]],"ltp":2.1,"tv":270.08,"id":23387705}]}]}
{"op":"mcm","clk":"11961596244","pt":1724593884910,"mc":[{"id":"1.232012908","rc":[{"batb":[[0,2.04,18],[1,1.9,42.71],[2,1.74,17.32]],"ltp":2.1,"tv":270.08,"id":23387705}]}]}
{"op":"mcm","clk":"11961596763","pt":1724593888841,"mc":[{"id":"1.232012908","rc":[{"batb":[[0,2.06,5],[1,2.04,18],[2,1.9,42.71]],"ltp":2.1,"tv":270.08,"id":23387705}]}]}
{"op":"mcm","clk":"11961597321","pt":1724593892134,"mc":[{"id":"1.232012908","rc":[{"batb":[[0,2.04,18],[1,1.9,42.71],[2,1.74,17.32]],"ltp":2.1,"tv":270.08,"id":23387705}]}]}
{"op":"mcm","clk":"11961597673","pt":1724593894536,"mc":[{"id":"1.232012908","rc":[{"batb":[[0,2.06,5],[1,2.04,18],[2,1.9,42.71]],"ltp":2.1,"tv":270.08,"id":23387705}]}]}
{"op":"mcm","clk":"11961598223","pt":1724593897943,"mc":[{"id":"1.232012908","rc":[{"batb":[[0,2.04,18],[1,1.9,42.71],[2,1.74,17.32]],"ltp":2.1,"tv":270.08,"id":23387705}]}]}
{"op":"mcm","clk":"11961598578","pt":1724593900143,"mc":[{"id":"1.232012908","rc":[{"batb":[[0,2.06,5],[1,2.04,18],[2,1.9,42.71]],"ltp":2.1,"tv":270.08,"id":23387705}]}]}
{"op":"mcm","clk":"11961599081","pt":1724593903459,"mc":[{"id":"1.232012908","rc":[{"batb":[[0,2.04,18],[1,1.9,42.71],[2,1.74,17.32]],"ltp":2.1,"tv":270.08,"id":23387705}]}]}
{"op":"mcm","clk":"11961600332","pt":1724593912149,"mc":[{"id":"1.232012908","rc":[{"batb":[[0,2.06,5],[1,2.04,18],[2,1.9,42.71]],"ltp":2.1,"tv":270.08,"id":23387705}]}]}
{"op":"mcm","clk":"11961600853","pt":1724593915459,"mc":[{"id":"1.232012908","rc":[{"batb":[[0,2.04,18],[1,1.9,42.71],[2,1.74,17.32]],"ltp":2.1,"tv":270.08,"id":23387705}]}]}
{"op":"mcm","clk":"11961601255","pt":1724593917950,"mc":[{"id":"1.232012908","rc":[{"batb":[[0,2.06,5],[1,2.04,18],[2,1.9,42.71]],"ltp":2.1,"tv":270.08,"id":23387705}]}]}
{"op":"mcm","clk":"11961601787","pt":1724593921376,"mc":[{"id":"1.232012908","rc":[{"batb":[[0,2.04,18],[1,1.9,42.71],[2,1.74,17.32]],"ltp":2.1,"tv":270.08,"id":23387705}]}]}
{"op":"mcm","clk":"11961602297","pt":1724593924363,"mc":[{"id":"1.232012908","rc":[{"batb":[[0,2.06,5],[1,2.04,18],[2,1.9,42.71]],"ltp":2.1,"tv":270.08,"id":23387705}]}]}
{"op":"mcm","clk":"11961602847","pt":1724593927772,"mc":[{"id":"1.232012908","rc":[{"batb":[[0,2.04,18],[1,1.9,42.71],[2,1.74,17.32]],"ltp":2.1,"tv":270.08,"id":23387705}]}]}
{"op":"mcm","clk":"11961603243","pt":1724593930283,"mc":[{"id":"1.232012908","rc":[{"batb":[[0,2.06,5],[1,2.04,18],[2,1.9,42.71]],"ltp":2.1,"tv":270.08,"id":23387705}]}]}
{"op":"mcm","clk":"11961603834","pt":1724593933737,"mc":[{"id":"1.232012908","rc":[{"batb":[[0,2.04,18],[1,1.9,42.71],[2,1.74,17.32]],"ltp":2.1,"tv":270.08,"id":23387705}]}]}
{"op":"mcm","clk":"11961604379","pt":1724593937148,"mc":[{"id":"1.232012908","rc":[{"batb":[[0,2.06,5],[1,2.04,18],[2,1.9,42.71]],"ltp":2.1,"tv":270.08,"id":23387705}]}]}
{"op":"mcm","clk":"11961604877","pt":1724593940453,"mc":[{"id":"1.232012908","rc":[{"batb":[[0,2.04,18],[1,1.9,42.71],[2,1.74,17.32]],"ltp":2.1,"tv":270.08,"id":23387705}]}]}
{"op":"mcm","clk":"11961605256","pt":1724593942869,"mc":[{"id":"1.232012908","rc":[{"batb":[[0,2.06,5],[1,2.04,18],[2,1.9,42.71]],"ltp":2.1,"tv":270.08,"id":23387705}]}]}
{"op":"mcm","clk":"11961605842","pt":1724593946081,"mc":[{"id":"1.232012908","rc":[{"batb":[[0,2.04,18],[1,1.9,42.71],[2,1.74,17.32]],"ltp":2.1,"tv":270.08,"id":23387705}]}]}
{"op":"mcm","clk":"11961606725","pt":1724593951492,"mc":[{"id":"1.232012908","rc":[{"batb":[[0,2.06,5],[1,2.04,18],[2,1.9,42.71]],"ltp":2.1,"tv":270.08,"id":23387705}]}]}
{"op":"mcm","clk":"11961607215","pt":1724593954772,"mc":[{"id":"1.232012908","rc":[{"batb":[[0,2.04,18],[1,1.9,42.71],[2,1.74,17.32]],"ltp":2.1,"tv":270.08,"id":23387705}]}]}
{"op":"mcm","clk":"11961608720","pt":1724593963976,"mc":[{"id":"1.232012908","rc":[{"batb":[[0,2.06,5],[1,2.04,18],[2,1.9,42.71]],"ltp":2.1,"tv":270.08,"id":23387705}]}]}
{"op":"mcm","clk":"11961609229","pt":1724593967177,"mc":[{"id":"1.232012908","rc":[{"batb":[[0,2.04,18],[1,1.9,42.71],[2,1.74,17.32]],"ltp":2.1,"tv":270.08,"id":23387705}]}]}
{"op":"mcm","clk":"11961609607","pt":1724593970125,"mc":[{"id":"1.232012908","rc":[{"batb":[[0,2.06,5],[1,2.04,18],[2,1.9,42.71]],"ltp":2.1,"tv":270.08,"id":23387705}]}]}
{"op":"mcm","clk":"11961610037","pt":1724593973509,"mc":[{"id":"1.232012908","rc":[{"batb":[[0,2.04,18],[1,1.9,42.71],[2,1.74,17.32]],"ltp":2.1,"tv":270.08,"id":23387705}]}]}
{"op":"mcm","clk":"11961610357","pt":1724593976209,"mc":[{"id":"1.232012908","rc":[{"batb":[[0,2.06,5],[1,2.04,18],[2,1.9,42.71]],"ltp":2.1,"tv":270.08,"id":23387705}]}]}
{"op":"mcm","clk":"11961610820","pt":1724593979609,"mc":[{"id":"1.232012908","rc":[{"batb":[[0,2.04,18],[1,1.9,42.71],[2,1.74,17.32]],"ltp":2.1,"tv":270.08,"id":23387705}]}]}
{"op":"mcm","clk":"11961611126","pt":1724593981891,"mc":[{"id":"1.232012908","rc":[{"batb":[[0,2.06,5],[1,2.04,18],[2,1.9,42.71]],"ltp":2.1,"tv":270.08,"id":23387705}]}]}
{"op":"mcm","clk":"11961611526","pt":1724593985121,"mc":[{"id":"1.232012908","rc":[{"batb":[[0,2.04,18],[1,1.9,42.71],[2,1.74,17.32]],"ltp":2.1,"tv":270.08,"id":23387705}]}]}
{"op":"mcm","clk":"11961611897","pt":1724593987932,"mc":[{"id":"1.232012908","rc":[{"batb":[[0,2.06,5],[1,2.04,18],[2,1.9,42.71]],"ltp":2.1,"tv":270.08,"id":23387705}]}]}
{"op":"mcm","clk":"11961612363","pt":1724593991400,"mc":[{"id":"1.232012908","rc":[{"batb":[[0,2.04,18],[1,1.9,42.71],[2,1.74,17.32]],"ltp":2.1,"tv":270.08,"id":23387705}]}]}
{"op":"mcm","clk":"11961612820","pt":1724593995338,"mc":[{"id":"1.232012908","rc":[{"batb":[[0,2.06,5],[1,2.04,18],[2,1.9,42.71]],"ltp":2.1,"tv":270.08,"id":23387705}]}]}
{"op":"mcm","clk":"11961613248","pt":1724593999063,"mc":[{"id":"1.232012908","rc":[{"batb":[[0,2.04,18],[1,1.9,42.71],[2,1.74,17.32]],"ltp":2.1,"tv":270.08,"id":23387705}]}]}
{"op":"mcm","clk":"11961613788","pt":1724594002725,"mc":[{"id":"1.232012908","rc":[{"batb":[[0,2.06,5],[1,2.04,18],[2,1.9,42.71]],"ltp":2.1,"tv":270.08,"id":23387705}]}]}
{"op":"mcm","clk":"11961614210","pt":1724594006150,"mc":[{"id":"1.232012908","rc":[{"batb":[[0,2.04,18],[1,1.9,42.71],[2,1.74,17.32]],"ltp":2.1,"tv":270.08,"id":23387705}]}]}
{"op":"mcm","clk":"11961614575","pt":1724594008917,"mc":[{"id":"1.232012908","rc":[{"batb":[[0,2.06,5],[1,2.04,18],[2,1.9,42.71]],"ltp":2.1,"tv":270.08,"id":23387705}]}]}
{"op":"mcm","clk":"11961615058","pt":1724594012349,"mc":[{"id":"1.232012908","rc":[{"batb":[[0,2.04,18],[1,1.9,42.71],[2,1.74,17.32]],"ltp":2.1,"tv":270.08,"id":23387705}]}]}
{"op":"mcm","clk":"11961615416","pt":1724594015144,"mc":[{"id":"1.232012908","rc":[{"batb":[[0,2.06,5],[1,2.04,18],[2,1.9,42.71]],"ltp":2.1,"tv":270.08,"id":23387705}]}]}
{"op":"mcm","clk":"11961615860","pt":1724594018462,"mc":[{"id":"1.232012908","rc":[{"batb":[[0,2.04,18],[1,1.9,42.71],[2,1.74,17.32]],"ltp":2.1,"tv":270.08,"id":23387705}]}]}
{"op":"mcm","clk":"11961616226","pt":1724594021066,"mc":[{"id":"1.232012908","rc":[{"batb":[[0,2.06,5],[1,2.04,18],[2,1.9,42.71]],"ltp":2.1,"tv":270.08,"id":23387705}]}]}
{"op":"mcm","clk":"11961616685","pt":1724594024453,"mc":[{"id":"1.232012908","rc":[{"batb":[[0,2.04,18],[1,1.9,42.71],[2,1.74,17.32]],"ltp":2.1,"tv":270.08,"id":23387705}]}]}
{"op":"mcm","clk":"11961617343","pt":1724594028766,"mc":[{"id":"1.232012908","rc":[{"batb":[[0,2.06,5],[1,2.04,18],[2,1.9,42.71]],"ltp":2.1,"tv":270.08,"id":23387705}]}]}
{"op":"mcm","clk":"11961617788","pt":1724594032140,"mc":[{"id":"1.232012908","rc":[{"batb":[[0,2.04,18],[1,1.9,42.71],[2,1.74,17.32]],"ltp":2.1,"tv":270.08,"id":23387705}]}]}
{"op":"mcm","clk":"11961618456","pt":1724594037081,"mc":[{"id":"1.232012908","rc":[{"batb":[[0,2.06,5],[1,2.04,18],[2,1.9,42.71]],"ltp":2.1,"tv":270.08,"id":23387705}]}]}
