{"op":"mcm","clk":"11921622317","pt":1724157341578,"mc":[{"id":"1.232048948","marketDefinition":{"bspMarket":false,"turnInPlayEnabled":true,"persistenceEnabled":true,"marketBaseRate":5.0,"eventId":"33511211","eventTypeId":"4","numberOfWinners":1,"bettingType":"ODDS","marketType":"MATCH_ODDS","marketTime":"2024-08-21T16:30:00.000Z","suspendTime":"2024-08-21T16:30:00.000Z","bspReconciled":false,"complete":true,"inPlay":false,"crossMatching":true,"runnersVoidable":false,"numberOfActiveRunners":2,"betDelay":0,"status":"OPEN","runners":[{"status":"ACTIVE","sortPriority":1,"id":67083366,"name":"New York Strikers"},{"status":"ACTIVE","sortPriority":2,"id":72857114,"name":"Boca Raton Trailblazers"}],"regulators":["MR_INT"],"countryCode":"GB","discountAllowed":false,"timezone":"GMT","openDate":"2024-08-21T16:30:00.000Z","version":6087504839,"name":"Match Odds","eventName":"New York Strikers v Boca Raton Trailblazers"},"rc":[{"batb":[[0,1.01,20]],"ltp":0.0,"tv":0.0,"id":72857114},{"batb":[[0,1.01,20]],"ltp":0.0,"tv":0.0,"id":67083366}]}]}
{"op":"mcm","clk":"11921622383","pt":1724157342603,"mc":[{"id":"1.232048948","rc":[{"batb":[[0,1.03,200],[1,1.02,200],[2,1.01,220]],"ltp":0.0,"tv":0.0,"id":72857114},{"batb":[[0,1.03,200],[1,1.02,200],[2,1.01,220]],"ltp":0.0,"tv":0.0,"id":67083366}]}]}
{"op":"mcm","clk":"11921622435","pt":1724157343339,"mc":[{"id":"1.232048948","marketDefinition":{"bspMarket":false,"turnInPlayEnabled":true,"persistenceEnabled":true,"marketBaseRate":5.0,"eventId":"33511211","eventTypeId":"4","numberOfWinners":1,"bettingType":"ODDS","marketType":"MATCH_ODDS","marketTime":"2024-08-21T16:30:00.000Z","suspendTime":"2024-08-21T16:30:00.000Z","bspReconciled":false,"complete":true,"inPlay":false,"crossMatching":true,"runnersVoidable":false,"numberOfActiveRunners":2,"betDelay":0,"status":"OPEN","runners":[{"status":"ACTIVE","sortPriority":1,"id":67083366,"name":"New York Strikers"},{"status":"ACTIVE","sortPriority":2,"id":72857114,"name":"Boca Raton Trailblazers"}],"regulators":["MR_INT"],"countryCode":"GB","discountAllowed":true,"timezone":"GMT","openDate":"2024-08-21T16:30:00.000Z","version":6087504839,"name":"Match Odds","eventName":"New York Strikers v Boca Raton Trailblazers"}}]}
{"op":"mcm","clk":"11921805560","pt":1724160652323,"mc":[{"id":"1.232048948","rc":[{"batb":[[2,1.01,481.95]],"ltp":0.0,"tv":0.0,"id":72857114},{"batb":[[2,1.01,481.95]],"ltp":0.0,"tv":0.0,"id":67083366}]}]}
{"op":"mcm","clk":"11921916753","pt":1724162695455,"mc":[{"id":"1.232048948","rc":[{"batb":[[0,1.03,205.19],[2,1.01,482.04]],"ltp":0.0,"tv":0.0,"id":72857114},{"batb":[[2,1.01,482.04]],"ltp":0.0,"tv":0.0,"id":67083366}]}]}
{"op":"mcm","clk":"11922251526","pt":1724167953092,"mc":[{"id":"1.232048948","rc":[{"batb":[[0,1.43,116.28],[1,1.33,151.52],[2,1.28,178.57]],"ltp":0.0,"tv":0.0,"id":72857114},{"batb":[[0,1.43,116.28],[1,1.33,151.52],[2,1.28,178.57]],"ltp":0.0,"tv":0.0,"id":67083366}]}]}
{"op":"mcm","clk":"11922351410","pt":1724168983926,"mc":[{"id":"1.232048948","rc":[{"batb":[[0,1.44,6.48],[1,1.43,116.28],[2,1.33,151.52]],"ltp":0.0,"tv":0.0,"id":72857114},{"batb":[[0,1.44,7.31],[1,1.43,116.28],[2,1.33,151.52]],"ltp":0.0,"tv":0.0,"id":67083366}]}]}
{"op":"mcm","clk":"11922376688","pt":1724169303556,"mc":[{"id":"1.232048948","rc":[{"batb":[[0,1.44,12.51]],"ltp":0.0,"tv":0.0,"id":72857114},{"batb":[[0,1.44,13.38]],"ltp":0.0,"tv":0.0,"id":67083366}]}]}
{"op":"mcm","clk":"11922878161","pt":1724173974930,"mc":[{"id":"1.232048948","rc":[{"batb":[[0,1.44,12.51]],"ltp":0.0,"tv":0.0,"id":72857114},{"batb":[[0,1.44,13.39]],"ltp":0.0,"tv":0.0,"id":67083366}]}]}
{"op":"mcm","clk":"11923134176","pt":1724176207895,"mc":[{"id":"1.232048948","rc":[{"batb":[[0,1.44,13.4]],"ltp":0.0,"tv":0.0,"id":72857114}]}]}
{"op":"mcm","clk":"11923134815","pt":1724176213699,"mc":[{"id":"1.232048948","rc":[{"batb":[[0,1.44,12.51]],"ltp":0.0,"tv":0.0,"id":72857114}]}]}
{"op":"mcm","clk":"11923534372","pt":1724179355491,"mc":[{"id":"1.232048948","rc":[{"batb":[[0,1.44,12.52]],"ltp":0.0,"tv":0.0,"id":72857114},{"batb":[[0,1.44,13.4]],"batl":[[0,1.5,1.23]],"ltp":0.0,"tv":0.0,"id":67083366}]}]}
{"op":"mcm","clk":"11923548688","pt":1724179386419,"mc":[{"id":"1.232048948","rc":[{"batb":[[0,1.9,1.23],[1,1.44,12.52],[2,1.43,116.28]],"ltp":0.0,"tv":0.0,"id":72857114}]}]}
{"op":"mcm","clk":"11923549823","pt":1724179394914,"mc":[{"id":"1.232048948","rc":[{"batb":[[0,1.44,12.52],[1,1.43,116.28],[2,1.33,151.52]],"ltp":0.0,"tv":0.0,"id":72857114}]}]}
{"op":"mcm","clk":"11923551419","pt":1724179407740,"mc":[{"id":"1.232048948","rc":[{"batb":[[0,3,1.23],[1,1.44,12.52],[2,1.43,116.28]],"ltp":0.0,"tv":0.0,"id":72857114}]}]}
{"op":"mcm","clk":"11923552083","pt":1724179412867,"mc":[{"id":"1.232048948","rc":[{"trd":[[3,1.23]],"batb":[[0,1.44,12.52],[1,1.43,116.28],[2,1.33,151.52]],"ltp":3.0,"tv":1.22,"id":72857114},{"trd":[[1.5,2.46]],"batb":[[0,1.5,1.12],[1,1.44,13.4],[2,1.43,116.28]],"ltp":1.5,"tv":2.45,"id":67083366}],"tv":3.68}]}
{"op":"mcm","clk":"11923552585","pt":1724179416949,"mc":[{"id":"1.232048948","rc":[{"batb":[[0,1.44,13.4],[1,1.43,116.28],[2,1.33,151.52]],"ltp":1.5,"tv":2.45,"id":67083366}]}]}
{"op":"mcm","clk":"11923555318","pt":1724179438670,"mc":[{"id":"1.232048948","rc":[{"batb":[[0,2,1.23],[1,1.44,12.52],[2,1.43,116.28]],"ltp":3.0,"tv":1.22,"id":72857114}]}]}
{"op":"mcm","clk":"11923557084","pt":1724179450375,"mc":[{"id":"1.232048948","rc":[{"batb":[[0,1.44,12.52],[1,1.43,116.28],[2,1.33,151.52]],"ltp":3.0,"tv":1.22,"id":72857114}]}]}
{"op":"mcm","clk":"11923560487","pt":1724179474604,"mc":[{"id":"1.232048948","rc":[{"batb":[[0,2,1.23],[1,1.44,13.4],[2,1.43,116.28]],"ltp":1.5,"tv":2.45,"id":67083366}]}]}
{"op":"mcm","clk":"11923561042","pt":1724179478832,"mc":[{"id":"1.232048948","rc":[{"trd":[[2,2.46]],"batb":[[0,1.44,13.4],[1,1.43,116.28],[2,1.33,151.52]],"batl":[[0,2,2.34]],"ltp":2.0,"tv":4.91,"id":67083366}],"tv":6.14}]}
{"op":"mcm","clk":"11923564373","pt":1724179501847,"mc":[{"id":"1.232048948","rc":[{"batb":[[0,2,1.23],[1,1.44,13.4],[2,1.43,116.28]],"ltp":2.0,"tv":4.91,"id":67083366}]}]}
{"op":"mcm","clk":"11923565561","pt":1724179509139,"mc":[{"id":"1.232048948","rc":[{"batb":[[0,1.44,13.4],[1,1.43,116.28],[2,1.33,151.52]],"ltp":2.0,"tv":4.91,"id":67083366}]}]}
{"op":"mcm","clk":"11923572633","pt":1724179553614,"mc":[{"id":"1.232048948","rc":[{"batb":[[0,2,1.23],[1,1.44,12.52],[2,1.43,116.28]],"ltp":3.0,"tv":1.22,"id":72857114}]}]}
{"op":"mcm","clk":"11923574392","pt":1724179563629,"mc":[{"id":"1.232048948","rc":[{"batb":[[0,1.44,12.52],[1,1.43,116.28],[2,1.33,151.52]],"ltp":3.0,"tv":1.22,"id":72857114}]}]}
{"op":"mcm","clk":"11923577710","pt":1724179581959,"mc":[{"id":"1.232048948","rc":[{"batb":[[0,1.9,1.23],[1,1.44,12.52],[2,1.43,116.28]],"ltp":3.0,"tv":1.22,"id":72857114}]}]}
{"op":"mcm","clk":"11923578711","pt":1724179588081,"mc":[{"id":"1.232048948","rc":[{"batb":[[0,1.44,12.52],[1,1.43,116.28],[2,1.33,151.52]],"ltp":3.0,"tv":1.22,"id":72857114}]}]}
{"op":"mcm","clk":"11923593625","pt":1724179675953,"mc":[{"id":"1.232048948","rc":[{"batl":[[0,1.6,0.77]],"ltp":3.0,"tv":1.22,"id":72857114}]}]}
{"op":"mcm","clk":"11923595402","pt":1724179686160,"mc":[{"id":"1.232048948","rc":[{"trd":[[1.44,1.7]],"batb":[[0,1.44,11.66]],"ltp":1.44,"tv":2.93,"id":72857114}],"tv":7.84}]}
{"op":"mcm","clk":"11924012372","pt":1724182177267,"mc":[{"id":"1.232048948","rc":[{"trd":[[1.44,1.7]],"batb":[[0,3,1.07],[1,1.44,11.66],[2,1.43,116.28]],"ltp":1.44,"tv":2.93,"id":72857114},{"trd":[[1.5,2.46],[2,2.46]],"batb":[[0,1.44,13.39]],"ltp":2.0,"tv":4.91,"id":67083366}],"tv":7.84}]}
{"op":"mcm","clk":"11924014428","pt":1724182189513,"mc":[{"id":"1.232048948","rc":[{"batb":[[0,1.44,11.66],[1,1.43,116.28],[2,1.33,151.52]],"ltp":1.44,"tv":2.93,"id":72857114}]}]}
{"op":"mcm","clk":"11924019257","pt":1724182218723,"mc":[{"id":"1.232048948","rc":[{"batb":[[0,3,1.07],[1,1.44,13.39],[2,1.43,116.28]],"ltp":2.0,"tv":4.91,"id":67083366}]}]}
{"op":"mcm","clk":"11924021031","pt":1724182228987,"mc":[{"id":"1.232048948","rc":[{"batb":[[0,1.44,13.39],[1,1.43,116.28],[2,1.33,151.52]],"ltp":2.0,"tv":4.91,"id":67083366}]}]}
{"op":"mcm","clk":"11924022327","pt":1724182236573,"mc":[{"id":"1.232048948","rc":[{"batb":[[0,3,1.07],[1,1.44,11.66],[2,1.43,116.28]],"ltp":1.44,"tv":2.93,"id":72857114}]}]}
{"op":"mcm","clk":"11924024796","pt":1724182251573,"mc":[{"id":"1.232048948","rc":[{"batb":[[0,1.44,11.66],[1,1.43,116.28],[2,1.33,151.52]],"ltp":1.44,"tv":2.93,"id":72857114}]}]}
{"op":"mcm","clk":"11924026391","pt":1724182261490,"mc":[{"id":"1.232048948","rc":[{"batb":[[0,3,1.07],[1,1.44,13.39],[2,1.43,116.28]],"ltp":2.0,"tv":4.91,"id":67083366}]}]}
{"op":"mcm","clk":"11924028301","pt":1724182273227,"mc":[{"id":"1.232048948","rc":[{"batb":[[0,1.44,13.39],[1,1.43,116.28],[2,1.33,151.52]],"ltp":2.0,"tv":4.91,"id":67083366}]}]}
{"op":"mcm","clk":"11924030022","pt":1724182283718,"mc":[{"id":"1.232048948","rc":[{"batb":[[0,3,1.07],[1,1.44,11.66],[2,1.43,116.28]],"ltp":1.44,"tv":2.93,"id":72857114}]}]}
{"op":"mcm","clk":"11924033384","pt":1724182303435,"mc":[{"id":"1.232048948","rc":[{"batb":[[0,1.44,11.66],[1,1.43,116.28],[2,1.33,151.52]],"ltp":1.44,"tv":2.93,"id":72857114}]}]}
{"op":"mcm","clk":"11924174126","pt":1724183447187,"mc":[{"id":"1.232048948","rc":[{"batl":[[0,1.48,1.15]],"ltp":1.44,"tv":2.93,"id":72857114}]}]}
{"op":"mcm","clk":"11924178101","pt":1724183475116,"mc":[{"id":"1.232048948","rc":[{"batl":[[0,1.48,1.15]],"ltp":2.0,"tv":4.91,"id":67083366}]}]}
{"op":"mcm","clk":"11924183965","pt":1724183516153,"mc":[{"id":"1.232048948","rc":[{"batl":[[0,1.48,1.15]],"ltp":1.44,"tv":2.93,"id":72857114}]}]}
{"op":"mcm","clk":"11924187860","pt":1724183543395,"mc":[{"id":"1.232048948","rc":[{"batl":[[0,1.48,1.15]],"ltp":2.0,"tv":4.91,"id":67083366}]}]}
{"op":"mcm","clk":"11924191677","pt":1724183571032,"mc":[{"id":"1.232048948","rc":[{"batl":[[0,1.48,1.15]],"ltp":1.44,"tv":2.93,"id":72857114}]}]}
{"op":"mcm","clk":"11924192067","pt":1724183573798,"mc":[{"id":"1.232048948","rc":[{"batb":[[0,1.48,3.57],[1,1.44,11.66],[2,1.43,116.28]],"ltp":1.44,"tv":2.93,"id":72857114}]}]}
{"op":"mcm","clk":"11924192738","pt":1724183578508,"mc":[{"id":"1.232048948","rc":[{"batb":[[0,1.44,11.66],[1,1.43,116.28],[2,1.33,151.52]],"ltp":1.44,"tv":2.93,"id":72857114}]}]}
{"op":"mcm","clk":"11924194879","pt":1724183594231,"mc":[{"id":"1.232048948","rc":[{"batl":[[0,1.48,1.15]],"ltp":2.0,"tv":4.91,"id":67083366}]}]}
{"op":"mcm","clk":"11924198157","pt":1724183616279,"mc":[{"id":"1.232048948","rc":[{"batl":[[0,1.48,1.15]],"ltp":1.44,"tv":2.93,"id":72857114}]}]}
{"op":"mcm","clk":"11924198671","pt":1724183619856,"mc":[{"id":"1.232048948","rc":[{"batb":[[0,1.48,3.57],[1,1.44,11.66],[2,1.43,116.28]],"ltp":1.44,"tv":2.93,"id":72857114}]}]}
{"op":"mcm","clk":"11924199348","pt":1724183624465,"mc":[{"id":"1.232048948","rc":[{"batb":[[0,1.44,11.66],[1,1.43,116.28],[2,1.33,151.52]],"ltp":1.44,"tv":2.93,"id":72857114}]}]}
{"op":"mcm","clk":"11924201135","pt":1724183637485,"mc":[{"id":"1.232048948","rc":[{"batl":[[0,1.48,1.15]],"ltp":2.0,"tv":4.91,"id":67083366}]}]}
{"op":"mcm","clk":"11924231490","pt":1724183866416,"mc":[{"id":"1.232048948","rc":[{"batl":[[0,1.48,1.15]],"ltp":1.44,"tv":2.93,"id":72857114}]}]}
{"op":"mcm","clk":"11924232571","pt":1724183874665,"mc":[{"id":"1.232048948","rc":[{"batl":[[0,1.48,1.15]],"ltp":2.0,"tv":4.91,"id":67083366}]}]}
{"op":"mcm","clk":"11924236448","pt":1724183904461,"mc":[{"id":"1.232048948","rc":[{"batl":[[0,1.48,1.15]],"ltp":1.44,"tv":2.93,"id":72857114}]}]}
{"op":"mcm","clk":"11924243526","pt":1724183958927,"mc":[{"id":"1.232048948","rc":[{"batl":[[0,1.48,1.15]],"ltp":2.0,"tv":4.91,"id":67083366}]}]}
{"op":"mcm","clk":"11924246534","pt":1724183982342,"mc":[{"id":"1.232048948","rc":[{"batl":[[0,1.48,1.15]],"ltp":1.44,"tv":2.93,"id":72857114}]}]}
{"op":"mcm","clk":"11924249801","pt":1724184008071,"mc":[{"id":"1.232048948","rc":[{"batb":[[0,1.44,13.39]],"batl":[[0,1.48,1.15]],"ltp":2.0,"tv":4.91,"id":67083366}],"tv":7.84}]}
{"op":"mcm","clk":"11924253330","pt":1724184035097,"mc":[{"id":"1.232048948","rc":[{"batl":[[0,1.48,1.15]],"ltp":1.44,"tv":2.93,"id":72857114}]}]}
{"op":"mcm","clk":"11924256251","pt":1724184057327,"mc":[{"id":"1.232048948","rc":[{"batl":[[0,1.48,1.15]],"ltp":2.0,"tv":4.91,"id":67083366}]}]}
{"op":"mcm","clk":"11924258754","pt":1724184077158,"mc":[{"id":"1.232048948","rc":[{"batl":[[0,1.48,1.15]],"ltp":1.44,"tv":2.93,"id":72857114}]}]}
{"op":"mcm","clk":"11924261652","pt":1724184099575,"mc":[{"id":"1.232048948","rc":[{"batl":[[0,1.48,1.15]],"ltp":2.0,"tv":4.91,"id":67083366}]}]}
{"op":"mcm","clk":"11924266320","pt":1724184136750,"mc":[{"id":"1.232048948","rc":[{"batl":[[0,1.48,1.15]],"ltp":1.44,"tv":2.93,"id":72857114}]}]}
{"op":"mcm","clk":"11924512674","pt":1724186172355,"mc":[{"id":"1.232048948","rc":[{"batl":[[0,1.48,1.15]],"ltp":2.0,"tv":4.91,"id":67083366}]}]}
{"op":"mcm","clk":"11924515419","pt":1724186206385,"mc":[{"id":"1.232048948","rc":[{"batl":[[0,1.48,1.15]],"ltp":1.44,"tv":2.93,"id":72857114}]}]}
{"op":"mcm","clk":"11924516027","pt":1724186214014,"mc":[{"id":"1.232048948","rc":[{"batl":[[0,1.48,1.15]],"ltp":2.0,"tv":4.91,"id":67083366}]}]}
{"op":"mcm","clk":"11924517667","pt":1724186233516,"mc":[{"id":"1.232048948","rc":[{"batl":[[0,1.48,1.15]],"ltp":1.44,"tv":2.93,"id":72857114}]}]}
{"op":"mcm","clk":"11924519088","pt":1724186251030,"mc":[{"id":"1.232048948","rc":[{"batl":[[0,1.48,1.15]],"ltp":2.0,"tv":4.91,"id":67083366}]}]}
{"op":"mcm","clk":"11924521042","pt":1724186278389,"mc":[{"id":"1.232048948","rc":[{"batl":[[0,1.48,1.15]],"ltp":1.44,"tv":2.93,"id":72857114}]}]}
{"op":"mcm","clk":"11924523930","pt":1724186319200,"mc":[{"id":"1.232048948","rc":[{"batl":[[0,1.48,1.15]],"ltp":2.0,"tv":4.91,"id":67083366}]}]}
{"op":"mcm","clk":"11924527108","pt":1724186365375,"mc":[{"id":"1.232048948","rc":[{"batl":[[0,1.48,1.15]],"ltp":1.44,"tv":2.93,"id":72857114}]}]}
{"op":"mcm","clk":"11924527485","pt":1724186370762,"mc":[{"id":"1.232048948","rc":[{"batl":[[0,3,24.62]],"ltp":2.0,"tv":4.91,"id":67083366}]}]}
{"op":"mcm","clk":"11924527615","pt":1724186372768,"mc":[{"id":"1.232048948","rc":[{"batb":[[0,1.44,5.62]],"ltp":1.44,"tv":2.93,"id":72857114}]}]}
{"op":"mcm","clk":"11924527967","pt":1724186377598,"mc":[{"id":"1.232048948","rc":[{"batl":[[0,3,24.62]],"ltp":1.44,"tv":2.93,"id":72857114}]}]}
{"op":"mcm","clk":"11924528052","pt":1724186378702,"mc":[{"id":"1.232048948","rc":[{"batb":[[0,1.44,7.31]],"ltp":2.0,"tv":4.91,"id":67083366}]}]}
{"op":"mcm","clk":"11924528571","pt":1724186386279,"mc":[{"id":"1.232048948","rc":[{"batl":[[0,1.53,1.15],[1,3,24.62]],"ltp":1.44,"tv":2.93,"id":72857114}]}]}
{"op":"mcm","clk":"11924528729","pt":1724186388384,"mc":[{"id":"1.232048948","rc":[{"batl":[[0,3,24.62],[1,3,0]],"ltp":1.44,"tv":2.93,"id":72857114}]}]}
{"op":"mcm","clk":"11924529393","pt":1724186398126,"mc":[{"id":"1.232048948","rc":[{"batl":[[0,1.53,1.15],[1,3,24.62]],"ltp":1.44,"tv":2.93,"id":72857114}]}]}
{"op":"mcm","clk":"11924529481","pt":1724186399897,"mc":[{"id":"1.232048948","rc":[{"batl":[[0,3,24.62],[1,3,0]],"ltp":1.44,"tv":2.93,"id":72857114}]}]}
{"op":"mcm","clk":"11924530075","pt":1724186409303,"mc":[{"id":"1.232048948","rc":[{"batl":[[0,1.53,1.15],[1,3,24.62]],"ltp":1.44,"tv":2.93,"id":72857114}]}]}
{"op":"mcm","clk":"11924530187","pt":1724186411225,"mc":[{"id":"1.232048948","rc":[{"batl":[[0,3,24.62],[1,3,0]],"ltp":1.44,"tv":2.93,"id":72857114}]}]}
{"op":"mcm","clk":"11924531565","pt":1724186433159,"mc":[{"id":"1.232048948","rc":[{"batl":[[0,1.53,1.15],[1,3,24.62]],"ltp":1.44,"tv":2.93,"id":72857114}]}]}
{"op":"mcm","clk":"11924531681","pt":1724186435084,"mc":[{"id":"1.232048948","rc":[{"batl":[[0,3,24.62],[1,3,0]],"ltp":1.44,"tv":2.93,"id":72857114}]}]}
{"op":"mcm","clk":"11924569492","pt":1724187268309,"mc":[{"id":"1.232048948","rc":[{"batb":[[0,1.44,11.61]],"ltp":1.44,"tv":2.93,"id":72857114},{"batb":[[0,1.44,13.38]],"ltp":2.0,"tv":4.91,"id":67083366}]}]}
{"op":"mcm","clk":"11924633820","pt":1724188938705,"mc":[{"id":"1.232048948","rc":[{"batb":[[0,1.44,11.61]],"ltp":1.44,"tv":2.93,"id":72857114},{"batb":[[0,1.44,13.38]],"ltp":2.0,"tv":4.9,"id":67083366}]}]}
{"op":"mcm","clk":"11924646170","pt":1724189276292,"mc":[{"id":"1.232048948","rc":[{"batb":[[0,1.44,12.61]],"ltp":1.44,"tv":2.93,"id":72857114}]}]}
{"op":"mcm","clk":"11924646391","pt":1724189282336,"mc":[{"id":"1.232048948","rc":[{"batb":[[0,1.44,11.61]],"ltp":1.44,"tv":2.93,"id":72857114}]}]}
{"op":"mcm","clk":"11924646862","pt":1724189293510,"mc":[{"id":"1.232048948","rc":[{"batb":[[0,2.5,1.07],[1,1.44,11.61],[2,1.43,116.28]],"ltp":1.44,"tv":2.93,"id":72857114}]}]}
{"op":"mcm","clk":"11924647201","pt":1724189303750,"mc":[{"id":"1.232048948","rc":[{"batb":[[0,1.44,11.61],[1,1.43,116.28],[2,1.33,151.52]],"ltp":1.44,"tv":2.93,"id":72857114}]}]}
{"op":"mcm","clk":"11924647883","pt":1724189319879,"mc":[{"id":"1.232048948","rc":[{"batb":[[0,2.7,1.07],[1,1.44,13.38],[2,1.43,116.28]],"ltp":2.0,"tv":4.9,"id":67083366}]}]}
{"op":"mcm","clk":"11924648412","pt":1724189330890,"mc":[{"id":"1.232048948","rc":[{"batb":[[0,1.44,13.38],[1,1.43,116.28],[2,1.33,151.52]],"ltp":2.0,"tv":4.9,"id":67083366}]}]}
{"op":"mcm","clk":"11924648955","pt":1724189344492,"mc":[{"id":"1.232048948","rc":[{"batb":[[0,2.7,1.07],[1,1.44,11.61],[2,1.43,116.28]],"ltp":1.44,"tv":2.93,"id":72857114}]}]}
{"op":"mcm","clk":"11924649405","pt":1724189355400,"mc":[{"id":"1.232048948","rc":[{"batb":[[0,1.44,11.61],[1,1.43,116.28],[2,1.33,151.52]],"ltp":1.44,"tv":2.93,"id":72857114}]}]}
{"op":"mcm","clk":"11924650414","pt":1724189381823,"mc":[{"id":"1.232048948","rc":[{"batb":[[0,3,1.07],[1,1.44,13.38],[2,1.43,116.28]],"ltp":2.0,"tv":4.9,"id":67083366}]}]}
{"op":"mcm","clk":"11924650967","pt":1724189394383,"mc":[{"id":"1.232048948","rc":[{"batb":[[0,1.44,13.38],[1,1.43,116.28],[2,1.33,151.52]],"ltp":2.0,"tv":4.9,"id":67083366}]}]}
{"op":"mcm","clk":"11924651642","pt":1724189407855,"mc":[{"id":"1.232048948","rc":[{"batb":[[0,3,1.07],[1,1.44,13.38],[2,1.43,116.28]],"ltp":2.0,"tv":4.9,"id":67083366}]}]}
{"op":"mcm","clk":"11924652196","pt":1724189419694,"mc":[{"id":"1.232048948","rc":[{"batb":[[0,1.44,13.38],[1,1.43,116.28],[2,1.33,151.52]],"ltp":2.0,"tv":4.9,"id":67083366}]}]}
{"op":"mcm","clk":"11924652983","pt":1724189437016,"mc":[{"id":"1.232048948","rc":[{"batb":[[0,3,1.07],[1,1.44,11.61],[2,1.43,116.28]],"ltp":1.44,"tv":2.93,"id":72857114}]}]}
{"op":"mcm","clk":"11924653352","pt":1724189444913,"mc":[{"id":"1.232048948","rc":[{"trd":[[3,2.3]],"batb":[[0,1.44,11.61],[1,1.43,116.28],[2,1.33,151.52]],"ltp":3.0,"tv":4.0,"id":72857114},{"trd":[[1.5,4.6]],"batb":[[0,1.44,14.18]],"ltp":1.5,"tv":7.05,"id":67083366}],"tv":11.06}]}
{"op":"mcm","clk":"11924654030","pt":1724189459273,"mc":[{"id":"1.232048948","rc":[{"batb":[[0,1.44,13.38]],"ltp":1.5,"tv":7.05,"id":67083366}]}]}
{"op":"mcm","clk":"11924654041","pt":1724189459422,"mc":[{"id":"1.232048948","rc":[{"batb":[[0,1.44,12.61]],"ltp":3.0,"tv":4.0,"id":72857114}]}]}
{"op":"mcm","clk":"11924654321","pt":1724189464916,"mc":[{"id":"1.232048948","rc":[{"trd":[[2.7,1]],"batb":[[0,1.44,11.61]],"ltp":2.7,"tv":5.0,"id":72857114},{"trd":[[1.59,1.69]],"batb":[[0,1.59,1.26],[1,1.44,13.38],[2,1.43,116.28]],"ltp":1.59,"tv":8.74,"id":67083366}],"tv":13.75}]}
{"op":"mcm","clk":"11924654466","pt":1724189467432,"mc":[{"id":"1.232048948","rc":[{"batb":[[0,1.44,13.38],[1,1.43,116.28],[2,1.33,151.52]],"ltp":1.59,"tv":8.74,"id":67083366}]}]}
{"op":"mcm","clk":"11924655705","pt":1724189492465,"mc":[{"id":"1.232048948","rc":[{"batb":[[0,1.44,12.61]],"ltp":2.7,"tv":5.0,"id":72857114}]}]}
{"op":"mcm","clk":"11924656303","pt":1724189504777,"mc":[{"id":"1.232048948","rc":[{"batb":[[0,1.44,11.61]],"ltp":2.7,"tv":5.0,"id":72857114}]}]}
{"op":"mcm","clk":"11924658245","pt":1724189552621,"mc":[{"id":"1.232048948","rc":[{"batb":[[0,2,1.07],[1,1.44,11.61],[2,1.43,116.28]],"ltp":2.7,"tv":5.0,"id":72857114}]}]}
{"op":"mcm","clk":"11924658510","pt":1724189558207,"mc":[{"id":"1.232048948","rc":[{"batb":[[0,1.44,11.61],[1,1.43,116.28],[2,1.33,151.52]],"ltp":2.7,"tv":5.0,"id":72857114}]}]}
{"op":"mcm","clk":"11924659275","pt":1724189576852,"mc":[{"id":"1.232048948","rc":[{"batb":[[0,1.44,12.61]],"ltp":2.7,"tv":5.0,"id":72857114}]}]}
{"op":"mcm","clk":"11924659380","pt":1724189580950,"mc":[{"id":"1.232048948","rc":[{"batl":[[0,1.98,3.94]],"ltp":1.59,"tv":8.74,"id":67083366}]}]}
{"op":"mcm","clk":"11924659465","pt":1724189582854,"mc":[{"id":"1.232048948","rc":[{"batb":[[0,1.44,11.61]],"ltp":2.7,"tv":5.0,"id":72857114}]}]}
{"op":"mcm","clk":"11924660502","pt":1724189602367,"mc":[{"id":"1.232048948","rc":[{"trd":[[1.98,5.96]],"batl":[[0,1.98,0.96]],"ltp":1.98,"tv":14.71,"id":67083366}],"tv":19.71}]}
{"op":"mcm","clk":"11924994162","pt":1724195574992,"mc":[{"id":"1.232048948","rc":[{"batb":[[0,1.44,11.61]],"ltp":2.7,"tv":5.0,"id":72857114},{"batb":[[0,1.44,13.39]],"ltp":1.98,"tv":14.71,"id":67083366}],"tv":19.71}]}
{"op":"mcm","clk":"11925296429","pt":1724200974988,"mc":[{"id":"1.232048948","rc":[{"batb":[[0,1.44,11.61]],"ltp":2.7,"tv":5.0,"id":72857114},{"batb":[[0,1.44,13.38]],"ltp":1.98,"tv":14.71,"id":67083366}],"tv":19.71}]}
{"op":"mcm","clk":"11925690907","pt":1724206375044,"mc":[{"id":"1.232048948","rc":[{"trd":[[1.44,1.7],[3,2.3]],"batb":[[0,1.44,11.61]],"ltp":2.7,"tv":5.0,"id":72857114},{"trd":[[1.98,5.97],[2,2.46]],"batb":[[0,1.44,13.39]],"ltp":1.98,"tv":14.71,"id":67083366}],"tv":19.72}]}
{"op":"mcm","clk":"11925833786","pt":1724209298883,"mc":[{"id":"1.232048948","rc":[{"batb":[[0,1.44,11.61]],"ltp":2.7,"tv":5.0,"id":72857114},{"batb":[[0,1.45,1.78],[1,1.44,13.39],[2,1.43,116.28]],"ltp":1.98,"tv":14.71,"id":67083366}],"tv":19.72}]}
{"op":"mcm","clk":"11925834353","pt":1724209309881,"mc":[{"id":"1.232048948","rc":[{"batb":[[0,1.45,1.78],[1,1.44,11.61],[2,1.43,116.28]],"ltp":2.7,"tv":5.0,"id":72857114}]}]}
{"op":"mcm","clk":"11925835307","pt":1724209328595,"mc":[{"id":"1.232048948","rc":[{"batb":[[0,1.46,1.78]],"ltp":1.98,"tv":14.71,"id":67083366}]}]}
{"op":"mcm","clk":"11926039362","pt":1724215136493,"mc":[{"id":"1.232048948","rc":[{"batb":[[0,1.45,2.72]],"ltp":2.7,"tv":5.0,"id":72857114}],"tv":19.72}]}
{"op":"mcm","clk":"11926039672","pt":1724215145873,"mc":[{"id":"1.232048948","rc":[{"batb":[[0,1.46,2.72]],"ltp":1.98,"tv":14.71,"id":67083366}]}]}
{"op":"mcm","clk":"11926134133","pt":1724217175002,"mc":[{"id":"1.232048948","tv":19.72}]}
{"op":"mcm","clk":"11926159815","pt":1724217695727,"mc":[{"id":"1.232048948","rc":[{"trd":[[1.6,0.94]],"batb":[[0,1.46,1.78]],"ltp":1.6,"tv":15.65,"id":67083366}],"tv":20.66}]}
{"op":"mcm","clk":"11926168684","pt":1724217919427,"mc":[{"id":"1.232048948","rc":[{"batb":[[0,1.46,2.72]],"ltp":1.6,"tv":15.65,"id":67083366}]}]}
{"op":"mcm","clk":"11926235206","pt":1724219536435,"mc":[{"id":"1.232048948","rc":[{"batb":[[0,1.55,1.47],[1,1.46,1.78],[2,1.44,13.38]],"ltp":1.6,"tv":15.65,"id":67083366}]}]}
{"op":"mcm","clk":"11926235780","pt":1724219547472,"mc":[{"id":"1.232048948","rc":[{"batb":[[0,1.55,1.47],[1,1.45,1.78],[2,1.44,11.61]],"ltp":2.7,"tv":5.0,"id":72857114}]}]}
{"op":"mcm","clk":"11926236189","pt":1724219555654,"mc":[{"id":"1.232048948","rc":[{"batb":[[0,1.6,1.47]],"ltp":2.7,"tv":5.0,"id":72857114}]}]}
{"op":"mcm","clk":"11926236708","pt":1724219564659,"mc":[{"id":"1.232048948","rc":[{"batb":[[0,1.6,1.47]],"ltp":1.6,"tv":15.65,"id":67083366}]}]}
{"op":"mcm","clk":"11926236916","pt":1724219570078,"mc":[{"id":"1.232048948","rc":[{"batb":[[0,1.6,1.43]],"ltp":2.7,"tv":5.0,"id":72857114}]}]}
{"op":"mcm","clk":"11926251145","pt":1724219923084,"mc":[{"id":"1.232048948","rc":[{"batl":[[0,1.65,1.15]],"ltp":1.6,"tv":15.65,"id":67083366}]}]}
{"op":"mcm","clk":"11926252286","pt":1724219958628,"mc":[{"id":"1.232048948","rc":[{"batl":[[0,1.69,1.15]],"ltp":2.7,"tv":5.0,"id":72857114}]}]}
{"op":"mcm","clk":"11926253320","pt":1724219993378,"mc":[{"id":"1.232048948","rc":[{"batl":[[0,1.65,1.15]],"ltp":1.6,"tv":15.65,"id":67083366}]}]}
{"op":"mcm","clk":"11926254423","pt":1724220017832,"mc":[{"id":"1.232048948","rc":[{"trd":[[3,2.3]],"batb":[[1,1.45,1.79],[2,1.44,11.61]],"batl":[[0,1.69,1.15]],"ltp":2.7,"tv":5.0,"id":72857114},{"trd":[[1.5,4.61],[1.98,5.97],[2,2.46]],"batb":[[1,1.46,1.79],[2,1.44,13.39]],"ltp":1.6,"tv":15.66,"id":67083366}],"tv":20.66}]}
{"op":"mcm","clk":"11926256065","pt":1724220047543,"mc":[{"id":"1.232048948","rc":[{"batl":[[0,1.65,1.15]],"ltp":1.6,"tv":15.66,"id":67083366}]}]}
{"op":"mcm","clk":"11926257045","pt":1724220069975,"mc":[{"id":"1.232048948","rc":[{"batl":[[0,1.69,1.15]],"ltp":2.7,"tv":5.0,"id":72857114}]}]}
{"op":"mcm","clk":"11926258160","pt":1724220096376,"mc":[{"id":"1.232048948","rc":[{"batl":[[0,1.65,1.15]],"ltp":1.6,"tv":15.66,"id":67083366}]}]}
{"op":"mcm","clk":"11926259310","pt":1724220122518,"mc":[{"id":"1.232048948","rc":[{"batb":[[1,1.44,11.61],[2,1.43,116.28]],"ltp":2.7,"tv":5.0,"id":72857114}]}]}
{"op":"mcm","clk":"11926259495","pt":1724220125918,"mc":[{"id":"1.232048948","rc":[{"batb":[[1,1.44,13.39],[2,1.43,116.28]],"ltp":1.6,"tv":15.66,"id":67083366}]}]}
{"op":"mcm","clk":"11926260161","pt":1724220141158,"mc":[{"id":"1.232048948","rc":[{"batl":[[0,1.69,1.15]],"ltp":2.7,"tv":5.0,"id":72857114}]}]}
{"op":"mcm","clk":"11926261213","pt":1724220165511,"mc":[{"id":"1.232048948","rc":[{"batl":[[0,1.65,1.15]],"ltp":1.6,"tv":15.66,"id":67083366}]}]}
{"op":"mcm","clk":"11926261953","pt":1724220184084,"mc":[{"id":"1.232048948","rc":[{"batl":[[0,1.69,1.15]],"ltp":2.7,"tv":5.0,"id":72857114}]}]}
{"op":"mcm","clk":"11926262925","pt":1724220204418,"mc":[{"id":"1.232048948","rc":[{"batl":[[0,1.65,1.15]],"ltp":1.6,"tv":15.66,"id":67083366}]}]}
{"op":"mcm","clk":"11926263936","pt":1724220224835,"mc":[{"id":"1.232048948","rc":[{"batl":[[0,1.69,1.15]],"ltp":2.7,"tv":5.0,"id":72857114}]}]}
{"op":"mcm","clk":"11926265318","pt":1724220259653,"mc":[{"id":"1.232048948","rc":[{"batl":[[0,1.65,1.15]],"ltp":1.6,"tv":15.66,"id":67083366}]}]}
{"op":"mcm","clk":"11926266241","pt":1724220285910,"mc":[{"id":"1.232048948","rc":[{"batl":[[0,1.69,1.15]],"ltp":2.7,"tv":5.0,"id":72857114}]}]}
{"op":"mcm","clk":"11926274489","pt":1724220485819,"mc":[{"id":"1.232048948","rc":[{"batb":[[0,1.44,12.51],[1,1.43,116.28],[2,1.33,151.52]],"ltp":2.7,"tv":5.0,"id":72857114}]}]}
{"op":"mcm","clk":"11926274673","pt":1724220490446,"mc":[{"id":"1.232048948","rc":[{"batb":[[0,1.44,14.33],[1,1.43,116.28],[2,1.33,151.52]],"ltp":1.6,"tv":15.66,"id":67083366}]}]}
{"op":"mcm","clk":"11926284882","pt":1724220752740,"mc":[{"id":"1.232048948","rc":[{"batb":[[0,1.44,12.53]],"ltp":2.7,"tv":5.0,"id":72857114}]}]}
{"op":"mcm","clk":"11926299254","pt":1724221082667,"mc":[{"id":"1.232048948","rc":[{"batl":[[0,1.65,1.15]],"ltp":1.6,"tv":15.66,"id":67083366}]}]}
{"op":"mcm","clk":"11926300300","pt":1724221109433,"mc":[{"id":"1.232048948","rc":[{"batl":[[0,1.66,1.15]],"ltp":2.7,"tv":5.0,"id":72857114}]}]}
{"op":"mcm","clk":"11926300822","pt":1724221120715,"mc":[{"id":"1.232048948","rc":[{"batl":[[0,1.63,1.15]],"ltp":1.6,"tv":15.66,"id":67083366}]}]}
{"op":"mcm","clk":"11926302303","pt":1724221157875,"mc":[{"id":"1.232048948","rc":[{"batb":[[0,1.63,1.98],[1,1.44,14.33],[2,1.43,116.28]],"ltp":1.6,"tv":15.66,"id":67083366}]}]}
{"op":"mcm","clk":"11926302647","pt":1724221165602,"mc":[{"id":"1.232048948","rc":[{"batb":[[0,1.6,1.88],[1,1.44,13.39]],"ltp":1.6,"tv":15.66,"id":67083366}]}]}
{"op":"mcm","clk":"11926303159","pt":1724221178089,"mc":[{"id":"1.232048948","rc":[{"batl":[[0,1.66,1.15]],"ltp":2.7,"tv":5.0,"id":72857114}]}]}
{"op":"mcm","clk":"11926303448","pt":1724221184500,"mc":[{"id":"1.232048948","rc":[{"batl":[[0,2.6,0.94]],"ltp":1.6,"tv":15.66,"id":67083366}]}]}
{"op":"mcm","clk":"11926303976","pt":1724221195754,"mc":[{"id":"1.232048948","rc":[{"batl":[[0,2.48,0.94]],"ltp":1.6,"tv":15.66,"id":67083366}]}]}
{"op":"mcm","clk":"11926304432","pt":1724221205829,"mc":[{"id":"1.232048948","rc":[{"batl":[[0,1.65,1.15],[1,2.48,0.94]],"ltp":1.6,"tv":15.66,"id":67083366}]}]}
{"op":"mcm","clk":"11926304575","pt":1724221208542,"mc":[{"id":"1.232048948","rc":[{"batl":[[0,2.48,0.94],[1,2.48,0]],"ltp":1.6,"tv":15.66,"id":67083366}]}]}
{"op":"mcm","clk":"11926304731","pt":1724221211825,"mc":[{"id":"1.232048948","rc":[{"batb":[[0,1.65,1.98],[1,1.6,1.88],[2,1.44,13.39]],"ltp":1.6,"tv":15.66,"id":67083366}]}]}
{"op":"mcm","clk":"11926304928","pt":1724221215974,"mc":[{"id":"1.232048948","rc":[{"batb":[[0,1.6,1.88],[1,1.44,13.39],[2,1.43,116.28]],"ltp":1.6,"tv":15.66,"id":67083366}]}]}
{"op":"mcm","clk":"11926305977","pt":1724221234173,"mc":[{"id":"1.232048948","rc":[{"batl":[[0,1.69,1.15]],"ltp":2.7,"tv":5.0,"id":72857114}]}]}
{"op":"mcm","clk":"11926307177","pt":1724221258805,"mc":[{"id":"1.232048948","rc":[{"batl":[[0,1.65,1.15],[1,2.48,0.94]],"ltp":1.6,"tv":15.66,"id":67083366}]}]}
{"op":"mcm","clk":"11926307259","pt":1724221260911,"mc":[{"id":"1.232048948","rc":[{"trd":[[1.65,2.3]],"batb":[[0,1.69,2.02],[1,1.6,1.88],[2,1.44,13.39]],"batl":[[0,2.48,0.94],[1,2.48,0]],"ltp":1.65,"tv":17.96,"id":67083366}],"tv":22.97}]}
{"op":"mcm","clk":"11926307493","pt":1724221265499,"mc":[{"id":"1.232048948","rc":[{"batb":[[0,1.6,1.88],[1,1.44,13.39],[2,1.43,116.28]],"ltp":1.65,"tv":17.96,"id":67083366}]}]}
{"op":"mcm","clk":"11926308979","pt":1724221298570,"mc":[{"id":"1.232048948","rc":[{"batl":[[0,1.69,1.15]],"ltp":2.7,"tv":5.0,"id":72857114}]}]}
{"op":"mcm","clk":"11926309940","pt":1724221317979,"mc":[{"id":"1.232048948","rc":[{"batl":[[0,1.7,1.15],[1,2.48,0.94]],"ltp":1.65,"tv":17.96,"id":67083366}]}]}
{"op":"mcm","clk":"11926310040","pt":1724221320288,"mc":[{"id":"1.232048948","rc":[{"batl":[[0,2.48,0.94],[1,2.48,0]],"ltp":1.65,"tv":17.96,"id":67083366}]}]}
{"op":"mcm","clk":"11926310838","pt":1724221338001,"mc":[{"id":"1.232048948","rc":[{"batl":[[0,1.69,1.15]],"ltp":2.7,"tv":5.0,"id":72857114}]}]}
{"op":"mcm","clk":"11926311902","pt":1724221360090,"mc":[{"id":"1.232048948","rc":[{"batl":[[0,1.72,1.15],[1,2.48,0.94]],"ltp":1.65,"tv":17.96,"id":67083366}]}]}
{"op":"mcm","clk":"11926311994","pt":1724221361832,"mc":[{"id":"1.232048948","rc":[{"batl":[[0,2.48,0.94],[1,2.48,0]],"ltp":1.65,"tv":17.96,"id":67083366}]}]}
{"op":"mcm","clk":"11926312290","pt":1724221368504,"mc":[{"id":"1.232048948","rc":[{"batb":[[0,1.44,14.33],[1,1.43,116.28],[2,1.33,151.52]],"ltp":1.65,"tv":17.96,"id":67083366}]}]}
{"op":"mcm","clk":"11926312930","pt":1724221381327,"mc":[{"id":"1.232048948","rc":[{"batl":[[0,1.69,1.15],[1,3,24.62]],"ltp":2.7,"tv":5.0,"id":72857114},{"batb":[[0,1.44,8.26]],"ltp":1.65,"tv":17.96,"id":67083366}]}]}
{"op":"mcm","clk":"11926313020","pt":1724221383131,"mc":[{"id":"1.232048948","rc":[{"batl":[[0,3,24.62],[1,3,0]],"ltp":2.7,"tv":5.0,"id":72857114}]}]}
{"op":"mcm","clk":"11926314027","pt":1724221402060,"mc":[{"id":"1.232048948","rc":[{"batl":[[0,1.65,1.15],[1,2.48,0.94]],"ltp":1.65,"tv":17.96,"id":67083366}]}]}
{"op":"mcm","clk":"11926314129","pt":1724221404163,"mc":[{"id":"1.232048948","rc":[{"batl":[[0,2.48,0.94],[1,2.48,0]],"ltp":1.65,"tv":17.96,"id":67083366}]}]}
{"op":"mcm","clk":"11926314170","pt":1724221404837,"mc":[{"id":"1.232048948","rc":[{"batb":[[0,1.64,1.98],[1,1.44,8.26],[2,1.43,116.28]],"ltp":1.65,"tv":17.96,"id":67083366}]}]}
{"op":"mcm","clk":"11926314582","pt":1724221413639,"mc":[{"id":"1.232048948","rc":[{"batb":[[0,1.65,2.02]],"ltp":1.65,"tv":17.96,"id":67083366}]}]}
{"op":"mcm","clk":"11926314736","pt":1724221417573,"mc":[{"id":"1.232048948","rc":[{"batb":[[0,1.44,8.26],[1,1.43,116.28],[2,1.33,151.52]],"ltp":1.65,"tv":17.96,"id":67083366}]}]}
{"op":"mcm","clk":"11926315219","pt":1724221429673,"mc":[{"id":"1.232048948","rc":[{"batl":[[0,1.69,1.15],[1,3,24.62]],"ltp":2.7,"tv":5.0,"id":72857114}]}]}
{"op":"mcm","clk":"11926315313","pt":1724221431879,"mc":[{"id":"1.232048948","rc":[{"batl":[[0,3,24.62],[1,3,0]],"ltp":2.7,"tv":5.0,"id":72857114}]}]}
{"op":"mcm","clk":"11926315356","pt":1724221432954,"mc":[{"id":"1.232048948","rc":[{"batb":[[0,1.64,1.89],[1,1.44,11.61],[2,1.43,116.28]],"ltp":2.7,"tv":5.0,"id":72857114}]}]}
{"op":"mcm","clk":"11926319371","pt":1724221524689,"mc":[{"id":"1.232048948","rc":[{"batl":[[0,2.48,1.37]],"ltp":1.65,"tv":17.96,"id":67083366}]}]}
{"op":"mcm","clk":"11926319552","pt":1724221529576,"mc":[{"id":"1.232048948","rc":[{"batb":[[0,1.44,7.32]],"ltp":1.65,"tv":17.96,"id":67083366}]}]}
{"op":"mcm","clk":"11926319751","pt":1724221533975,"mc":[{"id":"1.232048948","rc":[{"trd":[[1.67,0.14],[1.69,1.96]],"batb":[[0,1.44,11.61],[1,1.43,116.28],[2,1.33,151.52]],"ltp":1.67,"tv":7.1,"id":72857114},{"trd":[[2.48,0.09]],"batl":[[0,2.48,1.28]],"ltp":2.48,"tv":18.05,"id":67083366}],"tv":25.16}]}
{"op":"mcm","clk":"11926320541","pt":1724221554005,"mc":[{"id":"1.232048948","rc":[{"batb":[[0,1.44,8.3]],"ltp":2.48,"tv":18.05,"id":67083366}]}]}
{"op":"mcm","clk":"11926320676","pt":1724221557529,"mc":[{"id":"1.232048948","rc":[{"batl":[[0,2.48,2.22]],"ltp":2.48,"tv":18.05,"id":67083366}]}]}
{"op":"mcm","clk":"11926320926","pt":1724221562736,"mc":[{"id":"1.232048948","rc":[{"batb":[[0,1.6,1.96],[1,1.44,7.32],[2,1.43,116.28]],"ltp":2.48,"tv":18.05,"id":67083366}]}]}
{"op":"mcm","clk":"11926321223","pt":1724221570630,"mc":[{"id":"1.232048948","rc":[{"batb":[[0,1.61,1.96],[1,1.44,8.3]],"ltp":2.48,"tv":18.05,"id":67083366}]}]}
{"op":"mcm","clk":"11926321938","pt":1724221585653,"mc":[{"id":"1.232048948","rc":[{"batl":[[1,3,24.62]],"ltp":2.48,"tv":18.05,"id":67083366}]}]}
{"op":"mcm","clk":"11926321985","pt":1724221587135,"mc":[{"id":"1.232048948","rc":[{"batb":[[0,1.44,5.63]],"ltp":1.67,"tv":7.1,"id":72857114}]}]}
{"op":"mcm","clk":"11926323690","pt":1724221626916,"mc":[{"id":"1.232048948","rc":[{"batl":[[0,2.44,35.73],[1,3,24.62]],"ltp":1.67,"tv":7.1,"id":72857114}]}]}
{"op":"mcm","clk":"11926335322","pt":1724221934879,"mc":[{"id":"1.232048948","rc":[{"batb":[[0,1.51,5.63]],"ltp":1.67,"tv":7.1,"id":72857114},{"batb":[[0,1.7,7.32],[1,1.61,1.96],[2,1.43,117.26]],"ltp":2.48,"tv":18.05,"id":67083366}]}]}
{"op":"mcm","clk":"11926599921","pt":1724227974947,"mc":[{"id":"1.232048948","rc":[{"trd":[[3,2.31]],"batb":[[0,1.51,5.63]],"batl":[[0,2.44,35.74]],"ltp":1.67,"tv":7.11,"id":72857114},{"trd":[[1.98,5.97]],"batb":[[0,1.7,7.32]],"ltp":2.48,"tv":18.06,"id":67083366}],"tv":25.17}]}
{"op":"mcm","clk":"11926691923","pt":1724229698944,"mc":[{"id":"1.232048948","rc":[{"batl":[[1,3,0]],"ltp":1.67,"tv":7.11,"id":72857114},{"batb":[[1,1.43,116.28],[2,1.33,151.52]],"batl":[[1,3,0]],"ltp":2.48,"tv":18.06,"id":67083366}]}]}
{"op":"mcm","clk":"11926726260","pt":1724230344197,"mc":[{"id":"1.232048948","rc":[{"batb":[[0,1.44,5.63]],"ltp":1.67,"tv":7.11,"id":72857114},{"batb":[[0,1.43,116.28],[1,1.33,151.52],[2,1.28,178.57]],"ltp":2.48,"tv":18.06,"id":67083366}]}]}
{"op":"mcm","clk":"11926727051","pt":1724230359395,"mc":[{"id":"1.232048948","rc":[{"batb":[[0,1.44,11.35]],"ltp":1.67,"tv":7.11,"id":72857114}]}]}
{"op":"mcm","clk":"11926848840","pt":1724232583939,"mc":[{"id":"1.232048948","rc":[{"batb":[[0,1.44,11.35],[1,1.04,1.53],[2,1.03,205.19]],"batl":[[0,2.44,35.73]],"ltp":1.67,"tv":7.11,"id":72857114},{"batb":[[0,1.04,1.53],[1,1.03,200],[2,1.02,200]],"ltp":2.48,"tv":18.06,"id":67083366}]}]}
{"op":"mcm","clk":"11926849012","pt":1724232587238,"mc":[{"id":"1.232048948","rc":[{"batb":[[0,1.44,5.63]],"ltp":1.67,"tv":7.11,"id":72857114}]}]}
{"op":"mcm","clk":"11926999446","pt":1724234575562,"mc":[{"id":"1.232048948","rc":[{"trd":[[1.44,1.7],[3,2.3]],"batb":[[0,1.04,1.53],[1,1.03,205.19],[2,1.02,200]],"batl":[[0,2.44,35.69]],"ltp":1.67,"tv":7.1,"id":72857114},{"trd":[[1.5,4.6],[1.6,0.94],[1.65,2.3],[1.98,5.97],[2,2.46]],"batl":[[0,2.48,2.21]],"ltp":2.48,"tv":18.04,"id":67083366}],"tv":25.15}]}
{"op":"mcm","clk":"11927023444","pt":1724234828862,"mc":[{"id":"1.232048948","rc":[{"batl":[[0,2.4,1.78],[1,2.44,35.69]],"ltp":1.67,"tv":7.1,"id":72857114}]}]}
{"op":"mcm","clk":"11927026733","pt":1724234858485,"mc":[{"id":"1.232048948","rc":[{"batl":[[0,2.44,35.69],[1,2.44,0]],"ltp":1.67,"tv":7.1,"id":72857114}]}]}
{"op":"mcm","clk":"11927250455","pt":1724237140007,"mc":[{"id":"1.232048948","rc":[{"batb":[[0,1.68,12.61],[1,1.04,1.53],[2,1.03,205.19]],"ltp":1.67,"tv":7.1,"id":72857114}]}]}
{"op":"mcm","clk":"11927288775","pt":1724237508432,"mc":[{"id":"1.232048948","rc":[{"batb":[[0,1.04,2.07]],"ltp":2.48,"tv":18.04,"id":67083366}]}]}
{"op":"mcm","clk":"11927403347","pt":1724238774960,"mc":[{"id":"1.232048948","rc":[{"trd":[[1.44,1.7],[1.69,1.96],[2.7,1],[3,2.3]],"batb":[[0,1.68,12.61]],"ltp":1.67,"tv":7.09,"id":72857114},{"trd":[[1.5,4.6],[1.6,0.94],[1.65,2.3],[1.98,5.96],[2,2.45]],"batl":[[0,2.48,2.21]],"ltp":2.48,"tv":18.03,"id":67083366}],"tv":25.13}]}
{"op":"mcm","clk":"11927426095","pt":1724238940231,"mc":[{"id":"1.232048948","rc":[{"batb":[[0,1.04,1.53],[1,1.03,205.19],[2,1.02,200]],"ltp":1.67,"tv":7.09,"id":72857114}]}]}
{"op":"mcm","clk":"11927428107","pt":1724238959320,"mc":[{"id":"1.232048948","rc":[{"trd":[[1.2,1.07]],"batb":[[0,1.04,1.53]],"batl":[[0,2.3,1.93],[1,2.48,1.27]],"ltp":1.2,"tv":19.1,"id":67083366}],"tv":26.2}]}
{"op":"mcm","clk":"11927428473","pt":1724238962849,"mc":[{"id":"1.232048948","rc":[{"batb":[[0,1.68,12.61],[1,1.04,1.53],[2,1.03,205.19]],"ltp":1.67,"tv":7.09,"id":72857114}]}]}
{"op":"mcm","clk":"11927429384","pt":1724238971244,"mc":[{"id":"1.232048948","rc":[{"batl":[[0,2.48,2.21],[1,2.48,0]],"ltp":1.2,"tv":19.1,"id":67083366}]}]}
{"op":"mcm","clk":"11927430509","pt":1724238980442,"mc":[{"id":"1.232048948","rc":[{"batl":[[0,1.06,1.53],[1,2.48,2.21]],"ltp":1.2,"tv":19.1,"id":67083366}]}]}
{"op":"mcm","clk":"11927431497","pt":1724238989436,"mc":[{"id":"1.232048948","rc":[{"batl":[[0,2.48,2.21],[1,2.48,0]],"ltp":1.2,"tv":19.1,"id":67083366}]}]}
{"op":"mcm","clk":"11927453664","pt":1724239206753,"mc":[{"id":"1.232048948","rc":[{"batb":[[0,1.04,3.06]],"ltp":1.2,"tv":19.1,"id":67083366}]}]}
{"op":"mcm","clk":"11927454054","pt":1724239210440,"mc":[{"id":"1.232048948","rc":[{"batb":[[0,1.04,1.53]],"ltp":1.2,"tv":19.1,"id":67083366}]}]}
{"op":"mcm","clk":"11927455546","pt":1724239225433,"mc":[{"id":"1.232048948","rc":[{"batb":[[0,1.06,1.53],[1,1.04,1.53],[2,1.03,200]],"ltp":1.2,"tv":19.1,"id":67083366}]}]}
{"op":"mcm","clk":"11927459588","pt":1724239268391,"mc":[{"id":"1.232048948","rc":[{"batb":[[0,1.04,1.53],[1,1.03,200],[2,1.02,200]],"ltp":1.2,"tv":19.1,"id":67083366}]}]}
{"op":"mcm","clk":"11927470410","pt":1724239385517,"mc":[{"id":"1.232048948","rc":[{"batl":[[0,1.06,1.53],[1,2.48,2.21]],"ltp":1.2,"tv":19.1,"id":67083366}]}]}
{"op":"mcm","clk":"11927470849","pt":1724239391465,"mc":[{"id":"1.232048948","rc":[{"trd":[[1.06,3.07]],"batb":[[0,1.06,2.03],[1,1.04,1.53],[2,1.03,200]],"batl":[[0,2.48,2.21],[1,2.48,0]],"ltp":1.06,"tv":22.17,"id":67083366}],"tv":29.27}]}
{"op":"mcm","clk":"11927471373","pt":1724239398568,"mc":[{"id":"1.232048948","rc":[{"batb":[[0,1.04,1.53],[1,1.03,200],[2,1.02,200]],"ltp":1.06,"tv":22.17,"id":67083366}]}]}
{"op":"mcm","clk":"11927474091","pt":1724239433788,"mc":[{"id":"1.232048948","rc":[{"trd":[[2.3,1.87]],"batb":[[0,1.04,1.58]],"batl":[[0,2.48,1.27]],"ltp":2.3,"tv":24.04,"id":67083366}],"tv":31.14}]}
{"op":"mcm","clk":"11927474443","pt":1724239438090,"mc":[{"id":"1.232048948","rc":[{"batb":[[0,1.04,1.53]],"ltp":2.3,"tv":24.04,"id":67083366}]}]}
{"op":"mcm","clk":"11927477970","pt":1724239481450,"mc":[{"id":"1.232048948","rc":[{"batb":[[0,1.68,13.14]],"ltp":1.67,"tv":7.09,"id":72857114}]}]}
{"op":"mcm","clk":"11927480968","pt":1724239518510,"mc":[{"id":"1.232048948","rc":[{"batb":[[0,1.04,2.07]],"ltp":2.3,"tv":24.04,"id":67083366}]}]}
{"op":"mcm","clk":"11927481952","pt":1724239529540,"mc":[{"id":"1.232048948","rc":[{"batb":[[0,1.05,57.93],[1,1.04,1.53],[2,1.03,200]],"ltp":2.3,"tv":24.04,"id":67083366}]}]}
{"op":"mcm","clk":"11927482296","pt":1724239533646,"mc":[{"id":"1.232048948","rc":[{"batb":[[0,1.04,2.07],[1,1.03,200],[2,1.02,200]],"ltp":2.3,"tv":24.04,"id":67083366}]}]}
{"op":"mcm","clk":"11927486750","pt":1724239586680,"mc":[{"id":"1.232048948","rc":[{"batb":[[1,1.61,9.77],[2,1.04,1.53]],"ltp":1.67,"tv":7.09,"id":72857114}]}]}
{"op":"mcm","clk":"11927490417","pt":1724239630040,"mc":[{"id":"1.232048948","rc":[{"trd":[[1.2,2.14]],"batb":[[0,1.04,1.53]],"batl":[[0,2.48,1.86]],"ltp":1.2,"tv":25.11,"id":67083366}],"tv":32.21}]}
{"op":"mcm","clk":"11927490705","pt":1724239632727,"mc":[{"id":"1.232048948","rc":[{"batl":[[0,2.48,1.27]],"ltp":1.2,"tv":25.11,"id":67083366}]}]}
{"op":"mcm","clk":"11927492046","pt":1724239648486,"mc":[{"id":"1.232048948","rc":[{"batl":[[0,1.08,1.12],[1,2.48,1.27]],"ltp":1.2,"tv":25.11,"id":67083366}]}]}
{"op":"mcm","clk":"11927492407","pt":1724239652796,"mc":[{"id":"1.232048948","rc":[{"trd":[[1.08,2.24]],"batb":[[0,1.08,56.27],[1,1.04,1.53],[2,1.03,200]],"batl":[[0,2.48,1.27],[1,2.48,0]],"ltp":1.08,"tv":27.35,"id":67083366}],"tv":34.45}]}
{"op":"mcm","clk":"11927492664","pt":1724239655903,"mc":[{"id":"1.232048948","rc":[{"batb":[[0,1.04,1.53],[1,1.03,200],[2,1.02,200]],"ltp":1.08,"tv":27.35,"id":67083366}]}]}
{"op":"mcm","clk":"11927495861","pt":1724239695536,"mc":[{"id":"1.232048948","rc":[{"trd":[[2,0.54]],"batb":[[0,1.68,12.61]],"ltp":2.0,"tv":7.63,"id":72857114},{"trd":[[2,2.99]],"batb":[[0,1.04,2.11]],"ltp":2.0,"tv":27.89,"id":67083366}],"tv":35.52}]}
{"op":"mcm","clk":"11927496048","pt":1724239697525,"mc":[{"id":"1.232048948","rc":[{"batb":[[0,1.04,1.53]],"ltp":2.0,"tv":27.89,"id":67083366}]}]}
{"op":"mcm","clk":"11927496871","pt":1724239706932,"mc":[{"id":"1.232048948","rc":[{"batb":[[0,2,1.12],[1,1.04,1.53],[2,1.03,200]],"ltp":2.0,"tv":27.89,"id":67083366}]}]}
{"op":"mcm","clk":"11927497292","pt":1724239711849,"mc":[{"id":"1.232048948","rc":[{"trd":[[2,5.23]],"batb":[[0,1.04,1.53],[1,1.03,200],[2,1.02,200]],"batl":[[0,2,43.44],[1,2.48,1.27]],"ltp":2.0,"tv":30.13,"id":67083366}],"tv":37.76}]}
{"op":"mcm","clk":"11927497548","pt":1724239714954,"mc":[{"id":"1.232048948","rc":[{"batl":[[0,2.48,1.27],[1,2.48,0]],"ltp":2.0,"tv":30.13,"id":67083366}]}]}
{"op":"mcm","clk":"11927499603","pt":1724239739685,"mc":[{"id":"1.232048948","rc":[{"batl":[[0,1.1,1.12],[1,2.48,1.27]],"ltp":2.0,"tv":30.13,"id":67083366}]}]}
{"op":"mcm","clk":"11927499826","pt":1724239742494,"mc":[{"id":"1.232048948","rc":[{"trd":[[1.1,2.24]],"batb":[[0,2,35.65],[1,1.1,43.44],[2,1.04,1.53]],"batl":[[0,2.48,1.27],[1,2.48,0]],"ltp":1.1,"tv":32.37,"id":67083366}],"tv":40.0}]}
{"op":"mcm","clk":"11927500257","pt":1724239747099,"mc":[{"id":"1.232048948","rc":[{"batb":[[1,1.63,9.65]],"ltp":2.0,"tv":7.63,"id":72857114},{"batb":[[0,2.12,7.41],[1,1.04,1.53],[2,1.03,200]],"ltp":1.1,"tv":32.37,"id":67083366}]}]}
{"op":"mcm","clk":"11927500512","pt":1724239749991,"mc":[{"id":"1.232048948","rc":[{"trd":[[1.9,0.12]],"ltp":1.9,"tv":7.75,"id":72857114},{"trd":[[2.12,0.1]],"batb":[[0,2.12,7.31]],"ltp":2.12,"tv":32.47,"id":67083366}],"tv":40.22}]}
{"op":"mcm","clk":"11927502105","pt":1724239766914,"mc":[{"id":"1.232048948","rc":[{"trd":[[2.12,1.83]],"batb":[[0,2.12,6.45]],"ltp":2.12,"tv":34.19,"id":67083366}],"tv":41.94}]}
{"op":"mcm","clk":"11927502354","pt":1724239769694,"mc":[{"id":"1.232048948","rc":[{"batb":[[0,2.12,7.35]],"ltp":2.12,"tv":34.19,"id":67083366}]}]}
{"op":"mcm","clk":"11927508217","pt":1724239826693,"mc":[{"id":"1.232048948","rc":[{"trd":[[2.14,0.94]],"batb":[[0,2.12,6.88]],"ltp":2.14,"tv":35.13,"id":67083366}],"tv":42.89}]}
{"op":"mcm","clk":"11927510220","pt":1724239846483,"mc":[{"id":"1.232048948","rc":[{"trd":[[1.88,0.49],[1.9,0.52]],"ltp":1.9,"tv":8.64,"id":72857114},{"trd":[[2.12,2.18],[2.14,1.38]],"batb":[[0,2.12,6.09]],"ltp":2.12,"tv":35.93,"id":67083366}],"tv":44.57}]}
{"op":"mcm","clk":"11927510678","pt":1724239850988,"mc":[{"id":"1.232048948","rc":[{"batb":[[0,2.14,1.26],[1,2.12,6.09],[2,1.04,1.53]],"ltp":2.12,"tv":35.93,"id":67083366}]}]}
{"op":"mcm","clk":"11927528972","pt":1724240027820,"mc":[{"id":"1.232048948","rc":[{"batb":[[2,1.34,75.5]],"ltp":2.12,"tv":35.93,"id":67083366}]}]}
{"op":"mcm","clk":"11927585736","pt":1724240616958,"mc":[{"id":"1.232048948","rc":[{"trd":[[1.68,0.07]],"batb":[[0,1.68,12.54]],"ltp":1.68,"tv":8.71,"id":72857114},{"trd":[[2.48,0.14]],"ltp":2.48,"tv":35.97,"id":67083366}],"tv":44.68}]}
{"op":"mcm","clk":"11927598459","pt":1724240763146,"mc":[{"id":"1.232048948","rc":[{"batb":[[0,1.63,9.65],[1,1.04,1.53],[2,1.03,205.19]],"ltp":1.68,"tv":8.71,"id":72857114}]}]}
{"op":"mcm","clk":"11927598638","pt":1724240765577,"mc":[{"id":"1.232048948","rc":[{"batb":[[0,1.61,9.77]],"ltp":1.68,"tv":8.71,"id":72857114},{"batb":[[0,2.16,6.02],[1,2.14,1.26]],"ltp":2.48,"tv":35.97,"id":67083366}]}]}
{"op":"mcm","clk":"11927600465","pt":1724240784685,"mc":[{"id":"1.232048948","rc":[{"trd":[[2.14,3.34],[2.16,12.04]],"batb":[[0,1.34,75.78],[1,1.04,1.53],[2,1.03,200]],"ltp":2.14,"tv":49.97,"id":67083366}],"tv":58.69}]}
{"op":"mcm","clk":"11927600781","pt":1724240788105,"mc":[{"id":"1.232048948","rc":[{"batb":[[0,1.34,75.5]],"ltp":2.14,"tv":49.97,"id":67083366}]}]}
{"op":"mcm","clk":"11927601531","pt":1724240795517,"mc":[{"id":"1.232048948","rc":[{"batb":[[0,1.34,76.03]],"ltp":2.14,"tv":49.97,"id":67083366}]}]}
{"op":"mcm","clk":"11927607715","pt":1724240860286,"mc":[{"id":"1.232048948","rc":[{"batb":[[0,1.35,25.03],[1,1.34,75.5],[2,1.04,1.53]],"ltp":2.14,"tv":49.97,"id":67083366}]}]}
{"op":"mcm","clk":"11927648755","pt":1724241374532,"mc":[{"id":"1.232048948","rc":[{"batb":[[0,1.5,1.47],[1,1.35,24.5],[2,1.34,75.5]],"ltp":2.14,"tv":49.97,"id":67083366}]}]}
{"op":"mcm","clk":"11927649519","pt":1724241385533,"mc":[{"id":"1.232048948","rc":[{"batl":[[0,2.18,0.94]],"ltp":2.14,"tv":49.97,"id":67083366}]}]}
{"op":"mcm","clk":"11927663062","pt":1724241572312,"mc":[{"id":"1.232048948","rc":[{"batb":[[0,1.36,10.94]],"ltp":2.14,"tv":49.97,"id":67083366}]}]}
{"op":"mcm","clk":"11927663292","pt":1724241575517,"mc":[{"id":"1.232048948","rc":[{"batb":[[0,1.35,25.43],[1,1.34,75.5],[2,1.04,1.53]],"ltp":2.14,"tv":49.97,"id":67083366}]}]}
{"op":"mcm","clk":"11927663486","pt":1724241578180,"mc":[{"id":"1.232048948","rc":[{"batb":[[0,1.36,10.94],[1,1.35,24.5],[2,1.34,75.5]],"ltp":2.14,"tv":49.97,"id":67083366}]}]}
{"op":"mcm","clk":"11927663743","pt":1724241581505,"mc":[{"id":"1.232048948","rc":[{"batb":[[0,1.35,25.43],[1,1.34,75.5],[2,1.04,1.53]],"ltp":2.14,"tv":49.97,"id":67083366}]}]}
{"op":"mcm","clk":"11927664120","pt":1724241586732,"mc":[{"id":"1.232048948","rc":[{"batb":[[0,1.36,10.94],[1,1.35,24.5],[2,1.34,75.5]],"ltp":2.14,"tv":49.97,"id":67083366}]}]}
{"op":"mcm","clk":"11927664628","pt":1724241595205,"mc":[{"id":"1.232048948","rc":[{"batb":[[0,1.35,25.43],[1,1.34,75.5],[2,1.04,1.53]],"ltp":2.14,"tv":49.97,"id":67083366}]}]}
{"op":"mcm","clk":"11927664772","pt":1724241597628,"mc":[{"id":"1.232048948","rc":[{"batb":[[0,1.36,10.94],[1,1.35,24.5],[2,1.34,75.5]],"ltp":2.14,"tv":49.97,"id":67083366}]}]}
{"op":"mcm","clk":"11927665172","pt":1724241602548,"mc":[{"id":"1.232048948","rc":[{"batb":[[0,1.35,25.43],[1,1.34,75.5],[2,1.04,1.53]],"ltp":2.14,"tv":49.97,"id":67083366}]}]}
{"op":"mcm","clk":"11927665573","pt":1724241607048,"mc":[{"id":"1.232048948","rc":[{"trd":[[1.44,1.7],[3,2.3]],"ltp":1.68,"tv":8.71,"id":72857114},{"trd":[[1.06,3.07],[1.08,2.24],[1.1,2.24],[1.2,2.14],[1.5,4.6],[1.65,2.3],[1.98,5.96],[2,5.23],[2.3,1.87]],"batb":[[0,1.36,10.94],[1,1.35,24.5],[2,1.34,75.55]],"ltp":2.14,"tv":50.0,"id":67083366}],"tv":58.71}]}
{"op":"mcm","clk":"11927665930","pt":1724241611332,"mc":[{"id":"1.232048948","rc":[{"batb":[[0,1.35,25.43],[1,1.34,75.55],[2,1.04,1.53]],"ltp":2.14,"tv":50.0,"id":67083366}]}]}
{"op":"mcm","clk":"11927666440","pt":1724241617240,"mc":[{"id":"1.232048948","rc":[{"batb":[[0,1.36,10.94],[1,1.35,24.5],[2,1.34,75.55]],"ltp":2.14,"tv":50.0,"id":67083366}]}]}
{"op":"mcm","clk":"11927666704","pt":1724241620539,"mc":[{"id":"1.232048948","rc":[{"batb":[[0,1.35,25.43],[1,1.34,75.55],[2,1.04,1.53]],"ltp":2.14,"tv":50.0,"id":67083366}]}]}
{"op":"mcm","clk":"11927667335","pt":1724241629149,"mc":[{"id":"1.232048948","rc":[{"batb":[[0,1.36,10.94],[1,1.35,24.5],[2,1.34,75.55]],"ltp":2.14,"tv":50.0,"id":67083366}]}]}
{"op":"mcm","clk":"11927667621","pt":1724241633149,"mc":[{"id":"1.232048948","rc":[{"batb":[[0,1.35,25.43],[1,1.34,75.55],[2,1.04,1.53]],"ltp":2.14,"tv":50.0,"id":67083366}]}]}
{"op":"mcm","clk":"11927667794","pt":1724241635351,"mc":[{"id":"1.232048948","rc":[{"batb":[[0,1.36,10.94],[1,1.35,24.5],[2,1.34,75.55]],"ltp":2.14,"tv":50.0,"id":67083366}]}]}
{"op":"mcm","clk":"11927668068","pt":1724241639360,"mc":[{"id":"1.232048948","rc":[{"batb":[[0,1.35,25.43],[1,1.34,75.55],[2,1.04,1.53]],"ltp":2.14,"tv":50.0,"id":67083366}]}]}
{"op":"mcm","clk":"11927669000","pt":1724241651998,"mc":[{"id":"1.232048948","rc":[{"batb":[[0,1.36,10.94],[1,1.35,24.5],[2,1.34,75.55]],"ltp":2.14,"tv":50.0,"id":67083366}]}]}
{"op":"mcm","clk":"11927669277","pt":1724241656172,"mc":[{"id":"1.232048948","rc":[{"batb":[[0,1.35,25.43],[1,1.34,75.55],[2,1.04,1.53]],"ltp":2.14,"tv":50.0,"id":67083366}]}]}
{"op":"mcm","clk":"11927670246","pt":1724241669587,"mc":[{"id":"1.232048948","rc":[{"batb":[[0,1.36,10.94],[1,1.35,24.5],[2,1.34,75.55]],"ltp":2.14,"tv":50.0,"id":67083366}]}]}
{"op":"mcm","clk":"11927670518","pt":1724241673605,"mc":[{"id":"1.232048948","rc":[{"batb":[[0,1.35,25.43],[1,1.34,75.55],[2,1.04,1.53]],"ltp":2.14,"tv":50.0,"id":67083366}]}]}
{"op":"mcm","clk":"11927671312","pt":1724241683896,"mc":[{"id":"1.232048948","rc":[{"batb":[[0,1.36,10.94],[1,1.35,24.5],[2,1.34,75.55]],"ltp":2.14,"tv":50.0,"id":67083366}]}]}
{"op":"mcm","clk":"11927671980","pt":1724241693335,"mc":[{"id":"1.232048948","rc":[{"batb":[[0,1.35,25.43],[1,1.34,75.55],[2,1.04,1.53]],"ltp":2.14,"tv":50.0,"id":67083366}]}]}
{"op":"mcm","clk":"11927672257","pt":1724241697148,"mc":[{"id":"1.232048948","rc":[{"batb":[[0,1.36,10.94],[1,1.35,24.5],[2,1.34,75.55]],"ltp":2.14,"tv":50.0,"id":67083366}]}]}
{"op":"mcm","clk":"11927672678","pt":1724241702932,"mc":[{"id":"1.232048948","rc":[{"batb":[[0,1.35,25.43],[1,1.34,75.55],[2,1.04,1.53]],"ltp":2.14,"tv":50.0,"id":67083366}]}]}
{"op":"mcm","clk":"11927673012","pt":1724241708029,"mc":[{"id":"1.232048948","rc":[{"batb":[[0,1.36,10.94],[1,1.35,24.5],[2,1.34,75.55]],"ltp":2.14,"tv":50.0,"id":67083366}]}]}
{"op":"mcm","clk":"11927673276","pt":1724241711945,"mc":[{"id":"1.232048948","rc":[{"batb":[[0,1.35,25.43],[1,1.34,75.55],[2,1.04,1.53]],"ltp":2.14,"tv":50.0,"id":67083366}]}]}
{"op":"mcm","clk":"11927673475","pt":1724241714943,"mc":[{"id":"1.232048948","rc":[{"batb":[[0,1.36,10.94],[1,1.35,24.5],[2,1.34,75.55]],"ltp":2.14,"tv":50.0,"id":67083366}]}]}
{"op":"mcm","clk":"11927673782","pt":1724241719037,"mc":[{"id":"1.232048948","rc":[{"batb":[[0,1.35,25.43],[1,1.34,75.55],[2,1.04,1.53]],"ltp":2.14,"tv":50.0,"id":67083366}]}]}
{"op":"mcm","clk":"11927673959","pt":1724241721542,"mc":[{"id":"1.232048948","rc":[{"batb":[[0,1.36,10.94],[1,1.35,24.5],[2,1.34,75.55]],"ltp":2.14,"tv":50.0,"id":67083366}]}]}
{"op":"mcm","clk":"11927674267","pt":1724241725648,"mc":[{"id":"1.232048948","rc":[{"batb":[[0,1.35,25.43],[1,1.34,75.55],[2,1.04,1.53]],"ltp":2.14,"tv":50.0,"id":67083366}]}]}
{"op":"mcm","clk":"11927674737","pt":1724241731959,"mc":[{"id":"1.232048948","rc":[{"batb":[[0,1.36,10.94],[1,1.35,24.5],[2,1.34,75.55]],"ltp":2.14,"tv":50.0,"id":67083366}]}]}
{"op":"mcm","clk":"11927675031","pt":1724241735782,"mc":[{"id":"1.232048948","rc":[{"batb":[[0,1.35,25.43],[1,1.34,75.55],[2,1.04,1.53]],"ltp":2.14,"tv":50.0,"id":67083366}]}]}
{"op":"mcm","clk":"11927675562","pt":1724241742252,"mc":[{"id":"1.232048948","rc":[{"batb":[[0,1.36,10.94],[1,1.35,24.5],[2,1.34,75.55]],"ltp":2.14,"tv":50.0,"id":67083366}]}]}
{"op":"mcm","clk":"11927675861","pt":1724241745987,"mc":[{"id":"1.232048948","rc":[{"batb":[[0,1.35,25.43],[1,1.34,75.55],[2,1.04,1.53]],"ltp":2.14,"tv":50.0,"id":67083366}]}]}
{"op":"mcm","clk":"11927676271","pt":1724241751281,"mc":[{"id":"1.232048948","rc":[{"batb":[[0,1.36,10.94],[1,1.35,24.5],[2,1.34,75.55]],"ltp":2.14,"tv":50.0,"id":67083366}]}]}
{"op":"mcm","clk":"11927676588","pt":1724241755467,"mc":[{"id":"1.232048948","rc":[{"batb":[[0,1.35,25.43],[1,1.34,75.55],[2,1.04,1.53]],"ltp":2.14,"tv":50.0,"id":67083366}]}]}
{"op":"mcm","clk":"11927676748","pt":1724241757687,"mc":[{"id":"1.232048948","rc":[{"batb":[[0,1.36,10.94],[1,1.35,24.5],[2,1.34,75.55]],"ltp":2.14,"tv":50.0,"id":67083366}]}]}
{"op":"mcm","clk":"11927677014","pt":1724241761711,"mc":[{"id":"1.232048948","rc":[{"batb":[[0,1.35,25.43],[1,1.34,75.55],[2,1.04,1.53]],"ltp":2.14,"tv":50.0,"id":67083366}]}]}
{"op":"mcm","clk":"11927677326","pt":1724241766102,"mc":[{"id":"1.232048948","rc":[{"batb":[[0,1.36,10.94],[1,1.35,24.5],[2,1.34,75.55]],"ltp":2.14,"tv":50.0,"id":67083366}]}]}
{"op":"mcm","clk":"11927677593","pt":1724241769714,"mc":[{"id":"1.232048948","rc":[{"batb":[[0,1.35,25.43],[1,1.34,75.55],[2,1.04,1.53]],"ltp":2.14,"tv":50.0,"id":67083366}]}]}
{"op":"mcm","clk":"11927678077","pt":1724241777140,"mc":[{"id":"1.232048948","rc":[{"batb":[[0,1.36,10.94],[1,1.35,24.5],[2,1.34,75.55]],"ltp":2.14,"tv":50.0,"id":67083366}]}]}
{"op":"mcm","clk":"11927678316","pt":1724241780963,"mc":[{"id":"1.232048948","rc":[{"batb":[[0,1.35,25.43],[1,1.34,75.55],[2,1.04,1.53]],"ltp":2.14,"tv":50.0,"id":67083366}]}]}
{"op":"mcm","clk":"11927678526","pt":1724241783755,"mc":[{"id":"1.232048948","rc":[{"batb":[[0,1.36,10.94],[1,1.35,24.5],[2,1.34,75.55]],"ltp":2.14,"tv":50.0,"id":67083366}]}]}
{"op":"mcm","clk":"11927678806","pt":1724241787755,"mc":[{"id":"1.232048948","rc":[{"batb":[[0,1.35,25.43],[1,1.34,75.55],[2,1.04,1.53]],"ltp":2.14,"tv":50.0,"id":67083366}]}]}
{"op":"mcm","clk":"11927679393","pt":1724241795793,"mc":[{"id":"1.232048948","rc":[{"batb":[[0,1.36,10.94],[1,1.35,24.5],[2,1.34,75.55]],"ltp":2.14,"tv":50.0,"id":67083366}]}]}
{"op":"mcm","clk":"11927679636","pt":1724241799661,"mc":[{"id":"1.232048948","rc":[{"batb":[[0,1.35,25.43],[1,1.34,75.55],[2,1.04,1.53]],"ltp":2.14,"tv":50.0,"id":67083366}]}]}
{"op":"mcm","clk":"11927681207","pt":1724241823121,"mc":[{"id":"1.232048948","rc":[{"batb":[[0,1.36,10.94],[1,1.35,24.5],[2,1.34,75.55]],"ltp":2.14,"tv":50.0,"id":67083366}]}]}
{"op":"mcm","clk":"11927681658","pt":1724241829209,"mc":[{"id":"1.232048948","rc":[{"batb":[[0,1.35,25.43],[1,1.34,75.55],[2,1.04,1.53]],"ltp":2.14,"tv":50.0,"id":67083366}]}]}
{"op":"mcm","clk":"11927682224","pt":1724241837115,"mc":[{"id":"1.232048948","rc":[{"batb":[[0,1.36,10.94],[1,1.35,24.5],[2,1.34,75.55]],"ltp":2.14,"tv":50.0,"id":67083366}]}]}
{"op":"mcm","clk":"11927682896","pt":1724241845839,"mc":[{"id":"1.232048948","rc":[{"batb":[[0,1.35,25.43],[1,1.34,75.55],[2,1.04,1.53]],"ltp":2.14,"tv":50.0,"id":67083366}]}]}
{"op":"mcm","clk":"11927683115","pt":1724241849031,"mc":[{"id":"1.232048948","rc":[{"batb":[[0,1.37,10.94],[1,1.35,24.5],[2,1.34,75.55]],"ltp":2.14,"tv":50.0,"id":67083366}]}]}
{"op":"mcm","clk":"11927683685","pt":1724241857452,"mc":[{"id":"1.232048948","rc":[{"batb":[[0,1.35,25.43],[1,1.34,75.55],[2,1.04,1.53]],"ltp":2.14,"tv":50.0,"id":67083366}]}]}
{"op":"mcm","clk":"11927683851","pt":1724241859865,"mc":[{"id":"1.232048948","rc":[{"batb":[[0,1.36,10.94],[1,1.35,24.5],[2,1.34,75.55]],"ltp":2.14,"tv":50.0,"id":67083366}]}]}
{"op":"mcm","clk":"11927684169","pt":1724241864666,"mc":[{"id":"1.232048948","rc":[{"batb":[[0,1.35,25.43],[1,1.34,75.55],[2,1.04,1.53]],"ltp":2.14,"tv":50.0,"id":67083366}]}]}
{"op":"mcm","clk":"11927684762","pt":1724241873857,"mc":[{"id":"1.232048948","rc":[{"batb":[[0,1.36,1.83],[1,1.35,24.5],[2,1.34,75.55]],"ltp":2.14,"tv":50.0,"id":67083366}]}]}
{"op":"mcm","clk":"11927686676","pt":1724241900607,"mc":[{"id":"1.232048948","rc":[{"batb":[[2,1.04,1.53]],"ltp":2.14,"tv":50.0,"id":67083366}]}]}
{"op":"mcm","clk":"11927716670","pt":1724242383326,"mc":[{"id":"1.232048948","rc":[{"batb":[[0,1.04,1.53],[1,1.03,205.19],[2,1.02,200]],"ltp":1.68,"tv":8.71,"id":72857114}]}]}
{"op":"mcm","clk":"11927727566","pt":1724242538503,"mc":[{"id":"1.232048948","rc":[{"batl":[[0,900,1.86]],"ltp":2.14,"tv":50.0,"id":67083366}]}]}
{"op":"mcm","clk":"11927736923","pt":1724242660439,"mc":[{"id":"1.232048948","rc":[{"batb":[[1,1.04,1.53],[2,1.03,200]],"ltp":2.14,"tv":50.0,"id":67083366}]}]}
{"op":"mcm","clk":"11927743554","pt":1724242744109,"mc":[{"id":"1.232048948","rc":[{"batb":[[0,1.37,24.11],[1,1.04,2.42]],"ltp":2.14,"tv":50.0,"id":67083366}]}]}
{"op":"mcm","clk":"11927743573","pt":1724242744417,"mc":[{"id":"1.232048948","rc":[{"batb":[[0,1.38,10.94],[1,1.37,23.17],[2,1.04,2.42]],"ltp":2.14,"tv":50.0,"id":67083366}]}]}
{"op":"mcm","clk":"11927743835","pt":1724242747829,"mc":[{"id":"1.232048948","rc":[{"batb":[[0,1.37,24.11],[1,1.04,2.42],[2,1.03,200]],"ltp":2.14,"tv":50.0,"id":67083366}]}]}
{"op":"mcm","clk":"11927744640","pt":1724242758744,"mc":[{"id":"1.232048948","rc":[{"batb":[[0,1.38,10.94],[1,1.37,23.17],[2,1.04,2.42]],"ltp":2.14,"tv":50.0,"id":67083366}]}]}
{"op":"mcm","clk":"11927744937","pt":1724242762655,"mc":[{"id":"1.232048948","rc":[{"batb":[[0,1.37,24.11],[1,1.04,2.42],[2,1.03,200]],"ltp":2.14,"tv":50.0,"id":67083366}]}]}
{"op":"mcm","clk":"11927745172","pt":1724242765447,"mc":[{"id":"1.232048948","rc":[{"batb":[[0,1.38,10.94],[1,1.37,23.17],[2,1.04,2.42]],"ltp":2.14,"tv":50.0,"id":67083366}]}]}
{"op":"mcm","clk":"11927745450","pt":1724242769277,"mc":[{"id":"1.232048948","rc":[{"batb":[[0,1.37,24.11],[1,1.04,2.42],[2,1.03,200]],"ltp":2.14,"tv":50.0,"id":67083366}]}]}
{"op":"mcm","clk":"11927745666","pt":1724242772470,"mc":[{"id":"1.232048948","rc":[{"batb":[[0,1.38,10.94],[1,1.37,23.17],[2,1.04,2.42]],"ltp":2.14,"tv":50.0,"id":67083366}]}]}
{"op":"mcm","clk":"11927745895","pt":1724242775771,"mc":[{"id":"1.232048948","rc":[{"batb":[[0,1.37,24.11],[1,1.04,2.42],[2,1.03,200]],"ltp":2.14,"tv":50.0,"id":67083366}]}]}
{"op":"mcm","clk":"11927746534","pt":1724242784005,"mc":[{"id":"1.232048948","rc":[{"batb":[[0,1.38,10.94],[1,1.37,23.17],[2,1.04,2.42]],"ltp":2.14,"tv":50.0,"id":67083366}]}]}
{"op":"mcm","clk":"11927746840","pt":1724242787898,"mc":[{"id":"1.232048948","rc":[{"batb":[[0,1.37,24.11],[1,1.04,2.42],[2,1.03,200]],"ltp":2.14,"tv":50.0,"id":67083366}]}]}
{"op":"mcm","clk":"11927747399","pt":1724242794791,"mc":[{"id":"1.232048948","rc":[{"batb":[[0,1.38,10.94],[1,1.37,23.17],[2,1.04,2.42]],"ltp":2.14,"tv":50.0,"id":67083366}]}]}
{"op":"mcm","clk":"11927747741","pt":1724242799141,"mc":[{"id":"1.232048948","rc":[{"batb":[[0,1.37,24.11],[1,1.04,2.42],[2,1.03,200]],"ltp":2.14,"tv":50.0,"id":67083366}]}]}
{"op":"mcm","clk":"11927748535","pt":1724242809235,"mc":[{"id":"1.232048948","rc":[{"batb":[[0,1.38,10.94],[1,1.37,23.17],[2,1.04,2.42]],"ltp":2.14,"tv":50.0,"id":67083366}]}]}
{"op":"mcm","clk":"11927748829","pt":1724242812958,"mc":[{"id":"1.232048948","rc":[{"batb":[[0,1.37,24.11],[1,1.04,2.42],[2,1.03,200]],"ltp":2.14,"tv":50.0,"id":67083366}]}]}
{"op":"mcm","clk":"11927749042","pt":1724242815548,"mc":[{"id":"1.232048948","rc":[{"batb":[[0,1.38,10.94],[1,1.37,23.17],[2,1.04,2.42]],"ltp":2.14,"tv":50.0,"id":67083366}]}]}
{"op":"mcm","clk":"11927749368","pt":1724242819345,"mc":[{"id":"1.232048948","rc":[{"batb":[[0,1.37,24.11],[1,1.04,2.42],[2,1.03,200]],"ltp":2.14,"tv":50.0,"id":67083366}]}]}
{"op":"mcm","clk":"11927749752","pt":1724242824258,"mc":[{"id":"1.232048948","rc":[{"batb":[[0,1.38,10.94],[1,1.37,23.17],[2,1.04,2.42]],"ltp":2.14,"tv":50.0,"id":67083366}]}]}
{"op":"mcm","clk":"11927750116","pt":1724242828482,"mc":[{"id":"1.232048948","rc":[{"batb":[[0,1.37,24.11],[1,1.04,2.42],[2,1.03,200]],"ltp":2.14,"tv":50.0,"id":67083366}]}]}
{"op":"mcm","clk":"11927750359","pt":1724242831388,"mc":[{"id":"1.232048948","rc":[{"batb":[[0,1.38,10.94],[1,1.37,23.17],[2,1.04,2.42]],"ltp":2.14,"tv":50.0,"id":67083366}]}]}
{"op":"mcm","clk":"11927750628","pt":1724242835158,"mc":[{"id":"1.232048948","rc":[{"batb":[[0,1.37,24.11],[1,1.04,2.42],[2,1.03,200]],"ltp":2.14,"tv":50.0,"id":67083366}]}]}
{"op":"mcm","clk":"11927751124","pt":1724242840998,"mc":[{"id":"1.232048948","rc":[{"batb":[[0,1.38,10.94],[1,1.37,23.17],[2,1.04,2.42]],"ltp":2.14,"tv":50.0,"id":67083366}]}]}
{"op":"mcm","clk":"11927751400","pt":1724242844574,"mc":[{"id":"1.232048948","rc":[{"batb":[[0,1.37,24.11],[1,1.04,2.42],[2,1.03,200]],"ltp":2.14,"tv":50.0,"id":67083366}]}]}
{"op":"mcm","clk":"11927751560","pt":1724242846795,"mc":[{"id":"1.232048948","rc":[{"batb":[[0,1.38,10.94],[1,1.37,23.17],[2,1.04,2.42]],"ltp":2.14,"tv":50.0,"id":67083366}]}]}
{"op":"mcm","clk":"11927751829","pt":1724242850206,"mc":[{"id":"1.232048948","rc":[{"batb":[[0,1.37,24.11],[1,1.04,2.42],[2,1.03,200]],"ltp":2.14,"tv":50.0,"id":67083366}]}]}
{"op":"mcm","clk":"11927752038","pt":1724242852884,"mc":[{"id":"1.232048948","rc":[{"batb":[[0,1.38,10.94],[1,1.37,23.17],[2,1.04,2.42]],"ltp":2.14,"tv":50.0,"id":67083366}]}]}
{"op":"mcm","clk":"11927752304","pt":1724242856603,"mc":[{"id":"1.232048948","rc":[{"batb":[[0,1.37,24.11],[1,1.04,2.42],[2,1.03,200]],"ltp":2.14,"tv":50.0,"id":67083366}]}]}
{"op":"mcm","clk":"11927752661","pt":1724242862015,"mc":[{"id":"1.232048948","rc":[{"batb":[[0,1.38,10.94],[1,1.37,23.17],[2,1.04,2.42]],"ltp":2.14,"tv":50.0,"id":67083366}]}]}
{"op":"mcm","clk":"11927752966","pt":1724242866229,"mc":[{"id":"1.232048948","rc":[{"batb":[[0,1.37,24.11],[1,1.04,2.42],[2,1.03,200]],"ltp":2.14,"tv":50.0,"id":67083366}]}]}
{"op":"mcm","clk":"11927753204","pt":1724242869898,"mc":[{"id":"1.232048948","rc":[{"batb":[[0,1.38,10.94],[1,1.37,23.17],[2,1.04,2.42]],"ltp":2.14,"tv":50.0,"id":67083366}]}]}
{"op":"mcm","clk":"11927753450","pt":1724242873929,"mc":[{"id":"1.232048948","rc":[{"batb":[[0,1.37,24.11],[1,1.04,2.42],[2,1.03,200]],"ltp":2.14,"tv":50.0,"id":67083366}]}]}
{"op":"mcm","clk":"11927753630","pt":1724242876616,"mc":[{"id":"1.232048948","rc":[{"batb":[[0,1.38,10.94],[1,1.37,23.17],[2,1.04,2.42]],"ltp":2.14,"tv":50.0,"id":67083366}]}]}
{"op":"mcm","clk":"11927754276","pt":1724242885949,"mc":[{"id":"1.232048948","rc":[{"batb":[[0,1.37,24.11],[1,1.04,2.42],[2,1.03,200]],"ltp":2.14,"tv":50.0,"id":67083366}]}]}
{"op":"mcm","clk":"11927754665","pt":1724242891457,"mc":[{"id":"1.232048948","rc":[{"batb":[[0,1.38,10.94],[1,1.37,23.17],[2,1.04,2.42]],"ltp":2.14,"tv":50.0,"id":67083366}]}]}
{"op":"mcm","clk":"11927755167","pt":1724242898731,"mc":[{"id":"1.232048948","rc":[{"trd":[[2.94,0.48]],"batb":[[0,1.04,2.12]],"ltp":2.94,"tv":9.2,"id":72857114},{"trd":[[1.52,0.94]],"batb":[[0,1.38,10]],"ltp":1.52,"tv":50.94,"id":67083366}],"tv":60.14}]}
{"op":"mcm","clk":"11927755367","pt":1724242901536,"mc":[{"id":"1.232048948","rc":[{"batb":[[0,1.04,1.53]],"ltp":2.94,"tv":9.2,"id":72857114},{"batb":[[0,1.37,23.17],[1,1.04,2.42],[2,1.03,200]],"ltp":1.52,"tv":50.94,"id":67083366}]}]}
{"op":"mcm","clk":"11927755577","pt":1724242904840,"mc":[{"id":"1.232048948","rc":[{"batb":[[0,1.38,10],[1,1.37,23.17],[2,1.04,2.42]],"ltp":1.52,"tv":50.94,"id":67083366}]}]}
{"op":"mcm","clk":"11927756002","pt":1724242910950,"mc":[{"id":"1.232048948","rc":[{"batb":[[0,1.37,23.17],[1,1.04,2.42],[2,1.03,200]],"ltp":1.52,"tv":50.94,"id":67083366}]}]}
{"op":"mcm","clk":"11927756235","pt":1724242913953,"mc":[{"id":"1.232048948","rc":[{"batb":[[0,1.38,10],[1,1.37,23.17],[2,1.04,2.42]],"ltp":1.52,"tv":50.94,"id":67083366}]}]}
{"op":"mcm","clk":"11927756471","pt":1724242917547,"mc":[{"id":"1.232048948","rc":[{"batb":[[0,1.37,23.17],[1,1.04,2.42],[2,1.03,200]],"ltp":1.52,"tv":50.94,"id":67083366}]}]}
{"op":"mcm","clk":"11927756622","pt":1724242919552,"mc":[{"id":"1.232048948","rc":[{"batb":[[0,2.08,1.07],[1,1.37,23.17],[2,1.04,2.42]],"ltp":1.52,"tv":50.94,"id":67083366}]}]}
{"op":"mcm","clk":"11927756702","pt":1724242920951,"mc":[{"id":"1.232048948","rc":[{"batb":[[0,1.38,10]],"ltp":1.52,"tv":50.94,"id":67083366}]}]}
{"op":"mcm","clk":"11927756962","pt":1724242924494,"mc":[{"id":"1.232048948","rc":[{"batb":[[0,1.37,23.17],[1,1.04,2.42],[2,1.03,200]],"ltp":1.52,"tv":50.94,"id":67083366}]}]}
{"op":"mcm","clk":"11927757924","pt":1724242935798,"mc":[{"id":"1.232048948","rc":[{"trd":[[2.18,1.29]],"batb":[[0,1.38,10],[1,1.37,23.17],[2,1.04,2.42]],"batl":[[0,900,1.21]],"ltp":2.18,"tv":52.22,"id":67083366}],"tv":61.43}]}
{"op":"mcm","clk":"11927758731","pt":1724242945791,"mc":[{"id":"1.232048948","rc":[{"batb":[[0,1.37,23.17],[1,1.04,2.42],[2,1.03,200]],"ltp":2.18,"tv":52.22,"id":67083366}]}]}
{"op":"mcm","clk":"11927758870","pt":1724242947395,"mc":[{"id":"1.232048948","rc":[{"batb":[[0,1.74,3.41],[1,1.04,1.53],[2,1.03,205.19]],"ltp":2.94,"tv":9.2,"id":72857114}]}]}
{"op":"mcm","clk":"11927759011","pt":1724242949301,"mc":[{"id":"1.232048948","rc":[{"batb":[[1,1.67,3.41],[2,1.6,3.41]],"ltp":2.94,"tv":9.2,"id":72857114}]}]}
{"op":"mcm","clk":"11927759061","pt":1724242950015,"mc":[{"id":"1.232048948","rc":[{"batb":[[0,1.38,10],[1,1.37,23.17],[2,1.04,2.42]],"ltp":2.18,"tv":52.22,"id":67083366}]}]}
{"op":"mcm","clk":"11927759102","pt":1724242950688,"mc":[{"id":"1.232048948","rc":[{"batb":[[0,1.4,4.26],[1,1.38,10],[2,1.37,23.17]],"ltp":2.18,"tv":52.22,"id":67083366}]}]}
{"op":"mcm","clk":"11927759167","pt":1724242951610,"mc":[{"id":"1.232048948","rc":[{"batb":[[0,1.43,4.26],[1,1.4,4.26],[2,1.38,10]],"ltp":2.18,"tv":52.22,"id":67083366}]}]}
{"op":"mcm","clk":"11927759225","pt":1724242952497,"mc":[{"id":"1.232048948","rc":[{"batb":[[0,1.45,4.26],[1,1.43,4.26],[2,1.4,4.26]],"ltp":2.18,"tv":52.22,"id":67083366}]}]}
{"op":"mcm","clk":"11927759718","pt":1724242959223,"mc":[{"id":"1.232048948","rc":[{"batb":[[0,1.46,10],[1,1.45,4.26],[2,1.43,4.26]],"ltp":2.18,"tv":52.22,"id":67083366}]}]}
{"op":"mcm","clk":"11927760063","pt":1724242963917,"mc":[{"id":"1.232048948","rc":[{"batb":[[0,1.45,4.26],[1,1.43,4.26],[2,1.4,4.26]],"ltp":2.18,"tv":52.22,"id":67083366}]}]}
{"op":"mcm","clk":"11927760239","pt":1724242966304,"mc":[{"id":"1.232048948","rc":[{"batb":[[2,1.61,9.77]],"ltp":2.94,"tv":9.2,"id":72857114},{"batb":[[0,1.46,10],[1,1.45,4.26],[2,1.43,4.26]],"ltp":2.18,"tv":52.22,"id":67083366}]}]}
{"op":"mcm","clk":"11927760506","pt":1724242969818,"mc":[{"id":"1.232048948","rc":[{"batb":[[0,1.45,4.26],[1,1.43,4.26],[2,1.4,4.26]],"ltp":2.18,"tv":52.22,"id":67083366}]}]}
{"op":"mcm","clk":"11927760679","pt":1724242972129,"mc":[{"id":"1.232048948","rc":[{"batb":[[0,1.46,10],[1,1.45,4.26],[2,1.43,4.26]],"ltp":2.18,"tv":52.22,"id":67083366}]}]}
{"op":"mcm","clk":"11927760934","pt":1724242975635,"mc":[{"id":"1.232048948","rc":[{"batb":[[0,1.45,4.26],[1,1.43,4.26],[2,1.4,4.26]],"ltp":2.18,"tv":52.22,"id":67083366}]}]}
{"op":"mcm","clk":"11927761127","pt":1724242978426,"mc":[{"id":"1.232048948","rc":[{"batb":[[0,1.47,10],[1,1.45,4.26],[2,1.43,4.26]],"ltp":2.18,"tv":52.22,"id":67083366}]}]}
{"op":"mcm","clk":"11927761831","pt":1724242987358,"mc":[{"id":"1.232048948","rc":[{"batb":[[0,1.45,4.26],[1,1.43,4.26],[2,1.4,4.26]],"ltp":2.18,"tv":52.22,"id":67083366}]}]}
{"op":"mcm","clk":"11927761997","pt":1724242989772,"mc":[{"id":"1.232048948","rc":[{"batb":[[0,1.48,10],[1,1.45,4.26],[2,1.43,4.26]],"ltp":2.18,"tv":52.22,"id":67083366}]}]}
{"op":"mcm","clk":"11927762555","pt":1724242996045,"mc":[{"id":"1.232048948","rc":[{"batb":[[0,1.45,4.26],[1,1.43,4.26],[2,1.4,4.26]],"ltp":2.18,"tv":52.22,"id":67083366}]}]}
{"op":"mcm","clk":"11927763191","pt":1724243004363,"mc":[{"id":"1.232048948","rc":[{"batb":[[0,1.46,10],[1,1.45,4.26],[2,1.43,4.26]],"ltp":2.18,"tv":52.22,"id":67083366}]}]}
{"op":"mcm","clk":"11927763560","pt":1724243007977,"mc":[{"id":"1.232048948","rc":[{"batb":[[0,1.45,4.26],[1,1.43,4.26],[2,1.4,4.26]],"ltp":2.18,"tv":52.22,"id":67083366}]}]}
{"op":"mcm","clk":"11927763747","pt":1724243011111,"mc":[{"id":"1.232048948","rc":[{"batb":[[0,1.46,10],[1,1.45,4.26],[2,1.43,4.26]],"ltp":2.18,"tv":52.22,"id":67083366}]}]}
{"op":"mcm","clk":"11927764042","pt":1724243015286,"mc":[{"id":"1.232048948","rc":[{"batb":[[0,1.45,4.26],[1,1.43,4.26],[2,1.4,4.26]],"ltp":2.18,"tv":52.22,"id":67083366}]}]}
{"op":"mcm","clk":"11927764214","pt":1724243017702,"mc":[{"id":"1.232048948","rc":[{"batb":[[0,1.46,10],[1,1.45,4.26],[2,1.43,4.26]],"ltp":2.18,"tv":52.22,"id":67083366}]}]}
{"op":"mcm","clk":"11927764466","pt":1724243021411,"mc":[{"id":"1.232048948","rc":[{"batb":[[0,1.45,4.26],[1,1.43,4.26],[2,1.4,4.26]],"ltp":2.18,"tv":52.22,"id":67083366}]}]}
{"op":"mcm","clk":"11927764689","pt":1724243024214,"mc":[{"id":"1.232048948","rc":[{"batb":[[0,1.46,10],[1,1.45,4.26],[2,1.43,4.26]],"ltp":2.18,"tv":52.22,"id":67083366}]}]}
{"op":"mcm","clk":"11927764974","pt":1724243028091,"mc":[{"id":"1.232048948","rc":[{"batb":[[0,1.45,4.26],[1,1.43,4.26],[2,1.4,4.26]],"ltp":2.18,"tv":52.22,"id":67083366}]}]}
{"op":"mcm","clk":"11927765144","pt":1724243030873,"mc":[{"id":"1.232048948","rc":[{"batb":[[0,1.46,10],[1,1.45,4.26],[2,1.43,4.26]],"ltp":2.18,"tv":52.22,"id":67083366}]}]}
{"op":"mcm","clk":"11927765383","pt":1724243034487,"mc":[{"id":"1.232048948","rc":[{"batb":[[0,1.45,4.26],[1,1.43,4.26],[2,1.4,4.26]],"ltp":2.18,"tv":52.22,"id":67083366}]}]}
{"op":"mcm","clk":"11927765712","pt":1724243039127,"mc":[{"id":"1.232048948","rc":[{"batb":[[0,1.46,10],[1,1.45,4.26],[2,1.43,4.26]],"ltp":2.18,"tv":52.22,"id":67083366}]}]}
{"op":"mcm","clk":"11927765829","pt":1724243040730,"mc":[{"id":"1.232048948","rc":[{"batb":[[0,1.8,45.53],[1,1.74,3.41],[2,1.67,3.41]],"ltp":2.94,"tv":9.2,"id":72857114}]}]}
{"op":"mcm","clk":"11927765981","pt":1724243042714,"mc":[{"id":"1.232048948","rc":[{"batb":[[0,1.45,4.26],[1,1.43,4.26],[2,1.4,4.26]],"ltp":2.18,"tv":52.22,"id":67083366}]}]}
{"op":"mcm","clk":"11927766220","pt":1724243046227,"mc":[{"id":"1.232048948","rc":[{"batb":[[0,1.74,3.41],[1,1.67,3.41],[2,1.61,9.77]],"ltp":2.94,"tv":9.2,"id":72857114},{"batb":[[0,1.46,10],[1,1.45,4.26],[2,1.43,4.26]],"ltp":2.18,"tv":52.22,"id":67083366}]}]}
{"op":"mcm","clk":"11927766381","pt":1724243049524,"mc":[{"id":"1.232048948","rc":[{"batb":[[0,1.45,4.26],[1,1.43,4.26],[2,1.4,4.26]],"ltp":2.18,"tv":52.22,"id":67083366}]}]}
{"op":"mcm","clk":"11927767119","pt":1724243060444,"mc":[{"id":"1.232048948","rc":[{"batb":[[0,1.46,10],[1,1.45,4.26],[2,1.43,4.26]],"ltp":2.18,"tv":52.22,"id":67083366}]}]}
{"op":"mcm","clk":"11927767350","pt":1724243064025,"mc":[{"id":"1.232048948","rc":[{"batb":[[0,1.45,4.26],[1,1.43,4.26],[2,1.4,4.26]],"ltp":2.18,"tv":52.22,"id":67083366}]}]}
{"op":"mcm","clk":"11927767588","pt":1724243067443,"mc":[{"id":"1.232048948","rc":[{"batb":[[0,1.45,5.2]],"ltp":2.18,"tv":52.22,"id":67083366}]}]}
{"op":"mcm","clk":"11927767775","pt":1724243070017,"mc":[{"id":"1.232048948","rc":[{"batb":[[0,1.46,10.94],[1,1.45,4.26],[2,1.43,4.26]],"ltp":2.18,"tv":52.22,"id":67083366}]}]}
{"op":"mcm","clk":"11927768255","pt":1724243077443,"mc":[{"id":"1.232048948","rc":[{"batb":[[0,1.45,5.2],[1,1.43,4.26],[2,1.4,4.26]],"ltp":2.18,"tv":52.22,"id":67083366}]}]}
{"op":"mcm","clk":"11927768508","pt":1724243081850,"mc":[{"id":"1.232048948","rc":[{"batb":[[0,1.46,10.94],[1,1.45,4.26],[2,1.43,4.26]],"ltp":2.18,"tv":52.22,"id":67083366}]}]}
{"op":"mcm","clk":"11927768669","pt":1724243084438,"mc":[{"id":"1.232048948","rc":[{"batl":[[0,2.18,1.23],[1,900,0.92]],"ltp":2.18,"tv":52.22,"id":67083366}]}]}
{"op":"mcm","clk":"11927768911","pt":1724243087635,"mc":[{"id":"1.232048948","rc":[{"batb":[[0,1.45,5.2],[1,1.43,4.26],[2,1.4,4.26]],"ltp":2.18,"tv":52.22,"id":67083366}]}]}
{"op":"mcm","clk":"11927769206","pt":1724243092269,"mc":[{"id":"1.232048948","rc":[{"batb":[[0,1.46,10.94],[1,1.45,4.26],[2,1.43,4.26]],"ltp":2.18,"tv":52.22,"id":67083366}]}]}
{"op":"mcm","clk":"11927769424","pt":1724243096046,"mc":[{"id":"1.232048948","rc":[{"batb":[[0,1.45,5.2],[1,1.43,4.26],[2,1.4,4.26]],"ltp":2.18,"tv":52.22,"id":67083366}]}]}
{"op":"mcm","clk":"11927769595","pt":1724243099042,"mc":[{"id":"1.232048948","rc":[{"batb":[[0,1.46,10.94],[1,1.45,4.26],[2,1.43,4.26]],"ltp":2.18,"tv":52.22,"id":67083366}]}]}
{"op":"mcm","clk":"11927769825","pt":1724243102368,"mc":[{"id":"1.232048948","rc":[{"batb":[[0,1.45,5.2],[1,1.43,4.26],[2,1.4,4.26]],"ltp":2.18,"tv":52.22,"id":67083366}]}]}
{"op":"mcm","clk":"11927770715","pt":1724243115946,"mc":[{"id":"1.232048948","rc":[{"batb":[[0,1.46,10.94],[1,1.45,4.26],[2,1.43,4.26]],"ltp":2.18,"tv":52.22,"id":67083366}]}]}
{"op":"mcm","clk":"11927770929","pt":1724243119553,"mc":[{"id":"1.232048948","rc":[{"batb":[[0,1.45,5.2],[1,1.43,4.26],[2,1.4,4.26]],"ltp":2.18,"tv":52.22,"id":67083366}]}]}
{"op":"mcm","clk":"11927771185","pt":1724243124195,"mc":[{"id":"1.232048948","rc":[{"batb":[[0,1.46,10.94],[1,1.45,4.26],[2,1.43,4.26]],"ltp":2.18,"tv":52.22,"id":67083366}]}]}
{"op":"mcm","clk":"11927771401","pt":1724243127662,"mc":[{"id":"1.232048948","rc":[{"batb":[[0,1.45,5.2],[1,1.43,4.26],[2,1.4,4.26]],"ltp":2.18,"tv":52.22,"id":67083366}]}]}
{"op":"mcm","clk":"11927772031","pt":1724243137788,"mc":[{"id":"1.232048948","rc":[{"batb":[[0,1.46,10.94],[1,1.45,4.26],[2,1.43,4.26]],"ltp":2.18,"tv":52.22,"id":67083366}]}]}
{"op":"mcm","clk":"11927772329","pt":1724243141503,"mc":[{"id":"1.232048948","rc":[{"batb":[[0,1.45,5.2],[1,1.43,4.26],[2,1.4,4.26]],"ltp":2.18,"tv":52.22,"id":67083366}]}]}
{"op":"mcm","clk":"11927773078","pt":1724243152529,"mc":[{"id":"1.232048948","rc":[{"batb":[[0,1.46,10.94],[1,1.45,4.26],[2,1.43,4.26]],"ltp":2.18,"tv":52.22,"id":67083366}]}]}
{"op":"mcm","clk":"11927773298","pt":1724243156227,"mc":[{"id":"1.232048948","rc":[{"batb":[[0,1.45,5.2],[1,1.43,4.26],[2,1.4,4.26]],"ltp":2.18,"tv":52.22,"id":67083366}]}]}
{"op":"mcm","clk":"11927773429","pt":1724243158524,"mc":[{"id":"1.232048948","rc":[{"batb":[[0,1.46,10.94],[1,1.45,4.26],[2,1.43,4.26]],"ltp":2.18,"tv":52.22,"id":67083366}]}]}
{"op":"mcm","clk":"11927773657","pt":1724243162220,"mc":[{"id":"1.232048948","rc":[{"batb":[[0,1.45,5.2],[1,1.43,4.26],[2,1.4,4.26]],"ltp":2.18,"tv":52.22,"id":67083366}]}]}
{"op":"mcm","clk":"11927775452","pt":1724243194362,"mc":[{"id":"1.232048948","rc":[{"batb":[[0,1.46,10.94],[1,1.45,4.26],[2,1.43,4.26]],"ltp":2.18,"tv":52.22,"id":67083366}]}]}
{"op":"mcm","clk":"11927775752","pt":1724243199896,"mc":[{"id":"1.232048948","rc":[{"batb":[[0,1.45,5.2],[1,1.43,4.26],[2,1.4,4.26]],"ltp":2.18,"tv":52.22,"id":67083366}]}]}
{"op":"mcm","clk":"11927776179","pt":1724243207871,"mc":[{"id":"1.232048948","rc":[{"batb":[[0,1.46,10.94],[1,1.45,4.26],[2,1.43,4.26]],"ltp":2.18,"tv":52.22,"id":67083366}]}]}
{"op":"mcm","clk":"11927776724","pt":1724243218791,"mc":[{"id":"1.232048948","rc":[{"batb":[[0,1.45,5.2],[1,1.43,4.26],[2,1.4,4.26]],"ltp":2.18,"tv":52.22,"id":67083366}]}]}
{"op":"mcm","clk":"11927776924","pt":1724243222408,"mc":[{"id":"1.232048948","rc":[{"batb":[[0,1.46,10.94],[1,1.45,4.26],[2,1.43,4.26]],"ltp":2.18,"tv":52.22,"id":67083366}]}]}
{"op":"mcm","clk":"11927777234","pt":1724243227884,"mc":[{"id":"1.232048948","rc":[{"batb":[[0,1.45,5.2],[1,1.43,4.26],[2,1.4,4.26]],"ltp":2.18,"tv":52.22,"id":67083366}]}]}
{"op":"mcm","clk":"11927778063","pt":1724243244408,"mc":[{"id":"1.232048948","rc":[{"batb":[[0,1.46,10.94],[1,1.45,4.26],[2,1.43,4.26]],"ltp":2.18,"tv":52.22,"id":67083366}]}]}
{"op":"mcm","clk":"11927778257","pt":1724243248129,"mc":[{"id":"1.232048948","rc":[{"batb":[[0,1.45,5.2],[1,1.43,4.26],[2,1.4,4.26]],"ltp":2.18,"tv":52.22,"id":67083366}]}]}
{"op":"mcm","clk":"11927778603","pt":1724243255159,"mc":[{"id":"1.232048948","rc":[{"batb":[[0,1.46,10.94],[1,1.45,4.26],[2,1.43,4.26]],"ltp":2.18,"tv":52.22,"id":67083366}]}]}
{"op":"mcm","clk":"11927778783","pt":1724243258963,"mc":[{"id":"1.232048948","rc":[{"batb":[[0,1.45,5.2],[1,1.43,4.26],[2,1.4,4.26]],"ltp":2.18,"tv":52.22,"id":67083366}]}]}
{"op":"mcm","clk":"11927779010","pt":1724243263737,"mc":[{"id":"1.232048948","rc":[{"batb":[[0,1.46,10.94],[1,1.45,4.26],[2,1.43,4.26]],"ltp":2.18,"tv":52.22,"id":67083366}]}]}
{"op":"mcm","clk":"11927779226","pt":1724243267457,"mc":[{"id":"1.232048948","rc":[{"batb":[[0,1.45,5.2],[1,1.43,4.26],[2,1.4,4.26]],"ltp":2.18,"tv":52.22,"id":67083366}]}]}
{"op":"mcm","clk":"11927779489","pt":1724243274074,"mc":[{"id":"1.232048948","rc":[{"batb":[[0,1.46,10.94],[1,1.45,4.26],[2,1.43,4.26]],"ltp":2.18,"tv":52.22,"id":67083366}]}]}
{"op":"mcm","clk":"11927779707","pt":1724243277570,"mc":[{"id":"1.232048948","rc":[{"batb":[[0,1.45,5.2],[1,1.43,4.26],[2,1.4,4.26]],"ltp":2.18,"tv":52.22,"id":67083366}]}]}
{"op":"mcm","clk":"11927780424","pt":1724243290473,"mc":[{"id":"1.232048948","rc":[{"batb":[[0,1.46,10.94],[1,1.45,4.26],[2,1.43,4.26]],"ltp":2.18,"tv":52.22,"id":67083366}]}]}
{"op":"mcm","clk":"11927780467","pt":1724243291501,"mc":[{"id":"1.232048948","rc":[{"trd":[[1.92,1.02]],"batl":[[0,1.92,2.55]],"ltp":1.92,"tv":10.21,"id":72857114},{"trd":[[2.08,0.94]],"batl":[[0,900,1.21],[1,900,0]],"ltp":2.08,"tv":53.16,"id":67083366}],"tv":63.38}]}
{"op":"mcm","clk":"11927780604","pt":1724243294181,"mc":[{"id":"1.232048948","rc":[{"batb":[[0,1.45,5.2],[1,1.43,4.26],[2,1.4,4.26]],"ltp":2.08,"tv":53.16,"id":67083366}]}]}
{"op":"mcm","clk":"11927780754","pt":1724243296767,"mc":[{"id":"1.232048948","rc":[{"batb":[[0,1.46,10.94],[1,1.45,4.26],[2,1.43,4.26]],"ltp":2.08,"tv":53.16,"id":67083366}]}]}
{"op":"mcm","clk":"11927780961","pt":1724243300273,"mc":[{"id":"1.232048948","rc":[{"batb":[[0,1.45,5.2],[1,1.43,4.26],[2,1.4,4.26]],"ltp":2.08,"tv":53.16,"id":67083366}]}]}
{"op":"mcm","clk":"11927781237","pt":1724243305787,"mc":[{"id":"1.232048948","rc":[{"batb":[[0,1.46,10.94],[1,1.45,4.26],[2,1.43,4.26]],"ltp":2.08,"tv":53.16,"id":67083366}]}]}
{"op":"mcm","clk":"11927781455","pt":1724243309714,"mc":[{"id":"1.232048948","rc":[{"batb":[[0,1.45,5.2],[1,1.43,4.26],[2,1.4,4.26]],"ltp":2.08,"tv":53.16,"id":67083366}]}]}
{"op":"mcm","clk":"11927782617","pt":1724243331636,"mc":[{"id":"1.232048948","rc":[{"batb":[[0,1.46,10.94],[1,1.45,4.26],[2,1.43,4.26]],"ltp":2.08,"tv":53.16,"id":67083366}]}]}
{"op":"mcm","clk":"11927782831","pt":1724243335218,"mc":[{"id":"1.232048948","rc":[{"batb":[[0,1.45,5.2],[1,1.43,4.26],[2,1.4,4.26]],"ltp":2.08,"tv":53.16,"id":67083366}]}]}
{"op":"mcm","clk":"11927783062","pt":1724243339422,"mc":[{"id":"1.232048948","rc":[{"batb":[[0,1.46,10.94],[1,1.45,4.26],[2,1.43,4.26]],"ltp":2.08,"tv":53.16,"id":67083366}]}]}
{"op":"mcm","clk":"11927783268","pt":1724243343739,"mc":[{"id":"1.232048948","rc":[{"batb":[[0,1.45,5.2],[1,1.43,4.26],[2,1.4,4.26]],"ltp":2.08,"tv":53.16,"id":67083366}]}]}
{"op":"mcm","clk":"11927783559","pt":1724243348443,"mc":[{"id":"1.232048948","rc":[{"batb":[[0,1.46,10.94],[1,1.45,4.26],[2,1.43,4.26]],"ltp":2.08,"tv":53.16,"id":67083366}]}]}
{"op":"mcm","clk":"11927783771","pt":1724243352077,"mc":[{"id":"1.232048948","rc":[{"batb":[[0,1.45,5.2],[1,1.43,4.26],[2,1.4,4.26]],"ltp":2.08,"tv":53.16,"id":67083366}]}]}
{"op":"mcm","clk":"11927784204","pt":1724243359541,"mc":[{"id":"1.232048948","rc":[{"batb":[[0,1.46,10.94],[1,1.45,4.26],[2,1.43,4.26]],"ltp":2.08,"tv":53.16,"id":67083366}]}]}
{"op":"mcm","clk":"11927784405","pt":1724243363577,"mc":[{"id":"1.232048948","rc":[{"batb":[[0,1.45,5.2],[1,1.43,4.26],[2,1.4,4.26]],"ltp":2.08,"tv":53.16,"id":67083366}]}]}
{"op":"mcm","clk":"11927784529","pt":1724243365951,"mc":[{"id":"1.232048948","rc":[{"batb":[[0,1.46,10.94],[1,1.45,4.26],[2,1.43,4.26]],"ltp":2.08,"tv":53.16,"id":67083366}]}]}
{"op":"mcm","clk":"11927784715","pt":1724243369456,"mc":[{"id":"1.232048948","rc":[{"batb":[[0,1.45,5.2],[1,1.43,4.26],[2,1.4,4.26]],"ltp":2.08,"tv":53.16,"id":67083366}]}]}
{"op":"mcm","clk":"11927784950","pt":1724243373798,"mc":[{"id":"1.232048948","rc":[{"batb":[[0,1.46,10.94],[1,1.45,4.26],[2,1.43,4.26]],"ltp":2.08,"tv":53.16,"id":67083366}]}]}
{"op":"mcm","clk":"11927785183","pt":1724243377414,"mc":[{"id":"1.232048948","rc":[{"batb":[[0,1.45,5.2],[1,1.43,4.26],[2,1.4,4.26]],"ltp":2.08,"tv":53.16,"id":67083366}]}]}
{"op":"mcm","clk":"11927785988","pt":1724243392227,"mc":[{"id":"1.232048948","rc":[{"batb":[[0,1.46,10.94],[1,1.45,4.26],[2,1.43,4.26]],"ltp":2.08,"tv":53.16,"id":67083366}]}]}
{"op":"mcm","clk":"11927786202","pt":1724243396125,"mc":[{"id":"1.232048948","rc":[{"batb":[[0,1.45,5.2],[1,1.43,4.26],[2,1.4,4.26]],"ltp":2.08,"tv":53.16,"id":67083366}]}]}
{"op":"mcm","clk":"11927786493","pt":1724243400924,"mc":[{"id":"1.232048948","rc":[{"batb":[[0,1.46,10.94],[1,1.45,4.26],[2,1.43,4.26]],"ltp":2.08,"tv":53.16,"id":67083366}]}]}
{"op":"mcm","clk":"11927786860","pt":1724243404800,"mc":[{"id":"1.232048948","rc":[{"batb":[[0,1.45,5.2],[1,1.43,4.26],[2,1.4,4.26]],"ltp":2.08,"tv":53.16,"id":67083366}]}]}
{"op":"mcm","clk":"11927787454","pt":1724243413408,"mc":[{"id":"1.232048948","rc":[{"batb":[[0,1.46,10.94],[1,1.45,4.26],[2,1.43,4.26]],"ltp":2.08,"tv":53.16,"id":67083366}]}]}
{"op":"mcm","clk":"11927787655","pt":1724243416638,"mc":[{"id":"1.232048948","rc":[{"batb":[[0,1.45,5.2],[1,1.43,4.26],[2,1.4,4.26]],"ltp":2.08,"tv":53.16,"id":67083366}]}]}
{"op":"mcm","clk":"11927787908","pt":1724243420556,"mc":[{"id":"1.232048948","rc":[{"batb":[[0,1.46,10.94],[1,1.45,4.26],[2,1.43,4.26]],"ltp":2.08,"tv":53.16,"id":67083366}]}]}
{"op":"mcm","clk":"11927788170","pt":1724243424530,"mc":[{"id":"1.232048948","rc":[{"batb":[[0,1.45,5.2],[1,1.43,4.26],[2,1.4,4.26]],"ltp":2.08,"tv":53.16,"id":67083366}]}]}
{"op":"mcm","clk":"11927788398","pt":1724243428155,"mc":[{"id":"1.232048948","rc":[{"batb":[[0,1.46,10.94],[1,1.45,4.26],[2,1.43,4.26]],"ltp":2.08,"tv":53.16,"id":67083366}]}]}
{"op":"mcm","clk":"11927788597","pt":1724243431563,"mc":[{"id":"1.232048948","rc":[{"batb":[[0,1.45,5.2],[1,1.43,4.26],[2,1.4,4.26]],"ltp":2.08,"tv":53.16,"id":67083366}]}]}
{"op":"mcm","clk":"11927788900","pt":1724243435751,"mc":[{"id":"1.232048948","rc":[{"batb":[[0,1.46,10.94],[1,1.45,4.26],[2,1.43,4.26]],"ltp":2.08,"tv":53.16,"id":67083366}]}]}
{"op":"mcm","clk":"11927789165","pt":1724243439162,"mc":[{"id":"1.232048948","rc":[{"batb":[[0,1.45,5.2],[1,1.43,4.26],[2,1.4,4.26]],"ltp":2.08,"tv":53.16,"id":67083366}]}]}
{"op":"mcm","clk":"11927789347","pt":1724243441447,"mc":[{"id":"1.232048948","rc":[{"batb":[[0,1.46,10.94],[1,1.45,4.26],[2,1.43,4.26]],"ltp":2.08,"tv":53.16,"id":67083366}]}]}
{"op":"mcm","clk":"11927789607","pt":1724243445473,"mc":[{"id":"1.232048948","rc":[{"batb":[[0,1.45,5.2],[1,1.43,4.26],[2,1.4,4.26]],"ltp":2.08,"tv":53.16,"id":67083366}]}]}
{"op":"mcm","clk":"11927789808","pt":1724243447758,"mc":[{"id":"1.232048948","rc":[{"batb":[[0,1.46,10.94],[1,1.45,4.26],[2,1.43,4.26]],"ltp":2.08,"tv":53.16,"id":67083366}]}]}
{"op":"mcm","clk":"11927790019","pt":1724243451157,"mc":[{"id":"1.232048948","rc":[{"batb":[[0,1.45,5.2],[1,1.43,4.26],[2,1.4,4.26]],"ltp":2.08,"tv":53.16,"id":67083366}]}]}
{"op":"mcm","clk":"11927790217","pt":1724243454085,"mc":[{"id":"1.232048948","rc":[{"batb":[[0,1.46,10.94],[1,1.45,4.26],[2,1.43,4.26]],"ltp":2.08,"tv":53.16,"id":67083366}]}]}
{"op":"mcm","clk":"11927790483","pt":1724243457890,"mc":[{"id":"1.232048948","rc":[{"batb":[[0,1.45,5.2],[1,1.43,4.26],[2,1.4,4.26]],"ltp":2.08,"tv":53.16,"id":67083366}]}]}
{"op":"mcm","clk":"11927790840","pt":1724243463195,"mc":[{"id":"1.232048948","rc":[{"batb":[[0,1.46,10.94],[1,1.45,4.26],[2,1.43,4.26]],"ltp":2.08,"tv":53.16,"id":67083366}]}]}
{"op":"mcm","clk":"11927791104","pt":1724243466760,"mc":[{"id":"1.232048948","rc":[{"batb":[[0,1.45,5.2],[1,1.43,4.26],[2,1.4,4.26]],"ltp":2.08,"tv":53.16,"id":67083366}]}]}
{"op":"mcm","clk":"11927791645","pt":1724243474187,"mc":[{"id":"1.232048948","rc":[{"batb":[[0,1.46,10.94],[1,1.45,4.26],[2,1.43,4.26]],"ltp":2.08,"tv":53.16,"id":67083366}]}]}
{"op":"mcm","clk":"11927792246","pt":1724243482679,"mc":[{"id":"1.232048948","rc":[{"batb":[[0,1.45,5.2],[1,1.43,4.26],[2,1.4,4.26]],"ltp":2.08,"tv":53.16,"id":67083366}]}]}
{"op":"mcm","clk":"11927792451","pt":1724243486307,"mc":[{"id":"1.232048948","rc":[{"batb":[[0,1.46,10.94],[1,1.45,4.26],[2,1.43,4.26]],"ltp":2.08,"tv":53.16,"id":67083366}]}]}
{"op":"mcm","clk":"11927792834","pt":1724243492012,"mc":[{"id":"1.232048948","rc":[{"batb":[[0,1.45,5.2],[1,1.43,4.26],[2,1.4,4.26]],"ltp":2.08,"tv":53.16,"id":67083366}]}]}
{"op":"mcm","clk":"11927793062","pt":1724243495217,"mc":[{"id":"1.232048948","rc":[{"batb":[[0,1.46,10.94],[1,1.45,4.26],[2,1.43,4.26]],"ltp":2.08,"tv":53.16,"id":67083366}]}]}
{"op":"mcm","clk":"11927793306","pt":1724243499022,"mc":[{"id":"1.232048948","rc":[{"batb":[[0,1.45,5.2],[1,1.43,4.26],[2,1.4,4.26]],"ltp":2.08,"tv":53.16,"id":67083366}]}]}
{"op":"mcm","clk":"11927793589","pt":1724243503424,"mc":[{"id":"1.232048948","rc":[{"batb":[[0,1.46,10.94],[1,1.45,4.26],[2,1.43,4.26]],"ltp":2.08,"tv":53.16,"id":67083366}]}]}
{"op":"mcm","clk":"11927793802","pt":1724243507020,"mc":[{"id":"1.232048948","rc":[{"batb":[[0,1.45,5.2],[1,1.43,4.26],[2,1.4,4.26]],"ltp":2.08,"tv":53.16,"id":67083366}]}]}
{"op":"mcm","clk":"11927794092","pt":1724243511434,"mc":[{"id":"1.232048948","rc":[{"batb":[[0,1.46,10.94],[1,1.45,4.26],[2,1.43,4.26]],"ltp":2.08,"tv":53.16,"id":67083366}]}]}
{"op":"mcm","clk":"11927794297","pt":1724243514850,"mc":[{"id":"1.232048948","rc":[{"batb":[[0,1.45,5.2],[1,1.43,4.26],[2,1.4,4.26]],"ltp":2.08,"tv":53.16,"id":67083366}]}]}
{"op":"mcm","clk":"11927794564","pt":1724243519725,"mc":[{"id":"1.232048948","rc":[{"batb":[[0,1.46,10.94],[1,1.45,4.26],[2,1.43,4.26]],"ltp":2.08,"tv":53.16,"id":67083366}]}]}
{"op":"mcm","clk":"11927794768","pt":1724243523258,"mc":[{"id":"1.232048948","rc":[{"batb":[[0,1.45,5.2],[1,1.43,4.26],[2,1.4,4.26]],"ltp":2.08,"tv":53.16,"id":67083366}]}]}
{"op":"mcm","clk":"11927795289","pt":1724243531178,"mc":[{"id":"1.232048948","rc":[{"batb":[[0,1.46,10.94],[1,1.45,4.26],[2,1.43,4.26]],"ltp":2.08,"tv":53.16,"id":67083366}]}]}
{"op":"mcm","clk":"11927795525","pt":1724243534752,"mc":[{"id":"1.232048948","rc":[{"batb":[[0,1.45,5.2],[1,1.43,4.26],[2,1.4,4.26]],"ltp":2.08,"tv":53.16,"id":67083366}]}]}
{"op":"mcm","clk":"11927795674","pt":1724243537545,"mc":[{"id":"1.232048948","rc":[{"batb":[[0,1.46,10.94],[1,1.45,4.26],[2,1.43,4.26]],"ltp":2.08,"tv":53.16,"id":67083366}]}]}
{"op":"mcm","clk":"11927795891","pt":1724243541443,"mc":[{"id":"1.232048948","rc":[{"batb":[[0,1.45,5.2],[1,1.43,4.26],[2,1.4,4.26]],"ltp":2.08,"tv":53.16,"id":67083366}]}]}
{"op":"mcm","clk":"11927796245","pt":1724243547951,"mc":[{"id":"1.232048948","rc":[{"batb":[[0,1.46,10.94],[1,1.45,4.26],[2,1.43,4.26]],"ltp":2.08,"tv":53.16,"id":67083366}]}]}
{"op":"mcm","clk":"11927796543","pt":1724243551694,"mc":[{"id":"1.232048948","rc":[{"batb":[[0,1.45,5.2],[1,1.43,4.26],[2,1.4,4.26]],"ltp":2.08,"tv":53.16,"id":67083366}]}]}
{"op":"mcm","clk":"11927796961","pt":1724243557394,"mc":[{"id":"1.232048948","rc":[{"batb":[[0,1.46,10.94],[1,1.45,4.26],[2,1.43,4.26]],"ltp":2.08,"tv":53.16,"id":67083366}]}]}
{"op":"mcm","clk":"11927797631","pt":1724243566766,"mc":[{"id":"1.232048948","rc":[{"batb":[[0,1.45,5.2],[1,1.43,4.26],[2,1.4,4.26]],"ltp":2.08,"tv":53.16,"id":67083366}]}]}
{"op":"mcm","clk":"11927797876","pt":1724243570367,"mc":[{"id":"1.232048948","rc":[{"batb":[[0,1.46,10.94],[1,1.45,4.26],[2,1.43,4.26]],"ltp":2.08,"tv":53.16,"id":67083366}]}]}
{"op":"mcm","clk":"11927798246","pt":1724243575887,"mc":[{"id":"1.232048948","rc":[{"batb":[[0,1.45,5.2],[1,1.43,4.26],[2,1.4,4.26]],"ltp":2.08,"tv":53.16,"id":67083366}]}]}
{"op":"mcm","clk":"11927798446","pt":1724243579125,"mc":[{"id":"1.232048948","rc":[{"batb":[[0,1.46,10.94],[1,1.45,4.26],[2,1.43,4.26]],"ltp":2.08,"tv":53.16,"id":67083366}]}]}
{"op":"mcm","clk":"11927798653","pt":1724243582387,"mc":[{"id":"1.232048948","rc":[{"batb":[[0,1.45,5.2],[1,1.43,4.26],[2,1.4,4.26]],"ltp":2.08,"tv":53.16,"id":67083366}]}]}
{"op":"mcm","clk":"11927798879","pt":1724243585329,"mc":[{"id":"1.232048948","rc":[{"batb":[[0,1.46,10.94],[1,1.45,4.26],[2,1.43,4.26]],"ltp":2.08,"tv":53.16,"id":67083366}]}]}
{"op":"mcm","clk":"11927799068","pt":1724243588614,"mc":[{"id":"1.232048948","rc":[{"batb":[[0,1.45,5.2],[1,1.43,4.26],[2,1.4,4.26]],"ltp":2.08,"tv":53.16,"id":67083366}]}]}
{"op":"mcm","clk":"11927799359","pt":1724243593036,"mc":[{"id":"1.232048948","rc":[{"batb":[[0,1.46,10.94],[1,1.45,4.26],[2,1.43,4.26]],"ltp":2.08,"tv":53.16,"id":67083366}]}]}
{"op":"mcm","clk":"11927799592","pt":1724243596531,"mc":[{"id":"1.232048948","rc":[{"batb":[[0,1.45,5.2],[1,1.43,4.26],[2,1.4,4.26]],"ltp":2.08,"tv":53.16,"id":67083366}]}]}
{"op":"mcm","clk":"11927799784","pt":1724243598897,"mc":[{"id":"1.232048948","rc":[{"batb":[[0,1.46,10.94],[1,1.45,4.26],[2,1.43,4.26]],"ltp":2.08,"tv":53.16,"id":67083366}]}]}
{"op":"mcm","clk":"11927800029","pt":1724243602951,"mc":[{"id":"1.232048948","rc":[{"batb":[[0,1.45,5.2],[1,1.43,4.26],[2,1.4,4.26]],"ltp":2.08,"tv":53.16,"id":67083366}]}]}
{"op":"mcm","clk":"11927800482","pt":1724243609416,"mc":[{"id":"1.232048948","rc":[{"batb":[[0,1.46,10.94],[1,1.45,4.26],[2,1.43,4.26]],"ltp":2.08,"tv":53.16,"id":67083366}]}]}
{"op":"mcm","clk":"11927800708","pt":1724243612757,"mc":[{"id":"1.232048948","rc":[{"batb":[[0,1.45,5.2],[1,1.43,4.26],[2,1.4,4.26]],"ltp":2.08,"tv":53.16,"id":67083366}]}]}
{"op":"mcm","clk":"11927800966","pt":1724243615946,"mc":[{"id":"1.232048948","rc":[{"batb":[[0,1.46,10.94],[1,1.45,4.26],[2,1.43,4.26]],"ltp":2.08,"tv":53.16,"id":67083366}]}]}
{"op":"mcm","clk":"11927801228","pt":1724243619840,"mc":[{"id":"1.232048948","rc":[{"batb":[[0,1.45,5.2],[1,1.43,4.26],[2,1.4,4.26]],"ltp":2.08,"tv":53.16,"id":67083366}]}]}
{"op":"mcm","clk":"11927801356","pt":1724243622054,"mc":[{"id":"1.232048948","rc":[{"batb":[[0,1.46,10.94],[1,1.45,4.26],[2,1.43,4.26]],"ltp":2.08,"tv":53.16,"id":67083366}]}]}
{"op":"mcm","clk":"11927801621","pt":1724243625555,"mc":[{"id":"1.232048948","rc":[{"batb":[[0,1.45,5.2],[1,1.43,4.26],[2,1.4,4.26]],"ltp":2.08,"tv":53.16,"id":67083366}]}]}
{"op":"mcm","clk":"11927801872","pt":1724243629358,"mc":[{"id":"1.232048948","rc":[{"batb":[[0,1.46,10.94],[1,1.45,4.26],[2,1.43,4.26]],"ltp":2.08,"tv":53.16,"id":67083366}]}]}
{"op":"mcm","clk":"11927802111","pt":1724243633158,"mc":[{"id":"1.232048948","rc":[{"batb":[[0,1.45,5.2],[1,1.43,4.26],[2,1.4,4.26]],"ltp":2.08,"tv":53.16,"id":67083366}]}]}
{"op":"mcm","clk":"11927802558","pt":1724243640348,"mc":[{"id":"1.232048948","rc":[{"batb":[[0,1.46,10.94],[1,1.45,4.26],[2,1.43,4.26]],"ltp":2.08,"tv":53.16,"id":67083366}]}]}
{"op":"mcm","clk":"11927802800","pt":1724243643855,"mc":[{"id":"1.232048948","rc":[{"batb":[[0,1.45,5.2],[1,1.43,4.26],[2,1.4,4.26]],"ltp":2.08,"tv":53.16,"id":67083366}]}]}
{"op":"mcm","clk":"11927803193","pt":1724243649463,"mc":[{"id":"1.232048948","rc":[{"batb":[[0,1.46,10.94],[1,1.45,4.26],[2,1.43,4.26]],"ltp":2.08,"tv":53.16,"id":67083366}]}]}
{"op":"mcm","clk":"11927803432","pt":1724243652748,"mc":[{"id":"1.232048948","rc":[{"batb":[[0,1.45,5.2],[1,1.43,4.26],[2,1.4,4.26]],"ltp":2.08,"tv":53.16,"id":67083366}]}]}
{"op":"mcm","clk":"11927803793","pt":1724243657748,"mc":[{"id":"1.232048948","rc":[{"batb":[[0,1.46,10.94],[1,1.45,4.26],[2,1.43,4.26]],"ltp":2.08,"tv":53.16,"id":67083366}]}]}
{"op":"mcm","clk":"11927804045","pt":1724243661208,"mc":[{"id":"1.232048948","rc":[{"batb":[[0,1.45,5.2],[1,1.43,4.26],[2,1.4,4.26]],"ltp":2.08,"tv":53.16,"id":67083366}]}]}
{"op":"mcm","clk":"11927805190","pt":1724243676595,"mc":[{"id":"1.232048948","rc":[{"batb":[[0,1.46,10.94],[1,1.45,4.26],[2,1.43,4.26]],"ltp":2.08,"tv":53.16,"id":67083366}]}]}
{"op":"mcm","clk":"11927805502","pt":1724243680427,"mc":[{"id":"1.232048948","rc":[{"batb":[[0,1.45,5.2],[1,1.43,4.26],[2,1.4,4.26]],"ltp":2.08,"tv":53.16,"id":67083366}]}]}
{"op":"mcm","clk":"11927805835","pt":1724243684925,"mc":[{"id":"1.232048948","rc":[{"batb":[[0,1.47,10.94],[1,1.45,4.26],[2,1.43,4.26]],"ltp":2.08,"tv":53.16,"id":67083366}]}]}
{"op":"mcm","clk":"11927806620","pt":1724243695443,"mc":[{"id":"1.232048948","rc":[{"batb":[[0,1.45,5.2],[1,1.43,4.26],[2,1.4,4.26]],"ltp":2.08,"tv":53.16,"id":67083366}]}]}
{"op":"mcm","clk":"11927806937","pt":1724243699645,"mc":[{"id":"1.232048948","rc":[{"batb":[[0,1.46,10.94],[1,1.45,4.26],[2,1.43,4.26]],"ltp":2.08,"tv":53.16,"id":67083366}]}]}
{"op":"mcm","clk":"11927807484","pt":1724243706225,"mc":[{"id":"1.232048948","rc":[{"batb":[[0,1.45,5.2],[1,1.43,4.26],[2,1.4,4.26]],"ltp":2.08,"tv":53.16,"id":67083366}]}]}
{"op":"mcm","clk":"11927807705","pt":1724243709747,"mc":[{"id":"1.232048948","rc":[{"batb":[[0,1.46,10.94],[1,1.45,4.26],[2,1.43,4.26]],"ltp":2.08,"tv":53.16,"id":67083366}]}]}
{"op":"mcm","clk":"11927807977","pt":1724243713876,"mc":[{"id":"1.232048948","rc":[{"batb":[[0,1.45,5.2],[1,1.43,4.26],[2,1.4,4.26]],"ltp":2.08,"tv":53.16,"id":67083366}]}]}
{"op":"mcm","clk":"11927809364","pt":1724243733656,"mc":[{"id":"1.232048948","rc":[{"batb":[[0,1.46,10.94],[1,1.45,4.26],[2,1.43,4.26]],"ltp":2.08,"tv":53.16,"id":67083366}]}]}
{"op":"mcm","clk":"11927809758","pt":1724243739188,"mc":[{"id":"1.232048948","rc":[{"batb":[[0,1.45,5.2],[1,1.43,4.26],[2,1.4,4.26]],"ltp":2.08,"tv":53.16,"id":67083366}]}]}
{"op":"mcm","clk":"11927809962","pt":1724243741660,"mc":[{"id":"1.232048948","rc":[{"batb":[[0,1.46,10.94],[1,1.45,4.26],[2,1.43,4.26]],"ltp":2.08,"tv":53.16,"id":67083366}]}]}
{"op":"mcm","clk":"11927810216","pt":1724243745166,"mc":[{"id":"1.232048948","rc":[{"batb":[[0,1.45,5.2],[1,1.43,4.26],[2,1.4,4.26]],"ltp":2.08,"tv":53.16,"id":67083366}]}]}
{"op":"mcm","clk":"11927811191","pt":1724243759274,"mc":[{"id":"1.232048948","rc":[{"batb":[[0,1.46,10.94],[1,1.45,4.26],[2,1.43,4.26]],"ltp":2.08,"tv":53.16,"id":67083366}]}]}
{"op":"mcm","clk":"11927811473","pt":1724243763004,"mc":[{"id":"1.232048948","rc":[{"batb":[[0,1.45,5.2],[1,1.43,4.26],[2,1.4,4.26]],"ltp":2.08,"tv":53.16,"id":67083366}]}]}
{"op":"mcm","clk":"11927811667","pt":1724243765903,"mc":[{"id":"1.232048948","rc":[{"batb":[[0,1.46,10.94],[1,1.45,4.26],[2,1.43,4.26]],"ltp":2.08,"tv":53.16,"id":67083366}]}]}
{"op":"mcm","clk":"11927811860","pt":1724243769412,"mc":[{"id":"1.232048948","rc":[{"batb":[[0,1.45,5.2],[1,1.43,4.26],[2,1.4,4.26]],"ltp":2.08,"tv":53.16,"id":67083366}]}]}
{"op":"mcm","clk":"11927812074","pt":1724243773116,"mc":[{"id":"1.232048948","rc":[{"batb":[[0,1.46,10.94],[1,1.45,4.26],[2,1.43,4.26]],"ltp":2.08,"tv":53.16,"id":67083366}]}]}
{"op":"mcm","clk":"11927812129","pt":1724243774505,"mc":[{"id":"1.232048948","rc":[{"batb":[[0,1.47,1.83],[1,1.46,10],[2,1.45,4.26]],"ltp":2.08,"tv":53.16,"id":67083366}]}]}
{"op":"mcm","clk":"11927812269","pt":1724243776607,"mc":[{"id":"1.232048948","rc":[{"batb":[[1,1.45,4.26],[2,1.43,4.26]],"ltp":2.08,"tv":53.16,"id":67083366}]}]}
{"op":"mcm","clk":"11927869054","pt":1724244602289,"mc":[{"id":"1.232048948","rc":[{"batb":[[0,1.48,18.8],[1,1.45,5.16]],"ltp":2.08,"tv":53.16,"id":67083366}]}]}
{"op":"mcm","clk":"11927869078","pt":1724244602586,"mc":[{"id":"1.232048948","rc":[{"batb":[[0,1.49,10.94],[1,1.48,17.86],[2,1.45,5.16]],"ltp":2.08,"tv":53.16,"id":67083366}]}]}
{"op":"mcm","clk":"11927869309","pt":1724244605884,"mc":[{"id":"1.232048948","rc":[{"batb":[[0,1.48,18.8],[1,1.45,5.16],[2,1.43,4.26]],"ltp":2.08,"tv":53.16,"id":67083366}]}]}
{"op":"mcm","clk":"11927870310","pt":1724244616747,"mc":[{"id":"1.232048948","rc":[{"batb":[[0,1.49,10.94],[1,1.48,17.86],[2,1.45,5.16]],"ltp":2.08,"tv":53.16,"id":67083366}]}]}
{"op":"mcm","clk":"11927870607","pt":1724244620254,"mc":[{"id":"1.232048948","rc":[{"batb":[[0,1.48,18.8],[1,1.45,5.16],[2,1.43,4.26]],"ltp":2.08,"tv":53.16,"id":67083366}]}]}
{"op":"mcm","clk":"11927871111","pt":1724244628441,"mc":[{"id":"1.232048948","rc":[{"batb":[[0,1.49,10.94],[1,1.48,17.86],[2,1.45,5.16]],"ltp":2.08,"tv":53.16,"id":67083366}]}]}
{"op":"mcm","clk":"11927871308","pt":1724244631834,"mc":[{"id":"1.232048948","rc":[{"batb":[[0,1.48,18.8],[1,1.45,5.16],[2,1.43,4.26]],"ltp":2.08,"tv":53.16,"id":67083366}]}]}
{"op":"mcm","clk":"11927871605","pt":1724244637449,"mc":[{"id":"1.232048948","rc":[{"batb":[[0,1.49,10.94],[1,1.48,17.86],[2,1.45,5.16]],"ltp":2.08,"tv":53.16,"id":67083366}]}]}
{"op":"mcm","clk":"11927871808","pt":1724244640877,"mc":[{"id":"1.232048948","rc":[{"batb":[[0,1.48,18.8],[1,1.45,5.16],[2,1.43,4.26]],"ltp":2.08,"tv":53.16,"id":67083366}]}]}
{"op":"mcm","clk":"11927872274","pt":1724244649172,"mc":[{"id":"1.232048948","rc":[{"batb":[[0,1.49,10.94],[1,1.48,17.86],[2,1.45,5.16]],"ltp":2.08,"tv":53.16,"id":67083366}]}]}
{"op":"mcm","clk":"11927872493","pt":1724244652743,"mc":[{"id":"1.232048948","rc":[{"batb":[[0,1.48,18.8],[1,1.45,5.16],[2,1.43,4.26]],"ltp":2.08,"tv":53.16,"id":67083366}]}]}
{"op":"mcm","clk":"11927872649","pt":1724244655277,"mc":[{"id":"1.232048948","rc":[{"batb":[[0,1.49,10.94],[1,1.48,17.86],[2,1.45,5.16]],"ltp":2.08,"tv":53.16,"id":67083366}]}]}
{"op":"mcm","clk":"11927872843","pt":1724244658687,"mc":[{"id":"1.232048948","rc":[{"batb":[[0,1.48,18.8],[1,1.45,5.16],[2,1.43,4.26]],"ltp":2.08,"tv":53.16,"id":67083366}]}]}
{"op":"mcm","clk":"11927873012","pt":1724244661484,"mc":[{"id":"1.232048948","rc":[{"batb":[[0,1.49,10.94],[1,1.48,17.86],[2,1.45,5.16]],"ltp":2.08,"tv":53.16,"id":67083366}]}]}
{"op":"mcm","clk":"11927873246","pt":1724244665161,"mc":[{"id":"1.232048948","rc":[{"batb":[[0,1.48,18.8],[1,1.45,5.16],[2,1.43,4.26]],"ltp":2.08,"tv":53.16,"id":67083366}]}]}
{"op":"mcm","clk":"11927873455","pt":1724244668680,"mc":[{"id":"1.232048948","rc":[{"batb":[[0,1.49,10.94],[1,1.48,17.86],[2,1.45,5.16]],"ltp":2.08,"tv":53.16,"id":67083366}]}]}
{"op":"mcm","clk":"11927873668","pt":1724244672081,"mc":[{"id":"1.232048948","rc":[{"batb":[[0,1.48,18.8],[1,1.45,5.16],[2,1.43,4.26]],"ltp":2.08,"tv":53.16,"id":67083366}]}]}
{"op":"mcm","clk":"11927873900","pt":1724244676007,"mc":[{"id":"1.232048948","rc":[{"batb":[[0,1.49,10.94],[1,1.48,17.86],[2,1.45,5.16]],"ltp":2.08,"tv":53.16,"id":67083366}]}]}
{"op":"mcm","clk":"11927874088","pt":1724244679313,"mc":[{"id":"1.232048948","rc":[{"batb":[[0,1.48,18.8],[1,1.45,5.16],[2,1.43,4.26]],"ltp":2.08,"tv":53.16,"id":67083366}]}]}
{"op":"mcm","clk":"11927874242","pt":1724244682009,"mc":[{"id":"1.232048948","rc":[{"batb":[[0,1.49,10.94],[1,1.48,17.86],[2,1.45,5.16]],"ltp":2.08,"tv":53.16,"id":67083366}]}]}
{"op":"mcm","clk":"11927874436","pt":1724244685508,"mc":[{"id":"1.232048948","rc":[{"batb":[[0,1.48,18.8],[1,1.45,5.16],[2,1.43,4.26]],"ltp":2.08,"tv":53.16,"id":67083366}]}]}
{"op":"mcm","clk":"11927874618","pt":1724244688920,"mc":[{"id":"1.232048948","rc":[{"batb":[[0,1.49,10.94],[1,1.48,17.86],[2,1.45,5.16]],"ltp":2.08,"tv":53.16,"id":67083366}]}]}
{"op":"mcm","clk":"11927874813","pt":1724244692603,"mc":[{"id":"1.232048948","rc":[{"batb":[[0,1.48,18.8],[1,1.45,5.16],[2,1.43,4.26]],"ltp":2.08,"tv":53.16,"id":67083366}]}]}
{"op":"mcm","clk":"11927875317","pt":1724244702397,"mc":[{"id":"1.232048948","rc":[{"batb":[[0,1.49,10.94],[1,1.48,17.86],[2,1.45,5.16]],"ltp":2.08,"tv":53.16,"id":67083366}]}]}
{"op":"mcm","clk":"11927875556","pt":1724244706134,"mc":[{"id":"1.232048948","rc":[{"batb":[[0,1.48,18.8],[1,1.45,5.16],[2,1.43,4.26]],"ltp":2.08,"tv":53.16,"id":67083366}]}]}
{"op":"mcm","clk":"11927876013","pt":1724244715451,"mc":[{"id":"1.232048948","rc":[{"batb":[[0,1.49,10.94],[1,1.48,17.86],[2,1.45,5.16]],"ltp":2.08,"tv":53.16,"id":67083366}]}]}
{"op":"mcm","clk":"11927876235","pt":1724244719244,"mc":[{"id":"1.232048948","rc":[{"batb":[[0,1.48,18.8],[1,1.45,5.16],[2,1.43,4.26]],"ltp":2.08,"tv":53.16,"id":67083366}]}]}
{"op":"mcm","clk":"11927876388","pt":1724244721534,"mc":[{"id":"1.232048948","rc":[{"batb":[[0,1.49,10.94],[1,1.48,17.86],[2,1.45,5.16]],"ltp":2.08,"tv":53.16,"id":67083366}]}]}
{"op":"mcm","clk":"11927876669","pt":1724244725637,"mc":[{"id":"1.232048948","rc":[{"batb":[[0,1.48,18.8],[1,1.45,5.16],[2,1.43,4.26]],"ltp":2.08,"tv":53.16,"id":67083366}]}]}
{"op":"mcm","clk":"11927876898","pt":1724244729242,"mc":[{"id":"1.232048948","rc":[{"batb":[[0,1.49,10.94],[1,1.48,17.86],[2,1.45,5.16]],"ltp":2.08,"tv":53.16,"id":67083366}]}]}
{"op":"mcm","clk":"11927877123","pt":1724244732752,"mc":[{"id":"1.232048948","rc":[{"batb":[[0,1.48,18.8],[1,1.45,5.16],[2,1.43,4.26]],"ltp":2.08,"tv":53.16,"id":67083366}]}]}
{"op":"mcm","clk":"11927877307","pt":1724244735956,"mc":[{"id":"1.232048948","rc":[{"batb":[[0,1.49,10.94],[1,1.48,17.86],[2,1.45,5.16]],"ltp":2.08,"tv":53.16,"id":67083366}]}]}
{"op":"mcm","clk":"11927877530","pt":1724244739566,"mc":[{"id":"1.232048948","rc":[{"batb":[[0,1.48,18.8],[1,1.45,5.16],[2,1.43,4.26]],"ltp":2.08,"tv":53.16,"id":67083366}]}]}
{"op":"mcm","clk":"11927877693","pt":1724244742499,"mc":[{"id":"1.232048948","rc":[{"batb":[[0,1.49,10.94],[1,1.48,17.86],[2,1.45,5.16]],"ltp":2.08,"tv":53.16,"id":67083366}]}]}
{"op":"mcm","clk":"11927877892","pt":1724244745783,"mc":[{"id":"1.232048948","rc":[{"batb":[[0,1.48,18.8],[1,1.45,5.16],[2,1.43,4.26]],"ltp":2.08,"tv":53.16,"id":67083366}]}]}
{"op":"mcm","clk":"11927878338","pt":1724244752253,"mc":[{"id":"1.232048948","rc":[{"batb":[[0,1.49,10.94],[1,1.48,17.86],[2,1.45,5.16]],"ltp":2.08,"tv":53.16,"id":67083366}]}]}
{"op":"mcm","clk":"11927878586","pt":1724244755979,"mc":[{"id":"1.232048948","rc":[{"batb":[[0,1.48,18.8],[1,1.45,5.16],[2,1.43,4.26]],"ltp":2.08,"tv":53.16,"id":67083366}]}]}
{"op":"mcm","clk":"11927878965","pt":1724244762082,"mc":[{"id":"1.232048948","rc":[{"batb":[[0,1.49,10.94],[1,1.48,17.86],[2,1.45,5.16]],"ltp":2.08,"tv":53.16,"id":67083366}]}]}
{"op":"mcm","clk":"11927879216","pt":1724244765899,"mc":[{"id":"1.232048948","rc":[{"batb":[[0,1.48,18.8],[1,1.45,5.16],[2,1.43,4.26]],"ltp":2.08,"tv":53.16,"id":67083366}]}]}
{"op":"mcm","clk":"11927879561","pt":1724244770795,"mc":[{"id":"1.232048948","rc":[{"batb":[[0,1.49,10.94],[1,1.48,17.86],[2,1.45,5.16]],"ltp":2.08,"tv":53.16,"id":67083366}]}]}
{"op":"mcm","clk":"11927879776","pt":1724244774611,"mc":[{"id":"1.232048948","rc":[{"batb":[[0,1.48,18.8],[1,1.45,5.16],[2,1.43,4.26]],"ltp":2.08,"tv":53.16,"id":67083366}]}]}
{"op":"mcm","clk":"11927880008","pt":1724244778185,"mc":[{"id":"1.232048948","rc":[{"batb":[[0,1.49,10.94],[1,1.48,17.86],[2,1.45,5.16]],"ltp":2.08,"tv":53.16,"id":67083366}]}]}
{"op":"mcm","clk":"11927880223","pt":1724244782129,"mc":[{"id":"1.232048948","rc":[{"batb":[[0,1.48,18.8],[1,1.45,5.16],[2,1.43,4.26]],"ltp":2.08,"tv":53.16,"id":67083366}]}]}
{"op":"mcm","clk":"11927880581","pt":1724244787840,"mc":[{"id":"1.232048948","rc":[{"batb":[[0,1.49,10.94],[1,1.48,17.86],[2,1.45,5.16]],"ltp":2.08,"tv":53.16,"id":67083366}]}]}
{"op":"mcm","clk":"11927881077","pt":1724244795821,"mc":[{"id":"1.232048948","rc":[{"batb":[[0,1.48,18.8],[1,1.45,5.16],[2,1.43,4.26]],"ltp":2.08,"tv":53.16,"id":67083366}]}]}
{"op":"mcm","clk":"11927881675","pt":1724244803729,"mc":[{"id":"1.232048948","rc":[{"batb":[[0,1.49,10.94],[1,1.48,17.86],[2,1.45,5.16]],"ltp":2.08,"tv":53.16,"id":67083366}]}]}
{"op":"mcm","clk":"11927881838","pt":1724244806147,"mc":[{"id":"1.232048948","rc":[{"batb":[[0,1.8,6.21],[1,1.49,10.94],[2,1.48,17.86]],"batl":[[0,3.3,3.91],[1,900,0.92]],"ltp":2.08,"tv":53.16,"id":67083366}]}]}
{"op":"mcm","clk":"11927882332","pt":1724244813262,"mc":[{"id":"1.232048948","rc":[{"batb":[[0,1.81,4],[1,1.8,6.21],[2,1.48,18.8]],"ltp":2.08,"tv":53.16,"id":67083366}]}]}
{"op":"mcm","clk":"11927882352","pt":1724244813468,"mc":[{"id":"1.232048948","rc":[{"batb":[[0,1.81,10.21],[1,1.48,18.8],[2,1.45,5.16]],"ltp":2.08,"tv":53.16,"id":67083366}]}]}
{"op":"mcm","clk":"11927882499","pt":1724244816152,"mc":[{"id":"1.232048948","rc":[{"batb":[[0,1.82,10],[1,1.81,10.21],[2,1.48,18.8]],"ltp":2.08,"tv":53.16,"id":67083366}]}]}
{"op":"mcm","clk":"11927882596","pt":1724244817278,"mc":[{"id":"1.232048948","rc":[{"batb":[[1,1.81,4]],"ltp":2.08,"tv":53.16,"id":67083366}]}]}
{"op":"mcm","clk":"11927882652","pt":1724244818163,"mc":[{"id":"1.232048948","rc":[{"batb":[[0,1.82,16.21],[1,1.48,18.8],[2,1.45,5.16]],"ltp":2.08,"tv":53.16,"id":67083366}]}]}
{"op":"mcm","clk":"11927882876","pt":1724244821162,"mc":[{"id":"1.232048948","rc":[{"batb":[[0,1.83,10.21],[1,1.82,10],[2,1.48,18.8]],"ltp":2.08,"tv":53.16,"id":67083366}]}]}
{"op":"mcm","clk":"11927882928","pt":1724244821993,"mc":[{"id":"1.232048948","rc":[{"batb":[[1,1.48,18.8],[2,1.45,5.16]],"ltp":2.08,"tv":53.16,"id":67083366}]}]}
{"op":"mcm","clk":"11927883023","pt":1724244823486,"mc":[{"id":"1.232048948","rc":[{"batb":[[0,1.83,6.21]],"ltp":2.08,"tv":53.16,"id":67083366}]}]}
{"op":"mcm","clk":"11927883132","pt":1724244824988,"mc":[{"id":"1.232048948","rc":[{"batb":[[0,1.84,16.21]],"ltp":2.08,"tv":53.16,"id":67083366}]}]}
{"op":"mcm","clk":"11927883338","pt":1724244827990,"mc":[{"id":"1.232048948","rc":[{"batb":[[2,1.66,9.48]],"ltp":1.92,"tv":10.21,"id":72857114},{"batb":[[0,1.85,4],[1,1.84,6.21],[2,1.48,18.8]],"ltp":2.08,"tv":53.16,"id":67083366}]}]}
{"op":"mcm","clk":"11927883387","pt":1724244828872,"mc":[{"id":"1.232048948","rc":[{"batb":[[0,1.85,10.21],[1,1.48,18.8],[2,1.45,5.16]],"ltp":2.08,"tv":53.16,"id":67083366}]}]}
{"op":"mcm","clk":"11927883457","pt":1724244830167,"mc":[{"id":"1.232048948","rc":[{"batb":[[0,1.86,10],[1,1.85,6.21],[2,1.48,18.8]],"ltp":2.08,"tv":53.16,"id":67083366}]}]}
{"op":"mcm","clk":"11927883580","pt":1724244832280,"mc":[{"id":"1.232048948","rc":[{"batb":[[0,1.87,4],[1,1.86,16.21]],"ltp":2.08,"tv":53.16,"id":67083366}]}]}
{"op":"mcm","clk":"11927883622","pt":1724244832898,"mc":[{"id":"1.232048948","rc":[{"batb":[[0,1.87,10.21],[1,1.86,10]],"ltp":2.08,"tv":53.16,"id":67083366}]}]}
{"op":"mcm","clk":"11927883676","pt":1724244833571,"mc":[{"id":"1.232048948","rc":[{"batb":[[1,1.48,18.8],[2,1.45,5.16]],"ltp":2.08,"tv":53.16,"id":67083366}]}]}
{"op":"mcm","clk":"11927883773","pt":1724244834775,"mc":[{"id":"1.232048948","rc":[{"batb":[[0,1.87,6.21]],"ltp":2.08,"tv":53.16,"id":67083366}]}]}
{"op":"mcm","clk":"11927884134","pt":1724244840616,"mc":[{"id":"1.232048948","rc":[{"batb":[[0,1.88,14],[1,1.87,6.21],[2,1.48,18.8]],"ltp":2.08,"tv":53.16,"id":67083366}]}]}
{"op":"mcm","clk":"11927884187","pt":1724244841601,"mc":[{"id":"1.232048948","rc":[{"batb":[[0,1.88,20.21],[1,1.48,18.8],[2,1.45,5.16]],"ltp":2.08,"tv":53.16,"id":67083366}]}]}
{"op":"mcm","clk":"11927884277","pt":1724244842896,"mc":[{"id":"1.232048948","rc":[{"batb":[[0,1.88,16.21]],"ltp":2.08,"tv":53.16,"id":67083366}]}]}
{"op":"mcm","clk":"11927884339","pt":1724244843891,"mc":[{"id":"1.232048948","rc":[{"batb":[[0,1.88,6.21]],"ltp":2.08,"tv":53.16,"id":67083366}]}]}
{"op":"mcm","clk":"11927884493","pt":1724244846198,"mc":[{"id":"1.232048948","rc":[{"batb":[[0,1.9,10],[1,1.89,4],[2,1.88,6.21]],"ltp":2.08,"tv":53.16,"id":67083366}]}]}
{"op":"mcm","clk":"11927884530","pt":1724244846612,"mc":[{"id":"1.232048948","rc":[{"batb":[[0,1.9,16.21],[2,1.48,18.8]],"ltp":2.08,"tv":53.16,"id":67083366}]}]}
{"op":"mcm","clk":"11927884661","pt":1724244848515,"mc":[{"id":"1.232048948","rc":[{"batb":[[1,1.48,18.8],[2,1.45,5.16]],"ltp":2.08,"tv":53.16,"id":67083366}]}]}
{"op":"mcm","clk":"11927884774","pt":1724244849906,"mc":[{"id":"1.232048948","rc":[{"batb":[[0,1.9,6.21]],"ltp":2.08,"tv":53.16,"id":67083366}]}]}
{"op":"mcm","clk":"11927884885","pt":1724244851503,"mc":[{"id":"1.232048948","rc":[{"batb":[[0,1.91,4],[1,1.9,6.21],[2,1.48,18.8]],"ltp":2.08,"tv":53.16,"id":67083366}]}]}
{"op":"mcm","clk":"11927885014","pt":1724244853107,"mc":[{"id":"1.232048948","rc":[{"batb":[[0,1.92,10],[1,1.91,10.21]],"ltp":2.08,"tv":53.16,"id":67083366}]}]}
{"op":"mcm","clk":"11927885089","pt":1724244854193,"mc":[{"id":"1.232048948","rc":[{"batb":[[0,1.92,16.21],[1,1.48,18.8],[2,1.45,5.16]],"ltp":2.08,"tv":53.16,"id":67083366}]}]}
{"op":"mcm","clk":"11927885246","pt":1724244856617,"mc":[{"id":"1.232048948","rc":[{"batb":[[0,1.93,4],[1,1.92,6.21],[2,1.48,18.8]],"ltp":2.08,"tv":53.16,"id":67083366}]}]}
{"op":"mcm","clk":"11927885345","pt":1724244858095,"mc":[{"id":"1.232048948","rc":[{"batb":[[0,1.93,10.21],[1,1.48,18.8],[2,1.45,5.16]],"ltp":2.08,"tv":53.16,"id":67083366}]}]}
{"op":"mcm","clk":"11927885423","pt":1724244859325,"mc":[{"id":"1.232048948","rc":[{"batb":[[0,1.93,6.21]],"ltp":2.08,"tv":53.16,"id":67083366}]}]}
{"op":"mcm","clk":"11927885443","pt":1724244859633,"mc":[{"id":"1.232048948","rc":[{"batb":[[0,1.94,10],[1,1.93,6.21],[2,1.48,18.8]],"ltp":2.08,"tv":53.16,"id":67083366}]}]}
{"op":"mcm","clk":"11927885521","pt":1724244860714,"mc":[{"id":"1.232048948","rc":[{"batb":[[0,1.94,16.21],[1,1.48,18.8],[2,1.45,5.16]],"ltp":2.08,"tv":53.16,"id":67083366}]}]}
{"op":"mcm","clk":"11927885712","pt":1724244863306,"mc":[{"id":"1.232048948","rc":[{"batb":[[0,1.95,4],[1,1.94,6.21],[2,1.48,18.8]],"ltp":2.08,"tv":53.16,"id":67083366}]}]}
{"op":"mcm","clk":"11927885791","pt":1724244864502,"mc":[{"id":"1.232048948","rc":[{"batb":[[0,1.95,10.21],[1,1.48,18.8],[2,1.45,5.16]],"ltp":2.08,"tv":53.16,"id":67083366}]}]}
{"op":"mcm","clk":"11927885886","pt":1724244865728,"mc":[{"id":"1.232048948","rc":[{"batb":[[0,1.96,10],[1,1.95,6.21],[2,1.48,18.8]],"ltp":2.08,"tv":53.16,"id":67083366}]}]}
{"op":"mcm","clk":"11927886003","pt":1724244867122,"mc":[{"id":"1.232048948","rc":[{"batb":[[0,1.96,16.21],[1,1.48,18.8],[2,1.45,5.16]],"ltp":2.08,"tv":53.16,"id":67083366}]}]}
{"op":"mcm","clk":"11927886142","pt":1724244869238,"mc":[{"id":"1.232048948","rc":[{"batb":[[0,1.97,4],[1,1.96,6.21],[2,1.48,18.8]],"ltp":2.08,"tv":53.16,"id":67083366}]}]}
{"op":"mcm","clk":"11927886352","pt":1724244872233,"mc":[{"id":"1.232048948","rc":[{"batb":[[0,1.97,10]],"ltp":2.08,"tv":53.16,"id":67083366}]}]}
{"op":"mcm","clk":"11927886534","pt":1724244874415,"mc":[{"id":"1.232048948","rc":[{"batb":[[0,1.98,4],[1,1.97,10],[2,1.96,6.21]],"ltp":2.08,"tv":53.16,"id":67083366}]}]}
{"op":"mcm","clk":"11927886654","pt":1724244875921,"mc":[{"id":"1.232048948","rc":[{"batb":[[1,1.96,6.21],[2,1.48,18.8]],"ltp":2.08,"tv":53.16,"id":67083366}]}]}
{"op":"mcm","clk":"11927886759","pt":1724244877332,"mc":[{"id":"1.232048948","rc":[{"batb":[[0,1.96,6.21],[1,1.48,18.8],[2,1.45,5.16]],"ltp":2.08,"tv":53.16,"id":67083366}]}]}
{"op":"mcm","clk":"11927886951","pt":1724244880336,"mc":[{"id":"1.232048948","rc":[{"batb":[[0,1.97,14],[1,1.96,6.21],[2,1.48,18.8]],"ltp":2.08,"tv":53.16,"id":67083366}]}]}
{"op":"mcm","clk":"11927887150","pt":1724244883126,"mc":[{"id":"1.232048948","rc":[{"batb":[[0,1.97,10]],"ltp":2.08,"tv":53.16,"id":67083366}]}]}
{"op":"mcm","clk":"11927887227","pt":1724244884056,"mc":[{"id":"1.232048948","rc":[{"batb":[[0,1.96,6.21],[1,1.48,18.8],[2,1.45,5.16]],"ltp":2.08,"tv":53.16,"id":67083366}]}]}
{"op":"mcm","clk":"11927887352","pt":1724244885863,"mc":[{"id":"1.232048948","rc":[{"batb":[[0,1.97,4],[1,1.96,6.21],[2,1.48,18.8]],"ltp":2.08,"tv":53.16,"id":67083366}]}]}
{"op":"mcm","clk":"11927887514","pt":1724244888242,"mc":[{"id":"1.232048948","rc":[{"batb":[[0,1.96,6.21],[1,1.48,18.8],[2,1.45,5.16]],"ltp":2.08,"tv":53.16,"id":67083366}]}]}
{"op":"mcm","clk":"11927887528","pt":1724244888448,"mc":[{"id":"1.232048948","rc":[{"batb":[[0,1.97,10],[1,1.96,6.21],[2,1.48,18.8]],"ltp":2.08,"tv":53.16,"id":67083366}]}]}
{"op":"mcm","clk":"11927887686","pt":1724244890937,"mc":[{"id":"1.232048948","rc":[{"batb":[[0,1.98,4],[1,1.97,10],[2,1.96,6.21]],"ltp":2.08,"tv":53.16,"id":67083366}]}]}
{"op":"mcm","clk":"11927887757","pt":1724244892072,"mc":[{"id":"1.232048948","rc":[{"batb":[[1,1.96,6.21],[2,1.48,18.8]],"ltp":2.08,"tv":53.16,"id":67083366}]}]}
{"op":"mcm","clk":"11927887833","pt":1724244893462,"mc":[{"id":"1.232048948","rc":[{"batb":[[0,1.96,6.21],[1,1.48,18.8],[2,1.45,5.16]],"ltp":2.08,"tv":53.16,"id":67083366}]}]}
{"op":"mcm","clk":"11927887958","pt":1724244895272,"mc":[{"id":"1.232048948","rc":[{"batb":[[0,1.97,10],[1,1.96,6.21],[2,1.48,18.8]],"ltp":2.08,"tv":53.16,"id":67083366}]}]}
{"op":"mcm","clk":"11927887987","pt":1724244895744,"mc":[{"id":"1.232048948","rc":[{"batb":[[0,1.98,4],[1,1.97,10],[2,1.96,6.21]],"ltp":2.08,"tv":53.16,"id":67083366}]}]}
{"op":"mcm","clk":"11927888056","pt":1724244896465,"mc":[{"id":"1.232048948","rc":[{"batb":[[2,1.64,9.58]],"ltp":1.92,"tv":10.21,"id":72857114}]}]}
{"op":"mcm","clk":"11927888200","pt":1724244898165,"mc":[{"id":"1.232048948","rc":[{"batb":[[0,1.97,10],[1,1.96,6.21],[2,1.48,18.8]],"ltp":2.08,"tv":53.16,"id":67083366}]}]}
{"op":"mcm","clk":"11927888241","pt":1724244898573,"mc":[{"id":"1.232048948","rc":[{"batb":[[0,1.96,6.21],[1,1.48,18.8],[2,1.45,5.16]],"ltp":2.08,"tv":53.16,"id":67083366}]}]}
{"op":"mcm","clk":"11927888538","pt":1724244902462,"mc":[{"id":"1.232048948","rc":[{"batb":[[0,1.97,14],[1,1.96,6.21],[2,1.48,18.8]],"ltp":2.08,"tv":53.16,"id":67083366}]}]}
{"op":"mcm","clk":"11927888738","pt":1724244904962,"mc":[{"id":"1.232048948","rc":[{"batb":[[0,1.97,10]],"ltp":2.08,"tv":53.16,"id":67083366}]}]}
{"op":"mcm","clk":"11927888835","pt":1724244906057,"mc":[{"id":"1.232048948","rc":[{"batb":[[0,1.96,6.21],[1,1.48,18.8],[2,1.45,5.16]],"ltp":2.08,"tv":53.16,"id":67083366}]}]}
{"op":"mcm","clk":"11927888992","pt":1724244908379,"mc":[{"id":"1.232048948","rc":[{"batb":[[0,1.97,14],[1,1.96,6.21],[2,1.48,18.8]],"ltp":2.08,"tv":53.16,"id":67083366}]}]}
{"op":"mcm","clk":"11927889185","pt":1724244911489,"mc":[{"id":"1.232048948","rc":[{"batb":[[0,1.97,10]],"ltp":2.08,"tv":53.16,"id":67083366}]}]}
{"op":"mcm","clk":"11927889247","pt":1724244912475,"mc":[{"id":"1.232048948","rc":[{"batb":[[0,1.96,6.21],[1,1.48,18.8],[2,1.45,5.16]],"ltp":2.08,"tv":53.16,"id":67083366}]}]}
{"op":"mcm","clk":"11927889440","pt":1724244914982,"mc":[{"id":"1.232048948","rc":[{"batb":[[0,1.97,14],[1,1.96,6.21],[2,1.48,18.8]],"ltp":2.08,"tv":53.16,"id":67083366}]}]}
{"op":"mcm","clk":"11927889667","pt":1724244917893,"mc":[{"id":"1.232048948","rc":[{"batb":[[0,1.97,10]],"ltp":2.08,"tv":53.16,"id":67083366}]}]}
{"op":"mcm","clk":"11927889739","pt":1724244918979,"mc":[{"id":"1.232048948","rc":[{"batb":[[0,1.96,6.21],[1,1.48,18.8],[2,1.45,5.16]],"ltp":2.08,"tv":53.16,"id":67083366}]}]}
{"op":"mcm","clk":"11927889863","pt":1724244920792,"mc":[{"id":"1.232048948","rc":[{"batb":[[0,1.97,4],[1,1.96,6.21],[2,1.48,18.8]],"ltp":2.08,"tv":53.16,"id":67083366}]}]}
{"op":"mcm","clk":"11927890125","pt":1724244924197,"mc":[{"id":"1.232048948","rc":[{"batb":[[0,1.97,10]],"ltp":2.08,"tv":53.16,"id":67083366}]}]}
{"op":"mcm","clk":"11927890260","pt":1724244925968,"mc":[{"id":"1.232048948","rc":[{"batb":[[0,1.98,4],[1,1.97,10],[2,1.96,6.21]],"ltp":2.08,"tv":53.16,"id":67083366}]}]}
{"op":"mcm","clk":"11927890364","pt":1724244927672,"mc":[{"id":"1.232048948","rc":[{"batb":[[1,1.96,6.21],[2,1.48,18.8]],"ltp":2.08,"tv":53.16,"id":67083366}]}]}
{"op":"mcm","clk":"11927890440","pt":1724244928900,"mc":[{"id":"1.232048948","rc":[{"batb":[[0,1.96,6.21],[1,1.48,18.8],[2,1.45,5.16]],"ltp":2.08,"tv":53.16,"id":67083366}]}]}
{"op":"mcm","clk":"11927890536","pt":1724244930404,"mc":[{"id":"1.232048948","rc":[{"batb":[[0,1.97,10],[1,1.96,6.21],[2,1.48,18.8]],"ltp":2.08,"tv":53.16,"id":67083366}]}]}
{"op":"mcm","clk":"11927890760","pt":1724244933296,"mc":[{"id":"1.232048948","rc":[{"batb":[[0,1.98,4],[1,1.97,10],[2,1.96,6.21]],"ltp":2.08,"tv":53.16,"id":67083366}]}]}
{"op":"mcm","clk":"11927890797","pt":1724244933901,"mc":[{"id":"1.232048948","rc":[{"batb":[[1,1.96,6.21],[2,1.48,18.8]],"ltp":2.08,"tv":53.16,"id":67083366}]}]}
{"op":"mcm","clk":"11927890954","pt":1724244936077,"mc":[{"id":"1.232048948","rc":[{"batb":[[0,1.96,6.21],[1,1.48,18.8],[2,1.45,5.16]],"ltp":2.08,"tv":53.16,"id":67083366}]}]}
{"op":"mcm","clk":"11927890998","pt":1724244936599,"mc":[{"id":"1.232048948","rc":[{"batb":[[0,1.97,10],[1,1.96,6.21],[2,1.48,18.8]],"ltp":2.08,"tv":53.16,"id":67083366}]}]}
{"op":"mcm","clk":"11927891314","pt":1724244940094,"mc":[{"id":"1.232048948","rc":[{"batb":[[0,1.96,6.21],[1,1.48,18.8],[2,1.45,5.16]],"ltp":2.08,"tv":53.16,"id":67083366}]}]}
{"op":"mcm","clk":"11927891345","pt":1724244940505,"mc":[{"id":"1.232048948","rc":[{"batb":[[0,1.97,4],[1,1.96,6.21],[2,1.48,18.8]],"ltp":2.08,"tv":53.16,"id":67083366}]}]}
{"op":"mcm","clk":"11927891565","pt":1724244943287,"mc":[{"id":"1.232048948","rc":[{"batb":[[0,1.97,10]],"ltp":2.08,"tv":53.16,"id":67083366}]}]}
{"op":"mcm","clk":"11927891829","pt":1724244946825,"mc":[{"id":"1.232048948","rc":[{"batb":[[0,1.97,4]],"ltp":2.08,"tv":53.16,"id":67083366}]}]}
{"op":"mcm","clk":"11927892001","pt":1724244949316,"mc":[{"id":"1.232048948","rc":[{"batb":[[0,1.97,10]],"ltp":2.08,"tv":53.16,"id":67083366}]}]}
{"op":"mcm","clk":"11927892222","pt":1724244952112,"mc":[{"id":"1.232048948","rc":[{"batb":[[0,1.98,4],[1,1.97,10],[2,1.96,6.21]],"ltp":2.08,"tv":53.16,"id":67083366}]}]}
{"op":"mcm","clk":"11927892263","pt":1724244952624,"mc":[{"id":"1.232048948","rc":[{"batb":[[1,1.96,6.21],[2,1.48,18.8]],"ltp":2.08,"tv":53.16,"id":67083366}]}]}
{"op":"mcm","clk":"11927892449","pt":1724244954997,"mc":[{"id":"1.232048948","rc":[{"batb":[[0,1.97,10]],"ltp":2.08,"tv":53.16,"id":67083366}]}]}
{"op":"mcm","clk":"11927892596","pt":1724244957111,"mc":[{"id":"1.232048948","rc":[{"batb":[[0,1.98,4],[1,1.97,10],[2,1.96,6.21]],"ltp":2.08,"tv":53.16,"id":67083366}]}]}
{"op":"mcm","clk":"11927892672","pt":1724244958333,"mc":[{"id":"1.232048948","rc":[{"batb":[[1,1.96,6.21],[2,1.48,18.8]],"ltp":2.08,"tv":53.16,"id":67083366}]}]}
{"op":"mcm","clk":"11927892772","pt":1724244959632,"mc":[{"id":"1.232048948","rc":[{"batb":[[0,1.96,6.21],[1,1.48,18.8],[2,1.45,5.16]],"ltp":2.08,"tv":53.16,"id":67083366}]}]}
{"op":"mcm","clk":"11927892980","pt":1724244962220,"mc":[{"id":"1.232048948","rc":[{"batb":[[0,1.98,4],[1,1.97,10],[2,1.96,6.21]],"ltp":2.08,"tv":53.16,"id":67083366}]}]}
{"op":"mcm","clk":"11927893205","pt":1724244965319,"mc":[{"id":"1.232048948","rc":[{"batb":[[0,1.96,6.21],[1,1.48,18.8],[2,1.45,5.16]],"ltp":2.08,"tv":53.16,"id":67083366}]}]}
{"op":"mcm","clk":"11927893419","pt":1724244968112,"mc":[{"id":"1.232048948","rc":[{"batb":[[0,1.97,14],[1,1.96,6.21],[2,1.48,18.8]],"ltp":2.08,"tv":53.16,"id":67083366}]}]}
{"op":"mcm","clk":"11927893602","pt":1724244970837,"mc":[{"id":"1.232048948","rc":[{"batb":[[0,1.97,10]],"ltp":2.08,"tv":53.16,"id":67083366}]}]}
{"op":"mcm","clk":"11927893672","pt":1724244971723,"mc":[{"id":"1.232048948","rc":[{"batb":[[0,1.96,6.21],[1,1.48,18.8],[2,1.45,5.16]],"ltp":2.08,"tv":53.16,"id":67083366}]}]}
{"op":"mcm","clk":"11927893772","pt":1724244973113,"mc":[{"id":"1.232048948","rc":[{"batb":[[0,1.97,4],[1,1.96,6.21],[2,1.48,18.8]],"ltp":2.08,"tv":53.16,"id":67083366}]}]}
{"op":"mcm","clk":"11927894000","pt":1724244975947,"mc":[{"id":"1.232048948","rc":[{"batb":[[0,1.96,6.21],[1,1.48,18.8],[2,1.45,5.16]],"ltp":2.08,"tv":53.16,"id":67083366}]}]}
{"op":"mcm","clk":"11927894048","pt":1724244976527,"mc":[{"id":"1.232048948","rc":[{"batb":[[0,1.97,10],[1,1.96,6.21],[2,1.48,18.8]],"ltp":2.08,"tv":53.16,"id":67083366}]}]}
{"op":"mcm","clk":"11927894256","pt":1724244979149,"mc":[{"id":"1.232048948","rc":[{"batb":[[0,1.98,4],[1,1.97,10],[2,1.96,6.21]],"ltp":2.08,"tv":53.16,"id":67083366}]}]}
{"op":"mcm","clk":"11927894356","pt":1724244980243,"mc":[{"id":"1.232048948","rc":[{"batb":[[1,1.96,6.21],[2,1.48,18.8]],"ltp":2.08,"tv":53.16,"id":67083366}]}]}
{"op":"mcm","clk":"11927894438","pt":1724244981427,"mc":[{"id":"1.232048948","rc":[{"batb":[[0,1.96,6.21],[1,1.48,18.8],[2,1.45,5.16]],"ltp":2.08,"tv":53.16,"id":67083366}]}]}
{"op":"mcm","clk":"11927894560","pt":1724244983048,"mc":[{"id":"1.232048948","rc":[{"batb":[[0,1.97,10],[1,1.96,6.21],[2,1.48,18.8]],"ltp":2.08,"tv":53.16,"id":67083366}]}]}
{"op":"mcm","clk":"11927894600","pt":1724244983637,"mc":[{"id":"1.232048948","rc":[{"batb":[[0,1.98,4],[1,1.97,10],[2,1.96,6.21]],"ltp":2.08,"tv":53.16,"id":67083366}]}]}
{"op":"mcm","clk":"11927894772","pt":1724244986259,"mc":[{"id":"1.232048948","rc":[{"batb":[[0,1.97,10],[1,1.96,6.21],[2,1.48,18.8]],"ltp":2.08,"tv":53.16,"id":67083366}]}]}
{"op":"mcm","clk":"11927894806","pt":1724244986641,"mc":[{"id":"1.232048948","rc":[{"batb":[[0,1.96,6.21],[1,1.48,18.8],[2,1.45,5.16]],"ltp":2.08,"tv":53.16,"id":67083366}]}]}
{"op":"mcm","clk":"11927895114","pt":1724244990657,"mc":[{"id":"1.232048948","rc":[{"batb":[[0,1.97,14],[1,1.96,6.21],[2,1.48,18.8]],"ltp":2.08,"tv":53.16,"id":67083366}]}]}
{"op":"mcm","clk":"11927895300","pt":1724244993169,"mc":[{"id":"1.232048948","rc":[{"batb":[[0,1.97,10]],"ltp":2.08,"tv":53.16,"id":67083366}]}]}
{"op":"mcm","clk":"11927895385","pt":1724244994154,"mc":[{"id":"1.232048948","rc":[{"batb":[[0,1.96,6.21],[1,1.48,18.8],[2,1.45,5.16]],"ltp":2.08,"tv":53.16,"id":67083366}]}]}
{"op":"mcm","clk":"11927895521","pt":1724244995964,"mc":[{"id":"1.232048948","rc":[{"batb":[[0,1.97,4],[1,1.96,6.21],[2,1.48,18.8]],"ltp":2.08,"tv":53.16,"id":67083366}]}]}
{"op":"mcm","clk":"11927895698","pt":1724244998244,"mc":[{"id":"1.232048948","rc":[{"batb":[[0,1.96,6.21],[1,1.48,18.8],[2,1.45,5.16]],"ltp":2.08,"tv":53.16,"id":67083366}]}]}
{"op":"mcm","clk":"11927895707","pt":1724244998353,"mc":[{"id":"1.232048948","rc":[{"batb":[[0,1.97,10],[1,1.96,6.21],[2,1.48,18.8]],"ltp":2.08,"tv":53.16,"id":67083366}]}]}
{"op":"mcm","clk":"11927895966","pt":1724245001662,"mc":[{"id":"1.232048948","rc":[{"batb":[[0,1.98,4]],"ltp":2.08,"tv":53.16,"id":67083366}]}]}
{"op":"mcm","clk":"11927896156","pt":1724245004183,"mc":[{"id":"1.232048948","rc":[{"batb":[[0,1.97,10]],"ltp":2.08,"tv":53.16,"id":67083366}]}]}
{"op":"mcm","clk":"11927896468","pt":1724245008057,"mc":[{"id":"1.232048948","rc":[{"batb":[[0,1.97,4]],"ltp":2.08,"tv":53.16,"id":67083366}]}]}
{"op":"mcm","clk":"11927896644","pt":1724245010686,"mc":[{"id":"1.232048948","rc":[{"batb":[[0,1.97,10]],"ltp":2.08,"tv":53.16,"id":67083366}]}]}
{"op":"mcm","clk":"11927896891","pt":1724245014295,"mc":[{"id":"1.232048948","rc":[{"batb":[[0,1.98,4]],"ltp":2.08,"tv":53.16,"id":67083366}]}]}
{"op":"mcm","clk":"11927897100","pt":1724245017092,"mc":[{"id":"1.232048948","rc":[{"batb":[[0,1.96,6.21],[1,1.48,18.8],[2,1.45,5.16]],"ltp":2.08,"tv":53.16,"id":67083366}]}]}
{"op":"mcm","clk":"11927897131","pt":1724245017598,"mc":[{"id":"1.232048948","rc":[{"batb":[[0,1.97,10],[1,1.96,6.21],[2,1.48,18.8]],"ltp":2.08,"tv":53.16,"id":67083366}]}]}
{"op":"mcm","clk":"11927897328","pt":1724245020082,"mc":[{"id":"1.232048948","rc":[{"batb":[[0,1.98,4],[1,1.97,10],[2,1.96,6.21]],"ltp":2.08,"tv":53.16,"id":67083366}]}]}
{"op":"mcm","clk":"11927897393","pt":1724245020968,"mc":[{"id":"1.232048948","rc":[{"batb":[[1,1.96,6.21],[2,1.48,18.8]],"ltp":2.08,"tv":53.16,"id":67083366}]}]}
{"op":"mcm","clk":"11927897531","pt":1724245022795,"mc":[{"id":"1.232048948","rc":[{"batb":[[0,1.96,6.21],[1,1.48,18.8],[2,1.45,5.16]],"ltp":2.08,"tv":53.16,"id":67083366}]}]}
{"op":"mcm","clk":"11927897644","pt":1724245024187,"mc":[{"id":"1.232048948","rc":[{"batb":[[0,1.97,10],[1,1.96,6.21],[2,1.48,18.8]],"ltp":2.08,"tv":53.16,"id":67083366}]}]}
{"op":"mcm","clk":"11927897938","pt":1724245027901,"mc":[{"id":"1.232048948","rc":[{"batb":[[0,1.97,4]],"ltp":2.08,"tv":53.16,"id":67083366}]}]}
{"op":"mcm","clk":"11927898255","pt":1724245030788,"mc":[{"id":"1.232048948","rc":[{"batb":[[0,1.97,10]],"ltp":2.08,"tv":53.16,"id":67083366}]}]}
{"op":"mcm","clk":"11927898579","pt":1724245034302,"mc":[{"id":"1.232048948","rc":[{"batb":[[0,1.97,4]],"ltp":2.08,"tv":53.16,"id":67083366}]}]}
{"op":"mcm","clk":"11927898809","pt":1724245037103,"mc":[{"id":"1.232048948","rc":[{"batb":[[0,1.98,10]],"ltp":2.08,"tv":53.16,"id":67083366}]}]}
{"op":"mcm","clk":"11927899103","pt":1724245041118,"mc":[{"id":"1.232048948","rc":[{"batb":[[0,1.99,4]],"ltp":2.08,"tv":53.16,"id":67083366}]}]}
{"op":"mcm","clk":"11927899358","pt":1724245044218,"mc":[{"id":"1.232048948","rc":[{"batb":[[0,1.97,10]],"ltp":2.08,"tv":53.16,"id":67083366}]}]}
{"op":"mcm","clk":"11927899628","pt":1724245047922,"mc":[{"id":"1.232048948","rc":[{"batb":[[0,1.97,4]],"ltp":2.08,"tv":53.16,"id":67083366}]}]}
{"op":"mcm","clk":"11927899788","pt":1724245050206,"mc":[{"id":"1.232048948","rc":[{"batb":[[0,1.96,6.21],[1,1.48,18.8],[2,1.45,5.16]],"ltp":2.08,"tv":53.16,"id":67083366}]}]}
{"op":"mcm","clk":"11927899800","pt":1724245050414,"mc":[{"id":"1.232048948","rc":[{"batb":[[0,1.97,10],[1,1.96,6.21],[2,1.48,18.8]],"ltp":2.08,"tv":53.16,"id":67083366}]}]}
{"op":"mcm","clk":"11927900067","pt":1724245054024,"mc":[{"id":"1.232048948","rc":[{"batb":[[0,1.97,4]],"ltp":2.08,"tv":53.16,"id":67083366}]}]}
{"op":"mcm","clk":"11927900246","pt":1724245056319,"mc":[{"id":"1.232048948","rc":[{"batb":[[0,1.96,6.21],[1,1.48,18.8],[2,1.45,5.16]],"ltp":2.08,"tv":53.16,"id":67083366}]}]}
{"op":"mcm","clk":"11927900271","pt":1724245056629,"mc":[{"id":"1.232048948","rc":[{"batb":[[0,1.97,10],[1,1.96,6.21],[2,1.48,18.8]],"ltp":2.08,"tv":53.16,"id":67083366}]}]}
{"op":"mcm","clk":"11927900475","pt":1724245059317,"mc":[{"id":"1.232048948","rc":[{"batb":[[0,1.98,4],[1,1.97,10],[2,1.96,6.21]],"ltp":2.08,"tv":53.16,"id":67083366}]}]}
{"op":"mcm","clk":"11927900544","pt":1724245060227,"mc":[{"id":"1.232048948","rc":[{"batb":[[1,1.96,6.21],[2,1.48,18.8]],"ltp":2.08,"tv":53.16,"id":67083366}]}]}
{"op":"mcm","clk":"11927900652","pt":1724245061614,"mc":[{"id":"1.232048948","rc":[{"batb":[[0,1.96,6.21],[1,1.48,18.8],[2,1.45,5.16]],"ltp":2.08,"tv":53.16,"id":67083366}]}]}
{"op":"mcm","clk":"11927900835","pt":1724245064034,"mc":[{"id":"1.232048948","rc":[{"batb":[[0,1.97,14],[1,1.96,6.21],[2,1.48,18.8]],"ltp":2.08,"tv":53.16,"id":67083366}]}]}
{"op":"mcm","clk":"11927901033","pt":1724245066920,"mc":[{"id":"1.232048948","rc":[{"batb":[[0,1.97,10]],"ltp":2.08,"tv":53.16,"id":67083366}]}]}
{"op":"mcm","clk":"11927901107","pt":1724245068036,"mc":[{"id":"1.232048948","rc":[{"batb":[[0,1.96,6.21],[1,1.48,18.8],[2,1.45,5.16]],"ltp":2.08,"tv":53.16,"id":67083366}]}]}
{"op":"mcm","clk":"11927901192","pt":1724245069231,"mc":[{"id":"1.232048948","rc":[{"batb":[[0,1.97,4],[1,1.96,6.21],[2,1.48,18.8]],"ltp":2.08,"tv":53.16,"id":67083366}]}]}
{"op":"mcm","clk":"11927901306","pt":1724245070632,"mc":[{"id":"1.232048948","rc":[{"batb":[[0,1.98,10],[1,1.97,4],[2,1.96,6.21]],"ltp":2.08,"tv":53.16,"id":67083366}]}]}
{"op":"mcm","clk":"11927901374","pt":1724245071546,"mc":[{"id":"1.232048948","rc":[{"batb":[[1,1.96,6.21],[2,1.48,18.8]],"ltp":2.08,"tv":53.16,"id":67083366}]}]}
{"op":"mcm","clk":"11927901569","pt":1724245074334,"mc":[{"id":"1.232048948","rc":[{"batb":[[0,1.96,6.21],[1,1.48,18.8],[2,1.45,5.16]],"ltp":2.08,"tv":53.16,"id":67083366}]}]}
{"op":"mcm","clk":"11927901593","pt":1724245074643,"mc":[{"id":"1.232048948","rc":[{"batb":[[0,1.97,4],[1,1.96,6.21],[2,1.48,18.8]],"ltp":2.08,"tv":53.16,"id":67083366}]}]}
{"op":"mcm","clk":"11927901759","pt":1724245076863,"mc":[{"id":"1.232048948","rc":[{"batb":[[0,1.98,10]],"ltp":2.08,"tv":53.16,"id":67083366}]}]}
{"op":"mcm","clk":"11927901985","pt":1724245079949,"mc":[{"id":"1.232048948","rc":[{"batb":[[0,1.97,4]],"ltp":2.08,"tv":53.16,"id":67083366}]}]}
{"op":"mcm","clk":"11927902195","pt":1724245082560,"mc":[{"id":"1.232048948","rc":[{"batb":[[0,1.97,10]],"ltp":2.08,"tv":53.16,"id":67083366}]}]}
{"op":"mcm","clk":"11927902509","pt":1724245086080,"mc":[{"id":"1.232048948","rc":[{"batb":[[0,1.97,4]],"ltp":2.08,"tv":53.16,"id":67083366}]}]}
{"op":"mcm","clk":"11927902724","pt":1724245088866,"mc":[{"id":"1.232048948","rc":[{"batb":[[0,1.97,10]],"ltp":2.08,"tv":53.16,"id":67083366}]}]}
{"op":"mcm","clk":"11927902938","pt":1724245091151,"mc":[{"id":"1.232048948","rc":[{"batb":[[0,1.98,4],[1,1.97,10],[2,1.96,6.21]],"ltp":2.08,"tv":53.16,"id":67083366}]}]}
{"op":"mcm","clk":"11927903038","pt":1724245092181,"mc":[{"id":"1.232048948","rc":[{"batb":[[1,1.96,6.21],[2,1.48,18.8]],"ltp":2.08,"tv":53.16,"id":67083366}]}]}
{"op":"mcm","clk":"11927903166","pt":1724245093781,"mc":[{"id":"1.232048948","rc":[{"batb":[[0,1.96,6.21],[1,1.48,18.8],[2,1.45,5.16]],"ltp":2.08,"tv":53.16,"id":67083366}]}]}
{"op":"mcm","clk":"11927904954","pt":1724245116076,"mc":[{"id":"1.232048948","rc":[{"batb":[[0,1.97,14],[1,1.96,6.21],[2,1.48,18.8]],"ltp":2.08,"tv":53.16,"id":67083366}]}]}
{"op":"mcm","clk":"11927905139","pt":1724245118498,"mc":[{"id":"1.232048948","rc":[{"batb":[[0,1.97,10]],"ltp":2.08,"tv":53.16,"id":67083366}]}]}
{"op":"mcm","clk":"11927905226","pt":1724245119575,"mc":[{"id":"1.232048948","rc":[{"batb":[[0,1.96,6.21],[1,1.48,18.8],[2,1.45,5.16]],"ltp":2.08,"tv":53.16,"id":67083366}]}]}
{"op":"mcm","clk":"11927905701","pt":1724245125506,"mc":[{"id":"1.232048948","rc":[{"batb":[[0,1.97,14],[1,1.96,6.21],[2,1.48,18.8]],"ltp":2.08,"tv":53.16,"id":67083366}]}]}
{"op":"mcm","clk":"11927905933","pt":1724245128376,"mc":[{"id":"1.232048948","rc":[{"batb":[[0,1.97,10]],"ltp":2.08,"tv":53.16,"id":67083366}]}]}
{"op":"mcm","clk":"11927906020","pt":1724245129509,"mc":[{"id":"1.232048948","rc":[{"batb":[[0,1.96,6.21],[1,1.48,18.8],[2,1.45,5.16]],"ltp":2.08,"tv":53.16,"id":67083366}]}]}
{"op":"mcm","clk":"11927906194","pt":1724245131702,"mc":[{"id":"1.232048948","rc":[{"batb":[[0,1.97,14],[1,1.96,6.21],[2,1.48,18.8]],"ltp":2.08,"tv":53.16,"id":67083366}]}]}
{"op":"mcm","clk":"11927906391","pt":1724245134302,"mc":[{"id":"1.232048948","rc":[{"batb":[[0,1.97,10]],"ltp":2.08,"tv":53.16,"id":67083366}]}]}
{"op":"mcm","clk":"11927906460","pt":1724245135329,"mc":[{"id":"1.232048948","rc":[{"batb":[[0,1.96,6.21],[1,1.48,18.8],[2,1.45,5.16]],"ltp":2.08,"tv":53.16,"id":67083366}]}]}
{"op":"mcm","clk":"11927907732","pt":1724245151339,"mc":[{"id":"1.232048948","rc":[{"batb":[[0,1.97,14],[1,1.96,6.21],[2,1.48,18.8]],"ltp":2.08,"tv":53.16,"id":67083366}]}]}
{"op":"mcm","clk":"11927907915","pt":1724245154017,"mc":[{"id":"1.232048948","rc":[{"batb":[[0,1.97,10]],"ltp":2.08,"tv":53.16,"id":67083366}]}]}
{"op":"mcm","clk":"11927907983","pt":1724245155038,"mc":[{"id":"1.232048948","rc":[{"batb":[[0,1.96,6.21],[1,1.48,18.8],[2,1.45,5.16]],"ltp":2.08,"tv":53.16,"id":67083366}]}]}
{"op":"mcm","clk":"11927908195","pt":1724245158015,"mc":[{"id":"1.232048948","rc":[{"batb":[[0,1.97,14],[1,1.96,6.21],[2,1.48,18.8]],"ltp":2.08,"tv":53.16,"id":67083366}]}]}
{"op":"mcm","clk":"11927908467","pt":1724245161312,"mc":[{"id":"1.232048948","rc":[{"batb":[[0,1.96,6.21],[1,1.48,18.8],[2,1.45,5.16]],"ltp":2.08,"tv":53.16,"id":67083366}]}]}
{"op":"mcm","clk":"11927911096","pt":1724245200264,"mc":[{"id":"1.232048948","rc":[{"batb":[[0,1.97,14],[1,1.96,6.21],[2,1.48,18.8]],"ltp":2.08,"tv":53.16,"id":67083366}]}]}
{"op":"mcm","clk":"11927911378","pt":1724245202767,"mc":[{"id":"1.232048948","rc":[{"batb":[[0,1.97,10]],"ltp":2.08,"tv":53.16,"id":67083366}]}]}
{"op":"mcm","clk":"11927911481","pt":1724245203960,"mc":[{"id":"1.232048948","rc":[{"trd":[[1.44,1.7],[1.69,1.96],[2.7,1],[3,2.3]],"batb":[[2,1.64,9.58]],"ltp":1.92,"tv":10.2,"id":72857114},{"trd":[[1.06,3.07],[1.08,2.24],[1.1,2.24],[1.2,2.14],[1.5,4.6],[1.65,2.3],[1.98,5.96],[2,5.23],[2.12,2.18],[2.16,12.04],[2.18,1.29],[2.3,1.87]],"batb":[[0,1.96,6.2],[1,1.48,18.79],[2,1.45,5.15]],"batl":[[0,3.3,3.91]],"ltp":2.08,"tv":53.13,"id":67083366}],"tv":63.34}]}
{"op":"mcm","clk":"11927911635","pt":1724245205669,"mc":[{"id":"1.232048948","rc":[{"batb":[[0,1.97,4],[1,1.96,6.2],[2,1.48,18.79]],"ltp":2.08,"tv":53.13,"id":67083366}]}]}
{"op":"mcm","clk":"11927911738","pt":1724245207272,"mc":[{"id":"1.232048948","rc":[{"batb":[[0,1.98,10],[1,1.97,4],[2,1.96,6.2]],"ltp":2.08,"tv":53.13,"id":67083366}]}]}
{"op":"mcm","clk":"11927911847","pt":1724245208564,"mc":[{"id":"1.232048948","rc":[{"batb":[[1,1.96,6.2],[2,1.48,18.79]],"ltp":2.08,"tv":53.13,"id":67083366}]}]}
{"op":"mcm","clk":"11927911969","pt":1724245210065,"mc":[{"id":"1.232048948","rc":[{"batb":[[0,1.96,6.2],[1,1.48,18.79],[2,1.45,5.15]],"ltp":2.08,"tv":53.13,"id":67083366}]}]}
{"op":"mcm","clk":"11927912080","pt":1724245211665,"mc":[{"id":"1.232048948","rc":[{"batb":[[0,1.97,4],[1,1.96,6.2],[2,1.48,18.79]],"ltp":2.08,"tv":53.13,"id":67083366}]}]}
{"op":"mcm","clk":"11927912264","pt":1724245214300,"mc":[{"id":"1.232048948","rc":[{"batb":[[0,1.97,10]],"ltp":2.08,"tv":53.13,"id":67083366}]}]}
{"op":"mcm","clk":"11927912539","pt":1724245218209,"mc":[{"id":"1.232048948","rc":[{"batb":[[0,1.97,4]],"ltp":2.08,"tv":53.13,"id":67083366}]}]}
{"op":"mcm","clk":"11927912678","pt":1724245220118,"mc":[{"id":"1.232048948","rc":[{"batb":[[0,1.97,10]],"ltp":2.08,"tv":53.13,"id":67083366}]}]}
{"op":"mcm","clk":"11927912939","pt":1724245223481,"mc":[{"id":"1.232048948","rc":[{"batb":[[0,1.97,4]],"ltp":2.08,"tv":53.13,"id":67083366}]}]}
{"op":"mcm","clk":"11927913130","pt":1724245226223,"mc":[{"id":"1.232048948","rc":[{"batb":[[0,1.97,10]],"ltp":2.08,"tv":53.13,"id":67083366}]}]}
{"op":"mcm","clk":"11927913440","pt":1724245229812,"mc":[{"id":"1.232048948","rc":[{"batb":[[0,1.98,4]],"ltp":2.08,"tv":53.13,"id":67083366}]}]}
{"op":"mcm","clk":"11927913675","pt":1724245232698,"mc":[{"id":"1.232048948","rc":[{"batb":[[0,1.99,10]],"ltp":2.08,"tv":53.13,"id":67083366}]}]}
{"op":"mcm","clk":"11927913955","pt":1724245236308,"mc":[{"id":"1.232048948","rc":[{"batb":[[0,1.96,6.2],[1,1.48,18.79],[2,1.45,5.15]],"ltp":2.08,"tv":53.13,"id":67083366}]}]}
{"op":"mcm","clk":"11927913964","pt":1724245236412,"mc":[{"id":"1.232048948","rc":[{"batb":[[0,1.97,4],[1,1.96,6.2],[2,1.48,18.79]],"ltp":2.08,"tv":53.13,"id":67083366}]}]}
{"op":"mcm","clk":"11927914144","pt":1724245238830,"mc":[{"id":"1.232048948","rc":[{"batb":[[0,1.97,10]],"ltp":2.08,"tv":53.13,"id":67083366}]}]}
{"op":"mcm","clk":"11927914404","pt":1724245242333,"mc":[{"id":"1.232048948","rc":[{"batb":[[0,1.97,4]],"ltp":2.08,"tv":53.13,"id":67083366}]}]}
{"op":"mcm","clk":"11927914649","pt":1724245245013,"mc":[{"id":"1.232048948","rc":[{"batb":[[0,1.97,10]],"ltp":2.08,"tv":53.13,"id":67083366}]}]}
{"op":"mcm","clk":"11927914941","pt":1724245248316,"mc":[{"id":"1.232048948","rc":[{"batb":[[0,1.96,6.2],[1,1.48,18.79],[2,1.45,5.15]],"ltp":2.08,"tv":53.13,"id":67083366}]}]}
{"op":"mcm","clk":"11927914953","pt":1724245248520,"mc":[{"id":"1.232048948","rc":[{"batb":[[0,1.97,4],[1,1.96,6.2],[2,1.48,18.79]],"ltp":2.08,"tv":53.13,"id":67083366}]}]}
{"op":"mcm","clk":"11927915154","pt":1724245251143,"mc":[{"id":"1.232048948","rc":[{"batb":[[0,1.97,10]],"ltp":2.08,"tv":53.13,"id":67083366}]}]}
{"op":"mcm","clk":"11927915429","pt":1724245254858,"mc":[{"id":"1.232048948","rc":[{"batb":[[0,1.97,4]],"ltp":2.08,"tv":53.13,"id":67083366}]}]}
{"op":"mcm","clk":"11927915604","pt":1724245257441,"mc":[{"id":"1.232048948","rc":[{"batb":[[0,1.97,10]],"ltp":2.08,"tv":53.13,"id":67083366}]}]}
{"op":"mcm","clk":"11927915852","pt":1724245261155,"mc":[{"id":"1.232048948","rc":[{"batb":[[0,1.97,4]],"ltp":2.08,"tv":53.13,"id":67083366}]}]}
{"op":"mcm","clk":"11927916038","pt":1724245263638,"mc":[{"id":"1.232048948","rc":[{"batb":[[0,1.97,10]],"ltp":2.08,"tv":53.13,"id":67083366}]}]}
{"op":"mcm","clk":"11927916298","pt":1724245267035,"mc":[{"id":"1.232048948","rc":[{"batb":[[0,1.97,4]],"ltp":2.08,"tv":53.13,"id":67083366}]}]}
{"op":"mcm","clk":"11927916486","pt":1724245269660,"mc":[{"id":"1.232048948","rc":[{"batb":[[0,1.97,10]],"ltp":2.08,"tv":53.13,"id":67083366}]}]}
{"op":"mcm","clk":"11927916672","pt":1724245271933,"mc":[{"id":"1.232048948","rc":[{"batb":[[0,1.98,4],[1,1.97,10],[2,1.96,6.2]],"ltp":2.08,"tv":53.13,"id":67083366}]}]}
{"op":"mcm","clk":"11927916742","pt":1724245273070,"mc":[{"id":"1.232048948","rc":[{"batb":[[1,1.96,6.2],[2,1.48,18.79]],"ltp":2.08,"tv":53.13,"id":67083366}]}]}
{"op":"mcm","clk":"11927916810","pt":1724245274342,"mc":[{"id":"1.232048948","rc":[{"batb":[[0,1.96,6.2],[1,1.48,18.79],[2,1.45,5.15]],"ltp":2.08,"tv":53.13,"id":67083366}]}]}
{"op":"mcm","clk":"11927917083","pt":1724245279265,"mc":[{"id":"1.232048948","rc":[{"batb":[[0,1.97,14],[1,1.96,6.2],[2,1.48,18.79]],"ltp":2.08,"tv":53.13,"id":67083366}]}]}
{"op":"mcm","clk":"11927917257","pt":1724245282077,"mc":[{"id":"1.232048948","rc":[{"batb":[[0,1.97,10]],"ltp":2.08,"tv":53.13,"id":67083366}]}]}
{"op":"mcm","clk":"11927917320","pt":1724245282953,"mc":[{"id":"1.232048948","rc":[{"batb":[[0,1.96,6.2],[1,1.48,18.79],[2,1.45,5.15]],"ltp":2.08,"tv":53.13,"id":67083366}]}]}
{"op":"mcm","clk":"11927917437","pt":1724245284962,"mc":[{"id":"1.232048948","rc":[{"batb":[[0,1.97,4],[1,1.96,6.2],[2,1.48,18.79]],"ltp":2.08,"tv":53.13,"id":67083366}]}]}
{"op":"mcm","clk":"11927917470","pt":1724245285375,"mc":[{"id":"1.232048948","rc":[{"batb":[[0,1.98,10],[1,1.97,4],[2,1.96,6.2]],"ltp":2.08,"tv":53.13,"id":67083366}]}]}
{"op":"mcm","clk":"11927917620","pt":1724245287743,"mc":[{"id":"1.232048948","rc":[{"batb":[[1,1.96,6.2],[2,1.48,18.79]],"ltp":2.08,"tv":53.13,"id":67083366}]}]}
{"op":"mcm","clk":"11927917723","pt":1724245289182,"mc":[{"id":"1.232048948","rc":[{"batb":[[0,1.96,6.2],[1,1.48,18.79],[2,1.45,5.15]],"ltp":2.08,"tv":53.13,"id":67083366}]}]}
{"op":"mcm","clk":"11927917926","pt":1724245292079,"mc":[{"id":"1.232048948","rc":[{"batb":[[0,1.97,14],[1,1.96,6.2],[2,1.48,18.79]],"ltp":2.08,"tv":53.13,"id":67083366}]}]}
{"op":"mcm","clk":"11927918157","pt":1724245294756,"mc":[{"id":"1.232048948","rc":[{"batb":[[0,1.97,10]],"ltp":2.08,"tv":53.13,"id":67083366}]}]}
{"op":"mcm","clk":"11927918233","pt":1724245295692,"mc":[{"id":"1.232048948","rc":[{"batb":[[0,1.96,6.2],[1,1.48,18.79],[2,1.45,5.15]],"ltp":2.08,"tv":53.13,"id":67083366}]}]}
{"op":"mcm","clk":"11927918582","pt":1724245301156,"mc":[{"id":"1.232048948","rc":[{"batb":[[0,1.97,14],[1,1.96,6.2],[2,1.48,18.79]],"ltp":2.08,"tv":53.13,"id":67083366}]}]}
{"op":"mcm","clk":"11927918773","pt":1724245303992,"mc":[{"id":"1.232048948","rc":[{"batb":[[0,1.97,10]],"ltp":2.08,"tv":53.13,"id":67083366}]}]}
{"op":"mcm","clk":"11927918858","pt":1724245305081,"mc":[{"id":"1.232048948","rc":[{"batb":[[0,1.96,6.2],[1,1.48,18.79],[2,1.45,5.15]],"ltp":2.08,"tv":53.13,"id":67083366}]}]}
{"op":"mcm","clk":"11927919063","pt":1724245308070,"mc":[{"id":"1.232048948","rc":[{"batb":[[0,1.97,14],[1,1.96,6.2],[2,1.48,18.79]],"ltp":2.08,"tv":53.13,"id":67083366}]}]}
{"op":"mcm","clk":"11927919236","pt":1724245311002,"mc":[{"id":"1.232048948","rc":[{"batb":[[0,1.97,10]],"ltp":2.08,"tv":53.13,"id":67083366}]}]}
{"op":"mcm","clk":"11927919281","pt":1724245311875,"mc":[{"id":"1.232048948","rc":[{"batb":[[0,1.96,6.2],[1,1.48,18.79],[2,1.45,5.15]],"ltp":2.08,"tv":53.13,"id":67083366}]}]}
{"op":"mcm","clk":"11927919427","pt":1724245314292,"mc":[{"id":"1.232048948","rc":[{"batb":[[0,1.98,10],[1,1.97,4],[2,1.96,6.2]],"ltp":2.08,"tv":53.13,"id":67083366}]}]}
{"op":"mcm","clk":"11927919615","pt":1724245317116,"mc":[{"id":"1.232048948","rc":[{"batb":[[1,1.96,6.2],[2,1.48,18.79]],"ltp":2.08,"tv":53.13,"id":67083366}]}]}
{"op":"mcm","clk":"11927919678","pt":1724245318198,"mc":[{"id":"1.232048948","rc":[{"batb":[[0,1.96,6.2],[1,1.48,18.79],[2,1.45,5.15]],"ltp":2.08,"tv":53.13,"id":67083366}]}]}
{"op":"mcm","clk":"11927919798","pt":1724245320098,"mc":[{"id":"1.232048948","rc":[{"batb":[[0,1.97,4],[1,1.96,6.2],[2,1.48,18.79]],"ltp":2.08,"tv":53.13,"id":67083366}]}]}
{"op":"mcm","clk":"11927919818","pt":1724245320408,"mc":[{"id":"1.232048948","rc":[{"batb":[[0,1.98,10],[1,1.97,4],[2,1.96,6.2]],"ltp":2.08,"tv":53.13,"id":67083366}]}]}
{"op":"mcm","clk":"11927920011","pt":1724245323099,"mc":[{"id":"1.232048948","rc":[{"batb":[[1,1.96,6.2],[2,1.48,18.79]],"ltp":2.08,"tv":53.13,"id":67083366}]}]}
{"op":"mcm","clk":"11927920117","pt":1724245324391,"mc":[{"id":"1.232048948","rc":[{"batb":[[0,1.96,6.2],[1,1.48,18.79],[2,1.45,5.15]],"ltp":2.08,"tv":53.13,"id":67083366}]}]}
{"op":"mcm","clk":"11927920373","pt":1724245328104,"mc":[{"id":"1.232048948","rc":[{"batb":[[0,1.97,14],[1,1.96,6.2],[2,1.48,18.79]],"ltp":2.08,"tv":53.13,"id":67083366}]}]}
{"op":"mcm","clk":"11927920621","pt":1724245330893,"mc":[{"id":"1.232048948","rc":[{"batb":[[0,1.97,10]],"ltp":2.08,"tv":53.13,"id":67083366}]}]}
{"op":"mcm","clk":"11927920696","pt":1724245332026,"mc":[{"id":"1.232048948","rc":[{"batb":[[0,1.96,6.2],[1,1.48,18.79],[2,1.45,5.15]],"ltp":2.08,"tv":53.13,"id":67083366}]}]}
{"op":"mcm","clk":"11927921130","pt":1724245338032,"mc":[{"id":"1.232048948","rc":[{"batb":[[0,1.97,14],[1,1.96,6.2],[2,1.48,18.79]],"ltp":2.08,"tv":53.13,"id":67083366}]}]}
{"op":"mcm","clk":"11927921270","pt":1724245340143,"mc":[{"id":"1.232048948","rc":[{"batb":[[0,1.97,10]],"ltp":2.08,"tv":53.13,"id":67083366}]}]}
{"op":"mcm","clk":"11927921362","pt":1724245341740,"mc":[{"id":"1.232048948","rc":[{"batb":[[0,1.96,6.2],[1,1.48,18.79],[2,1.45,5.15]],"ltp":2.08,"tv":53.13,"id":67083366}]}]}
{"op":"mcm","clk":"11927921613","pt":1724245345315,"mc":[{"id":"1.232048948","rc":[{"batb":[[0,1.97,4],[1,1.96,6.2],[2,1.48,18.79]],"ltp":2.08,"tv":53.13,"id":67083366}]}]}
{"op":"mcm","clk":"11927921625","pt":1724245345415,"mc":[{"id":"1.232048948","rc":[{"batb":[[0,1.97,14]],"ltp":2.08,"tv":53.13,"id":67083366}]}]}
{"op":"mcm","clk":"11927921783","pt":1724245347832,"mc":[{"id":"1.232048948","rc":[{"batb":[[0,1.97,10]],"ltp":2.08,"tv":53.13,"id":67083366}]}]}
{"op":"mcm","clk":"11927921903","pt":1724245349431,"mc":[{"id":"1.232048948","rc":[{"batb":[[0,1.96,6.2],[1,1.48,18.79],[2,1.45,5.15]],"ltp":2.08,"tv":53.13,"id":67083366}]}]}
{"op":"mcm","clk":"11927922154","pt":1724245352434,"mc":[{"id":"1.232048948","rc":[{"batb":[[0,1.97,14],[1,1.96,6.2],[2,1.48,18.79]],"ltp":2.08,"tv":53.13,"id":67083366}]}]}
{"op":"mcm","clk":"11927922372","pt":1724245355071,"mc":[{"id":"1.232048948","rc":[{"batb":[[0,1.97,10]],"ltp":2.08,"tv":53.13,"id":67083366}]}]}
{"op":"mcm","clk":"11927922457","pt":1724245356057,"mc":[{"id":"1.232048948","rc":[{"batb":[[0,1.96,6.2],[1,1.48,18.79],[2,1.45,5.15]],"ltp":2.08,"tv":53.13,"id":67083366}]}]}
{"op":"mcm","clk":"11927922738","pt":1724245359934,"mc":[{"id":"1.232048948","rc":[{"batb":[[0,1.97,14],[1,1.96,6.2],[2,1.48,18.79]],"ltp":2.08,"tv":53.13,"id":67083366}]}]}
{"op":"mcm","clk":"11927922918","pt":1724245362869,"mc":[{"id":"1.232048948","rc":[{"batb":[[0,1.97,10]],"ltp":2.08,"tv":53.13,"id":67083366}]}]}
{"op":"mcm","clk":"11927922979","pt":1724245363743,"mc":[{"id":"1.232048948","rc":[{"batb":[[0,1.96,6.2],[1,1.48,18.79],[2,1.45,5.15]],"ltp":2.08,"tv":53.13,"id":67083366}]}]}
{"op":"mcm","clk":"11927923077","pt":1724245365544,"mc":[{"id":"1.232048948","rc":[{"batb":[[0,1.97,4],[1,1.96,6.2],[2,1.48,18.79]],"ltp":2.08,"tv":53.13,"id":67083366}]}]}
{"op":"mcm","clk":"11927923139","pt":1724245366432,"mc":[{"id":"1.232048948","rc":[{"batb":[[0,1.98,10],[1,1.97,4],[2,1.96,6.2]],"ltp":2.08,"tv":53.13,"id":67083366}]}]}
{"op":"mcm","clk":"11927923273","pt":1724245368249,"mc":[{"id":"1.232048948","rc":[{"batb":[[1,1.96,6.2],[2,1.48,18.79]],"ltp":2.08,"tv":53.13,"id":67083366}]}]}
{"op":"mcm","clk":"11927923399","pt":1724245369974,"mc":[{"id":"1.232048948","rc":[{"batb":[[0,1.96,6.2],[1,1.48,18.79],[2,1.45,5.15]],"ltp":2.08,"tv":53.13,"id":67083366}]}]}
{"op":"mcm","clk":"11927923686","pt":1724245373845,"mc":[{"id":"1.232048948","rc":[{"batb":[[0,1.97,14],[1,1.96,6.2],[2,1.48,18.79]],"ltp":2.08,"tv":53.13,"id":67083366}]}]}
{"op":"mcm","clk":"11927923952","pt":1724245377260,"mc":[{"id":"1.232048948","rc":[{"batb":[[0,1.96,6.2],[1,1.48,18.79],[2,1.45,5.15]],"ltp":2.08,"tv":53.13,"id":67083366}]}]}
{"op":"mcm","clk":"11927924959","pt":1724245390760,"mc":[{"id":"1.232048948","rc":[{"batb":[[0,1.97,14],[1,1.96,6.2],[2,1.48,18.79]],"ltp":2.08,"tv":53.13,"id":67083366}]}]}
{"op":"mcm","clk":"11927925098","pt":1724245393299,"mc":[{"id":"1.232048948","rc":[{"batb":[[0,1.97,10]],"ltp":2.08,"tv":53.13,"id":67083366}]}]}
{"op":"mcm","clk":"11927925200","pt":1724245394686,"mc":[{"id":"1.232048948","rc":[{"batb":[[0,1.96,6.2],[1,1.48,18.79],[2,1.45,5.15]],"ltp":2.08,"tv":53.13,"id":67083366}]}]}
{"op":"mcm","clk":"11927926603","pt":1724245416889,"mc":[{"id":"1.232048948","rc":[{"batb":[[0,1.97,14],[1,1.96,6.2],[2,1.48,18.79]],"ltp":2.08,"tv":53.13,"id":67083366}]}]}
{"op":"mcm","clk":"11927926774","pt":1724245420296,"mc":[{"id":"1.232048948","rc":[{"batb":[[0,1.96,6.2],[1,1.48,18.79],[2,1.45,5.15]],"ltp":2.08,"tv":53.13,"id":67083366}]}]}
{"op":"mcm","clk":"11927926875","pt":1724245421901,"mc":[{"id":"1.232048948","rc":[{"batb":[[0,1.97,4],[1,1.96,6.2],[2,1.48,18.79]],"ltp":2.08,"tv":53.13,"id":67083366}]}]}
{"op":"mcm","clk":"11927926915","pt":1724245422509,"mc":[{"id":"1.232048948","rc":[{"batb":[[0,1.98,10],[1,1.97,4],[2,1.96,6.2]],"ltp":2.08,"tv":53.13,"id":67083366}]}]}
{"op":"mcm","clk":"11927927070","pt":1724245424626,"mc":[{"id":"1.232048948","rc":[{"batb":[[1,1.96,6.2],[2,1.48,18.79]],"ltp":2.08,"tv":53.13,"id":67083366}]}]}
{"op":"mcm","clk":"11927927184","pt":1724245426229,"mc":[{"id":"1.232048948","rc":[{"batb":[[0,1.96,6.2],[1,1.48,18.79],[2,1.45,5.15]],"ltp":2.08,"tv":53.13,"id":67083366}]}]}
{"op":"mcm","clk":"11927927401","pt":1724245429331,"mc":[{"id":"1.232048948","rc":[{"batb":[[0,1.97,14],[1,1.96,6.2],[2,1.48,18.79]],"ltp":2.08,"tv":53.13,"id":67083366}]}]}
{"op":"mcm","clk":"11927927577","pt":1724245432219,"mc":[{"id":"1.232048948","rc":[{"batb":[[0,1.97,10]],"ltp":2.08,"tv":53.13,"id":67083366}]}]}
{"op":"mcm","clk":"11927927634","pt":1724245433158,"mc":[{"id":"1.232048948","rc":[{"batb":[[0,1.96,6.2],[1,1.48,18.79],[2,1.45,5.15]],"ltp":2.08,"tv":53.13,"id":67083366}]}]}
{"op":"mcm","clk":"11927927781","pt":1724245435758,"mc":[{"id":"1.232048948","rc":[{"batb":[[0,1.97,14],[1,1.96,6.2],[2,1.48,18.79]],"ltp":2.08,"tv":53.13,"id":67083366}]}]}
{"op":"mcm","clk":"11927928062","pt":1724245439317,"mc":[{"id":"1.232048948","rc":[{"batb":[[0,1.96,6.2],[1,1.48,18.79],[2,1.45,5.15]],"ltp":2.08,"tv":53.13,"id":67083366}]}]}
{"op":"mcm","clk":"11927928307","pt":1724245442157,"mc":[{"id":"1.232048948","rc":[{"batb":[[0,1.97,14],[1,1.96,6.2],[2,1.48,18.79]],"ltp":2.08,"tv":53.13,"id":67083366}]}]}
{"op":"mcm","clk":"11927928705","pt":1724245446335,"mc":[{"id":"1.232048948","rc":[{"batb":[[0,1.96,6.2],[1,1.48,18.79],[2,1.45,5.15]],"ltp":2.08,"tv":53.13,"id":67083366}]}]}
{"op":"mcm","clk":"11927928914","pt":1724245449233,"mc":[{"id":"1.232048948","rc":[{"batb":[[0,1.98,14],[1,1.96,6.2],[2,1.48,18.79]],"ltp":2.08,"tv":53.13,"id":67083366}]}]}
{"op":"mcm","clk":"11927929459","pt":1724245457854,"mc":[{"id":"1.232048948","rc":[{"batb":[[0,1.98,10]],"ltp":2.08,"tv":53.13,"id":67083366}]}]}
{"op":"mcm","clk":"11927929530","pt":1724245458940,"mc":[{"id":"1.232048948","rc":[{"batb":[[0,1.96,6.2],[1,1.48,18.79],[2,1.45,5.15]],"ltp":2.08,"tv":53.13,"id":67083366}]}]}
{"op":"mcm","clk":"11927929655","pt":1724245460952,"mc":[{"id":"1.232048948","rc":[{"batb":[[0,1.99,4],[1,1.96,6.2],[2,1.48,18.79]],"ltp":2.08,"tv":53.13,"id":67083366}]}]}
{"op":"mcm","clk":"11927929700","pt":1724245461663,"mc":[{"id":"1.232048948","rc":[{"batb":[[0,1.99,14]],"ltp":2.08,"tv":53.13,"id":67083366}]}]}
{"op":"mcm","clk":"11927930032","pt":1724245466951,"mc":[{"id":"1.232048948","rc":[{"batb":[[0,1.99,10]],"ltp":2.08,"tv":53.13,"id":67083366}]}]}
{"op":"mcm","clk":"11927930173","pt":1724245469169,"mc":[{"id":"1.232048948","rc":[{"batb":[[0,2,4]],"ltp":2.08,"tv":53.13,"id":67083366}]}]}
{"op":"mcm","clk":"11927930402","pt":1724245472285,"mc":[{"id":"1.232048948","rc":[{"batb":[[0,2.02,10],[1,2,4],[2,1.96,6.2]],"ltp":2.08,"tv":53.13,"id":67083366}]}]}
{"op":"mcm","clk":"11927930457","pt":1724245473070,"mc":[{"id":"1.232048948","rc":[{"batb":[[1,1.96,6.2],[2,1.48,18.79]],"ltp":2.08,"tv":53.13,"id":67083366}]}]}
{"op":"mcm","clk":"11927930715","pt":1724245477085,"mc":[{"id":"1.232048948","rc":[{"batb":[[0,1.97,4]],"ltp":2.08,"tv":53.13,"id":67083366}]}]}
{"op":"mcm","clk":"11927930887","pt":1724245479568,"mc":[{"id":"1.232048948","rc":[{"batb":[[0,1.97,10]],"ltp":2.08,"tv":53.13,"id":67083366}]}]}
{"op":"mcm","clk":"11927931117","pt":1724245483087,"mc":[{"id":"1.232048948","rc":[{"batb":[[0,1.98,4]],"ltp":2.08,"tv":53.13,"id":67083366}]}]}
{"op":"mcm","clk":"11927931354","pt":1724245486090,"mc":[{"id":"1.232048948","rc":[{"batb":[[0,1.96,6.2],[1,1.48,18.79],[2,1.45,5.15]],"ltp":2.08,"tv":53.13,"id":67083366}]}]}
{"op":"mcm","clk":"11927931839","pt":1724245492766,"mc":[{"id":"1.232048948","rc":[{"batb":[[0,1.97,14],[1,1.96,6.2],[2,1.48,18.79]],"ltp":2.08,"tv":53.13,"id":67083366}]}]}
{"op":"mcm","clk":"11927932540","pt":1724245502799,"mc":[{"id":"1.232048948","rc":[{"batb":[[0,1.97,10]],"ltp":2.08,"tv":53.13,"id":67083366}]}]}
{"op":"mcm","clk":"11927932618","pt":1724245503792,"mc":[{"id":"1.232048948","rc":[{"batb":[[0,1.96,6.2],[1,1.48,18.79],[2,1.45,5.15]],"ltp":2.08,"tv":53.13,"id":67083366}]}]}
{"op":"mcm","clk":"11927932719","pt":1724245505187,"mc":[{"id":"1.232048948","rc":[{"batb":[[0,1.98,4],[1,1.96,6.2],[2,1.48,18.79]],"ltp":2.08,"tv":53.13,"id":67083366}]}]}
{"op":"mcm","clk":"11927932943","pt":1724245508285,"mc":[{"id":"1.232048948","rc":[{"batb":[[0,1.98,14]],"ltp":2.08,"tv":53.13,"id":67083366}]}]}
{"op":"mcm","clk":"11927933231","pt":1724245512637,"mc":[{"id":"1.232048948","rc":[{"batb":[[0,1.98,10]],"ltp":2.08,"tv":53.13,"id":67083366}]}]}
{"op":"mcm","clk":"11927933492","pt":1724245516806,"mc":[{"id":"1.232048948","rc":[{"batb":[[0,1.99,4]],"ltp":2.08,"tv":53.13,"id":67083366}]}]}
{"op":"mcm","clk":"11927933692","pt":1724245520001,"mc":[{"id":"1.232048948","rc":[{"batb":[[1,1.97,10],[2,1.96,6.2]],"ltp":2.08,"tv":53.13,"id":67083366}]}]}
{"op":"mcm","clk":"11927933883","pt":1724245522521,"mc":[{"id":"1.232048948","rc":[{"batb":[[0,1.97,10],[1,1.96,6.2],[2,1.48,18.79]],"ltp":2.08,"tv":53.13,"id":67083366}]}]}
{"op":"mcm","clk":"11927934087","pt":1724245526028,"mc":[{"id":"1.232048948","rc":[{"batb":[[0,1.98,4]],"ltp":2.08,"tv":53.13,"id":67083366}]}]}
{"op":"mcm","clk":"11927934228","pt":1724245527996,"mc":[{"id":"1.232048948","rc":[{"batb":[[0,1.99,10],[1,1.98,4],[2,1.96,6.2]],"ltp":2.08,"tv":53.13,"id":67083366}]}]}
{"op":"mcm","clk":"11927934333","pt":1724245529937,"mc":[{"id":"1.232048948","rc":[{"batb":[[1,1.96,6.2],[2,1.48,18.79]],"ltp":2.08,"tv":53.13,"id":67083366}]}]}
{"op":"mcm","clk":"11927934537","pt":1724245532820,"mc":[{"id":"1.232048948","rc":[{"batb":[[0,1.97,4]],"ltp":2.08,"tv":53.13,"id":67083366}]}]}
{"op":"mcm","clk":"11927934685","pt":1724245535299,"mc":[{"id":"1.232048948","rc":[{"batb":[[0,1.96,6.2],[1,1.48,18.79],[2,1.45,5.15]],"ltp":2.08,"tv":53.13,"id":67083366}]}]}
{"op":"mcm","clk":"11927934699","pt":1724245535503,"mc":[{"id":"1.232048948","rc":[{"batb":[[0,1.97,10],[1,1.96,6.2],[2,1.48,18.79]],"ltp":2.08,"tv":53.13,"id":67083366}]}]}
{"op":"mcm","clk":"11927934917","pt":1724245539213,"mc":[{"id":"1.232048948","rc":[{"batb":[[0,1.96,6.2],[1,1.48,18.79],[2,1.45,5.15]],"ltp":2.08,"tv":53.13,"id":67083366}]}]}
{"op":"mcm","clk":"11927934937","pt":1724245539522,"mc":[{"id":"1.232048948","rc":[{"batb":[[0,1.97,4],[1,1.96,6.2],[2,1.48,18.79]],"ltp":2.08,"tv":53.13,"id":67083366}]}]}
{"op":"mcm","clk":"11927935116","pt":1724245542049,"mc":[{"id":"1.232048948","rc":[{"batb":[[0,1.96,6.2],[1,1.48,18.79],[2,1.45,5.15]],"ltp":2.08,"tv":53.13,"id":67083366}]}]}
{"op":"mcm","clk":"11927935138","pt":1724245542357,"mc":[{"id":"1.232048948","rc":[{"batb":[[0,1.97,10],[1,1.96,6.2],[2,1.48,18.79]],"ltp":2.08,"tv":53.13,"id":67083366}]}]}
{"op":"mcm","clk":"11927935353","pt":1724245545757,"mc":[{"id":"1.232048948","rc":[{"batb":[[0,1.98,4]],"ltp":2.08,"tv":53.13,"id":67083366}]}]}
{"op":"mcm","clk":"11927935525","pt":1724245548229,"mc":[{"id":"1.232048948","rc":[{"batb":[[0,1.97,10]],"ltp":2.08,"tv":53.13,"id":67083366}]}]}
{"op":"mcm","clk":"11927935671","pt":1724245550140,"mc":[{"id":"1.232048948","rc":[{"batb":[[0,1.98,4],[1,1.97,10],[2,1.96,6.2]],"ltp":2.08,"tv":53.13,"id":67083366}]}]}
{"op":"mcm","clk":"11927935806","pt":1724245551842,"mc":[{"id":"1.232048948","rc":[{"batb":[[1,1.96,6.2],[2,1.48,18.79]],"ltp":2.08,"tv":53.13,"id":67083366}]}]}
{"op":"mcm","clk":"11927935859","pt":1724245552720,"mc":[{"id":"1.232048948","rc":[{"batb":[[0,1.96,6.2],[1,1.48,18.79],[2,1.45,5.15]],"ltp":2.08,"tv":53.13,"id":67083366}]}]}
{"op":"mcm","clk":"11927936036","pt":1724245555745,"mc":[{"id":"1.232048948","rc":[{"batb":[[0,1.97,14],[1,1.96,6.2],[2,1.48,18.79]],"ltp":2.08,"tv":53.13,"id":67083366}]}]}
{"op":"mcm","clk":"11927936183","pt":1724245558427,"mc":[{"id":"1.232048948","rc":[{"batb":[[0,1.97,10]],"ltp":2.08,"tv":53.13,"id":67083366}]}]}
{"op":"mcm","clk":"11927936245","pt":1724245559558,"mc":[{"id":"1.232048948","rc":[{"batb":[[0,1.96,6.2],[1,1.48,18.79],[2,1.45,5.15]],"ltp":2.08,"tv":53.13,"id":67083366}]}]}
{"op":"mcm","clk":"11927936332","pt":1724245561161,"mc":[{"id":"1.232048948","rc":[{"batb":[[0,1.97,4],[1,1.96,6.2],[2,1.48,18.79]],"ltp":2.08,"tv":53.13,"id":67083366}]}]}
{"op":"mcm","clk":"11927936389","pt":1724245561842,"mc":[{"id":"1.232048948","rc":[{"batb":[[0,1.98,10],[1,1.97,4],[2,1.96,6.2]],"ltp":2.08,"tv":53.13,"id":67083366}]}]}
{"op":"mcm","clk":"11927936553","pt":1724245564266,"mc":[{"id":"1.232048948","rc":[{"batb":[[1,1.96,6.2],[2,1.48,18.79]],"ltp":2.08,"tv":53.13,"id":67083366}]}]}
{"op":"mcm","clk":"11927936663","pt":1724245565557,"mc":[{"id":"1.232048948","rc":[{"batb":[[0,1.96,6.2],[1,1.48,18.79],[2,1.45,5.15]],"ltp":2.08,"tv":53.13,"id":67083366}]}]}
{"op":"mcm","clk":"11927936985","pt":1724245570276,"mc":[{"id":"1.232048948","rc":[{"batb":[[0,1.97,14],[1,1.96,6.2],[2,1.48,18.79]],"ltp":2.08,"tv":53.13,"id":67083366}]}]}
{"op":"mcm","clk":"11927937122","pt":1724245572751,"mc":[{"id":"1.232048948","rc":[{"batb":[[0,1.97,10]],"ltp":2.08,"tv":53.13,"id":67083366}]}]}
{"op":"mcm","clk":"11927937189","pt":1724245573784,"mc":[{"id":"1.232048948","rc":[{"batb":[[0,1.96,6.2],[1,1.48,18.79],[2,1.45,5.15]],"ltp":2.08,"tv":53.13,"id":67083366}]}]}
{"op":"mcm","clk":"11927937264","pt":1724245575079,"mc":[{"id":"1.232048948","rc":[{"batb":[[0,1.97,4],[1,1.96,6.2],[2,1.48,18.79]],"ltp":2.08,"tv":53.13,"id":67083366}]}]}
{"op":"mcm","clk":"11927937458","pt":1724245578077,"mc":[{"id":"1.232048948","rc":[{"batb":[[0,1.97,10]],"ltp":2.08,"tv":53.13,"id":67083366}]}]}
{"op":"mcm","clk":"11927937492","pt":1724245578492,"mc":[{"id":"1.232048948","rc":[{"batl":[[0,2,3.56]],"ltp":1.92,"tv":10.2,"id":72857114}]}]}
{"op":"mcm","clk":"11927937604","pt":1724245580246,"mc":[{"id":"1.232048948","rc":[{"batb":[[0,1.98,4],[1,1.97,10],[2,1.96,6.2]],"ltp":2.08,"tv":53.13,"id":67083366}]}]}
{"op":"mcm","clk":"11927937664","pt":1724245581283,"mc":[{"id":"1.232048948","rc":[{"batb":[[1,1.96,6.2],[2,1.48,18.79]],"ltp":2.08,"tv":53.13,"id":67083366}]}]}
{"op":"mcm","clk":"11927937779","pt":1724245582989,"mc":[{"id":"1.232048948","rc":[{"batb":[[0,1.96,6.2],[1,1.48,18.79],[2,1.45,5.15]],"ltp":2.08,"tv":53.13,"id":67083366}]}]}
{"op":"mcm","clk":"11927937879","pt":1724245584584,"mc":[{"id":"1.232048948","rc":[{"batb":[[0,1.97,10],[1,1.96,6.2],[2,1.48,18.79]],"ltp":2.08,"tv":53.13,"id":67083366}]}]}
{"op":"mcm","clk":"11927938087","pt":1724245588081,"mc":[{"id":"1.232048948","rc":[{"batb":[[0,1.96,6.2],[1,1.48,18.79],[2,1.45,5.15]],"ltp":2.08,"tv":53.13,"id":67083366}]}]}
{"op":"mcm","clk":"11927938110","pt":1724245588493,"mc":[{"id":"1.232048948","rc":[{"batb":[[0,1.97,4],[1,1.96,6.2],[2,1.48,18.79]],"ltp":2.08,"tv":53.13,"id":67083366}]}]}
{"op":"mcm","clk":"11927938267","pt":1724245590968,"mc":[{"id":"1.232048948","rc":[{"batb":[[0,1.98,10]],"ltp":2.08,"tv":53.13,"id":67083366}]}]}
{"op":"mcm","clk":"11927938465","pt":1724245594280,"mc":[{"id":"1.232048948","rc":[{"batb":[[0,1.96,6.2],[1,1.48,18.79],[2,1.45,5.15]],"ltp":2.08,"tv":53.13,"id":67083366}]}]}
{"op":"mcm","clk":"11927938486","pt":1724245594696,"mc":[{"id":"1.232048948","rc":[{"batb":[[0,1.97,4],[1,1.96,6.2],[2,1.48,18.79]],"ltp":2.08,"tv":53.13,"id":67083366}]}]}
{"op":"mcm","clk":"11927938650","pt":1724245597110,"mc":[{"id":"1.232048948","rc":[{"batb":[[0,1.96,6.2],[1,1.48,18.79],[2,1.45,5.15]],"ltp":2.08,"tv":53.13,"id":67083366}]}]}
{"op":"mcm","clk":"11927938675","pt":1724245597374,"mc":[{"id":"1.232048948","rc":[{"batb":[[0,1.97,10],[1,1.96,6.2],[2,1.48,18.79]],"ltp":2.08,"tv":53.13,"id":67083366}]}]}
{"op":"mcm","clk":"11927938926","pt":1724245601179,"mc":[{"id":"1.232048948","rc":[{"batb":[[0,1.96,6.2],[1,1.48,18.79],[2,1.45,5.15]],"ltp":2.08,"tv":53.13,"id":67083366}]}]}
{"op":"mcm","clk":"11927938940","pt":1724245601488,"mc":[{"id":"1.232048948","rc":[{"batb":[[0,1.97,4],[1,1.96,6.2],[2,1.48,18.79]],"ltp":2.08,"tv":53.13,"id":67083366}]}]}
{"op":"mcm","clk":"11927939100","pt":1724245604013,"mc":[{"id":"1.232048948","rc":[{"batb":[[0,1.98,10]],"ltp":2.08,"tv":53.13,"id":67083366}]}]}
{"op":"mcm","clk":"11927939415","pt":1724245608103,"mc":[{"id":"1.232048948","rc":[{"batb":[[0,1.97,4]],"ltp":2.08,"tv":53.13,"id":67083366}]}]}
{"op":"mcm","clk":"11927939534","pt":1724245610108,"mc":[{"id":"1.232048948","rc":[{"batb":[[0,1.98,10],[1,1.97,4],[2,1.96,6.2]],"ltp":2.08,"tv":53.13,"id":67083366}]}]}
{"op":"mcm","clk":"11927939576","pt":1724245610781,"mc":[{"id":"1.232048948","rc":[{"batb":[[1,1.96,6.2],[2,1.48,18.79]],"ltp":2.08,"tv":53.13,"id":67083366}]}]}
{"op":"mcm","clk":"11927939746","pt":1724245614118,"mc":[{"id":"1.232048948","rc":[{"batb":[[0,1.97,4]],"ltp":2.08,"tv":53.13,"id":67083366}]}]}
{"op":"mcm","clk":"11927939866","pt":1724245616335,"mc":[{"id":"1.232048948","rc":[{"batb":[[0,1.96,6.2],[1,1.48,18.79],[2,1.45,5.15]],"ltp":2.08,"tv":53.13,"id":67083366}]}]}
{"op":"mcm","clk":"11927939884","pt":1724245616594,"mc":[{"id":"1.232048948","rc":[{"batb":[[0,1.97,10],[1,1.96,6.2],[2,1.48,18.79]],"ltp":2.08,"tv":53.13,"id":67083366}]}]}
{"op":"mcm","clk":"11927940121","pt":1724245620205,"mc":[{"id":"1.232048948","rc":[{"batb":[[0,1.98,4]],"ltp":2.08,"tv":53.13,"id":67083366}]}]}
{"op":"mcm","clk":"11927940297","pt":1724245622334,"mc":[{"id":"1.232048948","rc":[{"batb":[[0,1.96,6.2],[1,1.48,18.79],[2,1.45,5.15]],"ltp":2.08,"tv":53.13,"id":67083366}]}]}
{"op":"mcm","clk":"11927940784","pt":1724245629613,"mc":[{"id":"1.232048948","rc":[{"batb":[[0,1.97,14],[1,1.96,6.2],[2,1.48,18.79]],"ltp":2.08,"tv":53.13,"id":67083366}]}]}
{"op":"mcm","clk":"11927941395","pt":1724245638642,"mc":[{"id":"1.232048948","rc":[{"batb":[[0,1.97,10]],"ltp":2.08,"tv":53.13,"id":67083366}]}]}
{"op":"mcm","clk":"11927941449","pt":1724245639460,"mc":[{"id":"1.232048948","rc":[{"batb":[[0,1.96,6.2],[1,1.48,18.79],[2,1.45,5.15]],"ltp":2.08,"tv":53.13,"id":67083366}]}]}
{"op":"mcm","clk":"11927941544","pt":1724245640952,"mc":[{"id":"1.232048948","rc":[{"batb":[[0,1.98,4],[1,1.96,6.2],[2,1.48,18.79]],"ltp":2.08,"tv":53.13,"id":67083366}]}]}
{"op":"mcm","clk":"11927941644","pt":1724245642651,"mc":[{"id":"1.232048948","rc":[{"batb":[[0,1.98,14]],"ltp":2.08,"tv":53.13,"id":67083366}]}]}
{"op":"mcm","clk":"11927941946","pt":1724245646939,"mc":[{"id":"1.232048948","rc":[{"batb":[[0,1.98,10]],"ltp":2.08,"tv":53.13,"id":67083366}]}]}
{"op":"mcm","clk":"11927942091","pt":1724245649146,"mc":[{"id":"1.232048948","rc":[{"batb":[[0,1.96,6.2],[1,1.48,18.79],[2,1.45,5.15]],"ltp":2.08,"tv":53.13,"id":67083366}]}]}
{"op":"mcm","clk":"11927942149","pt":1724245650234,"mc":[{"id":"1.232048948","rc":[{"batb":[[0,1.99,4],[1,1.96,6.2],[2,1.48,18.79]],"ltp":2.08,"tv":53.13,"id":67083366}]}]}
{"op":"mcm","clk":"11927942239","pt":1724245651769,"mc":[{"id":"1.232048948","rc":[{"batb":[[0,2,10],[1,1.99,4],[2,1.96,6.2]],"ltp":2.08,"tv":53.13,"id":67083366}]}]}
{"op":"mcm","clk":"11927942352","pt":1724245653941,"mc":[{"id":"1.232048948","rc":[{"batb":[[1,1.96,6.2],[2,1.48,18.79]],"ltp":2.08,"tv":53.13,"id":67083366}]}]}
{"op":"mcm","clk":"11927942531","pt":1724245656251,"mc":[{"id":"1.232048948","rc":[{"batb":[[0,1.97,4]],"ltp":2.08,"tv":53.13,"id":67083366}]}]}
{"op":"mcm","clk":"11927942704","pt":1724245658773,"mc":[{"id":"1.232048948","rc":[{"batb":[[0,1.97,10]],"ltp":2.08,"tv":53.13,"id":67083366}]}]}
{"op":"mcm","clk":"11927942906","pt":1724245662262,"mc":[{"id":"1.232048948","rc":[{"batb":[[0,1.97,4]],"ltp":2.08,"tv":53.13,"id":67083366}]}]}
{"op":"mcm","clk":"11927943080","pt":1724245664790,"mc":[{"id":"1.232048948","rc":[{"batb":[[0,1.97,10]],"ltp":2.08,"tv":53.13,"id":67083366}]}]}
{"op":"mcm","clk":"11927943327","pt":1724245668288,"mc":[{"id":"1.232048948","rc":[{"batb":[[0,1.98,4]],"ltp":2.08,"tv":53.13,"id":67083366}]}]}
{"op":"mcm","clk":"11927943466","pt":1724245670269,"mc":[{"id":"1.232048948","rc":[{"batb":[[0,1.99,10],[1,1.98,4],[2,1.96,6.2]],"ltp":2.08,"tv":53.13,"id":67083366}]}]}
{"op":"mcm","clk":"11927943506","pt":1724245671091,"mc":[{"id":"1.232048948","rc":[{"batb":[[1,1.96,6.2],[2,1.48,18.79]],"ltp":2.08,"tv":53.13,"id":67083366}]}]}
{"op":"mcm","clk":"11927943695","pt":1724245673972,"mc":[{"id":"1.232048948","rc":[{"batb":[[0,1.97,4]],"ltp":2.08,"tv":53.13,"id":67083366}]}]}
{"op":"mcm","clk":"11927943859","pt":1724245676865,"mc":[{"id":"1.232048948","rc":[{"batb":[[0,1.97,10]],"ltp":2.08,"tv":53.13,"id":67083366}]}]}
{"op":"mcm","clk":"11927944052","pt":1724245680199,"mc":[{"id":"1.232048948","rc":[{"batb":[[0,1.98,4]],"ltp":2.08,"tv":53.13,"id":67083366}]}]}
{"op":"mcm","clk":"11927944214","pt":1724245682685,"mc":[{"id":"1.232048948","rc":[{"batb":[[0,1.96,6.2],[1,1.48,18.79],[2,1.45,5.15]],"ltp":2.08,"tv":53.13,"id":67083366}]}]}
{"op":"mcm","clk":"11927944266","pt":1724245683393,"mc":[{"id":"1.232048948","rc":[{"batb":[[0,1.97,10],[1,1.96,6.2],[2,1.48,18.79]],"ltp":2.08,"tv":53.13,"id":67083366}]}]}
{"op":"mcm","clk":"11927944561","pt":1724245687201,"mc":[{"id":"1.232048948","rc":[{"batb":[[0,1.96,6.2],[1,1.48,18.79],[2,1.45,5.15]],"ltp":2.08,"tv":53.13,"id":67083366}]}]}
{"op":"mcm","clk":"11927944576","pt":1724245687407,"mc":[{"id":"1.232048948","rc":[{"batb":[[0,1.97,4],[1,1.96,6.2],[2,1.48,18.79]],"ltp":2.08,"tv":53.13,"id":67083366}]}]}
{"op":"mcm","clk":"11927944751","pt":1724245689985,"mc":[{"id":"1.232048948","rc":[{"batb":[[0,1.97,10]],"ltp":2.08,"tv":53.13,"id":67083366}]}]}
{"op":"mcm","clk":"11927945006","pt":1724245693086,"mc":[{"id":"1.232048948","rc":[{"batb":[[0,1.98,4],[1,1.97,10],[2,1.96,6.2]],"ltp":2.08,"tv":53.13,"id":67083366}]}]}
{"op":"mcm","clk":"11927945031","pt":1724245693398,"mc":[{"id":"1.232048948","rc":[{"batb":[[1,1.96,6.2],[2,1.48,18.79]],"ltp":2.08,"tv":53.13,"id":67083366}]}]}
{"op":"mcm","clk":"11927945233","pt":1724245696019,"mc":[{"id":"1.232048948","rc":[{"batb":[[0,1.96,6.2],[1,1.48,18.79],[2,1.45,5.15]],"ltp":2.08,"tv":53.13,"id":67083366}]}]}
{"op":"mcm","clk":"11927945267","pt":1724245696384,"mc":[{"id":"1.232048948","rc":[{"batb":[[0,1.97,10],[1,1.96,6.2],[2,1.48,18.79]],"ltp":2.08,"tv":53.13,"id":67083366}]}]}
{"op":"mcm","clk":"11927945541","pt":1724245700300,"mc":[{"id":"1.232048948","rc":[{"batb":[[0,1.98,4]],"ltp":2.08,"tv":53.13,"id":67083366}]}]}
{"op":"mcm","clk":"11927945766","pt":1724245703800,"mc":[{"id":"1.232048948","rc":[{"batb":[[0,1.97,10]],"ltp":2.08,"tv":53.13,"id":67083366}]}]}
{"op":"mcm","clk":"11927946044","pt":1724245707628,"mc":[{"id":"1.232048948","rc":[{"batb":[[0,1.97,4]],"ltp":2.08,"tv":53.13,"id":67083366}]}]}
{"op":"mcm","clk":"11927946237","pt":1724245710213,"mc":[{"id":"1.232048948","rc":[{"batb":[[0,1.96,6.2],[1,1.48,18.79],[2,1.45,5.15]],"ltp":2.08,"tv":53.13,"id":67083366}]}]}
{"op":"mcm","clk":"11927946259","pt":1724245710623,"mc":[{"id":"1.232048948","rc":[{"batb":[[0,1.97,10],[1,1.96,6.2],[2,1.48,18.79]],"ltp":2.08,"tv":53.13,"id":67083366}]}]}
{"op":"mcm","clk":"11927946540","pt":1724245714227,"mc":[{"id":"1.232048948","rc":[{"batb":[[0,1.97,4]],"ltp":2.08,"tv":53.13,"id":67083366}]}]}
{"op":"mcm","clk":"11927946725","pt":1724245717124,"mc":[{"id":"1.232048948","rc":[{"batb":[[0,1.97,10]],"ltp":2.08,"tv":53.13,"id":67083366}]}]}
{"op":"mcm","clk":"11927946971","pt":1724245720741,"mc":[{"id":"1.232048948","rc":[{"batb":[[0,1.97,4]],"ltp":2.08,"tv":53.13,"id":67083366}]}]}
{"op":"mcm","clk":"11927947156","pt":1724245723250,"mc":[{"id":"1.232048948","rc":[{"batb":[[0,1.96,6.2],[1,1.48,18.79],[2,1.45,5.15]],"ltp":2.08,"tv":53.13,"id":67083366}]}]}
{"op":"mcm","clk":"11927947180","pt":1724245723554,"mc":[{"id":"1.232048948","rc":[{"batb":[[0,1.97,10],[1,1.96,6.2],[2,1.48,18.79]],"ltp":2.08,"tv":53.13,"id":67083366}]}]}
{"op":"mcm","clk":"11927947422","pt":1724245727027,"mc":[{"id":"1.232048948","rc":[{"batb":[[0,1.97,4]],"ltp":2.08,"tv":53.13,"id":67083366}]}]}
{"op":"mcm","clk":"11927947577","pt":1724245729849,"mc":[{"id":"1.232048948","rc":[{"batb":[[0,1.97,10]],"ltp":2.08,"tv":53.13,"id":67083366}]}]}
{"op":"mcm","clk":"11927947833","pt":1724245733553,"mc":[{"id":"1.232048948","rc":[{"batb":[[0,1.97,4]],"ltp":2.08,"tv":53.13,"id":67083366}]}]}
{"op":"mcm","clk":"11927948017","pt":1724245735864,"mc":[{"id":"1.232048948","rc":[{"batb":[[0,1.96,6.2],[1,1.48,18.79],[2,1.45,5.15]],"ltp":2.08,"tv":53.13,"id":67083366}]}]}
{"op":"mcm","clk":"11927948453","pt":1724245741854,"mc":[{"id":"1.232048948","rc":[{"batb":[[0,1.97,14],[1,1.96,6.2],[2,1.48,18.79]],"ltp":2.08,"tv":53.13,"id":67083366}]}]}
{"op":"mcm","clk":"11927949054","pt":1724245750491,"mc":[{"id":"1.232048948","rc":[{"batb":[[0,1.97,10]],"ltp":2.08,"tv":53.13,"id":67083366}]}]}
{"op":"mcm","clk":"11927949151","pt":1724245751648,"mc":[{"id":"1.232048948","rc":[{"batb":[[0,1.96,6.2],[1,1.48,18.79],[2,1.45,5.15]],"ltp":2.08,"tv":53.13,"id":67083366}]}]}
{"op":"mcm","clk":"11927949250","pt":1724245752878,"mc":[{"id":"1.232048948","rc":[{"batb":[[0,1.98,4],[1,1.96,6.2],[2,1.48,18.79]],"ltp":2.08,"tv":53.13,"id":67083366}]}]}
{"op":"mcm","clk":"11927949384","pt":1724245754679,"mc":[{"id":"1.232048948","rc":[{"batb":[[0,1.98,14]],"ltp":2.08,"tv":53.13,"id":67083366}]}]}
{"op":"mcm","clk":"11927949679","pt":1724245759269,"mc":[{"id":"1.232048948","rc":[{"batb":[[0,1.98,10]],"ltp":2.08,"tv":53.13,"id":67083366}]}]}
{"op":"mcm","clk":"11927949879","pt":1724245761960,"mc":[{"id":"1.232048948","rc":[{"batb":[[0,1.99,4]],"ltp":2.08,"tv":53.13,"id":67083366}]}]}
{"op":"mcm","clk":"11927950034","pt":1724245764076,"mc":[{"id":"1.232048948","rc":[{"batb":[[1,1.97,10],[2,1.96,6.2]],"ltp":2.08,"tv":53.13,"id":67083366}]}]}
{"op":"mcm","clk":"11927950167","pt":1724245766191,"mc":[{"id":"1.232048948","rc":[{"batb":[[0,1.97,10],[1,1.96,6.2],[2,1.48,18.79]],"ltp":2.08,"tv":53.13,"id":67083366}]}]}
{"op":"mcm","clk":"11927950476","pt":1724245770278,"mc":[{"id":"1.232048948","rc":[{"batb":[[0,1.97,4]],"ltp":2.08,"tv":53.13,"id":67083366}]}]}
{"op":"mcm","clk":"11927950699","pt":1724245773214,"mc":[{"id":"1.232048948","rc":[{"batb":[[0,1.97,10]],"ltp":2.08,"tv":53.13,"id":67083366}]}]}
{"op":"mcm","clk":"11927950838","pt":1724245775588,"mc":[{"id":"1.232048948","rc":[{"batb":[[0,1.98,4],[1,1.97,10],[2,1.96,6.2]],"ltp":2.08,"tv":53.13,"id":67083366}]}]}
{"op":"mcm","clk":"11927950900","pt":1724245776611,"mc":[{"id":"1.232048948","rc":[{"batb":[[1,1.96,6.2],[2,1.48,18.79]],"ltp":2.08,"tv":53.13,"id":67083366}]}]}
{"op":"mcm","clk":"11927951017","pt":1724245778311,"mc":[{"id":"1.232048948","rc":[{"batb":[[0,1.96,6.2],[1,1.48,18.79],[2,1.45,5.15]],"ltp":2.08,"tv":53.13,"id":67083366}]}]}
{"op":"mcm","clk":"11927951243","pt":1724245781912,"mc":[{"id":"1.232048948","rc":[{"batb":[[0,1.97,14],[1,1.96,6.2],[2,1.48,18.79]],"ltp":2.08,"tv":53.13,"id":67083366}]}]}
{"op":"mcm","clk":"11927951396","pt":1724245784591,"mc":[{"id":"1.232048948","rc":[{"batb":[[0,1.97,10]],"ltp":2.08,"tv":53.13,"id":67083366}]}]}
{"op":"mcm","clk":"11927951460","pt":1724245785615,"mc":[{"id":"1.232048948","rc":[{"batb":[[0,1.96,6.2],[1,1.48,18.79],[2,1.45,5.15]],"ltp":2.08,"tv":53.13,"id":67083366}]}]}
{"op":"mcm","clk":"11927951667","pt":1724245788204,"mc":[{"id":"1.232048948","rc":[{"batb":[[0,1.98,10],[1,1.97,4],[2,1.96,6.2]],"ltp":2.08,"tv":53.13,"id":67083366}]}]}
{"op":"mcm","clk":"11927951835","pt":1724245790310,"mc":[{"id":"1.232048948","rc":[{"batb":[[1,1.96,6.2],[2,1.48,18.79]],"ltp":2.08,"tv":53.13,"id":67083366}]}]}
{"op":"mcm","clk":"11927951928","pt":1724245791816,"mc":[{"id":"1.232048948","rc":[{"batb":[[0,1.96,6.2],[1,1.48,18.79],[2,1.45,5.15]],"ltp":2.08,"tv":53.13,"id":67083366}]}]}
{"op":"mcm","clk":"11927952146","pt":1724245795111,"mc":[{"id":"1.232048948","rc":[{"batb":[[0,1.97,14],[1,1.96,6.2],[2,1.48,18.79]],"ltp":2.08,"tv":53.13,"id":67083366}]}]}
{"op":"mcm","clk":"11927952346","pt":1724245797931,"mc":[{"id":"1.232048948","rc":[{"batb":[[0,1.97,10]],"ltp":2.08,"tv":53.13,"id":67083366}]}]}
{"op":"mcm","clk":"11927952406","pt":1724245798812,"mc":[{"id":"1.232048948","rc":[{"batb":[[0,1.96,6.2],[1,1.48,18.79],[2,1.45,5.15]],"ltp":2.08,"tv":53.13,"id":67083366}]}]}
{"op":"mcm","clk":"11927952988","pt":1724245807142,"mc":[{"id":"1.232048948","rc":[{"batb":[[0,1.97,14],[1,1.96,6.2],[2,1.48,18.79]],"ltp":2.08,"tv":53.13,"id":67083366}]}]}
{"op":"mcm","clk":"11927953159","pt":1724245809634,"mc":[{"id":"1.232048948","rc":[{"batb":[[0,1.97,10]],"ltp":2.08,"tv":53.13,"id":67083366}]}]}
{"op":"mcm","clk":"11927953290","pt":1724245811440,"mc":[{"id":"1.232048948","rc":[{"batb":[[0,1.96,6.2],[1,1.48,18.79],[2,1.45,5.15]],"ltp":2.08,"tv":53.13,"id":67083366}]}]}
{"op":"mcm","clk":"11927953446","pt":1724245813243,"mc":[{"id":"1.232048948","rc":[{"batb":[[0,1.97,4],[1,1.96,6.2],[2,1.48,18.79]],"ltp":2.08,"tv":53.13,"id":67083366}]}]}
{"op":"mcm","clk":"11927953504","pt":1724245814335,"mc":[{"id":"1.232048948","rc":[{"batb":[[0,1.98,10],[1,1.97,4],[2,1.96,6.2]],"ltp":2.08,"tv":53.13,"id":67083366}]}]}
{"op":"mcm","clk":"11927953635","pt":1724245816443,"mc":[{"id":"1.232048948","rc":[{"batb":[[1,1.96,6.2],[2,1.48,18.79]],"ltp":2.08,"tv":53.13,"id":67083366}]}]}
{"op":"mcm","clk":"11927953753","pt":1724245818145,"mc":[{"id":"1.232048948","rc":[{"batb":[[0,1.96,6.2],[1,1.48,18.79],[2,1.45,5.15]],"ltp":2.08,"tv":53.13,"id":67083366}]}]}
{"op":"mcm","clk":"11927953828","pt":1724245819541,"mc":[{"id":"1.232048948","rc":[{"batb":[[0,1.97,4],[1,1.96,6.2],[2,1.48,18.79]],"ltp":2.08,"tv":53.13,"id":67083366}]}]}
{"op":"mcm","clk":"11927953864","pt":1724245820357,"mc":[{"id":"1.232048948","rc":[{"batb":[[0,1.98,10],[1,1.97,4],[2,1.96,6.2]],"ltp":2.08,"tv":53.13,"id":67083366}]}]}
{"op":"mcm","clk":"11927954054","pt":1724245822752,"mc":[{"id":"1.232048948","rc":[{"batb":[[1,1.96,6.2],[2,1.48,18.79]],"ltp":2.08,"tv":53.13,"id":67083366}]}]}
{"op":"mcm","clk":"11927954164","pt":1724245824148,"mc":[{"id":"1.232048948","rc":[{"batb":[[0,1.96,6.2],[1,1.48,18.79],[2,1.45,5.15]],"ltp":2.08,"tv":53.13,"id":67083366}]}]}
{"op":"mcm","clk":"11927954538","pt":1724245829681,"mc":[{"id":"1.232048948","rc":[{"batb":[[0,1.99,14],[1,1.96,6.2],[2,1.48,18.79]],"ltp":2.08,"tv":53.13,"id":67083366}]}]}
{"op":"mcm","clk":"11927955132","pt":1724245839575,"mc":[{"id":"1.232048948","rc":[{"batb":[[0,1.99,10]],"ltp":2.08,"tv":53.13,"id":67083366}]}]}
{"op":"mcm","clk":"11927955209","pt":1724245840671,"mc":[{"id":"1.232048948","rc":[{"batb":[[0,1.96,6.2],[1,1.48,18.79],[2,1.45,5.15]],"ltp":2.08,"tv":53.13,"id":67083366}]}]}
{"op":"mcm","clk":"11927955466","pt":1724245844498,"mc":[{"id":"1.232048948","rc":[{"batb":[[0,2,14],[1,1.96,6.2],[2,1.48,18.79]],"ltp":2.08,"tv":53.13,"id":67083366}]}]}
{"op":"mcm","clk":"11927955844","pt":1724245849789,"mc":[{"id":"1.232048948","rc":[{"batb":[[0,2,10]],"ltp":2.08,"tv":53.13,"id":67083366}]}]}
{"op":"mcm","clk":"11927955923","pt":1724245850890,"mc":[{"id":"1.232048948","rc":[{"batb":[[0,1.96,6.2],[1,1.48,18.79],[2,1.45,5.15]],"ltp":2.08,"tv":53.13,"id":67083366}]}]}
{"op":"mcm","clk":"11927956014","pt":1724245852098,"mc":[{"id":"1.232048948","rc":[{"batb":[[0,1.97,4],[1,1.96,6.2],[2,1.48,18.79]],"ltp":2.08,"tv":53.13,"id":67083366}]}]}
{"op":"mcm","clk":"11927956162","pt":1724245854109,"mc":[{"id":"1.232048948","rc":[{"batb":[[0,1.98,10],[1,1.97,4],[2,1.96,6.2]],"ltp":2.08,"tv":53.13,"id":67083366}]}]}
{"op":"mcm","clk":"11927956213","pt":1724245854895,"mc":[{"id":"1.232048948","rc":[{"batb":[[1,1.96,6.2],[2,1.48,18.79]],"ltp":2.08,"tv":53.13,"id":67083366}]}]}
{"op":"mcm","clk":"11927956444","pt":1724245858178,"mc":[{"id":"1.232048948","rc":[{"batb":[[0,1.97,4]],"ltp":2.08,"tv":53.13,"id":67083366}]}]}
{"op":"mcm","clk":"11927956585","pt":1724245860099,"mc":[{"id":"1.232048948","rc":[{"batb":[[0,1.98,10],[1,1.97,4],[2,1.96,6.2]],"ltp":2.08,"tv":53.13,"id":67083366}]}]}
{"op":"mcm","clk":"11927956619","pt":1724245860610,"mc":[{"id":"1.232048948","rc":[{"batb":[[1,1.96,6.2],[2,1.48,18.79]],"ltp":2.08,"tv":53.13,"id":67083366}]}]}
{"op":"mcm","clk":"11927956871","pt":1724245864218,"mc":[{"id":"1.232048948","rc":[{"batb":[[0,1.97,4]],"ltp":2.08,"tv":53.13,"id":67083366}]}]}
{"op":"mcm","clk":"11927957063","pt":1724245866684,"mc":[{"id":"1.232048948","rc":[{"batb":[[0,1.96,6.2],[1,1.48,18.79],[2,1.45,5.15]],"ltp":2.08,"tv":53.13,"id":67083366}]}]}
{"op":"mcm","clk":"11927957184","pt":1724245868205,"mc":[{"id":"1.232048948","rc":[{"batb":[[0,1.97,10],[1,1.96,6.2],[2,1.48,18.79]],"ltp":2.08,"tv":53.13,"id":67083366}]}]}
{"op":"mcm","clk":"11927957243","pt":1724245869004,"mc":[{"id":"1.232048948","rc":[{"batb":[[0,1.97,14]],"ltp":2.08,"tv":53.13,"id":67083366}]}]}
{"op":"mcm","clk":"11927957499","pt":1724245872928,"mc":[{"id":"1.232048948","rc":[{"batb":[[0,1.96,6.2],[1,1.48,18.79],[2,1.45,5.15]],"ltp":2.08,"tv":53.13,"id":67083366}]}]}
{"op":"mcm","clk":"11927957738","pt":1724245876547,"mc":[{"id":"1.232048948","rc":[{"batb":[[0,1.97,14],[1,1.96,6.2],[2,1.48,18.79]],"ltp":2.08,"tv":53.13,"id":67083366}]}]}
{"op":"mcm","clk":"11927957873","pt":1724245879145,"mc":[{"id":"1.232048948","rc":[{"batb":[[0,1.97,10]],"ltp":2.08,"tv":53.13,"id":67083366}]}]}
{"op":"mcm","clk":"11927957949","pt":1724245879930,"mc":[{"id":"1.232048948","rc":[{"batb":[[0,1.96,6.2],[1,1.48,18.79],[2,1.45,5.15]],"ltp":2.08,"tv":53.13,"id":67083366}]}]}
{"op":"mcm","clk":"11927958360","pt":1724245886220,"mc":[{"id":"1.232048948","rc":[{"batb":[[0,1.97,14],[1,1.96,6.2],[2,1.48,18.79]],"ltp":2.08,"tv":53.13,"id":67083366}]}]}
{"op":"mcm","clk":"11927958522","pt":1724245888943,"mc":[{"id":"1.232048948","rc":[{"batb":[[0,1.97,10]],"ltp":2.08,"tv":53.13,"id":67083366}]}]}
{"op":"mcm","clk":"11927958582","pt":1724245889928,"mc":[{"id":"1.232048948","rc":[{"batb":[[0,1.96,6.2],[1,1.48,18.79],[2,1.45,5.15]],"ltp":2.08,"tv":53.13,"id":67083366}]}]}
{"op":"mcm","clk":"11927958740","pt":1724245892136,"mc":[{"id":"1.232048948","rc":[{"batb":[[0,1.98,10],[1,1.97,4],[2,1.96,6.2]],"ltp":2.08,"tv":53.13,"id":67083366}]}]}
{"op":"mcm","clk":"11927958882","pt":1724245894237,"mc":[{"id":"1.232048948","rc":[{"batb":[[1,1.96,6.2],[2,1.48,18.79]],"ltp":2.08,"tv":53.13,"id":67083366}]}]}
{"op":"mcm","clk":"11927959011","pt":1724245896235,"mc":[{"id":"1.232048948","rc":[{"batb":[[0,1.96,6.2],[1,1.48,18.79],[2,1.45,5.15]],"ltp":2.08,"tv":53.13,"id":67083366}]}]}
{"op":"mcm","clk":"11927959027","pt":1724245896441,"mc":[{"id":"1.232048948","rc":[{"batb":[[0,1.97,4],[1,1.96,6.2],[2,1.48,18.79]],"ltp":2.08,"tv":53.13,"id":67083366}]}]}
{"op":"mcm","clk":"11927959190","pt":1724245898747,"mc":[{"id":"1.232048948","rc":[{"batb":[[0,1.96,6.2],[1,1.48,18.79],[2,1.45,5.15]],"ltp":2.08,"tv":53.13,"id":67083366}]}]}
{"op":"mcm","clk":"11927959232","pt":1724245899426,"mc":[{"id":"1.232048948","rc":[{"batb":[[0,1.97,10],[1,1.96,6.2],[2,1.48,18.79]],"ltp":2.08,"tv":53.13,"id":67083366}]}]}
{"op":"mcm","clk":"11927959513","pt":1724245903024,"mc":[{"id":"1.232048948","rc":[{"batb":[[0,1.97,4]],"ltp":2.08,"tv":53.13,"id":67083366}]}]}
{"op":"mcm","clk":"11927959737","pt":1724245906051,"mc":[{"id":"1.232048948","rc":[{"batb":[[0,1.97,10]],"ltp":2.08,"tv":53.13,"id":67083366}]}]}
{"op":"mcm","clk":"11927960014","pt":1724245909240,"mc":[{"id":"1.232048948","rc":[{"batb":[[0,1.98,4],[1,1.97,10],[2,1.96,6.2]],"ltp":2.08,"tv":53.13,"id":67083366}]}]}
{"op":"mcm","clk":"11927960043","pt":1724245909555,"mc":[{"id":"1.232048948","rc":[{"batb":[[1,1.96,6.2],[2,1.48,18.79]],"ltp":2.08,"tv":53.13,"id":67083366}]}]}
{"op":"mcm","clk":"11927960200","pt":1724245912061,"mc":[{"id":"1.232048948","rc":[{"batb":[[0,1.97,10]],"ltp":2.08,"tv":53.13,"id":67083366}]}]}
{"op":"mcm","clk":"11927960490","pt":1724245915971,"mc":[{"id":"1.232048948","rc":[{"batb":[[0,1.97,4]],"ltp":2.08,"tv":53.13,"id":67083366}]}]}
{"op":"mcm","clk":"11927960680","pt":1724245918258,"mc":[{"id":"1.232048948","rc":[{"batb":[[0,1.96,6.2],[1,1.48,18.79],[2,1.45,5.15]],"ltp":2.08,"tv":53.13,"id":67083366}]}]}
{"op":"mcm","clk":"11927960714","pt":1724245918766,"mc":[{"id":"1.232048948","rc":[{"batb":[[0,1.97,10],[1,1.96,6.2],[2,1.48,18.79]],"ltp":2.08,"tv":53.13,"id":67083366}]}]}
{"op":"mcm","clk":"11927961016","pt":1724245922671,"mc":[{"id":"1.232048948","rc":[{"batb":[[0,1.98,4]],"ltp":2.08,"tv":53.13,"id":67083366}]}]}
{"op":"mcm","clk":"11927961308","pt":1724245926172,"mc":[{"id":"1.232048948","rc":[{"batb":[[0,1.97,10]],"ltp":2.08,"tv":53.13,"id":67083366}]}]}
{"op":"mcm","clk":"11927961492","pt":1724245928453,"mc":[{"id":"1.232048948","rc":[{"batb":[[0,1.98,4],[1,1.97,10],[2,1.96,6.2]],"ltp":2.08,"tv":53.13,"id":67083366}]}]}
{"op":"mcm","clk":"11927961595","pt":1724245929880,"mc":[{"id":"1.232048948","rc":[{"batb":[[1,1.96,6.2],[2,1.48,18.79]],"ltp":2.08,"tv":53.13,"id":67083366}]}]}
{"op":"mcm","clk":"11927961806","pt":1724245932257,"mc":[{"id":"1.232048948","rc":[{"batb":[[0,1.97,10]],"ltp":2.08,"tv":53.13,"id":67083366}]}]}
{"op":"mcm","clk":"11927962092","pt":1724245935664,"mc":[{"id":"1.232048948","rc":[{"batb":[[0,1.98,4]],"ltp":2.08,"tv":53.13,"id":67083366}]}]}
{"op":"mcm","clk":"11927962289","pt":1724245937989,"mc":[{"id":"1.232048948","rc":[{"batb":[[0,1.96,6.2],[1,1.48,18.79],[2,1.45,5.15]],"ltp":2.08,"tv":53.13,"id":67083366}]}]}
{"op":"mcm","clk":"11927962317","pt":1724245938404,"mc":[{"id":"1.232048948","rc":[{"batb":[[0,1.97,10],[1,1.96,6.2],[2,1.48,18.79]],"ltp":2.08,"tv":53.13,"id":67083366}]}]}
{"op":"mcm","clk":"11927962594","pt":1724245941978,"mc":[{"id":"1.232048948","rc":[{"batb":[[0,1.98,4]],"ltp":2.08,"tv":53.13,"id":67083366}]}]}
{"op":"mcm","clk":"11927962774","pt":1724245944202,"mc":[{"id":"1.232048948","rc":[{"batb":[[0,1.97,10]],"ltp":2.08,"tv":53.13,"id":67083366}]}]}
{"op":"mcm","clk":"11927962966","pt":1724245946188,"mc":[{"id":"1.232048948","rc":[{"batb":[[0,1.98,4],[1,1.97,10],[2,1.96,6.2]],"ltp":2.08,"tv":53.13,"id":67083366}]}]}
{"op":"mcm","clk":"11927963145","pt":1724245947998,"mc":[{"id":"1.232048948","rc":[{"batb":[[1,1.96,6.2],[2,1.48,18.79]],"ltp":2.08,"tv":53.13,"id":67083366}]}]}
{"op":"mcm","clk":"11927963213","pt":1724245948784,"mc":[{"id":"1.232048948","rc":[{"batb":[[0,1.96,6.2],[1,1.48,18.79],[2,1.45,5.15]],"ltp":2.08,"tv":53.13,"id":67083366}]}]}
{"op":"mcm","clk":"11927963546","pt":1724245953290,"mc":[{"id":"1.232048948","rc":[{"batb":[[0,1.97,14],[1,1.96,6.2],[2,1.48,18.79]],"ltp":2.08,"tv":53.13,"id":67083366}]}]}
{"op":"mcm","clk":"11927963741","pt":1724245956011,"mc":[{"id":"1.232048948","rc":[{"batb":[[0,1.97,10]],"ltp":2.08,"tv":53.13,"id":67083366}]}]}
{"op":"mcm","clk":"11927963830","pt":1724245957000,"mc":[{"id":"1.232048948","rc":[{"batb":[[0,1.96,6.2],[1,1.48,18.79],[2,1.45,5.15]],"ltp":2.08,"tv":53.13,"id":67083366}]}]}
{"op":"mcm","clk":"11927964103","pt":1724245960607,"mc":[{"id":"1.232048948","rc":[{"batb":[[0,1.97,14],[1,1.96,6.2],[2,1.48,18.79]],"ltp":2.08,"tv":53.13,"id":67083366}]}]}
{"op":"mcm","clk":"11927964416","pt":1724245964019,"mc":[{"id":"1.232048948","rc":[{"batb":[[0,1.97,10]],"ltp":2.08,"tv":53.13,"id":67083366}]}]}
{"op":"mcm","clk":"11927964474","pt":1724245964803,"mc":[{"id":"1.232048948","rc":[{"batb":[[0,1.96,6.2],[1,1.48,18.79],[2,1.45,5.15]],"ltp":2.08,"tv":53.13,"id":67083366}]}]}
{"op":"mcm","clk":"11927964927","pt":1724245970432,"mc":[{"id":"1.232048948","rc":[{"batb":[[0,1.98,14],[1,1.96,6.2],[2,1.48,18.79]],"ltp":2.08,"tv":53.13,"id":67083366}]}]}
{"op":"mcm","clk":"11927965711","pt":1724245979738,"mc":[{"id":"1.232048948","rc":[{"batb":[[0,1.98,10]],"ltp":2.08,"tv":53.13,"id":67083366}]}]}
{"op":"mcm","clk":"11927965807","pt":1724245980773,"mc":[{"id":"1.232048948","rc":[{"batb":[[0,1.96,6.2],[1,1.48,18.79],[2,1.45,5.15]],"ltp":2.08,"tv":53.13,"id":67083366}]}]}
{"op":"mcm","clk":"11927966029","pt":1724245983256,"mc":[{"id":"1.232048948","rc":[{"batb":[[0,1.99,14],[1,1.96,6.2],[2,1.48,18.79]],"ltp":2.08,"tv":53.13,"id":67083366}]}]}
{"op":"mcm","clk":"11927966366","pt":1724245987738,"mc":[{"id":"1.232048948","rc":[{"batb":[[0,1.99,10]],"ltp":2.08,"tv":53.13,"id":67083366}]}]}
{"op":"mcm","clk":"11927966446","pt":1724245988767,"mc":[{"id":"1.232048948","rc":[{"batb":[[0,1.96,6.2],[1,1.48,18.79],[2,1.45,5.15]],"ltp":2.08,"tv":53.13,"id":67083366}]}]}
{"op":"mcm","clk":"11927966546","pt":1724245990065,"mc":[{"id":"1.232048948","rc":[{"batb":[[0,1.97,4],[1,1.96,6.2],[2,1.48,18.79]],"ltp":2.08,"tv":53.13,"id":67083366}]}]}
{"op":"mcm","clk":"11927966650","pt":1724245991456,"mc":[{"id":"1.232048948","rc":[{"batb":[[0,1.98,10],[1,1.97,4],[2,1.96,6.2]],"ltp":2.08,"tv":53.13,"id":67083366}]}]}
{"op":"mcm","clk":"11927966786","pt":1724245993464,"mc":[{"id":"1.232048948","rc":[{"batb":[[1,1.96,6.2],[2,1.48,18.79]],"ltp":2.08,"tv":53.13,"id":67083366}]}]}
{"op":"mcm","clk":"11927966935","pt":1724245995638,"mc":[{"id":"1.232048948","rc":[{"batb":[[0,1.97,4]],"ltp":2.08,"tv":53.13,"id":67083366}]}]}
{"op":"mcm","clk":"11927967152","pt":1724245998259,"mc":[{"id":"1.232048948","rc":[{"batb":[[0,1.97,10]],"ltp":2.08,"tv":53.13,"id":67083366}]}]}
{"op":"mcm","clk":"11927967441","pt":1724246001769,"mc":[{"id":"1.232048948","rc":[{"batb":[[0,1.97,4]],"ltp":2.08,"tv":53.13,"id":67083366}]}]}
{"op":"mcm","clk":"11927967582","pt":1724246004045,"mc":[{"id":"1.232048948","rc":[{"batb":[[0,1.96,6.2],[1,1.48,18.79],[2,1.45,5.15]],"ltp":2.08,"tv":53.13,"id":67083366}]}]}
{"op":"mcm","clk":"11927967623","pt":1724246004757,"mc":[{"id":"1.232048948","rc":[{"batb":[[0,1.97,10],[1,1.96,6.2],[2,1.48,18.79]],"ltp":2.08,"tv":53.13,"id":67083366}]}]}
{"op":"mcm","clk":"11927967868","pt":1724246008262,"mc":[{"id":"1.232048948","rc":[{"batb":[[0,1.96,6.2],[1,1.48,18.79],[2,1.45,5.15]],"ltp":2.08,"tv":53.13,"id":67083366}]}]}
{"op":"mcm","clk":"11927967884","pt":1724246008472,"mc":[{"id":"1.232048948","rc":[{"batb":[[0,1.97,4],[1,1.96,6.2],[2,1.48,18.79]],"ltp":2.08,"tv":53.13,"id":67083366}]}]}
{"op":"mcm","clk":"11927968072","pt":1724246011262,"mc":[{"id":"1.232048948","rc":[{"batb":[[0,1.97,10]],"ltp":2.08,"tv":53.13,"id":67083366}]}]}
{"op":"mcm","clk":"11927968276","pt":1724246014052,"mc":[{"id":"1.232048948","rc":[{"batb":[[0,1.98,4],[1,1.97,10],[2,1.96,6.2]],"ltp":2.08,"tv":53.13,"id":67083366}]}]}
{"op":"mcm","clk":"11927968331","pt":1724246014854,"mc":[{"id":"1.232048948","rc":[{"batb":[[1,1.96,6.2],[2,1.48,18.79]],"ltp":2.08,"tv":53.13,"id":67083366}]}]}
{"op":"mcm","clk":"11927968442","pt":1724246016550,"mc":[{"id":"1.232048948","rc":[{"batb":[[0,1.96,6.2],[1,1.48,18.79],[2,1.45,5.15]],"ltp":2.08,"tv":53.13,"id":67083366}]}]}
{"op":"mcm","clk":"11927968504","pt":1724246017368,"mc":[{"id":"1.232048948","rc":[{"batb":[[0,1.97,10],[1,1.96,6.2],[2,1.48,18.79]],"ltp":2.08,"tv":53.13,"id":67083366}]}]}
{"op":"mcm","clk":"11927968740","pt":1724246021279,"mc":[{"id":"1.232048948","rc":[{"batb":[[0,1.97,4]],"ltp":2.08,"tv":53.13,"id":67083366}]}]}
{"op":"mcm","clk":"11927968892","pt":1724246023589,"mc":[{"id":"1.232048948","rc":[{"batb":[[0,1.97,10]],"ltp":2.08,"tv":53.13,"id":67083366}]}]}
{"op":"mcm","clk":"11927969137","pt":1724246027073,"mc":[{"id":"1.232048948","rc":[{"batb":[[0,1.97,4]],"ltp":2.08,"tv":53.13,"id":67083366}]}]}
{"op":"mcm","clk":"11927969329","pt":1724246029867,"mc":[{"id":"1.232048948","rc":[{"batb":[[0,1.97,10]],"ltp":2.08,"tv":53.13,"id":67083366}]}]}
{"op":"mcm","clk":"11927969564","pt":1724246033004,"mc":[{"id":"1.232048948","rc":[{"batb":[[0,1.98,4],[1,1.97,10],[2,1.96,6.2]],"ltp":2.08,"tv":53.13,"id":67083366}]}]}
{"op":"mcm","clk":"11927969586","pt":1724246033370,"mc":[{"id":"1.232048948","rc":[{"batb":[[1,1.96,6.2],[2,1.48,18.79]],"ltp":2.08,"tv":53.13,"id":67083366}]}]}
{"op":"mcm","clk":"11927969759","pt":1724246035786,"mc":[{"id":"1.232048948","rc":[{"batb":[[0,1.97,10]],"ltp":2.08,"tv":53.13,"id":67083366}]}]}
{"op":"mcm","clk":"11927969996","pt":1724246039297,"mc":[{"id":"1.232048948","rc":[{"batb":[[0,1.97,4]],"ltp":2.08,"tv":53.13,"id":67083366}]}]}
{"op":"mcm","clk":"11927970174","pt":1724246041588,"mc":[{"id":"1.232048948","rc":[{"batb":[[0,1.98,10]],"ltp":2.08,"tv":53.13,"id":67083366}]}]}
{"op":"mcm","clk":"11927970340","pt":1724246043813,"mc":[{"id":"1.232048948","rc":[{"batb":[[0,1.99,4],[1,1.98,10],[2,1.96,6.2]],"ltp":2.08,"tv":53.13,"id":67083366}]}]}
{"op":"mcm","clk":"11927970421","pt":1724246044690,"mc":[{"id":"1.232048948","rc":[{"batb":[[1,1.96,6.2],[2,1.48,18.79]],"ltp":2.08,"tv":53.13,"id":67083366}]}]}
{"op":"mcm","clk":"11927970573","pt":1724246047007,"mc":[{"id":"1.232048948","rc":[{"batb":[[0,1.97,10]],"ltp":2.08,"tv":53.13,"id":67083366}]}]}
{"op":"mcm","clk":"11927970715","pt":1724246049186,"mc":[{"id":"1.232048948","rc":[{"batb":[[0,1.98,4],[1,1.97,10],[2,1.96,6.2]],"ltp":2.08,"tv":53.13,"id":67083366}]}]}
{"op":"mcm","clk":"11927970786","pt":1724246050719,"mc":[{"id":"1.232048948","rc":[{"batb":[[1,1.96,6.2],[2,1.48,18.79]],"ltp":2.08,"tv":53.13,"id":67083366}]}]}
{"op":"mcm","clk":"11927970867","pt":1724246052318,"mc":[{"id":"1.232048948","rc":[{"batb":[[0,1.96,6.2],[1,1.48,18.79],[2,1.45,5.15]],"ltp":2.08,"tv":53.13,"id":67083366}]}]}
{"op":"mcm","clk":"11927970907","pt":1724246052925,"mc":[{"id":"1.232048948","rc":[{"batb":[[0,1.97,10],[1,1.96,6.2],[2,1.48,18.79]],"ltp":2.08,"tv":53.13,"id":67083366}]}]}
{"op":"mcm","clk":"11927971129","pt":1724246056694,"mc":[{"id":"1.232048948","rc":[{"batb":[[0,1.97,4]],"ltp":2.08,"tv":53.13,"id":67083366}]}]}
{"op":"mcm","clk":"11927971308","pt":1724246059308,"mc":[{"id":"1.232048948","rc":[{"batb":[[0,1.97,10]],"ltp":2.08,"tv":53.13,"id":67083366}]}]}
{"op":"mcm","clk":"11927971550","pt":1724246062700,"mc":[{"id":"1.232048948","rc":[{"batb":[[0,1.98,4]],"ltp":2.08,"tv":53.13,"id":67083366}]}]}
{"op":"mcm","clk":"11927971670","pt":1724246064903,"mc":[{"id":"1.232048948","rc":[{"batb":[[0,1.96,6.2],[1,1.48,18.79],[2,1.45,5.15]],"ltp":2.08,"tv":53.13,"id":67083366}]}]}
{"op":"mcm","clk":"11927971697","pt":1724246065425,"mc":[{"id":"1.232048948","rc":[{"batb":[[0,1.97,10],[1,1.96,6.2],[2,1.48,18.79]],"ltp":2.08,"tv":53.13,"id":67083366}]}]}
{"op":"mcm","clk":"11927971932","pt":1724246069320,"mc":[{"id":"1.232048948","rc":[{"batb":[[0,1.97,4]],"ltp":2.08,"tv":53.13,"id":67083366}]}]}
{"op":"mcm","clk":"11927972084","pt":1724246071846,"mc":[{"id":"1.232048948","rc":[{"batb":[[0,1.97,10]],"ltp":2.08,"tv":53.13,"id":67083366}]}]}
{"op":"mcm","clk":"11927972257","pt":1724246075037,"mc":[{"id":"1.232048948","rc":[{"batb":[[0,1.98,4]],"ltp":2.08,"tv":53.13,"id":67083366}]}]}
{"op":"mcm","clk":"11927972386","pt":1724246077257,"mc":[{"id":"1.232048948","rc":[{"batb":[[0,1.97,10]],"ltp":2.08,"tv":53.13,"id":67083366}]}]}
{"op":"mcm","clk":"11927972652","pt":1724246081019,"mc":[{"id":"1.232048948","rc":[{"batb":[[0,1.97,4]],"ltp":2.08,"tv":53.13,"id":67083366}]}]}
{"op":"mcm","clk":"11927972812","pt":1724246083852,"mc":[{"id":"1.232048948","rc":[{"batb":[[0,1.97,10]],"ltp":2.08,"tv":53.13,"id":67083366}]}]}
{"op":"mcm","clk":"11927972944","pt":1724246086065,"mc":[{"id":"1.232048948","rc":[{"batb":[[0,1.98,4],[1,1.97,10],[2,1.96,6.2]],"ltp":2.08,"tv":53.13,"id":67083366}]}]}
{"op":"mcm","clk":"11927973010","pt":1724246087141,"mc":[{"id":"1.232048948","rc":[{"batb":[[1,1.96,6.2],[2,1.48,18.79]],"ltp":2.08,"tv":53.13,"id":67083366}]}]}
{"op":"mcm","clk":"11927973121","pt":1724246088731,"mc":[{"id":"1.232048948","rc":[{"batb":[[0,1.96,6.2],[1,1.48,18.79],[2,1.45,5.15]],"ltp":2.08,"tv":53.13,"id":67083366}]}]}
{"op":"mcm","clk":"11927973347","pt":1724246092080,"mc":[{"id":"1.232048948","rc":[{"batb":[[0,1.97,14],[1,1.96,6.2],[2,1.48,18.79]],"ltp":2.08,"tv":53.13,"id":67083366}]}]}
{"op":"mcm","clk":"11927973526","pt":1724246095066,"mc":[{"id":"1.232048948","rc":[{"batb":[[0,1.97,10]],"ltp":2.08,"tv":53.13,"id":67083366}]}]}
{"op":"mcm","clk":"11927973554","pt":1724246095479,"mc":[{"id":"1.232048948","rc":[{"batb":[[0,1.96,6.2],[1,1.48,18.79],[2,1.45,5.15]],"ltp":2.08,"tv":53.13,"id":67083366}]}]}
{"op":"mcm","clk":"11927974032","pt":1724246101011,"mc":[{"id":"1.232048948","rc":[{"batb":[[0,1.97,14],[1,1.96,6.2],[2,1.48,18.79]],"ltp":2.08,"tv":53.13,"id":67083366}]}]}
{"op":"mcm","clk":"11927974249","pt":1724246103672,"mc":[{"id":"1.232048948","rc":[{"batb":[[0,1.97,10]],"ltp":2.08,"tv":53.13,"id":67083366}]}]}
{"op":"mcm","clk":"11927974322","pt":1724246104758,"mc":[{"id":"1.232048948","rc":[{"batb":[[0,1.96,6.2],[1,1.48,18.79],[2,1.45,5.15]],"ltp":2.08,"tv":53.13,"id":67083366}]}]}
{"op":"mcm","clk":"11927974484","pt":1724246106488,"mc":[{"id":"1.232048948","rc":[{"batb":[[0,1.97,4],[1,1.96,6.2],[2,1.48,18.79]],"ltp":2.08,"tv":53.13,"id":67083366}]}]}
{"op":"mcm","clk":"11927974687","pt":1724246109188,"mc":[{"id":"1.232048948","rc":[{"batb":[[0,1.98,10]],"ltp":2.08,"tv":53.13,"id":67083366}]}]}
{"op":"mcm","clk":"11927974949","pt":1724246112183,"mc":[{"id":"1.232048948","rc":[{"batb":[[0,1.97,4]],"ltp":2.08,"tv":53.13,"id":67083366}]}]}
{"op":"mcm","clk":"11927975163","pt":1724246114684,"mc":[{"id":"1.232048948","rc":[{"batb":[[0,1.97,10]],"ltp":2.08,"tv":53.13,"id":67083366}]}]}
{"op":"mcm","clk":"11927975410","pt":1724246118005,"mc":[{"id":"1.232048948","rc":[{"batb":[[0,1.98,4]],"ltp":2.08,"tv":53.13,"id":67083366}]}]}
{"op":"mcm","clk":"11927975525","pt":1724246119703,"mc":[{"id":"1.232048948","rc":[{"batb":[[0,1.96,6.2],[1,1.48,18.79],[2,1.45,5.15]],"ltp":2.08,"tv":53.13,"id":67083366}]}]}
{"op":"mcm","clk":"11927975837","pt":1724246123680,"mc":[{"id":"1.232048948","rc":[{"batb":[[0,1.97,14],[1,1.96,6.2],[2,1.48,18.79]],"ltp":2.08,"tv":53.13,"id":67083366}]}]}
{"op":"mcm","clk":"11927976069","pt":1724246126683,"mc":[{"id":"1.232048948","rc":[{"batb":[[0,1.97,10]],"ltp":2.08,"tv":53.13,"id":67083366}]}]}
{"op":"mcm","clk":"11927976143","pt":1724246127646,"mc":[{"id":"1.232048948","rc":[{"batb":[[0,1.96,6.2],[1,1.48,18.79],[2,1.45,5.15]],"ltp":2.08,"tv":53.13,"id":67083366}]}]}
{"op":"mcm","clk":"11927976330","pt":1724246130296,"mc":[{"id":"1.232048948","rc":[{"batb":[[0,1.97,14],[1,1.96,6.2],[2,1.48,18.79]],"ltp":2.08,"tv":53.13,"id":67083366}]}]}
{"op":"mcm","clk":"11927976504","pt":1724246132715,"mc":[{"id":"1.232048948","rc":[{"batb":[[0,1.97,10]],"ltp":2.08,"tv":53.13,"id":67083366}]}]}
{"op":"mcm","clk":"11927976571","pt":1724246133599,"mc":[{"id":"1.232048948","rc":[{"batb":[[0,1.96,6.2],[1,1.48,18.79],[2,1.45,5.15]],"ltp":2.08,"tv":53.13,"id":67083366}]}]}
{"op":"mcm","clk":"11927976890","pt":1724246137626,"mc":[{"id":"1.232048948","rc":[{"batb":[[0,1.97,14],[1,1.96,6.2],[2,1.48,18.79]],"ltp":2.08,"tv":53.13,"id":67083366}]}]}
{"op":"mcm","clk":"11927977091","pt":1724246140321,"mc":[{"id":"1.232048948","rc":[{"batb":[[0,1.97,10]],"ltp":2.08,"tv":53.13,"id":67083366}]}]}
{"op":"mcm","clk":"11927977158","pt":1724246141203,"mc":[{"id":"1.232048948","rc":[{"batb":[[0,1.96,6.2],[1,1.48,18.79],[2,1.45,5.15]],"ltp":2.08,"tv":53.13,"id":67083366}]}]}
{"op":"mcm","clk":"11927977373","pt":1724246144232,"mc":[{"id":"1.232048948","rc":[{"batb":[[0,1.97,14],[1,1.96,6.2],[2,1.48,18.79]],"ltp":2.08,"tv":53.13,"id":67083366}]}]}
{"op":"mcm","clk":"11927977544","pt":1724246146836,"mc":[{"id":"1.232048948","rc":[{"batb":[[0,1.97,10]],"ltp":2.08,"tv":53.13,"id":67083366}]}]}
{"op":"mcm","clk":"11927977606","pt":1724246147705,"mc":[{"id":"1.232048948","rc":[{"batb":[[0,1.96,6.2],[1,1.48,18.79],[2,1.45,5.15]],"ltp":2.08,"tv":53.13,"id":67083366}]}]}
{"op":"mcm","clk":"11927977792","pt":1724246150023,"mc":[{"id":"1.232048948","rc":[{"batb":[[0,1.98,10],[1,1.97,4],[2,1.96,6.2]],"ltp":2.08,"tv":53.13,"id":67083366}]}]}
{"op":"mcm","clk":"11927977973","pt":1724246152336,"mc":[{"id":"1.232048948","rc":[{"batb":[[1,1.96,6.2],[2,1.48,18.79]],"ltp":2.08,"tv":53.13,"id":67083366}]}]}
{"op":"mcm","clk":"11927978074","pt":1724246153726,"mc":[{"id":"1.232048948","rc":[{"batb":[[0,1.96,6.2],[1,1.48,18.79],[2,1.45,5.15]],"ltp":2.08,"tv":53.13,"id":67083366}]}]}
{"op":"mcm","clk":"11927978262","pt":1724246156315,"mc":[{"id":"1.232048948","rc":[{"batb":[[0,1.97,14],[1,1.96,6.2],[2,1.48,18.79]],"ltp":2.08,"tv":53.13,"id":67083366}]}]}
{"op":"mcm","clk":"11927978436","pt":1724246158837,"mc":[{"id":"1.232048948","rc":[{"batb":[[0,1.97,10]],"ltp":2.08,"tv":53.13,"id":67083366}]}]}
{"op":"mcm","clk":"11927978510","pt":1724246159926,"mc":[{"id":"1.232048948","rc":[{"batb":[[0,1.96,6.2],[1,1.48,18.79],[2,1.45,5.15]],"ltp":2.08,"tv":53.13,"id":67083366}]}]}
{"op":"mcm","clk":"11927979089","pt":1724246169333,"mc":[{"id":"1.232048948","rc":[{"batb":[[0,1.97,14],[1,1.96,6.2],[2,1.48,18.79]],"ltp":2.08,"tv":53.13,"id":67083366}]}]}
{"op":"mcm","clk":"11927979229","pt":1724246172059,"mc":[{"id":"1.232048948","rc":[{"batb":[[0,1.97,10]],"ltp":2.08,"tv":53.13,"id":67083366}]}]}
{"op":"mcm","clk":"11927979295","pt":1724246172973,"mc":[{"id":"1.232048948","rc":[{"batb":[[0,1.96,6.2],[1,1.48,18.79],[2,1.45,5.15]],"ltp":2.08,"tv":53.13,"id":67083366}]}]}
{"op":"mcm","clk":"11927979469","pt":1724246175853,"mc":[{"id":"1.232048948","rc":[{"batb":[[0,1.97,14],[1,1.96,6.2],[2,1.48,18.79]],"ltp":2.08,"tv":53.13,"id":67083366}]}]}
{"op":"mcm","clk":"11927979638","pt":1724246178764,"mc":[{"id":"1.232048948","rc":[{"batb":[[0,1.97,10]],"ltp":2.08,"tv":53.13,"id":67083366}]}]}
{"op":"mcm","clk":"11927979692","pt":1724246179645,"mc":[{"id":"1.232048948","rc":[{"batb":[[0,1.96,6.2],[1,1.48,18.79],[2,1.45,5.15]],"ltp":2.08,"tv":53.13,"id":67083366}]}]}
{"op":"mcm","clk":"11927979907","pt":1724246183074,"mc":[{"id":"1.232048948","rc":[{"batb":[[0,1.97,14],[1,1.96,6.2],[2,1.48,18.79]],"ltp":2.08,"tv":53.13,"id":67083366}]}]}
{"op":"mcm","clk":"11927980043","pt":1724246185569,"mc":[{"id":"1.232048948","rc":[{"batb":[[0,1.97,10]],"ltp":2.08,"tv":53.13,"id":67083366}]}]}
{"op":"mcm","clk":"11927980109","pt":1724246186587,"mc":[{"id":"1.232048948","rc":[{"batb":[[0,1.96,6.2],[1,1.48,18.79],[2,1.45,5.15]],"ltp":2.08,"tv":53.13,"id":67083366}]}]}
{"op":"mcm","clk":"11927980272","pt":1724246189269,"mc":[{"id":"1.232048948","rc":[{"batb":[[0,1.97,14],[1,1.96,6.2],[2,1.48,18.79]],"ltp":2.08,"tv":53.13,"id":67083366}]}]}
{"op":"mcm","clk":"11927980447","pt":1724246191993,"mc":[{"id":"1.232048948","rc":[{"batb":[[0,1.97,10]],"ltp":2.08,"tv":53.13,"id":67083366}]}]}
{"op":"mcm","clk":"11927980503","pt":1724246192773,"mc":[{"id":"1.232048948","rc":[{"batb":[[0,1.96,6.2],[1,1.48,18.79],[2,1.45,5.15]],"ltp":2.08,"tv":53.13,"id":67083366}]}]}
{"op":"mcm","clk":"11927980689","pt":1724246195757,"mc":[{"id":"1.232048948","rc":[{"batb":[[0,1.97,14],[1,1.96,6.2],[2,1.48,18.79]],"ltp":2.08,"tv":53.13,"id":67083366}]}]}
{"op":"mcm","clk":"11927980847","pt":1724246198372,"mc":[{"id":"1.232048948","rc":[{"batb":[[0,1.97,10]],"ltp":2.08,"tv":53.13,"id":67083366}]}]}
{"op":"mcm","clk":"11927980919","pt":1724246199361,"mc":[{"id":"1.232048948","rc":[{"batb":[[0,1.96,6.2],[1,1.48,18.79],[2,1.45,5.15]],"ltp":2.08,"tv":53.13,"id":67083366}]}]}
{"op":"mcm","clk":"11927981331","pt":1724246205692,"mc":[{"id":"1.232048948","rc":[{"batb":[[0,1.97,14],[1,1.96,6.2],[2,1.48,18.79]],"ltp":2.08,"tv":53.13,"id":67083366}]}]}
{"op":"mcm","clk":"11927981477","pt":1724246208107,"mc":[{"id":"1.232048948","rc":[{"batb":[[0,1.97,10]],"ltp":2.08,"tv":53.13,"id":67083366}]}]}
{"op":"mcm","clk":"11927981534","pt":1724246208986,"mc":[{"id":"1.232048948","rc":[{"batb":[[0,1.96,6.2],[1,1.48,18.79],[2,1.45,5.15]],"ltp":2.08,"tv":53.13,"id":67083366}]}]}
{"op":"mcm","clk":"11927981687","pt":1724246211184,"mc":[{"id":"1.232048948","rc":[{"batb":[[0,1.97,14],[1,1.96,6.2],[2,1.48,18.79]],"ltp":2.08,"tv":53.13,"id":67083366}]}]}
{"op":"mcm","clk":"11927981864","pt":1724246214116,"mc":[{"id":"1.232048948","rc":[{"batb":[[0,1.97,10]],"ltp":2.08,"tv":53.13,"id":67083366}]}]}
{"op":"mcm","clk":"11927981927","pt":1724246215104,"mc":[{"id":"1.232048948","rc":[{"batb":[[0,1.96,6.2],[1,1.48,18.79],[2,1.45,5.15]],"ltp":2.08,"tv":53.13,"id":67083366}]}]}
{"op":"mcm","clk":"11927982343","pt":1724246221999,"mc":[{"id":"1.232048948","rc":[{"batb":[[0,1.97,14],[1,1.96,6.2],[2,1.48,18.79]],"ltp":2.08,"tv":53.13,"id":67083366}]}]}
{"op":"mcm","clk":"11927982523","pt":1724246224521,"mc":[{"id":"1.232048948","rc":[{"batb":[[0,1.97,10]],"ltp":2.08,"tv":53.13,"id":67083366}]}]}
{"op":"mcm","clk":"11927982597","pt":1724246225605,"mc":[{"id":"1.232048948","rc":[{"batb":[[0,1.96,6.2],[1,1.48,18.79],[2,1.45,5.15]],"ltp":2.08,"tv":53.13,"id":67083366}]}]}
{"op":"mcm","clk":"11927982704","pt":1724246227096,"mc":[{"id":"1.232048948","rc":[{"batb":[[0,1.97,4],[1,1.96,6.2],[2,1.48,18.79]],"ltp":2.08,"tv":53.13,"id":67083366}]}]}
{"op":"mcm","clk":"11927982854","pt":1724246229517,"mc":[{"id":"1.232048948","rc":[{"batb":[[0,1.98,10]],"ltp":2.08,"tv":53.13,"id":67083366}]}]}
{"op":"mcm","clk":"11927983072","pt":1724246233313,"mc":[{"id":"1.232048948","rc":[{"batb":[[0,1.97,4]],"ltp":2.08,"tv":53.13,"id":67083366}]}]}
{"op":"mcm","clk":"11927983227","pt":1724246235839,"mc":[{"id":"1.232048948","rc":[{"batb":[[0,1.98,10]],"ltp":2.08,"tv":53.13,"id":67083366}]}]}
{"op":"mcm","clk":"11927983462","pt":1724246239816,"mc":[{"id":"1.232048948","rc":[{"batb":[[0,1.97,4]],"ltp":2.08,"tv":53.13,"id":67083366}]}]}
{"op":"mcm","clk":"11927983622","pt":1724246242133,"mc":[{"id":"1.232048948","rc":[{"batb":[[0,1.96,6.2],[1,1.48,18.79],[2,1.45,5.15]],"ltp":2.08,"tv":53.13,"id":67083366}]}]}
{"op":"mcm","clk":"11927983654","pt":1724246242544,"mc":[{"id":"1.232048948","rc":[{"batb":[[0,1.97,10],[1,1.96,6.2],[2,1.48,18.79]],"ltp":2.08,"tv":53.13,"id":67083366}]}]}
{"op":"mcm","clk":"11927983898","pt":1724246246156,"mc":[{"id":"1.232048948","rc":[{"batb":[[0,1.97,4]],"ltp":2.08,"tv":53.13,"id":67083366}]}]}
{"op":"mcm","clk":"11927984077","pt":1724246248938,"mc":[{"id":"1.232048948","rc":[{"batb":[[0,1.97,10]],"ltp":2.08,"tv":53.13,"id":67083366}]}]}
{"op":"mcm","clk":"11927984319","pt":1724246252858,"mc":[{"id":"1.232048948","rc":[{"batb":[[0,1.97,4]],"ltp":2.08,"tv":53.13,"id":67083366}]}]}
{"op":"mcm","clk":"11927984493","pt":1724246255238,"mc":[{"id":"1.232048948","rc":[{"batb":[[0,1.96,6.2],[1,1.48,18.79],[2,1.45,5.15]],"ltp":2.08,"tv":53.13,"id":67083366}]}]}
{"op":"mcm","clk":"11927984533","pt":1724246255753,"mc":[{"id":"1.232048948","rc":[{"batb":[[0,1.97,10],[1,1.96,6.2],[2,1.48,18.79]],"ltp":2.08,"tv":53.13,"id":67083366}]}]}
{"op":"mcm","clk":"11927984748","pt":1724246259043,"mc":[{"id":"1.232048948","rc":[{"batb":[[0,1.98,4],[1,1.97,10],[2,1.96,6.2]],"ltp":2.08,"tv":53.13,"id":67083366}]}]}
{"op":"mcm","clk":"11927984768","pt":1724246259355,"mc":[{"id":"1.232048948","rc":[{"batb":[[1,1.96,6.2],[2,1.48,18.79]],"ltp":2.08,"tv":53.13,"id":67083366}]}]}
{"op":"mcm","clk":"11927984896","pt":1724246261665,"mc":[{"id":"1.232048948","rc":[{"batb":[[0,1.97,10]],"ltp":2.08,"tv":53.13,"id":67083366}]}]}
{"op":"mcm","clk":"11927985127","pt":1724246265264,"mc":[{"id":"1.232048948","rc":[{"batb":[[0,1.96,6.2],[1,1.48,18.79],[2,1.45,5.15]],"ltp":2.08,"tv":53.13,"id":67083366}]}]}
{"op":"mcm","clk":"11927985147","pt":1724246265566,"mc":[{"id":"1.232048948","rc":[{"batb":[[0,1.97,4],[1,1.96,6.2],[2,1.48,18.79]],"ltp":2.08,"tv":53.13,"id":67083366}]}]}
{"op":"mcm","clk":"11927985286","pt":1724246268187,"mc":[{"id":"1.232048948","rc":[{"batb":[[0,1.98,10]],"ltp":2.08,"tv":53.13,"id":67083366}]}]}
{"op":"mcm","clk":"11927985497","pt":1724246272057,"mc":[{"id":"1.232048948","rc":[{"batb":[[0,1.97,4]],"ltp":2.08,"tv":53.13,"id":67083366}]}]}
{"op":"mcm","clk":"11927985645","pt":1724246274679,"mc":[{"id":"1.232048948","rc":[{"batb":[[0,1.97,10]],"ltp":2.08,"tv":53.13,"id":67083366}]}]}
{"op":"mcm","clk":"11927985902","pt":1724246278287,"mc":[{"id":"1.232048948","rc":[{"batb":[[0,1.97,4]],"ltp":2.08,"tv":53.13,"id":67083366}]}]}
{"op":"mcm","clk":"11927986074","pt":1724246281276,"mc":[{"id":"1.232048948","rc":[{"batb":[[0,1.97,10]],"ltp":2.08,"tv":53.13,"id":67083366}]}]}
{"op":"mcm","clk":"11927986297","pt":1724246285001,"mc":[{"id":"1.232048948","rc":[{"batb":[[0,1.98,4]],"ltp":2.08,"tv":53.13,"id":67083366}]}]}
{"op":"mcm","clk":"11927986517","pt":1724246287790,"mc":[{"id":"1.232048948","rc":[{"batb":[[0,1.97,10]],"ltp":2.08,"tv":53.13,"id":67083366}]}]}
{"op":"mcm","clk":"11927986797","pt":1724246291607,"mc":[{"id":"1.232048948","rc":[{"batb":[[0,1.97,4]],"ltp":2.08,"tv":53.13,"id":67083366}]}]}
{"op":"mcm","clk":"11927986977","pt":1724246294287,"mc":[{"id":"1.232048948","rc":[{"batb":[[0,1.97,10]],"ltp":2.08,"tv":53.13,"id":67083366}]}]}
{"op":"mcm","clk":"11927987246","pt":1724246298096,"mc":[{"id":"1.232048948","rc":[{"batb":[[0,1.97,4]],"ltp":2.08,"tv":53.13,"id":67083366}]}]}
{"op":"mcm","clk":"11927987399","pt":1724246300719,"mc":[{"id":"1.232048948","rc":[{"batb":[[0,1.97,10]],"ltp":2.08,"tv":53.13,"id":67083366}]}]}
{"op":"mcm","clk":"11927987636","pt":1724246304114,"mc":[{"id":"1.232048948","rc":[{"batb":[[0,1.96,6.2],[1,1.48,18.79],[2,1.45,5.15]],"ltp":2.08,"tv":53.13,"id":67083366}]}]}
{"op":"mcm","clk":"11927987656","pt":1724246304423,"mc":[{"id":"1.232048948","rc":[{"batb":[[0,1.97,4],[1,1.96,6.2],[2,1.48,18.79]],"ltp":2.08,"tv":53.13,"id":67083366}]}]}
{"op":"mcm","clk":"11927987834","pt":1724246306898,"mc":[{"id":"1.232048948","rc":[{"batb":[[0,1.98,10]],"ltp":2.08,"tv":53.13,"id":67083366}]}]}
{"op":"mcm","clk":"11927988047","pt":1724246310234,"mc":[{"id":"1.232048948","rc":[{"batb":[[0,1.96,6.2],[1,1.48,18.79],[2,1.45,5.15]],"ltp":2.08,"tv":53.13,"id":67083366}]}]}
{"op":"mcm","clk":"11927988073","pt":1724246310499,"mc":[{"id":"1.232048948","rc":[{"batb":[[0,1.97,4],[1,1.96,6.2],[2,1.48,18.79]],"ltp":2.08,"tv":53.13,"id":67083366}]}]}
