{"op":"mcm","clk":"11765912130","pt":1722594091904,"mc":[{"id":"1.231344826","marketDefinition":{"bspMarket":false,"turnInPlayEnabled":true,"persistenceEnabled":true,"marketBaseRate":5.0,"eventId":"33462739","eventTypeId":"4","numberOfWinners":1,"bettingType":"ODDS","marketType":"MATCH_ODDS","marketTime":"2024-08-04T10:00:00.000Z","suspendTime":"2024-08-04T10:00:00.000Z","bspReconciled":false,"complete":true,"inPlay":false,"crossMatching":false,"runnersVoidable":false,"numberOfActiveRunners":2,"betDelay":0,"status":"OPEN","runners":[{"status":"ACTIVE","sortPriority":1,"id":424676,"name":"Surrey"},{"status":"ACTIVE","sortPriority":2,"id":2780,"name":"Nottinghamshire"}],"regulators":["MR_INT"],"countryCode":"GB","discountAllowed":false,"timezone":"GMT","openDate":"2024-08-04T10:00:00.000Z","version":6051295021,"name":"Match Odds","eventName":"Surrey v Nottinghamshire"},"rc":[{"batb":[[0,1.03,200],[1,1.02,200],[2,1.01,220]],"ltp":0.0,"tv":0.0,"id":2780},{"batb":[[0,1.03,200],[1,1.02,200],[2,1.01,220]],"ltp":0.0,"tv":0.0,"id":424676}]}]}
{"op":"mcm","clk":"11765912175","pt":1722594093549,"mc":[{"id":"1.231344826","marketDefinition":{"bspMarket":false,"turnInPlayEnabled":true,"persistenceEnabled":true,"marketBaseRate":5.0,"eventId":"33462739","eventTypeId":"4","numberOfWinners":1,"bettingType":"ODDS","marketType":"MATCH_ODDS","marketTime":"2024-08-04T10:00:00.000Z","suspendTime":"2024-08-04T10:00:00.000Z","bspReconciled":false,"complete":true,"inPlay":false,"crossMatching":false,"runnersVoidable":false,"numberOfActiveRunners":2,"betDelay":0,"status":"OPEN","runners":[{"status":"ACTIVE","sortPriority":1,"id":424676,"name":"Surrey"},{"status":"ACTIVE","sortPriority":2,"id":2780,"name":"Nottinghamshire"}],"regulators":["MR_INT"],"countryCode":"GB","discountAllowed":true,"timezone":"GMT","openDate":"2024-08-04T10:00:00.000Z","version":6051295021,"name":"Match Odds","eventName":"Surrey v Nottinghamshire"}}]}
{"op":"mcm","clk":"11766122883","pt":1722599701903,"mc":[{"id":"1.231344826","rc":[{"batb":[[2,1.01,227.85]],"ltp":0.0,"tv":0.0,"id":2780},{"batb":[[2,1.01,227.85]],"ltp":0.0,"tv":0.0,"id":424676}]}]}
{"op":"mcm","clk":"11766123165","pt":1722599712344,"mc":[{"id":"1.231344826","rc":[{"batb":[[1,1.02,207.85]],"ltp":0.0,"tv":0.0,"id":2780},{"batb":[[1,1.02,207.85]],"ltp":0.0,"tv":0.0,"id":424676}]}]}
{"op":"mcm","clk":"11766123453","pt":1722599722956,"mc":[{"id":"1.231344826","rc":[{"batb":[[0,1.03,207.85]],"ltp":0.0,"tv":0.0,"id":2780},{"batb":[[0,1.03,207.85]],"ltp":0.0,"tv":0.0,"id":424676}]}]}
{"op":"mcm","clk":"11766123812","pt":1722599736953,"mc":[{"id":"1.231344826","rc":[{"batb":[[0,1.04,7.85],[1,1.03,207.85],[2,1.02,207.85]],"ltp":0.0,"tv":0.0,"id":2780},{"batb":[[0,1.04,7.85],[1,1.03,207.85],[2,1.02,207.85]],"ltp":0.0,"tv":0.0,"id":424676}]}]}
{"op":"mcm","clk":"11766124213","pt":1722599751194,"mc":[{"id":"1.231344826","rc":[{"batb":[[0,1.05,7.85],[1,1.04,7.85],[2,1.03,207.85]],"ltp":0.0,"tv":0.0,"id":2780},{"batb":[[0,1.05,7.85],[1,1.04,7.85],[2,1.03,207.85]],"ltp":0.0,"tv":0.0,"id":424676}]}]}
{"op":"mcm","clk":"11766124565","pt":1722599764291,"mc":[{"id":"1.231344826","rc":[{"batb":[[0,1.06,7.85],[1,1.05,7.85],[2,1.04,7.85]],"ltp":0.0,"tv":0.0,"id":2780},{"batb":[[0,1.06,7.85],[1,1.05,7.85],[2,1.04,7.85]],"ltp":0.0,"tv":0.0,"id":424676}]}]}
{"op":"mcm","clk":"11766124874","pt":1722599776596,"mc":[{"id":"1.231344826","rc":[{"batb":[[0,1.07,7.85],[1,1.06,7.85],[2,1.05,7.85]],"ltp":0.0,"tv":0.0,"id":2780},{"batb":[[0,1.07,7.85],[1,1.06,7.85],[2,1.05,7.85]],"ltp":0.0,"tv":0.0,"id":424676}]}]}
{"op":"mcm","clk":"11766125240","pt":1722599791081,"mc":[{"id":"1.231344826","rc":[{"batb":[[0,1.08,7.85],[1,1.07,7.85],[2,1.06,7.85]],"ltp":0.0,"tv":0.0,"id":2780},{"batb":[[0,1.08,7.85],[1,1.07,7.85],[2,1.06,7.85]],"ltp":0.0,"tv":0.0,"id":424676}]}]}
{"op":"mcm","clk":"11766164845","pt":1722600775150,"mc":[{"id":"1.231344826","rc":[{"batb":[[0,1.08,7.85],[1,1.07,7.85],[2,1.06,7.85]],"ltp":0.0,"tv":0.0,"id":2780},{"batb":[[0,1.08,7.85],[1,1.07,7.85],[2,1.06,7.85]],"ltp":0.0,"tv":0.0,"id":424676}]}]}
{"op":"mcm","clk":"11766375234","pt":1722606175138,"mc":[{"id":"1.231344826","rc":[{"batb":[[0,1.08,7.81],[1,1.07,7.81],[2,1.06,7.81]],"ltp":0.0,"tv":0.0,"id":2780},{"batb":[[0,1.08,7.81],[1,1.07,7.81],[2,1.06,7.81]],"ltp":0.0,"tv":0.0,"id":424676}]}]}
{"op":"mcm","clk":"11766643614","pt":1722611532996,"mc":[{"id":"1.231344826","rc":[{"batb":[[0,1.08,7.81],[1,1.07,7.81],[2,1.06,7.81]],"ltp":0.0,"tv":0.0,"id":2780},{"batb":[[0,1.16,3.88],[1,1.08,7.81],[2,1.07,7.81]],"ltp":0.0,"tv":0.0,"id":424676}]}]}
{"op":"mcm","clk":"11766644316","pt":1722611547232,"mc":[{"id":"1.231344826","rc":[{"batb":[[0,1.15,3.95],[1,1.08,7.81],[2,1.07,7.81]],"ltp":0.0,"tv":0.0,"id":2780}]}]}
{"op":"mcm","clk":"11766644874","pt":1722611558527,"mc":[{"id":"1.231344826","marketDefinition":{"bspMarket":false,"turnInPlayEnabled":true,"persistenceEnabled":true,"marketBaseRate":5.0,"eventId":"33462739","eventTypeId":"4","numberOfWinners":1,"bettingType":"ODDS","marketType":"MATCH_ODDS","marketTime":"2024-08-04T10:00:00.000Z","suspendTime":"2024-08-04T10:00:00.000Z","bspReconciled":false,"complete":true,"inPlay":false,"crossMatching":true,"runnersVoidable":false,"numberOfActiveRunners":2,"betDelay":0,"status":"OPEN","runners":[{"status":"ACTIVE","sortPriority":1,"id":424676,"name":"Surrey"},{"status":"ACTIVE","sortPriority":2,"id":2780,"name":"Nottinghamshire"}],"regulators":["MR_INT"],"countryCode":"GB","discountAllowed":true,"timezone":"GMT","openDate":"2024-08-04T10:00:00.000Z","version":6051295021,"name":"Match Odds","eventName":"Surrey v Nottinghamshire"}}]}
{"op":"mcm","clk":"11766777482","pt":1722613516305,"mc":[{"id":"1.231344826","rc":[{"batb":[[0,1.08,7.81],[1,1.07,7.81],[2,1.06,7.81]],"ltp":0.0,"tv":0.0,"id":2780}]}]}
{"op":"mcm","clk":"11766777789","pt":1722613521119,"mc":[{"id":"1.231344826","rc":[{"batb":[[0,1.08,7.81],[1,1.07,7.81],[2,1.06,7.81]],"ltp":0.0,"tv":0.0,"id":424676}]}]}
{"op":"mcm","clk":"11767164044","pt":1722616975183,"mc":[{"id":"1.231344826","rc":[{"batb":[[0,1.08,7.81],[1,1.07,7.81],[2,1.06,7.81]],"ltp":0.0,"tv":0.0,"id":2780},{"batb":[[0,1.08,7.81],[1,1.07,7.81],[2,1.06,7.81]],"ltp":0.0,"tv":0.0,"id":424676}]}]}
{"op":"mcm","clk":"11767255993","pt":1722617630016,"mc":[{"id":"1.231344826","rc":[{"batb":[[0,1.38,131.58],[1,1.33,151.52],[2,1.28,178.57]],"ltp":0.0,"tv":0.0,"id":2780},{"batb":[[0,1.38,131.58],[1,1.33,151.52],[2,1.28,178.57]],"ltp":0.0,"tv":0.0,"id":424676}]}]}
{"op":"mcm","clk":"11767723657","pt":1722620601489,"mc":[{"id":"1.231344826","rc":[{"batb":[[0,1.39,7.58],[1,1.38,131.58],[2,1.33,151.52]],"ltp":0.0,"tv":0.0,"id":2780},{"batb":[[0,1.39,7.8],[1,1.38,131.58],[2,1.33,151.52]],"ltp":0.0,"tv":0.0,"id":424676}]}]}
{"op":"mcm","clk":"11767992410","pt":1722622375159,"mc":[{"id":"1.231344826","rc":[{"batb":[[0,1.39,7.58]],"ltp":0.0,"tv":0.0,"id":2780},{"batb":[[0,1.39,7.79]],"ltp":0.0,"tv":0.0,"id":424676}]}]}
{"op":"mcm","clk":"11768649670","pt":1722626258793,"mc":[{"id":"1.231344826","rc":[{"batb":[[0,1.4,21.41],[1,1.39,7.57],[2,1.38,131.58]],"ltp":0.0,"tv":0.0,"id":2780},{"batb":[[0,1.4,21.41],[1,1.39,7.78],[2,1.38,131.58]],"ltp":0.0,"tv":0.0,"id":424676}]}]}
{"op":"mcm","clk":"11768898215","pt":1722628060902,"mc":[{"id":"1.231344826","rc":[{"batb":[[0,1.39,7.57],[1,1.38,131.58],[2,1.33,151.52]],"ltp":0.0,"tv":0.0,"id":2780},{"batb":[[0,1.39,7.78],[1,1.38,131.58],[2,1.33,151.52]],"ltp":0.0,"tv":0.0,"id":424676}]}]}
{"op":"mcm","clk":"11768900773","pt":1722628083944,"mc":[{"id":"1.231344826","rc":[{"batb":[[0,1.4,21.41],[1,1.39,7.57],[2,1.38,131.58]],"ltp":0.0,"tv":0.0,"id":2780},{"batb":[[0,1.4,21.41],[1,1.39,7.78],[2,1.38,131.58]],"ltp":0.0,"tv":0.0,"id":424676}]}]}
{"op":"mcm","clk":"11769072527","pt":1722629887121,"mc":[{"id":"1.231344826","rc":[{"batb":[[0,1.39,7.57],[1,1.38,131.58],[2,1.33,151.52]],"ltp":0.0,"tv":0.0,"id":2780},{"batb":[[0,1.39,7.78],[1,1.38,131.58],[2,1.33,151.52]],"ltp":0.0,"tv":0.0,"id":424676}]}]}
{"op":"mcm","clk":"11769083617","pt":1722630053851,"mc":[{"id":"1.231344826","rc":[{"batb":[[0,1.4,21.41],[1,1.39,7.57],[2,1.38,131.58]],"ltp":0.0,"tv":0.0,"id":2780},{"batb":[[0,1.4,21.41],[1,1.39,7.78],[2,1.38,131.58]],"ltp":0.0,"tv":0.0,"id":424676}]}]}
{"op":"mcm","clk":"11769182187","pt":1722631856186,"mc":[{"id":"1.231344826","rc":[{"batb":[[0,1.39,7.57],[1,1.38,131.58],[2,1.33,151.52]],"ltp":0.0,"tv":0.0,"id":2780},{"batb":[[0,1.39,7.78],[1,1.38,131.58],[2,1.33,151.52]],"ltp":0.0,"tv":0.0,"id":424676}]}]}
{"op":"mcm","clk":"11769185085","pt":1722631975106,"mc":[{"id":"1.231344826","rc":[{"batb":[[0,1.4,21.41],[1,1.39,7.57],[2,1.38,131.58]],"ltp":0.0,"tv":0.0,"id":2780},{"batb":[[0,1.4,21.41],[1,1.39,7.78],[2,1.38,131.58]],"ltp":0.0,"tv":0.0,"id":424676}]}]}
{"op":"mcm","clk":"11769226550","pt":1722633175083,"mc":[{"id":"1.231344826","rc":[{"batb":[[0,1.4,21.41],[1,1.39,7.57]],"ltp":0.0,"tv":0.0,"id":2780},{"batb":[[0,1.4,21.41],[1,1.39,7.79]],"ltp":0.0,"tv":0.0,"id":424676}]}]}
{"op":"mcm","clk":"11769247083","pt":1722633779862,"mc":[{"id":"1.231344826","rc":[{"batb":[[0,1.39,7.57],[1,1.38,131.58],[2,1.33,151.52]],"ltp":0.0,"tv":0.0,"id":2780},{"batb":[[0,1.39,7.79],[1,1.38,131.58],[2,1.33,151.52]],"ltp":0.0,"tv":0.0,"id":424676}]}]}
{"op":"mcm","clk":"11769250081","pt":1722633853723,"mc":[{"id":"1.231344826","rc":[{"batb":[[0,1.4,21.41],[1,1.39,7.57],[2,1.38,131.58]],"ltp":0.0,"tv":0.0,"id":2780},{"batb":[[0,1.4,21.41],[1,1.39,7.79],[2,1.38,131.58]],"ltp":0.0,"tv":0.0,"id":424676}]}]}
{"op":"mcm","clk":"11769304149","pt":1722635654689,"mc":[{"id":"1.231344826","rc":[{"batb":[[0,1.39,7.57],[1,1.38,131.58],[2,1.33,151.52]],"ltp":0.0,"tv":0.0,"id":2780},{"batb":[[0,1.39,7.79],[1,1.38,131.58],[2,1.33,151.52]],"ltp":0.0,"tv":0.0,"id":424676}]}]}
{"op":"mcm","clk":"11769306257","pt":1722635718489,"mc":[{"id":"1.231344826","rc":[{"batb":[[0,1.4,21.41],[1,1.39,7.57],[2,1.38,131.58]],"ltp":0.0,"tv":0.0,"id":2780},{"batb":[[0,1.4,21.41],[1,1.39,7.79],[2,1.38,131.58]],"ltp":0.0,"tv":0.0,"id":424676}]}]}
{"op":"mcm","clk":"11769312176","pt":1722635903260,"mc":[{"id":"1.231344826","rc":[{"batb":[[0,1.44,85.22],[1,1.4,21.41],[2,1.39,7.57]],"ltp":0.0,"tv":0.0,"id":2780}]}]}
{"op":"mcm","clk":"11769312233","pt":1722635904236,"mc":[{"id":"1.231344826","rc":[{"batb":[[0,1.44,85.22],[1,1.4,21.41],[2,1.39,7.79]],"ltp":0.0,"tv":0.0,"id":424676}]}]}
{"op":"mcm","clk":"11769356312","pt":1722637519471,"mc":[{"id":"1.231344826","rc":[{"batb":[[0,1.44,85.28],[1,1.39,7.57],[2,1.38,131.58]],"ltp":0.0,"tv":0.0,"id":2780},{"batb":[[0,1.44,85.28],[1,1.39,7.78],[2,1.38,131.58]],"ltp":0.0,"tv":0.0,"id":424676}]}]}
{"op":"mcm","clk":"11769357656","pt":1722637577814,"mc":[{"id":"1.231344826","rc":[{"batb":[[0,1.45,19.04],[1,1.44,85.28],[2,1.39,7.57]],"ltp":0.0,"tv":0.0,"id":2780},{"batb":[[0,1.45,19.04],[1,1.44,85.28],[2,1.39,7.78]],"ltp":0.0,"tv":0.0,"id":424676}]}]}
{"op":"mcm","clk":"11769368798","pt":1722637981449,"mc":[{"id":"1.231344826","rc":[{"batb":[[0,1.45,26.61],[2,1.38,131.58]],"ltp":0.0,"tv":0.0,"id":2780},{"batb":[[0,1.45,26.82],[2,1.38,131.58]],"ltp":0.0,"tv":0.0,"id":424676}]}]}
{"op":"mcm","clk":"11769434632","pt":1722639379034,"mc":[{"id":"1.231344826","rc":[{"batb":[[0,1.45,7.57]],"ltp":0.0,"tv":0.0,"id":2780},{"batb":[[0,1.45,7.78]],"ltp":0.0,"tv":0.0,"id":424676}]}]}
{"op":"mcm","clk":"11769436947","pt":1722639430281,"mc":[{"id":"1.231344826","rc":[{"batb":[[0,1.46,18.62],[1,1.45,7.57],[2,1.44,85.28]],"ltp":0.0,"tv":0.0,"id":2780},{"batb":[[0,1.46,18.62],[1,1.45,7.78],[2,1.44,85.28]],"ltp":0.0,"tv":0.0,"id":424676}]}]}
{"op":"mcm","clk":"11769515155","pt":1722641231526,"mc":[{"id":"1.231344826","rc":[{"batb":[[0,1.45,7.57],[1,1.44,85.28],[2,1.38,131.58]],"ltp":0.0,"tv":0.0,"id":2780},{"batb":[[0,1.45,7.79],[1,1.44,85.28],[2,1.38,131.58]],"ltp":0.0,"tv":0.0,"id":424676}]}]}
{"op":"mcm","clk":"11769515386","pt":1722641238211,"mc":[{"id":"1.231344826","rc":[{"batb":[[0,1.45,12.14]],"ltp":0.0,"tv":0.0,"id":2780},{"batb":[[0,1.45,12.36]],"ltp":0.0,"tv":0.0,"id":424676}]}]}
{"op":"mcm","clk":"11769515504","pt":1722641242010,"mc":[{"id":"1.231344826","rc":[{"batb":[[0,1.45,7.57]],"ltp":0.0,"tv":0.0,"id":2780},{"batb":[[0,1.45,7.79]],"ltp":0.0,"tv":0.0,"id":424676}]}]}
{"op":"mcm","clk":"11769516907","pt":1722641278369,"mc":[{"id":"1.231344826","rc":[{"batb":[[0,1.46,18.62],[1,1.45,7.57],[2,1.44,85.28]],"ltp":0.0,"tv":0.0,"id":2780},{"batb":[[0,1.46,18.62],[1,1.45,7.79],[2,1.44,85.28]],"ltp":0.0,"tv":0.0,"id":424676}]}]}
{"op":"mcm","clk":"11769599226","pt":1722643080062,"mc":[{"id":"1.231344826","rc":[{"batb":[[0,1.45,7.57],[1,1.44,85.28],[2,1.38,131.58]],"ltp":0.0,"tv":0.0,"id":2780},{"batb":[[0,1.45,7.79],[1,1.44,85.28],[2,1.38,131.58]],"ltp":0.0,"tv":0.0,"id":424676}]}]}
{"op":"mcm","clk":"11769601029","pt":1722643117219,"mc":[{"id":"1.231344826","rc":[{"batb":[[0,1.46,18.62],[1,1.45,7.57],[2,1.44,85.28]],"ltp":0.0,"tv":0.0,"id":2780},{"batb":[[0,1.46,18.62],[1,1.45,7.79],[2,1.44,85.28]],"ltp":0.0,"tv":0.0,"id":424676}]}]}
{"op":"mcm","clk":"11769720383","pt":1722644918874,"mc":[{"id":"1.231344826","rc":[{"batb":[[0,1.45,7.57],[1,1.44,85.28],[2,1.38,131.58]],"ltp":0.0,"tv":0.0,"id":2780},{"batb":[[0,1.45,7.79],[1,1.44,85.28],[2,1.38,131.58]],"ltp":0.0,"tv":0.0,"id":424676}]}]}
{"op":"mcm","clk":"11769721903","pt":1722644942988,"mc":[{"id":"1.231344826","rc":[{"batb":[[0,1.46,18.62],[1,1.45,7.57],[2,1.44,85.28]],"ltp":0.0,"tv":0.0,"id":2780},{"batb":[[0,1.46,18.62],[1,1.45,7.79],[2,1.44,85.28]],"ltp":0.0,"tv":0.0,"id":424676}]}]}
{"op":"mcm","clk":"11769838266","pt":1722646743123,"mc":[{"id":"1.231344826","rc":[{"batb":[[0,1.45,7.79],[1,1.44,85.28],[2,1.38,131.58]],"ltp":0.0,"tv":0.0,"id":424676}]}]}
{"op":"mcm","clk":"11769838405","pt":1722646744825,"mc":[{"id":"1.231344826","rc":[{"batb":[[0,1.45,7.57],[1,1.44,85.28],[2,1.38,131.58]],"ltp":0.0,"tv":0.0,"id":2780}]}]}
{"op":"mcm","clk":"11769839284","pt":1722646756066,"mc":[{"id":"1.231344826","rc":[{"batb":[[0,1.45,12.14]],"ltp":0.0,"tv":0.0,"id":2780},{"batb":[[0,1.45,12.36]],"ltp":0.0,"tv":0.0,"id":424676}]}]}
{"op":"mcm","clk":"11769839318","pt":1722646756630,"mc":[{"id":"1.231344826","rc":[{"batb":[[0,1.46,18.62],[1,1.45,12.14],[2,1.44,85.28]],"ltp":0.0,"tv":0.0,"id":2780},{"batb":[[0,1.46,18.62],[1,1.45,12.36],[2,1.44,85.28]],"ltp":0.0,"tv":0.0,"id":424676}]}]}
{"op":"mcm","clk":"11769839600","pt":1722646760356,"mc":[{"id":"1.231344826","rc":[{"batb":[[1,1.45,7.57]],"ltp":0.0,"tv":0.0,"id":2780},{"batb":[[1,1.45,7.79]],"ltp":0.0,"tv":0.0,"id":424676}]}]}
{"op":"mcm","clk":"11769984535","pt":1722648558930,"mc":[{"id":"1.231344826","rc":[{"batb":[[0,1.45,7.57],[1,1.44,85.28],[2,1.38,131.58]],"ltp":0.0,"tv":0.0,"id":2780},{"batb":[[0,1.45,7.79],[1,1.44,85.28],[2,1.38,131.58]],"ltp":0.0,"tv":0.0,"id":424676}]}]}
{"op":"mcm","clk":"11769985220","pt":1722648567435,"mc":[{"id":"1.231344826","rc":[{"batb":[[0,1.46,18.62],[1,1.45,7.57],[2,1.44,85.28]],"ltp":0.0,"tv":0.0,"id":2780},{"batb":[[0,1.46,18.62],[1,1.45,7.79],[2,1.44,85.28]],"ltp":0.0,"tv":0.0,"id":424676}]}]}
{"op":"mcm","clk":"11770133736","pt":1722650369255,"mc":[{"id":"1.231344826","rc":[{"batb":[[0,1.45,7.57],[1,1.44,85.28],[2,1.38,131.58]],"ltp":0.0,"tv":0.0,"id":2780},{"batb":[[0,1.45,7.79],[1,1.44,85.28],[2,1.38,131.58]],"ltp":0.0,"tv":0.0,"id":424676}]}]}
{"op":"mcm","clk":"11770134004","pt":1722650373362,"mc":[{"id":"1.231344826","rc":[{"batb":[[0,1.46,18.62],[1,1.45,7.57],[2,1.44,85.28]],"ltp":0.0,"tv":0.0,"id":2780},{"batb":[[0,1.46,18.62],[1,1.45,7.79],[2,1.44,85.28]],"ltp":0.0,"tv":0.0,"id":424676}]}]}
{"op":"mcm","clk":"11770271342","pt":1722652175123,"mc":[{"id":"1.231344826","rc":[{"batb":[[0,1.45,7.57],[1,1.44,85.28],[2,1.38,131.58]],"ltp":0.0,"tv":0.0,"id":2780},{"batb":[[0,1.45,7.79],[1,1.44,85.28],[2,1.38,131.58]],"ltp":0.0,"tv":0.0,"id":424676}]}]}
{"op":"mcm","clk":"11770273841","pt":1722652209729,"mc":[{"id":"1.231344826","rc":[{"batb":[[0,1.45,12.14]],"ltp":0.0,"tv":0.0,"id":2780},{"batb":[[0,1.45,12.36]],"ltp":0.0,"tv":0.0,"id":424676}]}]}
{"op":"mcm","clk":"11770274238","pt":1722652214127,"mc":[{"id":"1.231344826","rc":[{"batb":[[0,1.45,7.57]],"ltp":0.0,"tv":0.0,"id":2780},{"batb":[[0,1.45,7.79]],"ltp":0.0,"tv":0.0,"id":424676}]}]}
{"op":"mcm","clk":"11770282671","pt":1722652327293,"mc":[{"id":"1.231344826","rc":[{"batb":[[0,1.46,18.62],[1,1.45,7.57],[2,1.44,85.28]],"ltp":0.0,"tv":0.0,"id":2780},{"batb":[[0,1.46,18.62],[1,1.45,7.79],[2,1.44,85.28]],"ltp":0.0,"tv":0.0,"id":424676}]}]}
{"op":"mcm","clk":"11770410066","pt":1722654129345,"mc":[{"id":"1.231344826","rc":[{"batb":[[0,1.45,7.57],[1,1.44,85.28],[2,1.38,131.58]],"ltp":0.0,"tv":0.0,"id":2780},{"batb":[[0,1.45,7.79],[1,1.44,85.28],[2,1.38,131.58]],"ltp":0.0,"tv":0.0,"id":424676}]}]}
{"op":"mcm","clk":"11770418549","pt":1722654272490,"mc":[{"id":"1.231344826","rc":[{"batb":[[0,1.46,18.62],[1,1.45,7.57],[2,1.44,85.28]],"ltp":0.0,"tv":0.0,"id":2780},{"batb":[[0,1.46,18.62],[1,1.45,7.79],[2,1.44,85.28]],"ltp":0.0,"tv":0.0,"id":424676}]}]}
{"op":"mcm","clk":"11770525195","pt":1722656075049,"mc":[{"id":"1.231344826","rc":[{"batb":[[0,1.45,7.57],[1,1.44,85.28],[2,1.38,131.58]],"ltp":0.0,"tv":0.0,"id":2780},{"batb":[[0,1.45,7.79],[1,1.44,85.28],[2,1.38,131.58]],"ltp":0.0,"tv":0.0,"id":424676}]}]}
{"op":"mcm","clk":"11770530889","pt":1722656199289,"mc":[{"id":"1.231344826","rc":[{"batb":[[0,1.46,18.62],[1,1.45,7.57],[2,1.44,85.28]],"ltp":0.0,"tv":0.0,"id":2780},{"batb":[[0,1.46,18.62],[1,1.45,7.79],[2,1.44,85.28]],"ltp":0.0,"tv":0.0,"id":424676}]}]}
{"op":"mcm","clk":"11770618283","pt":1722658000426,"mc":[{"id":"1.231344826","rc":[{"batb":[[0,1.45,7.57],[1,1.44,85.28],[2,1.38,131.58]],"ltp":0.0,"tv":0.0,"id":2780}]}]}
{"op":"mcm","clk":"11770618301","pt":1722658000633,"mc":[{"id":"1.231344826","rc":[{"batb":[[0,1.45,7.79],[1,1.44,85.28],[2,1.38,131.58]],"ltp":0.0,"tv":0.0,"id":424676}]}]}
{"op":"mcm","clk":"11770623474","pt":1722658089342,"mc":[{"id":"1.231344826","rc":[{"batb":[[0,1.45,12.14]],"ltp":0.0,"tv":0.0,"id":2780},{"batb":[[0,1.45,12.36]],"ltp":0.0,"tv":0.0,"id":424676}]}]}
{"op":"mcm","clk":"11770623714","pt":1722658092902,"mc":[{"id":"1.231344826","rc":[{"batb":[[0,1.45,7.57]],"ltp":0.0,"tv":0.0,"id":2780},{"batb":[[0,1.45,7.79]],"ltp":0.0,"tv":0.0,"id":424676}]}]}
{"op":"mcm","clk":"11770625454","pt":1722658123532,"mc":[{"id":"1.231344826","rc":[{"batb":[[0,1.46,18.62],[1,1.45,7.57],[2,1.44,85.28]],"ltp":0.0,"tv":0.0,"id":2780},{"batb":[[0,1.46,18.62],[1,1.45,7.79],[2,1.44,85.28]],"ltp":0.0,"tv":0.0,"id":424676}]}]}
{"op":"mcm","clk":"11770708491","pt":1722659925490,"mc":[{"id":"1.231344826","rc":[{"batb":[[0,1.45,7.79],[1,1.44,85.28],[2,1.38,131.58]],"ltp":0.0,"tv":0.0,"id":424676}]}]}
{"op":"mcm","clk":"11770708503","pt":1722659925695,"mc":[{"id":"1.231344826","rc":[{"batb":[[0,1.45,7.57],[1,1.44,85.28],[2,1.38,131.58]],"ltp":0.0,"tv":0.0,"id":2780}]}]}
{"op":"mcm","clk":"11770710010","pt":1722659961706,"mc":[{"id":"1.231344826","rc":[{"batb":[[0,1.45,12.14]],"ltp":0.0,"tv":0.0,"id":2780},{"batb":[[0,1.45,12.36]],"ltp":0.0,"tv":0.0,"id":424676}]}]}
{"op":"mcm","clk":"11770710194","pt":1722659965344,"mc":[{"id":"1.231344826","rc":[{"batb":[[0,1.45,7.57]],"ltp":0.0,"tv":0.0,"id":2780},{"batb":[[0,1.45,7.79]],"ltp":0.0,"tv":0.0,"id":424676}]}]}
{"op":"mcm","clk":"11770712884","pt":1722660034701,"mc":[{"id":"1.231344826","rc":[{"batb":[[0,1.46,18.62],[1,1.45,7.57],[2,1.44,85.28]],"ltp":0.0,"tv":0.0,"id":2780},{"batb":[[0,1.46,18.62],[1,1.45,7.79],[2,1.44,85.28]],"ltp":0.0,"tv":0.0,"id":424676}]}]}
{"op":"mcm","clk":"11770803872","pt":1722661836951,"mc":[{"id":"1.231344826","rc":[{"batb":[[0,1.45,7.57],[1,1.44,85.28],[2,1.38,131.58]],"ltp":0.0,"tv":0.0,"id":2780},{"batb":[[0,1.45,7.79],[1,1.44,85.28],[2,1.38,131.58]],"ltp":0.0,"tv":0.0,"id":424676}]}]}
{"op":"mcm","clk":"11770805342","pt":1722661870864,"mc":[{"id":"1.231344826","rc":[{"batb":[[0,1.45,12.14]],"ltp":0.0,"tv":0.0,"id":2780},{"batb":[[0,1.45,12.36]],"ltp":0.0,"tv":0.0,"id":424676}]}]}
{"op":"mcm","clk":"11770805529","pt":1722661876195,"mc":[{"id":"1.231344826","rc":[{"batb":[[0,1.45,7.57]],"ltp":0.0,"tv":0.0,"id":2780},{"batb":[[0,1.45,7.79]],"ltp":0.0,"tv":0.0,"id":424676}]}]}
{"op":"mcm","clk":"11770807851","pt":1722661935561,"mc":[{"id":"1.231344826","rc":[{"batb":[[0,1.46,18.62],[1,1.45,7.57],[2,1.44,85.28]],"ltp":0.0,"tv":0.0,"id":2780},{"batb":[[0,1.46,18.62],[1,1.45,7.79],[2,1.44,85.28]],"ltp":0.0,"tv":0.0,"id":424676}]}]}
{"op":"mcm","clk":"11770844433","pt":1722662874394,"mc":[{"id":"1.231344826","rc":[{"batb":[[0,1.47,7],[1,1.46,18.62],[2,1.45,7.57]],"ltp":0.0,"tv":0.0,"id":2780},{"batb":[[0,1.55,5],[1,1.46,18.62],[2,1.45,7.79]],"ltp":0.0,"tv":0.0,"id":424676}]}]}
{"op":"mcm","clk":"11770886658","pt":1722663736405,"mc":[{"id":"1.231344826","rc":[{"batb":[[1,1.45,7.79],[2,1.44,85.28]],"ltp":0.0,"tv":0.0,"id":424676}]}]}
{"op":"mcm","clk":"11770886672","pt":1722663736605,"mc":[{"id":"1.231344826","rc":[{"batb":[[1,1.45,7.57],[2,1.44,85.28]],"ltp":0.0,"tv":0.0,"id":2780}]}]}
{"op":"mcm","clk":"11770892250","pt":1722663836163,"mc":[{"id":"1.231344826","rc":[{"batb":[[0,1.48,17.85],[1,1.47,7],[2,1.45,7.57]],"ltp":0.0,"tv":0.0,"id":2780},{"batb":[[0,1.56,15.3],[1,1.55,5],[2,1.45,7.79]],"ltp":0.0,"tv":0.0,"id":424676}]}]}
{"op":"mcm","clk":"11770923052","pt":1722664592749,"mc":[{"id":"1.231344826","rc":[{"batb":[[0,1.49,7],[1,1.48,17.85]],"ltp":0.0,"tv":0.0,"id":2780},{"batb":[[0,1.59,5],[1,1.56,15.3]],"ltp":0.0,"tv":0.0,"id":424676}]}]}
{"op":"mcm","clk":"11770984171","pt":1722665636396,"mc":[{"id":"1.231344826","rc":[{"batb":[[1,1.45,7.79],[2,1.44,85.28]],"ltp":0.0,"tv":0.0,"id":424676}]}]}
{"op":"mcm","clk":"11770984180","pt":1722665636598,"mc":[{"id":"1.231344826","rc":[{"batb":[[1,1.45,7.57],[2,1.44,85.28]],"ltp":0.0,"tv":0.0,"id":2780}]}]}
{"op":"mcm","clk":"11770989213","pt":1722665738537,"mc":[{"id":"1.231344826","rc":[{"batb":[[0,1.5,17.13],[1,1.49,7],[2,1.45,7.57]],"ltp":0.0,"tv":0.0,"id":2780},{"batb":[[0,1.6,14.28],[1,1.59,5],[2,1.45,7.79]],"ltp":0.0,"tv":0.0,"id":424676}]}]}
{"op":"mcm","clk":"11770996707","pt":1722665889972,"mc":[{"id":"1.231344826","rc":[{"batb":[[0,1.51,7],[1,1.5,17.13]],"ltp":0.0,"tv":0.0,"id":2780},{"batb":[[0,1.61,5],[1,1.6,14.28]],"ltp":0.0,"tv":0.0,"id":424676}]}]}
{"op":"mcm","clk":"11771000866","pt":1722665979089,"mc":[{"id":"1.231344826","rc":[{"batb":[[0,1.73,5]],"ltp":0.0,"tv":0.0,"id":424676}]}]}
{"op":"mcm","clk":"11771067812","pt":1722667539019,"mc":[{"id":"1.231344826","rc":[{"batb":[[1,1.45,7.57],[2,1.44,85.28]],"ltp":0.0,"tv":0.0,"id":2780},{"batb":[[1,1.45,7.79],[2,1.44,85.28]],"ltp":0.0,"tv":0.0,"id":424676}]}]}
{"op":"mcm","clk":"11771072959","pt":1722667639058,"mc":[{"id":"1.231344826","rc":[{"batb":[[0,1.52,16.47],[1,1.51,7],[2,1.45,7.57]],"ltp":0.0,"tv":0.0,"id":2780},{"batb":[[0,1.74,11.58],[1,1.73,5],[2,1.45,7.79]],"ltp":0.0,"tv":0.0,"id":424676}]}]}
{"op":"mcm","clk":"11771130730","pt":1722669079975,"mc":[{"id":"1.231344826","rc":[{"batb":[[0,1.53,7],[1,1.52,16.47]],"ltp":0.0,"tv":0.0,"id":2780},{"batb":[[0,1.75,5],[1,1.74,11.58]],"ltp":0.0,"tv":0.0,"id":424676}]}]}
{"op":"mcm","clk":"11771145271","pt":1722669439459,"mc":[{"id":"1.231344826","rc":[{"batb":[[1,1.45,7.57],[2,1.44,85.28]],"ltp":0.0,"tv":0.0,"id":2780},{"batb":[[1,1.45,7.79],[2,1.44,85.28]],"ltp":0.0,"tv":0.0,"id":424676}]}]}
{"op":"mcm","clk":"11771364631","pt":1722673216262,"mc":[{"id":"1.231344826","rc":[{"trd":[[1.53,4]],"batb":[[0,1.53,5]],"ltp":1.53,"tv":4.0,"id":2780}],"tv":4.0}]}
{"op":"mcm","clk":"11771396160","pt":1722673756860,"mc":[{"id":"1.231344826","rc":[{"batb":[[0,1.51,5]],"ltp":1.53,"tv":4.0,"id":2780}]}]}
{"op":"mcm","clk":"11773339850","pt":1722690947233,"mc":[{"id":"1.231344826","rc":[{"batl":[[0,2,567.97]],"ltp":1.53,"tv":4.0,"id":2780}]}]}
{"op":"mcm","clk":"11773341955","pt":1722690963871,"mc":[{"id":"1.231344826","rc":[{"batl":[[0,2.7,473.31]],"ltp":0.0,"tv":0.0,"id":424676}]}]}
{"op":"mcm","clk":"11773343161","pt":1722690972774,"mc":[{"id":"1.231344826","rc":[{"batl":[[1,2.06,473.31]],"ltp":1.53,"tv":4.0,"id":2780}]}]}
{"op":"mcm","clk":"11773434839","pt":1722691751997,"mc":[{"id":"1.231344826","rc":[{"batl":[[0,1.99,17.32],[1,2,567.97],[2,2.06,473.31]],"ltp":1.53,"tv":4.0,"id":2780}]}]}
{"op":"mcm","clk":"11773435525","pt":1722691757211,"mc":[{"id":"1.231344826","rc":[{"batb":[[0,1.59,17],[1,1.51,5],[2,1.45,7.57]],"ltp":1.53,"tv":4.0,"id":2780}]}]}
{"op":"mcm","clk":"11773499597","pt":1722692276966,"mc":[{"id":"1.231344826","rc":[{"batb":[[0,2.02,17.19],[1,1.75,5],[2,1.45,7.79]],"ltp":0.0,"tv":0.0,"id":424676}]}]}
{"op":"mcm","clk":"11773509825","pt":1722692353851,"mc":[{"id":"1.231344826","rc":[{"batl":[[0,2.68,16.65],[1,2.7,473.31]],"ltp":0.0,"tv":0.0,"id":424676}]}]}
{"op":"mcm","clk":"11773568128","pt":1722692730526,"mc":[{"id":"1.231344826","rc":[{"batb":[[0,1.6,7.57],[1,1.59,17],[2,1.51,5]],"ltp":1.53,"tv":4.0,"id":2780},{"batb":[[0,2.02,24.98],[2,1.44,85.28]],"ltp":0.0,"tv":0.0,"id":424676}]}]}
{"op":"mcm","clk":"11774575739","pt":1722698373634,"mc":[{"id":"1.231344826","rc":[{"batb":[[0,1.8,50.49],[1,1.6,7.57],[2,1.59,17]],"ltp":1.53,"tv":4.0,"id":2780},{"batb":[[0,2.14,35.43],[1,2.02,24.98],[2,1.75,5]],"ltp":0.0,"tv":0.0,"id":424676}]}]}
{"op":"mcm","clk":"11774576035","pt":1722698375033,"mc":[{"id":"1.231344826","rc":[{"batb":[[2,1.51,5]],"batl":[[0,2,567.97],[1,2.06,473.31],[2,2.06,0]],"ltp":1.53,"tv":4.0,"id":2780},{"batb":[[1,2.02,7.79]],"batl":[[0,2.7,473.31],[1,2.7,0]],"ltp":0.0,"tv":0.0,"id":424676}]}]}
{"op":"mcm","clk":"11774675487","pt":1722698802939,"mc":[{"id":"1.231344826","rc":[{"batb":[[1,1.51,5],[2,1.44,85.28]],"ltp":1.53,"tv":4.0,"id":2780},{"batb":[[1,1.75,5],[2,1.44,85.28]],"ltp":0.0,"tv":0.0,"id":424676}]}]}
{"op":"mcm","clk":"11775851392","pt":1722705543622,"mc":[{"id":"1.231344826","rc":[{"trd":[[1.8,100.98]],"batb":[[0,1.51,5],[1,1.44,85.28],[2,1.3,633.33]],"batl":[[0,1.8,49.51],[1,2,567.97],[2,2.06,473.31]],"ltp":1.8,"tv":104.98,"id":2780}],"tv":104.98}]}
{"op":"mcm","clk":"11775852125","pt":1722705548025,"mc":[{"id":"1.231344826","rc":[{"batb":[[0,1.76,53.14],[1,1.51,5],[2,1.44,85.28]],"batl":[[1,1.81,200],[2,2,567.97]],"ltp":1.8,"tv":104.98,"id":2780}]}]}
{"op":"mcm","clk":"11775852630","pt":1722705551199,"mc":[{"id":"1.231344826","rc":[{"batl":[[2,1.82,300]],"ltp":1.8,"tv":104.98,"id":2780}]}]}
{"op":"mcm","clk":"11776473426","pt":1722709316494,"mc":[{"id":"1.231344826","rc":[{"trd":[[1.76,1.73]],"batb":[[1,1.44,85.28],[2,1.3,633.33]],"ltp":1.76,"tv":106.71,"id":2780},{"trd":[[2.32,1.31]],"batb":[[0,2.16,12],[1,2.14,35.43]],"ltp":2.32,"tv":1.31,"id":424676}],"tv":108.02}]}
{"op":"mcm","clk":"11776473897","pt":1722709319002,"mc":[{"id":"1.231344826","rc":[{"batb":[[0,2.16,10]],"ltp":2.32,"tv":1.31,"id":424676}]}]}
{"op":"mcm","clk":"11776474083","pt":1722709319981,"mc":[{"id":"1.231344826","rc":[{"batb":[[0,2.14,35.43],[1,1.44,85.28],[2,1.3,633.33]],"ltp":2.32,"tv":1.31,"id":424676}]}]}
{"op":"mcm","clk":"11776523535","pt":1722709575747,"mc":[{"id":"1.231344826","rc":[{"batb":[[0,2.16,12],[1,2.14,35.43],[2,1.44,85.28]],"ltp":2.32,"tv":1.31,"id":424676}]}]}
{"op":"mcm","clk":"11776523996","pt":1722709578273,"mc":[{"id":"1.231344826","rc":[{"batb":[[0,2.16,10]],"ltp":2.32,"tv":1.31,"id":424676}]}]}
{"op":"mcm","clk":"11776524143","pt":1722709579070,"mc":[{"id":"1.231344826","rc":[{"batb":[[0,2.14,35.43],[1,1.44,85.28],[2,1.3,633.33]],"ltp":2.32,"tv":1.31,"id":424676}]}]}
{"op":"mcm","clk":"11776549935","pt":1722709733305,"mc":[{"id":"1.231344826","rc":[{"batb":[[0,2.16,12],[1,2.14,35.43],[2,1.44,85.28]],"ltp":2.32,"tv":1.31,"id":424676}]}]}
{"op":"mcm","clk":"11776550382","pt":1722709735840,"mc":[{"id":"1.231344826","rc":[{"batb":[[0,2.16,10]],"ltp":2.32,"tv":1.31,"id":424676}]}]}
{"op":"mcm","clk":"11776550535","pt":1722709736693,"mc":[{"id":"1.231344826","rc":[{"batb":[[0,2.14,35.43],[1,1.44,85.28],[2,1.3,633.33]],"ltp":2.32,"tv":1.31,"id":424676}]}]}
{"op":"mcm","clk":"11776557364","pt":1722709777175,"mc":[{"id":"1.231344826","rc":[{"batb":[[1,1.73,32],[2,1.44,85.28]],"ltp":1.76,"tv":106.71,"id":2780},{"batb":[[0,2.16,12],[1,2.14,35.43],[2,1.44,85.28]],"ltp":2.32,"tv":1.31,"id":424676}]}]}
{"op":"mcm","clk":"11776557766","pt":1722709779556,"mc":[{"id":"1.231344826","rc":[{"batb":[[0,2.16,10]],"ltp":2.32,"tv":1.31,"id":424676}]}]}
{"op":"mcm","clk":"11776557942","pt":1722709780558,"mc":[{"id":"1.231344826","rc":[{"batb":[[0,2.14,35.43],[1,1.44,85.28],[2,1.3,633.33]],"ltp":2.32,"tv":1.31,"id":424676}]}]}
{"op":"mcm","clk":"11776559633","pt":1722709790862,"mc":[{"id":"1.231344826","rc":[{"batb":[[1,1.74,17.32],[2,1.73,32]],"ltp":1.76,"tv":106.71,"id":2780},{"batb":[[0,2.16,12],[1,2.14,35.43],[2,1.74,17.32]],"ltp":2.32,"tv":1.31,"id":424676}]}]}
{"op":"mcm","clk":"11776560028","pt":1722709793080,"mc":[{"id":"1.231344826","rc":[{"batb":[[0,2.16,10]],"ltp":2.32,"tv":1.31,"id":424676}]}]}
{"op":"mcm","clk":"11776560245","pt":1722709794368,"mc":[{"id":"1.231344826","rc":[{"batb":[[0,2.14,35.43],[1,1.74,17.32],[2,1.44,85.28]],"ltp":2.32,"tv":1.31,"id":424676}]}]}
{"op":"mcm","clk":"11776736321","pt":1722710780151,"mc":[{"id":"1.231344826","rc":[{"trd":[[1.8,101.32]],"batl":[[0,1.8,49.17]],"ltp":1.8,"tv":107.05,"id":2780},{"trd":[[2.24,0.27]],"batb":[[0,2.16,12],[1,2.14,35.43],[2,1.74,17.32]],"ltp":2.24,"tv":1.58,"id":424676}],"tv":108.63}]}
{"op":"mcm","clk":"11776736757","pt":1722710782449,"mc":[{"id":"1.231344826","rc":[{"batb":[[0,2.16,10]],"ltp":2.24,"tv":1.58,"id":424676}]}]}
{"op":"mcm","clk":"11776736934","pt":1722710783464,"mc":[{"id":"1.231344826","rc":[{"batb":[[0,2.14,35.43],[1,1.74,17.32],[2,1.44,85.28]],"ltp":2.24,"tv":1.58,"id":424676}]}]}
{"op":"mcm","clk":"11776742572","pt":1722710816396,"mc":[{"id":"1.231344826","rc":[{"batb":[[0,2.16,12],[1,2.14,35.43],[2,1.74,17.32]],"batl":[[0,2.7,473.58]],"ltp":2.24,"tv":1.58,"id":424676}]}]}
{"op":"mcm","clk":"11776742992","pt":1722710818814,"mc":[{"id":"1.231344826","rc":[{"batb":[[0,2.16,10]],"ltp":2.24,"tv":1.58,"id":424676}]}]}
{"op":"mcm","clk":"11776743149","pt":1722710819828,"mc":[{"id":"1.231344826","rc":[{"batb":[[0,2.14,35.43],[1,1.74,17.32],[2,1.44,85.28]],"ltp":2.24,"tv":1.58,"id":424676}]}]}
{"op":"mcm","clk":"11776745482","pt":1722710833187,"mc":[{"id":"1.231344826","rc":[{"batb":[[0,2.16,12],[1,2.14,35.43],[2,1.74,17.32]],"batl":[[1,3,0.55]],"ltp":2.24,"tv":1.58,"id":424676}]}]}
{"op":"mcm","clk":"11776745898","pt":1722710835620,"mc":[{"id":"1.231344826","rc":[{"batb":[[0,2.16,10]],"ltp":2.24,"tv":1.58,"id":424676}]}]}
{"op":"mcm","clk":"11776746073","pt":1722710836623,"mc":[{"id":"1.231344826","rc":[{"batb":[[0,2.14,35.43],[1,1.74,17.32],[2,1.44,85.28]],"ltp":2.24,"tv":1.58,"id":424676}]}]}
{"op":"mcm","clk":"11776748830","pt":1722710851441,"mc":[{"id":"1.231344826","rc":[{"batb":[[0,2.16,12],[1,2.14,35.43],[2,1.74,17.32]],"batl":[[1,4,0.82]],"ltp":2.24,"tv":1.58,"id":424676}]}]}
{"op":"mcm","clk":"11776749184","pt":1722710853630,"mc":[{"id":"1.231344826","rc":[{"batb":[[0,2.16,10]],"ltp":2.24,"tv":1.58,"id":424676}]}]}
{"op":"mcm","clk":"11776749371","pt":1722710854738,"mc":[{"id":"1.231344826","rc":[{"batb":[[0,2.14,35.43],[1,1.74,17.32],[2,1.44,85.28]],"ltp":2.24,"tv":1.58,"id":424676}]}]}
{"op":"mcm","clk":"11776750723","pt":1722710863140,"mc":[{"id":"1.231344826","rc":[{"batb":[[0,2.16,12],[1,2.14,35.43],[2,1.74,17.32]],"batl":[[1,5,1.09]],"ltp":2.24,"tv":1.58,"id":424676}]}]}
{"op":"mcm","clk":"11776751277","pt":1722710866525,"mc":[{"id":"1.231344826","rc":[{"batb":[[0,2.14,35.43],[1,1.74,17.32],[2,1.44,85.28]],"ltp":2.24,"tv":1.58,"id":424676}]}]}
{"op":"mcm","clk":"11776753380","pt":1722710879257,"mc":[{"id":"1.231344826","rc":[{"batb":[[0,2.16,12],[1,2.14,35.43],[2,1.74,17.32]],"batl":[[0,4,1.09],[1,6.6,0.82]],"ltp":2.24,"tv":1.58,"id":424676}]}]}
{"op":"mcm","clk":"11776753778","pt":1722710881645,"mc":[{"id":"1.231344826","rc":[{"batb":[[0,2.16,10]],"ltp":2.24,"tv":1.58,"id":424676}]}]}
{"op":"mcm","clk":"11776753940","pt":1722710882548,"mc":[{"id":"1.231344826","rc":[{"batb":[[0,2.14,35.43],[1,1.74,17.32],[2,1.44,85.28]],"ltp":2.24,"tv":1.58,"id":424676}]}]}
{"op":"mcm","clk":"11776755938","pt":1722710894070,"mc":[{"id":"1.231344826","rc":[{"batb":[[0,2.16,12],[1,2.14,35.43],[2,1.74,17.32]],"batl":[[1,8,1.09]],"ltp":2.24,"tv":1.58,"id":424676}]}]}
{"op":"mcm","clk":"11776756308","pt":1722710896250,"mc":[{"id":"1.231344826","rc":[{"batb":[[0,2.16,10]],"ltp":2.24,"tv":1.58,"id":424676}]}]}
{"op":"mcm","clk":"11776756497","pt":1722710897455,"mc":[{"id":"1.231344826","rc":[{"batb":[[0,2.14,35.43],[1,1.74,17.32],[2,1.44,85.28]],"ltp":2.24,"tv":1.58,"id":424676}]}]}
{"op":"mcm","clk":"11776758435","pt":1722710908075,"mc":[{"id":"1.231344826","rc":[{"batb":[[0,2.16,12],[1,2.14,35.43],[2,1.74,17.32]],"batl":[[2,10,0.55]],"ltp":2.24,"tv":1.58,"id":424676}]}]}
{"op":"mcm","clk":"11776758812","pt":1722710910351,"mc":[{"id":"1.231344826","rc":[{"batb":[[0,2.16,10]],"ltp":2.24,"tv":1.58,"id":424676}]}]}
{"op":"mcm","clk":"11776758956","pt":1722710911295,"mc":[{"id":"1.231344826","rc":[{"batb":[[0,2.14,35.43],[1,1.74,17.32],[2,1.44,85.28]],"ltp":2.24,"tv":1.58,"id":424676}]}]}
{"op":"mcm","clk":"11776760394","pt":1722710920187,"mc":[{"id":"1.231344826","rc":[{"batb":[[0,2.16,12],[1,2.14,35.43],[2,1.74,17.32]],"batl":[[2,13,0.73]],"ltp":2.24,"tv":1.58,"id":424676}]}]}
{"op":"mcm","clk":"11776760769","pt":1722710922385,"mc":[{"id":"1.231344826","rc":[{"batb":[[0,2.16,10]],"ltp":2.24,"tv":1.58,"id":424676}]}]}
{"op":"mcm","clk":"11776760981","pt":1722710923509,"mc":[{"id":"1.231344826","rc":[{"batb":[[0,2.14,35.43],[1,1.74,17.32],[2,1.44,85.28]],"ltp":2.24,"tv":1.58,"id":424676}]}]}
{"op":"mcm","clk":"11776762417","pt":1722710933281,"mc":[{"id":"1.231344826","rc":[{"batb":[[0,2.16,12],[1,2.14,35.43],[2,1.74,17.32]],"batl":[[2,16.5,0.91]],"ltp":2.24,"tv":1.58,"id":424676}]}]}
{"op":"mcm","clk":"11776762718","pt":1722710935496,"mc":[{"id":"1.231344826","rc":[{"batb":[[0,2.16,10]],"ltp":2.24,"tv":1.58,"id":424676}]}]}
{"op":"mcm","clk":"11776762894","pt":1722710936810,"mc":[{"id":"1.231344826","rc":[{"batb":[[0,2.14,35.43],[1,1.74,17.32],[2,1.44,85.28]],"ltp":2.24,"tv":1.58,"id":424676}]}]}
{"op":"mcm","clk":"11776765156","pt":1722710952096,"mc":[{"id":"1.231344826","rc":[{"batb":[[0,2.16,12],[1,2.14,35.43],[2,1.74,17.32]],"batl":[[2,20,1.45]],"ltp":2.24,"tv":1.58,"id":424676}]}]}
{"op":"mcm","clk":"11776765559","pt":1722710954309,"mc":[{"id":"1.231344826","rc":[{"batb":[[0,2.16,10]],"ltp":2.24,"tv":1.58,"id":424676}]}]}
{"op":"mcm","clk":"11776765749","pt":1722710955519,"mc":[{"id":"1.231344826","rc":[{"batb":[[0,2.14,35.43],[1,1.74,17.32],[2,1.44,85.28]],"ltp":2.24,"tv":1.58,"id":424676}]}]}
{"op":"mcm","clk":"11776767663","pt":1722710967145,"mc":[{"id":"1.231344826","rc":[{"batb":[[0,2.16,12],[1,2.14,35.43],[2,1.74,17.32]],"ltp":2.24,"tv":1.58,"id":424676}]}]}
{"op":"mcm","clk":"11776767982","pt":1722710969371,"mc":[{"id":"1.231344826","rc":[{"batb":[[0,2.16,10]],"ltp":2.24,"tv":1.58,"id":424676}]}]}
{"op":"mcm","clk":"11776768164","pt":1722710970447,"mc":[{"id":"1.231344826","rc":[{"batb":[[0,2.14,35.43],[1,1.74,17.32],[2,1.44,85.28]],"ltp":2.24,"tv":1.58,"id":424676}]}]}
{"op":"mcm","clk":"11776769714","pt":1722710980118,"mc":[{"id":"1.231344826","rc":[{"batb":[[0,2.16,12],[1,2.14,35.43],[2,1.74,17.32]],"ltp":2.24,"tv":1.58,"id":424676}]}]}
{"op":"mcm","clk":"11776770278","pt":1722710983454,"mc":[{"id":"1.231344826","rc":[{"batb":[[0,2.14,35.43],[1,1.74,17.32],[2,1.44,85.28]],"ltp":2.24,"tv":1.58,"id":424676}]}]}
{"op":"mcm","clk":"11776771906","pt":1722710993158,"mc":[{"id":"1.231344826","rc":[{"batb":[[0,2.16,12],[1,2.14,35.43],[2,1.74,17.32]],"ltp":2.24,"tv":1.58,"id":424676}]}]}
{"op":"mcm","clk":"11776772274","pt":1722710995533,"mc":[{"id":"1.231344826","rc":[{"batb":[[0,2.16,10]],"ltp":2.24,"tv":1.58,"id":424676}]}]}
{"op":"mcm","clk":"11776772408","pt":1722710996485,"mc":[{"id":"1.231344826","rc":[{"batb":[[0,2.14,35.43],[1,1.74,17.32],[2,1.44,85.28]],"ltp":2.24,"tv":1.58,"id":424676}]}]}
{"op":"mcm","clk":"11776774013","pt":1722711006192,"mc":[{"id":"1.231344826","rc":[{"batb":[[0,2.16,12],[1,2.14,35.43],[2,1.74,17.32]],"ltp":2.24,"tv":1.58,"id":424676}]}]}
{"op":"mcm","clk":"11776774406","pt":1722711008583,"mc":[{"id":"1.231344826","rc":[{"batb":[[0,2.16,10]],"ltp":2.24,"tv":1.58,"id":424676}]}]}
{"op":"mcm","clk":"11776774579","pt":1722711009581,"mc":[{"id":"1.231344826","rc":[{"batb":[[0,2.14,35.43],[1,1.74,17.32],[2,1.44,85.28]],"ltp":2.24,"tv":1.58,"id":424676}]}]}
{"op":"mcm","clk":"11776777505","pt":1722711026701,"mc":[{"id":"1.231344826","rc":[{"batb":[[0,2.16,12],[1,2.14,35.43],[2,1.74,17.32]],"ltp":2.24,"tv":1.58,"id":424676}]}]}
{"op":"mcm","clk":"11776777860","pt":1722711028900,"mc":[{"id":"1.231344826","rc":[{"batb":[[0,2.16,10]],"ltp":2.24,"tv":1.58,"id":424676}]}]}
{"op":"mcm","clk":"11776778084","pt":1722711030227,"mc":[{"id":"1.231344826","rc":[{"batb":[[0,2.14,35.43],[1,1.74,17.32],[2,1.44,85.28]],"ltp":2.24,"tv":1.58,"id":424676}]}]}
{"op":"mcm","clk":"11776779584","pt":1722711038396,"mc":[{"id":"1.231344826","rc":[{"batb":[[0,2.16,12],[1,2.14,35.43],[2,1.74,17.32]],"ltp":2.24,"tv":1.58,"id":424676}]}]}
{"op":"mcm","clk":"11776779909","pt":1722711040595,"mc":[{"id":"1.231344826","rc":[{"batb":[[0,2.16,10]],"ltp":2.24,"tv":1.58,"id":424676}]}]}
{"op":"mcm","clk":"11776780109","pt":1722711041809,"mc":[{"id":"1.231344826","rc":[{"batb":[[0,2.14,35.43],[1,1.74,17.32],[2,1.44,85.28]],"ltp":2.24,"tv":1.58,"id":424676}]}]}
{"op":"mcm","clk":"11776781610","pt":1722711051212,"mc":[{"id":"1.231344826","rc":[{"batb":[[0,2.16,12],[1,2.14,35.43],[2,1.74,17.32]],"ltp":2.24,"tv":1.58,"id":424676}]}]}
{"op":"mcm","clk":"11776782112","pt":1722711054410,"mc":[{"id":"1.231344826","rc":[{"batb":[[0,2.14,35.43],[1,1.74,17.32],[2,1.44,85.28]],"ltp":2.24,"tv":1.58,"id":424676}]}]}
{"op":"mcm","clk":"11776783997","pt":1722711066137,"mc":[{"id":"1.231344826","rc":[{"batb":[[0,2.16,12],[1,2.14,35.43],[2,1.74,17.32]],"ltp":2.24,"tv":1.58,"id":424676}]}]}
{"op":"mcm","clk":"11776784371","pt":1722711068553,"mc":[{"id":"1.231344826","rc":[{"batb":[[0,2.16,10]],"ltp":2.24,"tv":1.58,"id":424676}]}]}
{"op":"mcm","clk":"11776784522","pt":1722711069554,"mc":[{"id":"1.231344826","rc":[{"batb":[[0,2.14,35.43],[1,1.74,17.32],[2,1.44,85.28]],"ltp":2.24,"tv":1.58,"id":424676}]}]}
{"op":"mcm","clk":"11776818136","pt":1722711292968,"mc":[{"id":"1.231344826","rc":[{"batb":[[0,2.16,12],[1,2.14,35.43],[2,1.74,17.32]],"ltp":2.24,"tv":1.58,"id":424676}]}]}
{"op":"mcm","clk":"11776818473","pt":1722711295351,"mc":[{"id":"1.231344826","rc":[{"batb":[[0,2.16,10]],"ltp":2.24,"tv":1.58,"id":424676}]}]}
{"op":"mcm","clk":"11776818633","pt":1722711296458,"mc":[{"id":"1.231344826","rc":[{"batb":[[0,2.14,35.43],[1,1.74,17.32],[2,1.44,85.28]],"ltp":2.24,"tv":1.58,"id":424676}]}]}
{"op":"mcm","clk":"11776833986","pt":1722711408399,"mc":[{"id":"1.231344826","rc":[{"batb":[[0,2.16,12],[1,2.14,35.43],[2,1.74,17.32]],"ltp":2.24,"tv":1.58,"id":424676}]}]}
{"op":"mcm","clk":"11776834321","pt":1722711410869,"mc":[{"id":"1.231344826","rc":[{"batb":[[0,2.16,10]],"ltp":2.24,"tv":1.58,"id":424676}]}]}
{"op":"mcm","clk":"11776834465","pt":1722711411911,"mc":[{"id":"1.231344826","rc":[{"batb":[[0,2.14,35.43],[1,1.74,17.32],[2,1.44,85.28]],"ltp":2.24,"tv":1.58,"id":424676}]}]}
{"op":"mcm","clk":"11776836907","pt":1722711429288,"mc":[{"id":"1.231344826","rc":[{"batb":[[0,2.16,12],[1,2.14,35.43],[2,1.74,17.32]],"ltp":2.24,"tv":1.58,"id":424676}]}]}
{"op":"mcm","clk":"11776837217","pt":1722711431495,"mc":[{"id":"1.231344826","rc":[{"batb":[[0,2.16,10]],"ltp":2.24,"tv":1.58,"id":424676}]}]}
{"op":"mcm","clk":"11776837360","pt":1722711432510,"mc":[{"id":"1.231344826","rc":[{"batb":[[0,2.14,35.43],[1,1.74,17.32],[2,1.44,85.28]],"ltp":2.24,"tv":1.58,"id":424676}]}]}
{"op":"mcm","clk":"11776837761","pt":1722711435324,"mc":[{"id":"1.231344826","rc":[{"batb":[[0,2.16,12],[1,2.14,35.43],[2,1.74,17.32]],"ltp":2.24,"tv":1.58,"id":424676}]}]}
{"op":"mcm","clk":"11776838142","pt":1722711437602,"mc":[{"id":"1.231344826","rc":[{"batb":[[0,2.16,10]],"ltp":2.24,"tv":1.58,"id":424676}]}]}
{"op":"mcm","clk":"11776838294","pt":1722711438600,"mc":[{"id":"1.231344826","rc":[{"batb":[[0,2.14,35.43],[1,1.74,17.32],[2,1.44,85.28]],"ltp":2.24,"tv":1.58,"id":424676}]}]}
{"op":"mcm","clk":"11776838881","pt":1722711442516,"mc":[{"id":"1.231344826","rc":[{"batb":[[0,2.18,2],[1,2.16,10],[2,2.14,35.43]],"ltp":2.24,"tv":1.58,"id":424676}]}]}
{"op":"mcm","clk":"11776839234","pt":1722711444938,"mc":[{"id":"1.231344826","rc":[{"batb":[[0,2.16,10],[1,2.14,35.43],[2,1.74,17.32]],"ltp":2.24,"tv":1.58,"id":424676}]}]}
{"op":"mcm","clk":"11776839343","pt":1722711445726,"mc":[{"id":"1.231344826","rc":[{"batb":[[0,2.14,35.43],[1,1.74,17.32],[2,1.44,85.28]],"ltp":2.24,"tv":1.58,"id":424676}]}]}
{"op":"mcm","clk":"11776839860","pt":1722711449208,"mc":[{"id":"1.231344826","rc":[{"batb":[[0,2.16,12],[1,2.14,35.43],[2,1.74,17.32]],"ltp":2.24,"tv":1.58,"id":424676}]}]}
{"op":"mcm","clk":"11776840194","pt":1722711451441,"mc":[{"id":"1.231344826","rc":[{"batb":[[0,2.16,10]],"ltp":2.24,"tv":1.58,"id":424676}]}]}
{"op":"mcm","clk":"11776840369","pt":1722711452638,"mc":[{"id":"1.231344826","rc":[{"batb":[[0,2.14,35.43],[1,1.74,17.32],[2,1.44,85.28]],"ltp":2.24,"tv":1.58,"id":424676}]}]}
{"op":"mcm","clk":"11776840893","pt":1722711456136,"mc":[{"id":"1.231344826","rc":[{"batb":[[0,2.16,12],[1,2.14,35.43],[2,1.74,17.32]],"ltp":2.24,"tv":1.58,"id":424676}]}]}
{"op":"mcm","clk":"11776841429","pt":1722711459541,"mc":[{"id":"1.231344826","rc":[{"batb":[[0,2.14,35.43],[1,1.74,17.32],[2,1.44,85.28]],"ltp":2.24,"tv":1.58,"id":424676}]}]}
{"op":"mcm","clk":"11776841821","pt":1722711462151,"mc":[{"id":"1.231344826","rc":[{"batb":[[0,2.16,12],[1,2.14,35.43],[2,1.74,17.32]],"ltp":2.24,"tv":1.58,"id":424676}]}]}
{"op":"mcm","clk":"11776842213","pt":1722711464426,"mc":[{"id":"1.231344826","rc":[{"batb":[[0,2.16,10]],"ltp":2.24,"tv":1.58,"id":424676}]}]}
{"op":"mcm","clk":"11776842361","pt":1722711465374,"mc":[{"id":"1.231344826","rc":[{"batb":[[0,2.14,35.43],[1,1.74,17.32],[2,1.44,85.28]],"ltp":2.24,"tv":1.58,"id":424676}]}]}
{"op":"mcm","clk":"11776842787","pt":1722711468260,"mc":[{"id":"1.231344826","rc":[{"batb":[[0,2.16,12],[1,2.14,35.43],[2,1.74,17.32]],"ltp":2.24,"tv":1.58,"id":424676}]}]}
{"op":"mcm","clk":"11776843272","pt":1722711471543,"mc":[{"id":"1.231344826","rc":[{"batb":[[0,2.14,35.43],[1,1.74,17.32],[2,1.44,85.28]],"ltp":2.24,"tv":1.58,"id":424676}]}]}
{"op":"mcm","clk":"11776843619","pt":1722711474223,"mc":[{"id":"1.231344826","rc":[{"batb":[[0,2.16,12],[1,2.14,35.43],[2,1.74,17.32]],"ltp":2.24,"tv":1.58,"id":424676}]}]}
{"op":"mcm","clk":"11776843962","pt":1722711476562,"mc":[{"id":"1.231344826","rc":[{"batb":[[0,2.16,10]],"ltp":2.24,"tv":1.58,"id":424676}]}]}
{"op":"mcm","clk":"11776844093","pt":1722711477567,"mc":[{"id":"1.231344826","rc":[{"batb":[[0,2.14,35.43],[1,1.74,17.32],[2,1.44,85.28]],"ltp":2.24,"tv":1.58,"id":424676}]}]}
{"op":"mcm","clk":"11776844501","pt":1722711480340,"mc":[{"id":"1.231344826","rc":[{"batb":[[0,2.16,12],[1,2.14,35.43],[2,1.74,17.32]],"ltp":2.24,"tv":1.58,"id":424676}]}]}
{"op":"mcm","clk":"11776844854","pt":1722711482541,"mc":[{"id":"1.231344826","rc":[{"batb":[[0,2.16,10]],"ltp":2.24,"tv":1.58,"id":424676}]}]}
{"op":"mcm","clk":"11776845034","pt":1722711483750,"mc":[{"id":"1.231344826","rc":[{"batb":[[0,2.14,35.43],[1,1.74,17.32],[2,1.44,85.28]],"ltp":2.24,"tv":1.58,"id":424676}]}]}
{"op":"mcm","clk":"11776845387","pt":1722711486185,"mc":[{"id":"1.231344826","rc":[{"batb":[[0,2.16,12],[1,2.14,35.43],[2,1.74,17.32]],"ltp":2.24,"tv":1.58,"id":424676}]}]}
{"op":"mcm","clk":"11776845771","pt":1722711488554,"mc":[{"id":"1.231344826","rc":[{"batb":[[0,2.16,10]],"ltp":2.24,"tv":1.58,"id":424676}]}]}
{"op":"mcm","clk":"11776845913","pt":1722711489550,"mc":[{"id":"1.231344826","rc":[{"batb":[[0,2.14,35.43],[1,1.74,17.32],[2,1.44,85.28]],"ltp":2.24,"tv":1.58,"id":424676}]}]}
{"op":"mcm","clk":"11776846420","pt":1722711493145,"mc":[{"id":"1.231344826","rc":[{"batb":[[0,2.16,12],[1,2.14,35.43],[2,1.74,17.32]],"ltp":2.24,"tv":1.58,"id":424676}]}]}
{"op":"mcm","clk":"11776846763","pt":1722711495451,"mc":[{"id":"1.231344826","rc":[{"batb":[[0,2.16,10]],"ltp":2.24,"tv":1.58,"id":424676}]}]}
{"op":"mcm","clk":"11776846886","pt":1722711496497,"mc":[{"id":"1.231344826","rc":[{"batb":[[0,2.14,35.43],[1,1.74,17.32],[2,1.44,85.28]],"ltp":2.24,"tv":1.58,"id":424676}]}]}
{"op":"mcm","clk":"11776847105","pt":1722711498284,"mc":[{"id":"1.231344826","rc":[{"batb":[[0,2.16,2],[1,2.14,35.43],[2,1.74,17.32]],"ltp":2.24,"tv":1.58,"id":424676}]}]}
{"op":"mcm","clk":"11776847403","pt":1722711500483,"mc":[{"id":"1.231344826","rc":[{"batb":[[0,2.14,35.43],[1,1.74,17.32],[2,1.44,85.28]],"ltp":2.24,"tv":1.58,"id":424676}]}]}
{"op":"mcm","clk":"11776847429","pt":1722711500694,"mc":[{"id":"1.231344826","rc":[{"batb":[[0,2.16,10],[1,2.14,35.43],[2,1.74,17.32]],"ltp":2.24,"tv":1.58,"id":424676}]}]}
{"op":"mcm","clk":"11776847889","pt":1722711504177,"mc":[{"id":"1.231344826","rc":[{"batb":[[0,2.16,2]],"ltp":2.24,"tv":1.58,"id":424676}]}]}
{"op":"mcm","clk":"11776848215","pt":1722711506659,"mc":[{"id":"1.231344826","rc":[{"batb":[[0,2.16,10]],"ltp":2.24,"tv":1.58,"id":424676}]}]}
{"op":"mcm","clk":"11776848585","pt":1722711509177,"mc":[{"id":"1.231344826","rc":[{"batb":[[0,2.18,2],[1,2.16,10],[2,2.14,35.43]],"ltp":2.24,"tv":1.58,"id":424676}]}]}
{"op":"mcm","clk":"11776848719","pt":1722711510180,"mc":[{"id":"1.231344826","rc":[{"batb":[[1,2.14,35.43],[2,1.74,17.32]],"ltp":2.24,"tv":1.58,"id":424676}]}]}
{"op":"mcm","clk":"11776848917","pt":1722711511560,"mc":[{"id":"1.231344826","rc":[{"batb":[[0,2.14,35.43],[1,1.74,17.32],[2,1.44,85.28]],"ltp":2.24,"tv":1.58,"id":424676}]}]}
{"op":"mcm","clk":"11776849488","pt":1722711515366,"mc":[{"id":"1.231344826","rc":[{"batb":[[0,2.16,12],[1,2.14,35.43],[2,1.74,17.32]],"ltp":2.24,"tv":1.58,"id":424676}]}]}
{"op":"mcm","clk":"11776849797","pt":1722711517669,"mc":[{"id":"1.231344826","rc":[{"batb":[[0,2.16,10]],"ltp":2.24,"tv":1.58,"id":424676}]}]}
{"op":"mcm","clk":"11776849938","pt":1722711518718,"mc":[{"id":"1.231344826","rc":[{"batb":[[0,2.14,35.43],[1,1.74,17.32],[2,1.44,85.28]],"ltp":2.24,"tv":1.58,"id":424676}]}]}
{"op":"mcm","clk":"11776850272","pt":1722711521200,"mc":[{"id":"1.231344826","rc":[{"batb":[[0,2.16,12],[1,2.14,35.43],[2,1.74,17.32]],"ltp":2.24,"tv":1.58,"id":424676}]}]}
{"op":"mcm","clk":"11776850623","pt":1722711523769,"mc":[{"id":"1.231344826","rc":[{"batb":[[0,2.16,10]],"ltp":2.24,"tv":1.58,"id":424676}]}]}
{"op":"mcm","clk":"11776850748","pt":1722711524819,"mc":[{"id":"1.231344826","rc":[{"batb":[[0,2.14,35.43],[1,1.74,17.32],[2,1.44,85.28]],"ltp":2.24,"tv":1.58,"id":424676}]}]}
{"op":"mcm","clk":"11776851098","pt":1722711527399,"mc":[{"id":"1.231344826","rc":[{"batb":[[0,2.16,12],[1,2.14,35.43],[2,1.74,17.32]],"ltp":2.24,"tv":1.58,"id":424676}]}]}
{"op":"mcm","clk":"11776851393","pt":1722711529713,"mc":[{"id":"1.231344826","rc":[{"batb":[[0,2.16,10]],"ltp":2.24,"tv":1.58,"id":424676}]}]}
{"op":"mcm","clk":"11776851561","pt":1722711530943,"mc":[{"id":"1.231344826","rc":[{"batb":[[0,2.14,35.43],[1,1.74,17.32],[2,1.44,85.28]],"ltp":2.24,"tv":1.58,"id":424676}]}]}
{"op":"mcm","clk":"11776851889","pt":1722711533518,"mc":[{"id":"1.231344826","rc":[{"batb":[[0,2.16,12],[1,2.14,35.43],[2,1.74,17.32]],"ltp":2.24,"tv":1.58,"id":424676}]}]}
{"op":"mcm","clk":"11776852144","pt":1722711535614,"mc":[{"id":"1.231344826","rc":[{"batb":[[0,2.16,10]],"ltp":2.24,"tv":1.58,"id":424676}]}]}
{"op":"mcm","clk":"11776852298","pt":1722711536706,"mc":[{"id":"1.231344826","rc":[{"batb":[[0,2.14,35.43],[1,1.74,17.32],[2,1.44,85.28]],"ltp":2.24,"tv":1.58,"id":424676}]}]}
{"op":"mcm","clk":"11776863130","pt":1722711621313,"mc":[{"id":"1.231344826","rc":[{"batb":[[0,2.16,12],[1,2.14,35.43],[2,1.74,17.32]],"ltp":2.24,"tv":1.58,"id":424676}]}]}
{"op":"mcm","clk":"11776863483","pt":1722711623908,"mc":[{"id":"1.231344826","rc":[{"batb":[[0,2.16,10]],"ltp":2.24,"tv":1.58,"id":424676}]}]}
{"op":"mcm","clk":"11776863623","pt":1722711624802,"mc":[{"id":"1.231344826","rc":[{"batb":[[0,2.14,35.43],[1,1.74,17.32],[2,1.44,85.28]],"ltp":2.24,"tv":1.58,"id":424676}]}]}
{"op":"mcm","clk":"11777203310","pt":1722713999995,"mc":[{"id":"1.231344826","rc":[{"batb":[[0,2.16,12],[1,2.14,35.43],[2,1.74,17.32]],"ltp":2.24,"tv":1.58,"id":424676}]}]}
{"op":"mcm","clk":"11777203610","pt":1722714002505,"mc":[{"id":"1.231344826","rc":[{"batb":[[0,2.16,10]],"ltp":2.24,"tv":1.58,"id":424676}]}]}
{"op":"mcm","clk":"11777203724","pt":1722714003509,"mc":[{"id":"1.231344826","rc":[{"batb":[[0,2.14,35.43],[1,1.74,17.32],[2,1.44,85.28]],"ltp":2.24,"tv":1.58,"id":424676}]}]}
{"op":"mcm","clk":"11777219580","pt":1722714138816,"mc":[{"id":"1.231344826","rc":[{"batb":[[0,2.16,12],[1,2.14,35.43],[2,1.74,17.32]],"ltp":2.24,"tv":1.58,"id":424676}]}]}
{"op":"mcm","clk":"11777219870","pt":1722714141415,"mc":[{"id":"1.231344826","rc":[{"batb":[[0,2.16,10]],"ltp":2.24,"tv":1.58,"id":424676}]}]}
{"op":"mcm","clk":"11777219978","pt":1722714142325,"mc":[{"id":"1.231344826","rc":[{"batb":[[0,2.14,35.43],[1,1.74,17.32],[2,1.44,85.28]],"ltp":2.24,"tv":1.58,"id":424676}]}]}
{"op":"mcm","clk":"11777220162","pt":1722714143811,"mc":[{"id":"1.231344826","rc":[{"batb":[[0,2.16,2],[1,2.14,35.43],[2,1.74,17.32]],"ltp":2.24,"tv":1.58,"id":424676}]}]}
{"op":"mcm","clk":"11777220458","pt":1722714146530,"mc":[{"id":"1.231344826","rc":[{"batb":[[0,2.16,10]],"ltp":2.24,"tv":1.58,"id":424676}]}]}
{"op":"mcm","clk":"11777220867","pt":1722714150009,"mc":[{"id":"1.231344826","rc":[{"batb":[[0,2.16,2]],"ltp":2.24,"tv":1.58,"id":424676}]}]}
{"op":"mcm","clk":"11777221129","pt":1722714152338,"mc":[{"id":"1.231344826","rc":[{"batb":[[0,2.16,10]],"ltp":2.24,"tv":1.58,"id":424676}]}]}
{"op":"mcm","clk":"11777221456","pt":1722714155712,"mc":[{"id":"1.231344826","rc":[{"batb":[[0,2.16,2]],"ltp":2.24,"tv":1.58,"id":424676}]}]}
{"op":"mcm","clk":"11777221720","pt":1722714158112,"mc":[{"id":"1.231344826","rc":[{"batb":[[0,2.16,10]],"ltp":2.24,"tv":1.58,"id":424676}]}]}
{"op":"mcm","clk":"11777222084","pt":1722714161515,"mc":[{"id":"1.231344826","rc":[{"batb":[[0,2.16,2]],"ltp":2.24,"tv":1.58,"id":424676}]}]}
{"op":"mcm","clk":"11777222345","pt":1722714163826,"mc":[{"id":"1.231344826","rc":[{"batb":[[0,2.16,10]],"ltp":2.24,"tv":1.58,"id":424676}]}]}
{"op":"mcm","clk":"11777222579","pt":1722714165932,"mc":[{"id":"1.231344826","rc":[{"batb":[[0,2.18,2],[1,2.16,10],[2,2.14,35.43]],"ltp":2.24,"tv":1.58,"id":424676}]}]}
{"op":"mcm","clk":"11777222688","pt":1722714167030,"mc":[{"id":"1.231344826","rc":[{"batb":[[1,2.14,35.43],[2,1.74,17.32]],"ltp":2.24,"tv":1.58,"id":424676}]}]}
{"op":"mcm","clk":"11777222807","pt":1722714168339,"mc":[{"id":"1.231344826","rc":[{"batb":[[0,2.14,35.43],[1,1.74,17.32],[2,1.44,85.28]],"ltp":2.24,"tv":1.58,"id":424676}]}]}
{"op":"mcm","clk":"11777223058","pt":1722714170951,"mc":[{"id":"1.231344826","rc":[{"batb":[[0,2.16,12],[1,2.14,35.43],[2,1.74,17.32]],"ltp":2.24,"tv":1.58,"id":424676}]}]}
{"op":"mcm","clk":"11777223308","pt":1722714173431,"mc":[{"id":"1.231344826","rc":[{"batb":[[0,2.16,10]],"ltp":2.24,"tv":1.58,"id":424676}]}]}
{"op":"mcm","clk":"11777223405","pt":1722714174439,"mc":[{"id":"1.231344826","rc":[{"batb":[[0,2.14,35.43],[1,1.74,17.32],[2,1.44,85.28]],"ltp":2.24,"tv":1.58,"id":424676}]}]}
{"op":"mcm","clk":"11777232624","pt":1722714178153,"mc":[{"id":"1.231344826","rc":[{"batb":[[0,2.16,12],[1,2.14,35.43],[2,1.74,17.32]],"ltp":2.24,"tv":1.58,"id":424676}]}]}
{"op":"mcm","clk":"11777232867","pt":1722714180585,"mc":[{"id":"1.231344826","rc":[{"batb":[[0,2.16,10]],"ltp":2.24,"tv":1.58,"id":424676}]}]}
{"op":"mcm","clk":"11777232956","pt":1722714181569,"mc":[{"id":"1.231344826","rc":[{"batb":[[0,2.14,35.43],[1,1.74,17.32],[2,1.44,85.28]],"ltp":2.24,"tv":1.58,"id":424676}]}]}
{"op":"mcm","clk":"11777233741","pt":1722714188774,"mc":[{"id":"1.231344826","rc":[{"batb":[[0,2.16,12],[1,2.14,35.43],[2,1.74,17.32]],"ltp":2.24,"tv":1.58,"id":424676}]}]}
{"op":"mcm","clk":"11777233978","pt":1722714191242,"mc":[{"id":"1.231344826","rc":[{"batb":[[0,2.16,10]],"ltp":2.24,"tv":1.58,"id":424676}]}]}
{"op":"mcm","clk":"11777234083","pt":1722714192186,"mc":[{"id":"1.231344826","rc":[{"batb":[[0,2.14,35.43],[1,1.74,17.32],[2,1.44,85.28]],"ltp":2.24,"tv":1.58,"id":424676}]}]}
{"op":"mcm","clk":"11777234416","pt":1722714195487,"mc":[{"id":"1.231344826","rc":[{"batb":[[0,2.16,10],[1,2.14,35.43],[2,1.74,17.32]],"ltp":2.24,"tv":1.58,"id":424676}]}]}
{"op":"mcm","clk":"11777234428","pt":1722714195551,"mc":[{"id":"1.231344826","rc":[{"batb":[[0,2.16,12]],"ltp":2.24,"tv":1.58,"id":424676}]}]}
{"op":"mcm","clk":"11777234668","pt":1722714197869,"mc":[{"id":"1.231344826","rc":[{"batb":[[0,2.16,10]],"ltp":2.24,"tv":1.58,"id":424676}]}]}
{"op":"mcm","clk":"11777234760","pt":1722714198878,"mc":[{"id":"1.231344826","rc":[{"batb":[[0,2.14,35.43],[1,1.74,17.32],[2,1.44,85.28]],"ltp":2.24,"tv":1.58,"id":424676}]}]}
{"op":"mcm","clk":"11777235174","pt":1722714203022,"mc":[{"id":"1.231344826","rc":[{"batb":[[0,2.16,12],[1,2.14,35.43],[2,1.74,17.32]],"ltp":2.24,"tv":1.58,"id":424676}]}]}
{"op":"mcm","clk":"11777235423","pt":1722714205483,"mc":[{"id":"1.231344826","rc":[{"batb":[[0,2.16,10]],"ltp":2.24,"tv":1.58,"id":424676}]}]}
{"op":"mcm","clk":"11777235525","pt":1722714206385,"mc":[{"id":"1.231344826","rc":[{"batb":[[0,2.14,35.43],[1,1.74,17.32],[2,1.44,85.28]],"ltp":2.24,"tv":1.58,"id":424676}]}]}
{"op":"mcm","clk":"11777235935","pt":1722714210077,"mc":[{"id":"1.231344826","rc":[{"batb":[[0,2.16,12],[1,2.14,35.43],[2,1.74,17.32]],"ltp":2.24,"tv":1.58,"id":424676}]}]}
{"op":"mcm","clk":"11777236177","pt":1722714212385,"mc":[{"id":"1.231344826","rc":[{"batb":[[0,2.16,10]],"ltp":2.24,"tv":1.58,"id":424676}]}]}
{"op":"mcm","clk":"11777236287","pt":1722714213389,"mc":[{"id":"1.231344826","rc":[{"batb":[[0,2.14,35.43],[1,1.74,17.32],[2,1.44,85.28]],"ltp":2.24,"tv":1.58,"id":424676}]}]}
{"op":"mcm","clk":"11777236438","pt":1722714214809,"mc":[{"id":"1.231344826","rc":[{"batb":[[0,2.16,2],[1,2.14,35.43],[2,1.74,17.32]],"ltp":2.24,"tv":1.58,"id":424676}]}]}
{"op":"mcm","clk":"11777236700","pt":1722714217188,"mc":[{"id":"1.231344826","rc":[{"batb":[[0,2.16,10]],"ltp":2.24,"tv":1.58,"id":424676}]}]}
{"op":"mcm","clk":"11777237044","pt":1722714220396,"mc":[{"id":"1.231344826","rc":[{"batb":[[0,2.14,35.43],[1,1.74,17.32],[2,1.44,85.28]],"ltp":2.24,"tv":1.58,"id":424676}]}]}
{"op":"mcm","clk":"11777237063","pt":1722714220605,"mc":[{"id":"1.231344826","rc":[{"batb":[[0,2.16,2],[1,2.14,35.43],[2,1.74,17.32]],"ltp":2.24,"tv":1.58,"id":424676}]}]}
{"op":"mcm","clk":"11777237306","pt":1722714223192,"mc":[{"id":"1.231344826","rc":[{"batb":[[0,2.16,10]],"ltp":2.24,"tv":1.58,"id":424676}]}]}
{"op":"mcm","clk":"11777237524","pt":1722714225291,"mc":[{"id":"1.231344826","rc":[{"batb":[[0,2.18,2],[1,2.16,10],[2,2.14,35.43]],"ltp":2.24,"tv":1.58,"id":424676}]}]}
{"op":"mcm","clk":"11777237648","pt":1722714226610,"mc":[{"id":"1.231344826","rc":[{"batb":[[1,2.14,35.43],[2,1.74,17.32]],"ltp":2.24,"tv":1.58,"id":424676}]}]}
{"op":"mcm","clk":"11777237764","pt":1722714227808,"mc":[{"id":"1.231344826","rc":[{"batb":[[0,2.14,35.43],[1,1.74,17.32],[2,1.44,85.28]],"ltp":2.24,"tv":1.58,"id":424676}]}]}
{"op":"mcm","clk":"11777238099","pt":1722714231113,"mc":[{"id":"1.231344826","rc":[{"batb":[[0,2.16,12],[1,2.14,35.43],[2,1.74,17.32]],"ltp":2.24,"tv":1.58,"id":424676}]}]}
{"op":"mcm","clk":"11777238365","pt":1722714233501,"mc":[{"id":"1.231344826","rc":[{"batb":[[0,2.16,10]],"ltp":2.24,"tv":1.58,"id":424676}]}]}
{"op":"mcm","clk":"11777238441","pt":1722714234320,"mc":[{"id":"1.231344826","rc":[{"batb":[[0,2.14,35.43],[1,1.74,17.32],[2,1.44,85.28]],"ltp":2.24,"tv":1.58,"id":424676}]}]}
{"op":"mcm","clk":"11777238636","pt":1722714236424,"mc":[{"id":"1.231344826","rc":[{"batb":[[0,2.16,2],[1,2.14,35.43],[2,1.74,17.32]],"ltp":2.24,"tv":1.58,"id":424676}]}]}
{"op":"mcm","clk":"11777238871","pt":1722714238741,"mc":[{"id":"1.231344826","rc":[{"batb":[[0,2.16,10]],"ltp":2.24,"tv":1.58,"id":424676}]}]}
{"op":"mcm","clk":"11777239241","pt":1722714242399,"mc":[{"id":"1.231344826","rc":[{"batb":[[0,2.16,2]],"ltp":2.24,"tv":1.58,"id":424676}]}]}
{"op":"mcm","clk":"11777239482","pt":1722714244822,"mc":[{"id":"1.231344826","rc":[{"batb":[[0,2.16,10]],"ltp":2.24,"tv":1.58,"id":424676}]}]}
{"op":"mcm","clk":"11777239825","pt":1722714248225,"mc":[{"id":"1.231344826","rc":[{"batb":[[0,2.18,2]],"ltp":2.24,"tv":1.58,"id":424676}]}]}
{"op":"mcm","clk":"11777240005","pt":1722714250019,"mc":[{"id":"1.231344826","rc":[{"batb":[[0,2.14,35.43],[1,1.74,17.32],[2,1.44,85.28]],"ltp":2.24,"tv":1.58,"id":424676}]}]}
{"op":"mcm","clk":"11777240147","pt":1722714251226,"mc":[{"id":"1.231344826","rc":[{"batb":[[0,2.16,10],[1,2.14,35.43],[2,1.74,17.32]],"ltp":2.24,"tv":1.58,"id":424676}]}]}
{"op":"mcm","clk":"11777240317","pt":1722714253007,"mc":[{"id":"1.231344826","rc":[{"batb":[[0,2.18,2],[1,2.16,10],[2,2.14,35.43]],"ltp":2.24,"tv":1.58,"id":424676}]}]}
{"op":"mcm","clk":"11777240560","pt":1722714255519,"mc":[{"id":"1.231344826","rc":[{"batb":[[0,2.14,35.43],[1,1.74,17.32],[2,1.44,85.28]],"ltp":2.24,"tv":1.58,"id":424676}]}]}
{"op":"mcm","clk":"11777240922","pt":1722714259023,"mc":[{"id":"1.231344826","rc":[{"batb":[[0,2.16,12],[1,2.14,35.43],[2,1.74,17.32]],"ltp":2.24,"tv":1.58,"id":424676}]}]}
{"op":"mcm","clk":"11777241174","pt":1722714261432,"mc":[{"id":"1.231344826","rc":[{"batb":[[0,2.16,10]],"ltp":2.24,"tv":1.58,"id":424676}]}]}
{"op":"mcm","clk":"11777241277","pt":1722714262426,"mc":[{"id":"1.231344826","rc":[{"batb":[[0,2.14,35.43],[1,1.74,17.32],[2,1.44,85.28]],"ltp":2.24,"tv":1.58,"id":424676}]}]}
{"op":"mcm","clk":"11777241730","pt":1722714266660,"mc":[{"id":"1.231344826","rc":[{"batb":[[0,2.16,12],[1,2.14,35.43],[2,1.74,17.32]],"ltp":2.24,"tv":1.58,"id":424676}]}]}
{"op":"mcm","clk":"11777241993","pt":1722714268960,"mc":[{"id":"1.231344826","rc":[{"batb":[[0,2.16,10]],"ltp":2.24,"tv":1.58,"id":424676}]}]}
{"op":"mcm","clk":"11777242083","pt":1722714269850,"mc":[{"id":"1.231344826","rc":[{"batb":[[0,2.14,35.43],[1,1.74,17.32],[2,1.44,85.28]],"ltp":2.24,"tv":1.58,"id":424676}]}]}
{"op":"mcm","clk":"11777242231","pt":1722714271229,"mc":[{"id":"1.231344826","rc":[{"batb":[[0,2.16,2],[1,2.14,35.43],[2,1.74,17.32]],"ltp":2.24,"tv":1.58,"id":424676}]}]}
{"op":"mcm","clk":"11777242548","pt":1722714273871,"mc":[{"id":"1.231344826","rc":[{"batb":[[0,2.16,10]],"ltp":2.24,"tv":1.58,"id":424676}]}]}
{"op":"mcm","clk":"11777242899","pt":1722714277279,"mc":[{"id":"1.231344826","rc":[{"batb":[[0,2.16,2]],"ltp":2.24,"tv":1.58,"id":424676}]}]}
{"op":"mcm","clk":"11777243202","pt":1722714280353,"mc":[{"id":"1.231344826","rc":[{"batb":[[0,2.16,10]],"ltp":2.24,"tv":1.58,"id":424676}]}]}
{"op":"mcm","clk":"11777243490","pt":1722714283070,"mc":[{"id":"1.231344826","rc":[{"batb":[[0,2.18,2],[1,2.16,10],[2,2.14,35.43]],"ltp":2.24,"tv":1.58,"id":424676}]}]}
{"op":"mcm","clk":"11777243576","pt":1722714283862,"mc":[{"id":"1.231344826","rc":[{"batb":[[1,2.14,35.43],[2,1.74,17.32]],"ltp":2.24,"tv":1.58,"id":424676}]}]}
{"op":"mcm","clk":"11777243716","pt":1722714285272,"mc":[{"id":"1.231344826","rc":[{"batb":[[0,2.14,35.43],[1,1.74,17.32],[2,1.44,85.28]],"ltp":2.24,"tv":1.58,"id":424676}]}]}
{"op":"mcm","clk":"11777244189","pt":1722714289681,"mc":[{"id":"1.231344826","rc":[{"batb":[[0,2.16,12],[1,2.14,35.43],[2,1.74,17.32]],"ltp":2.24,"tv":1.58,"id":424676}]}]}
{"op":"mcm","clk":"11777244433","pt":1722714292089,"mc":[{"id":"1.231344826","rc":[{"batb":[[0,2.16,10]],"ltp":2.24,"tv":1.58,"id":424676}]}]}
{"op":"mcm","clk":"11777244640","pt":1722714294898,"mc":[{"id":"1.231344826","rc":[{"batb":[[0,2.18,2]],"ltp":2.24,"tv":1.58,"id":424676}]}]}
{"op":"mcm","clk":"11777244873","pt":1722714296471,"mc":[{"id":"1.231344826","rc":[{"batb":[[0,2.14,35.43],[1,1.74,17.32],[2,1.44,85.28]],"ltp":2.24,"tv":1.58,"id":424676}]}]}
{"op":"mcm","clk":"11777244884","pt":1722714296578,"mc":[{"id":"1.231344826","rc":[{"batb":[[0,2.16,10],[1,2.14,35.43],[2,1.74,17.32]],"ltp":2.24,"tv":1.58,"id":424676}]}]}
{"op":"mcm","clk":"11777245255","pt":1722714300089,"mc":[{"id":"1.231344826","rc":[{"batb":[[0,2.16,2]],"ltp":2.24,"tv":1.58,"id":424676}]}]}
{"op":"mcm","clk":"11777245533","pt":1722714302516,"mc":[{"id":"1.231344826","rc":[{"batb":[[0,2.16,10]],"ltp":2.24,"tv":1.58,"id":424676}]}]}
{"op":"mcm","clk":"11777245815","pt":1722714305208,"mc":[{"id":"1.231344826","rc":[{"batb":[[0,2.18,2],[1,2.16,10],[2,2.14,35.43]],"ltp":2.24,"tv":1.58,"id":424676}]}]}
{"op":"mcm","clk":"11777245904","pt":1722714306001,"mc":[{"id":"1.231344826","rc":[{"batb":[[1,2.14,35.43],[2,1.74,17.32]],"ltp":2.24,"tv":1.58,"id":424676}]}]}
{"op":"mcm","clk":"11777246100","pt":1722714307627,"mc":[{"id":"1.231344826","rc":[{"batb":[[0,2.14,35.43],[1,1.74,17.32],[2,1.44,85.28]],"ltp":2.24,"tv":1.58,"id":424676}]}]}
{"op":"mcm","clk":"11777246438","pt":1722714310895,"mc":[{"id":"1.231344826","rc":[{"batb":[[0,2.16,12],[1,2.14,35.43],[2,1.74,17.32]],"ltp":2.24,"tv":1.58,"id":424676}]}]}
{"op":"mcm","clk":"11777246670","pt":1722714313394,"mc":[{"id":"1.231344826","rc":[{"batb":[[0,2.16,10]],"ltp":2.24,"tv":1.58,"id":424676}]}]}
{"op":"mcm","clk":"11777246781","pt":1722714314449,"mc":[{"id":"1.231344826","rc":[{"batb":[[0,2.14,35.43],[1,1.74,17.32],[2,1.44,85.28]],"ltp":2.24,"tv":1.58,"id":424676}]}]}
{"op":"mcm","clk":"11777246904","pt":1722714315610,"mc":[{"id":"1.231344826","rc":[{"batb":[[0,2.16,2],[1,2.14,35.43],[2,1.74,17.32]],"ltp":2.24,"tv":1.58,"id":424676}]}]}
{"op":"mcm","clk":"11777247161","pt":1722714318032,"mc":[{"id":"1.231344826","rc":[{"batb":[[0,2.16,10]],"ltp":2.24,"tv":1.58,"id":424676}]}]}
{"op":"mcm","clk":"11777247471","pt":1722714321545,"mc":[{"id":"1.231344826","rc":[{"batb":[[0,2.14,35.43],[1,1.74,17.32],[2,1.44,85.28]],"ltp":2.24,"tv":1.58,"id":424676}]}]}
{"op":"mcm","clk":"11777247488","pt":1722714321746,"mc":[{"id":"1.231344826","rc":[{"batb":[[0,2.16,2],[1,2.14,35.43],[2,1.74,17.32]],"ltp":2.24,"tv":1.58,"id":424676}]}]}
{"op":"mcm","clk":"11777247737","pt":1722714324111,"mc":[{"id":"1.231344826","rc":[{"batb":[[0,2.16,10]],"ltp":2.24,"tv":1.58,"id":424676}]}]}
{"op":"mcm","clk":"11777248056","pt":1722714327426,"mc":[{"id":"1.231344826","rc":[{"batb":[[0,2.14,35.43],[1,1.74,17.32],[2,1.44,85.28]],"ltp":2.24,"tv":1.58,"id":424676}]}]}
{"op":"mcm","clk":"11777248071","pt":1722714327636,"mc":[{"id":"1.231344826","rc":[{"batb":[[0,2.16,2],[1,2.14,35.43],[2,1.74,17.32]],"ltp":2.24,"tv":1.58,"id":424676}]}]}
{"op":"mcm","clk":"11777248313","pt":1722714330148,"mc":[{"id":"1.231344826","rc":[{"batb":[[0,2.16,10]],"ltp":2.24,"tv":1.58,"id":424676}]}]}
{"op":"mcm","clk":"11777248625","pt":1722714333448,"mc":[{"id":"1.231344826","rc":[{"batb":[[0,2.14,35.43],[1,1.74,17.32],[2,1.44,85.28]],"ltp":2.24,"tv":1.58,"id":424676}]}]}
{"op":"mcm","clk":"11777248637","pt":1722714333562,"mc":[{"id":"1.231344826","rc":[{"batb":[[0,2.16,2],[1,2.14,35.43],[2,1.74,17.32]],"ltp":2.24,"tv":1.58,"id":424676}]}]}
{"op":"mcm","clk":"11777248869","pt":1722714336060,"mc":[{"id":"1.231344826","rc":[{"batb":[[0,2.16,10]],"ltp":2.24,"tv":1.58,"id":424676}]}]}
{"op":"mcm","clk":"11777249069","pt":1722714338068,"mc":[{"id":"1.231344826","rc":[{"batb":[[0,2.18,2],[1,2.16,10],[2,2.14,35.43]],"ltp":2.24,"tv":1.58,"id":424676}]}]}
{"op":"mcm","clk":"11777249218","pt":1722714339266,"mc":[{"id":"1.231344826","rc":[{"batb":[[1,2.14,35.43],[2,1.74,17.32]],"ltp":2.24,"tv":1.58,"id":424676}]}]}
{"op":"mcm","clk":"11777249332","pt":1722714340465,"mc":[{"id":"1.231344826","rc":[{"batb":[[0,2.14,35.43],[1,1.74,17.32],[2,1.44,85.28]],"ltp":2.24,"tv":1.58,"id":424676}]}]}
{"op":"mcm","clk":"11777249512","pt":1722714342758,"mc":[{"id":"1.231344826","rc":[{"batb":[[0,2.18,2],[1,2.16,10],[2,2.14,35.43]],"ltp":2.24,"tv":1.58,"id":424676}]}]}
{"op":"mcm","clk":"11777249704","pt":1722714345057,"mc":[{"id":"1.231344826","rc":[{"batb":[[0,2.16,10],[1,2.14,35.43],[2,1.74,17.32]],"ltp":2.24,"tv":1.58,"id":424676}]}]}
{"op":"mcm","clk":"11777249791","pt":1722714345739,"mc":[{"id":"1.231344826","rc":[{"batb":[[0,2.14,35.43],[1,1.74,17.32],[2,1.44,85.28]],"ltp":2.24,"tv":1.58,"id":424676}]}]}
{"op":"mcm","clk":"11777250175","pt":1722714349672,"mc":[{"id":"1.231344826","rc":[{"batb":[[0,2.16,12],[1,2.14,35.43],[2,1.74,17.32]],"ltp":2.24,"tv":1.58,"id":424676}]}]}
{"op":"mcm","clk":"11777250433","pt":1722714352275,"mc":[{"id":"1.231344826","rc":[{"batb":[[0,2.16,10]],"ltp":2.24,"tv":1.58,"id":424676}]}]}
{"op":"mcm","clk":"11777250507","pt":1722714353058,"mc":[{"id":"1.231344826","rc":[{"batb":[[0,2.14,35.43],[1,1.74,17.32],[2,1.44,85.28]],"ltp":2.24,"tv":1.58,"id":424676}]}]}
{"op":"mcm","clk":"11777251323","pt":1722714361681,"mc":[{"id":"1.231344826","rc":[{"batb":[[0,2.16,12],[1,2.14,35.43],[2,1.74,17.32]],"ltp":2.24,"tv":1.58,"id":424676}]}]}
{"op":"mcm","clk":"11777251566","pt":1722714364295,"mc":[{"id":"1.231344826","rc":[{"batb":[[0,2.16,10]],"ltp":2.24,"tv":1.58,"id":424676}]}]}
{"op":"mcm","clk":"11777251641","pt":1722714365076,"mc":[{"id":"1.231344826","rc":[{"batb":[[0,2.14,35.43],[1,1.74,17.32],[2,1.44,85.28]],"ltp":2.24,"tv":1.58,"id":424676}]}]}
{"op":"mcm","clk":"11777252137","pt":1722714370143,"mc":[{"id":"1.231344826","rc":[{"batb":[[0,2.16,12],[1,2.14,35.43],[2,1.74,17.32]],"ltp":2.24,"tv":1.58,"id":424676}]}]}
{"op":"mcm","clk":"11777252438","pt":1722714373503,"mc":[{"id":"1.231344826","rc":[{"batb":[[0,2.14,35.43],[1,1.74,17.32],[2,1.44,85.28]],"ltp":2.24,"tv":1.58,"id":424676}]}]}
{"op":"mcm","clk":"11777252736","pt":1722714376197,"mc":[{"id":"1.231344826","rc":[{"batb":[[0,2.16,12],[1,2.14,35.43],[2,1.74,17.32]],"ltp":2.24,"tv":1.58,"id":424676}]}]}
{"op":"mcm","clk":"11777252959","pt":1722714378475,"mc":[{"id":"1.231344826","rc":[{"batb":[[0,2.16,10]],"ltp":2.24,"tv":1.58,"id":424676}]}]}
{"op":"mcm","clk":"11777253068","pt":1722714379479,"mc":[{"id":"1.231344826","rc":[{"batb":[[0,2.14,35.43],[1,1.74,17.32],[2,1.44,85.28]],"ltp":2.24,"tv":1.58,"id":424676}]}]}
{"op":"mcm","clk":"11777253561","pt":1722714384395,"mc":[{"id":"1.231344826","rc":[{"batb":[[0,2.16,12],[1,2.14,35.43],[2,1.74,17.32]],"ltp":2.24,"tv":1.58,"id":424676}]}]}
{"op":"mcm","clk":"11777253822","pt":1722714386922,"mc":[{"id":"1.231344826","rc":[{"batb":[[0,2.16,10]],"ltp":2.24,"tv":1.58,"id":424676}]}]}
{"op":"mcm","clk":"11777253922","pt":1722714387923,"mc":[{"id":"1.231344826","rc":[{"batb":[[0,2.14,35.43],[1,1.74,17.32],[2,1.44,85.28]],"ltp":2.24,"tv":1.58,"id":424676}]}]}
{"op":"mcm","clk":"11777254061","pt":1722714389202,"mc":[{"id":"1.231344826","rc":[{"batb":[[0,2.16,2],[1,2.14,35.43],[2,1.74,17.32]],"ltp":2.24,"tv":1.58,"id":424676}]}]}
{"op":"mcm","clk":"11777254344","pt":1722714391822,"mc":[{"id":"1.231344826","rc":[{"batb":[[0,2.16,10]],"ltp":2.24,"tv":1.58,"id":424676}]}]}
{"op":"mcm","clk":"11777254723","pt":1722714395211,"mc":[{"id":"1.231344826","rc":[{"batb":[[0,2.16,2]],"ltp":2.24,"tv":1.58,"id":424676}]}]}
{"op":"mcm","clk":"11777254936","pt":1722714397522,"mc":[{"id":"1.231344826","rc":[{"batb":[[0,2.14,35.43],[1,1.74,17.32],[2,1.44,85.28]],"ltp":2.24,"tv":1.58,"id":424676}]}]}
{"op":"mcm","clk":"11777254948","pt":1722714397628,"mc":[{"id":"1.231344826","rc":[{"batb":[[0,2.16,10],[1,2.14,35.43],[2,1.74,17.32]],"ltp":2.24,"tv":1.58,"id":424676}]}]}
{"op":"mcm","clk":"11777255175","pt":1722714399936,"mc":[{"id":"1.231344826","rc":[{"batb":[[0,2.18,2],[1,2.16,10],[2,2.14,35.43]],"ltp":2.24,"tv":1.58,"id":424676}]}]}
{"op":"mcm","clk":"11777255274","pt":1722714400832,"mc":[{"id":"1.231344826","rc":[{"batb":[[1,2.14,35.43],[2,1.74,17.32]],"ltp":2.24,"tv":1.58,"id":424676}]}]}
{"op":"mcm","clk":"11777255419","pt":1722714402352,"mc":[{"id":"1.231344826","rc":[{"batb":[[0,2.14,35.43],[1,1.74,17.32],[2,1.44,85.28]],"ltp":2.24,"tv":1.58,"id":424676}]}]}
{"op":"mcm","clk":"11777256281","pt":1722714410960,"mc":[{"id":"1.231344826","rc":[{"batb":[[0,2.16,12],[1,2.14,35.43],[2,1.74,17.32]],"ltp":2.24,"tv":1.58,"id":424676}]}]}
{"op":"mcm","clk":"11777256521","pt":1722714413345,"mc":[{"id":"1.231344826","rc":[{"batb":[[0,2.16,10]],"ltp":2.24,"tv":1.58,"id":424676}]}]}
{"op":"mcm","clk":"11777256598","pt":1722714414241,"mc":[{"id":"1.231344826","rc":[{"batb":[[0,2.14,35.43],[1,1.74,17.32],[2,1.44,85.28]],"ltp":2.24,"tv":1.58,"id":424676}]}]}
{"op":"mcm","clk":"11777257013","pt":1722714418849,"mc":[{"id":"1.231344826","rc":[{"batb":[[0,2.16,12],[1,2.14,35.43],[2,1.74,17.32]],"ltp":2.24,"tv":1.58,"id":424676}]}]}
{"op":"mcm","clk":"11777257225","pt":1722714421024,"mc":[{"id":"1.231344826","rc":[{"batb":[[0,2.16,10]],"ltp":2.24,"tv":1.58,"id":424676}]}]}
{"op":"mcm","clk":"11777257371","pt":1722714422243,"mc":[{"id":"1.231344826","rc":[{"batb":[[0,2.14,35.43],[1,1.74,17.32],[2,1.44,85.28]],"ltp":2.24,"tv":1.58,"id":424676}]}]}
{"op":"mcm","clk":"11777258106","pt":1722714429158,"mc":[{"id":"1.231344826","rc":[{"batb":[[0,2.16,12],[1,2.14,35.43],[2,1.74,17.32]],"ltp":2.24,"tv":1.58,"id":424676}]}]}
{"op":"mcm","clk":"11777258373","pt":1722714431644,"mc":[{"id":"1.231344826","rc":[{"batb":[[0,2.16,10]],"ltp":2.24,"tv":1.58,"id":424676}]}]}
{"op":"mcm","clk":"11777258464","pt":1722714432634,"mc":[{"id":"1.231344826","rc":[{"batb":[[0,2.14,35.43],[1,1.74,17.32],[2,1.44,85.28]],"ltp":2.24,"tv":1.58,"id":424676}]}]}
{"op":"mcm","clk":"11777259041","pt":1722714438677,"mc":[{"id":"1.231344826","rc":[{"batb":[[0,2.16,12],[1,2.14,35.43],[2,1.74,17.32]],"ltp":2.24,"tv":1.58,"id":424676}]}]}
{"op":"mcm","clk":"11777259267","pt":1722714440991,"mc":[{"id":"1.231344826","rc":[{"batb":[[0,2.16,10]],"ltp":2.24,"tv":1.58,"id":424676}]}]}
{"op":"mcm","clk":"11777259390","pt":1722714442087,"mc":[{"id":"1.231344826","rc":[{"batb":[[0,2.14,35.43],[1,1.74,17.32],[2,1.44,85.28]],"ltp":2.24,"tv":1.58,"id":424676}]}]}
{"op":"mcm","clk":"11777259523","pt":1722714443254,"mc":[{"id":"1.231344826","rc":[{"batb":[[0,2.16,2],[1,2.14,35.43],[2,1.74,17.32]],"ltp":2.24,"tv":1.58,"id":424676}]}]}
{"op":"mcm","clk":"11777259823","pt":1722714445878,"mc":[{"id":"1.231344826","rc":[{"batb":[[0,2.16,10]],"ltp":2.24,"tv":1.58,"id":424676}]}]}
{"op":"mcm","clk":"11777260181","pt":1722714449477,"mc":[{"id":"1.231344826","rc":[{"batb":[[0,2.16,2]],"ltp":2.24,"tv":1.58,"id":424676}]}]}
{"op":"mcm","clk":"11777260436","pt":1722714451962,"mc":[{"id":"1.231344826","rc":[{"batb":[[0,2.16,10]],"ltp":2.24,"tv":1.58,"id":424676}]}]}
{"op":"mcm","clk":"11777260805","pt":1722714455427,"mc":[{"id":"1.231344826","rc":[{"batb":[[0,2.14,35.43],[1,1.74,17.32],[2,1.44,85.28]],"ltp":2.24,"tv":1.58,"id":424676}]}]}
{"op":"mcm","clk":"11777260820","pt":1722714455583,"mc":[{"id":"1.231344826","rc":[{"batb":[[0,2.16,2],[1,2.14,35.43],[2,1.74,17.32]],"ltp":2.24,"tv":1.58,"id":424676}]}]}
{"op":"mcm","clk":"11777261037","pt":1722714458098,"mc":[{"id":"1.231344826","rc":[{"batb":[[0,2.16,10]],"ltp":2.24,"tv":1.58,"id":424676}]}]}
{"op":"mcm","clk":"11777261234","pt":1722714460151,"mc":[{"id":"1.231344826","rc":[{"batb":[[0,2.18,2],[1,2.16,10],[2,2.14,35.43]],"ltp":2.24,"tv":1.58,"id":424676}]}]}
{"op":"mcm","clk":"11777261354","pt":1722714461453,"mc":[{"id":"1.231344826","rc":[{"batb":[[1,2.14,35.43],[2,1.74,17.32]],"ltp":2.24,"tv":1.58,"id":424676}]}]}
{"op":"mcm","clk":"11777261445","pt":1722714462653,"mc":[{"id":"1.231344826","rc":[{"batb":[[0,2.14,35.43],[1,1.74,17.32],[2,1.44,85.28]],"ltp":2.24,"tv":1.58,"id":424676}]}]}
{"op":"mcm","clk":"11777261547","pt":1722714463769,"mc":[{"id":"1.231344826","rc":[{"batb":[[0,2.16,10],[1,2.14,35.43],[2,1.74,17.32]],"ltp":2.24,"tv":1.58,"id":424676}]}]}
{"op":"mcm","clk":"11777261826","pt":1722714466481,"mc":[{"id":"1.231344826","rc":[{"batb":[[0,2.18,2],[1,2.16,10],[2,2.14,35.43]],"ltp":2.24,"tv":1.58,"id":424676}]}]}
{"op":"mcm","clk":"11777261898","pt":1722714467163,"mc":[{"id":"1.231344826","rc":[{"batb":[[1,2.14,35.43],[2,1.74,17.32]],"ltp":2.24,"tv":1.58,"id":424676}]}]}
{"op":"mcm","clk":"11777262051","pt":1722714468880,"mc":[{"id":"1.231344826","rc":[{"batb":[[0,2.14,35.43],[1,1.74,17.32],[2,1.44,85.28]],"ltp":2.24,"tv":1.58,"id":424676}]}]}
{"op":"mcm","clk":"11777264102","pt":1722714488296,"mc":[{"id":"1.231344826","rc":[{"batb":[[0,2.16,12],[1,2.14,35.43],[2,1.74,17.32]],"ltp":2.24,"tv":1.58,"id":424676}]}]}
{"op":"mcm","clk":"11777264351","pt":1722714490806,"mc":[{"id":"1.231344826","rc":[{"batb":[[0,2.16,10]],"ltp":2.24,"tv":1.58,"id":424676}]}]}
{"op":"mcm","clk":"11777264439","pt":1722714491701,"mc":[{"id":"1.231344826","rc":[{"batb":[[0,2.14,35.43],[1,1.74,17.32],[2,1.44,85.28]],"ltp":2.24,"tv":1.58,"id":424676}]}]}
{"op":"mcm","clk":"11777264709","pt":1722714494097,"mc":[{"id":"1.231344826","rc":[{"batb":[[0,2.16,12],[1,2.14,35.43],[2,1.74,17.32]],"ltp":2.24,"tv":1.58,"id":424676}]}]}
{"op":"mcm","clk":"11777264948","pt":1722714496404,"mc":[{"id":"1.231344826","rc":[{"batb":[[0,2.16,10]],"ltp":2.24,"tv":1.58,"id":424676}]}]}
{"op":"mcm","clk":"11777265053","pt":1722714497399,"mc":[{"id":"1.231344826","rc":[{"batb":[[0,2.14,35.43],[1,1.74,17.32],[2,1.44,85.28]],"ltp":2.24,"tv":1.58,"id":424676}]}]}
{"op":"mcm","clk":"11777265174","pt":1722714498602,"mc":[{"id":"1.231344826","rc":[{"batb":[[0,2.16,2],[1,2.14,35.43],[2,1.74,17.32]],"ltp":2.24,"tv":1.58,"id":424676}]}]}
{"op":"mcm","clk":"11777265416","pt":1722714501110,"mc":[{"id":"1.231344826","rc":[{"batb":[[0,2.16,10]],"ltp":2.24,"tv":1.58,"id":424676}]}]}
{"op":"mcm","clk":"11777265784","pt":1722714504527,"mc":[{"id":"1.231344826","rc":[{"batb":[[0,2.14,35.43],[1,1.74,17.32],[2,1.44,85.28]],"ltp":2.24,"tv":1.58,"id":424676}]}]}
{"op":"mcm","clk":"11777265810","pt":1722714504737,"mc":[{"id":"1.231344826","rc":[{"batb":[[0,2.16,2],[1,2.14,35.43],[2,1.74,17.32]],"ltp":2.24,"tv":1.58,"id":424676}]}]}
{"op":"mcm","clk":"11777266039","pt":1722714507150,"mc":[{"id":"1.231344826","rc":[{"batb":[[0,2.16,10]],"ltp":2.24,"tv":1.58,"id":424676}]}]}
{"op":"mcm","clk":"11777266393","pt":1722714510532,"mc":[{"id":"1.231344826","rc":[{"batb":[[0,2.14,35.43],[1,1.74,17.32],[2,1.44,85.28]],"ltp":2.24,"tv":1.58,"id":424676}]}]}
{"op":"mcm","clk":"11777266408","pt":1722714510637,"mc":[{"id":"1.231344826","rc":[{"batb":[[0,2.16,2],[1,2.14,35.43],[2,1.74,17.32]],"ltp":2.24,"tv":1.58,"id":424676}]}]}
{"op":"mcm","clk":"11777266708","pt":1722714513109,"mc":[{"id":"1.231344826","rc":[{"batb":[[0,2.16,10]],"ltp":2.24,"tv":1.58,"id":424676}]}]}
{"op":"mcm","clk":"11777267073","pt":1722714516508,"mc":[{"id":"1.231344826","rc":[{"batb":[[0,2.16,2]],"ltp":2.24,"tv":1.58,"id":424676}]}]}
{"op":"mcm","clk":"11777267338","pt":1722714519006,"mc":[{"id":"1.231344826","rc":[{"batb":[[0,2.16,10]],"ltp":2.24,"tv":1.58,"id":424676}]}]}
{"op":"mcm","clk":"11777267617","pt":1722714521269,"mc":[{"id":"1.231344826","rc":[{"batb":[[0,2.18,2],[1,2.16,10],[2,2.14,35.43]],"ltp":2.24,"tv":1.58,"id":424676}]}]}
{"op":"mcm","clk":"11777267734","pt":1722714522313,"mc":[{"id":"1.231344826","rc":[{"batb":[[1,2.14,35.43],[2,1.74,17.32]],"ltp":2.24,"tv":1.58,"id":424676}]}]}
{"op":"mcm","clk":"11777267860","pt":1722714523638,"mc":[{"id":"1.231344826","rc":[{"batb":[[0,2.14,35.43],[1,1.74,17.32],[2,1.44,85.28]],"ltp":2.24,"tv":1.58,"id":424676}]}]}
{"op":"mcm","clk":"11777268322","pt":1722714527953,"mc":[{"id":"1.231344826","rc":[{"batb":[[0,2.16,12],[1,2.14,35.43],[2,1.74,17.32]],"ltp":2.24,"tv":1.58,"id":424676}]}]}
{"op":"mcm","clk":"11777268542","pt":1722714530251,"mc":[{"id":"1.231344826","rc":[{"batb":[[0,2.16,10]],"ltp":2.24,"tv":1.58,"id":424676}]}]}
{"op":"mcm","clk":"11777268623","pt":1722714531242,"mc":[{"id":"1.231344826","rc":[{"batb":[[0,2.14,35.43],[1,1.74,17.32],[2,1.44,85.28]],"ltp":2.24,"tv":1.58,"id":424676}]}]}
{"op":"mcm","clk":"11777268830","pt":1722714533645,"mc":[{"id":"1.231344826","rc":[{"batb":[[0,2.16,12],[1,2.14,35.43],[2,1.74,17.32]],"ltp":2.24,"tv":1.58,"id":424676}]}]}
{"op":"mcm","clk":"11777269046","pt":1722714536055,"mc":[{"id":"1.231344826","rc":[{"batb":[[0,2.16,10]],"ltp":2.24,"tv":1.58,"id":424676}]}]}
{"op":"mcm","clk":"11777269136","pt":1722714537049,"mc":[{"id":"1.231344826","rc":[{"batb":[[0,2.14,35.43],[1,1.74,17.32],[2,1.44,85.28]],"ltp":2.24,"tv":1.58,"id":424676}]}]}
{"op":"mcm","clk":"11777269601","pt":1722714541864,"mc":[{"id":"1.231344826","rc":[{"batb":[[0,2.16,12],[1,2.14,35.43],[2,1.74,17.32]],"ltp":2.24,"tv":1.58,"id":424676}]}]}
{"op":"mcm","clk":"11777269894","pt":1722714544171,"mc":[{"id":"1.231344826","rc":[{"batb":[[0,2.16,10]],"ltp":2.24,"tv":1.58,"id":424676}]}]}
{"op":"mcm","clk":"11777269978","pt":1722714545052,"mc":[{"id":"1.231344826","rc":[{"batb":[[0,2.14,35.43],[1,1.74,17.32],[2,1.44,85.28]],"ltp":2.24,"tv":1.58,"id":424676}]}]}
{"op":"mcm","clk":"11777270244","pt":1722714547459,"mc":[{"id":"1.231344826","rc":[{"batb":[[0,2.16,12],[1,2.14,35.43],[2,1.74,17.32]],"ltp":2.24,"tv":1.58,"id":424676}]}]}
{"op":"mcm","clk":"11777270521","pt":1722714549878,"mc":[{"id":"1.231344826","rc":[{"batb":[[0,2.16,10]],"ltp":2.24,"tv":1.58,"id":424676}]}]}
{"op":"mcm","clk":"11777270626","pt":1722714550872,"mc":[{"id":"1.231344826","rc":[{"batb":[[0,2.14,35.43],[1,1.74,17.32],[2,1.44,85.28]],"ltp":2.24,"tv":1.58,"id":424676}]}]}
{"op":"mcm","clk":"11777271088","pt":1722714554993,"mc":[{"id":"1.231344826","rc":[{"batb":[[0,2.16,12],[1,2.14,35.43],[2,1.74,17.32]],"ltp":2.24,"tv":1.58,"id":424676}]}]}
{"op":"mcm","clk":"11777271343","pt":1722714557195,"mc":[{"id":"1.231344826","rc":[{"batb":[[0,2.16,10]],"ltp":2.24,"tv":1.58,"id":424676}]}]}
{"op":"mcm","clk":"11777271462","pt":1722714558392,"mc":[{"id":"1.231344826","rc":[{"batb":[[0,2.14,35.43],[1,1.74,17.32],[2,1.44,85.28]],"ltp":2.24,"tv":1.58,"id":424676}]}]}
{"op":"mcm","clk":"11777271591","pt":1722714559589,"mc":[{"id":"1.231344826","rc":[{"batb":[[0,2.16,2],[1,2.14,35.43],[2,1.74,17.32]],"ltp":2.24,"tv":1.58,"id":424676}]}]}
{"op":"mcm","clk":"11777271826","pt":1722714562201,"mc":[{"id":"1.231344826","rc":[{"batb":[[0,2.16,10]],"ltp":2.24,"tv":1.58,"id":424676}]}]}
{"op":"mcm","clk":"11777272178","pt":1722714565483,"mc":[{"id":"1.231344826","rc":[{"batb":[[0,2.14,35.43],[1,1.74,17.32],[2,1.44,85.28]],"ltp":2.24,"tv":1.58,"id":424676}]}]}
{"op":"mcm","clk":"11777272199","pt":1722714565695,"mc":[{"id":"1.231344826","rc":[{"batb":[[0,2.16,2],[1,2.14,35.43],[2,1.74,17.32]],"ltp":2.24,"tv":1.58,"id":424676}]}]}
{"op":"mcm","clk":"11777272438","pt":1722714568100,"mc":[{"id":"1.231344826","rc":[{"batb":[[0,2.16,10]],"ltp":2.24,"tv":1.58,"id":424676}]}]}
{"op":"mcm","clk":"11777272781","pt":1722714571513,"mc":[{"id":"1.231344826","rc":[{"batb":[[0,2.16,2]],"ltp":2.24,"tv":1.58,"id":424676}]}]}
{"op":"mcm","clk":"11777273052","pt":1722714574222,"mc":[{"id":"1.231344826","rc":[{"batb":[[0,2.16,10]],"ltp":2.24,"tv":1.58,"id":424676}]}]}
{"op":"mcm","clk":"11777273396","pt":1722714577785,"mc":[{"id":"1.231344826","rc":[{"batb":[[0,2.16,2]],"ltp":2.24,"tv":1.58,"id":424676}]}]}
{"op":"mcm","clk":"11777273641","pt":1722714580298,"mc":[{"id":"1.231344826","rc":[{"batb":[[0,2.16,10]],"ltp":2.24,"tv":1.58,"id":424676}]}]}
{"op":"mcm","clk":"11777273967","pt":1722714583932,"mc":[{"id":"1.231344826","rc":[{"batb":[[0,2.16,2]],"ltp":2.24,"tv":1.58,"id":424676}]}]}
{"op":"mcm","clk":"11777274211","pt":1722714586435,"mc":[{"id":"1.231344826","rc":[{"batb":[[0,2.16,10]],"ltp":2.24,"tv":1.58,"id":424676}]}]}
{"op":"mcm","clk":"11777274508","pt":1722714589825,"mc":[{"id":"1.231344826","rc":[{"batb":[[0,2.18,2]],"ltp":2.24,"tv":1.58,"id":424676}]}]}
{"op":"mcm","clk":"11777274747","pt":1722714592224,"mc":[{"id":"1.231344826","rc":[{"batb":[[0,2.16,10]],"ltp":2.24,"tv":1.58,"id":424676}]}]}
{"op":"mcm","clk":"11777275094","pt":1722714595837,"mc":[{"id":"1.231344826","rc":[{"batb":[[0,2.16,2]],"ltp":2.24,"tv":1.58,"id":424676}]}]}
{"op":"mcm","clk":"11777275316","pt":1722714598218,"mc":[{"id":"1.231344826","rc":[{"batb":[[0,2.16,10]],"ltp":2.24,"tv":1.58,"id":424676}]}]}
{"op":"mcm","clk":"11777275645","pt":1722714601568,"mc":[{"id":"1.231344826","rc":[{"batb":[[0,2.18,2]],"ltp":2.24,"tv":1.58,"id":424676}]}]}
{"op":"mcm","clk":"11777275862","pt":1722714603931,"mc":[{"id":"1.231344826","rc":[{"batb":[[0,2.16,10]],"ltp":2.24,"tv":1.58,"id":424676}]}]}
{"op":"mcm","clk":"11777276168","pt":1722714607254,"mc":[{"id":"1.231344826","rc":[{"batb":[[0,2.16,2]],"ltp":2.24,"tv":1.58,"id":424676}]}]}
{"op":"mcm","clk":"11777276404","pt":1722714609868,"mc":[{"id":"1.231344826","rc":[{"batb":[[0,2.16,10]],"ltp":2.24,"tv":1.58,"id":424676}]}]}
{"op":"mcm","clk":"11777276764","pt":1722714613477,"mc":[{"id":"1.231344826","rc":[{"batb":[[0,2.16,2]],"ltp":2.24,"tv":1.58,"id":424676}]}]}
{"op":"mcm","clk":"11777277020","pt":1722714615944,"mc":[{"id":"1.231344826","rc":[{"batb":[[0,2.16,10]],"ltp":2.24,"tv":1.58,"id":424676}]}]}
{"op":"mcm","clk":"11777277353","pt":1722714619449,"mc":[{"id":"1.231344826","rc":[{"batb":[[0,2.16,2]],"ltp":2.24,"tv":1.58,"id":424676}]}]}
{"op":"mcm","clk":"11777277616","pt":1722714621981,"mc":[{"id":"1.231344826","rc":[{"batb":[[0,2.16,10]],"ltp":2.24,"tv":1.58,"id":424676}]}]}
{"op":"mcm","clk":"11777277823","pt":1722714624162,"mc":[{"id":"1.231344826","rc":[{"batb":[[0,2.18,2],[1,2.16,10],[2,2.14,35.43]],"ltp":2.24,"tv":1.58,"id":424676}]}]}
{"op":"mcm","clk":"11777277929","pt":1722714625256,"mc":[{"id":"1.231344826","rc":[{"batb":[[1,2.14,35.43],[2,1.74,17.32]],"ltp":2.24,"tv":1.58,"id":424676}]}]}
{"op":"mcm","clk":"11777278058","pt":1722714626445,"mc":[{"id":"1.231344826","rc":[{"batb":[[0,2.14,35.43],[1,1.74,17.32],[2,1.44,85.28]],"ltp":2.24,"tv":1.58,"id":424676}]}]}
{"op":"mcm","clk":"11777278383","pt":1722714629688,"mc":[{"id":"1.231344826","rc":[{"batb":[[0,2.16,12],[1,2.14,35.43],[2,1.74,17.32]],"ltp":2.24,"tv":1.58,"id":424676}]}]}
{"op":"mcm","clk":"11777278620","pt":1722714632058,"mc":[{"id":"1.231344826","rc":[{"batb":[[0,2.16,10]],"ltp":2.24,"tv":1.58,"id":424676}]}]}
{"op":"mcm","clk":"11777278720","pt":1722714633095,"mc":[{"id":"1.231344826","rc":[{"batb":[[0,2.14,35.43],[1,1.74,17.32],[2,1.44,85.28]],"ltp":2.24,"tv":1.58,"id":424676}]}]}
{"op":"mcm","clk":"11777279435","pt":1722714640391,"mc":[{"id":"1.231344826","rc":[{"batb":[[0,2.16,12],[1,2.14,35.43],[2,1.74,17.32]],"ltp":2.24,"tv":1.58,"id":424676}]}]}
{"op":"mcm","clk":"11777279663","pt":1722714642789,"mc":[{"id":"1.231344826","rc":[{"batb":[[0,2.16,10]],"ltp":2.24,"tv":1.58,"id":424676}]}]}
{"op":"mcm","clk":"11777279753","pt":1722714643778,"mc":[{"id":"1.231344826","rc":[{"batb":[[0,2.14,35.43],[1,1.74,17.32],[2,1.44,85.28]],"ltp":2.24,"tv":1.58,"id":424676}]}]}
{"op":"mcm","clk":"11777279916","pt":1722714645386,"mc":[{"id":"1.231344826","rc":[{"batb":[[0,2.16,2],[1,2.14,35.43],[2,1.74,17.32]],"ltp":2.24,"tv":1.58,"id":424676}]}]}
{"op":"mcm","clk":"11777280175","pt":1722714647994,"mc":[{"id":"1.231344826","rc":[{"batb":[[0,2.16,10]],"ltp":2.24,"tv":1.58,"id":424676}]}]}
{"op":"mcm","clk":"11777280514","pt":1722714651281,"mc":[{"id":"1.231344826","rc":[{"batb":[[0,2.16,2]],"ltp":2.24,"tv":1.58,"id":424676}]}]}
{"op":"mcm","clk":"11777280763","pt":1722714653888,"mc":[{"id":"1.231344826","rc":[{"batb":[[0,2.16,10]],"ltp":2.24,"tv":1.58,"id":424676}]}]}
{"op":"mcm","clk":"11777281087","pt":1722714657529,"mc":[{"id":"1.231344826","rc":[{"batb":[[0,2.16,2]],"ltp":2.24,"tv":1.58,"id":424676}]}]}
{"op":"mcm","clk":"11777281302","pt":1722714659894,"mc":[{"id":"1.231344826","rc":[{"batb":[[0,2.16,10]],"ltp":2.24,"tv":1.58,"id":424676}]}]}
{"op":"mcm","clk":"11777281696","pt":1722714663527,"mc":[{"id":"1.231344826","rc":[{"batb":[[0,2.16,2]],"ltp":2.24,"tv":1.58,"id":424676}]}]}
{"op":"mcm","clk":"11777281933","pt":1722714665935,"mc":[{"id":"1.231344826","rc":[{"batb":[[0,2.16,10]],"ltp":2.24,"tv":1.58,"id":424676}]}]}
{"op":"mcm","clk":"11777282291","pt":1722714669396,"mc":[{"id":"1.231344826","rc":[{"batb":[[0,2.16,2]],"ltp":2.24,"tv":1.58,"id":424676}]}]}
{"op":"mcm","clk":"11777282552","pt":1722714672019,"mc":[{"id":"1.231344826","rc":[{"batb":[[0,2.16,10]],"ltp":2.24,"tv":1.58,"id":424676}]}]}
{"op":"mcm","clk":"11777282898","pt":1722714675315,"mc":[{"id":"1.231344826","rc":[{"batb":[[0,2.16,2]],"ltp":2.24,"tv":1.58,"id":424676}]}]}
{"op":"mcm","clk":"11777283142","pt":1722714677704,"mc":[{"id":"1.231344826","rc":[{"batb":[[0,2.16,10]],"ltp":2.24,"tv":1.58,"id":424676}]}]}
{"op":"mcm","clk":"11777283495","pt":1722714681208,"mc":[{"id":"1.231344826","rc":[{"batb":[[0,2.16,2]],"ltp":2.24,"tv":1.58,"id":424676}]}]}
{"op":"mcm","clk":"11777283731","pt":1722714683451,"mc":[{"id":"1.231344826","rc":[{"batb":[[0,2.14,35.43],[1,1.74,17.32],[2,1.44,85.28]],"ltp":2.24,"tv":1.58,"id":424676}]}]}
{"op":"mcm","clk":"11777283743","pt":1722714683555,"mc":[{"id":"1.231344826","rc":[{"batb":[[0,2.16,10],[1,2.14,35.43],[2,1.74,17.32]],"ltp":2.24,"tv":1.58,"id":424676}]}]}
{"op":"mcm","clk":"11777284108","pt":1722714686846,"mc":[{"id":"1.231344826","rc":[{"batb":[[0,2.16,2]],"ltp":2.24,"tv":1.58,"id":424676}]}]}
{"op":"mcm","clk":"11777284356","pt":1722714689343,"mc":[{"id":"1.231344826","rc":[{"batb":[[0,2.16,10]],"ltp":2.24,"tv":1.58,"id":424676}]}]}
{"op":"mcm","clk":"11777284704","pt":1722714692915,"mc":[{"id":"1.231344826","rc":[{"batb":[[0,2.16,2]],"ltp":2.24,"tv":1.58,"id":424676}]}]}
{"op":"mcm","clk":"11777284948","pt":1722714695267,"mc":[{"id":"1.231344826","rc":[{"batb":[[0,2.16,10]],"ltp":2.24,"tv":1.58,"id":424676}]}]}
{"op":"mcm","clk":"11777285244","pt":1722714698338,"mc":[{"id":"1.231344826","rc":[{"batb":[[0,2.18,2],[1,2.16,10],[2,2.14,35.43]],"ltp":2.24,"tv":1.58,"id":424676}]}]}
{"op":"mcm","clk":"11777285268","pt":1722714698547,"mc":[{"id":"1.231344826","rc":[{"batb":[[1,2.14,35.43],[2,1.74,17.32]],"ltp":2.24,"tv":1.58,"id":424676}]}]}
{"op":"mcm","clk":"11777285521","pt":1722714700744,"mc":[{"id":"1.231344826","rc":[{"batb":[[0,2.16,10]],"ltp":2.24,"tv":1.58,"id":424676}]}]}
{"op":"mcm","clk":"11777285833","pt":1722714704068,"mc":[{"id":"1.231344826","rc":[{"batb":[[0,2.18,2]],"ltp":2.24,"tv":1.58,"id":424676}]}]}
{"op":"mcm","clk":"11777286088","pt":1722714706380,"mc":[{"id":"1.231344826","rc":[{"batb":[[0,2.16,10]],"ltp":2.24,"tv":1.58,"id":424676}]}]}
{"op":"mcm","clk":"11777286440","pt":1722714709663,"mc":[{"id":"1.231344826","rc":[{"batb":[[0,2.16,2]],"ltp":2.24,"tv":1.58,"id":424676}]}]}
{"op":"mcm","clk":"11777286677","pt":1722714712174,"mc":[{"id":"1.231344826","rc":[{"batb":[[0,2.16,10]],"ltp":2.24,"tv":1.58,"id":424676}]}]}
{"op":"mcm","clk":"11777287003","pt":1722714715774,"mc":[{"id":"1.231344826","rc":[{"batb":[[0,2.16,2]],"ltp":2.24,"tv":1.58,"id":424676}]}]}
{"op":"mcm","clk":"11777287235","pt":1722714718249,"mc":[{"id":"1.231344826","rc":[{"batb":[[0,2.16,10]],"ltp":2.24,"tv":1.58,"id":424676}]}]}
{"op":"mcm","clk":"11777287620","pt":1722714721869,"mc":[{"id":"1.231344826","rc":[{"batb":[[0,2.16,2]],"ltp":2.24,"tv":1.58,"id":424676}]}]}
{"op":"mcm","clk":"11777287840","pt":1722714724167,"mc":[{"id":"1.231344826","rc":[{"batb":[[0,2.16,10]],"ltp":2.24,"tv":1.58,"id":424676}]}]}
{"op":"mcm","clk":"11777288181","pt":1722714727659,"mc":[{"id":"1.231344826","rc":[{"batb":[[0,2.16,2]],"ltp":2.24,"tv":1.58,"id":424676}]}]}
{"op":"mcm","clk":"11777288419","pt":1722714730323,"mc":[{"id":"1.231344826","rc":[{"batb":[[0,2.16,10]],"ltp":2.24,"tv":1.58,"id":424676}]}]}
{"op":"mcm","clk":"11777288750","pt":1722714733693,"mc":[{"id":"1.231344826","rc":[{"batb":[[0,2.16,2]],"ltp":2.24,"tv":1.58,"id":424676}]}]}
{"op":"mcm","clk":"11777288990","pt":1722714736193,"mc":[{"id":"1.231344826","rc":[{"batb":[[0,2.16,10]],"ltp":2.24,"tv":1.58,"id":424676}]}]}
{"op":"mcm","clk":"11777289307","pt":1722714739469,"mc":[{"id":"1.231344826","rc":[{"batb":[[0,2.14,35.43],[1,1.74,17.32],[2,1.44,85.28]],"ltp":2.24,"tv":1.58,"id":424676}]}]}
{"op":"mcm","clk":"11777289318","pt":1722714739574,"mc":[{"id":"1.231344826","rc":[{"batb":[[0,2.16,2],[1,2.14,35.43],[2,1.74,17.32]],"ltp":2.24,"tv":1.58,"id":424676}]}]}
{"op":"mcm","clk":"11777289526","pt":1722714742072,"mc":[{"id":"1.231344826","rc":[{"batb":[[0,2.16,10]],"ltp":2.24,"tv":1.58,"id":424676}]}]}
{"op":"mcm","clk":"11777289806","pt":1722714745508,"mc":[{"id":"1.231344826","rc":[{"batb":[[0,2.14,35.43],[1,1.74,17.32],[2,1.44,85.28]],"ltp":2.24,"tv":1.58,"id":424676}]}]}
{"op":"mcm","clk":"11777289828","pt":1722714745715,"mc":[{"id":"1.231344826","rc":[{"batb":[[0,2.16,2],[1,2.14,35.43],[2,1.74,17.32]],"ltp":2.24,"tv":1.58,"id":424676}]}]}
{"op":"mcm","clk":"11777290024","pt":1722714748204,"mc":[{"id":"1.231344826","rc":[{"batb":[[0,2.16,10]],"ltp":2.24,"tv":1.58,"id":424676}]}]}
{"op":"mcm","clk":"11777290304","pt":1722714751519,"mc":[{"id":"1.231344826","rc":[{"batb":[[0,2.16,2]],"ltp":2.24,"tv":1.58,"id":424676}]}]}
{"op":"mcm","clk":"11777290536","pt":1722714754109,"mc":[{"id":"1.231344826","rc":[{"batb":[[0,2.16,10]],"ltp":2.24,"tv":1.58,"id":424676}]}]}
{"op":"mcm","clk":"11777290806","pt":1722714757322,"mc":[{"id":"1.231344826","rc":[{"batb":[[0,2.18,2]],"ltp":2.24,"tv":1.58,"id":424676}]}]}
{"op":"mcm","clk":"11777291064","pt":1722714760033,"mc":[{"id":"1.231344826","rc":[{"batb":[[0,2.16,10]],"ltp":2.24,"tv":1.58,"id":424676}]}]}
{"op":"mcm","clk":"11777291344","pt":1722714763526,"mc":[{"id":"1.231344826","rc":[{"batb":[[0,2.16,2]],"ltp":2.24,"tv":1.58,"id":424676}]}]}
{"op":"mcm","clk":"11777291567","pt":1722714765947,"mc":[{"id":"1.231344826","rc":[{"batb":[[0,2.16,10]],"ltp":2.24,"tv":1.58,"id":424676}]}]}
{"op":"mcm","clk":"11777291870","pt":1722714769324,"mc":[{"id":"1.231344826","rc":[{"batb":[[0,2.16,2]],"ltp":2.24,"tv":1.58,"id":424676}]}]}
{"op":"mcm","clk":"11777292090","pt":1722714771719,"mc":[{"id":"1.231344826","rc":[{"batb":[[0,2.16,10]],"ltp":2.24,"tv":1.58,"id":424676}]}]}
{"op":"mcm","clk":"11777292367","pt":1722714775028,"mc":[{"id":"1.231344826","rc":[{"batb":[[0,2.16,2]],"ltp":2.24,"tv":1.58,"id":424676}]}]}
{"op":"mcm","clk":"11777292537","pt":1722714777429,"mc":[{"id":"1.231344826","rc":[{"batb":[[0,2.14,35.43],[1,1.74,17.32],[2,1.44,85.28]],"ltp":2.24,"tv":1.58,"id":424676}]}]}
{"op":"mcm","clk":"11777292558","pt":1722714777634,"mc":[{"id":"1.231344826","rc":[{"batb":[[0,2.16,10],[1,2.14,35.43],[2,1.74,17.32]],"ltp":2.24,"tv":1.58,"id":424676}]}]}
{"op":"mcm","clk":"11777292847","pt":1722714781134,"mc":[{"id":"1.231344826","rc":[{"batb":[[0,2.16,2]],"ltp":2.24,"tv":1.58,"id":424676}]}]}
{"op":"mcm","clk":"11777293075","pt":1722714783535,"mc":[{"id":"1.231344826","rc":[{"batb":[[0,2.16,10]],"ltp":2.24,"tv":1.58,"id":424676}]}]}
{"op":"mcm","clk":"11777293420","pt":1722714786928,"mc":[{"id":"1.231344826","rc":[{"batb":[[0,2.16,2]],"ltp":2.24,"tv":1.58,"id":424676}]}]}
{"op":"mcm","clk":"11777293660","pt":1722714789434,"mc":[{"id":"1.231344826","rc":[{"batb":[[0,2.16,10]],"ltp":2.24,"tv":1.58,"id":424676}]}]}
{"op":"mcm","clk":"11777294016","pt":1722714793036,"mc":[{"id":"1.231344826","rc":[{"batb":[[0,2.16,2]],"ltp":2.24,"tv":1.58,"id":424676}]}]}
{"op":"mcm","clk":"11777294228","pt":1722714795334,"mc":[{"id":"1.231344826","rc":[{"batb":[[0,2.14,35.43],[1,1.74,17.32],[2,1.44,85.28]],"ltp":2.24,"tv":1.58,"id":424676}]}]}
{"op":"mcm","clk":"11777294251","pt":1722714795548,"mc":[{"id":"1.231344826","rc":[{"batb":[[0,2.16,10],[1,2.14,35.43],[2,1.74,17.32]],"ltp":2.24,"tv":1.58,"id":424676}]}]}
{"op":"mcm","clk":"11777294599","pt":1722714799083,"mc":[{"id":"1.231344826","rc":[{"batb":[[0,2.16,2]],"ltp":2.24,"tv":1.58,"id":424676}]}]}
{"op":"mcm","clk":"11777294841","pt":1722714801461,"mc":[{"id":"1.231344826","rc":[{"batb":[[0,2.16,10]],"ltp":2.24,"tv":1.58,"id":424676}]}]}
{"op":"mcm","clk":"11777295177","pt":1722714805059,"mc":[{"id":"1.231344826","rc":[{"batb":[[0,2.16,2]],"ltp":2.24,"tv":1.58,"id":424676}]}]}
{"op":"mcm","clk":"11777295394","pt":1722714807343,"mc":[{"id":"1.231344826","rc":[{"batb":[[0,2.14,35.43],[1,1.74,17.32],[2,1.44,85.28]],"ltp":2.24,"tv":1.58,"id":424676}]}]}
{"op":"mcm","clk":"11777295415","pt":1722714807553,"mc":[{"id":"1.231344826","rc":[{"batb":[[0,2.16,10],[1,2.14,35.43],[2,1.74,17.32]],"ltp":2.24,"tv":1.58,"id":424676}]}]}
{"op":"mcm","clk":"11777295733","pt":1722714811178,"mc":[{"id":"1.231344826","rc":[{"batb":[[0,2.16,2]],"ltp":2.24,"tv":1.58,"id":424676}]}]}
{"op":"mcm","clk":"11777295956","pt":1722714813739,"mc":[{"id":"1.231344826","rc":[{"batb":[[0,2.16,10]],"ltp":2.24,"tv":1.58,"id":424676}]}]}
{"op":"mcm","clk":"11777296238","pt":1722714817375,"mc":[{"id":"1.231344826","rc":[{"batb":[[0,2.16,2]],"ltp":2.24,"tv":1.58,"id":424676}]}]}
{"op":"mcm","clk":"11777296447","pt":1722714819768,"mc":[{"id":"1.231344826","rc":[{"batb":[[0,2.16,10]],"ltp":2.24,"tv":1.58,"id":424676}]}]}
{"op":"mcm","clk":"11777296687","pt":1722714823260,"mc":[{"id":"1.231344826","rc":[{"batb":[[0,2.16,2]],"ltp":2.24,"tv":1.58,"id":424676}]}]}
{"op":"mcm","clk":"11777296884","pt":1722714825753,"mc":[{"id":"1.231344826","rc":[{"batb":[[0,2.16,10]],"ltp":2.24,"tv":1.58,"id":424676}]}]}
{"op":"mcm","clk":"11777297175","pt":1722714829086,"mc":[{"id":"1.231344826","rc":[{"batb":[[0,2.16,2]],"ltp":2.24,"tv":1.58,"id":424676}]}]}
{"op":"mcm","clk":"11777297357","pt":1722714831478,"mc":[{"id":"1.231344826","rc":[{"batb":[[0,2.14,35.43],[1,1.74,17.32],[2,1.44,85.28]],"ltp":2.24,"tv":1.58,"id":424676}]}]}
{"op":"mcm","clk":"11777297376","pt":1722714831682,"mc":[{"id":"1.231344826","rc":[{"batb":[[0,2.16,10],[1,2.14,35.43],[2,1.74,17.32]],"ltp":2.24,"tv":1.58,"id":424676}]}]}
{"op":"mcm","clk":"11777297554","pt":1722714833969,"mc":[{"id":"1.231344826","rc":[{"batb":[[0,2.18,2],[1,2.16,10],[2,2.14,35.43]],"ltp":2.24,"tv":1.58,"id":424676}]}]}
{"op":"mcm","clk":"11777297653","pt":1722714835188,"mc":[{"id":"1.231344826","rc":[{"batb":[[1,2.14,35.43],[2,1.74,17.32]],"ltp":2.24,"tv":1.58,"id":424676}]}]}
{"op":"mcm","clk":"11777297734","pt":1722714836365,"mc":[{"id":"1.231344826","rc":[{"batb":[[0,2.14,35.43],[1,1.74,17.32],[2,1.44,85.28]],"ltp":2.24,"tv":1.58,"id":424676}]}]}
{"op":"mcm","clk":"11777298272","pt":1722714842162,"mc":[{"id":"1.231344826","rc":[{"batb":[[0,2.16,12],[1,2.14,35.43],[2,1.74,17.32]],"ltp":2.24,"tv":1.58,"id":424676}]}]}
{"op":"mcm","clk":"11777298541","pt":1722714844574,"mc":[{"id":"1.231344826","rc":[{"batb":[[0,2.16,10]],"ltp":2.24,"tv":1.58,"id":424676}]}]}
{"op":"mcm","clk":"11777298629","pt":1722714845564,"mc":[{"id":"1.231344826","rc":[{"batb":[[0,2.14,35.43],[1,1.74,17.32],[2,1.44,85.28]],"ltp":2.24,"tv":1.58,"id":424676}]}]}
{"op":"mcm","clk":"11777298835","pt":1722714848172,"mc":[{"id":"1.231344826","rc":[{"batb":[[0,2.16,12],[1,2.14,35.43],[2,1.74,17.32]],"ltp":2.24,"tv":1.58,"id":424676}]}]}
{"op":"mcm","clk":"11777299058","pt":1722714850672,"mc":[{"id":"1.231344826","rc":[{"batb":[[0,2.16,10]],"ltp":2.24,"tv":1.58,"id":424676}]}]}
{"op":"mcm","clk":"11777299149","pt":1722714851664,"mc":[{"id":"1.231344826","rc":[{"batb":[[0,2.14,35.43],[1,1.74,17.32],[2,1.44,85.28]],"ltp":2.24,"tv":1.58,"id":424676}]}]}
{"op":"mcm","clk":"11777299250","pt":1722714852862,"mc":[{"id":"1.231344826","rc":[{"batb":[[0,2.16,2],[1,2.14,35.43],[2,1.74,17.32]],"ltp":2.24,"tv":1.58,"id":424676}]}]}
{"op":"mcm","clk":"11777299442","pt":1722714855362,"mc":[{"id":"1.231344826","rc":[{"batb":[[0,2.16,10]],"ltp":2.24,"tv":1.58,"id":424676}]}]}
{"op":"mcm","clk":"11777299736","pt":1722714858803,"mc":[{"id":"1.231344826","rc":[{"batb":[[0,2.16,2]],"ltp":2.24,"tv":1.58,"id":424676}]}]}
{"op":"mcm","clk":"11777299946","pt":1722714861409,"mc":[{"id":"1.231344826","rc":[{"batb":[[0,2.16,10]],"ltp":2.24,"tv":1.58,"id":424676}]}]}
{"op":"mcm","clk":"11777300297","pt":1722714865106,"mc":[{"id":"1.231344826","rc":[{"batb":[[0,2.16,2]],"ltp":2.24,"tv":1.58,"id":424676}]}]}
{"op":"mcm","clk":"11777300553","pt":1722714867399,"mc":[{"id":"1.231344826","rc":[{"batb":[[0,2.14,35.43],[1,1.74,17.32],[2,1.44,85.28]],"ltp":2.24,"tv":1.58,"id":424676}]}]}
{"op":"mcm","clk":"11777300572","pt":1722714867607,"mc":[{"id":"1.231344826","rc":[{"batb":[[0,2.16,10],[1,2.14,35.43],[2,1.74,17.32]],"ltp":2.24,"tv":1.58,"id":424676}]}]}
{"op":"mcm","clk":"11777300909","pt":1722714871123,"mc":[{"id":"1.231344826","rc":[{"batb":[[0,2.16,2]],"ltp":2.24,"tv":1.58,"id":424676}]}]}
{"op":"mcm","clk":"11777301162","pt":1722714873719,"mc":[{"id":"1.231344826","rc":[{"batb":[[0,2.16,10]],"ltp":2.24,"tv":1.58,"id":424676}]}]}
{"op":"mcm","clk":"11777301514","pt":1722714877299,"mc":[{"id":"1.231344826","rc":[{"batb":[[0,2.16,2]],"ltp":2.24,"tv":1.58,"id":424676}]}]}
{"op":"mcm","clk":"11777301737","pt":1722714879689,"mc":[{"id":"1.231344826","rc":[{"batb":[[0,2.16,10]],"ltp":2.24,"tv":1.58,"id":424676}]}]}
{"op":"mcm","clk":"11777302003","pt":1722714883024,"mc":[{"id":"1.231344826","rc":[{"batb":[[0,2.16,2]],"ltp":2.24,"tv":1.58,"id":424676}]}]}
{"op":"mcm","clk":"11777302195","pt":1722714885405,"mc":[{"id":"1.231344826","rc":[{"batb":[[0,2.14,35.43],[1,1.74,17.32],[2,1.44,85.28]],"ltp":2.24,"tv":1.58,"id":424676}]}]}
{"op":"mcm","clk":"11777302213","pt":1722714885613,"mc":[{"id":"1.231344826","rc":[{"batb":[[0,2.16,10],[1,2.14,35.43],[2,1.74,17.32]],"ltp":2.24,"tv":1.58,"id":424676}]}]}
{"op":"mcm","clk":"11777302504","pt":1722714889031,"mc":[{"id":"1.231344826","rc":[{"batb":[[0,2.16,2]],"ltp":2.24,"tv":1.58,"id":424676}]}]}
{"op":"mcm","clk":"11777302815","pt":1722714892404,"mc":[{"id":"1.231344826","rc":[{"batb":[[0,2.16,10]],"ltp":2.24,"tv":1.58,"id":424676}]}]}
{"op":"mcm","clk":"11777303083","pt":1722714895823,"mc":[{"id":"1.231344826","rc":[{"batb":[[0,2.16,2]],"ltp":2.24,"tv":1.58,"id":424676}]}]}
{"op":"mcm","clk":"11777303276","pt":1722714898423,"mc":[{"id":"1.231344826","rc":[{"batb":[[0,2.16,10]],"ltp":2.24,"tv":1.58,"id":424676}]}]}
{"op":"mcm","clk":"11777303537","pt":1722714901606,"mc":[{"id":"1.231344826","rc":[{"batb":[[0,2.18,2]],"ltp":2.24,"tv":1.58,"id":424676}]}]}
{"op":"mcm","clk":"11777303785","pt":1722714903910,"mc":[{"id":"1.231344826","rc":[{"batb":[[0,2.16,10]],"ltp":2.24,"tv":1.58,"id":424676}]}]}
{"op":"mcm","clk":"11777304111","pt":1722714907351,"mc":[{"id":"1.231344826","rc":[{"batb":[[0,2.16,2]],"ltp":2.24,"tv":1.58,"id":424676}]}]}
{"op":"mcm","clk":"11777304303","pt":1722714909740,"mc":[{"id":"1.231344826","rc":[{"batb":[[0,2.16,10]],"ltp":2.24,"tv":1.58,"id":424676}]}]}
{"op":"mcm","clk":"11777304632","pt":1722714913026,"mc":[{"id":"1.231344826","rc":[{"batb":[[0,2.16,2]],"ltp":2.24,"tv":1.58,"id":424676}]}]}
{"op":"mcm","clk":"11777304835","pt":1722714915523,"mc":[{"id":"1.231344826","rc":[{"batb":[[0,2.14,35.43],[1,1.74,17.32],[2,1.44,85.28]],"ltp":2.24,"tv":1.58,"id":424676}]}]}
{"op":"mcm","clk":"11777304850","pt":1722714915621,"mc":[{"id":"1.231344826","rc":[{"batb":[[0,2.16,10],[1,2.14,35.43],[2,1.74,17.32]],"ltp":2.24,"tv":1.58,"id":424676}]}]}
{"op":"mcm","clk":"11777305163","pt":1722714919016,"mc":[{"id":"1.231344826","rc":[{"batb":[[0,2.16,2]],"ltp":2.24,"tv":1.58,"id":424676}]}]}
{"op":"mcm","clk":"11777305371","pt":1722714921327,"mc":[{"id":"1.231344826","rc":[{"batb":[[0,2.16,10]],"ltp":2.24,"tv":1.58,"id":424676}]}]}
{"op":"mcm","clk":"11777305666","pt":1722714924849,"mc":[{"id":"1.231344826","rc":[{"batb":[[0,2.16,2]],"ltp":2.24,"tv":1.58,"id":424676}]}]}
{"op":"mcm","clk":"11777305889","pt":1722714927344,"mc":[{"id":"1.231344826","rc":[{"batb":[[0,2.16,10]],"ltp":2.24,"tv":1.58,"id":424676}]}]}
{"op":"mcm","clk":"11777306161","pt":1722714930541,"mc":[{"id":"1.231344826","rc":[{"batb":[[0,2.18,2]],"ltp":2.24,"tv":1.58,"id":424676}]}]}
{"op":"mcm","clk":"11777306382","pt":1722714932742,"mc":[{"id":"1.231344826","rc":[{"batb":[[0,2.16,10]],"ltp":2.24,"tv":1.58,"id":424676}]}]}
{"op":"mcm","clk":"11777306748","pt":1722714936134,"mc":[{"id":"1.231344826","rc":[{"batb":[[0,2.18,2]],"ltp":2.24,"tv":1.58,"id":424676}]}]}
{"op":"mcm","clk":"11777306956","pt":1722714938541,"mc":[{"id":"1.231344826","rc":[{"batb":[[0,2.16,10]],"ltp":2.24,"tv":1.58,"id":424676}]}]}
{"op":"mcm","clk":"11777307161","pt":1722714941299,"mc":[{"id":"1.231344826","rc":[{"batb":[[0,2.18,2],[1,2.16,10],[2,2.14,35.43]],"ltp":2.24,"tv":1.58,"id":424676}]}]}
{"op":"mcm","clk":"11777307224","pt":1722714942078,"mc":[{"id":"1.231344826","rc":[{"batb":[[1,2.14,35.43],[2,1.74,17.32]],"ltp":2.24,"tv":1.58,"id":424676}]}]}
{"op":"mcm","clk":"11777307364","pt":1722714943662,"mc":[{"id":"1.231344826","rc":[{"batb":[[0,2.14,35.43],[1,1.74,17.32],[2,1.44,85.28]],"ltp":2.24,"tv":1.58,"id":424676}]}]}
{"op":"mcm","clk":"11777307482","pt":1722714944953,"mc":[{"id":"1.231344826","rc":[{"batb":[[0,2.16,10],[1,2.14,35.43],[2,1.74,17.32]],"ltp":2.24,"tv":1.58,"id":424676}]}]}
{"op":"mcm","clk":"11777307628","pt":1722714946565,"mc":[{"id":"1.231344826","rc":[{"batb":[[0,2.18,2],[1,2.16,10],[2,2.14,35.43]],"ltp":2.24,"tv":1.58,"id":424676}]}]}
{"op":"mcm","clk":"11777307791","pt":1722714948363,"mc":[{"id":"1.231344826","rc":[{"batb":[[1,2.14,35.43],[2,1.74,17.32]],"ltp":2.24,"tv":1.58,"id":424676}]}]}
{"op":"mcm","clk":"11777307852","pt":1722714948966,"mc":[{"id":"1.231344826","rc":[{"batb":[[0,2.14,35.43],[1,1.74,17.32],[2,1.44,85.28]],"ltp":2.24,"tv":1.58,"id":424676}]}]}
{"op":"mcm","clk":"11777308061","pt":1722714951368,"mc":[{"id":"1.231344826","rc":[{"batb":[[0,2.16,12],[1,2.14,35.43],[2,1.74,17.32]],"ltp":2.24,"tv":1.58,"id":424676}]}]}
{"op":"mcm","clk":"11777308255","pt":1722714953869,"mc":[{"id":"1.231344826","rc":[{"batb":[[0,2.16,10]],"ltp":2.24,"tv":1.58,"id":424676}]}]}
{"op":"mcm","clk":"11777308321","pt":1722714954659,"mc":[{"id":"1.231344826","rc":[{"batb":[[0,2.14,35.43],[1,1.74,17.32],[2,1.44,85.28]],"ltp":2.24,"tv":1.58,"id":424676}]}]}
{"op":"mcm","clk":"11777308925","pt":1722714962160,"mc":[{"id":"1.231344826","rc":[{"batb":[[0,2.16,12],[1,2.14,35.43],[2,1.74,17.32]],"ltp":2.24,"tv":1.58,"id":424676}]}]}
{"op":"mcm","clk":"11777309127","pt":1722714964569,"mc":[{"id":"1.231344826","rc":[{"batb":[[0,2.16,10]],"ltp":2.24,"tv":1.58,"id":424676}]}]}
{"op":"mcm","clk":"11777309201","pt":1722714965761,"mc":[{"id":"1.231344826","rc":[{"batb":[[0,2.14,35.43],[1,1.74,17.32],[2,1.44,85.28]],"ltp":2.24,"tv":1.58,"id":424676}]}]}
{"op":"mcm","clk":"11777309996","pt":1722714974716,"mc":[{"id":"1.231344826","rc":[{"batb":[[0,2.16,12],[1,2.14,35.43],[2,1.74,17.32]],"ltp":2.24,"tv":1.58,"id":424676}]}]}
{"op":"mcm","clk":"11777310240","pt":1722714977204,"mc":[{"id":"1.231344826","rc":[{"batb":[[0,2.16,10]],"ltp":2.24,"tv":1.58,"id":424676}]}]}
{"op":"mcm","clk":"11777310305","pt":1722714977902,"mc":[{"id":"1.231344826","rc":[{"batb":[[0,2.14,35.43],[1,1.74,17.32],[2,1.44,85.28]],"ltp":2.24,"tv":1.58,"id":424676}]}]}
{"op":"mcm","clk":"11777310565","pt":1722714980905,"mc":[{"id":"1.231344826","rc":[{"batb":[[0,2.16,12],[1,2.14,35.43],[2,1.74,17.32]],"ltp":2.24,"tv":1.58,"id":424676}]}]}
{"op":"mcm","clk":"11777310757","pt":1722714983310,"mc":[{"id":"1.231344826","rc":[{"batb":[[0,2.16,10]],"ltp":2.24,"tv":1.58,"id":424676}]}]}
{"op":"mcm","clk":"11777310829","pt":1722714984122,"mc":[{"id":"1.231344826","rc":[{"batb":[[0,2.14,35.43],[1,1.74,17.32],[2,1.44,85.28]],"ltp":2.24,"tv":1.58,"id":424676}]}]}
{"op":"mcm","clk":"11777310964","pt":1722714985908,"mc":[{"id":"1.231344826","rc":[{"batb":[[0,2.16,2],[1,2.14,35.43],[2,1.74,17.32]],"ltp":2.24,"tv":1.58,"id":424676}]}]}
{"op":"mcm","clk":"11777311158","pt":1722714988296,"mc":[{"id":"1.231344826","rc":[{"batb":[[0,2.16,10]],"ltp":2.24,"tv":1.58,"id":424676}]}]}
{"op":"mcm","clk":"11777311352","pt":1722714990690,"mc":[{"id":"1.231344826","rc":[{"batb":[[0,2.18,2],[1,2.16,10],[2,2.14,35.43]],"ltp":2.24,"tv":1.58,"id":424676}]}]}
{"op":"mcm","clk":"11777311434","pt":1722714991725,"mc":[{"id":"1.231344826","rc":[{"batb":[[1,2.14,35.43],[2,1.74,17.32]],"ltp":2.24,"tv":1.58,"id":424676}]}]}
{"op":"mcm","clk":"11777311544","pt":1722714992921,"mc":[{"id":"1.231344826","rc":[{"batb":[[0,2.14,35.43],[1,1.74,17.32],[2,1.44,85.28]],"ltp":2.24,"tv":1.58,"id":424676}]}]}
{"op":"mcm","clk":"11777311833","pt":1722714997222,"mc":[{"id":"1.231344826","rc":[{"batb":[[0,2.16,12],[1,2.14,35.43],[2,1.74,17.32]],"ltp":2.24,"tv":1.58,"id":424676}]}]}
{"op":"mcm","clk":"11777312084","pt":1722715000498,"mc":[{"id":"1.231344826","rc":[{"batb":[[0,2.14,35.43],[1,1.74,17.32],[2,1.44,85.28]],"ltp":2.24,"tv":1.58,"id":424676}]}]}
{"op":"mcm","clk":"11777312287","pt":1722715003040,"mc":[{"id":"1.231344826","rc":[{"batl":[[0,1.79,2],[1,1.8,49.17],[2,1.81,200]],"ltp":1.8,"tv":107.05,"id":2780},{"batb":[[0,2.16,12],[1,2.14,35.43],[2,1.74,17.32]],"ltp":2.24,"tv":1.58,"id":424676}]}]}
{"op":"mcm","clk":"11777312439","pt":1722715005323,"mc":[{"id":"1.231344826","rc":[{"batb":[[0,2.16,10]],"ltp":2.24,"tv":1.58,"id":424676}]}]}
{"op":"mcm","clk":"11777312529","pt":1722715006314,"mc":[{"id":"1.231344826","rc":[{"batb":[[0,2.14,35.43],[1,1.74,17.32],[2,1.44,85.28]],"ltp":2.24,"tv":1.58,"id":424676}]}]}
{"op":"mcm","clk":"11777312961","pt":1722715011317,"mc":[{"id":"1.231344826","rc":[{"batb":[[0,2.16,12],[1,2.14,35.43],[2,1.74,17.32]],"ltp":2.24,"tv":1.58,"id":424676}]}]}
{"op":"mcm","clk":"11777313133","pt":1722715013649,"mc":[{"id":"1.231344826","rc":[{"batb":[[0,2.16,10]],"ltp":2.24,"tv":1.58,"id":424676}]}]}
{"op":"mcm","clk":"11777313198","pt":1722715014632,"mc":[{"id":"1.231344826","rc":[{"batb":[[0,2.14,35.43],[1,1.74,17.32],[2,1.44,85.28]],"ltp":2.24,"tv":1.58,"id":424676}]}]}
{"op":"mcm","clk":"11777313401","pt":1722715017923,"mc":[{"id":"1.231344826","rc":[{"batb":[[0,2.16,12],[1,2.14,35.43],[2,1.74,17.32]],"ltp":2.24,"tv":1.58,"id":424676}]}]}
{"op":"mcm","clk":"11777313535","pt":1722715020159,"mc":[{"id":"1.231344826","rc":[{"batb":[[0,2.16,10]],"ltp":2.24,"tv":1.58,"id":424676}]}]}
{"op":"mcm","clk":"11777313623","pt":1722715021145,"mc":[{"id":"1.231344826","rc":[{"batb":[[0,2.14,35.43],[1,1.74,17.32],[2,1.44,85.28]],"ltp":2.24,"tv":1.58,"id":424676}]}]}
{"op":"mcm","clk":"11777313700","pt":1722715022557,"mc":[{"id":"1.231344826","rc":[{"batb":[[0,2.16,2],[1,2.14,35.43],[2,1.74,17.32]],"ltp":2.24,"tv":1.58,"id":424676}]}]}
{"op":"mcm","clk":"11777313888","pt":1722715025070,"mc":[{"id":"1.231344826","rc":[{"batb":[[0,2.16,10]],"ltp":2.24,"tv":1.58,"id":424676}]}]}
{"op":"mcm","clk":"11777314099","pt":1722715028358,"mc":[{"id":"1.231344826","rc":[{"batb":[[0,2.18,2]],"ltp":2.24,"tv":1.58,"id":424676}]}]}
{"op":"mcm","clk":"11777314239","pt":1722715030444,"mc":[{"id":"1.231344826","rc":[{"batb":[[0,2.16,10]],"ltp":2.24,"tv":1.58,"id":424676}]}]}
{"op":"mcm","clk":"11777314405","pt":1722715032842,"mc":[{"id":"1.231344826","rc":[{"batb":[[0,2.18,2],[1,2.16,10],[2,2.14,35.43]],"ltp":2.24,"tv":1.58,"id":424676}]}]}
{"op":"mcm","clk":"11777314456","pt":1722715033731,"mc":[{"id":"1.231344826","rc":[{"batb":[[1,2.14,35.43],[2,1.74,17.32]],"ltp":2.24,"tv":1.58,"id":424676}]}]}
{"op":"mcm","clk":"11777314552","pt":1722715035175,"mc":[{"id":"1.231344826","rc":[{"batb":[[0,2.14,35.43],[1,1.74,17.32],[2,1.44,85.28]],"ltp":2.24,"tv":1.58,"id":424676}]}]}
{"op":"mcm","clk":"11777314849","pt":1722715039242,"mc":[{"id":"1.231344826","rc":[{"batb":[[0,2.16,12],[1,2.14,35.43],[2,1.74,17.32]],"ltp":2.24,"tv":1.58,"id":424676}]}]}
{"op":"mcm","clk":"11777315014","pt":1722715041586,"mc":[{"id":"1.231344826","rc":[{"batb":[[0,2.16,10]],"ltp":2.24,"tv":1.58,"id":424676}]}]}
{"op":"mcm","clk":"11777315084","pt":1722715042570,"mc":[{"id":"1.231344826","rc":[{"batb":[[0,2.14,35.43],[1,1.74,17.32],[2,1.44,85.28]],"ltp":2.24,"tv":1.58,"id":424676}]}]}
{"op":"mcm","clk":"11777315157","pt":1722715044077,"mc":[{"id":"1.231344826","rc":[{"batb":[[0,2.16,2],[1,2.14,35.43],[2,1.74,17.32]],"ltp":2.24,"tv":1.58,"id":424676}]}]}
{"op":"mcm","clk":"11777315343","pt":1722715046463,"mc":[{"id":"1.231344826","rc":[{"batb":[[0,2.16,10]],"ltp":2.24,"tv":1.58,"id":424676}]}]}
{"op":"mcm","clk":"11777315579","pt":1722715049992,"mc":[{"id":"1.231344826","rc":[{"batb":[[0,2.16,2]],"ltp":2.24,"tv":1.58,"id":424676}]}]}
{"op":"mcm","clk":"11777315758","pt":1722715052352,"mc":[{"id":"1.231344826","rc":[{"batb":[[0,2.16,10]],"ltp":2.24,"tv":1.58,"id":424676}]}]}
{"op":"mcm","clk":"11777316044","pt":1722715055468,"mc":[{"id":"1.231344826","rc":[{"batb":[[0,2.14,35.43],[1,1.74,17.32],[2,1.44,85.28]],"ltp":2.24,"tv":1.58,"id":424676}]}]}
{"op":"mcm","clk":"11777316059","pt":1722715055675,"mc":[{"id":"1.231344826","rc":[{"batb":[[0,2.16,2],[1,2.14,35.43],[2,1.74,17.32]],"ltp":2.24,"tv":1.58,"id":424676}]}]}
{"op":"mcm","clk":"11777316232","pt":1722715058267,"mc":[{"id":"1.231344826","rc":[{"batb":[[0,2.16,10]],"ltp":2.24,"tv":1.58,"id":424676}]}]}
{"op":"mcm","clk":"11777316443","pt":1722715061468,"mc":[{"id":"1.231344826","rc":[{"batb":[[0,2.14,35.43],[1,1.74,17.32],[2,1.44,85.28]],"ltp":2.24,"tv":1.58,"id":424676}]}]}
{"op":"mcm","clk":"11777316460","pt":1722715061674,"mc":[{"id":"1.231344826","rc":[{"batb":[[0,2.16,2],[1,2.14,35.43],[2,1.74,17.32]],"ltp":2.24,"tv":1.58,"id":424676}]}]}
{"op":"mcm","clk":"11777316628","pt":1722715064060,"mc":[{"id":"1.231344826","rc":[{"batb":[[0,2.16,10]],"ltp":2.24,"tv":1.58,"id":424676}]}]}
{"op":"mcm","clk":"11777316824","pt":1722715067380,"mc":[{"id":"1.231344826","rc":[{"batb":[[0,2.16,2]],"ltp":2.24,"tv":1.58,"id":424676}]}]}
{"op":"mcm","clk":"11777316997","pt":1722715069983,"mc":[{"id":"1.231344826","rc":[{"batb":[[0,2.16,10]],"ltp":2.24,"tv":1.58,"id":424676}]}]}
{"op":"mcm","clk":"11777317237","pt":1722715073298,"mc":[{"id":"1.231344826","rc":[{"batb":[[0,2.16,2]],"ltp":2.24,"tv":1.58,"id":424676}]}]}
{"op":"mcm","clk":"11777317423","pt":1722715075688,"mc":[{"id":"1.231344826","rc":[{"batb":[[0,2.16,10]],"ltp":2.24,"tv":1.58,"id":424676}]}]}
{"op":"mcm","clk":"11777317653","pt":1722715079114,"mc":[{"id":"1.231344826","rc":[{"batb":[[0,2.16,2]],"ltp":2.24,"tv":1.58,"id":424676}]}]}
{"op":"mcm","clk":"11777317818","pt":1722715081513,"mc":[{"id":"1.231344826","rc":[{"batb":[[0,2.14,35.43],[1,1.74,17.32],[2,1.44,85.28]],"ltp":2.24,"tv":1.58,"id":424676}]}]}
{"op":"mcm","clk":"11777317822","pt":1722715081612,"mc":[{"id":"1.231344826","rc":[{"batb":[[0,2.16,10],[1,2.14,35.43],[2,1.74,17.32]],"ltp":2.24,"tv":1.58,"id":424676}]}]}
{"op":"mcm","clk":"11777318077","pt":1722715085207,"mc":[{"id":"1.231344826","rc":[{"batb":[[0,2.16,2]],"ltp":2.24,"tv":1.58,"id":424676}]}]}
{"op":"mcm","clk":"11777318245","pt":1722715087710,"mc":[{"id":"1.231344826","rc":[{"batb":[[0,2.16,10]],"ltp":2.24,"tv":1.58,"id":424676}]}]}
{"op":"mcm","clk":"11777318463","pt":1722715091027,"mc":[{"id":"1.231344826","rc":[{"batb":[[0,2.16,2]],"ltp":2.24,"tv":1.58,"id":424676}]}]}
{"op":"mcm","clk":"11777318637","pt":1722715093419,"mc":[{"id":"1.231344826","rc":[{"batb":[[0,2.16,10]],"ltp":2.24,"tv":1.58,"id":424676}]}]}
{"op":"mcm","clk":"11777318889","pt":1722715096701,"mc":[{"id":"1.231344826","rc":[{"batb":[[0,2.16,2]],"ltp":2.24,"tv":1.58,"id":424676}]}]}
{"op":"mcm","clk":"11777319059","pt":1722715099207,"mc":[{"id":"1.231344826","rc":[{"batb":[[0,2.16,10]],"ltp":2.24,"tv":1.58,"id":424676}]}]}
{"op":"mcm","clk":"11777319298","pt":1722715102533,"mc":[{"id":"1.231344826","rc":[{"batb":[[0,2.14,35.43],[1,1.74,17.32],[2,1.44,85.28]],"ltp":2.24,"tv":1.58,"id":424676}]}]}
{"op":"mcm","clk":"11777319309","pt":1722715102636,"mc":[{"id":"1.231344826","rc":[{"batb":[[0,2.16,2],[1,2.14,35.43],[2,1.74,17.32]],"ltp":2.24,"tv":1.58,"id":424676}]}]}
{"op":"mcm","clk":"11777319476","pt":1722715105238,"mc":[{"id":"1.231344826","rc":[{"batb":[[0,2.16,10]],"ltp":2.24,"tv":1.58,"id":424676}]}]}
{"op":"mcm","clk":"11777319727","pt":1722715108725,"mc":[{"id":"1.231344826","rc":[{"batb":[[0,2.16,2]],"ltp":2.24,"tv":1.58,"id":424676}]}]}
{"op":"mcm","clk":"11777319915","pt":1722715111330,"mc":[{"id":"1.231344826","rc":[{"batb":[[0,2.16,10]],"ltp":2.24,"tv":1.58,"id":424676}]}]}
{"op":"mcm","clk":"11777320158","pt":1722715114922,"mc":[{"id":"1.231344826","rc":[{"batb":[[0,2.16,2]],"ltp":2.24,"tv":1.58,"id":424676}]}]}
{"op":"mcm","clk":"11777320333","pt":1722715117515,"mc":[{"id":"1.231344826","rc":[{"batb":[[0,2.16,10]],"ltp":2.24,"tv":1.58,"id":424676}]}]}
{"op":"mcm","clk":"11777320567","pt":1722715120952,"mc":[{"id":"1.231344826","rc":[{"batb":[[0,2.16,2]],"ltp":2.24,"tv":1.58,"id":424676}]}]}
{"op":"mcm","clk":"11777320799","pt":1722715123402,"mc":[{"id":"1.231344826","rc":[{"batb":[[0,2.14,35.43],[1,1.74,17.32],[2,1.44,85.28]],"ltp":2.24,"tv":1.58,"id":424676}]}]}
{"op":"mcm","clk":"11777320816","pt":1722715123555,"mc":[{"id":"1.231344826","rc":[{"batb":[[0,2.16,10],[1,2.14,35.43],[2,1.74,17.32]],"ltp":2.24,"tv":1.58,"id":424676}]}]}
{"op":"mcm","clk":"11777321082","pt":1722715127065,"mc":[{"id":"1.231344826","rc":[{"batb":[[0,2.16,2]],"ltp":2.24,"tv":1.58,"id":424676}]}]}
{"op":"mcm","clk":"11777321326","pt":1722715129543,"mc":[{"id":"1.231344826","rc":[{"batb":[[0,2.16,10]],"ltp":2.24,"tv":1.58,"id":424676}]}]}
{"op":"mcm","clk":"11777321603","pt":1722715133250,"mc":[{"id":"1.231344826","rc":[{"batb":[[0,2.16,2]],"ltp":2.24,"tv":1.58,"id":424676}]}]}
{"op":"mcm","clk":"11777321831","pt":1722715135876,"mc":[{"id":"1.231344826","rc":[{"batb":[[0,2.16,10]],"ltp":2.24,"tv":1.58,"id":424676}]}]}
{"op":"mcm","clk":"11777322134","pt":1722715139353,"mc":[{"id":"1.231344826","rc":[{"batb":[[0,2.16,2]],"ltp":2.24,"tv":1.58,"id":424676}]}]}
{"op":"mcm","clk":"11777322365","pt":1722715141869,"mc":[{"id":"1.231344826","rc":[{"batb":[[0,2.16,10]],"ltp":2.24,"tv":1.58,"id":424676}]}]}
{"op":"mcm","clk":"11777322567","pt":1722715144005,"mc":[{"id":"1.231344826","rc":[{"batb":[[0,2.18,2],[1,2.16,10],[2,2.14,35.43]],"ltp":2.24,"tv":1.58,"id":424676}]}]}
{"op":"mcm","clk":"11777322710","pt":1722715145397,"mc":[{"id":"1.231344826","rc":[{"batb":[[1,2.14,35.43],[2,1.74,17.32]],"ltp":2.24,"tv":1.58,"id":424676}]}]}
{"op":"mcm","clk":"11777322803","pt":1722715146346,"mc":[{"id":"1.231344826","rc":[{"batb":[[0,2.14,35.43],[1,1.74,17.32],[2,1.44,85.28]],"ltp":2.24,"tv":1.58,"id":424676}]}]}
{"op":"mcm","clk":"11777323181","pt":1722715149675,"mc":[{"id":"1.231344826","rc":[{"batb":[[0,2.16,12],[1,2.14,35.43],[2,1.74,17.32]],"ltp":2.24,"tv":1.58,"id":424676}]}]}
{"op":"mcm","clk":"11777323368","pt":1722715151870,"mc":[{"id":"1.231344826","rc":[{"batb":[[0,2.16,10]],"ltp":2.24,"tv":1.58,"id":424676}]}]}
{"op":"mcm","clk":"11777323493","pt":1722715153099,"mc":[{"id":"1.231344826","rc":[{"batb":[[0,2.14,35.43],[1,1.74,17.32],[2,1.44,85.28]],"ltp":2.24,"tv":1.58,"id":424676}]}]}
{"op":"mcm","clk":"11777325784","pt":1722715183199,"mc":[{"id":"1.231344826","rc":[{"batb":[[0,2.16,12],[1,2.14,35.43],[2,1.74,17.32]],"ltp":2.24,"tv":1.58,"id":424676}]}]}
{"op":"mcm","clk":"11777326011","pt":1722715185505,"mc":[{"id":"1.231344826","rc":[{"batb":[[0,2.16,10]],"ltp":2.24,"tv":1.58,"id":424676}]}]}
{"op":"mcm","clk":"11777326079","pt":1722715186435,"mc":[{"id":"1.231344826","rc":[{"batb":[[0,2.14,35.43],[1,1.74,17.32],[2,1.44,85.28]],"ltp":2.24,"tv":1.58,"id":424676}]}]}
{"op":"mcm","clk":"11777326846","pt":1722715196636,"mc":[{"id":"1.231344826","rc":[{"batb":[[0,2.16,12],[1,2.14,35.43],[2,1.74,17.32]],"ltp":2.24,"tv":1.58,"id":424676}]}]}
{"op":"mcm","clk":"11777327031","pt":1722715199142,"mc":[{"id":"1.231344826","rc":[{"batb":[[0,2.16,10]],"ltp":2.24,"tv":1.58,"id":424676}]}]}
{"op":"mcm","clk":"11777327104","pt":1722715199928,"mc":[{"id":"1.231344826","rc":[{"batb":[[0,2.14,35.43],[1,1.74,17.32],[2,1.44,85.28]],"ltp":2.24,"tv":1.58,"id":424676}]}]}
{"op":"mcm","clk":"11777327420","pt":1722715202843,"mc":[{"id":"1.231344826","rc":[{"batb":[[0,2.16,12],[1,2.14,35.43],[2,1.74,17.32]],"ltp":2.24,"tv":1.58,"id":424676}]}]}
{"op":"mcm","clk":"11777327640","pt":1722715205165,"mc":[{"id":"1.231344826","rc":[{"batb":[[0,2.16,10]],"ltp":2.24,"tv":1.58,"id":424676}]}]}
{"op":"mcm","clk":"11777327733","pt":1722715206122,"mc":[{"id":"1.231344826","rc":[{"batb":[[0,2.14,35.43],[1,1.74,17.32],[2,1.44,85.28]],"ltp":2.24,"tv":1.58,"id":424676}]}]}
{"op":"mcm","clk":"11777328000","pt":1722715209255,"mc":[{"id":"1.231344826","rc":[{"batb":[[0,2.16,12],[1,2.14,35.43],[2,1.74,17.32]],"ltp":2.24,"tv":1.58,"id":424676}]}]}
{"op":"mcm","clk":"11777328197","pt":1722715211555,"mc":[{"id":"1.231344826","rc":[{"batb":[[0,2.16,10]],"ltp":2.24,"tv":1.58,"id":424676}]}]}
{"op":"mcm","clk":"11777328332","pt":1722715212766,"mc":[{"id":"1.231344826","rc":[{"batb":[[0,2.14,35.43],[1,1.74,17.32],[2,1.44,85.28]],"ltp":2.24,"tv":1.58,"id":424676}]}]}
{"op":"mcm","clk":"11777329226","pt":1722715221153,"mc":[{"id":"1.231344826","rc":[{"batb":[[0,2.16,12],[1,2.14,35.43],[2,1.74,17.32]],"ltp":2.24,"tv":1.58,"id":424676}]}]}
{"op":"mcm","clk":"11777329523","pt":1722715224268,"mc":[{"id":"1.231344826","rc":[{"batb":[[0,2.14,35.43],[1,1.74,17.32],[2,1.44,85.28]],"ltp":2.24,"tv":1.58,"id":424676}]}]}
{"op":"mcm","clk":"11777335188","pt":1722715289822,"mc":[{"id":"1.231344826","rc":[{"batb":[[0,2.16,12],[1,2.14,35.43],[2,1.74,17.32]],"ltp":2.24,"tv":1.58,"id":424676}]}]}
{"op":"mcm","clk":"11777335363","pt":1722715292117,"mc":[{"id":"1.231344826","rc":[{"batb":[[0,2.16,10]],"ltp":2.24,"tv":1.58,"id":424676}]}]}
{"op":"mcm","clk":"11777335450","pt":1722715293325,"mc":[{"id":"1.231344826","rc":[{"batb":[[0,2.14,35.43],[1,1.74,17.32],[2,1.44,85.28]],"ltp":2.24,"tv":1.58,"id":424676}]}]}
{"op":"mcm","clk":"11777361371","pt":1722715621349,"mc":[{"id":"1.231344826","rc":[{"batb":[[0,2.16,12],[1,2.14,35.43],[2,1.74,17.32]],"ltp":2.24,"tv":1.58,"id":424676}]}]}
{"op":"mcm","clk":"11777361526","pt":1722715623370,"mc":[{"id":"1.231344826","rc":[{"batb":[[0,2.16,10]],"ltp":2.24,"tv":1.58,"id":424676}]}]}
{"op":"mcm","clk":"11777361597","pt":1722715624258,"mc":[{"id":"1.231344826","rc":[{"batb":[[0,2.14,35.43],[1,1.74,17.32],[2,1.3,633.33]],"ltp":2.24,"tv":1.58,"id":424676}]}]}
{"op":"mcm","clk":"11777364520","pt":1722715659918,"mc":[{"id":"1.231344826","rc":[{"batb":[[0,2.16,12],[1,2.14,35.43],[2,1.74,17.32]],"ltp":2.24,"tv":1.58,"id":424676}]}]}
{"op":"mcm","clk":"11777364717","pt":1722715662216,"mc":[{"id":"1.231344826","rc":[{"batb":[[0,2.16,10]],"ltp":2.24,"tv":1.58,"id":424676}]}]}
{"op":"mcm","clk":"11777364809","pt":1722715663213,"mc":[{"id":"1.231344826","rc":[{"batb":[[0,2.14,35.43],[1,1.74,17.32],[2,1.3,633.33]],"ltp":2.24,"tv":1.58,"id":424676}]}]}
{"op":"mcm","clk":"11777379616","pt":1722715845208,"mc":[{"id":"1.231344826","rc":[{"batb":[[0,2.16,12],[1,2.14,35.43],[2,1.74,17.32]],"ltp":2.24,"tv":1.58,"id":424676}]}]}
{"op":"mcm","clk":"11777379906","pt":1722715848507,"mc":[{"id":"1.231344826","rc":[{"batb":[[0,2.14,35.43],[1,1.74,17.32],[2,1.3,633.33]],"ltp":2.24,"tv":1.58,"id":424676}]}]}
{"op":"mcm","clk":"11777391487","pt":1722715989756,"mc":[{"id":"1.231344826","rc":[{"batb":[[0,2.16,12],[1,2.14,35.43],[2,1.74,17.32]],"ltp":2.24,"tv":1.58,"id":424676}]}]}
{"op":"mcm","clk":"11777391728","pt":1722715992157,"mc":[{"id":"1.231344826","rc":[{"batb":[[0,2.16,10]],"ltp":2.24,"tv":1.58,"id":424676}]}]}
{"op":"mcm","clk":"11777391827","pt":1722715993155,"mc":[{"id":"1.231344826","rc":[{"batb":[[0,2.14,35.43],[1,1.74,17.32],[2,1.3,633.33]],"ltp":2.24,"tv":1.58,"id":424676}]}]}
{"op":"mcm","clk":"11777394433","pt":1722716021600,"mc":[{"id":"1.231344826","rc":[{"batb":[[0,2.16,12],[1,2.14,35.43],[2,1.74,17.32]],"ltp":2.24,"tv":1.58,"id":424676}]}]}
{"op":"mcm","clk":"11777394663","pt":1722716023910,"mc":[{"id":"1.231344826","rc":[{"batb":[[0,2.16,10]],"ltp":2.24,"tv":1.58,"id":424676}]}]}
{"op":"mcm","clk":"11777394744","pt":1722716024903,"mc":[{"id":"1.231344826","rc":[{"batb":[[0,2.14,35.43],[1,1.74,17.32],[2,1.3,633.33]],"ltp":2.24,"tv":1.58,"id":424676}]}]}
{"op":"mcm","clk":"11777421395","pt":1722716358280,"mc":[{"id":"1.231344826","rc":[{"batb":[[0,2.16,12],[1,2.14,35.43],[2,1.74,17.32]],"ltp":2.24,"tv":1.58,"id":424676}]}]}
{"op":"mcm","clk":"11777421537","pt":1722716361083,"mc":[{"id":"1.231344826","rc":[{"batb":[[0,2.16,10]],"ltp":2.24,"tv":1.58,"id":424676}]}]}
{"op":"mcm","clk":"11777421603","pt":1722716362087,"mc":[{"id":"1.231344826","rc":[{"batb":[[0,2.14,35.43],[1,1.74,17.32],[2,1.3,633.33]],"ltp":2.24,"tv":1.58,"id":424676}]}]}
{"op":"mcm","clk":"11777436941","pt":1722716582867,"mc":[{"id":"1.231344826","rc":[{"batb":[[0,2.16,12],[1,2.14,35.43],[2,1.74,17.32]],"ltp":2.24,"tv":1.58,"id":424676}]}]}
{"op":"mcm","clk":"11777437096","pt":1722716585403,"mc":[{"id":"1.231344826","rc":[{"batb":[[0,2.16,10]],"ltp":2.24,"tv":1.58,"id":424676}]}]}
{"op":"mcm","clk":"11777437163","pt":1722716586291,"mc":[{"id":"1.231344826","rc":[{"batb":[[0,2.14,35.43],[1,1.74,17.32],[2,1.3,633.33]],"ltp":2.24,"tv":1.58,"id":424676}]}]}
{"op":"mcm","clk":"11777444572","pt":1722716702712,"mc":[{"id":"1.231344826","rc":[{"batb":[[0,2.16,12],[1,2.14,35.43],[2,1.74,17.32]],"ltp":2.24,"tv":1.58,"id":424676}]}]}
{"op":"mcm","clk":"11777444699","pt":1722716705104,"mc":[{"id":"1.231344826","rc":[{"batb":[[0,2.16,10]],"ltp":2.24,"tv":1.58,"id":424676}]}]}
{"op":"mcm","clk":"11777444756","pt":1722716706114,"mc":[{"id":"1.231344826","rc":[{"batb":[[0,2.14,35.43],[1,1.74,17.32],[2,1.3,633.33]],"ltp":2.24,"tv":1.58,"id":424676}]}]}
{"op":"mcm","clk":"11777446696","pt":1722716741351,"mc":[{"id":"1.231344826","rc":[{"batb":[[0,2.16,12],[1,2.14,35.43],[2,1.74,17.32]],"ltp":2.24,"tv":1.58,"id":424676}]}]}
{"op":"mcm","clk":"11777446832","pt":1722716743750,"mc":[{"id":"1.231344826","rc":[{"batb":[[0,2.16,10]],"ltp":2.24,"tv":1.58,"id":424676}]}]}
{"op":"mcm","clk":"11777446877","pt":1722716744783,"mc":[{"id":"1.231344826","rc":[{"batb":[[0,2.14,35.43],[1,1.74,17.32],[2,1.3,633.33]],"ltp":2.24,"tv":1.58,"id":424676}]}]}
{"op":"mcm","clk":"11777448262","pt":1722716767682,"mc":[{"id":"1.231344826","rc":[{"batb":[[0,2.16,12],[1,2.14,35.43],[2,1.74,17.32]],"ltp":2.24,"tv":1.58,"id":424676}]}]}
{"op":"mcm","clk":"11777448416","pt":1722716770081,"mc":[{"id":"1.231344826","rc":[{"batb":[[0,2.16,10]],"ltp":2.24,"tv":1.58,"id":424676}]}]}
{"op":"mcm","clk":"11777448476","pt":1722716771072,"mc":[{"id":"1.231344826","rc":[{"batb":[[0,2.14,35.43],[1,1.74,17.32],[2,1.3,633.33]],"ltp":2.24,"tv":1.58,"id":424676}]}]}
{"op":"mcm","clk":"11777451843","pt":1722716822958,"mc":[{"id":"1.231344826","rc":[{"batb":[[0,2.16,12],[1,2.14,35.43],[2,1.74,17.32]],"ltp":2.24,"tv":1.58,"id":424676}]}]}
{"op":"mcm","clk":"11777452015","pt":1722716825521,"mc":[{"id":"1.231344826","rc":[{"batb":[[0,2.16,10]],"ltp":2.24,"tv":1.58,"id":424676}]}]}
{"op":"mcm","clk":"11777452069","pt":1722716826353,"mc":[{"id":"1.231344826","rc":[{"batb":[[0,2.14,35.43],[1,1.74,17.32],[2,1.3,633.33]],"ltp":2.24,"tv":1.58,"id":424676}]}]}
{"op":"mcm","clk":"11777452282","pt":1722716829736,"mc":[{"id":"1.231344826","rc":[{"batb":[[0,2.16,12],[1,2.14,35.43],[2,1.74,17.32]],"ltp":2.24,"tv":1.58,"id":424676}]}]}
{"op":"mcm","clk":"11777452454","pt":1722716832037,"mc":[{"id":"1.231344826","rc":[{"batb":[[0,2.16,10]],"ltp":2.24,"tv":1.58,"id":424676}]}]}
{"op":"mcm","clk":"11777452545","pt":1722716833032,"mc":[{"id":"1.231344826","rc":[{"batb":[[0,2.14,35.43],[1,1.74,17.32],[2,1.3,633.33]],"ltp":2.24,"tv":1.58,"id":424676}]}]}
{"op":"mcm","clk":"11777452851","pt":1722716837659,"mc":[{"id":"1.231344826","rc":[{"batb":[[0,2.16,12],[1,2.14,35.43],[2,1.74,17.32]],"ltp":2.24,"tv":1.58,"id":424676}]}]}
{"op":"mcm","clk":"11777453037","pt":1722716840244,"mc":[{"id":"1.231344826","rc":[{"batb":[[0,2.16,10]],"ltp":2.24,"tv":1.58,"id":424676}]}]}
{"op":"mcm","clk":"11777453085","pt":1722716840967,"mc":[{"id":"1.231344826","rc":[{"batb":[[0,2.14,35.43],[1,1.74,17.32],[2,1.3,633.33]],"ltp":2.24,"tv":1.58,"id":424676}]}]}
{"op":"mcm","clk":"11777454451","pt":1722716860780,"mc":[{"id":"1.231344826","rc":[{"batb":[[0,2.16,12],[1,2.14,35.43],[2,1.74,17.32]],"ltp":2.24,"tv":1.58,"id":424676}]}]}
{"op":"mcm","clk":"11777454608","pt":1722716863074,"mc":[{"id":"1.231344826","rc":[{"batb":[[0,2.16,10]],"ltp":2.24,"tv":1.58,"id":424676}]}]}
{"op":"mcm","clk":"11777454695","pt":1722716864065,"mc":[{"id":"1.231344826","rc":[{"batb":[[0,2.14,35.43],[1,1.74,17.32],[2,1.3,633.33]],"ltp":2.24,"tv":1.58,"id":424676}]}]}
{"op":"mcm","clk":"11777455322","pt":1722716871801,"mc":[{"id":"1.231344826","rc":[{"batb":[[0,2.16,12],[1,2.14,35.43],[2,1.74,17.32]],"ltp":2.24,"tv":1.58,"id":424676}]}]}
{"op":"mcm","clk":"11777455471","pt":1722716873993,"mc":[{"id":"1.231344826","rc":[{"batb":[[0,2.16,10]],"ltp":2.24,"tv":1.58,"id":424676}]}]}
{"op":"mcm","clk":"11777455537","pt":1722716875296,"mc":[{"id":"1.231344826","rc":[{"batb":[[0,2.14,35.43],[1,1.74,17.32],[2,1.3,633.33]],"ltp":2.24,"tv":1.58,"id":424676}]}]}
{"op":"mcm","clk":"11777461469","pt":1722716959297,"mc":[{"id":"1.231344826","rc":[{"batb":[[0,2.16,12],[1,2.14,35.43],[2,1.74,17.32]],"ltp":2.24,"tv":1.58,"id":424676}]}]}
{"op":"mcm","clk":"11777461642","pt":1722716961795,"mc":[{"id":"1.231344826","rc":[{"batb":[[0,2.16,10]],"ltp":2.24,"tv":1.58,"id":424676}]}]}
{"op":"mcm","clk":"11777461715","pt":1722716962792,"mc":[{"id":"1.231344826","rc":[{"batb":[[0,2.14,35.43],[1,1.74,17.32],[2,1.3,633.33]],"ltp":2.24,"tv":1.58,"id":424676}]}]}
{"op":"mcm","clk":"11777464203","pt":1722716996731,"mc":[{"id":"1.231344826","rc":[{"batb":[[0,2.16,12],[1,2.14,35.43],[2,1.74,17.32]],"ltp":2.24,"tv":1.58,"id":424676}]}]}
{"op":"mcm","clk":"11777464381","pt":1722716999235,"mc":[{"id":"1.231344826","rc":[{"batb":[[0,2.16,10]],"ltp":2.24,"tv":1.58,"id":424676}]}]}
{"op":"mcm","clk":"11777464447","pt":1722717000024,"mc":[{"id":"1.231344826","rc":[{"batb":[[0,2.14,35.43],[1,1.74,17.32],[2,1.3,633.33]],"ltp":2.24,"tv":1.58,"id":424676}]}]}
{"op":"mcm","clk":"11777469473","pt":1722717064426,"mc":[{"id":"1.231344826","rc":[{"batb":[[0,2.16,12],[1,2.14,35.43],[2,1.74,17.32]],"ltp":2.24,"tv":1.58,"id":424676}]}]}
{"op":"mcm","clk":"11777469658","pt":1722717066727,"mc":[{"id":"1.231344826","rc":[{"batb":[[0,2.16,10]],"ltp":2.24,"tv":1.58,"id":424676}]}]}
{"op":"mcm","clk":"11777469728","pt":1722717067920,"mc":[{"id":"1.231344826","rc":[{"batb":[[0,2.14,35.43],[1,1.74,17.32],[2,1.3,633.33]],"ltp":2.24,"tv":1.58,"id":424676}]}]}
{"op":"mcm","clk":"11777473785","pt":1722717126590,"mc":[{"id":"1.231344826","rc":[{"batb":[[0,2.16,12],[1,2.14,35.43],[2,1.74,17.32]],"ltp":2.24,"tv":1.58,"id":424676}]}]}
{"op":"mcm","clk":"11777473917","pt":1722717128934,"mc":[{"id":"1.231344826","rc":[{"batb":[[0,2.16,10]],"ltp":2.24,"tv":1.58,"id":424676}]}]}
{"op":"mcm","clk":"11777473966","pt":1722717129876,"mc":[{"id":"1.231344826","rc":[{"batb":[[0,2.14,35.43],[1,1.74,17.32],[2,1.3,633.33]],"ltp":2.24,"tv":1.58,"id":424676}]}]}
{"op":"mcm","clk":"11777474442","pt":1722717137680,"mc":[{"id":"1.231344826","rc":[{"batb":[[0,2.16,12],[1,2.14,35.43],[2,1.74,17.32]],"ltp":2.24,"tv":1.58,"id":424676}]}]}
{"op":"mcm","clk":"11777474583","pt":1722717140119,"mc":[{"id":"1.231344826","rc":[{"batb":[[0,2.16,10]],"ltp":2.24,"tv":1.58,"id":424676}]}]}
{"op":"mcm","clk":"11777474653","pt":1722717141105,"mc":[{"id":"1.231344826","rc":[{"batb":[[0,2.14,35.43],[1,1.74,17.32],[2,1.3,633.33]],"ltp":2.24,"tv":1.58,"id":424676}]}]}
{"op":"mcm","clk":"11777475495","pt":1722717154326,"mc":[{"id":"1.231344826","rc":[{"batb":[[0,2.16,12],[1,2.14,35.43],[2,1.74,17.32]],"ltp":2.24,"tv":1.58,"id":424676}]}]}
{"op":"mcm","clk":"11777475624","pt":1722717156726,"mc":[{"id":"1.231344826","rc":[{"batb":[[0,2.16,10]],"ltp":2.24,"tv":1.58,"id":424676}]}]}
{"op":"mcm","clk":"11777475669","pt":1722717157651,"mc":[{"id":"1.231344826","rc":[{"batb":[[0,2.14,35.43],[1,1.74,17.32],[2,1.3,633.33]],"ltp":2.24,"tv":1.58,"id":424676}]}]}
{"op":"mcm","clk":"11777483662","pt":1722717287059,"mc":[{"id":"1.231344826","rc":[{"batb":[[0,2.16,12],[1,2.14,35.43],[2,1.74,17.32]],"ltp":2.24,"tv":1.58,"id":424676}]}]}
{"op":"mcm","clk":"11777483813","pt":1722717289453,"mc":[{"id":"1.231344826","rc":[{"batb":[[0,2.16,10]],"ltp":2.24,"tv":1.58,"id":424676}]}]}
{"op":"mcm","clk":"11777483877","pt":1722717290351,"mc":[{"id":"1.231344826","rc":[{"batb":[[0,2.14,35.43],[1,1.74,17.32],[2,1.3,633.33]],"ltp":2.24,"tv":1.58,"id":424676}]}]}
{"op":"mcm","clk":"11777491263","pt":1722717409069,"mc":[{"id":"1.231344826","rc":[{"batb":[[0,2.16,12],[1,2.14,35.43],[2,1.74,17.32]],"ltp":2.24,"tv":1.58,"id":424676}]}]}
{"op":"mcm","clk":"11777491434","pt":1722717411294,"mc":[{"id":"1.231344826","rc":[{"batb":[[0,2.16,10]],"ltp":2.24,"tv":1.58,"id":424676}]}]}
{"op":"mcm","clk":"11777491522","pt":1722717412483,"mc":[{"id":"1.231344826","rc":[{"batb":[[0,2.14,35.43],[1,1.74,17.32],[2,1.3,633.33]],"ltp":2.24,"tv":1.58,"id":424676}]}]}
{"op":"mcm","clk":"11777502196","pt":1722717574575,"mc":[{"id":"1.231344826","rc":[{"batb":[[0,2.16,12],[1,2.14,35.43],[2,1.74,17.32]],"ltp":2.24,"tv":1.58,"id":424676}]}]}
{"op":"mcm","clk":"11777502390","pt":1722717577068,"mc":[{"id":"1.231344826","rc":[{"batb":[[0,2.16,10]],"ltp":2.24,"tv":1.58,"id":424676}]}]}
{"op":"mcm","clk":"11777502461","pt":1722717578107,"mc":[{"id":"1.231344826","rc":[{"batb":[[0,2.14,35.43],[1,1.74,17.32],[2,1.3,633.33]],"ltp":2.24,"tv":1.58,"id":424676}]}]}
{"op":"mcm","clk":"11777505404","pt":1722717627115,"mc":[{"id":"1.231344826","rc":[{"batb":[[0,2.16,12],[1,2.14,35.43],[2,1.74,17.32]],"ltp":2.24,"tv":1.58,"id":424676}]}]}
{"op":"mcm","clk":"11777505588","pt":1722717629609,"mc":[{"id":"1.231344826","rc":[{"batb":[[0,2.16,10]],"ltp":2.24,"tv":1.58,"id":424676}]}]}
{"op":"mcm","clk":"11777505664","pt":1722717630651,"mc":[{"id":"1.231344826","rc":[{"batb":[[0,2.14,35.43],[1,1.74,17.32],[2,1.3,633.33]],"ltp":2.24,"tv":1.58,"id":424676}]}]}
{"op":"mcm","clk":"11777507819","pt":1722717667472,"mc":[{"id":"1.231344826","rc":[{"batb":[[0,2.16,12],[1,2.14,35.43],[2,1.74,17.32]],"ltp":2.24,"tv":1.58,"id":424676}]}]}
{"op":"mcm","clk":"11777507980","pt":1722717669969,"mc":[{"id":"1.231344826","rc":[{"batb":[[0,2.16,10]],"ltp":2.24,"tv":1.58,"id":424676}]}]}
{"op":"mcm","clk":"11777508036","pt":1722717670960,"mc":[{"id":"1.231344826","rc":[{"batb":[[0,2.14,35.43],[1,1.74,17.32],[2,1.3,633.33]],"ltp":2.24,"tv":1.58,"id":424676}]}]}
{"op":"mcm","clk":"11777509076","pt":1722717689391,"mc":[{"id":"1.231344826","rc":[{"batb":[[0,2.16,12],[1,2.14,35.43],[2,1.74,17.32]],"ltp":2.24,"tv":1.58,"id":424676}]}]}
{"op":"mcm","clk":"11777509203","pt":1722717691684,"mc":[{"id":"1.231344826","rc":[{"batb":[[0,2.16,10]],"ltp":2.24,"tv":1.58,"id":424676}]}]}
{"op":"mcm","clk":"11777509267","pt":1722717692676,"mc":[{"id":"1.231344826","rc":[{"batb":[[0,2.14,35.43],[1,1.74,17.32],[2,1.3,633.33]],"ltp":2.24,"tv":1.58,"id":424676}]}]}
{"op":"mcm","clk":"11777509676","pt":1722717699899,"mc":[{"id":"1.231344826","rc":[{"batb":[[0,2.16,12],[1,2.14,35.43],[2,1.74,17.32]],"ltp":2.24,"tv":1.58,"id":424676}]}]}
{"op":"mcm","clk":"11777509807","pt":1722717702394,"mc":[{"id":"1.231344826","rc":[{"batb":[[0,2.16,10]],"ltp":2.24,"tv":1.58,"id":424676}]}]}
{"op":"mcm","clk":"11777509848","pt":1722717703119,"mc":[{"id":"1.231344826","rc":[{"batb":[[0,2.14,35.43],[1,1.74,17.32],[2,1.3,633.33]],"ltp":2.24,"tv":1.58,"id":424676}]}]}
{"op":"mcm","clk":"11777510111","pt":1722717708109,"mc":[{"id":"1.231344826","rc":[{"batb":[[0,2.16,12],[1,2.14,35.43],[2,1.74,17.32]],"ltp":2.24,"tv":1.58,"id":424676}]}]}
{"op":"mcm","clk":"11777510296","pt":1722717711537,"mc":[{"id":"1.231344826","rc":[{"batb":[[0,2.14,35.43],[1,1.74,17.32],[2,1.3,633.33]],"ltp":2.24,"tv":1.58,"id":424676}]}]}
{"op":"mcm","clk":"11777512844","pt":1722717756598,"mc":[{"id":"1.231344826","rc":[{"batb":[[0,2.16,12],[1,2.14,35.43],[2,1.74,17.32]],"ltp":2.24,"tv":1.58,"id":424676}]}]}
{"op":"mcm","clk":"11777513004","pt":1722717759198,"mc":[{"id":"1.231344826","rc":[{"batb":[[0,2.16,10]],"ltp":2.24,"tv":1.58,"id":424676}]}]}
{"op":"mcm","clk":"11777513064","pt":1722717760180,"mc":[{"id":"1.231344826","rc":[{"batb":[[0,2.14,35.43],[1,1.74,17.32],[2,1.3,633.33]],"ltp":2.24,"tv":1.58,"id":424676}]}]}
{"op":"mcm","clk":"11777519730","pt":1722717874194,"mc":[{"id":"1.231344826","rc":[{"batb":[[0,2.16,12],[1,2.14,35.43],[2,1.74,17.32]],"ltp":2.24,"tv":1.58,"id":424676}]}]}
{"op":"mcm","clk":"11777519857","pt":1722717876480,"mc":[{"id":"1.231344826","rc":[{"batb":[[0,2.16,10]],"ltp":2.24,"tv":1.58,"id":424676}]}]}
{"op":"mcm","clk":"11777519904","pt":1722717877474,"mc":[{"id":"1.231344826","rc":[{"batb":[[0,2.14,35.43],[1,1.74,17.32],[2,1.3,633.33]],"ltp":2.24,"tv":1.58,"id":424676}]}]}
{"op":"mcm","clk":"11777520013","pt":1722717879606,"mc":[{"id":"1.231344826","rc":[{"batb":[[0,2.16,2],[1,2.14,35.43],[2,1.74,17.32]],"ltp":2.24,"tv":1.58,"id":424676}]}]}
{"op":"mcm","clk":"11777520127","pt":1722717881905,"mc":[{"id":"1.231344826","rc":[{"batb":[[0,2.16,10]],"ltp":2.24,"tv":1.58,"id":424676}]}]}
{"op":"mcm","clk":"11777520314","pt":1722717885384,"mc":[{"id":"1.231344826","rc":[{"batb":[[0,2.16,2]],"ltp":2.24,"tv":1.58,"id":424676}]}]}
{"op":"mcm","clk":"11777520464","pt":1722717888095,"mc":[{"id":"1.231344826","rc":[{"batb":[[0,2.16,10]],"ltp":2.24,"tv":1.58,"id":424676}]}]}
{"op":"mcm","clk":"11777520715","pt":1722717891105,"mc":[{"id":"1.231344826","rc":[{"batb":[[0,2.18,2],[1,2.16,10],[2,2.14,35.43]],"ltp":2.24,"tv":1.58,"id":424676}]}]}
{"op":"mcm","clk":"11777520747","pt":1722717891621,"mc":[{"id":"1.231344826","rc":[{"batb":[[1,2.14,35.43],[2,1.74,17.32]],"ltp":2.24,"tv":1.58,"id":424676}]}]}
{"op":"mcm","clk":"11777520877","pt":1722717893905,"mc":[{"id":"1.231344826","rc":[{"batb":[[0,2.16,10]],"ltp":2.24,"tv":1.58,"id":424676}]}]}
{"op":"mcm","clk":"11777521077","pt":1722717897425,"mc":[{"id":"1.231344826","rc":[{"batb":[[0,2.16,2]],"ltp":2.24,"tv":1.58,"id":424676}]}]}
{"op":"mcm","clk":"11777521224","pt":1722717899812,"mc":[{"id":"1.231344826","rc":[{"batb":[[0,2.16,10]],"ltp":2.24,"tv":1.58,"id":424676}]}]}
{"op":"mcm","clk":"11777521467","pt":1722717903415,"mc":[{"id":"1.231344826","rc":[{"batb":[[0,2.16,2]],"ltp":2.24,"tv":1.58,"id":424676}]}]}
{"op":"mcm","clk":"11777521625","pt":1722717905701,"mc":[{"id":"1.231344826","rc":[{"batb":[[0,2.16,10]],"ltp":2.24,"tv":1.58,"id":424676}]}]}
{"op":"mcm","clk":"11777521852","pt":1722717909132,"mc":[{"id":"1.231344826","rc":[{"batb":[[0,2.16,2]],"ltp":2.24,"tv":1.58,"id":424676}]}]}
{"op":"mcm","clk":"11777522027","pt":1722717911522,"mc":[{"id":"1.231344826","rc":[{"batb":[[0,2.14,35.43],[1,1.74,17.32],[2,1.3,633.33]],"ltp":2.24,"tv":1.58,"id":424676}]}]}
{"op":"mcm","clk":"11777522035","pt":1722717911621,"mc":[{"id":"1.231344826","rc":[{"batb":[[0,2.16,10],[1,2.14,35.43],[2,1.74,17.32]],"ltp":2.24,"tv":1.58,"id":424676}]}]}
{"op":"mcm","clk":"11777522265","pt":1722717915051,"mc":[{"id":"1.231344826","rc":[{"batb":[[0,2.16,2]],"ltp":2.24,"tv":1.58,"id":424676}]}]}
{"op":"mcm","clk":"11777522424","pt":1722717917545,"mc":[{"id":"1.231344826","rc":[{"batb":[[0,2.16,10]],"ltp":2.24,"tv":1.58,"id":424676}]}]}
{"op":"mcm","clk":"11777522667","pt":1722717921044,"mc":[{"id":"1.231344826","rc":[{"batb":[[0,2.16,2]],"ltp":2.24,"tv":1.58,"id":424676}]}]}
{"op":"mcm","clk":"11777522827","pt":1722717923439,"mc":[{"id":"1.231344826","rc":[{"batb":[[0,2.14,35.43],[1,1.74,17.32],[2,1.3,633.33]],"ltp":2.24,"tv":1.58,"id":424676}]}]}
{"op":"mcm","clk":"11777522843","pt":1722717923647,"mc":[{"id":"1.231344826","rc":[{"batb":[[0,2.16,10],[1,2.14,35.43],[2,1.74,17.32]],"ltp":2.24,"tv":1.58,"id":424676}]}]}
{"op":"mcm","clk":"11777523063","pt":1722717926932,"mc":[{"id":"1.231344826","rc":[{"batb":[[0,2.16,2]],"ltp":2.24,"tv":1.58,"id":424676}]}]}
{"op":"mcm","clk":"11777523206","pt":1722717929360,"mc":[{"id":"1.231344826","rc":[{"batb":[[0,2.16,10]],"ltp":2.24,"tv":1.58,"id":424676}]}]}
{"op":"mcm","clk":"11777523513","pt":1722717932864,"mc":[{"id":"1.231344826","rc":[{"batb":[[0,2.16,2]],"ltp":2.24,"tv":1.58,"id":424676}]}]}
{"op":"mcm","clk":"11777523682","pt":1722717935482,"mc":[{"id":"1.231344826","rc":[{"batb":[[0,2.16,10]],"ltp":2.24,"tv":1.58,"id":424676}]}]}
{"op":"mcm","clk":"11777523869","pt":1722717938644,"mc":[{"id":"1.231344826","rc":[{"batb":[[0,2.16,2]],"ltp":2.24,"tv":1.58,"id":424676}]}]}
{"op":"mcm","clk":"11777523993","pt":1722717941138,"mc":[{"id":"1.231344826","rc":[{"batb":[[0,2.16,10]],"ltp":2.24,"tv":1.58,"id":424676}]}]}
{"op":"mcm","clk":"11777524185","pt":1722717944477,"mc":[{"id":"1.231344826","rc":[{"batb":[[0,2.16,2]],"ltp":2.24,"tv":1.58,"id":424676}]}]}
{"op":"mcm","clk":"11777524346","pt":1722717947077,"mc":[{"id":"1.231344826","rc":[{"batb":[[0,2.16,10]],"ltp":2.24,"tv":1.58,"id":424676}]}]}
{"op":"mcm","clk":"11777524559","pt":1722717950483,"mc":[{"id":"1.231344826","rc":[{"batb":[[0,2.16,2]],"ltp":2.24,"tv":1.58,"id":424676}]}]}
{"op":"mcm","clk":"11777524706","pt":1722717952871,"mc":[{"id":"1.231344826","rc":[{"batb":[[0,2.16,10]],"ltp":2.24,"tv":1.58,"id":424676}]}]}
{"op":"mcm","clk":"11777524904","pt":1722717956512,"mc":[{"id":"1.231344826","rc":[{"batb":[[0,2.16,2]],"ltp":2.24,"tv":1.58,"id":424676}]}]}
{"op":"mcm","clk":"11777525044","pt":1722717958782,"mc":[{"id":"1.231344826","rc":[{"batb":[[0,2.16,10]],"ltp":2.24,"tv":1.58,"id":424676}]}]}
{"op":"mcm","clk":"11777525194","pt":1722717961195,"mc":[{"id":"1.231344826","rc":[{"batb":[[0,2.18,2],[1,2.16,10],[2,2.14,35.43]],"ltp":2.24,"tv":1.58,"id":424676}]}]}
{"op":"mcm","clk":"11777525256","pt":1722717962185,"mc":[{"id":"1.231344826","rc":[{"batb":[[1,2.14,35.43],[2,1.74,17.32]],"ltp":2.24,"tv":1.58,"id":424676}]}]}
{"op":"mcm","clk":"11777525345","pt":1722717963595,"mc":[{"id":"1.231344826","rc":[{"batb":[[0,2.14,35.43],[1,1.74,17.32],[2,1.3,633.33]],"ltp":2.24,"tv":1.58,"id":424676}]}]}
{"op":"mcm","clk":"11777525470","pt":1722717965878,"mc":[{"id":"1.231344826","rc":[{"batb":[[0,2.16,12],[1,2.14,35.43],[2,1.74,17.32]],"ltp":2.24,"tv":1.58,"id":424676}]}]}
{"op":"mcm","clk":"11777525596","pt":1722717968112,"mc":[{"id":"1.231344826","rc":[{"batb":[[0,2.16,10]],"ltp":2.24,"tv":1.58,"id":424676}]}]}
{"op":"mcm","clk":"11777525682","pt":1722717969311,"mc":[{"id":"1.231344826","rc":[{"batb":[[0,2.14,35.43],[1,1.74,17.32],[2,1.3,633.33]],"ltp":2.24,"tv":1.58,"id":424676}]}]}
{"op":"mcm","clk":"11777526398","pt":1722717980114,"mc":[{"id":"1.231344826","rc":[{"batb":[[0,2.16,12],[1,2.14,35.43],[2,1.74,17.32]],"ltp":2.24,"tv":1.58,"id":424676}]}]}
{"op":"mcm","clk":"11777526543","pt":1722717982611,"mc":[{"id":"1.231344826","rc":[{"batb":[[0,2.16,10]],"ltp":2.24,"tv":1.58,"id":424676}]}]}
{"op":"mcm","clk":"11777526619","pt":1722717983651,"mc":[{"id":"1.231344826","rc":[{"batb":[[0,2.14,35.43],[1,1.74,17.32],[2,1.3,633.33]],"ltp":2.24,"tv":1.58,"id":424676}]}]}
{"op":"mcm","clk":"11777528877","pt":1722718019166,"mc":[{"id":"1.231344826","rc":[{"batb":[[0,2.16,12],[1,2.14,35.43],[2,1.74,17.32]],"ltp":2.24,"tv":1.58,"id":424676}]}]}
{"op":"mcm","clk":"11777529043","pt":1722718021371,"mc":[{"id":"1.231344826","rc":[{"batb":[[0,2.16,10]],"ltp":2.24,"tv":1.58,"id":424676}]}]}
{"op":"mcm","clk":"11777529141","pt":1722718022674,"mc":[{"id":"1.231344826","rc":[{"batb":[[0,2.14,35.43],[1,1.74,17.32],[2,1.3,633.33]],"ltp":2.24,"tv":1.58,"id":424676}]}]}
{"op":"mcm","clk":"11777529511","pt":1722718027954,"mc":[{"id":"1.231344826","rc":[{"batb":[[0,2.16,12],[1,2.14,35.43],[2,1.74,17.32]],"ltp":2.24,"tv":1.58,"id":424676}]}]}
{"op":"mcm","clk":"11777529676","pt":1722718030388,"mc":[{"id":"1.231344826","rc":[{"batb":[[0,2.16,10]],"ltp":2.24,"tv":1.58,"id":424676}]}]}
{"op":"mcm","clk":"11777529764","pt":1722718031586,"mc":[{"id":"1.231344826","rc":[{"batb":[[0,2.14,35.43],[1,1.74,17.32],[2,1.3,633.33]],"ltp":2.24,"tv":1.58,"id":424676}]}]}
{"op":"mcm","clk":"11777532711","pt":1722718074539,"mc":[{"id":"1.231344826","rc":[{"batb":[[0,2.16,12],[1,2.14,35.43],[2,1.74,17.32]],"ltp":2.24,"tv":1.58,"id":424676}]}]}
{"op":"mcm","clk":"11777532870","pt":1722718076842,"mc":[{"id":"1.231344826","rc":[{"batb":[[0,2.16,10]],"ltp":2.24,"tv":1.58,"id":424676}]}]}
{"op":"mcm","clk":"11777532943","pt":1722718077836,"mc":[{"id":"1.231344826","rc":[{"batb":[[0,2.14,35.43],[1,1.74,17.32],[2,1.3,633.33]],"ltp":2.24,"tv":1.58,"id":424676}]}]}
{"op":"mcm","clk":"11777533479","pt":1722718085746,"mc":[{"id":"1.231344826","rc":[{"batb":[[0,2.16,12],[1,2.14,35.43],[2,1.74,17.32]],"ltp":2.24,"tv":1.58,"id":424676}]}]}
{"op":"mcm","clk":"11777533631","pt":1722718088136,"mc":[{"id":"1.231344826","rc":[{"batb":[[0,2.16,10]],"ltp":2.24,"tv":1.58,"id":424676}]}]}
{"op":"mcm","clk":"11777533691","pt":1722718089129,"mc":[{"id":"1.231344826","rc":[{"batb":[[0,2.14,35.43],[1,1.74,17.32],[2,1.3,633.33]],"ltp":2.24,"tv":1.58,"id":424676}]}]}
{"op":"mcm","clk":"11777535046","pt":1722718110486,"mc":[{"id":"1.231344826","rc":[{"batb":[[0,2.16,12],[1,2.14,35.43],[2,1.74,17.32]],"ltp":2.24,"tv":1.58,"id":424676}]}]}
{"op":"mcm","clk":"11777535208","pt":1722718112882,"mc":[{"id":"1.231344826","rc":[{"batb":[[0,2.16,10]],"ltp":2.24,"tv":1.58,"id":424676}]}]}
{"op":"mcm","clk":"11777535275","pt":1722718113868,"mc":[{"id":"1.231344826","rc":[{"batb":[[0,2.14,35.43],[1,1.74,17.32],[2,1.3,633.33]],"ltp":2.24,"tv":1.58,"id":424676}]}]}
{"op":"mcm","clk":"11777536271","pt":1722718128563,"mc":[{"id":"1.231344826","rc":[{"batb":[[0,2.16,12],[1,2.14,35.43],[2,1.74,17.32]],"ltp":2.24,"tv":1.58,"id":424676}]}]}
{"op":"mcm","clk":"11777536445","pt":1722718130794,"mc":[{"id":"1.231344826","rc":[{"batb":[[0,2.16,10]],"ltp":2.24,"tv":1.58,"id":424676}]}]}
{"op":"mcm","clk":"11777536525","pt":1722718132093,"mc":[{"id":"1.231344826","rc":[{"batb":[[0,2.14,35.43],[1,1.74,17.32],[2,1.3,633.33]],"ltp":2.24,"tv":1.58,"id":424676}]}]}
{"op":"mcm","clk":"11777538067","pt":1722718156495,"mc":[{"id":"1.231344826","rc":[{"batb":[[0,2.16,12],[1,2.14,35.43],[2,1.74,17.32]],"ltp":2.24,"tv":1.58,"id":424676}]}]}
{"op":"mcm","clk":"11777538200","pt":1722718158825,"mc":[{"id":"1.231344826","rc":[{"batb":[[0,2.16,10]],"ltp":2.24,"tv":1.58,"id":424676}]}]}
{"op":"mcm","clk":"11777538264","pt":1722718159811,"mc":[{"id":"1.231344826","rc":[{"batb":[[0,2.14,35.43],[1,1.74,17.32],[2,1.3,633.33]],"ltp":2.24,"tv":1.58,"id":424676}]}]}
{"op":"mcm","clk":"11777539255","pt":1722718175619,"mc":[{"id":"1.231344826","rc":[{"batb":[[0,2.16,12],[1,2.14,35.43],[2,1.74,17.32]],"ltp":2.24,"tv":1.58,"id":424676}]}]}
{"op":"mcm","clk":"11777539398","pt":1722718178113,"mc":[{"id":"1.231344826","rc":[{"batb":[[0,2.16,10]],"ltp":2.24,"tv":1.58,"id":424676}]}]}
{"op":"mcm","clk":"11777539458","pt":1722718178936,"mc":[{"id":"1.231344826","rc":[{"batb":[[0,2.14,35.43],[1,1.74,17.32],[2,1.3,633.33]],"ltp":2.24,"tv":1.58,"id":424676}]}]}
{"op":"mcm","clk":"11777539653","pt":1722718181746,"mc":[{"id":"1.231344826","rc":[{"batb":[[0,2.16,12],[1,2.14,35.43],[2,1.74,17.32]],"ltp":2.24,"tv":1.58,"id":424676}]}]}
{"op":"mcm","clk":"11777539797","pt":1722718184246,"mc":[{"id":"1.231344826","rc":[{"batb":[[0,2.16,10]],"ltp":2.24,"tv":1.58,"id":424676}]}]}
{"op":"mcm","clk":"11777539845","pt":1722718185234,"mc":[{"id":"1.231344826","rc":[{"batb":[[0,2.14,35.43],[1,1.74,17.32],[2,1.3,633.33]],"ltp":2.24,"tv":1.58,"id":424676}]}]}
{"op":"mcm","clk":"11777540170","pt":1722718190468,"mc":[{"id":"1.231344826","rc":[{"batb":[[0,2.16,12],[1,2.14,35.43],[2,1.74,17.32]],"ltp":2.24,"tv":1.58,"id":424676}]}]}
{"op":"mcm","clk":"11777540315","pt":1722718192754,"mc":[{"id":"1.231344826","rc":[{"batb":[[0,2.16,10]],"ltp":2.24,"tv":1.58,"id":424676}]}]}
{"op":"mcm","clk":"11777540370","pt":1722718193857,"mc":[{"id":"1.231344826","rc":[{"batb":[[0,2.14,35.43],[1,1.74,17.32],[2,1.3,633.33]],"ltp":2.24,"tv":1.58,"id":424676}]}]}
{"op":"mcm","clk":"11777541827","pt":1722718216155,"mc":[{"id":"1.231344826","rc":[{"batb":[[0,2.16,12],[1,2.14,35.43],[2,1.74,17.32]],"ltp":2.24,"tv":1.58,"id":424676}]}]}
{"op":"mcm","clk":"11777541969","pt":1722718218480,"mc":[{"id":"1.231344826","rc":[{"batb":[[0,2.16,10]],"ltp":2.24,"tv":1.58,"id":424676}]}]}
{"op":"mcm","clk":"11777542028","pt":1722718219465,"mc":[{"id":"1.231344826","rc":[{"batb":[[0,2.14,35.43],[1,1.74,17.32],[2,1.3,633.33]],"ltp":2.24,"tv":1.58,"id":424676}]}]}
{"op":"mcm","clk":"11777542530","pt":1722718227661,"mc":[{"id":"1.231344826","rc":[{"batb":[[0,2.16,12],[1,2.14,35.43],[2,1.74,17.32]],"ltp":2.24,"tv":1.58,"id":424676}]}]}
{"op":"mcm","clk":"11777542655","pt":1722718229981,"mc":[{"id":"1.231344826","rc":[{"batb":[[0,2.16,10]],"ltp":2.24,"tv":1.58,"id":424676}]}]}
{"op":"mcm","clk":"11777542722","pt":1722718231175,"mc":[{"id":"1.231344826","rc":[{"batb":[[0,2.14,35.43],[1,1.74,17.32],[2,1.3,633.33]],"ltp":2.24,"tv":1.58,"id":424676}]}]}
{"op":"mcm","clk":"11777544271","pt":1722718257126,"mc":[{"id":"1.231344826","rc":[{"batb":[[0,2.16,12],[1,2.14,35.43],[2,1.74,17.32]],"ltp":2.24,"tv":1.58,"id":424676}]}]}
{"op":"mcm","clk":"11777544504","pt":1722718260538,"mc":[{"id":"1.231344826","rc":[{"batb":[[0,2.14,35.43],[1,1.74,17.32],[2,1.3,633.33]],"ltp":2.24,"tv":1.58,"id":424676}]}]}
{"op":"mcm","clk":"11777544624","pt":1722718262410,"mc":[{"id":"1.231344826","rc":[{"batb":[[0,2.16,2],[1,2.14,35.43],[2,1.74,17.32]],"ltp":2.24,"tv":1.58,"id":424676}]}]}
{"op":"mcm","clk":"11777544786","pt":1722718265106,"mc":[{"id":"1.231344826","rc":[{"batb":[[0,2.16,10]],"ltp":2.24,"tv":1.58,"id":424676}]}]}
{"op":"mcm","clk":"11777544908","pt":1722718267129,"mc":[{"id":"1.231344826","rc":[{"batb":[[0,2.18,2],[1,2.16,10],[2,2.14,35.43]],"ltp":2.24,"tv":1.58,"id":424676}]}]}
{"op":"mcm","clk":"11777544983","pt":1722718268431,"mc":[{"id":"1.231344826","rc":[{"batb":[[1,2.14,35.43],[2,1.74,17.32]],"ltp":2.24,"tv":1.58,"id":424676}]}]}
{"op":"mcm","clk":"11777545025","pt":1722718269315,"mc":[{"id":"1.231344826","rc":[{"batb":[[0,2.14,35.43],[1,1.74,17.32],[2,1.3,633.33]],"ltp":2.24,"tv":1.58,"id":424676}]}]}
{"op":"mcm","clk":"11777545095","pt":1722718270616,"mc":[{"id":"1.231344826","rc":[{"batb":[[0,2.16,10],[1,2.14,35.43],[2,1.74,17.32]],"ltp":2.24,"tv":1.58,"id":424676}]}]}
{"op":"mcm","clk":"11777545292","pt":1722718274036,"mc":[{"id":"1.231344826","rc":[{"batb":[[0,2.16,2]],"ltp":2.24,"tv":1.58,"id":424676}]}]}
{"op":"mcm","clk":"11777545469","pt":1722718276521,"mc":[{"id":"1.231344826","rc":[{"batb":[[0,2.16,10]],"ltp":2.24,"tv":1.58,"id":424676}]}]}
{"op":"mcm","clk":"11777545666","pt":1722718280031,"mc":[{"id":"1.231344826","rc":[{"batb":[[0,2.16,2]],"ltp":2.24,"tv":1.58,"id":424676}]}]}
{"op":"mcm","clk":"11777545819","pt":1722718282467,"mc":[{"id":"1.231344826","rc":[{"batb":[[0,2.14,35.43],[1,1.74,17.32],[2,1.3,633.33]],"ltp":2.24,"tv":1.58,"id":424676}]}]}
{"op":"mcm","clk":"11777545826","pt":1722718282575,"mc":[{"id":"1.231344826","rc":[{"batb":[[0,2.16,10],[1,2.14,35.43],[2,1.74,17.32]],"ltp":2.24,"tv":1.58,"id":424676}]}]}
{"op":"mcm","clk":"11777546038","pt":1722718285945,"mc":[{"id":"1.231344826","rc":[{"batb":[[0,2.16,2]],"ltp":2.24,"tv":1.58,"id":424676}]}]}
{"op":"mcm","clk":"11777546202","pt":1722718288433,"mc":[{"id":"1.231344826","rc":[{"batb":[[0,2.16,10]],"ltp":2.24,"tv":1.58,"id":424676}]}]}
{"op":"mcm","clk":"11777546421","pt":1722718291873,"mc":[{"id":"1.231344826","rc":[{"batb":[[0,2.16,2]],"ltp":2.24,"tv":1.58,"id":424676}]}]}
{"op":"mcm","clk":"11777546577","pt":1722718294366,"mc":[{"id":"1.231344826","rc":[{"batb":[[0,2.16,10]],"ltp":2.24,"tv":1.58,"id":424676}]}]}
{"op":"mcm","clk":"11777546788","pt":1722718297742,"mc":[{"id":"1.231344826","rc":[{"batb":[[0,2.16,2]],"ltp":2.24,"tv":1.58,"id":424676}]}]}
{"op":"mcm","clk":"11777546953","pt":1722718300541,"mc":[{"id":"1.231344826","rc":[{"batb":[[0,2.16,10]],"ltp":2.24,"tv":1.58,"id":424676}]}]}
{"op":"mcm","clk":"11777547138","pt":1722718304060,"mc":[{"id":"1.231344826","rc":[{"batb":[[0,2.16,2]],"ltp":2.24,"tv":1.58,"id":424676}]}]}
{"op":"mcm","clk":"11777547278","pt":1722718306387,"mc":[{"id":"1.231344826","rc":[{"batb":[[0,2.16,10]],"ltp":2.24,"tv":1.58,"id":424676}]}]}
{"op":"mcm","clk":"11777547465","pt":1722718309699,"mc":[{"id":"1.231344826","rc":[{"batb":[[0,2.16,2]],"ltp":2.24,"tv":1.58,"id":424676}]}]}
{"op":"mcm","clk":"11777547602","pt":1722718312085,"mc":[{"id":"1.231344826","rc":[{"batb":[[0,2.16,10]],"ltp":2.24,"tv":1.58,"id":424676}]}]}
{"op":"mcm","clk":"11777547800","pt":1722718315402,"mc":[{"id":"1.231344826","rc":[{"batb":[[0,2.16,2]],"ltp":2.24,"tv":1.58,"id":424676}]}]}
{"op":"mcm","clk":"11777547931","pt":1722718317778,"mc":[{"id":"1.231344826","rc":[{"batb":[[0,2.16,10]],"ltp":2.24,"tv":1.58,"id":424676}]}]}
{"op":"mcm","clk":"11777548114","pt":1722718321091,"mc":[{"id":"1.231344826","rc":[{"batb":[[0,2.16,2]],"ltp":2.24,"tv":1.58,"id":424676}]}]}
{"op":"mcm","clk":"11777548244","pt":1722718323370,"mc":[{"id":"1.231344826","rc":[{"batb":[[0,2.14,35.43],[1,1.74,17.32],[2,1.3,633.33]],"ltp":2.24,"tv":1.58,"id":424676}]}]}
{"op":"mcm","clk":"11777548262","pt":1722718323573,"mc":[{"id":"1.231344826","rc":[{"batb":[[0,2.16,10],[1,2.14,35.43],[2,1.74,17.32]],"ltp":2.24,"tv":1.58,"id":424676}]}]}
{"op":"mcm","clk":"11777548453","pt":1722718326988,"mc":[{"id":"1.231344826","rc":[{"batb":[[0,2.16,2]],"ltp":2.24,"tv":1.58,"id":424676}]}]}
{"op":"mcm","clk":"11777548581","pt":1722718329482,"mc":[{"id":"1.231344826","rc":[{"batb":[[0,2.16,10]],"ltp":2.24,"tv":1.58,"id":424676}]}]}
{"op":"mcm","clk":"11777548767","pt":1722718332782,"mc":[{"id":"1.231344826","rc":[{"batb":[[0,2.16,2]],"ltp":2.24,"tv":1.58,"id":424676}]}]}
{"op":"mcm","clk":"11777548913","pt":1722718335111,"mc":[{"id":"1.231344826","rc":[{"batb":[[0,2.16,10]],"ltp":2.24,"tv":1.58,"id":424676}]}]}
{"op":"mcm","clk":"11777549133","pt":1722718338520,"mc":[{"id":"1.231344826","rc":[{"batb":[[0,2.16,2]],"ltp":2.24,"tv":1.58,"id":424676}]}]}
{"op":"mcm","clk":"11777549279","pt":1722718341119,"mc":[{"id":"1.231344826","rc":[{"batb":[[0,2.16,10]],"ltp":2.24,"tv":1.58,"id":424676}]}]}
{"op":"mcm","clk":"11777549461","pt":1722718344533,"mc":[{"id":"1.231344826","rc":[{"batb":[[0,2.14,35.43],[1,1.74,17.32],[2,1.3,633.33]],"ltp":2.24,"tv":1.58,"id":424676}]}]}
{"op":"mcm","clk":"11777549467","pt":1722718344591,"mc":[{"id":"1.231344826","rc":[{"batb":[[0,2.16,2],[1,2.14,35.43],[2,1.74,17.32]],"ltp":2.24,"tv":1.58,"id":424676}]}]}
{"op":"mcm","clk":"11777549601","pt":1722718346909,"mc":[{"id":"1.231344826","rc":[{"batb":[[0,2.16,10]],"ltp":2.24,"tv":1.58,"id":424676}]}]}
{"op":"mcm","clk":"11777549839","pt":1722718350426,"mc":[{"id":"1.231344826","rc":[{"batb":[[0,2.16,2]],"ltp":2.24,"tv":1.58,"id":424676}]}]}
{"op":"mcm","clk":"11777550000","pt":1722718353009,"mc":[{"id":"1.231344826","rc":[{"batb":[[0,2.16,10]],"ltp":2.24,"tv":1.58,"id":424676}]}]}
{"op":"mcm","clk":"11777550250","pt":1722718356419,"mc":[{"id":"1.231344826","rc":[{"batb":[[0,2.16,2]],"ltp":2.24,"tv":1.58,"id":424676}]}]}
{"op":"mcm","clk":"11777550466","pt":1722718359545,"mc":[{"id":"1.231344826","rc":[{"batb":[[0,2.16,10]],"ltp":2.24,"tv":1.58,"id":424676}]}]}
{"op":"mcm","clk":"11777550706","pt":1722718362940,"mc":[{"id":"1.231344826","rc":[{"batb":[[0,2.16,2]],"ltp":2.24,"tv":1.58,"id":424676}]}]}
{"op":"mcm","clk":"11777550888","pt":1722718365425,"mc":[{"id":"1.231344826","rc":[{"batb":[[0,2.16,10]],"ltp":2.24,"tv":1.58,"id":424676}]}]}
{"op":"mcm","clk":"11777551126","pt":1722718368951,"mc":[{"id":"1.231344826","rc":[{"batb":[[0,2.16,2]],"ltp":2.24,"tv":1.58,"id":424676}]}]}
{"op":"mcm","clk":"11777551270","pt":1722718371539,"mc":[{"id":"1.231344826","rc":[{"batb":[[0,2.16,10]],"ltp":2.24,"tv":1.58,"id":424676}]}]}
{"op":"mcm","clk":"11777551510","pt":1722718375137,"mc":[{"id":"1.231344826","rc":[{"batb":[[0,2.16,2]],"ltp":2.24,"tv":1.58,"id":424676}]}]}
{"op":"mcm","clk":"11777551661","pt":1722718377457,"mc":[{"id":"1.231344826","rc":[{"batb":[[0,2.16,10]],"ltp":2.24,"tv":1.58,"id":424676}]}]}
{"op":"mcm","clk":"11777551863","pt":1722718380858,"mc":[{"id":"1.231344826","rc":[{"batb":[[0,2.16,2]],"ltp":2.24,"tv":1.58,"id":424676}]}]}
{"op":"mcm","clk":"11777552036","pt":1722718383249,"mc":[{"id":"1.231344826","rc":[{"batb":[[0,2.16,10]],"ltp":2.24,"tv":1.58,"id":424676}]}]}
{"op":"mcm","clk":"11777552223","pt":1722718386544,"mc":[{"id":"1.231344826","rc":[{"batb":[[0,2.14,35.43],[1,1.74,17.32],[2,1.3,633.33]],"ltp":2.24,"tv":1.58,"id":424676}]}]}
{"op":"mcm","clk":"11777552233","pt":1722718386751,"mc":[{"id":"1.231344826","rc":[{"batb":[[0,2.16,2],[1,2.14,35.43],[2,1.74,17.32]],"ltp":2.24,"tv":1.58,"id":424676}]}]}
{"op":"mcm","clk":"11777552391","pt":1722718389070,"mc":[{"id":"1.231344826","rc":[{"batb":[[0,2.16,10]],"ltp":2.24,"tv":1.58,"id":424676}]}]}
{"op":"mcm","clk":"11777552612","pt":1722718392438,"mc":[{"id":"1.231344826","rc":[{"batb":[[0,2.16,2]],"ltp":2.24,"tv":1.58,"id":424676}]}]}
{"op":"mcm","clk":"11777552772","pt":1722718394861,"mc":[{"id":"1.231344826","rc":[{"batb":[[0,2.16,10]],"ltp":2.24,"tv":1.58,"id":424676}]}]}
{"op":"mcm","clk":"11777552989","pt":1722718398273,"mc":[{"id":"1.231344826","rc":[{"batb":[[0,2.16,2]],"ltp":2.24,"tv":1.58,"id":424676}]}]}
{"op":"mcm","clk":"11777553152","pt":1722718400750,"mc":[{"id":"1.231344826","rc":[{"batb":[[0,2.16,10]],"ltp":2.24,"tv":1.58,"id":424676}]}]}
{"op":"mcm","clk":"11777553370","pt":1722718404254,"mc":[{"id":"1.231344826","rc":[{"batb":[[0,2.16,2]],"ltp":2.24,"tv":1.58,"id":424676}]}]}
{"op":"mcm","clk":"11777553517","pt":1722718406773,"mc":[{"id":"1.231344826","rc":[{"batb":[[0,2.16,10]],"ltp":2.24,"tv":1.58,"id":424676}]}]}
{"op":"mcm","clk":"11777553719","pt":1722718410378,"mc":[{"id":"1.231344826","rc":[{"batb":[[0,2.16,2]],"ltp":2.24,"tv":1.58,"id":424676}]}]}
{"op":"mcm","clk":"11777553881","pt":1722718412802,"mc":[{"id":"1.231344826","rc":[{"batb":[[0,2.16,10]],"ltp":2.24,"tv":1.58,"id":424676}]}]}
{"op":"mcm","clk":"11777554089","pt":1722718416098,"mc":[{"id":"1.231344826","rc":[{"batb":[[0,2.16,2]],"ltp":2.24,"tv":1.58,"id":424676}]}]}
{"op":"mcm","clk":"11777554229","pt":1722718418415,"mc":[{"id":"1.231344826","rc":[{"batb":[[0,2.16,10]],"ltp":2.24,"tv":1.58,"id":424676}]}]}
{"op":"mcm","clk":"11777554472","pt":1722718421812,"mc":[{"id":"1.231344826","rc":[{"batb":[[0,2.16,2]],"ltp":2.24,"tv":1.58,"id":424676}]}]}
{"op":"mcm","clk":"11777554651","pt":1722718424186,"mc":[{"id":"1.231344826","rc":[{"batb":[[0,2.16,10]],"ltp":2.24,"tv":1.58,"id":424676}]}]}
{"op":"mcm","clk":"11777554922","pt":1722718427487,"mc":[{"id":"1.231344826","rc":[{"batb":[[0,2.14,35.43],[1,1.74,17.32],[2,1.3,633.33]],"ltp":2.24,"tv":1.58,"id":424676}]}]}
{"op":"mcm","clk":"11777554932","pt":1722718427691,"mc":[{"id":"1.231344826","rc":[{"batb":[[0,2.16,2],[1,2.14,35.43],[2,1.74,17.32]],"ltp":2.24,"tv":1.58,"id":424676}]}]}
{"op":"mcm","clk":"11777555079","pt":1722718430007,"mc":[{"id":"1.231344826","rc":[{"batb":[[0,2.16,10]],"ltp":2.24,"tv":1.58,"id":424676}]}]}
{"op":"mcm","clk":"11777555275","pt":1722718433305,"mc":[{"id":"1.231344826","rc":[{"batb":[[0,2.16,2]],"ltp":2.24,"tv":1.58,"id":424676}]}]}
{"op":"mcm","clk":"11777555398","pt":1722718435828,"mc":[{"id":"1.231344826","rc":[{"batb":[[0,2.16,10]],"ltp":2.24,"tv":1.58,"id":424676}]}]}
{"op":"mcm","clk":"11777555595","pt":1722718439330,"mc":[{"id":"1.231344826","rc":[{"batb":[[0,2.16,2]],"ltp":2.24,"tv":1.58,"id":424676}]}]}
{"op":"mcm","clk":"11777555717","pt":1722718441504,"mc":[{"id":"1.231344826","rc":[{"batb":[[0,2.14,35.43],[1,1.74,17.32],[2,1.3,633.33]],"ltp":2.24,"tv":1.58,"id":424676}]}]}
{"op":"mcm","clk":"11777555722","pt":1722718441606,"mc":[{"id":"1.231344826","rc":[{"batb":[[0,2.16,10],[1,2.14,35.43],[2,1.74,17.32]],"ltp":2.24,"tv":1.58,"id":424676}]}]}
{"op":"mcm","clk":"11777555945","pt":1722718445011,"mc":[{"id":"1.231344826","rc":[{"batb":[[0,2.16,2]],"ltp":2.24,"tv":1.58,"id":424676}]}]}
{"op":"mcm","clk":"11777556079","pt":1722718447430,"mc":[{"id":"1.231344826","rc":[{"batb":[[0,2.16,10]],"ltp":2.24,"tv":1.58,"id":424676}]}]}
{"op":"mcm","clk":"11777556292","pt":1722718450833,"mc":[{"id":"1.231344826","rc":[{"batb":[[0,2.16,2]],"ltp":2.24,"tv":1.58,"id":424676}]}]}
{"op":"mcm","clk":"11777556451","pt":1722718453510,"mc":[{"id":"1.231344826","rc":[{"batb":[[0,2.16,10]],"ltp":2.24,"tv":1.58,"id":424676}]}]}
{"op":"mcm","clk":"11777556653","pt":1722718457007,"mc":[{"id":"1.231344826","rc":[{"batb":[[0,2.16,2]],"ltp":2.24,"tv":1.58,"id":424676}]}]}
{"op":"mcm","clk":"11777556829","pt":1722718459530,"mc":[{"id":"1.231344826","rc":[{"batb":[[0,2.16,10]],"ltp":2.24,"tv":1.58,"id":424676}]}]}
{"op":"mcm","clk":"11777557069","pt":1722718462931,"mc":[{"id":"1.231344826","rc":[{"batb":[[0,2.16,2]],"ltp":2.24,"tv":1.58,"id":424676}]}]}
{"op":"mcm","clk":"11777557212","pt":1722718465457,"mc":[{"id":"1.231344826","rc":[{"batb":[[0,2.14,35.43],[1,1.74,17.32],[2,1.3,633.33]],"ltp":2.24,"tv":1.58,"id":424676}]}]}
{"op":"mcm","clk":"11777557221","pt":1722718465553,"mc":[{"id":"1.231344826","rc":[{"batb":[[0,2.16,10],[1,2.14,35.43],[2,1.74,17.32]],"ltp":2.24,"tv":1.58,"id":424676}]}]}
{"op":"mcm","clk":"11777557398","pt":1722718469160,"mc":[{"id":"1.231344826","rc":[{"batb":[[0,2.16,2]],"ltp":2.24,"tv":1.58,"id":424676}]}]}
{"op":"mcm","clk":"11777557545","pt":1722718471431,"mc":[{"id":"1.231344826","rc":[{"batb":[[0,2.16,10]],"ltp":2.24,"tv":1.58,"id":424676}]}]}
{"op":"mcm","clk":"11777557890","pt":1722718474982,"mc":[{"id":"1.231344826","rc":[{"batb":[[0,2.16,2]],"ltp":2.24,"tv":1.58,"id":424676}]}]}
{"op":"mcm","clk":"11777558156","pt":1722718477352,"mc":[{"id":"1.231344826","rc":[{"batb":[[0,2.16,10]],"ltp":2.24,"tv":1.58,"id":424676}]}]}
{"op":"mcm","clk":"11777558390","pt":1722718480749,"mc":[{"id":"1.231344826","rc":[{"batb":[[0,2.16,2]],"ltp":2.24,"tv":1.58,"id":424676}]}]}
{"op":"mcm","clk":"11777558520","pt":1722718483175,"mc":[{"id":"1.231344826","rc":[{"batb":[[0,2.16,10]],"ltp":2.24,"tv":1.58,"id":424676}]}]}
{"op":"mcm","clk":"11777558762","pt":1722718486538,"mc":[{"id":"1.231344826","rc":[{"batb":[[0,2.16,2]],"ltp":2.24,"tv":1.58,"id":424676}]}]}
{"op":"mcm","clk":"11777558905","pt":1722718488956,"mc":[{"id":"1.231344826","rc":[{"batb":[[0,2.16,10]],"ltp":2.24,"tv":1.58,"id":424676}]}]}
{"op":"mcm","clk":"11777559160","pt":1722718492464,"mc":[{"id":"1.231344826","rc":[{"batb":[[0,2.16,2]],"ltp":2.24,"tv":1.58,"id":424676}]}]}
{"op":"mcm","clk":"11777559337","pt":1722718495148,"mc":[{"id":"1.231344826","rc":[{"batb":[[0,2.16,10]],"ltp":2.24,"tv":1.58,"id":424676}]}]}
{"op":"mcm","clk":"11777559537","pt":1722718498689,"mc":[{"id":"1.231344826","rc":[{"batb":[[0,2.16,2]],"ltp":2.24,"tv":1.58,"id":424676}]}]}
{"op":"mcm","clk":"11777559708","pt":1722718501265,"mc":[{"id":"1.231344826","rc":[{"batb":[[0,2.16,10]],"ltp":2.24,"tv":1.58,"id":424676}]}]}
{"op":"mcm","clk":"11777559956","pt":1722718504463,"mc":[{"id":"1.231344826","rc":[{"batb":[[0,2.14,35.43],[1,1.74,17.32],[2,1.3,633.33]],"ltp":2.24,"tv":1.58,"id":424676}]}]}
{"op":"mcm","clk":"11777559970","pt":1722718504671,"mc":[{"id":"1.231344826","rc":[{"batb":[[0,2.16,2],[1,2.14,35.43],[2,1.74,17.32]],"ltp":2.24,"tv":1.58,"id":424676}]}]}
{"op":"mcm","clk":"11777560144","pt":1722718506991,"mc":[{"id":"1.231344826","rc":[{"batb":[[0,2.16,10]],"ltp":2.24,"tv":1.58,"id":424676}]}]}
{"op":"mcm","clk":"11777560361","pt":1722718510496,"mc":[{"id":"1.231344826","rc":[{"batb":[[0,2.16,2]],"ltp":2.24,"tv":1.58,"id":424676}]}]}
{"op":"mcm","clk":"11777560509","pt":1722718512977,"mc":[{"id":"1.231344826","rc":[{"batb":[[0,2.16,10]],"ltp":2.24,"tv":1.58,"id":424676}]}]}
{"op":"mcm","clk":"11777560723","pt":1722718516475,"mc":[{"id":"1.231344826","rc":[{"batb":[[0,2.16,2]],"ltp":2.24,"tv":1.58,"id":424676}]}]}
{"op":"mcm","clk":"11777560875","pt":1722718518894,"mc":[{"id":"1.231344826","rc":[{"batb":[[0,2.16,10]],"ltp":2.24,"tv":1.58,"id":424676}]}]}
{"op":"mcm","clk":"11777561055","pt":1722718522287,"mc":[{"id":"1.231344826","rc":[{"batb":[[0,2.16,2]],"ltp":2.24,"tv":1.58,"id":424676}]}]}
{"op":"mcm","clk":"11777561210","pt":1722718524512,"mc":[{"id":"1.231344826","rc":[{"batb":[[0,2.14,35.43],[1,1.74,17.32],[2,1.3,633.33]],"ltp":2.24,"tv":1.58,"id":424676}]}]}
{"op":"mcm","clk":"11777561222","pt":1722718524614,"mc":[{"id":"1.231344826","rc":[{"batb":[[0,2.16,10],[1,2.14,35.43],[2,1.74,17.32]],"ltp":2.24,"tv":1.58,"id":424676}]}]}
{"op":"mcm","clk":"11777561423","pt":1722718527911,"mc":[{"id":"1.231344826","rc":[{"batb":[[0,2.16,2]],"ltp":2.24,"tv":1.58,"id":424676}]}]}
{"op":"mcm","clk":"11777561569","pt":1722718530220,"mc":[{"id":"1.231344826","rc":[{"batb":[[0,2.16,10]],"ltp":2.24,"tv":1.58,"id":424676}]}]}
{"op":"mcm","clk":"11777561744","pt":1722718533417,"mc":[{"id":"1.231344826","rc":[{"batb":[[0,2.14,35.43],[1,1.74,17.32],[2,1.3,633.33]],"ltp":2.24,"tv":1.58,"id":424676}]}]}
{"op":"mcm","clk":"11777561760","pt":1722718533622,"mc":[{"id":"1.231344826","rc":[{"batb":[[0,2.16,2],[1,2.14,35.43],[2,1.74,17.32]],"ltp":2.24,"tv":1.58,"id":424676}]}]}
{"op":"mcm","clk":"11777561909","pt":1722718536003,"mc":[{"id":"1.231344826","rc":[{"batb":[[0,2.16,10]],"ltp":2.24,"tv":1.58,"id":424676}]}]}
{"op":"mcm","clk":"11777562110","pt":1722718539313,"mc":[{"id":"1.231344826","rc":[{"batb":[[0,2.16,2]],"ltp":2.24,"tv":1.58,"id":424676}]}]}
{"op":"mcm","clk":"11777562243","pt":1722718541721,"mc":[{"id":"1.231344826","rc":[{"batb":[[0,2.16,10]],"ltp":2.24,"tv":1.58,"id":424676}]}]}
{"op":"mcm","clk":"11777562492","pt":1722718545119,"mc":[{"id":"1.231344826","rc":[{"batb":[[0,2.16,2]],"ltp":2.24,"tv":1.58,"id":424676}]}]}
{"op":"mcm","clk":"11777562635","pt":1722718547504,"mc":[{"id":"1.231344826","rc":[{"batb":[[0,2.16,10]],"ltp":2.24,"tv":1.58,"id":424676}]}]}
{"op":"mcm","clk":"11777562878","pt":1722718550913,"mc":[{"id":"1.231344826","rc":[{"batb":[[0,2.16,2]],"ltp":2.24,"tv":1.58,"id":424676}]}]}
{"op":"mcm","clk":"11777563019","pt":1722718553328,"mc":[{"id":"1.231344826","rc":[{"batb":[[0,2.16,10]],"ltp":2.24,"tv":1.58,"id":424676}]}]}
{"op":"mcm","clk":"11777563232","pt":1722718556824,"mc":[{"id":"1.231344826","rc":[{"batb":[[0,2.16,2]],"ltp":2.24,"tv":1.58,"id":424676}]}]}
{"op":"mcm","clk":"11777563365","pt":1722718559243,"mc":[{"id":"1.231344826","rc":[{"batb":[[0,2.16,10]],"ltp":2.24,"tv":1.58,"id":424676}]}]}
{"op":"mcm","clk":"11777563566","pt":1722718562541,"mc":[{"id":"1.231344826","rc":[{"batb":[[0,2.16,2]],"ltp":2.24,"tv":1.58,"id":424676}]}]}
{"op":"mcm","clk":"11777563708","pt":1722718564811,"mc":[{"id":"1.231344826","rc":[{"batb":[[0,2.16,10]],"ltp":2.24,"tv":1.58,"id":424676}]}]}
{"op":"mcm","clk":"11777563903","pt":1722718568252,"mc":[{"id":"1.231344826","rc":[{"batb":[[0,2.16,2]],"ltp":2.24,"tv":1.58,"id":424676}]}]}
{"op":"mcm","clk":"11777564035","pt":1722718570417,"mc":[{"id":"1.231344826","rc":[{"batb":[[0,2.14,35.43],[1,1.74,17.32],[2,1.3,633.33]],"ltp":2.24,"tv":1.58,"id":424676}]}]}
{"op":"mcm","clk":"11777564045","pt":1722718570624,"mc":[{"id":"1.231344826","rc":[{"batb":[[0,2.16,10],[1,2.14,35.43],[2,1.74,17.32]],"ltp":2.24,"tv":1.58,"id":424676}]}]}
{"op":"mcm","clk":"11777564240","pt":1722718574324,"mc":[{"id":"1.231344826","rc":[{"batb":[[0,2.16,2]],"ltp":2.24,"tv":1.58,"id":424676}]}]}
{"op":"mcm","clk":"11777564360","pt":1722718576540,"mc":[{"id":"1.231344826","rc":[{"batb":[[0,2.14,35.43],[1,1.74,17.32],[2,1.3,633.33]],"ltp":2.24,"tv":1.58,"id":424676}]}]}
{"op":"mcm","clk":"11777564369","pt":1722718576645,"mc":[{"id":"1.231344826","rc":[{"batb":[[0,2.16,10],[1,2.14,35.43],[2,1.74,17.32]],"ltp":2.24,"tv":1.58,"id":424676}]}]}
{"op":"mcm","clk":"11777564587","pt":1722718580050,"mc":[{"id":"1.231344826","rc":[{"batb":[[0,2.16,2]],"ltp":2.24,"tv":1.58,"id":424676}]}]}
{"op":"mcm","clk":"11777564765","pt":1722718582366,"mc":[{"id":"1.231344826","rc":[{"batb":[[0,2.16,10]],"ltp":2.24,"tv":1.58,"id":424676}]}]}
{"op":"mcm","clk":"11777564966","pt":1722718585758,"mc":[{"id":"1.231344826","rc":[{"batb":[[0,2.16,2]],"ltp":2.24,"tv":1.58,"id":424676}]}]}
{"op":"mcm","clk":"11777565144","pt":1722718588171,"mc":[{"id":"1.231344826","rc":[{"batb":[[0,2.16,10]],"ltp":2.24,"tv":1.58,"id":424676}]}]}
{"op":"mcm","clk":"11777565316","pt":1722718591363,"mc":[{"id":"1.231344826","rc":[{"batb":[[0,2.18,2]],"ltp":2.24,"tv":1.58,"id":424676}]}]}
{"op":"mcm","clk":"11777565464","pt":1722718593778,"mc":[{"id":"1.231344826","rc":[{"batb":[[0,2.16,10]],"ltp":2.24,"tv":1.58,"id":424676}]}]}
{"op":"mcm","clk":"11777565647","pt":1722718597069,"mc":[{"id":"1.231344826","rc":[{"batb":[[0,2.16,2]],"ltp":2.24,"tv":1.58,"id":424676}]}]}
{"op":"mcm","clk":"11777565787","pt":1722718599440,"mc":[{"id":"1.231344826","rc":[{"batb":[[0,2.14,35.43],[1,1.74,17.32],[2,1.3,633.33]],"ltp":2.24,"tv":1.58,"id":424676}]}]}
{"op":"mcm","clk":"11777565797","pt":1722718599644,"mc":[{"id":"1.231344826","rc":[{"batb":[[0,2.16,10],[1,2.14,35.43],[2,1.74,17.32]],"ltp":2.24,"tv":1.58,"id":424676}]}]}
{"op":"mcm","clk":"11777565976","pt":1722718603250,"mc":[{"id":"1.231344826","rc":[{"batb":[[0,2.16,2]],"ltp":2.24,"tv":1.58,"id":424676}]}]}
{"op":"mcm","clk":"11777566101","pt":1722718605475,"mc":[{"id":"1.231344826","rc":[{"batb":[[0,2.14,35.43],[1,1.74,17.32],[2,1.3,633.33]],"ltp":2.24,"tv":1.58,"id":424676}]}]}
{"op":"mcm","clk":"11777566108","pt":1722718605577,"mc":[{"id":"1.231344826","rc":[{"batb":[[0,2.16,10],[1,2.14,35.43],[2,1.74,17.32]],"ltp":2.24,"tv":1.58,"id":424676}]}]}
{"op":"mcm","clk":"11777566327","pt":1722718608876,"mc":[{"id":"1.231344826","rc":[{"batb":[[0,2.16,2]],"ltp":2.24,"tv":1.58,"id":424676}]}]}
{"op":"mcm","clk":"11777566464","pt":1722718611193,"mc":[{"id":"1.231344826","rc":[{"batb":[[0,2.16,10]],"ltp":2.24,"tv":1.58,"id":424676}]}]}
{"op":"mcm","clk":"11777566632","pt":1722718614495,"mc":[{"id":"1.231344826","rc":[{"batb":[[0,2.16,2]],"ltp":2.24,"tv":1.58,"id":424676}]}]}
{"op":"mcm","clk":"11777566776","pt":1722718617084,"mc":[{"id":"1.231344826","rc":[{"batb":[[0,2.16,10]],"ltp":2.24,"tv":1.58,"id":424676}]}]}
{"op":"mcm","clk":"11777566982","pt":1722718620499,"mc":[{"id":"1.231344826","rc":[{"batb":[[0,2.16,2]],"ltp":2.24,"tv":1.58,"id":424676}]}]}
{"op":"mcm","clk":"11777567152","pt":1722718622873,"mc":[{"id":"1.231344826","rc":[{"batb":[[0,2.16,10]],"ltp":2.24,"tv":1.58,"id":424676}]}]}
{"op":"mcm","clk":"11777567389","pt":1722718626478,"mc":[{"id":"1.231344826","rc":[{"batb":[[0,2.16,2]],"ltp":2.24,"tv":1.58,"id":424676}]}]}
{"op":"mcm","clk":"11777567540","pt":1722718628803,"mc":[{"id":"1.231344826","rc":[{"batb":[[0,2.16,10]],"ltp":2.24,"tv":1.58,"id":424676}]}]}
{"op":"mcm","clk":"11777567753","pt":1722718632303,"mc":[{"id":"1.231344826","rc":[{"batb":[[0,2.16,2]],"ltp":2.24,"tv":1.58,"id":424676}]}]}
{"op":"mcm","clk":"11777567885","pt":1722718634817,"mc":[{"id":"1.231344826","rc":[{"batb":[[0,2.16,10]],"ltp":2.24,"tv":1.58,"id":424676}]}]}
{"op":"mcm","clk":"11777568059","pt":1722718638117,"mc":[{"id":"1.231344826","rc":[{"batb":[[0,2.16,2]],"ltp":2.24,"tv":1.58,"id":424676}]}]}
{"op":"mcm","clk":"11777568172","pt":1722718640488,"mc":[{"id":"1.231344826","rc":[{"batb":[[0,2.14,35.43],[1,1.74,17.32],[2,1.3,633.33]],"ltp":2.24,"tv":1.58,"id":424676}]}]}
{"op":"mcm","clk":"11777568178","pt":1722718640594,"mc":[{"id":"1.231344826","rc":[{"batb":[[0,2.16,10],[1,2.14,35.43],[2,1.74,17.32]],"ltp":2.24,"tv":1.58,"id":424676}]}]}
{"op":"mcm","clk":"11777568361","pt":1722718643990,"mc":[{"id":"1.231344826","rc":[{"batb":[[0,2.16,2]],"ltp":2.24,"tv":1.58,"id":424676}]}]}
{"op":"mcm","clk":"11777568504","pt":1722718646315,"mc":[{"id":"1.231344826","rc":[{"batb":[[0,2.16,10]],"ltp":2.24,"tv":1.58,"id":424676}]}]}
{"op":"mcm","clk":"11777568646","pt":1722718648792,"mc":[{"id":"1.231344826","rc":[{"batb":[[0,2.18,2],[1,2.16,10],[2,2.14,35.43]],"ltp":2.24,"tv":1.58,"id":424676}]}]}
{"op":"mcm","clk":"11777568697","pt":1722718649624,"mc":[{"id":"1.231344826","rc":[{"batb":[[1,2.14,35.43],[2,1.74,17.32]],"ltp":2.24,"tv":1.58,"id":424676}]}]}
{"op":"mcm","clk":"11777568814","pt":1722718651209,"mc":[{"id":"1.231344826","rc":[{"batb":[[0,2.14,35.43],[1,1.74,17.32],[2,1.3,633.33]],"ltp":2.24,"tv":1.58,"id":424676}]}]}
{"op":"mcm","clk":"11777569466","pt":1722718659424,"mc":[{"id":"1.231344826","rc":[{"batb":[[0,2.16,12],[1,2.14,35.43],[2,1.74,17.32]],"ltp":2.24,"tv":1.58,"id":424676}]}]}
{"op":"mcm","clk":"11777569588","pt":1722718661734,"mc":[{"id":"1.231344826","rc":[{"batb":[[0,2.16,10]],"ltp":2.24,"tv":1.58,"id":424676}]}]}
{"op":"mcm","clk":"11777569652","pt":1722718662712,"mc":[{"id":"1.231344826","rc":[{"batb":[[0,2.14,35.43],[1,1.74,17.32],[2,1.3,633.33]],"ltp":2.24,"tv":1.58,"id":424676}]}]}
{"op":"mcm","clk":"11777570962","pt":1722718681757,"mc":[{"id":"1.231344826","rc":[{"batb":[[0,2.16,12],[1,2.14,35.43],[2,1.74,17.32]],"ltp":2.24,"tv":1.58,"id":424676}]}]}
{"op":"mcm","clk":"11777571143","pt":1722718684142,"mc":[{"id":"1.231344826","rc":[{"batb":[[0,2.16,10]],"ltp":2.24,"tv":1.58,"id":424676}]}]}
{"op":"mcm","clk":"11777571222","pt":1722718685128,"mc":[{"id":"1.231344826","rc":[{"batb":[[0,2.14,35.43],[1,1.74,17.32],[2,1.3,633.33]],"ltp":2.24,"tv":1.58,"id":424676}]}]}
{"op":"mcm","clk":"11777571577","pt":1722718690241,"mc":[{"id":"1.231344826","rc":[{"batb":[[0,2.16,12],[1,2.14,35.43],[2,1.74,17.32]],"ltp":2.24,"tv":1.58,"id":424676}]}]}
{"op":"mcm","clk":"11777571769","pt":1722718692825,"mc":[{"id":"1.231344826","rc":[{"batb":[[0,2.16,10]],"ltp":2.24,"tv":1.58,"id":424676}]}]}
{"op":"mcm","clk":"11777571836","pt":1722718693755,"mc":[{"id":"1.231344826","rc":[{"batb":[[0,2.14,35.43],[1,1.74,17.32],[2,1.3,633.33]],"ltp":2.24,"tv":1.58,"id":424676}]}]}
{"op":"mcm","clk":"11777572060","pt":1722718697324,"mc":[{"id":"1.231344826","rc":[{"batb":[[0,2.16,12],[1,2.14,35.43],[2,1.74,17.32]],"ltp":2.24,"tv":1.58,"id":424676}]}]}
{"op":"mcm","clk":"11777572217","pt":1722718699855,"mc":[{"id":"1.231344826","rc":[{"batb":[[0,2.16,10]],"ltp":2.24,"tv":1.58,"id":424676}]}]}
{"op":"mcm","clk":"11777572293","pt":1722718700848,"mc":[{"id":"1.231344826","rc":[{"batb":[[0,2.14,35.43],[1,1.74,17.32],[2,1.3,633.33]],"ltp":2.24,"tv":1.58,"id":424676}]}]}
{"op":"mcm","clk":"11777583254","pt":1722718861475,"mc":[{"id":"1.231344826","rc":[{"batb":[[0,2.16,12],[1,2.14,35.43],[2,1.74,17.32]],"ltp":2.24,"tv":1.58,"id":424676}]}]}
{"op":"mcm","clk":"11777583434","pt":1722718863915,"mc":[{"id":"1.231344826","rc":[{"batb":[[0,2.16,10]],"ltp":2.24,"tv":1.58,"id":424676}]}]}
{"op":"mcm","clk":"11777583501","pt":1722718864894,"mc":[{"id":"1.231344826","rc":[{"batb":[[0,2.14,35.43],[1,1.74,17.32],[2,1.3,633.33]],"ltp":2.24,"tv":1.58,"id":424676}]}]}
{"op":"mcm","clk":"11777583730","pt":1722718867787,"mc":[{"id":"1.231344826","rc":[{"batb":[[0,2.16,12],[1,2.14,35.43],[2,1.74,17.32]],"ltp":2.24,"tv":1.58,"id":424676}]}]}
{"op":"mcm","clk":"11777583867","pt":1722718870006,"mc":[{"id":"1.231344826","rc":[{"batb":[[0,2.16,10]],"ltp":2.24,"tv":1.58,"id":424676}]}]}
{"op":"mcm","clk":"11777583951","pt":1722718871196,"mc":[{"id":"1.231344826","rc":[{"batb":[[0,2.14,35.43],[1,1.74,17.32],[2,1.3,633.33]],"ltp":2.24,"tv":1.58,"id":424676}]}]}
{"op":"mcm","clk":"11777588377","pt":1722718937282,"mc":[{"id":"1.231344826","rc":[{"batb":[[0,2.16,12],[1,2.14,35.43],[2,1.74,17.32]],"ltp":2.24,"tv":1.58,"id":424676}]}]}
{"op":"mcm","clk":"11777588558","pt":1722718939664,"mc":[{"id":"1.231344826","rc":[{"batb":[[0,2.16,10]],"ltp":2.24,"tv":1.58,"id":424676}]}]}
{"op":"mcm","clk":"11777588628","pt":1722718940593,"mc":[{"id":"1.231344826","rc":[{"batb":[[0,2.14,35.43],[1,1.74,17.32],[2,1.3,633.33]],"ltp":2.24,"tv":1.58,"id":424676}]}]}
{"op":"mcm","clk":"11777589180","pt":1722718948557,"mc":[{"id":"1.231344826","rc":[{"batb":[[0,2.16,12],[1,2.14,35.43],[2,1.74,17.32]],"ltp":2.24,"tv":1.58,"id":424676}]}]}
{"op":"mcm","clk":"11777589347","pt":1722718950879,"mc":[{"id":"1.231344826","rc":[{"batb":[[0,2.16,10]],"ltp":2.24,"tv":1.58,"id":424676}]}]}
{"op":"mcm","clk":"11777589416","pt":1722718951865,"mc":[{"id":"1.231344826","rc":[{"batb":[[0,2.14,35.43],[1,1.74,17.32],[2,1.3,633.33]],"ltp":2.24,"tv":1.58,"id":424676}]}]}
{"op":"mcm","clk":"11777614305","pt":1722719333981,"mc":[{"id":"1.231344826","rc":[{"batb":[[0,2.16,12],[1,2.14,35.43],[2,1.74,17.32]],"ltp":2.24,"tv":1.58,"id":424676}]}]}
{"op":"mcm","clk":"11777614483","pt":1722719336264,"mc":[{"id":"1.231344826","rc":[{"batb":[[0,2.16,10]],"ltp":2.24,"tv":1.58,"id":424676}]}]}
{"op":"mcm","clk":"11777614554","pt":1722719337256,"mc":[{"id":"1.231344826","rc":[{"batb":[[0,2.14,35.43],[1,1.74,17.32],[2,1.3,633.33]],"ltp":2.24,"tv":1.58,"id":424676}]}]}
{"op":"mcm","clk":"11777618544","pt":1722719399310,"mc":[{"id":"1.231344826","rc":[{"batb":[[0,2.16,12],[1,2.14,35.43],[2,1.74,17.32]],"ltp":2.24,"tv":1.58,"id":424676}]}]}
{"op":"mcm","clk":"11777618710","pt":1722719401750,"mc":[{"id":"1.231344826","rc":[{"batb":[[0,2.16,10]],"ltp":2.24,"tv":1.58,"id":424676}]}]}
{"op":"mcm","clk":"11777618769","pt":1722719402731,"mc":[{"id":"1.231344826","rc":[{"batb":[[0,2.14,35.43],[1,1.74,17.32],[2,1.3,633.33]],"ltp":2.24,"tv":1.58,"id":424676}]}]}
{"op":"mcm","clk":"11777620472","pt":1722719428869,"mc":[{"id":"1.231344826","rc":[{"batb":[[0,2.16,12],[1,2.14,35.43],[2,1.74,17.32]],"ltp":2.24,"tv":1.58,"id":424676}]}]}
{"op":"mcm","clk":"11777620646","pt":1722719431333,"mc":[{"id":"1.231344826","rc":[{"batb":[[0,2.16,10]],"ltp":2.24,"tv":1.58,"id":424676}]}]}
{"op":"mcm","clk":"11777620716","pt":1722719432161,"mc":[{"id":"1.231344826","rc":[{"batb":[[0,2.14,35.43],[1,1.74,17.32],[2,1.3,633.33]],"ltp":2.24,"tv":1.58,"id":424676}]}]}
{"op":"mcm","clk":"11777647085","pt":1722719680734,"mc":[{"id":"1.231344826","rc":[{"batb":[[0,2.16,12],[1,2.14,35.43],[2,1.74,17.32]],"ltp":2.24,"tv":1.58,"id":424676}]}]}
{"op":"mcm","clk":"11777647268","pt":1722719683470,"mc":[{"id":"1.231344826","rc":[{"batb":[[0,2.16,10]],"ltp":2.24,"tv":1.58,"id":424676}]}]}
{"op":"mcm","clk":"11777647331","pt":1722719684349,"mc":[{"id":"1.231344826","rc":[{"batb":[[0,2.14,35.43],[1,1.74,17.32],[2,1.3,633.33]],"ltp":2.24,"tv":1.58,"id":424676}]}]}
{"op":"mcm","clk":"11777648267","pt":1722719697392,"mc":[{"id":"1.231344826","rc":[{"batb":[[0,2.16,12],[1,2.14,35.43],[2,1.74,17.32]],"ltp":2.24,"tv":1.58,"id":424676}]}]}
{"op":"mcm","clk":"11777648456","pt":1722719699877,"mc":[{"id":"1.231344826","rc":[{"batb":[[0,2.16,10]],"ltp":2.24,"tv":1.58,"id":424676}]}]}
{"op":"mcm","clk":"11777648549","pt":1722719700873,"mc":[{"id":"1.231344826","rc":[{"batb":[[0,2.14,35.43],[1,1.74,17.32],[2,1.3,633.33]],"ltp":2.24,"tv":1.58,"id":424676}]}]}
{"op":"mcm","clk":"11777649322","pt":1722719708596,"mc":[{"id":"1.231344826","rc":[{"batb":[[0,2.16,12],[1,2.14,35.43],[2,1.74,17.32]],"ltp":2.24,"tv":1.58,"id":424676}]}]}
{"op":"mcm","clk":"11777649501","pt":1722719710984,"mc":[{"id":"1.231344826","rc":[{"batb":[[0,2.16,10]],"ltp":2.24,"tv":1.58,"id":424676}]}]}
{"op":"mcm","clk":"11777649573","pt":1722719712007,"mc":[{"id":"1.231344826","rc":[{"batb":[[0,2.14,35.43],[1,1.74,17.32],[2,1.3,633.33]],"ltp":2.24,"tv":1.58,"id":424676}]}]}
{"op":"mcm","clk":"11777651581","pt":1722719736091,"mc":[{"id":"1.231344826","rc":[{"batb":[[0,2.16,12],[1,2.14,35.43],[2,1.74,17.32]],"ltp":2.24,"tv":1.58,"id":424676}]}]}
{"op":"mcm","clk":"11777651784","pt":1722719738415,"mc":[{"id":"1.231344826","rc":[{"batb":[[0,2.16,10]],"ltp":2.24,"tv":1.58,"id":424676}]}]}
{"op":"mcm","clk":"11777651868","pt":1722719739402,"mc":[{"id":"1.231344826","rc":[{"batb":[[0,2.14,35.43],[1,1.74,17.32],[2,1.3,633.33]],"ltp":2.24,"tv":1.58,"id":424676}]}]}
{"op":"mcm","clk":"11777652526","pt":1722719748527,"mc":[{"id":"1.231344826","rc":[{"batb":[[0,2.16,12],[1,2.14,35.43],[2,1.74,17.32]],"ltp":2.24,"tv":1.58,"id":424676}]}]}
{"op":"mcm","clk":"11777652672","pt":1722719750739,"mc":[{"id":"1.231344826","rc":[{"batb":[[0,2.16,10]],"ltp":2.24,"tv":1.58,"id":424676}]}]}
{"op":"mcm","clk":"11777652768","pt":1722719752042,"mc":[{"id":"1.231344826","rc":[{"batb":[[0,2.14,35.43],[1,1.74,17.32],[2,1.3,633.33]],"ltp":2.24,"tv":1.58,"id":424676}]}]}
{"op":"mcm","clk":"11777656263","pt":1722719800170,"mc":[{"id":"1.231344826","rc":[{"batb":[[0,2.16,12],[1,2.14,35.43],[2,1.74,17.32]],"ltp":2.24,"tv":1.58,"id":424676}]}]}
{"op":"mcm","clk":"11777656439","pt":1722719802500,"mc":[{"id":"1.231344826","rc":[{"batb":[[0,2.16,10]],"ltp":2.24,"tv":1.58,"id":424676}]}]}
{"op":"mcm","clk":"11777656502","pt":1722719803486,"mc":[{"id":"1.231344826","rc":[{"batb":[[0,2.14,35.43],[1,1.74,17.32],[2,1.3,633.33]],"ltp":2.24,"tv":1.58,"id":424676}]}]}
{"op":"mcm","clk":"11777660406","pt":1722719859147,"mc":[{"id":"1.231344826","rc":[{"batb":[[0,2.16,12],[1,2.14,35.43],[2,1.74,17.32]],"ltp":2.24,"tv":1.58,"id":424676}]}]}
{"op":"mcm","clk":"11777660586","pt":1722719861531,"mc":[{"id":"1.231344826","rc":[{"batb":[[0,2.16,10]],"ltp":2.24,"tv":1.58,"id":424676}]}]}
{"op":"mcm","clk":"11777660653","pt":1722719862521,"mc":[{"id":"1.231344826","rc":[{"batb":[[0,2.14,35.43],[1,1.74,17.32],[2,1.3,633.33]],"ltp":2.24,"tv":1.58,"id":424676}]}]}
{"op":"mcm","clk":"11777662740","pt":1722719889690,"mc":[{"id":"1.231344826","rc":[{"batb":[[0,2.16,12],[1,2.14,35.43],[2,1.74,17.32]],"ltp":2.24,"tv":1.58,"id":424676}]}]}
{"op":"mcm","clk":"11777662944","pt":1722719892201,"mc":[{"id":"1.231344826","rc":[{"batb":[[0,2.16,10]],"ltp":2.24,"tv":1.58,"id":424676}]}]}
{"op":"mcm","clk":"11777663006","pt":1722719892974,"mc":[{"id":"1.231344826","rc":[{"batb":[[0,2.14,35.43],[1,1.74,17.32],[2,1.3,633.33]],"ltp":2.24,"tv":1.58,"id":424676}]}]}
{"op":"mcm","clk":"11777663841","pt":1722719905192,"mc":[{"id":"1.231344826","rc":[{"batb":[[0,2.16,12],[1,2.14,35.43],[2,1.74,17.32]],"ltp":2.24,"tv":1.58,"id":424676}]}]}
{"op":"mcm","clk":"11777664002","pt":1722719907694,"mc":[{"id":"1.231344826","rc":[{"batb":[[0,2.16,10]],"ltp":2.24,"tv":1.58,"id":424676}]}]}
{"op":"mcm","clk":"11777664080","pt":1722719908590,"mc":[{"id":"1.231344826","rc":[{"batb":[[0,2.14,35.43],[1,1.74,17.32],[2,1.3,633.33]],"ltp":2.24,"tv":1.58,"id":424676}]}]}
{"op":"mcm","clk":"11777666608","pt":1722719944934,"mc":[{"id":"1.231344826","rc":[{"batb":[[0,2.16,12],[1,2.14,35.43],[2,1.74,17.32]],"ltp":2.24,"tv":1.58,"id":424676}]}]}
{"op":"mcm","clk":"11777666776","pt":1722719947529,"mc":[{"id":"1.231344826","rc":[{"batb":[[0,2.16,10]],"ltp":2.24,"tv":1.58,"id":424676}]}]}
{"op":"mcm","clk":"11777666838","pt":1722719948456,"mc":[{"id":"1.231344826","rc":[{"batb":[[0,2.14,35.43],[1,1.74,17.32],[2,1.3,633.33]],"ltp":2.24,"tv":1.58,"id":424676}]}]}
{"op":"mcm","clk":"11777667151","pt":1722719953340,"mc":[{"id":"1.231344826","rc":[{"batb":[[0,2.16,12],[1,2.14,35.43],[2,1.74,17.32]],"ltp":2.24,"tv":1.58,"id":424676}]}]}
{"op":"mcm","clk":"11777667331","pt":1722719955876,"mc":[{"id":"1.231344826","rc":[{"batb":[[0,2.16,10]],"ltp":2.24,"tv":1.58,"id":424676}]}]}
{"op":"mcm","clk":"11777667392","pt":1722719956751,"mc":[{"id":"1.231344826","rc":[{"batb":[[0,2.14,35.43],[1,1.74,17.32],[2,1.3,633.33]],"ltp":2.24,"tv":1.58,"id":424676}]}]}
{"op":"mcm","clk":"11777667514","pt":1722719958161,"mc":[{"id":"1.231344826","rc":[{"batb":[[0,2.16,2],[1,2.14,35.43],[2,1.74,17.32]],"ltp":2.24,"tv":1.58,"id":424676}]}]}
{"op":"mcm","clk":"11777667690","pt":1722719960441,"mc":[{"id":"1.231344826","rc":[{"batb":[[0,2.14,35.43],[1,1.74,17.32],[2,1.3,633.33]],"ltp":2.24,"tv":1.58,"id":424676}]}]}
{"op":"mcm","clk":"11777667697","pt":1722719960549,"mc":[{"id":"1.231344826","rc":[{"batb":[[0,2.16,10],[1,2.14,35.43],[2,1.74,17.32]],"ltp":2.24,"tv":1.58,"id":424676}]}]}
{"op":"mcm","clk":"11777667869","pt":1722719962820,"mc":[{"id":"1.231344826","rc":[{"batb":[[0,2.18,2],[1,2.16,10],[2,2.14,35.43]],"ltp":2.24,"tv":1.58,"id":424676}]}]}
{"op":"mcm","clk":"11777667947","pt":1722719964155,"mc":[{"id":"1.231344826","rc":[{"batb":[[1,2.14,35.43],[2,1.74,17.32]],"ltp":2.24,"tv":1.58,"id":424676}]}]}
{"op":"mcm","clk":"11777668036","pt":1722719965170,"mc":[{"id":"1.231344826","rc":[{"batb":[[0,2.14,35.43],[1,1.74,17.32],[2,1.3,633.33]],"ltp":2.24,"tv":1.58,"id":424676}]}]}
{"op":"mcm","clk":"11777668827","pt":1722719976748,"mc":[{"id":"1.231344826","rc":[{"batb":[[0,2.16,12],[1,2.14,35.43],[2,1.74,17.32]],"ltp":2.24,"tv":1.58,"id":424676}]}]}
{"op":"mcm","clk":"11777668977","pt":1722719978967,"mc":[{"id":"1.231344826","rc":[{"batb":[[0,2.16,10]],"ltp":2.24,"tv":1.58,"id":424676}]}]}
{"op":"mcm","clk":"11777669042","pt":1722719980065,"mc":[{"id":"1.231344826","rc":[{"batb":[[0,2.14,35.43],[1,1.74,17.32],[2,1.3,633.33]],"ltp":2.24,"tv":1.58,"id":424676}]}]}
{"op":"mcm","clk":"11777669292","pt":1722719984391,"mc":[{"id":"1.231344826","rc":[{"batb":[[0,2.16,12],[1,2.14,35.43],[2,1.74,17.32]],"ltp":2.24,"tv":1.58,"id":424676}]}]}
{"op":"mcm","clk":"11777669467","pt":1722719986893,"mc":[{"id":"1.231344826","rc":[{"batb":[[0,2.16,10]],"ltp":2.24,"tv":1.58,"id":424676}]}]}
{"op":"mcm","clk":"11777669532","pt":1722719987781,"mc":[{"id":"1.231344826","rc":[{"batb":[[0,2.14,35.43],[1,1.74,17.32],[2,1.3,633.33]],"ltp":2.24,"tv":1.58,"id":424676}]}]}
{"op":"mcm","clk":"11777670255","pt":1722719999106,"mc":[{"id":"1.231344826","rc":[{"batb":[[0,2.16,12],[1,2.14,35.43],[2,1.74,17.32]],"ltp":2.24,"tv":1.58,"id":424676}]}]}
{"op":"mcm","clk":"11777670406","pt":1722720001605,"mc":[{"id":"1.231344826","rc":[{"batb":[[0,2.16,10]],"ltp":2.24,"tv":1.58,"id":424676}]}]}
{"op":"mcm","clk":"11777670485","pt":1722720002597,"mc":[{"id":"1.231344826","rc":[{"batb":[[0,2.14,35.43],[1,1.74,17.32],[2,1.3,633.33]],"ltp":2.24,"tv":1.58,"id":424676}]}]}
{"op":"mcm","clk":"11777671078","pt":1722720010385,"mc":[{"id":"1.231344826","rc":[{"batb":[[0,2.16,12],[1,2.14,35.43],[2,1.74,17.32]],"ltp":2.24,"tv":1.58,"id":424676}]}]}
{"op":"mcm","clk":"11777671230","pt":1722720012899,"mc":[{"id":"1.231344826","rc":[{"batb":[[0,2.16,10]],"ltp":2.24,"tv":1.58,"id":424676}]}]}
{"op":"mcm","clk":"11777671297","pt":1722720013816,"mc":[{"id":"1.231344826","rc":[{"batb":[[0,2.14,35.43],[1,1.74,17.32],[2,1.3,633.33]],"ltp":2.24,"tv":1.58,"id":424676}]}]}
{"op":"mcm","clk":"11777672753","pt":1722720035133,"mc":[{"id":"1.231344826","rc":[{"batb":[[0,2.16,12],[1,2.14,35.43],[2,1.74,17.32]],"ltp":2.24,"tv":1.58,"id":424676}]}]}
{"op":"mcm","clk":"11777672898","pt":1722720037423,"mc":[{"id":"1.231344826","rc":[{"batb":[[0,2.16,10]],"ltp":2.24,"tv":1.58,"id":424676}]}]}
{"op":"mcm","clk":"11777672977","pt":1722720038511,"mc":[{"id":"1.231344826","rc":[{"batb":[[0,2.14,35.43],[1,1.74,17.32],[2,1.3,633.33]],"ltp":2.24,"tv":1.58,"id":424676}]}]}
{"op":"mcm","clk":"11777673101","pt":1722720040432,"mc":[{"id":"1.231344826","rc":[{"batb":[[0,2.16,2],[1,2.14,35.43],[2,1.74,17.32]],"ltp":2.24,"tv":1.58,"id":424676}]}]}
{"op":"mcm","clk":"11777673260","pt":1722720042824,"mc":[{"id":"1.231344826","rc":[{"batb":[[0,2.16,10]],"ltp":2.24,"tv":1.58,"id":424676}]}]}
{"op":"mcm","clk":"11777673478","pt":1722720046240,"mc":[{"id":"1.231344826","rc":[{"batb":[[0,2.16,2]],"ltp":2.24,"tv":1.58,"id":424676}]}]}
{"op":"mcm","clk":"11777673642","pt":1722720048528,"mc":[{"id":"1.231344826","rc":[{"batb":[[0,2.16,10]],"ltp":2.24,"tv":1.58,"id":424676}]}]}
{"op":"mcm","clk":"11777673858","pt":1722720051962,"mc":[{"id":"1.231344826","rc":[{"batb":[[0,2.16,2]],"ltp":2.24,"tv":1.58,"id":424676}]}]}
{"op":"mcm","clk":"11777674010","pt":1722720054439,"mc":[{"id":"1.231344826","rc":[{"batb":[[0,2.16,10]],"ltp":2.24,"tv":1.58,"id":424676}]}]}
{"op":"mcm","clk":"11777674282","pt":1722720057741,"mc":[{"id":"1.231344826","rc":[{"batb":[[0,2.16,2]],"ltp":2.24,"tv":1.58,"id":424676}]}]}
{"op":"mcm","clk":"11777674423","pt":1722720060064,"mc":[{"id":"1.231344826","rc":[{"batb":[[0,2.16,10]],"ltp":2.24,"tv":1.58,"id":424676}]}]}
{"op":"mcm","clk":"11777674643","pt":1722720063458,"mc":[{"id":"1.231344826","rc":[{"batb":[[0,2.16,2]],"ltp":2.24,"tv":1.58,"id":424676}]}]}
{"op":"mcm","clk":"11777674810","pt":1722720065958,"mc":[{"id":"1.231344826","rc":[{"batb":[[0,2.16,10]],"ltp":2.24,"tv":1.58,"id":424676}]}]}
{"op":"mcm","clk":"11777675042","pt":1722720069475,"mc":[{"id":"1.231344826","rc":[{"batb":[[0,2.16,2]],"ltp":2.24,"tv":1.58,"id":424676}]}]}
{"op":"mcm","clk":"11777675198","pt":1722720072064,"mc":[{"id":"1.231344826","rc":[{"batb":[[0,2.16,10]],"ltp":2.24,"tv":1.58,"id":424676}]}]}
{"op":"mcm","clk":"11777675411","pt":1722720075538,"mc":[{"id":"1.231344826","rc":[{"batb":[[0,2.16,2]],"ltp":2.24,"tv":1.58,"id":424676}]}]}
{"op":"mcm","clk":"11777675564","pt":1722720078062,"mc":[{"id":"1.231344826","rc":[{"batb":[[0,2.16,10]],"ltp":2.24,"tv":1.58,"id":424676}]}]}
{"op":"mcm","clk":"11777675695","pt":1722720080181,"mc":[{"id":"1.231344826","rc":[{"batb":[[0,2.18,2],[1,2.16,10],[2,2.14,35.43]],"ltp":2.24,"tv":1.58,"id":424676}]}]}
{"op":"mcm","clk":"11777675776","pt":1722720081375,"mc":[{"id":"1.231344826","rc":[{"batb":[[1,2.14,35.43],[2,1.74,17.32]],"ltp":2.24,"tv":1.58,"id":424676}]}]}
{"op":"mcm","clk":"11777675850","pt":1722720082572,"mc":[{"id":"1.231344826","rc":[{"batb":[[0,2.14,35.43],[1,1.74,17.32],[2,1.3,633.33]],"ltp":2.24,"tv":1.58,"id":424676}]}]}
{"op":"mcm","clk":"11777676290","pt":1722720090053,"mc":[{"id":"1.231344826","rc":[{"batb":[[0,2.16,12],[1,2.14,35.43],[2,1.74,17.32]],"ltp":2.24,"tv":1.58,"id":424676}]}]}
{"op":"mcm","clk":"11777676444","pt":1722720092494,"mc":[{"id":"1.231344826","rc":[{"batb":[[0,2.16,10]],"ltp":2.24,"tv":1.58,"id":424676}]}]}
{"op":"mcm","clk":"11777676524","pt":1722720093691,"mc":[{"id":"1.231344826","rc":[{"batb":[[0,2.14,35.43],[1,1.74,17.32],[2,1.3,633.33]],"ltp":2.24,"tv":1.58,"id":424676}]}]}
{"op":"mcm","clk":"11777677702","pt":1722720110876,"mc":[{"id":"1.231344826","rc":[{"batb":[[0,2.16,12],[1,2.14,35.43],[2,1.74,17.32]],"ltp":2.24,"tv":1.58,"id":424676}]}]}
{"op":"mcm","clk":"11777677869","pt":1722720113396,"mc":[{"id":"1.231344826","rc":[{"batb":[[0,2.16,10]],"ltp":2.24,"tv":1.58,"id":424676}]}]}
{"op":"mcm","clk":"11777677931","pt":1722720114380,"mc":[{"id":"1.231344826","rc":[{"batb":[[0,2.14,35.43],[1,1.74,17.32],[2,1.3,633.33]],"ltp":2.24,"tv":1.58,"id":424676}]}]}
{"op":"mcm","clk":"11777678479","pt":1722720122822,"mc":[{"id":"1.231344826","rc":[{"batb":[[0,2.16,12],[1,2.14,35.43],[2,1.74,17.32]],"ltp":2.24,"tv":1.58,"id":424676}]}]}
{"op":"mcm","clk":"11777678649","pt":1722720125303,"mc":[{"id":"1.231344826","rc":[{"batb":[[0,2.16,10]],"ltp":2.24,"tv":1.58,"id":424676}]}]}
{"op":"mcm","clk":"11777678709","pt":1722720126187,"mc":[{"id":"1.231344826","rc":[{"batb":[[0,2.14,35.43],[1,1.74,17.32],[2,1.3,633.33]],"ltp":2.24,"tv":1.58,"id":424676}]}]}
{"op":"mcm","clk":"11777681030","pt":1722720169551,"mc":[{"id":"1.231344826","rc":[{"batb":[[0,2.16,12],[1,2.14,35.43],[2,1.74,17.32]],"ltp":2.24,"tv":1.58,"id":424676}]}]}
{"op":"mcm","clk":"11777681168","pt":1722720172079,"mc":[{"id":"1.231344826","rc":[{"batb":[[0,2.16,10]],"ltp":2.24,"tv":1.58,"id":424676}]}]}
{"op":"mcm","clk":"11777681211","pt":1722720173062,"mc":[{"id":"1.231344826","rc":[{"batb":[[0,2.14,35.43],[1,1.74,17.32],[2,1.3,633.33]],"ltp":2.24,"tv":1.58,"id":424676}]}]}
{"op":"mcm","clk":"11777681379","pt":1722720176581,"mc":[{"id":"1.231344826","rc":[{"batb":[[0,2.16,12],[1,2.14,35.43],[2,1.74,17.32]],"ltp":2.24,"tv":1.58,"id":424676}]}]}
{"op":"mcm","clk":"11777681484","pt":1722720178959,"mc":[{"id":"1.231344826","rc":[{"batb":[[0,2.16,10]],"ltp":2.24,"tv":1.58,"id":424676}]}]}
{"op":"mcm","clk":"11777681536","pt":1722720179945,"mc":[{"id":"1.231344826","rc":[{"batb":[[0,2.14,35.43],[1,1.74,17.32],[2,1.3,633.33]],"ltp":2.24,"tv":1.58,"id":424676}]}]}
{"op":"mcm","clk":"11777681812","pt":1722720186096,"mc":[{"id":"1.231344826","rc":[{"batb":[[0,2.16,12],[1,2.14,35.43],[2,1.74,17.32]],"ltp":2.24,"tv":1.58,"id":424676}]}]}
{"op":"mcm","clk":"11777681915","pt":1722720188380,"mc":[{"id":"1.231344826","rc":[{"batb":[[0,2.16,10]],"ltp":2.24,"tv":1.58,"id":424676}]}]}
{"op":"mcm","clk":"11777681979","pt":1722720189562,"mc":[{"id":"1.231344826","rc":[{"batb":[[0,2.14,35.43],[1,1.74,17.32],[2,1.3,633.33]],"ltp":2.24,"tv":1.58,"id":424676}]}]}
{"op":"mcm","clk":"11777682234","pt":1722720195281,"mc":[{"id":"1.231344826","rc":[{"batb":[[0,2.16,12],[1,2.14,35.43],[2,1.74,17.32]],"ltp":2.24,"tv":1.58,"id":424676}]}]}
{"op":"mcm","clk":"11777682362","pt":1722720197771,"mc":[{"id":"1.231344826","rc":[{"batb":[[0,2.16,10]],"ltp":2.24,"tv":1.58,"id":424676}]}]}
{"op":"mcm","clk":"11777682411","pt":1722720198698,"mc":[{"id":"1.231344826","rc":[{"batb":[[0,2.14,35.43],[1,1.74,17.32],[2,1.3,633.33]],"ltp":2.24,"tv":1.58,"id":424676}]}]}
{"op":"mcm","clk":"11777682511","pt":1722720200708,"mc":[{"id":"1.231344826","rc":[{"batb":[[0,2.16,2],[1,2.14,35.43],[2,1.74,17.32]],"ltp":2.24,"tv":1.58,"id":424676}]}]}
{"op":"mcm","clk":"11777682653","pt":1722720203086,"mc":[{"id":"1.231344826","rc":[{"batb":[[0,2.16,10]],"ltp":2.24,"tv":1.58,"id":424676}]}]}
{"op":"mcm","clk":"11777682836","pt":1722720206492,"mc":[{"id":"1.231344826","rc":[{"batb":[[0,2.16,2]],"ltp":2.24,"tv":1.58,"id":424676}]}]}
{"op":"mcm","clk":"11777682977","pt":1722720208817,"mc":[{"id":"1.231344826","rc":[{"batb":[[0,2.16,10]],"ltp":2.24,"tv":1.58,"id":424676}]}]}
{"op":"mcm","clk":"11777683177","pt":1722720212427,"mc":[{"id":"1.231344826","rc":[{"batb":[[0,2.16,2]],"ltp":2.24,"tv":1.58,"id":424676}]}]}
{"op":"mcm","clk":"11777683308","pt":1722720214846,"mc":[{"id":"1.231344826","rc":[{"batb":[[0,2.16,10]],"ltp":2.24,"tv":1.58,"id":424676}]}]}
{"op":"mcm","clk":"11777683509","pt":1722720218405,"mc":[{"id":"1.231344826","rc":[{"batb":[[0,2.16,2]],"ltp":2.24,"tv":1.58,"id":424676}]}]}
{"op":"mcm","clk":"11777683664","pt":1722720220820,"mc":[{"id":"1.231344826","rc":[{"batb":[[0,2.16,10]],"ltp":2.24,"tv":1.58,"id":424676}]}]}
{"op":"mcm","clk":"11777683869","pt":1722720224331,"mc":[{"id":"1.231344826","rc":[{"batb":[[0,2.16,2]],"ltp":2.24,"tv":1.58,"id":424676}]}]}
{"op":"mcm","clk":"11777683989","pt":1722720226544,"mc":[{"id":"1.231344826","rc":[{"batb":[[0,2.14,35.43],[1,1.74,17.32],[2,1.3,633.33]],"ltp":2.24,"tv":1.58,"id":424676}]}]}
{"op":"mcm","clk":"11777683996","pt":1722720226652,"mc":[{"id":"1.231344826","rc":[{"batb":[[0,2.16,10],[1,2.14,35.43],[2,1.74,17.32]],"ltp":2.24,"tv":1.58,"id":424676}]}]}
{"op":"mcm","clk":"11777684200","pt":1722720230359,"mc":[{"id":"1.231344826","rc":[{"batb":[[0,2.16,2]],"ltp":2.24,"tv":1.58,"id":424676}]}]}
{"op":"mcm","clk":"11777684349","pt":1722720232837,"mc":[{"id":"1.231344826","rc":[{"batb":[[0,2.16,10]],"ltp":2.24,"tv":1.58,"id":424676}]}]}
{"op":"mcm","clk":"11777684533","pt":1722720236339,"mc":[{"id":"1.231344826","rc":[{"batb":[[0,2.16,2]],"ltp":2.24,"tv":1.58,"id":424676}]}]}
{"op":"mcm","clk":"11777684666","pt":1722720238961,"mc":[{"id":"1.231344826","rc":[{"batb":[[0,2.16,10]],"ltp":2.24,"tv":1.58,"id":424676}]}]}
{"op":"mcm","clk":"11777684858","pt":1722720242365,"mc":[{"id":"1.231344826","rc":[{"batb":[[0,2.14,35.43],[1,1.74,17.32],[2,1.3,633.33]],"ltp":2.24,"tv":1.58,"id":424676}]}]}
{"op":"mcm","clk":"11777684868","pt":1722720242570,"mc":[{"id":"1.231344826","rc":[{"batb":[[0,2.16,2],[1,2.14,35.43],[2,1.74,17.32]],"ltp":2.24,"tv":1.58,"id":424676}]}]}
{"op":"mcm","clk":"11777685001","pt":1722720245145,"mc":[{"id":"1.231344826","rc":[{"batb":[[0,2.16,10]],"ltp":2.24,"tv":1.58,"id":424676}]}]}
{"op":"mcm","clk":"11777685190","pt":1722720248491,"mc":[{"id":"1.231344826","rc":[{"batb":[[0,2.14,35.43],[1,1.74,17.32],[2,1.3,633.33]],"ltp":2.24,"tv":1.58,"id":424676}]}]}
{"op":"mcm","clk":"11777685203","pt":1722720248649,"mc":[{"id":"1.231344826","rc":[{"batb":[[0,2.16,2],[1,2.14,35.43],[2,1.74,17.32]],"ltp":2.24,"tv":1.58,"id":424676}]}]}
{"op":"mcm","clk":"11777685345","pt":1722720251270,"mc":[{"id":"1.231344826","rc":[{"batb":[[0,2.16,10]],"ltp":2.24,"tv":1.58,"id":424676}]}]}
{"op":"mcm","clk":"11777685532","pt":1722720254781,"mc":[{"id":"1.231344826","rc":[{"batb":[[0,2.16,2]],"ltp":2.24,"tv":1.58,"id":424676}]}]}
{"op":"mcm","clk":"11777685658","pt":1722720257202,"mc":[{"id":"1.231344826","rc":[{"batb":[[0,2.16,10]],"ltp":2.24,"tv":1.58,"id":424676}]}]}
{"op":"mcm","clk":"11777685844","pt":1722720260495,"mc":[{"id":"1.231344826","rc":[{"batb":[[0,2.18,2]],"ltp":2.24,"tv":1.58,"id":424676}]}]}
{"op":"mcm","clk":"11777685948","pt":1722720262502,"mc":[{"id":"1.231344826","rc":[{"batb":[[0,2.14,35.43],[1,1.74,17.32],[2,1.3,633.33]],"ltp":2.24,"tv":1.58,"id":424676}]}]}
{"op":"mcm","clk":"11777685954","pt":1722720262556,"mc":[{"id":"1.231344826","rc":[{"batb":[[0,2.16,10],[1,2.14,35.43],[2,1.74,17.32]],"ltp":2.24,"tv":1.58,"id":424676}]}]}
{"op":"mcm","clk":"11777686077","pt":1722720265074,"mc":[{"id":"1.231344826","rc":[{"batb":[[0,2.18,2],[1,2.16,10],[2,2.14,35.43]],"ltp":2.24,"tv":1.58,"id":424676}]}]}
{"op":"mcm","clk":"11777686128","pt":1722720266102,"mc":[{"id":"1.231344826","rc":[{"batb":[[1,2.14,35.43],[2,1.74,17.32]],"ltp":2.24,"tv":1.58,"id":424676}]}]}
{"op":"mcm","clk":"11777686200","pt":1722720267388,"mc":[{"id":"1.231344826","rc":[{"batb":[[0,2.14,35.43],[1,1.74,17.32],[2,1.3,633.33]],"ltp":2.24,"tv":1.58,"id":424676}]}]}
{"op":"mcm","clk":"11777686611","pt":1722720275387,"mc":[{"id":"1.231344826","rc":[{"batb":[[0,2.16,12],[1,2.14,35.43],[2,1.74,17.32]],"ltp":2.24,"tv":1.58,"id":424676}]}]}
{"op":"mcm","clk":"11777686750","pt":1722720277915,"mc":[{"id":"1.231344826","rc":[{"batb":[[0,2.16,10]],"ltp":2.24,"tv":1.58,"id":424676}]}]}
{"op":"mcm","clk":"11777686796","pt":1722720278795,"mc":[{"id":"1.231344826","rc":[{"batb":[[0,2.14,35.43],[1,1.74,17.32],[2,1.3,633.33]],"ltp":2.24,"tv":1.58,"id":424676}]}]}
{"op":"mcm","clk":"11777688217","pt":1722720306910,"mc":[{"id":"1.231344826","rc":[{"batb":[[0,2.16,12],[1,2.14,35.43],[2,1.74,17.32]],"ltp":2.24,"tv":1.58,"id":424676}]}]}
{"op":"mcm","clk":"11777688336","pt":1722720309227,"mc":[{"id":"1.231344826","rc":[{"batb":[[0,2.16,10]],"ltp":2.24,"tv":1.58,"id":424676}]}]}
{"op":"mcm","clk":"11777688411","pt":1722720310423,"mc":[{"id":"1.231344826","rc":[{"batb":[[0,2.14,35.43],[1,1.74,17.32],[2,1.3,633.33]],"ltp":2.24,"tv":1.58,"id":424676}]}]}
{"op":"mcm","clk":"11777690719","pt":1722720352904,"mc":[{"id":"1.231344826","rc":[{"batb":[[0,2.16,12],[1,2.14,35.43],[2,1.74,17.32]],"ltp":2.24,"tv":1.58,"id":424676}]}]}
{"op":"mcm","clk":"11777690850","pt":1722720355380,"mc":[{"id":"1.231344826","rc":[{"batb":[[0,2.16,10]],"ltp":2.24,"tv":1.58,"id":424676}]}]}
{"op":"mcm","clk":"11777690901","pt":1722720356306,"mc":[{"id":"1.231344826","rc":[{"batb":[[0,2.14,35.43],[1,1.74,17.32],[2,1.3,633.33]],"ltp":2.24,"tv":1.58,"id":424676}]}]}
{"op":"mcm","clk":"11777690968","pt":1722720357701,"mc":[{"id":"1.231344826","rc":[{"batb":[[0,2.16,2],[1,2.14,35.43],[2,1.74,17.32]],"ltp":2.24,"tv":1.58,"id":424676}]}]}
{"op":"mcm","clk":"11777691104","pt":1722720360074,"mc":[{"id":"1.231344826","rc":[{"batb":[[0,2.16,10]],"ltp":2.24,"tv":1.58,"id":424676}]}]}
{"op":"mcm","clk":"11777691285","pt":1722720363493,"mc":[{"id":"1.231344826","rc":[{"batb":[[0,2.14,35.43],[1,1.74,17.32],[2,1.3,633.33]],"ltp":2.24,"tv":1.58,"id":424676}]}]}
{"op":"mcm","clk":"11777691295","pt":1722720363699,"mc":[{"id":"1.231344826","rc":[{"batb":[[0,2.16,2],[1,2.14,35.43],[2,1.74,17.32]],"ltp":2.24,"tv":1.58,"id":424676}]}]}
{"op":"mcm","clk":"11777691403","pt":1722720365990,"mc":[{"id":"1.231344826","rc":[{"batb":[[0,2.16,10]],"ltp":2.24,"tv":1.58,"id":424676}]}]}
{"op":"mcm","clk":"11777691603","pt":1722720369400,"mc":[{"id":"1.231344826","rc":[{"batb":[[0,2.16,2]],"ltp":2.24,"tv":1.58,"id":424676}]}]}
{"op":"mcm","clk":"11777691721","pt":1722720371718,"mc":[{"id":"1.231344826","rc":[{"batb":[[0,2.16,10]],"ltp":2.24,"tv":1.58,"id":424676}]}]}
{"op":"mcm","clk":"11777691826","pt":1722720373787,"mc":[{"id":"1.231344826","rc":[{"batb":[[0,2.18,2],[1,2.16,10],[2,2.14,35.43]],"ltp":2.24,"tv":1.58,"id":424676}]}]}
{"op":"mcm","clk":"11777691901","pt":1722720375029,"mc":[{"id":"1.231344826","rc":[{"batb":[[1,2.14,35.43],[2,1.74,17.32]],"ltp":2.24,"tv":1.58,"id":424676}]}]}
{"op":"mcm","clk":"11777691974","pt":1722720376314,"mc":[{"id":"1.231344826","rc":[{"batb":[[0,2.14,35.43],[1,1.74,17.32],[2,1.3,633.33]],"ltp":2.24,"tv":1.58,"id":424676}]}]}
{"op":"mcm","clk":"11777692082","pt":1722720378324,"mc":[{"id":"1.231344826","rc":[{"batb":[[0,2.16,10],[1,2.14,35.43],[2,1.74,17.32]],"ltp":2.24,"tv":1.58,"id":424676}]}]}
{"op":"mcm","clk":"11777692177","pt":1722720379996,"mc":[{"id":"1.231344826","rc":[{"batb":[[0,2.18,2],[1,2.16,10],[2,2.14,35.43]],"ltp":2.24,"tv":1.58,"id":424676}]}]}
{"op":"mcm","clk":"11777692299","pt":1722720382325,"mc":[{"id":"1.231344826","rc":[{"batb":[[0,2.14,35.43],[1,1.74,17.32],[2,1.3,633.33]],"ltp":2.24,"tv":1.58,"id":424676}]}]}
{"op":"mcm","clk":"11777692463","pt":1722720385529,"mc":[{"id":"1.231344826","rc":[{"batb":[[0,2.16,12],[1,2.14,35.43],[2,1.74,17.32]],"ltp":2.24,"tv":1.58,"id":424676}]}]}
{"op":"mcm","clk":"11777692613","pt":1722720387951,"mc":[{"id":"1.231344826","rc":[{"batb":[[0,2.16,10]],"ltp":2.24,"tv":1.58,"id":424676}]}]}
{"op":"mcm","clk":"11777692663","pt":1722720388941,"mc":[{"id":"1.231344826","rc":[{"batb":[[0,2.14,35.43],[1,1.74,17.32],[2,1.3,633.33]],"ltp":2.24,"tv":1.58,"id":424676}]}]}
{"op":"mcm","clk":"11777693302","pt":1722720400666,"mc":[{"id":"1.231344826","rc":[{"batb":[[0,2.16,12],[1,2.14,35.43],[2,1.74,17.32]],"ltp":2.24,"tv":1.58,"id":424676}]}]}
{"op":"mcm","clk":"11777693432","pt":1722720402930,"mc":[{"id":"1.231344826","rc":[{"batb":[[0,2.16,10]],"ltp":2.24,"tv":1.58,"id":424676}]}]}
{"op":"mcm","clk":"11777693495","pt":1722720403958,"mc":[{"id":"1.231344826","rc":[{"batb":[[0,2.14,35.43],[1,1.74,17.32],[2,1.3,633.33]],"ltp":2.24,"tv":1.58,"id":424676}]}]}
{"op":"mcm","clk":"11777693673","pt":1722720407252,"mc":[{"id":"1.231344826","rc":[{"batb":[[0,2.16,12],[1,2.14,35.43],[2,1.74,17.32]],"ltp":2.24,"tv":1.58,"id":424676}]}]}
{"op":"mcm","clk":"11777693805","pt":1722720409777,"mc":[{"id":"1.231344826","rc":[{"batb":[[0,2.16,10]],"ltp":2.24,"tv":1.58,"id":424676}]}]}
{"op":"mcm","clk":"11777693852","pt":1722720410654,"mc":[{"id":"1.231344826","rc":[{"batb":[[0,2.14,35.43],[1,1.74,17.32],[2,1.3,633.33]],"ltp":2.24,"tv":1.58,"id":424676}]}]}
{"op":"mcm","clk":"11777694170","pt":1722720415764,"mc":[{"id":"1.231344826","rc":[{"batb":[[0,2.16,12],[1,2.14,35.43],[2,1.74,17.32]],"ltp":2.24,"tv":1.58,"id":424676}]}]}
{"op":"mcm","clk":"11777694277","pt":1722720418183,"mc":[{"id":"1.231344826","rc":[{"batb":[[0,2.16,10]],"ltp":2.24,"tv":1.58,"id":424676}]}]}
{"op":"mcm","clk":"11777694342","pt":1722720419065,"mc":[{"id":"1.231344826","rc":[{"batb":[[0,2.14,35.43],[1,1.74,17.32],[2,1.3,633.33]],"ltp":2.24,"tv":1.58,"id":424676}]}]}
{"op":"mcm","clk":"11777694872","pt":1722720427989,"mc":[{"id":"1.231344826","rc":[{"batb":[[0,2.16,12],[1,2.14,35.43],[2,1.74,17.32]],"ltp":2.24,"tv":1.58,"id":424676}]}]}
{"op":"mcm","clk":"11777695061","pt":1722720431495,"mc":[{"id":"1.231344826","rc":[{"batb":[[0,2.14,35.43],[1,1.74,17.32],[2,1.3,633.33]],"ltp":2.24,"tv":1.58,"id":424676}]}]}
{"op":"mcm","clk":"11777696765","pt":1722720462243,"mc":[{"id":"1.231344826","rc":[{"batb":[[0,2.16,12],[1,2.14,35.43],[2,1.74,17.32]],"ltp":2.24,"tv":1.58,"id":424676}]}]}
{"op":"mcm","clk":"11777696888","pt":1722720464514,"mc":[{"id":"1.231344826","rc":[{"batb":[[0,2.16,10]],"ltp":2.24,"tv":1.58,"id":424676}]}]}
{"op":"mcm","clk":"11777696937","pt":1722720465445,"mc":[{"id":"1.231344826","rc":[{"batb":[[0,2.14,35.43],[1,1.74,17.32],[2,1.3,633.33]],"ltp":2.24,"tv":1.58,"id":424676}]}]}
{"op":"mcm","clk":"11777697154","pt":1722720468854,"mc":[{"id":"1.231344826","rc":[{"batb":[[0,2.16,12],[1,2.14,35.43],[2,1.74,17.32]],"ltp":2.24,"tv":1.58,"id":424676}]}]}
{"op":"mcm","clk":"11777697319","pt":1722720471333,"mc":[{"id":"1.231344826","rc":[{"batb":[[0,2.16,10]],"ltp":2.24,"tv":1.58,"id":424676}]}]}
{"op":"mcm","clk":"11777697375","pt":1722720472360,"mc":[{"id":"1.231344826","rc":[{"batb":[[0,2.14,35.43],[1,1.74,17.32],[2,1.3,633.33]],"ltp":2.24,"tv":1.58,"id":424676}]}]}
{"op":"mcm","clk":"11777697466","pt":1722720473858,"mc":[{"id":"1.231344826","rc":[{"batb":[[0,2.16,2],[1,2.14,35.43],[2,1.74,17.32]],"ltp":2.24,"tv":1.58,"id":424676}]}]}
{"op":"mcm","clk":"11777697594","pt":1722720476229,"mc":[{"id":"1.231344826","rc":[{"batb":[[0,2.16,10]],"ltp":2.24,"tv":1.58,"id":424676}]}]}
{"op":"mcm","clk":"11777697789","pt":1722720479839,"mc":[{"id":"1.231344826","rc":[{"batb":[[0,2.16,2]],"ltp":2.24,"tv":1.58,"id":424676}]}]}
{"op":"mcm","clk":"11777697936","pt":1722720482366,"mc":[{"id":"1.231344826","rc":[{"batb":[[0,2.16,10]],"ltp":2.24,"tv":1.58,"id":424676}]}]}
{"op":"mcm","clk":"11777698100","pt":1722720485674,"mc":[{"id":"1.231344826","rc":[{"batb":[[0,2.16,2]],"ltp":2.24,"tv":1.58,"id":424676}]}]}
{"op":"mcm","clk":"11777698215","pt":1722720487951,"mc":[{"id":"1.231344826","rc":[{"batb":[[0,2.16,10]],"ltp":2.24,"tv":1.58,"id":424676}]}]}
{"op":"mcm","clk":"11777698396","pt":1722720491349,"mc":[{"id":"1.231344826","rc":[{"batb":[[0,2.16,2]],"ltp":2.24,"tv":1.58,"id":424676}]}]}
{"op":"mcm","clk":"11777698542","pt":1722720493978,"mc":[{"id":"1.231344826","rc":[{"batb":[[0,2.16,10]],"ltp":2.24,"tv":1.58,"id":424676}]}]}
{"op":"mcm","clk":"11777698734","pt":1722720497482,"mc":[{"id":"1.231344826","rc":[{"batb":[[0,2.14,35.43],[1,1.74,17.32],[2,1.3,633.33]],"ltp":2.24,"tv":1.58,"id":424676}]}]}
