{"op":"mcm","clk":"11833623454","pt":1723117221551,"mc":[{"id":"1.231583502","marketDefinition":{"bspMarket":false,"turnInPlayEnabled":true,"persistenceEnabled":true,"marketBaseRate":5.0,"eventId":"33477704","eventTypeId":"4","numberOfWinners":1,"bettingType":"ODDS","marketType":"MATCH_ODDS","marketTime":"2024-08-10T10:00:00.000Z","suspendTime":"2024-08-10T10:00:00.000Z","bspReconciled":false,"complete":true,"inPlay":false,"crossMatching":true,"runnersVoidable":false,"numberOfActiveRunners":2,"betDelay":0,"status":"OPEN","runners":[{"status":"ACTIVE","sortPriority":1,"id":40096579,"name":"Southern Brave Women"},{"status":"ACTIVE","sortPriority":2,"id":40096580,"name":"Trent Rockets Women"}],"regulators":["MR_INT"],"countryCode":"GB","discountAllowed":false,"timezone":"GMT","openDate":"2024-08-10T10:00:00.000Z","version":6061759595,"name":"Match Odds","eventName":"Southern Brave Women v Trent Rockets Women"},"rc":[{"batb":[[0,1.03,200],[1,1.02,200],[2,1.01,220]],"ltp":0.0,"tv":0.0,"id":40096579},{"batb":[[0,1.03,200],[1,1.02,200],[2,1.01,220]],"ltp":0.0,"tv":0.0,"id":40096580}]}]}
{"op":"mcm","clk":"11833623590","pt":1723117225019,"mc":[{"id":"1.231583502","marketDefinition":{"bspMarket":false,"turnInPlayEnabled":true,"persistenceEnabled":true,"marketBaseRate":5.0,"eventId":"33477704","eventTypeId":"4","numberOfWinners":1,"bettingType":"ODDS","marketType":"MATCH_ODDS","marketTime":"2024-08-10T10:00:00.000Z","suspendTime":"2024-08-10T10:00:00.000Z","bspReconciled":false,"complete":true,"inPlay":false,"crossMatching":true,"runnersVoidable":false,"numberOfActiveRunners":2,"betDelay":0,"status":"OPEN","runners":[{"status":"ACTIVE","sortPriority":1,"id":40096579,"name":"Southern Brave Women"},{"status":"ACTIVE","sortPriority":2,"id":40096580,"name":"Trent Rockets Women"}],"regulators":["MR_INT"],"countryCode":"GB","discountAllowed":true,"timezone":"GMT","openDate":"2024-08-10T10:00:00.000Z","version":6061759595,"name":"Match Odds","eventName":"Southern Brave Women v Trent Rockets Women"}}]}
{"op":"mcm","clk":"11833688173","pt":1723118411179,"mc":[{"id":"1.231583502","rc":[{"batb":[[0,1.1,25000],[1,1.09,25000],[2,1.08,25000]],"ltp":0.0,"tv":0.0,"id":40096579},{"batb":[[0,1.1,25000],[1,1.09,25000],[2,1.08,25000]],"ltp":0.0,"tv":0.0,"id":40096580}]}]}
{"op":"mcm","clk":"11833688442","pt":1723118415817,"mc":[{"id":"1.231583502","rc":[{"batb":[[0,1.08,10000],[1,1.07,25000],[2,1.06,25000]],"ltp":0.0,"tv":0.0,"id":40096579}]}]}
{"op":"mcm","clk":"11833688507","pt":1723118417003,"mc":[{"id":"1.231583502","rc":[{"batb":[[0,1.05,25000],[1,1.04,25000],[2,1.03,25200]],"ltp":0.0,"tv":0.0,"id":40096579}]}]}
{"op":"mcm","clk":"11833688568","pt":1723118417886,"mc":[{"id":"1.231583502","rc":[{"batb":[[0,1.04,25000],[1,1.03,25200],[2,1.02,25200]],"ltp":0.0,"tv":0.0,"id":40096579}]}]}
{"op":"mcm","clk":"11833688895","pt":1723118422880,"mc":[{"id":"1.231583502","rc":[{"batb":[[0,1.09,10000],[1,1.08,25000],[2,1.07,25000]],"ltp":0.0,"tv":0.0,"id":40096580}]}]}
{"op":"mcm","clk":"11833688935","pt":1723118423502,"mc":[{"id":"1.231583502","rc":[{"batb":[[0,1.07,25000],[1,1.06,25000],[2,1.05,25000]],"ltp":0.0,"tv":0.0,"id":40096580}]}]}
{"op":"mcm","clk":"11833689008","pt":1723118424891,"mc":[{"id":"1.231583502","rc":[{"batb":[[0,1.05,25000],[1,1.04,25000],[2,1.03,25200]],"ltp":0.0,"tv":0.0,"id":40096580}]}]}
{"op":"mcm","clk":"11833689075","pt":1723118426228,"mc":[{"id":"1.231583502","rc":[{"batb":[[0,1.04,25000],[1,1.03,25200],[2,1.02,25200]],"ltp":0.0,"tv":0.0,"id":40096580}]}]}
{"op":"mcm","clk":"11834341949","pt":1723129857849,"mc":[{"id":"1.231583502","rc":[{"batb":[[0,1.25,100],[1,1.04,25000],[2,1.03,25200]],"ltp":0.0,"tv":0.0,"id":40096579}]}]}
{"op":"mcm","clk":"11834342023","pt":1723129858653,"mc":[{"id":"1.231583502","rc":[{"batb":[[0,1.25,100],[1,1.04,25000],[2,1.03,25200]],"ltp":0.0,"tv":0.0,"id":40096580}]}]}
{"op":"mcm","clk":"11834733941","pt":1723134125346,"mc":[{"id":"1.231583502","rc":[{"batb":[[0,1.25,100.91]],"ltp":0.0,"tv":0.0,"id":40096579}]}]}
{"op":"mcm","clk":"11834734904","pt":1723134133747,"mc":[{"id":"1.231583502","rc":[{"batb":[[0,1.25,100.91]],"ltp":0.0,"tv":0.0,"id":40096580}]}]}
{"op":"mcm","clk":"11835183335","pt":1723137482890,"mc":[{"id":"1.231583502","rc":[{"batb":[[0,1.26,20.91],[1,1.25,100],[2,1.04,25000]],"ltp":0.0,"tv":0.0,"id":40096579},{"batb":[[0,1.26,20.91],[1,1.25,100],[2,1.04,25000]],"ltp":0.0,"tv":0.0,"id":40096580}]}]}
{"op":"mcm","clk":"11835402147","pt":1723138943347,"mc":[{"id":"1.231583502","rc":[{"batb":[[0,4.5,1.57],[1,1.26,20.91],[2,1.25,100]],"ltp":0.0,"tv":0.0,"id":40096579}]}]}
{"op":"mcm","clk":"11835402844","pt":1723138948232,"mc":[{"id":"1.231583502","rc":[{"batb":[[0,1.26,20.91],[1,1.25,100],[2,1.04,25000]],"ltp":0.0,"tv":0.0,"id":40096579}]}]}
{"op":"mcm","clk":"11835403755","pt":1723138954107,"mc":[{"id":"1.231583502","rc":[{"batb":[[0,4.5,1.57],[1,1.26,20.91],[2,1.25,100]],"ltp":0.0,"tv":0.0,"id":40096579}]}]}
{"op":"mcm","clk":"11835404501","pt":1723138958898,"mc":[{"id":"1.231583502","rc":[{"batb":[[0,1.26,20.91],[1,1.25,100],[2,1.04,25000]],"ltp":0.0,"tv":0.0,"id":40096579}]}]}
{"op":"mcm","clk":"11835404765","pt":1723138960638,"mc":[{"id":"1.231583502","rc":[{"batl":[[0,4.5,1]],"ltp":0.0,"tv":0.0,"id":40096579}]}]}
{"op":"mcm","clk":"11835936611","pt":1723142078898,"mc":[{"id":"1.231583502","rc":[{"batl":[[0,1.29,1.57]],"ltp":0.0,"tv":0.0,"id":40096580}]}]}
{"op":"mcm","clk":"11835947875","pt":1723142145670,"mc":[{"id":"1.231583502","rc":[{"batl":[[0,1.28,1.57]],"ltp":0.0,"tv":0.0,"id":40096579}]}]}
{"op":"mcm","clk":"11835948667","pt":1723142150358,"mc":[{"id":"1.231583502","rc":[{"trd":[[1.28,3.14]],"batb":[[0,1.28,2.07],[1,1.26,20.91],[2,1.25,100]],"ltp":1.28,"tv":3.13,"id":40096579}],"tv":3.13}]}
{"op":"mcm","clk":"11835949224","pt":1723142153845,"mc":[{"id":"1.231583502","rc":[{"batb":[[0,1.26,20.91],[1,1.25,100],[2,1.04,25000]],"ltp":1.28,"tv":3.13,"id":40096579}]}]}
{"op":"mcm","clk":"11835950464","pt":1723142161486,"mc":[{"id":"1.231583502","rc":[{"batl":[[0,1.3,1.57]],"ltp":1.28,"tv":3.13,"id":40096579}]}]}
{"op":"mcm","clk":"11835951140","pt":1723142165364,"mc":[{"id":"1.231583502","rc":[{"trd":[[1.3,3.14]],"batb":[[0,1.3,2.07],[1,1.26,20.91],[2,1.25,100]],"ltp":1.3,"tv":6.27,"id":40096579}],"tv":6.27}]}
{"op":"mcm","clk":"11835951860","pt":1723142169787,"mc":[{"id":"1.231583502","rc":[{"batb":[[0,1.26,20.91],[1,1.25,100],[2,1.04,25000]],"ltp":1.3,"tv":6.27,"id":40096579}]}]}
{"op":"mcm","clk":"11836055179","pt":1723142681365,"mc":[{"id":"1.231583502","rc":[{"batl":[[0,1.3,1.26]],"ltp":1.3,"tv":6.27,"id":40096579}]}]}
{"op":"mcm","clk":"11836065136","pt":1723142744702,"mc":[{"id":"1.231583502","rc":[{"batl":[[0,1.3,2.35]],"ltp":0.0,"tv":0.0,"id":40096580}]}]}
{"op":"mcm","clk":"11836065784","pt":1723142748677,"mc":[{"id":"1.231583502","rc":[{"trd":[[1.3,4.71]],"batb":[[0,1.3,1.29],[1,1.26,20.91],[2,1.25,100]],"ltp":1.3,"tv":4.7,"id":40096580}],"tv":10.98}]}
{"op":"mcm","clk":"11836066244","pt":1723142751380,"mc":[{"id":"1.231583502","rc":[{"batb":[[0,1.3,141.9]],"ltp":1.3,"tv":4.7,"id":40096580}]}]}
{"op":"mcm","clk":"11836066813","pt":1723142754753,"mc":[{"id":"1.231583502","rc":[{"batb":[[0,1.3,1.29]],"ltp":1.3,"tv":4.7,"id":40096580}]}]}
{"op":"mcm","clk":"11836066918","pt":1723142755490,"mc":[{"id":"1.231583502","rc":[{"batb":[[0,1.26,20.91],[1,1.25,100],[2,1.04,25000]],"ltp":1.3,"tv":4.7,"id":40096580}]}]}
{"op":"mcm","clk":"11836138137","pt":1723143230304,"mc":[{"id":"1.231583502","rc":[{"batb":[[0,2.16,32.68],[1,1.26,20.91],[2,1.25,100]],"ltp":1.3,"tv":6.27,"id":40096579},{"batb":[[0,1.78,48.6],[1,1.26,20.91],[2,1.25,100]],"ltp":1.3,"tv":4.7,"id":40096580}]}]}
{"op":"mcm","clk":"11836142835","pt":1723143266635,"mc":[{"id":"1.231583502","rc":[{"trd":[[2.16,64]],"batb":[[0,1.26,21.59],[1,1.25,100],[2,1.04,25000]],"ltp":2.16,"tv":70.27,"id":40096579}],"tv":74.98}]}
{"op":"mcm","clk":"11836143288","pt":1723143270429,"mc":[{"id":"1.231583502","rc":[{"batb":[[0,2.08,35.1],[1,1.26,20.91],[2,1.25,100]],"ltp":2.16,"tv":70.27,"id":40096579}]}]}
{"op":"mcm","clk":"11836147352","pt":1723143303717,"mc":[{"id":"1.231583502","rc":[{"trd":[[1.78,1.14]],"batb":[[0,1.78,48.03]],"ltp":1.78,"tv":5.85,"id":40096580}],"tv":76.12}]}
{"op":"mcm","clk":"11836147584","pt":1723143305712,"mc":[{"id":"1.231583502","rc":[{"batb":[[0,1.78,48.6]],"ltp":1.78,"tv":5.85,"id":40096580}]}]}
{"op":"mcm","clk":"11836160482","pt":1723143404453,"mc":[{"id":"1.231583502","rc":[{"batb":[[0,1.8,222.6],[1,1.78,48.6],[2,1.26,20.91]],"ltp":1.78,"tv":5.85,"id":40096580}]}]}
{"op":"mcm","clk":"11836213514","pt":1723143794424,"mc":[{"id":"1.231583502","rc":[{"trd":[[1.28,3.14],[1.3,3.14],[2.08,1.94]],"batb":[[0,2.08,34.13]],"ltp":2.08,"tv":72.21,"id":40096579},{"trd":[[1.3,4.71]],"ltp":1.78,"tv":5.84,"id":40096580}],"tv":78.05}]}
{"op":"mcm","clk":"11836213917","pt":1723143797930,"mc":[{"id":"1.231583502","rc":[{"batb":[[0,2.08,35.1]],"ltp":2.08,"tv":72.21,"id":40096579}]}]}
{"op":"mcm","clk":"11836257167","pt":1723144146244,"mc":[{"id":"1.231583502","rc":[{"batl":[[0,2.24,8.71]],"ltp":2.08,"tv":72.21,"id":40096579},{"batb":[[0,1.81,10.93],[1,1.8,222.6],[2,1.78,48.6]],"ltp":1.78,"tv":5.84,"id":40096580}]}]}
{"op":"mcm","clk":"11836262319","pt":1723144185377,"mc":[{"id":"1.231583502","rc":[{"batb":[[0,1.81,210.93]],"ltp":1.78,"tv":5.84,"id":40096580}]}]}
{"op":"mcm","clk":"11836362081","pt":1723144929262,"mc":[{"id":"1.231583502","rc":[{"batb":[[1,1.74,17.32],[2,1.26,20.91]],"ltp":2.08,"tv":72.21,"id":40096579}]}]}
{"op":"mcm","clk":"11836701425","pt":1723147975212,"mc":[{"id":"1.231583502","rc":[{"trd":[[1.28,3.14],[1.3,3.14]],"batl":[[0,2.24,8.71]],"ltp":2.08,"tv":72.21,"id":40096579},{"trd":[[1.3,4.71]],"batb":[[0,1.81,210.93]],"ltp":1.78,"tv":5.85,"id":40096580}],"tv":78.06}]}
{"op":"mcm","clk":"11836734502","pt":1723148608788,"mc":[{"id":"1.231583502","rc":[{"batb":[[1,1.8,2],[2,1.74,17.32]],"ltp":2.08,"tv":72.21,"id":40096579},{"batb":[[1,1.8,224.6]],"ltp":1.78,"tv":5.85,"id":40096580}]}]}
{"op":"mcm","clk":"11836841928","pt":1723151485898,"mc":[{"id":"1.231583502","rc":[{"trd":[[1.28,3.14],[1.3,3.14]],"ltp":2.08,"tv":72.2,"id":40096579},{"trd":[[1.3,4.71]],"ltp":1.78,"tv":5.84,"id":40096580}],"tv":78.05}]}
{"op":"mcm","clk":"11836873672","pt":1723152658100,"mc":[{"id":"1.231583502","rc":[{"batb":[[0,2.1,10],[1,2.08,35.1],[2,1.8,2]],"ltp":2.08,"tv":72.2,"id":40096579}]}]}
{"op":"mcm","clk":"11836873814","pt":1723152662321,"mc":[{"id":"1.231583502","rc":[{"batb":[[0,2.08,35.1],[1,1.8,2],[2,1.74,17.32]],"ltp":2.08,"tv":72.2,"id":40096579}]}]}
{"op":"mcm","clk":"11836873901","pt":1723152665024,"mc":[{"id":"1.231583502","rc":[{"batb":[[0,2.1,10],[1,2.08,35.1],[2,1.8,2]],"ltp":2.08,"tv":72.2,"id":40096579}]}]}
{"op":"mcm","clk":"11836874011","pt":1723152668210,"mc":[{"id":"1.231583502","rc":[{"batb":[[0,2.08,35.1],[1,1.8,2],[2,1.74,17.32]],"ltp":2.08,"tv":72.2,"id":40096579}]}]}
{"op":"mcm","clk":"11836874177","pt":1723152672222,"mc":[{"id":"1.231583502","rc":[{"batb":[[0,2.1,10],[1,2.08,35.1],[2,1.8,2]],"ltp":2.08,"tv":72.2,"id":40096579}]}]}
{"op":"mcm","clk":"11836874308","pt":1723152675505,"mc":[{"id":"1.231583502","rc":[{"batb":[[0,2.08,35.1],[1,1.8,2],[2,1.74,17.32]],"ltp":2.08,"tv":72.2,"id":40096579}]}]}
{"op":"mcm","clk":"11836874474","pt":1723152679816,"mc":[{"id":"1.231583502","rc":[{"batb":[[0,2.1,10],[1,2.08,35.1],[2,1.8,2]],"ltp":2.08,"tv":72.2,"id":40096579}]}]}
{"op":"mcm","clk":"11836874624","pt":1723152683147,"mc":[{"id":"1.231583502","rc":[{"batb":[[0,2.08,35.1],[1,1.8,2],[2,1.74,17.32]],"ltp":2.08,"tv":72.2,"id":40096579}]}]}
{"op":"mcm","clk":"11836874876","pt":1723152689464,"mc":[{"id":"1.231583502","rc":[{"batb":[[0,2.1,10],[1,2.08,35.1],[2,1.8,2]],"ltp":2.08,"tv":72.2,"id":40096579}]}]}
{"op":"mcm","clk":"11836874974","pt":1723152692870,"mc":[{"id":"1.231583502","rc":[{"batb":[[0,2.08,35.1],[1,1.8,2],[2,1.74,17.32]],"ltp":2.08,"tv":72.2,"id":40096579}]}]}
{"op":"mcm","clk":"11836875086","pt":1723152695036,"mc":[{"id":"1.231583502","rc":[{"batb":[[0,2.1,10],[1,2.08,35.1],[2,1.8,2]],"ltp":2.08,"tv":72.2,"id":40096579}]}]}
{"op":"mcm","clk":"11836875230","pt":1723152698378,"mc":[{"id":"1.231583502","rc":[{"batb":[[0,2.08,35.1],[1,1.8,2],[2,1.74,17.32]],"ltp":2.08,"tv":72.2,"id":40096579}]}]}
{"op":"mcm","clk":"11836875324","pt":1723152700944,"mc":[{"id":"1.231583502","rc":[{"batb":[[0,2.1,10],[1,2.08,35.1],[2,1.8,2]],"ltp":2.08,"tv":72.2,"id":40096579}]}]}
{"op":"mcm","clk":"11836875450","pt":1723152704437,"mc":[{"id":"1.231583502","rc":[{"batb":[[0,2.08,35.1],[1,1.8,2],[2,1.74,17.32]],"ltp":2.08,"tv":72.2,"id":40096579}]}]}
{"op":"mcm","clk":"11836875534","pt":1723152706747,"mc":[{"id":"1.231583502","rc":[{"batb":[[0,2.1,10],[1,2.08,35.1],[2,1.8,2]],"ltp":2.08,"tv":72.2,"id":40096579}]}]}
{"op":"mcm","clk":"11836875652","pt":1723152710182,"mc":[{"id":"1.231583502","rc":[{"batb":[[0,2.08,35.1],[1,1.8,2],[2,1.74,17.32]],"ltp":2.08,"tv":72.2,"id":40096579}]}]}
{"op":"mcm","clk":"11836875873","pt":1723152715681,"mc":[{"id":"1.231583502","rc":[{"batb":[[0,2.1,10],[1,2.08,35.1],[2,1.8,2]],"ltp":2.08,"tv":72.2,"id":40096579}]}]}
{"op":"mcm","clk":"11836875995","pt":1723152718967,"mc":[{"id":"1.231583502","rc":[{"batb":[[0,2.08,35.1],[1,1.8,2],[2,1.74,17.32]],"ltp":2.08,"tv":72.2,"id":40096579}]}]}
{"op":"mcm","clk":"11836876134","pt":1723152722974,"mc":[{"id":"1.231583502","rc":[{"batb":[[0,2.1,10],[1,2.08,35.1],[2,1.8,2]],"ltp":2.08,"tv":72.2,"id":40096579}]}]}
{"op":"mcm","clk":"11836876249","pt":1723152726316,"mc":[{"id":"1.231583502","rc":[{"batb":[[0,2.08,35.1],[1,1.8,2],[2,1.74,17.32]],"ltp":2.08,"tv":72.2,"id":40096579}]}]}
{"op":"mcm","clk":"11836876373","pt":1723152729700,"mc":[{"id":"1.231583502","rc":[{"batb":[[0,2.1,10],[1,2.08,35.1],[2,1.8,2]],"ltp":2.08,"tv":72.2,"id":40096579}]}]}
{"op":"mcm","clk":"11836876532","pt":1723152733188,"mc":[{"id":"1.231583502","rc":[{"batb":[[0,2.08,35.1],[1,1.8,2],[2,1.74,17.32]],"ltp":2.08,"tv":72.2,"id":40096579}]}]}
{"op":"mcm","clk":"11836876648","pt":1723152736624,"mc":[{"id":"1.231583502","rc":[{"batb":[[0,2.1,10],[1,2.08,35.1],[2,1.8,2]],"ltp":2.08,"tv":72.2,"id":40096579}]}]}
{"op":"mcm","clk":"11836876766","pt":1723152740109,"mc":[{"id":"1.231583502","rc":[{"batb":[[0,2.08,35.1],[1,1.8,2],[2,1.74,17.32]],"ltp":2.08,"tv":72.2,"id":40096579}]}]}
{"op":"mcm","clk":"11836876838","pt":1723152742522,"mc":[{"id":"1.231583502","rc":[{"batb":[[0,2.1,10],[1,2.08,35.1],[2,1.8,2]],"ltp":2.08,"tv":72.2,"id":40096579}]}]}
{"op":"mcm","clk":"11836876942","pt":1723152745806,"mc":[{"id":"1.231583502","rc":[{"batb":[[0,2.08,35.1],[1,1.8,2],[2,1.74,17.32]],"ltp":2.08,"tv":72.2,"id":40096579}]}]}
{"op":"mcm","clk":"11836877033","pt":1723152748422,"mc":[{"id":"1.231583502","rc":[{"batb":[[0,2.1,10],[1,2.08,35.1],[2,1.8,2]],"ltp":2.08,"tv":72.2,"id":40096579}]}]}
{"op":"mcm","clk":"11836877176","pt":1723152751812,"mc":[{"id":"1.231583502","rc":[{"batb":[[0,2.08,35.1],[1,1.8,2],[2,1.74,17.32]],"ltp":2.08,"tv":72.2,"id":40096579}]}]}
{"op":"mcm","clk":"11836877294","pt":1723152754525,"mc":[{"id":"1.231583502","rc":[{"batb":[[0,2.1,10],[1,2.08,35.1],[2,1.8,2]],"ltp":2.08,"tv":72.2,"id":40096579}]}]}
{"op":"mcm","clk":"11836877402","pt":1723152757806,"mc":[{"id":"1.231583502","rc":[{"batb":[[0,2.08,35.1],[1,1.8,2],[2,1.74,17.32]],"ltp":2.08,"tv":72.2,"id":40096579}]}]}
{"op":"mcm","clk":"11836877474","pt":1723152760468,"mc":[{"id":"1.231583502","rc":[{"batb":[[0,2.1,10],[1,2.08,35.1],[2,1.8,2]],"ltp":2.08,"tv":72.2,"id":40096579}]}]}
{"op":"mcm","clk":"11836877587","pt":1723152763762,"mc":[{"id":"1.231583502","rc":[{"batb":[[0,2.08,35.1],[1,1.8,2],[2,1.74,17.32]],"ltp":2.08,"tv":72.2,"id":40096579}]}]}
{"op":"mcm","clk":"11836877728","pt":1723152767557,"mc":[{"id":"1.231583502","rc":[{"batb":[[0,2.1,10],[1,2.08,35.1],[2,1.8,2]],"ltp":2.08,"tv":72.2,"id":40096579}]}]}
{"op":"mcm","clk":"11836877930","pt":1723152770834,"mc":[{"id":"1.231583502","rc":[{"batb":[[0,2.08,35.1],[1,1.8,2],[2,1.74,17.32]],"ltp":2.08,"tv":72.2,"id":40096579}]}]}
{"op":"mcm","clk":"11836878056","pt":1723152773865,"mc":[{"id":"1.231583502","rc":[{"batb":[[0,2.1,10],[1,2.08,35.1],[2,1.8,2]],"ltp":2.08,"tv":72.2,"id":40096579}]}]}
{"op":"mcm","clk":"11836878217","pt":1723152777250,"mc":[{"id":"1.231583502","rc":[{"batb":[[0,2.08,35.1],[1,1.8,2],[2,1.74,17.32]],"ltp":2.08,"tv":72.2,"id":40096579}]}]}
{"op":"mcm","clk":"11836878457","pt":1723152783257,"mc":[{"id":"1.231583502","rc":[{"batb":[[0,2.1,10],[1,2.08,35.1],[2,1.8,2]],"ltp":2.08,"tv":72.2,"id":40096579}]}]}
{"op":"mcm","clk":"11836878593","pt":1723152786685,"mc":[{"id":"1.231583502","rc":[{"batb":[[0,2.08,35.1],[1,1.8,2],[2,1.74,17.32]],"ltp":2.08,"tv":72.2,"id":40096579}]}]}
{"op":"mcm","clk":"11836878823","pt":1723152792686,"mc":[{"id":"1.231583502","rc":[{"batb":[[0,2.1,10],[1,2.08,35.1],[2,1.8,2]],"ltp":2.08,"tv":72.2,"id":40096579}]}]}
{"op":"mcm","clk":"11836878958","pt":1723152796073,"mc":[{"id":"1.231583502","rc":[{"batb":[[0,2.08,35.1],[1,1.8,2],[2,1.74,17.32]],"ltp":2.08,"tv":72.2,"id":40096579}]}]}
{"op":"mcm","clk":"11836879035","pt":1723152798483,"mc":[{"id":"1.231583502","rc":[{"batb":[[0,2.1,10],[1,2.08,35.1],[2,1.8,2]],"ltp":2.08,"tv":72.2,"id":40096579}]}]}
{"op":"mcm","clk":"11836879166","pt":1723152801883,"mc":[{"id":"1.231583502","rc":[{"batb":[[0,2.08,35.1],[1,1.8,2],[2,1.74,17.32]],"ltp":2.08,"tv":72.2,"id":40096579}]}]}
{"op":"mcm","clk":"11836879330","pt":1723152805171,"mc":[{"id":"1.231583502","rc":[{"batb":[[0,2.1,10],[1,2.08,35.1],[2,1.8,2]],"ltp":2.08,"tv":72.2,"id":40096579}]}]}
{"op":"mcm","clk":"11836879539","pt":1723152808506,"mc":[{"id":"1.231583502","rc":[{"batb":[[0,2.08,35.1],[1,1.8,2],[2,1.74,17.32]],"ltp":2.08,"tv":72.2,"id":40096579}]}]}
{"op":"mcm","clk":"11836879683","pt":1723152810871,"mc":[{"id":"1.231583502","rc":[{"batb":[[0,2.1,10],[1,2.08,35.1],[2,1.8,2]],"ltp":2.08,"tv":72.2,"id":40096579}]}]}
{"op":"mcm","clk":"11836879909","pt":1723152814309,"mc":[{"id":"1.231583502","rc":[{"batb":[[0,2.08,35.1],[1,1.8,2],[2,1.74,17.32]],"ltp":2.08,"tv":72.2,"id":40096579}]}]}
{"op":"mcm","clk":"11836879999","pt":1723152816877,"mc":[{"id":"1.231583502","rc":[{"batb":[[0,2.1,10],[1,2.08,35.1],[2,1.8,2]],"ltp":2.08,"tv":72.2,"id":40096579}]}]}
{"op":"mcm","clk":"11836880123","pt":1723152820119,"mc":[{"id":"1.231583502","rc":[{"batb":[[0,2.08,35.1],[1,1.8,2],[2,1.74,17.32]],"ltp":2.08,"tv":72.2,"id":40096579}]}]}
{"op":"mcm","clk":"11836880283","pt":1723152823839,"mc":[{"id":"1.231583502","rc":[{"batb":[[0,2.1,10],[1,2.08,35.1],[2,1.8,2]],"ltp":2.08,"tv":72.2,"id":40096579}]}]}
{"op":"mcm","clk":"11836880441","pt":1723152827427,"mc":[{"id":"1.231583502","rc":[{"batb":[[0,2.08,35.1],[1,1.8,2],[2,1.74,17.32]],"ltp":2.08,"tv":72.2,"id":40096579}]}]}
{"op":"mcm","clk":"11836880516","pt":1723152829632,"mc":[{"id":"1.231583502","rc":[{"batb":[[0,2.1,10],[1,2.08,35.1],[2,1.8,2]],"ltp":2.08,"tv":72.2,"id":40096579}]}]}
{"op":"mcm","clk":"11836880625","pt":1723152833013,"mc":[{"id":"1.231583502","rc":[{"batb":[[0,2.08,35.1],[1,1.8,2],[2,1.74,17.32]],"ltp":2.08,"tv":72.2,"id":40096579}]}]}
{"op":"mcm","clk":"11836880703","pt":1723152835537,"mc":[{"id":"1.231583502","rc":[{"batb":[[0,2.1,10],[1,2.08,35.1],[2,1.8,2]],"ltp":2.08,"tv":72.2,"id":40096579}]}]}
{"op":"mcm","clk":"11836880835","pt":1723152838819,"mc":[{"id":"1.231583502","rc":[{"batb":[[0,2.08,35.1],[1,1.8,2],[2,1.74,17.32]],"ltp":2.08,"tv":72.2,"id":40096579}]}]}
{"op":"mcm","clk":"11836880924","pt":1723152841330,"mc":[{"id":"1.231583502","rc":[{"batb":[[0,2.1,10],[1,2.08,35.1],[2,1.8,2]],"ltp":2.08,"tv":72.2,"id":40096579}]}]}
{"op":"mcm","clk":"11836881061","pt":1723152844714,"mc":[{"id":"1.231583502","rc":[{"batb":[[0,2.08,35.1],[1,1.8,2],[2,1.74,17.32]],"ltp":2.08,"tv":72.2,"id":40096579}]}]}
{"op":"mcm","clk":"11836881213","pt":1723152848452,"mc":[{"id":"1.231583502","rc":[{"batb":[[0,2.1,10],[1,2.08,35.1],[2,1.8,2]],"ltp":2.08,"tv":72.2,"id":40096579}]}]}
{"op":"mcm","clk":"11836881343","pt":1723152851843,"mc":[{"id":"1.231583502","rc":[{"batb":[[0,2.08,35.1],[1,1.8,2],[2,1.74,17.32]],"ltp":2.08,"tv":72.2,"id":40096579}]}]}
{"op":"mcm","clk":"11836881482","pt":1723152855345,"mc":[{"id":"1.231583502","rc":[{"batb":[[0,2.1,10],[1,2.08,35.1],[2,1.8,2]],"ltp":2.08,"tv":72.2,"id":40096579}]}]}
{"op":"mcm","clk":"11836881633","pt":1723152858642,"mc":[{"id":"1.231583502","rc":[{"batb":[[0,2.08,35.1],[1,1.8,2],[2,1.74,17.32]],"ltp":2.08,"tv":72.2,"id":40096579}]}]}
{"op":"mcm","clk":"11836881730","pt":1723152861565,"mc":[{"id":"1.231583502","rc":[{"batb":[[0,2.1,10],[1,2.08,35.1],[2,1.8,2]],"ltp":2.08,"tv":72.2,"id":40096579}]}]}
{"op":"mcm","clk":"11836881827","pt":1723152864952,"mc":[{"id":"1.231583502","rc":[{"batb":[[0,2.08,35.1],[1,1.8,2],[2,1.74,17.32]],"ltp":2.08,"tv":72.2,"id":40096579}]}]}
{"op":"mcm","clk":"11836882018","pt":1723152869481,"mc":[{"id":"1.231583502","rc":[{"batb":[[0,2.1,10],[1,2.08,35.1],[2,1.8,2]],"ltp":2.08,"tv":72.2,"id":40096579}]}]}
{"op":"mcm","clk":"11836882143","pt":1723152872977,"mc":[{"id":"1.231583502","rc":[{"batb":[[0,2.08,35.1],[1,1.8,2],[2,1.74,17.32]],"ltp":2.08,"tv":72.2,"id":40096579}]}]}
{"op":"mcm","clk":"11836882285","pt":1723152876468,"mc":[{"id":"1.231583502","rc":[{"batb":[[0,2.1,10],[1,2.08,35.1],[2,1.8,2]],"ltp":2.08,"tv":72.2,"id":40096579}]}]}
{"op":"mcm","clk":"11836882436","pt":1723152879761,"mc":[{"id":"1.231583502","rc":[{"batb":[[0,2.08,35.1],[1,1.8,2],[2,1.74,17.32]],"ltp":2.08,"tv":72.2,"id":40096579}]}]}
{"op":"mcm","clk":"11836882681","pt":1723152884696,"mc":[{"id":"1.231583502","rc":[{"batb":[[0,2.1,10],[1,2.08,35.1],[2,1.8,2]],"ltp":2.08,"tv":72.2,"id":40096579}]}]}
{"op":"mcm","clk":"11836882806","pt":1723152888140,"mc":[{"id":"1.231583502","rc":[{"batb":[[0,2.08,35.1],[1,1.8,2],[2,1.74,17.32]],"ltp":2.08,"tv":72.2,"id":40096579}]}]}
{"op":"mcm","clk":"11836882892","pt":1723152890450,"mc":[{"id":"1.231583502","rc":[{"batb":[[0,2.1,10],[1,2.08,35.1],[2,1.8,2]],"ltp":2.08,"tv":72.2,"id":40096579}]}]}
{"op":"mcm","clk":"11836883008","pt":1723152893737,"mc":[{"id":"1.231583502","rc":[{"batb":[[0,2.08,35.1],[1,1.8,2],[2,1.74,17.32]],"ltp":2.08,"tv":72.2,"id":40096579}]}]}
{"op":"mcm","clk":"11836883126","pt":1723152896232,"mc":[{"id":"1.231583502","rc":[{"batb":[[0,2.1,10],[1,2.08,35.1],[2,1.8,2]],"ltp":2.08,"tv":72.2,"id":40096579}]}]}
{"op":"mcm","clk":"11836883252","pt":1723152899513,"mc":[{"id":"1.231583502","rc":[{"batb":[[0,2.08,35.1],[1,1.8,2],[2,1.74,17.32]],"ltp":2.08,"tv":72.2,"id":40096579}]}]}
{"op":"mcm","clk":"11836883432","pt":1723152904849,"mc":[{"id":"1.231583502","rc":[{"batb":[[0,2.1,10],[1,2.08,35.1],[2,1.8,2]],"ltp":2.08,"tv":72.2,"id":40096579}]}]}
{"op":"mcm","clk":"11836883548","pt":1723152908129,"mc":[{"id":"1.231583502","rc":[{"batb":[[0,2.08,35.1],[1,1.8,2],[2,1.74,17.32]],"ltp":2.08,"tv":72.2,"id":40096579}]}]}
{"op":"mcm","clk":"11836883674","pt":1723152910867,"mc":[{"id":"1.231583502","rc":[{"batb":[[0,2.1,10],[1,2.08,35.1],[2,1.8,2]],"ltp":2.08,"tv":72.2,"id":40096579}]}]}
{"op":"mcm","clk":"11836883834","pt":1723152914260,"mc":[{"id":"1.231583502","rc":[{"batb":[[0,2.08,35.1],[1,1.8,2],[2,1.74,17.32]],"ltp":2.08,"tv":72.2,"id":40096579}]}]}
{"op":"mcm","clk":"11836883930","pt":1723152916877,"mc":[{"id":"1.231583502","rc":[{"batb":[[0,2.1,10],[1,2.08,35.1],[2,1.8,2]],"ltp":2.08,"tv":72.2,"id":40096579}]}]}
{"op":"mcm","clk":"11836883952","pt":1723152917236,"mc":[{"id":"1.231583502","rc":[{"trd":[[2.1,9.64]],"batb":[[0,2.08,35.46],[1,1.8,2],[2,1.74,17.32]],"ltp":2.1,"tv":81.84,"id":40096579},{"trd":[[1.91,10.6]],"ltp":1.91,"tv":16.44,"id":40096580}],"tv":98.29}]}
{"op":"mcm","clk":"11836884081","pt":1723152920163,"mc":[{"id":"1.231583502","rc":[{"batb":[[0,2.08,35.1]],"ltp":2.1,"tv":81.84,"id":40096579}]}]}
{"op":"mcm","clk":"11836884188","pt":1723152922470,"mc":[{"id":"1.231583502","rc":[{"batb":[[0,2.1,10],[1,2.08,35.1],[2,1.8,2]],"ltp":2.1,"tv":81.84,"id":40096579}]}]}
{"op":"mcm","clk":"11836884329","pt":1723152925858,"mc":[{"id":"1.231583502","rc":[{"batb":[[0,2.08,35.1],[1,1.8,2],[2,1.74,17.32]],"ltp":2.1,"tv":81.84,"id":40096579}]}]}
{"op":"mcm","clk":"11836884483","pt":1723152929656,"mc":[{"id":"1.231583502","rc":[{"batb":[[0,2.1,10],[1,2.08,35.1],[2,1.8,2]],"ltp":2.1,"tv":81.84,"id":40096579}]}]}
{"op":"mcm","clk":"11836884592","pt":1723152933042,"mc":[{"id":"1.231583502","rc":[{"batb":[[0,2.08,35.1],[1,1.8,2],[2,1.74,17.32]],"ltp":2.1,"tv":81.84,"id":40096579}]}]}
{"op":"mcm","clk":"11836884686","pt":1723152935653,"mc":[{"id":"1.231583502","rc":[{"batb":[[0,2.1,10],[1,2.08,35.1],[2,1.8,2]],"ltp":2.1,"tv":81.84,"id":40096579}]}]}
{"op":"mcm","clk":"11836884792","pt":1723152938882,"mc":[{"id":"1.231583502","rc":[{"batb":[[0,2.08,35.1],[1,1.8,2],[2,1.74,17.32]],"ltp":2.1,"tv":81.84,"id":40096579}]}]}
{"op":"mcm","clk":"11836884895","pt":1723152941393,"mc":[{"id":"1.231583502","rc":[{"batb":[[0,2.1,10],[1,2.08,35.1],[2,1.8,2]],"ltp":2.1,"tv":81.84,"id":40096579}]}]}
{"op":"mcm","clk":"11836885030","pt":1723152944774,"mc":[{"id":"1.231583502","rc":[{"batb":[[0,2.08,35.1],[1,1.8,2],[2,1.74,17.32]],"ltp":2.1,"tv":81.84,"id":40096579}]}]}
{"op":"mcm","clk":"11836885201","pt":1723152949193,"mc":[{"id":"1.231583502","rc":[{"batb":[[0,2.1,10],[1,2.08,35.1],[2,1.8,2]],"ltp":2.1,"tv":81.84,"id":40096579}]}]}
{"op":"mcm","clk":"11836885353","pt":1723152952476,"mc":[{"id":"1.231583502","rc":[{"batb":[[0,2.08,35.1],[1,1.8,2],[2,1.74,17.32]],"ltp":2.1,"tv":81.84,"id":40096579},{"batb":[[0,1.83,35],[1,1.81,210.93],[2,1.8,224.6]],"ltp":1.91,"tv":16.44,"id":40096580}]}]}
{"op":"mcm","clk":"11836885386","pt":1723152953195,"mc":[{"id":"1.231583502","rc":[{"batb":[[1,1.81,200]],"ltp":1.91,"tv":16.44,"id":40096580}]}]}
{"op":"mcm","clk":"11837125233","pt":1723158775153,"mc":[{"id":"1.231583502","rc":[{"trd":[[1.28,3.14],[1.3,3.14]],"ltp":2.1,"tv":81.85,"id":40096579},{"trd":[[1.3,4.71]],"ltp":1.91,"tv":16.45,"id":40096580}],"tv":98.3}]}
{"op":"mcm","clk":"11837359269","pt":1723164175162,"mc":[{"id":"1.231583502","rc":[{"trd":[[1.3,4.71]],"ltp":1.91,"tv":16.44,"id":40096580}],"tv":98.3}]}
{"op":"mcm","clk":"11837583806","pt":1723169575176,"mc":[{"id":"1.231583502","rc":[{"trd":[[1.28,3.14],[1.3,3.14]],"ltp":2.1,"tv":81.84,"id":40096579},{"trd":[[1.3,4.7]],"ltp":1.91,"tv":16.44,"id":40096580}],"tv":98.29}]}
{"op":"mcm","clk":"11837805839","pt":1723174975194,"mc":[{"id":"1.231583502","rc":[{"trd":[[1.28,3.14],[1.3,3.14]],"ltp":2.1,"tv":81.84,"id":40096579},{"trd":[[1.3,4.7]],"ltp":1.91,"tv":16.44,"id":40096580}],"tv":98.29}]}
{"op":"mcm","clk":"11838036881","pt":1723180375191,"mc":[{"id":"1.231583502","rc":[{"trd":[[1.28,3.14],[1.3,3.14]],"ltp":2.1,"tv":81.84,"id":40096579},{"trd":[[1.3,4.71]],"ltp":1.91,"tv":16.44,"id":40096580}],"tv":98.29}]}
{"op":"mcm","clk":"11838271928","pt":1723185775238,"mc":[{"id":"1.231583502","rc":[{"trd":[[1.28,3.14],[1.3,3.14]],"ltp":2.1,"tv":81.84,"id":40096579},{"trd":[[1.3,4.7]],"ltp":1.91,"tv":16.44,"id":40096580}],"tv":98.29}]}
{"op":"mcm","clk":"11838281121","pt":1723185964948,"mc":[{"id":"1.231583502","rc":[{"batb":[[0,1.83,257]],"ltp":1.91,"tv":16.44,"id":40096580}]}]}
{"op":"mcm","clk":"11838317142","pt":1723186704263,"mc":[{"id":"1.231583502","rc":[{"batl":[[0,2.2,10.4]],"ltp":2.1,"tv":81.84,"id":40096579},{"batb":[[0,1.84,12.62],[1,1.83,257],[2,1.81,200]],"ltp":1.91,"tv":16.44,"id":40096580}]}]}
{"op":"mcm","clk":"11838321759","pt":1723186803175,"mc":[{"id":"1.231583502","rc":[{"batb":[[0,2.1,10],[1,2.08,35.1],[2,1.8,2]],"ltp":2.1,"tv":81.84,"id":40096579}]}]}
{"op":"mcm","clk":"11838322061","pt":1723186807348,"mc":[{"id":"1.231583502","rc":[{"trd":[[1.28,3.13],[1.3,3.13],[2.08,1.93]],"batb":[[0,2.08,35.1],[1,1.8,2],[2,1.74,17.32]],"batl":[[0,2.2,10.4]],"ltp":2.1,"tv":81.83,"id":40096579},{"trd":[[1.3,4.7]],"batb":[[0,1.84,12.61]],"ltp":1.91,"tv":16.43,"id":40096580}],"tv":98.27}]}
{"op":"mcm","clk":"11838322228","pt":1723186809670,"mc":[{"id":"1.231583502","rc":[{"batb":[[0,2.1,10],[1,2.08,35.1],[2,1.8,2]],"ltp":2.1,"tv":81.83,"id":40096579}]}]}
{"op":"mcm","clk":"11838322436","pt":1723186813285,"mc":[{"id":"1.231583502","rc":[{"batb":[[0,2.08,35.1],[1,1.8,2],[2,1.74,17.32]],"ltp":2.1,"tv":81.83,"id":40096579}]}]}
{"op":"mcm","clk":"11838322613","pt":1723186816058,"mc":[{"id":"1.231583502","rc":[{"batb":[[0,2.1,10],[1,2.08,35.1],[2,1.8,2]],"ltp":2.1,"tv":81.83,"id":40096579}]}]}
{"op":"mcm","clk":"11838322837","pt":1723186819970,"mc":[{"id":"1.231583502","rc":[{"batb":[[0,2.08,35.1],[1,1.8,2],[2,1.74,17.32]],"ltp":2.1,"tv":81.83,"id":40096579}]}]}
{"op":"mcm","clk":"11838323085","pt":1723186824079,"mc":[{"id":"1.231583502","rc":[{"batb":[[0,2.1,10],[1,2.08,35.1],[2,1.8,2]],"ltp":2.1,"tv":81.83,"id":40096579}]}]}
{"op":"mcm","clk":"11838323249","pt":1723186827578,"mc":[{"id":"1.231583502","rc":[{"batb":[[0,2.08,35.1],[1,1.8,2],[2,1.74,17.32]],"ltp":2.1,"tv":81.83,"id":40096579}]}]}
{"op":"mcm","clk":"11838323385","pt":1723186829898,"mc":[{"id":"1.231583502","rc":[{"batb":[[0,2.1,10],[1,2.08,35.1],[2,1.8,2]],"ltp":2.1,"tv":81.83,"id":40096579}]}]}
{"op":"mcm","clk":"11838323604","pt":1723186833083,"mc":[{"id":"1.231583502","rc":[{"batb":[[0,2.08,35.1],[1,1.8,2],[2,1.74,17.32]],"ltp":2.1,"tv":81.83,"id":40096579}]}]}
{"op":"mcm","clk":"11838323782","pt":1723186836903,"mc":[{"id":"1.231583502","rc":[{"batb":[[0,2.1,10],[1,2.08,35.1],[2,1.8,2]],"ltp":2.1,"tv":81.83,"id":40096579}]}]}
{"op":"mcm","clk":"11838323966","pt":1723186840300,"mc":[{"id":"1.231583502","rc":[{"batb":[[0,2.08,35.1],[1,1.8,2],[2,1.74,17.32]],"ltp":2.1,"tv":81.83,"id":40096579}]}]}
{"op":"mcm","clk":"11838324088","pt":1723186842480,"mc":[{"id":"1.231583502","rc":[{"batb":[[0,2.1,10],[1,2.08,35.1],[2,1.8,2]],"ltp":2.1,"tv":81.83,"id":40096579}]}]}
{"op":"mcm","clk":"11838324264","pt":1723186845884,"mc":[{"id":"1.231583502","rc":[{"batb":[[0,2.08,35.1],[1,1.8,2],[2,1.74,17.32]],"ltp":2.1,"tv":81.83,"id":40096579}]}]}
{"op":"mcm","clk":"11838324435","pt":1723186850091,"mc":[{"id":"1.231583502","rc":[{"batb":[[0,2.1,10],[1,2.08,35.1],[2,1.8,2]],"ltp":2.1,"tv":81.83,"id":40096579}]}]}
{"op":"mcm","clk":"11838324652","pt":1723186853682,"mc":[{"id":"1.231583502","rc":[{"batb":[[0,2.08,35.1],[1,1.8,2],[2,1.74,17.32]],"ltp":2.1,"tv":81.83,"id":40096579}]}]}
{"op":"mcm","clk":"11838324814","pt":1723186857011,"mc":[{"id":"1.231583502","rc":[{"batb":[[0,2.1,10],[1,2.08,35.1],[2,1.8,2]],"ltp":2.1,"tv":81.83,"id":40096579}]}]}
{"op":"mcm","clk":"11838324987","pt":1723186860406,"mc":[{"id":"1.231583502","rc":[{"batb":[[0,2.08,35.1],[1,1.8,2],[2,1.74,17.32]],"ltp":2.1,"tv":81.83,"id":40096579}]}]}
{"op":"mcm","clk":"11838325146","pt":1723186862816,"mc":[{"id":"1.231583502","rc":[{"batb":[[0,2.1,10],[1,2.08,35.1],[2,1.8,2]],"ltp":2.1,"tv":81.83,"id":40096579}]}]}
{"op":"mcm","clk":"11838325335","pt":1723186866010,"mc":[{"id":"1.231583502","rc":[{"batb":[[0,2.08,35.1],[1,1.8,2],[2,1.74,17.32]],"ltp":2.1,"tv":81.83,"id":40096579}]}]}
{"op":"mcm","clk":"11838325482","pt":1723186868320,"mc":[{"id":"1.231583502","rc":[{"batb":[[0,2.1,10],[1,2.08,35.1],[2,1.8,2]],"ltp":2.1,"tv":81.83,"id":40096579}]}]}
{"op":"mcm","clk":"11838325701","pt":1723186871820,"mc":[{"id":"1.231583502","rc":[{"batb":[[0,2.08,35.1],[1,1.8,2],[2,1.74,17.32]],"ltp":2.1,"tv":81.83,"id":40096579}]}]}
{"op":"mcm","clk":"11838325855","pt":1723186875050,"mc":[{"id":"1.231583502","rc":[{"batb":[[0,2.1,10],[1,2.08,35.1],[2,1.8,2]],"ltp":2.1,"tv":81.83,"id":40096579}]}]}
{"op":"mcm","clk":"11838326011","pt":1723186878542,"mc":[{"id":"1.231583502","rc":[{"batb":[[0,2.08,35.1],[1,1.8,2],[2,1.74,17.32]],"ltp":2.1,"tv":81.83,"id":40096579}]}]}
{"op":"mcm","clk":"11838326139","pt":1723186881021,"mc":[{"id":"1.231583502","rc":[{"batb":[[0,2.1,10],[1,2.08,35.1],[2,1.8,2]],"ltp":2.1,"tv":81.83,"id":40096579}]}]}
{"op":"mcm","clk":"11838326339","pt":1723186884252,"mc":[{"id":"1.231583502","rc":[{"batb":[[0,2.08,35.1],[1,1.8,2],[2,1.74,17.32]],"ltp":2.1,"tv":81.83,"id":40096579}]}]}
{"op":"mcm","clk":"11838326527","pt":1723186887439,"mc":[{"id":"1.231583502","rc":[{"batb":[[0,2.1,10],[1,2.08,35.1],[2,1.8,2]],"ltp":2.1,"tv":81.83,"id":40096579}]}]}
{"op":"mcm","clk":"11838326775","pt":1723186891247,"mc":[{"id":"1.231583502","rc":[{"batb":[[0,2.08,35.1],[1,1.8,2],[2,1.74,17.32]],"ltp":2.1,"tv":81.83,"id":40096579}]}]}
{"op":"mcm","clk":"11838326892","pt":1723186893556,"mc":[{"id":"1.231583502","rc":[{"batb":[[0,2.1,10],[1,2.08,35.1],[2,1.8,2]],"ltp":2.1,"tv":81.83,"id":40096579}]}]}
{"op":"mcm","clk":"11838327023","pt":1723186896950,"mc":[{"id":"1.231583502","rc":[{"batb":[[0,2.08,35.1],[1,1.8,2],[2,1.74,17.32]],"ltp":2.1,"tv":81.83,"id":40096579}]}]}
{"op":"mcm","clk":"11838327205","pt":1723186900563,"mc":[{"id":"1.231583502","rc":[{"batb":[[0,2.1,10],[1,2.08,35.1],[2,1.8,2]],"ltp":2.1,"tv":81.83,"id":40096579}]}]}
{"op":"mcm","clk":"11838327431","pt":1723186904278,"mc":[{"id":"1.231583502","rc":[{"batb":[[0,2.08,35.1],[1,1.8,2],[2,1.74,17.32]],"ltp":2.1,"tv":81.83,"id":40096579}]}]}
{"op":"mcm","clk":"11838327565","pt":1723186907044,"mc":[{"id":"1.231583502","rc":[{"batb":[[0,2.1,10],[1,2.08,35.1],[2,1.8,2]],"ltp":2.1,"tv":81.83,"id":40096579}]}]}
{"op":"mcm","clk":"11838327724","pt":1723186910550,"mc":[{"id":"1.231583502","rc":[{"batb":[[0,2.08,35.1],[1,1.8,2],[2,1.74,17.32]],"ltp":2.1,"tv":81.83,"id":40096579}]}]}
{"op":"mcm","clk":"11838327854","pt":1723186913077,"mc":[{"id":"1.231583502","rc":[{"batb":[[0,2.1,10],[1,2.08,35.1],[2,1.8,2]],"ltp":2.1,"tv":81.83,"id":40096579}]}]}
{"op":"mcm","clk":"11838328001","pt":1723186916360,"mc":[{"id":"1.231583502","rc":[{"batb":[[0,2.08,35.1],[1,1.8,2],[2,1.74,17.32]],"ltp":2.1,"tv":81.83,"id":40096579}]}]}
{"op":"mcm","clk":"11838328134","pt":1723186919288,"mc":[{"id":"1.231583502","rc":[{"batb":[[0,2.1,10],[1,2.08,35.1],[2,1.8,2]],"ltp":2.1,"tv":81.83,"id":40096579}]}]}
{"op":"mcm","clk":"11838328337","pt":1723186922589,"mc":[{"id":"1.231583502","rc":[{"batb":[[0,2.08,35.1],[1,1.8,2],[2,1.74,17.32]],"ltp":2.1,"tv":81.83,"id":40096579}]}]}
{"op":"mcm","clk":"11838328488","pt":1723186925364,"mc":[{"id":"1.231583502","rc":[{"batb":[[0,2.1,10],[1,2.08,35.1],[2,1.8,2]],"ltp":2.1,"tv":81.83,"id":40096579}]}]}
{"op":"mcm","clk":"11838328673","pt":1723186928915,"mc":[{"id":"1.231583502","rc":[{"batb":[[0,2.08,35.1],[1,1.8,2],[2,1.74,17.32]],"ltp":2.1,"tv":81.83,"id":40096579}]}]}
{"op":"mcm","clk":"11838328777","pt":1723186931282,"mc":[{"id":"1.231583502","rc":[{"batb":[[0,2.1,10],[1,2.08,35.1],[2,1.8,2]],"ltp":2.1,"tv":81.83,"id":40096579}]}]}
{"op":"mcm","clk":"11838328987","pt":1723186934514,"mc":[{"id":"1.231583502","rc":[{"batb":[[0,2.08,35.1],[1,1.8,2],[2,1.74,17.32]],"ltp":2.1,"tv":81.83,"id":40096579}]}]}
{"op":"mcm","clk":"11838329144","pt":1723186937089,"mc":[{"id":"1.231583502","rc":[{"batb":[[0,2.1,10],[1,2.08,35.1],[2,1.8,2]],"ltp":2.1,"tv":81.83,"id":40096579}]}]}
{"op":"mcm","clk":"11838329341","pt":1723186940998,"mc":[{"id":"1.231583502","rc":[{"batb":[[0,2.08,35.1],[1,1.8,2],[2,1.74,17.32]],"ltp":2.1,"tv":81.83,"id":40096579}]}]}
{"op":"mcm","clk":"11838329487","pt":1723186943319,"mc":[{"id":"1.231583502","rc":[{"batb":[[0,2.1,10],[1,2.08,35.1],[2,1.8,2]],"ltp":2.1,"tv":81.83,"id":40096579}]}]}
{"op":"mcm","clk":"11838329654","pt":1723186946612,"mc":[{"id":"1.231583502","rc":[{"batb":[[0,2.08,35.1],[1,1.8,2],[2,1.74,17.32]],"ltp":2.1,"tv":81.83,"id":40096579}]}]}
{"op":"mcm","clk":"11838329803","pt":1723186949036,"mc":[{"id":"1.231583502","rc":[{"batb":[[0,2.1,10],[1,2.08,35.1],[2,1.8,2]],"ltp":2.1,"tv":81.83,"id":40096579}]}]}
{"op":"mcm","clk":"11838329977","pt":1723186952201,"mc":[{"id":"1.231583502","rc":[{"batb":[[0,2.08,35.1],[1,1.8,2],[2,1.74,17.32]],"ltp":2.1,"tv":81.83,"id":40096579}]}]}
{"op":"mcm","clk":"11838330139","pt":1723186954930,"mc":[{"id":"1.231583502","rc":[{"batb":[[0,2.1,10],[1,2.08,35.1],[2,1.8,2]],"ltp":2.1,"tv":81.83,"id":40096579}]}]}
{"op":"mcm","clk":"11838330308","pt":1723186958221,"mc":[{"id":"1.231583502","rc":[{"batb":[[0,2.08,35.1],[1,1.8,2],[2,1.74,17.32]],"ltp":2.1,"tv":81.83,"id":40096579}]}]}
{"op":"mcm","clk":"11838330462","pt":1723186960946,"mc":[{"id":"1.231583502","rc":[{"batb":[[0,2.1,10],[1,2.08,35.1],[2,1.8,2]],"ltp":2.1,"tv":81.83,"id":40096579}]}]}
{"op":"mcm","clk":"11838330683","pt":1723186964150,"mc":[{"id":"1.231583502","rc":[{"batb":[[0,2.08,35.1],[1,1.8,2],[2,1.74,17.32]],"ltp":2.1,"tv":81.83,"id":40096579}]}]}
{"op":"mcm","clk":"11838330815","pt":1723186966747,"mc":[{"id":"1.231583502","rc":[{"batb":[[0,2.1,10],[1,2.08,35.1],[2,1.8,2]],"ltp":2.1,"tv":81.83,"id":40096579}]}]}
{"op":"mcm","clk":"11838330989","pt":1723186970352,"mc":[{"id":"1.231583502","rc":[{"batb":[[0,2.08,35.1],[1,1.8,2],[2,1.74,17.32]],"ltp":2.1,"tv":81.83,"id":40096579}]}]}
{"op":"mcm","clk":"11838331116","pt":1723186972860,"mc":[{"id":"1.231583502","rc":[{"batb":[[0,2.1,10],[1,2.08,35.1],[2,1.8,2]],"ltp":2.1,"tv":81.83,"id":40096579}]}]}
{"op":"mcm","clk":"11838331256","pt":1723186976143,"mc":[{"id":"1.231583502","rc":[{"batb":[[0,2.08,35.1],[1,1.8,2],[2,1.74,17.32]],"ltp":2.1,"tv":81.83,"id":40096579}]}]}
{"op":"mcm","clk":"11838331371","pt":1723186978663,"mc":[{"id":"1.231583502","rc":[{"batb":[[0,2.1,10],[1,2.08,35.1],[2,1.8,2]],"ltp":2.1,"tv":81.83,"id":40096579}]}]}
{"op":"mcm","clk":"11838331523","pt":1723186981957,"mc":[{"id":"1.231583502","rc":[{"batb":[[0,2.08,35.1],[1,1.8,2],[2,1.74,17.32]],"ltp":2.1,"tv":81.83,"id":40096579}]}]}
{"op":"mcm","clk":"11838331680","pt":1723186984571,"mc":[{"id":"1.231583502","rc":[{"batb":[[0,2.1,10],[1,2.08,35.1],[2,1.8,2]],"ltp":2.1,"tv":81.83,"id":40096579}]}]}
{"op":"mcm","clk":"11838331887","pt":1723186988274,"mc":[{"id":"1.231583502","rc":[{"batb":[[0,2.08,35.1],[1,1.8,2],[2,1.74,17.32]],"ltp":2.1,"tv":81.83,"id":40096579}]}]}
{"op":"mcm","clk":"11838332022","pt":1723186990849,"mc":[{"id":"1.231583502","rc":[{"batb":[[0,2.1,10],[1,2.08,35.1],[2,1.8,2]],"ltp":2.1,"tv":81.83,"id":40096579}]}]}
{"op":"mcm","clk":"11838332238","pt":1723186994493,"mc":[{"id":"1.231583502","rc":[{"batb":[[0,2.08,35.1],[1,1.8,2],[2,1.74,17.32]],"ltp":2.1,"tv":81.83,"id":40096579}]}]}
{"op":"mcm","clk":"11838332340","pt":1723186996761,"mc":[{"id":"1.231583502","rc":[{"batb":[[0,2.1,10],[1,2.08,35.1],[2,1.8,2]],"ltp":2.1,"tv":81.83,"id":40096579}]}]}
{"op":"mcm","clk":"11838332533","pt":1723187000763,"mc":[{"id":"1.231583502","rc":[{"batb":[[0,2.08,35.1],[1,1.8,2],[2,1.74,17.32]],"ltp":2.1,"tv":81.83,"id":40096579}]}]}
{"op":"mcm","clk":"11838332742","pt":1723187004000,"mc":[{"id":"1.231583502","rc":[{"batb":[[0,2.1,10],[1,2.08,35.1],[2,1.8,2]],"ltp":2.1,"tv":81.83,"id":40096579}]}]}
{"op":"mcm","clk":"11838332916","pt":1723187007288,"mc":[{"id":"1.231583502","rc":[{"batb":[[0,2.08,35.1],[1,1.8,2],[2,1.74,17.32]],"ltp":2.1,"tv":81.83,"id":40096579}]}]}
{"op":"mcm","clk":"11838333050","pt":1723187009897,"mc":[{"id":"1.231583502","rc":[{"batb":[[0,2.1,10],[1,2.08,35.1],[2,1.8,2]],"ltp":2.1,"tv":81.83,"id":40096579}]}]}
{"op":"mcm","clk":"11838333222","pt":1723187013325,"mc":[{"id":"1.231583502","rc":[{"batb":[[0,2.08,35.1],[1,1.8,2],[2,1.74,17.32]],"ltp":2.1,"tv":81.83,"id":40096579}]}]}
{"op":"mcm","clk":"11838333425","pt":1723187016904,"mc":[{"id":"1.231583502","rc":[{"batb":[[0,2.1,10],[1,2.08,35.1],[2,1.8,2]],"ltp":2.1,"tv":81.83,"id":40096579}]}]}
{"op":"mcm","clk":"11838333615","pt":1723187020301,"mc":[{"id":"1.231583502","rc":[{"batb":[[0,2.08,35.1],[1,1.8,2],[2,1.74,17.32]],"ltp":2.1,"tv":81.83,"id":40096579}]}]}
{"op":"mcm","clk":"11838333739","pt":1723187022922,"mc":[{"id":"1.231583502","rc":[{"batb":[[0,2.1,10],[1,2.08,35.1],[2,1.8,2]],"ltp":2.1,"tv":81.83,"id":40096579}]}]}
{"op":"mcm","clk":"11838333916","pt":1723187026219,"mc":[{"id":"1.231583502","rc":[{"batb":[[0,2.08,35.1],[1,1.8,2],[2,1.74,17.32]],"ltp":2.1,"tv":81.83,"id":40096579}]}]}
{"op":"mcm","clk":"11838334056","pt":1723187028832,"mc":[{"id":"1.231583502","rc":[{"batb":[[0,2.1,10],[1,2.08,35.1],[2,1.8,2]],"ltp":2.1,"tv":81.83,"id":40096579}]}]}
{"op":"mcm","clk":"11838334284","pt":1723187032536,"mc":[{"id":"1.231583502","rc":[{"batb":[[0,2.08,35.1],[1,1.8,2],[2,1.74,17.32]],"ltp":2.1,"tv":81.83,"id":40096579}]}]}
{"op":"mcm","clk":"11838334421","pt":1723187034945,"mc":[{"id":"1.231583502","rc":[{"batb":[[0,2.1,10],[1,2.08,35.1],[2,1.8,2]],"ltp":2.1,"tv":81.83,"id":40096579}]}]}
{"op":"mcm","clk":"11838334607","pt":1723187038347,"mc":[{"id":"1.231583502","rc":[{"batb":[[0,2.08,35.1],[1,1.8,2],[2,1.74,17.32]],"ltp":2.1,"tv":81.83,"id":40096579}]}]}
{"op":"mcm","clk":"11838334776","pt":1723187041440,"mc":[{"id":"1.231583502","rc":[{"batb":[[0,2.1,10],[1,2.08,35.1],[2,1.8,2]],"ltp":2.1,"tv":81.83,"id":40096579}]}]}
{"op":"mcm","clk":"11838335020","pt":1723187044941,"mc":[{"id":"1.231583502","rc":[{"batb":[[0,2.08,35.1],[1,1.8,2],[2,1.74,17.32]],"ltp":2.1,"tv":81.83,"id":40096579}]}]}
{"op":"mcm","clk":"11838335172","pt":1723187047463,"mc":[{"id":"1.231583502","rc":[{"batb":[[0,2.1,10],[1,2.08,35.1],[2,1.8,2]],"ltp":2.1,"tv":81.83,"id":40096579}]}]}
{"op":"mcm","clk":"11838335346","pt":1723187050756,"mc":[{"id":"1.231583502","rc":[{"batb":[[0,2.08,35.1],[1,1.8,2],[2,1.74,17.32]],"ltp":2.1,"tv":81.83,"id":40096579}]}]}
{"op":"mcm","clk":"11838335600","pt":1723187055690,"mc":[{"id":"1.231583502","rc":[{"batb":[[0,2.1,10],[1,2.08,35.1],[2,1.8,2]],"ltp":2.1,"tv":81.83,"id":40096579}]}]}
{"op":"mcm","clk":"11838335798","pt":1723187059156,"mc":[{"id":"1.231583502","rc":[{"batb":[[0,2.08,35.1],[1,1.8,2],[2,1.74,17.32]],"ltp":2.1,"tv":81.83,"id":40096579}]}]}
{"op":"mcm","clk":"11838335981","pt":1723187062192,"mc":[{"id":"1.231583502","rc":[{"batb":[[0,2.1,10],[1,2.08,35.1],[2,1.8,2]],"ltp":2.1,"tv":81.83,"id":40096579}]}]}
{"op":"mcm","clk":"11838336212","pt":1723187065941,"mc":[{"id":"1.231583502","rc":[{"batb":[[0,2.08,35.1],[1,1.8,2],[2,1.74,17.32]],"ltp":2.1,"tv":81.83,"id":40096579}]}]}
{"op":"mcm","clk":"11838336411","pt":1723187069337,"mc":[{"id":"1.231583502","rc":[{"batb":[[0,2.1,10],[1,2.08,35.1],[2,1.8,2]],"ltp":2.1,"tv":81.83,"id":40096579}]}]}
{"op":"mcm","clk":"11838336606","pt":1723187072637,"mc":[{"id":"1.231583502","rc":[{"batb":[[0,2.08,35.1],[1,1.8,2],[2,1.74,17.32]],"ltp":2.1,"tv":81.83,"id":40096579}]}]}
{"op":"mcm","clk":"11838337070","pt":1723187080360,"mc":[{"id":"1.231583502","rc":[{"batb":[[0,2.1,10],[1,2.08,35.1],[2,1.8,2]],"ltp":2.1,"tv":81.83,"id":40096579}]}]}
{"op":"mcm","clk":"11838337303","pt":1723187084369,"mc":[{"id":"1.231583502","rc":[{"batb":[[0,2.08,35.1],[1,1.8,2],[2,1.74,17.32]],"ltp":2.1,"tv":81.83,"id":40096579}]}]}
{"op":"mcm","clk":"11838337420","pt":1723187086848,"mc":[{"id":"1.231583502","rc":[{"batb":[[0,2.1,10],[1,2.08,35.1],[2,1.8,2]],"ltp":2.1,"tv":81.83,"id":40096579}]}]}
{"op":"mcm","clk":"11838337641","pt":1723187090295,"mc":[{"id":"1.231583502","rc":[{"batb":[[0,2.08,35.1],[1,1.8,2],[2,1.74,17.32]],"ltp":2.1,"tv":81.83,"id":40096579}]}]}
{"op":"mcm","clk":"11838337796","pt":1723187092660,"mc":[{"id":"1.231583502","rc":[{"batb":[[0,2.1,10],[1,2.08,35.1],[2,1.8,2]],"ltp":2.1,"tv":81.83,"id":40096579}]}]}
{"op":"mcm","clk":"11838338027","pt":1723187096168,"mc":[{"id":"1.231583502","rc":[{"batb":[[0,2.08,35.1],[1,1.8,2],[2,1.74,17.32]],"ltp":2.1,"tv":81.83,"id":40096579}]}]}
{"op":"mcm","clk":"11838338261","pt":1723187100174,"mc":[{"id":"1.231583502","rc":[{"batb":[[0,2.1,10],[1,2.08,35.1],[2,1.8,2]],"ltp":2.1,"tv":81.83,"id":40096579}]}]}
{"op":"mcm","clk":"11838338474","pt":1723187103402,"mc":[{"id":"1.231583502","rc":[{"batb":[[0,2.08,35.1],[1,1.8,2],[2,1.74,17.32]],"ltp":2.1,"tv":81.83,"id":40096579}]}]}
{"op":"mcm","clk":"11838338710","pt":1723187107418,"mc":[{"id":"1.231583502","rc":[{"batb":[[0,2.1,10],[1,2.08,35.1],[2,1.8,2]],"ltp":2.1,"tv":81.83,"id":40096579}]}]}
{"op":"mcm","clk":"11838338939","pt":1723187110815,"mc":[{"id":"1.231583502","rc":[{"batb":[[0,2.08,35.1],[1,1.8,2],[2,1.74,17.32]],"ltp":2.1,"tv":81.83,"id":40096579}]}]}
{"op":"mcm","clk":"11838339167","pt":1723187114800,"mc":[{"id":"1.231583502","rc":[{"batb":[[0,2.1,10],[1,2.08,35.1],[2,1.8,2]],"ltp":2.1,"tv":81.83,"id":40096579}]}]}
{"op":"mcm","clk":"11838339361","pt":1723187118308,"mc":[{"id":"1.231583502","rc":[{"batb":[[0,2.08,35.1],[1,1.8,2],[2,1.74,17.32]],"ltp":2.1,"tv":81.83,"id":40096579}]}]}
{"op":"mcm","clk":"11838339503","pt":1723187120722,"mc":[{"id":"1.231583502","rc":[{"batb":[[0,2.1,10],[1,2.08,35.1],[2,1.8,2]],"ltp":2.1,"tv":81.83,"id":40096579}]}]}
{"op":"mcm","clk":"11838339722","pt":1723187124113,"mc":[{"id":"1.231583502","rc":[{"batb":[[0,2.08,35.1],[1,1.8,2],[2,1.74,17.32]],"ltp":2.1,"tv":81.83,"id":40096579}]}]}
{"op":"mcm","clk":"11838339882","pt":1723187126835,"mc":[{"id":"1.231583502","rc":[{"batb":[[0,2.1,10],[1,2.08,35.1],[2,1.8,2]],"ltp":2.1,"tv":81.83,"id":40096579}]}]}
{"op":"mcm","clk":"11838340082","pt":1723187130230,"mc":[{"id":"1.231583502","rc":[{"batb":[[0,2.08,35.1],[1,1.8,2],[2,1.74,17.32]],"ltp":2.1,"tv":81.83,"id":40096579}]}]}
{"op":"mcm","clk":"11838340246","pt":1723187133315,"mc":[{"id":"1.231583502","rc":[{"batb":[[0,2.1,10],[1,2.08,35.1],[2,1.8,2]],"ltp":2.1,"tv":81.83,"id":40096579}]}]}
{"op":"mcm","clk":"11838340458","pt":1723187136708,"mc":[{"id":"1.231583502","rc":[{"batb":[[0,2.08,35.1],[1,1.8,2],[2,1.74,17.32]],"ltp":2.1,"tv":81.83,"id":40096579}]}]}
{"op":"mcm","clk":"11838340655","pt":1723187139537,"mc":[{"id":"1.231583502","rc":[{"batb":[[0,2.1,10],[1,2.08,35.1],[2,1.8,2]],"ltp":2.1,"tv":81.83,"id":40096579}]}]}
{"op":"mcm","clk":"11838340919","pt":1723187142859,"mc":[{"id":"1.231583502","rc":[{"batb":[[0,2.08,35.1],[1,1.8,2],[2,1.74,17.32]],"ltp":2.1,"tv":81.83,"id":40096579}]}]}
{"op":"mcm","clk":"11838341121","pt":1723187145938,"mc":[{"id":"1.231583502","rc":[{"batb":[[0,2.1,10],[1,2.08,35.1],[2,1.8,2]],"ltp":2.1,"tv":81.83,"id":40096579}]}]}
{"op":"mcm","clk":"11838341337","pt":1723187149332,"mc":[{"id":"1.231583502","rc":[{"batb":[[0,2.08,35.1],[1,1.8,2],[2,1.74,17.32]],"ltp":2.1,"tv":81.83,"id":40096579}]}]}
{"op":"mcm","clk":"11838341475","pt":1723187152155,"mc":[{"id":"1.231583502","rc":[{"batb":[[0,2.1,10],[1,2.08,35.1],[2,1.8,2]],"ltp":2.1,"tv":81.83,"id":40096579}]}]}
{"op":"mcm","clk":"11838341702","pt":1723187155648,"mc":[{"id":"1.231583502","rc":[{"batb":[[0,2.08,35.1],[1,1.8,2],[2,1.74,17.32]],"ltp":2.1,"tv":81.83,"id":40096579}]}]}
{"op":"mcm","clk":"11838341835","pt":1723187158056,"mc":[{"id":"1.231583502","rc":[{"batb":[[0,2.1,10],[1,2.08,35.1],[2,1.8,2]],"ltp":2.1,"tv":81.83,"id":40096579}]}]}
{"op":"mcm","clk":"11838342040","pt":1723187161390,"mc":[{"id":"1.231583502","rc":[{"batb":[[0,2.08,35.1],[1,1.8,2],[2,1.74,17.32]],"ltp":2.1,"tv":81.83,"id":40096579}]}]}
{"op":"mcm","clk":"11838342243","pt":1723187164674,"mc":[{"id":"1.231583502","rc":[{"batb":[[0,2.1,10],[1,2.08,35.1],[2,1.8,2]],"ltp":2.1,"tv":81.83,"id":40096579}]}]}
{"op":"mcm","clk":"11838342451","pt":1723187167969,"mc":[{"id":"1.231583502","rc":[{"batb":[[0,2.08,35.1],[1,1.8,2],[2,1.74,17.32]],"ltp":2.1,"tv":81.83,"id":40096579}]}]}
{"op":"mcm","clk":"11838342559","pt":1723187170487,"mc":[{"id":"1.231583502","rc":[{"batb":[[0,2.1,10],[1,2.08,35.1],[2,1.8,2]],"ltp":2.1,"tv":81.83,"id":40096579}]}]}
{"op":"mcm","clk":"11838342766","pt":1723187173866,"mc":[{"id":"1.231583502","rc":[{"batb":[[0,2.08,35.1],[1,1.8,2],[2,1.74,17.32]],"ltp":2.1,"tv":81.83,"id":40096579}]}]}
{"op":"mcm","clk":"11838342927","pt":1723187177197,"mc":[{"id":"1.231583502","rc":[{"batb":[[0,2.1,10],[1,2.08,35.1],[2,1.8,2]],"ltp":2.1,"tv":81.83,"id":40096579}]}]}
{"op":"mcm","clk":"11838343115","pt":1723187180877,"mc":[{"id":"1.231583502","rc":[{"batb":[[0,2.08,35.1],[1,1.8,2],[2,1.74,17.32]],"ltp":2.1,"tv":81.83,"id":40096579}]}]}
{"op":"mcm","clk":"11838343341","pt":1723187184169,"mc":[{"id":"1.231583502","rc":[{"batb":[[0,2.1,10],[1,2.08,35.1],[2,1.8,2]],"ltp":2.1,"tv":81.83,"id":40096579}]}]}
{"op":"mcm","clk":"11838343532","pt":1723187187600,"mc":[{"id":"1.231583502","rc":[{"batb":[[0,2.08,35.1],[1,1.8,2],[2,1.74,17.32]],"ltp":2.1,"tv":81.83,"id":40096579}]}]}
{"op":"mcm","clk":"11838343657","pt":1723187190000,"mc":[{"id":"1.231583502","rc":[{"batb":[[0,2.1,10],[1,2.08,35.1],[2,1.8,2]],"ltp":2.1,"tv":81.83,"id":40096579}]}]}
{"op":"mcm","clk":"11838343847","pt":1723187193487,"mc":[{"id":"1.231583502","rc":[{"batb":[[0,2.08,35.1],[1,1.8,2],[2,1.74,17.32]],"ltp":2.1,"tv":81.83,"id":40096579}]}]}
{"op":"mcm","clk":"11838343980","pt":1723187196298,"mc":[{"id":"1.231583502","rc":[{"batb":[[0,2.1,10],[1,2.08,35.1],[2,1.8,2]],"ltp":2.1,"tv":81.83,"id":40096579}]}]}
{"op":"mcm","clk":"11838344160","pt":1723187199929,"mc":[{"id":"1.231583502","rc":[{"batb":[[0,2.08,35.1],[1,1.8,2],[2,1.74,17.32]],"ltp":2.1,"tv":81.83,"id":40096579}]}]}
{"op":"mcm","clk":"11838344321","pt":1723187202495,"mc":[{"id":"1.231583502","rc":[{"batb":[[0,2.1,10],[1,2.08,35.1],[2,1.8,2]],"ltp":2.1,"tv":81.83,"id":40096579}]}]}
{"op":"mcm","clk":"11838344488","pt":1723187205832,"mc":[{"id":"1.231583502","rc":[{"batb":[[0,2.08,35.1],[1,1.8,2],[2,1.74,17.32]],"ltp":2.1,"tv":81.83,"id":40096579}]}]}
{"op":"mcm","clk":"11838344648","pt":1723187209162,"mc":[{"id":"1.231583502","rc":[{"batb":[[0,2.1,10],[1,2.08,35.1],[2,1.8,2]],"ltp":2.1,"tv":81.83,"id":40096579}]}]}
{"op":"mcm","clk":"11838344840","pt":1723187212553,"mc":[{"id":"1.231583502","rc":[{"batb":[[0,2.08,35.1],[1,1.8,2],[2,1.74,17.32]],"ltp":2.1,"tv":81.83,"id":40096579}]}]}
{"op":"mcm","clk":"11838345061","pt":1723187216452,"mc":[{"id":"1.231583502","rc":[{"batb":[[0,2.1,10],[1,2.08,35.1],[2,1.8,2]],"ltp":2.1,"tv":81.83,"id":40096579}]}]}
{"op":"mcm","clk":"11838345206","pt":1723187219876,"mc":[{"id":"1.231583502","rc":[{"batb":[[0,2.08,35.1],[1,1.8,2],[2,1.74,17.32]],"ltp":2.1,"tv":81.83,"id":40096579}]}]}
{"op":"mcm","clk":"11838345340","pt":1723187222396,"mc":[{"id":"1.231583502","rc":[{"batb":[[0,2.1,10],[1,2.08,35.1],[2,1.8,2]],"ltp":2.1,"tv":81.83,"id":40096579}]}]}
{"op":"mcm","clk":"11838345546","pt":1723187225900,"mc":[{"id":"1.231583502","rc":[{"batb":[[0,2.08,35.1],[1,1.8,2],[2,1.74,17.32]],"ltp":2.1,"tv":81.83,"id":40096579}]}]}
{"op":"mcm","clk":"11838345694","pt":1723187228262,"mc":[{"id":"1.231583502","rc":[{"batb":[[0,2.1,10],[1,2.08,35.1],[2,1.8,2]],"ltp":2.1,"tv":81.83,"id":40096579}]}]}
{"op":"mcm","clk":"11838345910","pt":1723187231803,"mc":[{"id":"1.231583502","rc":[{"batb":[[0,2.08,35.1],[1,1.8,2],[2,1.74,17.32]],"ltp":2.1,"tv":81.83,"id":40096579}]}]}
{"op":"mcm","clk":"11838346201","pt":1723187236676,"mc":[{"id":"1.231583502","rc":[{"batb":[[0,2.1,10],[1,2.08,35.1],[2,1.8,2]],"ltp":2.1,"tv":81.83,"id":40096579}]}]}
{"op":"mcm","clk":"11838346365","pt":1723187240304,"mc":[{"id":"1.231583502","rc":[{"batb":[[0,2.08,35.1],[1,1.8,2],[2,1.74,17.32]],"ltp":2.1,"tv":81.83,"id":40096579}]}]}
{"op":"mcm","clk":"11838346594","pt":1723187243689,"mc":[{"id":"1.231583502","rc":[{"batb":[[0,2.1,10],[1,2.08,35.1],[2,1.8,2]],"ltp":2.1,"tv":81.83,"id":40096579}]}]}
{"op":"mcm","clk":"11838346760","pt":1723187247015,"mc":[{"id":"1.231583502","rc":[{"batb":[[0,2.08,35.1],[1,1.8,2],[2,1.74,17.32]],"ltp":2.1,"tv":81.83,"id":40096579}]}]}
{"op":"mcm","clk":"11838346942","pt":1723187250093,"mc":[{"id":"1.231583502","rc":[{"batb":[[0,2.1,10],[1,2.08,35.1],[2,1.8,2]],"ltp":2.1,"tv":81.83,"id":40096579}]}]}
{"op":"mcm","clk":"11838347100","pt":1723187253528,"mc":[{"id":"1.231583502","rc":[{"batb":[[0,2.08,35.1],[1,1.8,2],[2,1.74,17.32]],"ltp":2.1,"tv":81.83,"id":40096579}]}]}
{"op":"mcm","clk":"11838347226","pt":1723187255904,"mc":[{"id":"1.231583502","rc":[{"batb":[[0,2.1,10],[1,2.08,35.1],[2,1.8,2]],"ltp":2.1,"tv":81.83,"id":40096579}]}]}
{"op":"mcm","clk":"11838347412","pt":1723187259305,"mc":[{"id":"1.231583502","rc":[{"batb":[[0,2.08,35.1],[1,1.8,2],[2,1.74,17.32]],"ltp":2.1,"tv":81.83,"id":40096579}]}]}
{"op":"mcm","clk":"11838347652","pt":1723187262695,"mc":[{"id":"1.231583502","rc":[{"batb":[[0,2.1,10],[1,2.08,35.1],[2,1.8,2]],"ltp":2.1,"tv":81.83,"id":40096579}]}]}
{"op":"mcm","clk":"11838347873","pt":1723187266232,"mc":[{"id":"1.231583502","rc":[{"batb":[[0,2.08,35.1],[1,1.8,2],[2,1.74,17.32]],"ltp":2.1,"tv":81.83,"id":40096579}]}]}
{"op":"mcm","clk":"11838348009","pt":1723187269206,"mc":[{"id":"1.231583502","rc":[{"batb":[[0,2.1,10],[1,2.08,35.1],[2,1.8,2]],"ltp":2.1,"tv":81.83,"id":40096579}]}]}
{"op":"mcm","clk":"11838348240","pt":1723187273249,"mc":[{"id":"1.231583502","rc":[{"batb":[[0,2.08,35.1],[1,1.8,2],[2,1.74,17.32]],"ltp":2.1,"tv":81.83,"id":40096579}]}]}
{"op":"mcm","clk":"11838348490","pt":1723187276954,"mc":[{"id":"1.231583502","rc":[{"batb":[[0,2.1,10],[1,2.08,35.1],[2,1.8,2]],"ltp":2.1,"tv":81.83,"id":40096579}]}]}
{"op":"mcm","clk":"11838348685","pt":1723187280245,"mc":[{"id":"1.231583502","rc":[{"batb":[[0,2.08,35.1],[1,1.8,2],[2,1.74,17.32]],"ltp":2.1,"tv":81.83,"id":40096579}]}]}
{"op":"mcm","clk":"11838348820","pt":1723187282567,"mc":[{"id":"1.231583502","rc":[{"batb":[[0,2.1,10],[1,2.08,35.1],[2,1.8,2]],"ltp":2.1,"tv":81.83,"id":40096579}]}]}
{"op":"mcm","clk":"11838349081","pt":1723187285961,"mc":[{"id":"1.231583502","rc":[{"batb":[[0,2.08,35.1],[1,1.8,2],[2,1.74,17.32]],"ltp":2.1,"tv":81.83,"id":40096579}]}]}
{"op":"mcm","clk":"11838349250","pt":1723187288639,"mc":[{"id":"1.231583502","rc":[{"batb":[[0,2.1,10],[1,2.08,35.1],[2,1.8,2]],"ltp":2.1,"tv":81.83,"id":40096579}]}]}
{"op":"mcm","clk":"11838349508","pt":1723187292350,"mc":[{"id":"1.231583502","rc":[{"batb":[[0,2.08,35.1],[1,1.8,2],[2,1.74,17.32]],"ltp":2.1,"tv":81.83,"id":40096579}]}]}
{"op":"mcm","clk":"11838349747","pt":1723187295682,"mc":[{"id":"1.231583502","rc":[{"batb":[[0,2.1,10],[1,2.08,35.1],[2,1.8,2]],"ltp":2.1,"tv":81.83,"id":40096579}]}]}
{"op":"mcm","clk":"11838349932","pt":1723187298981,"mc":[{"id":"1.231583502","rc":[{"batb":[[0,2.08,35.1],[1,1.8,2],[2,1.74,17.32]],"ltp":2.1,"tv":81.83,"id":40096579}]}]}
{"op":"mcm","clk":"11838350238","pt":1723187304082,"mc":[{"id":"1.231583502","rc":[{"batb":[[0,2.1,10],[1,2.08,35.1],[2,1.8,2]],"ltp":2.1,"tv":81.83,"id":40096579}]}]}
{"op":"mcm","clk":"11838350465","pt":1723187307271,"mc":[{"id":"1.231583502","rc":[{"batb":[[0,2.08,35.1],[1,1.8,2],[2,1.74,17.32]],"ltp":2.1,"tv":81.83,"id":40096579}]}]}
{"op":"mcm","clk":"11838350669","pt":1723187310108,"mc":[{"id":"1.231583502","rc":[{"batb":[[0,2.1,10],[1,2.08,35.1],[2,1.8,2]],"ltp":2.1,"tv":81.83,"id":40096579}]}]}
{"op":"mcm","clk":"11838350899","pt":1723187313305,"mc":[{"id":"1.231583502","rc":[{"batb":[[0,2.08,35.1],[1,1.8,2],[2,1.74,17.32]],"ltp":2.1,"tv":81.83,"id":40096579}]}]}
{"op":"mcm","clk":"11838351467","pt":1723187320776,"mc":[{"id":"1.231583502","rc":[{"batb":[[0,2.1,10],[1,2.08,35.1],[2,1.8,2]],"ltp":2.1,"tv":81.83,"id":40096579}]}]}
{"op":"mcm","clk":"11838351700","pt":1723187324321,"mc":[{"id":"1.231583502","rc":[{"batb":[[0,2.08,35.1],[1,1.8,2],[2,1.74,17.32]],"ltp":2.1,"tv":81.83,"id":40096579}]}]}
{"op":"mcm","clk":"11838352214","pt":1723187331906,"mc":[{"id":"1.231583502","rc":[{"batb":[[0,2.1,10],[1,2.08,35.1],[2,1.8,2]],"ltp":2.1,"tv":81.83,"id":40096579}]}]}
{"op":"mcm","clk":"11838352453","pt":1723187335528,"mc":[{"id":"1.231583502","rc":[{"batb":[[0,2.08,35.1],[1,1.8,2],[2,1.74,17.32]],"ltp":2.1,"tv":81.83,"id":40096579}]}]}
{"op":"mcm","clk":"11838352645","pt":1723187339018,"mc":[{"id":"1.231583502","rc":[{"batb":[[0,2.1,10],[1,2.08,35.1],[2,1.8,2]],"ltp":2.1,"tv":81.83,"id":40096579}]}]}
{"op":"mcm","clk":"11838352818","pt":1723187342423,"mc":[{"id":"1.231583502","rc":[{"batb":[[0,2.08,35.1],[1,1.8,2],[2,1.74,17.32]],"ltp":2.1,"tv":81.83,"id":40096579}]}]}
{"op":"mcm","clk":"11838353092","pt":1723187346428,"mc":[{"id":"1.231583502","rc":[{"batb":[[0,2.1,10],[1,2.08,35.1],[2,1.8,2]],"ltp":2.1,"tv":81.83,"id":40096579}]}]}
{"op":"mcm","clk":"11838353320","pt":1723187349825,"mc":[{"id":"1.231583502","rc":[{"batb":[[0,2.08,35.1],[1,1.8,2],[2,1.74,17.32]],"ltp":2.1,"tv":81.83,"id":40096579}]}]}
{"op":"mcm","clk":"11838353446","pt":1723187352237,"mc":[{"id":"1.231583502","rc":[{"batb":[[0,2.1,10],[1,2.08,35.1],[2,1.8,2]],"ltp":2.1,"tv":81.83,"id":40096579}]}]}
{"op":"mcm","clk":"11838353653","pt":1723187355525,"mc":[{"id":"1.231583502","rc":[{"batb":[[0,2.08,35.1],[1,1.8,2],[2,1.74,17.32]],"ltp":2.1,"tv":81.83,"id":40096579}]}]}
{"op":"mcm","clk":"11838353814","pt":1723187358615,"mc":[{"id":"1.231583502","rc":[{"batb":[[0,2.1,10],[1,2.08,35.1],[2,1.8,2]],"ltp":2.1,"tv":81.83,"id":40096579}]}]}
{"op":"mcm","clk":"11838354013","pt":1723187362061,"mc":[{"id":"1.231583502","rc":[{"batb":[[0,2.08,35.1],[1,1.8,2],[2,1.74,17.32]],"ltp":2.1,"tv":81.83,"id":40096579}]}]}
{"op":"mcm","clk":"11838354163","pt":1723187364527,"mc":[{"id":"1.231583502","rc":[{"batb":[[0,2.1,10],[1,2.08,35.1],[2,1.8,2]],"ltp":2.1,"tv":81.83,"id":40096579}]}]}
{"op":"mcm","clk":"11838354318","pt":1723187368070,"mc":[{"id":"1.231583502","rc":[{"batb":[[0,2.08,35.1],[1,1.8,2],[2,1.74,17.32]],"ltp":2.1,"tv":81.83,"id":40096579}]}]}
{"op":"mcm","clk":"11838354573","pt":1723187372463,"mc":[{"id":"1.231583502","rc":[{"batb":[[0,2.1,10],[1,2.08,35.1],[2,1.8,2]],"ltp":2.1,"tv":81.83,"id":40096579}]}]}
{"op":"mcm","clk":"11838354777","pt":1723187375761,"mc":[{"id":"1.231583502","rc":[{"batb":[[0,2.08,35.1],[1,1.8,2],[2,1.74,17.32]],"ltp":2.1,"tv":81.83,"id":40096579}]}]}
{"op":"mcm","clk":"11838354972","pt":1723187378744,"mc":[{"id":"1.231583502","rc":[{"batb":[[0,2.1,10],[1,2.08,35.1],[2,1.8,2]],"ltp":2.1,"tv":81.83,"id":40096579}]}]}
{"op":"mcm","clk":"11838355117","pt":1723187382189,"mc":[{"id":"1.231583502","rc":[{"batb":[[0,2.08,35.1],[1,1.8,2],[2,1.74,17.32]],"ltp":2.1,"tv":81.83,"id":40096579}]}]}
{"op":"mcm","clk":"11838355292","pt":1723187385779,"mc":[{"id":"1.231583502","rc":[{"batb":[[0,2.1,10],[1,2.08,35.1],[2,1.8,2]],"ltp":2.1,"tv":81.83,"id":40096579}]}]}
{"op":"mcm","clk":"11838355437","pt":1723187389157,"mc":[{"id":"1.231583502","rc":[{"batb":[[0,2.08,35.1],[1,1.8,2],[2,1.74,17.32]],"ltp":2.1,"tv":81.83,"id":40096579}]}]}
{"op":"mcm","clk":"11838355689","pt":1723187393874,"mc":[{"id":"1.231583502","rc":[{"batb":[[0,2.1,10],[1,2.08,35.1],[2,1.8,2]],"ltp":2.1,"tv":81.83,"id":40096579}]}]}
{"op":"mcm","clk":"11838355844","pt":1723187397566,"mc":[{"id":"1.231583502","rc":[{"batb":[[0,2.08,35.1],[1,1.8,2],[2,1.74,17.32]],"ltp":2.1,"tv":81.83,"id":40096579}]}]}
{"op":"mcm","clk":"11838355948","pt":1723187400277,"mc":[{"id":"1.231583502","rc":[{"batb":[[0,2.1,10],[1,2.08,35.1],[2,1.8,2]],"ltp":2.1,"tv":81.83,"id":40096579}]}]}
{"op":"mcm","clk":"11838356115","pt":1723187403693,"mc":[{"id":"1.231583502","rc":[{"batb":[[0,2.08,35.1],[1,1.8,2],[2,1.74,17.32]],"ltp":2.1,"tv":81.83,"id":40096579}]}]}
{"op":"mcm","clk":"11838356448","pt":1723187408985,"mc":[{"id":"1.231583502","rc":[{"batb":[[0,2.1,10],[1,2.08,35.1],[2,1.8,2]],"ltp":2.1,"tv":81.83,"id":40096579}]}]}
{"op":"mcm","clk":"11838356616","pt":1723187412426,"mc":[{"id":"1.231583502","rc":[{"batb":[[0,2.08,35.1],[1,1.8,2],[2,1.74,17.32]],"ltp":2.1,"tv":81.83,"id":40096579}]}]}
{"op":"mcm","clk":"11838356791","pt":1723187415817,"mc":[{"id":"1.231583502","rc":[{"batb":[[0,2.1,10],[1,2.08,35.1],[2,1.8,2]],"ltp":2.1,"tv":81.83,"id":40096579}]}]}
{"op":"mcm","clk":"11838356969","pt":1723187419249,"mc":[{"id":"1.231583502","rc":[{"batb":[[0,2.08,35.1],[1,1.8,2],[2,1.74,17.32]],"ltp":2.1,"tv":81.83,"id":40096579}]}]}
{"op":"mcm","clk":"11838357161","pt":1723187422839,"mc":[{"id":"1.231583502","rc":[{"batb":[[0,2.1,10],[1,2.08,35.1],[2,1.8,2]],"ltp":2.1,"tv":81.83,"id":40096579}]}]}
{"op":"mcm","clk":"11838357333","pt":1723187426016,"mc":[{"id":"1.231583502","rc":[{"batb":[[0,2.08,35.1],[1,1.8,2],[2,1.74,17.32]],"ltp":2.1,"tv":81.83,"id":40096579}]}]}
{"op":"mcm","clk":"11838357447","pt":1723187428535,"mc":[{"id":"1.231583502","rc":[{"batb":[[0,2.1,10],[1,2.08,35.1],[2,1.8,2]],"ltp":2.1,"tv":81.83,"id":40096579}]}]}
{"op":"mcm","clk":"11838357567","pt":1723187431751,"mc":[{"id":"1.231583502","rc":[{"batb":[[0,2.08,35.1],[1,1.8,2],[2,1.74,17.32]],"ltp":2.1,"tv":81.83,"id":40096579}]}]}
{"op":"mcm","clk":"11838357723","pt":1723187434728,"mc":[{"id":"1.231583502","rc":[{"batb":[[0,2.1,10],[1,2.08,35.1],[2,1.8,2]],"ltp":2.1,"tv":81.83,"id":40096579}]}]}
{"op":"mcm","clk":"11838357902","pt":1723187438078,"mc":[{"id":"1.231583502","rc":[{"batb":[[0,2.08,35.1],[1,1.8,2],[2,1.74,17.32]],"ltp":2.1,"tv":81.83,"id":40096579}]}]}
{"op":"mcm","clk":"11838358204","pt":1723187444174,"mc":[{"id":"1.231583502","rc":[{"batb":[[0,2.1,10],[1,2.08,35.1],[2,1.8,2]],"ltp":2.1,"tv":81.83,"id":40096579}]}]}
{"op":"mcm","clk":"11838358375","pt":1723187448021,"mc":[{"id":"1.231583502","rc":[{"batb":[[0,2.08,35.1],[1,1.8,2],[2,1.74,17.32]],"ltp":2.1,"tv":81.83,"id":40096579}]}]}
{"op":"mcm","clk":"11838358499","pt":1723187450992,"mc":[{"id":"1.231583502","rc":[{"batb":[[0,2.1,10],[1,2.08,35.1],[2,1.8,2]],"ltp":2.1,"tv":81.83,"id":40096579}]}]}
{"op":"mcm","clk":"11838358704","pt":1723187454480,"mc":[{"id":"1.231583502","rc":[{"batb":[[0,2.08,35.1],[1,1.8,2],[2,1.74,17.32]],"ltp":2.1,"tv":81.83,"id":40096579}]}]}
{"op":"mcm","clk":"11838358988","pt":1723187460165,"mc":[{"id":"1.231583502","rc":[{"batb":[[0,2.1,10],[1,2.08,35.1],[2,1.8,2]],"ltp":2.1,"tv":81.83,"id":40096579}]}]}
{"op":"mcm","clk":"11838359172","pt":1723187463764,"mc":[{"id":"1.231583502","rc":[{"batb":[[0,2.08,35.1],[1,1.8,2],[2,1.74,17.32]],"ltp":2.1,"tv":81.83,"id":40096579}]}]}
{"op":"mcm","clk":"11838359324","pt":1723187466885,"mc":[{"id":"1.231583502","rc":[{"batb":[[0,2.1,10],[1,2.08,35.1],[2,1.8,2]],"ltp":2.1,"tv":81.83,"id":40096579}]}]}
{"op":"mcm","clk":"11838359490","pt":1723187470421,"mc":[{"id":"1.231583502","rc":[{"batb":[[0,2.08,35.1],[1,1.8,2],[2,1.74,17.32]],"ltp":2.1,"tv":81.83,"id":40096579}]}]}
{"op":"mcm","clk":"11838359673","pt":1723187473903,"mc":[{"id":"1.231583502","rc":[{"batb":[[0,2.1,10],[1,2.08,35.1],[2,1.8,2]],"ltp":2.1,"tv":81.83,"id":40096579}]}]}
{"op":"mcm","clk":"11838359819","pt":1723187477205,"mc":[{"id":"1.231583502","rc":[{"batb":[[0,2.08,35.1],[1,1.8,2],[2,1.74,17.32]],"ltp":2.1,"tv":81.83,"id":40096579}]}]}
{"op":"mcm","clk":"11838359943","pt":1723187479821,"mc":[{"id":"1.231583502","rc":[{"batb":[[0,2.1,10],[1,2.08,35.1],[2,1.8,2]],"ltp":2.1,"tv":81.83,"id":40096579}]}]}
{"op":"mcm","clk":"11838360126","pt":1723187483315,"mc":[{"id":"1.231583502","rc":[{"batb":[[0,2.08,35.1],[1,1.8,2],[2,1.74,17.32]],"ltp":2.1,"tv":81.83,"id":40096579}]}]}
{"op":"mcm","clk":"11838360294","pt":1723187486031,"mc":[{"id":"1.231583502","rc":[{"batb":[[0,2.1,10],[1,2.08,35.1],[2,1.8,2]],"ltp":2.1,"tv":81.83,"id":40096579}]}]}
{"op":"mcm","clk":"11838360447","pt":1723187489217,"mc":[{"id":"1.231583502","rc":[{"batb":[[0,2.08,35.1],[1,1.8,2],[2,1.74,17.32]],"ltp":2.1,"tv":81.83,"id":40096579}]}]}
{"op":"mcm","clk":"11838360594","pt":1723187492545,"mc":[{"id":"1.231583502","rc":[{"batb":[[0,2.1,10],[1,2.08,35.1],[2,1.8,2]],"ltp":2.1,"tv":81.83,"id":40096579}]}]}
{"op":"mcm","clk":"11838360732","pt":1723187495927,"mc":[{"id":"1.231583502","rc":[{"batb":[[0,2.08,35.1],[1,1.8,2],[2,1.74,17.32]],"ltp":2.1,"tv":81.83,"id":40096579}]}]}
{"op":"mcm","clk":"11838360862","pt":1723187498132,"mc":[{"id":"1.231583502","rc":[{"batb":[[0,2.1,10],[1,2.08,35.1],[2,1.8,2]],"ltp":2.1,"tv":81.83,"id":40096579}]}]}
{"op":"mcm","clk":"11838361046","pt":1723187501529,"mc":[{"id":"1.231583502","rc":[{"batb":[[0,2.08,35.1],[1,1.8,2],[2,1.74,17.32]],"ltp":2.1,"tv":81.83,"id":40096579}]}]}
{"op":"mcm","clk":"11838361182","pt":1723187503840,"mc":[{"id":"1.231583502","rc":[{"batb":[[0,2.1,10],[1,2.08,35.1],[2,1.8,2]],"ltp":2.1,"tv":81.83,"id":40096579}]}]}
{"op":"mcm","clk":"11838361339","pt":1723187507226,"mc":[{"id":"1.231583502","rc":[{"batb":[[0,2.08,35.1],[1,1.8,2],[2,1.74,17.32]],"ltp":2.1,"tv":81.83,"id":40096579}]}]}
{"op":"mcm","clk":"11838361463","pt":1723187509641,"mc":[{"id":"1.231583502","rc":[{"batb":[[0,2.1,10],[1,2.08,35.1],[2,1.8,2]],"ltp":2.1,"tv":81.83,"id":40096579}]}]}
{"op":"mcm","clk":"11838361652","pt":1723187512824,"mc":[{"id":"1.231583502","rc":[{"batb":[[0,2.08,35.1],[1,1.8,2],[2,1.74,17.32]],"ltp":2.1,"tv":81.83,"id":40096579}]}]}
{"op":"mcm","clk":"11838361795","pt":1723187515247,"mc":[{"id":"1.231583502","rc":[{"batb":[[0,2.1,10],[1,2.08,35.1],[2,1.8,2]],"ltp":2.1,"tv":81.83,"id":40096579}]}]}
{"op":"mcm","clk":"11838362005","pt":1723187518660,"mc":[{"id":"1.231583502","rc":[{"batb":[[0,2.08,35.1],[1,1.8,2],[2,1.74,17.32]],"ltp":2.1,"tv":81.83,"id":40096579}]}]}
{"op":"mcm","clk":"11838362159","pt":1723187521337,"mc":[{"id":"1.231583502","rc":[{"batb":[[0,2.1,10],[1,2.08,35.1],[2,1.8,2]],"ltp":2.1,"tv":81.83,"id":40096579}]}]}
{"op":"mcm","clk":"11838362364","pt":1723187524873,"mc":[{"id":"1.231583502","rc":[{"batb":[[0,2.08,35.1],[1,1.8,2],[2,1.74,17.32]],"ltp":2.1,"tv":81.83,"id":40096579}]}]}
{"op":"mcm","clk":"11838362494","pt":1723187527241,"mc":[{"id":"1.231583502","rc":[{"batb":[[0,2.1,10],[1,2.08,35.1],[2,1.8,2]],"ltp":2.1,"tv":81.83,"id":40096579}]}]}
{"op":"mcm","clk":"11838362660","pt":1723187530574,"mc":[{"id":"1.231583502","rc":[{"batb":[[0,2.08,35.1],[1,1.8,2],[2,1.74,17.32]],"ltp":2.1,"tv":81.83,"id":40096579}]}]}
{"op":"mcm","clk":"11838362831","pt":1723187533354,"mc":[{"id":"1.231583502","rc":[{"batb":[[0,2.1,10],[1,2.08,35.1],[2,1.8,2]],"ltp":2.1,"tv":81.83,"id":40096579}]}]}
{"op":"mcm","clk":"11838363024","pt":1723187536682,"mc":[{"id":"1.231583502","rc":[{"batb":[[0,2.08,35.1],[1,1.8,2],[2,1.74,17.32]],"ltp":2.1,"tv":81.83,"id":40096579}]}]}
{"op":"mcm","clk":"11838363126","pt":1723187538988,"mc":[{"id":"1.231583502","rc":[{"batb":[[0,2.1,10],[1,2.08,35.1],[2,1.8,2]],"ltp":2.1,"tv":81.83,"id":40096579}]}]}
{"op":"mcm","clk":"11838363302","pt":1723187542386,"mc":[{"id":"1.231583502","rc":[{"batb":[[0,2.08,35.1],[1,1.8,2],[2,1.74,17.32]],"ltp":2.1,"tv":81.83,"id":40096579}]}]}
{"op":"mcm","clk":"11838363428","pt":1723187544896,"mc":[{"id":"1.231583502","rc":[{"batb":[[0,2.1,10],[1,2.08,35.1],[2,1.8,2]],"ltp":2.1,"tv":81.83,"id":40096579}]}]}
{"op":"mcm","clk":"11838363612","pt":1723187548083,"mc":[{"id":"1.231583502","rc":[{"batb":[[0,2.08,35.1],[1,1.8,2],[2,1.74,17.32]],"ltp":2.1,"tv":81.83,"id":40096579}]}]}
{"op":"mcm","clk":"11838363755","pt":1723187550970,"mc":[{"id":"1.231583502","rc":[{"batb":[[0,2.1,10],[1,2.08,35.1],[2,1.8,2]],"ltp":2.1,"tv":81.83,"id":40096579}]}]}
{"op":"mcm","clk":"11838363912","pt":1723187554213,"mc":[{"id":"1.231583502","rc":[{"batb":[[0,2.08,35.1],[1,1.8,2],[2,1.74,17.32]],"ltp":2.1,"tv":81.83,"id":40096579}]}]}
{"op":"mcm","clk":"11838364057","pt":1723187556796,"mc":[{"id":"1.231583502","rc":[{"batb":[[0,2.1,10],[1,2.08,35.1],[2,1.8,2]],"ltp":2.1,"tv":81.83,"id":40096579}]}]}
{"op":"mcm","clk":"11838364240","pt":1723187560277,"mc":[{"id":"1.231583502","rc":[{"batb":[[0,2.08,35.1],[1,1.8,2],[2,1.74,17.32]],"ltp":2.1,"tv":81.83,"id":40096579}]}]}
{"op":"mcm","clk":"11838364337","pt":1723187562689,"mc":[{"id":"1.231583502","rc":[{"batb":[[0,2.1,10],[1,2.08,35.1],[2,1.8,2]],"ltp":2.1,"tv":81.83,"id":40096579}]}]}
{"op":"mcm","clk":"11838364506","pt":1723187566182,"mc":[{"id":"1.231583502","rc":[{"batb":[[0,2.08,35.1],[1,1.8,2],[2,1.74,17.32]],"ltp":2.1,"tv":81.83,"id":40096579}]}]}
{"op":"mcm","clk":"11838364643","pt":1723187569005,"mc":[{"id":"1.231583502","rc":[{"batb":[[0,2.1,10],[1,2.08,35.1],[2,1.8,2]],"ltp":2.1,"tv":81.83,"id":40096579}]}]}
{"op":"mcm","clk":"11838364799","pt":1723187572204,"mc":[{"id":"1.231583502","rc":[{"batb":[[0,2.08,35.1],[1,1.8,2],[2,1.74,17.32]],"ltp":2.1,"tv":81.83,"id":40096579}]}]}
{"op":"mcm","clk":"11838364952","pt":1723187575583,"mc":[{"id":"1.231583502","rc":[{"batb":[[0,2.1,10],[1,2.08,35.1],[2,1.8,2]],"ltp":2.1,"tv":81.83,"id":40096579}]}]}
{"op":"mcm","clk":"11838365100","pt":1723187578917,"mc":[{"id":"1.231583502","rc":[{"batb":[[0,2.08,35.1],[1,1.8,2],[2,1.74,17.32]],"ltp":2.1,"tv":81.83,"id":40096579}]}]}
{"op":"mcm","clk":"11838365238","pt":1723187581390,"mc":[{"id":"1.231583502","rc":[{"batb":[[0,2.1,10],[1,2.08,35.1],[2,1.8,2]],"ltp":2.1,"tv":81.83,"id":40096579}]}]}
{"op":"mcm","clk":"11838365429","pt":1723187584728,"mc":[{"id":"1.231583502","rc":[{"batb":[[0,2.08,35.1],[1,1.8,2],[2,1.74,17.32]],"ltp":2.1,"tv":81.83,"id":40096579}]}]}
{"op":"mcm","clk":"11838365520","pt":1723187586936,"mc":[{"id":"1.231583502","rc":[{"batb":[[0,2.1,10],[1,2.08,35.1],[2,1.8,2]],"ltp":2.1,"tv":81.83,"id":40096579}]}]}
{"op":"mcm","clk":"11838365696","pt":1723187590234,"mc":[{"id":"1.231583502","rc":[{"batb":[[0,2.08,35.1],[1,1.8,2],[2,1.74,17.32]],"ltp":2.1,"tv":81.83,"id":40096579}]}]}
{"op":"mcm","clk":"11838365855","pt":1723187592715,"mc":[{"id":"1.231583502","rc":[{"batb":[[0,2.1,10],[1,2.08,35.1],[2,1.8,2]],"ltp":2.1,"tv":81.83,"id":40096579}]}]}
{"op":"mcm","clk":"11838366094","pt":1723187596734,"mc":[{"id":"1.231583502","rc":[{"batb":[[0,2.08,35.1],[1,1.8,2],[2,1.74,17.32]],"ltp":2.1,"tv":81.83,"id":40096579}]}]}
{"op":"mcm","clk":"11838366213","pt":1723187599053,"mc":[{"id":"1.231583502","rc":[{"batb":[[0,2.1,10],[1,2.08,35.1],[2,1.8,2]],"ltp":2.1,"tv":81.83,"id":40096579}]}]}
{"op":"mcm","clk":"11838366394","pt":1723187602252,"mc":[{"id":"1.231583502","rc":[{"batb":[[0,2.08,35.1],[1,1.8,2],[2,1.74,17.32]],"ltp":2.1,"tv":81.83,"id":40096579}]}]}
{"op":"mcm","clk":"11838366568","pt":1723187605739,"mc":[{"id":"1.231583502","rc":[{"batb":[[0,2.1,10],[1,2.08,35.1],[2,1.8,2]],"ltp":2.1,"tv":81.83,"id":40096579}]}]}
{"op":"mcm","clk":"11838366728","pt":1723187609134,"mc":[{"id":"1.231583502","rc":[{"batb":[[0,2.08,35.1],[1,1.8,2],[2,1.74,17.32]],"ltp":2.1,"tv":81.83,"id":40096579}]}]}
{"op":"mcm","clk":"11838366925","pt":1723187612475,"mc":[{"id":"1.231583502","rc":[{"batb":[[0,2.1,10],[1,2.08,35.1],[2,1.8,2]],"ltp":2.1,"tv":81.83,"id":40096579}]}]}
{"op":"mcm","clk":"11838367091","pt":1723187615655,"mc":[{"id":"1.231583502","rc":[{"batb":[[0,2.08,35.1],[1,1.8,2],[2,1.74,17.32]],"ltp":2.1,"tv":81.83,"id":40096579}]}]}
{"op":"mcm","clk":"11838367261","pt":1723187619246,"mc":[{"id":"1.231583502","rc":[{"batb":[[0,2.1,10],[1,2.08,35.1],[2,1.8,2]],"ltp":2.1,"tv":81.83,"id":40096579}]}]}
{"op":"mcm","clk":"11838367419","pt":1723187622553,"mc":[{"id":"1.231583502","rc":[{"batb":[[0,2.08,35.1],[1,1.8,2],[2,1.74,17.32]],"ltp":2.1,"tv":81.83,"id":40096579}]}]}
{"op":"mcm","clk":"11838367551","pt":1723187625561,"mc":[{"id":"1.231583502","rc":[{"batb":[[0,2.1,10],[1,2.08,35.1],[2,1.8,2]],"ltp":2.1,"tv":81.83,"id":40096579}]}]}
{"op":"mcm","clk":"11838367734","pt":1723187629260,"mc":[{"id":"1.231583502","rc":[{"batb":[[0,2.08,35.1],[1,1.8,2],[2,1.74,17.32]],"ltp":2.1,"tv":81.83,"id":40096579}]}]}
{"op":"mcm","clk":"11838367857","pt":1723187632081,"mc":[{"id":"1.231583502","rc":[{"batb":[[0,2.1,10],[1,2.08,35.1],[2,1.8,2]],"ltp":2.1,"tv":81.83,"id":40096579}]}]}
{"op":"mcm","clk":"11838368041","pt":1723187635671,"mc":[{"id":"1.231583502","rc":[{"batb":[[0,2.08,35.1],[1,1.8,2],[2,1.74,17.32]],"ltp":2.1,"tv":81.83,"id":40096579}]}]}
{"op":"mcm","clk":"11838368130","pt":1723187638074,"mc":[{"id":"1.231583502","rc":[{"batb":[[0,2.1,10],[1,2.08,35.1],[2,1.8,2]],"ltp":2.1,"tv":81.83,"id":40096579}]}]}
{"op":"mcm","clk":"11838368304","pt":1723187641667,"mc":[{"id":"1.231583502","rc":[{"batb":[[0,2.08,35.1],[1,1.8,2],[2,1.74,17.32]],"ltp":2.1,"tv":81.83,"id":40096579}]}]}
{"op":"mcm","clk":"11838368465","pt":1723187644504,"mc":[{"id":"1.231583502","rc":[{"batb":[[0,2.1,10],[1,2.08,35.1],[2,1.8,2]],"ltp":2.1,"tv":81.83,"id":40096579}]}]}
{"op":"mcm","clk":"11838368657","pt":1723187647908,"mc":[{"id":"1.231583502","rc":[{"batb":[[0,2.08,35.1],[1,1.8,2],[2,1.74,17.32]],"ltp":2.1,"tv":81.83,"id":40096579}]}]}
{"op":"mcm","clk":"11838368913","pt":1723187652683,"mc":[{"id":"1.231583502","rc":[{"batb":[[0,2.1,10],[1,2.08,35.1],[2,1.8,2]],"ltp":2.1,"tv":81.83,"id":40096579}]}]}
{"op":"mcm","clk":"11838369102","pt":1723187656727,"mc":[{"id":"1.231583502","rc":[{"batb":[[0,2.08,35.1],[1,1.8,2],[2,1.74,17.32]],"ltp":2.1,"tv":81.83,"id":40096579}]}]}
{"op":"mcm","clk":"11838369209","pt":1723187659500,"mc":[{"id":"1.231583502","rc":[{"batb":[[0,2.1,10],[1,2.08,35.1],[2,1.8,2]],"ltp":2.1,"tv":81.83,"id":40096579}]}]}
{"op":"mcm","clk":"11838369379","pt":1723187662937,"mc":[{"id":"1.231583502","rc":[{"batb":[[0,2.08,35.1],[1,1.8,2],[2,1.74,17.32]],"ltp":2.1,"tv":81.83,"id":40096579}]}]}
{"op":"mcm","clk":"11838369542","pt":1723187666019,"mc":[{"id":"1.231583502","rc":[{"batb":[[0,2.1,10],[1,2.08,35.1],[2,1.8,2]],"ltp":2.1,"tv":81.83,"id":40096579}]}]}
{"op":"mcm","clk":"11838369693","pt":1723187669408,"mc":[{"id":"1.231583502","rc":[{"batb":[[0,2.08,35.1],[1,1.8,2],[2,1.74,17.32]],"ltp":2.1,"tv":81.83,"id":40096579}]}]}
{"op":"mcm","clk":"11838369966","pt":1723187675043,"mc":[{"id":"1.231583502","rc":[{"batb":[[0,2.1,10],[1,2.08,35.1],[2,1.8,2]],"ltp":2.1,"tv":81.83,"id":40096579}]}]}
{"op":"mcm","clk":"11838370123","pt":1723187678539,"mc":[{"id":"1.231583502","rc":[{"batb":[[0,2.08,35.1],[1,1.8,2],[2,1.74,17.32]],"ltp":2.1,"tv":81.83,"id":40096579}]}]}
{"op":"mcm","clk":"11838370260","pt":1723187681361,"mc":[{"id":"1.231583502","rc":[{"batb":[[0,2.1,10],[1,2.08,35.1],[2,1.8,2]],"ltp":2.1,"tv":81.83,"id":40096579}]}]}
{"op":"mcm","clk":"11838370456","pt":1723187684858,"mc":[{"id":"1.231583502","rc":[{"batb":[[0,2.08,35.1],[1,1.8,2],[2,1.74,17.32]],"ltp":2.1,"tv":81.83,"id":40096579}]}]}
{"op":"mcm","clk":"11838370577","pt":1723187687475,"mc":[{"id":"1.231583502","rc":[{"batb":[[0,2.1,10],[1,2.08,35.1],[2,1.8,2]],"ltp":2.1,"tv":81.83,"id":40096579}]}]}
{"op":"mcm","clk":"11838370751","pt":1723187690754,"mc":[{"id":"1.231583502","rc":[{"batb":[[0,2.08,35.1],[1,1.8,2],[2,1.74,17.32]],"ltp":2.1,"tv":81.83,"id":40096579}]}]}
{"op":"mcm","clk":"11838370984","pt":1723187695464,"mc":[{"id":"1.231583502","rc":[{"batb":[[0,2.1,10],[1,2.08,35.1],[2,1.8,2]],"ltp":2.1,"tv":81.83,"id":40096579}]}]}
{"op":"mcm","clk":"11838371121","pt":1723187698792,"mc":[{"id":"1.231583502","rc":[{"batb":[[0,2.08,35.1],[1,1.8,2],[2,1.74,17.32]],"ltp":2.1,"tv":81.83,"id":40096579}]}]}
{"op":"mcm","clk":"11838371239","pt":1723187701363,"mc":[{"id":"1.231583502","rc":[{"batb":[[0,2.1,10],[1,2.08,35.1],[2,1.8,2]],"ltp":2.1,"tv":81.83,"id":40096579}]}]}
{"op":"mcm","clk":"11838371455","pt":1723187704872,"mc":[{"id":"1.231583502","rc":[{"batb":[[0,2.08,35.1],[1,1.8,2],[2,1.74,17.32]],"ltp":2.1,"tv":81.83,"id":40096579}]}]}
{"op":"mcm","clk":"11838371704","pt":1723187709596,"mc":[{"id":"1.231583502","rc":[{"batb":[[0,2.1,10],[1,2.08,35.1],[2,1.8,2]],"ltp":2.1,"tv":81.83,"id":40096579}]}]}
{"op":"mcm","clk":"11838371891","pt":1723187712778,"mc":[{"id":"1.231583502","rc":[{"batb":[[0,2.08,35.1],[1,1.8,2],[2,1.74,17.32]],"ltp":2.1,"tv":81.83,"id":40096579}]}]}
{"op":"mcm","clk":"11838372030","pt":1723187715496,"mc":[{"id":"1.231583502","rc":[{"batb":[[0,2.1,10],[1,2.08,35.1],[2,1.8,2]],"ltp":2.1,"tv":81.83,"id":40096579}]}]}
{"op":"mcm","clk":"11838372222","pt":1723187719193,"mc":[{"id":"1.231583502","rc":[{"batb":[[0,2.08,35.1],[1,1.8,2],[2,1.74,17.32]],"ltp":2.1,"tv":81.83,"id":40096579}]}]}
{"op":"mcm","clk":"11838372356","pt":1723187721800,"mc":[{"id":"1.231583502","rc":[{"batb":[[0,2.1,10],[1,2.08,35.1],[2,1.8,2]],"ltp":2.1,"tv":81.83,"id":40096579}]}]}
{"op":"mcm","clk":"11838372543","pt":1723187725197,"mc":[{"id":"1.231583502","rc":[{"batb":[[0,2.08,35.1],[1,1.8,2],[2,1.74,17.32]],"ltp":2.1,"tv":81.83,"id":40096579}]}]}
{"op":"mcm","clk":"11838372697","pt":1723187728503,"mc":[{"id":"1.231583502","rc":[{"batb":[[0,2.1,10],[1,2.08,35.1],[2,1.8,2]],"ltp":2.1,"tv":81.83,"id":40096579}]}]}
{"op":"mcm","clk":"11838372869","pt":1723187731910,"mc":[{"id":"1.231583502","rc":[{"batb":[[0,2.08,35.1],[1,1.8,2],[2,1.74,17.32]],"ltp":2.1,"tv":81.83,"id":40096579}]}]}
{"op":"mcm","clk":"11838372985","pt":1723187734411,"mc":[{"id":"1.231583502","rc":[{"batb":[[0,2.1,10],[1,2.08,35.1],[2,1.8,2]],"ltp":2.1,"tv":81.83,"id":40096579}]}]}
{"op":"mcm","clk":"11838373152","pt":1723187737806,"mc":[{"id":"1.231583502","rc":[{"batb":[[0,2.08,35.1],[1,1.8,2],[2,1.74,17.32]],"ltp":2.1,"tv":81.83,"id":40096579}]}]}
{"op":"mcm","clk":"11838373289","pt":1723187740732,"mc":[{"id":"1.231583502","rc":[{"batb":[[0,2.1,10],[1,2.08,35.1],[2,1.8,2]],"ltp":2.1,"tv":81.83,"id":40096579}]}]}
{"op":"mcm","clk":"11838373459","pt":1723187744331,"mc":[{"id":"1.231583502","rc":[{"batb":[[0,2.08,35.1],[1,1.8,2],[2,1.74,17.32]],"ltp":2.1,"tv":81.83,"id":40096579}]}]}
{"op":"mcm","clk":"11838373586","pt":1723187746908,"mc":[{"id":"1.231583502","rc":[{"batb":[[0,2.1,10],[1,2.08,35.1],[2,1.8,2]],"ltp":2.1,"tv":81.83,"id":40096579}]}]}
{"op":"mcm","clk":"11838373760","pt":1723187750450,"mc":[{"id":"1.231583502","rc":[{"batb":[[0,2.08,35.1],[1,1.8,2],[2,1.74,17.32]],"ltp":2.1,"tv":81.83,"id":40096579}]}]}
{"op":"mcm","clk":"11838373904","pt":1723187752820,"mc":[{"id":"1.231583502","rc":[{"batb":[[0,2.1,10],[1,2.08,35.1],[2,1.8,2]],"ltp":2.1,"tv":81.83,"id":40096579}]}]}
{"op":"mcm","clk":"11838374076","pt":1723187756153,"mc":[{"id":"1.231583502","rc":[{"batb":[[0,2.08,35.1],[1,1.8,2],[2,1.74,17.32]],"ltp":2.1,"tv":81.83,"id":40096579}]}]}
{"op":"mcm","clk":"11838374202","pt":1723187758832,"mc":[{"id":"1.231583502","rc":[{"batb":[[0,2.1,10],[1,2.08,35.1],[2,1.8,2]],"ltp":2.1,"tv":81.83,"id":40096579}]}]}
{"op":"mcm","clk":"11838374394","pt":1723187762135,"mc":[{"id":"1.231583502","rc":[{"batb":[[0,2.08,35.1],[1,1.8,2],[2,1.74,17.32]],"ltp":2.1,"tv":81.83,"id":40096579}]}]}
{"op":"mcm","clk":"11838374565","pt":1723187765323,"mc":[{"id":"1.231583502","rc":[{"batb":[[0,2.1,10],[1,2.08,35.1],[2,1.8,2]],"ltp":2.1,"tv":81.83,"id":40096579}]}]}
{"op":"mcm","clk":"11838374713","pt":1723187768658,"mc":[{"id":"1.231583502","rc":[{"batb":[[0,2.08,35.1],[1,1.8,2],[2,1.74,17.32]],"ltp":2.1,"tv":81.83,"id":40096579}]}]}
{"op":"mcm","clk":"11838374879","pt":1723187771649,"mc":[{"id":"1.231583502","rc":[{"batb":[[0,2.1,10],[1,2.08,35.1],[2,1.8,2]],"ltp":2.1,"tv":81.83,"id":40096579}]}]}
{"op":"mcm","clk":"11838375072","pt":1723187774946,"mc":[{"id":"1.231583502","rc":[{"batb":[[0,2.08,35.1],[1,1.8,2],[2,1.74,17.32]],"ltp":2.1,"tv":81.83,"id":40096579}]}]}
{"op":"mcm","clk":"11838375212","pt":1723187778073,"mc":[{"id":"1.231583502","rc":[{"batb":[[0,2.1,10],[1,2.08,35.1],[2,1.8,2]],"ltp":2.1,"tv":81.83,"id":40096579}]}]}
{"op":"mcm","clk":"11838375358","pt":1723187781366,"mc":[{"id":"1.231583502","rc":[{"batb":[[0,2.08,35.1],[1,1.8,2],[2,1.74,17.32]],"ltp":2.1,"tv":81.83,"id":40096579}]}]}
{"op":"mcm","clk":"11838375612","pt":1723187785494,"mc":[{"id":"1.231583502","rc":[{"batb":[[0,2.1,10],[1,2.08,35.1],[2,1.8,2]],"ltp":2.1,"tv":81.83,"id":40096579}]}]}
{"op":"mcm","clk":"11838375834","pt":1723187789299,"mc":[{"id":"1.231583502","rc":[{"batb":[[0,2.08,35.1],[1,1.8,2],[2,1.74,17.32]],"ltp":2.1,"tv":81.83,"id":40096579}]}]}
{"op":"mcm","clk":"11838375959","pt":1723187791769,"mc":[{"id":"1.231583502","rc":[{"batb":[[0,2.1,10],[1,2.08,35.1],[2,1.8,2]],"ltp":2.1,"tv":81.83,"id":40096579}]}]}
{"op":"mcm","clk":"11838376027","pt":1723187793158,"mc":[{"id":"1.231583502","rc":[{"batb":[[0,1.85,200],[1,1.84,12.61],[2,1.83,257]],"ltp":1.91,"tv":16.43,"id":40096580}]}]}
{"op":"mcm","clk":"11838376122","pt":1723187795267,"mc":[{"id":"1.231583502","rc":[{"batb":[[0,2.08,35.1],[1,1.8,2],[2,1.74,17.32]],"ltp":2.1,"tv":81.83,"id":40096579},{"batb":[[1,1.83,257],[2,1.81,200]],"ltp":1.91,"tv":16.43,"id":40096580}]}]}
{"op":"mcm","clk":"11838376270","pt":1723187797892,"mc":[{"id":"1.231583502","rc":[{"batb":[[0,1.86,200],[1,1.85,200],[2,1.83,257]],"ltp":1.91,"tv":16.43,"id":40096580}]}]}
{"op":"mcm","clk":"11838376683","pt":1723187805906,"mc":[{"id":"1.231583502","rc":[{"batb":[[0,1.85,200],[1,1.83,257],[2,1.81,200]],"ltp":1.91,"tv":16.43,"id":40096580}]}]}
{"op":"mcm","clk":"11838376743","pt":1723187807290,"mc":[{"id":"1.231583502","rc":[{"batb":[[0,1.83,257],[1,1.81,200],[2,1.8,224.6]],"ltp":1.91,"tv":16.43,"id":40096580}]}]}
{"op":"mcm","clk":"11838422669","pt":1723188552994,"mc":[{"id":"1.231583502","rc":[{"batl":[[0,2.2,10.4]],"ltp":2.1,"tv":81.83,"id":40096579},{"batb":[[0,1.84,12.62],[1,1.83,257],[2,1.81,200]],"ltp":1.91,"tv":16.43,"id":40096580}]}]}
{"op":"mcm","clk":"11838422675","pt":1723188553094,"mc":[{"id":"1.231583502","rc":[{"batb":[[0,2.1,10],[1,2.08,35.1],[2,1.8,2]],"ltp":2.1,"tv":81.83,"id":40096579}]}]}
{"op":"mcm","clk":"11838422902","pt":1723188556491,"mc":[{"id":"1.231583502","rc":[{"batb":[[0,2.08,35.1],[1,1.8,2],[2,1.74,17.32]],"ltp":2.1,"tv":81.83,"id":40096579}]}]}
{"op":"mcm","clk":"11838423049","pt":1723188559005,"mc":[{"id":"1.231583502","rc":[{"batb":[[0,2.1,10],[1,2.08,35.1],[2,1.8,2]],"ltp":2.1,"tv":81.83,"id":40096579}]}]}
{"op":"mcm","clk":"11838423248","pt":1723188562606,"mc":[{"id":"1.231583502","rc":[{"batb":[[0,2.08,35.1],[1,1.8,2],[2,1.74,17.32]],"ltp":2.1,"tv":81.83,"id":40096579}]}]}
{"op":"mcm","clk":"11838423414","pt":1723188564818,"mc":[{"id":"1.231583502","rc":[{"batb":[[0,2.1,10],[1,2.08,35.1],[2,1.8,2]],"ltp":2.1,"tv":81.83,"id":40096579}]}]}
{"op":"mcm","clk":"11838423618","pt":1723188568114,"mc":[{"id":"1.231583502","rc":[{"batb":[[0,2.08,35.1],[1,1.8,2],[2,1.74,17.32]],"ltp":2.1,"tv":81.83,"id":40096579}]}]}
{"op":"mcm","clk":"11838423760","pt":1723188570589,"mc":[{"id":"1.231583502","rc":[{"batb":[[0,2.1,10],[1,2.08,35.1],[2,1.8,2]],"ltp":2.1,"tv":81.83,"id":40096579}]}]}
{"op":"mcm","clk":"11838423986","pt":1723188574090,"mc":[{"id":"1.231583502","rc":[{"batb":[[0,2.08,35.1],[1,1.8,2],[2,1.74,17.32]],"ltp":2.1,"tv":81.83,"id":40096579}]}]}
{"op":"mcm","clk":"11838424169","pt":1723188577525,"mc":[{"id":"1.231583502","rc":[{"batb":[[0,2.1,10],[1,2.08,35.1],[2,1.8,2]],"ltp":2.1,"tv":81.83,"id":40096579}]}]}
{"op":"mcm","clk":"11838424370","pt":1723188580919,"mc":[{"id":"1.231583502","rc":[{"batb":[[0,2.08,35.1],[1,1.8,2],[2,1.74,17.32]],"ltp":2.1,"tv":81.83,"id":40096579}]}]}
{"op":"mcm","clk":"11838424495","pt":1723188583229,"mc":[{"id":"1.231583502","rc":[{"batb":[[0,2.1,10],[1,2.08,35.1],[2,1.8,2]],"ltp":2.1,"tv":81.83,"id":40096579}]}]}
{"op":"mcm","clk":"11838424672","pt":1723188586530,"mc":[{"id":"1.231583502","rc":[{"batb":[[0,2.08,35.1],[1,1.8,2],[2,1.74,17.32]],"ltp":2.1,"tv":81.83,"id":40096579}]}]}
{"op":"mcm","clk":"11838424810","pt":1723188589108,"mc":[{"id":"1.231583502","rc":[{"batb":[[0,2.1,10],[1,2.08,35.1],[2,1.8,2]],"ltp":2.1,"tv":81.83,"id":40096579}]}]}
{"op":"mcm","clk":"11838424981","pt":1723188592343,"mc":[{"id":"1.231583502","rc":[{"batb":[[0,2.08,35.1],[1,1.8,2],[2,1.74,17.32]],"ltp":2.1,"tv":81.83,"id":40096579}]}]}
{"op":"mcm","clk":"11838425144","pt":1723188594609,"mc":[{"id":"1.231583502","rc":[{"batb":[[0,2.1,10],[1,2.08,35.1],[2,1.8,2]],"ltp":2.1,"tv":81.83,"id":40096579}]}]}
{"op":"mcm","clk":"11838425321","pt":1723188598057,"mc":[{"id":"1.231583502","rc":[{"batb":[[0,2.08,35.1],[1,1.8,2],[2,1.74,17.32]],"ltp":2.1,"tv":81.83,"id":40096579}]}]}
{"op":"mcm","clk":"11838425465","pt":1723188600631,"mc":[{"id":"1.231583502","rc":[{"batb":[[0,2.1,10],[1,2.08,35.1],[2,1.8,2]],"ltp":2.1,"tv":81.83,"id":40096579}]}]}
{"op":"mcm","clk":"11838425699","pt":1723188603928,"mc":[{"id":"1.231583502","rc":[{"batb":[[0,2.08,35.1],[1,1.8,2],[2,1.74,17.32]],"ltp":2.1,"tv":81.83,"id":40096579}]}]}
{"op":"mcm","clk":"11838425870","pt":1723188606242,"mc":[{"id":"1.231583502","rc":[{"batb":[[0,2.1,10],[1,2.08,35.1],[2,1.8,2]],"ltp":2.1,"tv":81.83,"id":40096579}]}]}
{"op":"mcm","clk":"11838426130","pt":1723188609741,"mc":[{"id":"1.231583502","rc":[{"batb":[[0,2.08,35.1],[1,1.8,2],[2,1.74,17.32]],"ltp":2.1,"tv":81.83,"id":40096579}]}]}
{"op":"mcm","clk":"11838426266","pt":1723188612057,"mc":[{"id":"1.231583502","rc":[{"batb":[[0,2.1,10],[1,2.08,35.1],[2,1.8,2]],"ltp":2.1,"tv":81.83,"id":40096579}]}]}
{"op":"mcm","clk":"11838426512","pt":1723188615665,"mc":[{"id":"1.231583502","rc":[{"batb":[[0,2.08,35.1],[1,1.8,2],[2,1.74,17.32]],"ltp":2.1,"tv":81.83,"id":40096579}]}]}
{"op":"mcm","clk":"11838426651","pt":1723188618076,"mc":[{"id":"1.231583502","rc":[{"batb":[[0,2.1,10],[1,2.08,35.1],[2,1.8,2]],"ltp":2.1,"tv":81.83,"id":40096579}]}]}
{"op":"mcm","clk":"11838426868","pt":1723188621361,"mc":[{"id":"1.231583502","rc":[{"batb":[[0,2.08,35.1],[1,1.8,2],[2,1.74,17.32]],"ltp":2.1,"tv":81.83,"id":40096579}]}]}
{"op":"mcm","clk":"11838427031","pt":1723188623794,"mc":[{"id":"1.231583502","rc":[{"batb":[[0,2.1,10],[1,2.08,35.1],[2,1.8,2]],"ltp":2.1,"tv":81.83,"id":40096579}]}]}
{"op":"mcm","clk":"11838427266","pt":1723188627089,"mc":[{"id":"1.231583502","rc":[{"batb":[[0,2.08,35.1],[1,1.8,2],[2,1.74,17.32]],"ltp":2.1,"tv":81.83,"id":40096579}]}]}
{"op":"mcm","clk":"11838427403","pt":1723188629303,"mc":[{"id":"1.231583502","rc":[{"batb":[[0,2.1,10],[1,2.08,35.1],[2,1.8,2]],"ltp":2.1,"tv":81.83,"id":40096579}]}]}
{"op":"mcm","clk":"11838427618","pt":1723188632700,"mc":[{"id":"1.231583502","rc":[{"batb":[[0,2.08,35.1],[1,1.8,2],[2,1.74,17.32]],"ltp":2.1,"tv":81.83,"id":40096579}]}]}
{"op":"mcm","clk":"11838427842","pt":1723188636201,"mc":[{"id":"1.231583502","rc":[{"batb":[[0,2.1,10],[1,2.08,35.1],[2,1.8,2]],"ltp":2.1,"tv":81.83,"id":40096579}]}]}
{"op":"mcm","clk":"11838428077","pt":1723188639711,"mc":[{"id":"1.231583502","rc":[{"batb":[[0,2.08,35.1],[1,1.8,2],[2,1.74,17.32]],"ltp":2.1,"tv":81.83,"id":40096579}]}]}
{"op":"mcm","clk":"11838428202","pt":1723188641874,"mc":[{"id":"1.231583502","rc":[{"batb":[[0,2.1,10],[1,2.08,35.1],[2,1.8,2]],"ltp":2.1,"tv":81.83,"id":40096579}]}]}
{"op":"mcm","clk":"11838428440","pt":1723188645429,"mc":[{"id":"1.231583502","rc":[{"batb":[[0,2.08,35.1],[1,1.8,2],[2,1.74,17.32]],"ltp":2.1,"tv":81.83,"id":40096579}]}]}
{"op":"mcm","clk":"11838428602","pt":1723188648007,"mc":[{"id":"1.231583502","rc":[{"batb":[[0,2.1,10],[1,2.08,35.1],[2,1.8,2]],"ltp":2.1,"tv":81.83,"id":40096579}]}]}
{"op":"mcm","clk":"11838428821","pt":1723188651404,"mc":[{"id":"1.231583502","rc":[{"batb":[[0,2.08,35.1],[1,1.8,2],[2,1.74,17.32]],"ltp":2.1,"tv":81.83,"id":40096579}]}]}
{"op":"mcm","clk":"11838429007","pt":1723188653922,"mc":[{"id":"1.231583502","rc":[{"batb":[[0,2.1,10],[1,2.08,35.1],[2,1.8,2]],"ltp":2.1,"tv":81.83,"id":40096579}]}]}
{"op":"mcm","clk":"11838429175","pt":1723188657313,"mc":[{"id":"1.231583502","rc":[{"batb":[[0,2.08,35.1],[1,1.8,2],[2,1.74,17.32]],"ltp":2.1,"tv":81.83,"id":40096579}]}]}
{"op":"mcm","clk":"11838429325","pt":1723188659827,"mc":[{"id":"1.231583502","rc":[{"batb":[[0,2.1,10],[1,2.08,35.1],[2,1.8,2]],"ltp":2.1,"tv":81.83,"id":40096579}]}]}
{"op":"mcm","clk":"11838429529","pt":1723188663229,"mc":[{"id":"1.231583502","rc":[{"batb":[[0,2.08,35.1],[1,1.8,2],[2,1.74,17.32]],"ltp":2.1,"tv":81.83,"id":40096579}]}]}
{"op":"mcm","clk":"11838429731","pt":1723188665902,"mc":[{"id":"1.231583502","rc":[{"batb":[[0,2.1,10],[1,2.08,35.1],[2,1.8,2]],"ltp":2.1,"tv":81.83,"id":40096579}]}]}
{"op":"mcm","clk":"11838429975","pt":1723188669355,"mc":[{"id":"1.231583502","rc":[{"batb":[[0,2.08,35.1],[1,1.8,2],[2,1.74,17.32]],"ltp":2.1,"tv":81.83,"id":40096579}]}]}
{"op":"mcm","clk":"11838430162","pt":1723188672141,"mc":[{"id":"1.231583502","rc":[{"batb":[[0,2.1,10],[1,2.08,35.1],[2,1.8,2]],"ltp":2.1,"tv":81.83,"id":40096579}]}]}
{"op":"mcm","clk":"11838430364","pt":1723188675344,"mc":[{"id":"1.231583502","rc":[{"batb":[[0,2.08,35.1],[1,1.8,2],[2,1.74,17.32]],"ltp":2.1,"tv":81.83,"id":40096579}]}]}
{"op":"mcm","clk":"11838430496","pt":1723188677554,"mc":[{"id":"1.231583502","rc":[{"batb":[[0,2.1,10],[1,2.08,35.1],[2,1.8,2]],"ltp":2.1,"tv":81.83,"id":40096579}]}]}
{"op":"mcm","clk":"11838430716","pt":1723188680751,"mc":[{"id":"1.231583502","rc":[{"batb":[[0,2.08,35.1],[1,1.8,2],[2,1.74,17.32]],"ltp":2.1,"tv":81.83,"id":40096579}]}]}
{"op":"mcm","clk":"11838430974","pt":1723188684366,"mc":[{"id":"1.231583502","rc":[{"batb":[[0,2.1,10],[1,2.08,35.1],[2,1.8,2]],"ltp":2.1,"tv":81.83,"id":40096579}]}]}
{"op":"mcm","clk":"11838431188","pt":1723188687652,"mc":[{"id":"1.231583502","rc":[{"batb":[[0,2.08,35.1],[1,1.8,2],[2,1.74,17.32]],"ltp":2.1,"tv":81.83,"id":40096579}]}]}
{"op":"mcm","clk":"11838431380","pt":1723188690644,"mc":[{"id":"1.231583502","rc":[{"batb":[[0,2.1,10],[1,2.08,35.1],[2,1.8,2]],"ltp":2.1,"tv":81.83,"id":40096579}]}]}
{"op":"mcm","clk":"11838431630","pt":1723188694143,"mc":[{"id":"1.231583502","rc":[{"batb":[[0,2.08,35.1],[1,1.8,2],[2,1.74,17.32]],"ltp":2.1,"tv":81.83,"id":40096579}]}]}
{"op":"mcm","clk":"11838431821","pt":1723188696979,"mc":[{"id":"1.231583502","rc":[{"batb":[[0,2.1,10],[1,2.08,35.1],[2,1.8,2]],"ltp":2.1,"tv":81.83,"id":40096579}]}]}
{"op":"mcm","clk":"11838432030","pt":1723188700273,"mc":[{"id":"1.231583502","rc":[{"batb":[[0,2.08,35.1],[1,1.8,2],[2,1.74,17.32]],"ltp":2.1,"tv":81.83,"id":40096579}]}]}
{"op":"mcm","clk":"11838432159","pt":1723188702493,"mc":[{"id":"1.231583502","rc":[{"batb":[[0,2.1,10],[1,2.08,35.1],[2,1.8,2]],"ltp":2.1,"tv":81.83,"id":40096579}]}]}
{"op":"mcm","clk":"11838432382","pt":1723188705988,"mc":[{"id":"1.231583502","rc":[{"batb":[[0,2.08,35.1],[1,1.8,2],[2,1.74,17.32]],"ltp":2.1,"tv":81.83,"id":40096579}]}]}
{"op":"mcm","clk":"11838432672","pt":1723188709995,"mc":[{"id":"1.231583502","rc":[{"batb":[[0,2.1,10],[1,2.08,35.1],[2,1.8,2]],"ltp":2.1,"tv":81.83,"id":40096579}]}]}
{"op":"mcm","clk":"11838432920","pt":1723188713510,"mc":[{"id":"1.231583502","rc":[{"batb":[[0,2.08,35.1],[1,1.8,2],[2,1.74,17.32]],"ltp":2.1,"tv":81.83,"id":40096579}]}]}
{"op":"mcm","clk":"11838433049","pt":1723188715679,"mc":[{"id":"1.231583502","rc":[{"batb":[[0,2.1,10],[1,2.08,35.1],[2,1.8,2]],"ltp":2.1,"tv":81.83,"id":40096579}]}]}
{"op":"mcm","clk":"11838433226","pt":1723188719014,"mc":[{"id":"1.231583502","rc":[{"batb":[[0,2.08,35.1],[1,1.8,2],[2,1.74,17.32]],"ltp":2.1,"tv":81.83,"id":40096579}]}]}
{"op":"mcm","clk":"11838433379","pt":1723188721199,"mc":[{"id":"1.231583502","rc":[{"batb":[[0,2.1,10],[1,2.08,35.1],[2,1.8,2]],"ltp":2.1,"tv":81.83,"id":40096579}]}]}
{"op":"mcm","clk":"11838433630","pt":1723188724598,"mc":[{"id":"1.231583502","rc":[{"batb":[[0,2.08,35.1],[1,1.8,2],[2,1.74,17.32]],"ltp":2.1,"tv":81.83,"id":40096579}]}]}
{"op":"mcm","clk":"11838433890","pt":1723188728206,"mc":[{"id":"1.231583502","rc":[{"batb":[[0,2.1,10],[1,2.08,35.1],[2,1.8,2]],"ltp":2.1,"tv":81.83,"id":40096579}]}]}
{"op":"mcm","clk":"11838434088","pt":1723188731701,"mc":[{"id":"1.231583502","rc":[{"batb":[[0,2.08,35.1],[1,1.8,2],[2,1.74,17.32]],"ltp":2.1,"tv":81.83,"id":40096579}]}]}
{"op":"mcm","clk":"11838434262","pt":1723188734225,"mc":[{"id":"1.231583502","rc":[{"batb":[[0,2.1,10],[1,2.08,35.1],[2,1.8,2]],"ltp":2.1,"tv":81.83,"id":40096579}]}]}
{"op":"mcm","clk":"11838434460","pt":1723188737828,"mc":[{"id":"1.231583502","rc":[{"batb":[[0,2.08,35.1],[1,1.8,2],[2,1.74,17.32]],"ltp":2.1,"tv":81.83,"id":40096579}]}]}
{"op":"mcm","clk":"11838434735","pt":1723188742117,"mc":[{"id":"1.231583502","rc":[{"batb":[[0,2.1,10],[1,2.08,35.1],[2,1.8,2]],"ltp":2.1,"tv":81.83,"id":40096579}]}]}
{"op":"mcm","clk":"11838434944","pt":1723188745420,"mc":[{"id":"1.231583502","rc":[{"batb":[[0,2.08,35.1],[1,1.8,2],[2,1.74,17.32]],"ltp":2.1,"tv":81.83,"id":40096579}]}]}
{"op":"mcm","clk":"11838479507","pt":1723189567275,"mc":[{"id":"1.231583502","rc":[{"batl":[[1,1000,0.02]],"ltp":2.1,"tv":81.83,"id":40096579},{"batl":[[0,1000,0.02]],"ltp":1.91,"tv":16.43,"id":40096580}]}]}
{"op":"mcm","clk":"11838520924","pt":1723190400742,"mc":[{"id":"1.231583502","rc":[{"batb":[[0,2.1,10],[1,2.08,35.1],[2,1.8,2]],"ltp":2.1,"tv":81.83,"id":40096579},{"batb":[[0,1.85,10],[1,1.84,12.62],[2,1.83,257]],"ltp":1.91,"tv":16.43,"id":40096580}]}]}
{"op":"mcm","clk":"11838521192","pt":1723190404266,"mc":[{"id":"1.231583502","rc":[{"trd":[[1.28,3.13],[1.3,3.13]],"batb":[[0,2.08,35.1],[1,1.8,2],[2,1.74,17.32]],"ltp":2.1,"tv":81.84,"id":40096579},{"trd":[[1.3,4.7]],"batb":[[0,1.84,12.62],[1,1.83,257],[2,1.81,200]],"ltp":1.91,"tv":16.44,"id":40096580}],"tv":98.28}]}
{"op":"mcm","clk":"11838521393","pt":1723190406544,"mc":[{"id":"1.231583502","rc":[{"batb":[[0,2.1,10],[1,2.08,35.1],[2,1.8,2]],"ltp":2.1,"tv":81.84,"id":40096579},{"batb":[[0,1.85,10],[1,1.84,12.62],[2,1.83,257]],"ltp":1.91,"tv":16.44,"id":40096580}]}]}
{"op":"mcm","clk":"11838521619","pt":1723190410259,"mc":[{"id":"1.231583502","rc":[{"batb":[[0,2.08,35.1],[1,1.8,2],[2,1.74,17.32]],"ltp":2.1,"tv":81.84,"id":40096579},{"batb":[[0,1.84,12.62],[1,1.83,257],[2,1.81,200]],"ltp":1.91,"tv":16.44,"id":40096580}]}]}
{"op":"mcm","clk":"11838521906","pt":1723190414347,"mc":[{"id":"1.231583502","rc":[{"batb":[[0,2.1,10],[1,2.08,35.1],[2,1.8,2]],"ltp":2.1,"tv":81.84,"id":40096579},{"batb":[[0,1.85,10],[1,1.84,12.62],[2,1.83,257]],"ltp":1.91,"tv":16.44,"id":40096580}]}]}
{"op":"mcm","clk":"11838522160","pt":1723190417649,"mc":[{"id":"1.231583502","rc":[{"batb":[[0,2.08,35.1],[1,1.8,2],[2,1.74,17.32]],"ltp":2.1,"tv":81.84,"id":40096579},{"batb":[[0,1.84,12.62],[1,1.83,257],[2,1.81,200]],"ltp":1.91,"tv":16.44,"id":40096580}]}]}
{"op":"mcm","clk":"11838522299","pt":1723190420177,"mc":[{"id":"1.231583502","rc":[{"batb":[[0,2.1,10],[1,2.08,35.1],[2,1.8,2]],"ltp":2.1,"tv":81.84,"id":40096579},{"batb":[[0,1.85,10],[1,1.84,12.62],[2,1.83,257]],"ltp":1.91,"tv":16.44,"id":40096580}]}]}
{"op":"mcm","clk":"11838522573","pt":1723190423842,"mc":[{"id":"1.231583502","rc":[{"batb":[[0,2.08,35.1],[1,1.8,2],[2,1.74,17.32]],"ltp":2.1,"tv":81.84,"id":40096579},{"batb":[[0,1.84,12.62],[1,1.83,257],[2,1.81,200]],"ltp":1.91,"tv":16.44,"id":40096580}]}]}
{"op":"mcm","clk":"11838522707","pt":1723190426368,"mc":[{"id":"1.231583502","rc":[{"batb":[[0,2.1,10],[1,2.08,35.1],[2,1.8,2]],"ltp":2.1,"tv":81.84,"id":40096579},{"batb":[[0,1.85,10],[1,1.84,12.62],[2,1.83,257]],"ltp":1.91,"tv":16.44,"id":40096580}]}]}
{"op":"mcm","clk":"11838522898","pt":1723190429782,"mc":[{"id":"1.231583502","rc":[{"batb":[[0,2.08,35.1],[1,1.8,2],[2,1.74,17.32]],"ltp":2.1,"tv":81.84,"id":40096579},{"batb":[[0,1.84,12.62],[1,1.83,257],[2,1.81,200]],"ltp":1.91,"tv":16.44,"id":40096580}]}]}
{"op":"mcm","clk":"11838523172","pt":1723190433663,"mc":[{"id":"1.231583502","rc":[{"batb":[[0,2.1,10],[1,2.08,35.1],[2,1.8,2]],"ltp":2.1,"tv":81.84,"id":40096579},{"batb":[[0,1.85,10],[1,1.84,12.62],[2,1.83,257]],"ltp":1.91,"tv":16.44,"id":40096580}]}]}
{"op":"mcm","clk":"11838523433","pt":1723190437281,"mc":[{"id":"1.231583502","rc":[{"batb":[[0,2.08,35.1],[1,1.8,2],[2,1.74,17.32]],"ltp":2.1,"tv":81.84,"id":40096579},{"batb":[[0,1.84,12.62],[1,1.83,257],[2,1.81,200]],"ltp":1.91,"tv":16.44,"id":40096580}]}]}
{"op":"mcm","clk":"11838523683","pt":1723190441161,"mc":[{"id":"1.231583502","rc":[{"batb":[[0,2.1,10],[1,2.08,35.1],[2,1.8,2]],"ltp":2.1,"tv":81.84,"id":40096579},{"batb":[[0,1.85,10],[1,1.84,12.62],[2,1.83,257]],"ltp":1.91,"tv":16.44,"id":40096580}]}]}
{"op":"mcm","clk":"11838523903","pt":1723190444669,"mc":[{"id":"1.231583502","rc":[{"batb":[[0,2.08,35.1],[1,1.8,2],[2,1.74,17.32]],"ltp":2.1,"tv":81.84,"id":40096579},{"batb":[[0,1.84,12.62],[1,1.83,257],[2,1.81,200]],"ltp":1.91,"tv":16.44,"id":40096580}]}]}
{"op":"mcm","clk":"11838524110","pt":1723190447877,"mc":[{"id":"1.231583502","rc":[{"batb":[[0,2.1,10],[1,2.08,35.1],[2,1.8,2]],"ltp":2.1,"tv":81.84,"id":40096579},{"batb":[[0,1.85,10],[1,1.84,12.62],[2,1.83,257]],"ltp":1.91,"tv":16.44,"id":40096580}]}]}
{"op":"mcm","clk":"11838524319","pt":1723190451281,"mc":[{"id":"1.231583502","rc":[{"batb":[[0,2.08,35.1],[1,1.8,2],[2,1.74,17.32]],"ltp":2.1,"tv":81.84,"id":40096579},{"batb":[[0,1.84,12.62],[1,1.83,257],[2,1.81,200]],"ltp":1.91,"tv":16.44,"id":40096580}]}]}
{"op":"mcm","clk":"11838524429","pt":1723190453699,"mc":[{"id":"1.231583502","rc":[{"batb":[[0,2.1,10],[1,2.08,35.1],[2,1.8,2]],"ltp":2.1,"tv":81.84,"id":40096579},{"batb":[[0,1.85,10],[1,1.84,12.62],[2,1.83,257]],"ltp":1.91,"tv":16.44,"id":40096580}]}]}
{"op":"mcm","clk":"11838524628","pt":1723190457201,"mc":[{"id":"1.231583502","rc":[{"batb":[[0,2.08,35.1],[1,1.8,2],[2,1.74,17.32]],"ltp":2.1,"tv":81.84,"id":40096579},{"batb":[[0,1.84,12.62],[1,1.83,257],[2,1.81,200]],"ltp":1.91,"tv":16.44,"id":40096580}]}]}
{"op":"mcm","clk":"11838524746","pt":1723190459628,"mc":[{"id":"1.231583502","rc":[{"batb":[[0,2.1,10],[1,2.08,35.1],[2,1.8,2]],"ltp":2.1,"tv":81.84,"id":40096579},{"batb":[[0,1.85,10],[1,1.84,12.62],[2,1.83,257]],"ltp":1.91,"tv":16.44,"id":40096580}]}]}
{"op":"mcm","clk":"11838524954","pt":1723190463134,"mc":[{"id":"1.231583502","rc":[{"batb":[[0,2.08,35.1],[1,1.8,2],[2,1.74,17.32]],"ltp":2.1,"tv":81.84,"id":40096579},{"batb":[[0,1.84,12.62],[1,1.83,257],[2,1.81,200]],"ltp":1.91,"tv":16.44,"id":40096580}]}]}
{"op":"mcm","clk":"11838525090","pt":1723190465917,"mc":[{"id":"1.231583502","rc":[{"batb":[[0,2.1,10],[1,2.08,35.1],[2,1.8,2]],"ltp":2.1,"tv":81.84,"id":40096579},{"batb":[[0,1.85,10],[1,1.84,12.62],[2,1.83,257]],"ltp":1.91,"tv":16.44,"id":40096580}]}]}
{"op":"mcm","clk":"11838525317","pt":1723190469503,"mc":[{"id":"1.231583502","rc":[{"batb":[[0,2.08,35.1],[1,1.8,2],[2,1.74,17.32]],"ltp":2.1,"tv":81.84,"id":40096579},{"batb":[[0,1.84,12.62],[1,1.83,257],[2,1.81,200]],"ltp":1.91,"tv":16.44,"id":40096580}]}]}
{"op":"mcm","clk":"11838525442","pt":1723190471723,"mc":[{"id":"1.231583502","rc":[{"batb":[[0,2.1,10],[1,2.08,35.1],[2,1.8,2]],"ltp":2.1,"tv":81.84,"id":40096579},{"batb":[[0,1.85,10],[1,1.84,12.62],[2,1.83,257]],"ltp":1.91,"tv":16.44,"id":40096580}]}]}
{"op":"mcm","clk":"11838525583","pt":1723190474914,"mc":[{"id":"1.231583502","rc":[{"batb":[[0,2.08,35.1],[1,1.8,2],[2,1.74,17.32]],"ltp":2.1,"tv":81.84,"id":40096579}]}]}
{"op":"mcm","clk":"11838525589","pt":1723190475017,"mc":[{"id":"1.231583502","rc":[{"batb":[[0,1.84,12.62],[1,1.83,257],[2,1.81,200]],"ltp":1.91,"tv":16.44,"id":40096580}]}]}
{"op":"mcm","clk":"11838525749","pt":1723190478008,"mc":[{"id":"1.231583502","rc":[{"batb":[[0,2.1,10],[1,2.08,35.1],[2,1.8,2]],"ltp":2.1,"tv":81.84,"id":40096579},{"batb":[[0,1.85,10],[1,1.84,12.62],[2,1.83,257]],"ltp":1.91,"tv":16.44,"id":40096580}]}]}
{"op":"mcm","clk":"11838525955","pt":1723190481447,"mc":[{"id":"1.231583502","rc":[{"batb":[[0,2.08,35.1],[1,1.8,2],[2,1.74,17.32]],"ltp":2.1,"tv":81.84,"id":40096579},{"batb":[[0,1.84,12.62],[1,1.83,257],[2,1.81,200]],"ltp":1.91,"tv":16.44,"id":40096580}]}]}
{"op":"mcm","clk":"11838526112","pt":1723190483862,"mc":[{"id":"1.231583502","rc":[{"batb":[[0,2.1,10],[1,2.08,35.1],[2,1.8,2]],"ltp":2.1,"tv":81.84,"id":40096579},{"batb":[[0,1.85,10],[1,1.84,12.62],[2,1.83,257]],"ltp":1.91,"tv":16.44,"id":40096580}]}]}
{"op":"mcm","clk":"11838526275","pt":1723190487259,"mc":[{"id":"1.231583502","rc":[{"batb":[[0,2.08,35.1],[1,1.8,2],[2,1.74,17.32]],"ltp":2.1,"tv":81.84,"id":40096579},{"batb":[[0,1.84,12.62],[1,1.83,257],[2,1.81,200]],"ltp":1.91,"tv":16.44,"id":40096580}]}]}
{"op":"mcm","clk":"11838526440","pt":1723190489939,"mc":[{"id":"1.231583502","rc":[{"batb":[[0,2.1,10],[1,2.08,35.1],[2,1.8,2]],"ltp":2.1,"tv":81.84,"id":40096579},{"batb":[[0,1.85,10],[1,1.84,12.62],[2,1.83,257]],"ltp":1.91,"tv":16.44,"id":40096580}]}]}
{"op":"mcm","clk":"11838526658","pt":1723190493461,"mc":[{"id":"1.231583502","rc":[{"batb":[[0,2.08,35.1],[1,1.8,2],[2,1.74,17.32]],"ltp":2.1,"tv":81.84,"id":40096579},{"batb":[[0,1.84,12.62],[1,1.83,257],[2,1.81,200]],"ltp":1.91,"tv":16.44,"id":40096580}]}]}
{"op":"mcm","clk":"11838526830","pt":1723190496244,"mc":[{"id":"1.231583502","rc":[{"batb":[[0,2.1,10],[1,2.08,35.1],[2,1.8,2]],"ltp":2.1,"tv":81.84,"id":40096579},{"batb":[[0,1.85,10],[1,1.84,12.62],[2,1.83,257]],"ltp":1.91,"tv":16.44,"id":40096580}]}]}
{"op":"mcm","clk":"11838527065","pt":1723190499743,"mc":[{"id":"1.231583502","rc":[{"batb":[[0,2.08,35.1],[1,1.8,2],[2,1.74,17.32]],"ltp":2.1,"tv":81.84,"id":40096579},{"batb":[[0,1.84,12.62],[1,1.83,257],[2,1.81,200]],"ltp":1.91,"tv":16.44,"id":40096580}]}]}
{"op":"mcm","clk":"11838527222","pt":1723190502583,"mc":[{"id":"1.231583502","rc":[{"batb":[[0,2.1,10],[1,2.08,35.1],[2,1.8,2]],"ltp":2.1,"tv":81.84,"id":40096579},{"batb":[[0,1.85,10],[1,1.84,12.62],[2,1.83,257]],"ltp":1.91,"tv":16.44,"id":40096580}]}]}
{"op":"mcm","clk":"11838527407","pt":1723190505977,"mc":[{"id":"1.231583502","rc":[{"batb":[[0,2.08,35.1],[1,1.8,2],[2,1.74,17.32]],"ltp":2.1,"tv":81.84,"id":40096579},{"batb":[[0,1.84,12.62],[1,1.83,257],[2,1.81,200]],"ltp":1.91,"tv":16.44,"id":40096580}]}]}
{"op":"mcm","clk":"11838527593","pt":1723190509268,"mc":[{"id":"1.231583502","rc":[{"batb":[[0,2.1,10],[1,2.08,35.1],[2,1.8,2]],"ltp":2.1,"tv":81.84,"id":40096579},{"batb":[[0,1.85,10],[1,1.84,12.62],[2,1.83,257]],"ltp":1.91,"tv":16.44,"id":40096580}]}]}
{"op":"mcm","clk":"11838527813","pt":1723190513184,"mc":[{"id":"1.231583502","rc":[{"batb":[[0,2.08,35.1],[1,1.8,2],[2,1.74,17.32]],"ltp":2.1,"tv":81.84,"id":40096579},{"batb":[[0,1.84,12.62],[1,1.83,257],[2,1.81,200]],"ltp":1.91,"tv":16.44,"id":40096580}]}]}
{"op":"mcm","clk":"11838527910","pt":1723190515400,"mc":[{"id":"1.231583502","rc":[{"batb":[[0,2.1,10],[1,2.08,35.1],[2,1.8,2]],"ltp":2.1,"tv":81.84,"id":40096579},{"batb":[[0,1.85,10],[1,1.84,12.62],[2,1.83,257]],"ltp":1.91,"tv":16.44,"id":40096580}]}]}
{"op":"mcm","clk":"11838528083","pt":1723190518601,"mc":[{"id":"1.231583502","rc":[{"batb":[[0,2.08,35.1],[1,1.8,2],[2,1.74,17.32]],"ltp":2.1,"tv":81.84,"id":40096579},{"batb":[[0,1.84,12.62],[1,1.83,257],[2,1.81,200]],"ltp":1.91,"tv":16.44,"id":40096580}]}]}
{"op":"mcm","clk":"11838528312","pt":1723190522523,"mc":[{"id":"1.231583502","rc":[{"batb":[[0,2.1,10],[1,2.08,35.1],[2,1.8,2]],"ltp":2.1,"tv":81.84,"id":40096579},{"batb":[[0,1.85,10],[1,1.84,12.62],[2,1.83,257]],"ltp":1.91,"tv":16.44,"id":40096580}]}]}
{"op":"mcm","clk":"11838528600","pt":1723190527022,"mc":[{"id":"1.231583502","rc":[{"batb":[[0,2.08,35.1],[1,1.8,2],[2,1.74,17.32]],"ltp":2.1,"tv":81.84,"id":40096579},{"batb":[[0,1.84,12.62],[1,1.83,257],[2,1.81,200]],"ltp":1.91,"tv":16.44,"id":40096580}]}]}
{"op":"mcm","clk":"11838528960","pt":1723190532796,"mc":[{"id":"1.231583502","rc":[{"batb":[[0,2.1,10],[1,2.08,35.1],[2,1.8,2]],"ltp":2.1,"tv":81.84,"id":40096579},{"batb":[[0,1.85,10],[1,1.84,12.62],[2,1.83,257]],"ltp":1.91,"tv":16.44,"id":40096580}]}]}
{"op":"mcm","clk":"11838529135","pt":1723190536506,"mc":[{"id":"1.231583502","rc":[{"batb":[[0,2.08,35.1],[1,1.8,2],[2,1.74,17.32]],"ltp":2.1,"tv":81.84,"id":40096579},{"batb":[[0,1.84,12.62],[1,1.83,257],[2,1.81,200]],"ltp":1.91,"tv":16.44,"id":40096580}]}]}
{"op":"mcm","clk":"11838529306","pt":1723190538829,"mc":[{"id":"1.231583502","rc":[{"batb":[[0,2.1,10],[1,2.08,35.1],[2,1.8,2]],"ltp":2.1,"tv":81.84,"id":40096579},{"batb":[[0,1.85,10],[1,1.84,12.62],[2,1.83,257]],"ltp":1.91,"tv":16.44,"id":40096580}]}]}
{"op":"mcm","clk":"11838529505","pt":1723190542231,"mc":[{"id":"1.231583502","rc":[{"batb":[[0,2.08,35.1],[1,1.8,2],[2,1.74,17.32]],"ltp":2.1,"tv":81.84,"id":40096579},{"batb":[[0,1.84,12.62],[1,1.83,257],[2,1.81,200]],"ltp":1.91,"tv":16.44,"id":40096580}]}]}
{"op":"mcm","clk":"11838529642","pt":1723190544933,"mc":[{"id":"1.231583502","rc":[{"batb":[[0,2.1,10],[1,2.08,35.1],[2,1.8,2]],"ltp":2.1,"tv":81.84,"id":40096579},{"batb":[[0,1.85,10],[1,1.84,12.62],[2,1.83,257]],"ltp":1.91,"tv":16.44,"id":40096580}]}]}
{"op":"mcm","clk":"11838529829","pt":1723190548345,"mc":[{"id":"1.231583502","rc":[{"batb":[[0,2.08,35.1],[1,1.8,2],[2,1.74,17.32]],"ltp":2.1,"tv":81.84,"id":40096579},{"batb":[[0,1.84,12.62],[1,1.83,257],[2,1.81,200]],"ltp":1.91,"tv":16.44,"id":40096580}]}]}
{"op":"mcm","clk":"11838530331","pt":1723190556846,"mc":[{"id":"1.231583502","rc":[{"batb":[[0,2.1,10],[1,2.08,35.1],[2,1.8,2]],"ltp":2.1,"tv":81.84,"id":40096579},{"batb":[[0,1.85,10],[1,1.84,12.62],[2,1.83,257]],"ltp":1.91,"tv":16.44,"id":40096580}]}]}
{"op":"mcm","clk":"11838530556","pt":1723190560520,"mc":[{"id":"1.231583502","rc":[{"batb":[[0,2.08,35.1],[1,1.8,2],[2,1.74,17.32]],"ltp":2.1,"tv":81.84,"id":40096579},{"batb":[[0,1.84,12.62],[1,1.83,257],[2,1.81,200]],"ltp":1.91,"tv":16.44,"id":40096580}]}]}
{"op":"mcm","clk":"11838530712","pt":1723190563048,"mc":[{"id":"1.231583502","rc":[{"batb":[[0,2.1,10],[1,2.08,35.1],[2,1.8,2]],"ltp":2.1,"tv":81.84,"id":40096579},{"batb":[[0,1.85,10],[1,1.84,12.62],[2,1.83,257]],"ltp":1.91,"tv":16.44,"id":40096580}]}]}
{"op":"mcm","clk":"11838530908","pt":1723190566447,"mc":[{"id":"1.231583502","rc":[{"batb":[[0,2.08,35.1],[1,1.8,2],[2,1.74,17.32]],"ltp":2.1,"tv":81.84,"id":40096579},{"batb":[[0,1.84,12.62],[1,1.83,257],[2,1.81,200]],"ltp":1.91,"tv":16.44,"id":40096580}]}]}
{"op":"mcm","clk":"11838531177","pt":1723190570667,"mc":[{"id":"1.231583502","rc":[{"batb":[[0,2.1,10],[1,2.08,35.1],[2,1.8,2]],"ltp":2.1,"tv":81.84,"id":40096579},{"batb":[[0,1.85,10],[1,1.84,12.62],[2,1.83,257]],"ltp":1.91,"tv":16.44,"id":40096580}]}]}
{"op":"mcm","clk":"11838531390","pt":1723190574061,"mc":[{"id":"1.231583502","rc":[{"batb":[[0,2.08,35.1],[1,1.8,2],[2,1.74,17.32]],"ltp":2.1,"tv":81.84,"id":40096579},{"batb":[[0,1.84,12.62],[1,1.83,257],[2,1.81,200]],"ltp":1.91,"tv":16.44,"id":40096580}]}]}
{"op":"mcm","clk":"11838531565","pt":1723190577363,"mc":[{"id":"1.231583502","rc":[{"batb":[[0,2.1,10],[1,2.08,35.1],[2,1.8,2]],"ltp":2.1,"tv":81.84,"id":40096579},{"batb":[[0,1.85,10],[1,1.84,12.62],[2,1.83,257]],"ltp":1.91,"tv":16.44,"id":40096580}]}]}
{"op":"mcm","clk":"11838531787","pt":1723190580872,"mc":[{"id":"1.231583502","rc":[{"batb":[[0,2.08,35.1],[1,1.8,2],[2,1.74,17.32]],"ltp":2.1,"tv":81.84,"id":40096579},{"batb":[[0,1.84,12.62],[1,1.83,257],[2,1.81,200]],"ltp":1.91,"tv":16.44,"id":40096580}]}]}
{"op":"mcm","clk":"11838532342","pt":1723190588592,"mc":[{"id":"1.231583502","rc":[{"batb":[[0,2.1,10],[1,2.08,35.1],[2,1.8,2]],"ltp":2.1,"tv":81.84,"id":40096579},{"batb":[[0,1.85,10],[1,1.84,12.62],[2,1.83,257]],"ltp":1.91,"tv":16.44,"id":40096580}]}]}
{"op":"mcm","clk":"11838532562","pt":1723190591886,"mc":[{"id":"1.231583502","rc":[{"batb":[[0,2.08,35.1],[1,1.8,2],[2,1.74,17.32]],"ltp":2.1,"tv":81.84,"id":40096579},{"batb":[[0,1.84,12.62],[1,1.83,257],[2,1.81,200]],"ltp":1.91,"tv":16.44,"id":40096580}]}]}
{"op":"mcm","clk":"11838532801","pt":1723190595892,"mc":[{"id":"1.231583502","rc":[{"batb":[[0,2.1,10],[1,2.08,35.1],[2,1.8,2]],"ltp":2.1,"tv":81.84,"id":40096579},{"batb":[[0,1.85,10],[1,1.84,12.62],[2,1.83,257]],"ltp":1.91,"tv":16.44,"id":40096580}]}]}
{"op":"mcm","clk":"11838533014","pt":1723190599280,"mc":[{"id":"1.231583502","rc":[{"batb":[[0,2.08,35.1],[1,1.8,2],[2,1.74,17.32]],"ltp":2.1,"tv":81.84,"id":40096579},{"batb":[[0,1.84,12.62],[1,1.83,257],[2,1.81,200]],"ltp":1.91,"tv":16.44,"id":40096580}]}]}
{"op":"mcm","clk":"11838533405","pt":1723190606178,"mc":[{"id":"1.231583502","rc":[{"batb":[[0,2.1,10],[1,2.08,35.1],[2,1.8,2]],"ltp":2.1,"tv":81.84,"id":40096579},{"batb":[[0,1.85,10],[1,1.84,12.62],[2,1.83,257]],"ltp":1.91,"tv":16.44,"id":40096580}]}]}
{"op":"mcm","clk":"11838533576","pt":1723190609588,"mc":[{"id":"1.231583502","rc":[{"batb":[[0,2.08,35.1],[1,1.8,2],[2,1.74,17.32]],"ltp":2.1,"tv":81.84,"id":40096579},{"batb":[[0,1.84,12.62],[1,1.83,257],[2,1.81,200]],"ltp":1.91,"tv":16.44,"id":40096580}]}]}
{"op":"mcm","clk":"11838533733","pt":1723190612384,"mc":[{"id":"1.231583502","rc":[{"batb":[[0,2.1,10],[1,2.08,35.1],[2,1.8,2]],"ltp":2.1,"tv":81.84,"id":40096579},{"batb":[[0,1.85,10],[1,1.84,12.62],[2,1.83,257]],"ltp":1.91,"tv":16.44,"id":40096580}]}]}
{"op":"mcm","clk":"11838533955","pt":1723190615890,"mc":[{"id":"1.231583502","rc":[{"batb":[[0,2.08,35.1],[1,1.8,2],[2,1.74,17.32]],"ltp":2.1,"tv":81.84,"id":40096579},{"batb":[[0,1.84,12.62],[1,1.83,257],[2,1.81,200]],"ltp":1.91,"tv":16.44,"id":40096580}]}]}
{"op":"mcm","clk":"11838534099","pt":1723190618426,"mc":[{"id":"1.231583502","rc":[{"batb":[[0,2.1,10],[1,2.08,35.1],[2,1.8,2]],"ltp":2.1,"tv":81.84,"id":40096579},{"batb":[[0,1.85,10],[1,1.84,12.62],[2,1.83,257]],"ltp":1.91,"tv":16.44,"id":40096580}]}]}
{"op":"mcm","clk":"11838534322","pt":1723190621998,"mc":[{"id":"1.231583502","rc":[{"batb":[[0,2.08,35.1],[1,1.8,2],[2,1.74,17.32]],"ltp":2.1,"tv":81.84,"id":40096579},{"batb":[[0,1.84,12.62],[1,1.83,257],[2,1.81,200]],"ltp":1.91,"tv":16.44,"id":40096580}]}]}
{"op":"mcm","clk":"11838534523","pt":1723190625596,"mc":[{"id":"1.231583502","rc":[{"batb":[[0,2.1,10],[1,2.08,35.1],[2,1.8,2]],"ltp":2.1,"tv":81.84,"id":40096579},{"batb":[[0,1.85,10],[1,1.84,12.62],[2,1.83,257]],"ltp":1.91,"tv":16.44,"id":40096580}]}]}
{"op":"mcm","clk":"11838534725","pt":1723190629196,"mc":[{"id":"1.231583502","rc":[{"batb":[[0,2.08,35.1],[1,1.8,2],[2,1.74,17.32]],"ltp":2.1,"tv":81.84,"id":40096579},{"batb":[[0,1.84,12.62],[1,1.83,257],[2,1.81,200]],"ltp":1.91,"tv":16.44,"id":40096580}]}]}
{"op":"mcm","clk":"11838534850","pt":1723190631507,"mc":[{"id":"1.231583502","rc":[{"batb":[[0,2.1,10],[1,2.08,35.1],[2,1.8,2]],"ltp":2.1,"tv":81.84,"id":40096579},{"batb":[[0,1.85,10],[1,1.84,12.62],[2,1.83,257]],"ltp":1.91,"tv":16.44,"id":40096580}]}]}
{"op":"mcm","clk":"11838535104","pt":1723190635213,"mc":[{"id":"1.231583502","rc":[{"batb":[[0,2.08,35.1],[1,1.8,2],[2,1.74,17.32]],"ltp":2.1,"tv":81.84,"id":40096579},{"batb":[[0,1.84,12.62],[1,1.83,257],[2,1.81,200]],"ltp":1.91,"tv":16.44,"id":40096580}]}]}
{"op":"mcm","clk":"11838535228","pt":1723190637928,"mc":[{"id":"1.231583502","rc":[{"batb":[[0,2.1,10],[1,2.08,35.1],[2,1.8,2]],"ltp":2.1,"tv":81.84,"id":40096579},{"batb":[[0,1.85,10],[1,1.84,12.62],[2,1.83,257]],"ltp":1.91,"tv":16.44,"id":40096580}]}]}
{"op":"mcm","clk":"11838535443","pt":1723190641337,"mc":[{"id":"1.231583502","rc":[{"batb":[[0,2.08,35.1],[1,1.8,2],[2,1.74,17.32]],"ltp":2.1,"tv":81.84,"id":40096579},{"batb":[[0,1.84,12.62],[1,1.83,257],[2,1.81,200]],"ltp":1.91,"tv":16.44,"id":40096580}]}]}
{"op":"mcm","clk":"11838535612","pt":1723190643919,"mc":[{"id":"1.231583502","rc":[{"batb":[[0,2.1,10],[1,2.08,35.1],[2,1.8,2]],"ltp":2.1,"tv":81.84,"id":40096579},{"batb":[[0,1.85,10],[1,1.84,12.62],[2,1.83,257]],"ltp":1.91,"tv":16.44,"id":40096580}]}]}
{"op":"mcm","clk":"11838535844","pt":1723190647946,"mc":[{"id":"1.231583502","rc":[{"batb":[[0,2.08,35.1],[1,1.8,2],[2,1.74,17.32]],"ltp":2.1,"tv":81.84,"id":40096579},{"batb":[[0,1.84,12.62],[1,1.83,257],[2,1.81,200]],"ltp":1.91,"tv":16.44,"id":40096580}]}]}
{"op":"mcm","clk":"11838536020","pt":1723190650424,"mc":[{"id":"1.231583502","rc":[{"batb":[[0,2.1,10],[1,2.08,35.1],[2,1.8,2]],"ltp":2.1,"tv":81.84,"id":40096579},{"batb":[[0,1.85,10],[1,1.84,12.62],[2,1.83,257]],"ltp":1.91,"tv":16.44,"id":40096580}]}]}
{"op":"mcm","clk":"11838536283","pt":1723190653952,"mc":[{"id":"1.231583502","rc":[{"batb":[[0,2.08,35.1],[1,1.8,2],[2,1.74,17.32]],"ltp":2.1,"tv":81.84,"id":40096579},{"batb":[[0,1.84,12.62],[1,1.83,257],[2,1.81,200]],"ltp":1.91,"tv":16.44,"id":40096580}]}]}
{"op":"mcm","clk":"11838536460","pt":1723190656858,"mc":[{"id":"1.231583502","rc":[{"batb":[[0,2.1,10],[1,2.08,35.1],[2,1.8,2]],"ltp":2.1,"tv":81.84,"id":40096579},{"batb":[[0,1.85,10],[1,1.84,12.62],[2,1.83,257]],"ltp":1.91,"tv":16.44,"id":40096580}]}]}
{"op":"mcm","clk":"11838536655","pt":1723190660554,"mc":[{"id":"1.231583502","rc":[{"batb":[[0,2.08,35.1],[1,1.8,2],[2,1.74,17.32]],"ltp":2.1,"tv":81.84,"id":40096579},{"batb":[[0,1.84,12.62],[1,1.83,257],[2,1.81,200]],"ltp":1.91,"tv":16.44,"id":40096580}]}]}
{"op":"mcm","clk":"11838536878","pt":1723190663959,"mc":[{"id":"1.231583502","rc":[{"batb":[[0,2.1,10],[1,2.08,35.1],[2,1.8,2]],"ltp":2.1,"tv":81.84,"id":40096579},{"batb":[[0,1.85,10],[1,1.84,12.62],[2,1.83,257]],"ltp":1.91,"tv":16.44,"id":40096580}]}]}
{"op":"mcm","clk":"11838537081","pt":1723190667557,"mc":[{"id":"1.231583502","rc":[{"batb":[[0,2.08,35.1],[1,1.8,2],[2,1.74,17.32]],"ltp":2.1,"tv":81.84,"id":40096579},{"batb":[[0,1.84,12.62],[1,1.83,257],[2,1.81,200]],"ltp":1.91,"tv":16.44,"id":40096580}]}]}
{"op":"mcm","clk":"11838537226","pt":1723190669872,"mc":[{"id":"1.231583502","rc":[{"batb":[[0,2.1,10],[1,2.08,35.1],[2,1.8,2]],"ltp":2.1,"tv":81.84,"id":40096579},{"batb":[[0,1.85,10],[1,1.84,12.62],[2,1.83,257]],"ltp":1.91,"tv":16.44,"id":40096580}]}]}
{"op":"mcm","clk":"11838537435","pt":1723190673377,"mc":[{"id":"1.231583502","rc":[{"batb":[[0,2.08,35.1],[1,1.8,2],[2,1.74,17.32]],"ltp":2.1,"tv":81.84,"id":40096579},{"batb":[[0,1.84,12.62],[1,1.83,257],[2,1.81,200]],"ltp":1.91,"tv":16.44,"id":40096580}]}]}
{"op":"mcm","clk":"11838537586","pt":1723190675958,"mc":[{"id":"1.231583502","rc":[{"batb":[[0,2.1,10],[1,2.08,35.1],[2,1.8,2]],"ltp":2.1,"tv":81.84,"id":40096579},{"batb":[[0,1.85,10],[1,1.84,12.62],[2,1.83,257]],"ltp":1.91,"tv":16.44,"id":40096580}]}]}
{"op":"mcm","clk":"11838537826","pt":1723190679366,"mc":[{"id":"1.231583502","rc":[{"batb":[[0,2.08,35.1],[1,1.8,2],[2,1.74,17.32]],"ltp":2.1,"tv":81.84,"id":40096579},{"batb":[[0,1.84,12.62],[1,1.83,257],[2,1.81,200]],"ltp":1.91,"tv":16.44,"id":40096580}]}]}
{"op":"mcm","clk":"11838538009","pt":1723190682252,"mc":[{"id":"1.231583502","rc":[{"batb":[[0,2.1,10],[1,2.08,35.1],[2,1.8,2]],"ltp":2.1,"tv":81.84,"id":40096579},{"batb":[[0,1.85,10],[1,1.84,12.62],[2,1.83,257]],"ltp":1.91,"tv":16.44,"id":40096580}]}]}
{"op":"mcm","clk":"11838538221","pt":1723190685760,"mc":[{"id":"1.231583502","rc":[{"batb":[[0,2.08,35.1],[1,1.8,2],[2,1.74,17.32]],"ltp":2.1,"tv":81.84,"id":40096579},{"batb":[[0,1.84,12.62],[1,1.83,257],[2,1.81,200]],"ltp":1.91,"tv":16.44,"id":40096580}]}]}
{"op":"mcm","clk":"11838538384","pt":1723190688348,"mc":[{"id":"1.231583502","rc":[{"batb":[[0,2.1,10],[1,2.08,35.1],[2,1.8,2]],"ltp":2.1,"tv":81.84,"id":40096579},{"batb":[[0,1.85,10],[1,1.84,12.62],[2,1.83,257]],"ltp":1.91,"tv":16.44,"id":40096580}]}]}
{"op":"mcm","clk":"11838538604","pt":1723190691876,"mc":[{"id":"1.231583502","rc":[{"batb":[[0,2.08,35.1],[1,1.8,2],[2,1.74,17.32]],"ltp":2.1,"tv":81.84,"id":40096579},{"batb":[[0,1.84,12.62],[1,1.83,257],[2,1.81,200]],"ltp":1.91,"tv":16.44,"id":40096580}]}]}
{"op":"mcm","clk":"11838538747","pt":1723190694357,"mc":[{"id":"1.231583502","rc":[{"batb":[[0,2.1,10],[1,2.08,35.1],[2,1.8,2]],"ltp":2.1,"tv":81.84,"id":40096579},{"batb":[[0,1.85,10],[1,1.84,12.62],[2,1.83,257]],"ltp":1.91,"tv":16.44,"id":40096580}]}]}
{"op":"mcm","clk":"11838538955","pt":1723190697859,"mc":[{"id":"1.231583502","rc":[{"batb":[[0,2.08,35.1],[1,1.8,2],[2,1.74,17.32]],"ltp":2.1,"tv":81.84,"id":40096579},{"batb":[[0,1.84,12.62],[1,1.83,257],[2,1.81,200]],"ltp":1.91,"tv":16.44,"id":40096580}]}]}
{"op":"mcm","clk":"11838539081","pt":1723190700295,"mc":[{"id":"1.231583502","rc":[{"batb":[[0,2.1,10],[1,2.08,35.1],[2,1.8,2]],"ltp":2.1,"tv":81.84,"id":40096579},{"batb":[[0,1.85,10],[1,1.84,12.62],[2,1.83,257]],"ltp":1.91,"tv":16.44,"id":40096580}]}]}
{"op":"mcm","clk":"11838539266","pt":1723190703605,"mc":[{"id":"1.231583502","rc":[{"batb":[[0,2.08,35.1],[1,1.8,2],[2,1.74,17.32]],"ltp":2.1,"tv":81.84,"id":40096579},{"batb":[[0,1.84,12.62],[1,1.83,257],[2,1.81,200]],"ltp":1.91,"tv":16.44,"id":40096580}]}]}
{"op":"mcm","clk":"11838539454","pt":1723190706802,"mc":[{"id":"1.231583502","rc":[{"batb":[[0,2.1,10],[1,2.08,35.1],[2,1.8,2]],"ltp":2.1,"tv":81.84,"id":40096579},{"batb":[[0,1.85,10],[1,1.84,12.62],[2,1.83,257]],"ltp":1.91,"tv":16.44,"id":40096580}]}]}
{"op":"mcm","clk":"11838539702","pt":1723190710523,"mc":[{"id":"1.231583502","rc":[{"batb":[[0,2.08,35.1],[1,1.8,2],[2,1.74,17.32]],"ltp":2.1,"tv":81.84,"id":40096579},{"batb":[[0,1.84,12.62],[1,1.83,257],[2,1.81,200]],"ltp":1.91,"tv":16.44,"id":40096580}]}]}
{"op":"mcm","clk":"11838539914","pt":1723190713816,"mc":[{"id":"1.231583502","rc":[{"batb":[[0,2.1,10],[1,2.08,35.1],[2,1.8,2]],"ltp":2.1,"tv":81.84,"id":40096579},{"batb":[[0,1.85,10],[1,1.84,12.62],[2,1.83,257]],"ltp":1.91,"tv":16.44,"id":40096580}]}]}
{"op":"mcm","clk":"11838540110","pt":1723190717306,"mc":[{"id":"1.231583502","rc":[{"batb":[[0,2.08,35.1],[1,1.8,2],[2,1.74,17.32]],"ltp":2.1,"tv":81.84,"id":40096579},{"batb":[[0,1.84,12.62],[1,1.83,257],[2,1.81,200]],"ltp":1.91,"tv":16.44,"id":40096580}]}]}
{"op":"mcm","clk":"11838540433","pt":1723190722398,"mc":[{"id":"1.231583502","rc":[{"batb":[[0,2.1,10],[1,2.08,35.1],[2,1.8,2]],"ltp":2.1,"tv":81.84,"id":40096579},{"batb":[[0,1.85,10],[1,1.84,12.62],[2,1.83,257]],"ltp":1.91,"tv":16.44,"id":40096580}]}]}
{"op":"mcm","clk":"11838540642","pt":1723190725813,"mc":[{"id":"1.231583502","rc":[{"batb":[[0,2.08,35.1],[1,1.8,2],[2,1.74,17.32]],"ltp":2.1,"tv":81.84,"id":40096579},{"batb":[[0,1.84,12.62],[1,1.83,257],[2,1.81,200]],"ltp":1.91,"tv":16.44,"id":40096580}]}]}
{"op":"mcm","clk":"11838540842","pt":1723190728806,"mc":[{"id":"1.231583502","rc":[{"batb":[[0,2.1,10],[1,2.08,35.1],[2,1.8,2]],"ltp":2.1,"tv":81.84,"id":40096579},{"batb":[[0,1.85,10],[1,1.84,12.62],[2,1.83,257]],"ltp":1.91,"tv":16.44,"id":40096580}]}]}
{"op":"mcm","clk":"11838541012","pt":1723190732148,"mc":[{"id":"1.231583502","rc":[{"batb":[[0,2.08,35.1],[1,1.8,2],[2,1.74,17.32]],"ltp":2.1,"tv":81.84,"id":40096579},{"batb":[[0,1.84,12.62],[1,1.83,257],[2,1.81,200]],"ltp":1.91,"tv":16.44,"id":40096580}]}]}
{"op":"mcm","clk":"11838541227","pt":1723190735448,"mc":[{"id":"1.231583502","rc":[{"batb":[[0,2.1,10],[1,2.08,35.1],[2,1.8,2]],"ltp":2.1,"tv":81.84,"id":40096579},{"batb":[[0,1.85,10],[1,1.84,12.62],[2,1.83,257]],"ltp":1.91,"tv":16.44,"id":40096580}]}]}
{"op":"mcm","clk":"11838541476","pt":1723190738954,"mc":[{"id":"1.231583502","rc":[{"batb":[[0,2.08,35.1],[1,1.8,2],[2,1.74,17.32]],"ltp":2.1,"tv":81.84,"id":40096579},{"batb":[[0,1.84,12.62],[1,1.83,257],[2,1.81,200]],"ltp":1.91,"tv":16.44,"id":40096580}]}]}
{"op":"mcm","clk":"11838541677","pt":1723190742556,"mc":[{"id":"1.231583502","rc":[{"batb":[[0,2.1,10],[1,2.08,35.1],[2,1.8,2]],"ltp":2.1,"tv":81.84,"id":40096579},{"batb":[[0,1.85,10],[1,1.84,12.62],[2,1.83,257]],"ltp":1.91,"tv":16.44,"id":40096580}]}]}
{"op":"mcm","clk":"11838541884","pt":1723190746268,"mc":[{"id":"1.231583502","rc":[{"batb":[[0,2.08,35.1],[1,1.8,2],[2,1.74,17.32]],"ltp":2.1,"tv":81.84,"id":40096579},{"batb":[[0,1.84,12.62],[1,1.83,257],[2,1.81,200]],"ltp":1.91,"tv":16.44,"id":40096580}]}]}
{"op":"mcm","clk":"11838542090","pt":1723190749980,"mc":[{"id":"1.231583502","rc":[{"batb":[[0,2.1,10],[1,2.08,35.1],[2,1.8,2]],"ltp":2.1,"tv":81.84,"id":40096579},{"batb":[[0,1.85,10],[1,1.84,12.62],[2,1.83,257]],"ltp":1.91,"tv":16.44,"id":40096580}]}]}
{"op":"mcm","clk":"11838542329","pt":1723190753636,"mc":[{"id":"1.231583502","rc":[{"batb":[[0,2.08,35.1],[1,1.8,2],[2,1.74,17.32]],"ltp":2.1,"tv":81.84,"id":40096579},{"batb":[[0,1.84,12.62],[1,1.83,257],[2,1.81,200]],"ltp":1.91,"tv":16.44,"id":40096580}]}]}
{"op":"mcm","clk":"11838542469","pt":1723190756049,"mc":[{"id":"1.231583502","rc":[{"batb":[[0,2.1,10],[1,2.08,35.1],[2,1.8,2]],"ltp":2.1,"tv":81.84,"id":40096579},{"batb":[[0,1.85,10],[1,1.84,12.62],[2,1.83,257]],"ltp":1.91,"tv":16.44,"id":40096580}]}]}
{"op":"mcm","clk":"11838542698","pt":1723190759586,"mc":[{"id":"1.231583502","rc":[{"batb":[[0,2.08,35.1],[1,1.8,2],[2,1.74,17.32]],"ltp":2.1,"tv":81.84,"id":40096579},{"batb":[[0,1.84,12.62],[1,1.83,257],[2,1.81,200]],"ltp":1.91,"tv":16.44,"id":40096580}]}]}
{"op":"mcm","clk":"11838542959","pt":1723190764062,"mc":[{"id":"1.231583502","rc":[{"batb":[[0,2.1,10],[1,2.08,35.1],[2,1.8,2]],"ltp":2.1,"tv":81.84,"id":40096579},{"batb":[[0,1.85,10],[1,1.84,12.62],[2,1.83,257]],"ltp":1.91,"tv":16.44,"id":40096580}]}]}
{"op":"mcm","clk":"11838543141","pt":1723190767680,"mc":[{"id":"1.231583502","rc":[{"batb":[[0,2.08,35.1],[1,1.8,2],[2,1.74,17.32]],"ltp":2.1,"tv":81.84,"id":40096579},{"batb":[[0,1.84,12.62],[1,1.83,257],[2,1.81,200]],"ltp":1.91,"tv":16.44,"id":40096580}]}]}
{"op":"mcm","clk":"11838543324","pt":1723190770881,"mc":[{"id":"1.231583502","rc":[{"batb":[[0,2.1,10],[1,2.08,35.1],[2,1.8,2]],"ltp":2.1,"tv":81.84,"id":40096579},{"batb":[[0,1.85,10],[1,1.84,12.62],[2,1.83,257]],"ltp":1.91,"tv":16.44,"id":40096580}]}]}
{"op":"mcm","clk":"11838543542","pt":1723190774270,"mc":[{"id":"1.231583502","rc":[{"batb":[[0,2.08,35.1],[1,1.8,2],[2,1.74,17.32]],"ltp":2.1,"tv":81.84,"id":40096579},{"batb":[[0,1.84,12.62],[1,1.83,257],[2,1.81,200]],"ltp":1.91,"tv":16.44,"id":40096580}]}]}
{"op":"mcm","clk":"11838543675","pt":1723190776580,"mc":[{"id":"1.231583502","rc":[{"batb":[[0,2.1,10],[1,2.08,35.1],[2,1.8,2]],"ltp":2.1,"tv":81.84,"id":40096579},{"batb":[[0,1.85,10],[1,1.84,12.62],[2,1.83,257]],"ltp":1.91,"tv":16.44,"id":40096580}]}]}
{"op":"mcm","clk":"11838543881","pt":1723190779768,"mc":[{"id":"1.231583502","rc":[{"batb":[[0,2.08,35.1],[1,1.8,2],[2,1.74,17.32]],"ltp":2.1,"tv":81.84,"id":40096579},{"batb":[[0,1.84,12.62],[1,1.83,257],[2,1.81,200]],"ltp":1.91,"tv":16.44,"id":40096580}]}]}
{"op":"mcm","clk":"11838544040","pt":1723190782497,"mc":[{"id":"1.231583502","rc":[{"batb":[[0,2.1,10],[1,2.08,35.1],[2,1.8,2]],"ltp":2.1,"tv":81.84,"id":40096579},{"batb":[[0,1.85,10],[1,1.84,12.62],[2,1.83,257]],"ltp":1.91,"tv":16.44,"id":40096580}]}]}
{"op":"mcm","clk":"11838544220","pt":1723190785690,"mc":[{"id":"1.231583502","rc":[{"batb":[[0,2.08,35.1],[1,1.8,2],[2,1.74,17.32]],"ltp":2.1,"tv":81.84,"id":40096579},{"batb":[[0,1.84,12.62],[1,1.83,257],[2,1.81,200]],"ltp":1.91,"tv":16.44,"id":40096580}]}]}
{"op":"mcm","clk":"11838544365","pt":1723190788306,"mc":[{"id":"1.231583502","rc":[{"batb":[[0,2.1,10],[1,2.08,35.1],[2,1.8,2]],"ltp":2.1,"tv":81.84,"id":40096579},{"batb":[[0,1.85,10],[1,1.84,12.62],[2,1.83,257]],"ltp":1.91,"tv":16.44,"id":40096580}]}]}
{"op":"mcm","clk":"11838544592","pt":1723190791706,"mc":[{"id":"1.231583502","rc":[{"batb":[[0,2.08,35.1],[1,1.8,2],[2,1.74,17.32]],"ltp":2.1,"tv":81.84,"id":40096579},{"batb":[[0,1.84,12.62],[1,1.83,257],[2,1.81,200]],"ltp":1.91,"tv":16.44,"id":40096580}]}]}
{"op":"mcm","clk":"11838544790","pt":1723190794890,"mc":[{"id":"1.231583502","rc":[{"batb":[[0,2.1,10],[1,2.08,35.1],[2,1.8,2]],"ltp":2.1,"tv":81.84,"id":40096579},{"batb":[[0,1.85,10],[1,1.84,12.62],[2,1.83,257]],"ltp":1.91,"tv":16.44,"id":40096580}]}]}
{"op":"mcm","clk":"11838544988","pt":1723190798532,"mc":[{"id":"1.231583502","rc":[{"batb":[[0,2.08,35.1],[1,1.8,2],[2,1.74,17.32]],"ltp":2.1,"tv":81.84,"id":40096579},{"batb":[[0,1.84,12.62],[1,1.83,257],[2,1.81,200]],"ltp":1.91,"tv":16.44,"id":40096580}]}]}
{"op":"mcm","clk":"11838545164","pt":1723190801509,"mc":[{"id":"1.231583502","rc":[{"batb":[[0,2.1,10],[1,2.08,35.1],[2,1.8,2]],"ltp":2.1,"tv":81.84,"id":40096579},{"batb":[[0,1.85,10],[1,1.84,12.62],[2,1.83,257]],"ltp":1.91,"tv":16.44,"id":40096580}]}]}
{"op":"mcm","clk":"11838545361","pt":1723190804799,"mc":[{"id":"1.231583502","rc":[{"batb":[[0,2.08,35.1],[1,1.8,2],[2,1.74,17.32]],"ltp":2.1,"tv":81.84,"id":40096579}]}]}
{"op":"mcm","clk":"11838545520","pt":1723190807631,"mc":[{"id":"1.231583502","rc":[{"batb":[[0,2.1,10],[1,2.08,35.1],[2,1.8,2]],"ltp":2.1,"tv":81.84,"id":40096579},{"batb":[[0,1.86,10],[1,1.85,10],[2,1.84,12.62]],"ltp":1.91,"tv":16.44,"id":40096580}]}]}
{"op":"mcm","clk":"11838545702","pt":1723190810922,"mc":[{"id":"1.231583502","rc":[{"batb":[[0,2.08,35.1],[1,1.8,2],[2,1.74,17.32]],"ltp":2.1,"tv":81.84,"id":40096579},{"batb":[[0,1.85,10],[1,1.83,257],[2,1.81,200]],"ltp":1.91,"tv":16.44,"id":40096580}]}]}
{"op":"mcm","clk":"11838545870","pt":1723190813746,"mc":[{"id":"1.231583502","rc":[{"batb":[[0,2.1,10],[1,2.08,35.1],[2,1.8,2]],"ltp":2.1,"tv":81.84,"id":40096579},{"batb":[[0,1.86,10],[1,1.85,10],[2,1.83,257]],"ltp":1.91,"tv":16.44,"id":40096580}]}]}
{"op":"mcm","clk":"11838545908","pt":1723190814519,"mc":[{"id":"1.231583502","rc":[{"batl":[[0,1000,0.02],[1,1000,0]],"ltp":2.1,"tv":81.84,"id":40096579}]}]}
{"op":"mcm","clk":"11838546052","pt":1723190816831,"mc":[{"id":"1.231583502","rc":[{"trd":[[2.1,18.74]],"batb":[[0,2.08,36],[1,1.8,2],[2,1.74,17.32]],"ltp":2.1,"tv":90.94,"id":40096579},{"trd":[[1.91,20.6]],"ltp":1.91,"tv":26.44,"id":40096580}],"tv":117.38}]}
{"op":"mcm","clk":"11838546065","pt":1723190817036,"mc":[{"id":"1.231583502","rc":[{"batb":[[0,2.08,35.1]],"ltp":2.1,"tv":90.94,"id":40096579},{"batb":[[0,1.85,10],[1,1.83,257],[2,1.81,200]],"ltp":1.91,"tv":26.44,"id":40096580}]}]}
{"op":"mcm","clk":"11838546244","pt":1723190819519,"mc":[{"id":"1.231583502","rc":[{"batb":[[0,2.1,10],[1,2.08,35.1],[2,1.8,2]],"ltp":2.1,"tv":90.94,"id":40096579},{"batb":[[0,1.86,10],[1,1.85,10],[2,1.83,257]],"ltp":1.91,"tv":26.44,"id":40096580}]}]}
{"op":"mcm","clk":"11838546504","pt":1723190823345,"mc":[{"id":"1.231583502","rc":[{"batb":[[0,2.08,35.1],[1,1.8,2],[2,1.74,17.32]],"ltp":2.1,"tv":90.94,"id":40096579},{"batb":[[0,1.85,10],[1,1.83,257],[2,1.81,200]],"ltp":1.91,"tv":26.44,"id":40096580}]}]}
{"op":"mcm","clk":"11838546653","pt":1723190826062,"mc":[{"id":"1.231583502","rc":[{"batb":[[0,2.1,10],[1,2.08,35.1],[2,1.8,2]],"ltp":2.1,"tv":90.94,"id":40096579},{"batb":[[0,1.86,10],[1,1.85,10],[2,1.83,257]],"ltp":1.91,"tv":26.44,"id":40096580}]}]}
{"op":"mcm","clk":"11838546883","pt":1723190829585,"mc":[{"id":"1.231583502","rc":[{"batb":[[0,2.08,35.1],[1,1.8,2],[2,1.74,17.32]],"ltp":2.1,"tv":90.94,"id":40096579},{"batb":[[0,1.85,10],[1,1.83,257],[2,1.81,200]],"ltp":1.91,"tv":26.44,"id":40096580}]}]}
{"op":"mcm","clk":"11838547074","pt":1723190832859,"mc":[{"id":"1.231583502","rc":[{"batb":[[0,2.1,10],[1,2.08,35.1],[2,1.8,2]],"ltp":2.1,"tv":90.94,"id":40096579},{"batb":[[0,1.86,10],[1,1.85,10],[2,1.83,257]],"ltp":1.91,"tv":26.44,"id":40096580}]}]}
{"op":"mcm","clk":"11838547254","pt":1723190836184,"mc":[{"id":"1.231583502","rc":[{"batb":[[0,2.08,35.1],[1,1.8,2],[2,1.74,17.32]],"ltp":2.1,"tv":90.94,"id":40096579},{"batb":[[0,1.85,10],[1,1.83,257],[2,1.81,200]],"ltp":1.91,"tv":26.44,"id":40096580}]}]}
{"op":"mcm","clk":"11838547383","pt":1723190838849,"mc":[{"id":"1.231583502","rc":[{"batb":[[0,2.1,10],[1,2.08,35.1],[2,1.8,2]],"ltp":2.1,"tv":90.94,"id":40096579},{"batb":[[0,1.86,10],[1,1.85,10],[2,1.83,257]],"ltp":1.91,"tv":26.44,"id":40096580}]}]}
{"op":"mcm","clk":"11838547558","pt":1723190842283,"mc":[{"id":"1.231583502","rc":[{"batb":[[0,2.08,35.1],[1,1.8,2],[2,1.74,17.32]],"ltp":2.1,"tv":90.94,"id":40096579},{"batb":[[0,1.85,10],[1,1.83,257],[2,1.81,200]],"ltp":1.91,"tv":26.44,"id":40096580}]}]}
{"op":"mcm","clk":"11838547712","pt":1723190844860,"mc":[{"id":"1.231583502","rc":[{"batb":[[0,2.1,10],[1,2.08,35.1],[2,1.8,2]],"ltp":2.1,"tv":90.94,"id":40096579},{"batb":[[0,1.86,10],[1,1.85,10],[2,1.83,257]],"ltp":1.91,"tv":26.44,"id":40096580}]}]}
{"op":"mcm","clk":"11838547909","pt":1723190848052,"mc":[{"id":"1.231583502","rc":[{"batb":[[0,2.08,35.1],[1,1.8,2],[2,1.74,17.32]],"ltp":2.1,"tv":90.94,"id":40096579},{"batb":[[0,1.85,10],[1,1.83,257],[2,1.81,200]],"ltp":1.91,"tv":26.44,"id":40096580}]}]}
{"op":"mcm","clk":"11838548057","pt":1723190850674,"mc":[{"id":"1.231583502","rc":[{"batb":[[0,2.1,10],[1,2.08,35.1],[2,1.8,2]],"ltp":2.1,"tv":90.94,"id":40096579},{"batb":[[0,1.86,10],[1,1.85,10],[2,1.83,257]],"ltp":1.91,"tv":26.44,"id":40096580}]}]}
{"op":"mcm","clk":"11838548256","pt":1723190854083,"mc":[{"id":"1.231583502","rc":[{"batb":[[0,2.08,35.1],[1,1.8,2],[2,1.74,17.32]],"ltp":2.1,"tv":90.94,"id":40096579},{"batb":[[0,1.85,10],[1,1.83,257],[2,1.81,200]],"ltp":1.91,"tv":26.44,"id":40096580}]}]}
{"op":"mcm","clk":"11838548402","pt":1723190856752,"mc":[{"id":"1.231583502","rc":[{"batb":[[0,2.1,10],[1,2.08,35.1],[2,1.8,2]],"ltp":2.1,"tv":90.94,"id":40096579},{"batb":[[0,1.86,10],[1,1.85,10],[2,1.83,257]],"ltp":1.91,"tv":26.44,"id":40096580}]}]}
{"op":"mcm","clk":"11838548630","pt":1723190860768,"mc":[{"id":"1.231583502","rc":[{"batb":[[0,2.08,35.1],[1,1.8,2],[2,1.74,17.32]],"ltp":2.1,"tv":90.94,"id":40096579},{"batb":[[0,1.85,10],[1,1.83,257],[2,1.81,200]],"ltp":1.91,"tv":26.44,"id":40096580}]}]}
{"op":"mcm","clk":"11838548766","pt":1723190863486,"mc":[{"id":"1.231583502","rc":[{"batb":[[0,2.1,10],[1,2.08,35.1],[2,1.8,2]],"ltp":2.1,"tv":90.94,"id":40096579},{"batb":[[0,1.86,10],[1,1.85,10],[2,1.83,257]],"ltp":1.91,"tv":26.44,"id":40096580}]}]}
{"op":"mcm","clk":"11838548971","pt":1723190866998,"mc":[{"id":"1.231583502","rc":[{"batb":[[0,2.08,35.1],[1,1.8,2],[2,1.74,17.32]],"ltp":2.1,"tv":90.94,"id":40096579},{"batb":[[0,1.85,10],[1,1.83,257],[2,1.81,200]],"ltp":1.91,"tv":26.44,"id":40096580}]}]}
{"op":"mcm","clk":"11838549171","pt":1723190870704,"mc":[{"id":"1.231583502","rc":[{"batb":[[0,2.1,10],[1,2.08,35.1],[2,1.8,2]],"ltp":2.1,"tv":90.94,"id":40096579},{"batb":[[0,1.86,10],[1,1.85,10],[2,1.83,257]],"ltp":1.91,"tv":26.44,"id":40096580}]}]}
{"op":"mcm","clk":"11838549403","pt":1723190874266,"mc":[{"id":"1.231583502","rc":[{"batb":[[0,2.08,35.1],[1,1.8,2],[2,1.74,17.32]],"ltp":2.1,"tv":90.94,"id":40096579},{"batb":[[0,1.85,10],[1,1.83,257],[2,1.81,200]],"ltp":1.91,"tv":26.44,"id":40096580}]}]}
{"op":"mcm","clk":"11838549556","pt":1723190876795,"mc":[{"id":"1.231583502","rc":[{"batb":[[0,2.1,10],[1,2.08,35.1],[2,1.8,2]],"ltp":2.1,"tv":90.94,"id":40096579},{"batb":[[0,1.86,10],[1,1.85,10],[2,1.83,257]],"ltp":1.91,"tv":26.44,"id":40096580}]}]}
{"op":"mcm","clk":"11838549753","pt":1723190880190,"mc":[{"id":"1.231583502","rc":[{"batb":[[0,2.08,35.1],[1,1.8,2],[2,1.74,17.32]],"ltp":2.1,"tv":90.94,"id":40096579},{"batb":[[0,1.85,10],[1,1.83,257],[2,1.81,200]],"ltp":1.91,"tv":26.44,"id":40096580}]}]}
{"op":"mcm","clk":"11838549965","pt":1723190884108,"mc":[{"id":"1.231583502","rc":[{"batb":[[0,2.1,10],[1,2.08,35.1],[2,1.8,2]],"ltp":2.1,"tv":90.94,"id":40096579},{"batb":[[0,1.86,10],[1,1.85,10],[2,1.83,257]],"ltp":1.91,"tv":26.44,"id":40096580}]}]}
{"op":"mcm","clk":"11838550171","pt":1723190887495,"mc":[{"id":"1.231583502","rc":[{"batb":[[0,2.08,35.1],[1,1.8,2],[2,1.74,17.32]],"ltp":2.1,"tv":90.94,"id":40096579},{"batb":[[0,1.85,10],[1,1.83,257],[2,1.81,200]],"ltp":1.91,"tv":26.44,"id":40096580}]}]}
{"op":"mcm","clk":"11838550384","pt":1723190890815,"mc":[{"id":"1.231583502","rc":[{"batb":[[0,2.1,10],[1,2.08,35.1],[2,1.8,2]],"ltp":2.1,"tv":90.94,"id":40096579},{"batb":[[0,1.86,10],[1,1.85,10],[2,1.83,257]],"ltp":1.91,"tv":26.44,"id":40096580}]}]}
{"op":"mcm","clk":"11838550559","pt":1723190894220,"mc":[{"id":"1.231583502","rc":[{"batb":[[0,2.08,35.1],[1,1.8,2],[2,1.74,17.32]],"ltp":2.1,"tv":90.94,"id":40096579},{"batb":[[0,1.85,10],[1,1.83,257],[2,1.81,200]],"ltp":1.91,"tv":26.44,"id":40096580}]}]}
{"op":"mcm","clk":"11838550743","pt":1723190897317,"mc":[{"id":"1.231583502","rc":[{"batb":[[0,2.1,10],[1,2.08,35.1],[2,1.8,2]],"ltp":2.1,"tv":90.94,"id":40096579},{"batb":[[0,1.86,10],[1,1.85,10],[2,1.83,257]],"ltp":1.91,"tv":26.44,"id":40096580}]}]}
{"op":"mcm","clk":"11838550915","pt":1723190900912,"mc":[{"id":"1.231583502","rc":[{"batb":[[0,2.08,35.1],[1,1.8,2],[2,1.74,17.32]],"ltp":2.1,"tv":90.94,"id":40096579},{"batb":[[0,1.85,10],[1,1.83,257],[2,1.81,200]],"ltp":1.91,"tv":26.44,"id":40096580}]}]}
{"op":"mcm","clk":"11838551029","pt":1723190903319,"mc":[{"id":"1.231583502","rc":[{"batb":[[0,2.1,10],[1,2.08,35.1],[2,1.8,2]],"ltp":2.1,"tv":90.94,"id":40096579},{"batb":[[0,1.86,10],[1,1.85,10],[2,1.83,257]],"ltp":1.91,"tv":26.44,"id":40096580}]}]}
{"op":"mcm","clk":"11838551206","pt":1723190906958,"mc":[{"id":"1.231583502","rc":[{"batb":[[0,2.08,35.1],[1,1.8,2],[2,1.74,17.32]],"ltp":2.1,"tv":90.94,"id":40096579},{"batb":[[0,1.85,10],[1,1.83,257],[2,1.81,200]],"ltp":1.91,"tv":26.44,"id":40096580}]}]}
{"op":"mcm","clk":"11838551374","pt":1723190910133,"mc":[{"id":"1.231583502","rc":[{"batb":[[0,2.1,10],[1,2.08,35.1],[2,1.8,2]],"ltp":2.1,"tv":90.94,"id":40096579},{"batb":[[0,1.86,10],[1,1.85,10],[2,1.83,257]],"ltp":1.91,"tv":26.44,"id":40096580}]}]}
{"op":"mcm","clk":"11838551544","pt":1723190913466,"mc":[{"id":"1.231583502","rc":[{"batb":[[0,2.08,35.1],[1,1.8,2],[2,1.74,17.32]],"ltp":2.1,"tv":90.94,"id":40096579},{"batb":[[0,1.85,10],[1,1.83,257],[2,1.81,200]],"ltp":1.91,"tv":26.44,"id":40096580}]}]}
{"op":"mcm","clk":"11838551704","pt":1723190916763,"mc":[{"id":"1.231583502","rc":[{"batb":[[0,2.1,10],[1,2.08,35.1],[2,1.8,2]],"ltp":2.1,"tv":90.94,"id":40096579},{"batb":[[0,1.86,10],[1,1.85,10],[2,1.83,257]],"ltp":1.91,"tv":26.44,"id":40096580}]}]}
{"op":"mcm","clk":"11838551954","pt":1723190921283,"mc":[{"id":"1.231583502","rc":[{"batb":[[0,2.08,35.1],[1,1.8,2],[2,1.74,17.32]],"ltp":2.1,"tv":90.94,"id":40096579},{"batb":[[0,1.85,10],[1,1.83,257],[2,1.81,200]],"ltp":1.91,"tv":26.44,"id":40096580}]}]}
{"op":"mcm","clk":"11838552200","pt":1723190925288,"mc":[{"id":"1.231583502","rc":[{"batb":[[0,2.1,10],[1,2.08,35.1],[2,1.8,2]],"ltp":2.1,"tv":90.94,"id":40096579},{"batb":[[0,1.86,10],[1,1.85,10],[2,1.83,257]],"ltp":1.91,"tv":26.44,"id":40096580}]}]}
{"op":"mcm","clk":"11838552393","pt":1723190928671,"mc":[{"id":"1.231583502","rc":[{"batb":[[0,2.08,35.1],[1,1.8,2],[2,1.74,17.32]],"ltp":2.1,"tv":90.94,"id":40096579},{"batb":[[0,1.85,10],[1,1.83,257],[2,1.81,200]],"ltp":1.91,"tv":26.44,"id":40096580}]}]}
{"op":"mcm","clk":"11838552482","pt":1723190930973,"mc":[{"id":"1.231583502","rc":[{"batb":[[0,2.1,10],[1,2.08,35.1],[2,1.8,2]],"ltp":2.1,"tv":90.94,"id":40096579},{"batb":[[0,1.86,10],[1,1.85,10],[2,1.83,257]],"ltp":1.91,"tv":26.44,"id":40096580}]}]}
{"op":"mcm","clk":"11838552601","pt":1723190933076,"mc":[{"id":"1.231583502","rc":[{"trd":[[2.1,27.84]],"batb":[[0,2.08,36],[1,1.8,2],[2,1.74,17.32]],"ltp":2.1,"tv":100.04,"id":40096579},{"trd":[[1.91,30.6]],"ltp":1.91,"tv":36.44,"id":40096580}],"tv":136.48}]}
{"op":"mcm","clk":"11838552652","pt":1723190934201,"mc":[{"id":"1.231583502","rc":[{"batb":[[0,2.08,35.1]],"ltp":2.1,"tv":100.04,"id":40096579},{"batb":[[0,1.85,10],[1,1.83,257],[2,1.81,200]],"ltp":1.91,"tv":36.44,"id":40096580}]}]}
{"op":"mcm","clk":"11838552829","pt":1723190937696,"mc":[{"id":"1.231583502","rc":[{"batb":[[0,2.1,10],[1,2.08,35.1],[2,1.8,2]],"ltp":2.1,"tv":100.04,"id":40096579},{"batb":[[0,1.86,10],[1,1.85,10],[2,1.83,257]],"ltp":1.91,"tv":36.44,"id":40096580}]}]}
{"op":"mcm","clk":"11838552984","pt":1723190941181,"mc":[{"id":"1.231583502","rc":[{"batb":[[0,2.08,35.1],[1,1.8,2],[2,1.74,17.32]],"ltp":2.1,"tv":100.04,"id":40096579},{"batb":[[0,1.85,10],[1,1.83,257],[2,1.81,200]],"ltp":1.91,"tv":36.44,"id":40096580}]}]}
{"op":"mcm","clk":"11838553095","pt":1723190943402,"mc":[{"id":"1.231583502","rc":[{"batb":[[0,2.1,10],[1,2.08,35.1],[2,1.8,2]],"ltp":2.1,"tv":100.04,"id":40096579},{"batb":[[0,1.86,10],[1,1.85,10],[2,1.83,257]],"ltp":1.91,"tv":36.44,"id":40096580}]}]}
{"op":"mcm","clk":"11838553259","pt":1723190946699,"mc":[{"id":"1.231583502","rc":[{"batb":[[0,2.08,35.1],[1,1.8,2],[2,1.74,17.32]],"ltp":2.1,"tv":100.04,"id":40096579},{"batb":[[0,1.85,10],[1,1.83,257],[2,1.81,200]],"ltp":1.91,"tv":36.44,"id":40096580}]}]}
{"op":"mcm","clk":"11838553383","pt":1723190949009,"mc":[{"id":"1.231583502","rc":[{"batb":[[0,2.1,10],[1,2.08,35.1],[2,1.8,2]],"ltp":2.1,"tv":100.04,"id":40096579},{"batb":[[0,1.86,10],[1,1.85,10],[2,1.83,257]],"ltp":1.91,"tv":36.44,"id":40096580}]}]}
{"op":"mcm","clk":"11838553597","pt":1723190952503,"mc":[{"id":"1.231583502","rc":[{"batb":[[0,2.08,35.1],[1,1.8,2],[2,1.74,17.32]],"ltp":2.1,"tv":100.04,"id":40096579},{"batb":[[0,1.85,10],[1,1.83,257],[2,1.81,200]],"ltp":1.91,"tv":36.44,"id":40096580}]}]}
{"op":"mcm","clk":"11838553731","pt":1723190955112,"mc":[{"id":"1.231583502","rc":[{"batb":[[0,2.1,10],[1,2.08,35.1],[2,1.8,2]],"ltp":2.1,"tv":100.04,"id":40096579},{"batb":[[0,1.86,10],[1,1.85,10],[2,1.83,257]],"ltp":1.91,"tv":36.44,"id":40096580}]}]}
{"op":"mcm","clk":"11838553905","pt":1723190958606,"mc":[{"id":"1.231583502","rc":[{"batb":[[0,2.08,35.1],[1,1.8,2],[2,1.74,17.32]],"ltp":2.1,"tv":100.04,"id":40096579},{"batb":[[0,1.85,10],[1,1.83,257],[2,1.81,200]],"ltp":1.91,"tv":36.44,"id":40096580}]}]}
{"op":"mcm","clk":"11838554034","pt":1723190961528,"mc":[{"id":"1.231583502","rc":[{"batb":[[0,2.1,10],[1,2.08,35.1],[2,1.8,2]],"ltp":2.1,"tv":100.04,"id":40096579},{"batb":[[0,1.86,10],[1,1.85,10],[2,1.83,257]],"ltp":1.91,"tv":36.44,"id":40096580}]}]}
{"op":"mcm","clk":"11838554262","pt":1723190965336,"mc":[{"id":"1.231583502","rc":[{"batb":[[0,2.08,35.1],[1,1.8,2],[2,1.74,17.32]],"ltp":2.1,"tv":100.04,"id":40096579},{"batb":[[0,1.85,10],[1,1.83,257],[2,1.81,200]],"ltp":1.91,"tv":36.44,"id":40096580}]}]}
{"op":"mcm","clk":"11838554418","pt":1723190968518,"mc":[{"id":"1.231583502","rc":[{"batb":[[0,2.1,10],[1,2.08,35.1],[2,1.8,2]],"ltp":2.1,"tv":100.04,"id":40096579},{"batb":[[0,1.86,10],[1,1.85,10],[2,1.83,257]],"ltp":1.91,"tv":36.44,"id":40096580}]}]}
{"op":"mcm","clk":"11838554580","pt":1723190971958,"mc":[{"id":"1.231583502","rc":[{"batb":[[0,2.08,35.1],[1,1.8,2],[2,1.74,17.32]],"ltp":2.1,"tv":100.04,"id":40096579},{"batb":[[0,1.85,10],[1,1.83,257],[2,1.81,200]],"ltp":1.91,"tv":36.44,"id":40096580}]}]}
{"op":"mcm","clk":"11838554779","pt":1723190975452,"mc":[{"id":"1.231583502","rc":[{"batb":[[0,2.1,10],[1,2.08,35.1],[2,1.8,2]],"ltp":2.1,"tv":100.04,"id":40096579},{"batb":[[0,1.86,10],[1,1.85,10],[2,1.83,257]],"ltp":1.91,"tv":36.44,"id":40096580}]}]}
{"op":"mcm","clk":"11838554950","pt":1723190978744,"mc":[{"id":"1.231583502","rc":[{"batb":[[0,2.08,35.1],[1,1.8,2],[2,1.74,17.32]],"ltp":2.1,"tv":100.04,"id":40096579},{"batb":[[0,1.85,10],[1,1.83,257],[2,1.81,200]],"ltp":1.91,"tv":36.44,"id":40096580}]}]}
{"op":"mcm","clk":"11838555146","pt":1723190982468,"mc":[{"id":"1.231583502","rc":[{"batb":[[0,2.1,10],[1,2.08,35.1],[2,1.8,2]],"ltp":2.1,"tv":100.04,"id":40096579},{"batb":[[0,1.86,10],[1,1.85,10],[2,1.83,257]],"ltp":1.91,"tv":36.44,"id":40096580}]}]}
{"op":"mcm","clk":"11838555346","pt":1723190985963,"mc":[{"id":"1.231583502","rc":[{"batb":[[0,2.08,35.1],[1,1.8,2],[2,1.74,17.32]],"ltp":2.1,"tv":100.04,"id":40096579},{"batb":[[0,1.85,10],[1,1.83,257],[2,1.81,200]],"ltp":1.91,"tv":36.44,"id":40096580}]}]}
{"op":"mcm","clk":"11838555518","pt":1723190988944,"mc":[{"id":"1.231583502","rc":[{"batb":[[0,2.1,10],[1,2.08,35.1],[2,1.8,2]],"ltp":2.1,"tv":100.04,"id":40096579},{"batb":[[0,1.86,10],[1,1.85,10],[2,1.83,257]],"ltp":1.91,"tv":36.44,"id":40096580}]}]}
{"op":"mcm","clk":"11838555703","pt":1723190992537,"mc":[{"id":"1.231583502","rc":[{"batb":[[0,2.08,35.1],[1,1.8,2],[2,1.74,17.32]],"ltp":2.1,"tv":100.04,"id":40096579},{"batb":[[0,1.85,10],[1,1.83,257],[2,1.81,200]],"ltp":1.91,"tv":36.44,"id":40096580}]}]}
{"op":"mcm","clk":"11838555884","pt":1723190995784,"mc":[{"id":"1.231583502","rc":[{"batb":[[0,2.1,10],[1,2.08,35.1],[2,1.8,2]],"ltp":2.1,"tv":100.04,"id":40096579},{"batb":[[0,1.86,10],[1,1.85,10],[2,1.83,257]],"ltp":1.91,"tv":36.44,"id":40096580}]}]}
{"op":"mcm","clk":"11838556066","pt":1723190999153,"mc":[{"id":"1.231583502","rc":[{"batb":[[0,2.08,35.1],[1,1.8,2],[2,1.74,17.32]],"ltp":2.1,"tv":100.04,"id":40096579},{"batb":[[0,1.85,10],[1,1.83,257],[2,1.81,200]],"ltp":1.91,"tv":36.44,"id":40096580}]}]}
{"op":"mcm","clk":"11838556283","pt":1723191002770,"mc":[{"id":"1.231583502","rc":[{"batb":[[0,2.1,10],[1,2.08,35.1],[2,1.8,2]],"ltp":2.1,"tv":100.04,"id":40096579},{"batb":[[0,1.86,10],[1,1.85,10],[2,1.83,257]],"ltp":1.91,"tv":36.44,"id":40096580}]}]}
{"op":"mcm","clk":"11838556464","pt":1723191006078,"mc":[{"id":"1.231583502","rc":[{"batb":[[0,2.08,35.1],[1,1.8,2],[2,1.74,17.32]],"ltp":2.1,"tv":100.04,"id":40096579},{"batb":[[0,1.85,10],[1,1.83,257],[2,1.81,200]],"ltp":1.91,"tv":36.44,"id":40096580}]}]}
{"op":"mcm","clk":"11838556653","pt":1723191009298,"mc":[{"id":"1.231583502","rc":[{"batb":[[0,2.1,10],[1,2.08,35.1],[2,1.8,2]],"ltp":2.1,"tv":100.04,"id":40096579},{"batb":[[0,1.86,10],[1,1.85,10],[2,1.83,257]],"ltp":1.91,"tv":36.44,"id":40096580}]}]}
{"op":"mcm","clk":"11838556856","pt":1723191012588,"mc":[{"id":"1.231583502","rc":[{"batb":[[0,2.08,35.1],[1,1.8,2],[2,1.74,17.32]],"ltp":2.1,"tv":100.04,"id":40096579},{"batb":[[0,1.85,10],[1,1.83,257],[2,1.81,200]],"ltp":1.91,"tv":36.44,"id":40096580}]}]}
{"op":"mcm","clk":"11838557031","pt":1723191015777,"mc":[{"id":"1.231583502","rc":[{"batb":[[0,2.1,10],[1,2.08,35.1],[2,1.8,2]],"ltp":2.1,"tv":100.04,"id":40096579},{"batb":[[0,1.86,10],[1,1.85,10],[2,1.83,257]],"ltp":1.91,"tv":36.44,"id":40096580}]}]}
{"op":"mcm","clk":"11838557185","pt":1723191019111,"mc":[{"id":"1.231583502","rc":[{"batb":[[0,2.08,35.1],[1,1.8,2],[2,1.74,17.32]],"ltp":2.1,"tv":100.04,"id":40096579},{"batb":[[0,1.85,10],[1,1.83,257],[2,1.81,200]],"ltp":1.91,"tv":36.44,"id":40096580}]}]}
{"op":"mcm","clk":"11838557332","pt":1723191022392,"mc":[{"id":"1.231583502","rc":[{"batb":[[0,2.1,10],[1,2.08,35.1],[2,1.8,2]],"ltp":2.1,"tv":100.04,"id":40096579},{"batb":[[0,1.86,10],[1,1.85,10],[2,1.83,257]],"ltp":1.91,"tv":36.44,"id":40096580}]}]}
{"op":"mcm","clk":"11838557522","pt":1723191025995,"mc":[{"id":"1.231583502","rc":[{"batb":[[0,2.08,35.1],[1,1.8,2],[2,1.74,17.32]],"ltp":2.1,"tv":100.04,"id":40096579},{"batb":[[0,1.85,10],[1,1.83,257],[2,1.81,200]],"ltp":1.91,"tv":36.44,"id":40096580}]}]}
{"op":"mcm","clk":"11838557682","pt":1723191028819,"mc":[{"id":"1.231583502","rc":[{"batb":[[0,2.1,10],[1,2.08,35.1],[2,1.8,2]],"ltp":2.1,"tv":100.04,"id":40096579},{"batb":[[0,1.86,10],[1,1.85,10],[2,1.83,257]],"ltp":1.91,"tv":36.44,"id":40096580}]}]}
{"op":"mcm","clk":"11838557860","pt":1723191032305,"mc":[{"id":"1.231583502","rc":[{"batb":[[0,2.08,35.1],[1,1.8,2],[2,1.74,17.32]],"ltp":2.1,"tv":100.04,"id":40096579},{"batb":[[0,1.85,10],[1,1.83,257],[2,1.81,200]],"ltp":1.91,"tv":36.44,"id":40096580}]}]}
{"op":"mcm","clk":"11838558004","pt":1723191035513,"mc":[{"id":"1.231583502","rc":[{"batb":[[0,2.1,10],[1,2.08,35.1],[2,1.8,2]],"ltp":2.1,"tv":100.04,"id":40096579},{"batb":[[0,1.86,10],[1,1.85,10],[2,1.83,257]],"ltp":1.91,"tv":36.44,"id":40096580}]}]}
{"op":"mcm","clk":"11838558166","pt":1723191038800,"mc":[{"id":"1.231583502","rc":[{"batb":[[0,2.08,35.1],[1,1.8,2],[2,1.74,17.32]],"ltp":2.1,"tv":100.04,"id":40096579},{"batb":[[0,1.85,10],[1,1.83,257],[2,1.81,200]],"ltp":1.91,"tv":36.44,"id":40096580}]}]}
{"op":"mcm","clk":"11838558322","pt":1723191041937,"mc":[{"id":"1.231583502","rc":[{"batb":[[0,2.1,10],[1,2.08,35.1],[2,1.8,2]],"ltp":2.1,"tv":100.04,"id":40096579},{"batb":[[0,1.86,10],[1,1.85,10],[2,1.83,257]],"ltp":1.91,"tv":36.44,"id":40096580}]}]}
{"op":"mcm","clk":"11838558512","pt":1723191045230,"mc":[{"id":"1.231583502","rc":[{"batb":[[0,2.08,35.1],[1,1.8,2],[2,1.74,17.32]],"ltp":2.1,"tv":100.04,"id":40096579},{"batb":[[0,1.85,10],[1,1.83,257],[2,1.81,200]],"ltp":1.91,"tv":36.44,"id":40096580}]}]}
{"op":"mcm","clk":"11838558689","pt":1723191048843,"mc":[{"id":"1.231583502","rc":[{"batb":[[0,2.1,10],[1,2.08,35.1],[2,1.8,2]],"ltp":2.1,"tv":100.04,"id":40096579},{"batb":[[0,1.86,10],[1,1.85,10],[2,1.83,257]],"ltp":1.91,"tv":36.44,"id":40096580}]}]}
{"op":"mcm","clk":"11838558849","pt":1723191052031,"mc":[{"id":"1.231583502","rc":[{"batb":[[0,2.08,35.1],[1,1.8,2],[2,1.74,17.32]],"ltp":2.1,"tv":100.04,"id":40096579},{"batb":[[0,1.85,10],[1,1.83,257],[2,1.81,200]],"ltp":1.91,"tv":36.44,"id":40096580}]}]}
{"op":"mcm","clk":"11838559089","pt":1723191056163,"mc":[{"id":"1.231583502","rc":[{"batb":[[0,2.1,10],[1,2.08,35.1],[2,1.8,2]],"ltp":2.1,"tv":100.04,"id":40096579},{"batb":[[0,1.86,10],[1,1.85,10],[2,1.83,257]],"ltp":1.91,"tv":36.44,"id":40096580}]}]}
{"op":"mcm","clk":"11838559295","pt":1723191059424,"mc":[{"id":"1.231583502","rc":[{"batb":[[0,2.08,35.1],[1,1.8,2],[2,1.74,17.32]],"ltp":2.1,"tv":100.04,"id":40096579},{"batb":[[0,1.85,10],[1,1.83,257],[2,1.81,200]],"ltp":1.91,"tv":36.44,"id":40096580}]}]}
{"op":"mcm","clk":"11838559485","pt":1723191063140,"mc":[{"id":"1.231583502","rc":[{"batb":[[0,2.1,10],[1,2.08,35.1],[2,1.8,2]],"ltp":2.1,"tv":100.04,"id":40096579},{"batb":[[0,1.86,10],[1,1.85,10],[2,1.83,257]],"ltp":1.91,"tv":36.44,"id":40096580}]}]}
{"op":"mcm","clk":"11838559665","pt":1723191066652,"mc":[{"id":"1.231583502","rc":[{"batb":[[0,2.08,35.1],[1,1.8,2],[2,1.74,17.32]],"ltp":2.1,"tv":100.04,"id":40096579},{"batb":[[0,1.85,10],[1,1.83,257],[2,1.81,200]],"ltp":1.91,"tv":36.44,"id":40096580}]}]}
{"op":"mcm","clk":"11838559853","pt":1723191069748,"mc":[{"id":"1.231583502","rc":[{"batb":[[0,2.1,10],[1,2.08,35.1],[2,1.8,2]],"ltp":2.1,"tv":100.04,"id":40096579},{"batb":[[0,1.86,10],[1,1.85,10],[2,1.83,257]],"ltp":1.91,"tv":36.44,"id":40096580}]}]}
{"op":"mcm","clk":"11838560031","pt":1723191073040,"mc":[{"id":"1.231583502","rc":[{"batb":[[0,2.08,35.1],[1,1.8,2],[2,1.74,17.32]],"ltp":2.1,"tv":100.04,"id":40096579},{"batb":[[0,1.85,10],[1,1.83,257],[2,1.81,200]],"ltp":1.91,"tv":36.44,"id":40096580}]}]}
{"op":"mcm","clk":"11838560209","pt":1723191076487,"mc":[{"id":"1.231583502","rc":[{"batb":[[0,2.1,10],[1,2.08,35.1],[2,1.8,2]],"ltp":2.1,"tv":100.04,"id":40096579},{"batb":[[0,1.86,10],[1,1.85,10],[2,1.83,257]],"ltp":1.91,"tv":36.44,"id":40096580}]}]}
{"op":"mcm","clk":"11838560412","pt":1723191080255,"mc":[{"id":"1.231583502","rc":[{"batb":[[0,2.08,35.1],[1,1.8,2],[2,1.74,17.32]],"ltp":2.1,"tv":100.04,"id":40096579},{"batb":[[0,1.85,10],[1,1.83,257],[2,1.81,200]],"ltp":1.91,"tv":36.44,"id":40096580}]}]}
{"op":"mcm","clk":"11838560581","pt":1723191083405,"mc":[{"id":"1.231583502","rc":[{"batb":[[0,2.1,10],[1,2.08,35.1],[2,1.8,2]],"ltp":2.1,"tv":100.04,"id":40096579},{"batb":[[0,1.86,10],[1,1.85,10],[2,1.83,257]],"ltp":1.91,"tv":36.44,"id":40096580}]}]}
{"op":"mcm","clk":"11838560755","pt":1723191086675,"mc":[{"id":"1.231583502","rc":[{"batb":[[0,2.08,35.1],[1,1.8,2],[2,1.74,17.32]],"ltp":2.1,"tv":100.04,"id":40096579},{"batb":[[0,1.85,10],[1,1.83,257],[2,1.81,200]],"ltp":1.91,"tv":36.44,"id":40096580}]}]}
{"op":"mcm","clk":"11838560896","pt":1723191089092,"mc":[{"id":"1.231583502","rc":[{"batb":[[0,2.1,10],[1,2.08,35.1],[2,1.8,2]],"ltp":2.1,"tv":100.04,"id":40096579},{"batb":[[0,1.86,10],[1,1.85,10],[2,1.83,257]],"ltp":1.91,"tv":36.44,"id":40096580}]}]}
{"op":"mcm","clk":"11838561128","pt":1723191092493,"mc":[{"id":"1.231583502","rc":[{"batb":[[0,2.08,35.1],[1,1.8,2],[2,1.74,17.32]],"ltp":2.1,"tv":100.04,"id":40096579},{"batb":[[0,1.85,10],[1,1.83,257],[2,1.81,200]],"ltp":1.91,"tv":36.44,"id":40096580}]}]}
{"op":"mcm","clk":"11838561270","pt":1723191095013,"mc":[{"id":"1.231583502","rc":[{"batb":[[0,2.1,10],[1,2.08,35.1],[2,1.8,2]],"ltp":2.1,"tv":100.04,"id":40096579},{"batb":[[0,1.86,10],[1,1.85,10],[2,1.83,257]],"ltp":1.91,"tv":36.44,"id":40096580}]}]}
{"op":"mcm","clk":"11838561433","pt":1723191098503,"mc":[{"id":"1.231583502","rc":[{"batb":[[0,2.08,35.1],[1,1.8,2],[2,1.74,17.32]],"ltp":2.1,"tv":100.04,"id":40096579},{"batb":[[0,1.85,10],[1,1.83,257],[2,1.81,200]],"ltp":1.91,"tv":36.44,"id":40096580}]}]}
{"op":"mcm","clk":"11838561621","pt":1723191101803,"mc":[{"id":"1.231583502","rc":[{"batb":[[0,2.1,10],[1,2.08,35.1],[2,1.8,2]],"ltp":2.1,"tv":100.04,"id":40096579},{"batb":[[0,1.86,10],[1,1.85,10],[2,1.83,257]],"ltp":1.91,"tv":36.44,"id":40096580}]}]}
{"op":"mcm","clk":"11838561811","pt":1723191105397,"mc":[{"id":"1.231583502","rc":[{"batb":[[0,2.08,35.1],[1,1.8,2],[2,1.74,17.32]],"ltp":2.1,"tv":100.04,"id":40096579},{"batb":[[0,1.85,10],[1,1.83,257],[2,1.81,200]],"ltp":1.91,"tv":36.44,"id":40096580}]}]}
{"op":"mcm","clk":"11838561918","pt":1723191107808,"mc":[{"id":"1.231583502","rc":[{"batb":[[0,2.1,10],[1,2.08,35.1],[2,1.8,2]],"ltp":2.1,"tv":100.04,"id":40096579},{"batb":[[0,1.86,10],[1,1.85,10],[2,1.83,257]],"ltp":1.91,"tv":36.44,"id":40096580}]}]}
{"op":"mcm","clk":"11838562086","pt":1723191111310,"mc":[{"id":"1.231583502","rc":[{"batb":[[0,2.08,35.1],[1,1.8,2],[2,1.74,17.32]],"ltp":2.1,"tv":100.04,"id":40096579},{"batb":[[0,1.85,10],[1,1.83,257],[2,1.81,200]],"ltp":1.91,"tv":36.44,"id":40096580}]}]}
{"op":"mcm","clk":"11838562294","pt":1723191115003,"mc":[{"id":"1.231583502","rc":[{"batb":[[0,2.1,10],[1,2.08,35.1],[2,1.8,2]],"ltp":2.1,"tv":100.04,"id":40096579},{"batb":[[0,1.86,10],[1,1.85,10],[2,1.83,257]],"ltp":1.91,"tv":36.44,"id":40096580}]}]}
{"op":"mcm","clk":"11838562463","pt":1723191118339,"mc":[{"id":"1.231583502","rc":[{"batb":[[0,2.08,35.1],[1,1.8,2],[2,1.74,17.32]],"ltp":2.1,"tv":100.04,"id":40096579},{"batb":[[0,1.85,10],[1,1.83,257],[2,1.81,200]],"ltp":1.91,"tv":36.44,"id":40096580}]}]}
{"op":"mcm","clk":"11838562560","pt":1723191120549,"mc":[{"id":"1.231583502","rc":[{"batb":[[0,2.1,10],[1,2.08,35.1],[2,1.8,2]],"ltp":2.1,"tv":100.04,"id":40096579},{"batb":[[0,1.86,10],[1,1.85,10],[2,1.83,257]],"ltp":1.91,"tv":36.44,"id":40096580}]}]}
{"op":"mcm","clk":"11838562741","pt":1723191124060,"mc":[{"id":"1.231583502","rc":[{"batb":[[0,2.08,35.1],[1,1.8,2],[2,1.74,17.32]],"ltp":2.1,"tv":100.04,"id":40096579},{"batb":[[0,1.85,10],[1,1.83,257],[2,1.81,200]],"ltp":1.91,"tv":36.44,"id":40096580}]}]}
{"op":"mcm","clk":"11838562937","pt":1723191127556,"mc":[{"id":"1.231583502","rc":[{"batb":[[0,2.1,10],[1,2.08,35.1],[2,1.8,2]],"ltp":2.1,"tv":100.04,"id":40096579},{"batb":[[0,1.86,10],[1,1.85,10],[2,1.83,257]],"ltp":1.91,"tv":36.44,"id":40096580}]}]}
{"op":"mcm","clk":"11838563187","pt":1723191130950,"mc":[{"id":"1.231583502","rc":[{"batb":[[0,2.08,35.1],[1,1.8,2],[2,1.74,17.32]],"ltp":2.1,"tv":100.04,"id":40096579},{"batb":[[0,1.85,10],[1,1.83,257],[2,1.81,200]],"ltp":1.91,"tv":36.44,"id":40096580}]}]}
{"op":"mcm","clk":"11838563311","pt":1723191133321,"mc":[{"id":"1.231583502","rc":[{"batb":[[0,2.1,10],[1,2.08,35.1],[2,1.8,2]],"ltp":2.1,"tv":100.04,"id":40096579},{"batb":[[0,1.86,10],[1,1.85,10],[2,1.83,257]],"ltp":1.91,"tv":36.44,"id":40096580}]}]}
{"op":"mcm","clk":"11838563479","pt":1723191136728,"mc":[{"id":"1.231583502","rc":[{"batb":[[0,2.08,35.1],[1,1.8,2],[2,1.74,17.32]],"ltp":2.1,"tv":100.04,"id":40096579},{"batb":[[0,1.85,10],[1,1.83,257],[2,1.81,200]],"ltp":1.91,"tv":36.44,"id":40096580}]}]}
{"op":"mcm","clk":"11838563617","pt":1723191139662,"mc":[{"id":"1.231583502","rc":[{"batb":[[0,2.1,10],[1,2.08,35.1],[2,1.8,2]],"ltp":2.1,"tv":100.04,"id":40096579},{"batb":[[0,1.86,10],[1,1.85,10],[2,1.83,257]],"ltp":1.91,"tv":36.44,"id":40096580}]}]}
{"op":"mcm","clk":"11838563793","pt":1723191143042,"mc":[{"id":"1.231583502","rc":[{"batb":[[0,2.08,35.1],[1,1.8,2],[2,1.74,17.32]],"ltp":2.1,"tv":100.04,"id":40096579},{"batb":[[0,1.85,10],[1,1.83,257],[2,1.81,200]],"ltp":1.91,"tv":36.44,"id":40096580}]}]}
{"op":"mcm","clk":"11838563965","pt":1723191146079,"mc":[{"id":"1.231583502","rc":[{"batb":[[0,2.1,10],[1,2.08,35.1],[2,1.8,2]],"ltp":2.1,"tv":100.04,"id":40096579},{"batb":[[0,1.86,10],[1,1.85,10],[2,1.83,257]],"ltp":1.91,"tv":36.44,"id":40096580}]}]}
{"op":"mcm","clk":"11838564160","pt":1723191149465,"mc":[{"id":"1.231583502","rc":[{"batb":[[0,2.08,35.1],[1,1.8,2],[2,1.74,17.32]],"ltp":2.1,"tv":100.04,"id":40096579},{"batb":[[0,1.85,10],[1,1.83,257],[2,1.81,200]],"ltp":1.91,"tv":36.44,"id":40096580}]}]}
{"op":"mcm","clk":"11838564298","pt":1723191152481,"mc":[{"id":"1.231583502","rc":[{"batb":[[0,2.1,10],[1,2.08,35.1],[2,1.8,2]],"ltp":2.1,"tv":100.04,"id":40096579},{"batb":[[0,1.86,10],[1,1.85,10],[2,1.83,257]],"ltp":1.91,"tv":36.44,"id":40096580}]}]}
{"op":"mcm","clk":"11838564475","pt":1723191156176,"mc":[{"id":"1.231583502","rc":[{"batb":[[0,2.08,35.1],[1,1.8,2],[2,1.74,17.32]],"ltp":2.1,"tv":100.04,"id":40096579},{"batb":[[0,1.85,10],[1,1.83,257],[2,1.81,200]],"ltp":1.91,"tv":36.44,"id":40096580}]}]}
{"op":"mcm","clk":"11838564666","pt":1723191159483,"mc":[{"id":"1.231583502","rc":[{"batb":[[0,2.1,10],[1,2.08,35.1],[2,1.8,2]],"ltp":2.1,"tv":100.04,"id":40096579},{"batb":[[0,1.86,10],[1,1.85,10],[2,1.83,257]],"ltp":1.91,"tv":36.44,"id":40096580}]}]}
{"op":"mcm","clk":"11838564860","pt":1723191162785,"mc":[{"id":"1.231583502","rc":[{"batb":[[0,2.08,35.1],[1,1.8,2],[2,1.74,17.32]],"ltp":2.1,"tv":100.04,"id":40096579},{"batb":[[0,1.85,10],[1,1.83,257],[2,1.81,200]],"ltp":1.91,"tv":36.44,"id":40096580}]}]}
{"op":"mcm","clk":"11838565034","pt":1723191166275,"mc":[{"id":"1.231583502","rc":[{"batb":[[0,2.1,10],[1,2.08,35.1],[2,1.8,2]],"ltp":2.1,"tv":100.04,"id":40096579},{"batb":[[0,1.86,10],[1,1.85,10],[2,1.83,257]],"ltp":1.91,"tv":36.44,"id":40096580}]}]}
{"op":"mcm","clk":"11838565257","pt":1723191170599,"mc":[{"id":"1.231583502","rc":[{"batb":[[0,2.08,35.1],[1,1.8,2],[2,1.74,17.32]],"ltp":2.1,"tv":100.04,"id":40096579},{"batb":[[0,1.85,10],[1,1.83,257],[2,1.81,200]],"ltp":1.91,"tv":36.44,"id":40096580}]}]}
{"op":"mcm","clk":"11838565493","pt":1723191174627,"mc":[{"id":"1.231583502","rc":[{"batb":[[0,2.1,10],[1,2.08,35.1],[2,1.8,2]],"ltp":2.1,"tv":100.04,"id":40096579},{"batb":[[0,1.86,10],[1,1.85,10],[2,1.83,257]],"ltp":1.91,"tv":36.44,"id":40096580}]}]}
{"op":"mcm","clk":"11838578952","pt":1723191178117,"mc":[{"id":"1.231583502","rc":[{"batb":[[0,2.08,35.1],[1,1.8,2],[2,1.74,17.32]],"ltp":2.1,"tv":100.04,"id":40096579},{"batb":[[0,1.85,10],[1,1.83,257],[2,1.81,200]],"ltp":1.91,"tv":36.44,"id":40096580}]}]}
{"op":"mcm","clk":"11838579126","pt":1723191181610,"mc":[{"id":"1.231583502","rc":[{"batb":[[0,2.1,10],[1,2.08,35.1],[2,1.8,2]],"ltp":2.1,"tv":100.04,"id":40096579},{"batb":[[0,1.86,10],[1,1.85,10],[2,1.83,257]],"ltp":1.91,"tv":36.44,"id":40096580}]}]}
{"op":"mcm","clk":"11838579306","pt":1723191185115,"mc":[{"id":"1.231583502","rc":[{"batb":[[0,2.08,35.1],[1,1.8,2],[2,1.74,17.32]],"ltp":2.1,"tv":100.04,"id":40096579},{"batb":[[0,1.85,10],[1,1.83,257],[2,1.81,200]],"ltp":1.91,"tv":36.44,"id":40096580}]}]}
{"op":"mcm","clk":"11838579595","pt":1723191190040,"mc":[{"id":"1.231583502","rc":[{"batb":[[0,2.1,10],[1,2.08,35.1],[2,1.8,2]],"ltp":2.1,"tv":100.04,"id":40096579},{"batb":[[0,1.86,10],[1,1.85,10],[2,1.83,257]],"ltp":1.91,"tv":36.44,"id":40096580}]}]}
{"op":"mcm","clk":"11838579763","pt":1723191193440,"mc":[{"id":"1.231583502","rc":[{"batb":[[0,2.08,35.1],[1,1.8,2],[2,1.74,17.32]],"ltp":2.1,"tv":100.04,"id":40096579},{"batb":[[0,1.85,10],[1,1.83,257],[2,1.81,200]],"ltp":1.91,"tv":36.44,"id":40096580}]}]}
{"op":"mcm","clk":"11838579980","pt":1723191197924,"mc":[{"id":"1.231583502","rc":[{"batb":[[0,2.1,10],[1,2.08,35.1],[2,1.8,2]],"ltp":2.1,"tv":100.04,"id":40096579},{"batb":[[0,1.86,10],[1,1.85,10],[2,1.83,257]],"ltp":1.91,"tv":36.44,"id":40096580}]}]}
{"op":"mcm","clk":"11838580145","pt":1723191201415,"mc":[{"id":"1.231583502","rc":[{"batb":[[0,2.08,35.1],[1,1.8,2],[2,1.74,17.32]],"ltp":2.1,"tv":100.04,"id":40096579},{"batb":[[0,1.85,10],[1,1.83,257],[2,1.81,200]],"ltp":1.91,"tv":36.44,"id":40096580}]}]}
{"op":"mcm","clk":"11838580330","pt":1723191204629,"mc":[{"id":"1.231583502","rc":[{"batb":[[0,2.1,10],[1,2.08,35.1],[2,1.8,2]],"ltp":2.1,"tv":100.04,"id":40096579},{"batb":[[0,1.86,10],[1,1.85,10],[2,1.83,257]],"ltp":1.91,"tv":36.44,"id":40096580}]}]}
{"op":"mcm","clk":"11838580520","pt":1723191208126,"mc":[{"id":"1.231583502","rc":[{"batb":[[0,2.08,35.1],[1,1.8,2],[2,1.74,17.32]],"ltp":2.1,"tv":100.04,"id":40096579},{"batb":[[0,1.85,10],[1,1.83,257],[2,1.81,200]],"ltp":1.91,"tv":36.44,"id":40096580}]}]}
{"op":"mcm","clk":"11838580820","pt":1723191213551,"mc":[{"id":"1.231583502","rc":[{"batb":[[0,2.1,10],[1,2.08,35.1],[2,1.8,2]],"ltp":2.1,"tv":100.04,"id":40096579},{"batb":[[0,1.86,10],[1,1.85,10],[2,1.83,257]],"ltp":1.91,"tv":36.44,"id":40096580}]}]}
{"op":"mcm","clk":"11838581016","pt":1723191217150,"mc":[{"id":"1.231583502","rc":[{"batb":[[0,2.08,35.1],[1,1.8,2],[2,1.74,17.32]],"ltp":2.1,"tv":100.04,"id":40096579},{"batb":[[0,1.85,10],[1,1.83,257],[2,1.81,200]],"ltp":1.91,"tv":36.44,"id":40096580}]}]}
{"op":"mcm","clk":"11838581163","pt":1723191220145,"mc":[{"id":"1.231583502","rc":[{"batb":[[0,2.1,10],[1,2.08,35.1],[2,1.8,2]],"ltp":2.1,"tv":100.04,"id":40096579},{"batb":[[0,1.86,10],[1,1.85,10],[2,1.83,257]],"ltp":1.91,"tv":36.44,"id":40096580}]}]}
{"op":"mcm","clk":"11838581337","pt":1723191223450,"mc":[{"id":"1.231583502","rc":[{"batb":[[0,2.08,35.1],[1,1.8,2],[2,1.74,17.32]],"ltp":2.1,"tv":100.04,"id":40096579},{"batb":[[0,1.85,10],[1,1.83,257],[2,1.81,200]],"ltp":1.91,"tv":36.44,"id":40096580}]}]}
{"op":"mcm","clk":"11838581460","pt":1723191226267,"mc":[{"id":"1.231583502","rc":[{"batb":[[0,2.1,10],[1,2.08,35.1],[2,1.8,2]],"ltp":2.1,"tv":100.04,"id":40096579},{"batb":[[0,1.86,10],[1,1.85,10],[2,1.83,257]],"ltp":1.91,"tv":36.44,"id":40096580}]}]}
{"op":"mcm","clk":"11838581699","pt":1723191229870,"mc":[{"id":"1.231583502","rc":[{"batb":[[0,2.08,35.1],[1,1.8,2],[2,1.74,17.32]],"ltp":2.1,"tv":100.04,"id":40096579},{"batb":[[0,1.85,10],[1,1.83,257],[2,1.81,200]],"ltp":1.91,"tv":36.44,"id":40096580}]}]}
{"op":"mcm","clk":"11838581975","pt":1723191235099,"mc":[{"id":"1.231583502","rc":[{"batb":[[0,2.1,10],[1,2.08,35.1],[2,1.8,2]],"ltp":2.1,"tv":100.04,"id":40096579},{"batb":[[0,1.86,10],[1,1.85,10],[2,1.83,257]],"ltp":1.91,"tv":36.44,"id":40096580}]}]}
{"op":"mcm","clk":"11838582182","pt":1723191238699,"mc":[{"id":"1.231583502","rc":[{"batb":[[0,2.08,35.1],[1,1.8,2],[2,1.74,17.32]],"ltp":2.1,"tv":100.04,"id":40096579},{"batb":[[0,1.85,10],[1,1.83,257],[2,1.81,200]],"ltp":1.91,"tv":36.44,"id":40096580}]}]}
{"op":"mcm","clk":"11838582335","pt":1723191241900,"mc":[{"id":"1.231583502","rc":[{"batb":[[0,2.1,10],[1,2.08,35.1],[2,1.8,2]],"ltp":2.1,"tv":100.04,"id":40096579},{"batb":[[0,1.86,10],[1,1.85,10],[2,1.83,257]],"ltp":1.91,"tv":36.44,"id":40096580}]}]}
{"op":"mcm","clk":"11838582568","pt":1723191245586,"mc":[{"id":"1.231583502","rc":[{"batb":[[0,2.08,35.1],[1,1.8,2],[2,1.74,17.32]],"ltp":2.1,"tv":100.04,"id":40096579},{"batb":[[0,1.85,10],[1,1.83,257],[2,1.81,200]],"ltp":1.91,"tv":36.44,"id":40096580}]}]}
{"op":"mcm","clk":"11838582714","pt":1723191248008,"mc":[{"id":"1.231583502","rc":[{"batb":[[0,2.1,10],[1,2.08,35.1],[2,1.8,2]],"ltp":2.1,"tv":100.04,"id":40096579},{"batb":[[0,1.86,10],[1,1.85,10],[2,1.83,257]],"ltp":1.91,"tv":36.44,"id":40096580}]}]}
{"op":"mcm","clk":"11838582914","pt":1723191251921,"mc":[{"id":"1.231583502","rc":[{"batb":[[0,2.08,35.1],[1,1.8,2],[2,1.74,17.32]],"ltp":2.1,"tv":100.04,"id":40096579},{"batb":[[0,1.85,10],[1,1.83,257],[2,1.81,200]],"ltp":1.91,"tv":36.44,"id":40096580}]}]}
{"op":"mcm","clk":"11838583058","pt":1723191255021,"mc":[{"id":"1.231583502","rc":[{"batb":[[0,2.1,10],[1,2.08,35.1],[2,1.8,2]],"ltp":2.1,"tv":100.04,"id":40096579},{"batb":[[0,1.86,10],[1,1.85,10],[2,1.83,257]],"ltp":1.91,"tv":36.44,"id":40096580}]}]}
{"op":"mcm","clk":"11838583213","pt":1723191258524,"mc":[{"id":"1.231583502","rc":[{"batb":[[0,2.08,35.1],[1,1.8,2],[2,1.74,17.32]],"ltp":2.1,"tv":100.04,"id":40096579},{"batb":[[0,1.85,10],[1,1.83,257],[2,1.81,200]],"ltp":1.91,"tv":36.44,"id":40096580}]}]}
{"op":"mcm","clk":"11838583429","pt":1723191262484,"mc":[{"id":"1.231583502","rc":[{"batb":[[0,2.1,10],[1,2.08,35.1],[2,1.8,2]],"ltp":2.1,"tv":100.04,"id":40096579},{"batb":[[0,1.86,10],[1,1.85,10],[2,1.83,257]],"ltp":1.91,"tv":36.44,"id":40096580}]}]}
{"op":"mcm","clk":"11838583630","pt":1723191265820,"mc":[{"id":"1.231583502","rc":[{"batb":[[0,2.08,35.1],[1,1.8,2],[2,1.74,17.32]],"ltp":2.1,"tv":100.04,"id":40096579},{"batb":[[0,1.85,10],[1,1.83,257],[2,1.81,200]],"ltp":1.91,"tv":36.44,"id":40096580}]}]}
{"op":"mcm","clk":"11838583887","pt":1723191271819,"mc":[{"id":"1.231583502","rc":[{"batb":[[0,2.1,10],[1,2.08,35.1],[2,1.8,2]],"ltp":2.1,"tv":100.04,"id":40096579},{"batb":[[0,1.86,10],[1,1.85,10],[2,1.83,257]],"ltp":1.91,"tv":36.44,"id":40096580}]}]}
{"op":"mcm","clk":"11838584056","pt":1723191275421,"mc":[{"id":"1.231583502","rc":[{"batb":[[0,2.08,35.1],[1,1.8,2],[2,1.74,17.32]],"ltp":2.1,"tv":100.04,"id":40096579},{"batb":[[0,1.85,10],[1,1.83,257],[2,1.81,200]],"ltp":1.91,"tv":36.44,"id":40096580}]}]}
{"op":"mcm","clk":"11838584217","pt":1723191278537,"mc":[{"id":"1.231583502","rc":[{"batb":[[0,2.1,10],[1,2.08,35.1],[2,1.8,2]],"ltp":2.1,"tv":100.04,"id":40096579},{"batb":[[0,1.86,10],[1,1.85,10],[2,1.83,257]],"ltp":1.91,"tv":36.44,"id":40096580}]}]}
{"op":"mcm","clk":"11838584386","pt":1723191282128,"mc":[{"id":"1.231583502","rc":[{"batb":[[0,2.08,35.1],[1,1.8,2],[2,1.74,17.32]],"ltp":2.1,"tv":100.04,"id":40096579},{"batb":[[0,1.85,10],[1,1.83,257],[2,1.81,200]],"ltp":1.91,"tv":36.44,"id":40096580}]}]}
{"op":"mcm","clk":"11838584573","pt":1723191285730,"mc":[{"id":"1.231583502","rc":[{"batb":[[0,2.1,10],[1,2.08,35.1],[2,1.8,2]],"ltp":2.1,"tv":100.04,"id":40096579},{"batb":[[0,1.86,10],[1,1.85,10],[2,1.83,257]],"ltp":1.91,"tv":36.44,"id":40096580}]}]}
{"op":"mcm","clk":"11838584726","pt":1723191289062,"mc":[{"id":"1.231583502","rc":[{"batb":[[0,2.08,35.1],[1,1.8,2],[2,1.74,17.32]],"ltp":2.1,"tv":100.04,"id":40096579},{"batb":[[0,1.85,10],[1,1.83,257],[2,1.81,200]],"ltp":1.91,"tv":36.44,"id":40096580}]}]}
{"op":"mcm","clk":"11838584854","pt":1723191291976,"mc":[{"id":"1.231583502","rc":[{"batb":[[0,2.1,10],[1,2.08,35.1],[2,1.8,2]],"ltp":2.1,"tv":100.04,"id":40096579},{"batb":[[0,1.86,10],[1,1.85,10],[2,1.83,257]],"ltp":1.91,"tv":36.44,"id":40096580}]}]}
{"op":"mcm","clk":"11838585029","pt":1723191295476,"mc":[{"id":"1.231583502","rc":[{"batb":[[0,2.08,35.1],[1,1.8,2],[2,1.74,17.32]],"ltp":2.1,"tv":100.04,"id":40096579},{"batb":[[0,1.85,10],[1,1.83,257],[2,1.81,200]],"ltp":1.91,"tv":36.44,"id":40096580}]}]}
{"op":"mcm","clk":"11838585326","pt":1723191300974,"mc":[{"id":"1.231583502","rc":[{"batb":[[0,2.1,10],[1,2.08,35.1],[2,1.8,2]],"ltp":2.1,"tv":100.04,"id":40096579},{"batb":[[0,1.86,10],[1,1.85,10],[2,1.83,257]],"ltp":1.91,"tv":36.44,"id":40096580}]}]}
{"op":"mcm","clk":"11838585513","pt":1723191304480,"mc":[{"id":"1.231583502","rc":[{"batb":[[0,2.08,35.1],[1,1.8,2],[2,1.74,17.32]],"ltp":2.1,"tv":100.04,"id":40096579},{"batb":[[0,1.85,10],[1,1.83,257],[2,1.81,200]],"ltp":1.91,"tv":36.44,"id":40096580}]}]}
{"op":"mcm","clk":"11838585621","pt":1723191307098,"mc":[{"id":"1.231583502","rc":[{"batb":[[0,2.1,10],[1,2.08,35.1],[2,1.8,2]],"ltp":2.1,"tv":100.04,"id":40096579},{"batb":[[0,1.86,10],[1,1.85,10],[2,1.83,257]],"ltp":1.91,"tv":36.44,"id":40096580}]}]}
{"op":"mcm","clk":"11838585801","pt":1723191310395,"mc":[{"id":"1.231583502","rc":[{"batb":[[0,2.08,35.1],[1,1.8,2],[2,1.74,17.32]],"ltp":2.1,"tv":100.04,"id":40096579},{"batb":[[0,1.85,10],[1,1.83,257],[2,1.81,200]],"ltp":1.91,"tv":36.44,"id":40096580}]}]}
{"op":"mcm","clk":"11838585937","pt":1723191312598,"mc":[{"id":"1.231583502","rc":[{"batb":[[0,2.1,10],[1,2.08,35.1],[2,1.8,2]],"ltp":2.1,"tv":100.04,"id":40096579},{"batb":[[0,1.86,10],[1,1.85,10],[2,1.83,257]],"ltp":1.91,"tv":36.44,"id":40096580}]}]}
{"op":"mcm","clk":"11838586099","pt":1723191316103,"mc":[{"id":"1.231583502","rc":[{"batb":[[0,2.08,35.1],[1,1.8,2],[2,1.74,17.32]],"ltp":2.1,"tv":100.04,"id":40096579},{"batb":[[0,1.85,10],[1,1.83,257],[2,1.81,200]],"ltp":1.91,"tv":36.44,"id":40096580}]}]}
{"op":"mcm","clk":"11838586251","pt":1723191318896,"mc":[{"id":"1.231583502","rc":[{"batb":[[0,2.1,10],[1,2.08,35.1],[2,1.8,2]],"ltp":2.1,"tv":100.04,"id":40096579},{"batb":[[0,1.86,10],[1,1.85,10],[2,1.83,257]],"ltp":1.91,"tv":36.44,"id":40096580}]}]}
{"op":"mcm","clk":"11838586457","pt":1723191322807,"mc":[{"id":"1.231583502","rc":[{"batb":[[0,2.08,35.1],[1,1.8,2],[2,1.74,17.32]],"ltp":2.1,"tv":100.04,"id":40096579},{"batb":[[0,1.85,10],[1,1.83,257],[2,1.81,200]],"ltp":1.91,"tv":36.44,"id":40096580}]}]}
{"op":"mcm","clk":"11838586606","pt":1723191326007,"mc":[{"id":"1.231583502","rc":[{"batb":[[0,2.1,10],[1,2.08,35.1],[2,1.8,2]],"ltp":2.1,"tv":100.04,"id":40096579},{"batb":[[0,1.86,10],[1,1.85,10],[2,1.83,257]],"ltp":1.91,"tv":36.44,"id":40096580}]}]}
{"op":"mcm","clk":"11838586807","pt":1723191329623,"mc":[{"id":"1.231583502","rc":[{"batb":[[0,2.08,35.1],[1,1.8,2],[2,1.74,17.32]],"ltp":2.1,"tv":100.04,"id":40096579},{"batb":[[0,1.85,10],[1,1.83,257],[2,1.81,200]],"ltp":1.91,"tv":36.44,"id":40096580}]}]}
{"op":"mcm","clk":"11838586950","pt":1723191333018,"mc":[{"id":"1.231583502","rc":[{"batb":[[0,2.1,10],[1,2.08,35.1],[2,1.8,2]],"ltp":2.1,"tv":100.04,"id":40096579},{"batb":[[0,1.86,10],[1,1.85,10],[2,1.83,257]],"ltp":1.91,"tv":36.44,"id":40096580}]}]}
{"op":"mcm","clk":"11838587105","pt":1723191336509,"mc":[{"id":"1.231583502","rc":[{"batb":[[0,2.08,35.1],[1,1.8,2],[2,1.74,17.32]],"ltp":2.1,"tv":100.04,"id":40096579},{"batb":[[0,1.85,10],[1,1.83,257],[2,1.81,200]],"ltp":1.91,"tv":36.44,"id":40096580}]}]}
{"op":"mcm","clk":"11838587226","pt":1723191338829,"mc":[{"id":"1.231583502","rc":[{"batb":[[0,2.1,10],[1,2.08,35.1],[2,1.8,2]],"ltp":2.1,"tv":100.04,"id":40096579},{"batb":[[0,1.86,10],[1,1.85,10],[2,1.83,257]],"ltp":1.91,"tv":36.44,"id":40096580}]}]}
{"op":"mcm","clk":"11838587388","pt":1723191342631,"mc":[{"id":"1.231583502","rc":[{"batb":[[0,2.08,35.1],[1,1.8,2],[2,1.74,17.32]],"ltp":2.1,"tv":100.04,"id":40096579},{"batb":[[0,1.85,10],[1,1.83,257],[2,1.81,200]],"ltp":1.91,"tv":36.44,"id":40096580}]}]}
{"op":"mcm","clk":"11838587722","pt":1723191349912,"mc":[{"id":"1.231583502","rc":[{"batb":[[0,2.1,10],[1,2.08,35.1],[2,1.8,2]],"ltp":2.1,"tv":100.04,"id":40096579},{"batb":[[0,1.86,10],[1,1.85,10],[2,1.83,257]],"ltp":1.91,"tv":36.44,"id":40096580}]}]}
{"op":"mcm","clk":"11838587870","pt":1723191353354,"mc":[{"id":"1.231583502","rc":[{"batb":[[0,2.08,35.1],[1,1.8,2],[2,1.74,17.32]],"ltp":2.1,"tv":100.04,"id":40096579},{"batb":[[0,1.85,10],[1,1.83,257],[2,1.81,200]],"ltp":1.91,"tv":36.44,"id":40096580}]}]}
{"op":"mcm","clk":"11838587978","pt":1723191356121,"mc":[{"id":"1.231583502","rc":[{"batb":[[0,2.1,10],[1,2.08,35.1],[2,1.8,2]],"ltp":2.1,"tv":100.04,"id":40096579},{"batb":[[0,1.86,10],[1,1.85,10],[2,1.83,257]],"ltp":1.91,"tv":36.44,"id":40096580}]}]}
{"op":"mcm","clk":"11838588162","pt":1723191359457,"mc":[{"id":"1.231583502","rc":[{"batb":[[0,2.08,35.1],[1,1.8,2],[2,1.74,17.32]],"ltp":2.1,"tv":100.04,"id":40096579},{"batb":[[0,1.85,10],[1,1.83,257],[2,1.81,200]],"ltp":1.91,"tv":36.44,"id":40096580}]}]}
{"op":"mcm","clk":"11838588289","pt":1723191362125,"mc":[{"id":"1.231583502","rc":[{"batb":[[0,2.1,10],[1,2.08,35.1],[2,1.8,2]],"ltp":2.1,"tv":100.04,"id":40096579},{"batb":[[0,1.86,10],[1,1.85,10],[2,1.83,257]],"ltp":1.91,"tv":36.44,"id":40096580}]}]}
{"op":"mcm","clk":"11838588425","pt":1723191365460,"mc":[{"id":"1.231583502","rc":[{"batb":[[0,2.08,35.1],[1,1.8,2],[2,1.74,17.32]],"ltp":2.1,"tv":100.04,"id":40096579},{"batb":[[0,1.85,10],[1,1.83,257],[2,1.81,200]],"ltp":1.91,"tv":36.44,"id":40096580}]}]}
{"op":"mcm","clk":"11838588585","pt":1723191368241,"mc":[{"id":"1.231583502","rc":[{"batb":[[0,2.1,10],[1,2.08,35.1],[2,1.8,2]],"ltp":2.1,"tv":100.04,"id":40096579},{"batb":[[0,1.86,10],[1,1.85,10],[2,1.83,257]],"ltp":1.91,"tv":36.44,"id":40096580}]}]}
{"op":"mcm","clk":"11838588791","pt":1723191371756,"mc":[{"id":"1.231583502","rc":[{"batb":[[0,2.08,35.1],[1,1.8,2],[2,1.74,17.32]],"ltp":2.1,"tv":100.04,"id":40096579},{"batb":[[0,1.85,10],[1,1.83,257],[2,1.81,200]],"ltp":1.91,"tv":36.44,"id":40096580}]}]}
{"op":"mcm","clk":"11838589155","pt":1723191378392,"mc":[{"id":"1.231583502","rc":[{"batb":[[0,2.1,10],[1,2.08,35.1],[2,1.8,2]],"ltp":2.1,"tv":100.04,"id":40096579},{"batb":[[0,1.86,10],[1,1.85,10],[2,1.83,257]],"ltp":1.91,"tv":36.44,"id":40096580}]}]}
{"op":"mcm","clk":"11838589309","pt":1723191381779,"mc":[{"id":"1.231583502","rc":[{"batb":[[0,2.08,35.1],[1,1.8,2],[2,1.74,17.32]],"ltp":2.1,"tv":100.04,"id":40096579},{"batb":[[0,1.85,10],[1,1.83,257],[2,1.81,200]],"ltp":1.91,"tv":36.44,"id":40096580}]}]}
{"op":"mcm","clk":"11838589431","pt":1723191384092,"mc":[{"id":"1.231583502","rc":[{"batb":[[0,2.1,10],[1,2.08,35.1],[2,1.8,2]],"ltp":2.1,"tv":100.04,"id":40096579},{"batb":[[0,1.86,10],[1,1.85,10],[2,1.83,257]],"ltp":1.91,"tv":36.44,"id":40096580}]}]}
{"op":"mcm","clk":"11838589592","pt":1723191387589,"mc":[{"id":"1.231583502","rc":[{"batb":[[0,2.08,35.1],[1,1.8,2],[2,1.74,17.32]],"ltp":2.1,"tv":100.04,"id":40096579},{"batb":[[0,1.85,10],[1,1.83,257],[2,1.81,200]],"ltp":1.91,"tv":36.44,"id":40096580}]}]}
{"op":"mcm","clk":"11838589744","pt":1723191391073,"mc":[{"id":"1.231583502","rc":[{"batb":[[0,2.1,10],[1,2.08,35.1],[2,1.8,2]],"ltp":2.1,"tv":100.04,"id":40096579},{"batb":[[0,1.86,10],[1,1.85,10],[2,1.83,257]],"ltp":1.91,"tv":36.44,"id":40096580}]}]}
{"op":"mcm","clk":"11838589964","pt":1723191394569,"mc":[{"id":"1.231583502","rc":[{"batb":[[0,2.08,35.1],[1,1.8,2],[2,1.74,17.32]],"ltp":2.1,"tv":100.04,"id":40096579},{"batb":[[0,1.85,10],[1,1.83,257],[2,1.81,200]],"ltp":1.91,"tv":36.44,"id":40096580}]}]}
{"op":"mcm","clk":"11838590194","pt":1723191399004,"mc":[{"id":"1.231583502","rc":[{"batb":[[0,2.1,10],[1,2.08,35.1],[2,1.8,2]],"ltp":2.1,"tv":100.04,"id":40096579},{"batb":[[0,1.86,10],[1,1.85,10],[2,1.83,257]],"ltp":1.91,"tv":36.44,"id":40096580}]}]}
{"op":"mcm","clk":"11838590324","pt":1723191402295,"mc":[{"id":"1.231583502","rc":[{"batb":[[0,2.08,35.1],[1,1.8,2],[2,1.74,17.32]],"ltp":2.1,"tv":100.04,"id":40096579},{"batb":[[0,1.85,10],[1,1.83,257],[2,1.81,200]],"ltp":1.91,"tv":36.44,"id":40096580}]}]}
{"op":"mcm","clk":"11838590448","pt":1723191404613,"mc":[{"id":"1.231583502","rc":[{"batb":[[0,2.1,10],[1,2.08,35.1],[2,1.8,2]],"ltp":2.1,"tv":100.04,"id":40096579},{"batb":[[0,1.86,10],[1,1.85,10],[2,1.83,257]],"ltp":1.91,"tv":36.44,"id":40096580}]}]}
{"op":"mcm","clk":"11838590596","pt":1723191407889,"mc":[{"id":"1.231583502","rc":[{"batb":[[0,2.08,35.1],[1,1.8,2],[2,1.74,17.32]],"ltp":2.1,"tv":100.04,"id":40096579},{"batb":[[0,1.85,10],[1,1.83,257],[2,1.81,200]],"ltp":1.91,"tv":36.44,"id":40096580}]}]}
{"op":"mcm","clk":"11838590770","pt":1723191411493,"mc":[{"id":"1.231583502","rc":[{"batb":[[0,2.1,10],[1,2.08,35.1],[2,1.8,2]],"ltp":2.1,"tv":100.04,"id":40096579},{"batb":[[0,1.86,10],[1,1.85,10],[2,1.83,257]],"ltp":1.91,"tv":36.44,"id":40096580}]}]}
{"op":"mcm","clk":"11838590956","pt":1723191414833,"mc":[{"id":"1.231583502","rc":[{"batb":[[0,2.08,35.1],[1,1.8,2],[2,1.74,17.32]],"ltp":2.1,"tv":100.04,"id":40096579},{"batb":[[0,1.85,10],[1,1.83,257],[2,1.81,200]],"ltp":1.91,"tv":36.44,"id":40096580}]}]}
{"op":"mcm","clk":"11838591190","pt":1723191420127,"mc":[{"id":"1.231583502","rc":[{"batb":[[0,2.1,10],[1,2.08,35.1],[2,1.8,2]],"ltp":2.1,"tv":100.04,"id":40096579},{"batb":[[0,1.86,10],[1,1.85,10],[2,1.83,257]],"ltp":1.91,"tv":36.44,"id":40096580}]}]}
{"op":"mcm","clk":"11838591363","pt":1723191423531,"mc":[{"id":"1.231583502","rc":[{"batb":[[0,2.08,35.1],[1,1.8,2],[2,1.74,17.32]],"ltp":2.1,"tv":100.04,"id":40096579},{"batb":[[0,1.85,10],[1,1.83,257],[2,1.81,200]],"ltp":1.91,"tv":36.44,"id":40096580}]}]}
{"op":"mcm","clk":"11838591486","pt":1723191426410,"mc":[{"id":"1.231583502","rc":[{"batb":[[0,2.1,10],[1,2.08,35.1],[2,1.8,2]],"ltp":2.1,"tv":100.04,"id":40096579},{"batb":[[0,1.86,10],[1,1.85,10],[2,1.83,257]],"ltp":1.91,"tv":36.44,"id":40096580}]}]}
{"op":"mcm","clk":"11838591659","pt":1723191429922,"mc":[{"id":"1.231583502","rc":[{"batb":[[0,2.08,35.1],[1,1.8,2],[2,1.74,17.32]],"ltp":2.1,"tv":100.04,"id":40096579},{"batb":[[0,1.85,10],[1,1.83,257],[2,1.81,200]],"ltp":1.91,"tv":36.44,"id":40096580}]}]}
{"op":"mcm","clk":"11838591811","pt":1723191433359,"mc":[{"id":"1.231583502","rc":[{"batb":[[0,2.1,10],[1,2.08,35.1],[2,1.8,2]],"ltp":2.1,"tv":100.04,"id":40096579},{"batb":[[0,1.86,10],[1,1.85,10],[2,1.83,257]],"ltp":1.91,"tv":36.44,"id":40096580}]}]}
{"op":"mcm","clk":"11838591934","pt":1723191436847,"mc":[{"id":"1.231583502","rc":[{"batb":[[0,2.08,35.1],[1,1.8,2],[2,1.74,17.32]],"ltp":2.1,"tv":100.04,"id":40096579},{"batb":[[0,1.85,10],[1,1.83,257],[2,1.81,200]],"ltp":1.91,"tv":36.44,"id":40096580}]}]}
{"op":"mcm","clk":"11838592068","pt":1723191440231,"mc":[{"id":"1.231583502","rc":[{"batb":[[0,2.1,10],[1,2.08,35.1],[2,1.8,2]],"ltp":2.1,"tv":100.04,"id":40096579},{"batb":[[0,1.86,10],[1,1.85,10],[2,1.83,257]],"ltp":1.91,"tv":36.44,"id":40096580}]}]}
{"op":"mcm","clk":"11838592326","pt":1723191447156,"mc":[{"id":"1.231583502","rc":[{"batb":[[0,2.08,35.1],[1,1.8,2],[2,1.74,17.32]],"ltp":2.1,"tv":100.04,"id":40096579},{"batb":[[0,1.85,10],[1,1.83,257],[2,1.81,200]],"ltp":1.91,"tv":36.44,"id":40096580}]}]}
{"op":"mcm","clk":"11838592445","pt":1723191450077,"mc":[{"id":"1.231583502","rc":[{"batb":[[0,2.1,10],[1,2.08,35.1],[2,1.8,2]],"ltp":2.1,"tv":100.04,"id":40096579},{"batb":[[0,1.86,10],[1,1.85,10],[2,1.83,257]],"ltp":1.91,"tv":36.44,"id":40096580}]}]}
{"op":"mcm","clk":"11838592575","pt":1723191453569,"mc":[{"id":"1.231583502","rc":[{"batb":[[0,2.08,35.1],[1,1.8,2],[2,1.74,17.32]],"ltp":2.1,"tv":100.04,"id":40096579},{"batb":[[0,1.85,10],[1,1.83,257],[2,1.81,200]],"ltp":1.91,"tv":36.44,"id":40096580}]}]}
{"op":"mcm","clk":"11838592777","pt":1723191458061,"mc":[{"id":"1.231583502","rc":[{"batb":[[0,2.1,10],[1,2.08,35.1],[2,1.8,2]],"ltp":2.1,"tv":100.04,"id":40096579},{"batb":[[0,1.86,10],[1,1.85,10],[2,1.83,257]],"ltp":1.91,"tv":36.44,"id":40096580}]}]}
{"op":"mcm","clk":"11838592935","pt":1723191461673,"mc":[{"id":"1.231583502","rc":[{"batb":[[0,2.08,35.1],[1,1.8,2],[2,1.74,17.32]],"ltp":2.1,"tv":100.04,"id":40096579},{"batb":[[0,1.85,10],[1,1.83,257],[2,1.81,200]],"ltp":1.91,"tv":36.44,"id":40096580}]}]}
{"op":"mcm","clk":"11838593093","pt":1723191464859,"mc":[{"id":"1.231583502","rc":[{"batb":[[0,2.1,10],[1,2.08,35.1],[2,1.8,2]],"ltp":2.1,"tv":100.04,"id":40096579},{"batb":[[0,1.86,10],[1,1.85,10],[2,1.83,257]],"ltp":1.91,"tv":36.44,"id":40096580}]}]}
{"op":"mcm","clk":"11838593297","pt":1723191468591,"mc":[{"id":"1.231583502","rc":[{"batb":[[0,2.08,35.1],[1,1.8,2],[2,1.74,17.32]],"ltp":2.1,"tv":100.04,"id":40096579},{"batb":[[0,1.85,10],[1,1.83,257],[2,1.81,200]],"ltp":1.91,"tv":36.44,"id":40096580}]}]}
{"op":"mcm","clk":"11838593441","pt":1723191471769,"mc":[{"id":"1.231583502","rc":[{"batb":[[0,2.1,10],[1,2.08,35.1],[2,1.8,2]],"ltp":2.1,"tv":100.04,"id":40096579},{"batb":[[0,1.86,10],[1,1.85,10],[2,1.83,257]],"ltp":1.91,"tv":36.44,"id":40096580}]}]}
{"op":"mcm","clk":"11838593597","pt":1723191475313,"mc":[{"id":"1.231583502","rc":[{"batb":[[0,2.08,35.1],[1,1.8,2],[2,1.74,17.32]],"ltp":2.1,"tv":100.04,"id":40096579},{"batb":[[0,1.85,10],[1,1.83,257],[2,1.81,200]],"ltp":1.91,"tv":36.44,"id":40096580}]}]}
{"op":"mcm","clk":"11838593705","pt":1723191477568,"mc":[{"id":"1.231583502","rc":[{"batb":[[0,2.1,10],[1,2.08,35.1],[2,1.8,2]],"ltp":2.1,"tv":100.04,"id":40096579},{"batb":[[0,1.86,10],[1,1.85,10],[2,1.83,257]],"ltp":1.91,"tv":36.44,"id":40096580}]}]}
{"op":"mcm","clk":"11838593859","pt":1723191481531,"mc":[{"id":"1.231583502","rc":[{"batb":[[0,2.08,35.1],[1,1.8,2],[2,1.74,17.32]],"ltp":2.1,"tv":100.04,"id":40096579},{"batb":[[0,1.85,10],[1,1.83,257],[2,1.81,200]],"ltp":1.91,"tv":36.44,"id":40096580}]}]}
{"op":"mcm","clk":"11838593971","pt":1723191483991,"mc":[{"id":"1.231583502","rc":[{"batb":[[0,2.1,10],[1,2.08,35.1],[2,1.8,2]],"ltp":2.1,"tv":100.04,"id":40096579},{"batb":[[0,1.86,10],[1,1.85,10],[2,1.83,257]],"ltp":1.91,"tv":36.44,"id":40096580}]}]}
{"op":"mcm","clk":"11838594087","pt":1723191487418,"mc":[{"id":"1.231583502","rc":[{"batb":[[0,2.08,35.1],[1,1.8,2],[2,1.74,17.32]],"ltp":2.1,"tv":100.04,"id":40096579},{"batb":[[0,1.85,10],[1,1.83,257],[2,1.81,200]],"ltp":1.91,"tv":36.44,"id":40096580}]}]}
{"op":"mcm","clk":"11838594533","pt":1723191496037,"mc":[{"id":"1.231583502","rc":[{"batb":[[0,2.1,10],[1,2.08,35.1],[2,1.8,2]],"ltp":2.1,"tv":100.04,"id":40096579},{"batb":[[0,1.86,10],[1,1.85,10],[2,1.83,257]],"ltp":1.91,"tv":36.44,"id":40096580}]}]}
{"op":"mcm","clk":"11838594712","pt":1723191499724,"mc":[{"id":"1.231583502","rc":[{"batb":[[0,2.08,35.1],[1,1.8,2],[2,1.74,17.32]],"ltp":2.1,"tv":100.04,"id":40096579},{"batb":[[0,1.85,10],[1,1.83,257],[2,1.81,200]],"ltp":1.91,"tv":36.44,"id":40096580}]}]}
{"op":"mcm","clk":"11838594826","pt":1723191502241,"mc":[{"id":"1.231583502","rc":[{"batb":[[0,2.1,10],[1,2.08,35.1],[2,1.8,2]],"ltp":2.1,"tv":100.04,"id":40096579},{"batb":[[0,1.86,10],[1,1.85,10],[2,1.83,257]],"ltp":1.91,"tv":36.44,"id":40096580}]}]}
{"op":"mcm","clk":"11838595015","pt":1723191505826,"mc":[{"id":"1.231583502","rc":[{"batb":[[0,2.08,35.1],[1,1.8,2],[2,1.74,17.32]],"ltp":2.1,"tv":100.04,"id":40096579},{"batb":[[0,1.85,10],[1,1.83,257],[2,1.81,200]],"ltp":1.91,"tv":36.44,"id":40096580}]}]}
{"op":"mcm","clk":"11838595206","pt":1723191510022,"mc":[{"id":"1.231583502","rc":[{"batb":[[0,2.1,10],[1,2.08,35.1],[2,1.8,2]],"ltp":2.1,"tv":100.04,"id":40096579},{"batb":[[0,1.86,10],[1,1.85,10],[2,1.83,257]],"ltp":1.91,"tv":36.44,"id":40096580}]}]}
{"op":"mcm","clk":"11838595355","pt":1723191513454,"mc":[{"id":"1.231583502","rc":[{"batb":[[0,2.08,35.1],[1,1.8,2],[2,1.74,17.32]],"ltp":2.1,"tv":100.04,"id":40096579},{"batb":[[0,1.85,10],[1,1.83,257],[2,1.81,200]],"ltp":1.91,"tv":36.44,"id":40096580}]}]}
{"op":"mcm","clk":"11838595690","pt":1723191521248,"mc":[{"id":"1.231583502","rc":[{"batb":[[0,2.1,10],[1,2.08,35.1],[2,1.8,2]],"ltp":2.1,"tv":100.04,"id":40096579},{"batb":[[0,1.86,10],[1,1.85,10],[2,1.83,257]],"ltp":1.91,"tv":36.44,"id":40096580}]}]}
{"op":"mcm","clk":"11838595856","pt":1723191524944,"mc":[{"id":"1.231583502","rc":[{"batb":[[0,2.08,35.1],[1,1.8,2],[2,1.74,17.32]],"ltp":2.1,"tv":100.04,"id":40096579},{"batb":[[0,1.85,10],[1,1.83,257],[2,1.81,200]],"ltp":1.91,"tv":36.44,"id":40096580}]}]}
{"op":"mcm","clk":"11838596047","pt":1723191529661,"mc":[{"id":"1.231583502","rc":[{"batb":[[0,2.1,10],[1,2.08,35.1],[2,1.8,2]],"ltp":2.1,"tv":100.04,"id":40096579},{"batb":[[0,1.86,10],[1,1.85,10],[2,1.83,257]],"ltp":1.91,"tv":36.44,"id":40096580}]}]}
{"op":"mcm","clk":"11838596195","pt":1723191533149,"mc":[{"id":"1.231583502","rc":[{"batb":[[0,2.08,35.1],[1,1.8,2],[2,1.74,17.32]],"ltp":2.1,"tv":100.04,"id":40096579},{"batb":[[0,1.85,10],[1,1.83,257],[2,1.81,200]],"ltp":1.91,"tv":36.44,"id":40096580}]}]}
{"op":"mcm","clk":"11838596485","pt":1723191538850,"mc":[{"id":"1.231583502","rc":[{"batb":[[0,2.1,10],[1,2.08,35.1],[2,1.8,2]],"ltp":2.1,"tv":100.04,"id":40096579},{"batb":[[0,1.86,10],[1,1.85,10],[2,1.83,257]],"ltp":1.91,"tv":36.44,"id":40096580}]}]}
{"op":"mcm","clk":"11838596645","pt":1723191542558,"mc":[{"id":"1.231583502","rc":[{"batb":[[0,2.08,35.1],[1,1.8,2],[2,1.74,17.32]],"ltp":2.1,"tv":100.04,"id":40096579},{"batb":[[0,1.85,10],[1,1.83,257],[2,1.81,200]],"ltp":1.91,"tv":36.44,"id":40096580}]}]}
{"op":"mcm","clk":"11838596912","pt":1723191547801,"mc":[{"id":"1.231583502","rc":[{"batb":[[0,2.1,10],[1,2.08,35.1],[2,1.8,2]],"ltp":2.1,"tv":100.04,"id":40096579},{"batb":[[0,1.86,10],[1,1.85,10],[2,1.83,257]],"ltp":1.91,"tv":36.44,"id":40096580}]}]}
{"op":"mcm","clk":"11838597080","pt":1723191551404,"mc":[{"id":"1.231583502","rc":[{"batb":[[0,2.08,35.1],[1,1.8,2],[2,1.74,17.32]],"ltp":2.1,"tv":100.04,"id":40096579},{"batb":[[0,1.85,10],[1,1.83,257],[2,1.81,200]],"ltp":1.91,"tv":36.44,"id":40096580}]}]}
{"op":"mcm","clk":"11838597234","pt":1723191554893,"mc":[{"id":"1.231583502","rc":[{"batb":[[0,2.1,10],[1,2.08,35.1],[2,1.8,2]],"ltp":2.1,"tv":100.04,"id":40096579},{"batb":[[0,1.86,10],[1,1.85,10],[2,1.83,257]],"ltp":1.91,"tv":36.44,"id":40096580}]}]}
{"op":"mcm","clk":"11838597392","pt":1723191558597,"mc":[{"id":"1.231583502","rc":[{"batb":[[0,2.08,35.1],[1,1.8,2],[2,1.74,17.32]],"ltp":2.1,"tv":100.04,"id":40096579},{"batb":[[0,1.85,10],[1,1.83,257],[2,1.81,200]],"ltp":1.91,"tv":36.44,"id":40096580}]}]}
{"op":"mcm","clk":"11838597496","pt":1723191561307,"mc":[{"id":"1.231583502","rc":[{"batb":[[0,2.1,10],[1,2.08,35.1],[2,1.8,2]],"ltp":2.1,"tv":100.04,"id":40096579},{"batb":[[0,1.86,10],[1,1.85,10],[2,1.83,257]],"ltp":1.91,"tv":36.44,"id":40096580}]}]}
{"op":"mcm","clk":"11838597657","pt":1723191564589,"mc":[{"id":"1.231583502","rc":[{"batb":[[0,2.08,35.1],[1,1.8,2],[2,1.74,17.32]],"ltp":2.1,"tv":100.04,"id":40096579},{"batb":[[0,1.85,10],[1,1.83,257],[2,1.81,200]],"ltp":1.91,"tv":36.44,"id":40096580}]}]}
{"op":"mcm","clk":"11838597777","pt":1723191567207,"mc":[{"id":"1.231583502","rc":[{"batb":[[0,2.1,10],[1,2.08,35.1],[2,1.8,2]],"ltp":2.1,"tv":100.04,"id":40096579},{"batb":[[0,1.86,10],[1,1.85,10],[2,1.83,257]],"ltp":1.91,"tv":36.44,"id":40096580}]}]}
{"op":"mcm","clk":"11838597897","pt":1723191570791,"mc":[{"id":"1.231583502","rc":[{"batb":[[0,2.08,35.1],[1,1.8,2],[2,1.74,17.32]],"ltp":2.1,"tv":100.04,"id":40096579},{"batb":[[0,1.85,10],[1,1.83,257],[2,1.81,200]],"ltp":1.91,"tv":36.44,"id":40096580}]}]}
{"op":"mcm","clk":"11838597972","pt":1723191572993,"mc":[{"id":"1.231583502","rc":[{"batb":[[0,2.1,10],[1,2.08,35.1],[2,1.8,2]],"ltp":2.1,"tv":100.04,"id":40096579},{"batb":[[0,1.86,10],[1,1.85,10],[2,1.83,257]],"ltp":1.91,"tv":36.44,"id":40096580}]}]}
{"op":"mcm","clk":"11838598087","pt":1723191576531,"mc":[{"id":"1.231583502","rc":[{"batb":[[0,2.08,35.1],[1,1.8,2],[2,1.74,17.32]],"ltp":2.1,"tv":100.04,"id":40096579},{"batb":[[0,1.85,10],[1,1.83,257],[2,1.81,200]],"ltp":1.91,"tv":36.44,"id":40096580}]}]}
{"op":"mcm","clk":"11838598235","pt":1723191579318,"mc":[{"id":"1.231583502","rc":[{"batb":[[0,2.1,10],[1,2.08,35.1],[2,1.8,2]],"ltp":2.1,"tv":100.04,"id":40096579},{"batb":[[0,1.86,10],[1,1.85,10],[2,1.83,257]],"ltp":1.91,"tv":36.44,"id":40096580}]}]}
{"op":"mcm","clk":"11838598416","pt":1723191582605,"mc":[{"id":"1.231583502","rc":[{"batb":[[0,2.08,35.1],[1,1.8,2],[2,1.74,17.32]],"ltp":2.1,"tv":100.04,"id":40096579},{"batb":[[0,1.85,10],[1,1.83,257],[2,1.81,200]],"ltp":1.91,"tv":36.44,"id":40096580}]}]}
{"op":"mcm","clk":"11838598619","pt":1723191586839,"mc":[{"id":"1.231583502","rc":[{"trd":[[2.1,36.94]],"batb":[[0,2.08,36]],"ltp":2.1,"tv":109.14,"id":40096579},{"trd":[[1.91,40.6]],"batb":[[0,1.86,10],[1,1.85,10],[2,1.83,257]],"ltp":1.91,"tv":46.44,"id":40096580}],"tv":155.58}]}
{"op":"mcm","clk":"11838598738","pt":1723191590241,"mc":[{"id":"1.231583502","rc":[{"batb":[[0,2.08,35.1]],"ltp":2.1,"tv":109.14,"id":40096579},{"batb":[[0,1.85,10],[1,1.83,257],[2,1.81,200]],"ltp":1.91,"tv":46.44,"id":40096580}]}]}
{"op":"mcm","clk":"11838598843","pt":1723191593016,"mc":[{"id":"1.231583502","rc":[{"batb":[[0,2.1,10],[1,2.08,35.1],[2,1.8,2]],"ltp":2.1,"tv":109.14,"id":40096579},{"batb":[[0,1.86,10],[1,1.85,10],[2,1.83,257]],"ltp":1.91,"tv":46.44,"id":40096580}]}]}
{"op":"mcm","clk":"11838598995","pt":1723191596865,"mc":[{"id":"1.231583502","rc":[{"batb":[[0,2.08,35.1],[1,1.8,2],[2,1.74,17.32]],"ltp":2.1,"tv":109.14,"id":40096579},{"batb":[[0,1.85,10],[1,1.83,257],[2,1.81,200]],"ltp":1.91,"tv":46.44,"id":40096580}]}]}
{"op":"mcm","clk":"11838599090","pt":1723191599322,"mc":[{"id":"1.231583502","rc":[{"batb":[[0,2.1,10],[1,2.08,35.1],[2,1.8,2]],"ltp":2.1,"tv":109.14,"id":40096579},{"batb":[[0,1.86,10],[1,1.85,10],[2,1.83,257]],"ltp":1.91,"tv":46.44,"id":40096580}]}]}
{"op":"mcm","clk":"11838599291","pt":1723191603136,"mc":[{"id":"1.231583502","rc":[{"batb":[[0,2.08,35.1],[1,1.8,2],[2,1.74,17.32]],"ltp":2.1,"tv":109.14,"id":40096579},{"batb":[[0,1.87,10]],"ltp":1.91,"tv":46.44,"id":40096580}]}]}
{"op":"mcm","clk":"11838599516","pt":1723191607257,"mc":[{"id":"1.231583502","rc":[{"batb":[[0,2.1,10],[1,2.08,35.1],[2,1.8,2]],"ltp":2.1,"tv":109.14,"id":40096579},{"batb":[[0,1.88,10],[1,1.87,10],[2,1.85,10]],"ltp":1.91,"tv":46.44,"id":40096580}]}]}
{"op":"mcm","clk":"11838599694","pt":1723191611073,"mc":[{"id":"1.231583502","rc":[{"batb":[[0,2.08,35.1],[1,1.8,2],[2,1.74,17.32]],"ltp":2.1,"tv":109.14,"id":40096579},{"batb":[[0,1.87,10],[1,1.85,10],[2,1.83,257]],"ltp":1.91,"tv":46.44,"id":40096580}]}]}
{"op":"mcm","clk":"11838599811","pt":1723191613346,"mc":[{"id":"1.231583502","rc":[{"batb":[[0,2.1,10],[1,2.08,35.1],[2,1.8,2]],"ltp":2.1,"tv":109.14,"id":40096579},{"batb":[[0,1.88,10],[1,1.87,10],[2,1.85,10]],"ltp":1.91,"tv":46.44,"id":40096580}]}]}
{"op":"mcm","clk":"11838599972","pt":1723191616987,"mc":[{"id":"1.231583502","rc":[{"batb":[[0,1.8,2],[1,1.74,17.32],[2,1.6,2]],"ltp":2.1,"tv":109.14,"id":40096579},{"batb":[[0,1.87,10],[1,1.85,10],[2,1.83,257]],"ltp":1.91,"tv":46.44,"id":40096580}]}]}
{"op":"mcm","clk":"11838599978","pt":1723191617143,"mc":[{"id":"1.231583502","rc":[{"batb":[[0,1.83,91.11],[1,1.8,2],[2,1.74,17.32]],"ltp":2.1,"tv":109.14,"id":40096579}]}]}
{"op":"mcm","clk":"11838600111","pt":1723191619968,"mc":[{"id":"1.231583502","rc":[{"batb":[[0,1.84,10],[1,1.83,91.11],[2,1.8,2]],"ltp":2.1,"tv":109.14,"id":40096579},{"batb":[[0,1.88,10],[1,1.87,10],[2,1.85,10]],"ltp":1.91,"tv":46.44,"id":40096580}]}]}
{"op":"mcm","clk":"11838600193","pt":1723191621558,"mc":[{"id":"1.231583502","rc":[{"batb":[[0,2.08,35.1],[1,1.84,10],[2,1.83,91.11]],"ltp":2.1,"tv":109.14,"id":40096579}]}]}
{"op":"mcm","clk":"11838600284","pt":1723191623459,"mc":[{"id":"1.231583502","rc":[{"batb":[[1,1.83,91.11],[2,1.8,2]],"ltp":2.1,"tv":109.14,"id":40096579},{"batb":[[0,1.87,10],[1,1.85,10],[2,1.83,257]],"ltp":1.91,"tv":46.44,"id":40096580}]}]}
{"op":"mcm","clk":"11838600542","pt":1723191628664,"mc":[{"id":"1.231583502","rc":[{"batb":[[0,2.1,10],[1,2.08,35.1],[2,1.83,91.11]],"ltp":2.1,"tv":109.14,"id":40096579},{"batb":[[0,1.88,10],[1,1.87,10],[2,1.85,10]],"ltp":1.91,"tv":46.44,"id":40096580}]}]}
{"op":"mcm","clk":"11838600666","pt":1723191631755,"mc":[{"id":"1.231583502","rc":[{"batb":[[1,1.83,91.11],[2,1.8,2]],"ltp":2.1,"tv":109.14,"id":40096579}]}]}
{"op":"mcm","clk":"11838600700","pt":1723191632576,"mc":[{"id":"1.231583502","rc":[{"batb":[[0,1.82,91.62],[1,1.8,2],[2,1.74,17.32]],"ltp":2.1,"tv":109.14,"id":40096579},{"batb":[[0,1.87,10],[1,1.85,10],[2,1.83,257]],"ltp":1.91,"tv":46.44,"id":40096580}]}]}
{"op":"mcm","clk":"11838600851","pt":1723191635676,"mc":[{"id":"1.231583502","rc":[{"batb":[[0,1.91,10],[1,1.87,10],[2,1.85,10]],"ltp":1.91,"tv":46.44,"id":40096580}]}]}
{"op":"mcm","clk":"11838600905","pt":1723191636706,"mc":[{"id":"1.231583502","rc":[{"batb":[[0,2.08,35.1],[1,1.83,10],[2,1.82,91.62]],"ltp":2.1,"tv":109.14,"id":40096579},{"batb":[[0,1.92,10],[1,1.91,10],[2,1.87,10]],"ltp":1.91,"tv":46.44,"id":40096580}]}]}
{"op":"mcm","clk":"11838601051","pt":1723191640001,"mc":[{"id":"1.231583502","rc":[{"batb":[[1,1.82,91.62],[2,1.8,2]],"ltp":2.1,"tv":109.14,"id":40096579},{"batb":[[0,1.91,10],[1,1.87,10],[2,1.85,10]],"ltp":1.91,"tv":46.44,"id":40096580}]}]}
{"op":"mcm","clk":"11838601182","pt":1723191643193,"mc":[{"id":"1.231583502","rc":[{"trd":[[2.1,46.94]],"ltp":2.1,"tv":119.14,"id":40096579},{"trd":[[1.91,51.59]],"batb":[[0,1.92,9.01]],"ltp":1.91,"tv":57.43,"id":40096580}],"tv":176.57}]}
{"op":"mcm","clk":"11838601296","pt":1723191645613,"mc":[{"id":"1.231583502","rc":[{"trd":[[2.1,55.18]],"batb":[[0,2.1,1.76],[1,2.08,35.1],[2,1.82,91.62]],"ltp":2.1,"tv":127.38,"id":40096579},{"trd":[[1.92,9.01]],"batb":[[0,1.87,10],[1,1.85,10],[2,1.83,257]],"ltp":1.92,"tv":66.44,"id":40096580}],"tv":193.82}]}
{"op":"mcm","clk":"11838601477","pt":1723191649729,"mc":[{"id":"1.231583502","rc":[{"batb":[[0,2.08,35.1],[1,1.8,2],[2,1.74,17.32]],"ltp":2.1,"tv":127.38,"id":40096579},{"batb":[[0,1.88,10],[1,1.87,10],[2,1.85,10]],"ltp":1.92,"tv":66.44,"id":40096580}]}]}
{"op":"mcm","clk":"11838601513","pt":1723191650509,"mc":[{"id":"1.231583502","rc":[{"batb":[[0,1.91,1],[1,1.88,10],[2,1.87,10]],"ltp":1.92,"tv":66.44,"id":40096580}]}]}
{"op":"mcm","clk":"11838601646","pt":1723191653337,"mc":[{"id":"1.231583502","rc":[{"trd":[[2.1,56.09]],"batb":[[0,2.1,9.09],[1,2.08,35.1],[2,1.8,2]],"ltp":2.1,"tv":128.29,"id":40096579},{"trd":[[1.91,52.59]],"batb":[[0,1.87,10],[1,1.85,10],[2,1.83,257]],"ltp":1.91,"tv":67.44,"id":40096580}],"tv":195.73}]}
{"op":"mcm","clk":"11838601816","pt":1723191656835,"mc":[{"id":"1.231583502","rc":[{"batb":[[0,2.08,35.1],[1,1.8,2],[2,1.74,17.32]],"ltp":2.1,"tv":128.29,"id":40096579},{"batb":[[0,1.88,10],[1,1.87,10],[2,1.85,10]],"ltp":1.91,"tv":67.44,"id":40096580}]}]}
{"op":"mcm","clk":"11838601927","pt":1723191659104,"mc":[{"id":"1.231583502","rc":[{"batb":[[0,2.1,10],[1,2.08,35.1],[2,1.8,2]],"ltp":2.1,"tv":128.29,"id":40096579}]}]}
{"op":"mcm","clk":"11838602008","pt":1723191660819,"mc":[{"id":"1.231583502","rc":[{"batb":[[0,1.87,10],[1,1.85,10],[2,1.83,257]],"ltp":1.91,"tv":67.44,"id":40096580}]}]}
{"op":"mcm","clk":"11838602034","pt":1723191661339,"mc":[{"id":"1.231583502","rc":[{"trd":[[2.1,64.28]],"batb":[[0,2.1,1.81]],"ltp":2.1,"tv":136.48,"id":40096579},{"trd":[[1.91,61.59]],"ltp":1.91,"tv":76.44,"id":40096580}],"tv":212.92}]}
{"op":"mcm","clk":"11838602090","pt":1723191662557,"mc":[{"id":"1.231583502","rc":[{"batb":[[0,2.08,35.1],[1,1.8,2],[2,1.74,17.32]],"ltp":2.1,"tv":136.48,"id":40096579}]}]}
{"op":"mcm","clk":"11838602185","pt":1723191664234,"mc":[{"id":"1.231583502","rc":[{"batb":[[0,1.88,10],[1,1.87,10],[2,1.85,10]],"ltp":1.91,"tv":76.44,"id":40096580}]}]}
{"op":"mcm","clk":"11838602278","pt":1723191665932,"mc":[{"id":"1.231583502","rc":[{"batb":[[0,2.1,10],[1,2.08,35.1],[2,1.8,2]],"ltp":2.1,"tv":136.48,"id":40096579}]}]}
{"op":"mcm","clk":"11838602343","pt":1723191666960,"mc":[{"id":"1.231583502","rc":[{"batb":[[1,1.8,2],[2,1.74,17.32]],"ltp":2.1,"tv":136.48,"id":40096579}]}]}
{"op":"mcm","clk":"11838602378","pt":1723191667640,"mc":[{"id":"1.231583502","rc":[{"batb":[[0,1.87,10],[1,1.85,10],[2,1.83,257]],"ltp":1.91,"tv":76.44,"id":40096580}]}]}
{"op":"mcm","clk":"11838602411","pt":1723191668148,"mc":[{"id":"1.231583502","rc":[{"trd":[[2.1,73.38]],"batb":[[0,1.82,92.52]],"ltp":2.1,"tv":145.58,"id":40096579},{"trd":[[1.91,71.59]],"ltp":1.91,"tv":86.44,"id":40096580}],"tv":232.02}]}
{"op":"mcm","clk":"11838602479","pt":1723191669341,"mc":[{"id":"1.231583502","rc":[{"batb":[[0,1.82,91.62]],"ltp":2.1,"tv":145.58,"id":40096579}]}]}
{"op":"mcm","clk":"11838602606","pt":1723191671969,"mc":[{"id":"1.231583502","rc":[{"batb":[[0,2.08,35.1],[1,1.82,91.62],[2,1.8,2]],"ltp":2.1,"tv":145.58,"id":40096579}]}]}
{"op":"mcm","clk":"11838602617","pt":1723191672174,"mc":[{"id":"1.231583502","rc":[{"batb":[[0,2.1,10],[1,2.08,35.1],[2,1.82,91.62]],"ltp":2.1,"tv":145.58,"id":40096579},{"batb":[[0,1.88,10],[1,1.87,10],[2,1.85,10]],"ltp":1.91,"tv":86.44,"id":40096580}]}]}
{"op":"mcm","clk":"11838602800","pt":1723191675571,"mc":[{"id":"1.231583502","rc":[{"batb":[[0,2.08,35.1],[1,1.82,91.62],[2,1.8,2]],"ltp":2.1,"tv":145.58,"id":40096579},{"batb":[[0,1.87,10],[1,1.85,10],[2,1.83,257]],"ltp":1.91,"tv":86.44,"id":40096580}]}]}
{"op":"mcm","clk":"11838603096","pt":1723191681374,"mc":[{"id":"1.231583502","rc":[{"batb":[[0,2.1,10],[1,2.08,35.1],[2,1.82,91.62]],"ltp":2.1,"tv":145.58,"id":40096579},{"batb":[[0,1.88,10],[1,1.87,10],[2,1.85,10]],"ltp":1.91,"tv":86.44,"id":40096580}]}]}
{"op":"mcm","clk":"11838603148","pt":1723191682254,"mc":[{"id":"1.231583502","rc":[{"batb":[[1,1.8,2],[2,1.74,17.32]],"ltp":2.1,"tv":145.58,"id":40096579}]}]}
{"op":"mcm","clk":"11838603261","pt":1723191684875,"mc":[{"id":"1.231583502","rc":[{"batb":[[0,1.8,2],[1,1.74,17.32],[2,1.6,2]],"ltp":2.1,"tv":145.58,"id":40096579},{"batb":[[0,1.87,10],[1,1.85,10],[2,1.83,257]],"ltp":1.91,"tv":86.44,"id":40096580}]}]}
{"op":"mcm","clk":"11838603276","pt":1723191685083,"mc":[{"id":"1.231583502","rc":[{"batb":[[0,1.82,91.62],[1,1.8,2],[2,1.74,17.32]],"ltp":2.1,"tv":145.58,"id":40096579}]}]}
{"op":"mcm","clk":"11838603374","pt":1723191686991,"mc":[{"id":"1.231583502","rc":[{"batb":[[0,2.08,35.1],[1,1.91,10],[2,1.9,60]],"ltp":2.1,"tv":145.58,"id":40096579},{"batb":[[0,1.88,10],[1,1.87,10],[2,1.85,10]],"ltp":1.91,"tv":86.44,"id":40096580}]}]}
{"op":"mcm","clk":"11838603504","pt":1723191690274,"mc":[{"id":"1.231583502","rc":[{"batb":[[1,1.9,60],[2,1.82,91.62]],"ltp":2.1,"tv":145.58,"id":40096579},{"batb":[[0,1.87,10],[1,1.85,10],[2,1.83,257]],"ltp":1.91,"tv":86.44,"id":40096580}]}]}
{"op":"mcm","clk":"11838603768","pt":1723191696190,"mc":[{"id":"1.231583502","rc":[{"batb":[[0,2.1,10],[1,2.08,35.1],[2,1.9,60]],"ltp":2.1,"tv":145.58,"id":40096579},{"batb":[[0,1.88,10],[1,1.87,10],[2,1.85,10]],"ltp":1.91,"tv":86.44,"id":40096580}]}]}
{"op":"mcm","clk":"11838603822","pt":1723191697282,"mc":[{"id":"1.231583502","rc":[{"batb":[[1,1.9,60],[2,1.8,2]],"ltp":2.1,"tv":145.58,"id":40096579}]}]}
{"op":"mcm","clk":"11838603942","pt":1723191700321,"mc":[{"id":"1.231583502","rc":[{"batb":[[0,1.9,107.91],[1,1.8,2],[2,1.74,17.32]],"ltp":2.1,"tv":145.58,"id":40096579},{"batb":[[0,1.87,10],[1,1.85,10],[2,1.83,257]],"ltp":1.91,"tv":86.44,"id":40096580}]}]}
{"op":"mcm","clk":"11838604028","pt":1723191702128,"mc":[{"id":"1.231583502","rc":[{"batb":[[0,2.08,35.1],[1,1.9,107.91],[2,1.8,2]],"ltp":2.1,"tv":145.58,"id":40096579}]}]}
{"op":"mcm","clk":"11838604124","pt":1723191703725,"mc":[{"id":"1.231583502","rc":[{"batb":[[0,2.1,10],[1,2.08,35.1],[2,1.9,107.91]],"ltp":2.1,"tv":145.58,"id":40096579},{"batb":[[0,1.88,10],[1,1.87,10],[2,1.85,10]],"ltp":1.91,"tv":86.44,"id":40096580}]}]}
{"op":"mcm","clk":"11838604293","pt":1723191707395,"mc":[{"id":"1.231583502","rc":[{"batb":[[0,1.9,107.91],[1,1.8,2],[2,1.74,17.32]],"ltp":2.1,"tv":145.58,"id":40096579},{"batb":[[0,1.87,10],[1,1.85,10],[2,1.83,257]],"ltp":1.91,"tv":86.44,"id":40096580}]}]}
{"op":"mcm","clk":"11838604455","pt":1723191710599,"mc":[{"id":"1.231583502","rc":[{"batb":[[0,1.91,10],[1,1.9,107.91],[2,1.8,2]],"ltp":2.1,"tv":145.58,"id":40096579},{"batb":[[0,1.88,10],[1,1.87,10],[2,1.85,10]],"ltp":1.91,"tv":86.44,"id":40096580}]}]}
{"op":"mcm","clk":"11838604478","pt":1723191711109,"mc":[{"id":"1.231583502","rc":[{"batb":[[0,1.91,10],[1,1.88,10],[2,1.87,10]],"ltp":1.91,"tv":86.44,"id":40096580}]}]}
{"op":"mcm","clk":"11838604543","pt":1723191712095,"mc":[{"id":"1.231583502","rc":[{"batb":[[0,2.08,35.1],[1,1.91,10],[2,1.9,107.91]],"ltp":2.1,"tv":145.58,"id":40096579}]}]}
{"op":"mcm","clk":"11838604664","pt":1723191714312,"mc":[{"id":"1.231583502","rc":[{"batb":[[1,1.9,107.91],[2,1.8,2]],"ltp":2.1,"tv":145.58,"id":40096579},{"batb":[[1,1.87,10],[2,1.85,10]],"ltp":1.91,"tv":86.44,"id":40096580}]}]}
{"op":"mcm","clk":"11838604894","pt":1723191718545,"mc":[{"id":"1.231583502","rc":[{"trd":[[2.1,83.38]],"ltp":2.1,"tv":155.58,"id":40096579},{"trd":[[1.91,82.58]],"batb":[[0,1.92,9.01]],"ltp":1.91,"tv":97.43,"id":40096580}],"tv":253.01}]}
{"op":"mcm","clk":"11838605072","pt":1723191721947,"mc":[{"id":"1.231583502","rc":[{"batb":[[0,1.87,10],[1,1.85,10],[2,1.83,257]],"ltp":1.91,"tv":97.43,"id":40096580}]}]}
{"op":"mcm","clk":"11838605082","pt":1723191722152,"mc":[{"id":"1.231583502","rc":[{"batb":[[0,2.1,10],[1,2.08,35.1],[2,1.9,60]],"ltp":2.1,"tv":155.58,"id":40096579}]}]}
{"op":"mcm","clk":"11838605235","pt":1723191725552,"mc":[{"id":"1.231583502","rc":[{"batb":[[0,2.08,35.1],[1,1.9,60],[2,1.8,2]],"ltp":2.1,"tv":155.58,"id":40096579},{"batb":[[0,1.88,10],[1,1.87,10],[2,1.85,10]],"ltp":1.91,"tv":97.43,"id":40096580}]}]}
{"op":"mcm","clk":"11838605401","pt":1723191728861,"mc":[{"id":"1.231583502","rc":[{"batb":[[0,2.1,10],[1,2.08,35.1],[2,1.9,60]],"ltp":2.1,"tv":155.58,"id":40096579},{"batb":[[0,1.87,10],[1,1.85,10],[2,1.83,257]],"ltp":1.91,"tv":97.43,"id":40096580}]}]}
{"op":"mcm","clk":"11838605526","pt":1723191730926,"mc":[{"id":"1.231583502","rc":[{"batb":[[0,1.88,10],[1,1.87,10],[2,1.85,10]],"ltp":1.91,"tv":97.43,"id":40096580}]}]}
{"op":"mcm","clk":"11838605545","pt":1723191731341,"mc":[{"id":"1.231583502","rc":[{"trd":[[2.1,93.38]],"batb":[[0,2.08,35.1],[1,1.9,60],[2,1.8,2]],"ltp":2.1,"tv":165.58,"id":40096579},{"trd":[[1.91,93.57]],"batb":[[0,1.91,89.01],[1,1.88,10],[2,1.87,10]],"ltp":1.91,"tv":108.42,"id":40096580}],"tv":274.0}]}
{"op":"mcm","clk":"11838605726","pt":1723191734866,"mc":[{"id":"1.231583502","rc":[{"trd":[[2.1,103.38]],"ltp":2.1,"tv":175.58,"id":40096579},{"trd":[[1.91,104.56]],"batb":[[0,1.91,78.02],[1,1.87,10],[2,1.85,10]],"ltp":1.91,"tv":119.41,"id":40096580}],"tv":294.99}]}
{"op":"mcm","clk":"11838605862","pt":1723191737346,"mc":[{"id":"1.231583502","rc":[{"trd":[[2.1,113.38]],"ltp":2.1,"tv":185.58,"id":40096579},{"trd":[[1.91,115.55]],"batb":[[0,1.92,10],[1,1.91,67.03],[2,1.87,10]],"ltp":1.91,"tv":130.4,"id":40096580}],"tv":315.98}]}
{"op":"mcm","clk":"11838606035","pt":1723191740867,"mc":[{"id":"1.231583502","rc":[{"batb":[[0,1.91,67.03],[1,1.87,10],[2,1.85,10]],"ltp":1.91,"tv":130.4,"id":40096580}]}]}
{"op":"mcm","clk":"11838606103","pt":1723191741333,"mc":[{"id":"1.231583502","rc":[{"trd":[[2.1,123.38]],"ltp":2.1,"tv":195.58,"id":40096579},{"trd":[[1.91,126.54]],"batb":[[0,1.91,56.04]],"ltp":1.91,"tv":141.39,"id":40096580}],"tv":336.97}]}
{"op":"mcm","clk":"11838606247","pt":1723191744060,"mc":[{"id":"1.231583502","rc":[{"trd":[[2.1,133.38]],"ltp":2.1,"tv":205.58,"id":40096579},{"trd":[[1.91,137.53]],"batb":[[0,1.92,10],[1,1.91,45.05],[2,1.87,10]],"ltp":1.91,"tv":152.38,"id":40096580}],"tv":357.96}]}
{"op":"mcm","clk":"11838613558","pt":1723191888320,"mc":[{"id":"1.231583502","rc":[{"trd":[[2.08,20.49]],"batb":[[0,2.08,16.54]],"ltp":2.08,"tv":224.14,"id":40096579},{"trd":[[1.93,20]],"ltp":1.93,"tv":172.38,"id":40096580}],"tv":396.52}]}
{"op":"mcm","clk":"11838613841","pt":1723191893003,"mc":[{"id":"1.231583502","rc":[{"batb":[[0,2.08,35.1]],"ltp":2.08,"tv":224.14,"id":40096579}]}]}
{"op":"mcm","clk":"11838614162","pt":1723191898614,"mc":[{"id":"1.231583502","rc":[{"batb":[[0,1.92,17]],"ltp":1.93,"tv":172.38,"id":40096580}]}]}
{"op":"mcm","clk":"11838616138","pt":1723191933608,"mc":[{"id":"1.231583502","rc":[{"trd":[[2.1,143.38]],"ltp":2.1,"tv":234.14,"id":40096579},{"trd":[[1.92,19.95]],"batb":[[0,1.92,6.06]],"ltp":1.92,"tv":183.32,"id":40096580}],"tv":417.46}]}
{"op":"mcm","clk":"11838616352","pt":1723191937615,"mc":[{"id":"1.231583502","rc":[{"trd":[[2.1,153.38]],"ltp":2.1,"tv":244.14,"id":40096579},{"trd":[[1.91,142.43],[1.92,26.01]],"batb":[[0,1.91,40.15],[1,1.87,10],[2,1.85,10]],"ltp":1.91,"tv":194.28,"id":40096580}],"tv":438.42}]}
{"op":"mcm","clk":"11838616533","pt":1723191940611,"mc":[{"id":"1.231583502","rc":[{"trd":[[2.1,163.38]],"ltp":2.1,"tv":254.14,"id":40096579},{"trd":[[1.91,153.42]],"batb":[[0,1.91,29.16]],"ltp":1.91,"tv":205.27,"id":40096580}],"tv":459.41}]}
{"op":"mcm","clk":"11838616838","pt":1723191945921,"mc":[{"id":"1.231583502","rc":[{"trd":[[2.1,173.38]],"ltp":2.1,"tv":264.14,"id":40096579},{"trd":[[1.91,164.41]],"batb":[[0,1.91,18.17]],"ltp":1.91,"tv":216.26,"id":40096580}],"tv":480.4}]}
{"op":"mcm","clk":"11838617008","pt":1723191949105,"mc":[{"id":"1.231583502","rc":[{"trd":[[2.1,183.38]],"ltp":2.1,"tv":274.14,"id":40096579},{"trd":[[1.91,175.4]],"batb":[[0,1.91,7.18]],"ltp":1.91,"tv":227.25,"id":40096580}],"tv":501.39}]}
{"op":"mcm","clk":"11838617100","pt":1723191951525,"mc":[{"id":"1.231583502","rc":[{"trd":[[2.1,189.91]],"batb":[[0,2.1,3.47],[1,2.08,35.1],[2,1.9,60]],"ltp":2.1,"tv":280.67,"id":40096579},{"trd":[[1.91,182.58]],"batb":[[0,1.87,10],[1,1.85,10],[2,1.83,257]],"ltp":1.91,"tv":234.43,"id":40096580}],"tv":515.1}]}
{"op":"mcm","clk":"11838617253","pt":1723191954805,"mc":[{"id":"1.231583502","rc":[{"batb":[[0,2.08,35.1],[1,1.9,60],[2,1.8,2]],"ltp":2.1,"tv":280.67,"id":40096579}]}]}
{"op":"mcm","clk":"11838617384","pt":1723191957216,"mc":[{"id":"1.231583502","rc":[{"batb":[[0,2.1,10],[1,2.08,35.1],[2,1.9,60]],"ltp":2.1,"tv":280.67,"id":40096579}]}]}
{"op":"mcm","clk":"11838617537","pt":1723191960502,"mc":[{"id":"1.231583502","rc":[{"batb":[[0,2.08,35.1],[1,1.9,60],[2,1.8,2]],"ltp":2.1,"tv":280.67,"id":40096579}]}]}
{"op":"mcm","clk":"11838617719","pt":1723191964104,"mc":[{"id":"1.231583502","rc":[{"batb":[[0,2.1,10],[1,2.08,35.1],[2,1.9,60]],"ltp":2.1,"tv":280.67,"id":40096579}]}]}
{"op":"mcm","clk":"11838617863","pt":1723191967434,"mc":[{"id":"1.231583502","rc":[{"batb":[[0,2.08,35.1],[1,1.9,60],[2,1.8,2]],"ltp":2.1,"tv":280.67,"id":40096579}]}]}
{"op":"mcm","clk":"11838618008","pt":1723191969744,"mc":[{"id":"1.231583502","rc":[{"batb":[[0,2.1,10],[1,2.08,35.1],[2,1.9,60]],"ltp":2.1,"tv":280.67,"id":40096579}]}]}
{"op":"mcm","clk":"11838618174","pt":1723191972824,"mc":[{"id":"1.231583502","rc":[{"batb":[[0,2.08,35.1],[1,1.9,60],[2,1.8,2]],"ltp":2.1,"tv":280.67,"id":40096579}]}]}
{"op":"mcm","clk":"11838618368","pt":1723191976017,"mc":[{"id":"1.231583502","rc":[{"batb":[[0,2.1,10],[1,2.08,35.1],[2,1.9,60]],"ltp":2.1,"tv":280.67,"id":40096579}]}]}
{"op":"mcm","clk":"11838618524","pt":1723191979260,"mc":[{"id":"1.231583502","rc":[{"batb":[[0,2.08,35.1],[1,1.9,60],[2,1.8,2]],"ltp":2.1,"tv":280.67,"id":40096579}]}]}
{"op":"mcm","clk":"11838618637","pt":1723191981619,"mc":[{"id":"1.231583502","rc":[{"batb":[[0,2.1,10],[1,2.08,35.1],[2,1.9,60]],"ltp":2.1,"tv":280.67,"id":40096579}]}]}
{"op":"mcm","clk":"11838618823","pt":1723191984958,"mc":[{"id":"1.231583502","rc":[{"batb":[[0,2.08,35.1],[1,1.9,60],[2,1.8,2]],"ltp":2.1,"tv":280.67,"id":40096579}]}]}
{"op":"mcm","clk":"11838618940","pt":1723191987169,"mc":[{"id":"1.231583502","rc":[{"batb":[[0,2.1,10],[1,2.08,35.1],[2,1.9,60]],"ltp":2.1,"tv":280.67,"id":40096579}]}]}
{"op":"mcm","clk":"11838619094","pt":1723191990559,"mc":[{"id":"1.231583502","rc":[{"batb":[[0,2.08,35.1],[1,1.9,60],[2,1.8,2]],"ltp":2.1,"tv":280.67,"id":40096579}]}]}
{"op":"mcm","clk":"11838619289","pt":1723191994268,"mc":[{"id":"1.231583502","rc":[{"batb":[[0,2.1,10],[1,2.08,35.1],[2,1.9,60]],"ltp":2.1,"tv":280.67,"id":40096579}]}]}
{"op":"mcm","clk":"11838619458","pt":1723191997451,"mc":[{"id":"1.231583502","rc":[{"batb":[[0,2.08,35.1],[1,1.9,60],[2,1.8,2]],"ltp":2.1,"tv":280.67,"id":40096579}]}]}
{"op":"mcm","clk":"11838619560","pt":1723191999763,"mc":[{"id":"1.231583502","rc":[{"batb":[[0,2.1,10],[1,2.08,35.1],[2,1.9,60]],"ltp":2.1,"tv":280.67,"id":40096579}]}]}
{"op":"mcm","clk":"11838619729","pt":1723192003197,"mc":[{"id":"1.231583502","rc":[{"batb":[[0,2.08,35.1],[1,1.9,60],[2,1.8,2]],"ltp":2.1,"tv":280.67,"id":40096579}]}]}
{"op":"mcm","clk":"11838619873","pt":1723192005972,"mc":[{"id":"1.231583502","rc":[{"batb":[[0,2.1,10],[1,2.08,35.1],[2,1.9,60]],"ltp":2.1,"tv":280.67,"id":40096579}]}]}
