{"op":"mcm","clk":"11789375584","pt":1723021406381,"mc":[{"id":"1.231540814","marketDefinition":{"bspMarket":false,"turnInPlayEnabled":true,"persistenceEnabled":true,"marketBaseRate":5.0,"eventId":"33474963","eventTypeId":"4","numberOfWinners":1,"bettingType":"ODDS","marketType":"MATCH_ODDS","marketTime":"2024-08-09T10:00:00.000Z","suspendTime":"2024-08-09T10:00:00.000Z","bspReconciled":false,"complete":true,"inPlay":false,"crossMatching":false,"runnersVoidable":false,"numberOfActiveRunners":2,"betDelay":0,"status":"OPEN","runners":[{"status":"ACTIVE","sortPriority":1,"id":31374,"name":"Durham"},{"status":"ACTIVE","sortPriority":2,"id":3961,"name":"Hampshire"}],"regulators":["MR_INT"],"countryCode":"GB","discountAllowed":false,"timezone":"GMT","openDate":"2024-08-09T10:00:00.000Z","version":6060462864,"name":"Match Odds","eventName":"Durham v Hampshire"},"rc":[{"batb":[[0,1.03,200],[1,1.02,200],[2,1.01,220]],"ltp":0.0,"tv":0.0,"id":3961},{"batb":[[0,1.03,200],[1,1.02,200],[2,1.01,220]],"ltp":0.0,"tv":0.0,"id":31374}]}]}
{"op":"mcm","clk":"11789375699","pt":1723021407772,"mc":[{"id":"1.231540814","marketDefinition":{"bspMarket":false,"turnInPlayEnabled":true,"persistenceEnabled":true,"marketBaseRate":5.0,"eventId":"33474963","eventTypeId":"4","numberOfWinners":1,"bettingType":"ODDS","marketType":"MATCH_ODDS","marketTime":"2024-08-09T10:00:00.000Z","suspendTime":"2024-08-09T10:00:00.000Z","bspReconciled":false,"complete":true,"inPlay":false,"crossMatching":false,"runnersVoidable":false,"numberOfActiveRunners":2,"betDelay":0,"status":"OPEN","runners":[{"status":"ACTIVE","sortPriority":1,"id":31374,"name":"Durham"},{"status":"ACTIVE","sortPriority":2,"id":3961,"name":"Hampshire"}],"regulators":["MR_INT"],"countryCode":"GB","discountAllowed":true,"timezone":"GMT","openDate":"2024-08-09T10:00:00.000Z","version":6060462864,"name":"Match Odds","eventName":"Durham v Hampshire"}}]}
{"op":"mcm","clk":"11789435497","pt":1723022269975,"mc":[{"id":"1.231540814","rc":[{"batb":[[0,1.25,100],[1,1.03,200],[2,1.02,200]],"ltp":0.0,"tv":0.0,"id":3961},{"batb":[[0,1.25,100],[1,1.03,200],[2,1.02,200]],"ltp":0.0,"tv":0.0,"id":31374}]}]}
{"op":"mcm","clk":"11789489411","pt":1723023065809,"mc":[{"id":"1.231540814","marketDefinition":{"bspMarket":false,"turnInPlayEnabled":true,"persistenceEnabled":true,"marketBaseRate":5.0,"eventId":"33474963","eventTypeId":"4","numberOfWinners":1,"bettingType":"ODDS","marketType":"MATCH_ODDS","marketTime":"2024-08-09T10:00:00.000Z","suspendTime":"2024-08-09T10:00:00.000Z","bspReconciled":false,"complete":true,"inPlay":false,"crossMatching":true,"runnersVoidable":false,"numberOfActiveRunners":2,"betDelay":0,"status":"OPEN","runners":[{"status":"ACTIVE","sortPriority":1,"id":31374,"name":"Durham"},{"status":"ACTIVE","sortPriority":2,"id":3961,"name":"Hampshire"}],"regulators":["MR_INT"],"countryCode":"GB","discountAllowed":true,"timezone":"GMT","openDate":"2024-08-09T10:00:00.000Z","version":6060462864,"name":"Match Odds","eventName":"Durham v Hampshire"}}]}
{"op":"mcm","clk":"11789748545","pt":1723026537880,"mc":[{"id":"1.231540814","rc":[{"batb":[[2,1.02,207.87]],"ltp":0.0,"tv":0.0,"id":3961},{"batb":[[2,1.02,207.87]],"ltp":0.0,"tv":0.0,"id":31374}]}]}
{"op":"mcm","clk":"11789749890","pt":1723026555839,"mc":[{"id":"1.231540814","rc":[{"batb":[[2,1.02,247.21]],"ltp":0.0,"tv":0.0,"id":3961},{"batb":[[2,1.02,247.21]],"ltp":0.0,"tv":0.0,"id":31374}]}]}
{"op":"mcm","clk":"11789751032","pt":1723026571678,"mc":[{"id":"1.231540814","rc":[{"batb":[[1,1.03,207.87]],"ltp":0.0,"tv":0.0,"id":3961},{"batb":[[1,1.03,207.87]],"ltp":0.0,"tv":0.0,"id":31374}]}]}
{"op":"mcm","clk":"11789752805","pt":1723026595527,"mc":[{"id":"1.231540814","rc":[{"batb":[[1,1.04,7.87],[2,1.03,207.87]],"ltp":0.0,"tv":0.0,"id":3961},{"batb":[[1,1.04,7.87],[2,1.03,207.87]],"ltp":0.0,"tv":0.0,"id":31374}]}]}
{"op":"mcm","clk":"11789754673","pt":1723026618530,"mc":[{"id":"1.231540814","rc":[{"batb":[[1,1.05,7.87],[2,1.04,7.87]],"ltp":0.0,"tv":0.0,"id":3961},{"batb":[[1,1.05,7.87],[2,1.04,7.87]],"ltp":0.0,"tv":0.0,"id":31374}]}]}
{"op":"mcm","clk":"11789756732","pt":1723026644376,"mc":[{"id":"1.231540814","rc":[{"batb":[[1,1.06,7.87],[2,1.05,7.87]],"ltp":0.0,"tv":0.0,"id":3961},{"batb":[[1,1.06,7.87],[2,1.05,7.87]],"ltp":0.0,"tv":0.0,"id":31374}]}]}
{"op":"mcm","clk":"11789758437","pt":1723026667575,"mc":[{"id":"1.231540814","rc":[{"batb":[[1,1.07,7.87],[2,1.06,7.87]],"ltp":0.0,"tv":0.0,"id":3961},{"batb":[[1,1.07,7.87],[2,1.06,7.87]],"ltp":0.0,"tv":0.0,"id":31374}]}]}
{"op":"mcm","clk":"11789759942","pt":1723026688412,"mc":[{"id":"1.231540814","rc":[{"batb":[[1,1.08,7.87],[2,1.07,7.87]],"ltp":0.0,"tv":0.0,"id":3961},{"batb":[[1,1.08,7.87],[2,1.07,7.87]],"ltp":0.0,"tv":0.0,"id":31374}]}]}
{"op":"mcm","clk":"11790072349","pt":1723030974922,"mc":[{"id":"1.231540814","rc":[{"batb":[[1,1.08,7.86],[2,1.07,7.86]],"ltp":0.0,"tv":0.0,"id":3961},{"batb":[[1,1.08,7.86],[2,1.07,7.86]],"ltp":0.0,"tv":0.0,"id":31374}]}]}
{"op":"mcm","clk":"11790403562","pt":1723036374906,"mc":[{"id":"1.231540814","rc":[{"batb":[[1,1.08,7.86],[2,1.07,7.86]],"ltp":0.0,"tv":0.0,"id":3961},{"batb":[[1,1.08,7.86],[2,1.07,7.86]],"ltp":0.0,"tv":0.0,"id":31374}]}]}
{"op":"mcm","clk":"11790605300","pt":1723039807903,"mc":[{"id":"1.231540814","rc":[{"batb":[[0,1.26,33.19],[1,1.25,100],[2,1.08,7.86]],"ltp":0.0,"tv":0.0,"id":3961},{"batb":[[0,1.26,33.19],[1,1.25,100],[2,1.08,7.86]],"ltp":0.0,"tv":0.0,"id":31374}]}]}
{"op":"mcm","clk":"11790728215","pt":1723041608541,"mc":[{"id":"1.231540814","rc":[{"batb":[[0,1.25,100],[1,1.08,7.86],[2,1.07,7.86]],"ltp":0.0,"tv":0.0,"id":3961},{"batb":[[0,1.25,100],[1,1.08,7.86],[2,1.07,7.86]],"ltp":0.0,"tv":0.0,"id":31374}]}]}
{"op":"mcm","clk":"11790733383","pt":1723041665022,"mc":[{"id":"1.231540814","rc":[{"batb":[[0,1.26,33.19],[1,1.25,100],[2,1.08,7.86]],"ltp":0.0,"tv":0.0,"id":3961},{"batb":[[0,1.26,33.19],[1,1.25,100],[2,1.08,7.86]],"ltp":0.0,"tv":0.0,"id":31374}]}]}
{"op":"mcm","clk":"11790755991","pt":1723041823275,"mc":[{"id":"1.231540814","rc":[{"batb":[[0,1.27,7.27],[1,1.26,33.19],[2,1.25,100]],"ltp":0.0,"tv":0.0,"id":3961},{"batb":[[0,1.27,7.2],[1,1.26,33.19],[2,1.25,100]],"ltp":0.0,"tv":0.0,"id":31374}]}]}
{"op":"mcm","clk":"11790911713","pt":1723043470078,"mc":[{"id":"1.231540814","rc":[{"batb":[[0,1.27,7.27],[1,1.25,100],[2,1.08,7.86]],"ltp":0.0,"tv":0.0,"id":3961},{"batb":[[0,1.27,7.2],[1,1.25,100],[2,1.08,7.86]],"ltp":0.0,"tv":0.0,"id":31374}]}]}
{"op":"mcm","clk":"11790915862","pt":1723043513642,"mc":[{"id":"1.231540814","rc":[{"batb":[[0,1.28,30.84],[1,1.27,7.27],[2,1.25,100]],"ltp":0.0,"tv":0.0,"id":3961},{"batb":[[0,1.28,30.84],[1,1.27,7.2],[2,1.25,100]],"ltp":0.0,"tv":0.0,"id":31374}]}]}
{"op":"mcm","clk":"11791052693","pt":1723044945411,"mc":[{"id":"1.231540814","rc":[{"batb":[[0,1.29,7.2],[1,1.28,30.84]],"ltp":0.0,"tv":0.0,"id":31374}]}]}
{"op":"mcm","clk":"11791052739","pt":1723044945888,"mc":[{"id":"1.231540814","rc":[{"batb":[[0,1.29,7.27],[1,1.28,30.84]],"ltp":0.0,"tv":0.0,"id":3961}]}]}
{"op":"mcm","clk":"11791093197","pt":1723045315032,"mc":[{"id":"1.231540814","rc":[{"batb":[[1,1.25,100],[2,1.08,7.86]],"ltp":0.0,"tv":0.0,"id":3961},{"batb":[[1,1.25,100],[2,1.08,7.86]],"ltp":0.0,"tv":0.0,"id":31374}]}]}
{"op":"mcm","clk":"11791098462","pt":1723045360296,"mc":[{"id":"1.231540814","rc":[{"batb":[[0,1.3,28.79],[1,1.29,7.27],[2,1.25,100]],"ltp":0.0,"tv":0.0,"id":3961},{"batb":[[0,1.3,28.79],[1,1.29,7.2],[2,1.25,100]],"ltp":0.0,"tv":0.0,"id":31374}]}]}
{"op":"mcm","clk":"11791117835","pt":1723045548809,"mc":[{"id":"1.231540814","rc":[{"trd":[[1.3,0.14]],"batb":[[0,1.3,28.72]],"ltp":1.3,"tv":0.14,"id":31374}],"tv":0.14}]}
{"op":"mcm","clk":"11791199937","pt":1723046475713,"mc":[{"id":"1.231540814","rc":[{"batb":[[0,1.31,7.27],[1,1.3,28.78]],"ltp":0.0,"tv":0.0,"id":3961},{"batb":[[0,1.31,7.2],[1,1.3,28.71]],"ltp":1.3,"tv":0.14,"id":31374}]}]}
{"op":"mcm","clk":"11791260463","pt":1723047161449,"mc":[{"id":"1.231540814","rc":[{"batb":[[1,1.25,100],[2,1.08,7.86]],"ltp":0.0,"tv":0.0,"id":3961},{"batb":[[1,1.25,100],[2,1.08,7.86]],"ltp":1.3,"tv":0.14,"id":31374}]}]}
{"op":"mcm","clk":"11791273108","pt":1723047201121,"mc":[{"id":"1.231540814","rc":[{"batb":[[0,1.32,26.98],[1,1.31,7.27],[2,1.25,100]],"ltp":0.0,"tv":0.0,"id":3961}]}]}
{"op":"mcm","clk":"11791352397","pt":1723047990607,"mc":[{"id":"1.231540814","rc":[{"batb":[[0,1.26,7.2]],"ltp":1.3,"tv":0.14,"id":31374}]}]}
{"op":"mcm","clk":"11791352430","pt":1723047991071,"mc":[{"id":"1.231540814","rc":[{"batb":[[0,1.33,7.27],[1,1.32,26.98]],"ltp":0.0,"tv":0.0,"id":3961}]}]}
{"op":"mcm","clk":"11791361773","pt":1723048113930,"mc":[{"id":"1.231540814","rc":[{"batb":[[0,1.29,3.16],[1,1.26,7.2],[2,1.25,100]],"ltp":1.3,"tv":0.14,"id":31374}]}]}
{"op":"mcm","clk":"11791362892","pt":1723048127947,"mc":[{"id":"1.231540814","rc":[{"batb":[[0,1.36,3.16],[1,1.33,7.27],[2,1.32,26.98]],"ltp":0.0,"tv":0.0,"id":3961}]}]}
{"op":"mcm","clk":"11791448405","pt":1723049002092,"mc":[{"id":"1.231540814","rc":[{"batb":[[2,1.25,100]],"ltp":0.0,"tv":0.0,"id":3961}]}]}
{"op":"mcm","clk":"11791449672","pt":1723049018370,"mc":[{"id":"1.231540814","rc":[{"batb":[[0,1.37,23.34],[1,1.36,3.16],[2,1.33,7.27]],"ltp":0.0,"tv":0.0,"id":3961}]}]}
{"op":"mcm","clk":"11791495409","pt":1723049512451,"mc":[{"id":"1.231540814","rc":[{"batb":[[1,1.25,100],[2,1.08,7.86]],"ltp":1.3,"tv":0.14,"id":31374}]}]}
{"op":"mcm","clk":"11791495446","pt":1723049512866,"mc":[{"id":"1.231540814","rc":[{"batb":[[2,1.26,7.27]],"ltp":0.0,"tv":0.0,"id":3961}]}]}
{"op":"mcm","clk":"11791651710","pt":1723050818742,"mc":[{"id":"1.231540814","rc":[{"batb":[[0,1.36,3.17],[1,1.26,7.28],[2,1.25,100]],"ltp":0.0,"tv":0.0,"id":3961},{"batb":[[0,1.29,3.17],[2,1.08,7.87]],"ltp":1.3,"tv":0.14,"id":31374}]}]}
{"op":"mcm","clk":"11791669235","pt":1723050952496,"mc":[{"id":"1.231540814","rc":[{"batb":[[0,1.37,23.35],[1,1.36,3.17],[2,1.26,7.28]],"ltp":0.0,"tv":0.0,"id":3961}]}]}
{"op":"mcm","clk":"11791681394","pt":1723051045304,"mc":[{"id":"1.231540814","rc":[{"batb":[[2,1.25,100]],"ltp":0.0,"tv":0.0,"id":3961}]}]}
{"op":"mcm","clk":"11791734666","pt":1723051421186,"mc":[{"id":"1.231540814","rc":[{"batb":[[0,1.72,61.68],[1,1.37,23.35],[2,1.36,3.17]],"ltp":0.0,"tv":0.0,"id":3961},{"batb":[[0,2.28,34.69],[1,1.29,3.17],[2,1.25,100]],"ltp":1.3,"tv":0.14,"id":31374}]}]}
{"op":"mcm","clk":"11791948786","pt":1723052752742,"mc":[{"id":"1.231540814","rc":[{"batb":[[1,1.36,3.17],[2,1.25,100]],"ltp":0.0,"tv":0.0,"id":3961}]}]}
{"op":"mcm","clk":"11792719504","pt":1723057974912,"mc":[{"id":"1.231540814","rc":[{"batb":[[1,1.36,3.17]],"ltp":0.0,"tv":0.0,"id":3961},{"batb":[[1,1.29,3.17]],"ltp":1.3,"tv":0.14,"id":31374}]}]}
{"op":"mcm","clk":"11793142553","pt":1723063908989,"mc":[{"id":"1.231540814","rc":[{"batb":[[1,1.25,100],[2,1.08,7.88]],"ltp":0.0,"tv":0.0,"id":3961}]}]}
{"op":"mcm","clk":"11793142660","pt":1723063912010,"mc":[{"id":"1.231540814","rc":[{"batb":[[1,1.25,100],[2,1.08,7.88]],"ltp":1.3,"tv":0.14,"id":31374}]}]}
{"op":"mcm","clk":"11793346258","pt":1723068774931,"mc":[{"id":"1.231540814","rc":[{"batb":[[2,1.08,7.88]],"ltp":0.0,"tv":0.0,"id":3961},{"batb":[[2,1.08,7.88]],"ltp":1.3,"tv":0.14,"id":31374}]}]}
{"op":"mcm","clk":"11793632622","pt":1723074174910,"mc":[{"id":"1.231540814","rc":[{"batb":[[2,1.08,7.88]],"ltp":0.0,"tv":0.0,"id":3961},{"batb":[[2,1.08,7.88]],"ltp":1.3,"tv":0.14,"id":31374}]}]}
{"op":"mcm","clk":"11793955066","pt":1723079574946,"mc":[{"id":"1.231540814","rc":[{"batb":[[2,1.08,7.89]],"ltp":0.0,"tv":0.0,"id":3961},{"batb":[[2,1.08,7.89]],"ltp":1.3,"tv":0.14,"id":31374}]}]}
{"op":"mcm","clk":"11794201731","pt":1723084974928,"mc":[{"id":"1.231540814","rc":[{"batb":[[2,1.08,7.88]],"ltp":0.0,"tv":0.0,"id":3961},{"batb":[[2,1.08,7.88]],"ltp":1.3,"tv":0.14,"id":31374}]}]}
{"op":"mcm","clk":"11794394305","pt":1723090374932,"mc":[{"id":"1.231540814","rc":[{"batb":[[2,1.08,7.88]],"ltp":0.0,"tv":0.0,"id":3961},{"batb":[[2,1.08,7.88]],"ltp":1.3,"tv":0.14,"id":31374}]}]}
{"op":"mcm","clk":"11794596576","pt":1723095774950,"mc":[{"id":"1.231540814","rc":[{"batb":[[2,1.08,7.88]],"ltp":0.0,"tv":0.0,"id":3961},{"batb":[[2,1.08,7.88]],"ltp":1.3,"tv":0.14,"id":31374}]}]}
{"op":"mcm","clk":"11794763062","pt":1723100072210,"mc":[{"id":"1.231540814","rc":[{"batb":[[2,1.08,7.88]],"batl":[[0,1.77,20.65]],"ltp":0.0,"tv":0.0,"id":3961},{"batb":[[2,1.08,7.88]],"ltp":1.3,"tv":0.14,"id":31374}]}]}
{"op":"mcm","clk":"11794763427","pt":1723100080593,"mc":[{"id":"1.231540814","rc":[{"batl":[[1,1.8,25.81]],"ltp":0.0,"tv":0.0,"id":3961}]}]}
{"op":"mcm","clk":"11794763667","pt":1723100086707,"mc":[{"id":"1.231540814","rc":[{"batl":[[2,1.84,41.29]],"ltp":0.0,"tv":0.0,"id":3961}]}]}
{"op":"mcm","clk":"11794812586","pt":1723101174943,"mc":[{"id":"1.231540814","rc":[{"batb":[[2,1.08,7.87]],"batl":[[0,1.77,20.66],[1,1.8,25.82],[2,1.84,41.32]],"ltp":0.0,"tv":0.0,"id":3961},{"batb":[[2,1.08,7.87]],"ltp":1.3,"tv":0.14,"id":31374}]}]}
{"op":"mcm","clk":"11794953184","pt":1723104422341,"mc":[{"id":"1.231540814","rc":[{"trd":[[1.72,2]],"batb":[[0,1.72,60.68],[2,1.08,7.87]],"batl":[[0,1.77,20.62],[1,1.8,25.77],[2,1.84,41.23]],"ltp":1.72,"tv":2.0,"id":3961},{"batb":[[2,1.08,7.87]],"ltp":1.3,"tv":0.14,"id":31374}],"tv":2.14}]}
{"op":"mcm","clk":"11794953277","pt":1723104424547,"mc":[{"id":"1.231540814","rc":[{"batb":[[0,1.72,61.68]],"ltp":1.72,"tv":2.0,"id":3961}]}]}
{"op":"mcm","clk":"11795310187","pt":1723111974907,"mc":[{"id":"1.231540814","rc":[{"batb":[[2,1.08,7.89]],"batl":[[0,1.77,20.67],[1,1.8,25.84],[2,1.84,41.34]],"ltp":1.72,"tv":2.0,"id":3961},{"batb":[[2,1.08,7.89]],"ltp":1.3,"tv":0.14,"id":31374}]}]}
{"op":"mcm","clk":"11795446044","pt":1723114113651,"mc":[{"id":"1.231540814","rc":[{"trd":[[1.72,2.1]],"batb":[[0,1.72,61.58]],"ltp":1.72,"tv":2.1,"id":3961},{"trd":[[2.4,0.07]],"ltp":2.4,"tv":0.21,"id":31374}],"tv":2.31}]}
{"op":"mcm","clk":"11795446331","pt":1723114118334,"mc":[{"id":"1.231540814","rc":[{"batb":[[0,1.72,61.68]],"ltp":1.72,"tv":2.1,"id":3961}]}]}
{"op":"mcm","clk":"11795615931","pt":1723117374960,"mc":[{"id":"1.231540814","rc":[{"batb":[[2,1.08,7.88]],"batl":[[0,1.77,20.65],[1,1.8,25.81],[2,1.84,41.3]],"ltp":1.72,"tv":2.1,"id":3961},{"batb":[[2,1.08,7.88]],"ltp":2.4,"tv":0.21,"id":31374}]}]}
{"op":"mcm","clk":"11795875074","pt":1723122774946,"mc":[{"id":"1.231540814","rc":[{"batb":[[2,1.08,7.89]],"batl":[[0,1.77,20.67],[1,1.8,25.84],[2,1.84,41.34]],"ltp":1.72,"tv":2.1,"id":3961},{"batb":[[2,1.08,7.89]],"ltp":2.4,"tv":0.21,"id":31374}]}]}
{"op":"mcm","clk":"11795999938","pt":1723125516014,"mc":[{"id":"1.231540814","rc":[{"batl":[[0,1.75,100],[1,1.77,20.67],[2,1.8,25.84]],"ltp":1.72,"tv":2.1,"id":3961}]}]}
{"op":"mcm","clk":"11796000117","pt":1723125519833,"mc":[{"id":"1.231540814","rc":[{"batl":[[1,1.76,200],[2,1.77,20.67]],"ltp":1.72,"tv":2.1,"id":3961}]}]}
{"op":"mcm","clk":"11796000270","pt":1723125523330,"mc":[{"id":"1.231540814","rc":[{"batl":[[2,1.77,320.67]],"ltp":1.72,"tv":2.1,"id":3961}]}]}
{"op":"mcm","clk":"11796041819","pt":1723126244154,"mc":[{"id":"1.231540814","rc":[{"batb":[[2,1.08,7.87]],"batl":[[0,1.74,4.91],[1,1.75,100],[2,1.76,200]],"ltp":1.72,"tv":2.1,"id":3961},{"batb":[[2,1.08,7.87]],"ltp":2.4,"tv":0.21,"id":31374}]}]}
{"op":"mcm","clk":"11796080817","pt":1723126909103,"mc":[{"id":"1.231540814","rc":[{"batb":[[0,1.72,52.65]],"ltp":1.72,"tv":2.1,"id":3961},{"batb":[[0,2.28,29.61]],"ltp":2.4,"tv":0.21,"id":31374}]}]}
{"op":"mcm","clk":"11796357142","pt":1723131200632,"mc":[{"id":"1.231540814","rc":[{"trd":[[1.74,9.58]],"batb":[[2,1.08,7.86]],"batl":[[0,1.75,100],[1,1.76,200],[2,1.77,320.67]],"ltp":1.74,"tv":11.67,"id":3961},{"batb":[[2,1.08,7.86]],"ltp":2.4,"tv":0.21,"id":31374}],"tv":11.88}]}
{"op":"mcm","clk":"11796357193","pt":1723131201349,"mc":[{"id":"1.231540814","rc":[{"trd":[[1.75,199.5]],"batl":[[0,1.76,200.25],[1,1.77,320.67],[2,1.78,400]],"ltp":1.75,"tv":211.17,"id":3961}],"tv":211.38}]}
{"op":"mcm","clk":"11796357395","pt":1723131204041,"mc":[{"id":"1.231540814","rc":[{"batb":[[0,1.73,4.81],[1,1.72,52.65],[2,1.25,100]],"ltp":1.75,"tv":211.17,"id":3961}]}]}
{"op":"mcm","clk":"11796369162","pt":1723131364925,"mc":[{"id":"1.231540814","rc":[{"trd":[[1.75,200],[1.76,171.46]],"batl":[[0,1.76,114.27]],"ltp":1.76,"tv":383.13,"id":3961}],"tv":383.34}]}
{"op":"mcm","clk":"11796419640","pt":1723131986994,"mc":[{"id":"1.231540814","rc":[{"batb":[[0,2.32,4.3],[1,2.28,29.61],[2,1.25,100]],"ltp":2.4,"tv":0.21,"id":31374}]}]}
{"op":"mcm","clk":"11796447987","pt":1723132363863,"mc":[{"id":"1.231540814","rc":[{"batb":[[2,1.08,7.86]],"ltp":1.76,"tv":383.13,"id":3961},{"batb":[[2,1.08,7.86]],"ltp":2.4,"tv":0.21,"id":31374}]}]}
{"op":"mcm","clk":"11796449945","pt":1723132387703,"mc":[{"id":"1.231540814","rc":[{"batb":[[2,1.43,116.28]],"ltp":1.76,"tv":383.13,"id":3961},{"batb":[[2,1.48,104.17]],"ltp":2.4,"tv":0.21,"id":31374}]}]}
{"op":"mcm","clk":"11796449964","pt":1723132387908,"mc":[{"id":"1.231540814","rc":[{"batb":[[2,1.53,94.34]],"ltp":1.76,"tv":383.13,"id":3961},{"batb":[[2,1.53,94.34]],"ltp":2.4,"tv":0.21,"id":31374}]}]}
{"op":"mcm","clk":"11796453689","pt":1723132440036,"mc":[{"id":"1.231540814","rc":[{"batb":[[2,1.48,104.17]],"ltp":1.76,"tv":383.13,"id":3961}]}]}
{"op":"mcm","clk":"11796453971","pt":1723132444328,"mc":[{"id":"1.231540814","rc":[{"batb":[[2,1.48,104.17]],"ltp":2.4,"tv":0.21,"id":31374}]}]}
{"op":"mcm","clk":"11796558903","pt":1723133574995,"mc":[{"id":"1.231540814","rc":[{"trd":[[1.74,9.57]],"batb":[[0,1.73,4.8]],"batl":[[1,1.77,320.65]],"ltp":1.76,"tv":383.12,"id":3961},{"batb":[[0,2.32,4.29]],"ltp":2.4,"tv":0.21,"id":31374}],"tv":383.33}]}
{"op":"mcm","clk":"11796595899","pt":1723133920433,"mc":[{"id":"1.231540814","rc":[{"batb":[[2,1.67,33]],"ltp":1.76,"tv":383.12,"id":3961}]}]}
{"op":"mcm","clk":"11797107874","pt":1723138974995,"mc":[{"id":"1.231540814","rc":[{"trd":[[1.74,9.57]],"batb":[[0,1.73,4.8]],"batl":[[1,1.77,320.65]],"ltp":1.76,"tv":383.12,"id":3961},{"batb":[[0,2.32,4.29]],"ltp":2.4,"tv":0.2,"id":31374}],"tv":383.33}]}
{"op":"mcm","clk":"11797765920","pt":1723143731287,"mc":[{"id":"1.231540814","rc":[{"batb":[[0,1.74,1.02],[1,1.73,4.8],[2,1.72,52.65]],"batl":[[1,1.77,320.68]],"ltp":1.76,"tv":383.12,"id":3961}]}]}
{"op":"mcm","clk":"11797766734","pt":1723143737380,"mc":[{"id":"1.231540814","rc":[{"batb":[[0,1.73,4.8],[1,1.72,52.65],[2,1.67,33]],"ltp":1.76,"tv":383.12,"id":3961}]}]}
{"op":"mcm","clk":"11797821109","pt":1723144140388,"mc":[{"id":"1.231540814","rc":[{"batb":[[2,1.68,4.55]],"ltp":1.76,"tv":383.12,"id":3961}]}]}
{"op":"mcm","clk":"11797833166","pt":1723144218361,"mc":[{"id":"1.231540814","rc":[{"batb":[[2,2.02,4.55]],"ltp":2.4,"tv":0.2,"id":31374}]}]}
{"op":"mcm","clk":"11797835160","pt":1723144230682,"mc":[{"id":"1.231540814","rc":[{"batl":[[0,2.8,4.55]],"ltp":2.4,"tv":0.2,"id":31374}]}]}
{"op":"mcm","clk":"11798348532","pt":1723148525023,"mc":[{"id":"1.231540814","rc":[{"trd":[[1.74,9.57],[1.76,175.46]],"batb":[[0,1.73,4.8],[2,1.68,4.55]],"batl":[[0,1.76,112.27],[1,1.77,320.67]],"ltp":1.76,"tv":387.12,"id":3961},{"batb":[[0,2.32,4.29],[2,2.02,4.55]],"batl":[[0,2.8,4.55]],"ltp":2.4,"tv":0.2,"id":31374}],"tv":387.33}]}
{"op":"mcm","clk":"11798556163","pt":1723152658053,"mc":[{"id":"1.231540814","rc":[{"batb":[[2,1.68,4.55]],"batl":[[1,1.77,320.68]],"ltp":1.76,"tv":387.12,"id":3961},{"batb":[[0,2.34,14],[1,2.32,4.29],[2,2.28,29.61]],"batl":[[0,2.8,4.55]],"ltp":2.4,"tv":0.21,"id":31374}]}]}
{"op":"mcm","clk":"11798556257","pt":1723152660262,"mc":[{"id":"1.231540814","rc":[{"batb":[[1,2.28,29.61],[2,2.02,4.55]],"ltp":2.4,"tv":0.21,"id":31374}]}]}
{"op":"mcm","clk":"11798556310","pt":1723152661286,"mc":[{"id":"1.231540814","rc":[{"batb":[[0,2.34,10]],"ltp":2.4,"tv":0.21,"id":31374}]}]}
{"op":"mcm","clk":"11798556354","pt":1723152662259,"mc":[{"id":"1.231540814","rc":[{"batb":[[0,2.28,29.61],[1,2.02,4.55],[2,1.8,2]],"ltp":2.4,"tv":0.21,"id":31374}]}]}
{"op":"mcm","clk":"11798556435","pt":1723152663897,"mc":[{"id":"1.231540814","rc":[{"batb":[[0,2.3,4],[1,2.28,29.61],[2,2.02,4.55]],"ltp":2.4,"tv":0.21,"id":31374}]}]}
{"op":"mcm","clk":"11798556484","pt":1723152664976,"mc":[{"id":"1.231540814","rc":[{"batb":[[0,2.32,10],[1,2.3,4],[2,2.28,29.61]],"ltp":2.4,"tv":0.21,"id":31374}]}]}
{"op":"mcm","clk":"11798556538","pt":1723152666305,"mc":[{"id":"1.231540814","rc":[{"batb":[[1,2.28,29.61],[2,2.02,4.55]],"ltp":2.4,"tv":0.21,"id":31374}]}]}
{"op":"mcm","clk":"11798556631","pt":1723152668369,"mc":[{"id":"1.231540814","rc":[{"batb":[[0,2.3,4]],"ltp":2.4,"tv":0.21,"id":31374}]}]}
{"op":"mcm","clk":"11798556659","pt":1723152668987,"mc":[{"id":"1.231540814","rc":[{"batb":[[0,2.32,4.41],[1,2.3,4],[2,2.28,29.61]],"ltp":2.4,"tv":0.21,"id":31374}]}]}
{"op":"mcm","clk":"11798556753","pt":1723152670887,"mc":[{"id":"1.231540814","rc":[{"batb":[[0,2.34,10],[1,2.32,4.41]],"ltp":2.4,"tv":0.21,"id":31374}]}]}
{"op":"mcm","clk":"11798556820","pt":1723152672381,"mc":[{"id":"1.231540814","rc":[{"batb":[[1,2.28,29.61],[2,2.02,4.55]],"ltp":2.4,"tv":0.21,"id":31374}]}]}
{"op":"mcm","clk":"11798556923","pt":1723152674583,"mc":[{"id":"1.231540814","rc":[{"batb":[[0,2.3,4]],"ltp":2.4,"tv":0.21,"id":31374}]}]}
{"op":"mcm","clk":"11798557033","pt":1723152677096,"mc":[{"id":"1.231540814","rc":[{"batb":[[0,2.3,10]],"ltp":2.4,"tv":0.21,"id":31374}]}]}
{"op":"mcm","clk":"11798557198","pt":1723152680326,"mc":[{"id":"1.231540814","rc":[{"batb":[[0,2.32,4]],"ltp":2.4,"tv":0.21,"id":31374}]}]}
{"op":"mcm","clk":"11798557296","pt":1723152682133,"mc":[{"id":"1.231540814","rc":[{"batb":[[0,2.28,29.61],[1,2.02,4.55],[2,1.8,2]],"ltp":2.4,"tv":0.21,"id":31374}]}]}
{"op":"mcm","clk":"11798557381","pt":1723152684332,"mc":[{"id":"1.231540814","rc":[{"batb":[[0,2.3,14],[1,2.28,29.61],[2,2.02,4.55]],"ltp":2.4,"tv":0.21,"id":31374}]}]}
{"op":"mcm","clk":"11798557479","pt":1723152686597,"mc":[{"id":"1.231540814","rc":[{"batb":[[0,2.3,10]],"ltp":2.4,"tv":0.21,"id":31374}]}]}
{"op":"mcm","clk":"11798557525","pt":1723152687624,"mc":[{"id":"1.231540814","rc":[{"batb":[[0,2.28,29.61],[1,2.02,4.55],[2,1.8,2]],"ltp":2.4,"tv":0.21,"id":31374}]}]}
{"op":"mcm","clk":"11798557599","pt":1723152689413,"mc":[{"id":"1.231540814","rc":[{"batb":[[0,2.3,4],[1,2.28,29.61],[2,2.02,4.55]],"ltp":2.4,"tv":0.21,"id":31374}]}]}
{"op":"mcm","clk":"11798557648","pt":1723152690594,"mc":[{"id":"1.231540814","rc":[{"batb":[[0,2.32,10],[1,2.3,4],[2,2.28,29.61]],"ltp":2.4,"tv":0.21,"id":31374}]}]}
{"op":"mcm","clk":"11798557703","pt":1723152691724,"mc":[{"id":"1.231540814","rc":[{"batb":[[1,2.28,29.61],[2,2.02,4.55]],"ltp":2.4,"tv":0.21,"id":31374}]}]}
{"op":"mcm","clk":"11798557846","pt":1723152693920,"mc":[{"id":"1.231540814","rc":[{"batb":[[0,2.3,4]],"ltp":2.4,"tv":0.21,"id":31374}]}]}
{"op":"mcm","clk":"11798557963","pt":1723152696324,"mc":[{"id":"1.231540814","rc":[{"batb":[[0,2.3,10]],"ltp":2.4,"tv":0.21,"id":31374}]}]}
{"op":"mcm","clk":"11798558121","pt":1723152699710,"mc":[{"id":"1.231540814","rc":[{"batb":[[0,2.28,29.61],[1,2.02,4.55],[2,1.8,2]],"ltp":2.4,"tv":0.21,"id":31374}]}]}
{"op":"mcm","clk":"11798558124","pt":1723152699814,"mc":[{"id":"1.231540814","rc":[{"batb":[[0,2.3,4],[1,2.28,29.61],[2,2.02,4.55]],"ltp":2.4,"tv":0.21,"id":31374}]}]}
{"op":"mcm","clk":"11798558220","pt":1723152702224,"mc":[{"id":"1.231540814","rc":[{"batb":[[0,2.3,10]],"ltp":2.4,"tv":0.21,"id":31374}]}]}
{"op":"mcm","clk":"11798558341","pt":1723152705618,"mc":[{"id":"1.231540814","rc":[{"batb":[[0,2.32,4]],"ltp":2.4,"tv":0.21,"id":31374}]}]}
{"op":"mcm","clk":"11798558432","pt":1723152708136,"mc":[{"id":"1.231540814","rc":[{"batb":[[0,2.3,10]],"ltp":2.4,"tv":0.21,"id":31374}]}]}
{"op":"mcm","clk":"11798558558","pt":1723152711519,"mc":[{"id":"1.231540814","rc":[{"batb":[[0,2.32,4]],"ltp":2.4,"tv":0.21,"id":31374}]}]}
{"op":"mcm","clk":"11798558639","pt":1723152713729,"mc":[{"id":"1.231540814","rc":[{"batb":[[0,2.3,10]],"ltp":2.4,"tv":0.21,"id":31374}]}]}
{"op":"mcm","clk":"11798558753","pt":1723152717221,"mc":[{"id":"1.231540814","rc":[{"batb":[[0,2.3,4]],"ltp":2.4,"tv":0.21,"id":31374}]}]}
{"op":"mcm","clk":"11798558832","pt":1723152719635,"mc":[{"id":"1.231540814","rc":[{"batb":[[0,2.3,10]],"ltp":2.4,"tv":0.21,"id":31374}]}]}
{"op":"mcm","clk":"11798558948","pt":1723152722923,"mc":[{"id":"1.231540814","rc":[{"batb":[[0,2.32,4]],"ltp":2.4,"tv":0.21,"id":31374}]}]}
{"op":"mcm","clk":"11798559049","pt":1723152725341,"mc":[{"id":"1.231540814","rc":[{"batb":[[0,2.34,10]],"ltp":2.4,"tv":0.21,"id":31374}]}]}
{"op":"mcm","clk":"11798559172","pt":1723152728570,"mc":[{"id":"1.231540814","rc":[{"batb":[[0,2.3,4]],"ltp":2.4,"tv":0.21,"id":31374}]}]}
{"op":"mcm","clk":"11798559282","pt":1723152731138,"mc":[{"id":"1.231540814","rc":[{"batb":[[0,2.3,10]],"ltp":2.4,"tv":0.21,"id":31374}]}]}
{"op":"mcm","clk":"11798559403","pt":1723152734570,"mc":[{"id":"1.231540814","rc":[{"batb":[[0,2.32,4]],"ltp":2.4,"tv":0.21,"id":31374}]}]}
{"op":"mcm","clk":"11798559476","pt":1723152736677,"mc":[{"id":"1.231540814","rc":[{"batb":[[0,2.3,10]],"ltp":2.4,"tv":0.21,"id":31374}]}]}
{"op":"mcm","clk":"11798559569","pt":1723152739083,"mc":[{"id":"1.231540814","rc":[{"batb":[[0,2.32,4],[1,2.3,10],[2,2.28,29.61]],"ltp":2.4,"tv":0.21,"id":31374}]}]}
{"op":"mcm","clk":"11798559606","pt":1723152740058,"mc":[{"id":"1.231540814","rc":[{"batb":[[1,2.28,29.61],[2,2.02,4.55]],"ltp":2.4,"tv":0.21,"id":31374}]}]}
{"op":"mcm","clk":"11798559668","pt":1723152741349,"mc":[{"id":"1.231540814","rc":[{"batb":[[0,2.28,29.61],[1,2.02,4.55],[2,1.8,2]],"ltp":2.4,"tv":0.21,"id":31374}]}]}
{"op":"mcm","clk":"11798559723","pt":1723152742576,"mc":[{"id":"1.231540814","rc":[{"batb":[[0,2.3,10],[1,2.28,29.61],[2,2.02,4.55]],"ltp":2.4,"tv":0.21,"id":31374}]}]}
{"op":"mcm","clk":"11798559756","pt":1723152743652,"mc":[{"id":"1.231540814","rc":[{"batb":[[0,2.32,4],[1,2.3,10],[2,2.28,29.61]],"ltp":2.4,"tv":0.21,"id":31374}]}]}
{"op":"mcm","clk":"11798559838","pt":1723152745962,"mc":[{"id":"1.231540814","rc":[{"batb":[[0,2.28,29.61],[1,2.02,4.55],[2,1.8,2]],"ltp":2.4,"tv":0.21,"id":31374}]}]}
{"op":"mcm","clk":"11798559945","pt":1723152748373,"mc":[{"id":"1.231540814","rc":[{"batb":[[0,2.3,14],[1,2.28,29.61],[2,2.02,4.55]],"ltp":2.4,"tv":0.21,"id":31374}]}]}
{"op":"mcm","clk":"11798560011","pt":1723152750680,"mc":[{"id":"1.231540814","rc":[{"batb":[[0,2.3,10]],"ltp":2.4,"tv":0.21,"id":31374}]}]}
{"op":"mcm","clk":"11798560049","pt":1723152751808,"mc":[{"id":"1.231540814","rc":[{"batb":[[0,2.28,29.61],[1,2.02,4.55],[2,1.8,2]],"ltp":2.4,"tv":0.21,"id":31374}]}]}
{"op":"mcm","clk":"11798560146","pt":1723152754472,"mc":[{"id":"1.231540814","rc":[{"batb":[[0,2.3,14],[1,2.28,29.61],[2,2.02,4.55]],"ltp":2.4,"tv":0.21,"id":31374}]}]}
{"op":"mcm","clk":"11798560252","pt":1723152756800,"mc":[{"id":"1.231540814","rc":[{"batb":[[0,2.3,10]],"ltp":2.4,"tv":0.21,"id":31374}]}]}
{"op":"mcm","clk":"11798560296","pt":1723152757806,"mc":[{"id":"1.231540814","rc":[{"batb":[[0,2.28,29.61],[1,2.02,4.55],[2,1.8,2]],"ltp":2.4,"tv":0.21,"id":31374}]}]}
{"op":"mcm","clk":"11798560338","pt":1723152758995,"mc":[{"id":"1.231540814","rc":[{"batb":[[0,2.3,4],[1,2.28,29.61],[2,2.02,4.55]],"ltp":2.4,"tv":0.21,"id":31374}]}]}
{"op":"mcm","clk":"11798560382","pt":1723152760466,"mc":[{"id":"1.231540814","rc":[{"batb":[[0,2.32,10],[1,2.3,4],[2,2.28,29.61]],"ltp":2.4,"tv":0.21,"id":31374}]}]}
{"op":"mcm","clk":"11798560424","pt":1723152761405,"mc":[{"id":"1.231540814","rc":[{"batb":[[1,2.28,29.61],[2,2.02,4.55]],"ltp":2.4,"tv":0.21,"id":31374}]}]}
{"op":"mcm","clk":"11798560505","pt":1723152763713,"mc":[{"id":"1.231540814","rc":[{"batb":[[0,2.3,4]],"ltp":2.4,"tv":0.21,"id":31374}]}]}
{"op":"mcm","clk":"11798560614","pt":1723152766015,"mc":[{"id":"1.231540814","rc":[{"batb":[[0,2.3,10]],"ltp":2.4,"tv":0.21,"id":31374}]}]}
{"op":"mcm","clk":"11798560797","pt":1723152769387,"mc":[{"id":"1.231540814","rc":[{"batb":[[0,2.32,4]],"ltp":2.4,"tv":0.21,"id":31374}]}]}
{"op":"mcm","clk":"11798560889","pt":1723152771263,"mc":[{"id":"1.231540814","rc":[{"batb":[[0,2.28,29.61],[1,2.02,4.55],[2,1.8,2]],"ltp":2.4,"tv":0.21,"id":31374}]}]}
{"op":"mcm","clk":"11798560939","pt":1723152772480,"mc":[{"id":"1.231540814","rc":[{"batb":[[0,2.3,10],[1,2.28,29.61],[2,2.02,4.55]],"ltp":2.4,"tv":0.21,"id":31374}]}]}
{"op":"mcm","clk":"11798561003","pt":1723152773813,"mc":[{"id":"1.231540814","rc":[{"batb":[[0,2.32,4],[1,2.3,10],[2,2.28,29.61]],"ltp":2.4,"tv":0.21,"id":31374}]}]}
{"op":"mcm","clk":"11798561110","pt":1723152776328,"mc":[{"id":"1.231540814","rc":[{"batb":[[0,2.28,29.61],[1,2.02,4.55],[2,1.8,2]],"ltp":2.4,"tv":0.21,"id":31374}]}]}
{"op":"mcm","clk":"11798561208","pt":1723152778642,"mc":[{"id":"1.231540814","rc":[{"batb":[[0,2.3,14],[1,2.28,29.61],[2,2.02,4.55]],"ltp":2.4,"tv":0.21,"id":31374}]}]}
{"op":"mcm","clk":"11798561304","pt":1723152781057,"mc":[{"id":"1.231540814","rc":[{"batb":[[0,2.3,10]],"ltp":2.4,"tv":0.21,"id":31374}]}]}
{"op":"mcm","clk":"11798561350","pt":1723152782127,"mc":[{"id":"1.231540814","rc":[{"batb":[[0,2.28,29.61],[1,2.02,4.55],[2,1.8,2]],"ltp":2.4,"tv":0.21,"id":31374}]}]}
{"op":"mcm","clk":"11798561395","pt":1723152783306,"mc":[{"id":"1.231540814","rc":[{"batb":[[0,2.3,4],[1,2.28,29.61],[2,2.02,4.55]],"ltp":2.4,"tv":0.21,"id":31374}]}]}
{"op":"mcm","clk":"11798561506","pt":1723152785721,"mc":[{"id":"1.231540814","rc":[{"batb":[[0,2.32,10]],"ltp":2.4,"tv":0.21,"id":31374}]}]}
{"op":"mcm","clk":"11798561676","pt":1723152789108,"mc":[{"id":"1.231540814","rc":[{"batb":[[0,2.3,4]],"ltp":2.4,"tv":0.21,"id":31374}]}]}
{"op":"mcm","clk":"11798561800","pt":1723152791518,"mc":[{"id":"1.231540814","rc":[{"batb":[[0,2.3,10]],"ltp":2.4,"tv":0.21,"id":31374}]}]}
{"op":"mcm","clk":"11798561890","pt":1723152793913,"mc":[{"id":"1.231540814","rc":[{"batb":[[0,2.32,4],[1,2.3,10],[2,2.28,29.61]],"ltp":2.4,"tv":0.21,"id":31374}]}]}
{"op":"mcm","clk":"11798561929","pt":1723152794952,"mc":[{"id":"1.231540814","rc":[{"batb":[[1,2.28,29.61],[2,2.02,4.55]],"ltp":2.4,"tv":0.21,"id":31374}]}]}
{"op":"mcm","clk":"11798562002","pt":1723152796126,"mc":[{"id":"1.231540814","rc":[{"batb":[[0,2.28,29.61],[1,2.02,4.55],[2,1.8,2]],"ltp":2.4,"tv":0.21,"id":31374}]}]}
{"op":"mcm","clk":"11798562112","pt":1723152798442,"mc":[{"id":"1.231540814","rc":[{"batb":[[0,2.3,14],[1,2.28,29.61],[2,2.02,4.55]],"ltp":2.4,"tv":0.21,"id":31374}]}]}
{"op":"mcm","clk":"11798562256","pt":1723152801675,"mc":[{"id":"1.231540814","rc":[{"batb":[[0,2.28,29.61],[1,2.02,4.55],[2,1.8,2]],"ltp":2.4,"tv":0.21,"id":31374}]}]}
{"op":"mcm","clk":"11798562454","pt":1723152805120,"mc":[{"id":"1.231540814","rc":[{"batb":[[0,2.3,14],[1,2.28,29.61],[2,2.02,4.55]],"ltp":2.4,"tv":0.21,"id":31374}]}]}
{"op":"mcm","clk":"11798562575","pt":1723152807530,"mc":[{"id":"1.231540814","rc":[{"batb":[[0,2.3,10]],"ltp":2.4,"tv":0.21,"id":31374}]}]}
{"op":"mcm","clk":"11798562619","pt":1723152808453,"mc":[{"id":"1.231540814","rc":[{"batb":[[0,2.28,29.61],[1,2.02,4.55],[2,1.8,2]],"ltp":2.4,"tv":0.21,"id":31374}]}]}
{"op":"mcm","clk":"11798562730","pt":1723152810867,"mc":[{"id":"1.231540814","rc":[{"batb":[[0,2.3,14],[1,2.28,29.61],[2,2.02,4.55]],"ltp":2.4,"tv":0.21,"id":31374}]}]}
{"op":"mcm","clk":"11798562829","pt":1723152813129,"mc":[{"id":"1.231540814","rc":[{"batb":[[0,2.3,10]],"ltp":2.4,"tv":0.21,"id":31374}]}]}
{"op":"mcm","clk":"11798562882","pt":1723152814257,"mc":[{"id":"1.231540814","rc":[{"batb":[[0,2.28,29.61],[1,2.02,4.55],[2,1.8,2]],"ltp":2.4,"tv":0.21,"id":31374}]}]}
{"op":"mcm","clk":"11798562932","pt":1723152815641,"mc":[{"id":"1.231540814","rc":[{"batb":[[0,2.3,4],[1,2.28,29.61],[2,2.02,4.55]],"ltp":2.4,"tv":0.21,"id":31374}]}]}
{"op":"mcm","clk":"11798562960","pt":1723152816823,"mc":[{"id":"1.231540814","rc":[{"batb":[[0,2.32,10],[1,2.3,4],[2,2.28,29.61]],"ltp":2.4,"tv":0.21,"id":31374}]}]}
{"op":"mcm","clk":"11798562983","pt":1723152817847,"mc":[{"id":"1.231540814","rc":[{"batb":[[1,2.28,29.61],[2,2.02,4.55]],"ltp":2.4,"tv":0.21,"id":31374}]}]}
{"op":"mcm","clk":"11798563056","pt":1723152820269,"mc":[{"id":"1.231540814","rc":[{"batb":[[0,2.3,4]],"ltp":2.4,"tv":0.21,"id":31374}]}]}
{"op":"mcm","clk":"11798563137","pt":1723152822650,"mc":[{"id":"1.231540814","rc":[{"batb":[[0,2.3,10]],"ltp":2.4,"tv":0.21,"id":31374}]}]}
{"op":"mcm","clk":"11798563233","pt":1723152826142,"mc":[{"id":"1.231540814","rc":[{"batb":[[0,2.3,4]],"ltp":2.4,"tv":0.21,"id":31374}]}]}
{"op":"mcm","clk":"11798563323","pt":1723152828454,"mc":[{"id":"1.231540814","rc":[{"batb":[[0,2.3,10]],"ltp":2.4,"tv":0.21,"id":31374}]}]}
{"op":"mcm","clk":"11798563472","pt":1723152831677,"mc":[{"id":"1.231540814","rc":[{"batb":[[0,2.32,4]],"ltp":2.4,"tv":0.21,"id":31374}]}]}
{"op":"mcm","clk":"11798563539","pt":1723152833265,"mc":[{"id":"1.231540814","rc":[{"batb":[[0,2.28,29.61],[1,2.02,4.55],[2,1.8,2]],"ltp":2.4,"tv":0.21,"id":31374}]}]}
{"op":"mcm","clk":"11798563581","pt":1723152834350,"mc":[{"id":"1.231540814","rc":[{"batb":[[0,2.3,10],[1,2.28,29.61],[2,2.02,4.55]],"ltp":2.4,"tv":0.21,"id":31374}]}]}
{"op":"mcm","clk":"11798563617","pt":1723152835585,"mc":[{"id":"1.231540814","rc":[{"batb":[[0,2.32,4],[1,2.3,10],[2,2.28,29.61]],"ltp":2.4,"tv":0.21,"id":31374}]}]}
{"op":"mcm","clk":"11798563711","pt":1723152837996,"mc":[{"id":"1.231540814","rc":[{"batb":[[0,2.28,29.61],[1,2.02,4.55],[2,1.8,2]],"ltp":2.4,"tv":0.21,"id":31374}]}]}
{"op":"mcm","clk":"11798563788","pt":1723152840199,"mc":[{"id":"1.231540814","rc":[{"batb":[[0,2.3,14],[1,2.28,29.61],[2,2.02,4.55]],"ltp":2.4,"tv":0.21,"id":31374}]}]}
{"op":"mcm","clk":"11798563887","pt":1723152842458,"mc":[{"id":"1.231540814","rc":[{"batb":[[0,2.3,10]],"ltp":2.4,"tv":0.21,"id":31374}]}]}
{"op":"mcm","clk":"11798563930","pt":1723152843486,"mc":[{"id":"1.231540814","rc":[{"batb":[[0,2.28,29.61],[1,2.02,4.55],[2,1.8,2]],"ltp":2.4,"tv":0.21,"id":31374}]}]}
{"op":"mcm","clk":"11798563969","pt":1723152844559,"mc":[{"id":"1.231540814","rc":[{"batb":[[0,2.3,4],[1,2.28,29.61],[2,2.02,4.55]],"ltp":2.4,"tv":0.21,"id":31374}]}]}
{"op":"mcm","clk":"11798564037","pt":1723152846662,"mc":[{"id":"1.231540814","rc":[{"batb":[[0,2.32,10],[1,2.3,4],[2,2.28,29.61]],"ltp":2.4,"tv":0.21,"id":31374}]}]}
{"op":"mcm","clk":"11798564040","pt":1723152846766,"mc":[{"id":"1.231540814","rc":[{"batb":[[1,2.28,29.61],[2,2.02,4.55]],"ltp":2.4,"tv":0.21,"id":31374}]}]}
{"op":"mcm","clk":"11798564177","pt":1723152850095,"mc":[{"id":"1.231540814","rc":[{"batb":[[0,2.3,4]],"ltp":2.4,"tv":0.21,"id":31374}]}]}
{"op":"mcm","clk":"11798564239","pt":1723152851381,"mc":[{"id":"1.231540814","rc":[{"batb":[[0,2.32,4.41],[1,2.3,4],[2,2.28,29.61]],"ltp":2.4,"tv":0.21,"id":31374}]}]}
{"op":"mcm","clk":"11798564294","pt":1723152852611,"mc":[{"id":"1.231540814","rc":[{"batb":[[0,2.34,10],[1,2.32,4.41]],"ltp":2.4,"tv":0.21,"id":31374}]}]}
{"op":"mcm","clk":"11798564351","pt":1723152853900,"mc":[{"id":"1.231540814","rc":[{"batb":[[1,2.28,29.61],[2,2.02,4.55]],"ltp":2.4,"tv":0.21,"id":31374}]}]}
{"op":"mcm","clk":"11798564412","pt":1723152855314,"mc":[{"id":"1.231540814","rc":[{"batb":[[0,2.36,4],[1,2.34,10],[2,2.28,29.61]],"ltp":2.4,"tv":0.21,"id":31374}]}]}
{"op":"mcm","clk":"11798564438","pt":1723152855906,"mc":[{"id":"1.231540814","rc":[{"batb":[[1,2.28,29.61],[2,2.02,4.55]],"ltp":2.4,"tv":0.21,"id":31374}]}]}
{"op":"mcm","clk":"11798564498","pt":1723152857813,"mc":[{"id":"1.231540814","rc":[{"batb":[[0,2.28,29.61],[1,2.02,4.55],[2,1.8,2]],"ltp":2.4,"tv":0.21,"id":31374}]}]}
{"op":"mcm","clk":"11798564599","pt":1723152860384,"mc":[{"id":"1.231540814","rc":[{"batb":[[0,2.3,14],[1,2.28,29.61],[2,2.02,4.55]],"ltp":2.4,"tv":0.21,"id":31374}]}]}
{"op":"mcm","clk":"11798564687","pt":1723152862697,"mc":[{"id":"1.231540814","rc":[{"batb":[[0,2.3,10]],"ltp":2.4,"tv":0.21,"id":31374}]}]}
{"op":"mcm","clk":"11798564724","pt":1723152863720,"mc":[{"id":"1.231540814","rc":[{"batb":[[0,2.28,29.61],[1,2.02,4.55],[2,1.8,2]],"ltp":2.4,"tv":0.21,"id":31374}]}]}
{"op":"mcm","clk":"11798564765","pt":1723152864799,"mc":[{"id":"1.231540814","rc":[{"batb":[[0,2.3,4],[1,2.28,29.61],[2,2.02,4.55]],"ltp":2.4,"tv":0.21,"id":31374}]}]}
{"op":"mcm","clk":"11798564826","pt":1723152866598,"mc":[{"id":"1.231540814","rc":[{"batb":[[0,2.32,10],[1,2.3,4],[2,2.28,29.61]],"ltp":2.4,"tv":0.21,"id":31374}]}]}
{"op":"mcm","clk":"11798564850","pt":1723152867114,"mc":[{"id":"1.231540814","rc":[{"batb":[[1,2.28,29.61],[2,2.02,4.55]],"ltp":2.4,"tv":0.21,"id":31374}]}]}
{"op":"mcm","clk":"11798564959","pt":1723152869534,"mc":[{"id":"1.231540814","rc":[{"batb":[[0,2.34,4],[1,2.32,10],[2,2.28,29.61]],"ltp":2.4,"tv":0.21,"id":31374}]}]}
{"op":"mcm","clk":"11798564975","pt":1723152869891,"mc":[{"id":"1.231540814","rc":[{"batb":[[1,2.28,29.61],[2,2.02,4.55]],"ltp":2.4,"tv":0.21,"id":31374}]}]}
{"op":"mcm","clk":"11798565057","pt":1723152871792,"mc":[{"id":"1.231540814","rc":[{"batb":[[0,2.28,29.61],[1,2.02,4.55],[2,1.8,2]],"ltp":2.4,"tv":0.21,"id":31374}]}]}
{"op":"mcm","clk":"11798565174","pt":1723152874619,"mc":[{"id":"1.231540814","rc":[{"batb":[[0,2.3,14],[1,2.28,29.61],[2,2.02,4.55]],"ltp":2.4,"tv":0.21,"id":31374}]}]}
{"op":"mcm","clk":"11798565246","pt":1723152876929,"mc":[{"id":"1.231540814","rc":[{"batb":[[0,2.3,10]],"ltp":2.4,"tv":0.21,"id":31374}]}]}
{"op":"mcm","clk":"11798565290","pt":1723152877802,"mc":[{"id":"1.231540814","rc":[{"batb":[[0,2.28,29.61],[1,2.02,4.55],[2,1.8,2]],"ltp":2.4,"tv":0.21,"id":31374}]}]}
{"op":"mcm","clk":"11798565570","pt":1723152884747,"mc":[{"id":"1.231540814","rc":[{"batb":[[0,2.3,14],[1,2.28,29.61],[2,2.02,4.55]],"ltp":2.4,"tv":0.21,"id":31374}]}]}
{"op":"mcm","clk":"11798565658","pt":1723152887108,"mc":[{"id":"1.231540814","rc":[{"batb":[[0,2.3,10]],"ltp":2.4,"tv":0.21,"id":31374}]}]}
{"op":"mcm","clk":"11798565696","pt":1723152888140,"mc":[{"id":"1.231540814","rc":[{"batb":[[0,2.28,29.61],[1,2.02,4.55],[2,1.8,2]],"ltp":2.4,"tv":0.21,"id":31374}]}]}
{"op":"mcm","clk":"11798565782","pt":1723152890448,"mc":[{"id":"1.231540814","rc":[{"batb":[[0,2.3,14],[1,2.28,29.61],[2,2.02,4.55]],"ltp":2.4,"tv":0.21,"id":31374}]}]}
{"op":"mcm","clk":"11798565920","pt":1723152893737,"mc":[{"id":"1.231540814","rc":[{"batb":[[0,2.28,29.61],[1,2.02,4.55],[2,1.8,2]],"ltp":2.4,"tv":0.21,"id":31374}]}]}
{"op":"mcm","clk":"11798566021","pt":1723152896232,"mc":[{"id":"1.231540814","rc":[{"batb":[[0,2.3,14],[1,2.28,29.61],[2,2.02,4.55]],"ltp":2.4,"tv":0.21,"id":31374}]}]}
{"op":"mcm","clk":"11798566151","pt":1723152899718,"mc":[{"id":"1.231540814","rc":[{"batb":[[0,2.28,29.61],[1,2.02,4.55],[2,1.8,2]],"ltp":2.4,"tv":0.21,"id":31374}]}]}
{"op":"mcm","clk":"11798566218","pt":1723152901259,"mc":[{"id":"1.231540814","rc":[{"batb":[[0,2.3,4],[1,2.28,29.61],[2,2.02,4.55]],"ltp":2.4,"tv":0.21,"id":31374}]}]}
{"op":"mcm","clk":"11798566312","pt":1723152903722,"mc":[{"id":"1.231540814","rc":[{"batb":[[0,2.3,10]],"ltp":2.4,"tv":0.21,"id":31374}]}]}
{"op":"mcm","clk":"11798566446","pt":1723152907260,"mc":[{"id":"1.231540814","rc":[{"batb":[[0,2.3,4]],"ltp":2.4,"tv":0.21,"id":31374}]}]}
{"op":"mcm","clk":"11798566519","pt":1723152909527,"mc":[{"id":"1.231540814","rc":[{"batb":[[0,2.32,10]],"ltp":2.4,"tv":0.21,"id":31374}]}]}
{"op":"mcm","clk":"11798566650","pt":1723152913129,"mc":[{"id":"1.231540814","rc":[{"batb":[[0,2.3,4]],"ltp":2.4,"tv":0.21,"id":31374}]}]}
{"op":"mcm","clk":"11798566728","pt":1723152915442,"mc":[{"id":"1.231540814","rc":[{"batb":[[0,2.32,10]],"ltp":2.4,"tv":0.21,"id":31374}]}]}
{"op":"mcm","clk":"11798566844","pt":1723152918979,"mc":[{"id":"1.231540814","rc":[{"batb":[[0,2.3,4]],"ltp":2.4,"tv":0.21,"id":31374}]}]}
{"op":"mcm","clk":"11798566908","pt":1723152921240,"mc":[{"id":"1.231540814","rc":[{"batb":[[0,2.3,10]],"ltp":2.4,"tv":0.21,"id":31374}]}]}
{"op":"mcm","clk":"11798566982","pt":1723152923650,"mc":[{"id":"1.231540814","rc":[{"batb":[[0,2.32,4],[1,2.3,10],[2,2.28,29.61]],"ltp":2.4,"tv":0.21,"id":31374}]}]}
{"op":"mcm","clk":"11798567008","pt":1723152924472,"mc":[{"id":"1.231540814","rc":[{"batb":[[1,2.28,29.61],[2,2.02,4.55]],"ltp":2.4,"tv":0.21,"id":31374}]}]}
{"op":"mcm","clk":"11798567061","pt":1723152925960,"mc":[{"id":"1.231540814","rc":[{"batb":[[0,2.28,29.61],[1,2.02,4.55],[2,1.8,2]],"ltp":2.4,"tv":0.21,"id":31374}]}]}
{"op":"mcm","clk":"11798567118","pt":1723152927657,"mc":[{"id":"1.231540814","rc":[{"batb":[[0,2.3,10],[1,2.28,29.61],[2,2.02,4.55]],"ltp":2.4,"tv":0.21,"id":31374}]}]}
{"op":"mcm","clk":"11798567194","pt":1723152929656,"mc":[{"id":"1.231540814","rc":[{"batb":[[0,2.32,4],[1,2.3,10],[2,2.28,29.61]],"ltp":2.4,"tv":0.21,"id":31374}]}]}
{"op":"mcm","clk":"11798567249","pt":1723152931148,"mc":[{"id":"1.231540814","rc":[{"batb":[[1,2.28,29.61],[2,2.02,4.55]],"ltp":2.4,"tv":0.21,"id":31374}]}]}
{"op":"mcm","clk":"11798567281","pt":1723152932068,"mc":[{"id":"1.231540814","rc":[{"batb":[[0,2.28,29.61],[1,2.02,4.55],[2,1.8,2]],"ltp":2.4,"tv":0.21,"id":31374}]}]}
{"op":"mcm","clk":"11798567364","pt":1723152934370,"mc":[{"id":"1.231540814","rc":[{"batb":[[0,2.3,14],[1,2.28,29.61],[2,2.02,4.55]],"ltp":2.4,"tv":0.21,"id":31374}]}]}
{"op":"mcm","clk":"11798567457","pt":1723152936677,"mc":[{"id":"1.231540814","rc":[{"batb":[[0,2.3,10]],"ltp":2.4,"tv":0.21,"id":31374}]}]}
{"op":"mcm","clk":"11798567499","pt":1723152937651,"mc":[{"id":"1.231540814","rc":[{"batb":[[0,2.28,29.61],[1,2.02,4.55],[2,1.8,2]],"ltp":2.4,"tv":0.21,"id":31374}]}]}
{"op":"mcm","clk":"11798567593","pt":1723152940165,"mc":[{"id":"1.231540814","rc":[{"batb":[[0,2.3,14],[1,2.28,29.61],[2,2.02,4.55]],"ltp":2.4,"tv":0.21,"id":31374}]}]}
{"op":"mcm","clk":"11798567659","pt":1723152942365,"mc":[{"id":"1.231540814","rc":[{"batb":[[0,2.3,10]],"ltp":2.4,"tv":0.21,"id":31374}]}]}
{"op":"mcm","clk":"11798567701","pt":1723152943545,"mc":[{"id":"1.231540814","rc":[{"batb":[[0,2.28,29.61],[1,2.02,4.55],[2,1.8,2]],"ltp":2.4,"tv":0.21,"id":31374}]}]}
{"op":"mcm","clk":"11798567740","pt":1723152944773,"mc":[{"id":"1.231540814","rc":[{"batb":[[0,2.3,4],[1,2.28,29.61],[2,2.02,4.55]],"ltp":2.4,"tv":0.21,"id":31374}]}]}
{"op":"mcm","clk":"11798567762","pt":1723152945950,"mc":[{"id":"1.231540814","rc":[{"batb":[[0,2.32,10],[1,2.3,4],[2,2.28,29.61]],"ltp":2.4,"tv":0.21,"id":31374}]}]}
{"op":"mcm","clk":"11798567795","pt":1723152947183,"mc":[{"id":"1.231540814","rc":[{"batb":[[1,2.28,29.61],[2,2.02,4.55]],"ltp":2.4,"tv":0.21,"id":31374}]}]}
{"op":"mcm","clk":"11798567867","pt":1723152949498,"mc":[{"id":"1.231540814","rc":[{"batb":[[0,2.3,4]],"ltp":2.4,"tv":0.21,"id":31374}]}]}
{"op":"mcm","clk":"11798567961","pt":1723152951703,"mc":[{"id":"1.231540814","rc":[{"batb":[[0,2.28,29.61],[1,2.02,4.55],[2,1.8,2]],"ltp":2.4,"tv":0.21,"id":31374}]}]}
{"op":"mcm","clk":"11798567967","pt":1723152951806,"mc":[{"id":"1.231540814","rc":[{"batb":[[0,2.3,10],[1,2.28,29.61],[2,2.02,4.55]],"ltp":2.4,"tv":0.21,"id":31374}]}]}
{"op":"mcm","clk":"11798568205","pt":1723152954277,"mc":[{"id":"1.231540814","rc":[{"batb":[[0,2.32,4],[1,2.3,10],[2,2.28,29.61]],"ltp":2.4,"tv":0.21,"id":31374}]}]}
{"op":"mcm","clk":"11798568285","pt":1723152954986,"mc":[{"id":"1.231540814","rc":[{"batb":[[1,2.28,29.61],[2,2.02,4.55]],"ltp":2.4,"tv":0.21,"id":31374}]}]}
{"op":"mcm","clk":"11798568413","pt":1723152956608,"mc":[{"id":"1.231540814","rc":[{"batb":[[0,2.28,29.61],[1,2.02,4.55],[2,1.8,2]],"ltp":2.4,"tv":0.21,"id":31374}]}]}
{"op":"mcm","clk":"11798568542","pt":1723152958975,"mc":[{"id":"1.231540814","rc":[{"batb":[[0,2.3,14],[1,2.28,29.61],[2,2.02,4.55]],"ltp":2.4,"tv":0.21,"id":31374}]}]}
{"op":"mcm","clk":"11798568632","pt":1723152961386,"mc":[{"id":"1.231540814","rc":[{"batb":[[0,2.3,10]],"ltp":2.4,"tv":0.21,"id":31374}]}]}
{"op":"mcm","clk":"11798568662","pt":1723152962409,"mc":[{"id":"1.231540814","rc":[{"batb":[[0,2.28,29.61],[1,2.02,4.55],[2,1.8,2]],"ltp":2.4,"tv":0.21,"id":31374}]}]}
{"op":"mcm","clk":"11798568719","pt":1723152964203,"mc":[{"id":"1.231540814","rc":[{"batb":[[0,2.3,4],[1,2.28,29.61],[2,2.02,4.55]],"ltp":2.4,"tv":0.21,"id":31374}]}]}
{"op":"mcm","clk":"11798568791","pt":1723152966409,"mc":[{"id":"1.231540814","rc":[{"batb":[[0,2.32,10]],"ltp":2.4,"tv":0.21,"id":31374}]}]}
{"op":"mcm","clk":"11798568890","pt":1723152969384,"mc":[{"id":"1.231540814","rc":[{"batb":[[0,2.34,4]],"ltp":2.4,"tv":0.21,"id":31374}]}]}
{"op":"mcm","clk":"11798568969","pt":1723152971185,"mc":[{"id":"1.231540814","rc":[{"batb":[[0,2.28,29.61],[1,2.02,4.55],[2,1.8,2]],"ltp":2.4,"tv":0.21,"id":31374}]}]}
{"op":"mcm","clk":"11798569032","pt":1723152972888,"mc":[{"id":"1.231540814","rc":[{"batb":[[0,2.3,10],[1,2.28,29.61],[2,2.02,4.55]],"ltp":2.4,"tv":0.21,"id":31374}]}]}
{"op":"mcm","clk":"11798569168","pt":1723152976580,"mc":[{"id":"1.231540814","rc":[{"batb":[[0,2.3,4]],"ltp":2.4,"tv":0.21,"id":31374}]}]}
{"op":"mcm","clk":"11798569282","pt":1723152979094,"mc":[{"id":"1.231540814","rc":[{"batb":[[0,2.3,10]],"ltp":2.4,"tv":0.21,"id":31374}]}]}
{"op":"mcm","clk":"11798569388","pt":1723152981717,"mc":[{"id":"1.231540814","rc":[{"batb":[[0,2.32,4],[1,2.3,10],[2,2.28,29.61]],"ltp":2.4,"tv":0.21,"id":31374}]}]}
{"op":"mcm","clk":"11798569420","pt":1723152982492,"mc":[{"id":"1.231540814","rc":[{"batb":[[1,2.28,29.61],[2,2.02,4.55]],"ltp":2.4,"tv":0.21,"id":31374}]}]}
{"op":"mcm","clk":"11798569471","pt":1723152984027,"mc":[{"id":"1.231540814","rc":[{"batb":[[0,2.28,29.61],[1,2.02,4.55],[2,1.8,2]],"ltp":2.4,"tv":0.21,"id":31374}]}]}
{"op":"mcm","clk":"11798569511","pt":1723152985115,"mc":[{"id":"1.231540814","rc":[{"batb":[[0,2.3,10],[1,2.28,29.61],[2,2.02,4.55]],"ltp":2.4,"tv":0.21,"id":31374}]}]}
{"op":"mcm","clk":"11798569558","pt":1723152986332,"mc":[{"id":"1.231540814","rc":[{"batb":[[0,2.32,4],[1,2.3,10],[2,2.28,29.61]],"ltp":2.4,"tv":0.21,"id":31374}]}]}
{"op":"mcm","clk":"11798569647","pt":1723152988535,"mc":[{"id":"1.231540814","rc":[{"batb":[[0,2.28,29.61],[1,2.02,4.55],[2,1.8,2]],"ltp":2.4,"tv":0.21,"id":31374}]}]}
{"op":"mcm","clk":"11798569788","pt":1723152991711,"mc":[{"id":"1.231540814","rc":[{"batb":[[0,2.3,14],[1,2.28,29.61],[2,2.02,4.55]],"ltp":2.4,"tv":0.21,"id":31374}]}]}
{"op":"mcm","clk":"11798569862","pt":1723152994012,"mc":[{"id":"1.231540814","rc":[{"batb":[[0,2.3,10]],"ltp":2.4,"tv":0.21,"id":31374}]}]}
{"op":"mcm","clk":"11798569902","pt":1723152995139,"mc":[{"id":"1.231540814","rc":[{"batb":[[0,2.28,29.61],[1,2.02,4.55],[2,1.8,2]],"ltp":2.4,"tv":0.21,"id":31374}]}]}
{"op":"mcm","clk":"11798569935","pt":1723152996317,"mc":[{"id":"1.231540814","rc":[{"batb":[[0,2.3,4],[1,2.28,29.61],[2,2.02,4.55]],"ltp":2.4,"tv":0.21,"id":31374}]}]}
{"op":"mcm","clk":"11798569976","pt":1723152997440,"mc":[{"id":"1.231540814","rc":[{"batb":[[0,2.32,10],[1,2.3,4],[2,2.28,29.61]],"ltp":2.4,"tv":0.21,"id":31374}]}]}
{"op":"mcm","clk":"11798570007","pt":1723152998617,"mc":[{"id":"1.231540814","rc":[{"batb":[[1,2.28,29.61],[2,2.02,4.55]],"ltp":2.4,"tv":0.21,"id":31374}]}]}
{"op":"mcm","clk":"11798570070","pt":1723153000929,"mc":[{"id":"1.231540814","rc":[{"batb":[[0,2.3,4]],"ltp":2.4,"tv":0.21,"id":31374}]}]}
{"op":"mcm","clk":"11798570153","pt":1723153003441,"mc":[{"id":"1.231540814","rc":[{"batb":[[0,2.3,10]],"ltp":2.4,"tv":0.21,"id":31374}]}]}
{"op":"mcm","clk":"11798570265","pt":1723153006723,"mc":[{"id":"1.231540814","rc":[{"batb":[[0,2.32,4]],"ltp":2.4,"tv":0.21,"id":31374}]}]}
{"op":"mcm","clk":"11798570303","pt":1723153008049,"mc":[{"id":"1.231540814","rc":[{"batb":[[0,2.28,29.61],[1,2.02,4.55],[2,1.8,2]],"ltp":2.4,"tv":0.21,"id":31374}]}]}
{"op":"mcm","clk":"11798570353","pt":1723153009230,"mc":[{"id":"1.231540814","rc":[{"batb":[[0,2.3,10],[1,2.28,29.61],[2,2.02,4.55]],"ltp":2.4,"tv":0.21,"id":31374}]}]}
{"op":"mcm","clk":"11798570484","pt":1723153012719,"mc":[{"id":"1.231540814","rc":[{"batb":[[0,2.32,4]],"ltp":2.4,"tv":0.21,"id":31374}]}]}
{"op":"mcm","clk":"11798570539","pt":1723153014356,"mc":[{"id":"1.231540814","rc":[{"batb":[[0,2.28,29.61],[1,2.02,4.55],[2,1.8,2]],"ltp":2.4,"tv":0.21,"id":31374}]}]}
{"op":"mcm","clk":"11798570665","pt":1723153017443,"mc":[{"id":"1.231540814","rc":[{"batb":[[0,2.3,14],[1,2.28,29.61],[2,2.02,4.55]],"ltp":2.4,"tv":0.21,"id":31374}]}]}
{"op":"mcm","clk":"11798570749","pt":1723153019853,"mc":[{"id":"1.231540814","rc":[{"batb":[[0,2.3,10]],"ltp":2.4,"tv":0.21,"id":31374}]}]}
{"op":"mcm","clk":"11798570779","pt":1723153020828,"mc":[{"id":"1.231540814","rc":[{"batb":[[0,2.28,29.61],[1,2.02,4.55],[2,1.8,2]],"ltp":2.4,"tv":0.21,"id":31374}]}]}
{"op":"mcm","clk":"11798570872","pt":1723153023232,"mc":[{"id":"1.231540814","rc":[{"batb":[[0,2.3,14],[1,2.28,29.61],[2,2.02,4.55]],"ltp":2.4,"tv":0.21,"id":31374}]}]}
{"op":"mcm","clk":"11798570951","pt":1723153025642,"mc":[{"id":"1.231540814","rc":[{"batb":[[0,2.32,4.71],[1,2.3,10],[2,2.28,29.61]],"ltp":2.4,"tv":0.21,"id":31374}]}]}
{"op":"mcm","clk":"11798570973","pt":1723153026564,"mc":[{"id":"1.231540814","rc":[{"batb":[[1,2.28,29.61],[2,2.02,4.55]],"ltp":2.4,"tv":0.21,"id":31374}]}]}
{"op":"mcm","clk":"11798571016","pt":1723153027744,"mc":[{"id":"1.231540814","rc":[{"batb":[[0,2.34,4],[1,2.32,4.71],[2,2.28,29.61]],"ltp":2.4,"tv":0.21,"id":31374}]}]}
{"op":"mcm","clk":"11798571065","pt":1723153029026,"mc":[{"id":"1.231540814","rc":[{"batb":[[0,2.36,10],[1,2.34,4],[2,2.32,4.71]],"ltp":2.4,"tv":0.21,"id":31374}]}]}
{"op":"mcm","clk":"11798571085","pt":1723153029945,"mc":[{"id":"1.231540814","rc":[{"batb":[[1,2.32,4.71],[2,2.28,29.61]],"ltp":2.4,"tv":0.21,"id":31374}]}]}
{"op":"mcm","clk":"11798571144","pt":1723153031537,"mc":[{"id":"1.231540814","rc":[{"batb":[[1,2.28,29.61],[2,2.02,4.55]],"ltp":2.4,"tv":0.21,"id":31374}]}]}
{"op":"mcm","clk":"11798571180","pt":1723153032358,"mc":[{"id":"1.231540814","rc":[{"batb":[[0,2.3,4]],"ltp":2.4,"tv":0.21,"id":31374}]}]}
{"op":"mcm","clk":"11798571247","pt":1723153034666,"mc":[{"id":"1.231540814","rc":[{"batb":[[0,2.28,29.61],[1,2.02,4.55],[2,1.8,2]],"ltp":2.4,"tv":0.21,"id":31374}]}]}
{"op":"mcm","clk":"11798571256","pt":1723153034870,"mc":[{"id":"1.231540814","rc":[{"batb":[[0,2.3,10],[1,2.28,29.61],[2,2.02,4.55]],"ltp":2.4,"tv":0.21,"id":31374}]}]}
{"op":"mcm","clk":"11798571352","pt":1723153038464,"mc":[{"id":"1.231540814","rc":[{"batb":[[0,2.3,4]],"ltp":2.4,"tv":0.21,"id":31374}]}]}
{"op":"mcm","clk":"11798571439","pt":1723153040876,"mc":[{"id":"1.231540814","rc":[{"batb":[[0,2.3,10]],"ltp":2.4,"tv":0.21,"id":31374}]}]}
{"op":"mcm","clk":"11798571509","pt":1723153042979,"mc":[{"id":"1.231540814","rc":[{"batb":[[0,2.32,4],[1,2.3,10],[2,2.28,29.61]],"ltp":2.4,"tv":0.21,"id":31374}]}]}
{"op":"mcm","clk":"11798571556","pt":1723153044262,"mc":[{"id":"1.231540814","rc":[{"batb":[[1,2.28,29.61],[2,2.02,4.55]],"ltp":2.4,"tv":0.21,"id":31374}]}]}
{"op":"mcm","clk":"11798571582","pt":1723153045241,"mc":[{"id":"1.231540814","rc":[{"batb":[[0,2.28,29.61],[1,2.02,4.55],[2,1.8,2]],"ltp":2.4,"tv":0.21,"id":31374}]}]}
{"op":"mcm","clk":"11798571641","pt":1723153047652,"mc":[{"id":"1.231540814","rc":[{"batb":[[0,2.3,14],[1,2.28,29.61],[2,2.02,4.55]],"ltp":2.4,"tv":0.21,"id":31374}]}]}
{"op":"mcm","clk":"11798571722","pt":1723153050166,"mc":[{"id":"1.231540814","rc":[{"batb":[[0,2.3,10]],"ltp":2.4,"tv":0.21,"id":31374}]}]}
{"op":"mcm","clk":"11798571746","pt":1723153050984,"mc":[{"id":"1.231540814","rc":[{"batb":[[0,2.28,29.61],[1,2.02,4.55],[2,1.8,2]],"ltp":2.4,"tv":0.21,"id":31374}]}]}
{"op":"mcm","clk":"11798571827","pt":1723153053249,"mc":[{"id":"1.231540814","rc":[{"batb":[[0,2.3,14],[1,2.28,29.61],[2,2.02,4.55]],"ltp":2.4,"tv":0.21,"id":31374}]}]}
{"op":"mcm","clk":"11798571898","pt":1723153055554,"mc":[{"id":"1.231540814","rc":[{"batb":[[0,2.3,10]],"ltp":2.4,"tv":0.21,"id":31374}]}]}
{"op":"mcm","clk":"11798571925","pt":1723153056577,"mc":[{"id":"1.231540814","rc":[{"batb":[[0,2.28,29.61],[1,2.02,4.55],[2,1.8,2]],"ltp":2.4,"tv":0.21,"id":31374}]}]}
{"op":"mcm","clk":"11798571961","pt":1723153057764,"mc":[{"id":"1.231540814","rc":[{"batb":[[0,2.3,4],[1,2.28,29.61],[2,2.02,4.55]],"ltp":2.4,"tv":0.21,"id":31374}]}]}
{"op":"mcm","clk":"11798572052","pt":1723153060070,"mc":[{"id":"1.231540814","rc":[{"batb":[[0,2.32,10]],"ltp":2.4,"tv":0.21,"id":31374}]}]}
{"op":"mcm","clk":"11798572139","pt":1723153063149,"mc":[{"id":"1.231540814","rc":[{"batb":[[0,2.34,4]],"ltp":2.4,"tv":0.21,"id":31374}]}]}
{"op":"mcm","clk":"11798572217","pt":1723153065657,"mc":[{"id":"1.231540814","rc":[{"batb":[[0,2.28,29.61],[1,2.02,4.55],[2,1.8,2]],"ltp":2.4,"tv":0.21,"id":31374}]}]}
{"op":"mcm","clk":"11798572223","pt":1723153065760,"mc":[{"id":"1.231540814","rc":[{"batb":[[0,2.36,10],[1,2.28,29.61],[2,2.02,4.55]],"ltp":2.4,"tv":0.21,"id":31374}]}]}
{"op":"mcm","clk":"11798572333","pt":1723153069047,"mc":[{"id":"1.231540814","rc":[{"batb":[[0,2.3,4]],"ltp":2.4,"tv":0.21,"id":31374}]}]}
{"op":"mcm","clk":"11798572408","pt":1723153071559,"mc":[{"id":"1.231540814","rc":[{"batb":[[0,2.3,10]],"ltp":2.4,"tv":0.21,"id":31374}]}]}
{"op":"mcm","clk":"11798572526","pt":1723153075091,"mc":[{"id":"1.231540814","rc":[{"batb":[[0,2.32,4]],"ltp":2.4,"tv":0.21,"id":31374}]}]}
{"op":"mcm","clk":"11798572629","pt":1723153077454,"mc":[{"id":"1.231540814","rc":[{"batb":[[0,2.3,10]],"ltp":2.4,"tv":0.21,"id":31374}]}]}
{"op":"mcm","clk":"11798572696","pt":1723153079562,"mc":[{"id":"1.231540814","rc":[{"batb":[[0,2.32,4],[1,2.3,10],[2,2.28,29.61]],"ltp":2.4,"tv":0.21,"id":31374}]}]}
{"op":"mcm","clk":"11798572741","pt":1723153080893,"mc":[{"id":"1.231540814","rc":[{"batb":[[1,2.28,29.61],[2,2.02,4.55]],"ltp":2.4,"tv":0.21,"id":31374}]}]}
{"op":"mcm","clk":"11798572760","pt":1723153081867,"mc":[{"id":"1.231540814","rc":[{"batb":[[0,2.28,29.61],[1,2.02,4.55],[2,1.8,2]],"ltp":2.4,"tv":0.21,"id":31374}]}]}
{"op":"mcm","clk":"11798572843","pt":1723153083968,"mc":[{"id":"1.231540814","rc":[{"batb":[[0,2.32,4],[1,2.3,10],[2,2.28,29.61]],"ltp":2.4,"tv":0.21,"id":31374}]}]}
{"op":"mcm","clk":"11798572898","pt":1723153086476,"mc":[{"id":"1.231540814","rc":[{"batb":[[0,2.3,10],[1,2.28,29.61],[2,2.02,4.55]],"ltp":2.4,"tv":0.21,"id":31374}]}]}
{"op":"mcm","clk":"11798572912","pt":1723153087092,"mc":[{"id":"1.231540814","rc":[{"batb":[[0,2.28,29.61],[1,2.02,4.55],[2,1.8,2]],"ltp":2.4,"tv":0.21,"id":31374}]}]}
{"op":"mcm","clk":"11798573050","pt":1723153092368,"mc":[{"id":"1.231540814","rc":[{"batb":[[0,2.3,14],[1,2.28,29.61],[2,2.02,4.55]],"ltp":2.4,"tv":0.21,"id":31374}]}]}
{"op":"mcm","clk":"11798573124","pt":1723153094670,"mc":[{"id":"1.231540814","rc":[{"batb":[[0,2.3,10]],"ltp":2.4,"tv":0.21,"id":31374}]}]}
{"op":"mcm","clk":"11798573144","pt":1723153095692,"mc":[{"id":"1.231540814","rc":[{"batb":[[0,2.28,29.61],[1,2.02,4.55],[2,1.8,2]],"ltp":2.4,"tv":0.21,"id":31374}]}]}
{"op":"mcm","clk":"11798573231","pt":1723153098407,"mc":[{"id":"1.231540814","rc":[{"batb":[[0,2.3,14],[1,2.28,29.61],[2,2.02,4.55]],"ltp":2.4,"tv":0.21,"id":31374}]}]}
{"op":"mcm","clk":"11798573316","pt":1723153100612,"mc":[{"id":"1.231540814","rc":[{"batb":[[0,2.3,10]],"ltp":2.4,"tv":0.21,"id":31374}]}]}
{"op":"mcm","clk":"11798573367","pt":1723153101792,"mc":[{"id":"1.231540814","rc":[{"batb":[[0,2.28,29.61],[1,2.02,4.55],[2,1.8,2]],"ltp":2.4,"tv":0.21,"id":31374}]}]}
{"op":"mcm","clk":"11798573469","pt":1723153104305,"mc":[{"id":"1.231540814","rc":[{"batb":[[0,2.3,14],[1,2.28,29.61],[2,2.02,4.55]],"ltp":2.4,"tv":0.21,"id":31374}]}]}
{"op":"mcm","clk":"11798573539","pt":1723153106611,"mc":[{"id":"1.231540814","rc":[{"batb":[[0,2.3,10]],"ltp":2.4,"tv":0.21,"id":31374}]}]}
{"op":"mcm","clk":"11798573558","pt":1723153107482,"mc":[{"id":"1.231540814","rc":[{"batb":[[0,2.28,29.61],[1,2.02,4.55],[2,1.8,2]],"ltp":2.4,"tv":0.21,"id":31374}]}]}
{"op":"mcm","clk":"11798573602","pt":1723153109019,"mc":[{"id":"1.231540814","rc":[{"batb":[[0,2.3,4],[1,2.28,29.61],[2,2.02,4.55]],"ltp":2.4,"tv":0.21,"id":31374}]}]}
{"op":"mcm","clk":"11798573658","pt":1723153111321,"mc":[{"id":"1.231540814","rc":[{"batb":[[0,2.32,10]],"ltp":2.4,"tv":0.21,"id":31374}]}]}
{"op":"mcm","clk":"11798573781","pt":1723153114605,"mc":[{"id":"1.231540814","rc":[{"batb":[[0,2.34,4]],"ltp":2.4,"tv":0.21,"id":31374}]}]}
{"op":"mcm","clk":"11798573860","pt":1723153117113,"mc":[{"id":"1.231540814","rc":[{"batb":[[0,2.3,10]],"ltp":2.4,"tv":0.21,"id":31374}]}]}
{"op":"mcm","clk":"11798573972","pt":1723153120399,"mc":[{"id":"1.231540814","rc":[{"batb":[[0,2.32,4]],"ltp":2.4,"tv":0.21,"id":31374}]}]}
{"op":"mcm","clk":"11798574032","pt":1723153122710,"mc":[{"id":"1.231540814","rc":[{"batb":[[0,2.34,10],[1,2.32,4],[2,2.28,29.61]],"ltp":2.4,"tv":0.21,"id":31374}]}]}
{"op":"mcm","clk":"11798574037","pt":1723153122812,"mc":[{"id":"1.231540814","rc":[{"batb":[[1,2.28,29.61],[2,2.02,4.55]],"ltp":2.4,"tv":0.21,"id":31374}]}]}
{"op":"mcm","clk":"11798574097","pt":1723153125114,"mc":[{"id":"1.231540814","rc":[{"batb":[[0,2.36,4],[1,2.34,10],[2,2.28,29.61]],"ltp":2.4,"tv":0.21,"id":31374}]}]}
{"op":"mcm","clk":"11798574126","pt":1723153125993,"mc":[{"id":"1.231540814","rc":[{"batb":[[1,2.28,29.61],[2,2.02,4.55]],"ltp":2.4,"tv":0.21,"id":31374}]}]}
{"op":"mcm","clk":"11798574164","pt":1723153127428,"mc":[{"id":"1.231540814","rc":[{"batb":[[0,2.28,29.61],[1,2.02,4.55],[2,1.8,2]],"ltp":2.4,"tv":0.21,"id":31374}]}]}
{"op":"mcm","clk":"11798574243","pt":1723153129736,"mc":[{"id":"1.231540814","rc":[{"batb":[[0,2.3,14],[1,2.28,29.61],[2,2.02,4.55]],"ltp":2.4,"tv":0.21,"id":31374}]}]}
{"op":"mcm","clk":"11798574327","pt":1723153131996,"mc":[{"id":"1.231540814","rc":[{"batb":[[0,2.3,10]],"ltp":2.4,"tv":0.21,"id":31374}]}]}
{"op":"mcm","clk":"11798574357","pt":1723153132916,"mc":[{"id":"1.231540814","rc":[{"batb":[[0,2.28,29.61],[1,2.02,4.55],[2,1.8,2]],"ltp":2.4,"tv":0.21,"id":31374}]}]}
{"op":"mcm","clk":"11798574388","pt":1723153134100,"mc":[{"id":"1.231540814","rc":[{"batb":[[0,2.3,4],[1,2.28,29.61],[2,2.02,4.55]],"ltp":2.4,"tv":0.21,"id":31374}]}]}
{"op":"mcm","clk":"11798574465","pt":1723153136601,"mc":[{"id":"1.231540814","rc":[{"batb":[[0,2.3,10]],"ltp":2.4,"tv":0.21,"id":31374}]}]}
{"op":"mcm","clk":"11798574563","pt":1723153139114,"mc":[{"id":"1.231540814","rc":[{"batb":[[0,2.32,4],[1,2.3,10],[2,2.28,29.61]],"ltp":2.4,"tv":0.21,"id":31374}]}]}
{"op":"mcm","clk":"11798574586","pt":1723153139833,"mc":[{"id":"1.231540814","rc":[{"batb":[[1,2.28,29.61],[2,2.02,4.55]],"ltp":2.4,"tv":0.21,"id":31374}]}]}
{"op":"mcm","clk":"11798574641","pt":1723153141420,"mc":[{"id":"1.231540814","rc":[{"batb":[[0,2.28,29.61],[1,2.02,4.55],[2,1.8,2]],"ltp":2.4,"tv":0.21,"id":31374}]}]}
{"op":"mcm","clk":"11798574689","pt":1723153142504,"mc":[{"id":"1.231540814","rc":[{"batb":[[0,2.3,10],[1,2.28,29.61],[2,2.02,4.55]],"ltp":2.4,"tv":0.21,"id":31374}]}]}
{"op":"mcm","clk":"11798574726","pt":1723153143728,"mc":[{"id":"1.231540814","rc":[{"batb":[[0,2.32,4],[1,2.3,10],[2,2.28,29.61]],"ltp":2.4,"tv":0.21,"id":31374}]}]}
{"op":"mcm","clk":"11798574806","pt":1723153145905,"mc":[{"id":"1.231540814","rc":[{"batb":[[0,2.28,29.61],[1,2.02,4.55],[2,1.8,2]],"ltp":2.4,"tv":0.21,"id":31374}]}]}
{"op":"mcm","clk":"11798574903","pt":1723153148419,"mc":[{"id":"1.231540814","rc":[{"batb":[[0,2.3,14],[1,2.28,29.61],[2,2.02,4.55]],"ltp":2.4,"tv":0.21,"id":31374}]}]}
{"op":"mcm","clk":"11798575037","pt":1723153152727,"mc":[{"id":"1.231540814","rc":[{"batb":[[0,2.28,29.61],[1,2.02,4.55],[2,1.8,2]],"ltp":2.4,"tv":0.21,"id":31374}]}]}
{"op":"mcm","clk":"11798575077","pt":1723153154110,"mc":[{"id":"1.231540814","rc":[{"batb":[[0,2.3,4],[1,2.28,29.61],[2,2.02,4.55]],"ltp":2.4,"tv":0.21,"id":31374}]}]}
{"op":"mcm","clk":"11798575130","pt":1723153155549,"mc":[{"id":"1.231540814","rc":[{"batb":[[0,2.32,10],[1,2.3,4],[2,2.28,29.61]],"ltp":2.4,"tv":0.21,"id":31374}]}]}
{"op":"mcm","clk":"11798575167","pt":1723153156525,"mc":[{"id":"1.231540814","rc":[{"batb":[[1,2.28,29.61],[2,2.02,4.55]],"ltp":2.4,"tv":0.21,"id":31374}]}]}
{"op":"mcm","clk":"11798575277","pt":1723153159243,"mc":[{"id":"1.231540814","rc":[{"batb":[[0,2.3,4]],"ltp":2.4,"tv":0.21,"id":31374}]}]}
{"op":"mcm","clk":"11798575362","pt":1723153161650,"mc":[{"id":"1.231540814","rc":[{"batb":[[0,2.3,10]],"ltp":2.4,"tv":0.21,"id":31374}]}]}
{"op":"mcm","clk":"11798575501","pt":1723153165450,"mc":[{"id":"1.231540814","rc":[{"batb":[[0,2.3,4]],"ltp":2.4,"tv":0.21,"id":31374}]}]}
{"op":"mcm","clk":"11798575586","pt":1723153167655,"mc":[{"id":"1.231540814","rc":[{"batb":[[0,2.28,29.61],[1,2.02,4.55],[2,1.8,2]],"ltp":2.4,"tv":0.21,"id":31374}]}]}
{"op":"mcm","clk":"11798575590","pt":1723153167757,"mc":[{"id":"1.231540814","rc":[{"batb":[[0,2.3,10],[1,2.28,29.61],[2,2.02,4.55]],"ltp":2.4,"tv":0.21,"id":31374}]}]}
{"op":"mcm","clk":"11798575626","pt":1723153169039,"mc":[{"id":"1.231540814","rc":[{"batb":[[0,2.32,4.71],[1,2.3,10],[2,2.28,29.61]],"ltp":2.4,"tv":0.21,"id":31374}]}]}
{"op":"mcm","clk":"11798575663","pt":1723153170217,"mc":[{"id":"1.231540814","rc":[{"batb":[[0,2.34,4],[1,2.32,4.71],[2,2.3,10]],"ltp":2.4,"tv":0.21,"id":31374}]}]}
{"op":"mcm","clk":"11798575695","pt":1723153171240,"mc":[{"id":"1.231540814","rc":[{"batb":[[2,2.28,29.61]],"ltp":2.4,"tv":0.21,"id":31374}]}]}
{"op":"mcm","clk":"11798575744","pt":1723153172627,"mc":[{"id":"1.231540814","rc":[{"batb":[[0,2.32,4.71],[1,2.28,29.61],[2,2.02,4.55]],"ltp":2.4,"tv":0.21,"id":31374}]}]}
{"op":"mcm","clk":"11798575801","pt":1723153174059,"mc":[{"id":"1.231540814","rc":[{"batb":[[0,2.34,10]],"ltp":2.4,"tv":0.21,"id":31374}]}]}
{"op":"mcm","clk":"11798575832","pt":1723153175135,"mc":[{"id":"1.231540814","rc":[{"batb":[[0,2.36,4],[1,2.34,10],[2,2.28,29.61]],"ltp":2.4,"tv":0.21,"id":31374}]}]}
{"op":"mcm","clk":"11798575920","pt":1723153177542,"mc":[{"id":"1.231540814","rc":[{"batb":[[0,2.28,29.61],[1,2.02,4.55],[2,1.8,2]],"ltp":2.4,"tv":0.21,"id":31374}]}]}
{"op":"mcm","clk":"11798575978","pt":1723153179742,"mc":[{"id":"1.231540814","rc":[{"batb":[[0,2.3,14],[1,2.28,29.61],[2,2.02,4.55]],"ltp":2.4,"tv":0.21,"id":31374}]}]}
{"op":"mcm","clk":"11798576048","pt":1723153182254,"mc":[{"id":"1.231540814","rc":[{"batb":[[0,2.3,10]],"ltp":2.4,"tv":0.21,"id":31374}]}]}
{"op":"mcm","clk":"11798576071","pt":1723153183274,"mc":[{"id":"1.231540814","rc":[{"batb":[[0,2.28,29.61],[1,2.02,4.55],[2,1.8,2]],"ltp":2.4,"tv":0.21,"id":31374}]}]}
{"op":"mcm","clk":"11798576187","pt":1723153186656,"mc":[{"id":"1.231540814","rc":[{"batb":[[0,2.3,14],[1,2.28,29.61],[2,2.02,4.55]],"ltp":2.4,"tv":0.21,"id":31374}]}]}
{"op":"mcm","clk":"11798576268","pt":1723153189063,"mc":[{"id":"1.231540814","rc":[{"batb":[[0,2.3,10]],"ltp":2.4,"tv":0.21,"id":31374}]}]}
{"op":"mcm","clk":"11798576322","pt":1723153190049,"mc":[{"id":"1.231540814","rc":[{"batb":[[0,2.28,29.61],[1,2.02,4.55],[2,1.8,2]],"ltp":2.4,"tv":0.21,"id":31374}]}]}
{"op":"mcm","clk":"11798576373","pt":1723153191276,"mc":[{"id":"1.231540814","rc":[{"batb":[[0,2.3,4],[1,2.28,29.61],[2,2.02,4.55]],"ltp":2.4,"tv":0.21,"id":31374}]}]}
{"op":"mcm","clk":"11798576453","pt":1723153193585,"mc":[{"id":"1.231540814","rc":[{"batb":[[0,2.32,10]],"ltp":2.4,"tv":0.21,"id":31374}]}]}
{"op":"mcm","clk":"11798576589","pt":1723153196866,"mc":[{"id":"1.231540814","rc":[{"batb":[[0,2.3,4]],"ltp":2.4,"tv":0.21,"id":31374}]}]}
{"op":"mcm","clk":"11798576682","pt":1723153199173,"mc":[{"id":"1.231540814","rc":[{"batb":[[0,2.3,10]],"ltp":2.4,"tv":0.21,"id":31374}]}]}
{"op":"mcm","clk":"11798576827","pt":1723153202559,"mc":[{"id":"1.231540814","rc":[{"batb":[[0,2.32,4]],"ltp":2.4,"tv":0.21,"id":31374}]}]}
{"op":"mcm","clk":"11798576883","pt":1723153204359,"mc":[{"id":"1.231540814","rc":[{"batb":[[0,2.28,29.61],[1,2.02,4.55],[2,1.8,2]],"ltp":2.4,"tv":0.21,"id":31374}]}]}
{"op":"mcm","clk":"11798576930","pt":1723153205587,"mc":[{"id":"1.231540814","rc":[{"batb":[[0,2.3,10],[1,2.28,29.61],[2,2.02,4.55]],"ltp":2.4,"tv":0.21,"id":31374}]}]}
{"op":"mcm","clk":"11798576975","pt":1723153207483,"mc":[{"id":"1.231540814","rc":[{"batb":[[0,2.32,4],[1,2.3,10],[2,2.28,29.61]],"ltp":2.4,"tv":0.21,"id":31374}]}]}
{"op":"mcm","clk":"11798577026","pt":1723153208869,"mc":[{"id":"1.231540814","rc":[{"batb":[[1,2.28,29.61],[2,2.02,4.55]],"ltp":2.4,"tv":0.21,"id":31374}]}]}
{"op":"mcm","clk":"11798577054","pt":1723153209792,"mc":[{"id":"1.231540814","rc":[{"batb":[[0,2.28,29.61],[1,2.02,4.55],[2,1.8,2]],"ltp":2.4,"tv":0.21,"id":31374}]}]}
{"op":"mcm","clk":"11798577197","pt":1723153213896,"mc":[{"id":"1.231540814","rc":[{"batb":[[0,2.3,14],[1,2.28,29.61],[2,2.02,4.55]],"ltp":2.4,"tv":0.21,"id":31374}]}]}
{"op":"mcm","clk":"11798577273","pt":1723153216205,"mc":[{"id":"1.231540814","rc":[{"batb":[[0,2.3,10]],"ltp":2.4,"tv":0.21,"id":31374}]}]}
{"op":"mcm","clk":"11798577310","pt":1723153217283,"mc":[{"id":"1.231540814","rc":[{"batb":[[0,2.28,29.61],[1,2.02,4.55],[2,1.8,2]],"ltp":2.4,"tv":0.21,"id":31374}]}]}
{"op":"mcm","clk":"11798577342","pt":1723153218364,"mc":[{"id":"1.231540814","rc":[{"batb":[[0,2.3,4],[1,2.28,29.61],[2,2.02,4.55]],"ltp":2.4,"tv":0.21,"id":31374}]}]}
{"op":"mcm","clk":"11798577392","pt":1723153219697,"mc":[{"id":"1.231540814","rc":[{"batb":[[0,2.32,10],[1,2.3,4],[2,2.28,29.61]],"ltp":2.4,"tv":0.21,"id":31374}]}]}
{"op":"mcm","clk":"11798577434","pt":1723153220873,"mc":[{"id":"1.231540814","rc":[{"batb":[[1,2.28,29.61],[2,2.02,4.55]],"ltp":2.4,"tv":0.21,"id":31374}]}]}
{"op":"mcm","clk":"11798577517","pt":1723153223282,"mc":[{"id":"1.231540814","rc":[{"batb":[[0,2.34,4]],"ltp":2.4,"tv":0.21,"id":31374}]}]}
{"op":"mcm","clk":"11798577594","pt":1723153225692,"mc":[{"id":"1.231540814","rc":[{"batb":[[0,2.3,10]],"ltp":2.4,"tv":0.21,"id":31374}]}]}
{"op":"mcm","clk":"11798577696","pt":1723153228093,"mc":[{"id":"1.231540814","rc":[{"batb":[[0,2.32,4],[1,2.3,10],[2,2.28,29.61]],"ltp":2.4,"tv":0.21,"id":31374}]}]}
{"op":"mcm","clk":"11798577734","pt":1723153229015,"mc":[{"id":"1.231540814","rc":[{"batb":[[1,2.28,29.61],[2,2.02,4.55]],"ltp":2.4,"tv":0.21,"id":31374}]}]}
{"op":"mcm","clk":"11798577783","pt":1723153230297,"mc":[{"id":"1.231540814","rc":[{"batb":[[0,2.28,29.61],[1,2.02,4.55],[2,1.8,2]],"ltp":2.4,"tv":0.21,"id":31374}]}]}
{"op":"mcm","clk":"11798577825","pt":1723153231577,"mc":[{"id":"1.231540814","rc":[{"batb":[[0,2.3,10],[1,2.28,29.61],[2,2.02,4.55]],"ltp":2.4,"tv":0.21,"id":31374}]}]}
{"op":"mcm","clk":"11798577862","pt":1723153232805,"mc":[{"id":"1.231540814","rc":[{"batb":[[0,2.32,4],[1,2.3,10],[2,2.28,29.61]],"ltp":2.4,"tv":0.21,"id":31374}]}]}
{"op":"mcm","clk":"11798577919","pt":1723153235111,"mc":[{"id":"1.231540814","rc":[{"batb":[[0,2.28,29.61],[1,2.02,4.55],[2,1.8,2]],"ltp":2.4,"tv":0.21,"id":31374}]}]}
{"op":"mcm","clk":"11798577984","pt":1723153237317,"mc":[{"id":"1.231540814","rc":[{"batb":[[0,2.3,14],[1,2.28,29.61],[2,2.02,4.55]],"ltp":2.4,"tv":0.21,"id":31374}]}]}
{"op":"mcm","clk":"11798578053","pt":1723153239620,"mc":[{"id":"1.231540814","rc":[{"batb":[[0,2.3,10]],"ltp":2.4,"tv":0.21,"id":31374}]}]}
{"op":"mcm","clk":"11798578087","pt":1723153240499,"mc":[{"id":"1.231540814","rc":[{"batb":[[0,2.28,29.61],[1,2.02,4.55],[2,1.8,2]],"ltp":2.4,"tv":0.21,"id":31374}]}]}
{"op":"mcm","clk":"11798578153","pt":1723153243009,"mc":[{"id":"1.231540814","rc":[{"batb":[[0,2.3,14],[1,2.28,29.61],[2,2.02,4.55]],"ltp":2.4,"tv":0.21,"id":31374}]}]}
{"op":"mcm","clk":"11798578230","pt":1723153245310,"mc":[{"id":"1.231540814","rc":[{"batb":[[0,2.3,10]],"ltp":2.4,"tv":0.21,"id":31374}]}]}
{"op":"mcm","clk":"11798578253","pt":1723153246335,"mc":[{"id":"1.231540814","rc":[{"batb":[[0,2.28,29.61],[1,2.02,4.55],[2,1.8,2]],"ltp":2.4,"tv":0.21,"id":31374}]}]}
{"op":"mcm","clk":"11798578296","pt":1723153247513,"mc":[{"id":"1.231540814","rc":[{"batb":[[0,2.3,4],[1,2.28,29.61],[2,2.02,4.55]],"ltp":2.4,"tv":0.21,"id":31374}]}]}
{"op":"mcm","clk":"11798578323","pt":1723153248792,"mc":[{"id":"1.231540814","rc":[{"batb":[[0,2.32,10],[1,2.3,4],[2,2.28,29.61]],"ltp":2.4,"tv":0.21,"id":31374}]}]}
{"op":"mcm","clk":"11798578358","pt":1723153249816,"mc":[{"id":"1.231540814","rc":[{"batb":[[1,2.28,29.61],[2,2.02,4.55]],"ltp":2.4,"tv":0.21,"id":31374}]}]}
{"op":"mcm","clk":"11798578448","pt":1723153252325,"mc":[{"id":"1.231540814","rc":[{"batb":[[0,2.3,4]],"ltp":2.4,"tv":0.21,"id":31374}]}]}
{"op":"mcm","clk":"11798578512","pt":1723153254727,"mc":[{"id":"1.231540814","rc":[{"batb":[[0,2.3,10]],"ltp":2.4,"tv":0.21,"id":31374}]}]}
{"op":"mcm","clk":"11798578560","pt":1723153256925,"mc":[{"id":"1.231540814","rc":[{"batb":[[0,2.32,4],[1,2.3,10],[2,2.28,29.61]],"ltp":2.4,"tv":0.21,"id":31374}]}]}
{"op":"mcm","clk":"11798578603","pt":1723153258203,"mc":[{"id":"1.231540814","rc":[{"batb":[[1,2.28,29.61],[2,2.02,4.55]],"ltp":2.4,"tv":0.21,"id":31374}]}]}
{"op":"mcm","clk":"11798578639","pt":1723153259436,"mc":[{"id":"1.231540814","rc":[{"batb":[[0,2.28,29.61],[1,2.02,4.55],[2,1.8,2]],"ltp":2.4,"tv":0.21,"id":31374}]}]}
{"op":"mcm","clk":"11798578683","pt":1723153261533,"mc":[{"id":"1.231540814","rc":[{"batb":[[0,2.3,10],[1,2.28,29.61],[2,2.02,4.55]],"ltp":2.4,"tv":0.21,"id":31374}]}]}
{"op":"mcm","clk":"11798578689","pt":1723153261738,"mc":[{"id":"1.231540814","rc":[{"batb":[[0,2.32,4],[1,2.3,10],[2,2.28,29.61]],"ltp":2.4,"tv":0.21,"id":31374}]}]}
{"op":"mcm","clk":"11798578747","pt":1723153264046,"mc":[{"id":"1.231540814","rc":[{"batb":[[0,2.3,10],[1,2.28,29.61],[2,2.02,4.55]],"ltp":2.4,"tv":0.21,"id":31374}]}]}
{"op":"mcm","clk":"11798578762","pt":1723153264815,"mc":[{"id":"1.231540814","rc":[{"batb":[[0,2.28,29.61],[1,2.02,4.55],[2,1.8,2]],"ltp":2.4,"tv":0.21,"id":31374}]}]}
{"op":"mcm","clk":"11798578839","pt":1723153267430,"mc":[{"id":"1.231540814","rc":[{"batb":[[0,2.3,14],[1,2.28,29.61],[2,2.02,4.55]],"ltp":2.4,"tv":0.21,"id":31374}]}]}
{"op":"mcm","clk":"11798578910","pt":1723153269737,"mc":[{"id":"1.231540814","rc":[{"batb":[[0,2.3,10]],"ltp":2.4,"tv":0.21,"id":31374}]}]}
{"op":"mcm","clk":"11798578947","pt":1723153270758,"mc":[{"id":"1.231540814","rc":[{"batb":[[0,2.28,29.61],[1,2.02,4.55],[2,1.8,2]],"ltp":2.4,"tv":0.21,"id":31374}]}]}
{"op":"mcm","clk":"11798578987","pt":1723153272139,"mc":[{"id":"1.231540814","rc":[{"batb":[[0,2.3,4],[1,2.28,29.61],[2,2.02,4.55]],"ltp":2.4,"tv":0.21,"id":31374}]}]}
{"op":"mcm","clk":"11798579057","pt":1723153274549,"mc":[{"id":"1.231540814","rc":[{"batb":[[0,2.32,10]],"ltp":2.4,"tv":0.21,"id":31374}]}]}
{"op":"mcm","clk":"11798579143","pt":1723153277728,"mc":[{"id":"1.231540814","rc":[{"batb":[[0,2.28,29.61],[1,2.02,4.55],[2,1.8,2]],"ltp":2.4,"tv":0.21,"id":31374}]}]}
{"op":"mcm","clk":"11798579148","pt":1723153277831,"mc":[{"id":"1.231540814","rc":[{"batb":[[0,2.34,4],[1,2.28,29.61],[2,2.02,4.55]],"ltp":2.4,"tv":0.21,"id":31374}]}]}
{"op":"mcm","clk":"11798579226","pt":1723153280081,"mc":[{"id":"1.231540814","rc":[{"batb":[[0,2.36,10]],"ltp":2.4,"tv":0.21,"id":31374}]}]}
{"op":"mcm","clk":"11798579333","pt":1723153283522,"mc":[{"id":"1.231540814","rc":[{"batb":[[0,2.3,4]],"ltp":2.4,"tv":0.21,"id":31374}]}]}
{"op":"mcm","clk":"11798579435","pt":1723153285934,"mc":[{"id":"1.231540814","rc":[{"batb":[[0,2.3,10]],"ltp":2.4,"tv":0.21,"id":31374}]}]}
{"op":"mcm","clk":"11798579561","pt":1723153289363,"mc":[{"id":"1.231540814","rc":[{"batb":[[0,2.3,4]],"ltp":2.4,"tv":0.21,"id":31374}]}]}
{"op":"mcm","clk":"11798579645","pt":1723153291772,"mc":[{"id":"1.231540814","rc":[{"batb":[[0,2.32,10]],"ltp":2.4,"tv":0.21,"id":31374}]}]}
{"op":"mcm","clk":"11798579696","pt":1723153294033,"mc":[{"id":"1.231540814","rc":[{"batb":[[0,2.34,4],[1,2.32,10],[2,2.28,29.61]],"ltp":2.4,"tv":0.21,"id":31374}]}]}
{"op":"mcm","clk":"11798579728","pt":1723153295159,"mc":[{"id":"1.231540814","rc":[{"batb":[[1,2.28,29.61],[2,2.02,4.55]],"ltp":2.4,"tv":0.21,"id":31374}]}]}
{"op":"mcm","clk":"11798579750","pt":1723153296235,"mc":[{"id":"1.231540814","rc":[{"batb":[[0,2.28,29.61],[1,2.02,4.55],[2,1.8,2]],"ltp":2.4,"tv":0.21,"id":31374}]}]}
{"op":"mcm","clk":"11798579782","pt":1723153297565,"mc":[{"id":"1.231540814","rc":[{"batb":[[0,2.3,10],[1,2.28,29.61],[2,2.02,4.55]],"ltp":2.4,"tv":0.21,"id":31374}]}]}
{"op":"mcm","clk":"11798579823","pt":1723153298645,"mc":[{"id":"1.231540814","rc":[{"batb":[[0,2.32,4],[1,2.3,10],[2,2.28,29.61]],"ltp":2.4,"tv":0.21,"id":31374}]}]}
{"op":"mcm","clk":"11798579872","pt":1723153300845,"mc":[{"id":"1.231540814","rc":[{"batb":[[0,2.28,29.61],[1,2.02,4.55],[2,1.8,2]],"ltp":2.4,"tv":0.21,"id":31374}]}]}
{"op":"mcm","clk":"11798579947","pt":1723153303253,"mc":[{"id":"1.231540814","rc":[{"batb":[[0,2.3,14],[1,2.28,29.61],[2,2.02,4.55]],"ltp":2.4,"tv":0.21,"id":31374}]}]}
{"op":"mcm","clk":"11798580018","pt":1723153305656,"mc":[{"id":"1.231540814","rc":[{"batb":[[0,2.3,10]],"ltp":2.4,"tv":0.21,"id":31374}]}]}
{"op":"mcm","clk":"11798580049","pt":1723153306677,"mc":[{"id":"1.231540814","rc":[{"batb":[[0,2.28,29.61],[1,2.02,4.55],[2,1.8,2]],"ltp":2.4,"tv":0.21,"id":31374}]}]}
{"op":"mcm","clk":"11798580121","pt":1723153309085,"mc":[{"id":"1.231540814","rc":[{"batb":[[0,2.3,14],[1,2.28,29.61],[2,2.02,4.55]],"ltp":2.4,"tv":0.21,"id":31374}]}]}
{"op":"mcm","clk":"11798580200","pt":1723153311446,"mc":[{"id":"1.231540814","rc":[{"batb":[[0,2.3,10]],"ltp":2.4,"tv":0.21,"id":31374}]}]}
{"op":"mcm","clk":"11798580231","pt":1723153312466,"mc":[{"id":"1.231540814","rc":[{"batb":[[0,2.32,4.71]],"ltp":2.4,"tv":0.21,"id":31374}]}]}
{"op":"mcm","clk":"11798580260","pt":1723153313540,"mc":[{"id":"1.231540814","rc":[{"batb":[[0,2.34,4],[1,2.32,4.71],[2,2.28,29.61]],"ltp":2.4,"tv":0.21,"id":31374}]}]}
{"op":"mcm","clk":"11798580303","pt":1723153314871,"mc":[{"id":"1.231540814","rc":[{"batb":[[0,2.36,10],[1,2.34,4],[2,2.32,4.71]],"ltp":2.4,"tv":0.21,"id":31374}]}]}
{"op":"mcm","clk":"11798580341","pt":1723153315843,"mc":[{"id":"1.231540814","rc":[{"batb":[[1,2.32,4.71],[2,2.28,29.61]],"ltp":2.4,"tv":0.21,"id":31374}]}]}
{"op":"mcm","clk":"11798580378","pt":1723153316871,"mc":[{"id":"1.231540814","rc":[{"batb":[[1,2.28,29.61],[2,2.02,4.55]],"ltp":2.4,"tv":0.21,"id":31374}]}]}
{"op":"mcm","clk":"11798580436","pt":1723153318355,"mc":[{"id":"1.231540814","rc":[{"batb":[[0,2.3,4]],"ltp":2.4,"tv":0.21,"id":31374}]}]}
{"op":"mcm","clk":"11798580538","pt":1723153321066,"mc":[{"id":"1.231540814","rc":[{"batb":[[0,2.3,10]],"ltp":2.4,"tv":0.21,"id":31374}]}]}
{"op":"mcm","clk":"11798580637","pt":1723153324497,"mc":[{"id":"1.231540814","rc":[{"batb":[[0,2.32,4]],"ltp":2.4,"tv":0.21,"id":31374}]}]}
{"op":"mcm","clk":"11798580698","pt":1723153326186,"mc":[{"id":"1.231540814","rc":[{"batb":[[0,2.28,29.61],[1,2.02,4.55],[2,1.8,2]],"ltp":2.4,"tv":0.21,"id":31374}]}]}
{"op":"mcm","clk":"11798580763","pt":1723153328698,"mc":[{"id":"1.231540814","rc":[{"batb":[[0,2.3,14],[1,2.28,29.61],[2,2.02,4.55]],"ltp":2.4,"tv":0.21,"id":31374}]}]}
{"op":"mcm","clk":"11798580818","pt":1723153330897,"mc":[{"id":"1.231540814","rc":[{"batb":[[0,2.3,10]],"ltp":2.4,"tv":0.21,"id":31374}]}]}
{"op":"mcm","clk":"11798580848","pt":1723153332074,"mc":[{"id":"1.231540814","rc":[{"batb":[[0,2.28,29.61],[1,2.02,4.55],[2,1.8,2]],"ltp":2.4,"tv":0.21,"id":31374}]}]}
{"op":"mcm","clk":"11798580885","pt":1723153333407,"mc":[{"id":"1.231540814","rc":[{"batb":[[0,2.3,4],[1,2.28,29.61],[2,2.02,4.55]],"ltp":2.4,"tv":0.21,"id":31374}]}]}
{"op":"mcm","clk":"11798580937","pt":1723153335308,"mc":[{"id":"1.231540814","rc":[{"batb":[[0,2.32,10],[1,2.3,4],[2,2.28,29.61]],"ltp":2.4,"tv":0.21,"id":31374}]}]}
{"op":"mcm","clk":"11798580955","pt":1723153335770,"mc":[{"id":"1.231540814","rc":[{"batb":[[1,2.28,29.61],[2,2.02,4.55]],"ltp":2.4,"tv":0.21,"id":31374}]}]}
{"op":"mcm","clk":"11798581034","pt":1723153338686,"mc":[{"id":"1.231540814","rc":[{"batb":[[0,2.3,4]],"ltp":2.4,"tv":0.21,"id":31374}]}]}
{"op":"mcm","clk":"11798581123","pt":1723153341192,"mc":[{"id":"1.231540814","rc":[{"batb":[[0,2.3,10]],"ltp":2.4,"tv":0.21,"id":31374}]}]}
{"op":"mcm","clk":"11798581197","pt":1723153343300,"mc":[{"id":"1.231540814","rc":[{"batb":[[0,2.32,4],[1,2.3,10],[2,2.28,29.61]],"ltp":2.4,"tv":0.21,"id":31374}]}]}
{"op":"mcm","clk":"11798581232","pt":1723153344575,"mc":[{"id":"1.231540814","rc":[{"batb":[[1,2.28,29.61],[2,2.02,4.55]],"ltp":2.4,"tv":0.21,"id":31374}]}]}
{"op":"mcm","clk":"11798581274","pt":1723153345600,"mc":[{"id":"1.231540814","rc":[{"batb":[[0,2.28,29.61],[1,2.02,4.55],[2,1.8,2]],"ltp":2.4,"tv":0.21,"id":31374}]}]}
{"op":"mcm","clk":"11798581336","pt":1723153348007,"mc":[{"id":"1.231540814","rc":[{"batb":[[0,2.3,14],[1,2.28,29.61],[2,2.02,4.55]],"ltp":2.4,"tv":0.21,"id":31374}]}]}
{"op":"mcm","clk":"11798581407","pt":1723153350416,"mc":[{"id":"1.231540814","rc":[{"batb":[[0,2.3,10]],"ltp":2.4,"tv":0.21,"id":31374}]}]}
{"op":"mcm","clk":"11798581431","pt":1723153351395,"mc":[{"id":"1.231540814","rc":[{"batb":[[0,2.28,29.61],[1,2.02,4.55],[2,1.8,2]],"ltp":2.4,"tv":0.21,"id":31374}]}]}
{"op":"mcm","clk":"11798581460","pt":1723153352572,"mc":[{"id":"1.231540814","rc":[{"batb":[[0,2.3,4],[1,2.28,29.61],[2,2.02,4.55]],"ltp":2.4,"tv":0.21,"id":31374}]}]}
{"op":"mcm","clk":"11798581531","pt":1723153354927,"mc":[{"id":"1.231540814","rc":[{"batb":[[0,2.32,10]],"ltp":2.4,"tv":0.21,"id":31374}]}]}
{"op":"mcm","clk":"11798581633","pt":1723153358419,"mc":[{"id":"1.231540814","rc":[{"batb":[[0,2.3,4]],"ltp":2.4,"tv":0.21,"id":31374}]}]}
{"op":"mcm","clk":"11798581685","pt":1723153360719,"mc":[{"id":"1.231540814","rc":[{"batb":[[0,2.32,10],[1,2.3,4],[2,2.28,29.61]],"ltp":2.4,"tv":0.21,"id":31374}]}]}
{"op":"mcm","clk":"11798581689","pt":1723153360925,"mc":[{"id":"1.231540814","rc":[{"batb":[[1,2.28,29.61],[2,2.02,4.55]],"ltp":2.4,"tv":0.21,"id":31374}]}]}
{"op":"mcm","clk":"11798581739","pt":1723153363180,"mc":[{"id":"1.231540814","rc":[{"batb":[[0,2.34,4],[1,2.32,10],[2,2.28,29.61]],"ltp":2.4,"tv":0.21,"id":31374}]}]}
{"op":"mcm","clk":"11798581760","pt":1723153363898,"mc":[{"id":"1.231540814","rc":[{"batb":[[1,2.28,29.61],[2,2.02,4.55]],"ltp":2.4,"tv":0.21,"id":31374}]}]}
{"op":"mcm","clk":"11798581819","pt":1723153365485,"mc":[{"id":"1.231540814","rc":[{"batb":[[0,2.28,29.61],[1,2.02,4.55],[2,1.8,2]],"ltp":2.4,"tv":0.21,"id":31374}]}]}
{"op":"mcm","clk":"11798581930","pt":1723153368925,"mc":[{"id":"1.231540814","rc":[{"batb":[[0,2.3,14],[1,2.28,29.61],[2,2.02,4.55]],"ltp":2.4,"tv":0.21,"id":31374}]}]}
{"op":"mcm","clk":"11798581999","pt":1723153371199,"mc":[{"id":"1.231540814","rc":[{"batb":[[0,2.3,10]],"ltp":2.4,"tv":0.21,"id":31374}]}]}
{"op":"mcm","clk":"11798582036","pt":1723153372327,"mc":[{"id":"1.231540814","rc":[{"batb":[[0,2.28,29.61],[1,2.02,4.55],[2,1.8,2]],"ltp":2.4,"tv":0.21,"id":31374}]}]}
{"op":"mcm","clk":"11798582103","pt":1723153374633,"mc":[{"id":"1.231540814","rc":[{"batb":[[0,2.3,14],[1,2.28,29.61],[2,2.02,4.55]],"ltp":2.4,"tv":0.21,"id":31374}]}]}
{"op":"mcm","clk":"11798582170","pt":1723153376912,"mc":[{"id":"1.231540814","rc":[{"batb":[[0,2.3,10]],"ltp":2.4,"tv":0.21,"id":31374}]}]}
{"op":"mcm","clk":"11798582198","pt":1723153377835,"mc":[{"id":"1.231540814","rc":[{"batb":[[0,2.28,29.61],[1,2.02,4.55],[2,1.8,2]],"ltp":2.4,"tv":0.21,"id":31374}]}]}
{"op":"mcm","clk":"11798582285","pt":1723153379409,"mc":[{"id":"1.231540814","rc":[{"batb":[[0,2.3,4],[1,2.28,29.61],[2,2.02,4.55]],"ltp":2.4,"tv":0.21,"id":31374}]}]}
{"op":"mcm","clk":"11798582329","pt":1723153380601,"mc":[{"id":"1.231540814","rc":[{"batb":[[0,2.32,10],[1,2.3,4],[2,2.28,29.61]],"ltp":2.4,"tv":0.21,"id":31374}]}]}
{"op":"mcm","clk":"11798582375","pt":1723153381936,"mc":[{"id":"1.231540814","rc":[{"batb":[[1,2.28,29.61],[2,2.02,4.55]],"ltp":2.4,"tv":0.21,"id":31374}]}]}
{"op":"mcm","clk":"11798582464","pt":1723153384144,"mc":[{"id":"1.231540814","rc":[{"batb":[[0,2.34,4]],"ltp":2.4,"tv":0.21,"id":31374}]}]}
{"op":"mcm","clk":"11798582523","pt":1723153386449,"mc":[{"id":"1.231540814","rc":[{"batb":[[0,2.36,10]],"ltp":2.4,"tv":0.21,"id":31374}]}]}
{"op":"mcm","clk":"11798582638","pt":1723153389936,"mc":[{"id":"1.231540814","rc":[{"batb":[[0,2.3,4]],"ltp":2.4,"tv":0.21,"id":31374}]}]}
{"op":"mcm","clk":"11798582723","pt":1723153392246,"mc":[{"id":"1.231540814","rc":[{"batb":[[0,2.32,10]],"ltp":2.4,"tv":0.21,"id":31374}]}]}
{"op":"mcm","clk":"11798582818","pt":1723153395529,"mc":[{"id":"1.231540814","rc":[{"batb":[[0,2.34,4]],"ltp":2.4,"tv":0.21,"id":31374}]}]}
{"op":"mcm","clk":"11798582879","pt":1723153397839,"mc":[{"id":"1.231540814","rc":[{"batb":[[0,2.36,10]],"ltp":2.4,"tv":0.21,"id":31374}]}]}
{"op":"mcm","clk":"11798582970","pt":1723153401327,"mc":[{"id":"1.231540814","rc":[{"batb":[[0,2.3,4]],"ltp":2.4,"tv":0.21,"id":31374}]}]}
{"op":"mcm","clk":"11798583042","pt":1723153403655,"mc":[{"id":"1.231540814","rc":[{"batb":[[0,2.28,29.61],[1,2.02,4.55],[2,1.8,2]],"ltp":2.4,"tv":0.21,"id":31374}]}]}
{"op":"mcm","clk":"11798583049","pt":1723153403760,"mc":[{"id":"1.231540814","rc":[{"batb":[[0,2.32,10],[1,2.28,29.61],[2,2.02,4.55]],"ltp":2.4,"tv":0.21,"id":31374}]}]}
{"op":"mcm","clk":"11798583164","pt":1723153407247,"mc":[{"id":"1.231540814","rc":[{"batb":[[0,2.3,4]],"ltp":2.4,"tv":0.21,"id":31374}]}]}
{"op":"mcm","clk":"11798583225","pt":1723153409557,"mc":[{"id":"1.231540814","rc":[{"batb":[[0,2.3,10]],"ltp":2.4,"tv":0.21,"id":31374}]}]}
{"op":"mcm","clk":"11798583320","pt":1723153413253,"mc":[{"id":"1.231540814","rc":[{"batb":[[0,2.3,4]],"ltp":2.4,"tv":0.21,"id":31374}]}]}
{"op":"mcm","clk":"11798583371","pt":1723153415659,"mc":[{"id":"1.231540814","rc":[{"batb":[[0,2.3,10]],"ltp":2.4,"tv":0.21,"id":31374}]}]}
{"op":"mcm","clk":"11798583483","pt":1723153419254,"mc":[{"id":"1.231540814","rc":[{"batb":[[0,2.3,4]],"ltp":2.4,"tv":0.21,"id":31374}]}]}
{"op":"mcm","clk":"11798583545","pt":1723153421608,"mc":[{"id":"1.231540814","rc":[{"batb":[[0,2.28,29.61],[1,2.02,4.55],[2,1.8,2]],"ltp":2.4,"tv":0.21,"id":31374}]}]}
{"op":"mcm","clk":"11798583550","pt":1723153421763,"mc":[{"id":"1.231540814","rc":[{"batb":[[0,2.3,10],[1,2.28,29.61],[2,2.02,4.55]],"ltp":2.4,"tv":0.21,"id":31374}]}]}
{"op":"mcm","clk":"11798583627","pt":1723153424377,"mc":[{"id":"1.231540814","rc":[{"batb":[[0,2.32,4],[1,2.3,10],[2,2.28,29.61]],"ltp":2.4,"tv":0.21,"id":31374}]}]}
{"op":"mcm","clk":"11798583660","pt":1723153425043,"mc":[{"id":"1.231540814","rc":[{"batb":[[1,2.28,29.61],[2,2.02,4.55]],"ltp":2.4,"tv":0.21,"id":31374}]}]}
{"op":"mcm","clk":"11798583698","pt":1723153426733,"mc":[{"id":"1.231540814","rc":[{"batb":[[0,2.28,29.61],[1,2.02,4.55],[2,1.8,2]],"ltp":2.4,"tv":0.21,"id":31374}]}]}
{"op":"mcm","clk":"11798583737","pt":1723153427963,"mc":[{"id":"1.231540814","rc":[{"batb":[[0,2.3,10],[1,2.28,29.61],[2,2.02,4.55]],"ltp":2.4,"tv":0.21,"id":31374}]}]}
{"op":"mcm","clk":"11798583781","pt":1723153429145,"mc":[{"id":"1.231540814","rc":[{"batb":[[0,2.32,4],[1,2.3,10],[2,2.28,29.61]],"ltp":2.4,"tv":0.21,"id":31374}]}]}
{"op":"mcm","clk":"11798583876","pt":1723153431451,"mc":[{"id":"1.231540814","rc":[{"batb":[[0,2.28,29.61],[1,2.02,4.55],[2,1.8,2]],"ltp":2.4,"tv":0.21,"id":31374}]}]}
{"op":"mcm","clk":"11798583974","pt":1723153433858,"mc":[{"id":"1.231540814","rc":[{"batb":[[0,2.3,14],[1,2.28,29.61],[2,2.02,4.55]],"ltp":2.4,"tv":0.21,"id":31374}]}]}
{"op":"mcm","clk":"11798584037","pt":1723153436265,"mc":[{"id":"1.231540814","rc":[{"batb":[[0,2.3,10]],"ltp":2.4,"tv":0.21,"id":31374}]}]}
{"op":"mcm","clk":"11798584072","pt":1723153437297,"mc":[{"id":"1.231540814","rc":[{"batb":[[0,2.28,29.61],[1,2.02,4.55],[2,1.8,2]],"ltp":2.4,"tv":0.21,"id":31374}]}]}
{"op":"mcm","clk":"11798584203","pt":1723153440069,"mc":[{"id":"1.231540814","rc":[{"batb":[[0,2.3,14],[1,2.28,29.61],[2,2.02,4.55]],"ltp":2.4,"tv":0.21,"id":31374}]}]}
{"op":"mcm","clk":"11798584283","pt":1723153442477,"mc":[{"id":"1.231540814","rc":[{"batb":[[0,2.3,10]],"ltp":2.4,"tv":0.21,"id":31374}]}]}
{"op":"mcm","clk":"11798584329","pt":1723153443453,"mc":[{"id":"1.231540814","rc":[{"batb":[[0,2.28,29.61],[1,2.02,4.55],[2,1.8,2]],"ltp":2.4,"tv":0.21,"id":31374}]}]}
{"op":"mcm","clk":"11798584405","pt":1723153445399,"mc":[{"id":"1.231540814","rc":[{"batb":[[0,2.3,4],[1,2.28,29.61],[2,2.02,4.55]],"ltp":2.4,"tv":0.21,"id":31374}]}]}
{"op":"mcm","clk":"11798584460","pt":1723153446678,"mc":[{"id":"1.231540814","rc":[{"batb":[[0,2.32,10],[1,2.3,4],[2,2.28,29.61]],"ltp":2.4,"tv":0.21,"id":31374}]}]}
{"op":"mcm","clk":"11798584489","pt":1723153447701,"mc":[{"id":"1.231540814","rc":[{"batb":[[1,2.28,29.61],[2,2.02,4.55]],"ltp":2.4,"tv":0.21,"id":31374}]}]}
{"op":"mcm","clk":"11798584494","pt":1723153447803,"mc":[{"id":"1.231540814","rc":[{"batb":[[0,2.32,14.41]],"ltp":2.4,"tv":0.21,"id":31374}]}]}
{"op":"mcm","clk":"11798584580","pt":1723153450114,"mc":[{"id":"1.231540814","rc":[{"batb":[[0,2.34,4],[1,2.32,4.41],[2,2.28,29.61]],"ltp":2.4,"tv":0.21,"id":31374}]}]}
{"op":"mcm","clk":"11798584663","pt":1723153452368,"mc":[{"id":"1.231540814","rc":[{"batb":[[0,2.36,10]],"ltp":2.4,"tv":0.21,"id":31374}]}]}
{"op":"mcm","clk":"11798584683","pt":1723153453033,"mc":[{"id":"1.231540814","rc":[{"batb":[[1,2.28,29.61],[2,2.02,4.55]],"ltp":2.4,"tv":0.21,"id":31374}]}]}
{"op":"mcm","clk":"11798584771","pt":1723153455900,"mc":[{"id":"1.231540814","rc":[{"batb":[[0,2.3,4]],"ltp":2.4,"tv":0.21,"id":31374}]}]}
{"op":"mcm","clk":"11798584868","pt":1723153458314,"mc":[{"id":"1.231540814","rc":[{"batb":[[0,2.3,10]],"ltp":2.4,"tv":0.21,"id":31374}]}]}
{"op":"mcm","clk":"11798585003","pt":1723153461596,"mc":[{"id":"1.231540814","rc":[{"batb":[[0,2.32,4]],"ltp":2.4,"tv":0.21,"id":31374}]}]}
{"op":"mcm","clk":"11798585119","pt":1723153464109,"mc":[{"id":"1.231540814","rc":[{"batb":[[0,2.34,10]],"ltp":2.4,"tv":0.21,"id":31374}]}]}
{"op":"mcm","clk":"11798585256","pt":1723153467389,"mc":[{"id":"1.231540814","rc":[{"batb":[[0,2.3,4]],"ltp":2.4,"tv":0.21,"id":31374}]}]}
{"op":"mcm","clk":"11798585328","pt":1723153469697,"mc":[{"id":"1.231540814","rc":[{"batb":[[0,2.28,29.61],[1,2.02,4.55],[2,1.8,2]],"ltp":2.4,"tv":0.21,"id":31374}]}]}
{"op":"mcm","clk":"11798585332","pt":1723153469799,"mc":[{"id":"1.231540814","rc":[{"batb":[[0,2.3,10],[1,2.28,29.61],[2,2.02,4.55]],"ltp":2.4,"tv":0.21,"id":31374}]}]}
{"op":"mcm","clk":"11798585451","pt":1723153473026,"mc":[{"id":"1.231540814","rc":[{"batb":[[0,2.32,4]],"ltp":2.4,"tv":0.21,"id":31374}]}]}
{"op":"mcm","clk":"11798585527","pt":1723153475494,"mc":[{"id":"1.231540814","rc":[{"batb":[[0,2.3,10]],"ltp":2.4,"tv":0.21,"id":31374}]}]}
{"op":"mcm","clk":"11798585594","pt":1723153477600,"mc":[{"id":"1.231540814","rc":[{"batb":[[0,2.32,4],[1,2.3,10],[2,2.28,29.61]],"ltp":2.4,"tv":0.21,"id":31374}]}]}
{"op":"mcm","clk":"11798585633","pt":1723153478827,"mc":[{"id":"1.231540814","rc":[{"batb":[[1,2.28,29.61],[2,2.02,4.55]],"ltp":2.4,"tv":0.21,"id":31374}]}]}
{"op":"mcm","clk":"11798585678","pt":1723153480009,"mc":[{"id":"1.231540814","rc":[{"batb":[[0,2.28,29.61],[1,2.02,4.55],[2,1.8,2]],"ltp":2.4,"tv":0.21,"id":31374}]}]}
{"op":"mcm","clk":"11798585840","pt":1723153484521,"mc":[{"id":"1.231540814","rc":[{"batb":[[0,2.3,14],[1,2.28,29.61],[2,2.02,4.55]],"ltp":2.4,"tv":0.21,"id":31374}]}]}
{"op":"mcm","clk":"11798585924","pt":1723153486729,"mc":[{"id":"1.231540814","rc":[{"batb":[[0,2.3,10]],"ltp":2.4,"tv":0.21,"id":31374}]}]}
{"op":"mcm","clk":"11798585963","pt":1723153487804,"mc":[{"id":"1.231540814","rc":[{"batb":[[0,2.28,29.61],[1,2.02,4.55],[2,1.8,2]],"ltp":2.4,"tv":0.21,"id":31374}]}]}
{"op":"mcm","clk":"11798586061","pt":1723153490724,"mc":[{"id":"1.231540814","rc":[{"batb":[[0,2.3,14],[1,2.28,29.61],[2,2.02,4.55]],"ltp":2.4,"tv":0.21,"id":31374}]}]}
{"op":"mcm","clk":"11798586148","pt":1723153493137,"mc":[{"id":"1.231540814","rc":[{"batb":[[0,2.3,10]],"ltp":2.4,"tv":0.21,"id":31374}]}]}
{"op":"mcm","clk":"11798586181","pt":1723153494111,"mc":[{"id":"1.231540814","rc":[{"batb":[[0,2.28,29.61],[1,2.02,4.55],[2,1.8,2]],"ltp":2.4,"tv":0.21,"id":31374}]}]}
{"op":"mcm","clk":"11798586350","pt":1723153498724,"mc":[{"id":"1.231540814","rc":[{"batb":[[0,2.3,14],[1,2.28,29.61],[2,2.02,4.55]],"ltp":2.4,"tv":0.21,"id":31374}]}]}
{"op":"mcm","clk":"11798586427","pt":1723153500928,"mc":[{"id":"1.231540814","rc":[{"batb":[[0,2.3,10]],"ltp":2.4,"tv":0.21,"id":31374}]}]}
{"op":"mcm","clk":"11798586478","pt":1723153502159,"mc":[{"id":"1.231540814","rc":[{"batb":[[0,2.28,29.61],[1,2.02,4.55],[2,1.8,2]],"ltp":2.4,"tv":0.21,"id":31374}]}]}
{"op":"mcm","clk":"11798586542","pt":1723153503546,"mc":[{"id":"1.231540814","rc":[{"batb":[[0,2.3,4],[1,2.28,29.61],[2,2.02,4.55]],"ltp":2.4,"tv":0.21,"id":31374}]}]}
{"op":"mcm","clk":"11798586588","pt":1723153504624,"mc":[{"id":"1.231540814","rc":[{"batb":[[0,2.32,10],[1,2.3,4],[2,2.28,29.61]],"ltp":2.4,"tv":0.21,"id":31374}]}]}
{"op":"mcm","clk":"11798586631","pt":1723153505650,"mc":[{"id":"1.231540814","rc":[{"batb":[[1,2.28,29.61],[2,2.02,4.55]],"ltp":2.4,"tv":0.21,"id":31374}]}]}
{"op":"mcm","clk":"11798586722","pt":1723153508162,"mc":[{"id":"1.231540814","rc":[{"batb":[[0,2.3,4]],"ltp":2.4,"tv":0.21,"id":31374}]}]}
{"op":"mcm","clk":"11798586812","pt":1723153510525,"mc":[{"id":"1.231540814","rc":[{"batb":[[0,2.3,10]],"ltp":2.4,"tv":0.21,"id":31374}]}]}
{"op":"mcm","clk":"11798586924","pt":1723153514055,"mc":[{"id":"1.231540814","rc":[{"batb":[[0,2.3,4]],"ltp":2.4,"tv":0.21,"id":31374}]}]}
{"op":"mcm","clk":"11798587002","pt":1723153516459,"mc":[{"id":"1.231540814","rc":[{"batb":[[0,2.3,10]],"ltp":2.4,"tv":0.21,"id":31374}]}]}
{"op":"mcm","clk":"11798587148","pt":1723153520045,"mc":[{"id":"1.231540814","rc":[{"batb":[[0,2.3,4]],"ltp":2.4,"tv":0.21,"id":31374}]}]}
{"op":"mcm","clk":"11798587255","pt":1723153522469,"mc":[{"id":"1.231540814","rc":[{"batb":[[0,2.3,10]],"ltp":2.4,"tv":0.21,"id":31374}]}]}
{"op":"mcm","clk":"11798587381","pt":1723153525953,"mc":[{"id":"1.231540814","rc":[{"batb":[[0,2.3,4]],"ltp":2.4,"tv":0.21,"id":31374}]}]}
{"op":"mcm","clk":"11798587482","pt":1723153528464,"mc":[{"id":"1.231540814","rc":[{"batb":[[0,2.3,10]],"ltp":2.4,"tv":0.21,"id":31374}]}]}
{"op":"mcm","clk":"11798587605","pt":1723153531689,"mc":[{"id":"1.231540814","rc":[{"batb":[[0,2.28,29.61],[1,2.02,4.55],[2,1.8,2]],"ltp":2.4,"tv":0.21,"id":31374}]}]}
{"op":"mcm","clk":"11798587609","pt":1723153531791,"mc":[{"id":"1.231540814","rc":[{"batb":[[0,2.3,4],[1,2.28,29.61],[2,2.02,4.55]],"ltp":2.4,"tv":0.21,"id":31374}]}]}
{"op":"mcm","clk":"11798587692","pt":1723153534147,"mc":[{"id":"1.231540814","rc":[{"batb":[[0,2.3,10]],"ltp":2.4,"tv":0.21,"id":31374}]}]}
{"op":"mcm","clk":"11798587794","pt":1723153537582,"mc":[{"id":"1.231540814","rc":[{"batb":[[0,2.32,4]],"ltp":2.4,"tv":0.21,"id":31374}]}]}
{"op":"mcm","clk":"11798587884","pt":1723153539991,"mc":[{"id":"1.231540814","rc":[{"batb":[[0,2.3,10]],"ltp":2.4,"tv":0.21,"id":31374}]}]}
{"op":"mcm","clk":"11798587960","pt":1723153542197,"mc":[{"id":"1.231540814","rc":[{"batb":[[0,2.32,4],[1,2.3,10],[2,2.28,29.61]],"ltp":2.4,"tv":0.21,"id":31374}]}]}
{"op":"mcm","clk":"11798588002","pt":1723153543272,"mc":[{"id":"1.231540814","rc":[{"batb":[[1,2.28,29.61],[2,2.02,4.55]],"ltp":2.4,"tv":0.21,"id":31374}]}]}
{"op":"mcm","clk":"11798588051","pt":1723153544457,"mc":[{"id":"1.231540814","rc":[{"batb":[[0,2.28,29.61],[1,2.02,4.55],[2,1.8,2]],"ltp":2.4,"tv":0.21,"id":31374}]}]}
{"op":"mcm","clk":"11798588099","pt":1723153545688,"mc":[{"id":"1.231540814","rc":[{"batb":[[0,2.3,10],[1,2.28,29.61],[2,2.02,4.55]],"ltp":2.4,"tv":0.21,"id":31374}]}]}
{"op":"mcm","clk":"11798588153","pt":1723153546866,"mc":[{"id":"1.231540814","rc":[{"batb":[[0,2.32,4],[1,2.3,10],[2,2.28,29.61]],"ltp":2.4,"tv":0.21,"id":31374}]}]}
{"op":"mcm","clk":"11798588240","pt":1723153549477,"mc":[{"id":"1.231540814","rc":[{"batb":[[0,2.28,29.61],[1,2.02,4.55],[2,1.8,2]],"ltp":2.4,"tv":0.21,"id":31374}]}]}
{"op":"mcm","clk":"11798588324","pt":1723153551894,"mc":[{"id":"1.231540814","rc":[{"batb":[[0,2.3,14],[1,2.28,29.61],[2,2.02,4.55]],"ltp":2.4,"tv":0.21,"id":31374}]}]}
{"op":"mcm","clk":"11798588387","pt":1723153554206,"mc":[{"id":"1.231540814","rc":[{"batb":[[0,2.3,10]],"ltp":2.4,"tv":0.21,"id":31374}]}]}
{"op":"mcm","clk":"11798588426","pt":1723153555085,"mc":[{"id":"1.231540814","rc":[{"batb":[[0,2.28,29.61],[1,2.02,4.55],[2,1.8,2]],"ltp":2.4,"tv":0.21,"id":31374}]}]}
{"op":"mcm","clk":"11798588516","pt":1723153557597,"mc":[{"id":"1.231540814","rc":[{"batb":[[0,2.3,14],[1,2.28,29.61],[2,2.02,4.55]],"ltp":2.4,"tv":0.21,"id":31374}]}]}
{"op":"mcm","clk":"11798588621","pt":1723153560015,"mc":[{"id":"1.231540814","rc":[{"batb":[[0,2.3,10]],"ltp":2.4,"tv":0.21,"id":31374}]}]}
{"op":"mcm","clk":"11798588668","pt":1723153560891,"mc":[{"id":"1.231540814","rc":[{"batb":[[0,2.28,29.61],[1,2.02,4.55],[2,1.8,2]],"ltp":2.4,"tv":0.21,"id":31374}]}]}
{"op":"mcm","clk":"11798588755","pt":1723153563206,"mc":[{"id":"1.231540814","rc":[{"batb":[[0,2.3,14],[1,2.28,29.61],[2,2.02,4.55]],"ltp":2.4,"tv":0.21,"id":31374}]}]}
{"op":"mcm","clk":"11798588871","pt":1723153565728,"mc":[{"id":"1.231540814","rc":[{"batb":[[0,2.3,10]],"ltp":2.4,"tv":0.21,"id":31374}]}]}
{"op":"mcm","clk":"11798588923","pt":1723153566500,"mc":[{"id":"1.231540814","rc":[{"batb":[[0,2.28,29.61],[1,2.02,4.55],[2,1.8,2]],"ltp":2.4,"tv":0.21,"id":31374}]}]}
{"op":"mcm","clk":"11798589004","pt":1723153567889,"mc":[{"id":"1.231540814","rc":[{"batb":[[0,2.3,4],[1,2.28,29.61],[2,2.02,4.55]],"ltp":2.4,"tv":0.21,"id":31374}]}]}
{"op":"mcm","clk":"11798589074","pt":1723153569225,"mc":[{"id":"1.231540814","rc":[{"batb":[[0,2.32,10],[1,2.3,4],[2,2.28,29.61]],"ltp":2.4,"tv":0.21,"id":31374}]}]}
{"op":"mcm","clk":"11798589120","pt":1723153570305,"mc":[{"id":"1.231540814","rc":[{"batb":[[1,2.28,29.61],[2,2.02,4.55]],"ltp":2.4,"tv":0.21,"id":31374}]}]}
{"op":"mcm","clk":"11798589236","pt":1723153572717,"mc":[{"id":"1.231540814","rc":[{"batb":[[0,2.3,4]],"ltp":2.4,"tv":0.21,"id":31374}]}]}
{"op":"mcm","clk":"11798589360","pt":1723153575040,"mc":[{"id":"1.231540814","rc":[{"batb":[[0,2.32,10]],"ltp":2.4,"tv":0.21,"id":31374}]}]}
{"op":"mcm","clk":"11798589572","pt":1723153578439,"mc":[{"id":"1.231540814","rc":[{"batb":[[0,2.3,4]],"ltp":2.4,"tv":0.21,"id":31374}]}]}
{"op":"mcm","clk":"11798589694","pt":1723153580714,"mc":[{"id":"1.231540814","rc":[{"batb":[[0,2.3,10]],"ltp":2.4,"tv":0.21,"id":31374}]}]}
{"op":"mcm","clk":"11798589812","pt":1723153583237,"mc":[{"id":"1.231540814","rc":[{"batb":[[0,2.32,8.71],[1,2.3,10],[2,2.28,29.61]],"ltp":2.4,"tv":0.21,"id":31374}]}]}
{"op":"mcm","clk":"11798589854","pt":1723153584010,"mc":[{"id":"1.231540814","rc":[{"batb":[[1,2.28,29.61],[2,2.02,4.55]],"ltp":2.4,"tv":0.21,"id":31374}]}]}
{"op":"mcm","clk":"11798589937","pt":1723153585356,"mc":[{"id":"1.231540814","rc":[{"batb":[[0,2.32,4.71]],"ltp":2.4,"tv":0.21,"id":31374}]}]}
{"op":"mcm","clk":"11798590095","pt":1723153587530,"mc":[{"id":"1.231540814","rc":[{"batb":[[0,2.34,14],[1,2.32,4.71],[2,2.28,29.61]],"ltp":2.4,"tv":0.21,"id":31374}]}]}
{"op":"mcm","clk":"11798590131","pt":1723153588042,"mc":[{"id":"1.231540814","rc":[{"batb":[[1,2.28,29.61],[2,2.02,4.55]],"ltp":2.4,"tv":0.21,"id":31374}]}]}
{"op":"mcm","clk":"11798590242","pt":1723153589856,"mc":[{"id":"1.231540814","rc":[{"batb":[[0,2.34,10]],"ltp":2.4,"tv":0.21,"id":31374}]}]}
{"op":"mcm","clk":"11798590304","pt":1723153590835,"mc":[{"id":"1.231540814","rc":[{"batb":[[0,2.28,29.61],[1,2.02,4.55],[2,1.8,2]],"ltp":2.4,"tv":0.21,"id":31374}]}]}
{"op":"mcm","clk":"11798590388","pt":1723153592119,"mc":[{"id":"1.231540814","rc":[{"batb":[[0,2.3,4],[1,2.28,29.61],[2,2.02,4.55]],"ltp":2.4,"tv":0.21,"id":31374}]}]}
{"op":"mcm","clk":"11798590542","pt":1723153594439,"mc":[{"id":"1.231540814","rc":[{"batb":[[0,2.32,10]],"ltp":2.4,"tv":0.21,"id":31374}]}]}
{"op":"mcm","clk":"11798590721","pt":1723153597928,"mc":[{"id":"1.231540814","rc":[{"batb":[[0,2.3,4]],"ltp":2.4,"tv":0.21,"id":31374}]}]}
{"op":"mcm","clk":"11798590821","pt":1723153600048,"mc":[{"id":"1.231540814","rc":[{"batb":[[0,2.32,10]],"ltp":2.4,"tv":0.21,"id":31374}]}]}
{"op":"mcm","clk":"11798590986","pt":1723153603340,"mc":[{"id":"1.231540814","rc":[{"batb":[[0,2.34,4]],"ltp":2.4,"tv":0.21,"id":31374}]}]}
{"op":"mcm","clk":"11798591084","pt":1723153605647,"mc":[{"id":"1.231540814","rc":[{"batb":[[0,2.28,29.61],[1,2.02,4.55],[2,1.8,2]],"ltp":2.4,"tv":0.21,"id":31374}]}]}
{"op":"mcm","clk":"11798591089","pt":1723153605748,"mc":[{"id":"1.231540814","rc":[{"batb":[[0,2.3,10],[1,2.28,29.61],[2,2.02,4.55]],"ltp":2.4,"tv":0.21,"id":31374}]}]}
{"op":"mcm","clk":"11798591189","pt":1723153608059,"mc":[{"id":"1.231540814","rc":[{"batb":[[0,2.32,4],[1,2.3,10],[2,2.28,29.61]],"ltp":2.4,"tv":0.21,"id":31374}]}]}
{"op":"mcm","clk":"11798591229","pt":1723153609083,"mc":[{"id":"1.231540814","rc":[{"batb":[[1,2.28,29.61],[2,2.02,4.55]],"ltp":2.4,"tv":0.21,"id":31374}]}]}
{"op":"mcm","clk":"11798591282","pt":1723153610372,"mc":[{"id":"1.231540814","rc":[{"batb":[[0,2.28,29.61],[1,2.02,4.55],[2,1.8,2]],"ltp":2.4,"tv":0.21,"id":31374}]}]}
{"op":"mcm","clk":"11798591339","pt":1723153611655,"mc":[{"id":"1.231540814","rc":[{"batb":[[0,2.3,10],[1,2.28,29.61],[2,2.02,4.55]],"ltp":2.4,"tv":0.21,"id":31374}]}]}
{"op":"mcm","clk":"11798591395","pt":1723153612937,"mc":[{"id":"1.231540814","rc":[{"batb":[[0,2.32,4],[1,2.3,10],[2,2.28,29.61]],"ltp":2.4,"tv":0.21,"id":31374}]}]}
{"op":"mcm","clk":"11798591491","pt":1723153615153,"mc":[{"id":"1.231540814","rc":[{"batb":[[0,2.28,29.61],[1,2.02,4.55],[2,1.8,2]],"ltp":2.4,"tv":0.21,"id":31374}]}]}
{"op":"mcm","clk":"11798591606","pt":1723153617569,"mc":[{"id":"1.231540814","rc":[{"batb":[[0,2.3,14],[1,2.28,29.61],[2,2.02,4.55]],"ltp":2.4,"tv":0.21,"id":31374}]}]}
{"op":"mcm","clk":"11798591707","pt":1723153619878,"mc":[{"id":"1.231540814","rc":[{"batb":[[0,2.3,10]],"ltp":2.4,"tv":0.21,"id":31374}]}]}
{"op":"mcm","clk":"11798591739","pt":1723153620850,"mc":[{"id":"1.231540814","rc":[{"batb":[[0,2.28,29.61],[1,2.02,4.55],[2,1.8,2]],"ltp":2.4,"tv":0.21,"id":31374}]}]}
{"op":"mcm","clk":"11798591891","pt":1723153624951,"mc":[{"id":"1.231540814","rc":[{"batb":[[0,2.3,14],[1,2.28,29.61],[2,2.02,4.55]],"ltp":2.4,"tv":0.21,"id":31374}]}]}
{"op":"mcm","clk":"11798591988","pt":1723153627360,"mc":[{"id":"1.231540814","rc":[{"batb":[[0,2.3,10]],"ltp":2.4,"tv":0.21,"id":31374}]}]}
{"op":"mcm","clk":"11798592031","pt":1723153628384,"mc":[{"id":"1.231540814","rc":[{"batb":[[0,2.28,29.61],[1,2.02,4.55],[2,1.8,2]],"ltp":2.4,"tv":0.21,"id":31374}]}]}
{"op":"mcm","clk":"11798592084","pt":1723153629667,"mc":[{"id":"1.231540814","rc":[{"batb":[[0,2.3,4],[1,2.28,29.61],[2,2.02,4.55]],"ltp":2.4,"tv":0.21,"id":31374}]}]}
{"op":"mcm","clk":"11798592132","pt":1723153630794,"mc":[{"id":"1.231540814","rc":[{"batb":[[0,2.32,10],[1,2.3,4],[2,2.28,29.61]],"ltp":2.4,"tv":0.21,"id":31374}]}]}
{"op":"mcm","clk":"11798592192","pt":1723153632075,"mc":[{"id":"1.231540814","rc":[{"batb":[[1,2.28,29.61],[2,2.02,4.55]],"ltp":2.4,"tv":0.21,"id":31374}]}]}
{"op":"mcm","clk":"11798592279","pt":1723153634282,"mc":[{"id":"1.231540814","rc":[{"batb":[[0,2.3,4]],"ltp":2.4,"tv":0.21,"id":31374}]}]}
{"op":"mcm","clk":"11798592380","pt":1723153636691,"mc":[{"id":"1.231540814","rc":[{"batb":[[0,2.3,10]],"ltp":2.4,"tv":0.21,"id":31374}]}]}
{"op":"mcm","clk":"11798592486","pt":1723153639104,"mc":[{"id":"1.231540814","rc":[{"batb":[[0,2.32,4],[1,2.3,10],[2,2.28,29.61]],"ltp":2.4,"tv":0.21,"id":31374}]}]}
{"op":"mcm","clk":"11798592529","pt":1723153639978,"mc":[{"id":"1.231540814","rc":[{"batb":[[1,2.28,29.61],[2,2.02,4.55]],"ltp":2.4,"tv":0.21,"id":31374}]}]}
{"op":"mcm","clk":"11798592601","pt":1723153641488,"mc":[{"id":"1.231540814","rc":[{"batb":[[0,2.28,29.61],[1,2.02,4.55],[2,1.8,2]],"ltp":2.4,"tv":0.21,"id":31374}]}]}
{"op":"mcm","clk":"11798592692","pt":1723153643801,"mc":[{"id":"1.231540814","rc":[{"batb":[[0,2.3,14],[1,2.28,29.61],[2,2.02,4.55]],"ltp":2.4,"tv":0.21,"id":31374}]}]}
{"op":"mcm","clk":"11798592779","pt":1723153646004,"mc":[{"id":"1.231540814","rc":[{"batb":[[0,2.3,10]],"ltp":2.4,"tv":0.21,"id":31374}]}]}
{"op":"mcm","clk":"11798592815","pt":1723153647188,"mc":[{"id":"1.231540814","rc":[{"batb":[[0,2.28,29.61],[1,2.02,4.55],[2,1.8,2]],"ltp":2.4,"tv":0.21,"id":31374}]}]}
{"op":"mcm","clk":"11798592960","pt":1723153650631,"mc":[{"id":"1.231540814","rc":[{"batb":[[0,2.3,14],[1,2.28,29.61],[2,2.02,4.55]],"ltp":2.4,"tv":0.21,"id":31374}]}]}
{"op":"mcm","clk":"11798593050","pt":1723153652937,"mc":[{"id":"1.231540814","rc":[{"batb":[[0,2.3,10]],"ltp":2.4,"tv":0.21,"id":31374}]}]}
{"op":"mcm","clk":"11798593101","pt":1723153654017,"mc":[{"id":"1.231540814","rc":[{"batb":[[0,2.28,29.61],[1,2.02,4.55],[2,1.8,2]],"ltp":2.4,"tv":0.21,"id":31374}]}]}
{"op":"mcm","clk":"11798593152","pt":1723153655302,"mc":[{"id":"1.231540814","rc":[{"batb":[[0,2.3,4],[1,2.28,29.61],[2,2.02,4.55]],"ltp":2.4,"tv":0.21,"id":31374}]}]}
{"op":"mcm","clk":"11798593219","pt":1723153656635,"mc":[{"id":"1.231540814","rc":[{"batb":[[0,2.32,10],[1,2.3,4],[2,2.28,29.61]],"ltp":2.4,"tv":0.21,"id":31374}]}]}
{"op":"mcm","clk":"11798593256","pt":1723153657812,"mc":[{"id":"1.231540814","rc":[{"batb":[[1,2.28,29.61],[2,2.02,4.55]],"ltp":2.4,"tv":0.21,"id":31374}]}]}
{"op":"mcm","clk":"11798593324","pt":1723153659919,"mc":[{"id":"1.231540814","rc":[{"batb":[[0,2.3,4]],"ltp":2.4,"tv":0.21,"id":31374}]}]}
{"op":"mcm","clk":"11798593403","pt":1723153662330,"mc":[{"id":"1.231540814","rc":[{"batb":[[0,2.3,10]],"ltp":2.4,"tv":0.21,"id":31374}]}]}
{"op":"mcm","clk":"11798593542","pt":1723153665508,"mc":[{"id":"1.231540814","rc":[{"batb":[[0,2.32,4]],"ltp":2.4,"tv":0.21,"id":31374}]}]}
{"op":"mcm","clk":"11798593592","pt":1723153667044,"mc":[{"id":"1.231540814","rc":[{"batb":[[0,2.28,29.61],[1,2.02,4.55],[2,1.8,2]],"ltp":2.4,"tv":0.21,"id":31374}]}]}
{"op":"mcm","clk":"11798593639","pt":1723153668227,"mc":[{"id":"1.231540814","rc":[{"batb":[[0,2.3,10],[1,2.28,29.61],[2,2.02,4.55]],"ltp":2.4,"tv":0.21,"id":31374}]}]}
{"op":"mcm","clk":"11798593787","pt":1723153671512,"mc":[{"id":"1.231540814","rc":[{"batb":[[0,2.32,4]],"ltp":2.4,"tv":0.21,"id":31374}]}]}
{"op":"mcm","clk":"11798593877","pt":1723153674016,"mc":[{"id":"1.231540814","rc":[{"batb":[[0,2.3,10]],"ltp":2.4,"tv":0.21,"id":31374}]}]}
{"op":"mcm","clk":"11798593986","pt":1723153677558,"mc":[{"id":"1.231540814","rc":[{"batb":[[0,2.3,4]],"ltp":2.4,"tv":0.21,"id":31374}]}]}
{"op":"mcm","clk":"11798594087","pt":1723153679715,"mc":[{"id":"1.231540814","rc":[{"batb":[[0,2.32,10],[1,2.3,4],[2,2.28,29.61]],"ltp":2.4,"tv":0.21,"id":31374}]}]}
{"op":"mcm","clk":"11798594103","pt":1723153679923,"mc":[{"id":"1.231540814","rc":[{"batb":[[1,2.28,29.61],[2,2.02,4.55]],"ltp":2.4,"tv":0.21,"id":31374}]}]}
{"op":"mcm","clk":"11798594248","pt":1723153683154,"mc":[{"id":"1.231540814","rc":[{"batb":[[0,2.34,4]],"ltp":2.4,"tv":0.21,"id":31374}]}]}
{"op":"mcm","clk":"11798594323","pt":1723153685456,"mc":[{"id":"1.231540814","rc":[{"batb":[[0,2.3,10]],"ltp":2.4,"tv":0.21,"id":31374}]}]}
{"op":"mcm","clk":"11798594420","pt":1723153688737,"mc":[{"id":"1.231540814","rc":[{"batb":[[0,2.32,4]],"ltp":2.4,"tv":0.21,"id":31374}]}]}
{"op":"mcm","clk":"11798594501","pt":1723153691146,"mc":[{"id":"1.231540814","rc":[{"batb":[[0,2.3,10]],"ltp":2.4,"tv":0.21,"id":31374}]}]}
{"op":"mcm","clk":"11798594588","pt":1723153693556,"mc":[{"id":"1.231540814","rc":[{"batb":[[0,2.32,4],[1,2.3,10],[2,2.28,29.61]],"ltp":2.4,"tv":0.21,"id":31374}]}]}
{"op":"mcm","clk":"11798594627","pt":1723153694430,"mc":[{"id":"1.231540814","rc":[{"batb":[[1,2.28,29.61],[2,2.02,4.55]],"ltp":2.4,"tv":0.21,"id":31374}]}]}
{"op":"mcm","clk":"11798594702","pt":1723153695759,"mc":[{"id":"1.231540814","rc":[{"batb":[[0,2.28,29.61],[1,2.02,4.55],[2,1.8,2]],"ltp":2.4,"tv":0.21,"id":31374}]}]}
{"op":"mcm","clk":"11798594753","pt":1723153696940,"mc":[{"id":"1.231540814","rc":[{"batb":[[0,2.3,10],[1,2.28,29.61],[2,2.02,4.55]],"ltp":2.4,"tv":0.21,"id":31374}]}]}
{"op":"mcm","clk":"11798594810","pt":1723153698170,"mc":[{"id":"1.231540814","rc":[{"batb":[[0,2.32,4],[1,2.3,10],[2,2.28,29.61]],"ltp":2.4,"tv":0.21,"id":31374}]}]}
{"op":"mcm","clk":"11798594904","pt":1723153700635,"mc":[{"id":"1.231540814","rc":[{"batb":[[0,2.28,29.61],[1,2.02,4.55],[2,1.8,2]],"ltp":2.4,"tv":0.21,"id":31374}]}]}
{"op":"mcm","clk":"11798594978","pt":1723153702843,"mc":[{"id":"1.231540814","rc":[{"batb":[[0,2.3,14],[1,2.28,29.61],[2,2.02,4.55]],"ltp":2.4,"tv":0.21,"id":31374}]}]}
{"op":"mcm","clk":"11798595072","pt":1723153705278,"mc":[{"id":"1.231540814","rc":[{"batb":[[0,2.3,10]],"ltp":2.4,"tv":0.21,"id":31374}]}]}
{"op":"mcm","clk":"11798595109","pt":1723153706154,"mc":[{"id":"1.231540814","rc":[{"batb":[[0,2.28,29.61],[1,2.02,4.55],[2,1.8,2]],"ltp":2.4,"tv":0.21,"id":31374}]}]}
{"op":"mcm","clk":"11798595260","pt":1723153708676,"mc":[{"id":"1.231540814","rc":[{"batb":[[0,2.3,14],[1,2.28,29.61],[2,2.02,4.55]],"ltp":2.4,"tv":0.21,"id":31374}]}]}
{"op":"mcm","clk":"11798595365","pt":1723153710884,"mc":[{"id":"1.231540814","rc":[{"batb":[[0,2.3,10]],"ltp":2.4,"tv":0.21,"id":31374}]}]}
{"op":"mcm","clk":"11798595414","pt":1723153711860,"mc":[{"id":"1.231540814","rc":[{"batb":[[0,2.28,29.61],[1,2.02,4.55],[2,1.8,2]],"ltp":2.4,"tv":0.21,"id":31374}]}]}
{"op":"mcm","clk":"11798595487","pt":1723153713351,"mc":[{"id":"1.231540814","rc":[{"batb":[[0,2.3,4],[1,2.28,29.61],[2,2.02,4.55]],"ltp":2.4,"tv":0.21,"id":31374}]}]}
{"op":"mcm","clk":"11798595555","pt":1723153715658,"mc":[{"id":"1.231540814","rc":[{"batb":[[0,2.32,10],[1,2.3,4],[2,2.28,29.61]],"ltp":2.4,"tv":0.21,"id":31374}]}]}
{"op":"mcm","clk":"11798595561","pt":1723153715759,"mc":[{"id":"1.231540814","rc":[{"batb":[[1,2.28,29.61],[2,2.02,4.55]],"ltp":2.4,"tv":0.21,"id":31374}]}]}
{"op":"mcm","clk":"11798595653","pt":1723153717971,"mc":[{"id":"1.231540814","rc":[{"batb":[[0,2.34,4],[1,2.32,10],[2,2.28,29.61]],"ltp":2.4,"tv":0.21,"id":31374}]}]}
{"op":"mcm","clk":"11798595709","pt":1723153719102,"mc":[{"id":"1.231540814","rc":[{"batb":[[1,2.28,29.61],[2,2.02,4.55]],"ltp":2.4,"tv":0.21,"id":31374}]}]}
{"op":"mcm","clk":"11798595787","pt":1723153720485,"mc":[{"id":"1.231540814","rc":[{"batb":[[0,2.28,29.61],[1,2.02,4.55],[2,1.8,2]],"ltp":2.4,"tv":0.21,"id":31374}]}]}
{"op":"mcm","clk":"11798595845","pt":1723153721768,"mc":[{"id":"1.231540814","rc":[{"batb":[[0,2.3,10],[1,2.28,29.61],[2,2.02,4.55]],"ltp":2.4,"tv":0.21,"id":31374}]}]}
{"op":"mcm","clk":"11798595914","pt":1723153723252,"mc":[{"id":"1.231540814","rc":[{"batb":[[0,2.34,4],[1,2.32,4.71],[2,2.3,10]],"ltp":2.4,"tv":0.21,"id":31374}]}]}
{"op":"mcm","clk":"11798596001","pt":1723153725455,"mc":[{"id":"1.231540814","rc":[{"batb":[[0,2.32,4.71],[1,2.28,29.61],[2,2.02,4.55]],"ltp":2.4,"tv":0.21,"id":31374}]}]}
{"op":"mcm","clk":"11798596087","pt":1723153727860,"mc":[{"id":"1.231540814","rc":[{"batb":[[0,2.34,14],[1,2.32,4.71],[2,2.28,29.61]],"ltp":2.4,"tv":0.21,"id":31374}]}]}
{"op":"mcm","clk":"11798596145","pt":1723153729090,"mc":[{"id":"1.231540814","rc":[{"batb":[[1,2.28,29.61],[2,2.02,4.55]],"ltp":2.4,"tv":0.21,"id":31374}]}]}
{"op":"mcm","clk":"11798596179","pt":1723153730067,"mc":[{"id":"1.231540814","rc":[{"batb":[[0,2.34,10]],"ltp":2.4,"tv":0.21,"id":31374}]}]}
{"op":"mcm","clk":"11798596240","pt":1723153731200,"mc":[{"id":"1.231540814","rc":[{"batb":[[0,2.28,29.61],[1,2.02,4.55],[2,1.8,2]],"ltp":2.4,"tv":0.21,"id":31374}]}]}
{"op":"mcm","clk":"11798596297","pt":1723153732486,"mc":[{"id":"1.231540814","rc":[{"batb":[[0,2.3,4],[1,2.28,29.61],[2,2.02,4.55]],"ltp":2.4,"tv":0.21,"id":31374}]}]}
{"op":"mcm","clk":"11798596349","pt":1723153733665,"mc":[{"id":"1.231540814","rc":[{"batb":[[0,2.32,10],[1,2.3,4],[2,2.28,29.61]],"ltp":2.4,"tv":0.21,"id":31374}]}]}
{"op":"mcm","clk":"11798596384","pt":1723153734791,"mc":[{"id":"1.231540814","rc":[{"batb":[[1,2.28,29.61],[2,2.02,4.55]],"ltp":2.4,"tv":0.21,"id":31374}]}]}
{"op":"mcm","clk":"11798596477","pt":1723153737196,"mc":[{"id":"1.231540814","rc":[{"batb":[[0,2.3,4]],"ltp":2.4,"tv":0.21,"id":31374}]}]}
{"op":"mcm","clk":"11798596570","pt":1723153739612,"mc":[{"id":"1.231540814","rc":[{"batb":[[0,2.32,10]],"ltp":2.4,"tv":0.21,"id":31374}]}]}
{"op":"mcm","clk":"11798596702","pt":1723153742690,"mc":[{"id":"1.231540814","rc":[{"batb":[[0,2.3,4]],"ltp":2.4,"tv":0.21,"id":31374}]}]}
{"op":"mcm","clk":"11798596811","pt":1723153745106,"mc":[{"id":"1.231540814","rc":[{"batb":[[0,2.3,10]],"ltp":2.4,"tv":0.21,"id":31374}]}]}
{"op":"mcm","clk":"11798596912","pt":1723153747309,"mc":[{"id":"1.231540814","rc":[{"batb":[[0,2.32,4],[1,2.3,10],[2,2.28,29.61]],"ltp":2.4,"tv":0.21,"id":31374}]}]}
{"op":"mcm","clk":"11798596943","pt":1723153748230,"mc":[{"id":"1.231540814","rc":[{"batb":[[1,2.28,29.61],[2,2.02,4.55]],"ltp":2.4,"tv":0.21,"id":31374}]}]}
{"op":"mcm","clk":"11798596994","pt":1723153749611,"mc":[{"id":"1.231540814","rc":[{"batb":[[0,2.28,29.61],[1,2.02,4.55],[2,1.8,2]],"ltp":2.4,"tv":0.21,"id":31374}]}]}
{"op":"mcm","clk":"11798597092","pt":1723153751811,"mc":[{"id":"1.231540814","rc":[{"batb":[[0,2.3,14],[1,2.28,29.61],[2,2.02,4.55]],"ltp":2.4,"tv":0.21,"id":31374}]}]}
{"op":"mcm","clk":"11798597178","pt":1723153754014,"mc":[{"id":"1.231540814","rc":[{"batb":[[0,2.3,10]],"ltp":2.4,"tv":0.21,"id":31374}]}]}
{"op":"mcm","clk":"11798597223","pt":1723153755193,"mc":[{"id":"1.231540814","rc":[{"batb":[[0,2.28,29.61],[1,2.02,4.55],[2,1.8,2]],"ltp":2.4,"tv":0.21,"id":31374}]}]}
{"op":"mcm","clk":"11798597281","pt":1723153756423,"mc":[{"id":"1.231540814","rc":[{"batb":[[0,2.3,4],[1,2.28,29.61],[2,2.02,4.55]],"ltp":2.4,"tv":0.21,"id":31374}]}]}
{"op":"mcm","clk":"11798597330","pt":1723153757806,"mc":[{"id":"1.231540814","rc":[{"batb":[[0,2.32,10],[1,2.3,4],[2,2.28,29.61]],"ltp":2.4,"tv":0.21,"id":31374}]}]}
{"op":"mcm","clk":"11798597373","pt":1723153758828,"mc":[{"id":"1.231540814","rc":[{"batb":[[1,2.28,29.61],[2,2.02,4.55]],"ltp":2.4,"tv":0.21,"id":31374}]}]}
{"op":"mcm","clk":"11798597463","pt":1723153761345,"mc":[{"id":"1.231540814","rc":[{"batb":[[0,2.3,4]],"ltp":2.4,"tv":0.21,"id":31374}]}]}
{"op":"mcm","clk":"11798597566","pt":1723153763703,"mc":[{"id":"1.231540814","rc":[{"batb":[[0,2.3,10]],"ltp":2.4,"tv":0.21,"id":31374}]}]}
{"op":"mcm","clk":"11798597669","pt":1723153766010,"mc":[{"id":"1.231540814","rc":[{"batb":[[0,2.32,4],[1,2.3,10],[2,2.28,29.61]],"ltp":2.4,"tv":0.21,"id":31374}]}]}
{"op":"mcm","clk":"11798597707","pt":1723153767033,"mc":[{"id":"1.231540814","rc":[{"batb":[[1,2.28,29.61],[2,2.02,4.55]],"ltp":2.4,"tv":0.21,"id":31374}]}]}
{"op":"mcm","clk":"11798597770","pt":1723153768416,"mc":[{"id":"1.231540814","rc":[{"batb":[[0,2.28,29.61],[1,2.02,4.55],[2,1.8,2]],"ltp":2.4,"tv":0.21,"id":31374}]}]}
{"op":"mcm","clk":"11798597824","pt":1723153769745,"mc":[{"id":"1.231540814","rc":[{"batb":[[0,2.3,10],[1,2.28,29.61],[2,2.02,4.55]],"ltp":2.4,"tv":0.21,"id":31374}]}]}
{"op":"mcm","clk":"11798597922","pt":1723153771646,"mc":[{"id":"1.231540814","rc":[{"batb":[[0,2.32,4],[1,2.3,10],[2,2.28,29.61]],"ltp":2.4,"tv":0.21,"id":31374}]}]}
{"op":"mcm","clk":"11798597975","pt":1723153772931,"mc":[{"id":"1.231540814","rc":[{"batb":[[1,2.28,29.61],[2,2.02,4.55]],"ltp":2.4,"tv":0.21,"id":31374}]}]}
{"op":"mcm","clk":"11798598024","pt":1723153774006,"mc":[{"id":"1.231540814","rc":[{"batb":[[0,2.28,29.61],[1,2.02,4.55],[2,1.8,2]],"ltp":2.4,"tv":0.21,"id":31374}]}]}
{"op":"mcm","clk":"11798598063","pt":1723153775136,"mc":[{"id":"1.231540814","rc":[{"batb":[[0,2.3,10],[1,2.28,29.61],[2,2.02,4.55]],"ltp":2.4,"tv":0.21,"id":31374}]}]}
{"op":"mcm","clk":"11798598117","pt":1723153776214,"mc":[{"id":"1.231540814","rc":[{"batb":[[0,2.32,4],[1,2.3,10],[2,2.28,29.61]],"ltp":2.4,"tv":0.21,"id":31374}]}]}
{"op":"mcm","clk":"11798598238","pt":1723153778529,"mc":[{"id":"1.231540814","rc":[{"batb":[[0,2.28,29.61],[1,2.02,4.55],[2,1.8,2]],"ltp":2.4,"tv":0.21,"id":31374}]}]}
{"op":"mcm","clk":"11798598383","pt":1723153781924,"mc":[{"id":"1.231540814","rc":[{"batb":[[0,2.3,14],[1,2.28,29.61],[2,2.02,4.55]],"ltp":2.4,"tv":0.21,"id":31374}]}]}
{"op":"mcm","clk":"11798598461","pt":1723153784328,"mc":[{"id":"1.231540814","rc":[{"batb":[[0,2.3,10]],"ltp":2.4,"tv":0.21,"id":31374}]}]}
{"op":"mcm","clk":"11798598500","pt":1723153785353,"mc":[{"id":"1.231540814","rc":[{"batb":[[0,2.28,29.61],[1,2.02,4.55],[2,1.8,2]],"ltp":2.4,"tv":0.21,"id":31374}]}]}
{"op":"mcm","clk":"11798598551","pt":1723153786637,"mc":[{"id":"1.231540814","rc":[{"batb":[[0,2.3,4],[1,2.28,29.61],[2,2.02,4.55]],"ltp":2.4,"tv":0.21,"id":31374}]}]}
{"op":"mcm","clk":"11798598601","pt":1723153787865,"mc":[{"id":"1.231540814","rc":[{"batb":[[0,2.32,10],[1,2.3,4],[2,2.28,29.61]],"ltp":2.4,"tv":0.21,"id":31374}]}]}
{"op":"mcm","clk":"11798598655","pt":1723153788944,"mc":[{"id":"1.231540814","rc":[{"batb":[[1,2.28,29.61],[2,2.02,4.55]],"ltp":2.4,"tv":0.21,"id":31374}]}]}
{"op":"mcm","clk":"11798598763","pt":1723153791253,"mc":[{"id":"1.231540814","rc":[{"batb":[[0,2.3,4]],"ltp":2.4,"tv":0.21,"id":31374}]}]}
{"op":"mcm","clk":"11798598872","pt":1723153793469,"mc":[{"id":"1.231540814","rc":[{"batb":[[0,2.32,10]],"ltp":2.4,"tv":0.21,"id":31374}]}]}
{"op":"mcm","clk":"11798598952","pt":1723153795785,"mc":[{"id":"1.231540814","rc":[{"batb":[[0,2.34,4],[1,2.32,10],[2,2.28,29.61]],"ltp":2.4,"tv":0.21,"id":31374}]}]}
{"op":"mcm","clk":"11798599022","pt":1723153796870,"mc":[{"id":"1.231540814","rc":[{"batb":[[1,2.28,29.61],[2,2.02,4.55]],"ltp":2.4,"tv":0.21,"id":31374}]}]}
{"op":"mcm","clk":"11798599078","pt":1723153798153,"mc":[{"id":"1.231540814","rc":[{"batb":[[0,2.28,29.61],[1,2.02,4.55],[2,1.8,2]],"ltp":2.4,"tv":0.21,"id":31374}]}]}
{"op":"mcm","clk":"11798599203","pt":1723153801287,"mc":[{"id":"1.231540814","rc":[{"batb":[[0,2.3,14],[1,2.28,29.61],[2,2.02,4.55]],"ltp":2.4,"tv":0.21,"id":31374}]}]}
{"op":"mcm","clk":"11798599318","pt":1723153803550,"mc":[{"id":"1.231540814","rc":[{"batb":[[0,2.3,10]],"ltp":2.4,"tv":0.21,"id":31374}]}]}
{"op":"mcm","clk":"11798599359","pt":1723153804472,"mc":[{"id":"1.231540814","rc":[{"batb":[[0,2.28,29.61],[1,2.02,4.55],[2,1.8,2]],"ltp":2.4,"tv":0.21,"id":31374}]}]}
{"op":"mcm","clk":"11798599413","pt":1723153805866,"mc":[{"id":"1.231540814","rc":[{"batb":[[0,2.3,4],[1,2.28,29.61],[2,2.02,4.55]],"ltp":2.4,"tv":0.21,"id":31374}]}]}
{"op":"mcm","clk":"11798599466","pt":1723153807091,"mc":[{"id":"1.231540814","rc":[{"batb":[[0,2.32,10],[1,2.3,4],[2,2.28,29.61]],"ltp":2.4,"tv":0.21,"id":31374}]}]}
{"op":"mcm","clk":"11798599519","pt":1723153808279,"mc":[{"id":"1.231540814","rc":[{"batb":[[1,2.28,29.61],[2,2.02,4.55]],"ltp":2.4,"tv":0.21,"id":31374}]}]}
{"op":"mcm","clk":"11798599606","pt":1723153810395,"mc":[{"id":"1.231540814","rc":[{"batb":[[0,2.34,4]],"ltp":2.4,"tv":0.21,"id":31374}]}]}
{"op":"mcm","clk":"11798599693","pt":1723153812702,"mc":[{"id":"1.231540814","rc":[{"batb":[[0,2.28,29.61],[1,2.02,4.55],[2,1.8,2]],"ltp":2.4,"tv":0.21,"id":31374}]}]}
{"op":"mcm","clk":"11798599696","pt":1723153812804,"mc":[{"id":"1.231540814","rc":[{"batb":[[0,2.36,10],[1,2.28,29.61],[2,2.02,4.55]],"ltp":2.4,"tv":0.21,"id":31374}]}]}
{"op":"mcm","clk":"11798599858","pt":1723153816295,"mc":[{"id":"1.231540814","rc":[{"batb":[[0,2.3,4]],"ltp":2.4,"tv":0.21,"id":31374}]}]}
{"op":"mcm","clk":"11798599978","pt":1723153818605,"mc":[{"id":"1.231540814","rc":[{"batb":[[0,2.28,29.61],[1,2.02,4.55],[2,1.8,2]],"ltp":2.4,"tv":0.21,"id":31374}]}]}
{"op":"mcm","clk":"11798599987","pt":1723153818810,"mc":[{"id":"1.231540814","rc":[{"batb":[[0,2.3,10],[1,2.28,29.61],[2,2.02,4.55]],"ltp":2.4,"tv":0.21,"id":31374}]}]}
{"op":"mcm","clk":"11798600130","pt":1723153822092,"mc":[{"id":"1.231540814","rc":[{"batb":[[0,2.3,4]],"ltp":2.4,"tv":0.21,"id":31374}]}]}
{"op":"mcm","clk":"11798600222","pt":1723153824303,"mc":[{"id":"1.231540814","rc":[{"batb":[[0,2.32,10]],"ltp":2.4,"tv":0.21,"id":31374}]}]}
{"op":"mcm","clk":"11798600305","pt":1723153826705,"mc":[{"id":"1.231540814","rc":[{"batb":[[0,2.34,4],[1,2.32,10],[2,2.28,29.61]],"ltp":2.4,"tv":0.21,"id":31374}]}]}
{"op":"mcm","clk":"11798600334","pt":1723153827528,"mc":[{"id":"1.231540814","rc":[{"batb":[[1,2.28,29.61],[2,2.02,4.55]],"ltp":2.4,"tv":0.21,"id":31374}]}]}
{"op":"mcm","clk":"11798600410","pt":1723153829016,"mc":[{"id":"1.231540814","rc":[{"batb":[[0,2.28,29.61],[1,2.02,4.55],[2,1.8,2]],"ltp":2.4,"tv":0.21,"id":31374}]}]}
{"op":"mcm","clk":"11798600463","pt":1723153830199,"mc":[{"id":"1.231540814","rc":[{"batb":[[0,2.3,10],[1,2.28,29.61],[2,2.02,4.55]],"ltp":2.4,"tv":0.21,"id":31374}]}]}
{"op":"mcm","clk":"11798600509","pt":1723153831429,"mc":[{"id":"1.231540814","rc":[{"batb":[[0,2.32,4],[1,2.3,10],[2,2.28,29.61]],"ltp":2.4,"tv":0.21,"id":31374}]}]}
{"op":"mcm","clk":"11798600599","pt":1723153833630,"mc":[{"id":"1.231540814","rc":[{"batb":[[1,2.28,29.61],[2,2.02,4.55]],"ltp":2.4,"tv":0.21,"id":31374}]}]}
{"op":"mcm","clk":"11798600613","pt":1723153833834,"mc":[{"id":"1.231540814","rc":[{"batb":[[0,2.28,29.61],[1,2.02,4.55],[2,1.8,2]],"ltp":2.4,"tv":0.21,"id":31374}]}]}
{"op":"mcm","clk":"11798600728","pt":1723153836095,"mc":[{"id":"1.231540814","rc":[{"batb":[[0,2.32,4],[1,2.3,10],[2,2.28,29.61]],"ltp":2.4,"tv":0.21,"id":31374}]}]}
{"op":"mcm","clk":"11798600822","pt":1723153838402,"mc":[{"id":"1.231540814","rc":[{"batb":[[0,2.3,10],[1,2.28,29.61],[2,2.02,4.55]],"ltp":2.4,"tv":0.21,"id":31374}]}]}
{"op":"mcm","clk":"11798600864","pt":1723153839221,"mc":[{"id":"1.231540814","rc":[{"batb":[[0,2.28,29.61],[1,2.02,4.55],[2,1.8,2]],"ltp":2.4,"tv":0.21,"id":31374}]}]}
{"op":"mcm","clk":"11798600932","pt":1723153840609,"mc":[{"id":"1.231540814","rc":[{"batb":[[0,2.3,4],[1,2.28,29.61],[2,2.02,4.55]],"ltp":2.4,"tv":0.21,"id":31374}]}]}
{"op":"mcm","clk":"11798601034","pt":1723153843019,"mc":[{"id":"1.231540814","rc":[{"batb":[[0,2.32,10]],"ltp":2.4,"tv":0.21,"id":31374}]}]}
{"op":"mcm","clk":"11798601136","pt":1723153846244,"mc":[{"id":"1.231540814","rc":[{"batb":[[0,2.3,4]],"ltp":2.4,"tv":0.21,"id":31374}]}]}
{"op":"mcm","clk":"11798601236","pt":1723153848552,"mc":[{"id":"1.231540814","rc":[{"batb":[[0,2.3,10]],"ltp":2.4,"tv":0.21,"id":31374}]}]}
{"op":"mcm","clk":"11798601392","pt":1723153851942,"mc":[{"id":"1.231540814","rc":[{"batb":[[0,2.32,4]],"ltp":2.4,"tv":0.21,"id":31374}]}]}
{"op":"mcm","clk":"11798601482","pt":1723153854252,"mc":[{"id":"1.231540814","rc":[{"batb":[[0,2.3,10]],"ltp":2.4,"tv":0.21,"id":31374}]}]}
{"op":"mcm","clk":"11798601621","pt":1723153857635,"mc":[{"id":"1.231540814","rc":[{"batb":[[0,2.32,4]],"ltp":2.4,"tv":0.21,"id":31374}]}]}
{"op":"mcm","clk":"11798601698","pt":1723153859123,"mc":[{"id":"1.231540814","rc":[{"batb":[[0,2.28,29.61],[1,2.02,4.55],[2,1.8,2]],"ltp":2.4,"tv":0.21,"id":31374}]}]}
{"op":"mcm","clk":"11798601801","pt":1723153861434,"mc":[{"id":"1.231540814","rc":[{"batb":[[0,2.3,14],[1,2.28,29.61],[2,2.02,4.55]],"ltp":2.4,"tv":0.21,"id":31374}]}]}
{"op":"mcm","clk":"11798601857","pt":1723153862664,"mc":[{"id":"1.231540814","rc":[{"batb":[[0,2.32,4.91],[1,2.3,14],[2,2.28,29.61]],"ltp":2.4,"tv":0.21,"id":31374}]}]}
{"op":"mcm","clk":"11798601967","pt":1723153864721,"mc":[{"id":"1.231540814","rc":[{"batb":[[1,2.28,29.61],[2,2.02,4.55]],"ltp":2.4,"tv":0.21,"id":31374}]}]}
{"op":"mcm","clk":"11798602011","pt":1723153865950,"mc":[{"id":"1.231540814","rc":[{"batb":[[0,2.34,4],[1,2.32,4.91],[2,2.28,29.61]],"ltp":2.4,"tv":0.21,"id":31374}]}]}
{"op":"mcm","clk":"11798602077","pt":1723153867234,"mc":[{"id":"1.231540814","rc":[{"batb":[[0,2.36,10],[1,2.34,4],[2,2.32,4.91]],"ltp":2.4,"tv":0.21,"id":31374}]}]}
{"op":"mcm","clk":"11798602147","pt":1723153868365,"mc":[{"id":"1.231540814","rc":[{"batb":[[1,2.32,4.91],[2,2.28,29.61]],"ltp":2.4,"tv":0.21,"id":31374}]}]}
{"op":"mcm","clk":"11798602233","pt":1723153870666,"mc":[{"id":"1.231540814","rc":[{"batb":[[0,2.3,4],[1,2.28,29.61],[2,2.02,4.55]],"ltp":2.4,"tv":0.21,"id":31374}]}]}
{"op":"mcm","clk":"11798602331","pt":1723153873078,"mc":[{"id":"1.231540814","rc":[{"batb":[[0,2.3,10]],"ltp":2.4,"tv":0.21,"id":31374}]}]}
{"op":"mcm","clk":"11798602417","pt":1723153875447,"mc":[{"id":"1.231540814","rc":[{"batb":[[0,2.32,4],[1,2.3,10],[2,2.28,29.61]],"ltp":2.4,"tv":0.21,"id":31374}]}]}
{"op":"mcm","clk":"11798602462","pt":1723153876468,"mc":[{"id":"1.231540814","rc":[{"batb":[[1,2.28,29.61],[2,2.02,4.55]],"ltp":2.4,"tv":0.21,"id":31374}]}]}
{"op":"mcm","clk":"11798602507","pt":1723153877752,"mc":[{"id":"1.231540814","rc":[{"batb":[[0,2.28,29.61],[1,2.02,4.55],[2,1.8,2]],"ltp":2.4,"tv":0.21,"id":31374}]}]}
{"op":"mcm","clk":"11798602665","pt":1723153881080,"mc":[{"id":"1.231540814","rc":[{"batb":[[0,2.3,14],[1,2.28,29.61],[2,2.02,4.55]],"ltp":2.4,"tv":0.21,"id":31374}]}]}
{"op":"mcm","clk":"11798602780","pt":1723153883490,"mc":[{"id":"1.231540814","rc":[{"batb":[[0,2.3,10]],"ltp":2.4,"tv":0.21,"id":31374}]}]}
{"op":"mcm","clk":"11798602823","pt":1723153884569,"mc":[{"id":"1.231540814","rc":[{"batb":[[0,2.28,29.61],[1,2.02,4.55],[2,1.8,2]],"ltp":2.4,"tv":0.21,"id":31374}]}]}
{"op":"mcm","clk":"11798602876","pt":1723153885960,"mc":[{"id":"1.231540814","rc":[{"batb":[[0,2.3,4],[1,2.28,29.61],[2,2.02,4.55]],"ltp":2.4,"tv":0.21,"id":31374}]}]}
{"op":"mcm","clk":"11798602918","pt":1723153887085,"mc":[{"id":"1.231540814","rc":[{"batb":[[0,2.32,10],[1,2.3,4],[2,2.28,29.61]],"ltp":2.4,"tv":0.21,"id":31374}]}]}
{"op":"mcm","clk":"11798602976","pt":1723153888369,"mc":[{"id":"1.231540814","rc":[{"batb":[[1,2.28,29.61],[2,2.02,4.55]],"ltp":2.4,"tv":0.21,"id":31374}]}]}
{"op":"mcm","clk":"11798603050","pt":1723153890317,"mc":[{"id":"1.231540814","rc":[{"batb":[[0,2.28,29.61],[1,2.02,4.55],[2,1.8,2]],"ltp":2.4,"tv":0.21,"id":31374}]}]}
{"op":"mcm","clk":"11798603113","pt":1723153891926,"mc":[{"id":"1.231540814","rc":[{"batb":[[0,2.3,4],[1,2.28,29.61],[2,2.02,4.55]],"ltp":2.4,"tv":0.21,"id":31374}]}]}
{"op":"mcm","clk":"11798603226","pt":1723153894336,"mc":[{"id":"1.231540814","rc":[{"batb":[[0,2.32,10]],"ltp":2.4,"tv":0.21,"id":31374}]}]}
{"op":"mcm","clk":"11798603343","pt":1723153897722,"mc":[{"id":"1.231540814","rc":[{"batb":[[0,2.34,4]],"ltp":2.4,"tv":0.21,"id":31374}]}]}
{"op":"mcm","clk":"11798603385","pt":1723153899154,"mc":[{"id":"1.231540814","rc":[{"batb":[[0,2.28,29.61],[1,2.02,4.55],[2,1.8,2]],"ltp":2.4,"tv":0.21,"id":31374}]}]}
{"op":"mcm","clk":"11798603424","pt":1723153900334,"mc":[{"id":"1.231540814","rc":[{"batb":[[0,2.3,10],[1,2.28,29.61],[2,2.02,4.55]],"ltp":2.4,"tv":0.21,"id":31374}]}]}
{"op":"mcm","clk":"11798603461","pt":1723153901512,"mc":[{"id":"1.231540814","rc":[{"batb":[[0,2.32,4],[1,2.3,10],[2,2.28,29.61]],"ltp":2.4,"tv":0.21,"id":31374}]}]}
{"op":"mcm","clk":"11798603552","pt":1723153903617,"mc":[{"id":"1.231540814","rc":[{"batb":[[1,2.28,29.61],[2,2.02,4.55]],"ltp":2.4,"tv":0.21,"id":31374}]}]}
{"op":"mcm","clk":"11798603562","pt":1723153903826,"mc":[{"id":"1.231540814","rc":[{"batb":[[0,2.28,29.61],[1,2.02,4.55],[2,1.8,2]],"ltp":2.4,"tv":0.21,"id":31374}]}]}
{"op":"mcm","clk":"11798603633","pt":1723153906136,"mc":[{"id":"1.231540814","rc":[{"batb":[[0,2.3,14],[1,2.28,29.61],[2,2.02,4.55]],"ltp":2.4,"tv":0.21,"id":31374}]}]}
{"op":"mcm","clk":"11798603721","pt":1723153908646,"mc":[{"id":"1.231540814","rc":[{"batb":[[0,2.3,10]],"ltp":2.4,"tv":0.21,"id":31374}]}]}
{"op":"mcm","clk":"11798603747","pt":1723153909364,"mc":[{"id":"1.231540814","rc":[{"batb":[[0,2.28,29.61],[1,2.02,4.55],[2,1.8,2]],"ltp":2.4,"tv":0.21,"id":31374}]}]}
{"op":"mcm","clk":"11798603803","pt":1723153910962,"mc":[{"id":"1.231540814","rc":[{"batb":[[0,2.3,4],[1,2.28,29.61],[2,2.02,4.55]],"ltp":2.4,"tv":0.21,"id":31374}]}]}
{"op":"mcm","clk":"11798603880","pt":1723153913467,"mc":[{"id":"1.231540814","rc":[{"batb":[[0,2.32,10]],"ltp":2.4,"tv":0.21,"id":31374}]}]}
{"op":"mcm","clk":"11798603986","pt":1723153916646,"mc":[{"id":"1.231540814","rc":[{"batb":[[0,2.34,4]],"ltp":2.4,"tv":0.21,"id":31374}]}]}
{"op":"mcm","clk":"11798604063","pt":1723153919058,"mc":[{"id":"1.231540814","rc":[{"batb":[[0,2.3,10]],"ltp":2.4,"tv":0.21,"id":31374}]}]}
{"op":"mcm","clk":"11798604141","pt":1723153921166,"mc":[{"id":"1.231540814","rc":[{"batb":[[0,2.32,4],[1,2.3,10],[2,2.28,29.61]],"ltp":2.4,"tv":0.21,"id":31374}]}]}
{"op":"mcm","clk":"11798604180","pt":1723153922354,"mc":[{"id":"1.231540814","rc":[{"batb":[[1,2.28,29.61],[2,2.02,4.55]],"ltp":2.4,"tv":0.21,"id":31374}]}]}
{"op":"mcm","clk":"11798604240","pt":1723153923582,"mc":[{"id":"1.231540814","rc":[{"batb":[[0,2.28,29.61],[1,2.02,4.55],[2,1.8,2]],"ltp":2.4,"tv":0.21,"id":31374}]}]}
{"op":"mcm","clk":"11798604429","pt":1723153928257,"mc":[{"id":"1.231540814","rc":[{"batb":[[0,2.3,14],[1,2.28,29.61],[2,2.02,4.55]],"ltp":2.4,"tv":0.21,"id":31374}]}]}
{"op":"mcm","clk":"11798604507","pt":1723153930871,"mc":[{"id":"1.231540814","rc":[{"batb":[[0,2.3,10]],"ltp":2.4,"tv":0.21,"id":31374}]}]}
{"op":"mcm","clk":"11798604530","pt":1723153931793,"mc":[{"id":"1.231540814","rc":[{"batb":[[0,2.28,29.61],[1,2.02,4.55],[2,1.8,2]],"ltp":2.4,"tv":0.21,"id":31374}]}]}
{"op":"mcm","clk":"11798604589","pt":1723153933947,"mc":[{"id":"1.231540814","rc":[{"batb":[[0,2.3,14],[1,2.28,29.61],[2,2.02,4.55]],"ltp":2.4,"tv":0.21,"id":31374}]}]}
{"op":"mcm","clk":"11798604676","pt":1723153936352,"mc":[{"id":"1.231540814","rc":[{"batb":[[0,2.3,10]],"ltp":2.4,"tv":0.21,"id":31374}]}]}
{"op":"mcm","clk":"11798604707","pt":1723153937272,"mc":[{"id":"1.231540814","rc":[{"batb":[[0,2.28,29.61],[1,2.02,4.55],[2,1.8,2]],"ltp":2.4,"tv":0.21,"id":31374}]}]}
{"op":"mcm","clk":"11798604766","pt":1723153938656,"mc":[{"id":"1.231540814","rc":[{"batb":[[0,2.3,4],[1,2.28,29.61],[2,2.02,4.55]],"ltp":2.4,"tv":0.21,"id":31374}]}]}
{"op":"mcm","clk":"11798604857","pt":1723153939891,"mc":[{"id":"1.231540814","rc":[{"batb":[[0,2.32,10],[1,2.3,4],[2,2.28,29.61]],"ltp":2.4,"tv":0.21,"id":31374}]}]}
{"op":"mcm","clk":"11798604942","pt":1723153940976,"mc":[{"id":"1.231540814","rc":[{"batb":[[1,2.28,29.61],[2,2.02,4.55]],"ltp":2.4,"tv":0.21,"id":31374}]}]}
{"op":"mcm","clk":"11798605107","pt":1723153943293,"mc":[{"id":"1.231540814","rc":[{"batb":[[0,2.3,4]],"ltp":2.4,"tv":0.21,"id":31374}]}]}
{"op":"mcm","clk":"11798605253","pt":1723153945609,"mc":[{"id":"1.231540814","rc":[{"batb":[[0,2.32,10]],"ltp":2.4,"tv":0.21,"id":31374}]}]}
{"op":"mcm","clk":"11798605464","pt":1723153949302,"mc":[{"id":"1.231540814","rc":[{"batb":[[0,2.3,4]],"ltp":2.4,"tv":0.21,"id":31374}]}]}
{"op":"mcm","clk":"11798605589","pt":1723153951867,"mc":[{"id":"1.231540814","rc":[{"batb":[[0,2.3,10]],"ltp":2.4,"tv":0.21,"id":31374}]}]}
{"op":"mcm","clk":"11798605679","pt":1723153953974,"mc":[{"id":"1.231540814","rc":[{"batb":[[0,2.32,4],[1,2.3,10],[2,2.28,29.61]],"ltp":2.4,"tv":0.21,"id":31374}]}]}
{"op":"mcm","clk":"11798605716","pt":1723153955093,"mc":[{"id":"1.231540814","rc":[{"batb":[[1,2.28,29.61],[2,2.02,4.55]],"ltp":2.4,"tv":0.21,"id":31374}]}]}
{"op":"mcm","clk":"11798605760","pt":1723153956383,"mc":[{"id":"1.231540814","rc":[{"batb":[[0,2.28,29.61],[1,2.02,4.55],[2,1.8,2]],"ltp":2.4,"tv":0.21,"id":31374}]}]}
{"op":"mcm","clk":"11798605852","pt":1723153958585,"mc":[{"id":"1.231540814","rc":[{"batb":[[0,2.3,14],[1,2.28,29.61],[2,2.02,4.55]],"ltp":2.4,"tv":0.21,"id":31374}]}]}
{"op":"mcm","clk":"11798606003","pt":1723153960780,"mc":[{"id":"1.231540814","rc":[{"batb":[[0,2.3,10]],"ltp":2.4,"tv":0.21,"id":31374}]}]}
{"op":"mcm","clk":"11798606055","pt":1723153962012,"mc":[{"id":"1.231540814","rc":[{"batb":[[0,2.28,29.61],[1,2.02,4.55],[2,1.8,2]],"ltp":2.4,"tv":0.21,"id":31374}]}]}
{"op":"mcm","clk":"11798606109","pt":1723153963091,"mc":[{"id":"1.231540814","rc":[{"batb":[[0,2.3,4],[1,2.28,29.61],[2,2.02,4.55]],"ltp":2.4,"tv":0.21,"id":31374}]}]}
{"op":"mcm","clk":"11798606174","pt":1723153964425,"mc":[{"id":"1.231540814","rc":[{"batb":[[0,2.32,10],[1,2.3,4],[2,2.28,29.61]],"ltp":2.4,"tv":0.21,"id":31374}]}]}
{"op":"mcm","clk":"11798606208","pt":1723153965400,"mc":[{"id":"1.231540814","rc":[{"batb":[[1,2.28,29.61],[2,2.02,4.55]],"ltp":2.4,"tv":0.21,"id":31374}]}]}
{"op":"mcm","clk":"11798606329","pt":1723153968020,"mc":[{"id":"1.231540814","rc":[{"batb":[[0,2.3,4]],"ltp":2.4,"tv":0.21,"id":31374}]}]}
{"op":"mcm","clk":"11798606423","pt":1723153970429,"mc":[{"id":"1.231540814","rc":[{"batb":[[0,2.3,10]],"ltp":2.4,"tv":0.21,"id":31374}]}]}
{"op":"mcm","clk":"11798606524","pt":1723153972633,"mc":[{"id":"1.231540814","rc":[{"batb":[[0,2.32,4],[1,2.3,10],[2,2.28,29.61]],"ltp":2.4,"tv":0.21,"id":31374}]}]}
{"op":"mcm","clk":"11798606578","pt":1723153973812,"mc":[{"id":"1.231540814","rc":[{"batb":[[1,2.28,29.61],[2,2.02,4.55]],"ltp":2.4,"tv":0.21,"id":31374}]}]}
{"op":"mcm","clk":"11798606636","pt":1723153974992,"mc":[{"id":"1.231540814","rc":[{"batb":[[0,2.28,29.61],[1,2.02,4.55],[2,1.8,2]],"ltp":2.4,"tv":0.21,"id":31374}]}]}
{"op":"mcm","clk":"11798606728","pt":1723153977199,"mc":[{"id":"1.231540814","rc":[{"batb":[[0,2.3,14],[1,2.28,29.61],[2,2.02,4.55]],"ltp":2.4,"tv":0.21,"id":31374}]}]}
{"op":"mcm","clk":"11798606811","pt":1723153979612,"mc":[{"id":"1.231540814","rc":[{"batb":[[0,2.3,10]],"ltp":2.4,"tv":0.21,"id":31374}]}]}
{"op":"mcm","clk":"11798606848","pt":1723153980637,"mc":[{"id":"1.231540814","rc":[{"batb":[[0,2.28,29.61],[1,2.02,4.55],[2,1.8,2]],"ltp":2.4,"tv":0.21,"id":31374}]}]}
{"op":"mcm","clk":"11798606889","pt":1723153981821,"mc":[{"id":"1.231540814","rc":[{"batb":[[0,2.3,4],[1,2.28,29.61],[2,2.02,4.55]],"ltp":2.4,"tv":0.21,"id":31374}]}]}
{"op":"mcm","clk":"11798606974","pt":1723153984153,"mc":[{"id":"1.231540814","rc":[{"batb":[[0,2.32,10]],"ltp":2.4,"tv":0.21,"id":31374}]}]}
{"op":"mcm","clk":"11798607072","pt":1723153987521,"mc":[{"id":"1.231540814","rc":[{"batb":[[0,2.3,4]],"ltp":2.4,"tv":0.21,"id":31374}]}]}
{"op":"mcm","clk":"11798607161","pt":1723153989938,"mc":[{"id":"1.231540814","rc":[{"batb":[[0,2.32,10]],"ltp":2.4,"tv":0.21,"id":31374}]}]}
{"op":"mcm","clk":"11798607276","pt":1723153993320,"mc":[{"id":"1.231540814","rc":[{"batb":[[0,2.3,4]],"ltp":2.4,"tv":0.21,"id":31374}]}]}
{"op":"mcm","clk":"11798607367","pt":1723153995932,"mc":[{"id":"1.231540814","rc":[{"batb":[[0,2.3,10]],"ltp":2.4,"tv":0.21,"id":31374}]}]}
{"op":"mcm","clk":"11798607430","pt":1723153998239,"mc":[{"id":"1.231540814","rc":[{"batb":[[0,2.32,4],[1,2.3,10],[2,2.28,29.61]],"ltp":2.4,"tv":0.21,"id":31374}]}]}
{"op":"mcm","clk":"11798607454","pt":1723153999212,"mc":[{"id":"1.231540814","rc":[{"batb":[[1,2.28,29.61],[2,2.02,4.55]],"ltp":2.4,"tv":0.21,"id":31374}]}]}
{"op":"mcm","clk":"11798607484","pt":1723154000547,"mc":[{"id":"1.231540814","rc":[{"batb":[[0,2.28,29.61],[1,2.02,4.55],[2,1.8,2]],"ltp":2.4,"tv":0.21,"id":31374}]}]}
{"op":"mcm","clk":"11798607524","pt":1723154001624,"mc":[{"id":"1.231540814","rc":[{"batb":[[0,2.3,10],[1,2.28,29.61],[2,2.02,4.55]],"ltp":2.4,"tv":0.21,"id":31374}]}]}
{"op":"mcm","clk":"11798607540","pt":1723154002138,"mc":[{"id":"1.231540814","rc":[{"batb":[[0,2.32,4.71],[1,2.3,10],[2,2.28,29.61]],"ltp":2.4,"tv":0.21,"id":31374}]}]}
{"op":"mcm","clk":"11798607689","pt":1723154005063,"mc":[{"id":"1.231540814","rc":[{"batb":[[0,2.34,4],[1,2.32,4.71]],"ltp":2.4,"tv":0.21,"id":31374}]}]}
{"op":"mcm","clk":"11798607767","pt":1723154007431,"mc":[{"id":"1.231540814","rc":[{"batb":[[0,2.34,10]],"ltp":2.4,"tv":0.21,"id":31374}]}]}
{"op":"mcm","clk":"11798607778","pt":1723154007837,"mc":[{"id":"1.231540814","rc":[{"batb":[[1,2.28,29.61],[2,2.02,4.55]],"ltp":2.4,"tv":0.21,"id":31374}]}]}
{"op":"mcm","clk":"11798607848","pt":1723154010040,"mc":[{"id":"1.231540814","rc":[{"batb":[[0,2.36,4],[1,2.34,10],[2,2.28,29.61]],"ltp":2.4,"tv":0.21,"id":31374}]}]}
{"op":"mcm","clk":"11798607870","pt":1723154010758,"mc":[{"id":"1.231540814","rc":[{"batb":[[1,2.28,29.61],[2,2.02,4.55]],"ltp":2.4,"tv":0.21,"id":31374}]}]}
{"op":"mcm","clk":"11798607925","pt":1723154012453,"mc":[{"id":"1.231540814","rc":[{"batb":[[0,2.28,29.61],[1,2.02,4.55],[2,1.8,2]],"ltp":2.4,"tv":0.21,"id":31374}]}]}
{"op":"mcm","clk":"11798607995","pt":1723154014566,"mc":[{"id":"1.231540814","rc":[{"batb":[[0,2.3,14],[1,2.28,29.61],[2,2.02,4.55]],"ltp":2.4,"tv":0.21,"id":31374}]}]}
{"op":"mcm","clk":"11798608082","pt":1723154016948,"mc":[{"id":"1.231540814","rc":[{"batb":[[0,2.3,10]],"ltp":2.4,"tv":0.21,"id":31374}]}]}
{"op":"mcm","clk":"11798608160","pt":1723154017971,"mc":[{"id":"1.231540814","rc":[{"batb":[[0,2.28,29.61],[1,2.02,4.55],[2,1.8,2]],"ltp":2.4,"tv":0.21,"id":31374}]}]}
{"op":"mcm","clk":"11798608267","pt":1723154021369,"mc":[{"id":"1.231540814","rc":[{"batb":[[0,2.3,14],[1,2.28,29.61],[2,2.02,4.55]],"ltp":2.4,"tv":0.21,"id":31374}]}]}
{"op":"mcm","clk":"11798608356","pt":1723154023775,"mc":[{"id":"1.231540814","rc":[{"batb":[[0,2.3,10]],"ltp":2.4,"tv":0.21,"id":31374}]}]}
{"op":"mcm","clk":"11798608388","pt":1723154024749,"mc":[{"id":"1.231540814","rc":[{"batb":[[0,2.28,29.61],[1,2.02,4.55],[2,1.8,2]],"ltp":2.4,"tv":0.21,"id":31374}]}]}
{"op":"mcm","clk":"11798608434","pt":1723154025981,"mc":[{"id":"1.231540814","rc":[{"batb":[[0,2.3,4],[1,2.28,29.61],[2,2.02,4.55]],"ltp":2.4,"tv":0.21,"id":31374}]}]}
{"op":"mcm","clk":"11798608515","pt":1723154028238,"mc":[{"id":"1.231540814","rc":[{"batb":[[0,2.32,10]],"ltp":2.4,"tv":0.21,"id":31374}]}]}
{"op":"mcm","clk":"11798608613","pt":1723154030550,"mc":[{"id":"1.231540814","rc":[{"batb":[[0,2.34,4],[1,2.32,10],[2,2.28,29.61]],"ltp":2.4,"tv":0.21,"id":31374}]}]}
{"op":"mcm","clk":"11798608663","pt":1723154031575,"mc":[{"id":"1.231540814","rc":[{"batb":[[1,2.28,29.61],[2,2.02,4.55]],"ltp":2.4,"tv":0.21,"id":31374}]}]}
{"op":"mcm","clk":"11798608710","pt":1723154032858,"mc":[{"id":"1.231540814","rc":[{"batb":[[0,2.28,29.61],[1,2.02,4.55],[2,1.8,2]],"ltp":2.4,"tv":0.21,"id":31374}]}]}
{"op":"mcm","clk":"11798608756","pt":1723154034085,"mc":[{"id":"1.231540814","rc":[{"batb":[[0,2.3,10],[1,2.28,29.61],[2,2.02,4.55]],"ltp":2.4,"tv":0.21,"id":31374}]}]}
{"op":"mcm","clk":"11798608803","pt":1723154035261,"mc":[{"id":"1.231540814","rc":[{"batb":[[0,2.32,4],[1,2.3,10],[2,2.28,29.61]],"ltp":2.4,"tv":0.21,"id":31374}]}]}
{"op":"mcm","clk":"11798608889","pt":1723154037672,"mc":[{"id":"1.231540814","rc":[{"batb":[[0,2.28,29.61],[1,2.02,4.55],[2,1.8,2]],"ltp":2.4,"tv":0.21,"id":31374}]}]}
{"op":"mcm","clk":"11798609002","pt":1723154040956,"mc":[{"id":"1.231540814","rc":[{"batb":[[0,2.3,14],[1,2.28,29.61],[2,2.02,4.55]],"ltp":2.4,"tv":0.21,"id":31374}]}]}
{"op":"mcm","clk":"11798609072","pt":1723154043364,"mc":[{"id":"1.231540814","rc":[{"batb":[[0,2.3,10]],"ltp":2.4,"tv":0.21,"id":31374}]}]}
{"op":"mcm","clk":"11798609108","pt":1723154044388,"mc":[{"id":"1.231540814","rc":[{"batb":[[0,2.28,29.61],[1,2.02,4.55],[2,1.8,2]],"ltp":2.4,"tv":0.21,"id":31374}]}]}
{"op":"mcm","clk":"11798609161","pt":1723154045565,"mc":[{"id":"1.231540814","rc":[{"batb":[[0,2.3,4],[1,2.28,29.61],[2,2.02,4.55]],"ltp":2.4,"tv":0.21,"id":31374}]}]}
{"op":"mcm","clk":"11798609197","pt":1723154046897,"mc":[{"id":"1.231540814","rc":[{"batb":[[0,2.32,10],[1,2.3,4],[2,2.28,29.61]],"ltp":2.4,"tv":0.21,"id":31374}]}]}
{"op":"mcm","clk":"11798609243","pt":1723154047971,"mc":[{"id":"1.231540814","rc":[{"batb":[[1,2.28,29.61],[2,2.02,4.55]],"ltp":2.4,"tv":0.21,"id":31374}]}]}
{"op":"mcm","clk":"11798609320","pt":1723154050277,"mc":[{"id":"1.231540814","rc":[{"batb":[[0,2.3,4]],"ltp":2.4,"tv":0.21,"id":31374}]}]}
{"op":"mcm","clk":"11798609409","pt":1723154052585,"mc":[{"id":"1.231540814","rc":[{"batb":[[0,2.32,10]],"ltp":2.4,"tv":0.21,"id":31374}]}]}
{"op":"mcm","clk":"11798609472","pt":1723154054997,"mc":[{"id":"1.231540814","rc":[{"batb":[[0,2.34,4],[1,2.32,10],[2,2.28,29.61]],"ltp":2.4,"tv":0.21,"id":31374}]}]}
{"op":"mcm","clk":"11798609502","pt":1723154055974,"mc":[{"id":"1.231540814","rc":[{"batb":[[1,2.28,29.61],[2,2.02,4.55]],"ltp":2.4,"tv":0.21,"id":31374}]}]}
{"op":"mcm","clk":"11798609546","pt":1723154057404,"mc":[{"id":"1.231540814","rc":[{"batb":[[0,2.28,29.61],[1,2.02,4.55],[2,1.8,2]],"ltp":2.4,"tv":0.21,"id":31374}]}]}
{"op":"mcm","clk":"11798609616","pt":1723154059560,"mc":[{"id":"1.231540814","rc":[{"batb":[[0,2.32,4],[1,2.3,10],[2,2.28,29.61]],"ltp":2.4,"tv":0.21,"id":31374}]}]}
{"op":"mcm","clk":"11798609678","pt":1723154061765,"mc":[{"id":"1.231540814","rc":[{"batb":[[0,2.3,10],[1,2.28,29.61],[2,2.02,4.55]],"ltp":2.4,"tv":0.21,"id":31374}]}]}
{"op":"mcm","clk":"11798609698","pt":1723154062792,"mc":[{"id":"1.231540814","rc":[{"batb":[[0,2.28,29.61],[1,2.02,4.55],[2,1.8,2]],"ltp":2.4,"tv":0.21,"id":31374}]}]}
{"op":"mcm","clk":"11798609732","pt":1723154064072,"mc":[{"id":"1.231540814","rc":[{"batb":[[0,2.3,4],[1,2.28,29.61],[2,2.02,4.55]],"ltp":2.4,"tv":0.21,"id":31374}]}]}
{"op":"mcm","clk":"11798609804","pt":1723154066580,"mc":[{"id":"1.231540814","rc":[{"batb":[[0,2.32,10]],"ltp":2.4,"tv":0.21,"id":31374}]}]}
{"op":"mcm","clk":"11798609912","pt":1723154069913,"mc":[{"id":"1.231540814","rc":[{"batb":[[0,2.3,4]],"ltp":2.4,"tv":0.21,"id":31374}]}]}
{"op":"mcm","clk":"11798609976","pt":1723154072204,"mc":[{"id":"1.231540814","rc":[{"batb":[[0,2.3,10]],"ltp":2.4,"tv":0.21,"id":31374}]}]}
{"op":"mcm","clk":"11798610076","pt":1723154075585,"mc":[{"id":"1.231540814","rc":[{"batb":[[0,2.32,4]],"ltp":2.4,"tv":0.21,"id":31374}]}]}
{"op":"mcm","clk":"11798610152","pt":1723154077887,"mc":[{"id":"1.231540814","rc":[{"batb":[[0,2.34,10]],"ltp":2.4,"tv":0.21,"id":31374}]}]}
{"op":"mcm","clk":"11798610236","pt":1723154081424,"mc":[{"id":"1.231540814","rc":[{"batb":[[0,2.3,4]],"ltp":2.4,"tv":0.21,"id":31374}]}]}
{"op":"mcm","clk":"11798610296","pt":1723154083677,"mc":[{"id":"1.231540814","rc":[{"batb":[[0,2.28,29.61],[1,2.02,4.55],[2,1.8,2]],"ltp":2.4,"tv":0.21,"id":31374}]}]}
{"op":"mcm","clk":"11798610300","pt":1723154083780,"mc":[{"id":"1.231540814","rc":[{"batb":[[0,2.3,10],[1,2.28,29.61],[2,2.02,4.55]],"ltp":2.4,"tv":0.21,"id":31374}]}]}
{"op":"mcm","clk":"11798610348","pt":1723154086085,"mc":[{"id":"1.231540814","rc":[{"batb":[[0,2.32,4],[1,2.3,10],[2,2.28,29.61]],"ltp":2.4,"tv":0.21,"id":31374}]}]}
{"op":"mcm","clk":"11798610371","pt":1723154087111,"mc":[{"id":"1.231540814","rc":[{"batb":[[1,2.28,29.61],[2,2.02,4.55]],"ltp":2.4,"tv":0.21,"id":31374}]}]}
{"op":"mcm","clk":"11798610418","pt":1723154088288,"mc":[{"id":"1.231540814","rc":[{"batb":[[0,2.28,29.61],[1,2.02,4.55],[2,1.8,2]],"ltp":2.4,"tv":0.21,"id":31374}]}]}
{"op":"mcm","clk":"11798610458","pt":1723154089619,"mc":[{"id":"1.231540814","rc":[{"batb":[[0,2.3,10],[1,2.28,29.61],[2,2.02,4.55]],"ltp":2.4,"tv":0.21,"id":31374}]}]}
{"op":"mcm","clk":"11798610554","pt":1723154092437,"mc":[{"id":"1.231540814","rc":[{"batb":[[0,2.32,4],[1,2.3,10],[2,2.28,29.61]],"ltp":2.4,"tv":0.21,"id":31374}]}]}
{"op":"mcm","clk":"11798610573","pt":1723154092899,"mc":[{"id":"1.231540814","rc":[{"batb":[[1,2.28,29.61],[2,2.02,4.55]],"ltp":2.4,"tv":0.21,"id":31374}]}]}
{"op":"mcm","clk":"11798610614","pt":1723154094798,"mc":[{"id":"1.231540814","rc":[{"batb":[[0,2.28,29.61],[1,2.02,4.55],[2,1.8,2]],"ltp":2.4,"tv":0.21,"id":31374}]}]}
{"op":"mcm","clk":"11798610688","pt":1723154097705,"mc":[{"id":"1.231540814","rc":[{"batb":[[0,2.3,14],[1,2.28,29.61],[2,2.02,4.55]],"ltp":2.4,"tv":0.21,"id":31374}]}]}
{"op":"mcm","clk":"11798610749","pt":1723154100118,"mc":[{"id":"1.231540814","rc":[{"batb":[[0,2.3,10]],"ltp":2.4,"tv":0.21,"id":31374}]}]}
{"op":"mcm","clk":"11798610783","pt":1723154101135,"mc":[{"id":"1.231540814","rc":[{"batb":[[0,2.28,29.61],[1,2.02,4.55],[2,1.8,2]],"ltp":2.4,"tv":0.21,"id":31374}]}]}
{"op":"mcm","clk":"11798610863","pt":1723154103854,"mc":[{"id":"1.231540814","rc":[{"batb":[[0,2.3,14],[1,2.28,29.61],[2,2.02,4.55]],"ltp":2.4,"tv":0.21,"id":31374}]}]}
{"op":"mcm","clk":"11798610943","pt":1723154106158,"mc":[{"id":"1.231540814","rc":[{"batb":[[0,2.3,10]],"ltp":2.4,"tv":0.21,"id":31374}]}]}
{"op":"mcm","clk":"11798610960","pt":1723154107131,"mc":[{"id":"1.231540814","rc":[{"batb":[[0,2.28,29.61],[1,2.02,4.55],[2,1.8,2]],"ltp":2.4,"tv":0.21,"id":31374}]}]}
{"op":"mcm","clk":"11798611052","pt":1723154110048,"mc":[{"id":"1.231540814","rc":[{"batb":[[0,2.3,14],[1,2.28,29.61],[2,2.02,4.55]],"ltp":2.4,"tv":0.21,"id":31374}]}]}
{"op":"mcm","clk":"11798611118","pt":1723154112351,"mc":[{"id":"1.231540814","rc":[{"batb":[[0,2.3,10]],"ltp":2.4,"tv":0.21,"id":31374}]}]}
{"op":"mcm","clk":"11798611146","pt":1723154113323,"mc":[{"id":"1.231540814","rc":[{"batb":[[0,2.28,29.61],[1,2.02,4.55],[2,1.8,2]],"ltp":2.4,"tv":0.21,"id":31374}]}]}
{"op":"mcm","clk":"11798611170","pt":1723154114549,"mc":[{"id":"1.231540814","rc":[{"batb":[[0,2.3,4],[1,2.28,29.61],[2,2.02,4.55]],"ltp":2.4,"tv":0.21,"id":31374}]}]}
{"op":"mcm","clk":"11798611249","pt":1723154116958,"mc":[{"id":"1.231540814","rc":[{"batb":[[0,2.3,10]],"ltp":2.4,"tv":0.21,"id":31374}]}]}
{"op":"mcm","clk":"11798611365","pt":1723154120358,"mc":[{"id":"1.231540814","rc":[{"batb":[[0,2.32,4]],"ltp":2.4,"tv":0.21,"id":31374}]}]}
{"op":"mcm","clk":"11798611447","pt":1723154122655,"mc":[{"id":"1.231540814","rc":[{"batb":[[0,2.34,10]],"ltp":2.4,"tv":0.21,"id":31374}]}]}
{"op":"mcm","clk":"11798611548","pt":1723154126047,"mc":[{"id":"1.231540814","rc":[{"batb":[[0,2.3,4]],"ltp":2.4,"tv":0.21,"id":31374}]}]}
{"op":"mcm","clk":"11798611613","pt":1723154128353,"mc":[{"id":"1.231540814","rc":[{"batb":[[0,2.3,10]],"ltp":2.4,"tv":0.21,"id":31374}]}]}
{"op":"mcm","clk":"11798611712","pt":1723154131580,"mc":[{"id":"1.231540814","rc":[{"batb":[[0,2.32,4]],"ltp":2.4,"tv":0.21,"id":31374}]}]}
{"op":"mcm","clk":"11798611752","pt":1723154132962,"mc":[{"id":"1.231540814","rc":[{"batb":[[0,2.28,29.61],[1,2.02,4.55],[2,1.8,2]],"ltp":2.4,"tv":0.21,"id":31374}]}]}
{"op":"mcm","clk":"11798611777","pt":1723154134088,"mc":[{"id":"1.231540814","rc":[{"batb":[[0,2.3,10],[1,2.28,29.61],[2,2.02,4.55]],"ltp":2.4,"tv":0.21,"id":31374}]}]}
{"op":"mcm","clk":"11798611816","pt":1723154135369,"mc":[{"id":"1.231540814","rc":[{"batb":[[0,2.32,4],[1,2.3,10],[2,2.28,29.61]],"ltp":2.4,"tv":0.21,"id":31374}]}]}
{"op":"mcm","clk":"11798611894","pt":1723154137569,"mc":[{"id":"1.231540814","rc":[{"batb":[[0,2.28,29.61],[1,2.02,4.55],[2,1.8,2]],"ltp":2.4,"tv":0.21,"id":31374}]}]}
{"op":"mcm","clk":"11798612014","pt":1723154141101,"mc":[{"id":"1.231540814","rc":[{"batb":[[0,2.3,14],[1,2.28,29.61],[2,2.02,4.55]],"ltp":2.4,"tv":0.21,"id":31374}]}]}
{"op":"mcm","clk":"11798612079","pt":1723154143405,"mc":[{"id":"1.231540814","rc":[{"batb":[[0,2.3,10]],"ltp":2.4,"tv":0.21,"id":31374}]}]}
{"op":"mcm","clk":"11798612126","pt":1723154144382,"mc":[{"id":"1.231540814","rc":[{"batb":[[0,2.32,4.71]],"ltp":2.4,"tv":0.21,"id":31374}]}]}
{"op":"mcm","clk":"11798612200","pt":1723154146905,"mc":[{"id":"1.231540814","rc":[{"batb":[[0,2.34,14],[1,2.32,4.71],[2,2.28,29.61]],"ltp":2.4,"tv":0.21,"id":31374}]}]}
{"op":"mcm","clk":"11798612228","pt":1723154147781,"mc":[{"id":"1.231540814","rc":[{"batb":[[1,2.28,29.61],[2,2.02,4.55]],"ltp":2.4,"tv":0.21,"id":31374}]}]}
{"op":"mcm","clk":"11798612267","pt":1723154149213,"mc":[{"id":"1.231540814","rc":[{"batb":[[0,2.34,10]],"ltp":2.4,"tv":0.21,"id":31374}]}]}
{"op":"mcm","clk":"11798612297","pt":1723154150086,"mc":[{"id":"1.231540814","rc":[{"batb":[[0,2.28,29.61],[1,2.02,4.55],[2,1.8,2]],"ltp":2.4,"tv":0.21,"id":31374}]}]}
{"op":"mcm","clk":"11798612339","pt":1723154151574,"mc":[{"id":"1.231540814","rc":[{"batb":[[0,2.3,4],[1,2.28,29.61],[2,2.02,4.55]],"ltp":2.4,"tv":0.21,"id":31374}]}]}
{"op":"mcm","clk":"11798612419","pt":1723154154083,"mc":[{"id":"1.231540814","rc":[{"batb":[[0,2.3,10]],"ltp":2.4,"tv":0.21,"id":31374}]}]}
{"op":"mcm","clk":"11798612515","pt":1723154157508,"mc":[{"id":"1.231540814","rc":[{"batb":[[0,2.3,4]],"ltp":2.4,"tv":0.21,"id":31374}]}]}
{"op":"mcm","clk":"11798612610","pt":1723154159918,"mc":[{"id":"1.231540814","rc":[{"batb":[[0,2.32,10]],"ltp":2.4,"tv":0.21,"id":31374}]}]}
{"op":"mcm","clk":"11798612692","pt":1723154162227,"mc":[{"id":"1.231540814","rc":[{"batb":[[0,2.34,4],[1,2.32,10],[2,2.28,29.61]],"ltp":2.4,"tv":0.21,"id":31374}]}]}
{"op":"mcm","clk":"11798612735","pt":1723154163405,"mc":[{"id":"1.231540814","rc":[{"batb":[[1,2.28,29.61],[2,2.02,4.55]],"ltp":2.4,"tv":0.21,"id":31374}]}]}
{"op":"mcm","clk":"11798612772","pt":1723154164634,"mc":[{"id":"1.231540814","rc":[{"batb":[[0,2.28,29.61],[1,2.02,4.55],[2,1.8,2]],"ltp":2.4,"tv":0.21,"id":31374}]}]}
{"op":"mcm","clk":"11798612818","pt":1723154165815,"mc":[{"id":"1.231540814","rc":[{"batb":[[0,2.3,10],[1,2.28,29.61],[2,2.02,4.55]],"ltp":2.4,"tv":0.21,"id":31374}]}]}
{"op":"mcm","clk":"11798612859","pt":1723154166896,"mc":[{"id":"1.231540814","rc":[{"batb":[[0,2.32,4],[1,2.3,10],[2,2.28,29.61]],"ltp":2.4,"tv":0.21,"id":31374}]}]}
{"op":"mcm","clk":"11798612930","pt":1723154169216,"mc":[{"id":"1.231540814","rc":[{"batb":[[0,2.28,29.61],[1,2.02,4.55],[2,1.8,2]],"ltp":2.4,"tv":0.21,"id":31374}]}]}
{"op":"mcm","clk":"11798613003","pt":1723154171621,"mc":[{"id":"1.231540814","rc":[{"batb":[[0,2.3,14],[1,2.28,29.61],[2,2.02,4.55]],"ltp":2.4,"tv":0.21,"id":31374}]}]}
{"op":"mcm","clk":"11798613076","pt":1723154174028,"mc":[{"id":"1.231540814","rc":[{"batb":[[0,2.3,10]],"ltp":2.4,"tv":0.21,"id":31374}]}]}
{"op":"mcm","clk":"11798613103","pt":1723154175002,"mc":[{"id":"1.231540814","rc":[{"batb":[[0,2.28,29.61],[1,2.02,4.55],[2,1.8,2]],"ltp":2.4,"tv":0.21,"id":31374}]}]}
{"op":"mcm","clk":"11798613176","pt":1723154177319,"mc":[{"id":"1.231540814","rc":[{"batb":[[0,2.3,14],[1,2.28,29.61],[2,2.02,4.55]],"ltp":2.4,"tv":0.21,"id":31374}]}]}
{"op":"mcm","clk":"11798613250","pt":1723154179518,"mc":[{"id":"1.231540814","rc":[{"batb":[[0,2.3,10]],"ltp":2.4,"tv":0.21,"id":31374}]}]}
{"op":"mcm","clk":"11798613277","pt":1723154180437,"mc":[{"id":"1.231540814","rc":[{"batb":[[0,2.28,29.61],[1,2.02,4.55],[2,1.8,2]],"ltp":2.4,"tv":0.21,"id":31374}]}]}
{"op":"mcm","clk":"11798613337","pt":1723154181926,"mc":[{"id":"1.231540814","rc":[{"batb":[[0,2.3,4],[1,2.28,29.61],[2,2.02,4.55]],"ltp":2.4,"tv":0.21,"id":31374}]}]}
{"op":"mcm","clk":"11798613426","pt":1723154184333,"mc":[{"id":"1.231540814","rc":[{"batb":[[0,2.32,10]],"ltp":2.4,"tv":0.21,"id":31374}]}]}
{"op":"mcm","clk":"11798613511","pt":1723154187611,"mc":[{"id":"1.231540814","rc":[{"batb":[[0,2.34,4]],"ltp":2.4,"tv":0.21,"id":31374}]}]}
{"op":"mcm","clk":"11798613575","pt":1723154189861,"mc":[{"id":"1.231540814","rc":[{"batb":[[0,2.36,10]],"ltp":2.4,"tv":0.21,"id":31374}]}]}
{"op":"mcm","clk":"11798613705","pt":1723154193346,"mc":[{"id":"1.231540814","rc":[{"batb":[[0,2.3,4]],"ltp":2.4,"tv":0.21,"id":31374}]}]}
{"op":"mcm","clk":"11798613790","pt":1723154195652,"mc":[{"id":"1.231540814","rc":[{"batb":[[0,2.3,10]],"ltp":2.4,"tv":0.21,"id":31374}]}]}
{"op":"mcm","clk":"11798613892","pt":1723154198938,"mc":[{"id":"1.231540814","rc":[{"batb":[[0,2.3,4]],"ltp":2.4,"tv":0.21,"id":31374}]}]}
{"op":"mcm","clk":"11798613967","pt":1723154201349,"mc":[{"id":"1.231540814","rc":[{"batb":[[0,2.32,10]],"ltp":2.4,"tv":0.21,"id":31374}]}]}
{"op":"mcm","clk":"11798614062","pt":1723154204732,"mc":[{"id":"1.231540814","rc":[{"batb":[[0,2.34,4]],"ltp":2.4,"tv":0.21,"id":31374}]}]}
{"op":"mcm","clk":"11798614094","pt":1723154206063,"mc":[{"id":"1.231540814","rc":[{"batb":[[0,2.28,29.61],[1,2.02,4.55],[2,1.8,2]],"ltp":2.4,"tv":0.21,"id":31374}]}]}
{"op":"mcm","clk":"11798614134","pt":1723154207246,"mc":[{"id":"1.231540814","rc":[{"batb":[[0,2.3,10],[1,2.28,29.61],[2,2.02,4.55]],"ltp":2.4,"tv":0.21,"id":31374}]}]}
{"op":"mcm","clk":"11798614178","pt":1723154208470,"mc":[{"id":"1.231540814","rc":[{"batb":[[0,2.32,4],[1,2.3,10],[2,2.28,29.61]],"ltp":2.4,"tv":0.21,"id":31374}]}]}
{"op":"mcm","clk":"11798614246","pt":1723154210673,"mc":[{"id":"1.231540814","rc":[{"batb":[[1,2.28,29.61],[2,2.02,4.55]],"ltp":2.4,"tv":0.21,"id":31374}]}]}
{"op":"mcm","clk":"11798614254","pt":1723154210879,"mc":[{"id":"1.231540814","rc":[{"batb":[[0,2.28,29.61],[1,2.02,4.55],[2,1.8,2]],"ltp":2.4,"tv":0.21,"id":31374}]}]}
{"op":"mcm","clk":"11798614361","pt":1723154214261,"mc":[{"id":"1.231540814","rc":[{"batb":[[0,2.3,14],[1,2.28,29.61],[2,2.02,4.55]],"ltp":2.4,"tv":0.21,"id":31374}]}]}
{"op":"mcm","clk":"11798614430","pt":1723154216465,"mc":[{"id":"1.231540814","rc":[{"batb":[[0,2.3,10]],"ltp":2.4,"tv":0.21,"id":31374}]}]}
{"op":"mcm","clk":"11798614458","pt":1723154217590,"mc":[{"id":"1.231540814","rc":[{"batb":[[0,2.28,29.61],[1,2.02,4.55],[2,1.8,2]],"ltp":2.4,"tv":0.21,"id":31374}]}]}
{"op":"mcm","clk":"11798614599","pt":1723154221288,"mc":[{"id":"1.231540814","rc":[{"batb":[[0,2.3,14],[1,2.28,29.61],[2,2.02,4.55]],"ltp":2.4,"tv":0.21,"id":31374}]}]}
{"op":"mcm","clk":"11798614672","pt":1723154223551,"mc":[{"id":"1.231540814","rc":[{"batb":[[0,2.3,10]],"ltp":2.4,"tv":0.21,"id":31374}]}]}
{"op":"mcm","clk":"11798614698","pt":1723154224678,"mc":[{"id":"1.231540814","rc":[{"batb":[[0,2.28,29.61],[1,2.02,4.55],[2,1.8,2]],"ltp":2.4,"tv":0.21,"id":31374}]}]}
{"op":"mcm","clk":"11798614744","pt":1723154226276,"mc":[{"id":"1.231540814","rc":[{"batb":[[0,2.3,4],[1,2.28,29.61],[2,2.02,4.55]],"ltp":2.4,"tv":0.21,"id":31374}]}]}
{"op":"mcm","clk":"11798614786","pt":1723154227463,"mc":[{"id":"1.231540814","rc":[{"batb":[[0,2.32,10],[1,2.3,4],[2,2.28,29.61]],"ltp":2.4,"tv":0.21,"id":31374}]}]}
{"op":"mcm","clk":"11798614831","pt":1723154228690,"mc":[{"id":"1.231540814","rc":[{"batb":[[1,2.28,29.61],[2,2.02,4.55]],"ltp":2.4,"tv":0.21,"id":31374}]}]}
{"op":"mcm","clk":"11798614904","pt":1723154231002,"mc":[{"id":"1.231540814","rc":[{"batb":[[0,2.3,4]],"ltp":2.4,"tv":0.21,"id":31374}]}]}
{"op":"mcm","clk":"11798614978","pt":1723154233472,"mc":[{"id":"1.231540814","rc":[{"batb":[[0,2.3,10]],"ltp":2.4,"tv":0.21,"id":31374}]}]}
{"op":"mcm","clk":"11798615090","pt":1723154236698,"mc":[{"id":"1.231540814","rc":[{"batb":[[0,2.32,4]],"ltp":2.4,"tv":0.21,"id":31374}]}]}
{"op":"mcm","clk":"11798615166","pt":1723154239002,"mc":[{"id":"1.231540814","rc":[{"batb":[[0,2.34,10]],"ltp":2.4,"tv":0.21,"id":31374}]}]}
{"op":"mcm","clk":"11798615243","pt":1723154241508,"mc":[{"id":"1.231540814","rc":[{"batb":[[0,2.36,4],[1,2.34,10],[2,2.28,29.61]],"ltp":2.4,"tv":0.21,"id":31374}]}]}
{"op":"mcm","clk":"11798615265","pt":1723154242280,"mc":[{"id":"1.231540814","rc":[{"batb":[[1,2.28,29.61],[2,2.02,4.55]],"ltp":2.4,"tv":0.21,"id":31374}]}]}
{"op":"mcm","clk":"11798615317","pt":1723154243814,"mc":[{"id":"1.231540814","rc":[{"batb":[[0,2.28,29.61],[1,2.02,4.55],[2,1.8,2]],"ltp":2.4,"tv":0.21,"id":31374}]}]}
{"op":"mcm","clk":"11798615350","pt":1723154244893,"mc":[{"id":"1.231540814","rc":[{"batb":[[0,2.3,10],[1,2.28,29.61],[2,2.02,4.55]],"ltp":2.4,"tv":0.21,"id":31374}]}]}
{"op":"mcm","clk":"11798615400","pt":1723154246684,"mc":[{"id":"1.231540814","rc":[{"batb":[[0,2.32,4],[1,2.3,10],[2,2.28,29.61]],"ltp":2.4,"tv":0.21,"id":31374}]}]}
{"op":"mcm","clk":"11798615452","pt":1723154248423,"mc":[{"id":"1.231540814","rc":[{"batb":[[1,2.28,29.61],[2,2.02,4.55]],"ltp":2.4,"tv":0.21,"id":31374}]}]}
{"op":"mcm","clk":"11798615472","pt":1723154248990,"mc":[{"id":"1.231540814","rc":[{"batb":[[0,2.28,29.61],[1,2.02,4.55],[2,1.8,2]],"ltp":2.4,"tv":0.21,"id":31374}]}]}
{"op":"mcm","clk":"11798615554","pt":1723154251601,"mc":[{"id":"1.231540814","rc":[{"batb":[[0,2.3,14],[1,2.28,29.61],[2,2.02,4.55]],"ltp":2.4,"tv":0.21,"id":31374}]}]}
{"op":"mcm","clk":"11798615638","pt":1723154254111,"mc":[{"id":"1.231540814","rc":[{"batb":[[0,2.3,10]],"ltp":2.4,"tv":0.21,"id":31374}]}]}
{"op":"mcm","clk":"11798615681","pt":1723154255094,"mc":[{"id":"1.231540814","rc":[{"batb":[[0,2.28,29.61],[1,2.02,4.55],[2,1.8,2]],"ltp":2.4,"tv":0.21,"id":31374}]}]}
{"op":"mcm","clk":"11798615724","pt":1723154256420,"mc":[{"id":"1.231540814","rc":[{"batb":[[0,2.3,4],[1,2.28,29.61],[2,2.02,4.55]],"ltp":2.4,"tv":0.21,"id":31374}]}]}
{"op":"mcm","clk":"11798615765","pt":1723154257603,"mc":[{"id":"1.231540814","rc":[{"batb":[[0,2.32,10],[1,2.3,4],[2,2.28,29.61]],"ltp":2.4,"tv":0.21,"id":31374}]}]}
{"op":"mcm","clk":"11798615804","pt":1723154258731,"mc":[{"id":"1.231540814","rc":[{"batb":[[1,2.28,29.61],[2,2.02,4.55]],"ltp":2.4,"tv":0.21,"id":31374}]}]}
{"op":"mcm","clk":"11798615880","pt":1723154261194,"mc":[{"id":"1.231540814","rc":[{"batb":[[0,2.34,4]],"ltp":2.4,"tv":0.21,"id":31374}]}]}
{"op":"mcm","clk":"11798615961","pt":1723154263601,"mc":[{"id":"1.231540814","rc":[{"batb":[[0,2.28,29.61],[1,2.02,4.55],[2,1.8,2]],"ltp":2.4,"tv":0.21,"id":31374}]}]}
{"op":"mcm","clk":"11798615969","pt":1723154263806,"mc":[{"id":"1.231540814","rc":[{"batb":[[0,2.3,10],[1,2.28,29.61],[2,2.02,4.55]],"ltp":2.4,"tv":0.21,"id":31374}]}]}
{"op":"mcm","clk":"11798616084","pt":1723154267135,"mc":[{"id":"1.231540814","rc":[{"batb":[[0,2.32,4]],"ltp":2.4,"tv":0.21,"id":31374}]}]}
{"op":"mcm","clk":"11798616157","pt":1723154269334,"mc":[{"id":"1.231540814","rc":[{"batb":[[0,2.3,10]],"ltp":2.4,"tv":0.21,"id":31374}]}]}
{"op":"mcm","clk":"11798616230","pt":1723154271696,"mc":[{"id":"1.231540814","rc":[{"batb":[[0,2.32,4],[1,2.3,10],[2,2.28,29.61]],"ltp":2.4,"tv":0.21,"id":31374}]}]}
{"op":"mcm","clk":"11798616269","pt":1723154272616,"mc":[{"id":"1.231540814","rc":[{"batb":[[1,2.28,29.61],[2,2.02,4.55]],"ltp":2.4,"tv":0.21,"id":31374}]}]}
{"op":"mcm","clk":"11798616303","pt":1723154273998,"mc":[{"id":"1.231540814","rc":[{"batb":[[0,2.28,29.61],[1,2.02,4.55],[2,1.8,2]],"ltp":2.4,"tv":0.21,"id":31374}]}]}
{"op":"mcm","clk":"11798616338","pt":1723154275228,"mc":[{"id":"1.231540814","rc":[{"batb":[[0,2.3,10],[1,2.28,29.61],[2,2.02,4.55]],"ltp":2.4,"tv":0.21,"id":31374}]}]}
{"op":"mcm","clk":"11798616446","pt":1723154278617,"mc":[{"id":"1.231540814","rc":[{"batb":[[0,2.28,29.61],[1,2.02,4.55],[2,1.8,2]],"ltp":2.4,"tv":0.21,"id":31374}]}]}
{"op":"mcm","clk":"11798616452","pt":1723154278820,"mc":[{"id":"1.231540814","rc":[{"batb":[[0,2.3,4],[1,2.28,29.61],[2,2.02,4.55]],"ltp":2.4,"tv":0.21,"id":31374}]}]}
{"op":"mcm","clk":"11798616540","pt":1723154281022,"mc":[{"id":"1.231540814","rc":[{"batb":[[0,2.32,10]],"ltp":2.4,"tv":0.21,"id":31374}]}]}
{"op":"mcm","clk":"11798616669","pt":1723154284458,"mc":[{"id":"1.231540814","rc":[{"batb":[[0,2.3,4]],"ltp":2.4,"tv":0.21,"id":31374}]}]}
{"op":"mcm","clk":"11798616746","pt":1723154286817,"mc":[{"id":"1.231540814","rc":[{"batb":[[0,2.34,10],[1,2.32,4.41],[2,2.28,29.61]],"ltp":2.4,"tv":0.21,"id":31374}]}]}
{"op":"mcm","clk":"11798616843","pt":1723154290045,"mc":[{"id":"1.231540814","rc":[{"batb":[[0,2.36,4],[1,2.28,29.61],[2,2.02,4.55]],"ltp":2.4,"tv":0.21,"id":31374}]}]}
{"op":"mcm","clk":"11798616925","pt":1723154292248,"mc":[{"id":"1.231540814","rc":[{"batb":[[0,2.3,10]],"ltp":2.4,"tv":0.21,"id":31374}]}]}
{"op":"mcm","clk":"11798616997","pt":1723154294354,"mc":[{"id":"1.231540814","rc":[{"batb":[[0,2.32,4],[1,2.3,10],[2,2.28,29.61]],"ltp":2.4,"tv":0.21,"id":31374}]}]}
{"op":"mcm","clk":"11798617042","pt":1723154295531,"mc":[{"id":"1.231540814","rc":[{"batb":[[1,2.28,29.61],[2,2.02,4.55]],"ltp":2.4,"tv":0.21,"id":31374}]}]}
{"op":"mcm","clk":"11798617094","pt":1723154296765,"mc":[{"id":"1.231540814","rc":[{"batb":[[0,2.28,29.61],[1,2.02,4.55],[2,1.8,2]],"ltp":2.4,"tv":0.21,"id":31374}]}]}
{"op":"mcm","clk":"11798617183","pt":1723154299332,"mc":[{"id":"1.231540814","rc":[{"batb":[[0,2.3,14],[1,2.28,29.61],[2,2.02,4.55]],"ltp":2.4,"tv":0.21,"id":31374}]}]}
{"op":"mcm","clk":"11798617290","pt":1723154302668,"mc":[{"id":"1.231540814","rc":[{"batb":[[0,2.28,29.61],[1,2.02,4.55],[2,1.8,2]],"ltp":2.4,"tv":0.21,"id":31374}]}]}
{"op":"mcm","clk":"11798617371","pt":1723154305177,"mc":[{"id":"1.231540814","rc":[{"batb":[[0,2.3,14],[1,2.28,29.61],[2,2.02,4.55]],"ltp":2.4,"tv":0.21,"id":31374}]}]}
{"op":"mcm","clk":"11798617435","pt":1723154307381,"mc":[{"id":"1.231540814","rc":[{"batb":[[0,2.3,10]],"ltp":2.4,"tv":0.21,"id":31374}]}]}
{"op":"mcm","clk":"11798617467","pt":1723154308557,"mc":[{"id":"1.231540814","rc":[{"batb":[[0,2.28,29.61],[1,2.02,4.55],[2,1.8,2]],"ltp":2.4,"tv":0.21,"id":31374}]}]}
{"op":"mcm","clk":"11798617496","pt":1723154309785,"mc":[{"id":"1.231540814","rc":[{"batb":[[0,2.3,4],[1,2.28,29.61],[2,2.02,4.55]],"ltp":2.4,"tv":0.21,"id":31374}]}]}
{"op":"mcm","clk":"11798617547","pt":1723154310971,"mc":[{"id":"1.231540814","rc":[{"batb":[[0,2.32,10],[1,2.3,4],[2,2.28,29.61]],"ltp":2.4,"tv":0.21,"id":31374}]}]}
{"op":"mcm","clk":"11798617597","pt":1723154312156,"mc":[{"id":"1.231540814","rc":[{"batb":[[1,2.28,29.61],[2,2.02,4.55]],"ltp":2.4,"tv":0.21,"id":31374}]}]}
{"op":"mcm","clk":"11798617674","pt":1723154314262,"mc":[{"id":"1.231540814","rc":[{"batb":[[0,2.3,4]],"ltp":2.4,"tv":0.21,"id":31374}]}]}
{"op":"mcm","clk":"11798617757","pt":1723154316880,"mc":[{"id":"1.231540814","rc":[{"batb":[[0,2.3,10]],"ltp":2.4,"tv":0.21,"id":31374}]}]}
{"op":"mcm","clk":"11798617813","pt":1723154319090,"mc":[{"id":"1.231540814","rc":[{"batb":[[0,2.32,4],[1,2.3,10],[2,2.28,29.61]],"ltp":2.4,"tv":0.21,"id":31374}]}]}
{"op":"mcm","clk":"11798617843","pt":1723154320071,"mc":[{"id":"1.231540814","rc":[{"batb":[[1,2.28,29.61],[2,2.02,4.55]],"ltp":2.4,"tv":0.21,"id":31374}]}]}
{"op":"mcm","clk":"11798617895","pt":1723154321456,"mc":[{"id":"1.231540814","rc":[{"batb":[[0,2.28,29.61],[1,2.02,4.55],[2,1.8,2]],"ltp":2.4,"tv":0.21,"id":31374}]}]}
{"op":"mcm","clk":"11798618051","pt":1723154325763,"mc":[{"id":"1.231540814","rc":[{"batb":[[0,2.3,14],[1,2.28,29.61],[2,2.02,4.55]],"ltp":2.4,"tv":0.21,"id":31374}]}]}
{"op":"mcm","clk":"11798618127","pt":1723154328170,"mc":[{"id":"1.231540814","rc":[{"batb":[[0,2.3,10]],"ltp":2.4,"tv":0.21,"id":31374}]}]}
{"op":"mcm","clk":"11798618156","pt":1723154329193,"mc":[{"id":"1.231540814","rc":[{"batb":[[0,2.28,29.61],[1,2.02,4.55],[2,1.8,2]],"ltp":2.4,"tv":0.21,"id":31374}]}]}
{"op":"mcm","clk":"11798618187","pt":1723154330571,"mc":[{"id":"1.231540814","rc":[{"batb":[[0,2.3,4],[1,2.28,29.61],[2,2.02,4.55]],"ltp":2.4,"tv":0.21,"id":31374}]}]}
{"op":"mcm","clk":"11798618263","pt":1723154333081,"mc":[{"id":"1.231540814","rc":[{"batb":[[0,2.3,10]],"ltp":2.4,"tv":0.21,"id":31374}]}]}
{"op":"mcm","clk":"11798618330","pt":1723154335384,"mc":[{"id":"1.231540814","rc":[{"batb":[[0,2.32,4],[1,2.3,10],[2,2.28,29.61]],"ltp":2.4,"tv":0.21,"id":31374}]}]}
{"op":"mcm","clk":"11798618360","pt":1723154336509,"mc":[{"id":"1.231540814","rc":[{"batb":[[1,2.28,29.61],[2,2.02,4.55]],"ltp":2.4,"tv":0.21,"id":31374}]}]}
{"op":"mcm","clk":"11798618400","pt":1723154337794,"mc":[{"id":"1.231540814","rc":[{"batb":[[0,2.28,29.61],[1,2.02,4.55],[2,1.8,2]],"ltp":2.4,"tv":0.21,"id":31374}]}]}
{"op":"mcm","clk":"11798618423","pt":1723154339020,"mc":[{"id":"1.231540814","rc":[{"batb":[[0,2.3,10],[1,2.28,29.61],[2,2.02,4.55]],"ltp":2.4,"tv":0.21,"id":31374}]}]}
{"op":"mcm","clk":"11798618461","pt":1723154340198,"mc":[{"id":"1.231540814","rc":[{"batb":[[0,2.32,4],[1,2.3,10],[2,2.28,29.61]],"ltp":2.4,"tv":0.21,"id":31374}]}]}
{"op":"mcm","clk":"11798618539","pt":1723154342713,"mc":[{"id":"1.231540814","rc":[{"batb":[[0,2.28,29.61],[1,2.02,4.55],[2,1.8,2]],"ltp":2.4,"tv":0.21,"id":31374}]}]}
{"op":"mcm","clk":"11798618655","pt":1723154345995,"mc":[{"id":"1.231540814","rc":[{"batb":[[0,2.3,14],[1,2.28,29.61],[2,2.02,4.55]],"ltp":2.4,"tv":0.21,"id":31374}]}]}
{"op":"mcm","clk":"11798618706","pt":1723154348405,"mc":[{"id":"1.231540814","rc":[{"batb":[[0,2.3,10]],"ltp":2.4,"tv":0.21,"id":31374}]}]}
{"op":"mcm","clk":"11798618732","pt":1723154349326,"mc":[{"id":"1.231540814","rc":[{"batb":[[0,2.28,29.61],[1,2.02,4.55],[2,1.8,2]],"ltp":2.4,"tv":0.21,"id":31374}]}]}
{"op":"mcm","clk":"11798618771","pt":1723154350610,"mc":[{"id":"1.231540814","rc":[{"batb":[[0,2.3,4],[1,2.28,29.61],[2,2.02,4.55]],"ltp":2.4,"tv":0.21,"id":31374}]}]}
{"op":"mcm","clk":"11798618811","pt":1723154351890,"mc":[{"id":"1.231540814","rc":[{"batb":[[0,2.32,10],[1,2.3,4],[2,2.28,29.61]],"ltp":2.4,"tv":0.21,"id":31374}]}]}
{"op":"mcm","clk":"11798618846","pt":1723154352918,"mc":[{"id":"1.231540814","rc":[{"batb":[[1,2.28,29.61],[2,2.02,4.55]],"ltp":2.4,"tv":0.21,"id":31374}]}]}
{"op":"mcm","clk":"11798618919","pt":1723154355429,"mc":[{"id":"1.231540814","rc":[{"batb":[[0,2.3,4]],"ltp":2.4,"tv":0.21,"id":31374}]}]}
{"op":"mcm","clk":"11798618986","pt":1723154357734,"mc":[{"id":"1.231540814","rc":[{"batb":[[0,2.28,29.61],[1,2.02,4.55],[2,1.8,2]],"ltp":2.4,"tv":0.21,"id":31374}]}]}
{"op":"mcm","clk":"11798618993","pt":1723154357789,"mc":[{"id":"1.231540814","rc":[{"batb":[[0,2.3,10],[1,2.28,29.61],[2,2.02,4.55]],"ltp":2.4,"tv":0.21,"id":31374}]}]}
{"op":"mcm","clk":"11798619078","pt":1723154360099,"mc":[{"id":"1.231540814","rc":[{"batb":[[0,2.32,4],[1,2.3,10],[2,2.28,29.61]],"ltp":2.4,"tv":0.21,"id":31374}]}]}
{"op":"mcm","clk":"11798619114","pt":1723154361227,"mc":[{"id":"1.231540814","rc":[{"batb":[[1,2.28,29.61],[2,2.02,4.55]],"ltp":2.4,"tv":0.21,"id":31374}]}]}
{"op":"mcm","clk":"11798619161","pt":1723154362410,"mc":[{"id":"1.231540814","rc":[{"batb":[[0,2.28,29.61],[1,2.02,4.55],[2,1.8,2]],"ltp":2.4,"tv":0.21,"id":31374}]}]}
{"op":"mcm","clk":"11798619198","pt":1723154363739,"mc":[{"id":"1.231540814","rc":[{"batb":[[0,2.3,10],[1,2.28,29.61],[2,2.02,4.55]],"ltp":2.4,"tv":0.21,"id":31374}]}]}
{"op":"mcm","clk":"11798619303","pt":1723154367222,"mc":[{"id":"1.231540814","rc":[{"batb":[[0,2.3,4]],"ltp":2.4,"tv":0.21,"id":31374}]}]}
{"op":"mcm","clk":"11798619373","pt":1723154369626,"mc":[{"id":"1.231540814","rc":[{"batb":[[0,2.32,10]],"ltp":2.4,"tv":0.21,"id":31374}]}]}
{"op":"mcm","clk":"11798619437","pt":1723154371918,"mc":[{"id":"1.231540814","rc":[{"batb":[[0,2.34,4],[1,2.32,10],[2,2.28,29.61]],"ltp":2.4,"tv":0.21,"id":31374}]}]}
{"op":"mcm","clk":"11798619475","pt":1723154372942,"mc":[{"id":"1.231540814","rc":[{"batb":[[1,2.28,29.61],[2,2.02,4.55]],"ltp":2.4,"tv":0.21,"id":31374}]}]}
{"op":"mcm","clk":"11798619516","pt":1723154374225,"mc":[{"id":"1.231540814","rc":[{"batb":[[0,2.28,29.61],[1,2.02,4.55],[2,1.8,2]],"ltp":2.4,"tv":0.21,"id":31374}]}]}
{"op":"mcm","clk":"11798619553","pt":1723154375454,"mc":[{"id":"1.231540814","rc":[{"batb":[[0,2.3,10],[1,2.28,29.61],[2,2.02,4.55]],"ltp":2.4,"tv":0.21,"id":31374}]}]}
{"op":"mcm","clk":"11798619624","pt":1723154378626,"mc":[{"id":"1.231540814","rc":[{"batb":[[0,2.28,29.61],[1,2.02,4.55],[2,1.8,2]],"ltp":2.4,"tv":0.21,"id":31374}]}]}
{"op":"mcm","clk":"11798620255","pt":1723154400327,"mc":[{"id":"1.231540814","rc":[{"batb":[[0,2.3,14],[1,2.28,29.61],[2,2.02,4.55]],"ltp":2.4,"tv":0.21,"id":31374}]}]}
{"op":"mcm","clk":"11798620381","pt":1723154403660,"mc":[{"id":"1.231540814","rc":[{"batb":[[0,2.28,29.61],[1,2.02,4.55],[2,1.8,2]],"ltp":2.4,"tv":0.21,"id":31374}]}]}
{"op":"mcm","clk":"11798620447","pt":1723154405050,"mc":[{"id":"1.231540814","rc":[{"batb":[[0,2.3,4],[1,2.28,29.61],[2,2.02,4.55]],"ltp":2.4,"tv":0.21,"id":31374}]}]}
{"op":"mcm","clk":"11798620507","pt":1723154406388,"mc":[{"id":"1.231540814","rc":[{"batl":[[1,1.77,320.68]],"ltp":1.76,"tv":387.12,"id":3961},{"batb":[[0,2.32,10],[1,2.3,4],[2,2.28,29.61]],"ltp":2.4,"tv":0.21,"id":31374}]}]}
{"op":"mcm","clk":"11798620538","pt":1723154407354,"mc":[{"id":"1.231540814","rc":[{"batb":[[1,2.28,29.61],[2,2.02,4.55]],"ltp":2.4,"tv":0.21,"id":31374}]}]}
{"op":"mcm","clk":"11798620628","pt":1723154409671,"mc":[{"id":"1.231540814","rc":[{"batb":[[0,2.28,29.61],[1,2.02,4.55],[2,1.8,2]],"ltp":2.4,"tv":0.21,"id":31374}]}]}
{"op":"mcm","clk":"11798620635","pt":1723154409875,"mc":[{"id":"1.231540814","rc":[{"batb":[[0,2.3,4],[1,2.28,29.61],[2,2.02,4.55]],"ltp":2.4,"tv":0.21,"id":31374}]}]}
{"op":"mcm","clk":"11798620717","pt":1723154412042,"mc":[{"id":"1.231540814","rc":[{"batb":[[0,2.32,10]],"ltp":2.4,"tv":0.21,"id":31374}]}]}
{"op":"mcm","clk":"11798620781","pt":1723154414455,"mc":[{"id":"1.231540814","rc":[{"batb":[[0,2.34,4],[1,2.32,10],[2,2.28,29.61]],"ltp":2.4,"tv":0.21,"id":31374}]}]}
{"op":"mcm","clk":"11798620809","pt":1723154415379,"mc":[{"id":"1.231540814","rc":[{"batb":[[1,2.28,29.61],[2,2.02,4.55]],"ltp":2.4,"tv":0.21,"id":31374}]}]}
{"op":"mcm","clk":"11798620859","pt":1723154416665,"mc":[{"id":"1.231540814","rc":[{"batb":[[0,2.28,29.61],[1,2.02,4.55],[2,1.8,2]],"ltp":2.4,"tv":0.21,"id":31374}]}]}
{"op":"mcm","clk":"11798620906","pt":1723154417851,"mc":[{"id":"1.231540814","rc":[{"batb":[[0,2.3,10],[1,2.28,29.61],[2,2.02,4.55]],"ltp":2.4,"tv":0.21,"id":31374}]}]}
{"op":"mcm","clk":"11798620966","pt":1723154419390,"mc":[{"id":"1.231540814","rc":[{"batb":[[0,2.32,4],[1,2.3,10],[2,2.28,29.61]],"ltp":2.4,"tv":0.21,"id":31374}]}]}
{"op":"mcm","clk":"11798621047","pt":1723154421654,"mc":[{"id":"1.231540814","rc":[{"batb":[[0,2.28,29.61],[1,2.02,4.55],[2,1.8,2]],"ltp":2.4,"tv":0.21,"id":31374}]}]}
{"op":"mcm","clk":"11798621166","pt":1723154424586,"mc":[{"id":"1.231540814","rc":[{"batb":[[0,2.32,4.91],[1,2.3,14],[2,2.28,29.61]],"ltp":2.4,"tv":0.21,"id":31374}]}]}
{"op":"mcm","clk":"11798621230","pt":1723154426387,"mc":[{"id":"1.231540814","rc":[{"batb":[[1,2.3,10]],"ltp":2.4,"tv":0.21,"id":31374}]}]}
{"op":"mcm","clk":"11798621272","pt":1723154427372,"mc":[{"id":"1.231540814","rc":[{"batb":[[1,2.28,29.61],[2,2.02,4.55]],"ltp":2.4,"tv":0.21,"id":31374}]}]}
{"op":"mcm","clk":"11798621329","pt":1723154428603,"mc":[{"id":"1.231540814","rc":[{"batb":[[0,2.34,4],[1,2.32,4.91],[2,2.28,29.61]],"ltp":2.4,"tv":0.21,"id":31374}]}]}
{"op":"mcm","clk":"11798621388","pt":1723154429987,"mc":[{"id":"1.231540814","rc":[{"batb":[[0,2.36,10],[1,2.34,4],[2,2.32,4.91]],"ltp":2.4,"tv":0.21,"id":31374}]}]}
{"op":"mcm","clk":"11798621455","pt":1723154431683,"mc":[{"id":"1.231540814","rc":[{"batb":[[1,2.28,29.61],[2,2.02,4.55]],"ltp":2.4,"tv":0.21,"id":31374}]}]}
{"op":"mcm","clk":"11798621539","pt":1723154433375,"mc":[{"id":"1.231540814","rc":[{"batb":[[0,2.3,4]],"ltp":2.4,"tv":0.21,"id":31374}]}]}
{"op":"mcm","clk":"11798621638","pt":1723154435696,"mc":[{"id":"1.231540814","rc":[{"batb":[[0,2.3,10]],"ltp":2.4,"tv":0.21,"id":31374}]}]}
{"op":"mcm","clk":"11798621721","pt":1723154438087,"mc":[{"id":"1.231540814","rc":[{"batb":[[0,2.32,4],[1,2.3,10],[2,2.28,29.61]],"ltp":2.4,"tv":0.21,"id":31374}]}]}
{"op":"mcm","clk":"11798621766","pt":1723154439164,"mc":[{"id":"1.231540814","rc":[{"batb":[[1,2.28,29.61],[2,2.02,4.55]],"ltp":2.4,"tv":0.21,"id":31374}]}]}
{"op":"mcm","clk":"11798621811","pt":1723154440599,"mc":[{"id":"1.231540814","rc":[{"batb":[[0,2.28,29.61],[1,2.02,4.55],[2,1.8,2]],"ltp":2.4,"tv":0.21,"id":31374}]}]}
{"op":"mcm","clk":"11798621901","pt":1723154442809,"mc":[{"id":"1.231540814","rc":[{"batb":[[0,2.3,14],[1,2.28,29.61],[2,2.02,4.55]],"ltp":2.4,"tv":0.21,"id":31374}]}]}
{"op":"mcm","clk":"11798622005","pt":1723154445173,"mc":[{"id":"1.231540814","rc":[{"batb":[[0,2.3,10]],"ltp":2.4,"tv":0.21,"id":31374}]}]}
{"op":"mcm","clk":"11798622050","pt":1723154446201,"mc":[{"id":"1.231540814","rc":[{"batb":[[0,2.28,29.61],[1,2.02,4.55],[2,1.8,2]],"ltp":2.4,"tv":0.21,"id":31374}]}]}
{"op":"mcm","clk":"11798622150","pt":1723154448712,"mc":[{"id":"1.231540814","rc":[{"batb":[[0,2.3,14],[1,2.28,29.61],[2,2.02,4.55]],"ltp":2.4,"tv":0.21,"id":31374}]}]}
{"op":"mcm","clk":"11798622229","pt":1723154451072,"mc":[{"id":"1.231540814","rc":[{"batb":[[0,2.3,10]],"ltp":2.4,"tv":0.21,"id":31374}]}]}
{"op":"mcm","clk":"11798622260","pt":1723154452096,"mc":[{"id":"1.231540814","rc":[{"batb":[[0,2.28,29.61],[1,2.02,4.55],[2,1.8,2]],"ltp":2.4,"tv":0.21,"id":31374}]}]}
{"op":"mcm","clk":"11798622310","pt":1723154453277,"mc":[{"id":"1.231540814","rc":[{"batb":[[0,2.3,4],[1,2.28,29.61],[2,2.02,4.55]],"ltp":2.4,"tv":0.21,"id":31374}]}]}
{"op":"mcm","clk":"11798622368","pt":1723154454612,"mc":[{"id":"1.231540814","rc":[{"batb":[[0,2.32,10],[1,2.3,4],[2,2.28,29.61]],"ltp":2.4,"tv":0.21,"id":31374}]}]}
{"op":"mcm","clk":"11798622398","pt":1723154455591,"mc":[{"id":"1.231540814","rc":[{"batb":[[1,2.28,29.61],[2,2.02,4.55]],"ltp":2.4,"tv":0.21,"id":31374}]}]}
{"op":"mcm","clk":"11798622500","pt":1723154457694,"mc":[{"id":"1.231540814","rc":[{"batb":[[0,2.28,29.61],[1,2.02,4.55],[2,1.8,2]],"ltp":2.4,"tv":0.21,"id":31374}]}]}
{"op":"mcm","clk":"11798622506","pt":1723154457797,"mc":[{"id":"1.231540814","rc":[{"batb":[[0,2.34,4],[1,2.28,29.61],[2,2.02,4.55]],"ltp":2.4,"tv":0.21,"id":31374}]}]}
{"op":"mcm","clk":"11798622596","pt":1723154460107,"mc":[{"id":"1.231540814","rc":[{"batb":[[0,2.36,10]],"ltp":2.4,"tv":0.21,"id":31374}]}]}
{"op":"mcm","clk":"11798622727","pt":1723154463496,"mc":[{"id":"1.231540814","rc":[{"batb":[[0,2.3,4]],"ltp":2.4,"tv":0.21,"id":31374}]}]}
{"op":"mcm","clk":"11798622817","pt":1723154465916,"mc":[{"id":"1.231540814","rc":[{"batb":[[0,2.3,10]],"ltp":2.4,"tv":0.21,"id":31374}]}]}
{"op":"mcm","clk":"11798622940","pt":1723154469195,"mc":[{"id":"1.231540814","rc":[{"batb":[[0,2.3,4]],"ltp":2.4,"tv":0.21,"id":31374}]}]}
{"op":"mcm","clk":"11798623042","pt":1723154471514,"mc":[{"id":"1.231540814","rc":[{"batb":[[0,2.3,10]],"ltp":2.4,"tv":0.21,"id":31374}]}]}
{"op":"mcm","clk":"11798623153","pt":1723154474602,"mc":[{"id":"1.231540814","rc":[{"batb":[[0,2.32,4],[1,2.3,10],[2,2.28,29.61]],"ltp":2.4,"tv":0.21,"id":31374}]}]}
{"op":"mcm","clk":"11798623160","pt":1723154474809,"mc":[{"id":"1.231540814","rc":[{"batb":[[1,2.28,29.61],[2,2.02,4.55]],"ltp":2.4,"tv":0.21,"id":31374}]}]}
{"op":"mcm","clk":"11798623233","pt":1723154476813,"mc":[{"id":"1.231540814","rc":[{"batb":[[0,2.28,29.61],[1,2.02,4.55],[2,1.8,2]],"ltp":2.4,"tv":0.21,"id":31374}]}]}
{"op":"mcm","clk":"11798623271","pt":1723154477994,"mc":[{"id":"1.231540814","rc":[{"batb":[[0,2.3,10],[1,2.28,29.61],[2,2.02,4.55]],"ltp":2.4,"tv":0.21,"id":31374}]}]}
{"op":"mcm","clk":"11798623310","pt":1723154479227,"mc":[{"id":"1.231540814","rc":[{"batb":[[0,2.32,4],[1,2.3,10],[2,2.28,29.61]],"ltp":2.4,"tv":0.21,"id":31374}]}]}
{"op":"mcm","clk":"11798623392","pt":1723154481541,"mc":[{"id":"1.231540814","rc":[{"batb":[[0,2.28,29.61],[1,2.02,4.55],[2,1.8,2]],"ltp":2.4,"tv":0.21,"id":31374}]}]}
{"op":"mcm","clk":"11798623489","pt":1723154483906,"mc":[{"id":"1.231540814","rc":[{"batb":[[0,2.3,14],[1,2.28,29.61],[2,2.02,4.55]],"ltp":2.4,"tv":0.21,"id":31374}]}]}
{"op":"mcm","clk":"11798623600","pt":1723154486243,"mc":[{"id":"1.231540814","rc":[{"batb":[[0,2.3,10]],"ltp":2.4,"tv":0.21,"id":31374}]}]}
{"op":"mcm","clk":"11798623645","pt":1723154487217,"mc":[{"id":"1.231540814","rc":[{"batb":[[0,2.28,29.61],[1,2.02,4.55],[2,1.8,2]],"ltp":2.4,"tv":0.21,"id":31374}]}]}
{"op":"mcm","clk":"11798623835","pt":1723154490821,"mc":[{"id":"1.231540814","rc":[{"batb":[[0,2.3,14],[1,2.28,29.61],[2,2.02,4.55]],"ltp":2.4,"tv":0.21,"id":31374}]}]}
{"op":"mcm","clk":"11798623933","pt":1723154493128,"mc":[{"id":"1.231540814","rc":[{"batb":[[0,2.3,10]],"ltp":2.4,"tv":0.21,"id":31374}]}]}
{"op":"mcm","clk":"11798623960","pt":1723154494156,"mc":[{"id":"1.231540814","rc":[{"batb":[[0,2.28,29.61],[1,2.02,4.55],[2,1.8,2]],"ltp":2.4,"tv":0.21,"id":31374}]}]}
{"op":"mcm","clk":"11798624016","pt":1723154495512,"mc":[{"id":"1.231540814","rc":[{"batb":[[0,2.3,4],[1,2.28,29.61],[2,2.02,4.55]],"ltp":2.4,"tv":0.21,"id":31374}]}]}
{"op":"mcm","clk":"11798624059","pt":1723154496846,"mc":[{"id":"1.231540814","rc":[{"batb":[[0,2.32,10],[1,2.3,4],[2,2.28,29.61]],"ltp":2.4,"tv":0.21,"id":31374}]}]}
{"op":"mcm","clk":"11798624091","pt":1723154497828,"mc":[{"id":"1.231540814","rc":[{"batb":[[1,2.28,29.61],[2,2.02,4.55]],"ltp":2.4,"tv":0.21,"id":31374}]}]}
{"op":"mcm","clk":"11798624192","pt":1723154500339,"mc":[{"id":"1.231540814","rc":[{"batb":[[0,2.3,4]],"ltp":2.4,"tv":0.21,"id":31374}]}]}
{"op":"mcm","clk":"11798624271","pt":1723154502649,"mc":[{"id":"1.231540814","rc":[{"batb":[[0,2.32,10]],"ltp":2.4,"tv":0.21,"id":31374}]}]}
{"op":"mcm","clk":"11798624367","pt":1723154505732,"mc":[{"id":"1.231540814","rc":[{"batb":[[0,2.28,29.61],[1,2.02,4.55],[2,1.8,2]],"ltp":2.4,"tv":0.21,"id":31374}]}]}
{"op":"mcm","clk":"11798624371","pt":1723154505834,"mc":[{"id":"1.231540814","rc":[{"batb":[[0,2.3,4],[1,2.28,29.61],[2,2.02,4.55]],"ltp":2.4,"tv":0.21,"id":31374}]}]}
{"op":"mcm","clk":"11798624432","pt":1723154508449,"mc":[{"id":"1.231540814","rc":[{"batb":[[0,2.3,10]],"ltp":2.4,"tv":0.21,"id":31374}]}]}
{"op":"mcm","clk":"11798624535","pt":1723154511677,"mc":[{"id":"1.231540814","rc":[{"batb":[[0,2.32,4]],"ltp":2.4,"tv":0.21,"id":31374}]}]}
{"op":"mcm","clk":"11798624601","pt":1723154514040,"mc":[{"id":"1.231540814","rc":[{"batb":[[0,2.3,10]],"ltp":2.4,"tv":0.21,"id":31374}]}]}
{"op":"mcm","clk":"11798624657","pt":1723154516147,"mc":[{"id":"1.231540814","rc":[{"batb":[[0,2.32,4],[1,2.3,10],[2,2.28,29.61]],"ltp":2.4,"tv":0.21,"id":31374}]}]}
{"op":"mcm","clk":"11798624687","pt":1723154517478,"mc":[{"id":"1.231540814","rc":[{"batb":[[1,2.28,29.61],[2,2.02,4.55]],"ltp":2.4,"tv":0.21,"id":31374}]}]}
{"op":"mcm","clk":"11798624712","pt":1723154518349,"mc":[{"id":"1.231540814","rc":[{"batb":[[0,2.28,29.61],[1,2.02,4.55],[2,1.8,2]],"ltp":2.4,"tv":0.21,"id":31374}]}]}
{"op":"mcm","clk":"11798624739","pt":1723154519645,"mc":[{"id":"1.231540814","rc":[{"batb":[[0,2.3,10],[1,2.28,29.61],[2,2.02,4.55]],"ltp":2.4,"tv":0.21,"id":31374}]}]}
{"op":"mcm","clk":"11798624853","pt":1723154523190,"mc":[{"id":"1.231540814","rc":[{"batb":[[0,2.3,4]],"ltp":2.4,"tv":0.21,"id":31374}]}]}
{"op":"mcm","clk":"11798624912","pt":1723154525559,"mc":[{"id":"1.231540814","rc":[{"batb":[[0,2.32,10]],"ltp":2.4,"tv":0.21,"id":31374}]}]}
{"op":"mcm","clk":"11798625007","pt":1723154528069,"mc":[{"id":"1.231540814","rc":[{"batb":[[0,2.34,4],[1,2.32,10],[2,2.28,29.61]],"ltp":2.4,"tv":0.21,"id":31374}]}]}
{"op":"mcm","clk":"11798625040","pt":1723154528891,"mc":[{"id":"1.231540814","rc":[{"batb":[[1,2.28,29.61],[2,2.02,4.55]],"ltp":2.4,"tv":0.21,"id":31374}]}]}
{"op":"mcm","clk":"11798625083","pt":1723154530484,"mc":[{"id":"1.231540814","rc":[{"batb":[[0,2.28,29.61],[1,2.02,4.55],[2,1.8,2]],"ltp":2.4,"tv":0.21,"id":31374}]}]}
{"op":"mcm","clk":"11798625121","pt":1723154531665,"mc":[{"id":"1.231540814","rc":[{"batb":[[0,2.3,10],[1,2.28,29.61],[2,2.02,4.55]],"ltp":2.4,"tv":0.21,"id":31374}]}]}
{"op":"mcm","clk":"11798625179","pt":1723154533260,"mc":[{"id":"1.231540814","rc":[{"batb":[[0,2.32,4],[1,2.3,10],[2,2.28,29.61]],"ltp":2.4,"tv":0.21,"id":31374}]}]}
{"op":"mcm","clk":"11798625266","pt":1723154535671,"mc":[{"id":"1.231540814","rc":[{"batb":[[0,2.28,29.61],[1,2.02,4.55],[2,1.8,2]],"ltp":2.4,"tv":0.21,"id":31374}]}]}
{"op":"mcm","clk":"11798625342","pt":1723154538391,"mc":[{"id":"1.231540814","rc":[{"batb":[[0,2.3,14],[1,2.28,29.61],[2,2.02,4.55]],"ltp":2.4,"tv":0.21,"id":31374}]}]}
{"op":"mcm","clk":"11798625408","pt":1723154540700,"mc":[{"id":"1.231540814","rc":[{"batb":[[0,2.3,10]],"ltp":2.4,"tv":0.21,"id":31374}]}]}
{"op":"mcm","clk":"11798625449","pt":1723154541777,"mc":[{"id":"1.231540814","rc":[{"batb":[[0,2.28,29.61],[1,2.02,4.55],[2,1.8,2]],"ltp":2.4,"tv":0.21,"id":31374}]}]}
{"op":"mcm","clk":"11798625574","pt":1723154545072,"mc":[{"id":"1.231540814","rc":[{"batb":[[0,2.3,14],[1,2.28,29.61],[2,2.02,4.55]],"ltp":2.4,"tv":0.21,"id":31374}]}]}
{"op":"mcm","clk":"11798625651","pt":1723154547586,"mc":[{"id":"1.231540814","rc":[{"batb":[[0,2.3,10]],"ltp":2.4,"tv":0.21,"id":31374}]}]}
{"op":"mcm","clk":"11798625687","pt":1723154548408,"mc":[{"id":"1.231540814","rc":[{"batb":[[0,2.28,29.61],[1,2.02,4.55],[2,1.8,2]],"ltp":2.4,"tv":0.21,"id":31374}]}]}
{"op":"mcm","clk":"11798625725","pt":1723154549791,"mc":[{"id":"1.231540814","rc":[{"batb":[[0,2.3,4],[1,2.28,29.61],[2,2.02,4.55]],"ltp":2.4,"tv":0.21,"id":31374}]}]}
{"op":"mcm","clk":"11798625793","pt":1723154552103,"mc":[{"id":"1.231540814","rc":[{"batb":[[0,2.32,10]],"ltp":2.4,"tv":0.21,"id":31374}]}]}
{"op":"mcm","clk":"11798625860","pt":1723154554615,"mc":[{"id":"1.231540814","rc":[{"batb":[[0,2.34,4],[1,2.32,10],[2,2.28,29.61]],"ltp":2.4,"tv":0.21,"id":31374}]}]}
{"op":"mcm","clk":"11798625886","pt":1723154555285,"mc":[{"id":"1.231540814","rc":[{"batb":[[1,2.28,29.61],[2,2.02,4.55]],"ltp":2.4,"tv":0.21,"id":31374}]}]}
{"op":"mcm","clk":"11798625938","pt":1723154556925,"mc":[{"id":"1.231540814","rc":[{"batb":[[0,2.28,29.61],[1,2.02,4.55],[2,1.8,2]],"ltp":2.4,"tv":0.21,"id":31374}]}]}
{"op":"mcm","clk":"11798625979","pt":1723154558109,"mc":[{"id":"1.231540814","rc":[{"batb":[[0,2.3,10],[1,2.28,29.61],[2,2.02,4.55]],"ltp":2.4,"tv":0.21,"id":31374}]}]}
{"op":"mcm","clk":"11798626048","pt":1723154560010,"mc":[{"id":"1.231540814","rc":[{"batb":[[0,2.32,4],[1,2.3,10],[2,2.28,29.61]],"ltp":2.4,"tv":0.21,"id":31374}]}]}
{"op":"mcm","clk":"11798626099","pt":1723154561500,"mc":[{"id":"1.231540814","rc":[{"batb":[[1,2.28,29.61],[2,2.02,4.55]],"ltp":2.4,"tv":0.21,"id":31374}]}]}
{"op":"mcm","clk":"11798626130","pt":1723154562422,"mc":[{"id":"1.231540814","rc":[{"batb":[[0,2.28,29.61],[1,2.02,4.55],[2,1.8,2]],"ltp":2.4,"tv":0.21,"id":31374}]}]}
{"op":"mcm","clk":"11798626206","pt":1723154564625,"mc":[{"id":"1.231540814","rc":[{"batb":[[0,2.3,14],[1,2.28,29.61],[2,2.02,4.55]],"ltp":2.4,"tv":0.21,"id":31374}]}]}
{"op":"mcm","clk":"11798626270","pt":1723154566891,"mc":[{"id":"1.231540814","rc":[{"batb":[[0,2.3,10]],"ltp":2.4,"tv":0.21,"id":31374}]}]}
{"op":"mcm","clk":"11798626316","pt":1723154568020,"mc":[{"id":"1.231540814","rc":[{"batb":[[0,2.28,29.61],[1,2.02,4.55],[2,1.8,2]],"ltp":2.4,"tv":0.21,"id":31374}]}]}
{"op":"mcm","clk":"11798626348","pt":1723154569200,"mc":[{"id":"1.231540814","rc":[{"batb":[[0,2.3,4],[1,2.28,29.61],[2,2.02,4.55]],"ltp":2.4,"tv":0.21,"id":31374}]}]}
{"op":"mcm","clk":"11798626381","pt":1723154570329,"mc":[{"id":"1.231540814","rc":[{"batb":[[0,2.32,10],[1,2.3,4],[2,2.28,29.61]],"ltp":2.4,"tv":0.21,"id":31374}]}]}
{"op":"mcm","clk":"11798626414","pt":1723154571614,"mc":[{"id":"1.231540814","rc":[{"batb":[[1,2.28,29.61],[2,2.02,4.55]],"ltp":2.4,"tv":0.21,"id":31374}]}]}
{"op":"mcm","clk":"11798626473","pt":1723154573618,"mc":[{"id":"1.231540814","rc":[{"batb":[[0,2.28,29.61],[1,2.02,4.55],[2,1.8,2]],"ltp":2.4,"tv":0.21,"id":31374}]}]}
{"op":"mcm","clk":"11798626514","pt":1723154575003,"mc":[{"id":"1.231540814","rc":[{"batb":[[0,2.3,4],[1,2.28,29.61],[2,2.02,4.55]],"ltp":2.4,"tv":0.21,"id":31374}]}]}
{"op":"mcm","clk":"11798626632","pt":1723154577547,"mc":[{"id":"1.231540814","rc":[{"batb":[[0,2.3,10]],"ltp":2.4,"tv":0.21,"id":31374}]}]}
{"op":"mcm","clk":"11798626874","pt":1723154580941,"mc":[{"id":"1.231540814","rc":[{"batb":[[0,2.32,4]],"ltp":2.4,"tv":0.21,"id":31374}]}]}
{"op":"mcm","clk":"11798626963","pt":1723154583424,"mc":[{"id":"1.231540814","rc":[{"batb":[[0,2.3,10]],"ltp":2.4,"tv":0.21,"id":31374}]}]}
{"op":"mcm","clk":"11798627092","pt":1723154586720,"mc":[{"id":"1.231540814","rc":[{"batb":[[0,2.3,4]],"ltp":2.4,"tv":0.21,"id":31374}]}]}
{"op":"mcm","clk":"11798627183","pt":1723154589332,"mc":[{"id":"1.231540814","rc":[{"batb":[[0,2.34,10],[1,2.32,4.41],[2,2.28,29.61]],"ltp":2.4,"tv":0.21,"id":31374}]}]}
{"op":"mcm","clk":"11798627294","pt":1723154592562,"mc":[{"id":"1.231540814","rc":[{"batb":[[0,2.36,4]],"ltp":2.4,"tv":0.21,"id":31374}]}]}
{"op":"mcm","clk":"11798627374","pt":1723154594725,"mc":[{"id":"1.231540814","rc":[{"trd":[[1.73,4.8]],"batb":[[0,1.72,52.65],[1,1.68,4.55],[2,1.67,33]],"ltp":1.73,"tv":391.93,"id":3961},{"trd":[[2.38,3.49]],"batb":[[0,2.38,6.51]],"ltp":2.38,"tv":3.7,"id":31374}],"tv":395.63}]}
{"op":"mcm","clk":"11798627498","pt":1723154598125,"mc":[{"id":"1.231540814","rc":[{"batb":[[0,2.34,4]],"ltp":2.38,"tv":3.7,"id":31374}]}]}
{"op":"mcm","clk":"11798627586","pt":1723154600536,"mc":[{"id":"1.231540814","rc":[{"batb":[[0,2.34,10]],"ltp":2.38,"tv":3.7,"id":31374}]}]}
{"op":"mcm","clk":"11798627596","pt":1723154601047,"mc":[{"id":"1.231540814","rc":[{"batb":[[1,2.28,29.61],[2,2.02,4.55]],"ltp":2.38,"tv":3.7,"id":31374}]}]}
{"op":"mcm","clk":"11798627675","pt":1723154603868,"mc":[{"id":"1.231540814","rc":[{"batb":[[0,2.3,4]],"ltp":2.38,"tv":3.7,"id":31374}]}]}
{"op":"mcm","clk":"11798627740","pt":1723154606277,"mc":[{"id":"1.231540814","rc":[{"batb":[[0,2.32,10]],"ltp":2.38,"tv":3.7,"id":31374}]}]}
{"op":"mcm","clk":"11798627823","pt":1723154609569,"mc":[{"id":"1.231540814","rc":[{"batb":[[0,2.3,4]],"ltp":2.38,"tv":3.7,"id":31374}]}]}
{"op":"mcm","clk":"11798627905","pt":1723154611936,"mc":[{"id":"1.231540814","rc":[{"batb":[[0,2.3,10]],"ltp":2.38,"tv":3.7,"id":31374}]}]}
{"op":"mcm","clk":"11798628056","pt":1723154615372,"mc":[{"id":"1.231540814","rc":[{"batb":[[0,2.3,4]],"ltp":2.38,"tv":3.7,"id":31374}]}]}
{"op":"mcm","clk":"11798628127","pt":1723154617578,"mc":[{"id":"1.231540814","rc":[{"batb":[[0,2.28,29.61],[1,2.02,4.55],[2,1.8,2]],"ltp":2.38,"tv":3.7,"id":31374}]}]}
{"op":"mcm","clk":"11798628141","pt":1723154617782,"mc":[{"id":"1.231540814","rc":[{"batb":[[0,2.3,10],[1,2.28,29.61],[2,2.02,4.55]],"ltp":2.38,"tv":3.7,"id":31374}]}]}
{"op":"mcm","clk":"11798628248","pt":1723154621380,"mc":[{"id":"1.231540814","rc":[{"batb":[[0,2.32,4]],"ltp":2.38,"tv":3.7,"id":31374}]}]}
{"op":"mcm","clk":"11798628321","pt":1723154623994,"mc":[{"id":"1.231540814","rc":[{"batb":[[0,2.3,10]],"ltp":2.38,"tv":3.7,"id":31374}]}]}
{"op":"mcm","clk":"11798628416","pt":1723154627274,"mc":[{"id":"1.231540814","rc":[{"batb":[[0,2.32,4]],"ltp":2.38,"tv":3.7,"id":31374}]}]}
{"op":"mcm","clk":"11798628490","pt":1723154629480,"mc":[{"id":"1.231540814","rc":[{"batb":[[0,2.34,10]],"ltp":2.38,"tv":3.7,"id":31374}]}]}
{"op":"mcm","clk":"11798628577","pt":1723154632194,"mc":[{"id":"1.231540814","rc":[{"batb":[[0,2.36,4],[1,2.34,10],[2,2.28,29.61]],"ltp":2.38,"tv":3.7,"id":31374}]}]}
{"op":"mcm","clk":"11798628606","pt":1723154632764,"mc":[{"id":"1.231540814","rc":[{"batb":[[1,2.28,29.61],[2,2.02,4.55]],"ltp":2.38,"tv":3.7,"id":31374}]}]}
{"op":"mcm","clk":"11798628664","pt":1723154634504,"mc":[{"id":"1.231540814","rc":[{"batb":[[0,2.28,29.61],[1,2.02,4.55],[2,1.8,2]],"ltp":2.38,"tv":3.7,"id":31374}]}]}
{"op":"mcm","clk":"11798628698","pt":1723154635587,"mc":[{"id":"1.231540814","rc":[{"batb":[[0,2.3,10],[1,2.28,29.61],[2,2.02,4.55]],"ltp":2.38,"tv":3.7,"id":31374}]}]}
{"op":"mcm","clk":"11798628808","pt":1723154639180,"mc":[{"id":"1.231540814","rc":[{"batb":[[0,2.3,4]],"ltp":2.38,"tv":3.7,"id":31374}]}]}
{"op":"mcm","clk":"11798628890","pt":1723154641492,"mc":[{"id":"1.231540814","rc":[{"batb":[[0,2.3,10]],"ltp":2.38,"tv":3.7,"id":31374}]}]}
{"op":"mcm","clk":"11798629011","pt":1723154644886,"mc":[{"id":"1.231540814","rc":[{"batb":[[0,2.32,4]],"ltp":2.38,"tv":3.7,"id":31374}]}]}
{"op":"mcm","clk":"11798629094","pt":1723154647102,"mc":[{"id":"1.231540814","rc":[{"batb":[[0,2.34,10]],"ltp":2.38,"tv":3.7,"id":31374}]}]}
{"op":"mcm","clk":"11798629171","pt":1723154649305,"mc":[{"id":"1.231540814","rc":[{"batb":[[0,2.36,4],[1,2.34,10],[2,2.28,29.61]],"ltp":2.38,"tv":3.7,"id":31374}]}]}
{"op":"mcm","clk":"11798629215","pt":1723154650594,"mc":[{"id":"1.231540814","rc":[{"batb":[[1,2.28,29.61],[2,2.02,4.55]],"ltp":2.38,"tv":3.7,"id":31374}]}]}
{"op":"mcm","clk":"11798629249","pt":1723154651625,"mc":[{"id":"1.231540814","rc":[{"batb":[[0,2.28,29.61],[1,2.02,4.55],[2,1.8,2]],"ltp":2.38,"tv":3.7,"id":31374}]}]}
{"op":"mcm","clk":"11798629306","pt":1723154653220,"mc":[{"id":"1.231540814","rc":[{"batb":[[0,2.3,10],[1,2.28,29.61],[2,2.02,4.55]],"ltp":2.38,"tv":3.7,"id":31374}]}]}
{"op":"mcm","clk":"11798629387","pt":1723154655429,"mc":[{"id":"1.231540814","rc":[{"batb":[[0,2.32,4],[1,2.3,10],[2,2.28,29.61]],"ltp":2.38,"tv":3.7,"id":31374}]}]}
{"op":"mcm","clk":"11798629468","pt":1723154657637,"mc":[{"id":"1.231540814","rc":[{"batb":[[0,2.28,29.61],[1,2.02,4.55],[2,1.8,2]],"ltp":2.38,"tv":3.7,"id":31374}]}]}
{"op":"mcm","clk":"11798629702","pt":1723154663662,"mc":[{"id":"1.231540814","rc":[{"batb":[[0,2.3,14],[1,2.28,29.61],[2,2.02,4.55]],"ltp":2.38,"tv":3.7,"id":31374}]}]}
{"op":"mcm","clk":"11798629783","pt":1723154666179,"mc":[{"id":"1.231540814","rc":[{"batb":[[0,2.3,10]],"ltp":2.38,"tv":3.7,"id":31374}]}]}
{"op":"mcm","clk":"11798629813","pt":1723154666951,"mc":[{"id":"1.231540814","rc":[{"batb":[[0,2.28,29.61],[1,2.02,4.55],[2,1.8,2]],"ltp":2.38,"tv":3.7,"id":31374}]}]}
{"op":"mcm","clk":"11798629889","pt":1723154669368,"mc":[{"id":"1.231540814","rc":[{"batb":[[0,2.3,14],[1,2.28,29.61],[2,2.02,4.55]],"ltp":2.38,"tv":3.7,"id":31374}]}]}
{"op":"mcm","clk":"11798629971","pt":1723154671683,"mc":[{"id":"1.231540814","rc":[{"batb":[[0,2.3,10]],"ltp":2.38,"tv":3.7,"id":31374}]}]}
{"op":"mcm","clk":"11798630006","pt":1723154672560,"mc":[{"id":"1.231540814","rc":[{"batb":[[0,2.28,29.61],[1,2.02,4.55],[2,1.8,2]],"ltp":2.38,"tv":3.7,"id":31374}]}]}
{"op":"mcm","clk":"11798630118","pt":1723154675282,"mc":[{"id":"1.231540814","rc":[{"batb":[[0,2.3,14],[1,2.28,29.61],[2,2.02,4.55]],"ltp":2.38,"tv":3.7,"id":31374}]}]}
{"op":"mcm","clk":"11798630202","pt":1723154677697,"mc":[{"id":"1.231540814","rc":[{"batb":[[0,2.3,10]],"ltp":2.38,"tv":3.7,"id":31374}]}]}
{"op":"mcm","clk":"11798630234","pt":1723154678676,"mc":[{"id":"1.231540814","rc":[{"batb":[[0,2.28,29.61],[1,2.02,4.55],[2,1.8,2]],"ltp":2.38,"tv":3.7,"id":31374}]}]}
{"op":"mcm","clk":"11798630355","pt":1723154682377,"mc":[{"id":"1.231540814","rc":[{"batb":[[0,2.3,14],[1,2.28,29.61],[2,2.02,4.55]],"ltp":2.38,"tv":3.7,"id":31374}]}]}
{"op":"mcm","clk":"11798630435","pt":1723154684787,"mc":[{"id":"1.231540814","rc":[{"batb":[[0,2.3,10]],"ltp":2.38,"tv":3.7,"id":31374}]}]}
{"op":"mcm","clk":"11798630473","pt":1723154685814,"mc":[{"id":"1.231540814","rc":[{"batb":[[0,2.28,29.61],[1,2.02,4.55],[2,1.8,2]],"ltp":2.38,"tv":3.7,"id":31374}]}]}
{"op":"mcm","clk":"11798630509","pt":1723154687096,"mc":[{"id":"1.231540814","rc":[{"batb":[[0,2.3,4],[1,2.28,29.61],[2,2.02,4.55]],"ltp":2.38,"tv":3.7,"id":31374}]}]}
{"op":"mcm","clk":"11798630555","pt":1723154688281,"mc":[{"id":"1.231540814","rc":[{"batb":[[0,2.32,10],[1,2.3,4],[2,2.28,29.61]],"ltp":2.38,"tv":3.7,"id":31374}]}]}
{"op":"mcm","clk":"11798630604","pt":1723154689406,"mc":[{"id":"1.231540814","rc":[{"batb":[[1,2.28,29.61],[2,2.02,4.55]],"ltp":2.38,"tv":3.7,"id":31374}]}]}
{"op":"mcm","clk":"11798630676","pt":1723154691716,"mc":[{"id":"1.231540814","rc":[{"batb":[[0,2.34,4]],"ltp":2.38,"tv":3.7,"id":31374}]}]}
{"op":"mcm","clk":"11798630764","pt":1723154694034,"mc":[{"id":"1.231540814","rc":[{"batb":[[0,2.3,10]],"ltp":2.38,"tv":3.7,"id":31374}]}]}
{"op":"mcm","clk":"11798630826","pt":1723154696490,"mc":[{"id":"1.231540814","rc":[{"batb":[[0,2.32,4],[1,2.3,10],[2,2.28,29.61]],"ltp":2.38,"tv":3.7,"id":31374}]}]}
{"op":"mcm","clk":"11798630848","pt":1723154697311,"mc":[{"id":"1.231540814","rc":[{"batb":[[1,2.28,29.61],[2,2.02,4.55]],"ltp":2.38,"tv":3.7,"id":31374}]}]}
{"op":"mcm","clk":"11798630897","pt":1723154698811,"mc":[{"id":"1.231540814","rc":[{"batb":[[0,2.28,29.61],[1,2.02,4.55],[2,1.8,2]],"ltp":2.38,"tv":3.7,"id":31374}]}]}
{"op":"mcm","clk":"11798630941","pt":1723154699944,"mc":[{"id":"1.231540814","rc":[{"batb":[[0,2.3,10],[1,2.28,29.61],[2,2.02,4.55]],"ltp":2.38,"tv":3.7,"id":31374}]}]}
{"op":"mcm","clk":"11798630991","pt":1723154701126,"mc":[{"id":"1.231540814","rc":[{"batb":[[0,2.32,4],[1,2.3,10],[2,2.28,29.61]],"ltp":2.38,"tv":3.7,"id":31374}]}]}
{"op":"mcm","clk":"11798631069","pt":1723154703498,"mc":[{"id":"1.231540814","rc":[{"batb":[[0,2.28,29.61],[1,2.02,4.55],[2,1.8,2]],"ltp":2.38,"tv":3.7,"id":31374}]}]}
{"op":"mcm","clk":"11798631241","pt":1723154707721,"mc":[{"id":"1.231540814","rc":[{"batl":[[0,1.75,5.52],[1,1.76,112.27],[2,1.77,320.68]],"ltp":1.73,"tv":391.93,"id":3961},{"batb":[[0,2.3,14],[1,2.28,29.61],[2,2.02,4.55]],"ltp":2.38,"tv":3.7,"id":31374}]}]}
{"op":"mcm","clk":"11798631306","pt":1723154709437,"mc":[{"id":"1.231540814","rc":[{"batb":[[0,2.3,10]],"ltp":2.38,"tv":3.7,"id":31374}]}]}
{"op":"mcm","clk":"11798631345","pt":1723154710416,"mc":[{"id":"1.231540814","rc":[{"batb":[[0,2.28,29.61],[1,2.02,4.55],[2,1.8,2]],"ltp":2.38,"tv":3.7,"id":31374}]}]}
{"op":"mcm","clk":"11798631388","pt":1723154711603,"mc":[{"id":"1.231540814","rc":[{"batb":[[0,2.3,4],[1,2.28,29.61],[2,2.02,4.55]],"ltp":2.38,"tv":3.7,"id":31374}]}]}
{"op":"mcm","clk":"11798631439","pt":1723154712936,"mc":[{"id":"1.231540814","rc":[{"batb":[[0,2.32,10],[1,2.3,4],[2,2.28,29.61]],"ltp":2.38,"tv":3.7,"id":31374}]}]}
{"op":"mcm","clk":"11798631485","pt":1723154713812,"mc":[{"id":"1.231540814","rc":[{"batb":[[1,2.28,29.61],[2,2.02,4.55]],"ltp":2.38,"tv":3.7,"id":31374}]}]}
{"op":"mcm","clk":"11798631581","pt":1723154716326,"mc":[{"id":"1.231540814","rc":[{"batb":[[0,2.34,4]],"ltp":2.38,"tv":3.7,"id":31374}]}]}
{"op":"mcm","clk":"11798631665","pt":1723154718635,"mc":[{"id":"1.231540814","rc":[{"batb":[[0,2.36,10]],"ltp":2.38,"tv":3.7,"id":31374}]}]}
{"op":"mcm","clk":"11798631759","pt":1723154721050,"mc":[{"id":"1.231540814","rc":[{"batl":[[0,1.76,112.27],[1,1.77,320.68],[2,1.78,400]],"ltp":1.73,"tv":391.93,"id":3961},{"batb":[[0,2.38,4],[1,2.36,10],[2,2.28,29.61]],"ltp":2.38,"tv":3.7,"id":31374}]}]}
{"op":"mcm","clk":"11798631794","pt":1723154722026,"mc":[{"id":"1.231540814","rc":[{"batb":[[1,2.28,29.61],[2,2.02,4.55]],"ltp":2.38,"tv":3.7,"id":31374}]}]}
{"op":"mcm","clk":"11798631851","pt":1723154723515,"mc":[{"id":"1.231540814","rc":[{"batb":[[0,2.28,29.61],[1,2.02,4.55],[2,1.8,2]],"ltp":2.38,"tv":3.7,"id":31374}]}]}
{"op":"mcm","clk":"11798631968","pt":1723154726651,"mc":[{"id":"1.231540814","rc":[{"batb":[[0,2.3,14],[1,2.28,29.61],[2,2.02,4.55]],"ltp":2.38,"tv":3.7,"id":31374}]}]}
{"op":"mcm","clk":"11798632056","pt":1723154728858,"mc":[{"id":"1.231540814","rc":[{"batb":[[0,2.3,10]],"ltp":2.38,"tv":3.7,"id":31374}]}]}
{"op":"mcm","clk":"11798632107","pt":1723154730049,"mc":[{"id":"1.231540814","rc":[{"batb":[[0,2.28,29.61],[1,2.02,4.55],[2,1.8,2]],"ltp":2.38,"tv":3.7,"id":31374}]}]}
{"op":"mcm","clk":"11798632214","pt":1723154732448,"mc":[{"id":"1.231540814","rc":[{"batb":[[0,2.3,14],[1,2.28,29.61],[2,2.02,4.55]],"ltp":2.38,"tv":3.7,"id":31374}]}]}
{"op":"mcm","clk":"11798632317","pt":1723154735637,"mc":[{"id":"1.231540814","rc":[{"batb":[[0,2.28,29.61],[1,2.02,4.55],[2,1.8,2]],"ltp":2.38,"tv":3.7,"id":31374}]}]}
{"op":"mcm","clk":"11798632400","pt":1723154738049,"mc":[{"id":"1.231540814","rc":[{"batb":[[0,2.3,14],[1,2.28,29.61],[2,2.02,4.55]],"ltp":2.38,"tv":3.7,"id":31374}]}]}
{"op":"mcm","clk":"11798632484","pt":1723154740461,"mc":[{"id":"1.231540814","rc":[{"batb":[[0,2.3,10]],"ltp":2.38,"tv":3.7,"id":31374}]}]}
{"op":"mcm","clk":"11798632515","pt":1723154741332,"mc":[{"id":"1.231540814","rc":[{"batb":[[0,2.28,29.61],[1,2.02,4.55],[2,1.8,2]],"ltp":2.38,"tv":3.7,"id":31374}]}]}
{"op":"mcm","clk":"11798632682","pt":1723154746177,"mc":[{"id":"1.231540814","rc":[{"batb":[[0,2.3,14],[1,2.28,29.61],[2,2.02,4.55]],"ltp":2.38,"tv":3.7,"id":31374}]}]}
{"op":"mcm","clk":"11798632750","pt":1723154748359,"mc":[{"id":"1.231540814","rc":[{"batb":[[0,2.3,10]],"ltp":2.38,"tv":3.7,"id":31374}]}]}
{"op":"mcm","clk":"11798632786","pt":1723154749485,"mc":[{"id":"1.231540814","rc":[{"batb":[[0,2.28,29.61],[1,2.02,4.55],[2,1.8,2]],"ltp":2.38,"tv":3.7,"id":31374}]}]}
{"op":"mcm","clk":"11798632869","pt":1723154751789,"mc":[{"id":"1.231540814","rc":[{"batb":[[0,2.3,14],[1,2.28,29.61],[2,2.02,4.55]],"ltp":2.38,"tv":3.7,"id":31374}]}]}
{"op":"mcm","clk":"11798632947","pt":1723154754148,"mc":[{"id":"1.231540814","rc":[{"batb":[[0,2.3,10]],"ltp":2.38,"tv":3.7,"id":31374}]}]}
{"op":"mcm","clk":"11798632989","pt":1723154755171,"mc":[{"id":"1.231540814","rc":[{"batb":[[0,2.28,29.61],[1,2.02,4.55],[2,1.8,2]],"ltp":2.38,"tv":3.7,"id":31374}]}]}
{"op":"mcm","clk":"11798633083","pt":1723154758345,"mc":[{"id":"1.231540814","rc":[{"batb":[[0,2.3,14],[1,2.28,29.61],[2,2.02,4.55]],"ltp":2.38,"tv":3.7,"id":31374}]}]}
{"op":"mcm","clk":"11798633204","pt":1723154761677,"mc":[{"id":"1.231540814","rc":[{"batb":[[0,2.28,29.61],[1,2.02,4.55],[2,1.8,2]],"ltp":2.38,"tv":3.7,"id":31374}]}]}
{"op":"mcm","clk":"11798633339","pt":1723154765002,"mc":[{"id":"1.231540814","rc":[{"batb":[[0,2.3,14],[1,2.28,29.61],[2,2.02,4.55]],"ltp":2.38,"tv":3.7,"id":31374}]}]}
{"op":"mcm","clk":"11798633419","pt":1723154767477,"mc":[{"id":"1.231540814","rc":[{"batb":[[0,2.3,10]],"ltp":2.38,"tv":3.7,"id":31374}]}]}
{"op":"mcm","clk":"11798633445","pt":1723154768183,"mc":[{"id":"1.231540814","rc":[{"batb":[[0,2.28,29.61],[1,2.02,4.55],[2,1.8,2]],"ltp":2.38,"tv":3.7,"id":31374}]}]}
{"op":"mcm","clk":"11798633594","pt":1723154771793,"mc":[{"id":"1.231540814","rc":[{"batb":[[0,2.3,14],[1,2.28,29.61],[2,2.02,4.55]],"ltp":2.38,"tv":3.7,"id":31374}]}]}
{"op":"mcm","clk":"11798633682","pt":1723154774098,"mc":[{"id":"1.231540814","rc":[{"batb":[[0,2.3,10]],"ltp":2.38,"tv":3.7,"id":31374}]}]}
{"op":"mcm","clk":"11798633724","pt":1723154775176,"mc":[{"id":"1.231540814","rc":[{"batb":[[0,2.28,29.61],[1,2.02,4.55],[2,1.8,2]],"ltp":2.38,"tv":3.7,"id":31374}]}]}
{"op":"mcm","clk":"11798633757","pt":1723154776402,"mc":[{"id":"1.231540814","rc":[{"batb":[[0,2.3,4],[1,2.28,29.61],[2,2.02,4.55]],"ltp":2.38,"tv":3.7,"id":31374}]}]}
{"op":"mcm","clk":"11798633800","pt":1723154777681,"mc":[{"id":"1.231540814","rc":[{"batb":[[0,2.32,10],[1,2.3,4],[2,2.28,29.61]],"ltp":2.38,"tv":3.7,"id":31374}]}]}
{"op":"mcm","clk":"11798633822","pt":1723154778706,"mc":[{"id":"1.231540814","rc":[{"batb":[[1,2.28,29.61],[2,2.02,4.55]],"ltp":2.38,"tv":3.7,"id":31374}]}]}
{"op":"mcm","clk":"11798633935","pt":1723154781682,"mc":[{"id":"1.231540814","rc":[{"batb":[[0,2.3,4]],"ltp":2.38,"tv":3.7,"id":31374}]}]}
{"op":"mcm","clk":"11798634020","pt":1723154784202,"mc":[{"id":"1.231540814","rc":[{"batb":[[0,2.32,10]],"ltp":2.38,"tv":3.7,"id":31374}]}]}
{"op":"mcm","clk":"11798634141","pt":1723154787291,"mc":[{"id":"1.231540814","rc":[{"batb":[[0,2.3,4]],"ltp":2.38,"tv":3.7,"id":31374}]}]}
{"op":"mcm","clk":"11798634237","pt":1723154789905,"mc":[{"id":"1.231540814","rc":[{"batb":[[0,2.3,10]],"ltp":2.38,"tv":3.7,"id":31374}]}]}
{"op":"mcm","clk":"11798634323","pt":1723154792677,"mc":[{"id":"1.231540814","rc":[{"batb":[[0,2.32,4],[1,2.3,10],[2,2.28,29.61]],"ltp":2.38,"tv":3.7,"id":31374}]}]}
{"op":"mcm","clk":"11798634339","pt":1723154793289,"mc":[{"id":"1.231540814","rc":[{"batb":[[1,2.28,29.61],[2,2.02,4.55]],"ltp":2.38,"tv":3.7,"id":31374}]}]}
{"op":"mcm","clk":"11798634403","pt":1723154795193,"mc":[{"id":"1.231540814","rc":[{"batb":[[0,2.28,29.61],[1,2.02,4.55],[2,1.8,2]],"ltp":2.38,"tv":3.7,"id":31374}]}]}
{"op":"mcm","clk":"11798634482","pt":1723154797411,"mc":[{"id":"1.231540814","rc":[{"batb":[[0,2.3,14],[1,2.28,29.61],[2,2.02,4.55]],"ltp":2.38,"tv":3.7,"id":31374}]}]}
{"op":"mcm","clk":"11798634584","pt":1723154799617,"mc":[{"id":"1.231540814","rc":[{"batb":[[0,2.3,10]],"ltp":2.38,"tv":3.7,"id":31374}]}]}
{"op":"mcm","clk":"11798634619","pt":1723154800596,"mc":[{"id":"1.231540814","rc":[{"batb":[[0,2.28,29.61],[1,2.02,4.55],[2,1.8,2]],"ltp":2.38,"tv":3.7,"id":31374}]}]}
{"op":"mcm","clk":"11798634659","pt":1723154801931,"mc":[{"id":"1.231540814","rc":[{"batb":[[0,2.3,4],[1,2.28,29.61],[2,2.02,4.55]],"ltp":2.38,"tv":3.7,"id":31374}]}]}
{"op":"mcm","clk":"11798634739","pt":1723154804235,"mc":[{"id":"1.231540814","rc":[{"batb":[[0,2.32,10]],"ltp":2.38,"tv":3.7,"id":31374}]}]}
{"op":"mcm","clk":"11798634842","pt":1723154807416,"mc":[{"id":"1.231540814","rc":[{"batb":[[0,2.34,4]],"ltp":2.38,"tv":3.7,"id":31374}]}]}
{"op":"mcm","clk":"11798634897","pt":1723154809207,"mc":[{"id":"1.231540814","rc":[{"batb":[[0,2.28,29.61],[1,2.02,4.55],[2,1.8,2]],"ltp":2.38,"tv":3.7,"id":31374}]}]}
{"op":"mcm","clk":"11798634971","pt":1723154811511,"mc":[{"id":"1.231540814","rc":[{"batb":[[0,2.32,4],[1,2.3,10],[2,2.28,29.61]],"ltp":2.38,"tv":3.7,"id":31374}]}]}
{"op":"mcm","clk":"11798635064","pt":1723154814629,"mc":[{"id":"1.231540814","rc":[{"batb":[[0,2.28,29.61],[1,2.02,4.55],[2,1.8,2]],"ltp":2.38,"tv":3.7,"id":31374}]}]}
{"op":"mcm","clk":"11798635158","pt":1723154817344,"mc":[{"id":"1.231540814","rc":[{"batb":[[0,2.3,14],[1,2.28,29.61],[2,2.02,4.55]],"ltp":2.38,"tv":3.7,"id":31374}]}]}
{"op":"mcm","clk":"11798635238","pt":1723154819601,"mc":[{"id":"1.231540814","rc":[{"batb":[[0,2.3,10]],"ltp":2.38,"tv":3.7,"id":31374}]}]}
{"op":"mcm","clk":"11798635263","pt":1723154820625,"mc":[{"id":"1.231540814","rc":[{"batb":[[0,2.28,29.61],[1,2.02,4.55],[2,1.8,2]],"ltp":2.38,"tv":3.7,"id":31374}]}]}
{"op":"mcm","clk":"11798635313","pt":1723154822112,"mc":[{"id":"1.231540814","rc":[{"batb":[[0,2.3,4],[1,2.28,29.61],[2,2.02,4.55]],"ltp":2.38,"tv":3.7,"id":31374}]}]}
{"op":"mcm","clk":"11798635354","pt":1723154823341,"mc":[{"id":"1.231540814","rc":[{"batb":[[0,2.32,10],[1,2.3,4],[2,2.28,29.61]],"ltp":2.38,"tv":3.7,"id":31374}]}]}
{"op":"mcm","clk":"11798635380","pt":1723154824415,"mc":[{"id":"1.231540814","rc":[{"batb":[[1,2.28,29.61],[2,2.02,4.55]],"ltp":2.38,"tv":3.7,"id":31374}]}]}
{"op":"mcm","clk":"11798635475","pt":1723154826722,"mc":[{"id":"1.231540814","rc":[{"batb":[[0,2.28,29.61],[1,2.02,4.55],[2,1.8,2]],"ltp":2.38,"tv":3.7,"id":31374}]}]}
{"op":"mcm","clk":"11798635481","pt":1723154826824,"mc":[{"id":"1.231540814","rc":[{"batb":[[0,2.3,4],[1,2.28,29.61],[2,2.02,4.55]],"ltp":2.38,"tv":3.7,"id":31374}]}]}
{"op":"mcm","clk":"11798635569","pt":1723154829233,"mc":[{"id":"1.231540814","rc":[{"batb":[[0,2.32,10]],"ltp":2.38,"tv":3.7,"id":31374}]}]}
{"op":"mcm","clk":"11798635699","pt":1723154832517,"mc":[{"id":"1.231540814","rc":[{"batb":[[0,2.3,4]],"ltp":2.38,"tv":3.7,"id":31374}]}]}
{"op":"mcm","clk":"11798635791","pt":1723154835138,"mc":[{"id":"1.231540814","rc":[{"batb":[[0,2.3,10]],"ltp":2.38,"tv":3.7,"id":31374}]}]}
{"op":"mcm","clk":"11798635852","pt":1723154837130,"mc":[{"id":"1.231540814","rc":[{"batb":[[0,2.32,4],[1,2.3,10],[2,2.28,29.61]],"ltp":2.38,"tv":3.7,"id":31374}]}]}
{"op":"mcm","clk":"11798635889","pt":1723154838361,"mc":[{"id":"1.231540814","rc":[{"batb":[[1,2.28,29.61],[2,2.02,4.55]],"ltp":2.38,"tv":3.7,"id":31374}]}]}
{"op":"mcm","clk":"11798635941","pt":1723154839541,"mc":[{"id":"1.231540814","rc":[{"batb":[[0,2.28,29.61],[1,2.02,4.55],[2,1.8,2]],"ltp":2.38,"tv":3.7,"id":31374}]}]}
{"op":"mcm","clk":"11798636030","pt":1723154841849,"mc":[{"id":"1.231540814","rc":[{"batb":[[0,2.3,14],[1,2.28,29.61],[2,2.02,4.55]],"ltp":2.38,"tv":3.7,"id":31374}]}]}
{"op":"mcm","clk":"11798636135","pt":1723154844361,"mc":[{"id":"1.231540814","rc":[{"batb":[[0,2.3,10]],"ltp":2.38,"tv":3.7,"id":31374}]}]}
{"op":"mcm","clk":"11798636157","pt":1723154845029,"mc":[{"id":"1.231540814","rc":[{"batb":[[0,2.28,29.61],[1,2.02,4.55],[2,1.8,2]],"ltp":2.38,"tv":3.7,"id":31374}]}]}
{"op":"mcm","clk":"11798636263","pt":1723154847751,"mc":[{"id":"1.231540814","rc":[{"batb":[[0,2.3,14],[1,2.28,29.61],[2,2.02,4.55]],"ltp":2.38,"tv":3.7,"id":31374}]}]}
{"op":"mcm","clk":"11798636348","pt":1723154850059,"mc":[{"id":"1.231540814","rc":[{"batb":[[0,2.3,10]],"ltp":2.38,"tv":3.7,"id":31374}]}]}
{"op":"mcm","clk":"11798636383","pt":1723154851035,"mc":[{"id":"1.231540814","rc":[{"batb":[[0,2.28,29.61],[1,2.02,4.55],[2,1.8,2]],"ltp":2.38,"tv":3.7,"id":31374}]}]}
{"op":"mcm","clk":"11798636424","pt":1723154852466,"mc":[{"id":"1.231540814","rc":[{"batb":[[0,2.3,4],[1,2.28,29.61],[2,2.02,4.55]],"ltp":2.38,"tv":3.7,"id":31374}]}]}
{"op":"mcm","clk":"11798636491","pt":1723154854158,"mc":[{"id":"1.231540814","rc":[{"batb":[[0,2.32,10],[1,2.3,4],[2,2.28,29.61]],"ltp":2.38,"tv":3.7,"id":31374}]}]}
{"op":"mcm","clk":"11798636509","pt":1723154854777,"mc":[{"id":"1.231540814","rc":[{"batb":[[1,2.28,29.61],[2,2.02,4.55]],"ltp":2.38,"tv":3.7,"id":31374}]}]}
{"op":"mcm","clk":"11798636600","pt":1723154857658,"mc":[{"id":"1.231540814","rc":[{"batb":[[0,2.28,29.61],[1,2.02,4.55],[2,1.8,2]],"ltp":2.38,"tv":3.7,"id":31374}]}]}
{"op":"mcm","clk":"11798636604","pt":1723154857760,"mc":[{"id":"1.231540814","rc":[{"batb":[[0,2.3,4],[1,2.28,29.61],[2,2.02,4.55]],"ltp":2.38,"tv":3.7,"id":31374}]}]}
{"op":"mcm","clk":"11798636684","pt":1723154860086,"mc":[{"id":"1.231540814","rc":[{"batb":[[0,2.3,10]],"ltp":2.38,"tv":3.7,"id":31374}]}]}
{"op":"mcm","clk":"11798636789","pt":1723154863569,"mc":[{"id":"1.231540814","rc":[{"batb":[[0,2.3,4]],"ltp":2.38,"tv":3.7,"id":31374}]}]}
{"op":"mcm","clk":"11798636862","pt":1723154865672,"mc":[{"id":"1.231540814","rc":[{"batb":[[0,2.32,10],[1,2.3,4],[2,2.28,29.61]],"ltp":2.38,"tv":3.7,"id":31374}]}]}
{"op":"mcm","clk":"11798636866","pt":1723154865877,"mc":[{"id":"1.231540814","rc":[{"batb":[[1,2.28,29.61],[2,2.02,4.55]],"ltp":2.38,"tv":3.7,"id":31374}]}]}
{"op":"mcm","clk":"11798636961","pt":1723154869057,"mc":[{"id":"1.231540814","rc":[{"batb":[[0,2.3,4]],"ltp":2.38,"tv":3.7,"id":31374}]}]}
{"op":"mcm","clk":"11798637030","pt":1723154871468,"mc":[{"id":"1.231540814","rc":[{"batb":[[0,2.3,10]],"ltp":2.38,"tv":3.7,"id":31374}]}]}
{"op":"mcm","clk":"11798637105","pt":1723154873773,"mc":[{"id":"1.231540814","rc":[{"batb":[[0,2.32,4],[1,2.3,10],[2,2.28,29.61]],"ltp":2.38,"tv":3.7,"id":31374}]}]}
{"op":"mcm","clk":"11798637141","pt":1723154874795,"mc":[{"id":"1.231540814","rc":[{"batb":[[1,2.28,29.61],[2,2.02,4.55]],"ltp":2.38,"tv":3.7,"id":31374}]}]}
{"op":"mcm","clk":"11798637170","pt":1723154875974,"mc":[{"id":"1.231540814","rc":[{"batb":[[0,2.28,29.61],[1,2.02,4.55],[2,1.8,2]],"ltp":2.38,"tv":3.7,"id":31374}]}]}
{"op":"mcm","clk":"11798637233","pt":1723154877259,"mc":[{"id":"1.231540814","rc":[{"batb":[[0,2.3,10],[1,2.28,29.61],[2,2.02,4.55]],"ltp":2.38,"tv":3.7,"id":31374}]}]}
{"op":"mcm","clk":"11798637265","pt":1723154878384,"mc":[{"id":"1.231540814","rc":[{"batb":[[0,2.32,4],[1,2.3,10],[2,2.28,29.61]],"ltp":2.38,"tv":3.7,"id":31374}]}]}
{"op":"mcm","clk":"11798637339","pt":1723154880690,"mc":[{"id":"1.231540814","rc":[{"batb":[[0,2.28,29.61],[1,2.02,4.55],[2,1.8,2]],"ltp":2.38,"tv":3.7,"id":31374}]}]}
{"op":"mcm","clk":"11798637474","pt":1723154884077,"mc":[{"id":"1.231540814","rc":[{"batb":[[0,2.3,14],[1,2.28,29.61],[2,2.02,4.55]],"ltp":2.38,"tv":3.7,"id":31374}]}]}
