{"op":"mcm","clk":"11940899096","pt":1724415554532,"mc":[{"id":"1.232196998","marketDefinition":{"bspMarket":false,"turnInPlayEnabled":true,"persistenceEnabled":true,"marketBaseRate":5.0,"eventId":"33520514","eventTypeId":"4","numberOfWinners":1,"bettingType":"ODDS","marketType":"MATCH_ODDS","marketTime":"2024-08-23T23:00:00.000Z","suspendTime":"2024-08-23T23:00:00.000Z","bspReconciled":false,"complete":true,"inPlay":false,"crossMatching":true,"runnersVoidable":false,"numberOfActiveRunners":2,"betDelay":0,"status":"OPEN","runners":[{"status":"ACTIVE","sortPriority":1,"id":72963954,"name":"Trinidad Knight Riders W"},{"status":"ACTIVE","sortPriority":2,"id":60191231,"name":"Guyana Amazon W"}],"regulators":["MR_INT"],"countryCode":"GB","discountAllowed":false,"timezone":"GMT","openDate":"2024-08-23T23:00:00.000Z","version":6092195645,"name":"Match Odds","eventName":"Trinidad Knight Riders W v Guyana Amazon W"},"rc":[{"batb":[[0,1.03,200],[1,1.02,200],[2,1.01,220]],"ltp":0.0,"tv":0.0,"id":60191231},{"batb":[[0,1.03,200],[1,1.02,200],[2,1.01,220]],"ltp":0.0,"tv":0.0,"id":72963954}]}]}
{"op":"mcm","clk":"11940899643","pt":1724415559321,"mc":[{"id":"1.232196998","marketDefinition":{"bspMarket":false,"turnInPlayEnabled":true,"persistenceEnabled":true,"marketBaseRate":5.0,"eventId":"33520514","eventTypeId":"4","numberOfWinners":1,"bettingType":"ODDS","marketType":"MATCH_ODDS","marketTime":"2024-08-23T23:00:00.000Z","suspendTime":"2024-08-23T23:00:00.000Z","bspReconciled":false,"complete":true,"inPlay":false,"crossMatching":true,"runnersVoidable":false,"numberOfActiveRunners":2,"betDelay":0,"status":"OPEN","runners":[{"status":"ACTIVE","sortPriority":1,"id":72963954,"name":"Trinidad Knight Riders W"},{"status":"ACTIVE","sortPriority":2,"id":60191231,"name":"Guyana Amazon W"}],"regulators":["MR_INT"],"countryCode":"GB","discountAllowed":true,"timezone":"GMT","openDate":"2024-08-23T23:00:00.000Z","version":6092195645,"name":"Match Odds","eventName":"Trinidad Knight Riders W v Guyana Amazon W"}}]}
{"op":"mcm","clk":"11940911608","pt":1724415664236,"mc":[{"id":"1.232196998","rc":[{"batb":[[0,1.39,53.62],[1,1.03,200],[2,1.02,200]],"ltp":0.0,"tv":0.0,"id":72963954}]}]}
{"op":"mcm","clk":"11940911633","pt":1724415664438,"mc":[{"id":"1.232196998","rc":[{"batb":[[0,1.83,34.69],[1,1.03,200],[2,1.02,200]],"ltp":0.0,"tv":0.0,"id":60191231}]}]}
{"op":"mcm","clk":"11940966842","pt":1724416250514,"mc":[{"id":"1.232196998","rc":[{"batb":[[2,1.02,293.72]],"ltp":0.0,"tv":0.0,"id":60191231},{"batb":[[2,1.02,293.72]],"ltp":0.0,"tv":0.0,"id":72963954}]}]}
{"op":"mcm","clk":"11940989598","pt":1724416503973,"mc":[{"id":"1.232196998","rc":[{"batb":[[1,1.2,1000],[2,1.03,200]],"ltp":0.0,"tv":0.0,"id":72963954}]}]}
{"op":"mcm","clk":"11940989903","pt":1724416507261,"mc":[{"id":"1.232196998","rc":[{"batb":[[1,1.2,1000],[2,1.03,200]],"ltp":0.0,"tv":0.0,"id":60191231}]}]}
{"op":"mcm","clk":"11941089102","pt":1724417392314,"mc":[{"id":"1.232196998","rc":[{"batb":[[0,1.52,7.7],[1,1.39,53.62],[2,1.2,1006.67]],"batl":[[0,2.22,5.13],[1,2.48,4.62]],"ltp":0.0,"tv":0.0,"id":72963954}]}]}
{"op":"mcm","clk":"11941094280","pt":1724417464427,"mc":[{"id":"1.232196998","rc":[{"batb":[[0,1.54,48.32],[1,1.52,7.7]],"ltp":0.0,"tv":0.0,"id":72963954}]}]}
{"op":"mcm","clk":"11941094373","pt":1724417465910,"mc":[{"id":"1.232196998","rc":[{"batb":[[0,1.54,56.02],[1,1.2,1006.67],[2,1.03,200]],"ltp":0.0,"tv":0.0,"id":72963954}]}]}
{"op":"mcm","clk":"11941095714","pt":1724417485022,"mc":[{"id":"1.232196998","marketDefinition":{"bspMarket":false,"turnInPlayEnabled":true,"persistenceEnabled":true,"marketBaseRate":5.0,"eventId":"33520514","eventTypeId":"4","numberOfWinners":1,"bettingType":"ODDS","marketType":"MATCH_ODDS","marketTime":"2024-08-24T00:00:00.000Z","suspendTime":"2024-08-24T00:00:00.000Z","bspReconciled":false,"complete":true,"inPlay":false,"crossMatching":true,"runnersVoidable":false,"numberOfActiveRunners":2,"betDelay":0,"status":"OPEN","runners":[{"status":"ACTIVE","sortPriority":1,"id":72963954,"name":"Trinidad Knight Riders W"},{"status":"ACTIVE","sortPriority":2,"id":60191231,"name":"Guyana Amazon W"}],"regulators":["MR_INT"],"countryCode":"GB","discountAllowed":true,"timezone":"GMT","openDate":"2024-08-23T23:00:00.000Z","version":6092241051,"name":"Match Odds","eventName":"Trinidad Knight Riders W v Guyana Amazon W"}}]}
{"op":"mcm","clk":"11941095846","pt":1724417487003,"mc":[{"id":"1.232196998","marketDefinition":{"bspMarket":false,"turnInPlayEnabled":true,"persistenceEnabled":true,"marketBaseRate":5.0,"eventId":"33520514","eventTypeId":"4","numberOfWinners":1,"bettingType":"ODDS","marketType":"MATCH_ODDS","marketTime":"2024-08-24T00:00:00.000Z","suspendTime":"2024-08-24T00:00:00.000Z","bspReconciled":false,"complete":true,"inPlay":false,"crossMatching":true,"runnersVoidable":false,"numberOfActiveRunners":2,"betDelay":0,"status":"OPEN","runners":[{"status":"ACTIVE","sortPriority":1,"id":72963954,"name":"Trinidad Knight Riders W"},{"status":"ACTIVE","sortPriority":2,"id":60191231,"name":"Guyana Amazon W"}],"regulators":["MR_INT"],"countryCode":"GB","discountAllowed":true,"timezone":"GMT","openDate":"2024-08-24T00:00:00.000Z","version":6092241051,"name":"Match Odds","eventName":"Trinidad Knight Riders Women v Guyana Amazon Warri"}}]}
{"op":"mcm","clk":"11941096472","pt":1724417495936,"mc":[{"id":"1.232196998","rc":[{"batb":[[0,1.2,1000],[1,1.03,200],[2,1.02,293.72]],"ltp":0.0,"tv":0.0,"id":60191231},{"batb":[[0,1.57,47.39],[1,1.54,7.7],[2,1.2,1006.67]],"batl":[[0,2.18,29.11],[1,2.22,5.13],[2,2.48,4.62]],"ltp":0.0,"tv":0.0,"id":72963954}]}]}
{"op":"mcm","clk":"11941096559","pt":1724417497229,"mc":[{"id":"1.232196998","rc":[{"batb":[[0,1.57,55.09],[1,1.2,1006.67],[2,1.03,200]],"ltp":0.0,"tv":0.0,"id":72963954}]}]}
{"op":"mcm","clk":"11941096690","pt":1724417499070,"mc":[{"id":"1.232196998","marketDefinition":{"bspMarket":false,"turnInPlayEnabled":true,"persistenceEnabled":true,"marketBaseRate":5.0,"eventId":"33520514","eventTypeId":"4","numberOfWinners":1,"bettingType":"ODDS","marketType":"MATCH_ODDS","marketTime":"2024-08-23T23:00:00.000Z","suspendTime":"2024-08-23T23:00:00.000Z","bspReconciled":false,"complete":true,"inPlay":false,"crossMatching":true,"runnersVoidable":false,"numberOfActiveRunners":2,"betDelay":0,"status":"OPEN","runners":[{"status":"ACTIVE","sortPriority":1,"id":72963954,"name":"Trinidad Knight Riders W"},{"status":"ACTIVE","sortPriority":2,"id":60191231,"name":"Guyana Amazon W"}],"regulators":["MR_INT"],"countryCode":"GB","discountAllowed":true,"timezone":"GMT","openDate":"2024-08-24T00:00:00.000Z","version":6092241225,"name":"Match Odds","eventName":"Trinidad Knight Riders Women v Guyana Amazon Warri"}}]}
{"op":"mcm","clk":"11941096849","pt":1724417501055,"mc":[{"id":"1.232196998","marketDefinition":{"bspMarket":false,"turnInPlayEnabled":true,"persistenceEnabled":true,"marketBaseRate":5.0,"eventId":"33520514","eventTypeId":"4","numberOfWinners":1,"bettingType":"ODDS","marketType":"MATCH_ODDS","marketTime":"2024-08-23T23:00:00.000Z","suspendTime":"2024-08-23T23:00:00.000Z","bspReconciled":false,"complete":true,"inPlay":false,"crossMatching":true,"runnersVoidable":false,"numberOfActiveRunners":2,"betDelay":0,"status":"OPEN","runners":[{"status":"ACTIVE","sortPriority":1,"id":72963954,"name":"Trinidad Knight Riders W"},{"status":"ACTIVE","sortPriority":2,"id":60191231,"name":"Guyana Amazon W"}],"regulators":["MR_INT"],"countryCode":"GB","discountAllowed":true,"timezone":"GMT","openDate":"2024-08-23T23:00:00.000Z","version":6092241225,"name":"Match Odds","eventName":"Trinidad Knight Riders Women v Guyana Amazon Warri"}}]}
{"op":"mcm","clk":"11941097465","pt":1724417510125,"mc":[{"id":"1.232196998","marketDefinition":{"bspMarket":false,"turnInPlayEnabled":true,"persistenceEnabled":true,"marketBaseRate":5.0,"eventId":"33520514","eventTypeId":"4","numberOfWinners":1,"bettingType":"ODDS","marketType":"MATCH_ODDS","marketTime":"2024-08-24T00:00:00.000Z","suspendTime":"2024-08-24T00:00:00.000Z","bspReconciled":false,"complete":true,"inPlay":false,"crossMatching":true,"runnersVoidable":false,"numberOfActiveRunners":2,"betDelay":0,"status":"OPEN","runners":[{"status":"ACTIVE","sortPriority":1,"id":72963954,"name":"Trinidad Knight Riders W"},{"status":"ACTIVE","sortPriority":2,"id":60191231,"name":"Guyana Amazon W"}],"regulators":["MR_INT"],"countryCode":"GB","discountAllowed":true,"timezone":"GMT","openDate":"2024-08-23T23:00:00.000Z","version":6092241377,"name":"Match Odds","eventName":"Trinidad Knight Riders Women v Guyana Amazon Warri"}}]}
{"op":"mcm","clk":"11941097602","pt":1724417512122,"mc":[{"id":"1.232196998","marketDefinition":{"bspMarket":false,"turnInPlayEnabled":true,"persistenceEnabled":true,"marketBaseRate":5.0,"eventId":"33520514","eventTypeId":"4","numberOfWinners":1,"bettingType":"ODDS","marketType":"MATCH_ODDS","marketTime":"2024-08-24T00:00:00.000Z","suspendTime":"2024-08-24T00:00:00.000Z","bspReconciled":false,"complete":true,"inPlay":false,"crossMatching":true,"runnersVoidable":false,"numberOfActiveRunners":2,"betDelay":0,"status":"OPEN","runners":[{"status":"ACTIVE","sortPriority":1,"id":72963954,"name":"Trinidad Knight Riders W"},{"status":"ACTIVE","sortPriority":2,"id":60191231,"name":"Guyana Amazon W"}],"regulators":["MR_INT"],"countryCode":"GB","discountAllowed":true,"timezone":"GMT","openDate":"2024-08-24T00:00:00.000Z","version":6092241377,"name":"Match Odds","eventName":"Trinidad Knight Riders Women v Guyana Amazon Warri"}}]}
{"op":"mcm","clk":"11941117552","pt":1724417754930,"mc":[{"id":"1.232196998","rc":[{"batb":[[1,1.04,1.53],[2,1.03,200]],"ltp":0.0,"tv":0.0,"id":60191231},{"batb":[[2,1.04,1.53]],"ltp":0.0,"tv":0.0,"id":72963954}]}]}
{"op":"mcm","clk":"11941198752","pt":1724418681897,"mc":[{"id":"1.232196998","rc":[{"batb":[[0,1.62,112.87],[1,1.57,55.09],[2,1.2,1006.67]],"ltp":0.0,"tv":0.0,"id":72963954}]}]}
{"op":"mcm","clk":"11941198892","pt":1724418683195,"mc":[{"id":"1.232196998","rc":[{"batb":[[1,1.57,47.39]],"ltp":0.0,"tv":0.0,"id":72963954}]}]}
{"op":"mcm","clk":"11941198899","pt":1724418683298,"mc":[{"id":"1.232196998","rc":[{"batb":[[0,1.62,120.57]],"ltp":0.0,"tv":0.0,"id":72963954}]}]}
{"op":"mcm","clk":"11941200092","pt":1724418696109,"mc":[{"id":"1.232196998","rc":[{"batb":[[1,1.2,1006.67],[2,1.04,1.53]],"ltp":0.0,"tv":0.0,"id":72963954}]}]}
{"op":"mcm","clk":"11941200182","pt":1724418696891,"mc":[{"id":"1.232196998","rc":[{"batb":[[0,1.63,53.32],[1,1.62,112.87],[2,1.2,1006.67]],"ltp":0.0,"tv":0.0,"id":72963954}]}]}
{"op":"mcm","clk":"11941216503","pt":1724418853777,"mc":[{"id":"1.232196998","rc":[{"batb":[[0,1.63,166.19],[1,1.2,1006.67],[2,1.04,1.53]],"ltp":0.0,"tv":0.0,"id":72963954}]}]}
{"op":"mcm","clk":"11941230903","pt":1724418986119,"mc":[{"id":"1.232196998","rc":[{"batb":[[1,1.21,82.31],[2,1.2,1006.67]],"ltp":0.0,"tv":0.0,"id":72963954}]}]}
{"op":"mcm","clk":"11941232036","pt":1724418997809,"mc":[{"id":"1.232196998","rc":[{"batb":[[0,1.21,82.31],[1,1.2,1000],[2,1.04,1.53]],"ltp":0.0,"tv":0.0,"id":60191231}]}]}
{"op":"mcm","clk":"11941263318","pt":1724419319653,"mc":[{"id":"1.232196998","rc":[{"batb":[[0,1.64,25.48],[1,1.63,166.19],[2,1.21,82.31]],"ltp":0.0,"tv":0.0,"id":72963954}]}]}
{"op":"mcm","clk":"11941266623","pt":1724419352118,"mc":[{"id":"1.232196998","rc":[{"batb":[[2,1.05,5.19]],"ltp":0.0,"tv":0.0,"id":60191231},{"batb":[[1,1.63,120.57]],"ltp":0.0,"tv":0.0,"id":72963954}]}]}
{"op":"mcm","clk":"11941266645","pt":1724419352324,"mc":[{"id":"1.232196998","rc":[{"batb":[[0,1.66,44.79],[1,1.64,25.48],[2,1.63,120.57]],"ltp":0.0,"tv":0.0,"id":72963954}]}]}
{"op":"mcm","clk":"11941365934","pt":1724420352867,"mc":[{"id":"1.232196998","rc":[{"batb":[[0,1.67,26.54],[1,1.66,44.79]],"ltp":0.0,"tv":0.0,"id":72963954}]}]}
{"op":"mcm","clk":"11941367839","pt":1724420374788,"mc":[{"id":"1.232196998","rc":[{"batb":[[0,1.67,27.07]],"ltp":0.0,"tv":0.0,"id":72963954}]}]}
{"op":"mcm","clk":"11941371851","pt":1724420416859,"mc":[{"id":"1.232196998","rc":[{"batb":[[0,1.67,27.14]],"ltp":0.0,"tv":0.0,"id":72963954}]}]}
{"op":"mcm","clk":"11941378996","pt":1724420496826,"mc":[{"id":"1.232196998","rc":[{"batb":[[0,1.68,44.26],[1,1.67,27.14]],"ltp":0.0,"tv":0.0,"id":72963954}]}]}
{"op":"mcm","clk":"11941382593","pt":1724420539778,"mc":[{"id":"1.232196998","rc":[{"batb":[[0,1.69,25.66],[1,1.68,44.26]],"ltp":0.0,"tv":0.0,"id":72963954}]}]}
{"op":"mcm","clk":"11941383651","pt":1724420551881,"mc":[{"id":"1.232196998","rc":[{"batb":[[0,1.69,26.16]],"ltp":0.0,"tv":0.0,"id":72963954}]}]}
{"op":"mcm","clk":"11941404443","pt":1724420795983,"mc":[{"id":"1.232196998","rc":[{"batb":[[1,1.63,120.57],[2,1.21,82.31]],"ltp":0.0,"tv":0.0,"id":72963954}]}]}
{"op":"mcm","clk":"11941467715","pt":1724421492261,"mc":[{"id":"1.232196998","rc":[{"batb":[[1,1.05,5.19],[2,1.04,1.53]],"ltp":0.0,"tv":0.0,"id":60191231}]}]}
{"op":"mcm","clk":"11941504276","pt":1724421933932,"mc":[{"id":"1.232196998","rc":[{"batb":[[0,1.21,82.31]],"ltp":0.0,"tv":0.0,"id":60191231},{"batb":[[0,1.7,6.45],[1,1.69,26.17],[2,1.63,120.57]],"ltp":0.0,"tv":0.0,"id":72963954}]}]}
{"op":"mcm","clk":"11941603720","pt":1724422911906,"mc":[{"id":"1.232196998","rc":[{"batb":[[0,1.71,25.29],[1,1.7,6.45]],"ltp":0.0,"tv":0.0,"id":72963954}]}]}
{"op":"mcm","clk":"11941611974","pt":1724423007805,"mc":[{"id":"1.232196998","rc":[{"batb":[[0,1.71,25.58]],"ltp":0.0,"tv":0.0,"id":72963954}]}]}
{"op":"mcm","clk":"11941612836","pt":1724423017820,"mc":[{"id":"1.232196998","rc":[{"batb":[[0,1.71,25.63]],"ltp":0.0,"tv":0.0,"id":72963954}]}]}
{"op":"mcm","clk":"11941613672","pt":1724423028827,"mc":[{"id":"1.232196998","rc":[{"batb":[[0,1.71,25.65]],"ltp":0.0,"tv":0.0,"id":72963954}]}]}
{"op":"mcm","clk":"11941614498","pt":1724423038848,"mc":[{"id":"1.232196998","rc":[{"batb":[[0,1.71,25.65]],"ltp":0.0,"tv":0.0,"id":72963954}]}]}
{"op":"mcm","clk":"11941615203","pt":1724423047858,"mc":[{"id":"1.232196998","rc":[{"batb":[[0,1.71,25.65]],"ltp":0.0,"tv":0.0,"id":72963954}]}]}
{"op":"mcm","clk":"11941804285","pt":1724425617848,"mc":[{"id":"1.232196998","rc":[{"batb":[[0,1.21,82.62]],"ltp":0.0,"tv":0.0,"id":60191231},{"batb":[[0,1.7,6.41],[1,1.63,120.63],[2,1.6,15.16]],"batl":[[1,2.22,5.13],[2,2.48,4.62]],"ltp":0.0,"tv":0.0,"id":72963954}]}]}
{"op":"mcm","clk":"11941806358","pt":1724425639583,"mc":[{"id":"1.232196998","rc":[{"batb":[[0,1.91,682.28],[1,1.21,82.62],[2,1.05,5.19]],"ltp":0.0,"tv":0.0,"id":60191231}]}]}
{"op":"mcm","clk":"11941828299","pt":1724425885979,"mc":[{"id":"1.232196998","rc":[{"batb":[[0,1.93,32.86],[1,1.91,682.28],[2,1.21,82.62]],"ltp":0.0,"tv":0.0,"id":60191231},{"batl":[[0,2.22,6.06],[1,2.48,4.62],[2,2.48,0]],"ltp":0.0,"tv":0.0,"id":72963954}]}]}
{"op":"mcm","clk":"11941828698","pt":1724425890829,"mc":[{"id":"1.232196998","rc":[{"batl":[[0,2.22,5.13]],"ltp":0.0,"tv":0.0,"id":72963954}]}]}
{"op":"mcm","clk":"11941866562","pt":1724426414073,"mc":[{"id":"1.232196998","rc":[{"batb":[[1,1.64,6.24],[2,1.63,120.63]],"ltp":0.0,"tv":0.0,"id":72963954}]}]}
{"op":"mcm","clk":"11941873570","pt":1724426518082,"mc":[{"id":"1.232196998","rc":[{"batb":[[1,1.65,1.18],[2,1.64,6.24]],"ltp":0.0,"tv":0.0,"id":72963954}]}]}
{"op":"mcm","clk":"11941873590","pt":1724426518397,"mc":[{"id":"1.232196998","rc":[{"batb":[[0,1.94,1],[1,1.93,32.86],[2,1.91,682.28]],"ltp":0.0,"tv":0.0,"id":60191231}]}]}
{"op":"mcm","clk":"11941893252","pt":1724426796164,"mc":[{"id":"1.232196998","rc":[{"batb":[[0,1.95,32.52],[1,1.94,1]],"ltp":0.0,"tv":0.0,"id":60191231}]}]}
{"op":"mcm","clk":"11942010184","pt":1724428021058,"mc":[{"id":"1.232196998","rc":[{"batb":[[0,1.66,44.57],[2,1.64,12.65]],"ltp":0.0,"tv":0.0,"id":72963954}]}]}
{"op":"mcm","clk":"11942010208","pt":1724428021312,"mc":[{"id":"1.232196998","rc":[{"batb":[[0,1.96,6.48],[1,1.95,32.52],[2,1.94,1]],"ltp":0.0,"tv":0.0,"id":60191231}]}]}
{"op":"mcm","clk":"11942010345","pt":1724428023458,"mc":[{"id":"1.232196998","rc":[{"batb":[[2,1.64,6.41]],"ltp":0.0,"tv":0.0,"id":72963954}]}]}
{"op":"mcm","clk":"11942018880","pt":1724428153061,"mc":[{"id":"1.232196998","rc":[{"batb":[[0,1.97,32.04],[1,1.96,6.48]],"ltp":0.0,"tv":0.0,"id":60191231},{"batl":[[1,2.24,17.61],[2,2.48,4.62]],"ltp":0.0,"tv":0.0,"id":72963954}]}]}
{"op":"mcm","clk":"11942287322","pt":1724430663679,"mc":[{"id":"1.232196998","rc":[{"batl":[[0,2.5,0.7]],"ltp":0.0,"tv":0.0,"id":60191231},{"batl":[[0,2.22,5.14],[1,2.24,17.61],[2,2.48,4.62]],"ltp":0.0,"tv":0.0,"id":72963954}]}]}
{"op":"mcm","clk":"11942289080","pt":1724430679027,"mc":[{"id":"1.232196998","rc":[{"batl":[[0,2.48,29.82],[1,2.5,0.7]],"ltp":0.0,"tv":0.0,"id":60191231},{"batb":[[0,1.65,1.18],[1,1.64,6.41],[2,1.63,120.74]],"batl":[[0,2.22,5.91]],"ltp":0.0,"tv":0.0,"id":72963954}]}]}
{"op":"mcm","clk":"11942290638","pt":1724430692032,"mc":[{"id":"1.232196998","rc":[{"batl":[[0,2.48,30.52],[1,2.5,0]],"ltp":0.0,"tv":0.0,"id":60191231}]}]}
{"op":"mcm","clk":"11942304299","pt":1724430795842,"mc":[{"id":"1.232196998","rc":[{"trd":[[2.44,1.41]],"batb":[[0,2.44,1.57],[1,1.97,32.04],[2,1.96,6.48]],"ltp":2.44,"tv":1.4,"id":60191231}],"tv":1.4}]}
{"op":"mcm","clk":"11942306326","pt":1724430811179,"mc":[{"id":"1.232196998","rc":[{"batb":[[0,1.97,32.04],[1,1.96,6.48],[2,1.94,1]],"ltp":2.44,"tv":1.4,"id":60191231}]}]}
{"op":"mcm","clk":"11942306354","pt":1724430811358,"mc":[{"id":"1.232196998","rc":[{"batb":[[0,1.66,44.57],[1,1.65,1.18],[2,1.64,6.41]],"ltp":0.0,"tv":0.0,"id":72963954}]}]}
{"op":"mcm","clk":"11942309208","pt":1724430834198,"mc":[{"id":"1.232196998","rc":[{"trd":[[2,0.76]],"ltp":2.0,"tv":2.16,"id":60191231},{"trd":[[2,0.76]],"batl":[[0,2.22,5.15]],"ltp":2.0,"tv":0.75,"id":72963954}],"tv":2.92}]}
{"op":"mcm","clk":"11942312473","pt":1724430858033,"mc":[{"id":"1.232196998","rc":[{"batb":[[0,1.96,6.48],[1,1.94,1],[2,1.21,82.67]],"ltp":2.0,"tv":2.16,"id":60191231},{"trd":[[2,5.31]],"batl":[[0,2.22,5.14]],"ltp":2.0,"tv":5.3,"id":72963954}],"tv":7.47}]}
{"op":"mcm","clk":"11942314508","pt":1724430873742,"mc":[{"id":"1.232196998","rc":[{"batb":[[0,1.99,2.27],[1,1.66,44.57],[2,1.65,1.18]],"ltp":2.0,"tv":5.3,"id":72963954}]}]}
{"op":"mcm","clk":"11942315468","pt":1724430881251,"mc":[{"id":"1.232196998","rc":[{"batb":[[0,1.66,44.57],[1,1.65,1.18],[2,1.64,6.41]],"batl":[[0,2.04,30.78],[1,2.22,5.14],[2,2.24,17.61]],"ltp":2.0,"tv":5.3,"id":72963954}]}]}
{"op":"mcm","clk":"11942317275","pt":1724430895078,"mc":[{"id":"1.232196998","rc":[{"batb":[[0,1.99,2.27],[1,1.66,44.57],[2,1.65,1.18]],"ltp":2.0,"tv":5.3,"id":72963954}]}]}
{"op":"mcm","clk":"11942317323","pt":1724430895387,"mc":[{"id":"1.232196998","rc":[{"batl":[[0,2.22,5.14],[1,2.24,17.61],[2,2.48,4.62]],"ltp":2.0,"tv":5.3,"id":72963954}]}]}
{"op":"mcm","clk":"11942319500","pt":1724430911171,"mc":[{"id":"1.232196998","rc":[{"batb":[[0,1.66,44.57],[1,1.65,1.18],[2,1.64,6.41]],"batl":[[0,2,31.39],[1,2.22,5.14],[2,2.24,17.61]],"ltp":2.0,"tv":5.3,"id":72963954}]}]}
{"op":"mcm","clk":"11942322942","pt":1724430935215,"mc":[{"id":"1.232196998","rc":[{"trd":[[2.46,4.5]],"batb":[[0,1.96,6.5]],"ltp":2.46,"tv":6.66,"id":60191231},{"batb":[[0,1.65,1.18],[1,1.64,6.41],[2,1.63,120.74]],"ltp":2.0,"tv":5.3,"id":72963954}],"tv":11.97}]}
{"op":"mcm","clk":"11942322970","pt":1724430935428,"mc":[{"id":"1.232196998","rc":[{"batb":[[0,1.66,44.3],[1,1.65,1.18],[2,1.64,6.41]],"ltp":2.0,"tv":5.3,"id":72963954}]}]}
{"op":"mcm","clk":"11942323710","pt":1724430940823,"mc":[{"id":"1.232196998","rc":[{"batb":[[0,1.96,6.48]],"ltp":2.46,"tv":6.66,"id":60191231}]}]}
{"op":"mcm","clk":"11942325515","pt":1724430954232,"mc":[{"id":"1.232196998","rc":[{"trd":[[2.46,8.22]],"batb":[[0,1.96,6.9]],"ltp":2.46,"tv":10.38,"id":60191231},{"batb":[[0,1.67,44.03]],"ltp":2.0,"tv":5.3,"id":72963954}],"tv":15.69}]}
{"op":"mcm","clk":"11942326508","pt":1724430961545,"mc":[{"id":"1.232196998","rc":[{"batb":[[0,1.96,6.48]],"ltp":2.46,"tv":10.38,"id":60191231}]}]}
{"op":"mcm","clk":"11942328294","pt":1724430974744,"mc":[{"id":"1.232196998","rc":[{"batb":[[0,2.44,1.52],[1,1.96,6.48],[2,1.94,1]],"ltp":2.46,"tv":10.38,"id":60191231},{"batb":[[0,1.65,1.18],[1,1.64,6.41],[2,1.63,120.74]],"ltp":2.0,"tv":5.3,"id":72963954}]}]}
{"op":"mcm","clk":"11942330517","pt":1724430991607,"mc":[{"id":"1.232196998","rc":[{"batb":[[0,1.96,6.48],[1,1.94,1],[2,1.21,82.67]],"ltp":2.46,"tv":10.38,"id":60191231},{"batb":[[0,1.67,44.03],[1,1.65,1.18],[2,1.64,6.41]],"ltp":2.0,"tv":5.3,"id":72963954}]}]}
{"op":"mcm","clk":"11942333148","pt":1724431011812,"mc":[{"id":"1.232196998","rc":[{"batb":[[0,2.44,1.52],[1,1.96,6.48],[2,1.94,1]],"ltp":2.46,"tv":10.38,"id":60191231},{"batb":[[0,1.65,1.18],[1,1.64,6.41],[2,1.63,120.74]],"ltp":2.0,"tv":5.3,"id":72963954}]}]}
{"op":"mcm","clk":"11942334741","pt":1724431023826,"mc":[{"id":"1.232196998","rc":[{"batb":[[0,1.96,6.48],[1,1.94,1],[2,1.21,82.67]],"ltp":2.46,"tv":10.38,"id":60191231},{"batb":[[0,1.66,44.3],[1,1.65,1.18],[2,1.64,6.41]],"ltp":2.0,"tv":5.3,"id":72963954}]}]}
{"op":"mcm","clk":"11942337884","pt":1724431047290,"mc":[{"id":"1.232196998","rc":[{"batb":[[0,1.99,2.27],[1,1.66,44.3],[2,1.65,1.18]],"ltp":2.0,"tv":5.3,"id":72963954}]}]}
{"op":"mcm","clk":"11942337916","pt":1724431047500,"mc":[{"id":"1.232196998","rc":[{"trd":[[1.99,4.54]],"batb":[[0,1.66,44.3],[1,1.65,1.18],[2,1.64,6.41]],"batl":[[0,2.22,5.14],[1,2.24,17.61],[2,2.48,4.62]],"ltp":1.99,"tv":9.85,"id":72963954}],"tv":20.23}]}
{"op":"mcm","clk":"11942341971","pt":1724431076218,"mc":[{"id":"1.232196998","rc":[{"trd":[[1.98,4.5]],"batb":[[0,1.66,44.32]],"batl":[[0,2.04,30.76],[1,2.22,5.14],[2,2.24,17.61]],"ltp":1.98,"tv":14.35,"id":72963954}],"tv":24.74}]}
{"op":"mcm","clk":"11942342599","pt":1724431080517,"mc":[{"id":"1.232196998","rc":[{"batb":[[0,1.66,44.3]],"ltp":1.98,"tv":14.35,"id":72963954}]}]}
{"op":"mcm","clk":"11942344743","pt":1724431095744,"mc":[{"id":"1.232196998","rc":[{"batb":[[0,1.97,2.27],[1,1.66,44.3],[2,1.65,1.18]],"batl":[[0,2.22,5.14],[1,2.24,17.61],[2,2.48,4.62]],"ltp":1.98,"tv":14.35,"id":72963954}]}]}
{"op":"mcm","clk":"11942345453","pt":1724431100727,"mc":[{"id":"1.232196998","rc":[{"trd":[[1.97,1.76]],"batb":[[0,1.97,1.39]],"ltp":1.97,"tv":16.11,"id":72963954}],"tv":26.49}]}
{"op":"mcm","clk":"11942347053","pt":1724431111738,"mc":[{"id":"1.232196998","rc":[{"batb":[[0,1.66,44.3],[1,1.65,1.18],[2,1.64,6.41]],"batl":[[0,2.02,31.07],[1,2.22,5.14],[2,2.24,17.61]],"ltp":1.97,"tv":16.11,"id":72963954}]}]}
{"op":"mcm","clk":"11942349048","pt":1724431126663,"mc":[{"id":"1.232196998","rc":[{"batb":[[0,1.66,45.18]],"ltp":1.97,"tv":16.11,"id":72963954}]}]}
{"op":"mcm","clk":"11942352722","pt":1724431153388,"mc":[{"id":"1.232196998","rc":[{"batb":[[0,2.42,2.27],[1,1.96,6.48],[2,1.94,1]],"ltp":2.46,"tv":10.38,"id":60191231}]}]}
{"op":"mcm","clk":"11942354246","pt":1724431165913,"mc":[{"id":"1.232196998","rc":[{"batb":[[0,1.96,6.48],[1,1.94,1],[2,1.21,82.67]],"ltp":2.46,"tv":10.38,"id":60191231}]}]}
{"op":"mcm","clk":"11942358149","pt":1724431195746,"mc":[{"id":"1.232196998","rc":[{"batb":[[0,1.67,27.55],[1,1.66,44.3],[2,1.65,1.18]],"ltp":1.97,"tv":16.11,"id":72963954}]}]}
{"op":"mcm","clk":"11942358555","pt":1724431198564,"mc":[{"id":"1.232196998","rc":[{"batb":[[0,1.97,2.27],[1,1.67,27.55],[2,1.66,44.3]],"batl":[[0,2.22,5.14],[1,2.24,17.61],[2,2.48,4.62]],"ltp":1.97,"tv":16.11,"id":72963954}]}]}
{"op":"mcm","clk":"11942359129","pt":1724431202871,"mc":[{"id":"1.232196998","rc":[{"trd":[[1.97,6.31]],"batb":[[0,1.67,27.55],[1,1.66,44.3],[2,1.65,1.18]],"batl":[[0,1.97,15.59],[1,2.04,30.76],[2,2.22,5.14]],"ltp":1.97,"tv":20.66,"id":72963954}],"tv":31.04}]}
{"op":"mcm","clk":"11942359388","pt":1724431204658,"mc":[{"id":"1.232196998","rc":[{"batl":[[0,1.97,16.47]],"ltp":1.97,"tv":20.66,"id":72963954}]}]}
{"op":"mcm","clk":"11942361276","pt":1724431218703,"mc":[{"id":"1.232196998","rc":[{"batb":[[0,1.95,2.27],[1,1.67,27.55]],"batl":[[1,2.22,5.14],[2,2.24,17.61]],"ltp":1.97,"tv":20.66,"id":72963954}]}]}
{"op":"mcm","clk":"11942361691","pt":1724431221851,"mc":[{"id":"1.232196998","rc":[{"trd":[[1.95,4.55]],"batb":[[0,1.68,44.64],[1,1.67,26.67]],"batl":[[0,1.95,15.59],[1,1.97,16.47],[2,2.22,5.14]],"ltp":1.95,"tv":25.21,"id":72963954}],"tv":35.59}]}
{"op":"mcm","clk":"11942361791","pt":1724431222789,"mc":[{"id":"1.232196998","rc":[{"batl":[[0,1.95,16.47],[1,1.97,15.59]],"ltp":1.95,"tv":25.21,"id":72963954}]}]}
{"op":"mcm","clk":"11942362323","pt":1724431226816,"mc":[{"id":"1.232196998","rc":[{"batl":[[0,1.97,16.47],[1,2.22,5.14],[2,2.24,17.61]],"ltp":1.95,"tv":25.21,"id":72963954}]}]}
{"op":"mcm","clk":"11942363249","pt":1724431233891,"mc":[{"id":"1.232196998","rc":[{"batl":[[0,2.04,31.64]],"ltp":1.95,"tv":25.21,"id":72963954}]}]}
{"op":"mcm","clk":"11942363588","pt":1724431236778,"mc":[{"id":"1.232196998","rc":[{"batb":[[1,1.65,1.18],[2,1.64,6.41]],"ltp":1.95,"tv":25.21,"id":72963954}]}]}
{"op":"mcm","clk":"11942374363","pt":1724431316412,"mc":[{"id":"1.232196998","rc":[{"batb":[[0,1.93,1.52],[1,1.68,44.64],[2,1.65,1.18]],"ltp":1.95,"tv":25.21,"id":72963954}]}]}
{"op":"mcm","clk":"11942374684","pt":1724431318994,"mc":[{"id":"1.232196998","rc":[{"batb":[[0,1.68,44.64],[1,1.65,1.18],[2,1.64,6.41]],"ltp":1.95,"tv":25.21,"id":72963954}]}]}
{"op":"mcm","clk":"11942374867","pt":1724431320728,"mc":[{"id":"1.232196998","rc":[{"batl":[[0,1.93,17.86],[1,2.04,31.64],[2,2.22,5.14]],"ltp":1.95,"tv":25.21,"id":72963954}]}]}
{"op":"mcm","clk":"11942376979","pt":1724431336029,"mc":[{"id":"1.232196998","rc":[{"batb":[[0,1.91,1.52],[1,1.68,44.64],[2,1.65,1.18]],"ltp":1.95,"tv":25.21,"id":72963954}]}]}
{"op":"mcm","clk":"11942377017","pt":1724431336348,"mc":[{"id":"1.232196998","rc":[{"batl":[[1,2.22,6.02],[2,2.24,17.61]],"ltp":1.95,"tv":25.21,"id":72963954}]}]}
{"op":"mcm","clk":"11942377391","pt":1724431339057,"mc":[{"id":"1.232196998","rc":[{"trd":[[1.91,3.03]],"batb":[[0,1.68,44.64],[1,1.65,1.18],[2,1.64,6.41]],"batl":[[0,1.91,16.35],[1,2.04,31.64],[2,2.22,5.14]],"ltp":1.91,"tv":28.24,"id":72963954}],"tv":38.62}]}
{"op":"mcm","clk":"11942379311","pt":1724431352863,"mc":[{"id":"1.232196998","rc":[{"batl":[[0,2.04,31.64],[1,2.22,5.14],[2,2.24,17.61]],"ltp":1.91,"tv":28.24,"id":72963954}]}]}
{"op":"mcm","clk":"11942379417","pt":1724431353758,"mc":[{"id":"1.232196998","rc":[{"batl":[[0,2.04,30.76]],"ltp":1.91,"tv":28.24,"id":72963954}]}]}
{"op":"mcm","clk":"11942379919","pt":1724431357756,"mc":[{"id":"1.232196998","rc":[{"trd":[[1.68,19.96]],"batb":[[0,1.69,5],[1,1.68,34.66],[2,1.65,1.18]],"ltp":1.68,"tv":48.19,"id":72963954}],"tv":58.58}]}
{"op":"mcm","clk":"11942380388","pt":1724431361250,"mc":[{"id":"1.232196998","rc":[{"batb":[[0,1.68,34.66],[1,1.65,1.18],[2,1.64,6.41]],"ltp":1.68,"tv":48.19,"id":72963954}]}]}
{"op":"mcm","clk":"11942381798","pt":1724431372096,"mc":[{"id":"1.232196998","rc":[{"batb":[[0,1.93,2.27],[1,1.68,34.66],[2,1.65,1.18]],"batl":[[0,2.04,40.61]],"ltp":1.68,"tv":48.19,"id":72963954}]}]}
{"op":"mcm","clk":"11942382258","pt":1724431375709,"mc":[{"id":"1.232196998","rc":[{"trd":[[1.93,4.55]],"batb":[[0,1.68,34.66],[1,1.65,1.18],[2,1.64,6.41]],"batl":[[0,1.93,15.59],[1,2.04,40.61],[2,2.22,5.14]],"ltp":1.93,"tv":52.74,"id":72963954}],"tv":63.13}]}
{"op":"mcm","clk":"11942383564","pt":1724431384930,"mc":[{"id":"1.232196998","rc":[{"batb":[[0,1.69,5],[1,1.68,34.66],[2,1.65,1.18]],"batl":[[0,2.04,40.61],[1,2.22,5.14],[2,2.24,17.61]],"ltp":1.93,"tv":52.74,"id":72963954}]}]}
{"op":"mcm","clk":"11942383748","pt":1724431386536,"mc":[{"id":"1.232196998","rc":[{"batb":[[0,1.88,2.27],[1,1.69,5],[2,1.68,34.66]],"ltp":1.93,"tv":52.74,"id":72963954}]}]}
{"op":"mcm","clk":"11942383972","pt":1724431388324,"mc":[{"id":"1.232196998","rc":[{"batb":[[1,1.68,34.66],[2,1.65,1.18]],"ltp":1.93,"tv":52.74,"id":72963954}]}]}
{"op":"mcm","clk":"11942384289","pt":1724431390736,"mc":[{"id":"1.232196998","rc":[{"trd":[[1.88,4.55]],"batb":[[0,1.68,34.66],[1,1.65,1.18],[2,1.64,6.41]],"batl":[[0,1.88,15.59],[1,2.04,40.61],[2,2.22,5.14]],"ltp":1.88,"tv":57.29,"id":72963954}],"tv":67.68}]}
{"op":"mcm","clk":"11942384411","pt":1724431391829,"mc":[{"id":"1.232196998","rc":[{"batb":[[0,1.97,182.13],[1,1.96,6.48],[2,1.94,1]],"ltp":2.46,"tv":10.38,"id":60191231}]}]}
{"op":"mcm","clk":"11942384938","pt":1724431395913,"mc":[{"id":"1.232196998","rc":[{"batb":[[0,1.69,5.88],[1,1.68,33.78],[2,1.65,1.18]],"batl":[[0,2.04,40.61],[1,2.22,5.14],[2,2.24,17.61]],"ltp":1.88,"tv":57.29,"id":72963954}]}]}
{"op":"mcm","clk":"11942385354","pt":1724431399319,"mc":[{"id":"1.232196998","rc":[{"batb":[[0,1.68,34.66],[1,1.65,1.18],[2,1.64,6.41]],"ltp":1.88,"tv":57.29,"id":72963954}]}]}
{"op":"mcm","clk":"11942386281","pt":1724431407191,"mc":[{"id":"1.232196998","rc":[{"batb":[[0,1.7,183.01],[1,1.68,33.78],[2,1.65,1.18]],"ltp":1.88,"tv":57.29,"id":72963954}]}]}
{"op":"mcm","clk":"11942386325","pt":1724431407501,"mc":[{"id":"1.232196998","rc":[{"batb":[[0,1.71,5.88],[1,1.7,182.13],[2,1.68,33.78]],"batl":[[0,2.02,31.07],[1,2.04,9.85],[2,2.22,5.14]],"ltp":1.88,"tv":57.29,"id":72963954}]}]}
{"op":"mcm","clk":"11942386726","pt":1724431410709,"mc":[{"id":"1.232196998","rc":[{"batb":[[0,1.7,183.01],[1,1.68,33.78],[2,1.65,1.18]],"ltp":1.88,"tv":57.29,"id":72963954}]}]}
{"op":"mcm","clk":"11942386962","pt":1724431412714,"mc":[{"id":"1.232196998","rc":[{"batb":[[0,1.85,3.15]],"ltp":1.88,"tv":57.29,"id":72963954}]}]}
{"op":"mcm","clk":"11942387413","pt":1724431416722,"mc":[{"id":"1.232196998","rc":[{"trd":[[1.85,4.55],[1.88,6.31]],"batb":[[0,1.68,33.78],[1,1.65,1.18],[2,1.64,6.41]],"batl":[[0,1.85,14.71],[1,1.99,35.22],[2,2.02,31.07]],"ltp":1.85,"tv":63.6,"id":72963954}],"tv":73.98}]}
{"op":"mcm","clk":"11942387753","pt":1724431419723,"mc":[{"id":"1.232196998","rc":[{"batl":[[0,1.99,35.22],[1,2.02,31.07],[2,2.04,9.85]],"ltp":1.85,"tv":63.6,"id":72963954}]}]}
{"op":"mcm","clk":"11942388614","pt":1724431426627,"mc":[{"id":"1.232196998","rc":[{"batl":[[2,2.22,5.14]],"ltp":1.85,"tv":63.6,"id":72963954}]}]}
{"op":"mcm","clk":"11942389048","pt":1724431430238,"mc":[{"id":"1.232196998","rc":[{"trd":[[1.68,35.28]],"batb":[[0,1.68,26.12]],"ltp":1.68,"tv":78.92,"id":72963954}],"tv":89.31}]}
{"op":"mcm","clk":"11942389087","pt":1724431430550,"mc":[{"id":"1.232196998","rc":[{"batb":[[0,1.65,1.18],[1,1.64,6.41],[2,1.63,120.74]],"batl":[[0,1.98,31.69],[1,1.99,35.22]],"ltp":1.68,"tv":78.92,"id":72963954}]}]}
{"op":"mcm","clk":"11942392202","pt":1724431455072,"mc":[{"id":"1.232196998","rc":[{"batb":[[0,1.68,182.13],[1,1.65,1.18],[2,1.64,6.41]],"ltp":1.68,"tv":78.92,"id":72963954}]}]}
{"op":"mcm","clk":"11942392421","pt":1724431456883,"mc":[{"id":"1.232196998","rc":[{"batb":[[1,1.66,13.77],[2,1.65,1.18]],"ltp":1.68,"tv":78.92,"id":72963954}]}]}
{"op":"mcm","clk":"11942394126","pt":1724431469675,"mc":[{"id":"1.232196998","rc":[{"batl":[[0,1.81,35.22],[1,1.98,31.69],[2,1.99,35.22]],"ltp":1.68,"tv":78.92,"id":72963954}]}]}
{"op":"mcm","clk":"11942396561","pt":1724431486811,"mc":[{"id":"1.232196998","rc":[{"batb":[[0,1.66,48.98],[1,1.65,1.18],[2,1.64,6.41]],"batl":[[0,1.8,39.75],[1,1.81,35.22]],"ltp":1.68,"tv":78.92,"id":72963954}]}]}
{"op":"mcm","clk":"11942402177","pt":1724431528458,"mc":[{"id":"1.232196998","rc":[{"batl":[[0,1.81,35.22],[1,1.99,35.22],[2,2.22,5.14]],"ltp":1.68,"tv":78.92,"id":72963954}]}]}
{"op":"mcm","clk":"11942403657","pt":1724431538726,"mc":[{"id":"1.232196998","rc":[{"batb":[[0,1.8,13.77],[1,1.66,48.98],[2,1.65,1.18]],"ltp":1.68,"tv":78.92,"id":72963954}]}]}
{"op":"mcm","clk":"11942408563","pt":1724431573778,"mc":[{"id":"1.232196998","rc":[{"batb":[[0,1.66,62.75],[1,1.65,1.18],[2,1.64,6.41]],"ltp":1.68,"tv":78.92,"id":72963954}]}]}
{"op":"mcm","clk":"11942409028","pt":1724431577083,"mc":[{"id":"1.232196998","rc":[{"batb":[[0,1.96,6.48],[1,1.94,1],[2,1.81,35.22]],"ltp":2.46,"tv":10.38,"id":60191231}]}]}
{"op":"mcm","clk":"11942410382","pt":1724431586798,"mc":[{"id":"1.232196998","rc":[{"batb":[[0,1.66,48.98]],"ltp":1.68,"tv":78.92,"id":72963954}]}]}
{"op":"mcm","clk":"11942411316","pt":1724431593119,"mc":[{"id":"1.232196998","rc":[{"batb":[[0,1.67,13.77],[1,1.66,35.22],[2,1.65,1.18]],"ltp":1.68,"tv":78.92,"id":72963954}]}]}
{"op":"mcm","clk":"11942429412","pt":1724431740715,"mc":[{"id":"1.232196998","rc":[{"batl":[[0,1.81,35.39]],"ltp":1.68,"tv":78.92,"id":72963954}]}]}
{"op":"mcm","clk":"11942430596","pt":1724431751786,"mc":[{"id":"1.232196998","rc":[{"batb":[[0,1.97,5],[1,1.96,6.48],[2,1.94,1]],"batl":[[0,2.48,0.18]],"ltp":2.46,"tv":10.38,"id":60191231}]}]}
{"op":"mcm","clk":"11942430946","pt":1724431755209,"mc":[{"id":"1.232196998","rc":[{"batb":[[0,1.96,6.48],[1,1.94,1],[2,1.81,35.22]],"ltp":2.46,"tv":10.38,"id":60191231}]}]}
{"op":"mcm","clk":"11942432850","pt":1724431774021,"mc":[{"id":"1.232196998","rc":[{"batb":[[0,1.97,5],[1,1.96,6.48],[2,1.94,1]],"ltp":2.46,"tv":10.38,"id":60191231},{"batb":[[0,1.8,13.59]],"batl":[[0,1.81,35.22]],"ltp":1.68,"tv":78.92,"id":72963954}]}]}
{"op":"mcm","clk":"11942433225","pt":1724431777431,"mc":[{"id":"1.232196998","rc":[{"batb":[[0,1.96,6.48],[1,1.94,1],[2,1.81,35.22]],"ltp":2.46,"tv":10.38,"id":60191231}]}]}
{"op":"mcm","clk":"11942434475","pt":1724431789043,"mc":[{"id":"1.232196998","rc":[{"batb":[[0,1.97,5],[1,1.96,6.48],[2,1.94,1]],"ltp":2.46,"tv":10.38,"id":60191231}]}]}
{"op":"mcm","clk":"11942434743","pt":1724431791938,"mc":[{"id":"1.232196998","rc":[{"batl":[[0,2.48,0.32]],"ltp":2.46,"tv":10.38,"id":60191231}]}]}
{"op":"mcm","clk":"11942434779","pt":1724431792309,"mc":[{"id":"1.232196998","rc":[{"batb":[[0,1.96,6.48],[1,1.94,1],[2,1.81,35.22]],"ltp":2.46,"tv":10.38,"id":60191231}]}]}
{"op":"mcm","clk":"11942438983","pt":1724431831570,"mc":[{"id":"1.232196998","rc":[{"batb":[[0,1.97,5],[1,1.96,6.48],[2,1.94,1]],"ltp":2.46,"tv":10.38,"id":60191231}]}]}
{"op":"mcm","clk":"11942439320","pt":1724431834890,"mc":[{"id":"1.232196998","rc":[{"batb":[[0,1.96,6.48],[1,1.94,1],[2,1.81,35.22]],"ltp":2.46,"tv":10.38,"id":60191231}]}]}
{"op":"mcm","clk":"11942440064","pt":1724431842106,"mc":[{"id":"1.232196998","rc":[{"batb":[[0,1.97,5],[1,1.96,6.48],[2,1.94,1]],"ltp":2.46,"tv":10.38,"id":60191231},{"batl":[[2,2.24,17.61]],"ltp":1.68,"tv":78.92,"id":72963954}]}]}
{"op":"mcm","clk":"11942440404","pt":1724431845409,"mc":[{"id":"1.232196998","rc":[{"batb":[[0,1.96,6.48],[1,1.94,1],[2,1.81,35.22]],"ltp":2.46,"tv":10.38,"id":60191231}]}]}
{"op":"mcm","clk":"11942444546","pt":1724431887280,"mc":[{"id":"1.232196998","rc":[{"batb":[[0,1.97,5],[1,1.96,6.48],[2,1.94,1]],"ltp":2.46,"tv":10.38,"id":60191231}]}]}
{"op":"mcm","clk":"11942444906","pt":1724431890690,"mc":[{"id":"1.232196998","rc":[{"batb":[[0,1.96,6.48],[1,1.94,1],[2,1.81,35.22]],"ltp":2.46,"tv":10.38,"id":60191231}]}]}
{"op":"mcm","clk":"11942450920","pt":1724431949151,"mc":[{"id":"1.232196998","rc":[{"batb":[[0,1.97,5],[1,1.96,6.48],[2,1.94,1]],"ltp":2.46,"tv":10.38,"id":60191231}]}]}
{"op":"mcm","clk":"11942451249","pt":1724431952663,"mc":[{"id":"1.232196998","rc":[{"batb":[[0,1.96,6.48],[1,1.94,1],[2,1.81,35.22]],"ltp":2.46,"tv":10.38,"id":60191231}]}]}
{"op":"mcm","clk":"11942452458","pt":1724431963971,"mc":[{"id":"1.232196998","rc":[{"batb":[[0,1.97,5],[1,1.96,6.48],[2,1.94,1]],"ltp":2.46,"tv":10.38,"id":60191231},{"batb":[[0,1.66,35.22],[1,1.65,1.18],[2,1.64,6.41]],"ltp":1.68,"tv":78.92,"id":72963954}]}]}
{"op":"mcm","clk":"11942452779","pt":1724431967278,"mc":[{"id":"1.232196998","rc":[{"batb":[[0,1.96,6.48],[1,1.94,1],[2,1.81,35.22]],"ltp":2.46,"tv":10.38,"id":60191231}]}]}
{"op":"mcm","clk":"11942455464","pt":1724431994687,"mc":[{"id":"1.232196998","rc":[{"trd":[[1.81,27.18]],"batl":[[0,1.81,21.63]],"ltp":1.81,"tv":106.1,"id":72963954}],"tv":116.49}]}
{"op":"mcm","clk":"11942455555","pt":1724431995579,"mc":[{"id":"1.232196998","rc":[{"batb":[[0,1.97,5],[1,1.96,6.48],[2,1.94,1]],"ltp":2.46,"tv":10.38,"id":60191231}]}]}
{"op":"mcm","clk":"11942455851","pt":1724431998907,"mc":[{"id":"1.232196998","rc":[{"batb":[[0,1.96,6.48],[1,1.94,1],[2,1.81,35.22]],"ltp":2.46,"tv":10.38,"id":60191231}]}]}
{"op":"mcm","clk":"11942455950","pt":1724431999901,"mc":[{"id":"1.232196998","rc":[{"batl":[[0,2.5,0.32]],"ltp":2.46,"tv":10.38,"id":60191231}]}]}
{"op":"mcm","clk":"11942458397","pt":1724432024939,"mc":[{"id":"1.232196998","rc":[{"batb":[[0,1.97,5],[1,1.96,6.48],[2,1.94,1]],"ltp":2.46,"tv":10.38,"id":60191231},{"batb":[[0,1.66,36.07]],"ltp":1.81,"tv":106.1,"id":72963954}]}]}
{"op":"mcm","clk":"11942458711","pt":1724432028125,"mc":[{"id":"1.232196998","rc":[{"batb":[[0,1.96,6.48],[1,1.94,1],[2,1.81,35.22]],"ltp":2.46,"tv":10.38,"id":60191231}]}]}
{"op":"mcm","clk":"11942459650","pt":1724432037529,"mc":[{"id":"1.232196998","rc":[{"batb":[[0,1.97,5],[1,1.96,6.48],[2,1.94,1]],"ltp":2.46,"tv":10.38,"id":60191231}]}]}
{"op":"mcm","clk":"11942459948","pt":1724432040961,"mc":[{"id":"1.232196998","rc":[{"batb":[[0,1.96,6.48],[1,1.94,1],[2,1.81,35.22]],"ltp":2.46,"tv":10.38,"id":60191231}]}]}
{"op":"mcm","clk":"11942461078","pt":1724432052054,"mc":[{"id":"1.232196998","rc":[{"batb":[[0,1.97,5],[1,1.96,6.48],[2,1.94,1]],"ltp":2.46,"tv":10.38,"id":60191231}]}]}
{"op":"mcm","clk":"11942461415","pt":1724432055378,"mc":[{"id":"1.232196998","rc":[{"batb":[[0,1.96,6.48],[1,1.94,1],[2,1.81,35.22]],"ltp":2.46,"tv":10.38,"id":60191231}]}]}
{"op":"mcm","clk":"11942462935","pt":1724432072377,"mc":[{"id":"1.232196998","rc":[{"batb":[[0,1.97,5],[1,1.96,6.48],[2,1.94,1]],"ltp":2.46,"tv":10.38,"id":60191231}]}]}
{"op":"mcm","clk":"11942463294","pt":1724432076060,"mc":[{"id":"1.232196998","rc":[{"batb":[[0,1.96,6.48],[1,1.94,1],[2,1.81,35.22]],"ltp":2.46,"tv":10.38,"id":60191231}]}]}
{"op":"mcm","clk":"11942466785","pt":1724432109697,"mc":[{"id":"1.232196998","rc":[{"batb":[[0,1.97,5],[1,1.96,6.48],[2,1.94,1]],"ltp":2.46,"tv":10.38,"id":60191231}]}]}
{"op":"mcm","clk":"11942467192","pt":1724432113041,"mc":[{"id":"1.232196998","rc":[{"batb":[[0,1.96,6.48],[1,1.94,1],[2,1.81,35.22]],"ltp":2.46,"tv":10.38,"id":60191231}]}]}
{"op":"mcm","clk":"11942467897","pt":1724432118733,"mc":[{"id":"1.232196998","rc":[{"batb":[[0,1.97,5],[1,1.96,6.48],[2,1.94,1]],"ltp":2.46,"tv":10.38,"id":60191231}]}]}
{"op":"mcm","clk":"11942468307","pt":1724432122022,"mc":[{"id":"1.232196998","rc":[{"batb":[[0,1.96,6.48],[1,1.94,1],[2,1.81,35.22]],"ltp":2.46,"tv":10.38,"id":60191231}]}]}
{"op":"mcm","clk":"11942474507","pt":1724432183091,"mc":[{"id":"1.232196998","rc":[{"batb":[[0,1.97,5],[1,1.96,6.48],[2,1.94,1]],"ltp":2.46,"tv":10.38,"id":60191231}]}]}
{"op":"mcm","clk":"11942474925","pt":1724432186499,"mc":[{"id":"1.232196998","rc":[{"batb":[[0,1.96,6.48],[1,1.94,1],[2,1.81,35.22]],"ltp":2.46,"tv":10.38,"id":60191231}]}]}
{"op":"mcm","clk":"11942475773","pt":1724432193836,"mc":[{"id":"1.232196998","rc":[{"batb":[[0,1.97,5],[1,1.96,6.48],[2,1.94,1]],"ltp":2.46,"tv":10.38,"id":60191231}]}]}
{"op":"mcm","clk":"11942476176","pt":1724432197324,"mc":[{"id":"1.232196998","rc":[{"batb":[[0,1.96,6.48],[1,1.94,1],[2,1.81,35.22]],"ltp":2.46,"tv":10.38,"id":60191231}]}]}
{"op":"mcm","clk":"11942476699","pt":1724432202841,"mc":[{"id":"1.232196998","rc":[{"batb":[[0,1.97,5],[1,1.96,6.48],[2,1.94,1]],"ltp":2.46,"tv":10.38,"id":60191231},{"batl":[[2,2.24,22.75]],"ltp":1.81,"tv":106.1,"id":72963954}]}]}
{"op":"mcm","clk":"11942476969","pt":1724432205657,"mc":[{"id":"1.232196998","rc":[{"batb":[[0,1.96,6.48],[1,1.94,1],[2,1.81,35.22]],"ltp":2.46,"tv":10.38,"id":60191231}]}]}
{"op":"mcm","clk":"11942480117","pt":1724432239916,"mc":[{"id":"1.232196998","rc":[{"batb":[[0,1.97,5],[1,1.96,6.48],[2,1.94,1]],"ltp":2.46,"tv":10.38,"id":60191231}]}]}
{"op":"mcm","clk":"11942480441","pt":1724432243420,"mc":[{"id":"1.232196998","rc":[{"batb":[[0,1.96,6.48],[1,1.94,1],[2,1.81,35.22]],"ltp":2.46,"tv":10.38,"id":60191231}]}]}
{"op":"mcm","clk":"11942482762","pt":1724432268131,"mc":[{"id":"1.232196998","rc":[{"batb":[[0,1.97,5],[1,1.96,6.48],[2,1.94,1]],"ltp":2.46,"tv":10.38,"id":60191231}]}]}
{"op":"mcm","clk":"11942483096","pt":1724432271550,"mc":[{"id":"1.232196998","rc":[{"batb":[[0,1.96,6.48],[1,1.94,1],[2,1.81,35.22]],"ltp":2.46,"tv":10.38,"id":60191231}]}]}
{"op":"mcm","clk":"11942484171","pt":1724432283162,"mc":[{"id":"1.232196998","rc":[{"batb":[[0,1.97,5],[1,1.96,6.48],[2,1.94,1]],"ltp":2.46,"tv":10.38,"id":60191231},{"batb":[[0,1.67,1.91],[1,1.66,35.22],[2,1.65,1.18]],"ltp":1.81,"tv":106.1,"id":72963954}]}]}
{"op":"mcm","clk":"11942484463","pt":1724432286438,"mc":[{"id":"1.232196998","rc":[{"batb":[[0,1.96,6.48],[1,1.94,1],[2,1.81,35.22]],"ltp":2.46,"tv":10.38,"id":60191231}]}]}
{"op":"mcm","clk":"11942484940","pt":1724432290260,"mc":[{"id":"1.232196998","rc":[{"batb":[[0,1.97,5],[1,1.96,6.48],[2,1.94,1]],"batl":[[0,2.48,0.32]],"ltp":2.46,"tv":10.38,"id":60191231}]}]}
{"op":"mcm","clk":"11942485322","pt":1724432293754,"mc":[{"id":"1.232196998","rc":[{"batb":[[0,1.96,6.48],[1,1.94,1],[2,1.81,35.22]],"ltp":2.46,"tv":10.38,"id":60191231}]}]}
{"op":"mcm","clk":"11942488141","pt":1724432322318,"mc":[{"id":"1.232196998","rc":[{"batb":[[0,1.97,5],[1,1.96,6.48],[2,1.94,1]],"ltp":2.46,"tv":10.38,"id":60191231}]}]}
{"op":"mcm","clk":"11942488462","pt":1724432325818,"mc":[{"id":"1.232196998","rc":[{"batb":[[0,1.96,6.48],[1,1.94,1],[2,1.81,35.22]],"ltp":2.46,"tv":10.38,"id":60191231}]}]}
{"op":"mcm","clk":"11942488723","pt":1724432328892,"mc":[{"id":"1.232196998","rc":[{"batb":[[0,1.97,5],[1,1.96,6.48],[2,1.94,1]],"ltp":2.46,"tv":10.38,"id":60191231}]}]}
{"op":"mcm","clk":"11942489077","pt":1724432332293,"mc":[{"id":"1.232196998","rc":[{"batb":[[0,1.96,6.48],[1,1.94,1],[2,1.81,35.22]],"ltp":2.46,"tv":10.38,"id":60191231}]}]}
{"op":"mcm","clk":"11942496451","pt":1724432400985,"mc":[{"id":"1.232196998","rc":[{"batb":[[0,1.97,5],[1,1.96,6.48],[2,1.94,1]],"ltp":2.46,"tv":10.38,"id":60191231}]}]}
{"op":"mcm","clk":"11942497013","pt":1724432404289,"mc":[{"id":"1.232196998","rc":[{"batb":[[0,1.96,6.48],[1,1.94,1],[2,1.81,35.22]],"ltp":2.46,"tv":10.38,"id":60191231},{"trd":[[1.68,35.28],[1.81,27.19],[1.88,6.31],[1.97,6.31]],"batb":[[1,1.66,35.22]],"batl":[[0,1.81,21.63],[1,1.99,35.22],[2,2.24,22.75]],"ltp":1.81,"tv":106.12,"id":72963954}],"tv":116.5}]}
{"op":"mcm","clk":"11942498042","pt":1724432411902,"mc":[{"id":"1.232196998","rc":[{"batb":[[0,1.97,5],[1,1.96,6.48],[2,1.94,1]],"ltp":2.46,"tv":10.38,"id":60191231}]}]}
{"op":"mcm","clk":"11942498475","pt":1724432415423,"mc":[{"id":"1.232196998","rc":[{"batb":[[0,1.96,6.48],[1,1.94,1],[2,1.81,35.22]],"ltp":2.46,"tv":10.38,"id":60191231}]}]}
{"op":"mcm","clk":"11942501205","pt":1724432439230,"mc":[{"id":"1.232196998","rc":[{"batb":[[0,1.97,5],[1,1.96,6.48],[2,1.94,1]],"ltp":2.46,"tv":10.38,"id":60191231}]}]}
{"op":"mcm","clk":"11942501575","pt":1724432442527,"mc":[{"id":"1.232196998","rc":[{"batb":[[0,1.96,6.48],[1,1.94,1],[2,1.81,35.22]],"ltp":2.46,"tv":10.38,"id":60191231}]}]}
{"op":"mcm","clk":"11942507800","pt":1724432492761,"mc":[{"id":"1.232196998","rc":[{"batb":[[0,1.97,5],[1,1.96,6.48],[2,1.94,1]],"ltp":2.46,"tv":10.38,"id":60191231}]}]}
{"op":"mcm","clk":"11942508270","pt":1724432496234,"mc":[{"id":"1.232196998","rc":[{"batb":[[0,1.96,6.48],[1,1.94,1],[2,1.81,35.22]],"ltp":2.46,"tv":10.38,"id":60191231}]}]}
{"op":"mcm","clk":"11942517380","pt":1724432561118,"mc":[{"id":"1.232196998","rc":[{"batb":[[0,1.97,5],[1,1.96,6.48],[2,1.94,1]],"ltp":2.46,"tv":10.38,"id":60191231}]}]}
{"op":"mcm","clk":"11942517895","pt":1724432564725,"mc":[{"id":"1.232196998","rc":[{"batb":[[0,1.96,6.48],[1,1.94,1],[2,1.81,35.22]],"ltp":2.46,"tv":10.38,"id":60191231}]}]}
{"op":"mcm","clk":"11942541053","pt":1724432718886,"mc":[{"id":"1.232196998","rc":[{"batb":[[0,1.97,5],[1,1.96,6.48],[2,1.94,1]],"ltp":2.46,"tv":10.38,"id":60191231},{"batb":[[0,1.67,1.06]],"ltp":1.81,"tv":106.12,"id":72963954}]}]}
{"op":"mcm","clk":"11942541548","pt":1724432722445,"mc":[{"id":"1.232196998","rc":[{"batb":[[0,1.96,6.48],[1,1.94,1],[2,1.81,35.22]],"ltp":2.46,"tv":10.38,"id":60191231}]}]}
{"op":"mcm","clk":"11942543240","pt":1724432733886,"mc":[{"id":"1.232196998","rc":[{"batb":[[0,1.97,5],[1,1.96,6.48],[2,1.94,1]],"ltp":2.46,"tv":10.38,"id":60191231},{"trd":[[1.81,28.76]],"batl":[[0,1.81,20.84]],"ltp":1.81,"tv":107.69,"id":72963954}],"tv":118.08}]}
{"op":"mcm","clk":"11942543731","pt":1724432737099,"mc":[{"id":"1.232196998","rc":[{"batb":[[0,1.96,6.48],[1,1.94,1],[2,1.81,35.22]],"ltp":2.46,"tv":10.38,"id":60191231}]}]}
{"op":"mcm","clk":"11942569024","pt":1724432896780,"mc":[{"id":"1.232196998","rc":[{"batb":[[0,1.97,5],[1,1.96,6.48],[2,1.94,1]],"batl":[[0,2.48,1.2]],"ltp":2.46,"tv":10.38,"id":60191231}]}]}
{"op":"mcm","clk":"11942569559","pt":1724432900091,"mc":[{"id":"1.232196998","rc":[{"batb":[[0,1.96,6.48],[1,1.94,1],[2,1.81,35.22]],"ltp":2.46,"tv":10.38,"id":60191231}]}]}
{"op":"mcm","clk":"11942571209","pt":1724432909787,"mc":[{"id":"1.232196998","rc":[{"batb":[[0,1.97,5],[1,1.96,6.48],[2,1.94,1]],"batl":[[0,2.48,1.18]],"ltp":2.46,"tv":10.38,"id":60191231}]}]}
{"op":"mcm","clk":"11942571729","pt":1724432912909,"mc":[{"id":"1.232196998","rc":[{"batb":[[0,1.96,6.48],[1,1.94,1],[2,1.81,35.22]],"ltp":2.46,"tv":10.38,"id":60191231}]}]}
{"op":"mcm","clk":"11942574865","pt":1724432932118,"mc":[{"id":"1.232196998","rc":[{"batb":[[0,1.97,5],[1,1.96,6.48],[2,1.94,1]],"ltp":2.46,"tv":10.38,"id":60191231},{"batl":[[1,1.99,36.1]],"ltp":1.81,"tv":107.69,"id":72963954}]}]}
{"op":"mcm","clk":"11942575393","pt":1724432935413,"mc":[{"id":"1.232196998","rc":[{"batb":[[0,1.96,6.48],[1,1.94,1],[2,1.81,35.22]],"ltp":2.46,"tv":10.38,"id":60191231}]}]}
{"op":"mcm","clk":"11942583841","pt":1724432988482,"mc":[{"id":"1.232196998","rc":[{"batb":[[0,1.97,5],[1,1.96,6.48],[2,1.94,1]],"ltp":2.46,"tv":10.38,"id":60191231}]}]}
{"op":"mcm","clk":"11942584439","pt":1724432991867,"mc":[{"id":"1.232196998","rc":[{"batb":[[0,1.96,6.48],[1,1.94,1],[2,1.81,35.22]],"ltp":2.46,"tv":10.38,"id":60191231}]}]}
{"op":"mcm","clk":"11942584886","pt":1724432994877,"mc":[{"id":"1.232196998","rc":[{"batb":[[0,1.97,5],[1,1.96,6.48],[2,1.94,1]],"ltp":2.46,"tv":10.38,"id":60191231}]}]}
{"op":"mcm","clk":"11942585415","pt":1724432998274,"mc":[{"id":"1.232196998","rc":[{"batb":[[0,1.96,6.48],[1,1.94,1],[2,1.81,35.22]],"ltp":2.46,"tv":10.38,"id":60191231}]}]}
{"op":"mcm","clk":"11942590306","pt":1724433030181,"mc":[{"id":"1.232196998","rc":[{"trd":[[2.46,9.08]],"batb":[[0,1.97,5],[1,1.96,6.48],[2,1.94,1]],"batl":[[0,2.48,0.32]],"ltp":2.46,"tv":11.24,"id":60191231},{"trd":[[1.68,36.54]],"batl":[[0,1.81,21.58]],"ltp":1.68,"tv":108.95,"id":72963954}],"tv":120.2}]}
{"op":"mcm","clk":"11942590856","pt":1724433033523,"mc":[{"id":"1.232196998","rc":[{"batb":[[0,1.96,6.48],[1,1.94,1],[2,1.81,35.22]],"ltp":2.46,"tv":11.24,"id":60191231}]}]}
{"op":"mcm","clk":"11942595855","pt":1724433064820,"mc":[{"id":"1.232196998","rc":[{"batb":[[0,1.97,5],[1,1.96,6.48],[2,1.94,1]],"ltp":2.46,"tv":11.24,"id":60191231}]}]}
{"op":"mcm","clk":"11942596406","pt":1724433068340,"mc":[{"id":"1.232196998","rc":[{"batb":[[0,1.96,6.48],[1,1.94,1],[2,1.81,35.22]],"ltp":2.46,"tv":11.24,"id":60191231}]}]}
{"op":"mcm","clk":"11942600904","pt":1724433097754,"mc":[{"id":"1.232196998","rc":[{"batb":[[0,1.97,5],[1,1.96,6.48],[2,1.94,1]],"batl":[[0,2.48,0.61]],"ltp":2.46,"tv":11.24,"id":60191231}]}]}
{"op":"mcm","clk":"11942601449","pt":1724433101194,"mc":[{"id":"1.232196998","rc":[{"batb":[[0,1.96,6.48],[1,1.94,1],[2,1.81,35.22]],"ltp":2.46,"tv":11.24,"id":60191231}]}]}
{"op":"mcm","clk":"11942606096","pt":1724433131790,"mc":[{"id":"1.232196998","rc":[{"batb":[[0,1.97,5],[1,1.96,6.48],[2,1.94,1]],"ltp":2.46,"tv":11.24,"id":60191231}]}]}
{"op":"mcm","clk":"11942606608","pt":1724433135087,"mc":[{"id":"1.232196998","rc":[{"batb":[[0,1.96,6.48],[1,1.94,1],[2,1.81,35.22]],"ltp":2.46,"tv":11.24,"id":60191231}]}]}
{"op":"mcm","clk":"11942609419","pt":1724433152213,"mc":[{"id":"1.232196998","rc":[{"batb":[[0,1.97,5],[1,1.96,6.48],[2,1.94,1]],"ltp":2.46,"tv":11.24,"id":60191231}]}]}
{"op":"mcm","clk":"11942609997","pt":1724433155496,"mc":[{"id":"1.232196998","rc":[{"batb":[[0,1.96,6.48],[1,1.94,1],[2,1.81,35.22]],"ltp":2.46,"tv":11.24,"id":60191231}]}]}
{"op":"mcm","clk":"11942636304","pt":1724433199834,"mc":[{"id":"1.232196998","rc":[{"batb":[[0,1.97,5.7],[1,1.96,6.48],[2,1.94,1]],"ltp":2.46,"tv":11.24,"id":60191231}]}]}
{"op":"mcm","clk":"11942636826","pt":1724433203285,"mc":[{"id":"1.232196998","rc":[{"batb":[[0,1.96,7.19],[1,1.94,1],[2,1.81,35.22]],"ltp":2.46,"tv":11.24,"id":60191231}]}]}
{"op":"mcm","clk":"11942646773","pt":1724433260727,"mc":[{"id":"1.232196998","rc":[{"batb":[[0,1.97,5.7],[1,1.96,6.48],[2,1.94,1]],"ltp":2.46,"tv":11.24,"id":60191231}]}]}
{"op":"mcm","clk":"11942647383","pt":1724433264323,"mc":[{"id":"1.232196998","rc":[{"batb":[[0,1.96,7.19],[1,1.94,1],[2,1.81,35.22]],"ltp":2.46,"tv":11.24,"id":60191231}]}]}
{"op":"mcm","clk":"11942650238","pt":1724433282048,"mc":[{"id":"1.232196998","rc":[{"batb":[[0,1.97,5.7],[1,1.96,6.48],[2,1.94,1]],"ltp":2.46,"tv":11.24,"id":60191231}]}]}
{"op":"mcm","clk":"11942650766","pt":1724433285465,"mc":[{"id":"1.232196998","rc":[{"batb":[[0,1.96,7.19],[1,1.94,1],[2,1.81,35.22]],"ltp":2.46,"tv":11.24,"id":60191231}]}]}
{"op":"mcm","clk":"11942651208","pt":1724433287862,"mc":[{"id":"1.232196998","rc":[{"batb":[[0,1.97,5.7],[1,1.96,6.48],[2,1.94,1]],"ltp":2.46,"tv":11.24,"id":60191231},{"batl":[[0,1.8,1.62],[1,1.81,20.84],[2,1.99,36.1]],"ltp":1.68,"tv":108.95,"id":72963954}]}]}
{"op":"mcm","clk":"11942651783","pt":1724433291362,"mc":[{"id":"1.232196998","rc":[{"batb":[[0,1.96,7.19],[1,1.94,1],[2,1.81,35.22]],"ltp":2.46,"tv":11.24,"id":60191231}]}]}
{"op":"mcm","clk":"11942663212","pt":1724433354416,"mc":[{"id":"1.232196998","rc":[{"batb":[[0,1.97,5.7],[1,1.96,6.48],[2,1.94,1]],"ltp":2.46,"tv":11.24,"id":60191231}]}]}
{"op":"mcm","clk":"11942663759","pt":1724433357707,"mc":[{"id":"1.232196998","rc":[{"batb":[[0,1.96,7.19],[1,1.94,1],[2,1.81,35.22]],"ltp":2.46,"tv":11.24,"id":60191231}]}]}
{"op":"mcm","clk":"11942670917","pt":1724433403048,"mc":[{"id":"1.232196998","rc":[{"batb":[[0,1.97,5.7],[1,1.96,6.48],[2,1.94,1]],"ltp":2.46,"tv":11.24,"id":60191231}]}]}
{"op":"mcm","clk":"11942671453","pt":1724433406319,"mc":[{"id":"1.232196998","rc":[{"batb":[[0,1.96,7.19],[1,1.94,1],[2,1.81,35.22]],"ltp":2.46,"tv":11.24,"id":60191231}]}]}
{"op":"mcm","clk":"11942673888","pt":1724433422148,"mc":[{"id":"1.232196998","rc":[{"batb":[[0,1.97,5.7],[1,1.96,6.48],[2,1.94,1]],"ltp":2.46,"tv":11.24,"id":60191231}]}]}
{"op":"mcm","clk":"11942674374","pt":1724433425466,"mc":[{"id":"1.232196998","rc":[{"batb":[[0,1.96,7.19],[1,1.94,1],[2,1.81,35.22]],"ltp":2.46,"tv":11.24,"id":60191231}]}]}
{"op":"mcm","clk":"11942678091","pt":1724433449597,"mc":[{"id":"1.232196998","rc":[{"batb":[[0,1.97,5.7],[1,1.96,6.48],[2,1.94,1]],"ltp":2.46,"tv":11.24,"id":60191231}]}]}
{"op":"mcm","clk":"11942678628","pt":1724433452996,"mc":[{"id":"1.232196998","rc":[{"batb":[[0,1.96,7.19],[1,1.94,1],[2,1.81,35.22]],"ltp":2.46,"tv":11.24,"id":60191231}]}]}
{"op":"mcm","clk":"11942679531","pt":1724433458388,"mc":[{"id":"1.232196998","rc":[{"batb":[[0,1.97,5.7],[1,1.96,6.48],[2,1.94,1]],"ltp":2.46,"tv":11.24,"id":60191231}]}]}
{"op":"mcm","clk":"11942680079","pt":1724433461684,"mc":[{"id":"1.232196998","rc":[{"batb":[[0,1.96,7.19],[1,1.94,1],[2,1.81,35.22]],"ltp":2.46,"tv":11.24,"id":60191231}]}]}
{"op":"mcm","clk":"11942680893","pt":1724433466515,"mc":[{"id":"1.232196998","rc":[{"batb":[[0,1.97,5.7],[1,1.96,6.48],[2,1.94,1]],"ltp":2.46,"tv":11.24,"id":60191231}]}]}
{"op":"mcm","clk":"11942681399","pt":1724433469908,"mc":[{"id":"1.232196998","rc":[{"batb":[[0,1.96,7.19],[1,1.94,1],[2,1.81,35.22]],"ltp":2.46,"tv":11.24,"id":60191231}]}]}
{"op":"mcm","clk":"11942682509","pt":1724433477231,"mc":[{"id":"1.232196998","rc":[{"batb":[[0,1.97,5.7],[1,1.96,6.48],[2,1.94,1]],"ltp":2.46,"tv":11.24,"id":60191231}]}]}
{"op":"mcm","clk":"11942683076","pt":1724433480729,"mc":[{"id":"1.232196998","rc":[{"batb":[[0,1.96,7.19],[1,1.94,1],[2,1.81,35.22]],"ltp":2.46,"tv":11.24,"id":60191231}]}]}
{"op":"mcm","clk":"11942688030","pt":1724433508854,"mc":[{"id":"1.232196998","rc":[{"batb":[[0,1.97,5.7],[1,1.96,6.48],[2,1.94,1]],"ltp":2.46,"tv":11.24,"id":60191231}]}]}
{"op":"mcm","clk":"11942688537","pt":1724433512038,"mc":[{"id":"1.232196998","rc":[{"batb":[[0,1.96,7.19],[1,1.94,1],[2,1.81,35.22]],"ltp":2.46,"tv":11.24,"id":60191231}]}]}
{"op":"mcm","clk":"11942699136","pt":1724433576958,"mc":[{"id":"1.232196998","rc":[{"batb":[[0,1.97,5.7],[1,1.96,6.48],[2,1.94,1]],"ltp":2.46,"tv":11.24,"id":60191231},{"trd":[[1.68,38.02]],"batb":[[0,1.66,35.54],[1,1.65,1.18],[2,1.64,6.41]],"batl":[[0,1.81,21.72],[1,1.99,36.1],[2,2.24,22.75]],"ltp":1.68,"tv":110.43,"id":72963954}],"tv":121.68}]}
{"op":"mcm","clk":"11942699736","pt":1724433580507,"mc":[{"id":"1.232196998","rc":[{"batb":[[0,1.96,7.19],[1,1.94,1],[2,1.81,35.22]],"ltp":2.46,"tv":11.24,"id":60191231}]}]}
{"op":"mcm","clk":"11942702869","pt":1724433599692,"mc":[{"id":"1.232196998","rc":[{"batb":[[0,1.97,5.7],[1,1.96,6.48],[2,1.94,1]],"ltp":2.46,"tv":11.24,"id":60191231}]}]}
{"op":"mcm","clk":"11942703545","pt":1724433603176,"mc":[{"id":"1.232196998","rc":[{"batb":[[0,1.96,7.19],[1,1.94,1],[2,1.81,35.22]],"ltp":2.46,"tv":11.24,"id":60191231}]}]}
{"op":"mcm","clk":"11942713729","pt":1724433665224,"mc":[{"id":"1.232196998","rc":[{"batb":[[0,1.97,5.7],[1,1.96,6.48],[2,1.94,1]],"ltp":2.46,"tv":11.24,"id":60191231}]}]}
{"op":"mcm","clk":"11942714314","pt":1724433668562,"mc":[{"id":"1.232196998","rc":[{"batb":[[0,1.96,7.19],[1,1.94,1],[2,1.81,35.22]],"ltp":2.46,"tv":11.24,"id":60191231}]}]}
{"op":"mcm","clk":"11942715459","pt":1724433675640,"mc":[{"id":"1.232196998","rc":[{"batb":[[0,1.97,5.7],[1,1.96,6.48],[2,1.94,1]],"ltp":2.46,"tv":11.24,"id":60191231}]}]}
{"op":"mcm","clk":"11942715939","pt":1724433678943,"mc":[{"id":"1.232196998","rc":[{"batb":[[0,1.96,7.19],[1,1.94,1],[2,1.81,35.22]],"ltp":2.46,"tv":11.24,"id":60191231}]}]}
{"op":"mcm","clk":"11942717600","pt":1724433689355,"mc":[{"id":"1.232196998","rc":[{"batb":[[0,1.97,5.7],[1,1.96,6.48],[2,1.94,1]],"ltp":2.46,"tv":11.24,"id":60191231}]}]}
{"op":"mcm","clk":"11942718137","pt":1724433692685,"mc":[{"id":"1.232196998","rc":[{"batb":[[0,1.96,7.19],[1,1.94,1],[2,1.81,35.22]],"ltp":2.46,"tv":11.24,"id":60191231}]}]}
{"op":"mcm","clk":"11942719206","pt":1724433699479,"mc":[{"id":"1.232196998","rc":[{"batb":[[0,1.97,5.7],[1,1.96,6.48],[2,1.94,1]],"ltp":2.46,"tv":11.24,"id":60191231}]}]}
{"op":"mcm","clk":"11942719723","pt":1724433702875,"mc":[{"id":"1.232196998","rc":[{"batb":[[0,1.96,7.19],[1,1.94,1],[2,1.81,35.22]],"ltp":2.46,"tv":11.24,"id":60191231}]}]}
{"op":"mcm","clk":"11942720445","pt":1724433707279,"mc":[{"id":"1.232196998","rc":[{"batb":[[0,1.97,5.7],[1,1.96,6.48],[2,1.94,1]],"ltp":2.46,"tv":11.24,"id":60191231}]}]}
{"op":"mcm","clk":"11942720837","pt":1724433709765,"mc":[{"id":"1.232196998","rc":[{"batb":[[0,1.96,7.19],[1,1.94,1],[2,1.81,35.22]],"ltp":2.46,"tv":11.24,"id":60191231}]}]}
{"op":"mcm","clk":"11942721650","pt":1724433714981,"mc":[{"id":"1.232196998","rc":[{"batb":[[0,1.97,5.7],[1,1.96,6.48],[2,1.94,1]],"ltp":2.46,"tv":11.24,"id":60191231}]}]}
{"op":"mcm","clk":"11942722215","pt":1724433718273,"mc":[{"id":"1.232196998","rc":[{"batb":[[0,1.96,7.19],[1,1.94,1],[2,1.81,35.22]],"ltp":2.46,"tv":11.24,"id":60191231}]}]}
{"op":"mcm","clk":"11942723551","pt":1724433725979,"mc":[{"id":"1.232196998","rc":[{"batb":[[0,1.97,5.7],[1,1.96,6.48],[2,1.94,1]],"ltp":2.46,"tv":11.24,"id":60191231}]}]}
{"op":"mcm","clk":"11942724158","pt":1724433729414,"mc":[{"id":"1.232196998","rc":[{"batb":[[0,1.96,7.19],[1,1.94,1],[2,1.81,35.22]],"ltp":2.46,"tv":11.24,"id":60191231}]}]}
{"op":"mcm","clk":"11942725117","pt":1724433734730,"mc":[{"id":"1.232196998","rc":[{"batb":[[0,1.97,5.7],[1,1.96,6.48],[2,1.94,1]],"ltp":2.46,"tv":11.24,"id":60191231}]}]}
{"op":"mcm","clk":"11942725724","pt":1724433737997,"mc":[{"id":"1.232196998","rc":[{"batb":[[0,1.96,7.19],[1,1.94,1],[2,1.81,35.22]],"ltp":2.46,"tv":11.24,"id":60191231}]}]}
{"op":"mcm","clk":"11942726571","pt":1724433742619,"mc":[{"id":"1.232196998","rc":[{"batb":[[0,1.97,5.7],[1,1.96,6.48],[2,1.94,1]],"ltp":2.46,"tv":11.24,"id":60191231}]}]}
{"op":"mcm","clk":"11942727189","pt":1724433746016,"mc":[{"id":"1.232196998","rc":[{"batb":[[0,1.96,7.19],[1,1.94,1],[2,1.81,35.22]],"ltp":2.46,"tv":11.24,"id":60191231}]}]}
{"op":"mcm","clk":"11942730034","pt":1724433763943,"mc":[{"id":"1.232196998","rc":[{"batb":[[0,1.97,5.7],[1,1.96,6.48],[2,1.94,1]],"ltp":2.46,"tv":11.24,"id":60191231}]}]}
{"op":"mcm","clk":"11942730627","pt":1724433767450,"mc":[{"id":"1.232196998","rc":[{"batb":[[0,1.96,7.19],[1,1.94,1],[2,1.81,35.22]],"ltp":2.46,"tv":11.24,"id":60191231}]}]}
{"op":"mcm","clk":"11942731068","pt":1724433770025,"mc":[{"id":"1.232196998","rc":[{"batb":[[0,1.97,5.7],[1,1.96,6.48],[2,1.94,1]],"ltp":2.46,"tv":11.24,"id":60191231}]}]}
{"op":"mcm","clk":"11942731536","pt":1724433773446,"mc":[{"id":"1.232196998","rc":[{"batb":[[0,1.96,7.19],[1,1.94,1],[2,1.81,35.22]],"ltp":2.46,"tv":11.24,"id":60191231}]}]}
{"op":"mcm","clk":"11942733079","pt":1724433783666,"mc":[{"id":"1.232196998","rc":[{"batb":[[0,1.97,5.7],[1,1.96,6.48],[2,1.94,1]],"ltp":2.46,"tv":11.24,"id":60191231}]}]}
{"op":"mcm","clk":"11942733661","pt":1724433787076,"mc":[{"id":"1.232196998","rc":[{"batb":[[0,1.96,7.19],[1,1.94,1],[2,1.81,35.22]],"ltp":2.46,"tv":11.24,"id":60191231}]}]}
{"op":"mcm","clk":"11942735838","pt":1724433799851,"mc":[{"id":"1.232196998","rc":[{"batb":[[0,1.97,5.7],[1,1.96,6.48],[2,1.94,1]],"ltp":2.46,"tv":11.24,"id":60191231}]}]}
{"op":"mcm","clk":"11942736387","pt":1724433803372,"mc":[{"id":"1.232196998","rc":[{"batb":[[0,1.96,7.19],[1,1.94,1],[2,1.81,35.22]],"ltp":2.46,"tv":11.24,"id":60191231}]}]}
{"op":"mcm","clk":"11942736867","pt":1724433806375,"mc":[{"id":"1.232196998","rc":[{"batb":[[0,1.97,5.7],[1,1.96,6.48],[2,1.94,1]],"ltp":2.46,"tv":11.24,"id":60191231}]}]}
{"op":"mcm","clk":"11942737366","pt":1724433809691,"mc":[{"id":"1.232196998","rc":[{"batb":[[0,1.96,7.19],[1,1.94,1],[2,1.81,35.22]],"ltp":2.46,"tv":11.24,"id":60191231}]}]}
{"op":"mcm","clk":"11942739291","pt":1724433821983,"mc":[{"id":"1.232196998","rc":[{"batb":[[0,1.97,5.7],[1,1.96,6.48],[2,1.94,1]],"ltp":2.46,"tv":11.24,"id":60191231}]}]}
{"op":"mcm","clk":"11942739846","pt":1724433825299,"mc":[{"id":"1.232196998","rc":[{"batb":[[0,1.96,7.19],[1,1.94,1],[2,1.81,35.22]],"ltp":2.46,"tv":11.24,"id":60191231}]}]}
{"op":"mcm","clk":"11942740907","pt":1724433831991,"mc":[{"id":"1.232196998","rc":[{"batb":[[0,1.97,5.7],[1,1.96,6.48],[2,1.94,1]],"ltp":2.46,"tv":11.24,"id":60191231}]}]}
{"op":"mcm","clk":"11942741449","pt":1724433835516,"mc":[{"id":"1.232196998","rc":[{"batb":[[0,1.96,7.19],[1,1.94,1],[2,1.81,35.22]],"ltp":2.46,"tv":11.24,"id":60191231}]}]}
{"op":"mcm","clk":"11942742390","pt":1724433841733,"mc":[{"id":"1.232196998","rc":[{"batb":[[0,1.97,5.7],[1,1.96,6.48],[2,1.94,1]],"ltp":2.46,"tv":11.24,"id":60191231}]}]}
{"op":"mcm","clk":"11942742954","pt":1724433845010,"mc":[{"id":"1.232196998","rc":[{"batb":[[0,1.96,7.19],[1,1.94,1],[2,1.81,35.22]],"ltp":2.46,"tv":11.24,"id":60191231}]}]}
{"op":"mcm","clk":"11942743921","pt":1724433851026,"mc":[{"id":"1.232196998","rc":[{"batb":[[0,1.97,5.7],[1,1.96,6.48],[2,1.94,1]],"ltp":2.46,"tv":11.24,"id":60191231}]}]}
{"op":"mcm","clk":"11942744572","pt":1724433854931,"mc":[{"id":"1.232196998","rc":[{"batb":[[0,1.96,7.19],[1,1.94,1],[2,1.81,35.22]],"ltp":2.46,"tv":11.24,"id":60191231}]}]}
{"op":"mcm","clk":"11942745053","pt":1724433857944,"mc":[{"id":"1.232196998","rc":[{"batb":[[0,1.97,5.7],[1,1.96,6.48],[2,1.94,1]],"ltp":2.46,"tv":11.24,"id":60191231}]}]}
{"op":"mcm","clk":"11942745525","pt":1724433861112,"mc":[{"id":"1.232196998","rc":[{"batb":[[0,1.96,7.19],[1,1.94,1],[2,1.81,35.22]],"ltp":2.46,"tv":11.24,"id":60191231}]}]}
{"op":"mcm","clk":"11942747436","pt":1724433873049,"mc":[{"id":"1.232196998","rc":[{"batb":[[0,1.97,5.7],[1,1.96,6.48],[2,1.94,1]],"ltp":2.46,"tv":11.24,"id":60191231}]}]}
{"op":"mcm","clk":"11942747967","pt":1724433876457,"mc":[{"id":"1.232196998","rc":[{"batb":[[0,1.96,7.19],[1,1.94,1],[2,1.81,35.22]],"ltp":2.46,"tv":11.24,"id":60191231}]}]}
{"op":"mcm","clk":"11942748451","pt":1724433879429,"mc":[{"id":"1.232196998","rc":[{"batb":[[0,1.97,5.7],[1,1.96,6.48],[2,1.94,1]],"ltp":2.46,"tv":11.24,"id":60191231}]}]}
{"op":"mcm","clk":"11942749100","pt":1724433883392,"mc":[{"id":"1.232196998","rc":[{"batb":[[0,1.96,7.19],[1,1.94,1],[2,1.81,35.22]],"ltp":2.46,"tv":11.24,"id":60191231}]}]}
{"op":"mcm","clk":"11942750424","pt":1724433891769,"mc":[{"id":"1.232196998","rc":[{"batb":[[0,1.97,5.7],[1,1.96,6.48],[2,1.94,1]],"ltp":2.46,"tv":11.24,"id":60191231}]}]}
{"op":"mcm","clk":"11942750953","pt":1724433894977,"mc":[{"id":"1.232196998","rc":[{"batb":[[0,1.96,7.19],[1,1.94,1],[2,1.81,35.22]],"ltp":2.46,"tv":11.24,"id":60191231}]}]}
{"op":"mcm","clk":"11942751455","pt":1724433898196,"mc":[{"id":"1.232196998","rc":[{"batb":[[0,1.97,5.7],[1,1.96,6.48],[2,1.94,1]],"ltp":2.46,"tv":11.24,"id":60191231}]}]}
{"op":"mcm","clk":"11942752041","pt":1724433901707,"mc":[{"id":"1.232196998","rc":[{"batb":[[0,1.96,7.19],[1,1.94,1],[2,1.81,35.22]],"ltp":2.46,"tv":11.24,"id":60191231}]}]}
{"op":"mcm","clk":"11942753924","pt":1724433912120,"mc":[{"id":"1.232196998","rc":[{"batb":[[0,1.97,5.7],[1,1.96,6.48],[2,1.94,1]],"ltp":2.46,"tv":11.24,"id":60191231}]}]}
{"op":"mcm","clk":"11942754523","pt":1724433915368,"mc":[{"id":"1.232196998","rc":[{"batb":[[0,1.96,7.19],[1,1.94,1],[2,1.81,35.22]],"ltp":2.46,"tv":11.24,"id":60191231}]}]}
{"op":"mcm","clk":"11942755112","pt":1724433918778,"mc":[{"id":"1.232196998","rc":[{"batb":[[0,1.97,5.7],[1,1.96,6.48],[2,1.94,1]],"ltp":2.46,"tv":11.24,"id":60191231}]}]}
{"op":"mcm","clk":"11942755637","pt":1724433921964,"mc":[{"id":"1.232196998","rc":[{"batb":[[0,1.96,7.19],[1,1.94,1],[2,1.81,35.22]],"ltp":2.46,"tv":11.24,"id":60191231}]}]}
{"op":"mcm","clk":"11942756534","pt":1724433927261,"mc":[{"id":"1.232196998","rc":[{"batb":[[0,1.97,5.7],[1,1.96,6.48],[2,1.94,1]],"ltp":2.46,"tv":11.24,"id":60191231}]}]}
{"op":"mcm","clk":"11942757086","pt":1724433930682,"mc":[{"id":"1.232196998","rc":[{"batb":[[0,1.96,7.19],[1,1.94,1],[2,1.81,35.22]],"ltp":2.46,"tv":11.24,"id":60191231}]}]}
{"op":"mcm","clk":"11942758405","pt":1724433938209,"mc":[{"id":"1.232196998","rc":[{"batb":[[0,1.97,5.7],[1,1.96,6.48],[2,1.94,1]],"ltp":2.46,"tv":11.24,"id":60191231}]}]}
{"op":"mcm","clk":"11942758984","pt":1724433941597,"mc":[{"id":"1.232196998","rc":[{"batb":[[0,1.96,7.19],[1,1.94,1],[2,1.81,35.22]],"ltp":2.46,"tv":11.24,"id":60191231}]}]}
{"op":"mcm","clk":"11942760371","pt":1724433950016,"mc":[{"id":"1.232196998","rc":[{"batb":[[0,1.97,5.7],[1,1.96,6.48],[2,1.94,1]],"ltp":2.46,"tv":11.24,"id":60191231}]}]}
{"op":"mcm","clk":"11942760951","pt":1724433953504,"mc":[{"id":"1.232196998","rc":[{"batb":[[0,1.96,7.19],[1,1.94,1],[2,1.81,35.22]],"ltp":2.46,"tv":11.24,"id":60191231}]}]}
{"op":"mcm","clk":"11942762091","pt":1724433960113,"mc":[{"id":"1.232196998","rc":[{"batb":[[0,1.97,5.7],[1,1.96,6.48],[2,1.94,1]],"ltp":2.46,"tv":11.24,"id":60191231}]}]}
{"op":"mcm","clk":"11942762787","pt":1724433963714,"mc":[{"id":"1.232196998","rc":[{"batb":[[0,1.96,7.19],[1,1.94,1],[2,1.81,35.22]],"ltp":2.46,"tv":11.24,"id":60191231}]}]}
{"op":"mcm","clk":"11942763724","pt":1724433968612,"mc":[{"id":"1.232196998","rc":[{"batb":[[0,1.97,5.7],[1,1.96,6.48],[2,1.94,1]],"ltp":2.46,"tv":11.24,"id":60191231}]}]}
{"op":"mcm","clk":"11942764321","pt":1724433972037,"mc":[{"id":"1.232196998","rc":[{"batb":[[0,1.96,7.19],[1,1.94,1],[2,1.81,35.22]],"ltp":2.46,"tv":11.24,"id":60191231}]}]}
{"op":"mcm","clk":"11942765083","pt":1724433975956,"mc":[{"id":"1.232196998","rc":[{"batb":[[0,1.97,5.7],[1,1.96,6.48],[2,1.94,1]],"ltp":2.46,"tv":11.24,"id":60191231}]}]}
{"op":"mcm","clk":"11942765733","pt":1724433979247,"mc":[{"id":"1.232196998","rc":[{"batb":[[0,1.96,7.19],[1,1.94,1],[2,1.81,35.22]],"ltp":2.46,"tv":11.24,"id":60191231}]}]}
{"op":"mcm","clk":"11942766485","pt":1724433983533,"mc":[{"id":"1.232196998","rc":[{"batb":[[0,1.97,5.7],[1,1.96,6.48],[2,1.94,1]],"ltp":2.46,"tv":11.24,"id":60191231}]}]}
{"op":"mcm","clk":"11942767140","pt":1724433987134,"mc":[{"id":"1.232196998","rc":[{"batb":[[0,1.96,7.19],[1,1.94,1],[2,1.81,35.22]],"ltp":2.46,"tv":11.24,"id":60191231}]}]}
{"op":"mcm","clk":"11942768637","pt":1724433995642,"mc":[{"id":"1.232196998","rc":[{"batb":[[0,1.97,5.7],[1,1.96,6.48],[2,1.94,1]],"ltp":2.46,"tv":11.24,"id":60191231}]}]}
{"op":"mcm","clk":"11942769199","pt":1724433999171,"mc":[{"id":"1.232196998","rc":[{"batb":[[0,1.96,7.19],[1,1.94,1],[2,1.81,35.22]],"ltp":2.46,"tv":11.24,"id":60191231}]}]}
{"op":"mcm","clk":"11942771121","pt":1724434010591,"mc":[{"id":"1.232196998","rc":[{"batb":[[0,1.97,5.7],[1,1.96,6.48],[2,1.94,1]],"ltp":2.46,"tv":11.24,"id":60191231}]}]}
{"op":"mcm","clk":"11942771673","pt":1724434014063,"mc":[{"id":"1.232196998","rc":[{"batb":[[0,1.96,7.19],[1,1.94,1],[2,1.81,35.22]],"ltp":2.46,"tv":11.24,"id":60191231}]}]}
{"op":"mcm","clk":"11942780723","pt":1724434067732,"mc":[{"id":"1.232196998","rc":[{"batb":[[0,1.97,5.7],[1,1.96,6.48],[2,1.94,1]],"ltp":2.46,"tv":11.24,"id":60191231}]}]}
{"op":"mcm","clk":"11942781423","pt":1724434071455,"mc":[{"id":"1.232196998","rc":[{"batb":[[0,1.96,7.19],[1,1.94,1],[2,1.81,35.22]],"ltp":2.46,"tv":11.24,"id":60191231}]}]}
{"op":"mcm","clk":"11942782031","pt":1724434074957,"mc":[{"id":"1.232196998","rc":[{"batb":[[0,1.97,5.7],[1,1.96,6.48],[2,1.94,1]],"ltp":2.46,"tv":11.24,"id":60191231}]}]}
{"op":"mcm","clk":"11942782644","pt":1724434078454,"mc":[{"id":"1.232196998","rc":[{"batb":[[0,1.96,7.19],[1,1.94,1],[2,1.81,35.22]],"ltp":2.46,"tv":11.24,"id":60191231}]}]}
{"op":"mcm","clk":"11942784065","pt":1724434086233,"mc":[{"id":"1.232196998","rc":[{"batb":[[0,1.97,5.7],[1,1.96,6.48],[2,1.94,1]],"ltp":2.46,"tv":11.24,"id":60191231}]}]}
{"op":"mcm","clk":"11942784685","pt":1724434089949,"mc":[{"id":"1.232196998","rc":[{"batb":[[0,1.96,7.19],[1,1.94,1],[2,1.81,35.22]],"ltp":2.46,"tv":11.24,"id":60191231}]}]}
{"op":"mcm","clk":"11942785480","pt":1724434093878,"mc":[{"id":"1.232196998","rc":[{"batb":[[0,1.97,5.7],[1,1.96,6.48],[2,1.94,1]],"ltp":2.46,"tv":11.24,"id":60191231}]}]}
{"op":"mcm","clk":"11942786113","pt":1724434096984,"mc":[{"id":"1.232196998","rc":[{"batl":[[0,2.5,0.61]],"ltp":2.46,"tv":11.24,"id":60191231}]}]}
{"op":"mcm","clk":"11942786235","pt":1724434097682,"mc":[{"id":"1.232196998","rc":[{"batb":[[0,1.96,7.19],[1,1.94,1],[2,1.81,35.22]],"ltp":2.46,"tv":11.24,"id":60191231}]}]}
{"op":"mcm","clk":"11942787416","pt":1724434103925,"mc":[{"id":"1.232196998","rc":[{"batb":[[0,1.97,5.7],[1,1.96,6.48],[2,1.94,1]],"ltp":2.46,"tv":11.24,"id":60191231}]}]}
{"op":"mcm","clk":"11942788006","pt":1724434107205,"mc":[{"id":"1.232196998","rc":[{"batb":[[0,1.96,7.19],[1,1.94,1],[2,1.81,35.22]],"ltp":2.46,"tv":11.24,"id":60191231}]}]}
{"op":"mcm","clk":"11942788812","pt":1724434111522,"mc":[{"id":"1.232196998","rc":[{"batb":[[0,1.97,5.7],[1,1.96,6.48],[2,1.94,1]],"ltp":2.46,"tv":11.24,"id":60191231}]}]}
{"op":"mcm","clk":"11942789486","pt":1724434115133,"mc":[{"id":"1.232196998","rc":[{"batb":[[0,1.96,7.19],[1,1.94,1],[2,1.81,35.22]],"ltp":2.46,"tv":11.24,"id":60191231}]}]}
{"op":"mcm","clk":"11942791131","pt":1724434124516,"mc":[{"id":"1.232196998","rc":[{"batb":[[0,1.97,5.7],[1,1.96,6.48],[2,1.94,1]],"ltp":2.46,"tv":11.24,"id":60191231}]}]}
{"op":"mcm","clk":"11942791770","pt":1724434128049,"mc":[{"id":"1.232196998","rc":[{"batb":[[0,1.96,7.19],[1,1.94,1],[2,1.81,35.22]],"ltp":2.46,"tv":11.24,"id":60191231}]}]}
{"op":"mcm","clk":"11942794504","pt":1724434143791,"mc":[{"id":"1.232196998","rc":[{"batb":[[0,1.97,5.7],[1,1.96,6.48],[2,1.94,1]],"ltp":2.46,"tv":11.24,"id":60191231}]}]}
{"op":"mcm","clk":"11942795207","pt":1724434147269,"mc":[{"id":"1.232196998","rc":[{"batb":[[0,1.96,7.19],[1,1.94,1],[2,1.81,35.22]],"ltp":2.46,"tv":11.24,"id":60191231}]}]}
{"op":"mcm","clk":"11942796803","pt":1724434155296,"mc":[{"id":"1.232196998","rc":[{"batb":[[0,1.97,5.7],[1,1.96,6.48],[2,1.94,1]],"ltp":2.46,"tv":11.24,"id":60191231}]}]}
{"op":"mcm","clk":"11942797514","pt":1724434158875,"mc":[{"id":"1.232196998","rc":[{"batb":[[0,1.96,7.19],[1,1.94,1],[2,1.81,35.22]],"ltp":2.46,"tv":11.24,"id":60191231}]}]}
{"op":"mcm","clk":"11942797622","pt":1724434159511,"mc":[{"id":"1.232196998","rc":[{"batb":[[0,1.68,182.45],[1,1.66,35.22],[2,1.65,1.18]],"ltp":1.68,"tv":110.43,"id":72963954}]}]}
{"op":"mcm","clk":"11942800825","pt":1724434176524,"mc":[{"id":"1.232196998","rc":[{"batb":[[0,1.97,5.7],[1,1.96,6.48],[2,1.94,1]],"ltp":2.46,"tv":11.24,"id":60191231}]}]}
{"op":"mcm","clk":"11942801113","pt":1724434178210,"mc":[{"id":"1.232196998","rc":[{"batl":[[0,1.71,1.82],[1,1.81,21.72],[2,1.99,36.1]],"ltp":1.68,"tv":110.43,"id":72963954}]}]}
{"op":"mcm","clk":"11942801531","pt":1724434180326,"mc":[{"id":"1.232196998","rc":[{"batb":[[0,1.96,7.19],[1,1.94,1],[2,1.81,35.22]],"ltp":2.46,"tv":11.24,"id":60191231}]}]}
{"op":"mcm","clk":"11942803431","pt":1724434190706,"mc":[{"id":"1.232196998","rc":[{"batb":[[0,1.97,5.7],[1,1.96,6.48],[2,1.94,1]],"ltp":2.46,"tv":11.24,"id":60191231}]}]}
{"op":"mcm","clk":"11942804087","pt":1724434194307,"mc":[{"id":"1.232196998","rc":[{"batb":[[0,1.96,7.19],[1,1.94,1],[2,1.81,35.22]],"ltp":2.46,"tv":11.24,"id":60191231}]}]}
{"op":"mcm","clk":"11942805040","pt":1724434199380,"mc":[{"id":"1.232196998","rc":[{"batb":[[0,1.97,5.7],[1,1.96,6.48],[2,1.94,1]],"ltp":2.46,"tv":11.24,"id":60191231}]}]}
{"op":"mcm","clk":"11942805764","pt":1724434202621,"mc":[{"id":"1.232196998","rc":[{"batb":[[0,1.96,7.19],[1,1.94,1],[2,1.81,35.22]],"ltp":2.46,"tv":11.24,"id":60191231}]}]}
{"op":"mcm","clk":"11942806887","pt":1724434208148,"mc":[{"id":"1.232196998","rc":[{"batb":[[0,1.97,5.7],[1,1.96,6.48],[2,1.94,1]],"ltp":2.46,"tv":11.24,"id":60191231}]}]}
{"op":"mcm","clk":"11942807643","pt":1724434211542,"mc":[{"id":"1.232196998","rc":[{"batb":[[0,1.96,7.19],[1,1.94,1],[2,1.81,35.22]],"ltp":2.46,"tv":11.24,"id":60191231}]}]}
{"op":"mcm","clk":"11942808408","pt":1724434215125,"mc":[{"id":"1.232196998","rc":[{"batb":[[0,1.97,5.7],[1,1.96,6.48],[2,1.94,1]],"ltp":2.46,"tv":11.24,"id":60191231},{"batb":[[0,1.66,35.54],[1,1.65,1.18],[2,1.64,6.41]],"ltp":1.68,"tv":110.43,"id":72963954}]}]}
{"op":"mcm","clk":"11942809022","pt":1724434218454,"mc":[{"id":"1.232196998","rc":[{"batb":[[0,1.96,7.19],[1,1.94,1],[2,1.81,35.22]],"ltp":2.46,"tv":11.24,"id":60191231}]}]}
{"op":"mcm","clk":"11942809536","pt":1724434221139,"mc":[{"id":"1.232196998","rc":[{"batb":[[0,1.97,5.7],[1,1.96,6.48],[2,1.94,1]],"ltp":2.46,"tv":11.24,"id":60191231}]}]}
{"op":"mcm","clk":"11942810172","pt":1724434224665,"mc":[{"id":"1.232196998","rc":[{"batb":[[0,1.96,7.19],[1,1.94,1],[2,1.81,35.22]],"ltp":2.46,"tv":11.24,"id":60191231}]}]}
{"op":"mcm","clk":"11942810688","pt":1724434227459,"mc":[{"id":"1.232196998","rc":[{"batb":[[0,1.97,5.7],[1,1.96,6.48],[2,1.94,1]],"ltp":2.46,"tv":11.24,"id":60191231}]}]}
{"op":"mcm","clk":"11942811253","pt":1724434230685,"mc":[{"id":"1.232196998","rc":[{"batb":[[0,1.96,7.19],[1,1.94,1],[2,1.81,35.22]],"ltp":2.46,"tv":11.24,"id":60191231}]}]}
{"op":"mcm","clk":"11942812808","pt":1724434238867,"mc":[{"id":"1.232196998","rc":[{"batb":[[0,1.97,5.7],[1,1.96,6.48],[2,1.94,1]],"ltp":2.46,"tv":11.24,"id":60191231}]}]}
{"op":"mcm","clk":"11942813464","pt":1724434242290,"mc":[{"id":"1.232196998","rc":[{"batb":[[0,1.96,7.19],[1,1.94,1],[2,1.81,35.22]],"ltp":2.46,"tv":11.24,"id":60191231}]}]}
{"op":"mcm","clk":"11942815490","pt":1724434253593,"mc":[{"id":"1.232196998","rc":[{"batb":[[0,1.97,5.7],[1,1.96,6.48],[2,1.94,1]],"ltp":2.46,"tv":11.24,"id":60191231}]}]}
{"op":"mcm","clk":"11942816114","pt":1724434256984,"mc":[{"id":"1.232196998","rc":[{"batb":[[0,1.96,7.19],[1,1.94,1],[2,1.81,35.22]],"ltp":2.46,"tv":11.24,"id":60191231}]}]}
{"op":"mcm","clk":"11942816889","pt":1724434260895,"mc":[{"id":"1.232196998","rc":[{"batb":[[0,1.97,5.7],[1,1.96,6.48],[2,1.94,1]],"ltp":2.46,"tv":11.24,"id":60191231}]}]}
{"op":"mcm","clk":"11942817583","pt":1724434264415,"mc":[{"id":"1.232196998","rc":[{"batb":[[0,1.96,7.19],[1,1.94,1],[2,1.81,35.22]],"ltp":2.46,"tv":11.24,"id":60191231}]}]}
{"op":"mcm","clk":"11942818304","pt":1724434267922,"mc":[{"id":"1.232196998","rc":[{"batb":[[0,1.97,5.7],[1,1.96,6.48],[2,1.94,1]],"ltp":2.46,"tv":11.24,"id":60191231}]}]}
{"op":"mcm","clk":"11942818986","pt":1724434271392,"mc":[{"id":"1.232196998","rc":[{"batb":[[0,1.96,7.19],[1,1.94,1],[2,1.81,35.22]],"ltp":2.46,"tv":11.24,"id":60191231}]}]}
{"op":"mcm","clk":"11942819538","pt":1724434274235,"mc":[{"id":"1.232196998","rc":[{"batb":[[0,1.97,5.7],[1,1.96,6.48],[2,1.94,1]],"ltp":2.46,"tv":11.24,"id":60191231}]}]}
{"op":"mcm","clk":"11942820262","pt":1724434278234,"mc":[{"id":"1.232196998","rc":[{"batb":[[0,1.96,7.19],[1,1.94,1],[2,1.81,35.22]],"ltp":2.46,"tv":11.24,"id":60191231}]}]}
{"op":"mcm","clk":"11942822066","pt":1724434287110,"mc":[{"id":"1.232196998","rc":[{"batb":[[0,1.97,5.7],[1,1.96,6.48],[2,1.94,1]],"ltp":2.46,"tv":11.24,"id":60191231}]}]}
{"op":"mcm","clk":"11942822755","pt":1724434290826,"mc":[{"id":"1.232196998","rc":[{"batb":[[0,1.96,7.19],[1,1.94,1],[2,1.81,35.22]],"ltp":2.46,"tv":11.24,"id":60191231}]}]}
{"op":"mcm","clk":"11942824124","pt":1724434298151,"mc":[{"id":"1.232196998","rc":[{"batb":[[0,1.97,5.7],[1,1.96,6.48],[2,1.94,1]],"ltp":2.46,"tv":11.24,"id":60191231}]}]}
{"op":"mcm","clk":"11942824436","pt":1724434299928,"mc":[{"id":"1.232196998","rc":[{"trd":[[1.71,3.64]],"batb":[[0,1.71,16.05],[1,1.66,35.54],[2,1.65,1.18]],"batl":[[0,1.81,21.72],[1,1.99,36.1],[2,2.24,22.75]],"ltp":1.71,"tv":114.07,"id":72963954}],"tv":125.32}]}
{"op":"mcm","clk":"11942824751","pt":1724434301614,"mc":[{"id":"1.232196998","rc":[{"batb":[[0,1.96,7.19],[1,1.94,1],[2,1.81,35.22]],"ltp":2.46,"tv":11.24,"id":60191231}]}]}
{"op":"mcm","clk":"11942825277","pt":1724434304441,"mc":[{"id":"1.232196998","rc":[{"batb":[[0,1.97,5.7],[1,1.96,6.48],[2,1.94,1]],"ltp":2.46,"tv":11.24,"id":60191231}]}]}
{"op":"mcm","clk":"11942825757","pt":1724434306731,"mc":[{"id":"1.232196998","rc":[{"batb":[[0,1.66,35.54],[1,1.65,1.18],[2,1.64,6.41]],"ltp":1.71,"tv":114.07,"id":72963954}]}]}
{"op":"mcm","clk":"11942825945","pt":1724434307838,"mc":[{"id":"1.232196998","rc":[{"batb":[[0,1.96,7.19],[1,1.94,1],[2,1.81,35.22]],"ltp":2.46,"tv":11.24,"id":60191231}]}]}
{"op":"mcm","clk":"11942826997","pt":1724434313563,"mc":[{"id":"1.232196998","rc":[{"batb":[[0,1.97,5.7],[1,1.96,6.48],[2,1.94,1]],"ltp":2.46,"tv":11.24,"id":60191231}]}]}
{"op":"mcm","clk":"11942827672","pt":1724434317265,"mc":[{"id":"1.232196998","rc":[{"batb":[[0,1.96,7.19],[1,1.94,1],[2,1.81,35.22]],"ltp":2.46,"tv":11.24,"id":60191231}]}]}
{"op":"mcm","clk":"11942828378","pt":1724434321274,"mc":[{"id":"1.232196998","rc":[{"batb":[[0,1.97,5.7],[1,1.96,6.48],[2,1.94,1]],"ltp":2.46,"tv":11.24,"id":60191231}]}]}
{"op":"mcm","clk":"11942829150","pt":1724434325155,"mc":[{"id":"1.232196998","rc":[{"batb":[[0,1.96,7.19],[1,1.94,1],[2,1.81,35.22]],"ltp":2.46,"tv":11.24,"id":60191231}]}]}
{"op":"mcm","clk":"11942830468","pt":1724434331952,"mc":[{"id":"1.232196998","rc":[{"batb":[[0,1.97,5.7],[1,1.96,6.48],[2,1.94,1]],"ltp":2.46,"tv":11.24,"id":60191231}]}]}
{"op":"mcm","clk":"11942831128","pt":1724434335472,"mc":[{"id":"1.232196998","rc":[{"batb":[[0,1.96,7.19],[1,1.94,1],[2,1.81,35.22]],"ltp":2.46,"tv":11.24,"id":60191231}]}]}
{"op":"mcm","clk":"11942831622","pt":1724434338271,"mc":[{"id":"1.232196998","rc":[{"batb":[[0,1.97,5.7],[1,1.96,6.48],[2,1.94,1]],"ltp":2.46,"tv":11.24,"id":60191231}]}]}
{"op":"mcm","clk":"11942832252","pt":1724434341671,"mc":[{"id":"1.232196998","rc":[{"batb":[[0,1.96,7.19],[1,1.94,1],[2,1.81,35.22]],"ltp":2.46,"tv":11.24,"id":60191231}]}]}
{"op":"mcm","clk":"11942832888","pt":1724434345003,"mc":[{"id":"1.232196998","rc":[{"batb":[[0,1.97,5.7],[1,1.96,6.48],[2,1.94,1]],"ltp":2.46,"tv":11.24,"id":60191231}]}]}
{"op":"mcm","clk":"11942833376","pt":1724434347696,"mc":[{"id":"1.232196998","rc":[{"batl":[[0,1.8,1.53],[1,1.81,20.84],[2,1.99,36.1]],"ltp":1.71,"tv":114.07,"id":72963954}]}]}
{"op":"mcm","clk":"11942833502","pt":1724434348384,"mc":[{"id":"1.232196998","rc":[{"batb":[[0,1.96,7.19],[1,1.94,1],[2,1.81,35.22]],"ltp":2.46,"tv":11.24,"id":60191231}]}]}
{"op":"mcm","clk":"11942834910","pt":1724434355600,"mc":[{"id":"1.232196998","rc":[{"batb":[[0,1.97,5.7],[1,1.96,6.48],[2,1.94,1]],"ltp":2.46,"tv":11.24,"id":60191231}]}]}
{"op":"mcm","clk":"11942835459","pt":1724434358814,"mc":[{"id":"1.232196998","rc":[{"batb":[[0,1.96,7.19],[1,1.94,1],[2,1.81,35.22]],"ltp":2.46,"tv":11.24,"id":60191231}]}]}
{"op":"mcm","clk":"11942836032","pt":1724434361938,"mc":[{"id":"1.232196998","rc":[{"batb":[[0,1.97,5.7],[1,1.96,6.48],[2,1.94,1]],"ltp":2.46,"tv":11.24,"id":60191231}]}]}
{"op":"mcm","clk":"11942836688","pt":1724434365507,"mc":[{"id":"1.232196998","rc":[{"batb":[[0,1.96,7.19],[1,1.94,1],[2,1.81,35.22]],"ltp":2.46,"tv":11.24,"id":60191231}]}]}
{"op":"mcm","clk":"11942837306","pt":1724434368804,"mc":[{"id":"1.232196998","rc":[{"batb":[[0,1.97,5.7],[1,1.96,6.48],[2,1.94,1]],"ltp":2.46,"tv":11.24,"id":60191231}]}]}
{"op":"mcm","clk":"11942837929","pt":1724434372121,"mc":[{"id":"1.232196998","rc":[{"batb":[[0,1.96,7.19],[1,1.94,1],[2,1.81,35.22]],"ltp":2.46,"tv":11.24,"id":60191231}]}]}
{"op":"mcm","clk":"11942838432","pt":1724434374724,"mc":[{"id":"1.232196998","rc":[{"batb":[[0,1.97,5.7],[1,1.96,6.48],[2,1.94,1]],"ltp":2.46,"tv":11.24,"id":60191231}]}]}
{"op":"mcm","clk":"11942838617","pt":1724434375725,"mc":[{"id":"1.232196998","rc":[{"batl":[[0,1.81,21.72],[1,1.99,36.1],[2,2.24,22.75]],"ltp":1.71,"tv":114.07,"id":72963954}]}]}
{"op":"mcm","clk":"11942839086","pt":1724434378132,"mc":[{"id":"1.232196998","rc":[{"batb":[[0,1.96,7.19],[1,1.94,1],[2,1.81,35.22]],"ltp":2.46,"tv":11.24,"id":60191231}]}]}
{"op":"mcm","clk":"11942840112","pt":1724434383641,"mc":[{"id":"1.232196998","rc":[{"batb":[[0,1.97,5.7],[1,1.96,6.48],[2,1.94,1]],"ltp":2.46,"tv":11.24,"id":60191231}]}]}
{"op":"mcm","clk":"11942840686","pt":1724434386919,"mc":[{"id":"1.232196998","rc":[{"batb":[[0,1.96,7.19],[1,1.94,1],[2,1.81,35.22]],"ltp":2.46,"tv":11.24,"id":60191231}]}]}
{"op":"mcm","clk":"11942841492","pt":1724434390742,"mc":[{"id":"1.232196998","rc":[{"batb":[[0,1.97,5.7],[1,1.96,6.48],[2,1.94,1]],"ltp":2.46,"tv":11.24,"id":60191231}]}]}
{"op":"mcm","clk":"11942842186","pt":1724434394019,"mc":[{"id":"1.232196998","rc":[{"batb":[[0,1.96,7.19],[1,1.94,1],[2,1.81,35.22]],"ltp":2.46,"tv":11.24,"id":60191231}]}]}
{"op":"mcm","clk":"11942843459","pt":1724434400059,"mc":[{"id":"1.232196998","rc":[{"batb":[[0,1.97,5.7],[1,1.96,6.48],[2,1.94,1]],"ltp":2.46,"tv":11.24,"id":60191231}]}]}
{"op":"mcm","clk":"11942844227","pt":1724434403664,"mc":[{"id":"1.232196998","rc":[{"batb":[[0,1.96,7.19],[1,1.94,1],[2,1.81,35.22]],"ltp":2.46,"tv":11.24,"id":60191231}]}]}
{"op":"mcm","clk":"11942845723","pt":1724434410572,"mc":[{"id":"1.232196998","rc":[{"batb":[[0,1.97,5.7],[1,1.96,6.48],[2,1.94,1]],"ltp":2.46,"tv":11.24,"id":60191231}]}]}
{"op":"mcm","clk":"11942846528","pt":1724434414071,"mc":[{"id":"1.232196998","rc":[{"batb":[[0,1.96,7.19],[1,1.94,1],[2,1.81,35.22]],"ltp":2.46,"tv":11.24,"id":60191231}]}]}
{"op":"mcm","clk":"11942847094","pt":1724434416787,"mc":[{"id":"1.232196998","rc":[{"batb":[[0,1.97,5.7],[1,1.96,6.48],[2,1.94,1]],"ltp":2.46,"tv":11.24,"id":60191231}]}]}
{"op":"mcm","clk":"11942847774","pt":1724434420268,"mc":[{"id":"1.232196998","rc":[{"batb":[[0,1.96,7.19],[1,1.94,1],[2,1.81,35.22]],"ltp":2.46,"tv":11.24,"id":60191231}]}]}
{"op":"mcm","clk":"11942849041","pt":1724434426167,"mc":[{"id":"1.232196998","rc":[{"batb":[[0,1.97,5.7],[1,1.96,6.48],[2,1.94,1]],"ltp":2.46,"tv":11.24,"id":60191231}]}]}
{"op":"mcm","clk":"11942849744","pt":1724434429456,"mc":[{"id":"1.232196998","rc":[{"batb":[[0,1.96,7.19],[1,1.94,1],[2,1.81,35.22]],"ltp":2.46,"tv":11.24,"id":60191231}]}]}
{"op":"mcm","clk":"11942850064","pt":1724434431092,"mc":[{"id":"1.232196998","rc":[{"batb":[[2,1.63,113.13]],"ltp":1.71,"tv":114.07,"id":72963954}]}]}
{"op":"mcm","clk":"11942850166","pt":1724434431364,"mc":[{"id":"1.232196998","rc":[{"batb":[[0,1.94,1.7],[1,1.81,35.22],[2,1.21,24.76]],"ltp":2.46,"tv":11.24,"id":60191231}]}]}
{"op":"mcm","clk":"11942859916","pt":1724434476735,"mc":[{"id":"1.232196998","rc":[{"trd":[[2.26,0.7]],"batb":[[0,1.94,1]],"ltp":2.26,"tv":11.95,"id":60191231},{"trd":[[1.8,2.64]],"batb":[[0,1.8,1.55],[1,1.66,35.54],[2,1.65,1.18]],"batl":[[0,1.81,20.84]],"ltp":1.8,"tv":116.71,"id":72963954}],"tv":128.67}]}
{"op":"mcm","clk":"11942860744","pt":1724434480736,"mc":[{"id":"1.232196998","rc":[{"trd":[[1.8,5.74]],"batb":[[0,1.66,35.54],[1,1.65,1.18],[2,1.63,113.13]],"batl":[[0,1.8,16.32],[1,1.81,20.84],[2,1.99,36.1]],"ltp":1.8,"tv":119.81,"id":72963954}],"tv":131.76}]}
{"op":"mcm","clk":"11942861589","pt":1724434484839,"mc":[{"id":"1.232196998","rc":[{"batl":[[0,1.81,20.84],[1,1.99,36.1],[2,2.24,22.75]],"ltp":1.8,"tv":119.81,"id":72963954}]}]}
{"op":"mcm","clk":"11942883720","pt":1724434595734,"mc":[{"id":"1.232196998","rc":[{"batl":[[0,1.81,21.03]],"ltp":1.8,"tv":119.81,"id":72963954}]}]}
{"op":"mcm","clk":"11942886693","pt":1724434610702,"mc":[{"id":"1.232196998","rc":[{"batl":[[0,1.81,20.84]],"ltp":1.8,"tv":119.81,"id":72963954}]}]}
{"op":"mcm","clk":"11942925467","pt":1724434815063,"mc":[{"id":"1.232196998","rc":[{"trd":[[2.22,1.27]],"ltp":2.22,"tv":13.22,"id":60191231},{"trd":[[1.81,30.32]],"batl":[[0,1.81,19.29]],"ltp":1.81,"tv":121.37,"id":72963954}],"tv":134.59}]}
{"op":"mcm","clk":"11943046984","pt":1724435499655,"mc":[{"id":"1.232196998","rc":[{"batl":[[0,2.5,1.23]],"ltp":2.22,"tv":13.22,"id":60191231}]}]}
{"op":"mcm","clk":"11943109279","pt":1724435967005,"mc":[{"id":"1.232196998","rc":[{"batb":[[0,1.72,27],[1,1.66,35.54],[2,1.65,1.18]],"ltp":1.81,"tv":121.37,"id":72963954}]}]}
{"op":"mcm","clk":"11943113605","pt":1724435999031,"mc":[{"id":"1.232196998","rc":[{"batb":[[0,1.74,27],[1,1.72,27],[2,1.66,35.54]],"ltp":1.81,"tv":121.37,"id":72963954}]}]}
{"op":"mcm","clk":"11943114997","pt":1724436006454,"mc":[{"id":"1.232196998","rc":[{"trd":[[2,0.76],[2.26,0.7],[2.44,1.41],[2.46,9.07]],"batb":[[1,1.81,35.16],[2,1.21,24.77]],"batl":[[0,2.5,1.23]],"ltp":2.22,"tv":13.21,"id":60191231},{"trd":[[1.68,37.99],[1.71,3.64],[1.8,5.73],[1.81,30.27],[1.85,4.54],[1.88,6.3],[1.91,3.03],[1.93,4.54],[1.95,4.54],[1.97,6.3],[1.98,4.5],[1.99,4.54],[2,5.3]],"batb":[[0,1.72,27],[1,1.66,35.48],[2,1.65,1.18]],"batl":[[0,1.81,19.25],[1,1.99,36.04],[2,2.24,22.72]],"ltp":1.81,"tv":121.21,"id":72963954}],"tv":134.42}]}
{"op":"mcm","clk":"11943115181","pt":1724436007553,"mc":[{"id":"1.232196998","rc":[{"batb":[[0,1.66,35.48],[1,1.65,1.18],[2,1.63,113.14]],"ltp":1.81,"tv":121.21,"id":72963954}]}]}
{"op":"mcm","clk":"11943272764","pt":1724436781715,"mc":[{"id":"1.232196998","rc":[{"batl":[[0,1.81,19.44]],"ltp":1.81,"tv":121.21,"id":72963954}]}]}
{"op":"mcm","clk":"11943328132","pt":1724437044812,"mc":[{"id":"1.232196998","rc":[{"batl":[[0,2.48,0.93]],"ltp":2.22,"tv":13.21,"id":60191231}]}]}
{"op":"mcm","clk":"11943376629","pt":1724437266753,"mc":[{"id":"1.232196998","rc":[{"batl":[[0,2.48,0.32]],"ltp":2.22,"tv":13.21,"id":60191231}]}]}
{"op":"mcm","clk":"11943378687","pt":1724437275728,"mc":[{"id":"1.232196998","rc":[{"batb":[[0,1.67,1.2],[1,1.66,35.16],[2,1.65,1.18]],"ltp":1.81,"tv":121.21,"id":72963954}]}]}
{"op":"mcm","clk":"11943437881","pt":1724437562707,"mc":[{"id":"1.232196998","rc":[{"batl":[[2,2.24,5.14]],"ltp":1.81,"tv":121.21,"id":72963954}]}]}
{"op":"mcm","clk":"11943451014","pt":1724437629803,"mc":[{"id":"1.232196998","rc":[{"batl":[[0,1.81,19.25]],"ltp":1.81,"tv":121.21,"id":72963954}]}]}
{"op":"mcm","clk":"11943516982","pt":1724437965126,"mc":[{"id":"1.232196998","rc":[{"trd":[[1.81,30.61]],"batl":[[0,1.81,19.08]],"ltp":1.81,"tv":121.56,"id":72963954}],"tv":134.77}]}
{"op":"mcm","clk":"11943735135","pt":1724438935700,"mc":[{"id":"1.232196998","rc":[{"trd":[[2.22,2.86]],"ltp":2.22,"tv":14.79,"id":60191231},{"trd":[[1.81,32.56]],"batl":[[0,1.81,17.13]],"ltp":1.81,"tv":123.51,"id":72963954}],"tv":138.31}]}
{"op":"mcm","clk":"11943943614","pt":1724440115261,"mc":[{"id":"1.232196998","rc":[{"trd":[[2.22,2.86],[2.44,1.41],[2.46,9.08]],"batb":[[1,1.81,35.19],[2,1.21,24.76]],"ltp":2.22,"tv":14.8,"id":60191231},{"trd":[[1.68,38.01],[1.71,3.64],[1.8,5.73],[1.81,32.66],[1.85,4.55],[1.88,6.3],[1.91,3.03],[1.93,4.55],[1.95,4.55],[1.97,6.3],[1.98,4.5],[1.99,4.54],[2,5.31]],"batb":[[1,1.66,35.19]],"batl":[[0,1.81,17.11],[1,1.99,36.07]],"ltp":1.81,"tv":123.65,"id":72963954}],"tv":138.46}]}
{"op":"mcm","clk":"11943944604","pt":1724440120373,"mc":[{"id":"1.232196998","rc":[{"trd":[[1.81,32.72]],"batl":[[0,1.81,17.08]],"ltp":1.81,"tv":123.72,"id":72963954}],"tv":138.52}]}
{"op":"mcm","clk":"11943945683","pt":1724440125468,"mc":[{"id":"1.232196998","rc":[{"trd":[[1.81,32.79]],"batl":[[0,1.81,17.04]],"ltp":1.81,"tv":123.78,"id":72963954}],"tv":138.59}]}
{"op":"mcm","clk":"11944045261","pt":1724440633026,"mc":[{"id":"1.232196998","rc":[{"batl":[[0,2.4,15.58]],"ltp":2.22,"tv":14.8,"id":60191231}]}]}
{"op":"mcm","clk":"11944074684","pt":1724440783127,"mc":[{"id":"1.232196998","rc":[{"trd":[[2.4,15.58]],"ltp":2.4,"tv":30.38,"id":60191231},{"trd":[[1.71,25.51]],"batl":[[0,1.71,850.5],[1,1.81,17.04],[2,1.99,36.07]],"ltp":1.71,"tv":145.65,"id":72963954}],"tv":176.04}]}
{"op":"mcm","clk":"11944101868","pt":1724440924571,"mc":[{"id":"1.232196998","rc":[{"batl":[[0,1.71,849.39]],"ltp":1.71,"tv":145.65,"id":72963954}]}]}
{"op":"mcm","clk":"11944115385","pt":1724440994055,"mc":[{"id":"1.232196998","rc":[{"batl":[[0,1.71,667.26]],"ltp":1.71,"tv":145.65,"id":72963954}]}]}
{"op":"mcm","clk":"11944168155","pt":1724441276765,"mc":[{"id":"1.232196998","rc":[{"trd":[[2.4,19.19]],"ltp":2.4,"tv":33.99,"id":60191231},{"trd":[[1.71,30.57]],"batl":[[0,1.71,662.2]],"ltp":1.71,"tv":150.71,"id":72963954}],"tv":184.71}]}
{"op":"mcm","clk":"11944218025","pt":1724441555728,"mc":[{"id":"1.232196998","rc":[{"trd":[[1.7,0.38]],"batb":[[0,1.67,1]],"ltp":1.7,"tv":151.1,"id":72963954}],"tv":185.09}]}
{"op":"mcm","clk":"11944250322","pt":1724441751714,"mc":[{"id":"1.232196998","rc":[{"batb":[[0,1.67,1.74]],"ltp":1.7,"tv":151.1,"id":72963954}]}]}
{"op":"mcm","clk":"11944279415","pt":1724441953241,"mc":[{"id":"1.232196998","rc":[{"batb":[[0,2.42,11.87],[1,1.94,1],[2,1.81,35.19]],"ltp":2.4,"tv":33.99,"id":60191231},{"trd":[[1.7,2.11]],"batb":[[0,1.66,36.07],[1,1.65,1.18],[2,1.63,113.16]],"batl":[[0,1.7,15.75],[1,1.71,662.2],[2,1.81,17.04]],"ltp":1.7,"tv":152.83,"id":72963954}],"tv":186.82}]}
{"op":"mcm","clk":"11944287116","pt":1724442010776,"mc":[{"id":"1.232196998","rc":[{"trd":[[1.7,2.82]],"batl":[[0,1.7,15.4]],"ltp":1.7,"tv":153.53,"id":72963954}],"tv":187.53}]}
{"op":"mcm","clk":"11944288074","pt":1724442017963,"mc":[{"id":"1.232196998","rc":[{"batb":[[0,1.66,35.47]],"ltp":1.7,"tv":153.53,"id":72963954}]}]}
{"op":"mcm","clk":"11944297378","pt":1724442087035,"mc":[{"id":"1.232196998","rc":[{"trd":[[2.4,47.93],[2.42,34.56]],"batb":[[0,1.94,1],[1,1.81,35.19],[2,1.21,24.76]],"ltp":2.4,"tv":97.29,"id":60191231},{"trd":[[1.7,18.22],[1.71,70.92]],"batl":[[0,1.71,621.85],[1,1.81,17.04],[2,1.99,36.07]],"ltp":1.71,"tv":209.28,"id":72963954}],"tv":306.58}]}
{"op":"mcm","clk":"11944297495","pt":1724442087824,"mc":[{"id":"1.232196998","rc":[{"batl":[[0,2.5,11.49]],"ltp":2.4,"tv":97.29,"id":60191231},{"batb":[[0,1.67,17.19],[1,1.66,35.19],[2,1.65,1.18]],"ltp":1.71,"tv":209.28,"id":72963954}]}]}
{"op":"mcm","clk":"11944303664","pt":1724442131670,"mc":[{"id":"1.232196998","rc":[{"trd":[[1.71,106.11]],"batl":[[0,1.71,604.25]],"ltp":1.71,"tv":244.47,"id":72963954}],"tv":341.77}]}
{"op":"mcm","clk":"11944305060","pt":1724442141690,"mc":[{"id":"1.232196998","rc":[{"trd":[[1.71,107.87]],"batl":[[0,1.71,603.37]],"ltp":1.71,"tv":246.23,"id":72963954}],"tv":343.53}]}
{"op":"mcm","clk":"11944315571","pt":1724442216688,"mc":[{"id":"1.232196998","rc":[{"trd":[[2.4,48.84]],"ltp":2.4,"tv":98.2,"id":60191231},{"trd":[[1.71,109.15]],"batl":[[0,1.71,602.09]],"ltp":1.71,"tv":247.51,"id":72963954}],"tv":345.72}]}
{"op":"mcm","clk":"11944319924","pt":1724442245719,"mc":[{"id":"1.232196998","rc":[{"trd":[[2.4,49.75]],"ltp":2.4,"tv":99.11,"id":60191231},{"trd":[[1.71,110.43]],"batl":[[0,1.71,600.81]],"ltp":1.71,"tv":248.79,"id":72963954}],"tv":347.91}]}
{"op":"mcm","clk":"11944524087","pt":1724443917745,"mc":[{"id":"1.232196998","rc":[{"trd":[[2.22,2.86],[2.44,1.41],[2.46,9.07]],"batb":[[1,1.81,35.17],[2,1.21,24.76]],"batl":[[0,2.5,11.49]],"ltp":2.4,"tv":99.11,"id":60191231},{"trd":[[1.68,37.99],[1.7,18.21],[1.71,120.97],[1.8,5.73],[1.81,32.76],[1.85,4.54],[1.88,6.3],[1.91,3.03],[1.93,4.54],[1.95,4.54],[1.97,6.3],[1.98,4.5],[1.99,4.54],[2,5.3]],"batb":[[0,1.67,17.18],[1,1.66,35.17]],"batl":[[0,1.71,595.53],[1,1.81,17.03],[2,1.99,36.04]],"ltp":1.71,"tv":259.26,"id":72963954}],"tv":358.37}]}
{"op":"mcm","clk":"11944609264","pt":1724444501905,"mc":[{"id":"1.232196998","rc":[{"batb":[[0,1.67,132.29]],"ltp":1.71,"tv":259.26,"id":72963954}]}]}
{"op":"mcm","clk":"11944612716","pt":1724444533662,"mc":[{"id":"1.232196998","rc":[{"batl":[[1,2.72,110.99]],"ltp":2.4,"tv":99.11,"id":60191231}]}]}
{"op":"mcm","clk":"11944614271","pt":1724444546694,"mc":[{"id":"1.232196998","rc":[{"trd":[[2.4,306.97]],"ltp":2.4,"tv":356.32,"id":60191231},{"trd":[[1.71,481.97]],"batl":[[0,1.71,234.53]],"ltp":1.71,"tv":620.26,"id":72963954}],"tv":976.59}]}
{"op":"mcm","clk":"11944622603","pt":1724444619742,"mc":[{"id":"1.232196998","rc":[{"batl":[[1,2.72,0]],"ltp":2.4,"tv":356.32,"id":60191231}]}]}
{"op":"mcm","clk":"11944626552","pt":1724444658170,"mc":[{"id":"1.232196998","rc":[{"trd":[[1.67,251.02]],"batb":[[0,1.67,6.78]],"ltp":1.67,"tv":871.28,"id":72963954}],"tv":1227.61}]}
{"op":"mcm","clk":"11944627258","pt":1724444663789,"mc":[{"id":"1.232196998","rc":[{"trd":[[1.67,264.58]],"batb":[[0,1.66,35.17],[1,1.65,1.18],[2,1.63,113.17]],"batl":[[0,1.67,5.78],[1,1.71,234.53],[2,1.81,17.03]],"ltp":1.67,"tv":884.84,"id":72963954}],"tv":1241.17}]}
{"op":"mcm","clk":"11944628294","pt":1724444673288,"mc":[{"id":"1.232196998","rc":[{"batl":[[0,1.71,234.53],[1,1.81,17.03],[2,1.99,36.04]],"ltp":1.67,"tv":884.84,"id":72963954}]}]}
{"op":"mcm","clk":"11944639465","pt":1724444775697,"mc":[{"id":"1.232196998","rc":[{"batl":[[0,1.7,11.51],[1,1.71,234.53],[2,1.81,17.03]],"ltp":1.67,"tv":884.84,"id":72963954}]}]}
{"op":"mcm","clk":"11944652520","pt":1724444892693,"mc":[{"id":"1.232196998","rc":[{"trd":[[1.7,41.23]],"batb":[[0,1.7,51.25],[1,1.66,35.17],[2,1.65,1.18]],"batl":[[0,1.71,234.53],[1,1.81,17.03],[2,1.99,36.04]],"ltp":1.7,"tv":907.86,"id":72963954}],"tv":1264.19}]}
{"op":"mcm","clk":"11944652904","pt":1724444896494,"mc":[{"id":"1.232196998","rc":[{"batl":[[0,2.42,11.87]],"ltp":2.4,"tv":356.32,"id":60191231},{"batb":[[0,1.7,62.76]],"ltp":1.7,"tv":907.86,"id":72963954}]}]}
{"op":"mcm","clk":"11944665694","pt":1724445020504,"mc":[{"id":"1.232196998","rc":[{"batb":[[0,1.7,61.09]],"ltp":1.7,"tv":907.86,"id":72963954}]}]}
{"op":"mcm","clk":"11944671029","pt":1724445075368,"mc":[{"id":"1.232196998","rc":[{"trd":[[2.4,308.64]],"ltp":2.4,"tv":357.99,"id":60191231},{"trd":[[1.71,484.31]],"batl":[[0,1.71,232.19]],"ltp":1.71,"tv":910.2,"id":72963954}],"tv":1268.2}]}
{"op":"mcm","clk":"11944678871","pt":1724445159166,"mc":[{"id":"1.232196998","rc":[{"trd":[[2.42,58.3]],"batb":[[0,2.42,4.89],[1,1.94,1],[2,1.81,35.17]],"ltp":2.42,"tv":381.73,"id":60191231}],"tv":1291.94}]}
{"op":"mcm","clk":"11944680191","pt":1724445173500,"mc":[{"id":"1.232196998","rc":[{"batb":[[0,2.42,1.54]],"ltp":2.42,"tv":381.73,"id":60191231}]}]}
{"op":"mcm","clk":"11944697052","pt":1724445374085,"mc":[{"id":"1.232196998","rc":[{"trd":[[1.7,41.39]],"batb":[[0,1.7,61.01]],"ltp":1.7,"tv":910.36,"id":72963954}],"tv":1292.1}]}
{"op":"mcm","clk":"11944738157","pt":1724445871133,"mc":[{"id":"1.232196998","rc":[{"trd":[[1.7,156.51]],"batb":[[0,1.7,3.46]],"ltp":1.7,"tv":1025.48,"id":72963954}],"tv":1407.21}]}
{"op":"mcm","clk":"11944738284","pt":1724445872929,"mc":[{"id":"1.232196998","rc":[{"batb":[[0,1.67,3.52]],"ltp":1.7,"tv":1025.48,"id":72963954}]}]}
{"op":"mcm","clk":"11944740230","pt":1724445897262,"mc":[{"id":"1.232196998","rc":[{"batl":[[0,1.7,57.56],[1,1.71,232.19],[2,1.81,17.03]],"ltp":1.7,"tv":1025.48,"id":72963954}]}]}
{"op":"mcm","clk":"11944764774","pt":1724446222217,"mc":[{"id":"1.232196998","rc":[{"batl":[[0,1.69,4.32],[1,1.7,57.56],[2,1.71,232.19]],"ltp":1.7,"tv":1025.48,"id":72963954}]}]}
{"op":"mcm","clk":"11944767621","pt":1724446258186,"mc":[{"id":"1.232196998","rc":[{"trd":[[1.69,8.64]],"batb":[[0,1.69,2.79],[1,1.67,7.89],[2,1.66,35.17]],"batl":[[0,1.7,57.56],[1,1.71,232.19],[2,1.81,17.03]],"ltp":1.69,"tv":1034.12,"id":72963954}],"tv":1415.85}]}
{"op":"mcm","clk":"11944769390","pt":1724446281165,"mc":[{"id":"1.232196998","rc":[{"batb":[[2,1.81,784.54]],"ltp":2.42,"tv":381.73,"id":60191231}]}]}
{"op":"mcm","clk":"11944770123","pt":1724446290589,"mc":[{"id":"1.232196998","rc":[{"batb":[[2,1.81,716.42]],"ltp":2.42,"tv":381.73,"id":60191231}]}]}
{"op":"mcm","clk":"11944803816","pt":1724446716060,"mc":[{"id":"1.232196998","rc":[{"batb":[[0,1.67,7.89],[1,1.66,35.17],[2,1.65,1.18]],"batl":[[0,1.69,13.97],[1,1.7,57.56],[2,1.71,232.19]],"ltp":1.69,"tv":1034.12,"id":72963954}]}]}
{"op":"mcm","clk":"11944816205","pt":1724446866667,"mc":[{"id":"1.232196998","rc":[{"trd":[[2.22,2.86],[2.4,308.6],[2.42,58.29],[2.46,9.07]],"batb":[[2,1.81,716.13]],"ltp":2.42,"tv":381.68,"id":60191231},{"trd":[[1.67,264.58],[1.68,37.99],[1.69,12.08],[1.7,156.5],[1.71,484.33],[1.8,5.73],[1.81,32.79],[1.88,6.3],[1.97,6.3],[1.98,4.5],[1.99,4.54]],"batb":[[0,1.67,7.89],[1,1.66,35.19]],"batl":[[0,1.69,12.25]],"ltp":1.69,"tv":1037.59,"id":72963954}],"tv":1419.27}]}
{"op":"mcm","clk":"11944816893","pt":1724446874350,"mc":[{"id":"1.232196998","rc":[{"batl":[[1,1.71,232.19],[2,1.81,17.04]],"ltp":1.69,"tv":1037.59,"id":72963954}]}]}
{"op":"mcm","clk":"11944825447","pt":1724446980742,"mc":[{"id":"1.232196998","rc":[{"trd":[[1.69,34.08]],"batl":[[0,1.69,1.25]],"ltp":1.69,"tv":1059.58,"id":72963954}],"tv":1441.27}]}
{"op":"mcm","clk":"11944825865","pt":1724446985661,"mc":[{"id":"1.232196998","rc":[{"trd":[[1.69,36.58]],"batb":[[0,1.69,3.15],[1,1.67,7.89],[2,1.66,35.19]],"batl":[[0,1.71,232.19],[1,1.81,17.04],[2,1.99,36.07]],"ltp":1.69,"tv":1062.08,"id":72963954}],"tv":1443.77}]}
{"op":"mcm","clk":"11944829070","pt":1724447023840,"mc":[{"id":"1.232196998","rc":[{"batb":[[0,1.67,7.89],[1,1.66,35.19],[2,1.65,1.18]],"ltp":1.69,"tv":1062.08,"id":72963954}]}]}
{"op":"mcm","clk":"11944829644","pt":1724447030717,"mc":[{"id":"1.232196998","rc":[{"trd":[[1.71,490.63]],"batl":[[0,1.71,229.04]],"ltp":1.71,"tv":1068.38,"id":72963954}],"tv":1450.07}]}
{"op":"mcm","clk":"11944830823","pt":1724447046346,"mc":[{"id":"1.232196998","rc":[{"batb":[[0,1.68,1.72],[1,1.67,7.89],[2,1.66,35.19]],"ltp":1.71,"tv":1068.38,"id":72963954}]}]}
{"op":"mcm","clk":"11944835804","pt":1724447114676,"mc":[{"id":"1.232196998","rc":[{"trd":[[1.71,491.87]],"batl":[[0,1.71,228.42]],"ltp":1.71,"tv":1069.62,"id":72963954}],"tv":1451.3}]}
{"op":"mcm","clk":"11944848968","pt":1724447282840,"mc":[{"id":"1.232196998","rc":[{"batb":[[0,2.42,13.64]],"ltp":2.42,"tv":381.68,"id":60191231}]}]}
{"op":"mcm","clk":"11944849776","pt":1724447293673,"mc":[{"id":"1.232196998","rc":[{"trd":[[2.42,82.49]],"batb":[[0,1.94,1],[1,1.81,716.13],[2,1.21,24.75]],"batl":[[0,2.42,3.12]],"ltp":2.42,"tv":405.88,"id":60191231}],"tv":1475.5}]}
{"op":"mcm","clk":"11944849974","pt":1724447295578,"mc":[{"id":"1.232196998","rc":[{"batl":[[1,2.5,11.71]],"ltp":2.42,"tv":405.88,"id":60191231}]}]}
{"op":"mcm","clk":"11944894483","pt":1724447889120,"mc":[{"id":"1.232196998","rc":[{"trd":[[2.42,85.61]],"batl":[[0,2.5,11.71],[1,2.5,0]],"ltp":2.42,"tv":409.0,"id":60191231},{"trd":[[1.7,160.94]],"batl":[[0,1.7,7.31],[1,1.71,228.42],[2,1.81,17.04]],"ltp":1.7,"tv":1074.06,"id":72963954}],"tv":1483.07}]}
{"op":"mcm","clk":"11944897057","pt":1724447923410,"mc":[{"id":"1.232196998","rc":[{"batl":[[0,1.71,228.42],[1,1.81,17.04],[2,1.99,36.07]],"ltp":1.7,"tv":1074.06,"id":72963954}]}]}
{"op":"mcm","clk":"11944897828","pt":1724447932931,"mc":[{"id":"1.232196998","rc":[{"trd":[[1.68,41.42]],"batb":[[0,1.67,7.89],[1,1.66,35.19],[2,1.65,1.18]],"batl":[[0,1.68,5.59],[1,1.71,228.42],[2,1.81,17.04]],"ltp":1.68,"tv":1077.5,"id":72963954}],"tv":1486.5}]}
{"op":"mcm","clk":"11944899176","pt":1724447951071,"mc":[{"id":"1.232196998","rc":[{"batl":[[0,1.71,228.42],[1,1.81,17.04],[2,1.99,36.07]],"ltp":1.68,"tv":1077.5,"id":72963954}]}]}
{"op":"mcm","clk":"11944900020","pt":1724447960864,"mc":[{"id":"1.232196998","rc":[{"trd":[[1.67,275.76]],"batb":[[0,1.67,2.3]],"ltp":1.67,"tv":1088.68,"id":72963954}],"tv":1497.68}]}
{"op":"mcm","clk":"11944921880","pt":1724448204752,"mc":[{"id":"1.232196998","rc":[{"trd":[[1.71,495.39]],"batl":[[0,1.71,226.66]],"ltp":1.71,"tv":1092.2,"id":72963954}],"tv":1501.2}]}
{"op":"mcm","clk":"11944926217","pt":1724448258684,"mc":[{"id":"1.232196998","rc":[{"trd":[[1.71,502.43]],"batl":[[0,1.71,223.14]],"ltp":1.71,"tv":1099.24,"id":72963954}],"tv":1508.24}]}
{"op":"mcm","clk":"11944927383","pt":1724448273697,"mc":[{"id":"1.232196998","rc":[{"trd":[[1.71,520.03]],"batl":[[0,1.71,214.34]],"ltp":1.71,"tv":1116.84,"id":72963954}],"tv":1525.84}]}
{"op":"mcm","clk":"11944930604","pt":1724448311726,"mc":[{"id":"1.232196998","rc":[{"trd":[[1.71,521.09]],"batl":[[0,1.71,213.81]],"ltp":1.71,"tv":1117.89,"id":72963954}],"tv":1526.9}]}
{"op":"mcm","clk":"11945003348","pt":1724449250631,"mc":[{"id":"1.232196998","rc":[{"trd":[[1.71,669.19]],"batl":[[0,1.71,139.76]],"ltp":1.71,"tv":1266.0,"id":72963954}],"tv":1675.0}]}
{"op":"mcm","clk":"11945030880","pt":1724449389254,"mc":[{"id":"1.232196998","rc":[{"trd":[[1.67,280.36]],"batb":[[0,1.66,35.19],[1,1.65,1.18],[2,1.63,113.16]],"batl":[[0,1.67,27.7],[1,1.71,139.76],[2,1.81,17.04]],"ltp":1.67,"tv":1270.6,"id":72963954}],"tv":1679.6}]}
{"op":"mcm","clk":"11945030946","pt":1724449390049,"mc":[{"id":"1.232196998","rc":[{"trd":[[1.67,335.76]],"batl":[[0,1.7,10.49]],"ltp":1.67,"tv":1326.0,"id":72963954}],"tv":1735.0}]}
{"op":"mcm","clk":"11945037088","pt":1724449493742,"mc":[{"id":"1.232196998","rc":[{"trd":[[1.7,181.92]],"batb":[[0,1.7,26.53],[1,1.66,35.19],[2,1.65,1.18]],"batl":[[0,1.71,139.76],[1,1.81,17.04],[2,1.99,36.07]],"ltp":1.7,"tv":1346.98,"id":72963954}],"tv":1755.99}]}
{"op":"mcm","clk":"11945037153","pt":1724449494821,"mc":[{"id":"1.232196998","rc":[{"batl":[[0,2.42,12.1]],"ltp":2.42,"tv":409.0,"id":60191231},{"batb":[[0,1.7,37.03]],"ltp":1.7,"tv":1346.98,"id":72963954}]}]}
{"op":"mcm","clk":"11945037556","pt":1724449501947,"mc":[{"id":"1.232196998","rc":[{"trd":[[1.71,722.25]],"batb":[[0,1.7,10.49]],"batl":[[0,1.71,113.23]],"ltp":1.71,"tv":1400.05,"id":72963954}],"tv":1809.05}]}
{"op":"mcm","clk":"11945037669","pt":1724449503852,"mc":[{"id":"1.232196998","rc":[{"batl":[[0,2.5,11.71]],"ltp":2.42,"tv":409.0,"id":60191231}]}]}
{"op":"mcm","clk":"11945037780","pt":1724449505745,"mc":[{"id":"1.232196998","rc":[{"batb":[[0,1.67,10.68]],"ltp":1.71,"tv":1400.05,"id":72963954}]}]}
{"op":"mcm","clk":"11945040419","pt":1724449549708,"mc":[{"id":"1.232196998","rc":[{"trd":[[1.71,746.93]],"batl":[[0,1.71,100.89]],"ltp":1.71,"tv":1424.73,"id":72963954}],"tv":1833.73}]}
{"op":"mcm","clk":"11945047070","pt":1724449653977,"mc":[{"id":"1.232196998","rc":[{"batb":[[0,1.67,45.87],[1,1.65,1.18],[2,1.63,113.16]],"ltp":1.71,"tv":1424.73,"id":72963954}]}]}
{"op":"mcm","clk":"11945054888","pt":1724449776114,"mc":[{"id":"1.232196998","rc":[{"batb":[[2,1.6,15.13]],"ltp":1.71,"tv":1424.73,"id":72963954}]}]}
{"op":"mcm","clk":"11945078962","pt":1724450143290,"mc":[{"id":"1.232196998","rc":[{"trd":[[2.4,380.09]],"ltp":2.4,"tv":480.5,"id":60191231},{"trd":[[1.71,847.27]],"batl":[[0,1.81,17.59],[1,1.99,36.07],[2,2.08,5.14]],"ltp":1.71,"tv":1525.07,"id":72963954}],"tv":2005.57}]}
{"op":"mcm","clk":"11945078971","pt":1724450143390,"mc":[{"id":"1.232196998","rc":[{"trd":[[1.71,848.37]],"batl":[[0,1.81,17.04]],"ltp":1.71,"tv":1526.17,"id":72963954}],"tv":2006.67}]}
{"op":"mcm","clk":"11945085356","pt":1724450235809,"mc":[{"id":"1.232196998","rc":[{"batb":[[0,1.68,35.19],[1,1.67,10.68],[2,1.65,1.18]],"ltp":1.71,"tv":1526.17,"id":72963954}]}]}
{"op":"mcm","clk":"11945085477","pt":1724450237397,"mc":[{"id":"1.232196998","rc":[{"batl":[[0,2.46,11.91]],"ltp":2.4,"tv":480.5,"id":60191231},{"batb":[[0,1.69,10.55],[1,1.68,35.19]],"ltp":1.71,"tv":1526.17,"id":72963954}]}]}
{"op":"mcm","clk":"11945097070","pt":1724450401790,"mc":[{"id":"1.232196998","rc":[{"batb":[[0,2.02,5],[1,2,17.78],[2,1.94,1]],"ltp":2.4,"tv":480.5,"id":60191231},{"batb":[[1,1.68,61.34]],"ltp":1.71,"tv":1526.17,"id":72963954}]}]}
{"op":"mcm","clk":"11945097269","pt":1724450403655,"mc":[{"id":"1.232196998","rc":[{"trd":[[2.22,2.86],[2.4,379.96],[2.42,85.65]],"batb":[[0,2.02,22.46],[1,2,17.81]],"batl":[[0,2.46,11.92]],"ltp":2.4,"tv":480.41,"id":60191231},{"trd":[[1.67,335.8],[1.68,41.43],[1.69,36.57],[1.7,181.98],[1.71,848.23],[1.8,5.73],[1.81,32.76],[1.85,4.54],[1.88,6.3],[1.93,4.54],[1.95,4.54],[1.97,6.3]],"batb":[[0,1.69,10.57],[1,1.68,61.35]],"batl":[[0,1.81,17.03],[1,1.99,36.04],[2,2.08,5.14]],"ltp":1.71,"tv":1526.09,"id":72963954}],"tv":2006.5}]}
{"op":"mcm","clk":"11945097403","pt":1724450405091,"mc":[{"id":"1.232196998","rc":[{"batb":[[0,2.02,17.46]],"ltp":2.4,"tv":480.41,"id":60191231}]}]}
{"op":"mcm","clk":"11945097461","pt":1724450405760,"mc":[{"id":"1.232196998","rc":[{"batb":[[0,2,17.81],[1,1.94,1],[2,1.81,716.36]],"ltp":2.4,"tv":480.41,"id":60191231}]}]}
{"op":"mcm","clk":"11945099873","pt":1724450436294,"mc":[{"id":"1.232196998","rc":[{"batb":[[0,1.69,16.49]],"ltp":1.71,"tv":1526.09,"id":72963954}]}]}
{"op":"mcm","clk":"11945099881","pt":1724450436395,"mc":[{"id":"1.232196998","rc":[{"batb":[[0,2.02,5],[1,2,17.81],[2,1.94,1]],"ltp":2.4,"tv":480.41,"id":60191231}]}]}
{"op":"mcm","clk":"11945100063","pt":1724450438727,"mc":[{"id":"1.232196998","rc":[{"batb":[[0,2.02,22.46]],"ltp":2.4,"tv":480.41,"id":60191231}]}]}
{"op":"mcm","clk":"11945100198","pt":1724450440218,"mc":[{"id":"1.232196998","rc":[{"batb":[[0,2,17.81],[1,1.94,1],[2,1.81,716.36]],"ltp":2.4,"tv":480.41,"id":60191231}]}]}
{"op":"mcm","clk":"11945105516","pt":1724450515616,"mc":[{"id":"1.232196998","rc":[{"batb":[[0,2.02,5],[1,2,17.81],[2,1.94,1]],"ltp":2.4,"tv":480.41,"id":60191231},{"batb":[[0,1.69,17.33]],"ltp":1.71,"tv":1526.09,"id":72963954}]}]}
{"op":"mcm","clk":"11945105675","pt":1724450517718,"mc":[{"id":"1.232196998","rc":[{"batb":[[0,2.02,22.46]],"ltp":2.4,"tv":480.41,"id":60191231}]}]}
{"op":"mcm","clk":"11945105743","pt":1724450518941,"mc":[{"id":"1.232196998","rc":[{"batb":[[0,2.02,17.46]],"ltp":2.4,"tv":480.41,"id":60191231}]}]}
{"op":"mcm","clk":"11945105768","pt":1724450519352,"mc":[{"id":"1.232196998","rc":[{"batb":[[0,2,17.81],[1,1.94,1],[2,1.81,716.36]],"ltp":2.4,"tv":480.41,"id":60191231}]}]}
{"op":"mcm","clk":"11945113681","pt":1724450638067,"mc":[{"id":"1.232196998","rc":[{"batb":[[0,2.02,5],[1,2,17.81],[2,1.94,1]],"ltp":2.4,"tv":480.41,"id":60191231},{"batl":[[0,1.8,227.07],[1,1.81,17.03],[2,1.99,36.04]],"ltp":1.71,"tv":1526.09,"id":72963954}]}]}
{"op":"mcm","clk":"11945113796","pt":1724450639858,"mc":[{"id":"1.232196998","rc":[{"batb":[[0,2.22,14.6],[1,2.02,5],[2,2,17.81]],"ltp":2.4,"tv":480.41,"id":60191231}]}]}
{"op":"mcm","clk":"11945113905","pt":1724450641342,"mc":[{"id":"1.232196998","rc":[{"batb":[[1,2,17.81],[2,1.94,1]],"ltp":2.4,"tv":480.41,"id":60191231}]}]}
{"op":"mcm","clk":"11945114265","pt":1724450647153,"mc":[{"id":"1.232196998","rc":[{"batb":[[0,2.24,5],[1,2.22,14.6],[2,2,17.81]],"ltp":2.4,"tv":480.41,"id":60191231},{"batb":[[0,1.69,16.49]],"ltp":1.71,"tv":1526.09,"id":72963954}]}]}
{"op":"mcm","clk":"11945114464","pt":1724450650480,"mc":[{"id":"1.232196998","rc":[{"batb":[[0,2.22,14.6],[1,2,17.81],[2,1.94,1]],"ltp":2.4,"tv":480.41,"id":60191231}]}]}
{"op":"mcm","clk":"11945119553","pt":1724450721950,"mc":[{"id":"1.232196998","rc":[{"batb":[[0,2.24,5],[1,2.22,14.6],[2,2,17.81]],"ltp":2.4,"tv":480.41,"id":60191231},{"batb":[[0,1.69,51.65],[1,1.68,26.19]],"ltp":1.71,"tv":1526.09,"id":72963954}]}]}
{"op":"mcm","clk":"11945119785","pt":1724450725228,"mc":[{"id":"1.232196998","rc":[{"batb":[[0,2.22,14.6],[1,2,17.81],[2,1.94,1]],"ltp":2.4,"tv":480.41,"id":60191231}]}]}
{"op":"mcm","clk":"11945144427","pt":1724451085402,"mc":[{"id":"1.232196998","rc":[{"batb":[[0,2.24,5],[1,2.22,14.6],[2,2,17.81]],"ltp":2.4,"tv":480.41,"id":60191231},{"batb":[[2,1.65,55.68]],"ltp":1.71,"tv":1526.09,"id":72963954}]}]}
{"op":"mcm","clk":"11945144676","pt":1724451088765,"mc":[{"id":"1.232196998","rc":[{"batb":[[0,2.22,14.6],[1,2,17.81],[2,1.94,1]],"ltp":2.4,"tv":480.41,"id":60191231}]}]}
{"op":"mcm","clk":"11945174775","pt":1724451534823,"mc":[{"id":"1.232196998","rc":[{"batb":[[0,2.24,5],[1,2.22,14.6],[2,2,17.81]],"ltp":2.4,"tv":480.41,"id":60191231},{"batb":[[0,1.7,140.92],[1,1.69,51.65],[2,1.68,26.19]],"ltp":1.71,"tv":1526.09,"id":72963954}]}]}
{"op":"mcm","clk":"11945174862","pt":1724451536104,"mc":[{"id":"1.232196998","rc":[{"batb":[[1,1.69,60.97]],"ltp":1.71,"tv":1526.09,"id":72963954}]}]}
{"op":"mcm","clk":"11945174874","pt":1724451536309,"mc":[{"id":"1.232196998","rc":[{"batl":[[0,2.42,12.12]],"ltp":2.4,"tv":480.41,"id":60191231},{"batb":[[0,1.71,10.45],[1,1.7,140.92],[2,1.69,60.97]],"ltp":1.71,"tv":1526.09,"id":72963954}]}]}
{"op":"mcm","clk":"11945174998","pt":1724451538150,"mc":[{"id":"1.232196998","rc":[{"batb":[[0,2.22,14.6],[1,2,17.81],[2,1.94,1]],"ltp":2.4,"tv":480.41,"id":60191231},{"batb":[[1,1.7,166.37]],"ltp":1.71,"tv":1526.09,"id":72963954}]}]}
{"op":"mcm","clk":"11945175146","pt":1724451540822,"mc":[{"id":"1.232196998","rc":[{"batb":[[0,2.24,5],[1,2.22,14.6],[2,2.04,94.85]],"ltp":2.4,"tv":480.41,"id":60191231}]}]}
{"op":"mcm","clk":"11945175365","pt":1724451544215,"mc":[{"id":"1.232196998","rc":[{"batb":[[0,2.22,14.6],[1,2.04,94.85],[2,2,17.81]],"ltp":2.4,"tv":480.41,"id":60191231}]}]}
{"op":"mcm","clk":"11945176741","pt":1724451566273,"mc":[{"id":"1.232196998","rc":[{"batb":[[0,1.71,24.24]],"ltp":1.71,"tv":1526.09,"id":72963954}]}]}
{"op":"mcm","clk":"11945176747","pt":1724451566373,"mc":[{"id":"1.232196998","rc":[{"batb":[[0,2.24,5],[1,2.22,14.6],[2,2.04,94.85]],"ltp":2.4,"tv":480.41,"id":60191231}]}]}
{"op":"mcm","clk":"11945176945","pt":1724451569650,"mc":[{"id":"1.232196998","rc":[{"batb":[[0,2.22,14.6],[1,2.04,94.85],[2,2,17.81]],"ltp":2.4,"tv":480.41,"id":60191231}]}]}
{"op":"mcm","clk":"11945180568","pt":1724451634224,"mc":[{"id":"1.232196998","rc":[{"batl":[[0,1.79,93.6],[1,1.8,227.07],[2,1.81,17.03]],"ltp":1.71,"tv":1526.09,"id":72963954}]}]}
{"op":"mcm","clk":"11945180573","pt":1724451634325,"mc":[{"id":"1.232196998","rc":[{"batb":[[0,2.24,5],[1,2.22,14.6],[2,2.04,94.85]],"ltp":2.4,"tv":480.41,"id":60191231}]}]}
{"op":"mcm","clk":"11945180625","pt":1724451635445,"mc":[{"id":"1.232196998","rc":[{"batb":[[0,2.24,19.37]],"ltp":2.4,"tv":480.41,"id":60191231}]}]}
{"op":"mcm","clk":"11945180729","pt":1724451637539,"mc":[{"id":"1.232196998","rc":[{"batb":[[0,2.24,14.37]],"ltp":2.4,"tv":480.41,"id":60191231}]}]}
{"op":"mcm","clk":"11945180949","pt":1724451641424,"mc":[{"id":"1.232196998","rc":[{"batb":[[0,2.26,5],[1,2.24,14.37],[2,2.22,14.6]],"ltp":2.4,"tv":480.41,"id":60191231},{"trd":[[1.79,151.38]],"batl":[[0,1.79,17.91]],"ltp":1.79,"tv":1677.47,"id":72963954}],"tv":2157.88}]}
{"op":"mcm","clk":"11945181157","pt":1724451644748,"mc":[{"id":"1.232196998","rc":[{"batb":[[0,2.24,14.37],[1,2.22,14.6],[2,2.04,94.85]],"ltp":2.4,"tv":480.41,"id":60191231}]}]}
{"op":"mcm","clk":"11945181807","pt":1724451656587,"mc":[{"id":"1.232196998","rc":[{"batb":[[0,2.26,5],[1,2.24,14.37],[2,2.22,14.6]],"ltp":2.4,"tv":480.41,"id":60191231},{"trd":[[1.79,187.2]],"batl":[[0,1.8,222.27],[1,1.81,17.03],[2,1.99,36.04]],"ltp":1.79,"tv":1713.29,"id":72963954}],"tv":2193.7}]}
{"op":"mcm","clk":"11945181993","pt":1724451659762,"mc":[{"id":"1.232196998","rc":[{"batb":[[0,2.24,14.37],[1,2.22,14.6],[2,2.04,94.85]],"ltp":2.4,"tv":480.41,"id":60191231}]}]}
{"op":"mcm","clk":"11945182931","pt":1724451675772,"mc":[{"id":"1.232196998","rc":[{"batb":[[0,2.26,5],[1,2.24,14.37],[2,2.22,14.6]],"ltp":2.4,"tv":480.41,"id":60191231}]}]}
{"op":"mcm","clk":"11945183140","pt":1724451679209,"mc":[{"id":"1.232196998","rc":[{"batb":[[0,2.24,14.37],[1,2.22,14.6],[2,2.04,94.85]],"ltp":2.4,"tv":480.41,"id":60191231}]}]}
{"op":"mcm","clk":"11945183293","pt":1724451682081,"mc":[{"id":"1.232196998","rc":[{"batb":[[0,2.26,5],[1,2.24,14.37],[2,2.22,14.6]],"ltp":2.4,"tv":480.41,"id":60191231}]}]}
{"op":"mcm","clk":"11945183465","pt":1724451685724,"mc":[{"id":"1.232196998","rc":[{"batb":[[0,2.24,14.37],[1,2.22,14.6],[2,2.04,94.85]],"ltp":2.4,"tv":480.41,"id":60191231}]}]}
{"op":"mcm","clk":"11945203628","pt":1724452012530,"mc":[{"id":"1.232196998","rc":[{"trd":[[2.24,47.37]],"batb":[[0,2.24,5]],"ltp":2.24,"tv":527.78,"id":60191231},{"trd":[[1.8,28.92]],"batl":[[0,1.8,199.08]],"ltp":1.8,"tv":1736.48,"id":72963954}],"tv":2264.26}]}
{"op":"mcm","clk":"11945203848","pt":1724452015851,"mc":[{"id":"1.232196998","rc":[{"batb":[[0,2.22,14.6],[1,2.04,94.85],[2,2,17.81]],"ltp":2.24,"tv":527.78,"id":60191231}]}]}
{"op":"mcm","clk":"11945204832","pt":1724452030847,"mc":[{"id":"1.232196998","rc":[{"batb":[[0,2.24,5],[1,2.22,14.6],[2,2.04,94.85]],"ltp":2.24,"tv":527.78,"id":60191231},{"trd":[[1.71,851.57]],"batb":[[0,1.71,22.57]],"ltp":1.71,"tv":1739.82,"id":72963954}],"tv":2267.6}]}
{"op":"mcm","clk":"11945204876","pt":1724452031563,"mc":[{"id":"1.232196998","rc":[{"batl":[[0,2.42,20.82]],"ltp":2.24,"tv":527.78,"id":60191231}]}]}
{"op":"mcm","clk":"11945205072","pt":1724452034168,"mc":[{"id":"1.232196998","rc":[{"batb":[[0,2.22,14.6],[1,2.04,94.85],[2,2,17.81]],"ltp":2.24,"tv":527.78,"id":60191231}]}]}
{"op":"mcm","clk":"11945206854","pt":1724452061194,"mc":[{"id":"1.232196998","rc":[{"batl":[[0,1.79,7.57],[1,1.8,199.08],[2,1.81,17.03]],"ltp":1.71,"tv":1739.82,"id":72963954}]}]}
{"op":"mcm","clk":"11945206889","pt":1724452061708,"mc":[{"id":"1.232196998","rc":[{"batb":[[0,2.24,19.37],[1,2.22,14.6],[2,2.04,94.85]],"ltp":2.24,"tv":527.78,"id":60191231}]}]}
{"op":"mcm","clk":"11945207085","pt":1724452064576,"mc":[{"id":"1.232196998","rc":[{"batb":[[0,2.24,14.37]],"ltp":2.24,"tv":527.78,"id":60191231}]}]}
{"op":"mcm","clk":"11945207388","pt":1724452069698,"mc":[{"id":"1.232196998","rc":[{"batb":[[0,2.26,5],[1,2.24,14.37],[2,2.22,14.6]],"ltp":2.24,"tv":527.78,"id":60191231},{"batl":[[0,1.78,7.57],[1,1.79,7.57],[2,1.8,199.08]],"ltp":1.71,"tv":1739.82,"id":72963954}]}]}
{"op":"mcm","clk":"11945207599","pt":1724452072918,"mc":[{"id":"1.232196998","rc":[{"batb":[[0,2.26,14.14]],"ltp":2.24,"tv":527.78,"id":60191231}]}]}
{"op":"mcm","clk":"11945207632","pt":1724452073328,"mc":[{"id":"1.232196998","rc":[{"batb":[[0,2.24,14.37],[1,2.22,14.6],[2,2.04,94.85]],"ltp":2.24,"tv":527.78,"id":60191231}]}]}
{"op":"mcm","clk":"11945208061","pt":1724452079739,"mc":[{"id":"1.232196998","rc":[{"batb":[[0,2.26,5],[1,2.24,14.37],[2,2.22,14.6]],"ltp":2.24,"tv":527.78,"id":60191231},{"batl":[[0,1.77,7.57],[1,1.78,7.57],[2,1.79,7.57]],"ltp":1.71,"tv":1739.82,"id":72963954}]}]}
{"op":"mcm","clk":"11945208180","pt":1724452081734,"mc":[{"id":"1.232196998","rc":[{"batb":[[0,2.26,19.14]],"ltp":2.24,"tv":527.78,"id":60191231}]}]}
{"op":"mcm","clk":"11945208271","pt":1724452083023,"mc":[{"id":"1.232196998","rc":[{"batb":[[0,2.26,14.14]],"ltp":2.24,"tv":527.78,"id":60191231}]}]}
{"op":"mcm","clk":"11945208369","pt":1724452084506,"mc":[{"id":"1.232196998","rc":[{"batl":[[0,1.76,7.57],[1,1.77,7.57],[2,1.78,7.57]],"ltp":1.71,"tv":1739.82,"id":72963954}]}]}
{"op":"mcm","clk":"11945208462","pt":1724452086242,"mc":[{"id":"1.232196998","rc":[{"batb":[[2,2.04,94.85]],"ltp":2.24,"tv":527.78,"id":60191231}]}]}
{"op":"mcm","clk":"11945208491","pt":1724452086705,"mc":[{"id":"1.232196998","rc":[{"batb":[[0,2.28,18.92],[1,2.26,14.14],[2,2.24,14.37]],"ltp":2.24,"tv":527.78,"id":60191231}]}]}
{"op":"mcm","clk":"11945208686","pt":1724452089628,"mc":[{"id":"1.232196998","rc":[{"batb":[[0,2.28,13.92]],"ltp":2.24,"tv":527.78,"id":60191231}]}]}
{"op":"mcm","clk":"11945209808","pt":1724452106639,"mc":[{"id":"1.232196998","rc":[{"batb":[[0,2.3,5],[1,2.28,13.92],[2,2.26,14.14]],"ltp":2.24,"tv":527.78,"id":60191231},{"batl":[[0,1.75,7.57],[1,1.76,7.57],[2,1.77,7.57]],"ltp":1.71,"tv":1739.82,"id":72963954}]}]}
{"op":"mcm","clk":"11945209991","pt":1724452109869,"mc":[{"id":"1.232196998","rc":[{"batb":[[0,2.3,13.7]],"ltp":2.24,"tv":527.78,"id":60191231}]}]}
{"op":"mcm","clk":"11945210018","pt":1724452110329,"mc":[{"id":"1.232196998","rc":[{"batb":[[0,2.28,13.92],[1,2.26,14.14],[2,2.04,94.85]],"ltp":2.24,"tv":527.78,"id":60191231}]}]}
{"op":"mcm","clk":"11945210085","pt":1724452111355,"mc":[{"id":"1.232196998","rc":[{"batl":[[0,1.74,7.57],[1,1.75,7.57],[2,1.76,7.57]],"ltp":1.71,"tv":1739.82,"id":72963954}]}]}
{"op":"mcm","clk":"11945210242","pt":1724452113872,"mc":[{"id":"1.232196998","rc":[{"batb":[[0,2.32,5],[1,2.3,13.7],[2,2.28,13.92]],"ltp":2.24,"tv":527.78,"id":60191231}]}]}
{"op":"mcm","clk":"11945210473","pt":1724452117156,"mc":[{"id":"1.232196998","rc":[{"batb":[[0,2.32,13.49]],"batl":[[0,2.38,12.32]],"ltp":2.24,"tv":527.78,"id":60191231},{"batb":[[0,1.73,8.68],[1,1.72,130],[2,1.7,166.37]],"ltp":1.71,"tv":1739.82,"id":72963954}]}]}
{"op":"mcm","clk":"11945210511","pt":1724452117767,"mc":[{"id":"1.232196998","rc":[{"batb":[[0,2.3,13.7],[1,2.28,13.92],[2,2.04,94.85]],"ltp":2.24,"tv":527.78,"id":60191231}]}]}
{"op":"mcm","clk":"11945210568","pt":1724452118637,"mc":[{"id":"1.232196998","rc":[{"batb":[[1,1.72,154.74]],"ltp":1.71,"tv":1739.82,"id":72963954}]}]}
{"op":"mcm","clk":"11945210828","pt":1724452122284,"mc":[{"id":"1.232196998","rc":[{"trd":[[1.72,285.41],[1.73,17.35]],"batb":[[0,1.7,166.37],[1,1.69,60.97],[2,1.68,26.19]],"ltp":1.72,"tv":2042.58,"id":72963954}],"tv":2570.36}]}
{"op":"mcm","clk":"11945210873","pt":1724452122859,"mc":[{"id":"1.232196998","rc":[{"batb":[[0,2.32,5],[1,2.3,13.7],[2,2.28,13.92]],"batl":[[0,2.42,12.12]],"ltp":2.24,"tv":527.78,"id":60191231}]}]}
{"op":"mcm","clk":"11945211016","pt":1724452124705,"mc":[{"id":"1.232196998","rc":[{"batb":[[0,2.32,18.49]],"ltp":2.24,"tv":527.78,"id":60191231}]}]}
{"op":"mcm","clk":"11945211114","pt":1724452126184,"mc":[{"id":"1.232196998","rc":[{"batb":[[0,2.32,13.49]],"ltp":2.24,"tv":527.78,"id":60191231}]}]}
{"op":"mcm","clk":"11945211151","pt":1724452126786,"mc":[{"id":"1.232196998","rc":[{"batb":[[0,2.3,13.7],[1,2.28,13.92],[2,2.04,94.85]],"ltp":2.24,"tv":527.78,"id":60191231},{"batb":[[0,1.72,227.07],[1,1.7,166.37],[2,1.69,60.97]],"ltp":1.72,"tv":2042.58,"id":72963954}]}]}
{"op":"mcm","clk":"11945211285","pt":1724452128786,"mc":[{"id":"1.232196998","rc":[{"batb":[[1,1.71,25.09],[2,1.7,166.37]],"ltp":1.72,"tv":2042.58,"id":72963954}]}]}
{"op":"mcm","clk":"11945211381","pt":1724452130386,"mc":[{"id":"1.232196998","rc":[{"batb":[[0,1.72,204.36]],"ltp":1.72,"tv":2042.58,"id":72963954}]}]}
{"op":"mcm","clk":"11945213529","pt":1724452159816,"mc":[{"id":"1.232196998","rc":[{"batb":[[0,1.73,15.24],[1,1.72,204.36],[2,1.71,25.09]],"ltp":1.72,"tv":2042.58,"id":72963954}]}]}
{"op":"mcm","clk":"11945213591","pt":1724452160691,"mc":[{"id":"1.232196998","rc":[{"batb":[[1,1.72,229.1]],"ltp":1.72,"tv":2042.58,"id":72963954}]}]}
{"op":"mcm","clk":"11945214581","pt":1724452175801,"mc":[{"id":"1.232196998","rc":[{"batb":[[0,1.75,211.93],[1,1.73,15.24],[2,1.72,229.1]],"batl":[[0,1.76,7.57],[1,1.77,7.57],[2,1.78,7.57]],"ltp":1.72,"tv":2042.58,"id":72963954}]}]}
{"op":"mcm","clk":"11945214696","pt":1724452177697,"mc":[{"id":"1.232196998","rc":[{"batl":[[0,2.32,12.65]],"ltp":2.24,"tv":527.78,"id":60191231},{"batb":[[1,1.72,229.1],[2,1.71,25.09]],"ltp":1.72,"tv":2042.58,"id":72963954}]}]}
{"op":"mcm","clk":"11945214905","pt":1724452181241,"mc":[{"id":"1.232196998","rc":[{"batb":[[0,2.04,94.85],[1,1.94,1],[2,1.81,716.36]],"ltp":2.24,"tv":527.78,"id":60191231},{"batb":[[1,1.72,204.36],[2,1.7,140.92]],"ltp":1.72,"tv":2042.58,"id":72963954}]}]}
{"op":"mcm","clk":"11945214912","pt":1724452181343,"mc":[{"id":"1.232196998","rc":[{"batb":[[0,2.06,5],[1,2.04,94.85],[2,1.94,1]],"ltp":2.24,"tv":527.78,"id":60191231}]}]}
{"op":"mcm","clk":"11945215178","pt":1724452185225,"mc":[{"id":"1.232196998","rc":[{"batb":[[0,2.04,94.85],[1,1.94,1],[2,1.81,716.36]],"ltp":2.24,"tv":527.78,"id":60191231},{"batb":[[1,1.7,140.92],[2,1.69,35.16]],"ltp":1.72,"tv":2042.58,"id":72963954}]}]}
{"op":"mcm","clk":"11945215944","pt":1724452197735,"mc":[{"id":"1.232196998","rc":[{"batb":[[0,2.06,5],[1,2.04,94.85],[2,1.94,1]],"ltp":2.24,"tv":527.78,"id":60191231}]}]}
{"op":"mcm","clk":"11945216026","pt":1724452199223,"mc":[{"id":"1.232196998","rc":[{"batl":[[0,2.42,12.12]],"ltp":2.24,"tv":527.78,"id":60191231},{"batb":[[0,1.7,140.92],[1,1.69,35.16],[2,1.65,55.68]],"ltp":1.72,"tv":2042.58,"id":72963954}]}]}
{"op":"mcm","clk":"11945216175","pt":1724452201023,"mc":[{"id":"1.232196998","rc":[{"batb":[[0,2.04,94.85],[1,1.94,1],[2,1.81,716.36]],"ltp":2.24,"tv":527.78,"id":60191231}]}]}
{"op":"mcm","clk":"11945216526","pt":1724452204945,"mc":[{"id":"1.232196998","rc":[{"batb":[[0,2.06,5],[1,2.04,94.85],[2,1.94,1]],"ltp":2.24,"tv":527.78,"id":60191231},{"batb":[[0,1.71,227.07],[1,1.7,140.92],[2,1.69,35.16]],"ltp":1.72,"tv":2042.58,"id":72963954}]}]}
{"op":"mcm","clk":"11945216737","pt":1724452208221,"mc":[{"id":"1.232196998","rc":[{"batb":[[0,2.04,94.85],[1,1.94,1],[2,1.81,716.36]],"ltp":2.24,"tv":527.78,"id":60191231}]}]}
{"op":"mcm","clk":"11945217384","pt":1724452216962,"mc":[{"id":"1.232196998","rc":[{"batb":[[0,2.06,5],[1,2.04,94.85],[2,1.94,1]],"ltp":2.24,"tv":527.78,"id":60191231}]}]}
{"op":"mcm","clk":"11945217627","pt":1724452220458,"mc":[{"id":"1.232196998","rc":[{"batb":[[0,2.04,94.85],[1,1.94,1],[2,1.81,716.36]],"ltp":2.24,"tv":527.78,"id":60191231}]}]}
{"op":"mcm","clk":"11945218314","pt":1724452231237,"mc":[{"id":"1.232196998","rc":[{"batb":[[0,2.06,5],[1,2.04,94.85],[2,1.94,1]],"ltp":2.24,"tv":527.78,"id":60191231},{"trd":[[1.76,15.14],[1.77,15.14]],"batb":[[0,1.77,7276.53],[1,1.71,227.07],[2,1.7,140.92]],"batl":[[0,1.78,7.57],[1,1.79,7.57],[2,1.81,17.03]],"ltp":1.77,"tv":2072.85,"id":72963954}],"tv":2600.63}]}
{"op":"mcm","clk":"11945218319","pt":1724452231338,"mc":[{"id":"1.232196998","rc":[{"trd":[[2.28,5.91]],"batl":[[0,2.28,6.95]],"ltp":2.28,"tv":533.69,"id":60191231},{"trd":[[1.78,7.57]],"batl":[[0,1.79,7.57],[1,1.81,17.03],[2,1.99,36.04]],"ltp":1.78,"tv":2080.42,"id":72963954}],"tv":2614.11}]}
{"op":"mcm","clk":"11945218474","pt":1724452233939,"mc":[{"id":"1.232196998","rc":[{"batb":[[0,2.04,94.85],[1,1.94,1],[2,1.81,716.36]],"ltp":2.28,"tv":533.69,"id":60191231}]}]}
{"op":"mcm","clk":"11945218731","pt":1724452237487,"mc":[{"id":"1.232196998","rc":[{"batb":[[0,2.06,5],[1,2.04,94.85],[2,1.94,1]],"ltp":2.28,"tv":533.69,"id":60191231}]}]}
{"op":"mcm","clk":"11945218837","pt":1724452239491,"mc":[{"id":"1.232196998","rc":[{"trd":[[1.79,202.34]],"batb":[[0,1.79,2909.1],[1,1.77,7276.53],[2,1.71,227.07]],"batl":[[0,1.81,17.03],[1,1.99,36.04],[2,2.08,5.14]],"ltp":1.79,"tv":2095.56,"id":72963954}],"tv":2629.25}]}
{"op":"mcm","clk":"11945218926","pt":1724452240666,"mc":[{"id":"1.232196998","rc":[{"batb":[[0,2.04,94.85],[1,1.94,1],[2,1.81,716.36]],"ltp":2.28,"tv":533.69,"id":60191231}]}]}
{"op":"mcm","clk":"11945219149","pt":1724452244353,"mc":[{"id":"1.232196998","rc":[{"batb":[[0,2.06,5],[1,2.04,94.85],[2,1.94,1]],"ltp":2.28,"tv":533.69,"id":60191231}]}]}
{"op":"mcm","clk":"11945219394","pt":1724452248190,"mc":[{"id":"1.232196998","rc":[{"batb":[[0,2.08,15.94]],"ltp":2.28,"tv":533.69,"id":60191231}]}]}
{"op":"mcm","clk":"11945219560","pt":1724452251108,"mc":[{"id":"1.232196998","rc":[{"batb":[[0,2.1,5],[1,2.08,15.94],[2,2.04,94.85]],"ltp":2.28,"tv":533.69,"id":60191231}]}]}
{"op":"mcm","clk":"11945219772","pt":1724452254583,"mc":[{"id":"1.232196998","rc":[{"batb":[[0,2.08,15.94],[1,2.04,94.85],[2,1.94,1]],"ltp":2.28,"tv":533.69,"id":60191231}]}]}
{"op":"mcm","clk":"11945221632","pt":1724452282396,"mc":[{"id":"1.232196998","rc":[{"batb":[[0,2.1,5],[1,2.08,32.43],[2,2.04,94.85]],"ltp":2.28,"tv":533.69,"id":60191231},{"batb":[[1,1.78,22.83],[2,1.77,7276.53]],"ltp":1.79,"tv":2095.56,"id":72963954}]}]}
{"op":"mcm","clk":"11945221760","pt":1724452284341,"mc":[{"id":"1.232196998","rc":[{"batb":[[0,2.1,21.19]],"ltp":2.28,"tv":533.69,"id":60191231}]}]}
{"op":"mcm","clk":"11945221905","pt":1724452286134,"mc":[{"id":"1.232196998","rc":[{"batb":[[0,2.1,16.19],[1,2.08,16.49]],"ltp":2.28,"tv":533.69,"id":60191231}]}]}
{"op":"mcm","clk":"11945221932","pt":1724452286444,"mc":[{"id":"1.232196998","rc":[{"batb":[[0,2.12,15.94],[1,2.04,111.97],[2,1.94,1]],"ltp":2.28,"tv":533.69,"id":60191231}]}]}
{"op":"mcm","clk":"11945222082","pt":1724452288448,"mc":[{"id":"1.232196998","rc":[{"batb":[[0,2.14,5],[1,2.12,31.84],[2,2.04,111.97]],"ltp":2.28,"tv":533.69,"id":60191231}]}]}
{"op":"mcm","clk":"11945222204","pt":1724452290351,"mc":[{"id":"1.232196998","rc":[{"batb":[[0,2.14,20.62]],"ltp":2.28,"tv":533.69,"id":60191231}]}]}
{"op":"mcm","clk":"11945222288","pt":1724452291837,"mc":[{"id":"1.232196998","rc":[{"batb":[[0,2.14,15.62]],"ltp":2.28,"tv":533.69,"id":60191231}]}]}
{"op":"mcm","clk":"11945222322","pt":1724452292453,"mc":[{"id":"1.232196998","rc":[{"batb":[[0,2.12,31.84],[1,2.04,111.97],[2,1.94,1]],"ltp":2.28,"tv":533.69,"id":60191231}]}]}
{"op":"mcm","clk":"11945223059","pt":1724452304159,"mc":[{"id":"1.232196998","rc":[{"batb":[[0,2.14,5],[1,2.12,31.84],[2,2.04,111.97]],"ltp":2.28,"tv":533.69,"id":60191231}]}]}
{"op":"mcm","clk":"11945223186","pt":1724452306358,"mc":[{"id":"1.232196998","rc":[{"batb":[[0,2.14,20.62]],"ltp":2.28,"tv":533.69,"id":60191231}]}]}
{"op":"mcm","clk":"11945223289","pt":1724452307948,"mc":[{"id":"1.232196998","rc":[{"batb":[[0,2.12,31.84],[1,2.04,111.97],[2,1.94,1]],"ltp":2.28,"tv":533.69,"id":60191231}]}]}
{"op":"mcm","clk":"11945223454","pt":1724452310665,"mc":[{"id":"1.232196998","rc":[{"batb":[[0,2.14,5],[1,2.12,31.84],[2,2.04,111.97]],"ltp":2.28,"tv":533.69,"id":60191231}]}]}
{"op":"mcm","clk":"11945223565","pt":1724452312356,"mc":[{"id":"1.232196998","rc":[{"batb":[[0,2.14,20.62]],"ltp":2.28,"tv":533.69,"id":60191231}]}]}
{"op":"mcm","clk":"11945223654","pt":1724452314046,"mc":[{"id":"1.232196998","rc":[{"batb":[[0,2.14,15.62]],"ltp":2.28,"tv":533.69,"id":60191231}]}]}
{"op":"mcm","clk":"11945223684","pt":1724452314454,"mc":[{"id":"1.232196998","rc":[{"batb":[[0,2.12,31.84],[1,2.04,111.97],[2,1.94,1]],"ltp":2.28,"tv":533.69,"id":60191231}]}]}
{"op":"mcm","clk":"11945224041","pt":1724452320260,"mc":[{"id":"1.232196998","rc":[{"batb":[[0,2.14,5],[1,2.12,31.84],[2,2.04,111.97]],"ltp":2.28,"tv":533.69,"id":60191231}]}]}
{"op":"mcm","clk":"11945224089","pt":1724452321387,"mc":[{"id":"1.232196998","rc":[{"batb":[[0,2.14,20.62]],"ltp":2.28,"tv":533.69,"id":60191231}]}]}
{"op":"mcm","clk":"11945224183","pt":1724452322876,"mc":[{"id":"1.232196998","rc":[{"batb":[[0,2.14,15.62]],"ltp":2.28,"tv":533.69,"id":60191231}]}]}
{"op":"mcm","clk":"11945224223","pt":1724452323385,"mc":[{"id":"1.232196998","rc":[{"batb":[[0,2.12,31.84],[1,2.04,111.97],[2,1.94,1]],"ltp":2.28,"tv":533.69,"id":60191231}]}]}
{"op":"mcm","clk":"11945224755","pt":1724452331282,"mc":[{"id":"1.232196998","rc":[{"batb":[[0,2.14,5],[1,2.12,15.9],[2,2.04,111.97]],"ltp":2.28,"tv":533.69,"id":60191231}]}]}
{"op":"mcm","clk":"11945224777","pt":1724452331491,"mc":[{"id":"1.232196998","rc":[{"batb":[[1,2.04,111.97],[2,1.94,1]],"ltp":2.28,"tv":533.69,"id":60191231}]}]}
{"op":"mcm","clk":"11945224901","pt":1724452333383,"mc":[{"id":"1.232196998","rc":[{"batb":[[0,2.14,20.62]],"ltp":2.28,"tv":533.69,"id":60191231}]}]}
{"op":"mcm","clk":"11945225033","pt":1724452335280,"mc":[{"id":"1.232196998","rc":[{"batb":[[0,2.04,111.97],[1,1.94,1],[2,1.81,716.36]],"ltp":2.28,"tv":533.69,"id":60191231}]}]}
{"op":"mcm","clk":"11945225703","pt":1724452346392,"mc":[{"id":"1.232196998","rc":[{"batb":[[0,2.06,5],[1,2.04,111.97],[2,1.94,1]],"ltp":2.28,"tv":533.69,"id":60191231}]}]}
{"op":"mcm","clk":"11945225803","pt":1724452347982,"mc":[{"id":"1.232196998","rc":[{"trd":[[1.79,402.34]],"batb":[[0,1.79,2809.1]],"ltp":1.79,"tv":2295.56,"id":72963954}],"tv":2829.25}]}
{"op":"mcm","clk":"11945225832","pt":1724452348392,"mc":[{"id":"1.232196998","rc":[{"batb":[[0,2.06,21.8]],"ltp":2.28,"tv":533.69,"id":60191231}]}]}
{"op":"mcm","clk":"11945225907","pt":1724452349873,"mc":[{"id":"1.232196998","rc":[{"batb":[[0,2.06,16.8]],"ltp":2.28,"tv":533.69,"id":60191231}]}]}
{"op":"mcm","clk":"11945225952","pt":1724452350485,"mc":[{"id":"1.232196998","rc":[{"batb":[[0,2.04,111.97],[1,1.94,1],[2,1.81,716.36]],"ltp":2.28,"tv":533.69,"id":60191231}]}]}
{"op":"mcm","clk":"11945226097","pt":1724452352282,"mc":[{"id":"1.232196998","rc":[{"trd":[[2.22,16.74]],"batl":[[0,2.22,73.53],[1,2.28,6.95]],"ltp":2.22,"tv":547.57,"id":60191231},{"trd":[[1.81,49.79]],"batl":[[0,1.99,36.04],[1,2.08,5.14],[2,3.4,1.76]],"ltp":1.81,"tv":2312.59,"id":72963954}],"tv":2860.17}]}
{"op":"mcm","clk":"11945226130","pt":1724452352695,"mc":[{"id":"1.232196998","rc":[{"batb":[[0,2.08,31.63],[1,2.06,5],[2,2.04,111.97]],"batl":[[0,2.2,7.21],[1,2.22,73.53]],"ltp":2.22,"tv":547.57,"id":60191231}]}]}
{"op":"mcm","clk":"11945226183","pt":1724452353414,"mc":[{"id":"1.232196998","rc":[{"batb":[[0,1.79,2831.64]],"ltp":1.81,"tv":2312.59,"id":72963954}]}]}
{"op":"mcm","clk":"11945226259","pt":1724452354390,"mc":[{"id":"1.232196998","rc":[{"batb":[[1,2.06,21.8]],"ltp":2.22,"tv":547.57,"id":60191231},{"batb":[[0,1.81,21.99],[1,1.79,2831.64],[2,1.78,22.83]],"ltp":1.81,"tv":2312.59,"id":72963954}]}]}
{"op":"mcm","clk":"11945226355","pt":1724452355774,"mc":[{"id":"1.232196998","rc":[{"batb":[[1,2.06,16.8]],"ltp":2.22,"tv":547.57,"id":60191231}]}]}
{"op":"mcm","clk":"11945226785","pt":1724452361727,"mc":[{"id":"1.232196998","rc":[{"batb":[[0,2.1,5],[1,2.08,31.63],[2,2.06,16.8]],"ltp":2.22,"tv":547.57,"id":60191231}]}]}
{"op":"mcm","clk":"11945226847","pt":1724452362393,"mc":[{"id":"1.232196998","rc":[{"batb":[[1,2.08,48.12]],"ltp":2.22,"tv":547.57,"id":60191231}]}]}
{"op":"mcm","clk":"11945227049","pt":1724452365210,"mc":[{"id":"1.232196998","rc":[{"batb":[[0,2.08,48.12],[1,2.06,16.8],[2,2.04,111.97]],"batl":[[1,2.22,0]],"ltp":2.22,"tv":547.57,"id":60191231}]}]}
{"op":"mcm","clk":"11945227104","pt":1724452366087,"mc":[{"id":"1.232196998","rc":[{"batb":[[0,1.79,2831.64],[1,1.78,22.83],[2,1.77,7276.53]],"ltp":1.81,"tv":2312.59,"id":72963954}]}]}
{"op":"mcm","clk":"11945227247","pt":1724452368033,"mc":[{"id":"1.232196998","rc":[{"batb":[[0,2.1,5],[1,2.08,48.12],[2,2.06,16.8]],"batl":[[0,2.26,7.01]],"ltp":2.22,"tv":547.57,"id":60191231}]}]}
{"op":"mcm","clk":"11945227491","pt":1724452371209,"mc":[{"id":"1.232196998","rc":[{"batb":[[0,2.1,15.94]],"ltp":2.22,"tv":547.57,"id":60191231},{"batb":[[0,1.8,18.51],[1,1.79,2831.64],[2,1.78,22.83]],"ltp":1.81,"tv":2312.59,"id":72963954}]}]}
{"op":"mcm","clk":"11945228487","pt":1724452386040,"mc":[{"id":"1.232196998","rc":[{"trd":[[2.1,45.24]],"batb":[[0,2.12,30.98],[1,2.1,5],[2,2.04,111.97]],"ltp":2.1,"tv":592.81,"id":60191231}],"tv":2905.41}]}
{"op":"mcm","clk":"11945228705","pt":1724452389111,"mc":[{"id":"1.232196998","rc":[{"batb":[[1,2.1,16.19]],"ltp":2.1,"tv":592.81,"id":60191231}]}]}
{"op":"mcm","clk":"11945230336","pt":1724452414445,"mc":[{"id":"1.232196998","rc":[{"batb":[[0,2.14,5],[1,2.12,30.98],[2,2.1,16.19]],"ltp":2.1,"tv":592.81,"id":60191231}]}]}
{"op":"mcm","clk":"11945230471","pt":1724452415675,"mc":[{"id":"1.232196998","rc":[{"batb":[[1,2.12,46.88]],"ltp":2.1,"tv":592.81,"id":60191231}]}]}
{"op":"mcm","clk":"11945230609","pt":1724452417879,"mc":[{"id":"1.232196998","rc":[{"batb":[[0,2.12,46.88],[1,2.1,16.19],[2,2.04,111.97]],"ltp":2.1,"tv":592.81,"id":60191231}]}]}
{"op":"mcm","clk":"11945231063","pt":1724452425366,"mc":[{"id":"1.232196998","rc":[{"batb":[[0,2.14,5],[1,2.12,46.88],[2,2.1,16.19]],"ltp":2.1,"tv":592.81,"id":60191231}]}]}
{"op":"mcm","clk":"11945231203","pt":1724452428077,"mc":[{"id":"1.232196998","rc":[{"batb":[[1,1.79,22.54]],"ltp":1.81,"tv":2312.59,"id":72963954}]}]}
{"op":"mcm","clk":"11945231243","pt":1724452428791,"mc":[{"id":"1.232196998","rc":[{"batb":[[0,2.12,46.88],[1,2.1,16.19],[2,2.04,111.97]],"ltp":2.1,"tv":592.81,"id":60191231}]}]}
{"op":"mcm","clk":"11945231549","pt":1724452434165,"mc":[{"id":"1.232196998","rc":[{"batb":[[0,2.14,5],[1,2.12,46.88],[2,2.1,16.19]],"ltp":2.1,"tv":592.81,"id":60191231}]}]}
{"op":"mcm","clk":"11945231669","pt":1724452436566,"mc":[{"id":"1.232196998","rc":[{"batb":[[0,2.14,9]],"batl":[[0,2.26,11.01]],"ltp":2.1,"tv":592.81,"id":60191231}]}]}
{"op":"mcm","clk":"11945231709","pt":1724452437586,"mc":[{"id":"1.232196998","rc":[{"batb":[[0,2.14,4]],"ltp":2.1,"tv":592.81,"id":60191231}]}]}
{"op":"mcm","clk":"11945232664","pt":1724452454892,"mc":[{"id":"1.232196998","rc":[{"batb":[[0,2.16,5],[1,2.14,4],[2,2.12,15.9]],"ltp":2.1,"tv":592.81,"id":60191231}]}]}
{"op":"mcm","clk":"11945232708","pt":1724452456018,"mc":[{"id":"1.232196998","rc":[{"batb":[[1,2.04,111.97],[2,1.94,1]],"ltp":2.1,"tv":592.81,"id":60191231}]}]}
{"op":"mcm","clk":"11945232811","pt":1724452458231,"mc":[{"id":"1.232196998","rc":[{"batb":[[0,2.08,31.58]],"ltp":2.1,"tv":592.81,"id":60191231}]}]}
{"op":"mcm","clk":"11945232961","pt":1724452460630,"mc":[{"id":"1.232196998","rc":[{"batb":[[0,2.1,5],[1,2.08,31.58],[2,2.06,16.8]],"ltp":2.1,"tv":592.81,"id":60191231}]}]}
{"op":"mcm","clk":"11945233000","pt":1724452461402,"mc":[{"id":"1.232196998","rc":[{"batb":[[1,2.08,48.07]],"ltp":2.1,"tv":592.81,"id":60191231}]}]}
{"op":"mcm","clk":"11945233131","pt":1724452463818,"mc":[{"id":"1.232196998","rc":[{"batb":[[0,2.08,48.07],[1,2.06,16.8],[2,2.04,111.97]],"ltp":2.1,"tv":592.81,"id":60191231}]}]}
{"op":"mcm","clk":"11945233446","pt":1724452469239,"mc":[{"id":"1.232196998","rc":[{"batb":[[0,2.1,5],[1,2.08,48.07],[2,2.06,16.8]],"ltp":2.1,"tv":592.81,"id":60191231}]}]}
{"op":"mcm","clk":"11945233626","pt":1724452472827,"mc":[{"id":"1.232196998","rc":[{"batb":[[0,2.08,48.07],[1,2.06,16.8],[2,2.04,111.97]],"ltp":2.1,"tv":592.81,"id":60191231}]}]}
{"op":"mcm","clk":"11945233999","pt":1724452479645,"mc":[{"id":"1.232196998","rc":[{"batb":[[0,2.1,5],[1,2.08,48.07],[2,2.06,16.8]],"ltp":2.1,"tv":592.81,"id":60191231}]}]}
{"op":"mcm","clk":"11945234204","pt":1724452483233,"mc":[{"id":"1.232196998","rc":[{"batb":[[0,2.08,48.07],[1,2.06,16.8],[2,2.04,111.97]],"ltp":2.1,"tv":592.81,"id":60191231}]}]}
{"op":"mcm","clk":"11945235011","pt":1724452497963,"mc":[{"id":"1.232196998","rc":[{"batb":[[0,2.1,5],[1,2.08,48.07],[2,2.06,16.8]],"ltp":2.1,"tv":592.81,"id":60191231}]}]}
{"op":"mcm","clk":"11945235208","pt":1724452501454,"mc":[{"id":"1.232196998","rc":[{"batb":[[0,2.08,48.07],[1,2.06,16.8],[2,2.04,111.97]],"ltp":2.1,"tv":592.81,"id":60191231}]}]}
{"op":"mcm","clk":"11945236071","pt":1724452515851,"mc":[{"id":"1.232196998","rc":[{"batb":[[0,2.1,5],[1,2.08,48.07],[2,2.06,16.8]],"ltp":2.1,"tv":592.81,"id":60191231}]}]}
{"op":"mcm","clk":"11945236305","pt":1724452519252,"mc":[{"id":"1.232196998","rc":[{"batb":[[0,2.08,48.07],[1,2.06,16.8],[2,2.04,111.97]],"ltp":2.1,"tv":592.81,"id":60191231}]}]}
{"op":"mcm","clk":"11945236321","pt":1724452519454,"mc":[{"id":"1.232196998","rc":[{"batl":[[0,1.89,60.02],[1,1.99,36.04],[2,2.08,5.14]],"ltp":1.81,"tv":2312.59,"id":72963954}]}]}
{"op":"mcm","clk":"11945236454","pt":1724452521565,"mc":[{"id":"1.232196998","rc":[{"batb":[[0,2.12,5],[1,2.1,16.19],[2,2.08,48.07]],"ltp":2.1,"tv":592.81,"id":60191231}]}]}
{"op":"mcm","clk":"11945236672","pt":1724452524949,"mc":[{"id":"1.232196998","rc":[{"batb":[[0,2.1,16.19],[1,2.08,48.07],[2,2.06,16.8]],"ltp":2.1,"tv":592.81,"id":60191231}]}]}
{"op":"mcm","clk":"11945236718","pt":1724452525671,"mc":[{"id":"1.232196998","rc":[{"trd":[[1.89,75.68]],"batl":[[0,1.89,22.18]],"ltp":1.89,"tv":2388.28,"id":72963954}],"tv":2981.09}]}
{"op":"mcm","clk":"11945236912","pt":1724452527639,"mc":[{"id":"1.232196998","rc":[{"batb":[[0,2.12,5],[1,2.1,16.19],[2,2.08,48.07]],"ltp":2.1,"tv":592.81,"id":60191231}]}]}
{"op":"mcm","clk":"11945237253","pt":1724452531183,"mc":[{"id":"1.232196998","rc":[{"batb":[[0,2.1,16.19],[1,2.08,48.07],[2,2.06,16.8]],"ltp":2.1,"tv":592.81,"id":60191231}]}]}
{"op":"mcm","clk":"11945237269","pt":1724452531489,"mc":[{"id":"1.232196998","rc":[{"batb":[[1,2.08,16.49]],"ltp":2.1,"tv":592.81,"id":60191231},{"batl":[[0,1.89,56.93]],"ltp":1.89,"tv":2388.28,"id":72963954}]}]}
{"op":"mcm","clk":"11945237499","pt":1724452535293,"mc":[{"id":"1.232196998","rc":[{"batb":[[0,2.12,5],[1,2.1,16.19],[2,2.08,16.49]],"ltp":2.1,"tv":592.81,"id":60191231},{"trd":[[1.89,105.96]],"batl":[[0,1.89,41.79]],"ltp":1.89,"tv":2418.55,"id":72963954}],"tv":3011.37}]}
{"op":"mcm","clk":"11945237658","pt":1724452538068,"mc":[{"id":"1.232196998","rc":[{"batb":[[0,2.1,16.19],[1,2.08,16.49],[2,2.06,16.8]],"ltp":2.1,"tv":592.81,"id":60191231}]}]}
{"op":"mcm","clk":"11945237950","pt":1724452543202,"mc":[{"id":"1.232196998","rc":[{"batb":[[0,2.12,5],[1,2.1,16.19],[2,2.08,16.49]],"ltp":2.1,"tv":592.81,"id":60191231}]}]}
{"op":"mcm","clk":"11945238052","pt":1724452544894,"mc":[{"id":"1.232196998","rc":[{"batl":[[0,1.88,189.22],[1,1.89,41.79],[2,1.99,36.04]],"ltp":1.89,"tv":2418.55,"id":72963954}]}]}
{"op":"mcm","clk":"11945238142","pt":1724452546479,"mc":[{"id":"1.232196998","rc":[{"batb":[[0,2.1,16.19],[1,2.08,16.49],[2,2.06,16.8]],"ltp":2.1,"tv":592.81,"id":60191231}]}]}
{"op":"mcm","clk":"11945238450","pt":1724452552082,"mc":[{"id":"1.232196998","rc":[{"batb":[[0,2.12,5],[1,2.1,16.19],[2,2.08,16.49]],"ltp":2.1,"tv":592.81,"id":60191231},{"batl":[[0,1.87,14.1],[1,1.88,189.22],[2,1.89,41.79]],"ltp":1.89,"tv":2418.55,"id":72963954}]}]}
{"op":"mcm","clk":"11945238504","pt":1724452553004,"mc":[{"id":"1.232196998","rc":[{"batb":[[0,2.12,20.9]],"batl":[[0,2.26,7.01]],"ltp":2.1,"tv":592.81,"id":60191231}]}]}
{"op":"mcm","clk":"11945238616","pt":1724452555097,"mc":[{"id":"1.232196998","rc":[{"batb":[[0,2.12,15.9]],"ltp":2.1,"tv":592.81,"id":60191231},{"batl":[[1,1.89,231.01],[2,1.99,36.04]],"ltp":1.89,"tv":2418.55,"id":72963954}]}]}
{"op":"mcm","clk":"11945238665","pt":1724452556123,"mc":[{"id":"1.232196998","rc":[{"batl":[[0,1.89,231.01],[1,1.99,36.04],[2,2.08,5.14]],"ltp":1.89,"tv":2418.55,"id":72963954}]}]}
{"op":"mcm","clk":"11945239057","pt":1724452563182,"mc":[{"id":"1.232196998","rc":[{"batb":[[0,2.14,5],[1,2.12,15.9],[2,2.1,16.19]],"ltp":2.1,"tv":592.81,"id":60191231},{"trd":[[1.89,120.04]],"batl":[[0,1.89,223.44]],"ltp":1.89,"tv":2432.63,"id":72963954}],"tv":3025.45}]}
{"op":"mcm","clk":"11945239259","pt":1724452567214,"mc":[{"id":"1.232196998","rc":[{"batb":[[0,2.12,15.9],[1,2.1,16.19],[2,2.08,16.49]],"ltp":2.1,"tv":592.81,"id":60191231},{"batl":[[0,1.88,16.67],[1,1.89,223.44],[2,1.99,36.04]],"ltp":1.89,"tv":2432.63,"id":72963954}]}]}
{"op":"mcm","clk":"11945239356","pt":1724452569311,"mc":[{"id":"1.232196998","rc":[{"batb":[[0,2.14,5],[1,2.12,15.9],[2,2.1,16.19]],"ltp":2.1,"tv":592.81,"id":60191231}]}]}
{"op":"mcm","clk":"11945239557","pt":1724452572800,"mc":[{"id":"1.232196998","rc":[{"batb":[[0,2.12,15.9],[1,2.1,16.19],[2,2.08,16.49]],"ltp":2.1,"tv":592.81,"id":60191231}]}]}
{"op":"mcm","clk":"11945239710","pt":1724452575512,"mc":[{"id":"1.232196998","rc":[{"batb":[[0,2.14,5],[1,2.12,15.9],[2,2.1,16.19]],"ltp":2.1,"tv":592.81,"id":60191231}]}]}
{"op":"mcm","clk":"11945239894","pt":1724452579001,"mc":[{"id":"1.232196998","rc":[{"batb":[[0,2.12,15.9],[1,2.1,16.19],[2,2.08,16.49]],"ltp":2.1,"tv":592.81,"id":60191231},{"batl":[[1,1.89,188.69]],"ltp":1.89,"tv":2432.63,"id":72963954}]}]}
{"op":"mcm","clk":"11945240338","pt":1724452586340,"mc":[{"id":"1.232196998","rc":[{"batb":[[0,2.14,5],[1,2.12,15.9],[2,2.1,16.19]],"ltp":2.1,"tv":592.81,"id":60191231}]}]}
{"op":"mcm","clk":"11945240501","pt":1724452588655,"mc":[{"id":"1.232196998","rc":[{"batb":[[0,2.14,9]],"batl":[[0,2.26,11.01]],"ltp":2.1,"tv":592.81,"id":60191231}]}]}
{"op":"mcm","clk":"11945240559","pt":1724452589635,"mc":[{"id":"1.232196998","rc":[{"batb":[[0,2.14,4]],"ltp":2.1,"tv":592.81,"id":60191231}]}]}
{"op":"mcm","clk":"11945241142","pt":1724452600042,"mc":[{"id":"1.232196998","rc":[{"batb":[[0,2.16,5],[1,2.14,4],[2,2.12,15.9]],"ltp":2.1,"tv":592.81,"id":60191231}]}]}
{"op":"mcm","clk":"11945241331","pt":1724452603522,"mc":[{"id":"1.232196998","rc":[{"batb":[[0,2.14,4],[1,2.12,15.9],[2,2.1,16.19]],"ltp":2.1,"tv":592.81,"id":60191231}]}]}
{"op":"mcm","clk":"11945243306","pt":1724452635947,"mc":[{"id":"1.232196998","rc":[{"batb":[[0,2.16,5],[1,2.14,4],[2,2.12,15.9]],"ltp":2.1,"tv":592.81,"id":60191231},{"batb":[[0,1.83,418.84],[1,1.8,18.51],[2,1.79,22.54]],"ltp":1.89,"tv":2432.63,"id":72963954}]}]}
{"op":"mcm","clk":"11945243342","pt":1724452636460,"mc":[{"id":"1.232196998","rc":[{"batl":[[0,2.2,7.21],[1,2.26,4]],"ltp":2.1,"tv":592.81,"id":60191231}]}]}
{"op":"mcm","clk":"11945243403","pt":1724452637588,"mc":[{"id":"1.232196998","rc":[{"batb":[[1,1.82,21.72],[2,1.8,18.51]],"ltp":1.89,"tv":2432.63,"id":72963954}]}]}
{"op":"mcm","clk":"11945243507","pt":1724452639389,"mc":[{"id":"1.232196998","rc":[{"batb":[[0,2.14,4],[1,2.12,15.9],[2,2.1,16.19]],"ltp":2.1,"tv":592.81,"id":60191231}]}]}
{"op":"mcm","clk":"11945243888","pt":1724452645899,"mc":[{"id":"1.232196998","rc":[{"trd":[[1.83,192.02]],"batb":[[0,1.83,322.83]],"ltp":1.83,"tv":2624.65,"id":72963954}],"tv":3217.47}]}
{"op":"mcm","clk":"11945244073","pt":1724452649281,"mc":[{"id":"1.232196998","rc":[{"batb":[[0,1.84,4],[1,1.83,326.83],[2,1.82,21.72]],"ltp":1.83,"tv":2624.65,"id":72963954}]}]}
{"op":"mcm","clk":"11945244095","pt":1724452649589,"mc":[{"id":"1.232196998","rc":[{"batl":[[0,2.2,11.21]],"ltp":2.1,"tv":592.81,"id":60191231},{"batb":[[1,1.83,348.29]],"batl":[[0,1.88,20.67]],"ltp":1.83,"tv":2624.65,"id":72963954}]}]}
{"op":"mcm","clk":"11945244849","pt":1724452663275,"mc":[{"id":"1.232196998","rc":[{"batl":[[0,1.88,16.67],[1,1.99,36.04],[2,2.08,5.14]],"ltp":1.83,"tv":2624.65,"id":72963954}]}]}
{"op":"mcm","clk":"11945244881","pt":1724452663788,"mc":[{"id":"1.232196998","rc":[{"batb":[[0,2.12,31.12],[1,2.06,5],[2,2.04,111.97]],"ltp":2.1,"tv":592.81,"id":60191231},{"batl":[[0,1.99,36.04],[1,2.08,5.14],[2,3.4,1.76]],"ltp":1.83,"tv":2624.65,"id":72963954}]}]}
{"op":"mcm","clk":"11945244926","pt":1724452664607,"mc":[{"id":"1.232196998","rc":[{"batb":[[0,2.14,4],[1,2.12,35.12],[2,2.06,5]],"ltp":2.1,"tv":592.81,"id":60191231},{"batl":[[0,1.9,4],[1,1.99,36.04],[2,2.08,5.14]],"ltp":1.83,"tv":2624.65,"id":72963954}]}]}
{"op":"mcm","clk":"11945244975","pt":1724452665583,"mc":[{"id":"1.232196998","rc":[{"batb":[[1,2.12,51.02]],"ltp":2.1,"tv":592.81,"id":60191231}]}]}
{"op":"mcm","clk":"11945245041","pt":1724452667010,"mc":[{"id":"1.232196998","rc":[{"batb":[[2,2.04,111.97]],"ltp":2.1,"tv":592.81,"id":60191231},{"batb":[[0,1.84,20.85]],"ltp":1.83,"tv":2624.65,"id":72963954}]}]}
{"op":"mcm","clk":"11945245459","pt":1724452674096,"mc":[{"id":"1.232196998","rc":[{"batb":[[0,2.12,47.02],[1,2.04,111.97],[2,1.94,1]],"ltp":2.1,"tv":592.81,"id":60191231}]}]}
{"op":"mcm","clk":"11945245846","pt":1724452680892,"mc":[{"id":"1.232196998","rc":[{"batl":[[1,1.96,227.07],[2,1.99,36.04]],"ltp":1.83,"tv":2624.65,"id":72963954}]}]}
{"op":"mcm","clk":"11945245895","pt":1724452681714,"mc":[{"id":"1.232196998","rc":[{"trd":[[1.84,40]],"batb":[[0,1.83,349.14],[1,1.82,21.72],[2,1.79,22.54]],"ltp":1.84,"tv":2664.66,"id":72963954}],"tv":3257.47}]}
{"op":"mcm","clk":"11945246479","pt":1724452690732,"mc":[{"id":"1.232196998","rc":[{"batl":[[0,1.89,36.94],[1,1.9,4],[2,1.96,227.07]],"ltp":1.84,"tv":2664.66,"id":72963954}]}]}
{"op":"mcm","clk":"11945246798","pt":1724452694941,"mc":[{"id":"1.232196998","rc":[{"batb":[[0,2.14,4],[1,2.12,51.02],[2,2.04,111.97]],"ltp":2.1,"tv":592.81,"id":60191231},{"batl":[[0,1.89,40.94]],"ltp":1.84,"tv":2664.66,"id":72963954}]}]}
{"op":"mcm","clk":"11945247750","pt":1724452710215,"mc":[{"id":"1.232196998","rc":[{"batb":[[1,2.12,19.9]],"ltp":2.1,"tv":592.81,"id":60191231},{"batl":[[0,1.88,4],[1,1.89,40.94],[2,1.9,4]],"ltp":1.84,"tv":2664.66,"id":72963954}]}]}
{"op":"mcm","clk":"11945247792","pt":1724452710727,"mc":[{"id":"1.232196998","rc":[{"batb":[[0,2.12,15.9],[1,2.04,111.97],[2,1.94,1]],"ltp":2.1,"tv":592.81,"id":60191231},{"batl":[[0,1.89,71.85],[1,1.96,227.07],[2,1.99,36.04]],"ltp":1.84,"tv":2664.66,"id":72963954}]}]}
{"op":"mcm","clk":"11945247962","pt":1724452713135,"mc":[{"id":"1.232196998","rc":[{"batb":[[0,1.84,18.84],[1,1.83,348.29],[2,1.82,21.72]],"ltp":1.84,"tv":2664.66,"id":72963954}]}]}
{"op":"mcm","clk":"11945248001","pt":1724452713757,"mc":[{"id":"1.232196998","rc":[{"batl":[[0,1.89,34.91]],"ltp":1.84,"tv":2664.66,"id":72963954}]}]}
{"op":"mcm","clk":"11945248740","pt":1724452725225,"mc":[{"id":"1.232196998","rc":[{"batb":[[0,1.84,22.84]],"batl":[[0,1.88,4],[1,1.89,38.91],[2,1.96,227.07]],"ltp":1.84,"tv":2664.66,"id":72963954}]}]}
{"op":"mcm","clk":"11945248750","pt":1724452725351,"mc":[{"id":"1.232196998","rc":[{"batb":[[0,2.14,4],[1,2.12,19.9],[2,2.04,111.97]],"ltp":2.1,"tv":592.81,"id":60191231}]}]}
{"op":"mcm","clk":"11945250014","pt":1724452744164,"mc":[{"id":"1.232196998","rc":[{"trd":[[1.84,60.42]],"batb":[[0,1.84,12.64]],"ltp":1.84,"tv":2685.07,"id":72963954}],"tv":3277.89}]}
{"op":"mcm","clk":"11945250076","pt":1724452745290,"mc":[{"id":"1.232196998","rc":[{"batb":[[0,2.04,111.97],[1,1.94,1],[2,1.81,716.36]],"ltp":2.1,"tv":592.81,"id":60191231},{"batl":[[0,1.96,227.07],[1,1.99,36.04],[2,2.08,5.14]],"ltp":1.84,"tv":2685.07,"id":72963954}]}]}
{"op":"mcm","clk":"11945250088","pt":1724452745492,"mc":[{"id":"1.232196998","rc":[{"batb":[[0,2.06,5],[1,2.04,111.97],[2,1.94,1]],"ltp":2.1,"tv":592.81,"id":60191231},{"batl":[[0,1.93,34.19],[1,1.96,227.07],[2,1.99,36.04]],"ltp":1.84,"tv":2685.07,"id":72963954}]}]}
{"op":"mcm","clk":"11945250169","pt":1724452747084,"mc":[{"id":"1.232196998","rc":[{"batl":[[0,1.92,16.15],[1,1.93,34.19],[2,1.96,227.07]],"ltp":1.84,"tv":2685.07,"id":72963954}]}]}
{"op":"mcm","clk":"11945250203","pt":1724452747648,"mc":[{"id":"1.232196998","rc":[{"batb":[[0,2.06,21.8]],"ltp":2.1,"tv":592.81,"id":60191231}]}]}
{"op":"mcm","clk":"11945250259","pt":1724452748570,"mc":[{"id":"1.232196998","rc":[{"batb":[[0,2.06,16.8]],"ltp":2.1,"tv":592.81,"id":60191231}]}]}
{"op":"mcm","clk":"11945250474","pt":1724452751802,"mc":[{"id":"1.232196998","rc":[{"batb":[[0,2.08,5],[1,2.06,16.8],[2,2.04,111.97]],"ltp":2.1,"tv":592.81,"id":60191231}]}]}
{"op":"mcm","clk":"11945250730","pt":1724452755073,"mc":[{"id":"1.232196998","rc":[{"batb":[[0,2.06,16.8],[1,2.04,111.97],[2,1.94,1]],"ltp":2.1,"tv":592.81,"id":60191231}]}]}
{"op":"mcm","clk":"11945250764","pt":1724452755590,"mc":[{"id":"1.232196998","rc":[{"batb":[[0,2.08,4],[1,2.06,16.8],[2,2.04,111.97]],"ltp":2.1,"tv":592.81,"id":60191231}]}]}
{"op":"mcm","clk":"11945251846","pt":1724452772177,"mc":[{"id":"1.232196998","rc":[{"batb":[[0,2.1,5],[1,2.08,4],[2,2.06,16.8]],"ltp":2.1,"tv":592.81,"id":60191231}]}]}
{"op":"mcm","clk":"11945251942","pt":1724452773203,"mc":[{"id":"1.232196998","rc":[{"batb":[[0,2.12,31.12],[1,2.1,5]],"ltp":2.1,"tv":592.81,"id":60191231},{"batl":[[0,1.89,16.41],[1,1.96,227.07],[2,1.99,36.04]],"ltp":1.84,"tv":2685.07,"id":72963954}]}]}
{"op":"mcm","clk":"11945252073","pt":1724452774700,"mc":[{"id":"1.232196998","rc":[{"batb":[[1,2.1,21.19]],"ltp":2.1,"tv":592.81,"id":60191231}]}]}
{"op":"mcm","clk":"11945252119","pt":1724452775366,"mc":[{"id":"1.232196998","rc":[{"batb":[[1,2.1,16.19]],"ltp":2.1,"tv":592.81,"id":60191231}]}]}
{"op":"mcm","clk":"11945253216","pt":1724452792221,"mc":[{"id":"1.232196998","rc":[{"batb":[[0,2.12,5]],"ltp":2.1,"tv":592.81,"id":60191231},{"batl":[[0,1.87,5.27]],"ltp":1.84,"tv":2685.07,"id":72963954}]}]}
{"op":"mcm","clk":"11945253225","pt":1724452792322,"mc":[{"id":"1.232196998","rc":[{"batl":[[1,1.9,16.32],[2,1.96,227.07]],"ltp":1.84,"tv":2685.07,"id":72963954}]}]}
{"op":"mcm","clk":"11945253395","pt":1724452795216,"mc":[{"id":"1.232196998","rc":[{"batb":[[0,2.1,16.19],[1,2.06,16.8],[2,2.04,111.97]],"ltp":2.1,"tv":592.81,"id":60191231}]}]}
{"op":"mcm","clk":"11945254799","pt":1724452816221,"mc":[{"id":"1.232196998","rc":[{"batb":[[0,2.12,5],[1,2.04,111.97],[2,1.94,1]],"ltp":2.1,"tv":592.81,"id":60191231},{"batl":[[0,1.89,34.91]],"ltp":1.84,"tv":2685.07,"id":72963954}]}]}
{"op":"mcm","clk":"11945254865","pt":1724452817248,"mc":[{"id":"1.232196998","rc":[{"batl":[[0,1.88,16.5],[1,1.89,34.91]],"ltp":1.84,"tv":2685.07,"id":72963954}]}]}
{"op":"mcm","clk":"11945254960","pt":1724452818728,"mc":[{"id":"1.232196998","rc":[{"batb":[[1,2.1,16.19],[2,2.04,111.97]],"ltp":2.1,"tv":592.81,"id":60191231}]}]}
{"op":"mcm","clk":"11945254997","pt":1724452819342,"mc":[{"id":"1.232196998","rc":[{"batb":[[0,2.1,16.19],[1,2.04,111.97],[2,1.94,1]],"ltp":2.1,"tv":592.81,"id":60191231}]}]}
{"op":"mcm","clk":"11945255863","pt":1724452832266,"mc":[{"id":"1.232196998","rc":[{"batb":[[0,2.04,111.97],[1,1.94,1],[2,1.81,716.36]],"ltp":2.1,"tv":592.81,"id":60191231},{"batl":[[1,1.96,227.07],[2,1.99,36.04]],"ltp":1.84,"tv":2685.07,"id":72963954}]}]}
{"op":"mcm","clk":"11945255938","pt":1724452833140,"mc":[{"id":"1.232196998","rc":[{"batb":[[0,2.08,31.72],[1,2.06,5],[2,2.04,111.97]],"ltp":2.1,"tv":592.81,"id":60191231},{"batl":[[0,1.95,15.9]],"ltp":1.84,"tv":2685.07,"id":72963954}]}]}
{"op":"mcm","clk":"11945256066","pt":1724452834936,"mc":[{"id":"1.232196998","rc":[{"batb":[[1,2.06,21.8]],"ltp":2.1,"tv":592.81,"id":60191231},{"batl":[[0,1.92,16.15]],"ltp":1.84,"tv":2685.07,"id":72963954}]}]}
{"op":"mcm","clk":"11945256108","pt":1724452835554,"mc":[{"id":"1.232196998","rc":[{"batb":[[1,2.06,16.8]],"ltp":2.1,"tv":592.81,"id":60191231}]}]}
{"op":"mcm","clk":"11945256969","pt":1724452847143,"mc":[{"id":"1.232196998","rc":[{"batb":[[0,2.1,5]],"batl":[[0,2.2,28.17]],"ltp":2.1,"tv":592.81,"id":60191231},{"batl":[[0,1.91,34.55],[1,1.92,16.15],[2,1.96,227.07]],"ltp":1.84,"tv":2685.07,"id":72963954}]}]}
{"op":"mcm","clk":"11945257009","pt":1724452847662,"mc":[{"id":"1.232196998","rc":[{"batb":[[1,2.08,16.49],[2,2.06,16.8]],"ltp":2.1,"tv":592.81,"id":60191231}]}]}
{"op":"mcm","clk":"11945257063","pt":1724452848589,"mc":[{"id":"1.232196998","rc":[{"batl":[[1,1.96,227.07],[2,1.99,36.04]],"ltp":1.84,"tv":2685.07,"id":72963954}]}]}
{"op":"mcm","clk":"11945257155","pt":1724452849971,"mc":[{"id":"1.232196998","rc":[{"batb":[[0,2.08,16.49],[1,2.06,16.8],[2,2.04,111.97]],"ltp":2.1,"tv":592.81,"id":60191231}]}]}
{"op":"mcm","clk":"11945257992","pt":1724452862065,"mc":[{"id":"1.232196998","rc":[{"batb":[[0,2.12,5],[1,2.1,4],[2,2.08,20.49]],"ltp":2.1,"tv":592.81,"id":60191231}]}]}
{"op":"mcm","clk":"11945258194","pt":1724452864069,"mc":[{"id":"1.232196998","rc":[{"batl":[[0,1.9,16.32],[1,1.91,34.55],[2,1.96,227.07]],"ltp":1.84,"tv":2685.07,"id":72963954}]}]}
{"op":"mcm","clk":"11945258217","pt":1724452864379,"mc":[{"id":"1.232196998","rc":[{"batb":[[1,2.08,16.49],[2,2.06,16.8]],"ltp":2.1,"tv":592.81,"id":60191231}]}]}
{"op":"mcm","clk":"11945258279","pt":1724452865400,"mc":[{"id":"1.232196998","rc":[{"batb":[[0,2.08,16.49],[1,2.06,16.8],[2,2.04,111.97]],"ltp":2.1,"tv":592.81,"id":60191231}]}]}
{"op":"mcm","clk":"11945258797","pt":1724452873197,"mc":[{"id":"1.232196998","rc":[{"batb":[[0,2.1,5],[1,2.08,16.49],[2,2.06,16.8]],"ltp":2.1,"tv":592.81,"id":60191231},{"batb":[[1,1.83,25.46]],"batl":[[0,1.89,34.91],[1,1.9,16.32]],"ltp":1.84,"tv":2685.07,"id":72963954}]}]}
{"op":"mcm","clk":"11945258909","pt":1724452874692,"mc":[{"id":"1.232196998","rc":[{"batb":[[0,2.1,21.19]],"batl":[[0,2.2,20.96]],"ltp":2.1,"tv":592.81,"id":60191231},{"batl":[[1,1.96,227.07],[2,1.99,36.04]],"ltp":1.84,"tv":2685.07,"id":72963954}]}]}
{"op":"mcm","clk":"11945259087","pt":1724452877102,"mc":[{"id":"1.232196998","rc":[{"batb":[[0,2.12,4],[1,2.1,16.19],[2,2.08,16.49]],"ltp":2.1,"tv":592.81,"id":60191231},{"batl":[[0,1.88,4],[1,1.89,38.91],[2,1.96,227.07]],"ltp":1.84,"tv":2685.07,"id":72963954}]}]}
{"op":"mcm","clk":"11945259616","pt":1724452886082,"mc":[{"id":"1.232196998","rc":[{"batb":[[0,2.12,5]],"ltp":2.1,"tv":592.81,"id":60191231},{"batb":[[0,1.85,418.84],[1,1.84,12.64],[2,1.83,25.46]],"batl":[[0,1.89,34.91],[1,1.96,227.07],[2,1.99,36.04]],"ltp":1.84,"tv":2685.07,"id":72963954}]}]}
{"op":"mcm","clk":"11945259669","pt":1724452886901,"mc":[{"id":"1.232196998","rc":[{"batl":[[0,2.16,7.34],[1,2.2,4],[2,2.26,4]],"ltp":2.1,"tv":592.81,"id":60191231}]}]}
{"op":"mcm","clk":"11945259731","pt":1724452887674,"mc":[{"id":"1.232196998","rc":[{"batb":[[0,1.85,439.8]],"ltp":1.84,"tv":2685.07,"id":72963954}]}]}
{"op":"mcm","clk":"11945259791","pt":1724452888897,"mc":[{"id":"1.232196998","rc":[{"batl":[[0,1.88,16.5],[1,1.89,34.91],[2,1.96,227.07]],"ltp":1.84,"tv":2685.07,"id":72963954}]}]}
{"op":"mcm","clk":"11945259827","pt":1724452889413,"mc":[{"id":"1.232196998","rc":[{"batb":[[0,2.1,16.19],[1,2.08,16.49],[2,2.06,16.8]],"ltp":2.1,"tv":592.81,"id":60191231}]}]}
{"op":"mcm","clk":"11945260012","pt":1724452892098,"mc":[{"id":"1.232196998","rc":[{"batl":[[0,2.16,11.34]],"ltp":2.1,"tv":592.81,"id":60191231},{"batb":[[0,1.86,4],[1,1.85,439.8],[2,1.84,12.64]],"ltp":1.84,"tv":2685.07,"id":72963954}]}]}
{"op":"mcm","clk":"11945260654","pt":1724452901028,"mc":[{"id":"1.232196998","rc":[{"trd":[[2.16,8.67]],"batl":[[0,2.16,2.67]],"ltp":2.16,"tv":601.48,"id":60191231},{"trd":[[1.86,18.06]],"batb":[[0,1.85,439.8],[1,1.84,12.64],[2,1.83,25.46]],"batl":[[1,1.96,227.07],[2,1.99,36.04]],"ltp":1.86,"tv":2703.14,"id":72963954}],"tv":3304.62}]}
{"op":"mcm","clk":"11945260684","pt":1724452901492,"mc":[{"id":"1.232196998","rc":[{"batb":[[0,2.06,5],[1,2.04,111.97],[2,1.94,1]],"ltp":2.16,"tv":601.48,"id":60191231}]}]}
{"op":"mcm","clk":"11945260742","pt":1724452902619,"mc":[{"id":"1.232196998","rc":[{"batb":[[0,2.1,31.42],[1,2.06,5],[2,2.04,111.97]],"ltp":2.16,"tv":601.48,"id":60191231},{"batl":[[0,1.95,16.96]],"ltp":1.86,"tv":2703.14,"id":72963954}]}]}
{"op":"mcm","clk":"11945260900","pt":1724452905238,"mc":[{"id":"1.232196998","rc":[{"batb":[[1,2.08,16.49]],"ltp":2.16,"tv":601.48,"id":60191231},{"batb":[[1,1.84,4]],"batl":[[0,1.96,227.07],[1,1.99,36.04],[2,2.08,5.14]],"ltp":1.86,"tv":2703.14,"id":72963954}]}]}
{"op":"mcm","clk":"11945260957","pt":1724452906212,"mc":[{"id":"1.232196998","rc":[{"trd":[[2.16,11.34]],"batl":[[0,2.2,4],[1,2.26,4],[2,2.26,0]],"ltp":2.16,"tv":604.15,"id":60191231},{"trd":[[1.86,38.54]],"batl":[[0,1.86,84.22],[1,1.96,227.07],[2,1.99,36.04]],"ltp":1.86,"tv":2723.62,"id":72963954}],"tv":3327.77}]}
{"op":"mcm","clk":"11945260992","pt":1724452906825,"mc":[{"id":"1.232196998","rc":[{"batb":[[0,2.1,47.61]],"ltp":2.16,"tv":604.15,"id":60191231},{"batb":[[0,1.85,418.84],[1,1.84,25.2]],"ltp":1.86,"tv":2723.62,"id":72963954}]}]}
{"op":"mcm","clk":"11945261053","pt":1724452907802,"mc":[{"id":"1.232196998","rc":[{"batl":[[0,2.18,4],[1,2.2,4],[2,2.26,4]],"ltp":2.16,"tv":604.15,"id":60191231},{"batb":[[0,1.85,422.84]],"batl":[[0,1.86,100.89]],"ltp":1.86,"tv":2723.62,"id":72963954}]}]}
{"op":"mcm","clk":"11945261106","pt":1724452908725,"mc":[{"id":"1.232196998","rc":[{"batb":[[0,2.14,15.62],[1,2.1,47.61],[2,2.08,16.49]],"ltp":2.16,"tv":604.15,"id":60191231}]}]}
{"op":"mcm","clk":"11945262847","pt":1724452940749,"mc":[{"id":"1.232196998","rc":[{"trd":[[2.18,5.22]],"batb":[[1,2.1,16.19]],"batl":[[0,2.18,1.39]],"ltp":2.18,"tv":609.37,"id":60191231}],"tv":3332.99}]}
{"op":"mcm","clk":"11945263346","pt":1724452949045,"mc":[{"id":"1.232196998","rc":[{"batb":[[0,1.85,4]],"ltp":1.86,"tv":2723.62,"id":72963954}]}]}
{"op":"mcm","clk":"11945263386","pt":1724452949760,"mc":[{"id":"1.232196998","rc":[{"batb":[[0,1.71,252.15],[1,1.7,140.92],[2,1.69,35.16]],"ltp":1.86,"tv":2723.62,"id":72963954}]}]}
{"op":"mcm","clk":"11945264251","pt":1724452964282,"mc":[{"id":"1.232196998","rc":[{"batb":[[0,1.85,418.84],[1,1.71,252.15],[2,1.7,140.92]],"ltp":1.86,"tv":2723.62,"id":72963954}]}]}
{"op":"mcm","clk":"11945264258","pt":1724452964385,"mc":[{"id":"1.232196998","rc":[{"trd":[[1.85,204.54]],"batb":[[0,1.85,318.84]],"ltp":1.85,"tv":2923.62,"id":72963954}],"tv":3532.99}]}
{"op":"mcm","clk":"11945264395","pt":1724452966793,"mc":[{"id":"1.232196998","rc":[{"batb":[[1,1.84,21.2],[2,1.71,252.15]],"ltp":1.85,"tv":2923.62,"id":72963954}]}]}
{"op":"mcm","clk":"11945264447","pt":1724452967772,"mc":[{"id":"1.232196998","rc":[{"batl":[[0,2.18,4]],"ltp":2.18,"tv":609.37,"id":60191231},{"batb":[[0,1.85,322.84]],"ltp":1.85,"tv":2923.62,"id":72963954}]}]}
{"op":"mcm","clk":"11945264835","pt":1724452974094,"mc":[{"id":"1.232196998","rc":[{"trd":[[1.85,396.56]],"batb":[[0,1.85,226.83]],"ltp":1.85,"tv":3115.64,"id":72963954}],"tv":3725.01}]}
{"op":"mcm","clk":"11945265089","pt":1724452978679,"mc":[{"id":"1.232196998","rc":[{"batl":[[0,2.18,11.91]],"ltp":2.18,"tv":609.37,"id":60191231}]}]}
{"op":"mcm","clk":"11945266892","pt":1724453009905,"mc":[{"id":"1.232196998","rc":[{"trd":[[1.85,588.58]],"batb":[[0,1.85,130.82]],"ltp":1.85,"tv":3307.66,"id":72963954}],"tv":3917.03}]}
{"op":"mcm","clk":"11945268362","pt":1724453034829,"mc":[{"id":"1.232196998","rc":[{"trd":[[2.16,19.25]],"batl":[[0,2.18,4]],"ltp":2.16,"tv":617.28,"id":60191231},{"trd":[[1.86,47.73]],"batl":[[0,1.86,91.7]],"ltp":1.86,"tv":3316.85,"id":72963954}],"tv":3934.13}]}
{"op":"mcm","clk":"11945270568","pt":1724453072672,"mc":[{"id":"1.232196998","rc":[{"trd":[[1.85,599.13]],"batb":[[0,1.85,125.55]],"ltp":1.85,"tv":3327.39,"id":72963954}],"tv":3944.68}]}
{"op":"mcm","clk":"11945271397","pt":1724453086796,"mc":[{"id":"1.232196998","rc":[{"trd":[[1.85,791.15]],"batb":[[0,1.85,29.54]],"ltp":1.85,"tv":3519.41,"id":72963954}],"tv":4136.7}]}
{"op":"mcm","clk":"11945271520","pt":1724453088693,"mc":[{"id":"1.232196998","rc":[{"batb":[[0,2.16,4],[1,2.14,15.62],[2,2.1,16.19]],"ltp":2.16,"tv":617.28,"id":60191231},{"batl":[[0,1.86,95.7]],"ltp":1.85,"tv":3519.41,"id":72963954}]}]}
{"op":"mcm","clk":"11945271734","pt":1724453091917,"mc":[{"id":"1.232196998","rc":[{"trd":[[1.85,850.23]],"batb":[[0,1.71,252.15],[1,1.7,140.92],[2,1.69,35.16]],"batl":[[0,1.85,66.47],[1,1.86,95.7],[2,1.96,227.07]],"ltp":1.85,"tv":3578.49,"id":72963954}],"tv":4195.78}]}
{"op":"mcm","clk":"11945271892","pt":1724453093918,"mc":[{"id":"1.232196998","rc":[{"batl":[[0,1.84,16.85],[1,1.85,66.47],[2,1.86,79.03]],"ltp":1.85,"tv":3578.49,"id":72963954}]}]}
{"op":"mcm","clk":"11945271957","pt":1724453094788,"mc":[{"id":"1.232196998","rc":[{"batb":[[0,2.16,19.35]],"ltp":2.16,"tv":617.28,"id":60191231}]}]}
{"op":"mcm","clk":"11945272298","pt":1724453100132,"mc":[{"id":"1.232196998","rc":[{"trd":[[2.16,35.98],[2.18,19.45]],"batb":[[0,2.18,15.42],[1,2.16,10.98],[2,2.14,15.62]],"ltp":2.16,"tv":648.24,"id":60191231},{"trd":[[1.84,77.27]],"batb":[[0,1.72,19.54],[1,1.71,252.15],[2,1.7,140.92]],"batl":[[0,1.85,66.47],[1,1.86,79.03],[2,1.96,227.07]],"ltp":1.84,"tv":3595.34,"id":72963954}],"tv":4243.59}]}
{"op":"mcm","clk":"11945273812","pt":1724453124034,"mc":[{"id":"1.232196998","rc":[{"batl":[[0,1.84,6.25],[1,1.85,66.47],[2,1.86,79.03]],"ltp":1.84,"tv":3595.34,"id":72963954}]}]}
{"op":"mcm","clk":"11945274210","pt":1724453130843,"mc":[{"id":"1.232196998","rc":[{"batl":[[2,1.86,4]],"ltp":1.84,"tv":3595.34,"id":72963954}]}]}
{"op":"mcm","clk":"11945274297","pt":1724453132224,"mc":[{"id":"1.232196998","rc":[{"batl":[[1,1.96,227.07],[2,1.99,36.04]],"ltp":1.84,"tv":3595.34,"id":72963954}]}]}
{"op":"mcm","clk":"11945274428","pt":1724453133926,"mc":[{"id":"1.232196998","rc":[{"batb":[[0,1.73,227.07],[1,1.72,19.54],[2,1.71,25.09]],"batl":[[0,1.96,227.07],[1,1.99,36.04],[2,2.08,5.14]],"ltp":1.84,"tv":3595.34,"id":72963954}]}]}
{"op":"mcm","clk":"11945274475","pt":1724453134847,"mc":[{"id":"1.232196998","rc":[{"batb":[[1,2.04,111.97],[2,1.94,1]],"ltp":2.16,"tv":648.24,"id":60191231}]}]}
{"op":"mcm","clk":"11945274545","pt":1724453135874,"mc":[{"id":"1.232196998","rc":[{"batb":[[1,1.72,44.28]],"ltp":1.84,"tv":3595.34,"id":72963954}]}]}
{"op":"mcm","clk":"11945274708","pt":1724453138851,"mc":[{"id":"1.232196998","rc":[{"batb":[[0,2.06,16.45]],"ltp":2.16,"tv":648.24,"id":60191231},{"batb":[[0,1.74,19.02],[1,1.73,251.47],[2,1.72,24.74]],"batl":[[0,1.92,34.37],[1,1.96,227.07],[2,1.99,36.04]],"ltp":1.84,"tv":3595.34,"id":72963954}]}]}
{"op":"mcm","clk":"11945274826","pt":1724453140863,"mc":[{"id":"1.232196998","rc":[{"batb":[[0,2.06,33.25]],"ltp":2.16,"tv":648.24,"id":60191231}]}]}
{"op":"mcm","clk":"11945275146","pt":1724453145934,"mc":[{"id":"1.232196998","rc":[{"batb":[[0,1.75,227.07],[1,1.74,19.02],[2,1.7,166.37]],"ltp":1.84,"tv":3595.34,"id":72963954}]}]}
{"op":"mcm","clk":"11945275179","pt":1724453146551,"mc":[{"id":"1.232196998","rc":[{"trd":[[1.75,84.81]],"batb":[[0,1.75,184.66]],"ltp":1.75,"tv":3680.16,"id":72963954}],"tv":4328.4}]}
{"op":"mcm","clk":"11945275256","pt":1724453147833,"mc":[{"id":"1.232196998","rc":[{"batb":[[1,1.74,43.09]],"ltp":1.75,"tv":3680.16,"id":72963954}]}]}
{"op":"mcm","clk":"11945276014","pt":1724453160970,"mc":[{"id":"1.232196998","rc":[{"batl":[[0,1.89,189.22],[1,1.92,34.37],[2,1.96,227.07]],"ltp":1.75,"tv":3680.16,"id":72963954}]}]}
{"op":"mcm","clk":"11945276053","pt":1724453161890,"mc":[{"id":"1.232196998","rc":[{"batb":[[0,2.08,16.49],[1,2.06,33.25],[2,2.04,111.97]],"ltp":2.16,"tv":648.24,"id":60191231}]}]}
{"op":"mcm","clk":"11945276131","pt":1724453162903,"mc":[{"id":"1.232196998","rc":[{"batb":[[0,2.1,16.19],[1,2.08,16.49],[2,2.06,33.25]],"ltp":2.16,"tv":648.24,"id":60191231}]}]}
{"op":"mcm","clk":"11945276939","pt":1724453176210,"mc":[{"id":"1.232196998","rc":[{"batb":[[2,2.06,16.8]],"ltp":2.16,"tv":648.24,"id":60191231},{"batb":[[1,1.74,24.07]],"ltp":1.75,"tv":3680.16,"id":72963954}]}]}
{"op":"mcm","clk":"11945276994","pt":1724453176879,"mc":[{"id":"1.232196998","rc":[{"batb":[[0,2.14,15.42],[1,2.1,16.19],[2,2.08,16.49]],"ltp":2.16,"tv":648.24,"id":60191231},{"batb":[[0,1.76,19.02],[1,1.75,208.4],[2,1.74,24.07]],"batl":[[0,1.89,224.13],[1,1.96,227.07],[2,1.99,36.04]],"ltp":1.75,"tv":3680.16,"id":72963954}]}]}
{"op":"mcm","clk":"11945277071","pt":1724453177911,"mc":[{"id":"1.232196998","rc":[{"batb":[[1,2.12,15.9],[2,2.1,16.19]],"ltp":2.16,"tv":648.24,"id":60191231}]}]}
{"op":"mcm","clk":"11945277235","pt":1724453180114,"mc":[{"id":"1.232196998","rc":[{"batb":[[0,1.77,13.44],[1,1.76,19.02],[2,1.75,208.4]],"ltp":1.75,"tv":3680.16,"id":72963954}]}]}
{"op":"mcm","clk":"11945277335","pt":1724453181928,"mc":[{"id":"1.232196998","rc":[{"batb":[[1,1.76,42.46]],"ltp":1.75,"tv":3680.16,"id":72963954}]}]}
{"op":"mcm","clk":"11945277553","pt":1724453185503,"mc":[{"id":"1.232196998","rc":[{"batl":[[0,1.87,189.22],[1,1.89,34.91],[2,1.96,227.07]],"ltp":1.75,"tv":3680.16,"id":72963954}]}]}
{"op":"mcm","clk":"11945277701","pt":1724453188026,"mc":[{"id":"1.232196998","rc":[{"batb":[[0,2.14,35.48]],"ltp":2.16,"tv":648.24,"id":60191231},{"batl":[[1,1.96,227.07],[2,1.99,36.04]],"ltp":1.75,"tv":3680.16,"id":72963954}]}]}
{"op":"mcm","clk":"11945277810","pt":1724453189910,"mc":[{"id":"1.232196998","rc":[{"batl":[[0,1.86,4.19],[1,1.87,189.22],[2,1.96,227.07]],"ltp":1.75,"tv":3680.16,"id":72963954}]}]}
{"op":"mcm","clk":"11945277883","pt":1724453190885,"mc":[{"id":"1.232196998","rc":[{"batb":[[0,2.14,51.1]],"ltp":2.16,"tv":648.24,"id":60191231}]}]}
{"op":"mcm","clk":"11945278456","pt":1724453200910,"mc":[{"id":"1.232196998","rc":[{"batb":[[0,1.83,418.84],[1,1.77,13.44],[2,1.76,42.46]],"ltp":1.75,"tv":3680.16,"id":72963954}]}]}
{"op":"mcm","clk":"11945278603","pt":1724453202914,"mc":[{"id":"1.232196998","rc":[{"batb":[[1,1.82,21.72],[2,1.77,13.44]],"ltp":1.75,"tv":3680.16,"id":72963954}]}]}
{"op":"mcm","clk":"11945278667","pt":1724453204040,"mc":[{"id":"1.232196998","rc":[{"batl":[[0,1.86,13.01]],"ltp":1.75,"tv":3680.16,"id":72963954}]}]}
{"op":"mcm","clk":"11945278807","pt":1724453206310,"mc":[{"id":"1.232196998","rc":[{"trd":[[1.83,384.04]],"batb":[[0,1.83,322.83]],"ltp":1.83,"tv":3872.18,"id":72963954}],"tv":4520.42}]}
{"op":"mcm","clk":"11945278931","pt":1724453208715,"mc":[{"id":"1.232196998","rc":[{"batl":[[1,1.96,227.07],[2,1.99,36.04]],"ltp":1.83,"tv":3872.18,"id":72963954}]}]}
{"op":"mcm","clk":"11945278980","pt":1724453209737,"mc":[{"id":"1.232196998","rc":[{"batl":[[0,2.22,4]],"ltp":2.16,"tv":648.24,"id":60191231},{"batb":[[0,1.83,326.83]],"ltp":1.83,"tv":3872.18,"id":72963954}]}]}
{"op":"mcm","clk":"11945279012","pt":1724453210401,"mc":[{"id":"1.232196998","rc":[{"trd":[[1.83,576.06]],"batb":[[0,1.83,230.82]],"ltp":1.83,"tv":4064.2,"id":72963954}],"tv":4712.44}]}
{"op":"mcm","clk":"11945279135","pt":1724453212304,"mc":[{"id":"1.232196998","rc":[{"batl":[[0,1.86,4.19]],"ltp":1.83,"tv":4064.2,"id":72963954}]}]}
{"op":"mcm","clk":"11945279313","pt":1724453215124,"mc":[{"id":"1.232196998","rc":[{"batb":[[0,2.14,35.67]],"ltp":2.16,"tv":648.24,"id":60191231},{"trd":[[1.83,768.08]],"batb":[[0,1.84,18],[1,1.83,134.81],[2,1.82,21.72]],"batl":[[0,1.96,227.07],[1,1.99,36.04],[2,2.08,5.14]],"ltp":1.83,"tv":4256.22,"id":72963954}],"tv":4904.46}]}
{"op":"mcm","clk":"11945279360","pt":1724453215995,"mc":[{"id":"1.232196998","rc":[{"batb":[[1,1.83,156.27]],"ltp":1.83,"tv":4256.22,"id":72963954}]}]}
{"op":"mcm","clk":"11945279818","pt":1724453222513,"mc":[{"id":"1.232196998","rc":[{"trd":[[2.14,1.68]],"batb":[[0,2.14,34.84]],"ltp":2.14,"tv":649.92,"id":60191231}],"tv":4906.14}]}
{"op":"mcm","clk":"11945280003","pt":1724453224932,"mc":[{"id":"1.232196998","rc":[{"batb":[[0,2.16,4],[1,2.14,38.84],[2,2.12,15.9]],"batl":[[0,2.2,4],[1,2.22,4]],"ltp":2.14,"tv":649.92,"id":60191231},{"batb":[[0,1.84,22]],"batl":[[0,1.87,4],[1,1.88,4],[2,1.96,227.07]],"ltp":1.83,"tv":4256.22,"id":72963954}]}]}
{"op":"mcm","clk":"11945281332","pt":1724453248054,"mc":[{"id":"1.232196998","rc":[{"batl":[[0,2.22,4],[1,2.22,0]],"ltp":2.14,"tv":649.92,"id":60191231},{"trd":[[1.83,968.08],[1.84,121.27]],"batb":[[0,1.83,34.81],[1,1.82,21.72],[2,1.76,23.43]],"batl":[[0,1.84,74.01],[1,1.87,4],[2,1.88,4]],"ltp":1.83,"tv":4500.21,"id":72963954}],"tv":5150.14}]}
{"op":"mcm","clk":"11945281425","pt":1724453249949,"mc":[{"id":"1.232196998","rc":[{"batb":[[0,2.16,19.35]],"ltp":2.14,"tv":649.92,"id":60191231}]}]}
{"op":"mcm","clk":"11945281495","pt":1724453251279,"mc":[{"id":"1.232196998","rc":[{"batb":[[0,2.18,15.42],[1,2.16,19.35],[2,2.14,38.84]],"ltp":2.14,"tv":649.92,"id":60191231}]}]}
{"op":"mcm","clk":"11945281588","pt":1724453252976,"mc":[{"id":"1.232196998","rc":[{"trd":[[1.83,1037.7]],"batb":[[0,1.82,21.72],[1,1.76,23.43],[2,1.75,208.4]],"batl":[[0,1.83,61.2],[1,1.84,74.01],[2,1.87,4]],"ltp":1.83,"tv":4569.83,"id":72963954}],"tv":5219.76}]}
{"op":"mcm","clk":"11945281655","pt":1724453253949,"mc":[{"id":"1.232196998","rc":[{"batb":[[0,2.18,30.52]],"ltp":2.14,"tv":649.92,"id":60191231},{"batb":[[0,1.75,208.4],[1,1.74,24.07],[2,1.7,140.92]],"ltp":1.83,"tv":4569.83,"id":72963954}]}]}
{"op":"mcm","clk":"11945283350","pt":1724453282597,"mc":[{"id":"1.232196998","rc":[{"batb":[[0,1.76,18.55],[1,1.75,208.4],[2,1.74,24.07]],"ltp":1.83,"tv":4569.83,"id":72963954}]}]}
{"op":"mcm","clk":"11945283506","pt":1724453285106,"mc":[{"id":"1.232196998","rc":[{"trd":[[1.75,351.71],[1.76,52.24]],"batb":[[0,1.76,5.52],[1,1.75,74.96]],"batl":[[0,1.82,4.49],[1,1.83,61.2],[2,1.84,74.01]],"ltp":1.75,"tv":4873.83,"id":72963954}],"tv":5523.75}]}
{"op":"mcm","clk":"11945283761","pt":1724453289408,"mc":[{"id":"1.232196998","rc":[{"batb":[[0,2.2,15.42],[1,2.18,15.1],[2,2.16,19.35]],"ltp":2.14,"tv":649.92,"id":60191231}]}]}
{"op":"mcm","clk":"11945284453","pt":1724453301105,"mc":[{"id":"1.232196998","rc":[{"batb":[[0,2.24,5],[1,2.22,4],[2,2.2,19.42]],"batl":[[0,2.32,4]],"ltp":2.14,"tv":649.92,"id":60191231},{"batb":[[0,1.76,9.52]],"batl":[[0,1.82,41.03]],"ltp":1.75,"tv":4873.83,"id":72963954}]}]}
{"op":"mcm","clk":"11945284502","pt":1724453302025,"mc":[{"id":"1.232196998","rc":[{"batb":[[2,2.2,34.27]],"ltp":2.14,"tv":649.92,"id":60191231}]}]}
{"op":"mcm","clk":"11945284624","pt":1724453304023,"mc":[{"id":"1.232196998","rc":[{"batb":[[0,2.22,10.28],[1,2.2,34.27],[2,2.18,15.1]],"ltp":2.14,"tv":649.92,"id":60191231}]}]}
{"op":"mcm","clk":"11945284864","pt":1724453308125,"mc":[{"id":"1.232196998","rc":[{"batb":[[0,2.24,5],[1,2.22,10.28],[2,2.2,34.27]],"ltp":2.14,"tv":649.92,"id":60191231}]}]}
{"op":"mcm","clk":"11945285051","pt":1724453311511,"mc":[{"id":"1.232196998","rc":[{"batb":[[0,2.22,10.28],[1,2.2,34.27],[2,2.18,15.1]],"ltp":2.14,"tv":649.92,"id":60191231}]}]}
{"op":"mcm","clk":"11945285326","pt":1724453315604,"mc":[{"id":"1.232196998","rc":[{"batb":[[0,2.24,5],[1,2.22,10.28],[2,2.2,34.27]],"ltp":2.14,"tv":649.92,"id":60191231},{"batl":[[0,1.81,8.19],[1,1.82,41.03],[2,1.83,61.2]],"ltp":1.75,"tv":4873.83,"id":72963954}]}]}
{"op":"mcm","clk":"11945285441","pt":1724453318008,"mc":[{"id":"1.232196998","rc":[{"batb":[[1,2.22,24.88]],"ltp":2.14,"tv":649.92,"id":60191231}]}]}
{"op":"mcm","clk":"11945285481","pt":1724453318824,"mc":[{"id":"1.232196998","rc":[{"batb":[[0,2.22,24.88],[1,2.2,34.27],[2,2.18,15.1]],"ltp":2.14,"tv":649.92,"id":60191231}]}]}
{"op":"mcm","clk":"11945285517","pt":1724453319544,"mc":[{"id":"1.232196998","rc":[{"batb":[[0,2.22,10.28]],"ltp":2.14,"tv":649.92,"id":60191231}]}]}
{"op":"mcm","clk":"11945285664","pt":1724453322219,"mc":[{"id":"1.232196998","rc":[{"batb":[[0,2.24,5],[1,2.22,10.28],[2,2.2,34.27]],"ltp":2.14,"tv":649.92,"id":60191231}]}]}
{"op":"mcm","clk":"11945285778","pt":1724453324016,"mc":[{"id":"1.232196998","rc":[{"batb":[[1,2.22,24.88]],"ltp":2.14,"tv":649.92,"id":60191231},{"batl":[[2,1.87,4]],"ltp":1.75,"tv":4873.83,"id":72963954}]}]}
{"op":"mcm","clk":"11945285889","pt":1724453326028,"mc":[{"id":"1.232196998","rc":[{"batb":[[0,2.22,10.28],[1,2.2,34.27],[2,2.18,15.1]],"ltp":2.14,"tv":649.92,"id":60191231}]}]}
{"op":"mcm","clk":"11945286047","pt":1724453329247,"mc":[{"id":"1.232196998","rc":[{"batb":[[0,2.24,5],[1,2.22,10.28],[2,2.2,18.84]],"ltp":2.14,"tv":649.92,"id":60191231}]}]}
{"op":"mcm","clk":"11945286057","pt":1724453329348,"mc":[{"id":"1.232196998","rc":[{"batb":[[1,2.22,25.19]],"ltp":2.14,"tv":649.92,"id":60191231}]}]}
{"op":"mcm","clk":"11945286165","pt":1724453331248,"mc":[{"id":"1.232196998","rc":[{"batb":[[0,2.3,4],[1,2.24,5],[2,2.22,39.79]],"ltp":2.14,"tv":649.92,"id":60191231},{"trd":[[1.76,89.58]],"batb":[[0,1.75,51.21],[1,1.74,24.07],[2,1.7,140.92]],"batl":[[0,1.76,158.56],[1,1.81,8.19],[2,1.82,36.54]],"ltp":1.76,"tv":4911.17,"id":72963954}],"tv":5561.09}]}
{"op":"mcm","clk":"11945286190","pt":1724453331760,"mc":[{"id":"1.232196998","rc":[{"batb":[[1,2.22,39.79],[2,2.2,18.84]],"ltp":2.14,"tv":649.92,"id":60191231},{"batl":[[0,1.76,164.08]],"ltp":1.76,"tv":4911.17,"id":72963954}]}]}
{"op":"mcm","clk":"11945286269","pt":1724453332945,"mc":[{"id":"1.232196998","rc":[{"batb":[[1,2.28,13.92],[2,2.22,39.79]],"ltp":2.14,"tv":649.92,"id":60191231}]}]}
{"op":"mcm","clk":"11945286733","pt":1724453342078,"mc":[{"id":"1.232196998","rc":[{"batb":[[1,2.22,39.79],[2,2.2,18.84]],"ltp":2.14,"tv":649.92,"id":60191231},{"batl":[[0,1.76,5.52],[1,1.81,4.19],[2,1.82,32.54]],"ltp":1.76,"tv":4911.17,"id":72963954}]}]}
{"op":"mcm","clk":"11945286769","pt":1724453342647,"mc":[{"id":"1.232196998","rc":[{"batb":[[0,2.22,39.79],[1,2.2,18.84],[2,2.18,15.1]],"ltp":2.14,"tv":649.92,"id":60191231},{"batl":[[0,1.81,4.19],[1,1.82,32.54],[2,1.96,227.07]],"ltp":1.76,"tv":4911.17,"id":72963954}]}]}
{"op":"mcm","clk":"11945286988","pt":1724453346245,"mc":[{"id":"1.232196998","rc":[{"batb":[[0,2.24,5],[1,2.22,39.79],[2,2.2,18.84]],"batl":[[0,2.34,4]],"ltp":2.14,"tv":649.92,"id":60191231},{"trd":[[1.75,462.13]],"batb":[[0,1.74,24.07],[1,1.7,140.92],[2,1.69,35.16]],"batl":[[0,1.75,103.31],[1,1.81,8.19],[2,1.82,32.54]],"ltp":1.75,"tv":5021.59,"id":72963954}],"tv":5671.51}]}
{"op":"mcm","clk":"11945287035","pt":1724453347063,"mc":[{"id":"1.232196998","rc":[{"trd":[[1.74,48.14],[1.75,662.13]],"batb":[[0,1.7,166.37],[1,1.69,35.16],[2,1.66,681.2]],"batl":[[0,1.75,8.87]],"ltp":1.74,"tv":5269.73,"id":72963954}],"tv":5919.65}]}
{"op":"mcm","clk":"11945287124","pt":1724453348044,"mc":[{"id":"1.232196998","rc":[{"batb":[[1,2.22,35.79],[2,2.2,14.84]],"ltp":2.14,"tv":649.92,"id":60191231},{"batb":[[0,1.7,140.92],[1,1.69,60.97]],"batl":[[1,1.81,4.19]],"ltp":1.74,"tv":5269.73,"id":72963954}]}]}
{"op":"mcm","clk":"11945287153","pt":1724453348553,"mc":[{"id":"1.232196998","rc":[{"batl":[[0,1.75,3.31]],"ltp":1.74,"tv":5269.73,"id":72963954}]}]}
{"op":"mcm","clk":"11945287260","pt":1724453350255,"mc":[{"id":"1.232196998","rc":[{"batb":[[0,2.22,35.79],[1,2.2,14.84],[2,2.18,15.1]],"ltp":2.14,"tv":649.92,"id":60191231},{"batl":[[1,1.81,10.47]],"ltp":1.74,"tv":5269.73,"id":72963954}]}]}
{"op":"mcm","clk":"11945287434","pt":1724453353081,"mc":[{"id":"1.232196998","rc":[{"batl":[[1,1.8,8.87],[2,1.81,10.47]],"ltp":1.74,"tv":5269.73,"id":72963954}]}]}
{"op":"mcm","clk":"11945287932","pt":1724453361259,"mc":[{"id":"1.232196998","rc":[{"batl":[[0,2.44,4]],"ltp":2.14,"tv":649.92,"id":60191231},{"batb":[[0,1.7,144.92]],"ltp":1.74,"tv":5269.73,"id":72963954}]}]}
{"op":"mcm","clk":"11945287937","pt":1724453361358,"mc":[{"id":"1.232196998","rc":[{"batb":[[0,2.24,5],[1,2.22,35.79],[2,2.2,14.84]],"ltp":2.14,"tv":649.92,"id":60191231}]}]}
{"op":"mcm","clk":"11945288117","pt":1724453364562,"mc":[{"id":"1.232196998","rc":[{"batb":[[0,2.22,35.79],[1,2.2,14.84],[2,2.18,15.1]],"ltp":2.14,"tv":649.92,"id":60191231}]}]}
{"op":"mcm","clk":"11945288292","pt":1724453367079,"mc":[{"id":"1.232196998","rc":[{"batb":[[0,2.24,5],[1,2.22,35.79],[2,2.2,14.84]],"ltp":2.14,"tv":649.92,"id":60191231},{"batb":[[0,1.71,4.19],[1,1.7,170.37],[2,1.69,60.97]],"ltp":1.74,"tv":5269.73,"id":72963954}]}]}
{"op":"mcm","clk":"11945288398","pt":1724453369279,"mc":[{"id":"1.232196998","rc":[{"batb":[[1,2.22,20.88]],"ltp":2.14,"tv":649.92,"id":60191231}]}]}
{"op":"mcm","clk":"11945288458","pt":1724453370404,"mc":[{"id":"1.232196998","rc":[{"batb":[[0,2.22,20.88],[1,2.2,14.84],[2,2.18,15.1]],"ltp":2.14,"tv":649.92,"id":60191231}]}]}
{"op":"mcm","clk":"11945288664","pt":1724453374712,"mc":[{"id":"1.232196998","rc":[{"batb":[[0,2.24,5],[1,2.22,20.88],[2,2.2,14.84]],"ltp":2.14,"tv":649.92,"id":60191231}]}]}
{"op":"mcm","clk":"11945288715","pt":1724453375595,"mc":[{"id":"1.232196998","rc":[{"trd":[[1.75,668.75]],"batb":[[0,1.71,5.07]],"batl":[[0,1.8,8.87],[1,1.81,10.47],[2,1.82,32.54]],"ltp":1.75,"tv":5276.35,"id":72963954}],"tv":5926.27}]}
{"op":"mcm","clk":"11945288857","pt":1724453378001,"mc":[{"id":"1.232196998","rc":[{"batb":[[0,2.22,20.88],[1,2.2,14.84],[2,2.18,15.1]],"ltp":2.14,"tv":649.92,"id":60191231}]}]}
{"op":"mcm","clk":"11945289071","pt":1724453382104,"mc":[{"id":"1.232196998","rc":[{"batb":[[0,2.24,5],[1,2.22,20.88],[2,2.2,14.84]],"ltp":2.14,"tv":649.92,"id":60191231},{"batb":[[0,1.71,232.14]],"ltp":1.75,"tv":5276.35,"id":72963954}]}]}
{"op":"mcm","clk":"11945289273","pt":1724453385488,"mc":[{"id":"1.232196998","rc":[{"batb":[[0,2.22,20.88],[1,2.2,14.84],[2,2.18,15.1]],"ltp":2.14,"tv":649.92,"id":60191231}]}]}
{"op":"mcm","clk":"11945289646","pt":1724453392526,"mc":[{"id":"1.232196998","rc":[{"batb":[[0,2.24,5],[1,2.22,20.88],[2,2.2,14.84]],"ltp":2.14,"tv":649.92,"id":60191231},{"batl":[[0,1.8,9.32]],"ltp":1.75,"tv":5276.35,"id":72963954}]}]}
{"op":"mcm","clk":"11945289827","pt":1724453395908,"mc":[{"id":"1.232196998","rc":[{"batb":[[0,2.22,20.88],[1,2.2,14.84],[2,2.18,15.1]],"ltp":2.14,"tv":649.92,"id":60191231}]}]}
{"op":"mcm","clk":"11945290017","pt":1724453400117,"mc":[{"id":"1.232196998","rc":[{"batb":[[0,2.24,5],[1,2.22,20.88],[2,2.2,14.84]],"ltp":2.14,"tv":649.92,"id":60191231}]}]}
{"op":"mcm","clk":"11945290198","pt":1724453403621,"mc":[{"id":"1.232196998","rc":[{"batb":[[0,2.22,20.88],[1,2.2,14.84],[2,2.18,15.1]],"ltp":2.14,"tv":649.92,"id":60191231}]}]}
{"op":"mcm","clk":"11945290396","pt":1724453408406,"mc":[{"id":"1.232196998","rc":[{"batb":[[0,2.24,5],[1,2.22,20.88],[2,2.2,30.27]],"ltp":2.14,"tv":649.92,"id":60191231}]}]}
{"op":"mcm","clk":"11945290538","pt":1724453411746,"mc":[{"id":"1.232196998","rc":[{"batb":[[0,2.22,20.88],[1,2.2,30.27],[2,2.18,15.1]],"ltp":2.14,"tv":649.92,"id":60191231},{"batl":[[0,1.8,10.72]],"ltp":1.75,"tv":5276.35,"id":72963954}]}]}
{"op":"mcm","clk":"11945291031","pt":1724453420245,"mc":[{"id":"1.232196998","rc":[{"batl":[[1,1.81,14.83]],"ltp":1.75,"tv":5276.35,"id":72963954}]}]}
{"op":"mcm","clk":"11945291036","pt":1724453420350,"mc":[{"id":"1.232196998","rc":[{"batb":[[0,2.24,5],[1,2.22,20.88],[2,2.2,30.27]],"ltp":2.14,"tv":649.92,"id":60191231}]}]}
{"op":"mcm","clk":"11945291199","pt":1724453423746,"mc":[{"id":"1.232196998","rc":[{"batb":[[0,2.22,20.88],[1,2.2,30.27],[2,2.18,15.1]],"ltp":2.14,"tv":649.92,"id":60191231}]}]}
{"op":"mcm","clk":"11945291486","pt":1724453429030,"mc":[{"id":"1.232196998","rc":[{"batb":[[0,2.24,5],[1,2.22,20.88],[2,2.2,30.27]],"ltp":2.14,"tv":649.92,"id":60191231}]}]}
{"op":"mcm","clk":"11945291670","pt":1724453432568,"mc":[{"id":"1.232196998","rc":[{"batb":[[0,2.22,20.88],[1,2.2,30.27],[2,2.18,15.1]],"ltp":2.14,"tv":649.92,"id":60191231}]}]}
{"op":"mcm","clk":"11945291860","pt":1724453436266,"mc":[{"id":"1.232196998","rc":[{"batb":[[0,1.71,231.26]],"ltp":1.75,"tv":5276.35,"id":72963954}]}]}
{"op":"mcm","clk":"11945291867","pt":1724453436368,"mc":[{"id":"1.232196998","rc":[{"batb":[[0,2.24,5],[1,2.22,20.88],[2,2.2,30.27]],"ltp":2.14,"tv":649.92,"id":60191231}]}]}
{"op":"mcm","clk":"11945292038","pt":1724453439759,"mc":[{"id":"1.232196998","rc":[{"batb":[[0,2.22,20.88],[1,2.2,30.27],[2,2.18,15.1]],"ltp":2.14,"tv":649.92,"id":60191231}]}]}
{"op":"mcm","clk":"11945292282","pt":1724453444488,"mc":[{"id":"1.232196998","rc":[{"batb":[[0,2.24,5],[1,2.22,20.88],[2,2.2,30.27]],"ltp":2.14,"tv":649.92,"id":60191231}]}]}
{"op":"mcm","clk":"11945292470","pt":1724453447771,"mc":[{"id":"1.232196998","rc":[{"batb":[[0,2.22,20.88],[1,2.2,30.27],[2,2.18,15.1]],"ltp":2.14,"tv":649.92,"id":60191231}]}]}
{"op":"mcm","clk":"11945292668","pt":1724453451976,"mc":[{"id":"1.232196998","rc":[{"batb":[[0,2.24,5],[1,2.22,20.88],[2,2.2,30.27]],"ltp":2.14,"tv":649.92,"id":60191231},{"batb":[[0,1.71,232.18]],"ltp":1.75,"tv":5276.35,"id":72963954}]}]}
{"op":"mcm","clk":"11945292877","pt":1724453455278,"mc":[{"id":"1.232196998","rc":[{"batb":[[0,2.22,20.88],[1,2.2,30.27],[2,2.18,15.1]],"ltp":2.14,"tv":649.92,"id":60191231}]}]}
{"op":"mcm","clk":"11945293047","pt":1724453458575,"mc":[{"id":"1.232196998","rc":[{"batb":[[0,2.24,5],[1,2.22,20.88],[2,2.2,30.27]],"ltp":2.14,"tv":649.92,"id":60191231}]}]}
{"op":"mcm","clk":"11945293243","pt":1724453461875,"mc":[{"id":"1.232196998","rc":[{"batb":[[0,2.22,20.88],[1,2.2,30.27],[2,2.18,15.1]],"ltp":2.14,"tv":649.92,"id":60191231}]}]}
{"op":"mcm","clk":"11945293447","pt":1724453464965,"mc":[{"id":"1.232196998","rc":[{"batb":[[0,2.24,5],[1,2.22,20.88],[2,2.2,30.27]],"ltp":2.14,"tv":649.92,"id":60191231}]}]}
{"op":"mcm","clk":"11945293624","pt":1724453468306,"mc":[{"id":"1.232196998","rc":[{"batb":[[0,2.22,20.88],[1,2.2,30.27],[2,2.18,15.1]],"ltp":2.14,"tv":649.92,"id":60191231}]}]}
{"op":"mcm","clk":"11945294375","pt":1724453479102,"mc":[{"id":"1.232196998","rc":[{"batb":[[0,2.24,5],[1,2.22,20.88],[2,2.2,30.27]],"ltp":2.14,"tv":649.92,"id":60191231}]}]}
{"op":"mcm","clk":"11945294550","pt":1724453481880,"mc":[{"id":"1.232196998","rc":[{"batl":[[2,1.96,227.07]],"ltp":1.75,"tv":5276.35,"id":72963954}]}]}
{"op":"mcm","clk":"11945294604","pt":1724453482604,"mc":[{"id":"1.232196998","rc":[{"batb":[[0,2.22,20.88],[1,2.2,30.27],[2,2.18,15.1]],"ltp":2.14,"tv":649.92,"id":60191231}]}]}
{"op":"mcm","clk":"11945294724","pt":1724453484100,"mc":[{"id":"1.232196998","rc":[{"batl":[[0,1.79,5.88],[1,1.8,26.97],[2,1.81,4.19]],"ltp":1.75,"tv":5276.35,"id":72963954}]}]}
{"op":"mcm","clk":"11945294794","pt":1724453485222,"mc":[{"id":"1.232196998","rc":[{"batb":[[1,2.2,14.84]],"ltp":2.14,"tv":649.92,"id":60191231}]}]}
{"op":"mcm","clk":"11945294855","pt":1724453486102,"mc":[{"id":"1.232196998","rc":[{"batb":[[0,2.24,19.37],[1,2.22,35.79],[2,2.2,14.84]],"ltp":2.14,"tv":649.92,"id":60191231}]}]}
{"op":"mcm","clk":"11945295012","pt":1724453489026,"mc":[{"id":"1.232196998","rc":[{"batb":[[0,2.24,14.37]],"ltp":2.14,"tv":649.92,"id":60191231}]}]}
{"op":"mcm","clk":"11945295772","pt":1724453502946,"mc":[{"id":"1.232196998","rc":[{"batb":[[0,2.26,5],[1,2.24,14.37],[2,2.22,35.79]],"ltp":2.14,"tv":649.92,"id":60191231},{"batl":[[0,1.79,10.07]],"ltp":1.75,"tv":5276.35,"id":72963954}]}]}
{"op":"mcm","clk":"11945295932","pt":1724453506411,"mc":[{"id":"1.232196998","rc":[{"batb":[[0,2.24,14.37],[1,2.22,35.79],[2,2.2,14.84]],"ltp":2.14,"tv":649.92,"id":60191231}]}]}
{"op":"mcm","clk":"11945296593","pt":1724453518957,"mc":[{"id":"1.232196998","rc":[{"batb":[[0,2.26,5],[1,2.24,14.37],[2,2.22,35.79]],"ltp":2.14,"tv":649.92,"id":60191231},{"trd":[[1.71,883.14],[1.72,287.25]],"batb":[[0,1.71,215.47]],"batl":[[1,1.8,10.27]],"ltp":1.71,"tv":5309.76,"id":72963954}],"tv":5959.68}]}
{"op":"mcm","clk":"11945296752","pt":1724453522259,"mc":[{"id":"1.232196998","rc":[{"batb":[[0,2.24,14.37],[1,2.22,35.79],[2,2.2,14.84]],"ltp":2.14,"tv":649.92,"id":60191231}]}]}
{"op":"mcm","clk":"11945296779","pt":1724453522631,"mc":[{"id":"1.232196998","rc":[{"batb":[[0,2.22,35.79],[1,2.2,14.84],[2,2.18,15.1]],"ltp":2.14,"tv":649.92,"id":60191231},{"batl":[[0,1.75,167.54],[1,1.79,10.07],[2,1.8,10.27]],"ltp":1.71,"tv":5309.76,"id":72963954}]}]}
{"op":"mcm","clk":"11945296869","pt":1724453524224,"mc":[{"id":"1.232196998","rc":[{"batl":[[0,1.74,5.59],[1,1.75,167.54],[2,1.79,4.64]],"ltp":1.71,"tv":5309.76,"id":72963954}]}]}
{"op":"mcm","clk":"11945296929","pt":1724453525245,"mc":[{"id":"1.232196998","rc":[{"batb":[[0,2.34,5],[1,2.32,13.49],[2,2.22,35.79]],"ltp":2.14,"tv":649.92,"id":60191231}]}]}
{"op":"mcm","clk":"11945296990","pt":1724453526636,"mc":[{"id":"1.232196998","rc":[{"batb":[[1,2.32,27.89],[2,2.22,20.88]],"ltp":2.14,"tv":649.92,"id":60191231}]}]}
{"op":"mcm","clk":"11945297066","pt":1724453528026,"mc":[{"id":"1.232196998","rc":[{"batb":[[0,2.34,9]],"batl":[[0,2.42,4],[1,2.44,4]],"ltp":2.14,"tv":649.92,"id":60191231},{"batb":[[0,1.71,219.47]],"batl":[[0,1.74,9.59]],"ltp":1.71,"tv":5309.76,"id":72963954}]}]}
{"op":"mcm","clk":"11945297097","pt":1724453528436,"mc":[{"id":"1.232196998","rc":[{"batb":[[0,2.34,4]],"ltp":2.14,"tv":649.92,"id":60191231}]}]}
{"op":"mcm","clk":"11945298056","pt":1724453545949,"mc":[{"id":"1.232196998","rc":[{"batb":[[0,1.71,4]],"ltp":1.71,"tv":5309.76,"id":72963954}]}]}
{"op":"mcm","clk":"11945298419","pt":1724453554586,"mc":[{"id":"1.232196998","rc":[{"batl":[[0,1.74,22.57]],"ltp":1.71,"tv":5309.76,"id":72963954}]}]}
{"op":"mcm","clk":"11945298578","pt":1724453558285,"mc":[{"id":"1.232196998","rc":[{"batb":[[0,2.36,4],[1,2.34,4],[2,2.32,27.89]],"ltp":2.14,"tv":649.92,"id":60191231},{"batl":[[0,1.73,4],[1,1.74,22.57],[2,1.75,167.54]],"ltp":1.71,"tv":5309.76,"id":72963954}]}]}
{"op":"mcm","clk":"11945298616","pt":1724453559157,"mc":[{"id":"1.232196998","rc":[{"batb":[[1,2.34,17.29]],"ltp":2.14,"tv":649.92,"id":60191231}]}]}
{"op":"mcm","clk":"11945298661","pt":1724453560388,"mc":[{"id":"1.232196998","rc":[{"batb":[[0,1.72,28.28],[1,1.71,4],[2,1.7,170.37]],"ltp":1.71,"tv":5309.76,"id":72963954}]}]}
{"op":"mcm","clk":"11945298767","pt":1724453562145,"mc":[{"id":"1.232196998","rc":[{"batb":[[1,1.71,29.09]],"ltp":1.71,"tv":5309.76,"id":72963954}]}]}
{"op":"mcm","clk":"11945298994","pt":1724453566258,"mc":[{"id":"1.232196998","rc":[{"batb":[[1,2.34,31.69],[2,2.32,13.49]],"ltp":2.14,"tv":649.92,"id":60191231}]}]}
{"op":"mcm","clk":"11945299081","pt":1724453567758,"mc":[{"id":"1.232196998","rc":[{"batl":[[1,1.74,26.76]],"ltp":1.71,"tv":5309.76,"id":72963954}]}]}
{"op":"mcm","clk":"11945299172","pt":1724453569665,"mc":[{"id":"1.232196998","rc":[{"trd":[[1.72,288.02]],"batb":[[0,1.72,27.89]],"ltp":1.72,"tv":5310.53,"id":72963954}],"tv":5960.45}]}
{"op":"mcm","clk":"11945299358","pt":1724453573474,"mc":[{"id":"1.232196998","rc":[{"batl":[[0,2.4,4],[1,2.42,4],[2,2.44,4]],"ltp":2.14,"tv":649.92,"id":60191231},{"batb":[[0,1.72,31.89]],"ltp":1.72,"tv":5310.53,"id":72963954}]}]}
{"op":"mcm","clk":"11945301171","pt":1724453612824,"mc":[{"id":"1.232196998","rc":[{"trd":[[2.36,4]],"batb":[[0,2.34,31.69],[1,2.32,13.49],[2,2.22,14.6]],"ltp":2.36,"tv":653.92,"id":60191231},{"trd":[[1.73,25.35],[1.74,107.09],[1.75,852.37]],"batl":[[0,1.75,75.73],[1,1.79,4.64],[2,1.8,237.34]],"ltp":1.75,"tv":5561.1,"id":72963954}],"tv":6215.03}]}
{"op":"mcm","clk":"11945301228","pt":1724453614218,"mc":[{"id":"1.232196998","rc":[{"batb":[[0,1.73,13.06],[1,1.72,56.63],[2,1.71,29.09]],"ltp":1.75,"tv":5561.1,"id":72963954}]}]}
{"op":"mcm","clk":"11945301433","pt":1724453618849,"mc":[{"id":"1.232196998","rc":[{"batl":[[0,2.38,4],[1,2.4,4],[2,2.42,4]],"ltp":2.36,"tv":653.92,"id":60191231},{"batb":[[0,1.73,17.06]],"batl":[[0,1.74,4],[1,1.75,79.73],[2,1.79,4.64]],"ltp":1.75,"tv":5561.1,"id":72963954}]}]}
{"op":"mcm","clk":"11945301938","pt":1724453629319,"mc":[{"id":"1.232196998","rc":[{"batb":[[2,2.3,5.87]],"ltp":2.36,"tv":653.92,"id":60191231},{"trd":[[1.74,115.09],[1.75,858.37]],"batl":[[0,1.75,76.73],[1,1.79,4.64],[2,1.8,237.34]],"ltp":1.75,"tv":5575.1,"id":72963954}],"tv":6229.03}]}
{"op":"mcm","clk":"11945302153","pt":1724453634148,"mc":[{"id":"1.232196998","rc":[{"batl":[[0,1.74,4],[1,1.75,76.73],[2,1.79,4.64]],"ltp":1.75,"tv":5575.1,"id":72963954}]}]}
{"op":"mcm","clk":"11945302465","pt":1724453642233,"mc":[{"id":"1.232196998","rc":[{"trd":[[1.74,117.09]],"batl":[[0,1.74,3]],"ltp":1.74,"tv":5577.1,"id":72963954}],"tv":6231.03}]}
{"op":"mcm","clk":"11945302635","pt":1724453646649,"mc":[{"id":"1.232196998","rc":[{"batb":[[0,1.73,21.73]],"ltp":1.74,"tv":5577.1,"id":72963954}]}]}
{"op":"mcm","clk":"11945303846","pt":1724453670217,"mc":[{"id":"1.232196998","rc":[{"trd":[[2.34,31.69]],"batb":[[0,2.32,13.49],[1,2.3,5.87],[2,2.22,14.6]],"ltp":2.34,"tv":685.61,"id":60191231},{"trd":[[1.74,123.09],[1.75,908.74]],"batb":[[0,1.75,45.44],[1,1.73,21.73],[2,1.72,56.63]],"batl":[[0,1.79,4.64],[1,1.8,237.34],[2,1.81,4.19]],"ltp":1.75,"tv":5633.47,"id":72963954}],"tv":6319.08}]}
{"op":"mcm","clk":"11945303896","pt":1724453671184,"mc":[{"id":"1.232196998","rc":[{"batb":[[0,2.3,5.87],[1,2.24,14.37]],"ltp":2.34,"tv":685.61,"id":60191231}]}]}
{"op":"mcm","clk":"11945303960","pt":1724453672219,"mc":[{"id":"1.232196998","rc":[{"batl":[[0,2.82,14.91],[1,2.4,0],[2,2.42,0]],"ltp":2.34,"tv":685.61,"id":60191231},{"batb":[[0,1.76,12.84],[1,1.75,69.19],[2,1.72,52.63]],"ltp":1.75,"tv":5633.47,"id":72963954}]}]}
{"op":"mcm","clk":"11945303966","pt":1724453672312,"mc":[{"id":"1.232196998","rc":[{"trd":[[2.32,5]],"ltp":2.32,"tv":690.61,"id":60191231},{"trd":[[1.76,96.17]],"batb":[[0,1.76,6.25]],"ltp":1.76,"tv":5640.06,"id":72963954}],"tv":6330.67}]}
{"op":"mcm","clk":"11945304512","pt":1724453682232,"mc":[{"id":"1.232196998","rc":[{"trd":[[2.32,9.74]],"batb":[[0,2.32,4.26],[1,2.3,5.87],[2,2.26,14.4]],"ltp":2.32,"tv":695.35,"id":60191231},{"trd":[[1.76,102.42]],"batb":[[0,1.75,64.98],[1,1.74,24.07]],"ltp":1.76,"tv":5646.31,"id":72963954}],"tv":6341.66}]}
{"op":"mcm","clk":"11945304597","pt":1724453684120,"mc":[{"id":"1.232196998","rc":[{"batb":[[0,2.3,6.13],[1,2.26,14.4],[2,2.24,14.37]],"ltp":2.32,"tv":695.35,"id":60191231}]}]}
{"op":"mcm","clk":"11945304644","pt":1724453685200,"mc":[{"id":"1.232196998","rc":[{"batb":[[0,2.3,5.87],[1,2.26,28.53]],"ltp":2.32,"tv":695.35,"id":60191231}]}]}
{"op":"mcm","clk":"11945304919","pt":1724453692117,"mc":[{"id":"1.232196998","rc":[{"batb":[[0,2.32,9],[1,2.3,5.87],[2,2.26,28.53]],"ltp":2.32,"tv":695.35,"id":60191231}]}]}
{"op":"mcm","clk":"11945305030","pt":1724453694787,"mc":[{"id":"1.232196998","rc":[{"batb":[[0,2.32,5]],"batl":[[0,2.34,4],[1,2.82,14.91]],"ltp":2.32,"tv":695.35,"id":60191231},{"batb":[[0,1.75,68.98]],"ltp":1.76,"tv":5646.31,"id":72963954}]}]}
{"op":"mcm","clk":"11945305054","pt":1724453695609,"mc":[{"id":"1.232196998","rc":[{"batb":[[0,2.3,5.87],[1,2.26,28.53],[2,2.24,14.37]],"ltp":2.32,"tv":695.35,"id":60191231}]}]}
{"op":"mcm","clk":"11945305337","pt":1724453702205,"mc":[{"id":"1.232196998","rc":[{"batl":[[0,1.79,21.28]],"ltp":1.76,"tv":5646.31,"id":72963954}]}]}
{"op":"mcm","clk":"11945305510","pt":1724453705802,"mc":[{"id":"1.232196998","rc":[{"batb":[[0,1.76,4.86],[1,1.75,68.98],[2,1.74,24.07]],"ltp":1.76,"tv":5646.31,"id":72963954}]}]}
{"op":"mcm","clk":"11945305585","pt":1724453707233,"mc":[{"id":"1.232196998","rc":[{"trd":[[2.3,5.87]],"batb":[[0,2.26,28.53],[1,2.24,14.37],[2,2.22,14.6]],"ltp":2.3,"tv":701.22,"id":60191231},{"trd":[[1.77,22.77],[1.79,444.9]],"batb":[[0,1.79,7262.76],[1,1.76,4.86],[2,1.75,92.73]],"batl":[[0,1.8,237.34],[1,1.81,4.19],[2,1.96,227.07]],"ltp":1.79,"tv":5696.5,"id":72963954}],"tv":6397.72}]}
{"op":"mcm","clk":"11945305609","pt":1724453707900,"mc":[{"id":"1.232196998","rc":[{"batb":[[0,2.26,14.4]],"ltp":2.3,"tv":701.22,"id":60191231},{"batb":[[0,1.79,7279.4],[1,1.75,92.73],[2,1.74,24.07]],"ltp":1.79,"tv":5696.5,"id":72963954}]}]}
{"op":"mcm","clk":"11945305665","pt":1724453709283,"mc":[{"id":"1.232196998","rc":[{"batb":[[1,1.78,22.83],[2,1.75,92.73]],"ltp":1.79,"tv":5696.5,"id":72963954}]}]}
{"op":"mcm","clk":"11945305691","pt":1724453709950,"mc":[{"id":"1.232196998","rc":[{"batl":[[0,2.28,4],[1,2.34,4],[2,2.82,14.91]],"ltp":2.3,"tv":701.22,"id":60191231},{"batb":[[0,1.79,7283.4]],"ltp":1.79,"tv":5696.5,"id":72963954}]}]}
{"op":"mcm","clk":"11945306117","pt":1724453718228,"mc":[{"id":"1.232196998","rc":[{"trd":[[2.26,15.1]],"batb":[[0,2.16,5],[1,2.14,34.84],[2,2.06,102.83]],"ltp":2.26,"tv":715.61,"id":60191231},{"trd":[[1.8,521.68]],"batb":[[0,1.8,36.25],[1,1.79,7305.94],[2,1.78,22.83]],"batl":[[0,1.81,4.19],[1,1.96,227.07],[2,1.99,36.04]],"ltp":1.8,"tv":6189.26,"id":72963954}],"tv":6904.88}]}
{"op":"mcm","clk":"11945306126","pt":1724453718432,"mc":[{"id":"1.232196998","rc":[{"batb":[[1,1.79,7289.3]],"ltp":1.8,"tv":6189.26,"id":72963954}]}]}
{"op":"mcm","clk":"11945306284","pt":1724453721149,"mc":[{"id":"1.232196998","rc":[{"batb":[[0,2.14,34.84],[1,2.06,102.83],[2,2.04,94.85]],"ltp":2.26,"tv":715.61,"id":60191231}]}]}
{"op":"mcm","clk":"11945306322","pt":1724453722042,"mc":[{"id":"1.232196998","rc":[{"trd":[[1.81,58.17]],"batb":[[0,1.81,12.26],[1,1.8,36.25],[2,1.79,7289.3]],"batl":[[0,1.96,227.07],[1,1.99,36.04],[2,2.08,5.14]],"ltp":1.81,"tv":6197.64,"id":72963954}],"tv":6913.26}]}
{"op":"mcm","clk":"11945306375","pt":1724453723224,"mc":[{"id":"1.232196998","rc":[{"batb":[[1,1.8,77.02]],"ltp":1.81,"tv":6197.64,"id":72963954}]}]}
{"op":"mcm","clk":"11945306383","pt":1724453723328,"mc":[{"id":"1.232196998","rc":[{"batb":[[0,2.16,5],[1,2.14,34.84],[2,2.06,102.83]],"ltp":2.26,"tv":715.61,"id":60191231}]}]}
{"op":"mcm","clk":"11945306469","pt":1724453725120,"mc":[{"id":"1.232196998","rc":[{"batl":[[0,2.22,4],[1,2.24,4],[2,2.28,4]],"ltp":2.26,"tv":715.61,"id":60191231},{"batb":[[0,1.81,16.26]],"ltp":1.81,"tv":6197.64,"id":72963954}]}]}
{"op":"mcm","clk":"11945306485","pt":1724453725534,"mc":[{"id":"1.232196998","rc":[{"batb":[[1,1.8,40.77],[2,1.79,26.54]],"ltp":1.81,"tv":6197.64,"id":72963954}]}]}
{"op":"mcm","clk":"11945306555","pt":1724453727023,"mc":[{"id":"1.232196998","rc":[{"batb":[[0,2.16,4]],"batl":[[0,2.82,14.91],[1,2.24,0],[2,2.28,0]],"ltp":2.26,"tv":715.61,"id":60191231},{"batb":[[0,1.81,12.26],[2,1.79,22.54]],"ltp":1.81,"tv":6197.64,"id":72963954}]}]}
{"op":"mcm","clk":"11945306648","pt":1724453728920,"mc":[{"id":"1.232196998","rc":[{"batb":[[0,2.18,5],[1,2.16,4],[2,2.14,34.84]],"ltp":2.26,"tv":715.61,"id":60191231}]}]}
{"op":"mcm","clk":"11945306668","pt":1724453729430,"mc":[{"id":"1.232196998","rc":[{"batb":[[1,2.14,34.84],[2,2.06,102.83]],"ltp":2.26,"tv":715.61,"id":60191231}]}]}
{"op":"mcm","clk":"11945306817","pt":1724453732654,"mc":[{"id":"1.232196998","rc":[{"batb":[[0,2.16,4]],"ltp":2.26,"tv":715.61,"id":60191231}]}]}
{"op":"mcm","clk":"11945306883","pt":1724453733733,"mc":[{"id":"1.232196998","rc":[{"batl":[[0,1.94,227.07]],"ltp":1.81,"tv":6197.64,"id":72963954}]}]}
{"op":"mcm","clk":"11945306915","pt":1724453735015,"mc":[{"id":"1.232196998","rc":[{"batb":[[0,2.16,5]],"ltp":2.26,"tv":715.61,"id":60191231}]}]}
{"op":"mcm","clk":"11945307028","pt":1724453738543,"mc":[{"id":"1.232196998","rc":[{"batb":[[0,2.16,4]],"ltp":2.26,"tv":715.61,"id":60191231}]}]}
{"op":"mcm","clk":"11945307096","pt":1724453740236,"mc":[{"id":"1.232196998","rc":[{"batb":[[0,2.16,8]],"ltp":2.26,"tv":715.61,"id":60191231},{"batb":[[0,1.81,16.26]],"batl":[[0,1.87,4],[1,1.94,227.07],[2,1.99,36.04]],"ltp":1.81,"tv":6197.64,"id":72963954}]}]}
{"op":"mcm","clk":"11945307128","pt":1724453741055,"mc":[{"id":"1.232196998","rc":[{"batb":[[0,2.18,5],[1,2.16,4],[2,2.14,34.84]],"ltp":2.26,"tv":715.61,"id":60191231}]}]}
{"op":"mcm","clk":"11945307278","pt":1724453744243,"mc":[{"id":"1.232196998","rc":[{"batb":[[0,2.2,4]],"ltp":2.26,"tv":715.61,"id":60191231}]}]}
{"op":"mcm","clk":"11945307383","pt":1724453746240,"mc":[{"id":"1.232196998","rc":[{"batb":[[0,2.16,4],[1,2.14,34.84],[2,2.06,102.83]],"ltp":2.26,"tv":715.61,"id":60191231}]}]}
{"op":"mcm","clk":"11945307391","pt":1724453746344,"mc":[{"id":"1.232196998","rc":[{"batb":[[0,2.18,5],[1,2.16,4],[2,2.14,34.84]],"ltp":2.26,"tv":715.61,"id":60191231}]}]}
{"op":"mcm","clk":"11945307522","pt":1724453749180,"mc":[{"id":"1.232196998","rc":[{"batb":[[0,2.2,4],[1,2.18,5],[2,2.16,4]],"ltp":2.26,"tv":715.61,"id":60191231}]}]}
{"op":"mcm","clk":"11945307553","pt":1724453749647,"mc":[{"id":"1.232196998","rc":[{"batb":[[1,2.14,34.84],[2,2.06,102.83]],"ltp":2.26,"tv":715.61,"id":60191231},{"batl":[[0,1.94,227.07],[1,1.99,36.04],[2,2.08,5.14]],"ltp":1.81,"tv":6197.64,"id":72963954}]}]}
{"op":"mcm","clk":"11945307646","pt":1724453751861,"mc":[{"id":"1.232196998","rc":[{"batb":[[0,2.16,5]],"ltp":2.26,"tv":715.61,"id":60191231}]}]}
{"op":"mcm","clk":"11945307818","pt":1724453755088,"mc":[{"id":"1.232196998","rc":[{"batb":[[0,2.14,34.84],[1,2.06,102.83],[2,2.04,94.85]],"ltp":2.26,"tv":715.61,"id":60191231}]}]}
{"op":"mcm","clk":"11945307841","pt":1724453755447,"mc":[{"id":"1.232196998","rc":[{"batb":[[0,2.16,8],[1,2.14,34.84],[2,2.06,102.83]],"ltp":2.26,"tv":715.61,"id":60191231},{"batb":[[0,1.81,12.26]],"batl":[[0,1.87,4],[1,1.94,227.07],[2,1.99,36.04]],"ltp":1.81,"tv":6197.64,"id":72963954}]}]}
{"op":"mcm","clk":"11945307952","pt":1724453757751,"mc":[{"id":"1.232196998","rc":[{"batb":[[0,2.18,5],[1,2.16,4],[2,2.14,34.84]],"ltp":2.26,"tv":715.61,"id":60191231}]}]}
{"op":"mcm","clk":"11945308078","pt":1724453761287,"mc":[{"id":"1.232196998","rc":[{"batb":[[0,2.18,4]],"ltp":2.26,"tv":715.61,"id":60191231}]}]}
{"op":"mcm","clk":"11945308156","pt":1724453763294,"mc":[{"id":"1.232196998","rc":[{"batb":[[0,2.2,5],[1,2.18,4],[2,2.16,4]],"ltp":2.26,"tv":715.61,"id":60191231}]}]}
{"op":"mcm","clk":"11945308171","pt":1724453763757,"mc":[{"id":"1.232196998","rc":[{"batb":[[1,2.14,34.84],[2,2.06,102.83]],"ltp":2.26,"tv":715.61,"id":60191231},{"batl":[[0,1.94,227.07],[1,1.99,36.04],[2,2.08,5.14]],"ltp":1.81,"tv":6197.64,"id":72963954}]}]}
{"op":"mcm","clk":"11945308307","pt":1724453766682,"mc":[{"id":"1.232196998","rc":[{"batb":[[0,2.16,4]],"ltp":2.26,"tv":715.61,"id":60191231}]}]}
{"op":"mcm","clk":"11945308425","pt":1724453769096,"mc":[{"id":"1.232196998","rc":[{"batb":[[0,2.14,34.84],[1,2.06,102.83],[2,2.04,94.85]],"ltp":2.26,"tv":715.61,"id":60191231}]}]}
{"op":"mcm","clk":"11945308438","pt":1724453769300,"mc":[{"id":"1.232196998","rc":[{"batb":[[0,2.16,5],[1,2.14,34.84],[2,2.06,102.83]],"ltp":2.26,"tv":715.61,"id":60191231}]}]}
{"op":"mcm","clk":"11945308497","pt":1724453770479,"mc":[{"id":"1.232196998","rc":[{"batb":[[0,2.16,9]],"ltp":2.26,"tv":715.61,"id":60191231},{"batb":[[0,1.81,16.26]],"batl":[[0,1.87,4],[1,1.94,227.07],[2,1.99,36.04]],"ltp":1.81,"tv":6197.64,"id":72963954}]}]}
{"op":"mcm","clk":"11945308602","pt":1724453772686,"mc":[{"id":"1.232196998","rc":[{"batb":[[0,2.18,4],[1,2.16,4],[2,2.14,34.84]],"ltp":2.26,"tv":715.61,"id":60191231},{"batl":[[0,1.86,7.86],[1,1.87,4],[2,1.94,227.07]],"ltp":1.81,"tv":6197.64,"id":72963954}]}]}
{"op":"mcm","clk":"11945308637","pt":1724453773297,"mc":[{"id":"1.232196998","rc":[{"batl":[[1,1.94,227.07],[2,1.99,36.04]],"ltp":1.81,"tv":6197.64,"id":72963954}]}]}
{"op":"mcm","clk":"11945308727","pt":1724453775202,"mc":[{"id":"1.232196998","rc":[{"batb":[[0,2.18,5]],"ltp":2.26,"tv":715.61,"id":60191231}]}]}
{"op":"mcm","clk":"11945308893","pt":1724453778095,"mc":[{"id":"1.232196998","rc":[{"batb":[[0,2.2,4],[1,2.18,5]],"ltp":2.26,"tv":715.61,"id":60191231}]}]}
{"op":"mcm","clk":"11945308941","pt":1724453779175,"mc":[{"id":"1.232196998","rc":[{"batb":[[1,2.16,2.51]],"ltp":2.26,"tv":715.61,"id":60191231}]}]}
{"op":"mcm","clk":"11945308971","pt":1724453780099,"mc":[{"id":"1.232196998","rc":[{"batb":[[0,2.16,2.51],[1,2.14,34.84],[2,2.06,102.83]],"ltp":2.26,"tv":715.61,"id":60191231}]}]}
{"op":"mcm","clk":"11945309210","pt":1724453784990,"mc":[{"id":"1.232196998","rc":[{"batb":[[0,2.18,4],[1,2.16,2.51],[2,2.14,34.84]],"ltp":2.26,"tv":715.61,"id":60191231}]}]}
{"op":"mcm","clk":"11945309246","pt":1724453785610,"mc":[{"id":"1.232196998","rc":[{"batb":[[0,2.2,5],[1,2.18,8],[2,2.16,2.51]],"batl":[[0,2.22,4],[1,2.24,4],[2,2.82,14.91]],"ltp":2.26,"tv":715.61,"id":60191231}]}]}
{"op":"mcm","clk":"11945309338","pt":1724453787477,"mc":[{"id":"1.232196998","rc":[{"batb":[[1,2.18,4],[2,2.16,17.86]],"ltp":2.26,"tv":715.61,"id":60191231}]}]}
{"op":"mcm","clk":"11945309430","pt":1724453789283,"mc":[{"id":"1.232196998","rc":[{"batb":[[0,2.18,4],[1,2.16,2.51],[2,2.14,34.84]],"ltp":2.26,"tv":715.61,"id":60191231}]}]}
{"op":"mcm","clk":"11945310790","pt":1724453818122,"mc":[{"id":"1.232196998","rc":[{"batb":[[1,2.14,34.84],[2,2.06,102.83]],"ltp":2.26,"tv":715.61,"id":60191231}]}]}
{"op":"mcm","clk":"11945310851","pt":1724453819208,"mc":[{"id":"1.232196998","rc":[{"batb":[[0,2.16,9]],"batl":[[0,2.82,14.91],[1,2.24,0],[2,2.82,0]],"ltp":2.26,"tv":715.61,"id":60191231}]}]}
{"op":"mcm","clk":"11945310980","pt":1724453821530,"mc":[{"id":"1.232196998","rc":[{"batb":[[0,2.16,5]],"ltp":2.26,"tv":715.61,"id":60191231}]}]}
{"op":"mcm","clk":"11945311039","pt":1724453822520,"mc":[{"id":"1.232196998","rc":[{"batb":[[0,2.14,34.84],[1,2.06,102.83],[2,2.04,94.85]],"ltp":2.26,"tv":715.61,"id":60191231}]}]}
{"op":"mcm","clk":"11945311152","pt":1724453825042,"mc":[{"id":"1.232196998","rc":[{"batb":[[0,2.16,9],[1,2.14,34.84],[2,2.06,102.83]],"ltp":2.26,"tv":715.61,"id":60191231}]}]}
{"op":"mcm","clk":"11945311271","pt":1724453827260,"mc":[{"id":"1.232196998","rc":[{"batb":[[0,2.16,5]],"ltp":2.26,"tv":715.61,"id":60191231}]}]}
{"op":"mcm","clk":"11945311344","pt":1724453828240,"mc":[{"id":"1.232196998","rc":[{"batb":[[0,2.18,2.51]],"ltp":2.26,"tv":715.61,"id":60191231}]}]}
{"op":"mcm","clk":"11945311530","pt":1724453831026,"mc":[{"id":"1.232196998","rc":[{"batl":[[0,2.22,4],[1,2.24,4],[2,2.82,14.91]],"ltp":2.26,"tv":715.61,"id":60191231}]}]}
{"op":"mcm","clk":"11945311853","pt":1724453836840,"mc":[{"id":"1.232196998","rc":[{"batb":[[0,1.82,418.84],[1,1.81,16.26],[2,1.8,40.77]],"ltp":1.81,"tv":6197.64,"id":72963954}]}]}
{"op":"mcm","clk":"11945311921","pt":1724453837968,"mc":[{"id":"1.232196998","rc":[{"batb":[[0,1.83,12.14],[1,1.82,437.35],[2,1.81,4]],"ltp":1.81,"tv":6197.64,"id":72963954}]}]}
{"op":"mcm","clk":"11945311984","pt":1724453839351,"mc":[{"id":"1.232196998","rc":[{"batb":[[1,1.82,459.07]],"ltp":1.81,"tv":6197.64,"id":72963954}]}]}
{"op":"mcm","clk":"11945312332","pt":1724453846064,"mc":[{"id":"1.232196998","rc":[{"batb":[[0,1.83,16.14]],"ltp":1.81,"tv":6197.64,"id":72963954}]}]}
{"op":"mcm","clk":"11945312456","pt":1724453848473,"mc":[{"id":"1.232196998","rc":[{"trd":[[1.82,141.72],[1.83,1069.98]],"batb":[[0,1.82,388.21],[1,1.81,4],[2,1.8,22.26]],"ltp":1.82,"tv":6371.64,"id":72963954}],"tv":7087.25}]}
{"op":"mcm","clk":"11945313069","pt":1724453861176,"mc":[{"id":"1.232196998","rc":[{"batb":[[0,1.82,392.21]],"ltp":1.82,"tv":6371.64,"id":72963954}]}]}
{"op":"mcm","clk":"11945313243","pt":1724453864770,"mc":[{"id":"1.232196998","rc":[{"trd":[[1.82,333.74]],"batb":[[0,1.82,296.2]],"ltp":1.82,"tv":6563.66,"id":72963954}],"tv":7279.27}]}
{"op":"mcm","clk":"11945313510","pt":1724453870270,"mc":[{"id":"1.232196998","rc":[{"trd":[[1.82,525.76]],"batb":[[0,1.82,200.19]],"ltp":1.82,"tv":6755.68,"id":72963954}],"tv":7471.29}]}
{"op":"mcm","clk":"11945318495","pt":1724453951814,"mc":[{"id":"1.232196998","rc":[{"batb":[[0,1.82,44.23]],"ltp":1.82,"tv":6755.68,"id":72963954}]}]}
{"op":"mcm","clk":"11945318540","pt":1724453952484,"mc":[{"id":"1.232196998","rc":[{"batb":[[0,1.82,22.51],[1,1.81,25.99]],"ltp":1.82,"tv":6755.68,"id":72963954}]}]}
{"op":"mcm","clk":"11945318580","pt":1724453953406,"mc":[{"id":"1.232196998","rc":[{"batb":[[0,1.82,4],[1,1.81,44.5]],"ltp":1.82,"tv":6755.68,"id":72963954}]}]}
{"op":"mcm","clk":"11945318769","pt":1724453956792,"mc":[{"id":"1.232196998","rc":[{"trd":[[1.81,147.17],[1.82,533.76]],"batb":[[0,1.8,22.26],[1,1.79,22.54],[2,1.78,22.83]],"batl":[[0,1.82,32.94],[1,1.86,7.86],[2,1.94,227.07]],"ltp":1.81,"tv":6852.68,"id":72963954}],"tv":7568.29}]}
{"op":"mcm","clk":"11945318849","pt":1724453958032,"mc":[{"id":"1.232196998","rc":[{"batb":[[0,2.22,5],[1,2.2,4],[2,2.18,2.51]],"batl":[[0,2.82,14.91],[1,2.24,0],[2,2.82,0]],"ltp":2.26,"tv":715.61,"id":60191231},{"batb":[[0,1.75,69.19],[1,1.72,27.89],[2,1.71,227.07]],"ltp":1.81,"tv":6852.68,"id":72963954}]}]}
{"op":"mcm","clk":"11945318868","pt":1724453958394,"mc":[{"id":"1.232196998","rc":[{"batb":[[1,2.2,18.84]],"ltp":2.26,"tv":715.61,"id":60191231}]}]}
{"op":"mcm","clk":"11945318970","pt":1724453960336,"mc":[{"id":"1.232196998","rc":[{"batb":[[1,2.2,14.84]],"ltp":2.26,"tv":715.61,"id":60191231}]}]}
{"op":"mcm","clk":"11945319030","pt":1724453961820,"mc":[{"id":"1.232196998","rc":[{"batb":[[0,2.2,14.84],[1,2.18,2.51],[2,2.14,34.84]],"ltp":2.26,"tv":715.61,"id":60191231},{"batl":[[0,1.86,7.86],[1,1.94,227.07],[2,1.99,36.04]],"ltp":1.81,"tv":6852.68,"id":72963954}]}]}
{"op":"mcm","clk":"11945319054","pt":1724453962639,"mc":[{"id":"1.232196998","rc":[{"batb":[[0,2.2,4]],"ltp":2.26,"tv":715.61,"id":60191231}]}]}
{"op":"mcm","clk":"11945319122","pt":1724453963921,"mc":[{"id":"1.232196998","rc":[{"batb":[[0,2.22,5],[1,2.2,4],[2,2.18,2.51]],"ltp":2.26,"tv":715.61,"id":60191231}]}]}
{"op":"mcm","clk":"11945319166","pt":1724453964946,"mc":[{"id":"1.232196998","rc":[{"batb":[[1,2.18,2.51],[2,2.14,34.84]],"ltp":2.26,"tv":715.61,"id":60191231}]}]}
{"op":"mcm","clk":"11945319284","pt":1724453967106,"mc":[{"id":"1.232196998","rc":[{"batl":[[0,2.32,4],[1,2.34,4],[2,2.82,14.91]],"ltp":2.26,"tv":715.61,"id":60191231}]}]}
{"op":"mcm","clk":"11945319295","pt":1724453967312,"mc":[{"id":"1.232196998","rc":[{"batb":[[0,2.18,2.51],[1,2.14,34.84],[2,2.06,102.83]],"ltp":2.26,"tv":715.61,"id":60191231},{"batb":[[0,1.82,418.84],[1,1.75,69.19],[2,1.72,27.89]],"ltp":1.81,"tv":6852.68,"id":72963954}]}]}
{"op":"mcm","clk":"11945319380","pt":1724453969415,"mc":[{"id":"1.232196998","rc":[{"batb":[[1,1.81,21.99],[2,1.75,69.19]],"ltp":1.81,"tv":6852.68,"id":72963954}]}]}
{"op":"mcm","clk":"11945319725","pt":1724453975930,"mc":[{"id":"1.232196998","rc":[{"batb":[[0,1.81,21.99],[1,1.75,69.19],[2,1.72,27.89]],"ltp":1.81,"tv":6852.68,"id":72963954}]}]}
{"op":"mcm","clk":"11945319756","pt":1724453976543,"mc":[{"id":"1.232196998","rc":[{"batb":[[0,1.75,69.19],[1,1.72,27.89],[2,1.71,227.07]],"ltp":1.81,"tv":6852.68,"id":72963954}]}]}
{"op":"mcm","clk":"11945320023","pt":1724453981620,"mc":[{"id":"1.232196998","rc":[{"batl":[[0,1.84,1.34],[1,1.86,7.86],[2,1.94,227.07]],"ltp":1.81,"tv":6852.68,"id":72963954}]}]}
{"op":"mcm","clk":"11945320243","pt":1724453985422,"mc":[{"id":"1.232196998","rc":[{"batb":[[0,1.83,418.84],[1,1.75,69.19],[2,1.72,27.89]],"ltp":1.81,"tv":6852.68,"id":72963954}]}]}
{"op":"mcm","clk":"11945320384","pt":1724453988441,"mc":[{"id":"1.232196998","rc":[{"batb":[[1,1.82,21.72],[2,1.75,69.19]],"ltp":1.81,"tv":6852.68,"id":72963954}]}]}
{"op":"mcm","clk":"11945320509","pt":1724453991159,"mc":[{"id":"1.232196998","rc":[{"batb":[[1,2.14,50.78]],"ltp":2.26,"tv":715.61,"id":60191231},{"batb":[[0,1.83,437.35]],"ltp":1.81,"tv":6852.68,"id":72963954}]}]}
{"op":"mcm","clk":"11945320551","pt":1724453991978,"mc":[{"id":"1.232196998","rc":[{"trd":[[1.83,1262]],"batb":[[0,1.83,341.34]],"ltp":1.83,"tv":7044.7,"id":72963954}],"tv":7760.31}]}
{"op":"mcm","clk":"11945320820","pt":1724453997264,"mc":[{"id":"1.232196998","rc":[{"trd":[[1.83,1454.02]],"batb":[[0,1.83,245.33]],"ltp":1.83,"tv":7236.72,"id":72963954}],"tv":7952.33}]}
