{"op":"mcm","clk":"11783918893","pt":1722938085633,"mc":[{"id":"1.231501231","marketDefinition":{"bspMarket":false,"turnInPlayEnabled":true,"persistenceEnabled":true,"marketBaseRate":5.0,"eventId":"33472344","eventTypeId":"4","numberOfWinners":1,"bettingType":"ODDS","marketType":"MATCH_ODDS","marketTime":"2024-08-09T10:00:00.000Z","suspendTime":"2024-08-09T10:00:00.000Z","bspReconciled":false,"complete":true,"inPlay":false,"crossMatching":false,"runnersVoidable":false,"numberOfActiveRunners":2,"betDelay":0,"status":"OPEN","runners":[{"status":"ACTIVE","sortPriority":1,"id":31376,"name":"Essex"},{"status":"ACTIVE","sortPriority":2,"id":424676,"name":"Surrey"}],"regulators":["MR_INT"],"countryCode":"GB","discountAllowed":false,"timezone":"GMT","openDate":"2024-08-09T10:00:00.000Z","version":6059476906,"name":"Match Odds","eventName":"Essex v Surrey"},"rc":[{"batb":[[0,1.03,200],[1,1.02,200],[2,1.01,220]],"ltp":0.0,"tv":0.0,"id":424676},{"batb":[[0,1.03,200],[1,1.02,200],[2,1.01,220]],"ltp":0.0,"tv":0.0,"id":31376}]}]}
{"op":"mcm","clk":"11783918959","pt":1722938087005,"mc":[{"id":"1.231501231","marketDefinition":{"bspMarket":false,"turnInPlayEnabled":true,"persistenceEnabled":true,"marketBaseRate":5.0,"eventId":"33472344","eventTypeId":"4","numberOfWinners":1,"bettingType":"ODDS","marketType":"MATCH_ODDS","marketTime":"2024-08-09T10:00:00.000Z","suspendTime":"2024-08-09T10:00:00.000Z","bspReconciled":false,"complete":true,"inPlay":false,"crossMatching":false,"runnersVoidable":false,"numberOfActiveRunners":2,"betDelay":0,"status":"OPEN","runners":[{"status":"ACTIVE","sortPriority":1,"id":31376,"name":"Essex"},{"status":"ACTIVE","sortPriority":2,"id":424676,"name":"Surrey"}],"regulators":["MR_INT"],"countryCode":"GB","discountAllowed":true,"timezone":"GMT","openDate":"2024-08-09T10:00:00.000Z","version":6059476906,"name":"Match Odds","eventName":"Essex v Surrey"}}]}
{"op":"mcm","clk":"11784021891","pt":1722940246483,"mc":[{"id":"1.231501231","rc":[{"batb":[[2,1.01,480.48]],"ltp":0.0,"tv":0.0,"id":424676},{"batb":[[2,1.01,480.48]],"ltp":0.0,"tv":0.0,"id":31376}]}]}
{"op":"mcm","clk":"11784115897","pt":1722942455285,"mc":[{"id":"1.231501231","rc":[{"batb":[[2,1.01,488.7]],"ltp":0.0,"tv":0.0,"id":424676},{"batb":[[2,1.01,488.7]],"ltp":0.0,"tv":0.0,"id":31376}]}]}
{"op":"mcm","clk":"11784116327","pt":1722942467188,"mc":[{"id":"1.231501231","rc":[{"batb":[[1,1.02,207.88]],"ltp":0.0,"tv":0.0,"id":424676},{"batb":[[1,1.02,207.88]],"ltp":0.0,"tv":0.0,"id":31376}]}]}
{"op":"mcm","clk":"11784116858","pt":1722942480518,"mc":[{"id":"1.231501231","rc":[{"batb":[[0,1.03,207.88]],"ltp":0.0,"tv":0.0,"id":424676},{"batb":[[0,1.03,207.88]],"ltp":0.0,"tv":0.0,"id":31376}]}]}
{"op":"mcm","clk":"11784117081","pt":1722942485303,"mc":[{"id":"1.231501231","marketDefinition":{"bspMarket":false,"turnInPlayEnabled":true,"persistenceEnabled":true,"marketBaseRate":5.0,"eventId":"33472344","eventTypeId":"4","numberOfWinners":1,"bettingType":"ODDS","marketType":"MATCH_ODDS","marketTime":"2024-08-09T10:00:00.000Z","suspendTime":"2024-08-09T10:00:00.000Z","bspReconciled":false,"complete":true,"inPlay":false,"crossMatching":true,"runnersVoidable":false,"numberOfActiveRunners":2,"betDelay":0,"status":"OPEN","runners":[{"status":"ACTIVE","sortPriority":1,"id":31376,"name":"Essex"},{"status":"ACTIVE","sortPriority":2,"id":424676,"name":"Surrey"}],"regulators":["MR_INT"],"countryCode":"GB","discountAllowed":true,"timezone":"GMT","openDate":"2024-08-09T10:00:00.000Z","version":6059476906,"name":"Match Odds","eventName":"Essex v Surrey"}}]}
{"op":"mcm","clk":"11784117446","pt":1722942495963,"mc":[{"id":"1.231501231","rc":[{"batb":[[1,1.02,247.29]],"ltp":0.0,"tv":0.0,"id":424676},{"batb":[[1,1.02,247.29]],"ltp":0.0,"tv":0.0,"id":31376}]}]}
{"op":"mcm","clk":"11784118003","pt":1722942511281,"mc":[{"id":"1.231501231","rc":[{"batb":[[0,1.04,7.88],[1,1.03,207.88],[2,1.02,247.29]],"ltp":0.0,"tv":0.0,"id":424676},{"batb":[[0,1.04,7.88],[1,1.03,207.88],[2,1.02,247.29]],"ltp":0.0,"tv":0.0,"id":31376}]}]}
{"op":"mcm","clk":"11784118410","pt":1722942523368,"mc":[{"id":"1.231501231","rc":[{"batb":[[0,1.05,7.88],[1,1.04,7.88],[2,1.03,207.88]],"ltp":0.0,"tv":0.0,"id":424676},{"batb":[[0,1.05,7.88],[1,1.04,7.88],[2,1.03,207.88]],"ltp":0.0,"tv":0.0,"id":31376}]}]}
{"op":"mcm","clk":"11784119149","pt":1722942545930,"mc":[{"id":"1.231501231","rc":[{"batb":[[0,1.06,7.88],[1,1.05,7.88],[2,1.04,7.88]],"ltp":0.0,"tv":0.0,"id":424676},{"batb":[[0,1.06,7.88],[1,1.05,7.88],[2,1.04,7.88]],"ltp":0.0,"tv":0.0,"id":31376}]}]}
{"op":"mcm","clk":"11784119660","pt":1722942560312,"mc":[{"id":"1.231501231","rc":[{"batb":[[0,1.07,7.88],[1,1.06,7.88],[2,1.05,7.88]],"ltp":0.0,"tv":0.0,"id":424676},{"batb":[[0,1.07,7.88],[1,1.06,7.88],[2,1.05,7.88]],"ltp":0.0,"tv":0.0,"id":31376}]}]}
{"op":"mcm","clk":"11784120185","pt":1722942573848,"mc":[{"id":"1.231501231","rc":[{"batb":[[0,1.08,7.88],[1,1.07,7.88],[2,1.06,7.88]],"ltp":0.0,"tv":0.0,"id":424676},{"batb":[[0,1.08,7.88],[1,1.07,7.88],[2,1.06,7.88]],"ltp":0.0,"tv":0.0,"id":31376}]}]}
{"op":"mcm","clk":"11784490501","pt":1722949974892,"mc":[{"id":"1.231501231","rc":[{"batb":[[0,1.08,7.89],[1,1.07,7.89],[2,1.06,7.89]],"ltp":0.0,"tv":0.0,"id":424676},{"batb":[[0,1.08,7.89],[1,1.07,7.89],[2,1.06,7.89]],"ltp":0.0,"tv":0.0,"id":31376}]}]}
{"op":"mcm","clk":"11784840339","pt":1722955374919,"mc":[{"id":"1.231501231","rc":[{"batb":[[0,1.08,7.88],[1,1.07,7.88],[2,1.06,7.88]],"ltp":0.0,"tv":0.0,"id":424676},{"batb":[[0,1.08,7.88],[1,1.07,7.88],[2,1.06,7.88]],"ltp":0.0,"tv":0.0,"id":31376}]}]}
{"op":"mcm","clk":"11785389511","pt":1722960745940,"mc":[{"id":"1.231501231","rc":[{"batb":[[0,1.25,100],[1,1.08,7.88],[2,1.07,7.88]],"ltp":0.0,"tv":0.0,"id":424676},{"batb":[[0,1.25,100],[1,1.08,7.88],[2,1.07,7.88]],"ltp":0.0,"tv":0.0,"id":31376}]}]}
{"op":"mcm","clk":"11785415785","pt":1722960892567,"mc":[{"id":"1.231501231","rc":[{"batb":[[0,1.26,33.27],[1,1.25,100],[2,1.08,7.88]],"ltp":0.0,"tv":0.0,"id":424676},{"batb":[[0,1.26,33.27],[1,1.25,100],[2,1.08,7.88]],"ltp":0.0,"tv":0.0,"id":31376}]}]}
{"op":"mcm","clk":"11785574267","pt":1722962255208,"mc":[{"id":"1.231501231","rc":[{"batb":[[0,2.2,3.15],[1,1.26,33.27],[2,1.25,100]],"ltp":0.0,"tv":0.0,"id":424676},{"batb":[[0,1.76,4.97],[1,1.26,33.27],[2,1.25,100]],"ltp":0.0,"tv":0.0,"id":31376}]}]}
{"op":"mcm","clk":"11785627180","pt":1722962693414,"mc":[{"id":"1.231501231","rc":[{"batb":[[1,1.25,100],[2,1.08,7.88]],"ltp":0.0,"tv":0.0,"id":424676},{"batb":[[1,1.25,100],[2,1.08,7.88]],"ltp":0.0,"tv":0.0,"id":31376}]}]}
{"op":"mcm","clk":"11786066947","pt":1722966174907,"mc":[{"id":"1.231501231","rc":[{"batb":[[2,1.08,7.87]],"ltp":0.0,"tv":0.0,"id":424676},{"batb":[[2,1.08,7.87]],"ltp":0.0,"tv":0.0,"id":31376}]}]}
{"op":"mcm","clk":"11786820318","pt":1722971574893,"mc":[{"id":"1.231501231","rc":[{"batb":[[2,1.08,7.87]],"ltp":0.0,"tv":0.0,"id":424676},{"batb":[[2,1.08,7.87]],"ltp":0.0,"tv":0.0,"id":31376}]}]}
{"op":"mcm","clk":"11787284675","pt":1722976974889,"mc":[{"id":"1.231501231","rc":[{"batb":[[2,1.08,7.88]],"ltp":0.0,"tv":0.0,"id":424676},{"batb":[[2,1.08,7.88]],"ltp":0.0,"tv":0.0,"id":31376}]}]}
{"op":"mcm","clk":"11787509980","pt":1722982374929,"mc":[{"id":"1.231501231","rc":[{"batb":[[2,1.08,7.88]],"ltp":0.0,"tv":0.0,"id":424676},{"batb":[[2,1.08,7.88]],"ltp":0.0,"tv":0.0,"id":31376}]}]}
{"op":"mcm","clk":"11787761452","pt":1722987774980,"mc":[{"id":"1.231501231","rc":[{"batb":[[2,1.08,7.88]],"ltp":0.0,"tv":0.0,"id":424676},{"batb":[[2,1.08,7.88]],"ltp":0.0,"tv":0.0,"id":31376}]}]}
{"op":"mcm","clk":"11788108819","pt":1722993175006,"mc":[{"id":"1.231501231","rc":[{"batb":[[2,1.08,7.87]],"ltp":0.0,"tv":0.0,"id":424676},{"batb":[[2,1.08,7.87]],"ltp":0.0,"tv":0.0,"id":31376}]}]}
{"op":"mcm","clk":"11788411165","pt":1722998574997,"mc":[{"id":"1.231501231","rc":[{"batb":[[2,1.08,7.87]],"ltp":0.0,"tv":0.0,"id":424676},{"batb":[[2,1.08,7.87]],"ltp":0.0,"tv":0.0,"id":31376}]}]}
{"op":"mcm","clk":"11788630750","pt":1723003974977,"mc":[{"id":"1.231501231","rc":[{"batb":[[2,1.08,7.87]],"ltp":0.0,"tv":0.0,"id":424676},{"batb":[[2,1.08,7.87]],"ltp":0.0,"tv":0.0,"id":31376}]}]}
{"op":"mcm","clk":"11788827658","pt":1723009374932,"mc":[{"id":"1.231501231","rc":[{"batb":[[2,1.08,7.87]],"ltp":0.0,"tv":0.0,"id":424676},{"batb":[[2,1.08,7.87]],"ltp":0.0,"tv":0.0,"id":31376}]}]}
{"op":"mcm","clk":"11788984670","pt":1723013588410,"mc":[{"id":"1.231501231","rc":[{"batb":[[1,1.74,17.32],[2,1.25,100]],"ltp":0.0,"tv":0.0,"id":424676},{"batb":[[1,1.74,17.32],[2,1.25,100]],"ltp":0.0,"tv":0.0,"id":31376}]}]}
{"op":"mcm","clk":"11789041642","pt":1723014841944,"mc":[{"id":"1.231501231","rc":[{"batl":[[0,5,1.01]],"ltp":0.0,"tv":0.0,"id":31376}]}]}
{"op":"mcm","clk":"11789041891","pt":1723014847239,"mc":[{"id":"1.231501231","rc":[{"batl":[[0,5,1.07]],"ltp":0.0,"tv":0.0,"id":31376}]}]}
{"op":"mcm","clk":"11789042093","pt":1723014851529,"mc":[{"id":"1.231501231","rc":[{"batl":[[0,5,1.11]],"ltp":0.0,"tv":0.0,"id":31376}]}]}
{"op":"mcm","clk":"11789042341","pt":1723014856440,"mc":[{"id":"1.231501231","rc":[{"batl":[[0,5,0.1]],"ltp":0.0,"tv":0.0,"id":31376}]}]}
{"op":"mcm","clk":"11789044155","pt":1723014899695,"mc":[{"id":"1.231501231","rc":[{"batb":[[0,1.8,1.07],[1,1.76,4.97],[2,1.74,17.32]],"ltp":0.0,"tv":0.0,"id":31376}]}]}
{"op":"mcm","clk":"11789046930","pt":1723014954531,"mc":[{"id":"1.231501231","rc":[{"batb":[[0,1.76,4.97],[1,1.74,17.32],[2,1.25,100]],"ltp":0.0,"tv":0.0,"id":31376}]}]}
{"op":"mcm","clk":"11789048481","pt":1723014986064,"mc":[{"id":"1.231501231","rc":[{"batl":[[0,5,1.01]],"ltp":0.0,"tv":0.0,"id":31376}]}]}
{"op":"mcm","clk":"11789048670","pt":1723014990057,"mc":[{"id":"1.231501231","rc":[{"batl":[[0,5,1.07]],"ltp":0.0,"tv":0.0,"id":31376}]}]}
{"op":"mcm","clk":"11789048926","pt":1723014994470,"mc":[{"id":"1.231501231","rc":[{"batl":[[0,5,1.11]],"ltp":0.0,"tv":0.0,"id":31376}]}]}
{"op":"mcm","clk":"11789049265","pt":1723015000889,"mc":[{"id":"1.231501231","rc":[{"batl":[[0,5,0.1]],"ltp":0.0,"tv":0.0,"id":31376}]}]}
{"op":"mcm","clk":"11789050299","pt":1723015020830,"mc":[{"id":"1.231501231","rc":[{"batb":[[0,1.8,1.07],[1,1.76,4.97],[2,1.74,17.32]],"ltp":0.0,"tv":0.0,"id":31376}]}]}
{"op":"mcm","clk":"11789050633","pt":1723015026601,"mc":[{"id":"1.231501231","rc":[{"trd":[[1.8,0.12]],"batb":[[0,1.8,1.01]],"batl":[[0,5,0.04]],"ltp":1.8,"tv":0.12,"id":31376}],"tv":0.12}]}
{"op":"mcm","clk":"11789053636","pt":1723015088278,"mc":[{"id":"1.231501231","rc":[{"batb":[[0,1.79,1.01]],"ltp":1.8,"tv":0.12,"id":31376}]}]}
{"op":"mcm","clk":"11789054583","pt":1723015109645,"mc":[{"id":"1.231501231","rc":[{"batb":[[0,1.78,1.01]],"ltp":1.8,"tv":0.12,"id":31376}]}]}
{"op":"mcm","clk":"11789055594","pt":1723015132145,"mc":[{"id":"1.231501231","rc":[{"batb":[[0,1.79,1.01]],"ltp":1.8,"tv":0.12,"id":31376}]}]}
{"op":"mcm","clk":"11789057541","pt":1723015172612,"mc":[{"id":"1.231501231","rc":[{"batb":[[0,1.8,1.01]],"ltp":1.8,"tv":0.12,"id":31376}]}]}
{"op":"mcm","clk":"11789063285","pt":1723015321579,"mc":[{"id":"1.231501231","rc":[{"batb":[[0,1.8,2.09]],"ltp":1.8,"tv":0.12,"id":31376}]}]}
{"op":"mcm","clk":"11789069700","pt":1723015493525,"mc":[{"id":"1.231501231","rc":[{"trd":[[2.2,1.19]],"batb":[[0,2.2,1.96]],"ltp":2.2,"tv":1.19,"id":424676},{"trd":[[1.84,1.42]],"batb":[[0,1.8,1.07]],"ltp":1.84,"tv":1.53,"id":31376}],"tv":2.72}]}
{"op":"mcm","clk":"11789069733","pt":1723015494444,"mc":[{"id":"1.231501231","rc":[{"batb":[[0,2.2,3.15]],"ltp":2.2,"tv":1.19,"id":424676}]}]}
{"op":"mcm","clk":"11789072122","pt":1723015560758,"mc":[{"id":"1.231501231","rc":[{"trd":[[2.2,2.09]],"batb":[[0,2.2,2.25]],"ltp":2.2,"tv":2.09,"id":424676},{"trd":[[1.84,2.49]],"batb":[[0,1.76,4.97],[1,1.74,17.32],[2,1.25,100]],"ltp":1.84,"tv":2.61,"id":31376}],"tv":4.7}]}
{"op":"mcm","clk":"11789072281","pt":1723015564702,"mc":[{"id":"1.231501231","rc":[{"batb":[[0,2.2,3.15]],"ltp":2.2,"tv":2.09,"id":424676}]}]}
{"op":"mcm","clk":"11789075419","pt":1723015652890,"mc":[{"id":"1.231501231","rc":[{"batl":[[0,5,2.15]],"ltp":1.84,"tv":2.61,"id":31376}]}]}
{"op":"mcm","clk":"11789076555","pt":1723015683258,"mc":[{"id":"1.231501231","rc":[{"batl":[[0,5.1,2.15]],"ltp":1.84,"tv":2.61,"id":31376}]}]}
{"op":"mcm","clk":"11789077093","pt":1723015698477,"mc":[{"id":"1.231501231","rc":[{"batl":[[0,5.1,1.07]],"ltp":1.84,"tv":2.61,"id":31376}]}]}
{"op":"mcm","clk":"11789077846","pt":1723015718279,"mc":[{"id":"1.231501231","rc":[{"batl":[[0,5,1.07]],"ltp":1.84,"tv":2.61,"id":31376}]}]}
{"op":"mcm","clk":"11789078219","pt":1723015726473,"mc":[{"id":"1.231501231","rc":[{"batl":[[0,5.1,1.07]],"ltp":1.84,"tv":2.61,"id":31376}]}]}
{"op":"mcm","clk":"11789079018","pt":1723015744336,"mc":[{"id":"1.231501231","rc":[{"batl":[[0,5.1,2.15]],"ltp":1.84,"tv":2.61,"id":31376}]}]}
{"op":"mcm","clk":"11789080103","pt":1723015770641,"mc":[{"id":"1.231501231","rc":[{"trd":[[1.76,4.29]],"batb":[[0,1.76,2.83]],"ltp":1.76,"tv":6.9,"id":31376}],"tv":8.99}]}
{"op":"mcm","clk":"11789080306","pt":1723015775543,"mc":[{"id":"1.231501231","rc":[{"batb":[[0,1.76,4.97]],"ltp":1.76,"tv":6.9,"id":31376}]}]}
{"op":"mcm","clk":"11789312109","pt":1723020174932,"mc":[{"id":"1.231501231","rc":[{"trd":[[1.76,4.29],[1.84,2.5]],"ltp":1.76,"tv":6.9,"id":31376}],"tv":8.99}]}
{"op":"mcm","clk":"11789600200","pt":1723024802110,"mc":[{"id":"1.231501231","rc":[{"batb":[[0,2.2,31.52]],"ltp":2.2,"tv":2.09,"id":424676},{"trd":[[1.76,4.29],[1.84,2.49]],"batb":[[0,1.76,49.76]],"ltp":1.76,"tv":6.9,"id":31376}],"tv":8.99}]}
{"op":"mcm","clk":"11789666304","pt":1723025574912,"mc":[{"id":"1.231501231","rc":[{"trd":[[1.76,4.29],[1.84,2.49]],"ltp":1.76,"tv":6.9,"id":31376}],"tv":8.99}]}
{"op":"mcm","clk":"11790072356","pt":1723030974922,"mc":[{"id":"1.231501231","rc":[{"trd":[[1.76,4.29],[1.84,2.49]],"ltp":1.76,"tv":6.89,"id":31376}],"tv":8.98}]}
{"op":"mcm","clk":"11790403569","pt":1723036374906,"mc":[{"id":"1.231501231","rc":[{"trd":[[1.76,4.29],[1.84,2.49]],"ltp":1.76,"tv":6.89,"id":31376}],"tv":8.98}]}
{"op":"mcm","clk":"11790645313","pt":1723040507797,"mc":[{"id":"1.231501231","rc":[{"batb":[[0,2.2,37]],"ltp":2.2,"tv":2.09,"id":424676},{"trd":[[1.84,2.49]],"batb":[[0,1.76,58.43]],"ltp":1.76,"tv":6.89,"id":31376}],"tv":8.98}]}
{"op":"mcm","clk":"11791708231","pt":1723051236443,"mc":[{"id":"1.231501231","rc":[{"trd":[[1.76,8.29],[1.84,2.49]],"batb":[[0,1.76,56.43]],"ltp":1.76,"tv":10.9,"id":31376}],"tv":12.99}]}
{"op":"mcm","clk":"11791708779","pt":1723051240461,"mc":[{"id":"1.231501231","rc":[{"batb":[[0,1.76,58.43]],"ltp":1.76,"tv":10.9,"id":31376}]}]}
{"op":"mcm","clk":"11792719511","pt":1723057974912,"mc":[{"id":"1.231501231","rc":[{"trd":[[1.76,8.29],[1.84,2.5]],"ltp":1.76,"tv":10.91,"id":31376}],"tv":13.0}]}
{"op":"mcm","clk":"11792964679","pt":1723060422382,"mc":[{"id":"1.231501231","rc":[{"batb":[[1,1.74,1]],"ltp":2.2,"tv":2.09,"id":424676},{"batb":[[1,1.74,1]],"ltp":1.76,"tv":10.91,"id":31376}]}]}
{"op":"mcm","clk":"11793007714","pt":1723061060231,"mc":[{"id":"1.231501231","tv":12.99}]}
{"op":"mcm","clk":"11793346264","pt":1723068774931,"mc":[{"id":"1.231501231","tv":12.99}]}
{"op":"mcm","clk":"11793632628","pt":1723074174910,"mc":[{"id":"1.231501231","rc":[{"trd":[[1.76,8.29],[1.84,2.5]],"ltp":1.76,"tv":10.91,"id":31376}],"tv":13.0}]}
{"op":"mcm","clk":"11793955072","pt":1723079574946,"mc":[{"id":"1.231501231","rc":[{"trd":[[1.76,8.3],[1.84,2.5]],"ltp":1.76,"tv":10.91,"id":31376}],"tv":13.0}]}
{"op":"mcm","clk":"11794173701","pt":1723084220758,"mc":[{"id":"1.231501231","marketDefinition":{"bspMarket":false,"turnInPlayEnabled":true,"persistenceEnabled":true,"marketBaseRate":5.0,"eventId":"33472344","eventTypeId":"4","numberOfWinners":1,"bettingType":"ODDS","marketType":"MATCH_ODDS","marketTime":"2024-08-09T13:00:00.000Z","suspendTime":"2024-08-09T13:00:00.000Z","bspReconciled":false,"complete":true,"inPlay":false,"crossMatching":true,"runnersVoidable":false,"numberOfActiveRunners":2,"betDelay":0,"status":"OPEN","runners":[{"status":"ACTIVE","sortPriority":1,"id":31376,"name":"Essex"},{"status":"ACTIVE","sortPriority":2,"id":424676,"name":"Surrey"}],"regulators":["MR_INT"],"countryCode":"GB","discountAllowed":true,"timezone":"GMT","openDate":"2024-08-09T10:00:00.000Z","version":6061568456,"name":"Match Odds","eventName":"Essex v Surrey"}}]}
{"op":"mcm","clk":"11794173721","pt":1723084221760,"mc":[{"id":"1.231501231","marketDefinition":{"bspMarket":false,"turnInPlayEnabled":true,"persistenceEnabled":true,"marketBaseRate":5.0,"eventId":"33472344","eventTypeId":"4","numberOfWinners":1,"bettingType":"ODDS","marketType":"MATCH_ODDS","marketTime":"2024-08-09T13:00:00.000Z","suspendTime":"2024-08-09T13:00:00.000Z","bspReconciled":false,"complete":true,"inPlay":false,"crossMatching":true,"runnersVoidable":false,"numberOfActiveRunners":2,"betDelay":0,"status":"OPEN","runners":[{"status":"ACTIVE","sortPriority":1,"id":31376,"name":"Essex"},{"status":"ACTIVE","sortPriority":2,"id":424676,"name":"Surrey"}],"regulators":["MR_INT"],"countryCode":"GB","discountAllowed":true,"timezone":"GMT","openDate":"2024-08-09T13:00:00.000Z","version":6061568456,"name":"Match Odds","eventName":"Essex v Surrey"}}]}
{"op":"mcm","clk":"11794201737","pt":1723084974928,"mc":[{"id":"1.231501231","rc":[{"trd":[[1.76,8.29],[1.84,2.5]],"ltp":1.76,"tv":10.91,"id":31376}],"tv":13.0}]}
{"op":"mcm","clk":"11794394311","pt":1723090374932,"mc":[{"id":"1.231501231","rc":[{"trd":[[1.76,8.29],[1.84,2.5]],"ltp":1.76,"tv":10.91,"id":31376}],"tv":13.0}]}
{"op":"mcm","clk":"11794496310","pt":1723093243897,"mc":[{"id":"1.231501231","rc":[{"trd":[[1.76,11.05],[1.84,2.5]],"batb":[[0,1.76,57.05]],"ltp":1.76,"tv":13.67,"id":31376}],"tv":15.76}]}
{"op":"mcm","clk":"11794496390","pt":1723093246174,"mc":[{"id":"1.231501231","rc":[{"batb":[[0,1.76,58.43]],"ltp":1.76,"tv":13.67,"id":31376}]}]}
{"op":"mcm","clk":"11794812592","pt":1723101174943,"mc":[{"id":"1.231501231","rc":[{"trd":[[1.76,11.05],[1.84,2.49]],"ltp":1.76,"tv":13.66,"id":31376}],"tv":15.75}]}
{"op":"mcm","clk":"11794902059","pt":1723103209982,"mc":[{"id":"1.231501231","rc":[{"batb":[[0,1.79,1.65],[1,1.76,58.43],[2,1.74,1]],"ltp":1.76,"tv":13.66,"id":31376}]}]}
{"op":"mcm","clk":"11795044921","pt":1723106574939,"mc":[{"id":"1.231501231","rc":[{"trd":[[1.76,11.05],[1.84,2.5]],"ltp":1.76,"tv":13.67,"id":31376}],"tv":15.76}]}
{"op":"mcm","clk":"11795310193","pt":1723111974908,"mc":[{"id":"1.231501231","rc":[{"trd":[[1.76,11.06],[1.84,2.5]],"ltp":1.76,"tv":13.67,"id":31376}],"tv":15.76}]}
{"op":"mcm","clk":"11795615937","pt":1723117374961,"mc":[{"id":"1.231501231","rc":[{"trd":[[1.76,11.05],[1.84,2.5]],"ltp":1.76,"tv":13.67,"id":31376}],"tv":15.76}]}
{"op":"mcm","clk":"11795875080","pt":1723122774947,"mc":[{"id":"1.231501231","rc":[{"trd":[[1.76,11.06],[1.84,2.5]],"ltp":1.76,"tv":13.67,"id":31376}],"tv":15.76}]}
{"op":"mcm","clk":"11796080801","pt":1723126908942,"mc":[{"id":"1.231501231","rc":[{"batb":[[0,2.2,31.59]],"ltp":2.2,"tv":2.09,"id":424676},{"trd":[[1.76,11.05],[1.84,2.49]],"batb":[[1,1.76,49.88]],"ltp":1.76,"tv":13.66,"id":31376}],"tv":15.75}]}
{"op":"mcm","clk":"11796423675","pt":1723132043933,"mc":[{"id":"1.231501231","rc":[{"trd":[[1.76,107.75],[1.79,3.3],[1.84,2.49]],"batb":[[0,1.76,1.53],[1,1.74,1],[2,1.25,100]],"ltp":1.76,"tv":113.66,"id":31376}],"tv":115.75}]}
{"op":"mcm","clk":"11796423950","pt":1723132047316,"mc":[{"id":"1.231501231","rc":[{"batb":[[0,1.74,1],[1,1.72,52.65]],"ltp":1.76,"tv":113.66,"id":31376}]}]}
{"op":"mcm","clk":"11796447998","pt":1723132364025,"mc":[{"id":"1.231501231","rc":[{"batb":[[2,1.08,7.86]],"ltp":2.2,"tv":2.09,"id":424676},{"batb":[[2,1.08,7.86]],"ltp":1.76,"tv":113.66,"id":31376}]}]}
{"op":"mcm","clk":"11796450140","pt":1723132389935,"mc":[{"id":"1.231501231","rc":[{"batb":[[2,1.43,116.28]],"ltp":2.2,"tv":2.09,"id":424676},{"batb":[[2,1.48,104.17]],"ltp":1.76,"tv":113.66,"id":31376}]}]}
{"op":"mcm","clk":"11796450163","pt":1723132390148,"mc":[{"id":"1.231501231","rc":[{"batb":[[2,1.53,94.34]],"ltp":2.2,"tv":2.09,"id":424676},{"batb":[[2,1.53,94.34]],"ltp":1.76,"tv":113.66,"id":31376}]}]}
{"op":"mcm","clk":"11796454664","pt":1723132454912,"mc":[{"id":"1.231501231","rc":[{"batb":[[2,1.48,104.17]],"ltp":1.76,"tv":113.66,"id":31376}]}]}
{"op":"mcm","clk":"11796454894","pt":1723132458529,"mc":[{"id":"1.231501231","rc":[{"batb":[[2,1.48,104.17]],"ltp":2.2,"tv":2.09,"id":424676}]}]}
{"op":"mcm","clk":"11796558927","pt":1723133574996,"mc":[{"id":"1.231501231","rc":[{"trd":[[1.76,107.74],[1.84,2.49]],"ltp":1.76,"tv":113.65,"id":31376}],"tv":115.74}]}
{"op":"mcm","clk":"11796676308","pt":1723134762626,"mc":[{"id":"1.231501231","rc":[{"batl":[[0,1.82,50]],"ltp":1.76,"tv":113.65,"id":31376}]}]}
{"op":"mcm","clk":"11796783507","pt":1723135818522,"mc":[{"id":"1.231501231","rc":[{"trd":[[2.2,42.09]],"batb":[[0,2.2,11.59]],"ltp":2.2,"tv":42.09,"id":424676}],"tv":155.74}]}
{"op":"mcm","clk":"11796783824","pt":1723135821917,"mc":[{"id":"1.231501231","rc":[{"batb":[[0,2.2,31.59]],"ltp":2.2,"tv":42.09,"id":424676}]}]}
{"op":"mcm","clk":"11796917529","pt":1723137181099,"mc":[{"id":"1.231501231","rc":[{"batl":[[0,1.9,100]],"ltp":1.76,"tv":113.65,"id":31376}]}]}
{"op":"mcm","clk":"11796918138","pt":1723137185525,"mc":[{"id":"1.231501231","rc":[{"batl":[[1,1.91,200]],"ltp":1.76,"tv":113.65,"id":31376}]}]}
{"op":"mcm","clk":"11796918996","pt":1723137191731,"mc":[{"id":"1.231501231","rc":[{"batl":[[2,1.92,300]],"ltp":1.76,"tv":113.65,"id":31376}]}]}
{"op":"mcm","clk":"11797016865","pt":1723138170978,"mc":[{"id":"1.231501231","rc":[{"batb":[[1,1.73,30],[2,1.72,52.65]],"ltp":1.76,"tv":113.65,"id":31376}]}]}
{"op":"mcm","clk":"11797017717","pt":1723138179923,"mc":[{"id":"1.231501231","rc":[{"batl":[[0,1.84,21.9],[1,1.9,100],[2,1.91,200]],"ltp":1.76,"tv":113.65,"id":31376}]}]}
{"op":"mcm","clk":"11797018014","pt":1723138182859,"mc":[{"id":"1.231501231","rc":[{"batl":[[0,1.86,21.9]],"ltp":1.76,"tv":113.65,"id":31376}]}]}
{"op":"mcm","clk":"11797069408","pt":1723138694330,"mc":[{"id":"1.231501231","rc":[{"batl":[[0,1.82,2],[1,1.86,21.9],[2,1.9,100]],"ltp":1.76,"tv":113.65,"id":31376}]}]}
{"op":"mcm","clk":"11797509867","pt":1723141953232,"mc":[{"id":"1.231501231","rc":[{"trd":[[2.2,62.09]],"batb":[[0,2.2,21.59]],"ltp":2.2,"tv":62.09,"id":424676},{"trd":[[1.84,2.49]],"ltp":1.76,"tv":113.65,"id":31376}],"tv":175.74}]}
{"op":"mcm","clk":"11797510093","pt":1723141954629,"mc":[{"id":"1.231501231","rc":[{"batb":[[0,2.2,31.59]],"ltp":2.2,"tv":62.09,"id":424676}]}]}
{"op":"mcm","clk":"11797866022","pt":1723144374977,"mc":[{"id":"1.231501231","rc":[{"trd":[[1.84,2.49]],"ltp":1.76,"tv":113.64,"id":31376}],"tv":175.73}]}
{"op":"mcm","clk":"11797908563","pt":1723144604344,"mc":[{"id":"1.231501231","rc":[{"batl":[[2,1.89,4.55]],"ltp":1.76,"tv":113.64,"id":31376}]}]}
{"op":"mcm","clk":"11797917272","pt":1723144666418,"mc":[{"id":"1.231501231","rc":[{"batb":[[1,2.02,4.55],[2,1.74,1]],"ltp":2.2,"tv":62.09,"id":424676}]}]}
{"op":"mcm","clk":"11797919257","pt":1723144681403,"mc":[{"id":"1.231501231","rc":[{"batb":[[2,1.91,4.55]],"ltp":2.2,"tv":62.09,"id":424676}]}]}
{"op":"mcm","clk":"11797924130","pt":1723144713367,"mc":[{"id":"1.231501231","rc":[{"batl":[[0,2.7,4.55]],"ltp":2.2,"tv":62.09,"id":424676}]}]}
{"op":"mcm","clk":"11797926764","pt":1723144731356,"mc":[{"id":"1.231501231","rc":[{"batl":[[1,2.9,4.55]],"ltp":2.2,"tv":62.09,"id":424676}]}]}
{"op":"mcm","clk":"11797957335","pt":1723144959405,"mc":[{"id":"1.231501231","rc":[{"batl":[[0,1.81,1.33],[1,1.82,2],[2,1.86,21.9]],"ltp":1.76,"tv":113.64,"id":31376}]}]}
{"op":"mcm","clk":"11798297253","pt":1723147801662,"mc":[{"id":"1.231501231","rc":[{"trd":[[2.2,68.57],[2.22,1.08]],"batb":[[0,2.2,28.35],[1,2.02,4.55],[2,1.91,4.55]],"batl":[[0,2.7,4.55],[1,2.9,4.55]],"ltp":2.2,"tv":69.64,"id":424676},{"trd":[[1.81,1.33]],"batl":[[0,1.82,2],[1,1.86,21.9],[2,1.89,4.55]],"ltp":1.81,"tv":114.97,"id":31376}],"tv":184.62}]}
{"op":"mcm","clk":"11798297539","pt":1723147805313,"mc":[{"id":"1.231501231","rc":[{"batb":[[0,2.2,31.59]],"ltp":2.2,"tv":69.64,"id":424676}]}]}
{"op":"mcm","clk":"11798351015","pt":1723148559537,"mc":[{"id":"1.231501231","rc":[{"batb":[[0,1.8,2],[1,1.74,1],[2,1.73,30]],"ltp":1.81,"tv":114.97,"id":31376}]}]}
{"op":"mcm","clk":"11798556159","pt":1723152658049,"mc":[{"id":"1.231501231","rc":[{"batb":[[0,2.22,14],[1,2.2,31.59],[2,2.02,4.55]],"batl":[[0,2.7,4.55],[1,2.9,4.55]],"ltp":2.2,"tv":69.64,"id":424676},{"batl":[[2,1.89,4.55]],"ltp":1.81,"tv":114.97,"id":31376}],"tv":184.62}]}
{"op":"mcm","clk":"11798556306","pt":1723152661283,"mc":[{"id":"1.231501231","rc":[{"batb":[[0,2.22,10]],"ltp":2.2,"tv":69.64,"id":424676}]}]}
{"op":"mcm","clk":"11798556348","pt":1723152662256,"mc":[{"id":"1.231501231","rc":[{"batb":[[0,2.2,31.59],[1,2.02,4.55],[2,1.91,4.55]],"ltp":2.2,"tv":69.64,"id":424676}]}]}
{"op":"mcm","clk":"11798556432","pt":1723152663847,"mc":[{"id":"1.231501231","rc":[{"batb":[[0,2.22,4],[1,2.2,31.59],[2,2.02,4.55]],"ltp":2.2,"tv":69.64,"id":424676}]}]}
{"op":"mcm","clk":"11798556485","pt":1723152665076,"mc":[{"id":"1.231501231","rc":[{"batb":[[0,2.24,10],[1,2.22,4],[2,2.2,31.59]],"ltp":2.2,"tv":69.64,"id":424676}]}]}
{"op":"mcm","clk":"11798556533","pt":1723152666253,"mc":[{"id":"1.231501231","rc":[{"batb":[[1,2.2,31.59],[2,2.02,4.55]],"ltp":2.2,"tv":69.64,"id":424676}]}]}
{"op":"mcm","clk":"11798556638","pt":1723152668572,"mc":[{"id":"1.231501231","rc":[{"batb":[[0,2.22,4]],"ltp":2.2,"tv":69.64,"id":424676}]}]}
{"op":"mcm","clk":"11798556755","pt":1723152670986,"mc":[{"id":"1.231501231","rc":[{"batb":[[0,2.2,31.59],[1,2.02,4.55],[2,1.91,4.55]],"ltp":2.2,"tv":69.64,"id":424676}]}]}
{"op":"mcm","clk":"11798556759","pt":1723152671088,"mc":[{"id":"1.231501231","rc":[{"batb":[[0,2.22,10],[1,2.2,31.59],[2,2.02,4.55]],"ltp":2.2,"tv":69.64,"id":424676}]}]}
{"op":"mcm","clk":"11798556919","pt":1723152674578,"mc":[{"id":"1.231501231","rc":[{"batb":[[0,2.22,4]],"ltp":2.2,"tv":69.64,"id":424676}]}]}
{"op":"mcm","clk":"11798557023","pt":1723152676889,"mc":[{"id":"1.231501231","rc":[{"batb":[[0,2.22,10]],"ltp":2.2,"tv":69.64,"id":424676}]}]}
{"op":"mcm","clk":"11798557162","pt":1723152679765,"mc":[{"id":"1.231501231","rc":[{"batb":[[0,2.24,4],[1,2.22,10],[2,2.2,31.59]],"ltp":2.2,"tv":69.64,"id":424676}]}]}
{"op":"mcm","clk":"11798557182","pt":1723152680072,"mc":[{"id":"1.231501231","rc":[{"batb":[[1,2.2,31.59],[2,2.02,4.55]],"ltp":2.2,"tv":69.64,"id":424676}]}]}
{"op":"mcm","clk":"11798557310","pt":1723152682383,"mc":[{"id":"1.231501231","rc":[{"batb":[[0,2.22,10]],"ltp":2.2,"tv":69.64,"id":424676}]}]}
{"op":"mcm","clk":"11798557438","pt":1723152685771,"mc":[{"id":"1.231501231","rc":[{"batb":[[0,2.22,4]],"ltp":2.2,"tv":69.64,"id":424676}]}]}
{"op":"mcm","clk":"11798557550","pt":1723152688286,"mc":[{"id":"1.231501231","rc":[{"batb":[[0,2.22,10]],"ltp":2.2,"tv":69.64,"id":424676}]}]}
{"op":"mcm","clk":"11798557645","pt":1723152690592,"mc":[{"id":"1.231501231","rc":[{"batb":[[0,2.24,4],[1,2.22,10],[2,2.2,31.59]],"ltp":2.2,"tv":69.64,"id":424676}]}]}
{"op":"mcm","clk":"11798557697","pt":1723152691570,"mc":[{"id":"1.231501231","rc":[{"batb":[[1,2.2,31.59],[2,2.02,4.55]],"ltp":2.2,"tv":69.64,"id":424676}]}]}
{"op":"mcm","clk":"11798557765","pt":1723152692978,"mc":[{"id":"1.231501231","rc":[{"batb":[[0,2.2,31.59],[1,2.02,4.55],[2,1.91,4.55]],"ltp":2.2,"tv":69.64,"id":424676}]}]}
{"op":"mcm","clk":"11798557910","pt":1723152695293,"mc":[{"id":"1.231501231","rc":[{"batb":[[0,2.24,4],[1,2.22,10],[2,2.2,31.59]],"ltp":2.2,"tv":69.64,"id":424676}]}]}
{"op":"mcm","clk":"11798558020","pt":1723152697610,"mc":[{"id":"1.231501231","rc":[{"batb":[[0,2.22,10],[1,2.2,31.59],[2,2.02,4.55]],"ltp":2.2,"tv":69.64,"id":424676}]}]}
{"op":"mcm","clk":"11798558058","pt":1723152698484,"mc":[{"id":"1.231501231","rc":[{"batb":[[0,2.2,31.59],[1,2.02,4.55],[2,1.91,4.55]],"ltp":2.2,"tv":69.64,"id":424676}]}]}
{"op":"mcm","clk":"11798558166","pt":1723152700994,"mc":[{"id":"1.231501231","rc":[{"batb":[[0,2.22,14],[1,2.2,31.59],[2,2.02,4.55]],"ltp":2.2,"tv":69.64,"id":424676}]}]}
{"op":"mcm","clk":"11798558263","pt":1723152703408,"mc":[{"id":"1.231501231","rc":[{"batb":[[0,2.22,10]],"ltp":2.2,"tv":69.64,"id":424676}]}]}
{"op":"mcm","clk":"11798558295","pt":1723152704387,"mc":[{"id":"1.231501231","rc":[{"batb":[[0,2.2,31.59],[1,2.02,4.55],[2,1.91,4.55]],"ltp":2.2,"tv":69.64,"id":424676}]}]}
{"op":"mcm","clk":"11798558337","pt":1723152705618,"mc":[{"id":"1.231501231","rc":[{"batb":[[0,2.22,4],[1,2.2,31.59],[2,2.02,4.55]],"ltp":2.2,"tv":69.64,"id":424676}]}]}
{"op":"mcm","clk":"11798558381","pt":1723152706801,"mc":[{"id":"1.231501231","rc":[{"batb":[[0,2.24,10],[1,2.22,4],[2,2.2,31.59]],"ltp":2.2,"tv":69.64,"id":424676}]}]}
{"op":"mcm","clk":"11798558425","pt":1723152707926,"mc":[{"id":"1.231501231","rc":[{"batb":[[1,2.2,31.59],[2,2.02,4.55]],"ltp":2.2,"tv":69.64,"id":424676}]}]}
{"op":"mcm","clk":"11798558505","pt":1723152710233,"mc":[{"id":"1.231501231","rc":[{"batb":[[0,2.22,4]],"ltp":2.2,"tv":69.64,"id":424676}]}]}
{"op":"mcm","clk":"11798558606","pt":1723152712703,"mc":[{"id":"1.231501231","rc":[{"batb":[[0,2.22,10]],"ltp":2.2,"tv":69.64,"id":424676}]}]}
{"op":"mcm","clk":"11798558707","pt":1723152715937,"mc":[{"id":"1.231501231","rc":[{"batb":[[0,2.24,4]],"ltp":2.2,"tv":69.64,"id":424676}]}]}
{"op":"mcm","clk":"11798558779","pt":1723152717942,"mc":[{"id":"1.231501231","rc":[{"batb":[[0,2.2,31.59],[1,2.02,4.55],[2,1.91,4.55]],"ltp":2.2,"tv":69.64,"id":424676}]}]}
{"op":"mcm","clk":"11798558782","pt":1723152718044,"mc":[{"id":"1.231501231","rc":[{"batb":[[0,2.22,10],[1,2.2,31.59],[2,2.02,4.55]],"ltp":2.2,"tv":69.64,"id":424676}]}]}
{"op":"mcm","clk":"11798558870","pt":1723152720716,"mc":[{"id":"1.231501231","rc":[{"batb":[[0,2.24,4],[1,2.22,10],[2,2.2,31.59]],"ltp":2.2,"tv":69.64,"id":424676}]}]}
{"op":"mcm","clk":"11798558887","pt":1723152721228,"mc":[{"id":"1.231501231","rc":[{"batb":[[1,2.2,31.59],[2,2.02,4.55]],"ltp":2.2,"tv":69.64,"id":424676}]}]}
{"op":"mcm","clk":"11798558952","pt":1723152723027,"mc":[{"id":"1.231501231","rc":[{"batb":[[0,2.2,31.59],[1,2.02,4.55],[2,1.91,4.55]],"ltp":2.2,"tv":69.64,"id":424676}]}]}
{"op":"mcm","clk":"11798559043","pt":1723152725239,"mc":[{"id":"1.231501231","rc":[{"batb":[[0,2.24,4],[1,2.22,10],[2,2.2,31.59]],"ltp":2.2,"tv":69.64,"id":424676}]}]}
{"op":"mcm","clk":"11798559127","pt":1723152727547,"mc":[{"id":"1.231501231","rc":[{"batb":[[0,2.22,10],[1,2.2,31.59],[2,2.02,4.55]],"ltp":2.2,"tv":69.64,"id":424676}]}]}
{"op":"mcm","clk":"11798559164","pt":1723152728318,"mc":[{"id":"1.231501231","rc":[{"batb":[[0,2.2,31.59],[1,2.02,4.55],[2,1.91,4.55]],"ltp":2.2,"tv":69.64,"id":424676}]}]}
{"op":"mcm","clk":"11798559216","pt":1723152729753,"mc":[{"id":"1.231501231","rc":[{"batb":[[0,2.22,4],[1,2.2,31.59],[2,2.02,4.55]],"ltp":2.2,"tv":69.64,"id":424676}]}]}
{"op":"mcm","clk":"11798559316","pt":1723152732267,"mc":[{"id":"1.231501231","rc":[{"batb":[[0,2.22,10]],"ltp":2.2,"tv":69.64,"id":424676}]}]}
{"op":"mcm","clk":"11798559393","pt":1723152734468,"mc":[{"id":"1.231501231","rc":[{"batb":[[0,2.24,4],[1,2.22,10],[2,2.2,31.59]],"ltp":2.2,"tv":69.64,"id":424676}]}]}
{"op":"mcm","clk":"11798559424","pt":1723152735440,"mc":[{"id":"1.231501231","rc":[{"batb":[[1,2.2,31.59],[2,2.02,4.55]],"ltp":2.2,"tv":69.64,"id":424676}]}]}
{"op":"mcm","clk":"11798559480","pt":1723152736778,"mc":[{"id":"1.231501231","rc":[{"batb":[[0,2.2,31.59],[1,2.02,4.55],[2,1.91,4.55]],"ltp":2.2,"tv":69.64,"id":424676}]}]}
{"op":"mcm","clk":"11798559526","pt":1723152737858,"mc":[{"id":"1.231501231","rc":[{"batb":[[0,2.22,10],[1,2.2,31.59],[2,2.02,4.55]],"ltp":2.2,"tv":69.64,"id":424676}]}]}
{"op":"mcm","clk":"11798559567","pt":1723152739035,"mc":[{"id":"1.231501231","rc":[{"batb":[[0,2.24,4],[1,2.22,10],[2,2.2,31.59]],"ltp":2.2,"tv":69.64,"id":424676}]}]}
{"op":"mcm","clk":"11798559666","pt":1723152741348,"mc":[{"id":"1.231501231","rc":[{"batb":[[0,2.2,31.59],[1,2.02,4.55],[2,1.91,4.55]],"ltp":2.2,"tv":69.64,"id":424676}]}]}
{"op":"mcm","clk":"11798559758","pt":1723152743755,"mc":[{"id":"1.231501231","rc":[{"batb":[[0,2.22,14],[1,2.2,31.59],[2,2.02,4.55]],"ltp":2.2,"tv":69.64,"id":424676}]}]}
{"op":"mcm","clk":"11798559878","pt":1723152746988,"mc":[{"id":"1.231501231","rc":[{"batb":[[0,2.2,31.59],[1,2.02,4.55],[2,1.91,4.55]],"ltp":2.2,"tv":69.64,"id":424676}]}]}
{"op":"mcm","clk":"11798559942","pt":1723152748373,"mc":[{"id":"1.231501231","rc":[{"batb":[[0,2.22,4],[1,2.2,31.59],[2,2.02,4.55]],"ltp":2.2,"tv":69.64,"id":424676}]}]}
{"op":"mcm","clk":"11798559982","pt":1723152749857,"mc":[{"id":"1.231501231","rc":[{"batb":[[0,2.24,10],[1,2.22,4],[2,2.2,31.59]],"ltp":2.2,"tv":69.64,"id":424676}]}]}
{"op":"mcm","clk":"11798560006","pt":1723152750678,"mc":[{"id":"1.231501231","rc":[{"batb":[[1,2.2,31.59],[2,2.02,4.55]],"ltp":2.2,"tv":69.64,"id":424676}]}]}
{"op":"mcm","clk":"11798560098","pt":1723152753395,"mc":[{"id":"1.231501231","rc":[{"batb":[[0,2.22,4]],"ltp":2.2,"tv":69.64,"id":424676}]}]}
{"op":"mcm","clk":"11798560216","pt":1723152755755,"mc":[{"id":"1.231501231","rc":[{"batb":[[0,2.22,10]],"ltp":2.2,"tv":69.64,"id":424676}]}]}
{"op":"mcm","clk":"11798560332","pt":1723152758985,"mc":[{"id":"1.231501231","rc":[{"batb":[[0,2.24,4],[1,2.22,10],[2,2.2,31.59]],"ltp":2.2,"tv":69.64,"id":424676}]}]}
{"op":"mcm","clk":"11798560344","pt":1723152759188,"mc":[{"id":"1.231501231","rc":[{"batb":[[1,2.2,31.59],[2,2.02,4.55]],"ltp":2.2,"tv":69.64,"id":424676}]}]}
{"op":"mcm","clk":"11798560419","pt":1723152761287,"mc":[{"id":"1.231501231","rc":[{"batb":[[0,2.22,10]],"ltp":2.2,"tv":69.64,"id":424676}]}]}
{"op":"mcm","clk":"11798560493","pt":1723152763401,"mc":[{"id":"1.231501231","rc":[{"batb":[[0,2.24,4],[1,2.22,10],[2,2.2,31.59]],"ltp":2.2,"tv":69.64,"id":424676}]}]}
{"op":"mcm","clk":"11798560550","pt":1723152764685,"mc":[{"id":"1.231501231","rc":[{"batb":[[1,2.2,31.59],[2,2.02,4.55]],"ltp":2.2,"tv":69.64,"id":424676}]}]}
{"op":"mcm","clk":"11798560599","pt":1723152765706,"mc":[{"id":"1.231501231","rc":[{"batb":[[0,2.2,31.59],[1,2.02,4.55],[2,1.91,4.55]],"ltp":2.2,"tv":69.64,"id":424676}]}]}
{"op":"mcm","clk":"11798560687","pt":1723152767505,"mc":[{"id":"1.231501231","rc":[{"batb":[[0,2.22,10],[1,2.2,31.59],[2,2.02,4.55]],"ltp":2.2,"tv":69.64,"id":424676}]}]}
{"op":"mcm","clk":"11798560775","pt":1723152768870,"mc":[{"id":"1.231501231","rc":[{"batb":[[0,2.24,4],[1,2.22,10],[2,2.2,31.59]],"ltp":2.2,"tv":69.64,"id":424676}]}]}
{"op":"mcm","clk":"11798560869","pt":1723152770885,"mc":[{"id":"1.231501231","rc":[{"batb":[[1,2.2,31.59],[2,2.02,4.55]],"ltp":2.2,"tv":69.64,"id":424676}]}]}
{"op":"mcm","clk":"11798560884","pt":1723152771194,"mc":[{"id":"1.231501231","rc":[{"batb":[[0,2.2,31.59],[1,2.02,4.55],[2,1.91,4.55]],"ltp":2.2,"tv":69.64,"id":424676}]}]}
{"op":"mcm","clk":"11798561001","pt":1723152773813,"mc":[{"id":"1.231501231","rc":[{"batb":[[0,2.22,14],[1,2.2,31.59],[2,2.02,4.55]],"ltp":2.2,"tv":69.64,"id":424676}]}]}
{"op":"mcm","clk":"11798561099","pt":1723152776121,"mc":[{"id":"1.231501231","rc":[{"batb":[[0,2.22,10]],"ltp":2.2,"tv":69.64,"id":424676}]}]}
{"op":"mcm","clk":"11798561140","pt":1723152777095,"mc":[{"id":"1.231501231","rc":[{"batb":[[0,2.2,31.59],[1,2.02,4.55],[2,1.91,4.55]],"ltp":2.2,"tv":69.64,"id":424676}]}]}
{"op":"mcm","clk":"11798561205","pt":1723152778631,"mc":[{"id":"1.231501231","rc":[{"batb":[[0,2.22,4],[1,2.2,31.59],[2,2.02,4.55]],"ltp":2.2,"tv":69.64,"id":424676}]}]}
{"op":"mcm","clk":"11798561299","pt":1723152780992,"mc":[{"id":"1.231501231","rc":[{"batb":[[0,2.2,31.59],[1,2.02,4.55],[2,1.91,4.55]],"ltp":2.2,"tv":69.64,"id":424676}]}]}
{"op":"mcm","clk":"11798561306","pt":1723152781095,"mc":[{"id":"1.231501231","rc":[{"batb":[[0,2.22,10],[1,2.2,31.59],[2,2.02,4.55]],"ltp":2.2,"tv":69.64,"id":424676}]}]}
{"op":"mcm","clk":"11798561394","pt":1723152783296,"mc":[{"id":"1.231501231","rc":[{"batb":[[0,2.24,4],[1,2.22,10],[2,2.2,31.59]],"ltp":2.2,"tv":69.64,"id":424676}]}]}
{"op":"mcm","clk":"11798561434","pt":1723152784331,"mc":[{"id":"1.231501231","rc":[{"batb":[[1,2.2,31.59],[2,2.02,4.55]],"ltp":2.2,"tv":69.64,"id":424676}]}]}
{"op":"mcm","clk":"11798561504","pt":1723152785711,"mc":[{"id":"1.231501231","rc":[{"batb":[[0,2.2,31.59],[1,2.02,4.55],[2,1.91,4.55]],"ltp":2.2,"tv":69.64,"id":424676}]}]}
{"op":"mcm","clk":"11798561602","pt":1723152787918,"mc":[{"id":"1.231501231","rc":[{"batb":[[0,2.24,4],[1,2.22,10],[2,2.2,31.59]],"ltp":2.2,"tv":69.64,"id":424676}]}]}
{"op":"mcm","clk":"11798561732","pt":1723152790307,"mc":[{"id":"1.231501231","rc":[{"batb":[[0,2.22,10],[1,2.2,31.59],[2,2.02,4.55]],"ltp":2.2,"tv":69.64,"id":424676}]}]}
{"op":"mcm","clk":"11798561780","pt":1723152791252,"mc":[{"id":"1.231501231","rc":[{"batb":[[0,2.2,31.59],[1,2.02,4.55],[2,1.91,4.55]],"ltp":2.2,"tv":69.64,"id":424676}]}]}
{"op":"mcm","clk":"11798561841","pt":1723152792737,"mc":[{"id":"1.231501231","rc":[{"batb":[[0,2.22,4],[1,2.2,31.59],[2,2.02,4.55]],"ltp":2.2,"tv":69.64,"id":424676}]}]}
{"op":"mcm","clk":"11798561889","pt":1723152793913,"mc":[{"id":"1.231501231","rc":[{"batb":[[0,2.24,10],[1,2.22,4],[2,2.2,31.59]],"ltp":2.2,"tv":69.64,"id":424676}]}]}
{"op":"mcm","clk":"11798561945","pt":1723152795148,"mc":[{"id":"1.231501231","rc":[{"batb":[[1,2.2,31.59],[2,2.02,4.55]],"ltp":2.2,"tv":69.64,"id":424676}]}]}
{"op":"mcm","clk":"11798562065","pt":1723152797366,"mc":[{"id":"1.231501231","rc":[{"batb":[[0,2.22,4]],"ltp":2.2,"tv":69.64,"id":424676}]}]}
{"op":"mcm","clk":"11798562172","pt":1723152799621,"mc":[{"id":"1.231501231","rc":[{"batb":[[0,2.22,10]],"ltp":2.2,"tv":69.64,"id":424676}]}]}
{"op":"mcm","clk":"11798562296","pt":1723152802957,"mc":[{"id":"1.231501231","rc":[{"batb":[[0,2.2,31.59],[1,2.02,4.55],[2,1.91,4.55]],"ltp":2.2,"tv":69.64,"id":424676}]}]}
{"op":"mcm","clk":"11798562303","pt":1723152803059,"mc":[{"id":"1.231501231","rc":[{"batb":[[0,2.22,4],[1,2.2,31.59],[2,2.02,4.55]],"ltp":2.2,"tv":69.64,"id":424676}]}]}
{"op":"mcm","clk":"11798562462","pt":1723152805225,"mc":[{"id":"1.231501231","rc":[{"batb":[[0,2.24,10]],"ltp":2.2,"tv":69.64,"id":424676}]}]}
{"op":"mcm","clk":"11798562624","pt":1723152808658,"mc":[{"id":"1.231501231","rc":[{"batb":[[0,2.22,4]],"ltp":2.2,"tv":69.64,"id":424676}]}]}
{"op":"mcm","clk":"11798562735","pt":1723152810969,"mc":[{"id":"1.231501231","rc":[{"batb":[[0,2.24,10]],"ltp":2.2,"tv":69.64,"id":424676}]}]}
{"op":"mcm","clk":"11798562895","pt":1723152814464,"mc":[{"id":"1.231501231","rc":[{"batb":[[0,2.22,4]],"ltp":2.2,"tv":69.64,"id":424676}]}]}
{"op":"mcm","clk":"11798562961","pt":1723152816875,"mc":[{"id":"1.231501231","rc":[{"batb":[[0,2.24,10]],"ltp":2.2,"tv":69.64,"id":424676}]}]}
{"op":"mcm","clk":"11798563058","pt":1723152820269,"mc":[{"id":"1.231501231","rc":[{"batb":[[0,2.22,4]],"ltp":2.2,"tv":69.64,"id":424676}]}]}
{"op":"mcm","clk":"11798563135","pt":1723152822649,"mc":[{"id":"1.231501231","rc":[{"batb":[[0,2.22,10]],"ltp":2.2,"tv":69.64,"id":424676}]}]}
{"op":"mcm","clk":"11798563231","pt":1723152826142,"mc":[{"id":"1.231501231","rc":[{"batb":[[0,2.22,4]],"ltp":2.2,"tv":69.64,"id":424676}]}]}
{"op":"mcm","clk":"11798563326","pt":1723152828455,"mc":[{"id":"1.231501231","rc":[{"batb":[[0,2.22,10]],"ltp":2.2,"tv":69.64,"id":424676}]}]}
{"op":"mcm","clk":"11798563440","pt":1723152830961,"mc":[{"id":"1.231501231","rc":[{"batb":[[0,2.24,4],[1,2.22,10],[2,2.2,31.59]],"ltp":2.2,"tv":69.64,"id":424676}]}]}
{"op":"mcm","clk":"11798563474","pt":1723152831679,"mc":[{"id":"1.231501231","rc":[{"batb":[[1,2.2,31.59],[2,2.02,4.55]],"ltp":2.2,"tv":69.64,"id":424676}]}]}
{"op":"mcm","clk":"11798563537","pt":1723152833265,"mc":[{"id":"1.231501231","rc":[{"batb":[[0,2.2,31.59],[1,2.02,4.55],[2,1.91,4.55]],"ltp":2.2,"tv":69.64,"id":424676}]}]}
{"op":"mcm","clk":"11798563579","pt":1723152834349,"mc":[{"id":"1.231501231","rc":[{"batb":[[0,2.22,10],[1,2.2,31.59],[2,2.02,4.55]],"ltp":2.2,"tv":69.64,"id":424676}]}]}
{"op":"mcm","clk":"11798563615","pt":1723152835585,"mc":[{"id":"1.231501231","rc":[{"batb":[[0,2.24,4],[1,2.22,10],[2,2.2,31.59]],"ltp":2.2,"tv":69.64,"id":424676}]}]}
{"op":"mcm","clk":"11798563708","pt":1723152837996,"mc":[{"id":"1.231501231","rc":[{"batb":[[0,2.2,31.59],[1,2.02,4.55],[2,1.91,4.55]],"ltp":2.2,"tv":69.64,"id":424676}]}]}
{"op":"mcm","clk":"11798563786","pt":1723152840148,"mc":[{"id":"1.231501231","rc":[{"batb":[[0,2.22,14],[1,2.2,31.59],[2,2.02,4.55]],"ltp":2.2,"tv":69.64,"id":424676}]}]}
{"op":"mcm","clk":"11798563890","pt":1723152842560,"mc":[{"id":"1.231501231","rc":[{"batb":[[0,2.22,10]],"ltp":2.2,"tv":69.64,"id":424676}]}]}
{"op":"mcm","clk":"11798563929","pt":1723152843484,"mc":[{"id":"1.231501231","rc":[{"batb":[[0,2.2,31.59],[1,2.02,4.55],[2,1.91,4.55]],"ltp":2.2,"tv":69.64,"id":424676}]}]}
{"op":"mcm","clk":"11798564035","pt":1723152846662,"mc":[{"id":"1.231501231","rc":[{"batb":[[0,2.22,14],[1,2.2,31.59],[2,2.02,4.55]],"ltp":2.2,"tv":69.64,"id":424676}]}]}
{"op":"mcm","clk":"11798564134","pt":1723152848963,"mc":[{"id":"1.231501231","rc":[{"batb":[[0,2.22,10]],"ltp":2.2,"tv":69.64,"id":424676}]}]}
{"op":"mcm","clk":"11798564162","pt":1723152849889,"mc":[{"id":"1.231501231","rc":[{"batb":[[0,2.2,31.59],[1,2.02,4.55],[2,1.91,4.55]],"ltp":2.2,"tv":69.64,"id":424676}]}]}
{"op":"mcm","clk":"11798564407","pt":1723152855290,"mc":[{"id":"1.231501231","rc":[{"batb":[[0,2.22,14],[1,2.2,31.59],[2,2.02,4.55]],"ltp":2.2,"tv":69.64,"id":424676}]}]}
{"op":"mcm","clk":"11798564493","pt":1723152857710,"mc":[{"id":"1.231501231","rc":[{"batb":[[0,2.22,10]],"ltp":2.2,"tv":69.64,"id":424676}]}]}
{"op":"mcm","clk":"11798564533","pt":1723152858691,"mc":[{"id":"1.231501231","rc":[{"batb":[[0,2.2,31.59],[1,2.02,4.55],[2,1.91,4.55]],"ltp":2.2,"tv":69.64,"id":424676}]}]}
{"op":"mcm","clk":"11798564598","pt":1723152860382,"mc":[{"id":"1.231501231","rc":[{"batb":[[0,2.22,4],[1,2.2,31.59],[2,2.02,4.55]],"ltp":2.2,"tv":69.64,"id":424676}]}]}
{"op":"mcm","clk":"11798564644","pt":1723152861617,"mc":[{"id":"1.231501231","rc":[{"batb":[[0,2.24,10],[1,2.22,4],[2,2.2,31.59]],"ltp":2.2,"tv":69.64,"id":424676}]}]}
{"op":"mcm","clk":"11798564685","pt":1723152862696,"mc":[{"id":"1.231501231","rc":[{"batb":[[1,2.2,31.59],[2,2.02,4.55]],"ltp":2.2,"tv":69.64,"id":424676}]}]}
{"op":"mcm","clk":"11798564768","pt":1723152864900,"mc":[{"id":"1.231501231","rc":[{"batb":[[0,2.2,31.59],[1,2.02,4.55],[2,1.91,4.55]],"ltp":2.2,"tv":69.64,"id":424676}]}]}
{"op":"mcm","clk":"11798564773","pt":1723152865003,"mc":[{"id":"1.231501231","rc":[{"batb":[[0,2.22,4],[1,2.2,31.59],[2,2.02,4.55]],"ltp":2.2,"tv":69.64,"id":424676}]}]}
{"op":"mcm","clk":"11798564868","pt":1723152867528,"mc":[{"id":"1.231501231","rc":[{"batb":[[0,2.22,10]],"ltp":2.2,"tv":69.64,"id":424676}]}]}
{"op":"mcm","clk":"11798565020","pt":1723152870919,"mc":[{"id":"1.231501231","rc":[{"batb":[[0,2.2,31.59],[1,2.02,4.55],[2,1.91,4.55]],"ltp":2.2,"tv":69.64,"id":424676}]}]}
{"op":"mcm","clk":"11798565022","pt":1723152871021,"mc":[{"id":"1.231501231","rc":[{"batb":[[0,2.22,4],[1,2.2,31.59],[2,2.02,4.55]],"ltp":2.2,"tv":69.64,"id":424676}]}]}
{"op":"mcm","clk":"11798565136","pt":1723152873490,"mc":[{"id":"1.231501231","rc":[{"batb":[[0,2.22,10]],"ltp":2.2,"tv":69.64,"id":424676}]}]}
{"op":"mcm","clk":"11798565241","pt":1723152876723,"mc":[{"id":"1.231501231","rc":[{"batb":[[0,2.24,4]],"ltp":2.2,"tv":69.64,"id":424676}]}]}
{"op":"mcm","clk":"11798565330","pt":1723152878932,"mc":[{"id":"1.231501231","rc":[{"trd":[[2.26,1.59]],"batb":[[0,2.26,8.41]],"ltp":2.26,"tv":71.24,"id":424676},{"trd":[[1.8,2.12]],"batb":[[0,1.74,1],[1,1.73,30],[2,1.72,52.65]],"ltp":1.8,"tv":116.97,"id":31376}],"tv":188.21}]}
{"op":"mcm","clk":"11798565460","pt":1723152882216,"mc":[{"id":"1.231501231","rc":[{"batb":[[0,2.22,4]],"ltp":2.26,"tv":71.24,"id":424676}]}]}
{"op":"mcm","clk":"11798565568","pt":1723152884695,"mc":[{"id":"1.231501231","rc":[{"batb":[[0,2.24,10]],"ltp":2.26,"tv":71.24,"id":424676}]}]}
{"op":"mcm","clk":"11798565700","pt":1723152888242,"mc":[{"id":"1.231501231","rc":[{"batb":[[0,2.22,4]],"ltp":2.26,"tv":71.24,"id":424676}]}]}
{"op":"mcm","clk":"11798565779","pt":1723152890398,"mc":[{"id":"1.231501231","rc":[{"batb":[[0,2.24,10]],"ltp":2.26,"tv":71.24,"id":424676}]}]}
{"op":"mcm","clk":"11798565885","pt":1723152892823,"mc":[{"id":"1.231501231","rc":[{"batb":[[0,2.26,4],[1,2.24,10],[2,2.2,31.59]],"ltp":2.26,"tv":71.24,"id":424676}]}]}
{"op":"mcm","clk":"11798565917","pt":1723152893737,"mc":[{"id":"1.231501231","rc":[{"batb":[[1,2.2,31.59],[2,2.02,4.55]],"ltp":2.26,"tv":71.24,"id":424676}]}]}
{"op":"mcm","clk":"11798565984","pt":1723152895021,"mc":[{"id":"1.231501231","rc":[{"batb":[[0,2.2,31.59],[1,2.02,4.55],[2,1.91,4.55]],"ltp":2.26,"tv":71.24,"id":424676}]}]}
{"op":"mcm","clk":"11798566022","pt":1723152896233,"mc":[{"id":"1.231501231","rc":[{"batb":[[0,2.22,10],[1,2.2,31.59],[2,2.02,4.55]],"ltp":2.26,"tv":71.24,"id":424676}]}]}
{"op":"mcm","clk":"11798566157","pt":1723152899822,"mc":[{"id":"1.231501231","rc":[{"batb":[[0,2.22,4]],"ltp":2.26,"tv":71.24,"id":424676}]}]}
{"op":"mcm","clk":"11798566250","pt":1723152902130,"mc":[{"id":"1.231501231","rc":[{"batb":[[0,2.22,10]],"ltp":2.26,"tv":71.24,"id":424676}]}]}
{"op":"mcm","clk":"11798566361","pt":1723152904850,"mc":[{"id":"1.231501231","rc":[{"batb":[[0,2.24,4],[1,2.22,10],[2,2.2,31.59]],"ltp":2.26,"tv":71.24,"id":424676}]}]}
{"op":"mcm","clk":"11798566382","pt":1723152905366,"mc":[{"id":"1.231501231","rc":[{"batb":[[1,2.2,31.59],[2,2.02,4.55]],"ltp":2.26,"tv":71.24,"id":424676}]}]}
{"op":"mcm","clk":"11798566442","pt":1723152907157,"mc":[{"id":"1.231501231","rc":[{"batb":[[0,2.2,31.59],[1,2.02,4.55],[2,1.91,4.55]],"ltp":2.26,"tv":71.24,"id":424676}]}]}
{"op":"mcm","clk":"11798566521","pt":1723152909527,"mc":[{"id":"1.231501231","rc":[{"batb":[[0,2.22,14],[1,2.2,31.59],[2,2.02,4.55]],"ltp":2.26,"tv":71.24,"id":424676}]}]}
{"op":"mcm","clk":"11798566592","pt":1723152911955,"mc":[{"id":"1.231501231","rc":[{"batb":[[0,2.22,10]],"ltp":2.26,"tv":71.24,"id":424676}]}]}
{"op":"mcm","clk":"11798566645","pt":1723152913077,"mc":[{"id":"1.231501231","rc":[{"batb":[[0,2.2,31.59],[1,2.02,4.55],[2,1.91,4.55]],"ltp":2.26,"tv":71.24,"id":424676}]}]}
{"op":"mcm","clk":"11798566729","pt":1723152915442,"mc":[{"id":"1.231501231","rc":[{"batb":[[0,2.22,14],[1,2.2,31.59],[2,2.02,4.55]],"ltp":2.26,"tv":71.24,"id":424676}]}]}
{"op":"mcm","clk":"11798566795","pt":1723152917646,"mc":[{"id":"1.231501231","rc":[{"batb":[[0,2.22,10]],"ltp":2.26,"tv":71.24,"id":424676}]}]}
{"op":"mcm","clk":"11798566833","pt":1723152918774,"mc":[{"id":"1.231501231","rc":[{"batb":[[0,2.2,31.59],[1,2.02,4.55],[2,1.91,4.55]],"ltp":2.26,"tv":71.24,"id":424676}]}]}
{"op":"mcm","clk":"11798566874","pt":1723152920057,"mc":[{"id":"1.231501231","rc":[{"batb":[[0,2.22,4],[1,2.2,31.59],[2,2.02,4.55]],"ltp":2.26,"tv":71.24,"id":424676}]}]}
{"op":"mcm","clk":"11798566939","pt":1723152922369,"mc":[{"id":"1.231501231","rc":[{"batb":[[0,2.24,10]],"ltp":2.26,"tv":71.24,"id":424676}]}]}
{"op":"mcm","clk":"11798567054","pt":1723152925754,"mc":[{"id":"1.231501231","rc":[{"batb":[[0,2.22,4]],"ltp":2.26,"tv":71.24,"id":424676}]}]}
{"op":"mcm","clk":"11798567139","pt":1723152928172,"mc":[{"id":"1.231501231","rc":[{"batb":[[0,2.22,10]],"ltp":2.26,"tv":71.24,"id":424676}]}]}
{"op":"mcm","clk":"11798567234","pt":1723152930784,"mc":[{"id":"1.231501231","rc":[{"batb":[[0,2.24,4],[1,2.22,10],[2,2.2,31.59]],"ltp":2.26,"tv":71.24,"id":424676}]}]}
{"op":"mcm","clk":"11798567259","pt":1723152931351,"mc":[{"id":"1.231501231","rc":[{"batb":[[1,2.2,31.59],[2,2.02,4.55]],"ltp":2.26,"tv":71.24,"id":424676}]}]}
{"op":"mcm","clk":"11798567329","pt":1723152933296,"mc":[{"id":"1.231501231","rc":[{"batb":[[0,2.2,31.59],[1,2.02,4.55],[2,1.91,4.55]],"ltp":2.26,"tv":71.24,"id":424676}]}]}
{"op":"mcm","clk":"11798567365","pt":1723152934372,"mc":[{"id":"1.231501231","rc":[{"batb":[[0,2.22,10],[1,2.2,31.59],[2,2.02,4.55]],"ltp":2.26,"tv":71.24,"id":424676}]}]}
{"op":"mcm","clk":"11798567410","pt":1723152935652,"mc":[{"id":"1.231501231","rc":[{"batb":[[0,2.24,4],[1,2.22,10],[2,2.2,31.59]],"ltp":2.26,"tv":71.24,"id":424676}]}]}
{"op":"mcm","clk":"11798567515","pt":1723152937959,"mc":[{"id":"1.231501231","rc":[{"batb":[[0,2.2,31.59],[1,2.02,4.55],[2,1.91,4.55]],"ltp":2.26,"tv":71.24,"id":424676}]}]}
{"op":"mcm","clk":"11798567594","pt":1723152940167,"mc":[{"id":"1.231501231","rc":[{"batb":[[0,2.22,14],[1,2.2,31.59],[2,2.02,4.55]],"ltp":2.26,"tv":71.24,"id":424676}]}]}
{"op":"mcm","clk":"11798567667","pt":1723152942572,"mc":[{"id":"1.231501231","rc":[{"batb":[[0,2.22,10]],"ltp":2.26,"tv":71.24,"id":424676}]}]}
{"op":"mcm","clk":"11798567699","pt":1723152943494,"mc":[{"id":"1.231501231","rc":[{"batb":[[0,2.2,31.59],[1,2.02,4.55],[2,1.91,4.55]],"ltp":2.26,"tv":71.24,"id":424676}]}]}
{"op":"mcm","clk":"11798567737","pt":1723152944671,"mc":[{"id":"1.231501231","rc":[{"batb":[[0,2.22,4],[1,2.2,31.59],[2,2.02,4.55]],"ltp":2.26,"tv":71.24,"id":424676}]}]}
{"op":"mcm","clk":"11798567789","pt":1723152946980,"mc":[{"id":"1.231501231","rc":[{"batb":[[0,2.24,10]],"ltp":2.26,"tv":71.24,"id":424676}]}]}
{"op":"mcm","clk":"11798567859","pt":1723152949296,"mc":[{"id":"1.231501231","rc":[{"batb":[[0,2.26,4]],"ltp":2.26,"tv":71.24,"id":424676}]}]}
{"op":"mcm","clk":"11798567956","pt":1723152951602,"mc":[{"id":"1.231501231","rc":[{"batb":[[0,2.22,10]],"ltp":2.26,"tv":71.24,"id":424676}]}]}
{"op":"mcm","clk":"11798568260","pt":1723152954772,"mc":[{"id":"1.231501231","rc":[{"batb":[[0,2.24,4]],"ltp":2.26,"tv":71.24,"id":424676}]}]}
{"op":"mcm","clk":"11798568429","pt":1723152956868,"mc":[{"id":"1.231501231","rc":[{"batb":[[0,2.22,10]],"ltp":2.26,"tv":71.24,"id":424676}]}]}
{"op":"mcm","clk":"11798568535","pt":1723152958974,"mc":[{"id":"1.231501231","rc":[{"batb":[[0,2.24,4],[1,2.22,10],[2,2.2,31.59]],"ltp":2.26,"tv":71.24,"id":424676}]}]}
{"op":"mcm","clk":"11798568586","pt":1723152960156,"mc":[{"id":"1.231501231","rc":[{"batb":[[1,2.2,31.59],[2,2.02,4.55]],"ltp":2.26,"tv":71.24,"id":424676}]}]}
{"op":"mcm","clk":"11798568628","pt":1723152961383,"mc":[{"id":"1.231501231","rc":[{"batb":[[0,2.2,31.59],[1,2.02,4.55],[2,1.91,4.55]],"ltp":2.26,"tv":71.24,"id":424676}]}]}
{"op":"mcm","clk":"11798568721","pt":1723152964255,"mc":[{"id":"1.231501231","rc":[{"batb":[[0,2.22,14],[1,2.2,31.59],[2,2.02,4.55]],"ltp":2.26,"tv":71.24,"id":424676}]}]}
{"op":"mcm","clk":"11798568796","pt":1723152966565,"mc":[{"id":"1.231501231","rc":[{"batb":[[0,2.22,10]],"ltp":2.26,"tv":71.24,"id":424676}]}]}
{"op":"mcm","clk":"11798568829","pt":1723152967691,"mc":[{"id":"1.231501231","rc":[{"batb":[[0,2.2,31.59],[1,2.02,4.55],[2,1.91,4.55]],"ltp":2.26,"tv":71.24,"id":424676}]}]}
{"op":"mcm","clk":"11798568869","pt":1723152968870,"mc":[{"id":"1.231501231","rc":[{"batb":[[0,2.22,4],[1,2.2,31.59],[2,2.02,4.55]],"ltp":2.26,"tv":71.24,"id":424676}]}]}
{"op":"mcm","clk":"11798568932","pt":1723152970465,"mc":[{"id":"1.231501231","rc":[{"batb":[[0,2.24,10],[1,2.22,4],[2,2.2,31.59]],"ltp":2.26,"tv":71.24,"id":424676}]}]}
{"op":"mcm","clk":"11798568973","pt":1723152971289,"mc":[{"id":"1.231501231","rc":[{"batb":[[1,2.2,31.59],[2,2.02,4.55]],"ltp":2.26,"tv":71.24,"id":424676}]}]}
{"op":"mcm","clk":"11798569067","pt":1723152973866,"mc":[{"id":"1.231501231","rc":[{"batb":[[0,2.22,4]],"ltp":2.26,"tv":71.24,"id":424676}]}]}
{"op":"mcm","clk":"11798569152","pt":1723152976271,"mc":[{"id":"1.231501231","rc":[{"batb":[[0,2.22,10]],"ltp":2.26,"tv":71.24,"id":424676}]}]}
{"op":"mcm","clk":"11798569241","pt":1723152978274,"mc":[{"id":"1.231501231","rc":[{"batb":[[0,2.24,4],[1,2.22,10],[2,2.2,31.59]],"ltp":2.26,"tv":71.24,"id":424676}]}]}
{"op":"mcm","clk":"11798569304","pt":1723152979709,"mc":[{"id":"1.231501231","rc":[{"batb":[[1,2.2,31.59],[2,2.02,4.55]],"ltp":2.26,"tv":71.24,"id":424676}]}]}
{"op":"mcm","clk":"11798569341","pt":1723152980587,"mc":[{"id":"1.231501231","rc":[{"batb":[[0,2.2,31.59],[1,2.02,4.55],[2,1.91,4.55]],"ltp":2.26,"tv":71.24,"id":424676}]}]}
{"op":"mcm","clk":"11798569514","pt":1723152985209,"mc":[{"id":"1.231501231","rc":[{"batb":[[0,2.22,14],[1,2.2,31.59],[2,2.02,4.55]],"ltp":2.26,"tv":71.24,"id":424676}]}]}
{"op":"mcm","clk":"11798569606","pt":1723152987613,"mc":[{"id":"1.231501231","rc":[{"batb":[[0,2.22,10]],"ltp":2.26,"tv":71.24,"id":424676}]}]}
{"op":"mcm","clk":"11798569649","pt":1723152988588,"mc":[{"id":"1.231501231","rc":[{"batb":[[0,2.2,31.59],[1,2.02,4.55],[2,1.91,4.55]],"ltp":2.26,"tv":71.24,"id":424676}]}]}
{"op":"mcm","clk":"11798569698","pt":1723152989713,"mc":[{"id":"1.231501231","rc":[{"batb":[[0,2.22,4],[1,2.2,31.59],[2,2.02,4.55]],"ltp":2.26,"tv":71.24,"id":424676}]}]}
{"op":"mcm","clk":"11798569794","pt":1723152991914,"mc":[{"id":"1.231501231","rc":[{"batb":[[0,2.24,10]],"ltp":2.26,"tv":71.24,"id":424676}]}]}
{"op":"mcm","clk":"11798569895","pt":1723152994988,"mc":[{"id":"1.231501231","rc":[{"batb":[[0,2.2,31.59],[1,2.02,4.55],[2,1.91,4.55]],"ltp":2.26,"tv":71.24,"id":424676}]}]}
{"op":"mcm","clk":"11798569901","pt":1723152995090,"mc":[{"id":"1.231501231","rc":[{"batb":[[0,2.22,4],[1,2.2,31.59],[2,2.02,4.55]],"ltp":2.26,"tv":71.24,"id":424676}]}]}
{"op":"mcm","clk":"11798569983","pt":1723152997595,"mc":[{"id":"1.231501231","rc":[{"batb":[[0,2.24,10]],"ltp":2.26,"tv":71.24,"id":424676}]}]}
{"op":"mcm","clk":"11798570057","pt":1723153000724,"mc":[{"id":"1.231501231","rc":[{"batb":[[0,2.26,4]],"ltp":2.26,"tv":71.24,"id":424676}]}]}
{"op":"mcm","clk":"11798570144","pt":1723153003237,"mc":[{"id":"1.231501231","rc":[{"batb":[[0,2.22,10]],"ltp":2.26,"tv":71.24,"id":424676}]}]}
{"op":"mcm","clk":"11798570223","pt":1723153005697,"mc":[{"id":"1.231501231","rc":[{"batb":[[0,2.24,4],[1,2.22,10],[2,2.2,31.59]],"ltp":2.26,"tv":71.24,"id":424676}]}]}
{"op":"mcm","clk":"11798570254","pt":1723153006516,"mc":[{"id":"1.231501231","rc":[{"batb":[[1,2.2,31.59],[2,2.02,4.55]],"ltp":2.26,"tv":71.24,"id":424676}]}]}
{"op":"mcm","clk":"11798570299","pt":1723153007897,"mc":[{"id":"1.231501231","rc":[{"batb":[[0,2.2,31.59],[1,2.02,4.55],[2,1.91,4.55]],"ltp":2.26,"tv":71.24,"id":424676}]}]}
{"op":"mcm","clk":"11798570349","pt":1723153009229,"mc":[{"id":"1.231501231","rc":[{"batb":[[0,2.22,10],[1,2.2,31.59],[2,2.02,4.55]],"ltp":2.26,"tv":71.24,"id":424676}]}]}
{"op":"mcm","clk":"11798570453","pt":1723153011944,"mc":[{"id":"1.231501231","rc":[{"batb":[[0,2.24,4],[1,2.22,10],[2,2.2,31.59]],"ltp":2.26,"tv":71.24,"id":424676}]}]}
{"op":"mcm","clk":"11798570478","pt":1723153012617,"mc":[{"id":"1.231501231","rc":[{"batb":[[1,2.2,31.59],[2,2.02,4.55]],"ltp":2.26,"tv":71.24,"id":424676}]}]}
{"op":"mcm","clk":"11798570535","pt":1723153014307,"mc":[{"id":"1.231501231","rc":[{"batb":[[0,2.2,31.59],[1,2.02,4.55],[2,1.91,4.55]],"ltp":2.26,"tv":71.24,"id":424676}]}]}
{"op":"mcm","clk":"11798570662","pt":1723153017443,"mc":[{"id":"1.231501231","rc":[{"batb":[[0,2.22,14],[1,2.2,31.59],[2,2.02,4.55]],"ltp":2.26,"tv":71.24,"id":424676}]}]}
{"op":"mcm","clk":"11798570748","pt":1723153019804,"mc":[{"id":"1.231501231","rc":[{"batb":[[0,2.22,10]],"ltp":2.26,"tv":71.24,"id":424676}]}]}
{"op":"mcm","clk":"11798570776","pt":1723153020827,"mc":[{"id":"1.231501231","rc":[{"batb":[[0,2.2,31.59],[1,2.02,4.55],[2,1.91,4.55]],"ltp":2.26,"tv":71.24,"id":424676}]}]}
{"op":"mcm","clk":"11798570868","pt":1723153023232,"mc":[{"id":"1.231501231","rc":[{"batb":[[0,2.22,14],[1,2.2,31.59],[2,2.02,4.55]],"ltp":2.26,"tv":71.24,"id":424676}]}]}
{"op":"mcm","clk":"11798570943","pt":1723153025541,"mc":[{"id":"1.231501231","rc":[{"batb":[[0,2.22,10]],"ltp":2.26,"tv":71.24,"id":424676}]}]}
{"op":"mcm","clk":"11798570970","pt":1723153026564,"mc":[{"id":"1.231501231","rc":[{"batb":[[0,2.2,31.59],[1,2.02,4.55],[2,1.91,4.55]],"ltp":2.26,"tv":71.24,"id":424676}]}]}
{"op":"mcm","clk":"11798571015","pt":1723153027744,"mc":[{"id":"1.231501231","rc":[{"batb":[[0,2.22,4],[1,2.2,31.59],[2,2.02,4.55]],"ltp":2.26,"tv":71.24,"id":424676}]}]}
{"op":"mcm","clk":"11798571062","pt":1723153029026,"mc":[{"id":"1.231501231","rc":[{"batb":[[0,2.24,10],[1,2.22,4],[2,2.2,31.59]],"ltp":2.26,"tv":71.24,"id":424676}]}]}
{"op":"mcm","clk":"11798571087","pt":1723153030048,"mc":[{"id":"1.231501231","rc":[{"batb":[[1,2.2,31.59],[2,2.02,4.55]],"ltp":2.26,"tv":71.24,"id":424676}]}]}
{"op":"mcm","clk":"11798571178","pt":1723153032358,"mc":[{"id":"1.231501231","rc":[{"batb":[[0,2.22,4]],"ltp":2.26,"tv":71.24,"id":424676}]}]}
{"op":"mcm","clk":"11798571251","pt":1723153034767,"mc":[{"id":"1.231501231","rc":[{"batb":[[0,2.22,10]],"ltp":2.26,"tv":71.24,"id":424676}]}]}
{"op":"mcm","clk":"11798571337","pt":1723153038159,"mc":[{"id":"1.231501231","rc":[{"batb":[[0,2.22,4]],"ltp":2.26,"tv":71.24,"id":424676}]}]}
{"op":"mcm","clk":"11798571433","pt":1723153040567,"mc":[{"id":"1.231501231","rc":[{"batb":[[0,2.22,10]],"ltp":2.26,"tv":71.24,"id":424676}]}]}
{"op":"mcm","clk":"11798571513","pt":1723153042980,"mc":[{"id":"1.231501231","rc":[{"batb":[[0,2.24,4],[1,2.22,10],[2,2.2,31.59]],"ltp":2.26,"tv":71.24,"id":424676}]}]}
{"op":"mcm","clk":"11798571546","pt":1723153043752,"mc":[{"id":"1.231501231","rc":[{"batb":[[1,2.2,31.59],[2,2.02,4.55]],"ltp":2.26,"tv":71.24,"id":424676}]}]}
{"op":"mcm","clk":"11798571580","pt":1723153045139,"mc":[{"id":"1.231501231","rc":[{"batb":[[0,2.2,31.59],[1,2.02,4.55],[2,1.91,4.55]],"ltp":2.26,"tv":71.24,"id":424676}]}]}
{"op":"mcm","clk":"11798571643","pt":1723153047653,"mc":[{"id":"1.231501231","rc":[{"batb":[[0,2.22,14],[1,2.2,31.59],[2,2.02,4.55]],"ltp":2.26,"tv":71.24,"id":424676}]}]}
{"op":"mcm","clk":"11798571748","pt":1723153050984,"mc":[{"id":"1.231501231","rc":[{"batb":[[0,2.2,31.59],[1,2.02,4.55],[2,1.91,4.55]],"ltp":2.26,"tv":71.24,"id":424676}]}]}
{"op":"mcm","clk":"11798571828","pt":1723153053250,"mc":[{"id":"1.231501231","rc":[{"batb":[[0,2.22,14],[1,2.2,31.59],[2,2.02,4.55]],"ltp":2.26,"tv":71.24,"id":424676}]}]}
{"op":"mcm","clk":"11798571895","pt":1723153055450,"mc":[{"id":"1.231501231","rc":[{"batb":[[0,2.22,10]],"ltp":2.26,"tv":71.24,"id":424676}]}]}
{"op":"mcm","clk":"11798571926","pt":1723153056577,"mc":[{"id":"1.231501231","rc":[{"batb":[[0,2.2,31.59],[1,2.02,4.55],[2,1.91,4.55]],"ltp":2.26,"tv":71.24,"id":424676}]}]}
{"op":"mcm","clk":"11798571963","pt":1723153057765,"mc":[{"id":"1.231501231","rc":[{"batb":[[0,2.22,4],[1,2.2,31.59],[2,2.02,4.55]],"ltp":2.26,"tv":71.24,"id":424676}]}]}
{"op":"mcm","clk":"11798572046","pt":1723153059866,"mc":[{"id":"1.231501231","rc":[{"batb":[[0,2.24,10],[1,2.22,4],[2,2.2,31.59]],"ltp":2.26,"tv":71.24,"id":424676}]}]}
{"op":"mcm","clk":"11798572053","pt":1723153060071,"mc":[{"id":"1.231501231","rc":[{"batb":[[1,2.2,31.59],[2,2.02,4.55]],"ltp":2.26,"tv":71.24,"id":424676}]}]}
{"op":"mcm","clk":"11798572140","pt":1723153063196,"mc":[{"id":"1.231501231","rc":[{"batb":[[0,2.26,4]],"ltp":2.26,"tv":71.24,"id":424676}]}]}
{"op":"mcm","clk":"11798572224","pt":1723153065760,"mc":[{"id":"1.231501231","rc":[{"batb":[[0,2.28,10]],"ltp":2.26,"tv":71.24,"id":424676}]}]}
{"op":"mcm","clk":"11798572284","pt":1723153067965,"mc":[{"id":"1.231501231","rc":[{"batb":[[0,2.3,4],[1,2.28,10],[2,2.2,31.59]],"ltp":2.26,"tv":71.24,"id":424676}]}]}
{"op":"mcm","clk":"11798572334","pt":1723153069097,"mc":[{"id":"1.231501231","rc":[{"batb":[[1,2.2,31.59],[2,2.02,4.55]],"ltp":2.26,"tv":71.24,"id":424676}]}]}
{"op":"mcm","clk":"11798572368","pt":1723153070176,"mc":[{"id":"1.231501231","rc":[{"batb":[[0,2.2,31.59],[1,2.02,4.55],[2,1.91,4.55]],"ltp":2.26,"tv":71.24,"id":424676}]}]}
{"op":"mcm","clk":"11798572523","pt":1723153074988,"mc":[{"id":"1.231501231","rc":[{"batb":[[0,2.22,14],[1,2.2,31.59],[2,2.02,4.55]],"ltp":2.26,"tv":71.24,"id":424676}]}]}
{"op":"mcm","clk":"11798572622","pt":1723153077299,"mc":[{"id":"1.231501231","rc":[{"batb":[[0,2.22,10]],"ltp":2.26,"tv":71.24,"id":424676}]}]}
{"op":"mcm","clk":"11798572651","pt":1723153078173,"mc":[{"id":"1.231501231","rc":[{"batb":[[0,2.2,31.59],[1,2.02,4.55],[2,1.91,4.55]],"ltp":2.26,"tv":71.24,"id":424676}]}]}
{"op":"mcm","clk":"11798572698","pt":1723153079612,"mc":[{"id":"1.231501231","rc":[{"batb":[[0,2.22,4],[1,2.2,31.59],[2,2.02,4.55]],"ltp":2.26,"tv":71.24,"id":424676}]}]}
{"op":"mcm","clk":"11798572739","pt":1723153080791,"mc":[{"id":"1.231501231","rc":[{"batb":[[0,2.24,10],[1,2.22,4],[2,2.2,31.59]],"ltp":2.26,"tv":71.24,"id":424676}]}]}
{"op":"mcm","clk":"11798572761","pt":1723153081917,"mc":[{"id":"1.231501231","rc":[{"batb":[[1,2.2,31.59],[2,2.02,4.55]],"ltp":2.26,"tv":71.24,"id":424676}]}]}
{"op":"mcm","clk":"11798572866","pt":1723153084584,"mc":[{"id":"1.231501231","rc":[{"batb":[[0,2.22,4]],"ltp":2.26,"tv":71.24,"id":424676}]}]}
{"op":"mcm","clk":"11798572909","pt":1723153086991,"mc":[{"id":"1.231501231","rc":[{"batb":[[0,2.22,10]],"ltp":2.26,"tv":71.24,"id":424676}]}]}
{"op":"mcm","clk":"11798572997","pt":1723153090523,"mc":[{"id":"1.231501231","rc":[{"batb":[[0,2.22,4]],"ltp":2.26,"tv":71.24,"id":424676}]}]}
{"op":"mcm","clk":"11798573070","pt":1723153092883,"mc":[{"id":"1.231501231","rc":[{"batb":[[0,2.22,10]],"ltp":2.26,"tv":71.24,"id":424676}]}]}
{"op":"mcm","clk":"11798573160","pt":1723153096206,"mc":[{"id":"1.231501231","rc":[{"batb":[[0,2.22,4]],"ltp":2.26,"tv":71.24,"id":424676}]}]}
{"op":"mcm","clk":"11798573243","pt":1723153098614,"mc":[{"id":"1.231501231","rc":[{"batb":[[0,2.24,10]],"ltp":2.26,"tv":71.24,"id":424676}]}]}
{"op":"mcm","clk":"11798573375","pt":1723153101946,"mc":[{"id":"1.231501231","rc":[{"batb":[[0,2.22,4]],"ltp":2.26,"tv":71.24,"id":424676}]}]}
{"op":"mcm","clk":"11798573467","pt":1723153104203,"mc":[{"id":"1.231501231","rc":[{"batb":[[0,2.24,10]],"ltp":2.26,"tv":71.24,"id":424676}]}]}
{"op":"mcm","clk":"11798573565","pt":1723153107635,"mc":[{"id":"1.231501231","rc":[{"batb":[[0,2.22,4]],"ltp":2.26,"tv":71.24,"id":424676}]}]}
{"op":"mcm","clk":"11798573639","pt":1723153110145,"mc":[{"id":"1.231501231","rc":[{"batb":[[0,2.22,10]],"ltp":2.26,"tv":71.24,"id":424676}]}]}
{"op":"mcm","clk":"11798573702","pt":1723153112553,"mc":[{"id":"1.231501231","rc":[{"batb":[[0,2.24,4],[1,2.22,10],[2,2.2,31.59]],"ltp":2.26,"tv":71.24,"id":424676}]}]}
{"op":"mcm","clk":"11798573733","pt":1723153113423,"mc":[{"id":"1.231501231","rc":[{"batb":[[1,2.2,31.59],[2,2.02,4.55]],"ltp":2.26,"tv":71.24,"id":424676}]}]}
{"op":"mcm","clk":"11798573791","pt":1723153114914,"mc":[{"id":"1.231501231","rc":[{"batb":[[0,2.2,31.59],[1,2.02,4.55],[2,1.91,4.55]],"ltp":2.26,"tv":71.24,"id":424676}]}]}
{"op":"mcm","clk":"11798573829","pt":1723153116040,"mc":[{"id":"1.231501231","rc":[{"batb":[[0,2.22,10],[1,2.2,31.59],[2,2.02,4.55]],"ltp":2.26,"tv":71.24,"id":424676}]}]}
{"op":"mcm","clk":"11798573904","pt":1723153118243,"mc":[{"id":"1.231501231","rc":[{"batb":[[0,2.24,4],[1,2.22,10],[2,2.2,31.59]],"ltp":2.26,"tv":71.24,"id":424676}]}]}
{"op":"mcm","clk":"11798573936","pt":1723153119217,"mc":[{"id":"1.231501231","rc":[{"batb":[[1,2.2,31.59],[2,2.02,4.55]],"ltp":2.26,"tv":71.24,"id":424676}]}]}
{"op":"mcm","clk":"11798573977","pt":1723153120552,"mc":[{"id":"1.231501231","rc":[{"batb":[[0,2.2,31.59],[1,2.02,4.55],[2,1.91,4.55]],"ltp":2.26,"tv":71.24,"id":424676}]}]}
{"op":"mcm","clk":"11798574034","pt":1723153122758,"mc":[{"id":"1.231501231","rc":[{"batb":[[0,2.22,14],[1,2.2,31.59],[2,2.02,4.55]],"ltp":2.26,"tv":71.24,"id":424676}]}]}
{"op":"mcm","clk":"11798574118","pt":1723153125836,"mc":[{"id":"1.231501231","rc":[{"batb":[[0,2.2,31.59],[1,2.02,4.55],[2,1.91,4.55]],"ltp":2.26,"tv":71.24,"id":424676}]}]}
{"op":"mcm","clk":"11798574245","pt":1723153129736,"mc":[{"id":"1.231501231","rc":[{"batb":[[0,2.22,14],[1,2.2,31.59],[2,2.02,4.55]],"ltp":2.26,"tv":71.24,"id":424676}]}]}
{"op":"mcm","clk":"11798574359","pt":1723153132964,"mc":[{"id":"1.231501231","rc":[{"batb":[[0,2.2,31.59],[1,2.02,4.55],[2,1.91,4.55]],"ltp":2.26,"tv":71.24,"id":424676}]}]}
{"op":"mcm","clk":"11798574513","pt":1723153137732,"mc":[{"id":"1.231501231","rc":[{"batb":[[0,2.22,14],[1,2.2,31.59],[2,2.02,4.55]],"ltp":2.26,"tv":71.24,"id":424676}]}]}
{"op":"mcm","clk":"11798574593","pt":1723153140038,"mc":[{"id":"1.231501231","rc":[{"batb":[[0,2.22,10]],"ltp":2.26,"tv":71.24,"id":424676}]}]}
{"op":"mcm","clk":"11798574626","pt":1723153141062,"mc":[{"id":"1.231501231","rc":[{"batb":[[0,2.2,31.59],[1,2.02,4.55],[2,1.91,4.55]],"ltp":2.26,"tv":71.24,"id":424676}]}]}
{"op":"mcm","clk":"11798574692","pt":1723153142552,"mc":[{"id":"1.231501231","rc":[{"batb":[[0,2.22,4],[1,2.2,31.59],[2,2.02,4.55]],"ltp":2.26,"tv":71.24,"id":424676}]}]}
{"op":"mcm","clk":"11798574727","pt":1723153143778,"mc":[{"id":"1.231501231","rc":[{"batb":[[0,2.24,10],[1,2.22,4],[2,2.2,31.59]],"ltp":2.26,"tv":71.24,"id":424676}]}]}
{"op":"mcm","clk":"11798574771","pt":1723153144982,"mc":[{"id":"1.231501231","rc":[{"batb":[[1,2.2,31.59],[2,2.02,4.55]],"ltp":2.26,"tv":71.24,"id":424676}]}]}
{"op":"mcm","clk":"11798574864","pt":1723153147242,"mc":[{"id":"1.231501231","rc":[{"batb":[[0,2.26,4]],"ltp":2.26,"tv":71.24,"id":424676}]}]}
{"op":"mcm","clk":"11798574942","pt":1723153149550,"mc":[{"id":"1.231501231","rc":[{"batb":[[0,2.28,10]],"ltp":2.26,"tv":71.24,"id":424676}]}]}
{"op":"mcm","clk":"11798575007","pt":1723153151960,"mc":[{"id":"1.231501231","rc":[{"batb":[[0,2.3,4],[1,2.28,10],[2,2.2,31.59]],"ltp":2.26,"tv":71.24,"id":424676}]}]}
{"op":"mcm","clk":"11798575043","pt":1723153152983,"mc":[{"id":"1.231501231","rc":[{"batb":[[1,2.2,31.59],[2,2.02,4.55]],"ltp":2.26,"tv":71.24,"id":424676}]}]}
{"op":"mcm","clk":"11798575084","pt":1723153154367,"mc":[{"id":"1.231501231","rc":[{"batb":[[0,2.2,31.59],[1,2.02,4.55],[2,1.91,4.55]],"ltp":2.26,"tv":71.24,"id":424676}]}]}
{"op":"mcm","clk":"11798575126","pt":1723153155499,"mc":[{"id":"1.231501231","rc":[{"batb":[[0,2.22,10],[1,2.2,31.59],[2,2.02,4.55]],"ltp":2.26,"tv":71.24,"id":424676}]}]}
{"op":"mcm","clk":"11798575210","pt":1723153157656,"mc":[{"id":"1.231501231","rc":[{"batb":[[0,2.24,4],[1,2.22,10],[2,2.2,31.59]],"ltp":2.26,"tv":71.24,"id":424676}]}]}
{"op":"mcm","clk":"11798575263","pt":1723153158984,"mc":[{"id":"1.231501231","rc":[{"batb":[[1,2.2,31.59],[2,2.02,4.55]],"ltp":2.26,"tv":71.24,"id":424676}]}]}
{"op":"mcm","clk":"11798575301","pt":1723153159961,"mc":[{"id":"1.231501231","rc":[{"batb":[[0,2.2,31.59],[1,2.02,4.55],[2,1.91,4.55]],"ltp":2.26,"tv":71.24,"id":424676}]}]}
{"op":"mcm","clk":"11798575339","pt":1723153161089,"mc":[{"id":"1.231501231","rc":[{"batb":[[0,2.22,10],[1,2.2,31.59],[2,2.02,4.55]],"ltp":2.26,"tv":71.24,"id":424676}]}]}
{"op":"mcm","clk":"11798575427","pt":1723153163449,"mc":[{"id":"1.231501231","rc":[{"batb":[[0,2.24,4],[1,2.22,10],[2,2.2,31.59]],"ltp":2.26,"tv":71.24,"id":424676}]}]}
{"op":"mcm","clk":"11798575450","pt":1723153164371,"mc":[{"id":"1.231501231","rc":[{"batb":[[1,2.2,31.59],[2,2.02,4.55]],"ltp":2.26,"tv":71.24,"id":424676}]}]}
{"op":"mcm","clk":"11798575518","pt":1723153165859,"mc":[{"id":"1.231501231","rc":[{"batb":[[0,2.2,31.59],[1,2.02,4.55],[2,1.91,4.55]],"ltp":2.26,"tv":71.24,"id":424676}]}]}
{"op":"mcm","clk":"11798575619","pt":1723153168884,"mc":[{"id":"1.231501231","rc":[{"batb":[[0,2.22,14],[1,2.2,31.59],[2,2.02,4.55]],"ltp":2.26,"tv":71.24,"id":424676}]}]}
{"op":"mcm","clk":"11798575692","pt":1723153171186,"mc":[{"id":"1.231501231","rc":[{"batb":[[0,2.22,10]],"ltp":2.26,"tv":71.24,"id":424676}]}]}
{"op":"mcm","clk":"11798575732","pt":1723153172165,"mc":[{"id":"1.231501231","rc":[{"batb":[[0,2.2,31.59],[1,2.02,4.55],[2,1.91,4.55]],"ltp":2.26,"tv":71.24,"id":424676}]}]}
{"op":"mcm","clk":"11798575791","pt":1723153173757,"mc":[{"id":"1.231501231","rc":[{"batb":[[0,2.22,4],[1,2.2,31.59],[2,2.02,4.55]],"ltp":2.26,"tv":71.24,"id":424676}]}]}
{"op":"mcm","clk":"11798575835","pt":1723153175184,"mc":[{"id":"1.231501231","rc":[{"batb":[[0,2.24,10],[1,2.22,4],[2,2.2,31.59]],"ltp":2.26,"tv":71.24,"id":424676}]}]}
{"op":"mcm","clk":"11798575868","pt":1723153176207,"mc":[{"id":"1.231501231","rc":[{"batb":[[1,2.2,31.59],[2,2.02,4.55]],"ltp":2.26,"tv":71.24,"id":424676}]}]}
{"op":"mcm","clk":"11798575952","pt":1723153178565,"mc":[{"id":"1.231501231","rc":[{"batb":[[0,2.22,4]],"ltp":2.26,"tv":71.24,"id":424676}]}]}
{"op":"mcm","clk":"11798576015","pt":1723153180971,"mc":[{"id":"1.231501231","rc":[{"batb":[[0,2.22,10]],"ltp":2.26,"tv":71.24,"id":424676}]}]}
{"op":"mcm","clk":"11798576105","pt":1723153184402,"mc":[{"id":"1.231501231","rc":[{"batb":[[0,2.22,4]],"ltp":2.26,"tv":71.24,"id":424676}]}]}
{"op":"mcm","clk":"11798576188","pt":1723153186705,"mc":[{"id":"1.231501231","rc":[{"batb":[[0,2.24,10]],"ltp":2.26,"tv":71.24,"id":424676}]}]}
{"op":"mcm","clk":"11798576271","pt":1723153189114,"mc":[{"id":"1.231501231","rc":[{"batb":[[0,2.26,4],[1,2.24,10],[2,2.2,31.59]],"ltp":2.26,"tv":71.24,"id":424676}]}]}
{"op":"mcm","clk":"11798576324","pt":1723153190096,"mc":[{"id":"1.231501231","rc":[{"batb":[[1,2.2,31.59],[2,2.02,4.55]],"ltp":2.26,"tv":71.24,"id":424676}]}]}
{"op":"mcm","clk":"11798576385","pt":1723153191482,"mc":[{"id":"1.231501231","rc":[{"batb":[[0,2.2,31.59],[1,2.02,4.55],[2,1.91,4.55]],"ltp":2.26,"tv":71.24,"id":424676}]}]}
{"op":"mcm","clk":"11798576461","pt":1723153193690,"mc":[{"id":"1.231501231","rc":[{"batb":[[0,2.24,4],[1,2.22,10],[2,2.2,31.59]],"ltp":2.26,"tv":71.24,"id":424676}]}]}
{"op":"mcm","clk":"11798576564","pt":1723153196097,"mc":[{"id":"1.231501231","rc":[{"batb":[[0,2.22,10],[1,2.2,31.59],[2,2.02,4.55]],"ltp":2.26,"tv":71.24,"id":424676}]}]}
{"op":"mcm","clk":"11798576593","pt":1723153197020,"mc":[{"id":"1.231501231","rc":[{"batb":[[0,2.2,31.59],[1,2.02,4.55],[2,1.91,4.55]],"ltp":2.26,"tv":71.24,"id":424676}]}]}
{"op":"mcm","clk":"11798576646","pt":1723153198405,"mc":[{"id":"1.231501231","rc":[{"batb":[[0,2.22,4],[1,2.2,31.59],[2,2.02,4.55]],"ltp":2.26,"tv":71.24,"id":424676}]}]}
{"op":"mcm","clk":"11798576757","pt":1723153200813,"mc":[{"id":"1.231501231","rc":[{"batb":[[0,2.24,10]],"ltp":2.26,"tv":71.24,"id":424676}]}]}
{"op":"mcm","clk":"11798576872","pt":1723153203898,"mc":[{"id":"1.231501231","rc":[{"batb":[[0,2.26,4]],"ltp":2.26,"tv":71.24,"id":424676}]}]}
{"op":"mcm","clk":"11798576948","pt":1723153206406,"mc":[{"id":"1.231501231","rc":[{"batb":[[0,2.22,10]],"ltp":2.26,"tv":71.24,"id":424676}]}]}
{"op":"mcm","clk":"11798577013","pt":1723153208715,"mc":[{"id":"1.231501231","rc":[{"batb":[[0,2.24,4],[1,2.22,10],[2,2.2,31.59]],"ltp":2.26,"tv":71.24,"id":424676}]}]}
{"op":"mcm","clk":"11798577056","pt":1723153209793,"mc":[{"id":"1.231501231","rc":[{"batb":[[1,2.2,31.59],[2,2.02,4.55]],"ltp":2.26,"tv":71.24,"id":424676}]}]}
{"op":"mcm","clk":"11798577091","pt":1723153211019,"mc":[{"id":"1.231501231","rc":[{"batb":[[0,2.2,31.59],[1,2.02,4.55],[2,1.91,4.55]],"ltp":2.26,"tv":71.24,"id":424676}]}]}
{"op":"mcm","clk":"11798577199","pt":1723153213897,"mc":[{"id":"1.231501231","rc":[{"batb":[[0,2.22,14],[1,2.2,31.59],[2,2.02,4.55]],"ltp":2.26,"tv":71.24,"id":424676}]}]}
{"op":"mcm","clk":"11798577276","pt":1723153216206,"mc":[{"id":"1.231501231","rc":[{"batb":[[0,2.22,10]],"ltp":2.26,"tv":71.24,"id":424676}]}]}
{"op":"mcm","clk":"11798577308","pt":1723153217231,"mc":[{"id":"1.231501231","rc":[{"batb":[[0,2.2,31.59],[1,2.02,4.55],[2,1.91,4.55]],"ltp":2.26,"tv":71.24,"id":424676}]}]}
{"op":"mcm","clk":"11798577344","pt":1723153218416,"mc":[{"id":"1.231501231","rc":[{"batb":[[0,2.22,4],[1,2.2,31.59],[2,2.02,4.55]],"ltp":2.26,"tv":71.24,"id":424676}]}]}
{"op":"mcm","clk":"11798577395","pt":1723153219746,"mc":[{"id":"1.231501231","rc":[{"batb":[[0,2.24,10],[1,2.22,4],[2,2.2,31.59]],"ltp":2.26,"tv":71.24,"id":424676}]}]}
{"op":"mcm","clk":"11798577431","pt":1723153220821,"mc":[{"id":"1.231501231","rc":[{"batb":[[1,2.2,31.59],[2,2.02,4.55]],"ltp":2.26,"tv":71.24,"id":424676}]}]}
{"op":"mcm","clk":"11798577516","pt":1723153223229,"mc":[{"id":"1.231501231","rc":[{"batb":[[0,2.26,4]],"ltp":2.26,"tv":71.24,"id":424676}]}]}
{"op":"mcm","clk":"11798577601","pt":1723153225836,"mc":[{"id":"1.231501231","rc":[{"batb":[[0,2.22,10]],"ltp":2.26,"tv":71.24,"id":424676}]}]}
{"op":"mcm","clk":"11798577698","pt":1723153228144,"mc":[{"id":"1.231501231","rc":[{"batb":[[0,2.24,4],[1,2.22,10],[2,2.2,31.59]],"ltp":2.26,"tv":71.24,"id":424676}]}]}
{"op":"mcm","clk":"11798577742","pt":1723153229221,"mc":[{"id":"1.231501231","rc":[{"batb":[[1,2.2,31.59],[2,2.02,4.55]],"ltp":2.26,"tv":71.24,"id":424676}]}]}
{"op":"mcm","clk":"11798577787","pt":1723153230450,"mc":[{"id":"1.231501231","rc":[{"batb":[[0,2.2,31.59],[1,2.02,4.55],[2,1.91,4.55]],"ltp":2.26,"tv":71.24,"id":424676}]}]}
{"op":"mcm","clk":"11798577827","pt":1723153231627,"mc":[{"id":"1.231501231","rc":[{"batb":[[0,2.22,10],[1,2.2,31.59],[2,2.02,4.55]],"ltp":2.26,"tv":71.24,"id":424676}]}]}
{"op":"mcm","clk":"11798577859","pt":1723153232754,"mc":[{"id":"1.231501231","rc":[{"batb":[[0,2.24,4],[1,2.22,10],[2,2.2,31.59]],"ltp":2.26,"tv":71.24,"id":424676}]}]}
{"op":"mcm","clk":"11798577913","pt":1723153234957,"mc":[{"id":"1.231501231","rc":[{"batb":[[1,2.2,31.59],[2,2.02,4.55]],"ltp":2.26,"tv":71.24,"id":424676}]}]}
{"op":"mcm","clk":"11798577920","pt":1723153235161,"mc":[{"id":"1.231501231","rc":[{"batb":[[0,2.2,31.59],[1,2.02,4.55],[2,1.91,4.55]],"ltp":2.26,"tv":71.24,"id":424676}]}]}
{"op":"mcm","clk":"11798577982","pt":1723153237268,"mc":[{"id":"1.231501231","rc":[{"batb":[[0,2.22,14],[1,2.2,31.59],[2,2.02,4.55]],"ltp":2.26,"tv":71.24,"id":424676}]}]}
{"op":"mcm","clk":"11798578046","pt":1723153239466,"mc":[{"id":"1.231501231","rc":[{"batb":[[0,2.22,10]],"ltp":2.26,"tv":71.24,"id":424676}]}]}
{"op":"mcm","clk":"11798578081","pt":1723153240443,"mc":[{"id":"1.231501231","rc":[{"batb":[[0,2.2,31.59],[1,2.02,4.55],[2,1.91,4.55]],"ltp":2.26,"tv":71.24,"id":424676}]}]}
{"op":"mcm","clk":"11798578151","pt":1723153242948,"mc":[{"id":"1.231501231","rc":[{"batb":[[0,2.22,14],[1,2.2,31.59],[2,2.02,4.55]],"ltp":2.26,"tv":71.24,"id":424676}]}]}
{"op":"mcm","clk":"11798578232","pt":1723153245361,"mc":[{"id":"1.231501231","rc":[{"batb":[[0,2.22,10]],"ltp":2.26,"tv":71.24,"id":424676}]}]}
{"op":"mcm","clk":"11798578255","pt":1723153246337,"mc":[{"id":"1.231501231","rc":[{"batb":[[0,2.2,31.59],[1,2.02,4.55],[2,1.91,4.55]],"ltp":2.26,"tv":71.24,"id":424676}]}]}
{"op":"mcm","clk":"11798578298","pt":1723153247561,"mc":[{"id":"1.231501231","rc":[{"batb":[[0,2.22,4],[1,2.2,31.59],[2,2.02,4.55]],"ltp":2.26,"tv":71.24,"id":424676}]}]}
{"op":"mcm","clk":"11798578321","pt":1723153248739,"mc":[{"id":"1.231501231","rc":[{"batb":[[0,2.24,10],[1,2.22,4],[2,2.2,31.59]],"ltp":2.26,"tv":71.24,"id":424676}]}]}
{"op":"mcm","clk":"11798578361","pt":1723153249869,"mc":[{"id":"1.231501231","rc":[{"batb":[[1,2.2,31.59],[2,2.02,4.55]],"ltp":2.26,"tv":71.24,"id":424676}]}]}
{"op":"mcm","clk":"11798578442","pt":1723153252169,"mc":[{"id":"1.231501231","rc":[{"batb":[[0,2.22,4]],"ltp":2.26,"tv":71.24,"id":424676}]}]}
{"op":"mcm","clk":"11798578510","pt":1723153254676,"mc":[{"id":"1.231501231","rc":[{"batb":[[0,2.22,10]],"ltp":2.26,"tv":71.24,"id":424676}]}]}
{"op":"mcm","clk":"11798578558","pt":1723153256874,"mc":[{"id":"1.231501231","rc":[{"batb":[[0,2.24,4],[1,2.22,10],[2,2.2,31.59]],"ltp":2.26,"tv":71.24,"id":424676}]}]}
{"op":"mcm","clk":"11798578596","pt":1723153257950,"mc":[{"id":"1.231501231","rc":[{"batb":[[1,2.2,31.59],[2,2.02,4.55]],"ltp":2.26,"tv":71.24,"id":424676}]}]}
{"op":"mcm","clk":"11798578634","pt":1723153259181,"mc":[{"id":"1.231501231","rc":[{"batb":[[0,2.2,31.59],[1,2.02,4.55],[2,1.91,4.55]],"ltp":2.26,"tv":71.24,"id":424676}]}]}
{"op":"mcm","clk":"11798578684","pt":1723153261585,"mc":[{"id":"1.231501231","rc":[{"batb":[[0,2.22,14],[1,2.2,31.59],[2,2.02,4.55]],"ltp":2.26,"tv":71.24,"id":424676}]}]}
{"op":"mcm","clk":"11798578743","pt":1723153263892,"mc":[{"id":"1.231501231","rc":[{"batb":[[0,2.22,10]],"ltp":2.26,"tv":71.24,"id":424676}]}]}
{"op":"mcm","clk":"11798578768","pt":1723153264966,"mc":[{"id":"1.231501231","rc":[{"batb":[[0,2.2,31.59],[1,2.02,4.55],[2,1.91,4.55]],"ltp":2.26,"tv":71.24,"id":424676}]}]}
{"op":"mcm","clk":"11798578800","pt":1723153266044,"mc":[{"id":"1.231501231","rc":[{"batb":[[0,2.22,4],[1,2.2,31.59],[2,2.02,4.55]],"ltp":2.26,"tv":71.24,"id":424676}]}]}
{"op":"mcm","clk":"11798578840","pt":1723153267479,"mc":[{"id":"1.231501231","rc":[{"batb":[[0,2.24,10],[1,2.22,4],[2,2.2,31.59]],"ltp":2.26,"tv":71.24,"id":424676}]}]}
{"op":"mcm","clk":"11798578884","pt":1723153268457,"mc":[{"id":"1.231501231","rc":[{"batb":[[1,2.2,31.59],[2,2.02,4.55]],"ltp":2.26,"tv":71.24,"id":424676}]}]}
{"op":"mcm","clk":"11798578957","pt":1723153270965,"mc":[{"id":"1.231501231","rc":[{"batb":[[0,2.22,4]],"ltp":2.26,"tv":71.24,"id":424676}]}]}
{"op":"mcm","clk":"11798579029","pt":1723153273270,"mc":[{"id":"1.231501231","rc":[{"batb":[[0,2.22,10]],"ltp":2.26,"tv":71.24,"id":424676}]}]}
{"op":"mcm","clk":"11798579113","pt":1723153276654,"mc":[{"id":"1.231501231","rc":[{"batb":[[0,2.22,4]],"ltp":2.26,"tv":71.24,"id":424676}]}]}
{"op":"mcm","clk":"11798579190","pt":1723153278855,"mc":[{"id":"1.231501231","rc":[{"batb":[[0,2.22,10]],"ltp":2.26,"tv":71.24,"id":424676}]}]}
{"op":"mcm","clk":"11798579297","pt":1723153282190,"mc":[{"id":"1.231501231","rc":[{"batb":[[0,2.22,4]],"ltp":2.26,"tv":71.24,"id":424676}]}]}
{"op":"mcm","clk":"11798579373","pt":1723153284700,"mc":[{"id":"1.231501231","rc":[{"batb":[[0,2.22,10]],"ltp":2.26,"tv":71.24,"id":424676}]}]}
{"op":"mcm","clk":"11798579526","pt":1723153287984,"mc":[{"id":"1.231501231","rc":[{"batb":[[0,2.24,4]],"ltp":2.26,"tv":71.24,"id":424676}]}]}
{"op":"mcm","clk":"11798579564","pt":1723153289412,"mc":[{"id":"1.231501231","rc":[{"batb":[[0,2.2,31.59],[1,2.02,4.55],[2,1.91,4.55]],"ltp":2.26,"tv":71.24,"id":424676}]}]}
{"op":"mcm","clk":"11798579642","pt":1723153291672,"mc":[{"id":"1.231501231","rc":[{"batb":[[0,2.22,14],[1,2.2,31.59],[2,2.02,4.55]],"ltp":2.26,"tv":71.24,"id":424676}]}]}
{"op":"mcm","clk":"11798579699","pt":1723153294188,"mc":[{"id":"1.231501231","rc":[{"batb":[[0,2.22,10]],"ltp":2.26,"tv":71.24,"id":424676}]}]}
{"op":"mcm","clk":"11798579725","pt":1723153295106,"mc":[{"id":"1.231501231","rc":[{"batb":[[0,2.2,31.59],[1,2.02,4.55],[2,1.91,4.55]],"ltp":2.26,"tv":71.24,"id":424676}]}]}
{"op":"mcm","clk":"11798579777","pt":1723153297514,"mc":[{"id":"1.231501231","rc":[{"batb":[[0,2.22,14],[1,2.2,31.59],[2,2.02,4.55]],"ltp":2.26,"tv":71.24,"id":424676}]}]}
{"op":"mcm","clk":"11798579843","pt":1723153299821,"mc":[{"id":"1.231501231","rc":[{"batb":[[0,2.22,10]],"ltp":2.26,"tv":71.24,"id":424676}]}]}
{"op":"mcm","clk":"11798579874","pt":1723153300897,"mc":[{"id":"1.231501231","rc":[{"batb":[[0,2.2,31.59],[1,2.02,4.55],[2,1.91,4.55]],"ltp":2.26,"tv":71.24,"id":424676}]}]}
{"op":"mcm","clk":"11798579943","pt":1723153303199,"mc":[{"id":"1.231501231","rc":[{"batb":[[0,2.22,14],[1,2.2,31.59],[2,2.02,4.55]],"ltp":2.26,"tv":71.24,"id":424676}]}]}
{"op":"mcm","clk":"11798580013","pt":1723153305606,"mc":[{"id":"1.231501231","rc":[{"batb":[[0,2.22,10]],"ltp":2.26,"tv":71.24,"id":424676}]}]}
{"op":"mcm","clk":"11798580047","pt":1723153306626,"mc":[{"id":"1.231501231","rc":[{"batb":[[0,2.2,31.59],[1,2.02,4.55],[2,1.91,4.55]],"ltp":2.26,"tv":71.24,"id":424676}]}]}
{"op":"mcm","clk":"11798580119","pt":1723153309033,"mc":[{"id":"1.231501231","rc":[{"batb":[[0,2.22,14],[1,2.2,31.59],[2,2.02,4.55]],"ltp":2.26,"tv":71.24,"id":424676}]}]}
{"op":"mcm","clk":"11798580192","pt":1723153311190,"mc":[{"id":"1.231501231","rc":[{"batb":[[0,2.22,10]],"ltp":2.26,"tv":71.24,"id":424676}]}]}
{"op":"mcm","clk":"11798580228","pt":1723153312416,"mc":[{"id":"1.231501231","rc":[{"batb":[[0,2.2,31.59],[1,2.02,4.55],[2,1.91,4.55]],"ltp":2.26,"tv":71.24,"id":424676}]}]}
{"op":"mcm","clk":"11798580262","pt":1723153313593,"mc":[{"id":"1.231501231","rc":[{"batb":[[0,2.22,4],[1,2.2,31.59],[2,2.02,4.55]],"ltp":2.26,"tv":71.24,"id":424676}]}]}
{"op":"mcm","clk":"11798580299","pt":1723153314829,"mc":[{"id":"1.231501231","rc":[{"batb":[[0,2.24,10],[1,2.22,4],[2,2.2,31.59]],"ltp":2.26,"tv":71.24,"id":424676}]}]}
{"op":"mcm","clk":"11798580344","pt":1723153315999,"mc":[{"id":"1.231501231","rc":[{"batb":[[1,2.2,31.59],[2,2.02,4.55]],"ltp":2.26,"tv":71.24,"id":424676}]}]}
{"op":"mcm","clk":"11798580440","pt":1723153318405,"mc":[{"id":"1.231501231","rc":[{"batb":[[0,2.22,4]],"ltp":2.26,"tv":71.24,"id":424676}]}]}
{"op":"mcm","clk":"11798580522","pt":1723153320809,"mc":[{"id":"1.231501231","rc":[{"batb":[[0,2.2,31.59],[1,2.02,4.55],[2,1.91,4.55]],"ltp":2.26,"tv":71.24,"id":424676}]}]}
{"op":"mcm","clk":"11798580532","pt":1723153321014,"mc":[{"id":"1.231501231","rc":[{"batb":[[0,2.22,10],[1,2.2,31.59],[2,2.02,4.55]],"ltp":2.26,"tv":71.24,"id":424676}]}]}
{"op":"mcm","clk":"11798580613","pt":1723153323730,"mc":[{"id":"1.231501231","rc":[{"batb":[[0,2.24,4],[1,2.22,10],[2,2.2,31.59]],"ltp":2.26,"tv":71.24,"id":424676}]}]}
{"op":"mcm","clk":"11798580640","pt":1723153324499,"mc":[{"id":"1.231501231","rc":[{"batb":[[1,2.2,31.59],[2,2.02,4.55]],"ltp":2.26,"tv":71.24,"id":424676}]}]}
{"op":"mcm","clk":"11798580699","pt":1723153326237,"mc":[{"id":"1.231501231","rc":[{"batb":[[0,2.2,31.59],[1,2.02,4.55],[2,1.91,4.55]],"ltp":2.26,"tv":71.24,"id":424676}]}]}
{"op":"mcm","clk":"11798580766","pt":1723153328701,"mc":[{"id":"1.231501231","rc":[{"batb":[[0,2.22,14],[1,2.2,31.59],[2,2.02,4.55]],"ltp":2.26,"tv":71.24,"id":424676}]}]}
{"op":"mcm","clk":"11798580824","pt":1723153331050,"mc":[{"id":"1.231501231","rc":[{"batb":[[0,2.22,10]],"ltp":2.26,"tv":71.24,"id":424676}]}]}
{"op":"mcm","clk":"11798580847","pt":1723153332023,"mc":[{"id":"1.231501231","rc":[{"batb":[[0,2.2,31.59],[1,2.02,4.55],[2,1.91,4.55]],"ltp":2.26,"tv":71.24,"id":424676}]}]}
{"op":"mcm","clk":"11798580883","pt":1723153333357,"mc":[{"id":"1.231501231","rc":[{"batb":[[0,2.22,4],[1,2.2,31.59],[2,2.02,4.55]],"ltp":2.26,"tv":71.24,"id":424676}]}]}
{"op":"mcm","clk":"11798580953","pt":1723153335728,"mc":[{"id":"1.231501231","rc":[{"batb":[[0,2.24,10]],"ltp":2.26,"tv":71.24,"id":424676}]}]}
{"op":"mcm","clk":"11798581029","pt":1723153338534,"mc":[{"id":"1.231501231","rc":[{"batb":[[0,2.22,4]],"ltp":2.26,"tv":71.24,"id":424676}]}]}
{"op":"mcm","clk":"11798581113","pt":1723153340936,"mc":[{"id":"1.231501231","rc":[{"batb":[[0,2.22,10]],"ltp":2.26,"tv":71.24,"id":424676}]}]}
{"op":"mcm","clk":"11798581198","pt":1723153343348,"mc":[{"id":"1.231501231","rc":[{"batb":[[0,2.24,4],[1,2.22,10],[2,2.2,31.59]],"ltp":2.26,"tv":71.24,"id":424676}]}]}
{"op":"mcm","clk":"11798581222","pt":1723153344369,"mc":[{"id":"1.231501231","rc":[{"batb":[[1,2.2,31.59],[2,2.02,4.55]],"ltp":2.26,"tv":71.24,"id":424676}]}]}
{"op":"mcm","clk":"11798581277","pt":1723153345650,"mc":[{"id":"1.231501231","rc":[{"batb":[[0,2.2,31.59],[1,2.02,4.55],[2,1.91,4.55]],"ltp":2.26,"tv":71.24,"id":424676}]}]}
{"op":"mcm","clk":"11798581338","pt":1723153348057,"mc":[{"id":"1.231501231","rc":[{"batb":[[0,2.22,14],[1,2.2,31.59],[2,2.02,4.55]],"ltp":2.26,"tv":71.24,"id":424676}]}]}
{"op":"mcm","clk":"11798581408","pt":1723153350468,"mc":[{"id":"1.231501231","rc":[{"batb":[[0,2.22,10]],"ltp":2.26,"tv":71.24,"id":424676}]}]}
{"op":"mcm","clk":"11798581428","pt":1723153351343,"mc":[{"id":"1.231501231","rc":[{"batb":[[0,2.2,31.59],[1,2.02,4.55],[2,1.91,4.55]],"ltp":2.26,"tv":71.24,"id":424676}]}]}
{"op":"mcm","clk":"11798581526","pt":1723153354877,"mc":[{"id":"1.231501231","rc":[{"batb":[[0,2.22,14],[1,2.2,31.59],[2,2.02,4.55]],"ltp":2.26,"tv":71.24,"id":424676}]}]}
{"op":"mcm","clk":"11798581596","pt":1723153357184,"mc":[{"id":"1.231501231","rc":[{"batb":[[0,2.22,10]],"ltp":2.26,"tv":71.24,"id":424676}]}]}
{"op":"mcm","clk":"11798581621","pt":1723153358060,"mc":[{"id":"1.231501231","rc":[{"batb":[[0,2.2,31.59],[1,2.02,4.55],[2,1.91,4.55]],"ltp":2.26,"tv":71.24,"id":424676}]}]}
{"op":"mcm","clk":"11798581661","pt":1723153359546,"mc":[{"id":"1.231501231","rc":[{"batb":[[0,2.22,4],[1,2.2,31.59],[2,2.02,4.55]],"ltp":2.26,"tv":71.24,"id":424676}]}]}
{"op":"mcm","clk":"11798581686","pt":1723153360771,"mc":[{"id":"1.231501231","rc":[{"batb":[[0,2.24,10],[1,2.22,4],[2,2.2,31.59]],"ltp":2.26,"tv":71.24,"id":424676}]}]}
{"op":"mcm","clk":"11798581707","pt":1723153361844,"mc":[{"id":"1.231501231","rc":[{"batb":[[1,2.2,31.59],[2,2.02,4.55]],"ltp":2.26,"tv":71.24,"id":424676}]}]}
{"op":"mcm","clk":"11798581770","pt":1723153364259,"mc":[{"id":"1.231501231","rc":[{"batb":[[0,2.22,4]],"ltp":2.26,"tv":71.24,"id":424676}]}]}
{"op":"mcm","clk":"11798581849","pt":1723153366772,"mc":[{"id":"1.231501231","rc":[{"batb":[[0,2.22,10]],"ltp":2.26,"tv":71.24,"id":424676}]}]}
{"op":"mcm","clk":"11798581931","pt":1723153368974,"mc":[{"id":"1.231501231","rc":[{"batb":[[0,2.24,4],[1,2.22,10],[2,2.2,31.59]],"ltp":2.26,"tv":71.24,"id":424676}]}]}
{"op":"mcm","clk":"11798581969","pt":1723153369948,"mc":[{"id":"1.231501231","rc":[{"batb":[[1,2.2,31.59],[2,2.02,4.55]],"ltp":2.26,"tv":71.24,"id":424676}]}]}
{"op":"mcm","clk":"11798581996","pt":1723153371148,"mc":[{"id":"1.231501231","rc":[{"batb":[[0,2.2,31.59],[1,2.02,4.55],[2,1.91,4.55]],"ltp":2.26,"tv":71.24,"id":424676}]}]}
{"op":"mcm","clk":"11798582098","pt":1723153374583,"mc":[{"id":"1.231501231","rc":[{"batb":[[0,2.22,14],[1,2.2,31.59],[2,2.02,4.55]],"ltp":2.26,"tv":71.24,"id":424676}]}]}
{"op":"mcm","clk":"11798582166","pt":1723153376855,"mc":[{"id":"1.231501231","rc":[{"batb":[[0,2.22,10]],"ltp":2.26,"tv":71.24,"id":424676}]}]}
{"op":"mcm","clk":"11798582192","pt":1723153377784,"mc":[{"id":"1.231501231","rc":[{"batb":[[0,2.2,31.59],[1,2.02,4.55],[2,1.91,4.55]],"ltp":2.26,"tv":71.24,"id":424676}]}]}
{"op":"mcm","clk":"11798582287","pt":1723153379512,"mc":[{"id":"1.231501231","rc":[{"batb":[[0,2.22,4],[1,2.2,31.59],[2,2.02,4.55]],"ltp":2.26,"tv":71.24,"id":424676}]}]}
{"op":"mcm","clk":"11798582332","pt":1723153380703,"mc":[{"id":"1.231501231","rc":[{"batb":[[0,2.24,10],[1,2.22,4],[2,2.2,31.59]],"ltp":2.26,"tv":71.24,"id":424676}]}]}
{"op":"mcm","clk":"11798582371","pt":1723153381883,"mc":[{"id":"1.231501231","rc":[{"batb":[[1,2.2,31.59],[2,2.02,4.55]],"ltp":2.26,"tv":71.24,"id":424676}]}]}
{"op":"mcm","clk":"11798582455","pt":1723153383993,"mc":[{"id":"1.231501231","rc":[{"batb":[[0,2.2,31.59],[1,2.02,4.55],[2,1.91,4.55]],"ltp":2.26,"tv":71.24,"id":424676}]}]}
{"op":"mcm","clk":"11798582460","pt":1723153384093,"mc":[{"id":"1.231501231","rc":[{"batb":[[0,2.26,4],[1,2.2,31.59],[2,2.02,4.55]],"ltp":2.26,"tv":71.24,"id":424676}]}]}
{"op":"mcm","clk":"11798582525","pt":1723153386500,"mc":[{"id":"1.231501231","rc":[{"batb":[[0,2.28,10]],"ltp":2.26,"tv":71.24,"id":424676}]}]}
{"op":"mcm","clk":"11798582602","pt":1723153388806,"mc":[{"id":"1.231501231","rc":[{"batb":[[0,2.3,4],[1,2.28,10],[2,2.2,31.59]],"ltp":2.26,"tv":71.24,"id":424676}]}]}
{"op":"mcm","clk":"11798582631","pt":1723153389783,"mc":[{"id":"1.231501231","rc":[{"batb":[[1,2.2,31.59],[2,2.02,4.55]],"ltp":2.26,"tv":71.24,"id":424676}]}]}
{"op":"mcm","clk":"11798582677","pt":1723153391069,"mc":[{"id":"1.231501231","rc":[{"batb":[[0,2.2,31.59],[1,2.02,4.55],[2,1.91,4.55]],"ltp":2.26,"tv":71.24,"id":424676}]}]}
{"op":"mcm","clk":"11798582726","pt":1723153392299,"mc":[{"id":"1.231501231","rc":[{"batb":[[0,2.22,10],[1,2.2,31.59],[2,2.02,4.55]],"ltp":2.26,"tv":71.24,"id":424676}]}]}
{"op":"mcm","clk":"11798582751","pt":1723153393377,"mc":[{"id":"1.231501231","rc":[{"batb":[[0,2.24,4],[1,2.22,10],[2,2.2,31.59]],"ltp":2.26,"tv":71.24,"id":424676}]}]}
{"op":"mcm","clk":"11798582825","pt":1723153395684,"mc":[{"id":"1.231501231","rc":[{"batb":[[0,2.2,31.59],[1,2.02,4.55],[2,1.91,4.55]],"ltp":2.26,"tv":71.24,"id":424676}]}]}
{"op":"mcm","clk":"11798582884","pt":1723153397892,"mc":[{"id":"1.231501231","rc":[{"batb":[[0,2.24,4],[1,2.22,10],[2,2.2,31.59]],"ltp":2.26,"tv":71.24,"id":424676}]}]}
{"op":"mcm","clk":"11798582941","pt":1723153400204,"mc":[{"id":"1.231501231","rc":[{"batb":[[0,2.22,10],[1,2.2,31.59],[2,2.02,4.55]],"ltp":2.26,"tv":71.24,"id":424676}]}]}
{"op":"mcm","clk":"11798582964","pt":1723153401225,"mc":[{"id":"1.231501231","rc":[{"batb":[[0,2.2,31.59],[1,2.02,4.55],[2,1.91,4.55]],"ltp":2.26,"tv":71.24,"id":424676}]}]}
{"op":"mcm","clk":"11798583005","pt":1723153402525,"mc":[{"id":"1.231501231","rc":[{"batb":[[0,2.22,4],[1,2.2,31.59],[2,2.02,4.55]],"ltp":2.26,"tv":71.24,"id":424676}]}]}
{"op":"mcm","clk":"11798583045","pt":1723153403710,"mc":[{"id":"1.231501231","rc":[{"batb":[[0,2.24,10],[1,2.22,4],[2,2.2,31.59]],"ltp":2.26,"tv":71.24,"id":424676}]}]}
{"op":"mcm","clk":"11798583084","pt":1723153404789,"mc":[{"id":"1.231501231","rc":[{"batb":[[1,2.2,31.59],[2,2.02,4.55]],"ltp":2.26,"tv":71.24,"id":424676}]}]}
{"op":"mcm","clk":"11798583154","pt":1723153406992,"mc":[{"id":"1.231501231","rc":[{"batb":[[0,2.2,31.59],[1,2.02,4.55],[2,1.91,4.55]],"ltp":2.26,"tv":71.24,"id":424676}]}]}
{"op":"mcm","clk":"11798583157","pt":1723153407095,"mc":[{"id":"1.231501231","rc":[{"batb":[[0,2.22,4],[1,2.2,31.59],[2,2.02,4.55]],"ltp":2.26,"tv":71.24,"id":424676}]}]}
{"op":"mcm","clk":"11798583224","pt":1723153409508,"mc":[{"id":"1.231501231","rc":[{"batb":[[0,2.22,10]],"ltp":2.26,"tv":71.24,"id":424676}]}]}
{"op":"mcm","clk":"11798583313","pt":1723153413002,"mc":[{"id":"1.231501231","rc":[{"batb":[[0,2.22,4]],"ltp":2.26,"tv":71.24,"id":424676}]}]}
{"op":"mcm","clk":"11798583360","pt":1723153415200,"mc":[{"id":"1.231501231","rc":[{"batb":[[0,2.24,10]],"ltp":2.26,"tv":71.24,"id":424676}]}]}
{"op":"mcm","clk":"11798583452","pt":1723153418638,"mc":[{"id":"1.231501231","rc":[{"batb":[[0,2.22,4]],"ltp":2.26,"tv":71.24,"id":424676}]}]}
{"op":"mcm","clk":"11798583533","pt":1723153421146,"mc":[{"id":"1.231501231","rc":[{"batb":[[0,2.22,10]],"ltp":2.26,"tv":71.24,"id":424676}]}]}
{"op":"mcm","clk":"11798583622","pt":1723153424326,"mc":[{"id":"1.231501231","rc":[{"batb":[[0,2.24,4]],"ltp":2.26,"tv":71.24,"id":424676}]}]}
{"op":"mcm","clk":"11798583700","pt":1723153426837,"mc":[{"id":"1.231501231","rc":[{"batb":[[0,2.22,10]],"ltp":2.26,"tv":71.24,"id":424676}]}]}
{"op":"mcm","clk":"11798583778","pt":1723153429145,"mc":[{"id":"1.231501231","rc":[{"batb":[[0,2.24,4],[1,2.22,10],[2,2.2,31.59]],"ltp":2.26,"tv":71.24,"id":424676}]}]}
{"op":"mcm","clk":"11798583820","pt":1723153430217,"mc":[{"id":"1.231501231","rc":[{"batb":[[1,2.2,31.59],[2,2.02,4.55]],"ltp":2.26,"tv":71.24,"id":424676}]}]}
{"op":"mcm","clk":"11798583878","pt":1723153431554,"mc":[{"id":"1.231501231","rc":[{"batb":[[0,2.2,31.59],[1,2.02,4.55],[2,1.91,4.55]],"ltp":2.26,"tv":71.24,"id":424676}]}]}
{"op":"mcm","clk":"11798583971","pt":1723153433856,"mc":[{"id":"1.231501231","rc":[{"batb":[[0,2.22,14],[1,2.2,31.59],[2,2.02,4.55]],"ltp":2.26,"tv":71.24,"id":424676}]}]}
{"op":"mcm","clk":"11798584036","pt":1723153436214,"mc":[{"id":"1.231501231","rc":[{"batb":[[0,2.22,10]],"ltp":2.26,"tv":71.24,"id":424676}]}]}
{"op":"mcm","clk":"11798584068","pt":1723153437241,"mc":[{"id":"1.231501231","rc":[{"batb":[[0,2.2,31.59],[1,2.02,4.55],[2,1.91,4.55]],"ltp":2.26,"tv":71.24,"id":424676}]}]}
{"op":"mcm","clk":"11798584202","pt":1723153440036,"mc":[{"id":"1.231501231","rc":[{"batb":[[0,2.22,14],[1,2.2,31.59],[2,2.02,4.55]],"ltp":2.26,"tv":71.24,"id":424676}]}]}
{"op":"mcm","clk":"11798584274","pt":1723153442224,"mc":[{"id":"1.231501231","rc":[{"batb":[[0,2.22,10]],"ltp":2.26,"tv":71.24,"id":424676}]}]}
{"op":"mcm","clk":"11798584317","pt":1723153443245,"mc":[{"id":"1.231501231","rc":[{"batb":[[0,2.2,31.59],[1,2.02,4.55],[2,1.91,4.55]],"ltp":2.26,"tv":71.24,"id":424676}]}]}
{"op":"mcm","clk":"11798584403","pt":1723153445349,"mc":[{"id":"1.231501231","rc":[{"batb":[[0,2.22,14],[1,2.2,31.59],[2,2.02,4.55]],"ltp":2.26,"tv":71.24,"id":424676}]}]}
{"op":"mcm","clk":"11798584486","pt":1723153447650,"mc":[{"id":"1.231501231","rc":[{"batb":[[0,2.22,10]],"ltp":2.26,"tv":71.24,"id":424676}]}]}
{"op":"mcm","clk":"11798584518","pt":1723153448674,"mc":[{"id":"1.231501231","rc":[{"batb":[[0,2.2,31.59],[1,2.02,4.55],[2,1.91,4.55]],"ltp":2.26,"tv":71.24,"id":424676}]}]}
{"op":"mcm","clk":"11798584577","pt":1723153450061,"mc":[{"id":"1.231501231","rc":[{"batb":[[0,2.22,4],[1,2.2,31.59],[2,2.02,4.55]],"ltp":2.26,"tv":71.24,"id":424676}]}]}
{"op":"mcm","clk":"11798584625","pt":1723153451242,"mc":[{"id":"1.231501231","rc":[{"batb":[[0,2.24,10],[1,2.22,4],[2,2.2,31.59]],"ltp":2.26,"tv":71.24,"id":424676}]}]}
{"op":"mcm","clk":"11798584666","pt":1723153452471,"mc":[{"id":"1.231501231","rc":[{"batb":[[1,2.2,31.59],[2,2.02,4.55]],"ltp":2.26,"tv":71.24,"id":424676}]}]}
{"op":"mcm","clk":"11798584733","pt":1723153454773,"mc":[{"id":"1.231501231","rc":[{"batb":[[0,2.22,4]],"ltp":2.26,"tv":71.24,"id":424676}]}]}
{"op":"mcm","clk":"11798584819","pt":1723153457183,"mc":[{"id":"1.231501231","rc":[{"batb":[[0,2.22,10]],"ltp":2.26,"tv":71.24,"id":424676}]}]}
{"op":"mcm","clk":"11798584909","pt":1723153459494,"mc":[{"id":"1.231501231","rc":[{"batb":[[0,2.24,4],[1,2.22,10],[2,2.2,31.59]],"ltp":2.26,"tv":71.24,"id":424676}]}]}
{"op":"mcm","clk":"11798584950","pt":1723153460469,"mc":[{"id":"1.231501231","rc":[{"batb":[[1,2.2,31.59],[2,2.02,4.55]],"ltp":2.26,"tv":71.24,"id":424676}]}]}
{"op":"mcm","clk":"11798585008","pt":1723153461750,"mc":[{"id":"1.231501231","rc":[{"batb":[[0,2.2,31.59],[1,2.02,4.55],[2,1.91,4.55]],"ltp":2.26,"tv":71.24,"id":424676}]}]}
{"op":"mcm","clk":"11798585053","pt":1723153462879,"mc":[{"id":"1.231501231","rc":[{"batb":[[0,2.22,10],[1,2.2,31.59],[2,2.02,4.55]],"ltp":2.26,"tv":71.24,"id":424676}]}]}
{"op":"mcm","clk":"11798585115","pt":1723153464059,"mc":[{"id":"1.231501231","rc":[{"batb":[[0,2.24,4],[1,2.22,10],[2,2.2,31.59]],"ltp":2.26,"tv":71.24,"id":424676}]}]}
{"op":"mcm","clk":"11798585214","pt":1723153466364,"mc":[{"id":"1.231501231","rc":[{"batb":[[0,2.2,31.59],[1,2.02,4.55],[2,1.91,4.55]],"ltp":2.26,"tv":71.24,"id":424676}]}]}
{"op":"mcm","clk":"11798585299","pt":1723153468569,"mc":[{"id":"1.231501231","rc":[{"batb":[[0,2.22,14],[1,2.2,31.59],[2,2.02,4.55]],"ltp":2.26,"tv":71.24,"id":424676}]}]}
{"op":"mcm","clk":"11798585385","pt":1723153470976,"mc":[{"id":"1.231501231","rc":[{"batb":[[0,2.22,10]],"ltp":2.26,"tv":71.24,"id":424676}]}]}
{"op":"mcm","clk":"11798585412","pt":1723153471899,"mc":[{"id":"1.231501231","rc":[{"batb":[[0,2.2,31.59],[1,2.02,4.55],[2,1.91,4.55]],"ltp":2.26,"tv":71.24,"id":424676}]}]}
{"op":"mcm","clk":"11798585484","pt":1723153474205,"mc":[{"id":"1.231501231","rc":[{"batb":[[0,2.22,14],[1,2.2,31.59],[2,2.02,4.55]],"ltp":2.26,"tv":71.24,"id":424676}]}]}
{"op":"mcm","clk":"11798585554","pt":1723153476472,"mc":[{"id":"1.231501231","rc":[{"batb":[[0,2.22,10]],"ltp":2.26,"tv":71.24,"id":424676}]}]}
{"op":"mcm","clk":"11798585590","pt":1723153477600,"mc":[{"id":"1.231501231","rc":[{"batb":[[0,2.2,31.59],[1,2.02,4.55],[2,1.91,4.55]],"ltp":2.26,"tv":71.24,"id":424676}]}]}
{"op":"mcm","clk":"11798585670","pt":1723153479906,"mc":[{"id":"1.231501231","rc":[{"batb":[[0,2.22,10],[1,2.2,31.59],[2,2.02,4.55]],"ltp":2.26,"tv":71.24,"id":424676}]}]}
{"op":"mcm","clk":"11798585674","pt":1723153480009,"mc":[{"id":"1.231501231","rc":[{"batb":[[0,2.22,14]],"ltp":2.26,"tv":71.24,"id":424676}]}]}
{"op":"mcm","clk":"11798585767","pt":1723153482319,"mc":[{"id":"1.231501231","rc":[{"batb":[[0,2.22,10]],"ltp":2.26,"tv":71.24,"id":424676}]}]}
{"op":"mcm","clk":"11798585807","pt":1723153483293,"mc":[{"id":"1.231501231","rc":[{"batb":[[0,2.2,31.59],[1,2.02,4.55],[2,1.91,4.55]],"ltp":2.26,"tv":71.24,"id":424676}]}]}
{"op":"mcm","clk":"11798585843","pt":1723153484572,"mc":[{"id":"1.231501231","rc":[{"batb":[[0,2.22,4],[1,2.2,31.59],[2,2.02,4.55]],"ltp":2.26,"tv":71.24,"id":424676}]}]}
{"op":"mcm","clk":"11798585896","pt":1723153485805,"mc":[{"id":"1.231501231","rc":[{"batb":[[0,2.24,10],[1,2.22,4],[2,2.2,31.59]],"ltp":2.26,"tv":71.24,"id":424676}]}]}
{"op":"mcm","clk":"11798585929","pt":1723153486932,"mc":[{"id":"1.231501231","rc":[{"batb":[[1,2.2,31.59],[2,2.02,4.55]],"ltp":2.26,"tv":71.24,"id":424676}]}]}
{"op":"mcm","clk":"11798586017","pt":1723153489238,"mc":[{"id":"1.231501231","rc":[{"batb":[[0,2.22,4]],"ltp":2.26,"tv":71.24,"id":424676}]}]}
{"op":"mcm","clk":"11798586102","pt":1723153491699,"mc":[{"id":"1.231501231","rc":[{"batb":[[0,2.22,10]],"ltp":2.26,"tv":71.24,"id":424676}]}]}
{"op":"mcm","clk":"11798586223","pt":1723153495135,"mc":[{"id":"1.231501231","rc":[{"batb":[[0,2.22,4]],"ltp":2.26,"tv":71.24,"id":424676}]}]}
{"op":"mcm","clk":"11798586301","pt":1723153497646,"mc":[{"id":"1.231501231","rc":[{"batb":[[0,2.22,10]],"ltp":2.26,"tv":71.24,"id":424676}]}]}
{"op":"mcm","clk":"11798586420","pt":1723153500827,"mc":[{"id":"1.231501231","rc":[{"batb":[[0,2.24,4]],"ltp":2.26,"tv":71.24,"id":424676}]}]}
{"op":"mcm","clk":"11798586489","pt":1723153502267,"mc":[{"id":"1.231501231","rc":[{"batb":[[0,2.2,31.59],[1,2.02,4.55],[2,1.91,4.55]],"ltp":2.26,"tv":71.24,"id":424676}]}]}
{"op":"mcm","clk":"11798586540","pt":1723153503495,"mc":[{"id":"1.231501231","rc":[{"batb":[[0,2.22,10],[1,2.2,31.59],[2,2.02,4.55]],"ltp":2.26,"tv":71.24,"id":424676}]}]}
{"op":"mcm","clk":"11798586589","pt":1723153504675,"mc":[{"id":"1.231501231","rc":[{"batb":[[0,2.24,4],[1,2.22,10],[2,2.2,31.59]],"ltp":2.26,"tv":71.24,"id":424676}]}]}
{"op":"mcm","clk":"11798586663","pt":1723153506680,"mc":[{"id":"1.231501231","rc":[{"batb":[[1,2.2,31.59],[2,2.02,4.55]],"ltp":2.26,"tv":71.24,"id":424676}]}]}
{"op":"mcm","clk":"11798586681","pt":1723153507191,"mc":[{"id":"1.231501231","rc":[{"batb":[[0,2.2,31.59],[1,2.02,4.55],[2,1.91,4.55]],"ltp":2.26,"tv":71.24,"id":424676}]}]}
{"op":"mcm","clk":"11798586764","pt":1723153509402,"mc":[{"id":"1.231501231","rc":[{"batb":[[0,2.22,14],[1,2.2,31.59],[2,2.02,4.55]],"ltp":2.26,"tv":71.24,"id":424676}]}]}
{"op":"mcm","clk":"11798586859","pt":1723153511805,"mc":[{"id":"1.231501231","rc":[{"batb":[[0,2.22,10]],"ltp":2.26,"tv":71.24,"id":424676}]}]}
{"op":"mcm","clk":"11798586885","pt":1723153512778,"mc":[{"id":"1.231501231","rc":[{"batb":[[0,2.2,31.59],[1,2.02,4.55],[2,1.91,4.55]],"ltp":2.26,"tv":71.24,"id":424676}]}]}
{"op":"mcm","clk":"11798586955","pt":1723153515181,"mc":[{"id":"1.231501231","rc":[{"batb":[[0,2.22,14],[1,2.2,31.59],[2,2.02,4.55]],"ltp":2.26,"tv":71.24,"id":424676}]}]}
{"op":"mcm","clk":"11798587055","pt":1723153517691,"mc":[{"id":"1.231501231","rc":[{"batb":[[0,2.22,10]],"ltp":2.26,"tv":71.24,"id":424676}]}]}
{"op":"mcm","clk":"11798587089","pt":1723153518507,"mc":[{"id":"1.231501231","rc":[{"batb":[[0,2.2,31.59],[1,2.02,4.55],[2,1.91,4.55]],"ltp":2.26,"tv":71.24,"id":424676}]}]}
{"op":"mcm","clk":"11798587189","pt":1723153521232,"mc":[{"id":"1.231501231","rc":[{"batb":[[0,2.22,14],[1,2.2,31.59],[2,2.02,4.55]],"ltp":2.26,"tv":71.24,"id":424676}]}]}
{"op":"mcm","clk":"11798587300","pt":1723153523749,"mc":[{"id":"1.231501231","rc":[{"batb":[[0,2.22,10]],"ltp":2.26,"tv":71.24,"id":424676}]}]}
{"op":"mcm","clk":"11798587324","pt":1723153524518,"mc":[{"id":"1.231501231","rc":[{"batb":[[0,2.2,31.59],[1,2.02,4.55],[2,1.91,4.55]],"ltp":2.26,"tv":71.24,"id":424676}]}]}
{"op":"mcm","clk":"11798587418","pt":1723153527134,"mc":[{"id":"1.231501231","rc":[{"batb":[[0,2.22,14],[1,2.2,31.59],[2,2.02,4.55]],"ltp":2.26,"tv":71.24,"id":424676}]}]}
{"op":"mcm","clk":"11798587521","pt":1723153529435,"mc":[{"id":"1.231501231","rc":[{"batb":[[0,2.22,10]],"ltp":2.26,"tv":71.24,"id":424676}]}]}
{"op":"mcm","clk":"11798587564","pt":1723153530616,"mc":[{"id":"1.231501231","rc":[{"batb":[[0,2.2,31.59],[1,2.02,4.55],[2,1.91,4.55]],"ltp":2.26,"tv":71.24,"id":424676}]}]}
{"op":"mcm","clk":"11798587648","pt":1723153532919,"mc":[{"id":"1.231501231","rc":[{"batb":[[0,2.22,14],[1,2.2,31.59],[2,2.02,4.55]],"ltp":2.26,"tv":71.24,"id":424676}]}]}
{"op":"mcm","clk":"11798587721","pt":1723153535325,"mc":[{"id":"1.231501231","rc":[{"batb":[[0,2.22,10]],"ltp":2.26,"tv":71.24,"id":424676}]}]}
{"op":"mcm","clk":"11798587747","pt":1723153536346,"mc":[{"id":"1.231501231","rc":[{"batb":[[0,2.2,31.59],[1,2.02,4.55],[2,1.91,4.55]],"ltp":2.26,"tv":71.24,"id":424676}]}]}
{"op":"mcm","clk":"11798587841","pt":1723153538713,"mc":[{"id":"1.231501231","rc":[{"batb":[[0,2.22,14],[1,2.2,31.59],[2,2.02,4.55]],"ltp":2.26,"tv":71.24,"id":424676}]}]}
{"op":"mcm","clk":"11798587907","pt":1723153541021,"mc":[{"id":"1.231501231","rc":[{"batb":[[0,2.22,10]],"ltp":2.26,"tv":71.24,"id":424676}]}]}
{"op":"mcm","clk":"11798587965","pt":1723153542250,"mc":[{"id":"1.231501231","rc":[{"batb":[[0,2.2,31.59],[1,2.02,4.55],[2,1.91,4.55]],"ltp":2.26,"tv":71.24,"id":424676}]}]}
{"op":"mcm","clk":"11798588096","pt":1723153545639,"mc":[{"id":"1.231501231","rc":[{"batb":[[0,2.22,14],[1,2.2,31.59],[2,2.02,4.55]],"ltp":2.26,"tv":71.24,"id":424676}]}]}
{"op":"mcm","clk":"11798588202","pt":1723153548150,"mc":[{"id":"1.231501231","rc":[{"batb":[[0,2.22,10]],"ltp":2.26,"tv":71.24,"id":424676}]}]}
{"op":"mcm","clk":"11798588225","pt":1723153549019,"mc":[{"id":"1.231501231","rc":[{"batb":[[0,2.2,31.59],[1,2.02,4.55],[2,1.91,4.55]],"ltp":2.26,"tv":71.24,"id":424676}]}]}
{"op":"mcm","clk":"11798588273","pt":1723153550664,"mc":[{"id":"1.231501231","rc":[{"batb":[[0,2.22,4],[1,2.2,31.59],[2,2.02,4.55]],"ltp":2.26,"tv":71.24,"id":424676}]}]}
{"op":"mcm","clk":"11798588327","pt":1723153551950,"mc":[{"id":"1.231501231","rc":[{"batb":[[0,2.24,10],[1,2.22,4],[2,2.2,31.59]],"ltp":2.26,"tv":71.24,"id":424676}]}]}
{"op":"mcm","clk":"11798588352","pt":1723153552926,"mc":[{"id":"1.231501231","rc":[{"batb":[[1,2.2,31.59],[2,2.02,4.55]],"ltp":2.26,"tv":71.24,"id":424676}]}]}
{"op":"mcm","clk":"11798588441","pt":1723153555447,"mc":[{"id":"1.231501231","rc":[{"batb":[[0,2.22,4]],"ltp":2.26,"tv":71.24,"id":424676}]}]}
{"op":"mcm","clk":"11798588520","pt":1723153557650,"mc":[{"id":"1.231501231","rc":[{"batb":[[0,2.24,10]],"ltp":2.26,"tv":71.24,"id":424676}]}]}
{"op":"mcm","clk":"11798588609","pt":1723153559759,"mc":[{"id":"1.231501231","rc":[{"batb":[[0,2.26,4],[1,2.24,10],[2,2.2,31.59]],"ltp":2.26,"tv":71.24,"id":424676}]}]}
{"op":"mcm","clk":"11798588662","pt":1723153560842,"mc":[{"id":"1.231501231","rc":[{"batb":[[1,2.2,31.59],[2,2.02,4.55]],"ltp":2.26,"tv":71.24,"id":424676}]}]}
{"op":"mcm","clk":"11798588713","pt":1723153562076,"mc":[{"id":"1.231501231","rc":[{"batb":[[0,2.2,31.59],[1,2.02,4.55],[2,1.91,4.55]],"ltp":2.26,"tv":71.24,"id":424676}]}]}
{"op":"mcm","clk":"11798588758","pt":1723153563260,"mc":[{"id":"1.231501231","rc":[{"batb":[[0,2.22,10],[1,2.2,31.59],[2,2.02,4.55]],"ltp":2.26,"tv":71.24,"id":424676}]}]}
{"op":"mcm","clk":"11798588806","pt":1723153564445,"mc":[{"id":"1.231501231","rc":[{"batb":[[0,2.24,4],[1,2.22,10],[2,2.2,31.59]],"ltp":2.26,"tv":71.24,"id":424676}]}]}
{"op":"mcm","clk":"11798588934","pt":1723153566656,"mc":[{"id":"1.231501231","rc":[{"batb":[[0,2.2,31.59],[1,2.02,4.55],[2,1.91,4.55]],"ltp":2.26,"tv":71.24,"id":424676}]}]}
{"op":"mcm","clk":"11798589070","pt":1723153569176,"mc":[{"id":"1.231501231","rc":[{"batb":[[0,2.22,14],[1,2.2,31.59],[2,2.02,4.55]],"ltp":2.26,"tv":71.24,"id":424676}]}]}
{"op":"mcm","clk":"11798589192","pt":1723153571587,"mc":[{"id":"1.231501231","rc":[{"batb":[[0,2.22,10]],"ltp":2.26,"tv":71.24,"id":424676}]}]}
{"op":"mcm","clk":"11798589226","pt":1723153572463,"mc":[{"id":"1.231501231","rc":[{"batb":[[0,2.2,31.59],[1,2.02,4.55],[2,1.91,4.55]],"ltp":2.26,"tv":71.24,"id":424676}]}]}
{"op":"mcm","clk":"11798589357","pt":1723153574989,"mc":[{"id":"1.231501231","rc":[{"batb":[[0,2.22,14],[1,2.2,31.59],[2,2.02,4.55]],"ltp":2.26,"tv":71.24,"id":424676}]}]}
{"op":"mcm","clk":"11798589505","pt":1723153577204,"mc":[{"id":"1.231501231","rc":[{"batb":[[0,2.22,10]],"ltp":2.26,"tv":71.24,"id":424676}]}]}
{"op":"mcm","clk":"11798589567","pt":1723153578286,"mc":[{"id":"1.231501231","rc":[{"batb":[[0,2.2,31.59],[1,2.02,4.55],[2,1.91,4.55]],"ltp":2.26,"tv":71.24,"id":424676}]}]}
{"op":"mcm","clk":"11798589614","pt":1723153579474,"mc":[{"id":"1.231501231","rc":[{"batb":[[0,2.22,4],[1,2.2,31.59],[2,2.02,4.55]],"ltp":2.26,"tv":71.24,"id":424676}]}]}
{"op":"mcm","clk":"11798589744","pt":1723153581895,"mc":[{"id":"1.231501231","rc":[{"batb":[[0,2.22,10]],"ltp":2.26,"tv":71.24,"id":424676}]}]}
{"op":"mcm","clk":"11798589930","pt":1723153585201,"mc":[{"id":"1.231501231","rc":[{"batb":[[0,2.22,4]],"ltp":2.26,"tv":71.24,"id":424676}]}]}
{"op":"mcm","clk":"11798590099","pt":1723153587576,"mc":[{"id":"1.231501231","rc":[{"batb":[[0,2.24,10]],"ltp":2.26,"tv":71.24,"id":424676}]}]}
{"op":"mcm","clk":"11798590308","pt":1723153590886,"mc":[{"id":"1.231501231","rc":[{"batb":[[0,2.22,4]],"ltp":2.26,"tv":71.24,"id":424676}]}]}
{"op":"mcm","clk":"11798590469","pt":1723153593303,"mc":[{"id":"1.231501231","rc":[{"batb":[[0,2.22,10]],"ltp":2.26,"tv":71.24,"id":424676}]}]}
{"op":"mcm","clk":"11798590599","pt":1723153595618,"mc":[{"id":"1.231501231","rc":[{"batb":[[0,2.24,4],[1,2.22,10],[2,2.2,31.59]],"ltp":2.26,"tv":71.24,"id":424676}]}]}
{"op":"mcm","clk":"11798590644","pt":1723153596597,"mc":[{"id":"1.231501231","rc":[{"batb":[[1,2.2,31.59],[2,2.02,4.55]],"ltp":2.26,"tv":71.24,"id":424676}]}]}
{"op":"mcm","clk":"11798590713","pt":1723153597823,"mc":[{"id":"1.231501231","rc":[{"batb":[[0,2.2,31.59],[1,2.02,4.55],[2,1.91,4.55]],"ltp":2.26,"tv":71.24,"id":424676}]}]}
{"op":"mcm","clk":"11798590818","pt":1723153599993,"mc":[{"id":"1.231501231","rc":[{"batb":[[0,2.22,14],[1,2.2,31.59],[2,2.02,4.55]],"ltp":2.26,"tv":71.24,"id":424676}]}]}
{"op":"mcm","clk":"11798590936","pt":1723153602208,"mc":[{"id":"1.231501231","rc":[{"batb":[[0,2.22,10]],"ltp":2.26,"tv":71.24,"id":424676}]}]}
{"op":"mcm","clk":"11798590988","pt":1723153603441,"mc":[{"id":"1.231501231","rc":[{"batb":[[0,2.2,31.59],[1,2.02,4.55],[2,1.91,4.55]],"ltp":2.26,"tv":71.24,"id":424676}]}]}
{"op":"mcm","clk":"11798591048","pt":1723153604723,"mc":[{"id":"1.231501231","rc":[{"batb":[[0,2.22,4],[1,2.2,31.59],[2,2.02,4.55]],"ltp":2.26,"tv":71.24,"id":424676}]}]}
{"op":"mcm","clk":"11798591137","pt":1723153606930,"mc":[{"id":"1.231501231","rc":[{"batb":[[0,2.24,10]],"ltp":2.26,"tv":71.24,"id":424676}]}]}
{"op":"mcm","clk":"11798591286","pt":1723153610527,"mc":[{"id":"1.231501231","rc":[{"batb":[[0,2.22,4]],"ltp":2.26,"tv":71.24,"id":424676}]}]}
{"op":"mcm","clk":"11798591392","pt":1723153612937,"mc":[{"id":"1.231501231","rc":[{"batb":[[0,2.24,10]],"ltp":2.26,"tv":71.24,"id":424676}]}]}
{"op":"mcm","clk":"11798591516","pt":1723153615717,"mc":[{"id":"1.231501231","rc":[{"batb":[[0,2.26,4],[1,2.24,10],[2,2.2,31.59]],"ltp":2.26,"tv":71.24,"id":424676},{"batl":[[0,1.8,450],[1,1.82,2],[2,1.86,21.9]],"ltp":1.8,"tv":116.97,"id":31376}]}]}
{"op":"mcm","clk":"11798591542","pt":1723153616331,"mc":[{"id":"1.231501231","rc":[{"batb":[[1,2.2,31.59],[2,2.02,4.55]],"ltp":2.26,"tv":71.24,"id":424676}]}]}
{"op":"mcm","clk":"11798591630","pt":1723153618031,"mc":[{"id":"1.231501231","rc":[{"batb":[[0,2.2,31.59],[1,2.02,4.55],[2,1.91,4.55]],"ltp":2.26,"tv":71.24,"id":424676}]}]}
{"op":"mcm","clk":"11798591887","pt":1723153624950,"mc":[{"id":"1.231501231","rc":[{"batb":[[0,2.22,14],[1,2.2,31.59],[2,2.02,4.55]],"ltp":2.26,"tv":71.24,"id":424676}]}]}
{"op":"mcm","clk":"11798591983","pt":1723153627256,"mc":[{"id":"1.231501231","rc":[{"batb":[[0,2.22,10]],"ltp":2.26,"tv":71.24,"id":424676}]}]}
{"op":"mcm","clk":"11798592028","pt":1723153628334,"mc":[{"id":"1.231501231","rc":[{"batb":[[0,2.2,31.59],[1,2.02,4.55],[2,1.91,4.55]],"ltp":2.26,"tv":71.24,"id":424676}]}]}
{"op":"mcm","clk":"11798592082","pt":1723153629666,"mc":[{"id":"1.231501231","rc":[{"batb":[[0,2.22,4],[1,2.2,31.59],[2,2.02,4.55]],"ltp":2.26,"tv":71.24,"id":424676}]}]}
{"op":"mcm","clk":"11798592135","pt":1723153630847,"mc":[{"id":"1.231501231","rc":[{"batb":[[0,2.24,10],[1,2.22,4],[2,2.2,31.59]],"ltp":2.26,"tv":71.24,"id":424676}]}]}
{"op":"mcm","clk":"11798592188","pt":1723153632026,"mc":[{"id":"1.231501231","rc":[{"batb":[[1,2.2,31.59],[2,2.02,4.55]],"ltp":2.26,"tv":71.24,"id":424676}]}]}
{"op":"mcm","clk":"11798592287","pt":1723153634439,"mc":[{"id":"1.231501231","rc":[{"batb":[[0,2.22,4]],"ltp":2.26,"tv":71.24,"id":424676}]}]}
{"op":"mcm","clk":"11798592389","pt":1723153636954,"mc":[{"id":"1.231501231","rc":[{"batb":[[0,2.22,10]],"ltp":2.26,"tv":71.24,"id":424676}]}]}
{"op":"mcm","clk":"11798592490","pt":1723153639157,"mc":[{"id":"1.231501231","rc":[{"batb":[[0,2.24,4],[1,2.22,10],[2,2.2,31.59]],"ltp":2.26,"tv":71.24,"id":424676}]}]}
{"op":"mcm","clk":"11798592539","pt":1723153640234,"mc":[{"id":"1.231501231","rc":[{"batb":[[1,2.2,31.59],[2,2.02,4.55]],"ltp":2.26,"tv":71.24,"id":424676}]}]}
{"op":"mcm","clk":"11798592594","pt":1723153641336,"mc":[{"id":"1.231501231","rc":[{"batb":[[0,2.2,31.59],[1,2.02,4.55],[2,1.91,4.55]],"ltp":2.26,"tv":71.24,"id":424676}]}]}
{"op":"mcm","clk":"11798592688","pt":1723153643749,"mc":[{"id":"1.231501231","rc":[{"batb":[[0,2.22,14],[1,2.2,31.59],[2,2.02,4.55]],"ltp":2.26,"tv":71.24,"id":424676}]}]}
{"op":"mcm","clk":"11798592782","pt":1723153646058,"mc":[{"id":"1.231501231","rc":[{"batb":[[0,2.22,10]],"ltp":2.26,"tv":71.24,"id":424676}]}]}
{"op":"mcm","clk":"11798592811","pt":1723153647137,"mc":[{"id":"1.231501231","rc":[{"batb":[[0,2.2,31.59],[1,2.02,4.55],[2,1.91,4.55]],"ltp":2.26,"tv":71.24,"id":424676}]}]}
{"op":"mcm","clk":"11798592962","pt":1723153650684,"mc":[{"id":"1.231501231","rc":[{"batb":[[0,2.22,14],[1,2.2,31.59],[2,2.02,4.55]],"ltp":2.26,"tv":71.24,"id":424676}]}]}
{"op":"mcm","clk":"11798593054","pt":1723153652988,"mc":[{"id":"1.231501231","rc":[{"batb":[[0,2.22,10]],"ltp":2.26,"tv":71.24,"id":424676}]}]}
{"op":"mcm","clk":"11798593098","pt":1723153653967,"mc":[{"id":"1.231501231","rc":[{"batb":[[0,2.2,31.59],[1,2.02,4.55],[2,1.91,4.55]],"ltp":2.26,"tv":71.24,"id":424676}]}]}
{"op":"mcm","clk":"11798593155","pt":1723153655354,"mc":[{"id":"1.231501231","rc":[{"batb":[[0,2.22,4],[1,2.2,31.59],[2,2.02,4.55]],"ltp":2.26,"tv":71.24,"id":424676}]}]}
{"op":"mcm","clk":"11798593216","pt":1723153656585,"mc":[{"id":"1.231501231","rc":[{"batb":[[0,2.24,10],[1,2.22,4],[2,2.2,31.59]],"ltp":2.26,"tv":71.24,"id":424676}]}]}
{"op":"mcm","clk":"11798593254","pt":1723153657760,"mc":[{"id":"1.231501231","rc":[{"batb":[[1,2.2,31.59],[2,2.02,4.55]],"ltp":2.26,"tv":71.24,"id":424676}]}]}
{"op":"mcm","clk":"11798593327","pt":1723153659970,"mc":[{"id":"1.231501231","rc":[{"batb":[[0,2.22,4]],"ltp":2.26,"tv":71.24,"id":424676}]}]}
{"op":"mcm","clk":"11798593402","pt":1723153662277,"mc":[{"id":"1.231501231","rc":[{"batb":[[0,2.22,10]],"ltp":2.26,"tv":71.24,"id":424676}]}]}
{"op":"mcm","clk":"11798593510","pt":1723153664788,"mc":[{"id":"1.231501231","rc":[{"batb":[[0,2.24,4],[1,2.22,10],[2,2.2,31.59]],"ltp":2.26,"tv":71.24,"id":424676}]}]}
{"op":"mcm","clk":"11798593544","pt":1723153665558,"mc":[{"id":"1.231501231","rc":[{"batb":[[1,2.2,31.59],[2,2.02,4.55]],"ltp":2.26,"tv":71.24,"id":424676}]}]}
{"op":"mcm","clk":"11798593595","pt":1723153667096,"mc":[{"id":"1.231501231","rc":[{"batb":[[0,2.2,31.59],[1,2.02,4.55],[2,1.91,4.55]],"ltp":2.26,"tv":71.24,"id":424676}]}]}
{"op":"mcm","clk":"11798593641","pt":1723153668273,"mc":[{"id":"1.231501231","rc":[{"batb":[[0,2.22,10],[1,2.2,31.59],[2,2.02,4.55]],"ltp":2.26,"tv":71.24,"id":424676}]}]}
{"op":"mcm","clk":"11798593783","pt":1723153671507,"mc":[{"id":"1.231501231","rc":[{"batb":[[0,2.24,4]],"ltp":2.26,"tv":71.24,"id":424676}]}]}
{"op":"mcm","clk":"11798593874","pt":1723153673964,"mc":[{"id":"1.231501231","rc":[{"batb":[[0,2.22,10]],"ltp":2.26,"tv":71.24,"id":424676}]}]}
{"op":"mcm","clk":"11798593974","pt":1723153677302,"mc":[{"id":"1.231501231","rc":[{"batb":[[0,2.22,4]],"ltp":2.26,"tv":71.24,"id":424676}]}]}
{"op":"mcm","clk":"11798594091","pt":1723153679819,"mc":[{"id":"1.231501231","rc":[{"batb":[[0,2.24,10]],"ltp":2.26,"tv":71.24,"id":424676}]}]}
{"op":"mcm","clk":"11798594251","pt":1723153683205,"mc":[{"id":"1.231501231","rc":[{"batb":[[0,2.26,4]],"ltp":2.26,"tv":71.24,"id":424676}]}]}
{"op":"mcm","clk":"11798594325","pt":1723153685507,"mc":[{"id":"1.231501231","rc":[{"batb":[[0,2.22,10]],"ltp":2.26,"tv":71.24,"id":424676}]}]}
{"op":"mcm","clk":"11798594418","pt":1723153688684,"mc":[{"id":"1.231501231","rc":[{"batb":[[0,2.24,4]],"ltp":2.26,"tv":71.24,"id":424676}]}]}
{"op":"mcm","clk":"11798594503","pt":1723153691198,"mc":[{"id":"1.231501231","rc":[{"batb":[[0,2.22,10]],"ltp":2.26,"tv":71.24,"id":424676}]}]}
{"op":"mcm","clk":"11798594585","pt":1723153693504,"mc":[{"id":"1.231501231","rc":[{"batb":[[0,2.24,4],[1,2.22,10],[2,2.2,31.59]],"ltp":2.26,"tv":71.24,"id":424676}]}]}
{"op":"mcm","clk":"11798594631","pt":1723153694531,"mc":[{"id":"1.231501231","rc":[{"batb":[[1,2.2,31.59],[2,2.02,4.55]],"ltp":2.26,"tv":71.24,"id":424676}]}]}
{"op":"mcm","clk":"11798594698","pt":1723153695709,"mc":[{"id":"1.231501231","rc":[{"batb":[[0,2.2,31.59],[1,2.02,4.55],[2,1.91,4.55]],"ltp":2.26,"tv":71.24,"id":424676}]}]}
{"op":"mcm","clk":"11798594757","pt":1723153697042,"mc":[{"id":"1.231501231","rc":[{"batb":[[0,2.22,10],[1,2.2,31.59],[2,2.02,4.55]],"ltp":2.26,"tv":71.24,"id":424676}]}]}
{"op":"mcm","clk":"11798594808","pt":1723153698119,"mc":[{"id":"1.231501231","rc":[{"batb":[[0,2.24,4],[1,2.22,10],[2,2.2,31.59]],"ltp":2.26,"tv":71.24,"id":424676}]}]}
{"op":"mcm","clk":"11798594895","pt":1723153700426,"mc":[{"id":"1.231501231","rc":[{"batb":[[0,2.2,31.59],[1,2.02,4.55],[2,1.91,4.55]],"ltp":2.26,"tv":71.24,"id":424676}]}]}
{"op":"mcm","clk":"11798594975","pt":1723153702841,"mc":[{"id":"1.231501231","rc":[{"batb":[[0,2.22,14],[1,2.2,31.59],[2,2.02,4.55]],"ltp":2.26,"tv":71.24,"id":424676}]}]}
{"op":"mcm","clk":"11798595069","pt":1723153705227,"mc":[{"id":"1.231501231","rc":[{"batb":[[0,2.22,10]],"ltp":2.26,"tv":71.24,"id":424676}]}]}
{"op":"mcm","clk":"11798595113","pt":1723153706205,"mc":[{"id":"1.231501231","rc":[{"batb":[[0,2.2,31.59],[1,2.02,4.55],[2,1.91,4.55]],"ltp":2.26,"tv":71.24,"id":424676}]}]}
{"op":"mcm","clk":"11798595252","pt":1723153708624,"mc":[{"id":"1.231501231","rc":[{"batb":[[0,2.22,14],[1,2.2,31.59],[2,2.02,4.55]],"ltp":2.26,"tv":71.24,"id":424676}]}]}
{"op":"mcm","clk":"11798595368","pt":1723153710936,"mc":[{"id":"1.231501231","rc":[{"batb":[[0,2.22,10]],"ltp":2.26,"tv":71.24,"id":424676}]}]}
{"op":"mcm","clk":"11798595416","pt":1723153711910,"mc":[{"id":"1.231501231","rc":[{"batb":[[0,2.2,31.59],[1,2.02,4.55],[2,1.91,4.55]],"ltp":2.26,"tv":71.24,"id":424676}]}]}
{"op":"mcm","clk":"11798595483","pt":1723153713348,"mc":[{"id":"1.231501231","rc":[{"batb":[[0,2.22,4],[1,2.2,31.59],[2,2.02,4.55]],"ltp":2.26,"tv":71.24,"id":424676}]}]}
{"op":"mcm","clk":"11798595558","pt":1723153715758,"mc":[{"id":"1.231501231","rc":[{"batb":[[0,2.24,10]],"ltp":2.26,"tv":71.24,"id":424676}]}]}
{"op":"mcm","clk":"11798595657","pt":1723153718020,"mc":[{"id":"1.231501231","rc":[{"batb":[[0,2.26,4],[1,2.24,10],[2,2.2,31.59]],"ltp":2.26,"tv":71.24,"id":424676}]}]}
{"op":"mcm","clk":"11798595701","pt":1723153719049,"mc":[{"id":"1.231501231","rc":[{"batb":[[1,2.2,31.59],[2,2.02,4.55]],"ltp":2.26,"tv":71.24,"id":424676}]}]}
{"op":"mcm","clk":"11798595783","pt":1723153720434,"mc":[{"id":"1.231501231","rc":[{"batb":[[0,2.2,31.59],[1,2.02,4.55],[2,1.91,4.55]],"ltp":2.26,"tv":71.24,"id":424676}]}]}
{"op":"mcm","clk":"11798595840","pt":1723153721766,"mc":[{"id":"1.231501231","rc":[{"batb":[[0,2.22,10],[1,2.2,31.59],[2,2.02,4.55]],"ltp":2.26,"tv":71.24,"id":424676}]}]}
{"op":"mcm","clk":"11798595957","pt":1723153724429,"mc":[{"id":"1.231501231","rc":[{"batb":[[0,2.24,4],[1,2.22,10],[2,2.2,31.59]],"ltp":2.26,"tv":71.24,"id":424676}]}]}
{"op":"mcm","clk":"11798595990","pt":1723153725352,"mc":[{"id":"1.231501231","rc":[{"batb":[[1,2.2,31.59],[2,2.02,4.55]],"ltp":2.26,"tv":71.24,"id":424676}]}]}
{"op":"mcm","clk":"11798596049","pt":1723153726733,"mc":[{"id":"1.231501231","rc":[{"batb":[[0,2.2,31.59],[1,2.02,4.55],[2,1.91,4.55]],"ltp":2.26,"tv":71.24,"id":424676}]}]}
{"op":"mcm","clk":"11798596083","pt":1723153727858,"mc":[{"id":"1.231501231","rc":[{"batb":[[0,2.22,10],[1,2.2,31.59],[2,2.02,4.55]],"ltp":2.26,"tv":71.24,"id":424676}]}]}
{"op":"mcm","clk":"11798596248","pt":1723153731354,"mc":[{"id":"1.231501231","rc":[{"batb":[[0,2.22,4]],"ltp":2.26,"tv":71.24,"id":424676}]}]}
{"op":"mcm","clk":"11798596351","pt":1723153733766,"mc":[{"id":"1.231501231","rc":[{"batb":[[0,2.24,10]],"ltp":2.26,"tv":71.24,"id":424676}]}]}
{"op":"mcm","clk":"11798596457","pt":1723153736840,"mc":[{"id":"1.231501231","rc":[{"batb":[[0,2.2,31.59],[1,2.02,4.55],[2,1.91,4.55]],"ltp":2.26,"tv":71.24,"id":424676}]}]}
{"op":"mcm","clk":"11798596474","pt":1723153737145,"mc":[{"id":"1.231501231","rc":[{"batb":[[0,2.22,4],[1,2.2,31.59],[2,2.02,4.55]],"ltp":2.26,"tv":71.24,"id":424676}]}]}
{"op":"mcm","clk":"11798596567","pt":1723153739556,"mc":[{"id":"1.231501231","rc":[{"batb":[[0,2.24,10]],"ltp":2.26,"tv":71.24,"id":424676}]}]}
{"op":"mcm","clk":"11798596705","pt":1723153742746,"mc":[{"id":"1.231501231","rc":[{"batb":[[0,2.22,4]],"ltp":2.26,"tv":71.24,"id":424676}]}]}
{"op":"mcm","clk":"11798596805","pt":1723153744951,"mc":[{"id":"1.231501231","rc":[{"batb":[[0,2.2,31.59],[1,2.02,4.55],[2,1.91,4.55]],"ltp":2.26,"tv":71.24,"id":424676}]}]}
{"op":"mcm","clk":"11798596816","pt":1723153745156,"mc":[{"id":"1.231501231","rc":[{"batb":[[0,2.22,10],[1,2.2,31.59],[2,2.02,4.55]],"ltp":2.26,"tv":71.24,"id":424676}]}]}
{"op":"mcm","clk":"11798596908","pt":1723153747258,"mc":[{"id":"1.231501231","rc":[{"batb":[[0,2.24,4],[1,2.22,10],[2,2.2,31.59]],"ltp":2.26,"tv":71.24,"id":424676}]}]}
{"op":"mcm","clk":"11798596953","pt":1723153748486,"mc":[{"id":"1.231501231","rc":[{"batb":[[1,2.2,31.59],[2,2.02,4.55]],"ltp":2.26,"tv":71.24,"id":424676}]}]}
{"op":"mcm","clk":"11798596989","pt":1723153749561,"mc":[{"id":"1.231501231","rc":[{"batb":[[0,2.2,31.59],[1,2.02,4.55],[2,1.91,4.55]],"ltp":2.26,"tv":71.24,"id":424676}]}]}
{"op":"mcm","clk":"11798597094","pt":1723153751865,"mc":[{"id":"1.231501231","rc":[{"batb":[[0,2.22,14],[1,2.2,31.59],[2,2.02,4.55]],"ltp":2.26,"tv":71.24,"id":424676}]}]}
{"op":"mcm","clk":"11798597190","pt":1723153754269,"mc":[{"id":"1.231501231","rc":[{"batb":[[0,2.22,10]],"ltp":2.26,"tv":71.24,"id":424676}]}]}
{"op":"mcm","clk":"11798597225","pt":1723153755295,"mc":[{"id":"1.231501231","rc":[{"batb":[[0,2.2,31.59],[1,2.02,4.55],[2,1.91,4.55]],"ltp":2.26,"tv":71.24,"id":424676}]}]}
{"op":"mcm","clk":"11798597276","pt":1723153756371,"mc":[{"id":"1.231501231","rc":[{"batb":[[0,2.22,4],[1,2.2,31.59],[2,2.02,4.55]],"ltp":2.26,"tv":71.24,"id":424676}]}]}
{"op":"mcm","clk":"11798597324","pt":1723153757806,"mc":[{"id":"1.231501231","rc":[{"batb":[[0,2.24,10],[1,2.22,4],[2,2.2,31.59]],"ltp":2.26,"tv":71.24,"id":424676}]}]}
{"op":"mcm","clk":"11798597369","pt":1723153758778,"mc":[{"id":"1.231501231","rc":[{"batb":[[1,2.2,31.59],[2,2.02,4.55]],"ltp":2.26,"tv":71.24,"id":424676}]}]}
{"op":"mcm","clk":"11798597447","pt":1723153760987,"mc":[{"id":"1.231501231","rc":[{"batb":[[0,2.2,31.59],[1,2.02,4.55],[2,1.91,4.55]],"ltp":2.26,"tv":71.24,"id":424676}]}]}
{"op":"mcm","clk":"11798597452","pt":1723153761090,"mc":[{"id":"1.231501231","rc":[{"batb":[[0,2.22,4],[1,2.2,31.59],[2,2.02,4.55]],"ltp":2.26,"tv":71.24,"id":424676}]}]}
{"op":"mcm","clk":"11798597555","pt":1723153763497,"mc":[{"id":"1.231501231","rc":[{"batb":[[0,2.22,10]],"ltp":2.26,"tv":71.24,"id":424676}]}]}
{"op":"mcm","clk":"11798597705","pt":1723153766982,"mc":[{"id":"1.231501231","rc":[{"batb":[[0,2.24,4]],"ltp":2.26,"tv":71.24,"id":424676}]}]}
{"op":"mcm","clk":"11798597777","pt":1723153768621,"mc":[{"id":"1.231501231","rc":[{"batb":[[0,2.2,31.59],[1,2.02,4.55],[2,1.91,4.55]],"ltp":2.26,"tv":71.24,"id":424676}]}]}
{"op":"mcm","clk":"11798597821","pt":1723153769695,"mc":[{"id":"1.231501231","rc":[{"batb":[[0,2.22,10],[1,2.2,31.59],[2,2.02,4.55]],"ltp":2.26,"tv":71.24,"id":424676}]}]}
{"op":"mcm","clk":"11798597919","pt":1723153771596,"mc":[{"id":"1.231501231","rc":[{"batb":[[0,2.24,4],[1,2.22,10],[2,2.2,31.59]],"ltp":2.26,"tv":71.24,"id":424676}]}]}
{"op":"mcm","clk":"11798597980","pt":1723153773032,"mc":[{"id":"1.231501231","rc":[{"batb":[[1,2.2,31.59],[2,2.02,4.55]],"ltp":2.26,"tv":71.24,"id":424676}]}]}
{"op":"mcm","clk":"11798598021","pt":1723153774006,"mc":[{"id":"1.231501231","rc":[{"batb":[[0,2.2,31.59],[1,2.02,4.55],[2,1.91,4.55]],"ltp":2.26,"tv":71.24,"id":424676}]}]}
{"op":"mcm","clk":"11798598060","pt":1723153775134,"mc":[{"id":"1.231501231","rc":[{"batb":[[0,2.22,10],[1,2.2,31.59],[2,2.02,4.55]],"ltp":2.26,"tv":71.24,"id":424676}]}]}
{"op":"mcm","clk":"11798598120","pt":1723153776317,"mc":[{"id":"1.231501231","rc":[{"batb":[[0,2.24,4],[1,2.22,10],[2,2.2,31.59]],"ltp":2.26,"tv":71.24,"id":424676}]}]}
{"op":"mcm","clk":"11798598241","pt":1723153778633,"mc":[{"id":"1.231501231","rc":[{"batb":[[0,2.2,31.59],[1,2.02,4.55],[2,1.91,4.55]],"ltp":2.26,"tv":71.24,"id":424676}]}]}
{"op":"mcm","clk":"11798598377","pt":1723153781924,"mc":[{"id":"1.231501231","rc":[{"batb":[[0,2.22,14],[1,2.2,31.59],[2,2.02,4.55]],"ltp":2.26,"tv":71.24,"id":424676}]}]}
{"op":"mcm","clk":"11798598457","pt":1723153784123,"mc":[{"id":"1.231501231","rc":[{"batb":[[0,2.22,10]],"ltp":2.26,"tv":71.24,"id":424676}]}]}
{"op":"mcm","clk":"11798598496","pt":1723153785304,"mc":[{"id":"1.231501231","rc":[{"batb":[[0,2.2,31.59],[1,2.02,4.55],[2,1.91,4.55]],"ltp":2.26,"tv":71.24,"id":424676}]}]}
{"op":"mcm","clk":"11798598546","pt":1723153786636,"mc":[{"id":"1.231501231","rc":[{"batb":[[0,2.22,4],[1,2.2,31.59],[2,2.02,4.55]],"ltp":2.26,"tv":71.24,"id":424676}]}]}
{"op":"mcm","clk":"11798598597","pt":1723153787814,"mc":[{"id":"1.231501231","rc":[{"batb":[[0,2.24,10],[1,2.22,4],[2,2.2,31.59]],"ltp":2.26,"tv":71.24,"id":424676}]}]}
{"op":"mcm","clk":"11798598647","pt":1723153788840,"mc":[{"id":"1.231501231","rc":[{"batb":[[1,2.2,31.59],[2,2.02,4.55]],"ltp":2.26,"tv":71.24,"id":424676}]}]}
{"op":"mcm","clk":"11798598758","pt":1723153791201,"mc":[{"id":"1.231501231","rc":[{"batb":[[0,2.22,4]],"ltp":2.26,"tv":71.24,"id":424676}]}]}
{"op":"mcm","clk":"11798598866","pt":1723153793416,"mc":[{"id":"1.231501231","rc":[{"batb":[[0,2.24,10]],"ltp":2.26,"tv":71.24,"id":424676}]}]}
{"op":"mcm","clk":"11798598956","pt":1723153795837,"mc":[{"id":"1.231501231","rc":[{"batb":[[0,2.26,4],[1,2.24,10],[2,2.2,31.59]],"ltp":2.26,"tv":71.24,"id":424676}]}]}
{"op":"mcm","clk":"11798599023","pt":1723153796920,"mc":[{"id":"1.231501231","rc":[{"batb":[[1,2.2,31.59],[2,2.02,4.55]],"ltp":2.26,"tv":71.24,"id":424676}]}]}
{"op":"mcm","clk":"11798599075","pt":1723153798152,"mc":[{"id":"1.231501231","rc":[{"batb":[[0,2.2,31.59],[1,2.02,4.55],[2,1.91,4.55]],"ltp":2.26,"tv":71.24,"id":424676}]}]}
{"op":"mcm","clk":"11798599198","pt":1723153801236,"mc":[{"id":"1.231501231","rc":[{"batb":[[0,2.22,14],[1,2.2,31.59],[2,2.02,4.55]],"ltp":2.26,"tv":71.24,"id":424676}]}]}
{"op":"mcm","clk":"11798599307","pt":1723153803448,"mc":[{"id":"1.231501231","rc":[{"batb":[[0,2.22,10]],"ltp":2.26,"tv":71.24,"id":424676}]}]}
{"op":"mcm","clk":"11798599360","pt":1723153804520,"mc":[{"id":"1.231501231","rc":[{"batb":[[0,2.2,31.59],[1,2.02,4.55],[2,1.91,4.55]],"ltp":2.26,"tv":71.24,"id":424676}]}]}
{"op":"mcm","clk":"11798599406","pt":1723153805859,"mc":[{"id":"1.231501231","rc":[{"batb":[[0,2.22,4],[1,2.2,31.59],[2,2.02,4.55]],"ltp":2.26,"tv":71.24,"id":424676}]}]}
{"op":"mcm","clk":"11798599468","pt":1723153807143,"mc":[{"id":"1.231501231","rc":[{"batb":[[0,2.24,10],[1,2.22,4],[2,2.2,31.59]],"ltp":2.26,"tv":71.24,"id":424676}]}]}
{"op":"mcm","clk":"11798599515","pt":1723153808225,"mc":[{"id":"1.231501231","rc":[{"batb":[[1,2.2,31.59],[2,2.02,4.55]],"ltp":2.26,"tv":71.24,"id":424676}]}]}
{"op":"mcm","clk":"11798599607","pt":1723153810443,"mc":[{"id":"1.231501231","rc":[{"batb":[[0,2.26,4]],"ltp":2.26,"tv":71.24,"id":424676}]}]}
{"op":"mcm","clk":"11798599694","pt":1723153812752,"mc":[{"id":"1.231501231","rc":[{"batb":[[0,2.28,10]],"ltp":2.26,"tv":71.24,"id":424676}]}]}
{"op":"mcm","clk":"11798599851","pt":1723153816142,"mc":[{"id":"1.231501231","rc":[{"batb":[[0,2.22,4]],"ltp":2.26,"tv":71.24,"id":424676}]}]}
{"op":"mcm","clk":"11798599968","pt":1723153818450,"mc":[{"id":"1.231501231","rc":[{"batb":[[0,2.22,10]],"ltp":2.26,"tv":71.24,"id":424676}]}]}
{"op":"mcm","clk":"11798600111","pt":1723153821782,"mc":[{"id":"1.231501231","rc":[{"batb":[[0,2.2,31.59],[1,2.02,4.55],[2,1.91,4.55]],"ltp":2.26,"tv":71.24,"id":424676}]}]}
{"op":"mcm","clk":"11798600124","pt":1723153822091,"mc":[{"id":"1.231501231","rc":[{"batb":[[0,2.22,4],[1,2.2,31.59],[2,2.02,4.55]],"ltp":2.26,"tv":71.24,"id":424676}]}]}
{"op":"mcm","clk":"11798600224","pt":1723153824351,"mc":[{"id":"1.231501231","rc":[{"batb":[[0,2.24,10]],"ltp":2.26,"tv":71.24,"id":424676}]}]}
{"op":"mcm","clk":"11798600307","pt":1723153826758,"mc":[{"id":"1.231501231","rc":[{"batb":[[0,2.26,4],[1,2.24,10],[2,2.2,31.59]],"ltp":2.26,"tv":71.24,"id":424676}]}]}
{"op":"mcm","clk":"11798600338","pt":1723153827681,"mc":[{"id":"1.231501231","rc":[{"batb":[[1,2.2,31.59],[2,2.02,4.55]],"ltp":2.26,"tv":71.24,"id":424676}]}]}
{"op":"mcm","clk":"11798600412","pt":1723153829068,"mc":[{"id":"1.231501231","rc":[{"batb":[[0,2.2,31.59],[1,2.02,4.55],[2,1.91,4.55]],"ltp":2.26,"tv":71.24,"id":424676}]}]}
{"op":"mcm","clk":"11798600460","pt":1723153830197,"mc":[{"id":"1.231501231","rc":[{"batb":[[0,2.22,10],[1,2.2,31.59],[2,2.02,4.55]],"ltp":2.26,"tv":71.24,"id":424676}]}]}
{"op":"mcm","clk":"11798600506","pt":1723153831376,"mc":[{"id":"1.231501231","rc":[{"batb":[[0,2.24,4],[1,2.22,10],[2,2.2,31.59]],"ltp":2.26,"tv":71.24,"id":424676}]}]}
{"op":"mcm","clk":"11798600602","pt":1723153833682,"mc":[{"id":"1.231501231","rc":[{"batb":[[0,2.2,31.59],[1,2.02,4.55],[2,1.91,4.55]],"ltp":2.26,"tv":71.24,"id":424676}]}]}
{"op":"mcm","clk":"11798600717","pt":1723153835990,"mc":[{"id":"1.231501231","rc":[{"batb":[[0,2.22,14],[1,2.2,31.59],[2,2.02,4.55]],"ltp":2.26,"tv":71.24,"id":424676}]}]}
{"op":"mcm","clk":"11798600812","pt":1723153838296,"mc":[{"id":"1.231501231","rc":[{"batb":[[0,2.22,10]],"ltp":2.26,"tv":71.24,"id":424676}]}]}
{"op":"mcm","clk":"11798600866","pt":1723153839272,"mc":[{"id":"1.231501231","rc":[{"batb":[[0,2.2,31.59],[1,2.02,4.55],[2,1.91,4.55]],"ltp":2.26,"tv":71.24,"id":424676}]}]}
{"op":"mcm","clk":"11798600926","pt":1723153840606,"mc":[{"id":"1.231501231","rc":[{"batb":[[0,2.22,4],[1,2.2,31.59],[2,2.02,4.55]],"ltp":2.26,"tv":71.24,"id":424676}]}]}
{"op":"mcm","clk":"11798601026","pt":1723153842914,"mc":[{"id":"1.231501231","rc":[{"batb":[[0,2.24,10]],"ltp":2.26,"tv":71.24,"id":424676}]}]}
{"op":"mcm","clk":"11798601142","pt":1723153846398,"mc":[{"id":"1.231501231","rc":[{"batb":[[0,2.22,4]],"ltp":2.26,"tv":71.24,"id":424676}]}]}
{"op":"mcm","clk":"11798601246","pt":1723153848811,"mc":[{"id":"1.231501231","rc":[{"batb":[[0,2.22,10]],"ltp":2.26,"tv":71.24,"id":424676}]}]}
{"op":"mcm","clk":"11798601394","pt":1723153851991,"mc":[{"id":"1.231501231","rc":[{"batb":[[0,2.24,4]],"ltp":2.26,"tv":71.24,"id":424676}]}]}
{"op":"mcm","clk":"11798601477","pt":1723153854201,"mc":[{"id":"1.231501231","rc":[{"batb":[[0,2.22,10]],"ltp":2.26,"tv":71.24,"id":424676}]}]}
{"op":"mcm","clk":"11798601570","pt":1723153856815,"mc":[{"id":"1.231501231","rc":[{"batb":[[0,2.24,4],[1,2.22,10],[2,2.2,31.59]],"ltp":2.26,"tv":71.24,"id":424676}]}]}
{"op":"mcm","clk":"11798601618","pt":1723153857585,"mc":[{"id":"1.231501231","rc":[{"batb":[[1,2.2,31.59],[2,2.02,4.55]],"ltp":2.26,"tv":71.24,"id":424676}]}]}
{"op":"mcm","clk":"11798601705","pt":1723153859326,"mc":[{"id":"1.231501231","rc":[{"batb":[[0,2.2,31.59],[1,2.02,4.55],[2,1.91,4.55]],"ltp":2.26,"tv":71.24,"id":424676}]}]}
{"op":"mcm","clk":"11798601802","pt":1723153861531,"mc":[{"id":"1.231501231","rc":[{"batb":[[0,2.24,4],[1,2.22,10],[2,2.2,31.59]],"ltp":2.26,"tv":71.24,"id":424676}]}]}
{"op":"mcm","clk":"11798601916","pt":1723153863844,"mc":[{"id":"1.231501231","rc":[{"batb":[[0,2.22,10],[1,2.2,31.59],[2,2.02,4.55]],"ltp":2.26,"tv":71.24,"id":424676}]}]}
{"op":"mcm","clk":"11798601965","pt":1723153864719,"mc":[{"id":"1.231501231","rc":[{"batb":[[0,2.2,31.59],[1,2.02,4.55],[2,1.91,4.55]],"ltp":2.26,"tv":71.24,"id":424676}]}]}
{"op":"mcm","clk":"11798602074","pt":1723153867231,"mc":[{"id":"1.231501231","rc":[{"batb":[[0,2.22,14],[1,2.2,31.59],[2,2.02,4.55]],"ltp":2.26,"tv":71.24,"id":424676}]}]}
{"op":"mcm","clk":"11798602199","pt":1723153869639,"mc":[{"id":"1.231501231","rc":[{"batb":[[0,2.22,10]],"ltp":2.26,"tv":71.24,"id":424676}]}]}
{"op":"mcm","clk":"11798602226","pt":1723153870513,"mc":[{"id":"1.231501231","rc":[{"batb":[[0,2.2,31.59],[1,2.02,4.55],[2,1.91,4.55]],"ltp":2.26,"tv":71.24,"id":424676}]}]}
{"op":"mcm","clk":"11798602282","pt":1723153872001,"mc":[{"id":"1.231501231","rc":[{"batb":[[0,2.22,4],[1,2.2,31.59],[2,2.02,4.55]],"ltp":2.26,"tv":71.24,"id":424676}]}]}
{"op":"mcm","clk":"11798602373","pt":1723153874309,"mc":[{"id":"1.231501231","rc":[{"batb":[[0,2.24,10]],"ltp":2.26,"tv":71.24,"id":424676}]}]}
{"op":"mcm","clk":"11798602499","pt":1723153877645,"mc":[{"id":"1.231501231","rc":[{"batb":[[0,2.26,4]],"ltp":2.26,"tv":71.24,"id":424676}]}]}
{"op":"mcm","clk":"11798602611","pt":1723153879953,"mc":[{"id":"1.231501231","rc":[{"batb":[[0,2.22,10]],"ltp":2.26,"tv":71.24,"id":424676}]}]}
{"op":"mcm","clk":"11798602732","pt":1723153882569,"mc":[{"id":"1.231501231","rc":[{"batb":[[0,2.24,4],[1,2.22,10],[2,2.2,31.59]],"ltp":2.26,"tv":71.24,"id":424676}]}]}
{"op":"mcm","clk":"11798602771","pt":1723153883238,"mc":[{"id":"1.231501231","rc":[{"batb":[[1,2.2,31.59],[2,2.02,4.55]],"ltp":2.26,"tv":71.24,"id":424676}]}]}
{"op":"mcm","clk":"11798602831","pt":1723153884825,"mc":[{"id":"1.231501231","rc":[{"batb":[[0,2.2,31.59],[1,2.02,4.55],[2,1.91,4.55]],"ltp":2.26,"tv":71.24,"id":424676}]}]}
{"op":"mcm","clk":"11798602872","pt":1723153885956,"mc":[{"id":"1.231501231","rc":[{"batb":[[0,2.22,10],[1,2.2,31.59],[2,2.02,4.55]],"ltp":2.26,"tv":71.24,"id":424676}]}]}
{"op":"mcm","clk":"11798602912","pt":1723153887035,"mc":[{"id":"1.231501231","rc":[{"batb":[[0,2.24,4],[1,2.22,10],[2,2.2,31.59]],"ltp":2.26,"tv":71.24,"id":424676}]}]}
{"op":"mcm","clk":"11798603013","pt":1723153889343,"mc":[{"id":"1.231501231","rc":[{"batb":[[0,2.2,31.59],[1,2.02,4.55],[2,1.91,4.55]],"ltp":2.26,"tv":71.24,"id":424676}]}]}
{"op":"mcm","clk":"11798603116","pt":1723153891977,"mc":[{"id":"1.231501231","rc":[{"batb":[[0,2.22,14],[1,2.2,31.59],[2,2.02,4.55]],"ltp":2.26,"tv":71.24,"id":424676}]}]}
{"op":"mcm","clk":"11798603228","pt":1723153894340,"mc":[{"id":"1.231501231","rc":[{"batb":[[0,2.22,10]],"ltp":2.26,"tv":71.24,"id":424676}]}]}
{"op":"mcm","clk":"11798603261","pt":1723153895367,"mc":[{"id":"1.231501231","rc":[{"batb":[[0,2.2,31.59],[1,2.02,4.55],[2,1.91,4.55]],"ltp":2.26,"tv":71.24,"id":424676}]}]}
{"op":"mcm","clk":"11798603309","pt":1723153896750,"mc":[{"id":"1.231501231","rc":[{"batb":[[0,2.22,4],[1,2.2,31.59],[2,2.02,4.55]],"ltp":2.26,"tv":71.24,"id":424676}]}]}
{"op":"mcm","clk":"11798603388","pt":1723153899156,"mc":[{"id":"1.231501231","rc":[{"batb":[[0,2.22,10]],"ltp":2.26,"tv":71.24,"id":424676}]}]}
{"op":"mcm","clk":"11798603462","pt":1723153901564,"mc":[{"id":"1.231501231","rc":[{"batb":[[0,2.24,4],[1,2.22,10],[2,2.2,31.59]],"ltp":2.26,"tv":71.24,"id":424676}]}]}
{"op":"mcm","clk":"11798603506","pt":1723153902593,"mc":[{"id":"1.231501231","rc":[{"batb":[[1,2.2,31.59],[2,2.02,4.55]],"ltp":2.26,"tv":71.24,"id":424676}]}]}
{"op":"mcm","clk":"11798603558","pt":1723153903770,"mc":[{"id":"1.231501231","rc":[{"batb":[[0,2.2,31.59],[1,2.02,4.55],[2,1.91,4.55]],"ltp":2.26,"tv":71.24,"id":424676}]}]}
{"op":"mcm","clk":"11798603588","pt":1723153904960,"mc":[{"id":"1.231501231","rc":[{"batb":[[0,2.22,10],[1,2.2,31.59],[2,2.02,4.55]],"ltp":2.26,"tv":71.24,"id":424676}]}]}
{"op":"mcm","clk":"11798603635","pt":1723153906188,"mc":[{"id":"1.231501231","rc":[{"batb":[[0,2.24,4],[1,2.22,10],[2,2.2,31.59]],"ltp":2.26,"tv":71.24,"id":424676}]}]}
{"op":"mcm","clk":"11798603717","pt":1723153908595,"mc":[{"id":"1.231501231","rc":[{"batb":[[0,2.2,31.59],[1,2.02,4.55],[2,1.91,4.55]],"ltp":2.26,"tv":71.24,"id":424676}]}]}
{"op":"mcm","clk":"11798603805","pt":1723153911007,"mc":[{"id":"1.231501231","rc":[{"batb":[[0,2.22,14],[1,2.2,31.59],[2,2.02,4.55]],"ltp":2.26,"tv":71.24,"id":424676}]}]}
{"op":"mcm","clk":"11798603877","pt":1723153913366,"mc":[{"id":"1.231501231","rc":[{"batb":[[0,2.22,10]],"ltp":2.26,"tv":71.24,"id":424676}]}]}
{"op":"mcm","clk":"11798603908","pt":1723153914492,"mc":[{"id":"1.231501231","rc":[{"batb":[[0,2.2,31.59],[1,2.02,4.55],[2,1.91,4.55]],"ltp":2.26,"tv":71.24,"id":424676}]}]}
{"op":"mcm","clk":"11798603982","pt":1723153916595,"mc":[{"id":"1.231501231","rc":[{"batb":[[0,2.22,14],[1,2.2,31.59],[2,2.02,4.55]],"ltp":2.26,"tv":71.24,"id":424676}]}]}
{"op":"mcm","clk":"11798604093","pt":1723153919781,"mc":[{"id":"1.231501231","rc":[{"batb":[[0,2.2,31.59],[1,2.02,4.55],[2,1.91,4.55]],"ltp":2.26,"tv":71.24,"id":424676}]}]}
{"op":"mcm","clk":"11798604236","pt":1723153923488,"mc":[{"id":"1.231501231","rc":[{"batb":[[0,2.22,14],[1,2.2,31.59],[2,2.02,4.55]],"ltp":2.26,"tv":71.24,"id":424676}]}]}
{"op":"mcm","clk":"11798604338","pt":1723153925797,"mc":[{"id":"1.231501231","rc":[{"batb":[[0,2.22,10]],"ltp":2.26,"tv":71.24,"id":424676}]}]}
{"op":"mcm","clk":"11798604374","pt":1723153926820,"mc":[{"id":"1.231501231","rc":[{"batb":[[0,2.2,31.59],[1,2.02,4.55],[2,1.91,4.55]],"ltp":2.26,"tv":71.24,"id":424676}]}]}
{"op":"mcm","clk":"11798604427","pt":1723153928207,"mc":[{"id":"1.231501231","rc":[{"batb":[[0,2.22,4],[1,2.2,31.59],[2,2.02,4.55]],"ltp":2.26,"tv":71.24,"id":424676}]}]}
{"op":"mcm","clk":"11798604501","pt":1723153930619,"mc":[{"id":"1.231501231","rc":[{"batb":[[0,2.24,10]],"ltp":2.26,"tv":71.24,"id":424676}]}]}
{"op":"mcm","clk":"11798604586","pt":1723153933899,"mc":[{"id":"1.231501231","rc":[{"batb":[[0,2.26,4]],"ltp":2.26,"tv":71.24,"id":424676}]}]}
{"op":"mcm","clk":"11798604678","pt":1723153936404,"mc":[{"id":"1.231501231","rc":[{"batb":[[0,2.28,10]],"ltp":2.26,"tv":71.24,"id":424676}]}]}
{"op":"mcm","clk":"11798604763","pt":1723153938610,"mc":[{"id":"1.231501231","rc":[{"batb":[[0,2.3,4],[1,2.28,10],[2,2.2,31.59]],"ltp":2.26,"tv":71.24,"id":424676}]}]}
{"op":"mcm","clk":"11798604848","pt":1723153939741,"mc":[{"id":"1.231501231","rc":[{"batb":[[1,2.2,31.59],[2,2.02,4.55]],"ltp":2.26,"tv":71.24,"id":424676}]}]}
{"op":"mcm","clk":"11798604947","pt":1723153941033,"mc":[{"id":"1.231501231","rc":[{"batb":[[0,2.2,31.59],[1,2.02,4.55],[2,1.91,4.55]],"ltp":2.26,"tv":71.24,"id":424676}]}]}
{"op":"mcm","clk":"11798605021","pt":1723153942215,"mc":[{"id":"1.231501231","rc":[{"batb":[[0,2.22,10],[1,2.2,31.59],[2,2.02,4.55]],"ltp":2.26,"tv":71.24,"id":424676}]}]}
{"op":"mcm","clk":"11798605246","pt":1723153945557,"mc":[{"id":"1.231501231","rc":[{"batb":[[0,2.24,4]],"ltp":2.26,"tv":71.24,"id":424676}]}]}
{"op":"mcm","clk":"11798605389","pt":1723153947926,"mc":[{"id":"1.231501231","rc":[{"batb":[[0,2.22,10]],"ltp":2.26,"tv":71.24,"id":424676}]}]}
{"op":"mcm","clk":"11798605514","pt":1723153950433,"mc":[{"id":"1.231501231","rc":[{"batb":[[0,2.24,4],[1,2.22,10],[2,2.2,31.59]],"ltp":2.26,"tv":71.24,"id":424676}]}]}
{"op":"mcm","clk":"11798605561","pt":1723153951306,"mc":[{"id":"1.231501231","rc":[{"batb":[[1,2.2,31.59],[2,2.02,4.55]],"ltp":2.26,"tv":71.24,"id":424676}]}]}
{"op":"mcm","clk":"11798605625","pt":1723153952840,"mc":[{"id":"1.231501231","rc":[{"batb":[[0,2.2,31.59],[1,2.02,4.55],[2,1.91,4.55]],"ltp":2.26,"tv":71.24,"id":424676}]}]}
{"op":"mcm","clk":"11798605674","pt":1723153953917,"mc":[{"id":"1.231501231","rc":[{"batb":[[0,2.22,10],[1,2.2,31.59],[2,2.02,4.55]],"ltp":2.26,"tv":71.24,"id":424676}]}]}
{"op":"mcm","clk":"11798605754","pt":1723153956229,"mc":[{"id":"1.231501231","rc":[{"batb":[[0,2.24,4],[1,2.22,10],[2,2.2,31.59]],"ltp":2.26,"tv":71.24,"id":424676}]}]}
{"op":"mcm","clk":"11798605788","pt":1723153957150,"mc":[{"id":"1.231501231","rc":[{"batb":[[1,2.2,31.59],[2,2.02,4.55]],"ltp":2.26,"tv":71.24,"id":424676}]}]}
{"op":"mcm","clk":"11798605849","pt":1723153958537,"mc":[{"id":"1.231501231","rc":[{"batb":[[0,2.2,31.59],[1,2.02,4.55],[2,1.91,4.55]],"ltp":2.26,"tv":71.24,"id":424676}]}]}
{"op":"mcm","clk":"11798605946","pt":1723153959827,"mc":[{"id":"1.231501231","rc":[{"batb":[[0,2.22,10],[1,2.2,31.59],[2,2.02,4.55]],"ltp":2.26,"tv":71.24,"id":424676}]}]}
{"op":"mcm","clk":"11798606112","pt":1723153963147,"mc":[{"id":"1.231501231","rc":[{"batb":[[0,2.24,4]],"ltp":2.26,"tv":71.24,"id":424676}]}]}
{"op":"mcm","clk":"11798606213","pt":1723153965553,"mc":[{"id":"1.231501231","rc":[{"batb":[[0,2.26,10]],"ltp":2.26,"tv":71.24,"id":424676}]}]}
{"op":"mcm","clk":"11798606367","pt":1723153968943,"mc":[{"id":"1.231501231","rc":[{"batb":[[0,2.2,31.59],[1,2.02,4.55],[2,1.91,4.55]],"ltp":2.26,"tv":71.24,"id":424676}]}]}
{"op":"mcm","clk":"11798606371","pt":1723153969046,"mc":[{"id":"1.231501231","rc":[{"batb":[[0,2.22,4],[1,2.2,31.59],[2,2.02,4.55]],"ltp":2.26,"tv":71.24,"id":424676}]}]}
{"op":"mcm","clk":"11798606472","pt":1723153971455,"mc":[{"id":"1.231501231","rc":[{"batb":[[0,2.22,10]],"ltp":2.26,"tv":71.24,"id":424676}]}]}
{"op":"mcm","clk":"11798606631","pt":1723153974967,"mc":[{"id":"1.231501231","rc":[{"batb":[[0,2.24,4]],"ltp":2.26,"tv":71.24,"id":424676}]}]}
{"op":"mcm","clk":"11798606739","pt":1723153977355,"mc":[{"id":"1.231501231","rc":[{"batb":[[0,2.26,10]],"ltp":2.26,"tv":71.24,"id":424676}]}]}
{"op":"mcm","clk":"11798606849","pt":1723153980640,"mc":[{"id":"1.231501231","rc":[{"batb":[[0,2.22,4]],"ltp":2.26,"tv":71.24,"id":424676}]}]}
{"op":"mcm","clk":"11798606923","pt":1723153982949,"mc":[{"id":"1.231501231","rc":[{"batb":[[0,2.22,10]],"ltp":2.26,"tv":71.24,"id":424676}]}]}
{"op":"mcm","clk":"11798607011","pt":1723153985266,"mc":[{"id":"1.231501231","rc":[{"batb":[[0,2.24,4],[1,2.22,10],[2,2.2,31.59]],"ltp":2.26,"tv":71.24,"id":424676}]}]}
{"op":"mcm","clk":"11798607041","pt":1723153986242,"mc":[{"id":"1.231501231","rc":[{"batb":[[1,2.2,31.59],[2,2.02,4.55]],"ltp":2.26,"tv":71.24,"id":424676}]}]}
{"op":"mcm","clk":"11798607074","pt":1723153987572,"mc":[{"id":"1.231501231","rc":[{"batb":[[0,2.2,31.59],[1,2.02,4.55],[2,1.91,4.55]],"ltp":2.26,"tv":71.24,"id":424676}]}]}
{"op":"mcm","clk":"11798607158","pt":1723153989887,"mc":[{"id":"1.231501231","rc":[{"batb":[[0,2.22,14],[1,2.2,31.59],[2,2.02,4.55]],"ltp":2.26,"tv":71.24,"id":424676}]}]}
{"op":"mcm","clk":"11798607240","pt":1723153992246,"mc":[{"id":"1.231501231","rc":[{"batb":[[0,2.22,10]],"ltp":2.26,"tv":71.24,"id":424676}]}]}
{"op":"mcm","clk":"11798607272","pt":1723153993270,"mc":[{"id":"1.231501231","rc":[{"batb":[[0,2.2,31.59],[1,2.02,4.55],[2,1.91,4.55]],"ltp":2.26,"tv":71.24,"id":424676}]}]}
{"op":"mcm","clk":"11798607320","pt":1723153994652,"mc":[{"id":"1.231501231","rc":[{"batb":[[0,2.22,4],[1,2.2,31.59],[2,2.02,4.55]],"ltp":2.26,"tv":71.24,"id":424676}]}]}
{"op":"mcm","clk":"11798607396","pt":1723153997057,"mc":[{"id":"1.231501231","rc":[{"batb":[[0,2.24,10]],"ltp":2.26,"tv":71.24,"id":424676}]}]}
{"op":"mcm","clk":"11798607480","pt":1723154000391,"mc":[{"id":"1.231501231","rc":[{"batb":[[0,2.26,4]],"ltp":2.26,"tv":71.24,"id":424676}]}]}
{"op":"mcm","clk":"11798607574","pt":1723154002961,"mc":[{"id":"1.231501231","rc":[{"batb":[[0,2.22,10]],"ltp":2.26,"tv":71.24,"id":424676}]}]}
{"op":"mcm","clk":"11798607691","pt":1723154005067,"mc":[{"id":"1.231501231","rc":[{"batb":[[0,2.24,4],[1,2.22,10],[2,2.2,31.59]],"ltp":2.26,"tv":71.24,"id":424676}]}]}
{"op":"mcm","clk":"11798607736","pt":1723154006400,"mc":[{"id":"1.231501231","rc":[{"batb":[[1,2.2,31.59],[2,2.02,4.55]],"ltp":2.26,"tv":71.24,"id":424676}]}]}
{"op":"mcm","clk":"11798607770","pt":1723154007581,"mc":[{"id":"1.231501231","rc":[{"batb":[[0,2.2,31.59],[1,2.02,4.55],[2,1.91,4.55]],"ltp":2.26,"tv":71.24,"id":424676}]}]}
{"op":"mcm","clk":"11798607844","pt":1723154009990,"mc":[{"id":"1.231501231","rc":[{"batb":[[0,2.22,14],[1,2.2,31.59],[2,2.02,4.55]],"ltp":2.26,"tv":71.24,"id":424676}]}]}
{"op":"mcm","clk":"11798607922","pt":1723154012401,"mc":[{"id":"1.231501231","rc":[{"batb":[[0,2.22,10]],"ltp":2.26,"tv":71.24,"id":424676}]}]}
{"op":"mcm","clk":"11798607954","pt":1723154013380,"mc":[{"id":"1.231501231","rc":[{"batb":[[0,2.2,31.59],[1,2.02,4.55],[2,1.91,4.55]],"ltp":2.26,"tv":71.24,"id":424676}]}]}
{"op":"mcm","clk":"11798607997","pt":1723154014610,"mc":[{"id":"1.231501231","rc":[{"batb":[[0,2.22,4],[1,2.2,31.59],[2,2.02,4.55]],"ltp":2.26,"tv":71.24,"id":424676}]}]}
{"op":"mcm","clk":"11798608077","pt":1723154016899,"mc":[{"id":"1.231501231","rc":[{"batb":[[0,2.24,10]],"ltp":2.26,"tv":71.24,"id":424676}]}]}
{"op":"mcm","clk":"11798608220","pt":1723154019983,"mc":[{"id":"1.231501231","rc":[{"batb":[[0,2.22,4]],"ltp":2.26,"tv":71.24,"id":424676}]}]}
{"op":"mcm","clk":"11798608320","pt":1723154022599,"mc":[{"id":"1.231501231","rc":[{"batb":[[0,2.22,10]],"ltp":2.26,"tv":71.24,"id":424676}]}]}
{"op":"mcm","clk":"11798608431","pt":1723154025930,"mc":[{"id":"1.231501231","rc":[{"batb":[[0,2.24,4]],"ltp":2.26,"tv":71.24,"id":424676}]}]}
{"op":"mcm","clk":"11798608511","pt":1723154028189,"mc":[{"id":"1.231501231","rc":[{"batb":[[0,2.26,10]],"ltp":2.26,"tv":71.24,"id":424676}]}]}
{"op":"mcm","clk":"11798608611","pt":1723154030497,"mc":[{"id":"1.231501231","rc":[{"batb":[[0,2.28,4],[1,2.26,10],[2,2.2,31.59]],"ltp":2.26,"tv":71.24,"id":424676}]}]}
{"op":"mcm","clk":"11798608666","pt":1723154031626,"mc":[{"id":"1.231501231","rc":[{"batb":[[1,2.2,31.59],[2,2.02,4.55]],"ltp":2.26,"tv":71.24,"id":424676}]}]}
{"op":"mcm","clk":"11798608713","pt":1723154032910,"mc":[{"id":"1.231501231","rc":[{"batb":[[0,2.2,31.59],[1,2.02,4.55],[2,1.91,4.55]],"ltp":2.26,"tv":71.24,"id":424676}]}]}
{"op":"mcm","clk":"11798608758","pt":1723154034136,"mc":[{"id":"1.231501231","rc":[{"batb":[[0,2.22,10],[1,2.2,31.59],[2,2.02,4.55]],"ltp":2.26,"tv":71.24,"id":424676}]}]}
{"op":"mcm","clk":"11798608801","pt":1723154035212,"mc":[{"id":"1.231501231","rc":[{"batb":[[0,2.24,4],[1,2.22,10],[2,2.2,31.59]],"ltp":2.26,"tv":71.24,"id":424676}]}]}
{"op":"mcm","clk":"11798608884","pt":1723154037622,"mc":[{"id":"1.231501231","rc":[{"batb":[[0,2.2,31.59],[1,2.02,4.55],[2,1.91,4.55]],"ltp":2.26,"tv":71.24,"id":424676}]}]}
{"op":"mcm","clk":"11798609005","pt":1723154041007,"mc":[{"id":"1.231501231","rc":[{"batb":[[0,2.22,14],[1,2.2,31.59],[2,2.02,4.55]],"ltp":2.26,"tv":71.24,"id":424676}]}]}
{"op":"mcm","clk":"11798609073","pt":1723154043416,"mc":[{"id":"1.231501231","rc":[{"batb":[[0,2.22,10]],"ltp":2.26,"tv":71.24,"id":424676}]}]}
{"op":"mcm","clk":"11798609111","pt":1723154044438,"mc":[{"id":"1.231501231","rc":[{"batb":[[0,2.2,31.59],[1,2.02,4.55],[2,1.91,4.55]],"ltp":2.26,"tv":71.24,"id":424676}]}]}
{"op":"mcm","clk":"11798609165","pt":1723154045617,"mc":[{"id":"1.231501231","rc":[{"batb":[[0,2.22,4],[1,2.2,31.59],[2,2.02,4.55]],"ltp":2.26,"tv":71.24,"id":424676}]}]}
{"op":"mcm","clk":"11798609195","pt":1723154046844,"mc":[{"id":"1.231501231","rc":[{"batb":[[0,2.24,10],[1,2.22,4],[2,2.2,31.59]],"ltp":2.26,"tv":71.24,"id":424676}]}]}
{"op":"mcm","clk":"11798609251","pt":1723154048128,"mc":[{"id":"1.231501231","rc":[{"batb":[[1,2.2,31.59],[2,2.02,4.55]],"ltp":2.26,"tv":71.24,"id":424676}]}]}
{"op":"mcm","clk":"11798609310","pt":1723154050126,"mc":[{"id":"1.231501231","rc":[{"batb":[[0,2.2,31.59],[1,2.02,4.55],[2,1.91,4.55]],"ltp":2.26,"tv":71.24,"id":424676}]}]}
{"op":"mcm","clk":"11798609368","pt":1723154051458,"mc":[{"id":"1.231501231","rc":[{"batb":[[0,2.22,4],[1,2.2,31.59],[2,2.02,4.55]],"ltp":2.26,"tv":71.24,"id":424676}]}]}
{"op":"mcm","clk":"11798609411","pt":1723154052637,"mc":[{"id":"1.231501231","rc":[{"batb":[[0,2.24,10],[1,2.22,4],[2,2.2,31.59]],"ltp":2.26,"tv":71.24,"id":424676}]}]}
{"op":"mcm","clk":"11798609443","pt":1723154053816,"mc":[{"id":"1.231501231","rc":[{"batb":[[1,2.2,31.59],[2,2.02,4.55]],"ltp":2.26,"tv":71.24,"id":424676}]}]}
{"op":"mcm","clk":"11798609510","pt":1723154056127,"mc":[{"id":"1.231501231","rc":[{"batb":[[0,2.26,4]],"ltp":2.26,"tv":71.24,"id":424676}]}]}
{"op":"mcm","clk":"11798609580","pt":1723154058331,"mc":[{"id":"1.231501231","rc":[{"batb":[[0,2.22,10]],"ltp":2.26,"tv":71.24,"id":424676}]}]}
{"op":"mcm","clk":"11798609676","pt":1723154061763,"mc":[{"id":"1.231501231","rc":[{"batb":[[0,2.24,4]],"ltp":2.26,"tv":71.24,"id":424676}]}]}
{"op":"mcm","clk":"11798609725","pt":1723154063969,"mc":[{"id":"1.231501231","rc":[{"batb":[[0,2.2,31.59],[1,2.02,4.55],[2,1.91,4.55]],"ltp":2.26,"tv":71.24,"id":424676}]}]}
{"op":"mcm","clk":"11798609729","pt":1723154064069,"mc":[{"id":"1.231501231","rc":[{"batb":[[0,2.26,10],[1,2.2,31.59],[2,2.02,4.55]],"ltp":2.26,"tv":71.24,"id":424676}]}]}
{"op":"mcm","clk":"11798609799","pt":1723154066476,"mc":[{"id":"1.231501231","rc":[{"batb":[[0,2.28,4],[1,2.26,10],[2,2.2,31.59]],"ltp":2.26,"tv":71.24,"id":424676}]}]}
{"op":"mcm","clk":"11798609835","pt":1723154067349,"mc":[{"id":"1.231501231","rc":[{"batb":[[1,2.2,31.59],[2,2.02,4.55]],"ltp":2.26,"tv":71.24,"id":424676}]}]}
{"op":"mcm","clk":"11798609869","pt":1723154068781,"mc":[{"id":"1.231501231","rc":[{"batb":[[0,2.2,31.59],[1,2.02,4.55],[2,1.91,4.55]],"ltp":2.26,"tv":71.24,"id":424676}]}]}
{"op":"mcm","clk":"11798609940","pt":1723154071071,"mc":[{"id":"1.231501231","rc":[{"batb":[[0,2.22,14],[1,2.2,31.59],[2,2.02,4.55]],"ltp":2.26,"tv":71.24,"id":424676}]}]}
{"op":"mcm","clk":"11798610010","pt":1723154073483,"mc":[{"id":"1.231501231","rc":[{"batb":[[0,2.22,10]],"ltp":2.26,"tv":71.24,"id":424676}]}]}
{"op":"mcm","clk":"11798610040","pt":1723154074456,"mc":[{"id":"1.231501231","rc":[{"batb":[[0,2.2,31.59],[1,2.02,4.55],[2,1.91,4.55]],"ltp":2.26,"tv":71.24,"id":424676}]}]}
{"op":"mcm","clk":"11798610077","pt":1723154075683,"mc":[{"id":"1.231501231","rc":[{"batb":[[0,2.22,4],[1,2.2,31.59],[2,2.02,4.55]],"ltp":2.26,"tv":71.24,"id":424676}]}]}
{"op":"mcm","clk":"11798610154","pt":1723154077989,"mc":[{"id":"1.231501231","rc":[{"batb":[[0,2.24,10]],"ltp":2.26,"tv":71.24,"id":424676}]}]}
{"op":"mcm","clk":"11798610232","pt":1723154081374,"mc":[{"id":"1.231501231","rc":[{"batb":[[0,2.22,4]],"ltp":2.26,"tv":71.24,"id":424676}]}]}
{"op":"mcm","clk":"11798610298","pt":1723154083779,"mc":[{"id":"1.231501231","rc":[{"batb":[[0,2.22,10]],"ltp":2.26,"tv":71.24,"id":424676}]}]}
{"op":"mcm","clk":"11798610350","pt":1723154086186,"mc":[{"id":"1.231501231","rc":[{"batb":[[0,2.24,4],[1,2.22,10],[2,2.2,31.59]],"ltp":2.26,"tv":71.24,"id":424676}]}]}
{"op":"mcm","clk":"11798610373","pt":1723154087162,"mc":[{"id":"1.231501231","rc":[{"batb":[[1,2.2,31.59],[2,2.02,4.55]],"ltp":2.26,"tv":71.24,"id":424676}]}]}
{"op":"mcm","clk":"11798610424","pt":1723154088491,"mc":[{"id":"1.231501231","rc":[{"batb":[[0,2.2,31.59],[1,2.02,4.55],[2,1.91,4.55]],"ltp":2.26,"tv":71.24,"id":424676}]}]}
{"op":"mcm","clk":"11798610456","pt":1723154089569,"mc":[{"id":"1.231501231","rc":[{"batb":[[0,2.22,10],[1,2.2,31.59],[2,2.02,4.55]],"ltp":2.26,"tv":71.24,"id":424676}]}]}
{"op":"mcm","clk":"11798610571","pt":1723154092899,"mc":[{"id":"1.231501231","rc":[{"batb":[[0,2.24,4]],"ltp":2.26,"tv":71.24,"id":424676}]}]}
{"op":"mcm","clk":"11798610609","pt":1723154094588,"mc":[{"id":"1.231501231","rc":[{"batb":[[0,2.2,31.59],[1,2.02,4.55],[2,1.91,4.55]],"ltp":2.26,"tv":71.24,"id":424676}]}]}
{"op":"mcm","clk":"11798610686","pt":1723154097704,"mc":[{"id":"1.231501231","rc":[{"batb":[[0,2.22,14],[1,2.2,31.59],[2,2.02,4.55]],"ltp":2.26,"tv":71.24,"id":424676}]}]}
{"op":"mcm","clk":"11798610779","pt":1723154100986,"mc":[{"id":"1.231501231","rc":[{"batb":[[0,2.2,31.59],[1,2.02,4.55],[2,1.91,4.55]],"ltp":2.26,"tv":71.24,"id":424676}]}]}
{"op":"mcm","clk":"11798610859","pt":1723154103803,"mc":[{"id":"1.231501231","rc":[{"batb":[[0,2.22,14],[1,2.2,31.59],[2,2.02,4.55]],"ltp":2.26,"tv":71.24,"id":424676}]}]}
{"op":"mcm","clk":"11798610939","pt":1723154106007,"mc":[{"id":"1.231501231","rc":[{"batb":[[0,2.22,10]],"ltp":2.26,"tv":71.24,"id":424676}]}]}
{"op":"mcm","clk":"11798610957","pt":1723154107129,"mc":[{"id":"1.231501231","rc":[{"batb":[[0,2.2,31.59],[1,2.02,4.55],[2,1.91,4.55]],"ltp":2.26,"tv":71.24,"id":424676}]}]}
{"op":"mcm","clk":"11798610994","pt":1723154108308,"mc":[{"id":"1.231501231","rc":[{"batb":[[0,2.22,4],[1,2.2,31.59],[2,2.02,4.55]],"ltp":2.26,"tv":71.24,"id":424676}]}]}
{"op":"mcm","clk":"11798611049","pt":1723154110000,"mc":[{"id":"1.231501231","rc":[{"batb":[[0,2.24,10],[1,2.22,4],[2,2.2,31.59]],"ltp":2.26,"tv":71.24,"id":424676}]}]}
{"op":"mcm","clk":"11798611072","pt":1723154110815,"mc":[{"id":"1.231501231","rc":[{"batb":[[1,2.2,31.59],[2,2.02,4.55]],"ltp":2.26,"tv":71.24,"id":424676}]}]}
{"op":"mcm","clk":"11798611144","pt":1723154113321,"mc":[{"id":"1.231501231","rc":[{"batb":[[0,2.22,4]],"ltp":2.26,"tv":71.24,"id":424676}]}]}
{"op":"mcm","clk":"11798611205","pt":1723154115830,"mc":[{"id":"1.231501231","rc":[{"batb":[[0,2.22,10]],"ltp":2.26,"tv":71.24,"id":424676}]}]}
{"op":"mcm","clk":"11798611289","pt":1723154118091,"mc":[{"id":"1.231501231","rc":[{"batb":[[0,2.24,4],[1,2.22,10],[2,2.2,31.59]],"ltp":2.26,"tv":71.24,"id":424676}]}]}
{"op":"mcm","clk":"11798611320","pt":1723154119118,"mc":[{"id":"1.231501231","rc":[{"batb":[[1,2.2,31.59],[2,2.02,4.55]],"ltp":2.26,"tv":71.24,"id":424676}]}]}
{"op":"mcm","clk":"11798611371","pt":1723154120605,"mc":[{"id":"1.231501231","rc":[{"batb":[[0,2.2,31.59],[1,2.02,4.55],[2,1.91,4.55]],"ltp":2.26,"tv":71.24,"id":424676}]}]}
{"op":"mcm","clk":"11798611456","pt":1723154122911,"mc":[{"id":"1.231501231","rc":[{"batb":[[0,2.24,4],[1,2.22,10],[2,2.2,31.59]],"ltp":2.26,"tv":71.24,"id":424676}]}]}
{"op":"mcm","clk":"11798611528","pt":1723154125226,"mc":[{"id":"1.231501231","rc":[{"batb":[[0,2.22,10],[1,2.2,31.59],[2,2.02,4.55]],"ltp":2.26,"tv":71.24,"id":424676}]}]}
{"op":"mcm","clk":"11798611550","pt":1723154126101,"mc":[{"id":"1.231501231","rc":[{"batb":[[0,2.2,31.59],[1,2.02,4.55],[2,1.91,4.55]],"ltp":2.26,"tv":71.24,"id":424676}]}]}
{"op":"mcm","clk":"11798611643","pt":1723154129531,"mc":[{"id":"1.231501231","rc":[{"batb":[[0,2.22,14],[1,2.2,31.59],[2,2.02,4.55]],"ltp":2.26,"tv":71.24,"id":424676}]}]}
{"op":"mcm","clk":"11798611719","pt":1723154131836,"mc":[{"id":"1.231501231","rc":[{"batb":[[0,2.22,10]],"ltp":2.26,"tv":71.24,"id":424676}]}]}
{"op":"mcm","clk":"11798611745","pt":1723154132706,"mc":[{"id":"1.231501231","rc":[{"batb":[[0,2.2,31.59],[1,2.02,4.55],[2,1.91,4.55]],"ltp":2.26,"tv":71.24,"id":424676}]}]}
{"op":"mcm","clk":"11798611780","pt":1723154134144,"mc":[{"id":"1.231501231","rc":[{"batb":[[0,2.22,4],[1,2.2,31.59],[2,2.02,4.55]],"ltp":2.26,"tv":71.24,"id":424676}]}]}
{"op":"mcm","clk":"11798611818","pt":1723154135419,"mc":[{"id":"1.231501231","rc":[{"batb":[[0,2.24,10],[1,2.22,4],[2,2.2,31.59]],"ltp":2.26,"tv":71.24,"id":424676}]}]}
{"op":"mcm","clk":"11798611866","pt":1723154136545,"mc":[{"id":"1.231501231","rc":[{"batb":[[1,2.2,31.59],[2,2.02,4.55]],"ltp":2.26,"tv":71.24,"id":424676}]}]}
{"op":"mcm","clk":"11798611944","pt":1723154138748,"mc":[{"id":"1.231501231","rc":[{"batb":[[0,2.26,4]],"ltp":2.26,"tv":71.24,"id":424676}]}]}
{"op":"mcm","clk":"11798612017","pt":1723154141153,"mc":[{"id":"1.231501231","rc":[{"batb":[[0,2.28,10]],"ltp":2.26,"tv":71.24,"id":424676}]}]}
{"op":"mcm","clk":"11798612137","pt":1723154144653,"mc":[{"id":"1.231501231","rc":[{"batb":[[0,2.22,4]],"ltp":2.26,"tv":71.24,"id":424676}]}]}
{"op":"mcm","clk":"11798612203","pt":1723154146956,"mc":[{"id":"1.231501231","rc":[{"batb":[[0,2.24,10]],"ltp":2.26,"tv":71.24,"id":424676}]}]}
{"op":"mcm","clk":"11798612303","pt":1723154150242,"mc":[{"id":"1.231501231","rc":[{"batb":[[0,2.22,4]],"ltp":2.26,"tv":71.24,"id":424676}]}]}
{"op":"mcm","clk":"11798612372","pt":1723154152647,"mc":[{"id":"1.231501231","rc":[{"batb":[[0,2.2,31.59],[1,2.02,4.55],[2,1.91,4.55]],"ltp":2.26,"tv":71.24,"id":424676}]}]}
{"op":"mcm","clk":"11798612381","pt":1723154153056,"mc":[{"id":"1.231501231","rc":[{"batb":[[0,2.22,10],[1,2.2,31.59],[2,2.02,4.55]],"ltp":2.26,"tv":71.24,"id":424676}]}]}
{"op":"mcm","clk":"11798612441","pt":1723154155257,"mc":[{"id":"1.231501231","rc":[{"batb":[[0,2.24,4],[1,2.22,10],[2,2.2,31.59]],"ltp":2.26,"tv":71.24,"id":424676}]}]}
{"op":"mcm","clk":"11798612481","pt":1723154156486,"mc":[{"id":"1.231501231","rc":[{"batb":[[1,2.2,31.59],[2,2.02,4.55]],"ltp":2.26,"tv":71.24,"id":424676}]}]}
{"op":"mcm","clk":"11798612518","pt":1723154157661,"mc":[{"id":"1.231501231","rc":[{"batb":[[0,2.2,31.59],[1,2.02,4.55],[2,1.91,4.55]],"ltp":2.26,"tv":71.24,"id":424676}]}]}
{"op":"mcm","clk":"11798612604","pt":1723154159868,"mc":[{"id":"1.231501231","rc":[{"batb":[[0,2.22,14],[1,2.2,31.59],[2,2.02,4.55]],"ltp":2.26,"tv":71.24,"id":424676}]}]}
{"op":"mcm","clk":"11798612690","pt":1723154162177,"mc":[{"id":"1.231501231","rc":[{"batb":[[0,2.22,10]],"ltp":2.26,"tv":71.24,"id":424676}]}]}
{"op":"mcm","clk":"11798612733","pt":1723154163353,"mc":[{"id":"1.231501231","rc":[{"batb":[[0,2.2,31.59],[1,2.02,4.55],[2,1.91,4.55]],"ltp":2.26,"tv":71.24,"id":424676}]}]}
{"op":"mcm","clk":"11798612813","pt":1723154165765,"mc":[{"id":"1.231501231","rc":[{"batb":[[0,2.22,14],[1,2.2,31.59],[2,2.02,4.55]],"ltp":2.26,"tv":71.24,"id":424676}]}]}
{"op":"mcm","clk":"11798612894","pt":1723154168085,"mc":[{"id":"1.231501231","rc":[{"batb":[[0,2.22,10]],"ltp":2.26,"tv":71.24,"id":424676}]}]}
{"op":"mcm","clk":"11798612924","pt":1723154169109,"mc":[{"id":"1.231501231","rc":[{"batb":[[0,2.2,31.59],[1,2.02,4.55],[2,1.91,4.55]],"ltp":2.26,"tv":71.24,"id":424676}]}]}
{"op":"mcm","clk":"11798612957","pt":1723154170393,"mc":[{"id":"1.231501231","rc":[{"batb":[[0,2.22,4],[1,2.2,31.59],[2,2.02,4.55]],"ltp":2.26,"tv":71.24,"id":424676}]}]}
{"op":"mcm","clk":"11798613000","pt":1723154171572,"mc":[{"id":"1.231501231","rc":[{"batb":[[0,2.24,10],[1,2.22,4],[2,2.2,31.59]],"ltp":2.26,"tv":71.24,"id":424676}]}]}
{"op":"mcm","clk":"11798613038","pt":1723154172801,"mc":[{"id":"1.231501231","rc":[{"batb":[[1,2.2,31.59],[2,2.02,4.55]],"ltp":2.26,"tv":71.24,"id":424676}]}]}
{"op":"mcm","clk":"11798613102","pt":1723154175001,"mc":[{"id":"1.231501231","rc":[{"batb":[[0,2.2,31.59],[1,2.02,4.55],[2,1.91,4.55]],"ltp":2.26,"tv":71.24,"id":424676}]}]}
{"op":"mcm","clk":"11798613105","pt":1723154175105,"mc":[{"id":"1.231501231","rc":[{"batb":[[0,2.22,4],[1,2.2,31.59],[2,2.02,4.55]],"ltp":2.26,"tv":71.24,"id":424676}]}]}
{"op":"mcm","clk":"11798613178","pt":1723154177370,"mc":[{"id":"1.231501231","rc":[{"batb":[[0,2.24,10]],"ltp":2.26,"tv":71.24,"id":424676}]}]}
{"op":"mcm","clk":"11798613290","pt":1723154180796,"mc":[{"id":"1.231501231","rc":[{"batb":[[0,2.22,4]],"ltp":2.26,"tv":71.24,"id":424676}]}]}
{"op":"mcm","clk":"11798613388","pt":1723154183205,"mc":[{"id":"1.231501231","rc":[{"batb":[[0,2.22,10]],"ltp":2.26,"tv":71.24,"id":424676}]}]}
{"op":"mcm","clk":"11798613484","pt":1723154186486,"mc":[{"id":"1.231501231","rc":[{"batb":[[0,2.24,4]],"ltp":2.26,"tv":71.24,"id":424676}]}]}
{"op":"mcm","clk":"11798613544","pt":1723154188687,"mc":[{"id":"1.231501231","rc":[{"batb":[[0,2.22,10]],"ltp":2.26,"tv":71.24,"id":424676}]}]}
{"op":"mcm","clk":"11798613616","pt":1723154191037,"mc":[{"id":"1.231501231","rc":[{"batb":[[0,2.24,4],[1,2.22,10],[2,2.2,31.59]],"ltp":2.26,"tv":71.24,"id":424676}]}]}
{"op":"mcm","clk":"11798613655","pt":1723154192013,"mc":[{"id":"1.231501231","rc":[{"batb":[[1,2.2,31.59],[2,2.02,4.55]],"ltp":2.26,"tv":71.24,"id":424676}]}]}
{"op":"mcm","clk":"11798613697","pt":1723154193193,"mc":[{"id":"1.231501231","rc":[{"batb":[[0,2.2,31.59],[1,2.02,4.55],[2,1.91,4.55]],"ltp":2.26,"tv":71.24,"id":424676}]}]}
{"op":"mcm","clk":"11798613775","pt":1723154195293,"mc":[{"id":"1.231501231","rc":[{"batb":[[0,2.22,14],[1,2.2,31.59],[2,2.02,4.55]],"ltp":2.26,"tv":71.24,"id":424676}]}]}
{"op":"mcm","clk":"11798613833","pt":1723154197704,"mc":[{"id":"1.231501231","rc":[{"batb":[[0,2.22,10]],"ltp":2.26,"tv":71.24,"id":424676}]}]}
{"op":"mcm","clk":"11798613879","pt":1723154198732,"mc":[{"id":"1.231501231","rc":[{"batb":[[0,2.2,31.59],[1,2.02,4.55],[2,1.91,4.55]],"ltp":2.26,"tv":71.24,"id":424676}]}]}
{"op":"mcm","clk":"11798613969","pt":1723154201401,"mc":[{"id":"1.231501231","rc":[{"batb":[[0,2.22,14],[1,2.2,31.59],[2,2.02,4.55]],"ltp":2.26,"tv":71.24,"id":424676}]}]}
{"op":"mcm","clk":"11798614033","pt":1723154203812,"mc":[{"id":"1.231501231","rc":[{"batb":[[0,2.22,10]],"ltp":2.26,"tv":71.24,"id":424676}]}]}
{"op":"mcm","clk":"11798614059","pt":1723154204732,"mc":[{"id":"1.231501231","rc":[{"batb":[[0,2.2,31.59],[1,2.02,4.55],[2,1.91,4.55]],"ltp":2.26,"tv":71.24,"id":424676}]}]}
{"op":"mcm","clk":"11798614090","pt":1723154205912,"mc":[{"id":"1.231501231","rc":[{"batb":[[0,2.22,4],[1,2.2,31.59],[2,2.02,4.55]],"ltp":2.26,"tv":71.24,"id":424676}]}]}
{"op":"mcm","clk":"11798614131","pt":1723154207246,"mc":[{"id":"1.231501231","rc":[{"batb":[[0,2.24,10],[1,2.22,4],[2,2.2,31.59]],"ltp":2.26,"tv":71.24,"id":424676}]}]}
{"op":"mcm","clk":"11798614175","pt":1723154208419,"mc":[{"id":"1.231501231","rc":[{"batb":[[1,2.2,31.59],[2,2.02,4.55]],"ltp":2.26,"tv":71.24,"id":424676}]}]}
{"op":"mcm","clk":"11798614249","pt":1723154210730,"mc":[{"id":"1.231501231","rc":[{"batb":[[0,2.22,4]],"ltp":2.26,"tv":71.24,"id":424676}]}]}
{"op":"mcm","clk":"11798614320","pt":1723154212930,"mc":[{"id":"1.231501231","rc":[{"batb":[[0,2.2,31.59],[1,2.02,4.55],[2,1.91,4.55]],"ltp":2.26,"tv":71.24,"id":424676}]}]}
{"op":"mcm","clk":"11798614324","pt":1723154213032,"mc":[{"id":"1.231501231","rc":[{"batb":[[0,2.22,10],[1,2.2,31.59],[2,2.02,4.55]],"ltp":2.26,"tv":71.24,"id":424676}]}]}
{"op":"mcm","clk":"11798614425","pt":1723154216362,"mc":[{"id":"1.231501231","rc":[{"batb":[[0,2.24,4]],"ltp":2.26,"tv":71.24,"id":424676}]}]}
{"op":"mcm","clk":"11798614499","pt":1723154218563,"mc":[{"id":"1.231501231","rc":[{"batb":[[0,2.22,10]],"ltp":2.26,"tv":71.24,"id":424676}]}]}
{"op":"mcm","clk":"11798614611","pt":1723154221750,"mc":[{"id":"1.231501231","rc":[{"batb":[[0,2.24,4]],"ltp":2.26,"tv":71.24,"id":424676}]}]}
{"op":"mcm","clk":"11798614670","pt":1723154223550,"mc":[{"id":"1.231501231","rc":[{"batb":[[0,2.2,31.59],[1,2.02,4.55],[2,1.91,4.55]],"ltp":2.26,"tv":71.24,"id":424676}]}]}
{"op":"mcm","clk":"11798614741","pt":1723154226273,"mc":[{"id":"1.231501231","rc":[{"batb":[[0,2.22,14],[1,2.2,31.59],[2,2.02,4.55]],"ltp":2.26,"tv":71.24,"id":424676}]}]}
{"op":"mcm","clk":"11798614820","pt":1723154228440,"mc":[{"id":"1.231501231","rc":[{"batb":[[0,2.22,10]],"ltp":2.26,"tv":71.24,"id":424676}]}]}
{"op":"mcm","clk":"11798614861","pt":1723154229668,"mc":[{"id":"1.231501231","rc":[{"batb":[[0,2.2,31.59],[1,2.02,4.55],[2,1.91,4.55]],"ltp":2.26,"tv":71.24,"id":424676}]}]}
{"op":"mcm","clk":"11798614933","pt":1723154232182,"mc":[{"id":"1.231501231","rc":[{"batb":[[0,2.22,14],[1,2.2,31.59],[2,2.02,4.55]],"ltp":2.26,"tv":71.24,"id":424676}]}]}
{"op":"mcm","clk":"11798615014","pt":1723154234444,"mc":[{"id":"1.231501231","rc":[{"batb":[[0,2.22,10]],"ltp":2.26,"tv":71.24,"id":424676}]}]}
{"op":"mcm","clk":"11798615035","pt":1723154235419,"mc":[{"id":"1.231501231","rc":[{"batb":[[0,2.2,31.59],[1,2.02,4.55],[2,1.91,4.55]],"ltp":2.26,"tv":71.24,"id":424676}]}]}
{"op":"mcm","clk":"11798615087","pt":1723154236646,"mc":[{"id":"1.231501231","rc":[{"batb":[[0,2.22,4],[1,2.2,31.59],[2,2.02,4.55]],"ltp":2.26,"tv":71.24,"id":424676}]}]}
{"op":"mcm","clk":"11798615126","pt":1723154237874,"mc":[{"id":"1.231501231","rc":[{"batb":[[0,2.24,10],[1,2.22,4],[2,2.2,31.59]],"ltp":2.26,"tv":71.24,"id":424676}]}]}
{"op":"mcm","clk":"11798615169","pt":1723154239056,"mc":[{"id":"1.231501231","rc":[{"batb":[[1,2.2,31.59],[2,2.02,4.55]],"ltp":2.26,"tv":71.24,"id":424676}]}]}
{"op":"mcm","clk":"11798615240","pt":1723154241461,"mc":[{"id":"1.231501231","rc":[{"batb":[[0,2.26,4]],"ltp":2.26,"tv":71.24,"id":424676}]}]}
{"op":"mcm","clk":"11798615313","pt":1723154243662,"mc":[{"id":"1.231501231","rc":[{"batb":[[0,2.28,10]],"ltp":2.26,"tv":71.24,"id":424676}]}]}
{"op":"mcm","clk":"11798615404","pt":1723154246889,"mc":[{"id":"1.231501231","rc":[{"batb":[[0,2.3,4]],"ltp":2.26,"tv":71.24,"id":424676}]}]}
{"op":"mcm","clk":"11798615484","pt":1723154249299,"mc":[{"id":"1.231501231","rc":[{"batb":[[0,2.22,10]],"ltp":2.26,"tv":71.24,"id":424676}]}]}
{"op":"mcm","clk":"11798615552","pt":1723154251600,"mc":[{"id":"1.231501231","rc":[{"batb":[[0,2.24,4],[1,2.22,10],[2,2.2,31.59]],"ltp":2.26,"tv":71.24,"id":424676}]}]}
{"op":"mcm","clk":"11798615584","pt":1723154252574,"mc":[{"id":"1.231501231","rc":[{"batb":[[1,2.2,31.59],[2,2.02,4.55]],"ltp":2.26,"tv":71.24,"id":424676}]}]}
{"op":"mcm","clk":"11798615631","pt":1723154254008,"mc":[{"id":"1.231501231","rc":[{"batb":[[0,2.2,31.59],[1,2.02,4.55],[2,1.91,4.55]],"ltp":2.26,"tv":71.24,"id":424676}]}]}
{"op":"mcm","clk":"11798615687","pt":1723154255292,"mc":[{"id":"1.231501231","rc":[{"batb":[[0,2.22,10],[1,2.2,31.59],[2,2.02,4.55]],"ltp":2.26,"tv":71.24,"id":424676}]}]}
{"op":"mcm","clk":"11798615726","pt":1723154256470,"mc":[{"id":"1.231501231","rc":[{"batb":[[0,2.24,4],[1,2.22,10],[2,2.2,31.59]],"ltp":2.26,"tv":71.24,"id":424676}]}]}
{"op":"mcm","clk":"11798615805","pt":1723154258782,"mc":[{"id":"1.231501231","rc":[{"batb":[[0,2.2,31.59],[1,2.02,4.55],[2,1.91,4.55]],"ltp":2.26,"tv":71.24,"id":424676}]}]}
{"op":"mcm","clk":"11798615876","pt":1723154261193,"mc":[{"id":"1.231501231","rc":[{"batb":[[0,2.22,14],[1,2.2,31.59],[2,2.02,4.55]],"ltp":2.26,"tv":71.24,"id":424676}]}]}
{"op":"mcm","clk":"11798615959","pt":1723154263599,"mc":[{"id":"1.231501231","rc":[{"batb":[[0,2.22,10]],"ltp":2.26,"tv":71.24,"id":424676}]}]}
{"op":"mcm","clk":"11798615991","pt":1723154264519,"mc":[{"id":"1.231501231","rc":[{"batb":[[0,2.2,31.59],[1,2.02,4.55],[2,1.91,4.55]],"ltp":2.26,"tv":71.24,"id":424676}]}]}
{"op":"mcm","clk":"11798616072","pt":1723154266929,"mc":[{"id":"1.231501231","rc":[{"batb":[[0,2.22,14],[1,2.2,31.59],[2,2.02,4.55]],"ltp":2.26,"tv":71.24,"id":424676}]}]}
{"op":"mcm","clk":"11798616143","pt":1723154269079,"mc":[{"id":"1.231501231","rc":[{"batb":[[0,2.22,10]],"ltp":2.26,"tv":71.24,"id":424676}]}]}
{"op":"mcm","clk":"11798616184","pt":1723154270206,"mc":[{"id":"1.231501231","rc":[{"batb":[[0,2.2,31.59],[1,2.02,4.55],[2,1.91,4.55]],"ltp":2.26,"tv":71.24,"id":424676}]}]}
{"op":"mcm","clk":"11798616227","pt":1723154271696,"mc":[{"id":"1.231501231","rc":[{"batb":[[0,2.22,4],[1,2.2,31.59],[2,2.02,4.55]],"ltp":2.26,"tv":71.24,"id":424676}]}]}
{"op":"mcm","clk":"11798616298","pt":1723154273897,"mc":[{"id":"1.231501231","rc":[{"batb":[[0,2.24,10]],"ltp":2.26,"tv":71.24,"id":424676}]}]}
{"op":"mcm","clk":"11798616401","pt":1723154277230,"mc":[{"id":"1.231501231","rc":[{"batb":[[0,2.22,4]],"ltp":2.26,"tv":71.24,"id":424676}]}]}
{"op":"mcm","clk":"11798616482","pt":1723154279638,"mc":[{"id":"1.231501231","rc":[{"batb":[[0,2.22,10]],"ltp":2.26,"tv":71.24,"id":424676}]}]}
{"op":"mcm","clk":"11798616605","pt":1723154282817,"mc":[{"id":"1.231501231","rc":[{"batb":[[0,2.24,4]],"ltp":2.26,"tv":71.24,"id":424676}]}]}
{"op":"mcm","clk":"11798616666","pt":1723154284408,"mc":[{"id":"1.231501231","rc":[{"batb":[[0,2.2,31.59],[1,2.02,4.55],[2,1.91,4.55]],"ltp":2.26,"tv":71.24,"id":424676}]}]}
{"op":"mcm","clk":"11798616705","pt":1723154285533,"mc":[{"id":"1.231501231","rc":[{"batb":[[0,2.22,10],[1,2.2,31.59],[2,2.02,4.55]],"ltp":2.26,"tv":71.24,"id":424676}]}]}
{"op":"mcm","clk":"11798616785","pt":1723154287941,"mc":[{"id":"1.231501231","rc":[{"batb":[[0,2.24,4],[1,2.22,10],[2,2.2,31.59]],"ltp":2.26,"tv":71.24,"id":424676}]}]}
{"op":"mcm","clk":"11798616814","pt":1723154288917,"mc":[{"id":"1.231501231","rc":[{"batb":[[1,2.2,31.59],[2,2.02,4.55]],"ltp":2.26,"tv":71.24,"id":424676}]}]}
{"op":"mcm","clk":"11798616849","pt":1723154290250,"mc":[{"id":"1.231501231","rc":[{"batb":[[0,2.2,31.59],[1,2.02,4.55],[2,1.91,4.55]],"ltp":2.26,"tv":71.24,"id":424676}]}]}
{"op":"mcm","clk":"11798616991","pt":1723154294352,"mc":[{"id":"1.231501231","rc":[{"batb":[[0,2.22,14],[1,2.2,31.59],[2,2.02,4.55]],"ltp":2.26,"tv":71.24,"id":424676}]}]}
{"op":"mcm","clk":"11798617092","pt":1723154296762,"mc":[{"id":"1.231501231","rc":[{"batb":[[0,2.22,10]],"ltp":2.26,"tv":71.24,"id":424676}]}]}
{"op":"mcm","clk":"11798617132","pt":1723154297944,"mc":[{"id":"1.231501231","rc":[{"batb":[[0,2.2,31.59],[1,2.02,4.55],[2,1.91,4.55]],"ltp":2.26,"tv":71.24,"id":424676}]}]}
{"op":"mcm","clk":"11798617179","pt":1723154299330,"mc":[{"id":"1.231501231","rc":[{"batb":[[0,2.22,4],[1,2.2,31.59],[2,2.02,4.55]],"ltp":2.26,"tv":71.24,"id":424676}]}]}
{"op":"mcm","clk":"11798617223","pt":1723154300563,"mc":[{"id":"1.231501231","rc":[{"batb":[[0,2.24,10],[1,2.22,4],[2,2.2,31.59]],"ltp":2.26,"tv":71.24,"id":424676}]}]}
{"op":"mcm","clk":"11798617258","pt":1723154301742,"mc":[{"id":"1.231501231","rc":[{"batb":[[1,2.2,31.59],[2,2.02,4.55]],"ltp":2.26,"tv":71.24,"id":424676}]}]}
{"op":"mcm","clk":"11798617336","pt":1723154303947,"mc":[{"id":"1.231501231","rc":[{"batb":[[0,2.2,31.59],[1,2.02,4.55],[2,1.91,4.55]],"ltp":2.26,"tv":71.24,"id":424676}]}]}
{"op":"mcm","clk":"11798617340","pt":1723154304050,"mc":[{"id":"1.231501231","rc":[{"batb":[[0,2.22,4],[1,2.2,31.59],[2,2.02,4.55]],"ltp":2.26,"tv":71.24,"id":424676}]}]}
{"op":"mcm","clk":"11798617406","pt":1723154306456,"mc":[{"id":"1.231501231","rc":[{"batb":[[0,2.24,10]],"ltp":2.26,"tv":71.24,"id":424676}]}]}
{"op":"mcm","clk":"11798617470","pt":1723154308659,"mc":[{"id":"1.231501231","rc":[{"batb":[[0,2.26,4],[1,2.24,10],[2,2.2,31.59]],"ltp":2.26,"tv":71.24,"id":424676}]}]}
{"op":"mcm","clk":"11798617493","pt":1723154309734,"mc":[{"id":"1.231501231","rc":[{"batb":[[1,2.2,31.59],[2,2.02,4.55]],"ltp":2.26,"tv":71.24,"id":424676}]}]}
{"op":"mcm","clk":"11798617544","pt":1723154310970,"mc":[{"id":"1.231501231","rc":[{"batb":[[0,2.2,31.59],[1,2.02,4.55],[2,1.91,4.55]],"ltp":2.26,"tv":71.24,"id":424676}]}]}
{"op":"mcm","clk":"11798617594","pt":1723154312154,"mc":[{"id":"1.231501231","rc":[{"batb":[[0,2.22,10],[1,2.2,31.59],[2,2.02,4.55]],"ltp":2.26,"tv":71.24,"id":424676}]}]}
{"op":"mcm","clk":"11798617647","pt":1723154313847,"mc":[{"id":"1.231501231","rc":[{"batb":[[0,2.24,4],[1,2.22,10],[2,2.2,31.59]],"ltp":2.26,"tv":71.24,"id":424676}]}]}
{"op":"mcm","clk":"11798617709","pt":1723154315441,"mc":[{"id":"1.231501231","rc":[{"batb":[[1,2.2,31.59],[2,2.02,4.55]],"ltp":2.26,"tv":71.24,"id":424676}]}]}
{"op":"mcm","clk":"11798617731","pt":1723154316059,"mc":[{"id":"1.231501231","rc":[{"batb":[[0,2.2,31.59],[1,2.02,4.55],[2,1.91,4.55]],"ltp":2.26,"tv":71.24,"id":424676}]}]}
{"op":"mcm","clk":"11798617811","pt":1723154319039,"mc":[{"id":"1.231501231","rc":[{"batb":[[0,2.22,14],[1,2.2,31.59],[2,2.02,4.55]],"ltp":2.26,"tv":71.24,"id":424676}]}]}
{"op":"mcm","clk":"11798617885","pt":1723154321250,"mc":[{"id":"1.231501231","rc":[{"batb":[[0,2.22,10]],"ltp":2.26,"tv":71.24,"id":424676}]}]}
{"op":"mcm","clk":"11798617931","pt":1723154322480,"mc":[{"id":"1.231501231","rc":[{"batb":[[0,2.2,31.59],[1,2.02,4.55],[2,1.91,4.55]],"ltp":2.26,"tv":71.24,"id":424676}]}]}
{"op":"mcm","clk":"11798618049","pt":1723154325763,"mc":[{"id":"1.231501231","rc":[{"batb":[[0,2.22,14],[1,2.2,31.59],[2,2.02,4.55]],"ltp":2.26,"tv":71.24,"id":424676}]}]}
{"op":"mcm","clk":"11798618119","pt":1723154327963,"mc":[{"id":"1.231501231","rc":[{"batb":[[0,2.22,10]],"ltp":2.26,"tv":71.24,"id":424676}]}]}
{"op":"mcm","clk":"11798618153","pt":1723154329189,"mc":[{"id":"1.231501231","rc":[{"batb":[[0,2.2,31.59],[1,2.02,4.55],[2,1.91,4.55]],"ltp":2.26,"tv":71.24,"id":424676}]}]}
{"op":"mcm","clk":"11798618192","pt":1723154330675,"mc":[{"id":"1.231501231","rc":[{"batb":[[0,2.22,4],[1,2.2,31.59],[2,2.02,4.55]],"ltp":2.26,"tv":71.24,"id":424676}]}]}
{"op":"mcm","clk":"11798618254","pt":1723154332978,"mc":[{"id":"1.231501231","rc":[{"batb":[[0,2.2,31.59],[1,2.02,4.55],[2,1.91,4.55]],"ltp":2.26,"tv":71.24,"id":424676}]}]}
{"op":"mcm","clk":"11798618260","pt":1723154333078,"mc":[{"id":"1.231501231","rc":[{"batb":[[0,2.22,10],[1,2.2,31.59],[2,2.02,4.55]],"ltp":2.26,"tv":71.24,"id":424676}]}]}
{"op":"mcm","clk":"11798618331","pt":1723154335484,"mc":[{"id":"1.231501231","rc":[{"batb":[[0,2.24,4],[1,2.22,10],[2,2.2,31.59]],"ltp":2.26,"tv":71.24,"id":424676}]}]}
{"op":"mcm","clk":"11798618357","pt":1723154336460,"mc":[{"id":"1.231501231","rc":[{"batb":[[1,2.2,31.59],[2,2.02,4.55]],"ltp":2.26,"tv":71.24,"id":424676}]}]}
{"op":"mcm","clk":"11798618398","pt":1723154337791,"mc":[{"id":"1.231501231","rc":[{"batb":[[0,2.2,31.59],[1,2.02,4.55],[2,1.91,4.55]],"ltp":2.26,"tv":71.24,"id":424676}]}]}
{"op":"mcm","clk":"11798618420","pt":1723154338970,"mc":[{"id":"1.231501231","rc":[{"batb":[[0,2.22,10],[1,2.2,31.59],[2,2.02,4.55]],"ltp":2.26,"tv":71.24,"id":424676}]}]}
{"op":"mcm","clk":"11798618458","pt":1723154340197,"mc":[{"id":"1.231501231","rc":[{"batb":[[0,2.24,4],[1,2.22,10],[2,2.2,31.59]],"ltp":2.26,"tv":71.24,"id":424676}]}]}
{"op":"mcm","clk":"11798618530","pt":1723154342558,"mc":[{"id":"1.231501231","rc":[{"batb":[[0,2.2,31.59],[1,2.02,4.55],[2,1.91,4.55]],"ltp":2.26,"tv":71.24,"id":424676}]}]}
{"op":"mcm","clk":"11798618652","pt":1723154345993,"mc":[{"id":"1.231501231","rc":[{"batb":[[0,2.22,10],[1,2.2,31.59],[2,2.02,4.55]],"ltp":2.26,"tv":71.24,"id":424676}]}]}
{"op":"mcm","clk":"11798618657","pt":1723154346096,"mc":[{"id":"1.231501231","rc":[{"batb":[[0,2.22,14]],"ltp":2.26,"tv":71.24,"id":424676}]}]}
{"op":"mcm","clk":"11798618701","pt":1723154348403,"mc":[{"id":"1.231501231","rc":[{"batb":[[0,2.22,10]],"ltp":2.26,"tv":71.24,"id":424676}]}]}
{"op":"mcm","clk":"11798618736","pt":1723154349380,"mc":[{"id":"1.231501231","rc":[{"batb":[[0,2.2,31.59],[1,2.02,4.55],[2,1.91,4.55]],"ltp":2.26,"tv":71.24,"id":424676}]}]}
{"op":"mcm","clk":"11798618768","pt":1723154350608,"mc":[{"id":"1.231501231","rc":[{"batb":[[0,2.22,4],[1,2.2,31.59],[2,2.02,4.55]],"ltp":2.26,"tv":71.24,"id":424676}]}]}
{"op":"mcm","clk":"11798618808","pt":1723154351888,"mc":[{"id":"1.231501231","rc":[{"batb":[[0,2.24,10],[1,2.22,4],[2,2.2,31.59]],"ltp":2.26,"tv":71.24,"id":424676}]}]}
{"op":"mcm","clk":"11798618844","pt":1723154352918,"mc":[{"id":"1.231501231","rc":[{"batb":[[1,2.2,31.59],[2,2.02,4.55]],"ltp":2.26,"tv":71.24,"id":424676}]}]}
{"op":"mcm","clk":"11798618921","pt":1723154355480,"mc":[{"id":"1.231501231","rc":[{"batb":[[0,2.22,4]],"ltp":2.26,"tv":71.24,"id":424676}]}]}
{"op":"mcm","clk":"11798618990","pt":1723154357789,"mc":[{"id":"1.231501231","rc":[{"batb":[[0,2.22,10]],"ltp":2.26,"tv":71.24,"id":424676}]}]}
{"op":"mcm","clk":"11798619080","pt":1723154360202,"mc":[{"id":"1.231501231","rc":[{"batb":[[0,2.24,4],[1,2.22,10],[2,2.2,31.59]],"ltp":2.26,"tv":71.24,"id":424676}]}]}
{"op":"mcm","clk":"11798619108","pt":1723154361123,"mc":[{"id":"1.231501231","rc":[{"batb":[[1,2.2,31.59],[2,2.02,4.55]],"ltp":2.26,"tv":71.24,"id":424676}]}]}
{"op":"mcm","clk":"11798619165","pt":1723154362508,"mc":[{"id":"1.231501231","rc":[{"batb":[[0,2.26,14.01]],"ltp":2.26,"tv":71.24,"id":424676}]}]}
{"op":"mcm","clk":"11798619195","pt":1723154363689,"mc":[{"id":"1.231501231","rc":[{"batb":[[0,2.28,10],[1,2.26,14.01],[2,2.2,31.59]],"ltp":2.26,"tv":71.24,"id":424676}]}]}
{"op":"mcm","clk":"11798619215","pt":1723154364305,"mc":[{"id":"1.231501231","rc":[{"batb":[[1,2.2,31.59],[2,2.02,4.55]],"ltp":2.26,"tv":71.24,"id":424676}]}]}
{"op":"mcm","clk":"11798619298","pt":1723154367119,"mc":[{"id":"1.231501231","rc":[{"batb":[[0,2.22,4]],"ltp":2.26,"tv":71.24,"id":424676}]}]}
{"op":"mcm","clk":"11798619365","pt":1723154369524,"mc":[{"id":"1.231501231","rc":[{"batb":[[0,2.24,10]],"ltp":2.26,"tv":71.24,"id":424676}]}]}
{"op":"mcm","clk":"11798619434","pt":1723154371917,"mc":[{"id":"1.231501231","rc":[{"batb":[[0,2.26,4],[1,2.24,10],[2,2.2,31.59]],"ltp":2.26,"tv":71.24,"id":424676}]}]}
{"op":"mcm","clk":"11798619469","pt":1723154372838,"mc":[{"id":"1.231501231","rc":[{"batb":[[1,2.2,31.59],[2,2.02,4.55]],"ltp":2.26,"tv":71.24,"id":424676}]}]}
{"op":"mcm","clk":"11798619518","pt":1723154374325,"mc":[{"id":"1.231501231","rc":[{"batb":[[0,2.2,31.59],[1,2.02,4.55],[2,1.91,4.55]],"ltp":2.26,"tv":71.24,"id":424676}]}]}
{"op":"mcm","clk":"11798619549","pt":1723154375404,"mc":[{"id":"1.231501231","rc":[{"batb":[[0,2.22,10],[1,2.2,31.59],[2,2.02,4.55]],"ltp":2.26,"tv":71.24,"id":424676}]}]}
{"op":"mcm","clk":"11798619632","pt":1723154378932,"mc":[{"id":"1.231501231","rc":[{"batb":[[0,2.2,31.59],[1,2.02,4.55],[2,1.91,4.55]],"ltp":2.26,"tv":71.24,"id":424676}]}]}
{"op":"mcm","clk":"11798620251","pt":1723154400274,"mc":[{"id":"1.231501231","rc":[{"batb":[[0,2.22,14],[1,2.2,31.59],[2,2.02,4.55]],"ltp":2.26,"tv":71.24,"id":424676}]}]}
{"op":"mcm","clk":"11798620336","pt":1723154402637,"mc":[{"id":"1.231501231","rc":[{"batb":[[0,2.22,10]],"ltp":2.26,"tv":71.24,"id":424676}]}]}
{"op":"mcm","clk":"11798620385","pt":1723154403667,"mc":[{"id":"1.231501231","rc":[{"batb":[[0,2.2,31.59],[1,2.02,4.55],[2,1.91,4.55]],"ltp":2.26,"tv":71.24,"id":424676}]}]}
{"op":"mcm","clk":"11798620450","pt":1723154405050,"mc":[{"id":"1.231501231","rc":[{"batb":[[0,2.22,4],[1,2.2,31.59],[2,2.02,4.55]],"ltp":2.26,"tv":71.24,"id":424676}]}]}
{"op":"mcm","clk":"11798620510","pt":1723154406389,"mc":[{"id":"1.231501231","rc":[{"batb":[[0,2.24,10],[1,2.22,4],[2,2.2,31.59]],"ltp":2.26,"tv":71.24,"id":424676}]}]}
{"op":"mcm","clk":"11798620541","pt":1723154407357,"mc":[{"id":"1.231501231","rc":[{"batb":[[1,2.2,31.59],[2,2.02,4.55]],"ltp":2.26,"tv":71.24,"id":424676}]}]}
{"op":"mcm","clk":"11798620637","pt":1723154409877,"mc":[{"id":"1.231501231","rc":[{"batb":[[0,2.22,4]],"ltp":2.26,"tv":71.24,"id":424676}]}]}
{"op":"mcm","clk":"11798620726","pt":1723154412250,"mc":[{"id":"1.231501231","rc":[{"batb":[[0,2.24,10]],"ltp":2.26,"tv":71.24,"id":424676}]}]}
{"op":"mcm","clk":"11798620752","pt":1723154413280,"mc":[{"id":"1.231501231","rc":[{"batb":[[0,2.26,14.15],[1,2.24,10],[2,2.2,31.59]],"ltp":2.26,"tv":71.24,"id":424676},{"batl":[[0,1.79,17.55],[1,1.8,450],[2,1.82,2]],"ltp":1.8,"tv":116.97,"id":31376}]}]}
{"op":"mcm","clk":"11798620778","pt":1723154414351,"mc":[{"id":"1.231501231","rc":[{"batb":[[0,2.28,4],[1,2.26,14.15],[2,2.24,10]],"ltp":2.26,"tv":71.24,"id":424676}]}]}
{"op":"mcm","clk":"11798620814","pt":1723154415484,"mc":[{"id":"1.231501231","rc":[{"batb":[[2,2.2,31.59]],"ltp":2.26,"tv":71.24,"id":424676}]}]}
{"op":"mcm","clk":"11798620861","pt":1723154416669,"mc":[{"id":"1.231501231","rc":[{"batb":[[0,2.26,14.15],[1,2.2,31.59],[2,2.02,4.55]],"ltp":2.26,"tv":71.24,"id":424676}]}]}
{"op":"mcm","clk":"11798620908","pt":1723154417901,"mc":[{"id":"1.231501231","rc":[{"batb":[[0,2.28,10],[1,2.26,14.15],[2,2.2,31.59]],"ltp":2.26,"tv":71.24,"id":424676}]}]}
{"op":"mcm","clk":"11798620967","pt":1723154419390,"mc":[{"id":"1.231501231","rc":[{"batb":[[0,2.3,4],[1,2.28,10],[2,2.26,14.15]],"ltp":2.26,"tv":71.24,"id":424676}]}]}
{"op":"mcm","clk":"11798621045","pt":1723154421601,"mc":[{"id":"1.231501231","rc":[{"batb":[[0,2.26,14.15],[1,2.2,31.59],[2,2.02,4.55]],"ltp":2.26,"tv":71.24,"id":424676}]}]}
{"op":"mcm","clk":"11798621139","pt":1723154423873,"mc":[{"id":"1.231501231","rc":[{"batb":[[0,2.28,14],[1,2.26,14.15],[2,2.2,31.59]],"ltp":2.26,"tv":71.24,"id":424676}]}]}
{"op":"mcm","clk":"11798621231","pt":1723154426394,"mc":[{"id":"1.231501231","rc":[{"batb":[[0,2.28,10]],"ltp":2.26,"tv":71.24,"id":424676}]}]}
{"op":"mcm","clk":"11798621275","pt":1723154427374,"mc":[{"id":"1.231501231","rc":[{"batb":[[0,2.26,14.15],[1,2.2,31.59],[2,2.02,4.55]],"ltp":2.26,"tv":71.24,"id":424676}]}]}
{"op":"mcm","clk":"11798621318","pt":1723154428498,"mc":[{"id":"1.231501231","rc":[{"batb":[[0,2.28,4],[1,2.26,14.15],[2,2.2,31.59]],"ltp":2.26,"tv":71.24,"id":424676}]}]}
{"op":"mcm","clk":"11798621389","pt":1723154429988,"mc":[{"id":"1.231501231","rc":[{"batb":[[0,2.3,10],[1,2.28,4],[2,2.26,14.15]],"ltp":2.26,"tv":71.24,"id":424676}]}]}
{"op":"mcm","clk":"11798621416","pt":1723154430805,"mc":[{"id":"1.231501231","rc":[{"batb":[[1,2.26,14.15],[2,2.2,31.59]],"ltp":2.26,"tv":71.24,"id":424676}]}]}
{"op":"mcm","clk":"11798621468","pt":1723154431992,"mc":[{"id":"1.231501231","rc":[{"batl":[[0,1.8,450],[1,1.82,2],[2,1.86,21.9]],"ltp":1.8,"tv":116.97,"id":31376}]}]}
{"op":"mcm","clk":"11798621534","pt":1723154433321,"mc":[{"id":"1.231501231","rc":[{"batb":[[0,2.32,4]],"ltp":2.26,"tv":71.24,"id":424676}]}]}
{"op":"mcm","clk":"11798621633","pt":1723154435595,"mc":[{"id":"1.231501231","rc":[{"batb":[[0,2.28,10]],"ltp":2.26,"tv":71.24,"id":424676}]}]}
{"op":"mcm","clk":"11798621685","pt":1723154436929,"mc":[{"id":"1.231501231","rc":[{"batb":[[1,2.2,31.59],[2,2.02,4.55]],"ltp":2.26,"tv":71.24,"id":424676}]}]}
{"op":"mcm","clk":"11798621756","pt":1723154438909,"mc":[{"id":"1.231501231","rc":[{"batb":[[0,2.3,4]],"ltp":2.26,"tv":71.24,"id":424676}]}]}
{"op":"mcm","clk":"11798621808","pt":1723154440548,"mc":[{"id":"1.231501231","rc":[{"batb":[[0,2.2,31.59],[1,2.02,4.55],[2,1.91,4.55]],"ltp":2.26,"tv":71.24,"id":424676}]}]}
{"op":"mcm","clk":"11798621903","pt":1723154442813,"mc":[{"id":"1.231501231","rc":[{"batb":[[0,2.22,14],[1,2.2,31.59],[2,2.02,4.55]],"ltp":2.26,"tv":71.24,"id":424676}]}]}
{"op":"mcm","clk":"11798622002","pt":1723154445121,"mc":[{"id":"1.231501231","rc":[{"batb":[[0,2.22,10]],"ltp":2.26,"tv":71.24,"id":424676}]}]}
{"op":"mcm","clk":"11798622044","pt":1723154446147,"mc":[{"id":"1.231501231","rc":[{"batb":[[0,2.2,31.59],[1,2.02,4.55],[2,1.91,4.55]],"ltp":2.26,"tv":71.24,"id":424676}]}]}
{"op":"mcm","clk":"11798622153","pt":1723154448716,"mc":[{"id":"1.231501231","rc":[{"batb":[[0,2.22,14],[1,2.2,31.59],[2,2.02,4.55]],"ltp":2.26,"tv":71.24,"id":424676}]}]}
{"op":"mcm","clk":"11798622231","pt":1723154451124,"mc":[{"id":"1.231501231","rc":[{"batb":[[0,2.22,10]],"ltp":2.26,"tv":71.24,"id":424676}]}]}
{"op":"mcm","clk":"11798622262","pt":1723154452148,"mc":[{"id":"1.231501231","rc":[{"batb":[[0,2.2,31.59],[1,2.02,4.55],[2,1.91,4.55]],"ltp":2.26,"tv":71.24,"id":424676}]}]}
{"op":"mcm","clk":"11798622308","pt":1723154453228,"mc":[{"id":"1.231501231","rc":[{"batb":[[0,2.22,4],[1,2.2,31.59],[2,2.02,4.55]],"ltp":2.26,"tv":71.24,"id":424676}]}]}
{"op":"mcm","clk":"11798622370","pt":1723154454616,"mc":[{"id":"1.231501231","rc":[{"batb":[[0,2.24,10],[1,2.22,4],[2,2.2,31.59]],"ltp":2.26,"tv":71.24,"id":424676}]}]}
{"op":"mcm","clk":"11798622401","pt":1723154455646,"mc":[{"id":"1.231501231","rc":[{"batb":[[1,2.2,31.59],[2,2.02,4.55]],"ltp":2.26,"tv":71.24,"id":424676}]}]}
{"op":"mcm","clk":"11798622515","pt":1723154457952,"mc":[{"id":"1.231501231","rc":[{"batb":[[0,2.26,4]],"ltp":2.26,"tv":71.24,"id":424676}]}]}
{"op":"mcm","clk":"11798622606","pt":1723154460365,"mc":[{"id":"1.231501231","rc":[{"batb":[[0,2.28,10]],"ltp":2.26,"tv":71.24,"id":424676}]}]}
{"op":"mcm","clk":"11798622707","pt":1723154462936,"mc":[{"id":"1.231501231","rc":[{"batb":[[0,2.3,4],[1,2.28,10],[2,2.2,31.59]],"ltp":2.26,"tv":71.24,"id":424676}]}]}
{"op":"mcm","clk":"11798622736","pt":1723154463653,"mc":[{"id":"1.231501231","rc":[{"batb":[[1,2.2,31.59],[2,2.02,4.55]],"ltp":2.26,"tv":71.24,"id":424676}]}]}
{"op":"mcm","clk":"11798622789","pt":1723154465346,"mc":[{"id":"1.231501231","rc":[{"batb":[[0,2.2,31.59],[1,2.02,4.55],[2,1.91,4.55]],"ltp":2.26,"tv":71.24,"id":424676}]}]}
{"op":"mcm","clk":"11798622875","pt":1723154467656,"mc":[{"id":"1.231501231","rc":[{"batb":[[0,2.22,14],[1,2.2,31.59],[2,2.02,4.55]],"ltp":2.26,"tv":71.24,"id":424676}]}]}
{"op":"mcm","clk":"11798622978","pt":1723154470077,"mc":[{"id":"1.231501231","rc":[{"batb":[[0,2.22,10]],"ltp":2.26,"tv":71.24,"id":424676}]}]}
{"op":"mcm","clk":"11798623021","pt":1723154471055,"mc":[{"id":"1.231501231","rc":[{"batb":[[0,2.2,31.59],[1,2.02,4.55],[2,1.91,4.55]],"ltp":2.26,"tv":71.24,"id":424676}]}]}
{"op":"mcm","clk":"11798623104","pt":1723154473262,"mc":[{"id":"1.231501231","rc":[{"batb":[[0,2.22,14],[1,2.2,31.59],[2,2.02,4.55]],"ltp":2.26,"tv":71.24,"id":424676}]}]}
{"op":"mcm","clk":"11798623197","pt":1723154475744,"mc":[{"id":"1.231501231","rc":[{"batb":[[0,2.22,10]],"ltp":2.26,"tv":71.24,"id":424676}]}]}
{"op":"mcm","clk":"11798623227","pt":1723154476663,"mc":[{"id":"1.231501231","rc":[{"batb":[[0,2.2,31.59],[1,2.02,4.55],[2,1.91,4.55]],"ltp":2.26,"tv":71.24,"id":424676}]}]}
{"op":"mcm","clk":"11798623274","pt":1723154478050,"mc":[{"id":"1.231501231","rc":[{"batb":[[0,2.22,4],[1,2.2,31.59],[2,2.02,4.55]],"ltp":2.26,"tv":71.24,"id":424676}]}]}
{"op":"mcm","clk":"11798623313","pt":1723154479286,"mc":[{"id":"1.231501231","rc":[{"batb":[[0,2.24,10],[1,2.22,4],[2,2.2,31.59]],"ltp":2.26,"tv":71.24,"id":424676}]}]}
{"op":"mcm","clk":"11798623355","pt":1723154480465,"mc":[{"id":"1.231501231","rc":[{"batb":[[1,2.2,31.59],[2,2.02,4.55]],"ltp":2.26,"tv":71.24,"id":424676}]}]}
{"op":"mcm","clk":"11798623435","pt":1723154482774,"mc":[{"id":"1.231501231","rc":[{"batb":[[0,2.22,4]],"ltp":2.26,"tv":71.24,"id":424676}]}]}
{"op":"mcm","clk":"11798623544","pt":1723154485064,"mc":[{"id":"1.231501231","rc":[{"batb":[[0,2.24,10]],"ltp":2.26,"tv":71.24,"id":424676}]}]}
{"op":"mcm","clk":"11798623653","pt":1723154487374,"mc":[{"id":"1.231501231","rc":[{"batb":[[0,2.26,4],[1,2.24,10],[2,2.2,31.59]],"ltp":2.26,"tv":71.24,"id":424676}]}]}
{"op":"mcm","clk":"11798623710","pt":1723154488503,"mc":[{"id":"1.231501231","rc":[{"batb":[[1,2.2,31.59],[2,2.02,4.55]],"ltp":2.26,"tv":71.24,"id":424676}]}]}
{"op":"mcm","clk":"11798623775","pt":1723154489687,"mc":[{"id":"1.231501231","rc":[{"batb":[[0,2.2,31.59],[1,2.02,4.55],[2,1.91,4.55]],"ltp":2.26,"tv":71.24,"id":424676}]}]}
{"op":"mcm","clk":"11798623832","pt":1723154490772,"mc":[{"id":"1.231501231","rc":[{"batb":[[0,2.22,10],[1,2.2,31.59],[2,2.02,4.55]],"ltp":2.26,"tv":71.24,"id":424676}]}]}
{"op":"mcm","clk":"11798623889","pt":1723154492101,"mc":[{"id":"1.231501231","rc":[{"batb":[[0,2.24,4],[1,2.22,10],[2,2.2,31.59]],"ltp":2.26,"tv":71.24,"id":424676}]}]}
{"op":"mcm","clk":"11798623971","pt":1723154494365,"mc":[{"id":"1.231501231","rc":[{"batb":[[0,2.2,31.59],[1,2.02,4.55],[2,1.91,4.55]],"ltp":2.26,"tv":71.24,"id":424676}]}]}
{"op":"mcm","clk":"11798624057","pt":1723154496799,"mc":[{"id":"1.231501231","rc":[{"batb":[[0,2.22,14],[1,2.2,31.59],[2,2.02,4.55]],"ltp":2.26,"tv":71.24,"id":424676}]}]}
{"op":"mcm","clk":"11798624139","pt":1723154499213,"mc":[{"id":"1.231501231","rc":[{"batb":[[0,2.22,10]],"ltp":2.26,"tv":71.24,"id":424676}]}]}
{"op":"mcm","clk":"11798624184","pt":1723154500188,"mc":[{"id":"1.231501231","rc":[{"batb":[[0,2.2,31.59],[1,2.02,4.55],[2,1.91,4.55]],"ltp":2.26,"tv":71.24,"id":424676}]}]}
{"op":"mcm","clk":"11798624266","pt":1723154502499,"mc":[{"id":"1.231501231","rc":[{"batb":[[0,2.22,14],[1,2.2,31.59],[2,2.02,4.55]],"ltp":2.26,"tv":71.24,"id":424676}]}]}
{"op":"mcm","clk":"11798624375","pt":1723154505991,"mc":[{"id":"1.231501231","rc":[{"batb":[[0,2.2,31.59],[1,2.02,4.55],[2,1.91,4.55]],"ltp":2.26,"tv":71.24,"id":424676}]}]}
{"op":"mcm","clk":"11798624398","pt":1723154507116,"mc":[{"id":"1.231501231","rc":[{"batb":[[0,2.22,4],[1,2.2,31.59],[2,2.02,4.55]],"ltp":2.26,"tv":71.24,"id":424676}]}]}
{"op":"mcm","clk":"11798624469","pt":1723154509526,"mc":[{"id":"1.231501231","rc":[{"batb":[[0,2.22,10]],"ltp":2.26,"tv":71.24,"id":424676}]}]}
{"op":"mcm","clk":"11798624533","pt":1723154511627,"mc":[{"id":"1.231501231","rc":[{"batb":[[0,2.24,4],[1,2.22,10],[2,2.2,31.59]],"ltp":2.26,"tv":71.24,"id":424676}]}]}
{"op":"mcm","clk":"11798624565","pt":1723154513014,"mc":[{"id":"1.231501231","rc":[{"batb":[[1,2.2,31.59],[2,2.02,4.55]],"ltp":2.26,"tv":71.24,"id":424676}]}]}
{"op":"mcm","clk":"11798624598","pt":1723154514016,"mc":[{"id":"1.231501231","rc":[{"batb":[[0,2.2,31.59],[1,2.02,4.55],[2,1.91,4.55]],"ltp":2.26,"tv":71.24,"id":424676}]}]}
{"op":"mcm","clk":"11798624659","pt":1723154516199,"mc":[{"id":"1.231501231","rc":[{"batb":[[0,2.22,14],[1,2.2,31.59],[2,2.02,4.55]],"ltp":2.26,"tv":71.24,"id":424676}]}]}
{"op":"mcm","clk":"11798624719","pt":1723154518506,"mc":[{"id":"1.231501231","rc":[{"batb":[[0,2.22,10]],"ltp":2.26,"tv":71.24,"id":424676}]}]}
{"op":"mcm","clk":"11798624734","pt":1723154519498,"mc":[{"id":"1.231501231","rc":[{"batb":[[0,2.2,31.59],[1,2.02,4.55],[2,1.91,4.55]],"ltp":2.26,"tv":71.24,"id":424676}]}]}
{"op":"mcm","clk":"11798624914","pt":1723154525607,"mc":[{"id":"1.231501231","rc":[{"batb":[[0,2.22,14],[1,2.2,31.59],[2,2.02,4.55]],"ltp":2.26,"tv":71.24,"id":424676}]}]}
{"op":"mcm","clk":"11798624968","pt":1723154526943,"mc":[{"id":"1.231501231","rc":[{"batb":[[0,2.26,13.81],[1,2.22,14],[2,2.2,31.59]],"ltp":2.26,"tv":71.24,"id":424676},{"batl":[[0,1.79,17.13],[1,1.8,450],[2,1.82,2]],"ltp":1.8,"tv":116.97,"id":31376}]}]}
{"op":"mcm","clk":"11798625012","pt":1723154528226,"mc":[{"id":"1.231501231","rc":[{"batb":[[1,2.22,10]],"ltp":2.26,"tv":71.24,"id":424676}]}]}
{"op":"mcm","clk":"11798625044","pt":1723154529049,"mc":[{"id":"1.231501231","rc":[{"batb":[[1,2.2,31.59],[2,2.02,4.55]],"ltp":2.26,"tv":71.24,"id":424676}]}]}
{"op":"mcm","clk":"11798625117","pt":1723154531615,"mc":[{"id":"1.231501231","rc":[{"batb":[[0,2.28,14],[1,2.26,13.81],[2,2.2,31.59]],"ltp":2.26,"tv":71.24,"id":424676}]}]}
{"op":"mcm","clk":"11798625209","pt":1723154534131,"mc":[{"id":"1.231501231","rc":[{"batb":[[0,2.28,10]],"ltp":2.26,"tv":71.24,"id":424676}]}]}
{"op":"mcm","clk":"11798625242","pt":1723154535110,"mc":[{"id":"1.231501231","rc":[{"batb":[[0,2.26,13.81],[1,2.2,31.59],[2,2.02,4.55]],"ltp":2.26,"tv":71.24,"id":424676}]}]}
{"op":"mcm","clk":"11798625337","pt":1723154538341,"mc":[{"id":"1.231501231","rc":[{"batb":[[0,2.28,14],[1,2.26,13.81],[2,2.2,31.59]],"ltp":2.26,"tv":71.24,"id":424676}]}]}
{"op":"mcm","clk":"11798625410","pt":1723154540752,"mc":[{"id":"1.231501231","rc":[{"batb":[[0,2.28,10]],"ltp":2.26,"tv":71.24,"id":424676}]}]}
{"op":"mcm","clk":"11798625451","pt":1723154541829,"mc":[{"id":"1.231501231","rc":[{"batb":[[0,2.26,13.81],[1,2.2,31.59],[2,2.02,4.55]],"ltp":2.26,"tv":71.24,"id":424676}]}]}
{"op":"mcm","clk":"11798625570","pt":1723154545070,"mc":[{"id":"1.231501231","rc":[{"batb":[[0,2.28,14],[1,2.26,13.81],[2,2.2,31.59]],"ltp":2.26,"tv":71.24,"id":424676}]}]}
{"op":"mcm","clk":"11798625642","pt":1723154547330,"mc":[{"id":"1.231501231","rc":[{"batb":[[0,2.28,10]],"ltp":2.26,"tv":71.24,"id":424676}]}]}
{"op":"mcm","clk":"11798625682","pt":1723154548358,"mc":[{"id":"1.231501231","rc":[{"batb":[[0,2.26,13.81],[1,2.2,31.59],[2,2.02,4.55]],"ltp":2.26,"tv":71.24,"id":424676}]}]}
{"op":"mcm","clk":"11798625727","pt":1723154549844,"mc":[{"id":"1.231501231","rc":[{"batb":[[0,2.28,4],[1,2.26,13.81],[2,2.2,31.59]],"ltp":2.26,"tv":71.24,"id":424676}]}]}
{"op":"mcm","clk":"11798625788","pt":1723154551951,"mc":[{"id":"1.231501231","rc":[{"batb":[[0,2.3,10],[1,2.28,4],[2,2.26,13.81]],"ltp":2.26,"tv":71.24,"id":424676}]}]}
{"op":"mcm","clk":"11798625794","pt":1723154552155,"mc":[{"id":"1.231501231","rc":[{"batb":[[1,2.26,13.81],[2,2.2,31.59]],"ltp":2.26,"tv":71.24,"id":424676}]}]}
{"op":"mcm","clk":"11798625829","pt":1723154553436,"mc":[{"id":"1.231501231","rc":[{"batl":[[0,1.8,450],[1,1.82,2],[2,1.86,21.9]],"ltp":1.8,"tv":116.97,"id":31376}]}]}
{"op":"mcm","clk":"11798625856","pt":1723154554566,"mc":[{"id":"1.231501231","rc":[{"batb":[[0,2.32,4],[1,2.3,10],[2,2.26,13.81]],"ltp":2.26,"tv":71.24,"id":424676}]}]}
{"op":"mcm","clk":"11798625887","pt":1723154555350,"mc":[{"id":"1.231501231","rc":[{"batb":[[1,2.26,13.81],[2,2.2,31.59]],"ltp":2.26,"tv":71.24,"id":424676}]}]}
{"op":"mcm","clk":"11798625940","pt":1723154556978,"mc":[{"id":"1.231501231","rc":[{"batb":[[0,2.26,13.81],[1,2.2,31.59],[2,2.02,4.55]],"ltp":2.26,"tv":71.24,"id":424676}]}]}
{"op":"mcm","clk":"11798626005","pt":1723154558774,"mc":[{"id":"1.231501231","rc":[{"batb":[[0,2.28,10]],"ltp":2.26,"tv":71.24,"id":424676}]}]}
{"op":"mcm","clk":"11798626045","pt":1723154559960,"mc":[{"id":"1.231501231","rc":[{"batb":[[0,2.3,4],[1,2.28,10],[2,2.2,31.59]],"ltp":2.26,"tv":71.24,"id":424676}]}]}
{"op":"mcm","clk":"11798626091","pt":1723154561446,"mc":[{"id":"1.231501231","rc":[{"batb":[[1,2.2,31.59],[2,2.02,4.55]],"ltp":2.26,"tv":71.24,"id":424676}]}]}
{"op":"mcm","clk":"11798626125","pt":1723154562270,"mc":[{"id":"1.231501231","rc":[{"batb":[[0,2.2,31.59],[1,2.02,4.55],[2,1.91,4.55]],"ltp":2.26,"tv":71.24,"id":424676}]}]}
{"op":"mcm","clk":"11798626203","pt":1723154564576,"mc":[{"id":"1.231501231","rc":[{"batb":[[0,2.22,14],[1,2.2,31.59],[2,2.02,4.55]],"ltp":2.26,"tv":71.24,"id":424676}]}]}
{"op":"mcm","clk":"11798626266","pt":1723154566888,"mc":[{"id":"1.231501231","rc":[{"batb":[[0,2.22,10]],"ltp":2.26,"tv":71.24,"id":424676}]}]}
{"op":"mcm","clk":"11798626309","pt":1723154567869,"mc":[{"id":"1.231501231","rc":[{"batb":[[0,2.2,31.59],[1,2.02,4.55],[2,1.91,4.55]],"ltp":2.26,"tv":71.24,"id":424676}]}]}
{"op":"mcm","clk":"11798626344","pt":1723154569149,"mc":[{"id":"1.231501231","rc":[{"batb":[[0,2.22,4],[1,2.2,31.59],[2,2.02,4.55]],"ltp":2.26,"tv":71.24,"id":424676}]}]}
{"op":"mcm","clk":"11798626383","pt":1723154570383,"mc":[{"id":"1.231501231","rc":[{"batb":[[0,2.24,10],[1,2.22,4],[2,2.2,31.59]],"ltp":2.26,"tv":71.24,"id":424676}]}]}
{"op":"mcm","clk":"11798626415","pt":1723154571666,"mc":[{"id":"1.231501231","rc":[{"batb":[[1,2.2,31.59],[2,2.02,4.55]],"ltp":2.26,"tv":71.24,"id":424676}]}]}
{"op":"mcm","clk":"11798626480","pt":1723154573874,"mc":[{"id":"1.231501231","rc":[{"batb":[[0,2.22,4]],"ltp":2.26,"tv":71.24,"id":424676}]}]}
{"op":"mcm","clk":"11798626576","pt":1723154576192,"mc":[{"id":"1.231501231","rc":[{"batb":[[0,2.22,10]],"ltp":2.26,"tv":71.24,"id":424676}]}]}
{"op":"mcm","clk":"11798626789","pt":1723154579762,"mc":[{"id":"1.231501231","rc":[{"batb":[[0,2.22,4]],"ltp":2.26,"tv":71.24,"id":424676}]}]}
{"op":"mcm","clk":"11798626917","pt":1723154582187,"mc":[{"id":"1.231501231","rc":[{"batb":[[0,2.22,10]],"ltp":2.26,"tv":71.24,"id":424676}]}]}
{"op":"mcm","clk":"11798627036","pt":1723154585583,"mc":[{"id":"1.231501231","rc":[{"batb":[[0,2.22,4]],"ltp":2.26,"tv":71.24,"id":424676}]}]}
{"op":"mcm","clk":"11798627134","pt":1723154587900,"mc":[{"id":"1.231501231","rc":[{"batb":[[0,2.24,10]],"ltp":2.26,"tv":71.24,"id":424676}]}]}
{"op":"mcm","clk":"11798627254","pt":1723154591331,"mc":[{"id":"1.231501231","rc":[{"batb":[[0,2.26,4]],"ltp":2.26,"tv":71.24,"id":424676}]}]}
{"op":"mcm","clk":"11798627330","pt":1723154593593,"mc":[{"id":"1.231501231","rc":[{"batb":[[0,2.22,10]],"ltp":2.26,"tv":71.24,"id":424676}]}]}
{"op":"mcm","clk":"11798627447","pt":1723154596839,"mc":[{"id":"1.231501231","rc":[{"batb":[[0,2.24,4]],"ltp":2.26,"tv":71.24,"id":424676}]}]}
{"op":"mcm","clk":"11798627533","pt":1723154599306,"mc":[{"id":"1.231501231","rc":[{"batb":[[0,2.22,10]],"ltp":2.26,"tv":71.24,"id":424676}]}]}
{"op":"mcm","clk":"11798627642","pt":1723154602795,"mc":[{"id":"1.231501231","rc":[{"batb":[[0,2.22,4]],"ltp":2.26,"tv":71.24,"id":424676}]}]}
{"op":"mcm","clk":"11798627708","pt":1723154605000,"mc":[{"id":"1.231501231","rc":[{"batb":[[0,2.24,10],[1,2.22,4],[2,2.2,31.59]],"ltp":2.26,"tv":71.24,"id":424676}]}]}
{"op":"mcm","clk":"11798627712","pt":1723154605101,"mc":[{"id":"1.231501231","rc":[{"batb":[[1,2.2,31.59],[2,2.02,4.55]],"ltp":2.26,"tv":71.24,"id":424676}]}]}
{"op":"mcm","clk":"11798627798","pt":1723154608541,"mc":[{"id":"1.231501231","rc":[{"batb":[[0,2.26,4]],"ltp":2.26,"tv":71.24,"id":424676}]}]}
{"op":"mcm","clk":"11798627872","pt":1723154610804,"mc":[{"id":"1.231501231","rc":[{"batb":[[0,2.28,10]],"ltp":2.26,"tv":71.24,"id":424676}]}]}
{"op":"mcm","clk":"11798627942","pt":1723154613116,"mc":[{"id":"1.231501231","rc":[{"batb":[[0,2.3,4],[1,2.28,10],[2,2.2,31.59]],"ltp":2.26,"tv":71.24,"id":424676}]}]}
{"op":"mcm","clk":"11798627987","pt":1723154614036,"mc":[{"id":"1.231501231","rc":[{"batb":[[1,2.2,31.59],[2,2.02,4.55]],"ltp":2.26,"tv":71.24,"id":424676}]}]}
{"op":"mcm","clk":"11798628060","pt":1723154615527,"mc":[{"id":"1.231501231","rc":[{"batb":[[0,2.2,31.59],[1,2.02,4.55],[2,1.91,4.55]],"ltp":2.26,"tv":71.24,"id":424676}]}]}
{"op":"mcm","clk":"11798628096","pt":1723154616709,"mc":[{"id":"1.231501231","rc":[{"batb":[[0,2.22,10],[1,2.2,31.59],[2,2.02,4.55]],"ltp":2.26,"tv":71.24,"id":424676}]}]}
{"op":"mcm","clk":"11798628172","pt":1723154618915,"mc":[{"id":"1.231501231","rc":[{"batb":[[0,2.24,4],[1,2.22,10],[2,2.2,31.59]],"ltp":2.26,"tv":71.24,"id":424676}]}]}
{"op":"mcm","clk":"11798628214","pt":1723154620148,"mc":[{"id":"1.231501231","rc":[{"batb":[[1,2.2,31.59],[2,2.02,4.55]],"ltp":2.26,"tv":71.24,"id":424676}]}]}
{"op":"mcm","clk":"11798628241","pt":1723154621228,"mc":[{"id":"1.231501231","rc":[{"batb":[[0,2.2,31.59],[1,2.02,4.55],[2,1.91,4.55]],"ltp":2.26,"tv":71.24,"id":424676}]}]}
{"op":"mcm","clk":"11798628274","pt":1723154622556,"mc":[{"id":"1.231501231","rc":[{"batb":[[0,2.22,10],[1,2.2,31.59],[2,2.02,4.55]],"ltp":2.26,"tv":71.24,"id":424676}]}]}
{"op":"mcm","clk":"11798628379","pt":1723154625945,"mc":[{"id":"1.231501231","rc":[{"batb":[[0,2.24,4]],"ltp":2.26,"tv":71.24,"id":424676}]}]}
{"op":"mcm","clk":"11798628421","pt":1723154627429,"mc":[{"id":"1.231501231","rc":[{"batb":[[0,2.2,31.59],[1,2.02,4.55],[2,1.91,4.55]],"ltp":2.26,"tv":71.24,"id":424676}]}]}
{"op":"mcm","clk":"11798628500","pt":1723154629737,"mc":[{"id":"1.231501231","rc":[{"batb":[[0,2.24,4],[1,2.22,10],[2,2.2,31.59]],"ltp":2.26,"tv":71.24,"id":424676}]}]}
{"op":"mcm","clk":"11798628609","pt":1723154632866,"mc":[{"id":"1.231501231","rc":[{"batb":[[0,2.2,31.59],[1,2.02,4.55],[2,1.91,4.55]],"ltp":2.26,"tv":71.24,"id":424676}]}]}
{"op":"mcm","clk":"11798628656","pt":1723154634250,"mc":[{"id":"1.231501231","rc":[{"batb":[[0,2.22,4],[1,2.2,31.59],[2,2.02,4.55]],"ltp":2.26,"tv":71.24,"id":424676}]}]}
{"op":"mcm","clk":"11798628700","pt":1723154635639,"mc":[{"id":"1.231501231","rc":[{"batb":[[0,2.24,10],[1,2.22,4],[2,2.2,31.59]],"ltp":2.26,"tv":71.24,"id":424676}]}]}
{"op":"mcm","clk":"11798628730","pt":1723154636666,"mc":[{"id":"1.231501231","rc":[{"batb":[[1,2.2,31.59],[2,2.02,4.55]],"ltp":2.26,"tv":71.24,"id":424676}]}]}
{"op":"mcm","clk":"11798628810","pt":1723154639281,"mc":[{"id":"1.231501231","rc":[{"batb":[[0,2.22,4]],"ltp":2.26,"tv":71.24,"id":424676}]}]}
{"op":"mcm","clk":"11798628908","pt":1723154641853,"mc":[{"id":"1.231501231","rc":[{"batb":[[0,2.22,10]],"ltp":2.26,"tv":71.24,"id":424676}]}]}
{"op":"mcm","clk":"11798629008","pt":1723154644838,"mc":[{"id":"1.231501231","rc":[{"batb":[[0,2.24,4],[1,2.22,10],[2,2.2,31.59]],"ltp":2.26,"tv":71.24,"id":424676}]}]}
{"op":"mcm","clk":"11798629016","pt":1723154645043,"mc":[{"id":"1.231501231","rc":[{"batb":[[1,2.2,31.59],[2,2.02,4.55]],"ltp":2.26,"tv":71.24,"id":424676}]}]}
{"op":"mcm","clk":"11798629104","pt":1723154647356,"mc":[{"id":"1.231501231","rc":[{"batb":[[0,2.22,10]],"ltp":2.26,"tv":71.24,"id":424676}]}]}
{"op":"mcm","clk":"11798629172","pt":1723154649358,"mc":[{"id":"1.231501231","rc":[{"batb":[[0,2.24,4],[1,2.22,10],[2,2.2,31.59]],"ltp":2.26,"tv":71.24,"id":424676}]}]}
{"op":"mcm","clk":"11798629210","pt":1723154650544,"mc":[{"id":"1.231501231","rc":[{"batb":[[1,2.2,31.59],[2,2.02,4.55]],"ltp":2.26,"tv":71.24,"id":424676}]}]}
{"op":"mcm","clk":"11798629255","pt":1723154651777,"mc":[{"id":"1.231501231","rc":[{"batb":[[0,2.2,31.59],[1,2.02,4.55],[2,1.91,4.55]],"ltp":2.26,"tv":71.24,"id":424676}]}]}
{"op":"mcm","clk":"11798629307","pt":1723154653269,"mc":[{"id":"1.231501231","rc":[{"batb":[[0,2.22,10],[1,2.2,31.59],[2,2.02,4.55]],"ltp":2.26,"tv":71.24,"id":424676}]}]}
{"op":"mcm","clk":"11798629391","pt":1723154655481,"mc":[{"id":"1.231501231","rc":[{"batb":[[0,2.24,4],[1,2.22,10],[2,2.2,31.59]],"ltp":2.26,"tv":71.24,"id":424676}]}]}
{"op":"mcm","clk":"11798629426","pt":1723154656814,"mc":[{"id":"1.231501231","rc":[{"batb":[[1,2.2,31.59],[2,2.02,4.55]],"ltp":2.26,"tv":71.24,"id":424676}]}]}
{"op":"mcm","clk":"11798629475","pt":1723154657894,"mc":[{"id":"1.231501231","rc":[{"batb":[[0,2.2,31.59],[1,2.02,4.55],[2,1.91,4.55]],"ltp":2.26,"tv":71.24,"id":424676}]}]}
{"op":"mcm","clk":"11798629511","pt":1723154659027,"mc":[{"id":"1.231501231","rc":[{"batb":[[0,2.22,10],[1,2.2,31.59],[2,2.02,4.55]],"ltp":2.26,"tv":71.24,"id":424676}]}]}
{"op":"mcm","clk":"11798629659","pt":1723154662329,"mc":[{"id":"1.231501231","rc":[{"batb":[[0,2.22,4]],"ltp":2.26,"tv":71.24,"id":424676}]}]}
{"op":"mcm","clk":"11798629747","pt":1723154664946,"mc":[{"id":"1.231501231","rc":[{"batb":[[0,2.22,10]],"ltp":2.26,"tv":71.24,"id":424676}]}]}
{"op":"mcm","clk":"11798629850","pt":1723154668236,"mc":[{"id":"1.231501231","rc":[{"batb":[[0,2.22,4]],"ltp":2.26,"tv":71.24,"id":424676}]}]}
{"op":"mcm","clk":"11798629937","pt":1723154670654,"mc":[{"id":"1.231501231","rc":[{"batb":[[0,2.24,10]],"ltp":2.26,"tv":71.24,"id":424676}]}]}
{"op":"mcm","clk":"11798630067","pt":1723154674151,"mc":[{"id":"1.231501231","rc":[{"batb":[[0,2.22,4]],"ltp":2.26,"tv":71.24,"id":424676}]}]}
{"op":"mcm","clk":"11798630163","pt":1723154676520,"mc":[{"id":"1.231501231","rc":[{"batb":[[0,2.24,10]],"ltp":2.26,"tv":71.24,"id":424676}]}]}
{"op":"mcm","clk":"11798630272","pt":1723154679961,"mc":[{"id":"1.231501231","rc":[{"batb":[[0,2.2,31.59],[1,2.02,4.55],[2,1.91,4.55]],"ltp":2.26,"tv":71.24,"id":424676}]}]}
{"op":"mcm","clk":"11798630275","pt":1723154680067,"mc":[{"id":"1.231501231","rc":[{"batb":[[0,2.22,4],[1,2.2,31.59],[2,2.02,4.55]],"ltp":2.26,"tv":71.24,"id":424676}]}]}
{"op":"mcm","clk":"11798630354","pt":1723154682324,"mc":[{"id":"1.231501231","rc":[{"batb":[[0,2.24,10]],"ltp":2.26,"tv":71.24,"id":424676}]}]}
{"op":"mcm","clk":"11798630478","pt":1723154685967,"mc":[{"id":"1.231501231","rc":[{"batb":[[0,2.22,4]],"ltp":2.26,"tv":71.24,"id":424676}]}]}
{"op":"mcm","clk":"11798630552","pt":1723154688279,"mc":[{"id":"1.231501231","rc":[{"batb":[[0,2.24,10]],"ltp":2.26,"tv":71.24,"id":424676}]}]}
{"op":"mcm","clk":"11798630643","pt":1723154690537,"mc":[{"id":"1.231501231","rc":[{"batb":[[0,2.26,4],[1,2.24,10],[2,2.2,31.59]],"ltp":2.26,"tv":71.24,"id":424676}]}]}
{"op":"mcm","clk":"11798630671","pt":1723154691562,"mc":[{"id":"1.231501231","rc":[{"batb":[[1,2.2,31.59],[2,2.02,4.55]],"ltp":2.26,"tv":71.24,"id":424676}]}]}
{"op":"mcm","clk":"11798630727","pt":1723154692950,"mc":[{"id":"1.231501231","rc":[{"batb":[[0,2.2,31.59],[1,2.02,4.55],[2,1.91,4.55]],"ltp":2.26,"tv":71.24,"id":424676}]}]}
{"op":"mcm","clk":"11798630794","pt":1723154695261,"mc":[{"id":"1.231501231","rc":[{"batb":[[0,2.22,14],[1,2.2,31.59],[2,2.02,4.55]],"ltp":2.26,"tv":71.24,"id":424676}]}]}
{"op":"mcm","clk":"11798630856","pt":1723154697569,"mc":[{"id":"1.231501231","rc":[{"batb":[[0,2.22,10]],"ltp":2.26,"tv":71.24,"id":424676}]}]}
{"op":"mcm","clk":"11798630885","pt":1723154698551,"mc":[{"id":"1.231501231","rc":[{"batb":[[0,2.2,31.59],[1,2.02,4.55],[2,1.91,4.55]],"ltp":2.26,"tv":71.24,"id":424676}]}]}
{"op":"mcm","clk":"11798630945","pt":1723154699990,"mc":[{"id":"1.231501231","rc":[{"batb":[[0,2.22,4],[1,2.2,31.59],[2,2.02,4.55]],"ltp":2.26,"tv":71.24,"id":424676}]}]}
{"op":"mcm","clk":"11798630986","pt":1723154701075,"mc":[{"id":"1.231501231","rc":[{"batb":[[0,2.24,10],[1,2.22,4],[2,2.2,31.59]],"ltp":2.26,"tv":71.24,"id":424676}]}]}
{"op":"mcm","clk":"11798631027","pt":1723154702467,"mc":[{"id":"1.231501231","rc":[{"batb":[[1,2.2,31.59],[2,2.02,4.55]],"ltp":2.26,"tv":71.24,"id":424676}]}]}
{"op":"mcm","clk":"11798631101","pt":1723154704374,"mc":[{"id":"1.231501231","rc":[{"batb":[[0,2.2,31.59],[1,2.02,4.55],[2,1.91,4.55]],"ltp":2.26,"tv":71.24,"id":424676}]}]}
{"op":"mcm","clk":"11798631201","pt":1723154706899,"mc":[{"id":"1.231501231","rc":[{"batb":[[0,2.22,14],[1,2.2,31.59],[2,2.02,4.55]],"ltp":2.26,"tv":71.24,"id":424676}]}]}
{"op":"mcm","clk":"11798631302","pt":1723154709386,"mc":[{"id":"1.231501231","rc":[{"batb":[[0,2.22,10]],"ltp":2.26,"tv":71.24,"id":424676}]}]}
{"op":"mcm","clk":"11798631343","pt":1723154710363,"mc":[{"id":"1.231501231","rc":[{"batb":[[0,2.26,13.59]],"ltp":2.26,"tv":71.24,"id":424676},{"batl":[[0,1.79,16.86],[1,1.8,450],[2,1.82,2]],"ltp":1.8,"tv":116.97,"id":31376}]}]}
{"op":"mcm","clk":"11798631384","pt":1723154711603,"mc":[{"id":"1.231501231","rc":[{"batb":[[0,2.28,4],[1,2.26,13.59],[2,2.2,31.59]],"ltp":2.26,"tv":71.24,"id":424676}]}]}
{"op":"mcm","clk":"11798631442","pt":1723154712988,"mc":[{"id":"1.231501231","rc":[{"batb":[[0,2.3,10],[1,2.28,4],[2,2.26,13.59]],"ltp":2.26,"tv":71.24,"id":424676}]}]}
{"op":"mcm","clk":"11798631481","pt":1723154713810,"mc":[{"id":"1.231501231","rc":[{"batb":[[1,2.26,13.59],[2,2.2,31.59]],"ltp":2.26,"tv":71.24,"id":424676}]}]}
{"op":"mcm","clk":"11798631577","pt":1723154716276,"mc":[{"id":"1.231501231","rc":[{"batb":[[0,2.32,4]],"ltp":2.26,"tv":71.24,"id":424676}]}]}
{"op":"mcm","clk":"11798631663","pt":1723154718584,"mc":[{"id":"1.231501231","rc":[{"batb":[[0,2.34,10]],"ltp":2.26,"tv":71.24,"id":424676}]}]}
{"op":"mcm","clk":"11798631791","pt":1723154721976,"mc":[{"id":"1.231501231","rc":[{"batb":[[0,2.2,31.59],[1,2.02,4.55],[2,1.91,4.55]],"ltp":2.26,"tv":71.24,"id":424676},{"batl":[[0,1.8,450],[1,1.82,2],[2,1.86,21.9]],"ltp":1.8,"tv":116.97,"id":31376}]}]}
{"op":"mcm","clk":"11798631801","pt":1723154722181,"mc":[{"id":"1.231501231","rc":[{"batb":[[0,2.22,4],[1,2.2,31.59],[2,2.02,4.55]],"ltp":2.26,"tv":71.24,"id":424676}]}]}
{"op":"mcm","clk":"11798631898","pt":1723154724597,"mc":[{"id":"1.231501231","rc":[{"batb":[[0,2.22,10]],"ltp":2.26,"tv":71.24,"id":424676}]}]}
{"op":"mcm","clk":"11798632010","pt":1723154727933,"mc":[{"id":"1.231501231","rc":[{"batb":[[0,2.24,4]],"ltp":2.26,"tv":71.24,"id":424676}]}]}
