{"op":"mcm","clk":"11819803669","pt":1723295951185,"mc":[{"id":"1.231659919","marketDefinition":{"bspMarket":false,"turnInPlayEnabled":true,"persistenceEnabled":true,"marketBaseRate":5.0,"eventId":"33483361","eventTypeId":"4","numberOfWinners":1,"bettingType":"ODDS","marketType":"MATCH_ODDS","marketTime":"2024-08-14T10:30:00.000Z","suspendTime":"2024-08-14T10:30:00.000Z","bspReconciled":false,"complete":true,"inPlay":false,"crossMatching":true,"runnersVoidable":false,"numberOfActiveRunners":2,"betDelay":0,"status":"OPEN","runners":[{"status":"ACTIVE","sortPriority":1,"id":40096579,"name":"Southern Brave Women"},{"status":"ACTIVE","sortPriority":2,"id":40096581,"name":"Welsh Fire Women"}],"regulators":["MR_INT"],"countryCode":"GB","discountAllowed":false,"timezone":"GMT","openDate":"2024-08-14T10:30:00.000Z","version":6065949870,"name":"Match Odds","eventName":"Southern Brave Women v Welsh Fire Women"},"rc":[{"batb":[[0,1.03,200],[1,1.02,200],[2,1.01,220]],"ltp":0.0,"tv":0.0,"id":40096579},{"batb":[[0,1.03,200],[1,1.02,200],[2,1.01,220]],"ltp":0.0,"tv":0.0,"id":40096581}]}]}
{"op":"mcm","clk":"11819803850","pt":1723295951884,"mc":[{"id":"1.231659919","marketDefinition":{"bspMarket":false,"turnInPlayEnabled":true,"persistenceEnabled":true,"marketBaseRate":5.0,"eventId":"33483361","eventTypeId":"4","numberOfWinners":1,"bettingType":"ODDS","marketType":"MATCH_ODDS","marketTime":"2024-08-14T10:30:00.000Z","suspendTime":"2024-08-14T10:30:00.000Z","bspReconciled":false,"complete":true,"inPlay":false,"crossMatching":true,"runnersVoidable":false,"numberOfActiveRunners":2,"betDelay":0,"status":"OPEN","runners":[{"status":"ACTIVE","sortPriority":1,"id":40096579,"name":"Southern Brave Women"},{"status":"ACTIVE","sortPriority":2,"id":40096581,"name":"Welsh Fire Women"}],"regulators":["MR_INT"],"countryCode":"GB","discountAllowed":true,"timezone":"GMT","openDate":"2024-08-14T10:30:00.000Z","version":6065949870,"name":"Match Odds","eventName":"Southern Brave Women v Welsh Fire Women"}}]}
{"op":"mcm","clk":"11820247221","pt":1723298349593,"mc":[{"id":"1.231659919","rc":[{"batb":[[0,1.1,25000],[1,1.09,25000],[2,1.08,25000]],"ltp":0.0,"tv":0.0,"id":40096579},{"batb":[[0,1.1,25000],[1,1.09,25000],[2,1.08,25000]],"ltp":0.0,"tv":0.0,"id":40096581}]}]}
{"op":"mcm","clk":"11820248604","pt":1723298360240,"mc":[{"id":"1.231659919","rc":[{"batb":[[0,1.09,15000],[1,1.08,25000],[2,1.07,25000]],"ltp":0.0,"tv":0.0,"id":40096579}]}]}
{"op":"mcm","clk":"11820248718","pt":1723298361250,"mc":[{"id":"1.231659919","rc":[{"batb":[[0,1.06,25000],[1,1.05,25000],[2,1.04,25000]],"ltp":0.0,"tv":0.0,"id":40096579}]}]}
{"op":"mcm","clk":"11820248772","pt":1723298361612,"mc":[{"id":"1.231659919","rc":[{"batb":[[0,1.05,25000],[1,1.04,25000],[2,1.03,25200]],"ltp":0.0,"tv":0.0,"id":40096579}]}]}
{"op":"mcm","clk":"11820248881","pt":1723298362621,"mc":[{"id":"1.231659919","rc":[{"batb":[[0,1.04,25000],[1,1.03,25200],[2,1.02,25200]],"ltp":0.0,"tv":0.0,"id":40096579}]}]}
{"op":"mcm","clk":"11820249060","pt":1723298363845,"mc":[{"id":"1.231659919","rc":[{"batb":[[0,1.03,25200],[1,1.02,25200],[2,1.01,25220]],"ltp":0.0,"tv":0.0,"id":40096579}]}]}
{"op":"mcm","clk":"11820249529","pt":1723298367327,"mc":[{"id":"1.231659919","rc":[{"batb":[[0,1.09,25000],[1,1.08,25000],[2,1.07,25000]],"ltp":0.0,"tv":0.0,"id":40096581}]}]}
{"op":"mcm","clk":"11820249664","pt":1723298368336,"mc":[{"id":"1.231659919","rc":[{"batb":[[0,1.07,10000],[1,1.06,25000],[2,1.05,25000]],"ltp":0.0,"tv":0.0,"id":40096581}]}]}
{"op":"mcm","clk":"11820249726","pt":1723298368843,"mc":[{"id":"1.231659919","rc":[{"batb":[[0,1.05,25000],[1,1.04,25000],[2,1.03,25200]],"ltp":0.0,"tv":0.0,"id":40096581}]}]}
{"op":"mcm","clk":"11820249905","pt":1723298370223,"mc":[{"id":"1.231659919","rc":[{"batb":[[0,1.04,25000],[1,1.03,25200],[2,1.02,25200]],"ltp":0.0,"tv":0.0,"id":40096581}]}]}
{"op":"mcm","clk":"11820253224","pt":1723298394845,"mc":[{"id":"1.231659919","rc":[{"batb":[[0,1.04,25000],[1,1.03,25200],[2,1.02,25200]],"ltp":0.0,"tv":0.0,"id":40096579}]}]}
{"op":"mcm","clk":"11824774992","pt":1723319697677,"mc":[{"id":"1.231659919","rc":[{"batb":[[0,1.55,151.6],[1,1.04,25000],[2,1.03,25200]],"ltp":0.0,"tv":0.0,"id":40096579},{"batb":[[0,1.45,161.17],[1,1.04,25000],[2,1.03,25200]],"ltp":0.0,"tv":0.0,"id":40096581}]}]}
{"op":"mcm","clk":"11825027469","pt":1723321040246,"mc":[{"id":"1.231659919","rc":[{"batb":[[0,1.56,7.44],[1,1.55,151.6],[2,1.04,25000]],"ltp":0.0,"tv":0.0,"id":40096579},{"batb":[[0,1.46,7.92],[1,1.45,161.17],[2,1.04,25000]],"ltp":0.0,"tv":0.0,"id":40096581}]}]}
{"op":"mcm","clk":"11825043517","pt":1723321123324,"mc":[{"id":"1.231659919","rc":[{"batb":[[0,1.56,15.04],[1,1.04,25000],[2,1.03,25200]],"ltp":0.0,"tv":0.0,"id":40096579},{"batb":[[0,1.46,15.23],[1,1.04,25000],[2,1.03,25200]],"ltp":0.0,"tv":0.0,"id":40096581}]}]}
{"op":"mcm","clk":"11825043561","pt":1723321123474,"mc":[{"id":"1.231659919","rc":[{"batb":[[0,1.61,145.88],[1,1.56,15.04],[2,1.04,25000]],"ltp":0.0,"tv":0.0,"id":40096579},{"batb":[[0,1.52,153.65],[1,1.46,15.23],[2,1.04,25000]],"ltp":0.0,"tv":0.0,"id":40096581}]}]}
{"op":"mcm","clk":"11825043923","pt":1723321125159,"mc":[{"id":"1.231659919","rc":[{"batb":[[1,1.56,7.6]],"ltp":0.0,"tv":0.0,"id":40096579},{"batb":[[1,1.46,7.31]],"ltp":0.0,"tv":0.0,"id":40096581}]}]}
{"op":"mcm","clk":"11825266753","pt":1723322459292,"mc":[{"id":"1.231659919","rc":[{"batb":[[0,1.62,7.16],[1,1.61,145.88],[2,1.56,7.6]],"ltp":0.0,"tv":0.0,"id":40096579},{"batb":[[0,1.53,7.55],[1,1.52,153.65],[2,1.46,7.31]],"batl":[[0,2.62,4.37]],"ltp":0.0,"tv":0.0,"id":40096581}]}]}
{"op":"mcm","clk":"11825272929","pt":1723322510229,"mc":[{"id":"1.231659919","rc":[{"batb":[[0,1.64,143.18],[1,1.62,7.16]],"ltp":0.0,"tv":0.0,"id":40096579},{"batb":[[0,1.54,151.63],[1,1.53,7.55]],"ltp":0.0,"tv":0.0,"id":40096581}]}]}
{"op":"mcm","clk":"11825273221","pt":1723322512313,"mc":[{"id":"1.231659919","rc":[{"batb":[[1,1.56,7.6],[2,1.04,25000]],"ltp":0.0,"tv":0.0,"id":40096579},{"batb":[[1,1.46,7.31],[2,1.04,25000]],"ltp":0.0,"tv":0.0,"id":40096581}]}]}
{"op":"mcm","clk":"11825368555","pt":1723323336669,"mc":[{"id":"1.231659919","rc":[{"batb":[[2,1.25,100]],"ltp":0.0,"tv":0.0,"id":40096579},{"batb":[[2,1.25,100]],"ltp":0.0,"tv":0.0,"id":40096581}]}]}
{"op":"mcm","clk":"11825370020","pt":1723323352239,"mc":[{"id":"1.231659919","rc":[{"batb":[[0,1.65,7.6],[1,1.64,143.18]],"ltp":0.0,"tv":0.0,"id":40096579},{"batb":[[0,1.55,7.31],[1,1.54,151.63]],"ltp":0.0,"tv":0.0,"id":40096581}]}]}
{"op":"mcm","clk":"11825387731","pt":1723323562142,"mc":[{"id":"1.231659919","rc":[{"batb":[[0,1.67,140.57],[1,1.65,7.6]],"ltp":0.0,"tv":0.0,"id":40096579},{"batb":[[0,1.56,149.66],[1,1.55,7.31]],"ltp":0.0,"tv":0.0,"id":40096581}]}]}
{"op":"mcm","clk":"11825510834","pt":1723324904044,"mc":[{"id":"1.231659919","rc":[{"batb":[[0,1.68,6.9],[1,1.67,140.57],[2,1.65,7.6]],"ltp":0.0,"tv":0.0,"id":40096579},{"batb":[[0,1.57,7.35],[1,1.56,149.66],[2,1.55,7.31]],"batl":[[0,2.48,4.61]],"ltp":0.0,"tv":0.0,"id":40096581}]}]}
{"op":"mcm","clk":"11825515678","pt":1723324959875,"mc":[{"id":"1.231659919","rc":[{"batb":[[0,1.69,138.89],[1,1.68,6.9]],"ltp":0.0,"tv":0.0,"id":40096579},{"batb":[[0,1.58,147.74],[1,1.57,7.35]],"ltp":0.0,"tv":0.0,"id":40096581}]}]}
{"op":"mcm","clk":"11825515786","pt":1723324961594,"mc":[{"id":"1.231659919","rc":[{"batb":[[1,1.65,7.6],[2,1.25,100]],"ltp":0.0,"tv":0.0,"id":40096579},{"batb":[[1,1.55,7.31],[2,1.25,100]],"ltp":0.0,"tv":0.0,"id":40096581}]}]}
{"op":"mcm","clk":"11825571456","pt":1723325740359,"mc":[{"id":"1.231659919","rc":[{"batb":[[1,1.25,100],[2,1.04,25000]],"ltp":0.0,"tv":0.0,"id":40096579}]}]}
{"op":"mcm","clk":"11825571506","pt":1723325740829,"mc":[{"id":"1.231659919","rc":[{"batb":[[0,1.7,7.6],[1,1.69,138.89],[2,1.25,100]],"ltp":0.0,"tv":0.0,"id":40096579},{"batb":[[0,1.59,7.31],[1,1.58,147.74]],"ltp":0.0,"tv":0.0,"id":40096581}]}]}
{"op":"mcm","clk":"11825583331","pt":1723325925696,"mc":[{"id":"1.231659919","rc":[{"batb":[[0,1.71,137.25],[1,1.7,7.6]],"ltp":0.0,"tv":0.0,"id":40096579},{"batb":[[0,1.6,145.87],[1,1.59,7.31]],"ltp":0.0,"tv":0.0,"id":40096581}]}]}
{"op":"mcm","clk":"11825599588","pt":1723326179035,"mc":[{"id":"1.231659919","rc":[{"batb":[[0,2.06,3.68],[1,1.71,137.25],[2,1.7,7.6]],"ltp":0.0,"tv":0.0,"id":40096579},{"batb":[[0,1.87,4.48],[1,1.6,145.87],[2,1.59,7.31]],"ltp":0.0,"tv":0.0,"id":40096581}]}]}
{"op":"mcm","clk":"11825662842","pt":1723327276340,"mc":[{"id":"1.231659919","rc":[{"batb":[[1,1.72,6.92],[2,1.71,137.25]],"ltp":0.0,"tv":0.0,"id":40096579},{"batb":[[1,1.61,7.38]],"batl":[[0,2.4,4.95]],"ltp":0.0,"tv":0.0,"id":40096581}]}]}
{"op":"mcm","clk":"11825662850","pt":1723327276443,"mc":[{"id":"1.231659919","rc":[{"batb":[[2,1.7,7.6]],"ltp":0.0,"tv":0.0,"id":40096579}]}]}
{"op":"mcm","clk":"11825663027","pt":1723327279527,"mc":[{"id":"1.231659919","rc":[{"batb":[[1,1.7,7.6],[2,1.25,100]],"ltp":0.0,"tv":0.0,"id":40096579},{"batb":[[1,1.59,7.31],[2,1.25,100]],"ltp":0.0,"tv":0.0,"id":40096581}]}]}
{"op":"mcm","clk":"11825704367","pt":1723328058955,"mc":[{"id":"1.231659919","rc":[{"batb":[[1,1.25,100],[2,1.04,25000]],"ltp":0.0,"tv":0.0,"id":40096579},{"batb":[[1,1.25,100],[2,1.04,25000]],"ltp":0.0,"tv":0.0,"id":40096581}]}]}
{"op":"mcm","clk":"11828281917","pt":1723369880978,"mc":[{"id":"1.231659919","rc":[{"batb":[[1,1.74,17.32],[2,1.25,100]],"ltp":0.0,"tv":0.0,"id":40096579},{"batb":[[1,1.74,17.32],[2,1.25,100]],"ltp":0.0,"tv":0.0,"id":40096581}]}]}
{"op":"mcm","clk":"11830884844","pt":1723386110833,"mc":[{"id":"1.231659919","rc":[{"batb":[[0,2.06,3.8]],"ltp":0.0,"tv":0.0,"id":40096579},{"batb":[[0,1.87,4.63]],"ltp":0.0,"tv":0.0,"id":40096581}]}]}
{"op":"mcm","clk":"11832176364","pt":1723393420843,"mc":[{"id":"1.231659919","rc":[{"batb":[[0,1.89,69.23],[1,1.87,4.63],[2,1.74,17.32]],"ltp":0.0,"tv":0.0,"id":40096581}]}]}
{"op":"mcm","clk":"11832177828","pt":1723393429968,"mc":[{"id":"1.231659919","rc":[{"batb":[[0,1.87,4.63],[1,1.74,17.32],[2,1.25,100]],"ltp":0.0,"tv":0.0,"id":40096581}]}]}
{"op":"mcm","clk":"11836258479","pt":1723447654508,"mc":[{"id":"1.231659919","rc":[{"trd":[[2.06,0.32]],"batb":[[0,2.06,3.64]],"ltp":2.06,"tv":0.32,"id":40096579}],"tv":0.32}]}
{"op":"mcm","clk":"11836258621","pt":1723447659068,"mc":[{"id":"1.231659919","rc":[{"batb":[[0,2.06,3.8]],"ltp":2.06,"tv":0.32,"id":40096579}]}]}
{"op":"mcm","clk":"11836477353","pt":1723455448195,"mc":[{"id":"1.231659919","rc":[{"trd":[[2.06,0.8]],"batb":[[0,2.06,3.56]],"ltp":2.06,"tv":0.8,"id":40096579}],"tv":0.8}]}
{"op":"mcm","clk":"11836477516","pt":1723455453182,"mc":[{"id":"1.231659919","rc":[{"batb":[[0,2.06,3.8]],"ltp":2.06,"tv":0.8,"id":40096579}]}]}
{"op":"mcm","clk":"11836494178","pt":1723456102147,"mc":[{"id":"1.231659919","rc":[{"batb":[[0,1.75,113.23]],"ltp":2.06,"tv":0.8,"id":40096579},{"batb":[[0,1.74,17.32],[1,1.25,100],[2,1.04,25000]],"ltp":0.0,"tv":0.0,"id":40096581}]}]}
{"op":"mcm","clk":"11836520190","pt":1723456839982,"mc":[{"id":"1.231659919","rc":[{"batb":[[0,1.76,5.56],[1,1.75,113.23],[2,1.74,17.32]],"ltp":2.06,"tv":0.8,"id":40096579}]}]}
{"op":"mcm","clk":"11836542009","pt":1723457408926,"mc":[{"id":"1.231659919","rc":[{"batb":[[0,1.77,111.94],[1,1.76,5.56]],"ltp":2.06,"tv":0.8,"id":40096579}]}]}
{"op":"mcm","clk":"11836542045","pt":1723457409810,"mc":[{"id":"1.231659919","rc":[{"batb":[[1,1.74,17.32],[2,1.25,100]],"ltp":2.06,"tv":0.8,"id":40096579}]}]}
{"op":"mcm","clk":"11836544328","pt":1723457464762,"mc":[{"id":"1.231659919","rc":[{"batb":[[0,2.06,3.83],[1,1.77,111.94],[2,1.74,17.32]],"ltp":2.06,"tv":0.8,"id":40096579},{"batb":[[0,1.87,4.66],[1,1.74,17.32],[2,1.25,100]],"ltp":0.0,"tv":0.0,"id":40096581}]}]}
{"op":"mcm","clk":"11836550498","pt":1723457612382,"mc":[{"id":"1.231659919","rc":[{"batb":[[1,1.74,17.32],[2,1.25,100]],"ltp":2.06,"tv":0.8,"id":40096579}]}]}
{"op":"mcm","clk":"11836582758","pt":1723458603628,"mc":[{"id":"1.231659919","rc":[{"batb":[[0,2.06,38.32]],"ltp":2.06,"tv":0.8,"id":40096579},{"batb":[[0,1.87,46.69]],"ltp":0.0,"tv":0.0,"id":40096581}]}]}
{"op":"mcm","clk":"11836946136","pt":1723469715357,"mc":[{"id":"1.231659919","rc":[{"batb":[[0,2.06,74.87]],"ltp":2.06,"tv":0.8,"id":40096579},{"batb":[[0,1.87,91.22]],"ltp":0.0,"tv":0.0,"id":40096581}]}]}
{"op":"mcm","clk":"11836946143","pt":1723469715459,"mc":[{"id":"1.231659919","rc":[{"batb":[[0,2.06,36.55]],"ltp":2.06,"tv":0.8,"id":40096579},{"batb":[[0,1.87,44.53]],"ltp":0.0,"tv":0.0,"id":40096581}]}]}
{"op":"mcm","clk":"11837228727","pt":1723477048712,"mc":[{"id":"1.231659919","rc":[{"trd":[[2.06,0.96]],"batb":[[0,2.06,36.47]],"ltp":2.06,"tv":0.96,"id":40096579}],"tv":0.96}]}
{"op":"mcm","clk":"11837228820","pt":1723477050626,"mc":[{"id":"1.231659919","rc":[{"batb":[[0,2.06,36.55]],"ltp":2.06,"tv":0.96,"id":40096579}]}]}
{"op":"mcm","clk":"11837758909","pt":1723485819181,"mc":[{"id":"1.231659919","rc":[{"batb":[[1,1.75,444],[2,1.74,17.32]],"ltp":0.0,"tv":0.0,"id":40096581}]}]}
{"op":"mcm","clk":"11838161764","pt":1723490500210,"mc":[{"id":"1.231659919","rc":[{"trd":[[2.06,1.55]],"batb":[[0,2.06,36.26]],"ltp":2.06,"tv":1.54,"id":40096579}],"tv":1.54}]}
{"op":"mcm","clk":"11838162014","pt":1723490503517,"mc":[{"id":"1.231659919","rc":[{"batb":[[0,2.06,36.55]],"ltp":2.06,"tv":1.54,"id":40096579}]}]}
{"op":"mcm","clk":"11839936335","pt":1723534429508,"mc":[{"id":"1.231659919","rc":[{"trd":[[2.06,1.54]],"batl":[[0,12,0.52]],"ltp":2.06,"tv":1.54,"id":40096579},{"batl":[[0,12,0.52]],"ltp":0.0,"tv":0.0,"id":40096581}],"tv":1.54}]}
{"op":"mcm","clk":"11840440279","pt":1723546537580,"mc":[{"id":"1.231659919","rc":[{"batl":[[0,2.36,1],[1,12,0.52]],"ltp":2.06,"tv":1.54,"id":40096579}]}]}
{"op":"mcm","clk":"11841014670","pt":1723556116116,"mc":[{"id":"1.231659919","rc":[{"batb":[[0,2.06,35.79]],"ltp":2.06,"tv":1.54,"id":40096579},{"batb":[[0,1.87,43.61]],"ltp":0.0,"tv":0.0,"id":40096581}]}]}
{"op":"mcm","clk":"11841019482","pt":1723556205542,"mc":[{"id":"1.231659919","rc":[{"batb":[[1,1.86,555],[2,1.74,17.32]],"ltp":2.06,"tv":1.54,"id":40096579}]}]}
{"op":"mcm","clk":"11841024685","pt":1723556324314,"mc":[{"id":"1.231659919","rc":[{"batb":[[1,1.89,222],[2,1.86,555]],"ltp":2.06,"tv":1.54,"id":40096579}]}]}
{"op":"mcm","clk":"11841215467","pt":1723561093950,"mc":[{"id":"1.231659919","rc":[{"batl":[[0,1.94,2],[1,12,0.52]],"ltp":0.0,"tv":0.0,"id":40096581}]}]}
{"op":"mcm","clk":"11841332530","pt":1723562613035,"mc":[{"id":"1.231659919","rc":[{"batb":[[0,1.86,44.11]],"ltp":0.0,"tv":0.0,"id":40096581}]}]}
{"op":"mcm","clk":"11841438547","pt":1723563950132,"mc":[{"id":"1.231659919","rc":[{"batl":[[1,1.98,138.46],[2,12,0.52]],"ltp":0.0,"tv":0.0,"id":40096581}]}]}
{"op":"mcm","clk":"11841439410","pt":1723563960222,"mc":[{"id":"1.231659919","rc":[{"batb":[[1,1.78,138.46],[2,1.75,444]],"ltp":0.0,"tv":0.0,"id":40096581}]}]}
{"op":"mcm","clk":"11841653090","pt":1723566388984,"mc":[{"id":"1.231659919","rc":[{"batb":[[1,2,9],[2,1.89,222]],"ltp":2.06,"tv":1.54,"id":40096579}]}]}
{"op":"mcm","clk":"11841653690","pt":1723566395499,"mc":[{"id":"1.231659919","rc":[{"batl":[[0,2.2,9],[1,2.36,1],[2,12,0.52]],"ltp":2.06,"tv":1.54,"id":40096579}]}]}
{"op":"mcm","clk":"11841796867","pt":1723567660114,"mc":[{"id":"1.231659919","rc":[{"trd":[[2.06,27.98]],"batb":[[0,2.06,22.57]],"ltp":2.06,"tv":27.98,"id":40096579}],"tv":27.98}]}
{"op":"mcm","clk":"11841797040","pt":1723567662133,"mc":[{"id":"1.231659919","rc":[{"batb":[[0,2.06,35.79]],"ltp":2.06,"tv":27.98,"id":40096579}]}]}
{"op":"mcm","clk":"11841951919","pt":1723569298130,"mc":[{"id":"1.231659919","rc":[{"trd":[[2.06,27.96]],"ltp":2.06,"tv":27.95,"id":40096579},{"trd":[[1.86,29.24]],"batb":[[0,1.86,29.49]],"ltp":1.86,"tv":29.23,"id":40096581}],"tv":57.19}]}
{"op":"mcm","clk":"11841952033","pt":1723569299326,"mc":[{"id":"1.231659919","rc":[{"batb":[[0,2.08,10],[1,2.06,35.79],[2,2,9]],"ltp":2.06,"tv":27.95,"id":40096579},{"batb":[[0,1.86,44.11]],"ltp":1.86,"tv":29.23,"id":40096581}]}]}
{"op":"mcm","clk":"11841952437","pt":1723569303341,"mc":[{"id":"1.231659919","rc":[{"batb":[[0,2.06,35.79],[1,2,9],[2,1.89,222]],"ltp":2.06,"tv":27.95,"id":40096579}]}]}
{"op":"mcm","clk":"11841960200","pt":1723569379638,"mc":[{"id":"1.231659919","rc":[{"batb":[[0,2.08,10],[1,2.06,35.79],[2,2,9]],"ltp":2.06,"tv":27.95,"id":40096579}]}]}
{"op":"mcm","clk":"11841960777","pt":1723569384319,"mc":[{"id":"1.231659919","rc":[{"batb":[[0,2.06,35.79],[1,2,9],[2,1.89,222]],"ltp":2.06,"tv":27.95,"id":40096579}]}]}
{"op":"mcm","clk":"11841961228","pt":1723569388725,"mc":[{"id":"1.231659919","rc":[{"batb":[[0,2.08,10],[1,2.06,35.79],[2,2,9]],"ltp":2.06,"tv":27.95,"id":40096579}]}]}
{"op":"mcm","clk":"11841962253","pt":1723569399256,"mc":[{"id":"1.231659919","rc":[{"batb":[[0,2.06,35.79],[1,2,9],[2,1.89,222]],"ltp":2.06,"tv":27.95,"id":40096579}]}]}
{"op":"mcm","clk":"11841962819","pt":1723569405457,"mc":[{"id":"1.231659919","rc":[{"batb":[[0,2.08,10],[1,2.06,35.79],[2,2,9]],"ltp":2.06,"tv":27.95,"id":40096579}]}]}
{"op":"mcm","clk":"11841963599","pt":1723569413292,"mc":[{"id":"1.231659919","rc":[{"batb":[[0,2.06,35.79],[1,2,9],[2,1.89,222]],"ltp":2.06,"tv":27.95,"id":40096579}]}]}
{"op":"mcm","clk":"11841964010","pt":1723569417407,"mc":[{"id":"1.231659919","rc":[{"batb":[[0,2.08,10],[1,2.06,35.79],[2,2,9]],"ltp":2.06,"tv":27.95,"id":40096579}]}]}
{"op":"mcm","clk":"11841964814","pt":1723569425914,"mc":[{"id":"1.231659919","rc":[{"batb":[[0,2.06,35.79],[1,2,9],[2,1.89,222]],"ltp":2.06,"tv":27.95,"id":40096579}]}]}
{"op":"mcm","clk":"11841965289","pt":1723569430913,"mc":[{"id":"1.231659919","rc":[{"batb":[[0,2.08,10],[1,2.06,35.79],[2,2,9]],"ltp":2.06,"tv":27.95,"id":40096579}]}]}
{"op":"mcm","clk":"11841965996","pt":1723569437598,"mc":[{"id":"1.231659919","rc":[{"batb":[[0,2.06,35.79],[1,2,9],[2,1.89,222]],"ltp":2.06,"tv":27.95,"id":40096579}]}]}
{"op":"mcm","clk":"11841966363","pt":1723569441024,"mc":[{"id":"1.231659919","rc":[{"batb":[[0,2.08,10],[1,2.06,35.79],[2,2,9]],"ltp":2.06,"tv":27.95,"id":40096579}]}]}
{"op":"mcm","clk":"11841966947","pt":1723569447512,"mc":[{"id":"1.231659919","rc":[{"batb":[[0,2.06,35.79],[1,2,9],[2,1.89,222]],"ltp":2.06,"tv":27.95,"id":40096579}]}]}
{"op":"mcm","clk":"11841967272","pt":1723569451144,"mc":[{"id":"1.231659919","rc":[{"batb":[[0,2.08,10],[1,2.06,35.79],[2,2,9]],"ltp":2.06,"tv":27.95,"id":40096579}]}]}
{"op":"mcm","clk":"11841967967","pt":1723569458129,"mc":[{"id":"1.231659919","rc":[{"batb":[[0,2.06,35.79],[1,2,9],[2,1.89,222]],"ltp":2.06,"tv":27.95,"id":40096579}]}]}
{"op":"mcm","clk":"11841968265","pt":1723569461348,"mc":[{"id":"1.231659919","rc":[{"batb":[[0,2.08,10],[1,2.06,35.79],[2,2,9]],"ltp":2.06,"tv":27.95,"id":40096579}]}]}
{"op":"mcm","clk":"11841968816","pt":1723569467829,"mc":[{"id":"1.231659919","rc":[{"batb":[[0,2.06,35.79],[1,2,9],[2,1.89,222]],"ltp":2.06,"tv":27.95,"id":40096579}]}]}
{"op":"mcm","clk":"11841969111","pt":1723569471142,"mc":[{"id":"1.231659919","rc":[{"batb":[[0,2.08,10],[1,2.06,35.79],[2,2,9]],"ltp":2.06,"tv":27.95,"id":40096579}]}]}
{"op":"mcm","clk":"11841969704","pt":1723569477464,"mc":[{"id":"1.231659919","rc":[{"batb":[[0,2.06,35.79],[1,2,9],[2,1.89,222]],"ltp":2.06,"tv":27.95,"id":40096579}]}]}
{"op":"mcm","clk":"11842013923","pt":1723569988768,"mc":[{"id":"1.231659919","rc":[{"batb":[[0,2.08,10],[1,2.06,35.79],[2,2,9]],"ltp":2.06,"tv":27.95,"id":40096579}]}]}
{"op":"mcm","clk":"11842014453","pt":1723569994675,"mc":[{"id":"1.231659919","rc":[{"batb":[[0,2.06,35.79],[1,2,9],[2,1.89,222]],"ltp":2.06,"tv":27.95,"id":40096579}]}]}
{"op":"mcm","clk":"11842068814","pt":1723570540028,"mc":[{"id":"1.231659919","rc":[{"batb":[[0,2.08,10],[1,2.06,35.79],[2,2,9]],"ltp":2.06,"tv":27.95,"id":40096579},{"trd":[[1.86,117.24]],"batb":[[0,1.78,138.57],[1,1.75,444],[2,1.74,17.32]],"ltp":1.86,"tv":117.23,"id":40096581}],"tv":145.19}]}
{"op":"mcm","clk":"11842069148","pt":1723570543554,"mc":[{"id":"1.231659919","rc":[{"batb":[[0,2.06,35.79],[1,2,9],[2,1.89,222]],"ltp":2.06,"tv":27.95,"id":40096579},{"batb":[[0,1.82,46.27],[1,1.78,138.46],[2,1.75,444]],"ltp":1.86,"tv":117.23,"id":40096581}]}]}
{"op":"mcm","clk":"11842097737","pt":1723570823533,"mc":[{"id":"1.231659919","rc":[{"batb":[[2,1.74,17.32]],"ltp":1.86,"tv":117.23,"id":40096581}]}]}
{"op":"mcm","clk":"11842098856","pt":1723570835949,"mc":[{"id":"1.231659919","rc":[{"batb":[[2,1.74,350.32]],"ltp":1.86,"tv":117.23,"id":40096581}]}]}
{"op":"mcm","clk":"11842249020","pt":1723572336390,"mc":[{"id":"1.231659919","rc":[{"trd":[[2.06,27.95]],"batb":[[0,2.08,10],[1,2.06,35.79],[2,2,9]],"ltp":2.06,"tv":27.95,"id":40096579},{"trd":[[1.86,117.23]],"ltp":1.86,"tv":117.23,"id":40096581}],"tv":145.18}]}
{"op":"mcm","clk":"11842249626","pt":1723572341445,"mc":[{"id":"1.231659919","rc":[{"batb":[[0,2.06,35.79],[1,2,9],[2,1.89,222]],"ltp":2.06,"tv":27.95,"id":40096579}]}]}
{"op":"mcm","clk":"11842249851","pt":1723572343656,"mc":[{"id":"1.231659919","rc":[{"batb":[[0,2.1,10],[1,2.06,35.79],[2,2,9]],"ltp":2.06,"tv":27.95,"id":40096579}]}]}
{"op":"mcm","clk":"11842250828","pt":1723572354224,"mc":[{"id":"1.231659919","rc":[{"batb":[[0,2.06,35.79],[1,2,9],[2,1.89,222]],"ltp":2.06,"tv":27.95,"id":40096579}]}]}
{"op":"mcm","clk":"11842251252","pt":1723572358661,"mc":[{"id":"1.231659919","rc":[{"batb":[[0,2.08,10],[1,2.06,35.79],[2,2,9]],"ltp":2.06,"tv":27.95,"id":40096579}]}]}
{"op":"mcm","clk":"11842252016","pt":1723572365252,"mc":[{"id":"1.231659919","rc":[{"batb":[[0,2.06,35.79],[1,2,9],[2,1.89,222]],"ltp":2.06,"tv":27.95,"id":40096579}]}]}
{"op":"mcm","clk":"11842446444","pt":1723574122696,"mc":[{"id":"1.231659919","rc":[{"batb":[[0,2.08,10],[1,2.06,35.79],[2,2,9]],"ltp":2.06,"tv":27.95,"id":40096579}]}]}
{"op":"mcm","clk":"11842446948","pt":1723574127045,"mc":[{"id":"1.231659919","rc":[{"batb":[[0,2.06,35.79],[1,2,9],[2,1.89,222]],"ltp":2.06,"tv":27.95,"id":40096579}]}]}
{"op":"mcm","clk":"11842448265","pt":1723574137876,"mc":[{"id":"1.231659919","rc":[{"batb":[[0,2.08,10],[1,2.06,35.79],[2,2,9]],"ltp":2.06,"tv":27.95,"id":40096579}]}]}
{"op":"mcm","clk":"11842448796","pt":1723574142273,"mc":[{"id":"1.231659919","rc":[{"batb":[[0,2.06,35.79],[1,2,9],[2,1.89,222]],"ltp":2.06,"tv":27.95,"id":40096579}]}]}
{"op":"mcm","clk":"11842473741","pt":1723574352843,"mc":[{"id":"1.231659919","rc":[{"batb":[[0,2.08,10],[1,2.06,35.79],[2,2,9]],"ltp":2.06,"tv":27.95,"id":40096579}]}]}
{"op":"mcm","clk":"11842474134","pt":1723574356435,"mc":[{"id":"1.231659919","rc":[{"batb":[[0,2.06,35.79],[1,2,9],[2,1.89,222]],"ltp":2.06,"tv":27.95,"id":40096579}]}]}
{"op":"mcm","clk":"11842491777","pt":1723574495687,"mc":[{"id":"1.231659919","rc":[{"batb":[[0,2.08,10],[1,2.06,35.79],[2,2,9]],"ltp":2.06,"tv":27.95,"id":40096579}]}]}
{"op":"mcm","clk":"11842492215","pt":1723574498897,"mc":[{"id":"1.231659919","rc":[{"batb":[[0,2.06,35.79],[1,2,9],[2,1.89,222]],"ltp":2.06,"tv":27.95,"id":40096579}]}]}
{"op":"mcm","clk":"11842516136","pt":1723574674793,"mc":[{"id":"1.231659919","rc":[{"trd":[[2.2,9]],"batl":[[0,2.36,1],[1,12,0.52],[2,12,0]],"ltp":2.2,"tv":36.95,"id":40096579},{"trd":[[1.83,10.82]],"batl":[[0,1.83,22.15],[1,1.94,2],[2,1.98,138.46]],"ltp":1.83,"tv":128.04,"id":40096581}],"tv":165.0}]}
{"op":"mcm","clk":"11842516218","pt":1723574675394,"mc":[{"id":"1.231659919","rc":[{"batb":[[0,2.08,10],[1,2.06,35.79],[2,2,9]],"ltp":2.2,"tv":36.95,"id":40096579}]}]}
{"op":"mcm","clk":"11842516775","pt":1723574679083,"mc":[{"id":"1.231659919","rc":[{"batb":[[0,2.06,35.79],[1,2,9],[2,1.89,222]],"ltp":2.2,"tv":36.95,"id":40096579}]}]}
{"op":"mcm","clk":"11842530991","pt":1723574767306,"mc":[{"id":"1.231659919","rc":[{"batb":[[0,2.08,10],[1,2.06,35.79],[2,2,9]],"ltp":2.2,"tv":36.95,"id":40096579}]}]}
{"op":"mcm","clk":"11842531619","pt":1723574771084,"mc":[{"id":"1.231659919","rc":[{"batb":[[0,2.06,35.79],[1,2,9],[2,1.89,222]],"ltp":2.2,"tv":36.95,"id":40096579}]}]}
{"op":"mcm","clk":"11842551246","pt":1723574890947,"mc":[{"id":"1.231659919","rc":[{"batb":[[0,2.08,10],[1,2.06,35.79],[2,2,9]],"ltp":2.2,"tv":36.95,"id":40096579}]}]}
{"op":"mcm","clk":"11842551882","pt":1723574894870,"mc":[{"id":"1.231659919","rc":[{"batb":[[0,2.06,35.79],[1,2,9],[2,1.89,222]],"ltp":2.2,"tv":36.95,"id":40096579}]}]}
{"op":"mcm","clk":"11842560109","pt":1723574943683,"mc":[{"id":"1.231659919","rc":[{"batb":[[0,2.08,10],[1,2.06,35.79],[2,2,9]],"ltp":2.2,"tv":36.95,"id":40096579}]}]}
{"op":"mcm","clk":"11842560768","pt":1723574947805,"mc":[{"id":"1.231659919","rc":[{"batb":[[0,2.06,35.79],[1,2,9],[2,1.89,222]],"ltp":2.2,"tv":36.95,"id":40096579}]}]}
{"op":"mcm","clk":"11842594844","pt":1723575140950,"mc":[{"id":"1.231659919","rc":[{"batb":[[0,2.08,10],[1,2.06,35.79],[2,2,9]],"ltp":2.2,"tv":36.95,"id":40096579}]}]}
{"op":"mcm","clk":"11842595587","pt":1723575144967,"mc":[{"id":"1.231659919","rc":[{"batb":[[0,2.06,35.79],[1,2,9],[2,1.89,222]],"ltp":2.2,"tv":36.95,"id":40096579}]}]}
{"op":"mcm","clk":"11842603072","pt":1723575187405,"mc":[{"id":"1.231659919","rc":[{"batb":[[0,2.08,10],[1,2.06,35.79],[2,2,9]],"ltp":2.2,"tv":36.95,"id":40096579}]}]}
{"op":"mcm","clk":"11842603691","pt":1723575190713,"mc":[{"id":"1.231659919","rc":[{"batb":[[0,2.06,35.79],[1,2,9],[2,1.89,222]],"ltp":2.2,"tv":36.95,"id":40096579}]}]}
{"op":"mcm","clk":"11842653452","pt":1723575474049,"mc":[{"id":"1.231659919","rc":[{"batb":[[0,2.08,10],[1,2.06,35.79],[2,2,9]],"ltp":2.2,"tv":36.95,"id":40096579}]}]}
{"op":"mcm","clk":"11842654095","pt":1723575477651,"mc":[{"id":"1.231659919","rc":[{"batb":[[0,2.06,35.79],[1,2,9],[2,1.89,222]],"ltp":2.2,"tv":36.95,"id":40096579}]}]}
{"op":"mcm","clk":"11842658424","pt":1723575502309,"mc":[{"id":"1.231659919","rc":[{"batb":[[0,2.08,10],[1,2.06,35.79],[2,2,9]],"ltp":2.2,"tv":36.95,"id":40096579}]}]}
{"op":"mcm","clk":"11842658992","pt":1723575505769,"mc":[{"id":"1.231659919","rc":[{"batb":[[0,2.06,35.79],[1,2,9],[2,1.89,222]],"ltp":2.2,"tv":36.95,"id":40096579}]}]}
{"op":"mcm","clk":"11842664224","pt":1723575534663,"mc":[{"id":"1.231659919","rc":[{"batb":[[0,2.08,10],[1,2.06,35.79],[2,2,9]],"ltp":2.2,"tv":36.95,"id":40096579}]}]}
{"op":"mcm","clk":"11842664732","pt":1723575537954,"mc":[{"id":"1.231659919","rc":[{"batb":[[0,2.06,35.79],[1,2,9],[2,1.89,222]],"ltp":2.2,"tv":36.95,"id":40096579}]}]}
{"op":"mcm","clk":"11842671227","pt":1723575576243,"mc":[{"id":"1.231659919","rc":[{"batb":[[0,2.08,10],[1,2.06,35.79],[2,2,9]],"ltp":2.2,"tv":36.95,"id":40096579}]}]}
{"op":"mcm","clk":"11842671846","pt":1723575579753,"mc":[{"id":"1.231659919","rc":[{"batb":[[0,2.06,35.79],[1,2,9],[2,1.89,222]],"ltp":2.2,"tv":36.95,"id":40096579}]}]}
{"op":"mcm","clk":"11842673569","pt":1723575589138,"mc":[{"id":"1.231659919","rc":[{"batb":[[0,2.08,10],[1,2.06,35.79],[2,2,9]],"ltp":2.2,"tv":36.95,"id":40096579}]}]}
{"op":"mcm","clk":"11842674194","pt":1723575592652,"mc":[{"id":"1.231659919","rc":[{"batb":[[0,2.06,35.79],[1,2,9],[2,1.89,222]],"ltp":2.2,"tv":36.95,"id":40096579}]}]}
{"op":"mcm","clk":"11842682660","pt":1723575637657,"mc":[{"id":"1.231659919","rc":[{"trd":[[2.06,27.94]],"batb":[[0,2.08,10],[1,2.06,35.79],[2,2,9]],"ltp":2.2,"tv":36.93,"id":40096579},{"trd":[[1.83,10.83],[1.86,117.21]],"batl":[[0,1.83,22.17]],"ltp":1.83,"tv":128.04,"id":40096581}],"tv":164.97}]}
{"op":"mcm","clk":"11842683444","pt":1723575642041,"mc":[{"id":"1.231659919","rc":[{"batb":[[0,2.06,35.79],[1,2,9],[2,1.89,222]],"ltp":2.2,"tv":36.93,"id":40096579}]}]}
{"op":"mcm","clk":"11842687137","pt":1723575661877,"mc":[{"id":"1.231659919","rc":[{"batb":[[0,2.08,10],[1,2.06,35.79],[2,2,9]],"ltp":2.2,"tv":36.93,"id":40096579}]}]}
{"op":"mcm","clk":"11842687793","pt":1723575665460,"mc":[{"id":"1.231659919","rc":[{"batb":[[0,2.06,35.79],[1,2,9],[2,1.89,222]],"ltp":2.2,"tv":36.93,"id":40096579}]}]}
{"op":"mcm","clk":"11842690158","pt":1723575677553,"mc":[{"id":"1.231659919","rc":[{"batb":[[0,2.08,10],[1,2.06,35.79],[2,2,9]],"ltp":2.2,"tv":36.93,"id":40096579}]}]}
{"op":"mcm","clk":"11842690782","pt":1723575681160,"mc":[{"id":"1.231659919","rc":[{"batb":[[0,2.06,35.79],[1,2,9],[2,1.89,222]],"ltp":2.2,"tv":36.93,"id":40096579}]}]}
{"op":"mcm","clk":"11842693686","pt":1723575697741,"mc":[{"id":"1.231659919","rc":[{"batb":[[0,2.08,10],[1,2.06,35.79],[2,2,9]],"ltp":2.2,"tv":36.93,"id":40096579}]}]}
{"op":"mcm","clk":"11842694306","pt":1723575701054,"mc":[{"id":"1.231659919","rc":[{"batb":[[0,2.06,35.79],[1,2,9],[2,1.89,222]],"ltp":2.2,"tv":36.93,"id":40096579}]}]}
{"op":"mcm","clk":"11842695151","pt":1723575706164,"mc":[{"id":"1.231659919","rc":[{"batb":[[0,2.08,10],[1,2.06,35.79],[2,2,9]],"ltp":2.2,"tv":36.93,"id":40096579}]}]}
{"op":"mcm","clk":"11842695691","pt":1723575709777,"mc":[{"id":"1.231659919","rc":[{"batb":[[0,2.06,35.79],[1,2,9],[2,1.89,222]],"ltp":2.2,"tv":36.93,"id":40096579}]}]}
{"op":"mcm","clk":"11842702075","pt":1723575748727,"mc":[{"id":"1.231659919","rc":[{"batb":[[0,2.08,10],[1,2.06,35.79],[2,2,9]],"ltp":2.2,"tv":36.93,"id":40096579}]}]}
{"op":"mcm","clk":"11842702735","pt":1723575752617,"mc":[{"id":"1.231659919","rc":[{"batb":[[0,2.06,35.79],[1,2,9],[2,1.89,222]],"ltp":2.2,"tv":36.93,"id":40096579}]}]}
{"op":"mcm","clk":"11842703383","pt":1723575755851,"mc":[{"id":"1.231659919","rc":[{"batb":[[0,2.08,10],[1,2.06,35.79],[2,2,9]],"ltp":2.2,"tv":36.93,"id":40096579}]}]}
{"op":"mcm","clk":"11842704013","pt":1723575759844,"mc":[{"id":"1.231659919","rc":[{"batb":[[0,2.06,35.79],[1,2,9],[2,1.89,222]],"ltp":2.2,"tv":36.93,"id":40096579}]}]}
{"op":"mcm","clk":"11842705419","pt":1723575768348,"mc":[{"id":"1.231659919","rc":[{"batb":[[0,2.08,10],[1,2.06,35.79],[2,2,9]],"ltp":2.2,"tv":36.93,"id":40096579}]}]}
{"op":"mcm","clk":"11842706057","pt":1723575771839,"mc":[{"id":"1.231659919","rc":[{"batb":[[0,2.06,35.79],[1,2,9],[2,1.89,222]],"ltp":2.2,"tv":36.93,"id":40096579}]}]}
{"op":"mcm","clk":"11842706546","pt":1723575774777,"mc":[{"id":"1.231659919","rc":[{"batb":[[0,2.08,10],[1,2.06,35.79],[2,2,9]],"ltp":2.2,"tv":36.93,"id":40096579}]}]}
{"op":"mcm","clk":"11842707191","pt":1723575778474,"mc":[{"id":"1.231659919","rc":[{"batb":[[0,2.06,35.79],[1,2,9],[2,1.89,222]],"ltp":2.2,"tv":36.93,"id":40096579}]}]}
{"op":"mcm","clk":"11842708317","pt":1723575784481,"mc":[{"id":"1.231659919","rc":[{"batb":[[0,2.08,10],[1,2.06,35.79],[2,2,9]],"ltp":2.2,"tv":36.93,"id":40096579}]}]}
{"op":"mcm","clk":"11842709084","pt":1723575788586,"mc":[{"id":"1.231659919","rc":[{"batb":[[0,2.06,35.79],[1,2,9],[2,1.89,222]],"ltp":2.2,"tv":36.93,"id":40096579}]}]}
{"op":"mcm","clk":"11842711759","pt":1723575803600,"mc":[{"id":"1.231659919","rc":[{"batb":[[0,2.08,10],[1,2.06,35.79],[2,2,9]],"ltp":2.2,"tv":36.93,"id":40096579}]}]}
{"op":"mcm","clk":"11842712379","pt":1723575807742,"mc":[{"id":"1.231659919","rc":[{"batb":[[0,2.06,35.79],[1,2,9],[2,1.89,222]],"ltp":2.2,"tv":36.93,"id":40096579}]}]}
{"op":"mcm","clk":"11842714819","pt":1723575821486,"mc":[{"id":"1.231659919","rc":[{"batb":[[0,2.08,10],[1,2.06,35.79],[2,2,9]],"ltp":2.2,"tv":36.93,"id":40096579}]}]}
{"op":"mcm","clk":"11842715517","pt":1723575825513,"mc":[{"id":"1.231659919","rc":[{"batb":[[0,2.06,35.79],[1,2,9],[2,1.89,222]],"ltp":2.2,"tv":36.93,"id":40096579}]}]}
{"op":"mcm","clk":"11842716994","pt":1723575833919,"mc":[{"id":"1.231659919","rc":[{"batb":[[0,2.08,10],[1,2.06,35.79],[2,2,9]],"ltp":2.2,"tv":36.93,"id":40096579}]}]}
{"op":"mcm","clk":"11842717614","pt":1723575837445,"mc":[{"id":"1.231659919","rc":[{"batb":[[0,2.06,35.79],[1,2,9],[2,1.89,222]],"ltp":2.2,"tv":36.93,"id":40096579}]}]}
{"op":"mcm","clk":"11842721534","pt":1723575857965,"mc":[{"id":"1.231659919","rc":[{"batb":[[0,2.08,10],[1,2.06,35.79],[2,2,9]],"ltp":2.2,"tv":36.93,"id":40096579}]}]}
{"op":"mcm","clk":"11842722235","pt":1723575861602,"mc":[{"id":"1.231659919","rc":[{"batb":[[0,2.06,35.79],[1,2,9],[2,1.89,222]],"ltp":2.2,"tv":36.93,"id":40096579}]}]}
{"op":"mcm","clk":"11842724528","pt":1723575874082,"mc":[{"id":"1.231659919","rc":[{"batb":[[0,2.08,10],[1,2.06,35.79],[2,2,9]],"ltp":2.2,"tv":36.93,"id":40096579}]}]}
{"op":"mcm","clk":"11842725167","pt":1723575877787,"mc":[{"id":"1.231659919","rc":[{"batb":[[0,2.06,35.79],[1,2,9],[2,1.89,222]],"ltp":2.2,"tv":36.93,"id":40096579}]}]}
{"op":"mcm","clk":"11842726114","pt":1723575883005,"mc":[{"id":"1.231659919","rc":[{"batb":[[0,2.08,10],[1,2.06,35.79],[2,2,9]],"ltp":2.2,"tv":36.93,"id":40096579}]}]}
{"op":"mcm","clk":"11842726808","pt":1723575886705,"mc":[{"id":"1.231659919","rc":[{"batb":[[0,2.06,35.79],[1,2,9],[2,1.89,222]],"ltp":2.2,"tv":36.93,"id":40096579}]}]}
{"op":"mcm","clk":"11842727323","pt":1723575889505,"mc":[{"id":"1.231659919","rc":[{"batb":[[0,2.08,10],[1,2.06,35.79],[2,2,9]],"ltp":2.2,"tv":36.93,"id":40096579}]}]}
{"op":"mcm","clk":"11842727974","pt":1723575893244,"mc":[{"id":"1.231659919","rc":[{"batb":[[0,2.06,35.79],[1,2,9],[2,1.89,222]],"ltp":2.2,"tv":36.93,"id":40096579}]}]}
{"op":"mcm","clk":"11842732324","pt":1723575915745,"mc":[{"id":"1.231659919","rc":[{"batb":[[0,2.08,10],[1,2.06,35.79],[2,2,9]],"ltp":2.2,"tv":36.93,"id":40096579}]}]}
{"op":"mcm","clk":"11842733059","pt":1723575919440,"mc":[{"id":"1.231659919","rc":[{"batb":[[0,2.06,35.79],[1,2,9],[2,1.89,222]],"ltp":2.2,"tv":36.93,"id":40096579}]}]}
{"op":"mcm","clk":"11842735693","pt":1723575933366,"mc":[{"id":"1.231659919","rc":[{"batb":[[0,2.08,10],[1,2.06,35.79],[2,2,9]],"ltp":2.2,"tv":36.93,"id":40096579}]}]}
{"op":"mcm","clk":"11842736465","pt":1723575937551,"mc":[{"id":"1.231659919","rc":[{"batb":[[0,2.06,35.79],[1,2,9],[2,1.89,222]],"ltp":2.2,"tv":36.93,"id":40096579}]}]}
{"op":"mcm","clk":"11842737714","pt":1723575944840,"mc":[{"id":"1.231659919","rc":[{"batb":[[0,2.08,10],[1,2.06,35.79],[2,2,9]],"ltp":2.2,"tv":36.93,"id":40096579}]}]}
{"op":"mcm","clk":"11842738520","pt":1723575948946,"mc":[{"id":"1.231659919","rc":[{"batb":[[0,2.06,35.79],[1,2,9],[2,1.89,222]],"ltp":2.2,"tv":36.93,"id":40096579}]}]}
{"op":"mcm","clk":"11842739357","pt":1723575953259,"mc":[{"id":"1.231659919","rc":[{"batb":[[0,2.08,10],[1,2.06,35.79],[2,2,9]],"ltp":2.2,"tv":36.93,"id":40096579}]}]}
{"op":"mcm","clk":"11842740098","pt":1723575957072,"mc":[{"id":"1.231659919","rc":[{"batb":[[0,2.06,35.79],[1,2,9],[2,1.89,222]],"ltp":2.2,"tv":36.93,"id":40096579}]}]}
{"op":"mcm","clk":"11842741188","pt":1723575962190,"mc":[{"id":"1.231659919","rc":[{"batb":[[0,2.08,10],[1,2.06,35.79],[2,2,9]],"ltp":2.2,"tv":36.93,"id":40096579}]}]}
{"op":"mcm","clk":"11842741865","pt":1723575965764,"mc":[{"id":"1.231659919","rc":[{"batb":[[0,2.06,35.79],[1,2,9],[2,1.89,222]],"ltp":2.2,"tv":36.93,"id":40096579}]}]}
{"op":"mcm","clk":"11842745048","pt":1723575982427,"mc":[{"id":"1.231659919","rc":[{"batb":[[0,2.08,10],[1,2.06,35.79],[2,2,9]],"ltp":2.2,"tv":36.93,"id":40096579}]}]}
{"op":"mcm","clk":"11842745879","pt":1723575986528,"mc":[{"id":"1.231659919","rc":[{"batb":[[0,2.06,35.79],[1,2,9],[2,1.89,222]],"ltp":2.2,"tv":36.93,"id":40096579}]}]}
{"op":"mcm","clk":"11842748630","pt":1723576000536,"mc":[{"id":"1.231659919","rc":[{"batb":[[0,2.08,10],[1,2.06,35.79],[2,2,9]],"ltp":2.2,"tv":36.93,"id":40096579}]}]}
{"op":"mcm","clk":"11842749346","pt":1723576004343,"mc":[{"id":"1.231659919","rc":[{"batb":[[0,2.06,35.79],[1,2,9],[2,1.89,222]],"ltp":2.2,"tv":36.93,"id":40096579}]}]}
{"op":"mcm","clk":"11842750618","pt":1723576010775,"mc":[{"id":"1.231659919","rc":[{"batb":[[0,2.08,10],[1,2.06,35.79],[2,2,9]],"ltp":2.2,"tv":36.93,"id":40096579}]}]}
{"op":"mcm","clk":"11842751792","pt":1723576016841,"mc":[{"id":"1.231659919","rc":[{"batb":[[0,2.06,35.79],[1,2,9],[2,1.89,222]],"ltp":2.2,"tv":36.93,"id":40096579}]}]}
{"op":"mcm","clk":"11842752315","pt":1723576019558,"mc":[{"id":"1.231659919","rc":[{"batb":[[0,2.1,10],[1,2.06,35.79],[2,2,9]],"ltp":2.2,"tv":36.93,"id":40096579}]}]}
{"op":"mcm","clk":"11842754321","pt":1723576030058,"mc":[{"id":"1.231659919","rc":[{"batb":[[0,2.06,35.79],[1,2,9],[2,1.89,222]],"ltp":2.2,"tv":36.93,"id":40096579}]}]}
{"op":"mcm","clk":"11842755020","pt":1723576033995,"mc":[{"id":"1.231659919","rc":[{"batb":[[0,2.08,10],[1,2.06,35.79],[2,2,9]],"ltp":2.2,"tv":36.93,"id":40096579}]}]}
{"op":"mcm","clk":"11842756297","pt":1723576041055,"mc":[{"id":"1.231659919","rc":[{"batb":[[0,2.06,35.79],[1,2,9],[2,1.89,222]],"ltp":2.2,"tv":36.93,"id":40096579}]}]}
{"op":"mcm","clk":"11842758092","pt":1723576050376,"mc":[{"id":"1.231659919","rc":[{"batb":[[0,2.08,10],[1,2.06,35.79],[2,2,9]],"ltp":2.2,"tv":36.93,"id":40096579}]}]}
{"op":"mcm","clk":"11842758795","pt":1723576054162,"mc":[{"id":"1.231659919","rc":[{"batb":[[0,2.06,35.79],[1,2,9],[2,1.89,222]],"ltp":2.2,"tv":36.93,"id":40096579}]}]}
{"op":"mcm","clk":"11842761135","pt":1723576066274,"mc":[{"id":"1.231659919","rc":[{"batb":[[0,2.08,10],[1,2.06,35.79],[2,2,9]],"ltp":2.2,"tv":36.93,"id":40096579}]}]}
{"op":"mcm","clk":"11842761856","pt":1723576069770,"mc":[{"id":"1.231659919","rc":[{"batb":[[0,2.06,35.79],[1,2,9],[2,1.89,222]],"ltp":2.2,"tv":36.93,"id":40096579}]}]}
{"op":"mcm","clk":"11842785736","pt":1723576204118,"mc":[{"id":"1.231659919","rc":[{"batb":[[0,2.08,10],[1,2.06,35.79],[2,2,9]],"ltp":2.2,"tv":36.93,"id":40096579}]}]}
{"op":"mcm","clk":"11842786398","pt":1723576207719,"mc":[{"id":"1.231659919","rc":[{"batb":[[0,2.06,35.79],[1,2,9],[2,1.89,222]],"ltp":2.2,"tv":36.93,"id":40096579}]}]}
{"op":"mcm","clk":"11842921346","pt":1723576901597,"mc":[{"id":"1.231659919","rc":[{"batb":[[0,2.08,10],[1,2.06,35.79],[2,2,9]],"ltp":2.2,"tv":36.93,"id":40096579}]}]}
{"op":"mcm","clk":"11842922092","pt":1723576905795,"mc":[{"id":"1.231659919","rc":[{"batb":[[0,2.06,35.79],[1,2,9],[2,1.89,222]],"ltp":2.2,"tv":36.93,"id":40096579}]}]}
{"op":"mcm","clk":"11842952002","pt":1723577068534,"mc":[{"id":"1.231659919","rc":[{"batb":[[0,2.08,10],[1,2.06,35.79],[2,2,9]],"ltp":2.2,"tv":36.93,"id":40096579}]}]}
{"op":"mcm","clk":"11842952710","pt":1723577072253,"mc":[{"id":"1.231659919","rc":[{"batb":[[0,2.06,35.79],[1,2,9],[2,1.89,222]],"ltp":2.2,"tv":36.93,"id":40096579}]}]}
{"op":"mcm","clk":"11843019018","pt":1723577441500,"mc":[{"id":"1.231659919","rc":[{"batb":[[0,2.08,10],[1,2.06,35.79],[2,2,9]],"ltp":2.2,"tv":36.93,"id":40096579}]}]}
{"op":"mcm","clk":"11843019791","pt":1723577445529,"mc":[{"id":"1.231659919","rc":[{"batb":[[0,2.06,35.79],[1,2,9],[2,1.89,222]],"ltp":2.2,"tv":36.93,"id":40096579}]}]}
{"op":"mcm","clk":"11843020422","pt":1723577449006,"mc":[{"id":"1.231659919","rc":[{"batb":[[0,2.08,10],[1,2.06,35.79],[2,2,9]],"ltp":2.2,"tv":36.93,"id":40096579}]}]}
{"op":"mcm","clk":"11843021099","pt":1723577453015,"mc":[{"id":"1.231659919","rc":[{"batb":[[0,2.06,35.79],[1,2,9],[2,1.89,222]],"ltp":2.2,"tv":36.93,"id":40096579}]}]}
{"op":"mcm","clk":"11843022760","pt":1723577462208,"mc":[{"id":"1.231659919","rc":[{"batb":[[0,2.08,10],[1,2.06,35.79],[2,2,9]],"ltp":2.2,"tv":36.93,"id":40096579}]}]}
{"op":"mcm","clk":"11843023537","pt":1723577465903,"mc":[{"id":"1.231659919","rc":[{"batb":[[0,2.06,35.79],[1,2,9],[2,1.89,222]],"ltp":2.2,"tv":36.93,"id":40096579}]}]}
{"op":"mcm","clk":"11843028736","pt":1723577493263,"mc":[{"id":"1.231659919","rc":[{"batb":[[0,2.08,10],[1,2.06,35.79],[2,2,9]],"ltp":2.2,"tv":36.93,"id":40096579}]}]}
{"op":"mcm","clk":"11843029315","pt":1723577496559,"mc":[{"id":"1.231659919","rc":[{"batb":[[0,2.06,35.79],[1,2,9],[2,1.89,222]],"ltp":2.2,"tv":36.93,"id":40096579}]}]}
{"op":"mcm","clk":"11843034297","pt":1723577526684,"mc":[{"id":"1.231659919","rc":[{"batb":[[0,2.08,10],[1,2.06,35.79],[2,2,9]],"ltp":2.2,"tv":36.93,"id":40096579}]}]}
{"op":"mcm","clk":"11843034926","pt":1723577530378,"mc":[{"id":"1.231659919","rc":[{"batb":[[0,2.06,35.79],[1,2,9],[2,1.89,222]],"ltp":2.2,"tv":36.93,"id":40096579}]}]}
{"op":"mcm","clk":"11843037779","pt":1723577546600,"mc":[{"id":"1.231659919","rc":[{"batb":[[0,2.08,10],[1,2.06,35.79],[2,2,9]],"ltp":2.2,"tv":36.93,"id":40096579}]}]}
{"op":"mcm","clk":"11843038371","pt":1723577549894,"mc":[{"id":"1.231659919","rc":[{"batb":[[0,2.06,35.79],[1,2,9],[2,1.89,222]],"ltp":2.2,"tv":36.93,"id":40096579}]}]}
{"op":"mcm","clk":"11843041192","pt":1723577567041,"mc":[{"id":"1.231659919","rc":[{"batb":[[0,2.08,10],[1,2.06,35.79],[2,2,9]],"ltp":2.2,"tv":36.93,"id":40096579}]}]}
{"op":"mcm","clk":"11843041797","pt":1723577570467,"mc":[{"id":"1.231659919","rc":[{"batb":[[0,2.06,35.79],[1,2,9],[2,1.89,222]],"ltp":2.2,"tv":36.93,"id":40096579}]}]}
{"op":"mcm","clk":"11843052845","pt":1723577639212,"mc":[{"id":"1.231659919","rc":[{"batb":[[0,2.08,10],[1,2.06,35.79],[2,2,9]],"ltp":2.2,"tv":36.93,"id":40096579}]}]}
{"op":"mcm","clk":"11843053451","pt":1723577643132,"mc":[{"id":"1.231659919","rc":[{"batb":[[0,2.06,35.79],[1,2,9],[2,1.89,222]],"ltp":2.2,"tv":36.93,"id":40096579}]}]}
{"op":"mcm","clk":"11843055700","pt":1723577657461,"mc":[{"id":"1.231659919","rc":[{"batb":[[0,2.08,10],[1,2.06,35.79],[2,2,9]],"ltp":2.2,"tv":36.93,"id":40096579}]}]}
{"op":"mcm","clk":"11843056308","pt":1723577661555,"mc":[{"id":"1.231659919","rc":[{"batb":[[0,2.06,35.79],[1,2,9],[2,1.89,222]],"ltp":2.2,"tv":36.93,"id":40096579}]}]}
{"op":"mcm","clk":"11843056852","pt":1723577665167,"mc":[{"id":"1.231659919","rc":[{"batb":[[0,2.08,10],[1,2.06,35.79],[2,2,9]],"ltp":2.2,"tv":36.93,"id":40096579}]}]}
{"op":"mcm","clk":"11843057463","pt":1723577669447,"mc":[{"id":"1.231659919","rc":[{"batb":[[0,2.06,35.79],[1,2,9],[2,1.89,222]],"ltp":2.2,"tv":36.93,"id":40096579}]}]}
{"op":"mcm","clk":"11843058138","pt":1723577673972,"mc":[{"id":"1.231659919","rc":[{"batb":[[0,2.08,10],[1,2.06,35.79],[2,2,9]],"ltp":2.2,"tv":36.93,"id":40096579}]}]}
{"op":"mcm","clk":"11843058745","pt":1723577678087,"mc":[{"id":"1.231659919","rc":[{"batb":[[0,2.06,35.79],[1,2,9],[2,1.89,222]],"ltp":2.2,"tv":36.93,"id":40096579}]}]}
{"op":"mcm","clk":"11843063763","pt":1723577714400,"mc":[{"id":"1.231659919","rc":[{"batb":[[0,2.08,10],[1,2.06,35.79],[2,2,9]],"ltp":2.2,"tv":36.93,"id":40096579}]}]}
{"op":"mcm","clk":"11843064278","pt":1723577718229,"mc":[{"id":"1.231659919","rc":[{"batb":[[0,2.06,35.79],[1,2,9],[2,1.89,222]],"ltp":2.2,"tv":36.93,"id":40096579}]}]}
{"op":"mcm","clk":"11843075046","pt":1723577802510,"mc":[{"id":"1.231659919","rc":[{"batb":[[0,2.08,10],[1,2.06,35.79],[2,2,9]],"ltp":2.2,"tv":36.93,"id":40096579}]}]}
{"op":"mcm","clk":"11843075520","pt":1723577806402,"mc":[{"id":"1.231659919","rc":[{"batb":[[0,2.06,35.79],[1,2,9],[2,1.89,222]],"ltp":2.2,"tv":36.93,"id":40096579}]}]}
{"op":"mcm","clk":"11843077462","pt":1723577822235,"mc":[{"id":"1.231659919","rc":[{"batb":[[0,2.08,10],[1,2.06,35.79],[2,2,9]],"ltp":2.2,"tv":36.93,"id":40096579}]}]}
{"op":"mcm","clk":"11843077876","pt":1723577825535,"mc":[{"id":"1.231659919","rc":[{"batb":[[0,2.06,35.79],[1,2,9],[2,1.89,222]],"ltp":2.2,"tv":36.93,"id":40096579}]}]}
{"op":"mcm","clk":"11843081385","pt":1723577852161,"mc":[{"id":"1.231659919","rc":[{"batb":[[0,2.08,10],[1,2.06,35.79],[2,2,9]],"ltp":2.2,"tv":36.93,"id":40096579}]}]}
{"op":"mcm","clk":"11843081864","pt":1723577855967,"mc":[{"id":"1.231659919","rc":[{"batb":[[0,2.06,35.79],[1,2,9],[2,1.89,222]],"ltp":2.2,"tv":36.93,"id":40096579}]}]}
{"op":"mcm","clk":"11843082957","pt":1723577864964,"mc":[{"id":"1.231659919","rc":[{"batb":[[0,2.08,10],[1,2.06,35.79],[2,2,9]],"ltp":2.2,"tv":36.93,"id":40096579}]}]}
{"op":"mcm","clk":"11843083424","pt":1723577868656,"mc":[{"id":"1.231659919","rc":[{"batb":[[0,2.06,35.79],[1,2,9],[2,1.89,222]],"ltp":2.2,"tv":36.93,"id":40096579}]}]}
{"op":"mcm","clk":"11843084211","pt":1723577875673,"mc":[{"id":"1.231659919","rc":[{"batb":[[0,2.08,10],[1,2.06,35.79],[2,2,9]],"ltp":2.2,"tv":36.93,"id":40096579}]}]}
{"op":"mcm","clk":"11843084676","pt":1723577879985,"mc":[{"id":"1.231659919","rc":[{"batb":[[0,2.06,35.79],[1,2,9],[2,1.89,222]],"ltp":2.2,"tv":36.93,"id":40096579}]}]}
{"op":"mcm","clk":"11843087009","pt":1723577898410,"mc":[{"id":"1.231659919","rc":[{"batb":[[0,2.08,10],[1,2.06,35.79],[2,2,9]],"ltp":2.2,"tv":36.93,"id":40096579}]}]}
{"op":"mcm","clk":"11843087495","pt":1723577902521,"mc":[{"id":"1.231659919","rc":[{"batb":[[0,2.06,35.79],[1,2,9],[2,1.89,222]],"ltp":2.2,"tv":36.93,"id":40096579}]}]}
{"op":"mcm","clk":"11843088226","pt":1723577908816,"mc":[{"id":"1.231659919","rc":[{"batb":[[0,2.08,10],[1,2.06,35.79],[2,2,9]],"ltp":2.2,"tv":36.93,"id":40096579}]}]}
{"op":"mcm","clk":"11843088616","pt":1723577912213,"mc":[{"id":"1.231659919","rc":[{"batb":[[0,2.06,35.79],[1,2,9],[2,1.89,222]],"ltp":2.2,"tv":36.93,"id":40096579}]}]}
{"op":"mcm","clk":"11843089900","pt":1723577923755,"mc":[{"id":"1.231659919","rc":[{"batb":[[0,2.08,10],[1,2.06,35.79],[2,2,9]],"ltp":2.2,"tv":36.93,"id":40096579}]}]}
{"op":"mcm","clk":"11843090331","pt":1723577927347,"mc":[{"id":"1.231659919","rc":[{"batb":[[0,2.06,35.79],[1,2,9],[2,1.89,222]],"ltp":2.2,"tv":36.93,"id":40096579}]}]}
{"op":"mcm","clk":"11843091530","pt":1723577937772,"mc":[{"id":"1.231659919","rc":[{"batb":[[0,2.08,10],[1,2.06,35.79],[2,2,9]],"ltp":2.2,"tv":36.93,"id":40096579}]}]}
{"op":"mcm","clk":"11843092223","pt":1723577943137,"mc":[{"id":"1.231659919","rc":[{"batb":[[0,2.06,35.79],[1,2,9],[2,1.89,222]],"ltp":2.2,"tv":36.93,"id":40096579}]}]}
{"op":"mcm","clk":"11843092909","pt":1723577948507,"mc":[{"id":"1.231659919","rc":[{"batb":[[0,2.08,10],[1,2.06,35.79],[2,2,9]],"ltp":2.2,"tv":36.93,"id":40096579}]}]}
{"op":"mcm","clk":"11843093426","pt":1723577952724,"mc":[{"id":"1.231659919","rc":[{"batb":[[0,2.06,35.79],[1,2,9],[2,1.89,222]],"ltp":2.2,"tv":36.93,"id":40096579}]}]}
{"op":"mcm","clk":"11843094036","pt":1723577957527,"mc":[{"id":"1.231659919","rc":[{"batb":[[0,2.08,10],[1,2.06,35.79],[2,2,9]],"ltp":2.2,"tv":36.93,"id":40096579}]}]}
{"op":"mcm","clk":"11843094563","pt":1723577961424,"mc":[{"id":"1.231659919","rc":[{"batb":[[0,2.06,35.79],[1,2,9],[2,1.89,222]],"ltp":2.2,"tv":36.93,"id":40096579}]}]}
{"op":"mcm","clk":"11843096659","pt":1723577978049,"mc":[{"id":"1.231659919","rc":[{"batb":[[0,2.08,10],[1,2.06,35.79],[2,2,9]],"ltp":2.2,"tv":36.93,"id":40096579}]}]}
{"op":"mcm","clk":"11843097058","pt":1723577981748,"mc":[{"id":"1.231659919","rc":[{"batb":[[0,2.06,35.79],[1,2,9],[2,1.89,222]],"ltp":2.2,"tv":36.93,"id":40096579}]}]}
{"op":"mcm","clk":"11843098454","pt":1723577993168,"mc":[{"id":"1.231659919","rc":[{"batb":[[0,2.08,10],[1,2.06,35.79],[2,2,9]],"ltp":2.2,"tv":36.93,"id":40096579}]}]}
{"op":"mcm","clk":"11843098853","pt":1723577996493,"mc":[{"id":"1.231659919","rc":[{"batb":[[0,2.06,35.79],[1,2,9],[2,1.89,222]],"ltp":2.2,"tv":36.93,"id":40096579}]}]}
{"op":"mcm","clk":"11843099246","pt":1723577999763,"mc":[{"id":"1.231659919","rc":[{"batb":[[0,2.08,10],[1,2.06,35.79],[2,2,9]],"ltp":2.2,"tv":36.93,"id":40096579}]}]}
{"op":"mcm","clk":"11843099652","pt":1723578003308,"mc":[{"id":"1.231659919","rc":[{"batb":[[0,2.06,35.79],[1,2,9],[2,1.89,222]],"ltp":2.2,"tv":36.93,"id":40096579}]}]}
{"op":"mcm","clk":"11843100085","pt":1723578006994,"mc":[{"id":"1.231659919","rc":[{"batb":[[0,2.08,10],[1,2.06,35.79],[2,2,9]],"ltp":2.2,"tv":36.93,"id":40096579}]}]}
{"op":"mcm","clk":"11843100604","pt":1723578011309,"mc":[{"id":"1.231659919","rc":[{"batb":[[0,2.06,35.79],[1,2,9],[2,1.89,222]],"ltp":2.2,"tv":36.93,"id":40096579}]}]}
{"op":"mcm","clk":"11843100900","pt":1723578013812,"mc":[{"id":"1.231659919","rc":[{"batb":[[0,2.08,10],[1,2.06,35.79],[2,2,9]],"ltp":2.2,"tv":36.93,"id":40096579}]}]}
{"op":"mcm","clk":"11843101443","pt":1723578017782,"mc":[{"id":"1.231659919","rc":[{"batb":[[0,2.06,35.79],[1,2,9],[2,1.89,222]],"ltp":2.2,"tv":36.93,"id":40096579}]}]}
{"op":"mcm","clk":"11843101802","pt":1723578020807,"mc":[{"id":"1.231659919","rc":[{"batb":[[0,2.08,10],[1,2.06,35.79],[2,2,9]],"ltp":2.2,"tv":36.93,"id":40096579}]}]}
{"op":"mcm","clk":"11843102296","pt":1723578024605,"mc":[{"id":"1.231659919","rc":[{"batb":[[0,2.06,35.79],[1,2,9],[2,1.89,222]],"ltp":2.2,"tv":36.93,"id":40096579}]}]}
{"op":"mcm","clk":"11843102741","pt":1723578028095,"mc":[{"id":"1.231659919","rc":[{"batb":[[0,2.08,10],[1,2.06,35.79],[2,2,9]],"ltp":2.2,"tv":36.93,"id":40096579}]}]}
{"op":"mcm","clk":"11843103263","pt":1723578032003,"mc":[{"id":"1.231659919","rc":[{"batb":[[0,2.06,35.79],[1,2,9],[2,1.89,222]],"ltp":2.2,"tv":36.93,"id":40096579}]}]}
{"op":"mcm","clk":"11843103807","pt":1723578036148,"mc":[{"id":"1.231659919","rc":[{"batb":[[0,2.08,10],[1,2.06,35.79],[2,2,9]],"ltp":2.2,"tv":36.93,"id":40096579}]}]}
{"op":"mcm","clk":"11843104316","pt":1723578039929,"mc":[{"id":"1.231659919","rc":[{"batb":[[0,2.06,35.79],[1,2,9],[2,1.89,222]],"ltp":2.2,"tv":36.93,"id":40096579}]}]}
{"op":"mcm","clk":"11843104705","pt":1723578042738,"mc":[{"id":"1.231659919","rc":[{"batb":[[0,2.08,10],[1,2.06,35.79],[2,2,9]],"ltp":2.2,"tv":36.93,"id":40096579}]}]}
{"op":"mcm","clk":"11843105190","pt":1723578046345,"mc":[{"id":"1.231659919","rc":[{"batb":[[0,2.06,35.79],[1,2,9],[2,1.89,222]],"ltp":2.2,"tv":36.93,"id":40096579}]}]}
{"op":"mcm","clk":"11843106124","pt":1723578053632,"mc":[{"id":"1.231659919","rc":[{"batb":[[0,2.08,10],[1,2.06,35.79],[2,2,9]],"ltp":2.2,"tv":36.93,"id":40096579}]}]}
{"op":"mcm","clk":"11843106629","pt":1723578057854,"mc":[{"id":"1.231659919","rc":[{"batb":[[0,2.06,35.79],[1,2,9],[2,1.89,222]],"ltp":2.2,"tv":36.93,"id":40096579}]}]}
{"op":"mcm","clk":"11843107313","pt":1723578063285,"mc":[{"id":"1.231659919","rc":[{"batb":[[0,2.08,10],[1,2.06,35.79],[2,2,9]],"ltp":2.2,"tv":36.93,"id":40096579}]}]}
{"op":"mcm","clk":"11843107746","pt":1723578066882,"mc":[{"id":"1.231659919","rc":[{"batb":[[0,2.06,35.79],[1,2,9],[2,1.89,222]],"ltp":2.2,"tv":36.93,"id":40096579}]}]}
{"op":"mcm","clk":"11843108154","pt":1723578069554,"mc":[{"id":"1.231659919","rc":[{"batb":[[0,2.08,10],[1,2.06,35.79],[2,2,9]],"ltp":2.2,"tv":36.93,"id":40096579}]}]}
{"op":"mcm","clk":"11843108595","pt":1723578073416,"mc":[{"id":"1.231659919","rc":[{"batb":[[0,2.06,35.79],[1,2,9],[2,1.89,222]],"ltp":2.2,"tv":36.93,"id":40096579}]}]}
{"op":"mcm","clk":"11843108938","pt":1723578076061,"mc":[{"id":"1.231659919","rc":[{"batb":[[0,2.08,10],[1,2.06,35.79],[2,2,9]],"ltp":2.2,"tv":36.93,"id":40096579}]}]}
{"op":"mcm","clk":"11843109415","pt":1723578079877,"mc":[{"id":"1.231659919","rc":[{"batb":[[0,2.06,35.79],[1,2,9],[2,1.89,222]],"ltp":2.2,"tv":36.93,"id":40096579}]}]}
{"op":"mcm","clk":"11843109776","pt":1723578082688,"mc":[{"id":"1.231659919","rc":[{"batb":[[0,2.08,10],[1,2.06,35.79],[2,2,9]],"ltp":2.2,"tv":36.93,"id":40096579}]}]}
{"op":"mcm","clk":"11843110283","pt":1723578086380,"mc":[{"id":"1.231659919","rc":[{"batb":[[0,2.06,35.79],[1,2,9],[2,1.89,222]],"ltp":2.2,"tv":36.93,"id":40096579}]}]}
{"op":"mcm","clk":"11843110793","pt":1723578090186,"mc":[{"id":"1.231659919","rc":[{"batb":[[0,2.08,10],[1,2.06,35.79],[2,2,9]],"ltp":2.2,"tv":36.93,"id":40096579}]}]}
{"op":"mcm","clk":"11843111280","pt":1723578094121,"mc":[{"id":"1.231659919","rc":[{"batb":[[0,2.06,35.79],[1,2,9],[2,1.89,222]],"ltp":2.2,"tv":36.93,"id":40096579}]}]}
{"op":"mcm","clk":"11843111926","pt":1723578099329,"mc":[{"id":"1.231659919","rc":[{"batb":[[0,2.08,10],[1,2.06,35.79],[2,2,9]],"ltp":2.2,"tv":36.93,"id":40096579}]}]}
{"op":"mcm","clk":"11843112436","pt":1723578103116,"mc":[{"id":"1.231659919","rc":[{"batb":[[0,2.06,35.79],[1,2,9],[2,1.89,222]],"ltp":2.2,"tv":36.93,"id":40096579}]}]}
{"op":"mcm","clk":"11843112747","pt":1723578106074,"mc":[{"id":"1.231659919","rc":[{"batb":[[0,2.08,10],[1,2.06,35.79],[2,2,9]],"ltp":2.2,"tv":36.93,"id":40096579}]}]}
{"op":"mcm","clk":"11843113247","pt":1723578109931,"mc":[{"id":"1.231659919","rc":[{"batb":[[0,2.06,35.79],[1,2,9],[2,1.89,222]],"ltp":2.2,"tv":36.93,"id":40096579}]}]}
{"op":"mcm","clk":"11843114265","pt":1723578117638,"mc":[{"id":"1.231659919","rc":[{"batb":[[0,2.08,10],[1,2.06,35.79],[2,2,9]],"ltp":2.2,"tv":36.93,"id":40096579}]}]}
{"op":"mcm","clk":"11843114782","pt":1723578121343,"mc":[{"id":"1.231659919","rc":[{"batb":[[0,2.06,35.79],[1,2,9],[2,1.89,222]],"ltp":2.2,"tv":36.93,"id":40096579}]}]}
{"op":"mcm","clk":"11843115426","pt":1723578125945,"mc":[{"id":"1.231659919","rc":[{"batb":[[0,2.08,10],[1,2.06,35.79],[2,2,9]],"ltp":2.2,"tv":36.93,"id":40096579}]}]}
{"op":"mcm","clk":"11843115973","pt":1723578129646,"mc":[{"id":"1.231659919","rc":[{"batb":[[0,2.06,35.79],[1,2,9],[2,1.89,222]],"ltp":2.2,"tv":36.93,"id":40096579}]}]}
{"op":"mcm","clk":"11843116982","pt":1723578136893,"mc":[{"id":"1.231659919","rc":[{"batb":[[0,2.08,10],[1,2.06,35.79],[2,2,9]],"ltp":2.2,"tv":36.93,"id":40096579}]}]}
{"op":"mcm","clk":"11843117442","pt":1723578140485,"mc":[{"id":"1.231659919","rc":[{"batb":[[0,2.06,35.79],[1,2,9],[2,1.89,222]],"ltp":2.2,"tv":36.93,"id":40096579}]}]}
{"op":"mcm","clk":"11843117809","pt":1723578143149,"mc":[{"id":"1.231659919","rc":[{"batb":[[0,2.08,10],[1,2.06,35.79],[2,2,9]],"ltp":2.2,"tv":36.93,"id":40096579}]}]}
{"op":"mcm","clk":"11843118327","pt":1723578146735,"mc":[{"id":"1.231659919","rc":[{"batb":[[0,2.06,35.79],[1,2,9],[2,1.89,222]],"ltp":2.2,"tv":36.93,"id":40096579}]}]}
{"op":"mcm","clk":"11843119332","pt":1723578154334,"mc":[{"id":"1.231659919","rc":[{"batb":[[0,2.08,10],[1,2.06,35.79],[2,2,9]],"ltp":2.2,"tv":36.93,"id":40096579}]}]}
{"op":"mcm","clk":"11843119855","pt":1723578158067,"mc":[{"id":"1.231659919","rc":[{"batb":[[0,2.06,35.79],[1,2,9],[2,1.89,222]],"ltp":2.2,"tv":36.93,"id":40096579}]}]}
{"op":"mcm","clk":"11843120219","pt":1723578160771,"mc":[{"id":"1.231659919","rc":[{"batb":[[0,2.08,10],[1,2.06,35.79],[2,2,9]],"ltp":2.2,"tv":36.93,"id":40096579}]}]}
{"op":"mcm","clk":"11843120689","pt":1723578164676,"mc":[{"id":"1.231659919","rc":[{"batb":[[0,2.06,35.79],[1,2,9],[2,1.89,222]],"ltp":2.2,"tv":36.93,"id":40096579}]}]}
{"op":"mcm","clk":"11843121418","pt":1723578170158,"mc":[{"id":"1.231659919","rc":[{"batb":[[0,2.08,10],[1,2.06,35.79],[2,2,9]],"ltp":2.2,"tv":36.93,"id":40096579}]}]}
{"op":"mcm","clk":"11843121864","pt":1723578173779,"mc":[{"id":"1.231659919","rc":[{"batb":[[0,2.06,35.79],[1,2,9],[2,1.89,222]],"ltp":2.2,"tv":36.93,"id":40096579}]}]}
{"op":"mcm","clk":"11843130318","pt":1723578176865,"mc":[{"id":"1.231659919","rc":[{"batb":[[0,2.08,10],[1,2.06,35.79],[2,2,9]],"ltp":2.2,"tv":36.93,"id":40096579}]}]}
{"op":"mcm","clk":"11843130839","pt":1723578181009,"mc":[{"id":"1.231659919","rc":[{"batb":[[0,2.06,35.79],[1,2,9],[2,1.89,222]],"ltp":2.2,"tv":36.93,"id":40096579}]}]}
{"op":"mcm","clk":"11843131184","pt":1723578183787,"mc":[{"id":"1.231659919","rc":[{"batb":[[0,2.08,10],[1,2.06,35.79],[2,2,9]],"ltp":2.2,"tv":36.93,"id":40096579}]}]}
{"op":"mcm","clk":"11843131670","pt":1723578187769,"mc":[{"id":"1.231659919","rc":[{"batb":[[0,2.06,35.79],[1,2,9],[2,1.89,222]],"ltp":2.2,"tv":36.93,"id":40096579}]}]}
{"op":"mcm","clk":"11843132020","pt":1723578190476,"mc":[{"id":"1.231659919","rc":[{"batb":[[0,2.08,10],[1,2.06,35.79],[2,2,9]],"ltp":2.2,"tv":36.93,"id":40096579}]}]}
{"op":"mcm","clk":"11843132431","pt":1723578193898,"mc":[{"id":"1.231659919","rc":[{"batb":[[0,2.06,35.79],[1,2,9],[2,1.89,222]],"ltp":2.2,"tv":36.93,"id":40096579}]}]}
{"op":"mcm","clk":"11843132953","pt":1723578198399,"mc":[{"id":"1.231659919","rc":[{"batb":[[0,2.08,10],[1,2.06,35.79],[2,2,9]],"ltp":2.2,"tv":36.93,"id":40096579}]}]}
{"op":"mcm","clk":"11843133390","pt":1723578202077,"mc":[{"id":"1.231659919","rc":[{"batb":[[0,2.06,35.79],[1,2,9],[2,1.89,222]],"ltp":2.2,"tv":36.93,"id":40096579}]}]}
{"op":"mcm","clk":"11843134196","pt":1723578208677,"mc":[{"id":"1.231659919","rc":[{"batb":[[0,2.08,10],[1,2.06,35.79],[2,2,9]],"ltp":2.2,"tv":36.93,"id":40096579}]}]}
{"op":"mcm","clk":"11843134655","pt":1723578212309,"mc":[{"id":"1.231659919","rc":[{"batb":[[0,2.06,35.79],[1,2,9],[2,1.89,222]],"ltp":2.2,"tv":36.93,"id":40096579}]}]}
{"op":"mcm","clk":"11843134989","pt":1723578215126,"mc":[{"id":"1.231659919","rc":[{"batb":[[0,2.08,10],[1,2.06,35.79],[2,2,9]],"ltp":2.2,"tv":36.93,"id":40096579}]}]}
{"op":"mcm","clk":"11843135437","pt":1723578218932,"mc":[{"id":"1.231659919","rc":[{"batb":[[0,2.06,35.79],[1,2,9],[2,1.89,222]],"ltp":2.2,"tv":36.93,"id":40096579}]}]}
{"op":"mcm","clk":"11843135747","pt":1723578221519,"mc":[{"id":"1.231659919","rc":[{"batb":[[0,2.08,10],[1,2.06,35.79],[2,2,9]],"ltp":2.2,"tv":36.93,"id":40096579}]}]}
{"op":"mcm","clk":"11843136192","pt":1723578225323,"mc":[{"id":"1.231659919","rc":[{"batb":[[0,2.06,35.79],[1,2,9],[2,1.89,222]],"ltp":2.2,"tv":36.93,"id":40096579}]}]}
{"op":"mcm","clk":"11843136730","pt":1723578230258,"mc":[{"id":"1.231659919","rc":[{"batb":[[0,2.08,10],[1,2.06,35.79],[2,2,9]],"ltp":2.2,"tv":36.93,"id":40096579}]}]}
{"op":"mcm","clk":"11843137180","pt":1723578234159,"mc":[{"id":"1.231659919","rc":[{"batb":[[0,2.06,35.79],[1,2,9],[2,1.89,222]],"ltp":2.2,"tv":36.93,"id":40096579}]}]}
{"op":"mcm","clk":"11843137548","pt":1723578237125,"mc":[{"id":"1.231659919","rc":[{"batb":[[0,2.08,10],[1,2.06,35.79],[2,2,9]],"ltp":2.2,"tv":36.93,"id":40096579}]}]}
{"op":"mcm","clk":"11843138129","pt":1723578241453,"mc":[{"id":"1.231659919","rc":[{"batb":[[0,2.06,35.79],[1,2,9],[2,1.89,222]],"ltp":2.2,"tv":36.93,"id":40096579}]}]}
{"op":"mcm","clk":"11843138735","pt":1723578246028,"mc":[{"id":"1.231659919","rc":[{"batb":[[0,2.08,10],[1,2.06,35.79],[2,2,9]],"ltp":2.2,"tv":36.93,"id":40096579}]}]}
{"op":"mcm","clk":"11843139291","pt":1723578250151,"mc":[{"id":"1.231659919","rc":[{"batb":[[0,2.06,35.79],[1,2,9],[2,1.89,222]],"ltp":2.2,"tv":36.93,"id":40096579}]}]}
{"op":"mcm","clk":"11843139426","pt":1723578251237,"mc":[{"id":"1.231659919","rc":[{"trd":[[1.82,20]],"batb":[[0,1.82,36.27]],"ltp":1.82,"tv":148.04,"id":40096581}],"tv":184.97}]}
{"op":"mcm","clk":"11843139647","pt":1723578252963,"mc":[{"id":"1.231659919","rc":[{"batb":[[0,2.08,10],[1,2.06,35.79],[2,2,9]],"ltp":2.2,"tv":36.93,"id":40096579},{"batb":[[0,1.82,46.27]],"ltp":1.82,"tv":148.04,"id":40096581}]}]}
{"op":"mcm","clk":"11843140136","pt":1723578256653,"mc":[{"id":"1.231659919","rc":[{"batb":[[0,2.06,35.79],[1,2,9],[2,1.89,222]],"ltp":2.2,"tv":36.93,"id":40096579}]}]}
{"op":"mcm","clk":"11843140716","pt":1723578261393,"mc":[{"id":"1.231659919","rc":[{"batb":[[0,2.08,10],[1,2.06,35.79],[2,2,9]],"ltp":2.2,"tv":36.93,"id":40096579}]}]}
{"op":"mcm","clk":"11843141183","pt":1723578264958,"mc":[{"id":"1.231659919","rc":[{"batb":[[0,2.06,35.79],[1,2,9],[2,1.89,222]],"ltp":2.2,"tv":36.93,"id":40096579}]}]}
{"op":"mcm","clk":"11843141615","pt":1723578268392,"mc":[{"id":"1.231659919","rc":[{"batb":[[0,2.08,10],[1,2.06,35.79],[2,2,9]],"ltp":2.2,"tv":36.93,"id":40096579}]}]}
{"op":"mcm","clk":"11843142065","pt":1723578271771,"mc":[{"id":"1.231659919","rc":[{"batb":[[0,2.06,35.79],[1,2,9],[2,1.89,222]],"ltp":2.2,"tv":36.93,"id":40096579}]}]}
{"op":"mcm","clk":"11843142663","pt":1723578276667,"mc":[{"id":"1.231659919","rc":[{"batb":[[0,2.08,10],[1,2.06,35.79],[2,2,9]],"ltp":2.2,"tv":36.93,"id":40096579}]}]}
{"op":"mcm","clk":"11843143139","pt":1723578280678,"mc":[{"id":"1.231659919","rc":[{"batb":[[0,2.06,35.79],[1,2,9],[2,1.89,222]],"ltp":2.2,"tv":36.93,"id":40096579}]}]}
{"op":"mcm","clk":"11843143984","pt":1723578286790,"mc":[{"id":"1.231659919","rc":[{"batb":[[0,2.08,10],[1,2.06,35.79],[2,2,9]],"ltp":2.2,"tv":36.93,"id":40096579}]}]}
{"op":"mcm","clk":"11843144514","pt":1723578290579,"mc":[{"id":"1.231659919","rc":[{"batb":[[0,2.06,35.79],[1,2,9],[2,1.89,222]],"ltp":2.2,"tv":36.93,"id":40096579}]}]}
{"op":"mcm","clk":"11843145091","pt":1723578294895,"mc":[{"id":"1.231659919","rc":[{"batb":[[0,2.08,10],[1,2.06,35.79],[2,2,9]],"ltp":2.2,"tv":36.93,"id":40096579}]}]}
{"op":"mcm","clk":"11843145746","pt":1723578299694,"mc":[{"id":"1.231659919","rc":[{"batb":[[0,2.06,35.79],[1,2,9],[2,1.89,222]],"ltp":2.2,"tv":36.93,"id":40096579}]}]}
{"op":"mcm","clk":"11843146456","pt":1723578304977,"mc":[{"id":"1.231659919","rc":[{"batb":[[0,2.08,10],[1,2.06,35.79],[2,2,9]],"ltp":2.2,"tv":36.93,"id":40096579}]}]}
{"op":"mcm","clk":"11843146905","pt":1723578308711,"mc":[{"id":"1.231659919","rc":[{"batb":[[0,2.06,35.79],[1,2,9],[2,1.89,222]],"ltp":2.2,"tv":36.93,"id":40096579}]}]}
{"op":"mcm","clk":"11843147496","pt":1723578313510,"mc":[{"id":"1.231659919","rc":[{"batb":[[0,2.08,10],[1,2.06,35.79],[2,2,9]],"ltp":2.2,"tv":36.93,"id":40096579}]}]}
{"op":"mcm","clk":"11843148028","pt":1723578317313,"mc":[{"id":"1.231659919","rc":[{"batb":[[0,2.06,35.79],[1,2,9],[2,1.89,222]],"ltp":2.2,"tv":36.93,"id":40096579}]}]}
{"op":"mcm","clk":"11843148361","pt":1723578320023,"mc":[{"id":"1.231659919","rc":[{"batb":[[0,2.08,10],[1,2.06,35.79],[2,2,9]],"ltp":2.2,"tv":36.93,"id":40096579}]}]}
{"op":"mcm","clk":"11843148827","pt":1723578323919,"mc":[{"id":"1.231659919","rc":[{"batb":[[0,2.06,35.79],[1,2,9],[2,1.89,222]],"ltp":2.2,"tv":36.93,"id":40096579}]}]}
{"op":"mcm","clk":"11843149490","pt":1723578329230,"mc":[{"id":"1.231659919","rc":[{"batb":[[0,2.08,10],[1,2.06,35.79],[2,2,9]],"ltp":2.2,"tv":36.93,"id":40096579}]}]}
{"op":"mcm","clk":"11843149922","pt":1723578332822,"mc":[{"id":"1.231659919","rc":[{"batb":[[0,2.06,35.79],[1,2,9],[2,1.89,222]],"ltp":2.2,"tv":36.93,"id":40096579}]}]}
{"op":"mcm","clk":"11843150210","pt":1723578335267,"mc":[{"id":"1.231659919","rc":[{"batb":[[0,2.08,10],[1,2.06,35.79],[2,2,9]],"ltp":2.2,"tv":36.93,"id":40096579}]}]}
{"op":"mcm","clk":"11843150631","pt":1723578339243,"mc":[{"id":"1.231659919","rc":[{"batb":[[0,2.06,35.79],[1,2,9],[2,1.89,222]],"ltp":2.2,"tv":36.93,"id":40096579}]}]}
{"op":"mcm","clk":"11843150896","pt":1723578341741,"mc":[{"id":"1.231659919","rc":[{"batb":[[0,2.08,10],[1,2.06,35.79],[2,2,9]],"ltp":2.2,"tv":36.93,"id":40096579}]}]}
{"op":"mcm","clk":"11843151300","pt":1723578345236,"mc":[{"id":"1.231659919","rc":[{"batb":[[0,2.06,35.79],[1,2,9],[2,1.89,222]],"ltp":2.2,"tv":36.93,"id":40096579}]}]}
{"op":"mcm","clk":"11843151616","pt":1723578348250,"mc":[{"id":"1.231659919","rc":[{"batb":[[0,2.08,10],[1,2.06,35.79],[2,2,9]],"ltp":2.2,"tv":36.93,"id":40096579}]}]}
{"op":"mcm","clk":"11843151986","pt":1723578351878,"mc":[{"id":"1.231659919","rc":[{"batb":[[0,2.06,35.79],[1,2,9],[2,1.89,222]],"ltp":2.2,"tv":36.93,"id":40096579}]}]}
{"op":"mcm","clk":"11843152368","pt":1723578355460,"mc":[{"id":"1.231659919","rc":[{"batb":[[0,2.08,10],[1,2.06,35.79],[2,2,9]],"ltp":2.2,"tv":36.93,"id":40096579}]}]}
{"op":"mcm","clk":"11843152766","pt":1723578359464,"mc":[{"id":"1.231659919","rc":[{"batb":[[0,2.06,35.79],[1,2,9],[2,1.89,222]],"ltp":2.2,"tv":36.93,"id":40096579}]}]}
{"op":"mcm","clk":"11843153112","pt":1723578362786,"mc":[{"id":"1.231659919","rc":[{"batb":[[0,2.08,10],[1,2.06,35.79],[2,2,9]],"ltp":2.2,"tv":36.93,"id":40096579}]}]}
{"op":"mcm","clk":"11843153513","pt":1723578366270,"mc":[{"id":"1.231659919","rc":[{"batb":[[0,2.06,35.79],[1,2,9],[2,1.89,222]],"ltp":2.2,"tv":36.93,"id":40096579}]}]}
{"op":"mcm","clk":"11843153838","pt":1723578369281,"mc":[{"id":"1.231659919","rc":[{"batb":[[0,2.08,10],[1,2.06,35.79],[2,2,9]],"ltp":2.2,"tv":36.93,"id":40096579}]}]}
{"op":"mcm","clk":"11843154202","pt":1723578372775,"mc":[{"id":"1.231659919","rc":[{"batb":[[0,2.06,35.79],[1,2,9],[2,1.89,222]],"ltp":2.2,"tv":36.93,"id":40096579}]}]}
{"op":"mcm","clk":"11843154741","pt":1723578376884,"mc":[{"id":"1.231659919","rc":[{"batb":[[0,2.08,10],[1,2.06,35.79],[2,2,9]],"ltp":2.2,"tv":36.93,"id":40096579}]}]}
{"op":"mcm","clk":"11843155154","pt":1723578380684,"mc":[{"id":"1.231659919","rc":[{"batb":[[0,2.06,35.79],[1,2,9],[2,1.89,222]],"ltp":2.2,"tv":36.93,"id":40096579}]}]}
{"op":"mcm","clk":"11843155932","pt":1723578387229,"mc":[{"id":"1.231659919","rc":[{"batb":[[0,2.08,10],[1,2.06,35.79],[2,2,9]],"ltp":2.2,"tv":36.93,"id":40096579}]}]}
{"op":"mcm","clk":"11843156379","pt":1723578390626,"mc":[{"id":"1.231659919","rc":[{"batb":[[0,2.06,35.79],[1,2,9],[2,1.89,222]],"ltp":2.2,"tv":36.93,"id":40096579}]}]}
{"op":"mcm","clk":"11843156854","pt":1723578394337,"mc":[{"id":"1.231659919","rc":[{"batb":[[0,2.08,10],[1,2.06,35.79],[2,2,9]],"ltp":2.2,"tv":36.93,"id":40096579}]}]}
{"op":"mcm","clk":"11843157339","pt":1723578398198,"mc":[{"id":"1.231659919","rc":[{"batb":[[0,2.06,35.79],[1,2,9],[2,1.89,222]],"ltp":2.2,"tv":36.93,"id":40096579}]}]}
{"op":"mcm","clk":"11843157666","pt":1723578401056,"mc":[{"id":"1.231659919","rc":[{"batb":[[0,2.08,10],[1,2.06,35.79],[2,2,9]],"ltp":2.2,"tv":36.93,"id":40096579}]}]}
{"op":"mcm","clk":"11843158055","pt":1723578404654,"mc":[{"id":"1.231659919","rc":[{"batb":[[0,2.06,35.79],[1,2,9],[2,1.89,222]],"ltp":2.2,"tv":36.93,"id":40096579}]}]}
{"op":"mcm","clk":"11843158573","pt":1723578409285,"mc":[{"id":"1.231659919","rc":[{"batb":[[0,2.08,10],[1,2.06,35.79],[2,2,9]],"ltp":2.2,"tv":36.93,"id":40096579}]}]}
{"op":"mcm","clk":"11843159025","pt":1723578412883,"mc":[{"id":"1.231659919","rc":[{"batb":[[0,2.06,35.79],[1,2,9],[2,1.89,222]],"ltp":2.2,"tv":36.93,"id":40096579}]}]}
{"op":"mcm","clk":"11843159434","pt":1723578415919,"mc":[{"id":"1.231659919","rc":[{"batb":[[0,2.08,10],[1,2.06,35.79],[2,2,9]],"ltp":2.2,"tv":36.93,"id":40096579}]}]}
{"op":"mcm","clk":"11843159887","pt":1723578419798,"mc":[{"id":"1.231659919","rc":[{"batb":[[0,2.06,35.79],[1,2,9],[2,1.89,222]],"ltp":2.2,"tv":36.93,"id":40096579}]}]}
{"op":"mcm","clk":"11843160307","pt":1723578422931,"mc":[{"id":"1.231659919","rc":[{"batb":[[0,2.08,10],[1,2.06,35.79],[2,2,9]],"ltp":2.2,"tv":36.93,"id":40096579}]}]}
{"op":"mcm","clk":"11843160755","pt":1723578426236,"mc":[{"id":"1.231659919","rc":[{"batb":[[0,2.06,35.79],[1,2,9],[2,1.89,222]],"ltp":2.2,"tv":36.93,"id":40096579}]}]}
{"op":"mcm","clk":"11843161227","pt":1723578429462,"mc":[{"id":"1.231659919","rc":[{"batb":[[0,2.08,10],[1,2.06,35.79],[2,2,9]],"ltp":2.2,"tv":36.93,"id":40096579}]}]}
{"op":"mcm","clk":"11843161767","pt":1723578433472,"mc":[{"id":"1.231659919","rc":[{"batb":[[0,2.06,35.79],[1,2,9],[2,1.89,222]],"ltp":2.2,"tv":36.93,"id":40096579}]}]}
{"op":"mcm","clk":"11843162223","pt":1723578436364,"mc":[{"id":"1.231659919","rc":[{"batb":[[0,2.08,10],[1,2.06,35.79],[2,2,9]],"ltp":2.2,"tv":36.93,"id":40096579}]}]}
{"op":"mcm","clk":"11843162676","pt":1723578439977,"mc":[{"id":"1.231659919","rc":[{"batb":[[0,2.06,35.79],[1,2,9],[2,1.89,222]],"ltp":2.2,"tv":36.93,"id":40096579}]}]}
{"op":"mcm","clk":"11843163079","pt":1723578443066,"mc":[{"id":"1.231659919","rc":[{"batb":[[0,2.08,10],[1,2.06,35.79],[2,2,9]],"ltp":2.2,"tv":36.93,"id":40096579}]}]}
{"op":"mcm","clk":"11843163520","pt":1723578446900,"mc":[{"id":"1.231659919","rc":[{"batb":[[0,2.06,35.79],[1,2,9],[2,1.89,222]],"ltp":2.2,"tv":36.93,"id":40096579}]}]}
{"op":"mcm","clk":"11843164084","pt":1723578451094,"mc":[{"id":"1.231659919","rc":[{"batb":[[0,2.08,10],[1,2.06,35.79],[2,2,9]],"ltp":2.2,"tv":36.93,"id":40096579}]}]}
{"op":"mcm","clk":"11843164585","pt":1723578455202,"mc":[{"id":"1.231659919","rc":[{"batb":[[0,2.06,35.79],[1,2,9],[2,1.89,222]],"ltp":2.2,"tv":36.93,"id":40096579}]}]}
{"op":"mcm","clk":"11843164902","pt":1723578457497,"mc":[{"id":"1.231659919","rc":[{"batb":[[0,2.08,10],[1,2.06,35.79],[2,2,9]],"ltp":2.2,"tv":36.93,"id":40096579}]}]}
{"op":"mcm","clk":"11843165339","pt":1723578460905,"mc":[{"id":"1.231659919","rc":[{"batb":[[0,2.06,35.79],[1,2,9],[2,1.89,222]],"ltp":2.2,"tv":36.93,"id":40096579}]}]}
{"op":"mcm","clk":"11843165801","pt":1723578464618,"mc":[{"id":"1.231659919","rc":[{"batb":[[0,2.08,10],[1,2.06,35.79],[2,2,9]],"ltp":2.2,"tv":36.93,"id":40096579}]}]}
{"op":"mcm","clk":"11843166257","pt":1723578468519,"mc":[{"id":"1.231659919","rc":[{"batb":[[0,2.06,35.79],[1,2,9],[2,1.89,222]],"ltp":2.2,"tv":36.93,"id":40096579}]}]}
{"op":"mcm","clk":"11843166629","pt":1723578471608,"mc":[{"id":"1.231659919","rc":[{"batb":[[0,2.08,10],[1,2.06,35.79],[2,2,9]],"ltp":2.2,"tv":36.93,"id":40096579}]}]}
{"op":"mcm","clk":"11843167063","pt":1723578474951,"mc":[{"id":"1.231659919","rc":[{"batb":[[0,2.06,35.79],[1,2,9],[2,1.89,222]],"ltp":2.2,"tv":36.93,"id":40096579}]}]}
{"op":"mcm","clk":"11843167510","pt":1723578478360,"mc":[{"id":"1.231659919","rc":[{"batb":[[0,2.08,10],[1,2.06,35.79],[2,2,9]],"ltp":2.2,"tv":36.93,"id":40096579}]}]}
{"op":"mcm","clk":"11843167962","pt":1723578481842,"mc":[{"id":"1.231659919","rc":[{"batb":[[0,2.06,35.79],[1,2,9],[2,1.89,222]],"ltp":2.2,"tv":36.93,"id":40096579}]}]}
{"op":"mcm","clk":"11843168798","pt":1723578488151,"mc":[{"id":"1.231659919","rc":[{"batb":[[0,2.08,10],[1,2.06,35.79],[2,2,9]],"ltp":2.2,"tv":36.93,"id":40096579}]}]}
{"op":"mcm","clk":"11843169302","pt":1723578491761,"mc":[{"id":"1.231659919","rc":[{"batb":[[0,2.06,35.79],[1,2,9],[2,1.89,222]],"ltp":2.2,"tv":36.93,"id":40096579}]}]}
{"op":"mcm","clk":"11843169850","pt":1723578495718,"mc":[{"id":"1.231659919","rc":[{"batb":[[0,2.08,10],[1,2.06,35.79],[2,2,9]],"ltp":2.2,"tv":36.93,"id":40096579}]}]}
{"op":"mcm","clk":"11843170331","pt":1723578499167,"mc":[{"id":"1.231659919","rc":[{"batb":[[0,2.06,35.79],[1,2,9],[2,1.89,222]],"ltp":2.2,"tv":36.93,"id":40096579}]}]}
{"op":"mcm","clk":"11843170772","pt":1723578502193,"mc":[{"id":"1.231659919","rc":[{"batb":[[0,2.08,10],[1,2.06,35.79],[2,2,9]],"ltp":2.2,"tv":36.93,"id":40096579}]}]}
{"op":"mcm","clk":"11843171306","pt":1723578505601,"mc":[{"id":"1.231659919","rc":[{"batb":[[0,2.06,35.79],[1,2,9],[2,1.89,222]],"ltp":2.2,"tv":36.93,"id":40096579}]}]}
{"op":"mcm","clk":"11843171853","pt":1723578509311,"mc":[{"id":"1.231659919","rc":[{"batb":[[0,2.08,10],[1,2.06,35.79],[2,2,9]],"ltp":2.2,"tv":36.93,"id":40096579}]}]}
{"op":"mcm","clk":"11843172520","pt":1723578513295,"mc":[{"id":"1.231659919","rc":[{"batb":[[0,2.06,35.79],[1,2,9],[2,1.89,222]],"ltp":2.2,"tv":36.93,"id":40096579}]}]}
{"op":"mcm","clk":"11843172846","pt":1723578515599,"mc":[{"id":"1.231659919","rc":[{"batb":[[0,2.08,10],[1,2.06,35.79],[2,2,9]],"ltp":2.2,"tv":36.93,"id":40096579}]}]}
{"op":"mcm","clk":"11843173366","pt":1723578519118,"mc":[{"id":"1.231659919","rc":[{"batb":[[0,2.06,35.79],[1,2,9],[2,1.89,222]],"ltp":2.2,"tv":36.93,"id":40096579}]}]}
{"op":"mcm","clk":"11843173843","pt":1723578522213,"mc":[{"id":"1.231659919","rc":[{"batb":[[0,2.08,10],[1,2.06,35.79],[2,2,9]],"ltp":2.2,"tv":36.93,"id":40096579}]}]}
{"op":"mcm","clk":"11843174425","pt":1723578526136,"mc":[{"id":"1.231659919","rc":[{"batb":[[0,2.06,35.79],[1,2,9],[2,1.89,222]],"ltp":2.2,"tv":36.93,"id":40096579}]}]}
{"op":"mcm","clk":"11843174899","pt":1723578529417,"mc":[{"id":"1.231659919","rc":[{"batb":[[0,2.08,10],[1,2.06,35.79],[2,2,9]],"ltp":2.2,"tv":36.93,"id":40096579}]}]}
{"op":"mcm","clk":"11843175476","pt":1723578533419,"mc":[{"id":"1.231659919","rc":[{"batb":[[0,2.06,35.79],[1,2,9],[2,1.89,222]],"ltp":2.2,"tv":36.93,"id":40096579}]}]}
{"op":"mcm","clk":"11843175944","pt":1723578536762,"mc":[{"id":"1.231659919","rc":[{"batb":[[0,2.08,10],[1,2.06,35.79],[2,2,9]],"ltp":2.2,"tv":36.93,"id":40096579}]}]}
{"op":"mcm","clk":"11843176513","pt":1723578540531,"mc":[{"id":"1.231659919","rc":[{"batb":[[0,2.06,35.79],[1,2,9],[2,1.89,222]],"ltp":2.2,"tv":36.93,"id":40096579}]}]}
{"op":"mcm","clk":"11843177650","pt":1723578547644,"mc":[{"id":"1.231659919","rc":[{"batb":[[0,2.08,10],[1,2.06,35.79],[2,2,9]],"ltp":2.2,"tv":36.93,"id":40096579}]}]}
{"op":"mcm","clk":"11843178204","pt":1723578551158,"mc":[{"id":"1.231659919","rc":[{"batb":[[0,2.06,35.79],[1,2,9],[2,1.89,222]],"ltp":2.2,"tv":36.93,"id":40096579}]}]}
{"op":"mcm","clk":"11843179087","pt":1723578556765,"mc":[{"id":"1.231659919","rc":[{"batb":[[0,2.08,10],[1,2.06,35.79],[2,2,9]],"ltp":2.2,"tv":36.93,"id":40096579}]}]}
{"op":"mcm","clk":"11843179636","pt":1723578560242,"mc":[{"id":"1.231659919","rc":[{"batb":[[0,2.06,35.79],[1,2,9],[2,1.89,222]],"ltp":2.2,"tv":36.93,"id":40096579}]}]}
{"op":"mcm","clk":"11843180248","pt":1723578564075,"mc":[{"id":"1.231659919","rc":[{"batb":[[0,2.08,10],[1,2.06,35.79],[2,2,9]],"ltp":2.2,"tv":36.93,"id":40096579}]}]}
{"op":"mcm","clk":"11843180917","pt":1723578567985,"mc":[{"id":"1.231659919","rc":[{"batb":[[0,2.06,35.79],[1,2,9],[2,1.89,222]],"ltp":2.2,"tv":36.93,"id":40096579}]}]}
{"op":"mcm","clk":"11843181420","pt":1723578571383,"mc":[{"id":"1.231659919","rc":[{"batb":[[0,2.08,10],[1,2.06,35.79],[2,2,9]],"ltp":2.2,"tv":36.93,"id":40096579},{"trd":[[1.83,55.15]],"batl":[[0,1.94,2.02],[1,1.98,138.46],[2,12,0.52]],"ltp":1.83,"tv":192.35,"id":40096581}],"tv":229.29}]}
{"op":"mcm","clk":"11843181958","pt":1723578574888,"mc":[{"id":"1.231659919","rc":[{"batb":[[0,2.06,35.79],[1,2,9],[2,1.89,222]],"ltp":2.2,"tv":36.93,"id":40096579}]}]}
{"op":"mcm","clk":"11843182608","pt":1723578578807,"mc":[{"id":"1.231659919","rc":[{"batb":[[0,2.08,10],[1,2.06,35.79],[2,2,9]],"ltp":2.2,"tv":36.93,"id":40096579}]}]}
{"op":"mcm","clk":"11843183156","pt":1723578582232,"mc":[{"id":"1.231659919","rc":[{"batb":[[0,2.06,35.79],[1,2,9],[2,1.89,222]],"ltp":2.2,"tv":36.93,"id":40096579}]}]}
{"op":"mcm","clk":"11843183675","pt":1723578585515,"mc":[{"id":"1.231659919","rc":[{"batb":[[0,2.08,10],[1,2.06,35.79],[2,2,9]],"ltp":2.2,"tv":36.93,"id":40096579}]}]}
{"op":"mcm","clk":"11843184195","pt":1723578588894,"mc":[{"id":"1.231659919","rc":[{"batb":[[0,2.06,35.79],[1,2,9],[2,1.89,222]],"ltp":2.2,"tv":36.93,"id":40096579}]}]}
{"op":"mcm","clk":"11843184829","pt":1723578592734,"mc":[{"id":"1.231659919","rc":[{"batb":[[0,2.08,10],[1,2.06,35.79],[2,2,9]],"ltp":2.2,"tv":36.93,"id":40096579}]}]}
{"op":"mcm","clk":"11843185389","pt":1723578596301,"mc":[{"id":"1.231659919","rc":[{"batb":[[0,2.06,35.79],[1,2,9],[2,1.89,222]],"ltp":2.2,"tv":36.93,"id":40096579}]}]}
{"op":"mcm","clk":"11843185843","pt":1723578599218,"mc":[{"id":"1.231659919","rc":[{"batb":[[0,2.08,10],[1,2.06,35.79],[2,2,9]],"ltp":2.2,"tv":36.93,"id":40096579}]}]}
{"op":"mcm","clk":"11843186471","pt":1723578603309,"mc":[{"id":"1.231659919","rc":[{"batb":[[0,2.06,35.79],[1,2,9],[2,1.89,222]],"ltp":2.2,"tv":36.93,"id":40096579}]}]}
{"op":"mcm","clk":"11843187101","pt":1723578607446,"mc":[{"id":"1.231659919","rc":[{"batb":[[0,2.08,10],[1,2.06,35.79],[2,2,9]],"ltp":2.2,"tv":36.93,"id":40096579}]}]}
{"op":"mcm","clk":"11843187653","pt":1723578610926,"mc":[{"id":"1.231659919","rc":[{"batb":[[0,2.06,35.79],[1,2,9],[2,1.89,222]],"ltp":2.2,"tv":36.93,"id":40096579}]}]}
{"op":"mcm","clk":"11843188370","pt":1723578615522,"mc":[{"id":"1.231659919","rc":[{"batb":[[0,2.08,10],[1,2.06,35.79],[2,2,9]],"ltp":2.2,"tv":36.93,"id":40096579}]}]}
{"op":"mcm","clk":"11843189001","pt":1723578619473,"mc":[{"id":"1.231659919","rc":[{"batb":[[0,2.06,35.79],[1,2,9],[2,1.89,222]],"ltp":2.2,"tv":36.93,"id":40096579}]}]}
{"op":"mcm","clk":"11843190297","pt":1723578627370,"mc":[{"id":"1.231659919","rc":[{"batb":[[0,2.08,10],[1,2.06,35.79],[2,2,9]],"ltp":2.2,"tv":36.93,"id":40096579}]}]}
{"op":"mcm","clk":"11843191003","pt":1723578631451,"mc":[{"id":"1.231659919","rc":[{"batb":[[0,2.06,35.79],[1,2,9],[2,1.89,222]],"ltp":2.2,"tv":36.93,"id":40096579}]}]}
{"op":"mcm","clk":"11843191373","pt":1723578633781,"mc":[{"id":"1.231659919","rc":[{"batb":[[0,2.08,10],[1,2.06,35.79],[2,2,9]],"ltp":2.2,"tv":36.93,"id":40096579}]}]}
{"op":"mcm","clk":"11843192048","pt":1723578637474,"mc":[{"id":"1.231659919","rc":[{"batb":[[0,2.06,35.79],[1,2,9],[2,1.89,222]],"ltp":2.2,"tv":36.93,"id":40096579}]}]}
{"op":"mcm","clk":"11843192593","pt":1723578640745,"mc":[{"id":"1.231659919","rc":[{"batb":[[0,2.08,10],[1,2.06,35.79],[2,2,9]],"ltp":2.2,"tv":36.93,"id":40096579}]}]}
{"op":"mcm","clk":"11843193207","pt":1723578644484,"mc":[{"id":"1.231659919","rc":[{"batb":[[0,2.06,35.79],[1,2,9],[2,1.89,222]],"ltp":2.2,"tv":36.93,"id":40096579}]}]}
{"op":"mcm","clk":"11843193673","pt":1723578647386,"mc":[{"id":"1.231659919","rc":[{"batb":[[0,2.08,10],[1,2.06,35.79],[2,2,9]],"ltp":2.2,"tv":36.93,"id":40096579}]}]}
{"op":"mcm","clk":"11843194265","pt":1723578650979,"mc":[{"id":"1.231659919","rc":[{"batb":[[0,2.06,35.79],[1,2,9],[2,1.89,222]],"ltp":2.2,"tv":36.93,"id":40096579}]}]}
{"op":"mcm","clk":"11843194848","pt":1723578654563,"mc":[{"id":"1.231659919","rc":[{"batb":[[0,2.08,10],[1,2.06,35.79],[2,2,9]],"ltp":2.2,"tv":36.93,"id":40096579}]}]}
{"op":"mcm","clk":"11843195412","pt":1723578658194,"mc":[{"id":"1.231659919","rc":[{"batb":[[0,2.06,35.79],[1,2,9],[2,1.89,222]],"ltp":2.2,"tv":36.93,"id":40096579}]}]}
{"op":"mcm","clk":"11843195954","pt":1723578661770,"mc":[{"id":"1.231659919","rc":[{"batb":[[0,2.08,10],[1,2.06,35.79],[2,2,9]],"ltp":2.2,"tv":36.93,"id":40096579}]}]}
{"op":"mcm","clk":"11843196495","pt":1723578665175,"mc":[{"id":"1.231659919","rc":[{"batb":[[0,2.06,35.79],[1,2,9],[2,1.89,222]],"ltp":2.2,"tv":36.93,"id":40096579}]}]}
{"op":"mcm","clk":"11843196829","pt":1723578667386,"mc":[{"id":"1.231659919","rc":[{"batb":[[0,2.08,10],[1,2.06,35.79],[2,2,9]],"ltp":2.2,"tv":36.93,"id":40096579}]}]}
{"op":"mcm","clk":"11843197426","pt":1723578671220,"mc":[{"id":"1.231659919","rc":[{"batb":[[0,2.06,35.79],[1,2,9],[2,1.89,222]],"ltp":2.2,"tv":36.93,"id":40096579}]}]}
{"op":"mcm","clk":"11843197861","pt":1723578673522,"mc":[{"id":"1.231659919","rc":[{"batb":[[0,2.08,10],[1,2.06,35.79],[2,2,9]],"ltp":2.2,"tv":36.93,"id":40096579}]}]}
{"op":"mcm","clk":"11843198529","pt":1723578677124,"mc":[{"id":"1.231659919","rc":[{"batb":[[0,2.06,35.79],[1,2,9],[2,1.89,222]],"ltp":2.2,"tv":36.93,"id":40096579}]}]}
{"op":"mcm","clk":"11843199090","pt":1723578680612,"mc":[{"id":"1.231659919","rc":[{"batb":[[0,2.08,10],[1,2.06,35.79],[2,2,9]],"ltp":2.2,"tv":36.93,"id":40096579}]}]}
{"op":"mcm","clk":"11843199711","pt":1723578684327,"mc":[{"id":"1.231659919","rc":[{"batb":[[0,2.06,35.79],[1,2,9],[2,1.89,222]],"ltp":2.2,"tv":36.93,"id":40096579}]}]}
{"op":"mcm","clk":"11843200796","pt":1723578690622,"mc":[{"id":"1.231659919","rc":[{"batb":[[0,2.08,10],[1,2.06,35.79],[2,2,9]],"ltp":2.2,"tv":36.93,"id":40096579}]}]}
{"op":"mcm","clk":"11843201537","pt":1723578694918,"mc":[{"id":"1.231659919","rc":[{"batb":[[0,2.06,35.79],[1,2,9],[2,1.89,222]],"ltp":2.2,"tv":36.93,"id":40096579}]}]}
{"op":"mcm","clk":"11843202020","pt":1723578697816,"mc":[{"id":"1.231659919","rc":[{"batb":[[0,2.08,10],[1,2.06,35.79],[2,2,9]],"ltp":2.2,"tv":36.93,"id":40096579}]}]}
{"op":"mcm","clk":"11843202722","pt":1723578701845,"mc":[{"id":"1.231659919","rc":[{"batb":[[0,2.06,35.79],[1,2,9],[2,1.89,222]],"ltp":2.2,"tv":36.93,"id":40096579}]}]}
{"op":"mcm","clk":"11843203290","pt":1723578705335,"mc":[{"id":"1.231659919","rc":[{"batb":[[0,2.08,10],[1,2.06,35.79],[2,2,9]],"ltp":2.2,"tv":36.93,"id":40096579}]}]}
{"op":"mcm","clk":"11843203965","pt":1723578709246,"mc":[{"id":"1.231659919","rc":[{"batb":[[0,2.06,35.79],[1,2,9],[2,1.89,222]],"ltp":2.2,"tv":36.93,"id":40096579}]}]}
{"op":"mcm","clk":"11843204338","pt":1723578711467,"mc":[{"id":"1.231659919","rc":[{"batb":[[0,2.08,10],[1,2.06,35.79],[2,2,9]],"ltp":2.2,"tv":36.93,"id":40096579}]}]}
{"op":"mcm","clk":"11843205038","pt":1723578715462,"mc":[{"id":"1.231659919","rc":[{"batb":[[0,2.06,35.79],[1,2,9],[2,1.89,222]],"ltp":2.2,"tv":36.93,"id":40096579}]}]}
{"op":"mcm","clk":"11843205523","pt":1723578718375,"mc":[{"id":"1.231659919","rc":[{"batb":[[0,2.08,10],[1,2.06,35.79],[2,2,9]],"ltp":2.2,"tv":36.93,"id":40096579}]}]}
{"op":"mcm","clk":"11843206055","pt":1723578721845,"mc":[{"id":"1.231659919","rc":[{"batb":[[0,2.06,35.79],[1,2,9],[2,1.89,222]],"ltp":2.2,"tv":36.93,"id":40096579}]}]}
{"op":"mcm","clk":"11843206557","pt":1723578724869,"mc":[{"id":"1.231659919","rc":[{"batb":[[0,2.08,10],[1,2.06,35.79],[2,2,9]],"ltp":2.2,"tv":36.93,"id":40096579}]}]}
{"op":"mcm","clk":"11843207198","pt":1723578728773,"mc":[{"id":"1.231659919","rc":[{"batb":[[0,2.06,35.79],[1,2,9],[2,1.89,222]],"ltp":2.2,"tv":36.93,"id":40096579}]}]}
{"op":"mcm","clk":"11843207737","pt":1723578732048,"mc":[{"id":"1.231659919","rc":[{"batb":[[0,2.08,10],[1,2.06,35.79],[2,2,9]],"ltp":2.2,"tv":36.93,"id":40096579}]}]}
{"op":"mcm","clk":"11843208426","pt":1723578736268,"mc":[{"id":"1.231659919","rc":[{"batb":[[0,2.06,35.79],[1,2,9],[2,1.89,222]],"ltp":2.2,"tv":36.93,"id":40096579}]}]}
{"op":"mcm","clk":"11843209255","pt":1723578741080,"mc":[{"id":"1.231659919","rc":[{"batb":[[0,2.08,10],[1,2.06,35.79],[2,2,9]],"ltp":2.2,"tv":36.93,"id":40096579}]}]}
{"op":"mcm","clk":"11843209861","pt":1723578744694,"mc":[{"id":"1.231659919","rc":[{"batb":[[0,2.06,35.79],[1,2,9],[2,1.89,222]],"ltp":2.2,"tv":36.93,"id":40096579}]}]}
{"op":"mcm","clk":"11843210256","pt":1723578747185,"mc":[{"id":"1.231659919","rc":[{"batb":[[0,2.08,10],[1,2.06,35.79],[2,2,9]],"ltp":2.2,"tv":36.93,"id":40096579}]}]}
{"op":"mcm","clk":"11843210790","pt":1723578750615,"mc":[{"id":"1.231659919","rc":[{"batb":[[0,2.06,35.79],[1,2,9],[2,1.89,222]],"ltp":2.2,"tv":36.93,"id":40096579}]}]}
{"op":"mcm","clk":"11843211424","pt":1723578754389,"mc":[{"id":"1.231659919","rc":[{"batb":[[0,2.08,10],[1,2.06,35.79],[2,2,9]],"ltp":2.2,"tv":36.93,"id":40096579}]}]}
{"op":"mcm","clk":"11843211982","pt":1723578758018,"mc":[{"id":"1.231659919","rc":[{"batb":[[0,2.06,35.79],[1,2,9],[2,1.89,222]],"ltp":2.2,"tv":36.93,"id":40096579}]}]}
{"op":"mcm","clk":"11843212506","pt":1723578761637,"mc":[{"id":"1.231659919","rc":[{"batb":[[0,2.08,10],[1,2.06,35.79],[2,2,9]],"ltp":2.2,"tv":36.93,"id":40096579}]}]}
{"op":"mcm","clk":"11843213083","pt":1723578765226,"mc":[{"id":"1.231659919","rc":[{"batb":[[0,2.06,35.79],[1,2,9],[2,1.89,222]],"ltp":2.2,"tv":36.93,"id":40096579}]}]}
{"op":"mcm","clk":"11843213562","pt":1723578768249,"mc":[{"id":"1.231659919","rc":[{"batb":[[0,2.08,10],[1,2.06,35.79],[2,2,9]],"ltp":2.2,"tv":36.93,"id":40096579}]}]}
{"op":"mcm","clk":"11843214192","pt":1723578772319,"mc":[{"id":"1.231659919","rc":[{"batb":[[0,2.06,35.79],[1,2,9],[2,1.89,222]],"ltp":2.2,"tv":36.93,"id":40096579}]}]}
{"op":"mcm","clk":"11843214763","pt":1723578776037,"mc":[{"id":"1.231659919","rc":[{"batb":[[0,2.08,10],[1,2.06,35.79],[2,2,9]],"ltp":2.2,"tv":36.93,"id":40096579}]}]}
{"op":"mcm","clk":"11843215407","pt":1723578780347,"mc":[{"id":"1.231659919","rc":[{"batb":[[0,2.06,35.79],[1,2,9],[2,1.89,222]],"ltp":2.2,"tv":36.93,"id":40096579}]}]}
{"op":"mcm","clk":"11843215826","pt":1723578782935,"mc":[{"id":"1.231659919","rc":[{"batb":[[0,2.08,10],[1,2.06,35.79],[2,2,9]],"ltp":2.2,"tv":36.93,"id":40096579}]}]}
{"op":"mcm","clk":"11843216466","pt":1723578786936,"mc":[{"id":"1.231659919","rc":[{"batb":[[0,2.06,35.79],[1,2,9],[2,1.89,222]],"ltp":2.2,"tv":36.93,"id":40096579}]}]}
{"op":"mcm","clk":"11843216860","pt":1723578789497,"mc":[{"id":"1.231659919","rc":[{"batb":[[0,2.08,10],[1,2.06,35.79],[2,2,9]],"ltp":2.2,"tv":36.93,"id":40096579}]}]}
{"op":"mcm","clk":"11843217397","pt":1723578793069,"mc":[{"id":"1.231659919","rc":[{"batb":[[0,2.06,35.79],[1,2,9],[2,1.89,222]],"ltp":2.2,"tv":36.93,"id":40096579}]}]}
{"op":"mcm","clk":"11843217905","pt":1723578796249,"mc":[{"id":"1.231659919","rc":[{"batb":[[0,2.08,10],[1,2.06,35.79],[2,2,9]],"ltp":2.2,"tv":36.93,"id":40096579}]}]}
{"op":"mcm","clk":"11843218394","pt":1723578799570,"mc":[{"id":"1.231659919","rc":[{"batb":[[0,2.06,35.79],[1,2,9],[2,1.89,222]],"ltp":2.2,"tv":36.93,"id":40096579}]}]}
{"op":"mcm","clk":"11843219083","pt":1723578803790,"mc":[{"id":"1.231659919","rc":[{"batb":[[0,2.08,10],[1,2.06,35.79],[2,2,9]],"ltp":2.2,"tv":36.93,"id":40096579}]}]}
{"op":"mcm","clk":"11843219720","pt":1723578807591,"mc":[{"id":"1.231659919","rc":[{"batb":[[0,2.06,35.79],[1,2,9],[2,1.89,222]],"ltp":2.2,"tv":36.93,"id":40096579}]}]}
{"op":"mcm","clk":"11843220540","pt":1723578812811,"mc":[{"id":"1.231659919","rc":[{"batb":[[0,2.08,10],[1,2.06,35.79],[2,2,9]],"ltp":2.2,"tv":36.93,"id":40096579}]}]}
{"op":"mcm","clk":"11843221122","pt":1723578816333,"mc":[{"id":"1.231659919","rc":[{"batb":[[0,2.06,35.79],[1,2,9],[2,1.89,222]],"ltp":2.2,"tv":36.93,"id":40096579}]}]}
{"op":"mcm","clk":"11843221679","pt":1723578819818,"mc":[{"id":"1.231659919","rc":[{"batb":[[0,2.08,10],[1,2.06,35.79],[2,2,9]],"ltp":2.2,"tv":36.93,"id":40096579}]}]}
{"op":"mcm","clk":"11843222270","pt":1723578823439,"mc":[{"id":"1.231659919","rc":[{"batb":[[0,2.06,35.79],[1,2,9],[2,1.89,222]],"ltp":2.2,"tv":36.93,"id":40096579}]}]}
{"op":"mcm","clk":"11843222719","pt":1723578826429,"mc":[{"id":"1.231659919","rc":[{"batb":[[0,2.08,10],[1,2.06,35.79],[2,2,9]],"ltp":2.2,"tv":36.93,"id":40096579}]}]}
{"op":"mcm","clk":"11843223277","pt":1723578829772,"mc":[{"id":"1.231659919","rc":[{"batb":[[0,2.06,35.79],[1,2,9],[2,1.89,222]],"ltp":2.2,"tv":36.93,"id":40096579}]}]}
{"op":"mcm","clk":"11843223691","pt":1723578832489,"mc":[{"id":"1.231659919","rc":[{"batb":[[0,2.08,10],[1,2.06,35.79],[2,2,9]],"ltp":2.2,"tv":36.93,"id":40096579}]}]}
{"op":"mcm","clk":"11843224368","pt":1723578836821,"mc":[{"id":"1.231659919","rc":[{"batb":[[0,2.06,35.79],[1,2,9],[2,1.89,222]],"ltp":2.2,"tv":36.93,"id":40096579}]}]}
{"op":"mcm","clk":"11843225129","pt":1723578841599,"mc":[{"id":"1.231659919","rc":[{"batb":[[0,2.08,10],[1,2.06,35.79],[2,2,9]],"ltp":2.2,"tv":36.93,"id":40096579}]}]}
{"op":"mcm","clk":"11843225774","pt":1723578845616,"mc":[{"id":"1.231659919","rc":[{"batb":[[0,2.06,35.79],[1,2,9],[2,1.89,222]],"ltp":2.2,"tv":36.93,"id":40096579}]}]}
{"op":"mcm","clk":"11843226156","pt":1723578848189,"mc":[{"id":"1.231659919","rc":[{"batb":[[0,2.08,10],[1,2.06,35.79],[2,2,9]],"ltp":2.2,"tv":36.93,"id":40096579}]}]}
{"op":"mcm","clk":"11843226727","pt":1723578851802,"mc":[{"id":"1.231659919","rc":[{"batb":[[0,2.06,35.79],[1,2,9],[2,1.89,222]],"ltp":2.2,"tv":36.93,"id":40096579}]}]}
{"op":"mcm","clk":"11843227252","pt":1723578855277,"mc":[{"id":"1.231659919","rc":[{"batb":[[0,2.08,10],[1,2.06,35.79],[2,2,9]],"ltp":2.2,"tv":36.93,"id":40096579}]}]}
{"op":"mcm","clk":"11843227848","pt":1723578858917,"mc":[{"id":"1.231659919","rc":[{"batb":[[0,2.06,35.79],[1,2,9],[2,1.89,222]],"ltp":2.2,"tv":36.93,"id":40096579}]}]}
{"op":"mcm","clk":"11843228444","pt":1723578862900,"mc":[{"id":"1.231659919","rc":[{"batb":[[0,2.08,10],[1,2.06,35.79],[2,2,9]],"ltp":2.2,"tv":36.93,"id":40096579}]}]}
{"op":"mcm","clk":"11843228979","pt":1723578866391,"mc":[{"id":"1.231659919","rc":[{"batb":[[0,2.06,35.79],[1,2,9],[2,1.89,222]],"ltp":2.2,"tv":36.93,"id":40096579}]}]}
{"op":"mcm","clk":"11843229469","pt":1723578869400,"mc":[{"id":"1.231659919","rc":[{"batb":[[0,2.08,10],[1,2.06,35.79],[2,2,9]],"ltp":2.2,"tv":36.93,"id":40096579}]}]}
{"op":"mcm","clk":"11843230044","pt":1723578873113,"mc":[{"id":"1.231659919","rc":[{"batb":[[0,2.06,35.79],[1,2,9],[2,1.89,222]],"ltp":2.2,"tv":36.93,"id":40096579}]}]}
{"op":"mcm","clk":"11843230480","pt":1723578876064,"mc":[{"id":"1.231659919","rc":[{"batb":[[0,2.08,10],[1,2.06,35.79],[2,2,9]],"ltp":2.2,"tv":36.93,"id":40096579}]}]}
{"op":"mcm","clk":"11843231111","pt":1723578880420,"mc":[{"id":"1.231659919","rc":[{"batb":[[0,2.06,35.79],[1,2,9],[2,1.89,222]],"ltp":2.2,"tv":36.93,"id":40096579}]}]}
{"op":"mcm","clk":"11843231528","pt":1723578883257,"mc":[{"id":"1.231659919","rc":[{"batb":[[0,2.08,10],[1,2.06,35.79],[2,2,9]],"ltp":2.2,"tv":36.93,"id":40096579}]}]}
{"op":"mcm","clk":"11843232129","pt":1723578887028,"mc":[{"id":"1.231659919","rc":[{"batb":[[0,2.06,35.79],[1,2,9],[2,1.89,222]],"ltp":2.2,"tv":36.93,"id":40096579}]}]}
{"op":"mcm","clk":"11843232556","pt":1723578889756,"mc":[{"id":"1.231659919","rc":[{"batb":[[0,2.08,10],[1,2.06,35.79],[2,2,9]],"ltp":2.2,"tv":36.93,"id":40096579}]}]}
{"op":"mcm","clk":"11843233098","pt":1723578893538,"mc":[{"id":"1.231659919","rc":[{"batb":[[0,2.06,35.79],[1,2,9],[2,1.89,222]],"ltp":2.2,"tv":36.93,"id":40096579}]}]}
{"op":"mcm","clk":"11843233590","pt":1723578896731,"mc":[{"id":"1.231659919","rc":[{"batb":[[0,2.08,10],[1,2.06,35.79],[2,2,9]],"ltp":2.2,"tv":36.93,"id":40096579}]}]}
{"op":"mcm","clk":"11843234174","pt":1723578900461,"mc":[{"id":"1.231659919","rc":[{"batb":[[0,2.06,35.79],[1,2,9],[2,1.89,222]],"ltp":2.2,"tv":36.93,"id":40096579}]}]}
{"op":"mcm","clk":"11843234709","pt":1723578903837,"mc":[{"id":"1.231659919","rc":[{"batb":[[0,2.08,10],[1,2.06,35.79],[2,2,9]],"ltp":2.2,"tv":36.93,"id":40096579}]}]}
{"op":"mcm","clk":"11843235394","pt":1723578908152,"mc":[{"id":"1.231659919","rc":[{"batb":[[0,2.06,35.79],[1,2,9],[2,1.89,222]],"ltp":2.2,"tv":36.93,"id":40096579}]}]}
{"op":"mcm","clk":"11843235781","pt":1723578910564,"mc":[{"id":"1.231659919","rc":[{"batb":[[0,2.08,10],[1,2.06,35.79],[2,2,9]],"ltp":2.2,"tv":36.93,"id":40096579}]}]}
{"op":"mcm","clk":"11843236419","pt":1723578914566,"mc":[{"id":"1.231659919","rc":[{"batb":[[0,2.06,35.79],[1,2,9],[2,1.89,222]],"ltp":2.2,"tv":36.93,"id":40096579}]}]}
{"op":"mcm","clk":"11843237158","pt":1723578919147,"mc":[{"id":"1.231659919","rc":[{"batb":[[0,2.08,10],[1,2.06,35.79],[2,2,9]],"ltp":2.2,"tv":36.93,"id":40096579}]}]}
{"op":"mcm","clk":"11843237779","pt":1723578922568,"mc":[{"id":"1.231659919","rc":[{"batb":[[0,2.06,35.79],[1,2,9],[2,1.89,222]],"ltp":2.2,"tv":36.93,"id":40096579}]}]}
{"op":"mcm","clk":"11843238410","pt":1723578926761,"mc":[{"id":"1.231659919","rc":[{"batb":[[0,2.08,10],[1,2.06,35.79],[2,2,9]],"ltp":2.2,"tv":36.93,"id":40096579}]}]}
{"op":"mcm","clk":"11843238959","pt":1723578930480,"mc":[{"id":"1.231659919","rc":[{"batb":[[0,2.06,35.79],[1,2,9],[2,1.89,222]],"ltp":2.2,"tv":36.93,"id":40096579}]}]}
{"op":"mcm","clk":"11843239319","pt":1723578932972,"mc":[{"id":"1.231659919","rc":[{"batb":[[0,2.08,10],[1,2.06,35.79],[2,2,9]],"ltp":2.2,"tv":36.93,"id":40096579}]}]}
{"op":"mcm","clk":"11843239801","pt":1723578936379,"mc":[{"id":"1.231659919","rc":[{"batb":[[0,2.06,35.79],[1,2,9],[2,1.89,222]],"ltp":2.2,"tv":36.93,"id":40096579}]}]}
{"op":"mcm","clk":"11843240492","pt":1723578941090,"mc":[{"id":"1.231659919","rc":[{"batb":[[0,2.08,10],[1,2.06,35.79],[2,2,9]],"ltp":2.2,"tv":36.93,"id":40096579}]}]}
{"op":"mcm","clk":"11843241020","pt":1723578944572,"mc":[{"id":"1.231659919","rc":[{"batb":[[0,2.06,35.79],[1,2,9],[2,1.89,222]],"ltp":2.2,"tv":36.93,"id":40096579}]}]}
{"op":"mcm","clk":"11843241826","pt":1723578950012,"mc":[{"id":"1.231659919","rc":[{"batb":[[0,2.08,10],[1,2.06,35.79],[2,2,9]],"ltp":2.2,"tv":36.93,"id":40096579}]}]}
{"op":"mcm","clk":"11843242435","pt":1723578953802,"mc":[{"id":"1.231659919","rc":[{"batb":[[0,2.06,35.79],[1,2,9],[2,1.89,222]],"ltp":2.2,"tv":36.93,"id":40096579}]}]}
{"op":"mcm","clk":"11843242923","pt":1723578956995,"mc":[{"id":"1.231659919","rc":[{"batb":[[0,2.08,10],[1,2.06,35.79],[2,2,9]],"ltp":2.2,"tv":36.93,"id":40096579}]}]}
{"op":"mcm","clk":"11843243559","pt":1723578961007,"mc":[{"id":"1.231659919","rc":[{"batb":[[0,2.06,35.79],[1,2,9],[2,1.89,222]],"ltp":2.2,"tv":36.93,"id":40096579}]}]}
{"op":"mcm","clk":"11843244011","pt":1723578963707,"mc":[{"id":"1.231659919","rc":[{"batb":[[0,2.08,10],[1,2.06,35.79],[2,2,9]],"ltp":2.2,"tv":36.93,"id":40096579}]}]}
{"op":"mcm","clk":"11843244591","pt":1723578967329,"mc":[{"id":"1.231659919","rc":[{"batb":[[0,2.06,35.79],[1,2,9],[2,1.89,222]],"ltp":2.2,"tv":36.93,"id":40096579}]}]}
{"op":"mcm","clk":"11843245275","pt":1723578971517,"mc":[{"id":"1.231659919","rc":[{"batb":[[0,2.08,10],[1,2.06,35.79],[2,2,9]],"ltp":2.2,"tv":36.93,"id":40096579}]}]}
{"op":"mcm","clk":"11843245938","pt":1723578975511,"mc":[{"id":"1.231659919","rc":[{"batb":[[0,2.06,35.79],[1,2,9],[2,1.89,222]],"ltp":2.2,"tv":36.93,"id":40096579}]}]}
{"op":"mcm","clk":"11843246413","pt":1723578978321,"mc":[{"id":"1.231659919","rc":[{"batb":[[0,2.08,10],[1,2.06,35.79],[2,2,9]],"ltp":2.2,"tv":36.93,"id":40096579}]}]}
{"op":"mcm","clk":"11843246988","pt":1723578981946,"mc":[{"id":"1.231659919","rc":[{"batb":[[0,2.06,35.79],[1,2,9],[2,1.89,222]],"ltp":2.2,"tv":36.93,"id":40096579}]}]}
{"op":"mcm","clk":"11843247425","pt":1723578984425,"mc":[{"id":"1.231659919","rc":[{"batb":[[0,2.08,10],[1,2.06,35.79],[2,2,9]],"ltp":2.2,"tv":36.93,"id":40096579}]}]}
{"op":"mcm","clk":"11843248012","pt":1723578988034,"mc":[{"id":"1.231659919","rc":[{"batb":[[0,2.06,35.79],[1,2,9],[2,1.89,222]],"ltp":2.2,"tv":36.93,"id":40096579}]}]}
{"op":"mcm","clk":"11843248434","pt":1723578990387,"mc":[{"id":"1.231659919","rc":[{"batb":[[0,2.08,10],[1,2.06,35.79],[2,2,9]],"ltp":2.2,"tv":36.93,"id":40096579}]}]}
{"op":"mcm","clk":"11843248815","pt":1723578992857,"mc":[{"id":"1.231659919","rc":[{"trd":[[1.83,55.18]],"batb":[[0,1.86,799.98],[1,1.82,46.27],[2,1.78,138.46]],"batl":[[0,1.94,2]],"ltp":1.83,"tv":192.39,"id":40096581}],"tv":229.33}]}
{"op":"mcm","clk":"11843248976","pt":1723578993857,"mc":[{"id":"1.231659919","rc":[{"batb":[[0,2.06,35.79],[1,2,9],[2,1.89,222]],"ltp":2.2,"tv":36.93,"id":40096579}]}]}
{"op":"mcm","clk":"11843249383","pt":1723578996653,"mc":[{"id":"1.231659919","rc":[{"batb":[[0,2.08,10],[1,2.06,35.79],[2,2,9]],"ltp":2.2,"tv":36.93,"id":40096579}]}]}
{"op":"mcm","clk":"11843249919","pt":1723579000175,"mc":[{"id":"1.231659919","rc":[{"batb":[[0,2.06,35.79],[1,2,9],[2,1.89,222]],"ltp":2.2,"tv":36.93,"id":40096579}]}]}
{"op":"mcm","clk":"11843250387","pt":1723579002854,"mc":[{"id":"1.231659919","rc":[{"batb":[[0,2.08,10],[1,2.06,35.79],[2,2,9]],"ltp":2.2,"tv":36.93,"id":40096579}]}]}
{"op":"mcm","clk":"11843250491","pt":1723579003544,"mc":[{"id":"1.231659919","rc":[{"batb":[[0,1.87,17.41],[1,1.86,799.98],[2,1.82,46.27]],"ltp":1.83,"tv":192.39,"id":40096581}]}]}
{"op":"mcm","clk":"11843250912","pt":1723579006244,"mc":[{"id":"1.231659919","rc":[{"batb":[[0,2.06,35.79],[1,2,9],[2,1.89,222]],"ltp":2.2,"tv":36.93,"id":40096579}]}]}
{"op":"mcm","clk":"11843251461","pt":1723579009965,"mc":[{"id":"1.231659919","rc":[{"batb":[[0,2.08,10],[1,2.06,35.79],[2,2,9]],"ltp":2.2,"tv":36.93,"id":40096579}]}]}
{"op":"mcm","clk":"11843251958","pt":1723579013371,"mc":[{"id":"1.231659919","rc":[{"batb":[[0,2.06,35.79],[1,2,9],[2,1.89,222]],"ltp":2.2,"tv":36.93,"id":40096579}]}]}
{"op":"mcm","clk":"11843252136","pt":1723579014575,"mc":[{"id":"1.231659919","rc":[{"batb":[[2,1.84,800]],"ltp":1.83,"tv":192.39,"id":40096581}]}]}
{"op":"mcm","clk":"11843252376","pt":1723579016188,"mc":[{"id":"1.231659919","rc":[{"batb":[[0,2.08,10],[1,2.06,35.79],[2,2,9]],"ltp":2.2,"tv":36.93,"id":40096579}]}]}
{"op":"mcm","clk":"11843252908","pt":1723579019782,"mc":[{"id":"1.231659919","rc":[{"batb":[[0,2.06,35.79],[1,2,9],[2,1.89,222]],"ltp":2.2,"tv":36.93,"id":40096579}]}]}
{"op":"mcm","clk":"11843253325","pt":1723579022572,"mc":[{"id":"1.231659919","rc":[{"batb":[[0,2.08,10],[1,2.06,35.79],[2,2,9]],"ltp":2.2,"tv":36.93,"id":40096579}]}]}
{"op":"mcm","clk":"11843253886","pt":1723579026196,"mc":[{"id":"1.231659919","rc":[{"batb":[[0,2.06,35.79],[1,2,9],[2,1.89,222]],"ltp":2.2,"tv":36.93,"id":40096579}]}]}
{"op":"mcm","clk":"11843254389","pt":1723579028880,"mc":[{"id":"1.231659919","rc":[{"batb":[[0,2.08,10],[1,2.06,35.79],[2,2,9]],"ltp":2.2,"tv":36.93,"id":40096579}]}]}
{"op":"mcm","clk":"11843254947","pt":1723579032720,"mc":[{"id":"1.231659919","rc":[{"batb":[[0,2.06,35.79],[1,2,9],[2,1.89,222]],"ltp":2.2,"tv":36.93,"id":40096579}]}]}
{"op":"mcm","clk":"11843255617","pt":1723579037077,"mc":[{"id":"1.231659919","rc":[{"batb":[[0,2.08,10],[1,2.06,35.79],[2,2,9]],"ltp":2.2,"tv":36.93,"id":40096579}]}]}
{"op":"mcm","clk":"11843256285","pt":1723579041076,"mc":[{"id":"1.231659919","rc":[{"batb":[[0,2.06,35.79],[1,2,9],[2,1.89,222]],"ltp":2.2,"tv":36.93,"id":40096579},{"batl":[[1,1.95,800],[2,1.98,138.46]],"ltp":1.83,"tv":192.39,"id":40096581}]}]}
{"op":"mcm","clk":"11843256964","pt":1723579045223,"mc":[{"id":"1.231659919","rc":[{"batb":[[0,2.08,10],[1,2.06,35.79],[2,2,9]],"ltp":2.2,"tv":36.93,"id":40096579}]}]}
{"op":"mcm","clk":"11843257534","pt":1723579048818,"mc":[{"id":"1.231659919","rc":[{"batb":[[0,2.06,35.79],[1,2,9],[2,1.89,222]],"ltp":2.2,"tv":36.93,"id":40096579}]}]}
{"op":"mcm","clk":"11843258051","pt":1723579052189,"mc":[{"id":"1.231659919","rc":[{"batb":[[0,2.08,10],[1,2.06,35.79],[2,2,9]],"ltp":2.2,"tv":36.93,"id":40096579}]}]}
{"op":"mcm","clk":"11843258556","pt":1723579055609,"mc":[{"id":"1.231659919","rc":[{"batb":[[0,2.06,35.79],[1,2,9],[2,1.89,222]],"ltp":2.2,"tv":36.93,"id":40096579}]}]}
{"op":"mcm","clk":"11843258899","pt":1723579057817,"mc":[{"id":"1.231659919","rc":[{"batb":[[0,2.08,10],[1,2.06,35.79],[2,2,9]],"ltp":2.2,"tv":36.93,"id":40096579}]}]}
{"op":"mcm","clk":"11843259389","pt":1723579061317,"mc":[{"id":"1.231659919","rc":[{"batb":[[0,2.06,35.79],[1,2,9],[2,1.89,222]],"ltp":2.2,"tv":36.93,"id":40096579}]}]}
{"op":"mcm","clk":"11843259871","pt":1723579064534,"mc":[{"id":"1.231659919","rc":[{"batb":[[0,2.08,10],[1,2.06,35.79],[2,2,9]],"ltp":2.2,"tv":36.93,"id":40096579}]}]}
{"op":"mcm","clk":"11843260440","pt":1723579068033,"mc":[{"id":"1.231659919","rc":[{"batb":[[0,2.06,35.79],[1,2,9],[2,1.89,222]],"ltp":2.2,"tv":36.93,"id":40096579}]}]}
{"op":"mcm","clk":"11843260968","pt":1723579070824,"mc":[{"id":"1.231659919","rc":[{"batb":[[0,2.08,10],[1,2.06,35.79],[2,2,9]],"ltp":2.2,"tv":36.93,"id":40096579}]}]}
{"op":"mcm","clk":"11843261527","pt":1723579074330,"mc":[{"id":"1.231659919","rc":[{"batb":[[0,2.06,35.79],[1,2,9],[2,1.89,222]],"ltp":2.2,"tv":36.93,"id":40096579}]}]}
{"op":"mcm","clk":"11843261992","pt":1723579077335,"mc":[{"id":"1.231659919","rc":[{"batb":[[0,2.08,10],[1,2.06,35.79],[2,2,9]],"ltp":2.2,"tv":36.93,"id":40096579}]}]}
{"op":"mcm","clk":"11843262552","pt":1723579080924,"mc":[{"id":"1.231659919","rc":[{"batb":[[0,2.06,35.79],[1,2,9],[2,1.89,222]],"ltp":2.2,"tv":36.93,"id":40096579}]}]}
{"op":"mcm","clk":"11843263128","pt":1723579084756,"mc":[{"id":"1.231659919","rc":[{"batb":[[0,2.08,10],[1,2.06,35.79],[2,2,9]],"ltp":2.2,"tv":36.93,"id":40096579}]}]}
{"op":"mcm","clk":"11843263733","pt":1723579088554,"mc":[{"id":"1.231659919","rc":[{"batb":[[0,2.06,35.79],[1,2,9],[2,1.89,222]],"ltp":2.2,"tv":36.93,"id":40096579}]}]}
{"op":"mcm","clk":"11843264408","pt":1723579092873,"mc":[{"id":"1.231659919","rc":[{"batb":[[0,2.08,10],[1,2.06,35.79],[2,2,9]],"ltp":2.2,"tv":36.93,"id":40096579}]}]}
{"op":"mcm","clk":"11843265127","pt":1723579097085,"mc":[{"id":"1.231659919","rc":[{"batb":[[0,2.06,35.79],[1,2,9],[2,1.89,222]],"ltp":2.2,"tv":36.93,"id":40096579}]}]}
{"op":"mcm","clk":"11843265526","pt":1723579099475,"mc":[{"id":"1.231659919","rc":[{"batb":[[0,2.08,10],[1,2.06,35.79],[2,2,9]],"ltp":2.2,"tv":36.93,"id":40096579}]}]}
{"op":"mcm","clk":"11843266088","pt":1723579103690,"mc":[{"id":"1.231659919","rc":[{"batb":[[0,2.06,35.79],[1,2,9],[2,1.89,222]],"ltp":2.2,"tv":36.93,"id":40096579}]}]}
{"op":"mcm","clk":"11843267601","pt":1723579111981,"mc":[{"id":"1.231659919","rc":[{"batb":[[0,2.08,10],[1,2.06,35.79]],"ltp":2.2,"tv":36.93,"id":40096579}]}]}
{"op":"mcm","clk":"11843269016","pt":1723579121418,"mc":[{"id":"1.231659919","rc":[{"batb":[[0,2.06,35.79],[1,1.89,222],[2,1.86,555]],"ltp":2.2,"tv":36.93,"id":40096579}]}]}
{"op":"mcm","clk":"11843269623","pt":1723579125682,"mc":[{"id":"1.231659919","rc":[{"batb":[[0,2.08,10],[1,2.06,35.79],[2,1.89,222]],"ltp":2.2,"tv":36.93,"id":40096579}]}]}
{"op":"mcm","clk":"11843270031","pt":1723579128648,"mc":[{"id":"1.231659919","rc":[{"batb":[[0,2.08,28.33]],"ltp":2.2,"tv":36.93,"id":40096579}]}]}
{"op":"mcm","clk":"11843270523","pt":1723579131688,"mc":[{"id":"1.231659919","rc":[{"batb":[[0,2.08,18.33]],"ltp":2.2,"tv":36.93,"id":40096579}]}]}
{"op":"mcm","clk":"11843271051","pt":1723579134775,"mc":[{"id":"1.231659919","rc":[{"batb":[[0,2.1,10],[1,2.08,18.33],[2,2.06,35.79]],"ltp":2.2,"tv":36.93,"id":40096579}]}]}
{"op":"mcm","clk":"11843271689","pt":1723579139097,"mc":[{"id":"1.231659919","rc":[{"batb":[[0,2.08,18.33],[1,2.06,35.79],[2,1.89,222]],"ltp":2.2,"tv":36.93,"id":40096579}]}]}
{"op":"mcm","clk":"11843272119","pt":1723579141727,"mc":[{"id":"1.231659919","rc":[{"batb":[[0,2.1,10],[1,2.08,18.33],[2,2.06,35.79]],"ltp":2.2,"tv":36.93,"id":40096579}]}]}
{"op":"mcm","clk":"11843272730","pt":1723579145385,"mc":[{"id":"1.231659919","rc":[{"batb":[[0,2.08,18.33],[1,2.06,35.79],[2,1.89,222]],"ltp":2.2,"tv":36.93,"id":40096579}]}]}
{"op":"mcm","clk":"11843273107","pt":1723579147700,"mc":[{"id":"1.231659919","rc":[{"batb":[[0,2.1,10],[1,2.08,18.33],[2,2.06,35.79]],"ltp":2.2,"tv":36.93,"id":40096579}]}]}
{"op":"mcm","clk":"11843273689","pt":1723579151223,"mc":[{"id":"1.231659919","rc":[{"batb":[[0,2.08,18.33],[1,2.06,35.79],[2,1.89,222]],"ltp":2.2,"tv":36.93,"id":40096579}]}]}
{"op":"mcm","clk":"11843274282","pt":1723579154935,"mc":[{"id":"1.231659919","rc":[{"batb":[[0,2.1,10],[1,2.08,18.33],[2,2.06,35.79]],"ltp":2.2,"tv":36.93,"id":40096579}]}]}
{"op":"mcm","clk":"11843274896","pt":1723579158517,"mc":[{"id":"1.231659919","rc":[{"batb":[[0,2.08,18.33],[1,2.06,35.79],[2,1.89,222]],"ltp":2.2,"tv":36.93,"id":40096579}]}]}
{"op":"mcm","clk":"11843275589","pt":1723579162700,"mc":[{"id":"1.231659919","rc":[{"batb":[[0,2.1,10],[1,2.08,18.33],[2,2.06,35.79]],"ltp":2.2,"tv":36.93,"id":40096579}]}]}
{"op":"mcm","clk":"11843276150","pt":1723579166248,"mc":[{"id":"1.231659919","rc":[{"batb":[[0,2.08,18.33],[1,2.06,35.79],[2,1.89,222]],"ltp":2.2,"tv":36.93,"id":40096579}]}]}
{"op":"mcm","clk":"11843277029","pt":1723579171751,"mc":[{"id":"1.231659919","rc":[{"batb":[[0,2.1,10],[1,2.08,18.33],[2,2.06,35.79]],"ltp":2.2,"tv":36.93,"id":40096579}]}]}
{"op":"mcm","clk":"11843277880","pt":1723579176719,"mc":[{"id":"1.231659919","rc":[{"batb":[[0,2.08,18.33],[1,2.06,35.79],[2,1.89,222]],"ltp":2.2,"tv":36.93,"id":40096579}]}]}
{"op":"mcm","clk":"11843278572","pt":1723579181029,"mc":[{"id":"1.231659919","rc":[{"batb":[[0,2.12,10],[1,2.08,18.33],[2,2.06,35.79]],"ltp":2.2,"tv":36.93,"id":40096579}]}]}
{"op":"mcm","clk":"11843278647","pt":1723579181448,"mc":[{"id":"1.231659919","rc":[{"batb":[[2,1.89,222]],"ltp":2.2,"tv":36.93,"id":40096579}]}]}
{"op":"mcm","clk":"11843280443","pt":1723579192351,"mc":[{"id":"1.231659919","rc":[{"batb":[[0,1.86,799.98],[1,1.84,800],[2,1.78,138.46]],"batl":[[0,1.88,22],[1,1.94,2],[2,1.95,800]],"ltp":1.83,"tv":192.39,"id":40096581}]}]}
{"op":"mcm","clk":"11843280504","pt":1723579192721,"mc":[{"id":"1.231659919","rc":[{"batb":[[0,2.08,18.33],[1,1.89,222],[2,1.86,555]],"ltp":2.2,"tv":36.93,"id":40096579}]}]}
{"op":"mcm","clk":"11843280901","pt":1723579195038,"mc":[{"id":"1.231659919","rc":[{"batb":[[0,2.14,10],[1,2.08,18.33],[2,1.89,222]],"ltp":2.2,"tv":36.93,"id":40096579}]}]}
{"op":"mcm","clk":"11843282241","pt":1723579203047,"mc":[{"id":"1.231659919","rc":[{"batb":[[0,2.08,18.33],[1,1.89,222],[2,1.86,555]],"ltp":2.2,"tv":36.93,"id":40096579}]}]}
{"op":"mcm","clk":"11843282683","pt":1723579205464,"mc":[{"id":"1.231659919","rc":[{"trd":[[2.06,27.94]],"batb":[[0,2.1,10],[1,2.08,18.33],[2,1.89,222]],"ltp":2.2,"tv":36.93,"id":40096579},{"trd":[[1.83,55.19],[1.86,117.22]],"ltp":1.83,"tv":192.4,"id":40096581}],"tv":229.34}]}
{"op":"mcm","clk":"11843282892","pt":1723579206464,"mc":[{"id":"1.231659919","rc":[{"batb":[[2,2.06,35.79]],"ltp":2.2,"tv":36.93,"id":40096579},{"batb":[[2,1.82,46.27]],"ltp":1.83,"tv":192.4,"id":40096581}]}]}
{"op":"mcm","clk":"11843283767","pt":1723579211962,"mc":[{"id":"1.231659919","rc":[{"batb":[[0,2.08,18.33],[1,2.06,35.79],[2,1.89,222]],"ltp":2.2,"tv":36.93,"id":40096579}]}]}
{"op":"mcm","clk":"11843284180","pt":1723579214476,"mc":[{"id":"1.231659919","rc":[{"batb":[[0,2.1,10],[1,2.08,18.33],[2,2.06,35.79]],"ltp":2.2,"tv":36.93,"id":40096579}]}]}
{"op":"mcm","clk":"11843285054","pt":1723579219576,"mc":[{"id":"1.231659919","rc":[{"batb":[[0,2.08,18.33],[1,2.06,35.79],[2,1.89,222]],"ltp":2.2,"tv":36.93,"id":40096579}]}]}
{"op":"mcm","clk":"11843285847","pt":1723579224353,"mc":[{"id":"1.231659919","rc":[{"batb":[[0,2.1,10],[1,2.08,18.33],[2,2.06,35.79]],"ltp":2.2,"tv":36.93,"id":40096579}]}]}
{"op":"mcm","clk":"11843286422","pt":1723579227886,"mc":[{"id":"1.231659919","rc":[{"batb":[[0,2.08,18.33],[1,2.06,35.79],[2,1.89,222]],"ltp":2.2,"tv":36.93,"id":40096579}]}]}
{"op":"mcm","clk":"11843286822","pt":1723579230361,"mc":[{"id":"1.231659919","rc":[{"batb":[[0,2.1,10],[1,2.08,18.33],[2,2.06,35.79]],"ltp":2.2,"tv":36.93,"id":40096579}]}]}
{"op":"mcm","clk":"11843287453","pt":1723579234064,"mc":[{"id":"1.231659919","rc":[{"batb":[[0,2.08,18.33],[1,2.06,35.79],[2,1.89,222]],"ltp":2.2,"tv":36.93,"id":40096579}]}]}
{"op":"mcm","clk":"11843287869","pt":1723579236688,"mc":[{"id":"1.231659919","rc":[{"batb":[[0,2.1,10],[1,2.08,18.33],[2,2.06,35.79]],"ltp":2.2,"tv":36.93,"id":40096579}]}]}
{"op":"mcm","clk":"11843288438","pt":1723579240310,"mc":[{"id":"1.231659919","rc":[{"batb":[[0,2.08,18.33],[1,2.06,35.79],[2,1.89,222]],"ltp":2.2,"tv":36.93,"id":40096579}]}]}
{"op":"mcm","clk":"11843288923","pt":1723579243320,"mc":[{"id":"1.231659919","rc":[{"batb":[[0,2.1,10],[1,2.08,18.33],[2,2.06,35.79]],"ltp":2.2,"tv":36.93,"id":40096579}]}]}
{"op":"mcm","clk":"11843289509","pt":1723579246791,"mc":[{"id":"1.231659919","rc":[{"batb":[[0,2.08,18.33],[1,2.06,35.79],[2,1.89,222]],"ltp":2.2,"tv":36.93,"id":40096579}]}]}
{"op":"mcm","clk":"11843290184","pt":1723579250874,"mc":[{"id":"1.231659919","rc":[{"batb":[[0,2.1,10],[1,2.08,18.33],[2,2.06,35.79]],"ltp":2.2,"tv":36.93,"id":40096579}]}]}
{"op":"mcm","clk":"11843290798","pt":1723579254697,"mc":[{"id":"1.231659919","rc":[{"batb":[[0,2.08,18.33],[1,2.06,35.79],[2,1.89,222]],"ltp":2.2,"tv":36.93,"id":40096579}]}]}
{"op":"mcm","clk":"11843291280","pt":1723579257784,"mc":[{"id":"1.231659919","rc":[{"batb":[[0,2.1,10],[1,2.08,18.33],[2,2.06,35.79]],"ltp":2.2,"tv":36.93,"id":40096579}]}]}
{"op":"mcm","clk":"11843291826","pt":1723579261310,"mc":[{"id":"1.231659919","rc":[{"batb":[[0,2.08,18.33],[1,2.06,35.79],[2,1.89,222]],"ltp":2.2,"tv":36.93,"id":40096579}]}]}
{"op":"mcm","clk":"11843292302","pt":1723579264105,"mc":[{"id":"1.231659919","rc":[{"batb":[[0,2.1,10],[1,2.08,18.33],[2,2.06,35.79]],"ltp":2.2,"tv":36.93,"id":40096579}]}]}
{"op":"mcm","clk":"11843292929","pt":1723579267718,"mc":[{"id":"1.231659919","rc":[{"batb":[[0,2.08,18.33],[1,2.06,35.79],[2,1.89,222]],"ltp":2.2,"tv":36.93,"id":40096579}]}]}
{"op":"mcm","clk":"11843293484","pt":1723579271020,"mc":[{"id":"1.231659919","rc":[{"batb":[[0,2.1,10],[1,2.08,18.33],[2,2.06,35.79]],"ltp":2.2,"tv":36.93,"id":40096579}]}]}
{"op":"mcm","clk":"11843294141","pt":1723579275217,"mc":[{"id":"1.231659919","rc":[{"batb":[[0,2.08,18.33],[1,2.06,35.79],[2,1.89,222]],"ltp":2.2,"tv":36.93,"id":40096579}]}]}
{"op":"mcm","clk":"11843294570","pt":1723579277927,"mc":[{"id":"1.231659919","rc":[{"batb":[[0,2.1,10],[1,2.08,18.33],[2,2.06,35.79]],"ltp":2.2,"tv":36.93,"id":40096579}]}]}
{"op":"mcm","clk":"11843295143","pt":1723579281643,"mc":[{"id":"1.231659919","rc":[{"batb":[[0,2.08,18.33],[1,2.06,35.79],[2,1.89,222]],"ltp":2.2,"tv":36.93,"id":40096579}]}]}
{"op":"mcm","clk":"11843295676","pt":1723579285024,"mc":[{"id":"1.231659919","rc":[{"batb":[[0,2.1,10],[1,2.08,18.33],[2,2.06,35.79]],"ltp":2.2,"tv":36.93,"id":40096579}]}]}
{"op":"mcm","clk":"11843296255","pt":1723579288683,"mc":[{"id":"1.231659919","rc":[{"batb":[[0,2.08,18.33],[1,2.06,35.79],[2,1.89,222]],"ltp":2.2,"tv":36.93,"id":40096579}]}]}
{"op":"mcm","clk":"11843297273","pt":1723579294853,"mc":[{"id":"1.231659919","rc":[{"batb":[[0,2.1,10],[1,2.08,18.33],[2,2.06,35.79]],"ltp":2.2,"tv":36.93,"id":40096579}]}]}
{"op":"mcm","clk":"11843297880","pt":1723579298659,"mc":[{"id":"1.231659919","rc":[{"batb":[[0,2.08,18.33],[1,2.06,35.79],[2,1.89,222]],"ltp":2.2,"tv":36.93,"id":40096579}]}]}
{"op":"mcm","clk":"11843298464","pt":1723579302046,"mc":[{"id":"1.231659919","rc":[{"batb":[[0,2.1,10],[1,2.08,18.33],[2,2.06,35.79]],"ltp":2.2,"tv":36.93,"id":40096579}]}]}
{"op":"mcm","clk":"11843299102","pt":1723579305934,"mc":[{"id":"1.231659919","rc":[{"batb":[[0,2.08,18.33],[1,2.06,35.79],[2,1.89,222]],"ltp":2.2,"tv":36.93,"id":40096579}]}]}
{"op":"mcm","clk":"11843299869","pt":1723579310697,"mc":[{"id":"1.231659919","rc":[{"batb":[[0,2.1,10],[1,2.08,18.33],[2,2.06,35.79]],"ltp":2.2,"tv":36.93,"id":40096579}]}]}
{"op":"mcm","clk":"11843300423","pt":1723579314173,"mc":[{"id":"1.231659919","rc":[{"batb":[[0,2.08,18.33],[1,2.06,35.79],[2,1.89,222]],"ltp":2.2,"tv":36.93,"id":40096579}]}]}
{"op":"mcm","clk":"11843300893","pt":1723579317081,"mc":[{"id":"1.231659919","rc":[{"batb":[[0,2.1,10],[1,2.08,18.33],[2,2.06,35.79]],"ltp":2.2,"tv":36.93,"id":40096579}]}]}
{"op":"mcm","clk":"11843301550","pt":1723579321276,"mc":[{"id":"1.231659919","rc":[{"batb":[[0,2.08,18.33],[1,2.06,35.79],[2,1.89,222]],"ltp":2.2,"tv":36.93,"id":40096579}]}]}
{"op":"mcm","clk":"11843302008","pt":1723579323858,"mc":[{"id":"1.231659919","rc":[{"batb":[[0,2.1,10],[1,2.08,18.33],[2,2.06,35.79]],"ltp":2.2,"tv":36.93,"id":40096579}]}]}
{"op":"mcm","clk":"11843302619","pt":1723579327559,"mc":[{"id":"1.231659919","rc":[{"batb":[[0,2.08,18.33],[1,2.06,35.79],[2,1.89,222]],"ltp":2.2,"tv":36.93,"id":40096579}]}]}
{"op":"mcm","clk":"11843303396","pt":1723579332094,"mc":[{"id":"1.231659919","rc":[{"batb":[[0,2.1,10],[1,2.08,18.33],[2,2.06,35.79]],"ltp":2.2,"tv":36.93,"id":40096579}]}]}
{"op":"mcm","clk":"11843303990","pt":1723579335768,"mc":[{"id":"1.231659919","rc":[{"batb":[[0,2.08,18.33],[1,2.06,35.79],[2,1.89,222]],"ltp":2.2,"tv":36.93,"id":40096579}]}]}
{"op":"mcm","clk":"11843304489","pt":1723579338906,"mc":[{"id":"1.231659919","rc":[{"batb":[[0,2.1,10],[1,2.08,18.33],[2,2.06,35.79]],"ltp":2.2,"tv":36.93,"id":40096579}]}]}
{"op":"mcm","clk":"11843305076","pt":1723579342611,"mc":[{"id":"1.231659919","rc":[{"batb":[[0,2.08,18.33],[1,2.06,35.79],[2,1.89,222]],"ltp":2.2,"tv":36.93,"id":40096579}]}]}
{"op":"mcm","clk":"11843305712","pt":1723579346875,"mc":[{"id":"1.231659919","rc":[{"batb":[[0,2.1,10],[1,2.08,18.33],[2,2.06,35.79]],"ltp":2.2,"tv":36.93,"id":40096579}]}]}
{"op":"mcm","clk":"11843306263","pt":1723579350500,"mc":[{"id":"1.231659919","rc":[{"batb":[[0,2.08,18.33],[1,2.06,35.79],[2,1.89,222]],"ltp":2.2,"tv":36.93,"id":40096579}]}]}
{"op":"mcm","clk":"11843306825","pt":1723579353637,"mc":[{"id":"1.231659919","rc":[{"batb":[[0,2.1,10],[1,2.08,18.33],[2,2.06,35.79]],"ltp":2.2,"tv":36.93,"id":40096579}]}]}
{"op":"mcm","clk":"11843307493","pt":1723579357515,"mc":[{"id":"1.231659919","rc":[{"batb":[[0,2.08,18.33],[1,2.06,35.79],[2,1.89,222]],"ltp":2.2,"tv":36.93,"id":40096579}]}]}
{"op":"mcm","clk":"11843308672","pt":1723579364559,"mc":[{"id":"1.231659919","rc":[{"batb":[[0,2.1,10],[1,2.08,18.33],[2,2.06,35.79]],"ltp":2.2,"tv":36.93,"id":40096579}]}]}
{"op":"mcm","clk":"11843309332","pt":1723579368129,"mc":[{"id":"1.231659919","rc":[{"batb":[[0,2.08,18.33],[1,2.06,35.79],[2,1.89,222]],"ltp":2.2,"tv":36.93,"id":40096579}]}]}
{"op":"mcm","clk":"11843310433","pt":1723579374422,"mc":[{"id":"1.231659919","rc":[{"batb":[[0,2.1,10],[1,2.08,18.33],[2,2.06,35.79]],"ltp":2.2,"tv":36.93,"id":40096579}]}]}
{"op":"mcm","clk":"11843311151","pt":1723579378334,"mc":[{"id":"1.231659919","rc":[{"batb":[[0,2.08,18.33],[1,2.06,35.79],[2,1.89,222]],"ltp":2.2,"tv":36.93,"id":40096579}]}]}
{"op":"mcm","clk":"11843311570","pt":1723579380857,"mc":[{"id":"1.231659919","rc":[{"batb":[[0,2.1,10],[1,2.08,18.33],[2,2.06,35.79]],"ltp":2.2,"tv":36.93,"id":40096579}]}]}
{"op":"mcm","clk":"11843312176","pt":1723579384495,"mc":[{"id":"1.231659919","rc":[{"batb":[[0,2.08,18.33],[1,2.06,35.79],[2,1.89,222]],"ltp":2.2,"tv":36.93,"id":40096579}]}]}
{"op":"mcm","clk":"11843312681","pt":1723579387346,"mc":[{"id":"1.231659919","rc":[{"batb":[[0,2.1,10],[1,2.08,18.33],[2,2.06,35.79]],"ltp":2.2,"tv":36.93,"id":40096579}]}]}
{"op":"mcm","clk":"11843313334","pt":1723579391135,"mc":[{"id":"1.231659919","rc":[{"batb":[[0,2.08,18.33],[1,2.06,35.79],[2,1.89,222]],"ltp":2.2,"tv":36.93,"id":40096579}]}]}
{"op":"mcm","clk":"11843313768","pt":1723579393569,"mc":[{"id":"1.231659919","rc":[{"batb":[[0,2.1,10],[1,2.08,18.33],[2,2.06,35.79]],"ltp":2.2,"tv":36.93,"id":40096579}]}]}
{"op":"mcm","clk":"11843314388","pt":1723579397253,"mc":[{"id":"1.231659919","rc":[{"batb":[[0,2.08,18.33],[1,2.06,35.79],[2,1.89,222]],"ltp":2.2,"tv":36.93,"id":40096579}]}]}
{"op":"mcm","clk":"11843314870","pt":1723579399881,"mc":[{"id":"1.231659919","rc":[{"batb":[[0,2.1,10],[1,2.08,18.33],[2,2.06,35.79]],"ltp":2.2,"tv":36.93,"id":40096579}]}]}
{"op":"mcm","clk":"11843315495","pt":1723579403472,"mc":[{"id":"1.231659919","rc":[{"batb":[[0,2.08,18.33],[1,2.06,35.79],[2,1.89,222]],"ltp":2.2,"tv":36.93,"id":40096579}]}]}
{"op":"mcm","clk":"11843315968","pt":1723579406211,"mc":[{"id":"1.231659919","rc":[{"batb":[[0,2.1,10],[1,2.08,18.33],[2,2.06,35.79]],"ltp":2.2,"tv":36.93,"id":40096579}]}]}
{"op":"mcm","clk":"11843316650","pt":1723579409801,"mc":[{"id":"1.231659919","rc":[{"batb":[[0,2.08,18.33],[1,2.06,35.79],[2,1.89,222]],"ltp":2.2,"tv":36.93,"id":40096579}]}]}
{"op":"mcm","clk":"11843317318","pt":1723579413792,"mc":[{"id":"1.231659919","rc":[{"batb":[[0,2.1,10],[1,2.08,18.33],[2,2.06,35.79]],"ltp":2.2,"tv":36.93,"id":40096579}]}]}
{"op":"mcm","clk":"11843317943","pt":1723579417117,"mc":[{"id":"1.231659919","rc":[{"batb":[[0,2.08,18.33],[1,2.06,35.79],[2,1.89,222]],"ltp":2.2,"tv":36.93,"id":40096579}]}]}
{"op":"mcm","clk":"11843318455","pt":1723579419888,"mc":[{"id":"1.231659919","rc":[{"batb":[[0,2.1,10],[1,2.08,18.33],[2,2.06,35.79]],"ltp":2.2,"tv":36.93,"id":40096579}]}]}
{"op":"mcm","clk":"11843319119","pt":1723579423791,"mc":[{"id":"1.231659919","rc":[{"batb":[[0,2.08,18.33],[1,2.06,35.79],[2,1.89,222]],"ltp":2.2,"tv":36.93,"id":40096579}]}]}
{"op":"mcm","clk":"11843319660","pt":1723579427011,"mc":[{"id":"1.231659919","rc":[{"batb":[[0,2.1,10],[1,2.08,18.33],[2,2.06,35.79]],"ltp":2.2,"tv":36.93,"id":40096579}]}]}
{"op":"mcm","clk":"11843320280","pt":1723579430712,"mc":[{"id":"1.231659919","rc":[{"batb":[[0,2.08,18.33],[1,2.06,35.79],[2,1.89,222]],"ltp":2.2,"tv":36.93,"id":40096579}]}]}
{"op":"mcm","clk":"11843321057","pt":1723579435508,"mc":[{"id":"1.231659919","rc":[{"batb":[[0,2.1,10],[1,2.08,18.33],[2,2.06,35.79]],"ltp":2.2,"tv":36.93,"id":40096579}]}]}
{"op":"mcm","clk":"11843321671","pt":1723579439335,"mc":[{"id":"1.231659919","rc":[{"batb":[[0,2.08,18.33],[1,2.06,35.79],[2,1.89,222]],"ltp":2.2,"tv":36.93,"id":40096579}]}]}
{"op":"mcm","clk":"11843322236","pt":1723579442740,"mc":[{"id":"1.231659919","rc":[{"batb":[[0,2.1,10],[1,2.08,18.33],[2,2.06,35.79]],"ltp":2.2,"tv":36.93,"id":40096579}]}]}
{"op":"mcm","clk":"11843322792","pt":1723579446145,"mc":[{"id":"1.231659919","rc":[{"batb":[[0,2.08,18.33],[1,2.06,35.79],[2,1.89,222]],"ltp":2.2,"tv":36.93,"id":40096579}]}]}
{"op":"mcm","clk":"11843324419","pt":1723579455331,"mc":[{"id":"1.231659919","rc":[{"batb":[[0,2.1,10],[1,2.08,18.33],[2,2.06,35.79]],"ltp":2.2,"tv":36.93,"id":40096579}]}]}
{"op":"mcm","clk":"11843325064","pt":1723579459333,"mc":[{"id":"1.231659919","rc":[{"batb":[[0,2.08,18.33],[1,2.06,35.79],[2,1.89,222]],"ltp":2.2,"tv":36.93,"id":40096579}]}]}
{"op":"mcm","clk":"11843325738","pt":1723579463544,"mc":[{"id":"1.231659919","rc":[{"batb":[[0,2.1,10],[1,2.08,18.33],[2,2.06,35.79]],"ltp":2.2,"tv":36.93,"id":40096579}]}]}
{"op":"mcm","clk":"11843326352","pt":1723579467164,"mc":[{"id":"1.231659919","rc":[{"batb":[[0,2.08,18.33],[1,2.06,35.79],[2,1.89,222]],"ltp":2.2,"tv":36.93,"id":40096579}]}]}
{"op":"mcm","clk":"11843326763","pt":1723579469729,"mc":[{"id":"1.231659919","rc":[{"batb":[[0,2.1,10],[1,2.08,18.33],[2,2.06,35.79]],"ltp":2.2,"tv":36.93,"id":40096579}]}]}
{"op":"mcm","clk":"11843327417","pt":1723579473734,"mc":[{"id":"1.231659919","rc":[{"batb":[[0,2.08,18.33],[1,2.06,35.79],[2,1.89,222]],"ltp":2.2,"tv":36.93,"id":40096579}]}]}
{"op":"mcm","clk":"11843328521","pt":1723579480677,"mc":[{"id":"1.231659919","rc":[{"batb":[[0,2.1,10],[1,2.08,18.33],[2,2.06,35.79]],"ltp":2.2,"tv":36.93,"id":40096579}]}]}
{"op":"mcm","clk":"11843329120","pt":1723579484552,"mc":[{"id":"1.231659919","rc":[{"batb":[[0,2.08,18.33],[1,2.06,35.79],[2,1.89,222]],"ltp":2.2,"tv":36.93,"id":40096579}]}]}
{"op":"mcm","clk":"11843329702","pt":1723579488245,"mc":[{"id":"1.231659919","rc":[{"batb":[[0,2.1,10],[1,2.08,18.33],[2,2.06,35.79]],"ltp":2.2,"tv":36.93,"id":40096579}]}]}
{"op":"mcm","clk":"11843330287","pt":1723579491687,"mc":[{"id":"1.231659919","rc":[{"batb":[[0,2.08,18.33],[1,2.06,35.79],[2,1.89,222]],"ltp":2.2,"tv":36.93,"id":40096579}]}]}
{"op":"mcm","clk":"11843331037","pt":1723579495554,"mc":[{"id":"1.231659919","rc":[{"batb":[[0,2.1,10],[1,2.08,18.33],[2,2.06,35.79]],"ltp":2.2,"tv":36.93,"id":40096579}]}]}
{"op":"mcm","clk":"11843331580","pt":1723579498849,"mc":[{"id":"1.231659919","rc":[{"batb":[[0,2.08,18.33],[1,2.06,35.79],[2,1.89,222]],"ltp":2.2,"tv":36.93,"id":40096579}]}]}
{"op":"mcm","clk":"11843332091","pt":1723579501860,"mc":[{"id":"1.231659919","rc":[{"batb":[[0,2.1,10],[1,2.08,18.33],[2,2.06,35.79]],"ltp":2.2,"tv":36.93,"id":40096579}]}]}
{"op":"mcm","clk":"11843332687","pt":1723579505380,"mc":[{"id":"1.231659919","rc":[{"batb":[[0,2.08,18.33],[1,2.06,35.79],[2,1.89,222]],"ltp":2.2,"tv":36.93,"id":40096579}]}]}
{"op":"mcm","clk":"11843333185","pt":1723579508261,"mc":[{"id":"1.231659919","rc":[{"batb":[[0,2.1,10],[1,2.08,18.33],[2,2.06,35.79]],"ltp":2.2,"tv":36.93,"id":40096579}]}]}
{"op":"mcm","clk":"11843333854","pt":1723579512381,"mc":[{"id":"1.231659919","rc":[{"batb":[[0,2.08,18.33],[1,2.06,35.79],[2,1.89,222]],"ltp":2.2,"tv":36.93,"id":40096579}]}]}
{"op":"mcm","clk":"11843334383","pt":1723579515285,"mc":[{"id":"1.231659919","rc":[{"batb":[[0,2.1,10],[1,2.08,18.33],[2,2.06,35.79]],"ltp":2.2,"tv":36.93,"id":40096579}]}]}
{"op":"mcm","clk":"11843335058","pt":1723579519374,"mc":[{"id":"1.231659919","rc":[{"batb":[[0,2.08,18.33],[1,2.06,35.79],[2,1.89,222]],"ltp":2.2,"tv":36.93,"id":40096579}]}]}
{"op":"mcm","clk":"11843335449","pt":1723579521585,"mc":[{"id":"1.231659919","rc":[{"batb":[[0,2.1,10],[1,2.08,18.33],[2,2.06,35.79]],"ltp":2.2,"tv":36.93,"id":40096579}]}]}
{"op":"mcm","clk":"11843336018","pt":1723579525268,"mc":[{"id":"1.231659919","rc":[{"batb":[[0,2.08,18.33],[1,2.06,35.79],[2,1.89,222]],"ltp":2.2,"tv":36.93,"id":40096579}]}]}
{"op":"mcm","clk":"11843336511","pt":1723579528205,"mc":[{"id":"1.231659919","rc":[{"batb":[[0,2.1,10],[1,2.08,18.33],[2,2.06,35.79]],"ltp":2.2,"tv":36.93,"id":40096579}]}]}
{"op":"mcm","clk":"11843337105","pt":1723579532086,"mc":[{"id":"1.231659919","rc":[{"batb":[[0,2.08,18.33],[1,2.06,35.79],[2,1.89,222]],"ltp":2.2,"tv":36.93,"id":40096579}]}]}
{"op":"mcm","clk":"11843337567","pt":1723579534878,"mc":[{"id":"1.231659919","rc":[{"batb":[[0,2.1,10],[1,2.08,18.33],[2,2.06,35.79]],"ltp":2.2,"tv":36.93,"id":40096579}]}]}
{"op":"mcm","clk":"11843338262","pt":1723579538913,"mc":[{"id":"1.231659919","rc":[{"batb":[[0,2.08,18.33],[1,2.06,35.79],[2,1.89,222]],"ltp":2.2,"tv":36.93,"id":40096579}]}]}
{"op":"mcm","clk":"11843338655","pt":1723579541300,"mc":[{"id":"1.231659919","rc":[{"batb":[[0,2.1,10],[1,2.08,18.33],[2,2.06,35.79]],"ltp":2.2,"tv":36.93,"id":40096579}]}]}
{"op":"mcm","clk":"11843339260","pt":1723579545296,"mc":[{"id":"1.231659919","rc":[{"batb":[[0,2.08,18.33],[1,2.06,35.79],[2,1.89,222]],"ltp":2.2,"tv":36.93,"id":40096579}]}]}
{"op":"mcm","clk":"11843339685","pt":1723579548118,"mc":[{"id":"1.231659919","rc":[{"batb":[[0,2.1,10],[1,2.08,18.33],[2,2.06,35.79]],"ltp":2.2,"tv":36.93,"id":40096579}]}]}
{"op":"mcm","clk":"11843340309","pt":1723579552215,"mc":[{"id":"1.231659919","rc":[{"batb":[[0,2.08,18.33],[1,2.06,35.79],[2,1.89,222]],"ltp":2.2,"tv":36.93,"id":40096579}]}]}
{"op":"mcm","clk":"11843340775","pt":1723579555231,"mc":[{"id":"1.231659919","rc":[{"batb":[[0,2.1,10],[1,2.08,18.33],[2,2.06,35.79]],"ltp":2.2,"tv":36.93,"id":40096579}]}]}
{"op":"mcm","clk":"11843341309","pt":1723579558743,"mc":[{"id":"1.231659919","rc":[{"batb":[[0,2.08,18.33],[1,2.06,35.79],[2,1.89,222]],"ltp":2.2,"tv":36.93,"id":40096579}]}]}
{"op":"mcm","clk":"11843341904","pt":1723579562127,"mc":[{"id":"1.231659919","rc":[{"batb":[[0,2.1,10],[1,2.08,18.33],[2,2.06,35.79]],"ltp":2.2,"tv":36.93,"id":40096579}]}]}
{"op":"mcm","clk":"11843342500","pt":1723579565546,"mc":[{"id":"1.231659919","rc":[{"batb":[[0,2.08,18.33],[1,2.06,35.79],[2,1.89,222]],"ltp":2.2,"tv":36.93,"id":40096579}]}]}
{"op":"mcm","clk":"11843342985","pt":1723579568849,"mc":[{"id":"1.231659919","rc":[{"batb":[[0,2.1,10],[1,2.08,18.33],[2,2.06,35.79]],"ltp":2.2,"tv":36.93,"id":40096579}]}]}
{"op":"mcm","clk":"11843343521","pt":1723579572258,"mc":[{"id":"1.231659919","rc":[{"batb":[[0,2.08,18.33],[1,2.06,35.79],[2,1.89,222]],"ltp":2.2,"tv":36.93,"id":40096579}]}]}
{"op":"mcm","clk":"11843343940","pt":1723579574944,"mc":[{"id":"1.231659919","rc":[{"batb":[[0,2.1,10],[1,2.08,18.33],[2,2.06,35.79]],"ltp":2.2,"tv":36.93,"id":40096579}]}]}
{"op":"mcm","clk":"11843344509","pt":1723579578664,"mc":[{"id":"1.231659919","rc":[{"batb":[[0,2.08,18.33],[1,2.06,35.79],[2,1.89,222]],"ltp":2.2,"tv":36.93,"id":40096579}]}]}
{"op":"mcm","clk":"11843345022","pt":1723579582057,"mc":[{"id":"1.231659919","rc":[{"batb":[[0,2.1,10],[1,2.08,18.33],[2,2.06,35.79]],"ltp":2.2,"tv":36.93,"id":40096579}]}]}
{"op":"mcm","clk":"11843345587","pt":1723579585771,"mc":[{"id":"1.231659919","rc":[{"batb":[[0,2.08,18.33],[1,2.06,35.79],[2,1.89,222]],"ltp":2.2,"tv":36.93,"id":40096579}]}]}
{"op":"mcm","clk":"11843346059","pt":1723579588859,"mc":[{"id":"1.231659919","rc":[{"batb":[[0,2.1,10],[1,2.08,18.33],[2,2.06,35.79]],"ltp":2.2,"tv":36.93,"id":40096579}]}]}
{"op":"mcm","clk":"11843346636","pt":1723579592580,"mc":[{"id":"1.231659919","rc":[{"batb":[[0,2.08,18.33],[1,2.06,35.79],[2,1.89,222]],"ltp":2.2,"tv":36.93,"id":40096579}]}]}
{"op":"mcm","clk":"11843347020","pt":1723579594859,"mc":[{"id":"1.231659919","rc":[{"batb":[[0,2.1,10],[1,2.08,18.33],[2,2.06,35.79]],"ltp":2.2,"tv":36.93,"id":40096579}]}]}
{"op":"mcm","clk":"11843347572","pt":1723579598368,"mc":[{"id":"1.231659919","rc":[{"batb":[[0,2.08,18.33],[1,2.06,35.79],[2,1.89,222]],"ltp":2.2,"tv":36.93,"id":40096579}]}]}
{"op":"mcm","clk":"11843348714","pt":1723579605496,"mc":[{"id":"1.231659919","rc":[{"batb":[[0,2.1,10],[1,2.08,18.33],[2,2.06,35.79]],"ltp":2.2,"tv":36.93,"id":40096579}]}]}
{"op":"mcm","clk":"11843349349","pt":1723579609381,"mc":[{"id":"1.231659919","rc":[{"batb":[[0,2.08,18.33],[1,2.06,35.79],[2,1.89,222]],"ltp":2.2,"tv":36.93,"id":40096579}]}]}
{"op":"mcm","clk":"11843349791","pt":1723579612061,"mc":[{"id":"1.231659919","rc":[{"batb":[[0,2.1,10],[1,2.08,18.33],[2,2.06,35.79]],"ltp":2.2,"tv":36.93,"id":40096579}]}]}
{"op":"mcm","clk":"11843350368","pt":1723579615494,"mc":[{"id":"1.231659919","rc":[{"batb":[[0,2.08,18.33],[1,2.06,35.79],[2,1.89,222]],"ltp":2.2,"tv":36.93,"id":40096579}]}]}
{"op":"mcm","clk":"11843351044","pt":1723579619708,"mc":[{"id":"1.231659919","rc":[{"batb":[[0,2.1,10],[1,2.08,18.33],[2,2.06,35.79]],"ltp":2.2,"tv":36.93,"id":40096579}]}]}
{"op":"mcm","clk":"11843351675","pt":1723579623593,"mc":[{"id":"1.231659919","rc":[{"batb":[[0,2.08,18.33],[1,2.06,35.79],[2,1.89,222]],"ltp":2.2,"tv":36.93,"id":40096579}]}]}
{"op":"mcm","clk":"11843352124","pt":1723579626603,"mc":[{"id":"1.231659919","rc":[{"batb":[[0,2.1,10],[1,2.08,18.33],[2,2.06,35.79]],"ltp":2.2,"tv":36.93,"id":40096579}]}]}
{"op":"mcm","clk":"11843353433","pt":1723579634423,"mc":[{"id":"1.231659919","rc":[{"batb":[[0,2.08,18.33],[1,2.06,35.79],[2,1.89,222]],"ltp":2.2,"tv":36.93,"id":40096579}]}]}
{"op":"mcm","clk":"11843354829","pt":1723579642147,"mc":[{"id":"1.231659919","rc":[{"batb":[[0,2.1,10],[1,2.08,18.33],[2,2.06,35.79]],"ltp":2.2,"tv":36.93,"id":40096579}]}]}
{"op":"mcm","clk":"11843356400","pt":1723579651832,"mc":[{"id":"1.231659919","rc":[{"batb":[[0,2.08,18.33],[1,2.06,35.79],[2,1.89,222]],"ltp":2.2,"tv":36.93,"id":40096579}]}]}
{"op":"mcm","clk":"11843356818","pt":1723579654411,"mc":[{"id":"1.231659919","rc":[{"batb":[[0,2.12,10],[1,2.08,18.33],[2,2.06,35.79]],"ltp":2.2,"tv":36.93,"id":40096579}]}]}
{"op":"mcm","clk":"11843357558","pt":1723579658630,"mc":[{"id":"1.231659919","rc":[{"batb":[[2,1.89,222]],"ltp":2.2,"tv":36.93,"id":40096579},{"batb":[[2,1.78,138.46]],"ltp":1.83,"tv":192.4,"id":40096581}]}]}
{"op":"mcm","clk":"11843358001","pt":1723579661262,"mc":[{"id":"1.231659919","rc":[{"batb":[[0,2.08,18.33],[1,1.89,222],[2,1.86,555]],"ltp":2.2,"tv":36.93,"id":40096579}]}]}
{"op":"mcm","clk":"11843358481","pt":1723579663952,"mc":[{"id":"1.231659919","rc":[{"batb":[[0,2.1,10],[1,2.08,18.33],[2,2.06,35.79]],"ltp":2.2,"tv":36.93,"id":40096579},{"batb":[[2,1.82,46.27]],"ltp":1.83,"tv":192.4,"id":40096581}]}]}
{"op":"mcm","clk":"11843359515","pt":1723579669788,"mc":[{"id":"1.231659919","rc":[{"batb":[[0,2.08,18.33],[1,2.06,35.79],[2,1.89,222]],"ltp":2.2,"tv":36.93,"id":40096579}]}]}
{"op":"mcm","clk":"11843360212","pt":1723579674170,"mc":[{"id":"1.231659919","rc":[{"batb":[[0,2.1,10],[1,2.08,18.33],[2,2.06,35.79]],"ltp":2.2,"tv":36.93,"id":40096579}]}]}
{"op":"mcm","clk":"11843360870","pt":1723579677959,"mc":[{"id":"1.231659919","rc":[{"batb":[[0,2.08,18.33],[1,2.06,35.79],[2,1.89,222]],"ltp":2.2,"tv":36.93,"id":40096579}]}]}
{"op":"mcm","clk":"11843361386","pt":1723579681254,"mc":[{"id":"1.231659919","rc":[{"batb":[[0,2.1,10],[1,2.08,18.33],[2,2.06,35.79]],"ltp":2.2,"tv":36.93,"id":40096579}]}]}
{"op":"mcm","clk":"11843361966","pt":1723579684669,"mc":[{"id":"1.231659919","rc":[{"batb":[[0,2.08,18.33],[1,2.06,35.79],[2,1.89,222]],"ltp":2.2,"tv":36.93,"id":40096579}]}]}
{"op":"mcm","clk":"11843362525","pt":1723579688077,"mc":[{"id":"1.231659919","rc":[{"batb":[[0,2.1,10],[1,2.08,18.33],[2,2.06,35.79]],"ltp":2.2,"tv":36.93,"id":40096579}]}]}
{"op":"mcm","clk":"11843363096","pt":1723579691545,"mc":[{"id":"1.231659919","rc":[{"batb":[[0,2.08,18.33],[1,2.06,35.79],[2,1.89,222]],"ltp":2.2,"tv":36.93,"id":40096579}]}]}
{"op":"mcm","clk":"11843363628","pt":1723579694953,"mc":[{"id":"1.231659919","rc":[{"batb":[[0,2.1,10],[1,2.08,18.33],[2,2.06,35.79]],"ltp":2.2,"tv":36.93,"id":40096579}]}]}
{"op":"mcm","clk":"11843364169","pt":1723579698384,"mc":[{"id":"1.231659919","rc":[{"batb":[[0,2.08,18.33],[1,2.06,35.79],[2,1.89,222]],"ltp":2.2,"tv":36.93,"id":40096579}]}]}
{"op":"mcm","clk":"11843364613","pt":1723579701181,"mc":[{"id":"1.231659919","rc":[{"batb":[[0,2.1,10],[1,2.08,18.33],[2,2.06,35.79]],"ltp":2.2,"tv":36.93,"id":40096579}]}]}
{"op":"mcm","clk":"11843365186","pt":1723579704564,"mc":[{"id":"1.231659919","rc":[{"batb":[[0,2.08,18.33],[1,2.06,35.79],[2,1.89,222]],"ltp":2.2,"tv":36.93,"id":40096579}]}]}
{"op":"mcm","clk":"11843365705","pt":1723579707523,"mc":[{"id":"1.231659919","rc":[{"batb":[[0,2.1,10],[1,2.08,18.33],[2,2.06,35.79]],"ltp":2.2,"tv":36.93,"id":40096579}]}]}
{"op":"mcm","clk":"11843366289","pt":1723579710809,"mc":[{"id":"1.231659919","rc":[{"batb":[[0,2.08,18.33],[1,2.06,35.79],[2,1.89,222]],"ltp":2.2,"tv":36.93,"id":40096579}]}]}
{"op":"mcm","clk":"11843367031","pt":1723579715125,"mc":[{"id":"1.231659919","rc":[{"batb":[[0,2.1,10],[1,2.08,18.33],[2,2.06,35.79]],"ltp":2.2,"tv":36.93,"id":40096579}]}]}
{"op":"mcm","clk":"11843367635","pt":1723579718705,"mc":[{"id":"1.231659919","rc":[{"batb":[[0,2.08,18.33],[1,2.06,35.79],[2,1.89,222]],"ltp":2.2,"tv":36.93,"id":40096579}]}]}
{"op":"mcm","clk":"11843368768","pt":1723579725320,"mc":[{"id":"1.231659919","rc":[{"batb":[[0,2.1,10],[1,2.08,18.33],[2,2.06,35.79]],"ltp":2.2,"tv":36.93,"id":40096579}]}]}
{"op":"mcm","clk":"11843369188","pt":1723579727896,"mc":[{"id":"1.231659919","rc":[{"batl":[[0,2.16,16.79],[1,2.36,1],[2,12,0.52]],"ltp":2.2,"tv":36.93,"id":40096579}]}]}
{"op":"mcm","clk":"11843369297","pt":1723579728626,"mc":[{"id":"1.231659919","rc":[{"batb":[[0,2.08,18.33],[1,2.06,35.79],[2,1.89,222]],"ltp":2.2,"tv":36.93,"id":40096579}]}]}
{"op":"mcm","clk":"11843377262","pt":1723579773994,"mc":[{"id":"1.231659919","rc":[{"batl":[[1,1.92,2]],"ltp":1.83,"tv":192.4,"id":40096581}]}]}
{"op":"mcm","clk":"11843403555","pt":1723579948518,"mc":[{"id":"1.231659919","rc":[{"batl":[[2,1.98,138.46]],"ltp":1.83,"tv":192.4,"id":40096581}]}]}
{"op":"mcm","clk":"11843408866","pt":1723579985351,"mc":[{"id":"1.231659919","rc":[{"batb":[[1,1.82,46.27],[2,1.78,138.46]],"ltp":1.83,"tv":192.4,"id":40096581}]}]}
{"op":"mcm","clk":"11843457018","pt":1723580322386,"mc":[{"id":"1.231659919","rc":[{"batb":[[0,2.1,10],[1,2.08,18.33],[2,2.06,35.79]],"batl":[[0,2.36,1],[1,12,0.52],[2,12,0]],"ltp":2.2,"tv":36.93,"id":40096579}]}]}
{"op":"mcm","clk":"11843457481","pt":1723580325679,"mc":[{"id":"1.231659919","rc":[{"batb":[[0,2.08,18.33],[1,2.06,35.79],[2,1.89,222]],"ltp":2.2,"tv":36.93,"id":40096579}]}]}
{"op":"mcm","clk":"11843458033","pt":1723580329059,"mc":[{"id":"1.231659919","rc":[{"batb":[[0,2.1,10],[1,2.08,18.33],[2,2.06,35.79]],"ltp":2.2,"tv":36.93,"id":40096579}]}]}
{"op":"mcm","clk":"11843458515","pt":1723580332358,"mc":[{"id":"1.231659919","rc":[{"batb":[[0,2.08,18.33],[1,2.06,35.79],[2,1.89,222]],"ltp":2.2,"tv":36.93,"id":40096579}]}]}
{"op":"mcm","clk":"11843459078","pt":1723580336297,"mc":[{"id":"1.231659919","rc":[{"batb":[[0,2.1,10],[1,2.08,18.33],[2,2.06,35.79]],"ltp":2.2,"tv":36.93,"id":40096579}]}]}
{"op":"mcm","clk":"11843459591","pt":1723580339896,"mc":[{"id":"1.231659919","rc":[{"batb":[[0,2.08,18.33],[1,2.06,35.79],[2,1.89,222]],"ltp":2.2,"tv":36.93,"id":40096579}]}]}
{"op":"mcm","clk":"11843460063","pt":1723580342977,"mc":[{"id":"1.231659919","rc":[{"batb":[[0,2.1,10],[1,2.08,18.33],[2,2.06,35.79]],"ltp":2.2,"tv":36.93,"id":40096579}]}]}
{"op":"mcm","clk":"11843460545","pt":1723580346275,"mc":[{"id":"1.231659919","rc":[{"batb":[[0,2.08,18.33],[1,2.06,35.79],[2,1.89,222]],"ltp":2.2,"tv":36.93,"id":40096579}]}]}
{"op":"mcm","clk":"11843461364","pt":1723580351602,"mc":[{"id":"1.231659919","rc":[{"batb":[[0,2.1,10],[1,2.08,18.33],[2,2.06,35.79]],"ltp":2.2,"tv":36.93,"id":40096579}]}]}
{"op":"mcm","clk":"11843461902","pt":1723580355119,"mc":[{"id":"1.231659919","rc":[{"batb":[[0,2.08,18.33],[1,2.06,35.79],[2,1.89,222]],"ltp":2.2,"tv":36.93,"id":40096579}]}]}
{"op":"mcm","clk":"11843462275","pt":1723580357524,"mc":[{"id":"1.231659919","rc":[{"batb":[[0,2.1,10],[1,2.08,18.33],[2,2.06,35.79]],"ltp":2.2,"tv":36.93,"id":40096579}]}]}
{"op":"mcm","clk":"11843462877","pt":1723580361023,"mc":[{"id":"1.231659919","rc":[{"batb":[[0,2.08,18.33],[1,2.06,35.79],[2,1.89,222]],"ltp":2.2,"tv":36.93,"id":40096579}]}]}
{"op":"mcm","clk":"11843463389","pt":1723580363911,"mc":[{"id":"1.231659919","rc":[{"batb":[[0,2.1,10],[1,2.08,18.33],[2,2.06,35.79]],"ltp":2.2,"tv":36.93,"id":40096579}]}]}
{"op":"mcm","clk":"11843464051","pt":1723580367884,"mc":[{"id":"1.231659919","rc":[{"batb":[[0,2.08,18.33],[1,2.06,35.79],[2,1.89,222]],"ltp":2.2,"tv":36.93,"id":40096579}]}]}
{"op":"mcm","clk":"11843464491","pt":1723580370396,"mc":[{"id":"1.231659919","rc":[{"batb":[[0,2.1,10],[1,2.08,18.33],[2,2.06,35.79]],"ltp":2.2,"tv":36.93,"id":40096579}]}]}
{"op":"mcm","clk":"11843465046","pt":1723580373932,"mc":[{"id":"1.231659919","rc":[{"batb":[[0,2.08,18.33],[1,2.06,35.79],[2,1.89,222]],"ltp":2.2,"tv":36.93,"id":40096579}]}]}
{"op":"mcm","clk":"11843465418","pt":1723580376328,"mc":[{"id":"1.231659919","rc":[{"batb":[[0,2.1,10],[1,2.08,18.33],[2,2.06,35.79]],"ltp":2.2,"tv":36.93,"id":40096579}]}]}
{"op":"mcm","clk":"11843466022","pt":1723580380128,"mc":[{"id":"1.231659919","rc":[{"batb":[[0,2.08,18.33],[1,2.06,35.79],[2,1.89,222]],"ltp":2.2,"tv":36.93,"id":40096579}]}]}
{"op":"mcm","clk":"11843466765","pt":1723580384829,"mc":[{"id":"1.231659919","rc":[{"batb":[[0,2.1,10],[1,2.08,18.33],[2,2.06,35.79]],"ltp":2.2,"tv":36.93,"id":40096579}]}]}
{"op":"mcm","clk":"11843467380","pt":1723580388233,"mc":[{"id":"1.231659919","rc":[{"batb":[[0,2.08,18.33],[1,2.06,35.79],[2,1.89,222]],"ltp":2.2,"tv":36.93,"id":40096579}]}]}
{"op":"mcm","clk":"11843467944","pt":1723580391929,"mc":[{"id":"1.231659919","rc":[{"batb":[[0,2.1,10],[1,2.08,18.33],[2,2.06,35.79]],"ltp":2.2,"tv":36.93,"id":40096579}]}]}
{"op":"mcm","clk":"11843468455","pt":1723580395327,"mc":[{"id":"1.231659919","rc":[{"batb":[[0,2.08,18.33],[1,2.06,35.79],[2,1.89,222]],"ltp":2.2,"tv":36.93,"id":40096579}]}]}
{"op":"mcm","clk":"11843469349","pt":1723580400964,"mc":[{"id":"1.231659919","rc":[{"batb":[[0,2.1,10],[1,2.08,18.33],[2,2.06,35.79]],"ltp":2.2,"tv":36.93,"id":40096579}]}]}
{"op":"mcm","clk":"11843469952","pt":1723580404629,"mc":[{"id":"1.231659919","rc":[{"batb":[[0,2.08,18.33],[1,2.06,35.79],[2,1.89,222]],"ltp":2.2,"tv":36.93,"id":40096579}]}]}
{"op":"mcm","clk":"11843470524","pt":1723580408238,"mc":[{"id":"1.231659919","rc":[{"batb":[[0,2.1,10],[1,2.08,18.33],[2,2.06,35.79]],"ltp":2.2,"tv":36.93,"id":40096579}]}]}
{"op":"mcm","clk":"11843471165","pt":1723580412160,"mc":[{"id":"1.231659919","rc":[{"batb":[[0,2.08,18.33],[1,2.06,35.79],[2,1.89,222]],"ltp":2.2,"tv":36.93,"id":40096579}]}]}
{"op":"mcm","clk":"11843471510","pt":1723580414458,"mc":[{"id":"1.231659919","rc":[{"batb":[[0,2.1,10],[1,2.08,18.33],[2,2.06,35.79]],"ltp":2.2,"tv":36.93,"id":40096579}]}]}
{"op":"mcm","clk":"11843472118","pt":1723580418071,"mc":[{"id":"1.231659919","rc":[{"batb":[[0,2.08,18.33],[1,2.06,35.79],[2,1.89,222]],"ltp":2.2,"tv":36.93,"id":40096579}]}]}
{"op":"mcm","clk":"11843472436","pt":1723580420360,"mc":[{"id":"1.231659919","rc":[{"batb":[[0,2.1,10],[1,2.08,18.33],[2,2.06,35.79]],"ltp":2.2,"tv":36.93,"id":40096579}]}]}
{"op":"mcm","clk":"11843472972","pt":1723580424060,"mc":[{"id":"1.231659919","rc":[{"batb":[[0,2.08,18.33],[1,2.06,35.79],[2,1.89,222]],"ltp":2.2,"tv":36.93,"id":40096579}]}]}
{"op":"mcm","clk":"11843473396","pt":1723580427284,"mc":[{"id":"1.231659919","rc":[{"batb":[[0,2.1,10],[1,2.08,18.33],[2,2.06,35.79]],"ltp":2.2,"tv":36.93,"id":40096579}]}]}
{"op":"mcm","clk":"11843473954","pt":1723580431054,"mc":[{"id":"1.231659919","rc":[{"batb":[[0,2.08,18.33],[1,2.06,35.79],[2,1.89,222]],"ltp":2.2,"tv":36.93,"id":40096579}]}]}
{"op":"mcm","clk":"11843474441","pt":1723580434282,"mc":[{"id":"1.231659919","rc":[{"batb":[[0,2.1,10],[1,2.08,18.33],[2,2.06,35.79]],"ltp":2.2,"tv":36.93,"id":40096579}]}]}
{"op":"mcm","clk":"11843474947","pt":1723580437570,"mc":[{"id":"1.231659919","rc":[{"batb":[[0,2.08,18.33],[1,2.06,35.79],[2,1.89,222]],"ltp":2.2,"tv":36.93,"id":40096579}]}]}
{"op":"mcm","clk":"11843475288","pt":1723580439907,"mc":[{"id":"1.231659919","rc":[{"batb":[[0,2.1,10],[1,2.08,18.33],[2,2.06,35.79]],"ltp":2.2,"tv":36.93,"id":40096579}]}]}
{"op":"mcm","clk":"11843475787","pt":1723580443405,"mc":[{"id":"1.231659919","rc":[{"batb":[[0,2.08,18.33],[1,2.06,35.79],[2,1.89,222]],"ltp":2.2,"tv":36.93,"id":40096579}]}]}
{"op":"mcm","clk":"11843476202","pt":1723580446380,"mc":[{"id":"1.231659919","rc":[{"batb":[[0,2.1,10],[1,2.08,18.33],[2,2.06,35.79]],"ltp":2.2,"tv":36.93,"id":40096579}]}]}
{"op":"mcm","clk":"11843476713","pt":1723580449974,"mc":[{"id":"1.231659919","rc":[{"batb":[[0,2.08,18.33],[1,2.06,35.79],[2,1.89,222]],"ltp":2.2,"tv":36.93,"id":40096579}]}]}
{"op":"mcm","clk":"11843477877","pt":1723580458718,"mc":[{"id":"1.231659919","rc":[{"batb":[[0,2.1,10],[1,2.08,18.33],[2,2.06,35.79]],"ltp":2.2,"tv":36.93,"id":40096579}]}]}
{"op":"mcm","clk":"11843478470","pt":1723580462236,"mc":[{"id":"1.231659919","rc":[{"batb":[[0,2.08,18.33],[1,2.06,35.79],[2,1.89,222]],"ltp":2.2,"tv":36.93,"id":40096579}]}]}
{"op":"mcm","clk":"11843478851","pt":1723580465099,"mc":[{"id":"1.231659919","rc":[{"batb":[[0,2.1,10],[1,2.08,18.33],[2,2.06,35.79]],"ltp":2.2,"tv":36.93,"id":40096579}]}]}
{"op":"mcm","clk":"11843479362","pt":1723580468909,"mc":[{"id":"1.231659919","rc":[{"batb":[[0,2.08,18.33],[1,2.06,35.79],[2,1.89,222]],"ltp":2.2,"tv":36.93,"id":40096579}]}]}
{"op":"mcm","clk":"11843479765","pt":1723580471514,"mc":[{"id":"1.231659919","rc":[{"batb":[[0,2.1,10],[1,2.08,18.33],[2,2.06,35.79]],"ltp":2.2,"tv":36.93,"id":40096579}]}]}
{"op":"mcm","clk":"11843480296","pt":1723580475306,"mc":[{"id":"1.231659919","rc":[{"batb":[[0,2.08,18.33],[1,2.06,35.79],[2,1.89,222]],"ltp":2.2,"tv":36.93,"id":40096579}]}]}
{"op":"mcm","clk":"11843480852","pt":1723580479116,"mc":[{"id":"1.231659919","rc":[{"batb":[[0,2.1,10],[1,2.08,18.33],[2,2.06,35.79]],"ltp":2.2,"tv":36.93,"id":40096579}]}]}
{"op":"mcm","clk":"11843481463","pt":1723580483132,"mc":[{"id":"1.231659919","rc":[{"batb":[[0,2.08,18.33],[1,2.06,35.79],[2,1.89,222]],"ltp":2.2,"tv":36.93,"id":40096579}]}]}
{"op":"mcm","clk":"11843481866","pt":1723580486148,"mc":[{"id":"1.231659919","rc":[{"batb":[[0,2.1,10],[1,2.08,18.33],[2,2.06,35.79]],"ltp":2.2,"tv":36.93,"id":40096579}]}]}
{"op":"mcm","clk":"11843482366","pt":1723580489854,"mc":[{"id":"1.231659919","rc":[{"batb":[[0,2.08,18.33],[1,2.06,35.79],[2,1.89,222]],"ltp":2.2,"tv":36.93,"id":40096579}]}]}
{"op":"mcm","clk":"11843482814","pt":1723580492624,"mc":[{"id":"1.231659919","rc":[{"batb":[[0,2.1,10],[1,2.08,18.33],[2,2.06,35.79]],"ltp":2.2,"tv":36.93,"id":40096579}]}]}
{"op":"mcm","clk":"11843483312","pt":1723580496428,"mc":[{"id":"1.231659919","rc":[{"batb":[[0,2.08,18.33],[1,2.06,35.79],[2,1.89,222]],"ltp":2.2,"tv":36.93,"id":40096579}]}]}
{"op":"mcm","clk":"11843483735","pt":1723580499458,"mc":[{"id":"1.231659919","rc":[{"batb":[[0,2.1,10],[1,2.08,18.33],[2,2.06,35.79]],"ltp":2.2,"tv":36.93,"id":40096579}]}]}
{"op":"mcm","clk":"11843484285","pt":1723580503273,"mc":[{"id":"1.231659919","rc":[{"batb":[[0,2.08,18.33],[1,2.06,35.79],[2,1.89,222]],"ltp":2.2,"tv":36.93,"id":40096579}]}]}
{"op":"mcm","clk":"11843484788","pt":1723580506966,"mc":[{"id":"1.231659919","rc":[{"batb":[[0,2.1,10],[1,2.08,18.33],[2,2.06,35.79]],"ltp":2.2,"tv":36.93,"id":40096579}]}]}
{"op":"mcm","clk":"11843485342","pt":1723580510766,"mc":[{"id":"1.231659919","rc":[{"batb":[[0,2.08,18.33],[1,2.06,35.79],[2,1.89,222]],"ltp":2.2,"tv":36.93,"id":40096579}]}]}
{"op":"mcm","clk":"11843485733","pt":1723580513490,"mc":[{"id":"1.231659919","rc":[{"batb":[[0,2.1,10],[1,2.08,18.33],[2,2.06,35.79]],"ltp":2.2,"tv":36.93,"id":40096579}]}]}
{"op":"mcm","clk":"11843486280","pt":1723580517260,"mc":[{"id":"1.231659919","rc":[{"batb":[[0,2.08,18.33],[1,2.06,35.79],[2,1.89,222]],"ltp":2.2,"tv":36.93,"id":40096579}]}]}
{"op":"mcm","clk":"11843486692","pt":1723580520241,"mc":[{"id":"1.231659919","rc":[{"batb":[[0,2.1,10],[1,2.08,18.33],[2,2.06,35.79]],"ltp":2.2,"tv":36.93,"id":40096579}]}]}
{"op":"mcm","clk":"11843487236","pt":1723580523855,"mc":[{"id":"1.231659919","rc":[{"batb":[[0,2.08,18.33],[1,2.06,35.79],[2,1.89,222]],"ltp":2.2,"tv":36.93,"id":40096579}]}]}
{"op":"mcm","clk":"11843487685","pt":1723580526682,"mc":[{"id":"1.231659919","rc":[{"batb":[[0,2.1,10],[1,2.08,18.33],[2,2.06,35.79]],"ltp":2.2,"tv":36.93,"id":40096579}]}]}
{"op":"mcm","clk":"11843488231","pt":1723580530311,"mc":[{"id":"1.231659919","rc":[{"batb":[[0,2.08,18.33],[1,2.06,35.79],[2,1.89,222]],"ltp":2.2,"tv":36.93,"id":40096579}]}]}
{"op":"mcm","clk":"11843488643","pt":1723580532795,"mc":[{"id":"1.231659919","rc":[{"batb":[[0,2.1,10],[1,2.08,18.33],[2,2.06,35.79]],"ltp":2.2,"tv":36.93,"id":40096579}]}]}
{"op":"mcm","clk":"11843489227","pt":1723580536704,"mc":[{"id":"1.231659919","rc":[{"batb":[[0,2.08,18.33],[1,2.06,35.79],[2,1.89,222]],"ltp":2.2,"tv":36.93,"id":40096579}]}]}
{"op":"mcm","clk":"11843489700","pt":1723580539991,"mc":[{"id":"1.231659919","rc":[{"batb":[[0,2.1,10],[1,2.08,18.33],[2,2.06,35.79]],"ltp":2.2,"tv":36.93,"id":40096579}]}]}
{"op":"mcm","clk":"11843490204","pt":1723580543318,"mc":[{"id":"1.231659919","rc":[{"batb":[[0,2.08,18.33],[1,2.06,35.79],[2,1.89,222]],"ltp":2.2,"tv":36.93,"id":40096579}]}]}
{"op":"mcm","clk":"11843491183","pt":1723580550032,"mc":[{"id":"1.231659919","rc":[{"batb":[[0,2.1,10],[1,2.08,18.33],[2,2.06,35.79]],"ltp":2.2,"tv":36.93,"id":40096579}]}]}
{"op":"mcm","clk":"11843491710","pt":1723580553427,"mc":[{"id":"1.231659919","rc":[{"batb":[[0,2.08,18.33],[1,2.06,35.79],[2,1.89,222]],"ltp":2.2,"tv":36.93,"id":40096579}]}]}
{"op":"mcm","clk":"11843492182","pt":1723580556448,"mc":[{"id":"1.231659919","rc":[{"batb":[[0,2.1,10],[1,2.08,18.33],[2,2.06,35.79]],"ltp":2.2,"tv":36.93,"id":40096579}]}]}
{"op":"mcm","clk":"11843492745","pt":1723580560212,"mc":[{"id":"1.231659919","rc":[{"batb":[[0,2.08,18.33],[1,2.06,35.79],[2,1.89,222]],"ltp":2.2,"tv":36.93,"id":40096579}]}]}
{"op":"mcm","clk":"11843493281","pt":1723580563604,"mc":[{"id":"1.231659919","rc":[{"batb":[[0,2.1,10],[1,2.08,18.33],[2,2.06,35.79]],"ltp":2.2,"tv":36.93,"id":40096579}]}]}
{"op":"mcm","clk":"11843493879","pt":1723580567643,"mc":[{"id":"1.231659919","rc":[{"batb":[[0,2.08,18.33],[1,2.06,35.79],[2,1.89,222]],"ltp":2.2,"tv":36.93,"id":40096579}]}]}
{"op":"mcm","clk":"11843494284","pt":1723580570548,"mc":[{"id":"1.231659919","rc":[{"batb":[[0,2.1,10],[1,2.08,18.33],[2,2.06,35.79]],"ltp":2.2,"tv":36.93,"id":40096579}]}]}
{"op":"mcm","clk":"11843494822","pt":1723580574039,"mc":[{"id":"1.231659919","rc":[{"batb":[[0,2.08,18.33],[1,2.06,35.79],[2,1.89,222]],"ltp":2.2,"tv":36.93,"id":40096579}]}]}
{"op":"mcm","clk":"11843495419","pt":1723580577962,"mc":[{"id":"1.231659919","rc":[{"batb":[[0,2.1,10],[1,2.08,18.33],[2,2.06,35.79]],"ltp":2.2,"tv":36.93,"id":40096579}]}]}
{"op":"mcm","clk":"11843495992","pt":1723580581669,"mc":[{"id":"1.231659919","rc":[{"batb":[[0,2.08,18.33],[1,2.06,35.79],[2,1.89,222]],"ltp":2.2,"tv":36.93,"id":40096579}]}]}
{"op":"mcm","clk":"11843496618","pt":1723580585764,"mc":[{"id":"1.231659919","rc":[{"batb":[[0,2.1,10],[1,2.08,18.33],[2,2.06,35.79]],"ltp":2.2,"tv":36.93,"id":40096579}]}]}
{"op":"mcm","clk":"11843497222","pt":1723580589474,"mc":[{"id":"1.231659919","rc":[{"batb":[[0,2.08,18.33],[1,2.06,35.79],[2,1.89,222]],"ltp":2.2,"tv":36.93,"id":40096579}]}]}
{"op":"mcm","clk":"11843497587","pt":1723580591876,"mc":[{"id":"1.231659919","rc":[{"batb":[[0,2.1,10],[1,2.08,18.33],[2,2.06,35.79]],"ltp":2.2,"tv":36.93,"id":40096579}]}]}
{"op":"mcm","clk":"11843498088","pt":1723580595379,"mc":[{"id":"1.231659919","rc":[{"batb":[[0,2.08,18.33],[1,2.06,35.79],[2,1.89,222]],"ltp":2.2,"tv":36.93,"id":40096579}]}]}
{"op":"mcm","clk":"11843498485","pt":1723580598050,"mc":[{"id":"1.231659919","rc":[{"batb":[[0,2.1,10],[1,2.08,18.33],[2,2.06,35.79]],"ltp":2.2,"tv":36.93,"id":40096579}]}]}
{"op":"mcm","clk":"11843499001","pt":1723580601600,"mc":[{"id":"1.231659919","rc":[{"batb":[[0,2.08,18.33],[1,2.06,35.79],[2,1.89,222]],"ltp":2.2,"tv":36.93,"id":40096579}]}]}
{"op":"mcm","clk":"11843499343","pt":1723580604012,"mc":[{"id":"1.231659919","rc":[{"batb":[[0,2.1,10],[1,2.08,18.33],[2,2.06,35.79]],"ltp":2.2,"tv":36.93,"id":40096579}]}]}
{"op":"mcm","clk":"11843499854","pt":1723580607590,"mc":[{"id":"1.231659919","rc":[{"batb":[[0,2.08,18.33],[1,2.06,35.79],[2,1.89,222]],"ltp":2.2,"tv":36.93,"id":40096579}]}]}
{"op":"mcm","clk":"11843500222","pt":1723580610301,"mc":[{"id":"1.231659919","rc":[{"batb":[[0,2.1,10],[1,2.08,18.33],[2,2.06,35.79]],"ltp":2.2,"tv":36.93,"id":40096579}]}]}
{"op":"mcm","clk":"11843500811","pt":1723580614189,"mc":[{"id":"1.231659919","rc":[{"batb":[[0,2.08,18.33],[1,2.06,35.79],[2,1.89,222]],"ltp":2.2,"tv":36.93,"id":40096579}]}]}
{"op":"mcm","clk":"11843501454","pt":1723580618711,"mc":[{"id":"1.231659919","rc":[{"batb":[[0,2.1,10],[1,2.08,18.33],[2,2.06,35.79]],"ltp":2.2,"tv":36.93,"id":40096579}]}]}
{"op":"mcm","clk":"11843501986","pt":1723580622408,"mc":[{"id":"1.231659919","rc":[{"batb":[[0,2.08,18.33],[1,2.06,35.79],[2,1.89,222]],"ltp":2.2,"tv":36.93,"id":40096579}]}]}
{"op":"mcm","clk":"11843502571","pt":1723580626521,"mc":[{"id":"1.231659919","rc":[{"batb":[[0,2.1,10],[1,2.08,18.33],[2,2.06,35.79]],"ltp":2.2,"tv":36.93,"id":40096579}]}]}
{"op":"mcm","clk":"11843503100","pt":1723580630029,"mc":[{"id":"1.231659919","rc":[{"batb":[[0,2.08,18.33],[1,2.06,35.79],[2,1.89,222]],"ltp":2.2,"tv":36.93,"id":40096579}]}]}
{"op":"mcm","clk":"11843503755","pt":1723580634196,"mc":[{"id":"1.231659919","rc":[{"batb":[[0,2.1,10],[1,2.08,18.33],[2,2.06,35.79]],"ltp":2.2,"tv":36.93,"id":40096579}]}]}
{"op":"mcm","clk":"11843504265","pt":1723580637827,"mc":[{"id":"1.231659919","rc":[{"batb":[[0,2.08,18.33],[1,2.06,35.79],[2,1.89,222]],"ltp":2.2,"tv":36.93,"id":40096579}]}]}
{"op":"mcm","clk":"11843504865","pt":1723580641844,"mc":[{"id":"1.231659919","rc":[{"batb":[[0,2.1,10],[1,2.08,18.33],[2,2.06,35.79]],"ltp":2.2,"tv":36.93,"id":40096579}]}]}
{"op":"mcm","clk":"11843505474","pt":1723580645708,"mc":[{"id":"1.231659919","rc":[{"batb":[[0,2.08,18.33],[1,2.06,35.79],[2,1.89,222]],"ltp":2.2,"tv":36.93,"id":40096579}]}]}
{"op":"mcm","clk":"11843505955","pt":1723580648833,"mc":[{"id":"1.231659919","rc":[{"batb":[[0,2.1,10],[1,2.08,18.33],[2,2.06,35.79]],"ltp":2.2,"tv":36.93,"id":40096579}]}]}
{"op":"mcm","clk":"11843506555","pt":1723580652620,"mc":[{"id":"1.231659919","rc":[{"batb":[[0,2.08,18.33],[1,2.06,35.79],[2,1.89,222]],"ltp":2.2,"tv":36.93,"id":40096579}]}]}
{"op":"mcm","clk":"11843506935","pt":1723580655229,"mc":[{"id":"1.231659919","rc":[{"batb":[[0,2.1,10],[1,2.08,18.33],[2,2.06,35.79]],"ltp":2.2,"tv":36.93,"id":40096579}]}]}
{"op":"mcm","clk":"11843507466","pt":1723580659016,"mc":[{"id":"1.231659919","rc":[{"batb":[[0,2.08,18.33],[1,2.06,35.79],[2,1.89,222]],"ltp":2.2,"tv":36.93,"id":40096579}]}]}
{"op":"mcm","clk":"11843507841","pt":1723580661843,"mc":[{"id":"1.231659919","rc":[{"batb":[[0,2.1,10],[1,2.08,18.33],[2,2.06,35.79]],"ltp":2.2,"tv":36.93,"id":40096579}]}]}
{"op":"mcm","clk":"11843508404","pt":1723580665732,"mc":[{"id":"1.231659919","rc":[{"batb":[[0,2.08,18.33],[1,2.06,35.79],[2,1.89,222]],"ltp":2.2,"tv":36.93,"id":40096579}]}]}
{"op":"mcm","clk":"11843509151","pt":1723580671264,"mc":[{"id":"1.231659919","rc":[{"batb":[[0,2.1,10],[1,2.08,18.33],[2,2.06,35.79]],"ltp":2.2,"tv":36.93,"id":40096579}]}]}
{"op":"mcm","clk":"11843509717","pt":1723580675164,"mc":[{"id":"1.231659919","rc":[{"batb":[[0,2.08,18.33],[1,2.06,35.79],[2,1.89,222]],"ltp":2.2,"tv":36.93,"id":40096579}]}]}
{"op":"mcm","clk":"11843510231","pt":1723580678462,"mc":[{"id":"1.231659919","rc":[{"batb":[[0,2.1,10],[1,2.08,18.33],[2,2.06,35.79]],"ltp":2.2,"tv":36.93,"id":40096579}]}]}
{"op":"mcm","clk":"11843510735","pt":1723580681980,"mc":[{"id":"1.231659919","rc":[{"batb":[[0,2.08,18.33],[1,2.06,35.79],[2,1.89,222]],"ltp":2.2,"tv":36.93,"id":40096579}]}]}
{"op":"mcm","clk":"11843511156","pt":1723580684873,"mc":[{"id":"1.231659919","rc":[{"batb":[[0,2.1,10],[1,2.08,18.33],[2,2.06,35.79]],"ltp":2.2,"tv":36.93,"id":40096579}]}]}
{"op":"mcm","clk":"11843511634","pt":1723580688149,"mc":[{"id":"1.231659919","rc":[{"trd":[[1.86,126.62]],"batb":[[0,1.86,795.28]],"ltp":1.86,"tv":201.8,"id":40096581}],"tv":238.74}]}
{"op":"mcm","clk":"11843511677","pt":1723580688461,"mc":[{"id":"1.231659919","rc":[{"batb":[[0,2.08,18.33],[1,2.06,35.79],[2,1.89,222]],"ltp":2.2,"tv":36.93,"id":40096579}]}]}
{"op":"mcm","clk":"11843512034","pt":1723580690994,"mc":[{"id":"1.231659919","rc":[{"batb":[[0,2.1,10],[1,2.08,18.33],[2,2.06,35.79]],"ltp":2.2,"tv":36.93,"id":40096579}]}]}
{"op":"mcm","clk":"11843512582","pt":1723580694897,"mc":[{"id":"1.231659919","rc":[{"batb":[[0,2.08,18.33],[1,2.06,35.79],[2,1.89,222]],"ltp":2.2,"tv":36.93,"id":40096579}]}]}
{"op":"mcm","clk":"11843512906","pt":1723580697298,"mc":[{"id":"1.231659919","rc":[{"batb":[[0,2.1,10],[1,2.08,18.33],[2,2.06,35.79]],"ltp":2.2,"tv":36.93,"id":40096579}]}]}
{"op":"mcm","clk":"11843513430","pt":1723580700905,"mc":[{"id":"1.231659919","rc":[{"batb":[[0,2.08,18.33],[1,2.06,35.79],[2,1.89,222]],"ltp":2.2,"tv":36.93,"id":40096579}]}]}
{"op":"mcm","clk":"11843514030","pt":1723580705184,"mc":[{"id":"1.231659919","rc":[{"batb":[[0,2.1,10],[1,2.08,18.33],[2,2.06,35.79]],"ltp":2.2,"tv":36.93,"id":40096579}]}]}
{"op":"mcm","clk":"11843514522","pt":1723580708602,"mc":[{"id":"1.231659919","rc":[{"batb":[[0,2.08,18.33],[1,2.06,35.79],[2,1.89,222]],"ltp":2.2,"tv":36.93,"id":40096579}]}]}
{"op":"mcm","clk":"11843514936","pt":1723580711732,"mc":[{"id":"1.231659919","rc":[{"batb":[[0,2.1,10],[1,2.08,18.33],[2,2.06,35.79]],"ltp":2.2,"tv":36.93,"id":40096579}]}]}
{"op":"mcm","clk":"11843515445","pt":1723580715401,"mc":[{"id":"1.231659919","rc":[{"batb":[[0,2.08,18.33],[1,2.06,35.79],[2,1.89,222]],"ltp":2.2,"tv":36.93,"id":40096579}]}]}
{"op":"mcm","clk":"11843515803","pt":1723580717906,"mc":[{"id":"1.231659919","rc":[{"batb":[[0,2.1,10],[1,2.08,18.33],[2,2.06,35.79]],"ltp":2.2,"tv":36.93,"id":40096579}]}]}
{"op":"mcm","clk":"11843516311","pt":1723580721246,"mc":[{"id":"1.231659919","rc":[{"batb":[[0,2.08,18.33],[1,2.06,35.79],[2,1.89,222]],"ltp":2.2,"tv":36.93,"id":40096579}]}]}
{"op":"mcm","clk":"11843516856","pt":1723580724758,"mc":[{"id":"1.231659919","rc":[{"batb":[[0,2.1,10],[1,2.08,18.33],[2,2.06,35.79]],"ltp":2.2,"tv":36.93,"id":40096579}]}]}
{"op":"mcm","clk":"11843517390","pt":1723580728255,"mc":[{"id":"1.231659919","rc":[{"batb":[[0,2.08,18.33],[1,2.06,35.79],[2,1.89,222]],"ltp":2.2,"tv":36.93,"id":40096579}]}]}
{"op":"mcm","clk":"11843517752","pt":1723580730448,"mc":[{"id":"1.231659919","rc":[{"batb":[[0,2.1,10],[1,2.08,18.33],[2,2.06,35.79]],"ltp":2.2,"tv":36.93,"id":40096579}]}]}
{"op":"mcm","clk":"11843518344","pt":1723580734342,"mc":[{"id":"1.231659919","rc":[{"batb":[[0,2.08,18.33],[1,2.06,35.79],[2,1.89,222]],"ltp":2.2,"tv":36.93,"id":40096579}]}]}
{"op":"mcm","clk":"11843518788","pt":1723580737446,"mc":[{"id":"1.231659919","rc":[{"batb":[[0,2.1,10],[1,2.08,18.33],[2,2.06,35.79]],"ltp":2.2,"tv":36.93,"id":40096579}]}]}
{"op":"mcm","clk":"11843519371","pt":1723580741227,"mc":[{"id":"1.231659919","rc":[{"batb":[[0,2.08,18.33],[1,2.06,35.79],[2,1.89,222]],"ltp":2.2,"tv":36.93,"id":40096579}]}]}
{"op":"mcm","clk":"11843519798","pt":1723580744078,"mc":[{"id":"1.231659919","rc":[{"batb":[[0,2.1,10],[1,2.08,18.33],[2,2.06,35.79]],"ltp":2.2,"tv":36.93,"id":40096579}]}]}
{"op":"mcm","clk":"11843520364","pt":1723580747831,"mc":[{"id":"1.231659919","rc":[{"batb":[[0,2.08,18.33],[1,2.06,35.79],[2,1.89,222]],"ltp":2.2,"tv":36.93,"id":40096579}]}]}
{"op":"mcm","clk":"11843520763","pt":1723580750656,"mc":[{"id":"1.231659919","rc":[{"batb":[[0,2.1,10],[1,2.08,18.33],[2,2.06,35.79]],"ltp":2.2,"tv":36.93,"id":40096579}]}]}
{"op":"mcm","clk":"11843521273","pt":1723580754469,"mc":[{"id":"1.231659919","rc":[{"batb":[[0,2.08,18.33],[1,2.06,35.79],[2,1.89,222]],"ltp":2.2,"tv":36.93,"id":40096579}]}]}
{"op":"mcm","clk":"11843522197","pt":1723580761184,"mc":[{"id":"1.231659919","rc":[{"batb":[[0,2.1,10],[1,2.08,18.33],[2,2.06,35.79]],"ltp":2.2,"tv":36.93,"id":40096579}]}]}
{"op":"mcm","clk":"11843522905","pt":1723580765958,"mc":[{"id":"1.231659919","rc":[{"batb":[[0,2.08,18.33],[1,2.06,35.79],[2,1.89,222]],"ltp":2.2,"tv":36.93,"id":40096579}]}]}
{"op":"mcm","clk":"11843523542","pt":1723580770989,"mc":[{"id":"1.231659919","rc":[{"batb":[[0,2.1,10],[1,2.08,18.33],[2,2.06,35.79]],"ltp":2.2,"tv":36.93,"id":40096579}]}]}
{"op":"mcm","clk":"11843524209","pt":1723580776095,"mc":[{"id":"1.231659919","rc":[{"batb":[[0,2.08,18.33],[1,2.06,35.79],[2,1.89,222]],"ltp":2.2,"tv":36.93,"id":40096579}]}]}
{"op":"mcm","clk":"11843524601","pt":1723580779065,"mc":[{"id":"1.231659919","rc":[{"batb":[[0,2.1,10],[1,2.08,18.33],[2,2.06,35.79]],"ltp":2.2,"tv":36.93,"id":40096579}]}]}
{"op":"mcm","clk":"11843525133","pt":1723580783054,"mc":[{"id":"1.231659919","rc":[{"batb":[[0,2.08,18.33],[1,2.06,35.79],[2,1.89,222]],"ltp":2.2,"tv":36.93,"id":40096579}]}]}
{"op":"mcm","clk":"11843525489","pt":1723580785757,"mc":[{"id":"1.231659919","rc":[{"batb":[[0,2.1,10],[1,2.08,18.33],[2,2.06,35.79]],"ltp":2.2,"tv":36.93,"id":40096579}]}]}
{"op":"mcm","clk":"11843526004","pt":1723580789466,"mc":[{"id":"1.231659919","rc":[{"batb":[[0,2.08,18.33],[1,2.06,35.79],[2,1.89,222]],"ltp":2.2,"tv":36.93,"id":40096579}]}]}
{"op":"mcm","clk":"11843526565","pt":1723580793380,"mc":[{"id":"1.231659919","rc":[{"batb":[[0,2.1,10],[1,2.08,18.33],[2,2.06,35.79]],"ltp":2.2,"tv":36.93,"id":40096579}]}]}
{"op":"mcm","clk":"11843527170","pt":1723580797283,"mc":[{"id":"1.231659919","rc":[{"batb":[[0,2.08,18.33],[1,2.06,35.79],[2,1.89,222]],"ltp":2.2,"tv":36.93,"id":40096579}]}]}
{"op":"mcm","clk":"11843527710","pt":1723580801795,"mc":[{"id":"1.231659919","rc":[{"batb":[[0,2.1,10],[1,2.08,18.33],[2,2.06,35.79]],"ltp":2.2,"tv":36.93,"id":40096579}]}]}
{"op":"mcm","clk":"11843528168","pt":1723580805804,"mc":[{"id":"1.231659919","rc":[{"batb":[[0,2.08,18.33],[1,2.06,35.79],[2,1.89,222]],"ltp":2.2,"tv":36.93,"id":40096579}]}]}
{"op":"mcm","clk":"11843528713","pt":1723580810213,"mc":[{"id":"1.231659919","rc":[{"batb":[[0,2.1,10],[1,2.08,18.33],[2,2.06,35.79]],"ltp":2.2,"tv":36.93,"id":40096579}]}]}
{"op":"mcm","clk":"11843529222","pt":1723580813807,"mc":[{"id":"1.231659919","rc":[{"batb":[[0,2.08,18.33],[1,2.06,35.79],[2,1.89,222]],"ltp":2.2,"tv":36.93,"id":40096579}]}]}
{"op":"mcm","clk":"11843529747","pt":1723580818281,"mc":[{"id":"1.231659919","rc":[{"batb":[[0,2.1,10],[1,2.08,18.33],[2,2.06,35.79]],"ltp":2.2,"tv":36.93,"id":40096579}]}]}
{"op":"mcm","clk":"11843530171","pt":1723580821847,"mc":[{"id":"1.231659919","rc":[{"batb":[[0,2.08,18.33],[1,2.06,35.79],[2,1.89,222]],"ltp":2.2,"tv":36.93,"id":40096579}]}]}
{"op":"mcm","clk":"11843530488","pt":1723580824233,"mc":[{"id":"1.231659919","rc":[{"batb":[[0,2.1,10],[1,2.08,18.33],[2,2.06,35.79]],"ltp":2.2,"tv":36.93,"id":40096579}]}]}
{"op":"mcm","clk":"11843530963","pt":1723580827991,"mc":[{"id":"1.231659919","rc":[{"batb":[[0,2.08,18.33],[1,2.06,35.79],[2,1.89,222]],"ltp":2.2,"tv":36.93,"id":40096579}]}]}
{"op":"mcm","clk":"11843531229","pt":1723580830114,"mc":[{"id":"1.231659919","rc":[{"trd":[[1.86,126.72]],"batb":[[0,1.86,795.23]],"ltp":1.86,"tv":201.9,"id":40096581}],"tv":238.84}]}
{"op":"mcm","clk":"11843531281","pt":1723580830628,"mc":[{"id":"1.231659919","rc":[{"batb":[[0,2.1,10],[1,2.08,18.33],[2,2.06,35.79]],"ltp":2.2,"tv":36.93,"id":40096579}]}]}
{"op":"mcm","clk":"11843531701","pt":1723580834127,"mc":[{"id":"1.231659919","rc":[{"batb":[[0,2.08,18.33],[1,2.06,35.79],[2,1.89,222]],"ltp":2.2,"tv":36.93,"id":40096579}]}]}
{"op":"mcm","clk":"11843532060","pt":1723580836826,"mc":[{"id":"1.231659919","rc":[{"batb":[[0,2.1,10],[1,2.08,18.33],[2,2.06,35.79]],"ltp":2.2,"tv":36.93,"id":40096579}]}]}
{"op":"mcm","clk":"11843532519","pt":1723580840420,"mc":[{"id":"1.231659919","rc":[{"batb":[[0,2.08,18.33],[1,2.06,35.79],[2,1.89,222]],"ltp":2.2,"tv":36.93,"id":40096579}]}]}
{"op":"mcm","clk":"11843532986","pt":1723580844130,"mc":[{"id":"1.231659919","rc":[{"batb":[[0,2.1,10],[1,2.08,18.33],[2,2.06,35.79]],"ltp":2.2,"tv":36.93,"id":40096579}]}]}
{"op":"mcm","clk":"11843533414","pt":1723580847457,"mc":[{"id":"1.231659919","rc":[{"batb":[[0,2.08,18.33],[1,2.06,35.79],[2,1.89,222]],"ltp":2.2,"tv":36.93,"id":40096579}]}]}
{"op":"mcm","clk":"11843533702","pt":1723580850251,"mc":[{"id":"1.231659919","rc":[{"batb":[[0,2.1,10],[1,2.08,18.33],[2,2.06,35.79]],"ltp":2.2,"tv":36.93,"id":40096579}]}]}
{"op":"mcm","clk":"11843534163","pt":1723580853632,"mc":[{"id":"1.231659919","rc":[{"batb":[[0,2.08,18.33],[1,2.06,35.79],[2,1.89,222]],"ltp":2.2,"tv":36.93,"id":40096579}]}]}
{"op":"mcm","clk":"11843534650","pt":1723580857529,"mc":[{"id":"1.231659919","rc":[{"batb":[[0,2.1,10],[1,2.08,18.33],[2,2.06,35.79]],"ltp":2.2,"tv":36.93,"id":40096579}]}]}
{"op":"mcm","clk":"11843535012","pt":1723580860946,"mc":[{"id":"1.231659919","rc":[{"batb":[[0,2.08,18.33],[1,2.06,35.79],[2,1.89,222]],"ltp":2.2,"tv":36.93,"id":40096579}]}]}
{"op":"mcm","clk":"11843535359","pt":1723580863557,"mc":[{"id":"1.231659919","rc":[{"batb":[[0,2.1,10],[1,2.08,18.33],[2,2.06,35.79]],"ltp":2.2,"tv":36.93,"id":40096579}]}]}
{"op":"mcm","clk":"11843535774","pt":1723580866875,"mc":[{"id":"1.231659919","rc":[{"batb":[[0,2.08,18.33],[1,2.06,35.79],[2,1.89,222]],"ltp":2.2,"tv":36.93,"id":40096579}]}]}
{"op":"mcm","clk":"11843536212","pt":1723580870162,"mc":[{"id":"1.231659919","rc":[{"batb":[[0,2.1,10],[1,2.08,18.33],[2,2.06,35.79]],"ltp":2.2,"tv":36.93,"id":40096579}]}]}
{"op":"mcm","clk":"11843536641","pt":1723580873589,"mc":[{"id":"1.231659919","rc":[{"batb":[[0,2.08,18.33],[1,2.06,35.79],[2,1.89,222]],"ltp":2.2,"tv":36.93,"id":40096579}]}]}
{"op":"mcm","clk":"11843536995","pt":1723580876091,"mc":[{"id":"1.231659919","rc":[{"batb":[[0,2.1,10],[1,2.08,18.33],[2,2.06,35.79]],"ltp":2.2,"tv":36.93,"id":40096579}]}]}
{"op":"mcm","clk":"11843537451","pt":1723580879504,"mc":[{"id":"1.231659919","rc":[{"batb":[[0,2.08,18.33],[1,2.06,35.79],[2,1.89,222]],"ltp":2.2,"tv":36.93,"id":40096579}]}]}
{"op":"mcm","clk":"11843537952","pt":1723580882599,"mc":[{"id":"1.231659919","rc":[{"batb":[[0,2.1,10],[1,2.08,18.33],[2,2.06,35.79]],"ltp":2.2,"tv":36.93,"id":40096579}]}]}
{"op":"mcm","clk":"11843538458","pt":1723580886285,"mc":[{"id":"1.231659919","rc":[{"batb":[[0,2.08,18.33],[1,2.06,35.79],[2,1.89,222]],"ltp":2.2,"tv":36.93,"id":40096579}]}]}
{"op":"mcm","clk":"11843538904","pt":1723580889607,"mc":[{"id":"1.231659919","rc":[{"batb":[[0,2.1,10],[1,2.08,18.33],[2,2.06,35.79]],"ltp":2.2,"tv":36.93,"id":40096579}]}]}
{"op":"mcm","clk":"11843539405","pt":1723580893194,"mc":[{"id":"1.231659919","rc":[{"batb":[[0,2.08,18.33],[1,2.06,35.79],[2,1.89,222]],"ltp":2.2,"tv":36.93,"id":40096579}]}]}
{"op":"mcm","clk":"11843539738","pt":1723580895583,"mc":[{"id":"1.231659919","rc":[{"batb":[[0,2.1,10],[1,2.08,18.33],[2,2.06,35.79]],"ltp":2.2,"tv":36.93,"id":40096579}]}]}
{"op":"mcm","clk":"11843540246","pt":1723580899424,"mc":[{"id":"1.231659919","rc":[{"batb":[[0,2.08,18.33],[1,2.06,35.79],[2,1.89,222]],"ltp":2.2,"tv":36.93,"id":40096579}]}]}
{"op":"mcm","clk":"11843540591","pt":1723580902027,"mc":[{"id":"1.231659919","rc":[{"batb":[[0,2.1,10],[1,2.08,18.33],[2,2.06,35.79]],"ltp":2.2,"tv":36.93,"id":40096579}]}]}
{"op":"mcm","clk":"11843541111","pt":1723580905727,"mc":[{"id":"1.231659919","rc":[{"batb":[[0,2.08,18.33],[1,2.06,35.79],[2,1.89,222]],"ltp":2.2,"tv":36.93,"id":40096579}]}]}
{"op":"mcm","clk":"11843541681","pt":1723580909310,"mc":[{"id":"1.231659919","rc":[{"batb":[[0,2.1,10],[1,2.08,18.33],[2,2.06,35.79]],"ltp":2.2,"tv":36.93,"id":40096579}]}]}
{"op":"mcm","clk":"11843542190","pt":1723580913103,"mc":[{"id":"1.231659919","rc":[{"batb":[[0,2.08,18.33],[1,2.06,35.79],[2,1.89,222]],"ltp":2.2,"tv":36.93,"id":40096579}]}]}
{"op":"mcm","clk":"11843542663","pt":1723580916427,"mc":[{"id":"1.231659919","rc":[{"batb":[[0,2.1,10],[1,2.08,18.33],[2,2.06,35.79]],"ltp":2.2,"tv":36.93,"id":40096579}]}]}
{"op":"mcm","clk":"11843543146","pt":1723580920121,"mc":[{"id":"1.231659919","rc":[{"batb":[[0,2.08,18.33],[1,2.06,35.79],[2,1.89,222]],"ltp":2.2,"tv":36.93,"id":40096579}]}]}
{"op":"mcm","clk":"11843543493","pt":1723580922628,"mc":[{"id":"1.231659919","rc":[{"batb":[[0,2.1,10],[1,2.08,18.33],[2,2.06,35.79]],"ltp":2.2,"tv":36.93,"id":40096579}]}]}
{"op":"mcm","clk":"11843543966","pt":1723580926411,"mc":[{"id":"1.231659919","rc":[{"batb":[[0,2.08,18.33],[1,2.06,35.79],[2,1.89,222]],"ltp":2.2,"tv":36.93,"id":40096579}]}]}
{"op":"mcm","clk":"11843544388","pt":1723580929938,"mc":[{"id":"1.231659919","rc":[{"batb":[[0,2.1,10],[1,2.08,18.33],[2,2.06,35.79]],"ltp":2.2,"tv":36.93,"id":40096579}]}]}
{"op":"mcm","clk":"11843544838","pt":1723580933929,"mc":[{"id":"1.231659919","rc":[{"batb":[[0,2.08,18.33],[1,2.06,35.79],[2,1.89,222]],"ltp":2.2,"tv":36.93,"id":40096579}]}]}
{"op":"mcm","clk":"11843545292","pt":1723580937660,"mc":[{"id":"1.231659919","rc":[{"batb":[[0,2.1,10],[1,2.08,18.33],[2,2.06,35.79]],"ltp":2.2,"tv":36.93,"id":40096579}]}]}
{"op":"mcm","clk":"11843545784","pt":1723580941555,"mc":[{"id":"1.231659919","rc":[{"batb":[[0,2.08,18.33],[1,2.06,35.79],[2,1.89,222]],"ltp":2.2,"tv":36.93,"id":40096579}]}]}
{"op":"mcm","clk":"11843546139","pt":1723580944470,"mc":[{"id":"1.231659919","rc":[{"batb":[[0,2.1,10],[1,2.08,18.33],[2,2.06,35.79]],"ltp":2.2,"tv":36.93,"id":40096579}]}]}
{"op":"mcm","clk":"11843546573","pt":1723580948153,"mc":[{"id":"1.231659919","rc":[{"batb":[[0,2.08,18.33],[1,2.06,35.79],[2,1.89,222]],"ltp":2.2,"tv":36.93,"id":40096579}]}]}
{"op":"mcm","clk":"11843546901","pt":1723580950758,"mc":[{"id":"1.231659919","rc":[{"batb":[[0,2.1,10],[1,2.08,18.33],[2,2.06,35.79]],"ltp":2.2,"tv":36.93,"id":40096579}]}]}
{"op":"mcm","clk":"11843547398","pt":1723580954557,"mc":[{"id":"1.231659919","rc":[{"batb":[[0,2.08,18.33],[1,2.06,35.79],[2,1.89,222]],"ltp":2.2,"tv":36.93,"id":40096579}]}]}
{"op":"mcm","clk":"11843547681","pt":1723580956849,"mc":[{"id":"1.231659919","rc":[{"batb":[[0,2.1,10],[1,2.08,18.33],[2,2.06,35.79]],"ltp":2.2,"tv":36.93,"id":40096579}]}]}
{"op":"mcm","clk":"11843548142","pt":1723580960275,"mc":[{"id":"1.231659919","rc":[{"batb":[[0,2.08,18.33],[1,2.06,35.79],[2,1.89,222]],"ltp":2.2,"tv":36.93,"id":40096579}]}]}
{"op":"mcm","clk":"11843548497","pt":1723580963071,"mc":[{"id":"1.231659919","rc":[{"batb":[[0,2.1,10],[1,2.08,18.33],[2,2.06,35.79]],"ltp":2.2,"tv":36.93,"id":40096579}]}]}
{"op":"mcm","clk":"11843548969","pt":1723580966550,"mc":[{"id":"1.231659919","rc":[{"batb":[[0,2.08,18.33],[1,2.06,35.79],[2,1.89,222]],"ltp":2.2,"tv":36.93,"id":40096579}]}]}
{"op":"mcm","clk":"11843549378","pt":1723580969199,"mc":[{"id":"1.231659919","rc":[{"batb":[[0,2.1,10],[1,2.08,18.33],[2,2.06,35.79]],"ltp":2.2,"tv":36.93,"id":40096579}]}]}
{"op":"mcm","clk":"11843549844","pt":1723580972881,"mc":[{"id":"1.231659919","rc":[{"batb":[[0,2.08,18.33],[1,2.06,35.79],[2,1.89,222]],"ltp":2.2,"tv":36.93,"id":40096579}]}]}
{"op":"mcm","clk":"11843550306","pt":1723580976405,"mc":[{"id":"1.231659919","rc":[{"batb":[[0,2.1,10],[1,2.08,18.33],[2,2.06,35.79]],"ltp":2.2,"tv":36.93,"id":40096579}]}]}
{"op":"mcm","clk":"11843550777","pt":1723580979990,"mc":[{"id":"1.231659919","rc":[{"batb":[[0,2.08,18.33],[1,2.06,35.79],[2,1.89,222]],"ltp":2.2,"tv":36.93,"id":40096579}]}]}
{"op":"mcm","clk":"11843551177","pt":1723580983204,"mc":[{"id":"1.231659919","rc":[{"batb":[[0,2.1,10],[1,2.08,18.33],[2,2.06,35.79]],"ltp":2.2,"tv":36.93,"id":40096579}]}]}
{"op":"mcm","clk":"11843551672","pt":1723580986992,"mc":[{"id":"1.231659919","rc":[{"batb":[[0,2.08,18.33],[1,2.06,35.79],[2,1.89,222]],"ltp":2.2,"tv":36.93,"id":40096579}]}]}
{"op":"mcm","clk":"11843551967","pt":1723580989276,"mc":[{"id":"1.231659919","rc":[{"batb":[[0,2.1,10],[1,2.08,18.33],[2,2.06,35.79]],"ltp":2.2,"tv":36.93,"id":40096579}]}]}
{"op":"mcm","clk":"11843552444","pt":1723580992695,"mc":[{"id":"1.231659919","rc":[{"batb":[[0,2.08,18.33],[1,2.06,35.79],[2,1.89,222]],"ltp":2.2,"tv":36.93,"id":40096579}]}]}
{"op":"mcm","clk":"11843552795","pt":1723580995710,"mc":[{"id":"1.231659919","rc":[{"batb":[[0,2.1,10],[1,2.08,18.33],[2,2.06,35.79]],"ltp":2.2,"tv":36.93,"id":40096579}]}]}
{"op":"mcm","clk":"11843553317","pt":1723580999407,"mc":[{"id":"1.231659919","rc":[{"batb":[[0,2.08,18.33],[1,2.06,35.79],[2,1.89,222]],"ltp":2.2,"tv":36.93,"id":40096579}]}]}
{"op":"mcm","clk":"11843553974","pt":1723581003893,"mc":[{"id":"1.231659919","rc":[{"batb":[[0,2.1,10],[1,2.08,18.33],[2,2.06,35.79]],"ltp":2.2,"tv":36.93,"id":40096579}]}]}
{"op":"mcm","clk":"11843554593","pt":1723581008003,"mc":[{"id":"1.231659919","rc":[{"batb":[[0,2.08,18.33],[1,2.06,35.79],[2,1.89,222]],"ltp":2.2,"tv":36.93,"id":40096579}]}]}
{"op":"mcm","clk":"11843554989","pt":1723581010506,"mc":[{"id":"1.231659919","rc":[{"batb":[[0,2.1,10],[1,2.08,18.33],[2,2.06,35.79]],"ltp":2.2,"tv":36.93,"id":40096579}]}]}
{"op":"mcm","clk":"11843555452","pt":1723581013931,"mc":[{"id":"1.231659919","rc":[{"batb":[[0,2.08,18.33],[1,2.06,35.79],[2,1.89,222]],"ltp":2.2,"tv":36.93,"id":40096579}]}]}
{"op":"mcm","clk":"11843555864","pt":1723581016839,"mc":[{"id":"1.231659919","rc":[{"batb":[[0,2.1,10],[1,2.08,18.33],[2,2.06,35.79]],"ltp":2.2,"tv":36.93,"id":40096579}]}]}
{"op":"mcm","clk":"11843556357","pt":1723581020325,"mc":[{"id":"1.231659919","rc":[{"batb":[[0,2.08,18.33],[1,2.06,35.79],[2,1.89,222]],"ltp":2.2,"tv":36.93,"id":40096579}]}]}
{"op":"mcm","clk":"11843556721","pt":1723581023037,"mc":[{"id":"1.231659919","rc":[{"batb":[[0,2.1,10],[1,2.08,18.33],[2,2.06,35.79]],"ltp":2.2,"tv":36.93,"id":40096579}]}]}
{"op":"mcm","clk":"11843557208","pt":1723581026740,"mc":[{"id":"1.231659919","rc":[{"batb":[[0,2.08,18.33],[1,2.06,35.79],[2,1.89,222]],"ltp":2.2,"tv":36.93,"id":40096579}]}]}
{"op":"mcm","clk":"11843557589","pt":1723581029545,"mc":[{"id":"1.231659919","rc":[{"batb":[[0,2.1,10],[1,2.08,18.33],[2,2.06,35.79]],"ltp":2.2,"tv":36.93,"id":40096579}]}]}
{"op":"mcm","clk":"11843558119","pt":1723581033334,"mc":[{"id":"1.231659919","rc":[{"batb":[[0,2.08,18.33],[1,2.06,35.79],[2,1.89,222]],"ltp":2.2,"tv":36.93,"id":40096579}]}]}
{"op":"mcm","clk":"11843558579","pt":1723581036966,"mc":[{"id":"1.231659919","rc":[{"batb":[[0,2.1,10],[1,2.08,18.33],[2,2.06,35.79]],"ltp":2.2,"tv":36.93,"id":40096579}]}]}
{"op":"mcm","clk":"11843559150","pt":1723581040658,"mc":[{"id":"1.231659919","rc":[{"batb":[[0,2.08,18.33],[1,2.06,35.79],[2,1.89,222]],"ltp":2.2,"tv":36.93,"id":40096579}]}]}
{"op":"mcm","clk":"11843559598","pt":1723581043878,"mc":[{"id":"1.231659919","rc":[{"batb":[[0,2.1,10],[1,2.08,18.33],[2,2.06,35.79]],"ltp":2.2,"tv":36.93,"id":40096579}]}]}
{"op":"mcm","clk":"11843560074","pt":1723581047460,"mc":[{"id":"1.231659919","rc":[{"batb":[[0,2.08,18.33],[1,2.06,35.79],[2,1.89,222]],"ltp":2.2,"tv":36.93,"id":40096579}]}]}
{"op":"mcm","clk":"11843560412","pt":1723581049948,"mc":[{"id":"1.231659919","rc":[{"batb":[[0,2.1,10],[1,2.08,18.33],[2,2.06,35.79]],"ltp":2.2,"tv":36.93,"id":40096579}]}]}
{"op":"mcm","clk":"11843560918","pt":1723581053672,"mc":[{"id":"1.231659919","rc":[{"batb":[[0,2.08,18.33],[1,2.06,35.79],[2,1.89,222]],"ltp":2.2,"tv":36.93,"id":40096579}]}]}
{"op":"mcm","clk":"11843561264","pt":1723581056275,"mc":[{"id":"1.231659919","rc":[{"batb":[[1,1.84,480],[2,1.82,46.27]],"ltp":1.86,"tv":201.9,"id":40096581}]}]}
{"op":"mcm","clk":"11843561321","pt":1723581056692,"mc":[{"id":"1.231659919","rc":[{"batb":[[0,2.1,10],[1,2.08,18.33],[2,2.06,35.79]],"ltp":2.2,"tv":36.93,"id":40096579}]}]}
{"op":"mcm","clk":"11843561726","pt":1723581059967,"mc":[{"id":"1.231659919","rc":[{"batb":[[0,2.08,18.33],[1,2.06,35.79],[2,1.89,222]],"ltp":2.2,"tv":36.93,"id":40096579}]}]}
{"op":"mcm","clk":"11843562252","pt":1723581063963,"mc":[{"id":"1.231659919","rc":[{"batb":[[0,2.1,10],[1,2.08,18.33],[2,2.06,35.79]],"ltp":2.2,"tv":36.93,"id":40096579}]}]}
{"op":"mcm","clk":"11843562679","pt":1723581067276,"mc":[{"id":"1.231659919","rc":[{"batb":[[0,2.08,18.33],[1,2.06,35.79],[2,1.89,222]],"ltp":2.2,"tv":36.93,"id":40096579}]}]}
{"op":"mcm","clk":"11843563139","pt":1723581070903,"mc":[{"id":"1.231659919","rc":[{"batb":[[0,2.1,10],[1,2.08,18.33],[2,2.06,35.79]],"ltp":2.2,"tv":36.93,"id":40096579}]}]}
{"op":"mcm","clk":"11843563649","pt":1723581074277,"mc":[{"id":"1.231659919","rc":[{"batb":[[0,2.08,18.33],[1,2.06,35.79],[2,1.89,222]],"ltp":2.2,"tv":36.93,"id":40096579}]}]}
{"op":"mcm","clk":"11843563969","pt":1723581076608,"mc":[{"id":"1.231659919","rc":[{"batb":[[0,2.1,10],[1,2.08,18.33],[2,2.06,35.79]],"ltp":2.2,"tv":36.93,"id":40096579}]}]}
{"op":"mcm","clk":"11843564555","pt":1723581080605,"mc":[{"id":"1.231659919","rc":[{"batb":[[0,2.08,18.33],[1,2.06,35.79],[2,1.89,222]],"ltp":2.2,"tv":36.93,"id":40096579}]}]}
{"op":"mcm","clk":"11843565064","pt":1723581084133,"mc":[{"id":"1.231659919","rc":[{"batb":[[0,2.1,10],[1,2.08,18.33],[2,2.06,35.79]],"ltp":2.2,"tv":36.93,"id":40096579}]}]}
{"op":"mcm","clk":"11843565588","pt":1723581087720,"mc":[{"id":"1.231659919","rc":[{"batb":[[0,2.08,18.33],[1,2.06,35.79],[2,1.89,222]],"ltp":2.2,"tv":36.93,"id":40096579}]}]}
{"op":"mcm","clk":"11843565925","pt":1723581090222,"mc":[{"id":"1.231659919","rc":[{"batb":[[0,2.1,10],[1,2.08,18.33],[2,2.06,35.79]],"ltp":2.2,"tv":36.93,"id":40096579}]}]}
{"op":"mcm","clk":"11843566396","pt":1723581093545,"mc":[{"id":"1.231659919","rc":[{"batb":[[0,2.08,18.33],[1,2.06,35.79],[2,1.89,222]],"ltp":2.2,"tv":36.93,"id":40096579}]}]}
{"op":"mcm","clk":"11843566790","pt":1723581096199,"mc":[{"id":"1.231659919","rc":[{"batb":[[0,2.1,10],[1,2.08,18.33],[2,2.06,35.79]],"ltp":2.2,"tv":36.93,"id":40096579}]}]}
{"op":"mcm","clk":"11843567266","pt":1723581099928,"mc":[{"id":"1.231659919","rc":[{"batb":[[0,2.08,18.33],[1,2.06,35.79],[2,1.89,222]],"ltp":2.2,"tv":36.93,"id":40096579}]}]}
{"op":"mcm","clk":"11843567662","pt":1723581103031,"mc":[{"id":"1.231659919","rc":[{"batb":[[0,2.1,10],[1,2.08,18.33],[2,2.06,35.79]],"ltp":2.2,"tv":36.93,"id":40096579}]}]}
{"op":"mcm","clk":"11843568100","pt":1723581106553,"mc":[{"id":"1.231659919","rc":[{"batb":[[0,2.08,18.33],[1,2.06,35.79],[2,1.89,222]],"ltp":2.2,"tv":36.93,"id":40096579}]}]}
{"op":"mcm","clk":"11843568406","pt":1723581108948,"mc":[{"id":"1.231659919","rc":[{"batb":[[0,2.1,10],[1,2.08,18.33],[2,2.06,35.79]],"ltp":2.2,"tv":36.93,"id":40096579}]}]}
{"op":"mcm","clk":"11843568868","pt":1723581112823,"mc":[{"id":"1.231659919","rc":[{"batb":[[0,2.08,18.33],[1,2.06,35.79],[2,1.89,222]],"ltp":2.2,"tv":36.93,"id":40096579}]}]}
{"op":"mcm","clk":"11843569241","pt":1723581115772,"mc":[{"id":"1.231659919","rc":[{"batb":[[0,2.1,10],[1,2.08,18.33],[2,2.06,35.79]],"ltp":2.2,"tv":36.93,"id":40096579}]}]}
{"op":"mcm","clk":"11843569794","pt":1723581119828,"mc":[{"id":"1.231659919","rc":[{"batb":[[0,2.08,18.33],[1,2.06,35.79],[2,1.89,222]],"ltp":2.2,"tv":36.93,"id":40096579}]}]}
{"op":"mcm","clk":"11843570281","pt":1723581123864,"mc":[{"id":"1.231659919","rc":[{"batb":[[0,2.1,10],[1,2.08,18.33],[2,2.06,35.79]],"ltp":2.2,"tv":36.93,"id":40096579}]}]}
{"op":"mcm","clk":"11843570769","pt":1723581127245,"mc":[{"id":"1.231659919","rc":[{"batb":[[0,2.08,18.33],[1,2.06,35.79],[2,1.89,222]],"ltp":2.2,"tv":36.93,"id":40096579}]}]}
{"op":"mcm","clk":"11843571098","pt":1723581129844,"mc":[{"id":"1.231659919","rc":[{"batb":[[0,2.1,10],[1,2.08,18.33],[2,2.06,35.79]],"ltp":2.2,"tv":36.93,"id":40096579}]}]}
{"op":"mcm","clk":"11843571520","pt":1723581133366,"mc":[{"id":"1.231659919","rc":[{"batb":[[0,2.08,18.33],[1,2.06,35.79],[2,1.89,222]],"ltp":2.2,"tv":36.93,"id":40096579}]}]}
{"op":"mcm","clk":"11843571925","pt":1723581136062,"mc":[{"id":"1.231659919","rc":[{"batb":[[0,2.1,10],[1,2.08,18.33],[2,2.06,35.79]],"ltp":2.2,"tv":36.93,"id":40096579}]}]}
{"op":"mcm","clk":"11843572351","pt":1723581139378,"mc":[{"id":"1.231659919","rc":[{"batb":[[0,2.08,18.33],[1,2.06,35.79],[2,1.89,222]],"ltp":2.2,"tv":36.93,"id":40096579}]}]}
{"op":"mcm","clk":"11843572733","pt":1723581142078,"mc":[{"id":"1.231659919","rc":[{"batb":[[0,2.1,10],[1,2.08,18.33],[2,2.06,35.79]],"ltp":2.2,"tv":36.93,"id":40096579}]}]}
{"op":"mcm","clk":"11843573192","pt":1723581145704,"mc":[{"id":"1.231659919","rc":[{"batb":[[0,2.08,18.33],[1,2.06,35.79],[2,1.89,222]],"ltp":2.2,"tv":36.93,"id":40096579}]}]}
{"op":"mcm","clk":"11843573464","pt":1723581147895,"mc":[{"id":"1.231659919","rc":[{"batb":[[0,2.1,10],[1,2.08,18.33],[2,2.06,35.79]],"ltp":2.2,"tv":36.93,"id":40096579}]}]}
{"op":"mcm","clk":"11843573908","pt":1723581151580,"mc":[{"id":"1.231659919","rc":[{"batb":[[0,2.08,18.33],[1,2.06,35.79],[2,1.89,222]],"ltp":2.2,"tv":36.93,"id":40096579}]}]}
{"op":"mcm","clk":"11843574237","pt":1723581154066,"mc":[{"id":"1.231659919","rc":[{"batb":[[0,2.1,10],[1,2.08,18.33],[2,2.06,35.79]],"ltp":2.2,"tv":36.93,"id":40096579}]}]}
{"op":"mcm","clk":"11843574673","pt":1723581157910,"mc":[{"id":"1.231659919","rc":[{"batb":[[0,2.08,18.33],[1,2.06,35.79],[2,1.89,222]],"ltp":2.2,"tv":36.93,"id":40096579}]}]}
{"op":"mcm","clk":"11843574995","pt":1723581160307,"mc":[{"id":"1.231659919","rc":[{"batb":[[0,2.1,10],[1,2.08,18.33],[2,2.06,35.79]],"ltp":2.2,"tv":36.93,"id":40096579}]}]}
{"op":"mcm","clk":"11843575450","pt":1723581163978,"mc":[{"id":"1.231659919","rc":[{"batb":[[0,2.08,18.33],[1,2.06,35.79],[2,1.89,222]],"ltp":2.2,"tv":36.93,"id":40096579}]}]}
{"op":"mcm","clk":"11843575703","pt":1723581166201,"mc":[{"id":"1.231659919","rc":[{"batb":[[0,2.1,10],[1,2.08,18.33],[2,2.06,35.79]],"ltp":2.2,"tv":36.93,"id":40096579}]}]}
{"op":"mcm","clk":"11843576021","pt":1723581168993,"mc":[{"id":"1.231659919","rc":[{"batl":[[2,1.94,640]],"ltp":1.86,"tv":201.9,"id":40096581}]}]}
{"op":"mcm","clk":"11843576140","pt":1723581170024,"mc":[{"id":"1.231659919","rc":[{"batb":[[0,2.08,18.33],[1,2.06,35.79],[2,1.89,222]],"ltp":2.2,"tv":36.93,"id":40096579}]}]}
{"op":"mcm","clk":"11843576485","pt":1723581172896,"mc":[{"id":"1.231659919","rc":[{"batb":[[0,2.1,10],[1,2.08,18.33],[2,2.06,35.79]],"ltp":2.2,"tv":36.93,"id":40096579}]}]}
{"op":"mcm","clk":"11843576911","pt":1723581176709,"mc":[{"id":"1.231659919","rc":[{"batb":[[0,2.08,18.33],[1,2.06,35.79],[2,1.89,222]],"ltp":2.2,"tv":36.93,"id":40096579}]}]}
{"op":"mcm","clk":"11843577304","pt":1723581179998,"mc":[{"id":"1.231659919","rc":[{"batb":[[0,2.1,10],[1,2.08,18.33],[2,2.06,35.79]],"ltp":2.2,"tv":36.93,"id":40096579}]}]}
{"op":"mcm","clk":"11843577671","pt":1723581183314,"mc":[{"id":"1.231659919","rc":[{"batb":[[0,2.08,18.33],[1,2.06,35.79],[2,1.89,222]],"ltp":2.2,"tv":36.93,"id":40096579}]}]}
{"op":"mcm","clk":"11843578008","pt":1723581186232,"mc":[{"id":"1.231659919","rc":[{"batb":[[0,2.1,10],[1,2.08,18.33],[2,2.06,35.79]],"ltp":2.2,"tv":36.93,"id":40096579}]}]}
{"op":"mcm","clk":"11843578463","pt":1723581190016,"mc":[{"id":"1.231659919","rc":[{"batb":[[0,2.08,18.33],[1,2.06,35.79],[2,1.89,222]],"ltp":2.2,"tv":36.93,"id":40096579}]}]}
{"op":"mcm","clk":"11843578726","pt":1723581192339,"mc":[{"id":"1.231659919","rc":[{"batb":[[0,2.1,10],[1,2.08,18.33],[2,2.06,35.79]],"ltp":2.2,"tv":36.93,"id":40096579}]}]}
{"op":"mcm","clk":"11843579184","pt":1723581196011,"mc":[{"id":"1.231659919","rc":[{"batb":[[0,2.08,18.33],[1,2.06,35.79],[2,1.89,222]],"ltp":2.2,"tv":36.93,"id":40096579}]}]}
{"op":"mcm","clk":"11843579607","pt":1723581198972,"mc":[{"id":"1.231659919","rc":[{"batb":[[0,2.1,10],[1,2.08,18.33],[2,2.06,35.79]],"ltp":2.2,"tv":36.93,"id":40096579}]}]}
{"op":"mcm","clk":"11843580042","pt":1723581202336,"mc":[{"id":"1.231659919","rc":[{"batb":[[0,2.08,18.33],[1,2.06,35.79],[2,1.89,222]],"ltp":2.2,"tv":36.93,"id":40096579}]}]}
{"op":"mcm","clk":"11843580378","pt":1723581204928,"mc":[{"id":"1.231659919","rc":[{"batb":[[0,2.1,10],[1,2.08,18.33],[2,2.06,35.79]],"ltp":2.2,"tv":36.93,"id":40096579}]}]}
{"op":"mcm","clk":"11843580894","pt":1723581208554,"mc":[{"id":"1.231659919","rc":[{"batb":[[0,2.08,18.33],[1,2.06,35.79],[2,1.89,222]],"ltp":2.2,"tv":36.93,"id":40096579}]}]}
{"op":"mcm","clk":"11843581224","pt":1723581210947,"mc":[{"id":"1.231659919","rc":[{"batb":[[0,2.1,10],[1,2.08,18.33],[2,2.06,35.79]],"ltp":2.2,"tv":36.93,"id":40096579}]}]}
{"op":"mcm","clk":"11843581654","pt":1723581214342,"mc":[{"id":"1.231659919","rc":[{"batb":[[0,2.08,18.33],[1,2.06,35.79],[2,1.89,222]],"ltp":2.2,"tv":36.93,"id":40096579}]}]}
{"op":"mcm","clk":"11843581952","pt":1723581217142,"mc":[{"id":"1.231659919","rc":[{"batb":[[0,2.1,10],[1,2.08,18.33],[2,2.06,35.79]],"ltp":2.2,"tv":36.93,"id":40096579}]}]}
{"op":"mcm","clk":"11843582434","pt":1723581220768,"mc":[{"id":"1.231659919","rc":[{"batb":[[0,2.08,18.33],[1,2.06,35.79],[2,1.89,222]],"ltp":2.2,"tv":36.93,"id":40096579}]}]}
{"op":"mcm","clk":"11843582708","pt":1723581223254,"mc":[{"id":"1.231659919","rc":[{"batb":[[0,2.1,10],[1,2.08,18.33],[2,2.06,35.79]],"ltp":2.2,"tv":36.93,"id":40096579}]}]}
{"op":"mcm","clk":"11843583170","pt":1723581226827,"mc":[{"id":"1.231659919","rc":[{"batb":[[0,2.08,18.33],[1,2.06,35.79],[2,1.89,222]],"ltp":2.2,"tv":36.93,"id":40096579}]}]}
{"op":"mcm","clk":"11843583614","pt":1723581230848,"mc":[{"id":"1.231659919","rc":[{"batb":[[0,2.1,10],[1,2.08,18.33],[2,2.06,35.79]],"ltp":2.2,"tv":36.93,"id":40096579}]}]}
{"op":"mcm","clk":"11843584022","pt":1723581234568,"mc":[{"id":"1.231659919","rc":[{"batb":[[0,2.08,18.33],[1,2.06,35.79],[2,1.89,222]],"ltp":2.2,"tv":36.93,"id":40096579}]}]}
{"op":"mcm","clk":"11843584294","pt":1723581237051,"mc":[{"id":"1.231659919","rc":[{"batb":[[0,2.1,10],[1,2.08,18.33],[2,2.06,35.79]],"ltp":2.2,"tv":36.93,"id":40096579}]}]}
{"op":"mcm","clk":"11843584756","pt":1723581240978,"mc":[{"id":"1.231659919","rc":[{"batb":[[0,2.08,18.33],[1,2.06,35.79],[2,1.89,222]],"ltp":2.2,"tv":36.93,"id":40096579}]}]}
{"op":"mcm","clk":"11843585039","pt":1723581243366,"mc":[{"id":"1.231659919","rc":[{"batb":[[0,2.1,10],[1,2.08,18.33],[2,2.06,35.79]],"ltp":2.2,"tv":36.93,"id":40096579}]}]}
{"op":"mcm","clk":"11843585449","pt":1723581247089,"mc":[{"id":"1.231659919","rc":[{"batb":[[0,2.08,18.33],[1,2.06,35.79],[2,1.89,222]],"ltp":2.2,"tv":36.93,"id":40096579}]}]}
{"op":"mcm","clk":"11843585787","pt":1723581250051,"mc":[{"id":"1.231659919","rc":[{"batb":[[0,2.1,10],[1,2.08,18.33],[2,2.06,35.79]],"ltp":2.2,"tv":36.93,"id":40096579}]}]}
{"op":"mcm","clk":"11843586203","pt":1723581254079,"mc":[{"id":"1.231659919","rc":[{"batb":[[0,2.08,18.33],[1,2.06,35.79],[2,1.89,222]],"ltp":2.2,"tv":36.93,"id":40096579}]}]}
{"op":"mcm","clk":"11843586640","pt":1723581258163,"mc":[{"id":"1.231659919","rc":[{"batb":[[0,2.1,10],[1,2.08,18.33],[2,2.06,35.79]],"ltp":2.2,"tv":36.93,"id":40096579}]}]}
{"op":"mcm","clk":"11843587120","pt":1723581262502,"mc":[{"id":"1.231659919","rc":[{"batb":[[0,2.08,18.33],[1,2.06,35.79],[2,1.89,222]],"ltp":2.2,"tv":36.93,"id":40096579}]}]}
{"op":"mcm","clk":"11843587438","pt":1723581265296,"mc":[{"id":"1.231659919","rc":[{"batb":[[0,2.1,10],[1,2.08,18.33],[2,2.06,35.79]],"ltp":2.2,"tv":36.93,"id":40096579}]}]}
{"op":"mcm","clk":"11843587857","pt":1723581268788,"mc":[{"id":"1.231659919","rc":[{"batb":[[0,2.08,18.33],[1,2.06,35.79],[2,1.89,222]],"ltp":2.2,"tv":36.93,"id":40096579}]}]}
{"op":"mcm","clk":"11843588234","pt":1723581272094,"mc":[{"id":"1.231659919","rc":[{"batb":[[0,2.1,10],[1,2.08,18.33],[2,2.06,35.79]],"ltp":2.2,"tv":36.93,"id":40096579}]}]}
{"op":"mcm","clk":"11843588668","pt":1723581275712,"mc":[{"id":"1.231659919","rc":[{"batb":[[0,2.08,18.33],[1,2.06,35.79],[2,1.89,222]],"ltp":2.2,"tv":36.93,"id":40096579}]}]}
{"op":"mcm","clk":"11843589212","pt":1723581280626,"mc":[{"id":"1.231659919","rc":[{"batb":[[0,2.1,10],[1,2.08,18.33],[2,2.06,35.79]],"ltp":2.2,"tv":36.93,"id":40096579}]}]}
{"op":"mcm","clk":"11843589663","pt":1723581284812,"mc":[{"id":"1.231659919","rc":[{"batb":[[0,2.08,18.33],[1,2.06,35.79],[2,1.89,222]],"ltp":2.2,"tv":36.93,"id":40096579}]}]}
{"op":"mcm","clk":"11843590103","pt":1723581288394,"mc":[{"id":"1.231659919","rc":[{"batb":[[0,2.12,10],[1,2.08,18.33],[2,2.06,35.79]],"ltp":2.2,"tv":36.93,"id":40096579}]}]}
{"op":"mcm","clk":"11843590286","pt":1723581289998,"mc":[{"id":"1.231659919","rc":[{"batb":[[2,1.89,222]],"ltp":2.2,"tv":36.93,"id":40096579},{"batb":[[2,1.78,138.46]],"batl":[[0,1.87,40.21],[1,1.88,22],[2,1.92,2]],"ltp":1.86,"tv":201.9,"id":40096581}]}]}
{"op":"mcm","clk":"11843591207","pt":1723581298312,"mc":[{"id":"1.231659919","rc":[{"batb":[[0,2.08,18.33],[1,1.89,222],[2,1.86,555]],"ltp":2.2,"tv":36.93,"id":40096579},{"batl":[[0,1.88,62.21],[1,1.92,2],[2,1.94,640]],"ltp":1.86,"tv":201.9,"id":40096581}]}]}
{"op":"mcm","clk":"11843591329","pt":1723581299298,"mc":[{"id":"1.231659919","rc":[{"batb":[[1,2.06,35.79],[2,1.89,222]],"ltp":2.2,"tv":36.93,"id":40096579},{"batb":[[2,1.82,46.27]],"ltp":1.86,"tv":201.9,"id":40096581}]}]}
{"op":"mcm","clk":"11843591500","pt":1723581300846,"mc":[{"id":"1.231659919","rc":[{"batb":[[0,2.14,10],[1,2.08,18.33],[2,2.06,35.79]],"batl":[[0,2.16,17.18],[1,2.36,1],[2,12,0.52]],"ltp":2.2,"tv":36.93,"id":40096579}]}]}
{"op":"mcm","clk":"11843591886","pt":1723581304410,"mc":[{"id":"1.231659919","rc":[{"batb":[[2,1.89,222]],"ltp":2.2,"tv":36.93,"id":40096579},{"batb":[[2,1.78,138.46]],"ltp":1.86,"tv":201.9,"id":40096581}]}]}
{"op":"mcm","clk":"11843592324","pt":1723581308236,"mc":[{"id":"1.231659919","rc":[{"batb":[[0,2.08,18.33],[1,1.89,222],[2,1.86,555]],"ltp":2.2,"tv":36.93,"id":40096579}]}]}
{"op":"mcm","clk":"11843592461","pt":1723581309341,"mc":[{"id":"1.231659919","rc":[{"batb":[[1,2.06,35.79],[2,1.89,222]],"ltp":2.2,"tv":36.93,"id":40096579},{"batb":[[2,1.82,46.27]],"ltp":1.86,"tv":201.9,"id":40096581}]}]}
{"op":"mcm","clk":"11843641734","pt":1723581913952,"mc":[{"id":"1.231659919","rc":[{"trd":[[1.88,124.42]],"batb":[[0,1.88,1937.79],[1,1.86,795.23],[2,1.84,480]],"batl":[[0,1.92,2],[1,1.94,640],[2,1.98,138.46]],"ltp":1.88,"tv":326.32,"id":40096581}],"tv":363.26}]}
{"op":"mcm","clk":"11843641874","pt":1723581916060,"mc":[{"id":"1.231659919","rc":[{"batb":[[0,2.1,10],[1,2.08,18.33],[2,2.06,35.79]],"batl":[[0,2.36,1],[1,12,0.52],[2,12,0]],"ltp":2.2,"tv":36.93,"id":40096579}]}]}
{"op":"mcm","clk":"11843641917","pt":1723581916576,"mc":[{"id":"1.231659919","rc":[{"batb":[[2,1.89,222]],"ltp":2.2,"tv":36.93,"id":40096579}]}]}
{"op":"mcm","clk":"11843642149","pt":1723581919281,"mc":[{"id":"1.231659919","rc":[{"batb":[[0,2.08,18.33],[1,1.89,222],[2,1.86,555]],"ltp":2.2,"tv":36.93,"id":40096579}]}]}
{"op":"mcm","clk":"11843642312","pt":1723581921598,"mc":[{"id":"1.231659919","rc":[{"batb":[[0,2.1,10],[1,2.08,18.33],[2,2.06,35.79]],"ltp":2.2,"tv":36.93,"id":40096579}]}]}
{"op":"mcm","clk":"11843642577","pt":1723581925060,"mc":[{"id":"1.231659919","rc":[{"batb":[[0,2.08,18.33],[1,2.06,35.79],[2,1.89,222]],"ltp":2.2,"tv":36.93,"id":40096579}]}]}
{"op":"mcm","clk":"11843642851","pt":1723581929202,"mc":[{"id":"1.231659919","rc":[{"batb":[[0,2.1,10],[1,2.08,18.33],[2,2.06,35.79]],"ltp":2.2,"tv":36.93,"id":40096579}]}]}
{"op":"mcm","clk":"11843643020","pt":1723581931578,"mc":[{"id":"1.231659919","rc":[{"batb":[[2,1.89,222]],"ltp":2.2,"tv":36.93,"id":40096579}]}]}
{"op":"mcm","clk":"11843643088","pt":1723581932609,"mc":[{"id":"1.231659919","rc":[{"batb":[[0,2.08,18.33],[1,1.89,222],[2,1.86,555]],"ltp":2.2,"tv":36.93,"id":40096579}]}]}
{"op":"mcm","clk":"11843643339","pt":1723581936530,"mc":[{"id":"1.231659919","rc":[{"batb":[[1,2.06,35.79],[2,1.89,222]],"ltp":2.2,"tv":36.93,"id":40096579}]}]}
{"op":"mcm","clk":"11843645640","pt":1723581974234,"mc":[{"id":"1.231659919","rc":[{"batb":[[0,1.86,795.23],[1,1.84,480],[2,1.78,138.46]],"ltp":1.88,"tv":326.32,"id":40096581}]}]}
{"op":"mcm","clk":"11843645796","pt":1723581976643,"mc":[{"id":"1.231659919","rc":[{"batb":[[2,1.82,46.27]],"ltp":1.88,"tv":326.32,"id":40096581}]}]}
{"op":"mcm","clk":"11843646334","pt":1723581988244,"mc":[{"id":"1.231659919","rc":[{"batl":[[0,1.89,62],[1,1.92,2],[2,1.94,640]],"ltp":1.88,"tv":326.32,"id":40096581}]}]}
{"op":"mcm","clk":"11843647298","pt":1723582009768,"mc":[{"id":"1.231659919","rc":[{"batl":[[0,1.92,2],[1,1.94,640],[2,1.98,138.46]],"ltp":1.88,"tv":326.32,"id":40096581}]}]}
{"op":"mcm","clk":"11843651692","pt":1723582106332,"mc":[{"id":"1.231659919","rc":[{"batl":[[0,2.12,2],[1,2.36,1],[2,12,0.52]],"ltp":2.2,"tv":36.93,"id":40096579}]}]}
{"op":"mcm","clk":"11843673344","pt":1723582662056,"mc":[{"id":"1.231659919","rc":[{"trd":[[2.12,2]],"batl":[[0,2.36,1],[1,12,0.52],[2,12,0]],"ltp":2.12,"tv":38.93,"id":40096579},{"trd":[[1.89,2.24]],"batl":[[0,1.89,7.76],[1,1.92,2],[2,1.94,640]],"ltp":1.89,"tv":328.56,"id":40096581}],"tv":367.5}]}
{"op":"mcm","clk":"11843673763","pt":1723582674374,"mc":[{"id":"1.231659919","rc":[{"batl":[[0,1.92,2],[1,1.94,640],[2,1.98,138.46]],"ltp":1.89,"tv":328.56,"id":40096581}]}]}
{"op":"mcm","clk":"11843674187","pt":1723582685090,"mc":[{"id":"1.231659919","rc":[{"trd":[[1.86,142.24]],"batb":[[0,1.86,787.47]],"ltp":1.86,"tv":344.08,"id":40096581}],"tv":383.02}]}
{"op":"mcm","clk":"11843675079","pt":1723582706929,"mc":[{"id":"1.231659919","rc":[{"batl":[[0,2.16,17.01],[1,2.36,1],[2,12,0.52]],"ltp":2.12,"tv":38.93,"id":40096579},{"batb":[[0,1.87,17.01],[1,1.86,787.47],[2,1.84,480]],"ltp":1.86,"tv":344.08,"id":40096581}]}]}
{"op":"mcm","clk":"11843677525","pt":1723582769067,"mc":[{"id":"1.231659919","rc":[{"batb":[[2,2,12.43]],"ltp":2.12,"tv":38.93,"id":40096579}]}]}
{"op":"mcm","clk":"11843715055","pt":1723583574952,"mc":[{"id":"1.231659919","rc":[{"trd":[[2.06,27.94]],"batb":[[2,2,12.43]],"ltp":2.12,"tv":38.94,"id":40096579},{"trd":[[1.83,55.19],[1.86,142.24]],"ltp":1.86,"tv":344.08,"id":40096581}],"tv":383.02}]}
{"op":"mcm","clk":"11843717973","pt":1723583594119,"mc":[{"id":"1.231659919","rc":[{"batb":[[2,1.82,46.27]],"ltp":1.86,"tv":344.08,"id":40096581}]}]}
{"op":"mcm","clk":"11843718572","pt":1723583608218,"mc":[{"id":"1.231659919","rc":[{"batb":[[0,1.87,497.01]],"ltp":1.86,"tv":344.08,"id":40096581}]}]}
{"op":"mcm","clk":"11843731465","pt":1723583944555,"mc":[{"id":"1.231659919","rc":[{"batl":[[0,1.9,35],[1,1.92,2],[2,1.94,640]],"ltp":1.86,"tv":344.08,"id":40096581}]}]}
{"op":"mcm","clk":"11843734366","pt":1723584029097,"mc":[{"id":"1.231659919","rc":[{"batb":[[0,1.87,17.01]],"ltp":1.86,"tv":344.08,"id":40096581}]}]}
{"op":"mcm","clk":"11843739025","pt":1723584161751,"mc":[{"id":"1.231659919","rc":[{"batb":[[0,2.08,10]],"ltp":2.12,"tv":38.94,"id":40096579}]}]}
{"op":"mcm","clk":"11843739168","pt":1723584165153,"mc":[{"id":"1.231659919","rc":[{"batb":[[0,2.06,35.79],[1,2,12.43],[2,1.9,16.58]],"ltp":2.12,"tv":38.94,"id":40096579}]}]}
{"op":"mcm","clk":"11843739299","pt":1723584168839,"mc":[{"id":"1.231659919","rc":[{"batb":[[0,2.08,10],[1,2.06,35.79],[2,2,12.43]],"ltp":2.12,"tv":38.94,"id":40096579}]}]}
{"op":"mcm","clk":"11843739323","pt":1723584169451,"mc":[{"id":"1.231659919","rc":[{"batb":[[0,2.1,18],[1,2.08,10],[2,2.06,35.79]],"ltp":2.12,"tv":38.94,"id":40096579}]}]}
{"op":"mcm","clk":"11843739417","pt":1723584172268,"mc":[{"id":"1.231659919","rc":[{"batb":[[1,2.06,35.79],[2,2,12.43]],"ltp":2.12,"tv":38.94,"id":40096579}]}]}
{"op":"mcm","clk":"11843767257","pt":1723585106859,"mc":[{"id":"1.231659919","rc":[{"trd":[[1.87,10]],"batb":[[0,1.87,12.01]],"ltp":1.87,"tv":354.08,"id":40096581}],"tv":393.02}]}
{"op":"mcm","clk":"11843767400","pt":1723585112350,"mc":[{"id":"1.231659919","rc":[{"batl":[[0,1.88,5],[1,1.9,35],[2,1.92,2]],"ltp":1.87,"tv":354.08,"id":40096581}]}]}
{"op":"mcm","clk":"11843767569","pt":1723585118437,"mc":[{"id":"1.231659919","rc":[{"batl":[[1,1.9,37]],"ltp":1.87,"tv":354.08,"id":40096581}]}]}
{"op":"mcm","clk":"11843779188","pt":1723585584021,"mc":[{"id":"1.231659919","rc":[{"trd":[[1.87,34.02]],"batb":[[0,1.86,787.47],[1,1.82,46.27],[2,1.81,16.58]],"batl":[[0,1.87,22.99],[1,1.88,5],[2,1.9,2]],"ltp":1.87,"tv":378.1,"id":40096581}],"tv":417.04}]}
{"op":"mcm","clk":"11843779237","pt":1723585585706,"mc":[{"id":"1.231659919","rc":[{"batl":[[0,2.36,1],[1,12,0.52],[2,12,0]],"ltp":2.12,"tv":38.94,"id":40096579},{"batl":[[0,1.87,40]],"ltp":1.87,"tv":378.1,"id":40096581}]}]}
{"op":"mcm","clk":"11843779539","pt":1723585597030,"mc":[{"id":"1.231659919","rc":[{"trd":[[1.86,188.22]],"batb":[[0,1.86,764.48],[1,1.83,2],[2,1.82,46.27]],"batl":[[0,1.88,5],[1,1.9,2],[2,1.92,2]],"ltp":1.86,"tv":424.08,"id":40096581}],"tv":463.02}]}
{"op":"mcm","clk":"11843779690","pt":1723585602314,"mc":[{"id":"1.231659919","rc":[{"batl":[[1,1.9,18.73]],"ltp":1.86,"tv":424.08,"id":40096581}]}]}
{"op":"mcm","clk":"11843781401","pt":1723585677913,"mc":[{"id":"1.231659919","rc":[{"trd":[[2.12,3]],"ltp":2.12,"tv":39.94,"id":40096579},{"trd":[[1.88,125.55]],"batl":[[0,1.88,3.87]],"ltp":1.88,"tv":425.21,"id":40096581}],"tv":465.15}]}
{"op":"mcm","clk":"11843799310","pt":1723586376969,"mc":[{"id":"1.231659919","rc":[{"batl":[[0,2.16,17.02],[1,2.36,1],[2,12,0.52]],"ltp":2.12,"tv":39.94,"id":40096579}]}]}
{"op":"mcm","clk":"11843801616","pt":1723586439863,"mc":[{"id":"1.231659919","rc":[{"trd":[[2.06,27.94]],"batb":[[2,2,12.44]],"ltp":2.12,"tv":39.94,"id":40096579},{"trd":[[1.83,55.18],[1.86,188.22]],"batb":[[0,1.87,19.09],[1,1.86,764.48]],"ltp":1.88,"tv":425.2,"id":40096581}],"tv":465.15}]}
{"op":"mcm","clk":"11843817558","pt":1723586915648,"mc":[{"id":"1.231659919","rc":[{"batl":[[0,2.14,5],[1,2.16,17.02],[2,2.36,1]],"ltp":2.12,"tv":39.94,"id":40096579}]}]}
{"op":"mcm","clk":"11843844947","pt":1723587843861,"mc":[{"id":"1.231659919","rc":[{"batb":[[0,1.87,17.09]],"ltp":1.88,"tv":425.2,"id":40096581}]}]}
{"op":"mcm","clk":"11843855180","pt":1723588187814,"mc":[{"id":"1.231659919","rc":[{"trd":[[1.88,133.29],[1.9,26.76]],"batl":[[0,1.9,5.35],[1,1.92,2],[2,1.94,640]],"ltp":1.9,"tv":459.7,"id":40096581}],"tv":499.65}]}
{"op":"mcm","clk":"11843856392","pt":1723588226417,"mc":[{"id":"1.231659919","rc":[{"trd":[[1.9,37.46]],"batb":[[0,1.9,7286.32],[1,1.87,17.09],[2,1.86,764.48]],"batl":[[0,1.92,2],[1,1.94,640],[2,1.98,138.46]],"ltp":1.9,"tv":470.4,"id":40096581}],"tv":510.35}]}
{"op":"mcm","clk":"11843856455","pt":1723588228119,"mc":[{"id":"1.231659919","rc":[{"batb":[[1,2,12.44],[2,1.9,16.58]],"batl":[[1,2.36,1],[2,12,0.52]],"ltp":2.12,"tv":39.94,"id":40096579},{"batb":[[1,1.86,764.48],[2,1.81,16.58]],"ltp":1.9,"tv":470.4,"id":40096581}]}]}
{"op":"mcm","clk":"11843856801","pt":1723588238330,"mc":[{"id":"1.231659919","rc":[{"trd":[[2.1,18]],"batb":[[0,2,12.44],[1,1.9,16.58],[2,1.89,222]],"ltp":2.1,"tv":57.94,"id":40096579},{"trd":[[1.91,19.79]],"batb":[[0,1.91,9.38],[1,1.9,7286.32],[2,1.86,764.48]],"ltp":1.91,"tv":490.19,"id":40096581}],"tv":548.14}]}
{"op":"mcm","clk":"11843856813","pt":1723588238742,"mc":[{"id":"1.231659919","rc":[{"batb":[[0,2.02,10],[1,2,12.44],[2,1.9,16.58]],"ltp":2.1,"tv":57.94,"id":40096579}]}]}
{"op":"mcm","clk":"11843856912","pt":1723588242141,"mc":[{"id":"1.231659919","rc":[{"batb":[[0,2,12.44],[1,1.9,16.58],[2,1.89,222]],"ltp":2.1,"tv":57.94,"id":40096579}]}]}
{"op":"mcm","clk":"11843856940","pt":1723588243016,"mc":[{"id":"1.231659919","rc":[{"batb":[[0,2.06,35.79],[1,2,12.44],[2,1.9,16.58]],"ltp":2.1,"tv":57.94,"id":40096579}]}]}
{"op":"mcm","clk":"11843864249","pt":1723588449574,"mc":[{"id":"1.231659919","rc":[{"batb":[[0,1.91,26.47]],"batl":[[1,1.93,17.09],[2,1.94,640]],"ltp":1.91,"tv":490.19,"id":40096581}]}]}
{"op":"mcm","clk":"11843881701","pt":1723588944779,"mc":[{"id":"1.231659919","rc":[{"batl":[[0,2.08,4],[1,2.14,5],[2,2.36,1]],"ltp":2.1,"tv":57.94,"id":40096579},{"trd":[[1.92,4],[1.93,18.6]],"batl":[[0,1.93,7.79],[1,1.94,640],[2,1.98,138.46]],"ltp":1.93,"tv":512.79,"id":40096581}],"tv":570.74}]}
{"op":"mcm","clk":"11843882069","pt":1723588954269,"mc":[{"id":"1.231659919","rc":[{"trd":[[1.93,30.6]],"batl":[[0,1.93,18.46]],"ltp":1.93,"tv":524.79,"id":40096581}],"tv":582.74}]}
{"op":"mcm","clk":"11843890185","pt":1723588988242,"mc":[{"id":"1.231659919","rc":[{"trd":[[1.93,67.52],[1.94,166.04]],"batb":[[0,1.92,6],[1,1.91,35.47],[2,1.9,7297.32]],"batl":[[0,1.94,556.98],[1,1.98,138.46],[2,12,0.52]],"ltp":1.94,"tv":727.75,"id":40096581}],"tv":785.7}]}
{"op":"mcm","clk":"11843890208","pt":1723588988856,"mc":[{"id":"1.231659919","rc":[{"batb":[[0,1.92,22.74]],"ltp":1.94,"tv":727.75,"id":40096581}]}]}
{"op":"mcm","clk":"11843890278","pt":1723588990857,"mc":[{"id":"1.231659919","rc":[{"batb":[[0,1.93,17.09],[1,1.92,22.74],[2,1.91,35.47]],"ltp":1.94,"tv":727.75,"id":40096581}]}]}
{"op":"mcm","clk":"11843890341","pt":1723588992244,"mc":[{"id":"1.231659919","rc":[{"batb":[[1,1.92,6]],"ltp":1.94,"tv":727.75,"id":40096581}]}]}
{"op":"mcm","clk":"11843890380","pt":1723588992861,"mc":[{"id":"1.231659919","rc":[{"batb":[[0,1.92,6],[1,1.91,35.47],[2,1.9,7297.32]],"ltp":1.94,"tv":727.75,"id":40096581}]}]}
{"op":"mcm","clk":"11843891493","pt":1723589021991,"mc":[{"id":"1.231659919","rc":[{"trd":[[1.94,194.38]],"batl":[[0,1.94,542.81]],"ltp":1.94,"tv":756.09,"id":40096581}],"tv":814.04}]}
{"op":"mcm","clk":"11843893117","pt":1723589067825,"mc":[{"id":"1.231659919","rc":[{"batb":[[0,1.92,22.74]],"ltp":1.94,"tv":756.09,"id":40096581}]}]}
{"op":"mcm","clk":"11843893140","pt":1723589068744,"mc":[{"id":"1.231659919","rc":[{"batb":[[0,1.93,17.09],[1,1.92,22.74],[2,1.91,35.47]],"ltp":1.94,"tv":756.09,"id":40096581}]}]}
{"op":"mcm","clk":"11843893214","pt":1723589070342,"mc":[{"id":"1.231659919","rc":[{"batb":[[0,1.92,6],[1,1.91,35.47],[2,1.9,7301.32]],"ltp":1.94,"tv":756.09,"id":40096581}]}]}
{"op":"mcm","clk":"11843893934","pt":1723589090362,"mc":[{"id":"1.231659919","rc":[{"trd":[[1.92,5.7]],"batb":[[0,1.92,5.15]],"ltp":1.92,"tv":757.8,"id":40096581}],"tv":815.74}]}
{"op":"mcm","clk":"11843896127","pt":1723589145826,"mc":[{"id":"1.231659919","rc":[{"batb":[[0,1.92,21.89]],"ltp":1.92,"tv":757.8,"id":40096581}]}]}
{"op":"mcm","clk":"11843896162","pt":1723589146902,"mc":[{"id":"1.231659919","rc":[{"batb":[[0,1.93,17.09],[1,1.92,21.89],[2,1.91,35.47]],"ltp":1.92,"tv":757.8,"id":40096581}]}]}
{"op":"mcm","clk":"11843896197","pt":1723589147723,"mc":[{"id":"1.231659919","rc":[{"batb":[[1,1.92,5.15]],"ltp":1.92,"tv":757.8,"id":40096581}]}]}
{"op":"mcm","clk":"11843896251","pt":1723589149107,"mc":[{"id":"1.231659919","rc":[{"batb":[[0,1.92,5.15],[1,1.91,35.47],[2,1.9,7301.32]],"ltp":1.92,"tv":757.8,"id":40096581}]}]}
{"op":"mcm","clk":"11843899239","pt":1723589224527,"mc":[{"id":"1.231659919","rc":[{"batb":[[0,1.92,21.89]],"ltp":1.92,"tv":757.8,"id":40096581}]}]}
{"op":"mcm","clk":"11843899309","pt":1723589226019,"mc":[{"id":"1.231659919","rc":[{"batb":[[0,1.93,17.09],[1,1.92,21.89],[2,1.91,35.47]],"ltp":1.92,"tv":757.8,"id":40096581}]}]}
{"op":"mcm","clk":"11843899343","pt":1723589226790,"mc":[{"id":"1.231659919","rc":[{"batb":[[1,1.92,5.15]],"ltp":1.92,"tv":757.8,"id":40096581}]}]}
{"op":"mcm","clk":"11843899387","pt":1723589228019,"mc":[{"id":"1.231659919","rc":[{"batb":[[0,1.92,5.15],[1,1.91,35.47],[2,1.9,7301.32]],"ltp":1.92,"tv":757.8,"id":40096581}]}]}
{"op":"mcm","clk":"11843902441","pt":1723589304207,"mc":[{"id":"1.231659919","rc":[{"batb":[[0,1.92,21.89]],"ltp":1.92,"tv":757.8,"id":40096581}]}]}
{"op":"mcm","clk":"11843902539","pt":1723589306217,"mc":[{"id":"1.231659919","rc":[{"batb":[[0,1.93,17.09],[1,1.92,21.89],[2,1.91,35.47]],"ltp":1.92,"tv":757.8,"id":40096581}]}]}
{"op":"mcm","clk":"11843902551","pt":1723589306627,"mc":[{"id":"1.231659919","rc":[{"batb":[[1,1.92,5.15]],"ltp":1.92,"tv":757.8,"id":40096581}]}]}
{"op":"mcm","clk":"11843902620","pt":1723589308006,"mc":[{"id":"1.231659919","rc":[{"batb":[[0,1.92,5.15],[1,1.91,35.47],[2,1.9,7302.32]],"ltp":1.92,"tv":757.8,"id":40096581}]}]}
{"op":"mcm","clk":"11843905566","pt":1723589382601,"mc":[{"id":"1.231659919","rc":[{"batb":[[0,1.92,21.89]],"ltp":1.92,"tv":757.8,"id":40096581}]}]}
{"op":"mcm","clk":"11843905621","pt":1723589383834,"mc":[{"id":"1.231659919","rc":[{"batb":[[0,1.93,17.09],[1,1.92,21.89],[2,1.91,35.47]],"ltp":1.92,"tv":757.8,"id":40096581}]}]}
{"op":"mcm","clk":"11843905663","pt":1723589384604,"mc":[{"id":"1.231659919","rc":[{"batb":[[1,1.92,5.15]],"ltp":1.92,"tv":757.8,"id":40096581}]}]}
{"op":"mcm","clk":"11843905710","pt":1723589386039,"mc":[{"id":"1.231659919","rc":[{"batb":[[0,1.92,5.15],[1,1.91,35.47],[2,1.9,7302.32]],"ltp":1.92,"tv":757.8,"id":40096581}]}]}
{"op":"mcm","clk":"11843908736","pt":1723589461333,"mc":[{"id":"1.231659919","rc":[{"batb":[[0,1.92,21.89]],"ltp":1.92,"tv":757.8,"id":40096581}]}]}
{"op":"mcm","clk":"11843908822","pt":1723589463229,"mc":[{"id":"1.231659919","rc":[{"batb":[[0,1.93,17.09],[1,1.92,21.89],[2,1.91,35.47]],"ltp":1.92,"tv":757.8,"id":40096581}]}]}
{"op":"mcm","clk":"11843908838","pt":1723589463636,"mc":[{"id":"1.231659919","rc":[{"batb":[[1,1.92,5.15]],"ltp":1.92,"tv":757.8,"id":40096581}]}]}
{"op":"mcm","clk":"11843908887","pt":1723589465127,"mc":[{"id":"1.231659919","rc":[{"batb":[[0,1.92,5.15],[1,1.91,35.47],[2,1.9,7302.32]],"ltp":1.92,"tv":757.8,"id":40096581}]}]}
{"op":"mcm","clk":"11843911664","pt":1723589540283,"mc":[{"id":"1.231659919","rc":[{"batb":[[0,1.93,17.09],[1,1.92,21.89],[2,1.91,35.47]],"ltp":1.92,"tv":757.8,"id":40096581}]}]}
{"op":"mcm","clk":"11843911708","pt":1723589541716,"mc":[{"id":"1.231659919","rc":[{"batb":[[1,1.92,5.15]],"ltp":1.92,"tv":757.8,"id":40096581}]}]}
{"op":"mcm","clk":"11843911781","pt":1723589544222,"mc":[{"id":"1.231659919","rc":[{"batb":[[0,1.92,5.15],[1,1.91,35.47],[2,1.9,7302.32]],"ltp":1.92,"tv":757.8,"id":40096581}]}]}
{"op":"mcm","clk":"11843914554","pt":1723589616610,"mc":[{"id":"1.231659919","rc":[{"batb":[[0,1.92,21.89]],"ltp":1.92,"tv":757.8,"id":40096581}]}]}
{"op":"mcm","clk":"11843914622","pt":1723589618810,"mc":[{"id":"1.231659919","rc":[{"batb":[[0,1.93,17.09],[1,1.92,21.89],[2,1.91,35.47]],"ltp":1.92,"tv":757.8,"id":40096581}]}]}
{"op":"mcm","clk":"11843914666","pt":1723589619887,"mc":[{"id":"1.231659919","rc":[{"batb":[[1,1.92,5.15]],"ltp":1.92,"tv":757.8,"id":40096581}]}]}
{"op":"mcm","clk":"11843914700","pt":1723589620807,"mc":[{"id":"1.231659919","rc":[{"batb":[[0,1.92,5.15],[1,1.91,35.47],[2,1.9,7302.32]],"ltp":1.92,"tv":757.8,"id":40096581}]}]}
{"op":"mcm","clk":"11843915577","pt":1723589647243,"mc":[{"id":"1.231659919","rc":[{"batb":[[0,1.92,17],[1,1.91,46.47]],"ltp":1.92,"tv":757.8,"id":40096581}]}]}
{"op":"mcm","clk":"11843915631","pt":1723589649241,"mc":[{"id":"1.231659919","rc":[{"batb":[[0,1.93,16.66],[1,1.92,17],[2,1.91,32.47]],"ltp":1.92,"tv":757.8,"id":40096581}]}]}
{"op":"mcm","clk":"11843915676","pt":1723589650831,"mc":[{"id":"1.231659919","rc":[{"batb":[[2,1.91,15.38]],"ltp":1.92,"tv":757.8,"id":40096581}]}]}
{"op":"mcm","clk":"11843915800","pt":1723589654417,"mc":[{"id":"1.231659919","rc":[{"batb":[[0,1.93,33.75]],"ltp":1.92,"tv":757.8,"id":40096581}]}]}
{"op":"mcm","clk":"11843923300","pt":1723589846372,"mc":[{"id":"1.231659919","rc":[{"trd":[[1.93,135.02]],"batb":[[0,1.92,17],[1,1.91,35.38],[2,1.9,7310.32]],"batl":[[0,1.93,417.06],[1,1.94,542.81],[2,1.98,138.46]],"ltp":1.93,"tv":825.3,"id":40096581}],"tv":883.24}]}
{"op":"mcm","clk":"11843923303","pt":1723589846471,"mc":[{"id":"1.231659919","rc":[{"batb":[[1,1.91,29.38]],"ltp":1.93,"tv":825.3,"id":40096581}]}]}
{"op":"mcm","clk":"11843923639","pt":1723589854060,"mc":[{"id":"1.231659919","rc":[{"trd":[[1.93,969.14],[1.94,242.52]],"batb":[[1,1.91,18.38],[2,1.9,7286.32]],"batl":[[0,1.94,518.74],[1,1.98,138.46],[2,12,0.52]],"ltp":1.94,"tv":1707.56,"id":40096581}],"tv":1765.5}]}
{"op":"mcm","clk":"11843923806","pt":1723589858681,"mc":[{"id":"1.231659919","rc":[{"batb":[[0,2.02,37.19]],"ltp":2.1,"tv":57.94,"id":40096579}]}]}
{"op":"mcm","clk":"11843929609","pt":1723589988052,"mc":[{"id":"1.231659919","rc":[{"batl":[[0,1.93,450.81],[1,1.94,518.74],[2,1.98,138.46]],"ltp":1.94,"tv":1707.56,"id":40096581}]}]}
{"op":"mcm","clk":"11843929923","pt":1723589994469,"mc":[{"id":"1.231659919","rc":[{"trd":[[1.93,1719.14]],"batl":[[0,1.93,75.81]],"ltp":1.93,"tv":2457.56,"id":40096581}],"tv":2515.5}]}
{"op":"mcm","clk":"11843930587","pt":1723590007219,"mc":[{"id":"1.231659919","rc":[{"trd":[[2.06,27.94]],"batb":[[1,2,12.43],[2,1.9,16.58]],"ltp":2.1,"tv":57.94,"id":40096579},{"trd":[[1.83,55.19],[1.86,188.22],[1.87,34.02],[1.9,37.47],[1.93,1870.77]],"batb":[[0,1.93,299.19],[1,1.92,17],[2,1.91,18.38]],"batl":[[0,1.94,518.74],[1,1.98,138.46],[2,12,0.52]],"ltp":1.93,"tv":2609.21,"id":40096581}],"tv":2667.15}]}
{"op":"mcm","clk":"11843934078","pt":1723590079712,"mc":[{"id":"1.231659919","rc":[{"trd":[[1.93,2469.15]],"batb":[[0,1.92,17],[1,1.91,18.38],[2,1.9,7286.32]],"batl":[[0,1.93,151.62],[1,1.94,518.74],[2,1.98,138.46]],"ltp":1.93,"tv":3207.59,"id":40096581}],"tv":3265.53}]}
{"op":"mcm","clk":"11843934562","pt":1723590089864,"mc":[{"id":"1.231659919","rc":[{"trd":[[1.93,2772.39],[1.94,272.02]],"batb":[[1,1.91,9.38]],"batl":[[0,1.94,503.99],[1,1.98,138.46],[2,12,0.52]],"ltp":1.94,"tv":3540.33,"id":40096581}],"tv":3598.27}]}
{"op":"mcm","clk":"11843936142","pt":1723590121187,"mc":[{"id":"1.231659919","rc":[{"batl":[[0,1.94,507.99]],"ltp":1.94,"tv":3540.33,"id":40096581}]}]}
{"op":"mcm","clk":"11843936164","pt":1723590121760,"mc":[{"id":"1.231659919","rc":[{"batl":[[0,1.94,503.99]],"ltp":1.94,"tv":3540.33,"id":40096581}]}]}
{"op":"mcm","clk":"11843936848","pt":1723590136262,"mc":[{"id":"1.231659919","rc":[{"batb":[[0,1.92,21]],"ltp":1.94,"tv":3540.33,"id":40096581}]}]}
{"op":"mcm","clk":"11843941917","pt":1723590237343,"mc":[{"id":"1.231659919","rc":[{"trd":[[2.08,4]],"batl":[[0,2.14,5],[1,2.36,1],[2,12,0.52]],"ltp":2.08,"tv":61.94,"id":40096579},{"trd":[[1.92,52.03]],"batb":[[0,1.91,9.38],[1,1.9,7286.32],[2,1.86,764.48]],"batl":[[0,1.92,274.67],[1,1.94,503.99],[2,1.98,138.46]],"ltp":1.92,"tv":3586.66,"id":40096581}],"tv":3648.6}]}
{"op":"mcm","clk":"11843941922","pt":1723590237445,"mc":[{"id":"1.231659919","rc":[{"batb":[[0,2.04,10],[1,2.02,37.19],[2,2,12.43]],"ltp":2.08,"tv":61.94,"id":40096579},{"batl":[[1,1.93,5],[2,1.94,503.99]],"ltp":1.92,"tv":3586.66,"id":40096581}]}]}
{"op":"mcm","clk":"11843942086","pt":1723590240746,"mc":[{"id":"1.231659919","rc":[{"batb":[[0,2.02,37.19],[1,2,12.43],[2,1.9,16.58]],"ltp":2.08,"tv":61.94,"id":40096579}]}]}
{"op":"mcm","clk":"11843942206","pt":1723590243414,"mc":[{"id":"1.231659919","rc":[{"batb":[[0,2.04,10],[1,2.02,37.19],[2,2,12.43]],"ltp":2.08,"tv":61.94,"id":40096579}]}]}
{"op":"mcm","clk":"11843942332","pt":1723590246817,"mc":[{"id":"1.231659919","rc":[{"batb":[[0,2.02,37.19],[1,2,12.43],[2,1.9,16.58]],"ltp":2.08,"tv":61.94,"id":40096579}]}]}
{"op":"mcm","clk":"11843942496","pt":1723590250666,"mc":[{"id":"1.231659919","rc":[{"batb":[[0,2.04,10],[1,2.02,37.19],[2,2,12.43]],"ltp":2.08,"tv":61.94,"id":40096579}]}]}
{"op":"mcm","clk":"11843942600","pt":1723590253953,"mc":[{"id":"1.231659919","rc":[{"batb":[[0,2.02,37.19],[1,2,12.43],[2,1.9,16.58]],"ltp":2.08,"tv":61.94,"id":40096579}]}]}
{"op":"mcm","clk":"11843942729","pt":1723590256833,"mc":[{"id":"1.231659919","rc":[{"batb":[[0,2.04,10],[1,2.02,37.19],[2,2,12.43]],"ltp":2.08,"tv":61.94,"id":40096579}]}]}
{"op":"mcm","clk":"11843942875","pt":1723590260276,"mc":[{"id":"1.231659919","rc":[{"batb":[[0,2.02,37.19],[1,2,12.43],[2,1.9,16.58]],"ltp":2.08,"tv":61.94,"id":40096579},{"trd":[[1.91,38.55]],"batb":[[0,1.9,7286.32],[1,1.86,764.48],[2,1.81,16.58]],"batl":[[0,1.91,265.29]],"ltp":1.91,"tv":3605.42,"id":40096581}],"tv":3667.36}]}
{"op":"mcm","clk":"11843943045","pt":1723590263864,"mc":[{"id":"1.231659919","rc":[{"batb":[[0,2.04,10],[1,2.02,37.19],[2,2,12.43]],"ltp":2.08,"tv":61.94,"id":40096579}]}]}
