{"op":"mcm","clk":"11776794421","pt":1722328758278,"mc":[{"id":"1.231241311","marketDefinition":{"bspMarket":false,"turnInPlayEnabled":true,"persistenceEnabled":true,"marketBaseRate":5.0,"eventId":"33454955","eventTypeId":"4","numberOfWinners":1,"bettingType":"ODDS","marketType":"MATCH_ODDS","marketTime":"2024-08-01T17:30:00.000Z","suspendTime":"2024-08-01T17:30:00.000Z","bspReconciled":false,"complete":true,"inPlay":false,"crossMatching":true,"runnersVoidable":false,"numberOfActiveRunners":2,"betDelay":0,"status":"OPEN","runners":[{"status":"ACTIVE","sortPriority":1,"id":26354926,"name":"Southern Brave"},{"status":"ACTIVE","sortPriority":2,"id":26354922,"name":"Manchester Originals"}],"regulators":["MR_INT"],"countryCode":"GB","discountAllowed":false,"timezone":"GMT","openDate":"2024-08-01T17:30:00.000Z","version":6047188142,"name":"Match Odds","eventName":"Southern Brave v Manchester Originals"},"rc":[{"batb":[[0,1.06,100],[1,1.05,100],[2,1.04,100]],"ltp":0.0,"tv":0.0,"id":26354926},{"batb":[[0,1.06,100],[1,1.05,100],[2,1.04,100]],"ltp":0.0,"tv":0.0,"id":26354922}]}]}
{"op":"mcm","clk":"11776794486","pt":1722328759279,"mc":[{"id":"1.231241311","marketDefinition":{"bspMarket":false,"turnInPlayEnabled":true,"persistenceEnabled":true,"marketBaseRate":5.0,"eventId":"33454955","eventTypeId":"4","numberOfWinners":1,"bettingType":"ODDS","marketType":"MATCH_ODDS","marketTime":"2024-08-01T17:30:00.000Z","suspendTime":"2024-08-01T17:30:00.000Z","bspReconciled":false,"complete":true,"inPlay":false,"crossMatching":true,"runnersVoidable":false,"numberOfActiveRunners":2,"betDelay":0,"status":"OPEN","runners":[{"status":"ACTIVE","sortPriority":1,"id":26354926,"name":"Southern Brave"},{"status":"ACTIVE","sortPriority":2,"id":26354922,"name":"Manchester Originals"}],"regulators":["MR_INT"],"countryCode":"GB","discountAllowed":true,"timezone":"GMT","openDate":"2024-08-01T17:30:00.000Z","version":6047188142,"name":"Match Odds","eventName":"Southern Brave v Manchester Originals"}}]}
{"op":"mcm","clk":"11777420373","pt":1722336134340,"mc":[{"id":"1.231241311","rc":[{"batb":[[0,1.1,25000],[1,1.09,25000],[2,1.08,25000]],"ltp":0.0,"tv":0.0,"id":26354926},{"batb":[[0,1.1,25000],[1,1.09,25000],[2,1.08,25000]],"ltp":0.0,"tv":0.0,"id":26354922}]}]}
{"op":"mcm","clk":"11778617050","pt":1722347981643,"mc":[{"id":"1.231241311","rc":[{"batb":[[0,1.1,10000]],"ltp":0.0,"tv":0.0,"id":26354926}]}]}
{"op":"mcm","clk":"11778617246","pt":1722347983460,"mc":[{"id":"1.231241311","rc":[{"batb":[[0,1.1,10000]],"ltp":0.0,"tv":0.0,"id":26354922}]}]}
{"op":"mcm","clk":"11778617542","pt":1722347986027,"mc":[{"id":"1.231241311","rc":[{"batb":[[1,1.09,10000]],"ltp":0.0,"tv":0.0,"id":26354926}]}]}
{"op":"mcm","clk":"11778617706","pt":1722347987838,"mc":[{"id":"1.231241311","rc":[{"batb":[[1,1.09,10000]],"ltp":0.0,"tv":0.0,"id":26354922}]}]}
{"op":"mcm","clk":"11778618123","pt":1722347992046,"mc":[{"id":"1.231241311","rc":[{"batb":[[2,1.08,10000]],"ltp":0.0,"tv":0.0,"id":26354922}]}]}
{"op":"mcm","clk":"11778618596","pt":1722347996964,"mc":[{"id":"1.231241311","rc":[{"batb":[[2,1.08,10000]],"ltp":0.0,"tv":0.0,"id":26354926}]}]}
{"op":"mcm","clk":"11780235476","pt":1722360972726,"mc":[{"id":"1.231241311","rc":[{"batb":[[0,1.25,100],[1,1.1,10000],[2,1.09,10000]],"ltp":0.0,"tv":0.0,"id":26354926},{"batb":[[0,1.25,100],[1,1.1,10000],[2,1.09,10000]],"ltp":0.0,"tv":0.0,"id":26354922}]}]}
{"op":"mcm","clk":"11780783915","pt":1722365566296,"mc":[{"id":"1.231241311","rc":[{"batb":[[0,1.64,333],[1,1.25,100],[2,1.1,10000]],"ltp":0.0,"tv":0.0,"id":26354926}]}]}
{"op":"mcm","clk":"11780940184","pt":1722366569515,"mc":[{"id":"1.231241311","rc":[{"batb":[[0,1.65,6.44],[1,1.64,333],[2,1.25,100]],"ltp":0.0,"tv":0.0,"id":26354926}]}]}
{"op":"mcm","clk":"11780998927","pt":1722366905970,"mc":[{"id":"1.231241311","rc":[{"batb":[[0,1.65,22.97]],"ltp":0.0,"tv":0.0,"id":26354926},{"batl":[[0,2.56,10.6]],"ltp":0.0,"tv":0.0,"id":26354922}]}]}
{"op":"mcm","clk":"11781470712","pt":1722370556869,"mc":[{"id":"1.231241311","rc":[{"batb":[[0,1.66,6],[1,1.65,22.97],[2,1.64,333]],"ltp":0.0,"tv":0.0,"id":26354926},{"batb":[[0,1.26,20],[1,1.25,100],[2,1.1,10000]],"ltp":0.0,"tv":0.0,"id":26354922}]}]}
{"op":"mcm","clk":"11781644144","pt":1722373418348,"mc":[{"id":"1.231241311","rc":[{"batb":[[0,2.46,29.87],[1,1.26,20],[2,1.25,100]],"ltp":0.0,"tv":0.0,"id":26354922}]}]}
{"op":"mcm","clk":"11781667454","pt":1722373980614,"mc":[{"id":"1.231241311","rc":[{"batb":[[1,1.65,16.53]],"ltp":0.0,"tv":0.0,"id":26354926}]}]}
{"op":"mcm","clk":"11781677644","pt":1722374243943,"mc":[{"id":"1.231241311","rc":[{"batb":[[0,1.65,16.53],[1,1.64,333],[2,1.62,70.33]],"ltp":0.0,"tv":0.0,"id":26354926},{"batb":[[1,1.25,100],[2,1.1,10000]],"ltp":0.0,"tv":0.0,"id":26354922}]}]}
{"op":"mcm","clk":"11781915319","pt":1722381057218,"mc":[{"id":"1.231241311","rc":[{"batb":[[0,1.65,16.53]],"ltp":0.0,"tv":0.0,"id":26354926}]}]}
{"op":"mcm","clk":"11782147821","pt":1722386574987,"mc":[{"id":"1.231241311","rc":[{"batb":[[0,1.65,16.53]],"ltp":0.0,"tv":0.0,"id":26354926}]}]}
{"op":"mcm","clk":"11782438595","pt":1722391974965,"mc":[{"id":"1.231241311","rc":[{"batb":[[0,1.65,16.53]],"ltp":0.0,"tv":0.0,"id":26354926}]}]}
{"op":"mcm","clk":"11782663970","pt":1722397374975,"mc":[{"id":"1.231241311","rc":[{"batb":[[0,1.65,16.53]],"ltp":0.0,"tv":0.0,"id":26354926}]}]}
{"op":"mcm","clk":"11782713595","pt":1722398859281,"mc":[{"id":"1.231241311","rc":[{"batb":[[0,1.65,16.54],[2,1.61,111]],"ltp":0.0,"tv":0.0,"id":26354926},{"batb":[[0,1.25,100],[1,1.1,10000],[2,1.09,10000]],"ltp":0.0,"tv":0.0,"id":26354922}]}]}
{"op":"mcm","clk":"11782714015","pt":1722398862570,"mc":[{"id":"1.231241311","rc":[{"batb":[[2,1.62,70.33]],"ltp":0.0,"tv":0.0,"id":26354926},{"batb":[[0,2.46,29.87],[1,1.25,100],[2,1.1,10000]],"ltp":0.0,"tv":0.0,"id":26354922}]}]}
{"op":"mcm","clk":"11782766801","pt":1722400234286,"mc":[{"id":"1.231241311","rc":[{"batb":[[2,1.61,111]],"ltp":0.0,"tv":0.0,"id":26354926},{"batb":[[0,1.25,100],[1,1.1,10000],[2,1.09,10000]],"ltp":0.0,"tv":0.0,"id":26354922}]}]}
{"op":"mcm","clk":"11782767322","pt":1722400237765,"mc":[{"id":"1.231241311","rc":[{"batb":[[2,1.62,70.33]],"ltp":0.0,"tv":0.0,"id":26354926},{"batb":[[0,2.46,29.87],[1,1.25,100],[2,1.1,10000]],"ltp":0.0,"tv":0.0,"id":26354922}]}]}
{"op":"mcm","clk":"11782782874","pt":1722400617518,"mc":[{"id":"1.231241311","rc":[{"batb":[[2,1.61,111]],"ltp":0.0,"tv":0.0,"id":26354926},{"batb":[[0,1.25,100],[1,1.1,10000],[2,1.09,10000]],"ltp":0.0,"tv":0.0,"id":26354922}]}]}
{"op":"mcm","clk":"11782783071","pt":1722400619154,"mc":[{"id":"1.231241311","rc":[{"batb":[[2,1.62,70.33]],"ltp":0.0,"tv":0.0,"id":26354926},{"batb":[[0,2.46,29.87],[1,1.25,100],[2,1.1,10000]],"ltp":0.0,"tv":0.0,"id":26354922}]}]}
{"op":"mcm","clk":"11782838714","pt":1722401937473,"mc":[{"id":"1.231241311","rc":[{"batb":[[2,1.61,111]],"ltp":0.0,"tv":0.0,"id":26354926},{"batb":[[0,1.25,100],[1,1.1,10000],[2,1.09,10000]],"ltp":0.0,"tv":0.0,"id":26354922}]}]}
{"op":"mcm","clk":"11782838884","pt":1722401939456,"mc":[{"id":"1.231241311","rc":[{"batb":[[2,1.62,70.33]],"ltp":0.0,"tv":0.0,"id":26354926},{"batb":[[0,2.46,29.87],[1,1.25,100],[2,1.1,10000]],"ltp":0.0,"tv":0.0,"id":26354922}]}]}
{"op":"mcm","clk":"11782849308","pt":1722402214870,"mc":[{"id":"1.231241311","rc":[{"batb":[[0,1.65,16.53],[2,1.61,111]],"ltp":0.0,"tv":0.0,"id":26354926},{"batb":[[0,1.25,100],[1,1.1,10000],[2,1.09,10000]],"ltp":0.0,"tv":0.0,"id":26354922}]}]}
{"op":"mcm","clk":"11782849387","pt":1722402215797,"mc":[{"id":"1.231241311","rc":[{"batb":[[2,1.62,70.33]],"ltp":0.0,"tv":0.0,"id":26354926},{"batb":[[0,2.46,29.87],[1,1.25,100],[2,1.1,10000]],"ltp":0.0,"tv":0.0,"id":26354922}]}]}
{"op":"mcm","clk":"11782915001","pt":1722403478010,"mc":[{"id":"1.231241311","rc":[{"batb":[[2,1.61,111]],"ltp":0.0,"tv":0.0,"id":26354926},{"batb":[[0,1.25,100],[1,1.1,10000],[2,1.09,10000]],"ltp":0.0,"tv":0.0,"id":26354922}]}]}
{"op":"mcm","clk":"11782915363","pt":1722403481503,"mc":[{"id":"1.231241311","rc":[{"batb":[[2,1.62,70.33]],"ltp":0.0,"tv":0.0,"id":26354926},{"batb":[[0,2.46,29.87],[1,1.25,100],[2,1.1,10000]],"ltp":0.0,"tv":0.0,"id":26354922}]}]}
{"op":"mcm","clk":"11782929628","pt":1722403756620,"mc":[{"id":"1.231241311","rc":[{"batb":[[2,1.61,111]],"ltp":0.0,"tv":0.0,"id":26354926},{"batb":[[0,1.25,100],[1,1.1,10000],[2,1.09,10000]],"ltp":0.0,"tv":0.0,"id":26354922}]}]}
{"op":"mcm","clk":"11782929790","pt":1722403757454,"mc":[{"id":"1.231241311","rc":[{"batb":[[2,1.62,70.33]],"ltp":0.0,"tv":0.0,"id":26354926},{"batb":[[0,2.46,29.87],[1,1.25,100],[2,1.1,10000]],"ltp":0.0,"tv":0.0,"id":26354922}]}]}
{"op":"mcm","clk":"11782985313","pt":1722405066680,"mc":[{"id":"1.231241311","rc":[{"batb":[[0,1.66,111],[1,1.65,16.53],[2,1.64,333]],"ltp":0.0,"tv":0.0,"id":26354926}]}]}
{"op":"mcm","clk":"11782985367","pt":1722405067908,"mc":[{"id":"1.231241311","rc":[{"batb":[[1,1.64,333],[2,1.62,70.33]],"ltp":0.0,"tv":0.0,"id":26354926}]}]}
{"op":"mcm","clk":"11782985868","pt":1722405080323,"mc":[{"id":"1.231241311","rc":[{"trd":[[1.69,2]],"ltp":1.69,"tv":2.0,"id":26354926},{"trd":[[2.46,1.37]],"batb":[[0,2.46,28.5]],"ltp":2.46,"tv":1.37,"id":26354922}],"tv":3.37}]}
{"op":"mcm","clk":"11782985994","pt":1722405083294,"mc":[{"id":"1.231241311","rc":[{"batb":[[0,2.46,29.87]],"ltp":2.46,"tv":1.37,"id":26354922}]}]}
{"op":"mcm","clk":"11782990399","pt":1722405183133,"mc":[{"id":"1.231241311","rc":[{"batb":[[2,1.57,950]],"ltp":1.69,"tv":2.0,"id":26354926},{"batb":[[0,1.25,100],[1,1.1,10000],[2,1.09,10000]],"ltp":2.46,"tv":1.37,"id":26354922}]}]}
{"op":"mcm","clk":"11782990449","pt":1722405183609,"mc":[{"id":"1.231241311","rc":[{"batb":[[2,1.62,70.33]],"ltp":1.69,"tv":2.0,"id":26354926},{"batb":[[0,2.46,29.87],[1,1.25,100],[2,1.1,10000]],"ltp":2.46,"tv":1.37,"id":26354922}]}]}
{"op":"mcm","clk":"11783019529","pt":1722405800530,"mc":[{"id":"1.231241311","rc":[{"batb":[[0,1.67,5.45],[1,1.66,111],[2,1.64,333]],"ltp":1.69,"tv":2.0,"id":26354926}]}]}
{"op":"mcm","clk":"11783351417","pt":1722413574970,"mc":[{"id":"1.231241311","rc":[{"batb":[[0,1.67,5.45]],"ltp":1.69,"tv":2.0,"id":26354926}]}]}
{"op":"mcm","clk":"11783392795","pt":1722414512418,"mc":[{"id":"1.231241311","marketDefinition":{"bspMarket":false,"turnInPlayEnabled":true,"persistenceEnabled":true,"marketBaseRate":5.0,"eventId":"33454955","eventTypeId":"4","numberOfWinners":1,"bettingType":"ODDS","marketType":"MATCH_ODDS","marketTime":"2024-08-01T13:00:00.000Z","suspendTime":"2024-08-01T13:00:00.000Z","bspReconciled":false,"complete":true,"inPlay":false,"crossMatching":true,"runnersVoidable":false,"numberOfActiveRunners":2,"betDelay":0,"status":"OPEN","runners":[{"status":"ACTIVE","sortPriority":1,"id":26354926,"name":"Southern Brave"},{"status":"ACTIVE","sortPriority":2,"id":26354922,"name":"Manchester Originals"}],"regulators":["MR_INT"],"countryCode":"GB","discountAllowed":true,"timezone":"GMT","openDate":"2024-08-01T17:30:00.000Z","version":6048530531,"name":"Match Odds","eventName":"Southern Brave v Manchester Originals"}}]}
{"op":"mcm","clk":"11783392854","pt":1722414513442,"mc":[{"id":"1.231241311","marketDefinition":{"bspMarket":false,"turnInPlayEnabled":true,"persistenceEnabled":true,"marketBaseRate":5.0,"eventId":"33454955","eventTypeId":"4","numberOfWinners":1,"bettingType":"ODDS","marketType":"MATCH_ODDS","marketTime":"2024-08-01T13:00:00.000Z","suspendTime":"2024-08-01T13:00:00.000Z","bspReconciled":false,"complete":true,"inPlay":false,"crossMatching":true,"runnersVoidable":false,"numberOfActiveRunners":2,"betDelay":0,"status":"OPEN","runners":[{"status":"ACTIVE","sortPriority":1,"id":26354926,"name":"Southern Brave"},{"status":"ACTIVE","sortPriority":2,"id":26354922,"name":"Manchester Originals"}],"regulators":["MR_INT"],"countryCode":"GB","discountAllowed":true,"timezone":"GMT","openDate":"2024-08-01T13:00:00.000Z","version":6048530531,"name":"Match Odds","eventName":"Southern Brave v Manchester Originals"}}]}
{"op":"mcm","clk":"11783403195","pt":1722414772872,"mc":[{"id":"1.231241311","marketDefinition":{"bspMarket":false,"turnInPlayEnabled":true,"persistenceEnabled":true,"marketBaseRate":5.0,"eventId":"33454955","eventTypeId":"4","numberOfWinners":1,"bettingType":"ODDS","marketType":"MATCH_ODDS","marketTime":"2024-08-01T17:30:00.000Z","suspendTime":"2024-08-01T17:30:00.000Z","bspReconciled":false,"complete":true,"inPlay":false,"crossMatching":true,"runnersVoidable":false,"numberOfActiveRunners":2,"betDelay":0,"status":"OPEN","runners":[{"status":"ACTIVE","sortPriority":1,"id":26354926,"name":"Southern Brave"},{"status":"ACTIVE","sortPriority":2,"id":26354922,"name":"Manchester Originals"}],"regulators":["MR_INT"],"countryCode":"GB","discountAllowed":true,"timezone":"GMT","openDate":"2024-08-01T13:00:00.000Z","version":6048533419,"name":"Match Odds","eventName":"Southern Brave v Manchester Originals"}}]}
{"op":"mcm","clk":"11783403297","pt":1722414774853,"mc":[{"id":"1.231241311","marketDefinition":{"bspMarket":false,"turnInPlayEnabled":true,"persistenceEnabled":true,"marketBaseRate":5.0,"eventId":"33454955","eventTypeId":"4","numberOfWinners":1,"bettingType":"ODDS","marketType":"MATCH_ODDS","marketTime":"2024-08-01T17:30:00.000Z","suspendTime":"2024-08-01T17:30:00.000Z","bspReconciled":false,"complete":true,"inPlay":false,"crossMatching":true,"runnersVoidable":false,"numberOfActiveRunners":2,"betDelay":0,"status":"OPEN","runners":[{"status":"ACTIVE","sortPriority":1,"id":26354926,"name":"Southern Brave"},{"status":"ACTIVE","sortPriority":2,"id":26354922,"name":"Manchester Originals"}],"regulators":["MR_INT"],"countryCode":"GB","discountAllowed":true,"timezone":"GMT","openDate":"2024-08-01T17:30:00.000Z","version":6048533419,"name":"Match Odds","eventName":"Southern Brave v Manchester Originals"}}]}
{"op":"mcm","clk":"11783486118","pt":1722416755326,"mc":[{"id":"1.231241311","rc":[{"batb":[[0,1.67,5.46],[2,1.64,401.14]],"ltp":1.69,"tv":2.0,"id":26354926},{"batb":[[0,2.44,30.28]],"ltp":2.46,"tv":1.37,"id":26354922}]}]}
{"op":"mcm","clk":"11783601767","pt":1722419149722,"mc":[{"id":"1.231241311","rc":[{"trd":[[1.7,0.07]],"ltp":1.7,"tv":2.07,"id":26354926},{"trd":[[2.44,0.05]],"batb":[[0,2.44,30.23]],"ltp":2.44,"tv":1.42,"id":26354922}],"tv":3.49}]}
{"op":"mcm","clk":"11783601829","pt":1722419150849,"mc":[{"id":"1.231241311","rc":[{"batb":[[0,2.44,30.28]],"ltp":2.44,"tv":1.42,"id":26354922}]}]}
{"op":"mcm","clk":"11783884923","pt":1722423832962,"mc":[{"id":"1.231241311","rc":[{"trd":[[1.7,43.53]],"batb":[[0,1.7,1630.4],[1,1.67,5.46],[2,1.66,111]],"ltp":1.7,"tv":45.53,"id":26354926},{"trd":[[2.44,30.33]],"batb":[[0,1.25,100],[1,1.1,10000],[2,1.09,10000]],"ltp":2.44,"tv":31.7,"id":26354922}],"tv":77.23}]}
{"op":"mcm","clk":"11783885029","pt":1722423834871,"mc":[{"id":"1.231241311","rc":[{"batb":[[1,1.66,111],[2,1.64,401.14]],"ltp":1.7,"tv":45.53,"id":26354926},{"batb":[[0,2.36,32.06],[1,1.25,100],[2,1.1,10000]],"ltp":2.44,"tv":31.7,"id":26354922}]}]}
{"op":"mcm","clk":"11783939700","pt":1722424558442,"mc":[{"id":"1.231241311","rc":[{"batb":[[0,1.71,17.13],[1,1.7,1630.4],[2,1.66,111]],"ltp":1.7,"tv":45.53,"id":26354926},{"batl":[[0,2.42,17.13]],"ltp":2.44,"tv":31.7,"id":26354922}]}]}
{"op":"mcm","clk":"11783970474","pt":1722425128256,"mc":[{"id":"1.231241311","rc":[{"batl":[[0,1.84,900]],"ltp":1.7,"tv":45.53,"id":26354926}]}]}
{"op":"mcm","clk":"11784232074","pt":1722428946567,"mc":[{"id":"1.231241311","rc":[{"batb":[[0,1.72,112.5],[1,1.71,17.13],[2,1.7,1630.4]],"ltp":1.7,"tv":45.53,"id":26354926},{"batl":[[0,2.42,17.13]],"ltp":2.44,"tv":31.7,"id":26354922}]}]}
{"op":"mcm","clk":"11784232236","pt":1722428948062,"mc":[{"id":"1.231241311","rc":[{"batb":[[1,1.7,1630.4],[2,1.66,111]],"ltp":1.7,"tv":45.53,"id":26354926}]}]}
{"op":"mcm","clk":"11784369934","pt":1722430376082,"mc":[{"id":"1.231241311","rc":[{"trd":[[1.72,3.6]],"batb":[[0,1.72,110.7]],"ltp":1.72,"tv":49.13,"id":26354926}],"tv":80.83}]}
{"op":"mcm","clk":"11784422219","pt":1722430978826,"mc":[{"id":"1.231241311","rc":[{"batb":[[1,1.1,10000],[2,1.09,10000]],"ltp":2.44,"tv":31.7,"id":26354922}]}]}
{"op":"mcm","clk":"11784642879","pt":1722433604156,"mc":[{"id":"1.231241311","rc":[{"batl":[[0,1.86,900]],"ltp":1.72,"tv":49.13,"id":26354926}]}]}
{"op":"mcm","clk":"11784799210","pt":1722435401120,"mc":[{"id":"1.231241311","rc":[{"trd":[[1.72,17.67]],"batb":[[0,1.72,96.63]],"ltp":1.72,"tv":63.2,"id":26354926},{"trd":[[2.4,10.08]],"ltp":2.4,"tv":41.77,"id":26354922}],"tv":104.97}]}
{"op":"mcm","clk":"11784819477","pt":1722435711540,"mc":[{"id":"1.231241311","rc":[{"batb":[[0,2.36,27.17]],"ltp":2.4,"tv":41.77,"id":26354922}]}]}
{"op":"mcm","clk":"11785237609","pt":1722440118537,"mc":[{"id":"1.231241311","rc":[{"batb":[[0,2.38,50.85],[1,2.36,27.17],[2,1.1,10000]],"ltp":2.4,"tv":41.77,"id":26354922}]}]}
{"op":"mcm","clk":"11785237926","pt":1722440121679,"mc":[{"id":"1.231241311","rc":[{"batb":[[1,1.1,10000],[2,1.09,10000]],"ltp":2.4,"tv":41.77,"id":26354922}]}]}
{"op":"mcm","clk":"11785238580","pt":1722440128247,"mc":[{"id":"1.231241311","rc":[{"batb":[[0,1.1,10000],[1,1.09,10000],[2,1.08,10000]],"ltp":2.4,"tv":41.77,"id":26354922}]}]}
{"op":"mcm","clk":"11785238591","pt":1722440128355,"mc":[{"id":"1.231241311","rc":[{"trd":[[1.72,88.63]],"batb":[[0,1.72,25.67]],"ltp":1.72,"tv":134.16,"id":26354926},{"trd":[[2.4,60.93]],"ltp":2.4,"tv":92.63,"id":26354922}],"tv":226.79}]}
{"op":"mcm","clk":"11785238916","pt":1722440131573,"mc":[{"id":"1.231241311","rc":[{"batb":[[0,2.36,27.17],[1,1.1,10000],[2,1.09,10000]],"ltp":2.4,"tv":92.63,"id":26354922}]}]}
{"op":"mcm","clk":"11785434344","pt":1722441941329,"mc":[{"id":"1.231241311","rc":[{"batl":[[0,1.76,45],[1,1.86,900]],"ltp":1.72,"tv":134.16,"id":26354926},{"trd":[[2.4,60.97]],"ltp":2.4,"tv":92.66,"id":26354922}],"tv":226.82}]}
{"op":"mcm","clk":"11785434932","pt":1722441946555,"mc":[{"id":"1.231241311","rc":[{"batl":[[1,1.8,22.5],[2,1.86,900]],"ltp":1.72,"tv":134.16,"id":26354926}]}]}
{"op":"mcm","clk":"11785435865","pt":1722441954758,"mc":[{"id":"1.231241311","rc":[{"batb":[[2,1.68,112.5]],"ltp":1.72,"tv":134.16,"id":26354926}]}]}
{"op":"mcm","clk":"11786005896","pt":1722445974968,"mc":[{"id":"1.231241311","rc":[{"trd":[[2.4,60.97]],"ltp":2.4,"tv":92.66,"id":26354922}],"tv":226.82}]}
{"op":"mcm","clk":"11786160303","pt":1722446940694,"mc":[{"id":"1.231241311","rc":[{"batb":[[0,2.36,47.47]],"ltp":2.4,"tv":92.66,"id":26354922}]}]}
{"op":"mcm","clk":"11786160925","pt":1722446944404,"mc":[{"id":"1.231241311","rc":[{"batb":[[0,2.36,20.3]],"ltp":2.4,"tv":92.66,"id":26354922}]}]}
{"op":"mcm","clk":"11786471690","pt":1722449057137,"mc":[{"id":"1.231241311","rc":[{"trd":[[2.4,60.95]],"ltp":2.4,"tv":92.65,"id":26354922}],"tv":226.81}]}
{"op":"mcm","clk":"11786537933","pt":1722449466643,"mc":[{"id":"1.231241311","rc":[{"batb":[[1,1.68,112.5],[2,1.65,111]],"ltp":1.72,"tv":134.16,"id":26354926}]}]}
{"op":"mcm","clk":"11786542353","pt":1722449493851,"mc":[{"id":"1.231241311","rc":[{"trd":[[1.74,64.38]],"batb":[[0,1.74,772.55],[1,1.72,25.67],[2,1.68,112.5]],"ltp":1.74,"tv":198.54,"id":26354926},{"trd":[[2.36,47.47]],"batb":[[0,1.1,10000],[1,1.09,10000],[2,1.08,10000]],"ltp":2.36,"tv":140.12,"id":26354922}],"tv":338.66}]}
{"op":"mcm","clk":"11786543139","pt":1722449498844,"mc":[{"id":"1.231241311","rc":[{"batb":[[0,2.28,28.87],[1,1.1,10000],[2,1.09,10000]],"ltp":2.36,"tv":140.12,"id":26354922}]}]}
{"op":"mcm","clk":"11786556822","pt":1722449581086,"mc":[{"id":"1.231241311","rc":[{"batb":[[0,1.72,25.67],[1,1.68,112.5],[2,1.65,111]],"ltp":1.74,"tv":198.54,"id":26354926}]}]}
{"op":"mcm","clk":"11786909161","pt":1722452147420,"mc":[{"id":"1.231241311","rc":[{"batl":[[0,1.74,1.17],[1,1.76,45],[2,1.8,22.5]],"ltp":1.74,"tv":198.54,"id":26354926}]}]}
{"op":"mcm","clk":"11786909584","pt":1722452151935,"mc":[{"id":"1.231241311","rc":[{"batl":[[0,1.76,45],[1,1.8,22.5],[2,1.86,900]],"ltp":1.74,"tv":198.54,"id":26354926}]}]}
{"op":"mcm","clk":"11786910354","pt":1722452158839,"mc":[{"id":"1.231241311","rc":[{"batl":[[0,1.74,2.34],[1,1.76,45],[2,1.8,22.5]],"ltp":1.74,"tv":198.54,"id":26354926}]}]}
{"op":"mcm","clk":"11786910700","pt":1722452161866,"mc":[{"id":"1.231241311","rc":[{"batl":[[0,1.76,45],[1,1.8,22.5],[2,1.86,900]],"ltp":1.74,"tv":198.54,"id":26354926}]}]}
{"op":"mcm","clk":"11786939016","pt":1722452469310,"mc":[{"id":"1.231241311","rc":[{"trd":[[2.4,61]],"batb":[[0,1.1,10000],[1,1.09,10000],[2,1.08,10000]],"ltp":2.36,"tv":140.17,"id":26354922}],"tv":338.71}]}
{"op":"mcm","clk":"11787031022","pt":1722453340658,"mc":[{"id":"1.231241311","rc":[{"batb":[[0,1.11,10],[1,1.1,10000],[2,1.09,10000]],"batl":[[0,5,0.78]],"ltp":2.36,"tv":140.17,"id":26354922}]}]}
{"op":"mcm","clk":"11787031382","pt":1722453343980,"mc":[{"id":"1.231241311","rc":[{"batb":[[0,1.1,10000],[1,1.09,10000],[2,1.08,10000]],"ltp":2.36,"tv":140.17,"id":26354922}]}]}
{"op":"mcm","clk":"11787031864","pt":1722453348218,"mc":[{"id":"1.231241311","rc":[{"batl":[[0,6,1.56]],"ltp":2.36,"tv":140.17,"id":26354922}]}]}
{"op":"mcm","clk":"11787032106","pt":1722453350088,"mc":[{"id":"1.231241311","rc":[{"batb":[[0,1.11,10],[1,1.1,10000],[2,1.09,10000]],"ltp":2.36,"tv":140.17,"id":26354922}]}]}
{"op":"mcm","clk":"11787032508","pt":1722453353790,"mc":[{"id":"1.231241311","rc":[{"batb":[[0,1.1,10000],[1,1.09,10000],[2,1.08,10000]],"ltp":2.36,"tv":140.17,"id":26354922}]}]}
{"op":"mcm","clk":"11787032703","pt":1722453355286,"mc":[{"id":"1.231241311","rc":[{"batl":[[1,7,0.78]],"ltp":2.36,"tv":140.17,"id":26354922}]}]}
{"op":"mcm","clk":"11787034079","pt":1722453366889,"mc":[{"id":"1.231241311","rc":[{"batb":[[0,1.11,10],[1,1.1,10000],[2,1.09,10000]],"batl":[[1,12,1.56]],"ltp":2.36,"tv":140.17,"id":26354922}]}]}
{"op":"mcm","clk":"11787034459","pt":1722453370115,"mc":[{"id":"1.231241311","rc":[{"batb":[[0,1.1,10000],[1,1.09,10000],[2,1.08,10000]],"ltp":2.36,"tv":140.17,"id":26354922}]}]}
{"op":"mcm","clk":"11787103447","pt":1722454135951,"mc":[{"id":"1.231241311","rc":[{"batb":[[0,1.11,10],[1,1.1,10000],[2,1.09,10000]],"ltp":2.36,"tv":140.17,"id":26354922}]}]}
{"op":"mcm","clk":"11787103752","pt":1722454139326,"mc":[{"id":"1.231241311","rc":[{"batb":[[0,1.1,10000],[1,1.09,10000],[2,1.08,10000]],"ltp":2.36,"tv":140.17,"id":26354922}]}]}
{"op":"mcm","clk":"11787119704","pt":1722454309525,"mc":[{"id":"1.231241311","rc":[{"batb":[[0,1.11,10],[1,1.1,10000],[2,1.09,10000]],"ltp":2.36,"tv":140.17,"id":26354922}]}]}
{"op":"mcm","clk":"11787120087","pt":1722454313098,"mc":[{"id":"1.231241311","rc":[{"batb":[[0,1.1,10000],[1,1.09,10000],[2,1.08,10000]],"ltp":2.36,"tv":140.17,"id":26354922}]}]}
{"op":"mcm","clk":"11787153228","pt":1722454628818,"mc":[{"id":"1.231241311","rc":[{"trd":[[1.72,108.63]],"batb":[[0,1.72,15.67]],"ltp":1.72,"tv":218.54,"id":26354926},{"batb":[[0,1.11,10],[1,1.1,10000],[2,1.09,10000]],"ltp":2.36,"tv":140.17,"id":26354922}],"tv":358.71}]}
{"op":"mcm","clk":"11787153501","pt":1722454632012,"mc":[{"id":"1.231241311","rc":[{"batb":[[0,1.1,10000],[1,1.09,10000],[2,1.08,10000]],"ltp":2.36,"tv":140.17,"id":26354922}]}]}
{"op":"mcm","clk":"11787155303","pt":1722454650661,"mc":[{"id":"1.231241311","rc":[{"batb":[[0,1.11,10],[1,1.1,10000],[2,1.09,10000]],"ltp":2.36,"tv":140.17,"id":26354922}]}]}
{"op":"mcm","clk":"11787155668","pt":1722454654247,"mc":[{"id":"1.231241311","rc":[{"batb":[[0,1.1,10000],[1,1.09,10000],[2,1.08,10000]],"ltp":2.36,"tv":140.17,"id":26354922}]}]}
{"op":"mcm","clk":"11787159319","pt":1722454690274,"mc":[{"id":"1.231241311","rc":[{"batb":[[1,1.69,53.57],[2,1.68,112.5]],"ltp":1.72,"tv":218.54,"id":26354926},{"batb":[[0,2.34,10],[1,2.32,28],[2,1.1,10000]],"ltp":2.36,"tv":140.17,"id":26354922}]}]}
{"op":"mcm","clk":"11787159763","pt":1722454693467,"mc":[{"id":"1.231241311","rc":[{"batb":[[0,2.32,28],[1,1.1,10000],[2,1.09,10000]],"ltp":2.36,"tv":140.17,"id":26354922}]}]}
{"op":"mcm","clk":"11787262185","pt":1722455908201,"mc":[{"id":"1.231241311","rc":[{"batb":[[0,2.34,10],[1,2.32,28],[2,1.1,10000]],"ltp":2.36,"tv":140.17,"id":26354922}]}]}
{"op":"mcm","clk":"11787262281","pt":1722455909752,"mc":[{"id":"1.231241311","rc":[{"batb":[[1,1.68,112.5],[2,1.65,111]],"ltp":1.72,"tv":218.54,"id":26354926},{"batb":[[1,1.1,10000],[2,1.09,10000]],"ltp":2.36,"tv":140.17,"id":26354922}]}]}
{"op":"mcm","clk":"11787262397","pt":1722455911777,"mc":[{"id":"1.231241311","rc":[{"batb":[[0,1.1,10000],[1,1.09,10000],[2,1.08,10000]],"ltp":2.36,"tv":140.17,"id":26354922}]}]}
{"op":"mcm","clk":"11787262557","pt":1722455915096,"mc":[{"id":"1.231241311","rc":[{"batb":[[1,1.69,53.57],[2,1.68,112.5]],"ltp":1.72,"tv":218.54,"id":26354926},{"batb":[[0,2.34,10],[1,2.32,28],[2,1.1,10000]],"ltp":2.36,"tv":140.17,"id":26354922}]}]}
{"op":"mcm","clk":"11787262767","pt":1722455918384,"mc":[{"id":"1.231241311","rc":[{"batb":[[0,2.32,28],[1,1.1,10000],[2,1.09,10000]],"ltp":2.36,"tv":140.17,"id":26354922}]}]}
{"op":"mcm","clk":"11787318548","pt":1722456673823,"mc":[{"id":"1.231241311","rc":[{"trd":[[2.4,60.95]],"batb":[[0,2.34,10],[1,2.32,28],[2,1.1,10000]],"ltp":2.36,"tv":140.11,"id":26354922}],"tv":358.65}]}
{"op":"mcm","clk":"11787318767","pt":1722456677042,"mc":[{"id":"1.231241311","rc":[{"batb":[[0,2.32,28],[1,1.1,10000],[2,1.09,10000]],"ltp":2.36,"tv":140.11,"id":26354922}]}]}
{"op":"mcm","clk":"11787320239","pt":1722456700057,"mc":[{"id":"1.231241311","rc":[{"batb":[[0,2.34,10],[1,2.32,28],[2,1.1,10000]],"ltp":2.36,"tv":140.11,"id":26354922}]}]}
{"op":"mcm","clk":"11787320451","pt":1722456703271,"mc":[{"id":"1.231241311","rc":[{"batb":[[1,1.68,112.5],[2,1.65,111]],"ltp":1.72,"tv":218.54,"id":26354926},{"batb":[[1,1.1,10000],[2,1.09,10000]],"ltp":2.36,"tv":140.11,"id":26354922}]}]}
{"op":"mcm","clk":"11787320481","pt":1722456703681,"mc":[{"id":"1.231241311","rc":[{"batb":[[0,1.1,10000],[1,1.09,10000],[2,1.08,10000]],"ltp":2.36,"tv":140.11,"id":26354922}]}]}
{"op":"mcm","clk":"11787320746","pt":1722456708195,"mc":[{"id":"1.231241311","rc":[{"batb":[[1,1.69,53.57],[2,1.68,112.5]],"ltp":1.72,"tv":218.54,"id":26354926},{"batb":[[0,2.32,28],[1,1.1,10000],[2,1.09,10000]],"ltp":2.36,"tv":140.11,"id":26354922}]}]}
{"op":"mcm","clk":"11787320753","pt":1722456708295,"mc":[{"id":"1.231241311","rc":[{"batb":[[0,2.34,10],[1,2.32,28],[2,1.1,10000]],"ltp":2.36,"tv":140.11,"id":26354922}]}]}
{"op":"mcm","clk":"11787320945","pt":1722456711611,"mc":[{"id":"1.231241311","rc":[{"batb":[[0,2.32,28],[1,1.1,10000],[2,1.09,10000]],"ltp":2.36,"tv":140.11,"id":26354922}]}]}
{"op":"mcm","clk":"11787321709","pt":1722456724290,"mc":[{"id":"1.231241311","rc":[{"batb":[[0,2.34,10],[1,2.32,28],[2,1.1,10000]],"ltp":2.36,"tv":140.11,"id":26354922}]}]}
{"op":"mcm","clk":"11787321930","pt":1722456726531,"mc":[{"id":"1.231241311","rc":[{"batb":[[0,2.32,28],[1,1.1,10000],[2,1.09,10000]],"ltp":2.36,"tv":140.11,"id":26354922}]}]}
{"op":"mcm","clk":"11787322386","pt":1722456734345,"mc":[{"id":"1.231241311","rc":[{"batb":[[0,2.34,10],[1,2.32,28],[2,1.1,10000]],"ltp":2.36,"tv":140.11,"id":26354922}]}]}
{"op":"mcm","clk":"11787322612","pt":1722456737994,"mc":[{"id":"1.231241311","rc":[{"batb":[[0,2.32,28],[1,1.1,10000],[2,1.09,10000]],"ltp":2.36,"tv":140.11,"id":26354922}]}]}
{"op":"mcm","clk":"11787333289","pt":1722456780755,"mc":[{"id":"1.231241311","rc":[{"batl":[[0,1.73,300],[1,1.76,45],[2,1.8,22.5]],"ltp":1.72,"tv":218.54,"id":26354926},{"batb":[[0,2.34,10],[1,2.32,28],[2,1.1,10000]],"ltp":2.36,"tv":140.11,"id":26354922}]}]}
{"op":"mcm","clk":"11787333501","pt":1722456783974,"mc":[{"id":"1.231241311","rc":[{"batb":[[1,1.68,112.5],[2,1.65,111]],"ltp":1.72,"tv":218.54,"id":26354926},{"batb":[[0,1.1,10000],[1,1.09,10000],[2,1.08,10000]],"ltp":2.36,"tv":140.11,"id":26354922}]}]}
{"op":"mcm","clk":"11787333829","pt":1722456788597,"mc":[{"id":"1.231241311","rc":[{"batb":[[1,1.69,53.57],[2,1.68,112.5]],"ltp":1.72,"tv":218.54,"id":26354926},{"batb":[[0,2.34,10],[1,2.32,28],[2,1.1,10000]],"ltp":2.36,"tv":140.11,"id":26354922}]}]}
{"op":"mcm","clk":"11787334078","pt":1722456791972,"mc":[{"id":"1.231241311","rc":[{"batb":[[0,2.32,28],[1,1.1,10000],[2,1.09,10000]],"ltp":2.36,"tv":140.11,"id":26354922}]}]}
{"op":"mcm","clk":"11787334736","pt":1722456802415,"mc":[{"id":"1.231241311","rc":[{"trd":[[1.73,600]],"batb":[[0,1.73,118.46],[1,1.72,15.67],[2,1.69,53.57]],"batl":[[0,1.76,45],[1,1.8,22.5],[2,1.86,900]],"ltp":1.73,"tv":818.54,"id":26354926},{"batb":[[0,2.34,10],[1,2.32,28],[2,1.1,10000]],"ltp":2.36,"tv":140.11,"id":26354922}],"tv":958.65}]}
{"op":"mcm","clk":"11787334818","pt":1722456803579,"mc":[{"id":"1.231241311","rc":[{"batb":[[2,1.68,112.5]],"ltp":1.73,"tv":818.54,"id":26354926},{"batb":[[1,1.1,10000],[2,1.09,10000]],"ltp":2.36,"tv":140.11,"id":26354922}]}]}
{"op":"mcm","clk":"11787334973","pt":1722456805585,"mc":[{"id":"1.231241311","rc":[{"batb":[[0,1.1,10000],[1,1.09,10000],[2,1.08,10000]],"ltp":2.36,"tv":140.11,"id":26354922}]}]}
{"op":"mcm","clk":"11787335194","pt":1722456808698,"mc":[{"id":"1.231241311","rc":[{"batb":[[2,1.69,53.57]],"ltp":1.73,"tv":818.54,"id":26354926},{"batb":[[0,2.34,10],[1,2.32,28],[2,1.1,10000]],"ltp":2.36,"tv":140.11,"id":26354922}]}]}
{"op":"mcm","clk":"11787335421","pt":1722456812113,"mc":[{"id":"1.231241311","rc":[{"batb":[[0,2.32,28],[1,1.1,10000],[2,1.09,10000]],"ltp":2.36,"tv":140.11,"id":26354922}]}]}
{"op":"mcm","clk":"11787346270","pt":1722456970984,"mc":[{"id":"1.231241311","rc":[{"trd":[[2.32,2]],"batb":[[0,2.34,10],[1,2.32,27],[2,1.1,10000]],"ltp":2.32,"tv":142.11,"id":26354922}],"tv":960.65}]}
{"op":"mcm","clk":"11787346475","pt":1722456974406,"mc":[{"id":"1.231241311","rc":[{"batb":[[2,1.68,112.5]],"ltp":1.73,"tv":818.54,"id":26354926},{"batb":[[0,1.1,10000],[1,1.09,10000],[2,1.08,10000]],"ltp":2.32,"tv":142.11,"id":26354922}]}]}
{"op":"mcm","clk":"11787346768","pt":1722456979269,"mc":[{"id":"1.231241311","rc":[{"batb":[[2,1.69,53.57]],"ltp":1.73,"tv":818.54,"id":26354926},{"batb":[[0,2.32,28],[1,1.1,10000],[2,1.09,10000]],"ltp":2.32,"tv":142.11,"id":26354922}]}]}
{"op":"mcm","clk":"11787346775","pt":1722456979375,"mc":[{"id":"1.231241311","rc":[{"batb":[[0,2.34,10],[1,2.32,28],[2,1.1,10000]],"ltp":2.32,"tv":142.11,"id":26354922}]}]}
{"op":"mcm","clk":"11787346999","pt":1722456982801,"mc":[{"id":"1.231241311","rc":[{"batb":[[0,2.32,28],[1,1.1,10000],[2,1.09,10000]],"ltp":2.32,"tv":142.11,"id":26354922}]}]}
{"op":"mcm","clk":"11787347764","pt":1722456994215,"mc":[{"id":"1.231241311","rc":[{"trd":[[1.73,720]],"batb":[[0,1.73,58.46]],"ltp":1.73,"tv":938.54,"id":26354926}],"tv":1080.65}]}
{"op":"mcm","clk":"11787347775","pt":1722456994423,"mc":[{"id":"1.231241311","rc":[{"batb":[[0,2.34,10],[1,2.32,28],[2,1.1,10000]],"ltp":2.32,"tv":142.11,"id":26354922}]}]}
{"op":"mcm","clk":"11787347969","pt":1722456997733,"mc":[{"id":"1.231241311","rc":[{"batb":[[0,2.32,28],[1,1.1,10000],[2,1.09,10000]],"ltp":2.32,"tv":142.11,"id":26354922}]}]}
{"op":"mcm","clk":"11787349426","pt":1722457021821,"mc":[{"id":"1.231241311","rc":[{"batb":[[0,2.34,10],[1,2.32,28],[2,1.1,10000]],"ltp":2.32,"tv":142.11,"id":26354922}]}]}
{"op":"mcm","clk":"11787349626","pt":1722457025141,"mc":[{"id":"1.231241311","rc":[{"batb":[[2,1.68,112.5]],"ltp":1.73,"tv":938.54,"id":26354926},{"batb":[[0,1.1,10000],[1,1.09,10000],[2,1.08,10000]],"ltp":2.32,"tv":142.11,"id":26354922}]}]}
{"op":"mcm","clk":"11787349912","pt":1722457029564,"mc":[{"id":"1.231241311","rc":[{"batb":[[2,1.69,53.57]],"ltp":1.73,"tv":938.54,"id":26354926},{"batb":[[0,2.34,10],[1,2.32,28],[2,1.1,10000]],"ltp":2.32,"tv":142.11,"id":26354922}]}]}
{"op":"mcm","clk":"11787350132","pt":1722457032877,"mc":[{"id":"1.231241311","rc":[{"batb":[[0,2.32,28],[1,1.1,10000],[2,1.09,10000]],"ltp":2.32,"tv":142.11,"id":26354922}]}]}
{"op":"mcm","clk":"11787351386","pt":1722457054108,"mc":[{"id":"1.231241311","rc":[{"batb":[[0,2.34,10],[1,2.32,28],[2,1.1,10000]],"ltp":2.32,"tv":142.11,"id":26354922}]}]}
{"op":"mcm","clk":"11787351418","pt":1722457054573,"mc":[{"id":"1.231241311","rc":[{"batb":[[2,1.68,112.5]],"ltp":1.73,"tv":938.54,"id":26354926},{"batb":[[1,1.1,10000],[2,1.09,10000]],"ltp":2.32,"tv":142.11,"id":26354922}]}]}
{"op":"mcm","clk":"11787351554","pt":1722457057513,"mc":[{"id":"1.231241311","rc":[{"batb":[[0,1.1,10000],[1,1.09,10000],[2,1.08,10000]],"ltp":2.32,"tv":142.11,"id":26354922}]}]}
{"op":"mcm","clk":"11787351685","pt":1722457059483,"mc":[{"id":"1.231241311","rc":[{"batb":[[2,1.69,53.57]],"ltp":1.73,"tv":938.54,"id":26354926},{"batb":[[0,2.32,28],[1,1.1,10000],[2,1.09,10000]],"ltp":2.32,"tv":142.11,"id":26354922}]}]}
{"op":"mcm","clk":"11787356013","pt":1722457132089,"mc":[{"id":"1.231241311","rc":[{"batb":[[0,2.34,10],[1,2.32,28],[2,1.1,10000]],"ltp":2.32,"tv":142.11,"id":26354922}]}]}
{"op":"mcm","clk":"11787356191","pt":1722457134898,"mc":[{"id":"1.231241311","rc":[{"batb":[[2,1.68,112.5]],"ltp":1.73,"tv":938.54,"id":26354926},{"batb":[[1,1.1,10000],[2,1.09,10000]],"ltp":2.32,"tv":142.11,"id":26354922}]}]}
{"op":"mcm","clk":"11787356239","pt":1722457135675,"mc":[{"id":"1.231241311","rc":[{"batb":[[0,1.1,10000],[1,1.09,10000],[2,1.08,10000]],"ltp":2.32,"tv":142.11,"id":26354922}]}]}
{"op":"mcm","clk":"11787356483","pt":1722457139896,"mc":[{"id":"1.231241311","rc":[{"batb":[[2,1.69,53.57]],"ltp":1.73,"tv":938.54,"id":26354926},{"batb":[[0,2.34,10],[1,2.32,28],[2,1.1,10000]],"ltp":2.32,"tv":142.11,"id":26354922}]}]}
{"op":"mcm","clk":"11787356694","pt":1722457143177,"mc":[{"id":"1.231241311","rc":[{"batb":[[0,2.32,28],[1,1.1,10000],[2,1.09,10000]],"ltp":2.32,"tv":142.11,"id":26354922}]}]}
{"op":"mcm","clk":"11787358425","pt":1722457172125,"mc":[{"id":"1.231241311","rc":[{"batb":[[0,2.34,10],[1,2.32,28],[2,1.1,10000]],"ltp":2.32,"tv":142.11,"id":26354922}]}]}
{"op":"mcm","clk":"11787358591","pt":1722457175028,"mc":[{"id":"1.231241311","rc":[{"batb":[[2,1.68,112.5]],"ltp":1.73,"tv":938.54,"id":26354926},{"batb":[[1,1.1,10000],[2,1.09,10000]],"ltp":2.32,"tv":142.11,"id":26354922}]}]}
{"op":"mcm","clk":"11787358612","pt":1722457175443,"mc":[{"id":"1.231241311","rc":[{"batb":[[0,1.1,10000],[1,1.09,10000],[2,1.08,10000]],"ltp":2.32,"tv":142.11,"id":26354922}]}]}
{"op":"mcm","clk":"11787358859","pt":1722457180164,"mc":[{"id":"1.231241311","rc":[{"batb":[[2,1.69,53.57]],"ltp":1.73,"tv":938.54,"id":26354926},{"batb":[[0,2.34,10],[1,2.32,28],[2,1.1,10000]],"ltp":2.32,"tv":142.11,"id":26354922}]}]}
{"op":"mcm","clk":"11787359009","pt":1722457183437,"mc":[{"id":"1.231241311","rc":[{"batb":[[0,2.32,28],[1,1.1,10000],[2,1.09,10000]],"ltp":2.32,"tv":142.11,"id":26354922}]}]}
{"op":"mcm","clk":"11787359609","pt":1722457195481,"mc":[{"id":"1.231241311","rc":[{"batb":[[0,2.34,10],[1,2.32,28],[2,1.1,10000]],"ltp":2.32,"tv":142.11,"id":26354922}]}]}
{"op":"mcm","clk":"11787359819","pt":1722457198952,"mc":[{"id":"1.231241311","rc":[{"batb":[[0,2.32,28],[1,1.1,10000],[2,1.09,10000]],"ltp":2.32,"tv":142.11,"id":26354922}]}]}
{"op":"mcm","clk":"11787364437","pt":1722457285325,"mc":[{"id":"1.231241311","rc":[{"batl":[[0,2.36,90.16],[1,6,1.56],[2,12,1.56]],"ltp":2.32,"tv":142.11,"id":26354922}]}]}
{"op":"mcm","clk":"11787364895","pt":1722457293541,"mc":[{"id":"1.231241311","rc":[{"batb":[[0,1.74,8.91],[1,1.73,58.46],[2,1.72,15.67]],"ltp":1.73,"tv":938.54,"id":26354926}]}]}
{"op":"mcm","clk":"11787367102","pt":1722457329805,"mc":[{"id":"1.231241311","rc":[{"batb":[[0,2.34,10],[1,2.32,28],[2,1.1,10000]],"batl":[[0,6,1.56],[1,12,1.56],[2,12,0]],"ltp":2.32,"tv":142.11,"id":26354922}]}]}
{"op":"mcm","clk":"11787367149","pt":1722457330582,"mc":[{"id":"1.231241311","rc":[{"batb":[[1,1.1,10000],[2,1.09,10000]],"ltp":2.32,"tv":142.11,"id":26354922}]}]}
{"op":"mcm","clk":"11787367213","pt":1722457331307,"mc":[{"id":"1.231241311","rc":[{"batb":[[0,1.73,58.46],[1,1.72,15.67],[2,1.68,112.5]],"ltp":1.73,"tv":938.54,"id":26354926}]}]}
{"op":"mcm","clk":"11787367322","pt":1722457333115,"mc":[{"id":"1.231241311","rc":[{"batb":[[0,1.1,10000],[1,1.09,10000],[2,1.08,10000]],"ltp":2.32,"tv":142.11,"id":26354922}]}]}
{"op":"mcm","clk":"11787367510","pt":1722457335827,"mc":[{"id":"1.231241311","rc":[{"batb":[[2,1.69,53.57]],"ltp":1.73,"tv":938.54,"id":26354926},{"batb":[[0,2.34,10],[1,2.32,28],[2,1.1,10000]],"ltp":2.32,"tv":142.11,"id":26354922}]}]}
{"op":"mcm","clk":"11787367764","pt":1722457339099,"mc":[{"id":"1.231241311","rc":[{"batb":[[0,2.32,28],[1,1.1,10000],[2,1.09,10000]],"ltp":2.32,"tv":142.11,"id":26354922}]}]}
{"op":"mcm","clk":"11787369814","pt":1722457367967,"mc":[{"id":"1.231241311","rc":[{"batl":[[0,2.34,2],[1,6,1.56],[2,12,1.56]],"ltp":2.32,"tv":142.11,"id":26354922}]}]}
{"op":"mcm","clk":"11787381243","pt":1722457548649,"mc":[{"id":"1.231241311","rc":[{"trd":[[2.32,58]],"batb":[[0,1.11,10]],"batl":[[0,2.32,44.13],[1,2.34,2],[2,6,1.56]],"ltp":2.32,"tv":198.11,"id":26354922}],"tv":1136.65}]}
{"op":"mcm","clk":"11787381409","pt":1722457551245,"mc":[{"id":"1.231241311","rc":[{"batb":[[0,2.24,29.8],[1,1.11,10],[2,1.1,10000]],"ltp":2.32,"tv":198.11,"id":26354922}]}]}
{"op":"mcm","clk":"11787381447","pt":1722457551969,"mc":[{"id":"1.231241311","rc":[{"batb":[[1,1.1,10000],[2,1.09,10000]],"ltp":2.32,"tv":198.11,"id":26354922}]}]}
{"op":"mcm","clk":"11787394903","pt":1722457808428,"mc":[{"id":"1.231241311","rc":[{"trd":[[1.75,6]],"ltp":1.75,"tv":944.54,"id":26354926},{"trd":[[2.32,62.53]],"batl":[[0,2.32,39.6]],"ltp":2.32,"tv":202.64,"id":26354922}],"tv":1147.18}]}
{"op":"mcm","clk":"11787406802","pt":1722458005966,"mc":[{"id":"1.231241311","rc":[{"batb":[[0,2.26,10],[1,2.24,29.8],[2,1.1,10000]],"batl":[[0,2.34,2],[1,6,1.56],[2,12,1.56]],"ltp":2.32,"tv":202.64,"id":26354922}]}]}
{"op":"mcm","clk":"11787406835","pt":1722458006484,"mc":[{"id":"1.231241311","rc":[{"batb":[[0,1.74,4.59],[1,1.73,58.46],[2,1.72,15.67]],"ltp":1.75,"tv":944.54,"id":26354926}]}]}
{"op":"mcm","clk":"11787406994","pt":1722458009388,"mc":[{"id":"1.231241311","rc":[{"batb":[[0,2.24,29.8],[1,1.1,10000],[2,1.09,10000]],"ltp":2.32,"tv":202.64,"id":26354922}]}]}
{"op":"mcm","clk":"11787409441","pt":1722458052614,"mc":[{"id":"1.231241311","rc":[{"batb":[[0,2.26,10],[1,2.24,29.8],[2,1.1,10000]],"ltp":2.32,"tv":202.64,"id":26354922}]}]}
{"op":"mcm","clk":"11787409730","pt":1722458057415,"mc":[{"id":"1.231241311","rc":[{"batb":[[0,2.24,29.8],[1,1.1,10000],[2,1.09,10000]],"ltp":2.32,"tv":202.64,"id":26354922}]}]}
{"op":"mcm","clk":"11787410462","pt":1722458070553,"mc":[{"id":"1.231241311","rc":[{"batl":[[0,2.32,39.58],[1,2.34,2],[2,6,1.56]],"ltp":2.32,"tv":202.64,"id":26354922}]}]}
{"op":"mcm","clk":"11787410551","pt":1722458072253,"mc":[{"id":"1.231241311","rc":[{"batb":[[0,1.73,58.46],[1,1.72,15.67],[2,1.69,53.57]],"ltp":1.75,"tv":944.54,"id":26354926}]}]}
{"op":"mcm","clk":"11787411536","pt":1722458089061,"mc":[{"id":"1.231241311","rc":[{"batb":[[0,2.26,10],[1,2.24,29.8],[2,1.1,10000]],"batl":[[0,2.34,2],[1,6,1.56],[2,12,1.56]],"ltp":2.32,"tv":202.64,"id":26354922}]}]}
{"op":"mcm","clk":"11787411592","pt":1722458089838,"mc":[{"id":"1.231241311","rc":[{"batb":[[0,1.74,4.59],[1,1.73,58.46],[2,1.72,15.67]],"ltp":1.75,"tv":944.54,"id":26354926}]}]}
{"op":"mcm","clk":"11787411742","pt":1722458092174,"mc":[{"id":"1.231241311","rc":[{"batb":[[0,2.24,29.8],[1,1.1,10000],[2,1.09,10000]],"ltp":2.32,"tv":202.64,"id":26354922}]}]}
{"op":"mcm","clk":"11787416356","pt":1722458175633,"mc":[{"id":"1.231241311","rc":[{"batb":[[0,2.26,10],[1,2.24,29.8],[2,1.1,10000]],"ltp":2.32,"tv":202.64,"id":26354922}]}]}
{"op":"mcm","clk":"11787416540","pt":1722458178944,"mc":[{"id":"1.231241311","rc":[{"batb":[[0,2.24,29.8],[1,1.1,10000],[2,1.09,10000]],"ltp":2.32,"tv":202.64,"id":26354922}]}]}
{"op":"mcm","clk":"11787418728","pt":1722458221713,"mc":[{"id":"1.231241311","rc":[{"batb":[[0,2.26,10],[1,2.24,29.8],[2,1.1,10000]],"ltp":2.32,"tv":202.64,"id":26354922}]}]}
{"op":"mcm","clk":"11787418953","pt":1722458225202,"mc":[{"id":"1.231241311","rc":[{"batb":[[0,2.24,29.8],[1,1.1,10000],[2,1.09,10000]],"ltp":2.32,"tv":202.64,"id":26354922}]}]}
{"op":"mcm","clk":"11787419102","pt":1722458227637,"mc":[{"id":"1.231241311","rc":[{"batb":[[0,2.26,10],[1,2.24,29.8],[2,1.1,10000]],"ltp":2.32,"tv":202.64,"id":26354922}]}]}
{"op":"mcm","clk":"11787419308","pt":1722458231049,"mc":[{"id":"1.231241311","rc":[{"batb":[[0,2.24,29.8],[1,1.1,10000],[2,1.09,10000]],"ltp":2.32,"tv":202.64,"id":26354922}]}]}
{"op":"mcm","clk":"11787419873","pt":1722458239928,"mc":[{"id":"1.231241311","rc":[{"batb":[[0,2.26,10],[1,2.24,29.8],[2,1.1,10000]],"ltp":2.32,"tv":202.64,"id":26354922}]}]}
{"op":"mcm","clk":"11787420084","pt":1722458243230,"mc":[{"id":"1.231241311","rc":[{"batb":[[0,2.24,29.8],[1,1.1,10000],[2,1.09,10000]],"ltp":2.32,"tv":202.64,"id":26354922}]}]}
{"op":"mcm","clk":"11787422451","pt":1722458281483,"mc":[{"id":"1.231241311","rc":[{"batb":[[0,2.26,10],[1,2.24,29.8],[2,1.1,10000]],"ltp":2.32,"tv":202.64,"id":26354922}]}]}
{"op":"mcm","clk":"11787422682","pt":1722458285093,"mc":[{"id":"1.231241311","rc":[{"batb":[[0,2.24,29.8],[1,1.1,10000],[2,1.09,10000]],"ltp":2.32,"tv":202.64,"id":26354922}]}]}
{"op":"mcm","clk":"11787424027","pt":1722458308109,"mc":[{"id":"1.231241311","rc":[{"batb":[[0,2.26,10],[1,2.24,29.8],[2,1.1,10000]],"ltp":2.32,"tv":202.64,"id":26354922}]}]}
{"op":"mcm","clk":"11787424226","pt":1722458311518,"mc":[{"id":"1.231241311","rc":[{"batb":[[0,2.24,29.8],[1,1.1,10000],[2,1.09,10000]],"ltp":2.32,"tv":202.64,"id":26354922}]}]}
{"op":"mcm","clk":"11787424314","pt":1722458312919,"mc":[{"id":"1.231241311","rc":[{"batb":[[0,1.75,54.1],[1,1.74,4.59],[2,1.73,58.46]],"ltp":1.75,"tv":944.54,"id":26354926}]}]}
{"op":"mcm","clk":"11787424434","pt":1722458315232,"mc":[{"id":"1.231241311","rc":[{"batb":[[1,1.73,58.46],[2,1.72,15.67]],"ltp":1.75,"tv":944.54,"id":26354926},{"batb":[[0,2.26,10],[1,2.24,29.8],[2,1.1,10000]],"ltp":2.32,"tv":202.64,"id":26354922}]}]}
{"op":"mcm","clk":"11787424647","pt":1722458318527,"mc":[{"id":"1.231241311","rc":[{"batb":[[0,2.24,29.8],[1,1.1,10000],[2,1.09,10000]],"ltp":2.32,"tv":202.64,"id":26354922}]}]}
{"op":"mcm","clk":"11787425084","pt":1722458326321,"mc":[{"id":"1.231241311","rc":[{"batb":[[0,2.26,10],[1,2.24,29.8],[2,1.1,10000]],"ltp":2.32,"tv":202.64,"id":26354922}]}]}
{"op":"mcm","clk":"11787425290","pt":1722458329820,"mc":[{"id":"1.231241311","rc":[{"batb":[[0,2.24,29.8],[1,1.1,10000],[2,1.09,10000]],"ltp":2.32,"tv":202.64,"id":26354922}]}]}
{"op":"mcm","clk":"11787425333","pt":1722458330641,"mc":[{"id":"1.231241311","rc":[{"batl":[[0,2.32,9.02],[1,2.34,2],[2,6,1.56]],"ltp":2.32,"tv":202.64,"id":26354922}]}]}
{"op":"mcm","clk":"11787427491","pt":1722458366191,"mc":[{"id":"1.231241311","rc":[{"batb":[[0,1.73,58.46],[1,1.72,15.67],[2,1.69,53.57]],"ltp":1.75,"tv":944.54,"id":26354926},{"batb":[[0,2.26,10],[1,2.24,29.8],[2,1.1,10000]],"batl":[[0,2.34,2],[1,6,1.56],[2,12,1.56]],"ltp":2.32,"tv":202.64,"id":26354922}]}]}
{"op":"mcm","clk":"11787427534","pt":1722458366969,"mc":[{"id":"1.231241311","rc":[{"batb":[[0,1.74,4.59],[1,1.73,58.46],[2,1.72,15.67]],"ltp":1.75,"tv":944.54,"id":26354926}]}]}
{"op":"mcm","clk":"11787427690","pt":1722458369389,"mc":[{"id":"1.231241311","rc":[{"batb":[[0,2.24,29.8],[1,1.1,10000],[2,1.09,10000]],"ltp":2.32,"tv":202.64,"id":26354922}]}]}
{"op":"mcm","clk":"11787427889","pt":1722458372897,"mc":[{"id":"1.231241311","rc":[{"batb":[[0,2.26,10],[1,2.24,29.8],[2,1.1,10000]],"ltp":2.32,"tv":202.64,"id":26354922}]}]}
{"op":"mcm","clk":"11787428078","pt":1722458376405,"mc":[{"id":"1.231241311","rc":[{"batb":[[0,2.24,29.8],[1,1.1,10000],[2,1.09,10000]],"ltp":2.32,"tv":202.64,"id":26354922}]}]}
{"op":"mcm","clk":"11787429495","pt":1722458402627,"mc":[{"id":"1.231241311","rc":[{"batb":[[0,2.26,10],[1,2.24,29.8],[2,1.1,10000]],"ltp":2.32,"tv":202.64,"id":26354922}]}]}
{"op":"mcm","clk":"11787429707","pt":1722458406030,"mc":[{"id":"1.231241311","rc":[{"batb":[[0,2.24,29.8],[1,1.1,10000],[2,1.09,10000]],"ltp":2.32,"tv":202.64,"id":26354922}]}]}
{"op":"mcm","clk":"11787429953","pt":1722458410058,"mc":[{"id":"1.231241311","rc":[{"batb":[[0,2.26,10],[1,2.24,29.8],[2,1.1,10000]],"ltp":2.32,"tv":202.64,"id":26354922}]}]}
{"op":"mcm","clk":"11787430172","pt":1722458413406,"mc":[{"id":"1.231241311","rc":[{"batb":[[0,2.24,29.8],[1,1.1,10000],[2,1.09,10000]],"ltp":2.32,"tv":202.64,"id":26354922}]}]}
{"op":"mcm","clk":"11787430943","pt":1722458425228,"mc":[{"id":"1.231241311","rc":[{"batl":[[1,1.8,112.5]],"ltp":1.75,"tv":944.54,"id":26354926}]}]}
{"op":"mcm","clk":"11787430947","pt":1722458425329,"mc":[{"id":"1.231241311","rc":[{"batb":[[0,2.26,10],[1,2.24,29.8],[2,1.1,10000]],"ltp":2.32,"tv":202.64,"id":26354922}]}]}
{"op":"mcm","clk":"11787431158","pt":1722458428741,"mc":[{"id":"1.231241311","rc":[{"batb":[[0,2.24,29.8],[1,1.1,10000],[2,1.09,10000]],"ltp":2.32,"tv":202.64,"id":26354922}]}]}
{"op":"mcm","clk":"11787431554","pt":1722458434828,"mc":[{"id":"1.231241311","rc":[{"batb":[[0,2.26,10],[1,2.24,29.8],[2,1.1,10000]],"ltp":2.32,"tv":202.64,"id":26354922}]}]}
{"op":"mcm","clk":"11787431792","pt":1722458438048,"mc":[{"id":"1.231241311","rc":[{"batb":[[0,2.24,29.8],[1,1.1,10000],[2,1.09,10000]],"ltp":2.32,"tv":202.64,"id":26354922}]}]}
{"op":"mcm","clk":"11787431946","pt":1722458440875,"mc":[{"id":"1.231241311","rc":[{"trd":[[1.76,28.28]],"batl":[[0,1.76,16.72]],"ltp":1.76,"tv":972.81,"id":26354926},{"trd":[[2.3,21.64]],"batb":[[0,2.26,10],[1,2.24,29.8],[2,1.1,10000]],"ltp":2.3,"tv":224.28,"id":26354922}],"tv":1197.1}]}
{"op":"mcm","clk":"11787432126","pt":1722458444077,"mc":[{"id":"1.231241311","rc":[{"batb":[[0,2.24,29.8],[1,1.1,10000],[2,1.09,10000]],"ltp":2.3,"tv":224.28,"id":26354922}]}]}
{"op":"mcm","clk":"11787432252","pt":1722458446454,"mc":[{"id":"1.231241311","rc":[{"batb":[[0,2.26,10],[1,2.24,29.8],[2,1.1,10000]],"ltp":2.3,"tv":224.28,"id":26354922}]}]}
{"op":"mcm","clk":"11787432474","pt":1722458450066,"mc":[{"id":"1.231241311","rc":[{"batb":[[0,2.24,29.8],[1,1.1,10000],[2,1.09,10000]],"ltp":2.3,"tv":224.28,"id":26354922}]}]}
{"op":"mcm","clk":"11787433379","pt":1722458465279,"mc":[{"id":"1.231241311","rc":[{"batb":[[1,2.12,54.28],[2,1.1,10000]],"ltp":2.3,"tv":224.28,"id":26354922}]}]}
{"op":"mcm","clk":"11787433391","pt":1722458465379,"mc":[{"id":"1.231241311","rc":[{"batb":[[0,2.26,10],[1,2.24,29.8],[2,2.12,54.28]],"ltp":2.3,"tv":224.28,"id":26354922}]}]}
{"op":"mcm","clk":"11787433623","pt":1722458468690,"mc":[{"id":"1.231241311","rc":[{"batb":[[0,2.24,29.8],[1,2.12,54.28],[2,1.1,10000]],"ltp":2.3,"tv":224.28,"id":26354922}]}]}
{"op":"mcm","clk":"11787433662","pt":1722458469312,"mc":[{"id":"1.231241311","rc":[{"batl":[[1,1.8,912.5]],"ltp":1.76,"tv":972.81,"id":26354926}]}]}
{"op":"mcm","clk":"11787434153","pt":1722458476295,"mc":[{"id":"1.231241311","rc":[{"batb":[[0,2.26,10],[1,2.24,29.8],[2,2.12,54.28]],"ltp":2.3,"tv":224.28,"id":26354922}]}]}
{"op":"mcm","clk":"11787434377","pt":1722458479808,"mc":[{"id":"1.231241311","rc":[{"batb":[[0,2.24,29.8],[1,2.12,54.28],[2,1.1,10000]],"ltp":2.3,"tv":224.28,"id":26354922}]}]}
{"op":"mcm","clk":"11787434754","pt":1722458486107,"mc":[{"id":"1.231241311","rc":[{"batb":[[0,2.26,10],[1,2.24,29.8],[2,2.12,54.28]],"ltp":2.3,"tv":224.28,"id":26354922}]}]}
{"op":"mcm","clk":"11787434936","pt":1722458489613,"mc":[{"id":"1.231241311","rc":[{"batb":[[0,2.24,29.8],[1,2.12,54.28],[2,1.1,10000]],"ltp":2.3,"tv":224.28,"id":26354922}]}]}
{"op":"mcm","clk":"11787435368","pt":1722458496540,"mc":[{"id":"1.231241311","rc":[{"batb":[[0,2.26,10],[1,2.24,29.8],[2,2.12,54.28]],"ltp":2.3,"tv":224.28,"id":26354922}]}]}
{"op":"mcm","clk":"11787435612","pt":1722458499912,"mc":[{"id":"1.231241311","rc":[{"batb":[[0,2.24,29.8],[1,2.12,54.28],[2,1.1,10000]],"ltp":2.3,"tv":224.28,"id":26354922}]}]}
{"op":"mcm","clk":"11787455298","pt":1722458829489,"mc":[{"id":"1.231241311","rc":[{"trd":[[1.74,72.38]],"batb":[[0,1.73,59.05],[1,1.72,15.67],[2,1.69,53.57]],"ltp":1.74,"tv":980.81,"id":26354926},{"batb":[[0,2.26,10],[1,2.24,29.8],[2,2.12,54.28]],"ltp":2.3,"tv":224.28,"id":26354922}],"tv":1205.1}]}
{"op":"mcm","clk":"11787455431","pt":1722458832996,"mc":[{"id":"1.231241311","rc":[{"batb":[[0,2.24,29.8],[1,2.12,54.28],[2,1.1,10000]],"ltp":2.3,"tv":224.28,"id":26354922}]}]}
{"op":"mcm","clk":"11787458542","pt":1722458920878,"mc":[{"id":"1.231241311","rc":[{"batb":[[0,1.74,100.59],[1,1.73,58.46],[2,1.72,15.67]],"ltp":1.74,"tv":980.81,"id":26354926},{"batb":[[0,2.26,10],[1,2.24,29.8],[2,2.12,54.28]],"ltp":2.3,"tv":224.28,"id":26354922}]}]}
{"op":"mcm","clk":"11787458644","pt":1722458924318,"mc":[{"id":"1.231241311","rc":[{"batb":[[0,2.24,29.8],[1,2.12,54.28],[2,1.1,10000]],"ltp":2.3,"tv":224.28,"id":26354922}]}]}
{"op":"mcm","clk":"11787459519","pt":1722458948733,"mc":[{"id":"1.231241311","rc":[{"batb":[[0,1.73,59.05],[1,1.72,15.67],[2,1.69,53.57]],"ltp":1.74,"tv":980.81,"id":26354926},{"batb":[[0,2.26,10],[1,2.24,29.8],[2,2.12,54.28]],"ltp":2.3,"tv":224.28,"id":26354922}]}]}
{"op":"mcm","clk":"11787459642","pt":1722458952226,"mc":[{"id":"1.231241311","rc":[{"batb":[[0,2.24,29.8],[1,2.12,54.28],[2,1.1,10000]],"ltp":2.3,"tv":224.28,"id":26354922}]}]}
{"op":"mcm","clk":"11787460057","pt":1722458962865,"mc":[{"id":"1.231241311","rc":[{"batb":[[0,1.74,200.59],[1,1.73,58.46],[2,1.72,15.67]],"ltp":1.74,"tv":980.81,"id":26354926},{"batb":[[0,2.26,10],[1,2.24,29.8],[2,2.12,54.28]],"ltp":2.3,"tv":224.28,"id":26354922}]}]}
{"op":"mcm","clk":"11787460190","pt":1722458966161,"mc":[{"id":"1.231241311","rc":[{"batb":[[0,2.24,29.8],[1,2.12,54.28],[2,1.1,10000]],"ltp":2.3,"tv":224.28,"id":26354922}]}]}
{"op":"mcm","clk":"11787464812","pt":1722459071349,"mc":[{"id":"1.231241311","rc":[{"batb":[[0,2.26,10],[1,2.24,29.8],[2,2.12,54.28]],"ltp":2.3,"tv":224.28,"id":26354922}]}]}
{"op":"mcm","clk":"11787464947","pt":1722459074946,"mc":[{"id":"1.231241311","rc":[{"batb":[[0,2.24,29.8],[1,2.12,54.28],[2,1.1,10000]],"ltp":2.3,"tv":224.28,"id":26354922}]}]}
{"op":"mcm","clk":"11787465736","pt":1722459094699,"mc":[{"id":"1.231241311","rc":[{"batb":[[0,2.26,10],[1,2.24,29.8],[2,2.12,54.28]],"ltp":2.3,"tv":224.28,"id":26354922}]}]}
{"op":"mcm","clk":"11787465867","pt":1722459098299,"mc":[{"id":"1.231241311","rc":[{"batb":[[0,2.24,29.8],[1,2.12,54.28],[2,1.1,10000]],"ltp":2.3,"tv":224.28,"id":26354922}]}]}
{"op":"mcm","clk":"11787465980","pt":1722459101586,"mc":[{"id":"1.231241311","rc":[{"batb":[[0,2.26,10],[1,2.24,29.8],[2,2.12,54.28]],"ltp":2.3,"tv":224.28,"id":26354922}]}]}
{"op":"mcm","clk":"11787466135","pt":1722459105079,"mc":[{"id":"1.231241311","rc":[{"batb":[[0,2.24,29.8],[1,2.12,54.28],[2,1.1,10000]],"ltp":2.3,"tv":224.28,"id":26354922}]}]}
{"op":"mcm","clk":"11787466241","pt":1722459107906,"mc":[{"id":"1.231241311","rc":[{"batb":[[0,2.26,10],[1,2.24,29.8],[2,2.12,54.28]],"ltp":2.3,"tv":224.28,"id":26354922}]}]}
{"op":"mcm","clk":"11787466365","pt":1722459111400,"mc":[{"id":"1.231241311","rc":[{"batb":[[0,2.24,29.8],[1,2.12,54.28],[2,1.1,10000]],"ltp":2.3,"tv":224.28,"id":26354922}]}]}
{"op":"mcm","clk":"11787466651","pt":1722459118382,"mc":[{"id":"1.231241311","rc":[{"batb":[[0,2.26,10],[1,2.24,29.8],[2,2.12,54.28]],"ltp":2.3,"tv":224.28,"id":26354922}]}]}
{"op":"mcm","clk":"11787466784","pt":1722459121818,"mc":[{"id":"1.231241311","rc":[{"batb":[[0,2.24,29.8],[1,2.12,54.28],[2,1.1,10000]],"ltp":2.3,"tv":224.28,"id":26354922}]}]}
{"op":"mcm","clk":"11787466890","pt":1722459124230,"mc":[{"id":"1.231241311","rc":[{"batb":[[0,2.26,10],[1,2.24,29.8],[2,2.12,54.28]],"ltp":2.3,"tv":224.28,"id":26354922}]}]}
{"op":"mcm","clk":"11787467022","pt":1722459127621,"mc":[{"id":"1.231241311","rc":[{"batb":[[0,2.24,29.8],[1,2.12,54.28],[2,1.1,10000]],"ltp":2.3,"tv":224.28,"id":26354922}]}]}
{"op":"mcm","clk":"11787467179","pt":1722459131526,"mc":[{"id":"1.231241311","rc":[{"batb":[[0,2.26,10],[1,2.24,29.8],[2,2.12,54.28]],"ltp":2.3,"tv":224.28,"id":26354922}]}]}
{"op":"mcm","clk":"11787467362","pt":1722459135998,"mc":[{"id":"1.231241311","rc":[{"batb":[[0,2.24,29.8],[1,2.12,54.28],[2,1.1,10000]],"ltp":2.3,"tv":224.28,"id":26354922}]}]}
{"op":"mcm","clk":"11787467562","pt":1722459141332,"mc":[{"id":"1.231241311","rc":[{"batb":[[0,2.26,10],[1,2.24,29.8],[2,2.12,54.28]],"ltp":2.3,"tv":224.28,"id":26354922}]}]}
{"op":"mcm","clk":"11787467712","pt":1722459144729,"mc":[{"id":"1.231241311","rc":[{"batb":[[0,2.24,29.8],[1,2.12,54.28],[2,1.1,10000]],"ltp":2.3,"tv":224.28,"id":26354922}]}]}
{"op":"mcm","clk":"11787468834","pt":1722459172471,"mc":[{"id":"1.231241311","rc":[{"batb":[[0,1.75,9.98],[1,1.74,200.59],[2,1.73,58.46]],"ltp":1.74,"tv":980.81,"id":26354926},{"batb":[[0,2.26,10],[1,2.24,29.8],[2,2.12,54.28]],"ltp":2.3,"tv":224.28,"id":26354922}]}]}
{"op":"mcm","clk":"11787468934","pt":1722459175759,"mc":[{"id":"1.231241311","rc":[{"batb":[[0,2.24,29.8],[1,2.12,54.28],[2,1.1,10000]],"ltp":2.3,"tv":224.28,"id":26354922}]}]}
{"op":"mcm","clk":"11787469052","pt":1722459178174,"mc":[{"id":"1.231241311","rc":[{"batb":[[0,2.26,10],[1,2.24,29.8],[2,2.12,54.28]],"ltp":2.3,"tv":224.28,"id":26354922}]}]}
{"op":"mcm","clk":"11787469194","pt":1722459181764,"mc":[{"id":"1.231241311","rc":[{"batb":[[0,2.24,29.8],[1,2.12,54.28],[2,1.1,10000]],"ltp":2.3,"tv":224.28,"id":26354922}]}]}
{"op":"mcm","clk":"11787469506","pt":1722459190082,"mc":[{"id":"1.231241311","rc":[{"batb":[[0,2.26,10],[1,2.24,29.8],[2,2.12,54.28]],"ltp":2.3,"tv":224.28,"id":26354922}]}]}
{"op":"mcm","clk":"11787469638","pt":1722459193582,"mc":[{"id":"1.231241311","rc":[{"batb":[[0,2.24,29.8],[1,2.12,54.28],[2,1.1,10000]],"batl":[[0,2.34,14.06]],"ltp":2.3,"tv":224.28,"id":26354922}]}]}
{"op":"mcm","clk":"11787469760","pt":1722459196973,"mc":[{"id":"1.231241311","rc":[{"batb":[[0,2.26,10],[1,2.24,29.8],[2,2.12,54.28]],"ltp":2.3,"tv":224.28,"id":26354922}]}]}
{"op":"mcm","clk":"11787469861","pt":1722459200279,"mc":[{"id":"1.231241311","rc":[{"batb":[[0,2.24,29.8],[1,2.12,54.28],[2,1.1,10000]],"ltp":2.3,"tv":224.28,"id":26354922}]}]}
{"op":"mcm","clk":"11787470342","pt":1722459214183,"mc":[{"id":"1.231241311","rc":[{"batb":[[0,2.26,10],[1,2.24,29.8],[2,2.12,54.28]],"ltp":2.3,"tv":224.28,"id":26354922}]}]}
{"op":"mcm","clk":"11787470470","pt":1722459217822,"mc":[{"id":"1.231241311","rc":[{"batb":[[0,2.24,29.8],[1,2.12,54.28],[2,1.1,10000]],"ltp":2.3,"tv":224.28,"id":26354922}]}]}
{"op":"mcm","clk":"11787470616","pt":1722459221519,"mc":[{"id":"1.231241311","rc":[{"batb":[[0,2.26,10],[1,2.24,29.8],[2,2.12,54.28]],"ltp":2.3,"tv":224.28,"id":26354922}]}]}
{"op":"mcm","clk":"11787470750","pt":1722459224910,"mc":[{"id":"1.231241311","rc":[{"batb":[[0,2.24,29.8],[1,2.12,54.28],[2,1.1,10000]],"ltp":2.3,"tv":224.28,"id":26354922}]}]}
{"op":"mcm","clk":"11787471225","pt":1722459236445,"mc":[{"id":"1.231241311","rc":[{"batb":[[0,2.26,10],[1,2.24,29.8],[2,2.12,54.28]],"ltp":2.3,"tv":224.28,"id":26354922}]}]}
{"op":"mcm","clk":"11787471392","pt":1722459239941,"mc":[{"id":"1.231241311","rc":[{"batb":[[0,2.24,29.8],[1,2.12,54.28],[2,1.1,10000]],"ltp":2.3,"tv":224.28,"id":26354922}]}]}
{"op":"mcm","clk":"11787472611","pt":1722459270383,"mc":[{"id":"1.231241311","rc":[{"batb":[[0,2.26,10],[1,2.24,29.8],[2,2.12,54.28]],"ltp":2.3,"tv":224.28,"id":26354922}]}]}
{"op":"mcm","clk":"11787472723","pt":1722459273969,"mc":[{"id":"1.231241311","rc":[{"batb":[[0,2.24,29.8],[1,2.12,54.28],[2,1.1,10000]],"ltp":2.3,"tv":224.28,"id":26354922}]}]}
{"op":"mcm","clk":"11787473102","pt":1722459283757,"mc":[{"id":"1.231241311","rc":[{"batb":[[0,2.26,10],[1,2.24,29.8],[2,2.12,54.28]],"ltp":2.3,"tv":224.28,"id":26354922}]}]}
{"op":"mcm","clk":"11787473251","pt":1722459287468,"mc":[{"id":"1.231241311","rc":[{"batb":[[0,2.24,29.8],[1,2.12,54.28],[2,1.1,10000]],"ltp":2.3,"tv":224.28,"id":26354922}]}]}
{"op":"mcm","clk":"11787473683","pt":1722459299475,"mc":[{"id":"1.231241311","rc":[{"batb":[[0,2.26,10],[1,2.24,29.8],[2,2.12,54.28]],"ltp":2.3,"tv":224.28,"id":26354922}]}]}
{"op":"mcm","clk":"11787473823","pt":1722459303121,"mc":[{"id":"1.231241311","rc":[{"batb":[[0,2.24,29.8],[1,2.12,54.28],[2,1.1,10000]],"ltp":2.3,"tv":224.28,"id":26354922}]}]}
{"op":"mcm","clk":"11787474376","pt":1722459318845,"mc":[{"id":"1.231241311","rc":[{"batb":[[0,2.26,10],[1,2.24,29.8],[2,2.12,54.28]],"ltp":2.3,"tv":224.28,"id":26354922}]}]}
{"op":"mcm","clk":"11787474488","pt":1722459322424,"mc":[{"id":"1.231241311","rc":[{"batb":[[0,2.24,29.8],[1,2.12,54.28],[2,1.1,10000]],"ltp":2.3,"tv":224.28,"id":26354922}]}]}
{"op":"mcm","clk":"11787474646","pt":1722459327140,"mc":[{"id":"1.231241311","rc":[{"batb":[[0,2.26,10],[1,2.24,29.8],[2,2.12,54.28]],"ltp":2.3,"tv":224.28,"id":26354922}]}]}
{"op":"mcm","clk":"11787474844","pt":1722459332022,"mc":[{"id":"1.231241311","rc":[{"batb":[[0,2.24,29.8],[1,2.12,54.28],[2,1.1,10000]],"ltp":2.3,"tv":224.28,"id":26354922}]}]}
{"op":"mcm","clk":"11787481711","pt":1722459513804,"mc":[{"id":"1.231241311","rc":[{"batb":[[0,2.26,10],[1,2.24,29.8],[2,2.12,54.28]],"ltp":2.3,"tv":224.28,"id":26354922}]}]}
{"op":"mcm","clk":"11787481863","pt":1722459517342,"mc":[{"id":"1.231241311","rc":[{"batb":[[0,2.24,29.8],[1,2.12,54.28],[2,1.1,10000]],"ltp":2.3,"tv":224.28,"id":26354922}]}]}
{"op":"mcm","clk":"11787483150","pt":1722459547570,"mc":[{"id":"1.231241311","rc":[{"batb":[[0,2.26,10],[1,2.24,29.8],[2,2.12,54.28]],"ltp":2.3,"tv":224.28,"id":26354922}]}]}
{"op":"mcm","clk":"11787483316","pt":1722459551158,"mc":[{"id":"1.231241311","rc":[{"batb":[[0,2.24,29.8],[1,2.12,54.28],[2,1.1,10000]],"ltp":2.3,"tv":224.28,"id":26354922}]}]}
{"op":"mcm","clk":"11787483527","pt":1722459555161,"mc":[{"id":"1.231241311","rc":[{"batb":[[0,2.26,10],[1,2.24,29.8],[2,2.12,54.28]],"ltp":2.3,"tv":224.28,"id":26354922}]}]}
{"op":"mcm","clk":"11787483700","pt":1722459558565,"mc":[{"id":"1.231241311","rc":[{"batb":[[0,2.24,29.8],[1,2.12,54.28],[2,1.1,10000]],"ltp":2.3,"tv":224.28,"id":26354922}]}]}
{"op":"mcm","clk":"11787483987","pt":1722459566825,"mc":[{"id":"1.231241311","rc":[{"batb":[[0,2.26,10],[1,2.24,29.8],[2,2.12,54.28]],"ltp":2.3,"tv":224.28,"id":26354922}]}]}
{"op":"mcm","clk":"11787484137","pt":1722459570210,"mc":[{"id":"1.231241311","rc":[{"batb":[[0,2.24,29.8],[1,2.12,54.28],[2,1.1,10000]],"ltp":2.3,"tv":224.28,"id":26354922}]}]}
{"op":"mcm","clk":"11787484387","pt":1722459576582,"mc":[{"id":"1.231241311","rc":[{"batb":[[0,2.26,10],[1,2.24,29.8],[2,2.12,54.28]],"ltp":2.3,"tv":224.28,"id":26354922}]}]}
{"op":"mcm","clk":"11787484507","pt":1722459580127,"mc":[{"id":"1.231241311","rc":[{"batb":[[0,2.24,29.8],[1,2.12,54.28],[2,1.1,10000]],"ltp":2.3,"tv":224.28,"id":26354922}]}]}
{"op":"mcm","clk":"11787484628","pt":1722459583400,"mc":[{"id":"1.231241311","rc":[{"batb":[[0,2.26,10],[1,2.24,29.8],[2,2.12,54.28]],"ltp":2.3,"tv":224.28,"id":26354922}]}]}
{"op":"mcm","clk":"11787484743","pt":1722459587040,"mc":[{"id":"1.231241311","rc":[{"batb":[[0,2.24,29.8],[1,2.12,54.28],[2,1.1,10000]],"ltp":2.3,"tv":224.28,"id":26354922}]}]}
{"op":"mcm","clk":"11787484941","pt":1722459592230,"mc":[{"id":"1.231241311","rc":[{"batb":[[0,2.26,10],[1,2.24,29.8],[2,2.12,54.28]],"ltp":2.3,"tv":224.28,"id":26354922}]}]}
{"op":"mcm","clk":"11787485066","pt":1722459595719,"mc":[{"id":"1.231241311","rc":[{"batb":[[0,2.24,29.8],[1,2.12,54.28],[2,1.1,10000]],"ltp":2.3,"tv":224.28,"id":26354922}]}]}
{"op":"mcm","clk":"11787486093","pt":1722459619038,"mc":[{"id":"1.231241311","rc":[{"trd":[[1.74,72.38]],"batb":[[0,1.75,9.98]],"ltp":1.74,"tv":980.82,"id":26354926},{"trd":[[2.4,60.97]],"batb":[[0,2.26,10],[1,2.24,29.8],[2,2.12,54.28]],"batl":[[0,2.34,14.06]],"ltp":2.3,"tv":224.3,"id":26354922}],"tv":1205.12}]}
{"op":"mcm","clk":"11787486275","pt":1722459622582,"mc":[{"id":"1.231241311","rc":[{"batb":[[0,2.24,29.8],[1,2.12,54.28],[2,1.1,10000]],"ltp":2.3,"tv":224.3,"id":26354922}]}]}
{"op":"mcm","clk":"11787486517","pt":1722459627976,"mc":[{"id":"1.231241311","rc":[{"batb":[[0,2.26,10],[1,2.24,29.8],[2,2.12,54.28]],"ltp":2.3,"tv":224.3,"id":26354922}]}]}
{"op":"mcm","clk":"11787486662","pt":1722459631269,"mc":[{"id":"1.231241311","rc":[{"batb":[[0,2.24,29.8],[1,2.12,54.28],[2,1.1,10000]],"ltp":2.3,"tv":224.3,"id":26354922}]}]}
{"op":"mcm","clk":"11787486890","pt":1722459637887,"mc":[{"id":"1.231241311","rc":[{"batb":[[0,2.26,10],[1,2.24,29.8],[2,2.12,54.28]],"ltp":2.3,"tv":224.3,"id":26354922}]}]}
{"op":"mcm","clk":"11787487011","pt":1722459641077,"mc":[{"id":"1.231241311","rc":[{"batb":[[0,2.24,29.8],[1,2.12,54.28],[2,1.1,10000]],"ltp":2.3,"tv":224.3,"id":26354922}]}]}
{"op":"mcm","clk":"11787487282","pt":1722459648871,"mc":[{"id":"1.231241311","rc":[{"batb":[[0,2.26,10],[1,2.24,29.8],[2,2.12,54.28]],"ltp":2.3,"tv":224.3,"id":26354922}]}]}
{"op":"mcm","clk":"11787487431","pt":1722459652475,"mc":[{"id":"1.231241311","rc":[{"batb":[[0,2.24,29.8],[1,2.12,54.28],[2,1.1,10000]],"ltp":2.3,"tv":224.3,"id":26354922}]}]}
{"op":"mcm","clk":"11787493197","pt":1722459784620,"mc":[{"id":"1.231241311","rc":[{"batb":[[0,2.26,10],[1,2.24,29.8],[2,2.12,54.28]],"ltp":2.3,"tv":224.3,"id":26354922}]}]}
{"op":"mcm","clk":"11787493324","pt":1722459787905,"mc":[{"id":"1.231241311","rc":[{"batb":[[0,2.24,29.8],[1,2.12,54.28],[2,1.1,10000]],"ltp":2.3,"tv":224.3,"id":26354922}]}]}
{"op":"mcm","clk":"11787493670","pt":1722459797138,"mc":[{"id":"1.231241311","rc":[{"batb":[[0,2.26,10],[1,2.24,29.8],[2,2.12,54.28]],"ltp":2.3,"tv":224.3,"id":26354922}]}]}
{"op":"mcm","clk":"11787493824","pt":1722459800425,"mc":[{"id":"1.231241311","rc":[{"batb":[[0,2.24,29.8],[1,2.12,54.28],[2,1.1,10000]],"ltp":2.3,"tv":224.3,"id":26354922}]}]}
{"op":"mcm","clk":"11787494141","pt":1722459808948,"mc":[{"id":"1.231241311","rc":[{"batb":[[0,2.26,10],[1,2.24,29.8],[2,2.12,54.28]],"ltp":2.3,"tv":224.3,"id":26354922}]}]}
{"op":"mcm","clk":"11787494261","pt":1722459812432,"mc":[{"id":"1.231241311","rc":[{"batb":[[0,2.24,29.8],[1,2.12,54.28],[2,1.1,10000]],"ltp":2.3,"tv":224.3,"id":26354922}]}]}
{"op":"mcm","clk":"11787494996","pt":1722459834379,"mc":[{"id":"1.231241311","rc":[{"batb":[[0,2.26,10],[1,2.24,29.8],[2,2.12,54.28]],"ltp":2.3,"tv":224.3,"id":26354922}]}]}
{"op":"mcm","clk":"11787495126","pt":1722459837658,"mc":[{"id":"1.231241311","rc":[{"batb":[[0,2.24,29.8],[1,2.12,54.28],[2,1.1,10000]],"ltp":2.3,"tv":224.3,"id":26354922}]}]}
{"op":"mcm","clk":"11787495376","pt":1722459845002,"mc":[{"id":"1.231241311","rc":[{"batb":[[0,2.26,10],[1,2.24,29.8],[2,2.12,54.28]],"ltp":2.3,"tv":224.3,"id":26354922}]}]}
{"op":"mcm","clk":"11787495532","pt":1722459848498,"mc":[{"id":"1.231241311","rc":[{"batb":[[0,2.24,29.8],[1,2.12,54.28],[2,1.1,10000]],"ltp":2.3,"tv":224.3,"id":26354922}]}]}
{"op":"mcm","clk":"11787495771","pt":1722459854978,"mc":[{"id":"1.231241311","rc":[{"batb":[[0,2.26,10],[1,2.24,29.8],[2,2.12,54.28]],"ltp":2.3,"tv":224.3,"id":26354922}]}]}
{"op":"mcm","clk":"11787495880","pt":1722459858412,"mc":[{"id":"1.231241311","rc":[{"batb":[[0,2.24,29.8],[1,2.12,54.28],[2,1.1,10000]],"ltp":2.3,"tv":224.3,"id":26354922}]}]}
{"op":"mcm","clk":"11787497081","pt":1722459890420,"mc":[{"id":"1.231241311","rc":[{"batb":[[0,2.26,10],[1,2.24,29.8],[2,2.12,54.28]],"ltp":2.3,"tv":224.3,"id":26354922}]}]}
{"op":"mcm","clk":"11787497225","pt":1722459894020,"mc":[{"id":"1.231241311","rc":[{"batb":[[0,2.24,29.8],[1,2.12,54.28],[2,1.1,10000]],"ltp":2.3,"tv":224.3,"id":26354922}]}]}
{"op":"mcm","clk":"11787503802","pt":1722460055707,"mc":[{"id":"1.231241311","rc":[{"batb":[[0,2.26,10],[1,2.24,29.8],[2,2.12,54.28]],"ltp":2.3,"tv":224.3,"id":26354922}]}]}
{"op":"mcm","clk":"11787503956","pt":1722460059096,"mc":[{"id":"1.231241311","rc":[{"batb":[[0,2.24,29.8],[1,2.12,54.28],[2,1.1,10000]],"ltp":2.3,"tv":224.3,"id":26354922}]}]}
{"op":"mcm","clk":"11787504495","pt":1722460072894,"mc":[{"id":"1.231241311","rc":[{"batb":[[0,2.26,10],[1,2.24,29.8],[2,2.12,54.28]],"ltp":2.3,"tv":224.3,"id":26354922}]}]}
{"op":"mcm","clk":"11787504663","pt":1722460076491,"mc":[{"id":"1.231241311","rc":[{"batb":[[0,2.24,29.8],[1,2.12,54.28],[2,1.1,10000]],"ltp":2.3,"tv":224.3,"id":26354922}]}]}
{"op":"mcm","clk":"11787505767","pt":1722460099047,"mc":[{"id":"1.231241311","rc":[{"batb":[[0,2.26,10],[1,2.24,29.8],[2,2.12,54.28]],"ltp":2.3,"tv":224.3,"id":26354922}]}]}
{"op":"mcm","clk":"11787505951","pt":1722460102646,"mc":[{"id":"1.231241311","rc":[{"batb":[[0,2.24,29.8],[1,2.12,54.28],[2,1.1,10000]],"ltp":2.3,"tv":224.3,"id":26354922}]}]}
{"op":"mcm","clk":"11787506298","pt":1722460109424,"mc":[{"id":"1.231241311","rc":[{"batb":[[0,2.26,10],[1,2.24,29.8],[2,2.12,54.28]],"ltp":2.3,"tv":224.3,"id":26354922}]}]}
{"op":"mcm","clk":"11787506460","pt":1722460112756,"mc":[{"id":"1.231241311","rc":[{"batb":[[0,2.24,29.8],[1,2.12,54.28],[2,1.1,10000]],"ltp":2.3,"tv":224.3,"id":26354922}]}]}
{"op":"mcm","clk":"11787506635","pt":1722460116043,"mc":[{"id":"1.231241311","rc":[{"batb":[[0,2.26,10],[1,2.24,29.8],[2,2.12,54.28]],"ltp":2.3,"tv":224.3,"id":26354922}]}]}
{"op":"mcm","clk":"11787506807","pt":1722460119583,"mc":[{"id":"1.231241311","rc":[{"batb":[[0,2.24,29.8],[1,2.12,54.28],[2,1.1,10000]],"ltp":2.3,"tv":224.3,"id":26354922}]}]}
{"op":"mcm","clk":"11787507192","pt":1722460126984,"mc":[{"id":"1.231241311","rc":[{"batb":[[0,2.26,10],[1,2.24,29.8],[2,2.12,54.28]],"ltp":2.3,"tv":224.3,"id":26354922}]}]}
{"op":"mcm","clk":"11787507374","pt":1722460130474,"mc":[{"id":"1.231241311","rc":[{"batb":[[0,2.24,29.8],[1,2.12,54.28],[2,1.1,10000]],"ltp":2.3,"tv":224.3,"id":26354922}]}]}
{"op":"mcm","clk":"11787507658","pt":1722460137420,"mc":[{"id":"1.231241311","rc":[{"batb":[[0,2.26,10],[1,2.24,29.8],[2,2.12,54.28]],"ltp":2.3,"tv":224.3,"id":26354922}]}]}
{"op":"mcm","clk":"11787507789","pt":1722460140997,"mc":[{"id":"1.231241311","rc":[{"batb":[[0,2.24,29.8],[1,2.12,54.28],[2,1.1,10000]],"ltp":2.3,"tv":224.3,"id":26354922}]}]}
{"op":"mcm","clk":"11787507889","pt":1722460143401,"mc":[{"id":"1.231241311","rc":[{"batb":[[0,2.26,10],[1,2.24,29.8],[2,2.12,54.28]],"ltp":2.3,"tv":224.3,"id":26354922}]}]}
{"op":"mcm","clk":"11787507944","pt":1722460145092,"mc":[{"id":"1.231241311","rc":[{"trd":[[1.75,18.78]],"batb":[[0,1.75,3.59]],"ltp":1.75,"tv":993.6,"id":26354926},{"batl":[[0,2.34,21.94]],"ltp":2.3,"tv":224.3,"id":26354922}],"tv":1217.9}]}
{"op":"mcm","clk":"11787508017","pt":1722460146788,"mc":[{"id":"1.231241311","rc":[{"batb":[[0,2.24,29.8],[1,2.12,54.28],[2,1.1,10000]],"ltp":2.3,"tv":224.3,"id":26354922}]}]}
{"op":"mcm","clk":"11787508185","pt":1722460150172,"mc":[{"id":"1.231241311","rc":[{"batb":[[0,2.26,10],[1,2.24,29.8],[2,2.12,54.28]],"ltp":2.3,"tv":224.3,"id":26354922}]}]}
{"op":"mcm","clk":"11787508341","pt":1722460153813,"mc":[{"id":"1.231241311","rc":[{"batb":[[0,2.24,29.8],[1,2.12,54.28],[2,1.1,10000]],"ltp":2.3,"tv":224.3,"id":26354922}]}]}
{"op":"mcm","clk":"11787508483","pt":1722460156582,"mc":[{"id":"1.231241311","rc":[{"batb":[[0,2.26,10],[1,2.24,29.8],[2,2.12,54.28]],"ltp":2.3,"tv":224.3,"id":26354922}]}]}
{"op":"mcm","clk":"11787508635","pt":1722460160125,"mc":[{"id":"1.231241311","rc":[{"batb":[[0,2.24,29.8],[1,2.12,54.28],[2,1.1,10000]],"ltp":2.3,"tv":224.3,"id":26354922}]}]}
{"op":"mcm","clk":"11787511645","pt":1722460223355,"mc":[{"id":"1.231241311","rc":[{"batb":[[0,2.26,10],[1,2.24,29.8],[2,2.12,54.28]],"ltp":2.3,"tv":224.3,"id":26354922}]}]}
{"op":"mcm","clk":"11787511817","pt":1722460226917,"mc":[{"id":"1.231241311","rc":[{"batb":[[0,2.24,29.8],[1,2.12,54.28],[2,1.1,10000]],"ltp":2.3,"tv":224.3,"id":26354922}]}]}
{"op":"mcm","clk":"11787512878","pt":1722460247144,"mc":[{"id":"1.231241311","rc":[{"batb":[[0,2.26,10],[1,2.24,29.8],[2,2.12,54.28]],"ltp":2.3,"tv":224.3,"id":26354922}]}]}
{"op":"mcm","clk":"11787513051","pt":1722460250428,"mc":[{"id":"1.231241311","rc":[{"batb":[[0,2.24,29.8],[1,2.12,54.28],[2,1.1,10000]],"ltp":2.3,"tv":224.3,"id":26354922}]}]}
{"op":"mcm","clk":"11787513924","pt":1722460265170,"mc":[{"id":"1.231241311","rc":[{"batb":[[0,2.26,10],[1,2.24,29.8],[2,2.12,54.28]],"ltp":2.3,"tv":224.3,"id":26354922}]}]}
{"op":"mcm","clk":"11787514134","pt":1722460268474,"mc":[{"id":"1.231241311","rc":[{"batb":[[0,2.24,29.8],[1,2.12,54.28],[2,1.1,10000]],"ltp":2.3,"tv":224.3,"id":26354922}]}]}
{"op":"mcm","clk":"11787514676","pt":1722460278901,"mc":[{"id":"1.231241311","rc":[{"batb":[[0,2.26,10],[1,2.24,29.8],[2,2.12,54.28]],"ltp":2.3,"tv":224.3,"id":26354922}]}]}
{"op":"mcm","clk":"11787514893","pt":1722460282293,"mc":[{"id":"1.231241311","rc":[{"batb":[[0,2.24,29.8],[1,2.12,54.28],[2,1.1,10000]],"ltp":2.3,"tv":224.3,"id":26354922}]}]}
{"op":"mcm","clk":"11787516259","pt":1722460309726,"mc":[{"id":"1.231241311","rc":[{"batb":[[0,2.26,10],[1,2.24,29.8],[2,2.12,54.28]],"ltp":2.3,"tv":224.3,"id":26354922}]}]}
{"op":"mcm","clk":"11787516416","pt":1722460313203,"mc":[{"id":"1.231241311","rc":[{"batb":[[0,2.24,29.8],[1,2.12,54.28],[2,1.1,10000]],"ltp":2.3,"tv":224.3,"id":26354922}]}]}
{"op":"mcm","clk":"11787516613","pt":1722460316655,"mc":[{"id":"1.231241311","rc":[{"batb":[[0,2.26,10],[1,2.24,29.8],[2,2.12,54.28]],"ltp":2.3,"tv":224.3,"id":26354922}]}]}
{"op":"mcm","clk":"11787516805","pt":1722460320032,"mc":[{"id":"1.231241311","rc":[{"batb":[[0,2.24,29.8],[1,2.12,54.28],[2,1.1,10000]],"ltp":2.3,"tv":224.3,"id":26354922}]}]}
{"op":"mcm","clk":"11787517900","pt":1722460339349,"mc":[{"id":"1.231241311","rc":[{"batb":[[0,2.26,10],[1,2.24,29.8],[2,2.12,54.28]],"ltp":2.3,"tv":224.3,"id":26354922}]}]}
{"op":"mcm","clk":"11787518110","pt":1722460342945,"mc":[{"id":"1.231241311","rc":[{"batb":[[0,2.24,29.8],[1,2.12,54.28],[2,1.1,10000]],"ltp":2.3,"tv":224.3,"id":26354922}]}]}
{"op":"mcm","clk":"11787518321","pt":1722460346748,"mc":[{"id":"1.231241311","rc":[{"batb":[[0,2.26,10],[1,2.24,29.8],[2,2.12,54.28]],"ltp":2.3,"tv":224.3,"id":26354922}]}]}
{"op":"mcm","clk":"11787518495","pt":1722460350380,"mc":[{"id":"1.231241311","rc":[{"batb":[[0,2.24,29.8],[1,2.12,54.28],[2,1.1,10000]],"ltp":2.3,"tv":224.3,"id":26354922}]}]}
{"op":"mcm","clk":"11787518652","pt":1722460353568,"mc":[{"id":"1.231241311","rc":[{"batb":[[0,2.26,10],[1,2.24,29.8],[2,2.12,54.28]],"ltp":2.3,"tv":224.3,"id":26354922}]}]}
{"op":"mcm","clk":"11787518788","pt":1722460356893,"mc":[{"id":"1.231241311","rc":[{"batb":[[0,2.24,29.8],[1,2.12,54.28],[2,1.1,10000]],"ltp":2.3,"tv":224.3,"id":26354922}]}]}
{"op":"mcm","clk":"11787530318","pt":1722460594753,"mc":[{"id":"1.231241311","rc":[{"batb":[[0,2.26,10],[1,2.24,29.8],[2,2.12,54.28]],"ltp":2.3,"tv":224.3,"id":26354922}]}]}
{"op":"mcm","clk":"11787530543","pt":1722460598859,"mc":[{"id":"1.231241311","rc":[{"batb":[[0,2.24,29.8],[1,2.12,54.28],[2,1.1,10000]],"ltp":2.3,"tv":224.3,"id":26354922}]}]}
{"op":"mcm","clk":"11787539767","pt":1722460796835,"mc":[{"id":"1.231241311","rc":[{"batb":[[0,2.26,10],[1,2.24,29.8],[2,2.12,54.28]],"ltp":2.3,"tv":224.3,"id":26354922}]}]}
{"op":"mcm","clk":"11787539881","pt":1722460800260,"mc":[{"id":"1.231241311","rc":[{"batb":[[0,2.24,29.8],[1,2.12,54.28],[2,1.1,10000]],"ltp":2.3,"tv":224.3,"id":26354922}]}]}
{"op":"mcm","clk":"11787540086","pt":1722460805380,"mc":[{"id":"1.231241311","rc":[{"batb":[[0,2.26,10],[1,2.24,29.8],[2,2.12,54.28]],"ltp":2.3,"tv":224.3,"id":26354922}]}]}
{"op":"mcm","clk":"11787540206","pt":1722460808766,"mc":[{"id":"1.231241311","rc":[{"batb":[[0,2.24,29.8],[1,2.12,54.28],[2,1.1,10000]],"ltp":2.3,"tv":224.3,"id":26354922}]}]}
{"op":"mcm","clk":"11787540437","pt":1722460814295,"mc":[{"id":"1.231241311","rc":[{"batb":[[0,2.26,10],[1,2.24,29.8],[2,2.12,54.28]],"ltp":2.3,"tv":224.3,"id":26354922}]}]}
{"op":"mcm","clk":"11787540571","pt":1722460817683,"mc":[{"id":"1.231241311","rc":[{"batb":[[0,2.24,29.8],[1,2.12,54.28],[2,1.1,10000]],"ltp":2.3,"tv":224.3,"id":26354922}]}]}
{"op":"mcm","clk":"11787540967","pt":1722460827420,"mc":[{"id":"1.231241311","rc":[{"batb":[[0,2.26,10],[1,2.24,29.8],[2,2.12,54.28]],"ltp":2.3,"tv":224.3,"id":26354922}]}]}
{"op":"mcm","clk":"11787541117","pt":1722460830795,"mc":[{"id":"1.231241311","rc":[{"batb":[[0,2.24,29.8],[1,2.12,54.28],[2,1.1,10000]],"ltp":2.3,"tv":224.3,"id":26354922}]}]}
{"op":"mcm","clk":"11787541215","pt":1722460833713,"mc":[{"id":"1.231241311","rc":[{"batb":[[0,2.26,10],[1,2.24,29.8],[2,2.12,54.28]],"ltp":2.3,"tv":224.3,"id":26354922}]}]}
{"op":"mcm","clk":"11787541349","pt":1722460837715,"mc":[{"id":"1.231241311","rc":[{"batb":[[0,2.24,29.8],[1,2.12,54.28],[2,1.1,10000]],"ltp":2.3,"tv":224.3,"id":26354922}]}]}
{"op":"mcm","clk":"11787541546","pt":1722460843300,"mc":[{"id":"1.231241311","rc":[{"batb":[[0,2.26,10],[1,2.24,29.8],[2,2.12,54.28]],"ltp":2.3,"tv":224.3,"id":26354922}]}]}
{"op":"mcm","clk":"11787541653","pt":1722460846730,"mc":[{"id":"1.231241311","rc":[{"batb":[[0,2.24,29.8],[1,2.12,54.28],[2,1.1,10000]],"ltp":2.3,"tv":224.3,"id":26354922}]}]}
{"op":"mcm","clk":"11787542259","pt":1722460864825,"mc":[{"id":"1.231241311","rc":[{"batb":[[0,2.26,10],[1,2.24,29.8],[2,2.12,54.28]],"ltp":2.3,"tv":224.3,"id":26354922}]}]}
{"op":"mcm","clk":"11787542417","pt":1722460868157,"mc":[{"id":"1.231241311","rc":[{"batb":[[0,2.24,29.8],[1,2.12,54.28],[2,1.1,10000]],"ltp":2.3,"tv":224.3,"id":26354922}]}]}
{"op":"mcm","clk":"11787542958","pt":1722460880884,"mc":[{"id":"1.231241311","rc":[{"batb":[[0,2.26,10],[1,2.24,29.8],[2,2.12,54.28]],"ltp":2.3,"tv":224.3,"id":26354922}]}]}
{"op":"mcm","clk":"11787543144","pt":1722460884282,"mc":[{"id":"1.231241311","rc":[{"batb":[[0,2.24,29.8],[1,2.12,54.28],[2,1.1,10000]],"ltp":2.3,"tv":224.3,"id":26354922}]}]}
{"op":"mcm","clk":"11787543777","pt":1722460900474,"mc":[{"id":"1.231241311","rc":[{"batb":[[0,2.26,10],[1,2.24,29.8],[2,2.12,54.28]],"ltp":2.3,"tv":224.3,"id":26354922}]}]}
{"op":"mcm","clk":"11787543918","pt":1722460904108,"mc":[{"id":"1.231241311","rc":[{"batb":[[0,2.24,29.8],[1,2.12,54.28],[2,1.1,10000]],"ltp":2.3,"tv":224.3,"id":26354922}]}]}
{"op":"mcm","clk":"11787544232","pt":1722460912009,"mc":[{"id":"1.231241311","rc":[{"batb":[[0,2.26,10],[1,2.24,29.8],[2,2.12,54.28]],"ltp":2.3,"tv":224.3,"id":26354922}]}]}
{"op":"mcm","clk":"11787544365","pt":1722460915290,"mc":[{"id":"1.231241311","rc":[{"batb":[[0,2.24,29.8],[1,2.12,54.28],[2,1.1,10000]],"ltp":2.3,"tv":224.3,"id":26354922}]}]}
{"op":"mcm","clk":"11787544600","pt":1722460920638,"mc":[{"id":"1.231241311","rc":[{"batb":[[0,2.26,10],[1,2.24,29.8],[2,2.12,54.28]],"ltp":2.3,"tv":224.3,"id":26354922}]}]}
{"op":"mcm","clk":"11787544734","pt":1722460924127,"mc":[{"id":"1.231241311","rc":[{"batb":[[0,2.24,29.8],[1,2.12,54.28],[2,1.1,10000]],"ltp":2.3,"tv":224.3,"id":26354922}]}]}
{"op":"mcm","clk":"11787546267","pt":1722460960588,"mc":[{"id":"1.231241311","rc":[{"batb":[[0,2.26,10],[1,2.24,29.8],[2,2.12,54.28]],"ltp":2.3,"tv":224.3,"id":26354922}]}]}
{"op":"mcm","clk":"11787546423","pt":1722460964179,"mc":[{"id":"1.231241311","rc":[{"batb":[[0,2.24,29.8],[1,2.12,54.28],[2,1.1,10000]],"ltp":2.3,"tv":224.3,"id":26354922}]}]}
{"op":"mcm","clk":"11787565271","pt":1722461395402,"mc":[{"id":"1.231241311","rc":[{"batb":[[0,2.26,10],[1,2.24,29.8],[2,2.12,54.28]],"ltp":2.3,"tv":224.3,"id":26354922}]}]}
{"op":"mcm","clk":"11787565476","pt":1722461398832,"mc":[{"id":"1.231241311","rc":[{"batb":[[0,2.24,29.8],[1,2.12,54.28],[2,1.1,10000]],"ltp":2.3,"tv":224.3,"id":26354922}]}]}
{"op":"mcm","clk":"11787566177","pt":1722461413252,"mc":[{"id":"1.231241311","rc":[{"batb":[[0,2.26,10],[1,2.24,29.8],[2,2.12,54.28]],"ltp":2.3,"tv":224.3,"id":26354922}]}]}
{"op":"mcm","clk":"11787566359","pt":1722461416737,"mc":[{"id":"1.231241311","rc":[{"batb":[[0,2.24,29.8],[1,2.12,54.28],[2,1.1,10000]],"ltp":2.3,"tv":224.3,"id":26354922}]}]}
{"op":"mcm","clk":"11787567681","pt":1722461440863,"mc":[{"id":"1.231241311","rc":[{"batb":[[0,2.26,10],[1,2.24,29.8],[2,2.12,54.28]],"ltp":2.3,"tv":224.3,"id":26354922}]}]}
{"op":"mcm","clk":"11787567849","pt":1722461444354,"mc":[{"id":"1.231241311","rc":[{"batb":[[0,2.24,29.8],[1,2.12,54.28],[2,1.1,10000]],"ltp":2.3,"tv":224.3,"id":26354922}]}]}
{"op":"mcm","clk":"11787569648","pt":1722461479643,"mc":[{"id":"1.231241311","rc":[{"batb":[[0,2.26,10],[1,2.24,29.8],[2,2.12,54.28]],"ltp":2.3,"tv":224.3,"id":26354922}]}]}
{"op":"mcm","clk":"11787569863","pt":1722461483216,"mc":[{"id":"1.231241311","rc":[{"batb":[[0,2.24,29.8],[1,2.12,54.28],[2,1.1,10000]],"ltp":2.3,"tv":224.3,"id":26354922}]}]}
{"op":"mcm","clk":"11787570840","pt":1722461500633,"mc":[{"id":"1.231241311","rc":[{"batb":[[0,2.26,10],[1,2.24,29.8],[2,2.12,54.28]],"ltp":2.3,"tv":224.3,"id":26354922}]}]}
{"op":"mcm","clk":"11787571008","pt":1722461504072,"mc":[{"id":"1.231241311","rc":[{"batb":[[0,2.24,29.8],[1,2.12,54.28],[2,1.1,10000]],"ltp":2.3,"tv":224.3,"id":26354922}]}]}
{"op":"mcm","clk":"11787571118","pt":1722461506345,"mc":[{"id":"1.231241311","rc":[{"batb":[[0,2.26,10],[1,2.24,29.8],[2,2.12,54.28]],"ltp":2.3,"tv":224.3,"id":26354922}]}]}
{"op":"mcm","clk":"11787571294","pt":1722461509848,"mc":[{"id":"1.231241311","rc":[{"batb":[[0,2.24,29.8],[1,2.12,54.28],[2,1.1,10000]],"ltp":2.3,"tv":224.3,"id":26354922}]}]}
{"op":"mcm","clk":"11787571461","pt":1722461513241,"mc":[{"id":"1.231241311","rc":[{"batb":[[0,2.26,10],[1,2.24,29.8],[2,2.12,54.28]],"ltp":2.3,"tv":224.3,"id":26354922}]}]}
{"op":"mcm","clk":"11787571633","pt":1722461516784,"mc":[{"id":"1.231241311","rc":[{"batb":[[0,2.24,29.8],[1,2.12,54.28],[2,1.1,10000]],"ltp":2.3,"tv":224.3,"id":26354922}]}]}
{"op":"mcm","clk":"11787571788","pt":1722461520071,"mc":[{"id":"1.231241311","rc":[{"batl":[[1,1.8,112.5]],"ltp":1.75,"tv":993.6,"id":26354926},{"batb":[[0,2.26,10],[1,2.24,29.8],[2,2.12,54.28]],"ltp":2.3,"tv":224.3,"id":26354922}]}]}
{"op":"mcm","clk":"11787571931","pt":1722461523403,"mc":[{"id":"1.231241311","rc":[{"batb":[[0,2.24,29.8],[1,2.12,54.28],[2,1.1,10000]],"ltp":2.3,"tv":224.3,"id":26354922}]}]}
{"op":"mcm","clk":"11787572285","pt":1722461531416,"mc":[{"id":"1.231241311","rc":[{"batb":[[0,2.26,10],[1,2.24,29.8],[2,2.12,54.28]],"ltp":2.3,"tv":224.3,"id":26354922}]}]}
{"op":"mcm","clk":"11787572474","pt":1722461534704,"mc":[{"id":"1.231241311","rc":[{"batb":[[0,2.24,29.8],[1,2.12,54.28],[2,1.1,10000]],"ltp":2.3,"tv":224.3,"id":26354922}]}]}
{"op":"mcm","clk":"11787573003","pt":1722461544410,"mc":[{"id":"1.231241311","rc":[{"batb":[[0,2.26,10],[1,2.24,29.8],[2,2.12,54.28]],"ltp":2.3,"tv":224.3,"id":26354922}]}]}
{"op":"mcm","clk":"11787573173","pt":1722461547908,"mc":[{"id":"1.231241311","rc":[{"batb":[[0,2.24,29.8],[1,2.12,54.28],[2,1.1,10000]],"ltp":2.3,"tv":224.3,"id":26354922}]}]}
{"op":"mcm","clk":"11787573386","pt":1722461551828,"mc":[{"id":"1.231241311","rc":[{"batb":[[0,2.26,10],[1,2.24,29.8],[2,2.12,54.28]],"ltp":2.3,"tv":224.3,"id":26354922}]}]}
{"op":"mcm","clk":"11787573569","pt":1722461555419,"mc":[{"id":"1.231241311","rc":[{"batb":[[0,2.24,29.8],[1,2.12,54.28],[2,1.1,10000]],"ltp":2.3,"tv":224.3,"id":26354922}]}]}
{"op":"mcm","clk":"11787573919","pt":1722461562343,"mc":[{"id":"1.231241311","rc":[{"batb":[[0,2.26,10],[1,2.24,29.8],[2,2.12,54.28]],"ltp":2.3,"tv":224.3,"id":26354922}]}]}
{"op":"mcm","clk":"11787574111","pt":1722461565851,"mc":[{"id":"1.231241311","rc":[{"batb":[[0,2.24,29.8],[1,2.12,54.28],[2,1.1,10000]],"ltp":2.3,"tv":224.3,"id":26354922}]}]}
{"op":"mcm","clk":"11787576314","pt":1722461606981,"mc":[{"id":"1.231241311","rc":[{"batb":[[0,2.26,10],[1,2.24,29.8],[2,2.12,54.28]],"ltp":2.3,"tv":224.3,"id":26354922}]}]}
{"op":"mcm","clk":"11787576530","pt":1722461610484,"mc":[{"id":"1.231241311","rc":[{"batb":[[0,2.24,29.8],[1,2.12,54.28],[2,1.1,10000]],"ltp":2.3,"tv":224.3,"id":26354922}]}]}
{"op":"mcm","clk":"11787576660","pt":1722461612589,"mc":[{"id":"1.231241311","rc":[{"batb":[[0,2.26,10],[1,2.24,29.8],[2,2.12,54.28]],"ltp":2.3,"tv":224.3,"id":26354922}]}]}
{"op":"mcm","clk":"11787576857","pt":1722461615988,"mc":[{"id":"1.231241311","rc":[{"batb":[[0,2.24,29.8],[1,2.12,54.28],[2,1.1,10000]],"ltp":2.3,"tv":224.3,"id":26354922}]}]}
{"op":"mcm","clk":"11787577099","pt":1722461620104,"mc":[{"id":"1.231241311","rc":[{"batb":[[0,2.26,10],[1,2.24,29.8],[2,2.12,54.28]],"ltp":2.3,"tv":224.3,"id":26354922}]}]}
{"op":"mcm","clk":"11787577323","pt":1722461623511,"mc":[{"id":"1.231241311","rc":[{"batb":[[0,2.24,29.8],[1,2.12,54.28],[2,1.1,10000]],"ltp":2.3,"tv":224.3,"id":26354922}]}]}
{"op":"mcm","clk":"11787577544","pt":1722461627514,"mc":[{"id":"1.231241311","rc":[{"batb":[[0,2.26,10],[1,2.24,29.8],[2,2.12,54.28]],"ltp":2.3,"tv":224.3,"id":26354922}]}]}
{"op":"mcm","clk":"11787577719","pt":1722461631015,"mc":[{"id":"1.231241311","rc":[{"batb":[[0,2.24,29.8],[1,2.12,54.28],[2,1.1,10000]],"ltp":2.3,"tv":224.3,"id":26354922}]}]}
{"op":"mcm","clk":"11787578009","pt":1722461636508,"mc":[{"id":"1.231241311","rc":[{"batb":[[0,2.26,10],[1,2.24,29.8],[2,2.12,54.28]],"ltp":2.3,"tv":224.3,"id":26354922}]}]}
{"op":"mcm","clk":"11787578173","pt":1722461640104,"mc":[{"id":"1.231241311","rc":[{"batb":[[0,2.24,29.8],[1,2.12,54.28],[2,1.1,10000]],"ltp":2.3,"tv":224.3,"id":26354922}]}]}
{"op":"mcm","clk":"11787579471","pt":1722461664652,"mc":[{"id":"1.231241311","rc":[{"batb":[[0,2.26,10],[1,2.24,29.8],[2,2.12,54.28]],"ltp":2.3,"tv":224.3,"id":26354922}]}]}
{"op":"mcm","clk":"11787579658","pt":1722461668145,"mc":[{"id":"1.231241311","rc":[{"batb":[[0,2.24,29.8],[1,2.12,54.28],[2,1.1,10000]],"ltp":2.3,"tv":224.3,"id":26354922}]}]}
{"op":"mcm","clk":"11787579801","pt":1722461670961,"mc":[{"id":"1.231241311","rc":[{"batb":[[0,2.26,10],[1,2.24,29.8],[2,2.12,54.28]],"ltp":2.3,"tv":224.3,"id":26354922}]}]}
{"op":"mcm","clk":"11787579965","pt":1722461674456,"mc":[{"id":"1.231241311","rc":[{"batb":[[0,2.24,29.8],[1,2.12,54.28],[2,1.1,10000]],"ltp":2.3,"tv":224.3,"id":26354922}]}]}
{"op":"mcm","clk":"11787580156","pt":1722461677848,"mc":[{"id":"1.231241311","rc":[{"batb":[[0,2.26,10],[1,2.24,29.8],[2,2.12,54.28]],"ltp":2.3,"tv":224.3,"id":26354922}]}]}
{"op":"mcm","clk":"11787580345","pt":1722461681240,"mc":[{"id":"1.231241311","rc":[{"batb":[[0,2.24,29.8],[1,2.12,54.28],[2,1.1,10000]],"ltp":2.3,"tv":224.3,"id":26354922}]}]}
{"op":"mcm","clk":"11787581375","pt":1722461702568,"mc":[{"id":"1.231241311","rc":[{"batb":[[0,2.26,10],[1,2.24,29.8],[2,2.12,54.28]],"ltp":2.3,"tv":224.3,"id":26354922}]}]}
{"op":"mcm","clk":"11787581582","pt":1722461706161,"mc":[{"id":"1.231241311","rc":[{"batb":[[0,2.24,29.8],[1,2.12,54.28],[2,1.1,10000]],"ltp":2.3,"tv":224.3,"id":26354922}]}]}
{"op":"mcm","clk":"11787582564","pt":1722461728097,"mc":[{"id":"1.231241311","rc":[{"batb":[[0,2.26,10],[1,2.24,29.8],[2,2.12,54.28]],"ltp":2.3,"tv":224.3,"id":26354922}]}]}
{"op":"mcm","clk":"11787582719","pt":1722461731696,"mc":[{"id":"1.231241311","rc":[{"batb":[[0,2.24,29.8],[1,2.12,54.28],[2,1.1,10000]],"ltp":2.3,"tv":224.3,"id":26354922}]}]}
{"op":"mcm","clk":"11787583045","pt":1722461738420,"mc":[{"id":"1.231241311","rc":[{"batb":[[0,2.26,10],[1,2.24,29.8],[2,2.12,54.28]],"ltp":2.3,"tv":224.3,"id":26354922}]}]}
{"op":"mcm","clk":"11787583217","pt":1722461741705,"mc":[{"id":"1.231241311","rc":[{"batb":[[0,2.24,29.8],[1,2.12,54.28],[2,1.1,10000]],"ltp":2.3,"tv":224.3,"id":26354922}]}]}
{"op":"mcm","clk":"11787584684","pt":1722461773311,"mc":[{"id":"1.231241311","rc":[{"batb":[[0,2.26,10],[1,2.24,29.8],[2,2.12,54.28]],"ltp":2.3,"tv":224.3,"id":26354922}]}]}
{"op":"mcm","clk":"11787584804","pt":1722461776662,"mc":[{"id":"1.231241311","rc":[{"batb":[[0,2.24,29.8],[1,2.12,54.28],[2,1.1,10000]],"ltp":2.3,"tv":224.3,"id":26354922}]}]}
{"op":"mcm","clk":"11787585246","pt":1722461785048,"mc":[{"id":"1.231241311","rc":[{"batb":[[0,2.26,10],[1,2.24,29.8],[2,2.12,54.28]],"ltp":2.3,"tv":224.3,"id":26354922}]}]}
{"op":"mcm","clk":"11787585389","pt":1722461788449,"mc":[{"id":"1.231241311","rc":[{"batb":[[0,2.24,29.8],[1,2.12,54.28],[2,1.1,10000]],"ltp":2.3,"tv":224.3,"id":26354922}]}]}
{"op":"mcm","clk":"11787585646","pt":1722461793743,"mc":[{"id":"1.231241311","rc":[{"batb":[[0,2.26,10],[1,2.24,29.8],[2,2.12,54.28]],"ltp":2.3,"tv":224.3,"id":26354922}]}]}
{"op":"mcm","clk":"11787585815","pt":1722461797140,"mc":[{"id":"1.231241311","rc":[{"batb":[[0,2.24,29.8],[1,2.12,54.28],[2,1.1,10000]],"ltp":2.3,"tv":224.3,"id":26354922}]}]}
{"op":"mcm","clk":"11787586133","pt":1722461802945,"mc":[{"id":"1.231241311","rc":[{"batb":[[0,2.26,10],[1,2.24,29.8],[2,2.12,54.28]],"ltp":2.3,"tv":224.3,"id":26354922}]}]}
{"op":"mcm","clk":"11787586322","pt":1722461806491,"mc":[{"id":"1.231241311","rc":[{"batb":[[0,2.24,29.8],[1,2.12,54.28],[2,1.1,10000]],"ltp":2.3,"tv":224.3,"id":26354922}]}]}
{"op":"mcm","clk":"11787586498","pt":1722461809675,"mc":[{"id":"1.231241311","rc":[{"batb":[[0,2.26,10],[1,2.24,29.8],[2,2.12,54.28]],"ltp":2.3,"tv":224.3,"id":26354922}]}]}
{"op":"mcm","clk":"11787586663","pt":1722461812866,"mc":[{"id":"1.231241311","rc":[{"batb":[[0,2.24,29.8],[1,2.12,54.28],[2,1.1,10000]],"ltp":2.3,"tv":224.3,"id":26354922}]}]}
{"op":"mcm","clk":"11787587743","pt":1722461832201,"mc":[{"id":"1.231241311","rc":[{"batb":[[0,2.26,10],[1,2.24,29.8],[2,2.12,54.28]],"ltp":2.3,"tv":224.3,"id":26354922}]}]}
{"op":"mcm","clk":"11787587914","pt":1722461835490,"mc":[{"id":"1.231241311","rc":[{"batb":[[0,2.24,29.8],[1,2.12,54.28],[2,1.1,10000]],"ltp":2.3,"tv":224.3,"id":26354922}]}]}
{"op":"mcm","clk":"11787588427","pt":1722461844382,"mc":[{"id":"1.231241311","rc":[{"batb":[[0,2.26,10],[1,2.24,29.8],[2,2.12,54.28]],"ltp":2.3,"tv":224.3,"id":26354922}]}]}
{"op":"mcm","clk":"11787588569","pt":1722461847815,"mc":[{"id":"1.231241311","rc":[{"batb":[[0,2.24,29.8],[1,2.12,54.28],[2,1.1,10000]],"ltp":2.3,"tv":224.3,"id":26354922}]}]}
{"op":"mcm","clk":"11787588841","pt":1722461853000,"mc":[{"id":"1.231241311","rc":[{"batb":[[0,2.26,10],[1,2.24,29.8],[2,2.12,54.28]],"ltp":2.3,"tv":224.3,"id":26354922}]}]}
{"op":"mcm","clk":"11787589001","pt":1722461856539,"mc":[{"id":"1.231241311","rc":[{"batb":[[0,2.24,29.8],[1,2.12,54.28],[2,1.1,10000]],"ltp":2.3,"tv":224.3,"id":26354922}]}]}
{"op":"mcm","clk":"11787589321","pt":1722461863112,"mc":[{"id":"1.231241311","rc":[{"batb":[[0,2.26,10],[1,2.24,29.8],[2,2.12,54.28]],"ltp":2.3,"tv":224.3,"id":26354922}]}]}
{"op":"mcm","clk":"11787589502","pt":1722461866423,"mc":[{"id":"1.231241311","rc":[{"batb":[[0,2.24,29.8],[1,2.12,54.28],[2,1.1,10000]],"ltp":2.3,"tv":224.3,"id":26354922}]}]}
{"op":"mcm","clk":"11787589770","pt":1722461872124,"mc":[{"id":"1.231241311","rc":[{"batb":[[0,2.26,10],[1,2.24,29.8],[2,2.12,54.28]],"ltp":2.3,"tv":224.3,"id":26354922}]}]}
{"op":"mcm","clk":"11787589901","pt":1722461875519,"mc":[{"id":"1.231241311","rc":[{"batb":[[0,2.24,29.8],[1,2.12,54.28],[2,1.1,10000]],"ltp":2.3,"tv":224.3,"id":26354922}]}]}
{"op":"mcm","clk":"11787590261","pt":1722461883324,"mc":[{"id":"1.231241311","rc":[{"batb":[[0,2.26,10],[1,2.24,29.8],[2,2.12,54.28]],"ltp":2.3,"tv":224.3,"id":26354922}]}]}
{"op":"mcm","clk":"11787590425","pt":1722461886621,"mc":[{"id":"1.231241311","rc":[{"batb":[[0,2.24,29.8],[1,2.12,54.28],[2,1.1,10000]],"ltp":2.3,"tv":224.3,"id":26354922}]}]}
{"op":"mcm","clk":"11787590674","pt":1722461891959,"mc":[{"id":"1.231241311","rc":[{"batb":[[0,2.26,10],[1,2.24,29.8],[2,2.12,54.28]],"ltp":2.3,"tv":224.3,"id":26354922}]}]}
{"op":"mcm","clk":"11787590844","pt":1722461895456,"mc":[{"id":"1.231241311","rc":[{"batb":[[0,2.24,29.8],[1,2.12,54.28],[2,1.1,10000]],"ltp":2.3,"tv":224.3,"id":26354922}]}]}
{"op":"mcm","clk":"11787591246","pt":1722461904188,"mc":[{"id":"1.231241311","rc":[{"batb":[[0,2.26,10],[1,2.24,29.8],[2,2.12,54.28]],"ltp":2.3,"tv":224.3,"id":26354922}]}]}
{"op":"mcm","clk":"11787591409","pt":1722461907582,"mc":[{"id":"1.231241311","rc":[{"batb":[[0,2.24,29.8],[1,2.12,54.28],[2,1.1,10000]],"ltp":2.3,"tv":224.3,"id":26354922}]}]}
{"op":"mcm","clk":"11787591510","pt":1722461909588,"mc":[{"id":"1.231241311","rc":[{"batb":[[0,1.75,4.59]],"ltp":1.75,"tv":993.6,"id":26354926}]}]}
{"op":"mcm","clk":"11787591795","pt":1722461915286,"mc":[{"id":"1.231241311","rc":[{"batb":[[0,2.26,10],[1,2.24,29.8],[2,2.12,54.28]],"ltp":2.3,"tv":224.3,"id":26354922}]}]}
{"op":"mcm","clk":"11787591944","pt":1722461918574,"mc":[{"id":"1.231241311","rc":[{"batb":[[0,2.24,29.8],[1,2.12,54.28],[2,1.1,10000]],"ltp":2.3,"tv":224.3,"id":26354922}]}]}
{"op":"mcm","clk":"11787592360","pt":1722461927096,"mc":[{"id":"1.231241311","rc":[{"batb":[[0,2.26,10],[1,2.24,29.8],[2,2.12,54.28]],"ltp":2.3,"tv":224.3,"id":26354922}]}]}
{"op":"mcm","clk":"11787592477","pt":1722461929507,"mc":[{"id":"1.231241311","rc":[{"trd":[[1.76,30.28]],"batb":[[0,1.75,3.59]],"batl":[[0,1.76,15.72]],"ltp":1.76,"tv":995.6,"id":26354926}],"tv":1219.9}]}
{"op":"mcm","clk":"11787592531","pt":1722461930486,"mc":[{"id":"1.231241311","rc":[{"batb":[[0,2.24,29.8],[1,2.12,54.28],[2,1.1,10000]],"ltp":2.3,"tv":224.3,"id":26354922}]}]}
{"op":"mcm","clk":"11787592961","pt":1722461938914,"mc":[{"id":"1.231241311","rc":[{"batb":[[0,2.26,10],[1,2.24,29.8],[2,2.12,54.28]],"ltp":2.3,"tv":224.3,"id":26354922}]}]}
{"op":"mcm","clk":"11787593165","pt":1722461942204,"mc":[{"id":"1.231241311","rc":[{"batb":[[0,2.24,29.8],[1,2.12,54.28],[2,1.1,10000]],"ltp":2.3,"tv":224.3,"id":26354922}]}]}
{"op":"mcm","clk":"11787593358","pt":1722461945702,"mc":[{"id":"1.231241311","rc":[{"batb":[[0,2.26,10],[1,2.24,29.8],[2,2.12,54.28]],"ltp":2.3,"tv":224.3,"id":26354922}]}]}
{"op":"mcm","clk":"11787593552","pt":1722461948987,"mc":[{"id":"1.231241311","rc":[{"batb":[[0,2.24,29.8],[1,2.12,54.28],[2,1.1,10000]],"ltp":2.3,"tv":224.3,"id":26354922}]}]}
{"op":"mcm","clk":"11787593798","pt":1722461953705,"mc":[{"id":"1.231241311","rc":[{"batb":[[0,2.26,10],[1,2.24,29.8],[2,2.12,54.28]],"ltp":2.3,"tv":224.3,"id":26354922}]}]}
{"op":"mcm","clk":"11787593969","pt":1722461957096,"mc":[{"id":"1.231241311","rc":[{"batb":[[0,2.24,29.8],[1,2.12,54.28],[2,1.1,10000]],"ltp":2.3,"tv":224.3,"id":26354922}]}]}
{"op":"mcm","clk":"11787594073","pt":1722461959297,"mc":[{"id":"1.231241311","rc":[{"batb":[[0,2.26,10],[1,2.24,29.8],[2,2.12,54.28]],"ltp":2.3,"tv":224.3,"id":26354922}]}]}
{"op":"mcm","clk":"11787594316","pt":1722461962837,"mc":[{"id":"1.231241311","rc":[{"batb":[[0,2.24,29.8],[1,2.12,54.28],[2,1.1,10000]],"ltp":2.3,"tv":224.3,"id":26354922}]}]}
{"op":"mcm","clk":"11787595155","pt":1722461978013,"mc":[{"id":"1.231241311","rc":[{"batb":[[0,2.26,10],[1,2.24,29.8],[2,2.12,54.28]],"ltp":2.3,"tv":224.3,"id":26354922}]}]}
{"op":"mcm","clk":"11787595339","pt":1722461981348,"mc":[{"id":"1.231241311","rc":[{"batb":[[0,2.24,29.8],[1,2.12,54.28],[2,1.1,10000]],"ltp":2.3,"tv":224.3,"id":26354922}]}]}
{"op":"mcm","clk":"11787595597","pt":1722461986540,"mc":[{"id":"1.231241311","rc":[{"batb":[[0,2.26,10],[1,2.24,29.8],[2,2.12,54.28]],"ltp":2.3,"tv":224.3,"id":26354922}]}]}
{"op":"mcm","clk":"11787595773","pt":1722461990034,"mc":[{"id":"1.231241311","rc":[{"batb":[[0,2.24,29.8],[1,2.12,54.28],[2,1.1,10000]],"ltp":2.3,"tv":224.3,"id":26354922}]}]}
{"op":"mcm","clk":"11787595935","pt":1722461993364,"mc":[{"id":"1.231241311","rc":[{"batb":[[0,2.26,10],[1,2.24,29.8],[2,2.12,54.28]],"ltp":2.3,"tv":224.3,"id":26354922}]}]}
{"op":"mcm","clk":"11787596116","pt":1722461996760,"mc":[{"id":"1.231241311","rc":[{"batb":[[0,2.24,29.8],[1,2.12,54.28],[2,1.1,10000]],"ltp":2.3,"tv":224.3,"id":26354922}]}]}
{"op":"mcm","clk":"11787596283","pt":1722461999941,"mc":[{"id":"1.231241311","rc":[{"batb":[[0,2.26,10],[1,2.24,29.8],[2,2.12,54.28]],"ltp":2.3,"tv":224.3,"id":26354922}]}]}
{"op":"mcm","clk":"11787596468","pt":1722462003254,"mc":[{"id":"1.231241311","rc":[{"batb":[[0,2.24,29.8],[1,2.12,54.28],[2,1.1,10000]],"ltp":2.3,"tv":224.3,"id":26354922}]}]}
{"op":"mcm","clk":"11787596778","pt":1722462009187,"mc":[{"id":"1.231241311","rc":[{"batb":[[0,2.26,10],[1,2.24,29.8],[2,2.12,54.28]],"ltp":2.3,"tv":224.3,"id":26354922}]}]}
{"op":"mcm","clk":"11787596959","pt":1722462012775,"mc":[{"id":"1.231241311","rc":[{"batb":[[0,2.24,29.8],[1,2.12,54.28],[2,1.1,10000]],"ltp":2.3,"tv":224.3,"id":26354922}]}]}
{"op":"mcm","clk":"11787597115","pt":1722462016161,"mc":[{"id":"1.231241311","rc":[{"batb":[[0,2.26,10],[1,2.24,29.8],[2,2.12,54.28]],"ltp":2.3,"tv":224.3,"id":26354922}]}]}
{"op":"mcm","clk":"11787597305","pt":1722462019665,"mc":[{"id":"1.231241311","rc":[{"batb":[[0,2.24,29.8],[1,2.12,54.28],[2,1.1,10000]],"ltp":2.3,"tv":224.3,"id":26354922}]}]}
{"op":"mcm","clk":"11787597507","pt":1722462023872,"mc":[{"id":"1.231241311","rc":[{"batb":[[0,2.26,10],[1,2.24,29.8],[2,2.12,54.28]],"ltp":2.3,"tv":224.3,"id":26354922}]}]}
{"op":"mcm","clk":"11787597678","pt":1722462027174,"mc":[{"id":"1.231241311","rc":[{"batb":[[0,2.24,29.8],[1,2.12,54.28],[2,1.1,10000]],"ltp":2.3,"tv":224.3,"id":26354922}]}]}
{"op":"mcm","clk":"11787597813","pt":1722462029579,"mc":[{"id":"1.231241311","rc":[{"batb":[[0,2.26,10],[1,2.24,29.8],[2,2.12,54.28]],"ltp":2.3,"tv":224.3,"id":26354922}]}]}
{"op":"mcm","clk":"11787597992","pt":1722462032871,"mc":[{"id":"1.231241311","rc":[{"batb":[[0,2.24,29.8],[1,2.12,54.28],[2,1.1,10000]],"ltp":2.3,"tv":224.3,"id":26354922}]}]}
{"op":"mcm","clk":"11787598125","pt":1722462035592,"mc":[{"id":"1.231241311","rc":[{"batb":[[0,2.26,10],[1,2.24,29.8],[2,2.12,54.28]],"ltp":2.3,"tv":224.3,"id":26354922}]}]}
{"op":"mcm","clk":"11787598289","pt":1722462038990,"mc":[{"id":"1.231241311","rc":[{"batb":[[0,2.24,29.8],[1,2.12,54.28],[2,1.1,10000]],"ltp":2.3,"tv":224.3,"id":26354922}]}]}
{"op":"mcm","clk":"11787598556","pt":1722462044073,"mc":[{"id":"1.231241311","rc":[{"batb":[[0,2.26,10],[1,2.24,29.8],[2,2.12,54.28]],"ltp":2.3,"tv":224.3,"id":26354922}]}]}
{"op":"mcm","clk":"11787598742","pt":1722462047468,"mc":[{"id":"1.231241311","rc":[{"batb":[[0,2.24,29.8],[1,2.12,54.28],[2,1.1,10000]],"ltp":2.3,"tv":224.3,"id":26354922}]}]}
{"op":"mcm","clk":"11787598983","pt":1722462052397,"mc":[{"id":"1.231241311","rc":[{"batb":[[0,2.26,10],[1,2.24,29.8],[2,2.12,54.28]],"ltp":2.3,"tv":224.3,"id":26354922}]}]}
{"op":"mcm","clk":"11787599150","pt":1722462055881,"mc":[{"id":"1.231241311","rc":[{"batb":[[0,2.24,29.8],[1,2.12,54.28],[2,1.1,10000]],"ltp":2.3,"tv":224.3,"id":26354922}]}]}
{"op":"mcm","clk":"11787599352","pt":1722462058710,"mc":[{"id":"1.231241311","rc":[{"batb":[[0,2.26,10],[1,2.24,29.8],[2,2.12,54.28]],"ltp":2.3,"tv":224.3,"id":26354922}]}]}
{"op":"mcm","clk":"11787599516","pt":1722462062104,"mc":[{"id":"1.231241311","rc":[{"batb":[[0,2.24,29.8],[1,2.12,54.28],[2,1.1,10000]],"ltp":2.3,"tv":224.3,"id":26354922}]}]}
{"op":"mcm","clk":"11787599631","pt":1722462064518,"mc":[{"id":"1.231241311","rc":[{"batb":[[0,2.26,10],[1,2.24,29.8],[2,2.12,54.28]],"ltp":2.3,"tv":224.3,"id":26354922}]}]}
{"op":"mcm","clk":"11787599900","pt":1722462067914,"mc":[{"id":"1.231241311","rc":[{"batb":[[0,2.24,29.8],[1,2.12,54.28],[2,1.1,10000]],"ltp":2.3,"tv":224.3,"id":26354922}]}]}
{"op":"mcm","clk":"11787600129","pt":1722462072421,"mc":[{"id":"1.231241311","rc":[{"batb":[[0,2.26,10],[1,2.24,29.8],[2,2.12,54.28]],"ltp":2.3,"tv":224.3,"id":26354922}]}]}
{"op":"mcm","clk":"11787600300","pt":1722462075806,"mc":[{"id":"1.231241311","rc":[{"batb":[[0,2.24,29.8],[1,2.12,54.28],[2,1.1,10000]],"ltp":2.3,"tv":224.3,"id":26354922}]}]}
{"op":"mcm","clk":"11787600507","pt":1722462079817,"mc":[{"id":"1.231241311","rc":[{"batb":[[0,2.26,10],[1,2.24,29.8],[2,2.12,54.28]],"ltp":2.3,"tv":224.3,"id":26354922}]}]}
{"op":"mcm","clk":"11787600669","pt":1722462083107,"mc":[{"id":"1.231241311","rc":[{"batb":[[0,2.24,29.8],[1,2.12,54.28],[2,1.1,10000]],"ltp":2.3,"tv":224.3,"id":26354922}]}]}
{"op":"mcm","clk":"11787600952","pt":1722462088800,"mc":[{"id":"1.231241311","rc":[{"batb":[[0,2.26,10],[1,2.24,29.8],[2,2.12,54.28]],"ltp":2.3,"tv":224.3,"id":26354922}]}]}
{"op":"mcm","clk":"11787601123","pt":1722462092135,"mc":[{"id":"1.231241311","rc":[{"batb":[[0,2.24,29.8],[1,2.12,54.28],[2,1.1,10000]],"ltp":2.3,"tv":224.3,"id":26354922}]}]}
{"op":"mcm","clk":"11787601255","pt":1722462094342,"mc":[{"id":"1.231241311","rc":[{"batb":[[0,2.26,10],[1,2.24,29.8],[2,2.12,54.28]],"ltp":2.3,"tv":224.3,"id":26354922}]}]}
{"op":"mcm","clk":"11787601478","pt":1722462097733,"mc":[{"id":"1.231241311","rc":[{"batb":[[0,2.24,29.8],[1,2.12,54.28],[2,1.1,10000]],"ltp":2.3,"tv":224.3,"id":26354922}]}]}
{"op":"mcm","clk":"11787601612","pt":1722462100053,"mc":[{"id":"1.231241311","rc":[{"batb":[[0,2.26,10],[1,2.24,29.8],[2,2.12,54.28]],"ltp":2.3,"tv":224.3,"id":26354922}]}]}
{"op":"mcm","clk":"11787601798","pt":1722462103463,"mc":[{"id":"1.231241311","rc":[{"batb":[[0,2.24,29.8],[1,2.12,54.28],[2,1.1,10000]],"ltp":2.3,"tv":224.3,"id":26354922}]}]}
{"op":"mcm","clk":"11787601990","pt":1722462106532,"mc":[{"id":"1.231241311","rc":[{"batb":[[0,2.26,10],[1,2.24,29.8],[2,2.12,54.28]],"ltp":2.3,"tv":224.3,"id":26354922}]}]}
{"op":"mcm","clk":"11787602178","pt":1722462109922,"mc":[{"id":"1.231241311","rc":[{"batb":[[0,2.24,29.8],[1,2.12,54.28],[2,1.1,10000]],"ltp":2.3,"tv":224.3,"id":26354922}]}]}
{"op":"mcm","clk":"11787602409","pt":1722462114448,"mc":[{"id":"1.231241311","rc":[{"batb":[[0,2.26,10],[1,2.24,29.8],[2,2.12,54.28]],"ltp":2.3,"tv":224.3,"id":26354922}]}]}
{"op":"mcm","clk":"11787602590","pt":1722462117839,"mc":[{"id":"1.231241311","rc":[{"batb":[[0,2.24,29.8],[1,2.12,54.28],[2,1.1,10000]],"ltp":2.3,"tv":224.3,"id":26354922}]}]}
{"op":"mcm","clk":"11787602788","pt":1722462120362,"mc":[{"id":"1.231241311","rc":[{"batb":[[0,2.26,10],[1,2.24,29.8],[2,2.12,54.28]],"ltp":2.3,"tv":224.3,"id":26354922}]}]}
{"op":"mcm","clk":"11787602996","pt":1722462123767,"mc":[{"id":"1.231241311","rc":[{"batb":[[0,2.24,29.8],[1,2.12,54.28],[2,1.1,10000]],"ltp":2.3,"tv":224.3,"id":26354922}]}]}
{"op":"mcm","clk":"11787603110","pt":1722462125873,"mc":[{"id":"1.231241311","rc":[{"batb":[[0,2.26,10],[1,2.24,29.8],[2,2.12,54.28]],"ltp":2.3,"tv":224.3,"id":26354922}]}]}
{"op":"mcm","clk":"11787603290","pt":1722462129263,"mc":[{"id":"1.231241311","rc":[{"batb":[[0,2.24,29.8],[1,2.12,54.28],[2,1.1,10000]],"ltp":2.3,"tv":224.3,"id":26354922}]}]}
{"op":"mcm","clk":"11787603488","pt":1722462132758,"mc":[{"id":"1.231241311","rc":[{"batb":[[0,2.26,10],[1,2.24,29.8],[2,2.12,54.28]],"ltp":2.3,"tv":224.3,"id":26354922}]}]}
{"op":"mcm","clk":"11787603685","pt":1722462136051,"mc":[{"id":"1.231241311","rc":[{"batb":[[0,2.24,29.8],[1,2.12,54.28],[2,1.1,10000]],"ltp":2.3,"tv":224.3,"id":26354922}]}]}
{"op":"mcm","clk":"11787603874","pt":1722462139384,"mc":[{"id":"1.231241311","rc":[{"batb":[[0,2.26,10],[1,2.24,29.8],[2,2.12,54.28]],"ltp":2.3,"tv":224.3,"id":26354922}]}]}
{"op":"mcm","clk":"11787604082","pt":1722462142785,"mc":[{"id":"1.231241311","rc":[{"batb":[[0,2.24,29.8],[1,2.12,54.28],[2,1.1,10000]],"ltp":2.3,"tv":224.3,"id":26354922}]}]}
{"op":"mcm","clk":"11787604211","pt":1722462145048,"mc":[{"id":"1.231241311","rc":[{"batb":[[0,2.26,10],[1,2.24,29.8],[2,2.12,54.28]],"ltp":2.3,"tv":224.3,"id":26354922}]}]}
{"op":"mcm","clk":"11787604404","pt":1722462148485,"mc":[{"id":"1.231241311","rc":[{"batb":[[0,2.24,29.8],[1,2.12,54.28],[2,1.1,10000]],"ltp":2.3,"tv":224.3,"id":26354922}]}]}
{"op":"mcm","clk":"11787604755","pt":1722462155005,"mc":[{"id":"1.231241311","rc":[{"batb":[[0,2.26,10],[1,2.24,29.8],[2,2.12,54.28]],"ltp":2.3,"tv":224.3,"id":26354922}]}]}
{"op":"mcm","clk":"11787604952","pt":1722462158508,"mc":[{"id":"1.231241311","rc":[{"batb":[[0,2.24,29.8],[1,2.12,54.28],[2,1.1,10000]],"ltp":2.3,"tv":224.3,"id":26354922}]}]}
{"op":"mcm","clk":"11787605472","pt":1722462169889,"mc":[{"id":"1.231241311","rc":[{"batb":[[0,2.26,10],[1,2.24,29.8],[2,2.12,54.28]],"ltp":2.3,"tv":224.3,"id":26354922}]}]}
{"op":"mcm","clk":"11787605654","pt":1722462173586,"mc":[{"id":"1.231241311","rc":[{"batb":[[0,2.24,29.8],[1,2.12,54.28],[2,1.1,10000]],"ltp":2.3,"tv":224.3,"id":26354922}]}]}
{"op":"mcm","clk":"11787613277","pt":1722462176202,"mc":[{"id":"1.231241311","rc":[{"batb":[[0,2.26,10],[1,2.24,29.8],[2,2.12,54.28]],"ltp":2.3,"tv":224.3,"id":26354922}]}]}
{"op":"mcm","clk":"11787613431","pt":1722462179586,"mc":[{"id":"1.231241311","rc":[{"batb":[[0,2.24,29.8],[1,2.12,54.28],[2,1.1,10000]],"ltp":2.3,"tv":224.3,"id":26354922}]}]}
{"op":"mcm","clk":"11787613689","pt":1722462185025,"mc":[{"id":"1.231241311","rc":[{"batb":[[0,2.26,10],[1,2.24,29.8],[2,2.12,54.28]],"ltp":2.3,"tv":224.3,"id":26354922}]}]}
{"op":"mcm","clk":"11787613898","pt":1722462189197,"mc":[{"id":"1.231241311","rc":[{"batb":[[0,2.24,29.8],[1,2.12,54.28],[2,1.1,10000]],"ltp":2.3,"tv":224.3,"id":26354922}]}]}
{"op":"mcm","clk":"11787614155","pt":1722462194334,"mc":[{"id":"1.231241311","rc":[{"batb":[[0,2.26,10],[1,2.24,29.8],[2,2.12,54.28]],"ltp":2.3,"tv":224.3,"id":26354922}]}]}
{"op":"mcm","clk":"11787614288","pt":1722462197718,"mc":[{"id":"1.231241311","rc":[{"batb":[[0,2.24,29.8],[1,2.12,54.28],[2,1.1,10000]],"ltp":2.3,"tv":224.3,"id":26354922}]}]}
{"op":"mcm","clk":"11787614609","pt":1722462203824,"mc":[{"id":"1.231241311","rc":[{"batb":[[0,2.26,10],[1,2.24,29.8],[2,2.12,54.28]],"ltp":2.3,"tv":224.3,"id":26354922}]}]}
{"op":"mcm","clk":"11787614777","pt":1722462207212,"mc":[{"id":"1.231241311","rc":[{"batb":[[0,2.24,29.8],[1,2.12,54.28],[2,1.1,10000]],"ltp":2.3,"tv":224.3,"id":26354922}]}]}
{"op":"mcm","clk":"11787614933","pt":1722462210034,"mc":[{"id":"1.231241311","rc":[{"batb":[[0,2.26,10],[1,2.24,29.8],[2,2.12,54.28]],"ltp":2.3,"tv":224.3,"id":26354922}]}]}
{"op":"mcm","clk":"11787615097","pt":1722462213325,"mc":[{"id":"1.231241311","rc":[{"batb":[[0,2.24,29.8],[1,2.12,54.28],[2,1.1,10000]],"ltp":2.3,"tv":224.3,"id":26354922}]}]}
{"op":"mcm","clk":"11787615243","pt":1722462215839,"mc":[{"id":"1.231241311","rc":[{"batb":[[0,2.26,10],[1,2.24,29.8],[2,2.12,54.28]],"ltp":2.3,"tv":224.3,"id":26354922}]}]}
{"op":"mcm","clk":"11787615406","pt":1722462219129,"mc":[{"id":"1.231241311","rc":[{"batb":[[0,2.24,29.8],[1,2.12,54.28],[2,1.1,10000]],"ltp":2.3,"tv":224.3,"id":26354922}]}]}
{"op":"mcm","clk":"11787615446","pt":1722462219846,"mc":[{"id":"1.231241311","rc":[{"trd":[[1.75,22.37]],"batb":[[0,1.74,200.59],[1,1.73,58.46],[2,1.72,15.67]],"ltp":1.75,"tv":999.19,"id":26354926},{"trd":[[2.34,46.56]],"batb":[[0,2.34,77.18],[1,2.24,29.8],[2,2.12,54.28]],"batl":[[0,6,1.56],[1,12,1.56],[2,12,0]],"ltp":2.34,"tv":270.86,"id":26354922}],"tv":1270.05}]}
{"op":"mcm","clk":"11787615507","pt":1722462221021,"mc":[{"id":"1.231241311","rc":[{"batl":[[0,1.75,9.98],[1,1.76,15.72],[2,1.8,112.5]],"ltp":1.75,"tv":999.19,"id":26354926},{"batb":[[0,2.34,97.12]],"ltp":2.34,"tv":270.86,"id":26354922}]}]}
{"op":"mcm","clk":"11787615600","pt":1722462223025,"mc":[{"id":"1.231241311","rc":[{"trd":[[1.74,190.62]],"batb":[[0,1.74,82.35]],"batl":[[0,1.75,14.54]],"ltp":1.74,"tv":1117.42,"id":26354926},{"trd":[[2.36,134.65]],"batb":[[0,2.24,29.8],[1,2.12,54.28],[2,1.1,10000]],"ltp":2.36,"tv":358.04,"id":26354922}],"tv":1475.47}]}
{"op":"mcm","clk":"11787615673","pt":1722462224728,"mc":[{"id":"1.231241311","rc":[{"batb":[[0,2.26,10],[1,2.24,29.8],[2,2.12,54.28]],"ltp":2.36,"tv":358.04,"id":26354922}]}]}
{"op":"mcm","clk":"11787615847","pt":1722462228262,"mc":[{"id":"1.231241311","rc":[{"batb":[[0,2.24,29.8],[1,2.12,54.28],[2,1.1,10000]],"ltp":2.36,"tv":358.04,"id":26354922}]}]}
{"op":"mcm","clk":"11787615964","pt":1722462230833,"mc":[{"id":"1.231241311","rc":[{"trd":[[1.74,245.96]],"batb":[[0,1.74,27.01]],"ltp":1.74,"tv":1172.76,"id":26354926},{"trd":[[2.36,175.45]],"batb":[[0,2.32,12.16],[1,2.26,10],[2,2.24,29.8]],"ltp":2.36,"tv":398.84,"id":26354922}],"tv":1571.61}]}
{"op":"mcm","clk":"11787616113","pt":1722462233863,"mc":[{"id":"1.231241311","rc":[{"batb":[[1,2.12,54.28],[2,1.1,10000]],"ltp":2.36,"tv":398.84,"id":26354922}]}]}
{"op":"mcm","clk":"11787616313","pt":1722462238076,"mc":[{"id":"1.231241311","rc":[{"batb":[[0,2.34,10],[1,2.32,12.16],[2,2.12,54.28]],"ltp":2.36,"tv":398.84,"id":26354922}]}]}
{"op":"mcm","clk":"11787616548","pt":1722462242147,"mc":[{"id":"1.231241311","rc":[{"batb":[[0,2.32,12.16],[1,2.12,54.28],[2,1.1,10000]],"ltp":2.36,"tv":398.84,"id":26354922}]}]}
{"op":"mcm","clk":"11787616830","pt":1722462247452,"mc":[{"id":"1.231241311","rc":[{"batb":[[0,2.34,10],[1,2.32,12.16],[2,2.12,54.28]],"ltp":2.36,"tv":398.84,"id":26354922}]}]}
{"op":"mcm","clk":"11787617026","pt":1722462251089,"mc":[{"id":"1.231241311","rc":[{"batb":[[0,2.32,12.16],[1,2.12,54.28],[2,1.1,10000]],"ltp":2.36,"tv":398.84,"id":26354922}]}]}
{"op":"mcm","clk":"11787617283","pt":1722462255661,"mc":[{"id":"1.231241311","rc":[{"batb":[[0,2.34,10],[1,2.32,12.16],[2,2.12,54.28]],"ltp":2.36,"tv":398.84,"id":26354922}]}]}
{"op":"mcm","clk":"11787617468","pt":1722462258990,"mc":[{"id":"1.231241311","rc":[{"batb":[[0,2.32,12.16],[1,2.12,54.28],[2,1.1,10000]],"ltp":2.36,"tv":398.84,"id":26354922}]}]}
{"op":"mcm","clk":"11787617700","pt":1722462263467,"mc":[{"id":"1.231241311","rc":[{"batb":[[0,2.34,10],[1,2.32,12.16],[2,2.12,54.28]],"ltp":2.36,"tv":398.84,"id":26354922}]}]}
{"op":"mcm","clk":"11787617880","pt":1722462267004,"mc":[{"id":"1.231241311","rc":[{"batb":[[0,2.32,12.16],[1,2.12,54.28],[2,1.1,10000]],"ltp":2.36,"tv":398.84,"id":26354922}]}]}
{"op":"mcm","clk":"11787618068","pt":1722462271206,"mc":[{"id":"1.231241311","rc":[{"trd":[[1.73,722.23],[1.74,272.97]],"batb":[[0,1.73,56.23],[1,1.72,15.67],[2,1.68,112.5]],"ltp":1.73,"tv":1202.0,"id":26354926},{"trd":[[2.36,195.36],[2.38,1.62]],"batb":[[0,2.34,10],[1,2.32,12.16],[2,2.12,54.28]],"ltp":2.38,"tv":420.37,"id":26354922}],"tv":1622.38}]}
{"op":"mcm","clk":"11787618204","pt":1722462273876,"mc":[{"id":"1.231241311","rc":[{"batb":[[0,2.32,12.16],[1,2.12,54.28],[2,1.1,10000]],"ltp":2.38,"tv":420.37,"id":26354922}]}]}
{"op":"mcm","clk":"11787618532","pt":1722462280516,"mc":[{"id":"1.231241311","rc":[{"batb":[[0,2.34,10],[1,2.32,12.16],[2,2.12,54.28]],"ltp":2.38,"tv":420.37,"id":26354922}]}]}
{"op":"mcm","clk":"11787618689","pt":1722462284015,"mc":[{"id":"1.231241311","rc":[{"batb":[[0,2.32,12.16],[1,2.12,54.28],[2,1.1,10000]],"ltp":2.38,"tv":420.37,"id":26354922}]}]}
{"op":"mcm","clk":"11787619101","pt":1722462292007,"mc":[{"id":"1.231241311","rc":[{"batb":[[0,2.34,10],[1,2.32,12.16],[2,2.12,54.28]],"ltp":2.38,"tv":420.37,"id":26354922}]}]}
{"op":"mcm","clk":"11787619329","pt":1722462295501,"mc":[{"id":"1.231241311","rc":[{"batb":[[0,2.32,12.16],[1,2.12,54.28],[2,1.1,10000]],"ltp":2.38,"tv":420.37,"id":26354922}]}]}
{"op":"mcm","clk":"11787619480","pt":1722462298116,"mc":[{"id":"1.231241311","rc":[{"batb":[[0,2.34,10],[1,2.32,12.16],[2,2.12,54.28]],"ltp":2.38,"tv":420.37,"id":26354922}]}]}
{"op":"mcm","clk":"11787619671","pt":1722462301414,"mc":[{"id":"1.231241311","rc":[{"batb":[[0,2.32,12.16],[1,2.12,54.28],[2,1.1,10000]],"ltp":2.38,"tv":420.37,"id":26354922}]}]}
{"op":"mcm","clk":"11787619769","pt":1722462303014,"mc":[{"id":"1.231241311","rc":[{"batb":[[0,2.34,7.88],[1,2.32,12.16],[2,2.12,54.28]],"ltp":2.38,"tv":420.37,"id":26354922}]}]}
{"op":"mcm","clk":"11787619826","pt":1722462304140,"mc":[{"id":"1.231241311","rc":[{"batb":[[0,2.36,10],[1,2.34,7.88],[2,2.32,12.16]],"ltp":2.38,"tv":420.37,"id":26354922}]}]}
{"op":"mcm","clk":"11787620003","pt":1722462307429,"mc":[{"id":"1.231241311","rc":[{"batb":[[0,2.34,7.88],[1,2.32,12.16],[2,2.12,54.28]],"ltp":2.38,"tv":420.37,"id":26354922}]}]}
{"op":"mcm","clk":"11787620181","pt":1722462310303,"mc":[{"id":"1.231241311","rc":[{"batb":[[0,2.36,10],[1,2.34,7.88],[2,2.32,12.16]],"ltp":2.38,"tv":420.37,"id":26354922}]}]}
{"op":"mcm","clk":"11787620365","pt":1722462313902,"mc":[{"id":"1.231241311","rc":[{"batb":[[0,2.34,7.88],[1,2.32,12.16],[2,2.12,54.28]],"ltp":2.38,"tv":420.37,"id":26354922}]}]}
{"op":"mcm","clk":"11787620472","pt":1722462316418,"mc":[{"id":"1.231241311","rc":[{"batb":[[0,2.36,10],[1,2.34,7.88],[2,2.32,12.16]],"ltp":2.38,"tv":420.37,"id":26354922}]}]}
{"op":"mcm","clk":"11787620617","pt":1722462319747,"mc":[{"id":"1.231241311","rc":[{"batb":[[0,2.34,7.88],[1,2.32,12.16],[2,2.12,54.28]],"ltp":2.38,"tv":420.37,"id":26354922}]}]}
{"op":"mcm","clk":"11787620798","pt":1722462323446,"mc":[{"id":"1.231241311","rc":[{"batb":[[0,2.36,10],[1,2.34,7.88],[2,2.32,12.16]],"ltp":2.38,"tv":420.37,"id":26354922}]}]}
{"op":"mcm","clk":"11787620933","pt":1722462326738,"mc":[{"id":"1.231241311","rc":[{"batb":[[0,2.34,7.88],[1,2.32,12.16],[2,2.12,54.28]],"ltp":2.38,"tv":420.37,"id":26354922}]}]}
{"op":"mcm","clk":"11787621058","pt":1722462329045,"mc":[{"id":"1.231241311","rc":[{"batb":[[0,2.36,10],[1,2.34,7.88],[2,2.32,12.16]],"ltp":2.38,"tv":420.37,"id":26354922}]}]}
{"op":"mcm","clk":"11787621211","pt":1722462332538,"mc":[{"id":"1.231241311","rc":[{"batb":[[0,2.34,7.88],[1,2.32,12.16],[2,2.12,54.28]],"ltp":2.38,"tv":420.37,"id":26354922}]}]}
{"op":"mcm","clk":"11787621492","pt":1722462338549,"mc":[{"id":"1.231241311","rc":[{"batb":[[0,2.36,10],[1,2.34,7.88],[2,2.32,12.16]],"ltp":2.38,"tv":420.37,"id":26354922}]}]}
{"op":"mcm","clk":"11787621684","pt":1722462342143,"mc":[{"id":"1.231241311","rc":[{"batb":[[0,2.34,7.88],[1,2.32,12.16],[2,2.12,54.28]],"ltp":2.38,"tv":420.37,"id":26354922}]}]}
{"op":"mcm","clk":"11787621800","pt":1722462344348,"mc":[{"id":"1.231241311","rc":[{"batb":[[0,2.36,10],[1,2.34,7.88],[2,2.32,12.16]],"ltp":2.38,"tv":420.37,"id":26354922}]}]}
{"op":"mcm","clk":"11787621974","pt":1722462348061,"mc":[{"id":"1.231241311","rc":[{"batb":[[0,2.34,7.88],[1,2.32,12.16],[2,2.12,54.28]],"ltp":2.38,"tv":420.37,"id":26354922}]}]}
{"op":"mcm","clk":"11787622638","pt":1722462363365,"mc":[{"id":"1.231241311","rc":[{"batb":[[0,2.36,10],[1,2.34,7.88],[2,2.32,12.16]],"ltp":2.38,"tv":420.37,"id":26354922}]}]}
{"op":"mcm","clk":"11787622847","pt":1722462366976,"mc":[{"id":"1.231241311","rc":[{"batb":[[0,2.34,7.88],[1,2.32,12.16],[2,2.12,54.28]],"ltp":2.38,"tv":420.37,"id":26354922}]}]}
{"op":"mcm","clk":"11787623010","pt":1722462369888,"mc":[{"id":"1.231241311","rc":[{"batb":[[0,2.36,10],[1,2.34,7.88],[2,2.32,12.16]],"ltp":2.38,"tv":420.37,"id":26354922}]}]}
{"op":"mcm","clk":"11787623189","pt":1722462373383,"mc":[{"id":"1.231241311","rc":[{"batb":[[0,2.34,7.88],[1,2.32,12.16],[2,2.12,54.28]],"ltp":2.38,"tv":420.37,"id":26354922}]}]}
{"op":"mcm","clk":"11787623327","pt":1722462375696,"mc":[{"id":"1.231241311","rc":[{"batb":[[0,2.36,10],[1,2.34,7.88],[2,2.32,12.16]],"ltp":2.38,"tv":420.37,"id":26354922}]}]}
{"op":"mcm","clk":"11787623490","pt":1722462378985,"mc":[{"id":"1.231241311","rc":[{"batb":[[0,2.34,7.88],[1,2.32,12.16],[2,2.12,54.28]],"ltp":2.38,"tv":420.37,"id":26354922}]}]}
{"op":"mcm","clk":"11787623866","pt":1722462386293,"mc":[{"id":"1.231241311","rc":[{"batb":[[0,2.36,10],[1,2.34,7.88],[2,2.32,12.16]],"ltp":2.38,"tv":420.37,"id":26354922}]}]}
{"op":"mcm","clk":"11787624010","pt":1722462389727,"mc":[{"id":"1.231241311","rc":[{"batb":[[0,2.34,7.88],[1,2.32,12.16],[2,2.12,54.28]],"ltp":2.38,"tv":420.37,"id":26354922}]}]}
{"op":"mcm","clk":"11787624629","pt":1722462400936,"mc":[{"id":"1.231241311","rc":[{"batb":[[0,2.36,10],[1,2.34,7.88],[2,2.32,12.16]],"ltp":2.38,"tv":420.37,"id":26354922}]}]}
{"op":"mcm","clk":"11787624786","pt":1722462404329,"mc":[{"id":"1.231241311","rc":[{"batb":[[0,2.34,7.88],[1,2.32,12.16],[2,2.12,54.28]],"ltp":2.38,"tv":420.37,"id":26354922}]}]}
{"op":"mcm","clk":"11787625105","pt":1722462410753,"mc":[{"id":"1.231241311","rc":[{"batb":[[0,2.36,10],[1,2.34,7.88],[2,2.32,12.16]],"ltp":2.38,"tv":420.37,"id":26354922}]}]}
{"op":"mcm","clk":"11787625269","pt":1722462414051,"mc":[{"id":"1.231241311","rc":[{"batb":[[0,2.34,7.88],[1,2.32,12.16],[2,2.12,54.28]],"ltp":2.38,"tv":420.37,"id":26354922}]}]}
{"op":"mcm","clk":"11787626672","pt":1722462438859,"mc":[{"id":"1.231241311","rc":[{"batb":[[0,2.36,10],[1,2.34,7.88],[2,2.32,12.16]],"ltp":2.38,"tv":420.37,"id":26354922}]}]}
{"op":"mcm","clk":"11787626841","pt":1722462442145,"mc":[{"id":"1.231241311","rc":[{"batb":[[0,2.34,7.88],[1,2.32,12.16],[2,2.12,54.28]],"ltp":2.38,"tv":420.37,"id":26354922}]}]}
{"op":"mcm","clk":"11787627258","pt":1722462449957,"mc":[{"id":"1.231241311","rc":[{"batl":[[2,1.79,225]],"ltp":1.73,"tv":1202.0,"id":26354926},{"batb":[[0,2.36,10],[1,2.34,7.88],[2,2.32,12.16]],"ltp":2.38,"tv":420.37,"id":26354922}]}]}
{"op":"mcm","clk":"11787627415","pt":1722462453348,"mc":[{"id":"1.231241311","rc":[{"batb":[[0,2.34,7.88],[1,2.32,12.16],[2,2.12,54.28]],"ltp":2.38,"tv":420.37,"id":26354922}]}]}
{"op":"mcm","clk":"11787627672","pt":1722462458390,"mc":[{"id":"1.231241311","rc":[{"batb":[[0,2.36,10],[1,2.34,7.88],[2,2.32,12.16]],"ltp":2.38,"tv":420.37,"id":26354922}]}]}
{"op":"mcm","clk":"11787627855","pt":1722462461777,"mc":[{"id":"1.231241311","rc":[{"batb":[[0,2.34,7.88],[1,2.32,12.16],[2,2.12,54.28]],"ltp":2.38,"tv":420.37,"id":26354922}]}]}
{"op":"mcm","clk":"11787628071","pt":1722462465991,"mc":[{"id":"1.231241311","rc":[{"batb":[[0,2.36,10],[1,2.34,7.88],[2,2.32,12.16]],"ltp":2.38,"tv":420.37,"id":26354922}]}]}
{"op":"mcm","clk":"11787628255","pt":1722462469484,"mc":[{"id":"1.231241311","rc":[{"batb":[[0,2.34,7.88],[1,2.32,12.16],[2,2.12,54.28]],"ltp":2.38,"tv":420.37,"id":26354922}]}]}
{"op":"mcm","clk":"11787628438","pt":1722462472264,"mc":[{"id":"1.231241311","rc":[{"batb":[[0,2.36,10],[1,2.34,7.88],[2,2.32,12.16]],"ltp":2.38,"tv":420.37,"id":26354922}]}]}
{"op":"mcm","clk":"11787628616","pt":1722462475608,"mc":[{"id":"1.231241311","rc":[{"batb":[[0,2.34,7.88],[1,2.32,12.16],[2,2.12,54.28]],"ltp":2.38,"tv":420.37,"id":26354922}]}]}
{"op":"mcm","clk":"11787628754","pt":1722462477986,"mc":[{"id":"1.231241311","rc":[{"batb":[[0,2.36,10],[1,2.34,7.88],[2,2.32,12.16]],"ltp":2.38,"tv":420.37,"id":26354922}]}]}
{"op":"mcm","clk":"11787628956","pt":1722462481480,"mc":[{"id":"1.231241311","rc":[{"batb":[[0,2.34,7.88],[1,2.32,12.16],[2,2.12,54.28]],"ltp":2.38,"tv":420.37,"id":26354922}]}]}
{"op":"mcm","clk":"11787629344","pt":1722462488383,"mc":[{"id":"1.231241311","rc":[{"batb":[[0,2.36,10],[1,2.34,7.88],[2,2.32,12.16]],"ltp":2.38,"tv":420.37,"id":26354922}]}]}
{"op":"mcm","clk":"11787629516","pt":1722462491927,"mc":[{"id":"1.231241311","rc":[{"batb":[[0,2.34,7.88],[1,2.32,12.16],[2,2.12,54.28]],"ltp":2.38,"tv":420.37,"id":26354922}]}]}
{"op":"mcm","clk":"11787629764","pt":1722462496820,"mc":[{"id":"1.231241311","rc":[{"batb":[[0,2.36,10],[1,2.34,7.88],[2,2.32,12.16]],"ltp":2.38,"tv":420.37,"id":26354922}]}]}
{"op":"mcm","clk":"11787629970","pt":1722462500519,"mc":[{"id":"1.231241311","rc":[{"batb":[[0,2.34,7.88],[1,2.32,12.16],[2,2.12,54.28]],"ltp":2.38,"tv":420.37,"id":26354922}]}]}
{"op":"mcm","clk":"11787630403","pt":1722462507420,"mc":[{"id":"1.231241311","rc":[{"batb":[[0,2.36,10],[1,2.34,7.88],[2,2.32,12.16]],"ltp":2.38,"tv":420.37,"id":26354922}]}]}
{"op":"mcm","clk":"11787630582","pt":1722462510853,"mc":[{"id":"1.231241311","rc":[{"batb":[[0,2.34,7.88],[1,2.32,12.16],[2,2.12,54.28]],"ltp":2.38,"tv":420.37,"id":26354922}]}]}
{"op":"mcm","clk":"11787632057","pt":1722462540671,"mc":[{"id":"1.231241311","rc":[{"batb":[[0,2.36,10],[1,2.34,7.88],[2,2.32,12.16]],"ltp":2.38,"tv":420.37,"id":26354922}]}]}
{"op":"mcm","clk":"11787632234","pt":1722462544172,"mc":[{"id":"1.231241311","rc":[{"batb":[[0,2.34,7.88],[1,2.32,12.16],[2,2.12,54.28]],"ltp":2.38,"tv":420.37,"id":26354922}]}]}
{"op":"mcm","clk":"11787632390","pt":1722462546954,"mc":[{"id":"1.231241311","rc":[{"batb":[[0,2.36,10],[1,2.34,7.88],[2,2.32,12.16]],"ltp":2.38,"tv":420.37,"id":26354922}]}]}
{"op":"mcm","clk":"11787632561","pt":1722462550347,"mc":[{"id":"1.231241311","rc":[{"batb":[[0,2.34,7.88],[1,2.32,12.16],[2,2.12,54.28]],"ltp":2.38,"tv":420.37,"id":26354922}]}]}
{"op":"mcm","clk":"11787633448","pt":1722462570969,"mc":[{"id":"1.231241311","rc":[{"batb":[[0,2.36,10],[1,2.34,7.88],[2,2.32,12.16]],"ltp":2.38,"tv":420.37,"id":26354922}]}]}
{"op":"mcm","clk":"11787633618","pt":1722462574510,"mc":[{"id":"1.231241311","rc":[{"batb":[[0,2.34,7.88],[1,2.32,12.16],[2,2.12,54.28]],"ltp":2.38,"tv":420.37,"id":26354922}]}]}
{"op":"mcm","clk":"11787633763","pt":1722462577681,"mc":[{"id":"1.231241311","rc":[{"batb":[[0,2.36,10],[1,2.34,7.88],[2,2.32,12.16]],"ltp":2.38,"tv":420.37,"id":26354922}]}]}
{"op":"mcm","clk":"11787633913","pt":1722462581159,"mc":[{"id":"1.231241311","rc":[{"batb":[[0,2.34,7.88],[1,2.32,12.16],[2,2.12,54.28]],"ltp":2.38,"tv":420.37,"id":26354922}]}]}
{"op":"mcm","clk":"11787634015","pt":1722462583426,"mc":[{"id":"1.231241311","rc":[{"batb":[[0,2.36,10],[1,2.34,7.88],[2,2.32,12.16]],"ltp":2.38,"tv":420.37,"id":26354922}]}]}
{"op":"mcm","clk":"11787634189","pt":1722462587002,"mc":[{"id":"1.231241311","rc":[{"batb":[[0,2.34,7.88],[1,2.32,12.16],[2,2.12,54.28]],"ltp":2.38,"tv":420.37,"id":26354922}]}]}
{"op":"mcm","clk":"11787639988","pt":1722462725727,"mc":[{"id":"1.231241311","rc":[{"batb":[[0,2.36,10],[1,2.34,7.88],[2,2.32,12.16]],"ltp":2.38,"tv":420.37,"id":26354922}]}]}
{"op":"mcm","clk":"11787640106","pt":1722462729158,"mc":[{"id":"1.231241311","rc":[{"batb":[[0,2.34,7.88],[1,2.32,12.16],[2,2.12,54.28]],"ltp":2.38,"tv":420.37,"id":26354922}]}]}
{"op":"mcm","clk":"11787642297","pt":1722462785014,"mc":[{"id":"1.231241311","rc":[{"batb":[[0,2.36,10],[1,2.34,7.88],[2,2.32,12.16]],"ltp":2.38,"tv":420.37,"id":26354922}]}]}
{"op":"mcm","clk":"11787642435","pt":1722462788649,"mc":[{"id":"1.231241311","rc":[{"batb":[[0,2.34,7.88],[1,2.32,12.16],[2,2.12,54.28]],"ltp":2.38,"tv":420.37,"id":26354922}]}]}
{"op":"mcm","clk":"11787642910","pt":1722462804462,"mc":[{"id":"1.231241311","rc":[{"batl":[[0,1.74,3],[1,1.75,14.54],[2,1.76,15.72]],"ltp":1.73,"tv":1202.0,"id":26354926},{"batb":[[0,2.36,10],[1,2.34,7.88],[2,2.32,12.16]],"ltp":2.38,"tv":420.37,"id":26354922}]}]}
{"op":"mcm","clk":"11787642975","pt":1722462806261,"mc":[{"id":"1.231241311","rc":[{"batb":[[2,2.12,54.28]],"ltp":2.38,"tv":420.37,"id":26354922}]}]}
{"op":"mcm","clk":"11787642979","pt":1722462806360,"mc":[{"id":"1.231241311","rc":[{"batb":[[0,2.36,21.96]],"ltp":2.38,"tv":420.37,"id":26354922}]}]}
{"op":"mcm","clk":"11787643111","pt":1722462808173,"mc":[{"id":"1.231241311","rc":[{"batl":[[0,1.74,13.04],[1,1.75,4.56]],"ltp":1.73,"tv":1202.0,"id":26354926},{"batb":[[0,2.36,11.96]],"ltp":2.38,"tv":420.37,"id":26354922}]}]}
{"op":"mcm","clk":"11787643135","pt":1722462808946,"mc":[{"id":"1.231241311","rc":[{"batb":[[0,2.34,19.94],[1,2.12,54.28],[2,1.1,10000]],"ltp":2.38,"tv":420.37,"id":26354922}]}]}
{"op":"mcm","clk":"11787647248","pt":1722462923135,"mc":[{"id":"1.231241311","rc":[{"batl":[[2,1.76,105.72]],"ltp":1.73,"tv":1202.0,"id":26354926},{"batb":[[0,2.36,10],[1,2.34,19.94],[2,2.12,54.28]],"ltp":2.38,"tv":420.37,"id":26354922}]}]}
{"op":"mcm","clk":"11787647379","pt":1722462926429,"mc":[{"id":"1.231241311","rc":[{"batb":[[0,2.34,19.94],[1,2.12,54.28],[2,1.1,10000]],"ltp":2.38,"tv":420.37,"id":26354922}]}]}
{"op":"mcm","clk":"11787648076","pt":1722462944777,"mc":[{"id":"1.231241311","rc":[{"batb":[[0,2.36,10],[1,2.34,19.94],[2,2.12,54.28]],"ltp":2.38,"tv":420.37,"id":26354922}]}]}
{"op":"mcm","clk":"11787648211","pt":1722462948268,"mc":[{"id":"1.231241311","rc":[{"batb":[[0,2.34,19.94],[1,2.12,54.28],[2,1.1,10000]],"ltp":2.38,"tv":420.37,"id":26354922}]}]}
{"op":"mcm","clk":"11787650237","pt":1722463006559,"mc":[{"id":"1.231241311","rc":[{"batb":[[0,2.36,10],[1,2.34,19.94],[2,2.12,54.28]],"ltp":2.38,"tv":420.37,"id":26354922}]}]}
{"op":"mcm","clk":"11787650356","pt":1722463010152,"mc":[{"id":"1.231241311","rc":[{"batb":[[0,2.34,19.94],[1,2.12,54.28],[2,1.1,10000]],"ltp":2.38,"tv":420.37,"id":26354922}]}]}
{"op":"mcm","clk":"11787652059","pt":1722463062786,"mc":[{"id":"1.231241311","rc":[{"batb":[[0,2.36,10],[1,2.34,19.94],[2,2.12,54.28]],"ltp":2.38,"tv":420.37,"id":26354922}]}]}
{"op":"mcm","clk":"11787652162","pt":1722463066221,"mc":[{"id":"1.231241311","rc":[{"batb":[[0,2.34,19.94],[1,2.12,54.28],[2,1.1,10000]],"ltp":2.38,"tv":420.37,"id":26354922}]}]}
{"op":"mcm","clk":"11787652292","pt":1722463070219,"mc":[{"id":"1.231241311","rc":[{"batb":[[0,2.36,10],[1,2.34,19.94],[2,2.12,54.28]],"ltp":2.38,"tv":420.37,"id":26354922}]}]}
{"op":"mcm","clk":"11787652437","pt":1722463073617,"mc":[{"id":"1.231241311","rc":[{"batb":[[0,2.34,19.94],[1,2.12,54.28],[2,1.1,10000]],"ltp":2.38,"tv":420.37,"id":26354922}]}]}
{"op":"mcm","clk":"11787652629","pt":1722463079923,"mc":[{"id":"1.231241311","rc":[{"batb":[[0,2.36,10],[1,2.34,19.94],[2,2.12,54.28]],"ltp":2.38,"tv":420.37,"id":26354922}]}]}
{"op":"mcm","clk":"11787652759","pt":1722463083327,"mc":[{"id":"1.231241311","rc":[{"batb":[[0,2.34,19.94],[1,2.12,54.28],[2,1.1,10000]],"ltp":2.38,"tv":420.37,"id":26354922}]}]}
{"op":"mcm","clk":"11787652890","pt":1722463086918,"mc":[{"id":"1.231241311","rc":[{"batb":[[0,2.36,10],[1,2.34,19.94],[2,2.12,54.28]],"ltp":2.38,"tv":420.37,"id":26354922}]}]}
{"op":"mcm","clk":"11787653002","pt":1722463090242,"mc":[{"id":"1.231241311","rc":[{"batb":[[0,2.34,19.94],[1,2.12,54.28],[2,1.1,10000]],"ltp":2.38,"tv":420.37,"id":26354922}]}]}
{"op":"mcm","clk":"11787653149","pt":1722463095226,"mc":[{"id":"1.231241311","rc":[{"batb":[[0,2.36,10],[1,2.34,19.94],[2,2.12,54.28]],"ltp":2.38,"tv":420.37,"id":26354922}]}]}
{"op":"mcm","clk":"11787653276","pt":1722463098719,"mc":[{"id":"1.231241311","rc":[{"batb":[[0,2.34,19.94],[1,2.12,54.28],[2,1.1,10000]],"ltp":2.38,"tv":420.37,"id":26354922}]}]}
{"op":"mcm","clk":"11787653467","pt":1722463103854,"mc":[{"id":"1.231241311","rc":[{"batb":[[0,2.36,10],[1,2.34,19.94],[2,2.12,54.28]],"ltp":2.38,"tv":420.37,"id":26354922}]}]}
{"op":"mcm","clk":"11787653591","pt":1722463107028,"mc":[{"id":"1.231241311","rc":[{"batb":[[0,2.34,19.94],[1,2.12,54.28],[2,1.1,10000]],"ltp":2.38,"tv":420.37,"id":26354922}]}]}
{"op":"mcm","clk":"11787653961","pt":1722463114333,"mc":[{"id":"1.231241311","rc":[{"batb":[[0,2.36,10],[1,2.34,19.94],[2,2.12,54.28]],"ltp":2.38,"tv":420.37,"id":26354922}]}]}
{"op":"mcm","clk":"11787654044","pt":1722463117871,"mc":[{"id":"1.231241311","rc":[{"batb":[[0,2.34,19.94],[1,2.12,54.28],[2,1.1,10000]],"ltp":2.38,"tv":420.37,"id":26354922}]}]}
{"op":"mcm","clk":"11787654323","pt":1722463125871,"mc":[{"id":"1.231241311","rc":[{"batb":[[0,2.36,10],[1,2.34,19.94],[2,2.12,54.28]],"ltp":2.38,"tv":420.37,"id":26354922}]}]}
{"op":"mcm","clk":"11787654415","pt":1722463129563,"mc":[{"id":"1.231241311","rc":[{"batb":[[0,2.34,19.94],[1,2.12,54.28],[2,1.1,10000]],"ltp":2.38,"tv":420.37,"id":26354922}]}]}
{"op":"mcm","clk":"11787654495","pt":1722463132482,"mc":[{"id":"1.231241311","rc":[{"batb":[[0,2.36,10],[1,2.34,19.94],[2,2.12,54.28]],"ltp":2.38,"tv":420.37,"id":26354922}]}]}
{"op":"mcm","clk":"11787654581","pt":1722463135876,"mc":[{"id":"1.231241311","rc":[{"batb":[[0,2.34,19.94],[1,2.12,54.28],[2,1.1,10000]],"ltp":2.38,"tv":420.37,"id":26354922}]}]}
{"op":"mcm","clk":"11787654689","pt":1722463139165,"mc":[{"id":"1.231241311","rc":[{"batb":[[0,2.36,10],[1,2.34,19.94],[2,2.12,54.28]],"ltp":2.38,"tv":420.37,"id":26354922}]}]}
{"op":"mcm","clk":"11787654817","pt":1722463142458,"mc":[{"id":"1.231241311","rc":[{"batb":[[0,2.34,19.94],[1,2.12,54.28],[2,1.1,10000]],"ltp":2.38,"tv":420.37,"id":26354922}]}]}
{"op":"mcm","clk":"11787655151","pt":1722463150701,"mc":[{"id":"1.231241311","rc":[{"batb":[[0,2.36,10],[1,2.34,19.94],[2,2.12,54.28]],"ltp":2.38,"tv":420.37,"id":26354922}]}]}
{"op":"mcm","clk":"11787655291","pt":1722463154203,"mc":[{"id":"1.231241311","rc":[{"batb":[[0,2.34,19.94],[1,2.12,54.28],[2,1.1,10000]],"ltp":2.38,"tv":420.37,"id":26354922}]}]}
{"op":"mcm","clk":"11787656257","pt":1722463182790,"mc":[{"id":"1.231241311","rc":[{"batb":[[0,2.36,10],[1,2.34,19.94],[2,2.12,54.28]],"ltp":2.38,"tv":420.37,"id":26354922}]}]}
{"op":"mcm","clk":"11787656374","pt":1722463186224,"mc":[{"id":"1.231241311","rc":[{"batb":[[0,2.34,19.94],[1,2.12,54.28],[2,1.1,10000]],"ltp":2.38,"tv":420.37,"id":26354922}]}]}
{"op":"mcm","clk":"11787656495","pt":1722463190120,"mc":[{"id":"1.231241311","rc":[{"batb":[[0,2.36,10],[1,2.34,167.94],[2,2.12,54.28]],"ltp":2.38,"tv":420.37,"id":26354922}]}]}
{"op":"mcm","clk":"11787656617","pt":1722463193612,"mc":[{"id":"1.231241311","rc":[{"batb":[[0,2.34,167.94],[1,2.12,54.28],[2,1.1,10000]],"ltp":2.38,"tv":420.37,"id":26354922}]}]}
{"op":"mcm","clk":"11787657592","pt":1722463214863,"mc":[{"id":"1.231241311","rc":[{"trd":[[1.75,22.37]],"batl":[[0,1.74,13.04]],"ltp":1.73,"tv":1202.0,"id":26354926},{"trd":[[2.34,46.56]],"batb":[[0,2.36,10],[1,2.34,167.94],[2,2.12,54.28]],"ltp":2.38,"tv":420.37,"id":26354922}],"tv":1622.38}]}
{"op":"mcm","clk":"11787657755","pt":1722463218260,"mc":[{"id":"1.231241311","rc":[{"batb":[[0,2.34,167.94],[1,2.12,54.28],[2,1.1,10000]],"ltp":2.38,"tv":420.37,"id":26354922}]}]}
{"op":"mcm","clk":"11787658287","pt":1722463230261,"mc":[{"id":"1.231241311","rc":[{"batb":[[0,2.36,10],[1,2.34,167.94],[2,2.12,54.28]],"ltp":2.38,"tv":420.37,"id":26354922}]}]}
{"op":"mcm","clk":"11787658461","pt":1722463233857,"mc":[{"id":"1.231241311","rc":[{"batb":[[0,2.34,167.94],[1,2.12,54.28],[2,1.1,10000]],"ltp":2.38,"tv":420.37,"id":26354922}]}]}
{"op":"mcm","clk":"11787658963","pt":1722463244780,"mc":[{"id":"1.231241311","rc":[{"batb":[[0,2.36,10],[1,2.34,167.94],[2,2.12,54.28]],"ltp":2.38,"tv":420.37,"id":26354922}]}]}
{"op":"mcm","clk":"11787659117","pt":1722463248173,"mc":[{"id":"1.231241311","rc":[{"batb":[[0,2.34,167.94],[1,2.12,54.28],[2,1.1,10000]],"ltp":2.38,"tv":420.37,"id":26354922}]}]}
{"op":"mcm","clk":"11787659508","pt":1722463257684,"mc":[{"id":"1.231241311","rc":[{"batb":[[0,2.36,10],[1,2.34,167.94],[2,2.12,54.28]],"ltp":2.38,"tv":420.37,"id":26354922}]}]}
{"op":"mcm","clk":"11787659644","pt":1722463261124,"mc":[{"id":"1.231241311","rc":[{"batb":[[0,2.34,167.94],[1,2.12,54.28],[2,1.1,10000]],"ltp":2.38,"tv":420.37,"id":26354922}]}]}
{"op":"mcm","clk":"11787662912","pt":1722463332307,"mc":[{"id":"1.231241311","rc":[{"batb":[[0,2.36,10],[1,2.34,167.94],[2,2.12,54.28]],"ltp":2.38,"tv":420.37,"id":26354922}]}]}
{"op":"mcm","clk":"11787663059","pt":1722463335902,"mc":[{"id":"1.231241311","rc":[{"batb":[[0,2.34,167.94],[1,2.12,54.28],[2,1.1,10000]],"ltp":2.38,"tv":420.37,"id":26354922}]}]}
{"op":"mcm","clk":"11787664004","pt":1722463359010,"mc":[{"id":"1.231241311","rc":[{"batb":[[0,2.36,10],[1,2.34,167.94],[2,2.12,54.28]],"ltp":2.38,"tv":420.37,"id":26354922}]}]}
{"op":"mcm","clk":"11787664160","pt":1722463362403,"mc":[{"id":"1.231241311","rc":[{"batb":[[0,2.34,167.94],[1,2.12,54.28],[2,1.1,10000]],"ltp":2.38,"tv":420.37,"id":26354922}]}]}
{"op":"mcm","clk":"11787664337","pt":1722463366519,"mc":[{"id":"1.231241311","rc":[{"batb":[[0,2.36,10],[1,2.34,167.94],[2,2.12,54.28]],"ltp":2.38,"tv":420.37,"id":26354922}]}]}
{"op":"mcm","clk":"11787664486","pt":1722463369817,"mc":[{"id":"1.231241311","rc":[{"batb":[[0,2.34,167.94],[1,2.12,54.28],[2,1.1,10000]],"ltp":2.38,"tv":420.37,"id":26354922}]}]}
{"op":"mcm","clk":"11787664726","pt":1722463375358,"mc":[{"id":"1.231241311","rc":[{"batb":[[0,2.36,10],[1,2.34,167.94],[2,2.12,54.28]],"ltp":2.38,"tv":420.37,"id":26354922}]}]}
{"op":"mcm","clk":"11787664913","pt":1722463378823,"mc":[{"id":"1.231241311","rc":[{"batb":[[0,2.34,167.94],[1,2.12,54.28],[2,1.1,10000]],"ltp":2.38,"tv":420.37,"id":26354922}]}]}
{"op":"mcm","clk":"11787665166","pt":1722463384142,"mc":[{"id":"1.231241311","rc":[{"batb":[[0,2.36,10],[1,2.34,167.94],[2,2.12,54.28]],"ltp":2.38,"tv":420.37,"id":26354922}]}]}
{"op":"mcm","clk":"11787665344","pt":1722463387331,"mc":[{"id":"1.231241311","rc":[{"batb":[[0,2.34,167.94],[1,2.12,54.28],[2,1.1,10000]],"ltp":2.38,"tv":420.37,"id":26354922}]}]}
{"op":"mcm","clk":"11787665483","pt":1722463389918,"mc":[{"id":"1.231241311","rc":[{"batb":[[0,2.36,10],[1,2.34,167.94],[2,2.12,54.28]],"ltp":2.38,"tv":420.37,"id":26354922}]}]}
{"op":"mcm","clk":"11787665683","pt":1722463393423,"mc":[{"id":"1.231241311","rc":[{"batb":[[0,2.34,167.94],[1,2.12,54.28],[2,1.1,10000]],"ltp":2.38,"tv":420.37,"id":26354922}]}]}
{"op":"mcm","clk":"11787665920","pt":1722463397686,"mc":[{"id":"1.231241311","rc":[{"batb":[[0,2.36,10],[1,2.34,167.94],[2,2.12,54.28]],"ltp":2.38,"tv":420.37,"id":26354922}]}]}
{"op":"mcm","clk":"11787666097","pt":1722463400986,"mc":[{"id":"1.231241311","rc":[{"batb":[[0,2.34,167.94],[1,2.12,54.28],[2,1.1,10000]],"ltp":2.38,"tv":420.37,"id":26354922}]}]}
{"op":"mcm","clk":"11787666656","pt":1722463411500,"mc":[{"id":"1.231241311","rc":[{"batb":[[0,2.36,10],[1,2.34,167.94],[2,2.12,54.28]],"ltp":2.38,"tv":420.37,"id":26354922}]}]}
{"op":"mcm","clk":"11787666809","pt":1722463414840,"mc":[{"id":"1.231241311","rc":[{"batb":[[0,2.34,167.94],[1,2.12,54.28],[2,1.1,10000]],"ltp":2.38,"tv":420.37,"id":26354922}]}]}
{"op":"mcm","clk":"11787667486","pt":1722463427842,"mc":[{"id":"1.231241311","rc":[{"batb":[[0,2.36,10],[1,2.34,167.94],[2,2.12,54.28]],"ltp":2.38,"tv":420.37,"id":26354922}]}]}
{"op":"mcm","clk":"11787667654","pt":1722463431247,"mc":[{"id":"1.231241311","rc":[{"batb":[[0,2.34,167.94],[1,2.12,54.28],[2,1.1,10000]],"ltp":2.38,"tv":420.37,"id":26354922}]}]}
{"op":"mcm","clk":"11787668466","pt":1722463447141,"mc":[{"id":"1.231241311","rc":[{"batb":[[0,2.36,10],[1,2.34,167.94],[2,2.12,54.28]],"ltp":2.38,"tv":420.37,"id":26354922}]}]}
{"op":"mcm","clk":"11787668643","pt":1722463450542,"mc":[{"id":"1.231241311","rc":[{"batb":[[0,2.34,167.94],[1,2.12,54.28],[2,1.1,10000]],"ltp":2.38,"tv":420.37,"id":26354922}]}]}
{"op":"mcm","clk":"11787671715","pt":1722463513067,"mc":[{"id":"1.231241311","rc":[{"batb":[[0,2.36,10],[1,2.34,167.94],[2,2.12,54.28]],"ltp":2.38,"tv":420.37,"id":26354922}]}]}
{"op":"mcm","clk":"11787671900","pt":1722463516572,"mc":[{"id":"1.231241311","rc":[{"batb":[[0,2.34,167.94],[1,2.12,54.28],[2,1.1,10000]],"ltp":2.38,"tv":420.37,"id":26354922}]}]}
{"op":"mcm","clk":"11787674879","pt":1722463575613,"mc":[{"id":"1.231241311","rc":[{"batb":[[0,2.36,10],[1,2.34,167.94],[2,2.12,54.28]],"ltp":2.38,"tv":420.37,"id":26354922}]}]}
{"op":"mcm","clk":"11787675081","pt":1722463578810,"mc":[{"id":"1.231241311","rc":[{"batb":[[0,2.34,167.94],[1,2.12,54.28],[2,1.1,10000]],"ltp":2.38,"tv":420.37,"id":26354922}]}]}
{"op":"mcm","clk":"11787675638","pt":1722463590119,"mc":[{"id":"1.231241311","rc":[{"batb":[[0,2.36,10],[1,2.34,167.94],[2,2.12,54.28]],"ltp":2.38,"tv":420.37,"id":26354922}]}]}
{"op":"mcm","clk":"11787675775","pt":1722463593415,"mc":[{"id":"1.231241311","rc":[{"batb":[[0,2.34,167.94],[1,2.12,54.28],[2,1.1,10000]],"ltp":2.38,"tv":420.37,"id":26354922}]}]}
{"op":"mcm","clk":"11787676452","pt":1722463607845,"mc":[{"id":"1.231241311","rc":[{"batb":[[0,2.36,10],[1,2.34,167.94],[2,2.12,54.28]],"ltp":2.38,"tv":420.37,"id":26354922}]}]}
{"op":"mcm","clk":"11787676630","pt":1722463611342,"mc":[{"id":"1.231241311","rc":[{"batb":[[0,2.34,167.94],[1,2.12,54.28],[2,1.1,10000]],"ltp":2.38,"tv":420.37,"id":26354922}]}]}
{"op":"mcm","clk":"11787682886","pt":1722463734801,"mc":[{"id":"1.231241311","rc":[{"batb":[[0,2.36,10],[1,2.34,167.94],[2,2.12,54.28]],"ltp":2.38,"tv":420.37,"id":26354922}]}]}
{"op":"mcm","clk":"11787683097","pt":1722463738775,"mc":[{"id":"1.231241311","rc":[{"batb":[[0,2.34,167.94],[1,2.12,54.28],[2,1.1,10000]],"ltp":2.38,"tv":420.37,"id":26354922}]}]}
{"op":"mcm","clk":"11787691457","pt":1722463894334,"mc":[{"id":"1.231241311","rc":[{"batb":[[0,2.36,10],[1,2.34,167.94],[2,2.12,54.28]],"ltp":2.38,"tv":420.37,"id":26354922}]}]}
{"op":"mcm","clk":"11787691637","pt":1722463897782,"mc":[{"id":"1.231241311","rc":[{"batb":[[0,2.34,167.94],[1,2.12,54.28],[2,1.1,10000]],"ltp":2.38,"tv":420.37,"id":26354922}]}]}
{"op":"mcm","clk":"11787711794","pt":1722464252429,"mc":[{"id":"1.231241311","rc":[{"batb":[[0,2.36,10],[1,2.34,167.94],[2,2.12,54.28]],"ltp":2.38,"tv":420.37,"id":26354922}]}]}
{"op":"mcm","clk":"11787711982","pt":1722464255626,"mc":[{"id":"1.231241311","rc":[{"batb":[[0,2.34,167.94],[1,2.12,54.28],[2,1.1,10000]],"ltp":2.38,"tv":420.37,"id":26354922}]}]}
{"op":"mcm","clk":"11787716836","pt":1722464348530,"mc":[{"id":"1.231241311","rc":[{"batb":[[0,2.36,10],[1,2.34,167.94],[2,2.12,54.28]],"ltp":2.38,"tv":420.37,"id":26354922}]}]}
{"op":"mcm","clk":"11787717041","pt":1722464352148,"mc":[{"id":"1.231241311","rc":[{"batb":[[0,2.34,167.94],[1,2.12,54.28],[2,1.1,10000]],"ltp":2.38,"tv":420.37,"id":26354922}]}]}
{"op":"mcm","clk":"11787717706","pt":1722464363351,"mc":[{"id":"1.231241311","rc":[{"batb":[[0,2.36,10],[1,2.34,167.94],[2,2.12,54.28]],"ltp":2.38,"tv":420.37,"id":26354922}]}]}
{"op":"mcm","clk":"11787717917","pt":1722464366755,"mc":[{"id":"1.231241311","rc":[{"batb":[[0,2.34,167.94],[1,2.12,54.28],[2,1.1,10000]],"ltp":2.38,"tv":420.37,"id":26354922}]}]}
{"op":"mcm","clk":"11787738418","pt":1722464725253,"mc":[{"id":"1.231241311","rc":[{"batb":[[0,2.36,10],[1,2.34,167.94],[2,2.12,54.28]],"ltp":2.38,"tv":420.37,"id":26354922}]}]}
{"op":"mcm","clk":"11787738671","pt":1722464730037,"mc":[{"id":"1.231241311","rc":[{"batb":[[0,2.34,167.94],[1,2.12,54.28],[2,1.1,10000]],"ltp":2.38,"tv":420.37,"id":26354922}]}]}
{"op":"mcm","clk":"11787744313","pt":1722464819523,"mc":[{"id":"1.231241311","rc":[{"batb":[[0,2.36,10],[1,2.34,167.94],[2,2.12,54.28]],"ltp":2.38,"tv":420.37,"id":26354922}]}]}
{"op":"mcm","clk":"11787744528","pt":1722464823073,"mc":[{"id":"1.231241311","rc":[{"batb":[[0,2.34,167.94],[1,2.12,54.28],[2,1.1,10000]],"ltp":2.38,"tv":420.37,"id":26354922}]}]}
{"op":"mcm","clk":"11787746053","pt":1722464847397,"mc":[{"id":"1.231241311","rc":[{"batb":[[0,2.36,10],[1,2.34,167.94],[2,2.12,54.28]],"ltp":2.38,"tv":420.37,"id":26354922}]}]}
{"op":"mcm","clk":"11787746253","pt":1722464850793,"mc":[{"id":"1.231241311","rc":[{"batb":[[0,2.34,167.94],[1,2.12,54.28],[2,1.1,10000]],"ltp":2.38,"tv":420.37,"id":26354922}]}]}
{"op":"mcm","clk":"11787747146","pt":1722464865920,"mc":[{"id":"1.231241311","rc":[{"batb":[[0,2.36,10],[1,2.34,167.94],[2,2.12,54.28]],"ltp":2.38,"tv":420.37,"id":26354922}]}]}
{"op":"mcm","clk":"11787747332","pt":1722464869208,"mc":[{"id":"1.231241311","rc":[{"batb":[[0,2.34,167.94],[1,2.12,54.28],[2,1.1,10000]],"ltp":2.38,"tv":420.37,"id":26354922}]}]}
{"op":"mcm","clk":"11787747545","pt":1722464872814,"mc":[{"id":"1.231241311","rc":[{"batb":[[0,2.36,10],[1,2.34,167.94],[2,2.12,54.28]],"ltp":2.38,"tv":420.37,"id":26354922}]}]}
{"op":"mcm","clk":"11787747755","pt":1722464876517,"mc":[{"id":"1.231241311","rc":[{"batb":[[0,2.34,167.94],[1,2.12,54.28],[2,1.1,10000]],"ltp":2.38,"tv":420.37,"id":26354922}]}]}
{"op":"mcm","clk":"11787756538","pt":1722465027457,"mc":[{"id":"1.231241311","rc":[{"batb":[[0,2.36,10],[1,2.34,167.94],[2,2.12,54.28]],"ltp":2.38,"tv":420.37,"id":26354922}]}]}
{"op":"mcm","clk":"11787756733","pt":1722465031041,"mc":[{"id":"1.231241311","rc":[{"batb":[[0,2.34,167.94],[1,2.12,54.28],[2,1.1,10000]],"ltp":2.38,"tv":420.37,"id":26354922}]}]}
{"op":"mcm","clk":"11787758438","pt":1722465059484,"mc":[{"id":"1.231241311","rc":[{"batb":[[0,2.36,10],[1,2.34,167.94],[2,2.12,54.28]],"ltp":2.38,"tv":420.37,"id":26354922}]}]}
{"op":"mcm","clk":"11787758641","pt":1722465062991,"mc":[{"id":"1.231241311","rc":[{"batb":[[0,2.34,167.94],[1,2.12,54.28],[2,1.1,10000]],"ltp":2.38,"tv":420.37,"id":26354922}]}]}
{"op":"mcm","clk":"11787760078","pt":1722465084328,"mc":[{"id":"1.231241311","rc":[{"batb":[[0,2.36,10],[1,2.34,167.94],[2,2.12,54.28]],"ltp":2.38,"tv":420.37,"id":26354922}]}]}
{"op":"mcm","clk":"11787760299","pt":1722465087927,"mc":[{"id":"1.231241311","rc":[{"batb":[[0,2.34,167.94],[1,2.12,54.28],[2,1.1,10000]],"ltp":2.38,"tv":420.37,"id":26354922}]}]}
{"op":"mcm","clk":"11787763656","pt":1722465143088,"mc":[{"id":"1.231241311","rc":[{"batb":[[0,2.36,10],[1,2.34,167.94],[2,2.12,54.28]],"ltp":2.38,"tv":420.37,"id":26354922}]}]}
{"op":"mcm","clk":"11787763849","pt":1722465146482,"mc":[{"id":"1.231241311","rc":[{"batb":[[0,2.34,167.94],[1,2.12,54.28],[2,1.1,10000]],"ltp":2.38,"tv":420.37,"id":26354922}]}]}
{"op":"mcm","clk":"11787770658","pt":1722465256977,"mc":[{"id":"1.231241311","rc":[{"batb":[[0,2.36,10],[1,2.34,167.94],[2,2.12,54.28]],"ltp":2.38,"tv":420.37,"id":26354922}]}]}
{"op":"mcm","clk":"11787770852","pt":1722465260270,"mc":[{"id":"1.231241311","rc":[{"batb":[[0,2.34,167.94],[1,2.12,54.28],[2,1.1,10000]],"ltp":2.38,"tv":420.37,"id":26354922}]}]}
{"op":"mcm","clk":"11787772390","pt":1722465283137,"mc":[{"id":"1.231241311","rc":[{"batb":[[0,2.36,10],[1,2.34,167.94],[2,2.12,54.28]],"ltp":2.38,"tv":420.37,"id":26354922}]}]}
{"op":"mcm","clk":"11787772596","pt":1722465286601,"mc":[{"id":"1.231241311","rc":[{"batb":[[0,2.34,167.94],[1,2.12,54.28],[2,1.1,10000]],"ltp":2.38,"tv":420.37,"id":26354922}]}]}
{"op":"mcm","clk":"11787772936","pt":1722465292323,"mc":[{"id":"1.231241311","rc":[{"batb":[[0,2.36,10],[1,2.34,167.94],[2,2.12,54.28]],"ltp":2.38,"tv":420.37,"id":26354922}]}]}
{"op":"mcm","clk":"11787773159","pt":1722465295828,"mc":[{"id":"1.231241311","rc":[{"batb":[[0,2.34,167.94],[1,2.12,54.28],[2,1.1,10000]],"ltp":2.38,"tv":420.37,"id":26354922}]}]}
{"op":"mcm","clk":"11787778989","pt":1722465389813,"mc":[{"id":"1.231241311","rc":[{"batb":[[0,2.36,10],[1,2.34,167.94],[2,2.12,54.28]],"ltp":2.38,"tv":420.37,"id":26354922}]}]}
{"op":"mcm","clk":"11787779248","pt":1722465393935,"mc":[{"id":"1.231241311","rc":[{"batb":[[0,2.34,167.94],[1,2.12,54.28],[2,1.1,10000]],"ltp":2.38,"tv":420.37,"id":26354922}]}]}
{"op":"mcm","clk":"11787782121","pt":1722465437880,"mc":[{"id":"1.231241311","rc":[{"batb":[[0,2.36,10],[1,2.34,167.94],[2,2.12,54.28]],"ltp":2.38,"tv":420.37,"id":26354922}]}]}
{"op":"mcm","clk":"11787782338","pt":1722465441487,"mc":[{"id":"1.231241311","rc":[{"batb":[[0,2.34,167.94],[1,2.12,54.28],[2,1.1,10000]],"ltp":2.38,"tv":420.37,"id":26354922}]}]}
{"op":"mcm","clk":"11787784006","pt":1722465468911,"mc":[{"id":"1.231241311","rc":[{"batb":[[0,2.36,10],[1,2.34,167.94],[2,2.12,54.28]],"ltp":2.38,"tv":420.37,"id":26354922}]}]}
{"op":"mcm","clk":"11787784241","pt":1722465472411,"mc":[{"id":"1.231241311","rc":[{"batb":[[0,2.34,167.94],[1,2.12,54.28],[2,1.1,10000]],"ltp":2.38,"tv":420.37,"id":26354922}]}]}
{"op":"mcm","clk":"11787789149","pt":1722465552507,"mc":[{"id":"1.231241311","rc":[{"batb":[[0,2.36,10],[1,2.34,167.94],[2,2.12,54.28]],"ltp":2.38,"tv":420.37,"id":26354922}]}]}
{"op":"mcm","clk":"11787789359","pt":1722465555908,"mc":[{"id":"1.231241311","rc":[{"batb":[[0,2.34,167.94],[1,2.12,54.28],[2,1.1,10000]],"ltp":2.38,"tv":420.37,"id":26354922}]}]}
{"op":"mcm","clk":"11787789510","pt":1722465558433,"mc":[{"id":"1.231241311","rc":[{"batb":[[0,2.36,10],[1,2.34,167.94],[2,2.12,54.28]],"ltp":2.38,"tv":420.37,"id":26354922}]}]}
{"op":"mcm","clk":"11787789684","pt":1722465561731,"mc":[{"id":"1.231241311","rc":[{"batb":[[0,2.34,167.94],[1,2.12,54.28],[2,1.1,10000]],"ltp":2.38,"tv":420.37,"id":26354922}]}]}
{"op":"mcm","clk":"11787792660","pt":1722465609252,"mc":[{"id":"1.231241311","rc":[{"batb":[[0,2.36,10],[1,2.34,167.94],[2,2.12,54.28]],"ltp":2.38,"tv":420.37,"id":26354922}]}]}
{"op":"mcm","clk":"11787792858","pt":1722465612753,"mc":[{"id":"1.231241311","rc":[{"batb":[[0,2.34,167.94],[1,2.12,54.28],[2,1.1,10000]],"ltp":2.38,"tv":420.37,"id":26354922}]}]}
{"op":"mcm","clk":"11787794016","pt":1722465630000,"mc":[{"id":"1.231241311","rc":[{"batb":[[0,2.36,10],[1,2.34,167.94],[2,2.12,54.28]],"ltp":2.38,"tv":420.37,"id":26354922}]}]}
{"op":"mcm","clk":"11787794247","pt":1722465633286,"mc":[{"id":"1.231241311","rc":[{"batb":[[0,2.34,167.94],[1,2.12,54.28],[2,1.1,10000]],"ltp":2.38,"tv":420.37,"id":26354922}]}]}
{"op":"mcm","clk":"11787794465","pt":1722465636477,"mc":[{"id":"1.231241311","rc":[{"batb":[[0,2.36,10],[1,2.34,167.94],[2,2.12,54.28]],"ltp":2.38,"tv":420.37,"id":26354922}]}]}
{"op":"mcm","clk":"11787794664","pt":1722465639926,"mc":[{"id":"1.231241311","rc":[{"batb":[[0,2.34,167.94],[1,2.12,54.28],[2,1.1,10000]],"ltp":2.38,"tv":420.37,"id":26354922}]}]}
{"op":"mcm","clk":"11787797187","pt":1722465678373,"mc":[{"id":"1.231241311","rc":[{"batb":[[0,2.36,10],[1,2.34,167.94],[2,2.12,54.28]],"ltp":2.38,"tv":420.37,"id":26354922}]}]}
{"op":"mcm","clk":"11787797380","pt":1722465681656,"mc":[{"id":"1.231241311","rc":[{"batb":[[0,2.34,167.94],[1,2.12,54.28],[2,1.1,10000]],"ltp":2.38,"tv":420.37,"id":26354922}]}]}
{"op":"mcm","clk":"11787798016","pt":1722465692452,"mc":[{"id":"1.231241311","rc":[{"batb":[[0,2.36,10],[1,2.34,167.94],[2,2.12,54.28]],"ltp":2.38,"tv":420.37,"id":26354922}]}]}
{"op":"mcm","clk":"11787798241","pt":1722465695949,"mc":[{"id":"1.231241311","rc":[{"batb":[[0,2.34,167.94],[1,2.12,54.28],[2,1.1,10000]],"ltp":2.38,"tv":420.37,"id":26354922}]}]}
{"op":"mcm","clk":"11787798442","pt":1722465699442,"mc":[{"id":"1.231241311","rc":[{"batb":[[0,2.36,10],[1,2.34,167.94],[2,2.12,54.28]],"ltp":2.38,"tv":420.37,"id":26354922}]}]}
{"op":"mcm","clk":"11787798633","pt":1722465702750,"mc":[{"id":"1.231241311","rc":[{"batb":[[0,2.34,167.94],[1,2.12,54.28],[2,1.1,10000]],"ltp":2.38,"tv":420.37,"id":26354922}]}]}
{"op":"mcm","clk":"11787801444","pt":1722465747225,"mc":[{"id":"1.231241311","rc":[{"batb":[[0,2.36,10],[1,2.34,167.94],[2,2.12,54.28]],"ltp":2.38,"tv":420.37,"id":26354922}]}]}
{"op":"mcm","clk":"11787801678","pt":1722465750515,"mc":[{"id":"1.231241311","rc":[{"batb":[[0,2.34,167.94],[1,2.12,54.28],[2,1.1,10000]],"ltp":2.38,"tv":420.37,"id":26354922}]}]}
{"op":"mcm","clk":"11787805039","pt":1722465803252,"mc":[{"id":"1.231241311","rc":[{"batb":[[0,2.36,10],[1,2.34,167.94],[2,2.12,54.28]],"ltp":2.38,"tv":420.37,"id":26354922}]}]}
{"op":"mcm","clk":"11787805227","pt":1722465806482,"mc":[{"id":"1.231241311","rc":[{"batb":[[0,2.34,167.94],[1,2.12,54.28],[2,1.1,10000]],"ltp":2.38,"tv":420.37,"id":26354922}]}]}
{"op":"mcm","clk":"11787806065","pt":1722465819692,"mc":[{"id":"1.231241311","rc":[{"batb":[[0,2.36,10],[1,2.34,167.94],[2,2.12,54.28]],"ltp":2.38,"tv":420.37,"id":26354922}]}]}
{"op":"mcm","clk":"11787806307","pt":1722465822988,"mc":[{"id":"1.231241311","rc":[{"batb":[[0,2.34,167.94],[1,2.12,54.28],[2,1.1,10000]],"ltp":2.38,"tv":420.37,"id":26354922}]}]}
{"op":"mcm","clk":"11787807002","pt":1722465833582,"mc":[{"id":"1.231241311","rc":[{"batb":[[0,2.36,10],[1,2.34,167.94],[2,2.12,54.28]],"ltp":2.38,"tv":420.37,"id":26354922}]}]}
{"op":"mcm","clk":"11787807207","pt":1722465836973,"mc":[{"id":"1.231241311","rc":[{"batb":[[0,2.34,167.94],[1,2.12,54.28],[2,1.1,10000]],"ltp":2.38,"tv":420.37,"id":26354922}]}]}
{"op":"mcm","clk":"11787811218","pt":1722465902299,"mc":[{"id":"1.231241311","rc":[{"batb":[[0,2.36,10],[1,2.34,167.94],[2,2.12,54.28]],"ltp":2.38,"tv":420.37,"id":26354922}]}]}
{"op":"mcm","clk":"11787811468","pt":1722465905742,"mc":[{"id":"1.231241311","rc":[{"batb":[[0,2.34,167.94],[1,2.12,54.28],[2,1.1,10000]],"ltp":2.38,"tv":420.37,"id":26354922}]}]}
{"op":"mcm","clk":"11787812536","pt":1722465922203,"mc":[{"id":"1.231241311","rc":[{"batb":[[0,2.36,10],[1,2.34,167.94],[2,2.12,54.28]],"ltp":2.38,"tv":420.37,"id":26354922}]}]}
{"op":"mcm","clk":"11787812721","pt":1722465925500,"mc":[{"id":"1.231241311","rc":[{"batb":[[0,2.34,167.94],[1,2.12,54.28],[2,1.1,10000]],"ltp":2.38,"tv":420.37,"id":26354922}]}]}
{"op":"mcm","clk":"11787822064","pt":1722466090551,"mc":[{"id":"1.231241311","rc":[{"batb":[[0,2.36,10],[1,2.34,167.94],[2,2.12,54.28]],"ltp":2.38,"tv":420.37,"id":26354922}]}]}
{"op":"mcm","clk":"11787822278","pt":1722466093943,"mc":[{"id":"1.231241311","rc":[{"batb":[[0,2.34,167.94],[1,2.12,54.28],[2,1.1,10000]],"ltp":2.38,"tv":420.37,"id":26354922}]}]}
{"op":"mcm","clk":"11787823325","pt":1722466112975,"mc":[{"id":"1.231241311","rc":[{"batb":[[0,2.36,10],[1,2.34,167.94],[2,2.12,54.28]],"ltp":2.38,"tv":420.37,"id":26354922}]}]}
{"op":"mcm","clk":"11787823507","pt":1722466116366,"mc":[{"id":"1.231241311","rc":[{"batb":[[0,2.34,167.94],[1,2.12,54.28],[2,1.1,10000]],"ltp":2.38,"tv":420.37,"id":26354922}]}]}
{"op":"mcm","clk":"11787824001","pt":1722466125463,"mc":[{"id":"1.231241311","rc":[{"batb":[[0,2.36,10],[1,2.34,167.94],[2,2.12,54.28]],"ltp":2.38,"tv":420.37,"id":26354922}]}]}
{"op":"mcm","clk":"11787824203","pt":1722466128904,"mc":[{"id":"1.231241311","rc":[{"batb":[[0,2.34,167.94],[1,2.12,54.28],[2,1.1,10000]],"ltp":2.38,"tv":420.37,"id":26354922}]}]}
{"op":"mcm","clk":"11787824658","pt":1722466136670,"mc":[{"id":"1.231241311","rc":[{"batb":[[0,2.36,10],[1,2.34,167.94],[2,2.12,54.28]],"ltp":2.38,"tv":420.37,"id":26354922}]}]}
{"op":"mcm","clk":"11787824838","pt":1722466140006,"mc":[{"id":"1.231241311","rc":[{"batb":[[0,2.34,167.94],[1,2.12,54.28],[2,1.1,10000]],"ltp":2.38,"tv":420.37,"id":26354922}]}]}
{"op":"mcm","clk":"11787835780","pt":1722466341498,"mc":[{"id":"1.231241311","rc":[{"batb":[[0,2.36,10],[1,2.34,167.94],[2,2.12,54.28]],"ltp":2.38,"tv":420.37,"id":26354922}]}]}
{"op":"mcm","clk":"11787835982","pt":1722466345042,"mc":[{"id":"1.231241311","rc":[{"batb":[[0,2.34,167.94],[1,2.12,54.28],[2,1.1,10000]],"ltp":2.38,"tv":420.37,"id":26354922}]}]}
{"op":"mcm","clk":"11787884701","pt":1722467312832,"mc":[{"id":"1.231241311","rc":[{"trd":[[1.75,22.37]],"batl":[[0,1.74,13.04]],"ltp":1.73,"tv":1202.0,"id":26354926},{"trd":[[2.34,46.56],[2.4,60.99]],"batb":[[0,2.36,10],[1,2.34,167.94],[2,2.12,54.28]],"ltp":2.38,"tv":420.39,"id":26354922}],"tv":1622.39}]}
{"op":"mcm","clk":"11787884898","pt":1722467316232,"mc":[{"id":"1.231241311","rc":[{"batb":[[0,2.34,167.94],[1,2.12,54.28],[2,1.1,10000]],"ltp":2.38,"tv":420.39,"id":26354922}]}]}
{"op":"mcm","clk":"11787885040","pt":1722467318502,"mc":[{"id":"1.231241311","rc":[{"batb":[[0,2.36,10],[1,2.34,167.94],[2,2.12,54.28]],"ltp":2.38,"tv":420.39,"id":26354922}]}]}
{"op":"mcm","clk":"11787885256","pt":1722467321904,"mc":[{"id":"1.231241311","rc":[{"batb":[[0,2.34,167.94],[1,2.12,54.28],[2,1.1,10000]],"ltp":2.38,"tv":420.39,"id":26354922}]}]}
{"op":"mcm","clk":"11787886348","pt":1722467339014,"mc":[{"id":"1.231241311","rc":[{"batb":[[0,2.36,10],[1,2.34,167.94],[2,2.12,54.28]],"ltp":2.38,"tv":420.39,"id":26354922}]}]}
{"op":"mcm","clk":"11787886570","pt":1722467342525,"mc":[{"id":"1.231241311","rc":[{"batb":[[0,2.34,167.94],[1,2.12,54.28],[2,1.1,10000]],"ltp":2.38,"tv":420.39,"id":26354922}]}]}
{"op":"mcm","clk":"11787886725","pt":1722467344743,"mc":[{"id":"1.231241311","rc":[{"batb":[[0,2.36,10],[1,2.34,167.94],[2,2.12,54.28]],"ltp":2.38,"tv":420.39,"id":26354922}]}]}
{"op":"mcm","clk":"11787886934","pt":1722467348149,"mc":[{"id":"1.231241311","rc":[{"batb":[[0,2.34,167.94],[1,2.12,54.28],[2,1.1,10000]],"ltp":2.38,"tv":420.39,"id":26354922}]}]}
{"op":"mcm","clk":"11787887145","pt":1722467350935,"mc":[{"id":"1.231241311","rc":[{"batb":[[0,2.36,10],[1,2.34,167.94],[2,2.12,54.28]],"ltp":2.38,"tv":420.39,"id":26354922}]}]}
{"op":"mcm","clk":"11787887404","pt":1722467354491,"mc":[{"id":"1.231241311","rc":[{"batb":[[0,2.34,167.94],[1,2.12,54.28],[2,1.1,10000]],"ltp":2.38,"tv":420.39,"id":26354922}]}]}
{"op":"mcm","clk":"11787887614","pt":1722467357481,"mc":[{"id":"1.231241311","rc":[{"batb":[[0,2.36,10],[1,2.34,167.94],[2,2.12,54.28]],"ltp":2.38,"tv":420.39,"id":26354922}]}]}
{"op":"mcm","clk":"11787887840","pt":1722467360939,"mc":[{"id":"1.231241311","rc":[{"batb":[[0,2.34,167.94],[1,2.12,54.28],[2,1.1,10000]],"ltp":2.38,"tv":420.39,"id":26354922}]}]}
{"op":"mcm","clk":"11787888036","pt":1722467363573,"mc":[{"id":"1.231241311","rc":[{"batb":[[0,2.36,10],[1,2.34,167.94],[2,2.12,54.28]],"ltp":2.38,"tv":420.39,"id":26354922}]}]}
{"op":"mcm","clk":"11787888248","pt":1722467366970,"mc":[{"id":"1.231241311","rc":[{"batb":[[0,2.34,167.94],[1,2.12,54.28],[2,1.1,10000]],"ltp":2.38,"tv":420.39,"id":26354922}]}]}
{"op":"mcm","clk":"11787888405","pt":1722467369591,"mc":[{"id":"1.231241311","rc":[{"batb":[[0,2.36,10],[1,2.34,167.94],[2,2.12,54.28]],"ltp":2.38,"tv":420.39,"id":26354922}]}]}
{"op":"mcm","clk":"11787888605","pt":1722467373092,"mc":[{"id":"1.231241311","rc":[{"batb":[[0,2.34,167.94],[1,2.12,54.28],[2,1.1,10000]],"ltp":2.38,"tv":420.39,"id":26354922}]}]}
{"op":"mcm","clk":"11787888787","pt":1722467376083,"mc":[{"id":"1.231241311","rc":[{"batb":[[0,2.36,10],[1,2.34,167.94],[2,2.12,54.28]],"ltp":2.38,"tv":420.39,"id":26354922}]}]}
{"op":"mcm","clk":"11787889009","pt":1722467379898,"mc":[{"id":"1.231241311","rc":[{"batb":[[0,2.34,167.94],[1,2.12,54.28],[2,1.1,10000]],"ltp":2.38,"tv":420.39,"id":26354922}]}]}
{"op":"mcm","clk":"11787889156","pt":1722467382377,"mc":[{"id":"1.231241311","rc":[{"batb":[[0,2.36,10],[1,2.34,167.94],[2,2.12,54.28]],"ltp":2.38,"tv":420.39,"id":26354922}]}]}
{"op":"mcm","clk":"11787889342","pt":1722467385580,"mc":[{"id":"1.231241311","rc":[{"batb":[[0,2.34,167.94],[1,2.12,54.28],[2,1.1,10000]],"ltp":2.38,"tv":420.39,"id":26354922}]}]}
{"op":"mcm","clk":"11787889494","pt":1722467388106,"mc":[{"id":"1.231241311","rc":[{"batb":[[0,2.36,10],[1,2.34,167.94],[2,2.12,54.28]],"ltp":2.38,"tv":420.39,"id":26354922}]}]}
{"op":"mcm","clk":"11787889678","pt":1722467391304,"mc":[{"id":"1.231241311","rc":[{"batb":[[0,2.34,167.94],[1,2.12,54.28],[2,1.1,10000]],"ltp":2.38,"tv":420.39,"id":26354922}]}]}
{"op":"mcm","clk":"11787889830","pt":1722467393824,"mc":[{"id":"1.231241311","rc":[{"batb":[[0,2.36,10],[1,2.34,167.94],[2,2.12,54.28]],"ltp":2.38,"tv":420.39,"id":26354922}]}]}
{"op":"mcm","clk":"11787890031","pt":1722467397185,"mc":[{"id":"1.231241311","rc":[{"batb":[[0,2.34,167.94],[1,2.12,54.28],[2,1.1,10000]],"ltp":2.38,"tv":420.39,"id":26354922}]}]}
{"op":"mcm","clk":"11787890149","pt":1722467399606,"mc":[{"id":"1.231241311","rc":[{"batb":[[0,2.36,10],[1,2.34,167.94],[2,2.12,54.28]],"ltp":2.38,"tv":420.39,"id":26354922}]}]}
{"op":"mcm","clk":"11787890364","pt":1722467403111,"mc":[{"id":"1.231241311","rc":[{"batb":[[0,2.34,167.94],[1,2.12,54.28],[2,1.1,10000]],"ltp":2.38,"tv":420.39,"id":26354922}]}]}
{"op":"mcm","clk":"11787890487","pt":1722467405326,"mc":[{"id":"1.231241311","rc":[{"batb":[[0,2.36,10],[1,2.34,167.94],[2,2.12,54.28]],"ltp":2.38,"tv":420.39,"id":26354922}]}]}
{"op":"mcm","clk":"11787890681","pt":1722467408736,"mc":[{"id":"1.231241311","rc":[{"batb":[[0,2.34,167.94],[1,2.12,54.28],[2,1.1,10000]],"ltp":2.38,"tv":420.39,"id":26354922}]}]}
{"op":"mcm","clk":"11787890797","pt":1722467410904,"mc":[{"id":"1.231241311","rc":[{"batb":[[0,2.36,10],[1,2.34,167.94],[2,2.12,54.28]],"ltp":2.38,"tv":420.39,"id":26354922}]}]}
{"op":"mcm","clk":"11787890991","pt":1722467414321,"mc":[{"id":"1.231241311","rc":[{"batb":[[0,2.34,167.94],[1,2.12,54.28],[2,1.1,10000]],"ltp":2.38,"tv":420.39,"id":26354922}]}]}
{"op":"mcm","clk":"11787891124","pt":1722467416638,"mc":[{"id":"1.231241311","rc":[{"batb":[[0,2.36,10],[1,2.34,167.94],[2,2.12,54.28]],"ltp":2.38,"tv":420.39,"id":26354922}]}]}
{"op":"mcm","clk":"11787891367","pt":1722467420451,"mc":[{"id":"1.231241311","rc":[{"batb":[[0,2.34,167.94],[1,2.12,54.28],[2,1.1,10000]],"ltp":2.38,"tv":420.39,"id":26354922}]}]}
{"op":"mcm","clk":"11787891508","pt":1722467422629,"mc":[{"id":"1.231241311","rc":[{"batb":[[0,2.36,10],[1,2.34,167.94],[2,2.12,54.28]],"ltp":2.38,"tv":420.39,"id":26354922}]}]}
{"op":"mcm","clk":"11787891721","pt":1722467426126,"mc":[{"id":"1.231241311","rc":[{"batb":[[0,2.34,167.94],[1,2.12,54.28],[2,1.1,10000]],"ltp":2.38,"tv":420.39,"id":26354922}]}]}
{"op":"mcm","clk":"11787891843","pt":1722467428235,"mc":[{"id":"1.231241311","rc":[{"batb":[[0,2.36,10],[1,2.34,167.94],[2,2.12,54.28]],"ltp":2.38,"tv":420.39,"id":26354922}]}]}
{"op":"mcm","clk":"11787892070","pt":1722467431756,"mc":[{"id":"1.231241311","rc":[{"batb":[[0,2.34,167.94],[1,2.12,54.28],[2,1.1,10000]],"ltp":2.38,"tv":420.39,"id":26354922}]}]}
{"op":"mcm","clk":"11787892202","pt":1722467433978,"mc":[{"id":"1.231241311","rc":[{"batb":[[0,2.36,10],[1,2.34,167.94],[2,2.12,54.28]],"ltp":2.38,"tv":420.39,"id":26354922}]}]}
{"op":"mcm","clk":"11787892409","pt":1722467437439,"mc":[{"id":"1.231241311","rc":[{"batb":[[0,2.34,167.94],[1,2.12,54.28],[2,1.1,10000]],"ltp":2.38,"tv":420.39,"id":26354922}]}]}
{"op":"mcm","clk":"11787892543","pt":1722467439753,"mc":[{"id":"1.231241311","rc":[{"batb":[[0,2.36,10],[1,2.34,167.94],[2,2.12,54.28]],"ltp":2.38,"tv":420.39,"id":26354922}]}]}
{"op":"mcm","clk":"11787892747","pt":1722467443256,"mc":[{"id":"1.231241311","rc":[{"batb":[[0,2.34,167.94],[1,2.12,54.28],[2,1.1,10000]],"ltp":2.38,"tv":420.39,"id":26354922}]}]}
{"op":"mcm","clk":"11787892878","pt":1722467445574,"mc":[{"id":"1.231241311","rc":[{"batb":[[0,2.36,10],[1,2.34,167.94],[2,2.12,54.28]],"ltp":2.38,"tv":420.39,"id":26354922}]}]}
{"op":"mcm","clk":"11787893089","pt":1722467448969,"mc":[{"id":"1.231241311","rc":[{"batb":[[0,2.34,167.94],[1,2.12,54.28],[2,1.1,10000]],"ltp":2.38,"tv":420.39,"id":26354922}]}]}
{"op":"mcm","clk":"11787893285","pt":1722467451955,"mc":[{"id":"1.231241311","rc":[{"batb":[[0,2.36,10],[1,2.34,167.94],[2,2.12,54.28]],"ltp":2.38,"tv":420.39,"id":26354922}]}]}
{"op":"mcm","clk":"11787893501","pt":1722467455398,"mc":[{"id":"1.231241311","rc":[{"batb":[[0,2.34,167.94],[1,2.12,54.28],[2,1.1,10000]],"ltp":2.38,"tv":420.39,"id":26354922}]}]}
{"op":"mcm","clk":"11787893647","pt":1722467457761,"mc":[{"id":"1.231241311","rc":[{"batb":[[0,2.36,10],[1,2.34,167.94],[2,2.12,54.28]],"ltp":2.38,"tv":420.39,"id":26354922}]}]}
{"op":"mcm","clk":"11787893862","pt":1722467461267,"mc":[{"id":"1.231241311","rc":[{"batb":[[0,2.34,167.94],[1,2.12,54.28],[2,1.1,10000]],"ltp":2.38,"tv":420.39,"id":26354922}]}]}
{"op":"mcm","clk":"11787894065","pt":1722467463587,"mc":[{"id":"1.231241311","rc":[{"batb":[[0,2.36,10],[1,2.34,167.94],[2,2.12,54.28]],"ltp":2.38,"tv":420.39,"id":26354922}]}]}
{"op":"mcm","clk":"11787894257","pt":1722467466887,"mc":[{"id":"1.231241311","rc":[{"batb":[[0,2.34,167.94],[1,2.12,54.28],[2,1.1,10000]],"ltp":2.38,"tv":420.39,"id":26354922}]}]}
{"op":"mcm","clk":"11787894368","pt":1722467469102,"mc":[{"id":"1.231241311","rc":[{"batb":[[0,2.36,10],[1,2.34,167.94],[2,2.12,54.28]],"ltp":2.38,"tv":420.39,"id":26354922}]}]}
{"op":"mcm","clk":"11787894542","pt":1722467472467,"mc":[{"id":"1.231241311","rc":[{"batb":[[0,2.34,167.94],[1,2.12,54.28],[2,1.1,10000]],"ltp":2.38,"tv":420.39,"id":26354922}]}]}
{"op":"mcm","clk":"11787894752","pt":1722467474993,"mc":[{"id":"1.231241311","rc":[{"batb":[[0,2.36,10],[1,2.34,167.94],[2,2.12,54.28]],"ltp":2.38,"tv":420.39,"id":26354922}]}]}
{"op":"mcm","clk":"11787894924","pt":1722467478596,"mc":[{"id":"1.231241311","rc":[{"batb":[[0,2.34,167.94],[1,2.12,54.28],[2,1.1,10000]],"ltp":2.38,"tv":420.39,"id":26354922}]}]}
{"op":"mcm","clk":"11787895085","pt":1722467481691,"mc":[{"id":"1.231241311","rc":[{"batb":[[0,2.36,10],[1,2.34,167.94],[2,2.12,54.28]],"ltp":2.38,"tv":420.39,"id":26354922}]}]}
{"op":"mcm","clk":"11787895257","pt":1722467484992,"mc":[{"id":"1.231241311","rc":[{"batb":[[0,2.34,167.94],[1,2.12,54.28],[2,1.1,10000]],"ltp":2.38,"tv":420.39,"id":26354922}]}]}
{"op":"mcm","clk":"11787895377","pt":1722467487413,"mc":[{"id":"1.231241311","rc":[{"batb":[[0,2.36,10],[1,2.34,167.94],[2,2.12,54.28]],"ltp":2.38,"tv":420.39,"id":26354922}]}]}
{"op":"mcm","clk":"11787895588","pt":1722467490718,"mc":[{"id":"1.231241311","rc":[{"batb":[[0,2.34,167.94],[1,2.12,54.28],[2,1.1,10000]],"ltp":2.38,"tv":420.39,"id":26354922}]}]}
{"op":"mcm","clk":"11787895752","pt":1722467493237,"mc":[{"id":"1.231241311","rc":[{"batb":[[0,2.36,10],[1,2.34,167.94],[2,2.12,54.28]],"ltp":2.38,"tv":420.39,"id":26354922}]}]}
{"op":"mcm","clk":"11787895952","pt":1722467496643,"mc":[{"id":"1.231241311","rc":[{"batb":[[0,2.34,167.94],[1,2.12,54.28],[2,1.1,10000]],"ltp":2.38,"tv":420.39,"id":26354922}]}]}
{"op":"mcm","clk":"11787896098","pt":1722467498712,"mc":[{"id":"1.231241311","rc":[{"batb":[[0,2.36,10],[1,2.34,167.94],[2,2.12,54.28]],"ltp":2.38,"tv":420.39,"id":26354922}]}]}
{"op":"mcm","clk":"11787896308","pt":1722467502063,"mc":[{"id":"1.231241311","rc":[{"batb":[[0,2.34,167.94],[1,2.12,54.28],[2,1.1,10000]],"ltp":2.38,"tv":420.39,"id":26354922}]}]}
{"op":"mcm","clk":"11787896438","pt":1722467504333,"mc":[{"id":"1.231241311","rc":[{"batb":[[0,2.36,10],[1,2.34,167.94],[2,2.12,54.28]],"ltp":2.38,"tv":420.39,"id":26354922}]}]}
{"op":"mcm","clk":"11787896703","pt":1722467507539,"mc":[{"id":"1.231241311","rc":[{"batb":[[0,2.34,167.94],[1,2.12,54.28],[2,1.1,10000]],"ltp":2.38,"tv":420.39,"id":26354922}]}]}
{"op":"mcm","clk":"11787896852","pt":1722467509957,"mc":[{"id":"1.231241311","rc":[{"batb":[[0,2.36,10],[1,2.34,167.94],[2,2.12,54.28]],"ltp":2.38,"tv":420.39,"id":26354922}]}]}
{"op":"mcm","clk":"11787897073","pt":1722467513361,"mc":[{"id":"1.231241311","rc":[{"batb":[[0,2.34,167.94],[1,2.12,54.28],[2,1.1,10000]],"ltp":2.38,"tv":420.39,"id":26354922}]}]}
{"op":"mcm","clk":"11787897225","pt":1722467515573,"mc":[{"id":"1.231241311","rc":[{"batb":[[0,2.36,10],[1,2.34,167.94],[2,2.12,54.28]],"ltp":2.38,"tv":420.39,"id":26354922}]}]}
{"op":"mcm","clk":"11787897454","pt":1722467519077,"mc":[{"id":"1.231241311","rc":[{"batb":[[0,2.34,167.94],[1,2.12,54.28],[2,1.1,10000]],"ltp":2.38,"tv":420.39,"id":26354922}]}]}
{"op":"mcm","clk":"11787897591","pt":1722467521150,"mc":[{"id":"1.231241311","rc":[{"batb":[[0,2.36,10],[1,2.34,167.94],[2,2.12,54.28]],"ltp":2.38,"tv":420.39,"id":26354922}]}]}
{"op":"mcm","clk":"11787897836","pt":1722467524450,"mc":[{"id":"1.231241311","rc":[{"batb":[[0,2.34,167.94],[1,2.12,54.28],[2,1.1,10000]],"ltp":2.38,"tv":420.39,"id":26354922}]}]}
{"op":"mcm","clk":"11787897994","pt":1722467526866,"mc":[{"id":"1.231241311","rc":[{"batb":[[0,2.36,10],[1,2.34,167.94],[2,2.12,54.28]],"ltp":2.38,"tv":420.39,"id":26354922}]}]}
{"op":"mcm","clk":"11787898228","pt":1722467530475,"mc":[{"id":"1.231241311","rc":[{"batb":[[0,2.34,167.94],[1,2.12,54.28],[2,1.1,10000]],"ltp":2.38,"tv":420.39,"id":26354922}]}]}
{"op":"mcm","clk":"11787898483","pt":1722467533871,"mc":[{"id":"1.231241311","rc":[{"batb":[[0,2.36,10],[1,2.34,167.94],[2,2.12,54.28]],"ltp":2.38,"tv":420.39,"id":26354922}]}]}
{"op":"mcm","clk":"11787898721","pt":1722467537166,"mc":[{"id":"1.231241311","rc":[{"batb":[[0,2.34,167.94],[1,2.12,54.28],[2,1.1,10000]],"ltp":2.38,"tv":420.39,"id":26354922}]}]}
{"op":"mcm","clk":"11787898862","pt":1722467539483,"mc":[{"id":"1.231241311","rc":[{"batb":[[0,2.36,10],[1,2.34,167.94],[2,2.12,54.28]],"ltp":2.38,"tv":420.39,"id":26354922}]}]}
{"op":"mcm","clk":"11787899070","pt":1722467542878,"mc":[{"id":"1.231241311","rc":[{"batb":[[0,2.34,167.94],[1,2.12,54.28],[2,1.1,10000]],"ltp":2.38,"tv":420.39,"id":26354922}]}]}
{"op":"mcm","clk":"11787899252","pt":1722467545513,"mc":[{"id":"1.231241311","rc":[{"batb":[[0,2.36,10],[1,2.34,167.94],[2,2.12,54.28]],"ltp":2.38,"tv":420.39,"id":26354922}]}]}
{"op":"mcm","clk":"11787899479","pt":1722467549116,"mc":[{"id":"1.231241311","rc":[{"batb":[[0,2.34,167.94],[1,2.12,54.28],[2,1.1,10000]],"ltp":2.38,"tv":420.39,"id":26354922}]}]}
{"op":"mcm","clk":"11787899617","pt":1722467551382,"mc":[{"id":"1.231241311","rc":[{"batb":[[0,2.36,10],[1,2.34,167.94],[2,2.12,54.28]],"ltp":2.38,"tv":420.39,"id":26354922}]}]}
{"op":"mcm","clk":"11787899844","pt":1722467554783,"mc":[{"id":"1.231241311","rc":[{"batb":[[0,2.34,167.94],[1,2.12,54.28],[2,1.1,10000]],"ltp":2.38,"tv":420.39,"id":26354922}]}]}
{"op":"mcm","clk":"11787899985","pt":1722467557201,"mc":[{"id":"1.231241311","rc":[{"batb":[[0,2.36,10],[1,2.34,167.94],[2,2.12,54.28]],"ltp":2.38,"tv":420.39,"id":26354922}]}]}
{"op":"mcm","clk":"11787900211","pt":1722467560506,"mc":[{"id":"1.231241311","rc":[{"batb":[[0,2.34,167.94],[1,2.12,54.28],[2,1.1,10000]],"ltp":2.38,"tv":420.39,"id":26354922}]}]}
{"op":"mcm","clk":"11787900380","pt":1722467563190,"mc":[{"id":"1.231241311","rc":[{"batb":[[0,2.36,10],[1,2.34,167.94],[2,2.12,54.28]],"ltp":2.38,"tv":420.39,"id":26354922}]}]}
{"op":"mcm","clk":"11787900588","pt":1722467566889,"mc":[{"id":"1.231241311","rc":[{"batb":[[0,2.34,167.94],[1,2.12,54.28],[2,1.1,10000]],"ltp":2.38,"tv":420.39,"id":26354922}]}]}
{"op":"mcm","clk":"11787900723","pt":1722467569104,"mc":[{"id":"1.231241311","rc":[{"batb":[[0,2.36,10],[1,2.34,167.94],[2,2.12,54.28]],"ltp":2.38,"tv":420.39,"id":26354922}]}]}
{"op":"mcm","clk":"11787900897","pt":1722467572498,"mc":[{"id":"1.231241311","rc":[{"batb":[[0,2.34,167.94],[1,2.12,54.28],[2,1.1,10000]],"ltp":2.38,"tv":420.39,"id":26354922}]}]}
{"op":"mcm","clk":"11787908380","pt":1722467575073,"mc":[{"id":"1.231241311","rc":[{"batb":[[0,2.36,10],[1,2.34,167.94],[2,2.12,54.28]],"ltp":2.38,"tv":420.39,"id":26354922}]}]}
{"op":"mcm","clk":"11787908556","pt":1722467578215,"mc":[{"id":"1.231241311","rc":[{"batb":[[0,2.34,167.94],[1,2.12,54.28],[2,1.1,10000]],"ltp":2.38,"tv":420.39,"id":26354922}]}]}
{"op":"mcm","clk":"11787908709","pt":1722467580529,"mc":[{"id":"1.231241311","rc":[{"batb":[[0,2.36,10],[1,2.34,167.94],[2,2.12,54.28]],"ltp":2.38,"tv":420.39,"id":26354922}]}]}
{"op":"mcm","clk":"11787908910","pt":1722467583946,"mc":[{"id":"1.231241311","rc":[{"batb":[[0,2.34,167.94],[1,2.12,54.28],[2,1.1,10000]],"ltp":2.38,"tv":420.39,"id":26354922}]}]}
{"op":"mcm","clk":"11787909062","pt":1722467586418,"mc":[{"id":"1.231241311","rc":[{"batb":[[0,2.36,10],[1,2.34,167.94],[2,2.12,54.28]],"ltp":2.38,"tv":420.39,"id":26354922}]}]}
{"op":"mcm","clk":"11787909289","pt":1722467589820,"mc":[{"id":"1.231241311","rc":[{"batb":[[0,2.34,167.94],[1,2.12,54.28],[2,1.1,10000]],"ltp":2.38,"tv":420.39,"id":26354922}]}]}
{"op":"mcm","clk":"11787909447","pt":1722467592552,"mc":[{"id":"1.231241311","rc":[{"batb":[[0,2.36,10],[1,2.34,167.94],[2,2.12,54.28]],"ltp":2.38,"tv":420.39,"id":26354922}]}]}
{"op":"mcm","clk":"11787909682","pt":1722467595959,"mc":[{"id":"1.231241311","rc":[{"batb":[[0,2.34,167.94],[1,2.12,54.28],[2,1.1,10000]],"ltp":2.38,"tv":420.39,"id":26354922}]}]}
{"op":"mcm","clk":"11787909840","pt":1722467598226,"mc":[{"id":"1.231241311","rc":[{"batb":[[0,2.36,10],[1,2.34,167.94],[2,2.12,54.28]],"ltp":2.38,"tv":420.39,"id":26354922}]}]}
{"op":"mcm","clk":"11787910100","pt":1722467601736,"mc":[{"id":"1.231241311","rc":[{"batb":[[0,2.34,167.94],[1,2.12,54.28],[2,1.1,10000]],"ltp":2.38,"tv":420.39,"id":26354922}]}]}
{"op":"mcm","clk":"11787910235","pt":1722467604159,"mc":[{"id":"1.231241311","rc":[{"batb":[[0,2.36,10],[1,2.34,167.94],[2,2.12,54.28]],"ltp":2.38,"tv":420.39,"id":26354922}]}]}
{"op":"mcm","clk":"11787910434","pt":1722467607459,"mc":[{"id":"1.231241311","rc":[{"batb":[[0,2.34,167.94],[1,2.12,54.28],[2,1.1,10000]],"ltp":2.38,"tv":420.39,"id":26354922}]}]}
{"op":"mcm","clk":"11787910573","pt":1722467609774,"mc":[{"id":"1.231241311","rc":[{"batb":[[0,2.36,10],[1,2.34,167.94],[2,2.12,54.28]],"ltp":2.38,"tv":420.39,"id":26354922}]}]}
{"op":"mcm","clk":"11787910806","pt":1722467613047,"mc":[{"id":"1.231241311","rc":[{"batb":[[0,2.34,167.94],[1,2.12,54.28],[2,1.1,10000]],"ltp":2.38,"tv":420.39,"id":26354922}]}]}
{"op":"mcm","clk":"11787910943","pt":1722467615468,"mc":[{"id":"1.231241311","rc":[{"batb":[[0,2.36,10],[1,2.34,167.94],[2,2.12,54.28]],"ltp":2.38,"tv":420.39,"id":26354922}]}]}
{"op":"mcm","clk":"11787911125","pt":1722467618770,"mc":[{"id":"1.231241311","rc":[{"batb":[[0,2.34,167.94],[1,2.12,54.28],[2,1.1,10000]],"ltp":2.38,"tv":420.39,"id":26354922}]}]}
{"op":"mcm","clk":"11787911280","pt":1722467621094,"mc":[{"id":"1.231241311","rc":[{"batb":[[0,2.36,10],[1,2.34,167.94],[2,2.12,54.28]],"ltp":2.38,"tv":420.39,"id":26354922}]}]}
{"op":"mcm","clk":"11787911435","pt":1722467624284,"mc":[{"id":"1.231241311","rc":[{"batb":[[0,2.34,167.94],[1,2.12,54.28],[2,1.1,10000]],"ltp":2.38,"tv":420.39,"id":26354922}]}]}
{"op":"mcm","clk":"11787911555","pt":1722467626760,"mc":[{"id":"1.231241311","rc":[{"batb":[[0,2.36,10],[1,2.34,167.94],[2,2.12,54.28]],"ltp":2.38,"tv":420.39,"id":26354922}]}]}
{"op":"mcm","clk":"11787911737","pt":1722467630158,"mc":[{"id":"1.231241311","rc":[{"batb":[[0,2.34,167.94],[1,2.12,54.28],[2,1.1,10000]],"ltp":2.38,"tv":420.39,"id":26354922}]}]}
{"op":"mcm","clk":"11787911974","pt":1722467633979,"mc":[{"id":"1.231241311","rc":[{"batb":[[0,2.36,10],[1,2.34,167.94],[2,2.12,54.28]],"ltp":2.38,"tv":420.39,"id":26354922}]}]}
{"op":"mcm","clk":"11787912209","pt":1722467637693,"mc":[{"id":"1.231241311","rc":[{"batb":[[0,2.34,167.94],[1,2.12,54.28],[2,1.1,10000]],"ltp":2.38,"tv":420.39,"id":26354922}]}]}
{"op":"mcm","clk":"11787912351","pt":1722467640103,"mc":[{"id":"1.231241311","rc":[{"batb":[[0,2.36,10],[1,2.34,167.94],[2,2.12,54.28]],"ltp":2.38,"tv":420.39,"id":26354922}]}]}
{"op":"mcm","clk":"11787912554","pt":1722467643422,"mc":[{"id":"1.231241311","rc":[{"batb":[[0,2.34,167.94],[1,2.12,54.28],[2,1.1,10000]],"ltp":2.38,"tv":420.39,"id":26354922}]}]}
{"op":"mcm","clk":"11787912704","pt":1722467645997,"mc":[{"id":"1.231241311","rc":[{"batb":[[0,2.36,10],[1,2.34,167.94],[2,2.12,54.28]],"ltp":2.38,"tv":420.39,"id":26354922}]}]}
{"op":"mcm","clk":"11787912893","pt":1722467649294,"mc":[{"id":"1.231241311","rc":[{"batb":[[0,2.34,167.94],[1,2.12,54.28],[2,1.1,10000]],"ltp":2.38,"tv":420.39,"id":26354922}]}]}
{"op":"mcm","clk":"11787913019","pt":1722467651721,"mc":[{"id":"1.231241311","rc":[{"batb":[[0,2.36,10],[1,2.34,167.94],[2,2.12,54.28]],"ltp":2.38,"tv":420.39,"id":26354922}]}]}
{"op":"mcm","clk":"11787913195","pt":1722467655032,"mc":[{"id":"1.231241311","rc":[{"batb":[[0,2.34,167.94],[1,2.12,54.28],[2,1.1,10000]],"ltp":2.38,"tv":420.39,"id":26354922}]}]}
{"op":"mcm","clk":"11787913313","pt":1722467657517,"mc":[{"id":"1.231241311","rc":[{"batb":[[0,2.36,10],[1,2.34,167.94],[2,2.12,54.28]],"ltp":2.38,"tv":420.39,"id":26354922}]}]}
{"op":"mcm","clk":"11787913510","pt":1722467660821,"mc":[{"id":"1.231241311","rc":[{"batb":[[0,2.34,167.94],[1,2.12,54.28],[2,1.1,10000]],"ltp":2.38,"tv":420.39,"id":26354922}]}]}
{"op":"mcm","clk":"11787913642","pt":1722467663347,"mc":[{"id":"1.231241311","rc":[{"batb":[[0,2.36,10],[1,2.34,167.94],[2,2.12,54.28]],"ltp":2.38,"tv":420.39,"id":26354922}]}]}
{"op":"mcm","clk":"11787913838","pt":1722467666746,"mc":[{"id":"1.231241311","rc":[{"batb":[[0,2.34,167.94],[1,2.12,54.28],[2,1.1,10000]],"ltp":2.38,"tv":420.39,"id":26354922}]}]}
{"op":"mcm","clk":"11787913988","pt":1722467669165,"mc":[{"id":"1.231241311","rc":[{"batb":[[0,2.36,10],[1,2.34,167.94],[2,2.12,54.28]],"ltp":2.38,"tv":420.39,"id":26354922}]}]}
{"op":"mcm","clk":"11787914180","pt":1722467672565,"mc":[{"id":"1.231241311","rc":[{"batb":[[0,2.34,167.94],[1,2.12,54.28],[2,1.1,10000]],"ltp":2.38,"tv":420.39,"id":26354922}]}]}
{"op":"mcm","clk":"11787914307","pt":1722467674835,"mc":[{"id":"1.231241311","rc":[{"batb":[[0,2.36,10],[1,2.34,167.94],[2,2.12,54.28]],"ltp":2.38,"tv":420.39,"id":26354922}]}]}
{"op":"mcm","clk":"11787914518","pt":1722467678339,"mc":[{"id":"1.231241311","rc":[{"batb":[[0,2.34,167.94],[1,2.12,54.28],[2,1.1,10000]],"ltp":2.38,"tv":420.39,"id":26354922}]}]}
{"op":"mcm","clk":"11787914648","pt":1722467680762,"mc":[{"id":"1.231241311","rc":[{"batb":[[0,2.36,10],[1,2.34,167.94],[2,2.12,54.28]],"ltp":2.38,"tv":420.39,"id":26354922}]}]}
{"op":"mcm","clk":"11787914815","pt":1722467684058,"mc":[{"id":"1.231241311","rc":[{"batb":[[0,2.34,167.94],[1,2.12,54.28],[2,1.1,10000]],"ltp":2.38,"tv":420.39,"id":26354922}]}]}
{"op":"mcm","clk":"11787914944","pt":1722467686438,"mc":[{"id":"1.231241311","rc":[{"batb":[[0,2.36,10],[1,2.34,167.94],[2,2.12,54.28]],"ltp":2.38,"tv":420.39,"id":26354922}]}]}
{"op":"mcm","clk":"11787915141","pt":1722467689882,"mc":[{"id":"1.231241311","rc":[{"batb":[[0,2.34,167.94],[1,2.12,54.28],[2,1.1,10000]],"ltp":2.38,"tv":420.39,"id":26354922}]}]}
{"op":"mcm","clk":"11787915273","pt":1722467692206,"mc":[{"id":"1.231241311","rc":[{"batb":[[0,2.36,10],[1,2.34,167.94],[2,2.12,54.28]],"ltp":2.38,"tv":420.39,"id":26354922}]}]}
{"op":"mcm","clk":"11787915458","pt":1722467695597,"mc":[{"id":"1.231241311","rc":[{"batb":[[0,2.34,167.94],[1,2.12,54.28],[2,1.1,10000]],"ltp":2.38,"tv":420.39,"id":26354922}]}]}
{"op":"mcm","clk":"11787915572","pt":1722467697868,"mc":[{"id":"1.231241311","rc":[{"batb":[[0,2.36,10],[1,2.34,167.94],[2,2.12,54.28]],"ltp":2.38,"tv":420.39,"id":26354922}]}]}
{"op":"mcm","clk":"11787915776","pt":1722467701280,"mc":[{"id":"1.231241311","rc":[{"batb":[[0,2.34,167.94],[1,2.12,54.28],[2,1.1,10000]],"ltp":2.38,"tv":420.39,"id":26354922}]}]}
{"op":"mcm","clk":"11787915894","pt":1722467703601,"mc":[{"id":"1.231241311","rc":[{"batb":[[0,2.36,10],[1,2.34,167.94],[2,2.12,54.28]],"ltp":2.38,"tv":420.39,"id":26354922}]}]}
{"op":"mcm","clk":"11787916099","pt":1722467706903,"mc":[{"id":"1.231241311","rc":[{"batb":[[0,2.34,167.94],[1,2.12,54.28],[2,1.1,10000]],"ltp":2.38,"tv":420.39,"id":26354922}]}]}
{"op":"mcm","clk":"11787916233","pt":1722467709178,"mc":[{"id":"1.231241311","rc":[{"batb":[[0,2.36,10],[1,2.34,167.94],[2,2.12,54.28]],"ltp":2.38,"tv":420.39,"id":26354922}]}]}
{"op":"mcm","clk":"11787916432","pt":1722467712625,"mc":[{"id":"1.231241311","rc":[{"batb":[[0,2.34,167.94],[1,2.12,54.28],[2,1.1,10000]],"ltp":2.38,"tv":420.39,"id":26354922}]}]}
{"op":"mcm","clk":"11787916641","pt":1722467715416,"mc":[{"id":"1.231241311","rc":[{"batb":[[0,2.36,10],[1,2.34,167.94],[2,2.12,54.28]],"ltp":2.38,"tv":420.39,"id":26354922}]}]}
{"op":"mcm","clk":"11787916831","pt":1722467718802,"mc":[{"id":"1.231241311","rc":[{"batb":[[0,2.34,167.94],[1,2.12,54.28],[2,1.1,10000]],"ltp":2.38,"tv":420.39,"id":26354922}]}]}
{"op":"mcm","clk":"11787916986","pt":1722467721395,"mc":[{"id":"1.231241311","rc":[{"batb":[[0,2.36,10],[1,2.34,167.94],[2,2.12,54.28]],"ltp":2.38,"tv":420.39,"id":26354922}]}]}
{"op":"mcm","clk":"11787917189","pt":1722467724702,"mc":[{"id":"1.231241311","rc":[{"batb":[[0,2.34,167.94],[1,2.12,54.28],[2,1.1,10000]],"ltp":2.38,"tv":420.39,"id":26354922}]}]}
{"op":"mcm","clk":"11787917353","pt":1722467727230,"mc":[{"id":"1.231241311","rc":[{"batb":[[0,2.36,10],[1,2.34,167.94],[2,2.12,54.28]],"ltp":2.38,"tv":420.39,"id":26354922}]}]}
{"op":"mcm","clk":"11787917559","pt":1722467730524,"mc":[{"id":"1.231241311","rc":[{"batb":[[0,2.34,167.94],[1,2.12,54.28],[2,1.1,10000]],"ltp":2.38,"tv":420.39,"id":26354922}]}]}
{"op":"mcm","clk":"11787917685","pt":1722467732814,"mc":[{"id":"1.231241311","rc":[{"batb":[[0,2.36,10],[1,2.34,167.94],[2,2.12,54.28]],"ltp":2.38,"tv":420.39,"id":26354922}]}]}
{"op":"mcm","clk":"11787917908","pt":1722467736095,"mc":[{"id":"1.231241311","rc":[{"batb":[[0,2.34,167.94],[1,2.12,54.28],[2,1.1,10000]],"ltp":2.38,"tv":420.39,"id":26354922}]}]}
{"op":"mcm","clk":"11787918168","pt":1722467739811,"mc":[{"id":"1.231241311","rc":[{"batb":[[0,2.36,10],[1,2.34,167.94],[2,2.12,54.28]],"ltp":2.38,"tv":420.39,"id":26354922}]}]}
{"op":"mcm","clk":"11787918463","pt":1722467743428,"mc":[{"id":"1.231241311","rc":[{"batb":[[0,2.34,167.94],[1,2.12,54.28],[2,1.1,10000]],"ltp":2.38,"tv":420.39,"id":26354922}]}]}
{"op":"mcm","clk":"11787918620","pt":1722467745639,"mc":[{"id":"1.231241311","rc":[{"batb":[[0,2.36,10],[1,2.34,167.94],[2,2.12,54.28]],"ltp":2.38,"tv":420.39,"id":26354922}]}]}
{"op":"mcm","clk":"11787918862","pt":1722467749247,"mc":[{"id":"1.231241311","rc":[{"batb":[[0,2.34,167.94],[1,2.12,54.28],[2,1.1,10000]],"ltp":2.38,"tv":420.39,"id":26354922}]}]}
{"op":"mcm","clk":"11787918998","pt":1722467751308,"mc":[{"id":"1.231241311","rc":[{"batb":[[0,2.36,10],[1,2.34,167.94],[2,2.12,54.28]],"ltp":2.38,"tv":420.39,"id":26354922}]}]}
{"op":"mcm","clk":"11787919211","pt":1722467754758,"mc":[{"id":"1.231241311","rc":[{"batb":[[0,2.34,167.94],[1,2.12,54.28],[2,1.1,10000]],"ltp":2.38,"tv":420.39,"id":26354922}]}]}
{"op":"mcm","clk":"11787919363","pt":1722467757030,"mc":[{"id":"1.231241311","rc":[{"batb":[[0,2.36,10],[1,2.34,167.94],[2,2.12,54.28]],"ltp":2.38,"tv":420.39,"id":26354922}]}]}
{"op":"mcm","clk":"11787919606","pt":1722467760636,"mc":[{"id":"1.231241311","rc":[{"batb":[[0,2.34,167.94],[1,2.12,54.28],[2,1.1,10000]],"ltp":2.38,"tv":420.39,"id":26354922}]}]}
{"op":"mcm","clk":"11787919839","pt":1722467763940,"mc":[{"id":"1.231241311","rc":[{"batb":[[0,2.36,10],[1,2.34,167.94],[2,2.12,54.28]],"ltp":2.38,"tv":420.39,"id":26354922}]}]}
{"op":"mcm","clk":"11787920080","pt":1722467767458,"mc":[{"id":"1.231241311","rc":[{"batb":[[0,2.34,167.94],[1,2.12,54.28],[2,1.1,10000]],"ltp":2.38,"tv":420.39,"id":26354922}]}]}
{"op":"mcm","clk":"11787920256","pt":1722467769789,"mc":[{"id":"1.231241311","rc":[{"batb":[[0,2.36,10],[1,2.34,167.94],[2,2.12,54.28]],"ltp":2.38,"tv":420.39,"id":26354922}]}]}
{"op":"mcm","clk":"11787920484","pt":1722467773040,"mc":[{"id":"1.231241311","rc":[{"batb":[[0,2.34,167.94],[1,2.12,54.28],[2,1.1,10000]],"ltp":2.38,"tv":420.39,"id":26354922}]}]}
{"op":"mcm","clk":"11787920628","pt":1722467775354,"mc":[{"id":"1.231241311","rc":[{"batb":[[0,2.36,10],[1,2.34,167.94],[2,2.12,54.28]],"ltp":2.38,"tv":420.39,"id":26354922}]}]}
{"op":"mcm","clk":"11787920871","pt":1722467778768,"mc":[{"id":"1.231241311","rc":[{"batb":[[0,2.34,167.94],[1,2.12,54.28],[2,1.1,10000]],"ltp":2.38,"tv":420.39,"id":26354922}]}]}
{"op":"mcm","clk":"11787921027","pt":1722467781088,"mc":[{"id":"1.231241311","rc":[{"batb":[[0,2.36,10],[1,2.34,167.94],[2,2.12,54.28]],"ltp":2.38,"tv":420.39,"id":26354922}]}]}
{"op":"mcm","clk":"11787921252","pt":1722467784391,"mc":[{"id":"1.231241311","rc":[{"batb":[[0,2.34,167.94],[1,2.12,54.28],[2,1.1,10000]],"ltp":2.38,"tv":420.39,"id":26354922}]}]}
{"op":"mcm","clk":"11787921478","pt":1722467787488,"mc":[{"id":"1.231241311","rc":[{"batb":[[0,2.36,10],[1,2.34,167.94],[2,2.12,54.28]],"ltp":2.38,"tv":420.39,"id":26354922}]}]}
{"op":"mcm","clk":"11787921702","pt":1722467790887,"mc":[{"id":"1.231241311","rc":[{"batb":[[0,2.34,167.94],[1,2.12,54.28],[2,1.1,10000]],"ltp":2.38,"tv":420.39,"id":26354922}]}]}
{"op":"mcm","clk":"11787921836","pt":1722467793203,"mc":[{"id":"1.231241311","rc":[{"batb":[[0,2.36,10],[1,2.34,167.94],[2,2.12,54.28]],"ltp":2.38,"tv":420.39,"id":26354922}]}]}
{"op":"mcm","clk":"11787922053","pt":1722467796655,"mc":[{"id":"1.231241311","rc":[{"batb":[[0,2.34,167.94],[1,2.12,54.28],[2,1.1,10000]],"ltp":2.38,"tv":420.39,"id":26354922}]}]}
{"op":"mcm","clk":"11787922191","pt":1722467798976,"mc":[{"id":"1.231241311","rc":[{"batb":[[0,2.36,10],[1,2.34,167.94],[2,2.12,54.28]],"ltp":2.38,"tv":420.39,"id":26354922}]}]}
{"op":"mcm","clk":"11787922380","pt":1722467802387,"mc":[{"id":"1.231241311","rc":[{"batb":[[0,2.34,167.94],[1,2.12,54.28],[2,1.1,10000]],"ltp":2.38,"tv":420.39,"id":26354922}]}]}
{"op":"mcm","clk":"11787922558","pt":1722467804805,"mc":[{"id":"1.231241311","rc":[{"batb":[[0,2.36,10],[1,2.34,167.94],[2,2.12,54.28]],"ltp":2.38,"tv":420.39,"id":26354922}]}]}
{"op":"mcm","clk":"11787922822","pt":1722467808113,"mc":[{"id":"1.231241311","rc":[{"batb":[[0,2.34,167.94],[1,2.12,54.28],[2,1.1,10000]],"ltp":2.38,"tv":420.39,"id":26354922}]}]}
{"op":"mcm","clk":"11787922945","pt":1722467810378,"mc":[{"id":"1.231241311","rc":[{"batb":[[0,2.36,10],[1,2.34,167.94],[2,2.12,54.28]],"ltp":2.38,"tv":420.39,"id":26354922}]}]}
{"op":"mcm","clk":"11787923199","pt":1722467813926,"mc":[{"id":"1.231241311","rc":[{"batb":[[0,2.34,167.94],[1,2.12,54.28],[2,1.1,10000]],"ltp":2.38,"tv":420.39,"id":26354922}]}]}
{"op":"mcm","clk":"11787923352","pt":1722467816193,"mc":[{"id":"1.231241311","rc":[{"batb":[[0,2.36,10],[1,2.34,167.94],[2,2.12,54.28]],"ltp":2.38,"tv":420.39,"id":26354922}]}]}
{"op":"mcm","clk":"11787923547","pt":1722467819538,"mc":[{"id":"1.231241311","rc":[{"batb":[[0,2.34,167.94],[1,2.12,54.28],[2,1.1,10000]],"ltp":2.38,"tv":420.39,"id":26354922}]}]}
{"op":"mcm","clk":"11787923665","pt":1722467821857,"mc":[{"id":"1.231241311","rc":[{"batb":[[0,2.36,10],[1,2.34,167.94],[2,2.12,54.28]],"ltp":2.38,"tv":420.39,"id":26354922}]}]}
{"op":"mcm","clk":"11787923917","pt":1722467825059,"mc":[{"id":"1.231241311","rc":[{"batb":[[0,2.34,167.94],[1,2.12,54.28],[2,1.1,10000]],"ltp":2.38,"tv":420.39,"id":26354922}]}]}
{"op":"mcm","clk":"11787924067","pt":1722467827433,"mc":[{"id":"1.231241311","rc":[{"batb":[[0,2.36,10],[1,2.34,167.94],[2,2.12,54.28]],"ltp":2.38,"tv":420.39,"id":26354922}]}]}
{"op":"mcm","clk":"11787924314","pt":1722467830838,"mc":[{"id":"1.231241311","rc":[{"batb":[[0,2.34,167.94],[1,2.12,54.28],[2,1.1,10000]],"ltp":2.38,"tv":420.39,"id":26354922}]}]}
{"op":"mcm","clk":"11787924464","pt":1722467833258,"mc":[{"id":"1.231241311","rc":[{"batb":[[0,2.36,10],[1,2.34,167.94],[2,2.12,54.28]],"ltp":2.38,"tv":420.39,"id":26354922}]}]}
{"op":"mcm","clk":"11787924675","pt":1722467836655,"mc":[{"id":"1.231241311","rc":[{"batb":[[0,2.34,167.94],[1,2.12,54.28],[2,1.1,10000]],"ltp":2.38,"tv":420.39,"id":26354922}]}]}
{"op":"mcm","clk":"11787924852","pt":1722467839138,"mc":[{"id":"1.231241311","rc":[{"batb":[[0,2.36,10],[1,2.34,167.94],[2,2.12,54.28]],"ltp":2.38,"tv":420.39,"id":26354922}]}]}
{"op":"mcm","clk":"11787925073","pt":1722467842552,"mc":[{"id":"1.231241311","rc":[{"batb":[[0,2.34,167.94],[1,2.12,54.28],[2,1.1,10000]],"ltp":2.38,"tv":420.39,"id":26354922}]}]}
{"op":"mcm","clk":"11787925207","pt":1722467844966,"mc":[{"id":"1.231241311","rc":[{"batb":[[0,2.36,10],[1,2.34,167.94],[2,2.12,54.28]],"ltp":2.38,"tv":420.39,"id":26354922}]}]}
{"op":"mcm","clk":"11787925444","pt":1722467848470,"mc":[{"id":"1.231241311","rc":[{"batb":[[0,2.34,167.94],[1,2.12,54.28],[2,1.1,10000]],"ltp":2.38,"tv":420.39,"id":26354922}]}]}
{"op":"mcm","clk":"11787925586","pt":1722467850639,"mc":[{"id":"1.231241311","rc":[{"batb":[[0,2.36,10],[1,2.34,167.94],[2,2.12,54.28]],"ltp":2.38,"tv":420.39,"id":26354922}]}]}
{"op":"mcm","clk":"11787925790","pt":1722467853948,"mc":[{"id":"1.231241311","rc":[{"batb":[[0,2.34,167.94],[1,2.12,54.28],[2,1.1,10000]],"ltp":2.38,"tv":420.39,"id":26354922}]}]}
{"op":"mcm","clk":"11787925916","pt":1722467856061,"mc":[{"id":"1.231241311","rc":[{"batb":[[0,2.36,10],[1,2.34,167.94],[2,2.12,54.28]],"ltp":2.38,"tv":420.39,"id":26354922}]}]}
{"op":"mcm","clk":"11787926124","pt":1722467859560,"mc":[{"id":"1.231241311","rc":[{"batb":[[0,2.34,167.94],[1,2.12,54.28],[2,1.1,10000]],"ltp":2.38,"tv":420.39,"id":26354922}]}]}
{"op":"mcm","clk":"11787926353","pt":1722467862868,"mc":[{"id":"1.231241311","rc":[{"batb":[[0,2.36,10],[1,2.34,167.94],[2,2.12,54.28]],"ltp":2.38,"tv":420.39,"id":26354922}]}]}
{"op":"mcm","clk":"11787926522","pt":1722467866166,"mc":[{"id":"1.231241311","rc":[{"batb":[[0,2.34,167.94],[1,2.12,54.28],[2,1.1,10000]],"ltp":2.38,"tv":420.39,"id":26354922}]}]}
{"op":"mcm","clk":"11787926635","pt":1722467868476,"mc":[{"id":"1.231241311","rc":[{"batb":[[0,2.36,10],[1,2.34,167.94],[2,2.12,54.28]],"ltp":2.38,"tv":420.39,"id":26354922}]}]}
{"op":"mcm","clk":"11787926834","pt":1722467871976,"mc":[{"id":"1.231241311","rc":[{"batb":[[0,2.34,167.94],[1,2.12,54.28],[2,1.1,10000]],"ltp":2.38,"tv":420.39,"id":26354922}]}]}
{"op":"mcm","clk":"11787926962","pt":1722467874394,"mc":[{"id":"1.231241311","rc":[{"batb":[[0,2.36,10],[1,2.34,167.94],[2,2.12,54.28]],"ltp":2.38,"tv":420.39,"id":26354922}]}]}
{"op":"mcm","clk":"11787927135","pt":1722467877798,"mc":[{"id":"1.231241311","rc":[{"batb":[[0,2.34,167.94],[1,2.12,54.28],[2,1.1,10000]],"ltp":2.38,"tv":420.39,"id":26354922}]}]}
{"op":"mcm","clk":"11787927261","pt":1722467880112,"mc":[{"id":"1.231241311","rc":[{"batb":[[0,2.36,10],[1,2.34,167.94],[2,2.12,54.28]],"ltp":2.38,"tv":420.39,"id":26354922}]}]}
{"op":"mcm","clk":"11787927457","pt":1722467883508,"mc":[{"id":"1.231241311","rc":[{"batb":[[0,2.34,167.94],[1,2.12,54.28],[2,1.1,10000]],"ltp":2.38,"tv":420.39,"id":26354922}]}]}
{"op":"mcm","clk":"11787927603","pt":1722467885776,"mc":[{"id":"1.231241311","rc":[{"batb":[[0,2.36,10],[1,2.34,167.94],[2,2.12,54.28]],"ltp":2.38,"tv":420.39,"id":26354922}]}]}
{"op":"mcm","clk":"11787927817","pt":1722467889421,"mc":[{"id":"1.231241311","rc":[{"batb":[[0,2.34,167.94],[1,2.12,54.28],[2,1.1,10000]],"ltp":2.38,"tv":420.39,"id":26354922}]}]}
{"op":"mcm","clk":"11787927953","pt":1722467891690,"mc":[{"id":"1.231241311","rc":[{"batb":[[0,2.36,10],[1,2.34,167.94],[2,2.12,54.28]],"ltp":2.38,"tv":420.39,"id":26354922}]}]}
{"op":"mcm","clk":"11787928140","pt":1722467894992,"mc":[{"id":"1.231241311","rc":[{"batb":[[0,2.34,167.94],[1,2.12,54.28],[2,1.1,10000]],"ltp":2.38,"tv":420.39,"id":26354922}]}]}
{"op":"mcm","clk":"11787928275","pt":1722467897317,"mc":[{"id":"1.231241311","rc":[{"batb":[[0,2.36,10],[1,2.34,167.94],[2,2.12,54.28]],"ltp":2.38,"tv":420.39,"id":26354922}]}]}
{"op":"mcm","clk":"11787928485","pt":1722467900523,"mc":[{"id":"1.231241311","rc":[{"batb":[[0,2.34,167.94],[1,2.12,54.28],[2,1.1,10000]],"ltp":2.38,"tv":420.39,"id":26354922}]}]}
{"op":"mcm","clk":"11787928612","pt":1722467902935,"mc":[{"id":"1.231241311","rc":[{"batb":[[0,2.36,10],[1,2.34,167.94],[2,2.12,54.28]],"ltp":2.38,"tv":420.39,"id":26354922}]}]}
{"op":"mcm","clk":"11787928810","pt":1722467906231,"mc":[{"id":"1.231241311","rc":[{"batb":[[0,2.34,167.94],[1,2.12,54.28],[2,1.1,10000]],"ltp":2.38,"tv":420.39,"id":26354922}]}]}
{"op":"mcm","clk":"11787928931","pt":1722467908586,"mc":[{"id":"1.231241311","rc":[{"batb":[[0,2.36,10],[1,2.34,167.94],[2,2.12,54.28]],"ltp":2.38,"tv":420.39,"id":26354922}]}]}
{"op":"mcm","clk":"11787929114","pt":1722467911928,"mc":[{"id":"1.231241311","rc":[{"batb":[[0,2.34,167.94],[1,2.12,54.28],[2,1.1,10000]],"ltp":2.38,"tv":420.39,"id":26354922}]}]}
{"op":"mcm","clk":"11787929269","pt":1722467914298,"mc":[{"id":"1.231241311","rc":[{"batb":[[0,2.36,10],[1,2.34,167.94],[2,2.12,54.28]],"ltp":2.38,"tv":420.39,"id":26354922}]}]}
{"op":"mcm","clk":"11787929490","pt":1722467917755,"mc":[{"id":"1.231241311","rc":[{"batb":[[0,2.34,167.94],[1,2.12,54.28],[2,1.1,10000]],"ltp":2.38,"tv":420.39,"id":26354922}]}]}
{"op":"mcm","clk":"11787929622","pt":1722467920026,"mc":[{"id":"1.231241311","rc":[{"batb":[[0,2.36,10],[1,2.34,167.94],[2,2.12,54.28]],"ltp":2.38,"tv":420.39,"id":26354922}]}]}
{"op":"mcm","clk":"11787929856","pt":1722467923528,"mc":[{"id":"1.231241311","rc":[{"batb":[[0,2.34,167.94],[1,2.12,54.28],[2,1.1,10000]],"ltp":2.38,"tv":420.39,"id":26354922}]}]}
{"op":"mcm","clk":"11787930013","pt":1722467925856,"mc":[{"id":"1.231241311","rc":[{"batb":[[0,2.36,10],[1,2.34,167.94],[2,2.12,54.28]],"ltp":2.38,"tv":420.39,"id":26354922}]}]}
{"op":"mcm","clk":"11787930245","pt":1722467929258,"mc":[{"id":"1.231241311","rc":[{"batb":[[0,2.34,167.94],[1,2.12,54.28],[2,1.1,10000]],"ltp":2.38,"tv":420.39,"id":26354922}]}]}
{"op":"mcm","clk":"11787930429","pt":1722467931639,"mc":[{"id":"1.231241311","rc":[{"batb":[[0,2.36,10],[1,2.34,167.94],[2,2.12,54.28]],"ltp":2.38,"tv":420.39,"id":26354922}]}]}
{"op":"mcm","clk":"11787930674","pt":1722467935247,"mc":[{"id":"1.231241311","rc":[{"batb":[[0,2.34,167.94],[1,2.12,54.28],[2,1.1,10000]],"ltp":2.38,"tv":420.39,"id":26354922}]}]}
{"op":"mcm","clk":"11787930816","pt":1722467937563,"mc":[{"id":"1.231241311","rc":[{"batb":[[0,2.36,10],[1,2.34,167.94],[2,2.12,54.28]],"ltp":2.38,"tv":420.39,"id":26354922}]}]}
{"op":"mcm","clk":"11787931029","pt":1722467940959,"mc":[{"id":"1.231241311","rc":[{"batb":[[0,2.34,167.94],[1,2.12,54.28],[2,1.1,10000]],"ltp":2.38,"tv":420.39,"id":26354922}]}]}
{"op":"mcm","clk":"11787931180","pt":1722467943234,"mc":[{"id":"1.231241311","rc":[{"batb":[[0,2.36,10],[1,2.34,167.94],[2,2.12,54.28]],"ltp":2.38,"tv":420.39,"id":26354922}]}]}
{"op":"mcm","clk":"11787931395","pt":1722467946585,"mc":[{"id":"1.231241311","rc":[{"batb":[[0,2.34,167.94],[1,2.12,54.28],[2,1.1,10000]],"ltp":2.38,"tv":420.39,"id":26354922}]}]}
{"op":"mcm","clk":"11787931544","pt":1722467948855,"mc":[{"id":"1.231241311","rc":[{"batb":[[0,2.36,10],[1,2.34,167.94],[2,2.12,54.28]],"ltp":2.38,"tv":420.39,"id":26354922}]}]}
{"op":"mcm","clk":"11787931759","pt":1722467952254,"mc":[{"id":"1.231241311","rc":[{"batb":[[0,2.34,167.94],[1,2.12,54.28],[2,1.1,10000]],"ltp":2.38,"tv":420.39,"id":26354922}]}]}
{"op":"mcm","clk":"11787931900","pt":1722467954570,"mc":[{"id":"1.231241311","rc":[{"batb":[[0,2.36,10],[1,2.34,167.94],[2,2.12,54.28]],"ltp":2.38,"tv":420.39,"id":26354922}]}]}
{"op":"mcm","clk":"11787932107","pt":1722467957870,"mc":[{"id":"1.231241311","rc":[{"batb":[[0,2.34,167.94],[1,2.12,54.28],[2,1.1,10000]],"ltp":2.38,"tv":420.39,"id":26354922}]}]}
{"op":"mcm","clk":"11787932265","pt":1722467960289,"mc":[{"id":"1.231241311","rc":[{"batb":[[0,2.36,10],[1,2.34,167.94],[2,2.12,54.28]],"ltp":2.38,"tv":420.39,"id":26354922}]}]}
{"op":"mcm","clk":"11787932490","pt":1722467963676,"mc":[{"id":"1.231241311","rc":[{"batb":[[0,2.34,167.94],[1,2.12,54.28],[2,1.1,10000]],"ltp":2.38,"tv":420.39,"id":26354922}]}]}
{"op":"mcm","clk":"11787932635","pt":1722467966002,"mc":[{"id":"1.231241311","rc":[{"batb":[[0,2.36,10],[1,2.34,167.94],[2,2.12,54.28]],"ltp":2.38,"tv":420.39,"id":26354922}]}]}
{"op":"mcm","clk":"11787932832","pt":1722467969253,"mc":[{"id":"1.231241311","rc":[{"batb":[[0,2.34,167.94],[1,2.12,54.28],[2,1.1,10000]],"ltp":2.38,"tv":420.39,"id":26354922}]}]}
{"op":"mcm","clk":"11787932977","pt":1722467971783,"mc":[{"id":"1.231241311","rc":[{"batb":[[0,2.36,10],[1,2.34,167.94],[2,2.12,54.28]],"ltp":2.38,"tv":420.39,"id":26354922}]}]}
{"op":"mcm","clk":"11787933172","pt":1722467975184,"mc":[{"id":"1.231241311","rc":[{"batb":[[0,2.34,167.94],[1,2.12,54.28],[2,1.1,10000]],"ltp":2.38,"tv":420.39,"id":26354922}]}]}
{"op":"mcm","clk":"11787933321","pt":1722467977602,"mc":[{"id":"1.231241311","rc":[{"batb":[[0,2.36,10],[1,2.34,167.94],[2,2.12,54.28]],"ltp":2.38,"tv":420.39,"id":26354922}]}]}
{"op":"mcm","clk":"11787933502","pt":1722467980977,"mc":[{"id":"1.231241311","rc":[{"batb":[[0,2.34,167.94],[1,2.12,54.28],[2,1.1,10000]],"ltp":2.38,"tv":420.39,"id":26354922}]}]}
{"op":"mcm","clk":"11787933652","pt":1722467983299,"mc":[{"id":"1.231241311","rc":[{"batb":[[0,2.36,10],[1,2.34,167.94],[2,2.12,54.28]],"ltp":2.38,"tv":420.39,"id":26354922}]}]}
{"op":"mcm","clk":"11787933838","pt":1722467986695,"mc":[{"id":"1.231241311","rc":[{"batb":[[0,2.34,167.94],[1,2.12,54.28],[2,1.1,10000]],"ltp":2.38,"tv":420.39,"id":26354922}]}]}
{"op":"mcm","clk":"11787933965","pt":1722467988983,"mc":[{"id":"1.231241311","rc":[{"batb":[[0,2.36,10],[1,2.34,167.94],[2,2.12,54.28]],"ltp":2.38,"tv":420.39,"id":26354922}]}]}
{"op":"mcm","clk":"11787934181","pt":1722467992287,"mc":[{"id":"1.231241311","rc":[{"batb":[[0,2.34,167.94],[1,2.12,54.28],[2,1.1,10000]],"ltp":2.38,"tv":420.39,"id":26354922}]}]}
{"op":"mcm","clk":"11787934321","pt":1722467994599,"mc":[{"id":"1.231241311","rc":[{"batb":[[0,2.36,10],[1,2.34,167.94],[2,2.12,54.28]],"ltp":2.38,"tv":420.39,"id":26354922}]}]}
{"op":"mcm","clk":"11787934555","pt":1722467997998,"mc":[{"id":"1.231241311","rc":[{"batb":[[0,2.34,167.94],[1,2.12,54.28],[2,1.1,10000]],"ltp":2.38,"tv":420.39,"id":26354922}]}]}
{"op":"mcm","clk":"11787934696","pt":1722468000414,"mc":[{"id":"1.231241311","rc":[{"batb":[[0,2.36,10],[1,2.34,167.94],[2,2.12,54.28]],"ltp":2.38,"tv":420.39,"id":26354922}]}]}
{"op":"mcm","clk":"11787934939","pt":1722468003816,"mc":[{"id":"1.231241311","rc":[{"batb":[[0,2.34,167.94],[1,2.12,54.28],[2,1.1,10000]],"ltp":2.38,"tv":420.39,"id":26354922}]}]}
{"op":"mcm","clk":"11787935102","pt":1722468006239,"mc":[{"id":"1.231241311","rc":[{"batb":[[0,2.36,10],[1,2.34,167.94],[2,2.12,54.28]],"ltp":2.38,"tv":420.39,"id":26354922}]}]}
{"op":"mcm","clk":"11787935314","pt":1722468009590,"mc":[{"id":"1.231241311","rc":[{"batb":[[0,2.34,167.94],[1,2.12,54.28],[2,1.1,10000]],"ltp":2.38,"tv":420.39,"id":26354922}]}]}
{"op":"mcm","clk":"11787935481","pt":1722468011899,"mc":[{"id":"1.231241311","rc":[{"batb":[[0,2.36,10],[1,2.34,167.94],[2,2.12,54.28]],"ltp":2.38,"tv":420.39,"id":26354922}]}]}
{"op":"mcm","clk":"11787935686","pt":1722468015291,"mc":[{"id":"1.231241311","rc":[{"batb":[[0,2.34,167.94],[1,2.12,54.28],[2,1.1,10000]],"ltp":2.38,"tv":420.39,"id":26354922}]}]}
{"op":"mcm","clk":"11787935826","pt":1722468017605,"mc":[{"id":"1.231241311","rc":[{"batb":[[0,2.36,10],[1,2.34,167.94],[2,2.12,54.28]],"ltp":2.38,"tv":420.39,"id":26354922}]}]}
{"op":"mcm","clk":"11787936068","pt":1722468020896,"mc":[{"id":"1.231241311","rc":[{"batb":[[0,2.34,167.94],[1,2.12,54.28],[2,1.1,10000]],"ltp":2.38,"tv":420.39,"id":26354922}]}]}
{"op":"mcm","clk":"11787936199","pt":1722468023224,"mc":[{"id":"1.231241311","rc":[{"batb":[[0,2.36,10],[1,2.34,167.94],[2,2.12,54.28]],"ltp":2.38,"tv":420.39,"id":26354922}]}]}
{"op":"mcm","clk":"11787936414","pt":1722468026630,"mc":[{"id":"1.231241311","rc":[{"batb":[[0,2.34,167.94],[1,2.12,54.28],[2,1.1,10000]],"ltp":2.38,"tv":420.39,"id":26354922}]}]}
{"op":"mcm","clk":"11787936614","pt":1722468028948,"mc":[{"id":"1.231241311","rc":[{"batb":[[0,2.36,10],[1,2.34,167.94],[2,2.12,54.28]],"ltp":2.38,"tv":420.39,"id":26354922}]}]}
{"op":"mcm","clk":"11787936844","pt":1722468032345,"mc":[{"id":"1.231241311","rc":[{"batb":[[0,2.34,167.94],[1,2.12,54.28],[2,1.1,10000]],"ltp":2.38,"tv":420.39,"id":26354922}]}]}
{"op":"mcm","clk":"11787937016","pt":1722468034718,"mc":[{"id":"1.231241311","rc":[{"batb":[[0,2.36,10],[1,2.34,167.94],[2,2.12,54.28]],"ltp":2.38,"tv":420.39,"id":26354922}]}]}
{"op":"mcm","clk":"11787937232","pt":1722468038123,"mc":[{"id":"1.231241311","rc":[{"batb":[[0,2.34,167.94],[1,2.12,54.28],[2,1.1,10000]],"ltp":2.38,"tv":420.39,"id":26354922}]}]}
{"op":"mcm","clk":"11787937376","pt":1722468040685,"mc":[{"id":"1.231241311","rc":[{"batb":[[0,2.36,10],[1,2.34,167.94],[2,2.12,54.28]],"ltp":2.38,"tv":420.39,"id":26354922}]}]}
{"op":"mcm","clk":"11787937582","pt":1722468044143,"mc":[{"id":"1.231241311","rc":[{"batb":[[0,2.34,167.94],[1,2.12,54.28],[2,1.1,10000]],"ltp":2.38,"tv":420.39,"id":26354922}]}]}
{"op":"mcm","clk":"11787937721","pt":1722468046552,"mc":[{"id":"1.231241311","rc":[{"batb":[[0,2.36,10],[1,2.34,167.94],[2,2.12,54.28]],"ltp":2.38,"tv":420.39,"id":26354922}]}]}
{"op":"mcm","clk":"11787937910","pt":1722468049948,"mc":[{"id":"1.231241311","rc":[{"batb":[[0,2.34,167.94],[1,2.12,54.28],[2,1.1,10000]],"ltp":2.38,"tv":420.39,"id":26354922}]}]}
{"op":"mcm","clk":"11787938051","pt":1722468052257,"mc":[{"id":"1.231241311","rc":[{"batb":[[0,2.36,10],[1,2.34,167.94],[2,2.12,54.28]],"ltp":2.38,"tv":420.39,"id":26354922}]}]}
{"op":"mcm","clk":"11787938252","pt":1722468055755,"mc":[{"id":"1.231241311","rc":[{"batb":[[0,2.34,167.94],[1,2.12,54.28],[2,1.1,10000]],"ltp":2.38,"tv":420.39,"id":26354922}]}]}
{"op":"mcm","clk":"11787938371","pt":1722468058083,"mc":[{"id":"1.231241311","rc":[{"batb":[[0,2.36,10],[1,2.34,167.94],[2,2.12,54.28]],"ltp":2.38,"tv":420.39,"id":26354922}]}]}
{"op":"mcm","clk":"11787938552","pt":1722468061438,"mc":[{"id":"1.231241311","rc":[{"batb":[[0,2.34,167.94],[1,2.12,54.28],[2,1.1,10000]],"ltp":2.38,"tv":420.39,"id":26354922}]}]}
{"op":"mcm","clk":"11787938693","pt":1722468063876,"mc":[{"id":"1.231241311","rc":[{"batb":[[0,2.36,10],[1,2.34,167.94],[2,2.12,54.28]],"ltp":2.38,"tv":420.39,"id":26354922}]}]}
{"op":"mcm","clk":"11787938937","pt":1722468067138,"mc":[{"id":"1.231241311","rc":[{"batb":[[0,2.34,167.94],[1,2.12,54.28],[2,1.1,10000]],"ltp":2.38,"tv":420.39,"id":26354922}]}]}
{"op":"mcm","clk":"11787939095","pt":1722468069473,"mc":[{"id":"1.231241311","rc":[{"batb":[[0,2.36,10],[1,2.34,167.94],[2,2.12,54.28]],"ltp":2.38,"tv":420.39,"id":26354922}]}]}
{"op":"mcm","clk":"11787939336","pt":1722468072877,"mc":[{"id":"1.231241311","rc":[{"batb":[[0,2.34,167.94],[1,2.12,54.28],[2,1.1,10000]],"ltp":2.38,"tv":420.39,"id":26354922}]}]}
{"op":"mcm","clk":"11787939472","pt":1722468075150,"mc":[{"id":"1.231241311","rc":[{"batb":[[0,2.36,10],[1,2.34,167.94],[2,2.12,54.28]],"ltp":2.38,"tv":420.39,"id":26354922}]}]}
{"op":"mcm","clk":"11787939690","pt":1722468078546,"mc":[{"id":"1.231241311","rc":[{"batb":[[0,2.34,167.94],[1,2.12,54.28],[2,1.1,10000]],"ltp":2.38,"tv":420.39,"id":26354922}]}]}
{"op":"mcm","clk":"11787939837","pt":1722468080959,"mc":[{"id":"1.231241311","rc":[{"batb":[[0,2.36,10],[1,2.34,167.94],[2,2.12,54.28]],"ltp":2.38,"tv":420.39,"id":26354922}]}]}
{"op":"mcm","clk":"11787940030","pt":1722468084261,"mc":[{"id":"1.231241311","rc":[{"batb":[[0,2.34,167.94],[1,2.12,54.28],[2,1.1,10000]],"ltp":2.38,"tv":420.39,"id":26354922}]}]}
{"op":"mcm","clk":"11787940175","pt":1722468086583,"mc":[{"id":"1.231241311","rc":[{"batb":[[0,2.36,10],[1,2.34,167.94],[2,2.12,54.28]],"ltp":2.38,"tv":420.39,"id":26354922}]}]}
{"op":"mcm","clk":"11787940382","pt":1722468089983,"mc":[{"id":"1.231241311","rc":[{"batb":[[0,2.34,167.94],[1,2.12,54.28],[2,1.1,10000]],"ltp":2.38,"tv":420.39,"id":26354922}]}]}
{"op":"mcm","clk":"11787940532","pt":1722468092304,"mc":[{"id":"1.231241311","rc":[{"batb":[[0,2.36,10],[1,2.34,167.94],[2,2.12,54.28]],"ltp":2.38,"tv":420.39,"id":26354922}]}]}
{"op":"mcm","clk":"11787940749","pt":1722468095864,"mc":[{"id":"1.231241311","rc":[{"batb":[[0,2.34,167.94],[1,2.12,54.28],[2,1.1,10000]],"ltp":2.38,"tv":420.39,"id":26354922}]}]}
{"op":"mcm","clk":"11787940890","pt":1722468098072,"mc":[{"id":"1.231241311","rc":[{"batb":[[0,2.36,10],[1,2.34,167.94],[2,2.12,54.28]],"ltp":2.38,"tv":420.39,"id":26354922}]}]}
{"op":"mcm","clk":"11787941088","pt":1722468101372,"mc":[{"id":"1.231241311","rc":[{"batb":[[0,2.34,167.94],[1,2.12,54.28],[2,1.1,10000]],"ltp":2.38,"tv":420.39,"id":26354922}]}]}
{"op":"mcm","clk":"11787941231","pt":1722468103903,"mc":[{"id":"1.231241311","rc":[{"batb":[[0,2.36,10],[1,2.34,167.94],[2,2.12,54.28]],"ltp":2.38,"tv":420.39,"id":26354922}]}]}
{"op":"mcm","clk":"11787941477","pt":1722468107380,"mc":[{"id":"1.231241311","rc":[{"batb":[[0,2.34,167.94],[1,2.12,54.28],[2,1.1,10000]],"ltp":2.38,"tv":420.39,"id":26354922}]}]}
{"op":"mcm","clk":"11787941628","pt":1722468109707,"mc":[{"id":"1.231241311","rc":[{"batb":[[0,2.36,10],[1,2.34,167.94],[2,2.12,54.28]],"ltp":2.38,"tv":420.39,"id":26354922}]}]}
{"op":"mcm","clk":"11787941856","pt":1722468112974,"mc":[{"id":"1.231241311","rc":[{"batb":[[0,2.34,167.94],[1,2.12,54.28],[2,1.1,10000]],"ltp":2.38,"tv":420.39,"id":26354922}]}]}
{"op":"mcm","clk":"11787942020","pt":1722468115383,"mc":[{"id":"1.231241311","rc":[{"batb":[[0,2.36,10],[1,2.34,167.94],[2,2.12,54.28]],"ltp":2.38,"tv":420.39,"id":26354922}]}]}
{"op":"mcm","clk":"11787942257","pt":1722468118806,"mc":[{"id":"1.231241311","rc":[{"batb":[[0,2.34,167.94],[1,2.12,54.28],[2,1.1,10000]],"ltp":2.38,"tv":420.39,"id":26354922}]}]}
{"op":"mcm","clk":"11787942411","pt":1722468120988,"mc":[{"id":"1.231241311","rc":[{"batb":[[0,2.36,10],[1,2.34,167.94],[2,2.12,54.28]],"ltp":2.38,"tv":420.39,"id":26354922}]}]}
{"op":"mcm","clk":"11787942635","pt":1722468124290,"mc":[{"id":"1.231241311","rc":[{"batb":[[0,2.34,167.94],[1,2.12,54.28],[2,1.1,10000]],"ltp":2.38,"tv":420.39,"id":26354922}]}]}
{"op":"mcm","clk":"11787942791","pt":1722468126613,"mc":[{"id":"1.231241311","rc":[{"batb":[[0,2.36,10],[1,2.34,167.94],[2,2.12,54.28]],"ltp":2.38,"tv":420.39,"id":26354922}]}]}
{"op":"mcm","clk":"11787943044","pt":1722468130109,"mc":[{"id":"1.231241311","rc":[{"batb":[[0,2.34,167.94],[1,2.12,54.28],[2,1.1,10000]],"ltp":2.38,"tv":420.39,"id":26354922}]}]}
{"op":"mcm","clk":"11787943182","pt":1722468132432,"mc":[{"id":"1.231241311","rc":[{"batb":[[0,2.36,10],[1,2.34,167.94],[2,2.12,54.28]],"ltp":2.38,"tv":420.39,"id":26354922}]}]}
{"op":"mcm","clk":"11787943414","pt":1722468135819,"mc":[{"id":"1.231241311","rc":[{"batb":[[0,2.34,167.94],[1,2.12,54.28],[2,1.1,10000]],"ltp":2.38,"tv":420.39,"id":26354922}]}]}
{"op":"mcm","clk":"11787943541","pt":1722468138142,"mc":[{"id":"1.231241311","rc":[{"batb":[[0,2.36,10],[1,2.34,167.94],[2,2.12,54.28]],"ltp":2.38,"tv":420.39,"id":26354922}]}]}
{"op":"mcm","clk":"11787943867","pt":1722468141546,"mc":[{"id":"1.231241311","rc":[{"batb":[[0,2.34,167.94],[1,2.12,54.28],[2,1.1,10000]],"ltp":2.38,"tv":420.39,"id":26354922}]}]}
{"op":"mcm","clk":"11787944003","pt":1722468143718,"mc":[{"id":"1.231241311","rc":[{"batb":[[0,2.36,10],[1,2.34,167.94],[2,2.12,54.28]],"ltp":2.38,"tv":420.39,"id":26354922}]}]}
{"op":"mcm","clk":"11787944218","pt":1722468147136,"mc":[{"id":"1.231241311","rc":[{"batb":[[0,2.34,167.94],[1,2.12,54.28],[2,1.1,10000]],"ltp":2.38,"tv":420.39,"id":26354922}]}]}
{"op":"mcm","clk":"11787944359","pt":1722468149452,"mc":[{"id":"1.231241311","rc":[{"batb":[[0,2.36,10],[1,2.34,167.94],[2,2.12,54.28]],"ltp":2.38,"tv":420.39,"id":26354922}]}]}
{"op":"mcm","clk":"11787944538","pt":1722468152752,"mc":[{"id":"1.231241311","rc":[{"batb":[[0,2.34,167.94],[1,2.12,54.28],[2,1.1,10000]],"ltp":2.38,"tv":420.39,"id":26354922}]}]}
{"op":"mcm","clk":"11787944690","pt":1722468155275,"mc":[{"id":"1.231241311","rc":[{"batb":[[0,2.36,10],[1,2.34,167.94],[2,2.12,54.28]],"ltp":2.38,"tv":420.39,"id":26354922}]}]}
{"op":"mcm","clk":"11787944897","pt":1722468158534,"mc":[{"id":"1.231241311","rc":[{"batb":[[0,2.34,167.94],[1,2.12,54.28],[2,1.1,10000]],"ltp":2.38,"tv":420.39,"id":26354922}]}]}
{"op":"mcm","clk":"11787945053","pt":1722468160851,"mc":[{"id":"1.231241311","rc":[{"batb":[[0,2.36,10],[1,2.34,167.94],[2,2.12,54.28]],"ltp":2.38,"tv":420.39,"id":26354922}]}]}
{"op":"mcm","clk":"11787945246","pt":1722468164257,"mc":[{"id":"1.231241311","rc":[{"batb":[[0,2.34,167.94],[1,2.12,54.28],[2,1.1,10000]],"ltp":2.38,"tv":420.39,"id":26354922}]}]}
{"op":"mcm","clk":"11787945372","pt":1722468166571,"mc":[{"id":"1.231241311","rc":[{"batb":[[0,2.36,10],[1,2.34,167.94],[2,2.12,54.28]],"ltp":2.38,"tv":420.39,"id":26354922}]}]}
{"op":"mcm","clk":"11787945551","pt":1722468169862,"mc":[{"id":"1.231241311","rc":[{"batb":[[0,2.34,167.94],[1,2.12,54.28],[2,1.1,10000]],"ltp":2.38,"tv":420.39,"id":26354922}]}]}
{"op":"mcm","clk":"11787945688","pt":1722468172286,"mc":[{"id":"1.231241311","rc":[{"batb":[[0,2.36,10],[1,2.34,167.94],[2,2.12,54.28]],"ltp":2.38,"tv":420.39,"id":26354922}]}]}
{"op":"mcm","clk":"11787945895","pt":1722468175788,"mc":[{"id":"1.231241311","rc":[{"batb":[[0,2.34,167.94],[1,2.12,54.28],[2,1.1,10000]],"ltp":2.38,"tv":420.39,"id":26354922}]}]}
{"op":"mcm","clk":"11787946050","pt":1722468178163,"mc":[{"id":"1.231241311","rc":[{"batb":[[0,2.36,10],[1,2.34,167.94],[2,2.12,54.28]],"ltp":2.38,"tv":420.39,"id":26354922}]}]}
{"op":"mcm","clk":"11787946252","pt":1722468181454,"mc":[{"id":"1.231241311","rc":[{"batb":[[0,2.34,167.94],[1,2.12,54.28],[2,1.1,10000]],"ltp":2.38,"tv":420.39,"id":26354922}]}]}
{"op":"mcm","clk":"11787946431","pt":1722468184600,"mc":[{"id":"1.231241311","rc":[{"batb":[[0,2.36,10],[1,2.34,167.94],[2,2.12,54.28]],"ltp":2.38,"tv":420.39,"id":26354922}]}]}
{"op":"mcm","clk":"11787946644","pt":1722468188206,"mc":[{"id":"1.231241311","rc":[{"batb":[[0,2.34,167.94],[1,2.12,54.28],[2,1.1,10000]],"ltp":2.38,"tv":420.39,"id":26354922}]}]}
{"op":"mcm","clk":"11787946812","pt":1722468190482,"mc":[{"id":"1.231241311","rc":[{"batb":[[0,2.36,10],[1,2.34,167.94],[2,2.12,54.28]],"ltp":2.38,"tv":420.39,"id":26354922}]}]}
{"op":"mcm","clk":"11787947019","pt":1722468193988,"mc":[{"id":"1.231241311","rc":[{"batb":[[0,2.34,167.94],[1,2.12,54.28],[2,1.1,10000]],"ltp":2.38,"tv":420.39,"id":26354922}]}]}
{"op":"mcm","clk":"11787947171","pt":1722468196516,"mc":[{"id":"1.231241311","rc":[{"batb":[[0,2.36,10],[1,2.34,167.94],[2,2.12,54.28]],"ltp":2.38,"tv":420.39,"id":26354922}]}]}
{"op":"mcm","clk":"11787947353","pt":1722468199914,"mc":[{"id":"1.231241311","rc":[{"batb":[[0,2.34,167.94],[1,2.12,54.28],[2,1.1,10000]],"ltp":2.38,"tv":420.39,"id":26354922}]}]}
{"op":"mcm","clk":"11787947489","pt":1722468202287,"mc":[{"id":"1.231241311","rc":[{"batb":[[0,2.36,10],[1,2.34,167.94],[2,2.12,54.28]],"ltp":2.38,"tv":420.39,"id":26354922}]}]}
{"op":"mcm","clk":"11787947648","pt":1722468205584,"mc":[{"id":"1.231241311","rc":[{"batb":[[0,2.34,167.94],[1,2.12,54.28],[2,1.1,10000]],"ltp":2.38,"tv":420.39,"id":26354922}]}]}
{"op":"mcm","clk":"11787947803","pt":1722468208000,"mc":[{"id":"1.231241311","rc":[{"batb":[[0,2.36,10],[1,2.34,167.94],[2,2.12,54.28]],"ltp":2.38,"tv":420.39,"id":26354922}]}]}
{"op":"mcm","clk":"11787947948","pt":1722468211192,"mc":[{"id":"1.231241311","rc":[{"batb":[[0,2.34,167.94],[1,2.12,54.28],[2,1.1,10000]],"ltp":2.38,"tv":420.39,"id":26354922}]}]}
{"op":"mcm","clk":"11787948074","pt":1722468213608,"mc":[{"id":"1.231241311","rc":[{"batb":[[0,2.36,10],[1,2.34,167.94],[2,2.12,54.28]],"ltp":2.38,"tv":420.39,"id":26354922}]}]}
{"op":"mcm","clk":"11787948271","pt":1722468216908,"mc":[{"id":"1.231241311","rc":[{"batb":[[0,2.34,167.94],[1,2.12,54.28],[2,1.1,10000]],"ltp":2.38,"tv":420.39,"id":26354922}]}]}
{"op":"mcm","clk":"11787948384","pt":1722468219221,"mc":[{"id":"1.231241311","rc":[{"batb":[[0,2.36,10],[1,2.34,167.94],[2,2.12,54.28]],"ltp":2.38,"tv":420.39,"id":26354922}]}]}
{"op":"mcm","clk":"11787948568","pt":1722468222522,"mc":[{"id":"1.231241311","rc":[{"batb":[[0,2.34,167.94],[1,2.12,54.28],[2,1.1,10000]],"ltp":2.38,"tv":420.39,"id":26354922}]}]}
{"op":"mcm","clk":"11787948684","pt":1722468224937,"mc":[{"id":"1.231241311","rc":[{"batb":[[0,2.36,10],[1,2.34,167.94],[2,2.12,54.28]],"ltp":2.38,"tv":420.39,"id":26354922}]}]}
{"op":"mcm","clk":"11787948862","pt":1722468228329,"mc":[{"id":"1.231241311","rc":[{"batb":[[0,2.34,167.94],[1,2.12,54.28],[2,1.1,10000]],"ltp":2.38,"tv":420.39,"id":26354922}]}]}
{"op":"mcm","clk":"11787949003","pt":1722468230914,"mc":[{"id":"1.231241311","rc":[{"batb":[[0,2.36,10],[1,2.34,167.94],[2,2.12,54.28]],"ltp":2.38,"tv":420.39,"id":26354922}]}]}
{"op":"mcm","clk":"11787949164","pt":1722468234216,"mc":[{"id":"1.231241311","rc":[{"batb":[[0,2.34,167.94],[1,2.12,54.28],[2,1.1,10000]],"ltp":2.38,"tv":420.39,"id":26354922}]}]}
{"op":"mcm","clk":"11787949275","pt":1722468236433,"mc":[{"id":"1.231241311","rc":[{"batb":[[0,2.36,10],[1,2.34,167.94],[2,2.12,54.28]],"ltp":2.38,"tv":420.39,"id":26354922}]}]}
{"op":"mcm","clk":"11787949440","pt":1722468239774,"mc":[{"id":"1.231241311","rc":[{"batb":[[0,2.34,167.94],[1,2.12,54.28],[2,1.1,10000]],"ltp":2.38,"tv":420.39,"id":26354922}]}]}
{"op":"mcm","clk":"11787949604","pt":1722468242159,"mc":[{"id":"1.231241311","rc":[{"batb":[[0,2.36,10],[1,2.34,167.94],[2,2.12,54.28]],"ltp":2.38,"tv":420.39,"id":26354922}]}]}
