{"op":"mcm","clk":"11935719183","pt":1724344537869,"mc":[{"id":"1.232160907","marketDefinition":{"bspMarket":false,"turnInPlayEnabled":true,"persistenceEnabled":true,"marketBaseRate":5.0,"eventId":"33518099","eventTypeId":"4","numberOfWinners":1,"bettingType":"ODDS","marketType":"MATCH_ODDS","marketTime":"2024-08-24T14:00:00.000Z","suspendTime":"2024-08-24T14:00:00.000Z","bspReconciled":false,"complete":true,"inPlay":false,"crossMatching":false,"runnersVoidable":false,"numberOfActiveRunners":2,"betDelay":0,"status":"OPEN","runners":[{"status":"ACTIVE","sortPriority":1,"id":891555,"name":"USA"},{"status":"ACTIVE","sortPriority":2,"id":144197,"name":"Canada"}],"regulators":["MR_INT"],"countryCode":"GB","discountAllowed":false,"timezone":"GMT","openDate":"2024-08-24T14:00:00.000Z","version":6091059679,"name":"Match Odds","eventName":"USA v Canada"},"rc":[{"batb":[[0,1.03,200],[1,1.02,200],[2,1.01,220]],"ltp":0.0,"tv":0.0,"id":144197},{"batb":[[0,1.03,200],[1,1.02,200],[2,1.01,220]],"ltp":0.0,"tv":0.0,"id":891555}]}]}
{"op":"mcm","clk":"11935719405","pt":1724344539338,"mc":[{"id":"1.232160907","marketDefinition":{"bspMarket":false,"turnInPlayEnabled":true,"persistenceEnabled":true,"marketBaseRate":5.0,"eventId":"33518099","eventTypeId":"4","numberOfWinners":1,"bettingType":"ODDS","marketType":"MATCH_ODDS","marketTime":"2024-08-24T14:00:00.000Z","suspendTime":"2024-08-24T14:00:00.000Z","bspReconciled":false,"complete":true,"inPlay":false,"crossMatching":false,"runnersVoidable":false,"numberOfActiveRunners":2,"betDelay":0,"status":"OPEN","runners":[{"status":"ACTIVE","sortPriority":1,"id":891555,"name":"USA"},{"status":"ACTIVE","sortPriority":2,"id":144197,"name":"Canada"}],"regulators":["MR_INT"],"countryCode":"GB","discountAllowed":true,"timezone":"GMT","openDate":"2024-08-24T14:00:00.000Z","version":6091059679,"name":"Match Odds","eventName":"USA v Canada"}}]}
{"op":"mcm","clk":"11935731593","pt":1724344621261,"mc":[{"id":"1.232160907","rc":[{"batb":[[1,1.02,3363.3],[2,1.01,6360.72]],"ltp":0.0,"tv":0.0,"id":891555}]}]}
{"op":"mcm","clk":"11935731712","pt":1724344621955,"mc":[{"id":"1.232160907","rc":[{"batb":[[1,1.02,3363.3],[2,1.01,6360.72]],"ltp":0.0,"tv":0.0,"id":144197},{"batb":[[0,1.04,1618.57],[1,1.03,2342.25],[2,1.02,3363.3]],"ltp":0.0,"tv":0.0,"id":891555}]}]}
{"op":"mcm","clk":"11935731823","pt":1724344622755,"mc":[{"id":"1.232160907","rc":[{"batb":[[0,1.04,1618.57],[1,1.03,2342.25],[2,1.02,3363.3]],"ltp":0.0,"tv":0.0,"id":144197}]}]}
{"op":"mcm","clk":"11935891097","pt":1724345683608,"mc":[{"id":"1.232160907","marketDefinition":{"bspMarket":false,"turnInPlayEnabled":true,"persistenceEnabled":true,"marketBaseRate":5.0,"eventId":"33518099","eventTypeId":"4","numberOfWinners":1,"bettingType":"ODDS","marketType":"MATCH_ODDS","marketTime":"2024-08-24T14:00:00.000Z","suspendTime":"2024-08-24T14:00:00.000Z","bspReconciled":false,"complete":true,"inPlay":false,"crossMatching":true,"runnersVoidable":false,"numberOfActiveRunners":2,"betDelay":0,"status":"OPEN","runners":[{"status":"ACTIVE","sortPriority":1,"id":891555,"name":"USA"},{"status":"ACTIVE","sortPriority":2,"id":144197,"name":"Canada"}],"regulators":["MR_INT"],"countryCode":"GB","discountAllowed":true,"timezone":"GMT","openDate":"2024-08-24T14:00:00.000Z","version":6091059679,"name":"Match Odds","eventName":"USA v Canada"}}]}
{"op":"mcm","clk":"11936087498","pt":1724346775115,"mc":[{"id":"1.232160907","rc":[{"batb":[[0,1.04,1619.26],[1,1.03,2343.16],[2,1.02,3364.64]],"ltp":0.0,"tv":0.0,"id":144197},{"batb":[[0,1.04,1619.26],[1,1.03,2343.16],[2,1.02,3364.64]],"ltp":0.0,"tv":0.0,"id":891555}]}]}
{"op":"mcm","clk":"11936933935","pt":1724352175149,"mc":[{"id":"1.232160907","rc":[{"batb":[[0,1.04,1618.98],[1,1.03,2342.8],[2,1.02,3364.11]],"ltp":0.0,"tv":0.0,"id":144197},{"batb":[[0,1.04,1618.98],[1,1.03,2342.8],[2,1.02,3364.11]],"ltp":0.0,"tv":0.0,"id":891555}]}]}
{"op":"mcm","clk":"11937376344","pt":1724356109594,"mc":[{"id":"1.232160907","rc":[{"batb":[[0,1.04,1619.83],[1,1.03,2341.89],[2,1.02,3362.76]],"ltp":0.0,"tv":0.0,"id":144197},{"batb":[[0,1.04,1619.83],[1,1.03,2341.89],[2,1.02,3362.76]],"ltp":0.0,"tv":0.0,"id":891555}]}]}
{"op":"mcm","clk":"11937511675","pt":1724357575142,"mc":[{"id":"1.232160907","rc":[{"batb":[[0,1.04,1620.51],[1,1.03,2342.8],[2,1.02,3364.11]],"ltp":0.0,"tv":0.0,"id":144197},{"batb":[[0,1.04,1620.51],[1,1.03,2342.8],[2,1.02,3364.11]],"ltp":0.0,"tv":0.0,"id":891555}]}]}
{"op":"mcm","clk":"11937843257","pt":1724362975122,"mc":[{"id":"1.232160907","rc":[{"batb":[[0,1.04,1620.1],[1,1.03,2342.25],[2,1.02,3363.3]],"ltp":0.0,"tv":0.0,"id":144197},{"batb":[[0,1.04,1620.1],[1,1.03,2342.25],[2,1.02,3363.3]],"ltp":0.0,"tv":0.0,"id":891555}]}]}
{"op":"mcm","clk":"11938143825","pt":1724368375097,"mc":[{"id":"1.232160907","rc":[{"batb":[[0,1.04,1620.24],[1,1.03,2342.43],[2,1.02,3363.57]],"ltp":0.0,"tv":0.0,"id":144197},{"batb":[[0,1.04,1620.24],[1,1.03,2342.43],[2,1.02,3363.57]],"ltp":0.0,"tv":0.0,"id":891555}]}]}
{"op":"mcm","clk":"11938792854","pt":1724379175169,"mc":[{"id":"1.232160907","rc":[{"batb":[[0,1.04,1620.65],[1,1.03,2342.98],[2,1.02,3364.37]],"ltp":0.0,"tv":0.0,"id":144197},{"batb":[[0,1.04,1620.65],[1,1.03,2342.98],[2,1.02,3364.37]],"ltp":0.0,"tv":0.0,"id":891555}]}]}
{"op":"mcm","clk":"11938894091","pt":1724383119733,"mc":[{"id":"1.232160907","rc":[{"batb":[[0,1.04,1621.32],[1,1.03,2343.16],[2,1.02,3364.64]],"ltp":0.0,"tv":0.0,"id":144197},{"batb":[[0,1.04,1620.79],[1,1.03,2343.16],[2,1.02,3364.64]],"ltp":0.0,"tv":0.0,"id":891555}]}]}
{"op":"mcm","clk":"11938894359","pt":1724383130703,"mc":[{"id":"1.232160907","rc":[{"batb":[[0,1.04,1621.32]],"ltp":0.0,"tv":0.0,"id":891555}]}]}
{"op":"mcm","clk":"11938912325","pt":1724384098630,"mc":[{"id":"1.232160907","rc":[{"batb":[[0,1.08,2.3],[1,1.04,1620.79],[2,1.03,2343.16]],"ltp":0.0,"tv":0.0,"id":891555}]}]}
{"op":"mcm","clk":"11938912502","pt":1724384108618,"mc":[{"id":"1.232160907","rc":[{"batb":[[0,1.08,2.3],[1,1.04,1620.79],[2,1.03,2343.16]],"ltp":0.0,"tv":0.0,"id":144197}]}]}
{"op":"mcm","clk":"11938915941","pt":1724384297430,"mc":[{"id":"1.232160907","rc":[{"batb":[[0,1.09,95.35],[1,1.08,1.77],[2,1.04,1620.79]],"ltp":0.0,"tv":0.0,"id":144197},{"batb":[[0,1.09,95.35],[1,1.08,1.77],[2,1.04,1620.79]],"ltp":0.0,"tv":0.0,"id":891555}]}]}
{"op":"mcm","clk":"11938973577","pt":1724386097895,"mc":[{"id":"1.232160907","rc":[{"batb":[[0,1.08,2.3],[1,1.04,1620.65],[2,1.03,2342.98]],"ltp":0.0,"tv":0.0,"id":144197},{"batb":[[0,1.08,2.3],[1,1.04,1620.65],[2,1.03,2342.98]],"ltp":0.0,"tv":0.0,"id":891555}]}]}
{"op":"mcm","clk":"11938977470","pt":1724386295907,"mc":[{"id":"1.232160907","rc":[{"batb":[[0,1.09,95.36],[1,1.08,1.77],[2,1.04,1620.65]],"ltp":0.0,"tv":0.0,"id":144197},{"batb":[[0,1.09,95.36],[1,1.08,1.77],[2,1.04,1620.65]],"ltp":0.0,"tv":0.0,"id":891555}]}]}
{"op":"mcm","clk":"11939016284","pt":1724388096262,"mc":[{"id":"1.232160907","rc":[{"batb":[[0,1.08,2.3],[1,1.04,1620.65],[2,1.03,2342.98]],"ltp":0.0,"tv":0.0,"id":144197},{"batb":[[0,1.08,2.3],[1,1.04,1620.65],[2,1.03,2342.98]],"ltp":0.0,"tv":0.0,"id":891555}]}]}
{"op":"mcm","clk":"11939019888","pt":1724388284759,"mc":[{"id":"1.232160907","rc":[{"batb":[[0,1.09,95.36],[1,1.08,1.77],[2,1.04,1620.65]],"ltp":0.0,"tv":0.0,"id":144197},{"batb":[[0,1.09,95.36],[1,1.08,1.77],[2,1.04,1620.65]],"ltp":0.0,"tv":0.0,"id":891555}]}]}
{"op":"mcm","clk":"11939022033","pt":1724388402792,"mc":[{"id":"1.232160907","rc":[{"batb":[[0,1.09,94.83]],"ltp":0.0,"tv":0.0,"id":891555}]}]}
{"op":"mcm","clk":"11939022092","pt":1724388405822,"mc":[{"id":"1.232160907","rc":[{"batb":[[0,1.09,94.83]],"ltp":0.0,"tv":0.0,"id":144197}]}]}
{"op":"mcm","clk":"11939042825","pt":1724389183729,"mc":[{"id":"1.232160907","rc":[{"batl":[[0,11.5,0.69]],"ltp":0.0,"tv":0.0,"id":891555}]}]}
{"op":"mcm","clk":"11939088291","pt":1724389975164,"mc":[{"id":"1.232160907","rc":[{"batb":[[0,1.09,94.8],[2,1.04,1620.24]],"ltp":0.0,"tv":0.0,"id":144197},{"batb":[[0,1.09,94.8],[2,1.04,1620.24]],"ltp":0.0,"tv":0.0,"id":891555}]}]}
{"op":"mcm","clk":"11939096671","pt":1724390085130,"mc":[{"id":"1.232160907","rc":[{"batb":[[0,1.08,1.77],[1,1.04,1620.24],[2,1.03,2342.43]],"ltp":0.0,"tv":0.0,"id":144197},{"batb":[[0,1.08,1.77],[1,1.04,1620.24],[2,1.03,2342.43]],"ltp":0.0,"tv":0.0,"id":891555}]}]}
{"op":"mcm","clk":"11939102790","pt":1724390270339,"mc":[{"id":"1.232160907","rc":[{"batb":[[0,1.1,85.32],[1,1.08,1.77],[2,1.04,1620.24]],"ltp":0.0,"tv":0.0,"id":144197},{"batb":[[0,1.09,94.8],[1,1.08,1.77],[2,1.04,1620.24]],"ltp":0.0,"tv":0.0,"id":891555}]}]}
{"op":"mcm","clk":"11939167509","pt":1724392070688,"mc":[{"id":"1.232160907","rc":[{"batb":[[0,1.08,1.77],[1,1.04,1620.24],[2,1.03,2342.43]],"ltp":0.0,"tv":0.0,"id":144197},{"batb":[[0,1.08,1.77],[1,1.04,1620.24],[2,1.03,2342.43]],"ltp":0.0,"tv":0.0,"id":891555}]}]}
{"op":"mcm","clk":"11939174157","pt":1724392249208,"mc":[{"id":"1.232160907","rc":[{"batb":[[0,1.1,85.32],[1,1.08,1.77],[2,1.04,1620.24]],"ltp":0.0,"tv":0.0,"id":144197},{"batb":[[0,1.09,94.8],[1,1.08,1.77],[2,1.04,1620.24]],"ltp":0.0,"tv":0.0,"id":891555}]}]}
{"op":"mcm","clk":"11939242671","pt":1724394049578,"mc":[{"id":"1.232160907","rc":[{"batb":[[0,1.08,1.77],[1,1.04,1619.83],[2,1.03,2341.89]],"ltp":0.0,"tv":0.0,"id":144197},{"batb":[[0,1.08,1.77],[1,1.04,1619.83],[2,1.03,2341.89]],"ltp":0.0,"tv":0.0,"id":891555}]}]}
{"op":"mcm","clk":"11939251411","pt":1724394221980,"mc":[{"id":"1.232160907","rc":[{"batb":[[0,1.1,85.3],[1,1.08,1.77],[2,1.04,1619.83]],"ltp":0.0,"tv":0.0,"id":144197},{"batb":[[0,1.09,94.78],[1,1.08,1.77],[2,1.04,1619.83]],"ltp":0.0,"tv":0.0,"id":891555}]}]}
{"op":"mcm","clk":"11939347308","pt":1724396022196,"mc":[{"id":"1.232160907","rc":[{"batb":[[0,1.08,1.77],[1,1.04,1619.83],[2,1.03,2341.89]],"ltp":0.0,"tv":0.0,"id":144197}]}]}
{"op":"mcm","clk":"11939347324","pt":1724396022351,"mc":[{"id":"1.232160907","rc":[{"batb":[[0,1.08,1.77],[1,1.04,1619.83],[2,1.03,2341.89]],"ltp":0.0,"tv":0.0,"id":891555}]}]}
{"op":"mcm","clk":"11939356986","pt":1724396200870,"mc":[{"id":"1.232160907","rc":[{"batb":[[0,1.1,85.3],[1,1.08,1.77],[2,1.04,1619.83]],"ltp":0.0,"tv":0.0,"id":144197},{"batb":[[0,1.09,94.78],[1,1.08,1.77],[2,1.04,1619.83]],"ltp":0.0,"tv":0.0,"id":891555}]}]}
{"op":"mcm","clk":"11939389560","pt":1724396859108,"mc":[{"id":"1.232160907","rc":[{"batb":[[0,1.1,85.24],[1,1.08,1.77],[2,1.04,1618.73]],"ltp":0.0,"tv":0.0,"id":144197},{"trd":[[1.09,2]],"batb":[[0,1.09,93.72],[1,1.08,1.77],[2,1.04,1618.73]],"ltp":1.09,"tv":2.0,"id":891555}],"tv":2.0}]}
{"op":"mcm","clk":"11939390143","pt":1724396872590,"mc":[{"id":"1.232160907","rc":[{"trd":[[1.09,4]],"batb":[[0,1.09,92.72]],"ltp":1.09,"tv":4.0,"id":891555}],"tv":4.0}]}
{"op":"mcm","clk":"11939450490","pt":1724398001265,"mc":[{"id":"1.232160907","rc":[{"batb":[[0,1.08,1.77],[1,1.04,1618.73],[2,1.03,2340.43]],"ltp":0.0,"tv":0.0,"id":144197},{"batb":[[0,1.08,1.77],[1,1.04,1618.73],[2,1.03,2340.43]],"ltp":1.09,"tv":4.0,"id":891555}]}]}
{"op":"mcm","clk":"11939461885","pt":1724398177385,"mc":[{"id":"1.232160907","rc":[{"batb":[[0,1.1,85.24],[1,1.08,1.77],[2,1.04,1618.73]],"ltp":0.0,"tv":0.0,"id":144197}]}]}
{"op":"mcm","clk":"11939484861","pt":1724398551175,"mc":[{"id":"1.232160907","rc":[{"batb":[[0,1.49,95.94],[1,1.1,85.24],[2,1.08,1.77]],"ltp":0.0,"tv":0.0,"id":144197}]}]}
{"op":"mcm","clk":"11939485571","pt":1724398564590,"mc":[{"id":"1.232160907","rc":[{"batb":[[0,1.49,95.94],[1,1.08,1.77],[2,1.04,1618.73]],"ltp":1.09,"tv":4.0,"id":891555}]}]}
{"op":"mcm","clk":"11939486337","pt":1724398581804,"mc":[{"id":"1.232160907","rc":[{"trd":[[1.49,101.58]],"batb":[[0,1.49,45.15]],"ltp":1.49,"tv":101.57,"id":144197},{"batb":[[0,1.5,5],[1,1.49,95.94],[2,1.08,1.77]],"ltp":1.09,"tv":4.0,"id":891555}],"tv":105.57}]}
{"op":"mcm","clk":"11939486524","pt":1724398585087,"mc":[{"id":"1.232160907","rc":[{"batb":[[0,1.49,95.94],[1,1.08,1.77],[2,1.04,1618.73]],"ltp":1.09,"tv":4.0,"id":891555}]}]}
{"op":"mcm","clk":"11939486675","pt":1724398588411,"mc":[{"id":"1.232160907","rc":[{"batb":[[0,1.5,5],[1,1.49,95.94],[2,1.08,1.77]],"ltp":1.09,"tv":4.0,"id":891555}]}]}
{"op":"mcm","clk":"11939486807","pt":1724398591595,"mc":[{"id":"1.232160907","rc":[{"batb":[[0,1.49,95.94],[1,1.08,1.77],[2,1.04,1618.73]],"ltp":1.09,"tv":4.0,"id":891555}]}]}
{"op":"mcm","clk":"11939486902","pt":1724398593820,"mc":[{"id":"1.232160907","rc":[{"trd":[[1.49,101.58]],"batb":[[0,1.5,5],[1,1.49,45.15],[2,1.08,1.77]],"ltp":1.49,"tv":105.57,"id":891555}],"tv":207.15}]}
{"op":"mcm","clk":"11939487039","pt":1724398596992,"mc":[{"id":"1.232160907","rc":[{"batb":[[0,1.49,45.15],[1,1.08,1.77],[2,1.04,1618.73]],"ltp":1.49,"tv":105.57,"id":891555}]}]}
{"op":"mcm","clk":"11939487285","pt":1724398602795,"mc":[{"id":"1.232160907","rc":[{"batb":[[0,1.5,5],[1,1.49,45.15],[2,1.08,1.77]],"ltp":1.49,"tv":105.57,"id":891555}]}]}
{"op":"mcm","clk":"11939487417","pt":1724398606177,"mc":[{"id":"1.232160907","rc":[{"batb":[[0,1.49,45.15],[1,1.08,1.77],[2,1.04,1618.73]],"ltp":1.49,"tv":105.57,"id":891555}]}]}
{"op":"mcm","clk":"11939487557","pt":1724398610321,"mc":[{"id":"1.232160907","rc":[{"batb":[[0,1.5,5],[1,1.49,45.15],[2,1.08,1.77]],"ltp":1.49,"tv":105.57,"id":891555}]}]}
{"op":"mcm","clk":"11939487618","pt":1724398611705,"mc":[{"id":"1.232160907","rc":[{"trd":[[1.49,152.37]],"batb":[[0,1.49,19.76]],"ltp":1.49,"tv":152.36,"id":144197}],"tv":257.94}]}
{"op":"mcm","clk":"11939487747","pt":1724398613705,"mc":[{"id":"1.232160907","rc":[{"batb":[[0,1.49,45.15],[1,1.08,1.77],[2,1.04,1618.73]],"ltp":1.49,"tv":105.57,"id":891555}]}]}
{"op":"mcm","clk":"11939487872","pt":1724398617337,"mc":[{"id":"1.232160907","rc":[{"batb":[[0,1.5,5],[1,1.49,45.15],[2,1.08,1.77]],"ltp":1.49,"tv":105.57,"id":891555}]}]}
{"op":"mcm","clk":"11939488020","pt":1724398620613,"mc":[{"id":"1.232160907","rc":[{"batb":[[0,1.49,45.15],[1,1.08,1.77],[2,1.04,1618.73]],"ltp":1.49,"tv":105.57,"id":891555}]}]}
{"op":"mcm","clk":"11939488133","pt":1724398622819,"mc":[{"id":"1.232160907","rc":[{"trd":[[1.49,152.37]],"batb":[[0,1.5,5],[1,1.49,19.76],[2,1.08,1.77]],"ltp":1.49,"tv":156.36,"id":891555}],"tv":308.73}]}
{"op":"mcm","clk":"11939488292","pt":1724398626113,"mc":[{"id":"1.232160907","rc":[{"batb":[[0,1.49,19.76],[1,1.08,1.77],[2,1.04,1618.73]],"ltp":1.49,"tv":156.36,"id":891555}]}]}
{"op":"mcm","clk":"11939488474","pt":1724398629723,"mc":[{"id":"1.232160907","rc":[{"batb":[[0,1.5,5],[1,1.49,19.76],[2,1.08,1.77]],"ltp":1.49,"tv":156.36,"id":891555}]}]}
{"op":"mcm","clk":"11939488625","pt":1724398633166,"mc":[{"id":"1.232160907","rc":[{"batb":[[0,1.49,19.76],[1,1.08,1.77],[2,1.04,1618.73]],"ltp":1.49,"tv":156.36,"id":891555}]}]}
{"op":"mcm","clk":"11939488763","pt":1724398636145,"mc":[{"id":"1.232160907","rc":[{"batb":[[0,1.5,5],[1,1.49,19.76],[2,1.08,1.77]],"ltp":1.49,"tv":156.36,"id":891555}]}]}
{"op":"mcm","clk":"11939488927","pt":1724398639677,"mc":[{"id":"1.232160907","rc":[{"trd":[[1.49,177.14]],"batb":[[0,1.49,7.37]],"ltp":1.49,"tv":177.14,"id":144197},{"batb":[[0,1.49,19.76],[1,1.08,1.77],[2,1.04,1618.73]],"ltp":1.49,"tv":156.36,"id":891555}],"tv":333.5}]}
{"op":"mcm","clk":"11939489148","pt":1724398643686,"mc":[{"id":"1.232160907","rc":[{"batb":[[0,1.5,5],[1,1.49,19.76],[2,1.08,1.77]],"ltp":1.49,"tv":156.36,"id":891555}]}]}
{"op":"mcm","clk":"11939489329","pt":1724398647170,"mc":[{"id":"1.232160907","rc":[{"batb":[[0,1.49,19.76],[1,1.08,1.77],[2,1.04,1618.73]],"ltp":1.49,"tv":156.36,"id":891555}]}]}
{"op":"mcm","clk":"11939489431","pt":1724398649700,"mc":[{"id":"1.232160907","rc":[{"batb":[[0,1.5,5],[1,1.49,19.76],[2,1.08,1.77]],"ltp":1.49,"tv":156.36,"id":891555}]}]}
{"op":"mcm","clk":"11939489592","pt":1724398652878,"mc":[{"id":"1.232160907","rc":[{"batb":[[0,1.49,19.76],[1,1.08,1.77],[2,1.04,1618.73]],"ltp":1.49,"tv":156.36,"id":891555}]}]}
{"op":"mcm","clk":"11939489713","pt":1724398654680,"mc":[{"id":"1.232160907","rc":[{"trd":[[1.49,177.14]],"batb":[[0,1.49,7.37]],"ltp":1.49,"tv":181.14,"id":891555}],"tv":358.28}]}
{"op":"mcm","clk":"11939489980","pt":1724398659968,"mc":[{"id":"1.232160907","rc":[{"batb":[[0,1.5,5],[1,1.49,7.37],[2,1.08,1.77]],"ltp":1.49,"tv":181.14,"id":891555}]}]}
{"op":"mcm","clk":"11939490143","pt":1724398663455,"mc":[{"id":"1.232160907","rc":[{"batb":[[0,1.49,7.37],[1,1.08,1.77],[2,1.04,1618.73]],"ltp":1.49,"tv":181.14,"id":891555}]}]}
{"op":"mcm","clk":"11939490282","pt":1724398665905,"mc":[{"id":"1.232160907","rc":[{"trd":[[1.49,189.53]],"batb":[[0,1.49,1.17]],"ltp":1.49,"tv":189.52,"id":144197},{"batb":[[0,1.5,5],[1,1.49,7.37],[2,1.08,1.77]],"ltp":1.49,"tv":181.14,"id":891555}],"tv":370.66}]}
{"op":"mcm","clk":"11939490493","pt":1724398669494,"mc":[{"id":"1.232160907","rc":[{"batb":[[0,1.49,7.37],[1,1.08,1.77],[2,1.04,1618.73]],"ltp":1.49,"tv":181.14,"id":891555}]}]}
{"op":"mcm","clk":"11939490749","pt":1724398674411,"mc":[{"id":"1.232160907","rc":[{"batb":[[0,1.5,5],[1,1.49,7.37],[2,1.08,1.77]],"ltp":1.49,"tv":181.14,"id":891555}]}]}
{"op":"mcm","clk":"11939490894","pt":1724398677583,"mc":[{"id":"1.232160907","rc":[{"batb":[[0,1.49,7.37],[1,1.08,1.77],[2,1.04,1618.73]],"ltp":1.49,"tv":181.14,"id":891555}]}]}
{"op":"mcm","clk":"11939491018","pt":1724398679792,"mc":[{"id":"1.232160907","rc":[{"batb":[[0,1.5,5],[1,1.49,7.37],[2,1.08,1.77]],"ltp":1.49,"tv":181.14,"id":891555}]}]}
{"op":"mcm","clk":"11939491067","pt":1724398680717,"mc":[{"id":"1.232160907","rc":[{"trd":[[1.49,179.53],[1.5,10]],"batb":[[0,1.49,6.18],[1,1.08,1.77],[2,1.04,1618.73]],"ltp":1.49,"tv":193.52,"id":891555}],"tv":383.05}]}
{"op":"mcm","clk":"11939491200","pt":1724398682923,"mc":[{"id":"1.232160907","rc":[{"batb":[[0,1.5,5],[1,1.49,6.18],[2,1.08,1.77]],"ltp":1.49,"tv":193.52,"id":891555}]}]}
{"op":"mcm","clk":"11939491407","pt":1724398686482,"mc":[{"id":"1.232160907","rc":[{"batb":[[0,1.49,6.18],[1,1.08,1.77],[2,1.04,1618.73]],"ltp":1.49,"tv":193.52,"id":891555}]}]}
{"op":"mcm","clk":"11939491821","pt":1724398694831,"mc":[{"id":"1.232160907","rc":[{"batb":[[0,1.5,5],[1,1.49,6.18],[2,1.08,1.77]],"ltp":1.49,"tv":193.52,"id":891555}]}]}
{"op":"mcm","clk":"11939491974","pt":1724398698217,"mc":[{"id":"1.232160907","rc":[{"batb":[[0,1.49,6.18],[1,1.08,1.77],[2,1.04,1618.73]],"ltp":1.49,"tv":193.52,"id":891555}]}]}
{"op":"mcm","clk":"11939492182","pt":1724398702934,"mc":[{"id":"1.232160907","rc":[{"trd":[[1.49,191.88]],"batb":[[0,1.1,85.24],[1,1.08,1.77],[2,1.04,1618.73]],"batl":[[0,1.49,1.92]],"ltp":1.49,"tv":191.87,"id":144197},{"batb":[[0,1.5,5],[1,1.49,6.18],[2,1.08,1.77]],"ltp":1.49,"tv":193.52,"id":891555}],"tv":385.4}]}
{"op":"mcm","clk":"11939492327","pt":1724398706152,"mc":[{"id":"1.232160907","rc":[{"batb":[[0,1.49,6.18],[1,1.08,1.77],[2,1.04,1618.73]],"ltp":1.49,"tv":193.52,"id":891555}]}]}
{"op":"mcm","clk":"11939492546","pt":1724398710940,"mc":[{"id":"1.232160907","rc":[{"batb":[[0,1.5,5],[1,1.49,6.18],[2,1.08,1.77]],"ltp":1.49,"tv":193.52,"id":891555}]}]}
{"op":"mcm","clk":"11939492750","pt":1724398714709,"mc":[{"id":"1.232160907","rc":[{"batb":[[0,1.49,6.18],[1,1.08,1.77],[2,1.04,1618.73]],"batl":[[0,8,3.54],[1,11.5,0.69]],"ltp":1.49,"tv":193.52,"id":891555}]}]}
{"op":"mcm","clk":"11939492900","pt":1724398718143,"mc":[{"id":"1.232160907","rc":[{"batb":[[0,1.5,5],[1,1.49,6.18],[2,1.08,1.77]],"ltp":1.49,"tv":193.52,"id":891555}]}]}
{"op":"mcm","clk":"11939493057","pt":1724398721622,"mc":[{"id":"1.232160907","rc":[{"batb":[[0,1.49,6.18],[1,1.08,1.77],[2,1.04,1618.73]],"ltp":1.49,"tv":193.52,"id":891555}]}]}
{"op":"mcm","clk":"11939493317","pt":1724398727058,"mc":[{"id":"1.232160907","rc":[{"batb":[[0,1.5,5],[1,1.49,6.18],[2,1.08,1.77]],"ltp":1.49,"tv":193.52,"id":891555}]}]}
{"op":"mcm","clk":"11939493473","pt":1724398730537,"mc":[{"id":"1.232160907","rc":[{"batb":[[0,1.49,6.18],[1,1.08,1.77],[2,1.04,1618.73]],"ltp":1.49,"tv":193.52,"id":891555}]}]}
{"op":"mcm","clk":"11939493586","pt":1724398732944,"mc":[{"id":"1.232160907","rc":[{"batb":[[0,1.5,5],[1,1.49,6.18],[2,1.08,1.77]],"ltp":1.49,"tv":193.52,"id":891555}]}]}
{"op":"mcm","clk":"11939493784","pt":1724398736228,"mc":[{"id":"1.232160907","rc":[{"batb":[[0,1.49,6.18],[1,1.08,1.77],[2,1.04,1618.73]],"ltp":1.49,"tv":193.52,"id":891555}]}]}
{"op":"mcm","clk":"11939493911","pt":1724398738944,"mc":[{"id":"1.232160907","rc":[{"batb":[[0,1.5,5],[1,1.49,6.18],[2,1.08,1.77]],"ltp":1.49,"tv":193.52,"id":891555}]}]}
{"op":"mcm","clk":"11939494105","pt":1724398742240,"mc":[{"id":"1.232160907","rc":[{"batb":[[0,1.49,6.18],[1,1.08,1.77],[2,1.04,1618.73]],"ltp":1.49,"tv":193.52,"id":891555}]}]}
{"op":"mcm","clk":"11939494233","pt":1724398744762,"mc":[{"id":"1.232160907","rc":[{"trd":[[1.49,181.76]],"batb":[[0,1.5,5],[1,1.49,5.06],[2,1.08,1.77]],"ltp":1.49,"tv":195.75,"id":891555}],"tv":387.63}]}
{"op":"mcm","clk":"11939494390","pt":1724398747960,"mc":[{"id":"1.232160907","rc":[{"batb":[[0,1.49,5.06],[1,1.08,1.77],[2,1.04,1618.73]],"ltp":1.49,"tv":195.75,"id":891555}]}]}
{"op":"mcm","clk":"11939494741","pt":1724398754392,"mc":[{"id":"1.232160907","rc":[{"batb":[[0,1.5,5],[1,1.49,5.06],[2,1.08,1.77]],"ltp":1.49,"tv":195.75,"id":891555}]}]}
{"op":"mcm","clk":"11939494921","pt":1724398757778,"mc":[{"id":"1.232160907","rc":[{"batb":[[0,1.49,5.06],[1,1.08,1.77],[2,1.04,1618.73]],"ltp":1.49,"tv":195.75,"id":891555}]}]}
{"op":"mcm","clk":"11939495210","pt":1724398763384,"mc":[{"id":"1.232160907","rc":[{"batb":[[0,1.5,5],[1,1.49,5.06],[2,1.08,1.77]],"ltp":1.49,"tv":195.75,"id":891555}]}]}
{"op":"mcm","clk":"11939495408","pt":1724398766673,"mc":[{"id":"1.232160907","rc":[{"batb":[[0,1.49,5.06],[1,1.08,1.77],[2,1.04,1618.73]],"ltp":1.49,"tv":195.75,"id":891555}]}]}
{"op":"mcm","clk":"11939495985","pt":1724398777296,"mc":[{"id":"1.232160907","rc":[{"batb":[[0,1.5,5],[1,1.49,5.06],[2,1.08,1.77]],"ltp":1.49,"tv":195.75,"id":891555}]}]}
{"op":"mcm","clk":"11939496114","pt":1724398780572,"mc":[{"id":"1.232160907","rc":[{"batb":[[0,1.49,5.06],[1,1.08,1.77],[2,1.04,1618.73]],"ltp":1.49,"tv":195.75,"id":891555}]}]}
{"op":"mcm","clk":"11939496908","pt":1724398794517,"mc":[{"id":"1.232160907","rc":[{"batb":[[0,1.5,5],[1,1.49,5.06],[2,1.08,1.77]],"ltp":1.49,"tv":195.75,"id":891555}]}]}
{"op":"mcm","clk":"11939497076","pt":1724398797799,"mc":[{"id":"1.232160907","rc":[{"batb":[[0,1.49,5.06],[1,1.08,1.77],[2,1.04,1618.73]],"ltp":1.49,"tv":195.75,"id":891555}]}]}
{"op":"mcm","clk":"11939497373","pt":1724398803507,"mc":[{"id":"1.232160907","rc":[{"batb":[[0,1.5,5],[1,1.49,5.06],[2,1.08,1.77]],"ltp":1.49,"tv":195.75,"id":891555}]}]}
{"op":"mcm","clk":"11939497567","pt":1724398806734,"mc":[{"id":"1.232160907","rc":[{"batb":[[0,1.49,5.06],[1,1.08,1.77],[2,1.04,1618.73]],"ltp":1.49,"tv":195.75,"id":891555}]}]}
{"op":"mcm","clk":"11939497830","pt":1724398812021,"mc":[{"id":"1.232160907","rc":[{"batb":[[0,1.5,5],[1,1.49,5.06],[2,1.08,1.77]],"ltp":1.49,"tv":195.75,"id":891555}]}]}
{"op":"mcm","clk":"11939498026","pt":1724398815454,"mc":[{"id":"1.232160907","rc":[{"batb":[[0,1.49,5.06],[1,1.08,1.77],[2,1.04,1618.73]],"ltp":1.49,"tv":195.75,"id":891555}]}]}
{"op":"mcm","clk":"11939498381","pt":1724398823140,"mc":[{"id":"1.232160907","rc":[{"batb":[[0,1.5,5],[1,1.49,5.06],[2,1.08,1.77]],"ltp":1.49,"tv":195.75,"id":891555}]}]}
{"op":"mcm","clk":"11939498523","pt":1724398826429,"mc":[{"id":"1.232160907","rc":[{"batb":[[0,1.49,5.06],[1,1.08,1.77],[2,1.04,1618.73]],"ltp":1.49,"tv":195.75,"id":891555}]}]}
{"op":"mcm","clk":"11939498677","pt":1724398829551,"mc":[{"id":"1.232160907","rc":[{"batb":[[0,1.5,5],[1,1.49,5.06],[2,1.08,1.77]],"ltp":1.49,"tv":195.75,"id":891555}]}]}
{"op":"mcm","clk":"11939498868","pt":1724398832952,"mc":[{"id":"1.232160907","rc":[{"batb":[[0,1.49,5.06],[1,1.08,1.77],[2,1.04,1618.73]],"ltp":1.49,"tv":195.75,"id":891555}]}]}
{"op":"mcm","clk":"11939499194","pt":1724398839829,"mc":[{"id":"1.232160907","rc":[{"batb":[[0,1.5,5],[1,1.49,5.06],[2,1.08,1.77]],"ltp":1.49,"tv":195.75,"id":891555}]}]}
{"op":"mcm","clk":"11939499396","pt":1724398843225,"mc":[{"id":"1.232160907","rc":[{"batb":[[0,1.49,5.06],[1,1.08,1.77],[2,1.04,1618.73]],"ltp":1.49,"tv":195.75,"id":891555}]}]}
{"op":"mcm","clk":"11939499799","pt":1724398851829,"mc":[{"id":"1.232160907","rc":[{"batb":[[0,1.5,5],[1,1.49,5.06],[2,1.08,1.77]],"ltp":1.49,"tv":195.75,"id":891555}]}]}
{"op":"mcm","clk":"11939499981","pt":1724398855569,"mc":[{"id":"1.232160907","rc":[{"batb":[[0,1.49,5.06],[1,1.08,1.77],[2,1.04,1618.73]],"ltp":1.49,"tv":195.75,"id":891555}]}]}
{"op":"mcm","clk":"11939500216","pt":1724398861848,"mc":[{"id":"1.232160907","rc":[{"batb":[[0,1.5,5],[1,1.49,5.06],[2,1.08,1.77]],"ltp":1.49,"tv":195.75,"id":891555}]}]}
{"op":"mcm","clk":"11939500375","pt":1724398865176,"mc":[{"id":"1.232160907","rc":[{"batb":[[0,1.49,5.06],[1,1.08,1.77],[2,1.04,1618.73]],"ltp":1.49,"tv":195.75,"id":891555}]}]}
{"op":"mcm","clk":"11939500679","pt":1724398871870,"mc":[{"id":"1.232160907","rc":[{"batb":[[0,1.5,5],[1,1.49,5.06],[2,1.08,1.77]],"ltp":1.49,"tv":195.75,"id":891555}]}]}
{"op":"mcm","clk":"11939500828","pt":1724398875197,"mc":[{"id":"1.232160907","rc":[{"batb":[[0,1.49,5.06],[1,1.08,1.77],[2,1.04,1618.73]],"ltp":1.49,"tv":195.75,"id":891555}]}]}
{"op":"mcm","clk":"11939500942","pt":1724398878314,"mc":[{"id":"1.232160907","rc":[{"batb":[[0,1.5,5],[1,1.49,5.06],[2,1.08,1.77]],"ltp":1.49,"tv":195.75,"id":891555}]}]}
{"op":"mcm","clk":"11939501101","pt":1724398881714,"mc":[{"id":"1.232160907","rc":[{"batb":[[0,1.49,5.06],[1,1.08,1.77],[2,1.04,1618.73]],"ltp":1.49,"tv":195.75,"id":891555}]}]}
{"op":"mcm","clk":"11939501877","pt":1724398898541,"mc":[{"id":"1.232160907","rc":[{"batb":[[0,1.5,5],[1,1.49,5.06],[2,1.08,1.77]],"ltp":1.49,"tv":195.75,"id":891555}]}]}
{"op":"mcm","clk":"11939502004","pt":1724398901819,"mc":[{"id":"1.232160907","rc":[{"batb":[[0,1.49,5.06],[1,1.08,1.77],[2,1.04,1618.73]],"ltp":1.49,"tv":195.75,"id":891555}]}]}
{"op":"mcm","clk":"11939502128","pt":1724398904640,"mc":[{"id":"1.232160907","rc":[{"trd":[[1.49,187.1]],"batb":[[0,1.49,2.39]],"ltp":1.49,"tv":201.09,"id":891555}],"tv":392.97}]}
{"op":"mcm","clk":"11939504374","pt":1724398954690,"mc":[{"id":"1.232160907","rc":[{"batb":[[0,1.49,400],[1,1.1,85.24],[2,1.08,1.77]],"ltp":1.49,"tv":191.87,"id":144197}]}]}
{"op":"mcm","clk":"11939506242","pt":1724398992662,"mc":[{"id":"1.232160907","rc":[{"batb":[[0,1.1,85.24],[1,1.08,1.77],[2,1.04,1618.73]],"ltp":1.49,"tv":191.87,"id":144197}]}]}
{"op":"mcm","clk":"11939507734","pt":1724399021794,"mc":[{"id":"1.232160907","rc":[{"batb":[[0,1.5,5],[1,1.49,5.05],[2,1.08,1.77]],"ltp":1.49,"tv":201.09,"id":891555}]}]}
{"op":"mcm","clk":"11939507922","pt":1724399024972,"mc":[{"id":"1.232160907","rc":[{"batb":[[0,1.49,5.05],[1,1.08,1.77],[2,1.04,1618.73]],"ltp":1.49,"tv":201.09,"id":891555}]}]}
{"op":"mcm","clk":"11939508259","pt":1724399030783,"mc":[{"id":"1.232160907","rc":[{"batb":[[0,1.5,5],[1,1.49,5.05],[2,1.08,1.77]],"ltp":1.49,"tv":201.09,"id":891555}]}]}
{"op":"mcm","clk":"11939508480","pt":1724399035590,"mc":[{"id":"1.232160907","rc":[{"batb":[[0,1.49,5.05],[1,1.08,1.77],[2,1.04,1618.73]],"ltp":1.49,"tv":201.09,"id":891555}]}]}
{"op":"mcm","clk":"11939508703","pt":1724399041021,"mc":[{"id":"1.232160907","rc":[{"batb":[[0,1.5,5],[1,1.49,5.05],[2,1.08,1.77]],"ltp":1.49,"tv":201.09,"id":891555}]}]}
{"op":"mcm","clk":"11939508930","pt":1724399044634,"mc":[{"id":"1.232160907","rc":[{"batb":[[0,1.49,5.05],[1,1.08,1.77],[2,1.04,1618.73]],"ltp":1.49,"tv":201.09,"id":891555}]}]}
{"op":"mcm","clk":"11939509110","pt":1724399047844,"mc":[{"id":"1.232160907","rc":[{"batb":[[0,1.5,5],[1,1.49,5.05],[2,1.08,1.77]],"ltp":1.49,"tv":201.09,"id":891555}]}]}
{"op":"mcm","clk":"11939509279","pt":1724399051233,"mc":[{"id":"1.232160907","rc":[{"batb":[[0,1.49,5.05],[1,1.08,1.77],[2,1.04,1618.73]],"ltp":1.49,"tv":201.09,"id":891555}]}]}
{"op":"mcm","clk":"11939509510","pt":1724399055741,"mc":[{"id":"1.232160907","rc":[{"batb":[[0,1.5,5],[1,1.49,5.05],[2,1.08,1.77]],"ltp":1.49,"tv":201.09,"id":891555}]}]}
{"op":"mcm","clk":"11939509670","pt":1724399059143,"mc":[{"id":"1.232160907","rc":[{"batb":[[0,1.49,5.05],[1,1.08,1.77],[2,1.04,1618.73]],"ltp":1.49,"tv":201.09,"id":891555}]}]}
{"op":"mcm","clk":"11939509932","pt":1724399062748,"mc":[{"id":"1.232160907","rc":[{"batb":[[0,1.49,2.66]],"ltp":1.49,"tv":201.09,"id":891555}]}]}
{"op":"mcm","clk":"11939515122","pt":1724399161633,"mc":[{"id":"1.232160907","rc":[{"batb":[[0,1.5,5],[1,1.49,5.05],[2,1.08,1.77]],"ltp":1.49,"tv":201.09,"id":891555}]}]}
{"op":"mcm","clk":"11939515367","pt":1724399164943,"mc":[{"id":"1.232160907","rc":[{"batb":[[0,1.49,5.05],[1,1.08,1.77],[2,1.04,1618.73]],"ltp":1.49,"tv":201.09,"id":891555}]}]}
{"op":"mcm","clk":"11939515657","pt":1724399170547,"mc":[{"id":"1.232160907","rc":[{"batb":[[0,1.5,5],[1,1.49,5.05],[2,1.08,1.77]],"ltp":1.49,"tv":201.09,"id":891555}]}]}
{"op":"mcm","clk":"11939515859","pt":1724399174032,"mc":[{"id":"1.232160907","rc":[{"batb":[[0,1.49,5.05],[1,1.08,1.77],[2,1.04,1618.73]],"ltp":1.49,"tv":201.09,"id":891555}]}]}
{"op":"mcm","clk":"11939516278","pt":1724399182344,"mc":[{"id":"1.232160907","rc":[{"batb":[[0,1.5,5],[1,1.49,5.05],[2,1.08,1.77]],"ltp":1.49,"tv":201.09,"id":891555}]}]}
{"op":"mcm","clk":"11939516474","pt":1724399185773,"mc":[{"id":"1.232160907","rc":[{"batb":[[0,1.49,5.05],[1,1.08,1.77],[2,1.04,1618.73]],"ltp":1.49,"tv":201.09,"id":891555}]}]}
{"op":"mcm","clk":"11939516959","pt":1724399193457,"mc":[{"id":"1.232160907","rc":[{"batb":[[0,1.5,5],[1,1.49,5.05],[2,1.08,1.77]],"ltp":1.49,"tv":201.09,"id":891555}]}]}
{"op":"mcm","clk":"11939517162","pt":1724399196857,"mc":[{"id":"1.232160907","rc":[{"batb":[[0,1.49,5.05],[1,1.08,1.77],[2,1.04,1618.73]],"ltp":1.49,"tv":201.09,"id":891555}]}]}
{"op":"mcm","clk":"11939517531","pt":1724399203580,"mc":[{"id":"1.232160907","rc":[{"batb":[[0,1.5,5],[1,1.49,5.05],[2,1.08,1.77]],"ltp":1.49,"tv":201.09,"id":891555}]}]}
{"op":"mcm","clk":"11939517735","pt":1724399207092,"mc":[{"id":"1.232160907","rc":[{"batb":[[0,1.49,5.05],[1,1.08,1.77],[2,1.04,1618.73]],"ltp":1.49,"tv":201.09,"id":891555}]}]}
{"op":"mcm","clk":"11939518212","pt":1724399215477,"mc":[{"id":"1.232160907","rc":[{"batb":[[0,1.5,5],[1,1.49,5.05],[2,1.08,1.77]],"ltp":1.49,"tv":201.09,"id":891555}]}]}
{"op":"mcm","clk":"11939518420","pt":1724399219083,"mc":[{"id":"1.232160907","rc":[{"batb":[[0,1.49,5.05],[1,1.08,1.77],[2,1.04,1618.73]],"ltp":1.49,"tv":201.09,"id":891555}]}]}
{"op":"mcm","clk":"11939518847","pt":1724399226024,"mc":[{"id":"1.232160907","rc":[{"batb":[[0,1.5,5],[1,1.49,5.05],[2,1.08,1.77]],"ltp":1.49,"tv":201.09,"id":891555}]}]}
{"op":"mcm","clk":"11939519050","pt":1724399229518,"mc":[{"id":"1.232160907","rc":[{"batb":[[0,1.49,5.05],[1,1.08,1.77],[2,1.04,1618.73]],"ltp":1.49,"tv":201.09,"id":891555}]}]}
{"op":"mcm","clk":"11939519387","pt":1724399235229,"mc":[{"id":"1.232160907","rc":[{"batb":[[0,1.5,5],[1,1.49,5.05],[2,1.08,1.77]],"ltp":1.49,"tv":201.09,"id":891555}]}]}
{"op":"mcm","clk":"11939519629","pt":1724399238727,"mc":[{"id":"1.232160907","rc":[{"batb":[[0,1.49,5.05],[1,1.08,1.77],[2,1.04,1618.73]],"ltp":1.49,"tv":201.09,"id":891555}]}]}
{"op":"mcm","clk":"11939520418","pt":1724399253853,"mc":[{"id":"1.232160907","rc":[{"batb":[[0,1.5,5],[1,1.49,5.05],[2,1.08,1.77]],"ltp":1.49,"tv":201.09,"id":891555}]}]}
{"op":"mcm","clk":"11939520608","pt":1724399257256,"mc":[{"id":"1.232160907","rc":[{"batb":[[0,1.49,5.05],[1,1.08,1.77],[2,1.04,1618.73]],"ltp":1.49,"tv":201.09,"id":891555}]}]}
{"op":"mcm","clk":"11939520717","pt":1724399259460,"mc":[{"id":"1.232160907","rc":[{"batb":[[0,1.5,5],[1,1.49,5.05],[2,1.08,1.77]],"ltp":1.49,"tv":201.09,"id":891555}]}]}
{"op":"mcm","clk":"11939520899","pt":1724399262647,"mc":[{"id":"1.232160907","rc":[{"batb":[[0,1.49,5.05],[1,1.08,1.77],[2,1.04,1618.73]],"ltp":1.49,"tv":201.09,"id":891555}]}]}
{"op":"mcm","clk":"11939521451","pt":1724399271862,"mc":[{"id":"1.232160907","rc":[{"batb":[[0,1.5,5],[1,1.49,5.05],[2,1.08,1.77]],"ltp":1.49,"tv":201.09,"id":891555}]}]}
{"op":"mcm","clk":"11939521638","pt":1724399275245,"mc":[{"id":"1.232160907","rc":[{"batb":[[0,1.49,5.05],[1,1.08,1.77],[2,1.04,1618.73]],"ltp":1.49,"tv":201.09,"id":891555}]}]}
{"op":"mcm","clk":"11939521824","pt":1724399278783,"mc":[{"id":"1.232160907","rc":[{"batb":[[0,1.5,5],[1,1.49,5.05],[2,1.08,1.77]],"ltp":1.49,"tv":201.09,"id":891555}]}]}
{"op":"mcm","clk":"11939522051","pt":1724399282054,"mc":[{"id":"1.232160907","rc":[{"batb":[[0,1.49,5.05],[1,1.08,1.77],[2,1.04,1618.73]],"ltp":1.49,"tv":201.09,"id":891555}]}]}
{"op":"mcm","clk":"11939522625","pt":1724399290072,"mc":[{"id":"1.232160907","rc":[{"batb":[[0,1.5,5],[1,1.49,5.05],[2,1.08,1.77]],"ltp":1.49,"tv":201.09,"id":891555}]}]}
{"op":"mcm","clk":"11939522802","pt":1724399293364,"mc":[{"id":"1.232160907","rc":[{"batb":[[0,1.49,5.05],[1,1.08,1.77],[2,1.04,1618.73]],"ltp":1.49,"tv":201.09,"id":891555}]}]}
{"op":"mcm","clk":"11939523229","pt":1724399299983,"mc":[{"id":"1.232160907","rc":[{"batb":[[0,1.5,5],[1,1.49,5.05],[2,1.08,1.77]],"ltp":1.49,"tv":201.09,"id":891555}]}]}
{"op":"mcm","clk":"11939523437","pt":1724399303275,"mc":[{"id":"1.232160907","rc":[{"batb":[[0,1.49,5.05],[1,1.08,1.77],[2,1.04,1618.73]],"ltp":1.49,"tv":201.09,"id":891555}]}]}
{"op":"mcm","clk":"11939523605","pt":1724399306608,"mc":[{"id":"1.232160907","rc":[{"batb":[[0,1.5,5],[1,1.49,5.05],[2,1.08,1.77]],"ltp":1.49,"tv":201.09,"id":891555}]}]}
{"op":"mcm","clk":"11939523759","pt":1724399309991,"mc":[{"id":"1.232160907","rc":[{"batb":[[0,1.49,5.05],[1,1.08,1.77],[2,1.04,1618.73]],"ltp":1.49,"tv":201.09,"id":891555}]}]}
{"op":"mcm","clk":"11939524066","pt":1724399313711,"mc":[{"id":"1.232160907","rc":[{"batb":[[0,1.5,5],[1,1.49,5.05],[2,1.08,1.77]],"ltp":1.49,"tv":201.09,"id":891555}]}]}
{"op":"mcm","clk":"11939524249","pt":1724399316989,"mc":[{"id":"1.232160907","rc":[{"batb":[[0,1.49,5.05],[1,1.08,1.77],[2,1.04,1618.73]],"ltp":1.49,"tv":201.09,"id":891555}]}]}
{"op":"mcm","clk":"11939524494","pt":1724399321525,"mc":[{"id":"1.232160907","rc":[{"batb":[[0,1.5,5],[1,1.49,5.05],[2,1.08,1.77]],"ltp":1.49,"tv":201.09,"id":891555}]}]}
{"op":"mcm","clk":"11939524708","pt":1724399324809,"mc":[{"id":"1.232160907","rc":[{"batb":[[0,1.49,5.05],[1,1.08,1.77],[2,1.04,1618.73]],"ltp":1.49,"tv":201.09,"id":891555}]}]}
{"op":"mcm","clk":"11939525063","pt":1724399331299,"mc":[{"id":"1.232160907","rc":[{"batb":[[0,1.5,5],[1,1.49,5.05],[2,1.08,1.77]],"ltp":1.49,"tv":201.09,"id":891555}]}]}
{"op":"mcm","clk":"11939525214","pt":1724399334741,"mc":[{"id":"1.232160907","rc":[{"batb":[[0,1.49,5.05],[1,1.08,1.77],[2,1.04,1618.73]],"ltp":1.49,"tv":201.09,"id":891555}]}]}
{"op":"mcm","clk":"11939525373","pt":1724399337051,"mc":[{"id":"1.232160907","rc":[{"batb":[[0,1.5,5],[1,1.49,5.05],[2,1.08,1.77]],"ltp":1.49,"tv":201.09,"id":891555}]}]}
{"op":"mcm","clk":"11939525570","pt":1724399340409,"mc":[{"id":"1.232160907","rc":[{"batb":[[0,1.49,5.05],[1,1.08,1.77],[2,1.04,1618.73]],"ltp":1.49,"tv":201.09,"id":891555}]}]}
{"op":"mcm","clk":"11939525905","pt":1724399346059,"mc":[{"id":"1.232160907","rc":[{"batb":[[0,1.5,5],[1,1.49,5.05],[2,1.08,1.77]],"ltp":1.49,"tv":201.09,"id":891555}]}]}
{"op":"mcm","clk":"11939526146","pt":1724399349454,"mc":[{"id":"1.232160907","rc":[{"batb":[[0,1.49,5.05],[1,1.08,1.77],[2,1.04,1618.73]],"ltp":1.49,"tv":201.09,"id":891555}]}]}
{"op":"mcm","clk":"11939526288","pt":1724399352130,"mc":[{"id":"1.232160907","rc":[{"batb":[[0,1.5,5],[1,1.49,5.05],[2,1.08,1.77]],"ltp":1.49,"tv":201.09,"id":891555}]}]}
{"op":"mcm","clk":"11939526478","pt":1724399355373,"mc":[{"id":"1.232160907","rc":[{"batb":[[0,1.49,5.05],[1,1.08,1.77],[2,1.04,1618.73]],"ltp":1.49,"tv":201.09,"id":891555}]}]}
{"op":"mcm","clk":"11939526606","pt":1724399357577,"mc":[{"id":"1.232160907","rc":[{"batb":[[0,1.5,5],[1,1.49,5.05],[2,1.08,1.77]],"ltp":1.49,"tv":201.09,"id":891555}]}]}
{"op":"mcm","clk":"11939526815","pt":1724399360868,"mc":[{"id":"1.232160907","rc":[{"batb":[[0,1.49,5.05],[1,1.08,1.77],[2,1.04,1618.73]],"ltp":1.49,"tv":201.09,"id":891555}]}]}
{"op":"mcm","clk":"11939526956","pt":1724399363747,"mc":[{"id":"1.232160907","rc":[{"batb":[[0,1.5,5],[1,1.49,5.05],[2,1.08,1.77]],"ltp":1.49,"tv":201.09,"id":891555}]}]}
{"op":"mcm","clk":"11939527159","pt":1724399367081,"mc":[{"id":"1.232160907","rc":[{"batb":[[0,1.49,5.05],[1,1.08,1.77],[2,1.04,1618.73]],"ltp":1.49,"tv":201.09,"id":891555}]}]}
{"op":"mcm","clk":"11939527528","pt":1724399372682,"mc":[{"id":"1.232160907","rc":[{"batb":[[0,1.5,5],[1,1.49,5.05],[2,1.08,1.77]],"ltp":1.49,"tv":201.09,"id":891555}]}]}
{"op":"mcm","clk":"11939527724","pt":1724399376078,"mc":[{"id":"1.232160907","rc":[{"batb":[[0,1.49,5.05],[1,1.08,1.77],[2,1.04,1618.73]],"ltp":1.49,"tv":201.09,"id":891555}]}]}
{"op":"mcm","clk":"11939528243","pt":1724399384686,"mc":[{"id":"1.232160907","rc":[{"batb":[[0,1.5,5],[1,1.49,5.05],[2,1.08,1.77]],"ltp":1.49,"tv":201.09,"id":891555}]}]}
{"op":"mcm","clk":"11939528448","pt":1724399388278,"mc":[{"id":"1.232160907","rc":[{"batb":[[0,1.49,5.05],[1,1.08,1.77],[2,1.04,1618.73]],"ltp":1.49,"tv":201.09,"id":891555}]}]}
{"op":"mcm","clk":"11939528966","pt":1724399396605,"mc":[{"id":"1.232160907","rc":[{"batb":[[0,1.5,5],[1,1.49,5.05],[2,1.08,1.77]],"ltp":1.49,"tv":201.09,"id":891555}]}]}
{"op":"mcm","clk":"11939529184","pt":1724399400079,"mc":[{"id":"1.232160907","rc":[{"batb":[[0,1.49,5.05],[1,1.08,1.77],[2,1.04,1618.73]],"ltp":1.49,"tv":201.09,"id":891555}]}]}
{"op":"mcm","clk":"11939529466","pt":1724399404410,"mc":[{"id":"1.232160907","rc":[{"batb":[[0,1.5,5],[1,1.49,5.05],[2,1.08,1.77]],"ltp":1.49,"tv":201.09,"id":891555}]}]}
{"op":"mcm","clk":"11939529700","pt":1724399407809,"mc":[{"id":"1.232160907","rc":[{"batb":[[0,1.49,5.05],[1,1.08,1.77],[2,1.04,1618.73]],"ltp":1.49,"tv":201.09,"id":891555}]}]}
{"op":"mcm","clk":"11939530528","pt":1724399420392,"mc":[{"id":"1.232160907","rc":[{"batb":[[0,1.5,5],[1,1.49,5.05],[2,1.08,1.77]],"ltp":1.49,"tv":201.09,"id":891555}]}]}
{"op":"mcm","clk":"11939530737","pt":1724399423939,"mc":[{"id":"1.232160907","rc":[{"batb":[[0,1.49,5.05],[1,1.08,1.77],[2,1.04,1618.73]],"ltp":1.49,"tv":201.09,"id":891555}]}]}
{"op":"mcm","clk":"11939531097","pt":1724399429530,"mc":[{"id":"1.232160907","rc":[{"batb":[[0,1.5,5],[1,1.49,5.05],[2,1.08,1.77]],"ltp":1.49,"tv":201.09,"id":891555}]}]}
{"op":"mcm","clk":"11939531269","pt":1724399432817,"mc":[{"id":"1.232160907","rc":[{"batb":[[0,1.49,5.05],[1,1.08,1.77],[2,1.04,1618.73]],"ltp":1.49,"tv":201.09,"id":891555}]}]}
{"op":"mcm","clk":"11939531928","pt":1724399442234,"mc":[{"id":"1.232160907","rc":[{"batb":[[0,1.5,5],[1,1.49,5.05],[2,1.08,1.77]],"ltp":1.49,"tv":201.09,"id":891555}]}]}
{"op":"mcm","clk":"11939532150","pt":1724399445568,"mc":[{"id":"1.232160907","rc":[{"batb":[[0,1.49,5.05],[1,1.08,1.77],[2,1.04,1618.73]],"ltp":1.49,"tv":201.09,"id":891555}]}]}
{"op":"mcm","clk":"11939533375","pt":1724399463449,"mc":[{"id":"1.232160907","rc":[{"batb":[[0,1.5,5],[1,1.49,5.05],[2,1.08,1.77]],"ltp":1.49,"tv":201.09,"id":891555}]}]}
{"op":"mcm","clk":"11939533630","pt":1724399466850,"mc":[{"id":"1.232160907","rc":[{"batb":[[0,1.49,5.05],[1,1.08,1.77],[2,1.04,1618.73]],"ltp":1.49,"tv":201.09,"id":891555}]}]}
{"op":"mcm","clk":"11939533842","pt":1724399470285,"mc":[{"id":"1.232160907","rc":[{"batb":[[0,1.5,5],[1,1.49,5.05],[2,1.08,1.77]],"ltp":1.49,"tv":201.09,"id":891555}]}]}
{"op":"mcm","clk":"11939534077","pt":1724399473570,"mc":[{"id":"1.232160907","rc":[{"batb":[[0,1.49,5.05],[1,1.08,1.77],[2,1.04,1618.73]],"ltp":1.49,"tv":201.09,"id":891555}]}]}
{"op":"mcm","clk":"11939534274","pt":1724399476494,"mc":[{"id":"1.232160907","rc":[{"batb":[[0,1.5,5],[1,1.49,5.05],[2,1.08,1.77]],"ltp":1.49,"tv":201.09,"id":891555}]}]}
{"op":"mcm","clk":"11939534474","pt":1724399479894,"mc":[{"id":"1.232160907","rc":[{"batb":[[0,1.49,5.05],[1,1.08,1.77],[2,1.04,1618.73]],"ltp":1.49,"tv":201.09,"id":891555}]}]}
{"op":"mcm","clk":"11939534780","pt":1724399484056,"mc":[{"id":"1.232160907","rc":[{"batb":[[0,1.5,5],[1,1.49,5.05],[2,1.08,1.77]],"ltp":1.49,"tv":201.09,"id":891555}]}]}
{"op":"mcm","clk":"11939534996","pt":1724399487492,"mc":[{"id":"1.232160907","rc":[{"batb":[[0,1.49,5.05],[1,1.08,1.77],[2,1.04,1618.73]],"ltp":1.49,"tv":201.09,"id":891555}]}]}
{"op":"mcm","clk":"11939535207","pt":1724399490990,"mc":[{"id":"1.232160907","rc":[{"batb":[[0,1.5,5],[1,1.49,5.05],[2,1.08,1.77]],"ltp":1.49,"tv":201.09,"id":891555}]}]}
{"op":"mcm","clk":"11939535475","pt":1724399494201,"mc":[{"id":"1.232160907","rc":[{"batb":[[0,1.49,5.05],[1,1.08,1.77],[2,1.04,1618.73]],"ltp":1.49,"tv":201.09,"id":891555}]}]}
{"op":"mcm","clk":"11939535732","pt":1724399498297,"mc":[{"id":"1.232160907","rc":[{"batb":[[0,1.5,5],[1,1.49,5.05],[2,1.08,1.77]],"ltp":1.49,"tv":201.09,"id":891555}]}]}
{"op":"mcm","clk":"11939535934","pt":1724399501475,"mc":[{"id":"1.232160907","rc":[{"batb":[[0,1.49,5.05],[1,1.08,1.77],[2,1.04,1618.73]],"ltp":1.49,"tv":201.09,"id":891555}]}]}
{"op":"mcm","clk":"11939536343","pt":1724399507598,"mc":[{"id":"1.232160907","rc":[{"batb":[[0,1.5,5],[1,1.49,5.05],[2,1.08,1.77]],"ltp":1.49,"tv":201.09,"id":891555}]}]}
{"op":"mcm","clk":"11939536581","pt":1724399510782,"mc":[{"id":"1.232160907","rc":[{"batb":[[0,1.49,5.05],[1,1.08,1.77],[2,1.04,1618.73]],"ltp":1.49,"tv":201.09,"id":891555}]}]}
{"op":"mcm","clk":"11939536828","pt":1724399514212,"mc":[{"id":"1.232160907","rc":[{"batb":[[0,1.5,5],[1,1.49,5.05],[2,1.08,1.77]],"ltp":1.49,"tv":201.09,"id":891555}]}]}
{"op":"mcm","clk":"11939537050","pt":1724399517606,"mc":[{"id":"1.232160907","rc":[{"batb":[[0,1.49,5.05],[1,1.08,1.77],[2,1.04,1618.73]],"ltp":1.49,"tv":201.09,"id":891555}]}]}
{"op":"mcm","clk":"11939537613","pt":1724399524948,"mc":[{"id":"1.232160907","rc":[{"batb":[[0,1.5,5],[1,1.49,5.05],[2,1.08,1.77]],"ltp":1.49,"tv":201.09,"id":891555}]}]}
{"op":"mcm","clk":"11939537868","pt":1724399528138,"mc":[{"id":"1.232160907","rc":[{"batb":[[0,1.49,5.05],[1,1.08,1.77],[2,1.04,1618.73]],"ltp":1.49,"tv":201.09,"id":891555}]}]}
{"op":"mcm","clk":"11939538505","pt":1724399536367,"mc":[{"id":"1.232160907","rc":[{"batb":[[0,1.5,5],[1,1.49,5.05],[2,1.08,1.77]],"ltp":1.49,"tv":201.09,"id":891555}]}]}
{"op":"mcm","clk":"11939538733","pt":1724399539551,"mc":[{"id":"1.232160907","rc":[{"batb":[[0,1.49,5.05],[1,1.08,1.77],[2,1.04,1618.73]],"ltp":1.49,"tv":201.09,"id":891555}]}]}
{"op":"mcm","clk":"11939539186","pt":1724399545044,"mc":[{"id":"1.232160907","rc":[{"batb":[[0,1.5,5],[1,1.49,5.05],[2,1.08,1.77]],"ltp":1.49,"tv":201.09,"id":891555}]}]}
{"op":"mcm","clk":"11939539460","pt":1724399548274,"mc":[{"id":"1.232160907","rc":[{"batb":[[0,1.49,5.05],[1,1.08,1.77],[2,1.04,1618.73]],"ltp":1.49,"tv":201.09,"id":891555}]}]}
{"op":"mcm","clk":"11939539836","pt":1724399553339,"mc":[{"id":"1.232160907","rc":[{"batb":[[0,1.5,5],[1,1.49,5.05],[2,1.08,1.77]],"ltp":1.49,"tv":201.09,"id":891555}]}]}
{"op":"mcm","clk":"11939540064","pt":1724399556670,"mc":[{"id":"1.232160907","rc":[{"batb":[[0,1.49,5.05],[1,1.08,1.77],[2,1.04,1618.73]],"ltp":1.49,"tv":201.09,"id":891555}]}]}
{"op":"mcm","clk":"11939540214","pt":1724399558882,"mc":[{"id":"1.232160907","rc":[{"batb":[[0,1.5,5],[1,1.49,5.05],[2,1.08,1.77]],"ltp":1.49,"tv":201.09,"id":891555}]}]}
{"op":"mcm","clk":"11939540463","pt":1724399562164,"mc":[{"id":"1.232160907","rc":[{"batb":[[0,1.49,5.05],[1,1.08,1.77],[2,1.04,1618.73]],"ltp":1.49,"tv":201.09,"id":891555}]}]}
{"op":"mcm","clk":"11939540704","pt":1724399565792,"mc":[{"id":"1.232160907","rc":[{"batb":[[0,1.5,5],[1,1.49,5.05],[2,1.08,1.77]],"ltp":1.49,"tv":201.09,"id":891555}]}]}
{"op":"mcm","clk":"11939540927","pt":1724399569001,"mc":[{"id":"1.232160907","rc":[{"batb":[[0,1.49,5.05],[1,1.08,1.77],[2,1.04,1618.73]],"ltp":1.49,"tv":201.09,"id":891555}]}]}
{"op":"mcm","clk":"11939541281","pt":1724399573781,"mc":[{"id":"1.232160907","rc":[{"batb":[[0,1.5,5],[1,1.49,5.05],[2,1.08,1.77]],"ltp":1.49,"tv":201.09,"id":891555}]}]}
{"op":"mcm","clk":"11939541557","pt":1724399577087,"mc":[{"id":"1.232160907","rc":[{"batb":[[0,1.49,5.05],[1,1.08,1.77],[2,1.04,1618.73]],"ltp":1.49,"tv":201.09,"id":891555}]}]}
{"op":"mcm","clk":"11939542549","pt":1724399590733,"mc":[{"id":"1.232160907","rc":[{"batb":[[0,1.5,5],[1,1.49,5.05],[2,1.08,1.77]],"ltp":1.49,"tv":201.09,"id":891555}]}]}
{"op":"mcm","clk":"11939542808","pt":1724399593974,"mc":[{"id":"1.232160907","rc":[{"batb":[[0,1.49,5.05],[1,1.08,1.77],[2,1.04,1618.73]],"ltp":1.49,"tv":201.09,"id":891555}]}]}
{"op":"mcm","clk":"11939543340","pt":1724399601280,"mc":[{"id":"1.232160907","rc":[{"batb":[[0,1.5,5],[1,1.49,5.05],[2,1.08,1.77]],"ltp":1.49,"tv":201.09,"id":891555}]}]}
{"op":"mcm","clk":"11939543616","pt":1724399604671,"mc":[{"id":"1.232160907","rc":[{"batb":[[0,1.49,5.05],[1,1.08,1.77],[2,1.04,1618.73]],"ltp":1.49,"tv":201.09,"id":891555}]}]}
{"op":"mcm","clk":"11939544147","pt":1724399612397,"mc":[{"id":"1.232160907","rc":[{"batb":[[0,1.5,5],[1,1.49,5.05],[2,1.08,1.77]],"ltp":1.49,"tv":201.09,"id":891555}]}]}
{"op":"mcm","clk":"11939544405","pt":1724399615583,"mc":[{"id":"1.232160907","rc":[{"batb":[[0,1.49,5.05],[1,1.08,1.77],[2,1.04,1618.73]],"ltp":1.49,"tv":201.09,"id":891555}]}]}
{"op":"mcm","clk":"11939545152","pt":1724399625772,"mc":[{"id":"1.232160907","rc":[{"batb":[[0,1.8,138.46],[1,1.1,85.24],[2,1.08,1.77]],"ltp":1.49,"tv":191.87,"id":144197},{"batb":[[0,1.5,5],[1,1.49,5.05],[2,1.08,1.77]],"ltp":1.49,"tv":201.09,"id":891555}]}]}
{"op":"mcm","clk":"11939545384","pt":1724399629106,"mc":[{"id":"1.232160907","rc":[{"batb":[[0,1.49,5.05],[1,1.08,1.77],[2,1.04,1618.73]],"ltp":1.49,"tv":201.09,"id":891555}]}]}
{"op":"mcm","clk":"11939545874","pt":1724399636099,"mc":[{"id":"1.232160907","rc":[{"batb":[[0,1.5,5],[1,1.49,5.05],[2,1.08,1.77]],"ltp":1.49,"tv":201.09,"id":891555}]}]}
{"op":"mcm","clk":"11939546080","pt":1724399639295,"mc":[{"id":"1.232160907","rc":[{"batb":[[0,1.49,5.05],[1,1.08,1.77],[2,1.04,1618.73]],"ltp":1.49,"tv":201.09,"id":891555}]}]}
{"op":"mcm","clk":"11939546250","pt":1724399641923,"mc":[{"id":"1.232160907","rc":[{"batb":[[0,1.5,5],[1,1.49,5.05],[2,1.08,1.77]],"ltp":1.49,"tv":201.09,"id":891555}]}]}
{"op":"mcm","clk":"11939546512","pt":1724399645233,"mc":[{"id":"1.232160907","rc":[{"batb":[[0,1.49,5.05],[1,1.08,1.77],[2,1.04,1618.73]],"ltp":1.49,"tv":201.09,"id":891555}]}]}
{"op":"mcm","clk":"11939546938","pt":1724399651611,"mc":[{"id":"1.232160907","rc":[{"batb":[[0,1.5,5],[1,1.49,5.05],[2,1.08,1.77]],"ltp":1.49,"tv":201.09,"id":891555}]}]}
{"op":"mcm","clk":"11939547199","pt":1724399655002,"mc":[{"id":"1.232160907","rc":[{"batb":[[0,1.49,5.05],[1,1.08,1.77],[2,1.04,1618.73]],"ltp":1.49,"tv":201.09,"id":891555}]}]}
{"op":"mcm","clk":"11939547644","pt":1724399661118,"mc":[{"id":"1.232160907","rc":[{"batb":[[0,1.5,5],[1,1.49,5.05],[2,1.08,1.77]],"ltp":1.49,"tv":201.09,"id":891555}]}]}
{"op":"mcm","clk":"11939547957","pt":1724399664712,"mc":[{"id":"1.232160907","rc":[{"batb":[[0,1.49,5.05],[1,1.08,1.77],[2,1.04,1618.73]],"ltp":1.49,"tv":201.09,"id":891555}]}]}
{"op":"mcm","clk":"11939548183","pt":1724399667845,"mc":[{"id":"1.232160907","rc":[{"batb":[[0,1.5,5],[1,1.49,5.05],[2,1.08,1.77]],"ltp":1.49,"tv":201.09,"id":891555}]}]}
{"op":"mcm","clk":"11939548417","pt":1724399671032,"mc":[{"id":"1.232160907","rc":[{"batb":[[0,1.49,5.05],[1,1.08,1.77],[2,1.04,1618.73]],"ltp":1.49,"tv":201.09,"id":891555}]}]}
{"op":"mcm","clk":"11939549250","pt":1724399683357,"mc":[{"id":"1.232160907","rc":[{"batb":[[0,1.5,5],[1,1.49,5.05],[2,1.08,1.77]],"ltp":1.49,"tv":201.09,"id":891555}]}]}
{"op":"mcm","clk":"11939549477","pt":1724399686864,"mc":[{"id":"1.232160907","rc":[{"batb":[[0,1.49,5.05],[1,1.08,1.77],[2,1.04,1618.73]],"ltp":1.49,"tv":201.09,"id":891555}]}]}
{"op":"mcm","clk":"11939549852","pt":1724399693555,"mc":[{"id":"1.232160907","rc":[{"batb":[[0,1.5,5],[1,1.49,5.05],[2,1.08,1.77]],"ltp":1.49,"tv":201.09,"id":891555}]}]}
{"op":"mcm","clk":"11939550076","pt":1724399697046,"mc":[{"id":"1.232160907","rc":[{"batb":[[0,1.49,5.05],[1,1.08,1.77],[2,1.04,1618.73]],"ltp":1.49,"tv":201.09,"id":891555}]}]}
{"op":"mcm","clk":"11939550669","pt":1724399705550,"mc":[{"id":"1.232160907","rc":[{"batb":[[0,1.5,5],[1,1.49,5.05],[2,1.08,1.77]],"ltp":1.49,"tv":201.09,"id":891555}]}]}
{"op":"mcm","clk":"11939550880","pt":1724399708779,"mc":[{"id":"1.232160907","rc":[{"batb":[[0,1.49,5.05],[1,1.08,1.77],[2,1.04,1618.73]],"ltp":1.49,"tv":201.09,"id":891555}]}]}
{"op":"mcm","clk":"11939551425","pt":1724399716746,"mc":[{"id":"1.232160907","rc":[{"batb":[[0,1.5,5],[1,1.49,5.05],[2,1.08,1.77]],"ltp":1.49,"tv":201.09,"id":891555}]}]}
{"op":"mcm","clk":"11939551616","pt":1724399720083,"mc":[{"id":"1.232160907","rc":[{"batb":[[0,1.49,5.05],[1,1.08,1.77],[2,1.04,1618.73]],"ltp":1.49,"tv":201.09,"id":891555}]}]}
{"op":"mcm","clk":"11939551802","pt":1724399723155,"mc":[{"id":"1.232160907","rc":[{"batb":[[0,1.5,5],[1,1.49,5.05],[2,1.08,1.77]],"ltp":1.49,"tv":201.09,"id":891555}]}]}
{"op":"mcm","clk":"11939551983","pt":1724399726360,"mc":[{"id":"1.232160907","rc":[{"batb":[[0,1.49,5.05],[1,1.08,1.77],[2,1.04,1618.73]],"ltp":1.49,"tv":201.09,"id":891555}]}]}
{"op":"mcm","clk":"11939552232","pt":1724399730565,"mc":[{"id":"1.232160907","rc":[{"batb":[[0,1.5,5],[1,1.49,5.05],[2,1.08,1.77]],"ltp":1.49,"tv":201.09,"id":891555}]}]}
{"op":"mcm","clk":"11939552424","pt":1724399733887,"mc":[{"id":"1.232160907","rc":[{"batb":[[0,1.49,5.05],[1,1.08,1.77],[2,1.04,1618.73]],"ltp":1.49,"tv":201.09,"id":891555}]}]}
{"op":"mcm","clk":"11939552638","pt":1724399736963,"mc":[{"id":"1.232160907","rc":[{"batb":[[0,1.5,5],[1,1.49,5.05],[2,1.08,1.77]],"ltp":1.49,"tv":201.09,"id":891555}]}]}
{"op":"mcm","clk":"11939552821","pt":1724399740194,"mc":[{"id":"1.232160907","rc":[{"batb":[[0,1.49,5.05],[1,1.08,1.77],[2,1.04,1618.73]],"ltp":1.49,"tv":201.09,"id":891555}]}]}
{"op":"mcm","clk":"11939553307","pt":1724399746972,"mc":[{"id":"1.232160907","rc":[{"batb":[[0,1.5,5],[1,1.49,5.05],[2,1.08,1.77]],"ltp":1.49,"tv":201.09,"id":891555}]}]}
{"op":"mcm","clk":"11939553508","pt":1724399750302,"mc":[{"id":"1.232160907","rc":[{"batb":[[0,1.49,5.05],[1,1.08,1.77],[2,1.04,1618.73]],"ltp":1.49,"tv":201.09,"id":891555}]}]}
{"op":"mcm","clk":"11939554087","pt":1724399759210,"mc":[{"id":"1.232160907","rc":[{"batb":[[0,1.5,5],[1,1.49,5.05],[2,1.08,1.77]],"ltp":1.49,"tv":201.09,"id":891555}]}]}
{"op":"mcm","clk":"11939554263","pt":1724399762610,"mc":[{"id":"1.232160907","rc":[{"batb":[[0,1.49,5.05],[1,1.08,1.77],[2,1.04,1618.73]],"ltp":1.49,"tv":201.09,"id":891555}]}]}
{"op":"mcm","clk":"11939554920","pt":1724399773000,"mc":[{"id":"1.232160907","rc":[{"batb":[[0,1.5,5],[1,1.49,5.05],[2,1.08,1.77]],"ltp":1.49,"tv":201.09,"id":891555}]}]}
{"op":"mcm","clk":"11939555113","pt":1724399776230,"mc":[{"id":"1.232160907","rc":[{"batb":[[0,1.49,5.05],[1,1.08,1.77],[2,1.04,1618.73]],"ltp":1.49,"tv":201.09,"id":891555}]}]}
{"op":"mcm","clk":"11939555720","pt":1724399786540,"mc":[{"id":"1.232160907","rc":[{"batb":[[0,1.5,5],[1,1.49,5.05],[2,1.08,1.77]],"ltp":1.49,"tv":201.09,"id":891555}]}]}
{"op":"mcm","clk":"11939555942","pt":1724399789926,"mc":[{"id":"1.232160907","rc":[{"batb":[[0,1.49,5.05],[1,1.08,1.77],[2,1.04,1618.73]],"ltp":1.49,"tv":201.09,"id":891555}]}]}
{"op":"mcm","clk":"11939556981","pt":1724399807043,"mc":[{"id":"1.232160907","rc":[{"batb":[[0,1.5,5],[1,1.49,5.05],[2,1.08,1.77]],"ltp":1.49,"tv":201.09,"id":891555}]}]}
{"op":"mcm","clk":"11939557178","pt":1724399810236,"mc":[{"id":"1.232160907","rc":[{"batb":[[0,1.49,5.05],[1,1.08,1.77],[2,1.04,1618.73]],"ltp":1.49,"tv":201.09,"id":891555}]}]}
{"op":"mcm","clk":"11939557541","pt":1724399816449,"mc":[{"id":"1.232160907","rc":[{"batb":[[0,1.5,5],[1,1.49,5.05],[2,1.08,1.77]],"ltp":1.49,"tv":201.09,"id":891555}]}]}
{"op":"mcm","clk":"11939557729","pt":1724399819686,"mc":[{"id":"1.232160907","rc":[{"batb":[[0,1.49,5.05],[1,1.08,1.77],[2,1.04,1618.73]],"ltp":1.49,"tv":201.09,"id":891555}]}]}
{"op":"mcm","clk":"11939558386","pt":1724399829677,"mc":[{"id":"1.232160907","rc":[{"batb":[[0,1.5,5],[1,1.49,5.05],[2,1.08,1.77]],"ltp":1.49,"tv":201.09,"id":891555}]}]}
{"op":"mcm","clk":"11939558580","pt":1724399833169,"mc":[{"id":"1.232160907","rc":[{"batb":[[0,1.49,5.05],[1,1.08,1.77],[2,1.04,1618.73]],"ltp":1.49,"tv":201.09,"id":891555}]}]}
{"op":"mcm","clk":"11939560000","pt":1724399858501,"mc":[{"id":"1.232160907","rc":[{"batb":[[0,1.5,5],[1,1.49,5.05],[2,1.08,1.77]],"ltp":1.49,"tv":201.09,"id":891555}]}]}
{"op":"mcm","clk":"11939560211","pt":1724399861914,"mc":[{"id":"1.232160907","rc":[{"batb":[[0,1.49,5.05],[1,1.08,1.77],[2,1.04,1618.73]],"ltp":1.49,"tv":201.09,"id":891555}]}]}
{"op":"mcm","clk":"11939561152","pt":1724399876325,"mc":[{"id":"1.232160907","rc":[{"batb":[[0,1.5,5],[1,1.49,5.05],[2,1.08,1.77]],"ltp":1.49,"tv":201.09,"id":891555}]}]}
{"op":"mcm","clk":"11939561298","pt":1724399879502,"mc":[{"id":"1.232160907","rc":[{"batb":[[0,1.49,5.05],[1,1.08,1.77],[2,1.04,1618.73]],"ltp":1.49,"tv":201.09,"id":891555}]}]}
{"op":"mcm","clk":"11939561873","pt":1724399889644,"mc":[{"id":"1.232160907","rc":[{"batb":[[0,1.5,5],[1,1.49,5.05],[2,1.08,1.77]],"ltp":1.49,"tv":201.09,"id":891555}]}]}
{"op":"mcm","clk":"11939562036","pt":1724399892828,"mc":[{"id":"1.232160907","rc":[{"batb":[[0,1.49,5.05],[1,1.08,1.77],[2,1.04,1618.73]],"ltp":1.49,"tv":201.09,"id":891555}]}]}
{"op":"mcm","clk":"11939562403","pt":1724399898259,"mc":[{"id":"1.232160907","rc":[{"batb":[[0,1.5,5],[1,1.49,5.05],[2,1.08,1.77]],"ltp":1.49,"tv":201.09,"id":891555}]}]}
{"op":"mcm","clk":"11939562580","pt":1724399901746,"mc":[{"id":"1.232160907","rc":[{"batb":[[0,1.49,5.05],[1,1.08,1.77],[2,1.04,1618.73]],"ltp":1.49,"tv":201.09,"id":891555}]}]}
{"op":"mcm","clk":"11939563282","pt":1724399915483,"mc":[{"id":"1.232160907","rc":[{"batb":[[0,1.5,5],[1,1.49,5.05],[2,1.08,1.77]],"ltp":1.49,"tv":201.09,"id":891555}]}]}
{"op":"mcm","clk":"11939563429","pt":1724399918867,"mc":[{"id":"1.232160907","rc":[{"batb":[[0,1.49,5.05],[1,1.08,1.77],[2,1.04,1618.73]],"ltp":1.49,"tv":201.09,"id":891555}]}]}
{"op":"mcm","clk":"11939563551","pt":1724399922192,"mc":[{"id":"1.232160907","rc":[{"batb":[[0,1.5,5],[1,1.49,5.05],[2,1.08,1.77]],"ltp":1.49,"tv":201.09,"id":891555}]}]}
{"op":"mcm","clk":"11939563739","pt":1724399925387,"mc":[{"id":"1.232160907","rc":[{"batb":[[0,1.49,5.05],[1,1.08,1.77],[2,1.04,1618.73]],"ltp":1.49,"tv":201.09,"id":891555}]}]}
{"op":"mcm","clk":"11939563848","pt":1724399927587,"mc":[{"id":"1.232160907","rc":[{"batb":[[0,1.5,5],[1,1.49,5.05],[2,1.08,1.77]],"ltp":1.49,"tv":201.09,"id":891555}]}]}
{"op":"mcm","clk":"11939564004","pt":1724399931067,"mc":[{"id":"1.232160907","rc":[{"batb":[[0,1.49,5.05],[1,1.08,1.77],[2,1.04,1618.73]],"ltp":1.49,"tv":201.09,"id":891555}]}]}
{"op":"mcm","clk":"11939564119","pt":1724399933873,"mc":[{"id":"1.232160907","rc":[{"batb":[[0,1.5,5],[1,1.49,5.05],[2,1.08,1.77]],"ltp":1.49,"tv":201.09,"id":891555}]}]}
{"op":"mcm","clk":"11939564238","pt":1724399937407,"mc":[{"id":"1.232160907","rc":[{"batb":[[0,1.49,5.05],[1,1.08,1.77],[2,1.04,1618.73]],"ltp":1.49,"tv":201.09,"id":891555}]}]}
{"op":"mcm","clk":"11939564640","pt":1724399946286,"mc":[{"id":"1.232160907","rc":[{"batb":[[0,1.5,5],[1,1.49,5.05],[2,1.08,1.77]],"ltp":1.49,"tv":201.09,"id":891555}]}]}
{"op":"mcm","clk":"11939564788","pt":1724399949802,"mc":[{"id":"1.232160907","rc":[{"batb":[[0,1.49,5.05],[1,1.08,1.77],[2,1.04,1618.73]],"ltp":1.49,"tv":201.09,"id":891555}]}]}
{"op":"mcm","clk":"11939565555","pt":1724399968421,"mc":[{"id":"1.232160907","rc":[{"batb":[[0,1.5,5],[1,1.49,5.05],[2,1.08,1.77]],"ltp":1.49,"tv":201.09,"id":891555}]}]}
{"op":"mcm","clk":"11939565697","pt":1724399972047,"mc":[{"id":"1.232160907","rc":[{"batb":[[0,1.49,5.05],[1,1.08,1.77],[2,1.04,1618.73]],"ltp":1.49,"tv":201.09,"id":891555}]}]}
{"op":"mcm","clk":"11939565931","pt":1724399977747,"mc":[{"id":"1.232160907","rc":[{"batb":[[1,1.08,1.77],[2,1.04,1618.73]],"ltp":1.49,"tv":191.87,"id":144197},{"batb":[[0,1.5,5],[1,1.49,5.05],[2,1.08,1.77]],"ltp":1.49,"tv":201.09,"id":891555}]}]}
{"op":"mcm","clk":"11939566071","pt":1724399981031,"mc":[{"id":"1.232160907","rc":[{"batb":[[0,1.49,5.05],[1,1.08,1.77],[2,1.04,1618.73]],"ltp":1.49,"tv":201.09,"id":891555}]}]}
{"op":"mcm","clk":"11939566225","pt":1724399984572,"mc":[{"id":"1.232160907","rc":[{"batb":[[0,1.5,5],[1,1.49,5.05],[2,1.08,1.77]],"ltp":1.49,"tv":201.09,"id":891555}]}]}
{"op":"mcm","clk":"11939566335","pt":1724399987948,"mc":[{"id":"1.232160907","rc":[{"batb":[[0,1.49,5.05],[1,1.08,1.77],[2,1.04,1618.73]],"ltp":1.49,"tv":201.09,"id":891555}]}]}
{"op":"mcm","clk":"11939566740","pt":1724399999059,"mc":[{"id":"1.232160907","rc":[{"batb":[[0,1.5,5],[1,1.49,5.05],[2,1.08,1.77]],"ltp":1.49,"tv":201.09,"id":891555}]}]}
{"op":"mcm","clk":"11939566955","pt":1724400002490,"mc":[{"id":"1.232160907","rc":[{"batb":[[0,1.49,5.05],[1,1.08,1.77],[2,1.04,1618.73]],"ltp":1.49,"tv":201.09,"id":891555}]}]}
{"op":"mcm","clk":"11939567454","pt":1724400010964,"mc":[{"id":"1.232160907","rc":[{"trd":[[1.49,191.97]],"batb":[[2,1.04,1618.04]],"ltp":1.49,"tv":191.96,"id":144197},{"trd":[[1.49,187.18],[1.5,10]],"batb":[[0,1.5,5],[1,1.49,5.05],[2,1.08,1.77]],"batl":[[0,8,3.54]],"ltp":1.49,"tv":201.18,"id":891555}],"tv":393.15}]}
{"op":"mcm","clk":"11939567673","pt":1724400014511,"mc":[{"id":"1.232160907","rc":[{"batb":[[0,1.49,5.05],[1,1.08,1.77],[2,1.04,1618.04]],"ltp":1.49,"tv":201.18,"id":891555}]}]}
{"op":"mcm","clk":"11939568178","pt":1724400024717,"mc":[{"id":"1.232160907","rc":[{"batb":[[0,1.5,5],[1,1.49,5.05],[2,1.08,1.77]],"ltp":1.49,"tv":201.18,"id":891555}]}]}
{"op":"mcm","clk":"11939568389","pt":1724400028010,"mc":[{"id":"1.232160907","rc":[{"batb":[[0,1.49,5.05],[1,1.08,1.77],[2,1.04,1618.04]],"ltp":1.49,"tv":201.18,"id":891555}]}]}
{"op":"mcm","clk":"11939568506","pt":1724400030711,"mc":[{"id":"1.232160907","rc":[{"batb":[[0,1.5,5],[1,1.49,5.05],[2,1.08,1.77]],"ltp":1.49,"tv":201.18,"id":891555}]}]}
{"op":"mcm","clk":"11939568663","pt":1724400034095,"mc":[{"id":"1.232160907","rc":[{"batb":[[0,1.49,5.05],[1,1.08,1.77],[2,1.04,1618.04]],"ltp":1.49,"tv":201.18,"id":891555}]}]}
{"op":"mcm","clk":"11939568944","pt":1724400040321,"mc":[{"id":"1.232160907","rc":[{"batb":[[0,1.5,5],[1,1.49,5.05],[2,1.08,1.77]],"ltp":1.49,"tv":201.18,"id":891555}]}]}
{"op":"mcm","clk":"11939569132","pt":1724400043701,"mc":[{"id":"1.232160907","rc":[{"batb":[[0,1.49,5.05],[1,1.08,1.77],[2,1.04,1618.04]],"ltp":1.49,"tv":201.18,"id":891555}]}]}
{"op":"mcm","clk":"11939569492","pt":1724400049409,"mc":[{"id":"1.232160907","rc":[{"batb":[[0,1.5,5],[1,1.49,5.05],[2,1.08,1.77]],"ltp":1.49,"tv":201.18,"id":891555}]}]}
{"op":"mcm","clk":"11939569670","pt":1724400052844,"mc":[{"id":"1.232160907","rc":[{"batb":[[0,1.49,5.05],[1,1.08,1.77],[2,1.04,1618.04]],"ltp":1.49,"tv":201.18,"id":891555}]}]}
{"op":"mcm","clk":"11939569816","pt":1724400055162,"mc":[{"id":"1.232160907","rc":[{"batb":[[0,1.5,5],[1,1.49,5.05],[2,1.08,1.77]],"ltp":1.49,"tv":201.18,"id":891555}]}]}
{"op":"mcm","clk":"11939569990","pt":1724400058554,"mc":[{"id":"1.232160907","rc":[{"batb":[[0,1.49,5.05],[1,1.08,1.77],[2,1.04,1618.04]],"ltp":1.49,"tv":201.18,"id":891555}]}]}
{"op":"mcm","clk":"11939570290","pt":1724400063030,"mc":[{"id":"1.232160907","rc":[{"batb":[[0,1.5,5],[1,1.49,5.05],[2,1.08,1.77]],"ltp":1.49,"tv":201.18,"id":891555}]}]}
{"op":"mcm","clk":"11939570528","pt":1724400066568,"mc":[{"id":"1.232160907","rc":[{"batb":[[0,1.49,5.05],[1,1.08,1.77],[2,1.04,1618.04]],"ltp":1.49,"tv":201.18,"id":891555}]}]}
{"op":"mcm","clk":"11939570820","pt":1724400072466,"mc":[{"id":"1.232160907","rc":[{"batb":[[0,1.5,5],[1,1.49,5.05],[2,1.08,1.77]],"ltp":1.49,"tv":201.18,"id":891555}]}]}
{"op":"mcm","clk":"11939570995","pt":1724400075655,"mc":[{"id":"1.232160907","rc":[{"batb":[[0,1.49,5.05],[1,1.08,1.77],[2,1.04,1618.04]],"ltp":1.49,"tv":201.18,"id":891555}]}]}
{"op":"mcm","clk":"11939571245","pt":1724400080939,"mc":[{"id":"1.232160907","rc":[{"batb":[[0,1.5,5],[1,1.49,5.05],[2,1.08,1.77]],"ltp":1.49,"tv":201.18,"id":891555}]}]}
{"op":"mcm","clk":"11939571422","pt":1724400084174,"mc":[{"id":"1.232160907","rc":[{"batb":[[0,1.49,5.05],[1,1.08,1.77],[2,1.04,1618.04]],"ltp":1.49,"tv":201.18,"id":891555}]}]}
{"op":"mcm","clk":"11939571614","pt":1724400088379,"mc":[{"id":"1.232160907","rc":[{"batb":[[0,1.5,5],[1,1.49,5.05],[2,1.08,1.77]],"ltp":1.49,"tv":201.18,"id":891555}]}]}
{"op":"mcm","clk":"11939571794","pt":1724400091964,"mc":[{"id":"1.232160907","rc":[{"batb":[[0,1.49,5.05],[1,1.08,1.77],[2,1.04,1618.04]],"ltp":1.49,"tv":201.18,"id":891555}]}]}
{"op":"mcm","clk":"11939571928","pt":1724400094283,"mc":[{"id":"1.232160907","rc":[{"batb":[[0,1.5,5],[1,1.49,5.05],[2,1.08,1.77]],"ltp":1.49,"tv":201.18,"id":891555}]}]}
{"op":"mcm","clk":"11939572118","pt":1724400097475,"mc":[{"id":"1.232160907","rc":[{"batb":[[0,1.49,5.05],[1,1.08,1.77],[2,1.04,1618.04]],"ltp":1.49,"tv":201.18,"id":891555}]}]}
{"op":"mcm","clk":"11939572794","pt":1724400111217,"mc":[{"id":"1.232160907","rc":[{"batb":[[0,1.5,5],[1,1.49,5.05],[2,1.08,1.77]],"ltp":1.49,"tv":201.18,"id":891555}]}]}
{"op":"mcm","clk":"11939572956","pt":1724400114689,"mc":[{"id":"1.232160907","rc":[{"batb":[[0,1.49,5.05],[1,1.08,1.77],[2,1.04,1618.04]],"ltp":1.49,"tv":201.18,"id":891555}]}]}
{"op":"mcm","clk":"11939573151","pt":1724400119684,"mc":[{"id":"1.232160907","rc":[{"batb":[[0,1.5,5],[1,1.49,5.05],[2,1.08,1.77]],"ltp":1.49,"tv":201.18,"id":891555}]}]}
{"op":"mcm","clk":"11939573374","pt":1724400123221,"mc":[{"id":"1.232160907","rc":[{"batb":[[0,1.49,5.05],[1,1.08,1.77],[2,1.04,1618.04]],"ltp":1.49,"tv":201.18,"id":891555}]}]}
{"op":"mcm","clk":"11939573828","pt":1724400133232,"mc":[{"id":"1.232160907","rc":[{"batb":[[0,1.5,5],[1,1.49,5.05],[2,1.08,1.77]],"ltp":1.49,"tv":201.18,"id":891555}]}]}
{"op":"mcm","clk":"11939574025","pt":1724400136625,"mc":[{"id":"1.232160907","rc":[{"batb":[[0,1.49,5.05],[1,1.08,1.77],[2,1.04,1618.04]],"ltp":1.49,"tv":201.18,"id":891555}]}]}
{"op":"mcm","clk":"11939574405","pt":1724400144235,"mc":[{"id":"1.232160907","rc":[{"batb":[[0,1.5,5],[1,1.49,5.05],[2,1.08,1.77]],"ltp":1.49,"tv":201.18,"id":891555}]}]}
{"op":"mcm","clk":"11939574596","pt":1724400147429,"mc":[{"id":"1.232160907","rc":[{"batb":[[0,1.49,5.05],[1,1.08,1.77],[2,1.04,1618.04]],"ltp":1.49,"tv":201.18,"id":891555}]}]}
{"op":"mcm","clk":"11939574845","pt":1724400152109,"mc":[{"id":"1.232160907","rc":[{"batb":[[0,1.5,5],[1,1.49,5.05],[2,1.08,1.77]],"ltp":1.49,"tv":201.18,"id":891555}]}]}
{"op":"mcm","clk":"11939575018","pt":1724400155545,"mc":[{"id":"1.232160907","rc":[{"batb":[[0,1.49,5.05],[1,1.08,1.77],[2,1.04,1618.04]],"ltp":1.49,"tv":201.18,"id":891555}]}]}
{"op":"mcm","clk":"11939575297","pt":1724400160548,"mc":[{"id":"1.232160907","rc":[{"batb":[[0,1.5,5],[1,1.49,5.05],[2,1.08,1.77]],"ltp":1.49,"tv":201.18,"id":891555}]}]}
{"op":"mcm","clk":"11939575471","pt":1724400163734,"mc":[{"id":"1.232160907","rc":[{"batb":[[0,1.49,5.05],[1,1.08,1.77],[2,1.04,1618.04]],"ltp":1.49,"tv":201.18,"id":891555}]}]}
{"op":"mcm","clk":"11939575770","pt":1724400170139,"mc":[{"id":"1.232160907","rc":[{"batb":[[0,1.5,5],[1,1.49,5.05],[2,1.08,1.77]],"ltp":1.49,"tv":201.18,"id":891555}]}]}
{"op":"mcm","clk":"11939575928","pt":1724400173365,"mc":[{"id":"1.232160907","rc":[{"batb":[[0,1.49,5.05],[1,1.08,1.77],[2,1.04,1618.04]],"ltp":1.49,"tv":201.18,"id":891555}]}]}
{"op":"mcm","clk":"11939576069","pt":1724400177057,"mc":[{"id":"1.232160907","rc":[{"batb":[[0,1.5,5],[1,1.49,5.05],[2,1.08,1.77]],"ltp":1.49,"tv":201.18,"id":891555}]}]}
{"op":"mcm","clk":"11939576211","pt":1724400180458,"mc":[{"id":"1.232160907","rc":[{"batb":[[0,1.49,5.05],[1,1.08,1.77],[2,1.04,1618.04]],"ltp":1.49,"tv":201.18,"id":891555}]}]}
{"op":"mcm","clk":"11939576334","pt":1724400183547,"mc":[{"id":"1.232160907","rc":[{"batb":[[0,1.5,5],[1,1.49,5.05],[2,1.08,1.77]],"ltp":1.49,"tv":201.18,"id":891555}]}]}
{"op":"mcm","clk":"11939576491","pt":1724400186784,"mc":[{"id":"1.232160907","rc":[{"batb":[[0,1.49,5.05],[1,1.08,1.77],[2,1.04,1618.04]],"ltp":1.49,"tv":201.18,"id":891555}]}]}
{"op":"mcm","clk":"11939577104","pt":1724400197800,"mc":[{"id":"1.232160907","rc":[{"batb":[[0,1.5,5],[1,1.49,5.05],[2,1.08,1.77]],"ltp":1.49,"tv":201.18,"id":891555}]}]}
{"op":"mcm","clk":"11939577289","pt":1724400201287,"mc":[{"id":"1.232160907","rc":[{"batb":[[0,1.49,5.05],[1,1.08,1.77],[2,1.04,1618.04]],"ltp":1.49,"tv":201.18,"id":891555}]}]}
{"op":"mcm","clk":"11939577421","pt":1724400205188,"mc":[{"id":"1.232160907","rc":[{"batb":[[0,1.5,5],[1,1.49,5.05],[2,1.08,1.77]],"ltp":1.49,"tv":201.18,"id":891555}]}]}
{"op":"mcm","clk":"11939577567","pt":1724400208779,"mc":[{"id":"1.232160907","rc":[{"batb":[[0,1.49,5.05],[1,1.08,1.77],[2,1.04,1618.04]],"ltp":1.49,"tv":201.18,"id":891555}]}]}
{"op":"mcm","clk":"11939578282","pt":1724400220808,"mc":[{"id":"1.232160907","rc":[{"batb":[[0,1.5,5],[1,1.49,5.05],[2,1.08,1.77]],"ltp":1.49,"tv":201.18,"id":891555}]}]}
{"op":"mcm","clk":"11939578448","pt":1724400224107,"mc":[{"id":"1.232160907","rc":[{"batb":[[0,1.49,5.05],[1,1.08,1.77],[2,1.04,1618.04]],"ltp":1.49,"tv":201.18,"id":891555}]}]}
{"op":"mcm","clk":"11939578674","pt":1724400226719,"mc":[{"id":"1.232160907","rc":[{"batb":[[0,1.5,5],[1,1.49,5.05],[2,1.08,1.77]],"ltp":1.49,"tv":201.18,"id":891555}]}]}
{"op":"mcm","clk":"11939578852","pt":1724400229905,"mc":[{"id":"1.232160907","rc":[{"batb":[[0,1.49,5.05],[1,1.08,1.77],[2,1.04,1618.04]],"ltp":1.49,"tv":201.18,"id":891555}]}]}
{"op":"mcm","clk":"11939579094","pt":1724400235602,"mc":[{"id":"1.232160907","rc":[{"batb":[[0,1.5,5],[1,1.49,5.05],[2,1.08,1.77]],"ltp":1.49,"tv":201.18,"id":891555}]}]}
{"op":"mcm","clk":"11939579223","pt":1724400239233,"mc":[{"id":"1.232160907","rc":[{"batb":[[0,1.49,5.05],[1,1.08,1.77],[2,1.04,1618.04]],"ltp":1.49,"tv":201.18,"id":891555}]}]}
{"op":"mcm","clk":"11939579308","pt":1724400241543,"mc":[{"id":"1.232160907","rc":[{"batb":[[0,1.5,5],[1,1.49,5.05],[2,1.08,1.77]],"ltp":1.49,"tv":201.18,"id":891555}]}]}
{"op":"mcm","clk":"11939579498","pt":1724400245056,"mc":[{"id":"1.232160907","rc":[{"batb":[[0,1.49,5.05],[1,1.08,1.77],[2,1.04,1618.04]],"ltp":1.49,"tv":201.18,"id":891555}]}]}
{"op":"mcm","clk":"11939579675","pt":1724400248453,"mc":[{"id":"1.232160907","rc":[{"batb":[[0,1.5,5],[1,1.49,5.05],[2,1.08,1.77]],"ltp":1.49,"tv":201.18,"id":891555}]}]}
{"op":"mcm","clk":"11939579845","pt":1724400251650,"mc":[{"id":"1.232160907","rc":[{"batb":[[0,1.49,5.05],[1,1.08,1.77],[2,1.04,1618.04]],"ltp":1.49,"tv":201.18,"id":891555}]}]}
{"op":"mcm","clk":"11939580097","pt":1724400256162,"mc":[{"id":"1.232160907","rc":[{"batb":[[0,1.5,5],[1,1.49,5.05],[2,1.08,1.77]],"ltp":1.49,"tv":201.18,"id":891555}]}]}
{"op":"mcm","clk":"11939580258","pt":1724400259449,"mc":[{"id":"1.232160907","rc":[{"batb":[[0,1.49,5.05],[1,1.08,1.77],[2,1.04,1618.04]],"ltp":1.49,"tv":201.18,"id":891555}]}]}
{"op":"mcm","clk":"11939580398","pt":1724400263061,"mc":[{"id":"1.232160907","rc":[{"batb":[[0,1.5,5],[1,1.49,5.05],[2,1.08,1.77]],"ltp":1.49,"tv":201.18,"id":891555}]}]}
{"op":"mcm","clk":"11939580572","pt":1724400266463,"mc":[{"id":"1.232160907","rc":[{"batb":[[0,1.49,5.05],[1,1.08,1.77],[2,1.04,1618.04]],"ltp":1.49,"tv":201.18,"id":891555}]}]}
{"op":"mcm","clk":"11939580736","pt":1724400270171,"mc":[{"id":"1.232160907","rc":[{"batb":[[0,1.5,5],[1,1.49,5.05],[2,1.08,1.77]],"ltp":1.49,"tv":201.18,"id":891555}]}]}
{"op":"mcm","clk":"11939580914","pt":1724400273442,"mc":[{"id":"1.232160907","rc":[{"batb":[[0,1.49,5.05],[1,1.08,1.77],[2,1.04,1618.04]],"ltp":1.49,"tv":201.18,"id":891555}]}]}
{"op":"mcm","clk":"11939581029","pt":1724400275664,"mc":[{"id":"1.232160907","rc":[{"batb":[[0,1.5,5],[1,1.49,5.05],[2,1.08,1.77]],"ltp":1.49,"tv":201.18,"id":891555}]}]}
{"op":"mcm","clk":"11939581151","pt":1724400278967,"mc":[{"id":"1.232160907","rc":[{"batb":[[0,1.49,5.05],[1,1.08,1.77],[2,1.04,1618.04]],"ltp":1.49,"tv":201.18,"id":891555}]}]}
{"op":"mcm","clk":"11939581285","pt":1724400282149,"mc":[{"id":"1.232160907","rc":[{"batb":[[0,1.5,5],[1,1.49,5.05],[2,1.08,1.77]],"ltp":1.49,"tv":201.18,"id":891555}]}]}
{"op":"mcm","clk":"11939581650","pt":1724400285501,"mc":[{"id":"1.232160907","rc":[{"batb":[[0,1.49,5.05],[1,1.08,1.77],[2,1.04,1618.04]],"ltp":1.49,"tv":201.18,"id":891555}]}]}
{"op":"mcm","clk":"11939582053","pt":1724400288504,"mc":[{"id":"1.232160907","rc":[{"batb":[[0,1.5,5],[1,1.49,5.05],[2,1.08,1.77]],"ltp":1.49,"tv":201.18,"id":891555}]}]}
{"op":"mcm","clk":"11939582501","pt":1724400291826,"mc":[{"id":"1.232160907","rc":[{"batb":[[0,1.49,5.05],[1,1.08,1.77],[2,1.04,1618.04]],"ltp":1.49,"tv":201.18,"id":891555}]}]}
{"op":"mcm","clk":"11939582959","pt":1724400295530,"mc":[{"id":"1.232160907","rc":[{"batb":[[0,1.5,5],[1,1.49,5.05],[2,1.08,1.77]],"ltp":1.49,"tv":201.18,"id":891555}]}]}
{"op":"mcm","clk":"11939583447","pt":1724400298951,"mc":[{"id":"1.232160907","rc":[{"batb":[[0,1.49,5.05],[1,1.08,1.77],[2,1.04,1618.04]],"ltp":1.49,"tv":201.18,"id":891555}]}]}
{"op":"mcm","clk":"11939583882","pt":1724400301800,"mc":[{"id":"1.232160907","rc":[{"batb":[[0,1.5,5],[1,1.49,5.05],[2,1.08,1.77]],"ltp":1.49,"tv":201.18,"id":891555}]}]}
{"op":"mcm","clk":"11939584341","pt":1724400305156,"mc":[{"id":"1.232160907","rc":[{"batb":[[0,1.49,5.05],[1,1.08,1.77],[2,1.04,1618.04]],"ltp":1.49,"tv":201.18,"id":891555}]}]}
{"op":"mcm","clk":"11939584661","pt":1724400307745,"mc":[{"id":"1.232160907","rc":[{"batb":[[0,1.5,5],[1,1.49,5.05],[2,1.08,1.77]],"ltp":1.49,"tv":201.18,"id":891555}]}]}
{"op":"mcm","clk":"11939584974","pt":1724400310807,"mc":[{"id":"1.232160907","rc":[{"batb":[[0,1.49,5.05],[1,1.08,1.77],[2,1.04,1618.04]],"ltp":1.49,"tv":201.18,"id":891555}]}]}
{"op":"mcm","clk":"11939585302","pt":1724400313021,"mc":[{"id":"1.232160907","rc":[{"batb":[[0,1.5,5],[1,1.49,5.05],[2,1.08,1.77]],"ltp":1.49,"tv":201.18,"id":891555}]}]}
{"op":"mcm","clk":"11939585673","pt":1724400316143,"mc":[{"id":"1.232160907","rc":[{"batb":[[0,1.49,5.05],[1,1.08,1.77],[2,1.04,1618.04]],"ltp":1.49,"tv":201.18,"id":891555}]}]}
{"op":"mcm","clk":"11939585909","pt":1724400318979,"mc":[{"id":"1.232160907","rc":[{"batb":[[0,1.5,5],[1,1.49,5.05],[2,1.08,1.77]],"ltp":1.49,"tv":201.18,"id":891555}]}]}
{"op":"mcm","clk":"11939586091","pt":1724400321969,"mc":[{"id":"1.232160907","rc":[{"batb":[[0,1.49,5.05],[1,1.08,1.77],[2,1.04,1618.04]],"ltp":1.49,"tv":201.18,"id":891555}]}]}
{"op":"mcm","clk":"11939586362","pt":1724400326862,"mc":[{"id":"1.232160907","rc":[{"batb":[[0,1.5,5],[1,1.49,5.05],[2,1.08,1.77]],"ltp":1.49,"tv":201.18,"id":891555}]}]}
{"op":"mcm","clk":"11939586519","pt":1724400330092,"mc":[{"id":"1.232160907","rc":[{"batb":[[0,1.49,5.05],[1,1.08,1.77],[2,1.04,1618.04]],"ltp":1.49,"tv":201.18,"id":891555}]}]}
{"op":"mcm","clk":"11939587044","pt":1724400335791,"mc":[{"id":"1.232160907","rc":[{"batb":[[0,1.5,5],[1,1.49,5.05],[2,1.08,1.77]],"ltp":1.49,"tv":201.18,"id":891555}]}]}
{"op":"mcm","clk":"11939587366","pt":1724400339249,"mc":[{"id":"1.232160907","rc":[{"batb":[[0,1.49,5.05],[1,1.08,1.77],[2,1.04,1618.04]],"ltp":1.49,"tv":201.18,"id":891555}]}]}
{"op":"mcm","clk":"11939587549","pt":1724400341876,"mc":[{"id":"1.232160907","rc":[{"batb":[[0,1.5,5],[1,1.49,5.05],[2,1.08,1.77]],"ltp":1.49,"tv":201.18,"id":891555}]}]}
{"op":"mcm","clk":"11939587736","pt":1724400345072,"mc":[{"id":"1.232160907","rc":[{"batb":[[0,1.49,5.05],[1,1.08,1.77],[2,1.04,1618.04]],"ltp":1.49,"tv":201.18,"id":891555}]}]}
{"op":"mcm","clk":"11939587967","pt":1724400348386,"mc":[{"id":"1.232160907","rc":[{"batb":[[0,1.5,5],[1,1.49,5.05],[2,1.08,1.77]],"ltp":1.49,"tv":201.18,"id":891555}]}]}
{"op":"mcm","clk":"11939588208","pt":1724400351987,"mc":[{"id":"1.232160907","rc":[{"batb":[[0,1.49,5.05],[1,1.08,1.77],[2,1.04,1618.04]],"ltp":1.49,"tv":201.18,"id":891555}]}]}
{"op":"mcm","clk":"11939588370","pt":1724400354666,"mc":[{"id":"1.232160907","rc":[{"batb":[[0,1.5,5],[1,1.49,5.05],[2,1.08,1.77]],"ltp":1.49,"tv":201.18,"id":891555}]}]}
{"op":"mcm","clk":"11939588546","pt":1724400357998,"mc":[{"id":"1.232160907","rc":[{"batb":[[0,1.49,5.05],[1,1.08,1.77],[2,1.04,1618.04]],"ltp":1.49,"tv":201.18,"id":891555}]}]}
{"op":"mcm","clk":"11939588620","pt":1724400360203,"mc":[{"id":"1.232160907","rc":[{"batb":[[0,1.5,5],[1,1.49,5.05],[2,1.08,1.77]],"ltp":1.49,"tv":201.18,"id":891555}]}]}
{"op":"mcm","clk":"11939588821","pt":1724400363572,"mc":[{"id":"1.232160907","rc":[{"batb":[[0,1.49,5.05],[1,1.08,1.77],[2,1.04,1618.04]],"ltp":1.49,"tv":201.18,"id":891555}]}]}
{"op":"mcm","clk":"11939589057","pt":1724400366395,"mc":[{"id":"1.232160907","rc":[{"batb":[[0,1.5,5],[1,1.49,5.05],[2,1.08,1.77]],"ltp":1.49,"tv":201.18,"id":891555}]}]}
{"op":"mcm","clk":"11939589273","pt":1724400369992,"mc":[{"id":"1.232160907","rc":[{"batb":[[0,1.49,5.05],[1,1.08,1.77],[2,1.04,1618.04]],"ltp":1.49,"tv":201.18,"id":891555}]}]}
{"op":"mcm","clk":"11939589455","pt":1724400372409,"mc":[{"id":"1.232160907","rc":[{"batb":[[0,1.5,5],[1,1.49,5.05],[2,1.08,1.77]],"ltp":1.49,"tv":201.18,"id":891555}]}]}
{"op":"mcm","clk":"11939589676","pt":1724400375678,"mc":[{"id":"1.232160907","rc":[{"batb":[[0,1.49,5.05],[1,1.08,1.77],[2,1.04,1618.04]],"ltp":1.49,"tv":201.18,"id":891555}]}]}
{"op":"mcm","clk":"11939589992","pt":1724400379193,"mc":[{"id":"1.232160907","rc":[{"batb":[[0,1.5,5],[1,1.49,5.05],[2,1.08,1.77]],"ltp":1.49,"tv":201.18,"id":891555}]}]}
{"op":"mcm","clk":"11939590242","pt":1724400382719,"mc":[{"id":"1.232160907","rc":[{"batb":[[0,1.49,5.05],[1,1.08,1.77],[2,1.04,1618.04]],"ltp":1.49,"tv":201.18,"id":891555}]}]}
{"op":"mcm","clk":"11939590737","pt":1724400386148,"mc":[{"id":"1.232160907","rc":[{"batb":[[0,1.5,5],[1,1.49,5.05],[2,1.08,1.77]],"ltp":1.49,"tv":201.18,"id":891555}]}]}
{"op":"mcm","clk":"11939591260","pt":1724400389529,"mc":[{"id":"1.232160907","rc":[{"batb":[[0,1.49,5.05],[1,1.08,1.77],[2,1.04,1618.04]],"ltp":1.49,"tv":201.18,"id":891555}]}]}
{"op":"mcm","clk":"11939591605","pt":1724400392065,"mc":[{"id":"1.232160907","rc":[{"batb":[[0,1.5,5],[1,1.49,5.05],[2,1.08,1.77]],"ltp":1.49,"tv":201.18,"id":891555}]}]}
{"op":"mcm","clk":"11939592111","pt":1724400395462,"mc":[{"id":"1.232160907","rc":[{"batb":[[0,1.49,5.05],[1,1.08,1.77],[2,1.04,1618.04]],"ltp":1.49,"tv":201.18,"id":891555}]}]}
{"op":"mcm","clk":"11939592449","pt":1724400397852,"mc":[{"id":"1.232160907","rc":[{"batb":[[0,1.5,5],[1,1.49,5.05],[2,1.08,1.77]],"ltp":1.49,"tv":201.18,"id":891555}]}]}
{"op":"mcm","clk":"11939592935","pt":1724400401271,"mc":[{"id":"1.232160907","rc":[{"batb":[[0,1.49,5.05],[1,1.08,1.77],[2,1.04,1618.04]],"ltp":1.49,"tv":201.18,"id":891555}]}]}
{"op":"mcm","clk":"11939593269","pt":1724400404070,"mc":[{"id":"1.232160907","rc":[{"batb":[[0,1.5,5],[1,1.49,5.05],[2,1.08,1.77]],"ltp":1.49,"tv":201.18,"id":891555}]}]}
{"op":"mcm","clk":"11939593644","pt":1724400407379,"mc":[{"id":"1.232160907","rc":[{"batb":[[0,1.49,5.05],[1,1.08,1.77],[2,1.04,1618.04]],"ltp":1.49,"tv":201.18,"id":891555}]}]}
{"op":"mcm","clk":"11939593938","pt":1724400409758,"mc":[{"id":"1.232160907","rc":[{"batb":[[0,1.5,5],[1,1.49,5.05],[2,1.08,1.77]],"ltp":1.49,"tv":201.18,"id":891555}]}]}
{"op":"mcm","clk":"11939594219","pt":1724400413256,"mc":[{"id":"1.232160907","rc":[{"batb":[[0,1.49,5.05],[1,1.08,1.77],[2,1.04,1618.04]],"ltp":1.49,"tv":201.18,"id":891555}]}]}
{"op":"mcm","clk":"11939594500","pt":1724400416957,"mc":[{"id":"1.232160907","rc":[{"batb":[[0,1.5,5],[1,1.49,5.05],[2,1.08,1.77]],"ltp":1.49,"tv":201.18,"id":891555}]}]}
{"op":"mcm","clk":"11939594699","pt":1724400420192,"mc":[{"id":"1.232160907","rc":[{"batb":[[0,1.49,5.05],[1,1.08,1.77],[2,1.04,1618.04]],"ltp":1.49,"tv":201.18,"id":891555}]}]}
{"op":"mcm","clk":"11939594930","pt":1724400423879,"mc":[{"id":"1.232160907","rc":[{"batb":[[0,1.5,5],[1,1.49,5.05],[2,1.08,1.77]],"ltp":1.49,"tv":201.18,"id":891555}]}]}
{"op":"mcm","clk":"11939595162","pt":1724400427074,"mc":[{"id":"1.232160907","rc":[{"batb":[[0,1.49,5.05],[1,1.08,1.77],[2,1.04,1618.04]],"ltp":1.49,"tv":201.18,"id":891555}]}]}
{"op":"mcm","clk":"11939595329","pt":1724400429707,"mc":[{"id":"1.232160907","rc":[{"batb":[[0,1.5,5],[1,1.49,5.05],[2,1.08,1.77]],"ltp":1.49,"tv":201.18,"id":891555}]}]}
{"op":"mcm","clk":"11939595632","pt":1724400432916,"mc":[{"id":"1.232160907","rc":[{"batb":[[0,1.49,5.05],[1,1.08,1.77],[2,1.04,1618.04]],"ltp":1.49,"tv":201.18,"id":891555}]}]}
{"op":"mcm","clk":"11939595923","pt":1724400437502,"mc":[{"id":"1.232160907","rc":[{"batb":[[0,1.5,5],[1,1.49,5.05],[2,1.08,1.77]],"ltp":1.49,"tv":201.18,"id":891555}]}]}
{"op":"mcm","clk":"11939596188","pt":1724400440897,"mc":[{"id":"1.232160907","rc":[{"batb":[[0,1.49,5.05],[1,1.08,1.77],[2,1.04,1618.04]],"ltp":1.49,"tv":201.18,"id":891555}]}]}
{"op":"mcm","clk":"11939596416","pt":1724400443787,"mc":[{"id":"1.232160907","rc":[{"batb":[[0,1.5,5],[1,1.49,5.05],[2,1.08,1.77]],"ltp":1.49,"tv":201.18,"id":891555}]}]}
{"op":"mcm","clk":"11939596696","pt":1724400446988,"mc":[{"id":"1.232160907","rc":[{"batb":[[0,1.49,5.05],[1,1.08,1.77],[2,1.04,1618.04]],"ltp":1.49,"tv":201.18,"id":891555}]}]}
{"op":"mcm","clk":"11939596956","pt":1724400451110,"mc":[{"id":"1.232160907","rc":[{"batb":[[0,1.5,5],[1,1.49,5.05],[2,1.08,1.77]],"ltp":1.49,"tv":201.18,"id":891555}]}]}
{"op":"mcm","clk":"11939597117","pt":1724400454525,"mc":[{"id":"1.232160907","rc":[{"batb":[[0,1.49,5.05],[1,1.08,1.77],[2,1.04,1618.04]],"ltp":1.49,"tv":201.18,"id":891555}]}]}
{"op":"mcm","clk":"11939597543","pt":1724400461906,"mc":[{"id":"1.232160907","rc":[{"batb":[[0,1.5,5],[1,1.49,5.05],[2,1.08,1.77]],"ltp":1.49,"tv":201.18,"id":891555}]}]}
{"op":"mcm","clk":"11939597711","pt":1724400465245,"mc":[{"id":"1.232160907","rc":[{"batb":[[0,1.49,5.05],[1,1.08,1.77],[2,1.04,1618.04]],"ltp":1.49,"tv":201.18,"id":891555}]}]}
{"op":"mcm","clk":"11939597956","pt":1724400469118,"mc":[{"id":"1.232160907","rc":[{"batb":[[0,1.5,5],[1,1.49,5.05],[2,1.08,1.77]],"ltp":1.49,"tv":201.18,"id":891555}]}]}
{"op":"mcm","clk":"11939598169","pt":1724400472626,"mc":[{"id":"1.232160907","rc":[{"batb":[[0,1.49,5.05],[1,1.08,1.77],[2,1.04,1618.04]],"ltp":1.49,"tv":201.18,"id":891555}]}]}
{"op":"mcm","clk":"11939598503","pt":1724400475838,"mc":[{"id":"1.232160907","rc":[{"batb":[[0,1.5,5],[1,1.49,5.05],[2,1.08,1.77]],"ltp":1.49,"tv":201.18,"id":891555}]}]}
{"op":"mcm","clk":"11939598730","pt":1724400479330,"mc":[{"id":"1.232160907","rc":[{"batb":[[0,1.49,5.05],[1,1.08,1.77],[2,1.04,1618.04]],"ltp":1.49,"tv":201.18,"id":891555}]}]}
{"op":"mcm","clk":"11939598874","pt":1724400481659,"mc":[{"id":"1.232160907","rc":[{"batb":[[0,1.5,5],[1,1.49,5.05],[2,1.08,1.77]],"ltp":1.49,"tv":201.18,"id":891555}]}]}
{"op":"mcm","clk":"11939599081","pt":1724400484948,"mc":[{"id":"1.232160907","rc":[{"batb":[[0,1.49,5.05],[1,1.08,1.77],[2,1.04,1618.04]],"ltp":1.49,"tv":201.18,"id":891555}]}]}
{"op":"mcm","clk":"11939599267","pt":1724400488046,"mc":[{"id":"1.232160907","rc":[{"batb":[[0,1.5,5],[1,1.49,5.05],[2,1.08,1.77]],"ltp":1.49,"tv":201.18,"id":891555}]}]}
{"op":"mcm","clk":"11939599495","pt":1724400491282,"mc":[{"id":"1.232160907","rc":[{"batb":[[0,1.49,5.05],[1,1.08,1.77],[2,1.04,1618.04]],"ltp":1.49,"tv":201.18,"id":891555}]}]}
{"op":"mcm","clk":"11939599672","pt":1724400493848,"mc":[{"id":"1.232160907","rc":[{"batb":[[0,1.5,5],[1,1.49,5.05],[2,1.08,1.77]],"ltp":1.49,"tv":201.18,"id":891555}]}]}
{"op":"mcm","clk":"11939599880","pt":1724400497165,"mc":[{"id":"1.232160907","rc":[{"batb":[[0,1.49,5.05],[1,1.08,1.77],[2,1.04,1618.04]],"ltp":1.49,"tv":201.18,"id":891555}]}]}
{"op":"mcm","clk":"11939600026","pt":1724400499377,"mc":[{"id":"1.232160907","rc":[{"batb":[[0,1.5,5],[1,1.49,5.05],[2,1.08,1.77]],"ltp":1.49,"tv":201.18,"id":891555}]}]}
{"op":"mcm","clk":"11939600233","pt":1724400502872,"mc":[{"id":"1.232160907","rc":[{"batb":[[0,1.49,5.05],[1,1.08,1.77],[2,1.04,1618.04]],"ltp":1.49,"tv":201.18,"id":891555}]}]}
{"op":"mcm","clk":"11939600393","pt":1724400505654,"mc":[{"id":"1.232160907","rc":[{"batb":[[0,1.5,5],[1,1.49,5.05],[2,1.08,1.77]],"ltp":1.49,"tv":201.18,"id":891555}]}]}
{"op":"mcm","clk":"11939600629","pt":1724400508850,"mc":[{"id":"1.232160907","rc":[{"batb":[[0,1.49,5.05],[1,1.08,1.77],[2,1.04,1618.04]],"ltp":1.49,"tv":201.18,"id":891555}]}]}
{"op":"mcm","clk":"11939600899","pt":1724400513681,"mc":[{"id":"1.232160907","rc":[{"batb":[[0,1.5,5],[1,1.49,5.05],[2,1.08,1.77]],"ltp":1.49,"tv":201.18,"id":891555}]}]}
{"op":"mcm","clk":"11939601068","pt":1724400516886,"mc":[{"id":"1.232160907","rc":[{"batb":[[0,1.49,5.05],[1,1.08,1.77],[2,1.04,1618.04]],"ltp":1.49,"tv":201.18,"id":891555}]}]}
{"op":"mcm","clk":"11939601498","pt":1724400522299,"mc":[{"id":"1.232160907","rc":[{"batb":[[0,1.5,5],[1,1.49,5.05],[2,1.08,1.77]],"ltp":1.49,"tv":201.18,"id":891555}]}]}
{"op":"mcm","clk":"11939601694","pt":1724400525709,"mc":[{"id":"1.232160907","rc":[{"batb":[[0,1.49,5.05],[1,1.08,1.77],[2,1.04,1618.04]],"ltp":1.49,"tv":201.18,"id":891555}]}]}
{"op":"mcm","clk":"11939601883","pt":1724400529012,"mc":[{"id":"1.232160907","rc":[{"batb":[[0,1.5,5],[1,1.49,5.05],[2,1.08,1.77]],"ltp":1.49,"tv":201.18,"id":891555}]}]}
{"op":"mcm","clk":"11939602096","pt":1724400532409,"mc":[{"id":"1.232160907","rc":[{"batb":[[0,1.49,5.05],[1,1.08,1.77],[2,1.04,1618.04]],"ltp":1.49,"tv":201.18,"id":891555}]}]}
{"op":"mcm","clk":"11939602246","pt":1724400534900,"mc":[{"id":"1.232160907","rc":[{"batb":[[0,1.5,5],[1,1.49,5.05],[2,1.08,1.77]],"ltp":1.49,"tv":201.18,"id":891555}]}]}
{"op":"mcm","clk":"11939602480","pt":1724400538085,"mc":[{"id":"1.232160907","rc":[{"batb":[[0,1.49,5.05],[1,1.08,1.77],[2,1.04,1618.04]],"ltp":1.49,"tv":201.18,"id":891555}]}]}
{"op":"mcm","clk":"11939602856","pt":1724400543096,"mc":[{"id":"1.232160907","rc":[{"batb":[[0,1.5,5],[1,1.49,5.05],[2,1.08,1.77]],"ltp":1.49,"tv":201.18,"id":891555}]}]}
{"op":"mcm","clk":"11939603078","pt":1724400546304,"mc":[{"id":"1.232160907","rc":[{"batb":[[0,1.49,5.05],[1,1.08,1.77],[2,1.04,1618.04]],"ltp":1.49,"tv":201.18,"id":891555}]}]}
{"op":"mcm","clk":"11939603268","pt":1724400549195,"mc":[{"id":"1.232160907","rc":[{"batb":[[0,1.5,5],[1,1.49,5.05],[2,1.08,1.77]],"ltp":1.49,"tv":201.18,"id":891555}]}]}
{"op":"mcm","clk":"11939603395","pt":1724400550849,"mc":[{"id":"1.232160907","rc":[{"batb":[[0,1.81,6.8],[1,1.8,138.46],[2,1.08,1.77]],"ltp":1.49,"tv":191.96,"id":144197},{"batl":[[0,2.24,5.42],[1,8,3.54],[2,11.5,0.69]],"ltp":1.49,"tv":201.18,"id":891555}]}]}
{"op":"mcm","clk":"11939603560","pt":1724400552509,"mc":[{"id":"1.232160907","rc":[{"batb":[[0,1.49,5.05],[1,1.08,1.77],[2,1.04,1618.04]],"ltp":1.49,"tv":201.18,"id":891555}]}]}
{"op":"mcm","clk":"11939603832","pt":1724400555807,"mc":[{"id":"1.232160907","rc":[{"batb":[[0,1.5,5],[1,1.49,5.05],[2,1.08,1.77]],"ltp":1.49,"tv":201.18,"id":891555}]}]}
{"op":"mcm","clk":"11939604142","pt":1724400559115,"mc":[{"id":"1.232160907","rc":[{"batb":[[0,1.49,5.05],[1,1.08,1.77],[2,1.04,1618.04]],"ltp":1.49,"tv":201.18,"id":891555}]}]}
{"op":"mcm","clk":"11939604353","pt":1724400562045,"mc":[{"id":"1.232160907","rc":[{"batb":[[0,1.5,5],[1,1.49,5.05],[2,1.08,1.77]],"ltp":1.49,"tv":201.18,"id":891555}]}]}
{"op":"mcm","clk":"11939604549","pt":1724400565302,"mc":[{"id":"1.232160907","rc":[{"batb":[[0,1.49,5.05],[1,1.08,1.77],[2,1.04,1618.04]],"ltp":1.49,"tv":201.18,"id":891555}]}]}
{"op":"mcm","clk":"11939604725","pt":1724400568233,"mc":[{"id":"1.232160907","rc":[{"batb":[[0,1.5,5],[1,1.49,5.05],[2,1.08,1.77]],"ltp":1.49,"tv":201.18,"id":891555}]}]}
{"op":"mcm","clk":"11939604931","pt":1724400571617,"mc":[{"id":"1.232160907","rc":[{"batb":[[0,1.49,5.05],[1,1.08,1.77],[2,1.04,1618.04]],"ltp":1.49,"tv":201.18,"id":891555}]}]}
{"op":"mcm","clk":"11939605279","pt":1724400576312,"mc":[{"id":"1.232160907","rc":[{"batb":[[0,1.5,5],[1,1.49,5.05],[2,1.08,1.77]],"ltp":1.49,"tv":201.18,"id":891555}]}]}
{"op":"mcm","clk":"11939605473","pt":1724400579628,"mc":[{"id":"1.232160907","rc":[{"batb":[[0,1.49,5.05],[1,1.08,1.77],[2,1.04,1618.04]],"ltp":1.49,"tv":201.18,"id":891555}]}]}
{"op":"mcm","clk":"11939605684","pt":1724400583320,"mc":[{"id":"1.232160907","rc":[{"batb":[[0,1.5,5],[1,1.49,5.05],[2,1.08,1.77]],"ltp":1.49,"tv":201.18,"id":891555}]}]}
{"op":"mcm","clk":"11939605907","pt":1724400586455,"mc":[{"id":"1.232160907","rc":[{"batb":[[0,1.49,5.05],[1,1.08,1.77],[2,1.04,1618.04]],"ltp":1.49,"tv":201.18,"id":891555}]}]}
{"op":"mcm","clk":"11939606214","pt":1724400589452,"mc":[{"id":"1.232160907","rc":[{"batb":[[0,1.5,5],[1,1.49,5.05],[2,1.08,1.77]],"ltp":1.49,"tv":201.18,"id":891555}]}]}
{"op":"mcm","clk":"11939606443","pt":1724400592735,"mc":[{"id":"1.232160907","rc":[{"batb":[[0,1.49,5.05],[1,1.08,1.77],[2,1.04,1618.04]],"ltp":1.49,"tv":201.18,"id":891555}]}]}
{"op":"mcm","clk":"11939606611","pt":1724400595846,"mc":[{"id":"1.232160907","rc":[{"batb":[[0,1.5,5],[1,1.49,5.05],[2,1.08,1.77]],"ltp":1.49,"tv":201.18,"id":891555}]}]}
{"op":"mcm","clk":"11939606776","pt":1724400599072,"mc":[{"id":"1.232160907","rc":[{"batb":[[0,1.49,5.05],[1,1.08,1.77],[2,1.04,1618.04]],"ltp":1.49,"tv":201.18,"id":891555}]}]}
{"op":"mcm","clk":"11939606957","pt":1724400601288,"mc":[{"id":"1.232160907","rc":[{"batb":[[0,1.5,5],[1,1.49,5.05],[2,1.08,1.77]],"ltp":1.49,"tv":201.18,"id":891555}]}]}
{"op":"mcm","clk":"11939607214","pt":1724400604581,"mc":[{"id":"1.232160907","rc":[{"batb":[[0,1.49,5.05],[1,1.08,1.77],[2,1.04,1618.04]],"ltp":1.49,"tv":201.18,"id":891555}]}]}
{"op":"mcm","clk":"11939607376","pt":1724400607089,"mc":[{"id":"1.232160907","rc":[{"batb":[[0,1.5,5],[1,1.49,5.05],[2,1.08,1.77]],"ltp":1.49,"tv":201.18,"id":891555}]}]}
{"op":"mcm","clk":"11939607654","pt":1724400610596,"mc":[{"id":"1.232160907","rc":[{"batb":[[0,1.49,5.05],[1,1.08,1.77],[2,1.04,1618.04]],"ltp":1.49,"tv":201.18,"id":891555}]}]}
{"op":"mcm","clk":"11939607833","pt":1724400613410,"mc":[{"id":"1.232160907","rc":[{"batb":[[0,1.5,5],[1,1.49,5.05],[2,1.08,1.77]],"ltp":1.49,"tv":201.18,"id":891555}]}]}
{"op":"mcm","clk":"11939608003","pt":1724400616589,"mc":[{"id":"1.232160907","rc":[{"batb":[[0,1.49,5.05],[1,1.08,1.77],[2,1.04,1618.04]],"ltp":1.49,"tv":201.18,"id":891555}]}]}
{"op":"mcm","clk":"11939608169","pt":1724400619520,"mc":[{"id":"1.232160907","rc":[{"batb":[[0,1.5,5],[1,1.49,5.05],[2,1.08,1.77]],"ltp":1.49,"tv":201.18,"id":891555}]}]}
{"op":"mcm","clk":"11939608408","pt":1724400622974,"mc":[{"id":"1.232160907","rc":[{"batb":[[0,1.49,5.05],[1,1.08,1.77],[2,1.04,1618.04]],"ltp":1.49,"tv":201.18,"id":891555}]}]}
{"op":"mcm","clk":"11939608534","pt":1724400625129,"mc":[{"id":"1.232160907","rc":[{"batb":[[0,1.5,5],[1,1.49,5.05],[2,1.08,1.77]],"ltp":1.49,"tv":201.18,"id":891555}]}]}
{"op":"mcm","clk":"11939608752","pt":1724400628457,"mc":[{"id":"1.232160907","rc":[{"batb":[[0,1.49,5.05],[1,1.08,1.77],[2,1.04,1618.04]],"ltp":1.49,"tv":201.18,"id":891555}]}]}
{"op":"mcm","clk":"11939608951","pt":1724400631637,"mc":[{"id":"1.232160907","rc":[{"batb":[[0,1.5,5],[1,1.49,5.05],[2,1.08,1.77]],"ltp":1.49,"tv":201.18,"id":891555}]}]}
{"op":"mcm","clk":"11939609118","pt":1724400634866,"mc":[{"id":"1.232160907","rc":[{"batb":[[0,1.49,5.05],[1,1.08,1.77],[2,1.04,1618.04]],"ltp":1.49,"tv":201.18,"id":891555}]}]}
{"op":"mcm","clk":"11939609334","pt":1724400637745,"mc":[{"id":"1.232160907","rc":[{"batb":[[0,1.5,5],[1,1.49,5.05],[2,1.08,1.77]],"ltp":1.49,"tv":201.18,"id":891555}]}]}
{"op":"mcm","clk":"11939609538","pt":1724400640972,"mc":[{"id":"1.232160907","rc":[{"batb":[[0,1.49,5.05],[1,1.08,1.77],[2,1.04,1618.04]],"ltp":1.49,"tv":201.18,"id":891555}]}]}
{"op":"mcm","clk":"11939609840","pt":1724400645765,"mc":[{"id":"1.232160907","rc":[{"batb":[[0,1.5,5],[1,1.49,5.05],[2,1.08,1.77]],"ltp":1.49,"tv":201.18,"id":891555}]}]}
{"op":"mcm","clk":"11939610085","pt":1724400649158,"mc":[{"id":"1.232160907","rc":[{"batb":[[0,1.49,5.05],[1,1.08,1.77],[2,1.04,1618.04]],"ltp":1.49,"tv":201.18,"id":891555}]}]}
{"op":"mcm","clk":"11939610266","pt":1724400651569,"mc":[{"id":"1.232160907","rc":[{"batb":[[0,1.5,5],[1,1.49,5.05],[2,1.08,1.77]],"ltp":1.49,"tv":201.18,"id":891555}]}]}
{"op":"mcm","clk":"11939610476","pt":1724400654952,"mc":[{"id":"1.232160907","rc":[{"batb":[[0,1.49,5.05],[1,1.08,1.77],[2,1.04,1618.04]],"ltp":1.49,"tv":201.18,"id":891555}]}]}
{"op":"mcm","clk":"11939610598","pt":1724400657356,"mc":[{"id":"1.232160907","rc":[{"batb":[[0,1.5,5],[1,1.49,5.05],[2,1.08,1.77]],"ltp":1.49,"tv":201.18,"id":891555}]}]}
{"op":"mcm","clk":"11939610848","pt":1724400660652,"mc":[{"id":"1.232160907","rc":[{"batb":[[0,1.49,5.05],[1,1.08,1.77],[2,1.04,1618.04]],"ltp":1.49,"tv":201.18,"id":891555}]}]}
{"op":"mcm","clk":"11939610993","pt":1724400662863,"mc":[{"id":"1.232160907","rc":[{"batb":[[0,1.5,5],[1,1.49,5.05],[2,1.08,1.77]],"ltp":1.49,"tv":201.18,"id":891555}]}]}
{"op":"mcm","clk":"11939611219","pt":1724400666045,"mc":[{"id":"1.232160907","rc":[{"batb":[[0,1.49,5.05],[1,1.08,1.77],[2,1.04,1618.04]],"ltp":1.49,"tv":201.18,"id":891555}]}]}
{"op":"mcm","clk":"11939611397","pt":1724400668764,"mc":[{"id":"1.232160907","rc":[{"batb":[[0,1.5,5],[1,1.49,5.05],[2,1.08,1.77]],"ltp":1.49,"tv":201.18,"id":891555}]}]}
{"op":"mcm","clk":"11939611662","pt":1724400672154,"mc":[{"id":"1.232160907","rc":[{"batb":[[0,1.49,5.05],[1,1.08,1.77],[2,1.04,1618.04]],"ltp":1.49,"tv":201.18,"id":891555}]}]}
{"op":"mcm","clk":"11939611938","pt":1724400676162,"mc":[{"id":"1.232160907","rc":[{"batb":[[0,1.5,5],[1,1.49,5.05],[2,1.08,1.77]],"ltp":1.49,"tv":201.18,"id":891555}]}]}
{"op":"mcm","clk":"11939612144","pt":1724400679463,"mc":[{"id":"1.232160907","rc":[{"batb":[[0,1.49,5.05],[1,1.08,1.77],[2,1.04,1618.04]],"ltp":1.49,"tv":201.18,"id":891555}]}]}
{"op":"mcm","clk":"11939612385","pt":1724400682466,"mc":[{"id":"1.232160907","rc":[{"batb":[[0,1.5,5],[1,1.49,5.05],[2,1.08,1.77]],"ltp":1.49,"tv":201.18,"id":891555}]}]}
{"op":"mcm","clk":"11939612629","pt":1724400685783,"mc":[{"id":"1.232160907","rc":[{"batb":[[0,1.49,5.05],[1,1.08,1.77],[2,1.04,1618.04]],"ltp":1.49,"tv":201.18,"id":891555}]}]}
{"op":"mcm","clk":"11939612966","pt":1724400690411,"mc":[{"id":"1.232160907","rc":[{"batb":[[0,1.5,5],[1,1.49,5.05],[2,1.08,1.77]],"ltp":1.49,"tv":201.18,"id":891555}]}]}
{"op":"mcm","clk":"11939613234","pt":1724400693807,"mc":[{"id":"1.232160907","rc":[{"batb":[[0,1.49,5.05],[1,1.08,1.77],[2,1.04,1618.04]],"ltp":1.49,"tv":201.18,"id":891555}]}]}
{"op":"mcm","clk":"11939613408","pt":1724400696063,"mc":[{"id":"1.232160907","rc":[{"batb":[[0,1.5,5],[1,1.49,5.05],[2,1.08,1.77]],"ltp":1.49,"tv":201.18,"id":891555}]}]}
{"op":"mcm","clk":"11939613627","pt":1724400699399,"mc":[{"id":"1.232160907","rc":[{"batb":[[0,1.49,5.05],[1,1.08,1.77],[2,1.04,1618.04]],"ltp":1.49,"tv":201.18,"id":891555}]}]}
{"op":"mcm","clk":"11939613816","pt":1724400701978,"mc":[{"id":"1.232160907","rc":[{"batb":[[0,1.5,5],[1,1.49,5.05],[2,1.08,1.77]],"ltp":1.49,"tv":201.18,"id":891555}]}]}
{"op":"mcm","clk":"11939614010","pt":1724400705212,"mc":[{"id":"1.232160907","rc":[{"batb":[[0,1.49,5.05],[1,1.08,1.77],[2,1.04,1618.04]],"ltp":1.49,"tv":201.18,"id":891555}]}]}
{"op":"mcm","clk":"11939614172","pt":1724400708005,"mc":[{"id":"1.232160907","rc":[{"batb":[[0,1.5,5],[1,1.49,5.05],[2,1.08,1.77]],"ltp":1.49,"tv":201.18,"id":891555}]}]}
{"op":"mcm","clk":"11939614364","pt":1724400711392,"mc":[{"id":"1.232160907","rc":[{"batb":[[0,1.49,5.05],[1,1.08,1.77],[2,1.04,1618.04]],"ltp":1.49,"tv":201.18,"id":891555}]}]}
{"op":"mcm","clk":"11939614595","pt":1724400714593,"mc":[{"id":"1.232160907","rc":[{"batb":[[0,1.5,5],[1,1.49,5.05],[2,1.08,1.77]],"ltp":1.49,"tv":201.18,"id":891555}]}]}
{"op":"mcm","clk":"11939614810","pt":1724400718005,"mc":[{"id":"1.232160907","rc":[{"batb":[[0,1.49,5.05],[1,1.08,1.77],[2,1.04,1618.04]],"ltp":1.49,"tv":201.18,"id":891555}]}]}
{"op":"mcm","clk":"11939614957","pt":1724400720313,"mc":[{"id":"1.232160907","rc":[{"batb":[[0,1.5,5],[1,1.49,5.05],[2,1.08,1.77]],"ltp":1.49,"tv":201.18,"id":891555}]}]}
{"op":"mcm","clk":"11939615130","pt":1724400723714,"mc":[{"id":"1.232160907","rc":[{"batb":[[0,1.49,5.05],[1,1.08,1.77],[2,1.04,1618.04]],"ltp":1.49,"tv":201.18,"id":891555}]}]}
{"op":"mcm","clk":"11939615294","pt":1724400726542,"mc":[{"id":"1.232160907","rc":[{"batb":[[0,1.5,5],[1,1.49,5.05],[2,1.08,1.77]],"ltp":1.49,"tv":201.18,"id":891555}]}]}
{"op":"mcm","clk":"11939615475","pt":1724400729719,"mc":[{"id":"1.232160907","rc":[{"batb":[[0,1.49,5.05],[1,1.08,1.77],[2,1.04,1618.04]],"ltp":1.49,"tv":201.18,"id":891555}]}]}
{"op":"mcm","clk":"11939615638","pt":1724400732549,"mc":[{"id":"1.232160907","rc":[{"batb":[[0,1.5,5],[1,1.49,5.05],[2,1.08,1.77]],"ltp":1.49,"tv":201.18,"id":891555}]}]}
{"op":"mcm","clk":"11939615813","pt":1724400735830,"mc":[{"id":"1.232160907","rc":[{"batb":[[0,1.49,5.05],[1,1.08,1.77],[2,1.04,1618.04]],"ltp":1.49,"tv":201.18,"id":891555}]}]}
{"op":"mcm","clk":"11939615975","pt":1724400738438,"mc":[{"id":"1.232160907","rc":[{"batb":[[0,1.5,5],[1,1.49,5.05],[2,1.08,1.77]],"ltp":1.49,"tv":201.18,"id":891555}]}]}
{"op":"mcm","clk":"11939616120","pt":1724400741620,"mc":[{"id":"1.232160907","rc":[{"batb":[[0,1.49,5.05],[1,1.08,1.77],[2,1.04,1618.04]],"ltp":1.49,"tv":201.18,"id":891555}]}]}
{"op":"mcm","clk":"11939616386","pt":1724400746031,"mc":[{"id":"1.232160907","rc":[{"batb":[[0,1.5,5],[1,1.49,5.05],[2,1.08,1.77]],"ltp":1.49,"tv":201.18,"id":891555}]}]}
{"op":"mcm","clk":"11939616621","pt":1724400749562,"mc":[{"id":"1.232160907","rc":[{"batb":[[0,1.49,5.05],[1,1.08,1.77],[2,1.04,1618.04]],"ltp":1.49,"tv":201.18,"id":891555}]}]}
{"op":"mcm","clk":"11939616791","pt":1724400752631,"mc":[{"id":"1.232160907","rc":[{"batb":[[0,1.5,5],[1,1.49,5.05],[2,1.08,1.77]],"ltp":1.49,"tv":201.18,"id":891555}]}]}
{"op":"mcm","clk":"11939616950","pt":1724400755873,"mc":[{"id":"1.232160907","rc":[{"batb":[[0,1.49,5.05],[1,1.08,1.77],[2,1.04,1618.04]],"ltp":1.49,"tv":201.18,"id":891555}]}]}
{"op":"mcm","clk":"11939617119","pt":1724400758254,"mc":[{"id":"1.232160907","rc":[{"batb":[[0,1.5,5],[1,1.49,5.05],[2,1.08,1.77]],"ltp":1.49,"tv":201.18,"id":891555}]}]}
{"op":"mcm","clk":"11939617282","pt":1724400761583,"mc":[{"id":"1.232160907","rc":[{"batb":[[0,1.49,5.05],[1,1.08,1.77],[2,1.04,1618.04]],"ltp":1.49,"tv":201.18,"id":891555}]}]}
{"op":"mcm","clk":"11939617459","pt":1724400764055,"mc":[{"id":"1.232160907","rc":[{"batb":[[0,1.5,5],[1,1.49,5.05],[2,1.08,1.77]],"ltp":1.49,"tv":201.18,"id":891555}]}]}
{"op":"mcm","clk":"11939617662","pt":1724400767283,"mc":[{"id":"1.232160907","rc":[{"batb":[[0,1.49,5.05],[1,1.08,1.77],[2,1.04,1618.04]],"ltp":1.49,"tv":201.18,"id":891555}]}]}
{"op":"mcm","clk":"11939617812","pt":1724400769592,"mc":[{"id":"1.232160907","rc":[{"batb":[[0,1.5,5],[1,1.49,5.05],[2,1.08,1.77]],"ltp":1.49,"tv":201.18,"id":891555}]}]}
{"op":"mcm","clk":"11939617975","pt":1724400772765,"mc":[{"id":"1.232160907","rc":[{"batb":[[0,1.49,5.05],[1,1.08,1.77],[2,1.04,1618.04]],"ltp":1.49,"tv":201.18,"id":891555}]}]}
{"op":"mcm","clk":"11939634560","pt":1724400775379,"mc":[{"id":"1.232160907","rc":[{"batb":[[0,1.5,5],[1,1.49,5.05],[2,1.08,1.77]],"ltp":1.49,"tv":201.18,"id":891555}]}]}
{"op":"mcm","clk":"11939634769","pt":1724400778566,"mc":[{"id":"1.232160907","rc":[{"batb":[[0,1.49,5.05],[1,1.08,1.77],[2,1.04,1618.04]],"ltp":1.49,"tv":201.18,"id":891555}]}]}
{"op":"mcm","clk":"11939635017","pt":1724400781999,"mc":[{"id":"1.232160907","rc":[{"batb":[[0,1.5,5],[1,1.49,5.05],[2,1.08,1.77]],"ltp":1.49,"tv":201.18,"id":891555}]}]}
{"op":"mcm","clk":"11939635291","pt":1724400785405,"mc":[{"id":"1.232160907","rc":[{"batb":[[0,1.49,5.05],[1,1.08,1.77],[2,1.04,1618.04]],"ltp":1.49,"tv":201.18,"id":891555}]}]}
{"op":"mcm","clk":"11939635575","pt":1724400788594,"mc":[{"id":"1.232160907","rc":[{"batb":[[0,1.5,5],[1,1.49,5.05],[2,1.08,1.77]],"ltp":1.49,"tv":201.18,"id":891555}]}]}
{"op":"mcm","clk":"11939635799","pt":1724400791821,"mc":[{"id":"1.232160907","rc":[{"batb":[[0,1.49,5.05],[1,1.08,1.77],[2,1.04,1618.04]],"ltp":1.49,"tv":201.18,"id":891555}]}]}
{"op":"mcm","clk":"11939636009","pt":1724400794387,"mc":[{"id":"1.232160907","rc":[{"batb":[[0,1.5,5],[1,1.49,5.05],[2,1.08,1.77]],"ltp":1.49,"tv":201.18,"id":891555}]}]}
{"op":"mcm","clk":"11939636226","pt":1724400797831,"mc":[{"id":"1.232160907","rc":[{"batb":[[0,1.49,5.05],[1,1.08,1.77],[2,1.04,1618.04]],"ltp":1.49,"tv":201.18,"id":891555}]}]}
{"op":"mcm","clk":"11939636494","pt":1724400801392,"mc":[{"id":"1.232160907","rc":[{"batb":[[0,1.5,5],[1,1.49,5.05],[2,1.08,1.77]],"ltp":1.49,"tv":201.18,"id":891555}]}]}
{"op":"mcm","clk":"11939636741","pt":1724400804698,"mc":[{"id":"1.232160907","rc":[{"batb":[[0,1.49,5.05],[1,1.08,1.77],[2,1.04,1618.04]],"ltp":1.49,"tv":201.18,"id":891555}]}]}
{"op":"mcm","clk":"11939636960","pt":1724400808289,"mc":[{"id":"1.232160907","rc":[{"batb":[[0,1.5,5],[1,1.49,5.05],[2,1.08,1.77]],"ltp":1.49,"tv":201.18,"id":891555}]}]}
{"op":"mcm","clk":"11939637143","pt":1724400811530,"mc":[{"id":"1.232160907","rc":[{"batb":[[0,1.49,5.05],[1,1.08,1.77],[2,1.04,1618.04]],"ltp":1.49,"tv":201.18,"id":891555}]}]}
{"op":"mcm","clk":"11939637303","pt":1724400813898,"mc":[{"id":"1.232160907","rc":[{"batb":[[0,1.5,5],[1,1.49,5.05],[2,1.08,1.77]],"ltp":1.49,"tv":201.18,"id":891555}]}]}
{"op":"mcm","clk":"11939637479","pt":1724400817227,"mc":[{"id":"1.232160907","rc":[{"batb":[[0,1.49,5.05],[1,1.08,1.77],[2,1.04,1618.04]],"ltp":1.49,"tv":201.18,"id":891555}]}]}
{"op":"mcm","clk":"11939637712","pt":1724400819913,"mc":[{"id":"1.232160907","rc":[{"batb":[[0,1.5,5],[1,1.49,5.05],[2,1.08,1.77]],"ltp":1.49,"tv":201.18,"id":891555}]}]}
{"op":"mcm","clk":"11939637922","pt":1724400823406,"mc":[{"id":"1.232160907","rc":[{"batb":[[0,1.49,5.05],[1,1.08,1.77],[2,1.04,1618.04]],"ltp":1.49,"tv":201.18,"id":891555}]}]}
{"op":"mcm","clk":"11939638063","pt":1724400826214,"mc":[{"id":"1.232160907","rc":[{"batb":[[0,1.5,5],[1,1.49,5.05],[2,1.08,1.77]],"ltp":1.49,"tv":201.18,"id":891555}]}]}
{"op":"mcm","clk":"11939638256","pt":1724400829559,"mc":[{"id":"1.232160907","rc":[{"batb":[[0,1.49,5.05],[1,1.08,1.77],[2,1.04,1618.04]],"ltp":1.49,"tv":201.18,"id":891555}]}]}
{"op":"mcm","clk":"11939638392","pt":1724400832015,"mc":[{"id":"1.232160907","rc":[{"batb":[[0,1.5,5],[1,1.49,5.05],[2,1.08,1.77]],"ltp":1.49,"tv":201.18,"id":891555}]}]}
{"op":"mcm","clk":"11939638619","pt":1724400835345,"mc":[{"id":"1.232160907","rc":[{"batb":[[0,1.49,5.05],[1,1.08,1.77],[2,1.04,1618.04]],"ltp":1.49,"tv":201.18,"id":891555}]}]}
{"op":"mcm","clk":"11939638788","pt":1724400838164,"mc":[{"id":"1.232160907","rc":[{"batb":[[0,1.5,5],[1,1.49,5.05],[2,1.08,1.77]],"ltp":1.49,"tv":201.18,"id":891555}]}]}
{"op":"mcm","clk":"11939639029","pt":1724400841562,"mc":[{"id":"1.232160907","rc":[{"batb":[[0,1.49,5.05],[1,1.08,1.77],[2,1.04,1618.04]],"ltp":1.49,"tv":201.18,"id":891555}]}]}
{"op":"mcm","clk":"11939639382","pt":1724400846344,"mc":[{"id":"1.232160907","rc":[{"batb":[[0,1.5,5],[1,1.49,5.05],[2,1.08,1.77]],"ltp":1.49,"tv":201.18,"id":891555}]}]}
{"op":"mcm","clk":"11939639597","pt":1724400849643,"mc":[{"id":"1.232160907","rc":[{"batb":[[0,1.49,5.05],[1,1.08,1.77],[2,1.04,1618.04]],"ltp":1.49,"tv":201.18,"id":891555}]}]}
{"op":"mcm","clk":"11939639885","pt":1724400854365,"mc":[{"id":"1.232160907","rc":[{"batb":[[0,1.5,5],[1,1.49,5.05],[2,1.08,1.77]],"ltp":1.49,"tv":201.18,"id":891555}]}]}
{"op":"mcm","clk":"11939640078","pt":1724400857670,"mc":[{"id":"1.232160907","rc":[{"batb":[[0,1.49,5.05],[1,1.08,1.77],[2,1.04,1618.04]],"ltp":1.49,"tv":201.18,"id":891555}]}]}
{"op":"mcm","clk":"11939640284","pt":1724400861066,"mc":[{"id":"1.232160907","rc":[{"batb":[[0,1.5,5],[1,1.49,5.05],[2,1.08,1.77]],"ltp":1.49,"tv":201.18,"id":891555}]}]}
{"op":"mcm","clk":"11939640447","pt":1724400864359,"mc":[{"id":"1.232160907","rc":[{"batb":[[0,1.49,5.05],[1,1.08,1.77],[2,1.04,1618.04]],"ltp":1.49,"tv":201.18,"id":891555}]}]}
{"op":"mcm","clk":"11939640822","pt":1724400870382,"mc":[{"id":"1.232160907","rc":[{"batb":[[0,1.5,5],[1,1.49,5.05],[2,1.08,1.77]],"ltp":1.49,"tv":201.18,"id":891555}]}]}
{"op":"mcm","clk":"11939641023","pt":1724400873881,"mc":[{"id":"1.232160907","rc":[{"batb":[[0,1.49,5.05],[1,1.08,1.77],[2,1.04,1618.04]],"ltp":1.49,"tv":201.18,"id":891555}]}]}
{"op":"mcm","clk":"11939641146","pt":1724400876199,"mc":[{"id":"1.232160907","rc":[{"batb":[[0,1.5,5],[1,1.49,5.05],[2,1.08,1.77]],"ltp":1.49,"tv":201.18,"id":891555}]}]}
{"op":"mcm","clk":"11939641374","pt":1724400879403,"mc":[{"id":"1.232160907","rc":[{"batb":[[0,1.49,5.05],[1,1.08,1.77],[2,1.04,1618.04]],"ltp":1.49,"tv":201.18,"id":891555}]}]}
{"op":"mcm","clk":"11939641565","pt":1724400882284,"mc":[{"id":"1.232160907","rc":[{"batb":[[0,1.5,5],[1,1.49,5.05],[2,1.08,1.77]],"ltp":1.49,"tv":201.18,"id":891555}]}]}
{"op":"mcm","clk":"11939641802","pt":1724400885583,"mc":[{"id":"1.232160907","rc":[{"batb":[[0,1.49,5.05],[1,1.08,1.77],[2,1.04,1618.04]],"ltp":1.49,"tv":201.18,"id":891555}]}]}
{"op":"mcm","clk":"11939641950","pt":1724400887797,"mc":[{"id":"1.232160907","rc":[{"batb":[[0,1.5,5],[1,1.49,5.05],[2,1.08,1.77]],"ltp":1.49,"tv":201.18,"id":891555}]}]}
{"op":"mcm","clk":"11939642172","pt":1724400891292,"mc":[{"id":"1.232160907","rc":[{"batb":[[0,1.49,5.05],[1,1.08,1.77],[2,1.04,1618.04]],"ltp":1.49,"tv":201.18,"id":891555}]}]}
{"op":"mcm","clk":"11939642362","pt":1724400893705,"mc":[{"id":"1.232160907","rc":[{"batb":[[0,1.5,5],[1,1.49,5.05],[2,1.08,1.77]],"ltp":1.49,"tv":201.18,"id":891555}]}]}
{"op":"mcm","clk":"11939642597","pt":1724400897105,"mc":[{"id":"1.232160907","rc":[{"batb":[[0,1.49,5.05],[1,1.08,1.77],[2,1.04,1618.04]],"ltp":1.49,"tv":201.18,"id":891555}]}]}
{"op":"mcm","clk":"11939642766","pt":1724400899593,"mc":[{"id":"1.232160907","rc":[{"batb":[[0,1.5,5],[1,1.49,5.05],[2,1.08,1.77]],"ltp":1.49,"tv":201.18,"id":891555}]}]}
{"op":"mcm","clk":"11939643009","pt":1724400902808,"mc":[{"id":"1.232160907","rc":[{"batb":[[0,1.49,5.05],[1,1.08,1.77],[2,1.04,1618.04]],"ltp":1.49,"tv":201.18,"id":891555}]}]}
{"op":"mcm","clk":"11939643191","pt":1724400905125,"mc":[{"id":"1.232160907","rc":[{"batb":[[0,1.5,5],[1,1.49,5.05],[2,1.08,1.77]],"ltp":1.49,"tv":201.18,"id":891555}]}]}
{"op":"mcm","clk":"11939643433","pt":1724400908318,"mc":[{"id":"1.232160907","rc":[{"batb":[[0,1.49,5.05],[1,1.08,1.77],[2,1.04,1618.04]],"ltp":1.49,"tv":201.18,"id":891555}]}]}
{"op":"mcm","clk":"11939643610","pt":1724400910736,"mc":[{"id":"1.232160907","rc":[{"batb":[[0,1.5,5],[1,1.49,5.05],[2,1.08,1.77]],"ltp":1.49,"tv":201.18,"id":891555}]}]}
{"op":"mcm","clk":"11939643868","pt":1724400913899,"mc":[{"id":"1.232160907","rc":[{"batb":[[0,1.49,5.05],[1,1.08,1.77],[2,1.04,1618.04]],"ltp":1.49,"tv":201.18,"id":891555}]}]}
{"op":"mcm","clk":"11939644037","pt":1724400916625,"mc":[{"id":"1.232160907","rc":[{"batb":[[0,1.5,5],[1,1.49,5.05],[2,1.08,1.77]],"ltp":1.49,"tv":201.18,"id":891555}]}]}
{"op":"mcm","clk":"11939644233","pt":1724400919917,"mc":[{"id":"1.232160907","rc":[{"batb":[[0,1.49,5.05],[1,1.08,1.77],[2,1.04,1618.04]],"ltp":1.49,"tv":201.18,"id":891555}]}]}
{"op":"mcm","clk":"11939644432","pt":1724400923044,"mc":[{"id":"1.232160907","rc":[{"batb":[[0,1.5,5],[1,1.49,5.05],[2,1.08,1.77]],"ltp":1.49,"tv":201.18,"id":891555}]}]}
{"op":"mcm","clk":"11939644628","pt":1724400926253,"mc":[{"id":"1.232160907","rc":[{"batb":[[0,1.49,5.05],[1,1.08,1.77],[2,1.04,1618.04]],"ltp":1.49,"tv":201.18,"id":891555}]}]}
{"op":"mcm","clk":"11939644800","pt":1724400929343,"mc":[{"id":"1.232160907","rc":[{"batb":[[0,1.5,5],[1,1.49,5.05],[2,1.08,1.77]],"ltp":1.49,"tv":201.18,"id":891555}]}]}
{"op":"mcm","clk":"11939645023","pt":1724400932928,"mc":[{"id":"1.232160907","rc":[{"batb":[[0,1.49,5.05],[1,1.08,1.77],[2,1.04,1618.04]],"ltp":1.49,"tv":201.18,"id":891555}]}]}
{"op":"mcm","clk":"11939645202","pt":1724400935644,"mc":[{"id":"1.232160907","rc":[{"batb":[[0,1.5,5],[1,1.49,5.05],[2,1.08,1.77]],"ltp":1.49,"tv":201.18,"id":891555}]}]}
{"op":"mcm","clk":"11939645393","pt":1724400938832,"mc":[{"id":"1.232160907","rc":[{"batb":[[0,1.49,5.05],[1,1.08,1.77],[2,1.04,1618.04]],"ltp":1.49,"tv":201.18,"id":891555}]}]}
{"op":"mcm","clk":"11939645822","pt":1724400941793,"mc":[{"id":"1.232160907","rc":[{"batb":[[0,1.5,5],[1,1.49,5.05],[2,1.08,1.77]],"ltp":1.49,"tv":201.18,"id":891555}]}]}
{"op":"mcm","clk":"11939646085","pt":1724400945160,"mc":[{"id":"1.232160907","rc":[{"batb":[[0,1.49,5.05],[1,1.08,1.77],[2,1.04,1618.04]],"ltp":1.49,"tv":201.18,"id":891555}]}]}
{"op":"mcm","clk":"11939646187","pt":1724400947538,"mc":[{"id":"1.232160907","rc":[{"batb":[[0,1.5,5],[1,1.49,5.05],[2,1.08,1.77]],"ltp":1.49,"tv":201.18,"id":891555}]}]}
{"op":"mcm","clk":"11939646405","pt":1724400950975,"mc":[{"id":"1.232160907","rc":[{"batb":[[0,1.49,5.05],[1,1.08,1.77],[2,1.04,1618.04]],"ltp":1.49,"tv":201.18,"id":891555}]}]}
{"op":"mcm","clk":"11939646715","pt":1724400954277,"mc":[{"id":"1.232160907","rc":[{"batb":[[0,1.5,5],[1,1.49,5.05],[2,1.08,1.77]],"ltp":1.49,"tv":201.18,"id":891555}]}]}
{"op":"mcm","clk":"11939646933","pt":1724400957464,"mc":[{"id":"1.232160907","rc":[{"batb":[[0,1.49,5.05],[1,1.08,1.77],[2,1.04,1618.04]],"ltp":1.49,"tv":201.18,"id":891555}]}]}
{"op":"mcm","clk":"11939647079","pt":1724400960071,"mc":[{"id":"1.232160907","rc":[{"batb":[[0,1.5,5],[1,1.49,5.05],[2,1.08,1.77]],"ltp":1.49,"tv":201.18,"id":891555}]}]}
{"op":"mcm","clk":"11939647387","pt":1724400963373,"mc":[{"id":"1.232160907","rc":[{"batb":[[0,1.49,5.05],[1,1.08,1.77],[2,1.04,1618.04]],"ltp":1.49,"tv":201.18,"id":891555}]}]}
{"op":"mcm","clk":"11939647686","pt":1724400967869,"mc":[{"id":"1.232160907","rc":[{"batb":[[0,1.5,5],[1,1.49,5.05],[2,1.08,1.77]],"ltp":1.49,"tv":201.18,"id":891555}]}]}
{"op":"mcm","clk":"11939647937","pt":1724400971360,"mc":[{"id":"1.232160907","rc":[{"batb":[[0,1.49,5.05],[1,1.08,1.77],[2,1.04,1618.04]],"ltp":1.49,"tv":201.18,"id":891555}]}]}
{"op":"mcm","clk":"11939648108","pt":1724400973777,"mc":[{"id":"1.232160907","rc":[{"batb":[[0,1.5,5],[1,1.49,5.05],[2,1.08,1.77]],"ltp":1.49,"tv":201.18,"id":891555}]}]}
{"op":"mcm","clk":"11939648314","pt":1724400977254,"mc":[{"id":"1.232160907","rc":[{"batb":[[0,1.49,5.05],[1,1.08,1.77],[2,1.04,1618.04]],"ltp":1.49,"tv":201.18,"id":891555}]}]}
{"op":"mcm","clk":"11939648568","pt":1724400980486,"mc":[{"id":"1.232160907","rc":[{"batb":[[0,1.5,5],[1,1.49,5.05],[2,1.08,1.77]],"ltp":1.49,"tv":201.18,"id":891555}]}]}
{"op":"mcm","clk":"11939648736","pt":1724400983807,"mc":[{"id":"1.232160907","rc":[{"batb":[[0,1.49,5.05],[1,1.08,1.77],[2,1.04,1618.04]],"ltp":1.49,"tv":201.18,"id":891555}]}]}
{"op":"mcm","clk":"11939648990","pt":1724400987816,"mc":[{"id":"1.232160907","rc":[{"batb":[[0,1.5,5],[1,1.49,5.05],[2,1.08,1.77]],"ltp":1.49,"tv":201.18,"id":891555}]}]}
{"op":"mcm","clk":"11939649230","pt":1724400991515,"mc":[{"id":"1.232160907","rc":[{"batb":[[0,1.49,5.05],[1,1.08,1.77],[2,1.04,1618.04]],"ltp":1.49,"tv":201.18,"id":891555}]}]}
{"op":"mcm","clk":"11939649621","pt":1724400995397,"mc":[{"id":"1.232160907","rc":[{"batb":[[0,1.5,5],[1,1.49,5.05],[2,1.08,1.77]],"ltp":1.49,"tv":201.18,"id":891555}]}]}
{"op":"mcm","clk":"11939649868","pt":1724400998806,"mc":[{"id":"1.232160907","rc":[{"batb":[[0,1.49,5.05],[1,1.08,1.77],[2,1.04,1618.04]],"ltp":1.49,"tv":201.18,"id":891555}]}]}
{"op":"mcm","clk":"11939650061","pt":1724401001485,"mc":[{"id":"1.232160907","rc":[{"batb":[[0,1.5,5],[1,1.49,5.05],[2,1.08,1.77]],"ltp":1.49,"tv":201.18,"id":891555}]}]}
{"op":"mcm","clk":"11939650339","pt":1724401004827,"mc":[{"id":"1.232160907","rc":[{"batb":[[0,1.49,5.05],[1,1.08,1.77],[2,1.04,1618.04]],"ltp":1.49,"tv":201.18,"id":891555}]}]}
{"op":"mcm","clk":"11939650538","pt":1724401008121,"mc":[{"id":"1.232160907","rc":[{"batb":[[0,1.5,5],[1,1.49,5.05],[2,1.08,1.77]],"ltp":1.49,"tv":201.18,"id":891555}]}]}
{"op":"mcm","clk":"11939650874","pt":1724401011513,"mc":[{"id":"1.232160907","rc":[{"batb":[[0,1.49,5.05],[1,1.08,1.77],[2,1.04,1618.04]],"ltp":1.49,"tv":201.18,"id":891555}]}]}
{"op":"mcm","clk":"11939651098","pt":1724401014033,"mc":[{"id":"1.232160907","rc":[{"batb":[[0,1.5,5],[1,1.49,5.05],[2,1.08,1.77]],"ltp":1.49,"tv":201.18,"id":891555}]}]}
{"op":"mcm","clk":"11939651286","pt":1724401017318,"mc":[{"id":"1.232160907","rc":[{"batb":[[0,1.49,5.05],[1,1.08,1.77],[2,1.04,1618.04]],"ltp":1.49,"tv":201.18,"id":891555}]}]}
{"op":"mcm","clk":"11939651484","pt":1724401020614,"mc":[{"id":"1.232160907","rc":[{"batb":[[0,1.5,5],[1,1.49,5.05],[2,1.08,1.77]],"ltp":1.49,"tv":201.18,"id":891555}]}]}
{"op":"mcm","clk":"11939651777","pt":1724401024021,"mc":[{"id":"1.232160907","rc":[{"batb":[[0,1.49,5.05],[1,1.08,1.77],[2,1.04,1618.04]],"ltp":1.49,"tv":201.18,"id":891555}]}]}
{"op":"mcm","clk":"11939651973","pt":1724401027816,"mc":[{"id":"1.232160907","rc":[{"batb":[[0,1.5,5],[1,1.49,5.05],[2,1.08,1.77]],"ltp":1.49,"tv":201.18,"id":891555}]}]}
{"op":"mcm","clk":"11939652206","pt":1724401031042,"mc":[{"id":"1.232160907","rc":[{"batb":[[0,1.49,5.05],[1,1.08,1.77],[2,1.04,1618.04]],"ltp":1.49,"tv":201.18,"id":891555}]}]}
{"op":"mcm","clk":"11939652535","pt":1724401035050,"mc":[{"id":"1.232160907","rc":[{"batb":[[0,1.5,5],[1,1.49,5.05],[2,1.08,1.77]],"ltp":1.49,"tv":201.18,"id":891555}]}]}
{"op":"mcm","clk":"11939652754","pt":1724401038550,"mc":[{"id":"1.232160907","rc":[{"batb":[[0,1.49,5.05],[1,1.08,1.77],[2,1.04,1618.04]],"ltp":1.49,"tv":201.18,"id":891555}]}]}
{"op":"mcm","clk":"11939652908","pt":1724401041228,"mc":[{"id":"1.232160907","rc":[{"batb":[[0,1.5,5],[1,1.49,5.05],[2,1.08,1.77]],"ltp":1.49,"tv":201.18,"id":891555}]}]}
{"op":"mcm","clk":"11939653134","pt":1724401044631,"mc":[{"id":"1.232160907","rc":[{"batb":[[0,1.49,5.05],[1,1.08,1.77],[2,1.04,1618.04]],"ltp":1.49,"tv":201.18,"id":891555}]}]}
{"op":"mcm","clk":"11939653484","pt":1724401047780,"mc":[{"id":"1.232160907","rc":[{"batb":[[0,1.5,5],[1,1.49,5.05],[2,1.08,1.77]],"ltp":1.49,"tv":201.18,"id":891555}]}]}
{"op":"mcm","clk":"11939653703","pt":1724401050966,"mc":[{"id":"1.232160907","rc":[{"batb":[[0,1.49,5.05],[1,1.08,1.77],[2,1.04,1618.04]],"ltp":1.49,"tv":201.18,"id":891555}]}]}
{"op":"mcm","clk":"11939653909","pt":1724401054549,"mc":[{"id":"1.232160907","rc":[{"batb":[[0,1.5,5],[1,1.49,5.05],[2,1.08,1.77]],"ltp":1.49,"tv":201.18,"id":891555}]}]}
{"op":"mcm","clk":"11939654113","pt":1724401057865,"mc":[{"id":"1.232160907","rc":[{"batb":[[0,1.49,5.05],[1,1.08,1.77],[2,1.04,1618.04]],"ltp":1.49,"tv":201.18,"id":891555}]}]}
{"op":"mcm","clk":"11939654265","pt":1724401060175,"mc":[{"id":"1.232160907","rc":[{"batb":[[0,1.5,5],[1,1.49,5.05],[2,1.08,1.77]],"ltp":1.49,"tv":201.18,"id":891555}]}]}
{"op":"mcm","clk":"11939654509","pt":1724401063578,"mc":[{"id":"1.232160907","rc":[{"batb":[[0,1.49,5.05],[1,1.08,1.77],[2,1.04,1618.04]],"ltp":1.49,"tv":201.18,"id":891555}]}]}
{"op":"mcm","clk":"11939654745","pt":1724401066764,"mc":[{"id":"1.232160907","rc":[{"batb":[[0,1.5,5],[1,1.49,5.05],[2,1.08,1.77]],"ltp":1.49,"tv":201.18,"id":891555}]}]}
{"op":"mcm","clk":"11939654953","pt":1724401070055,"mc":[{"id":"1.232160907","rc":[{"batb":[[0,1.49,5.05],[1,1.08,1.77],[2,1.04,1618.04]],"ltp":1.49,"tv":201.18,"id":891555}]}]}
{"op":"mcm","clk":"11939655121","pt":1724401072983,"mc":[{"id":"1.232160907","rc":[{"batb":[[0,1.5,5],[1,1.49,5.05],[2,1.08,1.77]],"ltp":1.49,"tv":201.18,"id":891555}]}]}
{"op":"mcm","clk":"11939655458","pt":1724401076294,"mc":[{"id":"1.232160907","rc":[{"batb":[[0,1.49,5.05],[1,1.08,1.77],[2,1.04,1618.04]],"ltp":1.49,"tv":201.18,"id":891555}]}]}
{"op":"mcm","clk":"11939655707","pt":1724401080994,"mc":[{"id":"1.232160907","rc":[{"batb":[[0,1.5,5],[1,1.49,5.05],[2,1.08,1.77]],"ltp":1.49,"tv":201.18,"id":891555}]}]}
{"op":"mcm","clk":"11939655925","pt":1724401084195,"mc":[{"id":"1.232160907","rc":[{"batb":[[0,1.49,5.05],[1,1.08,1.77],[2,1.04,1618.04]],"ltp":1.49,"tv":201.18,"id":891555}]}]}
{"op":"mcm","clk":"11939656085","pt":1724401086906,"mc":[{"id":"1.232160907","rc":[{"batb":[[0,1.5,5],[1,1.49,5.05],[2,1.08,1.77]],"ltp":1.49,"tv":201.18,"id":891555}]}]}
{"op":"mcm","clk":"11939656315","pt":1724401090502,"mc":[{"id":"1.232160907","rc":[{"batb":[[0,1.49,5.05],[1,1.08,1.77],[2,1.04,1618.04]],"ltp":1.49,"tv":201.18,"id":891555}]}]}
{"op":"mcm","clk":"11939656521","pt":1724401092922,"mc":[{"id":"1.232160907","rc":[{"batb":[[0,1.5,5],[1,1.49,5.05],[2,1.08,1.77]],"ltp":1.49,"tv":201.18,"id":891555}]}]}
{"op":"mcm","clk":"11939656825","pt":1724401096221,"mc":[{"id":"1.232160907","rc":[{"batb":[[0,1.49,5.05],[1,1.08,1.77],[2,1.04,1618.04]],"ltp":1.49,"tv":201.18,"id":891555}]}]}
{"op":"mcm","clk":"11939656970","pt":1724401098427,"mc":[{"id":"1.232160907","rc":[{"batb":[[0,1.5,5],[1,1.49,5.05],[2,1.08,1.77]],"ltp":1.49,"tv":201.18,"id":891555}]}]}
{"op":"mcm","clk":"11939657129","pt":1724401101813,"mc":[{"id":"1.232160907","rc":[{"batb":[[0,1.49,5.05],[1,1.08,1.77],[2,1.04,1618.04]],"ltp":1.49,"tv":201.18,"id":891555}]}]}
{"op":"mcm","clk":"11939657303","pt":1724401104640,"mc":[{"id":"1.232160907","rc":[{"batb":[[0,1.5,5],[1,1.49,5.05],[2,1.08,1.77]],"ltp":1.49,"tv":201.18,"id":891555}]}]}
{"op":"mcm","clk":"11939657484","pt":1724401107921,"mc":[{"id":"1.232160907","rc":[{"batb":[[0,1.49,5.05],[1,1.08,1.77],[2,1.04,1618.04]],"ltp":1.49,"tv":201.18,"id":891555}]}]}
{"op":"mcm","clk":"11939657645","pt":1724401110942,"mc":[{"id":"1.232160907","rc":[{"batb":[[0,1.5,5],[1,1.49,5.05],[2,1.08,1.77]],"ltp":1.49,"tv":201.18,"id":891555}]}]}
{"op":"mcm","clk":"11939657876","pt":1724401114238,"mc":[{"id":"1.232160907","rc":[{"batb":[[0,1.49,5.05],[1,1.08,1.77],[2,1.04,1618.04]],"ltp":1.49,"tv":201.18,"id":891555}]}]}
{"op":"mcm","clk":"11939658025","pt":1724401116654,"mc":[{"id":"1.232160907","rc":[{"batb":[[0,1.5,5],[1,1.49,5.05],[2,1.08,1.77]],"ltp":1.49,"tv":201.18,"id":891555}]}]}
{"op":"mcm","clk":"11939658247","pt":1724401120349,"mc":[{"id":"1.232160907","rc":[{"batb":[[0,1.49,5.05],[1,1.08,1.77],[2,1.04,1618.04]],"ltp":1.49,"tv":201.18,"id":891555}]}]}
{"op":"mcm","clk":"11939658463","pt":1724401123331,"mc":[{"id":"1.232160907","rc":[{"batb":[[0,1.5,5],[1,1.49,5.05],[2,1.08,1.77]],"ltp":1.49,"tv":201.18,"id":891555}]}]}
{"op":"mcm","clk":"11939658647","pt":1724401126655,"mc":[{"id":"1.232160907","rc":[{"batb":[[0,1.49,5.05],[1,1.08,1.77],[2,1.04,1618.04]],"ltp":1.49,"tv":201.18,"id":891555}]}]}
{"op":"mcm","clk":"11939658777","pt":1724401128864,"mc":[{"id":"1.232160907","rc":[{"batb":[[0,1.5,5],[1,1.49,5.05],[2,1.08,1.77]],"ltp":1.49,"tv":201.18,"id":891555}]}]}
{"op":"mcm","clk":"11939658992","pt":1724401132162,"mc":[{"id":"1.232160907","rc":[{"batb":[[0,1.49,5.05],[1,1.08,1.77],[2,1.04,1618.04]],"ltp":1.49,"tv":201.18,"id":891555}]}]}
{"op":"mcm","clk":"11939659243","pt":1724401135868,"mc":[{"id":"1.232160907","rc":[{"batb":[[0,1.5,5],[1,1.49,5.05],[2,1.08,1.77]],"ltp":1.49,"tv":201.18,"id":891555}]}]}
{"op":"mcm","clk":"11939659432","pt":1724401139073,"mc":[{"id":"1.232160907","rc":[{"batb":[[0,1.49,5.05],[1,1.08,1.77],[2,1.04,1618.04]],"ltp":1.49,"tv":201.18,"id":891555}]}]}
{"op":"mcm","clk":"11939659658","pt":1724401142438,"mc":[{"id":"1.232160907","rc":[{"batb":[[0,1.5,5],[1,1.49,5.05],[2,1.08,1.77]],"ltp":1.49,"tv":201.18,"id":891555}]}]}
{"op":"mcm","clk":"11939659950","pt":1724401145838,"mc":[{"id":"1.232160907","rc":[{"batb":[[0,1.49,5.05],[1,1.08,1.77],[2,1.04,1618.04]],"ltp":1.49,"tv":201.18,"id":891555}]}]}
{"op":"mcm","clk":"11939660135","pt":1724401148584,"mc":[{"id":"1.232160907","rc":[{"batb":[[0,1.5,5],[1,1.49,5.05],[2,1.08,1.77]],"ltp":1.49,"tv":201.18,"id":891555}]}]}
{"op":"mcm","clk":"11939660386","pt":1724401151878,"mc":[{"id":"1.232160907","rc":[{"batb":[[0,1.49,5.05],[1,1.08,1.77],[2,1.04,1618.04]],"ltp":1.49,"tv":201.18,"id":891555}]}]}
{"op":"mcm","clk":"11939660568","pt":1724401154288,"mc":[{"id":"1.232160907","rc":[{"batb":[[0,1.5,5],[1,1.49,5.05],[2,1.08,1.77]],"ltp":1.49,"tv":201.18,"id":891555}]}]}
{"op":"mcm","clk":"11939660786","pt":1724401157578,"mc":[{"id":"1.232160907","rc":[{"batb":[[0,1.49,5.05],[1,1.08,1.77],[2,1.04,1618.04]],"ltp":1.49,"tv":201.18,"id":891555}]}]}
{"op":"mcm","clk":"11939660925","pt":1724401159993,"mc":[{"id":"1.232160907","rc":[{"batb":[[0,1.5,5],[1,1.49,5.05],[2,1.08,1.77]],"ltp":1.49,"tv":201.18,"id":891555}]}]}
{"op":"mcm","clk":"11939661155","pt":1724401163279,"mc":[{"id":"1.232160907","rc":[{"batb":[[0,1.49,5.05],[1,1.08,1.77],[2,1.04,1618.04]],"ltp":1.49,"tv":201.18,"id":891555}]}]}
{"op":"mcm","clk":"11939661494","pt":1724401168776,"mc":[{"id":"1.232160907","rc":[{"batb":[[0,1.5,5],[1,1.49,5.05],[2,1.08,1.77]],"ltp":1.49,"tv":201.18,"id":891555}]}]}
{"op":"mcm","clk":"11939661705","pt":1724401172071,"mc":[{"id":"1.232160907","rc":[{"batb":[[0,1.49,5.05],[1,1.08,1.77],[2,1.04,1618.04]],"ltp":1.49,"tv":201.18,"id":891555}]}]}
{"op":"mcm","clk":"11939661886","pt":1724401174995,"mc":[{"id":"1.232160907","rc":[{"batb":[[0,1.5,5],[1,1.49,5.05],[2,1.08,1.77]],"ltp":1.49,"tv":201.18,"id":891555}]}]}
{"op":"mcm","clk":"11939662133","pt":1724401178297,"mc":[{"id":"1.232160907","rc":[{"batb":[[0,1.49,5.05],[1,1.08,1.77],[2,1.04,1618.04]],"ltp":1.49,"tv":201.18,"id":891555}]}]}
{"op":"mcm","clk":"11939662287","pt":1724401180605,"mc":[{"id":"1.232160907","rc":[{"batb":[[0,1.5,5],[1,1.49,5.05],[2,1.08,1.77]],"ltp":1.49,"tv":201.18,"id":891555}]}]}
{"op":"mcm","clk":"11939662516","pt":1724401183891,"mc":[{"id":"1.232160907","rc":[{"batb":[[0,1.49,5.05],[1,1.08,1.77],[2,1.04,1618.04]],"ltp":1.49,"tv":201.18,"id":891555}]}]}
{"op":"mcm","clk":"11939662767","pt":1724401188300,"mc":[{"id":"1.232160907","rc":[{"batb":[[0,1.5,5],[1,1.49,5.05],[2,1.08,1.77]],"ltp":1.49,"tv":201.18,"id":891555}]}]}
{"op":"mcm","clk":"11939662956","pt":1724401191400,"mc":[{"id":"1.232160907","rc":[{"batb":[[0,1.49,5.05],[1,1.08,1.77],[2,1.04,1618.04]],"ltp":1.49,"tv":201.18,"id":891555}]}]}
{"op":"mcm","clk":"11939663126","pt":1724401193704,"mc":[{"id":"1.232160907","rc":[{"batb":[[0,1.5,5],[1,1.49,5.05],[2,1.08,1.77]],"ltp":1.49,"tv":201.18,"id":891555}]}]}
{"op":"mcm","clk":"11939663311","pt":1724401197209,"mc":[{"id":"1.232160907","rc":[{"batb":[[0,1.49,5.05],[1,1.08,1.77],[2,1.04,1618.04]],"ltp":1.49,"tv":201.18,"id":891555}]}]}
{"op":"mcm","clk":"11939663468","pt":1724401199927,"mc":[{"id":"1.232160907","rc":[{"batb":[[0,1.5,5],[1,1.49,5.05],[2,1.08,1.77]],"ltp":1.49,"tv":201.18,"id":891555}]}]}
{"op":"mcm","clk":"11939663681","pt":1724401203314,"mc":[{"id":"1.232160907","rc":[{"batb":[[0,1.49,5.05],[1,1.08,1.77],[2,1.04,1618.04]],"ltp":1.49,"tv":201.18,"id":891555}]}]}
{"op":"mcm","clk":"11939663833","pt":1724401206241,"mc":[{"id":"1.232160907","rc":[{"batb":[[0,1.5,5],[1,1.49,5.05],[2,1.08,1.77]],"ltp":1.49,"tv":201.18,"id":891555}]}]}
{"op":"mcm","clk":"11939664034","pt":1724401209417,"mc":[{"id":"1.232160907","rc":[{"batb":[[0,1.49,5.05],[1,1.08,1.77],[2,1.04,1618.04]],"ltp":1.49,"tv":201.18,"id":891555}]}]}
{"op":"mcm","clk":"11939664525","pt":1724401217050,"mc":[{"id":"1.232160907","rc":[{"batb":[[0,1.5,5],[1,1.49,5.05],[2,1.08,1.77]],"ltp":1.49,"tv":201.18,"id":891555}]}]}
{"op":"mcm","clk":"11939664750","pt":1724401220228,"mc":[{"id":"1.232160907","rc":[{"batb":[[0,1.49,5.05],[1,1.08,1.77],[2,1.04,1618.04]],"ltp":1.49,"tv":201.18,"id":891555}]}]}
{"op":"mcm","clk":"11939664927","pt":1724401222850,"mc":[{"id":"1.232160907","rc":[{"batb":[[0,1.5,5],[1,1.49,5.05],[2,1.08,1.77]],"ltp":1.49,"tv":201.18,"id":891555}]}]}
{"op":"mcm","clk":"11939665162","pt":1724401226143,"mc":[{"id":"1.232160907","rc":[{"batb":[[0,1.49,5.05],[1,1.08,1.77],[2,1.04,1618.04]],"ltp":1.49,"tv":201.18,"id":891555}]}]}
{"op":"mcm","clk":"11939665367","pt":1724401229157,"mc":[{"id":"1.232160907","rc":[{"batb":[[0,1.5,5],[1,1.49,5.05],[2,1.08,1.77]],"ltp":1.49,"tv":201.18,"id":891555}]}]}
{"op":"mcm","clk":"11939665554","pt":1724401232553,"mc":[{"id":"1.232160907","rc":[{"batb":[[0,1.49,5.05],[1,1.08,1.77],[2,1.04,1618.04]],"ltp":1.49,"tv":201.18,"id":891555}]}]}
{"op":"mcm","clk":"11939665765","pt":1724401235473,"mc":[{"id":"1.232160907","rc":[{"batb":[[0,1.5,5],[1,1.49,5.05],[2,1.08,1.77]],"ltp":1.49,"tv":201.18,"id":891555}]}]}
{"op":"mcm","clk":"11939666050","pt":1724401238963,"mc":[{"id":"1.232160907","rc":[{"batb":[[0,1.49,5.05],[1,1.08,1.77],[2,1.04,1618.04]],"ltp":1.49,"tv":201.18,"id":891555}]}]}
{"op":"mcm","clk":"11939666214","pt":1724401241276,"mc":[{"id":"1.232160907","rc":[{"batb":[[0,1.5,5],[1,1.49,5.05],[2,1.08,1.77]],"ltp":1.49,"tv":201.18,"id":891555}]}]}
{"op":"mcm","clk":"11939666439","pt":1724401244758,"mc":[{"id":"1.232160907","rc":[{"batb":[[0,1.49,5.05],[1,1.08,1.77],[2,1.04,1618.04]],"ltp":1.49,"tv":201.18,"id":891555}]}]}
{"op":"mcm","clk":"11939666586","pt":1724401247271,"mc":[{"id":"1.232160907","rc":[{"batb":[[0,1.5,5],[1,1.49,5.05],[2,1.08,1.77]],"ltp":1.49,"tv":201.18,"id":891555}]}]}
{"op":"mcm","clk":"11939666793","pt":1724401250774,"mc":[{"id":"1.232160907","rc":[{"batb":[[0,1.49,5.05],[1,1.08,1.77],[2,1.04,1618.04]],"ltp":1.49,"tv":201.18,"id":891555}]}]}
{"op":"mcm","clk":"11939667118","pt":1724401256070,"mc":[{"id":"1.232160907","rc":[{"batb":[[0,1.5,5],[1,1.49,5.05],[2,1.08,1.77]],"ltp":1.49,"tv":201.18,"id":891555}]}]}
{"op":"mcm","clk":"11939667350","pt":1724401259559,"mc":[{"id":"1.232160907","rc":[{"batb":[[0,1.49,5.05],[1,1.08,1.77],[2,1.04,1618.04]],"ltp":1.49,"tv":201.18,"id":891555}]}]}
{"op":"mcm","clk":"11939667874","pt":1724401266062,"mc":[{"id":"1.232160907","rc":[{"batb":[[0,1.5,5],[1,1.49,5.05],[2,1.08,1.77]],"ltp":1.49,"tv":201.18,"id":891555}]}]}
{"op":"mcm","clk":"11939668145","pt":1724401269609,"mc":[{"id":"1.232160907","rc":[{"batb":[[0,1.49,5.05],[1,1.08,1.77],[2,1.04,1618.04]],"ltp":1.49,"tv":201.18,"id":891555}]}]}
{"op":"mcm","clk":"11939668332","pt":1724401272279,"mc":[{"id":"1.232160907","rc":[{"batb":[[0,1.5,5],[1,1.49,5.05],[2,1.08,1.77]],"ltp":1.49,"tv":201.18,"id":891555}]}]}
{"op":"mcm","clk":"11939668569","pt":1724401275565,"mc":[{"id":"1.232160907","rc":[{"batb":[[0,1.49,5.05],[1,1.08,1.77],[2,1.04,1618.04]],"ltp":1.49,"tv":201.18,"id":891555}]}]}
{"op":"mcm","clk":"11939668768","pt":1724401278597,"mc":[{"id":"1.232160907","rc":[{"batb":[[0,1.5,5],[1,1.49,5.05],[2,1.08,1.77]],"ltp":1.49,"tv":201.18,"id":891555}]}]}
{"op":"mcm","clk":"11939668970","pt":1724401281785,"mc":[{"id":"1.232160907","rc":[{"batb":[[0,1.49,5.05],[1,1.08,1.77],[2,1.04,1618.04]],"ltp":1.49,"tv":201.18,"id":891555}]}]}
{"op":"mcm","clk":"11939669235","pt":1724401285502,"mc":[{"id":"1.232160907","rc":[{"batb":[[0,1.5,5],[1,1.49,5.05],[2,1.08,1.77]],"ltp":1.49,"tv":201.18,"id":891555}]}]}
{"op":"mcm","clk":"11939669448","pt":1724401288813,"mc":[{"id":"1.232160907","rc":[{"batb":[[0,1.49,5.05],[1,1.08,1.77],[2,1.04,1618.04]],"ltp":1.49,"tv":201.18,"id":891555}]}]}
{"op":"mcm","clk":"11939669647","pt":1724401291589,"mc":[{"id":"1.232160907","rc":[{"batb":[[0,1.5,5],[1,1.49,5.05],[2,1.08,1.77]],"ltp":1.49,"tv":201.18,"id":891555}]}]}
{"op":"mcm","clk":"11939669844","pt":1724401294828,"mc":[{"id":"1.232160907","rc":[{"batb":[[0,1.49,5.05],[1,1.08,1.77],[2,1.04,1618.04]],"ltp":1.49,"tv":201.18,"id":891555}]}]}
{"op":"mcm","clk":"11939670109","pt":1724401298285,"mc":[{"id":"1.232160907","rc":[{"batb":[[0,1.5,5],[1,1.49,5.05],[2,1.08,1.77]],"ltp":1.49,"tv":201.18,"id":891555}]}]}
{"op":"mcm","clk":"11939670341","pt":1724401301636,"mc":[{"id":"1.232160907","rc":[{"batb":[[0,1.49,5.05],[1,1.08,1.77],[2,1.04,1618.04]],"ltp":1.49,"tv":201.18,"id":891555}]}]}
{"op":"mcm","clk":"11939670519","pt":1724401303905,"mc":[{"id":"1.232160907","rc":[{"batb":[[0,1.5,5],[1,1.49,5.05],[2,1.08,1.77]],"ltp":1.49,"tv":201.18,"id":891555}]}]}
{"op":"mcm","clk":"11939670756","pt":1724401307251,"mc":[{"id":"1.232160907","rc":[{"batb":[[0,1.49,5.05],[1,1.08,1.77],[2,1.04,1618.04]],"ltp":1.49,"tv":201.18,"id":891555}]}]}
{"op":"mcm","clk":"11939670915","pt":1724401309415,"mc":[{"id":"1.232160907","rc":[{"batb":[[0,1.5,5],[1,1.49,5.05],[2,1.08,1.77]],"ltp":1.49,"tv":201.18,"id":891555}]}]}
{"op":"mcm","clk":"11939671115","pt":1724401312812,"mc":[{"id":"1.232160907","rc":[{"batb":[[0,1.49,5.05],[1,1.08,1.77],[2,1.04,1618.04]],"ltp":1.49,"tv":201.18,"id":891555}]}]}
{"op":"mcm","clk":"11939671281","pt":1724401315132,"mc":[{"id":"1.232160907","rc":[{"batb":[[0,1.5,5],[1,1.49,5.05],[2,1.08,1.77]],"ltp":1.49,"tv":201.18,"id":891555}]}]}
{"op":"mcm","clk":"11939671477","pt":1724401318322,"mc":[{"id":"1.232160907","rc":[{"batb":[[0,1.49,5.05],[1,1.08,1.77],[2,1.04,1618.04]],"ltp":1.49,"tv":201.18,"id":891555}]}]}
{"op":"mcm","clk":"11939671681","pt":1724401321841,"mc":[{"id":"1.232160907","rc":[{"batb":[[0,1.5,5],[1,1.49,5.05],[2,1.08,1.77]],"ltp":1.49,"tv":201.18,"id":891555}]}]}
{"op":"mcm","clk":"11939671925","pt":1724401325119,"mc":[{"id":"1.232160907","rc":[{"batb":[[0,1.49,5.05],[1,1.08,1.77],[2,1.04,1618.04]],"ltp":1.49,"tv":201.18,"id":891555}]}]}
{"op":"mcm","clk":"11939672091","pt":1724401328152,"mc":[{"id":"1.232160907","rc":[{"batb":[[0,1.5,5],[1,1.49,5.05],[2,1.08,1.77]],"ltp":1.49,"tv":201.18,"id":891555}]}]}
{"op":"mcm","clk":"11939672345","pt":1724401331555,"mc":[{"id":"1.232160907","rc":[{"batb":[[0,1.49,5.05],[1,1.08,1.77],[2,1.04,1618.04]],"ltp":1.49,"tv":201.18,"id":891555}]}]}
{"op":"mcm","clk":"11939672641","pt":1724401335643,"mc":[{"id":"1.232160907","rc":[{"batb":[[0,1.5,5],[1,1.49,5.05],[2,1.08,1.77]],"ltp":1.49,"tv":201.18,"id":891555}]}]}
{"op":"mcm","clk":"11939672923","pt":1724401339244,"mc":[{"id":"1.232160907","rc":[{"batb":[[0,1.49,5.05],[1,1.08,1.77],[2,1.04,1618.04]],"ltp":1.49,"tv":201.18,"id":891555}]}]}
{"op":"mcm","clk":"11939673071","pt":1724401341558,"mc":[{"id":"1.232160907","rc":[{"batb":[[0,1.5,5],[1,1.49,5.05],[2,1.08,1.77]],"ltp":1.49,"tv":201.18,"id":891555}]}]}
{"op":"mcm","clk":"11939673306","pt":1724401344747,"mc":[{"id":"1.232160907","rc":[{"batb":[[0,1.49,5.05],[1,1.08,1.77],[2,1.04,1618.04]],"ltp":1.49,"tv":201.18,"id":891555}]}]}
{"op":"mcm","clk":"11939673543","pt":1724401348162,"mc":[{"id":"1.232160907","rc":[{"batb":[[0,1.5,5],[1,1.49,5.05],[2,1.08,1.77]],"ltp":1.49,"tv":201.18,"id":891555}]}]}
{"op":"mcm","clk":"11939673774","pt":1724401351576,"mc":[{"id":"1.232160907","rc":[{"batb":[[0,1.49,5.05],[1,1.08,1.77],[2,1.04,1618.04]],"ltp":1.49,"tv":201.18,"id":891555}]}]}
{"op":"mcm","clk":"11939674012","pt":1724401355071,"mc":[{"id":"1.232160907","rc":[{"batb":[[0,1.5,5],[1,1.49,5.05],[2,1.08,1.77]],"ltp":1.49,"tv":201.18,"id":891555}]}]}
{"op":"mcm","clk":"11939674238","pt":1724401358461,"mc":[{"id":"1.232160907","rc":[{"batb":[[0,1.49,5.05],[1,1.08,1.77],[2,1.04,1618.04]],"ltp":1.49,"tv":201.18,"id":891555}]}]}
{"op":"mcm","clk":"11939674569","pt":1724401363395,"mc":[{"id":"1.232160907","rc":[{"batb":[[0,1.5,5],[1,1.49,5.05],[2,1.08,1.77]],"ltp":1.49,"tv":201.18,"id":891555}]}]}
{"op":"mcm","clk":"11939674806","pt":1724401366786,"mc":[{"id":"1.232160907","rc":[{"batb":[[0,1.49,5.05],[1,1.08,1.77],[2,1.04,1618.04]],"ltp":1.49,"tv":201.18,"id":891555}]}]}
{"op":"mcm","clk":"11939675142","pt":1724401371712,"mc":[{"id":"1.232160907","rc":[{"batb":[[0,1.5,5],[1,1.49,5.05],[2,1.08,1.77]],"ltp":1.49,"tv":201.18,"id":891555}]}]}
{"op":"mcm","clk":"11939675369","pt":1724401375100,"mc":[{"id":"1.232160907","rc":[{"batb":[[0,1.49,5.05],[1,1.08,1.77],[2,1.04,1618.04]],"ltp":1.49,"tv":201.18,"id":891555}]}]}
{"op":"mcm","clk":"11939675655","pt":1724401378703,"mc":[{"id":"1.232160907","rc":[{"batb":[[0,1.5,5],[1,1.49,5.05],[2,1.08,1.77]],"ltp":1.49,"tv":201.18,"id":891555}]}]}
{"op":"mcm","clk":"11939675965","pt":1724401382306,"mc":[{"id":"1.232160907","rc":[{"batb":[[0,1.49,5.05],[1,1.08,1.77],[2,1.04,1618.04]],"ltp":1.49,"tv":201.18,"id":891555}]}]}
{"op":"mcm","clk":"11939676220","pt":1724401385489,"mc":[{"id":"1.232160907","rc":[{"batb":[[0,1.5,5],[1,1.49,5.05],[2,1.08,1.77]],"ltp":1.49,"tv":201.18,"id":891555}]}]}
{"op":"mcm","clk":"11939676471","pt":1724401388819,"mc":[{"id":"1.232160907","rc":[{"batb":[[0,1.49,5.05],[1,1.08,1.77],[2,1.04,1618.04]],"ltp":1.49,"tv":201.18,"id":891555}]}]}
{"op":"mcm","clk":"11939676677","pt":1724401391235,"mc":[{"id":"1.232160907","rc":[{"batb":[[0,1.5,5],[1,1.49,5.05],[2,1.08,1.77]],"ltp":1.49,"tv":201.18,"id":891555}]}]}
{"op":"mcm","clk":"11939676976","pt":1724401394512,"mc":[{"id":"1.232160907","rc":[{"batb":[[0,1.49,5.05],[1,1.08,1.77],[2,1.04,1618.04]],"ltp":1.49,"tv":201.18,"id":891555}]}]}
{"op":"mcm","clk":"11939677365","pt":1724401399745,"mc":[{"id":"1.232160907","rc":[{"batb":[[0,1.5,5],[1,1.49,5.05],[2,1.08,1.77]],"ltp":1.49,"tv":201.18,"id":891555}]}]}
{"op":"mcm","clk":"11939677633","pt":1724401403038,"mc":[{"id":"1.232160907","rc":[{"batb":[[0,1.49,5.05],[1,1.08,1.77],[2,1.04,1618.04]],"ltp":1.49,"tv":201.18,"id":891555}]}]}
{"op":"mcm","clk":"11939677922","pt":1724401406842,"mc":[{"id":"1.232160907","rc":[{"batb":[[0,1.5,5],[1,1.49,5.05],[2,1.08,1.77]],"ltp":1.49,"tv":201.18,"id":891555}]}]}
{"op":"mcm","clk":"11939678142","pt":1724401410229,"mc":[{"id":"1.232160907","rc":[{"batb":[[0,1.49,5.05],[1,1.08,1.77],[2,1.04,1618.04]],"ltp":1.49,"tv":201.18,"id":891555}]}]}
{"op":"mcm","clk":"11939678348","pt":1724401412813,"mc":[{"id":"1.232160907","rc":[{"batb":[[0,1.5,5],[1,1.49,5.05],[2,1.08,1.77]],"ltp":1.49,"tv":201.18,"id":891555}]}]}
{"op":"mcm","clk":"11939678584","pt":1724401416246,"mc":[{"id":"1.232160907","rc":[{"batb":[[0,1.49,5.05],[1,1.08,1.77],[2,1.04,1618.04]],"ltp":1.49,"tv":201.18,"id":891555}]}]}
{"op":"mcm","clk":"11939678719","pt":1724401418348,"mc":[{"id":"1.232160907","rc":[{"batb":[[0,1.5,5],[1,1.49,5.05],[2,1.08,1.77]],"ltp":1.49,"tv":201.18,"id":891555}]}]}
{"op":"mcm","clk":"11939678948","pt":1724401421730,"mc":[{"id":"1.232160907","rc":[{"batb":[[0,1.49,5.05],[1,1.08,1.77],[2,1.04,1618.04]],"ltp":1.49,"tv":201.18,"id":891555}]}]}
{"op":"mcm","clk":"11939679185","pt":1724401424755,"mc":[{"id":"1.232160907","rc":[{"batb":[[0,1.5,5],[1,1.49,5.05],[2,1.08,1.77]],"ltp":1.49,"tv":201.18,"id":891555}]}]}
{"op":"mcm","clk":"11939679426","pt":1724401428139,"mc":[{"id":"1.232160907","rc":[{"batb":[[0,1.49,5.05],[1,1.08,1.77],[2,1.04,1618.04]],"ltp":1.49,"tv":201.18,"id":891555}]}]}
{"op":"mcm","clk":"11939679615","pt":1724401431063,"mc":[{"id":"1.232160907","rc":[{"batb":[[0,1.5,5],[1,1.49,5.05],[2,1.08,1.77]],"ltp":1.49,"tv":201.18,"id":891555}]}]}
{"op":"mcm","clk":"11939679801","pt":1724401434342,"mc":[{"id":"1.232160907","rc":[{"batb":[[0,1.49,5.05],[1,1.08,1.77],[2,1.04,1618.04]],"ltp":1.49,"tv":201.18,"id":891555}]}]}
{"op":"mcm","clk":"11939680190","pt":1724401440245,"mc":[{"id":"1.232160907","rc":[{"batb":[[0,1.5,5],[1,1.49,5.05],[2,1.08,1.77]],"ltp":1.49,"tv":201.18,"id":891555}]}]}
{"op":"mcm","clk":"11939680415","pt":1724401443661,"mc":[{"id":"1.232160907","rc":[{"batb":[[0,1.49,5.05],[1,1.08,1.77],[2,1.04,1618.04]],"ltp":1.49,"tv":201.18,"id":891555}]}]}
{"op":"mcm","clk":"11939680616","pt":1724401446448,"mc":[{"id":"1.232160907","rc":[{"batb":[[0,1.5,5],[1,1.49,5.05],[2,1.08,1.77]],"ltp":1.49,"tv":201.18,"id":891555}]}]}
{"op":"mcm","clk":"11939680859","pt":1724401449898,"mc":[{"id":"1.232160907","rc":[{"batb":[[0,1.49,5.05],[1,1.08,1.77],[2,1.04,1618.04]],"ltp":1.49,"tv":201.18,"id":891555}]}]}
{"op":"mcm","clk":"11939681069","pt":1724401452772,"mc":[{"id":"1.232160907","rc":[{"batb":[[0,1.5,5],[1,1.49,5.05],[2,1.08,1.77]],"ltp":1.49,"tv":201.18,"id":891555}]}]}
{"op":"mcm","clk":"11939681304","pt":1724401455963,"mc":[{"id":"1.232160907","rc":[{"batb":[[0,1.49,5.05],[1,1.08,1.77],[2,1.04,1618.04]],"ltp":1.49,"tv":201.18,"id":891555}]}]}
{"op":"mcm","clk":"11939681506","pt":1724401458695,"mc":[{"id":"1.232160907","rc":[{"batb":[[0,1.5,5],[1,1.49,5.05],[2,1.08,1.77]],"ltp":1.49,"tv":201.18,"id":891555}]}]}
{"op":"mcm","clk":"11939681713","pt":1724401461863,"mc":[{"id":"1.232160907","rc":[{"batb":[[0,1.49,5.05],[1,1.08,1.77],[2,1.04,1618.04]],"ltp":1.49,"tv":201.18,"id":891555}]}]}
{"op":"mcm","clk":"11939681961","pt":1724401465664,"mc":[{"id":"1.232160907","rc":[{"batb":[[0,1.5,5],[1,1.49,5.05],[2,1.08,1.77]],"ltp":1.49,"tv":201.18,"id":891555}]}]}
{"op":"mcm","clk":"11939682198","pt":1724401469011,"mc":[{"id":"1.232160907","rc":[{"batb":[[0,1.49,5.05],[1,1.08,1.77],[2,1.04,1618.04]],"ltp":1.49,"tv":201.18,"id":891555}]}]}
{"op":"mcm","clk":"11939682366","pt":1724401471381,"mc":[{"id":"1.232160907","rc":[{"batb":[[0,1.5,5],[1,1.49,5.05],[2,1.08,1.77]],"ltp":1.49,"tv":201.18,"id":891555}]}]}
{"op":"mcm","clk":"11939682594","pt":1724401474618,"mc":[{"id":"1.232160907","rc":[{"batb":[[0,1.49,5.05],[1,1.08,1.77],[2,1.04,1618.04]],"ltp":1.49,"tv":201.18,"id":891555}]}]}
{"op":"mcm","clk":"11939682821","pt":1724401478010,"mc":[{"id":"1.232160907","rc":[{"batb":[[0,1.5,5],[1,1.49,5.05],[2,1.08,1.77]],"ltp":1.49,"tv":201.18,"id":891555}]}]}
{"op":"mcm","clk":"11939683053","pt":1724401481295,"mc":[{"id":"1.232160907","rc":[{"batb":[[0,1.49,5.05],[1,1.08,1.77],[2,1.04,1618.04]],"ltp":1.49,"tv":201.18,"id":891555}]}]}
{"op":"mcm","clk":"11939683228","pt":1724401483818,"mc":[{"id":"1.232160907","rc":[{"batb":[[0,1.5,5],[1,1.49,5.05],[2,1.08,1.77]],"ltp":1.49,"tv":201.18,"id":891555}]}]}
{"op":"mcm","clk":"11939683489","pt":1724401487214,"mc":[{"id":"1.232160907","rc":[{"batb":[[0,1.49,5.05],[1,1.08,1.77],[2,1.04,1618.04]],"ltp":1.49,"tv":201.18,"id":891555}]}]}
{"op":"mcm","clk":"11939683786","pt":1724401491835,"mc":[{"id":"1.232160907","rc":[{"batb":[[0,1.5,5],[1,1.49,5.05],[2,1.08,1.77]],"ltp":1.49,"tv":201.18,"id":891555}]}]}
{"op":"mcm","clk":"11939684025","pt":1724401495027,"mc":[{"id":"1.232160907","rc":[{"batb":[[0,1.49,5.05],[1,1.08,1.77],[2,1.04,1618.04]],"ltp":1.49,"tv":201.18,"id":891555}]}]}
{"op":"mcm","clk":"11939684253","pt":1724401498109,"mc":[{"id":"1.232160907","rc":[{"batb":[[0,1.5,5],[1,1.49,5.05],[2,1.08,1.77]],"ltp":1.49,"tv":201.18,"id":891555}]}]}
{"op":"mcm","clk":"11939684499","pt":1724401501459,"mc":[{"id":"1.232160907","rc":[{"batb":[[0,1.49,5.05],[1,1.08,1.77],[2,1.04,1618.04]],"ltp":1.49,"tv":201.18,"id":891555}]}]}
{"op":"mcm","clk":"11939684719","pt":1724401504634,"mc":[{"id":"1.232160907","rc":[{"batb":[[0,1.5,5],[1,1.49,5.05],[2,1.08,1.77]],"ltp":1.49,"tv":201.18,"id":891555}]}]}
{"op":"mcm","clk":"11939684971","pt":1724401508055,"mc":[{"id":"1.232160907","rc":[{"batb":[[0,1.49,5.05],[1,1.08,1.77],[2,1.04,1618.04]],"ltp":1.49,"tv":201.18,"id":891555}]}]}
{"op":"mcm","clk":"11939685187","pt":1724401510723,"mc":[{"id":"1.232160907","rc":[{"batb":[[0,1.5,5],[1,1.49,5.05],[2,1.08,1.77]],"ltp":1.49,"tv":201.18,"id":891555}]}]}
{"op":"mcm","clk":"11939685448","pt":1724401513868,"mc":[{"id":"1.232160907","rc":[{"batb":[[0,1.49,5.05],[1,1.08,1.77],[2,1.04,1618.04]],"ltp":1.49,"tv":201.18,"id":891555}]}]}
{"op":"mcm","clk":"11939685629","pt":1724401516235,"mc":[{"id":"1.232160907","rc":[{"batb":[[0,1.5,5],[1,1.49,5.05],[2,1.08,1.77]],"ltp":1.49,"tv":201.18,"id":891555}]}]}
{"op":"mcm","clk":"11939685878","pt":1724401519569,"mc":[{"id":"1.232160907","rc":[{"batb":[[0,1.49,5.05],[1,1.08,1.77],[2,1.04,1618.04]],"ltp":1.49,"tv":201.18,"id":891555}]}]}
{"op":"mcm","clk":"11939686279","pt":1724401526145,"mc":[{"id":"1.232160907","rc":[{"batb":[[0,1.5,5],[1,1.49,5.05],[2,1.08,1.77]],"ltp":1.49,"tv":201.18,"id":891555}]}]}
{"op":"mcm","clk":"11939686525","pt":1724401529485,"mc":[{"id":"1.232160907","rc":[{"batb":[[0,1.49,5.05],[1,1.08,1.77],[2,1.04,1618.04]],"ltp":1.49,"tv":201.18,"id":891555}]}]}
{"op":"mcm","clk":"11939686762","pt":1724401532988,"mc":[{"id":"1.232160907","rc":[{"batb":[[0,1.5,5],[1,1.49,5.05],[2,1.08,1.77]],"ltp":1.49,"tv":201.18,"id":891555}]}]}
{"op":"mcm","clk":"11939686990","pt":1724401536284,"mc":[{"id":"1.232160907","rc":[{"batb":[[0,1.49,5.05],[1,1.08,1.77],[2,1.04,1618.04]],"ltp":1.49,"tv":201.18,"id":891555}]}]}
{"op":"mcm","clk":"11939687183","pt":1724401539064,"mc":[{"id":"1.232160907","rc":[{"batb":[[0,1.5,5],[1,1.49,5.05],[2,1.08,1.77]],"ltp":1.49,"tv":201.18,"id":891555}]}]}
{"op":"mcm","clk":"11939687398","pt":1724401542305,"mc":[{"id":"1.232160907","rc":[{"batb":[[0,1.49,5.05],[1,1.08,1.77],[2,1.04,1618.04]],"ltp":1.49,"tv":201.18,"id":891555}]}]}
{"op":"mcm","clk":"11939687636","pt":1724401545796,"mc":[{"id":"1.232160907","rc":[{"batb":[[0,1.5,5],[1,1.49,5.05],[2,1.08,1.77]],"ltp":1.49,"tv":201.18,"id":891555}]}]}
{"op":"mcm","clk":"11939687844","pt":1724401549027,"mc":[{"id":"1.232160907","rc":[{"batb":[[0,1.49,5.05],[1,1.08,1.77],[2,1.04,1618.04]],"ltp":1.49,"tv":201.18,"id":891555}]}]}
{"op":"mcm","clk":"11939688037","pt":1724401552108,"mc":[{"id":"1.232160907","rc":[{"batb":[[0,1.5,5],[1,1.49,5.05],[2,1.08,1.77]],"ltp":1.49,"tv":201.18,"id":891555}]}]}
{"op":"mcm","clk":"11939688247","pt":1724401555492,"mc":[{"id":"1.232160907","rc":[{"batb":[[0,1.49,5.05],[1,1.08,1.77],[2,1.04,1618.04]],"ltp":1.49,"tv":201.18,"id":891555}]}]}
{"op":"mcm","clk":"11939688463","pt":1724401558634,"mc":[{"id":"1.232160907","rc":[{"batb":[[0,1.5,5],[1,1.49,5.05],[2,1.08,1.77]],"ltp":1.49,"tv":201.18,"id":891555}]}]}
{"op":"mcm","clk":"11939688701","pt":1724401561828,"mc":[{"id":"1.232160907","rc":[{"batb":[[0,1.49,5.05],[1,1.08,1.77],[2,1.04,1618.04]],"ltp":1.49,"tv":201.18,"id":891555}]}]}
{"op":"mcm","clk":"11939689009","pt":1724401566296,"mc":[{"id":"1.232160907","rc":[{"batb":[[0,1.5,5],[1,1.49,5.05],[2,1.08,1.77]],"ltp":1.49,"tv":201.18,"id":891555}]}]}
{"op":"mcm","clk":"11939689253","pt":1724401569749,"mc":[{"id":"1.232160907","rc":[{"batb":[[0,1.49,5.05],[1,1.08,1.77],[2,1.04,1618.04]],"ltp":1.49,"tv":201.18,"id":891555}]}]}
{"op":"mcm","clk":"11939689599","pt":1724401574031,"mc":[{"id":"1.232160907","rc":[{"batb":[[0,1.5,5],[1,1.49,5.05],[2,1.08,1.77]],"ltp":1.49,"tv":201.18,"id":891555}]}]}
{"op":"mcm","clk":"11939689810","pt":1724401577441,"mc":[{"id":"1.232160907","rc":[{"batb":[[0,1.49,5.05],[1,1.08,1.77],[2,1.04,1618.04]],"ltp":1.49,"tv":201.18,"id":891555}]}]}
{"op":"mcm","clk":"11939689961","pt":1724401579955,"mc":[{"id":"1.232160907","rc":[{"batb":[[0,1.5,5],[1,1.49,5.05],[2,1.08,1.77]],"ltp":1.49,"tv":201.18,"id":891555}]}]}
{"op":"mcm","clk":"11939690193","pt":1724401583342,"mc":[{"id":"1.232160907","rc":[{"batb":[[0,1.49,5.05],[1,1.08,1.77],[2,1.04,1618.04]],"ltp":1.49,"tv":201.18,"id":891555}]}]}
{"op":"mcm","clk":"11939690366","pt":1724401586634,"mc":[{"id":"1.232160907","rc":[{"batb":[[0,1.5,5],[1,1.49,5.05],[2,1.08,1.77]],"ltp":1.49,"tv":201.18,"id":891555}]}]}
{"op":"mcm","clk":"11939690577","pt":1724401590022,"mc":[{"id":"1.232160907","rc":[{"batb":[[0,1.49,5.05],[1,1.08,1.77],[2,1.04,1618.04]],"ltp":1.49,"tv":201.18,"id":891555}]}]}
{"op":"mcm","clk":"11939690706","pt":1724401592129,"mc":[{"id":"1.232160907","rc":[{"batb":[[0,1.5,5],[1,1.49,5.05],[2,1.08,1.77]],"ltp":1.49,"tv":201.18,"id":891555}]}]}
{"op":"mcm","clk":"11939690919","pt":1724401595560,"mc":[{"id":"1.232160907","rc":[{"batb":[[0,1.49,5.05],[1,1.08,1.77],[2,1.04,1618.04]],"ltp":1.49,"tv":201.18,"id":891555}]}]}
{"op":"mcm","clk":"11939691084","pt":1724401598225,"mc":[{"id":"1.232160907","rc":[{"batb":[[0,1.5,5],[1,1.49,5.05],[2,1.08,1.77]],"ltp":1.49,"tv":201.18,"id":891555}]}]}
{"op":"mcm","clk":"11939691290","pt":1724401601558,"mc":[{"id":"1.232160907","rc":[{"batb":[[0,1.49,5.05],[1,1.08,1.77],[2,1.04,1618.04]],"ltp":1.49,"tv":201.18,"id":891555}]}]}
{"op":"mcm","clk":"11939691449","pt":1724401603966,"mc":[{"id":"1.232160907","rc":[{"batb":[[0,1.5,5],[1,1.49,5.05],[2,1.08,1.77]],"ltp":1.49,"tv":201.18,"id":891555}]}]}
{"op":"mcm","clk":"11939691641","pt":1724401607146,"mc":[{"id":"1.232160907","rc":[{"batb":[[0,1.49,5.05],[1,1.08,1.77],[2,1.04,1618.04]],"ltp":1.49,"tv":201.18,"id":891555}]}]}
{"op":"mcm","clk":"11939691856","pt":1724401610268,"mc":[{"id":"1.232160907","rc":[{"batb":[[0,1.5,5],[1,1.49,5.05],[2,1.08,1.77]],"ltp":1.49,"tv":201.18,"id":891555}]}]}
{"op":"mcm","clk":"11939692052","pt":1724401613546,"mc":[{"id":"1.232160907","rc":[{"batb":[[0,1.49,5.05],[1,1.08,1.77],[2,1.04,1618.04]],"ltp":1.49,"tv":201.18,"id":891555}]}]}
{"op":"mcm","clk":"11939692243","pt":1724401616879,"mc":[{"id":"1.232160907","rc":[{"batb":[[0,1.5,5],[1,1.49,5.05],[2,1.08,1.77]],"ltp":1.49,"tv":201.18,"id":891555}]}]}
{"op":"mcm","clk":"11939692436","pt":1724401620151,"mc":[{"id":"1.232160907","rc":[{"batb":[[0,1.49,5.05],[1,1.08,1.77],[2,1.04,1618.04]],"ltp":1.49,"tv":201.18,"id":891555}]}]}
{"op":"mcm","clk":"11939692576","pt":1724401622459,"mc":[{"id":"1.232160907","rc":[{"batb":[[0,1.5,5],[1,1.49,5.05],[2,1.08,1.77]],"ltp":1.49,"tv":201.18,"id":891555}]}]}
{"op":"mcm","clk":"11939692791","pt":1724401625713,"mc":[{"id":"1.232160907","rc":[{"batb":[[0,1.49,5.05],[1,1.08,1.77],[2,1.04,1618.04]],"ltp":1.49,"tv":201.18,"id":891555}]}]}
{"op":"mcm","clk":"11939692961","pt":1724401628388,"mc":[{"id":"1.232160907","rc":[{"batb":[[0,1.5,5],[1,1.49,5.05],[2,1.08,1.77]],"ltp":1.49,"tv":201.18,"id":891555}]}]}
{"op":"mcm","clk":"11939693194","pt":1724401631784,"mc":[{"id":"1.232160907","rc":[{"batb":[[0,1.49,5.05],[1,1.08,1.77],[2,1.04,1618.04]],"ltp":1.49,"tv":201.18,"id":891555}]}]}
{"op":"mcm","clk":"11939693366","pt":1724401634898,"mc":[{"id":"1.232160907","rc":[{"batb":[[0,1.5,5],[1,1.49,5.05],[2,1.08,1.77]],"ltp":1.49,"tv":201.18,"id":891555}]}]}
{"op":"mcm","clk":"11939693576","pt":1724401638083,"mc":[{"id":"1.232160907","rc":[{"batb":[[0,1.49,5.05],[1,1.08,1.77],[2,1.04,1618.04]],"ltp":1.49,"tv":201.18,"id":891555}]}]}
{"op":"mcm","clk":"11939693755","pt":1724401641169,"mc":[{"id":"1.232160907","rc":[{"batb":[[0,1.5,5],[1,1.49,5.05],[2,1.08,1.77]],"ltp":1.49,"tv":201.18,"id":891555}]}]}
{"op":"mcm","clk":"11939693941","pt":1724401644492,"mc":[{"id":"1.232160907","rc":[{"batb":[[0,1.49,5.05],[1,1.08,1.77],[2,1.04,1618.04]],"ltp":1.49,"tv":201.18,"id":891555}]}]}
{"op":"mcm","clk":"11939694142","pt":1724401647525,"mc":[{"id":"1.232160907","rc":[{"batb":[[0,1.5,5],[1,1.49,5.05],[2,1.08,1.77]],"ltp":1.49,"tv":201.18,"id":891555}]}]}
{"op":"mcm","clk":"11939694323","pt":1724401650706,"mc":[{"id":"1.232160907","rc":[{"batb":[[0,1.49,5.05],[1,1.08,1.77],[2,1.04,1618.04]],"ltp":1.49,"tv":201.18,"id":891555}]}]}
{"op":"mcm","clk":"11939694550","pt":1724401654703,"mc":[{"id":"1.232160907","rc":[{"batb":[[0,1.5,5],[1,1.49,5.05],[2,1.08,1.77]],"ltp":1.49,"tv":201.18,"id":891555}]}]}
{"op":"mcm","clk":"11939694728","pt":1724401657924,"mc":[{"id":"1.232160907","rc":[{"batb":[[0,1.49,5.05],[1,1.08,1.77],[2,1.04,1618.04]],"ltp":1.49,"tv":201.18,"id":891555}]}]}
{"op":"mcm","clk":"11939694855","pt":1724401660326,"mc":[{"id":"1.232160907","rc":[{"batb":[[0,1.5,5],[1,1.49,5.05],[2,1.08,1.77]],"ltp":1.49,"tv":201.18,"id":891555}]}]}
{"op":"mcm","clk":"11939695026","pt":1724401663503,"mc":[{"id":"1.232160907","rc":[{"batb":[[0,1.49,5.05],[1,1.08,1.77],[2,1.04,1618.04]],"ltp":1.49,"tv":201.18,"id":891555}]}]}
{"op":"mcm","clk":"11939695204","pt":1724401666523,"mc":[{"id":"1.232160907","rc":[{"batb":[[0,1.5,5],[1,1.49,5.05],[2,1.08,1.77]],"ltp":1.49,"tv":201.18,"id":891555}]}]}
{"op":"mcm","clk":"11939695391","pt":1724401669730,"mc":[{"id":"1.232160907","rc":[{"batb":[[0,1.49,5.05],[1,1.08,1.77],[2,1.04,1618.04]],"ltp":1.49,"tv":201.18,"id":891555}]}]}
{"op":"mcm","clk":"11939695584","pt":1724401672817,"mc":[{"id":"1.232160907","rc":[{"batb":[[0,1.5,5],[1,1.49,5.05],[2,1.08,1.77]],"ltp":1.49,"tv":201.18,"id":891555}]}]}
{"op":"mcm","clk":"11939695761","pt":1724401675943,"mc":[{"id":"1.232160907","rc":[{"batb":[[0,1.49,5.05],[1,1.08,1.77],[2,1.04,1618.04]],"ltp":1.49,"tv":201.18,"id":891555}]}]}
{"op":"mcm","clk":"11939695896","pt":1724401678615,"mc":[{"id":"1.232160907","rc":[{"batb":[[0,1.5,5],[1,1.49,5.05],[2,1.08,1.77]],"ltp":1.49,"tv":201.18,"id":891555}]}]}
{"op":"mcm","clk":"11939696095","pt":1724401681862,"mc":[{"id":"1.232160907","rc":[{"batb":[[0,1.49,5.05],[1,1.08,1.77],[2,1.04,1618.04]],"ltp":1.49,"tv":201.18,"id":891555}]}]}
{"op":"mcm","clk":"11939696247","pt":1724401684131,"mc":[{"id":"1.232160907","rc":[{"batb":[[0,1.5,5],[1,1.49,5.05],[2,1.08,1.77]],"ltp":1.49,"tv":201.18,"id":891555}]}]}
{"op":"mcm","clk":"11939696457","pt":1724401687474,"mc":[{"id":"1.232160907","rc":[{"batb":[[0,1.49,5.05],[1,1.08,1.77],[2,1.04,1618.04]],"ltp":1.49,"tv":201.18,"id":891555}]}]}
{"op":"mcm","clk":"11939696645","pt":1724401690879,"mc":[{"id":"1.232160907","rc":[{"batb":[[0,1.5,5],[1,1.49,5.05],[2,1.08,1.77]],"ltp":1.49,"tv":201.18,"id":891555}]}]}
{"op":"mcm","clk":"11939696820","pt":1724401694063,"mc":[{"id":"1.232160907","rc":[{"batb":[[0,1.49,5.05],[1,1.08,1.77],[2,1.04,1618.04]],"ltp":1.49,"tv":201.18,"id":891555}]}]}
{"op":"mcm","clk":"11939696966","pt":1724401696637,"mc":[{"id":"1.232160907","rc":[{"batb":[[0,1.5,5],[1,1.49,5.05],[2,1.08,1.77]],"ltp":1.49,"tv":201.18,"id":891555}]}]}
{"op":"mcm","clk":"11939697104","pt":1724401699857,"mc":[{"id":"1.232160907","rc":[{"batb":[[0,1.49,5.05],[1,1.08,1.77],[2,1.04,1618.04]],"ltp":1.49,"tv":201.18,"id":891555}]}]}
{"op":"mcm","clk":"11939697314","pt":1724401703348,"mc":[{"id":"1.232160907","rc":[{"batb":[[0,1.5,5],[1,1.49,5.05],[2,1.08,1.77]],"ltp":1.49,"tv":201.18,"id":891555}]}]}
{"op":"mcm","clk":"11939697560","pt":1724401706684,"mc":[{"id":"1.232160907","rc":[{"batb":[[0,1.49,5.05],[1,1.08,1.77],[2,1.04,1618.04]],"ltp":1.49,"tv":201.18,"id":891555}]}]}
{"op":"mcm","clk":"11939698007","pt":1724401709802,"mc":[{"id":"1.232160907","rc":[{"batb":[[0,1.5,5],[1,1.49,5.05],[2,1.08,1.77]],"ltp":1.49,"tv":201.18,"id":891555}]}]}
{"op":"mcm","clk":"11939698231","pt":1724401713055,"mc":[{"id":"1.232160907","rc":[{"batb":[[0,1.49,5.05],[1,1.08,1.77],[2,1.04,1618.04]],"ltp":1.49,"tv":201.18,"id":891555}]}]}
{"op":"mcm","clk":"11939698464","pt":1724401715766,"mc":[{"id":"1.232160907","rc":[{"batb":[[0,1.5,5],[1,1.49,5.05],[2,1.08,1.77]],"ltp":1.49,"tv":201.18,"id":891555}]}]}
{"op":"mcm","clk":"11939698698","pt":1724401719058,"mc":[{"id":"1.232160907","rc":[{"batb":[[0,1.49,5.05],[1,1.08,1.77],[2,1.04,1618.04]],"ltp":1.49,"tv":201.18,"id":891555}]}]}
{"op":"mcm","clk":"11939698996","pt":1724401721278,"mc":[{"id":"1.232160907","rc":[{"batb":[[0,1.5,5],[1,1.49,5.05],[2,1.08,1.77]],"ltp":1.49,"tv":201.18,"id":891555}]}]}
{"op":"mcm","clk":"11939699214","pt":1724401724471,"mc":[{"id":"1.232160907","rc":[{"batb":[[0,1.49,5.05],[1,1.08,1.77],[2,1.04,1618.04]],"ltp":1.49,"tv":201.18,"id":891555}]}]}
{"op":"mcm","clk":"11939699426","pt":1724401727502,"mc":[{"id":"1.232160907","rc":[{"batb":[[0,1.5,5],[1,1.49,5.05],[2,1.08,1.77]],"ltp":1.49,"tv":201.18,"id":891555}]}]}
{"op":"mcm","clk":"11939699654","pt":1724401730691,"mc":[{"id":"1.232160907","rc":[{"batb":[[0,1.49,5.05],[1,1.08,1.77],[2,1.04,1618.04]],"ltp":1.49,"tv":201.18,"id":891555}]}]}
{"op":"mcm","clk":"11939699865","pt":1724401734008,"mc":[{"id":"1.232160907","rc":[{"batb":[[0,1.5,5],[1,1.49,5.05],[2,1.08,1.77]],"ltp":1.49,"tv":201.18,"id":891555}]}]}
{"op":"mcm","clk":"11939700071","pt":1724401737301,"mc":[{"id":"1.232160907","rc":[{"batb":[[0,1.49,5.05],[1,1.08,1.77],[2,1.04,1618.04]],"ltp":1.49,"tv":201.18,"id":891555}]}]}
{"op":"mcm","clk":"11939700237","pt":1724401740224,"mc":[{"id":"1.232160907","rc":[{"batb":[[0,1.5,5],[1,1.49,5.05],[2,1.08,1.77]],"ltp":1.49,"tv":201.18,"id":891555}]}]}
{"op":"mcm","clk":"11939700407","pt":1724401743522,"mc":[{"id":"1.232160907","rc":[{"batb":[[0,1.49,5.05],[1,1.08,1.77],[2,1.04,1618.04]],"ltp":1.49,"tv":201.18,"id":891555}]}]}
{"op":"mcm","clk":"11939700605","pt":1724401746004,"mc":[{"id":"1.232160907","rc":[{"batb":[[0,1.5,5],[1,1.49,5.05],[2,1.08,1.77]],"ltp":1.49,"tv":201.18,"id":891555}]}]}
{"op":"mcm","clk":"11939700791","pt":1724401749202,"mc":[{"id":"1.232160907","rc":[{"batb":[[0,1.49,5.05],[1,1.08,1.77],[2,1.04,1618.04]],"ltp":1.49,"tv":201.18,"id":891555}]}]}
{"op":"mcm","clk":"11939700948","pt":1724401751618,"mc":[{"id":"1.232160907","rc":[{"batb":[[0,1.5,5],[1,1.49,5.05],[2,1.08,1.77]],"ltp":1.49,"tv":201.18,"id":891555}]}]}
{"op":"mcm","clk":"11939701147","pt":1724401755006,"mc":[{"id":"1.232160907","rc":[{"batb":[[0,1.49,5.05],[1,1.08,1.77],[2,1.04,1618.04]],"ltp":1.49,"tv":201.18,"id":891555}]}]}
{"op":"mcm","clk":"11939701338","pt":1724401757827,"mc":[{"id":"1.232160907","rc":[{"batb":[[0,1.5,5],[1,1.49,5.05],[2,1.08,1.77]],"ltp":1.49,"tv":201.18,"id":891555}]}]}
{"op":"mcm","clk":"11939701728","pt":1724401761034,"mc":[{"id":"1.232160907","rc":[{"batb":[[0,1.49,5.05],[1,1.08,1.77],[2,1.04,1618.04]],"ltp":1.49,"tv":201.18,"id":891555}]}]}
{"op":"mcm","clk":"11939701906","pt":1724401763603,"mc":[{"id":"1.232160907","rc":[{"batb":[[0,1.5,5],[1,1.49,5.05],[2,1.08,1.77]],"ltp":1.49,"tv":201.18,"id":891555}]}]}
{"op":"mcm","clk":"11939702117","pt":1724401766935,"mc":[{"id":"1.232160907","rc":[{"batb":[[0,1.49,5.05],[1,1.08,1.77],[2,1.04,1618.04]],"ltp":1.49,"tv":201.18,"id":891555}]}]}
{"op":"mcm","clk":"11939702265","pt":1724401769346,"mc":[{"id":"1.232160907","rc":[{"batb":[[0,1.5,5],[1,1.49,5.05],[2,1.08,1.77]],"ltp":1.49,"tv":201.18,"id":891555}]}]}
{"op":"mcm","clk":"11939702501","pt":1724401772938,"mc":[{"id":"1.232160907","rc":[{"batb":[[0,1.49,5.05],[1,1.08,1.77],[2,1.04,1618.04]],"ltp":1.49,"tv":201.18,"id":891555}]}]}
{"op":"mcm","clk":"11939702659","pt":1724401775344,"mc":[{"id":"1.232160907","rc":[{"batb":[[0,1.5,5],[1,1.49,5.05],[2,1.08,1.77]],"ltp":1.49,"tv":201.18,"id":891555}]}]}
{"op":"mcm","clk":"11939703071","pt":1724401778646,"mc":[{"id":"1.232160907","rc":[{"batb":[[0,1.49,5.05],[1,1.08,1.77],[2,1.04,1618.04]],"ltp":1.49,"tv":201.18,"id":891555}]}]}
{"op":"mcm","clk":"11939703335","pt":1724401782960,"mc":[{"id":"1.232160907","rc":[{"batb":[[0,1.5,5],[1,1.49,5.05],[2,1.08,1.77]],"ltp":1.49,"tv":201.18,"id":891555}]}]}
{"op":"mcm","clk":"11939703481","pt":1724401786245,"mc":[{"id":"1.232160907","rc":[{"batb":[[0,1.49,5.05],[1,1.08,1.77],[2,1.04,1618.04]],"ltp":1.49,"tv":201.18,"id":891555}]}]}
{"op":"mcm","clk":"11939703600","pt":1724401788542,"mc":[{"id":"1.232160907","rc":[{"batb":[[0,1.5,5],[1,1.49,5.05],[2,1.08,1.77]],"ltp":1.49,"tv":201.18,"id":891555}]}]}
{"op":"mcm","clk":"11939703798","pt":1724401791941,"mc":[{"id":"1.232160907","rc":[{"batb":[[0,1.49,5.05],[1,1.08,1.77],[2,1.04,1618.04]],"ltp":1.49,"tv":201.18,"id":891555}]}]}
{"op":"mcm","clk":"11939703956","pt":1724401795334,"mc":[{"id":"1.232160907","rc":[{"batb":[[0,1.5,5],[1,1.49,5.05],[2,1.08,1.77]],"ltp":1.49,"tv":201.18,"id":891555}]}]}
{"op":"mcm","clk":"11939704120","pt":1724401798860,"mc":[{"id":"1.232160907","rc":[{"batb":[[0,1.49,5.05],[1,1.08,1.77],[2,1.04,1618.04]],"ltp":1.49,"tv":201.18,"id":891555}]}]}
{"op":"mcm","clk":"11939704272","pt":1724401801377,"mc":[{"id":"1.232160907","rc":[{"batb":[[0,1.5,5],[1,1.49,5.05],[2,1.08,1.77]],"ltp":1.49,"tv":201.18,"id":891555}]}]}
{"op":"mcm","clk":"11939704487","pt":1724401804672,"mc":[{"id":"1.232160907","rc":[{"batb":[[0,1.49,5.05],[1,1.08,1.77],[2,1.04,1618.04]],"ltp":1.49,"tv":201.18,"id":891555}]}]}
{"op":"mcm","clk":"11939704668","pt":1724401807245,"mc":[{"id":"1.232160907","rc":[{"batb":[[0,1.5,5],[1,1.49,5.05],[2,1.08,1.77]],"ltp":1.49,"tv":201.18,"id":891555}]}]}
{"op":"mcm","clk":"11939705035","pt":1724401810502,"mc":[{"id":"1.232160907","rc":[{"batb":[[0,1.49,5.05],[1,1.08,1.77],[2,1.04,1618.04]],"ltp":1.49,"tv":201.18,"id":891555}]}]}
{"op":"mcm","clk":"11939705272","pt":1724401812881,"mc":[{"id":"1.232160907","rc":[{"batb":[[0,1.5,5],[1,1.49,5.05],[2,1.08,1.77]],"ltp":1.49,"tv":201.18,"id":891555}]}]}
{"op":"mcm","clk":"11939705461","pt":1724401816372,"mc":[{"id":"1.232160907","rc":[{"batb":[[0,1.49,5.05],[1,1.08,1.77],[2,1.04,1618.04]],"ltp":1.49,"tv":201.18,"id":891555}]}]}
{"op":"mcm","clk":"11939705662","pt":1724401819452,"mc":[{"id":"1.232160907","rc":[{"batb":[[0,1.5,5],[1,1.49,5.05],[2,1.08,1.77]],"ltp":1.49,"tv":201.18,"id":891555}]}]}
{"op":"mcm","clk":"11939705859","pt":1724401822897,"mc":[{"id":"1.232160907","rc":[{"batb":[[0,1.49,5.05],[1,1.08,1.77],[2,1.04,1618.04]],"ltp":1.49,"tv":201.18,"id":891555}]}]}
{"op":"mcm","clk":"11939706102","pt":1724401825463,"mc":[{"id":"1.232160907","rc":[{"batb":[[0,1.5,5],[1,1.49,5.05],[2,1.08,1.77]],"ltp":1.49,"tv":201.18,"id":891555}]}]}
{"op":"mcm","clk":"11939706267","pt":1724401828692,"mc":[{"id":"1.232160907","rc":[{"batb":[[0,1.49,5.05],[1,1.08,1.77],[2,1.04,1618.04]],"ltp":1.49,"tv":201.18,"id":891555}]}]}
{"op":"mcm","clk":"11939706463","pt":1724401831974,"mc":[{"id":"1.232160907","rc":[{"batb":[[0,1.5,5],[1,1.49,5.05],[2,1.08,1.77]],"ltp":1.49,"tv":201.18,"id":891555}]}]}
{"op":"mcm","clk":"11939706643","pt":1724401835290,"mc":[{"id":"1.232160907","rc":[{"batb":[[0,1.49,5.05],[1,1.08,1.77],[2,1.04,1618.04]],"ltp":1.49,"tv":201.18,"id":891555}]}]}
{"op":"mcm","clk":"11939706779","pt":1724401837403,"mc":[{"id":"1.232160907","rc":[{"batb":[[0,1.5,5],[1,1.49,5.05],[2,1.08,1.77]],"ltp":1.49,"tv":201.18,"id":891555}]}]}
{"op":"mcm","clk":"11939706979","pt":1724401840798,"mc":[{"id":"1.232160907","rc":[{"batb":[[0,1.49,5.05],[1,1.08,1.77],[2,1.04,1618.04]],"ltp":1.49,"tv":201.18,"id":891555}]}]}
{"op":"mcm","clk":"11939707163","pt":1724401843925,"mc":[{"id":"1.232160907","rc":[{"batb":[[0,1.5,5],[1,1.49,5.05],[2,1.08,1.77]],"ltp":1.49,"tv":201.18,"id":891555}]}]}
{"op":"mcm","clk":"11939707388","pt":1724401847273,"mc":[{"id":"1.232160907","rc":[{"batb":[[0,1.49,5.05],[1,1.08,1.77],[2,1.04,1618.04]],"ltp":1.49,"tv":201.18,"id":891555}]}]}
{"op":"mcm","clk":"11939707588","pt":1724401850718,"mc":[{"id":"1.232160907","rc":[{"batb":[[0,1.5,5],[1,1.49,5.05],[2,1.08,1.77]],"ltp":1.49,"tv":201.18,"id":891555}]}]}
{"op":"mcm","clk":"11939707754","pt":1724401853921,"mc":[{"id":"1.232160907","rc":[{"batb":[[0,1.49,5.05],[1,1.08,1.77],[2,1.04,1618.04]],"ltp":1.49,"tv":201.18,"id":891555}]}]}
{"op":"mcm","clk":"11939707881","pt":1724401856228,"mc":[{"id":"1.232160907","rc":[{"batb":[[0,1.5,5],[1,1.49,5.05],[2,1.08,1.77]],"ltp":1.49,"tv":201.18,"id":891555}]}]}
{"op":"mcm","clk":"11939708146","pt":1724401859590,"mc":[{"id":"1.232160907","rc":[{"batb":[[0,1.49,5.05],[1,1.08,1.77],[2,1.04,1618.04]],"ltp":1.49,"tv":201.18,"id":891555}]}]}
{"op":"mcm","clk":"11939708508","pt":1724401863834,"mc":[{"id":"1.232160907","rc":[{"batb":[[0,1.5,5],[1,1.49,5.05],[2,1.08,1.77]],"ltp":1.49,"tv":201.18,"id":891555}]}]}
{"op":"mcm","clk":"11939708717","pt":1724401867008,"mc":[{"id":"1.232160907","rc":[{"batb":[[0,1.49,5.05],[1,1.08,1.77],[2,1.04,1618.04]],"ltp":1.49,"tv":201.18,"id":891555}]}]}
{"op":"mcm","clk":"11939708925","pt":1724401870922,"mc":[{"id":"1.232160907","rc":[{"batb":[[0,1.5,5],[1,1.49,5.05],[2,1.08,1.77]],"ltp":1.49,"tv":201.18,"id":891555}]}]}
{"op":"mcm","clk":"11939709214","pt":1724401874217,"mc":[{"id":"1.232160907","rc":[{"batb":[[0,1.49,5.05],[1,1.08,1.77],[2,1.04,1618.04]],"ltp":1.49,"tv":201.18,"id":891555}]}]}
{"op":"mcm","clk":"11939709402","pt":1724401877295,"mc":[{"id":"1.232160907","rc":[{"batb":[[0,1.5,5],[1,1.49,5.05],[2,1.08,1.77]],"ltp":1.49,"tv":201.18,"id":891555}]}]}
{"op":"mcm","clk":"11939709587","pt":1724401880630,"mc":[{"id":"1.232160907","rc":[{"batb":[[0,1.49,5.05],[1,1.08,1.77],[2,1.04,1618.04]],"ltp":1.49,"tv":201.18,"id":891555}]}]}
{"op":"mcm","clk":"11939709768","pt":1724401883713,"mc":[{"id":"1.232160907","rc":[{"batb":[[0,1.5,5],[1,1.49,5.05],[2,1.08,1.77]],"ltp":1.49,"tv":201.18,"id":891555}]}]}
{"op":"mcm","clk":"11939709944","pt":1724401886897,"mc":[{"id":"1.232160907","rc":[{"batb":[[0,1.49,5.05],[1,1.08,1.77],[2,1.04,1618.04]],"ltp":1.49,"tv":201.18,"id":891555}]}]}
{"op":"mcm","clk":"11939710106","pt":1724401889999,"mc":[{"id":"1.232160907","rc":[{"batb":[[0,1.5,5],[1,1.49,5.05],[2,1.08,1.77]],"ltp":1.49,"tv":201.18,"id":891555}]}]}
{"op":"mcm","clk":"11939710288","pt":1724401893342,"mc":[{"id":"1.232160907","rc":[{"batb":[[0,1.49,5.05],[1,1.08,1.77],[2,1.04,1618.04]],"ltp":1.49,"tv":201.18,"id":891555}]}]}
{"op":"mcm","clk":"11939710540","pt":1724401896438,"mc":[{"id":"1.232160907","rc":[{"batb":[[0,1.5,5],[1,1.49,5.05],[2,1.08,1.77]],"ltp":1.49,"tv":201.18,"id":891555}]}]}
{"op":"mcm","clk":"11939710726","pt":1724401899730,"mc":[{"id":"1.232160907","rc":[{"batb":[[0,1.49,5.05],[1,1.08,1.77],[2,1.04,1618.04]],"ltp":1.49,"tv":201.18,"id":891555}]}]}
{"op":"mcm","clk":"11939710894","pt":1724401902621,"mc":[{"id":"1.232160907","rc":[{"batb":[[0,1.5,5],[1,1.49,5.05],[2,1.08,1.77]],"ltp":1.49,"tv":201.18,"id":891555}]}]}
{"op":"mcm","clk":"11939711047","pt":1724401905808,"mc":[{"id":"1.232160907","rc":[{"batb":[[0,1.49,5.05],[1,1.08,1.77],[2,1.04,1618.04]],"ltp":1.49,"tv":201.18,"id":891555}]}]}
{"op":"mcm","clk":"11939711302","pt":1724401907939,"mc":[{"id":"1.232160907","rc":[{"batb":[[0,1.5,5],[1,1.49,5.05],[2,1.08,1.77]],"ltp":1.49,"tv":201.18,"id":891555}]}]}
{"op":"mcm","clk":"11939711529","pt":1724401911334,"mc":[{"id":"1.232160907","rc":[{"batb":[[0,1.49,5.05],[1,1.08,1.77],[2,1.04,1618.04]],"ltp":1.49,"tv":201.18,"id":891555}]}]}
{"op":"mcm","clk":"11939711719","pt":1724401915756,"mc":[{"id":"1.232160907","rc":[{"batb":[[0,1.5,5],[1,1.49,5.05],[2,1.08,1.77]],"ltp":1.49,"tv":201.18,"id":891555}]}]}
{"op":"mcm","clk":"11939711882","pt":1724401919139,"mc":[{"id":"1.232160907","rc":[{"batb":[[0,1.49,5.05],[1,1.08,1.77],[2,1.04,1618.04]],"ltp":1.49,"tv":201.18,"id":891555}]}]}
{"op":"mcm","clk":"11939711993","pt":1724401921547,"mc":[{"id":"1.232160907","rc":[{"batb":[[0,1.5,5],[1,1.49,5.05],[2,1.08,1.77]],"ltp":1.49,"tv":201.18,"id":891555}]}]}
{"op":"mcm","clk":"11939712259","pt":1724401924745,"mc":[{"id":"1.232160907","rc":[{"batb":[[0,1.49,5.05],[1,1.08,1.77],[2,1.04,1618.04]],"ltp":1.49,"tv":201.18,"id":891555}]}]}
{"op":"mcm","clk":"11939712400","pt":1724401927167,"mc":[{"id":"1.232160907","rc":[{"batb":[[0,1.5,5],[1,1.49,5.05],[2,1.08,1.77]],"ltp":1.49,"tv":201.18,"id":891555}]}]}
{"op":"mcm","clk":"11939712550","pt":1724401930347,"mc":[{"id":"1.232160907","rc":[{"batb":[[0,1.49,5.05],[1,1.08,1.77],[2,1.04,1618.04]],"ltp":1.49,"tv":201.18,"id":891555}]}]}
{"op":"mcm","clk":"11939712840","pt":1724401934776,"mc":[{"id":"1.232160907","rc":[{"batb":[[0,1.5,5],[1,1.49,5.05],[2,1.08,1.77]],"ltp":1.49,"tv":201.18,"id":891555}]}]}
{"op":"mcm","clk":"11939713027","pt":1724401938064,"mc":[{"id":"1.232160907","rc":[{"batb":[[0,1.49,5.05],[1,1.08,1.77],[2,1.04,1618.04]],"ltp":1.49,"tv":201.18,"id":891555}]}]}
{"op":"mcm","clk":"11939713284","pt":1724401941047,"mc":[{"id":"1.232160907","rc":[{"batb":[[0,1.5,5],[1,1.49,5.05],[2,1.08,1.77]],"ltp":1.49,"tv":201.18,"id":891555}]}]}
{"op":"mcm","clk":"11939713483","pt":1724401944390,"mc":[{"id":"1.232160907","rc":[{"batb":[[0,1.49,5.05],[1,1.08,1.77],[2,1.04,1618.04]],"ltp":1.49,"tv":201.18,"id":891555}]}]}
{"op":"mcm","clk":"11939713641","pt":1724401947421,"mc":[{"id":"1.232160907","rc":[{"batb":[[0,1.5,5],[1,1.49,5.05],[2,1.08,1.77]],"ltp":1.49,"tv":201.18,"id":891555}]}]}
{"op":"mcm","clk":"11939713900","pt":1724401950782,"mc":[{"id":"1.232160907","rc":[{"batb":[[0,1.49,5.05],[1,1.08,1.77],[2,1.04,1618.04]],"ltp":1.49,"tv":201.18,"id":891555}]}]}
{"op":"mcm","clk":"11939714224","pt":1724401953476,"mc":[{"id":"1.232160907","rc":[{"batb":[[0,1.5,5],[1,1.49,5.05],[2,1.08,1.77]],"ltp":1.49,"tv":201.18,"id":891555}]}]}
{"op":"mcm","clk":"11939714438","pt":1724401956975,"mc":[{"id":"1.232160907","rc":[{"batb":[[0,1.49,5.05],[1,1.08,1.77],[2,1.04,1618.04]],"ltp":1.49,"tv":201.18,"id":891555}]}]}
{"op":"mcm","clk":"11939714602","pt":1724401959905,"mc":[{"id":"1.232160907","rc":[{"batb":[[0,1.5,5],[1,1.49,5.05],[2,1.08,1.77]],"ltp":1.49,"tv":201.18,"id":891555}]}]}
{"op":"mcm","clk":"11939714816","pt":1724401963084,"mc":[{"id":"1.232160907","rc":[{"batb":[[0,1.49,5.05],[1,1.08,1.77],[2,1.04,1618.04]],"ltp":1.49,"tv":201.18,"id":891555}]}]}
{"op":"mcm","clk":"11939714984","pt":1724401965905,"mc":[{"id":"1.232160907","rc":[{"batb":[[0,1.5,5],[1,1.49,5.05],[2,1.08,1.77]],"ltp":1.49,"tv":201.18,"id":891555}]}]}
{"op":"mcm","clk":"11939715290","pt":1724401969305,"mc":[{"id":"1.232160907","rc":[{"batb":[[0,1.49,5.05],[1,1.08,1.77],[2,1.04,1618.04]],"ltp":1.49,"tv":201.18,"id":891555}]}]}
{"op":"mcm","clk":"11939715485","pt":1724401972484,"mc":[{"id":"1.232160907","rc":[{"batb":[[0,1.5,5],[1,1.49,5.05],[2,1.08,1.77]],"ltp":1.49,"tv":201.18,"id":891555}]}]}
{"op":"mcm","clk":"11939715624","pt":1724401975683,"mc":[{"id":"1.232160907","rc":[{"batb":[[0,1.49,5.05],[1,1.08,1.77],[2,1.04,1618.04]],"ltp":1.49,"tv":201.18,"id":891555}]}]}
{"op":"mcm","clk":"11939715841","pt":1724401978806,"mc":[{"id":"1.232160907","rc":[{"batb":[[0,1.5,5],[1,1.49,5.05],[2,1.08,1.77]],"ltp":1.49,"tv":201.18,"id":891555}]}]}
{"op":"mcm","clk":"11939716104","pt":1724401982204,"mc":[{"id":"1.232160907","rc":[{"batb":[[0,1.49,5.05],[1,1.08,1.77],[2,1.04,1618.04]],"ltp":1.49,"tv":201.18,"id":891555}]}]}
{"op":"mcm","clk":"11939716302","pt":1724401985193,"mc":[{"id":"1.232160907","rc":[{"batb":[[0,1.5,5],[1,1.49,5.05],[2,1.08,1.77]],"ltp":1.49,"tv":201.18,"id":891555}]}]}
{"op":"mcm","clk":"11939716572","pt":1724401988490,"mc":[{"id":"1.232160907","rc":[{"batb":[[0,1.49,5.05],[1,1.08,1.77],[2,1.04,1618.04]],"ltp":1.49,"tv":201.18,"id":891555}]}]}
{"op":"mcm","clk":"11939716737","pt":1724401991013,"mc":[{"id":"1.232160907","rc":[{"batb":[[0,1.5,5],[1,1.49,5.05],[2,1.08,1.77]],"ltp":1.49,"tv":201.18,"id":891555}]}]}
{"op":"mcm","clk":"11939716964","pt":1724401994311,"mc":[{"id":"1.232160907","rc":[{"batb":[[0,1.49,5.05],[1,1.08,1.77],[2,1.04,1618.04]],"ltp":1.49,"tv":201.18,"id":891555}]}]}
{"op":"mcm","clk":"11939717154","pt":1724401997534,"mc":[{"id":"1.232160907","rc":[{"batb":[[0,1.5,5],[1,1.49,5.05],[2,1.08,1.77]],"ltp":1.49,"tv":201.18,"id":891555}]}]}
{"op":"mcm","clk":"11939717409","pt":1724402000925,"mc":[{"id":"1.232160907","rc":[{"batb":[[0,1.49,5.05],[1,1.08,1.77],[2,1.04,1618.04]],"ltp":1.49,"tv":201.18,"id":891555}]}]}
{"op":"mcm","clk":"11939717701","pt":1724402003506,"mc":[{"id":"1.232160907","rc":[{"batb":[[0,1.5,5],[1,1.49,5.05],[2,1.08,1.77]],"ltp":1.49,"tv":201.18,"id":891555}]}]}
{"op":"mcm","clk":"11939717861","pt":1724402006802,"mc":[{"id":"1.232160907","rc":[{"batb":[[0,1.49,5.05],[1,1.08,1.77],[2,1.04,1618.04]],"ltp":1.49,"tv":201.18,"id":891555}]}]}
{"op":"mcm","clk":"11939718008","pt":1724402009416,"mc":[{"id":"1.232160907","rc":[{"batb":[[0,1.5,5],[1,1.49,5.05],[2,1.08,1.77]],"ltp":1.49,"tv":201.18,"id":891555}]}]}
{"op":"mcm","clk":"11939718360","pt":1724402012654,"mc":[{"id":"1.232160907","rc":[{"batb":[[0,1.49,5.05],[1,1.08,1.77],[2,1.04,1618.04]],"ltp":1.49,"tv":201.18,"id":891555}]}]}
{"op":"mcm","clk":"11939718797","pt":1724402019742,"mc":[{"id":"1.232160907","rc":[{"batb":[[0,1.5,5],[1,1.49,5.05],[2,1.08,1.77]],"ltp":1.49,"tv":201.18,"id":891555}]}]}
{"op":"mcm","clk":"11939719035","pt":1724402023146,"mc":[{"id":"1.232160907","rc":[{"batb":[[0,1.49,5.05],[1,1.08,1.77],[2,1.04,1618.04]],"ltp":1.49,"tv":201.18,"id":891555}]}]}
{"op":"mcm","clk":"11939719245","pt":1724402026430,"mc":[{"id":"1.232160907","rc":[{"batb":[[0,1.5,5],[1,1.49,5.05],[2,1.08,1.77]],"ltp":1.49,"tv":201.18,"id":891555}]}]}
{"op":"mcm","clk":"11939719476","pt":1724402029766,"mc":[{"id":"1.232160907","rc":[{"batb":[[0,1.49,5.05],[1,1.08,1.77],[2,1.04,1618.04]],"ltp":1.49,"tv":201.18,"id":891555}]}]}
{"op":"mcm","clk":"11939719607","pt":1724402032331,"mc":[{"id":"1.232160907","rc":[{"batb":[[0,1.5,5],[1,1.49,5.05],[2,1.08,1.77]],"ltp":1.49,"tv":201.18,"id":891555}]}]}
{"op":"mcm","clk":"11939719835","pt":1724402035863,"mc":[{"id":"1.232160907","rc":[{"batb":[[0,1.49,5.05],[1,1.08,1.77],[2,1.04,1618.04]],"ltp":1.49,"tv":201.18,"id":891555}]}]}
{"op":"mcm","clk":"11939720137","pt":1724402041663,"mc":[{"id":"1.232160907","rc":[{"batb":[[0,1.5,5],[1,1.49,5.05],[2,1.08,1.77]],"ltp":1.49,"tv":201.18,"id":891555}]}]}
{"op":"mcm","clk":"11939720490","pt":1724402045275,"mc":[{"id":"1.232160907","rc":[{"batb":[[0,1.49,5.05],[1,1.08,1.77],[2,1.04,1618.04]],"ltp":1.49,"tv":201.18,"id":891555}]}]}
{"op":"mcm","clk":"11939720709","pt":1724402048362,"mc":[{"id":"1.232160907","rc":[{"batb":[[0,1.5,5],[1,1.49,5.05],[2,1.08,1.77]],"ltp":1.49,"tv":201.18,"id":891555}]}]}
{"op":"mcm","clk":"11939720918","pt":1724402051562,"mc":[{"id":"1.232160907","rc":[{"batb":[[0,1.49,5.05],[1,1.08,1.77],[2,1.04,1618.04]],"ltp":1.49,"tv":201.18,"id":891555}]}]}
{"op":"mcm","clk":"11939721080","pt":1724402053980,"mc":[{"id":"1.232160907","rc":[{"batb":[[0,1.5,5],[1,1.49,5.05],[2,1.08,1.77]],"ltp":1.49,"tv":201.18,"id":891555}]}]}
{"op":"mcm","clk":"11939721317","pt":1724402057163,"mc":[{"id":"1.232160907","rc":[{"batb":[[0,1.49,5.05],[1,1.08,1.77],[2,1.04,1618.04]],"ltp":1.49,"tv":201.18,"id":891555}]}]}
{"op":"mcm","clk":"11939721451","pt":1724402059578,"mc":[{"id":"1.232160907","rc":[{"batb":[[0,1.5,5],[1,1.49,5.05],[2,1.08,1.77]],"ltp":1.49,"tv":201.18,"id":891555}]}]}
{"op":"mcm","clk":"11939721698","pt":1724402062973,"mc":[{"id":"1.232160907","rc":[{"batb":[[0,1.49,5.05],[1,1.08,1.77],[2,1.04,1618.04]],"ltp":1.49,"tv":201.18,"id":891555}]}]}
{"op":"mcm","clk":"11939721907","pt":1724402066368,"mc":[{"id":"1.232160907","rc":[{"batb":[[0,1.5,5],[1,1.49,5.05],[2,1.08,1.77]],"ltp":1.49,"tv":201.18,"id":891555}]}]}
{"op":"mcm","clk":"11939722128","pt":1724402069698,"mc":[{"id":"1.232160907","rc":[{"batb":[[0,1.49,5.05],[1,1.08,1.77],[2,1.04,1618.04]],"ltp":1.49,"tv":201.18,"id":891555}]}]}
{"op":"mcm","clk":"11939722298","pt":1724402072367,"mc":[{"id":"1.232160907","rc":[{"batb":[[0,1.5,5],[1,1.49,5.05],[2,1.08,1.77]],"ltp":1.49,"tv":201.18,"id":891555}]}]}
{"op":"mcm","clk":"11939722530","pt":1724402075986,"mc":[{"id":"1.232160907","rc":[{"batb":[[0,1.49,5.05],[1,1.08,1.77],[2,1.04,1618.04]],"ltp":1.49,"tv":201.18,"id":891555}]}]}
{"op":"mcm","clk":"11939722788","pt":1724402079078,"mc":[{"id":"1.232160907","rc":[{"batb":[[0,1.5,5],[1,1.49,5.05],[2,1.08,1.77]],"ltp":1.49,"tv":201.18,"id":891555}]}]}
{"op":"mcm","clk":"11939723012","pt":1724402082674,"mc":[{"id":"1.232160907","rc":[{"batb":[[0,1.49,5.05],[1,1.08,1.77],[2,1.04,1618.04]],"ltp":1.49,"tv":201.18,"id":891555}]}]}
{"op":"mcm","clk":"11939723169","pt":1724402085289,"mc":[{"id":"1.232160907","rc":[{"batb":[[0,1.5,5],[1,1.49,5.05],[2,1.08,1.77]],"ltp":1.49,"tv":201.18,"id":891555}]}]}
{"op":"mcm","clk":"11939723353","pt":1724402088612,"mc":[{"id":"1.232160907","rc":[{"batb":[[0,1.49,5.05],[1,1.08,1.77],[2,1.04,1618.04]],"ltp":1.49,"tv":201.18,"id":891555}]}]}
{"op":"mcm","clk":"11939723559","pt":1724402091699,"mc":[{"id":"1.232160907","rc":[{"batb":[[0,1.5,5],[1,1.49,5.05],[2,1.08,1.77]],"ltp":1.49,"tv":201.18,"id":891555}]}]}
{"op":"mcm","clk":"11939723737","pt":1724402094988,"mc":[{"id":"1.232160907","rc":[{"batb":[[0,1.49,5.05],[1,1.08,1.77],[2,1.04,1618.04]],"ltp":1.49,"tv":201.18,"id":891555}]}]}
{"op":"mcm","clk":"11939723907","pt":1724402097813,"mc":[{"id":"1.232160907","rc":[{"batb":[[0,1.5,5],[1,1.49,5.05],[2,1.08,1.77]],"ltp":1.49,"tv":201.18,"id":891555}]}]}
{"op":"mcm","clk":"11939724118","pt":1724402101323,"mc":[{"id":"1.232160907","rc":[{"batb":[[0,1.49,5.05],[1,1.08,1.77],[2,1.04,1618.04]],"ltp":1.49,"tv":201.18,"id":891555}]}]}
{"op":"mcm","clk":"11939724331","pt":1724402104923,"mc":[{"id":"1.232160907","rc":[{"batb":[[0,1.5,5],[1,1.49,5.05],[2,1.08,1.77]],"ltp":1.49,"tv":201.18,"id":891555}]}]}
{"op":"mcm","clk":"11939724512","pt":1724402108109,"mc":[{"id":"1.232160907","rc":[{"batb":[[0,1.49,5.05],[1,1.08,1.77],[2,1.04,1618.04]],"ltp":1.49,"tv":201.18,"id":891555}]}]}
{"op":"mcm","clk":"11939725077","pt":1724402116729,"mc":[{"id":"1.232160907","rc":[{"batb":[[0,1.5,5],[1,1.49,5.05],[2,1.08,1.77]],"ltp":1.49,"tv":201.18,"id":891555}]}]}
{"op":"mcm","clk":"11939725271","pt":1724402120222,"mc":[{"id":"1.232160907","rc":[{"batb":[[0,1.49,5.05],[1,1.08,1.77],[2,1.04,1618.04]],"ltp":1.49,"tv":201.18,"id":891555}]}]}
{"op":"mcm","clk":"11939725494","pt":1724402123711,"mc":[{"id":"1.232160907","rc":[{"batb":[[0,1.5,5],[1,1.49,5.05],[2,1.08,1.77]],"ltp":1.49,"tv":201.18,"id":891555}]}]}
{"op":"mcm","clk":"11939725657","pt":1724402127147,"mc":[{"id":"1.232160907","rc":[{"batb":[[0,1.49,5.05],[1,1.08,1.77],[2,1.04,1618.04]],"ltp":1.49,"tv":201.18,"id":891555}]}]}
{"op":"mcm","clk":"11939725765","pt":1724402129416,"mc":[{"id":"1.232160907","rc":[{"batb":[[0,1.5,5],[1,1.49,5.05],[2,1.08,1.77]],"ltp":1.49,"tv":201.18,"id":891555}]}]}
{"op":"mcm","clk":"11939725929","pt":1724402132866,"mc":[{"id":"1.232160907","rc":[{"batb":[[0,1.49,5.05],[1,1.08,1.77],[2,1.04,1618.04]],"ltp":1.49,"tv":201.18,"id":891555}]}]}
{"op":"mcm","clk":"11939726037","pt":1724402135175,"mc":[{"id":"1.232160907","rc":[{"batb":[[0,1.5,5],[1,1.49,5.05],[2,1.08,1.77]],"ltp":1.49,"tv":201.18,"id":891555}]}]}
{"op":"mcm","clk":"11939726206","pt":1724402138472,"mc":[{"id":"1.232160907","rc":[{"batb":[[0,1.49,5.05],[1,1.08,1.77],[2,1.04,1618.04]],"ltp":1.49,"tv":201.18,"id":891555}]}]}
{"op":"mcm","clk":"11939726338","pt":1724402140791,"mc":[{"id":"1.232160907","rc":[{"batb":[[0,1.5,5],[1,1.49,5.05],[2,1.08,1.77]],"ltp":1.49,"tv":201.18,"id":891555}]}]}
{"op":"mcm","clk":"11939726530","pt":1724402143980,"mc":[{"id":"1.232160907","rc":[{"batb":[[0,1.49,5.05],[1,1.08,1.77],[2,1.04,1618.04]],"ltp":1.49,"tv":201.18,"id":891555}]}]}
{"op":"mcm","clk":"11939726646","pt":1724402146350,"mc":[{"id":"1.232160907","rc":[{"batb":[[0,1.5,5],[1,1.49,5.05],[2,1.08,1.77]],"ltp":1.49,"tv":201.18,"id":891555}]}]}
{"op":"mcm","clk":"11939726778","pt":1724402149579,"mc":[{"id":"1.232160907","rc":[{"batb":[[0,1.49,5.05],[1,1.08,1.77],[2,1.04,1618.04]],"ltp":1.49,"tv":201.18,"id":891555}]}]}
{"op":"mcm","clk":"11939726883","pt":1724402151997,"mc":[{"id":"1.232160907","rc":[{"batb":[[0,1.5,5],[1,1.49,5.05],[2,1.08,1.77]],"ltp":1.49,"tv":201.18,"id":891555}]}]}
{"op":"mcm","clk":"11939727041","pt":1724402155179,"mc":[{"id":"1.232160907","rc":[{"batb":[[0,1.49,5.05],[1,1.08,1.77],[2,1.04,1618.04]],"ltp":1.49,"tv":201.18,"id":891555}]}]}
{"op":"mcm","clk":"11939727164","pt":1724402157858,"mc":[{"id":"1.232160907","rc":[{"batb":[[0,1.5,5],[1,1.49,5.05],[2,1.08,1.77]],"ltp":1.49,"tv":201.18,"id":891555}]}]}
{"op":"mcm","clk":"11939727412","pt":1724402161177,"mc":[{"id":"1.232160907","rc":[{"batb":[[0,1.49,5.05],[1,1.08,1.77],[2,1.04,1618.04]],"ltp":1.49,"tv":201.18,"id":891555}]}]}
{"op":"mcm","clk":"11939727610","pt":1724402164175,"mc":[{"id":"1.232160907","rc":[{"batb":[[0,1.5,5],[1,1.49,5.05],[2,1.08,1.77]],"ltp":1.49,"tv":201.18,"id":891555}]}]}
{"op":"mcm","clk":"11939727827","pt":1724402167480,"mc":[{"id":"1.232160907","rc":[{"batb":[[0,1.49,5.05],[1,1.08,1.77],[2,1.04,1618.04]],"ltp":1.49,"tv":201.18,"id":891555}]}]}
{"op":"mcm","clk":"11939728104","pt":1724402172094,"mc":[{"id":"1.232160907","rc":[{"batb":[[0,1.5,5],[1,1.49,5.05],[2,1.08,1.77]],"ltp":1.49,"tv":201.18,"id":891555}]}]}
{"op":"mcm","clk":"11939728310","pt":1724402175483,"mc":[{"id":"1.232160907","rc":[{"batb":[[0,1.49,5.05],[1,1.08,1.77],[2,1.04,1618.04]],"ltp":1.49,"tv":201.18,"id":891555}]}]}
{"op":"mcm","clk":"11939728541","pt":1724402178779,"mc":[{"id":"1.232160907","rc":[{"batb":[[0,1.5,5],[1,1.49,5.05],[2,1.08,1.77]],"ltp":1.49,"tv":201.18,"id":891555}]}]}
{"op":"mcm","clk":"11939728769","pt":1724402182095,"mc":[{"id":"1.232160907","rc":[{"batb":[[0,1.49,5.05],[1,1.08,1.77],[2,1.04,1618.04]],"ltp":1.49,"tv":201.18,"id":891555}]}]}
{"op":"mcm","clk":"11939728928","pt":1724402184273,"mc":[{"id":"1.232160907","rc":[{"batb":[[0,1.5,5],[1,1.49,5.05],[2,1.08,1.77]],"ltp":1.49,"tv":201.18,"id":891555}]}]}
{"op":"mcm","clk":"11939729112","pt":1724402187514,"mc":[{"id":"1.232160907","rc":[{"batb":[[0,1.49,5.05],[1,1.08,1.77],[2,1.04,1618.04]],"ltp":1.49,"tv":201.18,"id":891555}]}]}
{"op":"mcm","clk":"11939729278","pt":1724402190294,"mc":[{"id":"1.232160907","rc":[{"batb":[[0,1.5,5],[1,1.49,5.05],[2,1.08,1.77]],"ltp":1.49,"tv":201.18,"id":891555}]}]}
{"op":"mcm","clk":"11939729500","pt":1724402193624,"mc":[{"id":"1.232160907","rc":[{"batb":[[0,1.49,5.05],[1,1.08,1.77],[2,1.04,1618.04]],"ltp":1.49,"tv":201.18,"id":891555}]}]}
{"op":"mcm","clk":"11939729691","pt":1724402197010,"mc":[{"id":"1.232160907","rc":[{"batb":[[0,1.5,5],[1,1.49,5.05],[2,1.08,1.77]],"ltp":1.49,"tv":201.18,"id":891555}]}]}
{"op":"mcm","clk":"11939729925","pt":1724402200296,"mc":[{"id":"1.232160907","rc":[{"batb":[[0,1.49,5.05],[1,1.08,1.77],[2,1.04,1618.04]],"ltp":1.49,"tv":201.18,"id":891555}]}]}
{"op":"mcm","clk":"11939730049","pt":1724402202510,"mc":[{"id":"1.232160907","rc":[{"batb":[[0,1.5,5],[1,1.49,5.05],[2,1.08,1.77]],"ltp":1.49,"tv":201.18,"id":891555}]}]}
{"op":"mcm","clk":"11939730275","pt":1724402205896,"mc":[{"id":"1.232160907","rc":[{"batb":[[0,1.49,5.05],[1,1.08,1.77],[2,1.04,1618.04]],"ltp":1.49,"tv":201.18,"id":891555}]}]}
{"op":"mcm","clk":"11939730529","pt":1724402210916,"mc":[{"id":"1.232160907","rc":[{"batb":[[0,1.5,5],[1,1.49,5.05],[2,1.08,1.77]],"ltp":1.49,"tv":201.18,"id":891555}]}]}
{"op":"mcm","clk":"11939730690","pt":1724402214266,"mc":[{"id":"1.232160907","rc":[{"batb":[[0,1.49,5.05],[1,1.08,1.77],[2,1.04,1618.04]],"ltp":1.49,"tv":201.18,"id":891555}]}]}
{"op":"mcm","clk":"11939730939","pt":1724402219921,"mc":[{"id":"1.232160907","rc":[{"batb":[[0,1.5,5],[1,1.49,5.05],[2,1.08,1.77]],"ltp":1.49,"tv":201.18,"id":891555}]}]}
{"op":"mcm","clk":"11939731148","pt":1724402223416,"mc":[{"id":"1.232160907","rc":[{"batb":[[0,1.49,5.05],[1,1.08,1.77],[2,1.04,1618.04]],"ltp":1.49,"tv":201.18,"id":891555}]}]}
{"op":"mcm","clk":"11939731347","pt":1724402227628,"mc":[{"id":"1.232160907","rc":[{"batb":[[0,1.5,5],[1,1.49,5.05],[2,1.08,1.77]],"ltp":1.49,"tv":201.18,"id":891555}]}]}
{"op":"mcm","clk":"11939731516","pt":1724402230852,"mc":[{"id":"1.232160907","rc":[{"batb":[[0,1.49,5.05],[1,1.08,1.77],[2,1.04,1618.04]],"ltp":1.49,"tv":201.18,"id":891555}]}]}
{"op":"mcm","clk":"11939731727","pt":1724402233941,"mc":[{"id":"1.232160907","rc":[{"batb":[[0,1.5,5],[1,1.49,5.05],[2,1.08,1.77]],"ltp":1.49,"tv":201.18,"id":891555}]}]}
{"op":"mcm","clk":"11939731910","pt":1724402237163,"mc":[{"id":"1.232160907","rc":[{"batb":[[0,1.49,5.05],[1,1.08,1.77],[2,1.04,1618.04]],"ltp":1.49,"tv":201.18,"id":891555}]}]}
{"op":"mcm","clk":"11939732038","pt":1724402239370,"mc":[{"id":"1.232160907","rc":[{"batb":[[0,1.5,5],[1,1.49,5.05],[2,1.08,1.77]],"ltp":1.49,"tv":201.18,"id":891555}]}]}
{"op":"mcm","clk":"11939732225","pt":1724402242553,"mc":[{"id":"1.232160907","rc":[{"batb":[[0,1.49,5.05],[1,1.08,1.77],[2,1.04,1618.04]],"ltp":1.49,"tv":201.18,"id":891555}]}]}
{"op":"mcm","clk":"11939732514","pt":1724402247866,"mc":[{"id":"1.232160907","rc":[{"batb":[[0,1.5,5],[1,1.49,5.05],[2,1.08,1.77]],"ltp":1.49,"tv":201.18,"id":891555}]}]}
{"op":"mcm","clk":"11939732708","pt":1724402251158,"mc":[{"id":"1.232160907","rc":[{"batb":[[0,1.49,5.05],[1,1.08,1.77],[2,1.04,1618.04]],"ltp":1.49,"tv":201.18,"id":891555}]}]}
{"op":"mcm","clk":"11939732925","pt":1724402255583,"mc":[{"id":"1.232160907","rc":[{"batb":[[0,1.5,5],[1,1.49,5.05],[2,1.08,1.77]],"ltp":1.49,"tv":201.18,"id":891555}]}]}
{"op":"mcm","clk":"11939733066","pt":1724402258866,"mc":[{"id":"1.232160907","rc":[{"batb":[[0,1.49,5.05],[1,1.08,1.77],[2,1.04,1618.04]],"ltp":1.49,"tv":201.18,"id":891555}]}]}
{"op":"mcm","clk":"11939733293","pt":1724402263586,"mc":[{"id":"1.232160907","rc":[{"batb":[[0,1.5,5],[1,1.49,5.05],[2,1.08,1.77]],"ltp":1.49,"tv":201.18,"id":891555}]}]}
{"op":"mcm","clk":"11939733492","pt":1724402267076,"mc":[{"id":"1.232160907","rc":[{"batb":[[0,1.49,5.05],[1,1.08,1.77],[2,1.04,1618.04]],"ltp":1.49,"tv":201.18,"id":891555}]}]}
{"op":"mcm","clk":"11939733677","pt":1724402270777,"mc":[{"id":"1.232160907","rc":[{"batb":[[0,1.5,5],[1,1.49,5.05],[2,1.08,1.77]],"ltp":1.49,"tv":201.18,"id":891555}]}]}
{"op":"mcm","clk":"11939733837","pt":1724402274204,"mc":[{"id":"1.232160907","rc":[{"batb":[[0,1.49,5.05],[1,1.08,1.77],[2,1.04,1618.04]],"ltp":1.49,"tv":201.18,"id":891555}]}]}
{"op":"mcm","clk":"11939734027","pt":1724402278608,"mc":[{"id":"1.232160907","rc":[{"batb":[[0,1.5,5],[1,1.49,5.05],[2,1.08,1.77]],"ltp":1.49,"tv":201.18,"id":891555}]}]}
{"op":"mcm","clk":"11939734216","pt":1724402282103,"mc":[{"id":"1.232160907","rc":[{"batb":[[0,1.49,5.05],[1,1.08,1.77],[2,1.04,1618.04]],"ltp":1.49,"tv":201.18,"id":891555}]}]}
{"op":"mcm","clk":"11939734368","pt":1724402284420,"mc":[{"id":"1.232160907","rc":[{"batb":[[0,1.5,5],[1,1.49,5.05],[2,1.08,1.77]],"ltp":1.49,"tv":201.18,"id":891555}]}]}
{"op":"mcm","clk":"11939734551","pt":1724402287718,"mc":[{"id":"1.232160907","rc":[{"batb":[[0,1.49,5.05],[1,1.08,1.77],[2,1.04,1618.04]],"ltp":1.49,"tv":201.18,"id":891555}]}]}
{"op":"mcm","clk":"11939734994","pt":1724402293831,"mc":[{"id":"1.232160907","rc":[{"batb":[[0,1.5,5],[1,1.49,5.05],[2,1.08,1.77]],"ltp":1.49,"tv":201.18,"id":891555}]}]}
{"op":"mcm","clk":"11939735202","pt":1724402297015,"mc":[{"id":"1.232160907","rc":[{"batb":[[0,1.49,5.05],[1,1.08,1.77],[2,1.04,1618.04]],"ltp":1.49,"tv":201.18,"id":891555}]}]}
{"op":"mcm","clk":"11939735455","pt":1724402301131,"mc":[{"id":"1.232160907","rc":[{"batb":[[0,1.5,5],[1,1.49,5.05],[2,1.08,1.77]],"ltp":1.49,"tv":201.18,"id":891555}]}]}
{"op":"mcm","clk":"11939735653","pt":1724402304329,"mc":[{"id":"1.232160907","rc":[{"batb":[[0,1.49,5.05],[1,1.08,1.77],[2,1.04,1618.04]],"ltp":1.49,"tv":201.18,"id":891555}]}]}
{"op":"mcm","clk":"11939735796","pt":1724402306810,"mc":[{"id":"1.232160907","rc":[{"batb":[[0,1.5,5],[1,1.49,5.05],[2,1.08,1.77]],"ltp":1.49,"tv":201.18,"id":891555}]}]}
{"op":"mcm","clk":"11939735951","pt":1724402310140,"mc":[{"id":"1.232160907","rc":[{"batb":[[0,1.49,5.05],[1,1.08,1.77],[2,1.04,1618.04]],"ltp":1.49,"tv":201.18,"id":891555}]}]}
{"op":"mcm","clk":"11939736082","pt":1724402312724,"mc":[{"id":"1.232160907","rc":[{"batb":[[0,1.5,5],[1,1.49,5.05],[2,1.08,1.77]],"ltp":1.49,"tv":201.18,"id":891555}]}]}
{"op":"mcm","clk":"11939736310","pt":1724402316124,"mc":[{"id":"1.232160907","rc":[{"batb":[[0,1.49,5.05],[1,1.08,1.77],[2,1.04,1618.04]],"ltp":1.49,"tv":201.18,"id":891555}]}]}
{"op":"mcm","clk":"11939736471","pt":1724402319046,"mc":[{"id":"1.232160907","rc":[{"batb":[[0,1.5,5],[1,1.49,5.05],[2,1.08,1.77]],"ltp":1.49,"tv":201.18,"id":891555}]}]}
{"op":"mcm","clk":"11939736676","pt":1724402322454,"mc":[{"id":"1.232160907","rc":[{"batb":[[0,1.49,5.05],[1,1.08,1.77],[2,1.04,1618.04]],"ltp":1.49,"tv":201.18,"id":891555}]}]}
{"op":"mcm","clk":"11939737063","pt":1724402329044,"mc":[{"id":"1.232160907","rc":[{"batb":[[0,1.5,5],[1,1.49,5.05],[2,1.08,1.77]],"ltp":1.49,"tv":201.18,"id":891555}]}]}
{"op":"mcm","clk":"11939737093","pt":1724402329659,"mc":[{"id":"1.232160907","rc":[{"batb":[[1,1.08,1.77],[2,1.04,1618.04]],"ltp":1.49,"tv":191.96,"id":144197}]}]}
{"op":"mcm","clk":"11939737192","pt":1724402331461,"mc":[{"id":"1.232160907","rc":[{"batb":[[0,1.08,1.77],[1,1.04,1618.04],[2,1.03,2339.53]],"ltp":1.49,"tv":191.96,"id":144197},{"batl":[[0,8,3.54],[1,11.5,0.69],[2,11.5,0]],"ltp":1.49,"tv":201.18,"id":891555}]}]}
{"op":"mcm","clk":"11939737231","pt":1724402332448,"mc":[{"id":"1.232160907","rc":[{"batb":[[0,1.49,5.05],[1,1.08,1.77],[2,1.04,1618.04]],"ltp":1.49,"tv":201.18,"id":891555}]}]}
{"op":"mcm","clk":"11939737347","pt":1724402334661,"mc":[{"id":"1.232160907","rc":[{"batb":[[0,1.5,5],[1,1.49,5.05],[2,1.08,1.77]],"ltp":1.49,"tv":201.18,"id":891555}]}]}
{"op":"mcm","clk":"11939737540","pt":1724402338178,"mc":[{"id":"1.232160907","rc":[{"batb":[[0,1.49,5.05],[1,1.08,1.77],[2,1.04,1618.04]],"ltp":1.49,"tv":201.18,"id":891555}]}]}
{"op":"mcm","clk":"11939737756","pt":1724402341157,"mc":[{"id":"1.232160907","rc":[{"batb":[[0,1.5,5],[1,1.49,5.05],[2,1.08,1.77]],"ltp":1.49,"tv":201.18,"id":891555}]}]}
{"op":"mcm","clk":"11939737962","pt":1724402344559,"mc":[{"id":"1.232160907","rc":[{"batb":[[0,1.49,5.05],[1,1.08,1.77],[2,1.04,1618.04]],"ltp":1.49,"tv":201.18,"id":891555}]}]}
{"op":"mcm","clk":"11939738117","pt":1724402347077,"mc":[{"id":"1.232160907","rc":[{"batb":[[0,1.5,5],[1,1.49,5.05],[2,1.08,1.77]],"ltp":1.49,"tv":201.18,"id":891555}]}]}
{"op":"mcm","clk":"11939738312","pt":1724402350277,"mc":[{"id":"1.232160907","rc":[{"batb":[[0,1.49,5.05],[1,1.08,1.77],[2,1.04,1618.04]],"ltp":1.49,"tv":201.18,"id":891555}]}]}
{"op":"mcm","clk":"11939738524","pt":1724402353568,"mc":[{"id":"1.232160907","rc":[{"batb":[[0,1.5,5],[1,1.49,5.05],[2,1.08,1.77]],"ltp":1.49,"tv":201.18,"id":891555}]}]}
{"op":"mcm","clk":"11939738737","pt":1724402356872,"mc":[{"id":"1.232160907","rc":[{"batb":[[0,1.49,5.05],[1,1.08,1.77],[2,1.04,1618.04]],"ltp":1.49,"tv":201.18,"id":891555}]}]}
{"op":"mcm","clk":"11939738864","pt":1724402359279,"mc":[{"id":"1.232160907","rc":[{"batb":[[0,1.5,5],[1,1.49,5.05],[2,1.08,1.77]],"ltp":1.49,"tv":201.18,"id":891555}]}]}
{"op":"mcm","clk":"11939739045","pt":1724402362584,"mc":[{"id":"1.232160907","rc":[{"batb":[[0,1.49,5.05],[1,1.08,1.77],[2,1.04,1618.04]],"ltp":1.49,"tv":201.18,"id":891555}]}]}
{"op":"mcm","clk":"11939739189","pt":1724402364907,"mc":[{"id":"1.232160907","rc":[{"batb":[[0,1.5,5],[1,1.49,5.05],[2,1.08,1.77]],"ltp":1.49,"tv":201.18,"id":891555}]}]}
{"op":"mcm","clk":"11939739392","pt":1724402368203,"mc":[{"id":"1.232160907","rc":[{"batb":[[0,1.49,5.05],[1,1.08,1.77],[2,1.04,1618.04]],"ltp":1.49,"tv":201.18,"id":891555}]}]}
{"op":"mcm","clk":"11939739701","pt":1724402373698,"mc":[{"id":"1.232160907","rc":[{"batb":[[0,1.5,5],[1,1.49,5.05],[2,1.08,1.77]],"ltp":1.49,"tv":201.18,"id":891555}]}]}
{"op":"mcm","clk":"11939739880","pt":1724402376897,"mc":[{"id":"1.232160907","rc":[{"batb":[[0,1.49,5.05],[1,1.08,1.77],[2,1.04,1618.04]],"ltp":1.49,"tv":201.18,"id":891555}]}]}
{"op":"mcm","clk":"11939740189","pt":1724402381493,"mc":[{"id":"1.232160907","rc":[{"batb":[[0,1.5,5],[1,1.49,5.05],[2,1.08,1.77]],"ltp":1.49,"tv":201.18,"id":891555}]}]}
{"op":"mcm","clk":"11939740437","pt":1724402384793,"mc":[{"id":"1.232160907","rc":[{"batb":[[0,1.49,5.05],[1,1.08,1.77],[2,1.04,1618.04]],"ltp":1.49,"tv":201.18,"id":891555}]}]}
{"op":"mcm","clk":"11939740584","pt":1724402387430,"mc":[{"id":"1.232160907","rc":[{"batb":[[0,1.5,5],[1,1.49,5.05],[2,1.08,1.77]],"ltp":1.49,"tv":201.18,"id":891555}]}]}
{"op":"mcm","clk":"11939740787","pt":1724402390913,"mc":[{"id":"1.232160907","rc":[{"batb":[[0,1.49,5.05],[1,1.08,1.77],[2,1.04,1618.04]],"ltp":1.49,"tv":201.18,"id":891555}]}]}
{"op":"mcm","clk":"11939741077","pt":1724402396036,"mc":[{"id":"1.232160907","rc":[{"batb":[[0,1.5,5],[1,1.49,5.05],[2,1.08,1.77]],"ltp":1.49,"tv":201.18,"id":891555}]}]}
{"op":"mcm","clk":"11939741290","pt":1724402399426,"mc":[{"id":"1.232160907","rc":[{"batb":[[0,1.49,5.05],[1,1.08,1.77],[2,1.04,1618.04]],"ltp":1.49,"tv":201.18,"id":891555}]}]}
{"op":"mcm","clk":"11939741508","pt":1724402402433,"mc":[{"id":"1.232160907","rc":[{"batb":[[0,1.5,5],[1,1.49,5.05],[2,1.08,1.77]],"ltp":1.49,"tv":201.18,"id":891555}]}]}
{"op":"mcm","clk":"11939741790","pt":1724402405928,"mc":[{"id":"1.232160907","rc":[{"batb":[[0,1.49,5.05],[1,1.08,1.77],[2,1.04,1618.04]],"ltp":1.49,"tv":201.18,"id":891555}]}]}
{"op":"mcm","clk":"11939741969","pt":1724402408142,"mc":[{"id":"1.232160907","rc":[{"batb":[[0,1.5,5],[1,1.49,5.05],[2,1.08,1.77]],"ltp":1.49,"tv":201.18,"id":891555}]}]}
{"op":"mcm","clk":"11939742225","pt":1724402411546,"mc":[{"id":"1.232160907","rc":[{"batb":[[0,1.49,5.05],[1,1.08,1.77],[2,1.04,1618.04]],"ltp":1.49,"tv":201.18,"id":891555}]}]}
{"op":"mcm","clk":"11939742370","pt":1724402413714,"mc":[{"id":"1.232160907","rc":[{"batb":[[0,1.5,5],[1,1.49,5.05],[2,1.08,1.77]],"ltp":1.49,"tv":201.18,"id":891555}]}]}
{"op":"mcm","clk":"11939742586","pt":1724402417252,"mc":[{"id":"1.232160907","rc":[{"batb":[[0,1.49,5.05],[1,1.08,1.77],[2,1.04,1618.04]],"ltp":1.49,"tv":201.18,"id":891555}]}]}
{"op":"mcm","clk":"11939742734","pt":1724402419636,"mc":[{"id":"1.232160907","rc":[{"batb":[[0,1.5,5],[1,1.49,5.05],[2,1.08,1.77]],"ltp":1.49,"tv":201.18,"id":891555}]}]}
{"op":"mcm","clk":"11939742937","pt":1724402422961,"mc":[{"id":"1.232160907","rc":[{"batb":[[0,1.49,5.05],[1,1.08,1.77],[2,1.04,1618.04]],"ltp":1.49,"tv":201.18,"id":891555}]}]}
{"op":"mcm","clk":"11939743119","pt":1724402425529,"mc":[{"id":"1.232160907","rc":[{"batb":[[0,1.5,5],[1,1.49,5.05],[2,1.08,1.77]],"ltp":1.49,"tv":201.18,"id":891555}]}]}
{"op":"mcm","clk":"11939743340","pt":1724402429136,"mc":[{"id":"1.232160907","rc":[{"batb":[[0,1.49,5.05],[1,1.08,1.77],[2,1.04,1618.04]],"ltp":1.49,"tv":201.18,"id":891555}]}]}
{"op":"mcm","clk":"11939743508","pt":1724402431745,"mc":[{"id":"1.232160907","rc":[{"batb":[[0,1.5,5],[1,1.49,5.05],[2,1.08,1.77]],"ltp":1.49,"tv":201.18,"id":891555}]}]}
{"op":"mcm","clk":"11939743698","pt":1724402434974,"mc":[{"id":"1.232160907","rc":[{"batb":[[0,1.49,5.05],[1,1.08,1.77],[2,1.04,1618.04]],"ltp":1.49,"tv":201.18,"id":891555}]}]}
{"op":"mcm","clk":"11939743914","pt":1724402437860,"mc":[{"id":"1.232160907","rc":[{"batb":[[0,1.5,5],[1,1.49,5.05],[2,1.08,1.77]],"ltp":1.49,"tv":201.18,"id":891555}]}]}
{"op":"mcm","clk":"11939744158","pt":1724402441475,"mc":[{"id":"1.232160907","rc":[{"batb":[[0,1.49,5.05],[1,1.08,1.77],[2,1.04,1618.04]],"ltp":1.49,"tv":201.18,"id":891555}]}]}
{"op":"mcm","clk":"11939744322","pt":1724402443862,"mc":[{"id":"1.232160907","rc":[{"batb":[[0,1.5,5],[1,1.49,5.05],[2,1.08,1.77]],"ltp":1.49,"tv":201.18,"id":891555}]}]}
{"op":"mcm","clk":"11939744518","pt":1724402447047,"mc":[{"id":"1.232160907","rc":[{"batb":[[0,1.49,5.05],[1,1.08,1.77],[2,1.04,1618.04]],"ltp":1.49,"tv":201.18,"id":891555}]}]}
{"op":"mcm","clk":"11939744684","pt":1724402449676,"mc":[{"id":"1.232160907","rc":[{"batb":[[0,1.5,5],[1,1.49,5.05],[2,1.08,1.77]],"ltp":1.49,"tv":201.18,"id":891555}]}]}
{"op":"mcm","clk":"11939744900","pt":1724402452866,"mc":[{"id":"1.232160907","rc":[{"batb":[[0,1.49,5.05],[1,1.08,1.77],[2,1.04,1618.04]],"ltp":1.49,"tv":201.18,"id":891555}]}]}
{"op":"mcm","clk":"11939745111","pt":1724402456381,"mc":[{"id":"1.232160907","rc":[{"batb":[[0,1.5,5],[1,1.49,5.05],[2,1.08,1.77]],"ltp":1.49,"tv":201.18,"id":891555}]}]}
{"op":"mcm","clk":"11939745314","pt":1724402459583,"mc":[{"id":"1.232160907","rc":[{"batb":[[0,1.49,5.05],[1,1.08,1.77],[2,1.04,1618.04]],"ltp":1.49,"tv":201.18,"id":891555}]}]}
{"op":"mcm","clk":"11939745454","pt":1724402461897,"mc":[{"id":"1.232160907","rc":[{"batb":[[0,1.5,5],[1,1.49,5.05],[2,1.08,1.77]],"ltp":1.49,"tv":201.18,"id":891555}]}]}
{"op":"mcm","clk":"11939745651","pt":1724402465496,"mc":[{"id":"1.232160907","rc":[{"batb":[[0,1.49,5.05],[1,1.08,1.77],[2,1.04,1618.04]],"ltp":1.49,"tv":201.18,"id":891555}]}]}
{"op":"mcm","clk":"11939745819","pt":1724402468018,"mc":[{"id":"1.232160907","rc":[{"batb":[[0,1.5,5],[1,1.49,5.05],[2,1.08,1.77]],"ltp":1.49,"tv":201.18,"id":891555}]}]}
{"op":"mcm","clk":"11939746059","pt":1724402471308,"mc":[{"id":"1.232160907","rc":[{"batb":[[0,1.49,5.05],[1,1.08,1.77],[2,1.04,1618.04]],"ltp":1.49,"tv":201.18,"id":891555}]}]}
{"op":"mcm","clk":"11939746191","pt":1724402473622,"mc":[{"id":"1.232160907","rc":[{"batb":[[0,1.5,5],[1,1.49,5.05],[2,1.08,1.77]],"ltp":1.49,"tv":201.18,"id":891555}]}]}
{"op":"mcm","clk":"11939746375","pt":1724402476906,"mc":[{"id":"1.232160907","rc":[{"batb":[[0,1.49,5.05],[1,1.08,1.77],[2,1.04,1618.04]],"ltp":1.49,"tv":201.18,"id":891555}]}]}
{"op":"mcm","clk":"11939746576","pt":1724402479753,"mc":[{"id":"1.232160907","rc":[{"batb":[[0,1.5,5],[1,1.49,5.05],[2,1.08,1.77]],"ltp":1.49,"tv":201.18,"id":891555}]}]}
{"op":"mcm","clk":"11939746767","pt":1724402483161,"mc":[{"id":"1.232160907","rc":[{"batb":[[0,1.49,5.05],[1,1.08,1.77],[2,1.04,1618.04]],"ltp":1.49,"tv":201.18,"id":891555}]}]}
{"op":"mcm","clk":"11939746934","pt":1724402485988,"mc":[{"id":"1.232160907","rc":[{"batb":[[0,1.5,5],[1,1.49,5.05],[2,1.08,1.77]],"ltp":1.49,"tv":201.18,"id":891555}]}]}
{"op":"mcm","clk":"11939747144","pt":1724402489336,"mc":[{"id":"1.232160907","rc":[{"batb":[[0,1.49,5.05],[1,1.08,1.77],[2,1.04,1618.04]],"ltp":1.49,"tv":201.18,"id":891555}]}]}
{"op":"mcm","clk":"11939747292","pt":1724402491501,"mc":[{"id":"1.232160907","rc":[{"batb":[[0,1.5,5],[1,1.49,5.05],[2,1.08,1.77]],"ltp":1.49,"tv":201.18,"id":891555}]}]}
{"op":"mcm","clk":"11939747500","pt":1724402494932,"mc":[{"id":"1.232160907","rc":[{"batb":[[0,1.49,5.05],[1,1.08,1.77],[2,1.04,1618.04]],"ltp":1.49,"tv":201.18,"id":891555}]}]}
{"op":"mcm","clk":"11939747673","pt":1724402497398,"mc":[{"id":"1.232160907","rc":[{"batb":[[0,1.5,5],[1,1.49,5.05],[2,1.08,1.77]],"ltp":1.49,"tv":201.18,"id":891555}]}]}
{"op":"mcm","clk":"11939747909","pt":1724402500743,"mc":[{"id":"1.232160907","rc":[{"batb":[[0,1.49,5.05],[1,1.08,1.77],[2,1.04,1618.04]],"ltp":1.49,"tv":201.18,"id":891555}]}]}
{"op":"mcm","clk":"11939748103","pt":1724402503433,"mc":[{"id":"1.232160907","rc":[{"batb":[[0,1.5,5],[1,1.49,5.05],[2,1.08,1.77]],"ltp":1.49,"tv":201.18,"id":891555}]}]}
{"op":"mcm","clk":"11939748244","pt":1724402505737,"mc":[{"id":"1.232160907","rc":[{"batb":[[0,1.15,56.81],[1,1.08,1.77],[2,1.04,1618.04]],"ltp":1.49,"tv":191.96,"id":144197}]}]}
{"op":"mcm","clk":"11939748303","pt":1724402506817,"mc":[{"id":"1.232160907","rc":[{"batb":[[0,1.49,5.05],[1,1.08,1.77],[2,1.04,1618.04]],"ltp":1.49,"tv":201.18,"id":891555}]}]}
{"op":"mcm","clk":"11939748510","pt":1724402510115,"mc":[{"id":"1.232160907","rc":[{"batb":[[0,1.5,5],[1,1.49,5.05],[2,1.08,1.77]],"ltp":1.49,"tv":201.18,"id":891555}]}]}
{"op":"mcm","clk":"11939748747","pt":1724402513465,"mc":[{"id":"1.232160907","rc":[{"batb":[[0,1.49,5.05],[1,1.08,1.77],[2,1.04,1618.04]],"ltp":1.49,"tv":201.18,"id":891555}]}]}
{"op":"mcm","clk":"11939748998","pt":1724402517136,"mc":[{"id":"1.232160907","rc":[{"batb":[[0,1.5,5],[1,1.49,5.05],[2,1.08,1.77]],"ltp":1.49,"tv":201.18,"id":891555}]}]}
{"op":"mcm","clk":"11939749211","pt":1724402520496,"mc":[{"id":"1.232160907","rc":[{"batb":[[0,1.49,5.05],[1,1.08,1.77],[2,1.04,1618.04]],"ltp":1.49,"tv":201.18,"id":891555}]}]}
{"op":"mcm","clk":"11939749436","pt":1724402523529,"mc":[{"id":"1.232160907","rc":[{"batb":[[0,1.5,5],[1,1.49,5.05],[2,1.08,1.77]],"ltp":1.49,"tv":201.18,"id":891555}]}]}
{"op":"mcm","clk":"11939749644","pt":1724402526762,"mc":[{"id":"1.232160907","rc":[{"batb":[[0,1.49,5.05],[1,1.08,1.77],[2,1.04,1618.04]],"ltp":1.49,"tv":201.18,"id":891555}]}]}
{"op":"mcm","clk":"11939749847","pt":1724402529939,"mc":[{"id":"1.232160907","rc":[{"batb":[[0,1.5,5],[1,1.49,5.05],[2,1.08,1.77]],"ltp":1.49,"tv":201.18,"id":891555}]}]}
{"op":"mcm","clk":"11939750107","pt":1724402533241,"mc":[{"id":"1.232160907","rc":[{"batb":[[0,1.49,5.05],[1,1.08,1.77],[2,1.04,1618.04]],"ltp":1.49,"tv":201.18,"id":891555}]}]}
{"op":"mcm","clk":"11939750390","pt":1724402536569,"mc":[{"id":"1.232160907","rc":[{"batb":[[0,1.5,5],[1,1.49,5.05],[2,1.08,1.77]],"ltp":1.49,"tv":201.18,"id":891555}]}]}
{"op":"mcm","clk":"11939750640","pt":1724402540177,"mc":[{"id":"1.232160907","rc":[{"batb":[[0,1.49,5.05],[1,1.08,1.77],[2,1.04,1618.04]],"ltp":1.49,"tv":201.18,"id":891555}]}]}
{"op":"mcm","clk":"11939750788","pt":1724402542688,"mc":[{"id":"1.232160907","rc":[{"batb":[[0,1.5,5],[1,1.49,5.05],[2,1.08,1.77]],"ltp":1.49,"tv":201.18,"id":891555}]}]}
{"op":"mcm","clk":"11939751009","pt":1724402545887,"mc":[{"id":"1.232160907","rc":[{"batb":[[0,1.49,5.05],[1,1.08,1.77],[2,1.04,1618.04]],"ltp":1.49,"tv":201.18,"id":891555}]}]}
{"op":"mcm","clk":"11939751269","pt":1724402550193,"mc":[{"id":"1.232160907","rc":[{"batb":[[0,1.5,5],[1,1.49,5.05],[2,1.08,1.77]],"ltp":1.49,"tv":201.18,"id":891555}]}]}
{"op":"mcm","clk":"11939751481","pt":1724402553379,"mc":[{"id":"1.232160907","rc":[{"batb":[[0,1.49,5.05],[1,1.08,1.77],[2,1.04,1618.04]],"ltp":1.49,"tv":201.18,"id":891555}]}]}
{"op":"mcm","clk":"11939751641","pt":1724402555997,"mc":[{"id":"1.232160907","rc":[{"batb":[[0,1.5,5],[1,1.49,5.05],[2,1.08,1.77]],"ltp":1.49,"tv":201.18,"id":891555}]}]}
{"op":"mcm","clk":"11939751843","pt":1724402559179,"mc":[{"id":"1.232160907","rc":[{"batb":[[0,1.49,5.05],[1,1.08,1.77],[2,1.04,1618.04]],"ltp":1.49,"tv":201.18,"id":891555}]}]}
{"op":"mcm","clk":"11939752035","pt":1724402561907,"mc":[{"id":"1.232160907","rc":[{"batb":[[0,1.5,5],[1,1.49,5.05],[2,1.08,1.77]],"ltp":1.49,"tv":201.18,"id":891555}]}]}
{"op":"mcm","clk":"11939752266","pt":1724402565298,"mc":[{"id":"1.232160907","rc":[{"batb":[[0,1.49,5.05],[1,1.08,1.77],[2,1.04,1618.04]],"ltp":1.49,"tv":201.18,"id":891555}]}]}
{"op":"mcm","clk":"11939752402","pt":1724402567712,"mc":[{"id":"1.232160907","rc":[{"batb":[[0,1.5,5],[1,1.49,5.05],[2,1.08,1.77]],"ltp":1.49,"tv":201.18,"id":891555}]}]}
{"op":"mcm","clk":"11939752639","pt":1724402571025,"mc":[{"id":"1.232160907","rc":[{"batb":[[0,1.49,5.05],[1,1.08,1.77],[2,1.04,1618.04]],"ltp":1.49,"tv":201.18,"id":891555}]}]}
{"op":"mcm","clk":"11939752943","pt":1724402575227,"mc":[{"id":"1.232160907","rc":[{"batb":[[0,1.5,5],[1,1.49,5.05],[2,1.08,1.77]],"ltp":1.49,"tv":201.18,"id":891555}]}]}
{"op":"mcm","clk":"11939753173","pt":1724402578502,"mc":[{"id":"1.232160907","rc":[{"batb":[[0,1.49,5.05],[1,1.08,1.77],[2,1.04,1618.04]],"ltp":1.49,"tv":201.18,"id":891555}]}]}
{"op":"mcm","clk":"11939753360","pt":1724402580824,"mc":[{"id":"1.232160907","rc":[{"batb":[[0,1.5,5],[1,1.49,5.05],[2,1.08,1.77]],"ltp":1.49,"tv":201.18,"id":891555}]}]}
{"op":"mcm","clk":"11939753631","pt":1724402584137,"mc":[{"id":"1.232160907","rc":[{"batb":[[0,1.49,5.05],[1,1.08,1.77],[2,1.04,1618.04]],"ltp":1.49,"tv":201.18,"id":891555}]}]}
{"op":"mcm","clk":"11939753808","pt":1724402586595,"mc":[{"id":"1.232160907","rc":[{"batb":[[0,1.5,5],[1,1.49,5.05],[2,1.08,1.77]],"ltp":1.49,"tv":201.18,"id":891555}]}]}
{"op":"mcm","clk":"11939754035","pt":1724402589829,"mc":[{"id":"1.232160907","rc":[{"batb":[[0,1.49,5.05],[1,1.08,1.77],[2,1.04,1618.04]],"ltp":1.49,"tv":201.18,"id":891555}]}]}
{"op":"mcm","clk":"11939754233","pt":1724402592247,"mc":[{"id":"1.232160907","rc":[{"batb":[[0,1.5,5],[1,1.49,5.05],[2,1.08,1.77]],"ltp":1.49,"tv":201.18,"id":891555}]}]}
{"op":"mcm","clk":"11939754480","pt":1724402595641,"mc":[{"id":"1.232160907","rc":[{"batb":[[0,1.49,5.05],[1,1.08,1.77],[2,1.04,1618.04]],"ltp":1.49,"tv":201.18,"id":891555}]}]}
{"op":"mcm","clk":"11939754644","pt":1724402598207,"mc":[{"id":"1.232160907","rc":[{"batb":[[0,1.5,5],[1,1.49,5.05],[2,1.08,1.77]],"ltp":1.49,"tv":201.18,"id":891555}]}]}
{"op":"mcm","clk":"11939754843","pt":1724402601450,"mc":[{"id":"1.232160907","rc":[{"batb":[[0,1.49,5.05],[1,1.08,1.77],[2,1.04,1618.04]],"ltp":1.49,"tv":201.18,"id":891555}]}]}
{"op":"mcm","clk":"11939755008","pt":1724402603818,"mc":[{"id":"1.232160907","rc":[{"batb":[[0,1.5,5],[1,1.49,5.05],[2,1.08,1.77]],"ltp":1.49,"tv":201.18,"id":891555}]}]}
{"op":"mcm","clk":"11939755259","pt":1724402607053,"mc":[{"id":"1.232160907","rc":[{"batb":[[0,1.49,5.05],[1,1.08,1.77],[2,1.04,1618.04]],"ltp":1.49,"tv":201.18,"id":891555}]}]}
{"op":"mcm","clk":"11939755423","pt":1724402609418,"mc":[{"id":"1.232160907","rc":[{"batb":[[0,1.5,5],[1,1.49,5.05],[2,1.08,1.77]],"ltp":1.49,"tv":201.18,"id":891555}]}]}
{"op":"mcm","clk":"11939755656","pt":1724402612569,"mc":[{"id":"1.232160907","rc":[{"batb":[[0,1.49,5.05],[1,1.08,1.77],[2,1.04,1618.04]],"ltp":1.49,"tv":201.18,"id":891555}]}]}
{"op":"mcm","clk":"11939755811","pt":1724402614927,"mc":[{"id":"1.232160907","rc":[{"batb":[[0,1.5,5],[1,1.49,5.05],[2,1.08,1.77]],"ltp":1.49,"tv":201.18,"id":891555}]}]}
{"op":"mcm","clk":"11939756019","pt":1724402618157,"mc":[{"id":"1.232160907","rc":[{"batb":[[0,1.49,5.05],[1,1.08,1.77],[2,1.04,1618.04]],"ltp":1.49,"tv":201.18,"id":891555}]}]}
{"op":"mcm","clk":"11939756174","pt":1724402620951,"mc":[{"id":"1.232160907","rc":[{"batb":[[0,1.5,5],[1,1.49,5.05],[2,1.08,1.77]],"ltp":1.49,"tv":201.18,"id":891555}]}]}
{"op":"mcm","clk":"11939756363","pt":1724402624043,"mc":[{"id":"1.232160907","rc":[{"batb":[[0,1.49,5.05],[1,1.08,1.77],[2,1.04,1618.04]],"ltp":1.49,"tv":201.18,"id":891555}]}]}
{"op":"mcm","clk":"11939756504","pt":1724402626468,"mc":[{"id":"1.232160907","rc":[{"batb":[[0,1.5,5],[1,1.49,5.05],[2,1.08,1.77]],"ltp":1.49,"tv":201.18,"id":891555}]}]}
{"op":"mcm","clk":"11939756673","pt":1724402629752,"mc":[{"id":"1.232160907","rc":[{"batb":[[0,1.49,5.05],[1,1.08,1.77],[2,1.04,1618.04]],"ltp":1.49,"tv":201.18,"id":891555}]}]}
{"op":"mcm","clk":"11939756823","pt":1724402632270,"mc":[{"id":"1.232160907","rc":[{"batb":[[0,1.5,5],[1,1.49,5.05],[2,1.08,1.77]],"ltp":1.49,"tv":201.18,"id":891555}]}]}
{"op":"mcm","clk":"11939757029","pt":1724402635653,"mc":[{"id":"1.232160907","rc":[{"batb":[[0,1.49,5.05],[1,1.08,1.77],[2,1.04,1618.04]],"ltp":1.49,"tv":201.18,"id":891555}]}]}
{"op":"mcm","clk":"11939757261","pt":1724402639243,"mc":[{"id":"1.232160907","rc":[{"batb":[[0,1.5,5],[1,1.49,5.05],[2,1.08,1.77]],"ltp":1.49,"tv":201.18,"id":891555}]}]}
{"op":"mcm","clk":"11939757487","pt":1724402642474,"mc":[{"id":"1.232160907","rc":[{"batb":[[0,1.49,5.05],[1,1.08,1.77],[2,1.04,1618.04]],"ltp":1.49,"tv":201.18,"id":891555}]}]}
{"op":"mcm","clk":"11939757707","pt":1724402645614,"mc":[{"id":"1.232160907","rc":[{"batb":[[0,1.5,5],[1,1.49,5.05],[2,1.08,1.77]],"ltp":1.49,"tv":201.18,"id":891555}]}]}
{"op":"mcm","clk":"11939757910","pt":1724402648887,"mc":[{"id":"1.232160907","rc":[{"batb":[[0,1.49,5.05],[1,1.08,1.77],[2,1.04,1618.04]],"ltp":1.49,"tv":201.18,"id":891555}]}]}
{"op":"mcm","clk":"11939758081","pt":1724402651159,"mc":[{"id":"1.232160907","rc":[{"batb":[[0,1.5,5],[1,1.49,5.05],[2,1.08,1.77]],"ltp":1.49,"tv":201.18,"id":891555}]}]}
{"op":"mcm","clk":"11939758357","pt":1724402654572,"mc":[{"id":"1.232160907","rc":[{"batb":[[0,1.49,5.05],[1,1.08,1.77],[2,1.04,1618.04]],"ltp":1.49,"tv":201.18,"id":891555}]}]}
{"op":"mcm","clk":"11939758531","pt":1724402657004,"mc":[{"id":"1.232160907","rc":[{"batb":[[0,1.5,5],[1,1.49,5.05],[2,1.08,1.77]],"ltp":1.49,"tv":201.18,"id":891555}]}]}
{"op":"mcm","clk":"11939758736","pt":1724402660393,"mc":[{"id":"1.232160907","rc":[{"batb":[[0,1.49,5.05],[1,1.08,1.77],[2,1.04,1618.04]],"ltp":1.49,"tv":201.18,"id":891555}]}]}
{"op":"mcm","clk":"11939758889","pt":1724402662704,"mc":[{"id":"1.232160907","rc":[{"batb":[[0,1.5,5],[1,1.49,5.05],[2,1.08,1.77]],"ltp":1.49,"tv":201.18,"id":891555}]}]}
{"op":"mcm","clk":"11939759118","pt":1724402665927,"mc":[{"id":"1.232160907","rc":[{"batb":[[0,1.49,5.05],[1,1.08,1.77],[2,1.04,1618.04]],"ltp":1.49,"tv":201.18,"id":891555}]}]}
{"op":"mcm","clk":"11939759298","pt":1724402668736,"mc":[{"id":"1.232160907","rc":[{"batb":[[0,1.5,5],[1,1.49,5.05],[2,1.08,1.77]],"ltp":1.49,"tv":201.18,"id":891555}]}]}
{"op":"mcm","clk":"11939759508","pt":1724402672019,"mc":[{"id":"1.232160907","rc":[{"batb":[[0,1.49,5.05],[1,1.08,1.77],[2,1.04,1618.04]],"ltp":1.49,"tv":201.18,"id":891555}]}]}
{"op":"mcm","clk":"11939759714","pt":1724402675511,"mc":[{"id":"1.232160907","rc":[{"batb":[[0,1.5,5],[1,1.49,5.05],[2,1.08,1.77]],"ltp":1.49,"tv":201.18,"id":891555}]}]}
{"op":"mcm","clk":"11939759893","pt":1724402678703,"mc":[{"id":"1.232160907","rc":[{"batb":[[0,1.49,5.05],[1,1.08,1.77],[2,1.04,1618.04]],"ltp":1.49,"tv":201.18,"id":891555}]}]}
{"op":"mcm","clk":"11939760141","pt":1724402682601,"mc":[{"id":"1.232160907","rc":[{"batb":[[0,1.5,5],[1,1.49,5.05],[2,1.08,1.77]],"ltp":1.49,"tv":201.18,"id":891555}]}]}
{"op":"mcm","clk":"11939760394","pt":1724402686096,"mc":[{"id":"1.232160907","rc":[{"batb":[[0,1.49,5.05],[1,1.08,1.77],[2,1.04,1618.04]],"ltp":1.49,"tv":201.18,"id":891555}]}]}
{"op":"mcm","clk":"11939760550","pt":1724402688515,"mc":[{"id":"1.232160907","rc":[{"batb":[[0,1.5,5],[1,1.49,5.05],[2,1.08,1.77]],"ltp":1.49,"tv":201.18,"id":891555}]}]}
{"op":"mcm","clk":"11939760766","pt":1724402691805,"mc":[{"id":"1.232160907","rc":[{"batb":[[0,1.49,5.05],[1,1.08,1.77],[2,1.04,1618.04]],"ltp":1.49,"tv":201.18,"id":891555}]}]}
{"op":"mcm","clk":"11939760918","pt":1724402694217,"mc":[{"id":"1.232160907","rc":[{"batb":[[0,1.5,5],[1,1.49,5.05],[2,1.08,1.77]],"ltp":1.49,"tv":201.18,"id":891555}]}]}
{"op":"mcm","clk":"11939761102","pt":1724402697417,"mc":[{"id":"1.232160907","rc":[{"batb":[[0,1.49,5.05],[1,1.08,1.77],[2,1.04,1618.04]],"ltp":1.49,"tv":201.18,"id":891555}]}]}
{"op":"mcm","clk":"11939761236","pt":1724402699729,"mc":[{"id":"1.232160907","rc":[{"batb":[[0,1.5,5],[1,1.49,5.05],[2,1.08,1.77]],"ltp":1.49,"tv":201.18,"id":891555}]}]}
{"op":"mcm","clk":"11939761509","pt":1724402703043,"mc":[{"id":"1.232160907","rc":[{"batb":[[0,1.49,5.05],[1,1.08,1.77],[2,1.04,1618.04]],"ltp":1.49,"tv":201.18,"id":891555}]}]}
{"op":"mcm","clk":"11939761763","pt":1724402706447,"mc":[{"id":"1.232160907","rc":[{"batb":[[0,1.5,5],[1,1.49,5.05],[2,1.08,1.77]],"ltp":1.49,"tv":201.18,"id":891555}]}]}
{"op":"mcm","clk":"11939762024","pt":1724402709855,"mc":[{"id":"1.232160907","rc":[{"batb":[[0,1.49,5.05],[1,1.08,1.77],[2,1.04,1618.04]],"ltp":1.49,"tv":201.18,"id":891555}]}]}
{"op":"mcm","clk":"11939762215","pt":1724402712532,"mc":[{"id":"1.232160907","rc":[{"batb":[[0,1.5,5],[1,1.49,5.05],[2,1.08,1.77]],"ltp":1.49,"tv":201.18,"id":891555}]}]}
{"op":"mcm","clk":"11939762434","pt":1724402715824,"mc":[{"id":"1.232160907","rc":[{"batb":[[0,1.49,5.05],[1,1.08,1.77],[2,1.04,1618.04]],"ltp":1.49,"tv":201.18,"id":891555}]}]}
{"op":"mcm","clk":"11939762709","pt":1724402719660,"mc":[{"id":"1.232160907","rc":[{"batb":[[0,1.5,5],[1,1.49,5.05],[2,1.08,1.77]],"ltp":1.49,"tv":201.18,"id":891555}]}]}
{"op":"mcm","clk":"11939762950","pt":1724402723062,"mc":[{"id":"1.232160907","rc":[{"batb":[[0,1.49,5.05],[1,1.08,1.77],[2,1.04,1618.04]],"ltp":1.49,"tv":201.18,"id":891555}]}]}
