{"op":"mcm","clk":"11927678317","pt":1724241780963,"mc":[{"id":"1.232098082","marketDefinition":{"bspMarket":false,"turnInPlayEnabled":true,"persistenceEnabled":true,"marketBaseRate":5.0,"eventId":"33514511","eventTypeId":"4","numberOfWinners":1,"bettingType":"ODDS","marketType":"MATCH_ODDS","marketTime":"2024-08-22T09:30:00.000Z","suspendTime":"2024-08-22T09:30:00.000Z","bspReconciled":false,"complete":true,"inPlay":false,"crossMatching":false,"runnersVoidable":false,"numberOfActiveRunners":2,"betDelay":0,"status":"OPEN","runners":[{"status":"ACTIVE","sortPriority":1,"id":11392436,"name":"Estonia"},{"status":"ACTIVE","sortPriority":2,"id":48610314,"name":"Finland"}],"regulators":["MR_INT"],"countryCode":"GB","discountAllowed":false,"timezone":"GMT","openDate":"2024-08-22T09:30:00.000Z","version":6089046111,"name":"Match Odds","eventName":"Estonia v Finland"},"rc":[{"batb":[[0,1.01,20]],"ltp":0.0,"tv":0.0,"id":11392436},{"batb":[[0,1.01,20]],"ltp":0.0,"tv":0.0,"id":48610314}]}]}
{"op":"mcm","clk":"11927678410","pt":1724241782257,"mc":[{"id":"1.232098082","rc":[{"batb":[[0,1.03,200],[1,1.02,200],[2,1.01,220]],"ltp":0.0,"tv":0.0,"id":11392436},{"batb":[[0,1.03,200],[1,1.02,200],[2,1.01,220]],"ltp":0.0,"tv":0.0,"id":48610314}]}]}
{"op":"mcm","clk":"11927678648","pt":1724241785873,"mc":[{"id":"1.232098082","marketDefinition":{"bspMarket":false,"turnInPlayEnabled":true,"persistenceEnabled":true,"marketBaseRate":5.0,"eventId":"33514511","eventTypeId":"4","numberOfWinners":1,"bettingType":"ODDS","marketType":"MATCH_ODDS","marketTime":"2024-08-22T09:30:00.000Z","suspendTime":"2024-08-22T09:30:00.000Z","bspReconciled":false,"complete":true,"inPlay":false,"crossMatching":false,"runnersVoidable":false,"numberOfActiveRunners":2,"betDelay":0,"status":"OPEN","runners":[{"status":"ACTIVE","sortPriority":1,"id":11392436,"name":"Estonia"},{"status":"ACTIVE","sortPriority":2,"id":48610314,"name":"Finland"}],"regulators":["MR_INT"],"countryCode":"GB","discountAllowed":true,"timezone":"GMT","openDate":"2024-08-22T09:30:00.000Z","version":6089046111,"name":"Match Odds","eventName":"Estonia v Finland"}}]}
{"op":"mcm","clk":"11927791058","pt":1724243466294,"mc":[{"id":"1.232098082","rc":[{"batb":[[2,1.01,482.28]],"ltp":0.0,"tv":0.0,"id":11392436},{"batb":[[2,1.01,482.28]],"ltp":0.0,"tv":0.0,"id":48610314}]}]}
{"op":"mcm","clk":"11927945129","pt":1724245694691,"mc":[{"id":"1.232098082","rc":[{"batb":[[2,1.01,482.46]],"batl":[[0,1000,0.77]],"ltp":0.0,"tv":0.0,"id":11392436},{"batb":[[2,1.01,482.46]],"batl":[[0,1000,0.77]],"ltp":0.0,"tv":0.0,"id":48610314}]}]}
{"op":"mcm","clk":"11927945773","pt":1724245703906,"mc":[{"id":"1.232098082","rc":[{"batl":[[0,1000,1.15]],"ltp":0.0,"tv":0.0,"id":11392436},{"batl":[[0,1000,1.15]],"ltp":0.0,"tv":0.0,"id":48610314}]}]}
{"op":"mcm","clk":"11927946297","pt":1724245711136,"mc":[{"id":"1.232098082","rc":[{"batl":[[0,1000,1.53]],"ltp":0.0,"tv":0.0,"id":11392436},{"batl":[[0,1000,1.53]],"ltp":0.0,"tv":0.0,"id":48610314}]}]}
{"op":"mcm","clk":"11927946837","pt":1724245718732,"mc":[{"id":"1.232098082","marketDefinition":{"bspMarket":false,"turnInPlayEnabled":true,"persistenceEnabled":true,"marketBaseRate":5.0,"eventId":"33514511","eventTypeId":"4","numberOfWinners":1,"bettingType":"ODDS","marketType":"MATCH_ODDS","marketTime":"2024-08-22T09:30:00.000Z","suspendTime":"2024-08-22T09:30:00.000Z","bspReconciled":false,"complete":true,"inPlay":false,"crossMatching":true,"runnersVoidable":false,"numberOfActiveRunners":2,"betDelay":0,"status":"OPEN","runners":[{"status":"ACTIVE","sortPriority":1,"id":11392436,"name":"Estonia"},{"status":"ACTIVE","sortPriority":2,"id":48610314,"name":"Finland"}],"regulators":["MR_INT"],"countryCode":"GB","discountAllowed":true,"timezone":"GMT","openDate":"2024-08-22T09:30:00.000Z","version":6089046111,"name":"Match Odds","eventName":"Estonia v Finland"},"rc":[{"batl":[[0,1000,1.92]],"ltp":0.0,"tv":0.0,"id":11392436},{"batl":[[0,1000,1.92]],"ltp":0.0,"tv":0.0,"id":48610314}]}]}
{"op":"mcm","clk":"11927949489","pt":1724245756276,"mc":[{"id":"1.232098082","rc":[{"batl":[[0,24,1.15],[1,30,0.77]],"ltp":0.0,"tv":0.0,"id":11392436},{"batl":[[0,24,1.15],[1,30,0.77]],"ltp":0.0,"tv":0.0,"id":48610314}]}]}
{"op":"mcm","clk":"11928025695","pt":1724246893081,"mc":[{"id":"1.232098082","rc":[{"batb":[[0,1.85,10],[1,1.03,200],[2,1.02,200]],"ltp":0.0,"tv":0.0,"id":11392436}]}]}
{"op":"mcm","clk":"11928026416","pt":1724246903370,"mc":[{"id":"1.232098082","rc":[{"batb":[[0,1.19,26],[1,1.03,200],[2,1.02,200]],"ltp":0.0,"tv":0.0,"id":48610314}]}]}
{"op":"mcm","clk":"11928026967","pt":1724246911187,"mc":[{"id":"1.232098082","rc":[{"batb":[[0,2.1,10]],"ltp":0.0,"tv":0.0,"id":11392436}]}]}
{"op":"mcm","clk":"11928027804","pt":1724246922783,"mc":[{"id":"1.232098082","rc":[{"batl":[[0,1.89,15],[1,24,1.15],[2,30,0.77]],"ltp":0.0,"tv":0.0,"id":48610314}]}]}
{"op":"mcm","clk":"11928028571","pt":1724246932590,"mc":[{"id":"1.232098082","rc":[{"batb":[[0,2.14,10]],"ltp":0.0,"tv":0.0,"id":11392436}]}]}
{"op":"mcm","clk":"11928029162","pt":1724246940331,"mc":[{"id":"1.232098082","rc":[{"batl":[[0,1.87,15]],"ltp":0.0,"tv":0.0,"id":48610314}]}]}
{"op":"mcm","clk":"11928291227","pt":1724251091381,"mc":[{"id":"1.232098082","rc":[{"batb":[[0,2.16,7.38],[1,2.14,10],[2,1.03,200]],"ltp":0.0,"tv":0.0,"id":11392436},{"batb":[[0,1.2,42.8],[1,1.19,26],[2,1.03,200]],"ltp":0.0,"tv":0.0,"id":48610314}]}]}
{"op":"mcm","clk":"11928417012","pt":1724252892713,"mc":[{"id":"1.232098082","rc":[{"batb":[[0,2.14,10],[1,1.03,200],[2,1.02,200]],"batl":[[0,24,1.15]],"ltp":0.0,"tv":0.0,"id":11392436},{"batb":[[0,1.19,26],[1,1.03,200],[2,1.02,200]],"batl":[[1,24,1.15]],"ltp":0.0,"tv":0.0,"id":48610314}]}]}
{"op":"mcm","clk":"11928434762","pt":1724253068265,"mc":[{"id":"1.232098082","rc":[{"batb":[[0,2.16,7.38],[1,2.14,10],[2,1.03,200]],"ltp":0.0,"tv":0.0,"id":11392436},{"batb":[[0,1.2,42.8],[1,1.19,26],[2,1.03,200]],"ltp":0.0,"tv":0.0,"id":48610314}]}]}
{"op":"mcm","clk":"11928632541","pt":1724254868709,"mc":[{"id":"1.232098082","rc":[{"batb":[[0,2.14,10],[1,1.03,200],[2,1.02,200]],"ltp":0.0,"tv":0.0,"id":11392436},{"batb":[[0,1.19,26],[1,1.03,200],[2,1.02,200]],"ltp":0.0,"tv":0.0,"id":48610314}]}]}
{"op":"mcm","clk":"11928664871","pt":1724255034352,"mc":[{"id":"1.232098082","rc":[{"batb":[[0,2.16,7.38],[1,2.14,10],[2,1.03,200]],"ltp":0.0,"tv":0.0,"id":11392436},{"batb":[[0,1.2,42.8],[1,1.19,26],[2,1.03,200]],"ltp":0.0,"tv":0.0,"id":48610314}]}]}
{"op":"mcm","clk":"11928900946","pt":1724256834831,"mc":[{"id":"1.232098082","rc":[{"batb":[[0,2.14,10],[1,1.03,200],[2,1.02,200]],"batl":[[0,24,1.15]],"ltp":0.0,"tv":0.0,"id":11392436},{"batb":[[0,1.19,26],[1,1.03,200],[2,1.02,200]],"batl":[[1,24,1.15]],"ltp":0.0,"tv":0.0,"id":48610314}]}]}
{"op":"mcm","clk":"11928925606","pt":1724256993757,"mc":[{"id":"1.232098082","rc":[{"batb":[[0,2.16,7.38],[1,2.14,10],[2,1.03,200]],"ltp":0.0,"tv":0.0,"id":11392436},{"batb":[[0,1.2,42.81],[1,1.19,26],[2,1.03,200]],"ltp":0.0,"tv":0.0,"id":48610314}]}]}
{"op":"mcm","clk":"11929001392","pt":1724257557023,"mc":[{"id":"1.232098082","rc":[{"batb":[[2,1.04,1.53]],"ltp":0.0,"tv":0.0,"id":11392436},{"batb":[[2,1.04,1.53]],"ltp":0.0,"tv":0.0,"id":48610314}]}]}
{"op":"mcm","clk":"11929193402","pt":1724258794239,"mc":[{"id":"1.232098082","rc":[{"batb":[[0,2.14,10],[1,1.04,1.53],[2,1.03,200]],"ltp":0.0,"tv":0.0,"id":11392436},{"batb":[[0,1.19,26],[1,1.04,1.53],[2,1.03,200]],"ltp":0.0,"tv":0.0,"id":48610314}]}]}
{"op":"mcm","clk":"11929213405","pt":1724258930055,"mc":[{"id":"1.232098082","rc":[{"batb":[[0,2.16,7.38],[1,2.14,10],[2,1.04,1.53]],"ltp":0.0,"tv":0.0,"id":11392436},{"batb":[[0,1.2,42.81],[1,1.19,26],[2,1.04,1.53]],"ltp":0.0,"tv":0.0,"id":48610314}]}]}
{"op":"mcm","clk":"11929462278","pt":1724260375079,"mc":[{"id":"1.232098082","rc":[{"batb":[[0,2.16,7.38]],"batl":[[0,24,1.15]],"ltp":0.0,"tv":0.0,"id":11392436},{"batb":[[0,1.2,42.79]],"batl":[[1,24,1.15]],"ltp":0.0,"tv":0.0,"id":48610314}]}]}
{"op":"mcm","clk":"11929526338","pt":1724260730472,"mc":[{"id":"1.232098082","rc":[{"batb":[[0,2.14,10],[1,1.04,1.53],[2,1.03,200]],"ltp":0.0,"tv":0.0,"id":11392436},{"batb":[[0,1.19,26],[1,1.04,1.53],[2,1.03,200]],"ltp":0.0,"tv":0.0,"id":48610314}]}]}
{"op":"mcm","clk":"11929550504","pt":1724260885439,"mc":[{"id":"1.232098082","rc":[{"batb":[[0,2.16,7.38],[1,2.14,10],[2,1.04,1.53]],"ltp":0.0,"tv":0.0,"id":11392436},{"batb":[[0,1.2,42.79],[1,1.19,26],[2,1.04,1.53]],"ltp":0.0,"tv":0.0,"id":48610314}]}]}
{"op":"mcm","clk":"11929837753","pt":1724262685803,"mc":[{"id":"1.232098082","rc":[{"batb":[[0,2.14,10],[1,1.04,1.53],[2,1.03,200]],"ltp":0.0,"tv":0.0,"id":11392436},{"batb":[[0,1.19,26],[1,1.04,1.53],[2,1.03,200]],"ltp":0.0,"tv":0.0,"id":48610314}]}]}
{"op":"mcm","clk":"11929848474","pt":1724262768932,"mc":[{"id":"1.232098082","rc":[{"batb":[[0,2.16,7.38],[1,2.14,10],[2,1.04,1.53]],"ltp":0.0,"tv":0.0,"id":11392436},{"batb":[[0,1.2,42.79],[1,1.19,26],[2,1.04,1.53]],"ltp":0.0,"tv":0.0,"id":48610314}]}]}
{"op":"mcm","clk":"11929856886","pt":1724262842195,"mc":[{"id":"1.232098082","rc":[{"batb":[[0,3,18.44],[1,2.16,7.38],[2,2.14,10]],"ltp":0.0,"tv":0.0,"id":11392436},{"batb":[[0,1.43,85.77],[1,1.2,42.79],[2,1.19,26]],"ltp":0.0,"tv":0.0,"id":48610314}]}]}
{"op":"mcm","clk":"11930086277","pt":1724264280695,"mc":[{"id":"1.232098082","rc":[{"batb":[[1,2.16,7.38],[2,1.04,1.53]],"ltp":0.0,"tv":0.0,"id":11392436},{"batb":[[1,1.2,42.8],[2,1.04,1.53]],"batl":[[0,1.49,15]],"ltp":0.0,"tv":0.0,"id":48610314}]}]}
{"op":"mcm","clk":"11930134904","pt":1724264569463,"mc":[{"id":"1.232098082","rc":[{"batb":[[1,1.04,1.53],[2,1.03,200]],"ltp":0.0,"tv":0.0,"id":11392436},{"batb":[[1,1.04,1.53],[2,1.03,200]],"ltp":0.0,"tv":0.0,"id":48610314}]}]}
{"op":"mcm","clk":"11930488909","pt":1724266791086,"mc":[{"id":"1.232098082","rc":[{"trd":[[3.35,3.39]],"ltp":3.35,"tv":3.38,"id":11392436},{"trd":[[1.43,7.94]],"batb":[[0,1.43,77.83]],"ltp":1.43,"tv":7.94,"id":48610314}],"tv":11.32}]}
{"op":"mcm","clk":"11930489268","pt":1724266793476,"mc":[{"id":"1.232098082","rc":[{"batb":[[0,1.43,85.77]],"ltp":1.43,"tv":7.94,"id":48610314}]}]}
{"op":"mcm","clk":"11930490318","pt":1724266801068,"mc":[{"id":"1.232098082","rc":[{"trd":[[3.35,6.78]],"ltp":3.35,"tv":6.77,"id":11392436},{"trd":[[1.43,15.88]],"batb":[[0,1.43,77.83]],"ltp":1.43,"tv":15.88,"id":48610314}],"tv":22.65}]}
{"op":"mcm","clk":"11930490695","pt":1724266803496,"mc":[{"id":"1.232098082","rc":[{"batb":[[0,1.43,85.77]],"ltp":1.43,"tv":15.88,"id":48610314}]}]}
{"op":"mcm","clk":"11930495659","pt":1724266837363,"mc":[{"id":"1.232098082","rc":[{"trd":[[3.35,6.78]],"batb":[[0,3,25.22]],"ltp":3.35,"tv":6.77,"id":11392436}],"tv":22.65}]}
{"op":"mcm","clk":"11930496627","pt":1724266844320,"mc":[{"id":"1.232098082","rc":[{"trd":[[3.35,13.55]],"batb":[[0,3,18.44]],"ltp":3.35,"tv":13.55,"id":11392436},{"trd":[[1.43,31.75]],"batb":[[0,1.43,69.9]],"ltp":1.43,"tv":31.75,"id":48610314}],"tv":45.3}]}
{"op":"mcm","clk":"11930497221","pt":1724266848744,"mc":[{"id":"1.232098082","rc":[{"batb":[[0,1.43,85.77]],"ltp":1.43,"tv":31.75,"id":48610314}]}]}
{"op":"mcm","clk":"11930498687","pt":1724266859057,"mc":[{"id":"1.232098082","rc":[{"batb":[[1,2.6,5.08],[2,1.04,1.53]],"ltp":3.35,"tv":13.55,"id":11392436}]}]}
{"op":"mcm","clk":"11930519269","pt":1724267020374,"mc":[{"id":"1.232098082","rc":[{"trd":[[3.35,24.73]],"batb":[[0,3.05,10],[1,3,18.44],[2,2.6,5.08]],"ltp":3.35,"tv":24.73,"id":11392436},{"trd":[[1.43,57.94]],"batb":[[0,1.43,59.58]],"ltp":1.43,"tv":57.94,"id":48610314}],"tv":82.67}]}
{"op":"mcm","clk":"11930519654","pt":1724267023734,"mc":[{"id":"1.232098082","rc":[{"batb":[[0,3,18.44],[1,2.6,5.08],[2,1.04,1.53]],"ltp":3.35,"tv":24.73,"id":11392436}]}]}
{"op":"mcm","clk":"11930519705","pt":1724267024150,"mc":[{"id":"1.232098082","rc":[{"batb":[[0,1.43,85.77]],"ltp":1.43,"tv":57.94,"id":48610314}]}]}
{"op":"mcm","clk":"11930532922","pt":1724267126333,"mc":[{"id":"1.232098082","rc":[{"trd":[[3.35,28.12]],"batb":[[0,3.05,10],[1,3,18.44],[2,2.6,5.08]],"ltp":3.35,"tv":28.11,"id":11392436},{"trd":[[1.43,65.88]],"batb":[[0,1.43,77.83]],"ltp":1.43,"tv":65.88,"id":48610314}],"tv":93.99}]}
{"op":"mcm","clk":"11930533338","pt":1724267129764,"mc":[{"id":"1.232098082","rc":[{"batb":[[0,3,18.44],[1,2.6,5.08],[2,1.04,1.53]],"ltp":3.35,"tv":28.11,"id":11392436},{"batb":[[0,1.43,85.77]],"ltp":1.43,"tv":65.88,"id":48610314}]}]}
{"op":"mcm","clk":"11930536718","pt":1724267155727,"mc":[{"id":"1.232098082","rc":[{"trd":[[3.35,31.51]],"ltp":3.35,"tv":31.5,"id":11392436},{"trd":[[1.43,73.82]],"batb":[[0,1.43,77.83]],"ltp":1.43,"tv":73.82,"id":48610314}],"tv":105.32}]}
{"op":"mcm","clk":"11930536747","pt":1724267155956,"mc":[{"id":"1.232098082","rc":[{"batb":[[0,3.05,10],[1,3,18.44],[2,2.6,5.08]],"ltp":3.35,"tv":31.5,"id":11392436}]}]}
{"op":"mcm","clk":"11930537252","pt":1724267159466,"mc":[{"id":"1.232098082","rc":[{"batb":[[0,3,18.44],[1,2.6,5.08],[2,1.04,1.53]],"ltp":3.35,"tv":31.5,"id":11392436},{"batb":[[0,1.43,85.77]],"ltp":1.43,"tv":73.82,"id":48610314}]}]}
{"op":"mcm","clk":"11930548242","pt":1724267240856,"mc":[{"id":"1.232098082","rc":[{"trd":[[3.35,43.2]],"ltp":3.35,"tv":43.19,"id":11392436},{"trd":[[1.43,101.2]],"batb":[[0,1.43,58.39]],"ltp":1.43,"tv":101.2,"id":48610314}],"tv":144.39}]}
{"op":"mcm","clk":"11930548268","pt":1724267241060,"mc":[{"id":"1.232098082","rc":[{"batb":[[0,3.05,10],[1,3,18.44],[2,2.6,5.08]],"ltp":3.35,"tv":43.19,"id":11392436}]}]}
{"op":"mcm","clk":"11930548775","pt":1724267244671,"mc":[{"id":"1.232098082","rc":[{"batb":[[0,3,18.44],[1,2.6,5.08],[2,1.04,1.53]],"ltp":3.35,"tv":43.19,"id":11392436},{"batb":[[0,1.43,85.77]],"ltp":1.43,"tv":101.2,"id":48610314}]}]}
{"op":"mcm","clk":"11930551611","pt":1724267265595,"mc":[{"id":"1.232098082","rc":[{"batb":[[0,3.05,10],[1,3,18.44],[2,2.6,5.08]],"ltp":3.35,"tv":43.19,"id":11392436}]}]}
{"op":"mcm","clk":"11930552081","pt":1724267268995,"mc":[{"id":"1.232098082","rc":[{"batb":[[0,3,18.44],[1,2.6,5.08],[2,1.04,1.53]],"ltp":3.35,"tv":43.19,"id":11392436}]}]}
{"op":"mcm","clk":"11930553406","pt":1724267278227,"mc":[{"id":"1.232098082","rc":[{"batb":[[0,3.05,10],[1,3,18.44],[2,2.6,5.08]],"ltp":3.35,"tv":43.19,"id":11392436}]}]}
{"op":"mcm","clk":"11930553896","pt":1724267281721,"mc":[{"id":"1.232098082","rc":[{"batb":[[0,3,18.44],[1,2.6,5.08],[2,1.04,1.53]],"ltp":3.35,"tv":43.19,"id":11392436}]}]}
{"op":"mcm","clk":"11930558130","pt":1724267310735,"mc":[{"id":"1.232098082","rc":[{"batb":[[0,3.05,10],[1,3,18.44],[2,2.6,5.08]],"ltp":3.35,"tv":43.19,"id":11392436}]}]}
{"op":"mcm","clk":"11930558577","pt":1724267314054,"mc":[{"id":"1.232098082","rc":[{"batb":[[0,3,18.44],[1,2.6,5.08],[2,1.04,1.53]],"ltp":3.35,"tv":43.19,"id":11392436}]}]}
{"op":"mcm","clk":"11930559687","pt":1724267322389,"mc":[{"id":"1.232098082","rc":[{"batb":[[0,3.05,10],[1,3,18.44],[2,2.6,5.08]],"ltp":3.35,"tv":43.19,"id":11392436}]}]}
{"op":"mcm","clk":"11930560091","pt":1724267325685,"mc":[{"id":"1.232098082","rc":[{"batb":[[0,3,18.44],[1,2.6,5.08],[2,1.04,1.53]],"ltp":3.35,"tv":43.19,"id":11392436}]}]}
{"op":"mcm","clk":"11930561759","pt":1724267338173,"mc":[{"id":"1.232098082","rc":[{"batb":[[0,3.05,10],[1,3,18.44],[2,2.6,5.08]],"ltp":3.35,"tv":43.19,"id":11392436}]}]}
{"op":"mcm","clk":"11930562242","pt":1724267341587,"mc":[{"id":"1.232098082","rc":[{"batb":[[0,3,18.44],[1,2.6,5.08],[2,1.04,1.53]],"ltp":3.35,"tv":43.19,"id":11392436}]}]}
{"op":"mcm","clk":"11930565238","pt":1724267364791,"mc":[{"id":"1.232098082","rc":[{"batb":[[0,3.05,10],[1,3,18.44],[2,2.6,5.08]],"ltp":3.35,"tv":43.19,"id":11392436}]}]}
{"op":"mcm","clk":"11930565640","pt":1724267368218,"mc":[{"id":"1.232098082","rc":[{"batb":[[0,3,18.44],[1,2.6,5.08],[2,1.04,1.53]],"ltp":3.35,"tv":43.19,"id":11392436}]}]}
{"op":"mcm","clk":"11930568034","pt":1724267386822,"mc":[{"id":"1.232098082","rc":[{"batb":[[0,3.05,10],[1,3,18.44],[2,2.6,5.08]],"ltp":3.35,"tv":43.19,"id":11392436}]}]}
{"op":"mcm","clk":"11930568491","pt":1724267390138,"mc":[{"id":"1.232098082","rc":[{"batb":[[0,3,18.44],[1,2.6,5.08],[2,1.04,1.53]],"ltp":3.35,"tv":43.19,"id":11392436}]}]}
{"op":"mcm","clk":"11930572319","pt":1724267419684,"mc":[{"id":"1.232098082","rc":[{"batb":[[0,3.05,10],[1,3,18.44],[2,2.6,5.08]],"ltp":3.35,"tv":43.19,"id":11392436}]}]}
{"op":"mcm","clk":"11930572742","pt":1724267423067,"mc":[{"id":"1.232098082","rc":[{"batb":[[0,3,18.44],[1,2.6,5.08],[2,1.04,1.53]],"ltp":3.35,"tv":43.19,"id":11392436}]}]}
{"op":"mcm","clk":"11930574455","pt":1724267436968,"mc":[{"id":"1.232098082","rc":[{"batb":[[0,3.05,10],[1,3,18.44],[2,2.6,5.08]],"ltp":3.35,"tv":43.19,"id":11392436}]}]}
{"op":"mcm","clk":"11930574885","pt":1724267440273,"mc":[{"id":"1.232098082","rc":[{"batb":[[0,3,18.44],[1,2.6,5.08],[2,1.04,1.53]],"ltp":3.35,"tv":43.19,"id":11392436}]}]}
{"op":"mcm","clk":"11930582626","pt":1724267502546,"mc":[{"id":"1.232098082","rc":[{"batb":[[0,3.05,10],[1,3,18.44],[2,2.6,5.08]],"ltp":3.35,"tv":43.19,"id":11392436},{"trd":[[1.43,230.2]],"batb":[[0,1.43,21.27]],"ltp":1.43,"tv":230.19,"id":48610314}],"tv":273.39}]}
{"op":"mcm","clk":"11930582987","pt":1724267505572,"mc":[{"id":"1.232098082","rc":[{"batb":[[0,1.43,85.77]],"ltp":1.43,"tv":230.19,"id":48610314}]}]}
{"op":"mcm","clk":"11930583041","pt":1724267506041,"mc":[{"id":"1.232098082","rc":[{"batb":[[0,3,18.44],[1,2.6,5.08],[2,1.04,1.53]],"ltp":3.35,"tv":43.19,"id":11392436}]}]}
{"op":"mcm","clk":"11930583668","pt":1724267511435,"mc":[{"id":"1.232098082","rc":[{"batb":[[0,3.05,10],[1,3,18.44],[2,2.6,5.08]],"ltp":3.35,"tv":43.19,"id":11392436}]}]}
{"op":"mcm","clk":"11930584052","pt":1724267514669,"mc":[{"id":"1.232098082","rc":[{"batb":[[0,3,18.44],[1,2.6,5.08],[2,1.04,1.53]],"ltp":3.35,"tv":43.19,"id":11392436}]}]}
{"op":"mcm","clk":"11930586289","pt":1724267532279,"mc":[{"id":"1.232098082","rc":[{"trd":[[3.35,47.09]],"batb":[[0,3.05,10],[1,3,18.44],[2,2.6,5.08]],"ltp":3.35,"tv":47.09,"id":11392436},{"trd":[[1.43,239.33]],"batb":[[0,1.43,76.64]],"ltp":1.43,"tv":239.32,"id":48610314}],"tv":286.41}]}
{"op":"mcm","clk":"11930586764","pt":1724267535699,"mc":[{"id":"1.232098082","rc":[{"batb":[[0,3,18.44],[1,2.6,5.08],[2,1.04,1.53]],"ltp":3.35,"tv":47.09,"id":11392436},{"batb":[[0,1.43,85.77]],"ltp":1.43,"tv":239.32,"id":48610314}]}]}
{"op":"mcm","clk":"11930592980","pt":1724267581388,"mc":[{"id":"1.232098082","rc":[{"batb":[[0,3.05,10],[1,3,18.44],[2,2.6,5.08]],"ltp":3.35,"tv":47.09,"id":11392436}]}]}
{"op":"mcm","clk":"11930593446","pt":1724267584786,"mc":[{"id":"1.232098082","rc":[{"batb":[[0,3,18.44],[1,2.6,5.08],[2,1.04,1.53]],"ltp":3.35,"tv":47.09,"id":11392436}]}]}
{"op":"mcm","clk":"11930595957","pt":1724267603002,"mc":[{"id":"1.232098082","rc":[{"batb":[[0,3.05,10],[1,3,18.44],[2,2.6,5.08]],"ltp":3.35,"tv":47.09,"id":11392436}]}]}
{"op":"mcm","clk":"11930596389","pt":1724267606316,"mc":[{"id":"1.232098082","rc":[{"batb":[[0,3,18.44],[1,2.6,5.08],[2,1.04,1.53]],"ltp":3.35,"tv":47.09,"id":11392436}]}]}
{"op":"mcm","clk":"11930600866","pt":1724267639847,"mc":[{"id":"1.232098082","rc":[{"batb":[[0,3.1,178.43],[1,3,18.44],[2,2.6,5.08]],"ltp":3.35,"tv":47.09,"id":11392436}]}]}
{"op":"mcm","clk":"11930600888","pt":1724267640051,"mc":[{"id":"1.232098082","rc":[{"batb":[[0,3.15,10],[1,3.1,178.43],[2,3,18.44]],"ltp":3.35,"tv":47.09,"id":11392436}]}]}
{"op":"mcm","clk":"11930601316","pt":1724267643266,"mc":[{"id":"1.232098082","rc":[{"batb":[[0,3.1,178.43],[1,3,18.44],[2,2.6,5.08]],"ltp":3.35,"tv":47.09,"id":11392436}]}]}
{"op":"mcm","clk":"11930603867","pt":1724267662367,"mc":[{"id":"1.232098082","rc":[{"batb":[[0,3.15,10],[1,3.1,178.43],[2,3,18.44]],"ltp":3.35,"tv":47.09,"id":11392436}]}]}
{"op":"mcm","clk":"11930604295","pt":1724267665789,"mc":[{"id":"1.232098082","rc":[{"batb":[[0,3.1,178.43],[1,3,18.44],[2,2.6,5.08]],"ltp":3.35,"tv":47.09,"id":11392436}]}]}
{"op":"mcm","clk":"11930604982","pt":1724267671577,"mc":[{"id":"1.232098082","rc":[{"batb":[[0,3.15,10],[1,3.1,178.43],[2,3,18.44]],"ltp":3.35,"tv":47.09,"id":11392436}]}]}
{"op":"mcm","clk":"11930605409","pt":1724267675095,"mc":[{"id":"1.232098082","rc":[{"batb":[[0,3.1,178.43],[1,3,18.44],[2,2.6,5.08]],"ltp":3.35,"tv":47.09,"id":11392436}]}]}
{"op":"mcm","clk":"11930605751","pt":1724267677921,"mc":[{"id":"1.232098082","rc":[{"batb":[[0,3.15,10],[1,3.1,178.43],[2,3,18.44]],"ltp":3.35,"tv":47.09,"id":11392436}]}]}
{"op":"mcm","clk":"11930606149","pt":1724267681187,"mc":[{"id":"1.232098082","rc":[{"batb":[[0,3.1,178.43],[1,3,18.44],[2,2.6,5.08]],"ltp":3.35,"tv":47.09,"id":11392436}]}]}
{"op":"mcm","clk":"11930607475","pt":1724267691982,"mc":[{"id":"1.232098082","rc":[{"batb":[[0,3.15,10],[1,3.1,178.43],[2,3,18.44]],"ltp":3.35,"tv":47.09,"id":11392436}]}]}
{"op":"mcm","clk":"11930607910","pt":1724267695323,"mc":[{"id":"1.232098082","rc":[{"batb":[[0,3.1,178.43],[1,3,18.44],[2,2.6,5.08]],"ltp":3.35,"tv":47.09,"id":11392436}]}]}
{"op":"mcm","clk":"11930610879","pt":1724267719112,"mc":[{"id":"1.232098082","rc":[{"batb":[[0,3.15,10],[1,3.1,178.43],[2,3,18.44]],"ltp":3.35,"tv":47.09,"id":11392436}]}]}
{"op":"mcm","clk":"11930611301","pt":1724267722455,"mc":[{"id":"1.232098082","rc":[{"batb":[[0,3.1,178.43],[1,3,18.44],[2,2.6,5.08]],"ltp":3.35,"tv":47.09,"id":11392436}]}]}
{"op":"mcm","clk":"11930612216","pt":1724267729641,"mc":[{"id":"1.232098082","rc":[{"batb":[[0,3.25,10],[1,3.2,54.29],[2,3.1,178.43]],"ltp":3.35,"tv":47.09,"id":11392436}]}]}
{"op":"mcm","clk":"11930612666","pt":1724267733141,"mc":[{"id":"1.232098082","rc":[{"batb":[[0,3.2,54.29],[1,3.1,178.43],[2,3,18.44]],"ltp":3.35,"tv":47.09,"id":11392436}]}]}
{"op":"mcm","clk":"11930615414","pt":1724267756656,"mc":[{"id":"1.232098082","rc":[{"batb":[[0,3.15,10]],"ltp":3.35,"tv":47.09,"id":11392436}]}]}
{"op":"mcm","clk":"11930615812","pt":1724267760067,"mc":[{"id":"1.232098082","rc":[{"batb":[[0,3.1,178.43],[1,3,18.44],[2,2.6,5.08]],"ltp":3.35,"tv":47.09,"id":11392436}]}]}
{"op":"mcm","clk":"11930619349","pt":1724267787512,"mc":[{"id":"1.232098082","rc":[{"batb":[[0,3.15,10],[1,3.1,178.43],[2,3,18.44]],"ltp":3.35,"tv":47.09,"id":11392436}]}]}
{"op":"mcm","clk":"11930619722","pt":1724267790914,"mc":[{"id":"1.232098082","rc":[{"batb":[[0,3.1,178.43],[1,3,18.44],[2,2.6,5.08]],"ltp":3.35,"tv":47.09,"id":11392436}]}]}
{"op":"mcm","clk":"11930620145","pt":1724267794398,"mc":[{"id":"1.232098082","rc":[{"batb":[[0,3.15,10],[1,3.1,178.43],[2,3,18.44]],"ltp":3.35,"tv":47.09,"id":11392436}]}]}
{"op":"mcm","clk":"11930620600","pt":1724267797796,"mc":[{"id":"1.232098082","rc":[{"batb":[[0,3.1,178.43],[1,3,18.44],[2,2.6,5.08]],"ltp":3.35,"tv":47.09,"id":11392436}]}]}
{"op":"mcm","clk":"11930620958","pt":1724267800777,"mc":[{"id":"1.232098082","rc":[{"batb":[[0,3.15,10],[1,3.1,178.43],[2,3,18.44]],"ltp":3.35,"tv":47.09,"id":11392436}]}]}
{"op":"mcm","clk":"11930621342","pt":1724267804118,"mc":[{"id":"1.232098082","rc":[{"batb":[[0,3.1,178.43],[1,3,18.44],[2,2.6,5.08]],"ltp":3.35,"tv":47.09,"id":11392436}]}]}
{"op":"mcm","clk":"11930623055","pt":1724267817704,"mc":[{"id":"1.232098082","rc":[{"batb":[[0,3.15,10],[1,3.1,178.43],[2,3,18.44]],"ltp":3.35,"tv":47.09,"id":11392436}]}]}
{"op":"mcm","clk":"11930623479","pt":1724267821106,"mc":[{"id":"1.232098082","rc":[{"batb":[[0,3.1,178.43],[1,3,18.44],[2,2.6,5.08]],"ltp":3.35,"tv":47.09,"id":11392436}]}]}
{"op":"mcm","clk":"11930625066","pt":1724267833337,"mc":[{"id":"1.232098082","rc":[{"batb":[[0,3.15,10],[1,3.1,178.43],[2,3,18.44]],"ltp":3.35,"tv":47.09,"id":11392436}]}]}
{"op":"mcm","clk":"11930625311","pt":1724267835132,"mc":[{"id":"1.232098082","rc":[{"trd":[[3.35,60.97]],"ltp":3.35,"tv":60.97,"id":11392436},{"trd":[[1.43,271.85]],"batb":[[0,1.43,53.25]],"ltp":1.43,"tv":271.84,"id":48610314}],"tv":332.81}]}
{"op":"mcm","clk":"11930625526","pt":1724267836849,"mc":[{"id":"1.232098082","rc":[{"batb":[[0,3.1,178.43],[1,3,18.44],[2,2.6,5.08]],"ltp":3.35,"tv":60.97,"id":11392436},{"batb":[[0,1.43,85.77]],"ltp":1.43,"tv":271.84,"id":48610314}]}]}
{"op":"mcm","clk":"11930627347","pt":1724267848324,"mc":[{"id":"1.232098082","rc":[{"batb":[[0,3.15,10],[1,3.1,178.43],[2,3,18.44]],"ltp":3.35,"tv":60.97,"id":11392436}]}]}
{"op":"mcm","clk":"11930627871","pt":1724267851645,"mc":[{"id":"1.232098082","rc":[{"batb":[[0,3.1,178.43],[1,3,18.44],[2,2.6,5.08]],"ltp":3.35,"tv":60.97,"id":11392436}]}]}
{"op":"mcm","clk":"11930632159","pt":1724267883786,"mc":[{"id":"1.232098082","rc":[{"trd":[[3.35,67.14]],"batb":[[0,3.15,10],[1,3.1,178.43],[2,3,18.44]],"ltp":3.35,"tv":67.14,"id":11392436},{"trd":[[1.43,286.31]],"batb":[[0,1.43,71.31]],"ltp":1.43,"tv":286.3,"id":48610314}],"tv":353.45}]}
{"op":"mcm","clk":"11930632501","pt":1724267886372,"mc":[{"id":"1.232098082","rc":[{"batb":[[0,1.43,85.77]],"ltp":1.43,"tv":286.3,"id":48610314}]}]}
{"op":"mcm","clk":"11930632581","pt":1724267887001,"mc":[{"id":"1.232098082","rc":[{"batb":[[0,3.1,178.43],[1,3,18.44],[2,2.6,5.08]],"ltp":3.35,"tv":67.14,"id":11392436}]}]}
{"op":"mcm","clk":"11930633190","pt":1724267891794,"mc":[{"id":"1.232098082","rc":[{"batb":[[0,3.15,10],[1,3.1,178.43],[2,3,18.44]],"ltp":3.35,"tv":67.14,"id":11392436}]}]}
{"op":"mcm","clk":"11930633361","pt":1724267893574,"mc":[{"id":"1.232098082","rc":[{"batb":[[1,3,18.44],[2,2.6,5.08]],"ltp":3.35,"tv":67.14,"id":11392436}]}]}
{"op":"mcm","clk":"11930633573","pt":1724267895094,"mc":[{"id":"1.232098082","rc":[{"batb":[[0,3,18.44],[1,2.6,5.08],[2,1.04,1.53]],"ltp":3.35,"tv":67.14,"id":11392436}]}]}
{"op":"mcm","clk":"11930635121","pt":1724267906583,"mc":[{"id":"1.232098082","rc":[{"batb":[[0,3.05,10],[1,3,18.44],[2,2.6,5.08]],"ltp":3.35,"tv":67.14,"id":11392436}]}]}
{"op":"mcm","clk":"11930635501","pt":1724267909986,"mc":[{"id":"1.232098082","rc":[{"batb":[[0,3,18.44],[1,2.6,5.08],[2,1.04,1.53]],"ltp":3.35,"tv":67.14,"id":11392436}]}]}
{"op":"mcm","clk":"11930637752","pt":1724267929748,"mc":[{"id":"1.232098082","rc":[{"batb":[[0,3.05,10],[1,3,18.44],[2,2.6,5.08]],"ltp":3.35,"tv":67.14,"id":11392436}]}]}
{"op":"mcm","clk":"11930638198","pt":1724267933216,"mc":[{"id":"1.232098082","rc":[{"batb":[[0,3,18.44],[1,2.6,5.08],[2,1.04,1.53]],"ltp":3.35,"tv":67.14,"id":11392436}]}]}
{"op":"mcm","clk":"11930640686","pt":1724267955740,"mc":[{"id":"1.232098082","rc":[{"batb":[[0,3.05,10],[1,3,18.44],[2,2.6,5.08]],"ltp":3.35,"tv":67.14,"id":11392436},{"trd":[[1.43,395.52]],"batb":[[0,1.43,31.16]],"ltp":1.43,"tv":395.52,"id":48610314}],"tv":462.66}]}
{"op":"mcm","clk":"11930640789","pt":1724267956672,"mc":[{"id":"1.232098082","rc":[{"batb":[[0,1.43,85.77]],"ltp":1.43,"tv":395.52,"id":48610314}]}]}
{"op":"mcm","clk":"11930641040","pt":1724267959068,"mc":[{"id":"1.232098082","rc":[{"batb":[[0,3,18.44],[1,2.6,5.08],[2,1.04,1.53]],"ltp":3.35,"tv":67.14,"id":11392436}]}]}
{"op":"mcm","clk":"11930641285","pt":1724267961271,"mc":[{"id":"1.232098082","rc":[{"batb":[[0,3.05,10],[1,3,18.44],[2,2.6,5.08]],"ltp":3.35,"tv":67.14,"id":11392436}]}]}
{"op":"mcm","clk":"11930641658","pt":1724267964657,"mc":[{"id":"1.232098082","rc":[{"batb":[[0,3,18.44],[1,2.6,5.08],[2,1.04,1.53]],"ltp":3.35,"tv":67.14,"id":11392436}]}]}
{"op":"mcm","clk":"11930646422","pt":1724268006007,"mc":[{"id":"1.232098082","rc":[{"batb":[[0,3.05,10],[1,3,18.44],[2,2.6,5.08]],"ltp":3.35,"tv":67.14,"id":11392436}]}]}
{"op":"mcm","clk":"11930646826","pt":1724268009403,"mc":[{"id":"1.232098082","rc":[{"batb":[[0,3,18.44],[1,2.6,5.08],[2,1.04,1.53]],"ltp":3.35,"tv":67.14,"id":11392436}]}]}
{"op":"mcm","clk":"11930649826","pt":1724268033546,"mc":[{"id":"1.232098082","rc":[{"batb":[[0,3.05,10],[1,3,18.44],[2,2.6,5.08]],"ltp":3.35,"tv":67.14,"id":11392436}]}]}
{"op":"mcm","clk":"11930650271","pt":1724268036743,"mc":[{"id":"1.232098082","rc":[{"batb":[[0,3,18.44],[1,2.6,5.08],[2,1.04,1.53]],"ltp":3.35,"tv":67.14,"id":11392436}]}]}
{"op":"mcm","clk":"11930650645","pt":1724268039761,"mc":[{"id":"1.232098082","rc":[{"batb":[[0,3.05,10],[1,3,18.44],[2,2.6,5.08]],"ltp":3.35,"tv":67.14,"id":11392436}]}]}
{"op":"mcm","clk":"11930651036","pt":1724268043144,"mc":[{"id":"1.232098082","rc":[{"batb":[[0,3,18.44],[1,2.6,5.08],[2,1.04,1.53]],"ltp":3.35,"tv":67.14,"id":11392436}]}]}
{"op":"mcm","clk":"11930654594","pt":1724268074382,"mc":[{"id":"1.232098082","rc":[{"batb":[[0,3.05,10],[1,3,18.44],[2,2.6,5.08]],"ltp":3.35,"tv":67.14,"id":11392436}]}]}
{"op":"mcm","clk":"11930655010","pt":1724268077692,"mc":[{"id":"1.232098082","rc":[{"batb":[[0,3,18.44],[1,2.6,5.08],[2,1.04,1.53]],"ltp":3.35,"tv":67.14,"id":11392436}]}]}
{"op":"mcm","clk":"11930656720","pt":1724268092721,"mc":[{"id":"1.232098082","rc":[{"trd":[[3.35,73.31]],"batb":[[0,3.05,10],[1,3,18.44],[2,2.6,5.08]],"ltp":3.35,"tv":73.31,"id":11392436},{"trd":[[1.43,409.98]],"batb":[[0,1.43,71.31]],"ltp":1.43,"tv":409.98,"id":48610314}],"tv":483.29}]}
{"op":"mcm","clk":"11930657107","pt":1724268096197,"mc":[{"id":"1.232098082","rc":[{"batb":[[0,3,18.44],[1,2.6,5.08],[2,1.04,1.53]],"ltp":3.35,"tv":73.31,"id":11392436}]}]}
{"op":"mcm","clk":"11930657195","pt":1724268097012,"mc":[{"id":"1.232098082","rc":[{"batb":[[0,1.43,79.01]],"ltp":1.43,"tv":409.98,"id":48610314}]}]}
{"op":"mcm","clk":"11930658701","pt":1724268109730,"mc":[{"id":"1.232098082","rc":[{"batb":[[0,3.05,10],[1,3,18.44],[2,2.6,5.08]],"ltp":3.35,"tv":73.31,"id":11392436},{"trd":[[1.43,566.65]],"batb":[[0,1.04,2.21],[1,1.03,200],[2,1.02,200]],"ltp":1.43,"tv":566.64,"id":48610314}],"tv":639.95}]}
{"op":"mcm","clk":"11930658989","pt":1724268112026,"mc":[{"id":"1.232098082","rc":[{"batb":[[0,1.39,8.7],[1,1.04,1.53],[2,1.03,200]],"ltp":1.43,"tv":566.64,"id":48610314}]}]}
{"op":"mcm","clk":"11930659100","pt":1724268112921,"mc":[{"id":"1.232098082","rc":[{"batb":[[0,3,18.44],[1,2.6,5.08],[2,1.04,1.53]],"ltp":3.35,"tv":73.31,"id":11392436}]}]}
{"op":"mcm","clk":"11930667478","pt":1724268182199,"mc":[{"id":"1.232098082","rc":[{"trd":[[3.6,2.54]],"batb":[[0,3.05,10],[1,3,18.44],[2,2.6,5.08]],"ltp":3.6,"tv":75.85,"id":11392436},{"trd":[[1.39,6.58]],"batb":[[0,1.39,2.12]],"ltp":1.39,"tv":573.22,"id":48610314}],"tv":649.08}]}
{"op":"mcm","clk":"11930667843","pt":1724268185489,"mc":[{"id":"1.232098082","rc":[{"batb":[[0,3,18.44],[1,2.6,5.08],[2,1.04,1.53]],"ltp":3.6,"tv":75.85,"id":11392436}]}]}
{"op":"mcm","clk":"11930668010","pt":1724268187211,"mc":[{"id":"1.232098082","rc":[{"batb":[[0,1.39,5]],"ltp":1.39,"tv":573.22,"id":48610314}]}]}
{"op":"mcm","clk":"11930686037","pt":1724268341759,"mc":[{"id":"1.232098082","rc":[{"batb":[[0,3.05,10],[1,3,18.44],[2,2.6,5.08]],"ltp":3.6,"tv":75.85,"id":11392436}]}]}
{"op":"mcm","clk":"11930686477","pt":1724268345065,"mc":[{"id":"1.232098082","rc":[{"batb":[[0,3,18.44],[1,2.6,5.08],[2,1.04,1.53]],"ltp":3.6,"tv":75.85,"id":11392436}]}]}
{"op":"mcm","clk":"11930694271","pt":1724268406046,"mc":[{"id":"1.232098082","rc":[{"batb":[[0,3.05,10],[1,3,18.44],[2,2.6,5.08]],"ltp":3.6,"tv":75.85,"id":11392436}]}]}
{"op":"mcm","clk":"11930694696","pt":1724268409375,"mc":[{"id":"1.232098082","rc":[{"batb":[[0,3,18.44],[1,2.6,5.08],[2,1.04,1.53]],"ltp":3.6,"tv":75.85,"id":11392436}]}]}
{"op":"mcm","clk":"11930695068","pt":1724268412271,"mc":[{"id":"1.232098082","rc":[{"batb":[[0,3.05,10],[1,3,18.44],[2,2.6,5.08]],"ltp":3.6,"tv":75.85,"id":11392436}]}]}
{"op":"mcm","clk":"11930695482","pt":1724268415467,"mc":[{"id":"1.232098082","rc":[{"batb":[[0,3,18.44],[1,2.6,5.08],[2,1.04,1.53]],"ltp":3.6,"tv":75.85,"id":11392436}]}]}
{"op":"mcm","clk":"11930701848","pt":1724268465218,"mc":[{"id":"1.232098082","rc":[{"batb":[[0,3.05,10],[1,3,18.44],[2,2.6,5.08]],"ltp":3.6,"tv":75.85,"id":11392436}]}]}
{"op":"mcm","clk":"11930702205","pt":1724268468622,"mc":[{"id":"1.232098082","rc":[{"batb":[[0,3,18.44],[1,2.6,5.08],[2,1.04,1.53]],"ltp":3.6,"tv":75.85,"id":11392436}]}]}
{"op":"mcm","clk":"11930703869","pt":1724268484326,"mc":[{"id":"1.232098082","rc":[{"batb":[[0,3.05,10],[1,3,18.44],[2,2.6,5.08]],"ltp":3.6,"tv":75.85,"id":11392436}]}]}
{"op":"mcm","clk":"11930704232","pt":1724268487726,"mc":[{"id":"1.232098082","rc":[{"batb":[[0,3,18.44],[1,2.6,5.08],[2,1.04,1.53]],"ltp":3.6,"tv":75.85,"id":11392436}]}]}
{"op":"mcm","clk":"11930706171","pt":1724268505874,"mc":[{"id":"1.232098082","rc":[{"batb":[[0,3.05,10],[1,3,18.44],[2,2.6,5.08]],"ltp":3.6,"tv":75.85,"id":11392436}]}]}
{"op":"mcm","clk":"11930706535","pt":1724268509181,"mc":[{"id":"1.232098082","rc":[{"batb":[[0,3,18.44],[1,2.6,5.08],[2,1.04,1.53]],"ltp":3.6,"tv":75.85,"id":11392436}]}]}
{"op":"mcm","clk":"11930709159","pt":1724268531996,"mc":[{"id":"1.232098082","rc":[{"batb":[[0,3.05,10],[1,3,18.44],[2,2.6,5.08]],"ltp":3.6,"tv":75.85,"id":11392436}]}]}
{"op":"mcm","clk":"11930709508","pt":1724268535390,"mc":[{"id":"1.232098082","rc":[{"batb":[[0,3,18.44],[1,2.6,5.08],[2,1.04,1.53]],"ltp":3.6,"tv":75.85,"id":11392436}]}]}
{"op":"mcm","clk":"11930712365","pt":1724268560747,"mc":[{"id":"1.232098082","rc":[{"batb":[[0,3.05,10],[1,3,18.44],[2,2.6,5.08]],"ltp":3.6,"tv":75.85,"id":11392436}]}]}
{"op":"mcm","clk":"11930712720","pt":1724268563937,"mc":[{"id":"1.232098082","rc":[{"batb":[[0,3,18.44],[1,2.6,5.08],[2,1.04,1.53]],"ltp":3.6,"tv":75.85,"id":11392436}]}]}
{"op":"mcm","clk":"11930714712","pt":1724268579758,"mc":[{"id":"1.232098082","rc":[{"batb":[[0,3.05,10],[1,3,18.44],[2,2.6,5.08]],"ltp":3.6,"tv":75.85,"id":11392436}]}]}
{"op":"mcm","clk":"11930715076","pt":1724268583052,"mc":[{"id":"1.232098082","rc":[{"batb":[[0,3,18.44],[1,2.6,5.08],[2,1.04,1.53]],"ltp":3.6,"tv":75.85,"id":11392436}]}]}
{"op":"mcm","clk":"11930715401","pt":1724268585470,"mc":[{"id":"1.232098082","rc":[{"batb":[[0,3.05,10],[1,3,18.44],[2,2.6,5.08]],"ltp":3.6,"tv":75.85,"id":11392436}]}]}
{"op":"mcm","clk":"11930715826","pt":1724268588798,"mc":[{"id":"1.232098082","rc":[{"batb":[[0,3,18.44],[1,2.6,5.08],[2,1.04,1.53]],"ltp":3.6,"tv":75.85,"id":11392436}]}]}
{"op":"mcm","clk":"11930716276","pt":1724268592488,"mc":[{"id":"1.232098082","rc":[{"batb":[[0,3.05,10],[1,3,18.44],[2,2.6,5.08]],"ltp":3.6,"tv":75.85,"id":11392436}]}]}
{"op":"mcm","clk":"11930716733","pt":1724268595968,"mc":[{"id":"1.232098082","rc":[{"batb":[[0,3,18.44],[1,2.6,5.08],[2,1.04,1.53]],"ltp":3.6,"tv":75.85,"id":11392436}]}]}
{"op":"mcm","clk":"11930719733","pt":1724268619093,"mc":[{"id":"1.232098082","rc":[{"batb":[[0,3.05,10],[1,3,18.44],[2,2.6,5.08]],"ltp":3.6,"tv":75.85,"id":11392436}]}]}
{"op":"mcm","clk":"11930720162","pt":1724268622500,"mc":[{"id":"1.232098082","rc":[{"batb":[[0,3,18.44],[1,2.6,5.08],[2,1.04,1.53]],"ltp":3.6,"tv":75.85,"id":11392436}]}]}
{"op":"mcm","clk":"11930722694","pt":1724268642957,"mc":[{"id":"1.232098082","rc":[{"batb":[[0,3.05,10],[1,3,18.44],[2,2.6,5.08]],"ltp":3.6,"tv":75.85,"id":11392436}]}]}
{"op":"mcm","clk":"11930723146","pt":1724268646131,"mc":[{"id":"1.232098082","rc":[{"batb":[[0,3,18.44],[1,2.6,5.08],[2,1.04,1.53]],"ltp":3.6,"tv":75.85,"id":11392436}]}]}
{"op":"mcm","clk":"11930725037","pt":1724268661054,"mc":[{"id":"1.232098082","rc":[{"batb":[[0,3.05,10],[1,3,18.44],[2,2.6,5.08]],"ltp":3.6,"tv":75.85,"id":11392436}]}]}
{"op":"mcm","clk":"11930725406","pt":1724268664457,"mc":[{"id":"1.232098082","rc":[{"batb":[[0,3,18.44],[1,2.6,5.08],[2,1.04,1.53]],"ltp":3.6,"tv":75.85,"id":11392436}]}]}
{"op":"mcm","clk":"11930727607","pt":1724268682076,"mc":[{"id":"1.232098082","rc":[{"batb":[[0,3.05,10],[1,3,18.44],[2,2.6,5.08]],"ltp":3.6,"tv":75.85,"id":11392436}]}]}
{"op":"mcm","clk":"11930728016","pt":1724268685486,"mc":[{"id":"1.232098082","rc":[{"batb":[[0,3,18.44],[1,2.6,5.08],[2,1.04,1.53]],"ltp":3.6,"tv":75.85,"id":11392436}]}]}
{"op":"mcm","clk":"11930730236","pt":1724268704591,"mc":[{"id":"1.232098082","rc":[{"batb":[[0,3.05,10],[1,3,18.44],[2,2.6,5.08]],"ltp":3.6,"tv":75.85,"id":11392436}]}]}
{"op":"mcm","clk":"11930730700","pt":1724268707989,"mc":[{"id":"1.232098082","rc":[{"batb":[[0,3,18.44],[1,2.6,5.08],[2,1.04,1.53]],"ltp":3.6,"tv":75.85,"id":11392436}]}]}
{"op":"mcm","clk":"11930731139","pt":1724268711598,"mc":[{"id":"1.232098082","rc":[{"batb":[[0,3.05,10],[1,3,18.44],[2,2.6,5.08]],"ltp":3.6,"tv":75.85,"id":11392436}]}]}
{"op":"mcm","clk":"11930731563","pt":1724268715045,"mc":[{"id":"1.232098082","rc":[{"batb":[[0,3,18.44],[1,2.6,5.08],[2,1.04,1.53]],"ltp":3.6,"tv":75.85,"id":11392436}]}]}
{"op":"mcm","clk":"11930731999","pt":1724268718221,"mc":[{"id":"1.232098082","rc":[{"batb":[[0,3.05,10],[1,3,18.44],[2,2.6,5.08]],"ltp":3.6,"tv":75.85,"id":11392436}]}]}
{"op":"mcm","clk":"11930732407","pt":1724268721522,"mc":[{"id":"1.232098082","rc":[{"batb":[[0,3,18.44],[1,2.6,5.08],[2,1.04,1.53]],"ltp":3.6,"tv":75.85,"id":11392436}]}]}
{"op":"mcm","clk":"11930734599","pt":1724268739019,"mc":[{"id":"1.232098082","rc":[{"batb":[[0,3.05,10],[1,3,18.44],[2,2.6,5.08]],"ltp":3.6,"tv":75.85,"id":11392436}]}]}
{"op":"mcm","clk":"11930735045","pt":1724268742435,"mc":[{"id":"1.232098082","rc":[{"batb":[[0,3,18.44],[1,2.6,5.08],[2,1.04,1.53]],"ltp":3.6,"tv":75.85,"id":11392436}]}]}
{"op":"mcm","clk":"11930735934","pt":1724268749836,"mc":[{"id":"1.232098082","rc":[{"batb":[[0,3.05,10],[1,3,18.44],[2,2.6,5.08]],"ltp":3.6,"tv":75.85,"id":11392436}]}]}
{"op":"mcm","clk":"11930736400","pt":1724268753342,"mc":[{"id":"1.232098082","rc":[{"batb":[[0,3,18.44],[1,2.6,5.08],[2,1.04,1.53]],"ltp":3.6,"tv":75.85,"id":11392436}]}]}
{"op":"mcm","clk":"11930737235","pt":1724268760239,"mc":[{"id":"1.232098082","rc":[{"batb":[[0,3.05,10],[1,3,18.44],[2,2.6,5.08]],"ltp":3.6,"tv":75.85,"id":11392436}]}]}
{"op":"mcm","clk":"11930737610","pt":1724268763683,"mc":[{"id":"1.232098082","rc":[{"batb":[[0,3,18.44],[1,2.6,5.08],[2,1.04,1.53]],"ltp":3.6,"tv":75.85,"id":11392436}]}]}
{"op":"mcm","clk":"11930740984","pt":1724268791282,"mc":[{"id":"1.232098082","rc":[{"batb":[[0,3.05,10],[1,3,18.44],[2,2.6,5.08]],"ltp":3.6,"tv":75.85,"id":11392436}]}]}
{"op":"mcm","clk":"11930741459","pt":1724268794784,"mc":[{"id":"1.232098082","rc":[{"batb":[[0,3,18.44],[1,2.6,5.08],[2,1.04,1.53]],"ltp":3.6,"tv":75.85,"id":11392436}]}]}
{"op":"mcm","clk":"11930752069","pt":1724268881849,"mc":[{"id":"1.232098082","rc":[{"batb":[[0,3.05,10],[1,3,18.44],[2,2.6,5.08]],"ltp":3.6,"tv":75.85,"id":11392436}]}]}
{"op":"mcm","clk":"11930752445","pt":1724268885166,"mc":[{"id":"1.232098082","rc":[{"batb":[[0,3,18.44],[1,2.6,5.08],[2,1.04,1.53]],"ltp":3.6,"tv":75.85,"id":11392436}]}]}
{"op":"mcm","clk":"11930752883","pt":1724268888659,"mc":[{"id":"1.232098082","rc":[{"batb":[[0,3.05,10],[1,3,18.44],[2,2.6,5.08]],"ltp":3.6,"tv":75.85,"id":11392436}]}]}
{"op":"mcm","clk":"11930753301","pt":1724268892100,"mc":[{"id":"1.232098082","rc":[{"batb":[[0,3,18.44],[1,2.6,5.08],[2,1.04,1.53]],"ltp":3.6,"tv":75.85,"id":11392436}]}]}
{"op":"mcm","clk":"11930754514","pt":1724268902199,"mc":[{"id":"1.232098082","rc":[{"batb":[[0,3.05,10],[1,3,18.44],[2,2.6,5.08]],"ltp":3.6,"tv":75.85,"id":11392436}]}]}
{"op":"mcm","clk":"11930754866","pt":1724268905588,"mc":[{"id":"1.232098082","rc":[{"batb":[[0,3,18.44],[1,2.6,5.08],[2,1.04,1.53]],"ltp":3.6,"tv":75.85,"id":11392436}]}]}
{"op":"mcm","clk":"11930758602","pt":1724268938035,"mc":[{"id":"1.232098082","rc":[{"batb":[[0,3.05,10],[1,3,18.44],[2,2.6,5.08]],"ltp":3.6,"tv":75.85,"id":11392436}]}]}
{"op":"mcm","clk":"11930759028","pt":1724268941441,"mc":[{"id":"1.232098082","rc":[{"batb":[[0,3,18.44],[1,2.6,5.08],[2,1.04,1.53]],"ltp":3.6,"tv":75.85,"id":11392436}]}]}
{"op":"mcm","clk":"11930762121","pt":1724268964780,"mc":[{"id":"1.232098082","rc":[{"batb":[[0,3.05,10],[1,3,18.44],[2,2.6,5.08]],"ltp":3.6,"tv":75.85,"id":11392436}]}]}
{"op":"mcm","clk":"11930762565","pt":1724268968178,"mc":[{"id":"1.232098082","rc":[{"batb":[[0,3,18.44],[1,2.6,5.08],[2,1.04,1.53]],"ltp":3.6,"tv":75.85,"id":11392436}]}]}
{"op":"mcm","clk":"11930766307","pt":1724268998788,"mc":[{"id":"1.232098082","rc":[{"batb":[[0,3.05,10],[1,3,18.44],[2,2.6,5.08]],"ltp":3.6,"tv":75.85,"id":11392436}]}]}
{"op":"mcm","clk":"11930766704","pt":1724269002223,"mc":[{"id":"1.232098082","rc":[{"batb":[[0,3,18.44],[1,2.6,5.08],[2,1.04,1.53]],"ltp":3.6,"tv":75.85,"id":11392436}]}]}
{"op":"mcm","clk":"11930767178","pt":1724269006814,"mc":[{"id":"1.232098082","rc":[{"batb":[[0,3.05,10],[1,3,18.44],[2,2.6,5.08]],"ltp":3.6,"tv":75.85,"id":11392436}]}]}
{"op":"mcm","clk":"11930767579","pt":1724269010205,"mc":[{"id":"1.232098082","rc":[{"batb":[[0,3,18.44],[1,2.6,5.08],[2,1.04,1.53]],"ltp":3.6,"tv":75.85,"id":11392436}]}]}
{"op":"mcm","clk":"11930768394","pt":1724269017027,"mc":[{"id":"1.232098082","rc":[{"batb":[[0,3.05,10],[1,3,18.44],[2,2.6,5.08]],"ltp":3.6,"tv":75.85,"id":11392436}]}]}
{"op":"mcm","clk":"11930768792","pt":1724269020414,"mc":[{"id":"1.232098082","rc":[{"batb":[[0,3,18.44],[1,2.6,5.08],[2,1.04,1.53]],"ltp":3.6,"tv":75.85,"id":11392436}]}]}
{"op":"mcm","clk":"11930769473","pt":1724269026514,"mc":[{"id":"1.232098082","rc":[{"batb":[[0,3.05,10],[1,3,18.44],[2,2.6,5.08]],"ltp":3.6,"tv":75.85,"id":11392436}]}]}
{"op":"mcm","clk":"11930769836","pt":1724269029841,"mc":[{"id":"1.232098082","rc":[{"batb":[[0,3,18.44],[1,2.6,5.08],[2,1.04,1.53]],"ltp":3.6,"tv":75.85,"id":11392436}]}]}
{"op":"mcm","clk":"11930770780","pt":1724269037849,"mc":[{"id":"1.232098082","rc":[{"batb":[[0,3.05,10],[1,3,18.44],[2,2.6,5.08]],"ltp":3.6,"tv":75.85,"id":11392436}]}]}
{"op":"mcm","clk":"11930771155","pt":1724269041145,"mc":[{"id":"1.232098082","rc":[{"batb":[[0,3,18.44],[1,2.6,5.08],[2,1.04,1.53]],"ltp":3.6,"tv":75.85,"id":11392436}]}]}
{"op":"mcm","clk":"11930772009","pt":1724269047141,"mc":[{"id":"1.232098082","rc":[{"batb":[[0,3.05,10],[1,3,18.44],[2,2.6,5.08]],"ltp":3.6,"tv":75.85,"id":11392436}]}]}
{"op":"mcm","clk":"11930772515","pt":1724269050531,"mc":[{"id":"1.232098082","rc":[{"batb":[[0,3,18.44],[1,2.6,5.08],[2,1.04,1.53]],"ltp":3.6,"tv":75.85,"id":11392436}]}]}
{"op":"mcm","clk":"11930772802","pt":1724269052973,"mc":[{"id":"1.232098082","rc":[{"batb":[[0,3.05,10],[1,3,18.44],[2,2.6,5.08]],"ltp":3.6,"tv":75.85,"id":11392436}]}]}
{"op":"mcm","clk":"11930773238","pt":1724269056247,"mc":[{"id":"1.232098082","rc":[{"batb":[[0,3,18.44],[1,2.6,5.08],[2,1.04,1.53]],"ltp":3.6,"tv":75.85,"id":11392436}]}]}
{"op":"mcm","clk":"11930773707","pt":1724269060151,"mc":[{"id":"1.232098082","rc":[{"batb":[[0,3.05,10],[1,3,18.44],[2,2.6,5.08]],"ltp":3.6,"tv":75.85,"id":11392436}]}]}
{"op":"mcm","clk":"11930774123","pt":1724269063483,"mc":[{"id":"1.232098082","rc":[{"batb":[[0,3,18.44],[1,2.6,5.08],[2,1.04,1.53]],"ltp":3.6,"tv":75.85,"id":11392436}]}]}
{"op":"mcm","clk":"11930774967","pt":1724269070556,"mc":[{"id":"1.232098082","rc":[{"batb":[[0,3.05,10],[1,3,18.44],[2,2.6,5.08]],"ltp":3.6,"tv":75.85,"id":11392436}]}]}
{"op":"mcm","clk":"11930775379","pt":1724269073996,"mc":[{"id":"1.232098082","rc":[{"batb":[[0,3,18.44],[1,2.6,5.08],[2,1.04,1.53]],"ltp":3.6,"tv":75.85,"id":11392436}]}]}
{"op":"mcm","clk":"11930775994","pt":1724269078680,"mc":[{"id":"1.232098082","rc":[{"batb":[[0,3.05,10],[1,3,18.44],[2,2.6,5.08]],"ltp":3.6,"tv":75.85,"id":11392436}]}]}
{"op":"mcm","clk":"11930776416","pt":1724269081966,"mc":[{"id":"1.232098082","rc":[{"batb":[[0,3,18.44],[1,2.6,5.08],[2,1.04,1.53]],"ltp":3.6,"tv":75.85,"id":11392436}]}]}
{"op":"mcm","clk":"11930777109","pt":1724269087091,"mc":[{"id":"1.232098082","rc":[{"batb":[[0,3.05,10],[1,3,18.44],[2,2.6,5.08]],"ltp":3.6,"tv":75.85,"id":11392436}]}]}
{"op":"mcm","clk":"11930777560","pt":1724269090372,"mc":[{"id":"1.232098082","rc":[{"batb":[[0,3,18.44],[1,2.6,5.08],[2,1.04,1.53]],"ltp":3.6,"tv":75.85,"id":11392436}]}]}
{"op":"mcm","clk":"11930777923","pt":1724269092976,"mc":[{"id":"1.232098082","rc":[{"batb":[[0,3.05,10],[1,3,18.44],[2,2.6,5.08]],"ltp":3.6,"tv":75.85,"id":11392436}]}]}
{"op":"mcm","clk":"11930778385","pt":1724269096317,"mc":[{"id":"1.232098082","rc":[{"batb":[[0,3,18.44],[1,2.6,5.08],[2,1.04,1.53]],"ltp":3.6,"tv":75.85,"id":11392436}]}]}
{"op":"mcm","clk":"11930780153","pt":1724269110099,"mc":[{"id":"1.232098082","rc":[{"batb":[[0,3.05,10],[1,3,18.44],[2,2.6,5.08]],"ltp":3.6,"tv":75.85,"id":11392436}]}]}
{"op":"mcm","clk":"11930780528","pt":1724269113281,"mc":[{"id":"1.232098082","rc":[{"batb":[[0,3,18.44],[1,2.6,5.08],[2,1.04,1.53]],"ltp":3.6,"tv":75.85,"id":11392436}]}]}
{"op":"mcm","clk":"11930781338","pt":1724269120114,"mc":[{"id":"1.232098082","rc":[{"batb":[[0,3.05,10],[1,3,18.44],[2,2.6,5.08]],"ltp":3.6,"tv":75.85,"id":11392436}]}]}
{"op":"mcm","clk":"11930781770","pt":1724269123403,"mc":[{"id":"1.232098082","rc":[{"batb":[[0,3,18.44],[1,2.6,5.08],[2,1.04,1.53]],"ltp":3.6,"tv":75.85,"id":11392436}]}]}
{"op":"mcm","clk":"11930782396","pt":1724269128815,"mc":[{"id":"1.232098082","rc":[{"batb":[[0,3.05,10],[1,3,18.44],[2,2.6,5.08]],"ltp":3.6,"tv":75.85,"id":11392436}]}]}
{"op":"mcm","clk":"11930782775","pt":1724269132115,"mc":[{"id":"1.232098082","rc":[{"batb":[[0,3,18.44],[1,2.6,5.08],[2,1.04,1.53]],"ltp":3.6,"tv":75.85,"id":11392436}]}]}
{"op":"mcm","clk":"11930783092","pt":1724269134827,"mc":[{"id":"1.232098082","rc":[{"batb":[[0,3.05,10],[1,3,18.44],[2,2.6,5.08]],"ltp":3.6,"tv":75.85,"id":11392436}]}]}
{"op":"mcm","clk":"11930783525","pt":1724269138117,"mc":[{"id":"1.232098082","rc":[{"batb":[[0,3,18.44],[1,2.6,5.08],[2,1.04,1.53]],"ltp":3.6,"tv":75.85,"id":11392436}]}]}
{"op":"mcm","clk":"11930784006","pt":1724269142024,"mc":[{"id":"1.232098082","rc":[{"batb":[[0,3.05,10],[1,3,18.44],[2,2.6,5.08]],"ltp":3.6,"tv":75.85,"id":11392436}]}]}
{"op":"mcm","clk":"11930784412","pt":1724269145219,"mc":[{"id":"1.232098082","rc":[{"batb":[[0,3,18.44],[1,2.6,5.08],[2,1.04,1.53]],"ltp":3.6,"tv":75.85,"id":11392436}]}]}
{"op":"mcm","clk":"11930785176","pt":1724269151530,"mc":[{"id":"1.232098082","rc":[{"batb":[[0,3.05,10],[1,3,18.44],[2,2.6,5.08]],"ltp":3.6,"tv":75.85,"id":11392436}]}]}
{"op":"mcm","clk":"11930785595","pt":1724269154965,"mc":[{"id":"1.232098082","rc":[{"batb":[[0,3,18.44],[1,2.6,5.08],[2,1.04,1.53]],"ltp":3.6,"tv":75.85,"id":11392436}]}]}
{"op":"mcm","clk":"11930786595","pt":1724269163095,"mc":[{"id":"1.232098082","rc":[{"batb":[[0,3.05,10],[1,3,18.44],[2,2.6,5.08]],"ltp":3.6,"tv":75.85,"id":11392436}]}]}
{"op":"mcm","clk":"11930786999","pt":1724269166490,"mc":[{"id":"1.232098082","rc":[{"batb":[[0,3,18.44],[1,2.6,5.08],[2,1.04,1.53]],"ltp":3.6,"tv":75.85,"id":11392436}]}]}
{"op":"mcm","clk":"11930787494","pt":1724269170659,"mc":[{"id":"1.232098082","rc":[{"batb":[[0,3.05,10],[1,3,18.44],[2,2.6,5.08]],"ltp":3.6,"tv":75.85,"id":11392436}]}]}
{"op":"mcm","clk":"11930787872","pt":1724269173944,"mc":[{"id":"1.232098082","rc":[{"batb":[[0,3,18.44],[1,2.6,5.08],[2,1.04,1.53]],"ltp":3.6,"tv":75.85,"id":11392436}]}]}
{"op":"mcm","clk":"11930788510","pt":1724269179197,"mc":[{"id":"1.232098082","rc":[{"batb":[[0,3.05,10],[1,3,18.44],[2,2.6,5.08]],"ltp":3.6,"tv":75.85,"id":11392436}]}]}
{"op":"mcm","clk":"11930788926","pt":1724269182581,"mc":[{"id":"1.232098082","rc":[{"batb":[[0,3,18.44],[1,2.6,5.08],[2,1.04,1.53]],"ltp":3.6,"tv":75.85,"id":11392436}]}]}
{"op":"mcm","clk":"11930790080","pt":1724269193073,"mc":[{"id":"1.232098082","rc":[{"batb":[[0,3.05,10],[1,3,18.44],[2,2.6,5.08]],"ltp":3.6,"tv":75.85,"id":11392436}]}]}
{"op":"mcm","clk":"11930790503","pt":1724269196513,"mc":[{"id":"1.232098082","rc":[{"batb":[[0,3,18.44],[1,2.6,5.08],[2,1.04,1.53]],"ltp":3.6,"tv":75.85,"id":11392436}]}]}
{"op":"mcm","clk":"11930790767","pt":1724269198801,"mc":[{"id":"1.232098082","rc":[{"batb":[[0,3.05,10],[1,3,18.44],[2,2.6,5.08]],"ltp":3.6,"tv":75.85,"id":11392436}]}]}
{"op":"mcm","clk":"11930791201","pt":1724269202199,"mc":[{"id":"1.232098082","rc":[{"batb":[[0,3,18.44],[1,2.6,5.08],[2,1.04,1.53]],"ltp":3.6,"tv":75.85,"id":11392436}]}]}
{"op":"mcm","clk":"11930791540","pt":1724269204803,"mc":[{"id":"1.232098082","rc":[{"batb":[[0,3.05,10],[1,3,18.44],[2,2.6,5.08]],"ltp":3.6,"tv":75.85,"id":11392436}]}]}
{"op":"mcm","clk":"11930791926","pt":1724269208081,"mc":[{"id":"1.232098082","rc":[{"batb":[[0,3,18.44],[1,2.6,5.08],[2,1.04,1.53]],"ltp":3.6,"tv":75.85,"id":11392436}]}]}
{"op":"mcm","clk":"11930792402","pt":1724269212094,"mc":[{"id":"1.232098082","rc":[{"batb":[[0,3.05,10],[1,3,18.44],[2,2.6,5.08]],"ltp":3.6,"tv":75.85,"id":11392436}]}]}
{"op":"mcm","clk":"11930792768","pt":1724269215429,"mc":[{"id":"1.232098082","rc":[{"batb":[[0,3,18.44],[1,2.6,5.08],[2,1.04,1.53]],"ltp":3.6,"tv":75.85,"id":11392436}]}]}
{"op":"mcm","clk":"11930793053","pt":1724269217829,"mc":[{"id":"1.232098082","rc":[{"batb":[[0,3.05,10],[1,3,18.44],[2,2.6,5.08]],"ltp":3.6,"tv":75.85,"id":11392436}]}]}
{"op":"mcm","clk":"11930793407","pt":1724269221105,"mc":[{"id":"1.232098082","rc":[{"batb":[[0,3,18.44],[1,2.6,5.08],[2,1.04,1.53]],"ltp":3.6,"tv":75.85,"id":11392436}]}]}
{"op":"mcm","clk":"11930793851","pt":1724269224329,"mc":[{"id":"1.232098082","rc":[{"batb":[[0,3.05,10],[1,3,18.44],[2,2.6,5.08]],"ltp":3.6,"tv":75.85,"id":11392436}]}]}
{"op":"mcm","clk":"11930794271","pt":1724269227625,"mc":[{"id":"1.232098082","rc":[{"batb":[[0,3,18.44],[1,2.6,5.08],[2,1.04,1.53]],"ltp":3.6,"tv":75.85,"id":11392436}]}]}
{"op":"mcm","clk":"11930794640","pt":1724269230633,"mc":[{"id":"1.232098082","rc":[{"batb":[[0,3.05,10],[1,3,18.44],[2,2.6,5.08]],"ltp":3.6,"tv":75.85,"id":11392436}]}]}
{"op":"mcm","clk":"11930795038","pt":1724269233916,"mc":[{"id":"1.232098082","rc":[{"batb":[[0,3,18.44],[1,2.6,5.08],[2,1.04,1.53]],"ltp":3.6,"tv":75.85,"id":11392436}]}]}
{"op":"mcm","clk":"11930795597","pt":1724269238945,"mc":[{"id":"1.232098082","rc":[{"batb":[[0,3.05,10],[1,3,18.44],[2,2.6,5.08]],"ltp":3.6,"tv":75.85,"id":11392436}]}]}
{"op":"mcm","clk":"11930795994","pt":1724269242235,"mc":[{"id":"1.232098082","rc":[{"batb":[[0,3,18.44],[1,2.6,5.08],[2,1.04,1.53]],"ltp":3.6,"tv":75.85,"id":11392436}]}]}
{"op":"mcm","clk":"11930797039","pt":1724269251641,"mc":[{"id":"1.232098082","rc":[{"batb":[[0,3.05,10],[1,3,18.44],[2,2.6,5.08]],"ltp":3.6,"tv":75.85,"id":11392436}]}]}
{"op":"mcm","clk":"11930797382","pt":1724269255036,"mc":[{"id":"1.232098082","rc":[{"batb":[[0,3,18.44],[1,2.6,5.08],[2,1.04,1.53]],"ltp":3.6,"tv":75.85,"id":11392436}]}]}
{"op":"mcm","clk":"11930798848","pt":1724269267444,"mc":[{"id":"1.232098082","rc":[{"batb":[[0,3.05,10],[1,3,18.44],[2,2.6,5.08]],"ltp":3.6,"tv":75.85,"id":11392436}]}]}
{"op":"mcm","clk":"11930799251","pt":1724269270782,"mc":[{"id":"1.232098082","rc":[{"batb":[[0,3,18.44],[1,2.6,5.08],[2,1.04,1.53]],"ltp":3.6,"tv":75.85,"id":11392436}]}]}
{"op":"mcm","clk":"11930799531","pt":1724269273185,"mc":[{"id":"1.232098082","rc":[{"batb":[[0,3.05,10],[1,3,18.44],[2,2.6,5.08]],"ltp":3.6,"tv":75.85,"id":11392436}]}]}
{"op":"mcm","clk":"11930799951","pt":1724269276582,"mc":[{"id":"1.232098082","rc":[{"batb":[[0,3,18.44],[1,2.6,5.08],[2,1.04,1.53]],"ltp":3.6,"tv":75.85,"id":11392436}]}]}
{"op":"mcm","clk":"11930800744","pt":1724269283130,"mc":[{"id":"1.232098082","rc":[{"batb":[[0,3.05,10],[1,3,18.44],[2,2.6,5.08]],"ltp":3.6,"tv":75.85,"id":11392436}]}]}
{"op":"mcm","clk":"11930801101","pt":1724269286419,"mc":[{"id":"1.232098082","rc":[{"batb":[[0,3,18.44],[1,2.6,5.08],[2,1.04,1.53]],"ltp":3.6,"tv":75.85,"id":11392436}]}]}
{"op":"mcm","clk":"11930801450","pt":1724269289330,"mc":[{"id":"1.232098082","rc":[{"batb":[[0,3.05,10],[1,3,18.44],[2,2.6,5.08]],"ltp":3.6,"tv":75.85,"id":11392436}]}]}
{"op":"mcm","clk":"11930801812","pt":1724269292619,"mc":[{"id":"1.232098082","rc":[{"batb":[[0,3,18.44],[1,2.6,5.08],[2,1.04,1.53]],"ltp":3.6,"tv":75.85,"id":11392436}]}]}
{"op":"mcm","clk":"11930802145","pt":1724269296132,"mc":[{"id":"1.232098082","rc":[{"batb":[[0,3.05,10],[1,3,18.44],[2,2.6,5.08]],"ltp":3.6,"tv":75.85,"id":11392436}]}]}
{"op":"mcm","clk":"11930802494","pt":1724269299426,"mc":[{"id":"1.232098082","rc":[{"batb":[[0,3,18.44],[1,2.6,5.08],[2,1.04,1.53]],"ltp":3.6,"tv":75.85,"id":11392436}]}]}
{"op":"mcm","clk":"11930803187","pt":1724269305431,"mc":[{"id":"1.232098082","rc":[{"batb":[[0,3.05,10],[1,3,18.44],[2,2.6,5.08]],"ltp":3.6,"tv":75.85,"id":11392436}]}]}
{"op":"mcm","clk":"11930803602","pt":1724269309220,"mc":[{"id":"1.232098082","rc":[{"batb":[[0,3,18.44],[1,2.6,5.08],[2,1.04,1.53]],"ltp":3.6,"tv":75.85,"id":11392436}]}]}
{"op":"mcm","clk":"11930804526","pt":1724269316731,"mc":[{"id":"1.232098082","rc":[{"batb":[[0,3.05,10],[1,3,18.44],[2,2.6,5.08]],"ltp":3.6,"tv":75.85,"id":11392436}]}]}
{"op":"mcm","clk":"11930804881","pt":1724269320196,"mc":[{"id":"1.232098082","rc":[{"batb":[[0,3,18.44],[1,2.6,5.08],[2,1.04,1.53]],"ltp":3.6,"tv":75.85,"id":11392436}]}]}
{"op":"mcm","clk":"11930807259","pt":1724269342596,"mc":[{"id":"1.232098082","rc":[{"batb":[[0,3.05,10],[1,3,18.44],[2,2.6,5.08]],"ltp":3.6,"tv":75.85,"id":11392436}]}]}
{"op":"mcm","clk":"11930807757","pt":1724269345880,"mc":[{"id":"1.232098082","rc":[{"batb":[[0,3,18.44],[1,2.6,5.08],[2,1.04,1.53]],"ltp":3.6,"tv":75.85,"id":11392436}]}]}
{"op":"mcm","clk":"11930808403","pt":1724269351489,"mc":[{"id":"1.232098082","rc":[{"batb":[[0,3.05,10],[1,3,18.44],[2,2.6,5.08]],"ltp":3.6,"tv":75.85,"id":11392436}]}]}
{"op":"mcm","clk":"11930808744","pt":1724269354819,"mc":[{"id":"1.232098082","rc":[{"batb":[[0,3,18.44],[1,2.6,5.08],[2,1.04,1.53]],"ltp":3.6,"tv":75.85,"id":11392436}]}]}
{"op":"mcm","clk":"11930809789","pt":1724269365141,"mc":[{"id":"1.232098082","rc":[{"batb":[[0,3.05,10],[1,3,18.44],[2,2.6,5.08]],"ltp":3.6,"tv":75.85,"id":11392436}]}]}
{"op":"mcm","clk":"11930810147","pt":1724269368417,"mc":[{"id":"1.232098082","rc":[{"batb":[[0,3,18.44],[1,2.6,5.08],[2,1.04,1.53]],"ltp":3.6,"tv":75.85,"id":11392436}]}]}
{"op":"mcm","clk":"11930811830","pt":1724269384038,"mc":[{"id":"1.232098082","rc":[{"batb":[[0,3.05,10],[1,3,18.44],[2,2.6,5.08]],"ltp":3.6,"tv":75.85,"id":11392436}]}]}
{"op":"mcm","clk":"11930812216","pt":1724269387331,"mc":[{"id":"1.232098082","rc":[{"batb":[[0,3,18.44],[1,2.6,5.08],[2,1.04,1.53]],"ltp":3.6,"tv":75.85,"id":11392436}]}]}
{"op":"mcm","clk":"11930812470","pt":1724269389541,"mc":[{"id":"1.232098082","rc":[{"batb":[[0,3.05,10],[1,3,18.44],[2,2.6,5.08]],"ltp":3.6,"tv":75.85,"id":11392436}]}]}
{"op":"mcm","clk":"11930812821","pt":1724269392950,"mc":[{"id":"1.232098082","rc":[{"batb":[[0,3,18.44],[1,2.6,5.08],[2,1.04,1.53]],"ltp":3.6,"tv":75.85,"id":11392436}]}]}
{"op":"mcm","clk":"11930813080","pt":1724269395353,"mc":[{"id":"1.232098082","rc":[{"batb":[[0,3.05,10],[1,3,18.44],[2,2.6,5.08]],"ltp":3.6,"tv":75.85,"id":11392436}]}]}
{"op":"mcm","clk":"11930813510","pt":1724269398646,"mc":[{"id":"1.232098082","rc":[{"batb":[[0,3,18.44],[1,2.6,5.08],[2,1.04,1.53]],"ltp":3.6,"tv":75.85,"id":11392436}]}]}
{"op":"mcm","clk":"11930814050","pt":1724269403168,"mc":[{"id":"1.232098082","rc":[{"batb":[[0,3.05,10],[1,3,18.44],[2,2.6,5.08]],"ltp":3.6,"tv":75.85,"id":11392436}]}]}
{"op":"mcm","clk":"11930814406","pt":1724269406550,"mc":[{"id":"1.232098082","rc":[{"batb":[[0,3,18.44],[1,2.6,5.08],[2,1.04,1.53]],"ltp":3.6,"tv":75.85,"id":11392436}]}]}
{"op":"mcm","clk":"11930815784","pt":1724269419847,"mc":[{"id":"1.232098082","rc":[{"batb":[[0,3.05,10],[1,3,18.44],[2,2.6,5.08]],"ltp":3.6,"tv":75.85,"id":11392436}]}]}
{"op":"mcm","clk":"11930816154","pt":1724269423164,"mc":[{"id":"1.232098082","rc":[{"batb":[[0,3,18.44],[1,2.6,5.08],[2,1.04,1.53]],"ltp":3.6,"tv":75.85,"id":11392436}]}]}
{"op":"mcm","clk":"11930818081","pt":1724269440794,"mc":[{"id":"1.232098082","rc":[{"batb":[[0,3.05,10],[1,3,18.44],[2,2.6,5.08]],"ltp":3.6,"tv":75.85,"id":11392436}]}]}
{"op":"mcm","clk":"11930818517","pt":1724269444175,"mc":[{"id":"1.232098082","rc":[{"batb":[[0,3,18.44],[1,2.6,5.08],[2,1.04,1.53]],"ltp":3.6,"tv":75.85,"id":11392436}]}]}
{"op":"mcm","clk":"11930823085","pt":1724269487131,"mc":[{"id":"1.232098082","rc":[{"batb":[[0,3.05,10],[1,3,18.44],[2,2.6,5.08]],"ltp":3.6,"tv":75.85,"id":11392436}]}]}
{"op":"mcm","clk":"11930823433","pt":1724269490452,"mc":[{"id":"1.232098082","rc":[{"batb":[[0,3,18.44],[1,2.6,5.08],[2,1.04,1.53]],"ltp":3.6,"tv":75.85,"id":11392436}]}]}
{"op":"mcm","clk":"11930824632","pt":1724269501435,"mc":[{"id":"1.232098082","rc":[{"batb":[[0,3.05,10],[1,3,18.44],[2,2.6,5.08]],"ltp":3.6,"tv":75.85,"id":11392436}]}]}
{"op":"mcm","clk":"11930824993","pt":1724269504628,"mc":[{"id":"1.232098082","rc":[{"batb":[[0,3,18.44],[1,2.6,5.08],[2,1.04,1.53]],"ltp":3.6,"tv":75.85,"id":11392436}]}]}
{"op":"mcm","clk":"11930825607","pt":1724269510354,"mc":[{"id":"1.232098082","rc":[{"batb":[[0,3.05,10],[1,3,18.44],[2,2.6,5.08]],"ltp":3.6,"tv":75.85,"id":11392436}]}]}
{"op":"mcm","clk":"11930825975","pt":1724269513638,"mc":[{"id":"1.232098082","rc":[{"batb":[[0,3,18.44],[1,2.6,5.08],[2,1.04,1.53]],"ltp":3.6,"tv":75.85,"id":11392436}]}]}
{"op":"mcm","clk":"11930826307","pt":1724269516870,"mc":[{"id":"1.232098082","rc":[{"batb":[[0,3.05,10],[1,3,18.44],[2,2.6,5.08]],"ltp":3.6,"tv":75.85,"id":11392436}]}]}
{"op":"mcm","clk":"11930826692","pt":1724269520088,"mc":[{"id":"1.232098082","rc":[{"batb":[[0,3,18.44],[1,2.6,5.08],[2,1.04,1.53]],"ltp":3.6,"tv":75.85,"id":11392436}]}]}
{"op":"mcm","clk":"11930827072","pt":1724269523856,"mc":[{"id":"1.232098082","rc":[{"batb":[[0,3.05,10],[1,3,18.44],[2,2.6,5.08]],"ltp":3.6,"tv":75.85,"id":11392436}]}]}
{"op":"mcm","clk":"11930827427","pt":1724269527081,"mc":[{"id":"1.232098082","rc":[{"batb":[[0,3,18.44],[1,2.6,5.08],[2,1.04,1.53]],"ltp":3.6,"tv":75.85,"id":11392436}]}]}
{"op":"mcm","clk":"11930828357","pt":1724269535560,"mc":[{"id":"1.232098082","rc":[{"batb":[[0,3.05,10],[1,3,18.44],[2,2.6,5.08]],"ltp":3.6,"tv":75.85,"id":11392436}]}]}
{"op":"mcm","clk":"11930828731","pt":1724269538994,"mc":[{"id":"1.232098082","rc":[{"batb":[[0,3,18.44],[1,2.6,5.08],[2,1.04,1.53]],"ltp":3.6,"tv":75.85,"id":11392436}]}]}
{"op":"mcm","clk":"11930829849","pt":1724269549012,"mc":[{"id":"1.232098082","rc":[{"batb":[[0,3.05,10],[1,3,18.44],[2,2.6,5.08]],"ltp":3.6,"tv":75.85,"id":11392436}]}]}
{"op":"mcm","clk":"11930830208","pt":1724269552503,"mc":[{"id":"1.232098082","rc":[{"batb":[[0,3,18.44],[1,2.6,5.08],[2,1.04,1.53]],"ltp":3.6,"tv":75.85,"id":11392436}]}]}
{"op":"mcm","clk":"11930830845","pt":1724269558323,"mc":[{"id":"1.232098082","rc":[{"batb":[[0,3.05,10],[1,3,18.44],[2,2.6,5.08]],"ltp":3.6,"tv":75.85,"id":11392436}]}]}
{"op":"mcm","clk":"11930831189","pt":1724269561622,"mc":[{"id":"1.232098082","rc":[{"batb":[[0,3,18.44],[1,2.6,5.08],[2,1.04,1.53]],"ltp":3.6,"tv":75.85,"id":11392436}]}]}
{"op":"mcm","clk":"11930831623","pt":1724269565489,"mc":[{"id":"1.232098082","rc":[{"batb":[[0,3.05,10],[1,3,18.44],[2,2.6,5.08]],"ltp":3.6,"tv":75.85,"id":11392436}]}]}
{"op":"mcm","clk":"11930831952","pt":1724269568907,"mc":[{"id":"1.232098082","rc":[{"batb":[[0,3,18.44],[1,2.6,5.08],[2,1.04,1.53]],"ltp":3.6,"tv":75.85,"id":11392436}]}]}
{"op":"mcm","clk":"11930832587","pt":1724269575413,"mc":[{"id":"1.232098082","rc":[{"batb":[[0,3.05,10],[1,3,18.44],[2,2.6,5.08]],"ltp":3.6,"tv":75.85,"id":11392436}]}]}
{"op":"mcm","clk":"11930832921","pt":1724269578811,"mc":[{"id":"1.232098082","rc":[{"batb":[[0,3,18.44],[1,2.6,5.08],[2,1.04,1.53]],"ltp":3.6,"tv":75.85,"id":11392436}]}]}
{"op":"mcm","clk":"11930833465","pt":1724269583634,"mc":[{"id":"1.232098082","rc":[{"batb":[[0,3.05,10],[1,3,18.44],[2,2.6,5.08]],"ltp":3.6,"tv":75.85,"id":11392436}]}]}
{"op":"mcm","clk":"11930833812","pt":1724269586931,"mc":[{"id":"1.232098082","rc":[{"batb":[[0,3,18.44],[1,2.6,5.08],[2,1.04,1.53]],"ltp":3.6,"tv":75.85,"id":11392436}]}]}
{"op":"mcm","clk":"11930834033","pt":1724269589427,"mc":[{"id":"1.232098082","rc":[{"batb":[[0,3.05,10],[1,3,18.44],[2,2.6,5.08]],"ltp":3.6,"tv":75.85,"id":11392436}]}]}
{"op":"mcm","clk":"11930834392","pt":1724269592764,"mc":[{"id":"1.232098082","rc":[{"batb":[[0,3,18.44],[1,2.6,5.08],[2,1.04,1.53]],"ltp":3.6,"tv":75.85,"id":11392436}]}]}
{"op":"mcm","clk":"11930835385","pt":1724269601744,"mc":[{"id":"1.232098082","rc":[{"batb":[[0,3.05,10],[1,3,18.44],[2,2.6,5.08]],"ltp":3.6,"tv":75.85,"id":11392436}]}]}
{"op":"mcm","clk":"11930835721","pt":1724269604964,"mc":[{"id":"1.232098082","rc":[{"batb":[[0,3,18.44],[1,2.6,5.08],[2,1.04,1.53]],"ltp":3.6,"tv":75.85,"id":11392436}]}]}
{"op":"mcm","clk":"11930836611","pt":1724269613261,"mc":[{"id":"1.232098082","rc":[{"batb":[[0,3.05,10],[1,3,18.44],[2,2.6,5.08]],"ltp":3.6,"tv":75.85,"id":11392436}]}]}
{"op":"mcm","clk":"11930836997","pt":1724269616637,"mc":[{"id":"1.232098082","rc":[{"batb":[[0,3,18.44],[1,2.6,5.08],[2,1.04,1.53]],"ltp":3.6,"tv":75.85,"id":11392436}]}]}
{"op":"mcm","clk":"11930838889","pt":1724269632889,"mc":[{"id":"1.232098082","rc":[{"batb":[[0,3.05,10],[1,3,18.44],[2,2.6,5.08]],"ltp":3.6,"tv":75.85,"id":11392436}]}]}
{"op":"mcm","clk":"11930839285","pt":1724269636257,"mc":[{"id":"1.232098082","rc":[{"batb":[[0,3,18.44],[1,2.6,5.08],[2,1.04,1.53]],"ltp":3.6,"tv":75.85,"id":11392436}]}]}
{"op":"mcm","clk":"11930839830","pt":1724269640874,"mc":[{"id":"1.232098082","rc":[{"batb":[[0,3.05,10],[1,3,18.44],[2,2.6,5.08]],"ltp":3.6,"tv":75.85,"id":11392436}]}]}
{"op":"mcm","clk":"11930840175","pt":1724269644184,"mc":[{"id":"1.232098082","rc":[{"batb":[[0,3,18.44],[1,2.6,5.08],[2,1.04,1.53]],"ltp":3.6,"tv":75.85,"id":11392436}]}]}
{"op":"mcm","clk":"11930841553","pt":1724269655778,"mc":[{"id":"1.232098082","rc":[{"batb":[[0,3.05,10],[1,3,18.44],[2,2.6,5.08]],"ltp":3.6,"tv":75.85,"id":11392436}]}]}
{"op":"mcm","clk":"11930841896","pt":1724269659189,"mc":[{"id":"1.232098082","rc":[{"batb":[[0,3,18.44],[1,2.6,5.08],[2,1.04,1.53]],"ltp":3.6,"tv":75.85,"id":11392436}]}]}
{"op":"mcm","clk":"11930842525","pt":1724269665103,"mc":[{"id":"1.232098082","rc":[{"batb":[[0,3.05,10],[1,3,18.44],[2,2.6,5.08]],"ltp":3.6,"tv":75.85,"id":11392436}]}]}
{"op":"mcm","clk":"11930842892","pt":1724269668629,"mc":[{"id":"1.232098082","rc":[{"batb":[[0,3,18.44],[1,2.6,5.08],[2,1.04,1.53]],"ltp":3.6,"tv":75.85,"id":11392436}]}]}
{"op":"mcm","clk":"11930843991","pt":1724269679003,"mc":[{"id":"1.232098082","rc":[{"batb":[[0,3.05,10],[1,3,18.44],[2,2.6,5.08]],"ltp":3.6,"tv":75.85,"id":11392436}]}]}
{"op":"mcm","clk":"11930844325","pt":1724269682336,"mc":[{"id":"1.232098082","rc":[{"batb":[[0,3,18.44],[1,2.6,5.08],[2,1.04,1.53]],"ltp":3.6,"tv":75.85,"id":11392436}]}]}
{"op":"mcm","clk":"11930844605","pt":1724269684826,"mc":[{"id":"1.232098082","rc":[{"batb":[[0,3.05,10],[1,3,18.44],[2,2.6,5.08]],"ltp":3.6,"tv":75.85,"id":11392436}]}]}
{"op":"mcm","clk":"11930844949","pt":1724269688063,"mc":[{"id":"1.232098082","rc":[{"batb":[[0,3,18.44],[1,2.6,5.08],[2,1.04,1.53]],"ltp":3.6,"tv":75.85,"id":11392436}]}]}
{"op":"mcm","clk":"11930845362","pt":1724269691733,"mc":[{"id":"1.232098082","rc":[{"batb":[[0,3.05,10],[1,3,18.44],[2,2.6,5.08]],"ltp":3.6,"tv":75.85,"id":11392436}]}]}
{"op":"mcm","clk":"11930845647","pt":1724269695048,"mc":[{"id":"1.232098082","rc":[{"batb":[[0,3,18.44],[1,2.6,5.08],[2,1.04,1.53]],"ltp":3.6,"tv":75.85,"id":11392436}]}]}
{"op":"mcm","clk":"11930846064","pt":1724269699213,"mc":[{"id":"1.232098082","rc":[{"batb":[[0,3.05,10],[1,3,18.44],[2,2.6,5.08]],"ltp":3.6,"tv":75.85,"id":11392436}]}]}
{"op":"mcm","clk":"11930846411","pt":1724269702740,"mc":[{"id":"1.232098082","rc":[{"batb":[[0,3,18.44],[1,2.6,5.08],[2,1.04,1.53]],"ltp":3.6,"tv":75.85,"id":11392436}]}]}
{"op":"mcm","clk":"11930846894","pt":1724269707259,"mc":[{"id":"1.232098082","rc":[{"batb":[[0,3.05,10],[1,3,18.44],[2,2.6,5.08]],"ltp":3.6,"tv":75.85,"id":11392436}]}]}
{"op":"mcm","clk":"11930847198","pt":1724269710464,"mc":[{"id":"1.232098082","rc":[{"batb":[[0,3,18.44],[1,2.6,5.08],[2,1.04,1.53]],"ltp":3.6,"tv":75.85,"id":11392436}]}]}
{"op":"mcm","clk":"11930847912","pt":1724269717672,"mc":[{"id":"1.232098082","rc":[{"batb":[[0,3.05,10],[1,3,18.44],[2,2.6,5.08]],"ltp":3.6,"tv":75.85,"id":11392436}]}]}
{"op":"mcm","clk":"11930848262","pt":1724269720944,"mc":[{"id":"1.232098082","rc":[{"batb":[[0,3,18.44],[1,2.6,5.08],[2,1.04,1.53]],"ltp":3.6,"tv":75.85,"id":11392436}]}]}
{"op":"mcm","clk":"11930849489","pt":1724269732354,"mc":[{"id":"1.232098082","rc":[{"batb":[[0,3.05,10],[1,3,18.44],[2,2.6,5.08]],"ltp":3.6,"tv":75.85,"id":11392436}]}]}
{"op":"mcm","clk":"11930849844","pt":1724269735682,"mc":[{"id":"1.232098082","rc":[{"batb":[[0,3,18.44],[1,2.6,5.08],[2,1.04,1.53]],"ltp":3.6,"tv":75.85,"id":11392436}]}]}
{"op":"mcm","clk":"11930850174","pt":1724269738788,"mc":[{"id":"1.232098082","rc":[{"batb":[[0,3.05,10],[1,3,18.44],[2,2.6,5.08]],"ltp":3.6,"tv":75.85,"id":11392436}]}]}
{"op":"mcm","clk":"11930850515","pt":1724269742077,"mc":[{"id":"1.232098082","rc":[{"batb":[[0,3,18.44],[1,2.6,5.08],[2,1.04,1.53]],"ltp":3.6,"tv":75.85,"id":11392436}]}]}
{"op":"mcm","clk":"11930852231","pt":1724269759373,"mc":[{"id":"1.232098082","rc":[{"batb":[[0,3.05,10],[1,3,18.44],[2,2.6,5.08]],"ltp":3.6,"tv":75.85,"id":11392436}]}]}
{"op":"mcm","clk":"11930852608","pt":1724269762708,"mc":[{"id":"1.232098082","rc":[{"batb":[[0,3,18.44],[1,2.6,5.08],[2,1.04,1.53]],"ltp":3.6,"tv":75.85,"id":11392436}]}]}
{"op":"mcm","clk":"11930852859","pt":1724269764903,"mc":[{"id":"1.232098082","rc":[{"batb":[[0,3.05,10],[1,3,18.44],[2,2.6,5.08]],"ltp":3.6,"tv":75.85,"id":11392436}]}]}
{"op":"mcm","clk":"11930853218","pt":1724269768221,"mc":[{"id":"1.232098082","rc":[{"batb":[[0,3,18.44],[1,2.6,5.08],[2,1.04,1.53]],"ltp":3.6,"tv":75.85,"id":11392436}]}]}
{"op":"mcm","clk":"11930854224","pt":1724269778027,"mc":[{"id":"1.232098082","rc":[{"batb":[[0,3.05,10],[1,3,18.44],[2,2.6,5.08]],"ltp":3.6,"tv":75.85,"id":11392436}]}]}
{"op":"mcm","clk":"11930854569","pt":1724269781409,"mc":[{"id":"1.232098082","rc":[{"batb":[[0,3,18.44],[1,2.6,5.08],[2,1.04,1.53]],"ltp":3.6,"tv":75.85,"id":11392436}]}]}
{"op":"mcm","clk":"11930855399","pt":1724269789341,"mc":[{"id":"1.232098082","rc":[{"batb":[[0,3.05,10],[1,3,18.44],[2,2.6,5.08]],"ltp":3.6,"tv":75.85,"id":11392436}]}]}
{"op":"mcm","clk":"11930855733","pt":1724269792610,"mc":[{"id":"1.232098082","rc":[{"batb":[[0,3,18.44],[1,2.6,5.08],[2,1.04,1.53]],"ltp":3.6,"tv":75.85,"id":11392436}]}]}
{"op":"mcm","clk":"11930855977","pt":1724269795408,"mc":[{"id":"1.232098082","rc":[{"batb":[[0,3.05,10],[1,3,18.44],[2,2.6,5.08]],"ltp":3.6,"tv":75.85,"id":11392436}]}]}
{"op":"mcm","clk":"11930856402","pt":1724269798825,"mc":[{"id":"1.232098082","rc":[{"batb":[[0,3,18.44],[1,2.6,5.08],[2,1.04,1.53]],"ltp":3.6,"tv":75.85,"id":11392436}]}]}
{"op":"mcm","clk":"11930857638","pt":1724269810410,"mc":[{"id":"1.232098082","rc":[{"batb":[[0,3.05,10],[1,3,18.44],[2,2.6,5.08]],"ltp":3.6,"tv":75.85,"id":11392436}]}]}
{"op":"mcm","clk":"11930857980","pt":1724269813657,"mc":[{"id":"1.232098082","rc":[{"batb":[[0,3,18.44],[1,2.6,5.08],[2,1.04,1.53]],"ltp":3.6,"tv":75.85,"id":11392436}]}]}
{"op":"mcm","clk":"11930861278","pt":1724269845727,"mc":[{"id":"1.232098082","rc":[{"batb":[[0,3.05,10],[1,3,18.44],[2,2.6,5.08]],"ltp":3.6,"tv":75.85,"id":11392436}]}]}
{"op":"mcm","clk":"11930861634","pt":1724269849136,"mc":[{"id":"1.232098082","rc":[{"batb":[[0,3,18.44],[1,2.6,5.08],[2,1.04,1.53]],"ltp":3.6,"tv":75.85,"id":11392436}]}]}
{"op":"mcm","clk":"11930863195","pt":1724269863781,"mc":[{"id":"1.232098082","rc":[{"batb":[[0,3.05,10],[1,3,18.44],[2,2.6,5.08]],"ltp":3.6,"tv":75.85,"id":11392436}]}]}
{"op":"mcm","clk":"11930863585","pt":1724269867164,"mc":[{"id":"1.232098082","rc":[{"batb":[[0,3,18.44],[1,2.6,5.08],[2,1.04,1.53]],"ltp":3.6,"tv":75.85,"id":11392436}]}]}
{"op":"mcm","clk":"11930864701","pt":1724269877681,"mc":[{"id":"1.232098082","rc":[{"batb":[[0,3.05,10],[1,3,18.44],[2,2.6,5.08]],"ltp":3.6,"tv":75.85,"id":11392436}]}]}
{"op":"mcm","clk":"11930865059","pt":1724269881060,"mc":[{"id":"1.232098082","rc":[{"batb":[[0,3,18.44],[1,2.6,5.08],[2,1.04,1.53]],"ltp":3.6,"tv":75.85,"id":11392436}]}]}
{"op":"mcm","clk":"11930866151","pt":1724269891392,"mc":[{"id":"1.232098082","rc":[{"batb":[[0,3.05,10],[1,3,18.44],[2,2.6,5.08]],"ltp":3.6,"tv":75.85,"id":11392436}]}]}
{"op":"mcm","clk":"11930866466","pt":1724269894762,"mc":[{"id":"1.232098082","rc":[{"batb":[[0,3,18.44],[1,2.6,5.08],[2,1.04,1.53]],"ltp":3.6,"tv":75.85,"id":11392436}]}]}
{"op":"mcm","clk":"11930867228","pt":1724269902778,"mc":[{"id":"1.232098082","rc":[{"batb":[[0,3.05,10],[1,3,18.44],[2,2.6,5.08]],"ltp":3.6,"tv":75.85,"id":11392436}]}]}
{"op":"mcm","clk":"11930867511","pt":1724269906000,"mc":[{"id":"1.232098082","rc":[{"batb":[[0,3,18.44],[1,2.6,5.08],[2,1.04,1.53]],"ltp":3.6,"tv":75.85,"id":11392436}]}]}
{"op":"mcm","clk":"11930868057","pt":1724269912314,"mc":[{"id":"1.232098082","rc":[{"batb":[[0,3.05,10],[1,3,18.44],[2,2.6,5.08]],"ltp":3.6,"tv":75.85,"id":11392436}]}]}
{"op":"mcm","clk":"11930868368","pt":1724269915683,"mc":[{"id":"1.232098082","rc":[{"batb":[[0,3,18.44],[1,2.6,5.08],[2,1.04,1.53]],"ltp":3.6,"tv":75.85,"id":11392436}]}]}
{"op":"mcm","clk":"11930868689","pt":1724269919717,"mc":[{"id":"1.232098082","rc":[{"batb":[[0,3.05,10],[1,3,18.44],[2,2.6,5.08]],"ltp":3.6,"tv":75.85,"id":11392436}]}]}
{"op":"mcm","clk":"11930869019","pt":1724269923094,"mc":[{"id":"1.232098082","rc":[{"batb":[[0,3,18.44],[1,2.6,5.08],[2,1.04,1.53]],"ltp":3.6,"tv":75.85,"id":11392436}]}]}
{"op":"mcm","clk":"11930869366","pt":1724269926928,"mc":[{"id":"1.232098082","rc":[{"batb":[[0,3.05,10],[1,3,18.44],[2,2.6,5.08]],"ltp":3.6,"tv":75.85,"id":11392436}]}]}
{"op":"mcm","clk":"11930869724","pt":1724269930343,"mc":[{"id":"1.232098082","rc":[{"batb":[[0,3,18.44],[1,2.6,5.08],[2,1.04,1.53]],"ltp":3.6,"tv":75.85,"id":11392436}]}]}
{"op":"mcm","clk":"11930870210","pt":1724269935052,"mc":[{"id":"1.232098082","rc":[{"batb":[[0,3.05,10],[1,3,18.44],[2,2.6,5.08]],"ltp":3.6,"tv":75.85,"id":11392436}]}]}
{"op":"mcm","clk":"11930870567","pt":1724269938359,"mc":[{"id":"1.232098082","rc":[{"batb":[[0,3,18.44],[1,2.6,5.08],[2,1.04,1.53]],"ltp":3.6,"tv":75.85,"id":11392436}]}]}
{"op":"mcm","clk":"11930871933","pt":1724269950842,"mc":[{"id":"1.232098082","rc":[{"batb":[[0,3.05,10],[1,3,18.44],[2,2.6,5.08]],"ltp":3.6,"tv":75.85,"id":11392436}]}]}
{"op":"mcm","clk":"11930872308","pt":1724269954162,"mc":[{"id":"1.232098082","rc":[{"batb":[[0,3,18.44],[1,2.6,5.08],[2,1.04,1.53]],"ltp":3.6,"tv":75.85,"id":11392436}]}]}
{"op":"mcm","clk":"11930873143","pt":1724269961057,"mc":[{"id":"1.232098082","rc":[{"batb":[[0,3.05,10],[1,3,18.44],[2,2.6,5.08]],"ltp":3.6,"tv":75.85,"id":11392436}]}]}
{"op":"mcm","clk":"11930873536","pt":1724269964474,"mc":[{"id":"1.232098082","rc":[{"batb":[[0,3,18.44],[1,2.6,5.08],[2,1.04,1.53]],"ltp":3.6,"tv":75.85,"id":11392436}]}]}
{"op":"mcm","clk":"11930873915","pt":1724269967378,"mc":[{"id":"1.232098082","rc":[{"batb":[[0,3.05,10],[1,3,18.44],[2,2.6,5.08]],"ltp":3.6,"tv":75.85,"id":11392436}]}]}
{"op":"mcm","clk":"11930874262","pt":1724269970649,"mc":[{"id":"1.232098082","rc":[{"batb":[[0,3,18.44],[1,2.6,5.08],[2,1.04,1.53]],"ltp":3.6,"tv":75.85,"id":11392436}]}]}
{"op":"mcm","clk":"11930874883","pt":1724269976192,"mc":[{"id":"1.232098082","rc":[{"batb":[[0,3.05,10],[1,3,18.44],[2,2.6,5.08]],"ltp":3.6,"tv":75.85,"id":11392436}]}]}
{"op":"mcm","clk":"11930875245","pt":1724269979597,"mc":[{"id":"1.232098082","rc":[{"batb":[[0,3,18.44],[1,2.6,5.08],[2,1.04,1.53]],"ltp":3.6,"tv":75.85,"id":11392436}]}]}
{"op":"mcm","clk":"11930876879","pt":1724269994896,"mc":[{"id":"1.232098082","rc":[{"batb":[[0,3.05,10],[1,3,18.44],[2,2.6,5.08]],"ltp":3.6,"tv":75.85,"id":11392436}]}]}
{"op":"mcm","clk":"11930877236","pt":1724269998109,"mc":[{"id":"1.232098082","rc":[{"batb":[[0,3,18.44],[1,2.6,5.08],[2,1.04,1.53]],"ltp":3.6,"tv":75.85,"id":11392436}]}]}
{"op":"mcm","clk":"11930877588","pt":1724270001008,"mc":[{"id":"1.232098082","rc":[{"batb":[[0,3.05,10],[1,3,18.44],[2,2.6,5.08]],"ltp":3.6,"tv":75.85,"id":11392436}]}]}
{"op":"mcm","clk":"11930877978","pt":1724270004296,"mc":[{"id":"1.232098082","rc":[{"batb":[[0,3,18.44],[1,2.6,5.08],[2,1.04,1.53]],"ltp":3.6,"tv":75.85,"id":11392436}]}]}
{"op":"mcm","clk":"11930878262","pt":1724270006638,"mc":[{"id":"1.232098082","rc":[{"batb":[[0,3.05,10],[1,3,18.44],[2,2.6,5.08]],"ltp":3.6,"tv":75.85,"id":11392436}]}]}
{"op":"mcm","clk":"11930878693","pt":1724270010007,"mc":[{"id":"1.232098082","rc":[{"batb":[[0,3,18.44],[1,2.6,5.08],[2,1.04,1.53]],"ltp":3.6,"tv":75.85,"id":11392436}]}]}
{"op":"mcm","clk":"11930879129","pt":1724270013443,"mc":[{"id":"1.232098082","rc":[{"batb":[[0,3.05,10],[1,3,18.44],[2,2.6,5.08]],"ltp":3.6,"tv":75.85,"id":11392436}]}]}
{"op":"mcm","clk":"11930879541","pt":1724270016753,"mc":[{"id":"1.232098082","rc":[{"batb":[[0,3,18.44],[1,2.6,5.08],[2,1.04,1.53]],"ltp":3.6,"tv":75.85,"id":11392436}]}]}
{"op":"mcm","clk":"11930880254","pt":1724270022420,"mc":[{"id":"1.232098082","rc":[{"batb":[[0,3.05,10],[1,3,18.44],[2,2.6,5.08]],"ltp":3.6,"tv":75.85,"id":11392436}]}]}
{"op":"mcm","clk":"11930880625","pt":1724270025820,"mc":[{"id":"1.232098082","rc":[{"batb":[[0,3,18.44],[1,2.6,5.08],[2,1.04,1.53]],"ltp":3.6,"tv":75.85,"id":11392436}]}]}
{"op":"mcm","clk":"11930881271","pt":1724270031353,"mc":[{"id":"1.232098082","rc":[{"batb":[[0,3.05,10],[1,3,18.44],[2,2.6,5.08]],"ltp":3.6,"tv":75.85,"id":11392436}]}]}
{"op":"mcm","clk":"11930881671","pt":1724270034512,"mc":[{"id":"1.232098082","rc":[{"batb":[[0,3,18.44],[1,2.6,5.08],[2,1.04,1.53]],"ltp":3.6,"tv":75.85,"id":11392436}]}]}
{"op":"mcm","clk":"11930882504","pt":1724270042445,"mc":[{"id":"1.232098082","rc":[{"batb":[[0,3.05,10],[1,3,18.44],[2,2.6,5.08]],"ltp":3.6,"tv":75.85,"id":11392436}]}]}
{"op":"mcm","clk":"11930882876","pt":1724270045775,"mc":[{"id":"1.232098082","rc":[{"batb":[[0,3,18.44],[1,2.6,5.08],[2,1.04,1.53]],"ltp":3.6,"tv":75.85,"id":11392436}]}]}
{"op":"mcm","clk":"11930883156","pt":1724270048138,"mc":[{"id":"1.232098082","rc":[{"batb":[[0,3.05,10],[1,3,18.44],[2,2.6,5.08]],"ltp":3.6,"tv":75.85,"id":11392436}]}]}
{"op":"mcm","clk":"11930883500","pt":1724270051353,"mc":[{"id":"1.232098082","rc":[{"batb":[[0,3,18.44],[1,2.6,5.08],[2,1.04,1.53]],"ltp":3.6,"tv":75.85,"id":11392436}]}]}
{"op":"mcm","clk":"11930884121","pt":1724270056774,"mc":[{"id":"1.232098082","rc":[{"batb":[[0,3.05,10],[1,3,18.44],[2,2.6,5.08]],"ltp":3.6,"tv":75.85,"id":11392436}]}]}
{"op":"mcm","clk":"11930884424","pt":1724270059974,"mc":[{"id":"1.232098082","rc":[{"batb":[[0,3,18.44],[1,2.6,5.08],[2,1.04,1.53]],"ltp":3.6,"tv":75.85,"id":11392436}]}]}
{"op":"mcm","clk":"11930884644","pt":1724270062561,"mc":[{"id":"1.232098082","rc":[{"batb":[[0,3.05,10],[1,3,18.44],[2,2.6,5.08]],"ltp":3.6,"tv":75.85,"id":11392436}]}]}
{"op":"mcm","clk":"11930884956","pt":1724270065979,"mc":[{"id":"1.232098082","rc":[{"batb":[[0,3,18.44],[1,2.6,5.08],[2,1.04,1.53]],"ltp":3.6,"tv":75.85,"id":11392436}]}]}
{"op":"mcm","clk":"11930885351","pt":1724270070175,"mc":[{"id":"1.232098082","rc":[{"batb":[[0,3.05,10],[1,3,18.44],[2,2.6,5.08]],"ltp":3.6,"tv":75.85,"id":11392436}]}]}
{"op":"mcm","clk":"11930885630","pt":1724270073482,"mc":[{"id":"1.232098082","rc":[{"batb":[[0,3,18.44],[1,2.6,5.08],[2,1.04,1.53]],"ltp":3.6,"tv":75.85,"id":11392436}]}]}
{"op":"mcm","clk":"11930885869","pt":1724270076216,"mc":[{"id":"1.232098082","rc":[{"batb":[[0,3.05,10],[1,3,18.44],[2,2.6,5.08]],"ltp":3.6,"tv":75.85,"id":11392436}]}]}
{"op":"mcm","clk":"11930886208","pt":1724270079588,"mc":[{"id":"1.232098082","rc":[{"batb":[[0,3,18.44],[1,2.6,5.08],[2,1.04,1.53]],"ltp":3.6,"tv":75.85,"id":11392436}]}]}
{"op":"mcm","clk":"11930886553","pt":1724270083205,"mc":[{"id":"1.232098082","rc":[{"batb":[[0,3.05,10],[1,3,18.44],[2,2.6,5.08]],"ltp":3.6,"tv":75.85,"id":11392436}]}]}
{"op":"mcm","clk":"11930886819","pt":1724270086717,"mc":[{"id":"1.232098082","rc":[{"batb":[[0,3,18.44],[1,2.6,5.08],[2,1.04,1.53]],"ltp":3.6,"tv":75.85,"id":11392436}]}]}
{"op":"mcm","clk":"11930887530","pt":1724270094435,"mc":[{"id":"1.232098082","rc":[{"batb":[[0,3.05,10],[1,3,18.44],[2,2.6,5.08]],"ltp":3.6,"tv":75.85,"id":11392436}]}]}
{"op":"mcm","clk":"11930887859","pt":1724270097836,"mc":[{"id":"1.232098082","rc":[{"batb":[[0,3,18.44],[1,2.6,5.08],[2,1.04,1.53]],"ltp":3.6,"tv":75.85,"id":11392436}]}]}
{"op":"mcm","clk":"11930888039","pt":1724270099904,"mc":[{"id":"1.232098082","rc":[{"batb":[[0,3.05,10],[1,3,18.44],[2,2.6,5.08]],"ltp":3.6,"tv":75.85,"id":11392436}]}]}
{"op":"mcm","clk":"11930888421","pt":1724270103219,"mc":[{"id":"1.232098082","rc":[{"batb":[[0,3,18.44],[1,2.6,5.08],[2,1.04,1.53]],"ltp":3.6,"tv":75.85,"id":11392436}]}]}
{"op":"mcm","clk":"11930889358","pt":1724270112130,"mc":[{"id":"1.232098082","rc":[{"batb":[[0,3.05,10],[1,3,18.44],[2,2.6,5.08]],"ltp":3.6,"tv":75.85,"id":11392436}]}]}
{"op":"mcm","clk":"11930889686","pt":1724270115442,"mc":[{"id":"1.232098082","rc":[{"batb":[[0,3,18.44],[1,2.6,5.08],[2,1.04,1.53]],"ltp":3.6,"tv":75.85,"id":11392436}]}]}
{"op":"mcm","clk":"11930890436","pt":1724270122236,"mc":[{"id":"1.232098082","rc":[{"batb":[[0,3.05,10],[1,3,18.44],[2,2.6,5.08]],"ltp":3.6,"tv":75.85,"id":11392436}]}]}
{"op":"mcm","clk":"11930890779","pt":1724270125561,"mc":[{"id":"1.232098082","rc":[{"batb":[[0,3,18.44],[1,2.6,5.08],[2,1.04,1.53]],"ltp":3.6,"tv":75.85,"id":11392436}]}]}
{"op":"mcm","clk":"11930891197","pt":1724270129059,"mc":[{"id":"1.232098082","rc":[{"batb":[[0,3.05,10],[1,3,18.44],[2,2.6,5.08]],"ltp":3.6,"tv":75.85,"id":11392436}]}]}
{"op":"mcm","clk":"11930891600","pt":1724270132450,"mc":[{"id":"1.232098082","rc":[{"batb":[[0,3,18.44],[1,2.6,5.08],[2,1.04,1.53]],"ltp":3.6,"tv":75.85,"id":11392436}]}]}
{"op":"mcm","clk":"11930891897","pt":1724270135155,"mc":[{"id":"1.232098082","rc":[{"batb":[[0,3.05,10],[1,3,18.44],[2,2.6,5.08]],"ltp":3.6,"tv":75.85,"id":11392436}]}]}
{"op":"mcm","clk":"11930892259","pt":1724270138563,"mc":[{"id":"1.232098082","rc":[{"batb":[[0,3,18.44],[1,2.6,5.08],[2,1.04,1.53]],"ltp":3.6,"tv":75.85,"id":11392436}]}]}
{"op":"mcm","clk":"11930892513","pt":1724270141048,"mc":[{"id":"1.232098082","rc":[{"batb":[[0,3.05,10],[1,3,18.44],[2,2.6,5.08]],"ltp":3.6,"tv":75.85,"id":11392436}]}]}
{"op":"mcm","clk":"11930892864","pt":1724270144581,"mc":[{"id":"1.232098082","rc":[{"batb":[[0,3,18.44],[1,2.6,5.08],[2,1.04,1.53]],"ltp":3.6,"tv":75.85,"id":11392436}]}]}
{"op":"mcm","clk":"11930893165","pt":1724270147481,"mc":[{"id":"1.232098082","rc":[{"batb":[[0,3.05,10],[1,3,18.44],[2,2.6,5.08]],"ltp":3.6,"tv":75.85,"id":11392436}]}]}
{"op":"mcm","clk":"11930893461","pt":1724270150880,"mc":[{"id":"1.232098082","rc":[{"batb":[[0,3,18.44],[1,2.6,5.08],[2,1.04,1.53]],"ltp":3.6,"tv":75.85,"id":11392436}]}]}
{"op":"mcm","clk":"11930893686","pt":1724270153298,"mc":[{"id":"1.232098082","rc":[{"batb":[[0,3.05,10],[1,3,18.44],[2,2.6,5.08]],"ltp":3.6,"tv":75.85,"id":11392436}]}]}
{"op":"mcm","clk":"11930894025","pt":1724270156702,"mc":[{"id":"1.232098082","rc":[{"batb":[[0,3,18.44],[1,2.6,5.08],[2,1.04,1.53]],"ltp":3.6,"tv":75.85,"id":11392436}]}]}
{"op":"mcm","clk":"11930894409","pt":1724270160892,"mc":[{"id":"1.232098082","rc":[{"batb":[[0,3.05,10],[1,3,18.44],[2,2.6,5.08]],"ltp":3.6,"tv":75.85,"id":11392436}]}]}
{"op":"mcm","clk":"11930894701","pt":1724270164301,"mc":[{"id":"1.232098082","rc":[{"batb":[[0,3,18.44],[1,2.6,5.08],[2,1.04,1.53]],"ltp":3.6,"tv":75.85,"id":11392436}]}]}
{"op":"mcm","clk":"11930894894","pt":1724270166782,"mc":[{"id":"1.232098082","rc":[{"batb":[[0,3.05,10],[1,3,18.44],[2,2.6,5.08]],"ltp":3.6,"tv":75.85,"id":11392436}]}]}
{"op":"mcm","clk":"11930895165","pt":1724270169990,"mc":[{"id":"1.232098082","rc":[{"batb":[[0,3,18.44],[1,2.6,5.08],[2,1.04,1.53]],"ltp":3.6,"tv":75.85,"id":11392436}]}]}
{"op":"mcm","clk":"11930895921","pt":1724270177796,"mc":[{"id":"1.232098082","rc":[{"batb":[[0,3.05,10],[1,3,18.44],[2,2.6,5.08]],"ltp":3.6,"tv":75.85,"id":11392436}]}]}
{"op":"mcm","clk":"11930896244","pt":1724270181110,"mc":[{"id":"1.232098082","rc":[{"batb":[[0,3,18.44],[1,2.6,5.08],[2,1.04,1.53]],"ltp":3.6,"tv":75.85,"id":11392436}]}]}
{"op":"mcm","clk":"11930896798","pt":1724270186899,"mc":[{"id":"1.232098082","rc":[{"batb":[[0,3.05,10],[1,3,18.44],[2,2.6,5.08]],"ltp":3.6,"tv":75.85,"id":11392436}]}]}
{"op":"mcm","clk":"11930897112","pt":1724270190311,"mc":[{"id":"1.232098082","rc":[{"batb":[[0,3,18.44],[1,2.6,5.08],[2,1.04,1.53]],"ltp":3.6,"tv":75.85,"id":11392436}]}]}
{"op":"mcm","clk":"11930897403","pt":1724270193416,"mc":[{"id":"1.232098082","rc":[{"batb":[[0,3.05,10],[1,3,18.44],[2,2.6,5.08]],"ltp":3.6,"tv":75.85,"id":11392436}]}]}
{"op":"mcm","clk":"11930897745","pt":1724270196825,"mc":[{"id":"1.232098082","rc":[{"batb":[[0,3,18.44],[1,2.6,5.08],[2,1.04,1.53]],"ltp":3.6,"tv":75.85,"id":11392436}]}]}
{"op":"mcm","clk":"11930898462","pt":1724270204214,"mc":[{"id":"1.232098082","rc":[{"batb":[[0,3.05,10],[1,3,18.44],[2,2.6,5.08]],"ltp":3.6,"tv":75.85,"id":11392436}]}]}
{"op":"mcm","clk":"11930898831","pt":1724270207639,"mc":[{"id":"1.232098082","rc":[{"batb":[[0,3,18.44],[1,2.6,5.08],[2,1.04,1.53]],"ltp":3.6,"tv":75.85,"id":11392436}]}]}
{"op":"mcm","clk":"11930899058","pt":1724270210018,"mc":[{"id":"1.232098082","rc":[{"batb":[[0,3.05,10],[1,3,18.44],[2,2.6,5.08]],"ltp":3.6,"tv":75.85,"id":11392436}]}]}
{"op":"mcm","clk":"11930899372","pt":1724270213225,"mc":[{"id":"1.232098082","rc":[{"batb":[[0,3,18.44],[1,2.6,5.08],[2,1.04,1.53]],"ltp":3.6,"tv":75.85,"id":11392436}]}]}
{"op":"mcm","clk":"11930899658","pt":1724270215921,"mc":[{"id":"1.232098082","rc":[{"batb":[[0,3.05,10],[1,3,18.44],[2,2.6,5.08]],"ltp":3.6,"tv":75.85,"id":11392436}]}]}
{"op":"mcm","clk":"11930899956","pt":1724270219267,"mc":[{"id":"1.232098082","rc":[{"batb":[[0,3,18.44],[1,2.6,5.08],[2,1.04,1.53]],"ltp":3.6,"tv":75.85,"id":11392436}]}]}
{"op":"mcm","clk":"11930900177","pt":1724270221623,"mc":[{"id":"1.232098082","rc":[{"batb":[[0,3.05,10],[1,3,18.44],[2,2.6,5.08]],"ltp":3.6,"tv":75.85,"id":11392436}]}]}
{"op":"mcm","clk":"11930900534","pt":1724270224947,"mc":[{"id":"1.232098082","rc":[{"batb":[[0,3,18.44],[1,2.6,5.08],[2,1.04,1.53]],"ltp":3.6,"tv":75.85,"id":11392436}]}]}
{"op":"mcm","clk":"11930900746","pt":1724270227158,"mc":[{"id":"1.232098082","rc":[{"batb":[[0,3.05,10],[1,3,18.44],[2,2.6,5.08]],"ltp":3.6,"tv":75.85,"id":11392436}]}]}
{"op":"mcm","clk":"11930901076","pt":1724270230472,"mc":[{"id":"1.232098082","rc":[{"batb":[[0,3,18.44],[1,2.6,5.08],[2,1.04,1.53]],"ltp":3.6,"tv":75.85,"id":11392436}]}]}
{"op":"mcm","clk":"11930901424","pt":1724270233880,"mc":[{"id":"1.232098082","rc":[{"batb":[[0,3.05,10],[1,3,18.44],[2,2.6,5.08]],"ltp":3.6,"tv":75.85,"id":11392436}]}]}
{"op":"mcm","clk":"11930901753","pt":1724270237140,"mc":[{"id":"1.232098082","rc":[{"batb":[[0,3,18.44],[1,2.6,5.08],[2,1.04,1.53]],"ltp":3.6,"tv":75.85,"id":11392436}]}]}
{"op":"mcm","clk":"11930902006","pt":1724270239571,"mc":[{"id":"1.232098082","rc":[{"batb":[[0,3.05,10],[1,3,18.44],[2,2.6,5.08]],"ltp":3.6,"tv":75.85,"id":11392436}]}]}
{"op":"mcm","clk":"11930902332","pt":1724270242870,"mc":[{"id":"1.232098082","rc":[{"batb":[[0,3,18.44],[1,2.6,5.08],[2,1.04,1.53]],"ltp":3.6,"tv":75.85,"id":11392436}]}]}
{"op":"mcm","clk":"11930903741","pt":1724270255260,"mc":[{"id":"1.232098082","rc":[{"batb":[[0,3.05,10],[1,3,18.44],[2,2.6,5.08]],"ltp":3.6,"tv":75.85,"id":11392436}]}]}
{"op":"mcm","clk":"11930904074","pt":1724270258656,"mc":[{"id":"1.232098082","rc":[{"batb":[[0,3,18.44],[1,2.6,5.08],[2,1.04,1.53]],"ltp":3.6,"tv":75.85,"id":11392436}]}]}
{"op":"mcm","clk":"11930904279","pt":1724270261182,"mc":[{"id":"1.232098082","rc":[{"batb":[[0,3.05,10],[1,3,18.44],[2,2.6,5.08]],"ltp":3.6,"tv":75.85,"id":11392436}]}]}
{"op":"mcm","clk":"11930904620","pt":1724270264380,"mc":[{"id":"1.232098082","rc":[{"batb":[[0,3,18.44],[1,2.6,5.08],[2,1.04,1.53]],"ltp":3.6,"tv":75.85,"id":11392436}]}]}
{"op":"mcm","clk":"11930904901","pt":1724270267584,"mc":[{"id":"1.232098082","rc":[{"batb":[[0,3.05,10],[1,3,18.44],[2,2.6,5.08]],"ltp":3.6,"tv":75.85,"id":11392436}]}]}
{"op":"mcm","clk":"11930905185","pt":1724270270885,"mc":[{"id":"1.232098082","rc":[{"batb":[[0,3,18.44],[1,2.6,5.08],[2,1.04,1.53]],"ltp":3.6,"tv":75.85,"id":11392436}]}]}
{"op":"mcm","clk":"11930905547","pt":1724270274401,"mc":[{"id":"1.232098082","rc":[{"batb":[[0,3.05,10],[1,3,18.44],[2,2.6,5.08]],"ltp":3.6,"tv":75.85,"id":11392436}]}]}
{"op":"mcm","clk":"11930905845","pt":1724270277804,"mc":[{"id":"1.232098082","rc":[{"batb":[[0,3,18.44],[1,2.6,5.08],[2,1.04,1.53]],"ltp":3.6,"tv":75.85,"id":11392436}]}]}
{"op":"mcm","clk":"11930906631","pt":1724270286036,"mc":[{"id":"1.232098082","rc":[{"batb":[[0,3.05,10],[1,3,18.44],[2,2.6,5.08]],"ltp":3.6,"tv":75.85,"id":11392436}]}]}
{"op":"mcm","clk":"11930906959","pt":1724270289428,"mc":[{"id":"1.232098082","rc":[{"batb":[[0,3,18.44],[1,2.6,5.08],[2,1.04,1.53]],"ltp":3.6,"tv":75.85,"id":11392436}]}]}
{"op":"mcm","clk":"11930907419","pt":1724270294536,"mc":[{"id":"1.232098082","rc":[{"batb":[[0,3.05,10],[1,3,18.44],[2,2.6,5.08]],"ltp":3.6,"tv":75.85,"id":11392436}]}]}
{"op":"mcm","clk":"11930907741","pt":1724270297946,"mc":[{"id":"1.232098082","rc":[{"batb":[[0,3,18.44],[1,2.6,5.08],[2,1.04,1.53]],"ltp":3.6,"tv":75.85,"id":11392436}]}]}
{"op":"mcm","clk":"11930918539","pt":1724270413284,"mc":[{"id":"1.232098082","rc":[{"trd":[[3.35,73.37],[3.6,2.54]],"batb":[[0,3.05,10],[1,3,18.44],[2,2.6,5.09]],"batl":[[0,24,1.15]],"ltp":3.6,"tv":75.91,"id":11392436},{"trd":[[1.43,566.82]],"batl":[[1,24,1.15]],"ltp":1.39,"tv":573.4,"id":48610314}],"tv":649.31}]}
{"op":"mcm","clk":"11930918903","pt":1724270416697,"mc":[{"id":"1.232098082","rc":[{"batb":[[0,3,18.44],[1,2.6,5.09],[2,1.04,1.53]],"ltp":3.6,"tv":75.91,"id":11392436}]}]}
{"op":"mcm","clk":"11930919705","pt":1724270424912,"mc":[{"id":"1.232098082","rc":[{"batb":[[0,3.05,10],[1,3,18.44],[2,2.6,5.09]],"ltp":3.6,"tv":75.91,"id":11392436}]}]}
{"op":"mcm","clk":"11930920067","pt":1724270428331,"mc":[{"id":"1.232098082","rc":[{"batb":[[0,3,18.44],[1,2.6,5.09],[2,1.04,1.53]],"ltp":3.6,"tv":75.91,"id":11392436}]}]}
{"op":"mcm","clk":"11930921627","pt":1724270443498,"mc":[{"id":"1.232098082","rc":[{"batb":[[0,3.05,10],[1,3,18.44],[2,2.6,5.09]],"ltp":3.6,"tv":75.91,"id":11392436}]}]}
{"op":"mcm","clk":"11930922010","pt":1724270446811,"mc":[{"id":"1.232098082","rc":[{"batb":[[0,3,18.44],[1,2.6,5.09],[2,1.04,1.53]],"ltp":3.6,"tv":75.91,"id":11392436}]}]}
{"op":"mcm","clk":"11930922247","pt":1724270449218,"mc":[{"id":"1.232098082","rc":[{"batb":[[0,3.05,10],[1,3,18.44],[2,2.6,5.09]],"ltp":3.6,"tv":75.91,"id":11392436}]}]}
{"op":"mcm","clk":"11930922576","pt":1724270452527,"mc":[{"id":"1.232098082","rc":[{"batb":[[0,3,18.44],[1,2.6,5.09],[2,1.04,1.53]],"ltp":3.6,"tv":75.91,"id":11392436}]}]}
{"op":"mcm","clk":"11930923022","pt":1724270456928,"mc":[{"id":"1.232098082","rc":[{"batb":[[0,3.05,10],[1,3,18.44],[2,2.6,5.09]],"ltp":3.6,"tv":75.91,"id":11392436}]}]}
{"op":"mcm","clk":"11930923373","pt":1724270460129,"mc":[{"id":"1.232098082","rc":[{"batb":[[0,3,18.44],[1,2.6,5.09],[2,1.04,1.53]],"ltp":3.6,"tv":75.91,"id":11392436}]}]}
{"op":"mcm","clk":"11930925316","pt":1724270480361,"mc":[{"id":"1.232098082","rc":[{"batb":[[0,3.05,10],[1,3,18.44],[2,2.6,5.09]],"ltp":3.6,"tv":75.91,"id":11392436}]}]}
{"op":"mcm","clk":"11930925685","pt":1724270483763,"mc":[{"id":"1.232098082","rc":[{"batb":[[0,3,18.44],[1,2.6,5.09],[2,1.04,1.53]],"ltp":3.6,"tv":75.91,"id":11392436}]}]}
{"op":"mcm","clk":"11930926413","pt":1724270492369,"mc":[{"id":"1.232098082","rc":[{"batb":[[0,3.05,10],[1,3,18.44],[2,2.6,5.09]],"ltp":3.6,"tv":75.91,"id":11392436}]}]}
{"op":"mcm","clk":"11930926713","pt":1724270495678,"mc":[{"id":"1.232098082","rc":[{"batb":[[0,3,18.44],[1,2.6,5.09],[2,1.04,1.53]],"ltp":3.6,"tv":75.91,"id":11392436}]}]}
{"op":"mcm","clk":"11930927690","pt":1724270504976,"mc":[{"id":"1.232098082","rc":[{"batb":[[0,3.05,10],[1,3,18.44],[2,2.6,5.09]],"ltp":3.6,"tv":75.91,"id":11392436}]}]}
{"op":"mcm","clk":"11930928051","pt":1724270508389,"mc":[{"id":"1.232098082","rc":[{"batb":[[0,3,18.44],[1,2.6,5.09],[2,1.04,1.53]],"ltp":3.6,"tv":75.91,"id":11392436}]}]}
{"op":"mcm","clk":"11930928995","pt":1724270518288,"mc":[{"id":"1.232098082","rc":[{"batb":[[0,3.05,10],[1,3,18.44],[2,2.6,5.09]],"ltp":3.6,"tv":75.91,"id":11392436},{"batl":[[0,1.42,418.84],[1,1.49,15],[2,24,1.15]],"ltp":1.39,"tv":573.4,"id":48610314}]}]}
{"op":"mcm","clk":"11930929304","pt":1724270521711,"mc":[{"id":"1.232098082","rc":[{"batb":[[0,3,18.44],[1,2.6,5.09],[2,1.04,1.53]],"ltp":3.6,"tv":75.91,"id":11392436}]}]}
{"op":"mcm","clk":"11930932630","pt":1724270554662,"mc":[{"id":"1.232098082","rc":[{"batb":[[0,3.05,10],[1,3,18.44],[2,2.6,5.09]],"ltp":3.6,"tv":75.91,"id":11392436}]}]}
{"op":"mcm","clk":"11930933015","pt":1724270557913,"mc":[{"id":"1.232098082","rc":[{"batb":[[0,3,18.44],[1,2.6,5.09],[2,1.04,1.53]],"ltp":3.6,"tv":75.91,"id":11392436}]}]}
{"op":"mcm","clk":"11930934487","pt":1724270574065,"mc":[{"id":"1.232098082","rc":[{"batb":[[0,3.05,10],[1,3,18.44],[2,2.6,5.09]],"ltp":3.6,"tv":75.91,"id":11392436}]}]}
{"op":"mcm","clk":"11930934770","pt":1724270577347,"mc":[{"id":"1.232098082","rc":[{"batb":[[0,3,18.44],[1,2.6,5.09],[2,1.04,1.53]],"ltp":3.6,"tv":75.91,"id":11392436}]}]}
{"op":"mcm","clk":"11930936137","pt":1724270590893,"mc":[{"id":"1.232098082","rc":[{"batb":[[0,3.05,10],[1,3,18.44],[2,2.6,5.09]],"ltp":3.6,"tv":75.91,"id":11392436}]}]}
{"op":"mcm","clk":"11930936487","pt":1724270594273,"mc":[{"id":"1.232098082","rc":[{"batb":[[0,3,18.44],[1,2.6,5.09],[2,1.04,1.53]],"ltp":3.6,"tv":75.91,"id":11392436}]}]}
{"op":"mcm","clk":"11930937075","pt":1724270600365,"mc":[{"id":"1.232098082","rc":[{"batb":[[0,3.05,10],[1,3,18.44],[2,2.6,5.09]],"ltp":3.6,"tv":75.91,"id":11392436}]}]}
{"op":"mcm","clk":"11930937384","pt":1724270603824,"mc":[{"id":"1.232098082","rc":[{"batb":[[0,3,18.44],[1,2.6,5.09],[2,1.04,1.53]],"ltp":3.6,"tv":75.91,"id":11392436}]}]}
{"op":"mcm","clk":"11930944153","pt":1724270675984,"mc":[{"id":"1.232098082","rc":[{"batb":[[0,3.05,10],[1,3,18.44],[2,2.6,5.09]],"ltp":3.6,"tv":75.91,"id":11392436}]}]}
{"op":"mcm","clk":"11930944447","pt":1724270679393,"mc":[{"id":"1.232098082","rc":[{"batb":[[0,3,18.44],[1,2.6,5.09],[2,1.04,1.53]],"ltp":3.6,"tv":75.91,"id":11392436}]}]}
{"op":"mcm","clk":"11930949285","pt":1724270729425,"mc":[{"id":"1.232098082","rc":[{"batb":[[0,3.05,10],[1,3,18.44],[2,2.6,5.09]],"ltp":3.6,"tv":75.91,"id":11392436},{"batl":[[0,1.41,17.04],[1,1.42,418.84],[2,1.49,15]],"ltp":1.39,"tv":573.4,"id":48610314}]}]}
{"op":"mcm","clk":"11930949663","pt":1724270732733,"mc":[{"id":"1.232098082","rc":[{"batb":[[0,3,18.44],[1,2.6,5.09],[2,1.04,1.53]],"ltp":3.6,"tv":75.91,"id":11392436}]}]}
{"op":"mcm","clk":"11930953968","pt":1724270771190,"mc":[{"id":"1.232098082","rc":[{"batb":[[0,3.05,10],[1,3,18.44],[2,2.6,5.09]],"ltp":3.6,"tv":75.91,"id":11392436}]}]}
{"op":"mcm","clk":"11930954356","pt":1724270774550,"mc":[{"id":"1.232098082","rc":[{"batb":[[0,3,18.44],[1,2.6,5.09],[2,1.04,1.53]],"ltp":3.6,"tv":75.91,"id":11392436}]}]}
{"op":"mcm","clk":"11930958232","pt":1724270809937,"mc":[{"id":"1.232098082","rc":[{"batb":[[0,3.05,10],[1,3,18.44],[2,2.6,5.09]],"ltp":3.6,"tv":75.91,"id":11392436}]}]}
{"op":"mcm","clk":"11930958576","pt":1724270813238,"mc":[{"id":"1.232098082","rc":[{"batb":[[0,3,18.44],[1,2.6,5.09],[2,1.04,1.53]],"ltp":3.6,"tv":75.91,"id":11392436}]}]}
{"op":"mcm","clk":"11930958896","pt":1724270816342,"mc":[{"id":"1.232098082","rc":[{"batb":[[0,3.05,10],[1,3,18.44],[2,2.6,5.09]],"ltp":3.6,"tv":75.91,"id":11392436}]}]}
{"op":"mcm","clk":"11930959254","pt":1724270819740,"mc":[{"id":"1.232098082","rc":[{"batb":[[0,3,18.44],[1,2.6,5.09],[2,1.04,1.53]],"ltp":3.6,"tv":75.91,"id":11392436}]}]}
{"op":"mcm","clk":"11930960063","pt":1724270827455,"mc":[{"id":"1.232098082","rc":[{"batb":[[0,3.05,10],[1,3,18.44],[2,2.6,5.09]],"ltp":3.6,"tv":75.91,"id":11392436}]}]}
{"op":"mcm","clk":"11930960422","pt":1724270830955,"mc":[{"id":"1.232098082","rc":[{"batb":[[0,3,18.44],[1,2.6,5.09],[2,1.04,1.53]],"ltp":3.6,"tv":75.91,"id":11392436}]}]}
{"op":"mcm","clk":"11930960821","pt":1724270834540,"mc":[{"id":"1.232098082","rc":[{"batb":[[0,3.05,10],[1,3,18.44],[2,2.6,5.09]],"ltp":3.6,"tv":75.91,"id":11392436}]}]}
{"op":"mcm","clk":"11930961141","pt":1724270837847,"mc":[{"id":"1.232098082","rc":[{"batb":[[0,3,18.44],[1,2.6,5.09],[2,1.04,1.53]],"ltp":3.6,"tv":75.91,"id":11392436}]}]}
{"op":"mcm","clk":"11930962138","pt":1724270848435,"mc":[{"id":"1.232098082","rc":[{"batb":[[0,3.05,10],[1,3,23.53]],"ltp":3.6,"tv":75.91,"id":11392436}]}]}
{"op":"mcm","clk":"11930962447","pt":1724270851881,"mc":[{"id":"1.232098082","rc":[{"batb":[[0,3,23.53],[1,1.04,1.53],[2,1.03,200]],"ltp":3.6,"tv":75.91,"id":11392436}]}]}
{"op":"mcm","clk":"11930963162","pt":1724270859188,"mc":[{"id":"1.232098082","rc":[{"batb":[[0,3.05,10],[1,3,23.53],[2,1.04,1.53]],"ltp":3.6,"tv":75.91,"id":11392436}]}]}
{"op":"mcm","clk":"11930963469","pt":1724270862492,"mc":[{"id":"1.232098082","rc":[{"batb":[[0,3,23.53],[1,1.04,1.53],[2,1.03,200]],"ltp":3.6,"tv":75.91,"id":11392436}]}]}
{"op":"mcm","clk":"11930968362","pt":1724270909844,"mc":[{"id":"1.232098082","rc":[{"batb":[[0,3.45,10],[1,3.4,7.25],[2,3,23.53]],"ltp":3.6,"tv":75.91,"id":11392436}]}]}
{"op":"mcm","clk":"11930968708","pt":1724270913257,"mc":[{"id":"1.232098082","rc":[{"batb":[[0,3.4,7.25],[1,3,23.53],[2,1.04,1.53]],"ltp":3.6,"tv":75.91,"id":11392436}]}]}
{"op":"mcm","clk":"11930970207","pt":1724270928280,"mc":[{"id":"1.232098082","rc":[{"batb":[[0,3.45,10],[1,3.4,7.25],[2,3,23.53]],"ltp":3.6,"tv":75.91,"id":11392436}]}]}
{"op":"mcm","clk":"11930970550","pt":1724270931659,"mc":[{"id":"1.232098082","rc":[{"batb":[[0,3.4,7.25],[1,3,23.53],[2,1.04,1.53]],"ltp":3.6,"tv":75.91,"id":11392436}]}]}
{"op":"mcm","clk":"11930972168","pt":1724270947097,"mc":[{"id":"1.232098082","rc":[{"batb":[[0,3.45,10],[1,3.4,7.25],[2,3,23.53]],"ltp":3.6,"tv":75.91,"id":11392436}]}]}
{"op":"mcm","clk":"11930972498","pt":1724270950488,"mc":[{"id":"1.232098082","rc":[{"batb":[[0,3.4,7.25],[1,3,23.53],[2,1.04,1.53]],"ltp":3.6,"tv":75.91,"id":11392436}]}]}
{"op":"mcm","clk":"11930973634","pt":1724270962340,"mc":[{"id":"1.232098082","rc":[{"batb":[[0,3.45,10],[1,3.4,7.25],[2,3,23.53]],"ltp":3.6,"tv":75.91,"id":11392436}]}]}
{"op":"mcm","clk":"11930974012","pt":1724270965714,"mc":[{"id":"1.232098082","rc":[{"batb":[[0,3.4,7.25],[1,3,23.53],[2,1.04,1.53]],"ltp":3.6,"tv":75.91,"id":11392436}]}]}
{"op":"mcm","clk":"11930975415","pt":1724270980346,"mc":[{"id":"1.232098082","rc":[{"batb":[[0,3.45,10],[1,3.4,7.25],[2,3,23.53]],"ltp":3.6,"tv":75.91,"id":11392436}]}]}
{"op":"mcm","clk":"11930975767","pt":1724270983819,"mc":[{"id":"1.232098082","rc":[{"batb":[[0,3.4,7.25],[1,3,23.53],[2,1.04,1.53]],"ltp":3.6,"tv":75.91,"id":11392436}]}]}
{"op":"mcm","clk":"11930976354","pt":1724270989620,"mc":[{"id":"1.232098082","rc":[{"batb":[[0,3.45,10],[1,3.4,7.25],[2,3,23.53]],"ltp":3.6,"tv":75.91,"id":11392436}]}]}
{"op":"mcm","clk":"11930976659","pt":1724270992939,"mc":[{"id":"1.232098082","rc":[{"batb":[[0,3.4,7.25],[1,3,23.53],[2,1.04,1.53]],"ltp":3.6,"tv":75.91,"id":11392436}]}]}
{"op":"mcm","clk":"11930976882","pt":1724270995156,"mc":[{"id":"1.232098082","rc":[{"batb":[[0,3.45,10],[1,3.4,7.25],[2,3,23.53]],"ltp":3.6,"tv":75.91,"id":11392436}]}]}
{"op":"mcm","clk":"11930977231","pt":1724270998559,"mc":[{"id":"1.232098082","rc":[{"batb":[[0,3.4,7.25],[1,3,23.53],[2,1.04,1.53]],"ltp":3.6,"tv":75.91,"id":11392436}]}]}
{"op":"mcm","clk":"11930977914","pt":1724271004689,"mc":[{"id":"1.232098082","rc":[{"batb":[[0,3.45,10],[1,3.4,7.25],[2,3,23.53]],"ltp":3.6,"tv":75.91,"id":11392436}]}]}
{"op":"mcm","clk":"11930978239","pt":1724271007665,"mc":[{"id":"1.232098082","rc":[{"trd":[[1.39,16.58]],"batb":[[0,1.04,1.53],[1,1.03,200],[2,1.02,200]],"batl":[[0,1.39,3.82],[1,1.41,17.04],[2,1.42,418.84]],"ltp":1.39,"tv":583.4,"id":48610314}],"tv":659.31}]}
{"op":"mcm","clk":"11930978268","pt":1724271007874,"mc":[{"id":"1.232098082","rc":[{"batb":[[0,3.4,7.25],[1,3,23.53],[2,1.04,1.53]],"ltp":3.6,"tv":75.91,"id":11392436}]}]}
{"op":"mcm","clk":"11930978533","pt":1724271010466,"mc":[{"id":"1.232098082","rc":[{"batb":[[0,3.05,10]],"ltp":3.6,"tv":75.91,"id":11392436}]}]}
{"op":"mcm","clk":"11930978865","pt":1724271013974,"mc":[{"id":"1.232098082","rc":[{"batb":[[0,3,23.53],[1,1.04,1.53],[2,1.03,200]],"ltp":3.6,"tv":75.91,"id":11392436}]}]}
{"op":"mcm","clk":"11930980268","pt":1724271028705,"mc":[{"id":"1.232098082","rc":[{"batb":[[0,3.05,10],[1,3,23.53],[2,1.04,1.53]],"ltp":3.6,"tv":75.91,"id":11392436}]}]}
{"op":"mcm","clk":"11930980603","pt":1724271031979,"mc":[{"id":"1.232098082","rc":[{"batb":[[0,3,23.53],[1,1.04,1.53],[2,1.03,200]],"ltp":3.6,"tv":75.91,"id":11392436}]}]}
{"op":"mcm","clk":"11930980895","pt":1724271034578,"mc":[{"id":"1.232098082","rc":[{"batb":[[0,3.05,10],[1,3,23.53],[2,1.04,1.53]],"ltp":3.6,"tv":75.91,"id":11392436}]}]}
{"op":"mcm","clk":"11930981281","pt":1724271037998,"mc":[{"id":"1.232098082","rc":[{"batb":[[0,3,23.53],[1,1.04,1.53],[2,1.03,200]],"ltp":3.6,"tv":75.91,"id":11392436}]}]}
{"op":"mcm","clk":"11930982313","pt":1724271047244,"mc":[{"id":"1.232098082","rc":[{"batb":[[0,3.05,10],[1,3,23.53],[2,1.04,1.53]],"ltp":3.6,"tv":75.91,"id":11392436}]}]}
{"op":"mcm","clk":"11930982779","pt":1724271050491,"mc":[{"id":"1.232098082","rc":[{"batb":[[0,3,23.53],[1,1.04,1.53],[2,1.03,200]],"ltp":3.6,"tv":75.91,"id":11392436}]}]}
{"op":"mcm","clk":"11930983078","pt":1724271052951,"mc":[{"id":"1.232098082","rc":[{"batb":[[0,3.05,10],[1,3,23.53],[2,1.04,1.53]],"ltp":3.6,"tv":75.91,"id":11392436}]}]}
{"op":"mcm","clk":"11930983459","pt":1724271056219,"mc":[{"id":"1.232098082","rc":[{"batb":[[0,3,23.53],[1,1.04,1.53],[2,1.03,200]],"ltp":3.6,"tv":75.91,"id":11392436}]}]}
{"op":"mcm","clk":"11930984337","pt":1724271064234,"mc":[{"id":"1.232098082","rc":[{"batb":[[0,3.05,10],[1,3,23.53],[2,1.04,1.53]],"ltp":3.6,"tv":75.91,"id":11392436}]}]}
{"op":"mcm","clk":"11930984644","pt":1724271067445,"mc":[{"id":"1.232098082","rc":[{"batb":[[0,3,23.53],[1,1.04,1.53],[2,1.03,200]],"ltp":3.6,"tv":75.91,"id":11392436}]}]}
{"op":"mcm","clk":"11930985713","pt":1724271079401,"mc":[{"id":"1.232098082","rc":[{"batb":[[0,3.05,10],[1,3,23.53],[2,1.04,1.53]],"ltp":3.6,"tv":75.91,"id":11392436}]}]}
{"op":"mcm","clk":"11930986037","pt":1724271082762,"mc":[{"id":"1.232098082","rc":[{"batb":[[0,3,23.53],[1,1.04,1.53],[2,1.03,200]],"ltp":3.6,"tv":75.91,"id":11392436}]}]}
{"op":"mcm","clk":"11930986407","pt":1724271086590,"mc":[{"id":"1.232098082","rc":[{"batb":[[0,3.05,10],[1,3,23.53],[2,1.04,1.53]],"ltp":3.6,"tv":75.91,"id":11392436}]}]}
{"op":"mcm","clk":"11930986735","pt":1724271089999,"mc":[{"id":"1.232098082","rc":[{"batb":[[0,3,23.53],[1,1.04,1.53],[2,1.03,200]],"ltp":3.6,"tv":75.91,"id":11392436}]}]}
{"op":"mcm","clk":"11930987072","pt":1724271093275,"mc":[{"id":"1.232098082","rc":[{"batb":[[0,3.05,10],[1,3,23.53],[2,1.04,1.53]],"ltp":3.6,"tv":75.91,"id":11392436}]}]}
{"op":"mcm","clk":"11930987430","pt":1724271096689,"mc":[{"id":"1.232098082","rc":[{"batb":[[0,3,23.53],[1,1.04,1.53],[2,1.03,200]],"ltp":3.6,"tv":75.91,"id":11392436}]}]}
{"op":"mcm","clk":"11930987745","pt":1724271099788,"mc":[{"id":"1.232098082","rc":[{"batb":[[0,3.05,10],[1,3,23.53],[2,1.04,1.53]],"ltp":3.6,"tv":75.91,"id":11392436}]}]}
{"op":"mcm","clk":"11930988070","pt":1724271103295,"mc":[{"id":"1.232098082","rc":[{"batb":[[0,3,23.53],[1,1.04,1.53],[2,1.03,200]],"ltp":3.6,"tv":75.91,"id":11392436}]}]}
{"op":"mcm","clk":"11930988288","pt":1724271105716,"mc":[{"id":"1.232098082","rc":[{"batb":[[0,3.05,10],[1,3,23.53],[2,1.04,1.53]],"ltp":3.6,"tv":75.91,"id":11392436}]}]}
{"op":"mcm","clk":"11930988575","pt":1724271109020,"mc":[{"id":"1.232098082","rc":[{"batb":[[0,3,23.53],[1,1.04,1.53],[2,1.03,200]],"ltp":3.6,"tv":75.91,"id":11392436}]}]}
{"op":"mcm","clk":"11930988806","pt":1724271111606,"mc":[{"id":"1.232098082","rc":[{"batb":[[0,3.05,10],[1,3,23.53],[2,1.04,1.53]],"ltp":3.6,"tv":75.91,"id":11392436}]}]}
{"op":"mcm","clk":"11930989117","pt":1724271114913,"mc":[{"id":"1.232098082","rc":[{"batb":[[0,3,23.53],[1,1.04,1.53],[2,1.03,200]],"ltp":3.6,"tv":75.91,"id":11392436}]}]}
{"op":"mcm","clk":"11930989473","pt":1724271118634,"mc":[{"id":"1.232098082","rc":[{"batb":[[0,3.05,10],[1,3,23.53],[2,1.04,1.53]],"ltp":3.6,"tv":75.91,"id":11392436}]}]}
{"op":"mcm","clk":"11930989798","pt":1724271122022,"mc":[{"id":"1.232098082","rc":[{"batb":[[0,3,23.53],[1,1.04,1.53],[2,1.03,200]],"ltp":3.6,"tv":75.91,"id":11392436}]}]}
{"op":"mcm","clk":"11930990121","pt":1724271125544,"mc":[{"id":"1.232098082","rc":[{"batb":[[0,3.05,10],[1,3,23.53],[2,1.04,1.53]],"ltp":3.6,"tv":75.91,"id":11392436}]}]}
{"op":"mcm","clk":"11930990440","pt":1724271128925,"mc":[{"id":"1.232098082","rc":[{"batb":[[0,3,23.53],[1,1.04,1.53],[2,1.03,200]],"ltp":3.6,"tv":75.91,"id":11392436}]}]}
{"op":"mcm","clk":"11930991172","pt":1724271135829,"mc":[{"id":"1.232098082","rc":[{"batb":[[0,3.05,10],[1,3,23.53],[2,1.04,1.53]],"ltp":3.6,"tv":75.91,"id":11392436}]}]}
{"op":"mcm","clk":"11930991512","pt":1724271139357,"mc":[{"id":"1.232098082","rc":[{"batb":[[0,3,23.53],[1,1.04,1.53],[2,1.03,200]],"ltp":3.6,"tv":75.91,"id":11392436}]}]}
{"op":"mcm","clk":"11930991713","pt":1724271141530,"mc":[{"id":"1.232098082","rc":[{"batb":[[0,3.05,10],[1,3,23.53],[2,1.04,1.53]],"ltp":3.6,"tv":75.91,"id":11392436}]}]}
{"op":"mcm","clk":"11930992022","pt":1724271144951,"mc":[{"id":"1.232098082","rc":[{"batb":[[0,3,23.53],[1,1.04,1.53],[2,1.03,200]],"ltp":3.6,"tv":75.91,"id":11392436}]}]}
{"op":"mcm","clk":"11930992398","pt":1724271148637,"mc":[{"id":"1.232098082","rc":[{"batb":[[0,3.05,10],[1,3,23.53],[2,1.04,1.53]],"ltp":3.6,"tv":75.91,"id":11392436}]}]}
{"op":"mcm","clk":"11930992730","pt":1724271151949,"mc":[{"id":"1.232098082","rc":[{"batb":[[0,3,23.53],[1,1.04,1.53],[2,1.03,200]],"ltp":3.6,"tv":75.91,"id":11392436}]}]}
{"op":"mcm","clk":"11930993994","pt":1724271165686,"mc":[{"id":"1.232098082","rc":[{"batb":[[0,3.05,10],[1,3,23.53],[2,1.04,1.53]],"ltp":3.6,"tv":75.91,"id":11392436}]}]}
{"op":"mcm","clk":"11930994349","pt":1724271169068,"mc":[{"id":"1.232098082","rc":[{"batb":[[0,3,23.53],[1,1.04,1.53],[2,1.03,200]],"ltp":3.6,"tv":75.91,"id":11392436}]}]}
{"op":"mcm","clk":"11931005004","pt":1724271176077,"mc":[{"id":"1.232098082","rc":[{"batb":[[0,3.05,10],[1,3,23.53],[2,1.04,1.53]],"ltp":3.6,"tv":75.91,"id":11392436},{"batb":[[0,1.04,2.45]],"ltp":1.39,"tv":583.4,"id":48610314}]}]}
{"op":"mcm","clk":"11931005289","pt":1724271179386,"mc":[{"id":"1.232098082","rc":[{"batb":[[0,3,23.53],[1,1.04,1.53],[2,1.03,200]],"ltp":3.6,"tv":75.91,"id":11392436}]}]}
{"op":"mcm","clk":"11931006119","pt":1724271188588,"mc":[{"id":"1.232098082","rc":[{"batb":[[0,3.05,10],[1,3,23.53],[2,1.04,1.53]],"ltp":3.6,"tv":75.91,"id":11392436}]}]}
{"op":"mcm","clk":"11931006406","pt":1724271191904,"mc":[{"id":"1.232098082","rc":[{"batb":[[0,3,23.53],[1,1.04,1.53],[2,1.03,200]],"ltp":3.6,"tv":75.91,"id":11392436}]}]}
{"op":"mcm","clk":"11931006650","pt":1724271194614,"mc":[{"id":"1.232098082","rc":[{"batb":[[0,3.05,10],[1,3,23.53],[2,1.04,1.53]],"ltp":3.6,"tv":75.91,"id":11392436}]}]}
{"op":"mcm","clk":"11931006737","pt":1724271195498,"mc":[{"id":"1.232098082","rc":[{"batb":[[0,1.14,22.3],[1,1.04,1.53],[2,1.03,200]],"ltp":1.39,"tv":583.4,"id":48610314}]}]}
{"op":"mcm","clk":"11931006791","pt":1724271196016,"mc":[{"id":"1.232098082","rc":[{"batb":[[0,3.4,7.25],[1,3.05,10],[2,3,23.53]],"ltp":3.6,"tv":75.91,"id":11392436}]}]}
{"op":"mcm","clk":"11931006954","pt":1724271197788,"mc":[{"id":"1.232098082","rc":[{"batb":[[1,3,23.53],[2,1.04,1.53]],"ltp":3.6,"tv":75.91,"id":11392436}]}]}
{"op":"mcm","clk":"11931007496","pt":1724271203295,"mc":[{"id":"1.232098082","rc":[{"batb":[[0,3.45,10],[1,3.4,7.25],[2,3,23.53]],"ltp":3.6,"tv":75.91,"id":11392436},{"batl":[[0,1.41,17.04],[1,1.42,418.84],[2,1.49,15]],"ltp":1.39,"tv":583.4,"id":48610314}]}]}
{"op":"mcm","clk":"11931007823","pt":1724271206819,"mc":[{"id":"1.232098082","rc":[{"batb":[[0,3.4,7.25],[1,3,23.53],[2,1.04,1.53]],"ltp":3.6,"tv":75.91,"id":11392436}]}]}
{"op":"mcm","clk":"11931008261","pt":1724271211029,"mc":[{"id":"1.232098082","rc":[{"batb":[[0,3.45,10],[1,3.4,7.25],[2,3,23.53]],"ltp":3.6,"tv":75.91,"id":11392436}]}]}
{"op":"mcm","clk":"11931008613","pt":1724271214303,"mc":[{"id":"1.232098082","rc":[{"batb":[[0,3.4,7.25],[1,3,23.53],[2,1.04,1.53]],"ltp":3.6,"tv":75.91,"id":11392436}]}]}
{"op":"mcm","clk":"11931009017","pt":1724271218846,"mc":[{"id":"1.232098082","rc":[{"batb":[[0,3.45,10],[1,3.4,7.25],[2,3,23.53]],"ltp":3.6,"tv":75.91,"id":11392436}]}]}
{"op":"mcm","clk":"11931009310","pt":1724271222012,"mc":[{"id":"1.232098082","rc":[{"batb":[[0,3.4,7.25],[1,3,23.53],[2,1.04,1.53]],"ltp":3.6,"tv":75.91,"id":11392436}]}]}
{"op":"mcm","clk":"11931009554","pt":1724271224554,"mc":[{"id":"1.232098082","rc":[{"batb":[[0,3.45,10],[1,3.4,7.25],[2,3,23.53]],"ltp":3.6,"tv":75.91,"id":11392436}]}]}
{"op":"mcm","clk":"11931009880","pt":1724271227930,"mc":[{"id":"1.232098082","rc":[{"batb":[[0,3.4,7.25],[1,3,23.53],[2,1.04,1.53]],"ltp":3.6,"tv":75.91,"id":11392436}]}]}
{"op":"mcm","clk":"11931011348","pt":1724271243150,"mc":[{"id":"1.232098082","rc":[{"batb":[[0,3.45,10],[1,3.4,7.25],[2,3,23.53]],"ltp":3.6,"tv":75.91,"id":11392436}]}]}
{"op":"mcm","clk":"11931011674","pt":1724271246449,"mc":[{"id":"1.232098082","rc":[{"batb":[[0,3.4,7.25],[1,3,23.53],[2,1.04,1.53]],"ltp":3.6,"tv":75.91,"id":11392436}]}]}
{"op":"mcm","clk":"11931011980","pt":1724271249469,"mc":[{"id":"1.232098082","rc":[{"batb":[[0,3.45,10],[1,3.4,7.25],[2,3,23.53]],"ltp":3.6,"tv":75.91,"id":11392436}]}]}
{"op":"mcm","clk":"11931012302","pt":1724271252873,"mc":[{"id":"1.232098082","rc":[{"batb":[[0,3.4,7.25],[1,3,23.53],[2,1.04,1.53]],"ltp":3.6,"tv":75.91,"id":11392436}]}]}
{"op":"mcm","clk":"11931013068","pt":1724271260875,"mc":[{"id":"1.232098082","rc":[{"batb":[[0,3.45,10],[1,3.4,7.25],[2,3,23.53]],"ltp":3.6,"tv":75.91,"id":11392436}]}]}
{"op":"mcm","clk":"11931013409","pt":1724271264305,"mc":[{"id":"1.232098082","rc":[{"batb":[[0,3.4,7.25],[1,3,23.53],[2,1.04,1.53]],"ltp":3.6,"tv":75.91,"id":11392436}]}]}
{"op":"mcm","clk":"11931013691","pt":1724271267695,"mc":[{"id":"1.232098082","rc":[{"batb":[[0,3.45,10],[1,3.4,7.25],[2,3,23.53]],"ltp":3.6,"tv":75.91,"id":11392436}]}]}
{"op":"mcm","clk":"11931013971","pt":1724271271120,"mc":[{"id":"1.232098082","rc":[{"batb":[[0,3.4,7.25],[1,3,23.53],[2,1.04,1.53]],"ltp":3.6,"tv":75.91,"id":11392436}]}]}
{"op":"mcm","clk":"11931014251","pt":1724271274395,"mc":[{"id":"1.232098082","rc":[{"batb":[[0,3.45,10],[1,3.4,7.25],[2,3,23.53]],"ltp":3.6,"tv":75.91,"id":11392436}]}]}
{"op":"mcm","clk":"11931014543","pt":1724271277601,"mc":[{"id":"1.232098082","rc":[{"batb":[[0,3.4,7.25],[1,3,23.53],[2,1.04,1.53]],"ltp":3.6,"tv":75.91,"id":11392436}]}]}
{"op":"mcm","clk":"11931014978","pt":1724271282011,"mc":[{"id":"1.232098082","rc":[{"batb":[[0,3.45,10],[1,3.4,7.25],[2,3,23.53]],"ltp":3.6,"tv":75.91,"id":11392436}]}]}
{"op":"mcm","clk":"11931015302","pt":1724271285512,"mc":[{"id":"1.232098082","rc":[{"batb":[[0,3.4,7.25],[1,3,23.53],[2,1.04,1.53]],"batl":[[0,7.2,3.55],[1,24,1.15],[2,30,0.76]],"ltp":3.6,"tv":75.91,"id":11392436}]}]}
{"op":"mcm","clk":"11931015927","pt":1724271292825,"mc":[{"id":"1.232098082","rc":[{"batb":[[0,3.45,10],[1,3.4,7.25],[2,3,23.53]],"ltp":3.6,"tv":75.91,"id":11392436}]}]}
{"op":"mcm","clk":"11931016261","pt":1724271296198,"mc":[{"id":"1.232098082","rc":[{"batb":[[0,3.4,7.25],[1,3,23.53],[2,1.04,1.53]],"ltp":3.6,"tv":75.91,"id":11392436}]}]}
{"op":"mcm","clk":"11931016676","pt":1724271300651,"mc":[{"id":"1.232098082","rc":[{"batb":[[0,3.45,10],[1,3.4,7.25],[2,3,23.53]],"ltp":3.6,"tv":75.91,"id":11392436}]}]}
{"op":"mcm","clk":"11931016968","pt":1724271304147,"mc":[{"id":"1.232098082","rc":[{"batb":[[0,3.4,7.25],[1,3,23.53],[2,1.04,1.53]],"ltp":3.6,"tv":75.91,"id":11392436}]}]}
{"op":"mcm","clk":"11931017686","pt":1724271311833,"mc":[{"id":"1.232098082","rc":[{"batb":[[0,3.45,10],[1,3.4,7.25],[2,3,23.53]],"ltp":3.6,"tv":75.91,"id":11392436}]}]}
{"op":"mcm","clk":"11931017977","pt":1724271315051,"mc":[{"id":"1.232098082","rc":[{"batb":[[0,3.4,7.25],[1,3,23.53],[2,1.04,1.53]],"ltp":3.6,"tv":75.91,"id":11392436}]}]}
{"op":"mcm","clk":"11931018835","pt":1724271324962,"mc":[{"id":"1.232098082","rc":[{"batb":[[0,3.45,10],[1,3.4,7.25],[2,3,23.53]],"ltp":3.6,"tv":75.91,"id":11392436}]}]}
{"op":"mcm","clk":"11931019140","pt":1724271328368,"mc":[{"id":"1.232098082","rc":[{"batb":[[0,3.4,7.25],[1,3,23.53],[2,1.04,1.53]],"ltp":3.6,"tv":75.91,"id":11392436}]}]}
{"op":"mcm","clk":"11931026423","pt":1724271407955,"mc":[{"id":"1.232098082","rc":[{"batb":[[0,3.45,10],[1,3.4,7.25],[2,3,23.53]],"ltp":3.6,"tv":75.91,"id":11392436}]}]}
{"op":"mcm","clk":"11931026727","pt":1724271411248,"mc":[{"id":"1.232098082","rc":[{"batb":[[0,3.4,7.25],[1,3,23.53],[2,1.04,1.53]],"ltp":3.6,"tv":75.91,"id":11392436}]}]}
{"op":"mcm","clk":"11931031716","pt":1724271461012,"mc":[{"id":"1.232098082","rc":[{"batb":[[0,3.45,10],[1,3.4,7.25],[2,3,23.53]],"ltp":3.6,"tv":75.91,"id":11392436}]}]}
{"op":"mcm","clk":"11931032002","pt":1724271464280,"mc":[{"id":"1.232098082","rc":[{"batb":[[0,3.4,7.25],[1,3,23.53],[2,1.04,1.53]],"ltp":3.6,"tv":75.91,"id":11392436}]}]}
{"op":"mcm","clk":"11931032233","pt":1724271466811,"mc":[{"id":"1.232098082","rc":[{"batb":[[0,3.45,10],[1,3.4,7.25],[2,3,23.53]],"ltp":3.6,"tv":75.91,"id":11392436}]}]}
{"op":"mcm","clk":"11931032554","pt":1724271470087,"mc":[{"id":"1.232098082","rc":[{"batb":[[0,3.4,7.25],[1,3,23.53],[2,1.04,1.53]],"ltp":3.6,"tv":75.91,"id":11392436}]}]}
{"op":"mcm","clk":"11931033021","pt":1724271475020,"mc":[{"id":"1.232098082","rc":[{"batb":[[0,3.45,10],[1,3.4,7.25],[2,3,23.53]],"ltp":3.6,"tv":75.91,"id":11392436}]}]}
{"op":"mcm","clk":"11931033397","pt":1724271478431,"mc":[{"id":"1.232098082","rc":[{"batb":[[0,3.4,7.25],[1,3,23.53],[2,1.04,1.53]],"ltp":3.6,"tv":75.91,"id":11392436}]}]}
{"op":"mcm","clk":"11931033702","pt":1724271481592,"mc":[{"id":"1.232098082","rc":[{"batb":[[0,3.45,10],[1,3.4,7.25],[2,3,23.53]],"ltp":3.6,"tv":75.91,"id":11392436}]}]}
{"op":"mcm","clk":"11931034061","pt":1724271485118,"mc":[{"id":"1.232098082","rc":[{"batb":[[0,3.4,7.25],[1,3,23.53],[2,1.04,1.53]],"ltp":3.6,"tv":75.91,"id":11392436}]}]}
{"op":"mcm","clk":"11931034921","pt":1724271494045,"mc":[{"id":"1.232098082","rc":[{"batb":[[0,3.45,10],[1,3.4,7.25],[2,3,23.53]],"ltp":3.6,"tv":75.91,"id":11392436}]}]}
{"op":"mcm","clk":"11931035237","pt":1724271497317,"mc":[{"id":"1.232098082","rc":[{"batb":[[0,3.4,7.25],[1,3,23.53],[2,1.04,1.53]],"ltp":3.6,"tv":75.91,"id":11392436}]}]}
{"op":"mcm","clk":"11931035912","pt":1724271503032,"mc":[{"id":"1.232098082","rc":[{"batb":[[0,3.45,10],[1,3.4,7.25],[2,3,23.53]],"ltp":3.6,"tv":75.91,"id":11392436}]}]}
{"op":"mcm","clk":"11931036286","pt":1724271506540,"mc":[{"id":"1.232098082","rc":[{"batb":[[0,3.4,7.25],[1,3,23.53],[2,1.04,1.53]],"ltp":3.6,"tv":75.91,"id":11392436}]}]}
{"op":"mcm","clk":"11931036813","pt":1724271512963,"mc":[{"id":"1.232098082","rc":[{"batb":[[0,3.45,10],[1,3.4,7.25],[2,3,23.53]],"ltp":3.6,"tv":75.91,"id":11392436}]}]}
{"op":"mcm","clk":"11931037112","pt":1724271516363,"mc":[{"id":"1.232098082","rc":[{"batb":[[0,3.4,7.25],[1,3,23.53],[2,1.04,1.53]],"ltp":3.6,"tv":75.91,"id":11392436}]}]}
{"op":"mcm","clk":"11931037788","pt":1724271523571,"mc":[{"id":"1.232098082","rc":[{"batb":[[0,3.45,10],[1,3.4,7.25],[2,3,23.53]],"ltp":3.6,"tv":75.91,"id":11392436}]}]}
{"op":"mcm","clk":"11931038126","pt":1724271526845,"mc":[{"id":"1.232098082","rc":[{"batb":[[0,3.4,7.25],[1,3,23.53],[2,1.04,1.53]],"ltp":3.6,"tv":75.91,"id":11392436}]}]}
{"op":"mcm","clk":"11931039728","pt":1724271544199,"mc":[{"id":"1.232098082","rc":[{"batb":[[0,3.45,10],[1,3.4,7.25],[2,3,23.53]],"ltp":3.6,"tv":75.91,"id":11392436}]}]}
{"op":"mcm","clk":"11931040083","pt":1724271547572,"mc":[{"id":"1.232098082","rc":[{"batb":[[0,3.4,7.25],[1,3,23.53],[2,1.04,1.53]],"ltp":3.6,"tv":75.91,"id":11392436}]}]}
{"op":"mcm","clk":"11931040719","pt":1724271553886,"mc":[{"id":"1.232098082","rc":[{"batb":[[0,3.45,10],[1,3.4,7.25],[2,3,23.53]],"ltp":3.6,"tv":75.91,"id":11392436}]}]}
{"op":"mcm","clk":"11931041041","pt":1724271557322,"mc":[{"id":"1.232098082","rc":[{"batb":[[0,3.4,7.25],[1,3,23.53],[2,1.04,1.53]],"ltp":3.6,"tv":75.91,"id":11392436}]}]}
{"op":"mcm","clk":"11931041726","pt":1724271564497,"mc":[{"id":"1.232098082","rc":[{"batb":[[0,3.45,10],[1,3.4,7.25],[2,3,23.53]],"ltp":3.6,"tv":75.91,"id":11392436}]}]}
{"op":"mcm","clk":"11931042106","pt":1724271567914,"mc":[{"id":"1.232098082","rc":[{"batb":[[0,3.4,7.25],[1,3,23.53],[2,1.04,1.53]],"ltp":3.6,"tv":75.91,"id":11392436}]}]}
{"op":"mcm","clk":"11931042657","pt":1724271573516,"mc":[{"id":"1.232098082","rc":[{"batb":[[0,3.45,10],[1,3.4,7.25],[2,3,23.53]],"ltp":3.6,"tv":75.91,"id":11392436}]}]}
{"op":"mcm","clk":"11931043009","pt":1724271576934,"mc":[{"id":"1.232098082","rc":[{"batb":[[0,3.4,7.25],[1,3,23.53],[2,1.04,1.53]],"ltp":3.6,"tv":75.91,"id":11392436}]}]}
{"op":"mcm","clk":"11931044617","pt":1724271593431,"mc":[{"id":"1.232098082","rc":[{"batb":[[0,3.45,10],[1,3.4,7.25],[2,3,23.53]],"ltp":3.6,"tv":75.91,"id":11392436}]}]}
{"op":"mcm","clk":"11931044967","pt":1724271596950,"mc":[{"id":"1.232098082","rc":[{"batb":[[0,3.4,7.25],[1,3,23.53],[2,1.04,1.53]],"ltp":3.6,"tv":75.91,"id":11392436}]}]}
{"op":"mcm","clk":"11931045262","pt":1724271599859,"mc":[{"id":"1.232098082","rc":[{"batb":[[0,3.4,14.57]],"ltp":3.6,"tv":75.91,"id":11392436}]}]}
{"op":"mcm","clk":"11931045273","pt":1724271599954,"mc":[{"id":"1.232098082","rc":[{"batb":[[0,3.45,10],[1,3.4,14.57],[2,3,23.53]],"ltp":3.6,"tv":75.91,"id":11392436}]}]}
{"op":"mcm","clk":"11931045612","pt":1724271603269,"mc":[{"id":"1.232098082","rc":[{"batb":[[0,3.4,14.57],[1,3,23.53],[2,1.04,1.53]],"ltp":3.6,"tv":75.91,"id":11392436},{"batb":[[0,1.16,1.84],[1,1.14,21.38],[2,1.04,1.53]],"ltp":1.39,"tv":583.4,"id":48610314}]}]}
{"op":"mcm","clk":"11931046276","pt":1724271609854,"mc":[{"id":"1.232098082","rc":[{"batb":[[0,3.45,10],[1,3.4,14.57],[2,3,23.53]],"ltp":3.6,"tv":75.91,"id":11392436}]}]}
{"op":"mcm","clk":"11931046588","pt":1724271613279,"mc":[{"id":"1.232098082","rc":[{"batb":[[0,3.4,14.57],[1,3,23.53],[2,1.04,1.53]],"ltp":3.6,"tv":75.91,"id":11392436}]}]}
{"op":"mcm","clk":"11931047256","pt":1724271621154,"mc":[{"id":"1.232098082","rc":[{"batb":[[0,3.45,10],[1,3.4,14.57],[2,3,23.53]],"ltp":3.6,"tv":75.91,"id":11392436}]}]}
{"op":"mcm","clk":"11931047572","pt":1724271624466,"mc":[{"id":"1.232098082","rc":[{"batb":[[0,3.4,14.57],[1,3,23.53],[2,1.04,1.53]],"ltp":3.6,"tv":75.91,"id":11392436}]}]}
{"op":"mcm","clk":"11931047796","pt":1724271626894,"mc":[{"id":"1.232098082","rc":[{"batb":[[0,3.45,10],[1,3.4,14.57],[2,3,23.53]],"ltp":3.6,"tv":75.91,"id":11392436}]}]}
{"op":"mcm","clk":"11931048120","pt":1724271630271,"mc":[{"id":"1.232098082","rc":[{"batb":[[0,3.4,14.57],[1,3,23.53],[2,1.04,1.53]],"ltp":3.6,"tv":75.91,"id":11392436}]}]}
{"op":"mcm","clk":"11931048639","pt":1724271635705,"mc":[{"id":"1.232098082","rc":[{"batb":[[0,3.45,10],[1,3.4,14.57],[2,3,23.53]],"ltp":3.6,"tv":75.91,"id":11392436}]}]}
{"op":"mcm","clk":"11931048946","pt":1724271639012,"mc":[{"id":"1.232098082","rc":[{"batb":[[0,3.4,14.57],[1,3,23.53],[2,1.04,1.53]],"ltp":3.6,"tv":75.91,"id":11392436}]}]}
{"op":"mcm","clk":"11931049183","pt":1724271641713,"mc":[{"id":"1.232098082","rc":[{"batb":[[0,3.45,10],[1,3.4,14.57],[2,3,23.53]],"ltp":3.6,"tv":75.91,"id":11392436}]}]}
{"op":"mcm","clk":"11931049479","pt":1724271645081,"mc":[{"id":"1.232098082","rc":[{"batb":[[0,3.4,14.57],[1,3,23.53],[2,1.04,1.53]],"ltp":3.6,"tv":75.91,"id":11392436}]}]}
{"op":"mcm","clk":"11931049715","pt":1724271647919,"mc":[{"id":"1.232098082","rc":[{"batb":[[0,3.45,10],[1,3.4,14.57],[2,3,23.53]],"ltp":3.6,"tv":75.91,"id":11392436}]}]}
{"op":"mcm","clk":"11931050036","pt":1724271651300,"mc":[{"id":"1.232098082","rc":[{"batb":[[0,3.4,14.57],[1,3,23.53],[2,1.04,1.53]],"ltp":3.6,"tv":75.91,"id":11392436}]}]}
{"op":"mcm","clk":"11931050431","pt":1724271655406,"mc":[{"id":"1.232098082","rc":[{"batb":[[0,3.45,10],[1,3.4,14.57],[2,3,23.53]],"ltp":3.6,"tv":75.91,"id":11392436}]}]}
{"op":"mcm","clk":"11931050720","pt":1724271658825,"mc":[{"id":"1.232098082","rc":[{"batb":[[0,3.4,14.57],[1,3,23.53],[2,1.04,1.53]],"ltp":3.6,"tv":75.91,"id":11392436}]}]}
{"op":"mcm","clk":"11931051040","pt":1724271662404,"mc":[{"id":"1.232098082","rc":[{"batb":[[0,3.45,10],[1,3.4,14.57],[2,3,23.53]],"ltp":3.6,"tv":75.91,"id":11392436}]}]}
{"op":"mcm","clk":"11931051348","pt":1724271665715,"mc":[{"id":"1.232098082","rc":[{"batb":[[0,3.4,14.57],[1,3,23.53],[2,1.04,1.53]],"ltp":3.6,"tv":75.91,"id":11392436}]}]}
{"op":"mcm","clk":"11931051770","pt":1724271671349,"mc":[{"id":"1.232098082","rc":[{"batb":[[0,3.45,10],[1,3.4,14.57],[2,3,23.53]],"ltp":3.6,"tv":75.91,"id":11392436}]}]}
{"op":"mcm","clk":"11931052017","pt":1724271674657,"mc":[{"id":"1.232098082","rc":[{"batb":[[0,3.4,14.57],[1,3,23.53],[2,1.04,1.53]],"ltp":3.6,"tv":75.91,"id":11392436}]}]}
{"op":"mcm","clk":"11931052538","pt":1724271680862,"mc":[{"id":"1.232098082","rc":[{"batb":[[0,3.45,10],[1,3.4,14.57],[2,3,23.53]],"ltp":3.6,"tv":75.91,"id":11392436}]}]}
{"op":"mcm","clk":"11931052823","pt":1724271684274,"mc":[{"id":"1.232098082","rc":[{"batb":[[0,3.4,14.57],[1,3,23.53],[2,1.04,1.53]],"ltp":3.6,"tv":75.91,"id":11392436}]}]}
{"op":"mcm","clk":"11931053039","pt":1724271686764,"mc":[{"id":"1.232098082","rc":[{"batb":[[0,3.45,10],[1,3.4,14.57],[2,3,23.53]],"ltp":3.6,"tv":75.91,"id":11392436}]}]}
{"op":"mcm","clk":"11931053341","pt":1724271690183,"mc":[{"id":"1.232098082","rc":[{"batb":[[0,3.4,14.57],[1,3,23.53],[2,1.04,1.53]],"ltp":3.6,"tv":75.91,"id":11392436}]}]}
{"op":"mcm","clk":"11931053615","pt":1724271693760,"mc":[{"id":"1.232098082","rc":[{"batb":[[0,3.45,10],[1,3.4,14.57],[2,3,23.53]],"ltp":3.6,"tv":75.91,"id":11392436}]}]}
{"op":"mcm","clk":"11931053888","pt":1724271697066,"mc":[{"id":"1.232098082","rc":[{"batb":[[0,3.4,14.57],[1,3,23.53],[2,1.04,1.53]],"ltp":3.6,"tv":75.91,"id":11392436}]}]}
{"op":"mcm","clk":"11931054589","pt":1724271705284,"mc":[{"id":"1.232098082","rc":[{"batb":[[0,3.45,10],[1,3.4,14.57],[2,3,23.53]],"ltp":3.6,"tv":75.91,"id":11392436}]}]}
{"op":"mcm","clk":"11931054866","pt":1724271708600,"mc":[{"id":"1.232098082","rc":[{"batb":[[0,3.4,14.57],[1,3,23.53],[2,1.04,1.53]],"ltp":3.6,"tv":75.91,"id":11392436}]}]}
{"op":"mcm","clk":"11931055498","pt":1724271714712,"mc":[{"id":"1.232098082","rc":[{"batb":[[0,3.45,10],[1,3.4,14.57],[2,3,23.53]],"ltp":3.6,"tv":75.91,"id":11392436}]}]}
{"op":"mcm","clk":"11931055794","pt":1724271718019,"mc":[{"id":"1.232098082","rc":[{"batb":[[0,3.4,14.57],[1,3,23.53],[2,1.04,1.53]],"ltp":3.6,"tv":75.91,"id":11392436}]}]}
{"op":"mcm","clk":"11931056006","pt":1724271720613,"mc":[{"id":"1.232098082","rc":[{"batb":[[0,3.45,10],[1,3.4,14.57],[2,3,23.53]],"ltp":3.6,"tv":75.91,"id":11392436}]}]}
{"op":"mcm","clk":"11931056292","pt":1724271724129,"mc":[{"id":"1.232098082","rc":[{"batb":[[0,3.4,14.57],[1,3,23.53],[2,1.04,1.53]],"ltp":3.6,"tv":75.91,"id":11392436}]}]}
{"op":"mcm","clk":"11931056760","pt":1724271728637,"mc":[{"id":"1.232098082","rc":[{"batb":[[0,3.45,10],[1,3.4,14.57],[2,3,23.53]],"ltp":3.6,"tv":75.91,"id":11392436}]}]}
{"op":"mcm","clk":"11931057089","pt":1724271731840,"mc":[{"id":"1.232098082","rc":[{"batb":[[0,3.4,14.57],[1,3,23.53],[2,1.04,1.53]],"ltp":3.6,"tv":75.91,"id":11392436}]}]}
{"op":"mcm","clk":"11931057520","pt":1724271736358,"mc":[{"id":"1.232098082","rc":[{"batb":[[0,3.45,10],[1,3.4,14.57],[2,3,23.53]],"ltp":3.6,"tv":75.91,"id":11392436}]}]}
{"op":"mcm","clk":"11931057876","pt":1724271739733,"mc":[{"id":"1.232098082","rc":[{"batb":[[0,3.4,14.57],[1,3,23.53],[2,1.04,1.53]],"ltp":3.6,"tv":75.91,"id":11392436}]}]}
{"op":"mcm","clk":"11931058285","pt":1724271743831,"mc":[{"id":"1.232098082","rc":[{"batb":[[0,3.45,10],[1,3.4,14.57],[2,3,23.53]],"ltp":3.6,"tv":75.91,"id":11392436}]}]}
{"op":"mcm","clk":"11931058580","pt":1724271747138,"mc":[{"id":"1.232098082","rc":[{"batb":[[0,3.4,14.57],[1,3,23.53],[2,1.04,1.53]],"ltp":3.6,"tv":75.91,"id":11392436}]}]}
{"op":"mcm","clk":"11931058892","pt":1724271750559,"mc":[{"id":"1.232098082","rc":[{"batb":[[0,3.45,10],[1,3.4,14.57],[2,3,23.53]],"ltp":3.6,"tv":75.91,"id":11392436}]}]}
{"op":"mcm","clk":"11931059231","pt":1724271753845,"mc":[{"id":"1.232098082","rc":[{"batl":[[2,24,1.15]],"ltp":1.39,"tv":583.4,"id":48610314}]}]}
{"op":"mcm","clk":"11931059264","pt":1724271754253,"mc":[{"id":"1.232098082","rc":[{"batb":[[0,3.4,14.57],[1,3,23.53],[2,1.04,1.53]],"ltp":3.6,"tv":75.91,"id":11392436},{"batl":[[0,1.4,15],[1,1.41,17.04],[2,1.42,418.84]],"ltp":1.39,"tv":583.4,"id":48610314}]}]}
{"op":"mcm","clk":"11931059499","pt":1724271756484,"mc":[{"id":"1.232098082","rc":[{"batb":[[0,3.45,10],[1,3.4,14.57],[2,3,23.53]],"ltp":3.6,"tv":75.91,"id":11392436},{"batl":[[1,1.42,418.84],[2,24,1.15]],"ltp":1.39,"tv":583.4,"id":48610314}]}]}
{"op":"mcm","clk":"11931059847","pt":1724271759954,"mc":[{"id":"1.232098082","rc":[{"batb":[[0,3.4,14.57],[1,3,23.53],[2,1.04,1.53]],"ltp":3.6,"tv":75.91,"id":11392436}]}]}
{"op":"mcm","clk":"11931060571","pt":1724271767679,"mc":[{"id":"1.232098082","rc":[{"batb":[[0,3.45,10],[1,3.4,14.57],[2,3,23.53]],"ltp":3.6,"tv":75.91,"id":11392436}]}]}
{"op":"mcm","clk":"11931060884","pt":1724271771079,"mc":[{"id":"1.232098082","rc":[{"batb":[[0,3.4,14.57],[1,3,23.53],[2,1.04,1.53]],"ltp":3.6,"tv":75.91,"id":11392436}]}]}
{"op":"mcm","clk":"11931061083","pt":1724271773407,"mc":[{"id":"1.232098082","rc":[{"batb":[[0,3.45,10],[1,3.4,14.57],[2,3,23.53]],"ltp":3.6,"tv":75.91,"id":11392436}]}]}
{"op":"mcm","clk":"11931061344","pt":1724271776883,"mc":[{"id":"1.232098082","rc":[{"batb":[[0,3.4,14.57],[1,3,23.53],[2,1.04,1.53]],"ltp":3.6,"tv":75.91,"id":11392436}]}]}
{"op":"mcm","clk":"11931061548","pt":1724271779419,"mc":[{"id":"1.232098082","rc":[{"batb":[[0,3.45,10],[1,3.4,14.57],[2,3,23.53]],"ltp":3.6,"tv":75.91,"id":11392436}]}]}
{"op":"mcm","clk":"11931061862","pt":1724271782809,"mc":[{"id":"1.232098082","rc":[{"batb":[[0,3.4,14.57],[1,3,23.53],[2,1.04,1.53]],"ltp":3.6,"tv":75.91,"id":11392436}]}]}
{"op":"mcm","clk":"11931062101","pt":1724271785613,"mc":[{"id":"1.232098082","rc":[{"batb":[[0,3.45,10],[1,3.4,14.57],[2,3,23.53]],"ltp":3.6,"tv":75.91,"id":11392436}]}]}
{"op":"mcm","clk":"11931062385","pt":1724271788940,"mc":[{"id":"1.232098082","rc":[{"batb":[[0,3.4,14.57],[1,3,23.53],[2,1.04,1.53]],"ltp":3.6,"tv":75.91,"id":11392436}]}]}
{"op":"mcm","clk":"11931062615","pt":1724271791225,"mc":[{"id":"1.232098082","rc":[{"batb":[[0,3.45,10],[1,3.4,14.57],[2,3,23.53]],"ltp":3.6,"tv":75.91,"id":11392436}]}]}
{"op":"mcm","clk":"11931062929","pt":1724271794645,"mc":[{"id":"1.232098082","rc":[{"batb":[[0,3.4,14.57],[1,3,23.53],[2,1.04,1.53]],"ltp":3.6,"tv":75.91,"id":11392436}]}]}
{"op":"mcm","clk":"11931063266","pt":1724271798031,"mc":[{"id":"1.232098082","rc":[{"batb":[[0,3.45,10],[1,3.4,14.57],[2,3,23.53]],"ltp":3.6,"tv":75.91,"id":11392436}]}]}
{"op":"mcm","clk":"11931063625","pt":1724271801455,"mc":[{"id":"1.232098082","rc":[{"batb":[[0,3.4,14.57],[1,3,23.53],[2,1.04,1.53]],"ltp":3.6,"tv":75.91,"id":11392436}]}]}
{"op":"mcm","clk":"11931063875","pt":1724271803753,"mc":[{"id":"1.232098082","rc":[{"batb":[[0,3.45,10],[1,3.4,14.57],[2,3,23.53]],"ltp":3.6,"tv":75.91,"id":11392436}]}]}
{"op":"mcm","clk":"11931064216","pt":1724271807161,"mc":[{"id":"1.232098082","rc":[{"batb":[[0,3.4,14.57],[1,3,23.53],[2,1.04,1.53]],"ltp":3.6,"tv":75.91,"id":11392436}]}]}
{"op":"mcm","clk":"11931064627","pt":1724271810867,"mc":[{"id":"1.232098082","rc":[{"batb":[[0,3.45,10],[1,3.4,14.57],[2,3,23.53]],"ltp":3.6,"tv":75.91,"id":11392436}]}]}
{"op":"mcm","clk":"11931064981","pt":1724271814330,"mc":[{"id":"1.232098082","rc":[{"batb":[[0,3.4,14.57],[1,3,23.53],[2,1.04,1.53]],"ltp":3.6,"tv":75.91,"id":11392436}]}]}
{"op":"mcm","clk":"11931065273","pt":1724271817135,"mc":[{"id":"1.232098082","rc":[{"batb":[[0,3.45,10],[1,3.4,14.57],[2,3,23.53]],"ltp":3.6,"tv":75.91,"id":11392436}]}]}
{"op":"mcm","clk":"11931065623","pt":1724271820557,"mc":[{"id":"1.232098082","rc":[{"batb":[[0,3.4,14.57],[1,3,23.53],[2,1.04,1.53]],"ltp":3.6,"tv":75.91,"id":11392436}]}]}
{"op":"mcm","clk":"11931066320","pt":1724271827258,"mc":[{"id":"1.232098082","rc":[{"batb":[[0,3.45,10],[1,3.4,14.57],[2,3,23.53]],"ltp":3.6,"tv":75.91,"id":11392436}]}]}
{"op":"mcm","clk":"11931066678","pt":1724271830679,"mc":[{"id":"1.232098082","rc":[{"batb":[[0,3.4,14.57],[1,3,23.53],[2,1.04,1.53]],"ltp":3.6,"tv":75.91,"id":11392436}]}]}
{"op":"mcm","clk":"11931066945","pt":1724271833271,"mc":[{"id":"1.232098082","rc":[{"batb":[[0,3.45,10],[1,3.4,14.57],[2,3,23.53]],"ltp":3.6,"tv":75.91,"id":11392436}]}]}
{"op":"mcm","clk":"11931067245","pt":1724271836553,"mc":[{"id":"1.232098082","rc":[{"batb":[[0,3.4,14.57],[1,3,23.53],[2,1.04,1.53]],"ltp":3.6,"tv":75.91,"id":11392436}]}]}
{"op":"mcm","clk":"11931067479","pt":1724271839291,"mc":[{"id":"1.232098082","rc":[{"batb":[[0,3.45,10],[1,3.4,14.57],[2,3,23.53]],"ltp":3.6,"tv":75.91,"id":11392436}]}]}
{"op":"mcm","clk":"11931067776","pt":1724271842572,"mc":[{"id":"1.232098082","rc":[{"batb":[[0,3.4,14.57],[1,3,23.53],[2,1.04,1.53]],"ltp":3.6,"tv":75.91,"id":11392436}]}]}
{"op":"mcm","clk":"11931068502","pt":1724271851279,"mc":[{"id":"1.232098082","rc":[{"batb":[[0,3.45,10],[1,3.4,14.57],[2,3,23.53]],"ltp":3.6,"tv":75.91,"id":11392436}]}]}
{"op":"mcm","clk":"11931068821","pt":1724271854588,"mc":[{"id":"1.232098082","rc":[{"batb":[[0,3.4,14.57],[1,3,23.53],[2,1.04,1.53]],"ltp":3.6,"tv":75.91,"id":11392436}]}]}
{"op":"mcm","clk":"11931071839","pt":1724271884897,"mc":[{"id":"1.232098082","rc":[{"batb":[[0,3.45,10],[1,3.4,14.57],[2,3,23.53]],"ltp":3.6,"tv":75.91,"id":11392436}]}]}
{"op":"mcm","clk":"11931072191","pt":1724271888418,"mc":[{"id":"1.232098082","rc":[{"batb":[[0,3.4,14.57],[1,3,23.53],[2,1.04,1.53]],"ltp":3.6,"tv":75.91,"id":11392436}]}]}
{"op":"mcm","clk":"11931072573","pt":1724271891906,"mc":[{"id":"1.232098082","rc":[{"batb":[[0,3.45,10],[1,3.4,14.57],[2,3,23.53]],"ltp":3.6,"tv":75.91,"id":11392436}]}]}
{"op":"mcm","clk":"11931072908","pt":1724271895222,"mc":[{"id":"1.232098082","rc":[{"batb":[[0,3.4,14.57],[1,3,23.53],[2,1.04,1.53]],"ltp":3.6,"tv":75.91,"id":11392436}]}]}
{"op":"mcm","clk":"11931073102","pt":1724271897750,"mc":[{"id":"1.232098082","rc":[{"batb":[[0,3.45,10],[1,3.4,14.57],[2,3,23.53]],"ltp":3.6,"tv":75.91,"id":11392436}]}]}
{"op":"mcm","clk":"11931073394","pt":1724271901022,"mc":[{"id":"1.232098082","rc":[{"batb":[[0,3.4,14.57],[1,3,23.53],[2,1.04,1.53]],"ltp":3.6,"tv":75.91,"id":11392436}]}]}
{"op":"mcm","clk":"11931073970","pt":1724271907035,"mc":[{"id":"1.232098082","rc":[{"batb":[[0,3.45,10],[1,3.4,14.57],[2,3,23.53]],"ltp":3.6,"tv":75.91,"id":11392436}]}]}
{"op":"mcm","clk":"11931074290","pt":1724271910552,"mc":[{"id":"1.232098082","rc":[{"batb":[[0,3.4,14.57],[1,3,23.53],[2,1.04,1.53]],"ltp":3.6,"tv":75.91,"id":11392436}]}]}
{"op":"mcm","clk":"11931075000","pt":1724271918359,"mc":[{"id":"1.232098082","rc":[{"batb":[[0,3.45,10],[1,3.4,14.57],[2,3,23.53]],"ltp":3.6,"tv":75.91,"id":11392436}]}]}
{"op":"mcm","clk":"11931075324","pt":1724271921843,"mc":[{"id":"1.232098082","rc":[{"batb":[[0,3.4,14.57],[1,3,23.53],[2,1.04,1.53]],"ltp":3.6,"tv":75.91,"id":11392436}]}]}
{"op":"mcm","clk":"11931075546","pt":1724271924258,"mc":[{"id":"1.232098082","rc":[{"batb":[[0,3.45,10],[1,3.4,14.57],[2,3,23.53]],"ltp":3.6,"tv":75.91,"id":11392436}]}]}
{"op":"mcm","clk":"11931075867","pt":1724271927572,"mc":[{"id":"1.232098082","rc":[{"batb":[[0,3.4,14.57],[1,3,23.53],[2,1.04,1.53]],"ltp":3.6,"tv":75.91,"id":11392436}]}]}
{"op":"mcm","clk":"11931076509","pt":1724271933470,"mc":[{"id":"1.232098082","rc":[{"batb":[[0,3.45,10],[1,3.4,14.57],[2,3,23.53]],"ltp":3.6,"tv":75.91,"id":11392436}]}]}
{"op":"mcm","clk":"11931076898","pt":1724271936960,"mc":[{"id":"1.232098082","rc":[{"batb":[[0,3.4,14.57],[1,3,23.53],[2,1.04,1.53]],"ltp":3.6,"tv":75.91,"id":11392436}]}]}
{"op":"mcm","clk":"11931077229","pt":1724271940174,"mc":[{"id":"1.232098082","rc":[{"batb":[[0,3.45,10],[1,3.4,14.57],[2,3,23.53]],"ltp":3.6,"tv":75.91,"id":11392436}]}]}
{"op":"mcm","clk":"11931077551","pt":1724271943496,"mc":[{"id":"1.232098082","rc":[{"batb":[[0,3.4,14.57],[1,3,23.53],[2,1.04,1.53]],"ltp":3.6,"tv":75.91,"id":11392436}]}]}
{"op":"mcm","clk":"11931077766","pt":1724271945778,"mc":[{"id":"1.232098082","rc":[{"batb":[[0,3.45,10],[1,3.4,14.57],[2,3,23.53]],"ltp":3.6,"tv":75.91,"id":11392436}]}]}
{"op":"mcm","clk":"11931078069","pt":1724271949294,"mc":[{"id":"1.232098082","rc":[{"batb":[[0,3.4,14.57],[1,3,23.53],[2,1.04,1.53]],"ltp":3.6,"tv":75.91,"id":11392436}]}]}
{"op":"mcm","clk":"11931078314","pt":1724271951475,"mc":[{"id":"1.232098082","rc":[{"batb":[[0,3.45,10],[1,3.4,14.57],[2,3,23.53]],"ltp":3.6,"tv":75.91,"id":11392436}]}]}
{"op":"mcm","clk":"11931078624","pt":1724271955093,"mc":[{"id":"1.232098082","rc":[{"batb":[[0,3.4,14.57],[1,3,23.53],[2,1.04,1.53]],"ltp":3.6,"tv":75.91,"id":11392436}]}]}
{"op":"mcm","clk":"11931078930","pt":1724271958204,"mc":[{"id":"1.232098082","rc":[{"batb":[[0,3.45,10],[1,3.4,14.57],[2,3,23.53]],"ltp":3.6,"tv":75.91,"id":11392436}]}]}
{"op":"mcm","clk":"11931079234","pt":1724271961491,"mc":[{"id":"1.232098082","rc":[{"batb":[[0,3.4,14.57],[1,3,23.53],[2,1.04,1.53]],"ltp":3.6,"tv":75.91,"id":11392436}]}]}
{"op":"mcm","clk":"11931079471","pt":1724271963995,"mc":[{"id":"1.232098082","rc":[{"batb":[[0,3.45,10],[1,3.4,14.57],[2,3,23.53]],"ltp":3.6,"tv":75.91,"id":11392436}]}]}
{"op":"mcm","clk":"11931079813","pt":1724271967204,"mc":[{"id":"1.232098082","rc":[{"batb":[[0,3.4,14.57],[1,3,23.53],[2,1.04,1.53]],"ltp":3.6,"tv":75.91,"id":11392436}]}]}
{"op":"mcm","clk":"11931080403","pt":1724271973010,"mc":[{"id":"1.232098082","rc":[{"batb":[[0,3.45,10],[1,3.4,14.57],[2,3,23.53]],"ltp":3.6,"tv":75.91,"id":11392436}]}]}
{"op":"mcm","clk":"11931080773","pt":1724271976505,"mc":[{"id":"1.232098082","rc":[{"batb":[[0,3.4,14.57],[1,3,23.53],[2,1.04,1.53]],"ltp":3.6,"tv":75.91,"id":11392436}]}]}
{"op":"mcm","clk":"11931081329","pt":1724271982218,"mc":[{"id":"1.232098082","rc":[{"batb":[[0,3.45,10],[1,3.4,14.57],[2,3,23.53]],"ltp":3.6,"tv":75.91,"id":11392436}]}]}
{"op":"mcm","clk":"11931081615","pt":1724271985609,"mc":[{"id":"1.232098082","rc":[{"batb":[[0,3.4,14.57],[1,3,23.53],[2,1.04,1.53]],"ltp":3.6,"tv":75.91,"id":11392436}]}]}
{"op":"mcm","clk":"11931082019","pt":1724271990304,"mc":[{"id":"1.232098082","rc":[{"batb":[[0,3.45,10],[1,3.4,14.57],[2,3,23.53]],"ltp":3.6,"tv":75.91,"id":11392436}]}]}
{"op":"mcm","clk":"11931082300","pt":1724271993717,"mc":[{"id":"1.232098082","rc":[{"batb":[[0,3.4,14.57],[1,3,23.53],[2,1.04,1.53]],"ltp":3.6,"tv":75.91,"id":11392436}]}]}
{"op":"mcm","clk":"11931082592","pt":1724271997950,"mc":[{"id":"1.232098082","rc":[{"batb":[[0,3.45,10],[1,3.4,14.57],[2,3,23.53]],"ltp":3.6,"tv":75.91,"id":11392436}]}]}
{"op":"mcm","clk":"11931082850","pt":1724272001313,"mc":[{"id":"1.232098082","rc":[{"batb":[[0,3.4,14.57],[1,3,23.53],[2,1.04,1.53]],"ltp":3.6,"tv":75.91,"id":11392436}]}]}
{"op":"mcm","clk":"11931083059","pt":1724272004448,"mc":[{"id":"1.232098082","rc":[{"batb":[[0,3.45,10],[1,3.4,14.57],[2,3,23.53]],"ltp":3.6,"tv":75.91,"id":11392436}]}]}
{"op":"mcm","clk":"11931083315","pt":1724272007754,"mc":[{"id":"1.232098082","rc":[{"batb":[[0,3.4,14.57],[1,3,23.53],[2,1.04,1.53]],"ltp":3.6,"tv":75.91,"id":11392436}]}]}
{"op":"mcm","clk":"11931083641","pt":1724272011634,"mc":[{"id":"1.232098082","rc":[{"batb":[[0,3.45,10],[1,3.4,14.57],[2,3,23.53]],"ltp":3.6,"tv":75.91,"id":11392436}]}]}
{"op":"mcm","clk":"11931083927","pt":1724272015049,"mc":[{"id":"1.232098082","rc":[{"batb":[[0,3.4,14.57],[1,3,23.53],[2,1.04,1.53]],"ltp":3.6,"tv":75.91,"id":11392436}]}]}
{"op":"mcm","clk":"11931084544","pt":1724272022470,"mc":[{"id":"1.232098082","rc":[{"batb":[[0,3.45,10],[1,3.4,14.57],[2,3,23.53]],"ltp":3.6,"tv":75.91,"id":11392436}]}]}
{"op":"mcm","clk":"11931084814","pt":1724272025843,"mc":[{"id":"1.232098082","rc":[{"batb":[[0,3.4,14.57],[1,3,23.53],[2,1.04,1.53]],"ltp":3.6,"tv":75.91,"id":11392436}]}]}
{"op":"mcm","clk":"11931085018","pt":1724272028078,"mc":[{"id":"1.232098082","rc":[{"batb":[[0,3.45,10],[1,3.4,14.57],[2,3,23.53]],"ltp":3.6,"tv":75.91,"id":11392436}]}]}
{"op":"mcm","clk":"11931085261","pt":1724272031381,"mc":[{"id":"1.232098082","rc":[{"batb":[[0,3.4,14.57],[1,3,23.53],[2,1.04,1.53]],"ltp":3.6,"tv":75.91,"id":11392436}]}]}
{"op":"mcm","clk":"11931085583","pt":1724272034893,"mc":[{"id":"1.232098082","rc":[{"batb":[[0,3.45,10],[1,3.4,14.57],[2,3,23.53]],"ltp":3.6,"tv":75.91,"id":11392436}]}]}
{"op":"mcm","clk":"11931085894","pt":1724272038404,"mc":[{"id":"1.232098082","rc":[{"batb":[[0,3.4,14.57],[1,3,23.53],[2,1.04,1.53]],"ltp":3.6,"tv":75.91,"id":11392436}]}]}
{"op":"mcm","clk":"11931086317","pt":1724272042908,"mc":[{"id":"1.232098082","rc":[{"batb":[[0,3.45,10],[1,3.4,14.57],[2,3,23.53]],"ltp":3.6,"tv":75.91,"id":11392436}]}]}
{"op":"mcm","clk":"11931086654","pt":1724272046289,"mc":[{"id":"1.232098082","rc":[{"batb":[[0,3.4,14.57],[1,3,23.53],[2,1.04,1.53]],"ltp":3.6,"tv":75.91,"id":11392436}]}]}
{"op":"mcm","clk":"11931086919","pt":1724272048518,"mc":[{"id":"1.232098082","rc":[{"batb":[[0,3.45,10],[1,3.4,14.57],[2,3,23.53]],"ltp":3.6,"tv":75.91,"id":11392436}]}]}
{"op":"mcm","clk":"11931087217","pt":1724272051905,"mc":[{"id":"1.232098082","rc":[{"batb":[[0,3.4,14.57],[1,3,23.53],[2,1.04,1.53]],"ltp":3.6,"tv":75.91,"id":11392436}]}]}
{"op":"mcm","clk":"11931087963","pt":1724272060516,"mc":[{"id":"1.232098082","rc":[{"batb":[[0,3.45,10],[1,3.4,14.57],[2,3,23.53]],"ltp":3.6,"tv":75.91,"id":11392436}]}]}
{"op":"mcm","clk":"11931088207","pt":1724272063841,"mc":[{"id":"1.232098082","rc":[{"batb":[[0,3.4,14.57],[1,3,23.53],[2,1.04,1.53]],"ltp":3.6,"tv":75.91,"id":11392436}]}]}
{"op":"mcm","clk":"11931088447","pt":1724272066959,"mc":[{"id":"1.232098082","rc":[{"batb":[[0,3.45,10],[1,3.4,14.57],[2,3,23.53]],"ltp":3.6,"tv":75.91,"id":11392436}]}]}
{"op":"mcm","clk":"11931088699","pt":1724272070234,"mc":[{"id":"1.232098082","rc":[{"batb":[[0,3.4,14.57],[1,3,23.53],[2,1.04,1.53]],"ltp":3.6,"tv":75.91,"id":11392436}]}]}
{"op":"mcm","clk":"11931088992","pt":1724272074178,"mc":[{"id":"1.232098082","rc":[{"batb":[[0,3.45,10],[1,3.4,14.57],[2,3,23.53]],"ltp":3.6,"tv":75.91,"id":11392436}]}]}
{"op":"mcm","clk":"11931089266","pt":1724272077449,"mc":[{"id":"1.232098082","rc":[{"batb":[[0,3.4,14.57],[1,3,23.53],[2,1.04,1.53]],"ltp":3.6,"tv":75.91,"id":11392436}]}]}
{"op":"mcm","clk":"11931089638","pt":1724272082755,"mc":[{"id":"1.232098082","rc":[{"batb":[[0,3.45,10],[1,3.4,14.57],[2,3,23.53]],"ltp":3.6,"tv":75.91,"id":11392436}]}]}
{"op":"mcm","clk":"11931090029","pt":1724272086108,"mc":[{"id":"1.232098082","rc":[{"batb":[[0,3.4,14.57],[1,3,23.53],[2,1.04,1.53]],"ltp":3.6,"tv":75.91,"id":11392436}]}]}
{"op":"mcm","clk":"11931090248","pt":1724272088487,"mc":[{"id":"1.232098082","rc":[{"batb":[[0,3.45,10],[1,3.4,14.57],[2,3,23.53]],"ltp":3.6,"tv":75.91,"id":11392436}]}]}
{"op":"mcm","clk":"11931090498","pt":1724272091802,"mc":[{"id":"1.232098082","rc":[{"batb":[[0,3.4,14.57],[1,3,23.53],[2,1.04,1.53]],"ltp":3.6,"tv":75.91,"id":11392436}]}]}
{"op":"mcm","clk":"11931091305","pt":1724272102087,"mc":[{"id":"1.232098082","rc":[{"batb":[[0,3.45,10],[1,3.4,14.57],[2,3,23.53]],"ltp":3.6,"tv":75.91,"id":11392436}]}]}
{"op":"mcm","clk":"11931091538","pt":1724272105492,"mc":[{"id":"1.232098082","rc":[{"batb":[[0,3.4,14.57],[1,3,23.53],[2,1.04,1.53]],"ltp":3.6,"tv":75.91,"id":11392436}]}]}
{"op":"mcm","clk":"11931091819","pt":1724272109617,"mc":[{"id":"1.232098082","rc":[{"batb":[[0,3.45,10],[1,3.4,14.57],[2,3,23.53]],"ltp":3.6,"tv":75.91,"id":11392436}]}]}
{"op":"mcm","clk":"11931092057","pt":1724272113025,"mc":[{"id":"1.232098082","rc":[{"batb":[[0,3.4,14.57],[1,3,23.53],[2,1.04,1.53]],"ltp":3.6,"tv":75.91,"id":11392436}]}]}
{"op":"mcm","clk":"11931092247","pt":1724272115506,"mc":[{"id":"1.232098082","rc":[{"batb":[[0,3.45,10],[1,3.4,14.57],[2,3,23.53]],"ltp":3.6,"tv":75.91,"id":11392436}]}]}
{"op":"mcm","clk":"11931092521","pt":1724272118818,"mc":[{"id":"1.232098082","rc":[{"batb":[[0,3.4,14.57],[1,3,23.53],[2,1.04,1.53]],"ltp":3.6,"tv":75.91,"id":11392436}]}]}
{"op":"mcm","clk":"11931092817","pt":1724272122653,"mc":[{"id":"1.232098082","rc":[{"batb":[[0,3.45,10],[1,3.4,14.57],[2,3,23.53]],"ltp":3.6,"tv":75.91,"id":11392436}]}]}
{"op":"mcm","clk":"11931093049","pt":1724272125945,"mc":[{"id":"1.232098082","rc":[{"batb":[[0,3.4,14.57],[1,3,23.53],[2,1.04,1.53]],"ltp":3.6,"tv":75.91,"id":11392436}]}]}
{"op":"mcm","clk":"11931093290","pt":1724272129250,"mc":[{"id":"1.232098082","rc":[{"batb":[[0,3.45,10],[1,3.4,14.57],[2,3,23.53]],"ltp":3.6,"tv":75.91,"id":11392436}]}]}
{"op":"mcm","clk":"11931093568","pt":1724272132720,"mc":[{"id":"1.232098082","rc":[{"batb":[[0,3.4,14.57],[1,3,23.53],[2,1.04,1.53]],"ltp":3.6,"tv":75.91,"id":11392436}]}]}
{"op":"mcm","clk":"11931093946","pt":1724272138446,"mc":[{"id":"1.232098082","rc":[{"batb":[[0,3.45,10],[1,3.4,14.57],[2,3,23.53]],"ltp":3.6,"tv":75.91,"id":11392436}]}]}
{"op":"mcm","clk":"11931094169","pt":1724272141756,"mc":[{"id":"1.232098082","rc":[{"batb":[[0,3.4,14.57],[1,3,23.53],[2,1.04,1.53]],"ltp":3.6,"tv":75.91,"id":11392436}]}]}
{"op":"mcm","clk":"11931094429","pt":1724272144662,"mc":[{"id":"1.232098082","rc":[{"batb":[[0,3.45,10],[1,3.4,14.57],[2,3,23.53]],"ltp":3.6,"tv":75.91,"id":11392436}]}]}
{"op":"mcm","clk":"11931094635","pt":1724272147545,"mc":[{"id":"1.232098082","rc":[{"batl":[[0,24,1.15],[1,30,0.76],[2,30,0]],"ltp":3.6,"tv":75.91,"id":11392436}]}]}
{"op":"mcm","clk":"11931094656","pt":1724272147963,"mc":[{"id":"1.232098082","rc":[{"batb":[[0,3.4,14.57],[1,3,23.53],[2,1.04,1.53]],"ltp":3.6,"tv":75.91,"id":11392436}]}]}
{"op":"mcm","clk":"11931094812","pt":1724272150446,"mc":[{"id":"1.232098082","rc":[{"batb":[[0,3.45,10],[1,3.4,14.57],[2,3,23.53]],"ltp":3.6,"tv":75.91,"id":11392436}]}]}
{"op":"mcm","clk":"11931095033","pt":1724272153861,"mc":[{"id":"1.232098082","rc":[{"batb":[[0,3.4,14.57],[1,3,23.53],[2,1.04,1.53]],"ltp":3.6,"tv":75.91,"id":11392436}]}]}
{"op":"mcm","clk":"11931095339","pt":1724272157693,"mc":[{"id":"1.232098082","rc":[{"batb":[[0,3.45,10],[1,3.4,14.57],[2,3,23.53]],"ltp":3.6,"tv":75.91,"id":11392436}]}]}
{"op":"mcm","clk":"11931095601","pt":1724272160958,"mc":[{"id":"1.232098082","rc":[{"batb":[[0,3.4,14.57],[1,3,23.53],[2,1.04,1.53]],"ltp":3.6,"tv":75.91,"id":11392436}]}]}
{"op":"mcm","clk":"11931095834","pt":1724272164886,"mc":[{"id":"1.232098082","rc":[{"batb":[[0,3.45,10],[1,3.4,14.57],[2,3,23.53]],"ltp":3.6,"tv":75.91,"id":11392436}]}]}
{"op":"mcm","clk":"11931096062","pt":1724272168200,"mc":[{"id":"1.232098082","rc":[{"batb":[[0,3.4,14.57],[1,3,23.53],[2,1.04,1.53]],"ltp":3.6,"tv":75.91,"id":11392436}]}]}
{"op":"mcm","clk":"11931096206","pt":1724272170478,"mc":[{"id":"1.232098082","rc":[{"batb":[[0,3.45,10],[1,3.4,14.57],[2,3,23.53]],"ltp":3.6,"tv":75.91,"id":11392436}]}]}
{"op":"mcm","clk":"11931096481","pt":1724272173893,"mc":[{"id":"1.232098082","rc":[{"batb":[[0,3.4,14.57],[1,3,23.53],[2,1.04,1.53]],"ltp":3.6,"tv":75.91,"id":11392436}]}]}
{"op":"mcm","clk":"11931096801","pt":1724272177306,"mc":[{"id":"1.232098082","rc":[{"batb":[[0,3.45,10],[1,3.4,14.57],[2,3,23.53]],"ltp":3.6,"tv":75.91,"id":11392436}]}]}
{"op":"mcm","clk":"11931097129","pt":1724272180722,"mc":[{"id":"1.232098082","rc":[{"batb":[[0,3.4,14.57],[1,3,23.53],[2,1.04,1.53]],"ltp":3.6,"tv":75.91,"id":11392436}]}]}
{"op":"mcm","clk":"11931097402","pt":1724272183624,"mc":[{"id":"1.232098082","rc":[{"batb":[[0,3.45,10],[1,3.4,14.57],[2,3,23.53]],"ltp":3.6,"tv":75.91,"id":11392436}]}]}
{"op":"mcm","clk":"11931097709","pt":1724272187139,"mc":[{"id":"1.232098082","rc":[{"batb":[[0,3.4,14.57],[1,3,23.53],[2,1.04,1.53]],"ltp":3.6,"tv":75.91,"id":11392436}]}]}
{"op":"mcm","clk":"11931098911","pt":1724272200842,"mc":[{"id":"1.232098082","rc":[{"batb":[[0,3.45,10],[1,3.4,14.57],[2,3,23.53]],"ltp":3.6,"tv":75.91,"id":11392436}]}]}
{"op":"mcm","clk":"11931099239","pt":1724272204226,"mc":[{"id":"1.232098082","rc":[{"batb":[[0,3.4,14.57],[1,3,23.53],[2,1.04,1.53]],"ltp":3.6,"tv":75.91,"id":11392436}]}]}
{"op":"mcm","clk":"11931099456","pt":1724272207117,"mc":[{"id":"1.232098082","rc":[{"batb":[[0,3.45,10],[1,3.4,14.57],[2,3,23.53]],"ltp":3.6,"tv":75.91,"id":11392436}]}]}
{"op":"mcm","clk":"11931099694","pt":1724272210433,"mc":[{"id":"1.232098082","rc":[{"batb":[[0,3.4,14.57],[1,3,23.53],[2,1.04,1.53]],"ltp":3.6,"tv":75.91,"id":11392436}]}]}
{"op":"mcm","clk":"11931099933","pt":1724272213964,"mc":[{"id":"1.232098082","rc":[{"batb":[[0,3.45,10],[1,3.4,14.57],[2,3,23.53]],"ltp":3.6,"tv":75.91,"id":11392436}]}]}
{"op":"mcm","clk":"11931100198","pt":1724272217334,"mc":[{"id":"1.232098082","rc":[{"batb":[[0,3.4,14.57],[1,3,23.53],[2,1.04,1.53]],"ltp":3.6,"tv":75.91,"id":11392436}]}]}
{"op":"mcm","clk":"11931100513","pt":1724272220870,"mc":[{"id":"1.232098082","rc":[{"batb":[[0,3.45,10],[1,3.4,14.57],[2,3,23.53]],"ltp":3.6,"tv":75.91,"id":11392436}]}]}
{"op":"mcm","clk":"11931100817","pt":1724272224245,"mc":[{"id":"1.232098082","rc":[{"batb":[[0,3.4,14.57],[1,3,23.53],[2,1.04,1.53]],"ltp":3.6,"tv":75.91,"id":11392436}]}]}
{"op":"mcm","clk":"11931101043","pt":1724272226667,"mc":[{"id":"1.232098082","rc":[{"batb":[[0,3.45,10],[1,3.4,14.57],[2,3,23.53]],"ltp":3.6,"tv":75.91,"id":11392436}]}]}
{"op":"mcm","clk":"11931101302","pt":1724272230080,"mc":[{"id":"1.232098082","rc":[{"batb":[[0,3.4,14.57],[1,3,23.53],[2,1.04,1.53]],"ltp":3.6,"tv":75.91,"id":11392436}]}]}
{"op":"mcm","clk":"11931101512","pt":1724272232568,"mc":[{"id":"1.232098082","rc":[{"batb":[[0,3.45,10],[1,3.4,14.57],[2,3,23.53]],"ltp":3.6,"tv":75.91,"id":11392436}]}]}
{"op":"mcm","clk":"11931101815","pt":1724272235942,"mc":[{"id":"1.232098082","rc":[{"batb":[[0,3.4,14.57],[1,3,23.53],[2,1.04,1.53]],"ltp":3.6,"tv":75.91,"id":11392436}]}]}
{"op":"mcm","clk":"11931102064","pt":1724272238884,"mc":[{"id":"1.232098082","rc":[{"batb":[[0,3.45,10],[1,3.4,14.57],[2,3,23.53]],"ltp":3.6,"tv":75.91,"id":11392436}]}]}
{"op":"mcm","clk":"11931102334","pt":1724272242185,"mc":[{"id":"1.232098082","rc":[{"batb":[[0,3.4,14.57],[1,3,23.53],[2,1.04,1.53]],"ltp":3.6,"tv":75.91,"id":11392436}]}]}
{"op":"mcm","clk":"11931102565","pt":1724272244988,"mc":[{"id":"1.232098082","rc":[{"batb":[[0,3.45,10],[1,3.4,14.57],[2,3,23.53]],"ltp":3.6,"tv":75.91,"id":11392436}]}]}
{"op":"mcm","clk":"11931102854","pt":1724272248389,"mc":[{"id":"1.232098082","rc":[{"batb":[[0,3.4,14.57],[1,3,23.53],[2,1.04,1.53]],"ltp":3.6,"tv":75.91,"id":11392436}]}]}
{"op":"mcm","clk":"11931103331","pt":1724272254201,"mc":[{"id":"1.232098082","rc":[{"batb":[[0,3.45,10],[1,3.4,14.57],[2,3,23.53]],"ltp":3.6,"tv":75.91,"id":11392436}]}]}
{"op":"mcm","clk":"11931103597","pt":1724272257482,"mc":[{"id":"1.232098082","rc":[{"batb":[[0,3.4,14.57],[1,3,23.53],[2,1.04,1.53]],"ltp":3.6,"tv":75.91,"id":11392436}]}]}
{"op":"mcm","clk":"11931103775","pt":1724272259903,"mc":[{"id":"1.232098082","rc":[{"batb":[[0,3.45,10],[1,3.4,14.57],[2,3,23.53]],"ltp":3.6,"tv":75.91,"id":11392436}]}]}
{"op":"mcm","clk":"11931104127","pt":1724272263329,"mc":[{"id":"1.232098082","rc":[{"batb":[[0,3.4,14.57],[1,3,23.53],[2,1.04,1.53]],"ltp":3.6,"tv":75.91,"id":11392436}]}]}
{"op":"mcm","clk":"11931104572","pt":1724272267691,"mc":[{"id":"1.232098082","rc":[{"batb":[[0,3.45,10],[1,3.4,14.57],[2,3,23.53]],"ltp":3.6,"tv":75.91,"id":11392436}]}]}
{"op":"mcm","clk":"11931104853","pt":1724272271004,"mc":[{"id":"1.232098082","rc":[{"batb":[[0,3.4,14.57],[1,3,23.53],[2,1.04,1.53]],"ltp":3.6,"tv":75.91,"id":11392436}]}]}
{"op":"mcm","clk":"11931105186","pt":1724272274619,"mc":[{"id":"1.232098082","rc":[{"batb":[[0,3.45,10],[1,3.4,14.57],[2,3,23.53]],"ltp":3.6,"tv":75.91,"id":11392436}]}]}
{"op":"mcm","clk":"11931105429","pt":1724272277842,"mc":[{"id":"1.232098082","rc":[{"batb":[[0,3.4,14.57],[1,3,23.53],[2,1.04,1.53]],"ltp":3.6,"tv":75.91,"id":11392436}]}]}
{"op":"mcm","clk":"11931105695","pt":1724272281214,"mc":[{"id":"1.232098082","rc":[{"batb":[[0,3.45,10],[1,3.4,14.57],[2,3,23.53]],"ltp":3.6,"tv":75.91,"id":11392436}]}]}
{"op":"mcm","clk":"11931105991","pt":1724272284613,"mc":[{"id":"1.232098082","rc":[{"batb":[[0,3.4,14.57],[1,3,23.53],[2,1.04,1.53]],"ltp":3.6,"tv":75.91,"id":11392436}]}]}
{"op":"mcm","clk":"11931106458","pt":1724272290229,"mc":[{"id":"1.232098082","rc":[{"batb":[[0,3.45,10],[1,3.4,14.57],[2,3,23.53]],"ltp":3.6,"tv":75.91,"id":11392436}]}]}
{"op":"mcm","clk":"11931106754","pt":1724272293521,"mc":[{"id":"1.232098082","rc":[{"batb":[[0,3.4,14.57],[1,3,23.53],[2,1.04,1.53]],"ltp":3.6,"tv":75.91,"id":11392436}]}]}
{"op":"mcm","clk":"11931106976","pt":1724272296049,"mc":[{"id":"1.232098082","rc":[{"batb":[[0,3.45,10],[1,3.4,14.57],[2,3,23.53]],"ltp":3.6,"tv":75.91,"id":11392436}]}]}
{"op":"mcm","clk":"11931107227","pt":1724272299448,"mc":[{"id":"1.232098082","rc":[{"batb":[[0,3.4,14.57],[1,3,23.53],[2,1.04,1.53]],"ltp":3.6,"tv":75.91,"id":11392436}]}]}
{"op":"mcm","clk":"11931107484","pt":1724272303059,"mc":[{"id":"1.232098082","rc":[{"batb":[[0,3.45,10],[1,3.4,14.57],[2,3,23.53]],"ltp":3.6,"tv":75.91,"id":11392436}]}]}
{"op":"mcm","clk":"11931107791","pt":1724272306569,"mc":[{"id":"1.232098082","rc":[{"batb":[[0,3.4,14.57],[1,3,23.53],[2,1.04,1.53]],"ltp":3.6,"tv":75.91,"id":11392436}]}]}
{"op":"mcm","clk":"11931107983","pt":1724272308963,"mc":[{"id":"1.232098082","rc":[{"batb":[[0,3.45,10],[1,3.4,14.57],[2,3,23.53]],"ltp":3.6,"tv":75.91,"id":11392436}]}]}
{"op":"mcm","clk":"11931108292","pt":1724272312369,"mc":[{"id":"1.232098082","rc":[{"batb":[[0,3.4,14.57],[1,3,23.53],[2,1.04,1.53]],"ltp":3.6,"tv":75.91,"id":11392436}]}]}
{"op":"mcm","clk":"11931108542","pt":1724272315165,"mc":[{"id":"1.232098082","rc":[{"batb":[[0,3.45,10],[1,3.4,14.57],[2,3,23.53]],"ltp":3.6,"tv":75.91,"id":11392436}]}]}
{"op":"mcm","clk":"11931108831","pt":1724272318579,"mc":[{"id":"1.232098082","rc":[{"batb":[[0,3.4,14.57],[1,3,23.53],[2,1.04,1.53]],"ltp":3.6,"tv":75.91,"id":11392436}]}]}
{"op":"mcm","clk":"11931109026","pt":1724272320957,"mc":[{"id":"1.232098082","rc":[{"batb":[[0,3.45,10],[1,3.4,14.57],[2,3,23.53]],"ltp":3.6,"tv":75.91,"id":11392436}]}]}
{"op":"mcm","clk":"11931109352","pt":1724272324378,"mc":[{"id":"1.232098082","rc":[{"batb":[[0,3.4,14.57],[1,3,23.53],[2,1.04,1.53]],"ltp":3.6,"tv":75.91,"id":11392436}]}]}
{"op":"mcm","clk":"11931109727","pt":1724272328571,"mc":[{"id":"1.232098082","rc":[{"batb":[[0,3.45,10],[1,3.4,14.57],[2,3,23.53]],"ltp":3.6,"tv":75.91,"id":11392436}]}]}
{"op":"mcm","clk":"11931110045","pt":1724272331788,"mc":[{"id":"1.232098082","rc":[{"batb":[[0,3.4,14.57],[1,3,23.53],[2,1.04,1.53]],"ltp":3.6,"tv":75.91,"id":11392436}]}]}
{"op":"mcm","clk":"11931110230","pt":1724272333953,"mc":[{"id":"1.232098082","rc":[{"batb":[[0,3.45,10],[1,3.4,14.57],[2,3,23.53]],"ltp":3.6,"tv":75.91,"id":11392436}]}]}
{"op":"mcm","clk":"11931110514","pt":1724272337263,"mc":[{"id":"1.232098082","rc":[{"batb":[[0,3.4,14.57],[1,3,23.53],[2,1.04,1.53]],"ltp":3.6,"tv":75.91,"id":11392436}]}]}
{"op":"mcm","clk":"11931110750","pt":1724272340271,"mc":[{"id":"1.232098082","rc":[{"batb":[[0,3.45,10],[1,3.4,14.57],[2,3,23.53]],"ltp":3.6,"tv":75.91,"id":11392436}]}]}
{"op":"mcm","clk":"11931111044","pt":1724272343487,"mc":[{"id":"1.232098082","rc":[{"batb":[[0,3.4,14.57],[1,3,23.53],[2,1.04,1.53]],"ltp":3.6,"tv":75.91,"id":11392436}]}]}
{"op":"mcm","clk":"11931111378","pt":1724272346204,"mc":[{"id":"1.232098082","rc":[{"batb":[[0,3.45,10],[1,3.4,14.57],[2,3,23.53]],"ltp":3.6,"tv":75.91,"id":11392436}]}]}
{"op":"mcm","clk":"11931111797","pt":1724272349593,"mc":[{"id":"1.232098082","rc":[{"batb":[[0,3.4,14.57],[1,3,23.53],[2,1.04,1.53]],"ltp":3.6,"tv":75.91,"id":11392436}]}]}
{"op":"mcm","clk":"11931112106","pt":1724272353020,"mc":[{"id":"1.232098082","rc":[{"batb":[[0,3.45,10],[1,3.4,14.57],[2,3,23.53]],"ltp":3.6,"tv":75.91,"id":11392436}]}]}
{"op":"mcm","clk":"11931112392","pt":1724272356332,"mc":[{"id":"1.232098082","rc":[{"batb":[[0,3.4,14.57],[1,3,23.53],[2,1.04,1.53]],"ltp":3.6,"tv":75.91,"id":11392436}]}]}
{"op":"mcm","clk":"11931112703","pt":1724272360007,"mc":[{"id":"1.232098082","rc":[{"batb":[[0,3.45,10],[1,3.4,14.57],[2,3,23.53]],"ltp":3.6,"tv":75.91,"id":11392436}]}]}
{"op":"mcm","clk":"11931112968","pt":1724272363310,"mc":[{"id":"1.232098082","rc":[{"batb":[[0,3.4,14.57],[1,3,23.53],[2,1.04,1.53]],"ltp":3.6,"tv":75.91,"id":11392436}]}]}
{"op":"mcm","clk":"11931113176","pt":1724272365483,"mc":[{"id":"1.232098082","rc":[{"batb":[[0,3.45,10],[1,3.4,14.57],[2,3,23.53]],"ltp":3.6,"tv":75.91,"id":11392436}]}]}
{"op":"mcm","clk":"11931113436","pt":1724272368894,"mc":[{"id":"1.232098082","rc":[{"batb":[[0,3.4,14.57],[1,3,23.53],[2,1.04,1.53]],"ltp":3.6,"tv":75.91,"id":11392436}]}]}
{"op":"mcm","clk":"11931113862","pt":1724272374330,"mc":[{"id":"1.232098082","rc":[{"batb":[[0,3.45,10],[1,3.4,14.57],[2,3,23.53]],"ltp":3.6,"tv":75.91,"id":11392436}]}]}
{"op":"mcm","clk":"11931114145","pt":1724272377732,"mc":[{"id":"1.232098082","rc":[{"batb":[[0,3.4,14.57],[1,3,23.53],[2,1.04,1.53]],"ltp":3.6,"tv":75.91,"id":11392436}]}]}
{"op":"mcm","clk":"11931114310","pt":1724272380019,"mc":[{"id":"1.232098082","rc":[{"batb":[[0,3.45,10],[1,3.4,14.57],[2,3,23.53]],"ltp":3.6,"tv":75.91,"id":11392436}]}]}
{"op":"mcm","clk":"11931114587","pt":1724272383338,"mc":[{"id":"1.232098082","rc":[{"batb":[[0,3.4,14.57],[1,3,23.53],[2,1.04,1.53]],"ltp":3.6,"tv":75.91,"id":11392436}]}]}
{"op":"mcm","clk":"11931114886","pt":1724272386237,"mc":[{"id":"1.232098082","rc":[{"batb":[[0,3.45,10],[1,3.4,14.57],[2,3,23.53]],"ltp":3.6,"tv":75.91,"id":11392436}]}]}
{"op":"mcm","clk":"11931115175","pt":1724272389450,"mc":[{"id":"1.232098082","rc":[{"batb":[[0,3.4,14.57],[1,3,23.53],[2,1.04,1.53]],"ltp":3.6,"tv":75.91,"id":11392436}]}]}
{"op":"mcm","clk":"11931115395","pt":1724272392034,"mc":[{"id":"1.232098082","rc":[{"batb":[[0,3.45,10],[1,3.4,14.57],[2,3,23.53]],"ltp":3.6,"tv":75.91,"id":11392436}]}]}
{"op":"mcm","clk":"11931115678","pt":1724272395549,"mc":[{"id":"1.232098082","rc":[{"batb":[[0,3.4,14.57],[1,3,23.53],[2,1.04,1.53]],"ltp":3.6,"tv":75.91,"id":11392436}]}]}
{"op":"mcm","clk":"11931115888","pt":1724272398233,"mc":[{"id":"1.232098082","rc":[{"batb":[[0,3.45,10],[1,3.4,14.57],[2,3,23.53]],"ltp":3.6,"tv":75.91,"id":11392436}]}]}
{"op":"mcm","clk":"11931116130","pt":1724272401545,"mc":[{"id":"1.232098082","rc":[{"batb":[[0,3.4,14.57],[1,3,23.53],[2,1.04,1.53]],"ltp":3.6,"tv":75.91,"id":11392436}]}]}
{"op":"mcm","clk":"11931116376","pt":1724272404355,"mc":[{"id":"1.232098082","rc":[{"batb":[[0,3.45,10],[1,3.4,14.57],[2,3,23.53]],"ltp":3.6,"tv":75.91,"id":11392436}]}]}
{"op":"mcm","clk":"11931116621","pt":1724272407770,"mc":[{"id":"1.232098082","rc":[{"batb":[[0,3.4,14.57],[1,3,23.53],[2,1.04,1.53]],"ltp":3.6,"tv":75.91,"id":11392436}]}]}
{"op":"mcm","clk":"11931116935","pt":1724272411247,"mc":[{"id":"1.232098082","rc":[{"batb":[[0,3.45,10],[1,3.4,14.57],[2,3,23.53]],"ltp":3.6,"tv":75.91,"id":11392436}]}]}
{"op":"mcm","clk":"11931117238","pt":1724272414446,"mc":[{"id":"1.232098082","rc":[{"batb":[[0,3.4,14.57],[1,3,23.53],[2,1.04,1.53]],"ltp":3.6,"tv":75.91,"id":11392436}]}]}
{"op":"mcm","clk":"11931117468","pt":1724272417039,"mc":[{"id":"1.232098082","rc":[{"batb":[[0,3.45,10],[1,3.4,14.57],[2,3,23.53]],"ltp":3.6,"tv":75.91,"id":11392436}]}]}
{"op":"mcm","clk":"11931117774","pt":1724272420378,"mc":[{"id":"1.232098082","rc":[{"batb":[[0,3.4,14.57],[1,3,23.53],[2,1.04,1.53]],"ltp":3.6,"tv":75.91,"id":11392436}]}]}
{"op":"mcm","clk":"11931118048","pt":1724272423244,"mc":[{"id":"1.232098082","rc":[{"batb":[[0,3.45,10],[1,3.4,14.57],[2,3,23.53]],"ltp":3.6,"tv":75.91,"id":11392436}]}]}
{"op":"mcm","clk":"11931118413","pt":1724272426767,"mc":[{"id":"1.232098082","rc":[{"batb":[[0,3.4,14.57],[1,3,23.53],[2,1.04,1.53]],"ltp":3.6,"tv":75.91,"id":11392436}]}]}
{"op":"mcm","clk":"11931118700","pt":1724272429359,"mc":[{"id":"1.232098082","rc":[{"batb":[[0,3.45,10],[1,3.4,14.57],[2,3,23.53]],"ltp":3.6,"tv":75.91,"id":11392436}]}]}
{"op":"mcm","clk":"11931119020","pt":1724272432673,"mc":[{"id":"1.232098082","rc":[{"batb":[[0,3.4,14.57],[1,3,23.53],[2,1.04,1.53]],"ltp":3.6,"tv":75.91,"id":11392436}]}]}
{"op":"mcm","clk":"11931119426","pt":1724272437064,"mc":[{"id":"1.232098082","rc":[{"batb":[[0,3.45,10],[1,3.4,14.57],[2,3,23.53]],"ltp":3.6,"tv":75.91,"id":11392436}]}]}
{"op":"mcm","clk":"11931119714","pt":1724272440471,"mc":[{"id":"1.232098082","rc":[{"batb":[[0,3.4,14.57],[1,3,23.53],[2,1.04,1.53]],"ltp":3.6,"tv":75.91,"id":11392436}]}]}
{"op":"mcm","clk":"11931119953","pt":1724272443279,"mc":[{"id":"1.232098082","rc":[{"batb":[[0,3.45,10],[1,3.4,14.57],[2,3,23.53]],"ltp":3.6,"tv":75.91,"id":11392436}]}]}
{"op":"mcm","clk":"11931120241","pt":1724272446591,"mc":[{"id":"1.232098082","rc":[{"batb":[[0,3.4,14.57],[1,3,23.53],[2,1.04,1.53]],"ltp":3.6,"tv":75.91,"id":11392436}]}]}
{"op":"mcm","clk":"11931120492","pt":1724272449386,"mc":[{"id":"1.232098082","rc":[{"batb":[[0,3.45,10],[1,3.4,14.57],[2,3,23.53]],"ltp":3.6,"tv":75.91,"id":11392436}]}]}
{"op":"mcm","clk":"11931120774","pt":1724272452783,"mc":[{"id":"1.232098082","rc":[{"batb":[[0,3.4,14.57],[1,3,23.53],[2,1.04,1.53]],"ltp":3.6,"tv":75.91,"id":11392436}]}]}
{"op":"mcm","clk":"11931121072","pt":1724272456313,"mc":[{"id":"1.232098082","rc":[{"batb":[[0,3.45,10],[1,3.4,14.57],[2,3,23.53]],"ltp":3.6,"tv":75.91,"id":11392436}]}]}
{"op":"mcm","clk":"11931121331","pt":1724272459714,"mc":[{"id":"1.232098082","rc":[{"batb":[[0,3.4,14.57],[1,3,23.53],[2,1.04,1.53]],"ltp":3.6,"tv":75.91,"id":11392436}]}]}
{"op":"mcm","clk":"11931121509","pt":1724272462138,"mc":[{"id":"1.232098082","rc":[{"batb":[[0,3.45,10],[1,3.4,14.57],[2,3,23.53]],"ltp":3.6,"tv":75.91,"id":11392436}]}]}
{"op":"mcm","clk":"11931121761","pt":1724272465531,"mc":[{"id":"1.232098082","rc":[{"batb":[[0,3.4,14.57],[1,3,23.53],[2,1.04,1.53]],"ltp":3.6,"tv":75.91,"id":11392436}]}]}
{"op":"mcm","clk":"11931121957","pt":1724272468422,"mc":[{"id":"1.232098082","rc":[{"batb":[[0,3.45,10],[1,3.4,14.57],[2,3,23.53]],"ltp":3.6,"tv":75.91,"id":11392436}]}]}
{"op":"mcm","clk":"11931122226","pt":1724272471929,"mc":[{"id":"1.232098082","rc":[{"batb":[[0,3.4,14.57],[1,3,23.53],[2,1.04,1.53]],"ltp":3.6,"tv":75.91,"id":11392436}]}]}
{"op":"mcm","clk":"11931122451","pt":1724272474424,"mc":[{"id":"1.232098082","rc":[{"batb":[[0,3.45,10],[1,3.4,14.57],[2,3,23.53]],"ltp":3.6,"tv":75.91,"id":11392436}]}]}
{"op":"mcm","clk":"11931122719","pt":1724272477930,"mc":[{"id":"1.232098082","rc":[{"batb":[[0,3.4,14.57],[1,3,23.53],[2,1.04,1.53]],"ltp":3.6,"tv":75.91,"id":11392436}]}]}
{"op":"mcm","clk":"11931122883","pt":1724272480346,"mc":[{"id":"1.232098082","rc":[{"batb":[[0,3.45,10],[1,3.4,14.57],[2,3,23.53]],"ltp":3.6,"tv":75.91,"id":11392436}]}]}
{"op":"mcm","clk":"11931123096","pt":1724272483822,"mc":[{"id":"1.232098082","rc":[{"batb":[[0,3.4,14.57],[1,3,23.53],[2,1.04,1.53]],"ltp":3.6,"tv":75.91,"id":11392436}]}]}
{"op":"mcm","clk":"11931123302","pt":1724272486754,"mc":[{"id":"1.232098082","rc":[{"batb":[[0,3.45,10],[1,3.4,14.57],[2,3,23.53]],"ltp":3.6,"tv":75.91,"id":11392436}]}]}
{"op":"mcm","clk":"11931123603","pt":1724272490123,"mc":[{"id":"1.232098082","rc":[{"batb":[[0,3.4,14.57],[1,3,23.53],[2,1.04,1.53]],"ltp":3.6,"tv":75.91,"id":11392436}]}]}
{"op":"mcm","clk":"11931123886","pt":1724272493953,"mc":[{"id":"1.232098082","rc":[{"batb":[[0,3.45,10],[1,3.4,14.57],[2,3,23.53]],"ltp":3.6,"tv":75.91,"id":11392436}]}]}
{"op":"mcm","clk":"11931124139","pt":1724272497252,"mc":[{"id":"1.232098082","rc":[{"batb":[[0,3.4,14.57],[1,3,23.53],[2,1.04,1.53]],"ltp":3.6,"tv":75.91,"id":11392436}]}]}
{"op":"mcm","clk":"11931124348","pt":1724272500456,"mc":[{"id":"1.232098082","rc":[{"batb":[[0,3.45,10],[1,3.4,14.57],[2,3,23.53]],"ltp":3.6,"tv":75.91,"id":11392436}]}]}
{"op":"mcm","clk":"11931124594","pt":1724272503866,"mc":[{"id":"1.232098082","rc":[{"batb":[[0,3.4,14.57],[1,3,23.53],[2,1.04,1.53]],"ltp":3.6,"tv":75.91,"id":11392436}]}]}
{"op":"mcm","clk":"11931125031","pt":1724272509643,"mc":[{"id":"1.232098082","rc":[{"batb":[[0,3.45,10],[1,3.4,14.57],[2,3,23.53]],"ltp":3.6,"tv":75.91,"id":11392436}]}]}
{"op":"mcm","clk":"11931125326","pt":1724272513073,"mc":[{"id":"1.232098082","rc":[{"batb":[[0,3.4,14.57],[1,3,23.53],[2,1.04,1.53]],"ltp":3.6,"tv":75.91,"id":11392436}]}]}
{"op":"mcm","clk":"11931125563","pt":1724272515954,"mc":[{"id":"1.232098082","rc":[{"batb":[[0,3.45,10],[1,3.4,14.57],[2,3,23.53]],"ltp":3.6,"tv":75.91,"id":11392436}]}]}
{"op":"mcm","clk":"11931125842","pt":1724272519345,"mc":[{"id":"1.232098082","rc":[{"batb":[[0,3.4,14.57],[1,3,23.53],[2,1.04,1.53]],"ltp":3.6,"tv":75.91,"id":11392436}]}]}
{"op":"mcm","clk":"11931126040","pt":1724272521983,"mc":[{"id":"1.232098082","rc":[{"batb":[[0,3.45,10],[1,3.4,14.57],[2,3,23.53]],"ltp":3.6,"tv":75.91,"id":11392436}]}]}
{"op":"mcm","clk":"11931126353","pt":1724272525586,"mc":[{"id":"1.232098082","rc":[{"batb":[[0,3.4,14.57],[1,3,23.53],[2,1.04,1.53]],"ltp":3.6,"tv":75.91,"id":11392436}]}]}
{"op":"mcm","clk":"11931126591","pt":1724272528578,"mc":[{"id":"1.232098082","rc":[{"batb":[[0,3.45,10],[1,3.4,14.57],[2,3,23.53]],"ltp":3.6,"tv":75.91,"id":11392436}]}]}
{"op":"mcm","clk":"11931126875","pt":1724272531990,"mc":[{"id":"1.232098082","rc":[{"batb":[[0,3.4,14.57],[1,3,23.53],[2,1.04,1.53]],"ltp":3.6,"tv":75.91,"id":11392436}]}]}
{"op":"mcm","clk":"11931127149","pt":1724272535389,"mc":[{"id":"1.232098082","rc":[{"batb":[[0,3.45,10],[1,3.4,14.57],[2,3,23.53]],"ltp":3.6,"tv":75.91,"id":11392436}]}]}
{"op":"mcm","clk":"11931127423","pt":1724272538698,"mc":[{"id":"1.232098082","rc":[{"batb":[[0,3.4,14.57],[1,3,23.53],[2,1.04,1.53]],"ltp":3.6,"tv":75.91,"id":11392436}]}]}
{"op":"mcm","clk":"11931127692","pt":1724272541802,"mc":[{"id":"1.232098082","rc":[{"batb":[[0,3.45,10],[1,3.4,14.57],[2,3,23.53]],"ltp":3.6,"tv":75.91,"id":11392436}]}]}
{"op":"mcm","clk":"11931127999","pt":1724272545100,"mc":[{"id":"1.232098082","rc":[{"batb":[[0,3.4,14.57],[1,3,23.53],[2,1.04,1.53]],"ltp":3.6,"tv":75.91,"id":11392436}]}]}
{"op":"mcm","clk":"11931128509","pt":1724272551104,"mc":[{"id":"1.232098082","rc":[{"batb":[[0,3.45,10],[1,3.4,14.57],[2,3,23.53]],"ltp":3.6,"tv":75.91,"id":11392436}]}]}
{"op":"mcm","clk":"11931128833","pt":1724272554316,"mc":[{"id":"1.232098082","rc":[{"batb":[[0,3.4,14.57],[1,3,23.53],[2,1.04,1.53]],"ltp":3.6,"tv":75.91,"id":11392436}]}]}
{"op":"mcm","clk":"11931129061","pt":1724272556906,"mc":[{"id":"1.232098082","rc":[{"batb":[[0,3.45,10],[1,3.4,14.57],[2,3,23.53]],"ltp":3.6,"tv":75.91,"id":11392436}]}]}
{"op":"mcm","clk":"11931129314","pt":1724272560218,"mc":[{"id":"1.232098082","rc":[{"batb":[[0,3.4,14.57],[1,3,23.53],[2,1.04,1.53]],"ltp":3.6,"tv":75.91,"id":11392436}]}]}
{"op":"mcm","clk":"11931129638","pt":1724272563492,"mc":[{"id":"1.232098082","rc":[{"batb":[[0,3.45,10],[1,3.4,14.57],[2,3,23.53]],"ltp":3.6,"tv":75.91,"id":11392436}]}]}
{"op":"mcm","clk":"11931129935","pt":1724272566913,"mc":[{"id":"1.232098082","rc":[{"batb":[[0,3.4,14.57],[1,3,23.53],[2,1.04,1.53]],"ltp":3.6,"tv":75.91,"id":11392436}]}]}
{"op":"mcm","clk":"11931130307","pt":1724272571118,"mc":[{"id":"1.232098082","rc":[{"batb":[[0,3.45,10],[1,3.4,14.57],[2,3,23.53]],"ltp":3.6,"tv":75.91,"id":11392436}]}]}
{"op":"mcm","clk":"11931130629","pt":1724272574535,"mc":[{"id":"1.232098082","rc":[{"batb":[[0,3.4,14.57],[1,3,23.53],[2,1.04,1.53]],"ltp":3.6,"tv":75.91,"id":11392436}]}]}
{"op":"mcm","clk":"11931130988","pt":1724272578636,"mc":[{"id":"1.232098082","rc":[{"batb":[[0,3.45,10],[1,3.4,14.57],[2,3,23.53]],"ltp":3.6,"tv":75.91,"id":11392436}]}]}
{"op":"mcm","clk":"11931131313","pt":1724272582005,"mc":[{"id":"1.232098082","rc":[{"batb":[[0,3.4,14.57],[1,3,23.53],[2,1.04,1.53]],"ltp":3.6,"tv":75.91,"id":11392436}]}]}
{"op":"mcm","clk":"11931131517","pt":1724272584224,"mc":[{"id":"1.232098082","rc":[{"batb":[[0,3.45,10],[1,3.4,14.57],[2,3,23.53]],"ltp":3.6,"tv":75.91,"id":11392436}]}]}
{"op":"mcm","clk":"11931131825","pt":1724272587643,"mc":[{"id":"1.232098082","rc":[{"batb":[[0,3.4,14.57],[1,3,23.53],[2,1.04,1.53]],"ltp":3.6,"tv":75.91,"id":11392436}]}]}
{"op":"mcm","clk":"11931132084","pt":1724272590284,"mc":[{"id":"1.232098082","rc":[{"batb":[[0,3.45,10],[1,3.4,14.57],[2,3,23.53]],"ltp":3.6,"tv":75.91,"id":11392436}]}]}
{"op":"mcm","clk":"11931132408","pt":1724272593644,"mc":[{"id":"1.232098082","rc":[{"batb":[[0,3.4,14.57],[1,3,23.53],[2,1.04,1.53]],"ltp":3.6,"tv":75.91,"id":11392436}]}]}
{"op":"mcm","clk":"11931132637","pt":1724272595757,"mc":[{"id":"1.232098082","rc":[{"batb":[[0,3.45,10],[1,3.4,14.57],[2,3,23.53]],"ltp":3.6,"tv":75.91,"id":11392436}]}]}
{"op":"mcm","clk":"11931132942","pt":1724272599157,"mc":[{"id":"1.232098082","rc":[{"batb":[[0,3.4,14.57],[1,3,23.53],[2,1.04,1.53]],"ltp":3.6,"tv":75.91,"id":11392436}]}]}
{"op":"mcm","clk":"11931133188","pt":1724272601580,"mc":[{"id":"1.232098082","rc":[{"batb":[[0,3.45,10],[1,3.4,14.57],[2,3,23.53]],"ltp":3.6,"tv":75.91,"id":11392436}]}]}
{"op":"mcm","clk":"11931133511","pt":1724272604885,"mc":[{"id":"1.232098082","rc":[{"batb":[[0,3.4,14.57],[1,3,23.53],[2,1.04,1.53]],"ltp":3.6,"tv":75.91,"id":11392436}]}]}
{"op":"mcm","clk":"11931133861","pt":1724272608778,"mc":[{"id":"1.232098082","rc":[{"batb":[[0,3.45,10],[1,3.4,14.57],[2,3,23.53]],"ltp":3.6,"tv":75.91,"id":11392436}]}]}
{"op":"mcm","clk":"11931134165","pt":1724272612076,"mc":[{"id":"1.232098082","rc":[{"batb":[[0,3.4,14.57],[1,3,23.53],[2,1.04,1.53]],"ltp":3.6,"tv":75.91,"id":11392436}]}]}
{"op":"mcm","clk":"11931134386","pt":1724272614501,"mc":[{"id":"1.232098082","rc":[{"batb":[[0,3.45,10],[1,3.4,14.57],[2,3,23.53]],"ltp":3.6,"tv":75.91,"id":11392436}]}]}
{"op":"mcm","clk":"11931134717","pt":1724272617911,"mc":[{"id":"1.232098082","rc":[{"batb":[[0,3.4,14.57],[1,3,23.53],[2,1.04,1.53]],"ltp":3.6,"tv":75.91,"id":11392436}]}]}
{"op":"mcm","clk":"11931134998","pt":1724272621203,"mc":[{"id":"1.232098082","rc":[{"batb":[[0,3.45,10],[1,3.4,14.57],[2,3,23.53]],"ltp":3.6,"tv":75.91,"id":11392436}]}]}
{"op":"mcm","clk":"11931135306","pt":1724272624623,"mc":[{"id":"1.232098082","rc":[{"batb":[[0,3.4,14.57],[1,3,23.53],[2,1.04,1.53]],"ltp":3.6,"tv":75.91,"id":11392436}]}]}
{"op":"mcm","clk":"11931135498","pt":1724272626999,"mc":[{"id":"1.232098082","rc":[{"batb":[[0,3.45,10],[1,3.4,14.57],[2,3,23.53]],"ltp":3.6,"tv":75.91,"id":11392436}]}]}
{"op":"mcm","clk":"11931135821","pt":1724272630361,"mc":[{"id":"1.232098082","rc":[{"batb":[[0,3.4,14.57],[1,3,23.53],[2,1.04,1.53]],"ltp":3.6,"tv":75.91,"id":11392436}]}]}
{"op":"mcm","clk":"11931136061","pt":1724272632635,"mc":[{"id":"1.232098082","rc":[{"batb":[[0,3.45,10],[1,3.4,14.57],[2,3,23.53]],"ltp":3.6,"tv":75.91,"id":11392436}]}]}
{"op":"mcm","clk":"11931136341","pt":1724272636049,"mc":[{"id":"1.232098082","rc":[{"batb":[[0,3.4,14.57],[1,3,23.53],[2,1.04,1.53]],"ltp":3.6,"tv":75.91,"id":11392436}]}]}
{"op":"mcm","clk":"11931136578","pt":1724272638938,"mc":[{"id":"1.232098082","rc":[{"batb":[[0,3.45,10],[1,3.4,14.57],[2,3,23.53]],"ltp":3.6,"tv":75.91,"id":11392436}]}]}
{"op":"mcm","clk":"11931136865","pt":1724272642344,"mc":[{"id":"1.232098082","rc":[{"batb":[[0,3.4,14.57],[1,3,23.53],[2,1.04,1.53]],"ltp":3.6,"tv":75.91,"id":11392436}]}]}
{"op":"mcm","clk":"11931137203","pt":1724272645653,"mc":[{"id":"1.232098082","rc":[{"batb":[[0,3.45,10],[1,3.4,14.57],[2,3,23.53]],"ltp":3.6,"tv":75.91,"id":11392436}]}]}
{"op":"mcm","clk":"11931137505","pt":1724272649031,"mc":[{"id":"1.232098082","rc":[{"batb":[[0,3.4,14.57],[1,3,23.53],[2,1.04,1.53]],"ltp":3.6,"tv":75.91,"id":11392436}]}]}
{"op":"mcm","clk":"11931137698","pt":1724272651555,"mc":[{"id":"1.232098082","rc":[{"batb":[[0,3.45,10],[1,3.4,14.57],[2,3,23.53]],"ltp":3.6,"tv":75.91,"id":11392436}]}]}
{"op":"mcm","clk":"11931137992","pt":1724272654962,"mc":[{"id":"1.232098082","rc":[{"batb":[[0,3.4,14.57],[1,3,23.53],[2,1.04,1.53]],"ltp":3.6,"tv":75.91,"id":11392436}]}]}
{"op":"mcm","clk":"11931138211","pt":1724272657756,"mc":[{"id":"1.232098082","rc":[{"batb":[[0,3.45,10],[1,3.4,14.57],[2,3,23.53]],"ltp":3.6,"tv":75.91,"id":11392436}]}]}
{"op":"mcm","clk":"11931138495","pt":1724272661268,"mc":[{"id":"1.232098082","rc":[{"batb":[[0,3.4,14.57],[1,3,23.53],[2,1.04,1.53]],"ltp":3.6,"tv":75.91,"id":11392436}]}]}
{"op":"mcm","clk":"11931138705","pt":1724272663559,"mc":[{"id":"1.232098082","rc":[{"batb":[[0,3.45,10],[1,3.4,14.57],[2,3,23.53]],"ltp":3.6,"tv":75.91,"id":11392436}]}]}
{"op":"mcm","clk":"11931139019","pt":1724272667074,"mc":[{"id":"1.232098082","rc":[{"batb":[[0,3.4,14.57],[1,3,23.53],[2,1.04,1.53]],"ltp":3.6,"tv":75.91,"id":11392436}]}]}
{"op":"mcm","clk":"11931139615","pt":1724272673749,"mc":[{"id":"1.232098082","rc":[{"batb":[[0,3.45,10],[1,3.4,14.57],[2,3,23.53]],"ltp":3.6,"tv":75.91,"id":11392436}]}]}
{"op":"mcm","clk":"11931139924","pt":1724272677165,"mc":[{"id":"1.232098082","rc":[{"batb":[[0,3.4,14.57],[1,3,23.53],[2,1.04,1.53]],"ltp":3.6,"tv":75.91,"id":11392436}]}]}
{"op":"mcm","clk":"11931140459","pt":1724272683269,"mc":[{"id":"1.232098082","rc":[{"batb":[[0,3.45,10],[1,3.4,14.57],[2,3,23.53]],"ltp":3.6,"tv":75.91,"id":11392436}]}]}
{"op":"mcm","clk":"11931140782","pt":1724272686697,"mc":[{"id":"1.232098082","rc":[{"batb":[[0,3.4,14.57],[1,3,23.53],[2,1.04,1.53]],"ltp":3.6,"tv":75.91,"id":11392436}]}]}
{"op":"mcm","clk":"11931140968","pt":1724272689071,"mc":[{"id":"1.232098082","rc":[{"batb":[[0,3.45,10],[1,3.4,14.57],[2,3,23.53]],"ltp":3.6,"tv":75.91,"id":11392436}]}]}
{"op":"mcm","clk":"11931141204","pt":1724272692408,"mc":[{"id":"1.232098082","rc":[{"batb":[[0,3.4,14.57],[1,3,23.53],[2,1.04,1.53]],"ltp":3.6,"tv":75.91,"id":11392436}]}]}
{"op":"mcm","clk":"11931141572","pt":1724272697182,"mc":[{"id":"1.232098082","rc":[{"batb":[[0,3.45,10],[1,3.4,14.57],[2,3,23.53]],"ltp":3.6,"tv":75.91,"id":11392436}]}]}
{"op":"mcm","clk":"11931141810","pt":1724272700487,"mc":[{"id":"1.232098082","rc":[{"batb":[[0,3.4,14.57],[1,3,23.53],[2,1.04,1.53]],"ltp":3.6,"tv":75.91,"id":11392436}]}]}
{"op":"mcm","clk":"11931141987","pt":1724272702662,"mc":[{"id":"1.232098082","rc":[{"batb":[[0,3.45,10],[1,3.4,14.57],[2,3,23.53]],"ltp":3.6,"tv":75.91,"id":11392436}]}]}
{"op":"mcm","clk":"11931142253","pt":1724272706075,"mc":[{"id":"1.232098082","rc":[{"batb":[[0,3.4,14.57],[1,3,23.53],[2,1.04,1.53]],"ltp":3.6,"tv":75.91,"id":11392436}]}]}
{"op":"mcm","clk":"11931142614","pt":1724272709770,"mc":[{"id":"1.232098082","rc":[{"batb":[[0,3.45,10],[1,3.4,14.57],[2,3,23.53]],"ltp":3.6,"tv":75.91,"id":11392436}]}]}
{"op":"mcm","clk":"11931142916","pt":1724272713193,"mc":[{"id":"1.232098082","rc":[{"batb":[[0,3.4,14.57],[1,3,23.53],[2,1.04,1.53]],"ltp":3.6,"tv":75.91,"id":11392436}]}]}
{"op":"mcm","clk":"11931143111","pt":1724272715519,"mc":[{"id":"1.232098082","rc":[{"batb":[[0,3.45,10],[1,3.4,14.57],[2,3,23.53]],"ltp":3.6,"tv":75.91,"id":11392436}]}]}
{"op":"mcm","clk":"11931143414","pt":1724272718879,"mc":[{"id":"1.232098082","rc":[{"batb":[[0,3.4,14.57],[1,3,23.53],[2,1.04,1.53]],"ltp":3.6,"tv":75.91,"id":11392436}]}]}
{"op":"mcm","clk":"11931143623","pt":1724272721209,"mc":[{"id":"1.232098082","rc":[{"batb":[[0,3.45,10],[1,3.4,14.57],[2,3,23.53]],"ltp":3.6,"tv":75.91,"id":11392436}]}]}
{"op":"mcm","clk":"11931143872","pt":1724272724509,"mc":[{"id":"1.232098082","rc":[{"batb":[[0,3.4,14.57],[1,3,23.53],[2,1.04,1.53]],"ltp":3.6,"tv":75.91,"id":11392436}]}]}
{"op":"mcm","clk":"11931144258","pt":1724272729215,"mc":[{"id":"1.232098082","rc":[{"batb":[[0,3.45,10],[1,3.4,14.57],[2,3,23.53]],"ltp":3.6,"tv":75.91,"id":11392436}]}]}
{"op":"mcm","clk":"11931144533","pt":1724272732515,"mc":[{"id":"1.232098082","rc":[{"batb":[[0,3.4,14.57],[1,3,23.53],[2,1.04,1.53]],"ltp":3.6,"tv":75.91,"id":11392436}]}]}
{"op":"mcm","clk":"11931144750","pt":1724272735108,"mc":[{"id":"1.232098082","rc":[{"batb":[[0,3.45,10],[1,3.4,14.57],[2,3,23.53]],"ltp":3.6,"tv":75.91,"id":11392436}]}]}
{"op":"mcm","clk":"11931145046","pt":1724272738401,"mc":[{"id":"1.232098082","rc":[{"batb":[[0,3.4,14.57],[1,3,23.53],[2,1.04,1.53]],"ltp":3.6,"tv":75.91,"id":11392436}]}]}
{"op":"mcm","clk":"11931145237","pt":1724272740834,"mc":[{"id":"1.232098082","rc":[{"batb":[[0,3.45,10],[1,3.4,14.57],[2,3,23.53]],"ltp":3.6,"tv":75.91,"id":11392436}]}]}
{"op":"mcm","clk":"11931145504","pt":1724272744240,"mc":[{"id":"1.232098082","rc":[{"batb":[[0,3.4,14.57],[1,3,23.53],[2,1.04,1.53]],"ltp":3.6,"tv":75.91,"id":11392436}]}]}
{"op":"mcm","clk":"11931145867","pt":1724272747711,"mc":[{"id":"1.232098082","rc":[{"batb":[[0,3.45,10],[1,3.4,14.57],[2,3,23.53]],"ltp":3.6,"tv":75.91,"id":11392436}]}]}
{"op":"mcm","clk":"11931146220","pt":1724272751244,"mc":[{"id":"1.232098082","rc":[{"batb":[[0,3.4,14.57],[1,3,23.53],[2,1.04,1.53]],"ltp":3.6,"tv":75.91,"id":11392436}]}]}
{"op":"mcm","clk":"11931146423","pt":1724272753523,"mc":[{"id":"1.232098082","rc":[{"batb":[[0,3.45,10],[1,3.4,14.57],[2,3,23.53]],"ltp":3.6,"tv":75.91,"id":11392436}]}]}
{"op":"mcm","clk":"11931146754","pt":1724272757045,"mc":[{"id":"1.232098082","rc":[{"batb":[[0,3.4,14.57],[1,3,23.53],[2,1.04,1.53]],"ltp":3.6,"tv":75.91,"id":11392436}]}]}
{"op":"mcm","clk":"11931146993","pt":1724272759423,"mc":[{"id":"1.232098082","rc":[{"batb":[[0,3.45,10],[1,3.4,14.57],[2,3,23.53]],"ltp":3.6,"tv":75.91,"id":11392436}]}]}
{"op":"mcm","clk":"11931147260","pt":1724272762676,"mc":[{"id":"1.232098082","rc":[{"batb":[[0,3.4,14.57],[1,3,23.53],[2,1.04,1.53]],"ltp":3.6,"tv":75.91,"id":11392436}]}]}
{"op":"mcm","clk":"11931147546","pt":1724272765464,"mc":[{"id":"1.232098082","rc":[{"batb":[[0,3.45,10],[1,3.4,14.57],[2,3,23.53]],"ltp":3.6,"tv":75.91,"id":11392436}]}]}
{"op":"mcm","clk":"11931147816","pt":1724272768773,"mc":[{"id":"1.232098082","rc":[{"batb":[[0,3.4,14.57],[1,3,23.53],[2,1.04,1.53]],"ltp":3.6,"tv":75.91,"id":11392436}]}]}
{"op":"mcm","clk":"11931148056","pt":1724272771360,"mc":[{"id":"1.232098082","rc":[{"batb":[[0,3.45,10],[1,3.4,14.57],[2,3,23.53]],"ltp":3.6,"tv":75.91,"id":11392436}]}]}
{"op":"mcm","clk":"11931148324","pt":1724272774680,"mc":[{"id":"1.232098082","rc":[{"batb":[[0,3.4,14.57],[1,3,23.53],[2,1.04,1.53]],"ltp":3.6,"tv":75.91,"id":11392436}]}]}
{"op":"mcm","clk":"11931148525","pt":1724272776956,"mc":[{"id":"1.232098082","rc":[{"batb":[[0,3.45,10],[1,3.4,14.57],[2,3,23.53]],"ltp":3.6,"tv":75.91,"id":11392436}]}]}
{"op":"mcm","clk":"11931148827","pt":1724272780470,"mc":[{"id":"1.232098082","rc":[{"batb":[[0,3.4,14.57],[1,3,23.53],[2,1.04,1.53]],"ltp":3.6,"tv":75.91,"id":11392436}]}]}
{"op":"mcm","clk":"11931149175","pt":1724272784462,"mc":[{"id":"1.232098082","rc":[{"batb":[[0,3.45,10],[1,3.4,14.57],[2,3,23.53]],"ltp":3.6,"tv":75.91,"id":11392436}]}]}
{"op":"mcm","clk":"11931149475","pt":1724272787982,"mc":[{"id":"1.232098082","rc":[{"batb":[[0,3.4,14.57],[1,3,23.53],[2,1.04,1.53]],"ltp":3.6,"tv":75.91,"id":11392436}]}]}
{"op":"mcm","clk":"11931149707","pt":1724272790371,"mc":[{"id":"1.232098082","rc":[{"batb":[[0,3.45,10],[1,3.4,14.57],[2,3,23.53]],"ltp":3.6,"tv":75.91,"id":11392436}]}]}
{"op":"mcm","clk":"11931150010","pt":1724272793686,"mc":[{"id":"1.232098082","rc":[{"batb":[[0,3.4,14.57],[1,3,23.53],[2,1.04,1.53]],"ltp":3.6,"tv":75.91,"id":11392436}]}]}
{"op":"mcm","clk":"11931150230","pt":1724272796102,"mc":[{"id":"1.232098082","rc":[{"batb":[[0,3.45,10],[1,3.4,14.57],[2,3,23.53]],"ltp":3.6,"tv":75.91,"id":11392436}]}]}
{"op":"mcm","clk":"11931150544","pt":1724272799360,"mc":[{"id":"1.232098082","rc":[{"batb":[[0,3.4,14.57],[1,3,23.53],[2,1.04,1.53]],"ltp":3.6,"tv":75.91,"id":11392436}]}]}
{"op":"mcm","clk":"11931150772","pt":1724272801803,"mc":[{"id":"1.232098082","rc":[{"batb":[[0,3.45,10],[1,3.4,14.57],[2,3,23.53]],"ltp":3.6,"tv":75.91,"id":11392436}]}]}
{"op":"mcm","clk":"11931151088","pt":1724272805263,"mc":[{"id":"1.232098082","rc":[{"batb":[[0,3.4,14.57],[1,3,23.53],[2,1.04,1.53]],"ltp":3.6,"tv":75.91,"id":11392436}]}]}
{"op":"mcm","clk":"11931151344","pt":1724272808002,"mc":[{"id":"1.232098082","rc":[{"batb":[[0,3.45,10],[1,3.4,14.57],[2,3,23.53]],"ltp":3.6,"tv":75.91,"id":11392436}]}]}
{"op":"mcm","clk":"11931151635","pt":1724272811464,"mc":[{"id":"1.232098082","rc":[{"batb":[[0,3.4,14.57],[1,3,23.53],[2,1.04,1.53]],"ltp":3.6,"tv":75.91,"id":11392436}]}]}
{"op":"mcm","clk":"11931151873","pt":1724272814468,"mc":[{"id":"1.232098082","rc":[{"batb":[[0,3.45,10],[1,3.4,14.57],[2,3,23.53]],"ltp":3.6,"tv":75.91,"id":11392436}]}]}
{"op":"mcm","clk":"11931152168","pt":1724272817882,"mc":[{"id":"1.232098082","rc":[{"batb":[[0,3.4,14.57],[1,3,23.53],[2,1.04,1.53]],"ltp":3.6,"tv":75.91,"id":11392436}]}]}
{"op":"mcm","clk":"11931152393","pt":1724272820525,"mc":[{"id":"1.232098082","rc":[{"batb":[[0,3.45,10],[1,3.4,14.57],[2,3,23.53]],"ltp":3.6,"tv":75.91,"id":11392436}]}]}
{"op":"mcm","clk":"11931152514","pt":1724272821808,"mc":[{"id":"1.232098082","rc":[{"batb":[[0,1.3,5.35],[1,1.16,1.84],[2,1.14,21.38]],"ltp":1.39,"tv":583.4,"id":48610314}]}]}
{"op":"mcm","clk":"11931152710","pt":1724272823973,"mc":[{"id":"1.232098082","rc":[{"batb":[[0,3.4,14.57],[1,3,23.53],[2,1.04,1.53]],"ltp":3.6,"tv":75.91,"id":11392436}]}]}
{"op":"mcm","clk":"11931152911","pt":1724272826291,"mc":[{"id":"1.232098082","rc":[{"batb":[[0,3.45,10],[1,3.4,14.57],[2,3,23.53]],"ltp":3.6,"tv":75.91,"id":11392436}]}]}
{"op":"mcm","clk":"11931153182","pt":1724272829793,"mc":[{"id":"1.232098082","rc":[{"batb":[[0,3.4,14.57],[1,3,23.53],[2,1.04,1.53]],"ltp":3.6,"tv":75.91,"id":11392436}]}]}
{"op":"mcm","clk":"11931153401","pt":1724272832427,"mc":[{"id":"1.232098082","rc":[{"batb":[[0,3.45,10],[1,3.4,14.57],[2,3,23.53]],"ltp":3.6,"tv":75.91,"id":11392436}]}]}
{"op":"mcm","clk":"11931153717","pt":1724272835942,"mc":[{"id":"1.232098082","rc":[{"batb":[[0,3.4,14.57],[1,3,23.53],[2,1.04,1.53]],"ltp":3.6,"tv":75.91,"id":11392436}]}]}
{"op":"mcm","clk":"11931154114","pt":1724272840511,"mc":[{"id":"1.232098082","rc":[{"batb":[[0,3.45,10],[1,3.4,14.57],[2,3,23.53]],"ltp":3.6,"tv":75.91,"id":11392436}]}]}
{"op":"mcm","clk":"11931154429","pt":1724272843824,"mc":[{"id":"1.232098082","rc":[{"batb":[[0,3.4,14.57],[1,3,23.53],[2,1.04,1.53]],"ltp":3.6,"tv":75.91,"id":11392436}]}]}
{"op":"mcm","clk":"11931154713","pt":1724272846823,"mc":[{"id":"1.232098082","rc":[{"batb":[[0,3.45,10],[1,3.4,14.57],[2,3,23.53]],"ltp":3.6,"tv":75.91,"id":11392436}]}]}
{"op":"mcm","clk":"11931154797","pt":1724272847909,"mc":[{"id":"1.232098082","rc":[{"batb":[[2,1.04,1.53]],"ltp":1.39,"tv":583.4,"id":48610314}]}]}
{"op":"mcm","clk":"11931155029","pt":1724272850264,"mc":[{"id":"1.232098082","rc":[{"batb":[[0,3.4,14.57],[1,3,23.53],[2,1.04,1.53]],"ltp":3.6,"tv":75.91,"id":11392436}]}]}
{"op":"mcm","clk":"11931155240","pt":1724272852563,"mc":[{"id":"1.232098082","rc":[{"batb":[[0,3.45,10],[1,3.4,14.57],[2,3,23.53]],"ltp":3.6,"tv":75.91,"id":11392436}]}]}
{"op":"mcm","clk":"11931155367","pt":1724272853759,"mc":[{"id":"1.232098082","rc":[{"batb":[[1,1.04,2.45],[2,1.03,200]],"ltp":1.39,"tv":583.4,"id":48610314}]}]}
{"op":"mcm","clk":"11931155594","pt":1724272855944,"mc":[{"id":"1.232098082","rc":[{"batb":[[0,3.4,14.57],[1,3,23.53],[2,1.04,1.53]],"ltp":3.6,"tv":75.91,"id":11392436}]}]}
{"op":"mcm","clk":"11931155808","pt":1724272858147,"mc":[{"id":"1.232098082","rc":[{"batb":[[0,3.45,10],[1,3.4,14.57],[2,3,23.53]],"ltp":3.6,"tv":75.91,"id":11392436},{"batb":[[1,1.04,1.53]],"ltp":1.39,"tv":583.4,"id":48610314}]}]}
{"op":"mcm","clk":"11931156159","pt":1724272861534,"mc":[{"id":"1.232098082","rc":[{"batb":[[0,3.4,14.57],[1,3,23.53],[2,1.04,1.53]],"ltp":3.6,"tv":75.91,"id":11392436}]}]}
{"op":"mcm","clk":"11931156434","pt":1724272864326,"mc":[{"id":"1.232098082","rc":[{"batb":[[0,3.45,10],[1,3.4,14.57],[2,3,23.53]],"ltp":3.6,"tv":75.91,"id":11392436}]}]}
{"op":"mcm","clk":"11931156743","pt":1724272867639,"mc":[{"id":"1.232098082","rc":[{"batb":[[0,3.4,14.57],[1,3,23.53],[2,1.04,1.53]],"ltp":3.6,"tv":75.91,"id":11392436}]}]}
{"op":"mcm","clk":"11931156959","pt":1724272870078,"mc":[{"id":"1.232098082","rc":[{"batb":[[0,3.45,10],[1,3.4,14.57],[2,3,23.53]],"ltp":3.6,"tv":75.91,"id":11392436}]}]}
{"op":"mcm","clk":"11931157238","pt":1724272873479,"mc":[{"id":"1.232098082","rc":[{"batb":[[0,3.4,14.57],[1,3,23.53],[2,1.04,1.53]],"ltp":3.6,"tv":75.91,"id":11392436}]}]}
{"op":"mcm","clk":"11931157581","pt":1724272876847,"mc":[{"id":"1.232098082","rc":[{"batb":[[0,3.45,10],[1,3.4,14.57],[2,3,23.53]],"ltp":3.6,"tv":75.91,"id":11392436}]}]}
{"op":"mcm","clk":"11931157917","pt":1724272880151,"mc":[{"id":"1.232098082","rc":[{"batb":[[0,3.4,14.57],[1,3,23.53],[2,1.04,1.53]],"ltp":3.6,"tv":75.91,"id":11392436}]}]}
{"op":"mcm","clk":"11931158347","pt":1724272884656,"mc":[{"id":"1.232098082","rc":[{"batb":[[0,3.45,10],[1,3.4,14.57],[2,3,23.53]],"ltp":3.6,"tv":75.91,"id":11392436}]}]}
{"op":"mcm","clk":"11931158658","pt":1724272888060,"mc":[{"id":"1.232098082","rc":[{"batb":[[0,3.4,14.57],[1,3,23.53],[2,1.04,1.53]],"ltp":3.6,"tv":75.91,"id":11392436}]}]}
{"op":"mcm","clk":"11931158879","pt":1724272890493,"mc":[{"id":"1.232098082","rc":[{"batb":[[0,3.45,10],[1,3.4,14.57],[2,3,23.53]],"ltp":3.6,"tv":75.91,"id":11392436}]}]}
{"op":"mcm","clk":"11931159174","pt":1724272893654,"mc":[{"id":"1.232098082","rc":[{"batb":[[0,3.4,14.57],[1,3,23.53],[2,1.04,1.53]],"ltp":3.6,"tv":75.91,"id":11392436}]}]}
{"op":"mcm","clk":"11931159423","pt":1724272896386,"mc":[{"id":"1.232098082","rc":[{"batb":[[0,3.45,10],[1,3.4,14.57],[2,3,23.53]],"ltp":3.6,"tv":75.91,"id":11392436}]}]}
{"op":"mcm","clk":"11931159708","pt":1724272899798,"mc":[{"id":"1.232098082","rc":[{"batb":[[0,3.4,14.57],[1,3,23.53],[2,1.04,1.53]],"ltp":3.6,"tv":75.91,"id":11392436}]}]}
{"op":"mcm","clk":"11931160082","pt":1724272904190,"mc":[{"id":"1.232098082","rc":[{"batb":[[0,3.45,10],[1,3.4,14.57],[2,3,23.53]],"ltp":3.6,"tv":75.91,"id":11392436}]}]}
{"op":"mcm","clk":"11931160358","pt":1724272907595,"mc":[{"id":"1.232098082","rc":[{"batb":[[0,3.4,14.57],[1,3,23.53],[2,1.04,1.53]],"ltp":3.6,"tv":75.91,"id":11392436}]}]}
{"op":"mcm","clk":"11931160582","pt":1724272910174,"mc":[{"id":"1.232098082","rc":[{"batb":[[0,3.45,10],[1,3.4,14.57],[2,3,23.53]],"ltp":3.6,"tv":75.91,"id":11392436}]}]}
{"op":"mcm","clk":"11931160854","pt":1724272913479,"mc":[{"id":"1.232098082","rc":[{"batb":[[0,3.4,14.57],[1,3,23.53],[2,1.04,1.53]],"ltp":3.6,"tv":75.91,"id":11392436}]}]}
{"op":"mcm","clk":"11931161176","pt":1724272917607,"mc":[{"id":"1.232098082","rc":[{"batb":[[0,3.45,10],[1,3.4,14.57],[2,3,23.53]],"ltp":3.6,"tv":75.91,"id":11392436}]}]}
{"op":"mcm","clk":"11931161471","pt":1724272920915,"mc":[{"id":"1.232098082","rc":[{"batb":[[0,3.4,14.57],[1,3,23.53],[2,1.04,1.53]],"ltp":3.6,"tv":75.91,"id":11392436}]}]}
{"op":"mcm","clk":"11931161680","pt":1724272923409,"mc":[{"id":"1.232098082","rc":[{"batb":[[0,3.45,10],[1,3.4,14.57],[2,3,23.53]],"ltp":3.6,"tv":75.91,"id":11392436}]}]}
{"op":"mcm","clk":"11931161986","pt":1724272926615,"mc":[{"id":"1.232098082","rc":[{"batb":[[0,3.4,14.57],[1,3,23.53],[2,1.04,1.53]],"ltp":3.6,"tv":75.91,"id":11392436}]}]}
{"op":"mcm","clk":"11931162167","pt":1724272928793,"mc":[{"id":"1.232098082","rc":[{"batb":[[0,3.45,10],[1,3.4,14.57],[2,3,23.53]],"ltp":3.6,"tv":75.91,"id":11392436}]}]}
{"op":"mcm","clk":"11931162465","pt":1724272932101,"mc":[{"id":"1.232098082","rc":[{"batb":[[0,3.4,14.57],[1,3,23.53],[2,1.04,1.53]],"ltp":3.6,"tv":75.91,"id":11392436}]}]}
{"op":"mcm","clk":"11931162806","pt":1724272935412,"mc":[{"id":"1.232098082","rc":[{"batb":[[0,3.45,10],[1,3.4,14.57],[2,3,23.53]],"ltp":3.6,"tv":75.91,"id":11392436}]}]}
{"op":"mcm","clk":"11931163091","pt":1724272938628,"mc":[{"id":"1.232098082","rc":[{"batb":[[0,3.4,14.57],[1,3,23.53],[2,1.04,1.53]],"ltp":3.6,"tv":75.91,"id":11392436}]}]}
{"op":"mcm","clk":"11931163560","pt":1724272943506,"mc":[{"id":"1.232098082","rc":[{"batb":[[0,3.45,10],[1,3.4,14.57],[2,3,23.53]],"ltp":3.6,"tv":75.91,"id":11392436}]}]}
{"op":"mcm","clk":"11931163884","pt":1724272946923,"mc":[{"id":"1.232098082","rc":[{"batb":[[0,3.4,14.57],[1,3,23.53],[2,1.04,1.53]],"ltp":3.6,"tv":75.91,"id":11392436}]}]}
{"op":"mcm","clk":"11931164147","pt":1724272950131,"mc":[{"id":"1.232098082","rc":[{"batb":[[0,3.45,10],[1,3.4,14.57],[2,3,23.53]],"ltp":3.6,"tv":75.91,"id":11392436}]}]}
{"op":"mcm","clk":"11931164452","pt":1724272953440,"mc":[{"id":"1.232098082","rc":[{"batb":[[0,3.4,14.57],[1,3,23.53],[2,1.04,1.53]],"ltp":3.6,"tv":75.91,"id":11392436}]}]}
{"op":"mcm","clk":"11931164807","pt":1724272956949,"mc":[{"id":"1.232098082","rc":[{"batb":[[0,3.45,10],[1,3.4,14.57],[2,3,23.53]],"ltp":3.6,"tv":75.91,"id":11392436}]}]}
{"op":"mcm","clk":"11931165099","pt":1724272960458,"mc":[{"id":"1.232098082","rc":[{"batb":[[0,3.4,14.57],[1,3,23.53],[2,1.04,1.53]],"ltp":3.6,"tv":75.91,"id":11392436}]}]}
{"op":"mcm","clk":"11931166057","pt":1724272970740,"mc":[{"id":"1.232098082","rc":[{"batb":[[0,3.45,10],[1,3.4,14.57],[2,3,23.53]],"ltp":3.6,"tv":75.91,"id":11392436}]}]}
{"op":"mcm","clk":"11931166380","pt":1724272974156,"mc":[{"id":"1.232098082","rc":[{"batb":[[0,3.4,14.57],[1,3,23.53],[2,1.04,1.53]],"ltp":3.6,"tv":75.91,"id":11392436}]}]}
{"op":"mcm","clk":"11931166718","pt":1724272978430,"mc":[{"id":"1.232098082","rc":[{"batb":[[0,3.45,10],[1,3.4,14.57],[2,3,23.53]],"ltp":3.6,"tv":75.91,"id":11392436}]}]}
{"op":"mcm","clk":"11931167010","pt":1724272981741,"mc":[{"id":"1.232098082","rc":[{"batb":[[0,3.4,14.57],[1,3,23.53],[2,1.04,1.53]],"ltp":3.6,"tv":75.91,"id":11392436}]}]}
{"op":"mcm","clk":"11931167216","pt":1724272984064,"mc":[{"id":"1.232098082","rc":[{"batb":[[0,3.45,10],[1,3.4,14.57],[2,3,23.53]],"ltp":3.6,"tv":75.91,"id":11392436}]}]}
{"op":"mcm","clk":"11931167534","pt":1724272987370,"mc":[{"id":"1.232098082","rc":[{"batb":[[0,3.4,14.57],[1,3,23.53],[2,1.04,1.53]],"ltp":3.6,"tv":75.91,"id":11392436}]}]}
{"op":"mcm","clk":"11931167862","pt":1724272990577,"mc":[{"id":"1.232098082","rc":[{"batb":[[0,3.45,10],[1,3.4,14.57],[2,3,23.53]],"ltp":3.6,"tv":75.91,"id":11392436}]}]}
{"op":"mcm","clk":"11931168162","pt":1724272993879,"mc":[{"id":"1.232098082","rc":[{"batb":[[0,3.4,14.57],[1,3,23.53],[2,1.04,1.53]],"ltp":3.6,"tv":75.91,"id":11392436}]}]}
{"op":"mcm","clk":"11931168465","pt":1724272996976,"mc":[{"id":"1.232098082","rc":[{"batb":[[0,3.45,10],[1,3.4,14.57],[2,3,23.53]],"ltp":3.6,"tv":75.91,"id":11392436}]}]}
{"op":"mcm","clk":"11931168803","pt":1724273000290,"mc":[{"id":"1.232098082","rc":[{"batb":[[0,3.4,14.57],[1,3,23.53],[2,1.04,1.53]],"ltp":3.6,"tv":75.91,"id":11392436}]}]}
{"op":"mcm","clk":"11931169006","pt":1724273002461,"mc":[{"id":"1.232098082","rc":[{"batb":[[0,3.45,10],[1,3.4,14.57],[2,3,23.53]],"ltp":3.6,"tv":75.91,"id":11392436}]}]}
{"op":"mcm","clk":"11931169304","pt":1724273005868,"mc":[{"id":"1.232098082","rc":[{"batb":[[0,3.4,14.57],[1,3,23.53],[2,1.04,1.53]],"ltp":3.6,"tv":75.91,"id":11392436}]}]}
{"op":"mcm","clk":"11931169516","pt":1724273008290,"mc":[{"id":"1.232098082","rc":[{"batb":[[0,3.45,10],[1,3.4,14.57],[2,3,23.53]],"ltp":3.6,"tv":75.91,"id":11392436}]}]}
{"op":"mcm","clk":"11931169836","pt":1724273011700,"mc":[{"id":"1.232098082","rc":[{"batb":[[0,3.4,14.57],[1,3,23.53],[2,1.04,1.53]],"ltp":3.6,"tv":75.91,"id":11392436}]}]}
{"op":"mcm","clk":"11931170054","pt":1724273013993,"mc":[{"id":"1.232098082","rc":[{"batb":[[0,3.45,10],[1,3.4,14.57],[2,3,23.53]],"ltp":3.6,"tv":75.91,"id":11392436}]}]}
{"op":"mcm","clk":"11931170365","pt":1724273017207,"mc":[{"id":"1.232098082","rc":[{"batb":[[0,3.4,14.57],[1,3,23.53],[2,1.04,1.53]],"ltp":3.6,"tv":75.91,"id":11392436}]}]}
{"op":"mcm","clk":"11931170942","pt":1724273023920,"mc":[{"id":"1.232098082","rc":[{"batb":[[0,3.45,10],[1,3.4,14.57],[2,3,23.53]],"ltp":3.6,"tv":75.91,"id":11392436}]}]}
{"op":"mcm","clk":"11931171250","pt":1724273027219,"mc":[{"id":"1.232098082","rc":[{"batb":[[0,3.4,14.57],[1,3,23.53],[2,1.04,1.53]],"ltp":3.6,"tv":75.91,"id":11392436}]}]}
{"op":"mcm","clk":"11931171604","pt":1724273031509,"mc":[{"id":"1.232098082","rc":[{"batb":[[0,3.45,10],[1,3.4,14.57],[2,3,23.53]],"ltp":3.6,"tv":75.91,"id":11392436}]}]}
{"op":"mcm","clk":"11931171917","pt":1724273034919,"mc":[{"id":"1.232098082","rc":[{"batb":[[0,3.4,14.57],[1,3,23.53],[2,1.04,1.53]],"ltp":3.6,"tv":75.91,"id":11392436}]}]}
{"op":"mcm","clk":"11931172245","pt":1724273038638,"mc":[{"id":"1.232098082","rc":[{"batb":[[0,3.45,10],[1,3.4,14.57],[2,3,23.53]],"ltp":3.6,"tv":75.91,"id":11392436}]}]}
{"op":"mcm","clk":"11931172484","pt":1724273041953,"mc":[{"id":"1.232098082","rc":[{"batb":[[0,3.4,14.57],[1,3,23.53],[2,1.04,1.53]],"ltp":3.6,"tv":75.91,"id":11392436}]}]}
{"op":"mcm","clk":"11931172665","pt":1724273044237,"mc":[{"id":"1.232098082","rc":[{"batb":[[0,3.45,10],[1,3.4,14.57],[2,3,23.53]],"ltp":3.6,"tv":75.91,"id":11392436}]}]}
{"op":"mcm","clk":"11931172987","pt":1724273047711,"mc":[{"id":"1.232098082","rc":[{"batb":[[0,3.4,14.57],[1,3,23.53],[2,1.04,1.53]],"ltp":3.6,"tv":75.91,"id":11392436}]}]}
{"op":"mcm","clk":"11931173250","pt":1724273050535,"mc":[{"id":"1.232098082","rc":[{"batb":[[0,3.45,10],[1,3.4,14.57],[2,3,23.53]],"ltp":3.6,"tv":75.91,"id":11392436}]}]}
{"op":"mcm","clk":"11931173545","pt":1724273054021,"mc":[{"id":"1.232098082","rc":[{"batb":[[0,3.4,14.57],[1,3,23.53],[2,1.04,1.53]],"ltp":3.6,"tv":75.91,"id":11392436}]}]}
{"op":"mcm","clk":"11931173773","pt":1724273056452,"mc":[{"id":"1.232098082","rc":[{"batb":[[0,3.45,10],[1,3.4,14.57],[2,3,23.53]],"ltp":3.6,"tv":75.91,"id":11392436}]}]}
{"op":"mcm","clk":"11931174072","pt":1724273059758,"mc":[{"id":"1.232098082","rc":[{"batb":[[0,3.4,14.57],[1,3,23.53],[2,1.04,1.53]],"ltp":3.6,"tv":75.91,"id":11392436}]}]}
{"op":"mcm","clk":"11931174335","pt":1724273062452,"mc":[{"id":"1.232098082","rc":[{"batb":[[0,3.45,10],[1,3.4,14.57],[2,3,23.53]],"ltp":3.6,"tv":75.91,"id":11392436}]}]}
{"op":"mcm","clk":"11931174633","pt":1724273065826,"mc":[{"id":"1.232098082","rc":[{"batb":[[0,3.4,14.57],[1,3,23.53],[2,1.04,1.53]],"ltp":3.6,"tv":75.91,"id":11392436}]}]}
{"op":"mcm","clk":"11931174832","pt":1724273068556,"mc":[{"id":"1.232098082","rc":[{"batb":[[0,3.45,10],[1,3.4,14.57],[2,3,23.53]],"ltp":3.6,"tv":75.91,"id":11392436}]}]}
{"op":"mcm","clk":"11931175135","pt":1724273071968,"mc":[{"id":"1.232098082","rc":[{"batb":[[0,3.4,14.57],[1,3,23.53],[2,1.04,1.53]],"ltp":3.6,"tv":75.91,"id":11392436}]}]}
{"op":"mcm","clk":"11931175367","pt":1724273074457,"mc":[{"id":"1.232098082","rc":[{"batb":[[0,3.45,10],[1,3.4,14.57],[2,3,23.53]],"ltp":3.6,"tv":75.91,"id":11392436}]}]}
{"op":"mcm","clk":"11931175647","pt":1724273077766,"mc":[{"id":"1.232098082","rc":[{"batb":[[0,3.4,14.57],[1,3,23.53],[2,1.04,1.53]],"ltp":3.6,"tv":75.91,"id":11392436}]}]}
{"op":"mcm","clk":"11931175933","pt":1724273080869,"mc":[{"id":"1.232098082","rc":[{"batb":[[0,3.45,10],[1,3.4,14.57],[2,3,23.53]],"ltp":3.6,"tv":75.91,"id":11392436}]}]}
{"op":"mcm","clk":"11931176184","pt":1724273084077,"mc":[{"id":"1.232098082","rc":[{"batb":[[0,3.4,14.57],[1,3,23.53],[2,1.04,1.53]],"ltp":3.6,"tv":75.91,"id":11392436}]}]}
{"op":"mcm","clk":"11931176399","pt":1724273086557,"mc":[{"id":"1.232098082","rc":[{"batb":[[0,3.45,10],[1,3.4,14.57],[2,3,23.53]],"ltp":3.6,"tv":75.91,"id":11392436}]}]}
{"op":"mcm","clk":"11931176673","pt":1724273089868,"mc":[{"id":"1.232098082","rc":[{"batb":[[0,3.4,14.57],[1,3,23.53],[2,1.04,1.53]],"ltp":3.6,"tv":75.91,"id":11392436}]}]}
{"op":"mcm","clk":"11931176906","pt":1724273092462,"mc":[{"id":"1.232098082","rc":[{"batb":[[0,3.45,10],[1,3.4,14.57],[2,3,23.53]],"ltp":3.6,"tv":75.91,"id":11392436}]}]}
{"op":"mcm","clk":"11931177208","pt":1724273095868,"mc":[{"id":"1.232098082","rc":[{"batb":[[0,3.4,14.57],[1,3,23.53],[2,1.04,1.53]],"ltp":3.6,"tv":75.91,"id":11392436}]}]}
{"op":"mcm","clk":"11931177411","pt":1724273098500,"mc":[{"id":"1.232098082","rc":[{"batb":[[0,3.45,10],[1,3.4,14.57],[2,3,23.53]],"ltp":3.6,"tv":75.91,"id":11392436}]}]}
{"op":"mcm","clk":"11931177731","pt":1724273101874,"mc":[{"id":"1.232098082","rc":[{"batb":[[0,3.4,14.57],[1,3,23.53],[2,1.04,1.53]],"ltp":3.6,"tv":75.91,"id":11392436}]}]}
{"op":"mcm","clk":"11931178110","pt":1724273106109,"mc":[{"id":"1.232098082","rc":[{"batb":[[0,3.45,10],[1,3.4,14.57],[2,3,23.53]],"ltp":3.6,"tv":75.91,"id":11392436}]}]}
{"op":"mcm","clk":"11931178391","pt":1724273109388,"mc":[{"id":"1.232098082","rc":[{"batb":[[0,3.4,14.57],[1,3,23.53],[2,1.04,1.53]],"ltp":3.6,"tv":75.91,"id":11392436}]}]}
{"op":"mcm","clk":"11931178843","pt":1724273114085,"mc":[{"id":"1.232098082","rc":[{"batb":[[0,3.45,10],[1,3.4,14.57],[2,3,23.53]],"ltp":3.6,"tv":75.91,"id":11392436}]}]}
{"op":"mcm","clk":"11931179154","pt":1724273117394,"mc":[{"id":"1.232098082","rc":[{"batb":[[0,3.4,14.57],[1,3,23.53],[2,1.04,1.53]],"ltp":3.6,"tv":75.91,"id":11392436}]}]}
{"op":"mcm","clk":"11931179405","pt":1724273119609,"mc":[{"id":"1.232098082","rc":[{"batb":[[0,3.45,10],[1,3.4,14.57],[2,3,23.53]],"ltp":3.6,"tv":75.91,"id":11392436}]}]}
{"op":"mcm","clk":"11931179710","pt":1724273122926,"mc":[{"id":"1.232098082","rc":[{"batb":[[0,3.4,14.57],[1,3,23.53],[2,1.04,1.53]],"ltp":3.6,"tv":75.91,"id":11392436}]}]}
{"op":"mcm","clk":"11931179932","pt":1724273125612,"mc":[{"id":"1.232098082","rc":[{"batb":[[0,3.45,10],[1,3.4,14.57],[2,3,23.53]],"ltp":3.6,"tv":75.91,"id":11392436}]}]}
{"op":"mcm","clk":"11931180232","pt":1724273129022,"mc":[{"id":"1.232098082","rc":[{"batb":[[0,3.4,14.57],[1,3,23.53],[2,1.04,1.53]],"ltp":3.6,"tv":75.91,"id":11392436}]}]}
{"op":"mcm","clk":"11931180596","pt":1724273133011,"mc":[{"id":"1.232098082","rc":[{"batb":[[0,3.45,10],[1,3.4,14.57],[2,3,23.53]],"ltp":3.6,"tv":75.91,"id":11392436}]}]}
{"op":"mcm","clk":"11931180884","pt":1724273136220,"mc":[{"id":"1.232098082","rc":[{"batb":[[0,3.4,14.57],[1,3,23.53],[2,1.04,1.53]],"ltp":3.6,"tv":75.91,"id":11392436}]}]}
{"op":"mcm","clk":"11931181166","pt":1724273139341,"mc":[{"id":"1.232098082","rc":[{"batb":[[0,3.45,10],[1,3.4,14.57],[2,3,23.53]],"ltp":3.6,"tv":75.91,"id":11392436}]}]}
{"op":"mcm","clk":"11931181439","pt":1724273142739,"mc":[{"id":"1.232098082","rc":[{"batb":[[0,3.4,14.57],[1,3,23.53],[2,1.04,1.53]],"ltp":3.6,"tv":75.91,"id":11392436}]}]}
{"op":"mcm","clk":"11931181646","pt":1724273145023,"mc":[{"id":"1.232098082","rc":[{"batb":[[0,3.45,10],[1,3.4,14.57],[2,3,23.53]],"ltp":3.6,"tv":75.91,"id":11392436}]}]}
{"op":"mcm","clk":"11931181897","pt":1724273148262,"mc":[{"id":"1.232098082","rc":[{"batb":[[0,3.4,14.57],[1,3,23.53],[2,1.04,1.53]],"ltp":3.6,"tv":75.91,"id":11392436}]}]}
{"op":"mcm","clk":"11931182255","pt":1724273152546,"mc":[{"id":"1.232098082","rc":[{"batb":[[0,3.45,10],[1,3.4,14.57],[2,3,23.53]],"ltp":3.6,"tv":75.91,"id":11392436}]}]}
{"op":"mcm","clk":"11931182540","pt":1724273155851,"mc":[{"id":"1.232098082","rc":[{"batb":[[0,3.4,14.57],[1,3,23.53],[2,1.04,1.53]],"ltp":3.6,"tv":75.91,"id":11392436}]}]}
{"op":"mcm","clk":"11931182741","pt":1724273158278,"mc":[{"id":"1.232098082","rc":[{"batb":[[0,3.45,10],[1,3.4,14.57],[2,3,23.53]],"ltp":3.6,"tv":75.91,"id":11392436}]}]}
{"op":"mcm","clk":"11931183059","pt":1724273161450,"mc":[{"id":"1.232098082","rc":[{"batb":[[0,3.4,14.57],[1,3,23.53],[2,1.04,1.53]],"ltp":3.6,"tv":75.91,"id":11392436}]}]}
{"op":"mcm","clk":"11931183288","pt":1724273163789,"mc":[{"id":"1.232098082","rc":[{"batb":[[0,3.45,10],[1,3.4,14.57],[2,3,23.53]],"ltp":3.6,"tv":75.91,"id":11392436}]}]}
{"op":"mcm","clk":"11931183613","pt":1724273167549,"mc":[{"id":"1.232098082","rc":[{"batb":[[0,3.4,14.57],[1,3,23.53],[2,1.04,1.53]],"ltp":3.6,"tv":75.91,"id":11392436}]}]}
{"op":"mcm","clk":"11931183901","pt":1724273171162,"mc":[{"id":"1.232098082","rc":[{"batb":[[0,3.45,10],[1,3.4,14.57],[2,3,23.53]],"ltp":3.6,"tv":75.91,"id":11392436}]}]}
{"op":"mcm","clk":"11931184165","pt":1724273174479,"mc":[{"id":"1.232098082","rc":[{"batb":[[0,3.4,14.57],[1,3,23.53],[2,1.04,1.53]],"ltp":3.6,"tv":75.91,"id":11392436}]}]}
{"op":"mcm","clk":"11931184435","pt":1724273177691,"mc":[{"id":"1.232098082","rc":[{"batb":[[0,3.45,10],[1,3.4,14.57],[2,3,23.53]],"batl":[[0,24,0.76],[1,30,0]],"ltp":3.6,"tv":75.91,"id":11392436},{"batl":[[2,24,0.76]],"ltp":1.39,"tv":583.4,"id":48610314}]}]}
{"op":"mcm","clk":"11931184520","pt":1724273178679,"mc":[{"id":"1.232098082","rc":[{"batb":[[1,3,23.53],[2,1.04,1.53]],"ltp":3.6,"tv":75.91,"id":11392436}]}]}
{"op":"mcm","clk":"11931184707","pt":1724273180685,"mc":[{"id":"1.232098082","rc":[{"batb":[[0,3,23.53],[1,1.04,1.53],[2,1.03,200]],"ltp":3.6,"tv":75.91,"id":11392436}]}]}
{"op":"mcm","clk":"11931184984","pt":1724273183788,"mc":[{"id":"1.232098082","rc":[{"batb":[[0,3.05,10],[1,3,23.53],[2,1.04,1.53]],"ltp":3.6,"tv":75.91,"id":11392436}]}]}
{"op":"mcm","clk":"11931185320","pt":1724273187210,"mc":[{"id":"1.232098082","rc":[{"batb":[[0,3,23.53],[1,1.04,1.53],[2,1.03,200]],"ltp":3.6,"tv":75.91,"id":11392436}]}]}
{"op":"mcm","clk":"11931185510","pt":1724273189391,"mc":[{"id":"1.232098082","rc":[{"batb":[[0,3.05,10],[1,3,23.53],[2,1.04,1.53]],"ltp":3.6,"tv":75.91,"id":11392436}]}]}
{"op":"mcm","clk":"11931185806","pt":1724273192798,"mc":[{"id":"1.232098082","rc":[{"batb":[[0,3,23.53],[1,1.04,1.53],[2,1.03,200]],"ltp":3.6,"tv":75.91,"id":11392436}]}]}
{"op":"mcm","clk":"11931186095","pt":1724273196203,"mc":[{"id":"1.232098082","rc":[{"batb":[[0,3.05,10],[1,3,23.53],[2,1.04,1.53]],"ltp":3.6,"tv":75.91,"id":11392436}]}]}
{"op":"mcm","clk":"11931186360","pt":1724273199528,"mc":[{"id":"1.232098082","rc":[{"batb":[[0,3,23.53],[1,1.04,1.53],[2,1.03,200]],"ltp":3.6,"tv":75.91,"id":11392436}]}]}
{"op":"mcm","clk":"11931186551","pt":1724273201802,"mc":[{"id":"1.232098082","rc":[{"batb":[[0,3.05,10],[1,3,23.53],[2,1.04,1.53]],"ltp":3.6,"tv":75.91,"id":11392436}]}]}
{"op":"mcm","clk":"11931186865","pt":1724273205320,"mc":[{"id":"1.232098082","rc":[{"batb":[[0,3,23.53],[1,1.04,1.53],[2,1.03,200]],"ltp":3.6,"tv":75.91,"id":11392436}]}]}
{"op":"mcm","clk":"11931187025","pt":1724273207628,"mc":[{"id":"1.232098082","rc":[{"batb":[[0,3.05,10],[1,3,23.53],[2,1.04,1.53]],"ltp":3.6,"tv":75.91,"id":11392436}]}]}
{"op":"mcm","clk":"11931187301","pt":1724273211030,"mc":[{"id":"1.232098082","rc":[{"batb":[[0,3,23.53],[1,1.04,1.53],[2,1.03,200]],"ltp":3.6,"tv":75.91,"id":11392436}]}]}
{"op":"mcm","clk":"11931187502","pt":1724273213419,"mc":[{"id":"1.232098082","rc":[{"batb":[[0,3.05,10],[1,3,23.53],[2,1.04,1.53]],"ltp":3.6,"tv":75.91,"id":11392436}]}]}
{"op":"mcm","clk":"11931187782","pt":1724273216720,"mc":[{"id":"1.232098082","rc":[{"batb":[[0,3,23.53],[1,1.04,1.53],[2,1.03,200]],"ltp":3.6,"tv":75.91,"id":11392436}]}]}
{"op":"mcm","clk":"11931188160","pt":1724273221120,"mc":[{"id":"1.232098082","rc":[{"batb":[[0,3.05,10],[1,3,23.53],[2,1.04,1.53]],"ltp":3.6,"tv":75.91,"id":11392436}]}]}
{"op":"mcm","clk":"11931188496","pt":1724273224536,"mc":[{"id":"1.232098082","rc":[{"batb":[[0,3,23.53],[1,1.04,1.53],[2,1.03,200]],"ltp":3.6,"tv":75.91,"id":11392436}]}]}
{"op":"mcm","clk":"11931188695","pt":1724273226855,"mc":[{"id":"1.232098082","rc":[{"batb":[[0,3.05,10],[1,3,23.53],[2,1.04,1.53]],"ltp":3.6,"tv":75.91,"id":11392436}]}]}
{"op":"mcm","clk":"11931188993","pt":1724273230237,"mc":[{"id":"1.232098082","rc":[{"batb":[[0,3,23.53],[1,1.04,1.53],[2,1.03,200]],"ltp":3.6,"tv":75.91,"id":11392436}]}]}
{"op":"mcm","clk":"11931189193","pt":1724273232527,"mc":[{"id":"1.232098082","rc":[{"batb":[[0,3.05,10],[1,3,23.53],[2,1.04,1.53]],"ltp":3.6,"tv":75.91,"id":11392436}]}]}
{"op":"mcm","clk":"11931189491","pt":1724273235837,"mc":[{"id":"1.232098082","rc":[{"batb":[[0,3,23.53],[1,1.04,1.53],[2,1.03,200]],"ltp":3.6,"tv":75.91,"id":11392436}]}]}
{"op":"mcm","clk":"11931189780","pt":1724273238851,"mc":[{"id":"1.232098082","rc":[{"batb":[[0,3.05,10],[1,3,23.53],[2,1.04,1.53]],"ltp":3.6,"tv":75.91,"id":11392436}]}]}
{"op":"mcm","clk":"11931190045","pt":1724273242158,"mc":[{"id":"1.232098082","rc":[{"batb":[[0,3,23.53],[1,1.04,1.53],[2,1.03,200]],"ltp":3.6,"tv":75.91,"id":11392436}]}]}
{"op":"mcm","clk":"11931190249","pt":1724273244437,"mc":[{"id":"1.232098082","rc":[{"batb":[[0,3.05,10],[1,3,23.53],[2,1.04,1.53]],"ltp":3.6,"tv":75.91,"id":11392436}]}]}
{"op":"mcm","clk":"11931190517","pt":1724273247757,"mc":[{"id":"1.232098082","rc":[{"batb":[[0,3,23.53],[1,1.04,1.53],[2,1.03,200]],"ltp":3.6,"tv":75.91,"id":11392436}]}]}
{"op":"mcm","clk":"11931190838","pt":1724273251374,"mc":[{"id":"1.232098082","rc":[{"batb":[[0,3.05,10],[1,3,23.53],[2,1.04,1.53]],"ltp":3.6,"tv":75.91,"id":11392436}]}]}
{"op":"mcm","clk":"11931191194","pt":1724273254877,"mc":[{"id":"1.232098082","rc":[{"batb":[[0,3,23.53],[1,1.04,1.53],[2,1.03,200]],"ltp":3.6,"tv":75.91,"id":11392436}]}]}
{"op":"mcm","clk":"11931191547","pt":1724273259268,"mc":[{"id":"1.232098082","rc":[{"batb":[[0,3.05,10],[1,3,23.53],[2,1.04,1.53]],"ltp":3.6,"tv":75.91,"id":11392436}]}]}
{"op":"mcm","clk":"11931191829","pt":1724273262575,"mc":[{"id":"1.232098082","rc":[{"batb":[[0,3,23.53],[1,1.04,1.53],[2,1.03,200]],"ltp":3.6,"tv":75.91,"id":11392436}]}]}
{"op":"mcm","clk":"11931192032","pt":1724273264997,"mc":[{"id":"1.232098082","rc":[{"batb":[[0,3.05,10],[1,3,23.53],[2,1.04,1.53]],"ltp":3.6,"tv":75.91,"id":11392436}]}]}
{"op":"mcm","clk":"11931192308","pt":1724273268393,"mc":[{"id":"1.232098082","rc":[{"batb":[[0,3,23.53],[1,1.04,1.53],[2,1.03,200]],"ltp":3.6,"tv":75.91,"id":11392436}]}]}
{"op":"mcm","clk":"11931192514","pt":1724273270711,"mc":[{"id":"1.232098082","rc":[{"batb":[[0,3.05,10],[1,3,23.53],[2,1.04,1.53]],"ltp":3.6,"tv":75.91,"id":11392436}]}]}
{"op":"mcm","clk":"11931192824","pt":1724273274072,"mc":[{"id":"1.232098082","rc":[{"batb":[[0,3,23.53],[1,1.04,1.53],[2,1.03,200]],"ltp":3.6,"tv":75.91,"id":11392436}]}]}
{"op":"mcm","clk":"11931193079","pt":1724273276908,"mc":[{"id":"1.232098082","rc":[{"batb":[[0,3.05,10],[1,3,23.53],[2,1.04,1.53]],"ltp":3.6,"tv":75.91,"id":11392436}]}]}
{"op":"mcm","clk":"11931193370","pt":1724273280203,"mc":[{"id":"1.232098082","rc":[{"batb":[[0,3,23.53],[1,1.04,1.53],[2,1.03,200]],"ltp":3.6,"tv":75.91,"id":11392436}]}]}
{"op":"mcm","clk":"11931193618","pt":1724273282891,"mc":[{"id":"1.232098082","rc":[{"batb":[[0,3.05,10],[1,3,23.53],[2,1.04,1.53]],"ltp":3.6,"tv":75.91,"id":11392436}]}]}
{"op":"mcm","clk":"11931193910","pt":1724273286187,"mc":[{"id":"1.232098082","rc":[{"batb":[[0,3,23.53],[1,1.04,1.53],[2,1.03,200]],"ltp":3.6,"tv":75.91,"id":11392436}]}]}
{"op":"mcm","clk":"11931194371","pt":1724273292019,"mc":[{"id":"1.232098082","rc":[{"batb":[[0,3.05,10],[1,3,23.53],[2,1.04,1.53]],"ltp":3.6,"tv":75.91,"id":11392436}]}]}
{"op":"mcm","clk":"11931194607","pt":1724273295211,"mc":[{"id":"1.232098082","rc":[{"batb":[[0,3,23.53],[1,1.04,1.53],[2,1.03,200]],"ltp":3.6,"tv":75.91,"id":11392436}]}]}
{"op":"mcm","clk":"11931194814","pt":1724273297897,"mc":[{"id":"1.232098082","rc":[{"batb":[[0,3.05,10],[1,3,23.53],[2,1.04,1.53]],"ltp":3.6,"tv":75.91,"id":11392436}]}]}
{"op":"mcm","clk":"11931195084","pt":1724273301136,"mc":[{"id":"1.232098082","rc":[{"batb":[[0,3,23.53],[1,1.04,1.53],[2,1.03,200]],"ltp":3.6,"tv":75.91,"id":11392436}]}]}
{"op":"mcm","clk":"11931195295","pt":1724273303820,"mc":[{"id":"1.232098082","rc":[{"batb":[[0,3.05,10],[1,3,23.53],[2,1.04,1.53]],"ltp":3.6,"tv":75.91,"id":11392436}]}]}
{"op":"mcm","clk":"11931195587","pt":1724273307118,"mc":[{"id":"1.232098082","rc":[{"batb":[[0,3,23.53],[1,1.04,1.53],[2,1.03,200]],"ltp":3.6,"tv":75.91,"id":11392436}]}]}
{"op":"mcm","clk":"11931195914","pt":1724273311619,"mc":[{"id":"1.232098082","rc":[{"batb":[[0,3.05,10],[1,3,23.53],[2,1.04,1.53]],"ltp":3.6,"tv":75.91,"id":11392436}]}]}
{"op":"mcm","clk":"11931196159","pt":1724273315009,"mc":[{"id":"1.232098082","rc":[{"batb":[[0,3,23.53],[1,1.04,1.53],[2,1.03,200]],"ltp":3.6,"tv":75.91,"id":11392436}]}]}
{"op":"mcm","clk":"11931196362","pt":1724273317737,"mc":[{"id":"1.232098082","rc":[{"batb":[[0,3.05,10],[1,3,23.53],[2,1.04,1.53]],"ltp":3.6,"tv":75.91,"id":11392436}]}]}
{"op":"mcm","clk":"11931196585","pt":1724273321036,"mc":[{"id":"1.232098082","rc":[{"batb":[[0,3,23.53],[1,1.04,1.53],[2,1.03,200]],"ltp":3.6,"tv":75.91,"id":11392436}]}]}
{"op":"mcm","clk":"11931196778","pt":1724273323918,"mc":[{"id":"1.232098082","rc":[{"batb":[[0,3.05,10],[1,3,23.53],[2,1.04,1.53]],"ltp":3.6,"tv":75.91,"id":11392436}]}]}
{"op":"mcm","clk":"11931197036","pt":1724273327319,"mc":[{"id":"1.232098082","rc":[{"batb":[[0,3,23.53],[1,1.04,1.53],[2,1.03,200]],"ltp":3.6,"tv":75.91,"id":11392436}]}]}
{"op":"mcm","clk":"11931197230","pt":1724273330851,"mc":[{"id":"1.232098082","rc":[{"batb":[[0,3.05,10],[1,3,23.53],[2,1.04,1.53]],"ltp":3.6,"tv":75.91,"id":11392436}]}]}
{"op":"mcm","clk":"11931197432","pt":1724273334240,"mc":[{"id":"1.232098082","rc":[{"batb":[[0,3,23.53],[1,1.04,1.53],[2,1.03,200]],"ltp":3.6,"tv":75.91,"id":11392436}]}]}
{"op":"mcm","clk":"11931197595","pt":1724273336565,"mc":[{"id":"1.232098082","rc":[{"batb":[[0,3.05,10],[1,3,23.53],[2,1.04,1.53]],"ltp":3.6,"tv":75.91,"id":11392436}]}]}
{"op":"mcm","clk":"11931197841","pt":1724273339928,"mc":[{"id":"1.232098082","rc":[{"batb":[[0,3,23.53],[1,1.04,1.53],[2,1.03,200]],"ltp":3.6,"tv":75.91,"id":11392436}]}]}
{"op":"mcm","clk":"11931198091","pt":1724273343024,"mc":[{"id":"1.232098082","rc":[{"batb":[[0,3.05,10],[1,3,23.53],[2,1.04,1.53]],"ltp":3.6,"tv":75.91,"id":11392436}]}]}
