{"op":"mcm","clk":"11822805810","pt":1722941171613,"mc":[{"id":"1.231501647","marketDefinition":{"bspMarket":false,"turnInPlayEnabled":true,"persistenceEnabled":true,"marketBaseRate":5.0,"eventId":"33472580","eventTypeId":"4","numberOfWinners":1,"bettingType":"ODDS","marketType":"MATCH_ODDS","marketTime":"2024-08-08T10:30:00.000Z","suspendTime":"2024-08-08T10:30:00.000Z","bspReconciled":false,"complete":true,"inPlay":false,"crossMatching":true,"runnersVoidable":false,"numberOfActiveRunners":2,"betDelay":0,"status":"OPEN","runners":[{"status":"ACTIVE","sortPriority":1,"id":40096581,"name":"Welsh Fire Women"},{"status":"ACTIVE","sortPriority":2,"id":40096589,"name":"Northern Superchargers Women"}],"regulators":["MR_INT"],"countryCode":"GB","discountAllowed":false,"timezone":"GMT","openDate":"2024-08-08T10:30:00.000Z","version":6059504840,"name":"Match Odds","eventName":"Welsh Fire Women v Northern Superchargers Women"},"rc":[{"batb":[[0,1.03,200],[1,1.02,200],[2,1.01,220]],"ltp":0.0,"tv":0.0,"id":40096589},{"batb":[[0,1.03,200],[1,1.02,200],[2,1.01,220]],"ltp":0.0,"tv":0.0,"id":40096581}]}]}
{"op":"mcm","clk":"11822805933","pt":1722941172894,"mc":[{"id":"1.231501647","marketDefinition":{"bspMarket":false,"turnInPlayEnabled":true,"persistenceEnabled":true,"marketBaseRate":5.0,"eventId":"33472580","eventTypeId":"4","numberOfWinners":1,"bettingType":"ODDS","marketType":"MATCH_ODDS","marketTime":"2024-08-08T10:30:00.000Z","suspendTime":"2024-08-08T10:30:00.000Z","bspReconciled":false,"complete":true,"inPlay":false,"crossMatching":true,"runnersVoidable":false,"numberOfActiveRunners":2,"betDelay":0,"status":"OPEN","runners":[{"status":"ACTIVE","sortPriority":1,"id":40096581,"name":"Welsh Fire Women"},{"status":"ACTIVE","sortPriority":2,"id":40096589,"name":"Northern Superchargers Women"}],"regulators":["MR_INT"],"countryCode":"GB","discountAllowed":true,"timezone":"GMT","openDate":"2024-08-08T10:30:00.000Z","version":6059504840,"name":"Match Odds","eventName":"Welsh Fire Women v Northern Superchargers Women"}}]}
{"op":"mcm","clk":"11822900831","pt":1722942333573,"mc":[{"id":"1.231501647","rc":[{"batb":[[2,1.01,2220]],"ltp":0.0,"tv":0.0,"id":40096589},{"batb":[[2,1.01,2220]],"ltp":0.0,"tv":0.0,"id":40096581}]}]}
{"op":"mcm","clk":"11823022277","pt":1722943836375,"mc":[{"id":"1.231501647","rc":[{"batb":[[2,1.01,2480.82]],"ltp":0.0,"tv":0.0,"id":40096589},{"batb":[[2,1.01,2480.82]],"ltp":0.0,"tv":0.0,"id":40096581}]}]}
{"op":"mcm","clk":"11823333444","pt":1722948175003,"mc":[{"id":"1.231501647","rc":[{"batb":[[2,1.01,2480.12]],"ltp":0.0,"tv":0.0,"id":40096589},{"batb":[[2,1.01,2480.12]],"ltp":0.0,"tv":0.0,"id":40096581}]}]}
{"op":"mcm","clk":"11823434270","pt":1722949579617,"mc":[{"id":"1.231501647","rc":[{"batb":[[2,1.01,2480.38]],"ltp":0.0,"tv":0.0,"id":40096589},{"batb":[[2,1.01,9815.34]],"ltp":0.0,"tv":0.0,"id":40096581}]}]}
{"op":"mcm","clk":"11823434855","pt":1722949587546,"mc":[{"id":"1.231501647","rc":[{"batb":[[2,1.01,9815.34]],"ltp":0.0,"tv":0.0,"id":40096589}]}]}
{"op":"mcm","clk":"11823728208","pt":1722953574994,"mc":[{"id":"1.231501647","rc":[{"batb":[[2,1.01,9804.92]],"ltp":0.0,"tv":0.0,"id":40096589},{"batb":[[2,1.01,9804.92]],"ltp":0.0,"tv":0.0,"id":40096581}]}]}
{"op":"mcm","clk":"11823861209","pt":1722955180057,"mc":[{"id":"1.231501647","rc":[{"batb":[[2,1.01,9805.87]],"ltp":0.0,"tv":0.0,"id":40096589},{"batb":[[2,1.01,9805.87]],"ltp":0.0,"tv":0.0,"id":40096581}]}]}
{"op":"mcm","clk":"11823862058","pt":1722955191378,"mc":[{"id":"1.231501647","rc":[{"batb":[[1,1.02,200.79]],"ltp":0.0,"tv":0.0,"id":40096589},{"batb":[[1,1.02,200.79]],"ltp":0.0,"tv":0.0,"id":40096581}]}]}
{"op":"mcm","clk":"11823863122","pt":1722955205186,"mc":[{"id":"1.231501647","rc":[{"batb":[[0,1.02,201.58],[1,1.01,9805.87],[2,1.01,0]],"ltp":0.0,"tv":0.0,"id":40096589},{"batb":[[0,1.02,201.58],[1,1.01,9805.87],[2,1.01,0]],"ltp":0.0,"tv":0.0,"id":40096581}]}]}
{"op":"mcm","clk":"11823863877","pt":1722955215305,"mc":[{"id":"1.231501647","rc":[{"batb":[[0,1.03,1.58],[1,1.02,200.79],[2,1.01,9805.87]],"ltp":0.0,"tv":0.0,"id":40096589},{"batb":[[0,1.03,1.58],[1,1.02,200.79],[2,1.01,9805.87]],"ltp":0.0,"tv":0.0,"id":40096581}]}]}
{"op":"mcm","clk":"11823864709","pt":1722955225114,"mc":[{"id":"1.231501647","rc":[{"batb":[[0,1.04,1.58],[1,1.02,201.58]],"ltp":0.0,"tv":0.0,"id":40096589},{"batb":[[0,1.04,1.58],[1,1.02,201.58]],"ltp":0.0,"tv":0.0,"id":40096581}]}]}
{"op":"mcm","clk":"11824021967","pt":1722957185847,"mc":[{"id":"1.231501647","rc":[{"batb":[[0,1.1,25000],[1,1.08,10000],[2,1.07,10000]],"ltp":0.0,"tv":0.0,"id":40096589},{"batb":[[0,1.1,25000],[1,1.08,10000],[2,1.07,10000]],"ltp":0.0,"tv":0.0,"id":40096581}]}]}
{"op":"mcm","clk":"11824021990","pt":1722957186008,"mc":[{"id":"1.231501647","rc":[{"batb":[[1,1.09,25000],[2,1.08,25000]],"ltp":0.0,"tv":0.0,"id":40096589},{"batb":[[1,1.09,25000],[2,1.08,25000]],"ltp":0.0,"tv":0.0,"id":40096581}]}]}
{"op":"mcm","clk":"11824287369","pt":1722959797727,"mc":[{"id":"1.231501647","rc":[{"batb":[[0,1.5,138.46],[1,1.1,25000],[2,1.09,25000]],"ltp":0.0,"tv":0.0,"id":40096581}]}]}
{"op":"mcm","clk":"11824288575","pt":1722959809047,"mc":[{"id":"1.231501647","rc":[{"batb":[[0,1.5,138.46],[1,1.1,25000],[2,1.09,25000]],"ltp":0.0,"tv":0.0,"id":40096589}]}]}
{"op":"mcm","clk":"11824395377","pt":1722960746249,"mc":[{"id":"1.231501647","rc":[{"batb":[[1,1.25,100],[2,1.1,25000]],"ltp":0.0,"tv":0.0,"id":40096589},{"batb":[[1,1.25,100],[2,1.1,25000]],"ltp":0.0,"tv":0.0,"id":40096581}]}]}
{"op":"mcm","clk":"11824411406","pt":1722960892358,"mc":[{"id":"1.231501647","rc":[{"batb":[[0,1.51,16.96],[1,1.5,138.46],[2,1.25,100]],"ltp":0.0,"tv":0.0,"id":40096589},{"batb":[[0,1.51,16.96],[1,1.5,138.46],[2,1.25,100]],"ltp":0.0,"tv":0.0,"id":40096581}]}]}
{"op":"mcm","clk":"11824433092","pt":1722961091587,"mc":[{"id":"1.231501647","rc":[{"batb":[[0,1.51,23.1]],"ltp":0.0,"tv":0.0,"id":40096581}]}]}
{"op":"mcm","clk":"11824433126","pt":1722961091890,"mc":[{"id":"1.231501647","rc":[{"batb":[[0,1.51,23.84]],"ltp":0.0,"tv":0.0,"id":40096589}]}]}
{"op":"mcm","clk":"11824474656","pt":1722961484229,"mc":[{"id":"1.231501647","rc":[{"batb":[[1,1.25,100],[2,1.1,25000]],"ltp":0.0,"tv":0.0,"id":40096589},{"batb":[[1,1.25,100],[2,1.1,25000]],"ltp":0.0,"tv":0.0,"id":40096581}]}]}
{"op":"mcm","clk":"11824496576","pt":1722961697312,"mc":[{"id":"1.231501647","rc":[{"batl":[[0,1.9,75]],"ltp":0.0,"tv":0.0,"id":40096581}]}]}
{"op":"mcm","clk":"11824594536","pt":1722962692838,"mc":[{"id":"1.231501647","rc":[{"batb":[[0,1.51,6.88]],"ltp":0.0,"tv":0.0,"id":40096589},{"batb":[[0,1.51,6.14]],"ltp":0.0,"tv":0.0,"id":40096581}]}]}
{"op":"mcm","clk":"11824602408","pt":1722962770420,"mc":[{"id":"1.231501647","rc":[{"batb":[[0,1.25,100],[1,1.1,25000],[2,1.09,25000]],"ltp":0.0,"tv":0.0,"id":40096589},{"batb":[[0,1.26,6.14]],"ltp":0.0,"tv":0.0,"id":40096581}]}]}
{"op":"mcm","clk":"11824614873","pt":1722962898209,"mc":[{"id":"1.231501647","rc":[{"batb":[[0,2.12,7.72],[1,1.25,100],[2,1.1,25000]],"ltp":0.0,"tv":0.0,"id":40096589},{"batb":[[0,1.27,32.04],[1,1.26,6.14],[2,1.25,100]],"ltp":0.0,"tv":0.0,"id":40096581}]}]}
{"op":"mcm","clk":"11824684721","pt":1722963717198,"mc":[{"id":"1.231501647","rc":[{"batb":[[0,2.12,7.72]],"ltp":0.0,"tv":0.0,"id":40096589},{"batb":[[0,1.56,138.46],[1,1.27,32.01],[2,1.26,6.13]],"ltp":0.0,"tv":0.0,"id":40096581}]}]}
{"op":"mcm","clk":"11824688404","pt":1722963759104,"mc":[{"id":"1.231501647","rc":[{"batl":[[0,1.9,75.13]],"ltp":0.0,"tv":0.0,"id":40096581}]}]}
{"op":"mcm","clk":"11824691636","pt":1722963795949,"mc":[{"id":"1.231501647","rc":[{"batl":[[0,2.76,0.13]],"ltp":0.0,"tv":0.0,"id":40096589}]}]}
{"op":"mcm","clk":"11824699496","pt":1722963884073,"mc":[{"id":"1.231501647","rc":[{"batl":[[0,1.9,75]],"ltp":0.0,"tv":0.0,"id":40096581}]}]}
{"op":"mcm","clk":"11824755879","pt":1722964375862,"mc":[{"id":"1.231501647","rc":[{"trd":[[2.12,7.17]],"batb":[[0,1.25,100.55],[1,1.1,25000],[2,1.09,25000]],"ltp":2.12,"tv":7.16,"id":40096589},{"trd":[[1.9,158]],"ltp":1.9,"tv":158.0,"id":40096581}],"tv":165.16}]}
{"op":"mcm","clk":"11824757680","pt":1722964394687,"mc":[{"id":"1.231501647","rc":[{"batb":[[0,1.81,333],[1,1.56,138.46],[2,1.27,32.01]],"ltp":1.9,"tv":158.0,"id":40096581}]}]}
{"op":"mcm","clk":"11824760597","pt":1722964424739,"mc":[{"id":"1.231501647","rc":[{"batb":[[0,1.85,111.55],[1,1.25,100],[2,1.1,25000]],"ltp":2.12,"tv":7.16,"id":40096589}]}]}
{"op":"mcm","clk":"11824763596","pt":1722964457240,"mc":[{"id":"1.231501647","rc":[{"batb":[[0,1.82,6.13],[1,1.81,333],[2,1.56,138.46]],"ltp":1.9,"tv":158.0,"id":40096581}]}]}
{"op":"mcm","clk":"11824787927","pt":1722964698647,"mc":[{"id":"1.231501647","rc":[{"batb":[[0,1.85,111]],"ltp":2.12,"tv":7.16,"id":40096589}]}]}
{"op":"mcm","clk":"11824825568","pt":1722965130730,"mc":[{"id":"1.231501647","rc":[{"batl":[[0,2.22,13.46]],"ltp":2.12,"tv":7.16,"id":40096589},{"batb":[[0,1.82,22.78]],"ltp":1.9,"tv":158.0,"id":40096581}]}]}
{"op":"mcm","clk":"11824825587","pt":1722965130894,"mc":[{"id":"1.231501647","rc":[{"batb":[[0,1.86,10],[1,1.85,111],[2,1.25,100]],"ltp":2.12,"tv":7.16,"id":40096589}]}]}
{"op":"mcm","clk":"11824825854","pt":1722965134340,"mc":[{"id":"1.231501647","rc":[{"batb":[[0,1.85,111],[1,1.25,100],[2,1.1,25000]],"ltp":2.12,"tv":7.16,"id":40096589}]}]}
{"op":"mcm","clk":"11824827069","pt":1722965149632,"mc":[{"id":"1.231501647","rc":[{"batb":[[0,1.86,5.45],[1,1.85,111],[2,1.25,100]],"ltp":2.12,"tv":7.16,"id":40096589},{"batl":[[0,2.16,4.63]],"ltp":1.9,"tv":158.0,"id":40096581}]}]}
{"op":"mcm","clk":"11824827110","pt":1722965150146,"mc":[{"id":"1.231501647","rc":[{"batb":[[0,1.87,10],[1,1.86,5.45],[2,1.85,111]],"ltp":2.12,"tv":7.16,"id":40096589},{"batb":[[0,1.83,10],[1,1.82,22.78],[2,1.81,333]],"ltp":1.9,"tv":158.0,"id":40096581}]}]}
{"op":"mcm","clk":"11824827381","pt":1722965153531,"mc":[{"id":"1.231501647","rc":[{"batb":[[0,1.86,5.45],[1,1.85,111],[2,1.25,100]],"ltp":2.12,"tv":7.16,"id":40096589},{"batb":[[0,1.82,22.78],[1,1.81,333],[2,1.56,138.46]],"ltp":1.9,"tv":158.0,"id":40096581}]}]}
{"op":"mcm","clk":"11824841772","pt":1722965322114,"mc":[{"id":"1.231501647","rc":[{"batb":[[0,1.87,10],[1,1.86,5.45],[2,1.85,111]],"ltp":2.12,"tv":7.16,"id":40096589},{"batb":[[0,1.83,10],[1,1.82,22.78],[2,1.81,333]],"ltp":1.9,"tv":158.0,"id":40096581}]}]}
{"op":"mcm","clk":"11824842110","pt":1722965325515,"mc":[{"id":"1.231501647","rc":[{"batb":[[0,1.86,5.45],[1,1.85,111],[2,1.25,100]],"ltp":2.12,"tv":7.16,"id":40096589},{"batb":[[0,1.82,22.78],[1,1.81,333],[2,1.56,138.46]],"ltp":1.9,"tv":158.0,"id":40096581}]}]}
{"op":"mcm","clk":"11824849219","pt":1722965403391,"mc":[{"id":"1.231501647","rc":[{"batb":[[0,1.87,10],[1,1.86,5.45],[2,1.85,111]],"ltp":2.12,"tv":7.16,"id":40096589},{"batb":[[0,1.83,10],[1,1.82,22.78],[2,1.81,333]],"ltp":1.9,"tv":158.0,"id":40096581}]}]}
{"op":"mcm","clk":"11824849558","pt":1722965407220,"mc":[{"id":"1.231501647","rc":[{"batb":[[0,1.86,5.45],[1,1.85,111],[2,1.25,100]],"ltp":2.12,"tv":7.16,"id":40096589},{"batb":[[0,1.82,22.78],[1,1.81,333],[2,1.56,138.46]],"ltp":1.9,"tv":158.0,"id":40096581}]}]}
{"op":"mcm","clk":"11824850439","pt":1722965417367,"mc":[{"id":"1.231501647","rc":[{"batb":[[0,1.87,10],[1,1.86,5.45],[2,1.85,111]],"ltp":2.12,"tv":7.16,"id":40096589},{"batb":[[0,1.83,10],[1,1.82,22.78],[2,1.81,333]],"ltp":1.9,"tv":158.0,"id":40096581}]}]}
{"op":"mcm","clk":"11824850745","pt":1722965420814,"mc":[{"id":"1.231501647","rc":[{"batb":[[0,1.86,5.45],[1,1.85,111],[2,1.25,100]],"ltp":2.12,"tv":7.16,"id":40096589},{"batb":[[0,1.82,22.78],[1,1.81,333],[2,1.56,138.46]],"ltp":1.9,"tv":158.0,"id":40096581}]}]}
{"op":"mcm","clk":"11825022888","pt":1722967680688,"mc":[{"id":"1.231501647","rc":[{"trd":[[2.12,7.18]],"batb":[[0,1.87,10],[1,1.86,5.46],[2,1.85,111]],"batl":[[0,2.22,13.47]],"ltp":2.12,"tv":7.17,"id":40096589},{"batb":[[0,1.83,10],[1,1.82,22.8],[2,1.81,333]],"batl":[[0,2.16,4.63]],"ltp":1.9,"tv":158.0,"id":40096581}],"tv":165.17}]}
{"op":"mcm","clk":"11825023357","pt":1722967685806,"mc":[{"id":"1.231501647","rc":[{"batb":[[0,1.86,5.46],[1,1.85,111],[2,1.25,100]],"ltp":2.12,"tv":7.17,"id":40096589},{"batb":[[0,1.82,22.8],[1,1.81,333],[2,1.56,138.46]],"ltp":1.9,"tv":158.0,"id":40096581}]}]}
{"op":"mcm","clk":"11825109027","pt":1722968657333,"mc":[{"id":"1.231501647","rc":[{"batb":[[0,1.87,10],[1,1.86,5.46],[2,1.85,111]],"ltp":2.12,"tv":7.17,"id":40096589},{"batb":[[0,1.83,10],[1,1.82,22.8],[2,1.81,333]],"ltp":1.9,"tv":158.0,"id":40096581}]}]}
{"op":"mcm","clk":"11825109297","pt":1722968660830,"mc":[{"id":"1.231501647","rc":[{"batb":[[0,1.86,5.46],[1,1.85,111],[2,1.25,100]],"ltp":2.12,"tv":7.17,"id":40096589},{"batb":[[0,1.82,22.8],[1,1.81,333],[2,1.56,138.46]],"ltp":1.9,"tv":158.0,"id":40096581}]}]}
{"op":"mcm","clk":"11825113018","pt":1722968703803,"mc":[{"id":"1.231501647","rc":[{"batb":[[0,1.87,10],[1,1.86,5.46],[2,1.85,111]],"ltp":2.12,"tv":7.17,"id":40096589},{"batb":[[0,1.83,10],[1,1.82,22.8],[2,1.81,333]],"ltp":1.9,"tv":158.0,"id":40096581}]}]}
{"op":"mcm","clk":"11825113366","pt":1722968707218,"mc":[{"id":"1.231501647","rc":[{"batb":[[0,1.86,5.46],[1,1.85,111],[2,1.25,100]],"ltp":2.12,"tv":7.17,"id":40096589},{"batb":[[0,1.82,22.8],[1,1.81,333],[2,1.56,138.46]],"ltp":1.9,"tv":158.0,"id":40096581}]}]}
{"op":"mcm","clk":"11825118018","pt":1722968761753,"mc":[{"id":"1.231501647","rc":[{"batb":[[0,1.98,38.59],[1,1.86,5.46],[2,1.85,111]],"ltp":2.12,"tv":7.17,"id":40096589},{"batb":[[0,1.96,39.4],[1,1.82,22.8],[2,1.81,333]],"ltp":1.9,"tv":158.0,"id":40096581}]}]}
{"op":"mcm","clk":"11825118034","pt":1722968761956,"mc":[{"id":"1.231501647","rc":[{"batb":[[0,1.99,10],[1,1.98,38.59],[2,1.86,5.46]],"ltp":2.12,"tv":7.17,"id":40096589},{"batb":[[0,1.97,10],[1,1.96,39.4],[2,1.82,22.8]],"ltp":1.9,"tv":158.0,"id":40096581}]}]}
{"op":"mcm","clk":"11825118162","pt":1722968763568,"mc":[{"id":"1.231501647","rc":[{"batb":[[2,1.85,111]],"ltp":2.12,"tv":7.17,"id":40096589},{"batb":[[2,1.82,6.14]],"ltp":1.9,"tv":158.0,"id":40096581}]}]}
{"op":"mcm","clk":"11825118313","pt":1722968765273,"mc":[{"id":"1.231501647","rc":[{"batb":[[0,1.98,38.59],[1,1.85,111],[2,1.25,100]],"ltp":2.12,"tv":7.17,"id":40096589},{"batb":[[0,1.96,39.4],[1,1.82,6.14],[2,1.81,333]],"ltp":1.9,"tv":158.0,"id":40096581}]}]}
{"op":"mcm","clk":"11825173822","pt":1722969414742,"mc":[{"id":"1.231501647","rc":[{"batb":[[1,1.81,333],[2,1.56,138.46]],"ltp":1.9,"tv":158.0,"id":40096581}]}]}
{"op":"mcm","clk":"11825613715","pt":1722975174998,"mc":[{"id":"1.231501647","rc":[{"trd":[[2.12,7.18]],"ltp":2.12,"tv":7.17,"id":40096589}],"tv":165.17}]}
{"op":"mcm","clk":"11825671496","pt":1722976314565,"mc":[{"id":"1.231501647","rc":[{"trd":[[2.06,4.01]],"ltp":2.06,"tv":11.18,"id":40096589},{"trd":[[1.96,4.21]],"batb":[[0,1.96,35.19]],"ltp":1.96,"tv":162.21,"id":40096581}],"tv":173.39}]}
{"op":"mcm","clk":"11825671639","pt":1722976317772,"mc":[{"id":"1.231501647","rc":[{"batb":[[0,1.96,39.4]],"ltp":1.96,"tv":162.21,"id":40096581}]}]}
{"op":"mcm","clk":"11825836802","pt":1722980574996,"mc":[{"id":"1.231501647","rc":[{"trd":[[2.12,7.18]],"ltp":2.06,"tv":11.19,"id":40096589}],"tv":173.4}]}
{"op":"mcm","clk":"11826042396","pt":1722985974976,"mc":[{"id":"1.231501647","rc":[{"trd":[[2.12,7.18]],"ltp":2.06,"tv":11.18,"id":40096589}],"tv":173.39}]}
{"op":"mcm","clk":"11826288763","pt":1722991375030,"mc":[{"id":"1.231501647","rc":[{"trd":[[2.12,7.18]],"ltp":2.06,"tv":11.19,"id":40096589}],"tv":173.4}]}
{"op":"mcm","clk":"11826385406","pt":1722993677267,"mc":[{"id":"1.231501647","rc":[{"trd":[[2.12,7.17]],"ltp":2.06,"tv":11.18,"id":40096589},{"batb":[[2,1.25,100]],"ltp":1.96,"tv":162.21,"id":40096581}],"tv":173.39}]}
{"op":"mcm","clk":"11826393475","pt":1722993890627,"mc":[{"id":"1.231501647","rc":[{"batl":[[0,2,0.54]],"ltp":2.06,"tv":11.18,"id":40096589},{"batb":[[0,1.97,10],[1,1.96,39.4],[2,1.81,333]],"batl":[[0,5,2.57]],"ltp":1.96,"tv":162.21,"id":40096581}]}]}
{"op":"mcm","clk":"11826393589","pt":1722993893873,"mc":[{"id":"1.231501647","rc":[{"batb":[[0,1.96,39.4],[1,1.81,333],[2,1.25,100]],"ltp":1.96,"tv":162.21,"id":40096581}]}]}
{"op":"mcm","clk":"11826393727","pt":1722993896445,"mc":[{"id":"1.231501647","rc":[{"batb":[[0,1.97,10],[1,1.96,39.4],[2,1.81,333]],"batl":[[0,5,2.83]],"ltp":1.96,"tv":162.21,"id":40096581}]}]}
{"op":"mcm","clk":"11826393854","pt":1722993899574,"mc":[{"id":"1.231501647","rc":[{"batb":[[0,1.96,39.4],[1,1.81,333],[2,1.25,100]],"ltp":1.96,"tv":162.21,"id":40096581}]}]}
{"op":"mcm","clk":"11826393971","pt":1722993901954,"mc":[{"id":"1.231501647","rc":[{"batb":[[0,1.97,10],[1,1.96,39.4],[2,1.81,333]],"ltp":1.96,"tv":162.21,"id":40096581}]}]}
{"op":"mcm","clk":"11826394127","pt":1722993905346,"mc":[{"id":"1.231501647","rc":[{"trd":[[2,0.26]],"batl":[[0,2,0.28]],"ltp":2.0,"tv":11.44,"id":40096589},{"trd":[[2,0.26]],"batb":[[0,1.96,39.4],[1,1.81,333],[2,1.25,100]],"ltp":2.0,"tv":162.46,"id":40096581}],"tv":173.9}]}
{"op":"mcm","clk":"11826529143","pt":1722996775042,"mc":[{"id":"1.231501647","rc":[{"trd":[[2.12,7.17]],"ltp":2.0,"tv":11.43,"id":40096589}],"tv":173.9}]}
{"op":"mcm","clk":"11826791738","pt":1723002175014,"mc":[{"id":"1.231501647","rc":[{"trd":[[2.12,7.16]],"ltp":2.0,"tv":11.42,"id":40096589}],"tv":173.89}]}
{"op":"mcm","clk":"11827028865","pt":1723007575005,"mc":[{"id":"1.231501647","rc":[{"trd":[[2.12,7.16]],"ltp":2.0,"tv":11.42,"id":40096589}],"tv":173.89}]}
{"op":"mcm","clk":"11827288682","pt":1723013708979,"mc":[{"id":"1.231501647","rc":[{"batb":[[2,1.74,17.32]],"ltp":2.0,"tv":11.42,"id":40096589},{"batb":[[2,1.74,17.32]],"ltp":2.0,"tv":162.46,"id":40096581}]}]}
{"op":"mcm","clk":"11827411544","pt":1723018374965,"mc":[{"id":"1.231501647","rc":[{"trd":[[2.12,7.17]],"ltp":2.0,"tv":11.43,"id":40096589}],"tv":173.9}]}
{"op":"mcm","clk":"11827416248","pt":1723018454007,"mc":[{"id":"1.231501647","rc":[{"trd":[[2.06,13.97]],"ltp":2.06,"tv":21.39,"id":40096589},{"trd":[[1.96,14.68]],"batb":[[0,1.96,28.93]],"ltp":1.96,"tv":172.93,"id":40096581}],"tv":194.33}]}
{"op":"mcm","clk":"11827416351","pt":1723018458626,"mc":[{"id":"1.231501647","rc":[{"batb":[[0,1.96,39.4]],"ltp":1.96,"tv":172.93,"id":40096581}]}]}
{"op":"mcm","clk":"11827580734","pt":1723022852647,"mc":[{"id":"1.231501647","rc":[{"trd":[[2.12,7.17]],"ltp":2.06,"tv":21.39,"id":40096589},{"batb":[[0,1.97,15.75],[1,1.96,39.4],[2,1.81,333]],"ltp":1.96,"tv":172.93,"id":40096581}],"tv":194.33}]}
{"op":"mcm","clk":"11827581540","pt":1723022865674,"mc":[{"id":"1.231501647","rc":[{"batb":[[0,1.96,39.4],[1,1.81,333],[2,1.74,17.32]],"ltp":1.96,"tv":172.93,"id":40096581}]}]}
{"op":"mcm","clk":"11828066798","pt":1723029174992,"mc":[{"id":"1.231501647","rc":[{"trd":[[2.12,7.16]],"ltp":2.06,"tv":21.38,"id":40096589}],"tv":194.32}]}
{"op":"mcm","clk":"11828456349","pt":1723034574983,"mc":[{"id":"1.231501647","rc":[{"trd":[[2.12,7.16]],"ltp":2.06,"tv":21.38,"id":40096589}],"tv":194.32}]}
{"op":"mcm","clk":"11828812421","pt":1723039974971,"mc":[{"id":"1.231501647","rc":[{"trd":[[2.12,7.16]],"ltp":2.06,"tv":21.38,"id":40096589}],"tv":194.32}]}
{"op":"mcm","clk":"11828851766","pt":1723040507750,"mc":[{"id":"1.231501647","rc":[{"batb":[[0,1.98,45.31]],"ltp":2.06,"tv":21.38,"id":40096589},{"batb":[[0,1.96,46.26]],"ltp":1.96,"tv":172.93,"id":40096581}]}]}
{"op":"mcm","clk":"11828978796","pt":1723042361004,"mc":[{"id":"1.231501647","rc":[{"batb":[[0,1.97,10],[1,1.96,46.26],[2,1.81,333]],"batl":[[0,2.02,2]],"ltp":1.96,"tv":172.93,"id":40096581}]}]}
{"op":"mcm","clk":"11828979054","pt":1723042364212,"mc":[{"id":"1.231501647","rc":[{"batb":[[0,1.96,46.26],[1,1.81,333],[2,1.74,17.32]],"ltp":1.96,"tv":172.93,"id":40096581}]}]}
{"op":"mcm","clk":"11829024657","pt":1723042937358,"mc":[{"id":"1.231501647","rc":[{"trd":[[2.12,7.16]],"ltp":2.06,"tv":21.39,"id":40096589},{"batb":[[0,1.97,10],[1,1.96,46.26],[2,1.81,333]],"ltp":1.96,"tv":172.93,"id":40096581}],"tv":194.32}]}
{"op":"mcm","clk":"11829024924","pt":1723042940789,"mc":[{"id":"1.231501647","rc":[{"batb":[[0,1.96,46.26],[1,1.81,333],[2,1.74,17.32]],"ltp":1.96,"tv":172.93,"id":40096581}]}]}
{"op":"mcm","clk":"11829064989","pt":1723043394464,"mc":[{"id":"1.231501647","rc":[{"batb":[[0,1.97,10],[1,1.96,46.26],[2,1.81,333]],"ltp":1.96,"tv":172.93,"id":40096581}]}]}
{"op":"mcm","clk":"11829065378","pt":1723043398367,"mc":[{"id":"1.231501647","rc":[{"batb":[[0,1.96,46.26],[1,1.81,333],[2,1.74,17.32]],"ltp":1.96,"tv":172.93,"id":40096581}]}]}
{"op":"mcm","clk":"11829104178","pt":1723043776250,"mc":[{"id":"1.231501647","rc":[{"batb":[[0,1.97,10],[1,1.96,46.26],[2,1.81,333]],"ltp":1.96,"tv":172.93,"id":40096581}]}]}
{"op":"mcm","clk":"11829104551","pt":1723043779841,"mc":[{"id":"1.231501647","rc":[{"batb":[[0,1.96,46.26],[1,1.81,333],[2,1.74,17.32]],"ltp":1.96,"tv":172.93,"id":40096581}]}]}
{"op":"mcm","clk":"11829141702","pt":1723044165557,"mc":[{"id":"1.231501647","rc":[{"batb":[[0,1.97,10],[1,1.96,46.26],[2,1.81,333]],"ltp":1.96,"tv":172.93,"id":40096581}]}]}
{"op":"mcm","clk":"11829142014","pt":1723044168772,"mc":[{"id":"1.231501647","rc":[{"batb":[[0,1.96,46.26],[1,1.81,333],[2,1.74,17.32]],"ltp":1.96,"tv":172.93,"id":40096581}]}]}
{"op":"mcm","clk":"11829188028","pt":1723044646972,"mc":[{"id":"1.231501647","rc":[{"batb":[[0,1.97,10],[1,1.96,46.26],[2,1.81,333]],"ltp":1.96,"tv":172.93,"id":40096581}]}]}
{"op":"mcm","clk":"11829188374","pt":1723044650295,"mc":[{"id":"1.231501647","rc":[{"batb":[[0,1.96,46.26],[1,1.81,333],[2,1.74,17.32]],"ltp":1.96,"tv":172.93,"id":40096581}]}]}
{"op":"mcm","clk":"11829243114","pt":1723045165718,"mc":[{"id":"1.231501647","rc":[{"batb":[[0,1.97,10],[1,1.96,46.26],[2,1.81,333]],"ltp":1.96,"tv":172.93,"id":40096581}]}]}
{"op":"mcm","clk":"11829243506","pt":1723045169225,"mc":[{"id":"1.231501647","rc":[{"batb":[[0,1.96,46.26],[1,1.81,333],[2,1.74,17.32]],"ltp":1.96,"tv":172.93,"id":40096581}]}]}
{"op":"mcm","clk":"11829306793","pt":1723045701557,"mc":[{"id":"1.231501647","rc":[{"batb":[[0,1.97,10],[1,1.96,46.26],[2,1.81,333]],"ltp":1.96,"tv":172.93,"id":40096581}]}]}
{"op":"mcm","clk":"11829307164","pt":1723045705244,"mc":[{"id":"1.231501647","rc":[{"batb":[[0,1.96,46.26],[1,1.81,333],[2,1.74,17.32]],"ltp":1.96,"tv":172.93,"id":40096581}]}]}
{"op":"mcm","clk":"11829419446","pt":1723046881702,"mc":[{"id":"1.231501647","rc":[{"trd":[[2.12,7.16]],"ltp":2.06,"tv":21.38,"id":40096589},{"batb":[[0,1.97,10],[1,1.96,46.26],[2,1.81,333]],"ltp":1.96,"tv":172.93,"id":40096581}],"tv":194.32}]}
{"op":"mcm","clk":"11829419827","pt":1723046884911,"mc":[{"id":"1.231501647","rc":[{"batb":[[0,1.96,46.26],[1,1.81,333],[2,1.74,17.32]],"ltp":1.96,"tv":172.93,"id":40096581}]}]}
{"op":"mcm","clk":"11829456613","pt":1723047206862,"mc":[{"id":"1.231501647","rc":[{"batb":[[0,1.97,10],[1,1.96,46.26],[2,1.81,333]],"ltp":1.96,"tv":172.93,"id":40096581}]}]}
{"op":"mcm","clk":"11829456977","pt":1723047210469,"mc":[{"id":"1.231501647","rc":[{"batb":[[0,1.96,46.26],[1,1.81,333],[2,1.74,17.32]],"ltp":1.96,"tv":172.93,"id":40096581}]}]}
{"op":"mcm","clk":"11829470699","pt":1723047336747,"mc":[{"id":"1.231501647","rc":[{"batb":[[0,1.97,10],[1,1.96,46.26],[2,1.81,333]],"ltp":1.96,"tv":172.93,"id":40096581}]}]}
{"op":"mcm","clk":"11829471039","pt":1723047340044,"mc":[{"id":"1.231501647","rc":[{"batb":[[0,1.96,46.26],[1,1.81,333],[2,1.74,17.32]],"ltp":1.96,"tv":172.93,"id":40096581}]}]}
{"op":"mcm","clk":"11829480461","pt":1723047429744,"mc":[{"id":"1.231501647","rc":[{"batb":[[0,1.97,10],[1,1.96,46.26],[2,1.81,333]],"ltp":1.96,"tv":172.93,"id":40096581}]}]}
{"op":"mcm","clk":"11829480868","pt":1723047433276,"mc":[{"id":"1.231501647","rc":[{"batb":[[0,1.96,46.26],[1,1.81,333],[2,1.74,17.32]],"ltp":1.96,"tv":172.93,"id":40096581}]}]}
{"op":"mcm","clk":"11829498153","pt":1723047585776,"mc":[{"id":"1.231501647","rc":[{"batb":[[0,1.97,10],[1,1.96,46.26],[2,1.81,333]],"ltp":1.96,"tv":172.93,"id":40096581}]}]}
{"op":"mcm","clk":"11829498547","pt":1723047589031,"mc":[{"id":"1.231501647","rc":[{"batb":[[0,1.96,46.26],[1,1.81,333],[2,1.74,17.32]],"ltp":1.96,"tv":172.93,"id":40096581}]}]}
{"op":"mcm","clk":"11829525967","pt":1723047817542,"mc":[{"id":"1.231501647","rc":[{"batb":[[0,1.97,10],[1,1.96,46.26],[2,1.81,333]],"ltp":1.96,"tv":172.93,"id":40096581}]}]}
{"op":"mcm","clk":"11829526394","pt":1723047820613,"mc":[{"id":"1.231501647","rc":[{"batb":[[0,1.96,46.26],[1,1.81,333],[2,1.74,17.32]],"ltp":1.96,"tv":172.93,"id":40096581}]}]}
{"op":"mcm","clk":"11829531561","pt":1723047869188,"mc":[{"id":"1.231501647","rc":[{"batb":[[0,1.97,10],[1,1.96,46.26],[2,1.81,333]],"ltp":1.96,"tv":172.93,"id":40096581}]}]}
{"op":"mcm","clk":"11829531972","pt":1723047872551,"mc":[{"id":"1.231501647","rc":[{"batb":[[0,1.96,46.26],[1,1.81,333],[2,1.74,17.32]],"ltp":1.96,"tv":172.93,"id":40096581}]}]}
{"op":"mcm","clk":"11829532562","pt":1723047878361,"mc":[{"id":"1.231501647","rc":[{"batb":[[0,1.97,10],[1,1.96,46.26],[2,1.81,333]],"ltp":1.96,"tv":172.93,"id":40096581}]}]}
{"op":"mcm","clk":"11829532843","pt":1723047881579,"mc":[{"id":"1.231501647","rc":[{"batb":[[0,1.96,46.26],[1,1.81,333],[2,1.74,17.32]],"ltp":1.96,"tv":172.93,"id":40096581}]}]}
{"op":"mcm","clk":"11829540862","pt":1723047956070,"mc":[{"id":"1.231501647","rc":[{"batb":[[0,1.97,10],[1,1.96,46.26],[2,1.81,333]],"ltp":1.96,"tv":172.93,"id":40096581}]}]}
{"op":"mcm","clk":"11829541229","pt":1723047959389,"mc":[{"id":"1.231501647","rc":[{"batb":[[0,1.96,46.26],[1,1.81,333],[2,1.74,17.32]],"ltp":1.96,"tv":172.93,"id":40096581}]}]}
{"op":"mcm","clk":"11829549924","pt":1723048036489,"mc":[{"id":"1.231501647","rc":[{"batb":[[0,1.97,10],[1,1.96,46.26],[2,1.81,333]],"ltp":1.96,"tv":172.93,"id":40096581}]}]}
{"op":"mcm","clk":"11829550312","pt":1723048039863,"mc":[{"id":"1.231501647","rc":[{"batb":[[0,1.96,46.26],[1,1.81,333],[2,1.74,17.32]],"ltp":1.96,"tv":172.93,"id":40096581}]}]}
{"op":"mcm","clk":"11829551460","pt":1723048050191,"mc":[{"id":"1.231501647","rc":[{"batb":[[0,1.97,10],[1,1.96,46.26],[2,1.81,333]],"ltp":1.96,"tv":172.93,"id":40096581}]}]}
{"op":"mcm","clk":"11829551808","pt":1723048053615,"mc":[{"id":"1.231501647","rc":[{"batb":[[0,1.96,46.26],[1,1.81,333],[2,1.74,17.32]],"ltp":1.96,"tv":172.93,"id":40096581}]}]}
{"op":"mcm","clk":"11829553920","pt":1723048071922,"mc":[{"id":"1.231501647","rc":[{"batb":[[0,1.97,10],[1,1.96,46.26],[2,1.81,333]],"ltp":1.96,"tv":172.93,"id":40096581}]}]}
{"op":"mcm","clk":"11829554323","pt":1723048075331,"mc":[{"id":"1.231501647","rc":[{"batb":[[0,1.96,46.26],[1,1.81,333],[2,1.74,17.32]],"ltp":1.96,"tv":172.93,"id":40096581}]}]}
{"op":"mcm","clk":"11829556614","pt":1723048096941,"mc":[{"id":"1.231501647","rc":[{"batb":[[0,1.97,10],[1,1.96,46.26],[2,1.81,333]],"ltp":1.96,"tv":172.93,"id":40096581}]}]}
{"op":"mcm","clk":"11829556922","pt":1723048100220,"mc":[{"id":"1.231501647","rc":[{"batb":[[0,1.96,46.26],[1,1.81,333],[2,1.74,17.32]],"ltp":1.96,"tv":172.93,"id":40096581}]}]}
{"op":"mcm","clk":"11829558409","pt":1723048115650,"mc":[{"id":"1.231501647","rc":[{"batb":[[0,1.97,10],[1,1.96,46.26],[2,1.81,333]],"ltp":1.96,"tv":172.93,"id":40096581}]}]}
{"op":"mcm","clk":"11829558717","pt":1723048118867,"mc":[{"id":"1.231501647","rc":[{"batb":[[0,1.96,46.26],[1,1.81,333],[2,1.74,17.32]],"ltp":1.96,"tv":172.93,"id":40096581}]}]}
{"op":"mcm","clk":"11829559786","pt":1723048129246,"mc":[{"id":"1.231501647","rc":[{"batb":[[0,1.97,10],[1,1.96,46.26],[2,1.81,333]],"ltp":1.96,"tv":172.93,"id":40096581}]}]}
{"op":"mcm","clk":"11829560118","pt":1723048132456,"mc":[{"id":"1.231501647","rc":[{"batb":[[0,1.96,46.26],[1,1.81,333],[2,1.74,17.32]],"ltp":1.96,"tv":172.93,"id":40096581}]}]}
{"op":"mcm","clk":"11829561510","pt":1723048145979,"mc":[{"id":"1.231501647","rc":[{"batb":[[0,1.97,10],[1,1.96,46.26],[2,1.81,333]],"ltp":1.96,"tv":172.93,"id":40096581}]}]}
{"op":"mcm","clk":"11829561835","pt":1723048149166,"mc":[{"id":"1.231501647","rc":[{"batb":[[0,1.96,46.26],[1,1.81,333],[2,1.74,17.32]],"ltp":1.96,"tv":172.93,"id":40096581}]}]}
{"op":"mcm","clk":"11829578308","pt":1723048297570,"mc":[{"id":"1.231501647","rc":[{"batb":[[0,1.97,10],[1,1.96,46.26],[2,1.81,333]],"ltp":1.96,"tv":172.93,"id":40096581}]}]}
{"op":"mcm","clk":"11829578673","pt":1723048301290,"mc":[{"id":"1.231501647","rc":[{"batb":[[0,1.96,46.26],[1,1.81,333],[2,1.74,17.32]],"ltp":1.96,"tv":172.93,"id":40096581}]}]}
{"op":"mcm","clk":"11829589108","pt":1723048407284,"mc":[{"id":"1.231501647","rc":[{"batb":[[0,1.97,10],[1,1.96,46.26],[2,1.81,333]],"ltp":1.96,"tv":172.93,"id":40096581}]}]}
{"op":"mcm","clk":"11829589600","pt":1723048410695,"mc":[{"id":"1.231501647","rc":[{"batb":[[0,1.96,46.26],[1,1.81,333],[2,1.74,17.32]],"ltp":1.96,"tv":172.93,"id":40096581}]}]}
{"op":"mcm","clk":"11829595437","pt":1723048470656,"mc":[{"id":"1.231501647","rc":[{"batb":[[0,1.97,10],[1,1.96,46.26],[2,1.81,333]],"ltp":1.96,"tv":172.93,"id":40096581}]}]}
{"op":"mcm","clk":"11829595758","pt":1723048474030,"mc":[{"id":"1.231501647","rc":[{"batb":[[0,1.96,46.26],[1,1.81,333],[2,1.74,17.32]],"ltp":1.96,"tv":172.93,"id":40096581}]}]}
{"op":"mcm","clk":"11829597326","pt":1723048490365,"mc":[{"id":"1.231501647","rc":[{"batb":[[0,1.97,10],[1,1.96,46.26],[2,1.81,333]],"ltp":1.96,"tv":172.93,"id":40096581}]}]}
{"op":"mcm","clk":"11829597647","pt":1723048493747,"mc":[{"id":"1.231501647","rc":[{"batb":[[0,1.96,46.26],[1,1.81,333],[2,1.74,17.32]],"ltp":1.96,"tv":172.93,"id":40096581}]}]}
{"op":"mcm","clk":"11829610224","pt":1723048620191,"mc":[{"id":"1.231501647","rc":[{"batb":[[0,1.97,10],[1,1.96,46.26],[2,1.81,333]],"ltp":1.96,"tv":172.93,"id":40096581}]}]}
{"op":"mcm","clk":"11829610552","pt":1723048623481,"mc":[{"id":"1.231501647","rc":[{"batb":[[0,1.96,46.26],[1,1.81,333],[2,1.74,17.32]],"ltp":1.96,"tv":172.93,"id":40096581}]}]}
{"op":"mcm","clk":"11829610897","pt":1723048627179,"mc":[{"id":"1.231501647","rc":[{"batb":[[0,1.97,10],[1,1.96,46.26],[2,1.81,333]],"ltp":1.96,"tv":172.93,"id":40096581}]}]}
{"op":"mcm","clk":"11829611246","pt":1723048630714,"mc":[{"id":"1.231501647","rc":[{"batb":[[0,1.96,46.26],[1,1.81,333],[2,1.74,17.32]],"ltp":1.96,"tv":172.93,"id":40096581}]}]}
{"op":"mcm","clk":"11829614775","pt":1723048666839,"mc":[{"id":"1.231501647","rc":[{"batb":[[0,1.97,10],[1,1.96,46.26],[2,1.81,333]],"ltp":1.96,"tv":172.93,"id":40096581}]}]}
{"op":"mcm","clk":"11829615090","pt":1723048670124,"mc":[{"id":"1.231501647","rc":[{"batb":[[0,1.96,46.26],[1,1.81,333],[2,1.74,17.32]],"ltp":1.96,"tv":172.93,"id":40096581}]}]}
{"op":"mcm","clk":"11829616035","pt":1723048679978,"mc":[{"id":"1.231501647","rc":[{"batb":[[0,1.97,10],[1,1.96,46.26],[2,1.81,333]],"ltp":1.96,"tv":172.93,"id":40096581}]}]}
{"op":"mcm","clk":"11829616362","pt":1723048683367,"mc":[{"id":"1.231501647","rc":[{"batb":[[0,1.96,46.26],[1,1.81,333],[2,1.74,17.32]],"ltp":1.96,"tv":172.93,"id":40096581}]}]}
{"op":"mcm","clk":"11829617977","pt":1723048699998,"mc":[{"id":"1.231501647","rc":[{"batb":[[0,1.97,10],[1,1.96,46.26],[2,1.81,333]],"ltp":1.96,"tv":172.93,"id":40096581}]}]}
{"op":"mcm","clk":"11829618316","pt":1723048703400,"mc":[{"id":"1.231501647","rc":[{"batb":[[0,1.96,46.26],[1,1.81,333],[2,1.74,17.32]],"ltp":1.96,"tv":172.93,"id":40096581}]}]}
{"op":"mcm","clk":"11829619058","pt":1723048710627,"mc":[{"id":"1.231501647","rc":[{"batb":[[0,1.97,10],[1,1.96,46.26],[2,1.81,333]],"ltp":1.96,"tv":172.93,"id":40096581}]}]}
{"op":"mcm","clk":"11829619372","pt":1723048714138,"mc":[{"id":"1.231501647","rc":[{"batb":[[0,1.96,46.26],[1,1.81,333],[2,1.74,17.32]],"ltp":1.96,"tv":172.93,"id":40096581}]}]}
{"op":"mcm","clk":"11829621717","pt":1723048740551,"mc":[{"id":"1.231501647","rc":[{"batb":[[0,1.97,10],[1,1.96,46.26],[2,1.81,333]],"ltp":1.96,"tv":172.93,"id":40096581}]}]}
{"op":"mcm","clk":"11829622041","pt":1723048743965,"mc":[{"id":"1.231501647","rc":[{"batb":[[0,1.96,46.26],[1,1.81,333],[2,1.74,17.32]],"ltp":1.96,"tv":172.93,"id":40096581}]}]}
{"op":"mcm","clk":"11829624046","pt":1723048763701,"mc":[{"id":"1.231501647","rc":[{"batb":[[0,1.97,10],[1,1.96,46.26],[2,1.81,333]],"ltp":1.96,"tv":172.93,"id":40096581}]}]}
{"op":"mcm","clk":"11829624412","pt":1723048767278,"mc":[{"id":"1.231501647","rc":[{"batb":[[0,1.96,46.26],[1,1.81,333],[2,1.74,17.32]],"ltp":1.96,"tv":172.93,"id":40096581}]}]}
{"op":"mcm","clk":"11829629478","pt":1723048812166,"mc":[{"id":"1.231501647","rc":[{"batb":[[0,1.97,10],[1,1.96,46.26],[2,1.81,333]],"ltp":1.96,"tv":172.93,"id":40096581}]}]}
{"op":"mcm","clk":"11829629839","pt":1723048815454,"mc":[{"id":"1.231501647","rc":[{"batb":[[0,1.96,46.26],[1,1.81,333],[2,1.74,17.32]],"ltp":1.96,"tv":172.93,"id":40096581}]}]}
{"op":"mcm","clk":"11829630932","pt":1723048825008,"mc":[{"id":"1.231501647","rc":[{"batb":[[0,1.97,10],[1,1.96,46.26],[2,1.81,333]],"ltp":1.96,"tv":172.93,"id":40096581}]}]}
{"op":"mcm","clk":"11829631299","pt":1723048828504,"mc":[{"id":"1.231501647","rc":[{"batb":[[0,1.96,46.26],[1,1.81,333],[2,1.74,17.32]],"ltp":1.96,"tv":172.93,"id":40096581}]}]}
{"op":"mcm","clk":"11829631985","pt":1723048834480,"mc":[{"id":"1.231501647","rc":[{"batb":[[0,1.97,10],[1,1.96,46.26],[2,1.81,333]],"ltp":1.96,"tv":172.93,"id":40096581}]}]}
{"op":"mcm","clk":"11829632357","pt":1723048837807,"mc":[{"id":"1.231501647","rc":[{"batb":[[0,1.96,46.26],[1,1.81,333],[2,1.74,17.32]],"ltp":1.96,"tv":172.93,"id":40096581}]}]}
{"op":"mcm","clk":"11829632966","pt":1723048843015,"mc":[{"id":"1.231501647","rc":[{"batb":[[0,1.97,10],[1,1.96,46.26],[2,1.81,333]],"ltp":1.96,"tv":172.93,"id":40096581}]}]}
{"op":"mcm","clk":"11829633343","pt":1723048846396,"mc":[{"id":"1.231501647","rc":[{"batb":[[0,1.96,46.26],[1,1.81,333],[2,1.74,17.32]],"ltp":1.96,"tv":172.93,"id":40096581}]}]}
{"op":"mcm","clk":"11829633727","pt":1723048849621,"mc":[{"id":"1.231501647","rc":[{"batb":[[0,1.97,10],[1,1.96,46.26],[2,1.81,333]],"ltp":1.96,"tv":172.93,"id":40096581}]}]}
{"op":"mcm","clk":"11829634110","pt":1723048852808,"mc":[{"id":"1.231501647","rc":[{"batb":[[0,1.96,46.26],[1,1.81,333],[2,1.74,17.32]],"ltp":1.96,"tv":172.93,"id":40096581}]}]}
{"op":"mcm","clk":"11829638115","pt":1723048886626,"mc":[{"id":"1.231501647","rc":[{"batb":[[0,1.97,10],[1,1.96,46.26],[2,1.81,333]],"ltp":1.96,"tv":172.93,"id":40096581}]}]}
{"op":"mcm","clk":"11829638463","pt":1723048890084,"mc":[{"id":"1.231501647","rc":[{"batb":[[0,1.96,46.26],[1,1.81,333],[2,1.74,17.32]],"ltp":1.96,"tv":172.93,"id":40096581}]}]}
{"op":"mcm","clk":"11829640187","pt":1723048906183,"mc":[{"id":"1.231501647","rc":[{"batb":[[0,1.97,10],[1,1.96,46.26],[2,1.81,333]],"ltp":1.96,"tv":172.93,"id":40096581}]}]}
{"op":"mcm","clk":"11829640609","pt":1723048908600,"mc":[{"id":"1.231501647","rc":[{"batb":[[0,1.96,46.26],[1,1.81,333],[2,1.74,17.32]],"ltp":1.96,"tv":172.93,"id":40096581}]}]}
{"op":"mcm","clk":"11829642464","pt":1723048925218,"mc":[{"id":"1.231501647","rc":[{"batb":[[0,1.97,10],[1,1.96,46.26],[2,1.81,333]],"ltp":1.96,"tv":172.93,"id":40096581}]}]}
{"op":"mcm","clk":"11829642809","pt":1723048928448,"mc":[{"id":"1.231501647","rc":[{"batb":[[0,1.96,46.26],[1,1.81,333],[2,1.74,17.32]],"ltp":1.96,"tv":172.93,"id":40096581}]}]}
{"op":"mcm","clk":"11829646109","pt":1723048956494,"mc":[{"id":"1.231501647","rc":[{"batb":[[0,1.97,10],[1,1.96,46.26],[2,1.81,333]],"ltp":1.96,"tv":172.93,"id":40096581}]}]}
{"op":"mcm","clk":"11829646472","pt":1723048959774,"mc":[{"id":"1.231501647","rc":[{"batb":[[0,1.96,46.26],[1,1.81,333],[2,1.74,17.32]],"ltp":1.96,"tv":172.93,"id":40096581}]}]}
{"op":"mcm","clk":"11829648639","pt":1723048979868,"mc":[{"id":"1.231501647","rc":[{"batb":[[0,1.97,10],[1,1.96,46.26],[2,1.81,333]],"ltp":1.96,"tv":172.93,"id":40096581}]}]}
{"op":"mcm","clk":"11829649022","pt":1723048983177,"mc":[{"id":"1.231501647","rc":[{"batb":[[0,1.96,46.26],[1,1.81,333],[2,1.74,17.32]],"ltp":1.96,"tv":172.93,"id":40096581}]}]}
{"op":"mcm","clk":"11829649507","pt":1723048987266,"mc":[{"id":"1.231501647","rc":[{"batb":[[0,1.97,10],[1,1.96,46.26],[2,1.81,333]],"ltp":1.96,"tv":172.93,"id":40096581}]}]}
{"op":"mcm","clk":"11829649832","pt":1723048990577,"mc":[{"id":"1.231501647","rc":[{"batb":[[0,1.96,46.26],[1,1.81,333],[2,1.74,17.32]],"ltp":1.96,"tv":172.93,"id":40096581}]}]}
{"op":"mcm","clk":"11829651889","pt":1723049009524,"mc":[{"id":"1.231501647","rc":[{"batb":[[0,1.97,10],[1,1.96,46.26],[2,1.81,333]],"ltp":1.96,"tv":172.93,"id":40096581}]}]}
{"op":"mcm","clk":"11829652215","pt":1723049012911,"mc":[{"id":"1.231501647","rc":[{"batb":[[0,1.96,46.26],[1,1.81,333],[2,1.74,17.32]],"ltp":1.96,"tv":172.93,"id":40096581}]}]}
{"op":"mcm","clk":"11829654172","pt":1723049033164,"mc":[{"id":"1.231501647","rc":[{"batb":[[0,1.97,10],[1,1.96,46.26],[2,1.81,333]],"ltp":1.96,"tv":172.93,"id":40096581}]}]}
{"op":"mcm","clk":"11829654556","pt":1723049036455,"mc":[{"id":"1.231501647","rc":[{"batb":[[0,1.96,46.26],[1,1.81,333],[2,1.74,17.32]],"ltp":1.96,"tv":172.93,"id":40096581}]}]}
{"op":"mcm","clk":"11829655994","pt":1723049049384,"mc":[{"id":"1.231501647","rc":[{"batb":[[0,1.97,10],[1,1.96,46.26],[2,1.81,333]],"ltp":1.96,"tv":172.93,"id":40096581}]}]}
{"op":"mcm","clk":"11829656357","pt":1723049052685,"mc":[{"id":"1.231501647","rc":[{"batb":[[0,1.96,46.26],[1,1.81,333],[2,1.74,17.32]],"ltp":1.96,"tv":172.93,"id":40096581}]}]}
{"op":"mcm","clk":"11829666085","pt":1723049142982,"mc":[{"id":"1.231501647","rc":[{"batb":[[0,1.97,10],[1,1.96,46.26],[2,1.81,333]],"ltp":1.96,"tv":172.93,"id":40096581}]}]}
{"op":"mcm","clk":"11829666415","pt":1723049146199,"mc":[{"id":"1.231501647","rc":[{"batb":[[0,1.96,46.26],[1,1.81,333],[2,1.74,17.32]],"ltp":1.96,"tv":172.93,"id":40096581}]}]}
{"op":"mcm","clk":"11829667334","pt":1723049153902,"mc":[{"id":"1.231501647","rc":[{"batb":[[0,1.97,10],[1,1.96,46.26],[2,1.81,333]],"ltp":1.96,"tv":172.93,"id":40096581}]}]}
{"op":"mcm","clk":"11829667737","pt":1723049157290,"mc":[{"id":"1.231501647","rc":[{"batb":[[0,1.96,46.26],[1,1.81,333],[2,1.74,17.32]],"ltp":1.96,"tv":172.93,"id":40096581}]}]}
{"op":"mcm","clk":"11829669285","pt":1723049170209,"mc":[{"id":"1.231501647","rc":[{"batb":[[0,1.97,10],[1,1.96,46.26],[2,1.81,333]],"ltp":1.96,"tv":172.93,"id":40096581}]}]}
{"op":"mcm","clk":"11829669568","pt":1723049172656,"mc":[{"id":"1.231501647","rc":[{"batl":[[0,1.99,20],[1,2.02,2]],"ltp":1.96,"tv":172.93,"id":40096581}]}]}
{"op":"mcm","clk":"11829669713","pt":1723049173846,"mc":[{"id":"1.231501647","rc":[{"batb":[[0,1.96,46.26],[1,1.81,333],[2,1.74,17.32]],"ltp":1.96,"tv":172.93,"id":40096581}]}]}
{"op":"mcm","clk":"11829693237","pt":1723049401605,"mc":[{"id":"1.231501647","rc":[{"batb":[[1,1.91,28],[2,1.81,333]],"ltp":1.96,"tv":172.93,"id":40096581}]}]}
{"op":"mcm","clk":"11829693878","pt":1723049408717,"mc":[{"id":"1.231501647","rc":[{"batb":[[1,1.91,28],[2,1.85,111]],"ltp":2.06,"tv":21.38,"id":40096589}]}]}
{"op":"mcm","clk":"11829713507","pt":1723049661974,"mc":[{"id":"1.231501647","rc":[{"batb":[[2,1.85,138.46]],"ltp":1.96,"tv":172.93,"id":40096581}]}]}
{"op":"mcm","clk":"11829730257","pt":1723049881611,"mc":[{"id":"1.231501647","rc":[{"trd":[[1.96,14.72]],"batb":[[0,1.96,46.24]],"ltp":1.96,"tv":172.97,"id":40096581}],"tv":194.36}]}
{"op":"mcm","clk":"11829730470","pt":1723049884816,"mc":[{"id":"1.231501647","rc":[{"batb":[[0,1.96,46.26]],"ltp":1.96,"tv":172.97,"id":40096581}]}]}
{"op":"mcm","clk":"11829730508","pt":1723049885325,"mc":[{"id":"1.231501647","rc":[{"trd":[[1.96,14.76]],"batb":[[0,1.96,46.24]],"ltp":1.96,"tv":173.01,"id":40096581}],"tv":194.4}]}
{"op":"mcm","clk":"11829730812","pt":1723049889841,"mc":[{"id":"1.231501647","rc":[{"batb":[[0,1.96,46.26]],"ltp":1.96,"tv":173.01,"id":40096581}]}]}
{"op":"mcm","clk":"11829768294","pt":1723050320682,"mc":[{"id":"1.231501647","rc":[{"trd":[[2.12,7.17]],"ltp":2.06,"tv":21.39,"id":40096589},{"trd":[[1.96,54.76]],"batb":[[0,1.96,26.26]],"ltp":1.96,"tv":213.01,"id":40096581}],"tv":234.41}]}
{"op":"mcm","clk":"11829768408","pt":1723050321835,"mc":[{"id":"1.231501647","rc":[{"batb":[[0,1.96,46.26]],"ltp":1.96,"tv":213.01,"id":40096581}]}]}
{"op":"mcm","clk":"11829804925","pt":1723050706061,"mc":[{"id":"1.231501647","rc":[{"trd":[[1.96,56.86]],"batb":[[0,1.96,45.21]],"ltp":1.96,"tv":215.11,"id":40096581}],"tv":236.51}]}
{"op":"mcm","clk":"11829805143","pt":1723050708356,"mc":[{"id":"1.231501647","rc":[{"batb":[[0,1.96,46.26]],"ltp":1.96,"tv":215.11,"id":40096581}]}]}
{"op":"mcm","clk":"11829810893","pt":1723050767327,"mc":[{"id":"1.231501647","rc":[{"batl":[[0,1.98,2000],[1,1.99,20],[2,2.02,2]],"ltp":1.96,"tv":215.11,"id":40096581}]}]}
{"op":"mcm","clk":"11829821242","pt":1723050780324,"mc":[{"id":"1.231501647","rc":[{"batl":[[0,1.99,20.58],[1,2.02,2],[2,2.02,0]],"ltp":1.96,"tv":215.11,"id":40096581}]}]}
{"op":"mcm","clk":"11829822980","pt":1723050797559,"mc":[{"id":"1.231501647","rc":[{"batb":[[0,1.97,2000],[1,1.96,46.26],[2,1.91,28]],"ltp":1.96,"tv":215.11,"id":40096581}]}]}
{"op":"mcm","clk":"11829823086","pt":1723050798760,"mc":[{"id":"1.231501647","rc":[{"batb":[[1,1.91,28],[2,1.85,138.46]],"ltp":1.96,"tv":215.11,"id":40096581}]}]}
{"op":"mcm","clk":"11829823914","pt":1723050807770,"mc":[{"id":"1.231501647","rc":[{"batb":[[0,1.91,28.58],[1,1.85,138.46],[2,1.81,333]],"ltp":1.96,"tv":215.11,"id":40096581}]}]}
{"op":"mcm","clk":"11829823998","pt":1723050808660,"mc":[{"id":"1.231501647","rc":[{"batb":[[0,1.96,46.84],[1,1.91,28],[2,1.85,138.46]],"ltp":1.96,"tv":215.11,"id":40096581}]}]}
{"op":"mcm","clk":"11829832433","pt":1723050899840,"mc":[{"id":"1.231501647","rc":[{"batb":[[0,1.96,46.26]],"batl":[[0,1.99,20]],"ltp":1.96,"tv":215.11,"id":40096581}]}]}
{"op":"mcm","clk":"11829863110","pt":1723051242713,"mc":[{"id":"1.231501647","rc":[{"trd":[[1.99,40]],"batb":[[0,1.97,10],[1,1.96,46.26],[2,1.91,28]],"batl":[[0,2.02,2],[1,2.02,0]],"ltp":1.99,"tv":255.11,"id":40096581}],"tv":276.51}]}
{"op":"mcm","clk":"11829863423","pt":1723051246325,"mc":[{"id":"1.231501647","rc":[{"batb":[[0,1.96,46.26],[1,1.91,28],[2,1.85,138.46]],"ltp":1.99,"tv":255.11,"id":40096581}]}]}
{"op":"mcm","clk":"11829863868","pt":1723051251263,"mc":[{"id":"1.231501647","rc":[{"trd":[[2.02,4]],"ltp":2.02,"tv":259.11,"id":40096581}],"tv":280.51}]}
{"op":"mcm","clk":"11829865225","pt":1723051266530,"mc":[{"id":"1.231501647","rc":[{"batb":[[0,1.97,10],[1,1.96,46.26],[2,1.91,28]],"batl":[[0,2.02,2000]],"ltp":2.02,"tv":259.11,"id":40096581}]}]}
{"op":"mcm","clk":"11829865526","pt":1723051269766,"mc":[{"id":"1.231501647","rc":[{"batb":[[0,1.96,46.26],[1,1.91,28],[2,1.85,138.46]],"ltp":2.02,"tv":259.11,"id":40096581}]}]}
{"op":"mcm","clk":"11829866210","pt":1723051277180,"mc":[{"id":"1.231501647","rc":[{"batb":[[0,1.97,10],[1,1.96,46.26],[2,1.91,28]],"batl":[[0,2.02,0.58]],"ltp":2.02,"tv":259.11,"id":40096581}]}]}
{"op":"mcm","clk":"11829866520","pt":1723051280507,"mc":[{"id":"1.231501647","rc":[{"batb":[[0,1.96,46.26],[1,1.91,28],[2,1.85,138.46]],"ltp":2.02,"tv":259.11,"id":40096581}]}]}
{"op":"mcm","clk":"11829868165","pt":1723051296800,"mc":[{"id":"1.231501647","rc":[{"batb":[[0,1.97,2000],[1,1.96,46.26],[2,1.91,28]],"ltp":2.02,"tv":259.11,"id":40096581}]}]}
{"op":"mcm","clk":"11829868527","pt":1723051300788,"mc":[{"id":"1.231501647","rc":[{"batb":[[1,1.91,28],[2,1.85,138.46]],"ltp":2.02,"tv":259.11,"id":40096581}]}]}
{"op":"mcm","clk":"11829869112","pt":1723051307793,"mc":[{"id":"1.231501647","rc":[{"batb":[[0,1.92,10.58]],"ltp":2.02,"tv":259.11,"id":40096581}]}]}
{"op":"mcm","clk":"11829869369","pt":1723051310788,"mc":[{"id":"1.231501647","rc":[{"batb":[[0,1.96,46.84],[1,1.92,10],[2,1.91,28]],"ltp":2.02,"tv":259.11,"id":40096581}]}]}
{"op":"mcm","clk":"11829869404","pt":1723051311203,"mc":[{"id":"1.231501647","rc":[{"batb":[[1,1.91,28],[2,1.85,138.46]],"ltp":2.02,"tv":259.11,"id":40096581}]}]}
{"op":"mcm","clk":"11829870506","pt":1723051323627,"mc":[{"id":"1.231501647","rc":[{"batb":[[0,1.97,10.58],[1,1.96,46.26],[2,1.91,28]],"ltp":2.02,"tv":259.11,"id":40096581}]}]}
{"op":"mcm","clk":"11829870634","pt":1723051324899,"mc":[{"id":"1.231501647","rc":[{"batb":[[0,1.97,10]],"ltp":2.02,"tv":259.11,"id":40096581}]}]}
{"op":"mcm","clk":"11829870815","pt":1723051327116,"mc":[{"id":"1.231501647","rc":[{"batb":[[0,1.96,46.26],[1,1.91,28],[2,1.85,138.46]],"ltp":2.02,"tv":259.11,"id":40096581}]}]}
{"op":"mcm","clk":"11829871634","pt":1723051336435,"mc":[{"id":"1.231501647","rc":[{"batl":[[0,1.99,10]],"ltp":2.02,"tv":259.11,"id":40096581}]}]}
{"op":"mcm","clk":"11830120989","pt":1723054016904,"mc":[{"id":"1.231501647","rc":[{"trd":[[2.12,7.17]],"ltp":2.06,"tv":21.39,"id":40096589},{"batb":[[0,1.98,2.04],[1,1.96,46.26],[2,1.91,28]],"ltp":2.02,"tv":259.11,"id":40096581}],"tv":280.51}]}
{"op":"mcm","clk":"11830122595","pt":1723054034581,"mc":[{"id":"1.231501647","rc":[{"trd":[[1.98,4]],"batb":[[0,1.96,46.3],[1,1.91,28],[2,1.85,138.46]],"ltp":1.98,"tv":263.11,"id":40096581}],"tv":284.51}]}
{"op":"mcm","clk":"11830175790","pt":1723054536105,"mc":[{"id":"1.231501647","rc":[{"batl":[[1,2.02,2]],"ltp":1.98,"tv":263.11,"id":40096581}]}]}
{"op":"mcm","clk":"11830258069","pt":1723055372138,"mc":[{"id":"1.231501647","rc":[{"trd":[[1.99,40.08]],"batb":[[0,1.96,46.26]],"batl":[[0,1.99,9.96]],"ltp":1.99,"tv":263.19,"id":40096581}],"tv":284.59}]}
{"op":"mcm","clk":"11830705713","pt":1723059060033,"mc":[{"id":"1.231501647","rc":[{"trd":[[2,10.17],[2.12,7.18]],"batl":[[0,2,49.9]],"ltp":2.0,"tv":31.31,"id":40096589},{"trd":[[1.99,50.04]],"batb":[[0,1.97,10],[1,1.96,46.26],[2,1.91,28]],"batl":[[0,2.02,2],[1,2.02,0]],"ltp":1.99,"tv":273.15,"id":40096581}],"tv":304.47}]}
{"op":"mcm","clk":"11830706035","pt":1723059063530,"mc":[{"id":"1.231501647","rc":[{"batb":[[0,1.96,46.26],[1,1.91,28],[2,1.85,138.46]],"ltp":1.99,"tv":273.15,"id":40096581}]}]}
{"op":"mcm","clk":"11830708383","pt":1723059092283,"mc":[{"id":"1.231501647","rc":[{"trd":[[2,20.17]],"batl":[[0,2,44.9]],"ltp":2.0,"tv":41.31,"id":40096589},{"batb":[[0,1.97,10],[1,1.96,46.26],[2,1.91,28]],"ltp":1.99,"tv":273.15,"id":40096581}],"tv":314.47}]}
{"op":"mcm","clk":"11830708627","pt":1723059095567,"mc":[{"id":"1.231501647","rc":[{"batb":[[0,1.96,46.26],[1,1.91,28],[2,1.85,138.46]],"ltp":1.99,"tv":273.15,"id":40096581}]}]}
{"op":"mcm","clk":"11830709163","pt":1723059102884,"mc":[{"id":"1.231501647","rc":[{"batb":[[0,1.99,2.5],[1,1.98,45.31],[2,1.91,28]],"ltp":2.0,"tv":41.31,"id":40096589},{"batb":[[0,1.97,10],[1,1.96,46.26],[2,1.91,28]],"ltp":1.99,"tv":273.15,"id":40096581}]}]}
{"op":"mcm","clk":"11830709387","pt":1723059106156,"mc":[{"id":"1.231501647","rc":[{"batb":[[0,1.96,46.26],[1,1.91,28],[2,1.85,138.46]],"ltp":1.99,"tv":273.15,"id":40096581}]}]}
{"op":"mcm","clk":"11830714687","pt":1723059179192,"mc":[{"id":"1.231501647","rc":[{"trd":[[2,26.17]],"batl":[[0,2,41.9]],"ltp":2.0,"tv":47.31,"id":40096589},{"batb":[[0,1.97,10],[1,1.96,46.26],[2,1.91,28]],"ltp":1.99,"tv":273.15,"id":40096581}],"tv":320.47}]}
{"op":"mcm","clk":"11830715054","pt":1723059182698,"mc":[{"id":"1.231501647","rc":[{"batb":[[0,1.96,46.26],[1,1.91,28],[2,1.85,138.46]],"ltp":1.99,"tv":273.15,"id":40096581}]}]}
{"op":"mcm","clk":"11830715572","pt":1723059188315,"mc":[{"id":"1.231501647","rc":[{"trd":[[2,30.17]],"batl":[[0,2,39.9]],"ltp":2.0,"tv":51.31,"id":40096589},{"batb":[[0,1.97,10],[1,1.96,46.26],[2,1.91,28]],"ltp":1.99,"tv":273.15,"id":40096581}],"tv":324.47}]}
{"op":"mcm","clk":"11830715858","pt":1723059191691,"mc":[{"id":"1.231501647","rc":[{"batb":[[0,1.96,46.26],[1,1.91,28],[2,1.85,138.46]],"ltp":1.99,"tv":273.15,"id":40096581}]}]}
{"op":"mcm","clk":"11830728877","pt":1723059351783,"mc":[{"id":"1.231501647","rc":[{"batb":[[0,1.97,10],[1,1.96,46.26],[2,1.91,28]],"ltp":1.99,"tv":273.15,"id":40096581}]}]}
{"op":"mcm","clk":"11830729199","pt":1723059355572,"mc":[{"id":"1.231501647","rc":[{"batb":[[0,1.96,46.26],[1,1.91,28],[2,1.85,138.46]],"ltp":1.99,"tv":273.15,"id":40096581}]}]}
{"op":"mcm","clk":"11830753418","pt":1723059603103,"mc":[{"id":"1.231501647","rc":[{"batb":[[0,1.97,10],[1,1.96,46.26],[2,1.91,28]],"ltp":1.99,"tv":273.15,"id":40096581}]}]}
{"op":"mcm","clk":"11830753939","pt":1723059607590,"mc":[{"id":"1.231501647","rc":[{"batb":[[0,1.96,46.26],[1,1.91,28],[2,1.85,138.46]],"ltp":1.99,"tv":273.15,"id":40096581}]}]}
{"op":"mcm","clk":"11830818602","pt":1723060279568,"mc":[{"id":"1.231501647","rc":[{"batb":[[0,1.97,10],[1,1.96,46.26],[2,1.91,28]],"ltp":1.99,"tv":273.15,"id":40096581}]}]}
{"op":"mcm","clk":"11830818937","pt":1723060283355,"mc":[{"id":"1.231501647","rc":[{"batb":[[0,1.96,46.26],[1,1.91,28],[2,1.85,138.46]],"ltp":1.99,"tv":273.15,"id":40096581}]}]}
{"op":"mcm","clk":"11830875750","pt":1723060923882,"mc":[{"id":"1.231501647","rc":[{"trd":[[2,30.16]],"batl":[[0,2,39.89]],"ltp":2.0,"tv":51.3,"id":40096589},{"batb":[[0,1.97,10],[1,1.96,46.26],[2,1.91,28]],"ltp":1.99,"tv":273.15,"id":40096581}],"tv":324.46}]}
{"op":"mcm","clk":"11830876107","pt":1723060928190,"mc":[{"id":"1.231501647","rc":[{"batb":[[0,1.96,46.26],[1,1.91,28],[2,1.85,138.46]],"ltp":1.99,"tv":273.15,"id":40096581}]}]}
{"op":"mcm","clk":"11830922295","pt":1723061488926,"mc":[{"id":"1.231501647","rc":[{"trd":[[2,70.05]],"ltp":2.0,"tv":91.19,"id":40096589},{"trd":[[2,40.15]],"batl":[[0,1.99,20.11],[1,2.02,2]],"ltp":2.0,"tv":313.04,"id":40096581}],"tv":404.24}]}
{"op":"mcm","clk":"11830922949","pt":1723061496833,"mc":[{"id":"1.231501647","rc":[{"trd":[[1.96,97.08]],"batb":[[0,1.97,10],[1,1.96,46.26],[2,1.91,28]],"batl":[[0,2.02,2],[1,2.02,0]],"ltp":1.96,"tv":353.26,"id":40096581}],"tv":444.46}]}
{"op":"mcm","clk":"11830923227","pt":1723061499841,"mc":[{"id":"1.231501647","rc":[{"batb":[[0,1.96,46.26],[1,1.91,28],[2,1.85,138.46]],"ltp":1.96,"tv":353.26,"id":40096581}]}]}
{"op":"mcm","clk":"11830942540","pt":1723061608477,"mc":[{"id":"1.231501647","rc":[{"batb":[[0,1.97,10],[1,1.96,46.26],[2,1.91,28]],"ltp":1.96,"tv":353.26,"id":40096581}]}]}
{"op":"mcm","clk":"11830942949","pt":1723061612460,"mc":[{"id":"1.231501647","rc":[{"batb":[[0,1.96,46.26],[1,1.91,28],[2,1.85,138.46]],"ltp":1.96,"tv":353.26,"id":40096581}]}]}
{"op":"mcm","clk":"11830975137","pt":1723061978085,"mc":[{"id":"1.231501647","rc":[{"batb":[[0,1.97,10],[1,1.96,46.26],[2,1.91,28]],"ltp":1.96,"tv":353.26,"id":40096581}]}]}
{"op":"mcm","clk":"11830975425","pt":1723061981489,"mc":[{"id":"1.231501647","rc":[{"batb":[[0,1.96,46.26],[1,1.91,28],[2,1.85,138.46]],"ltp":1.96,"tv":353.26,"id":40096581}]}]}
{"op":"mcm","clk":"11830977428","pt":1723062004846,"mc":[{"id":"1.231501647","rc":[{"batb":[[0,1.97,10],[1,1.96,46.26],[2,1.91,28]],"ltp":1.96,"tv":353.26,"id":40096581}]}]}
{"op":"mcm","clk":"11830977719","pt":1723062008243,"mc":[{"id":"1.231501647","rc":[{"batb":[[0,1.96,46.26],[1,1.91,28],[2,1.85,138.46]],"ltp":1.96,"tv":353.26,"id":40096581}]}]}
{"op":"mcm","clk":"11830979686","pt":1723062033385,"mc":[{"id":"1.231501647","rc":[{"batb":[[0,1.97,10],[1,1.96,46.26],[2,1.91,28]],"ltp":1.96,"tv":353.26,"id":40096581}]}]}
{"op":"mcm","clk":"11830979982","pt":1723062036952,"mc":[{"id":"1.231501647","rc":[{"batb":[[0,1.96,46.26],[1,1.91,28],[2,1.85,138.46]],"ltp":1.96,"tv":353.26,"id":40096581}]}]}
{"op":"mcm","clk":"11830980808","pt":1723062047267,"mc":[{"id":"1.231501647","rc":[{"batb":[[0,1.97,10],[1,1.96,46.26],[2,1.91,28]],"ltp":1.96,"tv":353.26,"id":40096581}]}]}
{"op":"mcm","clk":"11830981134","pt":1723062051078,"mc":[{"id":"1.231501647","rc":[{"batb":[[0,1.96,46.26],[1,1.91,28],[2,1.85,138.46]],"ltp":1.96,"tv":353.26,"id":40096581}]}]}
{"op":"mcm","clk":"11830981661","pt":1723062057811,"mc":[{"id":"1.231501647","rc":[{"batb":[[0,1.97,10],[1,1.96,46.26],[2,1.91,28]],"ltp":1.96,"tv":353.26,"id":40096581}]}]}
{"op":"mcm","clk":"11830981898","pt":1723062061119,"mc":[{"id":"1.231501647","rc":[{"batb":[[0,1.96,46.26],[1,1.91,28],[2,1.85,138.46]],"ltp":1.96,"tv":353.26,"id":40096581}]}]}
{"op":"mcm","clk":"11830982116","pt":1723062064115,"mc":[{"id":"1.231501647","rc":[{"batb":[[0,1.97,10],[1,1.96,46.26],[2,1.91,28]],"ltp":1.96,"tv":353.26,"id":40096581}]}]}
{"op":"mcm","clk":"11830982359","pt":1723062067514,"mc":[{"id":"1.231501647","rc":[{"batb":[[0,1.96,46.26],[1,1.91,28],[2,1.85,138.46]],"ltp":1.96,"tv":353.26,"id":40096581}]}]}
{"op":"mcm","clk":"11830983129","pt":1723062077107,"mc":[{"id":"1.231501647","rc":[{"batb":[[0,1.97,10],[1,1.96,46.26],[2,1.91,28]],"ltp":1.96,"tv":353.26,"id":40096581}]}]}
{"op":"mcm","clk":"11830983468","pt":1723062081911,"mc":[{"id":"1.231501647","rc":[{"batb":[[0,1.96,46.26],[1,1.91,28],[2,1.85,138.46]],"ltp":1.96,"tv":353.26,"id":40096581}]}]}
{"op":"mcm","clk":"11830983720","pt":1723062085320,"mc":[{"id":"1.231501647","rc":[{"batb":[[0,1.97,10],[1,1.96,46.26],[2,1.91,28]],"ltp":1.96,"tv":353.26,"id":40096581}]}]}
{"op":"mcm","clk":"11830983952","pt":1723062088638,"mc":[{"id":"1.231501647","rc":[{"batb":[[0,1.96,46.26],[1,1.91,28],[2,1.85,138.46]],"ltp":1.96,"tv":353.26,"id":40096581}]}]}
{"op":"mcm","clk":"11830984288","pt":1723062092626,"mc":[{"id":"1.231501647","rc":[{"batb":[[0,1.97,10],[1,1.96,46.26],[2,1.91,28]],"ltp":1.96,"tv":353.26,"id":40096581}]}]}
{"op":"mcm","clk":"11830984678","pt":1723062096970,"mc":[{"id":"1.231501647","rc":[{"batb":[[0,1.96,46.26],[1,1.91,28],[2,1.85,138.46]],"ltp":1.96,"tv":353.26,"id":40096581}]}]}
{"op":"mcm","clk":"11830984909","pt":1723062099242,"mc":[{"id":"1.231501647","rc":[{"batb":[[0,1.97,10],[1,1.96,46.26],[2,1.91,28]],"ltp":1.96,"tv":353.26,"id":40096581}]}]}
{"op":"mcm","clk":"11830985251","pt":1723062102861,"mc":[{"id":"1.231501647","rc":[{"batb":[[0,1.96,46.26],[1,1.91,28],[2,1.85,138.46]],"ltp":1.96,"tv":353.26,"id":40096581}]}]}
{"op":"mcm","clk":"11830985639","pt":1723062106938,"mc":[{"id":"1.231501647","rc":[{"batb":[[0,1.97,10],[1,1.96,46.26],[2,1.91,28]],"ltp":1.96,"tv":353.26,"id":40096581}]}]}
{"op":"mcm","clk":"11830985911","pt":1723062110450,"mc":[{"id":"1.231501647","rc":[{"batb":[[0,1.96,46.26],[1,1.91,28],[2,1.85,138.46]],"ltp":1.96,"tv":353.26,"id":40096581}]}]}
{"op":"mcm","clk":"11830986186","pt":1723062113447,"mc":[{"id":"1.231501647","rc":[{"batb":[[0,1.97,10],[1,1.96,46.26],[2,1.91,28]],"ltp":1.96,"tv":353.26,"id":40096581}]}]}
{"op":"mcm","clk":"11830986455","pt":1723062116975,"mc":[{"id":"1.231501647","rc":[{"batb":[[0,1.96,46.26],[1,1.91,28],[2,1.85,138.46]],"ltp":1.96,"tv":353.26,"id":40096581}]}]}
{"op":"mcm","clk":"11830986646","pt":1723062119347,"mc":[{"id":"1.231501647","rc":[{"batb":[[0,1.97,10],[1,1.96,46.26],[2,1.91,28]],"ltp":1.96,"tv":353.26,"id":40096581}]}]}
{"op":"mcm","clk":"11830986884","pt":1723062122881,"mc":[{"id":"1.231501647","rc":[{"batb":[[0,1.96,46.26],[1,1.91,28],[2,1.85,138.46]],"ltp":1.96,"tv":353.26,"id":40096581}]}]}
{"op":"mcm","clk":"11830987130","pt":1723062126289,"mc":[{"id":"1.231501647","rc":[{"batb":[[0,1.97,10],[1,1.96,46.26],[2,1.91,28]],"ltp":1.96,"tv":353.26,"id":40096581}]}]}
{"op":"mcm","clk":"11830987428","pt":1723062129858,"mc":[{"id":"1.231501647","rc":[{"batb":[[0,1.96,46.26],[1,1.91,28],[2,1.85,138.46]],"ltp":1.96,"tv":353.26,"id":40096581}]}]}
{"op":"mcm","clk":"11830987574","pt":1723062132282,"mc":[{"id":"1.231501647","rc":[{"batb":[[0,1.97,10],[1,1.96,46.26],[2,1.91,28]],"ltp":1.96,"tv":353.26,"id":40096581}]}]}
{"op":"mcm","clk":"11830987862","pt":1723062135887,"mc":[{"id":"1.231501647","rc":[{"batb":[[0,1.96,46.26],[1,1.91,28],[2,1.85,138.46]],"ltp":1.96,"tv":353.26,"id":40096581}]}]}
{"op":"mcm","clk":"11830988046","pt":1723062138264,"mc":[{"id":"1.231501647","rc":[{"batb":[[0,1.97,10],[1,1.96,46.26],[2,1.91,28]],"ltp":1.96,"tv":353.26,"id":40096581}]}]}
{"op":"mcm","clk":"11830988293","pt":1723062141775,"mc":[{"id":"1.231501647","rc":[{"batb":[[0,1.96,46.26],[1,1.91,28],[2,1.85,138.46]],"ltp":1.96,"tv":353.26,"id":40096581}]}]}
{"op":"mcm","clk":"11830988591","pt":1723062145099,"mc":[{"id":"1.231501647","rc":[{"batb":[[0,1.97,10],[1,1.96,46.26],[2,1.91,28]],"ltp":1.96,"tv":353.26,"id":40096581}]}]}
{"op":"mcm","clk":"11830988949","pt":1723062148993,"mc":[{"id":"1.231501647","rc":[{"batb":[[0,1.96,46.26],[1,1.91,28],[2,1.85,138.46]],"ltp":1.96,"tv":353.26,"id":40096581}]}]}
{"op":"mcm","clk":"11830989160","pt":1723062151617,"mc":[{"id":"1.231501647","rc":[{"batb":[[0,1.97,10],[1,1.96,46.26],[2,1.91,28]],"ltp":1.96,"tv":353.26,"id":40096581}]}]}
{"op":"mcm","clk":"11830989377","pt":1723062154913,"mc":[{"id":"1.231501647","rc":[{"batb":[[0,1.96,46.26],[1,1.91,28],[2,1.85,138.46]],"ltp":1.96,"tv":353.26,"id":40096581}]}]}
{"op":"mcm","clk":"11830989640","pt":1723062158512,"mc":[{"id":"1.231501647","rc":[{"batb":[[0,1.97,10],[1,1.96,46.26],[2,1.91,28]],"ltp":1.96,"tv":353.26,"id":40096581}]}]}
{"op":"mcm","clk":"11830989904","pt":1723062161813,"mc":[{"id":"1.231501647","rc":[{"batb":[[0,1.96,46.26],[1,1.91,28],[2,1.85,138.46]],"ltp":1.96,"tv":353.26,"id":40096581}]}]}
{"op":"mcm","clk":"11830990130","pt":1723062164495,"mc":[{"id":"1.231501647","rc":[{"batb":[[0,1.97,10],[1,1.96,46.26],[2,1.91,28]],"ltp":1.96,"tv":353.26,"id":40096581}]}]}
{"op":"mcm","clk":"11830990363","pt":1723062167531,"mc":[{"id":"1.231501647","rc":[{"batb":[[0,1.96,46.26],[1,1.91,28],[2,1.85,138.46]],"ltp":1.96,"tv":353.26,"id":40096581}]}]}
{"op":"mcm","clk":"11830990560","pt":1723062170416,"mc":[{"id":"1.231501647","rc":[{"batb":[[0,1.97,10],[1,1.96,46.26],[2,1.91,28]],"ltp":1.96,"tv":353.26,"id":40096581}]}]}
{"op":"mcm","clk":"11830990873","pt":1723062174636,"mc":[{"id":"1.231501647","rc":[{"batb":[[0,1.96,46.26],[1,1.91,28],[2,1.85,138.46]],"ltp":1.96,"tv":353.26,"id":40096581}]}]}
{"op":"mcm","clk":"11830991067","pt":1723062177517,"mc":[{"id":"1.231501647","rc":[{"batb":[[0,1.97,10],[1,1.96,46.26],[2,1.91,28]],"ltp":1.96,"tv":353.26,"id":40096581}]}]}
{"op":"mcm","clk":"11830991286","pt":1723062180516,"mc":[{"id":"1.231501647","rc":[{"batb":[[0,1.96,46.26],[1,1.91,28],[2,1.85,138.46]],"ltp":1.96,"tv":353.26,"id":40096581}]}]}
{"op":"mcm","clk":"11830991503","pt":1723062183411,"mc":[{"id":"1.231501647","rc":[{"batb":[[0,1.97,10],[1,1.96,46.26],[2,1.91,28]],"ltp":1.96,"tv":353.26,"id":40096581}]}]}
{"op":"mcm","clk":"11830991771","pt":1723062186916,"mc":[{"id":"1.231501647","rc":[{"batb":[[0,1.96,46.26],[1,1.91,28],[2,1.85,138.46]],"ltp":1.96,"tv":353.26,"id":40096581}]}]}
{"op":"mcm","clk":"11830991971","pt":1723062189544,"mc":[{"id":"1.231501647","rc":[{"batb":[[0,1.97,10],[1,1.96,46.26],[2,1.91,28]],"ltp":1.96,"tv":353.26,"id":40096581}]}]}
{"op":"mcm","clk":"11830992249","pt":1723062193044,"mc":[{"id":"1.231501647","rc":[{"batb":[[0,1.96,46.26],[1,1.91,28],[2,1.85,138.46]],"ltp":1.96,"tv":353.26,"id":40096581}]}]}
{"op":"mcm","clk":"11830992510","pt":1723062196544,"mc":[{"id":"1.231501647","rc":[{"batb":[[0,1.97,10],[1,1.96,46.26],[2,1.91,28]],"ltp":1.96,"tv":353.26,"id":40096581}]}]}
{"op":"mcm","clk":"11830992759","pt":1723062199950,"mc":[{"id":"1.231501647","rc":[{"batb":[[0,1.96,46.26],[1,1.91,28],[2,1.85,138.46]],"ltp":1.96,"tv":353.26,"id":40096581}]}]}
{"op":"mcm","clk":"11830992957","pt":1723062202371,"mc":[{"id":"1.231501647","rc":[{"batb":[[0,1.97,10],[1,1.96,46.26],[2,1.91,28]],"ltp":1.96,"tv":353.26,"id":40096581}]}]}
{"op":"mcm","clk":"11830993190","pt":1723062205765,"mc":[{"id":"1.231501647","rc":[{"batb":[[0,1.96,46.26],[1,1.91,28],[2,1.85,138.46]],"ltp":1.96,"tv":353.26,"id":40096581}]}]}
{"op":"mcm","clk":"11830993455","pt":1723062209575,"mc":[{"id":"1.231501647","rc":[{"batb":[[0,1.97,10],[1,1.96,46.26],[2,1.91,28]],"ltp":1.96,"tv":353.26,"id":40096581}]}]}
{"op":"mcm","clk":"11830993696","pt":1723062212974,"mc":[{"id":"1.231501647","rc":[{"batb":[[0,1.96,46.26],[1,1.91,28],[2,1.85,138.46]],"ltp":1.96,"tv":353.26,"id":40096581}]}]}
{"op":"mcm","clk":"11830993911","pt":1723062215678,"mc":[{"id":"1.231501647","rc":[{"batb":[[0,1.97,10],[1,1.96,46.26],[2,1.91,28]],"ltp":1.96,"tv":353.26,"id":40096581}]}]}
{"op":"mcm","clk":"11830994147","pt":1723062219056,"mc":[{"id":"1.231501647","rc":[{"batb":[[0,1.96,46.26],[1,1.91,28],[2,1.85,138.46]],"ltp":1.96,"tv":353.26,"id":40096581}]}]}
{"op":"mcm","clk":"11830994314","pt":1723062221573,"mc":[{"id":"1.231501647","rc":[{"batb":[[0,1.97,10],[1,1.96,46.26],[2,1.91,28]],"ltp":1.96,"tv":353.26,"id":40096581}]}]}
{"op":"mcm","clk":"11830994514","pt":1723062224911,"mc":[{"id":"1.231501647","rc":[{"batb":[[0,1.96,46.26],[1,1.91,28],[2,1.85,138.46]],"ltp":1.96,"tv":353.26,"id":40096581}]}]}
{"op":"mcm","clk":"11830994681","pt":1723062227635,"mc":[{"id":"1.231501647","rc":[{"batb":[[0,1.97,10],[1,1.96,46.26],[2,1.91,28]],"ltp":1.96,"tv":353.26,"id":40096581}]}]}
{"op":"mcm","clk":"11830994870","pt":1723062231127,"mc":[{"id":"1.231501647","rc":[{"batb":[[0,1.96,46.26],[1,1.91,28],[2,1.85,138.46]],"ltp":1.96,"tv":353.26,"id":40096581}]}]}
{"op":"mcm","clk":"11830995027","pt":1723062233648,"mc":[{"id":"1.231501647","rc":[{"batb":[[0,1.97,10],[1,1.96,46.26],[2,1.91,28]],"ltp":1.96,"tv":353.26,"id":40096581}]}]}
{"op":"mcm","clk":"11830995236","pt":1723062237243,"mc":[{"id":"1.231501647","rc":[{"batb":[[0,1.96,46.26],[1,1.91,28],[2,1.85,138.46]],"ltp":1.96,"tv":353.26,"id":40096581}]}]}
{"op":"mcm","clk":"11830995424","pt":1723062240328,"mc":[{"id":"1.231501647","rc":[{"batb":[[0,1.97,10],[1,1.96,46.26],[2,1.91,28]],"ltp":1.96,"tv":353.26,"id":40096581}]}]}
{"op":"mcm","clk":"11830995658","pt":1723062243928,"mc":[{"id":"1.231501647","rc":[{"batb":[[0,1.96,46.26],[1,1.91,28],[2,1.85,138.46]],"ltp":1.96,"tv":353.26,"id":40096581}]}]}
{"op":"mcm","clk":"11830995888","pt":1723062246758,"mc":[{"id":"1.231501647","rc":[{"batb":[[0,1.97,10],[1,1.96,46.26],[2,1.91,28]],"ltp":1.96,"tv":353.26,"id":40096581}]}]}
{"op":"mcm","clk":"11830996127","pt":1723062250260,"mc":[{"id":"1.231501647","rc":[{"batb":[[0,1.96,46.26],[1,1.91,28],[2,1.85,138.46]],"ltp":1.96,"tv":353.26,"id":40096581}]}]}
{"op":"mcm","clk":"11830996325","pt":1723062253082,"mc":[{"id":"1.231501647","rc":[{"batb":[[0,1.97,10],[1,1.96,46.26],[2,1.91,28]],"ltp":1.96,"tv":353.26,"id":40096581}]}]}
{"op":"mcm","clk":"11830996580","pt":1723062256885,"mc":[{"id":"1.231501647","rc":[{"batb":[[0,1.96,46.26],[1,1.91,28],[2,1.85,138.46]],"ltp":1.96,"tv":353.26,"id":40096581}]}]}
{"op":"mcm","clk":"11830996758","pt":1723062259677,"mc":[{"id":"1.231501647","rc":[{"batb":[[0,1.97,10],[1,1.96,46.26],[2,1.91,28]],"ltp":1.96,"tv":353.26,"id":40096581}]}]}
{"op":"mcm","clk":"11830996972","pt":1723062263182,"mc":[{"id":"1.231501647","rc":[{"batb":[[0,1.96,46.26],[1,1.91,28],[2,1.85,138.46]],"ltp":1.96,"tv":353.26,"id":40096581}]}]}
{"op":"mcm","clk":"11830997283","pt":1723062267164,"mc":[{"id":"1.231501647","rc":[{"batb":[[0,1.97,10],[1,1.96,46.26],[2,1.91,28]],"ltp":1.96,"tv":353.26,"id":40096581}]}]}
{"op":"mcm","clk":"11830997490","pt":1723062270597,"mc":[{"id":"1.231501647","rc":[{"batb":[[0,1.96,46.26],[1,1.91,28],[2,1.85,138.46]],"ltp":1.96,"tv":353.26,"id":40096581}]}]}
{"op":"mcm","clk":"11830997677","pt":1723062273582,"mc":[{"id":"1.231501647","rc":[{"batb":[[0,1.97,10],[1,1.96,46.26],[2,1.91,28]],"ltp":1.96,"tv":353.26,"id":40096581}]}]}
{"op":"mcm","clk":"11830997937","pt":1723062277126,"mc":[{"id":"1.231501647","rc":[{"batb":[[0,1.96,46.26],[1,1.91,28],[2,1.85,138.46]],"ltp":1.96,"tv":353.26,"id":40096581}]}]}
{"op":"mcm","clk":"11830998150","pt":1723062280692,"mc":[{"id":"1.231501647","rc":[{"batb":[[0,1.97,10],[1,1.96,46.26],[2,1.91,28]],"ltp":1.96,"tv":353.26,"id":40096581}]}]}
{"op":"mcm","clk":"11830998335","pt":1723062284237,"mc":[{"id":"1.231501647","rc":[{"batb":[[0,1.96,46.26],[1,1.91,28],[2,1.85,138.46]],"ltp":1.96,"tv":353.26,"id":40096581}]}]}
{"op":"mcm","clk":"11830998464","pt":1723062286402,"mc":[{"id":"1.231501647","rc":[{"batb":[[0,1.97,10],[1,1.96,46.26],[2,1.91,28]],"ltp":1.96,"tv":353.26,"id":40096581}]}]}
{"op":"mcm","clk":"11830998626","pt":1723062289824,"mc":[{"id":"1.231501647","rc":[{"batb":[[0,1.96,46.26],[1,1.91,28],[2,1.85,138.46]],"ltp":1.96,"tv":353.26,"id":40096581}]}]}
{"op":"mcm","clk":"11830998903","pt":1723062294737,"mc":[{"id":"1.231501647","rc":[{"batb":[[0,1.97,10],[1,1.96,46.26],[2,1.91,28]],"ltp":1.96,"tv":353.26,"id":40096581}]}]}
{"op":"mcm","clk":"11830999111","pt":1723062298132,"mc":[{"id":"1.231501647","rc":[{"batb":[[0,1.96,46.26],[1,1.91,28],[2,1.85,138.46]],"ltp":1.96,"tv":353.26,"id":40096581}]}]}
{"op":"mcm","clk":"11830999275","pt":1723062300754,"mc":[{"id":"1.231501647","rc":[{"batb":[[0,1.97,10],[1,1.96,46.26],[2,1.91,28]],"ltp":1.96,"tv":353.26,"id":40096581}]}]}
{"op":"mcm","clk":"11830999515","pt":1723062304464,"mc":[{"id":"1.231501647","rc":[{"batb":[[0,1.96,46.26],[1,1.91,28],[2,1.85,138.46]],"ltp":1.96,"tv":353.26,"id":40096581}]}]}
{"op":"mcm","clk":"11830999745","pt":1723062307761,"mc":[{"id":"1.231501647","rc":[{"batb":[[0,1.97,10],[1,1.96,46.26],[2,1.91,28]],"ltp":1.96,"tv":353.26,"id":40096581}]}]}
{"op":"mcm","clk":"11830999994","pt":1723062311157,"mc":[{"id":"1.231501647","rc":[{"batb":[[0,1.96,46.26],[1,1.91,28],[2,1.85,138.46]],"ltp":1.96,"tv":353.26,"id":40096581}]}]}
{"op":"mcm","clk":"11831000159","pt":1723062313945,"mc":[{"id":"1.231501647","rc":[{"batb":[[0,1.97,10],[1,1.96,46.26],[2,1.91,28]],"ltp":1.96,"tv":353.26,"id":40096581}]}]}
{"op":"mcm","clk":"11831000386","pt":1723062317452,"mc":[{"id":"1.231501647","rc":[{"batb":[[0,1.96,46.26],[1,1.91,28],[2,1.85,138.46]],"ltp":1.96,"tv":353.26,"id":40096581}]}]}
{"op":"mcm","clk":"11831000533","pt":1723062319971,"mc":[{"id":"1.231501647","rc":[{"batb":[[0,1.97,10],[1,1.96,46.26],[2,1.91,28]],"ltp":1.96,"tv":353.26,"id":40096581}]}]}
{"op":"mcm","clk":"11831000750","pt":1723062323883,"mc":[{"id":"1.231501647","rc":[{"batb":[[0,1.96,46.26],[1,1.91,28],[2,1.85,138.46]],"ltp":1.96,"tv":353.26,"id":40096581}]}]}
{"op":"mcm","clk":"11831000890","pt":1723062326356,"mc":[{"id":"1.231501647","rc":[{"batb":[[0,1.97,10],[1,1.96,46.26],[2,1.91,28]],"ltp":1.96,"tv":353.26,"id":40096581}]}]}
{"op":"mcm","clk":"11831001149","pt":1723062329930,"mc":[{"id":"1.231501647","rc":[{"batb":[[0,1.96,46.26],[1,1.91,28],[2,1.85,138.46]],"ltp":1.96,"tv":353.26,"id":40096581}]}]}
{"op":"mcm","clk":"11831001298","pt":1723062332267,"mc":[{"id":"1.231501647","rc":[{"batb":[[0,1.97,10],[1,1.96,46.26],[2,1.91,28]],"ltp":1.96,"tv":353.26,"id":40096581}]}]}
{"op":"mcm","clk":"11831001510","pt":1723062335664,"mc":[{"id":"1.231501647","rc":[{"batb":[[0,1.96,46.26],[1,1.91,28],[2,1.85,138.46]],"ltp":1.96,"tv":353.26,"id":40096581}]}]}
{"op":"mcm","clk":"11831001679","pt":1723062338594,"mc":[{"id":"1.231501647","rc":[{"batb":[[0,1.97,10],[1,1.96,46.26],[2,1.91,28]],"ltp":1.96,"tv":353.26,"id":40096581}]}]}
{"op":"mcm","clk":"11831001777","pt":1723062340599,"mc":[{"id":"1.231501647","rc":[{"trd":[[1.97,20]],"batb":[[0,1.96,46.26],[1,1.91,28],[2,1.85,138.46]],"ltp":1.97,"tv":373.26,"id":40096581}],"tv":464.46}]}
{"op":"mcm","clk":"11831001947","pt":1723062343591,"mc":[{"id":"1.231501647","rc":[{"batb":[[0,1.97,10],[1,1.96,46.26],[2,1.91,28]],"ltp":1.97,"tv":373.26,"id":40096581}]}]}
{"op":"mcm","clk":"11831002172","pt":1723062347415,"mc":[{"id":"1.231501647","rc":[{"batb":[[0,1.96,46.26],[1,1.91,28],[2,1.85,138.46]],"ltp":1.97,"tv":373.26,"id":40096581}]}]}
{"op":"mcm","clk":"11831002321","pt":1723062349635,"mc":[{"id":"1.231501647","rc":[{"batb":[[0,1.97,10],[1,1.96,46.26],[2,1.91,28]],"ltp":1.97,"tv":373.26,"id":40096581}]}]}
{"op":"mcm","clk":"11831002541","pt":1723062353022,"mc":[{"id":"1.231501647","rc":[{"batb":[[0,1.96,46.26],[1,1.91,28],[2,1.85,138.46]],"ltp":1.97,"tv":373.26,"id":40096581}]}]}
{"op":"mcm","clk":"11831002855","pt":1723062358305,"mc":[{"id":"1.231501647","rc":[{"batb":[[0,1.97,10],[1,1.96,46.26],[2,1.91,28]],"ltp":1.97,"tv":373.26,"id":40096581}]}]}
{"op":"mcm","clk":"11831003071","pt":1723062361914,"mc":[{"id":"1.231501647","rc":[{"batb":[[0,1.96,46.26],[1,1.91,28],[2,1.85,138.46]],"ltp":1.97,"tv":373.26,"id":40096581}]}]}
{"op":"mcm","clk":"11831003268","pt":1723062365215,"mc":[{"id":"1.231501647","rc":[{"batb":[[0,1.97,10],[1,1.96,46.26],[2,1.91,28]],"ltp":1.97,"tv":373.26,"id":40096581}]}]}
{"op":"mcm","clk":"11831003488","pt":1723062368545,"mc":[{"id":"1.231501647","rc":[{"batb":[[0,1.96,46.26],[1,1.91,28],[2,1.85,138.46]],"ltp":1.97,"tv":373.26,"id":40096581}]}]}
{"op":"mcm","clk":"11831003669","pt":1723062371325,"mc":[{"id":"1.231501647","rc":[{"batb":[[0,1.97,10],[1,1.96,46.26],[2,1.91,28]],"ltp":1.97,"tv":373.26,"id":40096581}]}]}
{"op":"mcm","clk":"11831003948","pt":1723062375555,"mc":[{"id":"1.231501647","rc":[{"batb":[[0,1.96,46.26],[1,1.91,28],[2,1.85,138.46]],"ltp":1.97,"tv":373.26,"id":40096581}]}]}
{"op":"mcm","clk":"11831004146","pt":1723062378448,"mc":[{"id":"1.231501647","rc":[{"batb":[[0,1.97,10],[1,1.96,46.26],[2,1.91,28]],"ltp":1.97,"tv":373.26,"id":40096581}]}]}
{"op":"mcm","clk":"11831004367","pt":1723062381930,"mc":[{"id":"1.231501647","rc":[{"batb":[[0,1.96,46.26],[1,1.91,28],[2,1.85,138.46]],"ltp":1.97,"tv":373.26,"id":40096581}]}]}
{"op":"mcm","clk":"11831004521","pt":1723062384258,"mc":[{"id":"1.231501647","rc":[{"batb":[[0,1.97,10],[1,1.96,46.26],[2,1.91,28]],"ltp":1.97,"tv":373.26,"id":40096581}]}]}
{"op":"mcm","clk":"11831004767","pt":1723062388069,"mc":[{"id":"1.231501647","rc":[{"batb":[[0,1.96,46.26],[1,1.91,28],[2,1.85,138.46]],"ltp":1.97,"tv":373.26,"id":40096581}]}]}
{"op":"mcm","clk":"11831004899","pt":1723062390379,"mc":[{"id":"1.231501647","rc":[{"batb":[[0,1.97,10],[1,1.96,46.26],[2,1.91,28]],"ltp":1.97,"tv":373.26,"id":40096581}]}]}
{"op":"mcm","clk":"11831005099","pt":1723062393674,"mc":[{"id":"1.231501647","rc":[{"batb":[[0,1.96,46.26],[1,1.91,28],[2,1.85,138.46]],"ltp":1.97,"tv":373.26,"id":40096581}]}]}
{"op":"mcm","clk":"11831005267","pt":1723062396347,"mc":[{"id":"1.231501647","rc":[{"batb":[[0,1.97,10],[1,1.96,46.26],[2,1.91,28]],"ltp":1.97,"tv":373.26,"id":40096581}]}]}
{"op":"mcm","clk":"11831005460","pt":1723062399683,"mc":[{"id":"1.231501647","rc":[{"batb":[[0,1.96,46.26],[1,1.91,28],[2,1.85,138.46]],"ltp":1.97,"tv":373.26,"id":40096581}]}]}
{"op":"mcm","clk":"11831005969","pt":1723062405752,"mc":[{"id":"1.231501647","rc":[{"batb":[[0,1.97,10],[1,1.96,46.26],[2,1.91,28]],"ltp":1.97,"tv":373.26,"id":40096581}]}]}
{"op":"mcm","clk":"11831006150","pt":1723062409091,"mc":[{"id":"1.231501647","rc":[{"batb":[[0,1.96,46.26],[1,1.91,28],[2,1.85,138.46]],"ltp":1.97,"tv":373.26,"id":40096581}]}]}
{"op":"mcm","clk":"11831006527","pt":1723062414857,"mc":[{"id":"1.231501647","rc":[{"batb":[[0,1.97,10],[1,1.96,46.26],[2,1.91,28]],"ltp":1.97,"tv":373.26,"id":40096581}]}]}
{"op":"mcm","clk":"11831006717","pt":1723062418206,"mc":[{"id":"1.231501647","rc":[{"batb":[[0,1.96,46.26],[1,1.91,28],[2,1.85,138.46]],"ltp":1.97,"tv":373.26,"id":40096581}]}]}
{"op":"mcm","clk":"11831006914","pt":1723062421295,"mc":[{"id":"1.231501647","rc":[{"batb":[[0,1.97,10],[1,1.96,46.26],[2,1.91,28]],"ltp":1.97,"tv":373.26,"id":40096581}]}]}
{"op":"mcm","clk":"11831007117","pt":1723062424905,"mc":[{"id":"1.231501647","rc":[{"batb":[[0,1.96,46.26],[1,1.91,28],[2,1.85,138.46]],"ltp":1.97,"tv":373.26,"id":40096581}]}]}
{"op":"mcm","clk":"11831007361","pt":1723062428468,"mc":[{"id":"1.231501647","rc":[{"batb":[[0,1.97,10],[1,1.96,46.26],[2,1.91,28]],"ltp":1.97,"tv":373.26,"id":40096581}]}]}
{"op":"mcm","clk":"11831007593","pt":1723062432592,"mc":[{"id":"1.231501647","rc":[{"batb":[[0,1.96,46.26],[1,1.91,28],[2,1.85,138.46]],"ltp":1.97,"tv":373.26,"id":40096581}]}]}
{"op":"mcm","clk":"11831007719","pt":1723062435105,"mc":[{"id":"1.231501647","rc":[{"batb":[[0,1.97,10],[1,1.96,46.26],[2,1.91,28]],"ltp":1.97,"tv":373.26,"id":40096581}]}]}
{"op":"mcm","clk":"11831007903","pt":1723062438602,"mc":[{"id":"1.231501647","rc":[{"batb":[[0,1.96,46.26],[1,1.91,28],[2,1.85,138.46]],"ltp":1.97,"tv":373.26,"id":40096581}]}]}
{"op":"mcm","clk":"11831008050","pt":1723062441029,"mc":[{"id":"1.231501647","rc":[{"batb":[[0,1.97,10],[1,1.96,46.26],[2,1.91,28]],"ltp":1.97,"tv":373.26,"id":40096581}]}]}
{"op":"mcm","clk":"11831008255","pt":1723062444430,"mc":[{"id":"1.231501647","rc":[{"batb":[[0,1.96,46.26],[1,1.91,28],[2,1.85,138.46]],"ltp":1.97,"tv":373.26,"id":40096581}]}]}
{"op":"mcm","clk":"11831008391","pt":1723062446908,"mc":[{"id":"1.231501647","rc":[{"batb":[[0,1.97,10],[1,1.96,46.26],[2,1.91,28]],"ltp":1.97,"tv":373.26,"id":40096581}]}]}
{"op":"mcm","clk":"11831008585","pt":1723062450414,"mc":[{"id":"1.231501647","rc":[{"batb":[[0,1.96,46.26],[1,1.91,28],[2,1.85,138.46]],"ltp":1.97,"tv":373.26,"id":40096581}]}]}
{"op":"mcm","clk":"11831008750","pt":1723062452906,"mc":[{"id":"1.231501647","rc":[{"batb":[[0,1.97,10],[1,1.96,46.26],[2,1.91,28]],"ltp":1.97,"tv":373.26,"id":40096581}]}]}
{"op":"mcm","clk":"11831008945","pt":1723062456415,"mc":[{"id":"1.231501647","rc":[{"batb":[[0,1.96,46.26],[1,1.91,28],[2,1.85,138.46]],"ltp":1.97,"tv":373.26,"id":40096581}]}]}
{"op":"mcm","clk":"11831009119","pt":1723062458837,"mc":[{"id":"1.231501647","rc":[{"batb":[[0,1.97,10],[1,1.96,46.26],[2,1.91,28]],"ltp":1.97,"tv":373.26,"id":40096581}]}]}
{"op":"mcm","clk":"11831009362","pt":1723062462333,"mc":[{"id":"1.231501647","rc":[{"batb":[[0,1.96,46.26],[1,1.91,28],[2,1.85,138.46]],"ltp":1.97,"tv":373.26,"id":40096581}]}]}
{"op":"mcm","clk":"11831009585","pt":1723062466357,"mc":[{"id":"1.231501647","rc":[{"batb":[[0,1.97,10],[1,1.96,46.26],[2,1.91,28]],"ltp":1.97,"tv":373.26,"id":40096581}]}]}
{"op":"mcm","clk":"11831009810","pt":1723062469783,"mc":[{"id":"1.231501647","rc":[{"batb":[[0,1.96,46.26],[1,1.91,28],[2,1.85,138.46]],"ltp":1.97,"tv":373.26,"id":40096581}]}]}
{"op":"mcm","clk":"11831010049","pt":1723062473137,"mc":[{"id":"1.231501647","rc":[{"batb":[[0,1.97,10],[1,1.96,46.26],[2,1.91,28]],"ltp":1.97,"tv":373.26,"id":40096581}]}]}
{"op":"mcm","clk":"11831010254","pt":1723062476776,"mc":[{"id":"1.231501647","rc":[{"batb":[[0,1.96,46.26],[1,1.91,28],[2,1.85,138.46]],"ltp":1.97,"tv":373.26,"id":40096581}]}]}
{"op":"mcm","clk":"11831010407","pt":1723062479062,"mc":[{"id":"1.231501647","rc":[{"batb":[[0,1.97,10],[1,1.96,46.26],[2,1.91,28]],"ltp":1.97,"tv":373.26,"id":40096581}]}]}
{"op":"mcm","clk":"11831010620","pt":1723062482384,"mc":[{"id":"1.231501647","rc":[{"batb":[[0,1.96,46.26],[1,1.91,28],[2,1.85,138.46]],"ltp":1.97,"tv":373.26,"id":40096581}]}]}
{"op":"mcm","clk":"11831010783","pt":1723062484969,"mc":[{"id":"1.231501647","rc":[{"batb":[[0,1.97,10],[1,1.96,46.26],[2,1.91,28]],"ltp":1.97,"tv":373.26,"id":40096581}]}]}
{"op":"mcm","clk":"11831011002","pt":1723062488581,"mc":[{"id":"1.231501647","rc":[{"batb":[[0,1.96,46.26],[1,1.91,28],[2,1.85,138.46]],"ltp":1.97,"tv":373.26,"id":40096581}]}]}
{"op":"mcm","clk":"11831011209","pt":1723062491987,"mc":[{"id":"1.231501647","rc":[{"batb":[[0,1.97,10],[1,1.96,46.26],[2,1.91,28]],"ltp":1.97,"tv":373.26,"id":40096581}]}]}
{"op":"mcm","clk":"11831011468","pt":1723062495486,"mc":[{"id":"1.231501647","rc":[{"batb":[[0,1.96,46.26],[1,1.91,28],[2,1.85,138.46]],"ltp":1.97,"tv":373.26,"id":40096581}]}]}
{"op":"mcm","clk":"11831011704","pt":1723062498178,"mc":[{"id":"1.231501647","rc":[{"batb":[[0,1.97,10],[1,1.96,46.26],[2,1.91,28]],"ltp":1.97,"tv":373.26,"id":40096581}]}]}
{"op":"mcm","clk":"11831011974","pt":1723062501473,"mc":[{"id":"1.231501647","rc":[{"batb":[[0,1.96,46.26],[1,1.91,28],[2,1.85,138.46]],"ltp":1.97,"tv":373.26,"id":40096581}]}]}
{"op":"mcm","clk":"11831012218","pt":1723062504813,"mc":[{"id":"1.231501647","rc":[{"batb":[[0,1.97,10],[1,1.96,46.26],[2,1.91,28]],"ltp":1.97,"tv":373.26,"id":40096581}]}]}
{"op":"mcm","clk":"11831012441","pt":1723062508101,"mc":[{"id":"1.231501647","rc":[{"batb":[[0,1.96,46.26],[1,1.91,28],[2,1.85,138.46]],"ltp":1.97,"tv":373.26,"id":40096581}]}]}
{"op":"mcm","clk":"11831012640","pt":1723062511388,"mc":[{"id":"1.231501647","rc":[{"batb":[[0,1.97,10],[1,1.96,46.26],[2,1.91,28]],"ltp":1.97,"tv":373.26,"id":40096581}]}]}
{"op":"mcm","clk":"11831012829","pt":1723062514779,"mc":[{"id":"1.231501647","rc":[{"batb":[[0,1.96,46.26],[1,1.91,28],[2,1.85,138.46]],"ltp":1.97,"tv":373.26,"id":40096581}]}]}
{"op":"mcm","clk":"11831013006","pt":1723062517810,"mc":[{"id":"1.231501647","rc":[{"batb":[[0,1.97,10],[1,1.96,46.26],[2,1.91,28]],"ltp":1.97,"tv":373.26,"id":40096581}]}]}
{"op":"mcm","clk":"11831013238","pt":1723062521503,"mc":[{"id":"1.231501647","rc":[{"batb":[[0,1.96,46.26],[1,1.91,28],[2,1.85,138.46]],"ltp":1.97,"tv":373.26,"id":40096581}]}]}
{"op":"mcm","clk":"11831013375","pt":1723062523916,"mc":[{"id":"1.231501647","rc":[{"batb":[[0,1.97,10],[1,1.96,46.26],[2,1.91,28]],"ltp":1.97,"tv":373.26,"id":40096581}]}]}
{"op":"mcm","clk":"11831013589","pt":1723062527610,"mc":[{"id":"1.231501647","rc":[{"batb":[[0,1.96,46.26],[1,1.91,28],[2,1.85,138.46]],"ltp":1.97,"tv":373.26,"id":40096581}]}]}
{"op":"mcm","clk":"11831013774","pt":1723062530904,"mc":[{"id":"1.231501647","rc":[{"batb":[[0,1.97,10],[1,1.96,46.26],[2,1.91,28]],"ltp":1.97,"tv":373.26,"id":40096581}]}]}
{"op":"mcm","clk":"11831014014","pt":1723062534346,"mc":[{"id":"1.231501647","rc":[{"batb":[[0,1.96,46.26],[1,1.91,28],[2,1.85,138.46]],"ltp":1.97,"tv":373.26,"id":40096581}]}]}
{"op":"mcm","clk":"11831014171","pt":1723062536914,"mc":[{"id":"1.231501647","rc":[{"batb":[[0,1.97,10],[1,1.96,46.26],[2,1.91,28]],"ltp":1.97,"tv":373.26,"id":40096581}]}]}
{"op":"mcm","clk":"11831014403","pt":1723062540452,"mc":[{"id":"1.231501647","rc":[{"batb":[[0,1.96,46.26],[1,1.91,28],[2,1.85,138.46]],"ltp":1.97,"tv":373.26,"id":40096581}]}]}
{"op":"mcm","clk":"11831014730","pt":1723062545047,"mc":[{"id":"1.231501647","rc":[{"batb":[[0,1.97,10],[1,1.96,46.26],[2,1.91,28]],"ltp":1.97,"tv":373.26,"id":40096581}]}]}
{"op":"mcm","clk":"11831014984","pt":1723062548350,"mc":[{"id":"1.231501647","rc":[{"batb":[[0,1.96,46.26],[1,1.91,28],[2,1.85,138.46]],"ltp":1.97,"tv":373.26,"id":40096581}]}]}
{"op":"mcm","clk":"11831015284","pt":1723062553130,"mc":[{"id":"1.231501647","rc":[{"batb":[[0,1.97,10],[1,1.96,46.26],[2,1.91,28]],"ltp":1.97,"tv":373.26,"id":40096581}]}]}
{"op":"mcm","clk":"11831015477","pt":1723062556667,"mc":[{"id":"1.231501647","rc":[{"batb":[[0,1.96,46.26],[1,1.91,28],[2,1.85,138.46]],"ltp":1.97,"tv":373.26,"id":40096581}]}]}
{"op":"mcm","clk":"11831015651","pt":1723062559543,"mc":[{"id":"1.231501647","rc":[{"batb":[[0,1.97,10],[1,1.96,46.26],[2,1.91,28]],"ltp":1.97,"tv":373.26,"id":40096581}]}]}
{"op":"mcm","clk":"11831015850","pt":1723062563197,"mc":[{"id":"1.231501647","rc":[{"batb":[[0,1.96,46.26],[1,1.91,28],[2,1.85,138.46]],"ltp":1.97,"tv":373.26,"id":40096581}]}]}
{"op":"mcm","clk":"11831016044","pt":1723062566494,"mc":[{"id":"1.231501647","rc":[{"batb":[[0,1.97,10],[1,1.96,46.26],[2,1.91,28]],"ltp":1.97,"tv":373.26,"id":40096581}]}]}
{"op":"mcm","clk":"11831016219","pt":1723062569787,"mc":[{"id":"1.231501647","rc":[{"batb":[[0,1.96,46.26],[1,1.91,28],[2,1.85,138.46]],"ltp":1.97,"tv":373.26,"id":40096581}]}]}
{"op":"mcm","clk":"11831016404","pt":1723062573387,"mc":[{"id":"1.231501647","rc":[{"batb":[[0,1.97,10],[1,1.96,46.26],[2,1.91,28]],"ltp":1.97,"tv":373.26,"id":40096581}]}]}
{"op":"mcm","clk":"11831016660","pt":1723062577710,"mc":[{"id":"1.231501647","rc":[{"batb":[[0,2,51.1],[1,1.99,2.5],[2,1.98,45.31]],"ltp":2.0,"tv":91.19,"id":40096589},{"batb":[[0,1.96,46.26],[1,1.91,28],[2,1.85,138.46]],"ltp":1.97,"tv":373.26,"id":40096581}]}]}
{"op":"mcm","clk":"11831016769","pt":1723062579612,"mc":[{"id":"1.231501647","rc":[{"batb":[[0,1.97,10],[1,1.96,46.26],[2,1.91,28]],"ltp":1.97,"tv":373.26,"id":40096581}]}]}
{"op":"mcm","clk":"11831016929","pt":1723062582794,"mc":[{"id":"1.231501647","rc":[{"batb":[[2,1.91,28]],"ltp":2.0,"tv":91.19,"id":40096589},{"batb":[[0,1.91,28],[1,1.85,138.46],[2,1.81,333]],"ltp":1.97,"tv":373.26,"id":40096581}]}]}
{"op":"mcm","clk":"11831017080","pt":1723062585822,"mc":[{"id":"1.231501647","rc":[{"batb":[[0,1.92,10],[1,1.91,28],[2,1.85,138.46]],"ltp":1.97,"tv":373.26,"id":40096581}]}]}
{"op":"mcm","clk":"11831017157","pt":1723062587188,"mc":[{"id":"1.231501647","rc":[{"batb":[[2,1.98,45.31]],"ltp":2.0,"tv":91.19,"id":40096589},{"batb":[[0,1.96,46.26],[1,1.92,10],[2,1.91,28]],"ltp":1.97,"tv":373.26,"id":40096581}]}]}
{"op":"mcm","clk":"11831017266","pt":1723062589190,"mc":[{"id":"1.231501647","rc":[{"batb":[[1,1.91,28],[2,1.85,138.46]],"ltp":1.97,"tv":373.26,"id":40096581}]}]}
{"op":"mcm","clk":"11831017402","pt":1723062591808,"mc":[{"id":"1.231501647","rc":[{"batb":[[0,1.97,10],[1,1.96,46.26],[2,1.91,28]],"ltp":1.97,"tv":373.26,"id":40096581}]}]}
{"op":"mcm","clk":"11831017432","pt":1723062592326,"mc":[{"id":"1.231501647","rc":[{"batb":[[2,1.91,28]],"ltp":2.0,"tv":91.19,"id":40096589},{"batb":[[1,1.91,28],[2,1.85,138.46]],"ltp":1.97,"tv":373.26,"id":40096581}]}]}
{"op":"mcm","clk":"11831017635","pt":1723062595709,"mc":[{"id":"1.231501647","rc":[{"batb":[[0,1.91,28],[1,1.85,138.46],[2,1.81,333]],"ltp":1.97,"tv":373.26,"id":40096581}]}]}
{"op":"mcm","clk":"11831017758","pt":1723062597515,"mc":[{"id":"1.231501647","rc":[{"batb":[[2,1.98,45.31]],"ltp":2.0,"tv":91.19,"id":40096589},{"batb":[[0,1.97,10],[1,1.96,46.26],[2,1.91,28]],"ltp":1.97,"tv":373.26,"id":40096581}]}]}
{"op":"mcm","clk":"11831017975","pt":1723062600812,"mc":[{"id":"1.231501647","rc":[{"batb":[[0,1.96,46.26],[1,1.91,28],[2,1.85,138.46]],"ltp":1.97,"tv":373.26,"id":40096581}]}]}
{"op":"mcm","clk":"11831018269","pt":1723062604629,"mc":[{"id":"1.231501647","rc":[{"batb":[[0,1.97,10],[1,1.96,46.26],[2,1.91,28]],"ltp":1.97,"tv":373.26,"id":40096581}]}]}
{"op":"mcm","clk":"11831018482","pt":1723062607451,"mc":[{"id":"1.231501647","rc":[{"batb":[[2,1.91,28]],"ltp":2.0,"tv":91.19,"id":40096589},{"batb":[[1,1.91,28],[2,1.85,138.46]],"ltp":1.97,"tv":373.26,"id":40096581}]}]}
{"op":"mcm","clk":"11831018551","pt":1723062608432,"mc":[{"id":"1.231501647","rc":[{"batb":[[0,1.91,28],[1,1.85,138.46],[2,1.81,333]],"ltp":1.97,"tv":373.26,"id":40096581}]}]}
{"op":"mcm","clk":"11831018718","pt":1723062610950,"mc":[{"id":"1.231501647","rc":[{"batb":[[0,1.92,10],[1,1.91,28],[2,1.85,138.46]],"ltp":1.97,"tv":373.26,"id":40096581}]}]}
{"op":"mcm","clk":"11831018821","pt":1723062612347,"mc":[{"id":"1.231501647","rc":[{"batb":[[2,1.98,45.31]],"ltp":2.0,"tv":91.19,"id":40096589},{"batb":[[0,1.96,46.26],[1,1.92,10],[2,1.91,28]],"batl":[[0,1.97,3],[1,2.02,2]],"ltp":1.97,"tv":373.26,"id":40096581}]}]}
{"op":"mcm","clk":"11831018963","pt":1723062614249,"mc":[{"id":"1.231501647","rc":[{"batb":[[1,1.91,28],[2,1.85,138.46]],"ltp":1.97,"tv":373.26,"id":40096581}]}]}
{"op":"mcm","clk":"11831025123","pt":1723062711502,"mc":[{"id":"1.231501647","rc":[{"batb":[[0,1.97,10],[1,1.96,46.26],[2,1.91,28]],"batl":[[0,1.99,3]],"ltp":1.97,"tv":373.26,"id":40096581}]}]}
{"op":"mcm","clk":"11831025204","pt":1723062712891,"mc":[{"id":"1.231501647","rc":[{"batb":[[2,1.91,28]],"ltp":2.0,"tv":91.19,"id":40096589},{"batb":[[1,1.91,28],[2,1.85,138.46]],"ltp":1.97,"tv":373.26,"id":40096581}]}]}
{"op":"mcm","clk":"11831025303","pt":1723062714698,"mc":[{"id":"1.231501647","rc":[{"batb":[[0,1.91,28],[1,1.85,138.46],[2,1.81,333]],"ltp":1.97,"tv":373.26,"id":40096581}]}]}
{"op":"mcm","clk":"11831025497","pt":1723062717831,"mc":[{"id":"1.231501647","rc":[{"batb":[[2,1.98,45.31]],"ltp":2.0,"tv":91.19,"id":40096589},{"batb":[[0,1.96,46.26],[1,1.91,28],[2,1.85,138.46]],"ltp":1.97,"tv":373.26,"id":40096581}]}]}
{"op":"mcm","clk":"11831026752","pt":1723062737034,"mc":[{"id":"1.231501647","rc":[{"batb":[[1,1.91,48]],"ltp":1.97,"tv":373.26,"id":40096581}]}]}
{"op":"mcm","clk":"11831031106","pt":1723062803377,"mc":[{"id":"1.231501647","rc":[{"batb":[[1,1.92,800],[2,1.91,48]],"ltp":1.97,"tv":373.26,"id":40096581}]}]}
{"op":"mcm","clk":"11831031422","pt":1723062808824,"mc":[{"id":"1.231501647","rc":[{"batb":[[0,1.99,2.5],[1,1.98,45.31],[2,1.91,28]],"ltp":2.0,"tv":91.19,"id":40096589}]}]}
{"op":"mcm","clk":"11831031776","pt":1723062813816,"mc":[{"id":"1.231501647","rc":[{"batb":[[2,1.92,800]],"ltp":2.0,"tv":91.19,"id":40096589}]}]}
{"op":"mcm","clk":"11831060182","pt":1723063284243,"mc":[{"id":"1.231501647","rc":[{"batb":[[2,1.91,28]],"ltp":1.97,"tv":373.26,"id":40096581}]}]}
{"op":"mcm","clk":"11831093502","pt":1723063959960,"mc":[{"id":"1.231501647","rc":[{"batb":[[0,1.96,96.26]],"ltp":1.97,"tv":373.26,"id":40096581}]}]}
{"op":"mcm","clk":"11831095133","pt":1723063984388,"mc":[{"id":"1.231501647","rc":[{"batl":[[2,2.06,25]],"ltp":1.97,"tv":373.26,"id":40096581}]}]}
{"op":"mcm","clk":"11831096020","pt":1723064001122,"mc":[{"id":"1.231501647","rc":[{"trd":[[1.96,294.37]],"batb":[[0,1.92,829.94],[1,1.91,28],[2,1.9,800]],"batl":[[0,1.96,2.84],[1,1.99,3],[2,2.02,2]],"ltp":1.96,"tv":570.55,"id":40096581}],"tv":661.75}]}
{"op":"mcm","clk":"11831096302","pt":1723064005271,"mc":[{"id":"1.231501647","rc":[{"batb":[[0,1.92,878.21]],"ltp":1.96,"tv":570.55,"id":40096581}]}]}
{"op":"mcm","clk":"11831096558","pt":1723064006865,"mc":[{"id":"1.231501647","rc":[{"batb":[[0,1.92,848.27]],"ltp":1.96,"tv":570.55,"id":40096581}]}]}
{"op":"mcm","clk":"11831110943","pt":1723064211521,"mc":[{"id":"1.231501647","rc":[{"batb":[[0,1.93,17.21],[1,1.92,848.27],[2,1.91,28]],"ltp":1.96,"tv":570.55,"id":40096581}]}]}
{"op":"mcm","clk":"11831112800","pt":1723064244295,"mc":[{"id":"1.231501647","rc":[{"batb":[[0,1.93,817.21]],"ltp":1.96,"tv":570.55,"id":40096581}]}]}
{"op":"mcm","clk":"11831112947","pt":1723064247418,"mc":[{"id":"1.231501647","rc":[{"batb":[[1,1.92,48.27]],"ltp":1.96,"tv":570.55,"id":40096581}]}]}
{"op":"mcm","clk":"11831126981","pt":1723064517051,"mc":[{"id":"1.231501647","rc":[{"trd":[[2,70.03]],"batl":[[0,2.06,17.21]],"ltp":2.0,"tv":91.17,"id":40096589},{"batb":[[0,1.93,817.21]],"ltp":1.96,"tv":570.55,"id":40096581}],"tv":661.73}]}
{"op":"mcm","clk":"11831150607","pt":1723064950460,"mc":[{"id":"1.231501647","rc":[{"batb":[[0,1.94,100],[1,1.93,817.21],[2,1.92,48.27]],"ltp":1.96,"tv":570.55,"id":40096581}]}]}
{"op":"mcm","clk":"11831150643","pt":1723064951279,"mc":[{"id":"1.231501647","rc":[{"batb":[[1,1.93,800]],"ltp":1.96,"tv":570.55,"id":40096581}]}]}
{"op":"mcm","clk":"11831152669","pt":1723064988157,"mc":[{"id":"1.231501647","rc":[{"batb":[[0,1.99,102.5]],"ltp":2.0,"tv":91.17,"id":40096589}]}]}
{"op":"mcm","clk":"11831152967","pt":1723064993247,"mc":[{"id":"1.231501647","rc":[{"batl":[[2,2,5.95]],"ltp":1.96,"tv":570.55,"id":40096581}]}]}
{"op":"mcm","clk":"11831162131","pt":1723065163172,"mc":[{"id":"1.231501647","rc":[{"batb":[[0,1.95,8.88],[1,1.94,100],[2,1.93,800]],"ltp":1.96,"tv":570.55,"id":40096581}]}]}
{"op":"mcm","clk":"11831162421","pt":1723065168970,"mc":[{"id":"1.231501647","rc":[{"trd":[[1.95,4.44]],"batb":[[0,1.95,6.66]],"ltp":1.95,"tv":574.99,"id":40096581}],"tv":666.17}]}
{"op":"mcm","clk":"11831164209","pt":1723065202212,"mc":[{"id":"1.231501647","rc":[{"batl":[[2,2,14.6]],"ltp":1.95,"tv":574.99,"id":40096581}]}]}
{"op":"mcm","clk":"11831173921","pt":1723065374921,"mc":[{"id":"1.231501647","rc":[{"batb":[[0,1.95,12.8]],"ltp":1.95,"tv":574.99,"id":40096581}]}]}
{"op":"mcm","clk":"11831234138","pt":1723066500372,"mc":[{"id":"1.231501647","rc":[{"batl":[[0,1.96,142.12]],"ltp":1.95,"tv":574.99,"id":40096581}]}]}
{"op":"mcm","clk":"11831234197","pt":1723066501357,"mc":[{"id":"1.231501647","rc":[{"batb":[[0,1.95,6.66]],"batl":[[2,2,8.65]],"ltp":1.95,"tv":574.99,"id":40096581}]}]}
{"op":"mcm","clk":"11831234293","pt":1723066503155,"mc":[{"id":"1.231501647","rc":[{"batb":[[0,1.94,100],[1,1.93,800],[2,1.92,48.27]],"batl":[[2,2.02,2]],"ltp":1.95,"tv":574.99,"id":40096581}]}]}
{"op":"mcm","clk":"11831234422","pt":1723066505160,"mc":[{"id":"1.231501647","rc":[{"batl":[[0,1.95,2.22],[1,1.96,142.12],[2,1.99,3]],"ltp":1.95,"tv":574.99,"id":40096581}]}]}
{"op":"mcm","clk":"11831251286","pt":1723066827830,"mc":[{"id":"1.231501647","rc":[{"batl":[[1,1.96,2.84]],"ltp":1.95,"tv":574.99,"id":40096581}]}]}
{"op":"mcm","clk":"11831251340","pt":1723066828811,"mc":[{"id":"1.231501647","rc":[{"batl":[[0,2.06,17.21]],"ltp":2.0,"tv":91.17,"id":40096589},{"batl":[[0,1.96,2.84],[1,1.99,3],[2,2.02,2]],"ltp":1.95,"tv":574.99,"id":40096581}]}]}
{"op":"mcm","clk":"11831251445","pt":1723066831430,"mc":[{"id":"1.231501647","rc":[{"batb":[[0,2,8.12],[1,1.99,102.5],[2,1.98,45.31]],"ltp":2.0,"tv":91.17,"id":40096589},{"batl":[[2,2,10.69]],"ltp":1.95,"tv":574.99,"id":40096581}]}]}
{"op":"mcm","clk":"11831251705","pt":1723066836828,"mc":[{"id":"1.231501647","rc":[{"batb":[[0,1.95,5.81],[1,1.94,100],[2,1.93,800]],"ltp":1.95,"tv":574.99,"id":40096581}]}]}
{"op":"mcm","clk":"11831287241","pt":1723067322736,"mc":[{"id":"1.231501647","rc":[{"trd":[[1.95,5.47]],"batb":[[0,1.95,5.29]],"ltp":1.95,"tv":576.02,"id":40096581}],"tv":667.2}]}
{"op":"mcm","clk":"11831348319","pt":1723068483569,"mc":[{"id":"1.231501647","rc":[{"trd":[[2,70.03],[2.12,7.17]],"batb":[[0,2,8.12]],"batl":[[0,2.06,17.21]],"ltp":2.0,"tv":91.17,"id":40096589},{"trd":[[1.95,11.47]],"batb":[[0,1.95,2.29]],"batl":[[2,2,10.69]],"ltp":1.95,"tv":582.03,"id":40096581}],"tv":673.2}]}
{"op":"mcm","clk":"11831386122","pt":1723069112417,"mc":[{"id":"1.231501647","rc":[{"trd":[[1.95,16.05]],"batb":[[0,1.94,100],[1,1.93,800],[2,1.92,48.27]],"batl":[[0,1.95,1.37],[1,1.96,2.84],[2,1.99,8.69]],"ltp":1.95,"tv":586.6,"id":40096581}],"tv":677.78}]}
{"op":"mcm","clk":"11831389186","pt":1723069158979,"mc":[{"id":"1.231501647","rc":[{"batl":[[0,1.96,2.84],[1,1.99,8.69],[2,2,10.69]],"ltp":1.95,"tv":586.6,"id":40096581}]}]}
{"op":"mcm","clk":"11831391679","pt":1723069197940,"mc":[{"id":"1.231501647","rc":[{"trd":[[1.94,2.74]],"batb":[[0,1.94,98.63]],"ltp":1.94,"tv":589.34,"id":40096581}],"tv":680.51}]}
{"op":"mcm","clk":"11831527502","pt":1723071610419,"mc":[{"id":"1.231501647","rc":[{"trd":[[2,70.07],[2.12,7.18]],"batb":[[0,2,8.13]],"batl":[[0,2.06,34.23]],"ltp":2.0,"tv":91.21,"id":40096589},{"trd":[[1.95,16.06]],"batl":[[1,1.99,8.69],[2,2,10.7]],"ltp":1.94,"tv":589.35,"id":40096581}],"tv":680.57}]}
{"op":"mcm","clk":"11831605657","pt":1723072708433,"mc":[{"id":"1.231501647","rc":[{"batl":[[0,1.96,142.12]],"ltp":1.94,"tv":589.35,"id":40096581}]}]}
{"op":"mcm","clk":"11831605724","pt":1723072709314,"mc":[{"id":"1.231501647","rc":[{"batb":[[0,1.99,102.5],[1,1.98,45.31],[2,1.92,800]],"batl":[[0,2.06,17]],"ltp":2.0,"tv":91.21,"id":40096589},{"batl":[[0,1.95,2.22],[1,1.96,142.12],[2,1.99,8.69]],"ltp":1.94,"tv":589.35,"id":40096581}]}]}
{"op":"mcm","clk":"11831605814","pt":1723072710452,"mc":[{"id":"1.231501647","rc":[{"batl":[[0,1.95,8.04],[2,1.99,3]],"ltp":1.94,"tv":589.35,"id":40096581}]}]}
{"op":"mcm","clk":"11831713584","pt":1723074261747,"mc":[{"id":"1.231501647","rc":[{"trd":[[2.04,4.95]],"ltp":2.04,"tv":96.16,"id":40096589},{"trd":[[1.95,21.24]],"batl":[[0,1.95,2.86]],"ltp":1.95,"tv":594.53,"id":40096581}],"tv":690.7}]}
{"op":"mcm","clk":"11831750475","pt":1723074855426,"mc":[{"id":"1.231501647","rc":[{"batb":[[0,2.04,4.95],[1,1.99,102.5],[2,1.98,45.31]],"ltp":2.04,"tv":96.16,"id":40096589}]}]}
{"op":"mcm","clk":"11831854064","pt":1723076577217,"mc":[{"id":"1.231501647","rc":[{"trd":[[2,70.14],[2.12,7.19]],"ltp":2.04,"tv":96.24,"id":40096589},{"trd":[[1.94,2.74],[1.95,21.25]],"batl":[[0,1.95,2.86]],"ltp":1.95,"tv":594.54,"id":40096581}],"tv":690.79}]}
{"op":"mcm","clk":"11831854667","pt":1723076586421,"mc":[{"id":"1.231501647","rc":[{"batb":[[0,1.94,375.55]],"ltp":1.95,"tv":594.54,"id":40096581}]}]}
{"op":"mcm","clk":"11831854982","pt":1723076591150,"mc":[{"id":"1.231501647","rc":[{"batb":[[1,1.93,1076.92]],"ltp":1.95,"tv":594.54,"id":40096581}]}]}
{"op":"mcm","clk":"11831978908","pt":1723078210797,"mc":[{"id":"1.231501647","rc":[{"trd":[[1.95,26.97]],"batb":[[0,1.95,559.64],[1,1.94,375.55],[2,1.93,1076.92]],"batl":[[0,1.96,142.12],[1,1.99,3],[2,2.02,2]],"ltp":1.95,"tv":600.26,"id":40096581}],"tv":696.51}]}
{"op":"mcm","clk":"11831979158","pt":1723078214107,"mc":[{"id":"1.231501647","rc":[{"batb":[[0,1.94,375.55],[1,1.93,1076.92],[2,1.91,28]],"ltp":1.95,"tv":600.26,"id":40096581}]}]}
{"op":"mcm","clk":"11831979314","pt":1723078216314,"mc":[{"id":"1.231501647","rc":[{"batb":[[2,1.92,48.27]],"ltp":1.95,"tv":600.26,"id":40096581}]}]}
{"op":"mcm","clk":"11831981909","pt":1723078258944,"mc":[{"id":"1.231501647","rc":[{"batl":[[0,1.95,41.67],[1,1.96,142.12],[2,1.99,3]],"ltp":1.95,"tv":600.26,"id":40096581}]}]}
{"op":"mcm","clk":"11831982588","pt":1723078269658,"mc":[{"id":"1.231501647","rc":[{"batl":[[0,1.96,142.12],[1,1.99,3],[2,2.02,2]],"ltp":1.95,"tv":600.26,"id":40096581}]}]}
{"op":"mcm","clk":"11832045895","pt":1723079339993,"mc":[{"id":"1.231501647","rc":[{"trd":[[2,70.15]],"ltp":2.04,"tv":96.25,"id":40096589},{"trd":[[1.95,26.97]],"batl":[[0,1.95,22.5],[1,1.96,142.12],[2,1.99,3]],"ltp":1.95,"tv":600.26,"id":40096581}],"tv":696.52}]}
{"op":"mcm","clk":"11832046212","pt":1723079345820,"mc":[{"id":"1.231501647","rc":[{"batl":[[0,1.96,142.12],[1,1.99,3],[2,2.02,2]],"ltp":1.95,"tv":600.26,"id":40096581}]}]}
{"op":"mcm","clk":"11832047554","pt":1723079369549,"mc":[{"id":"1.231501647","rc":[{"trd":[[1.96,601.46]],"batb":[[0,1.96,35.03],[1,1.94,375.55],[2,1.93,1076.92]],"batl":[[0,1.99,3],[1,2.02,2],[2,2.06,25]],"ltp":1.96,"tv":907.35,"id":40096581}],"tv":1003.61}]}
{"op":"mcm","clk":"11832047627","pt":1723079370742,"mc":[{"id":"1.231501647","rc":[{"batb":[[1,2,8.29],[2,1.99,102.5]],"ltp":2.04,"tv":96.25,"id":40096589},{"batl":[[1,2,8.34],[2,2.02,2]],"ltp":1.96,"tv":907.35,"id":40096581}]}]}
{"op":"mcm","clk":"11832047671","pt":1723079371567,"mc":[{"id":"1.231501647","rc":[{"batb":[[0,1.94,375.55],[1,1.93,1076.92],[2,1.92,48.27]],"ltp":1.96,"tv":907.35,"id":40096581}]}]}
{"op":"mcm","clk":"11832047741","pt":1723079372857,"mc":[{"id":"1.231501647","rc":[{"batl":[[0,2.06,17.24]],"ltp":2.04,"tv":96.25,"id":40096589},{"batb":[[0,1.95,17.24],[1,1.94,375.55],[2,1.93,1076.92]],"ltp":1.96,"tv":907.35,"id":40096581}]}]}
{"op":"mcm","clk":"11832056711","pt":1723079523753,"mc":[{"id":"1.231501647","rc":[{"trd":[[2.04,9.9]],"batb":[[0,2,8.29],[1,1.99,102.5],[2,1.98,45.31]],"ltp":2.04,"tv":101.2,"id":40096589},{"trd":[[1.97,25.13]],"batb":[[0,1.97,39.95],[1,1.95,17.24],[2,1.94,375.55]],"ltp":1.97,"tv":912.48,"id":40096581}],"tv":1013.69}]}
{"op":"mcm","clk":"11832056755","pt":1723079524422,"mc":[{"id":"1.231501647","rc":[{"batb":[[1,1.94,375.55],[2,1.93,1076.92]],"ltp":1.97,"tv":912.48,"id":40096581}]}]}
{"op":"mcm","clk":"11832056887","pt":1723079526748,"mc":[{"id":"1.231501647","rc":[{"batb":[[2,1.92,800]],"ltp":2.04,"tv":101.2,"id":40096589}]}]}
{"op":"mcm","clk":"11832057957","pt":1723079544840,"mc":[{"id":"1.231501647","rc":[{"trd":[[1.99,56.04]],"batb":[[0,1.99,42.08],[1,1.97,39.95],[2,1.94,375.55]],"batl":[[0,2,8.34],[1,2.02,2],[2,2.06,25]],"ltp":1.99,"tv":918.48,"id":40096581}],"tv":1019.69}]}
{"op":"mcm","clk":"11832058050","pt":1723079546647,"mc":[{"id":"1.231501647","rc":[{"batb":[[0,1.99,102.5],[1,1.92,800],[2,1.91,28]],"ltp":2.04,"tv":101.2,"id":40096589},{"batl":[[0,2.02,2],[1,2.06,25],[2,2.06,0]],"ltp":1.99,"tv":918.48,"id":40096581}]}]}
{"op":"mcm","clk":"11832058481","pt":1723079552843,"mc":[{"id":"1.231501647","rc":[{"batb":[[0,1.95,10],[1,1.94,550.98],[2,1.93,1076.92]],"ltp":1.99,"tv":918.48,"id":40096581}]}]}
{"op":"mcm","clk":"11832058610","pt":1723079553766,"mc":[{"id":"1.231501647","rc":[{"batb":[[0,2,12.73],[1,1.99,102.5],[2,1.92,800]],"batl":[[0,2.06,16.99]],"ltp":2.04,"tv":101.2,"id":40096589},{"batb":[[0,1.95,26.99],[1,1.94,375.55]],"batl":[[0,2,12.79],[1,2.02,2],[2,2.06,25]],"ltp":1.99,"tv":918.48,"id":40096581}]}]}
{"op":"mcm","clk":"11832058651","pt":1723079554538,"mc":[{"id":"1.231501647","rc":[{"batl":[[0,2,7.73]],"ltp":1.99,"tv":918.48,"id":40096581}]}]}
{"op":"mcm","clk":"11832058740","pt":1723079555975,"mc":[{"id":"1.231501647","rc":[{"batb":[[0,1.95,16.99]],"ltp":1.99,"tv":918.48,"id":40096581}]}]}
{"op":"mcm","clk":"11832058805","pt":1723079556956,"mc":[{"id":"1.231501647","rc":[{"batb":[[2,1.98,45.31]],"ltp":2.04,"tv":101.2,"id":40096589}]}]}
{"op":"mcm","clk":"11832058896","pt":1723079558356,"mc":[{"id":"1.231501647","rc":[{"batb":[[0,1.96,10],[1,1.95,16.99],[2,1.94,375.55]],"ltp":1.99,"tv":918.48,"id":40096581}]}]}
{"op":"mcm","clk":"11832059108","pt":1723079561740,"mc":[{"id":"1.231501647","rc":[{"batb":[[0,1.95,16.99],[1,1.94,375.55],[2,1.93,1076.92]],"ltp":1.99,"tv":918.48,"id":40096581}]}]}
{"op":"mcm","clk":"11832059265","pt":1723079564260,"mc":[{"id":"1.231501647","rc":[{"batb":[[0,1.96,10],[1,1.95,16.99],[2,1.94,375.55]],"ltp":1.99,"tv":918.48,"id":40096581}]}]}
{"op":"mcm","clk":"11832059440","pt":1723079567546,"mc":[{"id":"1.231501647","rc":[{"batb":[[0,1.95,16.99],[1,1.94,375.55],[2,1.93,1076.92]],"ltp":1.99,"tv":918.48,"id":40096581}]}]}
{"op":"mcm","clk":"11832059604","pt":1723079570581,"mc":[{"id":"1.231501647","rc":[{"batb":[[0,1.96,10],[1,1.95,16.99],[2,1.94,375.55]],"ltp":1.99,"tv":918.48,"id":40096581}]}]}
{"op":"mcm","clk":"11832059789","pt":1723079573973,"mc":[{"id":"1.231501647","rc":[{"batb":[[0,1.95,16.99],[1,1.94,375.55],[2,1.93,1076.92]],"ltp":1.99,"tv":918.48,"id":40096581}]}]}
{"op":"mcm","clk":"11832059924","pt":1723079576493,"mc":[{"id":"1.231501647","rc":[{"batb":[[0,1.96,10],[1,1.95,16.99],[2,1.94,375.55]],"ltp":1.99,"tv":918.48,"id":40096581}]}]}
{"op":"mcm","clk":"11832060106","pt":1723079579883,"mc":[{"id":"1.231501647","rc":[{"batb":[[0,1.95,16.99],[1,1.94,375.55],[2,1.93,1076.92]],"ltp":1.99,"tv":918.48,"id":40096581}]}]}
{"op":"mcm","clk":"11832060292","pt":1723079583285,"mc":[{"id":"1.231501647","rc":[{"batb":[[0,1.96,10],[1,1.95,16.99],[2,1.94,375.55]],"ltp":1.99,"tv":918.48,"id":40096581}]}]}
{"op":"mcm","clk":"11832060490","pt":1723079586786,"mc":[{"id":"1.231501647","rc":[{"batb":[[0,1.95,16.99],[1,1.94,375.55],[2,1.93,1076.92]],"ltp":1.99,"tv":918.48,"id":40096581}]}]}
{"op":"mcm","clk":"11832060618","pt":1723079589203,"mc":[{"id":"1.231501647","rc":[{"batb":[[0,1.96,10],[1,1.95,16.99],[2,1.94,375.55]],"ltp":1.99,"tv":918.48,"id":40096581}]}]}
{"op":"mcm","clk":"11832060798","pt":1723079592594,"mc":[{"id":"1.231501647","rc":[{"batb":[[0,1.95,16.99],[1,1.94,375.55],[2,1.93,1076.92]],"ltp":1.99,"tv":918.48,"id":40096581}]}]}
{"op":"mcm","clk":"11832060946","pt":1723079595221,"mc":[{"id":"1.231501647","rc":[{"batb":[[0,1.96,10],[1,1.95,16.99],[2,1.94,375.55]],"ltp":1.99,"tv":918.48,"id":40096581}]}]}
{"op":"mcm","clk":"11832061141","pt":1723079598509,"mc":[{"id":"1.231501647","rc":[{"batb":[[0,1.95,16.99],[1,1.94,375.55],[2,1.93,1076.92]],"ltp":1.99,"tv":918.48,"id":40096581}]}]}
{"op":"mcm","clk":"11832061262","pt":1723079601182,"mc":[{"id":"1.231501647","rc":[{"batb":[[0,1.96,10],[1,1.95,16.99],[2,1.94,375.55]],"ltp":1.99,"tv":918.48,"id":40096581}]}]}
{"op":"mcm","clk":"11832061448","pt":1723079604831,"mc":[{"id":"1.231501647","rc":[{"batb":[[0,1.95,16.99],[1,1.94,375.55],[2,1.93,1076.92]],"ltp":1.99,"tv":918.48,"id":40096581}]}]}
{"op":"mcm","clk":"11832061586","pt":1723079607096,"mc":[{"id":"1.231501647","rc":[{"batb":[[0,1.96,10],[1,1.95,16.99],[2,1.94,375.55]],"ltp":1.99,"tv":918.48,"id":40096581}]}]}
{"op":"mcm","clk":"11832061756","pt":1723079610436,"mc":[{"id":"1.231501647","rc":[{"batb":[[0,1.95,16.99],[1,1.94,375.55],[2,1.93,1076.92]],"ltp":1.99,"tv":918.48,"id":40096581}]}]}
{"op":"mcm","clk":"11832061880","pt":1723079612805,"mc":[{"id":"1.231501647","rc":[{"batb":[[0,1.96,10],[1,1.95,16.99],[2,1.94,375.55]],"ltp":1.99,"tv":918.48,"id":40096581}]}]}
{"op":"mcm","clk":"11832062072","pt":1723079616409,"mc":[{"id":"1.231501647","rc":[{"batb":[[0,1.95,16.99],[1,1.94,375.55],[2,1.93,1076.92]],"ltp":1.99,"tv":918.48,"id":40096581}]}]}
{"op":"mcm","clk":"11832062249","pt":1723079619248,"mc":[{"id":"1.231501647","rc":[{"batb":[[0,1.96,10],[1,1.95,16.99],[2,1.94,375.55]],"ltp":1.99,"tv":918.48,"id":40096581}]}]}
{"op":"mcm","clk":"11832062442","pt":1723079622733,"mc":[{"id":"1.231501647","rc":[{"batb":[[0,1.95,16.99],[1,1.94,375.55],[2,1.93,1076.92]],"ltp":1.99,"tv":918.48,"id":40096581}]}]}
{"op":"mcm","clk":"11832062547","pt":1723079625145,"mc":[{"id":"1.231501647","rc":[{"batb":[[0,1.96,10],[1,1.95,16.99],[2,1.94,375.55]],"ltp":1.99,"tv":918.48,"id":40096581}]}]}
{"op":"mcm","clk":"11832062730","pt":1723079628747,"mc":[{"id":"1.231501647","rc":[{"batb":[[0,1.95,16.99],[1,1.94,375.55],[2,1.93,1076.92]],"ltp":1.99,"tv":918.48,"id":40096581}]}]}
{"op":"mcm","clk":"11832062859","pt":1723079631156,"mc":[{"id":"1.231501647","rc":[{"batb":[[0,1.96,10],[1,1.95,16.99],[2,1.94,375.55]],"ltp":1.99,"tv":918.48,"id":40096581}]}]}
{"op":"mcm","clk":"11832063048","pt":1723079634955,"mc":[{"id":"1.231501647","rc":[{"batb":[[0,1.95,16.99],[1,1.94,375.55],[2,1.93,1076.92]],"ltp":1.99,"tv":918.48,"id":40096581}]}]}
{"op":"mcm","clk":"11832063149","pt":1723079637159,"mc":[{"id":"1.231501647","rc":[{"batb":[[0,1.96,10],[1,1.95,16.99],[2,1.94,375.55]],"ltp":1.99,"tv":918.48,"id":40096581}]}]}
{"op":"mcm","clk":"11832063326","pt":1723079640467,"mc":[{"id":"1.231501647","rc":[{"batb":[[0,1.95,16.99],[1,1.94,375.55],[2,1.93,1076.92]],"ltp":1.99,"tv":918.48,"id":40096581}]}]}
{"op":"mcm","clk":"11832063453","pt":1723079642936,"mc":[{"id":"1.231501647","rc":[{"batb":[[0,1.96,10],[1,1.95,16.99],[2,1.94,375.55]],"ltp":1.99,"tv":918.48,"id":40096581}]}]}
{"op":"mcm","clk":"11832063672","pt":1723079646232,"mc":[{"id":"1.231501647","rc":[{"batb":[[0,1.95,16.99],[1,1.94,375.55],[2,1.93,1076.92]],"ltp":1.99,"tv":918.48,"id":40096581}]}]}
{"op":"mcm","clk":"11832063821","pt":1723079649062,"mc":[{"id":"1.231501647","rc":[{"batb":[[0,1.96,10],[1,1.95,16.99],[2,1.94,375.55]],"ltp":1.99,"tv":918.48,"id":40096581}]}]}
{"op":"mcm","clk":"11832063986","pt":1723079652251,"mc":[{"id":"1.231501647","rc":[{"batb":[[0,1.95,16.99],[1,1.94,375.55],[2,1.93,1076.92]],"ltp":1.99,"tv":918.48,"id":40096581}]}]}
{"op":"mcm","clk":"11832064170","pt":1723079655132,"mc":[{"id":"1.231501647","rc":[{"batb":[[0,1.96,10],[1,1.95,16.99],[2,1.94,375.55]],"ltp":1.99,"tv":918.48,"id":40096581}]}]}
{"op":"mcm","clk":"11832064335","pt":1723079658567,"mc":[{"id":"1.231501647","rc":[{"batb":[[0,1.95,16.99],[1,1.94,375.55],[2,1.93,1076.92]],"ltp":1.99,"tv":918.48,"id":40096581}]}]}
{"op":"mcm","clk":"11832064509","pt":1723079662062,"mc":[{"id":"1.231501647","rc":[{"batb":[[0,1.96,10],[1,1.95,16.99],[2,1.94,375.55]],"ltp":1.99,"tv":918.48,"id":40096581}]}]}
{"op":"mcm","clk":"11832064694","pt":1723079665559,"mc":[{"id":"1.231501647","rc":[{"batb":[[0,1.95,16.99],[1,1.94,375.55],[2,1.93,1076.92]],"ltp":1.99,"tv":918.48,"id":40096581}]}]}
{"op":"mcm","clk":"11832064831","pt":1723079668488,"mc":[{"id":"1.231501647","rc":[{"batb":[[0,1.96,10],[1,1.95,16.99],[2,1.94,375.55]],"ltp":1.99,"tv":918.48,"id":40096581}]}]}
{"op":"mcm","clk":"11832065029","pt":1723079672400,"mc":[{"id":"1.231501647","rc":[{"batb":[[0,1.95,16.99],[1,1.94,375.55],[2,1.93,1076.92]],"ltp":1.99,"tv":918.48,"id":40096581}]}]}
{"op":"mcm","clk":"11832065185","pt":1723079675169,"mc":[{"id":"1.231501647","rc":[{"batb":[[0,1.96,10],[1,1.95,16.99],[2,1.94,375.55]],"ltp":1.99,"tv":918.48,"id":40096581}]}]}
{"op":"mcm","clk":"11832065337","pt":1723079678509,"mc":[{"id":"1.231501647","rc":[{"batb":[[0,1.95,16.99],[1,1.94,375.55],[2,1.93,1076.92]],"ltp":1.99,"tv":918.48,"id":40096581}]}]}
{"op":"mcm","clk":"11832065453","pt":1723079680682,"mc":[{"id":"1.231501647","rc":[{"batb":[[0,1.96,10],[1,1.95,16.99],[2,1.94,375.55]],"ltp":1.99,"tv":918.48,"id":40096581}]}]}
{"op":"mcm","clk":"11832065585","pt":1723079684110,"mc":[{"id":"1.231501647","rc":[{"batb":[[0,1.95,16.99],[1,1.94,375.55],[2,1.93,1076.92]],"ltp":1.99,"tv":918.48,"id":40096581}]}]}
{"op":"mcm","clk":"11832065706","pt":1723079686898,"mc":[{"id":"1.231501647","rc":[{"batb":[[0,1.96,10],[1,1.95,16.99],[2,1.94,375.55]],"ltp":1.99,"tv":918.48,"id":40096581}]}]}
{"op":"mcm","clk":"11832065853","pt":1723079690194,"mc":[{"id":"1.231501647","rc":[{"batb":[[0,1.95,16.99],[1,1.94,375.55],[2,1.93,1076.92]],"ltp":1.99,"tv":918.48,"id":40096581}]}]}
{"op":"mcm","clk":"11832065978","pt":1723079692914,"mc":[{"id":"1.231501647","rc":[{"batb":[[0,1.96,10],[1,1.95,16.99],[2,1.94,375.55]],"ltp":1.99,"tv":918.48,"id":40096581}]}]}
{"op":"mcm","clk":"11832066143","pt":1723079696109,"mc":[{"id":"1.231501647","rc":[{"batb":[[0,1.95,16.99],[1,1.94,375.55],[2,1.93,1076.92]],"ltp":1.99,"tv":918.48,"id":40096581}]}]}
{"op":"mcm","clk":"11832066300","pt":1723079698929,"mc":[{"id":"1.231501647","rc":[{"batb":[[0,1.96,10],[1,1.95,16.99],[2,1.94,375.55]],"ltp":1.99,"tv":918.48,"id":40096581}]}]}
{"op":"mcm","clk":"11832066508","pt":1723079702226,"mc":[{"id":"1.231501647","rc":[{"batb":[[0,1.95,16.99],[1,1.94,375.55],[2,1.93,1076.92]],"ltp":1.99,"tv":918.48,"id":40096581}]}]}
{"op":"mcm","clk":"11832066695","pt":1723079704840,"mc":[{"id":"1.231501647","rc":[{"batb":[[0,1.96,10],[1,1.95,16.99],[2,1.94,375.55]],"ltp":1.99,"tv":918.48,"id":40096581}]}]}
{"op":"mcm","clk":"11832066924","pt":1723079708411,"mc":[{"id":"1.231501647","rc":[{"batb":[[0,1.95,16.99],[1,1.94,375.55],[2,1.93,1076.92]],"ltp":1.99,"tv":918.48,"id":40096581}]}]}
{"op":"mcm","clk":"11832067051","pt":1723079711135,"mc":[{"id":"1.231501647","rc":[{"batb":[[0,1.96,10],[1,1.95,16.99],[2,1.94,375.55]],"ltp":1.99,"tv":918.48,"id":40096581}]}]}
{"op":"mcm","clk":"11832067216","pt":1723079714328,"mc":[{"id":"1.231501647","rc":[{"batb":[[0,1.95,16.99],[1,1.94,375.55],[2,1.93,1076.92]],"ltp":1.99,"tv":918.48,"id":40096581}]}]}
{"op":"mcm","clk":"11832067348","pt":1723079717148,"mc":[{"id":"1.231501647","rc":[{"batb":[[0,1.96,10],[1,1.95,16.99],[2,1.94,375.55]],"ltp":1.99,"tv":918.48,"id":40096581}]}]}
{"op":"mcm","clk":"11832067539","pt":1723079720552,"mc":[{"id":"1.231501647","rc":[{"batb":[[0,1.95,16.99],[1,1.94,375.55],[2,1.93,1076.92]],"ltp":1.99,"tv":918.48,"id":40096581}]}]}
{"op":"mcm","clk":"11832067691","pt":1723079723131,"mc":[{"id":"1.231501647","rc":[{"batb":[[0,1.96,10],[1,1.95,16.99],[2,1.94,375.55]],"ltp":1.99,"tv":918.48,"id":40096581}]}]}
{"op":"mcm","clk":"11832067879","pt":1723079726470,"mc":[{"id":"1.231501647","rc":[{"batb":[[0,1.95,16.99],[1,1.94,375.55],[2,1.93,1076.92]],"ltp":1.99,"tv":918.48,"id":40096581}]}]}
{"op":"mcm","clk":"11832068068","pt":1723079729875,"mc":[{"id":"1.231501647","rc":[{"batb":[[0,1.96,10],[1,1.95,16.99],[2,1.94,375.55]],"ltp":1.99,"tv":918.48,"id":40096581}]}]}
{"op":"mcm","clk":"11832068261","pt":1723079733482,"mc":[{"id":"1.231501647","rc":[{"batb":[[0,1.95,16.99],[1,1.94,375.55],[2,1.93,1076.92]],"ltp":1.99,"tv":918.48,"id":40096581}]}]}
{"op":"mcm","clk":"11832068413","pt":1723079736153,"mc":[{"id":"1.231501647","rc":[{"batb":[[0,1.96,10],[1,1.95,16.99],[2,1.94,375.55]],"ltp":1.99,"tv":918.48,"id":40096581}]}]}
{"op":"mcm","clk":"11832068602","pt":1723079739586,"mc":[{"id":"1.231501647","rc":[{"batb":[[0,1.95,16.99],[1,1.94,375.55],[2,1.93,1076.92]],"ltp":1.99,"tv":918.48,"id":40096581}]}]}
{"op":"mcm","clk":"11832068729","pt":1723079742050,"mc":[{"id":"1.231501647","rc":[{"batb":[[0,1.96,10],[1,1.95,16.99],[2,1.94,375.55]],"ltp":1.99,"tv":918.48,"id":40096581}]}]}
{"op":"mcm","clk":"11832068917","pt":1723079745386,"mc":[{"id":"1.231501647","rc":[{"batb":[[0,1.95,16.99],[1,1.94,375.55],[2,1.93,1076.92]],"ltp":1.99,"tv":918.48,"id":40096581}]}]}
{"op":"mcm","clk":"11832069111","pt":1723079749084,"mc":[{"id":"1.231501647","rc":[{"batb":[[0,1.96,10],[1,1.95,16.99],[2,1.94,375.55]],"ltp":1.99,"tv":918.48,"id":40096581}]}]}
{"op":"mcm","clk":"11832069313","pt":1723079752378,"mc":[{"id":"1.231501647","rc":[{"batb":[[0,1.95,16.99],[1,1.94,375.55],[2,1.93,1076.92]],"ltp":1.99,"tv":918.48,"id":40096581}]}]}
{"op":"mcm","clk":"11832069456","pt":1723079754804,"mc":[{"id":"1.231501647","rc":[{"batb":[[0,1.96,10],[1,1.95,16.99],[2,1.94,375.55]],"ltp":1.99,"tv":918.48,"id":40096581}]}]}
{"op":"mcm","clk":"11832069640","pt":1723079758199,"mc":[{"id":"1.231501647","rc":[{"batb":[[0,1.95,16.99],[1,1.94,375.55],[2,1.93,1076.92]],"ltp":1.99,"tv":918.48,"id":40096581}]}]}
{"op":"mcm","clk":"11832069859","pt":1723079761804,"mc":[{"id":"1.231501647","rc":[{"batb":[[0,1.96,10],[1,1.95,16.99],[2,1.94,375.55]],"ltp":1.99,"tv":918.48,"id":40096581}]}]}
{"op":"mcm","clk":"11832070075","pt":1723079765304,"mc":[{"id":"1.231501647","rc":[{"batb":[[0,1.95,16.99],[1,1.94,375.55],[2,1.93,1076.92]],"ltp":1.99,"tv":918.48,"id":40096581}]}]}
{"op":"mcm","clk":"11832070219","pt":1723079767515,"mc":[{"id":"1.231501647","rc":[{"batb":[[0,1.96,10],[1,1.95,16.99],[2,1.94,375.55]],"ltp":1.99,"tv":918.48,"id":40096581}]}]}
{"op":"mcm","clk":"11832070441","pt":1723079771095,"mc":[{"id":"1.231501647","rc":[{"batb":[[0,1.95,16.99],[1,1.94,375.55],[2,1.93,1076.92]],"ltp":1.99,"tv":918.48,"id":40096581}]}]}
{"op":"mcm","clk":"11832070595","pt":1723079773839,"mc":[{"id":"1.231501647","rc":[{"batb":[[0,1.96,10],[1,1.95,16.99],[2,1.94,375.55]],"ltp":1.99,"tv":918.48,"id":40096581}]}]}
{"op":"mcm","clk":"11832070794","pt":1723079777296,"mc":[{"id":"1.231501647","rc":[{"batb":[[0,1.95,16.99],[1,1.94,375.55],[2,1.93,1076.92]],"ltp":1.99,"tv":918.48,"id":40096581}]}]}
{"op":"mcm","clk":"11832070974","pt":1723079780024,"mc":[{"id":"1.231501647","rc":[{"batb":[[0,1.96,10],[1,1.95,16.99],[2,1.94,375.55]],"ltp":1.99,"tv":918.48,"id":40096581}]}]}
{"op":"mcm","clk":"11832071177","pt":1723079783520,"mc":[{"id":"1.231501647","rc":[{"batb":[[0,1.95,16.99],[1,1.94,375.55],[2,1.93,1076.92]],"ltp":1.99,"tv":918.48,"id":40096581}]}]}
{"op":"mcm","clk":"11832071430","pt":1723079787325,"mc":[{"id":"1.231501647","rc":[{"batb":[[0,1.96,10],[1,1.95,16.99],[2,1.94,375.55]],"ltp":1.99,"tv":918.48,"id":40096581}]}]}
{"op":"mcm","clk":"11832071628","pt":1723079790924,"mc":[{"id":"1.231501647","rc":[{"batb":[[0,1.95,16.99],[1,1.94,375.55],[2,1.93,1076.92]],"ltp":1.99,"tv":918.48,"id":40096581}]}]}
{"op":"mcm","clk":"11832071784","pt":1723079793443,"mc":[{"id":"1.231501647","rc":[{"batb":[[0,1.96,10],[1,1.95,16.99],[2,1.94,375.55]],"ltp":1.99,"tv":918.48,"id":40096581}]}]}
{"op":"mcm","clk":"11832072013","pt":1723079797152,"mc":[{"id":"1.231501647","rc":[{"batb":[[0,1.95,16.99],[1,1.94,375.55],[2,1.93,1076.92]],"ltp":1.99,"tv":918.48,"id":40096581}]}]}
{"op":"mcm","clk":"11832072125","pt":1723079799375,"mc":[{"id":"1.231501647","rc":[{"batb":[[0,1.96,10],[1,1.95,16.99],[2,1.94,375.55]],"ltp":1.99,"tv":918.48,"id":40096581}]}]}
{"op":"mcm","clk":"11832072323","pt":1723079802877,"mc":[{"id":"1.231501647","rc":[{"batb":[[0,1.95,16.99],[1,1.94,375.55],[2,1.93,1076.92]],"ltp":1.99,"tv":918.48,"id":40096581}]}]}
{"op":"mcm","clk":"11832072512","pt":1723079805651,"mc":[{"id":"1.231501647","rc":[{"batb":[[0,1.96,10],[1,1.95,16.99],[2,1.94,375.55]],"ltp":1.99,"tv":918.48,"id":40096581}]}]}
{"op":"mcm","clk":"11832072703","pt":1723079809043,"mc":[{"id":"1.231501647","rc":[{"batb":[[0,1.95,16.99],[1,1.94,375.55],[2,1.93,1076.92]],"ltp":1.99,"tv":918.48,"id":40096581}]}]}
{"op":"mcm","clk":"11832072876","pt":1723079811365,"mc":[{"id":"1.231501647","rc":[{"batb":[[0,1.96,10],[1,1.95,16.99],[2,1.94,375.55]],"ltp":1.99,"tv":918.48,"id":40096581}]}]}
{"op":"mcm","clk":"11832073065","pt":1723079814858,"mc":[{"id":"1.231501647","rc":[{"batb":[[0,1.95,16.99],[1,1.94,375.55],[2,1.93,1076.92]],"ltp":1.99,"tv":918.48,"id":40096581}]}]}
{"op":"mcm","clk":"11832073190","pt":1723079817382,"mc":[{"id":"1.231501647","rc":[{"batb":[[0,1.96,10],[1,1.95,16.99],[2,1.94,375.55]],"ltp":1.99,"tv":918.48,"id":40096581}]}]}
{"op":"mcm","clk":"11832073373","pt":1723079820697,"mc":[{"id":"1.231501647","rc":[{"batb":[[0,1.95,16.99],[1,1.94,375.55],[2,1.93,1076.92]],"ltp":1.99,"tv":918.48,"id":40096581}]}]}
{"op":"mcm","clk":"11832073532","pt":1723079823478,"mc":[{"id":"1.231501647","rc":[{"batb":[[0,1.96,10],[1,1.95,16.99],[2,1.94,375.55]],"ltp":1.99,"tv":918.48,"id":40096581}]}]}
{"op":"mcm","clk":"11832073740","pt":1723079826883,"mc":[{"id":"1.231501647","rc":[{"batl":[[0,2.04,4.32],[1,2.06,16.99]],"ltp":2.04,"tv":101.2,"id":40096589},{"batb":[[0,1.95,16.99],[1,1.94,375.55],[2,1.93,1076.92]],"ltp":1.99,"tv":918.48,"id":40096581}]}]}
{"op":"mcm","clk":"11832073816","pt":1723079828375,"mc":[{"id":"1.231501647","rc":[{"batl":[[0,2.06,16.99],[1,2.06,0]],"ltp":2.04,"tv":101.2,"id":40096589}]}]}
{"op":"mcm","clk":"11832073877","pt":1723079829462,"mc":[{"id":"1.231501647","rc":[{"batb":[[0,1.96,10],[1,1.95,16.99],[2,1.94,375.55]],"ltp":1.99,"tv":918.48,"id":40096581}]}]}
{"op":"mcm","clk":"11832074060","pt":1723079832906,"mc":[{"id":"1.231501647","rc":[{"batb":[[0,1.95,16.99],[1,1.94,375.55],[2,1.93,1076.92]],"ltp":1.99,"tv":918.48,"id":40096581}]}]}
{"op":"mcm","clk":"11832074184","pt":1723079835382,"mc":[{"id":"1.231501647","rc":[{"batb":[[0,1.96,10],[1,1.95,16.99],[2,1.94,375.55]],"ltp":1.99,"tv":918.48,"id":40096581}]}]}
{"op":"mcm","clk":"11832074399","pt":1723079839004,"mc":[{"id":"1.231501647","rc":[{"batb":[[0,1.95,16.99],[1,1.94,375.55],[2,1.93,1076.92]],"ltp":1.99,"tv":918.48,"id":40096581}]}]}
{"op":"mcm","clk":"11832074532","pt":1723079841892,"mc":[{"id":"1.231501647","rc":[{"batb":[[0,1.96,10],[1,1.95,16.99],[2,1.94,375.55]],"ltp":1.99,"tv":918.48,"id":40096581}]}]}
{"op":"mcm","clk":"11832074723","pt":1723079845496,"mc":[{"id":"1.231501647","rc":[{"batb":[[0,1.95,16.99],[1,1.94,375.55],[2,1.93,1076.92]],"ltp":1.99,"tv":918.48,"id":40096581}]}]}
{"op":"mcm","clk":"11832074835","pt":1723079847714,"mc":[{"id":"1.231501647","rc":[{"batb":[[0,1.96,10],[1,1.95,16.99],[2,1.94,375.55]],"ltp":1.99,"tv":918.48,"id":40096581}]}]}
{"op":"mcm","clk":"11832075048","pt":1723079851620,"mc":[{"id":"1.231501647","rc":[{"batb":[[0,1.95,16.99],[1,1.94,375.55],[2,1.93,1076.92]],"ltp":1.99,"tv":918.48,"id":40096581}]}]}
{"op":"mcm","clk":"11832075201","pt":1723079854499,"mc":[{"id":"1.231501647","rc":[{"batb":[[0,1.96,10],[1,1.95,16.99],[2,1.94,375.55]],"ltp":1.99,"tv":918.48,"id":40096581}]}]}
{"op":"mcm","clk":"11832075418","pt":1723079858201,"mc":[{"id":"1.231501647","rc":[{"batb":[[0,1.95,16.99],[1,1.94,375.55],[2,1.93,1076.92]],"ltp":1.99,"tv":918.48,"id":40096581}]}]}
{"op":"mcm","clk":"11832075589","pt":1723079861332,"mc":[{"id":"1.231501647","rc":[{"batb":[[0,1.96,10],[1,1.95,16.99],[2,1.94,375.55]],"ltp":1.99,"tv":918.48,"id":40096581}]}]}
{"op":"mcm","clk":"11832075756","pt":1723079864817,"mc":[{"id":"1.231501647","rc":[{"batb":[[0,1.95,16.99],[1,1.94,375.55],[2,1.93,1076.92]],"ltp":1.99,"tv":918.48,"id":40096581}]}]}
{"op":"mcm","clk":"11832075912","pt":1723079867739,"mc":[{"id":"1.231501647","rc":[{"batb":[[0,1.96,10],[1,1.95,16.99],[2,1.94,375.55]],"ltp":1.99,"tv":918.48,"id":40096581}]}]}
{"op":"mcm","clk":"11832075980","pt":1723079869228,"mc":[{"id":"1.231501647","rc":[{"batl":[[0,2.04,4.32],[1,2.06,16.99]],"ltp":2.04,"tv":101.2,"id":40096589}]}]}
{"op":"mcm","clk":"11832076088","pt":1723079871129,"mc":[{"id":"1.231501647","rc":[{"batb":[[0,1.95,16.99],[1,1.94,375.55],[2,1.93,1076.92]],"ltp":1.99,"tv":918.48,"id":40096581}]}]}
{"op":"mcm","clk":"11832076128","pt":1723079872046,"mc":[{"id":"1.231501647","rc":[{"batl":[[0,2.06,16.99],[1,2.06,0]],"ltp":2.04,"tv":101.2,"id":40096589}]}]}
{"op":"mcm","clk":"11832076224","pt":1723079874347,"mc":[{"id":"1.231501647","rc":[{"batb":[[0,1.96,10],[1,1.95,16.99],[2,1.94,375.55]],"ltp":1.99,"tv":918.48,"id":40096581}]}]}
{"op":"mcm","clk":"11832076405","pt":1723079877738,"mc":[{"id":"1.231501647","rc":[{"batb":[[0,1.95,16.99],[1,1.94,375.55],[2,1.93,1076.92]],"ltp":1.99,"tv":918.48,"id":40096581}]}]}
{"op":"mcm","clk":"11832076526","pt":1723079880350,"mc":[{"id":"1.231501647","rc":[{"batb":[[0,1.96,10],[1,1.95,16.99],[2,1.94,375.55]],"ltp":1.99,"tv":918.48,"id":40096581}]}]}
{"op":"mcm","clk":"11832076698","pt":1723079883744,"mc":[{"id":"1.231501647","rc":[{"batb":[[0,1.95,16.99],[1,1.94,375.55],[2,1.93,1076.92]],"ltp":1.99,"tv":918.48,"id":40096581}]}]}
{"op":"mcm","clk":"11832076842","pt":1723079886338,"mc":[{"id":"1.231501647","rc":[{"batb":[[0,1.96,10],[1,1.95,16.99],[2,1.94,375.55]],"ltp":1.99,"tv":918.48,"id":40096581}]}]}
{"op":"mcm","clk":"11832076990","pt":1723079889634,"mc":[{"id":"1.231501647","rc":[{"batb":[[0,1.95,16.99],[1,1.94,375.55],[2,1.93,1076.92]],"ltp":1.99,"tv":918.48,"id":40096581}]}]}
{"op":"mcm","clk":"11832077153","pt":1723079892760,"mc":[{"id":"1.231501647","rc":[{"batb":[[0,1.96,10],[1,1.95,16.99],[2,1.94,375.55]],"ltp":1.99,"tv":918.48,"id":40096581}]}]}
{"op":"mcm","clk":"11832077324","pt":1723079896261,"mc":[{"id":"1.231501647","rc":[{"batb":[[0,1.95,16.99],[1,1.94,375.55],[2,1.93,1076.92]],"ltp":1.99,"tv":918.48,"id":40096581}]}]}
{"op":"mcm","clk":"11832077477","pt":1723079899081,"mc":[{"id":"1.231501647","rc":[{"batb":[[0,1.96,10],[1,1.95,16.99],[2,1.94,375.55]],"ltp":1.99,"tv":918.48,"id":40096581}]}]}
{"op":"mcm","clk":"11832077661","pt":1723079902480,"mc":[{"id":"1.231501647","rc":[{"batb":[[0,1.95,16.99],[1,1.94,375.55],[2,1.93,1076.92]],"ltp":1.99,"tv":918.48,"id":40096581}]}]}
{"op":"mcm","clk":"11832077771","pt":1723079904845,"mc":[{"id":"1.231501647","rc":[{"batb":[[0,1.96,10],[1,1.95,16.99],[2,1.94,375.55]],"ltp":1.99,"tv":918.48,"id":40096581}]}]}
{"op":"mcm","clk":"11832077925","pt":1723079908393,"mc":[{"id":"1.231501647","rc":[{"batb":[[0,1.95,16.99],[1,1.94,375.55],[2,1.93,1076.92]],"ltp":1.99,"tv":918.48,"id":40096581}]}]}
{"op":"mcm","clk":"11832078121","pt":1723079911692,"mc":[{"id":"1.231501647","rc":[{"batl":[[0,2.04,4.32],[1,2.06,16.99]],"ltp":2.04,"tv":101.2,"id":40096589},{"batb":[[0,1.96,10],[1,1.95,16.99],[2,1.94,375.55]],"ltp":1.99,"tv":918.48,"id":40096581}]}]}
{"op":"mcm","clk":"11832078266","pt":1723079914777,"mc":[{"id":"1.231501647","rc":[{"batb":[[0,1.95,16.99],[1,1.94,375.55],[2,1.93,1076.92]],"ltp":1.99,"tv":918.48,"id":40096581}]}]}
{"op":"mcm","clk":"11832078368","pt":1723079916883,"mc":[{"id":"1.231501647","rc":[{"batl":[[0,2.06,16.99],[1,2.06,0]],"ltp":2.04,"tv":101.2,"id":40096589}]}]}
{"op":"mcm","clk":"11832078388","pt":1723079917291,"mc":[{"id":"1.231501647","rc":[{"batb":[[0,1.96,10],[1,1.95,16.99],[2,1.94,375.55]],"ltp":1.99,"tv":918.48,"id":40096581}]}]}
{"op":"mcm","clk":"11832078565","pt":1723079920784,"mc":[{"id":"1.231501647","rc":[{"batb":[[0,1.95,16.99],[1,1.94,375.55],[2,1.93,1076.92]],"ltp":1.99,"tv":918.48,"id":40096581}]}]}
{"op":"mcm","clk":"11832078709","pt":1723079923359,"mc":[{"id":"1.231501647","rc":[{"batb":[[0,1.96,10],[1,1.95,16.99],[2,1.94,375.55]],"ltp":1.99,"tv":918.48,"id":40096581}]}]}
{"op":"mcm","clk":"11832078904","pt":1723079927030,"mc":[{"id":"1.231501647","rc":[{"batb":[[0,1.95,16.99],[1,1.94,375.55],[2,1.93,1076.92]],"ltp":1.99,"tv":918.48,"id":40096581}]}]}
{"op":"mcm","clk":"11832079060","pt":1723079930313,"mc":[{"id":"1.231501647","rc":[{"batb":[[0,1.96,10],[1,1.95,16.99],[2,1.94,375.55]],"ltp":1.99,"tv":918.48,"id":40096581}]}]}
{"op":"mcm","clk":"11832079230","pt":1723079933609,"mc":[{"id":"1.231501647","rc":[{"batb":[[0,1.95,16.99],[1,1.94,375.55],[2,1.93,1076.92]],"ltp":1.99,"tv":918.48,"id":40096581}]}]}
{"op":"mcm","clk":"11832079378","pt":1723079936480,"mc":[{"id":"1.231501647","rc":[{"batb":[[0,1.96,10],[1,1.95,16.99],[2,1.94,375.55]],"ltp":1.99,"tv":918.48,"id":40096581}]}]}
{"op":"mcm","clk":"11832079523","pt":1723079940228,"mc":[{"id":"1.231501647","rc":[{"batb":[[0,1.95,16.99],[1,1.94,375.55],[2,1.93,1076.92]],"ltp":1.99,"tv":918.48,"id":40096581}]}]}
{"op":"mcm","clk":"11832079680","pt":1723079942697,"mc":[{"id":"1.231501647","rc":[{"batb":[[0,1.96,10],[1,1.95,16.99],[2,1.94,375.55]],"ltp":1.99,"tv":918.48,"id":40096581}]}]}
{"op":"mcm","clk":"11832079857","pt":1723079946131,"mc":[{"id":"1.231501647","rc":[{"batb":[[0,1.95,16.99],[1,1.94,375.55],[2,1.93,1076.92]],"ltp":1.99,"tv":918.48,"id":40096581}]}]}
{"op":"mcm","clk":"11832080011","pt":1723079949418,"mc":[{"id":"1.231501647","rc":[{"batb":[[0,1.96,10],[1,1.95,16.99],[2,1.94,375.55]],"ltp":1.99,"tv":918.48,"id":40096581}]}]}
{"op":"mcm","clk":"11832080175","pt":1723079953103,"mc":[{"id":"1.231501647","rc":[{"batb":[[0,1.95,16.99],[1,1.94,375.55],[2,1.93,1076.92]],"ltp":1.99,"tv":918.48,"id":40096581}]}]}
{"op":"mcm","clk":"11832080276","pt":1723079955308,"mc":[{"id":"1.231501647","rc":[{"batb":[[0,1.96,10],[1,1.95,16.99],[2,1.94,375.55]],"ltp":1.99,"tv":918.48,"id":40096581}]}]}
{"op":"mcm","clk":"11832080300","pt":1723079955926,"mc":[{"id":"1.231501647","rc":[{"batl":[[0,2.04,4.32],[1,2.06,16.99]],"ltp":2.04,"tv":101.2,"id":40096589}]}]}
{"op":"mcm","clk":"11832080443","pt":1723079958861,"mc":[{"id":"1.231501647","rc":[{"batb":[[0,1.95,16.99],[1,1.94,375.55],[2,1.93,1076.92]],"ltp":1.99,"tv":918.48,"id":40096581}]}]}
{"op":"mcm","clk":"11832080517","pt":1723079960762,"mc":[{"id":"1.231501647","rc":[{"batl":[[0,2.06,16.99],[1,2.06,0]],"ltp":2.04,"tv":101.2,"id":40096589}]}]}
{"op":"mcm","clk":"11832080565","pt":1723079961842,"mc":[{"id":"1.231501647","rc":[{"batb":[[0,1.96,10],[1,1.95,16.99],[2,1.94,375.55]],"ltp":1.99,"tv":918.48,"id":40096581}]}]}
{"op":"mcm","clk":"11832080716","pt":1723079965127,"mc":[{"id":"1.231501647","rc":[{"batb":[[0,1.95,16.99],[1,1.94,375.55],[2,1.93,1076.92]],"ltp":1.99,"tv":918.48,"id":40096581}]}]}
{"op":"mcm","clk":"11832080869","pt":1723079968561,"mc":[{"id":"1.231501647","rc":[{"batb":[[0,1.96,10],[1,1.95,16.99],[2,1.94,375.55]],"ltp":1.99,"tv":918.48,"id":40096581}]}]}
{"op":"mcm","clk":"11832081004","pt":1723079971951,"mc":[{"id":"1.231501647","rc":[{"batb":[[0,1.95,16.99],[1,1.94,375.55],[2,1.93,1076.92]],"ltp":1.99,"tv":918.48,"id":40096581}]}]}
{"op":"mcm","clk":"11832081108","pt":1723079974364,"mc":[{"id":"1.231501647","rc":[{"batb":[[0,1.96,10],[1,1.95,16.99],[2,1.94,375.55]],"ltp":1.99,"tv":918.48,"id":40096581}]}]}
{"op":"mcm","clk":"11832081297","pt":1723079977867,"mc":[{"id":"1.231501647","rc":[{"batb":[[0,1.95,16.99],[1,1.94,375.55],[2,1.93,1076.92]],"ltp":1.99,"tv":918.48,"id":40096581}]}]}
{"op":"mcm","clk":"11832081437","pt":1723079980662,"mc":[{"id":"1.231501647","rc":[{"batb":[[0,1.96,10],[1,1.95,16.99],[2,1.94,375.55]],"ltp":1.99,"tv":918.48,"id":40096581}]}]}
{"op":"mcm","clk":"11832081616","pt":1723079984291,"mc":[{"id":"1.231501647","rc":[{"batb":[[0,1.95,16.99],[1,1.94,375.55],[2,1.93,1076.92]],"ltp":1.99,"tv":918.48,"id":40096581}]}]}
{"op":"mcm","clk":"11832081748","pt":1723079987085,"mc":[{"id":"1.231501647","rc":[{"batb":[[0,1.96,10],[1,1.95,16.99],[2,1.94,375.55]],"ltp":1.99,"tv":918.48,"id":40096581}]}]}
{"op":"mcm","clk":"11832081954","pt":1723079990472,"mc":[{"id":"1.231501647","rc":[{"batb":[[0,1.95,16.99],[1,1.94,375.55],[2,1.93,1076.92]],"ltp":1.99,"tv":918.48,"id":40096581}]}]}
{"op":"mcm","clk":"11832082079","pt":1723079992891,"mc":[{"id":"1.231501647","rc":[{"batb":[[0,1.96,10],[1,1.95,16.99],[2,1.94,375.55]],"ltp":1.99,"tv":918.48,"id":40096581}]}]}
{"op":"mcm","clk":"11832082246","pt":1723079996311,"mc":[{"id":"1.231501647","rc":[{"batb":[[0,1.95,16.99],[1,1.94,375.55],[2,1.93,1076.92]],"ltp":1.99,"tv":918.48,"id":40096581}]}]}
{"op":"mcm","clk":"11832082347","pt":1723079998575,"mc":[{"id":"1.231501647","rc":[{"batb":[[0,1.96,10],[1,1.95,16.99],[2,1.94,375.55]],"ltp":1.99,"tv":918.48,"id":40096581}]}]}
{"op":"mcm","clk":"11832082459","pt":1723080000693,"mc":[{"id":"1.231501647","rc":[{"batl":[[0,2.04,4.32],[1,2.06,16.99]],"ltp":2.04,"tv":101.2,"id":40096589}]}]}
{"op":"mcm","clk":"11832082511","pt":1723080001973,"mc":[{"id":"1.231501647","rc":[{"batb":[[0,1.95,16.99],[1,1.94,375.55],[2,1.93,1076.92]],"ltp":1.99,"tv":918.48,"id":40096581}]}]}
{"op":"mcm","clk":"11832082624","pt":1723080003514,"mc":[{"id":"1.231501647","rc":[{"batl":[[0,2.06,16.99],[1,2.06,0]],"ltp":2.04,"tv":101.2,"id":40096589}]}]}
{"op":"mcm","clk":"11832082730","pt":1723080005618,"mc":[{"id":"1.231501647","rc":[{"batb":[[0,1.96,10],[1,1.95,16.99],[2,1.94,375.55]],"ltp":1.99,"tv":918.48,"id":40096581}]}]}
{"op":"mcm","clk":"11832082923","pt":1723080009018,"mc":[{"id":"1.231501647","rc":[{"batb":[[0,1.95,16.99],[1,1.94,375.55],[2,1.93,1076.92]],"ltp":1.99,"tv":918.48,"id":40096581}]}]}
{"op":"mcm","clk":"11832083066","pt":1723080011497,"mc":[{"id":"1.231501647","rc":[{"batb":[[0,1.96,10],[1,1.95,16.99],[2,1.94,375.55]],"ltp":1.99,"tv":918.48,"id":40096581}]}]}
{"op":"mcm","clk":"11832083242","pt":1723080015027,"mc":[{"id":"1.231501647","rc":[{"batb":[[0,1.95,16.99],[1,1.94,375.55],[2,1.93,1076.92]],"ltp":1.99,"tv":918.48,"id":40096581}]}]}
{"op":"mcm","clk":"11832083382","pt":1723080017504,"mc":[{"id":"1.231501647","rc":[{"batb":[[0,1.96,10],[1,1.95,16.99],[2,1.94,375.55]],"ltp":1.99,"tv":918.48,"id":40096581}]}]}
{"op":"mcm","clk":"11832083559","pt":1723080020838,"mc":[{"id":"1.231501647","rc":[{"batb":[[0,1.95,16.99],[1,1.94,375.55],[2,1.93,1076.92]],"ltp":1.99,"tv":918.48,"id":40096581}]}]}
{"op":"mcm","clk":"11832083668","pt":1723080023304,"mc":[{"id":"1.231501647","rc":[{"batb":[[0,1.96,10],[1,1.95,16.99],[2,1.94,375.55]],"ltp":1.99,"tv":918.48,"id":40096581}]}]}
{"op":"mcm","clk":"11832083827","pt":1723080026648,"mc":[{"id":"1.231501647","rc":[{"batb":[[0,1.95,16.99],[1,1.94,375.55],[2,1.93,1076.92]],"ltp":1.99,"tv":918.48,"id":40096581}]}]}
{"op":"mcm","clk":"11832083938","pt":1723080029114,"mc":[{"id":"1.231501647","rc":[{"batb":[[0,1.96,10],[1,1.95,16.99],[2,1.94,375.55]],"ltp":1.99,"tv":918.48,"id":40096581}]}]}
{"op":"mcm","clk":"11832084116","pt":1723080032623,"mc":[{"id":"1.231501647","rc":[{"batb":[[0,1.95,16.99],[1,1.94,375.55],[2,1.93,1076.92]],"ltp":1.99,"tv":918.48,"id":40096581}]}]}
{"op":"mcm","clk":"11832084223","pt":1723080034946,"mc":[{"id":"1.231501647","rc":[{"batb":[[0,1.96,10],[1,1.95,16.99],[2,1.94,375.55]],"ltp":1.99,"tv":918.48,"id":40096581}]}]}
{"op":"mcm","clk":"11832084379","pt":1723080038330,"mc":[{"id":"1.231501647","rc":[{"batb":[[0,1.95,16.99],[1,1.94,375.55],[2,1.93,1076.92]],"ltp":1.99,"tv":918.48,"id":40096581}]}]}
{"op":"mcm","clk":"11832084504","pt":1723080040962,"mc":[{"id":"1.231501647","rc":[{"batb":[[0,1.96,10],[1,1.95,16.99],[2,1.94,375.55]],"ltp":1.99,"tv":918.48,"id":40096581}]}]}
{"op":"mcm","clk":"11832084662","pt":1723080044348,"mc":[{"id":"1.231501647","rc":[{"batl":[[0,2.04,4.32],[1,2.06,16.99]],"ltp":2.04,"tv":101.2,"id":40096589},{"batb":[[0,1.95,16.99],[1,1.94,375.55],[2,1.93,1076.92]],"ltp":1.99,"tv":918.48,"id":40096581}]}]}
{"op":"mcm","clk":"11832084792","pt":1723080047170,"mc":[{"id":"1.231501647","rc":[{"batl":[[0,2.06,16.99],[1,2.06,0]],"ltp":2.04,"tv":101.2,"id":40096589},{"batb":[[0,1.96,10],[1,1.95,16.99],[2,1.94,375.55]],"ltp":1.99,"tv":918.48,"id":40096581}]}]}
{"op":"mcm","clk":"11832084948","pt":1723080050453,"mc":[{"id":"1.231501647","rc":[{"batb":[[0,1.95,16.99],[1,1.94,375.55],[2,1.93,1076.92]],"ltp":1.99,"tv":918.48,"id":40096581}]}]}
{"op":"mcm","clk":"11832085124","pt":1723080053744,"mc":[{"id":"1.231501647","rc":[{"batb":[[0,1.96,10],[1,1.95,16.99],[2,1.94,375.55]],"ltp":1.99,"tv":918.48,"id":40096581}]}]}
{"op":"mcm","clk":"11832085276","pt":1723080057070,"mc":[{"id":"1.231501647","rc":[{"batb":[[0,1.95,16.99],[1,1.94,375.55],[2,1.93,1076.92]],"ltp":1.99,"tv":918.48,"id":40096581}]}]}
{"op":"mcm","clk":"11832085415","pt":1723080059893,"mc":[{"id":"1.231501647","rc":[{"batb":[[0,1.96,10],[1,1.95,16.99],[2,1.94,375.55]],"ltp":1.99,"tv":918.48,"id":40096581}]}]}
{"op":"mcm","clk":"11832085603","pt":1723080063590,"mc":[{"id":"1.231501647","rc":[{"batb":[[0,1.95,16.99],[1,1.94,375.55],[2,1.93,1076.92]],"ltp":1.99,"tv":918.48,"id":40096581}]}]}
{"op":"mcm","clk":"11832085734","pt":1723080065960,"mc":[{"id":"1.231501647","rc":[{"batb":[[0,1.96,10],[1,1.95,16.99],[2,1.94,375.55]],"ltp":1.99,"tv":918.48,"id":40096581}]}]}
{"op":"mcm","clk":"11832085931","pt":1723080069398,"mc":[{"id":"1.231501647","rc":[{"batb":[[0,1.95,16.99],[1,1.94,375.55],[2,1.93,1076.92]],"ltp":1.99,"tv":918.48,"id":40096581}]}]}
{"op":"mcm","clk":"11832086111","pt":1723080072679,"mc":[{"id":"1.231501647","rc":[{"batb":[[0,1.96,10],[1,1.95,16.99],[2,1.94,375.55]],"ltp":1.99,"tv":918.48,"id":40096581}]}]}
{"op":"mcm","clk":"11832086278","pt":1723080075908,"mc":[{"id":"1.231501647","rc":[{"batb":[[0,1.95,16.99],[1,1.94,375.55],[2,1.93,1076.92]],"ltp":1.99,"tv":918.48,"id":40096581}]}]}
{"op":"mcm","clk":"11832086408","pt":1723080079087,"mc":[{"id":"1.231501647","rc":[{"batb":[[0,1.96,10],[1,1.95,16.99],[2,1.94,375.55]],"ltp":1.99,"tv":918.48,"id":40096581}]}]}
{"op":"mcm","clk":"11832086568","pt":1723080082378,"mc":[{"id":"1.231501647","rc":[{"batb":[[0,1.95,16.99],[1,1.94,375.55],[2,1.93,1076.92]],"ltp":1.99,"tv":918.48,"id":40096581}]}]}
{"op":"mcm","clk":"11832086711","pt":1723080085094,"mc":[{"id":"1.231501647","rc":[{"batb":[[0,1.96,10],[1,1.95,16.99],[2,1.94,375.55]],"ltp":1.99,"tv":918.48,"id":40096581}]}]}
{"op":"mcm","clk":"11832086958","pt":1723080089377,"mc":[{"id":"1.231501647","rc":[{"batl":[[0,2.04,4.32],[1,2.06,16.99]],"ltp":2.04,"tv":101.2,"id":40096589},{"batb":[[0,1.95,16.99],[1,1.94,375.55],[2,1.93,1076.92]],"ltp":1.99,"tv":918.48,"id":40096581}]}]}
{"op":"mcm","clk":"11832087070","pt":1723080091579,"mc":[{"id":"1.231501647","rc":[{"batl":[[0,2.06,16.99],[1,2.06,0]],"ltp":2.04,"tv":101.2,"id":40096589},{"batb":[[0,1.96,10],[1,1.95,16.99],[2,1.94,375.55]],"ltp":1.99,"tv":918.48,"id":40096581}]}]}
{"op":"mcm","clk":"11832087249","pt":1723080095023,"mc":[{"id":"1.231501647","rc":[{"batb":[[0,1.95,16.99],[1,1.94,375.55],[2,1.93,1076.92]],"ltp":1.99,"tv":918.48,"id":40096581}]}]}
{"op":"mcm","clk":"11832087375","pt":1723080097590,"mc":[{"id":"1.231501647","rc":[{"batb":[[0,1.96,10],[1,1.95,16.99],[2,1.94,375.55]],"ltp":1.99,"tv":918.48,"id":40096581}]}]}
{"op":"mcm","clk":"11832087549","pt":1723080101044,"mc":[{"id":"1.231501647","rc":[{"batb":[[0,1.95,16.99],[1,1.94,375.55],[2,1.93,1076.92]],"ltp":1.99,"tv":918.48,"id":40096581}]}]}
{"op":"mcm","clk":"11832087670","pt":1723080103709,"mc":[{"id":"1.231501647","rc":[{"batb":[[0,1.96,10],[1,1.95,16.99],[2,1.94,375.55]],"ltp":1.99,"tv":918.48,"id":40096581}]}]}
{"op":"mcm","clk":"11832087842","pt":1723080107117,"mc":[{"id":"1.231501647","rc":[{"batb":[[0,1.95,16.99],[1,1.94,375.55],[2,1.93,1076.92]],"ltp":1.99,"tv":918.48,"id":40096581}]}]}
{"op":"mcm","clk":"11832087977","pt":1723080110519,"mc":[{"id":"1.231501647","rc":[{"batb":[[0,1.96,10],[1,1.95,16.99],[2,1.94,375.55]],"ltp":1.99,"tv":918.48,"id":40096581}]}]}
{"op":"mcm","clk":"11832088015","pt":1723080111441,"mc":[{"id":"1.231501647","rc":[{"batb":[[2,1.94,98.63]],"ltp":1.99,"tv":918.48,"id":40096581}]}]}
{"op":"mcm","clk":"11832088129","pt":1723080113811,"mc":[{"id":"1.231501647","rc":[{"batb":[[0,1.95,16.99],[1,1.94,98.63],[2,1.93,800]],"ltp":1.99,"tv":918.48,"id":40096581}]}]}
{"op":"mcm","clk":"11832088337","pt":1723080118230,"mc":[{"id":"1.231501647","rc":[{"batb":[[0,1.96,10],[1,1.95,16.99],[2,1.94,98.63]],"ltp":1.99,"tv":918.48,"id":40096581}]}]}
{"op":"mcm","clk":"11832088509","pt":1723080121731,"mc":[{"id":"1.231501647","rc":[{"batb":[[0,1.95,16.99],[1,1.94,98.63],[2,1.93,800]],"ltp":1.99,"tv":918.48,"id":40096581}]}]}
{"op":"mcm","clk":"11832088638","pt":1723080124448,"mc":[{"id":"1.231501647","rc":[{"batb":[[0,1.96,10],[1,1.95,16.99],[2,1.94,98.63]],"ltp":1.99,"tv":918.48,"id":40096581}]}]}
{"op":"mcm","clk":"11832088829","pt":1723080127819,"mc":[{"id":"1.231501647","rc":[{"batb":[[0,1.95,16.99],[1,1.94,98.63],[2,1.93,800]],"ltp":1.99,"tv":918.48,"id":40096581}]}]}
{"op":"mcm","clk":"11832088978","pt":1723080130221,"mc":[{"id":"1.231501647","rc":[{"batb":[[0,1.96,10],[1,1.95,16.99],[2,1.94,98.63]],"ltp":1.99,"tv":918.48,"id":40096581}]}]}
{"op":"mcm","clk":"11832089114","pt":1723080132739,"mc":[{"id":"1.231501647","rc":[{"batl":[[0,2.04,4.32],[1,2.06,16.99]],"ltp":2.04,"tv":101.2,"id":40096589}]}]}
{"op":"mcm","clk":"11832089155","pt":1723080133459,"mc":[{"id":"1.231501647","rc":[{"batb":[[0,1.95,16.99],[1,1.94,98.63],[2,1.93,800]],"ltp":1.99,"tv":918.48,"id":40096581}]}]}
{"op":"mcm","clk":"11832089233","pt":1723080134954,"mc":[{"id":"1.231501647","rc":[{"batl":[[0,2.06,16.99],[1,2.06,0]],"ltp":2.04,"tv":101.2,"id":40096589}]}]}
{"op":"mcm","clk":"11832089312","pt":1723080136342,"mc":[{"id":"1.231501647","rc":[{"batb":[[0,1.96,10],[1,1.95,16.99],[2,1.94,98.63]],"ltp":1.99,"tv":918.48,"id":40096581}]}]}
{"op":"mcm","clk":"11832089472","pt":1723080139850,"mc":[{"id":"1.231501647","rc":[{"batb":[[0,1.95,16.99],[1,1.94,98.63],[2,1.93,800]],"ltp":1.99,"tv":918.48,"id":40096581}]}]}
{"op":"mcm","clk":"11832089614","pt":1723080142841,"mc":[{"id":"1.231501647","rc":[{"batb":[[0,1.96,10],[1,1.95,16.99],[2,1.94,98.63]],"ltp":1.99,"tv":918.48,"id":40096581}]}]}
{"op":"mcm","clk":"11832089786","pt":1723080146485,"mc":[{"id":"1.231501647","rc":[{"batb":[[0,1.95,16.99],[1,1.94,98.63],[2,1.93,800]],"ltp":1.99,"tv":918.48,"id":40096581}]}]}
{"op":"mcm","clk":"11832089877","pt":1723080148644,"mc":[{"id":"1.231501647","rc":[{"batb":[[0,1.96,10],[1,1.95,16.99],[2,1.94,98.63]],"ltp":1.99,"tv":918.48,"id":40096581}]}]}
{"op":"mcm","clk":"11832090053","pt":1723080151991,"mc":[{"id":"1.231501647","rc":[{"batb":[[0,1.95,16.99],[1,1.94,98.63],[2,1.93,800]],"ltp":1.99,"tv":918.48,"id":40096581}]}]}
{"op":"mcm","clk":"11832090181","pt":1723080154669,"mc":[{"id":"1.231501647","rc":[{"batb":[[0,1.96,10],[1,1.95,16.99],[2,1.94,98.63]],"ltp":1.99,"tv":918.48,"id":40096581}]}]}
{"op":"mcm","clk":"11832090348","pt":1723080158079,"mc":[{"id":"1.231501647","rc":[{"batb":[[0,1.95,16.99],[1,1.94,98.63],[2,1.93,800]],"ltp":1.99,"tv":918.48,"id":40096581}]}]}
{"op":"mcm","clk":"11832090494","pt":1723080160601,"mc":[{"id":"1.231501647","rc":[{"batb":[[0,1.96,10],[1,1.95,16.99],[2,1.94,98.63]],"ltp":1.99,"tv":918.48,"id":40096581}]}]}
{"op":"mcm","clk":"11832090635","pt":1723080163901,"mc":[{"id":"1.231501647","rc":[{"batb":[[0,1.95,16.99],[1,1.94,98.63],[2,1.93,800]],"ltp":1.99,"tv":918.48,"id":40096581}]}]}
{"op":"mcm","clk":"11832090731","pt":1723080166168,"mc":[{"id":"1.231501647","rc":[{"batb":[[0,1.96,10],[1,1.95,16.99],[2,1.94,98.63]],"ltp":1.99,"tv":918.48,"id":40096581}]}]}
{"op":"mcm","clk":"11832090910","pt":1723080169675,"mc":[{"id":"1.231501647","rc":[{"batb":[[0,1.95,16.99],[1,1.94,98.63],[2,1.93,800]],"ltp":1.99,"tv":918.48,"id":40096581}]}]}
{"op":"mcm","clk":"11832091109","pt":1723080173284,"mc":[{"id":"1.231501647","rc":[{"batb":[[0,1.96,10],[1,1.95,16.99],[2,1.94,98.63]],"ltp":1.99,"tv":918.48,"id":40096581}]}]}
{"op":"mcm","clk":"11832091266","pt":1723080176626,"mc":[{"id":"1.231501647","rc":[{"batl":[[0,2.04,4.32],[1,2.06,16.99]],"ltp":2.04,"tv":101.2,"id":40096589},{"batb":[[0,1.95,16.99],[1,1.94,98.63],[2,1.93,800]],"ltp":1.99,"tv":918.48,"id":40096581}]}]}
{"op":"mcm","clk":"11832091429","pt":1723080179308,"mc":[{"id":"1.231501647","rc":[{"batl":[[0,2.06,16.99],[1,2.06,0]],"ltp":2.04,"tv":101.2,"id":40096589},{"batb":[[0,1.96,10],[1,1.95,16.99],[2,1.94,98.63]],"ltp":1.99,"tv":918.48,"id":40096581}]}]}
{"op":"mcm","clk":"11832091610","pt":1723080182910,"mc":[{"id":"1.231501647","rc":[{"batb":[[0,1.95,16.99],[1,1.94,98.63],[2,1.93,800]],"ltp":1.99,"tv":918.48,"id":40096581}]}]}
{"op":"mcm","clk":"11832091718","pt":1723080185325,"mc":[{"id":"1.231501647","rc":[{"batb":[[0,1.96,10],[1,1.95,16.99],[2,1.94,98.63]],"ltp":1.99,"tv":918.48,"id":40096581}]}]}
{"op":"mcm","clk":"11832091895","pt":1723080188719,"mc":[{"id":"1.231501647","rc":[{"batb":[[0,1.95,16.99],[1,1.94,98.63],[2,1.93,800]],"ltp":1.99,"tv":918.48,"id":40096581}]}]}
{"op":"mcm","clk":"11832092098","pt":1723080192732,"mc":[{"id":"1.231501647","rc":[{"batb":[[0,1.96,10],[1,1.95,16.99],[2,1.94,98.63]],"ltp":1.99,"tv":918.48,"id":40096581}]}]}
{"op":"mcm","clk":"11832092268","pt":1723080196129,"mc":[{"id":"1.231501647","rc":[{"batb":[[0,1.95,16.99],[1,1.94,98.63],[2,1.93,800]],"ltp":1.99,"tv":918.48,"id":40096581}]}]}
{"op":"mcm","clk":"11832092382","pt":1723080198644,"mc":[{"id":"1.231501647","rc":[{"batb":[[0,1.96,10],[1,1.95,16.99],[2,1.94,98.63]],"ltp":1.99,"tv":918.48,"id":40096581}]}]}
{"op":"mcm","clk":"11832092560","pt":1723080202042,"mc":[{"id":"1.231501647","rc":[{"batb":[[0,1.95,16.99],[1,1.94,98.63],[2,1.93,800]],"ltp":1.99,"tv":918.48,"id":40096581}]}]}
{"op":"mcm","clk":"11832092682","pt":1723080204918,"mc":[{"id":"1.231501647","rc":[{"batb":[[0,1.96,10],[1,1.95,16.99],[2,1.94,98.63]],"ltp":1.99,"tv":918.48,"id":40096581}]}]}
{"op":"mcm","clk":"11832092838","pt":1723080208212,"mc":[{"id":"1.231501647","rc":[{"batb":[[0,1.95,16.99],[1,1.94,98.63],[2,1.93,800]],"ltp":1.99,"tv":918.48,"id":40096581}]}]}
{"op":"mcm","clk":"11832092969","pt":1723080211243,"mc":[{"id":"1.231501647","rc":[{"batb":[[0,1.96,10],[1,1.95,16.99],[2,1.94,98.63]],"ltp":1.99,"tv":918.48,"id":40096581}]}]}
{"op":"mcm","clk":"11832093158","pt":1723080214441,"mc":[{"id":"1.231501647","rc":[{"batb":[[0,1.95,16.99],[1,1.94,98.63],[2,1.93,800]],"ltp":1.99,"tv":918.48,"id":40096581}]}]}
{"op":"mcm","clk":"11832093335","pt":1723080218047,"mc":[{"id":"1.231501647","rc":[{"batb":[[0,1.96,10],[1,1.95,16.99],[2,1.94,98.63]],"ltp":1.99,"tv":918.48,"id":40096581}]}]}
{"op":"mcm","clk":"11832093384","pt":1723080219235,"mc":[{"id":"1.231501647","rc":[{"batl":[[0,2.04,4.32],[1,2.06,16.99]],"ltp":2.04,"tv":101.2,"id":40096589}]}]}
{"op":"mcm","clk":"11832093500","pt":1723080221347,"mc":[{"id":"1.231501647","rc":[{"batb":[[0,1.95,16.99],[1,1.94,98.63],[2,1.93,800]],"ltp":1.99,"tv":918.48,"id":40096581}]}]}
{"op":"mcm","clk":"11832093605","pt":1723080223264,"mc":[{"id":"1.231501647","rc":[{"batl":[[0,2.06,16.99],[1,2.06,0]],"ltp":2.04,"tv":101.2,"id":40096589}]}]}
{"op":"mcm","clk":"11832093656","pt":1723080224548,"mc":[{"id":"1.231501647","rc":[{"batb":[[0,1.96,10],[1,1.95,16.99],[2,1.94,98.63]],"ltp":1.99,"tv":918.48,"id":40096581}]}]}
{"op":"mcm","clk":"11832093833","pt":1723080228144,"mc":[{"id":"1.231501647","rc":[{"batb":[[0,1.95,16.99],[1,1.94,98.63],[2,1.93,800]],"ltp":1.99,"tv":918.48,"id":40096581}]}]}
{"op":"mcm","clk":"11832093957","pt":1723080230666,"mc":[{"id":"1.231501647","rc":[{"batb":[[0,1.96,10],[1,1.95,16.99],[2,1.94,98.63]],"ltp":1.99,"tv":918.48,"id":40096581}]}]}
{"op":"mcm","clk":"11832094139","pt":1723080233962,"mc":[{"id":"1.231501647","rc":[{"batb":[[0,1.95,16.99],[1,1.94,98.63],[2,1.93,800]],"ltp":1.99,"tv":918.48,"id":40096581}]}]}
{"op":"mcm","clk":"11832094272","pt":1723080236479,"mc":[{"id":"1.231501647","rc":[{"batb":[[0,1.96,10],[1,1.95,16.99],[2,1.94,98.63]],"ltp":1.99,"tv":918.48,"id":40096581}]}]}
{"op":"mcm","clk":"11832094433","pt":1723080239663,"mc":[{"id":"1.231501647","rc":[{"batb":[[0,1.95,16.99],[1,1.94,98.63],[2,1.93,800]],"ltp":1.99,"tv":918.48,"id":40096581}]}]}
{"op":"mcm","clk":"11832094581","pt":1723080242348,"mc":[{"id":"1.231501647","rc":[{"batb":[[0,1.96,10],[1,1.95,16.99],[2,1.94,98.63]],"ltp":1.99,"tv":918.48,"id":40096581}]}]}
{"op":"mcm","clk":"11832094737","pt":1723080245693,"mc":[{"id":"1.231501647","rc":[{"batb":[[0,1.95,16.99],[1,1.94,98.63],[2,1.93,800]],"ltp":1.99,"tv":918.48,"id":40096581}]}]}
{"op":"mcm","clk":"11832094862","pt":1723080248360,"mc":[{"id":"1.231501647","rc":[{"batb":[[0,1.96,10],[1,1.95,16.99],[2,1.94,98.63]],"ltp":1.99,"tv":918.48,"id":40096581}]}]}
{"op":"mcm","clk":"11832095007","pt":1723080251758,"mc":[{"id":"1.231501647","rc":[{"batb":[[0,1.95,16.99],[1,1.94,98.63],[2,1.93,800]],"ltp":1.99,"tv":918.48,"id":40096581}]}]}
{"op":"mcm","clk":"11832095126","pt":1723080254476,"mc":[{"id":"1.231501647","rc":[{"batb":[[0,1.96,10],[1,1.95,16.99],[2,1.94,98.63]],"ltp":1.99,"tv":918.48,"id":40096581}]}]}
{"op":"mcm","clk":"11832095281","pt":1723080257872,"mc":[{"id":"1.231501647","rc":[{"batb":[[0,1.95,16.99],[1,1.94,98.63],[2,1.93,800]],"ltp":1.99,"tv":918.48,"id":40096581}]}]}
{"op":"mcm","clk":"11832095465","pt":1723080261306,"mc":[{"id":"1.231501647","rc":[{"batb":[[0,1.96,10],[1,1.95,16.99],[2,1.94,98.63]],"ltp":1.99,"tv":918.48,"id":40096581}]}]}
{"op":"mcm","clk":"11832095550","pt":1723080263209,"mc":[{"id":"1.231501647","rc":[{"batl":[[0,2.04,4.32],[1,2.06,16.99]],"ltp":2.04,"tv":101.2,"id":40096589}]}]}
{"op":"mcm","clk":"11832095611","pt":1723080264594,"mc":[{"id":"1.231501647","rc":[{"batb":[[0,1.95,16.99],[1,1.94,98.63],[2,1.93,800]],"ltp":1.99,"tv":918.48,"id":40096581}]}]}
{"op":"mcm","clk":"11832095632","pt":1723080265107,"mc":[{"id":"1.231501647","rc":[{"batl":[[0,2.06,16.99],[1,2.06,0]],"ltp":2.04,"tv":101.2,"id":40096589}]}]}
{"op":"mcm","clk":"11832095745","pt":1723080267010,"mc":[{"id":"1.231501647","rc":[{"batb":[[0,1.96,10],[1,1.95,16.99],[2,1.94,98.63]],"ltp":1.99,"tv":918.48,"id":40096581}]}]}
{"op":"mcm","clk":"11832095911","pt":1723080270502,"mc":[{"id":"1.231501647","rc":[{"batb":[[0,1.95,16.99],[1,1.94,98.63],[2,1.93,800]],"ltp":1.99,"tv":918.48,"id":40096581}]}]}
{"op":"mcm","clk":"11832096059","pt":1723080273076,"mc":[{"id":"1.231501647","rc":[{"batb":[[0,1.96,10],[1,1.95,16.99],[2,1.94,98.63]],"ltp":1.99,"tv":918.48,"id":40096581}]}]}
{"op":"mcm","clk":"11832096234","pt":1723080276590,"mc":[{"id":"1.231501647","rc":[{"batb":[[0,1.95,16.99],[1,1.94,98.63],[2,1.93,800]],"ltp":1.99,"tv":918.48,"id":40096581}]}]}
{"op":"mcm","clk":"11832096361","pt":1723080279209,"mc":[{"id":"1.231501647","rc":[{"batb":[[0,1.96,10],[1,1.95,16.99],[2,1.94,98.63]],"ltp":1.99,"tv":918.48,"id":40096581}]}]}
{"op":"mcm","clk":"11832096522","pt":1723080282812,"mc":[{"id":"1.231501647","rc":[{"batb":[[0,1.95,16.99],[1,1.94,98.63],[2,1.93,800]],"ltp":1.99,"tv":918.48,"id":40096581}]}]}
{"op":"mcm","clk":"11832096633","pt":1723080285329,"mc":[{"id":"1.231501647","rc":[{"batb":[[0,1.96,10],[1,1.95,16.99],[2,1.94,98.63]],"ltp":1.99,"tv":918.48,"id":40096581}]}]}
{"op":"mcm","clk":"11832096785","pt":1723080288727,"mc":[{"id":"1.231501647","rc":[{"batb":[[0,1.95,16.99],[1,1.94,98.63],[2,1.93,800]],"ltp":1.99,"tv":918.48,"id":40096581}]}]}
{"op":"mcm","clk":"11832096948","pt":1723080291818,"mc":[{"id":"1.231501647","rc":[{"batb":[[0,1.96,10],[1,1.95,16.99],[2,1.94,98.63]],"ltp":1.99,"tv":918.48,"id":40096581}]}]}
{"op":"mcm","clk":"11832097149","pt":1723080295216,"mc":[{"id":"1.231501647","rc":[{"batb":[[0,1.95,16.99],[1,1.94,98.63],[2,1.93,800]],"ltp":1.99,"tv":918.48,"id":40096581}]}]}
{"op":"mcm","clk":"11832097297","pt":1723080297523,"mc":[{"id":"1.231501647","rc":[{"batb":[[0,1.96,10],[1,1.95,16.99],[2,1.94,98.63]],"ltp":1.99,"tv":918.48,"id":40096581}]}]}
{"op":"mcm","clk":"11832097478","pt":1723080300722,"mc":[{"id":"1.231501647","rc":[{"batb":[[0,1.95,16.99],[1,1.94,98.63],[2,1.93,800]],"ltp":1.99,"tv":918.48,"id":40096581}]}]}
{"op":"mcm","clk":"11832097643","pt":1723080303674,"mc":[{"id":"1.231501647","rc":[{"batb":[[0,1.96,10],[1,1.95,16.99],[2,1.94,98.63]],"ltp":1.99,"tv":918.48,"id":40096581}]}]}
{"op":"mcm","clk":"11832097819","pt":1723080306348,"mc":[{"id":"1.231501647","rc":[{"batl":[[0,2.04,4.32],[1,2.06,16.99]],"ltp":2.04,"tv":101.2,"id":40096589}]}]}
{"op":"mcm","clk":"11832097862","pt":1723080307019,"mc":[{"id":"1.231501647","rc":[{"batb":[[0,1.95,16.99],[1,1.94,98.63],[2,1.93,800]],"ltp":1.99,"tv":918.48,"id":40096581}]}]}
{"op":"mcm","clk":"11832097939","pt":1723080308453,"mc":[{"id":"1.231501647","rc":[{"batl":[[0,2.06,16.99],[1,2.06,0]],"ltp":2.04,"tv":101.2,"id":40096589}]}]}
{"op":"mcm","clk":"11832098012","pt":1723080309942,"mc":[{"id":"1.231501647","rc":[{"batb":[[0,1.96,10],[1,1.95,16.99],[2,1.94,98.63]],"ltp":1.99,"tv":918.48,"id":40096581}]}]}
{"op":"mcm","clk":"11832098181","pt":1723080313140,"mc":[{"id":"1.231501647","rc":[{"batb":[[0,1.95,16.99],[1,1.94,98.63],[2,1.93,800]],"ltp":1.99,"tv":918.48,"id":40096581}]}]}
{"op":"mcm","clk":"11832098327","pt":1723080315961,"mc":[{"id":"1.231501647","rc":[{"batb":[[0,1.96,10],[1,1.95,16.99],[2,1.94,98.63]],"ltp":1.99,"tv":918.48,"id":40096581}]}]}
{"op":"mcm","clk":"11832098467","pt":1723080319350,"mc":[{"id":"1.231501647","rc":[{"batb":[[0,1.95,16.99],[1,1.94,98.63],[2,1.93,800]],"ltp":1.99,"tv":918.48,"id":40096581}]}]}
{"op":"mcm","clk":"11832098718","pt":1723080324948,"mc":[{"id":"1.231501647","rc":[{"batb":[[0,1.96,10],[1,1.95,16.99],[2,1.94,98.63]],"ltp":1.99,"tv":918.48,"id":40096581}]}]}
{"op":"mcm","clk":"11832098894","pt":1723080328646,"mc":[{"id":"1.231501647","rc":[{"batb":[[0,1.95,16.99],[1,1.94,98.63],[2,1.93,800]],"ltp":1.99,"tv":918.48,"id":40096581}]}]}
{"op":"mcm","clk":"11832098999","pt":1723080331103,"mc":[{"id":"1.231501647","rc":[{"batb":[[0,1.96,10],[1,1.95,16.99],[2,1.94,98.63]],"ltp":1.99,"tv":918.48,"id":40096581}]}]}
{"op":"mcm","clk":"11832099168","pt":1723080334862,"mc":[{"id":"1.231501647","rc":[{"batb":[[0,1.95,16.99],[1,1.94,98.63],[2,1.93,800]],"ltp":1.99,"tv":918.48,"id":40096581}]}]}
{"op":"mcm","clk":"11832099293","pt":1723080337282,"mc":[{"id":"1.231501647","rc":[{"batb":[[0,1.96,10],[1,1.95,16.99],[2,1.94,98.63]],"ltp":1.99,"tv":918.48,"id":40096581}]}]}
{"op":"mcm","clk":"11832099470","pt":1723080340568,"mc":[{"id":"1.231501647","rc":[{"batb":[[0,1.95,16.99],[1,1.94,98.63],[2,1.93,800]],"ltp":1.99,"tv":918.48,"id":40096581}]}]}
{"op":"mcm","clk":"11832099618","pt":1723080343190,"mc":[{"id":"1.231501647","rc":[{"batb":[[0,1.96,10],[1,1.95,16.99],[2,1.94,98.63]],"ltp":1.99,"tv":918.48,"id":40096581}]}]}
{"op":"mcm","clk":"11832099772","pt":1723080346488,"mc":[{"id":"1.231501647","rc":[{"batb":[[0,1.95,16.99],[1,1.94,98.63],[2,1.93,800]],"ltp":1.99,"tv":918.48,"id":40096581}]}]}
{"op":"mcm","clk":"11832099879","pt":1723080349012,"mc":[{"id":"1.231501647","rc":[{"batb":[[0,1.96,10],[1,1.95,16.99],[2,1.94,98.63]],"ltp":1.99,"tv":918.48,"id":40096581}]}]}
{"op":"mcm","clk":"11832099957","pt":1723080350912,"mc":[{"id":"1.231501647","rc":[{"batl":[[0,2.04,4.32],[1,2.06,16.99]],"ltp":2.04,"tv":101.2,"id":40096589}]}]}
{"op":"mcm","clk":"11832100020","pt":1723080352611,"mc":[{"id":"1.231501647","rc":[{"batb":[[0,1.95,16.99],[1,1.94,98.63],[2,1.93,800]],"ltp":1.99,"tv":918.48,"id":40096581}]}]}
{"op":"mcm","clk":"11832100040","pt":1723080353075,"mc":[{"id":"1.231501647","rc":[{"batl":[[0,2.06,16.99],[1,2.06,0]],"ltp":2.04,"tv":101.2,"id":40096589}]}]}
{"op":"mcm","clk":"11832100179","pt":1723080356412,"mc":[{"id":"1.231501647","rc":[{"batb":[[0,1.96,10],[1,1.95,16.99],[2,1.94,98.63]],"ltp":1.99,"tv":918.48,"id":40096581}]}]}
{"op":"mcm","clk":"11832100297","pt":1723080359597,"mc":[{"id":"1.231501647","rc":[{"batb":[[0,1.95,16.99],[1,1.94,98.63],[2,1.93,800]],"ltp":1.99,"tv":918.48,"id":40096581}]}]}
{"op":"mcm","clk":"11832100419","pt":1723080362424,"mc":[{"id":"1.231501647","rc":[{"batb":[[0,1.96,10],[1,1.95,16.99],[2,1.94,98.63]],"ltp":1.99,"tv":918.48,"id":40096581}]}]}
{"op":"mcm","clk":"11832100580","pt":1723080366024,"mc":[{"id":"1.231501647","rc":[{"batb":[[0,1.95,16.99],[1,1.94,98.63],[2,1.93,800]],"ltp":1.99,"tv":918.48,"id":40096581}]}]}
{"op":"mcm","clk":"11832100749","pt":1723080369624,"mc":[{"id":"1.231501647","rc":[{"batb":[[0,1.96,10],[1,1.95,16.99],[2,1.94,98.63]],"ltp":1.99,"tv":918.48,"id":40096581}]}]}
{"op":"mcm","clk":"11832100918","pt":1723080372928,"mc":[{"id":"1.231501647","rc":[{"batb":[[0,1.95,16.99],[1,1.94,98.63],[2,1.93,800]],"ltp":1.99,"tv":918.48,"id":40096581}]}]}
{"op":"mcm","clk":"11832101047","pt":1723080375504,"mc":[{"id":"1.231501647","rc":[{"batb":[[0,1.96,10],[1,1.95,16.99],[2,1.94,98.63]],"ltp":1.99,"tv":918.48,"id":40096581}]}]}
{"op":"mcm","clk":"11832101193","pt":1723080378836,"mc":[{"id":"1.231501647","rc":[{"batb":[[0,1.95,16.99],[1,1.94,98.63],[2,1.93,800]],"ltp":1.99,"tv":918.48,"id":40096581}]}]}
{"op":"mcm","clk":"11832101333","pt":1723080381820,"mc":[{"id":"1.231501647","rc":[{"batb":[[0,1.96,10],[1,1.95,16.99],[2,1.94,98.63]],"ltp":1.99,"tv":918.48,"id":40096581}]}]}
{"op":"mcm","clk":"11832101519","pt":1723080385423,"mc":[{"id":"1.231501647","rc":[{"batb":[[0,1.95,16.99],[1,1.94,98.63],[2,1.93,800]],"ltp":1.99,"tv":918.48,"id":40096581}]}]}
{"op":"mcm","clk":"11832101632","pt":1723080387941,"mc":[{"id":"1.231501647","rc":[{"batb":[[0,1.96,10],[1,1.95,16.99],[2,1.94,98.63]],"ltp":1.99,"tv":918.48,"id":40096581}]}]}
{"op":"mcm","clk":"11832101803","pt":1723080391331,"mc":[{"id":"1.231501647","rc":[{"batb":[[0,1.95,16.99],[1,1.94,98.63],[2,1.93,800]],"ltp":1.99,"tv":918.48,"id":40096581}]}]}
{"op":"mcm","clk":"11832101964","pt":1723080394526,"mc":[{"id":"1.231501647","rc":[{"batl":[[0,2.04,4.32],[1,2.06,16.99]],"ltp":2.04,"tv":101.2,"id":40096589},{"batb":[[0,1.96,10],[1,1.95,16.99],[2,1.94,98.63]],"ltp":1.99,"tv":918.48,"id":40096581}]}]}
{"op":"mcm","clk":"11832102103","pt":1723080397350,"mc":[{"id":"1.231501647","rc":[{"batb":[[0,1.95,16.99],[1,1.94,98.63],[2,1.93,800]],"ltp":1.99,"tv":918.48,"id":40096581}]}]}
{"op":"mcm","clk":"11832102194","pt":1723080399150,"mc":[{"id":"1.231501647","rc":[{"batl":[[0,2.06,16.99],[1,2.06,0]],"ltp":2.04,"tv":101.2,"id":40096589}]}]}
{"op":"mcm","clk":"11832102266","pt":1723080400435,"mc":[{"id":"1.231501647","rc":[{"batb":[[0,1.96,10],[1,1.95,16.99],[2,1.94,98.63]],"ltp":1.99,"tv":918.48,"id":40096581}]}]}
{"op":"mcm","clk":"11832102440","pt":1723080403835,"mc":[{"id":"1.231501647","rc":[{"batb":[[0,1.95,16.99],[1,1.94,98.63],[2,1.93,800]],"ltp":1.99,"tv":918.48,"id":40096581}]}]}
{"op":"mcm","clk":"11832102583","pt":1723080406359,"mc":[{"id":"1.231501647","rc":[{"batb":[[0,1.96,10],[1,1.95,16.99],[2,1.94,98.63]],"ltp":1.99,"tv":918.48,"id":40096581}]}]}
{"op":"mcm","clk":"11832102749","pt":1723080409745,"mc":[{"id":"1.231501647","rc":[{"batb":[[0,1.95,16.99],[1,1.94,98.63],[2,1.93,800]],"ltp":1.99,"tv":918.48,"id":40096581}]}]}
{"op":"mcm","clk":"11832102924","pt":1723080413384,"mc":[{"id":"1.231501647","rc":[{"batb":[[0,1.96,10],[1,1.95,16.99],[2,1.94,98.63]],"ltp":1.99,"tv":918.48,"id":40096581}]}]}
{"op":"mcm","clk":"11832103087","pt":1723080416676,"mc":[{"id":"1.231501647","rc":[{"batb":[[0,1.95,16.99],[1,1.94,98.63],[2,1.93,800]],"ltp":1.99,"tv":918.48,"id":40096581}]}]}
{"op":"mcm","clk":"11832103225","pt":1723080419556,"mc":[{"id":"1.231501647","rc":[{"batb":[[0,1.96,10],[1,1.95,16.99],[2,1.94,98.63]],"ltp":1.99,"tv":918.48,"id":40096581}]}]}
{"op":"mcm","clk":"11832103375","pt":1723080422796,"mc":[{"id":"1.231501647","rc":[{"batb":[[0,1.95,16.99],[1,1.94,98.63],[2,1.93,800]],"ltp":1.99,"tv":918.48,"id":40096581}]}]}
{"op":"mcm","clk":"11832103491","pt":1723080425475,"mc":[{"id":"1.231501647","rc":[{"batb":[[0,1.96,10],[1,1.95,16.99],[2,1.94,98.63]],"ltp":1.99,"tv":918.48,"id":40096581}]}]}
{"op":"mcm","clk":"11832103655","pt":1723080428883,"mc":[{"id":"1.231501647","rc":[{"batb":[[0,1.95,16.99],[1,1.94,98.63],[2,1.93,800]],"ltp":1.99,"tv":918.48,"id":40096581}]}]}
{"op":"mcm","clk":"11832103796","pt":1723080431559,"mc":[{"id":"1.231501647","rc":[{"batb":[[0,1.96,10],[1,1.95,16.99],[2,1.94,98.63]],"ltp":1.99,"tv":918.48,"id":40096581}]}]}
{"op":"mcm","clk":"11832103968","pt":1723080434802,"mc":[{"id":"1.231501647","rc":[{"batb":[[0,1.95,16.99],[1,1.94,98.63],[2,1.93,800]],"ltp":1.99,"tv":918.48,"id":40096581}]}]}
{"op":"mcm","clk":"11832104152","pt":1723080438661,"mc":[{"id":"1.231501647","rc":[{"batl":[[0,2.04,4.32],[1,2.06,16.99]],"ltp":2.04,"tv":101.2,"id":40096589},{"batb":[[0,1.96,10],[1,1.95,16.99],[2,1.94,98.63]],"ltp":1.99,"tv":918.48,"id":40096581}]}]}
{"op":"mcm","clk":"11832104335","pt":1723080442508,"mc":[{"id":"1.231501647","rc":[{"batb":[[0,1.95,16.99],[1,1.94,98.63],[2,1.93,800]],"ltp":1.99,"tv":918.48,"id":40096581}]}]}
{"op":"mcm","clk":"11832104377","pt":1723080443287,"mc":[{"id":"1.231501647","rc":[{"batl":[[0,2.06,16.99],[1,2.06,0]],"ltp":2.04,"tv":101.2,"id":40096589}]}]}
{"op":"mcm","clk":"11832104455","pt":1723080444768,"mc":[{"id":"1.231501647","rc":[{"batb":[[0,1.96,10],[1,1.95,16.99],[2,1.94,98.63]],"ltp":1.99,"tv":918.48,"id":40096581}]}]}
{"op":"mcm","clk":"11832104637","pt":1723080448673,"mc":[{"id":"1.231501647","rc":[{"batb":[[0,1.95,16.99],[1,1.94,98.63],[2,1.93,800]],"ltp":1.99,"tv":918.48,"id":40096581}]}]}
{"op":"mcm","clk":"11832104804","pt":1723080451913,"mc":[{"id":"1.231501647","rc":[{"batb":[[0,1.96,10],[1,1.95,16.99],[2,1.94,98.63]],"ltp":1.99,"tv":918.48,"id":40096581}]}]}
{"op":"mcm","clk":"11832104971","pt":1723080455404,"mc":[{"id":"1.231501647","rc":[{"batb":[[0,1.95,16.99],[1,1.94,98.63],[2,1.93,800]],"ltp":1.99,"tv":918.48,"id":40096581}]}]}
{"op":"mcm","clk":"11832105087","pt":1723080457617,"mc":[{"id":"1.231501647","rc":[{"batb":[[0,1.96,10],[1,1.95,16.99],[2,1.94,98.63]],"ltp":1.99,"tv":918.48,"id":40096581}]}]}
{"op":"mcm","clk":"11832105197","pt":1723080460809,"mc":[{"id":"1.231501647","rc":[{"batb":[[0,1.95,16.99],[1,1.94,98.63],[2,1.93,800]],"ltp":1.99,"tv":918.48,"id":40096581}]}]}
{"op":"mcm","clk":"11832105324","pt":1723080463623,"mc":[{"id":"1.231501647","rc":[{"batb":[[0,1.96,10],[1,1.95,16.99],[2,1.94,98.63]],"ltp":1.99,"tv":918.48,"id":40096581}]}]}
{"op":"mcm","clk":"11832105485","pt":1723080467128,"mc":[{"id":"1.231501647","rc":[{"batb":[[0,1.95,16.99],[1,1.94,98.63],[2,1.93,800]],"ltp":1.99,"tv":918.48,"id":40096581}]}]}
{"op":"mcm","clk":"11832105641","pt":1723080470232,"mc":[{"id":"1.231501647","rc":[{"batb":[[0,1.96,10],[1,1.95,16.99],[2,1.94,98.63]],"ltp":1.99,"tv":918.48,"id":40096581}]}]}
{"op":"mcm","clk":"11832105799","pt":1723080473523,"mc":[{"id":"1.231501647","rc":[{"batb":[[0,1.95,16.99],[1,1.94,98.63],[2,1.93,800]],"ltp":1.99,"tv":918.48,"id":40096581}]}]}
{"op":"mcm","clk":"11832105908","pt":1723080475933,"mc":[{"id":"1.231501647","rc":[{"batb":[[0,1.96,10],[1,1.95,16.99],[2,1.94,98.63]],"ltp":1.99,"tv":918.48,"id":40096581}]}]}
{"op":"mcm","clk":"11832106075","pt":1723080479333,"mc":[{"id":"1.231501647","rc":[{"batb":[[0,1.95,16.99],[1,1.94,98.63],[2,1.93,800]],"ltp":1.99,"tv":918.48,"id":40096581}]}]}
{"op":"mcm","clk":"11832106192","pt":1723080482115,"mc":[{"id":"1.231501647","rc":[{"batb":[[0,1.96,10],[1,1.95,16.99],[2,1.94,98.63]],"ltp":1.99,"tv":918.48,"id":40096581}]}]}
{"op":"mcm","clk":"11832106305","pt":1723080484121,"mc":[{"id":"1.231501647","rc":[{"batl":[[0,2.04,4.32],[1,2.06,16.99]],"ltp":2.04,"tv":101.2,"id":40096589}]}]}
{"op":"mcm","clk":"11832106383","pt":1723080485826,"mc":[{"id":"1.231501647","rc":[{"batb":[[0,1.95,16.99],[1,1.94,98.63],[2,1.93,800]],"ltp":1.99,"tv":918.48,"id":40096581}]}]}
{"op":"mcm","clk":"11832106426","pt":1723080486545,"mc":[{"id":"1.231501647","rc":[{"batl":[[0,2.06,16.99],[1,2.06,0]],"ltp":2.04,"tv":101.2,"id":40096589}]}]}
{"op":"mcm","clk":"11832106545","pt":1723080489045,"mc":[{"id":"1.231501647","rc":[{"batb":[[0,1.96,10],[1,1.95,16.99],[2,1.94,98.63]],"ltp":1.99,"tv":918.48,"id":40096581}]}]}
{"op":"mcm","clk":"11832106740","pt":1723080492922,"mc":[{"id":"1.231501647","rc":[{"batb":[[0,1.95,16.99],[1,1.94,98.63],[2,1.93,800]],"ltp":1.99,"tv":918.48,"id":40096581}]}]}
{"op":"mcm","clk":"11832106846","pt":1723080495544,"mc":[{"id":"1.231501647","rc":[{"batb":[[0,1.96,10],[1,1.95,16.99],[2,1.94,98.63]],"ltp":1.99,"tv":918.48,"id":40096581}]}]}
{"op":"mcm","clk":"11832107007","pt":1723080498928,"mc":[{"id":"1.231501647","rc":[{"batb":[[0,1.95,16.99],[1,1.94,98.63],[2,1.93,800]],"ltp":1.99,"tv":918.48,"id":40096581}]}]}
{"op":"mcm","clk":"11832107117","pt":1723080501339,"mc":[{"id":"1.231501647","rc":[{"batb":[[0,1.96,10],[1,1.95,16.99],[2,1.94,98.63]],"ltp":1.99,"tv":918.48,"id":40096581}]}]}
{"op":"mcm","clk":"11832107312","pt":1723080504933,"mc":[{"id":"1.231501647","rc":[{"batb":[[0,1.95,16.99],[1,1.94,98.63],[2,1.93,800]],"ltp":1.99,"tv":918.48,"id":40096581}]}]}
{"op":"mcm","clk":"11832107437","pt":1723080507580,"mc":[{"id":"1.231501647","rc":[{"batb":[[0,1.96,10],[1,1.95,16.99],[2,1.94,98.63]],"ltp":1.99,"tv":918.48,"id":40096581}]}]}
{"op":"mcm","clk":"11832107589","pt":1723080511171,"mc":[{"id":"1.231501647","rc":[{"batb":[[0,1.95,16.99],[1,1.94,98.63],[2,1.93,800]],"ltp":1.99,"tv":918.48,"id":40096581}]}]}
{"op":"mcm","clk":"11832107707","pt":1723080513585,"mc":[{"id":"1.231501647","rc":[{"batb":[[0,1.96,10],[1,1.95,16.99],[2,1.94,98.63]],"ltp":1.99,"tv":918.48,"id":40096581}]}]}
{"op":"mcm","clk":"11832107869","pt":1723080517260,"mc":[{"id":"1.231501647","rc":[{"batb":[[0,1.95,16.99],[1,1.94,98.63],[2,1.93,800]],"ltp":1.99,"tv":918.48,"id":40096581}]}]}
{"op":"mcm","clk":"11832107982","pt":1723080520077,"mc":[{"id":"1.231501647","rc":[{"batb":[[0,1.96,10],[1,1.95,16.99],[2,1.94,98.63]],"ltp":1.99,"tv":918.48,"id":40096581}]}]}
{"op":"mcm","clk":"11832108128","pt":1723080523577,"mc":[{"id":"1.231501647","rc":[{"batb":[[0,1.95,16.99],[1,1.94,98.63],[2,1.93,800]],"ltp":1.99,"tv":918.48,"id":40096581}]}]}
{"op":"mcm","clk":"11832108244","pt":1723080526770,"mc":[{"id":"1.231501647","rc":[{"batb":[[0,1.96,10],[1,1.95,16.99],[2,1.94,98.63]],"ltp":1.99,"tv":918.48,"id":40096581}]}]}
{"op":"mcm","clk":"11832108288","pt":1723080527888,"mc":[{"id":"1.231501647","rc":[{"batl":[[0,2.04,4.32],[1,2.06,16.99]],"ltp":2.04,"tv":101.2,"id":40096589}]}]}
{"op":"mcm","clk":"11832108396","pt":1723080530049,"mc":[{"id":"1.231501647","rc":[{"batb":[[0,1.95,16.99],[1,1.94,98.63],[2,1.93,800]],"ltp":1.99,"tv":918.48,"id":40096581}]}]}
{"op":"mcm","clk":"11832108507","pt":1723080532468,"mc":[{"id":"1.231501647","rc":[{"batl":[[0,2.06,16.99],[1,2.06,0]],"ltp":2.04,"tv":101.2,"id":40096589}]}]}
{"op":"mcm","clk":"11832108531","pt":1723080532890,"mc":[{"id":"1.231501647","rc":[{"batb":[[0,1.96,10],[1,1.95,16.99],[2,1.94,98.63]],"ltp":1.99,"tv":918.48,"id":40096581}]}]}
{"op":"mcm","clk":"11832108748","pt":1723080536757,"mc":[{"id":"1.231501647","rc":[{"batb":[[0,1.95,16.99],[1,1.94,98.63],[2,1.93,800]],"ltp":1.99,"tv":918.48,"id":40096581}]}]}
{"op":"mcm","clk":"11832108892","pt":1723080539886,"mc":[{"id":"1.231501647","rc":[{"batb":[[0,1.96,10],[1,1.95,16.99],[2,1.94,98.63]],"ltp":1.99,"tv":918.48,"id":40096581}]}]}
{"op":"mcm","clk":"11832109079","pt":1723080543401,"mc":[{"id":"1.231501647","rc":[{"batb":[[0,1.95,16.99],[1,1.94,98.63],[2,1.93,800]],"ltp":1.99,"tv":918.48,"id":40096581}]}]}
{"op":"mcm","clk":"11832109239","pt":1723080546088,"mc":[{"id":"1.231501647","rc":[{"batb":[[0,1.96,10],[1,1.95,16.99],[2,1.94,98.63]],"ltp":1.99,"tv":918.48,"id":40096581}]}]}
{"op":"mcm","clk":"11832109441","pt":1723080549494,"mc":[{"id":"1.231501647","rc":[{"batb":[[0,1.95,16.99],[1,1.94,98.63],[2,1.93,800]],"ltp":1.99,"tv":918.48,"id":40096581}]}]}
{"op":"mcm","clk":"11832109550","pt":1723080551719,"mc":[{"id":"1.231501647","rc":[{"batb":[[0,1.96,10],[1,1.95,16.99],[2,1.94,98.63]],"ltp":1.99,"tv":918.48,"id":40096581}]}]}
{"op":"mcm","clk":"11832109741","pt":1723080555027,"mc":[{"id":"1.231501647","rc":[{"batb":[[0,1.95,16.99],[1,1.94,98.63],[2,1.93,800]],"ltp":1.99,"tv":918.48,"id":40096581}]}]}
{"op":"mcm","clk":"11832109856","pt":1723080557702,"mc":[{"id":"1.231501647","rc":[{"batb":[[0,1.96,10],[1,1.95,16.99],[2,1.94,98.63]],"ltp":1.99,"tv":918.48,"id":40096581}]}]}
{"op":"mcm","clk":"11832110004","pt":1723080561303,"mc":[{"id":"1.231501647","rc":[{"batb":[[0,1.95,16.99],[1,1.94,98.63],[2,1.93,800]],"ltp":1.99,"tv":918.48,"id":40096581}]}]}
{"op":"mcm","clk":"11832110139","pt":1723080564045,"mc":[{"id":"1.231501647","rc":[{"batb":[[0,1.96,10],[1,1.95,16.99],[2,1.94,98.63]],"ltp":1.99,"tv":918.48,"id":40096581}]}]}
{"op":"mcm","clk":"11832110299","pt":1723080567608,"mc":[{"id":"1.231501647","rc":[{"batb":[[0,1.95,16.99],[1,1.94,98.63],[2,1.93,800]],"ltp":1.99,"tv":918.48,"id":40096581}]}]}
{"op":"mcm","clk":"11832110416","pt":1723080570115,"mc":[{"id":"1.231501647","rc":[{"batb":[[0,1.96,10],[1,1.95,16.99],[2,1.94,98.63]],"ltp":1.99,"tv":918.48,"id":40096581}]}]}
{"op":"mcm","clk":"11832110476","pt":1723080571501,"mc":[{"id":"1.231501647","rc":[{"batl":[[0,2.04,4.32],[1,2.06,16.99]],"ltp":2.04,"tv":101.2,"id":40096589}]}]}
{"op":"mcm","clk":"11832110562","pt":1723080573810,"mc":[{"id":"1.231501647","rc":[{"batb":[[0,1.95,16.99],[1,1.94,98.63],[2,1.93,800]],"ltp":1.99,"tv":918.48,"id":40096581}]}]}
{"op":"mcm","clk":"11832110665","pt":1723080576530,"mc":[{"id":"1.231501647","rc":[{"batl":[[0,2.06,16.99],[1,2.06,0]],"ltp":2.04,"tv":101.2,"id":40096589},{"batb":[[0,1.96,10],[1,1.95,16.99],[2,1.94,98.63]],"ltp":1.99,"tv":918.48,"id":40096581}]}]}
{"op":"mcm","clk":"11832110805","pt":1723080579818,"mc":[{"id":"1.231501647","rc":[{"batb":[[0,1.95,16.99],[1,1.94,98.63],[2,1.93,800]],"ltp":1.99,"tv":918.48,"id":40096581}]}]}
{"op":"mcm","clk":"11832110950","pt":1723080583605,"mc":[{"id":"1.231501647","rc":[{"batb":[[0,1.96,10],[1,1.95,16.99],[2,1.94,98.63]],"ltp":1.99,"tv":918.48,"id":40096581}]}]}
{"op":"mcm","clk":"11832111076","pt":1723080587139,"mc":[{"id":"1.231501647","rc":[{"batb":[[0,1.95,16.99],[1,1.94,98.63],[2,1.93,800]],"ltp":1.99,"tv":918.48,"id":40096581}]}]}
{"op":"mcm","clk":"11832111163","pt":1723080589451,"mc":[{"id":"1.231501647","rc":[{"batb":[[0,1.96,10],[1,1.95,16.99],[2,1.94,98.63]],"ltp":1.99,"tv":918.48,"id":40096581}]}]}
{"op":"mcm","clk":"11832111287","pt":1723080592932,"mc":[{"id":"1.231501647","rc":[{"batb":[[0,1.95,16.99],[1,1.94,98.63],[2,1.93,800]],"ltp":1.99,"tv":918.48,"id":40096581}]}]}
{"op":"mcm","clk":"11832111430","pt":1723080596737,"mc":[{"id":"1.231501647","rc":[{"batb":[[0,1.96,10],[1,1.95,16.99],[2,1.94,98.63]],"ltp":1.99,"tv":918.48,"id":40096581}]}]}
{"op":"mcm","clk":"11832111548","pt":1723080600069,"mc":[{"id":"1.231501647","rc":[{"batb":[[0,1.95,16.99],[1,1.94,98.63],[2,1.93,800]],"ltp":1.99,"tv":918.48,"id":40096581}]}]}
{"op":"mcm","clk":"11832111667","pt":1723080602852,"mc":[{"id":"1.231501647","rc":[{"batb":[[0,1.96,10],[1,1.95,16.99],[2,1.94,98.63]],"ltp":1.99,"tv":918.48,"id":40096581}]}]}
{"op":"mcm","clk":"11832111889","pt":1723080606653,"mc":[{"id":"1.231501647","rc":[{"batb":[[0,1.95,16.99],[1,1.94,98.63],[2,1.93,800]],"ltp":1.99,"tv":918.48,"id":40096581}]}]}
{"op":"mcm","clk":"11832112011","pt":1723080608957,"mc":[{"id":"1.231501647","rc":[{"batb":[[0,1.96,10],[1,1.95,16.99],[2,1.94,98.63]],"ltp":1.99,"tv":918.48,"id":40096581}]}]}
{"op":"mcm","clk":"11832112149","pt":1723080612345,"mc":[{"id":"1.231501647","rc":[{"batb":[[0,1.95,16.99],[1,1.94,98.63],[2,1.93,800]],"ltp":1.99,"tv":918.48,"id":40096581}]}]}
{"op":"mcm","clk":"11832112234","pt":1723080614765,"mc":[{"id":"1.231501647","rc":[{"batb":[[0,1.96,10],[1,1.95,16.99],[2,1.94,98.63]],"ltp":1.99,"tv":918.48,"id":40096581}]}]}
{"op":"mcm","clk":"11832112343","pt":1723080616971,"mc":[{"id":"1.231501647","rc":[{"batl":[[0,2.04,4.32],[1,2.06,16.99]],"ltp":2.04,"tv":101.2,"id":40096589}]}]}
{"op":"mcm","clk":"11832112379","pt":1723080618150,"mc":[{"id":"1.231501647","rc":[{"batb":[[0,1.95,16.99],[1,1.94,98.63],[2,1.93,800]],"ltp":1.99,"tv":918.48,"id":40096581}]}]}
{"op":"mcm","clk":"11832112424","pt":1723080619176,"mc":[{"id":"1.231501647","rc":[{"batl":[[0,2.06,16.99],[1,2.06,0]],"ltp":2.04,"tv":101.2,"id":40096589}]}]}
{"op":"mcm","clk":"11832112496","pt":1723080620792,"mc":[{"id":"1.231501647","rc":[{"batb":[[0,1.96,10],[1,1.95,16.99],[2,1.94,98.63]],"ltp":1.99,"tv":918.48,"id":40096581}]}]}
{"op":"mcm","clk":"11832112632","pt":1723080624493,"mc":[{"id":"1.231501647","rc":[{"batb":[[0,1.95,16.99],[1,1.94,98.63],[2,1.93,800]],"ltp":1.99,"tv":918.48,"id":40096581}]}]}
{"op":"mcm","clk":"11832112738","pt":1723080627056,"mc":[{"id":"1.231501647","rc":[{"batb":[[0,1.96,10],[1,1.95,16.99],[2,1.94,98.63]],"ltp":1.99,"tv":918.48,"id":40096581}]}]}
{"op":"mcm","clk":"11832112871","pt":1723080630946,"mc":[{"id":"1.231501647","rc":[{"batb":[[0,1.95,16.99],[1,1.94,98.63],[2,1.93,800]],"ltp":1.99,"tv":918.48,"id":40096581}]}]}
{"op":"mcm","clk":"11832112997","pt":1723080634181,"mc":[{"id":"1.231501647","rc":[{"batb":[[0,1.96,10],[1,1.95,16.99],[2,1.94,98.63]],"ltp":1.99,"tv":918.48,"id":40096581}]}]}
{"op":"mcm","clk":"11832113167","pt":1723080638485,"mc":[{"id":"1.231501647","rc":[{"batb":[[0,1.95,16.99],[1,1.94,98.63],[2,1.93,800]],"ltp":1.99,"tv":918.48,"id":40096581}]}]}
{"op":"mcm","clk":"11832113300","pt":1723080641059,"mc":[{"id":"1.231501647","rc":[{"batb":[[0,1.96,10],[1,1.95,16.99],[2,1.94,98.63]],"ltp":1.99,"tv":918.48,"id":40096581}]}]}
{"op":"mcm","clk":"11832113439","pt":1723080644689,"mc":[{"id":"1.231501647","rc":[{"batb":[[0,1.95,16.99],[1,1.94,98.63],[2,1.93,800]],"ltp":1.99,"tv":918.48,"id":40096581}]}]}
{"op":"mcm","clk":"11832113568","pt":1723080647006,"mc":[{"id":"1.231501647","rc":[{"batb":[[0,1.96,10],[1,1.95,16.99],[2,1.94,98.63]],"ltp":1.99,"tv":918.48,"id":40096581}]}]}
{"op":"mcm","clk":"11832113725","pt":1723080650500,"mc":[{"id":"1.231501647","rc":[{"batb":[[0,1.95,16.99],[1,1.94,98.63],[2,1.93,800]],"ltp":1.99,"tv":918.48,"id":40096581}]}]}
{"op":"mcm","clk":"11832113847","pt":1723080653528,"mc":[{"id":"1.231501647","rc":[{"batb":[[0,1.96,10],[1,1.95,16.99],[2,1.94,98.63]],"ltp":1.99,"tv":918.48,"id":40096581}]}]}
{"op":"mcm","clk":"11832114031","pt":1723080657127,"mc":[{"id":"1.231501647","rc":[{"batb":[[0,1.95,16.99],[1,1.94,98.63],[2,1.93,800]],"ltp":1.99,"tv":918.48,"id":40096581}]}]}
{"op":"mcm","clk":"11832114171","pt":1723080660310,"mc":[{"id":"1.231501647","rc":[{"batb":[[0,1.96,10],[1,1.95,16.99],[2,1.94,98.63]],"ltp":1.99,"tv":918.48,"id":40096581}]}]}
{"op":"mcm","clk":"11832114254","pt":1723080662214,"mc":[{"id":"1.231501647","rc":[{"batl":[[0,2.04,4.32],[1,2.06,16.99]],"ltp":2.04,"tv":101.2,"id":40096589}]}]}
{"op":"mcm","clk":"11832114334","pt":1723080663906,"mc":[{"id":"1.231501647","rc":[{"batb":[[0,1.95,16.99],[1,1.94,98.63],[2,1.93,800]],"ltp":1.99,"tv":918.48,"id":40096581}]}]}
{"op":"mcm","clk":"11832114401","pt":1723080665139,"mc":[{"id":"1.231501647","rc":[{"batl":[[0,2.06,16.99],[1,2.06,0]],"ltp":2.04,"tv":101.2,"id":40096589}]}]}
{"op":"mcm","clk":"11832114509","pt":1723080667137,"mc":[{"id":"1.231501647","rc":[{"batb":[[0,1.96,10],[1,1.95,16.99],[2,1.94,98.63]],"ltp":1.99,"tv":918.48,"id":40096581}]}]}
{"op":"mcm","clk":"11832114679","pt":1723080670731,"mc":[{"id":"1.231501647","rc":[{"batb":[[0,1.95,16.99],[1,1.94,98.63],[2,1.93,800]],"ltp":1.99,"tv":918.48,"id":40096581}]}]}
{"op":"mcm","clk":"11832114794","pt":1723080673358,"mc":[{"id":"1.231501647","rc":[{"batb":[[0,1.96,10],[1,1.95,16.99],[2,1.94,98.63]],"ltp":1.99,"tv":918.48,"id":40096581}]}]}
{"op":"mcm","clk":"11832114936","pt":1723080676846,"mc":[{"id":"1.231501647","rc":[{"batb":[[0,1.95,16.99],[1,1.94,98.63],[2,1.93,800]],"ltp":1.99,"tv":918.48,"id":40096581}]}]}
{"op":"mcm","clk":"11832115059","pt":1723080679463,"mc":[{"id":"1.231501647","rc":[{"batb":[[0,1.96,10],[1,1.95,16.99],[2,1.94,98.63]],"ltp":1.99,"tv":918.48,"id":40096581}]}]}
{"op":"mcm","clk":"11832115177","pt":1723080682745,"mc":[{"id":"1.231501647","rc":[{"batb":[[0,1.95,16.99],[1,1.94,98.63],[2,1.93,800]],"ltp":1.99,"tv":918.48,"id":40096581}]}]}
{"op":"mcm","clk":"11832115322","pt":1723080686446,"mc":[{"id":"1.231501647","rc":[{"batb":[[0,1.96,10],[1,1.95,16.99],[2,1.94,98.63]],"ltp":1.99,"tv":918.48,"id":40096581}]}]}
{"op":"mcm","clk":"11832115446","pt":1723080689836,"mc":[{"id":"1.231501647","rc":[{"batb":[[0,1.95,16.99],[1,1.94,98.63],[2,1.93,800]],"ltp":1.99,"tv":918.48,"id":40096581}]}]}
{"op":"mcm","clk":"11832115558","pt":1723080692761,"mc":[{"id":"1.231501647","rc":[{"batb":[[0,1.96,10],[1,1.95,16.99],[2,1.94,98.63]],"ltp":1.99,"tv":918.48,"id":40096581}]}]}
{"op":"mcm","clk":"11832115717","pt":1723080696146,"mc":[{"id":"1.231501647","rc":[{"batb":[[0,1.95,16.99],[1,1.94,98.63],[2,1.93,800]],"ltp":1.99,"tv":918.48,"id":40096581}]}]}
{"op":"mcm","clk":"11832115828","pt":1723080698661,"mc":[{"id":"1.231501647","rc":[{"batb":[[0,1.96,10],[1,1.95,16.99],[2,1.94,98.63]],"ltp":1.99,"tv":918.48,"id":40096581}]}]}
{"op":"mcm","clk":"11832116025","pt":1723080702148,"mc":[{"id":"1.231501647","rc":[{"batb":[[0,1.95,16.99],[1,1.94,98.63],[2,1.93,800]],"ltp":1.99,"tv":918.48,"id":40096581}]}]}
{"op":"mcm","clk":"11832116140","pt":1723080704558,"mc":[{"id":"1.231501647","rc":[{"batb":[[0,1.96,10],[1,1.95,16.99],[2,1.94,98.63]],"ltp":1.99,"tv":918.48,"id":40096581}]}]}
{"op":"mcm","clk":"11832116246","pt":1723080706470,"mc":[{"id":"1.231501647","rc":[{"batl":[[0,2.04,4.32],[1,2.06,16.99]],"ltp":2.04,"tv":101.2,"id":40096589}]}]}
{"op":"mcm","clk":"11832116338","pt":1723080708673,"mc":[{"id":"1.231501647","rc":[{"batl":[[0,2.06,16.99],[1,2.06,0]],"ltp":2.04,"tv":101.2,"id":40096589},{"batb":[[0,1.95,16.99],[1,1.94,98.63],[2,1.93,800]],"ltp":1.99,"tv":918.48,"id":40096581}]}]}
{"op":"mcm","clk":"11832116555","pt":1723080711957,"mc":[{"id":"1.231501647","rc":[{"batb":[[0,1.96,10],[1,1.95,16.99],[2,1.94,98.63]],"ltp":1.99,"tv":918.48,"id":40096581}]}]}
{"op":"mcm","clk":"11832116724","pt":1723080715313,"mc":[{"id":"1.231501647","rc":[{"batb":[[0,1.95,16.99],[1,1.94,98.63],[2,1.93,800]],"ltp":1.99,"tv":918.48,"id":40096581}]}]}
{"op":"mcm","clk":"11832116808","pt":1723080717565,"mc":[{"id":"1.231501647","rc":[{"batb":[[0,1.96,10],[1,1.95,16.99],[2,1.94,98.63]],"ltp":1.99,"tv":918.48,"id":40096581}]}]}
{"op":"mcm","clk":"11832116999","pt":1723080721105,"mc":[{"id":"1.231501647","rc":[{"batb":[[0,1.95,16.99],[1,1.94,98.63],[2,1.93,800]],"ltp":1.99,"tv":918.48,"id":40096581}]}]}
{"op":"mcm","clk":"11832117260","pt":1723080723473,"mc":[{"id":"1.231501647","rc":[{"batb":[[0,1.96,10],[1,1.95,16.99],[2,1.94,98.63]],"ltp":1.99,"tv":918.48,"id":40096581}]}]}
{"op":"mcm","clk":"11832117462","pt":1723080726806,"mc":[{"id":"1.231501647","rc":[{"batb":[[0,1.95,16.99],[1,1.94,98.63],[2,1.93,800]],"ltp":1.99,"tv":918.48,"id":40096581}]}]}
{"op":"mcm","clk":"11832117673","pt":1723080729678,"mc":[{"id":"1.231501647","rc":[{"batb":[[0,1.96,10],[1,1.95,16.99],[2,1.94,98.63]],"ltp":1.99,"tv":918.48,"id":40096581}]}]}
{"op":"mcm","clk":"11832117903","pt":1723080733424,"mc":[{"id":"1.231501647","rc":[{"batb":[[0,1.95,16.99],[1,1.94,98.63],[2,1.93,800]],"ltp":1.99,"tv":918.48,"id":40096581}]}]}
{"op":"mcm","clk":"11832117989","pt":1723080735892,"mc":[{"id":"1.231501647","rc":[{"batb":[[0,1.96,10],[1,1.95,16.99],[2,1.94,98.63]],"ltp":1.99,"tv":918.48,"id":40096581}]}]}
{"op":"mcm","clk":"11832118112","pt":1723080739214,"mc":[{"id":"1.231501647","rc":[{"batb":[[0,1.95,16.99],[1,1.94,98.63],[2,1.93,800]],"ltp":1.99,"tv":918.48,"id":40096581}]}]}
{"op":"mcm","clk":"11832118253","pt":1723080742604,"mc":[{"id":"1.231501647","rc":[{"batb":[[0,1.96,10],[1,1.95,16.99],[2,1.94,98.63]],"ltp":1.99,"tv":918.48,"id":40096581}]}]}
{"op":"mcm","clk":"11832118396","pt":1723080746200,"mc":[{"id":"1.231501647","rc":[{"batb":[[0,1.95,16.99],[1,1.94,98.63],[2,1.93,800]],"ltp":1.99,"tv":918.48,"id":40096581}]}]}
{"op":"mcm","clk":"11832118472","pt":1723080748624,"mc":[{"id":"1.231501647","rc":[{"batb":[[0,1.96,10],[1,1.95,16.99],[2,1.94,98.63]],"ltp":1.99,"tv":918.48,"id":40096581}]}]}
{"op":"mcm","clk":"11832118499","pt":1723080749237,"mc":[{"id":"1.231501647","rc":[{"batl":[[0,2.04,4.32],[1,2.06,16.99]],"ltp":2.04,"tv":101.2,"id":40096589}]}]}
{"op":"mcm","clk":"11832118587","pt":1723080752008,"mc":[{"id":"1.231501647","rc":[{"batb":[[0,1.95,16.99],[1,1.94,98.63],[2,1.93,800]],"ltp":1.99,"tv":918.48,"id":40096581}]}]}
{"op":"mcm","clk":"11832118637","pt":1723080753605,"mc":[{"id":"1.231501647","rc":[{"batl":[[0,2.06,16.99],[1,2.06,0]],"ltp":2.04,"tv":101.2,"id":40096589}]}]}
{"op":"mcm","clk":"11832118720","pt":1723080755708,"mc":[{"id":"1.231501647","rc":[{"batb":[[0,1.96,10],[1,1.95,16.99],[2,1.94,98.63]],"ltp":1.99,"tv":918.48,"id":40096581}]}]}
{"op":"mcm","clk":"11832118882","pt":1723080759163,"mc":[{"id":"1.231501647","rc":[{"batb":[[0,1.95,16.99],[1,1.94,98.63],[2,1.93,800]],"ltp":1.99,"tv":918.48,"id":40096581}]}]}
{"op":"mcm","clk":"11832119051","pt":1723080761849,"mc":[{"id":"1.231501647","rc":[{"batb":[[0,1.96,10],[1,1.95,16.99],[2,1.94,98.63]],"ltp":1.99,"tv":918.48,"id":40096581}]}]}
{"op":"mcm","clk":"11832119224","pt":1723080765423,"mc":[{"id":"1.231501647","rc":[{"batb":[[0,1.95,16.99],[1,1.94,98.63],[2,1.93,800]],"ltp":1.99,"tv":918.48,"id":40096581}]}]}
{"op":"mcm","clk":"11832119425","pt":1723080768144,"mc":[{"id":"1.231501647","rc":[{"batb":[[0,1.96,10],[1,1.95,16.99],[2,1.94,98.63]],"ltp":1.99,"tv":918.48,"id":40096581}]}]}
{"op":"mcm","clk":"11832119577","pt":1723080771628,"mc":[{"id":"1.231501647","rc":[{"batb":[[0,1.95,16.99],[1,1.94,98.63],[2,1.93,800]],"ltp":1.99,"tv":918.48,"id":40096581}]}]}
{"op":"mcm","clk":"11832119691","pt":1723080773930,"mc":[{"id":"1.231501647","rc":[{"batb":[[0,1.96,10],[1,1.95,16.99],[2,1.94,98.63]],"ltp":1.99,"tv":918.48,"id":40096581}]}]}
{"op":"mcm","clk":"11832119903","pt":1723080777472,"mc":[{"id":"1.231501647","rc":[{"batb":[[0,1.95,16.99],[1,1.94,98.63],[2,1.93,800]],"ltp":1.99,"tv":918.48,"id":40096581}]}]}
{"op":"mcm","clk":"11832119990","pt":1723080780039,"mc":[{"id":"1.231501647","rc":[{"batb":[[0,1.96,10],[1,1.95,16.99],[2,1.94,98.63]],"ltp":1.99,"tv":918.48,"id":40096581}]}]}
{"op":"mcm","clk":"11832120225","pt":1723080783477,"mc":[{"id":"1.231501647","rc":[{"batb":[[0,1.95,16.99],[1,1.94,98.63],[2,1.93,800]],"ltp":1.99,"tv":918.48,"id":40096581}]}]}
{"op":"mcm","clk":"11832120396","pt":1723080785839,"mc":[{"id":"1.231501647","rc":[{"batb":[[0,1.96,10],[1,1.95,16.99],[2,1.94,98.63]],"ltp":1.99,"tv":918.48,"id":40096581}]}]}
{"op":"mcm","clk":"11832120638","pt":1723080789349,"mc":[{"id":"1.231501647","rc":[{"batb":[[0,1.95,16.99],[1,1.94,98.63],[2,1.93,800]],"ltp":1.99,"tv":918.48,"id":40096581}]}]}
{"op":"mcm","clk":"11832120763","pt":1723080792070,"mc":[{"id":"1.231501647","rc":[{"batb":[[0,1.96,10],[1,1.95,16.99],[2,1.94,98.63]],"ltp":1.99,"tv":918.48,"id":40096581}]}]}
{"op":"mcm","clk":"11832120842","pt":1723080793767,"mc":[{"id":"1.231501647","rc":[{"batl":[[0,2.04,4.32],[1,2.06,16.99]],"ltp":2.04,"tv":101.2,"id":40096589}]}]}
{"op":"mcm","clk":"11832120912","pt":1723080795561,"mc":[{"id":"1.231501647","rc":[{"batb":[[0,1.95,16.99],[1,1.94,98.63],[2,1.93,800]],"ltp":1.99,"tv":918.48,"id":40096581}]}]}
{"op":"mcm","clk":"11832121016","pt":1723080797561,"mc":[{"id":"1.231501647","rc":[{"batl":[[0,2.06,16.99],[1,2.06,0]],"ltp":2.04,"tv":101.2,"id":40096589}]}]}
{"op":"mcm","clk":"11832121041","pt":1723080797968,"mc":[{"id":"1.231501647","rc":[{"batb":[[0,1.96,10],[1,1.95,16.99],[2,1.94,98.63]],"ltp":1.99,"tv":918.48,"id":40096581}]}]}
{"op":"mcm","clk":"11832121214","pt":1723080801358,"mc":[{"id":"1.231501647","rc":[{"batb":[[0,1.95,16.99],[1,1.94,98.63],[2,1.93,800]],"ltp":1.99,"tv":918.48,"id":40096581}]}]}
{"op":"mcm","clk":"11832121327","pt":1723080803972,"mc":[{"id":"1.231501647","rc":[{"batb":[[0,1.96,10],[1,1.95,16.99],[2,1.94,98.63]],"ltp":1.99,"tv":918.48,"id":40096581}]}]}
{"op":"mcm","clk":"11832121500","pt":1723080807362,"mc":[{"id":"1.231501647","rc":[{"batb":[[0,1.95,16.99],[1,1.94,98.63],[2,1.93,800]],"ltp":1.99,"tv":918.48,"id":40096581}]}]}
{"op":"mcm","clk":"11832121568","pt":1723080808596,"mc":[{"id":"1.231501647","rc":[{"trd":[[2,82.88]],"batb":[[0,1.99,102.5],[1,1.98,45.31],[2,1.92,800]],"ltp":2.0,"tv":113.93,"id":40096589},{"trd":[[2,68.34]],"batb":[[0,2,29.54],[1,1.95,16.99],[2,1.94,98.63]],"batl":[[0,2.02,2],[1,2.06,25],[2,2.06,0]],"ltp":2.0,"tv":946.67,"id":40096581}],"tv":1060.61}]}
{"op":"mcm","clk":"11832121617","pt":1723080809674,"mc":[{"id":"1.231501647","rc":[{"batl":[[0,2,5.03]],"ltp":2.0,"tv":113.93,"id":40096589},{"batb":[[1,1.94,98.63],[2,1.93,800]],"ltp":2.0,"tv":946.67,"id":40096581}]}]}
{"op":"mcm","clk":"11832121662","pt":1723080810804,"mc":[{"id":"1.231501647","rc":[{"batl":[[0,2,12.73]],"ltp":2.0,"tv":113.93,"id":40096589},{"batb":[[0,2,7.73]],"ltp":2.0,"tv":946.67,"id":40096581}]}]}
{"op":"mcm","clk":"11832121753","pt":1723080812699,"mc":[{"id":"1.231501647","rc":[{"batb":[[1,1.92,800],[2,1.91,28]],"ltp":2.0,"tv":113.93,"id":40096589}]}]}
{"op":"mcm","clk":"11832194220","pt":1723082290185,"mc":[{"id":"1.231501647","rc":[{"trd":[[2,133.78]],"batb":[[0,2,169.82],[1,1.99,102.5],[2,1.92,800]],"ltp":2.0,"tv":164.83,"id":40096589},{"trd":[[2,76.07]],"batb":[[0,1.94,98.63],[1,1.93,800],[2,1.91,28]],"ltp":2.0,"tv":954.4,"id":40096581}],"tv":1119.24}]}
{"op":"mcm","clk":"11832194274","pt":1723082291569,"mc":[{"id":"1.231501647","rc":[{"batb":[[0,1.95,7.41],[1,1.94,98.63],[2,1.93,800]],"ltp":2.0,"tv":954.4,"id":40096581}]}]}
{"op":"mcm","clk":"11832194301","pt":1723082292186,"mc":[{"id":"1.231501647","rc":[{"batl":[[0,2.06,16.97]],"ltp":2.0,"tv":164.83,"id":40096589},{"batb":[[0,1.95,12.62]],"ltp":2.0,"tv":954.4,"id":40096581}]}]}
{"op":"mcm","clk":"11832194382","pt":1723082294186,"mc":[{"id":"1.231501647","rc":[{"batb":[[2,1.98,45.31]],"ltp":2.0,"tv":164.83,"id":40096589}]}]}
{"op":"mcm","clk":"11832195011","pt":1723082307886,"mc":[{"id":"1.231501647","rc":[{"batb":[[1,1.99,310.49]],"ltp":2.0,"tv":164.83,"id":40096589}]}]}
{"op":"mcm","clk":"11832195155","pt":1723082311579,"mc":[{"id":"1.231501647","rc":[{"batl":[[0,1.99,3.88],[1,2.02,2],[2,2.06,25]],"ltp":2.0,"tv":954.4,"id":40096581}]}]}
{"op":"mcm","clk":"11832195558","pt":1723082321697,"mc":[{"id":"1.231501647","rc":[{"batl":[[0,1.99,16.93]],"ltp":2.0,"tv":954.4,"id":40096581}]}]}
{"op":"mcm","clk":"11832195578","pt":1723082322107,"mc":[{"id":"1.231501647","rc":[{"batb":[[0,1.99,102.5],[1,1.98,45.31],[2,1.92,800]],"ltp":2.0,"tv":164.83,"id":40096589}]}]}
{"op":"mcm","clk":"11832195663","pt":1723082323697,"mc":[{"id":"1.231501647","rc":[{"batl":[[0,1.99,3.88]],"ltp":2.0,"tv":954.4,"id":40096581}]}]}
{"op":"mcm","clk":"11832196788","pt":1723082351066,"mc":[{"id":"1.231501647","rc":[{"batl":[[0,2.02,2],[1,2.06,25],[2,2.06,0]],"ltp":2.0,"tv":954.4,"id":40096581}]}]}
{"op":"mcm","clk":"11832197100","pt":1723082357927,"mc":[{"id":"1.231501647","rc":[{"batl":[[0,2,7.73],[1,2.02,2],[2,2.06,25]],"ltp":2.0,"tv":954.4,"id":40096581}]}]}
{"op":"mcm","clk":"11832197809","pt":1723082375044,"mc":[{"id":"1.231501647","rc":[{"batb":[[0,1.95,289.54]],"ltp":2.0,"tv":954.4,"id":40096581}]}]}
{"op":"mcm","clk":"11832198462","pt":1723082389299,"mc":[{"id":"1.231501647","rc":[{"batl":[[0,1.97,3.88],[1,2,7.73],[2,2.02,2]],"ltp":2.0,"tv":954.4,"id":40096581}]}]}
{"op":"mcm","clk":"11832199640","pt":1723082411190,"mc":[{"id":"1.231501647","rc":[{"trd":[[2,133.74],[2.12,7.18]],"batl":[[0,2.06,16.96]],"ltp":2.0,"tv":164.78,"id":40096589},{"trd":[[1.95,26.96],[2,76.06]],"batb":[[0,1.96,10],[1,1.95,289.53],[2,1.94,98.63]],"batl":[[0,2,7.73],[1,2.02,2],[2,2.06,25]],"ltp":2.0,"tv":954.39,"id":40096581}],"tv":1119.18}]}
{"op":"mcm","clk":"11832199823","pt":1723082414699,"mc":[{"id":"1.231501647","rc":[{"batb":[[0,1.95,289.53],[1,1.94,98.63],[2,1.93,800]],"ltp":2.0,"tv":954.39,"id":40096581}]}]}
{"op":"mcm","clk":"11832199994","pt":1723082417742,"mc":[{"id":"1.231501647","rc":[{"batb":[[0,1.96,10],[1,1.95,289.53],[2,1.94,98.63]],"ltp":2.0,"tv":954.39,"id":40096581}]}]}
{"op":"mcm","clk":"11832200020","pt":1723082418409,"mc":[{"id":"1.231501647","rc":[{"trd":[[1.96,609.22]],"batb":[[0,1.96,6.12]],"ltp":1.96,"tv":962.15,"id":40096581}],"tv":1126.94}]}
{"op":"mcm","clk":"11832200165","pt":1723082420940,"mc":[{"id":"1.231501647","rc":[{"batb":[[0,1.95,289.53],[1,1.94,98.63],[2,1.93,800]],"ltp":1.96,"tv":962.15,"id":40096581}]}]}
{"op":"mcm","clk":"11832200309","pt":1723082423516,"mc":[{"id":"1.231501647","rc":[{"batb":[[0,1.96,10],[1,1.95,289.53],[2,1.94,98.63]],"ltp":1.96,"tv":962.15,"id":40096581}]}]}
{"op":"mcm","clk":"11832200432","pt":1723082427060,"mc":[{"id":"1.231501647","rc":[{"batb":[[0,1.95,289.53],[1,1.94,98.63],[2,1.93,800]],"ltp":1.96,"tv":962.15,"id":40096581}]}]}
{"op":"mcm","clk":"11832200513","pt":1723082429367,"mc":[{"id":"1.231501647","rc":[{"batb":[[0,1.96,10],[1,1.95,289.53],[2,1.94,98.63]],"ltp":1.96,"tv":962.15,"id":40096581}]}]}
{"op":"mcm","clk":"11832200644","pt":1723082432564,"mc":[{"id":"1.231501647","rc":[{"batb":[[0,1.95,289.53],[1,1.94,98.63],[2,1.93,800]],"ltp":1.96,"tv":962.15,"id":40096581}]}]}
{"op":"mcm","clk":"11832200775","pt":1723082436062,"mc":[{"id":"1.231501647","rc":[{"batb":[[0,1.96,10],[1,1.95,289.53],[2,1.94,98.63]],"ltp":1.96,"tv":962.15,"id":40096581}]}]}
{"op":"mcm","clk":"11832200869","pt":1723082439451,"mc":[{"id":"1.231501647","rc":[{"batb":[[0,1.95,289.53],[1,1.94,98.63],[2,1.93,800]],"ltp":1.96,"tv":962.15,"id":40096581}]}]}
{"op":"mcm","clk":"11832201010","pt":1723082442847,"mc":[{"id":"1.231501647","rc":[{"batb":[[0,1.96,10],[1,1.95,289.53],[2,1.94,98.63]],"ltp":1.96,"tv":962.15,"id":40096581}]}]}
{"op":"mcm","clk":"11832201147","pt":1723082446386,"mc":[{"id":"1.231501647","rc":[{"batb":[[0,1.95,289.53],[1,1.94,98.63],[2,1.93,800]],"ltp":1.96,"tv":962.15,"id":40096581}]}]}
{"op":"mcm","clk":"11832201249","pt":1723082448746,"mc":[{"id":"1.231501647","rc":[{"batb":[[0,1.96,10],[1,1.95,289.53],[2,1.94,98.63]],"ltp":1.96,"tv":962.15,"id":40096581}]}]}
{"op":"mcm","clk":"11832201386","pt":1723082452281,"mc":[{"id":"1.231501647","rc":[{"batb":[[0,1.95,289.53],[1,1.94,98.63],[2,1.93,800]],"ltp":1.96,"tv":962.15,"id":40096581}]}]}
{"op":"mcm","clk":"11832201485","pt":1723082455564,"mc":[{"id":"1.231501647","rc":[{"batb":[[0,1.96,10],[1,1.95,289.53],[2,1.94,98.63]],"ltp":1.96,"tv":962.15,"id":40096581}]}]}
{"op":"mcm","clk":"11832201617","pt":1723082458870,"mc":[{"id":"1.231501647","rc":[{"batb":[[0,1.95,289.53],[1,1.94,98.63],[2,1.93,800]],"ltp":1.96,"tv":962.15,"id":40096581}]}]}
{"op":"mcm","clk":"11832201709","pt":1723082461597,"mc":[{"id":"1.231501647","rc":[{"batb":[[0,1.96,10],[1,1.95,289.53],[2,1.94,98.63]],"ltp":1.96,"tv":962.15,"id":40096581}]}]}
{"op":"mcm","clk":"11832201857","pt":1723082465077,"mc":[{"id":"1.231501647","rc":[{"batb":[[0,1.95,289.53],[1,1.94,98.63],[2,1.93,800]],"ltp":1.96,"tv":962.15,"id":40096581}]}]}
{"op":"mcm","clk":"11832201932","pt":1723082467589,"mc":[{"id":"1.231501647","rc":[{"batb":[[0,1.96,10],[1,1.95,289.53],[2,1.94,98.63]],"ltp":1.96,"tv":962.15,"id":40096581}]}]}
{"op":"mcm","clk":"11832202037","pt":1723082470979,"mc":[{"id":"1.231501647","rc":[{"batb":[[0,1.95,289.53],[1,1.94,98.63],[2,1.93,800]],"ltp":1.96,"tv":962.15,"id":40096581}]}]}
{"op":"mcm","clk":"11832202163","pt":1723082474389,"mc":[{"id":"1.231501647","rc":[{"batb":[[0,1.96,10],[1,1.95,289.53],[2,1.94,98.63]],"ltp":1.96,"tv":962.15,"id":40096581}]}]}
{"op":"mcm","clk":"11832202285","pt":1723082477882,"mc":[{"id":"1.231501647","rc":[{"batb":[[0,1.95,289.53],[1,1.94,98.63],[2,1.93,800]],"ltp":1.96,"tv":962.15,"id":40096581}]}]}
{"op":"mcm","clk":"11832202369","pt":1723082480198,"mc":[{"id":"1.231501647","rc":[{"batb":[[0,1.96,10],[1,1.95,289.53],[2,1.94,98.63]],"ltp":1.96,"tv":962.15,"id":40096581}]}]}
{"op":"mcm","clk":"11832202481","pt":1723082483705,"mc":[{"id":"1.231501647","rc":[{"batb":[[0,1.95,289.53],[1,1.94,98.63],[2,1.93,800]],"ltp":1.96,"tv":962.15,"id":40096581}]}]}
{"op":"mcm","clk":"11832202567","pt":1723082485919,"mc":[{"id":"1.231501647","rc":[{"batb":[[0,1.96,10],[1,1.95,289.53],[2,1.94,98.63]],"ltp":1.96,"tv":962.15,"id":40096581}]}]}
{"op":"mcm","clk":"11832202690","pt":1723082489325,"mc":[{"id":"1.231501647","rc":[{"batb":[[0,1.95,289.53],[1,1.94,98.63],[2,1.93,800]],"ltp":1.96,"tv":962.15,"id":40096581}]}]}
{"op":"mcm","clk":"11832202781","pt":1723082492047,"mc":[{"id":"1.231501647","rc":[{"batb":[[0,1.96,10],[1,1.95,289.53],[2,1.94,98.63]],"ltp":1.96,"tv":962.15,"id":40096581}]}]}
{"op":"mcm","clk":"11832202899","pt":1723082495540,"mc":[{"id":"1.231501647","rc":[{"batb":[[0,1.95,289.53],[1,1.94,98.63],[2,1.93,800]],"ltp":1.96,"tv":962.15,"id":40096581}]}]}
{"op":"mcm","clk":"11832203004","pt":1723082498938,"mc":[{"id":"1.231501647","rc":[{"batb":[[0,1.96,10],[1,1.95,289.53],[2,1.94,98.63]],"ltp":1.96,"tv":962.15,"id":40096581}]}]}
{"op":"mcm","clk":"11832203142","pt":1723082502242,"mc":[{"id":"1.231501647","rc":[{"batb":[[0,1.95,289.53],[1,1.94,98.63],[2,1.93,800]],"ltp":1.96,"tv":962.15,"id":40096581}]}]}
{"op":"mcm","clk":"11832203234","pt":1723082505223,"mc":[{"id":"1.231501647","rc":[{"batb":[[0,1.96,10],[1,1.95,289.53],[2,1.94,98.63]],"ltp":1.96,"tv":962.15,"id":40096581}]}]}
{"op":"mcm","clk":"11832203442","pt":1723082509457,"mc":[{"id":"1.231501647","rc":[{"batb":[[0,1.95,289.53],[1,1.94,98.63],[2,1.93,800]],"ltp":1.96,"tv":962.15,"id":40096581}]}]}
{"op":"mcm","clk":"11832203548","pt":1723082511838,"mc":[{"id":"1.231501647","rc":[{"batb":[[0,1.96,10],[1,1.95,289.53],[2,1.94,98.63]],"ltp":1.96,"tv":962.15,"id":40096581}]}]}
{"op":"mcm","clk":"11832203694","pt":1723082515364,"mc":[{"id":"1.231501647","rc":[{"batb":[[0,1.95,289.53],[1,1.94,98.63],[2,1.93,800]],"ltp":1.96,"tv":962.15,"id":40096581}]}]}
{"op":"mcm","clk":"11832203856","pt":1723082518657,"mc":[{"id":"1.231501647","rc":[{"batb":[[0,1.96,10],[1,1.95,289.53],[2,1.94,98.63]],"ltp":1.96,"tv":962.15,"id":40096581}]}]}
{"op":"mcm","clk":"11832204060","pt":1723082522168,"mc":[{"id":"1.231501647","rc":[{"batb":[[0,1.95,289.53],[1,1.94,98.63],[2,1.93,800]],"ltp":1.96,"tv":962.15,"id":40096581}]}]}
{"op":"mcm","clk":"11832204242","pt":1723082525947,"mc":[{"id":"1.231501647","rc":[{"batb":[[0,1.96,10],[1,1.95,289.53],[2,1.94,98.63]],"ltp":1.96,"tv":962.15,"id":40096581}]}]}
{"op":"mcm","clk":"11832204411","pt":1723082529347,"mc":[{"id":"1.231501647","rc":[{"batb":[[0,1.95,289.53],[1,1.94,98.63],[2,1.93,800]],"ltp":1.96,"tv":962.15,"id":40096581}]}]}
{"op":"mcm","clk":"11832204558","pt":1723082532384,"mc":[{"id":"1.231501647","rc":[{"batb":[[0,1.96,10],[1,1.95,289.53],[2,1.94,98.63]],"ltp":1.96,"tv":962.15,"id":40096581}]}]}
{"op":"mcm","clk":"11832204706","pt":1723082536093,"mc":[{"id":"1.231501647","rc":[{"batb":[[0,1.95,289.53],[1,1.94,98.63],[2,1.93,800]],"ltp":1.96,"tv":962.15,"id":40096581}]}]}
{"op":"mcm","clk":"11832204838","pt":1723082539202,"mc":[{"id":"1.231501647","rc":[{"batb":[[0,1.96,10],[1,1.95,289.53],[2,1.94,98.63]],"ltp":1.96,"tv":962.15,"id":40096581}]}]}
{"op":"mcm","clk":"11832205002","pt":1723082542575,"mc":[{"id":"1.231501647","rc":[{"batb":[[0,1.95,289.53],[1,1.94,98.63],[2,1.93,800]],"ltp":1.96,"tv":962.15,"id":40096581}]}]}
{"op":"mcm","clk":"11832205208","pt":1723082546675,"mc":[{"id":"1.231501647","rc":[{"batb":[[0,1.96,10],[1,1.95,289.53],[2,1.94,98.63]],"ltp":1.96,"tv":962.15,"id":40096581}]}]}
{"op":"mcm","clk":"11832205353","pt":1723082550487,"mc":[{"id":"1.231501647","rc":[{"batb":[[0,1.95,289.53],[1,1.94,98.63],[2,1.93,800]],"ltp":1.96,"tv":962.15,"id":40096581}]}]}
{"op":"mcm","clk":"11832205447","pt":1723082552694,"mc":[{"id":"1.231501647","rc":[{"batb":[[0,1.96,10],[1,1.95,289.53],[2,1.94,98.63]],"ltp":1.96,"tv":962.15,"id":40096581}]}]}
{"op":"mcm","clk":"11832205588","pt":1723082556186,"mc":[{"id":"1.231501647","rc":[{"batb":[[0,1.95,289.53],[1,1.94,98.63],[2,1.93,800]],"ltp":1.96,"tv":962.15,"id":40096581}]}]}
{"op":"mcm","clk":"11832205820","pt":1723082561494,"mc":[{"id":"1.231501647","rc":[{"batb":[[0,1.96,10],[1,1.95,289.53],[2,1.94,98.63]],"ltp":1.96,"tv":962.15,"id":40096581}]}]}
{"op":"mcm","clk":"11832205979","pt":1723082565340,"mc":[{"id":"1.231501647","rc":[{"batb":[[0,1.95,289.53],[1,1.94,98.63],[2,1.93,800]],"ltp":1.96,"tv":962.15,"id":40096581}]}]}
{"op":"mcm","clk":"11832206027","pt":1723082566422,"mc":[{"id":"1.231501647","rc":[{"batl":[[0,2,13.16]],"ltp":1.96,"tv":962.15,"id":40096581}]}]}
{"op":"mcm","clk":"11832206079","pt":1723082567615,"mc":[{"id":"1.231501647","rc":[{"batb":[[0,1.96,10],[1,1.95,289.53],[2,1.94,98.63]],"ltp":1.96,"tv":962.15,"id":40096581}]}]}
{"op":"mcm","clk":"11832206216","pt":1723082571103,"mc":[{"id":"1.231501647","rc":[{"batb":[[0,1.95,289.53],[1,1.94,98.63],[2,1.93,800]],"ltp":1.96,"tv":962.15,"id":40096581}]}]}
{"op":"mcm","clk":"11832206388","pt":1723082575025,"mc":[{"id":"1.231501647","rc":[{"batb":[[0,1.96,10],[1,1.95,289.53],[2,1.94,98.63]],"ltp":1.96,"tv":962.15,"id":40096581}]}]}
{"op":"mcm","clk":"11832206538","pt":1723082578624,"mc":[{"id":"1.231501647","rc":[{"batb":[[0,1.95,289.53],[1,1.94,98.63],[2,1.93,800]],"ltp":1.96,"tv":962.15,"id":40096581}]}]}
{"op":"mcm","clk":"11832206709","pt":1723082582125,"mc":[{"id":"1.231501647","rc":[{"batb":[[0,1.96,10],[1,1.95,289.53],[2,1.94,98.63]],"ltp":1.96,"tv":962.15,"id":40096581}]}]}
{"op":"mcm","clk":"11832206890","pt":1723082585734,"mc":[{"id":"1.231501647","rc":[{"batb":[[0,1.95,289.53],[1,1.94,98.63],[2,1.93,800]],"ltp":1.96,"tv":962.15,"id":40096581}]}]}
{"op":"mcm","clk":"11832207001","pt":1723082588037,"mc":[{"id":"1.231501647","rc":[{"batb":[[0,1.96,10],[1,1.95,289.53],[2,1.94,98.63]],"ltp":1.96,"tv":962.15,"id":40096581}]}]}
{"op":"mcm","clk":"11832207200","pt":1723082591572,"mc":[{"id":"1.231501647","rc":[{"batb":[[0,1.95,289.53],[1,1.94,98.63],[2,1.93,800]],"ltp":1.96,"tv":962.15,"id":40096581}]}]}
{"op":"mcm","clk":"11832207313","pt":1723082593853,"mc":[{"id":"1.231501647","rc":[{"batb":[[0,1.96,10],[1,1.95,289.53],[2,1.94,98.63]],"ltp":1.96,"tv":962.15,"id":40096581}]}]}
{"op":"mcm","clk":"11832207384","pt":1723082595144,"mc":[{"id":"1.231501647","rc":[{"batb":[[0,2,7.7],[1,1.99,102.5],[2,1.98,45.31]],"ltp":2.0,"tv":164.78,"id":40096589}]}]}
{"op":"mcm","clk":"11832207513","pt":1723082597674,"mc":[{"id":"1.231501647","rc":[{"batb":[[0,1.95,289.53],[1,1.94,98.63],[2,1.93,800]],"ltp":1.96,"tv":962.15,"id":40096581}]}]}
{"op":"mcm","clk":"11832207672","pt":1723082600625,"mc":[{"id":"1.231501647","rc":[{"batb":[[0,1.96,10],[1,1.95,289.53],[2,1.94,98.63]],"ltp":1.96,"tv":962.15,"id":40096581}]}]}
{"op":"mcm","clk":"11832207818","pt":1723082603920,"mc":[{"id":"1.231501647","rc":[{"batb":[[0,1.95,289.53],[1,1.94,98.63],[2,1.93,800]],"ltp":1.96,"tv":962.15,"id":40096581}]}]}
{"op":"mcm","clk":"11832207955","pt":1723082606729,"mc":[{"id":"1.231501647","rc":[{"batb":[[0,1.96,10],[1,1.95,289.53],[2,1.94,98.63]],"ltp":1.96,"tv":962.15,"id":40096581}]}]}
{"op":"mcm","clk":"11832208139","pt":1723082610542,"mc":[{"id":"1.231501647","rc":[{"batb":[[0,1.95,289.53],[1,1.94,98.63],[2,1.93,800]],"ltp":1.96,"tv":962.15,"id":40096581}]}]}
{"op":"mcm","clk":"11832208262","pt":1723082613440,"mc":[{"id":"1.231501647","rc":[{"batb":[[0,1.96,10],[1,1.95,289.53],[2,1.94,98.63]],"ltp":1.96,"tv":962.15,"id":40096581}]}]}
{"op":"mcm","clk":"11832208396","pt":1723082616642,"mc":[{"id":"1.231501647","rc":[{"batb":[[0,1.95,289.53],[1,1.94,98.63],[2,1.93,800]],"ltp":1.96,"tv":962.15,"id":40096581}]}]}
{"op":"mcm","clk":"11832208589","pt":1723082620522,"mc":[{"id":"1.231501647","rc":[{"batb":[[0,1.96,10],[1,1.95,289.53],[2,1.94,98.63]],"ltp":1.96,"tv":962.15,"id":40096581}]}]}
{"op":"mcm","clk":"11832208765","pt":1723082624144,"mc":[{"id":"1.231501647","rc":[{"batb":[[0,1.95,289.53],[1,1.94,98.63],[2,1.93,800]],"ltp":1.96,"tv":962.15,"id":40096581}]}]}
{"op":"mcm","clk":"11832208889","pt":1723082626772,"mc":[{"id":"1.231501647","rc":[{"batb":[[0,1.96,10],[1,1.95,289.53],[2,1.94,98.63]],"ltp":1.96,"tv":962.15,"id":40096581}]}]}
{"op":"mcm","clk":"11832209042","pt":1723082630274,"mc":[{"id":"1.231501647","rc":[{"batb":[[0,1.95,289.53],[1,1.94,98.63],[2,1.93,800]],"ltp":1.96,"tv":962.15,"id":40096581}]}]}
{"op":"mcm","clk":"11832209176","pt":1723082632966,"mc":[{"id":"1.231501647","rc":[{"batb":[[0,1.96,10],[1,1.95,289.53],[2,1.94,98.63]],"ltp":1.96,"tv":962.15,"id":40096581}]}]}
{"op":"mcm","clk":"11832209367","pt":1723082636389,"mc":[{"id":"1.231501647","rc":[{"batb":[[0,1.95,289.53],[1,1.94,98.63],[2,1.93,800]],"ltp":1.96,"tv":962.15,"id":40096581}]}]}
{"op":"mcm","clk":"11832209537","pt":1723082638863,"mc":[{"id":"1.231501647","rc":[{"batb":[[0,1.96,10],[1,1.95,289.53],[2,1.94,98.63]],"ltp":1.96,"tv":962.15,"id":40096581}]}]}
{"op":"mcm","clk":"11832209706","pt":1723082642269,"mc":[{"id":"1.231501647","rc":[{"batb":[[0,1.95,289.53],[1,1.94,98.63],[2,1.93,800]],"ltp":1.96,"tv":962.15,"id":40096581}]}]}
{"op":"mcm","clk":"11832209849","pt":1723082644909,"mc":[{"id":"1.231501647","rc":[{"batb":[[0,1.96,10],[1,1.95,289.53],[2,1.94,98.63]],"ltp":1.96,"tv":962.15,"id":40096581}]}]}
{"op":"mcm","clk":"11832210030","pt":1723082648370,"mc":[{"id":"1.231501647","rc":[{"batl":[[0,2.04,17.23],[1,2.06,16.96]],"ltp":2.0,"tv":164.78,"id":40096589},{"batb":[[0,1.95,289.53],[1,1.94,98.63],[2,1.93,800]],"ltp":1.96,"tv":962.15,"id":40096581}]}]}
{"op":"mcm","clk":"11832210105","pt":1723082649868,"mc":[{"id":"1.231501647","rc":[{"batl":[[1,2.06,0]],"ltp":2.0,"tv":164.78,"id":40096589},{"batb":[[0,1.95,284.33]],"ltp":1.96,"tv":962.15,"id":40096581}]}]}
{"op":"mcm","clk":"11832210179","pt":1723082651162,"mc":[{"id":"1.231501647","rc":[{"batb":[[0,1.96,10],[1,1.95,284.33],[2,1.94,98.63]],"ltp":1.96,"tv":962.15,"id":40096581}]}]}
{"op":"mcm","clk":"11832210405","pt":1723082655492,"mc":[{"id":"1.231501647","rc":[{"batb":[[0,1.95,284.33],[1,1.94,98.63],[2,1.93,800]],"ltp":1.96,"tv":962.15,"id":40096581}]}]}
{"op":"mcm","clk":"11832210559","pt":1723082658793,"mc":[{"id":"1.231501647","rc":[{"batb":[[0,1.96,10],[1,1.95,284.33],[2,1.94,98.63]],"ltp":1.96,"tv":962.15,"id":40096581}]}]}
{"op":"mcm","clk":"11832210737","pt":1723082662177,"mc":[{"id":"1.231501647","rc":[{"batb":[[0,1.95,284.33],[1,1.94,98.63],[2,1.93,800]],"ltp":1.96,"tv":962.15,"id":40096581}]}]}
{"op":"mcm","clk":"11832210903","pt":1723082665316,"mc":[{"id":"1.231501647","rc":[{"batb":[[0,1.96,10],[1,1.95,284.33],[2,1.94,98.63]],"ltp":1.96,"tv":962.15,"id":40096581}]}]}
{"op":"mcm","clk":"11832211094","pt":1723082668723,"mc":[{"id":"1.231501647","rc":[{"batb":[[0,1.95,284.33],[1,1.94,98.63],[2,1.93,800]],"ltp":1.96,"tv":962.15,"id":40096581}]}]}
{"op":"mcm","clk":"11832211255","pt":1723082671910,"mc":[{"id":"1.231501647","rc":[{"batb":[[0,1.96,10],[1,1.95,284.33],[2,1.94,98.63]],"ltp":1.96,"tv":962.15,"id":40096581}]}]}
{"op":"mcm","clk":"11832211430","pt":1723082675313,"mc":[{"id":"1.231501647","rc":[{"batb":[[0,1.95,284.33],[1,1.94,98.63],[2,1.93,800]],"ltp":1.96,"tv":962.15,"id":40096581}]}]}
{"op":"mcm","clk":"11832211548","pt":1723082677733,"mc":[{"id":"1.231501647","rc":[{"batb":[[0,1.96,10],[1,1.95,284.33],[2,1.94,98.63]],"ltp":1.96,"tv":962.15,"id":40096581}]}]}
{"op":"mcm","clk":"11832211741","pt":1723082681244,"mc":[{"id":"1.231501647","rc":[{"batb":[[0,1.95,284.33],[1,1.94,98.63],[2,1.93,800]],"ltp":1.96,"tv":962.15,"id":40096581}]}]}
{"op":"mcm","clk":"11832211872","pt":1723082683718,"mc":[{"id":"1.231501647","rc":[{"batb":[[0,1.96,10],[1,1.95,284.33],[2,1.94,98.63]],"ltp":1.96,"tv":962.15,"id":40096581}]}]}
{"op":"mcm","clk":"11832212066","pt":1723082687242,"mc":[{"id":"1.231501647","rc":[{"batb":[[0,1.95,284.33],[1,1.94,98.63],[2,1.93,800]],"ltp":1.96,"tv":962.15,"id":40096581}]}]}
{"op":"mcm","clk":"11832212170","pt":1723082689610,"mc":[{"id":"1.231501647","rc":[{"batb":[[0,1.96,10],[1,1.95,284.33],[2,1.94,98.63]],"ltp":1.96,"tv":962.15,"id":40096581}]}]}
{"op":"mcm","clk":"11832212337","pt":1723082692944,"mc":[{"id":"1.231501647","rc":[{"batb":[[0,1.95,284.33],[1,1.94,98.63],[2,1.93,800]],"ltp":1.96,"tv":962.15,"id":40096581}]}]}
{"op":"mcm","clk":"11832212530","pt":1723082696358,"mc":[{"id":"1.231501647","rc":[{"batb":[[0,1.96,10],[1,1.95,284.33],[2,1.94,98.63]],"ltp":1.96,"tv":962.15,"id":40096581}]}]}
{"op":"mcm","clk":"11832212741","pt":1723082699766,"mc":[{"id":"1.231501647","rc":[{"batb":[[0,1.95,284.33],[1,1.94,98.63],[2,1.93,800]],"ltp":1.96,"tv":962.15,"id":40096581}]}]}
{"op":"mcm","clk":"11832212905","pt":1723082702938,"mc":[{"id":"1.231501647","rc":[{"batb":[[0,1.96,10],[1,1.95,284.33],[2,1.94,98.63]],"ltp":1.96,"tv":962.15,"id":40096581}]}]}
{"op":"mcm","clk":"11832213103","pt":1723082706402,"mc":[{"id":"1.231501647","rc":[{"batb":[[0,1.95,284.33],[1,1.94,98.63],[2,1.93,800]],"ltp":1.96,"tv":962.15,"id":40096581}]}]}
{"op":"mcm","clk":"11832213233","pt":1723082708874,"mc":[{"id":"1.231501647","rc":[{"batb":[[0,1.96,10],[1,1.95,284.33],[2,1.94,98.63]],"ltp":1.96,"tv":962.15,"id":40096581}]}]}
{"op":"mcm","clk":"11832213405","pt":1723082712280,"mc":[{"id":"1.231501647","rc":[{"batb":[[0,1.95,284.33],[1,1.94,98.63],[2,1.93,800]],"ltp":1.96,"tv":962.15,"id":40096581}]}]}
{"op":"mcm","clk":"11832213534","pt":1723082714755,"mc":[{"id":"1.231501647","rc":[{"batb":[[0,1.96,10],[1,1.95,284.33],[2,1.94,98.63]],"ltp":1.96,"tv":962.15,"id":40096581}]}]}
{"op":"mcm","clk":"11832213767","pt":1723082718383,"mc":[{"id":"1.231501647","rc":[{"batb":[[0,1.95,284.33],[1,1.94,98.63],[2,1.93,800]],"ltp":1.96,"tv":962.15,"id":40096581}]}]}
{"op":"mcm","clk":"11832213876","pt":1723082720765,"mc":[{"id":"1.231501647","rc":[{"batb":[[0,1.96,10],[1,1.95,284.33],[2,1.94,98.63]],"ltp":1.96,"tv":962.15,"id":40096581}]}]}
{"op":"mcm","clk":"11832214031","pt":1723082724165,"mc":[{"id":"1.231501647","rc":[{"batb":[[0,1.95,284.33],[1,1.94,98.63],[2,1.93,800]],"ltp":1.96,"tv":962.15,"id":40096581}]}]}
{"op":"mcm","clk":"11832214399","pt":1723082731775,"mc":[{"id":"1.231501647","rc":[{"batb":[[0,1.96,10],[1,1.95,284.33],[2,1.94,98.63]],"ltp":1.96,"tv":962.15,"id":40096581}]}]}
{"op":"mcm","clk":"11832214547","pt":1723082735693,"mc":[{"id":"1.231501647","rc":[{"batb":[[0,1.95,284.33],[1,1.94,98.63],[2,1.93,800]],"ltp":1.96,"tv":962.15,"id":40096581}]}]}
{"op":"mcm","clk":"11832214733","pt":1723082739157,"mc":[{"id":"1.231501647","rc":[{"batb":[[0,1.96,10],[1,1.95,284.33],[2,1.94,98.63]],"ltp":1.96,"tv":962.15,"id":40096581}]}]}
{"op":"mcm","clk":"11832214877","pt":1723082742567,"mc":[{"id":"1.231501647","rc":[{"batb":[[0,1.95,284.33],[1,1.94,98.63],[2,1.93,800]],"ltp":1.96,"tv":962.15,"id":40096581}]}]}
{"op":"mcm","clk":"11832214971","pt":1723082745186,"mc":[{"id":"1.231501647","rc":[{"batb":[[0,1.96,10],[1,1.95,284.33],[2,1.94,98.63]],"ltp":1.96,"tv":962.15,"id":40096581}]}]}
{"op":"mcm","clk":"11832215154","pt":1723082748695,"mc":[{"id":"1.231501647","rc":[{"batb":[[0,1.95,284.33],[1,1.94,98.63],[2,1.93,800]],"ltp":1.96,"tv":962.15,"id":40096581}]}]}
{"op":"mcm","clk":"11832215330","pt":1723082751984,"mc":[{"id":"1.231501647","rc":[{"batb":[[0,1.96,10],[1,1.95,284.33],[2,1.94,98.63]],"ltp":1.96,"tv":962.15,"id":40096581}]}]}
{"op":"mcm","clk":"11832215490","pt":1723082755323,"mc":[{"id":"1.231501647","rc":[{"batb":[[0,1.95,284.33],[1,1.94,98.63],[2,1.93,800]],"ltp":1.96,"tv":962.15,"id":40096581}]}]}
{"op":"mcm","clk":"11832215683","pt":1723082758329,"mc":[{"id":"1.231501647","rc":[{"batb":[[0,1.96,10],[1,1.95,284.33],[2,1.94,98.63]],"ltp":1.96,"tv":962.15,"id":40096581}]}]}
{"op":"mcm","clk":"11832215872","pt":1723082761533,"mc":[{"id":"1.231501647","rc":[{"batb":[[0,1.95,284.33],[1,1.94,98.63],[2,1.93,800]],"ltp":1.96,"tv":962.15,"id":40096581}]}]}
{"op":"mcm","clk":"11832216027","pt":1723082764212,"mc":[{"id":"1.231501647","rc":[{"batb":[[0,1.96,10],[1,1.95,284.33],[2,1.94,98.63]],"ltp":1.96,"tv":962.15,"id":40096581}]}]}
{"op":"mcm","clk":"11832216181","pt":1723082767609,"mc":[{"id":"1.231501647","rc":[{"batb":[[0,1.95,284.33],[1,1.94,98.63],[2,1.93,800]],"ltp":1.96,"tv":962.15,"id":40096581}]}]}
{"op":"mcm","clk":"11832216328","pt":1723082770228,"mc":[{"id":"1.231501647","rc":[{"batb":[[0,1.96,10],[1,1.95,284.33],[2,1.94,98.63]],"ltp":1.96,"tv":962.15,"id":40096581}]}]}
{"op":"mcm","clk":"11832216484","pt":1723082773721,"mc":[{"id":"1.231501647","rc":[{"batb":[[0,1.95,284.33],[1,1.94,98.63],[2,1.93,800]],"ltp":1.96,"tv":962.15,"id":40096581}]}]}
{"op":"mcm","clk":"11832216635","pt":1723082776649,"mc":[{"id":"1.231501647","rc":[{"batb":[[0,1.96,10],[1,1.95,284.33],[2,1.94,98.63]],"ltp":1.96,"tv":962.15,"id":40096581}]}]}
{"op":"mcm","clk":"11832216808","pt":1723082780043,"mc":[{"id":"1.231501647","rc":[{"batb":[[0,1.95,284.33],[1,1.94,98.63],[2,1.93,800]],"ltp":1.96,"tv":962.15,"id":40096581}]}]}
{"op":"mcm","clk":"11832216941","pt":1723082783127,"mc":[{"id":"1.231501647","rc":[{"batb":[[0,1.96,10],[1,1.95,284.33],[2,1.94,98.63]],"ltp":1.96,"tv":962.15,"id":40096581}]}]}
{"op":"mcm","clk":"11832217131","pt":1723082786733,"mc":[{"id":"1.231501647","rc":[{"batb":[[0,1.95,284.33],[1,1.94,98.63],[2,1.93,800]],"ltp":1.96,"tv":962.15,"id":40096581}]}]}
{"op":"mcm","clk":"11832217261","pt":1723082789367,"mc":[{"id":"1.231501647","rc":[{"batb":[[0,1.96,10],[1,1.95,284.33],[2,1.94,98.63]],"ltp":1.96,"tv":962.15,"id":40096581}]}]}
{"op":"mcm","clk":"11832217452","pt":1723082792972,"mc":[{"id":"1.231501647","rc":[{"batb":[[0,1.95,284.33],[1,1.94,98.63],[2,1.93,800]],"ltp":1.96,"tv":962.15,"id":40096581}]}]}
{"op":"mcm","clk":"11832217623","pt":1723082796267,"mc":[{"id":"1.231501647","rc":[{"batb":[[0,1.96,10],[1,1.95,284.33],[2,1.94,98.63]],"ltp":1.96,"tv":962.15,"id":40096581}]}]}
{"op":"mcm","clk":"11832217805","pt":1723082799780,"mc":[{"id":"1.231501647","rc":[{"batb":[[0,1.95,284.33],[1,1.94,98.63],[2,1.93,800]],"ltp":1.96,"tv":962.15,"id":40096581}]}]}
{"op":"mcm","clk":"11832217984","pt":1723082803181,"mc":[{"id":"1.231501647","rc":[{"batb":[[0,1.96,10],[1,1.95,284.33],[2,1.94,98.63]],"ltp":1.96,"tv":962.15,"id":40096581}]}]}
{"op":"mcm","clk":"11832218167","pt":1723082806585,"mc":[{"id":"1.231501647","rc":[{"batb":[[0,1.95,284.33],[1,1.94,98.63],[2,1.93,800]],"ltp":1.96,"tv":962.15,"id":40096581}]}]}
{"op":"mcm","clk":"11832218308","pt":1723082809060,"mc":[{"id":"1.231501647","rc":[{"batb":[[0,1.96,10],[1,1.95,284.33],[2,1.94,98.63]],"ltp":1.96,"tv":962.15,"id":40096581}]}]}
{"op":"mcm","clk":"11832218493","pt":1723082812360,"mc":[{"id":"1.231501647","rc":[{"batb":[[0,1.95,284.33],[1,1.94,98.63],[2,1.93,800]],"ltp":1.96,"tv":962.15,"id":40096581}]}]}
{"op":"mcm","clk":"11832218694","pt":1723082816196,"mc":[{"id":"1.231501647","rc":[{"batb":[[0,1.96,10],[1,1.95,284.33],[2,1.94,98.63]],"ltp":1.96,"tv":962.15,"id":40096581}]}]}
{"op":"mcm","clk":"11832218876","pt":1723082819697,"mc":[{"id":"1.231501647","rc":[{"batb":[[0,1.95,284.33],[1,1.94,98.63],[2,1.93,800]],"ltp":1.96,"tv":962.15,"id":40096581}]}]}
