{"op":"mcm","clk":"11856917356","pt":1723800178717,"mc":[{"id":"1.231875523","marketDefinition":{"bspMarket":false,"turnInPlayEnabled":true,"persistenceEnabled":true,"marketBaseRate":5.0,"eventId":"33499729","eventTypeId":"4","numberOfWinners":1,"bettingType":"ODDS","marketType":"MATCH_ODDS","marketTime":"2024-08-22T10:00:00.000Z","suspendTime":"2024-08-22T10:00:00.000Z","bspReconciled":false,"complete":true,"inPlay":false,"crossMatching":false,"runnersVoidable":false,"numberOfActiveRunners":3,"betDelay":0,"status":"OPEN","runners":[{"status":"ACTIVE","sortPriority":1,"id":31378,"name":"Middlesex"},{"status":"ACTIVE","sortPriority":2,"id":475559,"name":"Northamptonshire"},{"status":"ACTIVE","sortPriority":3,"id":60443,"name":"The Draw"}],"regulators":["MR_INT"],"countryCode":"GB","discountAllowed":false,"timezone":"GMT","openDate":"2024-08-22T10:00:00.000Z","version":6076597024,"name":"Match Odds","eventName":"Middlesex v Northamptonshire"},"rc":[{"batb":[[0,1.03,200],[1,1.02,200],[2,1.01,220]],"ltp":0.0,"tv":0.0,"id":31378},{"batb":[[0,1.03,200],[1,1.02,200],[2,1.01,220]],"ltp":0.0,"tv":0.0,"id":60443},{"batb":[[0,1.03,200],[1,1.02,200],[2,1.01,220]],"ltp":0.0,"tv":0.0,"id":475559}]}]}
{"op":"mcm","clk":"11856917403","pt":1723800180089,"mc":[{"id":"1.231875523","marketDefinition":{"bspMarket":false,"turnInPlayEnabled":true,"persistenceEnabled":true,"marketBaseRate":5.0,"eventId":"33499729","eventTypeId":"4","numberOfWinners":1,"bettingType":"ODDS","marketType":"MATCH_ODDS","marketTime":"2024-08-22T10:00:00.000Z","suspendTime":"2024-08-22T10:00:00.000Z","bspReconciled":false,"complete":true,"inPlay":false,"crossMatching":false,"runnersVoidable":false,"numberOfActiveRunners":3,"betDelay":0,"status":"OPEN","runners":[{"status":"ACTIVE","sortPriority":1,"id":31378,"name":"Middlesex"},{"status":"ACTIVE","sortPriority":2,"id":475559,"name":"Northamptonshire"},{"status":"ACTIVE","sortPriority":3,"id":60443,"name":"The Draw"}],"regulators":["MR_INT"],"countryCode":"GB","discountAllowed":true,"timezone":"GMT","openDate":"2024-08-22T10:00:00.000Z","version":6076597024,"name":"Match Odds","eventName":"Middlesex v Northamptonshire"}}]}
{"op":"mcm","clk":"11857017856","pt":1723802252663,"mc":[{"id":"1.231875523","rc":[{"trd":[[1.03,2]],"batb":[[0,1.03,199]],"ltp":1.03,"tv":2.0,"id":31378}],"tv":2.0}]}
{"op":"mcm","clk":"11857660664","pt":1723811308707,"mc":[{"id":"1.231875523","rc":[{"batb":[[0,1.25,100],[1,1.03,199],[2,1.02,200]],"ltp":1.03,"tv":2.0,"id":31378}]}]}
{"op":"mcm","clk":"11857660693","pt":1723811309151,"mc":[{"id":"1.231875523","rc":[{"batb":[[0,1.25,100],[1,1.03,200],[2,1.02,200]],"ltp":0.0,"tv":0.0,"id":475559},{"batb":[[0,1.25,100],[1,1.03,200],[2,1.02,200]],"ltp":0.0,"tv":0.0,"id":60443}]}]}
{"op":"mcm","clk":"11857663129","pt":1723811340629,"mc":[{"id":"1.231875523","rc":[{"batb":[[0,1.03,199],[1,1.02,200],[2,1.01,220]],"ltp":1.03,"tv":2.0,"id":31378},{"batb":[[0,1.03,200],[1,1.02,200],[2,1.01,220]],"ltp":0.0,"tv":0.0,"id":475559},{"batb":[[0,1.03,200],[1,1.02,200],[2,1.01,220]],"ltp":0.0,"tv":0.0,"id":60443}]}]}
{"op":"mcm","clk":"11857663562","pt":1723811345826,"mc":[{"id":"1.231875523","rc":[{"batb":[[0,1.25,100],[1,1.03,199],[2,1.02,200]],"ltp":1.03,"tv":2.0,"id":31378},{"batb":[[0,1.25,100],[1,1.03,200],[2,1.02,200]],"ltp":0.0,"tv":0.0,"id":475559},{"batb":[[0,1.25,100],[1,1.03,200],[2,1.02,200]],"ltp":0.0,"tv":0.0,"id":60443}]}]}
{"op":"mcm","clk":"11857664010","pt":1723811351440,"mc":[{"id":"1.231875523","rc":[{"batb":[[0,1.03,199],[1,1.02,200],[2,1.01,220]],"ltp":1.03,"tv":2.0,"id":31378},{"batb":[[0,1.03,200],[1,1.02,200],[2,1.01,220]],"ltp":0.0,"tv":0.0,"id":475559},{"batb":[[0,1.03,200],[1,1.02,200],[2,1.01,220]],"ltp":0.0,"tv":0.0,"id":60443}]}]}
{"op":"mcm","clk":"11857664454","pt":1723811357761,"mc":[{"id":"1.231875523","rc":[{"batl":[[0,95,5],[1,990,5]],"ltp":1.03,"tv":2.0,"id":31378},{"batl":[[0,95,5],[1,990,5]],"ltp":0.0,"tv":0.0,"id":475559},{"batl":[[0,95,5],[1,990,5]],"ltp":0.0,"tv":0.0,"id":60443}]}]}
{"op":"mcm","clk":"11857669234","pt":1723811420409,"mc":[{"id":"1.231875523","rc":[{"batb":[[0,1.04,500],[1,1.03,199],[2,1.02,200]],"ltp":1.03,"tv":2.0,"id":31378},{"batb":[[0,1.04,500],[1,1.03,200],[2,1.02,200]],"ltp":0.0,"tv":0.0,"id":475559},{"batb":[[0,1.04,500],[1,1.03,200],[2,1.02,200]],"ltp":0.0,"tv":0.0,"id":60443}]}]}
{"op":"mcm","clk":"11861498856","pt":1723841948944,"mc":[{"id":"1.231875523","marketDefinition":{"bspMarket":false,"turnInPlayEnabled":true,"persistenceEnabled":true,"marketBaseRate":5.0,"eventId":"33499729","eventTypeId":"4","numberOfWinners":1,"bettingType":"ODDS","marketType":"MATCH_ODDS","marketTime":"2024-08-22T10:00:00.000Z","suspendTime":"2024-08-22T10:00:00.000Z","bspReconciled":false,"complete":true,"inPlay":false,"crossMatching":true,"runnersVoidable":false,"numberOfActiveRunners":3,"betDelay":0,"status":"OPEN","runners":[{"status":"ACTIVE","sortPriority":1,"id":31378,"name":"Middlesex"},{"status":"ACTIVE","sortPriority":2,"id":475559,"name":"Northamptonshire"},{"status":"ACTIVE","sortPriority":3,"id":60443,"name":"The Draw"}],"regulators":["MR_INT"],"countryCode":"GB","discountAllowed":true,"timezone":"GMT","openDate":"2024-08-22T10:00:00.000Z","version":6076599840,"name":"Match Odds","eventName":"Middlesex v Northamptonshire"}}]}
{"op":"mcm","clk":"11866685511","pt":1723900067589,"mc":[{"id":"1.231875523","rc":[{"batb":[[0,1.05,44.3],[1,1.04,500],[2,1.03,199]],"batl":[[0,95,5.85]],"ltp":1.03,"tv":2.0,"id":31378},{"batb":[[0,1.05,44.3],[1,1.04,500],[2,1.03,200]],"batl":[[0,95,5.85]],"ltp":0.0,"tv":0.0,"id":60443},{"batb":[[0,1.05,44.3],[1,1.04,500],[2,1.03,200]],"batl":[[0,95,5.85]],"ltp":0.0,"tv":0.0,"id":475559}]}]}
{"op":"mcm","clk":"11866712755","pt":1723900214734,"mc":[{"id":"1.231875523","rc":[{"batb":[[0,1.06,142.66],[1,1.05,44.3],[2,1.04,500]],"ltp":1.03,"tv":2.0,"id":31378},{"batb":[[0,1.06,142.66],[1,1.05,44.3],[2,1.04,500]],"ltp":0.0,"tv":0.0,"id":60443},{"batb":[[0,1.06,142.66],[1,1.05,44.3],[2,1.04,500]],"ltp":0.0,"tv":0.0,"id":475559}]}]}
{"op":"mcm","clk":"11867084636","pt":1723902015070,"mc":[{"id":"1.231875523","rc":[{"batb":[[0,1.05,44.3],[1,1.04,500],[2,1.03,199]],"ltp":1.03,"tv":2.0,"id":31378},{"batb":[[0,1.05,44.3],[1,1.04,500],[2,1.03,200]],"ltp":0.0,"tv":0.0,"id":60443},{"batb":[[0,1.05,44.3],[1,1.04,500],[2,1.03,200]],"ltp":0.0,"tv":0.0,"id":475559}]}]}
{"op":"mcm","clk":"11867087859","pt":1723902029789,"mc":[{"id":"1.231875523","rc":[{"batb":[[0,1.06,142.66],[1,1.05,44.3],[2,1.04,500]],"ltp":1.03,"tv":2.0,"id":31378},{"batb":[[0,1.06,142.66],[1,1.05,44.3],[2,1.04,500]],"ltp":0.0,"tv":0.0,"id":60443},{"batb":[[0,1.06,142.66],[1,1.05,44.3],[2,1.04,500]],"ltp":0.0,"tv":0.0,"id":475559}]}]}
{"op":"mcm","clk":"11867485476","pt":1723903830055,"mc":[{"id":"1.231875523","rc":[{"batb":[[0,1.05,44.3],[1,1.04,500],[2,1.03,199]],"ltp":1.03,"tv":2.0,"id":31378}]}]}
{"op":"mcm","clk":"11867485602","pt":1723903830479,"mc":[{"id":"1.231875523","rc":[{"batb":[[0,1.05,44.3],[1,1.04,500],[2,1.03,200]],"ltp":0.0,"tv":0.0,"id":60443},{"batb":[[0,1.05,44.3],[1,1.04,500],[2,1.03,200]],"ltp":0.0,"tv":0.0,"id":475559}]}]}
{"op":"mcm","clk":"11867532981","pt":1723903986581,"mc":[{"id":"1.231875523","rc":[{"batb":[[0,1.06,142.66],[1,1.05,44.3],[2,1.04,500]],"ltp":1.03,"tv":2.0,"id":31378},{"batb":[[0,1.06,142.66],[1,1.05,44.3],[2,1.04,500]],"ltp":0.0,"tv":0.0,"id":60443},{"batb":[[0,1.06,142.66],[1,1.05,44.3],[2,1.04,500]],"ltp":0.0,"tv":0.0,"id":475559}]}]}
{"op":"mcm","clk":"11868054121","pt":1723905786949,"mc":[{"id":"1.231875523","rc":[{"batb":[[0,1.05,44.3],[1,1.04,500],[2,1.03,200]],"ltp":0.0,"tv":0.0,"id":60443},{"batb":[[0,1.05,44.3],[1,1.04,500],[2,1.03,200]],"ltp":0.0,"tv":0.0,"id":475559}]}]}
{"op":"mcm","clk":"11868054185","pt":1723905787152,"mc":[{"id":"1.231875523","rc":[{"batb":[[0,1.05,44.3],[1,1.04,500],[2,1.03,199]],"ltp":1.03,"tv":2.0,"id":31378}]}]}
{"op":"mcm","clk":"11868066359","pt":1723905827121,"mc":[{"id":"1.231875523","rc":[{"batb":[[0,1.04,500],[1,1.03,199],[2,1.02,200]],"batl":[[0,95,5]],"ltp":1.03,"tv":2.0,"id":31378},{"batb":[[0,1.04,500],[1,1.03,200],[2,1.02,200]],"batl":[[0,95,5]],"ltp":0.0,"tv":0.0,"id":60443}]}]}
{"op":"mcm","clk":"11868092427","pt":1723905917962,"mc":[{"id":"1.231875523","rc":[{"batb":[[0,1.06,142.66],[1,1.05,44.3],[2,1.04,500]],"ltp":0.0,"tv":0.0,"id":475559}]}]}
{"op":"mcm","clk":"11868525600","pt":1723907718170,"mc":[{"id":"1.231875523","rc":[{"batb":[[0,1.05,44.3],[1,1.04,500],[2,1.03,200]],"ltp":0.0,"tv":0.0,"id":475559}]}]}
{"op":"mcm","clk":"11868551125","pt":1723907805735,"mc":[{"id":"1.231875523","rc":[{"batb":[[0,1.06,142.66],[1,1.05,44.3],[2,1.04,500]],"ltp":0.0,"tv":0.0,"id":475559}]}]}
{"op":"mcm","clk":"11868958601","pt":1723909328001,"mc":[{"id":"1.231875523","rc":[{"batb":[[1,1.04,500],[2,1.03,200]],"ltp":0.0,"tv":0.0,"id":475559}]}]}
{"op":"mcm","clk":"11868958635","pt":1723909328119,"mc":[{"id":"1.231875523","rc":[{"batb":[[0,1.07,44.3],[1,1.06,142.66],[2,1.04,500]],"ltp":0.0,"tv":0.0,"id":475559}]}]}
{"op":"mcm","clk":"11868961586","pt":1723909340265,"mc":[{"id":"1.231875523","rc":[{"batb":[[0,1.05,55.37],[1,1.04,500],[2,1.03,199]],"ltp":1.03,"tv":2.0,"id":31378},{"batb":[[0,1.05,55.37],[1,1.04,500],[2,1.03,200]],"ltp":0.0,"tv":0.0,"id":60443}]}]}
{"op":"mcm","clk":"11868992811","pt":1723909466233,"mc":[{"id":"1.231875523","rc":[{"batl":[[0,95,5.85]],"ltp":1.03,"tv":2.0,"id":31378},{"batl":[[0,95,5.85]],"ltp":0.0,"tv":0.0,"id":60443}]}]}
{"op":"mcm","clk":"11868993810","pt":1723909469965,"mc":[{"id":"1.231875523","rc":[{"batb":[[0,1.06,142.66],[1,1.05,55.37],[2,1.04,500]],"ltp":1.03,"tv":2.0,"id":31378},{"batb":[[0,1.06,142.66],[1,1.05,55.37],[2,1.04,500]],"ltp":0.0,"tv":0.0,"id":60443}]}]}
{"op":"mcm","clk":"11869027246","pt":1723909605999,"mc":[{"id":"1.231875523","rc":[{"batb":[[1,1.04,500],[2,1.03,200]],"ltp":0.0,"tv":0.0,"id":475559}]}]}
{"op":"mcm","clk":"11869038157","pt":1723909654274,"mc":[{"id":"1.231875523","rc":[{"batb":[[0,1.08,106.99],[1,1.07,44.3],[2,1.04,500]],"ltp":0.0,"tv":0.0,"id":475559}]}]}
{"op":"mcm","clk":"11869330180","pt":1723911270233,"mc":[{"id":"1.231875523","rc":[{"batb":[[0,1.05,55.37],[1,1.04,500],[2,1.03,200]],"ltp":0.0,"tv":0.0,"id":60443}]}]}
{"op":"mcm","clk":"11869330317","pt":1723911271125,"mc":[{"id":"1.231875523","rc":[{"batb":[[0,1.05,55.37],[1,1.04,500],[2,1.03,199]],"ltp":1.03,"tv":2.0,"id":31378}]}]}
{"op":"mcm","clk":"11869346690","pt":1723911362523,"mc":[{"id":"1.231875523","rc":[{"batb":[[0,1.06,142.66],[1,1.05,55.37],[2,1.04,500]],"ltp":1.03,"tv":2.0,"id":31378},{"batb":[[0,1.06,142.66],[1,1.05,55.37],[2,1.04,500]],"ltp":0.0,"tv":0.0,"id":60443}]}]}
{"op":"mcm","clk":"11869363313","pt":1723911454446,"mc":[{"id":"1.231875523","rc":[{"batb":[[0,1.07,44.3],[1,1.04,500],[2,1.03,200]],"ltp":0.0,"tv":0.0,"id":475559}]}]}
{"op":"mcm","clk":"11869375990","pt":1723911522544,"mc":[{"id":"1.231875523","rc":[{"batb":[[0,1.08,106.99],[1,1.07,44.3],[2,1.04,500]],"ltp":0.0,"tv":0.0,"id":475559}]}]}
{"op":"mcm","clk":"11869697018","pt":1723913162928,"mc":[{"id":"1.231875523","rc":[{"batb":[[0,1.05,55.37],[1,1.04,500],[2,1.03,199]],"ltp":1.03,"tv":2.0,"id":31378},{"batb":[[0,1.05,55.37],[1,1.04,500],[2,1.03,200]],"ltp":0.0,"tv":0.0,"id":60443}]}]}
{"op":"mcm","clk":"11869719289","pt":1723913271468,"mc":[{"id":"1.231875523","rc":[{"batb":[[0,1.06,142.66],[1,1.05,55.37],[2,1.04,500]],"ltp":1.03,"tv":2.0,"id":31378},{"batb":[[0,1.06,142.66],[1,1.05,55.37],[2,1.04,500]],"ltp":0.0,"tv":0.0,"id":60443}]}]}
{"op":"mcm","clk":"11869729847","pt":1723913322838,"mc":[{"id":"1.231875523","rc":[{"batb":[[0,1.07,44.3],[1,1.04,500],[2,1.03,200]],"ltp":0.0,"tv":0.0,"id":475559}]}]}
{"op":"mcm","clk":"11869751564","pt":1723913427715,"mc":[{"id":"1.231875523","rc":[{"batb":[[0,1.08,106.99],[1,1.07,44.3],[2,1.04,500]],"ltp":0.0,"tv":0.0,"id":475559}]}]}
{"op":"mcm","clk":"11870058237","pt":1723915071890,"mc":[{"id":"1.231875523","rc":[{"batb":[[0,1.05,55.37],[1,1.04,500],[2,1.03,199]],"ltp":1.03,"tv":2.0,"id":31378},{"batb":[[0,1.05,55.37],[1,1.04,500],[2,1.03,200]],"ltp":0.0,"tv":0.0,"id":60443}]}]}
{"op":"mcm","clk":"11870066132","pt":1723915114024,"mc":[{"id":"1.231875523","rc":[{"batb":[[0,1.06,142.66],[1,1.05,55.37],[2,1.04,500]],"ltp":1.03,"tv":2.0,"id":31378},{"batb":[[0,1.06,142.66],[1,1.05,55.37],[2,1.04,500]],"ltp":0.0,"tv":0.0,"id":60443}]}]}
{"op":"mcm","clk":"11870088224","pt":1723915227953,"mc":[{"id":"1.231875523","rc":[{"batb":[[0,1.07,44.3],[1,1.04,500],[2,1.03,200]],"ltp":0.0,"tv":0.0,"id":475559}]}]}
{"op":"mcm","clk":"11870095222","pt":1723915265128,"mc":[{"id":"1.231875523","rc":[{"batb":[[0,1.08,106.99],[1,1.07,44.3],[2,1.04,500]],"ltp":0.0,"tv":0.0,"id":475559}]}]}
{"op":"mcm","clk":"11870404950","pt":1723916914425,"mc":[{"id":"1.231875523","rc":[{"batb":[[0,1.05,55.37],[1,1.04,500],[2,1.03,199]],"ltp":1.03,"tv":2.0,"id":31378},{"batb":[[0,1.05,55.37],[1,1.04,500],[2,1.03,200]],"ltp":0.0,"tv":0.0,"id":60443}]}]}
{"op":"mcm","clk":"11870429134","pt":1723917054732,"mc":[{"id":"1.231875523","rc":[{"batb":[[0,1.06,142.66],[1,1.05,55.37],[2,1.04,500]],"ltp":1.03,"tv":2.0,"id":31378},{"batb":[[0,1.06,142.66],[1,1.05,55.37],[2,1.04,500]],"ltp":0.0,"tv":0.0,"id":60443}]}]}
{"op":"mcm","clk":"11870431075","pt":1723917065359,"mc":[{"id":"1.231875523","rc":[{"batb":[[0,1.07,44.3],[1,1.04,500],[2,1.03,200]],"ltp":0.0,"tv":0.0,"id":475559}]}]}
{"op":"mcm","clk":"11870457120","pt":1723917202500,"mc":[{"id":"1.231875523","rc":[{"batb":[[0,1.08,106.99],[1,1.07,44.3],[2,1.04,500]],"ltp":0.0,"tv":0.0,"id":475559}]}]}
{"op":"mcm","clk":"11870823518","pt":1723918854989,"mc":[{"id":"1.231875523","rc":[{"batb":[[0,1.05,55.37],[1,1.04,500],[2,1.03,199]],"ltp":1.03,"tv":2.0,"id":31378}]}]}
{"op":"mcm","clk":"11870823565","pt":1723918855293,"mc":[{"id":"1.231875523","rc":[{"batb":[[0,1.05,55.37],[1,1.04,500],[2,1.03,200]],"ltp":0.0,"tv":0.0,"id":60443}]}]}
{"op":"mcm","clk":"11870840263","pt":1723918939998,"mc":[{"id":"1.231875523","rc":[{"batb":[[0,1.06,142.66],[1,1.05,55.37],[2,1.04,500]],"ltp":1.03,"tv":2.0,"id":31378},{"batb":[[0,1.06,142.66],[1,1.05,55.37],[2,1.04,500]],"ltp":0.0,"tv":0.0,"id":60443}]}]}
{"op":"mcm","clk":"11870852635","pt":1723919002772,"mc":[{"id":"1.231875523","rc":[{"batb":[[0,1.07,44.3],[1,1.04,500],[2,1.03,200]],"ltp":0.0,"tv":0.0,"id":475559}]}]}
{"op":"mcm","clk":"11870867899","pt":1723919081463,"mc":[{"id":"1.231875523","rc":[{"batb":[[0,1.08,106.99],[1,1.07,44.3],[2,1.04,500]],"ltp":0.0,"tv":0.0,"id":475559}]}]}
{"op":"mcm","clk":"11871234761","pt":1723920740481,"mc":[{"id":"1.231875523","rc":[{"batb":[[0,1.05,55.37],[1,1.04,500],[2,1.03,199]],"ltp":1.03,"tv":2.0,"id":31378},{"batb":[[0,1.05,55.37],[1,1.04,500],[2,1.03,200]],"ltp":0.0,"tv":0.0,"id":60443}]}]}
{"op":"mcm","clk":"11871238750","pt":1723920761195,"mc":[{"id":"1.231875523","rc":[{"batb":[[0,1.06,142.66],[1,1.05,55.37],[2,1.04,500]],"ltp":1.03,"tv":2.0,"id":31378},{"batb":[[0,1.06,142.66],[1,1.05,55.37],[2,1.04,500]],"ltp":0.0,"tv":0.0,"id":60443}]}]}
{"op":"mcm","clk":"11871261924","pt":1723920881660,"mc":[{"id":"1.231875523","rc":[{"batb":[[0,1.07,44.3],[1,1.04,500],[2,1.03,200]],"ltp":0.0,"tv":0.0,"id":475559}]}]}
{"op":"mcm","clk":"11871265476","pt":1723920900095,"mc":[{"id":"1.231875523","rc":[{"batb":[[0,1.08,106.99],[1,1.07,44.3],[2,1.04,500]],"ltp":0.0,"tv":0.0,"id":475559}]}]}
{"op":"mcm","clk":"11871319359","pt":1723921172952,"mc":[{"id":"1.231875523","rc":[{"batb":[[2,1.03,200]],"ltp":0.0,"tv":0.0,"id":60443}]}]}
{"op":"mcm","clk":"11871319609","pt":1723921174169,"mc":[{"id":"1.231875523","rc":[{"batb":[[2,1.03,200]],"ltp":0.0,"tv":0.0,"id":475559}]}]}
{"op":"mcm","clk":"11871319795","pt":1723921175097,"mc":[{"id":"1.231875523","rc":[{"batb":[[2,1.03,199]],"ltp":1.03,"tv":2.0,"id":31378}]}]}
{"op":"mcm","clk":"11871319994","pt":1723921176198,"mc":[{"id":"1.231875523","rc":[{"batb":[[0,1.07,285.71],[1,1.06,142.66],[2,1.05,55.37]],"ltp":1.03,"tv":2.0,"id":31378}]}]}
{"op":"mcm","clk":"11871320194","pt":1723921177260,"mc":[{"id":"1.231875523","rc":[{"batb":[[0,1.09,222.22],[1,1.08,106.99],[2,1.07,44.3]],"ltp":0.0,"tv":0.0,"id":475559}]}]}
{"op":"mcm","clk":"11871320492","pt":1723921178963,"mc":[{"id":"1.231875523","rc":[{"batb":[[0,1.07,285.71],[1,1.06,142.66],[2,1.05,55.37]],"ltp":0.0,"tv":0.0,"id":60443}]}]}
{"op":"mcm","clk":"11871629704","pt":1723922561481,"mc":[{"id":"1.231875523","rc":[{"batb":[[1,1.05,55.37],[2,1.03,199]],"ltp":1.03,"tv":2.0,"id":31378},{"batb":[[1,1.05,55.37],[2,1.03,200]],"ltp":0.0,"tv":0.0,"id":60443}]}]}
{"op":"mcm","clk":"11871651872","pt":1723922671331,"mc":[{"id":"1.231875523","rc":[{"batb":[[0,1.08,106.99],[1,1.07,285.71],[2,1.05,55.37]],"ltp":1.03,"tv":2.0,"id":31378},{"batb":[[0,1.08,106.99],[1,1.07,285.71],[2,1.05,55.37]],"ltp":0.0,"tv":0.0,"id":60443}]}]}
{"op":"mcm","clk":"11871657202","pt":1723922700271,"mc":[{"id":"1.231875523","rc":[{"batb":[[1,1.07,44.3],[2,1.03,200]],"ltp":0.0,"tv":0.0,"id":475559}]}]}
{"op":"mcm","clk":"11871676569","pt":1723922807061,"mc":[{"id":"1.231875523","rc":[{"batb":[[0,1.1,85.6],[1,1.09,222.22],[2,1.07,44.3]],"ltp":0.0,"tv":0.0,"id":475559}]}]}
{"op":"mcm","clk":"11871980401","pt":1723924471796,"mc":[{"id":"1.231875523","rc":[{"batb":[[0,1.07,285.71],[1,1.05,55.37],[2,1.03,199]],"ltp":1.03,"tv":2.0,"id":31378},{"batb":[[0,1.07,285.71],[1,1.05,55.37],[2,1.03,200]],"ltp":0.0,"tv":0.0,"id":60443}]}]}
{"op":"mcm","clk":"11871991625","pt":1723924543157,"mc":[{"id":"1.231875523","rc":[{"batb":[[0,1.08,106.99],[1,1.07,285.71],[2,1.05,55.37]],"ltp":1.03,"tv":2.0,"id":31378},{"batb":[[0,1.08,106.99],[1,1.07,285.71],[2,1.05,55.37]],"ltp":0.0,"tv":0.0,"id":60443}]}]}
{"op":"mcm","clk":"11872001495","pt":1723924607409,"mc":[{"id":"1.231875523","rc":[{"batb":[[0,1.09,222.22],[1,1.07,44.3],[2,1.03,200]],"ltp":0.0,"tv":0.0,"id":475559}]}]}
{"op":"mcm","clk":"11872011984","pt":1723924675876,"mc":[{"id":"1.231875523","rc":[{"batb":[[0,1.1,85.6],[1,1.09,222.22],[2,1.07,44.3]],"ltp":0.0,"tv":0.0,"id":475559}]}]}
{"op":"mcm","clk":"11872261237","pt":1723926343598,"mc":[{"id":"1.231875523","rc":[{"batb":[[0,1.07,285.71],[1,1.05,55.37],[2,1.03,199]],"ltp":1.03,"tv":2.0,"id":31378},{"batb":[[0,1.07,285.71],[1,1.05,55.37],[2,1.03,200]],"ltp":0.0,"tv":0.0,"id":60443}]}]}
{"op":"mcm","clk":"11872276944","pt":1723926459607,"mc":[{"id":"1.231875523","rc":[{"batb":[[0,1.08,106.99],[1,1.07,285.71],[2,1.05,55.37]],"ltp":1.03,"tv":2.0,"id":31378},{"batb":[[0,1.08,106.99],[1,1.07,285.71],[2,1.05,55.37]],"ltp":0.0,"tv":0.0,"id":60443}]}]}
{"op":"mcm","clk":"11872279178","pt":1723926476054,"mc":[{"id":"1.231875523","rc":[{"batb":[[0,1.09,222.22],[1,1.07,44.3],[2,1.03,200]],"ltp":0.0,"tv":0.0,"id":475559}]}]}
{"op":"mcm","clk":"11872293772","pt":1723926585114,"mc":[{"id":"1.231875523","rc":[{"batb":[[0,1.1,85.6],[1,1.09,222.22],[2,1.07,44.3]],"ltp":0.0,"tv":0.0,"id":475559}]}]}
{"op":"mcm","clk":"11872471497","pt":1723928260064,"mc":[{"id":"1.231875523","rc":[{"batb":[[0,1.07,285.71],[1,1.05,55.37],[2,1.03,199]],"ltp":1.03,"tv":2.0,"id":31378},{"batb":[[0,1.07,285.71],[1,1.05,55.37],[2,1.03,200]],"ltp":0.0,"tv":0.0,"id":60443}]}]}
{"op":"mcm","clk":"11872474511","pt":1723928301039,"mc":[{"id":"1.231875523","rc":[{"batb":[[0,1.08,106.99],[1,1.07,285.71],[2,1.05,55.37]],"ltp":1.03,"tv":2.0,"id":31378},{"batb":[[0,1.08,106.99],[1,1.07,285.71],[2,1.05,55.37]],"ltp":0.0,"tv":0.0,"id":60443}]}]}
{"op":"mcm","clk":"11872480901","pt":1723928385332,"mc":[{"id":"1.231875523","rc":[{"batb":[[0,1.09,222.22],[1,1.07,44.3],[2,1.03,200]],"ltp":0.0,"tv":0.0,"id":475559}]}]}
{"op":"mcm","clk":"11872483637","pt":1723928419144,"mc":[{"id":"1.231875523","rc":[{"batb":[[0,1.1,85.6],[1,1.09,222.22],[2,1.07,44.3]],"ltp":0.0,"tv":0.0,"id":475559}]}]}
{"op":"mcm","clk":"11872627579","pt":1723930101324,"mc":[{"id":"1.231875523","rc":[{"batb":[[0,1.07,285.71],[1,1.05,55.37],[2,1.03,199]],"ltp":1.03,"tv":2.0,"id":31378},{"batb":[[0,1.07,285.71],[1,1.05,55.37],[2,1.03,200]],"ltp":0.0,"tv":0.0,"id":60443}]}]}
{"op":"mcm","clk":"11872631552","pt":1723930152647,"mc":[{"id":"1.231875523","rc":[{"batb":[[0,1.08,106.99],[1,1.07,285.71],[2,1.05,55.37]],"ltp":1.03,"tv":2.0,"id":31378},{"batb":[[0,1.08,106.99],[1,1.07,285.71],[2,1.05,55.37]],"ltp":0.0,"tv":0.0,"id":60443}]}]}
{"op":"mcm","clk":"11872637065","pt":1723930219483,"mc":[{"id":"1.231875523","rc":[{"batb":[[0,1.09,222.22],[1,1.07,44.3],[2,1.03,200]],"ltp":0.0,"tv":0.0,"id":475559}]}]}
{"op":"mcm","clk":"11872641035","pt":1723930267824,"mc":[{"id":"1.231875523","rc":[{"batb":[[0,1.1,85.6],[1,1.09,222.22],[2,1.07,44.3]],"ltp":0.0,"tv":0.0,"id":475559}]}]}
{"op":"mcm","clk":"11872776506","pt":1723931953001,"mc":[{"id":"1.231875523","rc":[{"batb":[[0,1.07,285.71],[1,1.05,55.37],[2,1.03,199]],"ltp":1.03,"tv":2.0,"id":31378},{"batb":[[0,1.07,285.71],[1,1.05,55.37],[2,1.03,200]],"ltp":0.0,"tv":0.0,"id":60443}]}]}
{"op":"mcm","clk":"11872777330","pt":1723931966824,"mc":[{"id":"1.231875523","rc":[{"batb":[[0,1.08,106.99],[1,1.07,285.71],[2,1.05,55.37]],"ltp":1.03,"tv":2.0,"id":31378},{"batb":[[0,1.08,106.99],[1,1.07,285.71],[2,1.05,55.37]],"ltp":0.0,"tv":0.0,"id":60443}]}]}
{"op":"mcm","clk":"11872783896","pt":1723932068105,"mc":[{"id":"1.231875523","rc":[{"batb":[[0,1.09,222.22],[1,1.07,44.3],[2,1.03,200]],"ltp":0.0,"tv":0.0,"id":475559}]}]}
{"op":"mcm","clk":"11872784578","pt":1723932078531,"mc":[{"id":"1.231875523","rc":[{"batb":[[0,1.1,85.6],[1,1.09,222.22],[2,1.07,44.3]],"ltp":0.0,"tv":0.0,"id":475559}]}]}
{"op":"mcm","clk":"11872901054","pt":1723933767336,"mc":[{"id":"1.231875523","rc":[{"batb":[[0,1.07,285.71],[1,1.05,55.37],[2,1.03,199]],"ltp":1.03,"tv":2.0,"id":31378},{"batb":[[0,1.07,285.71],[1,1.05,55.37],[2,1.03,200]],"ltp":0.0,"tv":0.0,"id":60443}]}]}
{"op":"mcm","clk":"11872907108","pt":1723933856868,"mc":[{"id":"1.231875523","rc":[{"batb":[[0,1.08,106.99],[1,1.07,285.71],[2,1.05,55.37]],"ltp":1.03,"tv":2.0,"id":31378},{"batb":[[0,1.08,106.99],[1,1.07,285.71],[2,1.05,55.37]],"ltp":0.0,"tv":0.0,"id":60443}]}]}
{"op":"mcm","clk":"11872908707","pt":1723933878707,"mc":[{"id":"1.231875523","rc":[{"batb":[[0,1.09,222.22],[1,1.07,44.3],[2,1.03,200]],"ltp":0.0,"tv":0.0,"id":475559}]}]}
{"op":"mcm","clk":"11872914453","pt":1723933967612,"mc":[{"id":"1.231875523","rc":[{"batb":[[0,1.1,85.6],[1,1.09,222.22],[2,1.07,44.3]],"ltp":0.0,"tv":0.0,"id":475559}]}]}
{"op":"mcm","clk":"11873033472","pt":1723935657041,"mc":[{"id":"1.231875523","rc":[{"batb":[[0,1.07,285.71],[1,1.05,55.37],[2,1.03,200]],"ltp":0.0,"tv":0.0,"id":60443}]}]}
{"op":"mcm","clk":"11873033482","pt":1723935657245,"mc":[{"id":"1.231875523","rc":[{"batb":[[0,1.07,285.71],[1,1.05,55.37],[2,1.03,199]],"ltp":1.03,"tv":2.0,"id":31378}]}]}
{"op":"mcm","clk":"11873037887","pt":1723935720569,"mc":[{"id":"1.231875523","rc":[{"batb":[[0,1.08,106.99],[1,1.07,285.71],[2,1.05,55.37]],"ltp":1.03,"tv":2.0,"id":31378},{"batb":[[0,1.08,106.99],[1,1.07,285.71],[2,1.05,55.37]],"ltp":0.0,"tv":0.0,"id":60443}]}]}
{"op":"mcm","clk":"11873041234","pt":1723935767686,"mc":[{"id":"1.231875523","rc":[{"batb":[[0,1.09,222.22],[1,1.07,44.3],[2,1.03,200]],"ltp":0.0,"tv":0.0,"id":475559}]}]}
{"op":"mcm","clk":"11873045440","pt":1723935829174,"mc":[{"id":"1.231875523","rc":[{"batb":[[0,1.1,85.6],[1,1.09,222.22],[2,1.07,44.3]],"ltp":0.0,"tv":0.0,"id":475559}]}]}
{"op":"mcm","clk":"11873168822","pt":1723937521058,"mc":[{"id":"1.231875523","rc":[{"batb":[[0,1.07,285.71],[1,1.05,55.37],[2,1.03,199]],"ltp":1.03,"tv":2.0,"id":31378},{"batb":[[0,1.07,285.71],[1,1.05,55.37],[2,1.03,200]],"ltp":0.0,"tv":0.0,"id":60443}]}]}
{"op":"mcm","clk":"11873176578","pt":1723937629434,"mc":[{"id":"1.231875523","rc":[{"batb":[[0,1.09,222.22],[1,1.07,44.3],[2,1.03,200]],"ltp":0.0,"tv":0.0,"id":475559}]}]}
{"op":"mcm","clk":"11873177282","pt":1723937639354,"mc":[{"id":"1.231875523","rc":[{"batb":[[0,1.08,106.99],[1,1.07,285.71],[2,1.05,55.37]],"ltp":1.03,"tv":2.0,"id":31378},{"batb":[[0,1.1,85.6],[1,1.09,222.22],[2,1.07,44.3]],"ltp":0.0,"tv":0.0,"id":475559},{"batb":[[0,1.08,106.99],[1,1.07,285.71],[2,1.05,55.37]],"ltp":0.0,"tv":0.0,"id":60443}]}]}
{"op":"mcm","clk":"11873319989","pt":1723939440057,"mc":[{"id":"1.231875523","rc":[{"batb":[[0,1.07,285.71],[1,1.05,55.37],[2,1.03,199]],"ltp":1.03,"tv":2.0,"id":31378},{"batb":[[0,1.09,222.22],[1,1.07,44.3],[2,1.03,200]],"ltp":0.0,"tv":0.0,"id":475559},{"batb":[[0,1.07,285.71],[1,1.05,55.37],[2,1.03,200]],"ltp":0.0,"tv":0.0,"id":60443}]}]}
{"op":"mcm","clk":"11873330316","pt":1723939551812,"mc":[{"id":"1.231875523","rc":[{"batb":[[0,1.08,106.99],[1,1.07,285.71],[2,1.05,55.37]],"ltp":1.03,"tv":2.0,"id":31378},{"batb":[[0,1.1,85.6],[1,1.09,222.22],[2,1.07,44.3]],"ltp":0.0,"tv":0.0,"id":475559},{"batb":[[0,1.08,106.99],[1,1.07,285.71],[2,1.05,55.37]],"ltp":0.0,"tv":0.0,"id":60443}]}]}
{"op":"mcm","clk":"11873499253","pt":1723941352021,"mc":[{"id":"1.231875523","rc":[{"batb":[[0,1.07,285.71],[1,1.05,55.37],[2,1.03,199]],"ltp":1.03,"tv":2.0,"id":31378}]}]}
{"op":"mcm","clk":"11873499271","pt":1723941352326,"mc":[{"id":"1.231875523","rc":[{"batb":[[0,1.09,222.22],[1,1.07,44.3],[2,1.03,200]],"ltp":0.0,"tv":0.0,"id":475559}]}]}
{"op":"mcm","clk":"11873499315","pt":1723941353115,"mc":[{"id":"1.231875523","rc":[{"batb":[[0,1.07,285.71],[1,1.05,55.37],[2,1.03,200]],"ltp":0.0,"tv":0.0,"id":60443}]}]}
{"op":"mcm","clk":"11873507348","pt":1723941455294,"mc":[{"id":"1.231875523","rc":[{"batb":[[0,1.08,106.99],[1,1.07,285.71],[2,1.05,55.37]],"ltp":1.03,"tv":2.0,"id":31378},{"batb":[[0,1.08,106.99],[1,1.07,285.71],[2,1.05,55.37]],"ltp":0.0,"tv":0.0,"id":60443},{"batb":[[0,1.1,85.6],[1,1.09,222.22],[2,1.07,44.3]],"ltp":0.0,"tv":0.0,"id":475559}]}]}
{"op":"mcm","clk":"11873646879","pt":1723943255967,"mc":[{"id":"1.231875523","rc":[{"batb":[[0,1.07,285.71],[1,1.05,55.37],[2,1.03,199]],"ltp":1.03,"tv":2.0,"id":31378},{"batb":[[0,1.07,285.71],[1,1.05,55.37],[2,1.03,200]],"ltp":0.0,"tv":0.0,"id":60443},{"batb":[[0,1.09,222.22],[1,1.07,44.3],[2,1.03,200]],"ltp":0.0,"tv":0.0,"id":475559}]}]}
{"op":"mcm","clk":"11873653508","pt":1723943345981,"mc":[{"id":"1.231875523","rc":[{"batb":[[0,1.08,106.99],[1,1.07,285.71],[2,1.05,55.37]],"ltp":1.03,"tv":2.0,"id":31378},{"batb":[[0,1.08,106.99],[1,1.07,285.71],[2,1.05,55.37]],"ltp":0.0,"tv":0.0,"id":60443},{"batb":[[0,1.1,85.6],[1,1.09,222.22],[2,1.07,44.3]],"ltp":0.0,"tv":0.0,"id":475559}]}]}
{"op":"mcm","clk":"11873800435","pt":1723945146951,"mc":[{"id":"1.231875523","rc":[{"batb":[[0,1.07,285.71],[1,1.05,55.37],[2,1.03,199]],"ltp":1.03,"tv":2.0,"id":31378},{"batb":[[0,1.07,285.71],[1,1.05,55.37],[2,1.03,200]],"ltp":0.0,"tv":0.0,"id":60443}]}]}
{"op":"mcm","clk":"11873800452","pt":1723945147159,"mc":[{"id":"1.231875523","rc":[{"batb":[[0,1.09,222.22],[1,1.07,44.3],[2,1.03,200]],"ltp":0.0,"tv":0.0,"id":475559}]}]}
{"op":"mcm","clk":"11873805809","pt":1723945213752,"mc":[{"id":"1.231875523","rc":[{"batb":[[0,1.08,106.99],[1,1.07,285.71],[2,1.05,55.37]],"ltp":1.03,"tv":2.0,"id":31378},{"batb":[[0,1.08,106.99],[1,1.07,285.71],[2,1.05,55.37]],"ltp":0.0,"tv":0.0,"id":60443},{"batb":[[0,1.1,85.6],[1,1.09,222.22],[2,1.07,44.3]],"ltp":0.0,"tv":0.0,"id":475559}]}]}
{"op":"mcm","clk":"11873947957","pt":1723947014071,"mc":[{"id":"1.231875523","rc":[{"batb":[[0,1.07,285.71],[1,1.05,55.37],[2,1.03,199]],"ltp":1.03,"tv":2.0,"id":31378},{"batb":[[0,1.09,222.22],[1,1.07,44.3],[2,1.03,200]],"ltp":0.0,"tv":0.0,"id":475559}]}]}
{"op":"mcm","clk":"11873947969","pt":1723947014286,"mc":[{"id":"1.231875523","rc":[{"batb":[[0,1.07,285.71],[1,1.05,55.37],[2,1.03,200]],"ltp":0.0,"tv":0.0,"id":60443}]}]}
{"op":"mcm","clk":"11873950350","pt":1723947044803,"mc":[{"id":"1.231875523","rc":[{"batb":[[0,1.08,106.99],[1,1.07,285.71],[2,1.05,55.37]],"ltp":1.03,"tv":2.0,"id":31378},{"batb":[[0,1.1,85.6],[1,1.09,222.22],[2,1.07,44.3]],"ltp":0.0,"tv":0.0,"id":475559},{"batb":[[0,1.08,106.99],[1,1.07,285.71],[2,1.05,55.37]],"ltp":0.0,"tv":0.0,"id":60443}]}]}
{"op":"mcm","clk":"11874099792","pt":1723948845074,"mc":[{"id":"1.231875523","rc":[{"batb":[[0,1.07,285.71],[1,1.05,55.37],[2,1.03,199]],"ltp":1.03,"tv":2.0,"id":31378},{"batb":[[0,1.07,285.71],[1,1.05,55.37],[2,1.03,200]],"ltp":0.0,"tv":0.0,"id":60443}]}]}
{"op":"mcm","clk":"11874099809","pt":1723948845279,"mc":[{"id":"1.231875523","rc":[{"batb":[[0,1.09,222.22],[1,1.07,44.3],[2,1.03,200]],"ltp":0.0,"tv":0.0,"id":475559}]}]}
{"op":"mcm","clk":"11874112765","pt":1723949013821,"mc":[{"id":"1.231875523","rc":[{"batb":[[0,1.08,106.99],[1,1.07,285.71],[2,1.05,55.37]],"ltp":1.03,"tv":2.0,"id":31378},{"batb":[[0,1.1,85.6],[1,1.09,222.22],[2,1.07,44.3]],"ltp":0.0,"tv":0.0,"id":475559},{"batb":[[0,1.08,106.99],[1,1.07,285.71],[2,1.05,55.37]],"ltp":0.0,"tv":0.0,"id":60443}]}]}
{"op":"mcm","clk":"11874235943","pt":1723950813998,"mc":[{"id":"1.231875523","rc":[{"batb":[[0,1.07,285.71],[1,1.05,55.37],[2,1.03,200]],"ltp":0.0,"tv":0.0,"id":60443}]}]}
{"op":"mcm","clk":"11874235973","pt":1723950814408,"mc":[{"id":"1.231875523","rc":[{"batb":[[0,1.07,285.71],[1,1.05,55.37],[2,1.03,199]],"ltp":1.03,"tv":2.0,"id":31378},{"batb":[[0,1.09,222.22],[1,1.07,44.3],[2,1.03,200]],"ltp":0.0,"tv":0.0,"id":475559}]}]}
{"op":"mcm","clk":"11874245123","pt":1723950966638,"mc":[{"id":"1.231875523","rc":[{"batb":[[0,1.08,106.99],[1,1.07,285.71],[2,1.05,55.37]],"ltp":1.03,"tv":2.0,"id":31378},{"batb":[[0,1.1,85.6],[1,1.09,222.22],[2,1.07,44.3]],"ltp":0.0,"tv":0.0,"id":475559},{"batb":[[0,1.08,106.99],[1,1.07,285.71],[2,1.05,55.37]],"ltp":0.0,"tv":0.0,"id":60443}]}]}
{"op":"mcm","clk":"11874344792","pt":1723952767030,"mc":[{"id":"1.231875523","rc":[{"batb":[[0,1.07,285.71],[1,1.05,55.37],[2,1.03,199]],"ltp":1.03,"tv":2.0,"id":31378},{"batb":[[0,1.09,222.22],[1,1.07,44.3],[2,1.03,200]],"ltp":0.0,"tv":0.0,"id":475559}]}]}
{"op":"mcm","clk":"11874344809","pt":1723952767236,"mc":[{"id":"1.231875523","rc":[{"batb":[[0,1.07,285.71],[1,1.05,55.37],[2,1.03,200]],"ltp":0.0,"tv":0.0,"id":60443}]}]}
{"op":"mcm","clk":"11874350964","pt":1723952887773,"mc":[{"id":"1.231875523","rc":[{"batb":[[0,1.08,106.99],[1,1.07,285.71],[2,1.05,55.37]],"ltp":1.03,"tv":2.0,"id":31378},{"batb":[[0,1.1,85.6],[1,1.09,222.22],[2,1.07,44.3]],"ltp":0.0,"tv":0.0,"id":475559},{"batb":[[0,1.08,106.99],[1,1.07,285.71],[2,1.05,55.37]],"ltp":0.0,"tv":0.0,"id":60443}]}]}
{"op":"mcm","clk":"11874448127","pt":1723954687988,"mc":[{"id":"1.231875523","rc":[{"batb":[[0,1.07,285.71],[1,1.05,55.37],[2,1.03,199]],"ltp":1.03,"tv":2.0,"id":31378}]}]}
{"op":"mcm","clk":"11874448172","pt":1723954688807,"mc":[{"id":"1.231875523","rc":[{"batb":[[0,1.09,222.22],[1,1.07,44.3],[2,1.03,200]],"ltp":0.0,"tv":0.0,"id":475559},{"batb":[[0,1.07,285.71],[1,1.05,55.37],[2,1.03,200]],"ltp":0.0,"tv":0.0,"id":60443}]}]}
{"op":"mcm","clk":"11874453591","pt":1723954793633,"mc":[{"id":"1.231875523","rc":[{"batb":[[0,1.08,106.99],[1,1.07,285.71],[2,1.05,55.37]],"ltp":1.03,"tv":2.0,"id":31378},{"batb":[[0,1.1,85.6],[1,1.09,222.22],[2,1.07,44.3]],"ltp":0.0,"tv":0.0,"id":475559},{"batb":[[0,1.08,106.99],[1,1.07,285.71],[2,1.05,55.37]],"ltp":0.0,"tv":0.0,"id":60443}]}]}
{"op":"mcm","clk":"11874537242","pt":1723956593955,"mc":[{"id":"1.231875523","rc":[{"batb":[[0,1.07,285.71],[1,1.05,55.37],[2,1.03,199]],"ltp":1.03,"tv":2.0,"id":31378}]}]}
{"op":"mcm","clk":"11874537266","pt":1723956594363,"mc":[{"id":"1.231875523","rc":[{"batb":[[0,1.07,285.71],[1,1.05,55.37],[2,1.03,200]],"ltp":0.0,"tv":0.0,"id":60443},{"batb":[[0,1.09,222.22],[1,1.07,44.3],[2,1.03,200]],"ltp":0.0,"tv":0.0,"id":475559}]}]}
{"op":"mcm","clk":"11874539763","pt":1723956683746,"mc":[{"id":"1.231875523","rc":[{"batb":[[0,1.08,106.99],[1,1.07,285.71],[2,1.05,55.37]],"ltp":1.03,"tv":2.0,"id":31378},{"batb":[[0,1.08,106.99],[1,1.07,285.71],[2,1.05,55.37]],"ltp":0.0,"tv":0.0,"id":60443},{"batb":[[0,1.1,85.6],[1,1.09,222.22],[2,1.07,44.3]],"ltp":0.0,"tv":0.0,"id":475559}]}]}
{"op":"mcm","clk":"11874568230","pt":1723957564846,"mc":[{"id":"1.231875523","rc":[{"batb":[[0,1.09,55.37],[1,1.08,106.99],[2,1.07,285.71]],"ltp":1.03,"tv":2.0,"id":31378},{"batb":[[0,1.09,55.37],[1,1.08,106.99],[2,1.07,285.71]],"ltp":0.0,"tv":0.0,"id":60443},{"batb":[[0,1.11,44.3],[1,1.1,85.6],[2,1.09,222.22]],"ltp":0.0,"tv":0.0,"id":475559}]}]}
{"op":"mcm","clk":"11874593547","pt":1723958483825,"mc":[{"id":"1.231875523","rc":[{"batb":[[1,1.07,285.71],[2,1.03,199]],"ltp":1.03,"tv":2.0,"id":31378}]}]}
{"op":"mcm","clk":"11874593573","pt":1723958484237,"mc":[{"id":"1.231875523","rc":[{"batb":[[1,1.07,285.71],[2,1.03,200]],"ltp":0.0,"tv":0.0,"id":60443},{"batb":[[1,1.09,222.22],[2,1.03,200]],"ltp":0.0,"tv":0.0,"id":475559}]}]}
{"op":"mcm","clk":"11874596161","pt":1723958568029,"mc":[{"id":"1.231875523","rc":[{"batb":[[0,1.1,85.6],[1,1.09,55.37],[2,1.07,285.71]],"ltp":1.03,"tv":2.0,"id":31378},{"batb":[[0,1.1,85.6],[1,1.09,55.37],[2,1.07,285.71]],"ltp":0.0,"tv":0.0,"id":60443},{"batb":[[0,1.12,71.33],[1,1.11,44.3],[2,1.09,222.22]],"ltp":0.0,"tv":0.0,"id":475559}]}]}
{"op":"mcm","clk":"11874641856","pt":1723960368637,"mc":[{"id":"1.231875523","rc":[{"batb":[[0,1.09,55.37],[1,1.07,285.71],[2,1.03,199]],"ltp":1.03,"tv":2.0,"id":31378},{"batb":[[0,1.09,55.37],[1,1.07,285.71],[2,1.03,200]],"ltp":0.0,"tv":0.0,"id":60443},{"batb":[[0,1.11,44.3],[1,1.09,222.22],[2,1.03,200]],"ltp":0.0,"tv":0.0,"id":475559}]}]}
{"op":"mcm","clk":"11874643200","pt":1723960444163,"mc":[{"id":"1.231875523","rc":[{"batb":[[0,1.1,85.6],[1,1.09,55.37],[2,1.07,285.71]],"ltp":1.03,"tv":2.0,"id":31378},{"batb":[[0,1.1,85.6],[1,1.09,55.37],[2,1.07,285.71]],"ltp":0.0,"tv":0.0,"id":60443},{"batb":[[0,1.12,71.33],[1,1.11,44.3],[2,1.09,222.22]],"ltp":0.0,"tv":0.0,"id":475559}]}]}
{"op":"mcm","clk":"11874692676","pt":1723962244792,"mc":[{"id":"1.231875523","rc":[{"batb":[[0,1.09,55.37],[1,1.07,285.71],[2,1.03,199]],"ltp":1.03,"tv":2.0,"id":31378},{"batb":[[0,1.09,55.37],[1,1.07,285.71],[2,1.03,200]],"ltp":0.0,"tv":0.0,"id":60443},{"batb":[[0,1.11,44.3],[1,1.09,222.22],[2,1.03,200]],"ltp":0.0,"tv":0.0,"id":475559}]}]}
{"op":"mcm","clk":"11874694631","pt":1723962323098,"mc":[{"id":"1.231875523","rc":[{"batb":[[0,1.1,85.6],[1,1.09,55.37],[2,1.07,285.71]],"ltp":1.03,"tv":2.0,"id":31378},{"batb":[[0,1.1,85.6],[1,1.09,55.37],[2,1.07,285.71]],"ltp":0.0,"tv":0.0,"id":60443},{"batb":[[0,1.12,71.33],[1,1.11,44.3],[2,1.09,222.22]],"ltp":0.0,"tv":0.0,"id":475559}]}]}
{"op":"mcm","clk":"11874740106","pt":1723964123855,"mc":[{"id":"1.231875523","rc":[{"batb":[[0,1.09,55.37],[1,1.07,285.71],[2,1.03,199]],"ltp":1.03,"tv":2.0,"id":31378},{"batb":[[0,1.09,55.37],[1,1.07,285.71],[2,1.03,200]],"ltp":0.0,"tv":0.0,"id":60443},{"batb":[[0,1.11,44.3],[1,1.09,222.22],[2,1.03,200]],"ltp":0.0,"tv":0.0,"id":475559}]}]}
{"op":"mcm","clk":"11874741923","pt":1723964193845,"mc":[{"id":"1.231875523","rc":[{"batb":[[0,1.1,85.6],[1,1.09,55.37],[2,1.07,285.71]],"ltp":1.03,"tv":2.0,"id":31378},{"batb":[[0,1.1,85.6],[1,1.09,55.37],[2,1.07,285.71]],"ltp":0.0,"tv":0.0,"id":60443},{"batb":[[0,1.12,71.33],[1,1.11,44.3],[2,1.09,222.22]],"ltp":0.0,"tv":0.0,"id":475559}]}]}
{"op":"mcm","clk":"11874795356","pt":1723965994056,"mc":[{"id":"1.231875523","rc":[{"batb":[[0,1.09,55.37],[1,1.07,285.71],[2,1.03,199]],"ltp":1.03,"tv":2.0,"id":31378}]}]}
{"op":"mcm","clk":"11874795368","pt":1723965994359,"mc":[{"id":"1.231875523","rc":[{"batb":[[0,1.09,55.37],[1,1.07,285.71],[2,1.03,200]],"ltp":0.0,"tv":0.0,"id":60443},{"batb":[[0,1.11,44.3],[1,1.09,222.22],[2,1.03,200]],"ltp":0.0,"tv":0.0,"id":475559}]}]}
{"op":"mcm","clk":"11874797935","pt":1723966067120,"mc":[{"id":"1.231875523","rc":[{"batb":[[0,1.1,85.6],[1,1.09,55.37],[2,1.07,285.71]],"ltp":1.03,"tv":2.0,"id":31378},{"batb":[[0,1.1,85.6],[1,1.09,55.37],[2,1.07,285.71]],"ltp":0.0,"tv":0.0,"id":60443},{"batb":[[0,1.12,71.33],[1,1.11,44.3],[2,1.09,222.22]],"ltp":0.0,"tv":0.0,"id":475559}]}]}
{"op":"mcm","clk":"11874870228","pt":1723967867557,"mc":[{"id":"1.231875523","rc":[{"batb":[[0,1.09,55.37],[1,1.07,285.71],[2,1.03,199]],"ltp":1.03,"tv":2.0,"id":31378},{"batb":[[0,1.11,44.3],[1,1.09,222.22],[2,1.03,200]],"ltp":0.0,"tv":0.0,"id":475559},{"batb":[[0,1.09,55.37],[1,1.07,285.71],[2,1.03,200]],"ltp":0.0,"tv":0.0,"id":60443}]}]}
{"op":"mcm","clk":"11874876802","pt":1723968022629,"mc":[{"id":"1.231875523","rc":[{"batb":[[0,1.1,85.6],[1,1.09,55.37],[2,1.07,285.71]],"ltp":1.03,"tv":2.0,"id":31378},{"batb":[[0,1.12,71.33],[1,1.11,44.3],[2,1.09,222.22]],"ltp":0.0,"tv":0.0,"id":475559},{"batb":[[0,1.1,85.6],[1,1.09,55.37],[2,1.07,285.71]],"ltp":0.0,"tv":0.0,"id":60443}]}]}
{"op":"mcm","clk":"11874956305","pt":1723969355034,"mc":[{"id":"1.231875523","rc":[{"batb":[[0,1.11,55.37],[1,1.1,85.6]],"ltp":1.03,"tv":2.0,"id":31378},{"batb":[[0,1.13,44.3],[1,1.12,71.33]],"ltp":0.0,"tv":0.0,"id":475559},{"batb":[[0,1.11,55.37],[1,1.1,85.6]],"ltp":0.0,"tv":0.0,"id":60443}]}]}
{"op":"mcm","clk":"11874986516","pt":1723969822998,"mc":[{"id":"1.231875523","rc":[{"batb":[[1,1.07,285.71],[2,1.03,199]],"ltp":1.03,"tv":2.0,"id":31378},{"batb":[[1,1.07,285.71],[2,1.03,200]],"ltp":0.0,"tv":0.0,"id":60443}]}]}
{"op":"mcm","clk":"11874986529","pt":1723969823203,"mc":[{"id":"1.231875523","rc":[{"batb":[[1,1.09,222.22],[2,1.03,200]],"ltp":0.0,"tv":0.0,"id":475559}]}]}
{"op":"mcm","clk":"11874987506","pt":1723969839211,"mc":[{"id":"1.231875523","rc":[{"batb":[[0,1.12,71.33],[1,1.11,55.37],[2,1.07,285.71]],"ltp":1.03,"tv":2.0,"id":31378},{"batb":[[0,1.14,61.14],[1,1.13,44.3],[2,1.09,222.22]],"ltp":0.0,"tv":0.0,"id":475559},{"batb":[[0,1.12,71.33],[1,1.11,55.37],[2,1.07,285.71]],"ltp":0.0,"tv":0.0,"id":60443}]}]}
{"op":"mcm","clk":"11875110385","pt":1723971639811,"mc":[{"id":"1.231875523","rc":[{"batb":[[0,1.11,55.37],[1,1.07,285.71],[2,1.03,199]],"ltp":1.03,"tv":2.0,"id":31378},{"batb":[[0,1.13,44.3],[1,1.09,222.22],[2,1.03,200]],"ltp":0.0,"tv":0.0,"id":475559},{"batb":[[0,1.11,55.37],[1,1.07,285.71],[2,1.03,200]],"ltp":0.0,"tv":0.0,"id":60443}]}]}
{"op":"mcm","clk":"11875111780","pt":1723971653631,"mc":[{"id":"1.231875523","rc":[{"batb":[[0,1.12,71.33],[1,1.11,55.37],[2,1.07,285.71]],"ltp":1.03,"tv":2.0,"id":31378},{"batb":[[0,1.14,61.14],[1,1.13,44.3],[2,1.09,222.22]],"ltp":0.0,"tv":0.0,"id":475559},{"batb":[[0,1.12,71.33],[1,1.11,55.37],[2,1.07,285.71]],"ltp":0.0,"tv":0.0,"id":60443}]}]}
{"op":"mcm","clk":"11875274639","pt":1723973454076,"mc":[{"id":"1.231875523","rc":[{"batb":[[0,1.11,55.37],[1,1.07,285.71],[2,1.03,200]],"ltp":0.0,"tv":0.0,"id":60443},{"batb":[[0,1.13,44.3],[1,1.09,222.22],[2,1.03,200]],"ltp":0.0,"tv":0.0,"id":475559}]}]}
{"op":"mcm","clk":"11875274655","pt":1723973454281,"mc":[{"id":"1.231875523","rc":[{"batb":[[0,1.11,55.37],[1,1.07,285.71],[2,1.03,199]],"ltp":1.03,"tv":2.0,"id":31378}]}]}
{"op":"mcm","clk":"11875275066","pt":1723973459570,"mc":[{"id":"1.231875523","rc":[{"batb":[[0,1.12,71.33],[1,1.11,55.37],[2,1.07,285.71]],"ltp":1.03,"tv":2.0,"id":31378},{"batb":[[0,1.12,71.33],[1,1.11,55.37],[2,1.07,285.71]],"ltp":0.0,"tv":0.0,"id":60443},{"batb":[[0,1.14,61.14],[1,1.13,44.3],[2,1.09,222.22]],"ltp":0.0,"tv":0.0,"id":475559}]}]}
{"op":"mcm","clk":"11875293896","pt":1723973660223,"mc":[{"id":"1.231875523","rc":[{"batb":[[0,1.5,20],[1,1.12,71.33],[2,1.11,55.37]],"ltp":1.03,"tv":2.0,"id":31378}]}]}
{"op":"mcm","clk":"11875294725","pt":1723973669515,"mc":[{"id":"1.231875523","rc":[{"batb":[[0,1.5,20],[1,1.14,61.14],[2,1.13,44.3]],"ltp":0.0,"tv":0.0,"id":475559}]}]}
{"op":"mcm","clk":"11875295475","pt":1723973677908,"mc":[{"id":"1.231875523","rc":[{"batb":[[0,1.3,20],[1,1.12,71.33],[2,1.11,55.37]],"ltp":0.0,"tv":0.0,"id":60443}]}]}
{"op":"mcm","clk":"11875427686","pt":1723975259988,"mc":[{"id":"1.231875523","rc":[{"batb":[[1,1.11,55.37],[2,1.07,285.71]],"ltp":1.03,"tv":2.0,"id":31378},{"batb":[[1,1.11,55.37],[2,1.07,285.71]],"ltp":0.0,"tv":0.0,"id":60443},{"batb":[[1,1.13,44.3],[2,1.09,222.22]],"ltp":0.0,"tv":0.0,"id":475559}]}]}
{"op":"mcm","clk":"11875441425","pt":1723975435321,"mc":[{"id":"1.231875523","rc":[{"batb":[[0,1.51,16.78],[1,1.5,20],[2,1.11,55.37]],"ltp":1.03,"tv":2.0,"id":31378},{"batb":[[0,1.31,27.61],[1,1.3,20],[2,1.11,55.37]],"ltp":0.0,"tv":0.0,"id":60443},{"batb":[[0,1.51,16.78],[1,1.5,20],[2,1.13,44.3]],"ltp":0.0,"tv":0.0,"id":475559}]}]}
{"op":"mcm","clk":"11875615186","pt":1723977235778,"mc":[{"id":"1.231875523","rc":[{"batb":[[0,1.5,20],[1,1.11,55.37],[2,1.07,285.71]],"ltp":1.03,"tv":2.0,"id":31378},{"batb":[[0,1.3,20],[1,1.11,55.37],[2,1.07,285.71]],"ltp":0.0,"tv":0.0,"id":60443},{"batb":[[0,1.5,20],[1,1.13,44.3],[2,1.09,222.22]],"ltp":0.0,"tv":0.0,"id":475559}]}]}
{"op":"mcm","clk":"11875630426","pt":1723977387347,"mc":[{"id":"1.231875523","rc":[{"batb":[[0,1.51,16.78],[1,1.5,20],[2,1.11,55.37]],"ltp":1.03,"tv":2.0,"id":31378},{"batb":[[0,1.31,27.61],[1,1.3,20],[2,1.11,55.37]],"ltp":0.0,"tv":0.0,"id":60443},{"batb":[[0,1.51,16.78],[1,1.5,20],[2,1.13,44.3]],"ltp":0.0,"tv":0.0,"id":475559}]}]}
{"op":"mcm","clk":"11875797633","pt":1723979187730,"mc":[{"id":"1.231875523","rc":[{"batb":[[0,1.5,20],[1,1.11,55.37],[2,1.07,285.71]],"ltp":1.03,"tv":2.0,"id":31378},{"batb":[[0,1.5,20],[1,1.13,44.3],[2,1.09,222.22]],"ltp":0.0,"tv":0.0,"id":475559},{"batb":[[0,1.3,20],[1,1.11,55.37],[2,1.07,285.71]],"ltp":0.0,"tv":0.0,"id":60443}]}]}
{"op":"mcm","clk":"11875808767","pt":1723979317105,"mc":[{"id":"1.231875523","rc":[{"batb":[[0,1.51,16.78],[1,1.5,20],[2,1.11,55.37]],"ltp":1.03,"tv":2.0,"id":31378},{"batb":[[0,1.51,16.78],[1,1.5,20],[2,1.13,44.3]],"ltp":0.0,"tv":0.0,"id":475559},{"batb":[[0,1.31,27.61],[1,1.3,20],[2,1.11,55.37]],"ltp":0.0,"tv":0.0,"id":60443}]}]}
{"op":"mcm","clk":"11875992356","pt":1723981117721,"mc":[{"id":"1.231875523","rc":[{"batb":[[0,1.5,20],[1,1.11,55.37],[2,1.07,285.71]],"ltp":1.03,"tv":2.0,"id":31378},{"batb":[[0,1.5,20],[1,1.13,44.3],[2,1.09,222.22]],"ltp":0.0,"tv":0.0,"id":475559},{"batb":[[0,1.3,20],[1,1.11,55.37],[2,1.07,285.71]],"ltp":0.0,"tv":0.0,"id":60443}]}]}
{"op":"mcm","clk":"11876004321","pt":1723981209942,"mc":[{"id":"1.231875523","rc":[{"batb":[[0,1.51,16.78],[1,1.5,20],[2,1.11,55.37]],"ltp":1.03,"tv":2.0,"id":31378},{"batb":[[0,1.51,16.78],[1,1.5,20],[2,1.13,44.3]],"ltp":0.0,"tv":0.0,"id":475559},{"batb":[[0,1.31,27.61],[1,1.3,20],[2,1.11,55.37]],"ltp":0.0,"tv":0.0,"id":60443}]}]}
{"op":"mcm","clk":"11876198574","pt":1723983010517,"mc":[{"id":"1.231875523","rc":[{"batb":[[0,1.5,20],[1,1.11,55.37],[2,1.07,285.71]],"ltp":1.03,"tv":2.0,"id":31378},{"batb":[[0,1.5,20],[1,1.13,44.3],[2,1.09,222.22]],"ltp":0.0,"tv":0.0,"id":475559},{"batb":[[0,1.3,20],[1,1.11,55.37],[2,1.07,285.71]],"ltp":0.0,"tv":0.0,"id":60443}]}]}
{"op":"mcm","clk":"11876207259","pt":1723983087846,"mc":[{"id":"1.231875523","rc":[{"batb":[[0,1.51,16.78],[1,1.5,20],[2,1.11,55.37]],"ltp":1.03,"tv":2.0,"id":31378},{"batb":[[0,1.51,16.78],[1,1.5,20],[2,1.13,44.3]],"ltp":0.0,"tv":0.0,"id":475559},{"batb":[[0,1.31,27.61],[1,1.3,20],[2,1.11,55.37]],"ltp":0.0,"tv":0.0,"id":60443}]}]}
{"op":"mcm","clk":"11876432403","pt":1723984888016,"mc":[{"id":"1.231875523","rc":[{"batb":[[0,1.5,20],[1,1.11,55.37],[2,1.07,285.71]],"ltp":1.03,"tv":2.0,"id":31378}]}]}
{"op":"mcm","clk":"11876432440","pt":1723984888436,"mc":[{"id":"1.231875523","rc":[{"batb":[[0,1.5,20],[1,1.13,44.3],[2,1.09,222.22]],"ltp":0.0,"tv":0.0,"id":475559},{"batb":[[0,1.3,20],[1,1.11,55.37],[2,1.07,285.71]],"ltp":0.0,"tv":0.0,"id":60443}]}]}
{"op":"mcm","clk":"11876439735","pt":1723984942481,"mc":[{"id":"1.231875523","rc":[{"batb":[[0,1.51,16.78],[1,1.5,20],[2,1.11,55.37]],"ltp":1.03,"tv":2.0,"id":31378},{"batb":[[0,1.51,16.78],[1,1.5,20],[2,1.13,44.3]],"ltp":0.0,"tv":0.0,"id":475559},{"batb":[[0,1.31,27.61],[1,1.3,20],[2,1.11,55.37]],"ltp":0.0,"tv":0.0,"id":60443}]}]}
{"op":"mcm","clk":"11876708013","pt":1723986743043,"mc":[{"id":"1.231875523","rc":[{"batb":[[0,1.5,20],[1,1.11,55.37],[2,1.07,285.71]],"ltp":1.03,"tv":2.0,"id":31378},{"batb":[[0,1.5,20],[1,1.13,44.3],[2,1.09,222.22]],"ltp":0.0,"tv":0.0,"id":475559},{"batb":[[0,1.3,20],[1,1.11,55.37],[2,1.07,285.71]],"ltp":0.0,"tv":0.0,"id":60443}]}]}
{"op":"mcm","clk":"11876712244","pt":1723986767395,"mc":[{"id":"1.231875523","rc":[{"batb":[[0,1.51,16.78],[1,1.5,20],[2,1.11,55.37]],"ltp":1.03,"tv":2.0,"id":31378},{"batb":[[0,1.51,16.78],[1,1.5,20],[2,1.13,44.3]],"ltp":0.0,"tv":0.0,"id":475559},{"batb":[[0,1.31,27.61],[1,1.3,20],[2,1.11,55.37]],"ltp":0.0,"tv":0.0,"id":60443}]}]}
{"op":"mcm","clk":"11876983242","pt":1723988472465,"mc":[{"id":"1.231875523","rc":[{"batb":[[2,1.07,285.71]],"ltp":1.03,"tv":2.0,"id":31378},{"batb":[[2,1.09,222.22]],"ltp":0.0,"tv":0.0,"id":475559},{"batb":[[0,1.32,55.37],[1,1.31,27.61],[2,1.3,20]],"ltp":0.0,"tv":0.0,"id":60443}]}]}
{"op":"mcm","clk":"11876998055","pt":1723988567970,"mc":[{"id":"1.231875523","rc":[{"batb":[[0,1.5,20],[1,1.07,285.71],[2,1.03,199]],"ltp":1.03,"tv":2.0,"id":31378},{"batb":[[0,1.5,20],[1,1.09,222.22],[2,1.03,200]],"ltp":0.0,"tv":0.0,"id":475559},{"batb":[[1,1.3,20],[2,1.07,285.71]],"ltp":0.0,"tv":0.0,"id":60443}]}]}
{"op":"mcm","clk":"11877036039","pt":1723988714845,"mc":[{"id":"1.231875523","rc":[{"batb":[[0,1.51,16.78],[1,1.5,20],[2,1.07,285.71]],"ltp":1.03,"tv":2.0,"id":31378},{"batb":[[0,1.33,25.94],[1,1.32,55.37],[2,1.3,20]],"ltp":0.0,"tv":0.0,"id":60443},{"batb":[[0,1.51,16.78],[1,1.5,20],[2,1.09,222.22]],"ltp":0.0,"tv":0.0,"id":475559}]}]}
{"op":"mcm","clk":"11877335192","pt":1723990514996,"mc":[{"id":"1.231875523","rc":[{"batb":[[0,1.5,20],[1,1.07,285.71],[2,1.03,199]],"ltp":1.03,"tv":2.0,"id":31378}]}]}
{"op":"mcm","clk":"11877335270","pt":1723990515367,"mc":[{"id":"1.231875523","rc":[{"batb":[[0,1.32,55.37],[1,1.3,20],[2,1.07,285.71]],"ltp":0.0,"tv":0.0,"id":60443},{"batb":[[0,1.5,20],[1,1.09,222.22],[2,1.03,200]],"ltp":0.0,"tv":0.0,"id":475559}]}]}
{"op":"mcm","clk":"11877354651","pt":1723990621336,"mc":[{"id":"1.231875523","rc":[{"batb":[[0,1.51,16.78],[1,1.5,20],[2,1.07,285.71]],"ltp":1.03,"tv":2.0,"id":31378},{"batb":[[0,1.33,25.94],[1,1.32,55.37],[2,1.3,20]],"ltp":0.0,"tv":0.0,"id":60443},{"batb":[[0,1.51,16.78],[1,1.5,20],[2,1.09,222.22]],"ltp":0.0,"tv":0.0,"id":475559}]}]}
{"op":"mcm","clk":"11877423341","pt":1723991006325,"mc":[{"id":"1.231875523","rc":[{"batb":[[0,1.34,7.16],[1,1.33,25.94],[2,1.32,55.37]],"ltp":0.0,"tv":0.0,"id":60443}]}]}
{"op":"mcm","clk":"11877651379","pt":1723992421914,"mc":[{"id":"1.231875523","rc":[{"batb":[[0,1.5,20],[1,1.07,285.71],[2,1.03,199]],"ltp":1.03,"tv":2.0,"id":31378},{"batb":[[1,1.32,55.37],[2,1.3,20]],"ltp":0.0,"tv":0.0,"id":60443},{"batb":[[0,1.5,20],[1,1.09,222.22],[2,1.03,200]],"ltp":0.0,"tv":0.0,"id":475559}]}]}
{"op":"mcm","clk":"11877667241","pt":1723992529910,"mc":[{"id":"1.231875523","rc":[{"batb":[[0,1.51,16.78],[1,1.5,20],[2,1.07,285.71]],"ltp":1.03,"tv":2.0,"id":31378},{"batb":[[0,1.35,24.46],[1,1.34,7.16],[2,1.32,55.37]],"ltp":0.0,"tv":0.0,"id":60443},{"batb":[[0,1.51,16.78],[1,1.5,20],[2,1.09,222.22]],"ltp":0.0,"tv":0.0,"id":475559}]}]}
{"op":"mcm","clk":"11877787534","pt":1723993505475,"mc":[{"id":"1.231875523","rc":[{"batb":[[1,1.33,7.16]],"ltp":0.0,"tv":0.0,"id":60443}]}]}
{"op":"mcm","clk":"11877929722","pt":1723994330366,"mc":[{"id":"1.231875523","rc":[{"batb":[[0,1.5,20],[1,1.07,285.71],[2,1.03,199]],"ltp":1.03,"tv":2.0,"id":31378},{"batb":[[0,1.33,7.16],[1,1.32,55.37],[2,1.3,20]],"ltp":0.0,"tv":0.0,"id":60443}]}]}
{"op":"mcm","clk":"11877929850","pt":1723994331261,"mc":[{"id":"1.231875523","rc":[{"batb":[[0,1.5,20],[1,1.09,222.22],[2,1.03,200]],"ltp":0.0,"tv":0.0,"id":475559}]}]}
{"op":"mcm","clk":"11877942721","pt":1723994414686,"mc":[{"id":"1.231875523","rc":[{"batb":[[0,1.51,16.78],[1,1.5,20],[2,1.07,285.71]],"ltp":1.03,"tv":2.0,"id":31378},{"batb":[[0,1.34,25.18],[1,1.33,7.16],[2,1.32,55.37]],"ltp":0.0,"tv":0.0,"id":60443},{"batb":[[0,1.51,16.78],[1,1.5,20],[2,1.09,222.22]],"ltp":0.0,"tv":0.0,"id":475559}]}]}
{"op":"mcm","clk":"11878187008","pt":1723995955082,"mc":[{"id":"1.231875523","rc":[{"batb":[[0,1.35,7.16],[1,1.34,25.18]],"ltp":0.0,"tv":0.0,"id":60443}]}]}
{"op":"mcm","clk":"11878223801","pt":1723996214798,"mc":[{"id":"1.231875523","rc":[{"batb":[[0,1.5,20],[1,1.07,285.71],[2,1.03,199]],"ltp":1.03,"tv":2.0,"id":31378}]}]}
{"op":"mcm","clk":"11878223883","pt":1723996215269,"mc":[{"id":"1.231875523","rc":[{"batb":[[1,1.32,55.37],[2,1.3,20]],"ltp":0.0,"tv":0.0,"id":60443},{"batb":[[0,1.5,20],[1,1.09,222.22],[2,1.03,200]],"ltp":0.0,"tv":0.0,"id":475559}]}]}
{"op":"mcm","clk":"11878233405","pt":1723996289338,"mc":[{"id":"1.231875523","rc":[{"batb":[[0,1.51,16.78],[1,1.5,20],[2,1.07,285.71]],"ltp":1.03,"tv":2.0,"id":31378},{"batb":[[0,1.36,23.78],[1,1.35,7.16],[2,1.32,55.37]],"ltp":0.0,"tv":0.0,"id":60443},{"batb":[[0,1.51,16.78],[1,1.5,20],[2,1.09,222.22]],"ltp":0.0,"tv":0.0,"id":475559}]}]}
{"op":"mcm","clk":"11878463882","pt":1723998089808,"mc":[{"id":"1.231875523","rc":[{"batb":[[0,1.5,20],[1,1.07,285.71],[2,1.03,199]],"ltp":1.03,"tv":2.0,"id":31378},{"batb":[[0,1.35,7.16],[1,1.32,55.37],[2,1.3,20]],"ltp":0.0,"tv":0.0,"id":60443}]}]}
{"op":"mcm","clk":"11878463912","pt":1723998090122,"mc":[{"id":"1.231875523","rc":[{"batb":[[0,1.5,20],[1,1.09,222.22],[2,1.03,200]],"ltp":0.0,"tv":0.0,"id":475559}]}]}
{"op":"mcm","clk":"11878466009","pt":1723998110934,"mc":[{"id":"1.231875523","rc":[{"batb":[[0,1.51,16.78],[1,1.5,20],[2,1.07,285.71]],"ltp":1.03,"tv":2.0,"id":31378},{"batb":[[0,1.51,16.78],[1,1.5,20],[2,1.09,222.22]],"ltp":0.0,"tv":0.0,"id":475559}]}]}
{"op":"mcm","clk":"11878466035","pt":1723998111142,"mc":[{"id":"1.231875523","rc":[{"batb":[[0,1.36,23.78],[1,1.35,7.16],[2,1.32,55.37]],"ltp":0.0,"tv":0.0,"id":60443}]}]}
{"op":"mcm","clk":"11878491584","pt":1723998352507,"mc":[{"id":"1.231875523","rc":[{"batb":[[1,1.33,7.16]],"ltp":0.0,"tv":0.0,"id":60443}]}]}
{"op":"mcm","clk":"11878713842","pt":1723999911327,"mc":[{"id":"1.231875523","rc":[{"batb":[[0,1.5,20],[1,1.07,285.71],[2,1.03,199]],"ltp":1.03,"tv":2.0,"id":31378},{"batb":[[0,1.5,20],[1,1.09,222.22],[2,1.03,200]],"ltp":0.0,"tv":0.0,"id":475559}]}]}
{"op":"mcm","clk":"11878713990","pt":1723999912333,"mc":[{"id":"1.231875523","rc":[{"batb":[[0,1.33,7.16],[1,1.32,55.37],[2,1.3,20]],"ltp":0.0,"tv":0.0,"id":60443}]}]}
{"op":"mcm","clk":"11878734228","pt":1724000043463,"mc":[{"id":"1.231875523","rc":[{"batb":[[0,1.51,16.78],[1,1.5,20],[2,1.07,285.71]],"ltp":1.03,"tv":2.0,"id":31378},{"batb":[[0,1.34,25.18],[1,1.33,7.16],[2,1.32,55.37]],"ltp":0.0,"tv":0.0,"id":60443},{"batb":[[0,1.51,16.78],[1,1.5,20],[2,1.09,222.22]],"ltp":0.0,"tv":0.0,"id":475559}]}]}
{"op":"mcm","clk":"11878830140","pt":1724000737020,"mc":[{"id":"1.231875523","rc":[{"batb":[[0,1.35,7.16],[1,1.34,25.18]],"ltp":0.0,"tv":0.0,"id":60443}]}]}
{"op":"mcm","clk":"11879012288","pt":1724001843901,"mc":[{"id":"1.231875523","rc":[{"batb":[[0,1.5,20],[1,1.07,285.71],[2,1.03,199]],"ltp":1.03,"tv":2.0,"id":31378},{"batb":[[0,1.5,20],[1,1.09,222.22],[2,1.03,200]],"ltp":0.0,"tv":0.0,"id":475559}]}]}
{"op":"mcm","clk":"11879012403","pt":1724001844590,"mc":[{"id":"1.231875523","rc":[{"batb":[[1,1.32,55.37],[2,1.3,20]],"ltp":0.0,"tv":0.0,"id":60443}]}]}
{"op":"mcm","clk":"11879015630","pt":1724001866438,"mc":[{"id":"1.231875523","rc":[{"batb":[[0,1.51,16.78],[1,1.5,20],[2,1.07,285.71]],"ltp":1.03,"tv":2.0,"id":31378},{"batb":[[0,1.36,23.78],[1,1.35,7.16],[2,1.32,55.37]],"ltp":0.0,"tv":0.0,"id":60443},{"batb":[[0,1.51,16.78],[1,1.5,20],[2,1.09,222.22]],"ltp":0.0,"tv":0.0,"id":475559}]}]}
{"op":"mcm","clk":"11879091409","pt":1724002349517,"mc":[{"id":"1.231875523","rc":[{"batb":[[0,1.5,1.79],[1,1.36,23.78],[2,1.35,7.16]],"ltp":0.0,"tv":0.0,"id":60443}]}]}
{"op":"mcm","clk":"11879195923","pt":1724003035294,"mc":[{"id":"1.231875523","rc":[{"batb":[[2,1.33,7.16]],"ltp":0.0,"tv":0.0,"id":60443}]}]}
{"op":"mcm","clk":"11879288593","pt":1724003666940,"mc":[{"id":"1.231875523","rc":[{"batb":[[0,1.5,20],[1,1.07,285.71],[2,1.03,199]],"ltp":1.03,"tv":2.0,"id":31378},{"batb":[[0,1.5,20],[1,1.09,222.22],[2,1.03,200]],"ltp":0.0,"tv":0.0,"id":475559}]}]}
{"op":"mcm","clk":"11879288631","pt":1724003667243,"mc":[{"id":"1.231875523","rc":[{"batb":[[1,1.33,7.16],[2,1.32,55.37]],"ltp":0.0,"tv":0.0,"id":60443}]}]}
{"op":"mcm","clk":"11879301407","pt":1724003757838,"mc":[{"id":"1.231875523","rc":[{"batb":[[0,1.51,16.78],[1,1.5,20],[2,1.07,285.71]],"ltp":1.03,"tv":2.0,"id":31378},{"batb":[[0,1.51,16.78],[1,1.5,1.79],[2,1.33,7.16]],"ltp":0.0,"tv":0.0,"id":60443},{"batb":[[0,1.51,16.78],[1,1.5,20],[2,1.09,222.22]],"ltp":0.0,"tv":0.0,"id":475559}]}]}
{"op":"mcm","clk":"11879528882","pt":1724005033029,"mc":[{"id":"1.231875523","rc":[{"batb":[[2,1.32,55.37]],"ltp":0.0,"tv":0.0,"id":60443}]}]}
{"op":"mcm","clk":"11879634040","pt":1724005557990,"mc":[{"id":"1.231875523","rc":[{"batb":[[0,1.5,1.79],[1,1.32,55.37],[2,1.3,20]],"ltp":0.0,"tv":0.0,"id":60443}]}]}
{"op":"mcm","clk":"11879634114","pt":1724005558360,"mc":[{"id":"1.231875523","rc":[{"batb":[[0,1.5,20],[1,1.07,285.71],[2,1.03,199]],"ltp":1.03,"tv":2.0,"id":31378},{"batb":[[0,1.5,20],[1,1.09,222.22],[2,1.03,200]],"ltp":0.0,"tv":0.0,"id":475559}]}]}
{"op":"mcm","clk":"11879636150","pt":1724005568594,"mc":[{"id":"1.231875523","rc":[{"batb":[[0,1.51,16.78],[1,1.5,20],[2,1.07,285.71]],"ltp":1.03,"tv":2.0,"id":31378},{"batb":[[0,1.51,16.78],[1,1.5,20],[2,1.09,222.22]],"ltp":0.0,"tv":0.0,"id":475559},{"batb":[[0,1.51,16.78],[1,1.5,1.79],[2,1.32,55.37]],"ltp":0.0,"tv":0.0,"id":60443}]}]}
{"op":"mcm","clk":"11879991032","pt":1724007369011,"mc":[{"id":"1.231875523","rc":[{"batb":[[0,1.5,20],[1,1.07,285.71],[2,1.03,199]],"ltp":1.03,"tv":2.0,"id":31378},{"batb":[[0,1.5,20],[1,1.09,222.22],[2,1.03,200]],"ltp":0.0,"tv":0.0,"id":475559}]}]}
{"op":"mcm","clk":"11879991168","pt":1724007369800,"mc":[{"id":"1.231875523","rc":[{"batb":[[0,1.5,1.79],[1,1.32,55.37],[2,1.3,20]],"ltp":0.0,"tv":0.0,"id":60443}]}]}
{"op":"mcm","clk":"11880000175","pt":1724007426489,"mc":[{"id":"1.231875523","rc":[{"batb":[[0,1.51,16.78],[1,1.5,20],[2,1.07,285.71]],"ltp":1.03,"tv":2.0,"id":31378},{"batb":[[0,1.51,16.78],[1,1.5,20],[2,1.09,222.22]],"ltp":0.0,"tv":0.0,"id":475559},{"batb":[[0,1.51,16.78],[1,1.5,1.79],[2,1.32,55.37]],"ltp":0.0,"tv":0.0,"id":60443}]}]}
{"op":"mcm","clk":"11880191033","pt":1724008436531,"mc":[{"id":"1.231875523","rc":[{"batb":[[2,1.03,199]],"ltp":1.03,"tv":2.0,"id":31378}]}]}
{"op":"mcm","clk":"11880191345","pt":1724008438215,"mc":[{"id":"1.231875523","rc":[{"batb":[[2,1.09,222.22]],"ltp":1.03,"tv":2.0,"id":31378}]}]}
{"op":"mcm","clk":"11880341661","pt":1724009226959,"mc":[{"id":"1.231875523","rc":[{"batb":[[0,1.5,20],[1,1.09,222.22],[2,1.03,199]],"ltp":1.03,"tv":2.0,"id":31378},{"batb":[[0,1.5,20],[1,1.09,222.22],[2,1.03,200]],"ltp":0.0,"tv":0.0,"id":475559}]}]}
{"op":"mcm","clk":"11880341800","pt":1724009227687,"mc":[{"id":"1.231875523","rc":[{"batb":[[0,1.5,1.79],[1,1.32,55.37],[2,1.3,20]],"ltp":0.0,"tv":0.0,"id":60443}]}]}
{"op":"mcm","clk":"11880359102","pt":1724009320611,"mc":[{"id":"1.231875523","rc":[{"batb":[[0,1.51,16.78],[1,1.5,20],[2,1.09,222.22]],"ltp":1.03,"tv":2.0,"id":31378},{"batb":[[0,1.51,16.78],[1,1.5,20],[2,1.09,222.22]],"ltp":0.0,"tv":0.0,"id":475559},{"batb":[[0,1.51,16.78],[1,1.5,1.79],[2,1.32,55.37]],"ltp":0.0,"tv":0.0,"id":60443}]}]}
{"op":"mcm","clk":"11880723911","pt":1724011121036,"mc":[{"id":"1.231875523","rc":[{"batb":[[0,1.5,20],[1,1.09,222.22],[2,1.03,199]],"ltp":1.03,"tv":2.0,"id":31378},{"batb":[[0,1.5,20],[1,1.09,222.22],[2,1.03,200]],"ltp":0.0,"tv":0.0,"id":475559},{"batb":[[0,1.5,1.79],[1,1.32,55.37],[2,1.3,20]],"ltp":0.0,"tv":0.0,"id":60443}]}]}
{"op":"mcm","clk":"11880731775","pt":1724011169213,"mc":[{"id":"1.231875523","rc":[{"batb":[[0,1.51,16.78],[1,1.5,20],[2,1.09,222.22]],"ltp":1.03,"tv":2.0,"id":31378},{"batb":[[0,1.51,16.78],[1,1.5,20],[2,1.09,222.22]],"ltp":0.0,"tv":0.0,"id":475559},{"batb":[[0,1.51,16.78],[1,1.5,1.79],[2,1.32,55.37]],"ltp":0.0,"tv":0.0,"id":60443}]}]}
{"op":"mcm","clk":"11880989072","pt":1724012969676,"mc":[{"id":"1.231875523","rc":[{"batb":[[0,1.5,20],[1,1.09,222.22],[2,1.03,199]],"batl":[[0,95,5.85]],"ltp":1.03,"tv":2.0,"id":31378},{"batb":[[0,1.5,20],[1,1.09,222.22],[2,1.03,200]],"batl":[[0,95,5.85]],"ltp":0.0,"tv":0.0,"id":475559},{"batb":[[0,1.51,16.81],[2,1.32,55.44]],"batl":[[0,95,5.85]],"ltp":0.0,"tv":0.0,"id":60443}]}]}
{"op":"mcm","clk":"11880989169","pt":1724012970631,"mc":[{"id":"1.231875523","rc":[{"batb":[[0,1.5,1.79],[1,1.32,55.44],[2,1.3,20]],"ltp":0.0,"tv":0.0,"id":60443}]}]}
{"op":"mcm","clk":"11880995035","pt":1724013020845,"mc":[{"id":"1.231875523","rc":[{"batb":[[0,1.51,16.81],[1,1.5,20],[2,1.09,222.22]],"ltp":1.03,"tv":2.0,"id":31378},{"batb":[[0,1.51,16.81],[1,1.5,20],[2,1.09,222.22]],"ltp":0.0,"tv":0.0,"id":475559},{"batb":[[0,1.51,16.81],[1,1.5,1.79],[2,1.32,55.44]],"ltp":0.0,"tv":0.0,"id":60443}]}]}
{"op":"mcm","clk":"11881186454","pt":1724014820944,"mc":[{"id":"1.231875523","rc":[{"batb":[[0,1.51,16.8]],"ltp":1.03,"tv":2.0,"id":31378},{"batb":[[0,1.51,16.8]],"ltp":0.0,"tv":0.0,"id":475559},{"batb":[[0,1.5,1.8],[1,1.32,55.41],[2,1.3,20]],"ltp":0.0,"tv":0.0,"id":60443}]}]}
{"op":"mcm","clk":"11881186493","pt":1724014821458,"mc":[{"id":"1.231875523","rc":[{"batb":[[0,1.5,20],[1,1.09,222.22],[2,1.03,199]],"ltp":1.03,"tv":2.0,"id":31378},{"batb":[[0,1.5,20],[1,1.09,222.22],[2,1.03,200]],"ltp":0.0,"tv":0.0,"id":475559}]}]}
{"op":"mcm","clk":"11881193557","pt":1724014908323,"mc":[{"id":"1.231875523","rc":[{"batb":[[0,1.51,16.8],[1,1.5,20],[2,1.09,222.22]],"ltp":1.03,"tv":2.0,"id":31378},{"batb":[[0,1.51,16.8],[1,1.5,20],[2,1.09,222.22]],"ltp":0.0,"tv":0.0,"id":475559},{"batb":[[0,1.51,16.8],[1,1.5,1.8],[2,1.32,55.41]],"ltp":0.0,"tv":0.0,"id":60443}]}]}
{"op":"mcm","clk":"11881350272","pt":1724016708632,"mc":[{"id":"1.231875523","rc":[{"batb":[[0,1.5,20],[1,1.09,222.22],[2,1.03,199]],"ltp":1.03,"tv":2.0,"id":31378}]}]}
{"op":"mcm","clk":"11881350363","pt":1724016709731,"mc":[{"id":"1.231875523","rc":[{"batb":[[0,1.5,1.8],[1,1.32,55.41],[2,1.3,20]],"ltp":0.0,"tv":0.0,"id":60443},{"batb":[[0,1.5,20],[1,1.09,222.22],[2,1.03,200]],"ltp":0.0,"tv":0.0,"id":475559}]}]}
{"op":"mcm","clk":"11881358870","pt":1724016807878,"mc":[{"id":"1.231875523","rc":[{"batb":[[0,1.51,16.8],[1,1.5,20],[2,1.09,222.22]],"ltp":1.03,"tv":2.0,"id":31378},{"batb":[[0,1.51,16.8],[1,1.5,1.8],[2,1.32,55.41]],"ltp":0.0,"tv":0.0,"id":60443},{"batb":[[0,1.51,16.8],[1,1.5,20],[2,1.09,222.22]],"ltp":0.0,"tv":0.0,"id":475559}]}]}
{"op":"mcm","clk":"11881511847","pt":1724018608310,"mc":[{"id":"1.231875523","rc":[{"batb":[[0,1.5,20],[1,1.09,222.22],[2,1.03,199]],"ltp":1.03,"tv":2.0,"id":31378},{"batb":[[0,1.51,16.79],[2,1.32,55.37]],"ltp":0.0,"tv":0.0,"id":60443},{"batb":[[0,1.5,20],[1,1.09,222.22],[2,1.03,200]],"ltp":0.0,"tv":0.0,"id":475559}]}]}
{"op":"mcm","clk":"11881511912","pt":1724018609188,"mc":[{"id":"1.231875523","rc":[{"batb":[[0,1.5,1.8],[1,1.32,55.37],[2,1.3,20]],"ltp":0.0,"tv":0.0,"id":60443}]}]}
{"op":"mcm","clk":"11881515833","pt":1724018655035,"mc":[{"id":"1.231875523","rc":[{"batb":[[0,1.51,16.79],[1,1.5,20],[2,1.09,222.22]],"ltp":1.03,"tv":2.0,"id":31378},{"batb":[[0,1.51,16.79],[1,1.5,1.8],[2,1.32,55.37]],"ltp":0.0,"tv":0.0,"id":60443},{"batb":[[0,1.51,16.79],[1,1.5,20],[2,1.09,222.22]],"ltp":0.0,"tv":0.0,"id":475559}]}]}
{"op":"mcm","clk":"11881640807","pt":1724020455645,"mc":[{"id":"1.231875523","rc":[{"batb":[[0,1.5,20],[1,1.09,222.22],[2,1.03,199]],"ltp":1.03,"tv":2.0,"id":31378},{"batb":[[0,1.5,1.8],[1,1.32,55.37],[2,1.3,20]],"ltp":0.0,"tv":0.0,"id":60443},{"batb":[[0,1.5,20],[1,1.09,222.22],[2,1.03,200]],"ltp":0.0,"tv":0.0,"id":475559}]}]}
{"op":"mcm","clk":"11881642228","pt":1724020478047,"mc":[{"id":"1.231875523","rc":[{"batb":[[0,1.51,16.79],[1,1.5,20],[2,1.09,222.22]],"ltp":1.03,"tv":2.0,"id":31378},{"batb":[[0,1.51,16.79],[1,1.5,1.8],[2,1.32,55.37]],"ltp":0.0,"tv":0.0,"id":60443},{"batb":[[0,1.51,16.79],[1,1.5,20],[2,1.09,222.22]],"ltp":0.0,"tv":0.0,"id":475559}]}]}
{"op":"mcm","clk":"11881768940","pt":1724022278743,"mc":[{"id":"1.231875523","rc":[{"batb":[[0,1.5,20],[1,1.09,222.22],[2,1.03,199]],"ltp":1.03,"tv":2.0,"id":31378},{"batb":[[0,1.5,1.8],[1,1.32,55.37],[2,1.3,20]],"ltp":0.0,"tv":0.0,"id":60443},{"batb":[[0,1.5,20],[1,1.09,222.22],[2,1.03,200]],"ltp":0.0,"tv":0.0,"id":475559}]}]}
{"op":"mcm","clk":"11881776640","pt":1724022404819,"mc":[{"id":"1.231875523","rc":[{"batb":[[0,1.51,16.79],[1,1.5,20],[2,1.09,222.22]],"ltp":1.03,"tv":2.0,"id":31378},{"batb":[[0,1.51,16.79],[1,1.5,1.8],[2,1.32,55.37]],"ltp":0.0,"tv":0.0,"id":60443},{"batb":[[0,1.51,16.79],[1,1.5,20],[2,1.09,222.22]],"ltp":0.0,"tv":0.0,"id":475559}]}]}
{"op":"mcm","clk":"11881908654","pt":1724024205012,"mc":[{"id":"1.231875523","rc":[{"batb":[[0,1.5,1.8],[1,1.32,55.37],[2,1.3,20]],"ltp":0.0,"tv":0.0,"id":60443}]}]}
{"op":"mcm","clk":"11881908679","pt":1724024205422,"mc":[{"id":"1.231875523","rc":[{"batb":[[0,1.5,20],[1,1.09,222.22],[2,1.03,199]],"ltp":1.03,"tv":2.0,"id":31378},{"batb":[[0,1.5,20],[1,1.09,222.22],[2,1.03,200]],"ltp":0.0,"tv":0.0,"id":475559}]}]}
{"op":"mcm","clk":"11881913604","pt":1724024290179,"mc":[{"id":"1.231875523","rc":[{"batb":[[0,1.51,16.79],[1,1.5,20],[2,1.09,222.22]],"ltp":1.03,"tv":2.0,"id":31378},{"batb":[[0,1.51,16.79],[1,1.5,1.8],[2,1.32,55.37]],"ltp":0.0,"tv":0.0,"id":60443},{"batb":[[0,1.51,16.79],[1,1.5,20],[2,1.09,222.22]],"ltp":0.0,"tv":0.0,"id":475559}]}]}
{"op":"mcm","clk":"11882013118","pt":1724026090898,"mc":[{"id":"1.231875523","rc":[{"batb":[[0,1.5,20],[1,1.09,222.22],[2,1.03,199]],"ltp":1.03,"tv":2.0,"id":31378},{"batb":[[0,1.5,1.8],[1,1.32,55.36],[2,1.3,20]],"ltp":0.0,"tv":0.0,"id":60443},{"batb":[[0,1.5,20],[1,1.09,222.22],[2,1.03,200]],"ltp":0.0,"tv":0.0,"id":475559}]}]}
{"op":"mcm","clk":"11882015928","pt":1724026141658,"mc":[{"id":"1.231875523","rc":[{"batb":[[0,1.51,16.79],[1,1.5,20],[2,1.09,222.22]],"ltp":1.03,"tv":2.0,"id":31378},{"batb":[[0,1.51,16.79],[1,1.5,1.8],[2,1.32,55.36]],"ltp":0.0,"tv":0.0,"id":60443},{"batb":[[0,1.51,16.79],[1,1.5,20],[2,1.09,222.22]],"ltp":0.0,"tv":0.0,"id":475559}]}]}
{"op":"mcm","clk":"11882133187","pt":1724027942085,"mc":[{"id":"1.231875523","rc":[{"batb":[[0,1.5,20],[1,1.09,222.22],[2,1.03,200]],"ltp":0.0,"tv":0.0,"id":475559},{"batb":[[0,1.5,1.8],[1,1.32,55.36],[2,1.3,20]],"ltp":0.0,"tv":0.0,"id":60443}]}]}
{"op":"mcm","clk":"11882133201","pt":1724027942292,"mc":[{"id":"1.231875523","rc":[{"batb":[[0,1.5,20],[1,1.09,222.22],[2,1.03,199]],"ltp":1.03,"tv":2.0,"id":31378}]}]}
{"op":"mcm","clk":"11882135048","pt":1724027972754,"mc":[{"id":"1.231875523","rc":[{"batb":[[0,1.51,16.79],[1,1.5,20],[2,1.09,222.22]],"ltp":1.03,"tv":2.0,"id":31378},{"batb":[[0,1.51,16.79],[1,1.5,20],[2,1.09,222.22]],"ltp":0.0,"tv":0.0,"id":475559},{"batb":[[0,1.51,16.79],[1,1.5,1.8],[2,1.32,55.36]],"ltp":0.0,"tv":0.0,"id":60443}]}]}
{"op":"mcm","clk":"11882226422","pt":1724029772969,"mc":[{"id":"1.231875523","rc":[{"batb":[[0,1.5,20],[1,1.09,222.22],[2,1.03,199]],"ltp":1.03,"tv":2.0,"id":31378},{"batb":[[0,1.51,16.8]],"ltp":0.0,"tv":0.0,"id":475559},{"batb":[[0,1.51,16.8],[2,1.32,55.39]],"ltp":0.0,"tv":0.0,"id":60443}]}]}
{"op":"mcm","clk":"11882226469","pt":1724029773637,"mc":[{"id":"1.231875523","rc":[{"batb":[[0,1.5,20],[1,1.09,222.22],[2,1.03,200]],"ltp":0.0,"tv":0.0,"id":475559},{"batb":[[0,1.5,1.8],[1,1.32,55.39],[2,1.3,20]],"ltp":0.0,"tv":0.0,"id":60443}]}]}
{"op":"mcm","clk":"11882227235","pt":1724029790080,"mc":[{"id":"1.231875523","rc":[{"batb":[[0,1.51,16.8],[1,1.5,20],[2,1.09,222.22]],"ltp":1.03,"tv":2.0,"id":31378},{"batb":[[0,1.51,16.8],[1,1.5,20],[2,1.09,222.22]],"ltp":0.0,"tv":0.0,"id":475559},{"batb":[[0,1.51,16.8],[1,1.5,1.8],[2,1.32,55.39]],"ltp":0.0,"tv":0.0,"id":60443}]}]}
{"op":"mcm","clk":"11882303915","pt":1724031590969,"mc":[{"id":"1.231875523","rc":[{"batb":[[0,1.5,20],[1,1.09,222.22],[2,1.03,199]],"ltp":1.03,"tv":2.0,"id":31378},{"batb":[[0,1.5,20],[1,1.09,222.22],[2,1.03,200]],"ltp":0.0,"tv":0.0,"id":475559},{"batb":[[0,1.5,1.8],[1,1.32,55.39],[2,1.3,20]],"ltp":0.0,"tv":0.0,"id":60443}]}]}
{"op":"mcm","clk":"11882308589","pt":1724031699029,"mc":[{"id":"1.231875523","rc":[{"batb":[[0,1.51,16.8],[1,1.5,20],[2,1.09,222.22]],"ltp":1.03,"tv":2.0,"id":31378},{"batb":[[0,1.51,16.8],[1,1.5,20],[2,1.09,222.22]],"ltp":0.0,"tv":0.0,"id":475559},{"batb":[[0,1.51,16.8],[1,1.5,1.8],[2,1.32,55.39]],"ltp":0.0,"tv":0.0,"id":60443}]}]}
{"op":"mcm","clk":"11882383288","pt":1724033499658,"mc":[{"id":"1.231875523","rc":[{"batb":[[0,1.5,20],[1,1.09,222.22],[2,1.03,199]],"ltp":1.03,"tv":2.0,"id":31378},{"batb":[[0,1.5,1.8],[1,1.32,55.36],[2,1.3,20]],"ltp":0.0,"tv":0.0,"id":60443},{"batb":[[0,1.5,20],[1,1.09,222.22],[2,1.03,200]],"ltp":0.0,"tv":0.0,"id":475559}]}]}
{"op":"mcm","clk":"11882387547","pt":1724033594154,"mc":[{"id":"1.231875523","rc":[{"batb":[[0,1.51,16.79],[1,1.5,20],[2,1.09,222.22]],"ltp":1.03,"tv":2.0,"id":31378},{"batb":[[0,1.51,16.79],[1,1.5,1.8],[2,1.32,55.36]],"ltp":0.0,"tv":0.0,"id":60443},{"batb":[[0,1.51,16.79],[1,1.5,20],[2,1.09,222.22]],"ltp":0.0,"tv":0.0,"id":475559}]}]}
{"op":"mcm","clk":"11882454498","pt":1724035394642,"mc":[{"id":"1.231875523","rc":[{"batb":[[0,1.5,20],[1,1.09,222.22],[2,1.03,199]],"ltp":1.03,"tv":2.0,"id":31378},{"batb":[[0,1.5,1.8],[1,1.32,55.36],[2,1.3,20]],"ltp":0.0,"tv":0.0,"id":60443},{"batb":[[0,1.5,20],[1,1.09,222.22],[2,1.03,200]],"ltp":0.0,"tv":0.0,"id":475559}]}]}
{"op":"mcm","clk":"11882457833","pt":1724035485986,"mc":[{"id":"1.231875523","rc":[{"batb":[[0,1.51,16.79],[1,1.5,20],[2,1.09,222.22]],"ltp":1.03,"tv":2.0,"id":31378},{"batb":[[0,1.51,16.79],[1,1.5,1.8],[2,1.32,55.36]],"ltp":0.0,"tv":0.0,"id":60443},{"batb":[[0,1.51,16.79],[1,1.5,20],[2,1.09,222.22]],"ltp":0.0,"tv":0.0,"id":475559}]}]}
{"op":"mcm","clk":"11882512440","pt":1724037174982,"mc":[{"id":"1.231875523","rc":[{"batb":[[0,1.51,16.78]],"ltp":1.03,"tv":2.0,"id":31378},{"batb":[[0,1.51,16.78],[2,1.32,55.35]],"ltp":0.0,"tv":0.0,"id":60443},{"batb":[[0,1.51,16.78]],"ltp":0.0,"tv":0.0,"id":475559}]}]}
{"op":"mcm","clk":"11882517817","pt":1724037286665,"mc":[{"id":"1.231875523","rc":[{"batb":[[0,1.5,20],[1,1.09,222.22],[2,1.03,199]],"ltp":1.03,"tv":2.0,"id":31378},{"batb":[[0,1.5,1.8],[1,1.32,55.35],[2,1.3,20]],"ltp":0.0,"tv":0.0,"id":60443},{"batb":[[0,1.5,20],[1,1.09,222.22],[2,1.03,200]],"ltp":0.0,"tv":0.0,"id":475559}]}]}
{"op":"mcm","clk":"11882519343","pt":1724037362561,"mc":[{"id":"1.231875523","rc":[{"batb":[[0,1.51,16.78],[1,1.5,20],[2,1.09,222.22]],"ltp":1.03,"tv":2.0,"id":31378},{"batb":[[0,1.51,16.78],[1,1.5,1.8],[2,1.32,55.35]],"ltp":0.0,"tv":0.0,"id":60443},{"batb":[[0,1.51,16.78],[1,1.5,20],[2,1.09,222.22]],"ltp":0.0,"tv":0.0,"id":475559}]}]}
{"op":"mcm","clk":"11882570444","pt":1724039162790,"mc":[{"id":"1.231875523","rc":[{"batb":[[0,1.5,1.8],[1,1.32,55.35],[2,1.3,20]],"ltp":0.0,"tv":0.0,"id":60443}]}]}
{"op":"mcm","clk":"11882570473","pt":1724039163660,"mc":[{"id":"1.231875523","rc":[{"batb":[[0,1.5,20],[1,1.09,222.22],[2,1.03,199]],"ltp":1.03,"tv":2.0,"id":31378},{"batb":[[0,1.5,20],[1,1.09,222.22],[2,1.03,200]],"ltp":0.0,"tv":0.0,"id":475559}]}]}
{"op":"mcm","clk":"11882572484","pt":1724039224763,"mc":[{"id":"1.231875523","rc":[{"batb":[[0,1.51,16.78],[1,1.5,20],[2,1.09,222.22]],"ltp":1.03,"tv":2.0,"id":31378},{"batb":[[0,1.51,16.78],[1,1.5,1.8],[2,1.32,55.35]],"ltp":0.0,"tv":0.0,"id":60443},{"batb":[[0,1.51,16.78],[1,1.5,20],[2,1.09,222.22]],"ltp":0.0,"tv":0.0,"id":475559}]}]}
{"op":"mcm","clk":"11882611056","pt":1724041024960,"mc":[{"id":"1.231875523","rc":[{"batb":[[0,1.5,20],[1,1.09,222.22],[2,1.03,199]],"ltp":1.03,"tv":2.0,"id":31378},{"batb":[[0,1.5,1.8],[1,1.32,55.39],[2,1.3,20]],"ltp":0.0,"tv":0.0,"id":60443},{"batb":[[0,1.51,16.8]],"ltp":0.0,"tv":0.0,"id":475559}]}]}
{"op":"mcm","clk":"11882611061","pt":1724041025164,"mc":[{"id":"1.231875523","rc":[{"batb":[[0,1.5,20],[1,1.09,222.22],[2,1.03,200]],"ltp":0.0,"tv":0.0,"id":475559}]}]}
{"op":"mcm","clk":"11882612175","pt":1724041085332,"mc":[{"id":"1.231875523","rc":[{"batb":[[0,1.51,16.8],[1,1.5,20],[2,1.09,222.22]],"ltp":1.03,"tv":2.0,"id":31378},{"batb":[[0,1.51,16.8],[1,1.5,1.8],[2,1.32,55.39]],"ltp":0.0,"tv":0.0,"id":60443},{"batb":[[0,1.51,16.8],[1,1.5,20],[2,1.09,222.22]],"ltp":0.0,"tv":0.0,"id":475559}]}]}
{"op":"mcm","clk":"11882654151","pt":1724042886017,"mc":[{"id":"1.231875523","rc":[{"batb":[[0,1.5,1.8],[1,1.32,55.39],[2,1.3,20]],"ltp":0.0,"tv":0.0,"id":60443}]}]}
{"op":"mcm","clk":"11882654160","pt":1724042886427,"mc":[{"id":"1.231875523","rc":[{"batb":[[0,1.5,20],[1,1.09,222.22],[2,1.03,199]],"ltp":1.03,"tv":2.0,"id":31378},{"batb":[[0,1.5,20],[1,1.09,222.22],[2,1.03,200]],"ltp":0.0,"tv":0.0,"id":475559}]}]}
{"op":"mcm","clk":"11882655038","pt":1724042933774,"mc":[{"id":"1.231875523","rc":[{"batb":[[0,1.51,16.8],[1,1.5,20],[2,1.09,222.22]],"ltp":1.03,"tv":2.0,"id":31378},{"batb":[[0,1.51,16.8],[1,1.5,1.8],[2,1.32,55.39]],"ltp":0.0,"tv":0.0,"id":60443},{"batb":[[0,1.51,16.8],[1,1.5,20],[2,1.09,222.22]],"ltp":0.0,"tv":0.0,"id":475559}]}]}
{"op":"mcm","clk":"11882699262","pt":1724044734002,"mc":[{"id":"1.231875523","rc":[{"batb":[[0,1.51,16.8]],"ltp":1.03,"tv":2.0,"id":31378},{"batb":[[0,1.51,16.8],[2,1.32,55.4]],"ltp":0.0,"tv":0.0,"id":60443},{"batb":[[0,1.5,20],[1,1.09,222.22],[2,1.03,200]],"ltp":0.0,"tv":0.0,"id":475559}]}]}
{"op":"mcm","clk":"11882699285","pt":1724044735023,"mc":[{"id":"1.231875523","rc":[{"batb":[[0,1.5,20],[1,1.09,222.22],[2,1.03,199]],"ltp":1.03,"tv":2.0,"id":31378},{"batb":[[0,1.5,1.8],[1,1.32,55.4],[2,1.3,20]],"ltp":0.0,"tv":0.0,"id":60443}]}]}
{"op":"mcm","clk":"11882700288","pt":1724044777983,"mc":[{"id":"1.231875523","rc":[{"batb":[[0,1.51,16.8],[1,1.5,20],[2,1.09,222.22]],"ltp":1.03,"tv":2.0,"id":31378},{"batb":[[0,1.51,16.8],[1,1.5,1.8],[2,1.32,55.4]],"ltp":0.0,"tv":0.0,"id":60443},{"batb":[[0,1.51,16.8],[1,1.5,20],[2,1.09,222.22]],"ltp":0.0,"tv":0.0,"id":475559}]}]}
{"op":"mcm","clk":"11882746796","pt":1724046578777,"mc":[{"id":"1.231875523","rc":[{"batb":[[0,1.5,20],[1,1.09,222.22],[2,1.03,199]],"ltp":1.03,"tv":2.0,"id":31378},{"batb":[[0,1.5,1.8],[1,1.32,55.4],[2,1.3,20]],"ltp":0.0,"tv":0.0,"id":60443},{"batb":[[0,1.5,20],[1,1.09,222.22],[2,1.03,200]],"ltp":0.0,"tv":0.0,"id":475559}]}]}
{"op":"mcm","clk":"11882747672","pt":1724046618727,"mc":[{"id":"1.231875523","rc":[{"batb":[[0,1.51,16.8],[1,1.5,20],[2,1.09,222.22]],"ltp":1.03,"tv":2.0,"id":31378},{"batb":[[0,1.51,16.8],[1,1.5,1.8],[2,1.32,55.4]],"ltp":0.0,"tv":0.0,"id":60443},{"batb":[[0,1.51,16.8],[1,1.5,20],[2,1.09,222.22]],"ltp":0.0,"tv":0.0,"id":475559}]}]}
{"op":"mcm","clk":"11882785001","pt":1724047974967,"mc":[{"id":"1.231875523","rc":[{"batb":[[1,1.5,1.79],[2,1.32,55.39]],"ltp":0.0,"tv":0.0,"id":60443}]}]}
{"op":"mcm","clk":"11882802192","pt":1724048418920,"mc":[{"id":"1.231875523","rc":[{"batb":[[0,1.5,20],[1,1.09,222.22],[2,1.03,200]],"ltp":0.0,"tv":0.0,"id":475559}]}]}
{"op":"mcm","clk":"11882802198","pt":1724048419123,"mc":[{"id":"1.231875523","rc":[{"batb":[[0,1.5,20],[1,1.09,222.22],[2,1.03,199]],"ltp":1.03,"tv":2.0,"id":31378}]}]}
{"op":"mcm","clk":"11882802245","pt":1724048420516,"mc":[{"id":"1.231875523","rc":[{"batb":[[0,1.5,1.79],[1,1.32,55.39],[2,1.3,20]],"ltp":0.0,"tv":0.0,"id":60443}]}]}
{"op":"mcm","clk":"11882803278","pt":1724048458774,"mc":[{"id":"1.231875523","rc":[{"batb":[[0,1.51,16.8],[1,1.5,20],[2,1.09,222.22]],"ltp":1.03,"tv":2.0,"id":31378},{"batb":[[0,1.51,16.8],[1,1.5,20],[2,1.09,222.22]],"ltp":0.0,"tv":0.0,"id":475559},{"batb":[[0,1.51,16.8],[1,1.5,1.79],[2,1.32,55.39]],"ltp":0.0,"tv":0.0,"id":60443}]}]}
{"op":"mcm","clk":"11882847893","pt":1724050259951,"mc":[{"id":"1.231875523","rc":[{"batb":[[0,1.5,20],[1,1.09,222.22],[2,1.03,200]],"ltp":0.0,"tv":0.0,"id":475559}]}]}
{"op":"mcm","clk":"11882847909","pt":1724050260365,"mc":[{"id":"1.231875523","rc":[{"batb":[[0,1.5,20],[1,1.09,222.22],[2,1.03,199]],"ltp":1.03,"tv":2.0,"id":31378},{"batb":[[0,1.5,1.79],[1,1.32,55.39],[2,1.3,20]],"ltp":0.0,"tv":0.0,"id":60443}]}]}
{"op":"mcm","clk":"11882848862","pt":1724050292806,"mc":[{"id":"1.231875523","rc":[{"batb":[[0,1.51,16.8],[1,1.5,20],[2,1.09,222.22]],"ltp":1.03,"tv":2.0,"id":31378},{"batb":[[0,1.51,16.8],[1,1.5,20],[2,1.09,222.22]],"ltp":0.0,"tv":0.0,"id":475559},{"batb":[[0,1.51,16.8],[1,1.5,1.79],[2,1.32,55.39]],"ltp":0.0,"tv":0.0,"id":60443}]}]}
{"op":"mcm","clk":"11882889591","pt":1724052093082,"mc":[{"id":"1.231875523","rc":[{"batb":[[0,1.51,16.79]],"ltp":1.03,"tv":2.0,"id":31378},{"batb":[[0,1.5,20],[1,1.09,222.22],[2,1.03,200]],"ltp":0.0,"tv":0.0,"id":475559},{"batb":[[0,1.51,16.79],[2,1.32,55.37]],"ltp":0.0,"tv":0.0,"id":60443}]}]}
{"op":"mcm","clk":"11882889594","pt":1724052093287,"mc":[{"id":"1.231875523","rc":[{"batb":[[0,1.5,20],[1,1.09,222.22],[2,1.03,199]],"ltp":1.03,"tv":2.0,"id":31378}]}]}
{"op":"mcm","clk":"11882889603","pt":1724052094106,"mc":[{"id":"1.231875523","rc":[{"batb":[[0,1.5,1.79],[1,1.32,55.37],[2,1.3,20]],"ltp":0.0,"tv":0.0,"id":60443}]}]}
{"op":"mcm","clk":"11882890073","pt":1724052123414,"mc":[{"id":"1.231875523","rc":[{"batb":[[0,1.51,16.79],[1,1.5,20],[2,1.09,222.22]],"ltp":1.03,"tv":2.0,"id":31378},{"batb":[[0,1.51,16.79],[1,1.5,20],[2,1.09,222.22]],"ltp":0.0,"tv":0.0,"id":475559},{"batb":[[0,1.51,16.79],[1,1.5,1.79],[2,1.32,55.37]],"ltp":0.0,"tv":0.0,"id":60443}]}]}
{"op":"mcm","clk":"11882931327","pt":1724053923984,"mc":[{"id":"1.231875523","rc":[{"batb":[[0,1.5,20],[1,1.09,222.22],[2,1.03,199]],"ltp":1.03,"tv":2.0,"id":31378},{"batb":[[0,1.5,20],[1,1.09,222.22],[2,1.03,200]],"ltp":0.0,"tv":0.0,"id":475559},{"batb":[[0,1.5,1.79],[1,1.32,55.37],[2,1.3,20]],"ltp":0.0,"tv":0.0,"id":60443}]}]}
{"op":"mcm","clk":"11882931901","pt":1724053953938,"mc":[{"id":"1.231875523","rc":[{"batb":[[0,1.51,16.79],[1,1.5,20],[2,1.09,222.22]],"ltp":1.03,"tv":2.0,"id":31378},{"batb":[[0,1.51,16.79],[1,1.5,20],[2,1.09,222.22]],"ltp":0.0,"tv":0.0,"id":475559},{"batb":[[0,1.51,16.79],[1,1.5,1.79],[2,1.32,55.37]],"ltp":0.0,"tv":0.0,"id":60443}]}]}
{"op":"mcm","clk":"11882971821","pt":1724055754716,"mc":[{"id":"1.231875523","rc":[{"batb":[[0,1.5,20],[1,1.09,222.22],[2,1.03,199]],"ltp":1.03,"tv":2.0,"id":31378},{"batb":[[0,1.5,20],[1,1.09,222.22],[2,1.03,200]],"ltp":0.0,"tv":0.0,"id":475559},{"batb":[[0,1.5,1.79],[1,1.32,55.37],[2,1.3,20]],"ltp":0.0,"tv":0.0,"id":60443}]}]}
{"op":"mcm","clk":"11882972403","pt":1724055779238,"mc":[{"id":"1.231875523","rc":[{"batb":[[0,1.51,16.79],[1,1.5,20],[2,1.09,222.22]],"ltp":1.03,"tv":2.0,"id":31378},{"batb":[[0,1.51,16.79],[1,1.5,20],[2,1.09,222.22]],"ltp":0.0,"tv":0.0,"id":475559},{"batb":[[0,1.51,16.79],[1,1.5,1.79],[2,1.32,55.37]],"ltp":0.0,"tv":0.0,"id":60443}]}]}
{"op":"mcm","clk":"11883031845","pt":1724057579611,"mc":[{"id":"1.231875523","rc":[{"batb":[[0,1.5,20],[1,1.09,222.22],[2,1.03,200]],"ltp":0.0,"tv":0.0,"id":475559},{"batb":[[0,1.5,1.79],[1,1.32,55.37],[2,1.3,20]],"ltp":0.0,"tv":0.0,"id":60443}]}]}
{"op":"mcm","clk":"11883031874","pt":1724057580326,"mc":[{"id":"1.231875523","rc":[{"batb":[[0,1.5,20],[1,1.09,222.22],[2,1.03,199]],"ltp":1.03,"tv":2.0,"id":31378}]}]}
{"op":"mcm","clk":"11883032504","pt":1724057593747,"mc":[{"id":"1.231875523","rc":[{"batb":[[0,1.51,16.79],[1,1.5,20],[2,1.09,222.22]],"ltp":1.03,"tv":2.0,"id":31378},{"batb":[[0,1.51,16.79],[1,1.5,20],[2,1.09,222.22]],"ltp":0.0,"tv":0.0,"id":475559},{"batb":[[0,1.51,16.79],[1,1.5,1.79],[2,1.32,55.37]],"ltp":0.0,"tv":0.0,"id":60443}]}]}
{"op":"mcm","clk":"11883088235","pt":1724058774962,"mc":[{"id":"1.231875523","rc":[{"batb":[[0,1.51,16.77]],"ltp":1.03,"tv":2.0,"id":31378},{"batb":[[0,1.51,16.77]],"ltp":0.0,"tv":0.0,"id":475559},{"batb":[[0,1.51,16.77],[2,1.32,55.31]],"ltp":0.0,"tv":0.0,"id":60443}]}]}
{"op":"mcm","clk":"11883115554","pt":1724059394061,"mc":[{"id":"1.231875523","rc":[{"batb":[[0,1.5,20],[1,1.09,222.22],[2,1.03,199]],"ltp":1.03,"tv":2.0,"id":31378},{"batb":[[0,1.5,1.79],[1,1.32,55.31],[2,1.3,20]],"ltp":0.0,"tv":0.0,"id":60443}]}]}
{"op":"mcm","clk":"11883115567","pt":1724059394266,"mc":[{"id":"1.231875523","rc":[{"batb":[[0,1.5,20],[1,1.09,222.22],[2,1.03,200]],"ltp":0.0,"tv":0.0,"id":475559}]}]}
{"op":"mcm","clk":"11883116218","pt":1724059408671,"mc":[{"id":"1.231875523","rc":[{"batb":[[0,1.51,16.77],[1,1.5,20],[2,1.09,222.22]],"ltp":1.03,"tv":2.0,"id":31378},{"batb":[[0,1.51,16.77],[1,1.5,20],[2,1.09,222.22]],"ltp":0.0,"tv":0.0,"id":475559},{"batb":[[0,1.51,16.77],[1,1.5,1.79],[2,1.32,55.31]],"ltp":0.0,"tv":0.0,"id":60443}]}]}
{"op":"mcm","clk":"11883197411","pt":1724061208939,"mc":[{"id":"1.231875523","rc":[{"batb":[[0,1.5,20],[1,1.09,222.22],[2,1.03,199]],"ltp":1.03,"tv":2.0,"id":31378},{"batb":[[0,1.5,1.79],[1,1.32,55.31],[2,1.3,20]],"ltp":0.0,"tv":0.0,"id":60443}]}]}
{"op":"mcm","clk":"11883197416","pt":1724061209140,"mc":[{"id":"1.231875523","rc":[{"batb":[[0,1.5,20],[1,1.09,222.22],[2,1.03,200]],"ltp":0.0,"tv":0.0,"id":475559}]}]}
{"op":"mcm","clk":"11883197721","pt":1724061215747,"mc":[{"id":"1.231875523","rc":[{"batb":[[0,1.51,16.77],[1,1.5,20],[2,1.09,222.22]],"ltp":1.03,"tv":2.0,"id":31378},{"batb":[[0,1.51,16.77],[1,1.5,20],[2,1.09,222.22]],"ltp":0.0,"tv":0.0,"id":475559},{"batb":[[0,1.51,16.77],[1,1.5,1.79],[2,1.32,55.31]],"ltp":0.0,"tv":0.0,"id":60443}]}]}
{"op":"mcm","clk":"11883283738","pt":1724063016061,"mc":[{"id":"1.231875523","rc":[{"batb":[[0,1.51,16.78]],"ltp":1.03,"tv":2.0,"id":31378},{"batb":[[0,1.5,20],[1,1.09,222.22],[2,1.03,200]],"ltp":0.0,"tv":0.0,"id":475559},{"batb":[[0,1.5,1.79],[1,1.32,55.33],[2,1.3,20]],"ltp":0.0,"tv":0.0,"id":60443}]}]}
{"op":"mcm","clk":"11883283772","pt":1724063016887,"mc":[{"id":"1.231875523","rc":[{"batb":[[0,1.5,20],[1,1.09,222.22],[2,1.03,199]],"ltp":1.03,"tv":2.0,"id":31378}]}]}
{"op":"mcm","clk":"11883288254","pt":1724063120978,"mc":[{"id":"1.231875523","rc":[{"batb":[[0,1.51,16.78],[1,1.5,20],[2,1.09,222.22]],"ltp":1.03,"tv":2.0,"id":31378},{"batb":[[0,1.51,16.78],[1,1.5,20],[2,1.09,222.22]],"ltp":0.0,"tv":0.0,"id":475559},{"batb":[[0,1.51,16.78],[1,1.5,1.79],[2,1.32,55.33]],"ltp":0.0,"tv":0.0,"id":60443}]}]}
{"op":"mcm","clk":"11883381713","pt":1724064922035,"mc":[{"id":"1.231875523","rc":[{"batb":[[0,1.5,20],[1,1.09,222.22],[2,1.03,200]],"ltp":0.0,"tv":0.0,"id":475559},{"batb":[[0,1.5,1.79],[1,1.32,55.33],[2,1.3,20]],"ltp":0.0,"tv":0.0,"id":60443}]}]}
{"op":"mcm","clk":"11883381720","pt":1724064922240,"mc":[{"id":"1.231875523","rc":[{"batb":[[0,1.5,20],[1,1.09,222.22],[2,1.03,199]],"ltp":1.03,"tv":2.0,"id":31378}]}]}
{"op":"mcm","clk":"11883383502","pt":1724064961888,"mc":[{"id":"1.231875523","rc":[{"batb":[[0,1.51,16.78],[1,1.5,20],[2,1.09,222.22]],"ltp":1.03,"tv":2.0,"id":31378},{"batb":[[0,1.51,16.78],[1,1.5,20],[2,1.09,222.22]],"ltp":0.0,"tv":0.0,"id":475559},{"batb":[[0,1.51,16.78],[1,1.5,1.79],[2,1.32,55.33]],"ltp":0.0,"tv":0.0,"id":60443}]}]}
{"op":"mcm","clk":"11883464935","pt":1724066762086,"mc":[{"id":"1.231875523","rc":[{"batb":[[0,1.51,16.8]],"batl":[[0,95,5.85]],"ltp":1.03,"tv":2.0,"id":31378},{"batb":[[0,1.5,20],[1,1.09,222.22],[2,1.03,200]],"batl":[[0,95,5.85]],"ltp":0.0,"tv":0.0,"id":475559},{"batb":[[0,1.51,16.8],[1,1.5,1.8],[2,1.32,55.4]],"batl":[[0,95,5.85]],"ltp":0.0,"tv":0.0,"id":60443}]}]}
{"op":"mcm","clk":"11883464948","pt":1724066762292,"mc":[{"id":"1.231875523","rc":[{"batb":[[0,1.5,20],[1,1.09,222.22],[2,1.03,199]],"ltp":1.03,"tv":2.0,"id":31378},{"batb":[[0,1.5,1.8],[1,1.32,55.4],[2,1.3,20]],"ltp":0.0,"tv":0.0,"id":60443}]}]}
{"op":"mcm","clk":"11883466744","pt":1724066800223,"mc":[{"id":"1.231875523","rc":[{"batb":[[0,1.51,16.8],[1,1.5,20],[2,1.09,222.22]],"ltp":1.03,"tv":2.0,"id":31378},{"batb":[[0,1.51,16.8],[1,1.5,20],[2,1.09,222.22]],"ltp":0.0,"tv":0.0,"id":475559},{"batb":[[0,1.51,16.8],[1,1.5,1.8],[2,1.32,55.4]],"ltp":0.0,"tv":0.0,"id":60443}]}]}
{"op":"mcm","clk":"11883546365","pt":1724068600812,"mc":[{"id":"1.231875523","rc":[{"batb":[[0,1.5,20],[1,1.09,222.22],[2,1.03,199]],"ltp":1.03,"tv":2.0,"id":31378},{"batb":[[0,1.5,20],[1,1.09,222.22],[2,1.03,200]],"ltp":0.0,"tv":0.0,"id":475559},{"batb":[[0,1.5,1.8],[1,1.32,55.4],[2,1.3,20]],"ltp":0.0,"tv":0.0,"id":60443}]}]}
{"op":"mcm","clk":"11883547979","pt":1724068635463,"mc":[{"id":"1.231875523","rc":[{"batb":[[0,1.51,16.8],[1,1.5,20],[2,1.09,222.22]],"ltp":1.03,"tv":2.0,"id":31378},{"batb":[[0,1.51,16.8],[1,1.5,20],[2,1.09,222.22]],"ltp":0.0,"tv":0.0,"id":475559},{"batb":[[0,1.51,16.8],[1,1.5,1.8],[2,1.32,55.4]],"ltp":0.0,"tv":0.0,"id":60443}]}]}
{"op":"mcm","clk":"11883598773","pt":1724069574976,"mc":[{"id":"1.231875523","rc":[{"batb":[[0,1.51,16.8]],"ltp":1.03,"tv":2.0,"id":31378},{"batb":[[0,1.51,16.8],[1,1.5,1.79]],"ltp":0.0,"tv":0.0,"id":60443},{"batb":[[0,1.51,16.8]],"ltp":0.0,"tv":0.0,"id":475559}]}]}
{"op":"mcm","clk":"11883641138","pt":1724070435947,"mc":[{"id":"1.231875523","rc":[{"batb":[[0,1.5,20],[1,1.09,222.22],[2,1.03,199]],"ltp":1.03,"tv":2.0,"id":31378},{"batb":[[0,1.5,1.79],[1,1.32,55.4],[2,1.3,20]],"ltp":0.0,"tv":0.0,"id":60443},{"batb":[[0,1.5,20],[1,1.09,222.22],[2,1.03,200]],"ltp":0.0,"tv":0.0,"id":475559}]}]}
{"op":"mcm","clk":"11883642376","pt":1724070463083,"mc":[{"id":"1.231875523","rc":[{"batb":[[0,1.51,16.8],[1,1.5,20],[2,1.09,222.22]],"ltp":1.03,"tv":2.0,"id":31378},{"batb":[[0,1.51,16.8],[1,1.5,1.79],[2,1.32,55.4]],"ltp":0.0,"tv":0.0,"id":60443},{"batb":[[0,1.51,16.8],[1,1.5,20],[2,1.09,222.22]],"ltp":0.0,"tv":0.0,"id":475559}]}]}
{"op":"mcm","clk":"11883716460","pt":1724072263448,"mc":[{"id":"1.231875523","rc":[{"batb":[[0,1.5,20],[1,1.09,222.22],[2,1.03,199]],"ltp":1.03,"tv":2.0,"id":31378},{"batb":[[0,1.5,1.79],[1,1.32,55.4],[2,1.3,20]],"ltp":0.0,"tv":0.0,"id":60443},{"batb":[[0,1.5,20],[1,1.09,222.22],[2,1.03,200]],"ltp":0.0,"tv":0.0,"id":475559}]}]}
{"op":"mcm","clk":"11883717465","pt":1724072287467,"mc":[{"id":"1.231875523","rc":[{"batb":[[0,1.51,16.8],[1,1.5,20],[2,1.09,222.22]],"ltp":1.03,"tv":2.0,"id":31378},{"batb":[[0,1.51,16.8],[1,1.5,1.79],[2,1.32,55.4]],"ltp":0.0,"tv":0.0,"id":60443},{"batb":[[0,1.51,16.8],[1,1.5,20],[2,1.09,222.22]],"ltp":0.0,"tv":0.0,"id":475559}]}]}
{"op":"mcm","clk":"11883777427","pt":1724074087904,"mc":[{"id":"1.231875523","rc":[{"batb":[[0,1.5,20],[1,1.09,222.22],[2,1.03,199]],"ltp":1.03,"tv":2.0,"id":31378},{"batb":[[0,1.51,16.8]],"ltp":0.0,"tv":0.0,"id":60443},{"batb":[[0,1.5,20],[1,1.09,222.22],[2,1.03,200]],"ltp":0.0,"tv":0.0,"id":475559}]}]}
{"op":"mcm","clk":"11883777439","pt":1724074088110,"mc":[{"id":"1.231875523","rc":[{"batb":[[0,1.5,1.8],[1,1.32,55.4],[2,1.3,20]],"ltp":0.0,"tv":0.0,"id":60443}]}]}
{"op":"mcm","clk":"11883778253","pt":1724074107499,"mc":[{"id":"1.231875523","rc":[{"batb":[[0,1.51,16.8],[1,1.5,20],[2,1.09,222.22]],"ltp":1.03,"tv":2.0,"id":31378},{"batb":[[0,1.51,16.8],[1,1.5,1.8],[2,1.32,55.4]],"ltp":0.0,"tv":0.0,"id":60443},{"batb":[[0,1.51,16.8],[1,1.5,20],[2,1.09,222.22]],"ltp":0.0,"tv":0.0,"id":475559}]}]}
{"op":"mcm","clk":"11883820709","pt":1724075104700,"mc":[{"id":"1.231875523","rc":[{"batb":[[0,1.51,17.7],[1,1.32,55.4],[2,1.3,20]],"ltp":0.0,"tv":0.0,"id":60443}]}]}
{"op":"mcm","clk":"11883846734","pt":1724075908085,"mc":[{"id":"1.231875523","rc":[{"batb":[[0,1.5,20],[1,1.09,222.22],[2,1.03,199]],"ltp":1.03,"tv":2.0,"id":31378},{"batb":[[0,1.32,56.3],[1,1.3,20],[2,1.09,222.22]],"ltp":0.0,"tv":0.0,"id":60443},{"batb":[[0,1.5,20],[1,1.09,222.22],[2,1.03,200]],"ltp":0.0,"tv":0.0,"id":475559}]}]}
{"op":"mcm","clk":"11883847493","pt":1724075930134,"mc":[{"id":"1.231875523","rc":[{"batb":[[0,1.51,16.8],[1,1.5,20],[2,1.09,222.22]],"ltp":1.03,"tv":2.0,"id":31378},{"batb":[[0,1.33,26.86],[1,1.32,55.4],[2,1.3,20]],"ltp":0.0,"tv":0.0,"id":60443},{"batb":[[0,1.51,16.8],[1,1.5,20],[2,1.09,222.22]],"ltp":0.0,"tv":0.0,"id":475559}]}]}
{"op":"mcm","clk":"11883860354","pt":1724076234443,"mc":[{"id":"1.231875523","rc":[{"batb":[[0,1.51,16.79]],"ltp":1.03,"tv":2.0,"id":31378},{"batb":[[0,1.34,8.09],[1,1.33,25.95],[2,1.32,55.39]],"ltp":0.0,"tv":0.0,"id":60443},{"batb":[[0,1.51,16.79]],"ltp":0.0,"tv":0.0,"id":475559}]}]}
{"op":"mcm","clk":"11883922208","pt":1724077730491,"mc":[{"id":"1.231875523","rc":[{"batb":[[0,1.5,20],[1,1.09,222.22],[2,1.03,199]],"ltp":1.03,"tv":2.0,"id":31378},{"batb":[[1,1.32,55.39],[2,1.3,20]],"ltp":0.0,"tv":0.0,"id":60443}]}]}
{"op":"mcm","clk":"11883922245","pt":1724077731310,"mc":[{"id":"1.231875523","rc":[{"batb":[[0,1.5,20],[1,1.09,222.22],[2,1.03,200]],"ltp":0.0,"tv":0.0,"id":475559}]}]}
{"op":"mcm","clk":"11883922296","pt":1724077733022,"mc":[{"id":"1.231875523","rc":[{"batb":[[0,1.51,16.79],[1,1.5,20],[2,1.09,222.22]],"ltp":1.03,"tv":2.0,"id":31378},{"batb":[[0,1.35,25.37],[1,1.34,7.19],[2,1.32,55.39]],"ltp":0.0,"tv":0.0,"id":60443},{"batb":[[0,1.51,16.79],[1,1.5,20],[2,1.09,222.22]],"ltp":0.0,"tv":0.0,"id":475559}]}]}
{"op":"mcm","clk":"11883979940","pt":1724078966618,"mc":[{"id":"1.231875523","rc":[{"batb":[[1,1.33,7.19]],"ltp":0.0,"tv":0.0,"id":60443}]}]}
{"op":"mcm","clk":"11884001399","pt":1724079533585,"mc":[{"id":"1.231875523","rc":[{"batb":[[0,1.5,20],[1,1.09,222.22],[2,1.03,199]],"ltp":1.03,"tv":2.0,"id":31378},{"batb":[[0,1.33,8.09],[1,1.32,55.39],[2,1.3,20]],"ltp":0.0,"tv":0.0,"id":60443},{"batb":[[0,1.5,20],[1,1.09,222.22],[2,1.03,200]],"ltp":0.0,"tv":0.0,"id":475559}]}]}
{"op":"mcm","clk":"11884007649","pt":1724079683269,"mc":[{"id":"1.231875523","rc":[{"batb":[[0,1.51,16.79],[1,1.5,20],[2,1.09,222.22]],"ltp":1.03,"tv":2.0,"id":31378},{"batb":[[0,1.34,26.08],[1,1.33,7.18],[2,1.32,55.39]],"ltp":0.0,"tv":0.0,"id":60443},{"batb":[[0,1.51,16.79],[1,1.5,20],[2,1.09,222.22]],"ltp":0.0,"tv":0.0,"id":475559}]}]}
{"op":"mcm","clk":"11884086622","pt":1724080824832,"mc":[{"id":"1.231875523","rc":[{"batb":[[0,1.35,56.28],[1,1.34,25.19],[2,1.33,7.18]],"ltp":0.0,"tv":0.0,"id":60443}]}]}
{"op":"mcm","clk":"11884132809","pt":1724081483738,"mc":[{"id":"1.231875523","rc":[{"batb":[[0,1.5,20],[1,1.09,222.22],[2,1.03,199]],"ltp":1.03,"tv":2.0,"id":31378},{"batb":[[0,1.5,20],[1,1.09,222.22],[2,1.03,200]],"ltp":0.0,"tv":0.0,"id":475559},{"batb":[[1,1.33,7.18],[2,1.3,20]],"ltp":0.0,"tv":0.0,"id":60443}]}]}
{"op":"mcm","clk":"11884142472","pt":1724081631300,"mc":[{"id":"1.231875523","rc":[{"batb":[[0,1.51,16.79],[1,1.5,20],[2,1.09,222.22]],"ltp":1.03,"tv":2.0,"id":31378},{"batb":[[0,1.51,16.79],[1,1.5,20],[2,1.09,222.22]],"ltp":0.0,"tv":0.0,"id":475559},{"batb":[[0,1.36,24.68],[1,1.35,55.39],[2,1.33,7.18]],"ltp":0.0,"tv":0.0,"id":60443}]}]}
{"op":"mcm","clk":"11884148232","pt":1724081717459,"mc":[{"id":"1.231875523","rc":[{"batb":[[2,1.3,20]],"ltp":0.0,"tv":0.0,"id":60443}]}]}
{"op":"mcm","clk":"11884270275","pt":1724083431978,"mc":[{"id":"1.231875523","rc":[{"batb":[[0,1.5,20],[1,1.09,222.22],[2,1.03,199]],"ltp":1.03,"tv":2.0,"id":31378},{"batb":[[0,1.5,20],[1,1.09,222.22],[2,1.03,200]],"ltp":0.0,"tv":0.0,"id":475559},{"batb":[[0,1.35,56.32],[1,1.3,20],[2,1.09,222.22]],"ltp":0.0,"tv":0.0,"id":60443}]}]}
{"op":"mcm","clk":"11884270495","pt":1724083435502,"mc":[{"id":"1.231875523","rc":[{"batb":[[0,1.51,16.8],[1,1.5,20],[2,1.09,222.22]],"ltp":1.03,"tv":2.0,"id":31378},{"batb":[[0,1.51,16.8],[1,1.5,20],[2,1.09,222.22]],"ltp":0.0,"tv":0.0,"id":475559},{"batb":[[0,1.36,24.7],[1,1.35,55.42],[2,1.3,20]],"ltp":0.0,"tv":0.0,"id":60443}]}]}
{"op":"mcm","clk":"11884414378","pt":1724085235972,"mc":[{"id":"1.231875523","rc":[{"batb":[[0,1.5,20],[1,1.09,222.22],[2,1.03,199]],"ltp":1.03,"tv":2.0,"id":31378},{"batb":[[0,1.5,20],[1,1.09,222.22],[2,1.03,200]],"ltp":0.0,"tv":0.0,"id":475559}]}]}
{"op":"mcm","clk":"11884414396","pt":1724085236162,"mc":[{"id":"1.231875523","rc":[{"batb":[[0,1.35,56.32],[1,1.3,20],[2,1.09,222.22]],"ltp":0.0,"tv":0.0,"id":60443}]}]}
{"op":"mcm","clk":"11884418783","pt":1724085282703,"mc":[{"id":"1.231875523","rc":[{"batb":[[0,1.51,16.8],[1,1.5,20],[2,1.09,222.22]],"ltp":1.03,"tv":2.0,"id":31378},{"batb":[[0,1.51,16.8],[1,1.5,20],[2,1.09,222.22]],"ltp":0.0,"tv":0.0,"id":475559},{"batb":[[0,1.36,24.7],[1,1.35,55.42],[2,1.3,20]],"ltp":0.0,"tv":0.0,"id":60443}]}]}
{"op":"mcm","clk":"11884570308","pt":1724087083037,"mc":[{"id":"1.231875523","rc":[{"batb":[[0,1.51,16.81]],"ltp":1.03,"tv":2.0,"id":31378},{"batb":[[0,1.35,56.34],[1,1.3,20],[2,1.09,222.22]],"ltp":0.0,"tv":0.0,"id":60443},{"batb":[[0,1.5,20],[1,1.09,222.22],[2,1.03,200]],"ltp":0.0,"tv":0.0,"id":475559}]}]}
{"op":"mcm","clk":"11884570428","pt":1724087084134,"mc":[{"id":"1.231875523","rc":[{"batb":[[0,1.5,20],[1,1.09,222.22],[2,1.03,199]],"ltp":1.03,"tv":2.0,"id":31378}]}]}
{"op":"mcm","clk":"11884573212","pt":1724087110080,"mc":[{"id":"1.231875523","rc":[{"batb":[[0,1.51,16.81],[1,1.5,20],[2,1.09,222.22]],"ltp":1.03,"tv":2.0,"id":31378},{"batb":[[0,1.36,24.71],[1,1.35,55.45],[2,1.3,20]],"ltp":0.0,"tv":0.0,"id":60443},{"batb":[[0,1.51,16.81],[1,1.5,20],[2,1.09,222.22]],"ltp":0.0,"tv":0.0,"id":475559}]}]}
{"op":"mcm","clk":"11884768621","pt":1724088910720,"mc":[{"id":"1.231875523","rc":[{"batb":[[0,1.5,20],[1,1.09,222.22],[2,1.03,199]],"ltp":1.03,"tv":2.0,"id":31378},{"batb":[[0,1.35,56.34],[1,1.3,20],[2,1.09,222.22]],"ltp":0.0,"tv":0.0,"id":60443},{"batb":[[0,1.5,20],[1,1.09,222.22],[2,1.03,200]],"ltp":0.0,"tv":0.0,"id":475559}]}]}
{"op":"mcm","clk":"11884768835","pt":1724088912197,"mc":[{"id":"1.231875523","rc":[{"batb":[[0,1.51,16.81],[1,1.5,20],[2,1.09,222.22]],"ltp":1.03,"tv":2.0,"id":31378},{"batb":[[0,1.36,24.71],[1,1.35,55.45],[2,1.3,20]],"ltp":0.0,"tv":0.0,"id":60443},{"batb":[[0,1.51,16.81],[1,1.5,20],[2,1.09,222.22]],"ltp":0.0,"tv":0.0,"id":475559}]}]}
{"op":"mcm","clk":"11884942312","pt":1724090712864,"mc":[{"id":"1.231875523","rc":[{"batb":[[0,1.5,20],[1,1.09,222.22],[2,1.03,199]],"ltp":1.03,"tv":2.0,"id":31378},{"batb":[[0,1.35,56.32],[1,1.3,20],[2,1.09,222.22]],"ltp":0.0,"tv":0.0,"id":60443},{"batb":[[0,1.5,20],[1,1.09,222.22],[2,1.03,200]],"ltp":0.0,"tv":0.0,"id":475559}]}]}
{"op":"mcm","clk":"11884959596","pt":1724090857720,"mc":[{"id":"1.231875523","rc":[{"batb":[[0,1.51,16.8],[1,1.5,20],[2,1.09,222.22]],"ltp":1.03,"tv":2.0,"id":31378},{"batb":[[0,1.36,24.7],[1,1.35,55.42],[2,1.3,20]],"ltp":0.0,"tv":0.0,"id":60443},{"batb":[[0,1.51,16.8],[1,1.5,20],[2,1.09,222.22]],"ltp":0.0,"tv":0.0,"id":475559}]}]}
{"op":"mcm","clk":"11885193236","pt":1724092657989,"mc":[{"id":"1.231875523","rc":[{"batb":[[0,1.35,56.32],[1,1.3,20],[2,1.09,222.22]],"ltp":0.0,"tv":0.0,"id":60443}]}]}
{"op":"mcm","clk":"11885193286","pt":1724092658398,"mc":[{"id":"1.231875523","rc":[{"batb":[[0,1.5,20],[1,1.09,222.22],[2,1.03,199]],"ltp":1.03,"tv":2.0,"id":31378},{"batb":[[0,1.5,20],[1,1.09,222.22],[2,1.03,200]],"ltp":0.0,"tv":0.0,"id":475559}]}]}
{"op":"mcm","clk":"11885206139","pt":1724092760008,"mc":[{"id":"1.231875523","rc":[{"batb":[[0,1.51,16.8],[1,1.5,20],[2,1.09,222.22]],"ltp":1.03,"tv":2.0,"id":31378},{"batb":[[0,1.51,16.8],[1,1.5,20],[2,1.09,222.22]],"ltp":0.0,"tv":0.0,"id":475559},{"batb":[[0,1.36,24.7],[1,1.35,55.42],[2,1.3,20]],"ltp":0.0,"tv":0.0,"id":60443}]}]}
{"op":"mcm","clk":"11885400953","pt":1724094560427,"mc":[{"id":"1.231875523","rc":[{"batb":[[0,1.51,16.81]],"ltp":1.03,"tv":2.0,"id":31378},{"batb":[[0,1.5,20],[1,1.09,222.22],[2,1.03,200]],"ltp":0.0,"tv":0.0,"id":475559},{"batb":[[0,1.35,56.34],[1,1.3,20],[2,1.09,222.22]],"ltp":0.0,"tv":0.0,"id":60443}]}]}
{"op":"mcm","clk":"11885401049","pt":1724094561217,"mc":[{"id":"1.231875523","rc":[{"batb":[[0,1.5,20],[1,1.09,222.22],[2,1.03,199]],"ltp":1.03,"tv":2.0,"id":31378}]}]}
{"op":"mcm","clk":"11885408644","pt":1724094629034,"mc":[{"id":"1.231875523","rc":[{"batb":[[0,1.51,16.81],[1,1.5,20],[2,1.09,222.22]],"ltp":1.03,"tv":2.0,"id":31378},{"batb":[[0,1.51,16.81],[1,1.5,20],[2,1.09,222.22]],"ltp":0.0,"tv":0.0,"id":475559},{"batb":[[0,1.36,24.71],[1,1.35,55.44],[2,1.3,20]],"ltp":0.0,"tv":0.0,"id":60443}]}]}
{"op":"mcm","clk":"11885602934","pt":1724096429683,"mc":[{"id":"1.231875523","rc":[{"batb":[[0,1.5,20],[1,1.09,222.22],[2,1.03,199]],"ltp":1.03,"tv":2.0,"id":31378},{"batb":[[0,1.5,20],[1,1.09,222.22],[2,1.03,200]],"ltp":0.0,"tv":0.0,"id":475559},{"batb":[[0,1.35,56.34],[1,1.3,20],[2,1.09,222.22]],"ltp":0.0,"tv":0.0,"id":60443}]}]}
{"op":"mcm","clk":"11885609120","pt":1724096501619,"mc":[{"id":"1.231875523","rc":[{"batb":[[0,1.51,16.81],[1,1.5,20],[2,1.09,222.22]],"ltp":1.03,"tv":2.0,"id":31378},{"batb":[[0,1.51,16.81],[1,1.5,20],[2,1.09,222.22]],"ltp":0.0,"tv":0.0,"id":475559},{"batb":[[0,1.36,24.71],[1,1.35,55.44],[2,1.3,20]],"ltp":0.0,"tv":0.0,"id":60443}]}]}
{"op":"mcm","clk":"11885768067","pt":1724098302012,"mc":[{"id":"1.231875523","rc":[{"batb":[[0,1.51,16.81]],"ltp":1.03,"tv":2.0,"id":31378},{"batb":[[0,1.5,20],[1,1.09,222.22],[2,1.03,200]],"ltp":0.0,"tv":0.0,"id":475559},{"batb":[[0,1.35,56.36],[1,1.3,20],[2,1.09,222.22]],"ltp":0.0,"tv":0.0,"id":60443}]}]}
{"op":"mcm","clk":"11885768080","pt":1724098302220,"mc":[{"id":"1.231875523","rc":[{"batb":[[0,1.5,20],[1,1.09,222.22],[2,1.03,199]],"ltp":1.03,"tv":2.0,"id":31378}]}]}
{"op":"mcm","clk":"11885774380","pt":1724098386185,"mc":[{"id":"1.231875523","rc":[{"batb":[[0,1.51,16.81],[1,1.5,20],[2,1.09,222.22]],"ltp":1.03,"tv":2.0,"id":31378},{"batb":[[0,1.51,16.81],[1,1.5,20],[2,1.09,222.22]],"ltp":0.0,"tv":0.0,"id":475559},{"batb":[[0,1.36,24.72],[1,1.35,55.46],[2,1.3,20]],"ltp":0.0,"tv":0.0,"id":60443}]}]}
{"op":"mcm","clk":"11885926359","pt":1724100186756,"mc":[{"id":"1.231875523","rc":[{"batb":[[0,1.5,20],[1,1.09,222.22],[2,1.03,199]],"ltp":1.03,"tv":2.0,"id":31378},{"batb":[[0,1.5,20],[1,1.09,222.22],[2,1.03,200]],"ltp":0.0,"tv":0.0,"id":475559},{"batb":[[0,1.35,56.36],[1,1.3,20],[2,1.09,222.22]],"ltp":0.0,"tv":0.0,"id":60443}]}]}
{"op":"mcm","clk":"11885928874","pt":1724100220271,"mc":[{"id":"1.231875523","rc":[{"batb":[[0,1.51,16.81],[1,1.5,20],[2,1.09,222.22]],"ltp":1.03,"tv":2.0,"id":31378},{"batb":[[0,1.51,16.81],[1,1.5,20],[2,1.09,222.22]],"ltp":0.0,"tv":0.0,"id":475559},{"batb":[[0,1.36,24.72],[1,1.35,55.46],[2,1.3,20]],"ltp":0.0,"tv":0.0,"id":60443}]}]}
{"op":"mcm","clk":"11886016260","pt":1724101975038,"mc":[{"id":"1.231875523","rc":[{"batb":[[0,1.51,16.82]],"ltp":1.03,"tv":2.0,"id":31378},{"batb":[[0,1.51,16.82]],"ltp":0.0,"tv":0.0,"id":475559},{"batb":[[0,1.36,24.72]],"ltp":0.0,"tv":0.0,"id":60443}]}]}
{"op":"mcm","clk":"11886021226","pt":1724102020877,"mc":[{"id":"1.231875523","rc":[{"batb":[[0,1.5,20],[1,1.09,222.22],[2,1.03,199]],"ltp":1.03,"tv":2.0,"id":31378},{"batb":[[0,1.5,20],[1,1.09,222.22],[2,1.03,200]],"ltp":0.0,"tv":0.0,"id":475559},{"batb":[[0,1.35,56.36],[1,1.3,20],[2,1.09,222.22]],"ltp":0.0,"tv":0.0,"id":60443}]}]}
{"op":"mcm","clk":"11886027662","pt":1724102168733,"mc":[{"id":"1.231875523","rc":[{"batb":[[0,1.51,16.82],[1,1.5,20],[2,1.09,222.22]],"ltp":1.03,"tv":2.0,"id":31378},{"batb":[[0,1.51,16.82],[1,1.5,20],[2,1.09,222.22]],"ltp":0.0,"tv":0.0,"id":475559},{"batb":[[0,1.36,24.72],[1,1.35,55.46],[2,1.3,20]],"ltp":0.0,"tv":0.0,"id":60443}]}]}
{"op":"mcm","clk":"11886107007","pt":1724103969033,"mc":[{"id":"1.231875523","rc":[{"batb":[[0,1.5,20],[1,1.09,222.22],[2,1.03,199]],"ltp":1.03,"tv":2.0,"id":31378}]}]}
{"op":"mcm","clk":"11886107027","pt":1724103969398,"mc":[{"id":"1.231875523","rc":[{"batb":[[0,1.5,20],[1,1.09,222.22],[2,1.03,200]],"ltp":0.0,"tv":0.0,"id":475559},{"batb":[[0,1.35,56.36],[1,1.3,20],[2,1.09,222.22]],"ltp":0.0,"tv":0.0,"id":60443}]}]}
{"op":"mcm","clk":"11886113255","pt":1724104090508,"mc":[{"id":"1.231875523","rc":[{"batb":[[0,1.51,16.82],[1,1.5,20],[2,1.09,222.22]],"ltp":1.03,"tv":2.0,"id":31378},{"batb":[[0,1.51,16.82],[1,1.5,20],[2,1.09,222.22]],"ltp":0.0,"tv":0.0,"id":475559},{"batb":[[0,1.36,24.72],[1,1.35,55.46],[2,1.3,20]],"ltp":0.0,"tv":0.0,"id":60443}]}]}
{"op":"mcm","clk":"11886193818","pt":1724105890675,"mc":[{"id":"1.231875523","rc":[{"batb":[[0,1.5,20],[1,1.09,222.22],[2,1.03,199]],"ltp":1.03,"tv":2.0,"id":31378},{"batb":[[0,1.51,16.82]],"ltp":0.0,"tv":0.0,"id":475559},{"batb":[[0,1.36,24.72],[1,1.35,55.47]],"ltp":0.0,"tv":0.0,"id":60443}]}]}
{"op":"mcm","clk":"11886193852","pt":1724105891547,"mc":[{"id":"1.231875523","rc":[{"batb":[[0,1.5,20],[1,1.09,222.22],[2,1.03,200]],"ltp":0.0,"tv":0.0,"id":475559},{"batb":[[0,1.35,56.36],[1,1.3,20],[2,1.09,222.22]],"ltp":0.0,"tv":0.0,"id":60443}]}]}
{"op":"mcm","clk":"11886197240","pt":1724105989075,"mc":[{"id":"1.231875523","rc":[{"batb":[[0,1.51,16.82],[1,1.5,20],[2,1.09,222.22]],"ltp":1.03,"tv":2.0,"id":31378},{"batb":[[0,1.51,16.82],[1,1.5,20],[2,1.09,222.22]],"ltp":0.0,"tv":0.0,"id":475559}]}]}
{"op":"mcm","clk":"11886197242","pt":1724105989176,"mc":[{"id":"1.231875523","rc":[{"batb":[[0,1.36,24.72],[1,1.35,55.47],[2,1.3,20]],"ltp":0.0,"tv":0.0,"id":60443}]}]}
{"op":"mcm","clk":"11886267649","pt":1724107789464,"mc":[{"id":"1.231875523","rc":[{"batb":[[0,1.5,20],[1,1.09,222.22],[2,1.03,199]],"ltp":1.03,"tv":2.0,"id":31378},{"batb":[[0,1.35,56.36],[1,1.3,20],[2,1.09,222.22]],"ltp":0.0,"tv":0.0,"id":60443},{"batb":[[0,1.5,20],[1,1.09,222.22],[2,1.03,200]],"ltp":0.0,"tv":0.0,"id":475559}]}]}
{"op":"mcm","clk":"11886270315","pt":1724107870658,"mc":[{"id":"1.231875523","rc":[{"batb":[[0,1.51,16.82],[1,1.5,20],[2,1.09,222.22]],"ltp":1.03,"tv":2.0,"id":31378},{"batb":[[0,1.36,24.72],[1,1.35,55.47],[2,1.3,20]],"ltp":0.0,"tv":0.0,"id":60443},{"batb":[[0,1.51,16.82],[1,1.5,20],[2,1.09,222.22]],"ltp":0.0,"tv":0.0,"id":475559}]}]}
{"op":"mcm","clk":"11886341837","pt":1724109671052,"mc":[{"id":"1.231875523","rc":[{"batb":[[0,1.5,20],[1,1.09,222.22],[2,1.03,199]],"ltp":1.03,"tv":2.0,"id":31378},{"batb":[[0,1.35,56.37],[1,1.3,20],[2,1.09,222.22]],"ltp":0.0,"tv":0.0,"id":60443}]}]}
{"op":"mcm","clk":"11886341850","pt":1724109671258,"mc":[{"id":"1.231875523","rc":[{"batb":[[0,1.5,20],[1,1.09,222.22],[2,1.03,200]],"ltp":0.0,"tv":0.0,"id":475559}]}]}
{"op":"mcm","clk":"11886345166","pt":1724109744173,"mc":[{"id":"1.231875523","rc":[{"batb":[[0,1.51,16.82],[1,1.5,20],[2,1.09,222.22]],"ltp":1.03,"tv":2.0,"id":31378},{"batb":[[0,1.36,24.72],[1,1.35,55.47],[2,1.3,20]],"ltp":0.0,"tv":0.0,"id":60443},{"batb":[[0,1.51,16.82],[1,1.5,20],[2,1.09,222.22]],"ltp":0.0,"tv":0.0,"id":475559}]}]}
{"op":"mcm","clk":"11886424327","pt":1724111544924,"mc":[{"id":"1.231875523","rc":[{"batb":[[0,1.5,20],[1,1.09,222.22],[2,1.03,199]],"ltp":1.03,"tv":2.0,"id":31378},{"batb":[[0,1.35,56.37],[1,1.3,20],[2,1.09,222.22]],"ltp":0.0,"tv":0.0,"id":60443},{"batb":[[0,1.5,20],[1,1.09,222.22],[2,1.03,200]],"ltp":0.0,"tv":0.0,"id":475559}]}]}
{"op":"mcm","clk":"11886426410","pt":1724111599582,"mc":[{"id":"1.231875523","rc":[{"batb":[[0,1.51,16.82],[1,1.5,20],[2,1.09,222.22]],"ltp":1.03,"tv":2.0,"id":31378},{"batb":[[0,1.36,24.72],[1,1.35,55.47],[2,1.3,20]],"ltp":0.0,"tv":0.0,"id":60443},{"batb":[[0,1.51,16.82],[1,1.5,20],[2,1.09,222.22]],"ltp":0.0,"tv":0.0,"id":475559}]}]}
{"op":"mcm","clk":"11886484087","pt":1724112775053,"mc":[{"id":"1.231875523","rc":[{"batb":[[0,1.36,24.72]],"ltp":0.0,"tv":0.0,"id":60443}]}]}
{"op":"mcm","clk":"11886515962","pt":1724113399971,"mc":[{"id":"1.231875523","rc":[{"batb":[[0,1.5,20],[1,1.09,222.22],[2,1.03,200]],"ltp":0.0,"tv":0.0,"id":475559},{"batb":[[0,1.35,56.37],[1,1.3,20],[2,1.09,222.22]],"ltp":0.0,"tv":0.0,"id":60443}]}]}
{"op":"mcm","clk":"11886515979","pt":1724113400182,"mc":[{"id":"1.231875523","rc":[{"batb":[[0,1.5,20],[1,1.09,222.22],[2,1.03,199]],"ltp":1.03,"tv":2.0,"id":31378}]}]}
{"op":"mcm","clk":"11886518123","pt":1724113430639,"mc":[{"id":"1.231875523","rc":[{"batb":[[0,1.51,16.82],[1,1.5,20],[2,1.09,222.22]],"ltp":1.03,"tv":2.0,"id":31378},{"batb":[[0,1.51,16.82],[1,1.5,20],[2,1.09,222.22]],"ltp":0.0,"tv":0.0,"id":475559},{"batb":[[0,1.36,24.72],[1,1.35,55.47],[2,1.3,20]],"ltp":0.0,"tv":0.0,"id":60443}]}]}
{"op":"mcm","clk":"11886598974","pt":1724115231053,"mc":[{"id":"1.231875523","rc":[{"batb":[[0,1.5,20],[1,1.09,222.22],[2,1.03,199]],"ltp":1.03,"tv":2.0,"id":31378},{"batb":[[0,1.35,56.37],[1,1.3,20],[2,1.09,222.22]],"ltp":0.0,"tv":0.0,"id":60443}]}]}
{"op":"mcm","clk":"11886598981","pt":1724115231349,"mc":[{"id":"1.231875523","rc":[{"batb":[[0,1.5,20],[1,1.09,222.22],[2,1.03,200]],"ltp":0.0,"tv":0.0,"id":475559}]}]}
{"op":"mcm","clk":"11886599257","pt":1724115239352,"mc":[{"id":"1.231875523","rc":[{"batb":[[0,1.51,16.82],[1,1.5,20],[2,1.09,222.22]],"ltp":1.03,"tv":2.0,"id":31378},{"batb":[[0,1.51,16.82],[1,1.5,20],[2,1.09,222.22]],"ltp":0.0,"tv":0.0,"id":475559},{"batb":[[0,1.36,24.72],[1,1.35,55.47],[2,1.3,20]],"ltp":0.0,"tv":0.0,"id":60443}]}]}
{"op":"mcm","clk":"11886679833","pt":1724117040003,"mc":[{"id":"1.231875523","rc":[{"batb":[[0,1.5,20],[1,1.09,222.22],[2,1.03,199]],"ltp":1.03,"tv":2.0,"id":31378},{"batb":[[0,1.5,20],[1,1.09,222.22],[2,1.03,200]],"ltp":0.0,"tv":0.0,"id":475559},{"batb":[[0,1.35,56.37],[1,1.3,20],[2,1.09,222.22]],"ltp":0.0,"tv":0.0,"id":60443}]}]}
{"op":"mcm","clk":"11886685515","pt":1724117166625,"mc":[{"id":"1.231875523","rc":[{"batb":[[0,1.51,16.82],[1,1.5,20],[2,1.09,222.22]],"ltp":1.03,"tv":2.0,"id":31378},{"batb":[[0,1.51,16.82],[1,1.5,20],[2,1.09,222.22]],"ltp":0.0,"tv":0.0,"id":475559},{"batb":[[0,1.36,24.72],[1,1.35,55.47],[2,1.3,20]],"ltp":0.0,"tv":0.0,"id":60443}]}]}
{"op":"mcm","clk":"11886770644","pt":1724118966903,"mc":[{"id":"1.231875523","rc":[{"batb":[[0,1.5,20],[1,1.09,222.22],[2,1.03,200]],"ltp":0.0,"tv":0.0,"id":475559}]}]}
{"op":"mcm","clk":"11886770658","pt":1724118967161,"mc":[{"id":"1.231875523","rc":[{"batb":[[0,1.35,56.37],[1,1.3,20],[2,1.09,222.22]],"ltp":0.0,"tv":0.0,"id":60443}]}]}
{"op":"mcm","clk":"11886770709","pt":1724118968495,"mc":[{"id":"1.231875523","rc":[{"batb":[[0,1.5,20],[1,1.09,222.22],[2,1.03,199]],"ltp":1.03,"tv":2.0,"id":31378}]}]}
{"op":"mcm","clk":"11886774101","pt":1724119050592,"mc":[{"id":"1.231875523","rc":[{"batb":[[0,1.51,16.82],[1,1.5,20],[2,1.09,222.22]],"ltp":1.03,"tv":2.0,"id":31378},{"batb":[[0,1.36,24.72],[1,1.35,55.47],[2,1.3,20]],"ltp":0.0,"tv":0.0,"id":60443},{"batb":[[0,1.51,16.82],[1,1.5,20],[2,1.09,222.22]],"ltp":0.0,"tv":0.0,"id":475559}]}]}
{"op":"mcm","clk":"11886835908","pt":1724120850924,"mc":[{"id":"1.231875523","rc":[{"batb":[[0,1.51,16.82]],"ltp":1.03,"tv":2.0,"id":31378},{"batb":[[0,1.35,56.39],[1,1.3,20],[2,1.09,222.22]],"ltp":0.0,"tv":0.0,"id":60443},{"batb":[[0,1.5,20],[1,1.09,222.22],[2,1.03,200]],"ltp":0.0,"tv":0.0,"id":475559}]}]}
{"op":"mcm","clk":"11886835931","pt":1724120851641,"mc":[{"id":"1.231875523","rc":[{"batb":[[0,1.5,20],[1,1.09,222.22],[2,1.03,199]],"ltp":1.03,"tv":2.0,"id":31378}]}]}
{"op":"mcm","clk":"11886837904","pt":1724120911473,"mc":[{"id":"1.231875523","rc":[{"batb":[[0,1.51,16.82],[1,1.5,20],[2,1.09,222.22]],"ltp":1.03,"tv":2.0,"id":31378},{"batb":[[0,1.36,24.73],[1,1.35,55.49],[2,1.3,20]],"ltp":0.0,"tv":0.0,"id":60443},{"batb":[[0,1.51,16.82],[1,1.5,20],[2,1.09,222.22]],"ltp":0.0,"tv":0.0,"id":475559}]}]}
{"op":"mcm","clk":"11886924593","pt":1724123575112,"mc":[{"id":"1.231875523","rc":[{"batb":[[0,1.51,16.82]],"ltp":1.03,"tv":2.0,"id":31378},{"batb":[[0,1.36,24.72],[1,1.35,55.47]],"ltp":0.0,"tv":0.0,"id":60443},{"batb":[[0,1.51,16.82]],"ltp":0.0,"tv":0.0,"id":475559}]}]}
{"op":"mcm","clk":"11886928584","pt":1724123618787,"mc":[{"id":"1.231875523","rc":[{"batb":[[0,1.5,20],[1,1.09,222.22],[2,1.03,199]],"ltp":1.03,"tv":2.0,"id":31378},{"batb":[[0,1.35,56.37],[1,1.3,20],[2,1.09,222.22]],"ltp":0.0,"tv":0.0,"id":60443},{"batb":[[0,1.5,20],[1,1.09,222.22],[2,1.03,200]],"ltp":0.0,"tv":0.0,"id":475559}]}]}
{"op":"mcm","clk":"11886932284","pt":1724123739796,"mc":[{"id":"1.231875523","rc":[{"batb":[[0,1.51,16.82],[1,1.5,20],[2,1.09,222.22]],"ltp":1.03,"tv":2.0,"id":31378},{"batb":[[0,1.36,24.72],[1,1.35,55.47],[2,1.3,20]],"ltp":0.0,"tv":0.0,"id":60443},{"batb":[[0,1.51,16.82],[1,1.5,20],[2,1.09,222.22]],"ltp":0.0,"tv":0.0,"id":475559}]}]}
{"op":"mcm","clk":"11886990304","pt":1724125542708,"mc":[{"id":"1.231875523","rc":[{"batb":[[0,1.5,20],[1,1.09,222.22],[2,1.03,199]],"ltp":1.03,"tv":2.0,"id":31378},{"batb":[[0,1.35,56.37],[1,1.3,20],[2,1.09,222.22]],"ltp":0.0,"tv":0.0,"id":60443},{"batb":[[0,1.5,20],[1,1.09,222.22],[2,1.03,200]],"ltp":0.0,"tv":0.0,"id":475559}]}]}
{"op":"mcm","clk":"11886990529","pt":1724125557198,"mc":[{"id":"1.231875523","rc":[{"batb":[[0,1.51,16.82],[1,1.5,20],[2,1.09,222.22]],"ltp":1.03,"tv":2.0,"id":31378},{"batb":[[0,1.36,24.72],[1,1.35,55.47],[2,1.3,20]],"ltp":0.0,"tv":0.0,"id":60443},{"batb":[[0,1.51,16.82],[1,1.5,20],[2,1.09,222.22]],"ltp":0.0,"tv":0.0,"id":475559}]}]}
{"op":"mcm","clk":"11887045796","pt":1724127358674,"mc":[{"id":"1.231875523","rc":[{"batb":[[0,1.5,20],[1,1.09,222.22],[2,1.03,199]],"ltp":1.03,"tv":2.0,"id":31378},{"batb":[[0,1.35,56.37],[1,1.3,20],[2,1.09,222.22]],"ltp":0.0,"tv":0.0,"id":60443},{"batb":[[0,1.5,20],[1,1.09,222.22],[2,1.03,200]],"ltp":0.0,"tv":0.0,"id":475559}]}]}
{"op":"mcm","clk":"11887045880","pt":1724127362876,"mc":[{"id":"1.231875523","rc":[{"batb":[[0,1.51,16.82],[1,1.5,20],[2,1.09,222.22]],"ltp":1.03,"tv":2.0,"id":31378},{"batb":[[0,1.36,24.72],[1,1.35,55.47],[2,1.3,20]],"ltp":0.0,"tv":0.0,"id":60443},{"batb":[[0,1.51,16.82],[1,1.5,20],[2,1.09,222.22]],"ltp":0.0,"tv":0.0,"id":475559}]}]}
{"op":"mcm","clk":"11887111233","pt":1724129163938,"mc":[{"id":"1.231875523","rc":[{"batb":[[0,1.5,20],[1,1.09,222.22],[2,1.03,199]],"ltp":1.03,"tv":2.0,"id":31378},{"batb":[[0,1.5,20],[1,1.09,222.22],[2,1.03,200]],"ltp":0.0,"tv":0.0,"id":475559}]}]}
{"op":"mcm","clk":"11887111241","pt":1724129164143,"mc":[{"id":"1.231875523","rc":[{"batb":[[0,1.35,56.37],[1,1.3,20],[2,1.09,222.22]],"ltp":0.0,"tv":0.0,"id":60443}]}]}
{"op":"mcm","clk":"11887116872","pt":1724129313443,"mc":[{"id":"1.231875523","rc":[{"batb":[[0,1.51,16.82],[1,1.5,20],[2,1.09,222.22]],"ltp":1.03,"tv":2.0,"id":31378},{"batb":[[0,1.51,16.82],[1,1.5,20],[2,1.09,222.22]],"ltp":0.0,"tv":0.0,"id":475559},{"batb":[[0,1.36,24.72],[1,1.35,55.47],[2,1.3,20]],"ltp":0.0,"tv":0.0,"id":60443}]}]}
{"op":"mcm","clk":"11887186184","pt":1724131115072,"mc":[{"id":"1.231875523","rc":[{"batb":[[0,1.5,20],[1,1.09,222.22],[2,1.03,199]],"ltp":1.03,"tv":2.0,"id":31378},{"batb":[[0,1.35,56.37],[1,1.3,20],[2,1.09,222.22]],"ltp":0.0,"tv":0.0,"id":60443}]}]}
{"op":"mcm","clk":"11887186188","pt":1724131115126,"mc":[{"id":"1.231875523","rc":[{"batb":[[0,1.5,20],[1,1.09,222.22],[2,1.03,200]],"ltp":0.0,"tv":0.0,"id":475559}]}]}
{"op":"mcm","clk":"11887189780","pt":1724131180317,"mc":[{"id":"1.231875523","rc":[{"batb":[[0,1.51,16.82],[1,1.5,20],[2,1.09,222.22]],"ltp":1.03,"tv":2.0,"id":31378},{"batb":[[0,1.51,16.82],[1,1.5,20],[2,1.09,222.22]],"ltp":0.0,"tv":0.0,"id":475559},{"batb":[[0,1.36,24.72],[1,1.35,55.47],[2,1.3,20]],"ltp":0.0,"tv":0.0,"id":60443}]}]}
{"op":"mcm","clk":"11887253383","pt":1724132980888,"mc":[{"id":"1.231875523","rc":[{"batb":[[0,1.5,20],[1,1.09,222.22],[2,1.03,199]],"ltp":1.03,"tv":2.0,"id":31378},{"batb":[[0,1.5,20],[1,1.09,222.22],[2,1.03,200]],"ltp":0.0,"tv":0.0,"id":475559},{"batb":[[0,1.35,56.37],[1,1.3,20],[2,1.09,222.22]],"ltp":0.0,"tv":0.0,"id":60443}]}]}
{"op":"mcm","clk":"11887255565","pt":1724133047257,"mc":[{"id":"1.231875523","rc":[{"batb":[[0,1.51,16.82],[1,1.5,20],[2,1.09,222.22]],"ltp":1.03,"tv":2.0,"id":31378},{"batb":[[0,1.51,16.82],[1,1.5,20],[2,1.09,222.22]],"ltp":0.0,"tv":0.0,"id":475559},{"batb":[[0,1.36,24.72],[1,1.35,55.47],[2,1.3,20]],"ltp":0.0,"tv":0.0,"id":60443}]}]}
{"op":"mcm","clk":"11887315534","pt":1724134375061,"mc":[{"id":"1.231875523","rc":[{"batb":[[0,1.51,16.82]],"ltp":1.03,"tv":2.0,"id":31378},{"batb":[[0,1.51,16.82]],"ltp":0.0,"tv":0.0,"id":475559},{"batb":[[0,1.36,24.72],[1,1.35,55.47]],"ltp":0.0,"tv":0.0,"id":60443}]}]}
{"op":"mcm","clk":"11887335240","pt":1724134849952,"mc":[{"id":"1.231875523","rc":[{"batb":[[0,1.5,20],[1,1.09,222.22],[2,1.03,200]],"ltp":0.0,"tv":0.0,"id":475559},{"batb":[[0,1.35,56.36],[1,1.3,20],[2,1.09,222.22]],"ltp":0.0,"tv":0.0,"id":60443}]}]}
{"op":"mcm","clk":"11887335245","pt":1724134850155,"mc":[{"id":"1.231875523","rc":[{"batb":[[0,1.5,20],[1,1.09,222.22],[2,1.03,199]],"ltp":1.03,"tv":2.0,"id":31378}]}]}
{"op":"mcm","clk":"11887337308","pt":1724134912917,"mc":[{"id":"1.231875523","rc":[{"batb":[[0,1.51,16.82],[1,1.5,20],[2,1.09,222.22]],"ltp":1.03,"tv":2.0,"id":31378},{"batb":[[0,1.51,16.82],[1,1.5,20],[2,1.09,222.22]],"ltp":0.0,"tv":0.0,"id":475559},{"batb":[[0,1.36,24.72],[1,1.35,55.47],[2,1.3,20]],"ltp":0.0,"tv":0.0,"id":60443}]}]}
{"op":"mcm","clk":"11887409901","pt":1724136713068,"mc":[{"id":"1.231875523","rc":[{"batb":[[0,1.5,20],[1,1.09,222.22],[2,1.03,199]],"ltp":1.03,"tv":2.0,"id":31378}]}]}
{"op":"mcm","clk":"11887409907","pt":1724136713269,"mc":[{"id":"1.231875523","rc":[{"batb":[[0,1.5,20],[1,1.09,222.22],[2,1.03,200]],"ltp":0.0,"tv":0.0,"id":475559}]}]}
{"op":"mcm","clk":"11887409947","pt":1724136714860,"mc":[{"id":"1.231875523","rc":[{"batb":[[0,1.35,56.36],[1,1.3,20],[2,1.09,222.22]],"ltp":0.0,"tv":0.0,"id":60443}]}]}
{"op":"mcm","clk":"11887411756","pt":1724136776928,"mc":[{"id":"1.231875523","rc":[{"batb":[[0,1.51,16.82],[1,1.5,20],[2,1.09,222.22]],"ltp":1.03,"tv":2.0,"id":31378},{"batb":[[0,1.51,16.82],[1,1.5,20],[2,1.09,222.22]],"ltp":0.0,"tv":0.0,"id":475559},{"batb":[[0,1.36,24.72],[1,1.35,55.47],[2,1.3,20]],"ltp":0.0,"tv":0.0,"id":60443}]}]}
{"op":"mcm","clk":"11887488490","pt":1724138578821,"mc":[{"id":"1.231875523","rc":[{"batb":[[0,1.5,20],[1,1.09,222.22],[2,1.03,199]],"ltp":1.03,"tv":2.0,"id":31378},{"batb":[[0,1.5,20],[1,1.09,222.22],[2,1.03,200]],"ltp":0.0,"tv":0.0,"id":475559},{"batb":[[0,1.35,56.33],[1,1.3,20],[2,1.09,222.22]],"ltp":0.0,"tv":0.0,"id":60443}]}]}
{"op":"mcm","clk":"11887490661","pt":1724138639635,"mc":[{"id":"1.231875523","rc":[{"batb":[[0,1.51,16.81],[1,1.5,20],[2,1.09,222.22]],"ltp":1.03,"tv":2.0,"id":31378},{"batb":[[0,1.51,16.81],[1,1.5,20],[2,1.09,222.22]],"ltp":0.0,"tv":0.0,"id":475559},{"batb":[[0,1.36,24.7],[1,1.35,55.43],[2,1.3,20]],"ltp":0.0,"tv":0.0,"id":60443}]}]}
{"op":"mcm","clk":"11887573240","pt":1724140441668,"mc":[{"id":"1.231875523","rc":[{"batb":[[0,1.5,20],[1,1.09,222.22],[2,1.03,199]],"ltp":1.03,"tv":2.0,"id":31378},{"batb":[[0,1.5,20],[1,1.09,222.22],[2,1.03,200]],"ltp":0.0,"tv":0.0,"id":475559},{"batb":[[0,1.35,56.33],[1,1.3,20],[2,1.09,222.22]],"ltp":0.0,"tv":0.0,"id":60443}]}]}
{"op":"mcm","clk":"11887575640","pt":1724140503909,"mc":[{"id":"1.231875523","rc":[{"batb":[[0,1.51,16.81],[1,1.5,20],[2,1.09,222.22]],"ltp":1.03,"tv":2.0,"id":31378},{"batb":[[0,1.51,16.81],[1,1.5,20],[2,1.09,222.22]],"ltp":0.0,"tv":0.0,"id":475559},{"batb":[[0,1.36,24.7],[1,1.35,55.43],[2,1.3,20]],"ltp":0.0,"tv":0.0,"id":60443}]}]}
{"op":"mcm","clk":"11887662466","pt":1724142304383,"mc":[{"id":"1.231875523","rc":[{"batb":[[0,1.5,20],[1,1.09,222.22],[2,1.03,199]],"ltp":1.03,"tv":2.0,"id":31378},{"batb":[[0,1.5,20],[1,1.09,222.22],[2,1.03,200]],"ltp":0.0,"tv":0.0,"id":475559},{"batb":[[0,1.35,56.32],[1,1.3,20],[2,1.09,222.22]],"ltp":0.0,"tv":0.0,"id":60443}]}]}
{"op":"mcm","clk":"11887669335","pt":1724142441125,"mc":[{"id":"1.231875523","rc":[{"batb":[[0,1.51,16.8],[1,1.5,20],[2,1.09,222.22]],"ltp":1.03,"tv":2.0,"id":31378},{"batb":[[0,1.51,16.8],[1,1.5,20],[2,1.09,222.22]],"ltp":0.0,"tv":0.0,"id":475559},{"batb":[[0,1.36,24.7],[1,1.35,55.42],[2,1.3,20]],"ltp":0.0,"tv":0.0,"id":60443}]}]}
{"op":"mcm","clk":"11887755953","pt":1724144241740,"mc":[{"id":"1.231875523","rc":[{"batb":[[0,1.5,20],[1,1.09,222.22],[2,1.03,199]],"ltp":1.03,"tv":2.0,"id":31378},{"batb":[[0,1.5,20],[1,1.09,222.22],[2,1.03,200]],"ltp":0.0,"tv":0.0,"id":475559},{"batb":[[0,1.35,56.32],[1,1.3,20],[2,1.09,222.22]],"ltp":0.0,"tv":0.0,"id":60443}]}]}
{"op":"mcm","clk":"11887757958","pt":1724144284807,"mc":[{"id":"1.231875523","rc":[{"batb":[[0,1.51,16.8],[1,1.5,20],[2,1.09,222.22]],"ltp":1.03,"tv":2.0,"id":31378},{"batb":[[0,1.51,16.8],[1,1.5,20],[2,1.09,222.22]],"ltp":0.0,"tv":0.0,"id":475559},{"batb":[[0,1.36,24.7],[1,1.35,55.42],[2,1.3,20]],"ltp":0.0,"tv":0.0,"id":60443}]}]}
{"op":"mcm","clk":"11887803471","pt":1724145175046,"mc":[{"id":"1.231875523","rc":[{"batb":[[0,1.51,16.8]],"ltp":1.03,"tv":2.0,"id":31378},{"batb":[[0,1.51,16.8]],"ltp":0.0,"tv":0.0,"id":475559},{"batb":[[0,1.36,24.69],[1,1.35,55.4]],"ltp":0.0,"tv":0.0,"id":60443}]}]}
{"op":"mcm","clk":"11887842088","pt":1724146085933,"mc":[{"id":"1.231875523","rc":[{"batb":[[0,1.5,20],[1,1.09,222.22],[2,1.03,199]],"ltp":1.03,"tv":2.0,"id":31378}]}]}
{"op":"mcm","clk":"11887842105","pt":1724146086242,"mc":[{"id":"1.231875523","rc":[{"batb":[[0,1.5,20],[1,1.09,222.22],[2,1.03,200]],"ltp":0.0,"tv":0.0,"id":475559},{"batb":[[0,1.35,56.29],[1,1.3,20],[2,1.09,222.22]],"ltp":0.0,"tv":0.0,"id":60443}]}]}
{"op":"mcm","clk":"11887843482","pt":1724146121897,"mc":[{"id":"1.231875523","rc":[{"batb":[[0,1.51,16.8],[1,1.5,20],[2,1.09,222.22]],"ltp":1.03,"tv":2.0,"id":31378},{"batb":[[0,1.51,16.8],[1,1.5,20],[2,1.09,222.22]],"ltp":0.0,"tv":0.0,"id":475559},{"batb":[[0,1.36,24.69],[1,1.35,55.4],[2,1.3,20]],"ltp":0.0,"tv":0.0,"id":60443}]}]}
{"op":"mcm","clk":"11887927976","pt":1724147922484,"mc":[{"id":"1.231875523","rc":[{"batb":[[0,1.5,20],[1,1.09,222.22],[2,1.03,199]],"ltp":1.03,"tv":2.0,"id":31378},{"batb":[[0,1.5,20],[1,1.09,222.22],[2,1.03,200]],"ltp":0.0,"tv":0.0,"id":475559},{"batb":[[0,1.35,56.29],[1,1.3,20],[2,1.09,222.22]],"ltp":0.0,"tv":0.0,"id":60443}]}]}
{"op":"mcm","clk":"11887929474","pt":1724147953946,"mc":[{"id":"1.231875523","rc":[{"batb":[[0,1.51,16.8],[1,1.5,20],[2,1.09,222.22]],"ltp":1.03,"tv":2.0,"id":31378},{"batb":[[0,1.51,16.8],[1,1.5,20],[2,1.09,222.22]],"ltp":0.0,"tv":0.0,"id":475559},{"batb":[[0,1.36,24.69],[1,1.35,55.4],[2,1.3,20]],"ltp":0.0,"tv":0.0,"id":60443}]}]}
{"op":"mcm","clk":"11888021516","pt":1724149754768,"mc":[{"id":"1.231875523","rc":[{"batb":[[0,1.5,20],[1,1.09,222.22],[2,1.03,199]],"ltp":1.03,"tv":2.0,"id":31378},{"batb":[[0,1.5,20],[1,1.09,222.22],[2,1.03,200]],"ltp":0.0,"tv":0.0,"id":475559},{"batb":[[0,1.35,56.26],[1,1.3,20],[2,1.09,222.22]],"ltp":0.0,"tv":0.0,"id":60443}]}]}
{"op":"mcm","clk":"11888022890","pt":1724149785692,"mc":[{"id":"1.231875523","rc":[{"batb":[[0,1.51,16.79],[1,1.5,20],[2,1.09,222.22]],"ltp":1.03,"tv":2.0,"id":31378},{"batb":[[0,1.51,16.79],[1,1.5,20],[2,1.09,222.22]],"ltp":0.0,"tv":0.0,"id":475559},{"batb":[[0,1.36,24.67],[1,1.35,55.37],[2,1.3,20]],"ltp":0.0,"tv":0.0,"id":60443}]}]}
{"op":"mcm","clk":"11888116323","pt":1724151586078,"mc":[{"id":"1.231875523","rc":[{"batb":[[0,1.5,20],[1,1.09,222.22],[2,1.04,1.53]],"ltp":1.03,"tv":2.0,"id":31378},{"batb":[[0,1.35,56.26],[1,1.3,20],[2,1.09,222.22]],"ltp":0.0,"tv":0.0,"id":60443}]}]}
{"op":"mcm","clk":"11888116329","pt":1724151586188,"mc":[{"id":"1.231875523","rc":[{"batb":[[0,1.5,20],[1,1.09,222.22],[2,1.04,1.53]],"ltp":0.0,"tv":0.0,"id":475559}]}]}
{"op":"mcm","clk":"11888117081","pt":1724151602093,"mc":[{"id":"1.231875523","rc":[{"batb":[[0,1.51,16.79],[1,1.5,20],[2,1.09,222.22]],"ltp":1.03,"tv":2.0,"id":31378},{"batb":[[0,1.51,16.79],[1,1.5,20],[2,1.09,222.22]],"ltp":0.0,"tv":0.0,"id":475559},{"batb":[[0,1.36,24.67],[1,1.35,55.37],[2,1.3,20]],"ltp":0.0,"tv":0.0,"id":60443}]}]}
{"op":"mcm","clk":"11888212561","pt":1724153402573,"mc":[{"id":"1.231875523","rc":[{"batb":[[0,1.5,20],[1,1.09,222.22],[2,1.04,1.53]],"ltp":1.03,"tv":2.0,"id":31378},{"batb":[[0,1.5,20],[1,1.09,222.22],[2,1.04,1.53]],"ltp":0.0,"tv":0.0,"id":475559},{"batb":[[0,1.35,56.29],[1,1.3,20],[2,1.09,222.22]],"ltp":0.0,"tv":0.0,"id":60443}]}]}
{"op":"mcm","clk":"11888212619","pt":1724153403867,"mc":[{"id":"1.231875523","rc":[{"batb":[[0,1.51,16.79],[1,1.5,20],[2,1.09,222.22]],"ltp":1.03,"tv":2.0,"id":31378},{"batb":[[0,1.51,16.79],[1,1.5,20],[2,1.09,222.22]],"ltp":0.0,"tv":0.0,"id":475559},{"batb":[[0,1.36,24.69],[1,1.35,55.39],[2,1.3,20]],"ltp":0.0,"tv":0.0,"id":60443}]}]}
{"op":"mcm","clk":"11888295293","pt":1724155204733,"mc":[{"id":"1.231875523","rc":[{"batb":[[0,1.5,20],[1,1.09,222.22],[2,1.04,1.53]],"ltp":1.03,"tv":2.0,"id":31378},{"batb":[[0,1.5,20],[1,1.09,222.22],[2,1.04,1.53]],"ltp":0.0,"tv":0.0,"id":475559},{"batb":[[0,1.35,56.26],[1,1.3,20],[2,1.09,222.22]],"ltp":0.0,"tv":0.0,"id":60443}]}]}
{"op":"mcm","clk":"11888300885","pt":1724155344790,"mc":[{"id":"1.231875523","rc":[{"batb":[[0,1.51,16.78],[1,1.5,20],[2,1.09,222.22]],"ltp":1.03,"tv":2.0,"id":31378},{"batb":[[0,1.51,16.78],[1,1.5,20],[2,1.09,222.22]],"ltp":0.0,"tv":0.0,"id":475559},{"batb":[[0,1.36,24.67],[1,1.35,55.36],[2,1.3,20]],"ltp":0.0,"tv":0.0,"id":60443}]}]}
{"op":"mcm","clk":"11888393874","pt":1724157145622,"mc":[{"id":"1.231875523","rc":[{"batb":[[0,1.5,20],[1,1.09,222.22],[2,1.04,1.53]],"ltp":1.03,"tv":2.0,"id":31378},{"batb":[[0,1.35,56.26],[1,1.3,20],[2,1.09,222.22]],"ltp":0.0,"tv":0.0,"id":60443},{"batb":[[0,1.5,20],[1,1.09,222.22],[2,1.04,1.53]],"ltp":0.0,"tv":0.0,"id":475559}]}]}
{"op":"mcm","clk":"11888395593","pt":1724157179767,"mc":[{"id":"1.231875523","rc":[{"batb":[[0,1.51,16.78],[1,1.5,20],[2,1.09,222.22]],"ltp":1.03,"tv":2.0,"id":31378},{"batb":[[0,1.36,24.67],[1,1.35,55.36],[2,1.3,20]],"ltp":0.0,"tv":0.0,"id":60443},{"batb":[[0,1.51,16.78],[1,1.5,20],[2,1.09,222.22]],"ltp":0.0,"tv":0.0,"id":475559}]}]}
{"op":"mcm","clk":"11888475457","pt":1724158980760,"mc":[{"id":"1.231875523","rc":[{"batb":[[0,1.5,20],[1,1.09,222.22],[2,1.04,1.53]],"ltp":1.03,"tv":2.0,"id":31378},{"batb":[[0,1.35,56.26],[1,1.3,20],[2,1.09,222.22]],"ltp":0.0,"tv":0.0,"id":60443},{"batb":[[0,1.5,20],[1,1.09,222.22],[2,1.04,1.53]],"ltp":0.0,"tv":0.0,"id":475559}]}]}
{"op":"mcm","clk":"11888476461","pt":1724159002499,"mc":[{"id":"1.231875523","rc":[{"batb":[[0,1.51,16.79],[1,1.5,20],[2,1.09,222.22]],"ltp":1.03,"tv":2.0,"id":31378},{"batb":[[0,1.36,24.67],[1,1.35,55.37],[2,1.3,20]],"ltp":0.0,"tv":0.0,"id":60443},{"batb":[[0,1.51,16.79],[1,1.5,20],[2,1.09,222.22]],"ltp":0.0,"tv":0.0,"id":475559}]}]}
{"op":"mcm","clk":"11888568881","pt":1724160802952,"mc":[{"id":"1.231875523","rc":[{"batb":[[0,1.5,20],[1,1.09,222.22],[2,1.04,1.53]],"ltp":1.03,"tv":2.0,"id":31378}]}]}
{"op":"mcm","clk":"11888568906","pt":1724160803468,"mc":[{"id":"1.231875523","rc":[{"batb":[[0,1.35,56.26],[1,1.3,20],[2,1.09,222.22]],"ltp":0.0,"tv":0.0,"id":60443},{"batb":[[0,1.5,20],[1,1.09,222.22],[2,1.04,1.53]],"ltp":0.0,"tv":0.0,"id":475559}]}]}
{"op":"mcm","clk":"11888569396","pt":1724160813786,"mc":[{"id":"1.231875523","rc":[{"batb":[[0,1.51,16.79],[1,1.5,20],[2,1.09,222.22]],"ltp":1.03,"tv":2.0,"id":31378},{"batb":[[0,1.36,24.67],[1,1.35,55.37],[2,1.3,20]],"ltp":0.0,"tv":0.0,"id":60443},{"batb":[[0,1.51,16.79],[1,1.5,20],[2,1.09,222.22]],"ltp":0.0,"tv":0.0,"id":475559}]}]}
{"op":"mcm","clk":"11888667671","pt":1724162614548,"mc":[{"id":"1.231875523","rc":[{"batb":[[0,1.5,20],[1,1.09,222.22],[2,1.04,1.53]],"ltp":1.03,"tv":2.0,"id":31378},{"batb":[[0,1.35,56.28],[1,1.3,20],[2,1.09,222.22]],"ltp":0.0,"tv":0.0,"id":60443},{"batb":[[0,1.5,20],[1,1.09,222.22],[2,1.04,1.53]],"ltp":0.0,"tv":0.0,"id":475559}]}]}
{"op":"mcm","clk":"11888667876","pt":1724162618049,"mc":[{"id":"1.231875523","rc":[{"batb":[[0,1.51,16.79],[1,1.5,20],[2,1.09,222.22]],"ltp":1.03,"tv":2.0,"id":31378},{"batb":[[0,1.36,24.68],[1,1.35,55.39],[2,1.3,20]],"ltp":0.0,"tv":0.0,"id":60443},{"batb":[[0,1.51,16.79],[1,1.5,20],[2,1.09,222.22]],"ltp":0.0,"tv":0.0,"id":475559}]}]}
{"op":"mcm","clk":"11888769808","pt":1724164418696,"mc":[{"id":"1.231875523","rc":[{"batb":[[0,1.5,20],[1,1.09,222.22],[2,1.04,1.53]],"ltp":1.03,"tv":2.0,"id":31378},{"batb":[[0,1.35,56.28],[1,1.3,20],[2,1.09,222.22]],"ltp":0.0,"tv":0.0,"id":60443},{"batb":[[0,1.5,20],[1,1.09,222.22],[2,1.04,1.53]],"ltp":0.0,"tv":0.0,"id":475559}]}]}
{"op":"mcm","clk":"11888780387","pt":1724164575553,"mc":[{"id":"1.231875523","rc":[{"batb":[[0,1.51,16.79],[1,1.5,20],[2,1.09,222.22]],"ltp":1.03,"tv":2.0,"id":31378},{"batb":[[0,1.36,24.68],[1,1.35,55.39],[2,1.3,20]],"ltp":0.0,"tv":0.0,"id":60443},{"batb":[[0,1.51,16.79],[1,1.5,20],[2,1.09,222.22]],"ltp":0.0,"tv":0.0,"id":475559}]}]}
{"op":"mcm","clk":"11888895770","pt":1724166341874,"mc":[{"id":"1.231875523","rc":[{"batb":[[0,1.51,16.8]],"batl":[[0,90,1.02],[1,95,5],[2,990,5]],"ltp":1.03,"tv":2.0,"id":31378},{"batb":[[0,1.36,24.7],[1,1.35,55.43]],"batl":[[0,90,1.02],[1,95,5],[2,990,5]],"ltp":0.0,"tv":0.0,"id":60443},{"batb":[[0,1.51,16.8]],"batl":[[0,90,1.02],[1,95,5],[2,990,5]],"ltp":0.0,"tv":0.0,"id":475559}]}]}
{"op":"mcm","clk":"11888897538","pt":1724166371907,"mc":[{"id":"1.231875523","rc":[{"batl":[[2,990,5.17]],"ltp":1.03,"tv":2.0,"id":31378},{"batl":[[2,990,5.17]],"ltp":0.0,"tv":0.0,"id":60443},{"batl":[[2,990,5.17]],"ltp":0.0,"tv":0.0,"id":475559}]}]}
{"op":"mcm","clk":"11888897786","pt":1724166376043,"mc":[{"id":"1.231875523","rc":[{"batb":[[0,1.5,20],[1,1.09,222.22],[2,1.04,1.53]],"ltp":1.03,"tv":2.0,"id":31378},{"batb":[[0,1.5,20],[1,1.09,222.22],[2,1.04,1.53]],"ltp":0.0,"tv":0.0,"id":475559}]}]}
{"op":"mcm","clk":"11888897797","pt":1724166376238,"mc":[{"id":"1.231875523","rc":[{"batb":[[0,1.35,56.32],[1,1.3,20],[2,1.09,222.22]],"ltp":0.0,"tv":0.0,"id":60443}]}]}
{"op":"mcm","clk":"11888900538","pt":1724166418844,"mc":[{"id":"1.231875523","rc":[{"batl":[[2,990,5.34]],"ltp":1.03,"tv":2.0,"id":31378},{"batl":[[2,990,5.34]],"ltp":0.0,"tv":0.0,"id":60443},{"batl":[[2,990,5.34]],"ltp":0.0,"tv":0.0,"id":475559}]}]}
{"op":"mcm","clk":"11888903641","pt":1724166462221,"mc":[{"id":"1.231875523","rc":[{"batl":[[2,990,5.51]],"ltp":1.03,"tv":2.0,"id":31378},{"batl":[[2,990,5.51]],"ltp":0.0,"tv":0.0,"id":60443},{"batl":[[2,990,5.51]],"ltp":0.0,"tv":0.0,"id":475559}]}]}
{"op":"mcm","clk":"11888907188","pt":1724166515746,"mc":[{"id":"1.231875523","rc":[{"batb":[[0,1.51,16.8],[1,1.5,20],[2,1.09,222.22]],"ltp":1.03,"tv":2.0,"id":31378},{"batb":[[0,1.36,24.7],[1,1.35,55.43],[2,1.3,20]],"ltp":0.0,"tv":0.0,"id":60443},{"batb":[[0,1.51,16.8],[1,1.5,20],[2,1.09,222.22]],"ltp":0.0,"tv":0.0,"id":475559}]}]}
{"op":"mcm","clk":"11889069731","pt":1724168317085,"mc":[{"id":"1.231875523","rc":[{"batb":[[0,1.5,20],[1,1.09,222.22],[2,1.04,1.53]],"ltp":1.03,"tv":2.0,"id":31378}]}]}
{"op":"mcm","clk":"11889069774","pt":1724168317499,"mc":[{"id":"1.231875523","rc":[{"batb":[[0,1.35,56.32],[1,1.3,20],[2,1.09,222.22]],"ltp":0.0,"tv":0.0,"id":60443},{"batb":[[0,1.5,20],[1,1.09,222.22],[2,1.04,1.53]],"ltp":0.0,"tv":0.0,"id":475559}]}]}
{"op":"mcm","clk":"11889080954","pt":1724168445882,"mc":[{"id":"1.231875523","rc":[{"batb":[[0,1.51,16.8],[1,1.5,20],[2,1.09,222.22]],"ltp":1.03,"tv":2.0,"id":31378},{"batb":[[0,1.36,24.7],[1,1.35,55.43],[2,1.3,20]],"ltp":0.0,"tv":0.0,"id":60443},{"batb":[[0,1.51,16.8],[1,1.5,20],[2,1.09,222.22]],"ltp":0.0,"tv":0.0,"id":475559}]}]}
{"op":"mcm","clk":"11889242594","pt":1724170247062,"mc":[{"id":"1.231875523","rc":[{"batb":[[0,1.35,56.32],[1,1.3,20],[2,1.09,222.22]],"ltp":0.0,"tv":0.0,"id":60443},{"batb":[[0,1.5,20],[1,1.09,222.22],[2,1.04,1.53]],"ltp":0.0,"tv":0.0,"id":475559}]}]}
{"op":"mcm","clk":"11889242603","pt":1724170247165,"mc":[{"id":"1.231875523","rc":[{"batb":[[0,1.5,20],[1,1.09,222.22],[2,1.04,1.53]],"ltp":1.03,"tv":2.0,"id":31378}]}]}
{"op":"mcm","clk":"11889253753","pt":1724170363428,"mc":[{"id":"1.231875523","rc":[{"batb":[[0,1.51,16.8],[1,1.5,20],[2,1.09,222.22]],"ltp":1.03,"tv":2.0,"id":31378},{"batb":[[0,1.36,24.7],[1,1.35,55.42],[2,1.3,20]],"ltp":0.0,"tv":0.0,"id":60443},{"batb":[[0,1.51,16.8],[1,1.5,20],[2,1.09,222.22]],"ltp":0.0,"tv":0.0,"id":475559}]}]}
{"op":"mcm","clk":"11889414208","pt":1724172165910,"mc":[{"id":"1.231875523","rc":[{"batb":[[0,1.5,20],[1,1.09,222.22],[2,1.04,1.53]],"ltp":1.03,"tv":2.0,"id":31378},{"batb":[[0,1.35,56.32],[1,1.3,20],[2,1.09,222.22]],"ltp":0.0,"tv":0.0,"id":60443},{"batb":[[0,1.5,20],[1,1.09,222.22],[2,1.04,1.53]],"ltp":0.0,"tv":0.0,"id":475559}]}]}
{"op":"mcm","clk":"11889434436","pt":1724172257022,"mc":[{"id":"1.231875523","rc":[{"batb":[[0,1.51,16.8],[1,1.5,20],[2,1.09,222.22]],"ltp":1.03,"tv":2.0,"id":31378}]}]}
{"op":"mcm","clk":"11889434449","pt":1724172257125,"mc":[{"id":"1.231875523","rc":[{"batb":[[0,1.36,24.7],[1,1.35,55.42],[2,1.3,20]],"ltp":0.0,"tv":0.0,"id":60443},{"batb":[[0,1.51,16.8],[1,1.5,20],[2,1.09,222.22]],"ltp":0.0,"tv":0.0,"id":475559}]}]}
{"op":"mcm","clk":"11889571690","pt":1724173567514,"mc":[{"id":"1.231875523","rc":[{"batb":[[0,1.51,16.82]],"ltp":1.03,"tv":2.0,"id":31378},{"batb":[[0,1.5,1.79],[1,1.36,23.82],[2,1.35,55.47]],"ltp":0.0,"tv":0.0,"id":60443},{"batb":[[0,1.51,16.82]],"ltp":0.0,"tv":0.0,"id":475559}]}]}
{"op":"mcm","clk":"11889632520","pt":1724174059565,"mc":[{"id":"1.231875523","rc":[{"batb":[[0,1.5,20],[1,1.09,222.22],[2,1.04,1.53]],"ltp":1.03,"tv":2.0,"id":31378},{"batb":[[1,1.35,55.47],[2,1.3,20]],"ltp":0.0,"tv":0.0,"id":60443},{"batb":[[0,1.5,20],[1,1.09,222.22],[2,1.04,1.53]],"ltp":0.0,"tv":0.0,"id":475559}]}]}
{"op":"mcm","clk":"11889641485","pt":1724174128251,"mc":[{"id":"1.231875523","rc":[{"batb":[[0,1.51,16.82],[1,1.5,20],[2,1.09,222.22]],"ltp":1.03,"tv":2.0,"id":31378},{"batb":[[0,1.51,17.71],[1,1.35,56.36]],"ltp":0.0,"tv":0.0,"id":60443},{"batb":[[0,1.51,16.82],[1,1.5,20],[2,1.09,222.22]],"ltp":0.0,"tv":0.0,"id":475559}]}]}
{"op":"mcm","clk":"11889867294","pt":1724175928914,"mc":[{"id":"1.231875523","rc":[{"batb":[[0,1.5,20],[1,1.09,222.22],[2,1.04,1.53]],"ltp":1.03,"tv":2.0,"id":31378},{"batb":[[0,1.5,1.79],[1,1.35,55.47]],"ltp":0.0,"tv":0.0,"id":60443},{"batb":[[0,1.5,20],[1,1.09,222.22],[2,1.04,1.53]],"ltp":0.0,"tv":0.0,"id":475559}]}]}
{"op":"mcm","clk":"11889872222","pt":1724175964245,"mc":[{"id":"1.231875523","rc":[{"batb":[[0,1.51,16.82],[1,1.5,20],[2,1.09,222.22]],"ltp":1.03,"tv":2.0,"id":31378},{"batb":[[0,1.51,17.71],[1,1.35,56.36]],"ltp":0.0,"tv":0.0,"id":60443},{"batb":[[0,1.51,16.82],[1,1.5,20],[2,1.09,222.22]],"ltp":0.0,"tv":0.0,"id":475559}]}]}
{"op":"mcm","clk":"11890004473","pt":1724176976924,"mc":[{"id":"1.231875523","rc":[{"batb":[[0,1.51,16.83]],"batl":[[0,85,1.17],[1,95,5.85]],"ltp":1.03,"tv":2.0,"id":31378},{"batb":[[0,1.51,17.72],[1,1.35,56.38]],"ltp":0.0,"tv":0.0,"id":60443},{"batb":[[0,1.51,16.83]],"ltp":0.0,"tv":0.0,"id":475559}]}]}
{"op":"mcm","clk":"11890022384","pt":1724177102779,"mc":[{"id":"1.231875523","rc":[{"batl":[[0,85,1.17],[1,95,5.85]],"ltp":0.0,"tv":0.0,"id":60443}]}]}
{"op":"mcm","clk":"11890024088","pt":1724177113592,"mc":[{"id":"1.231875523","rc":[{"batl":[[0,85,1.17],[1,95,5.85]],"ltp":0.0,"tv":0.0,"id":475559}]}]}
{"op":"mcm","clk":"11890137399","pt":1724177766598,"mc":[{"id":"1.231875523","rc":[{"batb":[[0,1.5,20],[1,1.09,222.22],[2,1.04,1.53]],"ltp":1.03,"tv":2.0,"id":31378},{"batb":[[0,1.5,20],[1,1.09,222.22],[2,1.04,1.53]],"ltp":0.0,"tv":0.0,"id":475559},{"batb":[[0,1.5,1.79],[1,1.35,55.49]],"ltp":0.0,"tv":0.0,"id":60443}]}]}
{"op":"mcm","clk":"11890138393","pt":1724177772406,"mc":[{"id":"1.231875523","rc":[{"batb":[[0,1.51,16.83],[1,1.5,20],[2,1.09,222.22]],"ltp":1.03,"tv":2.0,"id":31378},{"batb":[[0,1.51,16.83],[1,1.5,20],[2,1.09,222.22]],"ltp":0.0,"tv":0.0,"id":475559},{"batb":[[0,1.51,17.72],[1,1.35,56.38]],"ltp":0.0,"tv":0.0,"id":60443}]}]}
{"op":"mcm","clk":"11890401919","pt":1724179573972,"mc":[{"id":"1.231875523","rc":[{"batb":[[0,1.5,20],[1,1.09,222.22],[2,1.04,1.53]],"ltp":1.03,"tv":2.0,"id":31378},{"batb":[[0,1.5,20],[1,1.09,222.22],[2,1.04,1.53]],"ltp":0.0,"tv":0.0,"id":475559},{"batb":[[0,1.5,1.79],[1,1.35,55.49]],"ltp":0.0,"tv":0.0,"id":60443}]}]}
{"op":"mcm","clk":"11890421873","pt":1724179677380,"mc":[{"id":"1.231875523","rc":[{"batb":[[0,1.51,16.83],[1,1.5,20],[2,1.09,222.22]],"ltp":1.03,"tv":2.0,"id":31378},{"batb":[[0,1.51,16.83],[1,1.5,20],[2,1.09,222.22]],"ltp":0.0,"tv":0.0,"id":475559},{"batb":[[0,1.51,17.72],[1,1.35,56.38]],"ltp":0.0,"tv":0.0,"id":60443}]}]}
{"op":"mcm","clk":"11890767542","pt":1724181480017,"mc":[{"id":"1.231875523","rc":[{"batb":[[0,1.5,20],[1,1.09,222.22],[2,1.04,1.53]],"ltp":1.03,"tv":2.0,"id":31378},{"batb":[[0,1.5,20],[1,1.09,222.22],[2,1.04,1.53]],"ltp":0.0,"tv":0.0,"id":475559},{"batb":[[0,1.51,17.71],[1,1.35,56.37]],"ltp":0.0,"tv":0.0,"id":60443}]}]}
{"op":"mcm","clk":"11890767570","pt":1724181480128,"mc":[{"id":"1.231875523","rc":[{"batb":[[0,1.5,1.79],[1,1.35,55.47]],"ltp":0.0,"tv":0.0,"id":60443}]}]}
{"op":"mcm","clk":"11890779200","pt":1724181537892,"mc":[{"id":"1.231875523","rc":[{"batb":[[0,1.51,16.82],[1,1.5,20],[2,1.09,222.22]],"ltp":1.03,"tv":2.0,"id":31378},{"batb":[[0,1.51,16.82],[1,1.5,20],[2,1.09,222.22]],"ltp":0.0,"tv":0.0,"id":475559},{"batb":[[0,1.51,17.71],[1,1.35,56.37]],"ltp":0.0,"tv":0.0,"id":60443}]}]}
{"op":"mcm","clk":"11891087855","pt":1724183339998,"mc":[{"id":"1.231875523","rc":[{"batb":[[0,1.5,20],[1,1.09,222.22],[2,1.04,1.53]],"ltp":0.0,"tv":0.0,"id":475559}]}]}
{"op":"mcm","clk":"11891087912","pt":1724183340367,"mc":[{"id":"1.231875523","rc":[{"batb":[[0,1.5,20],[1,1.09,222.22],[2,1.04,1.53]],"ltp":1.03,"tv":2.0,"id":31378},{"batb":[[0,1.5,1.79],[1,1.35,55.47]],"ltp":0.0,"tv":0.0,"id":60443}]}]}
{"op":"mcm","clk":"11891094104","pt":1724183378124,"mc":[{"id":"1.231875523","rc":[{"batb":[[0,1.51,16.82],[1,1.5,20],[2,1.09,222.22]],"ltp":1.03,"tv":2.0,"id":31378},{"batb":[[0,1.51,16.82],[1,1.5,20],[2,1.09,222.22]],"ltp":0.0,"tv":0.0,"id":475559},{"batb":[[0,1.51,17.71],[1,1.35,56.37]],"ltp":0.0,"tv":0.0,"id":60443}]}]}
{"op":"mcm","clk":"11891386126","pt":1724185180061,"mc":[{"id":"1.231875523","rc":[{"batb":[[0,1.5,20],[1,1.09,222.22],[2,1.04,1.53]],"ltp":1.03,"tv":2.0,"id":31378},{"batb":[[0,1.51,16.82]],"ltp":0.0,"tv":0.0,"id":475559},{"batb":[[0,1.51,17.72],[1,1.35,56.38]],"ltp":0.0,"tv":0.0,"id":60443}]}]}
{"op":"mcm","clk":"11891386175","pt":1724185180376,"mc":[{"id":"1.231875523","rc":[{"batb":[[0,1.5,20],[1,1.09,222.22],[2,1.04,1.53]],"ltp":0.0,"tv":0.0,"id":475559},{"batb":[[0,1.5,1.79],[1,1.35,55.48]],"ltp":0.0,"tv":0.0,"id":60443}]}]}
{"op":"mcm","clk":"11891406589","pt":1724185306644,"mc":[{"id":"1.231875523","rc":[{"batb":[[0,1.51,16.82],[1,1.5,20],[2,1.09,222.22]],"ltp":1.03,"tv":2.0,"id":31378},{"batb":[[0,1.51,16.82],[1,1.5,20],[2,1.09,222.22]],"ltp":0.0,"tv":0.0,"id":475559},{"batb":[[0,1.51,17.72],[1,1.35,56.38]],"ltp":0.0,"tv":0.0,"id":60443}]}]}
{"op":"mcm","clk":"11891593440","pt":1724187109082,"mc":[{"id":"1.231875523","rc":[{"batb":[[0,1.5,20],[1,1.09,222.22],[2,1.04,1.53]],"ltp":1.03,"tv":2.0,"id":31378},{"batb":[[0,1.5,20],[1,1.09,222.22],[2,1.04,1.53]],"ltp":0.0,"tv":0.0,"id":475559}]}]}
{"op":"mcm","clk":"11891593450","pt":1724187109284,"mc":[{"id":"1.231875523","rc":[{"batb":[[0,1.5,1.79],[1,1.35,55.48]],"ltp":0.0,"tv":0.0,"id":60443}]}]}
{"op":"mcm","clk":"11891596889","pt":1724187166328,"mc":[{"id":"1.231875523","rc":[{"batb":[[0,1.51,16.82],[1,1.5,20],[2,1.09,222.22]],"ltp":1.03,"tv":2.0,"id":31378},{"batb":[[0,1.51,16.82],[1,1.5,20],[2,1.09,222.22]],"ltp":0.0,"tv":0.0,"id":475559},{"batb":[[0,1.51,17.72],[1,1.35,56.38]],"ltp":0.0,"tv":0.0,"id":60443}]}]}
{"op":"mcm","clk":"11891677059","pt":1724188375065,"mc":[{"id":"1.231875523","rc":[{"batb":[[0,1.51,16.83]],"ltp":1.03,"tv":2.0,"id":31378},{"batb":[[0,1.51,17.72],[1,1.35,56.4]],"ltp":0.0,"tv":0.0,"id":60443},{"batb":[[0,1.51,16.83]],"ltp":0.0,"tv":0.0,"id":475559}]}]}
{"op":"mcm","clk":"11891712151","pt":1724188966698,"mc":[{"id":"1.231875523","rc":[{"batb":[[0,1.5,20],[1,1.09,222.22],[2,1.04,1.53]],"ltp":1.03,"tv":2.0,"id":31378},{"batb":[[0,1.5,20],[1,1.09,222.22],[2,1.04,1.53]],"ltp":0.0,"tv":0.0,"id":475559}]}]}
{"op":"mcm","clk":"11891712246","pt":1724188968691,"mc":[{"id":"1.231875523","rc":[{"batb":[[0,1.5,1.79],[1,1.35,55.5]],"ltp":0.0,"tv":0.0,"id":60443}]}]}
{"op":"mcm","clk":"11891717130","pt":1724189057722,"mc":[{"id":"1.231875523","rc":[{"batb":[[0,1.51,16.83],[1,1.5,20],[2,1.09,222.22]],"ltp":1.03,"tv":2.0,"id":31378},{"batb":[[0,1.51,17.72],[1,1.35,56.4]],"ltp":0.0,"tv":0.0,"id":60443},{"batb":[[0,1.51,16.83],[1,1.5,20],[2,1.09,222.22]],"ltp":0.0,"tv":0.0,"id":475559}]}]}
{"op":"mcm","clk":"11891815261","pt":1724190858749,"mc":[{"id":"1.231875523","rc":[{"batb":[[0,1.5,20],[1,1.09,222.22],[2,1.04,1.53]],"ltp":1.03,"tv":2.0,"id":31378},{"batb":[[0,1.5,1.79],[1,1.35,55.5]],"ltp":0.0,"tv":0.0,"id":60443},{"batb":[[0,1.5,20],[1,1.09,222.22],[2,1.04,1.53]],"ltp":0.0,"tv":0.0,"id":475559}]}]}
{"op":"mcm","clk":"11891818471","pt":1724190910069,"mc":[{"id":"1.231875523","rc":[{"batb":[[0,1.51,16.83],[1,1.5,20],[2,1.09,222.22]],"ltp":1.03,"tv":2.0,"id":31378},{"batb":[[0,1.51,17.72],[1,1.35,56.4]],"ltp":0.0,"tv":0.0,"id":60443},{"batb":[[0,1.51,16.83],[1,1.5,20],[2,1.09,222.22]],"ltp":0.0,"tv":0.0,"id":475559}]}]}
{"op":"mcm","clk":"11891904103","pt":1724192712905,"mc":[{"id":"1.231875523","rc":[{"batb":[[0,1.5,20],[1,1.09,222.22],[2,1.04,1.53]],"ltp":1.03,"tv":2.0,"id":31378},{"batb":[[0,1.5,1.79],[1,1.35,55.5]],"ltp":0.0,"tv":0.0,"id":60443},{"batb":[[0,1.5,20],[1,1.09,222.22],[2,1.04,1.53]],"ltp":0.0,"tv":0.0,"id":475559}]}]}
{"op":"mcm","clk":"11891905610","pt":1724192748916,"mc":[{"id":"1.231875523","rc":[{"batb":[[0,1.51,16.83],[1,1.5,20],[2,1.09,222.22]],"ltp":1.03,"tv":2.0,"id":31378},{"batb":[[0,1.51,17.72],[1,1.35,56.4]],"ltp":0.0,"tv":0.0,"id":60443},{"batb":[[0,1.51,16.83],[1,1.5,20],[2,1.09,222.22]],"ltp":0.0,"tv":0.0,"id":475559}]}]}
{"op":"mcm","clk":"11892000003","pt":1724194551693,"mc":[{"id":"1.231875523","rc":[{"batb":[[0,1.5,20],[1,1.09,222.22],[2,1.04,1.53]],"ltp":1.03,"tv":2.0,"id":31378},{"batb":[[0,1.5,1.79],[1,1.35,55.5]],"ltp":0.0,"tv":0.0,"id":60443},{"batb":[[0,1.5,20],[1,1.09,222.22],[2,1.04,1.53]],"ltp":0.0,"tv":0.0,"id":475559}]}]}
{"op":"mcm","clk":"11892001029","pt":1724194571035,"mc":[{"id":"1.231875523","rc":[{"batb":[[0,1.51,16.83],[1,1.5,20],[2,1.09,222.22]],"ltp":1.03,"tv":2.0,"id":31378},{"batb":[[0,1.51,17.72],[1,1.35,56.4]],"ltp":0.0,"tv":0.0,"id":60443},{"batb":[[0,1.51,16.83],[1,1.5,20],[2,1.09,222.22]],"ltp":0.0,"tv":0.0,"id":475559}]}]}
{"op":"mcm","clk":"11892097316","pt":1724196372530,"mc":[{"id":"1.231875523","rc":[{"batb":[[0,1.5,20],[1,1.09,222.22],[2,1.04,1.53]],"ltp":1.03,"tv":2.0,"id":31378},{"batb":[[0,1.5,1.79],[1,1.35,55.51]],"ltp":0.0,"tv":0.0,"id":60443},{"batb":[[0,1.5,20],[1,1.09,222.22],[2,1.04,1.53]],"ltp":0.0,"tv":0.0,"id":475559}]}]}
{"op":"mcm","clk":"11892103900","pt":1724196489790,"mc":[{"id":"1.231875523","rc":[{"batb":[[0,1.51,16.83],[1,1.5,20],[2,1.09,222.22]],"ltp":1.03,"tv":2.0,"id":31378},{"batb":[[0,1.51,17.72],[1,1.35,56.4]],"ltp":0.0,"tv":0.0,"id":60443},{"batb":[[0,1.51,16.83],[1,1.5,20],[2,1.09,222.22]],"ltp":0.0,"tv":0.0,"id":475559}]}]}
{"op":"mcm","clk":"11892202198","pt":1724198290937,"mc":[{"id":"1.231875523","rc":[{"batb":[[0,1.5,1.79],[1,1.35,55.51]],"ltp":0.0,"tv":0.0,"id":60443},{"batb":[[0,1.5,20],[1,1.09,222.22],[2,1.04,1.53]],"ltp":0.0,"tv":0.0,"id":475559}]}]}
{"op":"mcm","clk":"11892202212","pt":1724198291141,"mc":[{"id":"1.231875523","rc":[{"batb":[[0,1.5,20],[1,1.09,222.22],[2,1.04,1.53]],"ltp":1.03,"tv":2.0,"id":31378}]}]}
{"op":"mcm","clk":"11892207446","pt":1724198385946,"mc":[{"id":"1.231875523","rc":[{"batb":[[0,1.51,16.83],[1,1.5,20],[2,1.09,222.22]],"ltp":1.03,"tv":2.0,"id":31378},{"batb":[[0,1.51,17.72],[1,1.35,56.4]],"ltp":0.0,"tv":0.0,"id":60443},{"batb":[[0,1.51,16.83],[1,1.5,20],[2,1.09,222.22]],"ltp":0.0,"tv":0.0,"id":475559}]}]}
{"op":"mcm","clk":"11892260109","pt":1724199175146,"mc":[{"id":"1.231875523","rc":[{"batb":[[0,1.51,16.83]],"ltp":1.03,"tv":2.0,"id":31378},{"batb":[[0,1.51,16.83]],"ltp":0.0,"tv":0.0,"id":475559},{"batb":[[0,1.51,17.72],[1,1.35,56.39]],"ltp":0.0,"tv":0.0,"id":60443}]}]}
{"op":"mcm","clk":"11892325615","pt":1724200186987,"mc":[{"id":"1.231875523","rc":[{"batb":[[0,1.5,20],[1,1.09,222.22],[2,1.04,1.53]],"ltp":1.03,"tv":2.0,"id":31378}]}]}
{"op":"mcm","clk":"11892325641","pt":1724200187396,"mc":[{"id":"1.231875523","rc":[{"batb":[[0,1.5,20],[1,1.09,222.22],[2,1.04,1.53]],"ltp":0.0,"tv":0.0,"id":475559},{"batb":[[0,1.5,1.78],[1,1.35,55.49]],"ltp":0.0,"tv":0.0,"id":60443}]}]}
{"op":"mcm","clk":"11892329316","pt":1724200242732,"mc":[{"id":"1.231875523","rc":[{"batb":[[0,1.51,16.83],[1,1.5,20],[2,1.09,222.22]],"ltp":1.03,"tv":2.0,"id":31378},{"batb":[[0,1.51,16.83],[1,1.5,20],[2,1.09,222.22]],"ltp":0.0,"tv":0.0,"id":475559},{"batb":[[0,1.51,17.72],[1,1.35,56.39]],"ltp":0.0,"tv":0.0,"id":60443}]}]}
{"op":"mcm","clk":"11892429508","pt":1724202044996,"mc":[{"id":"1.231875523","rc":[{"batb":[[0,1.51,16.82]],"ltp":1.03,"tv":2.0,"id":31378},{"batb":[[0,1.5,20],[1,1.09,222.22],[2,1.04,1.53]],"ltp":0.0,"tv":0.0,"id":475559},{"batb":[[0,1.5,1.78],[1,1.35,55.49]],"ltp":0.0,"tv":0.0,"id":60443}]}]}
{"op":"mcm","clk":"11892429519","pt":1724202045202,"mc":[{"id":"1.231875523","rc":[{"batb":[[0,1.5,20],[1,1.09,222.22],[2,1.04,1.53]],"ltp":1.03,"tv":2.0,"id":31378}]}]}
{"op":"mcm","clk":"11892431014","pt":1724202075025,"mc":[{"id":"1.231875523","rc":[{"batb":[[0,1.51,16.82],[1,1.5,20],[2,1.09,222.22]],"ltp":1.03,"tv":2.0,"id":31378},{"batb":[[0,1.51,16.82],[1,1.5,20],[2,1.09,222.22]],"ltp":0.0,"tv":0.0,"id":475559},{"batb":[[0,1.51,17.72],[1,1.35,56.38]],"ltp":0.0,"tv":0.0,"id":60443}]}]}
{"op":"mcm","clk":"11892525808","pt":1724203875938,"mc":[{"id":"1.231875523","rc":[{"batb":[[0,1.5,20],[1,1.09,222.22],[2,1.04,1.53]],"ltp":1.03,"tv":2.0,"id":31378},{"batb":[[0,1.5,20],[1,1.09,222.22],[2,1.04,1.53]],"ltp":0.0,"tv":0.0,"id":475559},{"batb":[[0,1.5,1.78],[1,1.35,55.49]],"ltp":0.0,"tv":0.0,"id":60443}]}]}
{"op":"mcm","clk":"11892526237","pt":1724203884848,"mc":[{"id":"1.231875523","rc":[{"batb":[[0,1.51,16.82],[1,1.5,20],[2,1.09,222.22]],"ltp":1.03,"tv":2.0,"id":31378},{"batb":[[0,1.51,16.82],[1,1.5,20],[2,1.09,222.22]],"ltp":0.0,"tv":0.0,"id":475559},{"batb":[[0,1.51,17.72],[1,1.35,56.38]],"ltp":0.0,"tv":0.0,"id":60443}]}]}
{"op":"mcm","clk":"11892620110","pt":1724205686980,"mc":[{"id":"1.231875523","rc":[{"batb":[[0,1.5,20],[1,1.09,222.22],[2,1.04,1.53]],"ltp":1.03,"tv":2.0,"id":31378},{"batb":[[0,1.51,17.72],[1,1.35,56.39]],"ltp":0.0,"tv":0.0,"id":60443},{"batb":[[0,1.51,16.83]],"ltp":0.0,"tv":0.0,"id":475559}]}]}
{"op":"mcm","clk":"11892620124","pt":1724205687347,"mc":[{"id":"1.231875523","rc":[{"batb":[[0,1.5,1.79],[1,1.35,55.5]],"ltp":0.0,"tv":0.0,"id":60443},{"batb":[[0,1.5,20],[1,1.09,222.22],[2,1.04,1.53]],"ltp":0.0,"tv":0.0,"id":475559}]}]}
{"op":"mcm","clk":"11892623659","pt":1724205782497,"mc":[{"id":"1.231875523","rc":[{"batb":[[0,1.51,16.83],[1,1.5,20],[2,1.09,222.22]],"ltp":1.03,"tv":2.0,"id":31378},{"batb":[[0,1.51,17.72],[1,1.35,56.39]],"ltp":0.0,"tv":0.0,"id":60443},{"batb":[[0,1.51,16.83],[1,1.5,20],[2,1.09,222.22]],"ltp":0.0,"tv":0.0,"id":475559}]}]}
{"op":"mcm","clk":"11892697039","pt":1724207582956,"mc":[{"id":"1.231875523","rc":[{"batb":[[0,1.5,1.79],[1,1.35,55.5]],"ltp":0.0,"tv":0.0,"id":60443}]}]}
{"op":"mcm","clk":"11892697058","pt":1724207583265,"mc":[{"id":"1.231875523","rc":[{"batb":[[0,1.5,20],[1,1.09,222.22],[2,1.04,1.53]],"ltp":1.03,"tv":2.0,"id":31378},{"batb":[[0,1.5,20],[1,1.09,222.22],[2,1.04,1.53]],"ltp":0.0,"tv":0.0,"id":475559}]}]}
{"op":"mcm","clk":"11892699295","pt":1724207651320,"mc":[{"id":"1.231875523","rc":[{"batb":[[0,1.51,16.83],[1,1.5,20],[2,1.09,222.22]],"ltp":1.03,"tv":2.0,"id":31378},{"batb":[[0,1.51,17.72],[1,1.35,56.39]],"ltp":0.0,"tv":0.0,"id":60443},{"batb":[[0,1.51,16.83],[1,1.5,20],[2,1.09,222.22]],"ltp":0.0,"tv":0.0,"id":475559}]}]}
{"op":"mcm","clk":"11892766900","pt":1724209452668,"mc":[{"id":"1.231875523","rc":[{"batb":[[0,1.5,20],[1,1.09,222.22],[2,1.04,1.53]],"ltp":1.03,"tv":2.0,"id":31378},{"batb":[[0,1.5,1.79],[1,1.35,55.49]],"ltp":0.0,"tv":0.0,"id":60443},{"batb":[[0,1.5,20],[1,1.09,222.22],[2,1.04,1.53]],"ltp":0.0,"tv":0.0,"id":475559}]}]}
{"op":"mcm","clk":"11892768508","pt":1724209488985,"mc":[{"id":"1.231875523","rc":[{"batb":[[0,1.51,16.82],[1,1.5,20],[2,1.09,222.22]],"ltp":1.03,"tv":2.0,"id":31378},{"batb":[[0,1.51,17.72],[1,1.35,56.39]],"ltp":0.0,"tv":0.0,"id":60443},{"batb":[[0,1.51,16.82],[1,1.5,20],[2,1.09,222.22]],"ltp":0.0,"tv":0.0,"id":475559}]}]}
{"op":"mcm","clk":"11892861995","pt":1724211290634,"mc":[{"id":"1.231875523","rc":[{"batb":[[0,1.5,20],[1,1.09,222.22],[2,1.04,1.53]],"ltp":1.03,"tv":2.0,"id":31378},{"batb":[[0,1.5,20],[1,1.09,222.22],[2,1.04,1.53]],"ltp":0.0,"tv":0.0,"id":475559},{"batb":[[0,1.5,1.79],[1,1.35,55.49]],"ltp":0.0,"tv":0.0,"id":60443}]}]}
{"op":"mcm","clk":"11892862900","pt":1724211311872,"mc":[{"id":"1.231875523","rc":[{"batb":[[0,1.51,16.82],[1,1.5,20],[2,1.09,222.22]],"ltp":1.03,"tv":2.0,"id":31378},{"batb":[[0,1.51,16.82],[1,1.5,20],[2,1.09,222.22]],"ltp":0.0,"tv":0.0,"id":475559},{"batb":[[0,1.51,17.72],[1,1.35,56.39]],"ltp":0.0,"tv":0.0,"id":60443}]}]}
{"op":"mcm","clk":"11892967338","pt":1724213113822,"mc":[{"id":"1.231875523","rc":[{"batb":[[0,1.5,20],[1,1.09,222.22],[2,1.04,1.53]],"ltp":1.03,"tv":2.0,"id":31378},{"batb":[[0,1.5,20],[1,1.09,222.22],[2,1.04,1.53]],"ltp":0.0,"tv":0.0,"id":475559},{"batb":[[0,1.51,17.72],[1,1.35,56.38]],"ltp":0.0,"tv":0.0,"id":60443}]}]}
{"op":"mcm","clk":"11892967354","pt":1724213114126,"mc":[{"id":"1.231875523","rc":[{"batb":[[0,1.5,1.79],[1,1.35,55.48]],"ltp":0.0,"tv":0.0,"id":60443}]}]}
{"op":"mcm","clk":"11892968012","pt":1724213125927,"mc":[{"id":"1.231875523","rc":[{"batb":[[0,1.51,16.82],[1,1.5,20],[2,1.09,222.22]],"ltp":1.03,"tv":2.0,"id":31378},{"batb":[[0,1.51,16.82],[1,1.5,20],[2,1.09,222.22]],"ltp":0.0,"tv":0.0,"id":475559},{"batb":[[0,1.51,17.72],[1,1.35,56.38]],"ltp":0.0,"tv":0.0,"id":60443}]}]}
{"op":"mcm","clk":"11893064036","pt":1724214928016,"mc":[{"id":"1.231875523","rc":[{"batb":[[0,1.5,20],[1,1.09,222.22],[2,1.04,1.53]],"ltp":0.0,"tv":0.0,"id":475559}]}]}
{"op":"mcm","clk":"11893064057","pt":1724214928425,"mc":[{"id":"1.231875523","rc":[{"batb":[[0,1.5,20],[1,1.09,222.22],[2,1.04,1.53]],"ltp":1.03,"tv":2.0,"id":31378},{"batb":[[0,1.5,1.79],[1,1.35,55.48]],"ltp":0.0,"tv":0.0,"id":60443}]}]}
{"op":"mcm","clk":"11893068736","pt":1724215021151,"mc":[{"id":"1.231875523","rc":[{"batb":[[0,1.51,16.82],[1,1.5,20],[2,1.09,222.22]],"ltp":1.03,"tv":2.0,"id":31378},{"batb":[[0,1.51,16.82],[1,1.5,20],[2,1.09,222.22]],"ltp":0.0,"tv":0.0,"id":475559},{"batb":[[0,1.51,17.72],[1,1.35,56.38]],"ltp":0.0,"tv":0.0,"id":60443}]}]}
{"op":"mcm","clk":"11893159669","pt":1724216821930,"mc":[{"id":"1.231875523","rc":[{"batb":[[0,1.5,20],[1,1.09,222.22],[2,1.04,1.53]],"ltp":1.03,"tv":2.0,"id":31378},{"batb":[[0,1.5,20],[1,1.09,222.22],[2,1.04,1.53]],"ltp":0.0,"tv":0.0,"id":475559},{"batb":[[0,1.5,1.79],[1,1.35,55.48]],"ltp":0.0,"tv":0.0,"id":60443}]}]}
{"op":"mcm","clk":"11893163591","pt":1724216906510,"mc":[{"id":"1.231875523","rc":[{"batb":[[0,1.51,16.82],[1,1.5,20],[2,1.09,222.22]],"ltp":1.03,"tv":2.0,"id":31378},{"batb":[[0,1.51,16.82],[1,1.5,20],[2,1.09,222.22]],"ltp":0.0,"tv":0.0,"id":475559},{"batb":[[0,1.51,17.71],[1,1.35,56.38]],"ltp":0.0,"tv":0.0,"id":60443}]}]}
{"op":"mcm","clk":"11893248003","pt":1724218707075,"mc":[{"id":"1.231875523","rc":[{"batb":[[0,1.5,20],[1,1.09,222.22],[2,1.04,1.53]],"ltp":1.03,"tv":2.0,"id":31378},{"batb":[[0,1.5,1.79],[1,1.35,55.48]],"ltp":0.0,"tv":0.0,"id":60443}]}]}
{"op":"mcm","clk":"11893248010","pt":1724218707283,"mc":[{"id":"1.231875523","rc":[{"batb":[[0,1.5,20],[1,1.09,222.22],[2,1.04,1.53]],"ltp":0.0,"tv":0.0,"id":475559}]}]}
{"op":"mcm","clk":"11893251894","pt":1724218785484,"mc":[{"id":"1.231875523","rc":[{"batb":[[0,1.51,16.82],[1,1.5,20],[2,1.09,222.22]],"ltp":1.03,"tv":2.0,"id":31378},{"batb":[[0,1.51,16.82],[1,1.5,20],[2,1.09,222.22]],"ltp":0.0,"tv":0.0,"id":475559},{"batb":[[0,1.51,17.71],[1,1.35,56.38]],"ltp":0.0,"tv":0.0,"id":60443}]}]}
{"op":"mcm","clk":"11893340737","pt":1724220587698,"mc":[{"id":"1.231875523","rc":[{"batb":[[0,1.5,20],[1,1.09,222.22],[2,1.04,1.53]],"ltp":1.03,"tv":2.0,"id":31378},{"batb":[[0,1.5,20],[1,1.09,222.22],[2,1.04,1.53]],"ltp":0.0,"tv":0.0,"id":475559},{"batb":[[0,1.5,1.79],[1,1.35,55.5]],"ltp":0.0,"tv":0.0,"id":60443}]}]}
{"op":"mcm","clk":"11893344930","pt":1724220660354,"mc":[{"id":"1.231875523","rc":[{"batb":[[0,1.51,16.83],[1,1.5,20],[2,1.09,222.22]],"ltp":1.03,"tv":2.0,"id":31378},{"batb":[[0,1.51,16.83],[1,1.5,20],[2,1.09,222.22]],"ltp":0.0,"tv":0.0,"id":475559},{"batb":[[0,1.51,17.72],[1,1.35,56.39]],"ltp":0.0,"tv":0.0,"id":60443}]}]}
{"op":"mcm","clk":"11893441910","pt":1724222462633,"mc":[{"id":"1.231875523","rc":[{"batb":[[0,1.5,20],[1,1.09,222.22],[2,1.04,1.53]],"ltp":1.03,"tv":2.0,"id":31378},{"batb":[[0,1.5,20],[1,1.09,222.22],[2,1.04,1.53]],"ltp":0.0,"tv":0.0,"id":475559},{"batb":[[0,1.5,1.79],[1,1.35,55.5]],"ltp":0.0,"tv":0.0,"id":60443}]}]}
{"op":"mcm","clk":"11893445717","pt":1724222531275,"mc":[{"id":"1.231875523","rc":[{"batb":[[0,1.51,16.83],[1,1.5,20],[2,1.09,222.22]],"ltp":1.03,"tv":2.0,"id":31378},{"batb":[[0,1.51,16.83],[1,1.5,20],[2,1.09,222.22]],"ltp":0.0,"tv":0.0,"id":475559},{"batb":[[0,1.51,17.72],[1,1.35,56.39]],"ltp":0.0,"tv":0.0,"id":60443}]}]}
{"op":"mcm","clk":"11893528519","pt":1724224333719,"mc":[{"id":"1.231875523","rc":[{"batb":[[0,1.5,20],[1,1.09,222.22],[2,1.04,1.53]],"ltp":1.03,"tv":2.0,"id":31378},{"batb":[[0,1.5,20],[1,1.09,222.22],[2,1.04,1.53]],"ltp":0.0,"tv":0.0,"id":475559},{"batb":[[0,1.5,1.79],[1,1.35,55.51]],"ltp":0.0,"tv":0.0,"id":60443}]}]}
{"op":"mcm","clk":"11893531964","pt":1724224398777,"mc":[{"id":"1.231875523","rc":[{"batb":[[0,1.51,16.83],[1,1.5,20],[2,1.09,222.22]],"ltp":1.03,"tv":2.0,"id":31378},{"batb":[[0,1.51,16.83],[1,1.5,20],[2,1.09,222.22]],"ltp":0.0,"tv":0.0,"id":475559},{"batb":[[0,1.51,17.72],[1,1.35,56.41]],"ltp":0.0,"tv":0.0,"id":60443}]}]}
{"op":"mcm","clk":"11893613416","pt":1724226199716,"mc":[{"id":"1.231875523","rc":[{"batb":[[0,1.5,20],[1,1.09,222.22],[2,1.04,1.53]],"ltp":1.03,"tv":2.0,"id":31378},{"batb":[[0,1.5,20],[1,1.09,222.22],[2,1.04,1.53]],"ltp":0.0,"tv":0.0,"id":475559},{"batb":[[0,1.5,1.79],[1,1.35,55.51]],"ltp":0.0,"tv":0.0,"id":60443}]}]}
{"op":"mcm","clk":"11893615313","pt":1724226258994,"mc":[{"id":"1.231875523","rc":[{"batb":[[0,1.51,16.83],[1,1.5,20],[2,1.09,222.22]],"ltp":1.03,"tv":2.0,"id":31378},{"batb":[[0,1.51,16.83],[1,1.5,20],[2,1.09,222.22]],"ltp":0.0,"tv":0.0,"id":475559},{"batb":[[0,1.51,17.72],[1,1.35,56.41]],"ltp":0.0,"tv":0.0,"id":60443}]}]}
{"op":"mcm","clk":"11893697959","pt":1724228059702,"mc":[{"id":"1.231875523","rc":[{"batb":[[0,1.5,20],[1,1.09,222.22],[2,1.04,1.53]],"ltp":1.03,"tv":2.0,"id":31378},{"batb":[[0,1.5,20],[1,1.09,222.22],[2,1.04,1.53]],"ltp":0.0,"tv":0.0,"id":475559},{"batb":[[0,1.5,1.79],[1,1.35,55.51]],"ltp":0.0,"tv":0.0,"id":60443}]}]}
{"op":"mcm","clk":"11893701649","pt":1724228125000,"mc":[{"id":"1.231875523","rc":[{"batb":[[0,1.51,16.83],[1,1.5,20],[2,1.09,222.22]],"ltp":1.03,"tv":2.0,"id":31378},{"batb":[[0,1.51,16.83],[1,1.5,20],[2,1.09,222.22]],"ltp":0.0,"tv":0.0,"id":475559},{"batb":[[0,1.51,17.72],[1,1.35,56.4]],"ltp":0.0,"tv":0.0,"id":60443}]}]}
{"op":"mcm","clk":"11893797572","pt":1724229926000,"mc":[{"id":"1.231875523","rc":[{"batb":[[0,1.5,20],[1,1.09,222.22],[2,1.04,1.53]],"ltp":1.03,"tv":2.0,"id":31378},{"batb":[[0,1.5,20],[1,1.09,222.22],[2,1.04,1.53]],"ltp":0.0,"tv":0.0,"id":475559},{"batb":[[0,1.5,1.79],[1,1.35,55.51]],"ltp":0.0,"tv":0.0,"id":60443}]}]}
{"op":"mcm","clk":"11893804737","pt":1724230045612,"mc":[{"id":"1.231875523","rc":[{"batb":[[0,1.51,16.83],[1,1.5,20],[2,1.09,222.22]],"ltp":1.03,"tv":2.0,"id":31378},{"batb":[[0,1.51,16.83],[1,1.5,20],[2,1.09,222.22]],"ltp":0.0,"tv":0.0,"id":475559},{"batb":[[0,1.51,17.72],[1,1.35,56.4]],"ltp":0.0,"tv":0.0,"id":60443}]}]}
{"op":"mcm","clk":"11893895773","pt":1724231575058,"mc":[{"id":"1.231875523","rc":[{"batb":[[0,1.51,16.84]],"ltp":1.03,"tv":2.0,"id":31378},{"batb":[[0,1.51,16.84]],"ltp":0.0,"tv":0.0,"id":475559},{"batb":[[0,1.51,17.73],[1,1.35,56.43]],"ltp":0.0,"tv":0.0,"id":60443}]}]}
{"op":"mcm","clk":"11893914948","pt":1724231845954,"mc":[{"id":"1.231875523","rc":[{"batb":[[0,1.5,20],[1,1.09,222.22],[2,1.04,1.53]],"ltp":1.03,"tv":2.0,"id":31378}]}]}
{"op":"mcm","clk":"11893914977","pt":1724231846367,"mc":[{"id":"1.231875523","rc":[{"batb":[[0,1.5,20],[1,1.09,222.22],[2,1.04,1.53]],"ltp":0.0,"tv":0.0,"id":475559},{"batb":[[0,1.5,1.79],[1,1.35,55.53]],"ltp":0.0,"tv":0.0,"id":60443}]}]}
{"op":"mcm","clk":"11893918097","pt":1724231893421,"mc":[{"id":"1.231875523","rc":[{"batb":[[0,1.51,16.84],[1,1.5,20],[2,1.09,222.22]],"ltp":1.03,"tv":2.0,"id":31378},{"batb":[[0,1.51,16.84],[1,1.5,20],[2,1.09,222.22]],"ltp":0.0,"tv":0.0,"id":475559},{"batb":[[0,1.51,17.73],[1,1.35,56.43]],"ltp":0.0,"tv":0.0,"id":60443}]}]}
{"op":"mcm","clk":"11893990926","pt":1724232952550,"mc":[{"id":"1.231875523","rc":[{"batb":[[2,1.04,1.53]],"batl":[[1,180,1.03],[2,870,0.34]],"ltp":1.03,"tv":2.0,"id":31378},{"batb":[[2,1.04,1.53]],"batl":[[1,180,1.03],[2,870,0.34]],"ltp":0.0,"tv":0.0,"id":475559},{"batl":[[1,180,1.03],[2,870,0.34]],"ltp":0.0,"tv":0.0,"id":60443}]}]}
{"op":"mcm","clk":"11893991467","pt":1724232961041,"mc":[{"id":"1.231875523","rc":[{"batb":[[2,1.05,50]],"ltp":1.03,"tv":2.0,"id":31378},{"batb":[[2,1.04,64.03]],"ltp":0.0,"tv":0.0,"id":475559}]}]}
{"op":"mcm","clk":"11893991502","pt":1724232961551,"mc":[{"id":"1.231875523","rc":[{"batb":[[2,1.08,31.25]],"ltp":1.03,"tv":2.0,"id":31378},{"batb":[[2,1.08,31.25]],"ltp":0.0,"tv":0.0,"id":475559}]}]}
{"op":"mcm","clk":"11893992142","pt":1724232971372,"mc":[{"id":"1.231875523","rc":[{"batl":[[1,95,5.85],[2,990,5.51]],"ltp":1.03,"tv":2.0,"id":31378},{"batl":[[1,95,5.85],[2,990,5.51]],"ltp":0.0,"tv":0.0,"id":475559},{"batl":[[1,95,5.85],[2,990,5.51]],"ltp":0.0,"tv":0.0,"id":60443}]}]}
{"op":"mcm","clk":"11894044167","pt":1724233694888,"mc":[{"id":"1.231875523","rc":[{"batb":[[0,1.5,20],[1,1.08,31.25],[2,1.07,35.71]],"ltp":1.03,"tv":2.0,"id":31378},{"batb":[[0,1.5,20],[1,1.08,31.25],[2,1.07,35.71]],"ltp":0.0,"tv":0.0,"id":475559},{"batb":[[0,1.5,1.79],[1,1.35,55.53]],"ltp":0.0,"tv":0.0,"id":60443}]}]}
{"op":"mcm","clk":"11894047215","pt":1724233738698,"mc":[{"id":"1.231875523","rc":[{"batb":[[0,1.51,16.84],[1,1.5,20],[2,1.08,31.25]],"ltp":1.03,"tv":2.0,"id":31378},{"batb":[[0,1.51,16.84],[1,1.5,20],[2,1.08,31.25]],"ltp":0.0,"tv":0.0,"id":475559},{"batb":[[0,1.51,17.73],[1,1.35,56.43]],"ltp":0.0,"tv":0.0,"id":60443}]}]}
{"op":"mcm","clk":"11894195564","pt":1724235538955,"mc":[{"id":"1.231875523","rc":[{"batb":[[0,1.51,16.82]],"ltp":1.03,"tv":2.0,"id":31378},{"batb":[[0,1.51,16.82]],"ltp":0.0,"tv":0.0,"id":475559},{"batb":[[0,1.5,1.78],[1,1.35,55.47]],"ltp":0.0,"tv":0.0,"id":60443}]}]}
{"op":"mcm","clk":"11894195595","pt":1724235539265,"mc":[{"id":"1.231875523","rc":[{"batb":[[0,1.5,20],[1,1.08,31.25],[2,1.07,35.71]],"ltp":1.03,"tv":2.0,"id":31378},{"batb":[[0,1.5,20],[1,1.08,31.25],[2,1.07,35.71]],"ltp":0.0,"tv":0.0,"id":475559}]}]}
{"op":"mcm","clk":"11894198813","pt":1724235572897,"mc":[{"id":"1.231875523","rc":[{"batb":[[0,1.51,16.82],[1,1.5,20],[2,1.08,31.25]],"ltp":1.03,"tv":2.0,"id":31378},{"batb":[[0,1.51,16.82],[1,1.5,20],[2,1.08,31.25]],"ltp":0.0,"tv":0.0,"id":475559},{"batb":[[0,1.51,17.71],[1,1.35,56.36]],"ltp":0.0,"tv":0.0,"id":60443}]}]}
{"op":"mcm","clk":"11894377918","pt":1724237374583,"mc":[{"id":"1.231875523","rc":[{"batb":[[0,1.5,20],[1,1.08,31.25],[2,1.07,35.71]],"ltp":1.03,"tv":2.0,"id":31378},{"batb":[[0,1.5,1.78],[1,1.35,55.47]],"ltp":0.0,"tv":0.0,"id":60443},{"batb":[[0,1.5,20],[1,1.08,31.25],[2,1.07,35.71]],"ltp":0.0,"tv":0.0,"id":475559}]}]}
{"op":"mcm","clk":"11894380336","pt":1724237400712,"mc":[{"id":"1.231875523","rc":[{"batb":[[0,1.51,16.82],[1,1.5,20],[2,1.08,31.25]],"ltp":1.03,"tv":2.0,"id":31378},{"batb":[[0,1.51,17.71],[1,1.35,56.36]],"ltp":0.0,"tv":0.0,"id":60443},{"batb":[[0,1.51,16.82],[1,1.5,20],[2,1.08,31.25]],"ltp":0.0,"tv":0.0,"id":475559}]}]}
{"op":"mcm","clk":"11894541041","pt":1724239203926,"mc":[{"id":"1.231875523","rc":[{"batb":[[0,1.5,20],[1,1.08,31.25],[2,1.07,35.71]],"ltp":1.03,"tv":2.0,"id":31378},{"batb":[[0,1.5,1.78],[1,1.35,55.44]],"ltp":0.0,"tv":0.0,"id":60443},{"batb":[[0,1.5,20],[1,1.08,31.25],[2,1.07,35.71]],"ltp":0.0,"tv":0.0,"id":475559}]}]}
{"op":"mcm","clk":"11894543864","pt":1724239231655,"mc":[{"id":"1.231875523","rc":[{"batb":[[0,1.51,16.81],[1,1.5,20],[2,1.08,31.25]],"ltp":1.03,"tv":2.0,"id":31378},{"batb":[[0,1.51,17.7],[1,1.35,56.33]],"ltp":0.0,"tv":0.0,"id":60443},{"batb":[[0,1.51,16.81],[1,1.5,20],[2,1.08,31.25]],"ltp":0.0,"tv":0.0,"id":475559}]}]}
{"op":"mcm","clk":"11894713881","pt":1724241034489,"mc":[{"id":"1.231875523","rc":[{"batb":[[0,1.5,20],[1,1.08,31.25],[2,1.07,35.71]],"ltp":1.03,"tv":2.0,"id":31378},{"batb":[[0,1.5,1.78],[1,1.35,55.44]],"ltp":0.0,"tv":0.0,"id":60443},{"batb":[[0,1.5,20],[1,1.08,31.25],[2,1.07,35.71]],"ltp":0.0,"tv":0.0,"id":475559}]}]}
{"op":"mcm","clk":"11894722377","pt":1724241134857,"mc":[{"id":"1.231875523","rc":[{"batb":[[0,1.51,16.81],[1,1.5,20],[2,1.08,31.25]],"ltp":1.03,"tv":2.0,"id":31378},{"batb":[[0,1.51,17.7],[1,1.35,56.33]],"ltp":0.0,"tv":0.0,"id":60443},{"batb":[[0,1.51,16.81],[1,1.5,20],[2,1.08,31.25]],"ltp":0.0,"tv":0.0,"id":475559}]}]}
{"op":"mcm","clk":"11894817868","pt":1724242375080,"mc":[{"id":"1.231875523","rc":[{"batb":[[0,1.51,16.81]],"ltp":1.03,"tv":2.0,"id":31378},{"batb":[[0,1.51,16.81]],"ltp":0.0,"tv":0.0,"id":475559}]}]}
{"op":"mcm","clk":"11894856558","pt":1724242937775,"mc":[{"id":"1.231875523","rc":[{"batb":[[0,1.5,20],[1,1.08,31.25],[2,1.07,35.71]],"ltp":1.03,"tv":2.0,"id":31378},{"batb":[[0,1.5,1.78],[1,1.35,55.44]],"ltp":0.0,"tv":0.0,"id":60443},{"batb":[[0,1.5,20],[1,1.08,31.25],[2,1.07,35.71]],"ltp":0.0,"tv":0.0,"id":475559}]}]}
{"op":"mcm","clk":"11894861600","pt":1724243015275,"mc":[{"id":"1.231875523","rc":[{"batb":[[0,1.51,16.81],[1,1.5,20],[2,1.08,31.25]],"ltp":1.03,"tv":2.0,"id":31378},{"batb":[[0,1.51,17.7],[1,1.35,56.33]],"ltp":0.0,"tv":0.0,"id":60443},{"batb":[[0,1.51,16.81],[1,1.5,20],[2,1.08,31.25]],"ltp":0.0,"tv":0.0,"id":475559}]}]}
{"op":"mcm","clk":"11894971056","pt":1724244815945,"mc":[{"id":"1.231875523","rc":[{"batb":[[0,1.5,20],[1,1.08,31.25],[2,1.07,35.71]],"ltp":1.03,"tv":2.0,"id":31378},{"batb":[[0,1.5,1.78],[1,1.35,55.44]],"ltp":0.0,"tv":0.0,"id":60443},{"batb":[[0,1.5,20],[1,1.08,31.25],[2,1.07,35.71]],"ltp":0.0,"tv":0.0,"id":475559}]}]}
{"op":"mcm","clk":"11894974255","pt":1724244871414,"mc":[{"id":"1.231875523","rc":[{"batb":[[0,1.51,16.81],[1,1.5,20],[2,1.08,31.25]],"ltp":1.03,"tv":2.0,"id":31378},{"batb":[[0,1.51,17.7],[1,1.35,56.33]],"ltp":0.0,"tv":0.0,"id":60443},{"batb":[[0,1.51,16.81],[1,1.5,20],[2,1.08,31.25]],"ltp":0.0,"tv":0.0,"id":475559}]}]}
{"op":"mcm","clk":"11895084761","pt":1724246674012,"mc":[{"id":"1.231875523","rc":[{"batb":[[0,1.51,16.81]],"ltp":1.03,"tv":2.0,"id":31378},{"batb":[[0,1.5,1.78],[1,1.35,55.43]],"ltp":0.0,"tv":0.0,"id":60443},{"batb":[[0,1.51,16.81]],"ltp":0.0,"tv":0.0,"id":475559}]}]}
{"op":"mcm","clk":"11895084784","pt":1724246674271,"mc":[{"id":"1.231875523","rc":[{"batb":[[0,1.5,20],[1,1.08,31.25],[2,1.07,35.71]],"ltp":1.03,"tv":2.0,"id":31378},{"batb":[[0,1.5,20],[1,1.08,31.25],[2,1.07,35.71]],"ltp":0.0,"tv":0.0,"id":475559}]}]}
{"op":"mcm","clk":"11895087492","pt":1724246715431,"mc":[{"id":"1.231875523","rc":[{"batb":[[0,1.51,16.81],[1,1.5,20],[2,1.08,31.25]],"ltp":1.03,"tv":2.0,"id":31378},{"batb":[[0,1.51,17.7],[1,1.35,56.32]],"ltp":0.0,"tv":0.0,"id":60443},{"batb":[[0,1.51,16.81],[1,1.5,20],[2,1.08,31.25]],"ltp":0.0,"tv":0.0,"id":475559}]}]}
{"op":"mcm","clk":"11895222522","pt":1724248518061,"mc":[{"id":"1.231875523","rc":[{"batb":[[0,1.5,1.78],[1,1.35,55.43]],"ltp":0.0,"tv":0.0,"id":60443},{"batb":[[0,1.5,20],[1,1.08,31.25],[2,1.07,35.71]],"ltp":0.0,"tv":0.0,"id":475559}]}]}
{"op":"mcm","clk":"11895222530","pt":1724248518167,"mc":[{"id":"1.231875523","rc":[{"batb":[[0,1.5,20],[1,1.08,31.25],[2,1.07,35.71]],"ltp":1.03,"tv":2.0,"id":31378}]}]}
{"op":"mcm","clk":"11895224379","pt":1724248546327,"mc":[{"id":"1.231875523","rc":[{"batb":[[0,1.51,16.81],[1,1.5,20],[2,1.08,31.25]],"ltp":1.03,"tv":2.0,"id":31378},{"batb":[[0,1.51,17.7],[1,1.35,56.32]],"ltp":0.0,"tv":0.0,"id":60443},{"batb":[[0,1.51,16.81],[1,1.5,20],[2,1.08,31.25]],"ltp":0.0,"tv":0.0,"id":475559}]}]}
{"op":"mcm","clk":"11895378018","pt":1724250348894,"mc":[{"id":"1.231875523","rc":[{"batb":[[0,1.51,16.78]],"ltp":1.03,"tv":2.0,"id":31378},{"batb":[[0,1.5,1.78],[1,1.35,55.38]],"ltp":0.0,"tv":0.0,"id":60443},{"batb":[[0,1.51,16.78]],"ltp":0.0,"tv":0.0,"id":475559}]}]}
{"op":"mcm","clk":"11895378045","pt":1724250349309,"mc":[{"id":"1.231875523","rc":[{"batb":[[0,1.5,20],[1,1.08,31.25],[2,1.07,35.71]],"ltp":1.03,"tv":2.0,"id":31378},{"batb":[[0,1.5,20],[1,1.08,31.25],[2,1.07,35.71]],"ltp":0.0,"tv":0.0,"id":475559}]}]}
{"op":"mcm","clk":"11895379194","pt":1724250364237,"mc":[{"id":"1.231875523","rc":[{"batb":[[0,1.51,16.78],[1,1.5,20],[2,1.08,31.25]],"ltp":1.03,"tv":2.0,"id":31378},{"batb":[[0,1.51,17.68],[1,1.35,56.27]],"ltp":0.0,"tv":0.0,"id":60443},{"batb":[[0,1.51,16.78],[1,1.5,20],[2,1.08,31.25]],"ltp":0.0,"tv":0.0,"id":475559}]}]}
{"op":"mcm","clk":"11895543354","pt":1724252164965,"mc":[{"id":"1.231875523","rc":[{"batb":[[0,1.5,20],[1,1.08,31.25],[2,1.07,35.71]],"ltp":1.03,"tv":2.0,"id":31378},{"batb":[[0,1.5,1.78],[1,1.35,55.38]],"ltp":0.0,"tv":0.0,"id":60443},{"batb":[[0,1.5,20],[1,1.08,31.25],[2,1.07,35.71]],"ltp":0.0,"tv":0.0,"id":475559}]}]}
{"op":"mcm","clk":"11895554284","pt":1724252295419,"mc":[{"id":"1.231875523","rc":[{"batb":[[0,1.51,16.78],[1,1.5,20],[2,1.08,31.25]],"ltp":1.03,"tv":2.0,"id":31378},{"batb":[[0,1.51,17.68],[1,1.35,56.27]],"ltp":0.0,"tv":0.0,"id":60443},{"batb":[[0,1.51,16.78],[1,1.5,20],[2,1.08,31.25]],"ltp":0.0,"tv":0.0,"id":475559}]}]}
{"op":"mcm","clk":"11895658570","pt":1724253175060,"mc":[{"id":"1.231875523","rc":[{"batb":[[1,1.35,56.26]],"ltp":0.0,"tv":0.0,"id":60443}]}]}
{"op":"mcm","clk":"11895782961","pt":1724254097991,"mc":[{"id":"1.231875523","rc":[{"batb":[[0,1.5,1.78],[1,1.35,55.37]],"ltp":0.0,"tv":0.0,"id":60443}]}]}
{"op":"mcm","clk":"11895782999","pt":1724254098408,"mc":[{"id":"1.231875523","rc":[{"batb":[[0,1.5,20],[1,1.08,31.25],[2,1.07,35.71]],"ltp":1.03,"tv":2.0,"id":31378},{"batb":[[0,1.5,20],[1,1.08,31.25],[2,1.07,35.71]],"ltp":0.0,"tv":0.0,"id":475559}]}]}
{"op":"mcm","clk":"11895804137","pt":1724254263245,"mc":[{"id":"1.231875523","rc":[{"batb":[[0,1.51,16.79],[1,1.5,20],[2,1.08,31.25]],"ltp":1.03,"tv":2.0,"id":31378},{"batb":[[0,1.51,17.68],[1,1.35,56.26]],"ltp":0.0,"tv":0.0,"id":60443},{"batb":[[0,1.51,16.79],[1,1.5,20],[2,1.08,31.25]],"ltp":0.0,"tv":0.0,"id":475559}]}]}
{"op":"mcm","clk":"11896072685","pt":1724256064983,"mc":[{"id":"1.231875523","rc":[{"batb":[[0,1.5,20],[1,1.08,31.25],[2,1.07,35.71]],"ltp":1.03,"tv":2.0,"id":31378},{"batb":[[0,1.5,1.78],[1,1.35,55.39]],"ltp":0.0,"tv":0.0,"id":60443},{"batb":[[0,1.5,20],[1,1.08,31.25],[2,1.07,35.71]],"ltp":0.0,"tv":0.0,"id":475559}]}]}
{"op":"mcm","clk":"11896098404","pt":1724256227707,"mc":[{"id":"1.231875523","rc":[{"batb":[[0,1.51,16.79],[1,1.5,20],[2,1.08,31.25]],"ltp":1.03,"tv":2.0,"id":31378},{"batb":[[0,1.51,17.68],[1,1.35,56.27]],"ltp":0.0,"tv":0.0,"id":60443},{"batb":[[0,1.51,16.79],[1,1.5,20],[2,1.08,31.25]],"ltp":0.0,"tv":0.0,"id":475559}]}]}
{"op":"mcm","clk":"11896393146","pt":1724258028849,"mc":[{"id":"1.231875523","rc":[{"batb":[[0,1.5,20],[1,1.08,31.25],[2,1.07,35.71]],"ltp":0.0,"tv":0.0,"id":475559}]}]}
{"op":"mcm","clk":"11896393219","pt":1724258029367,"mc":[{"id":"1.231875523","rc":[{"batb":[[0,1.5,20],[1,1.08,31.25],[2,1.07,35.71]],"ltp":1.03,"tv":2.0,"id":31378},{"batb":[[0,1.5,1.78],[1,1.35,55.39]],"ltp":0.0,"tv":0.0,"id":60443}]}]}
{"op":"mcm","clk":"11896418906","pt":1724258173019,"mc":[{"id":"1.231875523","rc":[{"batb":[[0,1.51,16.79],[1,1.5,20],[2,1.08,31.25]],"ltp":1.03,"tv":2.0,"id":31378},{"batb":[[0,1.51,17.68],[1,1.35,56.27]],"ltp":0.0,"tv":0.0,"id":60443},{"batb":[[0,1.51,16.79],[1,1.5,20],[2,1.08,31.25]],"ltp":0.0,"tv":0.0,"id":475559}]}]}
{"op":"mcm","clk":"11896745718","pt":1724259976043,"mc":[{"id":"1.231875523","rc":[{"batb":[[0,1.5,20],[1,1.08,31.25],[2,1.07,35.71]],"ltp":1.03,"tv":2.0,"id":31378},{"batb":[[0,1.51,16.78]],"ltp":0.0,"tv":0.0,"id":475559},{"batb":[[0,1.51,17.67],[1,1.35,56.24]],"ltp":0.0,"tv":0.0,"id":60443}]}]}
{"op":"mcm","clk":"11896745782","pt":1724259976406,"mc":[{"id":"1.231875523","rc":[{"batb":[[0,1.5,20],[1,1.08,31.25],[2,1.07,35.71]],"ltp":0.0,"tv":0.0,"id":475559},{"batb":[[0,1.5,1.78],[1,1.35,55.35]],"ltp":0.0,"tv":0.0,"id":60443}]}]}
{"op":"mcm","clk":"11896772855","pt":1724260129926,"mc":[{"id":"1.231875523","rc":[{"batb":[[0,1.51,16.78],[1,1.5,20],[2,1.08,31.25]],"ltp":1.03,"tv":2.0,"id":31378},{"batb":[[0,1.51,16.78],[1,1.5,20],[2,1.08,31.25]],"ltp":0.0,"tv":0.0,"id":475559},{"batb":[[0,1.51,17.67],[1,1.35,56.24]],"ltp":0.0,"tv":0.0,"id":60443}]}]}
{"op":"mcm","clk":"11897070861","pt":1724261931626,"mc":[{"id":"1.231875523","rc":[{"batb":[[0,1.5,20],[1,1.08,31.25],[2,1.07,35.71]],"ltp":1.03,"tv":2.0,"id":31378},{"batb":[[0,1.5,20],[1,1.08,31.25],[2,1.07,35.71]],"ltp":0.0,"tv":0.0,"id":475559},{"batb":[[0,1.5,1.78],[1,1.35,55.35]],"ltp":0.0,"tv":0.0,"id":60443}]}]}
{"op":"mcm","clk":"11897088058","pt":1724262042951,"mc":[{"id":"1.231875523","rc":[{"batb":[[0,1.51,16.78],[1,1.5,20],[2,1.08,31.25]],"ltp":1.03,"tv":2.0,"id":31378},{"batb":[[0,1.51,16.78],[1,1.5,20],[2,1.08,31.25]],"ltp":0.0,"tv":0.0,"id":475559},{"batb":[[0,1.51,17.67],[1,1.35,56.24]],"ltp":0.0,"tv":0.0,"id":60443}]}]}
{"op":"mcm","clk":"11897361893","pt":1724263844835,"mc":[{"id":"1.231875523","rc":[{"batb":[[0,1.5,20],[1,1.08,31.25],[2,1.07,35.71]],"ltp":1.03,"tv":2.0,"id":31378},{"batb":[[0,1.5,20],[1,1.08,31.25],[2,1.07,35.71]],"ltp":0.0,"tv":0.0,"id":475559},{"batb":[[0,1.5,1.78],[1,1.35,55.37]],"ltp":0.0,"tv":0.0,"id":60443}]}]}
{"op":"mcm","clk":"11897371811","pt":1724263899529,"mc":[{"id":"1.231875523","rc":[{"batb":[[0,1.51,16.78],[1,1.5,20],[2,1.08,31.25]],"ltp":1.03,"tv":2.0,"id":31378},{"batb":[[0,1.51,16.78],[1,1.5,20],[2,1.08,31.25]],"ltp":0.0,"tv":0.0,"id":475559},{"batb":[[0,1.51,17.67],[1,1.35,56.25]],"ltp":0.0,"tv":0.0,"id":60443}]}]}
{"op":"mcm","clk":"11897720958","pt":1724265700993,"mc":[{"id":"1.231875523","rc":[{"batb":[[0,1.5,20],[1,1.08,31.25],[2,1.07,35.71]],"ltp":1.03,"tv":2.0,"id":31378},{"batb":[[0,1.5,1.78],[1,1.35,55.37]],"ltp":0.0,"tv":0.0,"id":60443}]}]}
{"op":"mcm","clk":"11897720996","pt":1724265701214,"mc":[{"id":"1.231875523","rc":[{"batb":[[0,1.5,20],[1,1.08,31.25],[2,1.07,35.71]],"ltp":0.0,"tv":0.0,"id":475559}]}]}
{"op":"mcm","clk":"11897725468","pt":1724265726725,"mc":[{"id":"1.231875523","rc":[{"batb":[[0,1.51,16.78],[1,1.5,20],[2,1.08,31.25]],"ltp":1.03,"tv":2.0,"id":31378},{"batb":[[0,1.51,16.78],[1,1.5,20],[2,1.08,31.25]],"ltp":0.0,"tv":0.0,"id":475559},{"batb":[[0,1.51,17.67],[1,1.35,56.25]],"ltp":0.0,"tv":0.0,"id":60443}]}]}
{"op":"mcm","clk":"11898007093","pt":1724267528232,"mc":[{"id":"1.231875523","rc":[{"batb":[[0,1.5,20],[1,1.08,31.25],[2,1.07,35.71]],"ltp":1.03,"tv":2.0,"id":31378},{"batb":[[0,1.5,20],[1,1.08,31.25],[2,1.07,35.71]],"ltp":0.0,"tv":0.0,"id":475559},{"batb":[[0,1.5,1.77],[1,1.35,55.35]],"ltp":0.0,"tv":0.0,"id":60443}]}]}
{"op":"mcm","clk":"11898034079","pt":1724267696902,"mc":[{"id":"1.231875523","rc":[{"batb":[[0,1.51,16.78],[1,1.5,20],[2,1.08,31.25]],"ltp":1.03,"tv":2.0,"id":31378},{"batb":[[0,1.51,16.78],[1,1.5,20],[2,1.08,31.25]],"ltp":0.0,"tv":0.0,"id":475559},{"batb":[[0,1.51,17.67],[1,1.35,56.24]],"ltp":0.0,"tv":0.0,"id":60443}]}]}
{"op":"mcm","clk":"11898304807","pt":1724269498459,"mc":[{"id":"1.231875523","rc":[{"batb":[[0,1.5,20],[1,1.08,31.25],[2,1.07,35.71]],"ltp":1.03,"tv":2.0,"id":31378},{"batb":[[0,1.5,1.77],[1,1.35,55.35]],"ltp":0.0,"tv":0.0,"id":60443},{"batb":[[0,1.5,20],[1,1.08,31.25],[2,1.07,35.71]],"ltp":0.0,"tv":0.0,"id":475559}]}]}
{"op":"mcm","clk":"11898322293","pt":1724269624448,"mc":[{"id":"1.231875523","rc":[{"batb":[[0,1.51,16.78],[1,1.5,20],[2,1.08,31.25]],"ltp":1.03,"tv":2.0,"id":31378},{"batb":[[0,1.51,17.67],[1,1.35,56.24]],"ltp":0.0,"tv":0.0,"id":60443},{"batb":[[0,1.51,16.78],[1,1.5,20],[2,1.08,31.25]],"ltp":0.0,"tv":0.0,"id":475559}]}]}
{"op":"mcm","clk":"11898487292","pt":1724271424994,"mc":[{"id":"1.231875523","rc":[{"batb":[[0,1.51,16.79]],"ltp":1.03,"tv":2.0,"id":31378},{"batb":[[0,1.5,1.78],[1,1.35,55.38]],"ltp":0.0,"tv":0.0,"id":60443},{"batb":[[0,1.5,20],[1,1.08,31.25],[2,1.07,35.71]],"ltp":0.0,"tv":0.0,"id":475559}]}]}
{"op":"mcm","clk":"11898487312","pt":1724271425203,"mc":[{"id":"1.231875523","rc":[{"batb":[[0,1.5,20],[1,1.08,31.25],[2,1.07,35.71]],"ltp":1.03,"tv":2.0,"id":31378}]}]}
{"op":"mcm","clk":"11898499541","pt":1724271548865,"mc":[{"id":"1.231875523","rc":[{"batb":[[0,1.51,16.79],[1,1.5,20],[2,1.08,31.25]],"ltp":1.03,"tv":2.0,"id":31378},{"batb":[[0,1.51,17.68],[1,1.35,56.27]],"ltp":0.0,"tv":0.0,"id":60443},{"batb":[[0,1.51,16.79],[1,1.5,20],[2,1.08,31.25]],"ltp":0.0,"tv":0.0,"id":475559}]}]}
{"op":"mcm","clk":"11898570072","pt":1724272349467,"mc":[{"id":"1.231875523","rc":[{"batb":[[0,1.8,62.5],[1,1.51,16.79],[2,1.5,20]],"ltp":1.03,"tv":2.0,"id":31378}]}]}
{"op":"mcm","clk":"11898570729","pt":1724272356998,"mc":[{"id":"1.231875523","rc":[{"batb":[[0,1.8,62.5],[1,1.51,16.79],[2,1.5,20]],"ltp":0.0,"tv":0.0,"id":475559}]}]}
{"op":"mcm","clk":"11898643055","pt":1724273352060,"mc":[{"id":"1.231875523","rc":[{"batb":[[1,1.5,20],[2,1.08,31.25]],"ltp":1.03,"tv":2.0,"id":31378},{"batb":[[0,1.5,1.78],[1,1.35,55.38]],"ltp":0.0,"tv":0.0,"id":60443},{"batb":[[1,1.5,20],[2,1.08,31.25]],"ltp":0.0,"tv":0.0,"id":475559}]}]}
{"op":"mcm","clk":"11898646554","pt":1724273408909,"mc":[{"id":"1.231875523","rc":[{"batb":[[0,1.81,10.57],[1,1.8,62.5],[2,1.5,20]],"ltp":1.03,"tv":2.0,"id":31378},{"batb":[[0,1.51,17.68],[1,1.35,56.27]],"ltp":0.0,"tv":0.0,"id":60443},{"batb":[[0,1.81,10.57],[1,1.8,62.5],[2,1.5,20]],"ltp":0.0,"tv":0.0,"id":475559}]}]}
{"op":"mcm","clk":"11898718979","pt":1724274774996,"mc":[{"id":"1.231875523","rc":[{"batb":[[0,1.81,10.57]],"ltp":1.03,"tv":2.0,"id":31378},{"batb":[[0,1.51,17.67],[1,1.35,56.25]],"ltp":0.0,"tv":0.0,"id":60443},{"batb":[[0,1.81,10.57]],"ltp":0.0,"tv":0.0,"id":475559}]}]}
{"op":"mcm","clk":"11898741228","pt":1724275209080,"mc":[{"id":"1.231875523","rc":[{"batb":[[0,1.8,62.5],[1,1.5,20],[2,1.08,31.25]],"ltp":0.0,"tv":0.0,"id":475559}]}]}
{"op":"mcm","clk":"11898741244","pt":1724275209443,"mc":[{"id":"1.231875523","rc":[{"batb":[[0,1.8,62.5],[1,1.5,20],[2,1.08,31.25]],"ltp":1.03,"tv":2.0,"id":31378},{"batb":[[0,1.5,1.78],[1,1.35,55.37]],"ltp":0.0,"tv":0.0,"id":60443}]}]}
{"op":"mcm","clk":"11898742209","pt":1724275228396,"mc":[{"id":"1.231875523","rc":[{"batb":[[0,1.81,10.57],[1,1.8,62.5],[2,1.5,20]],"ltp":1.03,"tv":2.0,"id":31378},{"batb":[[0,1.51,17.67],[1,1.35,56.25]],"ltp":0.0,"tv":0.0,"id":60443},{"batb":[[0,1.81,10.57],[1,1.8,62.5],[2,1.5,20]],"ltp":0.0,"tv":0.0,"id":475559}]}]}
{"op":"mcm","clk":"11898821357","pt":1724277028902,"mc":[{"id":"1.231875523","rc":[{"batb":[[0,1.5,1.78],[1,1.35,55.37]],"ltp":0.0,"tv":0.0,"id":60443}]}]}
{"op":"mcm","clk":"11898821374","pt":1724277029263,"mc":[{"id":"1.231875523","rc":[{"batb":[[0,1.8,62.5],[1,1.5,20],[2,1.08,31.25]],"ltp":1.03,"tv":2.0,"id":31378},{"batb":[[0,1.8,62.5],[1,1.5,20],[2,1.08,31.25]],"ltp":0.0,"tv":0.0,"id":475559}]}]}
{"op":"mcm","clk":"11898830216","pt":1724277205071,"mc":[{"id":"1.231875523","rc":[{"batb":[[0,1.81,10.57],[1,1.8,62.5],[2,1.5,20]],"ltp":1.03,"tv":2.0,"id":31378},{"batb":[[0,1.51,17.67],[1,1.35,56.25]],"ltp":0.0,"tv":0.0,"id":60443},{"batb":[[0,1.81,10.57],[1,1.8,62.5],[2,1.5,20]],"ltp":0.0,"tv":0.0,"id":475559}]}]}
{"op":"mcm","clk":"11898930889","pt":1724279007521,"mc":[{"id":"1.231875523","rc":[{"batb":[[0,1.8,62.5],[1,1.5,20],[2,1.08,31.25]],"ltp":1.03,"tv":2.0,"id":31378},{"batb":[[0,1.5,1.78],[1,1.35,55.35]],"ltp":0.0,"tv":0.0,"id":60443},{"batb":[[0,1.8,62.5],[1,1.5,20],[2,1.08,31.25]],"ltp":0.0,"tv":0.0,"id":475559}]}]}
{"op":"mcm","clk":"11898938609","pt":1724279142018,"mc":[{"id":"1.231875523","rc":[{"batb":[[0,1.81,10.56],[1,1.8,62.5],[2,1.5,20]],"ltp":1.03,"tv":2.0,"id":31378},{"batb":[[0,1.51,17.67],[1,1.35,56.24]],"ltp":0.0,"tv":0.0,"id":60443},{"batb":[[0,1.81,10.56],[1,1.8,62.5],[2,1.5,20]],"ltp":0.0,"tv":0.0,"id":475559}]}]}
{"op":"mcm","clk":"11899051416","pt":1724280943624,"mc":[{"id":"1.231875523","rc":[{"batb":[[0,1.8,62.5],[1,1.5,20],[2,1.08,31.25]],"ltp":1.03,"tv":2.0,"id":31378},{"batb":[[0,1.5,1.78],[1,1.35,55.35]],"ltp":0.0,"tv":0.0,"id":60443},{"batb":[[0,1.8,62.5],[1,1.5,20],[2,1.08,31.25]],"ltp":0.0,"tv":0.0,"id":475559}]}]}
{"op":"mcm","clk":"11899056829","pt":1724281058999,"mc":[{"id":"1.231875523","rc":[{"batb":[[0,1.81,10.56],[1,1.8,62.5],[2,1.5,20]],"ltp":1.03,"tv":2.0,"id":31378},{"batb":[[0,1.51,17.67],[1,1.35,56.24]],"ltp":0.0,"tv":0.0,"id":60443},{"batb":[[0,1.81,10.56],[1,1.8,62.5],[2,1.5,20]],"ltp":0.0,"tv":0.0,"id":475559}]}]}
{"op":"mcm","clk":"11899143617","pt":1724282861042,"mc":[{"id":"1.231875523","rc":[{"batb":[[0,1.8,62.5],[1,1.5,20],[2,1.08,31.25]],"ltp":1.03,"tv":2.0,"id":31378},{"batb":[[0,1.51,17.68],[1,1.35,56.27]],"ltp":0.0,"tv":0.0,"id":60443},{"batb":[[0,1.8,62.5],[1,1.5,20],[2,1.08,31.25]],"ltp":0.0,"tv":0.0,"id":475559}]}]}
{"op":"mcm","clk":"11899143623","pt":1724282861095,"mc":[{"id":"1.231875523","rc":[{"batb":[[0,1.5,1.78],[1,1.35,55.39]],"ltp":0.0,"tv":0.0,"id":60443}]}]}
{"op":"mcm","clk":"11899147840","pt":1724282952551,"mc":[{"id":"1.231875523","rc":[{"batb":[[0,1.81,10.57],[1,1.8,62.5],[2,1.5,20]],"ltp":1.03,"tv":2.0,"id":31378},{"batb":[[0,1.51,17.68],[1,1.35,56.27]],"ltp":0.0,"tv":0.0,"id":60443},{"batb":[[0,1.81,10.57],[1,1.8,62.5],[2,1.5,20]],"ltp":0.0,"tv":0.0,"id":475559}]}]}
{"op":"mcm","clk":"11899229090","pt":1724284753967,"mc":[{"id":"1.231875523","rc":[{"batb":[[0,1.8,62.5],[1,1.5,20],[2,1.08,31.25]],"ltp":1.03,"tv":2.0,"id":31378},{"batb":[[0,1.5,1.78],[1,1.35,55.39]],"ltp":0.0,"tv":0.0,"id":60443},{"batb":[[0,1.8,62.5],[1,1.5,20],[2,1.08,31.25]],"ltp":0.0,"tv":0.0,"id":475559}]}]}
{"op":"mcm","clk":"11899233406","pt":1724284828164,"mc":[{"id":"1.231875523","rc":[{"batb":[[0,1.81,10.57],[1,1.8,62.5],[2,1.5,20]],"ltp":1.03,"tv":2.0,"id":31378},{"batb":[[0,1.51,17.68],[1,1.35,56.26]],"ltp":0.0,"tv":0.0,"id":60443},{"batb":[[0,1.81,10.57],[1,1.8,62.5],[2,1.5,20]],"ltp":0.0,"tv":0.0,"id":475559}]}]}
{"op":"mcm","clk":"11899339526","pt":1724286628654,"mc":[{"id":"1.231875523","rc":[{"batb":[[0,1.8,62.5],[1,1.5,20],[2,1.08,31.25]],"ltp":1.03,"tv":2.0,"id":31378},{"batb":[[0,1.8,62.5],[1,1.5,20],[2,1.08,31.25]],"ltp":0.0,"tv":0.0,"id":475559},{"batb":[[0,1.5,1.78],[1,1.35,55.38]],"ltp":0.0,"tv":0.0,"id":60443}]}]}
{"op":"mcm","clk":"11899342452","pt":1724286679023,"mc":[{"id":"1.231875523","rc":[{"batb":[[0,1.81,10.57],[1,1.8,62.5],[2,1.5,20]],"ltp":1.03,"tv":2.0,"id":31378},{"batb":[[0,1.81,10.57],[1,1.8,62.5],[2,1.5,20]],"ltp":0.0,"tv":0.0,"id":475559},{"batb":[[0,1.51,17.68],[1,1.35,56.26]],"ltp":0.0,"tv":0.0,"id":60443}]}]}
{"op":"mcm","clk":"11899448133","pt":1724288479449,"mc":[{"id":"1.231875523","rc":[{"batb":[[0,1.8,62.5],[1,1.5,20],[2,1.08,31.25]],"ltp":1.03,"tv":2.0,"id":31378},{"batb":[[0,1.8,62.5],[1,1.5,20],[2,1.08,31.25]],"ltp":0.0,"tv":0.0,"id":475559},{"batb":[[0,1.5,1.78],[1,1.35,55.35]],"ltp":0.0,"tv":0.0,"id":60443}]}]}
{"op":"mcm","clk":"11899450096","pt":1724288511968,"mc":[{"id":"1.231875523","rc":[{"batb":[[0,1.81,10.56],[1,1.8,62.5],[2,1.5,20]],"ltp":1.03,"tv":2.0,"id":31378},{"batb":[[0,1.81,10.56],[1,1.8,62.5],[2,1.5,20]],"ltp":0.0,"tv":0.0,"id":475559},{"batb":[[0,1.51,17.67],[1,1.35,56.24]],"ltp":0.0,"tv":0.0,"id":60443}]}]}
{"op":"mcm","clk":"11899553756","pt":1724290313629,"mc":[{"id":"1.231875523","rc":[{"batb":[[0,1.8,62.5],[1,1.5,20],[2,1.08,31.25]],"ltp":1.03,"tv":2.0,"id":31378},{"batb":[[0,1.8,62.5],[1,1.5,20],[2,1.08,31.25]],"ltp":0.0,"tv":0.0,"id":475559},{"batb":[[0,1.5,1.78],[1,1.35,55.35]],"ltp":0.0,"tv":0.0,"id":60443}]}]}
{"op":"mcm","clk":"11899554184","pt":1724290323233,"mc":[{"id":"1.231875523","rc":[{"batb":[[0,1.81,10.56],[1,1.8,62.5],[2,1.5,20]],"ltp":1.03,"tv":2.0,"id":31378},{"batb":[[0,1.81,10.56],[1,1.8,62.5],[2,1.5,20]],"ltp":0.0,"tv":0.0,"id":475559},{"batb":[[0,1.51,17.67],[1,1.35,56.24]],"ltp":0.0,"tv":0.0,"id":60443}]}]}
{"op":"mcm","clk":"11899654565","pt":1724292125938,"mc":[{"id":"1.231875523","rc":[{"batb":[[0,1.5,1.78],[1,1.35,55.35]],"ltp":0.0,"tv":0.0,"id":60443},{"batb":[[0,1.8,62.5],[1,1.5,20],[2,1.08,31.25]],"ltp":0.0,"tv":0.0,"id":475559}]}]}
{"op":"mcm","clk":"11899654582","pt":1724292126140,"mc":[{"id":"1.231875523","rc":[{"batb":[[0,1.8,62.5],[1,1.5,20],[2,1.08,31.25]],"ltp":1.03,"tv":2.0,"id":31378}]}]}
{"op":"mcm","clk":"11899661185","pt":1724292281230,"mc":[{"id":"1.231875523","rc":[{"batb":[[0,1.81,10.56],[1,1.8,62.5],[2,1.5,20]],"ltp":1.03,"tv":2.0,"id":31378},{"batb":[[0,1.51,17.67],[1,1.35,56.24]],"ltp":0.0,"tv":0.0,"id":60443},{"batb":[[0,1.81,10.56],[1,1.8,62.5],[2,1.5,20]],"ltp":0.0,"tv":0.0,"id":475559}]}]}
{"op":"mcm","clk":"11899729269","pt":1724294081831,"mc":[{"id":"1.231875523","rc":[{"batb":[[0,1.8,62.5],[1,1.5,20],[2,1.08,31.25]],"ltp":1.03,"tv":2.0,"id":31378},{"batb":[[0,1.8,62.5],[1,1.5,20],[2,1.08,31.25]],"ltp":0.0,"tv":0.0,"id":475559}]}]}
{"op":"mcm","clk":"11899729278","pt":1724294082138,"mc":[{"id":"1.231875523","rc":[{"batb":[[0,1.5,1.78],[1,1.35,55.35]],"ltp":0.0,"tv":0.0,"id":60443}]}]}
{"op":"mcm","clk":"11899733540","pt":1724294216059,"mc":[{"id":"1.231875523","rc":[{"batb":[[0,1.81,10.56],[1,1.8,62.5],[2,1.5,20]],"ltp":1.03,"tv":2.0,"id":31378},{"batb":[[0,1.51,17.67],[1,1.35,56.24]],"ltp":0.0,"tv":0.0,"id":60443},{"batb":[[0,1.81,10.56],[1,1.8,62.5],[2,1.5,20]],"ltp":0.0,"tv":0.0,"id":475559}]}]}
{"op":"mcm","clk":"11899804211","pt":1724296017825,"mc":[{"id":"1.231875523","rc":[{"batb":[[0,1.8,62.5],[1,1.5,20],[2,1.08,31.25]],"ltp":1.03,"tv":2.0,"id":31378},{"batb":[[0,1.5,1.78],[1,1.35,55.35]],"ltp":0.0,"tv":0.0,"id":60443},{"batb":[[0,1.8,62.5],[1,1.5,20],[2,1.08,31.25]],"ltp":0.0,"tv":0.0,"id":475559}]}]}
{"op":"mcm","clk":"11899807830","pt":1724296126116,"mc":[{"id":"1.231875523","rc":[{"batb":[[0,1.81,10.56],[1,1.8,62.5],[2,1.5,20]],"ltp":1.03,"tv":2.0,"id":31378},{"batb":[[0,1.51,17.67],[1,1.35,56.24]],"ltp":0.0,"tv":0.0,"id":60443},{"batb":[[0,1.81,10.56],[1,1.8,62.5],[2,1.5,20]],"ltp":0.0,"tv":0.0,"id":475559}]}]}
{"op":"mcm","clk":"11899884680","pt":1724297926734,"mc":[{"id":"1.231875523","rc":[{"batb":[[0,1.8,62.5],[1,1.5,20],[2,1.08,31.25]],"ltp":1.03,"tv":2.0,"id":31378},{"batb":[[0,1.8,62.5],[1,1.5,20],[2,1.08,31.25]],"ltp":0.0,"tv":0.0,"id":475559},{"batb":[[0,1.5,1.78],[1,1.35,55.35]],"ltp":0.0,"tv":0.0,"id":60443}]}]}
{"op":"mcm","clk":"11899887539","pt":1724298024507,"mc":[{"id":"1.231875523","rc":[{"batb":[[0,1.81,10.56],[1,1.8,62.5],[2,1.5,20]],"ltp":1.03,"tv":2.0,"id":31378},{"batb":[[0,1.81,10.56],[1,1.8,62.5],[2,1.5,20]],"ltp":0.0,"tv":0.0,"id":475559},{"batb":[[0,1.51,17.67],[1,1.35,56.24]],"ltp":0.0,"tv":0.0,"id":60443}]}]}
{"op":"mcm","clk":"11899945574","pt":1724299824988,"mc":[{"id":"1.231875523","rc":[{"batb":[[0,1.8,62.5],[1,1.5,20],[2,1.08,31.25]],"ltp":1.03,"tv":2.0,"id":31378},{"batb":[[0,1.51,17.67],[1,1.35,56.25]],"ltp":0.0,"tv":0.0,"id":60443}]}]}
{"op":"mcm","clk":"11899945584","pt":1724299825462,"mc":[{"id":"1.231875523","rc":[{"batb":[[0,1.8,62.5],[1,1.5,20],[2,1.08,31.25]],"ltp":0.0,"tv":0.0,"id":475559},{"batb":[[0,1.5,1.78],[1,1.35,55.36]],"ltp":0.0,"tv":0.0,"id":60443}]}]}
{"op":"mcm","clk":"11899947925","pt":1724299912697,"mc":[{"id":"1.231875523","rc":[{"batb":[[0,1.81,10.57],[1,1.8,62.5],[2,1.5,20]],"ltp":1.03,"tv":2.0,"id":31378},{"batb":[[0,1.81,10.57],[1,1.8,62.5],[2,1.5,20]],"ltp":0.0,"tv":0.0,"id":475559},{"batb":[[0,1.51,17.67],[1,1.35,56.25]],"ltp":0.0,"tv":0.0,"id":60443}]}]}
{"op":"mcm","clk":"11899989197","pt":1724301715015,"mc":[{"id":"1.231875523","rc":[{"batb":[[0,1.8,62.5],[1,1.5,20],[2,1.08,31.25]],"ltp":1.03,"tv":2.0,"id":31378}]}]}
{"op":"mcm","clk":"11899989214","pt":1724301715378,"mc":[{"id":"1.231875523","rc":[{"batb":[[0,1.8,62.5],[1,1.5,20],[2,1.08,31.25]],"ltp":0.0,"tv":0.0,"id":475559},{"batb":[[0,1.5,1.78],[1,1.35,55.36]],"ltp":0.0,"tv":0.0,"id":60443}]}]}
{"op":"mcm","clk":"11900001525","pt":1724301787607,"mc":[{"id":"1.231875523","rc":[{"batb":[[0,1.81,10.57],[1,1.8,62.5],[2,1.5,20]],"ltp":1.03,"tv":2.0,"id":31378},{"batb":[[0,1.51,17.67],[1,1.35,56.25]],"ltp":0.0,"tv":0.0,"id":60443},{"batb":[[0,1.81,10.57],[1,1.8,62.5],[2,1.5,20]],"ltp":0.0,"tv":0.0,"id":475559}]}]}
{"op":"mcm","clk":"11900047069","pt":1724303590507,"mc":[{"id":"1.231875523","rc":[{"batb":[[0,1.8,62.5],[1,1.5,20],[2,1.08,31.25]],"ltp":1.03,"tv":2.0,"id":31378},{"batb":[[0,1.5,1.78],[1,1.35,55.36]],"ltp":0.0,"tv":0.0,"id":60443},{"batb":[[0,1.8,62.5],[1,1.5,20],[2,1.08,31.25]],"ltp":0.0,"tv":0.0,"id":475559}]}]}
{"op":"mcm","clk":"11900048926","pt":1724303663900,"mc":[{"id":"1.231875523","rc":[{"batb":[[0,1.81,10.57],[1,1.8,62.5],[2,1.5,20]],"ltp":1.03,"tv":2.0,"id":31378},{"batb":[[0,1.51,17.67],[1,1.35,56.25]],"ltp":0.0,"tv":0.0,"id":60443},{"batb":[[0,1.81,10.57],[1,1.8,62.5],[2,1.5,20]],"ltp":0.0,"tv":0.0,"id":475559}]}]}
{"op":"mcm","clk":"11900098747","pt":1724305466569,"mc":[{"id":"1.231875523","rc":[{"batb":[[0,1.8,62.5],[1,1.5,20],[2,1.08,31.25]],"ltp":1.03,"tv":2.0,"id":31378},{"batb":[[0,1.5,1.78],[1,1.35,55.36]],"ltp":0.0,"tv":0.0,"id":60443},{"batb":[[0,1.8,62.5],[1,1.5,20],[2,1.08,31.25]],"ltp":0.0,"tv":0.0,"id":475559}]}]}
{"op":"mcm","clk":"11900102503","pt":1724305607330,"mc":[{"id":"1.231875523","rc":[{"batb":[[0,1.81,10.57],[1,1.8,62.5],[2,1.5,20]],"ltp":1.03,"tv":2.0,"id":31378},{"batb":[[0,1.51,17.67],[1,1.35,56.25]],"ltp":0.0,"tv":0.0,"id":60443},{"batb":[[0,1.81,10.57],[1,1.8,62.5],[2,1.5,20]],"ltp":0.0,"tv":0.0,"id":475559}]}]}
{"op":"mcm","clk":"11900155471","pt":1724307175099,"mc":[{"id":"1.231875523","rc":[{"batb":[[0,1.51,17.67],[1,1.35,56.25]],"ltp":0.0,"tv":0.0,"id":60443}]}]}
{"op":"mcm","clk":"11900167234","pt":1724307408948,"mc":[{"id":"1.231875523","rc":[{"batb":[[0,1.8,62.5],[1,1.5,20],[2,1.08,31.25]],"ltp":1.03,"tv":2.0,"id":31378},{"batb":[[0,1.5,1.78],[1,1.35,55.36]],"ltp":0.0,"tv":0.0,"id":60443}]}]}
{"op":"mcm","clk":"11900167244","pt":1724307409156,"mc":[{"id":"1.231875523","rc":[{"batb":[[0,1.8,62.5],[1,1.5,20],[2,1.08,31.25]],"ltp":0.0,"tv":0.0,"id":475559}]}]}
{"op":"mcm","clk":"11900171217","pt":1724307535724,"mc":[{"id":"1.231875523","rc":[{"batb":[[0,1.81,10.57],[1,1.8,62.5],[2,1.5,20]],"ltp":1.03,"tv":2.0,"id":31378},{"batb":[[0,1.51,17.67],[1,1.35,56.25]],"ltp":0.0,"tv":0.0,"id":60443},{"batb":[[0,1.81,10.57],[1,1.8,62.5],[2,1.5,20]],"ltp":0.0,"tv":0.0,"id":475559}]}]}
{"op":"mcm","clk":"11900194982","pt":1724308347402,"mc":[{"id":"1.231875523","rc":[{"batl":[[0,85,1.71]],"ltp":1.03,"tv":2.0,"id":31378}]}]}
{"op":"mcm","clk":"11900197015","pt":1724308401472,"mc":[{"id":"1.231875523","rc":[{"batl":[[0,85,1.71]],"ltp":0.0,"tv":0.0,"id":475559}]}]}
{"op":"mcm","clk":"11900197237","pt":1724308407554,"mc":[{"id":"1.231875523","rc":[{"batl":[[0,55,1.47],[1,85,1],[2,95,5.85]],"ltp":1.03,"tv":2.0,"id":31378}]}]}
{"op":"mcm","clk":"11900197412","pt":1724308412063,"mc":[{"id":"1.231875523","rc":[{"batl":[[1,95,5.85],[2,990,5.51]],"ltp":1.03,"tv":2.0,"id":31378},{"batl":[[0,55,1.47],[1,85,1],[2,95,5.85]],"ltp":0.0,"tv":0.0,"id":475559}]}]}
{"op":"mcm","clk":"11900197570","pt":1724308416790,"mc":[{"id":"1.231875523","rc":[{"batl":[[0,50,1.71],[1,90,1.62],[2,95,5]],"ltp":1.03,"tv":2.0,"id":31378},{"batl":[[1,95,5.85],[2,990,5.51]],"ltp":0.0,"tv":0.0,"id":475559}]}]}
{"op":"mcm","clk":"11900197649","pt":1724308419304,"mc":[{"id":"1.231875523","rc":[{"batl":[[0,85,1.71]],"ltp":0.0,"tv":0.0,"id":60443}]}]}
{"op":"mcm","clk":"11900197756","pt":1724308422286,"mc":[{"id":"1.231875523","rc":[{"batl":[[0,50,1.71],[1,90,1.62],[2,95,5]],"ltp":0.0,"tv":0.0,"id":475559}]}]}
{"op":"mcm","clk":"11900197964","pt":1724308428279,"mc":[{"id":"1.231875523","rc":[{"batl":[[0,44,1.3],[1,50,1.17],[2,95,5.85]],"ltp":1.03,"tv":2.0,"id":31378}]}]}
{"op":"mcm","clk":"11900198099","pt":1724308431205,"mc":[{"id":"1.231875523","rc":[{"batl":[[0,44,1.3],[1,50,1.17],[2,95,5.85]],"ltp":0.0,"tv":0.0,"id":475559}]}]}
{"op":"mcm","clk":"11900198172","pt":1724308433424,"mc":[{"id":"1.231875523","rc":[{"batl":[[1,90,1.02],[2,95,5]],"ltp":1.03,"tv":2.0,"id":31378},{"batl":[[1,90,1.02],[2,95,5]],"ltp":0.0,"tv":0.0,"id":475559}]}]}
{"op":"mcm","clk":"11900198264","pt":1724308435739,"mc":[{"id":"1.231875523","rc":[{"batl":[[0,48,1.16],[1,95,5.85],[2,990,5.51]],"ltp":1.03,"tv":2.0,"id":31378}]}]}
{"op":"mcm","clk":"11900198394","pt":1724308439003,"mc":[{"id":"1.231875523","rc":[{"batl":[[0,42,1.54],[1,90,1.48],[2,95,5]],"ltp":1.03,"tv":2.0,"id":31378},{"batl":[[0,42,1.54],[1,90,1.48]],"ltp":0.0,"tv":0.0,"id":475559}]}]}
{"op":"mcm","clk":"11900198642","pt":1724308445701,"mc":[{"id":"1.231875523","rc":[{"batl":[[0,42,1.99],[1,90,1.02]],"ltp":0.0,"tv":0.0,"id":475559}]}]}
{"op":"mcm","clk":"11900198663","pt":1724308446522,"mc":[{"id":"1.231875523","rc":[{"batl":[[0,42,1.99],[1,90,1.02]],"ltp":1.03,"tv":2.0,"id":31378}]}]}
{"op":"mcm","clk":"11900198758","pt":1724308450116,"mc":[{"id":"1.231875523","rc":[{"batl":[[0,48,1.16],[1,95,5.85],[2,990,5.51]],"ltp":1.03,"tv":2.0,"id":31378},{"batl":[[0,48,1.16],[1,95,5.85],[2,990,5.51]],"ltp":0.0,"tv":0.0,"id":475559}]}]}
{"op":"mcm","clk":"11900198859","pt":1724308453752,"mc":[{"id":"1.231875523","rc":[{"batl":[[0,38,1.07],[1,85,1.17],[2,95,5.85]],"ltp":0.0,"tv":0.0,"id":60443}]}]}
{"op":"mcm","clk":"11900198948","pt":1724308455726,"mc":[{"id":"1.231875523","rc":[{"batl":[[0,34,1.54],[1,90,1.48],[2,95,5]],"ltp":1.03,"tv":2.0,"id":31378},{"batl":[[1,90,1.02],[2,95,5]],"ltp":0.0,"tv":0.0,"id":60443},{"batl":[[0,34,1.54],[1,90,1.48],[2,95,5]],"ltp":0.0,"tv":0.0,"id":475559}]}]}
{"op":"mcm","clk":"11900199150","pt":1724308461042,"mc":[{"id":"1.231875523","rc":[{"batl":[[0,34,1.99],[1,90,1.02]],"ltp":0.0,"tv":0.0,"id":475559}]}]}
{"op":"mcm","clk":"11900199188","pt":1724308461761,"mc":[{"id":"1.231875523","rc":[{"batl":[[0,34,1.99],[1,90,1.02]],"ltp":1.03,"tv":2.0,"id":31378},{"batl":[[0,36,1.54],[1,90,1.56]],"ltp":0.0,"tv":0.0,"id":60443}]}]}
{"op":"mcm","clk":"11900199337","pt":1724308466840,"mc":[{"id":"1.231875523","rc":[{"batl":[[0,48,1.16],[1,95,5.85],[2,990,5.51]],"ltp":1.03,"tv":2.0,"id":31378},{"batl":[[0,48,1.16],[1,95,5.85],[2,990,5.51]],"ltp":0.0,"tv":0.0,"id":475559}]}]}
{"op":"mcm","clk":"11900199566","pt":1724308472451,"mc":[{"id":"1.231875523","rc":[{"batl":[[0,21,1.54],[1,90,1.48],[2,95,5]],"ltp":1.03,"tv":2.0,"id":31378},{"batl":[[0,21,1.54],[1,90,1.48],[2,95,5]],"ltp":0.0,"tv":0.0,"id":475559}]}]}
{"op":"mcm","clk":"11900199632","pt":1724308474560,"mc":[{"id":"1.231875523","rc":[{"batl":[[0,21,1.99],[1,90,1.02]],"ltp":0.0,"tv":0.0,"id":475559}]}]}
{"op":"mcm","clk":"11900199652","pt":1724308475281,"mc":[{"id":"1.231875523","rc":[{"batl":[[0,21,1.99],[1,90,1.02]],"ltp":1.03,"tv":2.0,"id":31378}]}]}
{"op":"mcm","clk":"11900199943","pt":1724308483595,"mc":[{"id":"1.231875523","rc":[{"batl":[[0,48,1.16],[1,95,5.85],[2,990,5.51]],"ltp":1.03,"tv":2.0,"id":31378},{"batl":[[0,48,1.16],[1,95,5.85],[2,990,5.51]],"ltp":0.0,"tv":0.0,"id":475559}]}]}
{"op":"mcm","clk":"11900199994","pt":1724308485089,"mc":[{"id":"1.231875523","rc":[{"batl":[[0,36,1.53],[1,90,1.02],[2,95,5]],"ltp":1.03,"tv":2.0,"id":31378}]}]}
{"op":"mcm","clk":"11900200182","pt":1724308489157,"mc":[{"id":"1.231875523","rc":[{"batl":[[0,15.5,1.54],[1,48,1.16],[2,95,5.85]],"ltp":1.03,"tv":2.0,"id":31378},{"batl":[[0,15.5,1.54],[1,90,1.48],[2,95,5]],"ltp":0.0,"tv":0.0,"id":475559}]}]}
{"op":"mcm","clk":"11900200275","pt":1724308491163,"mc":[{"id":"1.231875523","rc":[{"batl":[[1,48,1.16],[2,95,5.85]],"ltp":0.0,"tv":0.0,"id":475559}]}]}
{"op":"mcm","clk":"11900200398","pt":1724308494301,"mc":[{"id":"1.231875523","rc":[{"batl":[[0,15.5,1.99],[1,90,1.56],[2,95,5]],"ltp":1.03,"tv":2.0,"id":31378}]}]}
{"op":"mcm","clk":"11900200461","pt":1724308496301,"mc":[{"id":"1.231875523","rc":[{"batl":[[0,15.5,1.99],[1,90,1.56],[2,95,5]],"ltp":0.0,"tv":0.0,"id":475559}]}]}
{"op":"mcm","clk":"11900200651","pt":1724308501086,"mc":[{"id":"1.231875523","rc":[{"batl":[[0,36,1.53],[1,90,1.02]],"ltp":1.03,"tv":2.0,"id":31378},{"batl":[[0,36,1.53],[1,90,1.02]],"ltp":0.0,"tv":0.0,"id":475559}]}]}
{"op":"mcm","clk":"11900200841","pt":1724308505915,"mc":[{"id":"1.231875523","rc":[{"batl":[[0,13.5,1.54],[1,48,1.16],[2,95,5.85]],"ltp":1.03,"tv":2.0,"id":31378},{"batl":[[0,13.5,1.54],[1,48,1.16],[2,95,5.85]],"ltp":0.0,"tv":0.0,"id":475559}]}]}
{"op":"mcm","clk":"11900201044","pt":1724308509685,"mc":[{"id":"1.231875523","rc":[{"batl":[[0,13.5,1.99],[1,90,1.56],[2,95,5]],"ltp":1.03,"tv":2.0,"id":31378}]}]}
{"op":"mcm","clk":"11900201347","pt":1724308515405,"mc":[{"id":"1.231875523","rc":[{"batl":[[0,13.5,1.99],[1,90,1.56],[2,95,5]],"ltp":0.0,"tv":0.0,"id":475559}]}]}
{"op":"mcm","clk":"11900201428","pt":1724308516996,"mc":[{"id":"1.231875523","rc":[{"batl":[[0,36,1.53],[1,90,1.02]],"ltp":1.03,"tv":2.0,"id":31378},{"batl":[[0,36,1.53],[1,90,1.02]],"ltp":0.0,"tv":0.0,"id":475559}]}]}
{"op":"mcm","clk":"11900201640","pt":1724308522725,"mc":[{"id":"1.231875523","rc":[{"batl":[[0,11.5,1.54],[1,48,1.16],[2,95,5.85]],"ltp":1.03,"tv":2.0,"id":31378},{"batl":[[0,11.5,1.54],[1,48,1.16],[2,95,5.85]],"ltp":0.0,"tv":0.0,"id":475559}]}]}
{"op":"mcm","clk":"11900201684","pt":1724308523803,"mc":[{"id":"1.231875523","rc":[{"batl":[[0,11.5,1.99],[1,90,1.56],[2,95,5]],"ltp":0.0,"tv":0.0,"id":475559}]}]}
{"op":"mcm","clk":"11900201730","pt":1724308524826,"mc":[{"id":"1.231875523","rc":[{"batl":[[0,11.5,1.99],[1,90,1.56],[2,95,5]],"ltp":1.03,"tv":2.0,"id":31378}]}]}
{"op":"mcm","clk":"11900202034","pt":1724308533722,"mc":[{"id":"1.231875523","rc":[{"batl":[[0,36,1.53],[1,90,1.02]],"ltp":1.03,"tv":2.0,"id":31378},{"batl":[[0,36,1.53],[1,90,1.02]],"ltp":0.0,"tv":0.0,"id":475559}]}]}
{"op":"mcm","clk":"11900202147","pt":1724308536438,"mc":[{"id":"1.231875523","rc":[{"batl":[[0,36,2.06]],"ltp":0.0,"tv":0.0,"id":475559}]}]}
{"op":"mcm","clk":"11900202239","pt":1724308539255,"mc":[{"id":"1.231875523","rc":[{"batl":[[0,9.8,1.54],[1,48,1.16],[2,95,5.85]],"ltp":1.03,"tv":2.0,"id":31378},{"batl":[[0,9.8,1.54],[1,36,1.53],[2,90,1.02]],"ltp":0.0,"tv":0.0,"id":475559}]}]}
{"op":"mcm","clk":"11900202413","pt":1724308545046,"mc":[{"id":"1.231875523","rc":[{"batl":[[0,9.8,1.99],[1,90,1.56],[2,95,5]],"ltp":1.03,"tv":2.0,"id":31378},{"batl":[[0,9.8,1.99],[1,36,1.07]],"ltp":0.0,"tv":0.0,"id":475559}]}]}
{"op":"mcm","clk":"11900202607","pt":1724308550362,"mc":[{"id":"1.231875523","rc":[{"batl":[[0,36,1.53],[1,90,1.02]],"ltp":1.03,"tv":2.0,"id":31378},{"batl":[[0,36,2.06],[1,90,1.02],[2,95,5]],"ltp":0.0,"tv":0.0,"id":475559}]}]}
{"op":"mcm","clk":"11900202688","pt":1724308553425,"mc":[{"id":"1.231875523","rc":[{"batb":[[0,1.83,2.29],[1,1.81,10.57],[2,1.8,62.5]],"ltp":1.03,"tv":2.0,"id":31378}]}]}
{"op":"mcm","clk":"11900202773","pt":1724308555930,"mc":[{"id":"1.231875523","rc":[{"batl":[[0,9.4,1.54],[1,48,1.16],[2,95,5.85]],"ltp":1.03,"tv":2.0,"id":31378},{"batl":[[0,9.4,1.54],[1,36,1.53],[2,90,1.02]],"ltp":0.0,"tv":0.0,"id":475559}]}]}
{"op":"mcm","clk":"11900202865","pt":1724308558134,"mc":[{"id":"1.231875523","rc":[{"batb":[[0,1.83,2.29],[1,1.81,10.57],[2,1.8,62.5]],"ltp":0.0,"tv":0.0,"id":475559}]}]}
{"op":"mcm","clk":"11900203016","pt":1724308562750,"mc":[{"id":"1.231875523","rc":[{"batl":[[0,9.4,1.99],[1,90,1.56],[2,95,5]],"ltp":1.03,"tv":2.0,"id":31378}]}]}
{"op":"mcm","clk":"11900203155","pt":1724308566542,"mc":[{"id":"1.231875523","rc":[{"batl":[[0,9.4,1.99],[1,36,1.07]],"ltp":0.0,"tv":0.0,"id":475559}]}]}
{"op":"mcm","clk":"11900203173","pt":1724308567162,"mc":[{"id":"1.231875523","rc":[{"batl":[[0,36,1.53],[1,90,1.02]],"ltp":1.03,"tv":2.0,"id":31378},{"batl":[[0,36,2.06],[1,90,1.02],[2,95,5]],"ltp":0.0,"tv":0.0,"id":475559}]}]}
{"op":"mcm","clk":"11900203422","pt":1724308572676,"mc":[{"id":"1.231875523","rc":[{"batl":[[0,8.8,1.54],[1,48,1.16],[2,95,5.85]],"ltp":1.03,"tv":2.0,"id":31378},{"batl":[[0,8.8,1.54],[1,36,1.53],[2,90,1.02]],"ltp":0.0,"tv":0.0,"id":475559}]}]}
{"op":"mcm","clk":"11900204288","pt":1724308594391,"mc":[{"id":"1.231875523","rc":[{"batb":[[0,1.53,1.65],[1,1.51,16.78],[2,1.35,56.25]],"ltp":0.0,"tv":0.0,"id":60443}]}]}
{"op":"mcm","clk":"11900221954","pt":1724309196439,"mc":[{"id":"1.231875523","rc":[{"batl":[[0,16,1.47],[1,36,1],[2,90,1.56]],"ltp":0.0,"tv":0.0,"id":60443}]}]}
{"op":"mcm","clk":"11900222101","pt":1724309201859,"mc":[{"id":"1.231875523","rc":[{"batl":[[1,90,1.56],[2,95,5]],"ltp":0.0,"tv":0.0,"id":60443}]}]}
{"op":"mcm","clk":"11900222377","pt":1724309207257,"mc":[{"id":"1.231875523","rc":[{"batl":[[0,15.5,1.54],[1,38,1.47],[2,90,1.02]],"ltp":0.0,"tv":0.0,"id":60443}]}]}
{"op":"mcm","clk":"11900227229","pt":1724309336004,"mc":[{"id":"1.231875523","rc":[{"batb":[[1,1.35,56.25],[2,1.3,20]],"ltp":0.0,"tv":0.0,"id":60443}]}]}
{"op":"mcm","clk":"11900227241","pt":1724309336313,"mc":[{"id":"1.231875523","rc":[{"batb":[[1,1.8,62.5],[2,1.5,20]],"ltp":1.03,"tv":2.0,"id":31378},{"batb":[[1,1.8,62.5],[2,1.5,20]],"ltp":0.0,"tv":0.0,"id":475559}]}]}
{"op":"mcm","clk":"11900231833","pt":1724309463256,"mc":[{"id":"1.231875523","rc":[{"batb":[[0,1.84,10.19],[1,1.83,2.29],[2,1.8,62.5]],"ltp":1.03,"tv":2.0,"id":31378},{"batb":[[1,1.51,16.78],[2,1.35,56.25]],"ltp":0.0,"tv":0.0,"id":60443},{"batb":[[0,1.84,10.19],[1,1.83,2.29],[2,1.8,62.5]],"ltp":0.0,"tv":0.0,"id":475559}]}]}
{"op":"mcm","clk":"11900298881","pt":1724311264928,"mc":[{"id":"1.231875523","rc":[{"batb":[[0,1.83,2.29],[1,1.8,62.5],[2,1.5,20]],"ltp":1.03,"tv":2.0,"id":31378},{"batb":[[0,1.53,1.65],[1,1.35,56.24],[2,1.3,20]],"ltp":0.0,"tv":0.0,"id":60443},{"batb":[[0,1.83,2.29],[1,1.8,62.5],[2,1.5,20]],"batl":[[1,36,1.53]],"ltp":0.0,"tv":0.0,"id":475559}]}]}
{"op":"mcm","clk":"11900303979","pt":1724311386998,"mc":[{"id":"1.231875523","rc":[{"batb":[[0,1.84,10.19],[1,1.83,2.29],[2,1.8,62.5]],"ltp":1.03,"tv":2.0,"id":31378},{"batb":[[1,1.51,16.78],[2,1.35,56.24]],"ltp":0.0,"tv":0.0,"id":60443},{"batb":[[0,1.84,10.19],[1,1.83,2.29],[2,1.8,62.5]],"ltp":0.0,"tv":0.0,"id":475559}]}]}
{"op":"mcm","clk":"11900387768","pt":1724313188041,"mc":[{"id":"1.231875523","rc":[{"batb":[[0,1.83,2.29],[1,1.8,62.5],[2,1.5,20]],"ltp":1.03,"tv":2.0,"id":31378},{"batb":[[0,1.83,2.29],[1,1.8,62.5],[2,1.5,20]],"ltp":0.0,"tv":0.0,"id":475559},{"batb":[[1,1.35,56.24],[2,1.3,20]],"ltp":0.0,"tv":0.0,"id":60443}]}]}
{"op":"mcm","clk":"11900392883","pt":1724313313285,"mc":[{"id":"1.231875523","rc":[{"batb":[[0,1.84,10.19],[1,1.83,2.29],[2,1.8,62.5]],"ltp":1.03,"tv":2.0,"id":31378},{"batb":[[0,1.84,10.19],[1,1.83,2.29],[2,1.8,62.5]],"ltp":0.0,"tv":0.0,"id":475559},{"batb":[[1,1.51,16.78],[2,1.35,56.24]],"ltp":0.0,"tv":0.0,"id":60443}]}]}
{"op":"mcm","clk":"11900479798","pt":1724315132931,"mc":[{"id":"1.231875523","rc":[{"batb":[[0,1.83,2.29],[1,1.8,62.5],[2,1.5,20]],"batl":[[2,95,5.85]],"ltp":1.03,"tv":2.0,"id":31378},{"batb":[[0,1.83,2.29],[1,1.8,62.5],[2,1.5,20]],"batl":[[2,90,1.02]],"ltp":0.0,"tv":0.0,"id":475559},{"batb":[[1,1.35,56.16],[2,1.3,20]],"batl":[[2,90,1.02]],"ltp":0.0,"tv":0.0,"id":60443}]}]}
{"op":"mcm","clk":"11900484866","pt":1724315241568,"mc":[{"id":"1.231875523","rc":[{"batb":[[0,1.84,10.17],[1,1.83,2.29],[2,1.8,62.5]],"ltp":1.03,"tv":2.0,"id":31378},{"batb":[[0,1.84,10.17],[1,1.83,2.29],[2,1.8,62.5]],"ltp":0.0,"tv":0.0,"id":475559},{"batb":[[1,1.51,16.76],[2,1.35,56.16]],"ltp":0.0,"tv":0.0,"id":60443}]}]}
{"op":"mcm","clk":"11900580801","pt":1724317043019,"mc":[{"id":"1.231875523","rc":[{"batb":[[0,1.83,2.29],[1,1.8,62.5],[2,1.5,20]],"ltp":1.03,"tv":2.0,"id":31378},{"batb":[[0,1.83,2.29],[1,1.8,62.5],[2,1.5,20]],"ltp":0.0,"tv":0.0,"id":475559},{"batb":[[1,1.35,56.16],[2,1.3,20]],"ltp":0.0,"tv":0.0,"id":60443}]}]}
{"op":"mcm","clk":"11900590079","pt":1724317168001,"mc":[{"id":"1.231875523","rc":[{"batb":[[0,1.84,10.17],[1,1.83,2.29],[2,1.8,62.5]],"ltp":1.03,"tv":2.0,"id":31378},{"batb":[[0,1.84,10.17],[1,1.83,2.29],[2,1.8,62.5]],"ltp":0.0,"tv":0.0,"id":475559},{"batb":[[1,1.51,16.76],[2,1.35,56.16]],"ltp":0.0,"tv":0.0,"id":60443}]}]}
{"op":"mcm","clk":"11900597325","pt":1724317259004,"mc":[{"id":"1.231875523","rc":[{"batb":[[0,1.84,10.47],[1,1.83,2.29]],"batl":[[0,8.8,1.83],[1,48,1.16]],"ltp":1.03,"tv":2.0,"id":31378},{"batb":[[0,1.84,10.47],[1,1.83,2.29]],"batl":[[0,8.8,1.83],[1,36,1.53]],"ltp":0.0,"tv":0.0,"id":475559},{"batb":[[0,1.54,1.06],[1,1.51,17.63],[2,1.35,56.11]],"batl":[[0,15.5,1.83],[1,38,1.47]],"ltp":0.0,"tv":0.0,"id":60443}]}]}
{"op":"mcm","clk":"11900621016","pt":1724317566788,"mc":[{"id":"1.231875523","rc":[{"batb":[[0,1.84,10.17]],"ltp":1.03,"tv":2.0,"id":31378},{"batb":[[0,1.84,10.17]],"ltp":0.0,"tv":0.0,"id":475559},{"batb":[[0,1.53,1.65],[1,1.51,16.74]],"ltp":0.0,"tv":0.0,"id":60443}]}]}
{"op":"mcm","clk":"11900621101","pt":1724317567972,"mc":[{"id":"1.231875523","rc":[{"batb":[[0,1.84,10.47]],"ltp":1.03,"tv":2.0,"id":31378},{"batb":[[0,1.84,10.47]],"ltp":0.0,"tv":0.0,"id":475559},{"batb":[[0,1.55,1.06],[1,1.51,17.63]],"ltp":0.0,"tv":0.0,"id":60443}]}]}
{"op":"mcm","clk":"11900638460","pt":1724317817960,"mc":[{"id":"1.231875523","rc":[{"batb":[[0,1.86,20],[1,1.84,10.47],[2,1.83,2.29]],"ltp":1.03,"tv":2.0,"id":31378}]}]}
{"op":"mcm","clk":"11900639070","pt":1724317825749,"mc":[{"id":"1.231875523","rc":[{"batb":[[0,1.86,20],[1,1.84,10.47],[2,1.83,2.29]],"ltp":0.0,"tv":0.0,"id":475559}]}]}
{"op":"mcm","clk":"11900639541","pt":1724317832872,"mc":[{"id":"1.231875523","rc":[{"batl":[[0,3.95,5],[1,15.5,1.83],[2,38,1.47]],"ltp":0.0,"tv":0.0,"id":60443}]}]}
{"op":"mcm","clk":"11900639956","pt":1724317838269,"mc":[{"id":"1.231875523","rc":[{"batl":[[1,16,1.77],[2,90,1.55]],"ltp":0.0,"tv":0.0,"id":60443}]}]}
{"op":"mcm","clk":"11900640390","pt":1724317843881,"mc":[{"id":"1.231875523","rc":[{"batl":[[0,3.9,1],[1,3.95,5],[2,16,1.77]],"ltp":0.0,"tv":0.0,"id":60443}]}]}
{"op":"mcm","clk":"11900641558","pt":1724317859623,"mc":[{"id":"1.231875523","rc":[{"batb":[[0,1.86,20.3]],"batl":[[0,8.6,1.13],[1,8.8,1],[2,48,1.16]],"ltp":1.03,"tv":2.0,"id":31378},{"batb":[[0,1.86,20.3]],"batl":[[0,8.6,1.13],[1,8.8,1],[2,36,1.53]],"ltp":0.0,"tv":0.0,"id":475559},{"batb":[[0,1.56,1.06],[1,1.53,1.19],[2,1.51,16.74]],"batl":[[0,3.9,1.3]],"ltp":0.0,"tv":0.0,"id":60443}]}]}
{"op":"mcm","clk":"11900641630","pt":1724317860503,"mc":[{"id":"1.231875523","rc":[{"batl":[[1,48,1.16],[2,95,5.85]],"ltp":1.03,"tv":2.0,"id":31378},{"batl":[[1,36,1.53],[2,90,1.02]],"ltp":0.0,"tv":0.0,"id":475559}]}]}
{"op":"mcm","clk":"11900641761","pt":1724317862081,"mc":[{"id":"1.231875523","rc":[{"batb":[[1,1.51,17.63],[2,1.35,56.11]],"ltp":0.0,"tv":0.0,"id":60443}]}]}
{"op":"mcm","clk":"11900641788","pt":1724317862385,"mc":[{"id":"1.231875523","rc":[{"batb":[[1,1.84,10.17]],"ltp":1.03,"tv":2.0,"id":31378},{"batb":[[1,1.84,10.17]],"ltp":0.0,"tv":0.0,"id":475559}]}]}
{"op":"mcm","clk":"11900641882","pt":1724317863510,"mc":[{"id":"1.231875523","rc":[{"batl":[[0,14,1.29],[1,90,1.55],[2,95,5]],"ltp":1.03,"tv":2.0,"id":31378},{"batl":[[0,14,1.29],[1,36,1.07]],"ltp":0.0,"tv":0.0,"id":475559},{"batl":[[2,16,1.47]],"ltp":0.0,"tv":0.0,"id":60443}]}]}
{"op":"mcm","clk":"11900642980","pt":1724317877217,"mc":[{"id":"1.231875523","rc":[{"batl":[[0,13.5,1.83],[1,36,1.53]],"ltp":0.0,"tv":0.0,"id":475559}]}]}
{"op":"mcm","clk":"11900643473","pt":1724317882820,"mc":[{"id":"1.231875523","rc":[{"batl":[[0,13.5,1.83],[1,48,1.16],[2,95,5.85]],"ltp":1.03,"tv":2.0,"id":31378}]}]}
{"op":"mcm","clk":"11900674688","pt":1724318137944,"mc":[{"id":"1.231875523","rc":[{"batb":[[0,1.86,20]],"ltp":1.03,"tv":2.0,"id":31378},{"batb":[[0,1.86,20]],"ltp":0.0,"tv":0.0,"id":475559}]}]}
{"op":"mcm","clk":"11900674763","pt":1724318138768,"mc":[{"id":"1.231875523","rc":[{"batl":[[0,13.5,1.53]],"ltp":1.03,"tv":2.0,"id":31378},{"batl":[[0,13.5,1.53]],"ltp":0.0,"tv":0.0,"id":475559},{"batb":[[0,1.53,1.65],[1,1.51,16.74]],"batl":[[0,3.9,1]],"ltp":0.0,"tv":0.0,"id":60443}]}]}
{"op":"mcm","clk":"11900675030","pt":1724318141753,"mc":[{"id":"1.231875523","rc":[{"batb":[[0,1.86,20.3]],"batl":[[0,13.5,1.83]],"ltp":1.03,"tv":2.0,"id":31378},{"batb":[[0,1.86,20.3]],"batl":[[0,13.5,1.83]],"ltp":0.0,"tv":0.0,"id":475559},{"batb":[[0,1.54,1.06],[1,1.51,17.63]],"batl":[[0,3.9,1.3]],"ltp":0.0,"tv":0.0,"id":60443}]}]}
{"op":"mcm","clk":"11900694128","pt":1724318382991,"mc":[{"id":"1.231875523","rc":[{"batl":[[1,16,1.47],[2,90,1.55]],"ltp":0.0,"tv":0.0,"id":60443}]}]}
{"op":"mcm","clk":"11900694215","pt":1724318384075,"mc":[{"id":"1.231875523","rc":[{"batl":[[0,3.85,5.3]],"ltp":0.0,"tv":0.0,"id":60443}]}]}
{"op":"mcm","clk":"11900694661","pt":1724318389610,"mc":[{"id":"1.231875523","rc":[{"batl":[[0,3.8,1],[1,3.85,5.3],[2,16,1.47]],"ltp":0.0,"tv":0.0,"id":60443}]}]}
{"op":"mcm","clk":"11900700011","pt":1724318451769,"mc":[{"id":"1.231875523","rc":[{"batb":[[0,1.86,20]],"ltp":1.03,"tv":2.0,"id":31378},{"batb":[[0,1.53,1.65],[1,1.51,16.74]],"ltp":0.0,"tv":0.0,"id":60443}]}]}
{"op":"mcm","clk":"11900700081","pt":1724318452688,"mc":[{"id":"1.231875523","rc":[{"batb":[[0,1.86,20]],"ltp":0.0,"tv":0.0,"id":475559}]}]}
{"op":"mcm","clk":"11900700205","pt":1724318454077,"mc":[{"id":"1.231875523","rc":[{"batl":[[0,13.5,1.53]],"ltp":1.03,"tv":2.0,"id":31378},{"batl":[[0,13.5,1.53]],"ltp":0.0,"tv":0.0,"id":475559},{"batl":[[1,3.85,5]],"ltp":0.0,"tv":0.0,"id":60443}]}]}
{"op":"mcm","clk":"11900700544","pt":1724318457983,"mc":[{"id":"1.231875523","rc":[{"batb":[[0,1.86,20.3]],"batl":[[0,13.5,1.83]],"ltp":1.03,"tv":2.0,"id":31378},{"batb":[[0,1.86,20.3]],"batl":[[0,13.5,1.83]],"ltp":0.0,"tv":0.0,"id":475559},{"batb":[[0,1.54,1.06],[1,1.51,17.63]],"batl":[[0,3.8,1.3]],"ltp":0.0,"tv":0.0,"id":60443}]}]}
{"op":"mcm","clk":"11900728174","pt":1724318769872,"mc":[{"id":"1.231875523","rc":[{"batb":[[0,1.86,20]],"ltp":1.03,"tv":2.0,"id":31378},{"batb":[[0,1.86,20]],"ltp":0.0,"tv":0.0,"id":475559},{"batb":[[0,1.53,1.65],[1,1.51,16.74]],"ltp":0.0,"tv":0.0,"id":60443}]}]}
{"op":"mcm","clk":"11900728339","pt":1724318771689,"mc":[{"id":"1.231875523","rc":[{"batl":[[0,13.5,1.53]],"ltp":1.03,"tv":2.0,"id":31378},{"batl":[[0,13.5,1.53]],"ltp":0.0,"tv":0.0,"id":475559},{"batl":[[0,3.8,1]],"ltp":0.0,"tv":0.0,"id":60443}]}]}
{"op":"mcm","clk":"11900728602","pt":1724318774993,"mc":[{"id":"1.231875523","rc":[{"batb":[[0,1.86,20.3]],"batl":[[0,13.5,1.83]],"ltp":1.03,"tv":2.0,"id":31378},{"batb":[[0,1.86,20.3]],"batl":[[0,13.5,1.83]],"ltp":0.0,"tv":0.0,"id":475559},{"batb":[[0,1.54,1.06],[1,1.51,17.63]],"batl":[[0,3.8,1.3]],"ltp":0.0,"tv":0.0,"id":60443}]}]}
{"op":"mcm","clk":"11900742377","pt":1724318968883,"mc":[{"id":"1.231875523","rc":[{"batb":[[1,1.83,2.29],[2,1.8,62.5]],"ltp":0.0,"tv":0.0,"id":475559},{"batb":[[1,1.5,1.77],[2,1.35,55.23]],"ltp":0.0,"tv":0.0,"id":60443}]}]}
{"op":"mcm","clk":"11900742394","pt":1724318969087,"mc":[{"id":"1.231875523","rc":[{"batb":[[1,1.83,2.29],[2,1.8,62.5]],"ltp":1.03,"tv":2.0,"id":31378}]}]}
{"op":"mcm","clk":"11900745583","pt":1724319011306,"mc":[{"id":"1.231875523","rc":[{"batb":[[0,1.87,10.12],[1,1.86,20],[2,1.83,2.29]],"ltp":1.03,"tv":2.0,"id":31378},{"batb":[[0,1.87,10.12],[1,1.86,20],[2,1.83,2.29]],"ltp":0.0,"tv":0.0,"id":475559},{"batb":[[0,1.54,16.88]],"ltp":0.0,"tv":0.0,"id":60443}]}]}
{"op":"mcm","clk":"11900751793","pt":1724319094076,"mc":[{"id":"1.231875523","rc":[{"batb":[[0,1.87,10.42]],"batl":[[0,13,1.13],[1,13.5,1],[2,48,1.16]],"ltp":1.03,"tv":2.0,"id":31378},{"batl":[[0,13,1.13],[1,13.5,1],[2,36,1.53]],"ltp":0.0,"tv":0.0,"id":475559},{"batb":[[0,1.55,1.06],[1,1.54,16.11],[2,1.5,1.77]],"batl":[[0,3.8,1.6]],"ltp":0.0,"tv":0.0,"id":60443}]}]}
{"op":"mcm","clk":"11900751840","pt":1724319094791,"mc":[{"id":"1.231875523","rc":[{"batb":[[0,1.87,10.12]],"ltp":1.03,"tv":2.0,"id":31378},{"batb":[[1,1.54,15.81]],"ltp":0.0,"tv":0.0,"id":60443}]}]}
{"op":"mcm","clk":"11900751907","pt":1724319095914,"mc":[{"id":"1.231875523","rc":[{"batl":[[0,13.5,1.83],[1,48,1.16],[2,95,5.85]],"ltp":1.03,"tv":2.0,"id":31378},{"batl":[[0,13.5,1.83],[1,36,1.53],[2,90,1.02]],"ltp":0.0,"tv":0.0,"id":475559}]}]}
{"op":"mcm","clk":"11900751925","pt":1724319096118,"mc":[{"id":"1.231875523","rc":[{"batl":[[0,3.8,1.3]],"ltp":0.0,"tv":0.0,"id":60443}]}]}
{"op":"mcm","clk":"11900773004","pt":1724319407066,"mc":[{"id":"1.231875523","rc":[{"batl":[[0,13,1.13],[1,13.5,1],[2,48,1.16]],"ltp":1.03,"tv":2.0,"id":31378},{"batl":[[0,13,1.13],[1,13.5,1],[2,36,1.53]],"ltp":0.0,"tv":0.0,"id":475559},{"batl":[[0,3.8,1.6]],"ltp":0.0,"tv":0.0,"id":60443}]}]}
{"op":"mcm","clk":"11900773020","pt":1724319407275,"mc":[{"id":"1.231875523","rc":[{"batb":[[0,1.87,10.42]],"ltp":1.03,"tv":2.0,"id":31378},{"batb":[[0,1.87,10.42]],"ltp":0.0,"tv":0.0,"id":475559},{"batb":[[0,1.56,1.06],[1,1.54,16.11]],"ltp":0.0,"tv":0.0,"id":60443}]}]}
{"op":"mcm","clk":"11900773134","pt":1724319408761,"mc":[{"id":"1.231875523","rc":[{"batl":[[1,48,1.16],[2,95,5.85]],"ltp":1.03,"tv":2.0,"id":31378},{"batl":[[1,36,1.53],[2,90,1.02]],"ltp":0.0,"tv":0.0,"id":475559}]}]}
{"op":"mcm","clk":"11900773580","pt":1724319414351,"mc":[{"id":"1.231875523","rc":[{"batl":[[0,12.5,1.53],[1,14,1.06],[2,90,1.55]],"ltp":1.03,"tv":2.0,"id":31378}]}]}
{"op":"mcm","clk":"11900774822","pt":1724319431075,"mc":[{"id":"1.231875523","rc":[{"batl":[[0,12.5,1.53],[1,14,1.06],[2,36,1.07]],"ltp":0.0,"tv":0.0,"id":475559}]}]}
{"op":"mcm","clk":"11900779655","pt":1724319489341,"mc":[{"id":"1.231875523","rc":[{"batb":[[0,1.87,10.12]],"ltp":0.0,"tv":0.0,"id":475559}]}]}
