{"op":"mcm","clk":"11977633918","pt":1724784739533,"mc":[{"id":"1.232352477","marketDefinition":{"bspMarket":false,"turnInPlayEnabled":true,"persistenceEnabled":true,"marketBaseRate":5.0,"eventId":"33532565","eventTypeId":"4","numberOfWinners":1,"bettingType":"ODDS","marketType":"MATCH_ODDS","marketTime":"2024-08-28T14:30:00.000Z","suspendTime":"2024-08-28T14:30:00.000Z","bspReconciled":false,"complete":true,"inPlay":false,"crossMatching":false,"runnersVoidable":false,"numberOfActiveRunners":2,"betDelay":0,"status":"OPEN","runners":[{"status":"ACTIVE","sortPriority":1,"id":61077257,"name":"Guernsey"},{"status":"ACTIVE","sortPriority":2,"id":206388,"name":"Denmark"}],"regulators":["MR_INT"],"countryCode":"GB","discountAllowed":false,"timezone":"GMT","openDate":"2024-08-28T14:30:00.000Z","version":6103806168,"name":"Match Odds","eventName":"Guernsey v Denmark"},"rc":[{"batb":[[0,1.03,200],[1,1.02,200],[2,1.01,220]],"ltp":0.0,"tv":0.0,"id":61077257},{"batb":[[0,1.03,200],[1,1.02,200],[2,1.01,220]],"ltp":0.0,"tv":0.0,"id":206388}]}]}
{"op":"mcm","clk":"11977634178","pt":1724784741170,"mc":[{"id":"1.232352477","marketDefinition":{"bspMarket":false,"turnInPlayEnabled":true,"persistenceEnabled":true,"marketBaseRate":5.0,"eventId":"33532565","eventTypeId":"4","numberOfWinners":1,"bettingType":"ODDS","marketType":"MATCH_ODDS","marketTime":"2024-08-28T14:30:00.000Z","suspendTime":"2024-08-28T14:30:00.000Z","bspReconciled":false,"complete":true,"inPlay":false,"crossMatching":false,"runnersVoidable":false,"numberOfActiveRunners":2,"betDelay":0,"status":"OPEN","runners":[{"status":"ACTIVE","sortPriority":1,"id":61077257,"name":"Guernsey"},{"status":"ACTIVE","sortPriority":2,"id":206388,"name":"Denmark"}],"regulators":["MR_INT"],"countryCode":"GB","discountAllowed":true,"timezone":"GMT","openDate":"2024-08-28T14:30:00.000Z","version":6103806168,"name":"Match Odds","eventName":"Guernsey v Denmark"}}]}
{"op":"mcm","clk":"11977914119","pt":1724786661564,"mc":[{"id":"1.232352477","rc":[{"batb":[[0,1.65,62.18],[1,1.03,200],[2,1.02,200]],"ltp":0.0,"tv":0.0,"id":61077257},{"batb":[[0,2.42,28.46],[1,1.03,200],[2,1.02,200]],"ltp":0.0,"tv":0.0,"id":206388}]}]}
{"op":"mcm","clk":"11977916773","pt":1724786680004,"mc":[{"id":"1.232352477","marketDefinition":{"bspMarket":false,"turnInPlayEnabled":true,"persistenceEnabled":true,"marketBaseRate":5.0,"eventId":"33532565","eventTypeId":"4","numberOfWinners":1,"bettingType":"ODDS","marketType":"MATCH_ODDS","marketTime":"2024-08-28T14:30:00.000Z","suspendTime":"2024-08-28T14:30:00.000Z","bspReconciled":false,"complete":true,"inPlay":false,"crossMatching":true,"runnersVoidable":false,"numberOfActiveRunners":2,"betDelay":0,"status":"OPEN","runners":[{"status":"ACTIVE","sortPriority":1,"id":61077257,"name":"Guernsey"},{"status":"ACTIVE","sortPriority":2,"id":206388,"name":"Denmark"}],"regulators":["MR_INT"],"countryCode":"GB","discountAllowed":true,"timezone":"GMT","openDate":"2024-08-28T14:30:00.000Z","version":6103806168,"name":"Match Odds","eventName":"Guernsey v Denmark"}}]}
{"op":"mcm","clk":"11977989452","pt":1724787156966,"mc":[{"id":"1.232352477","rc":[{"batl":[[0,15,0.75]],"ltp":0.0,"tv":0.0,"id":61077257},{"batl":[[0,15,0.75]],"ltp":0.0,"tv":0.0,"id":206388}]}]}
{"op":"mcm","clk":"11978217620","pt":1724788942602,"mc":[{"id":"1.232352477","rc":[{"trd":[[2.42,56]],"batb":[[0,1.04,5.46]],"ltp":2.42,"tv":56.0,"id":206388}],"tv":56.0}]}
{"op":"mcm","clk":"11978217709","pt":1724788943296,"mc":[{"id":"1.232352477","rc":[{"batb":[[0,2.34,30.16],[1,1.04,5],[2,1.03,200]],"ltp":2.42,"tv":56.0,"id":206388}]}]}
{"op":"mcm","clk":"11978218093","pt":1724788945874,"mc":[{"id":"1.232352477","rc":[{"batb":[[1,1.03,200],[2,1.02,200]],"ltp":2.42,"tv":56.0,"id":206388}]}]}
{"op":"mcm","clk":"11978272275","pt":1724789320729,"mc":[{"id":"1.232352477","rc":[{"batb":[[0,2.36,5],[1,2.34,30.16],[2,1.03,200]],"ltp":2.42,"tv":56.0,"id":206388}]}]}
{"op":"mcm","clk":"11978272729","pt":1724789324030,"mc":[{"id":"1.232352477","rc":[{"batb":[[0,2.34,30.16],[1,1.03,200],[2,1.02,200]],"ltp":2.42,"tv":56.0,"id":206388}]}]}
{"op":"mcm","clk":"11978368357","pt":1724789938053,"mc":[{"id":"1.232352477","rc":[{"batb":[[0,2.36,5],[1,2.34,30.16],[2,1.03,200]],"ltp":2.42,"tv":56.0,"id":206388}]}]}
{"op":"mcm","clk":"11978368784","pt":1724789941528,"mc":[{"id":"1.232352477","rc":[{"batb":[[0,2.34,30.16],[1,1.03,200],[2,1.02,200]],"ltp":2.42,"tv":56.0,"id":206388}]}]}
{"op":"mcm","clk":"11978369849","pt":1724789948638,"mc":[{"id":"1.232352477","rc":[{"batb":[[0,2.36,5],[1,2.34,30.16],[2,1.03,200]],"ltp":2.42,"tv":56.0,"id":206388}]}]}
{"op":"mcm","clk":"11978370355","pt":1724789952356,"mc":[{"id":"1.232352477","rc":[{"batb":[[0,2.34,30.16],[1,1.03,200],[2,1.02,200]],"ltp":2.42,"tv":56.0,"id":206388}]}]}
{"op":"mcm","clk":"11978371727","pt":1724789962466,"mc":[{"id":"1.232352477","rc":[{"batb":[[0,2.36,5],[1,2.34,30.16],[2,1.03,200]],"ltp":2.42,"tv":56.0,"id":206388}]}]}
{"op":"mcm","clk":"11978372238","pt":1724789966021,"mc":[{"id":"1.232352477","rc":[{"batb":[[0,2.34,30.16],[1,1.03,200],[2,1.02,200]],"ltp":2.42,"tv":56.0,"id":206388}]}]}
{"op":"mcm","clk":"11978373784","pt":1724789977060,"mc":[{"id":"1.232352477","rc":[{"batb":[[0,2.36,5],[1,2.34,30.16],[2,1.03,200]],"ltp":2.42,"tv":56.0,"id":206388}]}]}
{"op":"mcm","clk":"11978374310","pt":1724789980620,"mc":[{"id":"1.232352477","rc":[{"batb":[[0,2.34,30.16],[1,1.03,200],[2,1.02,200]],"ltp":2.42,"tv":56.0,"id":206388}]}]}
{"op":"mcm","clk":"11978374925","pt":1724789984827,"mc":[{"id":"1.232352477","rc":[{"batb":[[0,2.36,5],[1,2.34,30.16],[2,1.03,200]],"ltp":2.42,"tv":56.0,"id":206388}]}]}
{"op":"mcm","clk":"11978375399","pt":1724789988332,"mc":[{"id":"1.232352477","rc":[{"batb":[[0,2.34,30.16],[1,1.03,200],[2,1.02,200]],"ltp":2.42,"tv":56.0,"id":206388}]}]}
{"op":"mcm","clk":"11978375813","pt":1724789990902,"mc":[{"id":"1.232352477","rc":[{"batb":[[0,2.36,5],[1,2.34,30.16],[2,1.03,200]],"ltp":2.42,"tv":56.0,"id":206388}]}]}
{"op":"mcm","clk":"11978376306","pt":1724789994423,"mc":[{"id":"1.232352477","rc":[{"batb":[[0,2.34,30.16],[1,1.03,200],[2,1.02,200]],"ltp":2.42,"tv":56.0,"id":206388}]}]}
{"op":"mcm","clk":"11978376649","pt":1724789996816,"mc":[{"id":"1.232352477","rc":[{"batb":[[0,2.36,5],[1,2.34,30.16],[2,1.03,200]],"ltp":2.42,"tv":56.0,"id":206388}]}]}
{"op":"mcm","clk":"11978377109","pt":1724790000128,"mc":[{"id":"1.232352477","rc":[{"batb":[[0,2.34,30.16],[1,1.03,200],[2,1.02,200]],"ltp":2.42,"tv":56.0,"id":206388}]}]}
{"op":"mcm","clk":"11978378293","pt":1724790007929,"mc":[{"id":"1.232352477","rc":[{"batb":[[0,2.36,5],[1,2.34,30.16],[2,1.03,200]],"ltp":2.42,"tv":56.0,"id":206388}]}]}
{"op":"mcm","clk":"11978378833","pt":1724790011644,"mc":[{"id":"1.232352477","rc":[{"batb":[[0,2.34,30.16],[1,1.03,200],[2,1.02,200]],"ltp":2.42,"tv":56.0,"id":206388}]}]}
{"op":"mcm","clk":"11978379324","pt":1724790014951,"mc":[{"id":"1.232352477","rc":[{"batb":[[0,2.36,5],[1,2.34,30.16],[2,1.03,200]],"ltp":2.42,"tv":56.0,"id":206388}]}]}
{"op":"mcm","clk":"11978379825","pt":1724790018461,"mc":[{"id":"1.232352477","rc":[{"batb":[[0,2.34,30.16],[1,1.03,200],[2,1.02,200]],"ltp":2.42,"tv":56.0,"id":206388}]}]}
{"op":"mcm","clk":"11978380768","pt":1724790025074,"mc":[{"id":"1.232352477","rc":[{"batb":[[0,2.36,5],[1,2.34,30.16],[2,1.03,200]],"ltp":2.42,"tv":56.0,"id":206388}]}]}
{"op":"mcm","clk":"11978381249","pt":1724790028486,"mc":[{"id":"1.232352477","rc":[{"batb":[[0,2.34,30.16],[1,1.03,200],[2,1.02,200]],"ltp":2.42,"tv":56.0,"id":206388}]}]}
{"op":"mcm","clk":"11978381656","pt":1724790031472,"mc":[{"id":"1.232352477","rc":[{"batb":[[0,2.36,5],[1,2.34,30.16],[2,1.03,200]],"ltp":2.42,"tv":56.0,"id":206388}]}]}
{"op":"mcm","clk":"11978382126","pt":1724790034871,"mc":[{"id":"1.232352477","rc":[{"batb":[[0,2.34,30.16],[1,1.03,200],[2,1.02,200]],"ltp":2.42,"tv":56.0,"id":206388}]}]}
{"op":"mcm","clk":"11978382659","pt":1724790038760,"mc":[{"id":"1.232352477","rc":[{"batb":[[0,2.36,5],[1,2.34,30.16],[2,1.03,200]],"ltp":2.42,"tv":56.0,"id":206388}]}]}
{"op":"mcm","clk":"11978383171","pt":1724790042105,"mc":[{"id":"1.232352477","rc":[{"batb":[[0,2.34,30.16],[1,1.03,200],[2,1.02,200]],"ltp":2.42,"tv":56.0,"id":206388}]}]}
{"op":"mcm","clk":"11978383975","pt":1724790047707,"mc":[{"id":"1.232352477","rc":[{"batb":[[0,2.36,5],[1,2.34,30.16],[2,1.03,200]],"ltp":2.42,"tv":56.0,"id":206388}]}]}
{"op":"mcm","clk":"11978384459","pt":1724790051099,"mc":[{"id":"1.232352477","rc":[{"batb":[[0,2.34,30.16],[1,1.03,200],[2,1.02,200]],"ltp":2.42,"tv":56.0,"id":206388}]}]}
{"op":"mcm","clk":"11978385153","pt":1724790056084,"mc":[{"id":"1.232352477","rc":[{"batb":[[0,2.36,5],[1,2.34,30.16],[2,1.03,200]],"ltp":2.42,"tv":56.0,"id":206388}]}]}
{"op":"mcm","clk":"11978385628","pt":1724790059403,"mc":[{"id":"1.232352477","rc":[{"batb":[[0,2.34,30.16],[1,1.03,200],[2,1.02,200]],"ltp":2.42,"tv":56.0,"id":206388}]}]}
{"op":"mcm","clk":"11978386419","pt":1724790064780,"mc":[{"id":"1.232352477","rc":[{"batb":[[0,2.36,5],[1,2.34,30.16],[2,1.03,200]],"ltp":2.42,"tv":56.0,"id":206388}]}]}
{"op":"mcm","clk":"11978386914","pt":1724790068195,"mc":[{"id":"1.232352477","rc":[{"batb":[[0,2.34,30.16],[1,1.03,200],[2,1.02,200]],"ltp":2.42,"tv":56.0,"id":206388}]}]}
{"op":"mcm","clk":"11978387589","pt":1724790072614,"mc":[{"id":"1.232352477","rc":[{"batb":[[0,2.36,5],[1,2.34,30.16],[2,1.03,200]],"ltp":2.42,"tv":56.0,"id":206388}]}]}
{"op":"mcm","clk":"11978388121","pt":1724790076108,"mc":[{"id":"1.232352477","rc":[{"batb":[[0,2.34,30.16],[1,1.03,200],[2,1.02,200]],"ltp":2.42,"tv":56.0,"id":206388}]}]}
{"op":"mcm","clk":"11978389061","pt":1724790082513,"mc":[{"id":"1.232352477","rc":[{"batb":[[0,2.36,5],[1,2.34,30.16],[2,1.03,200]],"ltp":2.42,"tv":56.0,"id":206388}]}]}
{"op":"mcm","clk":"11978389560","pt":1724790086021,"mc":[{"id":"1.232352477","rc":[{"batb":[[0,2.34,30.16],[1,1.03,200],[2,1.02,200]],"ltp":2.42,"tv":56.0,"id":206388}]}]}
{"op":"mcm","clk":"11978389990","pt":1724790088958,"mc":[{"id":"1.232352477","rc":[{"batb":[[0,2.36,5],[1,2.34,30.16],[2,1.03,200]],"ltp":2.42,"tv":56.0,"id":206388}]}]}
{"op":"mcm","clk":"11978390584","pt":1724790092340,"mc":[{"id":"1.232352477","rc":[{"batb":[[0,2.34,30.16],[1,1.03,200],[2,1.02,200]],"ltp":2.42,"tv":56.0,"id":206388}]}]}
{"op":"mcm","clk":"11978391109","pt":1724790095117,"mc":[{"id":"1.232352477","rc":[{"batb":[[0,2.36,5],[1,2.34,30.16],[2,1.03,200]],"ltp":2.42,"tv":56.0,"id":206388}]}]}
{"op":"mcm","clk":"11978391759","pt":1724790098737,"mc":[{"id":"1.232352477","rc":[{"batb":[[0,2.34,30.16],[1,1.03,200],[2,1.02,200]],"ltp":2.42,"tv":56.0,"id":206388}]}]}
{"op":"mcm","clk":"11978392438","pt":1724790103533,"mc":[{"id":"1.232352477","rc":[{"batb":[[0,2.36,5],[1,2.34,30.16],[2,1.03,200]],"ltp":2.42,"tv":56.0,"id":206388}]}]}
{"op":"mcm","clk":"11978392979","pt":1724790107046,"mc":[{"id":"1.232352477","rc":[{"batb":[[0,2.34,30.16],[1,1.03,200],[2,1.02,200]],"ltp":2.42,"tv":56.0,"id":206388}]}]}
{"op":"mcm","clk":"11978393416","pt":1724790110167,"mc":[{"id":"1.232352477","rc":[{"batb":[[0,2.36,5],[1,2.34,30.16],[2,1.03,200]],"ltp":2.42,"tv":56.0,"id":206388}]}]}
{"op":"mcm","clk":"11978393903","pt":1724790113466,"mc":[{"id":"1.232352477","rc":[{"batb":[[0,2.34,30.16],[1,1.03,200],[2,1.02,200]],"ltp":2.42,"tv":56.0,"id":206388}]}]}
{"op":"mcm","clk":"11978394845","pt":1724790119950,"mc":[{"id":"1.232352477","rc":[{"batb":[[0,2.36,5],[1,2.34,30.16],[2,1.03,200]],"ltp":2.42,"tv":56.0,"id":206388}]}]}
{"op":"mcm","clk":"11978395375","pt":1724790123362,"mc":[{"id":"1.232352477","rc":[{"batb":[[0,2.34,30.16],[1,1.03,200],[2,1.02,200]],"ltp":2.42,"tv":56.0,"id":206388}]}]}
{"op":"mcm","clk":"11978395837","pt":1724790126486,"mc":[{"id":"1.232352477","rc":[{"batb":[[0,2.36,5],[1,2.34,30.16],[2,1.03,200]],"ltp":2.42,"tv":56.0,"id":206388}]}]}
{"op":"mcm","clk":"11978396324","pt":1724790129992,"mc":[{"id":"1.232352477","rc":[{"batb":[[0,2.34,30.16],[1,1.03,200],[2,1.02,200]],"ltp":2.42,"tv":56.0,"id":206388}]}]}
{"op":"mcm","clk":"11978396861","pt":1724790133800,"mc":[{"id":"1.232352477","rc":[{"batb":[[0,2.36,5],[1,2.34,30.16],[2,1.03,200]],"ltp":2.42,"tv":56.0,"id":206388}]}]}
{"op":"mcm","clk":"11978397403","pt":1724790137308,"mc":[{"id":"1.232352477","rc":[{"batb":[[0,2.34,30.16],[1,1.03,200],[2,1.02,200]],"ltp":2.42,"tv":56.0,"id":206388}]}]}
{"op":"mcm","clk":"11978397922","pt":1724790141096,"mc":[{"id":"1.232352477","rc":[{"batb":[[0,2.36,5],[1,2.34,30.16],[2,1.03,200]],"ltp":2.42,"tv":56.0,"id":206388}]}]}
{"op":"mcm","clk":"11978398368","pt":1724790144493,"mc":[{"id":"1.232352477","rc":[{"batb":[[0,2.34,30.16],[1,1.03,200],[2,1.02,200]],"ltp":2.42,"tv":56.0,"id":206388}]}]}
{"op":"mcm","clk":"11978399126","pt":1724790150082,"mc":[{"id":"1.232352477","rc":[{"batb":[[0,2.36,5],[1,2.34,30.16],[2,1.03,200]],"ltp":2.42,"tv":56.0,"id":206388}]}]}
{"op":"mcm","clk":"11978399643","pt":1724790153425,"mc":[{"id":"1.232352477","rc":[{"batb":[[0,2.34,30.16],[1,1.03,200],[2,1.02,200]],"ltp":2.42,"tv":56.0,"id":206388}]}]}
{"op":"mcm","clk":"11978400300","pt":1724790158326,"mc":[{"id":"1.232352477","rc":[{"batb":[[0,2.36,5],[1,2.34,30.16],[2,1.03,200]],"ltp":2.42,"tv":56.0,"id":206388}]}]}
{"op":"mcm","clk":"11978400779","pt":1724790161817,"mc":[{"id":"1.232352477","rc":[{"batb":[[0,2.34,30.16],[1,1.03,200],[2,1.02,200]],"ltp":2.42,"tv":56.0,"id":206388}]}]}
{"op":"mcm","clk":"11978401201","pt":1724790164555,"mc":[{"id":"1.232352477","rc":[{"batb":[[0,2.36,5],[1,2.34,30.16],[2,1.03,200]],"ltp":2.42,"tv":56.0,"id":206388}]}]}
{"op":"mcm","clk":"11978401744","pt":1724790168316,"mc":[{"id":"1.232352477","rc":[{"batb":[[0,2.34,30.16],[1,1.03,200],[2,1.02,200]],"ltp":2.42,"tv":56.0,"id":206388}]}]}
{"op":"mcm","clk":"11978402185","pt":1724790171337,"mc":[{"id":"1.232352477","rc":[{"batb":[[0,2.36,5],[1,2.34,30.16],[2,1.03,200]],"ltp":2.42,"tv":56.0,"id":206388}]}]}
{"op":"mcm","clk":"11978402628","pt":1724790174623,"mc":[{"id":"1.232352477","rc":[{"batb":[[0,2.34,30.16],[1,1.03,200],[2,1.02,200]],"ltp":2.42,"tv":56.0,"id":206388}]}]}
{"op":"mcm","clk":"11978403102","pt":1724790178051,"mc":[{"id":"1.232352477","rc":[{"batb":[[0,2.36,5],[1,2.34,30.16],[2,1.03,200]],"ltp":2.42,"tv":56.0,"id":206388}]}]}
{"op":"mcm","clk":"11978403528","pt":1724790181250,"mc":[{"id":"1.232352477","rc":[{"batb":[[0,2.34,30.16],[1,1.03,200],[2,1.02,200]],"ltp":2.42,"tv":56.0,"id":206388}]}]}
{"op":"mcm","clk":"11978404034","pt":1724790184945,"mc":[{"id":"1.232352477","rc":[{"batb":[[0,2.36,5],[1,2.34,30.16],[2,1.03,200]],"ltp":2.42,"tv":56.0,"id":206388}]}]}
{"op":"mcm","clk":"11978404486","pt":1724790188444,"mc":[{"id":"1.232352477","rc":[{"batb":[[0,2.34,30.16],[1,1.03,200],[2,1.02,200]],"ltp":2.42,"tv":56.0,"id":206388}]}]}
{"op":"mcm","clk":"11978404821","pt":1724790190947,"mc":[{"id":"1.232352477","rc":[{"batb":[[0,2.36,5],[1,2.34,30.16],[2,1.03,200]],"ltp":2.42,"tv":56.0,"id":206388}]}]}
{"op":"mcm","clk":"11978405275","pt":1724790194556,"mc":[{"id":"1.232352477","rc":[{"batb":[[0,2.34,30.16],[1,1.03,200],[2,1.02,200]],"ltp":2.42,"tv":56.0,"id":206388}]}]}
{"op":"mcm","clk":"11978405654","pt":1724790197734,"mc":[{"id":"1.232352477","rc":[{"batb":[[0,2.36,5],[1,2.34,30.16],[2,1.03,200]],"ltp":2.42,"tv":56.0,"id":206388}]}]}
{"op":"mcm","clk":"11978406048","pt":1724790201167,"mc":[{"id":"1.232352477","rc":[{"batb":[[0,2.34,30.16],[1,1.03,200],[2,1.02,200]],"ltp":2.42,"tv":56.0,"id":206388}]}]}
{"op":"mcm","clk":"11978406424","pt":1724790203978,"mc":[{"id":"1.232352477","rc":[{"batb":[[0,2.36,5],[1,2.34,30.16],[2,1.03,200]],"ltp":2.42,"tv":56.0,"id":206388}]}]}
{"op":"mcm","clk":"11978406864","pt":1724790207367,"mc":[{"id":"1.232352477","rc":[{"batb":[[0,2.34,30.16],[1,1.03,200],[2,1.02,200]],"ltp":2.42,"tv":56.0,"id":206388}]}]}
{"op":"mcm","clk":"11978407190","pt":1724790210187,"mc":[{"id":"1.232352477","rc":[{"batb":[[0,2.36,5],[1,2.34,30.16],[2,1.03,200]],"ltp":2.42,"tv":56.0,"id":206388}]}]}
{"op":"mcm","clk":"11978407719","pt":1724790213681,"mc":[{"id":"1.232352477","rc":[{"batb":[[0,2.34,30.16],[1,1.03,200],[2,1.02,200]],"ltp":2.42,"tv":56.0,"id":206388}]}]}
{"op":"mcm","clk":"11978408499","pt":1724790219771,"mc":[{"id":"1.232352477","rc":[{"batb":[[0,2.36,5],[1,2.34,30.16],[2,1.03,200]],"ltp":2.42,"tv":56.0,"id":206388}]}]}
{"op":"mcm","clk":"11978408946","pt":1724790223369,"mc":[{"id":"1.232352477","rc":[{"batb":[[0,2.34,30.16],[1,1.03,200],[2,1.02,200]],"ltp":2.42,"tv":56.0,"id":206388}]}]}
{"op":"mcm","clk":"11978409756","pt":1724790229602,"mc":[{"id":"1.232352477","rc":[{"batb":[[0,2.36,5],[1,2.34,30.16],[2,1.03,200]],"ltp":2.42,"tv":56.0,"id":206388}]}]}
{"op":"mcm","clk":"11978410198","pt":1724790232987,"mc":[{"id":"1.232352477","rc":[{"batb":[[0,2.34,30.16],[1,1.03,200],[2,1.02,200]],"ltp":2.42,"tv":56.0,"id":206388}]}]}
{"op":"mcm","clk":"11978410634","pt":1724790236480,"mc":[{"id":"1.232352477","rc":[{"batb":[[0,2.36,5],[1,2.34,30.16],[2,1.03,200]],"ltp":2.42,"tv":56.0,"id":206388}]}]}
{"op":"mcm","clk":"11978411012","pt":1724790239809,"mc":[{"id":"1.232352477","rc":[{"batb":[[0,2.34,30.16],[1,1.03,200],[2,1.02,200]],"ltp":2.42,"tv":56.0,"id":206388}]}]}
{"op":"mcm","clk":"11978411372","pt":1724790242547,"mc":[{"id":"1.232352477","rc":[{"batb":[[0,2.36,5],[1,2.34,30.16],[2,1.03,200]],"ltp":2.42,"tv":56.0,"id":206388}]}]}
{"op":"mcm","clk":"11978411875","pt":1724790245916,"mc":[{"id":"1.232352477","rc":[{"batb":[[0,2.34,30.16],[1,1.03,200],[2,1.02,200]],"ltp":2.42,"tv":56.0,"id":206388}]}]}
{"op":"mcm","clk":"11978412645","pt":1724790251716,"mc":[{"id":"1.232352477","rc":[{"batb":[[0,2.36,5],[1,2.34,30.16],[2,1.03,200]],"ltp":2.42,"tv":56.0,"id":206388}]}]}
{"op":"mcm","clk":"11978413076","pt":1724790255001,"mc":[{"id":"1.232352477","rc":[{"batb":[[0,2.34,30.16],[1,1.03,200],[2,1.02,200]],"ltp":2.42,"tv":56.0,"id":206388}]}]}
{"op":"mcm","clk":"11978413490","pt":1724790258326,"mc":[{"id":"1.232352477","rc":[{"batb":[[0,2.36,5],[1,2.34,30.16],[2,1.03,200]],"ltp":2.42,"tv":56.0,"id":206388}]}]}
{"op":"mcm","clk":"11978413895","pt":1724790261816,"mc":[{"id":"1.232352477","rc":[{"batb":[[0,2.34,30.16],[1,1.03,200],[2,1.02,200]],"ltp":2.42,"tv":56.0,"id":206388}]}]}
{"op":"mcm","clk":"11978414351","pt":1724790265425,"mc":[{"id":"1.232352477","rc":[{"batb":[[0,2.36,5],[1,2.34,30.16],[2,1.03,200]],"ltp":2.42,"tv":56.0,"id":206388}]}]}
{"op":"mcm","clk":"11978414743","pt":1724790268656,"mc":[{"id":"1.232352477","rc":[{"batb":[[0,2.34,30.16],[1,1.03,200],[2,1.02,200]],"ltp":2.42,"tv":56.0,"id":206388}]}]}
{"op":"mcm","clk":"11978415119","pt":1724790271937,"mc":[{"id":"1.232352477","rc":[{"batb":[[0,2.36,5],[1,2.34,30.16],[2,1.03,200]],"ltp":2.42,"tv":56.0,"id":206388}]}]}
{"op":"mcm","clk":"11978415593","pt":1724790275423,"mc":[{"id":"1.232352477","rc":[{"batb":[[0,2.34,30.16],[1,1.03,200],[2,1.02,200]],"ltp":2.42,"tv":56.0,"id":206388}]}]}
{"op":"mcm","clk":"11978415943","pt":1724790278135,"mc":[{"id":"1.232352477","rc":[{"batb":[[0,2.36,5],[1,2.34,30.16],[2,1.03,200]],"ltp":2.42,"tv":56.0,"id":206388}]}]}
{"op":"mcm","clk":"11978416387","pt":1724790281578,"mc":[{"id":"1.232352477","rc":[{"batb":[[0,2.34,30.16],[1,1.03,200],[2,1.02,200]],"ltp":2.42,"tv":56.0,"id":206388}]}]}
{"op":"mcm","clk":"11978416709","pt":1724790284135,"mc":[{"id":"1.232352477","rc":[{"batb":[[0,2.36,5],[1,2.34,30.16],[2,1.03,200]],"ltp":2.42,"tv":56.0,"id":206388}]}]}
{"op":"mcm","clk":"11978417137","pt":1724790287579,"mc":[{"id":"1.232352477","rc":[{"batb":[[0,2.34,30.16],[1,1.03,200],[2,1.02,200]],"ltp":2.42,"tv":56.0,"id":206388}]}]}
{"op":"mcm","clk":"11978417822","pt":1724790292660,"mc":[{"id":"1.232352477","rc":[{"batb":[[0,2.36,5],[1,2.34,30.16],[2,1.03,200]],"ltp":2.42,"tv":56.0,"id":206388}]}]}
{"op":"mcm","clk":"11978418295","pt":1724790296001,"mc":[{"id":"1.232352477","rc":[{"batb":[[0,2.34,30.16],[1,1.03,200],[2,1.02,200]],"ltp":2.42,"tv":56.0,"id":206388}]}]}
{"op":"mcm","clk":"11978419064","pt":1724790302465,"mc":[{"id":"1.232352477","rc":[{"batb":[[0,2.36,5],[1,2.34,30.16],[2,1.03,200]],"ltp":2.42,"tv":56.0,"id":206388}]}]}
{"op":"mcm","clk":"11978419542","pt":1724790306013,"mc":[{"id":"1.232352477","rc":[{"batb":[[0,2.34,30.16],[1,1.03,200],[2,1.02,200]],"ltp":2.42,"tv":56.0,"id":206388}]}]}
{"op":"mcm","clk":"11978420027","pt":1724790309406,"mc":[{"id":"1.232352477","rc":[{"batb":[[0,2.36,5],[1,2.34,30.16],[2,1.03,200]],"ltp":2.42,"tv":56.0,"id":206388}]}]}
{"op":"mcm","clk":"11978420453","pt":1724790312678,"mc":[{"id":"1.232352477","rc":[{"batb":[[0,2.34,30.16],[1,1.03,200],[2,1.02,200]],"ltp":2.42,"tv":56.0,"id":206388}]}]}
{"op":"mcm","clk":"11978420729","pt":1724790315009,"mc":[{"id":"1.232352477","rc":[{"batb":[[0,2.36,5],[1,2.34,30.16],[2,1.03,200]],"ltp":2.42,"tv":56.0,"id":206388}]}]}
{"op":"mcm","clk":"11978421159","pt":1724790318443,"mc":[{"id":"1.232352477","rc":[{"batb":[[0,2.34,30.16],[1,1.03,200],[2,1.02,200]],"ltp":2.42,"tv":56.0,"id":206388}]}]}
{"op":"mcm","clk":"11978421498","pt":1724790321103,"mc":[{"id":"1.232352477","rc":[{"batb":[[0,2.36,5],[1,2.34,30.16],[2,1.03,200]],"ltp":2.42,"tv":56.0,"id":206388}]}]}
{"op":"mcm","clk":"11978421896","pt":1724790324430,"mc":[{"id":"1.232352477","rc":[{"batb":[[0,2.34,30.16],[1,1.03,200],[2,1.02,200]],"ltp":2.42,"tv":56.0,"id":206388}]}]}
{"op":"mcm","clk":"11978422302","pt":1724790327250,"mc":[{"id":"1.232352477","rc":[{"batb":[[0,2.36,5],[1,2.34,30.16],[2,1.03,200]],"ltp":2.42,"tv":56.0,"id":206388}]}]}
{"op":"mcm","clk":"11978422737","pt":1724790330619,"mc":[{"id":"1.232352477","rc":[{"batb":[[0,2.34,30.16],[1,1.03,200],[2,1.02,200]],"ltp":2.42,"tv":56.0,"id":206388}]}]}
{"op":"mcm","clk":"11978423246","pt":1724790334640,"mc":[{"id":"1.232352477","rc":[{"batb":[[0,2.36,5],[1,2.34,30.16],[2,1.03,200]],"ltp":2.42,"tv":56.0,"id":206388}]}]}
{"op":"mcm","clk":"11978423665","pt":1724790337821,"mc":[{"id":"1.232352477","rc":[{"batb":[[0,2.34,30.16],[1,1.03,200],[2,1.02,200]],"ltp":2.42,"tv":56.0,"id":206388}]}]}
{"op":"mcm","clk":"11978424057","pt":1724790341224,"mc":[{"id":"1.232352477","rc":[{"batb":[[0,2.36,5],[1,2.34,30.16],[2,1.03,200]],"ltp":2.42,"tv":56.0,"id":206388}]}]}
{"op":"mcm","clk":"11978424482","pt":1724790344614,"mc":[{"id":"1.232352477","rc":[{"batb":[[0,2.34,30.16],[1,1.03,200],[2,1.02,200]],"ltp":2.42,"tv":56.0,"id":206388}]}]}
{"op":"mcm","clk":"11978424868","pt":1724790347623,"mc":[{"id":"1.232352477","rc":[{"batb":[[0,2.36,5],[1,2.34,30.16],[2,1.03,200]],"ltp":2.42,"tv":56.0,"id":206388}]}]}
{"op":"mcm","clk":"11978425270","pt":1724790351049,"mc":[{"id":"1.232352477","rc":[{"batb":[[0,2.34,30.16],[1,1.03,200],[2,1.02,200]],"ltp":2.42,"tv":56.0,"id":206388}]}]}
{"op":"mcm","clk":"11978425703","pt":1724790354954,"mc":[{"id":"1.232352477","rc":[{"batb":[[0,2.36,5],[1,2.34,30.16],[2,1.03,200]],"ltp":2.42,"tv":56.0,"id":206388}]}]}
{"op":"mcm","clk":"11978426083","pt":1724790358269,"mc":[{"id":"1.232352477","rc":[{"batb":[[0,2.34,30.16],[1,1.03,200],[2,1.02,200]],"ltp":2.42,"tv":56.0,"id":206388}]}]}
{"op":"mcm","clk":"11978426578","pt":1724790362232,"mc":[{"id":"1.232352477","rc":[{"batb":[[0,2.36,5],[1,2.34,30.16],[2,1.03,200]],"ltp":2.42,"tv":56.0,"id":206388}]}]}
{"op":"mcm","clk":"11978426989","pt":1724790365668,"mc":[{"id":"1.232352477","rc":[{"batb":[[0,2.34,30.16],[1,1.03,200],[2,1.02,200]],"ltp":2.42,"tv":56.0,"id":206388}]}]}
{"op":"mcm","clk":"11978427307","pt":1724790368256,"mc":[{"id":"1.232352477","rc":[{"batb":[[0,2.36,5],[1,2.34,30.16],[2,1.03,200]],"ltp":2.42,"tv":56.0,"id":206388}]}]}
{"op":"mcm","clk":"11978427731","pt":1724790371753,"mc":[{"id":"1.232352477","rc":[{"batb":[[0,2.34,30.16],[1,1.03,200],[2,1.02,200]],"ltp":2.42,"tv":56.0,"id":206388}]}]}
{"op":"mcm","clk":"11978428108","pt":1724790374768,"mc":[{"id":"1.232352477","rc":[{"batb":[[0,2.36,5],[1,2.34,30.16],[2,1.03,200]],"ltp":2.42,"tv":56.0,"id":206388}]}]}
{"op":"mcm","clk":"11978428481","pt":1724790378152,"mc":[{"id":"1.232352477","rc":[{"batb":[[0,2.34,30.16],[1,1.03,200],[2,1.02,200]],"ltp":2.42,"tv":56.0,"id":206388}]}]}
{"op":"mcm","clk":"11978428780","pt":1724790380591,"mc":[{"id":"1.232352477","rc":[{"batb":[[0,2.36,5],[1,2.34,30.16],[2,1.03,200]],"ltp":2.42,"tv":56.0,"id":206388}]}]}
{"op":"mcm","clk":"11978429203","pt":1724790383878,"mc":[{"id":"1.232352477","rc":[{"batb":[[0,2.34,30.16],[1,1.03,200],[2,1.02,200]],"ltp":2.42,"tv":56.0,"id":206388}]}]}
{"op":"mcm","clk":"11978429663","pt":1724790387597,"mc":[{"id":"1.232352477","rc":[{"batb":[[0,2.36,5],[1,2.34,30.16],[2,1.03,200]],"ltp":2.42,"tv":56.0,"id":206388}]}]}
{"op":"mcm","clk":"11978430064","pt":1724790390897,"mc":[{"id":"1.232352477","rc":[{"batb":[[0,2.34,30.16],[1,1.03,200],[2,1.02,200]],"ltp":2.42,"tv":56.0,"id":206388}]}]}
{"op":"mcm","clk":"11978430479","pt":1724790393564,"mc":[{"id":"1.232352477","rc":[{"batb":[[0,2.36,5],[1,2.34,30.16],[2,1.03,200]],"ltp":2.42,"tv":56.0,"id":206388}]}]}
{"op":"mcm","clk":"11978431010","pt":1724790397063,"mc":[{"id":"1.232352477","rc":[{"batb":[[0,2.34,30.16],[1,1.03,200],[2,1.02,200]],"ltp":2.42,"tv":56.0,"id":206388}]}]}
{"op":"mcm","clk":"11978431366","pt":1724790399982,"mc":[{"id":"1.232352477","rc":[{"batb":[[0,2.36,5],[1,2.34,30.16],[2,1.03,200]],"ltp":2.42,"tv":56.0,"id":206388}]}]}
{"op":"mcm","clk":"11978431797","pt":1724790403311,"mc":[{"id":"1.232352477","rc":[{"batb":[[0,2.34,30.16],[1,1.03,200],[2,1.02,200]],"ltp":2.42,"tv":56.0,"id":206388}]}]}
{"op":"mcm","clk":"11978432117","pt":1724790405807,"mc":[{"id":"1.232352477","rc":[{"batb":[[0,2.36,5],[1,2.34,30.16],[2,1.03,200]],"ltp":2.42,"tv":56.0,"id":206388}]}]}
{"op":"mcm","clk":"11978432553","pt":1724790409133,"mc":[{"id":"1.232352477","rc":[{"batb":[[0,2.34,30.16],[1,1.03,200],[2,1.02,200]],"ltp":2.42,"tv":56.0,"id":206388}]}]}
{"op":"mcm","clk":"11978432922","pt":1724790412011,"mc":[{"id":"1.232352477","rc":[{"batb":[[0,2.36,5],[1,2.34,30.16],[2,1.03,200]],"ltp":2.42,"tv":56.0,"id":206388}]}]}
{"op":"mcm","clk":"11978433419","pt":1724790415610,"mc":[{"id":"1.232352477","rc":[{"batb":[[0,2.34,30.16],[1,1.03,200],[2,1.02,200]],"ltp":2.42,"tv":56.0,"id":206388}]}]}
{"op":"mcm","clk":"11978433741","pt":1724790418119,"mc":[{"id":"1.232352477","rc":[{"batb":[[0,2.36,5],[1,2.34,30.16],[2,1.03,200]],"ltp":2.42,"tv":56.0,"id":206388}]}]}
{"op":"mcm","clk":"11978434147","pt":1724790421513,"mc":[{"id":"1.232352477","rc":[{"batb":[[0,2.34,30.16],[1,1.03,200],[2,1.02,200]],"ltp":2.42,"tv":56.0,"id":206388}]}]}
{"op":"mcm","clk":"11978434590","pt":1724790425251,"mc":[{"id":"1.232352477","rc":[{"batb":[[0,2.36,5],[1,2.34,30.16],[2,1.03,200]],"ltp":2.42,"tv":56.0,"id":206388}]}]}
{"op":"mcm","clk":"11978434997","pt":1724790428627,"mc":[{"id":"1.232352477","rc":[{"batb":[[0,2.34,30.16],[1,1.03,200],[2,1.02,200]],"ltp":2.42,"tv":56.0,"id":206388}]}]}
{"op":"mcm","clk":"11978435485","pt":1724790432757,"mc":[{"id":"1.232352477","rc":[{"batb":[[0,2.36,5],[1,2.34,30.16],[2,1.03,200]],"ltp":2.42,"tv":56.0,"id":206388}]}]}
{"op":"mcm","clk":"11978435915","pt":1724790435950,"mc":[{"id":"1.232352477","rc":[{"batb":[[0,2.34,30.16],[1,1.03,200],[2,1.02,200]],"ltp":2.42,"tv":56.0,"id":206388}]}]}
{"op":"mcm","clk":"11978437055","pt":1724790445137,"mc":[{"id":"1.232352477","rc":[{"batb":[[0,2.36,5],[1,2.34,30.16],[2,1.03,200]],"ltp":2.42,"tv":56.0,"id":206388}]}]}
{"op":"mcm","clk":"11978437483","pt":1724790448570,"mc":[{"id":"1.232352477","rc":[{"batb":[[0,2.34,30.16],[1,1.03,200],[2,1.02,200]],"ltp":2.42,"tv":56.0,"id":206388}]}]}
{"op":"mcm","clk":"11978438858","pt":1724790459991,"mc":[{"id":"1.232352477","rc":[{"batb":[[0,2.36,5],[1,2.34,30.16],[2,1.03,200]],"ltp":2.42,"tv":56.0,"id":206388}]}]}
{"op":"mcm","clk":"11978439260","pt":1724790463381,"mc":[{"id":"1.232352477","rc":[{"batb":[[0,2.34,30.16],[1,1.03,200],[2,1.02,200]],"ltp":2.42,"tv":56.0,"id":206388}]}]}
{"op":"mcm","clk":"11978439576","pt":1724790466095,"mc":[{"id":"1.232352477","rc":[{"batb":[[0,2.36,5],[1,2.34,30.16],[2,1.03,200]],"ltp":2.42,"tv":56.0,"id":206388}]}]}
{"op":"mcm","clk":"11978439959","pt":1724790469476,"mc":[{"id":"1.232352477","rc":[{"batb":[[0,2.34,30.16],[1,1.03,200],[2,1.02,200]],"ltp":2.42,"tv":56.0,"id":206388}]}]}
{"op":"mcm","clk":"11978440318","pt":1724790472599,"mc":[{"id":"1.232352477","rc":[{"batb":[[0,2.36,5],[1,2.34,30.16],[2,1.03,200]],"ltp":2.42,"tv":56.0,"id":206388}]}]}
{"op":"mcm","clk":"11978440705","pt":1724790475899,"mc":[{"id":"1.232352477","rc":[{"batb":[[0,2.34,30.16],[1,1.03,200],[2,1.02,200]],"ltp":2.42,"tv":56.0,"id":206388}]}]}
{"op":"mcm","clk":"11978440966","pt":1724790478392,"mc":[{"id":"1.232352477","rc":[{"batb":[[0,2.36,5],[1,2.34,30.16],[2,1.03,200]],"ltp":2.42,"tv":56.0,"id":206388}]}]}
{"op":"mcm","clk":"11978441360","pt":1724790481889,"mc":[{"id":"1.232352477","rc":[{"batb":[[0,2.34,30.16],[1,1.03,200],[2,1.02,200]],"ltp":2.42,"tv":56.0,"id":206388}]}]}
{"op":"mcm","clk":"11978441714","pt":1724790484805,"mc":[{"id":"1.232352477","rc":[{"batb":[[0,2.36,5],[1,2.34,30.16],[2,1.03,200]],"ltp":2.42,"tv":56.0,"id":206388}]}]}
{"op":"mcm","clk":"11978442131","pt":1724790488198,"mc":[{"id":"1.232352477","rc":[{"batb":[[0,2.34,30.16],[1,1.03,200],[2,1.02,200]],"ltp":2.42,"tv":56.0,"id":206388}]}]}
{"op":"mcm","clk":"11978442480","pt":1724790490800,"mc":[{"id":"1.232352477","rc":[{"batb":[[0,2.36,5],[1,2.34,30.16],[2,1.03,200]],"ltp":2.42,"tv":56.0,"id":206388}]}]}
{"op":"mcm","clk":"11978442890","pt":1724790494234,"mc":[{"id":"1.232352477","rc":[{"batb":[[0,2.34,30.16],[1,1.03,200],[2,1.02,200]],"ltp":2.42,"tv":56.0,"id":206388}]}]}
{"op":"mcm","clk":"11978443207","pt":1724790496784,"mc":[{"id":"1.232352477","rc":[{"batb":[[0,2.36,5],[1,2.34,30.16],[2,1.03,200]],"ltp":2.42,"tv":56.0,"id":206388}]}]}
{"op":"mcm","clk":"11978443623","pt":1724790500101,"mc":[{"id":"1.232352477","rc":[{"batb":[[0,2.34,30.16],[1,1.03,200],[2,1.02,200]],"ltp":2.42,"tv":56.0,"id":206388}]}]}
{"op":"mcm","clk":"11978444038","pt":1724790503744,"mc":[{"id":"1.232352477","rc":[{"batb":[[0,2.36,5],[1,2.34,30.16],[2,1.03,200]],"ltp":2.42,"tv":56.0,"id":206388}]}]}
{"op":"mcm","clk":"11978444507","pt":1724790507133,"mc":[{"id":"1.232352477","rc":[{"batb":[[0,2.34,30.16],[1,1.03,200],[2,1.02,200]],"ltp":2.42,"tv":56.0,"id":206388}]}]}
{"op":"mcm","clk":"11978444840","pt":1724790509734,"mc":[{"id":"1.232352477","rc":[{"batb":[[0,2.36,5],[1,2.34,30.16],[2,1.03,200]],"ltp":2.42,"tv":56.0,"id":206388}]}]}
{"op":"mcm","clk":"11978445274","pt":1724790513175,"mc":[{"id":"1.232352477","rc":[{"batb":[[0,2.34,30.16],[1,1.03,200],[2,1.02,200]],"ltp":2.42,"tv":56.0,"id":206388}]}]}
{"op":"mcm","clk":"11978445588","pt":1724790515517,"mc":[{"id":"1.232352477","rc":[{"batb":[[0,2.36,5],[1,2.34,30.16],[2,1.03,200]],"ltp":2.42,"tv":56.0,"id":206388}]}]}
{"op":"mcm","clk":"11978445997","pt":1724790518956,"mc":[{"id":"1.232352477","rc":[{"batb":[[0,2.34,30.16],[1,1.03,200],[2,1.02,200]],"ltp":2.42,"tv":56.0,"id":206388}]}]}
{"op":"mcm","clk":"11978446561","pt":1724790523237,"mc":[{"id":"1.232352477","rc":[{"batb":[[0,2.36,5],[1,2.34,30.16],[2,1.03,200]],"ltp":2.42,"tv":56.0,"id":206388}]}]}
{"op":"mcm","clk":"11978447031","pt":1724790526539,"mc":[{"id":"1.232352477","rc":[{"batb":[[0,2.34,30.16],[1,1.03,200],[2,1.02,200]],"ltp":2.42,"tv":56.0,"id":206388}]}]}
{"op":"mcm","clk":"11978447505","pt":1724790530344,"mc":[{"id":"1.232352477","rc":[{"batb":[[0,2.36,5],[1,2.34,30.16],[2,1.03,200]],"ltp":2.42,"tv":56.0,"id":206388}]}]}
{"op":"mcm","clk":"11978447910","pt":1724790533725,"mc":[{"id":"1.232352477","rc":[{"batb":[[0,2.34,30.16],[1,1.03,200],[2,1.02,200]],"ltp":2.42,"tv":56.0,"id":206388}]}]}
{"op":"mcm","clk":"11978448206","pt":1724790536444,"mc":[{"id":"1.232352477","rc":[{"batb":[[0,2.36,5],[1,2.34,30.16],[2,1.03,200]],"ltp":2.42,"tv":56.0,"id":206388}]}]}
{"op":"mcm","clk":"11978448532","pt":1724790539669,"mc":[{"id":"1.232352477","rc":[{"batb":[[0,2.34,30.16],[1,1.03,200],[2,1.02,200]],"ltp":2.42,"tv":56.0,"id":206388}]}]}
{"op":"mcm","clk":"11978448864","pt":1724790542578,"mc":[{"id":"1.232352477","rc":[{"batb":[[0,2.36,5],[1,2.34,30.16],[2,1.03,200]],"ltp":2.42,"tv":56.0,"id":206388}]}]}
{"op":"mcm","clk":"11978449240","pt":1724790545852,"mc":[{"id":"1.232352477","rc":[{"batb":[[0,2.34,30.16],[1,1.03,200],[2,1.02,200]],"ltp":2.42,"tv":56.0,"id":206388}]}]}
{"op":"mcm","clk":"11978449547","pt":1724790548516,"mc":[{"id":"1.232352477","rc":[{"batb":[[0,2.36,5],[1,2.34,30.16],[2,1.03,200]],"ltp":2.42,"tv":56.0,"id":206388}]}]}
{"op":"mcm","clk":"11978450099","pt":1724790551976,"mc":[{"id":"1.232352477","rc":[{"batb":[[0,2.34,30.16],[1,1.03,200],[2,1.02,200]],"ltp":2.42,"tv":56.0,"id":206388}]}]}
{"op":"mcm","clk":"11978450542","pt":1724790555304,"mc":[{"id":"1.232352477","rc":[{"batb":[[0,2.36,5],[1,2.34,30.16],[2,1.03,200]],"ltp":2.42,"tv":56.0,"id":206388}]}]}
{"op":"mcm","clk":"11978450962","pt":1724790558575,"mc":[{"id":"1.232352477","rc":[{"batb":[[0,2.34,30.16],[1,1.03,200],[2,1.02,200]],"ltp":2.42,"tv":56.0,"id":206388}]}]}
{"op":"mcm","clk":"11978451454","pt":1724790562681,"mc":[{"id":"1.232352477","rc":[{"batb":[[0,2.36,5],[1,2.34,30.16],[2,1.03,200]],"ltp":2.42,"tv":56.0,"id":206388}]}]}
{"op":"mcm","clk":"11978451862","pt":1724790566114,"mc":[{"id":"1.232352477","rc":[{"batb":[[0,2.34,30.16],[1,1.03,200],[2,1.02,200]],"ltp":2.42,"tv":56.0,"id":206388}]}]}
{"op":"mcm","clk":"11978452220","pt":1724790569280,"mc":[{"id":"1.232352477","rc":[{"batb":[[0,2.36,5],[1,2.34,30.16],[2,1.03,200]],"ltp":2.42,"tv":56.0,"id":206388}]}]}
{"op":"mcm","clk":"11978452623","pt":1724790572682,"mc":[{"id":"1.232352477","rc":[{"batb":[[0,2.34,30.16],[1,1.03,200],[2,1.02,200]],"ltp":2.42,"tv":56.0,"id":206388}]}]}
{"op":"mcm","clk":"11978452993","pt":1724790575811,"mc":[{"id":"1.232352477","rc":[{"batb":[[0,2.36,5],[1,2.34,30.16],[2,1.03,200]],"ltp":2.42,"tv":56.0,"id":206388}]}]}
{"op":"mcm","clk":"11978453340","pt":1724790579230,"mc":[{"id":"1.232352477","rc":[{"batb":[[0,2.34,30.16],[1,1.03,200],[2,1.02,200]],"ltp":2.42,"tv":56.0,"id":206388}]}]}
{"op":"mcm","clk":"11978453722","pt":1724790582713,"mc":[{"id":"1.232352477","rc":[{"batb":[[0,2.36,5],[1,2.34,30.16],[2,1.03,200]],"ltp":2.42,"tv":56.0,"id":206388}]}]}
{"op":"mcm","clk":"11978454091","pt":1724790585940,"mc":[{"id":"1.232352477","rc":[{"batb":[[0,2.34,30.16],[1,1.03,200],[2,1.02,200]],"ltp":2.42,"tv":56.0,"id":206388}]}]}
{"op":"mcm","clk":"11978454480","pt":1724790589150,"mc":[{"id":"1.232352477","rc":[{"batb":[[0,2.36,5],[1,2.34,30.16],[2,1.03,200]],"ltp":2.42,"tv":56.0,"id":206388}]}]}
{"op":"mcm","clk":"11978454877","pt":1724790592622,"mc":[{"id":"1.232352477","rc":[{"batb":[[0,2.34,30.16],[1,1.03,200],[2,1.02,200]],"ltp":2.42,"tv":56.0,"id":206388}]}]}
{"op":"mcm","clk":"11978455142","pt":1724790595061,"mc":[{"id":"1.232352477","rc":[{"batb":[[0,2.36,5],[1,2.34,30.16],[2,1.03,200]],"ltp":2.42,"tv":56.0,"id":206388}]}]}
{"op":"mcm","clk":"11978455488","pt":1724790598357,"mc":[{"id":"1.232352477","rc":[{"batb":[[0,2.34,30.16],[1,1.03,200],[2,1.02,200]],"ltp":2.42,"tv":56.0,"id":206388}]}]}
{"op":"mcm","clk":"11978455756","pt":1724790600746,"mc":[{"id":"1.232352477","rc":[{"batb":[[0,2.36,5],[1,2.34,30.16],[2,1.03,200]],"ltp":2.42,"tv":56.0,"id":206388}]}]}
{"op":"mcm","clk":"11978456157","pt":1724790604189,"mc":[{"id":"1.232352477","rc":[{"batb":[[0,2.34,30.16],[1,1.03,200],[2,1.02,200]],"ltp":2.42,"tv":56.0,"id":206388}]}]}
{"op":"mcm","clk":"11978456459","pt":1724790606681,"mc":[{"id":"1.232352477","rc":[{"batb":[[0,2.36,5],[1,2.34,30.16],[2,1.03,200]],"ltp":2.42,"tv":56.0,"id":206388}]}]}
{"op":"mcm","clk":"11978456936","pt":1724790610264,"mc":[{"id":"1.232352477","rc":[{"batb":[[0,2.34,30.16],[1,1.03,200],[2,1.02,200]],"ltp":2.42,"tv":56.0,"id":206388}]}]}
{"op":"mcm","clk":"11978457258","pt":1724790612776,"mc":[{"id":"1.232352477","rc":[{"batb":[[0,2.36,5],[1,2.34,30.16],[2,1.03,200]],"ltp":2.42,"tv":56.0,"id":206388}]}]}
{"op":"mcm","clk":"11978457670","pt":1724790616085,"mc":[{"id":"1.232352477","rc":[{"batb":[[0,2.34,30.16],[1,1.03,200],[2,1.02,200]],"ltp":2.42,"tv":56.0,"id":206388}]}]}
{"op":"mcm","clk":"11978457996","pt":1724790618680,"mc":[{"id":"1.232352477","rc":[{"batb":[[0,2.36,5],[1,2.34,30.16],[2,1.03,200]],"ltp":2.42,"tv":56.0,"id":206388}]}]}
{"op":"mcm","clk":"11978458379","pt":1724790621968,"mc":[{"id":"1.232352477","rc":[{"batb":[[0,2.34,30.16],[1,1.03,200],[2,1.02,200]],"ltp":2.42,"tv":56.0,"id":206388}]}]}
{"op":"mcm","clk":"11978458692","pt":1724790624568,"mc":[{"id":"1.232352477","rc":[{"batb":[[0,2.36,5],[1,2.34,30.16],[2,1.03,200]],"ltp":2.42,"tv":56.0,"id":206388}]}]}
{"op":"mcm","clk":"11978459154","pt":1724790628010,"mc":[{"id":"1.232352477","rc":[{"batb":[[0,2.34,30.16],[1,1.03,200],[2,1.02,200]],"ltp":2.42,"tv":56.0,"id":206388}]}]}
{"op":"mcm","clk":"11978459437","pt":1724790630315,"mc":[{"id":"1.232352477","rc":[{"batb":[[0,2.36,5],[1,2.34,30.16],[2,1.03,200]],"ltp":2.42,"tv":56.0,"id":206388}]}]}
{"op":"mcm","clk":"11978459865","pt":1724790633592,"mc":[{"id":"1.232352477","rc":[{"batb":[[0,2.34,30.16],[1,1.03,200],[2,1.02,200]],"ltp":2.42,"tv":56.0,"id":206388}]}]}
{"op":"mcm","clk":"11978460403","pt":1724790637879,"mc":[{"id":"1.232352477","rc":[{"batb":[[0,2.36,5],[1,2.34,30.16],[2,1.03,200]],"ltp":2.42,"tv":56.0,"id":206388}]}]}
{"op":"mcm","clk":"11978460842","pt":1724790641517,"mc":[{"id":"1.232352477","rc":[{"batb":[[0,2.34,30.16],[1,1.03,200],[2,1.02,200]],"ltp":2.42,"tv":56.0,"id":206388}]}]}
{"op":"mcm","clk":"11978461126","pt":1724790643821,"mc":[{"id":"1.232352477","rc":[{"batb":[[0,2.36,5],[1,2.34,30.16],[2,1.03,200]],"ltp":2.42,"tv":56.0,"id":206388}]}]}
{"op":"mcm","clk":"11978461556","pt":1724790647295,"mc":[{"id":"1.232352477","rc":[{"batb":[[0,2.34,30.16],[1,1.03,200],[2,1.02,200]],"ltp":2.42,"tv":56.0,"id":206388}]}]}
{"op":"mcm","clk":"11978461852","pt":1724790649674,"mc":[{"id":"1.232352477","rc":[{"batb":[[0,2.36,5],[1,2.34,30.16],[2,1.03,200]],"ltp":2.42,"tv":56.0,"id":206388}]}]}
{"op":"mcm","clk":"11978462265","pt":1724790653271,"mc":[{"id":"1.232352477","rc":[{"batb":[[0,2.34,30.16],[1,1.03,200],[2,1.02,200]],"ltp":2.42,"tv":56.0,"id":206388}]}]}
{"op":"mcm","clk":"11978462847","pt":1724790658158,"mc":[{"id":"1.232352477","rc":[{"batb":[[0,2.36,5],[1,2.34,30.16],[2,1.03,200]],"ltp":2.42,"tv":56.0,"id":206388}]}]}
{"op":"mcm","clk":"11978463240","pt":1724790661707,"mc":[{"id":"1.232352477","rc":[{"batb":[[0,2.34,30.16],[1,1.03,200],[2,1.02,200]],"ltp":2.42,"tv":56.0,"id":206388}]}]}
{"op":"mcm","clk":"11978463517","pt":1724790663991,"mc":[{"id":"1.232352477","rc":[{"batb":[[0,2.36,5],[1,2.34,30.16],[2,1.03,200]],"ltp":2.42,"tv":56.0,"id":206388}]}]}
{"op":"mcm","clk":"11978463869","pt":1724790667475,"mc":[{"id":"1.232352477","rc":[{"batb":[[0,2.34,30.16],[1,1.03,200],[2,1.02,200]],"ltp":2.42,"tv":56.0,"id":206388}]}]}
{"op":"mcm","clk":"11978464204","pt":1724790670581,"mc":[{"id":"1.232352477","rc":[{"batb":[[0,2.36,5],[1,2.34,30.16],[2,1.03,200]],"ltp":2.42,"tv":56.0,"id":206388}]}]}
{"op":"mcm","clk":"11978464567","pt":1724790673765,"mc":[{"id":"1.232352477","rc":[{"batb":[[0,2.34,30.16],[1,1.03,200],[2,1.02,200]],"ltp":2.42,"tv":56.0,"id":206388}]}]}
{"op":"mcm","clk":"11978465281","pt":1724790679678,"mc":[{"id":"1.232352477","rc":[{"batb":[[0,2.36,5],[1,2.34,30.16],[2,1.03,200]],"ltp":2.42,"tv":56.0,"id":206388}]}]}
{"op":"mcm","clk":"11978465649","pt":1724790683067,"mc":[{"id":"1.232352477","rc":[{"batb":[[0,2.34,30.16],[1,1.03,200],[2,1.02,200]],"ltp":2.42,"tv":56.0,"id":206388}]}]}
{"op":"mcm","clk":"11978466089","pt":1724790687281,"mc":[{"id":"1.232352477","rc":[{"batb":[[0,2.36,5],[1,2.34,30.16],[2,1.03,200]],"ltp":2.42,"tv":56.0,"id":206388}]}]}
{"op":"mcm","clk":"11978466554","pt":1724790690677,"mc":[{"id":"1.232352477","rc":[{"batb":[[0,2.34,30.16],[1,1.03,200],[2,1.02,200]],"ltp":2.42,"tv":56.0,"id":206388}]}]}
{"op":"mcm","clk":"11978466914","pt":1724790693209,"mc":[{"id":"1.232352477","rc":[{"batb":[[0,2.36,5],[1,2.34,30.16],[2,1.03,200]],"ltp":2.42,"tv":56.0,"id":206388}]}]}
{"op":"mcm","clk":"11978467412","pt":1724790696714,"mc":[{"id":"1.232352477","rc":[{"batb":[[0,2.34,30.16],[1,1.03,200],[2,1.02,200]],"ltp":2.42,"tv":56.0,"id":206388}]}]}
{"op":"mcm","clk":"11978467798","pt":1724790700294,"mc":[{"id":"1.232352477","rc":[{"batb":[[0,2.36,5],[1,2.34,30.16],[2,1.03,200]],"ltp":2.42,"tv":56.0,"id":206388}]}]}
{"op":"mcm","clk":"11978468122","pt":1724790703505,"mc":[{"id":"1.232352477","rc":[{"batb":[[0,2.34,30.16],[1,1.03,200],[2,1.02,200]],"ltp":2.42,"tv":56.0,"id":206388}]}]}
{"op":"mcm","clk":"11978468456","pt":1724790706877,"mc":[{"id":"1.232352477","rc":[{"batb":[[0,2.36,5],[1,2.34,30.16],[2,1.03,200]],"ltp":2.42,"tv":56.0,"id":206388}]}]}
{"op":"mcm","clk":"11978468844","pt":1724790710307,"mc":[{"id":"1.232352477","rc":[{"batb":[[0,2.34,30.16],[1,1.03,200],[2,1.02,200]],"ltp":2.42,"tv":56.0,"id":206388}]}]}
{"op":"mcm","clk":"11978469233","pt":1724790713530,"mc":[{"id":"1.232352477","rc":[{"batb":[[0,2.36,5],[1,2.34,30.16],[2,1.03,200]],"ltp":2.42,"tv":56.0,"id":206388}]}]}
{"op":"mcm","clk":"11978469609","pt":1724790716803,"mc":[{"id":"1.232352477","rc":[{"batb":[[0,2.34,30.16],[1,1.03,200],[2,1.02,200]],"ltp":2.42,"tv":56.0,"id":206388}]}]}
{"op":"mcm","clk":"11978470008","pt":1724790720332,"mc":[{"id":"1.232352477","rc":[{"batb":[[0,2.36,5],[1,2.34,30.16],[2,1.03,200]],"ltp":2.42,"tv":56.0,"id":206388}]}]}
{"op":"mcm","clk":"11978470363","pt":1724790723501,"mc":[{"id":"1.232352477","rc":[{"batb":[[0,2.34,30.16],[1,1.03,200],[2,1.02,200]],"ltp":2.42,"tv":56.0,"id":206388}]}]}
{"op":"mcm","clk":"11978470946","pt":1724790728441,"mc":[{"id":"1.232352477","rc":[{"batb":[[0,2.36,5],[1,2.34,30.16],[2,1.03,200]],"ltp":2.42,"tv":56.0,"id":206388}]}]}
{"op":"mcm","clk":"11978471317","pt":1724790731859,"mc":[{"id":"1.232352477","rc":[{"batb":[[0,2.34,30.16],[1,1.03,200],[2,1.02,200]],"ltp":2.42,"tv":56.0,"id":206388}]}]}
{"op":"mcm","clk":"11978471568","pt":1724790734240,"mc":[{"id":"1.232352477","rc":[{"batb":[[0,2.36,5],[1,2.34,30.16],[2,1.03,200]],"ltp":2.42,"tv":56.0,"id":206388}]}]}
{"op":"mcm","clk":"11978471954","pt":1724790737727,"mc":[{"id":"1.232352477","rc":[{"batb":[[0,2.34,30.16],[1,1.03,200],[2,1.02,200]],"ltp":2.42,"tv":56.0,"id":206388}]}]}
{"op":"mcm","clk":"11978472249","pt":1724790739918,"mc":[{"id":"1.232352477","rc":[{"batb":[[0,2.36,5],[1,2.34,30.16],[2,1.03,200]],"ltp":2.42,"tv":56.0,"id":206388}]}]}
{"op":"mcm","clk":"11978472653","pt":1724790743244,"mc":[{"id":"1.232352477","rc":[{"batb":[[0,2.34,30.16],[1,1.03,200],[2,1.02,200]],"ltp":2.42,"tv":56.0,"id":206388}]}]}
{"op":"mcm","clk":"11978473032","pt":1724790746217,"mc":[{"id":"1.232352477","rc":[{"batb":[[0,2.36,5],[1,2.34,30.16],[2,1.03,200]],"ltp":2.42,"tv":56.0,"id":206388}]}]}
{"op":"mcm","clk":"11978473361","pt":1724790749638,"mc":[{"id":"1.232352477","rc":[{"batb":[[0,2.34,30.16],[1,1.03,200],[2,1.02,200]],"ltp":2.42,"tv":56.0,"id":206388}]}]}
{"op":"mcm","clk":"11978473647","pt":1724790752140,"mc":[{"id":"1.232352477","rc":[{"batb":[[0,2.36,5],[1,2.34,30.16],[2,1.03,200]],"ltp":2.42,"tv":56.0,"id":206388}]}]}
{"op":"mcm","clk":"11978474036","pt":1724790755455,"mc":[{"id":"1.232352477","rc":[{"batb":[[0,2.34,30.16],[1,1.03,200],[2,1.02,200]],"ltp":2.42,"tv":56.0,"id":206388}]}]}
{"op":"mcm","clk":"11978474430","pt":1724790758779,"mc":[{"id":"1.232352477","rc":[{"batb":[[0,2.36,5],[1,2.34,30.16],[2,1.03,200]],"ltp":2.42,"tv":56.0,"id":206388}]}]}
{"op":"mcm","clk":"11978474788","pt":1724790762046,"mc":[{"id":"1.232352477","rc":[{"batb":[[0,2.34,30.16],[1,1.03,200],[2,1.02,200]],"ltp":2.42,"tv":56.0,"id":206388}]}]}
{"op":"mcm","clk":"11978475471","pt":1724790768167,"mc":[{"id":"1.232352477","rc":[{"batb":[[0,2.36,5],[1,2.34,30.16],[2,1.03,200]],"ltp":2.42,"tv":56.0,"id":206388}]}]}
{"op":"mcm","clk":"11978475915","pt":1724790771643,"mc":[{"id":"1.232352477","rc":[{"batb":[[0,2.34,30.16],[1,1.03,200],[2,1.02,200]],"ltp":2.42,"tv":56.0,"id":206388}]}]}
{"op":"mcm","clk":"11978476360","pt":1724790775176,"mc":[{"id":"1.232352477","rc":[{"batb":[[0,2.36,5],[1,2.34,30.16],[2,1.03,200]],"ltp":2.42,"tv":56.0,"id":206388}]}]}
{"op":"mcm","clk":"11978476744","pt":1724790778689,"mc":[{"id":"1.232352477","rc":[{"batb":[[0,2.34,30.16],[1,1.03,200],[2,1.02,200]],"ltp":2.42,"tv":56.0,"id":206388}]}]}
{"op":"mcm","clk":"11978477173","pt":1724790782486,"mc":[{"id":"1.232352477","rc":[{"batb":[[0,2.36,5],[1,2.34,30.16],[2,1.03,200]],"ltp":2.42,"tv":56.0,"id":206388}]}]}
{"op":"mcm","clk":"11978477565","pt":1724790785754,"mc":[{"id":"1.232352477","rc":[{"batb":[[0,2.34,30.16],[1,1.03,200],[2,1.02,200]],"ltp":2.42,"tv":56.0,"id":206388}]}]}
{"op":"mcm","clk":"11978478201","pt":1724790791804,"mc":[{"id":"1.232352477","rc":[{"batb":[[0,2.36,5],[1,2.34,30.16],[2,1.03,200]],"ltp":2.42,"tv":56.0,"id":206388}]}]}
{"op":"mcm","clk":"11978478602","pt":1724790795387,"mc":[{"id":"1.232352477","rc":[{"batb":[[0,2.34,30.16],[1,1.03,200],[2,1.02,200]],"ltp":2.42,"tv":56.0,"id":206388}]}]}
{"op":"mcm","clk":"11978479142","pt":1724790800172,"mc":[{"id":"1.232352477","rc":[{"batb":[[0,2.36,5],[1,2.34,30.16],[2,1.03,200]],"ltp":2.42,"tv":56.0,"id":206388}]}]}
{"op":"mcm","clk":"11978479504","pt":1724790803589,"mc":[{"id":"1.232352477","rc":[{"batb":[[0,2.34,30.16],[1,1.03,200],[2,1.02,200]],"ltp":2.42,"tv":56.0,"id":206388}]}]}
{"op":"mcm","clk":"11978479811","pt":1724790806486,"mc":[{"id":"1.232352477","rc":[{"batb":[[0,2.36,5],[1,2.34,30.16],[2,1.03,200]],"ltp":2.42,"tv":56.0,"id":206388}]}]}
{"op":"mcm","clk":"11978480209","pt":1724790810316,"mc":[{"id":"1.232352477","rc":[{"batb":[[0,2.34,30.16],[1,1.03,200],[2,1.02,200]],"ltp":2.42,"tv":56.0,"id":206388}]}]}
{"op":"mcm","clk":"11978480488","pt":1724790812707,"mc":[{"id":"1.232352477","rc":[{"batb":[[0,2.36,5],[1,2.34,30.16],[2,1.03,200]],"ltp":2.42,"tv":56.0,"id":206388}]}]}
{"op":"mcm","clk":"11978480897","pt":1724790816076,"mc":[{"id":"1.232352477","rc":[{"batb":[[0,2.34,30.16],[1,1.03,200],[2,1.02,200]],"ltp":2.42,"tv":56.0,"id":206388}]}]}
{"op":"mcm","clk":"11978481183","pt":1724790818815,"mc":[{"id":"1.232352477","rc":[{"batb":[[0,2.36,5],[1,2.34,30.16],[2,1.03,200]],"ltp":2.42,"tv":56.0,"id":206388}]}]}
{"op":"mcm","clk":"11978481592","pt":1724790822295,"mc":[{"id":"1.232352477","rc":[{"batb":[[0,2.34,30.16],[1,1.03,200],[2,1.02,200]],"ltp":2.42,"tv":56.0,"id":206388}]}]}
{"op":"mcm","clk":"11978481933","pt":1724790825410,"mc":[{"id":"1.232352477","rc":[{"batb":[[0,2.36,5],[1,2.34,30.16],[2,1.03,200]],"ltp":2.42,"tv":56.0,"id":206388}]}]}
{"op":"mcm","clk":"11978482369","pt":1724790829133,"mc":[{"id":"1.232352477","rc":[{"batb":[[0,2.34,30.16],[1,1.03,200],[2,1.02,200]],"ltp":2.42,"tv":56.0,"id":206388}]}]}
{"op":"mcm","clk":"11978482749","pt":1724790832510,"mc":[{"id":"1.232352477","rc":[{"batb":[[0,2.36,5],[1,2.34,30.16],[2,1.03,200]],"ltp":2.42,"tv":56.0,"id":206388}]}]}
{"op":"mcm","clk":"11978483082","pt":1724790835723,"mc":[{"id":"1.232352477","rc":[{"batb":[[0,2.34,30.16],[1,1.03,200],[2,1.02,200]],"ltp":2.42,"tv":56.0,"id":206388}]}]}
{"op":"mcm","clk":"11978483383","pt":1724790838939,"mc":[{"id":"1.232352477","rc":[{"batb":[[0,2.36,5],[1,2.34,30.16],[2,1.03,200]],"ltp":2.42,"tv":56.0,"id":206388}]}]}
{"op":"mcm","clk":"11978483721","pt":1724790842319,"mc":[{"id":"1.232352477","rc":[{"batb":[[0,2.34,30.16],[1,1.03,200],[2,1.02,200]],"ltp":2.42,"tv":56.0,"id":206388}]}]}
{"op":"mcm","clk":"11978484376","pt":1724790849135,"mc":[{"id":"1.232352477","rc":[{"batb":[[0,2.36,5],[1,2.34,30.16],[2,1.03,200]],"ltp":2.42,"tv":56.0,"id":206388}]}]}
{"op":"mcm","clk":"11978484720","pt":1724790852516,"mc":[{"id":"1.232352477","rc":[{"batb":[[0,2.34,30.16],[1,1.03,200],[2,1.02,200]],"ltp":2.42,"tv":56.0,"id":206388}]}]}
{"op":"mcm","clk":"11978485111","pt":1724790856344,"mc":[{"id":"1.232352477","rc":[{"batb":[[0,2.36,5],[1,2.34,30.16],[2,1.03,200]],"ltp":2.42,"tv":56.0,"id":206388}]}]}
{"op":"mcm","clk":"11978485463","pt":1724790859765,"mc":[{"id":"1.232352477","rc":[{"batb":[[0,2.34,30.16],[1,1.03,200],[2,1.02,200]],"ltp":2.42,"tv":56.0,"id":206388}]}]}
{"op":"mcm","clk":"11978485746","pt":1724790862475,"mc":[{"id":"1.232352477","rc":[{"batb":[[0,2.36,5],[1,2.34,30.16],[2,1.03,200]],"ltp":2.42,"tv":56.0,"id":206388}]}]}
{"op":"mcm","clk":"11978486103","pt":1724790866042,"mc":[{"id":"1.232352477","rc":[{"batb":[[0,2.34,30.16],[1,1.03,200],[2,1.02,200]],"ltp":2.42,"tv":56.0,"id":206388}]}]}
{"op":"mcm","clk":"11978486343","pt":1724790868467,"mc":[{"id":"1.232352477","rc":[{"batb":[[0,2.36,5],[1,2.34,30.16],[2,1.03,200]],"ltp":2.42,"tv":56.0,"id":206388}]}]}
{"op":"mcm","clk":"11978486705","pt":1724790872047,"mc":[{"id":"1.232352477","rc":[{"batb":[[0,2.34,30.16],[1,1.03,200],[2,1.02,200]],"ltp":2.42,"tv":56.0,"id":206388}]}]}
{"op":"mcm","clk":"11978486939","pt":1724790874474,"mc":[{"id":"1.232352477","rc":[{"batb":[[0,2.36,5],[1,2.34,30.16],[2,1.03,200]],"ltp":2.42,"tv":56.0,"id":206388}]}]}
{"op":"mcm","clk":"11978487304","pt":1724790877783,"mc":[{"id":"1.232352477","rc":[{"batb":[[0,2.34,30.16],[1,1.03,200],[2,1.02,200]],"ltp":2.42,"tv":56.0,"id":206388}]}]}
{"op":"mcm","clk":"11978487560","pt":1724790880161,"mc":[{"id":"1.232352477","rc":[{"batb":[[0,2.36,5],[1,2.34,30.16],[2,1.03,200]],"ltp":2.42,"tv":56.0,"id":206388}]}]}
{"op":"mcm","clk":"11978487944","pt":1724790883887,"mc":[{"id":"1.232352477","rc":[{"batb":[[0,2.34,30.16],[1,1.03,200],[2,1.02,200]],"ltp":2.42,"tv":56.0,"id":206388}]}]}
{"op":"mcm","clk":"11978488222","pt":1724790886467,"mc":[{"id":"1.232352477","rc":[{"batb":[[0,2.36,5],[1,2.34,30.16],[2,1.03,200]],"ltp":2.42,"tv":56.0,"id":206388}]}]}
{"op":"mcm","clk":"11978488577","pt":1724790889981,"mc":[{"id":"1.232352477","rc":[{"batb":[[0,2.34,30.16],[1,1.03,200],[2,1.02,200]],"ltp":2.42,"tv":56.0,"id":206388}]}]}
{"op":"mcm","clk":"11978488794","pt":1724790892199,"mc":[{"id":"1.232352477","rc":[{"batb":[[0,2.36,5],[1,2.34,30.16],[2,1.03,200]],"ltp":2.42,"tv":56.0,"id":206388}]}]}
{"op":"mcm","clk":"11978489158","pt":1724790895772,"mc":[{"id":"1.232352477","rc":[{"batb":[[0,2.34,30.16],[1,1.03,200],[2,1.02,200]],"ltp":2.42,"tv":56.0,"id":206388}]}]}
{"op":"mcm","clk":"11978489433","pt":1724790898401,"mc":[{"id":"1.232352477","rc":[{"batb":[[0,2.36,5],[1,2.34,30.16],[2,1.03,200]],"ltp":2.42,"tv":56.0,"id":206388}]}]}
{"op":"mcm","clk":"11978489794","pt":1724790901789,"mc":[{"id":"1.232352477","rc":[{"batb":[[0,2.34,30.16],[1,1.03,200],[2,1.02,200]],"ltp":2.42,"tv":56.0,"id":206388}]}]}
{"op":"mcm","clk":"11978490058","pt":1724790904169,"mc":[{"id":"1.232352477","rc":[{"batb":[[0,2.36,5],[1,2.34,30.16],[2,1.03,200]],"ltp":2.42,"tv":56.0,"id":206388}]}]}
{"op":"mcm","clk":"11978490405","pt":1724790907484,"mc":[{"id":"1.232352477","rc":[{"batb":[[0,2.34,30.16],[1,1.03,200],[2,1.02,200]],"ltp":2.42,"tv":56.0,"id":206388}]}]}
{"op":"mcm","clk":"11978490748","pt":1724790910527,"mc":[{"id":"1.232352477","rc":[{"batb":[[0,2.36,5],[1,2.34,30.16],[2,1.03,200]],"ltp":2.42,"tv":56.0,"id":206388}]}]}
{"op":"mcm","clk":"11978491130","pt":1724790913832,"mc":[{"id":"1.232352477","rc":[{"batb":[[0,2.34,30.16],[1,1.03,200],[2,1.02,200]],"ltp":2.42,"tv":56.0,"id":206388}]}]}
{"op":"mcm","clk":"11978491449","pt":1724790917317,"mc":[{"id":"1.232352477","rc":[{"batb":[[0,2.36,5],[1,2.34,30.16],[2,1.03,200]],"ltp":2.42,"tv":56.0,"id":206388}]}]}
{"op":"mcm","clk":"11978491782","pt":1724790920722,"mc":[{"id":"1.232352477","rc":[{"batb":[[0,2.34,30.16],[1,1.03,200],[2,1.02,200]],"ltp":2.42,"tv":56.0,"id":206388}]}]}
{"op":"mcm","clk":"11978492068","pt":1724790923505,"mc":[{"id":"1.232352477","rc":[{"batb":[[0,2.36,5],[1,2.34,30.16],[2,1.03,200]],"ltp":2.42,"tv":56.0,"id":206388}]}]}
{"op":"mcm","clk":"11978492411","pt":1724790926904,"mc":[{"id":"1.232352477","rc":[{"batb":[[0,2.34,30.16],[1,1.03,200],[2,1.02,200]],"ltp":2.42,"tv":56.0,"id":206388}]}]}
{"op":"mcm","clk":"11978492780","pt":1724790930627,"mc":[{"id":"1.232352477","rc":[{"batb":[[0,2.36,5],[1,2.34,30.16],[2,1.03,200]],"ltp":2.42,"tv":56.0,"id":206388}]}]}
{"op":"mcm","clk":"11978493132","pt":1724790934047,"mc":[{"id":"1.232352477","rc":[{"batb":[[0,2.34,30.16],[1,1.03,200],[2,1.02,200]],"ltp":2.42,"tv":56.0,"id":206388}]}]}
{"op":"mcm","clk":"11978493380","pt":1724790936629,"mc":[{"id":"1.232352477","rc":[{"batb":[[0,2.36,5],[1,2.34,30.16],[2,1.03,200]],"ltp":2.42,"tv":56.0,"id":206388}]}]}
{"op":"mcm","clk":"11978493705","pt":1724790940032,"mc":[{"id":"1.232352477","rc":[{"batb":[[0,2.34,30.16],[1,1.03,200],[2,1.02,200]],"ltp":2.42,"tv":56.0,"id":206388}]}]}
{"op":"mcm","clk":"11978493949","pt":1724790942715,"mc":[{"id":"1.232352477","rc":[{"batb":[[0,2.36,5],[1,2.34,30.16],[2,1.03,200]],"ltp":2.42,"tv":56.0,"id":206388}]}]}
{"op":"mcm","clk":"11978494285","pt":1724790946021,"mc":[{"id":"1.232352477","rc":[{"batb":[[0,2.34,30.16],[1,1.03,200],[2,1.02,200]],"ltp":2.42,"tv":56.0,"id":206388}]}]}
{"op":"mcm","clk":"11978494508","pt":1724790948340,"mc":[{"id":"1.232352477","rc":[{"batb":[[0,2.36,5],[1,2.34,30.16],[2,1.03,200]],"ltp":2.42,"tv":56.0,"id":206388}]}]}
{"op":"mcm","clk":"11978494858","pt":1724790951750,"mc":[{"id":"1.232352477","rc":[{"batb":[[0,2.34,30.16],[1,1.03,200],[2,1.02,200]],"ltp":2.42,"tv":56.0,"id":206388}]}]}
{"op":"mcm","clk":"11978495201","pt":1724790955373,"mc":[{"id":"1.232352477","rc":[{"batb":[[0,2.36,5],[1,2.34,30.16],[2,1.03,200]],"ltp":2.42,"tv":56.0,"id":206388}]}]}
{"op":"mcm","clk":"11978495495","pt":1724790958567,"mc":[{"id":"1.232352477","rc":[{"batb":[[0,2.34,30.16],[1,1.03,200],[2,1.02,200]],"ltp":2.42,"tv":56.0,"id":206388}]}]}
{"op":"mcm","clk":"11978495748","pt":1724790961564,"mc":[{"id":"1.232352477","rc":[{"batb":[[0,2.36,5],[1,2.34,30.16],[2,1.03,200]],"ltp":2.42,"tv":56.0,"id":206388}]}]}
{"op":"mcm","clk":"11978496075","pt":1724790965049,"mc":[{"id":"1.232352477","rc":[{"batb":[[0,2.34,30.16],[1,1.03,200],[2,1.02,200]],"ltp":2.42,"tv":56.0,"id":206388}]}]}
{"op":"mcm","clk":"11978496528","pt":1724790969963,"mc":[{"id":"1.232352477","rc":[{"batb":[[0,2.36,5],[1,2.34,30.16],[2,1.03,200]],"ltp":2.42,"tv":56.0,"id":206388}]}]}
{"op":"mcm","clk":"11978496818","pt":1724790973266,"mc":[{"id":"1.232352477","rc":[{"batb":[[0,2.34,30.16],[1,1.03,200],[2,1.02,200]],"ltp":2.42,"tv":56.0,"id":206388}]}]}
{"op":"mcm","clk":"11978497085","pt":1724790976367,"mc":[{"id":"1.232352477","rc":[{"batb":[[0,2.36,5],[1,2.34,30.16],[2,1.03,200]],"ltp":2.42,"tv":56.0,"id":206388}]}]}
{"op":"mcm","clk":"11978497406","pt":1724790979884,"mc":[{"id":"1.232352477","rc":[{"batb":[[0,2.34,30.16],[1,1.03,200],[2,1.02,200]],"ltp":2.42,"tv":56.0,"id":206388}]}]}
{"op":"mcm","clk":"11978497610","pt":1724790982257,"mc":[{"id":"1.232352477","rc":[{"batb":[[0,2.36,5],[1,2.34,30.16],[2,1.03,200]],"ltp":2.42,"tv":56.0,"id":206388}]}]}
{"op":"mcm","clk":"11978497916","pt":1724790985769,"mc":[{"id":"1.232352477","rc":[{"batb":[[0,2.34,30.16],[1,1.03,200],[2,1.02,200]],"ltp":2.42,"tv":56.0,"id":206388}]}]}
{"op":"mcm","clk":"11978498128","pt":1724790987984,"mc":[{"id":"1.232352477","rc":[{"batb":[[0,2.36,5],[1,2.34,30.16],[2,1.03,200]],"ltp":2.42,"tv":56.0,"id":206388}]}]}
{"op":"mcm","clk":"11978498517","pt":1724790991470,"mc":[{"id":"1.232352477","rc":[{"batb":[[0,2.34,30.16],[1,1.03,200],[2,1.02,200]],"ltp":2.42,"tv":56.0,"id":206388}]}]}
{"op":"mcm","clk":"11978498710","pt":1724790993698,"mc":[{"id":"1.232352477","rc":[{"batb":[[0,2.36,5],[1,2.34,30.16],[2,1.03,200]],"ltp":2.42,"tv":56.0,"id":206388}]}]}
{"op":"mcm","clk":"11978499109","pt":1724790997163,"mc":[{"id":"1.232352477","rc":[{"batb":[[0,2.34,30.16],[1,1.03,200],[2,1.02,200]],"ltp":2.42,"tv":56.0,"id":206388}]}]}
{"op":"mcm","clk":"11978499330","pt":1724790999483,"mc":[{"id":"1.232352477","rc":[{"batb":[[0,2.36,5],[1,2.34,30.16],[2,1.03,200]],"ltp":2.42,"tv":56.0,"id":206388}]}]}
{"op":"mcm","clk":"11978499663","pt":1724791002893,"mc":[{"id":"1.232352477","rc":[{"batb":[[0,2.34,30.16],[1,1.03,200],[2,1.02,200]],"ltp":2.42,"tv":56.0,"id":206388}]}]}
{"op":"mcm","clk":"11978499877","pt":1724791005215,"mc":[{"id":"1.232352477","rc":[{"batb":[[0,2.36,5],[1,2.34,30.16],[2,1.03,200]],"ltp":2.42,"tv":56.0,"id":206388}]}]}
{"op":"mcm","clk":"11978500209","pt":1724791008694,"mc":[{"id":"1.232352477","rc":[{"batb":[[0,2.34,30.16],[1,1.03,200],[2,1.02,200]],"ltp":2.42,"tv":56.0,"id":206388}]}]}
{"op":"mcm","clk":"11978500531","pt":1724791011792,"mc":[{"id":"1.232352477","rc":[{"batb":[[0,2.36,5],[1,2.34,30.16],[2,1.03,200]],"ltp":2.42,"tv":56.0,"id":206388}]}]}
{"op":"mcm","clk":"11978500831","pt":1724791015206,"mc":[{"id":"1.232352477","rc":[{"batb":[[0,2.34,30.16],[1,1.03,200],[2,1.02,200]],"ltp":2.42,"tv":56.0,"id":206388}]}]}
{"op":"mcm","clk":"11978501059","pt":1724791017632,"mc":[{"id":"1.232352477","rc":[{"batb":[[0,2.36,5],[1,2.34,30.16],[2,1.03,200]],"ltp":2.42,"tv":56.0,"id":206388}]}]}
{"op":"mcm","clk":"11978501395","pt":1724791020912,"mc":[{"id":"1.232352477","rc":[{"batb":[[0,2.34,30.16],[1,1.03,200],[2,1.02,200]],"ltp":2.42,"tv":56.0,"id":206388}]}]}
{"op":"mcm","clk":"11978501614","pt":1724791023402,"mc":[{"id":"1.232352477","rc":[{"batb":[[0,2.36,5],[1,2.34,30.16],[2,1.03,200]],"ltp":2.42,"tv":56.0,"id":206388}]}]}
{"op":"mcm","clk":"11978501876","pt":1724791026816,"mc":[{"id":"1.232352477","rc":[{"batb":[[0,2.34,30.16],[1,1.03,200],[2,1.02,200]],"ltp":2.42,"tv":56.0,"id":206388}]}]}
{"op":"mcm","clk":"11978502374","pt":1724791031225,"mc":[{"id":"1.232352477","rc":[{"batb":[[0,2.36,5],[1,2.34,30.16],[2,1.03,200]],"ltp":2.42,"tv":56.0,"id":206388}]}]}
{"op":"mcm","clk":"11978502610","pt":1724791034517,"mc":[{"id":"1.232352477","rc":[{"batb":[[0,2.34,30.16],[1,1.03,200],[2,1.02,200]],"ltp":2.42,"tv":56.0,"id":206388}]}]}
{"op":"mcm","clk":"11978502781","pt":1724791037047,"mc":[{"id":"1.232352477","rc":[{"batb":[[0,2.36,5],[1,2.34,30.16],[2,1.03,200]],"ltp":2.42,"tv":56.0,"id":206388}]}]}
{"op":"mcm","clk":"11978503082","pt":1724791040421,"mc":[{"id":"1.232352477","rc":[{"batb":[[0,2.34,30.16],[1,1.03,200],[2,1.02,200]],"ltp":2.42,"tv":56.0,"id":206388}]}]}
{"op":"mcm","clk":"11978503286","pt":1724791042639,"mc":[{"id":"1.232352477","rc":[{"batb":[[0,2.36,5],[1,2.34,30.16],[2,1.03,200]],"ltp":2.42,"tv":56.0,"id":206388}]}]}
{"op":"mcm","clk":"11978503616","pt":1724791046122,"mc":[{"id":"1.232352477","rc":[{"batb":[[0,2.34,30.16],[1,1.03,200],[2,1.02,200]],"ltp":2.42,"tv":56.0,"id":206388}]}]}
{"op":"mcm","clk":"11978503901","pt":1724791049633,"mc":[{"id":"1.232352477","rc":[{"batb":[[0,2.36,5],[1,2.34,30.16],[2,1.03,200]],"ltp":2.42,"tv":56.0,"id":206388}]}]}
{"op":"mcm","clk":"11978504220","pt":1724791053051,"mc":[{"id":"1.232352477","rc":[{"batb":[[0,2.34,30.16],[1,1.03,200],[2,1.02,200]],"ltp":2.42,"tv":56.0,"id":206388}]}]}
{"op":"mcm","clk":"11978504571","pt":1724791056449,"mc":[{"id":"1.232352477","rc":[{"batb":[[0,2.36,5],[1,2.34,30.16],[2,1.03,200]],"ltp":2.42,"tv":56.0,"id":206388}]}]}
{"op":"mcm","clk":"11978504890","pt":1724791059835,"mc":[{"id":"1.232352477","rc":[{"batb":[[0,2.34,30.16],[1,1.03,200],[2,1.02,200]],"ltp":2.42,"tv":56.0,"id":206388}]}]}
{"op":"mcm","clk":"11978505115","pt":1724791062250,"mc":[{"id":"1.232352477","rc":[{"batb":[[0,2.36,5],[1,2.34,30.16],[2,1.03,200]],"ltp":2.42,"tv":56.0,"id":206388}]}]}
{"op":"mcm","clk":"11978505496","pt":1724791065864,"mc":[{"id":"1.232352477","rc":[{"batb":[[0,2.34,30.16],[1,1.03,200],[2,1.02,200]],"ltp":2.42,"tv":56.0,"id":206388}]}]}
{"op":"mcm","clk":"11978505736","pt":1724791068257,"mc":[{"id":"1.232352477","rc":[{"batb":[[0,2.36,5],[1,2.34,30.16],[2,1.03,200]],"ltp":2.42,"tv":56.0,"id":206388}]}]}
{"op":"mcm","clk":"11978506057","pt":1724791071657,"mc":[{"id":"1.232352477","rc":[{"batb":[[0,2.34,30.16],[1,1.03,200],[2,1.02,200]],"ltp":2.42,"tv":56.0,"id":206388}]}]}
{"op":"mcm","clk":"11978506308","pt":1724791074357,"mc":[{"id":"1.232352477","rc":[{"batb":[[0,2.36,5],[1,2.34,30.16],[2,1.03,200]],"ltp":2.42,"tv":56.0,"id":206388}]}]}
{"op":"mcm","clk":"11978506618","pt":1724791077862,"mc":[{"id":"1.232352477","rc":[{"batb":[[0,2.34,30.16],[1,1.03,200],[2,1.02,200]],"ltp":2.42,"tv":56.0,"id":206388}]}]}
{"op":"mcm","clk":"11978506930","pt":1724791081256,"mc":[{"id":"1.232352477","rc":[{"batb":[[0,2.36,5],[1,2.34,30.16],[2,1.03,200]],"ltp":2.42,"tv":56.0,"id":206388}]}]}
{"op":"mcm","clk":"11978507253","pt":1724791084652,"mc":[{"id":"1.232352477","rc":[{"batb":[[0,2.34,30.16],[1,1.03,200],[2,1.02,200]],"ltp":2.42,"tv":56.0,"id":206388}]}]}
{"op":"mcm","clk":"11978507494","pt":1724791087291,"mc":[{"id":"1.232352477","rc":[{"batb":[[0,2.36,5],[1,2.34,30.16],[2,1.03,200]],"ltp":2.42,"tv":56.0,"id":206388}]}]}
{"op":"mcm","clk":"11978507822","pt":1724791090676,"mc":[{"id":"1.232352477","rc":[{"batb":[[0,2.34,30.16],[1,1.03,200],[2,1.02,200]],"ltp":2.42,"tv":56.0,"id":206388}]}]}
{"op":"mcm","clk":"11978508070","pt":1724791093271,"mc":[{"id":"1.232352477","rc":[{"batb":[[0,2.36,5],[1,2.34,30.16],[2,1.03,200]],"ltp":2.42,"tv":56.0,"id":206388}]}]}
{"op":"mcm","clk":"11978508388","pt":1724791096672,"mc":[{"id":"1.232352477","rc":[{"batb":[[0,2.34,30.16],[1,1.03,200],[2,1.02,200]],"ltp":2.42,"tv":56.0,"id":206388}]}]}
{"op":"mcm","clk":"11978508691","pt":1724791100082,"mc":[{"id":"1.232352477","rc":[{"batb":[[0,2.36,5],[1,2.34,30.16],[2,1.03,200]],"ltp":2.42,"tv":56.0,"id":206388}]}]}
{"op":"mcm","clk":"11978509027","pt":1724791103383,"mc":[{"id":"1.232352477","rc":[{"batb":[[0,2.34,30.16],[1,1.03,200],[2,1.02,200]],"ltp":2.42,"tv":56.0,"id":206388}]}]}
{"op":"mcm","clk":"11978509273","pt":1724791106013,"mc":[{"id":"1.232352477","rc":[{"batb":[[0,2.36,5],[1,2.34,30.16],[2,1.03,200]],"ltp":2.42,"tv":56.0,"id":206388}]}]}
{"op":"mcm","clk":"11978509585","pt":1724791109376,"mc":[{"id":"1.232352477","rc":[{"batb":[[0,2.34,30.16],[1,1.03,200],[2,1.02,200]],"ltp":2.42,"tv":56.0,"id":206388}]}]}
{"op":"mcm","clk":"11978509900","pt":1724791112884,"mc":[{"id":"1.232352477","rc":[{"batb":[[0,2.36,5],[1,2.34,30.16],[2,1.03,200]],"ltp":2.42,"tv":56.0,"id":206388}]}]}
{"op":"mcm","clk":"11978510188","pt":1724791116288,"mc":[{"id":"1.232352477","rc":[{"batb":[[0,2.34,30.16],[1,1.03,200],[2,1.02,200]],"ltp":2.42,"tv":56.0,"id":206388}]}]}
{"op":"mcm","clk":"11978510427","pt":1724791119130,"mc":[{"id":"1.232352477","rc":[{"batb":[[0,2.36,5],[1,2.34,30.16],[2,1.03,200]],"ltp":2.42,"tv":56.0,"id":206388}]}]}
{"op":"mcm","clk":"11978510725","pt":1724791122633,"mc":[{"id":"1.232352477","rc":[{"batb":[[0,2.34,30.16],[1,1.03,200],[2,1.02,200]],"ltp":2.42,"tv":56.0,"id":206388}]}]}
{"op":"mcm","clk":"11978510941","pt":1724791125007,"mc":[{"id":"1.232352477","rc":[{"batb":[[0,2.36,5],[1,2.34,30.16],[2,1.03,200]],"ltp":2.42,"tv":56.0,"id":206388}]}]}
{"op":"mcm","clk":"11978511320","pt":1724791128311,"mc":[{"id":"1.232352477","rc":[{"batb":[[0,2.34,30.16],[1,1.03,200],[2,1.02,200]],"ltp":2.42,"tv":56.0,"id":206388}]}]}
{"op":"mcm","clk":"11978511531","pt":1724791130636,"mc":[{"id":"1.232352477","rc":[{"batb":[[0,2.36,5],[1,2.34,30.16],[2,1.03,200]],"ltp":2.42,"tv":56.0,"id":206388}]}]}
{"op":"mcm","clk":"11978511878","pt":1724791134030,"mc":[{"id":"1.232352477","rc":[{"batb":[[0,2.34,30.16],[1,1.03,200],[2,1.02,200]],"ltp":2.42,"tv":56.0,"id":206388}]}]}
{"op":"mcm","clk":"11978512118","pt":1724791136547,"mc":[{"id":"1.232352477","rc":[{"batb":[[0,2.36,5],[1,2.34,30.16],[2,1.03,200]],"ltp":2.42,"tv":56.0,"id":206388}]}]}
{"op":"mcm","clk":"11978512412","pt":1724791139819,"mc":[{"id":"1.232352477","rc":[{"batb":[[0,2.34,30.16],[1,1.03,200],[2,1.02,200]],"ltp":2.42,"tv":56.0,"id":206388}]}]}
{"op":"mcm","clk":"11978512631","pt":1724791142339,"mc":[{"id":"1.232352477","rc":[{"batb":[[0,2.36,5],[1,2.34,30.16],[2,1.03,200]],"ltp":2.42,"tv":56.0,"id":206388}]}]}
{"op":"mcm","clk":"11978512911","pt":1724791145655,"mc":[{"id":"1.232352477","rc":[{"batb":[[0,2.34,30.16],[1,1.03,200],[2,1.02,200]],"ltp":2.42,"tv":56.0,"id":206388}]}]}
{"op":"mcm","clk":"11978513147","pt":1724791148237,"mc":[{"id":"1.232352477","rc":[{"batb":[[0,2.36,5],[1,2.34,30.16],[2,1.03,200]],"ltp":2.42,"tv":56.0,"id":206388}]}]}
{"op":"mcm","clk":"11978513496","pt":1724791151644,"mc":[{"id":"1.232352477","rc":[{"batb":[[0,2.34,30.16],[1,1.03,200],[2,1.02,200]],"ltp":2.42,"tv":56.0,"id":206388}]}]}
{"op":"mcm","clk":"11978513743","pt":1724791154025,"mc":[{"id":"1.232352477","rc":[{"batb":[[0,2.36,5],[1,2.34,30.16],[2,1.03,200]],"ltp":2.42,"tv":56.0,"id":206388}]}]}
{"op":"mcm","clk":"11978514091","pt":1724791157655,"mc":[{"id":"1.232352477","rc":[{"batb":[[0,2.34,30.16],[1,1.03,200],[2,1.02,200]],"ltp":2.42,"tv":56.0,"id":206388}]}]}
{"op":"mcm","clk":"11978514329","pt":1724791160085,"mc":[{"id":"1.232352477","rc":[{"batb":[[0,2.36,5],[1,2.34,30.16],[2,1.03,200]],"ltp":2.42,"tv":56.0,"id":206388}]}]}
{"op":"mcm","clk":"11978514690","pt":1724791163554,"mc":[{"id":"1.232352477","rc":[{"batb":[[0,2.34,30.16],[1,1.03,200],[2,1.02,200]],"ltp":2.42,"tv":56.0,"id":206388}]}]}
{"op":"mcm","clk":"11978515019","pt":1724791166873,"mc":[{"id":"1.232352477","rc":[{"batb":[[0,2.36,5],[1,2.34,30.16],[2,1.03,200]],"ltp":2.42,"tv":56.0,"id":206388}]}]}
{"op":"mcm","clk":"11978515332","pt":1724791170163,"mc":[{"id":"1.232352477","rc":[{"batb":[[0,2.34,30.16],[1,1.03,200],[2,1.02,200]],"ltp":2.42,"tv":56.0,"id":206388}]}]}
{"op":"mcm","clk":"11978515697","pt":1724791173869,"mc":[{"id":"1.232352477","rc":[{"batb":[[0,2.36,5],[1,2.34,30.16],[2,1.03,200]],"ltp":2.42,"tv":56.0,"id":206388}]}]}
{"op":"mcm","clk":"11978516003","pt":1724791177282,"mc":[{"id":"1.232352477","rc":[{"batb":[[0,2.34,30.16],[1,1.03,200],[2,1.02,200]],"ltp":2.42,"tv":56.0,"id":206388}]}]}
{"op":"mcm","clk":"11978516220","pt":1724791179760,"mc":[{"id":"1.232352477","rc":[{"batb":[[0,2.36,5],[1,2.34,30.16],[2,1.03,200]],"ltp":2.42,"tv":56.0,"id":206388}]}]}
{"op":"mcm","clk":"11978516476","pt":1724791183065,"mc":[{"id":"1.232352477","rc":[{"batb":[[0,2.34,30.16],[1,1.03,200],[2,1.02,200]],"ltp":2.42,"tv":56.0,"id":206388}]}]}
{"op":"mcm","clk":"11978516810","pt":1724791187152,"mc":[{"id":"1.232352477","rc":[{"batb":[[0,2.36,5],[1,2.34,30.16],[2,1.03,200]],"ltp":2.42,"tv":56.0,"id":206388}]}]}
{"op":"mcm","clk":"11978517078","pt":1724791190769,"mc":[{"id":"1.232352477","rc":[{"batb":[[0,2.34,30.16],[1,1.03,200],[2,1.02,200]],"ltp":2.42,"tv":56.0,"id":206388}]}]}
{"op":"mcm","clk":"11978517317","pt":1724791193594,"mc":[{"id":"1.232352477","rc":[{"batb":[[0,2.36,5],[1,2.34,30.16],[2,1.03,200]],"ltp":2.42,"tv":56.0,"id":206388}]}]}
{"op":"mcm","clk":"11978517581","pt":1724791196894,"mc":[{"id":"1.232352477","rc":[{"batb":[[0,2.34,30.16],[1,1.03,200],[2,1.02,200]],"ltp":2.42,"tv":56.0,"id":206388}]}]}
{"op":"mcm","clk":"11978517788","pt":1724791199104,"mc":[{"id":"1.232352477","rc":[{"batb":[[0,2.36,5],[1,2.34,30.16],[2,1.03,200]],"ltp":2.42,"tv":56.0,"id":206388}]}]}
{"op":"mcm","clk":"11978518093","pt":1724791202376,"mc":[{"id":"1.232352477","rc":[{"batb":[[0,2.34,30.16],[1,1.03,200],[2,1.02,200]],"ltp":2.42,"tv":56.0,"id":206388}]}]}
{"op":"mcm","clk":"11978518443","pt":1724791206289,"mc":[{"id":"1.232352477","rc":[{"batb":[[0,2.36,5],[1,2.34,30.16],[2,1.03,200]],"ltp":2.42,"tv":56.0,"id":206388}]}]}
{"op":"mcm","clk":"11978518737","pt":1724791209606,"mc":[{"id":"1.232352477","rc":[{"batb":[[0,2.34,30.16],[1,1.03,200],[2,1.02,200]],"ltp":2.42,"tv":56.0,"id":206388}]}]}
{"op":"mcm","clk":"11978519260","pt":1724791214800,"mc":[{"id":"1.232352477","rc":[{"batb":[[0,2.36,5],[1,2.34,30.16],[2,1.03,200]],"ltp":2.42,"tv":56.0,"id":206388}]}]}
{"op":"mcm","clk":"11978519584","pt":1724791218091,"mc":[{"id":"1.232352477","rc":[{"batb":[[0,2.34,30.16],[1,1.03,200],[2,1.02,200]],"ltp":2.42,"tv":56.0,"id":206388}]}]}
{"op":"mcm","clk":"11978519878","pt":1724791221509,"mc":[{"id":"1.232352477","rc":[{"batb":[[0,2.36,5],[1,2.34,30.16],[2,1.03,200]],"ltp":2.42,"tv":56.0,"id":206388}]}]}
{"op":"mcm","clk":"11978520227","pt":1724791224924,"mc":[{"id":"1.232352477","rc":[{"batb":[[0,2.34,30.16],[1,1.03,200],[2,1.02,200]],"ltp":2.42,"tv":56.0,"id":206388}]}]}
{"op":"mcm","clk":"11978520445","pt":1724791227412,"mc":[{"id":"1.232352477","rc":[{"batb":[[0,2.36,5],[1,2.34,30.16],[2,1.03,200]],"ltp":2.42,"tv":56.0,"id":206388}]}]}
{"op":"mcm","clk":"11978520754","pt":1724791230922,"mc":[{"id":"1.232352477","rc":[{"batb":[[0,2.34,30.16],[1,1.03,200],[2,1.02,200]],"ltp":2.42,"tv":56.0,"id":206388}]}]}
{"op":"mcm","clk":"11978521198","pt":1724791236549,"mc":[{"id":"1.232352477","rc":[{"batb":[[0,2.36,5],[1,2.34,30.16],[2,1.03,200]],"ltp":2.42,"tv":56.0,"id":206388}]}]}
{"op":"mcm","clk":"11978521489","pt":1724791239962,"mc":[{"id":"1.232352477","rc":[{"batb":[[0,2.34,30.16],[1,1.03,200],[2,1.02,200]],"ltp":2.42,"tv":56.0,"id":206388}]}]}
{"op":"mcm","clk":"11978521741","pt":1724791242546,"mc":[{"id":"1.232352477","rc":[{"batb":[[0,2.36,5],[1,2.34,30.16],[2,1.03,200]],"ltp":2.42,"tv":56.0,"id":206388}]}]}
{"op":"mcm","clk":"11978522030","pt":1724791246158,"mc":[{"id":"1.232352477","rc":[{"batb":[[0,2.34,30.16],[1,1.03,200],[2,1.02,200]],"ltp":2.42,"tv":56.0,"id":206388}]}]}
{"op":"mcm","clk":"11978522394","pt":1724791250445,"mc":[{"id":"1.232352477","rc":[{"batb":[[0,2.36,5],[1,2.34,30.16],[2,1.03,200]],"ltp":2.42,"tv":56.0,"id":206388}]}]}
{"op":"mcm","clk":"11978522688","pt":1724791253758,"mc":[{"id":"1.232352477","rc":[{"batb":[[0,2.34,30.16],[1,1.03,200],[2,1.02,200]],"ltp":2.42,"tv":56.0,"id":206388}]}]}
{"op":"mcm","clk":"11978523034","pt":1724791257381,"mc":[{"id":"1.232352477","rc":[{"batb":[[0,2.36,5],[1,2.34,30.16],[2,1.03,200]],"ltp":2.42,"tv":56.0,"id":206388}]}]}
{"op":"mcm","clk":"11978523282","pt":1724791260683,"mc":[{"id":"1.232352477","rc":[{"batb":[[0,2.34,30.16],[1,1.03,200],[2,1.02,200]],"ltp":2.42,"tv":56.0,"id":206388}]}]}
{"op":"mcm","clk":"11978523493","pt":1724791263162,"mc":[{"id":"1.232352477","rc":[{"batb":[[0,2.36,5],[1,2.34,30.16],[2,1.03,200]],"ltp":2.42,"tv":56.0,"id":206388}]}]}
{"op":"mcm","clk":"11978523787","pt":1724791266467,"mc":[{"id":"1.232352477","rc":[{"batb":[[0,2.34,30.16],[1,1.03,200],[2,1.02,200]],"ltp":2.42,"tv":56.0,"id":206388}]}]}
{"op":"mcm","clk":"11978524077","pt":1724791269769,"mc":[{"id":"1.232352477","rc":[{"batb":[[0,2.36,5],[1,2.34,30.16],[2,1.03,200]],"ltp":2.42,"tv":56.0,"id":206388}]}]}
{"op":"mcm","clk":"11978524363","pt":1724791273172,"mc":[{"id":"1.232352477","rc":[{"batb":[[0,2.34,30.16],[1,1.03,200],[2,1.02,200]],"ltp":2.42,"tv":56.0,"id":206388}]}]}
{"op":"mcm","clk":"11978524623","pt":1724791276274,"mc":[{"id":"1.232352477","rc":[{"batb":[[0,2.36,5],[1,2.34,30.16],[2,1.03,200]],"ltp":2.42,"tv":56.0,"id":206388}]}]}
{"op":"mcm","clk":"11978524911","pt":1724791279786,"mc":[{"id":"1.232352477","rc":[{"batb":[[0,2.34,30.16],[1,1.03,200],[2,1.02,200]],"ltp":2.42,"tv":56.0,"id":206388}]}]}
{"op":"mcm","clk":"11978525117","pt":1724791282426,"mc":[{"id":"1.232352477","rc":[{"batb":[[0,2.36,5],[1,2.34,30.16],[2,1.03,200]],"ltp":2.42,"tv":56.0,"id":206388}]}]}
{"op":"mcm","clk":"11978525456","pt":1724791285903,"mc":[{"id":"1.232352477","rc":[{"batb":[[0,2.34,30.16],[1,1.03,200],[2,1.02,200]],"ltp":2.42,"tv":56.0,"id":206388}]}]}
{"op":"mcm","clk":"11978525859","pt":1724791290816,"mc":[{"id":"1.232352477","rc":[{"batb":[[0,2.36,5],[1,2.34,30.16],[2,1.03,200]],"ltp":2.42,"tv":56.0,"id":206388}]}]}
{"op":"mcm","clk":"11978526143","pt":1724791294320,"mc":[{"id":"1.232352477","rc":[{"batb":[[0,2.34,30.16],[1,1.03,200],[2,1.02,200]],"ltp":2.42,"tv":56.0,"id":206388}]}]}
{"op":"mcm","clk":"11978526410","pt":1724791297341,"mc":[{"id":"1.232352477","rc":[{"batb":[[0,2.36,5],[1,2.34,30.16],[2,1.03,200]],"ltp":2.42,"tv":56.0,"id":206388}]}]}
{"op":"mcm","clk":"11978526711","pt":1724791300840,"mc":[{"id":"1.232352477","rc":[{"batb":[[0,2.34,30.16],[1,1.03,200],[2,1.02,200]],"ltp":2.42,"tv":56.0,"id":206388}]}]}
{"op":"mcm","clk":"11978527045","pt":1724791304767,"mc":[{"id":"1.232352477","rc":[{"batb":[[0,2.36,5],[1,2.34,30.16],[2,1.03,200]],"ltp":2.42,"tv":56.0,"id":206388}]}]}
{"op":"mcm","clk":"11978527336","pt":1724791308029,"mc":[{"id":"1.232352477","rc":[{"batb":[[0,2.34,30.16],[1,1.03,200],[2,1.02,200]],"ltp":2.42,"tv":56.0,"id":206388}]}]}
{"op":"mcm","clk":"11978527641","pt":1724791311664,"mc":[{"id":"1.232352477","rc":[{"batb":[[0,2.36,5],[1,2.34,30.16],[2,1.03,200]],"ltp":2.42,"tv":56.0,"id":206388}]}]}
{"op":"mcm","clk":"11978527904","pt":1724791314963,"mc":[{"id":"1.232352477","rc":[{"batb":[[0,2.34,30.16],[1,1.03,200],[2,1.02,200]],"ltp":2.42,"tv":56.0,"id":206388}]}]}
{"op":"mcm","clk":"11978528130","pt":1724791317972,"mc":[{"id":"1.232352477","rc":[{"batb":[[0,2.36,5],[1,2.34,30.16],[2,1.03,200]],"ltp":2.42,"tv":56.0,"id":206388}]}]}
{"op":"mcm","clk":"11978528429","pt":1724791321381,"mc":[{"id":"1.232352477","rc":[{"batb":[[0,2.34,30.16],[1,1.03,200],[2,1.02,200]],"ltp":2.42,"tv":56.0,"id":206388}]}]}
{"op":"mcm","clk":"11978528611","pt":1724791323758,"mc":[{"id":"1.232352477","rc":[{"batb":[[0,2.36,5],[1,2.34,30.16],[2,1.03,200]],"ltp":2.42,"tv":56.0,"id":206388}]}]}
{"op":"mcm","clk":"11978528847","pt":1724791327077,"mc":[{"id":"1.232352477","rc":[{"batb":[[0,2.34,30.16],[1,1.03,200],[2,1.02,200]],"ltp":2.42,"tv":56.0,"id":206388}]}]}
{"op":"mcm","clk":"11978529080","pt":1724791329672,"mc":[{"id":"1.232352477","rc":[{"batb":[[0,2.36,5],[1,2.34,30.16],[2,1.03,200]],"ltp":2.42,"tv":56.0,"id":206388}]}]}
{"op":"mcm","clk":"11978529432","pt":1724791333197,"mc":[{"id":"1.232352477","rc":[{"batb":[[0,2.34,30.16],[1,1.03,200],[2,1.02,200]],"ltp":2.42,"tv":56.0,"id":206388}]}]}
{"op":"mcm","clk":"11978529737","pt":1724791336610,"mc":[{"id":"1.232352477","rc":[{"batb":[[0,2.36,5],[1,2.34,30.16],[2,1.03,200]],"ltp":2.42,"tv":56.0,"id":206388}]}]}
{"op":"mcm","clk":"11978530025","pt":1724791339975,"mc":[{"id":"1.232352477","rc":[{"batb":[[0,2.34,30.16],[1,1.03,200],[2,1.02,200]],"ltp":2.42,"tv":56.0,"id":206388}]}]}
{"op":"mcm","clk":"11978530246","pt":1724791342920,"mc":[{"id":"1.232352477","rc":[{"batb":[[0,2.36,5],[1,2.34,30.16],[2,1.03,200]],"ltp":2.42,"tv":56.0,"id":206388}]}]}
{"op":"mcm","clk":"11978530485","pt":1724791346176,"mc":[{"id":"1.232352477","rc":[{"batb":[[0,2.34,30.16],[1,1.03,200],[2,1.02,200]],"ltp":2.42,"tv":56.0,"id":206388}]}]}
{"op":"mcm","clk":"11978530880","pt":1724791351697,"mc":[{"id":"1.232352477","rc":[{"batb":[[0,2.36,5],[1,2.34,30.16],[2,1.03,200]],"ltp":2.42,"tv":56.0,"id":206388}]}]}
{"op":"mcm","clk":"11978531146","pt":1724791355215,"mc":[{"id":"1.232352477","rc":[{"batb":[[0,2.34,30.16],[1,1.03,200],[2,1.02,200]],"ltp":2.42,"tv":56.0,"id":206388}]}]}
{"op":"mcm","clk":"11978531366","pt":1724791357600,"mc":[{"id":"1.232352477","rc":[{"batb":[[0,2.36,5],[1,2.34,30.16],[2,1.03,200]],"ltp":2.42,"tv":56.0,"id":206388}]}]}
{"op":"mcm","clk":"11978531622","pt":1724791361003,"mc":[{"id":"1.232352477","rc":[{"batb":[[0,2.34,30.16],[1,1.03,200],[2,1.02,200]],"ltp":2.42,"tv":56.0,"id":206388}]}]}
{"op":"mcm","clk":"11978531808","pt":1724791363737,"mc":[{"id":"1.232352477","rc":[{"batb":[[0,2.36,5],[1,2.34,30.16],[2,1.03,200]],"ltp":2.42,"tv":56.0,"id":206388}]}]}
{"op":"mcm","clk":"11978532052","pt":1724791367107,"mc":[{"id":"1.232352477","rc":[{"batb":[[0,2.34,30.16],[1,1.03,200],[2,1.02,200]],"ltp":2.42,"tv":56.0,"id":206388}]}]}
{"op":"mcm","clk":"11978532316","pt":1724791370604,"mc":[{"id":"1.232352477","rc":[{"batb":[[0,2.36,5],[1,2.34,30.16],[2,1.03,200]],"ltp":2.42,"tv":56.0,"id":206388}]}]}
{"op":"mcm","clk":"11978532518","pt":1724791373911,"mc":[{"id":"1.232352477","rc":[{"batb":[[0,2.34,30.16],[1,1.03,200],[2,1.02,200]],"ltp":2.42,"tv":56.0,"id":206388}]}]}
{"op":"mcm","clk":"11978532737","pt":1724791377631,"mc":[{"id":"1.232352477","rc":[{"batb":[[0,2.36,5],[1,2.34,30.16],[2,1.03,200]],"ltp":2.42,"tv":56.0,"id":206388}]}]}
{"op":"mcm","clk":"11978532965","pt":1724791380935,"mc":[{"id":"1.232352477","rc":[{"batb":[[0,2.34,30.16],[1,1.03,200],[2,1.02,200]],"ltp":2.42,"tv":56.0,"id":206388}]}]}
{"op":"mcm","clk":"11978533127","pt":1724791383418,"mc":[{"id":"1.232352477","rc":[{"batb":[[0,2.36,5],[1,2.34,30.16],[2,1.03,200]],"ltp":2.42,"tv":56.0,"id":206388}]}]}
{"op":"mcm","clk":"11978533378","pt":1724791386850,"mc":[{"id":"1.232352477","rc":[{"batb":[[0,2.34,30.16],[1,1.03,200],[2,1.02,200]],"ltp":2.42,"tv":56.0,"id":206388}]}]}
{"op":"mcm","clk":"11978533536","pt":1724791389264,"mc":[{"id":"1.232352477","rc":[{"batb":[[0,2.36,5],[1,2.34,30.16],[2,1.03,200]],"ltp":2.42,"tv":56.0,"id":206388}]}]}
{"op":"mcm","clk":"11978533733","pt":1724791392664,"mc":[{"id":"1.232352477","rc":[{"batb":[[0,2.34,30.16],[1,1.03,200],[2,1.02,200]],"ltp":2.42,"tv":56.0,"id":206388}]}]}
{"op":"mcm","clk":"11978533892","pt":1724791395036,"mc":[{"id":"1.232352477","rc":[{"batb":[[0,2.36,5],[1,2.34,30.16],[2,1.03,200]],"ltp":2.42,"tv":56.0,"id":206388}]}]}
{"op":"mcm","clk":"11978534126","pt":1724791398441,"mc":[{"id":"1.232352477","rc":[{"batb":[[0,2.34,30.16],[1,1.03,200],[2,1.02,200]],"ltp":2.42,"tv":56.0,"id":206388}]}]}
{"op":"mcm","clk":"11978534287","pt":1724791400761,"mc":[{"id":"1.232352477","rc":[{"batb":[[0,2.36,5],[1,2.34,30.16],[2,1.03,200]],"ltp":2.42,"tv":56.0,"id":206388}]}]}
{"op":"mcm","clk":"11978534545","pt":1724791404171,"mc":[{"id":"1.232352477","rc":[{"batb":[[0,2.34,30.16],[1,1.03,200],[2,1.02,200]],"ltp":2.42,"tv":56.0,"id":206388}]}]}
{"op":"mcm","clk":"11978534751","pt":1724791407561,"mc":[{"id":"1.232352477","rc":[{"batb":[[0,2.36,5],[1,2.34,30.16],[2,1.03,200]],"ltp":2.42,"tv":56.0,"id":206388}]}]}
{"op":"mcm","clk":"11978534993","pt":1724791410771,"mc":[{"id":"1.232352477","rc":[{"batb":[[0,2.34,30.16],[1,1.03,200],[2,1.02,200]],"ltp":2.42,"tv":56.0,"id":206388}]}]}
{"op":"mcm","clk":"11978535264","pt":1724791414864,"mc":[{"id":"1.232352477","rc":[{"batb":[[0,2.36,5],[1,2.34,30.16],[2,1.03,200]],"ltp":2.42,"tv":56.0,"id":206388}]}]}
{"op":"mcm","clk":"11978535459","pt":1724791418265,"mc":[{"id":"1.232352477","rc":[{"batb":[[0,2.34,30.16],[1,1.03,200],[2,1.02,200]],"ltp":2.42,"tv":56.0,"id":206388}]}]}
{"op":"mcm","clk":"11978535648","pt":1724791420890,"mc":[{"id":"1.232352477","rc":[{"batb":[[0,2.36,5],[1,2.34,30.16],[2,1.03,200]],"ltp":2.42,"tv":56.0,"id":206388}]}]}
{"op":"mcm","clk":"11978535868","pt":1724791424285,"mc":[{"id":"1.232352477","rc":[{"batb":[[0,2.34,30.16],[1,1.03,200],[2,1.02,200]],"ltp":2.42,"tv":56.0,"id":206388}]}]}
{"op":"mcm","clk":"11978536039","pt":1724791426762,"mc":[{"id":"1.232352477","rc":[{"batb":[[0,2.36,5],[1,2.34,30.16],[2,1.03,200]],"ltp":2.42,"tv":56.0,"id":206388}]}]}
{"op":"mcm","clk":"11978536260","pt":1724791430200,"mc":[{"id":"1.232352477","rc":[{"batb":[[0,2.34,30.16],[1,1.03,200],[2,1.02,200]],"ltp":2.42,"tv":56.0,"id":206388}]}]}
{"op":"mcm","clk":"11978536401","pt":1724791432365,"mc":[{"id":"1.232352477","rc":[{"batb":[[0,2.36,5],[1,2.34,30.16],[2,1.03,200]],"ltp":2.42,"tv":56.0,"id":206388}]}]}
{"op":"mcm","clk":"11978536632","pt":1724791435808,"mc":[{"id":"1.232352477","rc":[{"batb":[[0,2.34,30.16],[1,1.03,200],[2,1.02,200]],"ltp":2.42,"tv":56.0,"id":206388}]}]}
{"op":"mcm","clk":"11978536843","pt":1724791438497,"mc":[{"id":"1.232352477","rc":[{"batb":[[0,2.36,5],[1,2.34,30.16],[2,1.03,200]],"ltp":2.42,"tv":56.0,"id":206388}]}]}
{"op":"mcm","clk":"11978537070","pt":1724791441799,"mc":[{"id":"1.232352477","rc":[{"batb":[[0,2.34,30.16],[1,1.03,200],[2,1.02,200]],"ltp":2.42,"tv":56.0,"id":206388}]}]}
{"op":"mcm","clk":"11978537282","pt":1724791444599,"mc":[{"id":"1.232352477","rc":[{"batb":[[0,2.36,5],[1,2.34,30.16],[2,1.03,200]],"ltp":2.42,"tv":56.0,"id":206388}]}]}
{"op":"mcm","clk":"11978537542","pt":1724791447985,"mc":[{"id":"1.232352477","rc":[{"batb":[[0,2.34,30.16],[1,1.03,200],[2,1.02,200]],"ltp":2.42,"tv":56.0,"id":206388}]}]}
{"op":"mcm","clk":"11978537975","pt":1724791454608,"mc":[{"id":"1.232352477","rc":[{"batb":[[0,2.36,5],[1,2.34,30.16],[2,1.03,200]],"ltp":2.42,"tv":56.0,"id":206388}]}]}
{"op":"mcm","clk":"11978538233","pt":1724791458132,"mc":[{"id":"1.232352477","rc":[{"batb":[[0,2.34,30.16],[1,1.03,200],[2,1.02,200]],"ltp":2.42,"tv":56.0,"id":206388}]}]}
{"op":"mcm","clk":"11978538475","pt":1724791461708,"mc":[{"id":"1.232352477","rc":[{"batb":[[0,2.36,5],[1,2.34,30.16],[2,1.03,200]],"ltp":2.42,"tv":56.0,"id":206388}]}]}
{"op":"mcm","clk":"11978538723","pt":1724791465215,"mc":[{"id":"1.232352477","rc":[{"batb":[[0,2.34,30.16],[1,1.03,200],[2,1.02,200]],"ltp":2.42,"tv":56.0,"id":206388}]}]}
{"op":"mcm","clk":"11978538900","pt":1724791468106,"mc":[{"id":"1.232352477","rc":[{"batb":[[0,2.36,5],[1,2.34,30.16],[2,1.03,200]],"ltp":2.42,"tv":56.0,"id":206388}]}]}
{"op":"mcm","clk":"11978539170","pt":1724791471622,"mc":[{"id":"1.232352477","rc":[{"batb":[[0,2.34,30.16],[1,1.03,200],[2,1.02,200]],"ltp":2.42,"tv":56.0,"id":206388}]}]}
{"op":"mcm","clk":"11978539329","pt":1724791474256,"mc":[{"id":"1.232352477","rc":[{"batb":[[0,2.36,5],[1,2.34,30.16],[2,1.03,200]],"ltp":2.42,"tv":56.0,"id":206388}]}]}
{"op":"mcm","clk":"11978539634","pt":1724791477527,"mc":[{"id":"1.232352477","rc":[{"batb":[[0,2.34,30.16],[1,1.03,200],[2,1.02,200]],"ltp":2.42,"tv":56.0,"id":206388}]}]}
{"op":"mcm","clk":"11978539918","pt":1724791480955,"mc":[{"id":"1.232352477","rc":[{"batb":[[0,2.36,5],[1,2.34,30.16],[2,1.03,200]],"ltp":2.42,"tv":56.0,"id":206388}]}]}
{"op":"mcm","clk":"11978540172","pt":1724791484274,"mc":[{"id":"1.232352477","rc":[{"batb":[[0,2.34,30.16],[1,1.03,200],[2,1.02,200]],"ltp":2.42,"tv":56.0,"id":206388}]}]}
{"op":"mcm","clk":"11978540433","pt":1724791487478,"mc":[{"id":"1.232352477","rc":[{"batb":[[0,2.36,5],[1,2.34,30.16],[2,1.03,200]],"ltp":2.42,"tv":56.0,"id":206388}]}]}
{"op":"mcm","clk":"11978540715","pt":1724791490687,"mc":[{"id":"1.232352477","rc":[{"batb":[[0,2.34,30.16],[1,1.03,200],[2,1.02,200]],"ltp":2.42,"tv":56.0,"id":206388}]}]}
{"op":"mcm","clk":"11978540970","pt":1724791493265,"mc":[{"id":"1.232352477","rc":[{"batb":[[0,2.36,5],[1,2.34,30.16],[2,1.03,200]],"ltp":2.42,"tv":56.0,"id":206388}]}]}
{"op":"mcm","clk":"11978541277","pt":1724791496580,"mc":[{"id":"1.232352477","rc":[{"batb":[[0,2.34,30.16],[1,1.03,200],[2,1.02,200]],"ltp":2.42,"tv":56.0,"id":206388}]}]}
{"op":"mcm","clk":"11978541529","pt":1724791499304,"mc":[{"id":"1.232352477","rc":[{"batb":[[0,2.36,5],[1,2.34,30.16],[2,1.03,200]],"ltp":2.42,"tv":56.0,"id":206388}]}]}
{"op":"mcm","clk":"11978541830","pt":1724791502795,"mc":[{"id":"1.232352477","rc":[{"batb":[[0,2.34,30.16],[1,1.03,200],[2,1.02,200]],"ltp":2.42,"tv":56.0,"id":206388}]}]}
{"op":"mcm","clk":"11978541995","pt":1724791505178,"mc":[{"id":"1.232352477","rc":[{"batb":[[0,2.36,5],[1,2.34,30.16],[2,1.03,200]],"ltp":2.42,"tv":56.0,"id":206388}]}]}
{"op":"mcm","clk":"11978542228","pt":1724791508655,"mc":[{"id":"1.232352477","rc":[{"batb":[[0,2.34,30.16],[1,1.03,200],[2,1.02,200]],"ltp":2.42,"tv":56.0,"id":206388}]}]}
{"op":"mcm","clk":"11978542434","pt":1724791511184,"mc":[{"id":"1.232352477","rc":[{"batb":[[0,2.36,5],[1,2.34,30.16],[2,1.03,200]],"ltp":2.42,"tv":56.0,"id":206388}]}]}
{"op":"mcm","clk":"11978542735","pt":1724791514710,"mc":[{"id":"1.232352477","rc":[{"batb":[[0,2.34,30.16],[1,1.03,200],[2,1.02,200]],"ltp":2.42,"tv":56.0,"id":206388}]}]}
{"op":"mcm","clk":"11978542885","pt":1724791516786,"mc":[{"id":"1.232352477","rc":[{"batb":[[0,2.36,5],[1,2.34,30.16],[2,1.03,200]],"ltp":2.42,"tv":56.0,"id":206388}]}]}
{"op":"mcm","clk":"11978543158","pt":1724791520203,"mc":[{"id":"1.232352477","rc":[{"batb":[[0,2.34,30.16],[1,1.03,200],[2,1.02,200]],"ltp":2.42,"tv":56.0,"id":206388}]}]}
{"op":"mcm","clk":"11978543364","pt":1724791522901,"mc":[{"id":"1.232352477","rc":[{"batb":[[0,2.36,5],[1,2.34,30.16],[2,1.03,200]],"ltp":2.42,"tv":56.0,"id":206388}]}]}
{"op":"mcm","clk":"11978543603","pt":1724791526414,"mc":[{"id":"1.232352477","rc":[{"batb":[[0,2.34,30.16],[1,1.03,200],[2,1.02,200]],"ltp":2.42,"tv":56.0,"id":206388}]}]}
{"op":"mcm","clk":"11978543794","pt":1724791528690,"mc":[{"id":"1.232352477","rc":[{"batb":[[0,2.36,5],[1,2.34,30.16],[2,1.03,200]],"ltp":2.42,"tv":56.0,"id":206388}]}]}
{"op":"mcm","clk":"11978544088","pt":1724791532101,"mc":[{"id":"1.232352477","rc":[{"batb":[[0,2.34,30.16],[1,1.03,200],[2,1.02,200]],"ltp":2.42,"tv":56.0,"id":206388}]}]}
{"op":"mcm","clk":"11978544247","pt":1724791534385,"mc":[{"id":"1.232352477","rc":[{"batb":[[0,2.36,5],[1,2.34,30.16],[2,1.03,200]],"ltp":2.42,"tv":56.0,"id":206388}]}]}
{"op":"mcm","clk":"11978544480","pt":1724791537498,"mc":[{"id":"1.232352477","rc":[{"batb":[[0,2.34,30.16],[1,1.03,200],[2,1.02,200]],"ltp":2.42,"tv":56.0,"id":206388}]}]}
{"op":"mcm","clk":"11978544678","pt":1724791540227,"mc":[{"id":"1.232352477","rc":[{"batb":[[0,2.36,5],[1,2.34,30.16],[2,1.03,200]],"ltp":2.42,"tv":56.0,"id":206388}]}]}
{"op":"mcm","clk":"11978544960","pt":1724791543704,"mc":[{"id":"1.232352477","rc":[{"batb":[[0,2.34,30.16],[1,1.03,200],[2,1.02,200]],"ltp":2.42,"tv":56.0,"id":206388}]}]}
{"op":"mcm","clk":"11978545321","pt":1724791548621,"mc":[{"id":"1.232352477","rc":[{"batb":[[0,2.36,5],[1,2.34,30.16],[2,1.03,200]],"ltp":2.42,"tv":56.0,"id":206388}]}]}
{"op":"mcm","clk":"11978545595","pt":1724791552112,"mc":[{"id":"1.232352477","rc":[{"batb":[[0,2.34,30.16],[1,1.03,200],[2,1.02,200]],"ltp":2.42,"tv":56.0,"id":206388}]}]}
{"op":"mcm","clk":"11978545805","pt":1724791554732,"mc":[{"id":"1.232352477","rc":[{"batb":[[0,2.36,5],[1,2.34,30.16],[2,1.03,200]],"ltp":2.42,"tv":56.0,"id":206388}]}]}
{"op":"mcm","clk":"11978546091","pt":1724791558121,"mc":[{"id":"1.232352477","rc":[{"batb":[[0,2.34,30.16],[1,1.03,200],[2,1.02,200]],"ltp":2.42,"tv":56.0,"id":206388}]}]}
{"op":"mcm","clk":"11978546316","pt":1724791560748,"mc":[{"id":"1.232352477","rc":[{"batb":[[0,2.36,5],[1,2.34,30.16],[2,1.03,200]],"ltp":2.42,"tv":56.0,"id":206388}]}]}
{"op":"mcm","clk":"11978546583","pt":1724791564249,"mc":[{"id":"1.232352477","rc":[{"batb":[[0,2.34,30.16],[1,1.03,200],[2,1.02,200]],"ltp":2.42,"tv":56.0,"id":206388}]}]}
{"op":"mcm","clk":"11978546740","pt":1724791566441,"mc":[{"id":"1.232352477","rc":[{"batb":[[0,2.36,5],[1,2.34,30.16],[2,1.03,200]],"ltp":2.42,"tv":56.0,"id":206388}]}]}
{"op":"mcm","clk":"11978546990","pt":1724791569855,"mc":[{"id":"1.232352477","rc":[{"batb":[[0,2.34,30.16],[1,1.03,200],[2,1.02,200]],"ltp":2.42,"tv":56.0,"id":206388}]}]}
{"op":"mcm","clk":"11978547188","pt":1724791572438,"mc":[{"id":"1.232352477","rc":[{"batb":[[0,2.36,5],[1,2.34,30.16],[2,1.03,200]],"ltp":2.42,"tv":56.0,"id":206388}]}]}
{"op":"mcm","clk":"11978547415","pt":1724791575840,"mc":[{"id":"1.232352477","rc":[{"batb":[[0,2.34,30.16],[1,1.03,200],[2,1.02,200]],"ltp":2.42,"tv":56.0,"id":206388}]}]}
{"op":"mcm","clk":"11978547599","pt":1724791578536,"mc":[{"id":"1.232352477","rc":[{"batb":[[0,2.36,5],[1,2.34,30.16],[2,1.03,200]],"ltp":2.42,"tv":56.0,"id":206388}]}]}
{"op":"mcm","clk":"11978547835","pt":1724791582045,"mc":[{"id":"1.232352477","rc":[{"batb":[[0,2.34,30.16],[1,1.03,200],[2,1.02,200]],"ltp":2.42,"tv":56.0,"id":206388}]}]}
{"op":"mcm","clk":"11978548257","pt":1724791588075,"mc":[{"id":"1.232352477","rc":[{"batb":[[0,2.36,5],[1,2.34,30.16],[2,1.03,200]],"ltp":2.42,"tv":56.0,"id":206388}]}]}
{"op":"mcm","clk":"11978548503","pt":1724791591481,"mc":[{"id":"1.232352477","rc":[{"batb":[[0,2.34,30.16],[1,1.03,200],[2,1.02,200]],"ltp":2.42,"tv":56.0,"id":206388}]}]}
{"op":"mcm","clk":"11978548720","pt":1724791594683,"mc":[{"id":"1.232352477","rc":[{"batb":[[0,2.36,5],[1,2.34,30.16],[2,1.03,200]],"ltp":2.42,"tv":56.0,"id":206388}]}]}
{"op":"mcm","clk":"11978548944","pt":1724791598151,"mc":[{"id":"1.232352477","rc":[{"batb":[[0,2.34,30.16],[1,1.03,200],[2,1.02,200]],"ltp":2.42,"tv":56.0,"id":206388}]}]}
{"op":"mcm","clk":"11978549125","pt":1724791600581,"mc":[{"id":"1.232352477","rc":[{"batb":[[0,2.36,5],[1,2.34,30.16],[2,1.03,200]],"ltp":2.42,"tv":56.0,"id":206388}]}]}
{"op":"mcm","clk":"11978549346","pt":1724791603882,"mc":[{"id":"1.232352477","rc":[{"batb":[[0,2.34,30.16],[1,1.03,200],[2,1.02,200]],"ltp":2.42,"tv":56.0,"id":206388}]}]}
{"op":"mcm","clk":"11978549511","pt":1724791606674,"mc":[{"id":"1.232352477","rc":[{"batb":[[0,2.36,5],[1,2.34,30.16],[2,1.03,200]],"ltp":2.42,"tv":56.0,"id":206388}]}]}
{"op":"mcm","clk":"11978549743","pt":1724791609978,"mc":[{"id":"1.232352477","rc":[{"batb":[[0,2.34,30.16],[1,1.03,200],[2,1.02,200]],"ltp":2.42,"tv":56.0,"id":206388}]}]}
{"op":"mcm","clk":"11978549950","pt":1724791612865,"mc":[{"id":"1.232352477","rc":[{"batb":[[0,2.36,5],[1,2.34,30.16],[2,1.03,200]],"ltp":2.42,"tv":56.0,"id":206388}]}]}
{"op":"mcm","clk":"11978550201","pt":1724791616269,"mc":[{"id":"1.232352477","rc":[{"batb":[[0,2.34,30.16],[1,1.03,200],[2,1.02,200]],"ltp":2.42,"tv":56.0,"id":206388}]}]}
{"op":"mcm","clk":"11978550365","pt":1724791618690,"mc":[{"id":"1.232352477","rc":[{"batb":[[0,2.36,5],[1,2.34,30.16],[2,1.03,200]],"ltp":2.42,"tv":56.0,"id":206388}]}]}
{"op":"mcm","clk":"11978550603","pt":1724791622103,"mc":[{"id":"1.232352477","rc":[{"batb":[[0,2.34,30.16],[1,1.03,200],[2,1.02,200]],"ltp":2.42,"tv":56.0,"id":206388}]}]}
{"op":"mcm","clk":"11978550786","pt":1724791624481,"mc":[{"id":"1.232352477","rc":[{"batb":[[0,2.36,5],[1,2.34,30.16],[2,1.03,200]],"ltp":2.42,"tv":56.0,"id":206388}]}]}
{"op":"mcm","clk":"11978551019","pt":1724791627678,"mc":[{"id":"1.232352477","rc":[{"batb":[[0,2.34,30.16],[1,1.03,200],[2,1.02,200]],"ltp":2.42,"tv":56.0,"id":206388}]}]}
{"op":"mcm","clk":"11978551224","pt":1724791630473,"mc":[{"id":"1.232352477","rc":[{"batb":[[0,2.36,5],[1,2.34,30.16],[2,1.03,200]],"ltp":2.42,"tv":56.0,"id":206388}]}]}
{"op":"mcm","clk":"11978551411","pt":1724791633769,"mc":[{"id":"1.232352477","rc":[{"batb":[[0,2.34,30.16],[1,1.03,200],[2,1.02,200]],"ltp":2.42,"tv":56.0,"id":206388}]}]}
{"op":"mcm","clk":"11978551593","pt":1724791636602,"mc":[{"id":"1.232352477","rc":[{"batb":[[0,2.36,5],[1,2.34,30.16],[2,1.03,200]],"ltp":2.42,"tv":56.0,"id":206388}]}]}
{"op":"mcm","clk":"11978551789","pt":1724791639897,"mc":[{"id":"1.232352477","rc":[{"batb":[[0,2.34,30.16],[1,1.03,200],[2,1.02,200]],"ltp":2.42,"tv":56.0,"id":206388}]}]}
{"op":"mcm","clk":"11978551993","pt":1724791642582,"mc":[{"id":"1.232352477","rc":[{"batb":[[0,2.36,5],[1,2.34,30.16],[2,1.03,200]],"ltp":2.42,"tv":56.0,"id":206388}]}]}
{"op":"mcm","clk":"11978552216","pt":1724791645786,"mc":[{"id":"1.232352477","rc":[{"batb":[[0,2.34,30.16],[1,1.03,200],[2,1.02,200]],"ltp":2.42,"tv":56.0,"id":206388}]}]}
{"op":"mcm","clk":"11978552418","pt":1724791648510,"mc":[{"id":"1.232352477","rc":[{"batb":[[0,2.36,5],[1,2.34,30.16],[2,1.03,200]],"ltp":2.42,"tv":56.0,"id":206388}]}]}
{"op":"mcm","clk":"11978552614","pt":1724791651700,"mc":[{"id":"1.232352477","rc":[{"batb":[[0,2.34,30.16],[1,1.03,200],[2,1.02,200]],"ltp":2.42,"tv":56.0,"id":206388}]}]}
{"op":"mcm","clk":"11978552828","pt":1724791655399,"mc":[{"id":"1.232352477","rc":[{"batb":[[0,2.36,5],[1,2.34,30.16],[2,1.03,200]],"ltp":2.42,"tv":56.0,"id":206388}]}]}
{"op":"mcm","clk":"11978553084","pt":1724791658800,"mc":[{"id":"1.232352477","rc":[{"batb":[[0,2.34,30.16],[1,1.03,200],[2,1.02,200]],"ltp":2.42,"tv":56.0,"id":206388}]}]}
{"op":"mcm","clk":"11978553293","pt":1724791661702,"mc":[{"id":"1.232352477","rc":[{"batb":[[0,2.36,5],[1,2.34,30.16],[2,1.03,200]],"ltp":2.42,"tv":56.0,"id":206388}]}]}
{"op":"mcm","clk":"11978553512","pt":1724791665113,"mc":[{"id":"1.232352477","rc":[{"batb":[[0,2.34,30.16],[1,1.03,200],[2,1.02,200]],"ltp":2.42,"tv":56.0,"id":206388}]}]}
{"op":"mcm","clk":"11978553740","pt":1724791667540,"mc":[{"id":"1.232352477","rc":[{"batb":[[0,2.36,5],[1,2.34,30.16],[2,1.03,200]],"ltp":2.42,"tv":56.0,"id":206388}]}]}
{"op":"mcm","clk":"11978553943","pt":1724791670811,"mc":[{"id":"1.232352477","rc":[{"batb":[[0,2.34,30.16],[1,1.03,200],[2,1.02,200]],"ltp":2.42,"tv":56.0,"id":206388}]}]}
{"op":"mcm","clk":"11978554141","pt":1724791673402,"mc":[{"id":"1.232352477","rc":[{"batb":[[0,2.36,5],[1,2.34,30.16],[2,1.03,200]],"ltp":2.42,"tv":56.0,"id":206388}]}]}
{"op":"mcm","clk":"11978554372","pt":1724791676750,"mc":[{"id":"1.232352477","rc":[{"batb":[[0,2.34,30.16],[1,1.03,200],[2,1.02,200]],"ltp":2.42,"tv":56.0,"id":206388}]}]}
{"op":"mcm","clk":"11978554529","pt":1724791679019,"mc":[{"id":"1.232352477","rc":[{"batb":[[0,2.36,5],[1,2.34,30.16],[2,1.03,200]],"ltp":2.42,"tv":56.0,"id":206388}]}]}
{"op":"mcm","clk":"11978554847","pt":1724791682430,"mc":[{"id":"1.232352477","rc":[{"batb":[[0,2.34,30.16],[1,1.03,200],[2,1.02,200]],"ltp":2.42,"tv":56.0,"id":206388}]}]}
{"op":"mcm","clk":"11978555007","pt":1724791684848,"mc":[{"id":"1.232352477","rc":[{"batb":[[0,2.36,5],[1,2.34,30.16],[2,1.03,200]],"ltp":2.42,"tv":56.0,"id":206388}]}]}
{"op":"mcm","clk":"11978555253","pt":1724791688252,"mc":[{"id":"1.232352477","rc":[{"batb":[[0,2.34,30.16],[1,1.03,200],[2,1.02,200]],"ltp":2.42,"tv":56.0,"id":206388}]}]}
{"op":"mcm","clk":"11978555475","pt":1724791691137,"mc":[{"id":"1.232352477","rc":[{"batb":[[0,2.36,5],[1,2.34,30.16],[2,1.03,200]],"ltp":2.42,"tv":56.0,"id":206388}]}]}
{"op":"mcm","clk":"11978555740","pt":1724791694640,"mc":[{"id":"1.232352477","rc":[{"batb":[[0,2.34,30.16],[1,1.03,200],[2,1.02,200]],"ltp":2.42,"tv":56.0,"id":206388}]}]}
{"op":"mcm","clk":"11978555969","pt":1724791697836,"mc":[{"id":"1.232352477","rc":[{"batb":[[0,2.36,5],[1,2.34,30.16],[2,1.03,200]],"ltp":2.42,"tv":56.0,"id":206388}]}]}
{"op":"mcm","clk":"11978556199","pt":1724791701344,"mc":[{"id":"1.232352477","rc":[{"batb":[[0,2.34,30.16],[1,1.03,200],[2,1.02,200]],"ltp":2.42,"tv":56.0,"id":206388}]}]}
{"op":"mcm","clk":"11978556589","pt":1724791706238,"mc":[{"id":"1.232352477","rc":[{"batb":[[0,2.36,5],[1,2.34,30.16],[2,1.03,200]],"ltp":2.42,"tv":56.0,"id":206388}]}]}
{"op":"mcm","clk":"11978556838","pt":1724791709683,"mc":[{"id":"1.232352477","rc":[{"batb":[[0,2.34,30.16],[1,1.03,200],[2,1.02,200]],"ltp":2.42,"tv":56.0,"id":206388}]}]}
{"op":"mcm","clk":"11978557070","pt":1724791712876,"mc":[{"id":"1.232352477","rc":[{"batb":[[0,2.36,5],[1,2.34,30.16],[2,1.03,200]],"ltp":2.42,"tv":56.0,"id":206388}]}]}
{"op":"mcm","clk":"11978557287","pt":1724791716379,"mc":[{"id":"1.232352477","rc":[{"batb":[[0,2.34,30.16],[1,1.03,200],[2,1.02,200]],"ltp":2.42,"tv":56.0,"id":206388}]}]}
{"op":"mcm","clk":"11978557476","pt":1724791719363,"mc":[{"id":"1.232352477","rc":[{"batb":[[0,2.36,5],[1,2.34,30.16],[2,1.03,200]],"ltp":2.42,"tv":56.0,"id":206388}]}]}
{"op":"mcm","clk":"11978557728","pt":1724791722773,"mc":[{"id":"1.232352477","rc":[{"batb":[[0,2.34,30.16],[1,1.03,200],[2,1.02,200]],"ltp":2.42,"tv":56.0,"id":206388}]}]}
{"op":"mcm","clk":"11978557893","pt":1724791725193,"mc":[{"id":"1.232352477","rc":[{"batb":[[0,2.36,5],[1,2.34,30.16],[2,1.03,200]],"ltp":2.42,"tv":56.0,"id":206388}]}]}
{"op":"mcm","clk":"11978558132","pt":1724791728601,"mc":[{"id":"1.232352477","rc":[{"batb":[[0,2.34,30.16],[1,1.03,200],[2,1.02,200]],"ltp":2.42,"tv":56.0,"id":206388}]}]}
{"op":"mcm","clk":"11978558327","pt":1724791731136,"mc":[{"id":"1.232352477","rc":[{"batb":[[0,2.36,5],[1,2.34,30.16],[2,1.03,200]],"ltp":2.42,"tv":56.0,"id":206388}]}]}
{"op":"mcm","clk":"11978558588","pt":1724791734387,"mc":[{"id":"1.232352477","rc":[{"batb":[[0,2.34,30.16],[1,1.03,200],[2,1.02,200]],"ltp":2.42,"tv":56.0,"id":206388}]}]}
{"op":"mcm","clk":"11978558812","pt":1724791737116,"mc":[{"id":"1.232352477","rc":[{"batb":[[0,2.36,5],[1,2.34,30.16],[2,1.03,200]],"ltp":2.42,"tv":56.0,"id":206388}]}]}
{"op":"mcm","clk":"11978559106","pt":1724791740619,"mc":[{"id":"1.232352477","rc":[{"batb":[[0,2.34,30.16],[1,1.03,200],[2,1.02,200]],"ltp":2.42,"tv":56.0,"id":206388}]}]}
{"op":"mcm","clk":"11978559295","pt":1724791743303,"mc":[{"id":"1.232352477","rc":[{"batb":[[0,2.36,5],[1,2.34,30.16],[2,1.03,200]],"ltp":2.42,"tv":56.0,"id":206388}]}]}
{"op":"mcm","clk":"11978559547","pt":1724791746712,"mc":[{"id":"1.232352477","rc":[{"batb":[[0,2.34,30.16],[1,1.03,200],[2,1.02,200]],"ltp":2.42,"tv":56.0,"id":206388}]}]}
{"op":"mcm","clk":"11978559723","pt":1724791749131,"mc":[{"id":"1.232352477","rc":[{"batb":[[0,2.36,5],[1,2.34,30.16],[2,1.03,200]],"ltp":2.42,"tv":56.0,"id":206388}]}]}
{"op":"mcm","clk":"11978559992","pt":1724791752537,"mc":[{"id":"1.232352477","rc":[{"batb":[[0,2.34,30.16],[1,1.03,200],[2,1.02,200]],"ltp":2.42,"tv":56.0,"id":206388}]}]}
{"op":"mcm","clk":"11978560160","pt":1724791755014,"mc":[{"id":"1.232352477","rc":[{"batb":[[0,2.36,5],[1,2.34,30.16],[2,1.03,200]],"ltp":2.42,"tv":56.0,"id":206388}]}]}
{"op":"mcm","clk":"11978560409","pt":1724791758520,"mc":[{"id":"1.232352477","rc":[{"batb":[[0,2.34,30.16],[1,1.03,200],[2,1.02,200]],"ltp":2.42,"tv":56.0,"id":206388}]}]}
{"op":"mcm","clk":"11978560579","pt":1724791761038,"mc":[{"id":"1.232352477","rc":[{"batb":[[0,2.36,5],[1,2.34,30.16],[2,1.03,200]],"ltp":2.42,"tv":56.0,"id":206388}]}]}
{"op":"mcm","clk":"11978560833","pt":1724791764540,"mc":[{"id":"1.232352477","rc":[{"batb":[[0,2.34,30.16],[1,1.03,200],[2,1.02,200]],"ltp":2.42,"tv":56.0,"id":206388}]}]}
{"op":"mcm","clk":"11978561036","pt":1724791767063,"mc":[{"id":"1.232352477","rc":[{"batb":[[0,2.36,5],[1,2.34,30.16],[2,1.03,200]],"ltp":2.42,"tv":56.0,"id":206388}]}]}
{"op":"mcm","clk":"11978561304","pt":1724791770360,"mc":[{"id":"1.232352477","rc":[{"batb":[[0,2.34,30.16],[1,1.03,200],[2,1.02,200]],"ltp":2.42,"tv":56.0,"id":206388}]}]}
{"op":"mcm","clk":"11978561511","pt":1724791773346,"mc":[{"id":"1.232352477","rc":[{"batb":[[0,2.36,5],[1,2.34,30.16],[2,1.03,200]],"ltp":2.42,"tv":56.0,"id":206388}]}]}
{"op":"mcm","clk":"11978561742","pt":1724791776742,"mc":[{"id":"1.232352477","rc":[{"batb":[[0,2.34,30.16],[1,1.03,200],[2,1.02,200]],"ltp":2.42,"tv":56.0,"id":206388}]}]}
{"op":"mcm","clk":"11978561964","pt":1724791779465,"mc":[{"id":"1.232352477","rc":[{"batb":[[0,2.36,5],[1,2.34,30.16],[2,1.03,200]],"ltp":2.42,"tv":56.0,"id":206388}]}]}
{"op":"mcm","clk":"11978562251","pt":1724791782976,"mc":[{"id":"1.232352477","rc":[{"batb":[[0,2.34,30.16],[1,1.03,200],[2,1.02,200]],"ltp":2.42,"tv":56.0,"id":206388}]}]}
{"op":"mcm","clk":"11978562500","pt":1724791786485,"mc":[{"id":"1.232352477","rc":[{"batb":[[0,2.36,5],[1,2.34,30.16],[2,1.03,200]],"ltp":2.42,"tv":56.0,"id":206388}]}]}
{"op":"mcm","clk":"11978562755","pt":1724791789783,"mc":[{"id":"1.232352477","rc":[{"batb":[[0,2.34,30.16],[1,1.03,200],[2,1.02,200]],"ltp":2.42,"tv":56.0,"id":206388}]}]}
{"op":"mcm","clk":"11978562939","pt":1724791792152,"mc":[{"id":"1.232352477","rc":[{"batb":[[0,2.36,5],[1,2.34,30.16],[2,1.03,200]],"ltp":2.42,"tv":56.0,"id":206388}]}]}
{"op":"mcm","clk":"11978563203","pt":1724791795501,"mc":[{"id":"1.232352477","rc":[{"batb":[[0,2.34,30.16],[1,1.03,200],[2,1.02,200]],"ltp":2.42,"tv":56.0,"id":206388}]}]}
{"op":"mcm","clk":"11978563452","pt":1724791798700,"mc":[{"id":"1.232352477","rc":[{"batb":[[0,2.36,5],[1,2.34,30.16],[2,1.03,200]],"ltp":2.42,"tv":56.0,"id":206388}]}]}
{"op":"mcm","clk":"11978563714","pt":1724791802105,"mc":[{"id":"1.232352477","rc":[{"batb":[[0,2.34,30.16],[1,1.03,200],[2,1.02,200]],"ltp":2.42,"tv":56.0,"id":206388}]}]}
{"op":"mcm","clk":"11978563904","pt":1724791804895,"mc":[{"id":"1.232352477","rc":[{"batb":[[0,2.36,5],[1,2.34,30.16],[2,1.03,200]],"ltp":2.42,"tv":56.0,"id":206388}]}]}
{"op":"mcm","clk":"11978564131","pt":1724791808298,"mc":[{"id":"1.232352477","rc":[{"batb":[[0,2.34,30.16],[1,1.03,200],[2,1.02,200]],"ltp":2.42,"tv":56.0,"id":206388}]}]}
{"op":"mcm","clk":"11978564358","pt":1724791811704,"mc":[{"id":"1.232352477","rc":[{"batb":[[0,2.36,5],[1,2.34,30.16],[2,1.03,200]],"ltp":2.42,"tv":56.0,"id":206388}]}]}
{"op":"mcm","clk":"11978564589","pt":1724791815020,"mc":[{"id":"1.232352477","rc":[{"batb":[[0,2.34,30.16],[1,1.03,200],[2,1.02,200]],"ltp":2.42,"tv":56.0,"id":206388}]}]}
{"op":"mcm","clk":"11978564797","pt":1724791817929,"mc":[{"id":"1.232352477","rc":[{"batb":[[0,2.36,5],[1,2.34,30.16],[2,1.03,200]],"ltp":2.42,"tv":56.0,"id":206388}]}]}
{"op":"mcm","clk":"11978565019","pt":1724791821232,"mc":[{"id":"1.232352477","rc":[{"batb":[[0,2.34,30.16],[1,1.03,200],[2,1.02,200]],"ltp":2.42,"tv":56.0,"id":206388}]}]}
{"op":"mcm","clk":"11978565209","pt":1724791823921,"mc":[{"id":"1.232352477","rc":[{"batb":[[0,2.36,5],[1,2.34,30.16],[2,1.03,200]],"ltp":2.42,"tv":56.0,"id":206388}]}]}
{"op":"mcm","clk":"11978565423","pt":1724791827312,"mc":[{"id":"1.232352477","rc":[{"batb":[[0,2.34,30.16],[1,1.03,200],[2,1.02,200]],"ltp":2.42,"tv":56.0,"id":206388}]}]}
{"op":"mcm","clk":"11978565589","pt":1724791829940,"mc":[{"id":"1.232352477","rc":[{"batb":[[0,2.36,5],[1,2.34,30.16],[2,1.03,200]],"ltp":2.42,"tv":56.0,"id":206388}]}]}
{"op":"mcm","clk":"11978565820","pt":1724791833339,"mc":[{"id":"1.232352477","rc":[{"batb":[[0,2.34,30.16],[1,1.03,200],[2,1.02,200]],"ltp":2.42,"tv":56.0,"id":206388}]}]}
{"op":"mcm","clk":"11978566000","pt":1724791835920,"mc":[{"id":"1.232352477","rc":[{"batb":[[0,2.36,5],[1,2.34,30.16],[2,1.03,200]],"ltp":2.42,"tv":56.0,"id":206388}]}]}
{"op":"mcm","clk":"11978566260","pt":1724791839323,"mc":[{"id":"1.232352477","rc":[{"batb":[[0,2.34,30.16],[1,1.03,200],[2,1.02,200]],"ltp":2.42,"tv":56.0,"id":206388}]}]}
{"op":"mcm","clk":"11978566428","pt":1724791841740,"mc":[{"id":"1.232352477","rc":[{"batb":[[0,2.36,5],[1,2.34,30.16],[2,1.03,200]],"ltp":2.42,"tv":56.0,"id":206388}]}]}
{"op":"mcm","clk":"11978566685","pt":1724791845251,"mc":[{"id":"1.232352477","rc":[{"batb":[[0,2.34,30.16],[1,1.03,200],[2,1.02,200]],"ltp":2.42,"tv":56.0,"id":206388}]}]}
{"op":"mcm","clk":"11978566817","pt":1724791847465,"mc":[{"id":"1.232352477","rc":[{"batb":[[0,2.36,5],[1,2.34,30.16],[2,1.03,200]],"ltp":2.42,"tv":56.0,"id":206388}]}]}
{"op":"mcm","clk":"11978567050","pt":1724791850857,"mc":[{"id":"1.232352477","rc":[{"batb":[[0,2.34,30.16],[1,1.03,200],[2,1.02,200]],"ltp":2.42,"tv":56.0,"id":206388}]}]}
{"op":"mcm","clk":"11978567240","pt":1724791853943,"mc":[{"id":"1.232352477","rc":[{"batb":[[0,2.36,5],[1,2.34,30.16],[2,1.03,200]],"ltp":2.42,"tv":56.0,"id":206388}]}]}
{"op":"mcm","clk":"11978567467","pt":1724791857343,"mc":[{"id":"1.232352477","rc":[{"batb":[[0,2.34,30.16],[1,1.03,200],[2,1.02,200]],"ltp":2.42,"tv":56.0,"id":206388}]}]}
{"op":"mcm","clk":"11978567665","pt":1724791859975,"mc":[{"id":"1.232352477","rc":[{"batb":[[0,2.36,5],[1,2.34,30.16],[2,1.03,200]],"ltp":2.42,"tv":56.0,"id":206388}]}]}
{"op":"mcm","clk":"11978567931","pt":1724791863479,"mc":[{"id":"1.232352477","rc":[{"batb":[[0,2.34,30.16],[1,1.03,200],[2,1.02,200]],"ltp":2.42,"tv":56.0,"id":206388}]}]}
{"op":"mcm","clk":"11978568113","pt":1724791865970,"mc":[{"id":"1.232352477","rc":[{"batb":[[0,2.36,5],[1,2.34,30.16],[2,1.03,200]],"ltp":2.42,"tv":56.0,"id":206388}]}]}
{"op":"mcm","clk":"11978568354","pt":1724791869166,"mc":[{"id":"1.232352477","rc":[{"batb":[[0,2.34,30.16],[1,1.03,200],[2,1.02,200]],"ltp":2.42,"tv":56.0,"id":206388}]}]}
{"op":"mcm","clk":"11978568596","pt":1724791872870,"mc":[{"id":"1.232352477","rc":[{"batb":[[0,2.36,5],[1,2.34,30.16],[2,1.03,200]],"ltp":2.42,"tv":56.0,"id":206388}]}]}
{"op":"mcm","clk":"11978569038","pt":1724791878598,"mc":[{"id":"1.232352477","rc":[{"batb":[[0,2.34,30.16],[1,1.03,200],[2,1.02,200]],"ltp":2.42,"tv":56.0,"id":206388}]}]}
{"op":"mcm","clk":"11978569282","pt":1724791881590,"mc":[{"id":"1.232352477","rc":[{"batb":[[0,2.36,5],[1,2.34,30.16],[2,1.03,200]],"ltp":2.42,"tv":56.0,"id":206388}]}]}
{"op":"mcm","clk":"11978569615","pt":1724791885434,"mc":[{"id":"1.232352477","rc":[{"batb":[[0,2.34,30.16],[1,1.03,200],[2,1.02,200]],"ltp":2.42,"tv":56.0,"id":206388}]}]}
{"op":"mcm","clk":"11978569827","pt":1724791888081,"mc":[{"id":"1.232352477","rc":[{"batb":[[0,2.36,5],[1,2.34,30.16],[2,1.03,200]],"ltp":2.42,"tv":56.0,"id":206388}]}]}
{"op":"mcm","clk":"11978570123","pt":1724791891687,"mc":[{"id":"1.232352477","rc":[{"batb":[[0,2.34,30.16],[1,1.03,200],[2,1.02,200]],"ltp":2.42,"tv":56.0,"id":206388}]}]}
{"op":"mcm","clk":"11978570361","pt":1724791894117,"mc":[{"id":"1.232352477","rc":[{"batb":[[0,2.36,5],[1,2.34,30.16],[2,1.03,200]],"ltp":2.42,"tv":56.0,"id":206388}]}]}
{"op":"mcm","clk":"11978570681","pt":1724791897416,"mc":[{"id":"1.232352477","rc":[{"batb":[[0,2.34,30.16],[1,1.03,200],[2,1.02,200]],"ltp":2.42,"tv":56.0,"id":206388}]}]}
{"op":"mcm","clk":"11978570848","pt":1724791899893,"mc":[{"id":"1.232352477","rc":[{"batb":[[0,2.36,5],[1,2.34,30.16],[2,1.03,200]],"ltp":2.42,"tv":56.0,"id":206388}]}]}
{"op":"mcm","clk":"11978571119","pt":1724791903406,"mc":[{"id":"1.232352477","rc":[{"batb":[[0,2.34,30.16],[1,1.03,200],[2,1.02,200]],"ltp":2.42,"tv":56.0,"id":206388}]}]}
{"op":"mcm","clk":"11978571327","pt":1724791906002,"mc":[{"id":"1.232352477","rc":[{"batb":[[0,2.36,5],[1,2.34,30.16],[2,1.03,200]],"ltp":2.42,"tv":56.0,"id":206388}]}]}
{"op":"mcm","clk":"11978571599","pt":1724791909310,"mc":[{"id":"1.232352477","rc":[{"batb":[[0,2.34,30.16],[1,1.03,200],[2,1.02,200]],"ltp":2.42,"tv":56.0,"id":206388}]}]}
{"op":"mcm","clk":"11978571814","pt":1724791912209,"mc":[{"id":"1.232352477","rc":[{"batb":[[0,2.36,5],[1,2.34,30.16],[2,1.03,200]],"ltp":2.42,"tv":56.0,"id":206388}]}]}
{"op":"mcm","clk":"11978572078","pt":1724791915724,"mc":[{"id":"1.232352477","rc":[{"batb":[[0,2.34,30.16],[1,1.03,200],[2,1.02,200]],"ltp":2.42,"tv":56.0,"id":206388}]}]}
{"op":"mcm","clk":"11978572289","pt":1724791918165,"mc":[{"id":"1.232352477","rc":[{"batb":[[0,2.36,5],[1,2.34,30.16],[2,1.03,200]],"ltp":2.42,"tv":56.0,"id":206388}]}]}
{"op":"mcm","clk":"11978572555","pt":1724791921720,"mc":[{"id":"1.232352477","rc":[{"batb":[[0,2.34,30.16],[1,1.03,200],[2,1.02,200]],"ltp":2.42,"tv":56.0,"id":206388}]}]}
{"op":"mcm","clk":"11978572728","pt":1724791923953,"mc":[{"id":"1.232352477","rc":[{"batb":[[0,2.36,5],[1,2.34,30.16],[2,1.03,200]],"ltp":2.42,"tv":56.0,"id":206388}]}]}
{"op":"mcm","clk":"11978572976","pt":1724791927445,"mc":[{"id":"1.232352477","rc":[{"batb":[[0,2.34,30.16],[1,1.03,200],[2,1.02,200]],"ltp":2.42,"tv":56.0,"id":206388}]}]}
{"op":"mcm","clk":"11978573144","pt":1724791929664,"mc":[{"id":"1.232352477","rc":[{"batb":[[0,2.36,5],[1,2.34,30.16],[2,1.03,200]],"ltp":2.42,"tv":56.0,"id":206388}]}]}
{"op":"mcm","clk":"11978573392","pt":1724791933070,"mc":[{"id":"1.232352477","rc":[{"batb":[[0,2.34,30.16],[1,1.03,200],[2,1.02,200]],"ltp":2.42,"tv":56.0,"id":206388}]}]}
{"op":"mcm","clk":"11978573551","pt":1724791935650,"mc":[{"id":"1.232352477","rc":[{"batb":[[0,2.36,5],[1,2.34,30.16],[2,1.03,200]],"ltp":2.42,"tv":56.0,"id":206388}]}]}
{"op":"mcm","clk":"11978573825","pt":1724791939064,"mc":[{"id":"1.232352477","rc":[{"batb":[[0,2.34,30.16],[1,1.03,200],[2,1.02,200]],"ltp":2.42,"tv":56.0,"id":206388}]}]}
{"op":"mcm","clk":"11978574116","pt":1724791942875,"mc":[{"id":"1.232352477","rc":[{"batb":[[0,2.36,5],[1,2.34,30.16],[2,1.03,200]],"ltp":2.42,"tv":56.0,"id":206388}]}]}
{"op":"mcm","clk":"11978574342","pt":1724791946167,"mc":[{"id":"1.232352477","rc":[{"batb":[[0,2.34,30.16],[1,1.03,200],[2,1.02,200]],"ltp":2.42,"tv":56.0,"id":206388}]}]}
{"op":"mcm","clk":"11978574618","pt":1724791949894,"mc":[{"id":"1.232352477","rc":[{"batb":[[0,2.36,5],[1,2.34,30.16],[2,1.03,200]],"ltp":2.42,"tv":56.0,"id":206388}]}]}
{"op":"mcm","clk":"11978574872","pt":1724791953184,"mc":[{"id":"1.232352477","rc":[{"batb":[[0,2.34,30.16],[1,1.03,200],[2,1.02,200]],"ltp":2.42,"tv":56.0,"id":206388}]}]}
{"op":"mcm","clk":"11978575112","pt":1724791956278,"mc":[{"id":"1.232352477","rc":[{"batb":[[0,2.36,5],[1,2.34,30.16],[2,1.03,200]],"ltp":2.42,"tv":56.0,"id":206388}]}]}
{"op":"mcm","clk":"11978575335","pt":1724791959584,"mc":[{"id":"1.232352477","rc":[{"batb":[[0,2.34,30.16],[1,1.03,200],[2,1.02,200]],"ltp":2.42,"tv":56.0,"id":206388}]}]}
{"op":"mcm","clk":"11978575653","pt":1724791964061,"mc":[{"id":"1.232352477","rc":[{"batb":[[0,2.36,5],[1,2.34,30.16],[2,1.03,200]],"ltp":2.42,"tv":56.0,"id":206388}]}]}
{"op":"mcm","clk":"11978575909","pt":1724791967483,"mc":[{"id":"1.232352477","rc":[{"batb":[[0,2.34,30.16],[1,1.03,200],[2,1.02,200]],"ltp":2.42,"tv":56.0,"id":206388}]}]}
{"op":"mcm","clk":"11978576165","pt":1724791970986,"mc":[{"id":"1.232352477","rc":[{"batb":[[0,2.36,5],[1,2.34,30.16],[2,1.03,200]],"ltp":2.42,"tv":56.0,"id":206388}]}]}
{"op":"mcm","clk":"11978576431","pt":1724791974487,"mc":[{"id":"1.232352477","rc":[{"batb":[[0,2.34,30.16],[1,1.03,200],[2,1.02,200]],"ltp":2.42,"tv":56.0,"id":206388}]}]}
{"op":"mcm","clk":"11978576605","pt":1724791977108,"mc":[{"id":"1.232352477","rc":[{"batb":[[0,2.36,5],[1,2.34,30.16],[2,1.03,200]],"ltp":2.42,"tv":56.0,"id":206388}]}]}
{"op":"mcm","clk":"11978576830","pt":1724791980614,"mc":[{"id":"1.232352477","rc":[{"batb":[[0,2.34,30.16],[1,1.03,200],[2,1.02,200]],"ltp":2.42,"tv":56.0,"id":206388}]}]}
{"op":"mcm","clk":"11978577135","pt":1724791985311,"mc":[{"id":"1.232352477","rc":[{"batb":[[0,2.36,5],[1,2.34,30.16],[2,1.03,200]],"ltp":2.42,"tv":56.0,"id":206388}]}]}
{"op":"mcm","clk":"11978577362","pt":1724791988706,"mc":[{"id":"1.232352477","rc":[{"batb":[[0,2.34,30.16],[1,1.03,200],[2,1.02,200]],"ltp":2.42,"tv":56.0,"id":206388}]}]}
{"op":"mcm","clk":"11978577573","pt":1724791991743,"mc":[{"id":"1.232352477","rc":[{"batb":[[0,2.36,5],[1,2.34,30.16],[2,1.03,200]],"ltp":2.42,"tv":56.0,"id":206388}]}]}
{"op":"mcm","clk":"11978577846","pt":1724791995014,"mc":[{"id":"1.232352477","rc":[{"batb":[[0,2.34,30.16],[1,1.03,200],[2,1.02,200]],"ltp":2.42,"tv":56.0,"id":206388}]}]}
{"op":"mcm","clk":"11978578057","pt":1724791997749,"mc":[{"id":"1.232352477","rc":[{"batb":[[0,2.36,5],[1,2.34,30.16],[2,1.03,200]],"ltp":2.42,"tv":56.0,"id":206388}]}]}
{"op":"mcm","clk":"11978578299","pt":1724792001147,"mc":[{"id":"1.232352477","rc":[{"batb":[[0,2.34,30.16],[1,1.03,200],[2,1.02,200]],"ltp":2.42,"tv":56.0,"id":206388}]}]}
{"op":"mcm","clk":"11978578473","pt":1724792003832,"mc":[{"id":"1.232352477","rc":[{"batb":[[0,2.36,5],[1,2.34,30.16],[2,1.03,200]],"ltp":2.42,"tv":56.0,"id":206388}]}]}
{"op":"mcm","clk":"11978578697","pt":1724792007330,"mc":[{"id":"1.232352477","rc":[{"batb":[[0,2.34,30.16],[1,1.03,200],[2,1.02,200]],"ltp":2.42,"tv":56.0,"id":206388}]}]}
{"op":"mcm","clk":"11978578961","pt":1724792011549,"mc":[{"id":"1.232352477","rc":[{"batb":[[0,2.36,5],[1,2.34,30.16],[2,1.03,200]],"ltp":2.42,"tv":56.0,"id":206388}]}]}
{"op":"mcm","clk":"11978579184","pt":1724792014856,"mc":[{"id":"1.232352477","rc":[{"batb":[[0,2.34,30.16],[1,1.03,200],[2,1.02,200]],"ltp":2.42,"tv":56.0,"id":206388}]}]}
{"op":"mcm","clk":"11978579400","pt":1724792017755,"mc":[{"id":"1.232352477","rc":[{"batb":[[0,2.36,5],[1,2.34,30.16],[2,1.03,200]],"ltp":2.42,"tv":56.0,"id":206388}]}]}
{"op":"mcm","clk":"11978579668","pt":1724792021252,"mc":[{"id":"1.232352477","rc":[{"batb":[[0,2.34,30.16],[1,1.03,200],[2,1.02,200]],"ltp":2.42,"tv":56.0,"id":206388}]}]}
{"op":"mcm","clk":"11978579834","pt":1724792023879,"mc":[{"id":"1.232352477","rc":[{"batb":[[0,2.36,5],[1,2.34,30.16],[2,1.03,200]],"ltp":2.42,"tv":56.0,"id":206388}]}]}
{"op":"mcm","clk":"11978580064","pt":1724792027176,"mc":[{"id":"1.232352477","rc":[{"batb":[[0,2.34,30.16],[1,1.03,200],[2,1.02,200]],"ltp":2.42,"tv":56.0,"id":206388}]}]}
{"op":"mcm","clk":"11978580362","pt":1724792031151,"mc":[{"id":"1.232352477","rc":[{"batb":[[0,2.36,5],[1,2.34,30.16],[2,1.03,200]],"ltp":2.42,"tv":56.0,"id":206388}]}]}
{"op":"mcm","clk":"11978580583","pt":1724792034592,"mc":[{"id":"1.232352477","rc":[{"batb":[[0,2.34,30.16],[1,1.03,200],[2,1.02,200]],"ltp":2.42,"tv":56.0,"id":206388}]}]}
{"op":"mcm","clk":"11978580756","pt":1724792037088,"mc":[{"id":"1.232352477","rc":[{"batb":[[0,2.36,5],[1,2.34,30.16],[2,1.03,200]],"ltp":2.42,"tv":56.0,"id":206388}]}]}
{"op":"mcm","clk":"11978580996","pt":1724792040595,"mc":[{"id":"1.232352477","rc":[{"batb":[[0,2.34,30.16],[1,1.03,200],[2,1.02,200]],"ltp":2.42,"tv":56.0,"id":206388}]}]}
{"op":"mcm","clk":"11978581139","pt":1724792042658,"mc":[{"id":"1.232352477","rc":[{"batb":[[0,2.36,5],[1,2.34,30.16],[2,1.03,200]],"ltp":2.42,"tv":56.0,"id":206388}]}]}
{"op":"mcm","clk":"11978581359","pt":1724792045981,"mc":[{"id":"1.232352477","rc":[{"batb":[[0,2.34,30.16],[1,1.03,200],[2,1.02,200]],"ltp":2.42,"tv":56.0,"id":206388}]}]}
{"op":"mcm","clk":"11978581526","pt":1724792048562,"mc":[{"id":"1.232352477","rc":[{"batb":[[0,2.36,5],[1,2.34,30.16],[2,1.03,200]],"ltp":2.42,"tv":56.0,"id":206388}]}]}
{"op":"mcm","clk":"11978581786","pt":1724792052111,"mc":[{"id":"1.232352477","rc":[{"batb":[[0,2.34,30.16],[1,1.03,200],[2,1.02,200]],"ltp":2.42,"tv":56.0,"id":206388}]}]}
{"op":"mcm","clk":"11978582075","pt":1724792056498,"mc":[{"id":"1.232352477","rc":[{"batb":[[0,2.36,5],[1,2.34,30.16],[2,1.03,200]],"ltp":2.42,"tv":56.0,"id":206388}]}]}
{"op":"mcm","clk":"11978582306","pt":1724792059693,"mc":[{"id":"1.232352477","rc":[{"batb":[[0,2.34,30.16],[1,1.03,200],[2,1.02,200]],"ltp":2.42,"tv":56.0,"id":206388}]}]}
{"op":"mcm","clk":"11978582483","pt":1724792062220,"mc":[{"id":"1.232352477","rc":[{"batb":[[0,2.36,5],[1,2.34,30.16],[2,1.03,200]],"ltp":2.42,"tv":56.0,"id":206388}]}]}
{"op":"mcm","clk":"11978582672","pt":1724792065411,"mc":[{"id":"1.232352477","rc":[{"batb":[[0,2.34,30.16],[1,1.03,200],[2,1.02,200]],"ltp":2.42,"tv":56.0,"id":206388}]}]}
{"op":"mcm","clk":"11978582850","pt":1724792068190,"mc":[{"id":"1.232352477","rc":[{"batb":[[0,2.36,5],[1,2.34,30.16],[2,1.03,200]],"ltp":2.42,"tv":56.0,"id":206388}]}]}
{"op":"mcm","clk":"11978583056","pt":1724792071527,"mc":[{"id":"1.232352477","rc":[{"batb":[[0,2.34,30.16],[1,1.03,200],[2,1.02,200]],"ltp":2.42,"tv":56.0,"id":206388}]}]}
{"op":"mcm","clk":"11978583267","pt":1724792074615,"mc":[{"id":"1.232352477","rc":[{"batb":[[0,2.36,5],[1,2.34,30.16],[2,1.03,200]],"ltp":2.42,"tv":56.0,"id":206388}]}]}
{"op":"mcm","clk":"11978583503","pt":1724792078102,"mc":[{"id":"1.232352477","rc":[{"batb":[[0,2.34,30.16],[1,1.03,200],[2,1.02,200]],"ltp":2.42,"tv":56.0,"id":206388}]}]}
{"op":"mcm","clk":"11978583605","pt":1724792080310,"mc":[{"id":"1.232352477","rc":[{"batb":[[0,2.36,5],[1,2.34,30.16],[2,1.03,200]],"ltp":2.42,"tv":56.0,"id":206388}]}]}
{"op":"mcm","clk":"11978583787","pt":1724792083825,"mc":[{"id":"1.232352477","rc":[{"batb":[[0,2.34,30.16],[1,1.03,200],[2,1.02,200]],"ltp":2.42,"tv":56.0,"id":206388}]}]}
{"op":"mcm","clk":"11978583906","pt":1724792086137,"mc":[{"id":"1.232352477","rc":[{"batb":[[0,2.36,5],[1,2.34,30.16],[2,1.03,200]],"ltp":2.42,"tv":56.0,"id":206388}]}]}
{"op":"mcm","clk":"11978584106","pt":1724792089531,"mc":[{"id":"1.232352477","rc":[{"batb":[[0,2.34,30.16],[1,1.03,200],[2,1.02,200]],"ltp":2.42,"tv":56.0,"id":206388}]}]}
{"op":"mcm","clk":"11978584251","pt":1724792091948,"mc":[{"id":"1.232352477","rc":[{"batb":[[0,2.36,5],[1,2.34,30.16],[2,1.03,200]],"ltp":2.42,"tv":56.0,"id":206388}]}]}
{"op":"mcm","clk":"11978584431","pt":1724792095234,"mc":[{"id":"1.232352477","rc":[{"batb":[[0,2.34,30.16],[1,1.03,200],[2,1.02,200]],"ltp":2.42,"tv":56.0,"id":206388}]}]}
{"op":"mcm","clk":"11978584586","pt":1724792098158,"mc":[{"id":"1.232352477","rc":[{"batb":[[0,2.36,5],[1,2.34,30.16],[2,1.03,200]],"ltp":2.42,"tv":56.0,"id":206388}]}]}
{"op":"mcm","clk":"11978584774","pt":1724792101352,"mc":[{"id":"1.232352477","rc":[{"batb":[[0,2.34,30.16],[1,1.03,200],[2,1.02,200]],"ltp":2.42,"tv":56.0,"id":206388}]}]}
{"op":"mcm","clk":"11978584902","pt":1724792103521,"mc":[{"id":"1.232352477","rc":[{"batb":[[0,2.36,5],[1,2.34,30.16],[2,1.03,200]],"ltp":2.42,"tv":56.0,"id":206388}]}]}
{"op":"mcm","clk":"11978585092","pt":1724792106868,"mc":[{"id":"1.232352477","rc":[{"batb":[[0,2.34,30.16],[1,1.03,200],[2,1.02,200]],"ltp":2.42,"tv":56.0,"id":206388}]}]}
{"op":"mcm","clk":"11978585206","pt":1724792108935,"mc":[{"id":"1.232352477","rc":[{"batb":[[0,2.36,5],[1,2.34,30.16],[2,1.03,200]],"ltp":2.42,"tv":56.0,"id":206388}]}]}
{"op":"mcm","clk":"11978585443","pt":1724792112330,"mc":[{"id":"1.232352477","rc":[{"batb":[[0,2.34,30.16],[1,1.03,200],[2,1.02,200]],"ltp":2.42,"tv":56.0,"id":206388}]}]}
{"op":"mcm","clk":"11978585579","pt":1724792114745,"mc":[{"id":"1.232352477","rc":[{"batb":[[0,2.36,5],[1,2.34,30.16],[2,1.03,200]],"ltp":2.42,"tv":56.0,"id":206388}]}]}
{"op":"mcm","clk":"11978585774","pt":1724792117937,"mc":[{"id":"1.232352477","rc":[{"batb":[[0,2.34,30.16],[1,1.03,200],[2,1.02,200]],"ltp":2.42,"tv":56.0,"id":206388}]}]}
{"op":"mcm","clk":"11978585989","pt":1724792121579,"mc":[{"id":"1.232352477","rc":[{"batb":[[0,2.36,5],[1,2.34,30.16],[2,1.03,200]],"ltp":2.42,"tv":56.0,"id":206388}]}]}
{"op":"mcm","clk":"11978586187","pt":1724792124877,"mc":[{"id":"1.232352477","rc":[{"batb":[[0,2.34,30.16],[1,1.03,200],[2,1.02,200]],"ltp":2.42,"tv":56.0,"id":206388}]}]}
{"op":"mcm","clk":"11978586350","pt":1724792127555,"mc":[{"id":"1.232352477","rc":[{"batb":[[0,2.36,5],[1,2.34,30.16],[2,1.03,200]],"ltp":2.42,"tv":56.0,"id":206388}]}]}
{"op":"mcm","clk":"11978586538","pt":1724792130950,"mc":[{"id":"1.232352477","rc":[{"batb":[[0,2.34,30.16],[1,1.03,200],[2,1.02,200]],"ltp":2.42,"tv":56.0,"id":206388}]}]}
{"op":"mcm","clk":"11978586652","pt":1724792133164,"mc":[{"id":"1.232352477","rc":[{"batb":[[0,2.36,5],[1,2.34,30.16],[2,1.03,200]],"ltp":2.42,"tv":56.0,"id":206388}]}]}
{"op":"mcm","clk":"11978586862","pt":1724792136455,"mc":[{"id":"1.232352477","rc":[{"batb":[[0,2.34,30.16],[1,1.03,200],[2,1.02,200]],"ltp":2.42,"tv":56.0,"id":206388}]}]}
{"op":"mcm","clk":"11978587049","pt":1724792139187,"mc":[{"id":"1.232352477","rc":[{"batb":[[0,2.36,5],[1,2.34,30.16],[2,1.03,200]],"ltp":2.42,"tv":56.0,"id":206388}]}]}
{"op":"mcm","clk":"11978587310","pt":1724792142480,"mc":[{"id":"1.232352477","rc":[{"batb":[[0,2.34,30.16],[1,1.03,200],[2,1.02,200]],"ltp":2.42,"tv":56.0,"id":206388}]}]}
{"op":"mcm","clk":"11978587578","pt":1724792146709,"mc":[{"id":"1.232352477","rc":[{"batb":[[0,2.36,5],[1,2.34,30.16],[2,1.03,200]],"ltp":2.42,"tv":56.0,"id":206388}]}]}
{"op":"mcm","clk":"11978587824","pt":1724792150107,"mc":[{"id":"1.232352477","rc":[{"batb":[[0,2.34,30.16],[1,1.03,200],[2,1.02,200]],"ltp":2.42,"tv":56.0,"id":206388}]}]}
{"op":"mcm","clk":"11978587977","pt":1724792152596,"mc":[{"id":"1.232352477","rc":[{"batb":[[0,2.36,5],[1,2.34,30.16],[2,1.03,200]],"ltp":2.42,"tv":56.0,"id":206388}]}]}
{"op":"mcm","clk":"11978588173","pt":1724792155993,"mc":[{"id":"1.232352477","rc":[{"batb":[[0,2.34,30.16],[1,1.03,200],[2,1.02,200]],"ltp":2.42,"tv":56.0,"id":206388}]}]}
{"op":"mcm","clk":"11978588413","pt":1724792160300,"mc":[{"id":"1.232352477","rc":[{"batb":[[0,2.36,5],[1,2.34,30.16],[2,1.03,200]],"ltp":2.42,"tv":56.0,"id":206388}]}]}
{"op":"mcm","clk":"11978588600","pt":1724792163702,"mc":[{"id":"1.232352477","rc":[{"batb":[[0,2.34,30.16],[1,1.03,200],[2,1.02,200]],"ltp":2.42,"tv":56.0,"id":206388}]}]}
{"op":"mcm","clk":"11978588761","pt":1724792166322,"mc":[{"id":"1.232352477","rc":[{"batb":[[0,2.36,5],[1,2.34,30.16],[2,1.03,200]],"ltp":2.42,"tv":56.0,"id":206388}]}]}
{"op":"mcm","clk":"11978588950","pt":1724792169626,"mc":[{"id":"1.232352477","rc":[{"batb":[[0,2.34,30.16],[1,1.03,200],[2,1.02,200]],"ltp":2.42,"tv":56.0,"id":206388}]}]}
{"op":"mcm","clk":"11978589121","pt":1724792173017,"mc":[{"id":"1.232352477","rc":[{"batb":[[0,2.36,5],[1,2.34,30.16],[2,1.03,200]],"ltp":2.42,"tv":56.0,"id":206388}]}]}
{"op":"mcm","clk":"11978589355","pt":1724792176507,"mc":[{"id":"1.232352477","rc":[{"batb":[[0,2.34,30.16],[1,1.03,200],[2,1.02,200]],"ltp":2.42,"tv":56.0,"id":206388}]}]}
{"op":"mcm","clk":"11978589482","pt":1724792178826,"mc":[{"id":"1.232352477","rc":[{"batb":[[0,2.36,5],[1,2.34,30.16],[2,1.03,200]],"ltp":2.42,"tv":56.0,"id":206388}]}]}
{"op":"mcm","clk":"11978589648","pt":1724792182119,"mc":[{"id":"1.232352477","rc":[{"batb":[[0,2.34,30.16],[1,1.03,200],[2,1.02,200]],"ltp":2.42,"tv":56.0,"id":206388}]}]}
{"op":"mcm","clk":"11978589847","pt":1724792185518,"mc":[{"id":"1.232352477","rc":[{"batb":[[0,2.36,5],[1,2.34,30.16],[2,1.03,200]],"ltp":2.42,"tv":56.0,"id":206388}]}]}
{"op":"mcm","clk":"11978590036","pt":1724792189023,"mc":[{"id":"1.232352477","rc":[{"batb":[[0,2.34,30.16],[1,1.03,200],[2,1.02,200]],"ltp":2.42,"tv":56.0,"id":206388}]}]}
{"op":"mcm","clk":"11978590206","pt":1724792191759,"mc":[{"id":"1.232352477","rc":[{"batb":[[0,2.36,5],[1,2.34,30.16],[2,1.03,200]],"ltp":2.42,"tv":56.0,"id":206388}]}]}
{"op":"mcm","clk":"11978590420","pt":1724792195060,"mc":[{"id":"1.232352477","rc":[{"batb":[[0,2.34,30.16],[1,1.03,200],[2,1.02,200]],"ltp":2.42,"tv":56.0,"id":206388}]}]}
{"op":"mcm","clk":"11978590609","pt":1724792197683,"mc":[{"id":"1.232352477","rc":[{"batb":[[0,2.36,5],[1,2.34,30.16],[2,1.03,200]],"ltp":2.42,"tv":56.0,"id":206388}]}]}
{"op":"mcm","clk":"11978590797","pt":1724792201184,"mc":[{"id":"1.232352477","rc":[{"batb":[[0,2.34,30.16],[1,1.03,200],[2,1.02,200]],"ltp":2.42,"tv":56.0,"id":206388}]}]}
{"op":"mcm","clk":"11978590930","pt":1724792203550,"mc":[{"id":"1.232352477","rc":[{"batb":[[0,2.36,5],[1,2.34,30.16],[2,1.03,200]],"ltp":2.42,"tv":56.0,"id":206388}]}]}
{"op":"mcm","clk":"11978591100","pt":1724792206966,"mc":[{"id":"1.232352477","rc":[{"batb":[[0,2.34,30.16],[1,1.03,200],[2,1.02,200]],"ltp":2.42,"tv":56.0,"id":206388}]}]}
{"op":"mcm","clk":"11978591232","pt":1724792209482,"mc":[{"id":"1.232352477","rc":[{"batb":[[0,2.36,5],[1,2.34,30.16],[2,1.03,200]],"ltp":2.42,"tv":56.0,"id":206388}]}]}
{"op":"mcm","clk":"11978591479","pt":1724792212883,"mc":[{"id":"1.232352477","rc":[{"batb":[[0,2.34,30.16],[1,1.03,200],[2,1.02,200]],"ltp":2.42,"tv":56.0,"id":206388}]}]}
{"op":"mcm","clk":"11978591710","pt":1724792217674,"mc":[{"id":"1.232352477","rc":[{"batb":[[0,2.36,5],[1,2.34,30.16],[2,1.03,200]],"ltp":2.42,"tv":56.0,"id":206388}]}]}
{"op":"mcm","clk":"11978591880","pt":1724792221171,"mc":[{"id":"1.232352477","rc":[{"batb":[[0,2.34,30.16],[1,1.03,200],[2,1.02,200]],"ltp":2.42,"tv":56.0,"id":206388}]}]}
{"op":"mcm","clk":"11978592021","pt":1724792223694,"mc":[{"id":"1.232352477","rc":[{"batb":[[0,2.36,5],[1,2.34,30.16],[2,1.03,200]],"ltp":2.42,"tv":56.0,"id":206388}]}]}
{"op":"mcm","clk":"11978592182","pt":1724792227089,"mc":[{"id":"1.232352477","rc":[{"batb":[[0,2.34,30.16],[1,1.03,200],[2,1.02,200]],"ltp":2.42,"tv":56.0,"id":206388}]}]}
{"op":"mcm","clk":"11978592352","pt":1724792230374,"mc":[{"id":"1.232352477","rc":[{"batb":[[0,2.36,5],[1,2.34,30.16],[2,1.03,200]],"ltp":2.42,"tv":56.0,"id":206388}]}]}
{"op":"mcm","clk":"11978592508","pt":1724792233682,"mc":[{"id":"1.232352477","rc":[{"batb":[[0,2.34,30.16],[1,1.03,200],[2,1.02,200]],"ltp":2.42,"tv":56.0,"id":206388}]}]}
{"op":"mcm","clk":"11978592670","pt":1724792237027,"mc":[{"id":"1.232352477","rc":[{"batb":[[0,2.36,5],[1,2.34,30.16],[2,1.03,200]],"ltp":2.42,"tv":56.0,"id":206388}]}]}
{"op":"mcm","clk":"11978592830","pt":1724792240421,"mc":[{"id":"1.232352477","rc":[{"batb":[[0,2.34,30.16],[1,1.03,200],[2,1.02,200]],"ltp":2.42,"tv":56.0,"id":206388}]}]}
{"op":"mcm","clk":"11978592964","pt":1724792243096,"mc":[{"id":"1.232352477","rc":[{"batb":[[0,2.36,5],[1,2.34,30.16],[2,1.03,200]],"ltp":2.42,"tv":56.0,"id":206388}]}]}
{"op":"mcm","clk":"11978593140","pt":1724792246701,"mc":[{"id":"1.232352477","rc":[{"batb":[[0,2.34,30.16],[1,1.03,200],[2,1.02,200]],"ltp":2.42,"tv":56.0,"id":206388}]}]}
{"op":"mcm","clk":"11978593266","pt":1724792249848,"mc":[{"id":"1.232352477","rc":[{"batb":[[0,2.36,5],[1,2.34,30.16],[2,1.03,200]],"ltp":2.42,"tv":56.0,"id":206388}]}]}
{"op":"mcm","clk":"11978593425","pt":1724792253020,"mc":[{"id":"1.232352477","rc":[{"batb":[[0,2.34,30.16],[1,1.03,200],[2,1.02,200]],"ltp":2.42,"tv":56.0,"id":206388}]}]}
{"op":"mcm","clk":"11978593557","pt":1724792256022,"mc":[{"id":"1.232352477","rc":[{"batb":[[0,2.36,5],[1,2.34,30.16],[2,1.03,200]],"ltp":2.42,"tv":56.0,"id":206388}]}]}
{"op":"mcm","clk":"11978593716","pt":1724792259315,"mc":[{"id":"1.232352477","rc":[{"batb":[[0,2.34,30.16],[1,1.03,200],[2,1.02,200]],"ltp":2.42,"tv":56.0,"id":206388}]}]}
{"op":"mcm","clk":"11978593925","pt":1724792263318,"mc":[{"id":"1.232352477","rc":[{"batb":[[0,2.36,5],[1,2.34,30.16],[2,1.03,200]],"ltp":2.42,"tv":56.0,"id":206388}]}]}
{"op":"mcm","clk":"11978594095","pt":1724792266762,"mc":[{"id":"1.232352477","rc":[{"batb":[[0,2.34,30.16],[1,1.03,200],[2,1.02,200]],"ltp":2.42,"tv":56.0,"id":206388}]}]}
{"op":"mcm","clk":"11978594210","pt":1724792269233,"mc":[{"id":"1.232352477","rc":[{"batb":[[0,2.36,5],[1,2.34,30.16],[2,1.03,200]],"ltp":2.42,"tv":56.0,"id":206388}]}]}
{"op":"mcm","clk":"11978594398","pt":1724792272628,"mc":[{"id":"1.232352477","rc":[{"batb":[[0,2.34,30.16],[1,1.03,200],[2,1.02,200]],"ltp":2.42,"tv":56.0,"id":206388}]}]}
{"op":"mcm","clk":"11978594552","pt":1724792275042,"mc":[{"id":"1.232352477","rc":[{"batb":[[0,2.36,5],[1,2.34,30.16],[2,1.03,200]],"ltp":2.42,"tv":56.0,"id":206388}]}]}
{"op":"mcm","clk":"11978594772","pt":1724792278534,"mc":[{"id":"1.232352477","rc":[{"batb":[[0,2.34,30.16],[1,1.03,200],[2,1.02,200]],"ltp":2.42,"tv":56.0,"id":206388}]}]}
{"op":"mcm","clk":"11978594919","pt":1724792281047,"mc":[{"id":"1.232352477","rc":[{"batb":[[0,2.36,5],[1,2.34,30.16],[2,1.03,200]],"ltp":2.42,"tv":56.0,"id":206388}]}]}
{"op":"mcm","clk":"11978595128","pt":1724792284342,"mc":[{"id":"1.232352477","rc":[{"batb":[[0,2.34,30.16],[1,1.03,200],[2,1.02,200]],"ltp":2.42,"tv":56.0,"id":206388}]}]}
{"op":"mcm","clk":"11978595291","pt":1724792286864,"mc":[{"id":"1.232352477","rc":[{"batb":[[0,2.36,5],[1,2.34,30.16],[2,1.03,200]],"ltp":2.42,"tv":56.0,"id":206388}]}]}
{"op":"mcm","clk":"11978595467","pt":1724792290458,"mc":[{"id":"1.232352477","rc":[{"batb":[[0,2.34,30.16],[1,1.03,200],[2,1.02,200]],"ltp":2.42,"tv":56.0,"id":206388}]}]}
{"op":"mcm","clk":"11978595582","pt":1724792292572,"mc":[{"id":"1.232352477","rc":[{"batb":[[0,2.36,5],[1,2.34,30.16],[2,1.03,200]],"ltp":2.42,"tv":56.0,"id":206388}]}]}
{"op":"mcm","clk":"11978595724","pt":1724792295964,"mc":[{"id":"1.232352477","rc":[{"batb":[[0,2.34,30.16],[1,1.03,200],[2,1.02,200]],"ltp":2.42,"tv":56.0,"id":206388}]}]}
{"op":"mcm","clk":"11978596031","pt":1724792302671,"mc":[{"id":"1.232352477","rc":[{"batb":[[0,2.36,5],[1,2.34,30.16],[2,1.03,200]],"ltp":2.42,"tv":56.0,"id":206388}]}]}
{"op":"mcm","clk":"11978596170","pt":1724792306061,"mc":[{"id":"1.232352477","rc":[{"batb":[[0,2.34,30.16],[1,1.03,200],[2,1.02,200]],"ltp":2.42,"tv":56.0,"id":206388}]}]}
{"op":"mcm","clk":"11978596354","pt":1724792309560,"mc":[{"id":"1.232352477","rc":[{"batb":[[0,2.36,5],[1,2.34,30.16],[2,1.03,200]],"ltp":2.42,"tv":56.0,"id":206388}]}]}
{"op":"mcm","clk":"11978596529","pt":1724792312966,"mc":[{"id":"1.232352477","rc":[{"batb":[[0,2.34,30.16],[1,1.03,200],[2,1.02,200]],"ltp":2.42,"tv":56.0,"id":206388}]}]}
{"op":"mcm","clk":"11978596700","pt":1724792316562,"mc":[{"id":"1.232352477","rc":[{"batb":[[0,2.36,5],[1,2.34,30.16],[2,1.03,200]],"ltp":2.42,"tv":56.0,"id":206388}]}]}
{"op":"mcm","clk":"11978596861","pt":1724792319907,"mc":[{"id":"1.232352477","rc":[{"batb":[[0,2.34,30.16],[1,1.03,200],[2,1.02,200]],"ltp":2.42,"tv":56.0,"id":206388}]}]}
{"op":"mcm","clk":"11978597104","pt":1724792324784,"mc":[{"id":"1.232352477","rc":[{"batb":[[0,2.36,5],[1,2.34,30.16],[2,1.03,200]],"ltp":2.42,"tv":56.0,"id":206388}]}]}
{"op":"mcm","clk":"11978597259","pt":1724792328081,"mc":[{"id":"1.232352477","rc":[{"batb":[[0,2.34,30.16],[1,1.03,200],[2,1.02,200]],"ltp":2.42,"tv":56.0,"id":206388}]}]}
{"op":"mcm","clk":"11978597420","pt":1724792331014,"mc":[{"id":"1.232352477","rc":[{"batb":[[0,2.36,5],[1,2.34,30.16],[2,1.03,200]],"ltp":2.42,"tv":56.0,"id":206388}]}]}
{"op":"mcm","clk":"11978597609","pt":1724792334383,"mc":[{"id":"1.232352477","rc":[{"batb":[[0,2.34,30.16],[1,1.03,200],[2,1.02,200]],"ltp":2.42,"tv":56.0,"id":206388}]}]}
{"op":"mcm","clk":"11978597714","pt":1724792336596,"mc":[{"id":"1.232352477","rc":[{"batb":[[0,2.36,5],[1,2.34,30.16],[2,1.03,200]],"ltp":2.42,"tv":56.0,"id":206388}]}]}
{"op":"mcm","clk":"11978597905","pt":1724792339891,"mc":[{"id":"1.232352477","rc":[{"batb":[[0,2.34,30.16],[1,1.03,200],[2,1.02,200]],"ltp":2.42,"tv":56.0,"id":206388}]}]}
{"op":"mcm","clk":"11978598100","pt":1724792343697,"mc":[{"id":"1.232352477","rc":[{"batb":[[0,2.36,5],[1,2.34,30.16],[2,1.03,200]],"ltp":2.42,"tv":56.0,"id":206388}]}]}
{"op":"mcm","clk":"11978598278","pt":1724792347107,"mc":[{"id":"1.232352477","rc":[{"batb":[[0,2.34,30.16],[1,1.03,200],[2,1.02,200]],"ltp":2.42,"tv":56.0,"id":206388}]}]}
{"op":"mcm","clk":"11978598411","pt":1724792349627,"mc":[{"id":"1.232352477","rc":[{"batb":[[0,2.36,5],[1,2.34,30.16],[2,1.03,200]],"ltp":2.42,"tv":56.0,"id":206388}]}]}
{"op":"mcm","clk":"11978598644","pt":1724792353125,"mc":[{"id":"1.232352477","rc":[{"batb":[[0,2.34,30.16],[1,1.03,200],[2,1.02,200]],"ltp":2.42,"tv":56.0,"id":206388}]}]}
{"op":"mcm","clk":"11978598772","pt":1724792355553,"mc":[{"id":"1.232352477","rc":[{"batb":[[0,2.36,5],[1,2.34,30.16],[2,1.03,200]],"ltp":2.42,"tv":56.0,"id":206388}]}]}
{"op":"mcm","clk":"11978598971","pt":1724792358835,"mc":[{"id":"1.232352477","rc":[{"batb":[[0,2.34,30.16],[1,1.03,200],[2,1.02,200]],"ltp":2.42,"tv":56.0,"id":206388}]}]}
{"op":"mcm","clk":"11978599125","pt":1724792361251,"mc":[{"id":"1.232352477","rc":[{"batb":[[0,2.36,5],[1,2.34,30.16],[2,1.03,200]],"ltp":2.42,"tv":56.0,"id":206388}]}]}
{"op":"mcm","clk":"11978599310","pt":1724792364644,"mc":[{"id":"1.232352477","rc":[{"batb":[[0,2.34,30.16],[1,1.03,200],[2,1.02,200]],"ltp":2.42,"tv":56.0,"id":206388}]}]}
{"op":"mcm","clk":"11978599443","pt":1724792367060,"mc":[{"id":"1.232352477","rc":[{"batb":[[0,2.36,5],[1,2.34,30.16],[2,1.03,200]],"ltp":2.42,"tv":56.0,"id":206388}]}]}
{"op":"mcm","clk":"11978599628","pt":1724792370458,"mc":[{"id":"1.232352477","rc":[{"batb":[[0,2.34,30.16],[1,1.03,200],[2,1.02,200]],"ltp":2.42,"tv":56.0,"id":206388}]}]}
{"op":"mcm","clk":"11978599787","pt":1724792372978,"mc":[{"id":"1.232352477","rc":[{"batb":[[0,2.36,5],[1,2.34,30.16],[2,1.03,200]],"ltp":2.42,"tv":56.0,"id":206388}]}]}
{"op":"mcm","clk":"11978599965","pt":1724792376276,"mc":[{"id":"1.232352477","rc":[{"batb":[[0,2.34,30.16],[1,1.03,200],[2,1.02,200]],"ltp":2.42,"tv":56.0,"id":206388}]}]}
{"op":"mcm","clk":"11978600168","pt":1724792379677,"mc":[{"id":"1.232352477","rc":[{"batb":[[0,2.36,5],[1,2.34,30.16],[2,1.03,200]],"ltp":2.42,"tv":56.0,"id":206388}]}]}
{"op":"mcm","clk":"11978600356","pt":1724792383079,"mc":[{"id":"1.232352477","rc":[{"batb":[[0,2.34,30.16],[1,1.03,200],[2,1.02,200]],"ltp":2.42,"tv":56.0,"id":206388}]}]}
{"op":"mcm","clk":"11978600526","pt":1724792385767,"mc":[{"id":"1.232352477","rc":[{"batb":[[0,2.36,5],[1,2.34,30.16],[2,1.03,200]],"ltp":2.42,"tv":56.0,"id":206388}]}]}
{"op":"mcm","clk":"11978600703","pt":1724792389066,"mc":[{"id":"1.232352477","rc":[{"batb":[[0,2.34,30.16],[1,1.03,200],[2,1.02,200]],"ltp":2.42,"tv":56.0,"id":206388}]}]}
{"op":"mcm","clk":"11978600881","pt":1724792392578,"mc":[{"id":"1.232352477","rc":[{"batb":[[0,2.36,5],[1,2.34,30.16],[2,1.03,200]],"ltp":2.42,"tv":56.0,"id":206388}]}]}
{"op":"mcm","clk":"11978601054","pt":1724792395866,"mc":[{"id":"1.232352477","rc":[{"batb":[[0,2.34,30.16],[1,1.03,200],[2,1.02,200]],"ltp":2.42,"tv":56.0,"id":206388}]}]}
{"op":"mcm","clk":"11978601184","pt":1724792398284,"mc":[{"id":"1.232352477","rc":[{"batb":[[0,2.36,5],[1,2.34,30.16],[2,1.03,200]],"ltp":2.42,"tv":56.0,"id":206388}]}]}
{"op":"mcm","clk":"11978601398","pt":1724792401691,"mc":[{"id":"1.232352477","rc":[{"batb":[[0,2.34,30.16],[1,1.03,200],[2,1.02,200]],"ltp":2.42,"tv":56.0,"id":206388}]}]}
{"op":"mcm","clk":"11978601602","pt":1724792404388,"mc":[{"id":"1.232352477","rc":[{"batb":[[0,2.36,5],[1,2.34,30.16],[2,1.03,200]],"ltp":2.42,"tv":56.0,"id":206388}]}]}
{"op":"mcm","clk":"11978601770","pt":1724792407687,"mc":[{"id":"1.232352477","rc":[{"batb":[[0,2.34,30.16],[1,1.03,200],[2,1.02,200]],"ltp":2.42,"tv":56.0,"id":206388}]}]}
{"op":"mcm","clk":"11978601920","pt":1724792410211,"mc":[{"id":"1.232352477","rc":[{"batb":[[0,2.36,5],[1,2.34,30.16],[2,1.03,200]],"ltp":2.42,"tv":56.0,"id":206388}]}]}
{"op":"mcm","clk":"11978602161","pt":1724792413520,"mc":[{"id":"1.232352477","rc":[{"batb":[[0,2.34,30.16],[1,1.03,200],[2,1.02,200]],"ltp":2.42,"tv":56.0,"id":206388}]}]}
{"op":"mcm","clk":"11978602312","pt":1724792416111,"mc":[{"id":"1.232352477","rc":[{"batb":[[0,2.36,5],[1,2.34,30.16],[2,1.03,200]],"ltp":2.42,"tv":56.0,"id":206388}]}]}
{"op":"mcm","clk":"11978602521","pt":1724792419505,"mc":[{"id":"1.232352477","rc":[{"batb":[[0,2.34,30.16],[1,1.03,200],[2,1.02,200]],"ltp":2.42,"tv":56.0,"id":206388}]}]}
{"op":"mcm","clk":"11978602657","pt":1724792421924,"mc":[{"id":"1.232352477","rc":[{"batb":[[0,2.36,5],[1,2.34,30.16],[2,1.03,200]],"ltp":2.42,"tv":56.0,"id":206388}]}]}
{"op":"mcm","clk":"11978602850","pt":1724792425220,"mc":[{"id":"1.232352477","rc":[{"batb":[[0,2.34,30.16],[1,1.03,200],[2,1.02,200]],"ltp":2.42,"tv":56.0,"id":206388}]}]}
{"op":"mcm","clk":"11978603000","pt":1724792428105,"mc":[{"id":"1.232352477","rc":[{"batb":[[0,2.36,5],[1,2.34,30.16],[2,1.03,200]],"ltp":2.42,"tv":56.0,"id":206388}]}]}
{"op":"mcm","clk":"11978603138","pt":1724792431512,"mc":[{"id":"1.232352477","rc":[{"batb":[[0,2.34,30.16],[1,1.03,200],[2,1.02,200]],"ltp":2.42,"tv":56.0,"id":206388}]}]}
{"op":"mcm","clk":"11978603268","pt":1724792434444,"mc":[{"id":"1.232352477","rc":[{"batb":[[0,2.36,5],[1,2.34,30.16],[2,1.03,200]],"ltp":2.42,"tv":56.0,"id":206388}]}]}
{"op":"mcm","clk":"11978603455","pt":1724792437953,"mc":[{"id":"1.232352477","rc":[{"batb":[[0,2.34,30.16],[1,1.03,200],[2,1.02,200]],"ltp":2.42,"tv":56.0,"id":206388}]}]}
{"op":"mcm","clk":"11978603735","pt":1724792442749,"mc":[{"id":"1.232352477","rc":[{"batb":[[0,2.36,5],[1,2.34,30.16],[2,1.03,200]],"ltp":2.42,"tv":56.0,"id":206388}]}]}
{"op":"mcm","clk":"11978603933","pt":1724792446161,"mc":[{"id":"1.232352477","rc":[{"batb":[[0,2.34,30.16],[1,1.03,200],[2,1.02,200]],"ltp":2.42,"tv":56.0,"id":206388}]}]}
{"op":"mcm","clk":"11978604150","pt":1724792450140,"mc":[{"id":"1.232352477","rc":[{"batb":[[0,2.36,5],[1,2.34,30.16],[2,1.03,200]],"ltp":2.42,"tv":56.0,"id":206388}]}]}
{"op":"mcm","clk":"11978604368","pt":1724792453539,"mc":[{"id":"1.232352477","rc":[{"batb":[[0,2.34,30.16],[1,1.03,200],[2,1.02,200]],"ltp":2.42,"tv":56.0,"id":206388}]}]}
{"op":"mcm","clk":"11978604515","pt":1724792456142,"mc":[{"id":"1.232352477","rc":[{"batb":[[0,2.36,5],[1,2.34,30.16],[2,1.03,200]],"ltp":2.42,"tv":56.0,"id":206388}]}]}
{"op":"mcm","clk":"11978604726","pt":1724792459450,"mc":[{"id":"1.232352477","rc":[{"batb":[[0,2.34,30.16],[1,1.03,200],[2,1.02,200]],"ltp":2.42,"tv":56.0,"id":206388}]}]}
{"op":"mcm","clk":"11978604889","pt":1724792462184,"mc":[{"id":"1.232352477","rc":[{"batb":[[0,2.36,5],[1,2.34,30.16],[2,1.03,200]],"ltp":2.42,"tv":56.0,"id":206388}]}]}
{"op":"mcm","clk":"11978605150","pt":1724792465491,"mc":[{"id":"1.232352477","rc":[{"batb":[[0,2.34,30.16],[1,1.03,200],[2,1.02,200]],"ltp":2.42,"tv":56.0,"id":206388}]}]}
{"op":"mcm","clk":"11978605291","pt":1724792468078,"mc":[{"id":"1.232352477","rc":[{"batb":[[0,2.36,5],[1,2.34,30.16],[2,1.03,200]],"ltp":2.42,"tv":56.0,"id":206388}]}]}
{"op":"mcm","clk":"11978605455","pt":1724792471493,"mc":[{"id":"1.232352477","rc":[{"batb":[[0,2.34,30.16],[1,1.03,200],[2,1.02,200]],"ltp":2.42,"tv":56.0,"id":206388}]}]}
{"op":"mcm","clk":"11978605577","pt":1724792473972,"mc":[{"id":"1.232352477","rc":[{"batb":[[0,2.36,5],[1,2.34,30.16],[2,1.03,200]],"ltp":2.42,"tv":56.0,"id":206388}]}]}
{"op":"mcm","clk":"11978605761","pt":1724792477374,"mc":[{"id":"1.232352477","rc":[{"batb":[[0,2.34,30.16],[1,1.03,200],[2,1.02,200]],"ltp":2.42,"tv":56.0,"id":206388}]}]}
{"op":"mcm","clk":"11978605893","pt":1724792480004,"mc":[{"id":"1.232352477","rc":[{"batb":[[0,2.36,5],[1,2.34,30.16],[2,1.03,200]],"ltp":2.42,"tv":56.0,"id":206388}]}]}
{"op":"mcm","clk":"11978606115","pt":1724792483296,"mc":[{"id":"1.232352477","rc":[{"batb":[[0,2.34,30.16],[1,1.03,200],[2,1.02,200]],"ltp":2.42,"tv":56.0,"id":206388}]}]}
{"op":"mcm","clk":"11978606274","pt":1724792485918,"mc":[{"id":"1.232352477","rc":[{"batb":[[0,2.36,5],[1,2.34,30.16],[2,1.03,200]],"ltp":2.42,"tv":56.0,"id":206388}]}]}
{"op":"mcm","clk":"11978606435","pt":1724792489308,"mc":[{"id":"1.232352477","rc":[{"batb":[[0,2.34,30.16],[1,1.03,200],[2,1.02,200]],"ltp":2.42,"tv":56.0,"id":206388}]}]}
{"op":"mcm","clk":"11978606547","pt":1724792491825,"mc":[{"id":"1.232352477","rc":[{"batb":[[0,2.36,5],[1,2.34,30.16],[2,1.03,200]],"ltp":2.42,"tv":56.0,"id":206388}]}]}
{"op":"mcm","clk":"11978606738","pt":1724792495221,"mc":[{"id":"1.232352477","rc":[{"batb":[[0,2.34,30.16],[1,1.03,200],[2,1.02,200]],"ltp":2.42,"tv":56.0,"id":206388}]}]}
{"op":"mcm","clk":"11978607037","pt":1724792501309,"mc":[{"id":"1.232352477","rc":[{"batb":[[0,2.36,5],[1,2.34,30.16],[2,1.03,200]],"ltp":2.42,"tv":56.0,"id":206388}]}]}
{"op":"mcm","clk":"11978607193","pt":1724792504604,"mc":[{"id":"1.232352477","rc":[{"batb":[[0,2.34,30.16],[1,1.03,200],[2,1.02,200]],"ltp":2.42,"tv":56.0,"id":206388}]}]}
{"op":"mcm","clk":"11978607308","pt":1724792507019,"mc":[{"id":"1.232352477","rc":[{"batb":[[0,2.36,5],[1,2.34,30.16],[2,1.03,200]],"ltp":2.42,"tv":56.0,"id":206388}]}]}
{"op":"mcm","clk":"11978607437","pt":1724792510407,"mc":[{"id":"1.232352477","rc":[{"batb":[[0,2.34,30.16],[1,1.03,200],[2,1.02,200]],"ltp":2.42,"tv":56.0,"id":206388}]}]}
{"op":"mcm","clk":"11978607526","pt":1724792512927,"mc":[{"id":"1.232352477","rc":[{"batb":[[0,2.36,5],[1,2.34,30.16],[2,1.03,200]],"ltp":2.42,"tv":56.0,"id":206388}]}]}
{"op":"mcm","clk":"11978607718","pt":1724792516330,"mc":[{"id":"1.232352477","rc":[{"batb":[[0,2.34,30.16],[1,1.03,200],[2,1.02,200]],"ltp":2.42,"tv":56.0,"id":206388}]}]}
{"op":"mcm","clk":"11978607881","pt":1724792519639,"mc":[{"id":"1.232352477","rc":[{"batb":[[0,2.36,5],[1,2.34,30.16],[2,1.03,200]],"ltp":2.42,"tv":56.0,"id":206388}]}]}
{"op":"mcm","clk":"11978608071","pt":1724792523029,"mc":[{"id":"1.232352477","rc":[{"batb":[[0,2.34,30.16],[1,1.03,200],[2,1.02,200]],"ltp":2.42,"tv":56.0,"id":206388}]}]}
{"op":"mcm","clk":"11978608308","pt":1724792526740,"mc":[{"id":"1.232352477","rc":[{"batb":[[0,2.36,5],[1,2.34,30.16],[2,1.03,200]],"ltp":2.42,"tv":56.0,"id":206388}]}]}
{"op":"mcm","clk":"11978608491","pt":1724792530141,"mc":[{"id":"1.232352477","rc":[{"batb":[[0,2.34,30.16],[1,1.03,200],[2,1.02,200]],"ltp":2.42,"tv":56.0,"id":206388}]}]}
{"op":"mcm","clk":"11978608650","pt":1724792533132,"mc":[{"id":"1.232352477","rc":[{"batb":[[0,2.36,5],[1,2.34,30.16],[2,1.03,200]],"ltp":2.42,"tv":56.0,"id":206388}]}]}
{"op":"mcm","clk":"11978608830","pt":1724792536530,"mc":[{"id":"1.232352477","rc":[{"batb":[[0,2.34,30.16],[1,1.03,200],[2,1.02,200]],"ltp":2.42,"tv":56.0,"id":206388}]}]}
{"op":"mcm","clk":"11978608964","pt":1724792539159,"mc":[{"id":"1.232352477","rc":[{"batb":[[0,2.36,5],[1,2.34,30.16],[2,1.03,200]],"ltp":2.42,"tv":56.0,"id":206388}]}]}
{"op":"mcm","clk":"11978609125","pt":1724792542446,"mc":[{"id":"1.232352477","rc":[{"batb":[[0,2.34,30.16],[1,1.03,200],[2,1.02,200]],"ltp":2.42,"tv":56.0,"id":206388}]}]}
{"op":"mcm","clk":"11978609247","pt":1724792544994,"mc":[{"id":"1.232352477","rc":[{"batb":[[0,2.36,5],[1,2.34,30.16],[2,1.03,200]],"ltp":2.42,"tv":56.0,"id":206388}]}]}
{"op":"mcm","clk":"11978609412","pt":1724792548377,"mc":[{"id":"1.232352477","rc":[{"batb":[[0,2.34,30.16],[1,1.03,200],[2,1.02,200]],"ltp":2.42,"tv":56.0,"id":206388}]}]}
{"op":"mcm","clk":"11978609533","pt":1724792550887,"mc":[{"id":"1.232352477","rc":[{"batb":[[0,2.36,5],[1,2.34,30.16],[2,1.03,200]],"ltp":2.42,"tv":56.0,"id":206388}]}]}
{"op":"mcm","clk":"11978609731","pt":1724792554293,"mc":[{"id":"1.232352477","rc":[{"batb":[[0,2.34,30.16],[1,1.03,200],[2,1.02,200]],"ltp":2.42,"tv":56.0,"id":206388}]}]}
{"op":"mcm","clk":"11978609908","pt":1724792557704,"mc":[{"id":"1.232352477","rc":[{"batb":[[0,2.36,5],[1,2.34,30.16],[2,1.03,200]],"ltp":2.42,"tv":56.0,"id":206388}]}]}
{"op":"mcm","clk":"11978610077","pt":1724792561192,"mc":[{"id":"1.232352477","rc":[{"batb":[[0,2.34,30.16],[1,1.03,200],[2,1.02,200]],"ltp":2.42,"tv":56.0,"id":206388}]}]}
{"op":"mcm","clk":"11978610189","pt":1724792563709,"mc":[{"id":"1.232352477","rc":[{"batb":[[0,2.36,5],[1,2.34,30.16],[2,1.03,200]],"ltp":2.42,"tv":56.0,"id":206388}]}]}
{"op":"mcm","clk":"11978610347","pt":1724792567104,"mc":[{"id":"1.232352477","rc":[{"batb":[[0,2.34,30.16],[1,1.03,200],[2,1.02,200]],"ltp":2.42,"tv":56.0,"id":206388}]}]}
{"op":"mcm","clk":"11978610501","pt":1724792569889,"mc":[{"id":"1.232352477","rc":[{"batb":[[0,2.36,5],[1,2.34,30.16],[2,1.03,200]],"ltp":2.42,"tv":56.0,"id":206388}]}]}
{"op":"mcm","clk":"11978610687","pt":1724792573299,"mc":[{"id":"1.232352477","rc":[{"batb":[[0,2.34,30.16],[1,1.03,200],[2,1.02,200]],"ltp":2.42,"tv":56.0,"id":206388}]}]}
{"op":"mcm","clk":"11978610825","pt":1724792575914,"mc":[{"id":"1.232352477","rc":[{"batb":[[0,2.36,5],[1,2.34,30.16],[2,1.03,200]],"ltp":2.42,"tv":56.0,"id":206388}]}]}
{"op":"mcm","clk":"11978610975","pt":1724792579313,"mc":[{"id":"1.232352477","rc":[{"batb":[[0,2.34,30.16],[1,1.03,200],[2,1.02,200]],"ltp":2.42,"tv":56.0,"id":206388}]}]}
{"op":"mcm","clk":"11978611093","pt":1724792581889,"mc":[{"id":"1.232352477","rc":[{"batb":[[0,2.36,5],[1,2.34,30.16],[2,1.03,200]],"ltp":2.42,"tv":56.0,"id":206388}]}]}
{"op":"mcm","clk":"11978611262","pt":1724792585432,"mc":[{"id":"1.232352477","rc":[{"batb":[[0,2.34,30.16],[1,1.03,200],[2,1.02,200]],"ltp":2.42,"tv":56.0,"id":206388}]}]}
{"op":"mcm","clk":"11978611590","pt":1724792592803,"mc":[{"id":"1.232352477","rc":[{"batb":[[0,2.36,5],[1,2.34,30.16],[2,1.03,200]],"ltp":2.42,"tv":56.0,"id":206388}]}]}
{"op":"mcm","clk":"11978611733","pt":1724792596246,"mc":[{"id":"1.232352477","rc":[{"batb":[[0,2.34,30.16],[1,1.03,200],[2,1.02,200]],"ltp":2.42,"tv":56.0,"id":206388}]}]}
{"op":"mcm","clk":"11978611897","pt":1724792599541,"mc":[{"id":"1.232352477","rc":[{"batb":[[0,2.36,5],[1,2.34,30.16],[2,1.03,200]],"ltp":2.42,"tv":56.0,"id":206388}]}]}
{"op":"mcm","clk":"11978612074","pt":1724792602848,"mc":[{"id":"1.232352477","rc":[{"batb":[[0,2.34,30.16],[1,1.03,200],[2,1.02,200]],"ltp":2.42,"tv":56.0,"id":206388}]}]}
{"op":"mcm","clk":"11978612232","pt":1724792606756,"mc":[{"id":"1.232352477","rc":[{"batb":[[0,2.36,5],[1,2.34,30.16],[2,1.03,200]],"ltp":2.42,"tv":56.0,"id":206388}]}]}
{"op":"mcm","clk":"11978612368","pt":1724792610155,"mc":[{"id":"1.232352477","rc":[{"batb":[[0,2.34,30.16],[1,1.03,200],[2,1.02,200]],"ltp":2.42,"tv":56.0,"id":206388}]}]}
{"op":"mcm","clk":"11978612484","pt":1724792612840,"mc":[{"id":"1.232352477","rc":[{"batb":[[0,2.36,5],[1,2.34,30.16],[2,1.03,200]],"ltp":2.42,"tv":56.0,"id":206388}]}]}
{"op":"mcm","clk":"11978612628","pt":1724792616342,"mc":[{"id":"1.232352477","rc":[{"batb":[[0,2.34,30.16],[1,1.03,200],[2,1.02,200]],"ltp":2.42,"tv":56.0,"id":206388}]}]}
{"op":"mcm","clk":"11978612746","pt":1724792619069,"mc":[{"id":"1.232352477","rc":[{"batb":[[0,2.36,5],[1,2.34,30.16],[2,1.03,200]],"ltp":2.42,"tv":56.0,"id":206388}]}]}
{"op":"mcm","clk":"11978612895","pt":1724792622672,"mc":[{"id":"1.232352477","rc":[{"batb":[[0,2.34,30.16],[1,1.03,200],[2,1.02,200]],"ltp":2.42,"tv":56.0,"id":206388}]}]}
{"op":"mcm","clk":"11978613146","pt":1724792627267,"mc":[{"id":"1.232352477","rc":[{"batb":[[0,2.36,5],[1,2.34,30.16],[2,1.03,200]],"ltp":2.42,"tv":56.0,"id":206388}]}]}
{"op":"mcm","clk":"11978613303","pt":1724792630655,"mc":[{"id":"1.232352477","rc":[{"batb":[[0,2.34,30.16],[1,1.03,200],[2,1.02,200]],"ltp":2.42,"tv":56.0,"id":206388}]}]}
{"op":"mcm","clk":"11978613438","pt":1724792633272,"mc":[{"id":"1.232352477","rc":[{"batb":[[0,2.36,5],[1,2.34,30.16],[2,1.03,200]],"ltp":2.42,"tv":56.0,"id":206388}]}]}
{"op":"mcm","clk":"11978613592","pt":1724792636764,"mc":[{"id":"1.232352477","rc":[{"batb":[[0,2.34,30.16],[1,1.03,200],[2,1.02,200]],"ltp":2.42,"tv":56.0,"id":206388}]}]}
{"op":"mcm","clk":"11978613687","pt":1724792639095,"mc":[{"id":"1.232352477","rc":[{"batb":[[0,2.36,5],[1,2.34,30.16],[2,1.03,200]],"ltp":2.42,"tv":56.0,"id":206388}]}]}
{"op":"mcm","clk":"11978613871","pt":1724792642606,"mc":[{"id":"1.232352477","rc":[{"batb":[[0,2.34,30.16],[1,1.03,200],[2,1.02,200]],"ltp":2.42,"tv":56.0,"id":206388}]}]}
{"op":"mcm","clk":"11978614070","pt":1724792645900,"mc":[{"id":"1.232352477","rc":[{"batb":[[0,2.36,5],[1,2.34,30.16],[2,1.03,200]],"ltp":2.42,"tv":56.0,"id":206388}]}]}
{"op":"mcm","clk":"11978614248","pt":1724792649399,"mc":[{"id":"1.232352477","rc":[{"batb":[[0,2.34,30.16],[1,1.03,200],[2,1.02,200]],"ltp":2.42,"tv":56.0,"id":206388}]}]}
{"op":"mcm","clk":"11978614380","pt":1724792652122,"mc":[{"id":"1.232352477","rc":[{"batb":[[0,2.36,5],[1,2.34,30.16],[2,1.03,200]],"ltp":2.42,"tv":56.0,"id":206388}]}]}
{"op":"mcm","clk":"11978614582","pt":1724792655623,"mc":[{"id":"1.232352477","rc":[{"batb":[[0,2.34,30.16],[1,1.03,200],[2,1.02,200]],"ltp":2.42,"tv":56.0,"id":206388}]}]}
{"op":"mcm","clk":"11978614709","pt":1724792657834,"mc":[{"id":"1.232352477","rc":[{"batb":[[0,2.36,5],[1,2.34,30.16],[2,1.03,200]],"ltp":2.42,"tv":56.0,"id":206388}]}]}
{"op":"mcm","clk":"11978614903","pt":1724792661538,"mc":[{"id":"1.232352477","rc":[{"batb":[[0,2.34,30.16],[1,1.03,200],[2,1.02,200]],"ltp":2.42,"tv":56.0,"id":206388}]}]}
{"op":"mcm","clk":"11978615011","pt":1724792664054,"mc":[{"id":"1.232352477","rc":[{"batb":[[0,2.36,5],[1,2.34,30.16],[2,1.03,200]],"ltp":2.42,"tv":56.0,"id":206388}]}]}
{"op":"mcm","clk":"11978615161","pt":1724792667217,"mc":[{"id":"1.232352477","rc":[{"batb":[[0,2.34,30.16],[1,1.03,200],[2,1.02,200]],"ltp":2.42,"tv":56.0,"id":206388}]}]}
{"op":"mcm","clk":"11978615296","pt":1724792670918,"mc":[{"id":"1.232352477","rc":[{"batb":[[0,2.36,5],[1,2.34,30.16],[2,1.03,200]],"ltp":2.42,"tv":56.0,"id":206388}]}]}
{"op":"mcm","clk":"11978615467","pt":1724792674317,"mc":[{"id":"1.232352477","rc":[{"batb":[[0,2.34,30.16],[1,1.03,200],[2,1.02,200]],"ltp":2.42,"tv":56.0,"id":206388}]}]}
{"op":"mcm","clk":"11978615584","pt":1724792676635,"mc":[{"id":"1.232352477","rc":[{"batb":[[0,2.36,5],[1,2.34,30.16],[2,1.03,200]],"ltp":2.42,"tv":56.0,"id":206388}]}]}
{"op":"mcm","clk":"11978615755","pt":1724792680030,"mc":[{"id":"1.232352477","rc":[{"batb":[[0,2.34,30.16],[1,1.03,200],[2,1.02,200]],"ltp":2.42,"tv":56.0,"id":206388}]}]}
{"op":"mcm","clk":"11978615899","pt":1724792683262,"mc":[{"id":"1.232352477","rc":[{"batb":[[0,2.36,5],[1,2.34,30.16],[2,1.03,200]],"ltp":2.42,"tv":56.0,"id":206388}]}]}
{"op":"mcm","clk":"11978616075","pt":1724792686674,"mc":[{"id":"1.232352477","rc":[{"batb":[[0,2.34,30.16],[1,1.03,200],[2,1.02,200]],"ltp":2.42,"tv":56.0,"id":206388}]}]}
{"op":"mcm","clk":"11978616233","pt":1724792689765,"mc":[{"id":"1.232352477","rc":[{"batb":[[0,2.36,5],[1,2.34,30.16],[2,1.03,200]],"ltp":2.42,"tv":56.0,"id":206388}]}]}
{"op":"mcm","clk":"11978616409","pt":1724792693060,"mc":[{"id":"1.232352477","rc":[{"batb":[[0,2.34,30.16],[1,1.03,200],[2,1.02,200]],"ltp":2.42,"tv":56.0,"id":206388}]}]}
{"op":"mcm","clk":"11978616526","pt":1724792695585,"mc":[{"id":"1.232352477","rc":[{"batb":[[0,2.36,5],[1,2.34,30.16],[2,1.03,200]],"ltp":2.42,"tv":56.0,"id":206388}]}]}
{"op":"mcm","clk":"11978616703","pt":1724792698875,"mc":[{"id":"1.232352477","rc":[{"batb":[[0,2.34,30.16],[1,1.03,200],[2,1.02,200]],"ltp":2.42,"tv":56.0,"id":206388}]}]}
{"op":"mcm","clk":"11978616848","pt":1724792701463,"mc":[{"id":"1.232352477","rc":[{"batb":[[0,2.36,5],[1,2.34,30.16],[2,1.03,200]],"ltp":2.42,"tv":56.0,"id":206388}]}]}
{"op":"mcm","clk":"11978617026","pt":1724792704659,"mc":[{"id":"1.232352477","rc":[{"batb":[[0,2.34,30.16],[1,1.03,200],[2,1.02,200]],"ltp":2.42,"tv":56.0,"id":206388}]}]}
{"op":"mcm","clk":"11978617125","pt":1724792706873,"mc":[{"id":"1.232352477","rc":[{"batb":[[0,2.36,5],[1,2.34,30.16],[2,1.03,200]],"ltp":2.42,"tv":56.0,"id":206388}]}]}
{"op":"mcm","clk":"11978617291","pt":1724792710378,"mc":[{"id":"1.232352477","rc":[{"batb":[[0,2.34,30.16],[1,1.03,200],[2,1.02,200]],"ltp":2.42,"tv":56.0,"id":206388}]}]}
{"op":"mcm","clk":"11978617425","pt":1724792713103,"mc":[{"id":"1.232352477","rc":[{"batb":[[0,2.36,5],[1,2.34,30.16],[2,1.03,200]],"ltp":2.42,"tv":56.0,"id":206388}]}]}
{"op":"mcm","clk":"11978617551","pt":1724792716401,"mc":[{"id":"1.232352477","rc":[{"batb":[[0,2.34,30.16],[1,1.03,200],[2,1.02,200]],"ltp":2.42,"tv":56.0,"id":206388}]}]}
{"op":"mcm","clk":"11978617674","pt":1724792718981,"mc":[{"id":"1.232352477","rc":[{"batb":[[0,2.36,5],[1,2.34,30.16],[2,1.03,200]],"ltp":2.42,"tv":56.0,"id":206388}]}]}
{"op":"mcm","clk":"11978617841","pt":1724792722484,"mc":[{"id":"1.232352477","rc":[{"batb":[[0,2.34,30.16],[1,1.03,200],[2,1.02,200]],"ltp":2.42,"tv":56.0,"id":206388}]}]}
{"op":"mcm","clk":"11978618008","pt":1724792725795,"mc":[{"id":"1.232352477","rc":[{"batb":[[0,2.36,5],[1,2.34,30.16],[2,1.03,200]],"ltp":2.42,"tv":56.0,"id":206388}]}]}
{"op":"mcm","clk":"11978618145","pt":1724792729142,"mc":[{"id":"1.232352477","rc":[{"batb":[[0,2.34,30.16],[1,1.03,200],[2,1.02,200]],"ltp":2.42,"tv":56.0,"id":206388}]}]}
{"op":"mcm","clk":"11978618302","pt":1724792731725,"mc":[{"id":"1.232352477","rc":[{"batb":[[0,2.36,5],[1,2.34,30.16],[2,1.03,200]],"ltp":2.42,"tv":56.0,"id":206388}]}]}
{"op":"mcm","clk":"11978618482","pt":1724792735225,"mc":[{"id":"1.232352477","rc":[{"batb":[[0,2.34,30.16],[1,1.03,200],[2,1.02,200]],"ltp":2.42,"tv":56.0,"id":206388}]}]}
{"op":"mcm","clk":"11978618671","pt":1724792738526,"mc":[{"id":"1.232352477","rc":[{"batb":[[0,2.36,5],[1,2.34,30.16],[2,1.03,200]],"ltp":2.42,"tv":56.0,"id":206388}]}]}
{"op":"mcm","clk":"11978618852","pt":1724792741929,"mc":[{"id":"1.232352477","rc":[{"batb":[[0,2.34,30.16],[1,1.03,200],[2,1.02,200]],"ltp":2.42,"tv":56.0,"id":206388}]}]}
{"op":"mcm","clk":"11978619043","pt":1724792745834,"mc":[{"id":"1.232352477","rc":[{"batb":[[0,2.36,5],[1,2.34,30.16],[2,1.03,200]],"ltp":2.42,"tv":56.0,"id":206388}]}]}
{"op":"mcm","clk":"11978619183","pt":1724792749132,"mc":[{"id":"1.232352477","rc":[{"batb":[[0,2.34,30.16],[1,1.03,200],[2,1.02,200]],"ltp":2.42,"tv":56.0,"id":206388}]}]}
{"op":"mcm","clk":"11978619287","pt":1724792751856,"mc":[{"id":"1.232352477","rc":[{"batb":[[0,2.36,5],[1,2.34,30.16],[2,1.03,200]],"ltp":2.42,"tv":56.0,"id":206388}]}]}
{"op":"mcm","clk":"11978619421","pt":1724792755246,"mc":[{"id":"1.232352477","rc":[{"batb":[[0,2.34,30.16],[1,1.03,200],[2,1.02,200]],"ltp":2.42,"tv":56.0,"id":206388}]}]}
{"op":"mcm","clk":"11978619555","pt":1724792757928,"mc":[{"id":"1.232352477","rc":[{"batb":[[0,2.36,5],[1,2.34,30.16],[2,1.03,200]],"ltp":2.42,"tv":56.0,"id":206388}]}]}
{"op":"mcm","clk":"11978619721","pt":1724792761467,"mc":[{"id":"1.232352477","rc":[{"batb":[[0,2.34,30.16],[1,1.03,200],[2,1.02,200]],"ltp":2.42,"tv":56.0,"id":206388}]}]}
{"op":"mcm","clk":"11978619849","pt":1724792763677,"mc":[{"id":"1.232352477","rc":[{"batb":[[0,2.36,5],[1,2.34,30.16],[2,1.03,200]],"ltp":2.42,"tv":56.0,"id":206388}]}]}
{"op":"mcm","clk":"11978620031","pt":1724792767172,"mc":[{"id":"1.232352477","rc":[{"batb":[[0,2.34,30.16],[1,1.03,200],[2,1.02,200]],"ltp":2.42,"tv":56.0,"id":206388}]}]}
{"op":"mcm","clk":"11978620258","pt":1724792772366,"mc":[{"id":"1.232352477","rc":[{"batb":[[0,2.36,5],[1,2.34,30.16],[2,1.03,200]],"ltp":2.42,"tv":56.0,"id":206388}]}]}
{"op":"mcm","clk":"11978620471","pt":1724792775764,"mc":[{"id":"1.232352477","rc":[{"batb":[[0,2.34,30.16],[1,1.03,200],[2,1.02,200]],"ltp":2.42,"tv":56.0,"id":206388}]}]}
{"op":"mcm","clk":"11978620648","pt":1724792778560,"mc":[{"id":"1.232352477","rc":[{"batb":[[0,2.36,5],[1,2.34,30.16],[2,1.03,200]],"ltp":2.42,"tv":56.0,"id":206388}]}]}
{"op":"mcm","clk":"11978620815","pt":1724792782058,"mc":[{"id":"1.232352477","rc":[{"batb":[[0,2.34,30.16],[1,1.03,200],[2,1.02,200]],"ltp":2.42,"tv":56.0,"id":206388}]}]}
{"op":"mcm","clk":"11978620990","pt":1724792785205,"mc":[{"id":"1.232352477","rc":[{"batb":[[0,2.36,5],[1,2.34,30.16],[2,1.03,200]],"ltp":2.42,"tv":56.0,"id":206388}]}]}
{"op":"mcm","clk":"11978621145","pt":1724792788506,"mc":[{"id":"1.232352477","rc":[{"batb":[[0,2.34,30.16],[1,1.03,200],[2,1.02,200]],"ltp":2.42,"tv":56.0,"id":206388}]}]}
{"op":"mcm","clk":"11978621531","pt":1724792794296,"mc":[{"id":"1.232352477","rc":[{"batb":[[0,2.36,5],[1,2.34,30.16],[2,1.03,200]],"ltp":2.42,"tv":56.0,"id":206388}]}]}
{"op":"mcm","clk":"11978621722","pt":1724792797488,"mc":[{"id":"1.232352477","rc":[{"batb":[[0,2.34,30.16],[1,1.03,200],[2,1.02,200]],"ltp":2.42,"tv":56.0,"id":206388}]}]}
{"op":"mcm","clk":"11978621800","pt":1724792799902,"mc":[{"id":"1.232352477","rc":[{"batb":[[0,2.36,5],[1,2.34,30.16],[2,1.03,200]],"ltp":2.42,"tv":56.0,"id":206388}]}]}
{"op":"mcm","clk":"11978622007","pt":1724792803418,"mc":[{"id":"1.232352477","rc":[{"batb":[[0,2.34,30.16],[1,1.03,200],[2,1.02,200]],"ltp":2.42,"tv":56.0,"id":206388}]}]}
{"op":"mcm","clk":"11978622179","pt":1724792806100,"mc":[{"id":"1.232352477","rc":[{"batb":[[0,2.36,5],[1,2.34,30.16],[2,1.03,200]],"ltp":2.42,"tv":56.0,"id":206388}]}]}
{"op":"mcm","clk":"11978622367","pt":1724792809501,"mc":[{"id":"1.232352477","rc":[{"batb":[[0,2.34,30.16],[1,1.03,200],[2,1.02,200]],"ltp":2.42,"tv":56.0,"id":206388}]}]}
{"op":"mcm","clk":"11978622508","pt":1724792811924,"mc":[{"id":"1.232352477","rc":[{"batb":[[0,2.36,5],[1,2.34,30.16],[2,1.03,200]],"ltp":2.42,"tv":56.0,"id":206388}]}]}
{"op":"mcm","clk":"11978622672","pt":1724792815221,"mc":[{"id":"1.232352477","rc":[{"batb":[[0,2.34,30.16],[1,1.03,200],[2,1.02,200]],"ltp":2.42,"tv":56.0,"id":206388}]}]}
{"op":"mcm","clk":"11978622822","pt":1724792818608,"mc":[{"id":"1.232352477","rc":[{"batb":[[0,2.36,5],[1,2.34,30.16],[2,1.03,200]],"ltp":2.42,"tv":56.0,"id":206388}]}]}
{"op":"mcm","clk":"11978622949","pt":1724792821903,"mc":[{"id":"1.232352477","rc":[{"batb":[[0,2.34,30.16],[1,1.03,200],[2,1.02,200]],"ltp":2.42,"tv":56.0,"id":206388}]}]}
{"op":"mcm","clk":"11978623118","pt":1724792825509,"mc":[{"id":"1.232352477","rc":[{"batb":[[0,2.36,5],[1,2.34,30.16],[2,1.03,200]],"ltp":2.42,"tv":56.0,"id":206388}]}]}
{"op":"mcm","clk":"11978623297","pt":1724792828847,"mc":[{"id":"1.232352477","rc":[{"batb":[[0,2.34,30.16],[1,1.03,200],[2,1.02,200]],"ltp":2.42,"tv":56.0,"id":206388}]}]}
{"op":"mcm","clk":"11978623450","pt":1724792832141,"mc":[{"id":"1.232352477","rc":[{"batb":[[0,2.36,5],[1,2.34,30.16],[2,1.03,200]],"ltp":2.42,"tv":56.0,"id":206388}]}]}
{"op":"mcm","clk":"11978623597","pt":1724792835330,"mc":[{"id":"1.232352477","rc":[{"batb":[[0,2.34,30.16],[1,1.03,200],[2,1.02,200]],"ltp":2.42,"tv":56.0,"id":206388}]}]}
{"op":"mcm","clk":"11978623731","pt":1724792838060,"mc":[{"id":"1.232352477","rc":[{"batb":[[0,2.36,5],[1,2.34,30.16],[2,1.03,200]],"ltp":2.42,"tv":56.0,"id":206388}]}]}
{"op":"mcm","clk":"11978623869","pt":1724792841460,"mc":[{"id":"1.232352477","rc":[{"batb":[[0,2.34,30.16],[1,1.03,200],[2,1.02,200]],"ltp":2.42,"tv":56.0,"id":206388}]}]}
{"op":"mcm","clk":"11978623996","pt":1724792844545,"mc":[{"id":"1.232352477","rc":[{"batb":[[0,2.36,5],[1,2.34,30.16],[2,1.03,200]],"ltp":2.42,"tv":56.0,"id":206388}]}]}
{"op":"mcm","clk":"11978624124","pt":1724792847829,"mc":[{"id":"1.232352477","rc":[{"batb":[[0,2.34,30.16],[1,1.03,200],[2,1.02,200]],"ltp":2.42,"tv":56.0,"id":206388}]}]}
{"op":"mcm","clk":"11978624281","pt":1724792851735,"mc":[{"id":"1.232352477","rc":[{"batb":[[0,2.36,5],[1,2.34,30.16],[2,1.03,200]],"ltp":2.42,"tv":56.0,"id":206388}]}]}
{"op":"mcm","clk":"11978624456","pt":1724792854975,"mc":[{"id":"1.232352477","rc":[{"batb":[[0,2.34,30.16],[1,1.03,200],[2,1.02,200]],"ltp":2.42,"tv":56.0,"id":206388}]}]}
{"op":"mcm","clk":"11978624587","pt":1724792857855,"mc":[{"id":"1.232352477","rc":[{"batb":[[0,2.36,5],[1,2.34,30.16],[2,1.03,200]],"ltp":2.42,"tv":56.0,"id":206388}]}]}
{"op":"mcm","clk":"11978624721","pt":1724792861092,"mc":[{"id":"1.232352477","rc":[{"batb":[[0,2.34,30.16],[1,1.03,200],[2,1.02,200]],"ltp":2.42,"tv":56.0,"id":206388}]}]}
{"op":"mcm","clk":"11978624825","pt":1724792863460,"mc":[{"id":"1.232352477","rc":[{"batb":[[0,2.36,5],[1,2.34,30.16],[2,1.03,200]],"ltp":2.42,"tv":56.0,"id":206388}]}]}
{"op":"mcm","clk":"11978624998","pt":1724792866758,"mc":[{"id":"1.232352477","rc":[{"batb":[[0,2.34,30.16],[1,1.03,200],[2,1.02,200]],"ltp":2.42,"tv":56.0,"id":206388}]}]}
{"op":"mcm","clk":"11978625130","pt":1724792869586,"mc":[{"id":"1.232352477","rc":[{"batb":[[0,2.36,5],[1,2.34,30.16],[2,1.03,200]],"ltp":2.42,"tv":56.0,"id":206388}]}]}
{"op":"mcm","clk":"11978625309","pt":1724792872993,"mc":[{"id":"1.232352477","rc":[{"batb":[[0,2.34,30.16],[1,1.03,200],[2,1.02,200]],"ltp":2.42,"tv":56.0,"id":206388}]}]}
{"op":"mcm","clk":"11978625463","pt":1724792875980,"mc":[{"id":"1.232352477","rc":[{"batb":[[0,2.36,5],[1,2.34,30.16],[2,1.03,200]],"ltp":2.42,"tv":56.0,"id":206388}]}]}
{"op":"mcm","clk":"11978625654","pt":1724792879485,"mc":[{"id":"1.232352477","rc":[{"batb":[[0,2.34,30.16],[1,1.03,200],[2,1.02,200]],"ltp":2.42,"tv":56.0,"id":206388}]}]}
{"op":"mcm","clk":"11978625777","pt":1724792882115,"mc":[{"id":"1.232352477","rc":[{"batb":[[0,2.36,5],[1,2.34,30.16],[2,1.03,200]],"ltp":2.42,"tv":56.0,"id":206388}]}]}
{"op":"mcm","clk":"11978625943","pt":1724792885620,"mc":[{"id":"1.232352477","rc":[{"batb":[[0,2.34,30.16],[1,1.03,200],[2,1.02,200]],"ltp":2.42,"tv":56.0,"id":206388}]}]}
{"op":"mcm","clk":"11978626300","pt":1724792894518,"mc":[{"id":"1.232352477","rc":[{"batb":[[0,2.36,5],[1,2.34,30.16],[2,1.03,200]],"ltp":2.42,"tv":56.0,"id":206388}]}]}
{"op":"mcm","clk":"11978626496","pt":1724792897868,"mc":[{"id":"1.232352477","rc":[{"batb":[[0,2.34,30.16],[1,1.03,200],[2,1.02,200]],"ltp":2.42,"tv":56.0,"id":206388}]}]}
{"op":"mcm","clk":"11978626731","pt":1724792902952,"mc":[{"id":"1.232352477","rc":[{"batb":[[0,2.36,5],[1,2.34,30.16],[2,1.03,200]],"ltp":2.42,"tv":56.0,"id":206388}]}]}
{"op":"mcm","clk":"11978626898","pt":1724792906351,"mc":[{"id":"1.232352477","rc":[{"batb":[[0,2.34,30.16],[1,1.03,200],[2,1.02,200]],"ltp":2.42,"tv":56.0,"id":206388}]}]}
{"op":"mcm","clk":"11978627069","pt":1724792909798,"mc":[{"id":"1.232352477","rc":[{"batb":[[0,2.36,5],[1,2.34,30.16],[2,1.03,200]],"ltp":2.42,"tv":56.0,"id":206388}]}]}
{"op":"mcm","clk":"11978627252","pt":1724792913297,"mc":[{"id":"1.232352477","rc":[{"batb":[[0,2.34,30.16],[1,1.03,200],[2,1.02,200]],"ltp":2.42,"tv":56.0,"id":206388}]}]}
{"op":"mcm","clk":"11978627419","pt":1724792916585,"mc":[{"id":"1.232352477","rc":[{"batb":[[0,2.36,5],[1,2.34,30.16],[2,1.03,200]],"ltp":2.42,"tv":56.0,"id":206388}]}]}
{"op":"mcm","clk":"11978627575","pt":1724792919977,"mc":[{"id":"1.232352477","rc":[{"batb":[[0,2.34,30.16],[1,1.03,200],[2,1.02,200]],"ltp":2.42,"tv":56.0,"id":206388}]}]}
{"op":"mcm","clk":"11978627897","pt":1724792925676,"mc":[{"id":"1.232352477","rc":[{"batb":[[0,2.36,5],[1,2.34,30.16],[2,1.03,200]],"ltp":2.42,"tv":56.0,"id":206388}]}]}
{"op":"mcm","clk":"11978628081","pt":1724792929124,"mc":[{"id":"1.232352477","rc":[{"batb":[[0,2.34,30.16],[1,1.03,200],[2,1.02,200]],"ltp":2.42,"tv":56.0,"id":206388}]}]}
{"op":"mcm","clk":"11978628238","pt":1724792932316,"mc":[{"id":"1.232352477","rc":[{"batb":[[0,2.36,5],[1,2.34,30.16],[2,1.03,200]],"ltp":2.42,"tv":56.0,"id":206388}]}]}
{"op":"mcm","clk":"11978628414","pt":1724792935708,"mc":[{"id":"1.232352477","rc":[{"batb":[[0,2.34,30.16],[1,1.03,200],[2,1.02,200]],"ltp":2.42,"tv":56.0,"id":206388}]}]}
{"op":"mcm","clk":"11978628631","pt":1724792940502,"mc":[{"id":"1.232352477","rc":[{"batb":[[0,2.36,5],[1,2.34,30.16],[2,1.03,200]],"ltp":2.42,"tv":56.0,"id":206388}]}]}
{"op":"mcm","clk":"11978628797","pt":1724792944003,"mc":[{"id":"1.232352477","rc":[{"batb":[[0,2.34,30.16],[1,1.03,200],[2,1.02,200]],"ltp":2.42,"tv":56.0,"id":206388}]}]}
{"op":"mcm","clk":"11978628936","pt":1724792946724,"mc":[{"id":"1.232352477","rc":[{"batb":[[0,2.36,5],[1,2.34,30.16],[2,1.03,200]],"ltp":2.42,"tv":56.0,"id":206388}]}]}
{"op":"mcm","clk":"11978629117","pt":1724792950121,"mc":[{"id":"1.232352477","rc":[{"batb":[[0,2.34,30.16],[1,1.03,200],[2,1.02,200]],"ltp":2.42,"tv":56.0,"id":206388}]}]}
{"op":"mcm","clk":"11978629244","pt":1724792952640,"mc":[{"id":"1.232352477","rc":[{"batb":[[0,2.36,5],[1,2.34,30.16],[2,1.03,200]],"ltp":2.42,"tv":56.0,"id":206388}]}]}
{"op":"mcm","clk":"11978629404","pt":1724792955933,"mc":[{"id":"1.232352477","rc":[{"batb":[[0,2.34,30.16],[1,1.03,200],[2,1.02,200]],"ltp":2.42,"tv":56.0,"id":206388}]}]}
{"op":"mcm","clk":"11978629628","pt":1724792958610,"mc":[{"id":"1.232352477","rc":[{"batb":[[0,2.36,5],[1,2.34,30.16],[2,1.03,200]],"ltp":2.42,"tv":56.0,"id":206388}]}]}
{"op":"mcm","clk":"11978629806","pt":1724792961954,"mc":[{"id":"1.232352477","rc":[{"batb":[[0,2.34,30.16],[1,1.03,200],[2,1.02,200]],"ltp":2.42,"tv":56.0,"id":206388}]}]}
{"op":"mcm","clk":"11978629941","pt":1724792964636,"mc":[{"id":"1.232352477","rc":[{"batb":[[0,2.36,5],[1,2.34,30.16],[2,1.03,200]],"ltp":2.42,"tv":56.0,"id":206388}]}]}
{"op":"mcm","clk":"11978630113","pt":1724792968130,"mc":[{"id":"1.232352477","rc":[{"batb":[[0,2.34,30.16],[1,1.03,200],[2,1.02,200]],"ltp":2.42,"tv":56.0,"id":206388}]}]}
{"op":"mcm","clk":"11978630224","pt":1724792970555,"mc":[{"id":"1.232352477","rc":[{"batb":[[0,2.36,5],[1,2.34,30.16],[2,1.03,200]],"ltp":2.42,"tv":56.0,"id":206388}]}]}
{"op":"mcm","clk":"11978630393","pt":1724792973952,"mc":[{"id":"1.232352477","rc":[{"batb":[[0,2.34,30.16],[1,1.03,200],[2,1.02,200]],"ltp":2.42,"tv":56.0,"id":206388}]}]}
{"op":"mcm","clk":"11978630487","pt":1724792976164,"mc":[{"id":"1.232352477","rc":[{"batb":[[0,2.36,5],[1,2.34,30.16],[2,1.03,200]],"ltp":2.42,"tv":56.0,"id":206388}]}]}
{"op":"mcm","clk":"11978630637","pt":1724792979358,"mc":[{"id":"1.232352477","rc":[{"batb":[[0,2.34,30.16],[1,1.03,200],[2,1.02,200]],"ltp":2.42,"tv":56.0,"id":206388}]}]}
{"op":"mcm","clk":"11978630750","pt":1724792981985,"mc":[{"id":"1.232352477","rc":[{"batb":[[0,2.36,5],[1,2.34,30.16],[2,1.03,200]],"ltp":2.42,"tv":56.0,"id":206388}]}]}
{"op":"mcm","clk":"11978630938","pt":1724792985480,"mc":[{"id":"1.232352477","rc":[{"batb":[[0,2.34,30.16],[1,1.03,200],[2,1.02,200]],"ltp":2.42,"tv":56.0,"id":206388}]}]}
{"op":"mcm","clk":"11978631133","pt":1724792989652,"mc":[{"id":"1.232352477","rc":[{"batb":[[0,2.36,5],[1,2.34,30.16],[2,1.03,200]],"ltp":2.42,"tv":56.0,"id":206388}]}]}
{"op":"mcm","clk":"11978631284","pt":1724792992999,"mc":[{"id":"1.232352477","rc":[{"batb":[[0,2.34,30.16],[1,1.03,200],[2,1.02,200]],"ltp":2.42,"tv":56.0,"id":206388}]}]}
{"op":"mcm","clk":"11978631422","pt":1724792995781,"mc":[{"id":"1.232352477","rc":[{"batb":[[0,2.36,5],[1,2.34,30.16],[2,1.03,200]],"ltp":2.42,"tv":56.0,"id":206388}]}]}
{"op":"mcm","clk":"11978631621","pt":1724792998981,"mc":[{"id":"1.232352477","rc":[{"batb":[[0,2.34,30.16],[1,1.03,200],[2,1.02,200]],"ltp":2.42,"tv":56.0,"id":206388}]}]}
{"op":"mcm","clk":"11978631789","pt":1724793002611,"mc":[{"id":"1.232352477","rc":[{"batb":[[0,2.36,5],[1,2.34,30.16],[2,1.03,200]],"ltp":2.42,"tv":56.0,"id":206388}]}]}
{"op":"mcm","clk":"11978631933","pt":1724793005909,"mc":[{"id":"1.232352477","rc":[{"batb":[[0,2.34,30.16],[1,1.03,200],[2,1.02,200]],"ltp":2.42,"tv":56.0,"id":206388}]}]}
{"op":"mcm","clk":"11978632129","pt":1724793010390,"mc":[{"id":"1.232352477","rc":[{"batb":[[0,2.36,5],[1,2.34,30.16],[2,1.03,200]],"ltp":2.42,"tv":56.0,"id":206388}]}]}
{"op":"mcm","clk":"11978632306","pt":1724793013690,"mc":[{"id":"1.232352477","rc":[{"batb":[[0,2.34,30.16],[1,1.03,200],[2,1.02,200]],"ltp":2.42,"tv":56.0,"id":206388}]}]}
{"op":"mcm","clk":"11978632424","pt":1724793015998,"mc":[{"id":"1.232352477","rc":[{"batb":[[0,2.36,5],[1,2.34,30.16],[2,1.03,200]],"ltp":2.42,"tv":56.0,"id":206388}]}]}
{"op":"mcm","clk":"11978632645","pt":1724793019399,"mc":[{"id":"1.232352477","rc":[{"batb":[[0,2.34,30.16],[1,1.03,200],[2,1.02,200]],"ltp":2.42,"tv":56.0,"id":206388}]}]}
{"op":"mcm","clk":"11978632834","pt":1724793023616,"mc":[{"id":"1.232352477","rc":[{"batb":[[0,2.36,5],[1,2.34,30.16],[2,1.03,200]],"ltp":2.42,"tv":56.0,"id":206388}]}]}
{"op":"mcm","clk":"11978632994","pt":1724793027001,"mc":[{"id":"1.232352477","rc":[{"batb":[[0,2.34,30.16],[1,1.03,200],[2,1.02,200]],"ltp":2.42,"tv":56.0,"id":206388}]}]}
{"op":"mcm","clk":"11978633250","pt":1724793031227,"mc":[{"id":"1.232352477","rc":[{"batb":[[0,2.36,5],[1,2.34,30.16],[2,1.03,200]],"ltp":2.42,"tv":56.0,"id":206388}]}]}
{"op":"mcm","clk":"11978633434","pt":1724793034621,"mc":[{"id":"1.232352477","rc":[{"batb":[[0,2.34,30.16],[1,1.03,200],[2,1.02,200]],"ltp":2.42,"tv":56.0,"id":206388}]}]}
{"op":"mcm","clk":"11978633570","pt":1724793037801,"mc":[{"id":"1.232352477","rc":[{"batb":[[0,2.36,5],[1,2.34,30.16],[2,1.03,200]],"ltp":2.42,"tv":56.0,"id":206388}]}]}
{"op":"mcm","clk":"11978633697","pt":1724793041036,"mc":[{"id":"1.232352477","rc":[{"batb":[[0,2.34,30.16],[1,1.03,200],[2,1.02,200]],"ltp":2.42,"tv":56.0,"id":206388}]}]}
{"op":"mcm","clk":"11978633823","pt":1724793043916,"mc":[{"id":"1.232352477","rc":[{"batb":[[0,2.36,5],[1,2.34,30.16],[2,1.03,200]],"ltp":2.42,"tv":56.0,"id":206388}]}]}
{"op":"mcm","clk":"11978633991","pt":1724793047419,"mc":[{"id":"1.232352477","rc":[{"batb":[[0,2.34,30.16],[1,1.03,200],[2,1.02,200]],"ltp":2.42,"tv":56.0,"id":206388}]}]}
{"op":"mcm","clk":"11978634199","pt":1724793052449,"mc":[{"id":"1.232352477","rc":[{"batb":[[0,2.36,5],[1,2.34,30.16],[2,1.03,200]],"ltp":2.42,"tv":56.0,"id":206388}]}]}
{"op":"mcm","clk":"11978634378","pt":1724793056144,"mc":[{"id":"1.232352477","rc":[{"batb":[[0,2.34,30.16],[1,1.03,200],[2,1.02,200]],"ltp":2.42,"tv":56.0,"id":206388}]}]}
{"op":"mcm","clk":"11978634479","pt":1724793058459,"mc":[{"id":"1.232352477","rc":[{"batb":[[0,2.36,5],[1,2.34,30.16],[2,1.03,200]],"ltp":2.42,"tv":56.0,"id":206388}]}]}
{"op":"mcm","clk":"11978634624","pt":1724793061852,"mc":[{"id":"1.232352477","rc":[{"batb":[[0,2.34,30.16],[1,1.03,200],[2,1.02,200]],"ltp":2.42,"tv":56.0,"id":206388}]}]}
{"op":"mcm","clk":"11978634750","pt":1724793064565,"mc":[{"id":"1.232352477","rc":[{"batb":[[0,2.36,5],[1,2.34,30.16],[2,1.03,200]],"ltp":2.42,"tv":56.0,"id":206388}]}]}
{"op":"mcm","clk":"11978634903","pt":1724793067760,"mc":[{"id":"1.232352477","rc":[{"batb":[[0,2.34,30.16],[1,1.03,200],[2,1.02,200]],"ltp":2.42,"tv":56.0,"id":206388}]}]}
{"op":"mcm","clk":"11978635005","pt":1724793070578,"mc":[{"id":"1.232352477","rc":[{"batb":[[0,2.36,5],[1,2.34,30.16],[2,1.03,200]],"ltp":2.42,"tv":56.0,"id":206388}]}]}
{"op":"mcm","clk":"11978635143","pt":1724793074072,"mc":[{"id":"1.232352477","rc":[{"batb":[[0,2.34,30.16],[1,1.03,200],[2,1.02,200]],"ltp":2.42,"tv":56.0,"id":206388}]}]}
{"op":"mcm","clk":"11978635232","pt":1724793076487,"mc":[{"id":"1.232352477","rc":[{"batb":[[0,2.36,5],[1,2.34,30.16],[2,1.03,200]],"ltp":2.42,"tv":56.0,"id":206388}]}]}
{"op":"mcm","clk":"11978635363","pt":1724793079777,"mc":[{"id":"1.232352477","rc":[{"batb":[[0,2.34,30.16],[1,1.03,200],[2,1.02,200]],"ltp":2.42,"tv":56.0,"id":206388}]}]}
{"op":"mcm","clk":"11978635487","pt":1724793082293,"mc":[{"id":"1.232352477","rc":[{"batb":[[0,2.36,5],[1,2.34,30.16],[2,1.03,200]],"ltp":2.42,"tv":56.0,"id":206388}]}]}
{"op":"mcm","clk":"11978635655","pt":1724793085688,"mc":[{"id":"1.232352477","rc":[{"batb":[[0,2.34,30.16],[1,1.03,200],[2,1.02,200]],"ltp":2.42,"tv":56.0,"id":206388}]}]}
{"op":"mcm","clk":"11978635829","pt":1724793088671,"mc":[{"id":"1.232352477","rc":[{"batb":[[0,2.36,5],[1,2.34,30.16],[2,1.03,200]],"ltp":2.42,"tv":56.0,"id":206388}]}]}
{"op":"mcm","clk":"11978636002","pt":1724793092113,"mc":[{"id":"1.232352477","rc":[{"batb":[[0,2.34,30.16],[1,1.03,200],[2,1.02,200]],"ltp":2.42,"tv":56.0,"id":206388}]}]}
{"op":"mcm","clk":"11978636138","pt":1724793094484,"mc":[{"id":"1.232352477","rc":[{"batb":[[0,2.36,5],[1,2.34,30.16],[2,1.03,200]],"ltp":2.42,"tv":56.0,"id":206388}]}]}
{"op":"mcm","clk":"11978636319","pt":1724793097914,"mc":[{"id":"1.232352477","rc":[{"batb":[[0,2.34,30.16],[1,1.03,200],[2,1.02,200]],"ltp":2.42,"tv":56.0,"id":206388}]}]}
{"op":"mcm","clk":"11978636420","pt":1724793100388,"mc":[{"id":"1.232352477","rc":[{"batb":[[0,2.36,5],[1,2.34,30.16],[2,1.03,200]],"ltp":2.42,"tv":56.0,"id":206388}]}]}
{"op":"mcm","clk":"11978636561","pt":1724793103791,"mc":[{"id":"1.232352477","rc":[{"batb":[[0,2.34,30.16],[1,1.03,200],[2,1.02,200]],"ltp":2.42,"tv":56.0,"id":206388}]}]}
{"op":"mcm","clk":"11978636650","pt":1724793106204,"mc":[{"id":"1.232352477","rc":[{"batb":[[0,2.36,5],[1,2.34,30.16],[2,1.03,200]],"ltp":2.42,"tv":56.0,"id":206388}]}]}
{"op":"mcm","clk":"11978636780","pt":1724793109797,"mc":[{"id":"1.232352477","rc":[{"batb":[[0,2.34,30.16],[1,1.03,200],[2,1.02,200]],"ltp":2.42,"tv":56.0,"id":206388}]}]}
{"op":"mcm","clk":"11978636891","pt":1724793112104,"mc":[{"id":"1.232352477","rc":[{"batb":[[0,2.36,5],[1,2.34,30.16],[2,1.03,200]],"ltp":2.42,"tv":56.0,"id":206388}]}]}
{"op":"mcm","clk":"11978637045","pt":1724793115493,"mc":[{"id":"1.232352477","rc":[{"batb":[[0,2.34,30.16],[1,1.03,200],[2,1.02,200]],"ltp":2.42,"tv":56.0,"id":206388}]}]}
{"op":"mcm","clk":"11978637181","pt":1724793117909,"mc":[{"id":"1.232352477","rc":[{"batb":[[0,2.36,5],[1,2.34,30.16],[2,1.03,200]],"ltp":2.42,"tv":56.0,"id":206388}]}]}
{"op":"mcm","clk":"11978637372","pt":1724793121112,"mc":[{"id":"1.232352477","rc":[{"batb":[[0,2.34,30.16],[1,1.03,200],[2,1.02,200]],"ltp":2.42,"tv":56.0,"id":206388}]}]}
{"op":"mcm","clk":"11978637559","pt":1724793124040,"mc":[{"id":"1.232352477","rc":[{"batb":[[0,2.36,5],[1,2.34,30.16],[2,1.03,200]],"ltp":2.42,"tv":56.0,"id":206388}]}]}
{"op":"mcm","clk":"11978637730","pt":1724793127537,"mc":[{"id":"1.232352477","rc":[{"batb":[[0,2.34,30.16],[1,1.03,200],[2,1.02,200]],"ltp":2.42,"tv":56.0,"id":206388}]}]}
{"op":"mcm","clk":"11978637857","pt":1724793130460,"mc":[{"id":"1.232352477","rc":[{"batb":[[0,2.36,5],[1,2.34,30.16],[2,1.03,200]],"ltp":2.42,"tv":56.0,"id":206388}]}]}
{"op":"mcm","clk":"11978637989","pt":1724793133750,"mc":[{"id":"1.232352477","rc":[{"batb":[[0,2.34,30.16],[1,1.03,200],[2,1.02,200]],"ltp":2.42,"tv":56.0,"id":206388}]}]}
{"op":"mcm","clk":"11978638175","pt":1724793137251,"mc":[{"id":"1.232352477","rc":[{"batb":[[0,2.36,5],[1,2.34,30.16],[2,1.03,200]],"ltp":2.42,"tv":56.0,"id":206388}]}]}
{"op":"mcm","clk":"11978638362","pt":1724793140745,"mc":[{"id":"1.232352477","rc":[{"batb":[[0,2.34,30.16],[1,1.03,200],[2,1.02,200]],"ltp":2.42,"tv":56.0,"id":206388}]}]}
{"op":"mcm","clk":"11978638487","pt":1724793143361,"mc":[{"id":"1.232352477","rc":[{"batb":[[0,2.36,5],[1,2.34,30.16],[2,1.03,200]],"ltp":2.42,"tv":56.0,"id":206388}]}]}
{"op":"mcm","clk":"11978638624","pt":1724793146550,"mc":[{"id":"1.232352477","rc":[{"batb":[[0,2.34,30.16],[1,1.03,200],[2,1.02,200]],"ltp":2.42,"tv":56.0,"id":206388}]}]}
{"op":"mcm","clk":"11978638808","pt":1724793150050,"mc":[{"id":"1.232352477","rc":[{"batb":[[0,2.36,5],[1,2.34,30.16],[2,1.03,200]],"ltp":2.42,"tv":56.0,"id":206388}]}]}
{"op":"mcm","clk":"11978638983","pt":1724793153283,"mc":[{"id":"1.232352477","rc":[{"batb":[[0,2.34,30.16],[1,1.03,200],[2,1.02,200]],"ltp":2.42,"tv":56.0,"id":206388}]}]}
{"op":"mcm","clk":"11978639082","pt":1724793155655,"mc":[{"id":"1.232352477","rc":[{"batb":[[0,2.36,5],[1,2.34,30.16],[2,1.03,200]],"ltp":2.42,"tv":56.0,"id":206388}]}]}
{"op":"mcm","clk":"11978639248","pt":1724793158888,"mc":[{"id":"1.232352477","rc":[{"batb":[[0,2.34,30.16],[1,1.03,200],[2,1.02,200]],"ltp":2.42,"tv":56.0,"id":206388}]}]}
{"op":"mcm","clk":"11978639391","pt":1724793161872,"mc":[{"id":"1.232352477","rc":[{"batb":[[0,2.36,5],[1,2.34,30.16],[2,1.03,200]],"ltp":2.42,"tv":56.0,"id":206388}]}]}
{"op":"mcm","clk":"11978639554","pt":1724793165191,"mc":[{"id":"1.232352477","rc":[{"batb":[[0,2.34,30.16],[1,1.03,200],[2,1.02,200]],"ltp":2.42,"tv":56.0,"id":206388}]}]}
{"op":"mcm","clk":"11978639686","pt":1724793168574,"mc":[{"id":"1.232352477","rc":[{"batb":[[0,2.36,5],[1,2.34,30.16],[2,1.03,200]],"ltp":2.42,"tv":56.0,"id":206388}]}]}
{"op":"mcm","clk":"11978639829","pt":1724793171911,"mc":[{"id":"1.232352477","rc":[{"batb":[[0,2.34,30.16],[1,1.03,200],[2,1.02,200]],"ltp":2.42,"tv":56.0,"id":206388}]}]}
{"op":"mcm","clk":"11978639973","pt":1724793174481,"mc":[{"id":"1.232352477","rc":[{"batb":[[0,2.36,5],[1,2.34,30.16],[2,1.03,200]],"ltp":2.42,"tv":56.0,"id":206388}]}]}
{"op":"mcm","clk":"11978640119","pt":1724793177916,"mc":[{"id":"1.232352477","rc":[{"batb":[[0,2.34,30.16],[1,1.03,200],[2,1.02,200]],"ltp":2.42,"tv":56.0,"id":206388}]}]}
{"op":"mcm","clk":"11978640277","pt":1724793181110,"mc":[{"id":"1.232352477","rc":[{"batb":[[0,2.36,5],[1,2.34,30.16],[2,1.03,200]],"ltp":2.42,"tv":56.0,"id":206388}]}]}
{"op":"mcm","clk":"11978640455","pt":1724793184509,"mc":[{"id":"1.232352477","rc":[{"batb":[[0,2.34,30.16],[1,1.03,200],[2,1.02,200]],"ltp":2.42,"tv":56.0,"id":206388}]}]}
{"op":"mcm","clk":"11978640594","pt":1724793187292,"mc":[{"id":"1.232352477","rc":[{"batb":[[0,2.36,5],[1,2.34,30.16],[2,1.03,200]],"ltp":2.42,"tv":56.0,"id":206388}]}]}
{"op":"mcm","clk":"11978640734","pt":1724793190629,"mc":[{"id":"1.232352477","rc":[{"batb":[[0,2.34,30.16],[1,1.03,200],[2,1.02,200]],"ltp":2.42,"tv":56.0,"id":206388}]}]}
{"op":"mcm","clk":"11978640850","pt":1724793192842,"mc":[{"id":"1.232352477","rc":[{"batb":[[0,2.36,5],[1,2.34,30.16],[2,1.03,200]],"ltp":2.42,"tv":56.0,"id":206388}]}]}
{"op":"mcm","clk":"11978641029","pt":1724793196133,"mc":[{"id":"1.232352477","rc":[{"batb":[[0,2.34,30.16],[1,1.03,200],[2,1.02,200]],"ltp":2.42,"tv":56.0,"id":206388}]}]}
{"op":"mcm","clk":"11978641230","pt":1724793200137,"mc":[{"id":"1.232352477","rc":[{"batb":[[0,2.36,5],[1,2.34,30.16],[2,1.03,200]],"ltp":2.42,"tv":56.0,"id":206388}]}]}
{"op":"mcm","clk":"11978641379","pt":1724793203531,"mc":[{"id":"1.232352477","rc":[{"batb":[[0,2.34,30.16],[1,1.03,200],[2,1.02,200]],"ltp":2.42,"tv":56.0,"id":206388}]}]}
{"op":"mcm","clk":"11978641587","pt":1724793206926,"mc":[{"id":"1.232352477","rc":[{"batb":[[0,2.36,5],[1,2.34,30.16],[2,1.03,200]],"ltp":2.42,"tv":56.0,"id":206388}]}]}
{"op":"mcm","clk":"11978641750","pt":1724793210217,"mc":[{"id":"1.232352477","rc":[{"batb":[[0,2.34,30.16],[1,1.03,200],[2,1.02,200]],"ltp":2.42,"tv":56.0,"id":206388}]}]}
{"op":"mcm","clk":"11978641918","pt":1724793213426,"mc":[{"id":"1.232352477","rc":[{"batb":[[0,2.36,5],[1,2.34,30.16],[2,1.03,200]],"ltp":2.42,"tv":56.0,"id":206388}]}]}
{"op":"mcm","clk":"11978642047","pt":1724793216868,"mc":[{"id":"1.232352477","rc":[{"batb":[[0,2.34,30.16],[1,1.03,200],[2,1.02,200]],"ltp":2.42,"tv":56.0,"id":206388}]}]}
{"op":"mcm","clk":"11978642194","pt":1724793219339,"mc":[{"id":"1.232352477","rc":[{"batb":[[0,2.36,5],[1,2.34,30.16],[2,1.03,200]],"ltp":2.42,"tv":56.0,"id":206388}]}]}
{"op":"mcm","clk":"11978642364","pt":1724793222784,"mc":[{"id":"1.232352477","rc":[{"batb":[[0,2.34,30.16],[1,1.03,200],[2,1.02,200]],"ltp":2.42,"tv":56.0,"id":206388}]}]}
{"op":"mcm","clk":"11978642462","pt":1724793225051,"mc":[{"id":"1.232352477","rc":[{"batb":[[0,2.36,5],[1,2.34,30.16],[2,1.03,200]],"ltp":2.42,"tv":56.0,"id":206388}]}]}
{"op":"mcm","clk":"11978642622","pt":1724793228394,"mc":[{"id":"1.232352477","rc":[{"batb":[[0,2.34,30.16],[1,1.03,200],[2,1.02,200]],"ltp":2.42,"tv":56.0,"id":206388}]}]}
{"op":"mcm","clk":"11978642747","pt":1724793230859,"mc":[{"id":"1.232352477","rc":[{"batb":[[0,2.36,5],[1,2.34,30.16],[2,1.03,200]],"ltp":2.42,"tv":56.0,"id":206388}]}]}
{"op":"mcm","clk":"11978642872","pt":1724793234162,"mc":[{"id":"1.232352477","rc":[{"batb":[[0,2.34,30.16],[1,1.03,200],[2,1.02,200]],"ltp":2.42,"tv":56.0,"id":206388}]}]}
{"op":"mcm","clk":"11978642970","pt":1724793236576,"mc":[{"id":"1.232352477","rc":[{"batb":[[0,2.36,5],[1,2.34,30.16],[2,1.03,200]],"ltp":2.42,"tv":56.0,"id":206388}]}]}
{"op":"mcm","clk":"11978643123","pt":1724793239974,"mc":[{"id":"1.232352477","rc":[{"batb":[[0,2.34,30.16],[1,1.03,200],[2,1.02,200]],"ltp":2.42,"tv":56.0,"id":206388}]}]}
{"op":"mcm","clk":"11978643246","pt":1724793242499,"mc":[{"id":"1.232352477","rc":[{"batb":[[0,2.36,5],[1,2.34,30.16],[2,1.03,200]],"ltp":2.42,"tv":56.0,"id":206388}]}]}
{"op":"mcm","clk":"11978643422","pt":1724793245918,"mc":[{"id":"1.232352477","rc":[{"batb":[[0,2.34,30.16],[1,1.03,200],[2,1.02,200]],"ltp":2.42,"tv":56.0,"id":206388}]}]}
{"op":"mcm","clk":"11978643555","pt":1724793248496,"mc":[{"id":"1.232352477","rc":[{"batb":[[0,2.36,5],[1,2.34,30.16],[2,1.03,200]],"ltp":2.42,"tv":56.0,"id":206388}]}]}
{"op":"mcm","clk":"11978643686","pt":1724793251790,"mc":[{"id":"1.232352477","rc":[{"batb":[[0,2.34,30.16],[1,1.03,200],[2,1.02,200]],"ltp":2.42,"tv":56.0,"id":206388}]}]}
{"op":"mcm","clk":"11978643789","pt":1724793254005,"mc":[{"id":"1.232352477","rc":[{"batb":[[0,2.36,5],[1,2.34,30.16],[2,1.03,200]],"ltp":2.42,"tv":56.0,"id":206388}]}]}
{"op":"mcm","clk":"11978643929","pt":1724793257296,"mc":[{"id":"1.232352477","rc":[{"batb":[[0,2.34,30.16],[1,1.03,200],[2,1.02,200]],"ltp":2.42,"tv":56.0,"id":206388}]}]}
{"op":"mcm","clk":"11978644005","pt":1724793259814,"mc":[{"id":"1.232352477","rc":[{"batb":[[0,2.36,5],[1,2.34,30.16],[2,1.03,200]],"ltp":2.42,"tv":56.0,"id":206388}]}]}
{"op":"mcm","clk":"11978644152","pt":1724793263205,"mc":[{"id":"1.232352477","rc":[{"batb":[[0,2.34,30.16],[1,1.03,200],[2,1.02,200]],"ltp":2.42,"tv":56.0,"id":206388}]}]}
{"op":"mcm","clk":"11978644271","pt":1724793265730,"mc":[{"id":"1.232352477","rc":[{"batb":[[0,2.36,5],[1,2.34,30.16],[2,1.03,200]],"ltp":2.42,"tv":56.0,"id":206388}]}]}
{"op":"mcm","clk":"11978644454","pt":1724793269227,"mc":[{"id":"1.232352477","rc":[{"batb":[[0,2.34,30.16],[1,1.03,200],[2,1.02,200]],"ltp":2.42,"tv":56.0,"id":206388}]}]}
{"op":"mcm","clk":"11978644543","pt":1724793271539,"mc":[{"id":"1.232352477","rc":[{"batb":[[0,2.36,5],[1,2.34,30.16],[2,1.03,200]],"ltp":2.42,"tv":56.0,"id":206388}]}]}
{"op":"mcm","clk":"11978644704","pt":1724793275042,"mc":[{"id":"1.232352477","rc":[{"batb":[[0,2.34,30.16],[1,1.03,200],[2,1.02,200]],"ltp":2.42,"tv":56.0,"id":206388}]}]}
{"op":"mcm","clk":"11978644815","pt":1724793277561,"mc":[{"id":"1.232352477","rc":[{"batb":[[0,2.36,5],[1,2.34,30.16],[2,1.03,200]],"ltp":2.42,"tv":56.0,"id":206388}]}]}
{"op":"mcm","clk":"11978644951","pt":1724793280848,"mc":[{"id":"1.232352477","rc":[{"batb":[[0,2.34,30.16],[1,1.03,200],[2,1.02,200]],"ltp":2.42,"tv":56.0,"id":206388}]}]}
{"op":"mcm","clk":"11978645104","pt":1724793283476,"mc":[{"id":"1.232352477","rc":[{"batb":[[0,2.36,5],[1,2.34,30.16],[2,1.03,200]],"ltp":2.42,"tv":56.0,"id":206388}]}]}
{"op":"mcm","clk":"11978645251","pt":1724793286729,"mc":[{"id":"1.232352477","rc":[{"batb":[[0,2.34,30.16],[1,1.03,200],[2,1.02,200]],"ltp":2.42,"tv":56.0,"id":206388}]}]}
{"op":"mcm","clk":"11978645412","pt":1724793290069,"mc":[{"id":"1.232352477","rc":[{"batb":[[0,2.36,5],[1,2.34,30.16],[2,1.03,200]],"ltp":2.42,"tv":56.0,"id":206388}]}]}
{"op":"mcm","clk":"11978645582","pt":1724793293467,"mc":[{"id":"1.232352477","rc":[{"batb":[[0,2.34,30.16],[1,1.03,200],[2,1.02,200]],"ltp":2.42,"tv":56.0,"id":206388}]}]}
{"op":"mcm","clk":"11978645705","pt":1724793296045,"mc":[{"id":"1.232352477","rc":[{"batb":[[0,2.36,5],[1,2.34,30.16],[2,1.03,200]],"ltp":2.42,"tv":56.0,"id":206388}]}]}
{"op":"mcm","clk":"11978645851","pt":1724793299287,"mc":[{"id":"1.232352477","rc":[{"batb":[[0,2.34,30.16],[1,1.03,200],[2,1.02,200]],"ltp":2.42,"tv":56.0,"id":206388}]}]}
{"op":"mcm","clk":"11978645994","pt":1724793301986,"mc":[{"id":"1.232352477","rc":[{"batb":[[0,2.36,5],[1,2.34,30.16],[2,1.03,200]],"ltp":2.42,"tv":56.0,"id":206388}]}]}
{"op":"mcm","clk":"11978646187","pt":1724793305186,"mc":[{"id":"1.232352477","rc":[{"batb":[[0,2.34,30.16],[1,1.03,200],[2,1.02,200]],"ltp":2.42,"tv":56.0,"id":206388}]}]}
{"op":"mcm","clk":"11978646319","pt":1724793307658,"mc":[{"id":"1.232352477","rc":[{"batb":[[0,2.36,5],[1,2.34,30.16],[2,1.03,200]],"ltp":2.42,"tv":56.0,"id":206388}]}]}
{"op":"mcm","clk":"11978646520","pt":1724793311000,"mc":[{"id":"1.232352477","rc":[{"batb":[[0,2.34,30.16],[1,1.03,200],[2,1.02,200]],"ltp":2.42,"tv":56.0,"id":206388}]}]}
{"op":"mcm","clk":"11978646691","pt":1724793313480,"mc":[{"id":"1.232352477","rc":[{"batb":[[0,2.36,5],[1,2.34,30.16],[2,1.03,200]],"ltp":2.42,"tv":56.0,"id":206388}]}]}
{"op":"mcm","clk":"11978646851","pt":1724793316780,"mc":[{"id":"1.232352477","rc":[{"batb":[[0,2.34,30.16],[1,1.03,200],[2,1.02,200]],"ltp":2.42,"tv":56.0,"id":206388}]}]}
{"op":"mcm","clk":"11978646969","pt":1724793319305,"mc":[{"id":"1.232352477","rc":[{"batb":[[0,2.36,5],[1,2.34,30.16],[2,1.03,200]],"ltp":2.42,"tv":56.0,"id":206388}]}]}
{"op":"mcm","clk":"11978647123","pt":1724793322598,"mc":[{"id":"1.232352477","rc":[{"batb":[[0,2.34,30.16],[1,1.03,200],[2,1.02,200]],"ltp":2.42,"tv":56.0,"id":206388}]}]}
{"op":"mcm","clk":"11978647270","pt":1724793325376,"mc":[{"id":"1.232352477","rc":[{"batb":[[0,2.36,5],[1,2.34,30.16],[2,1.03,200]],"ltp":2.42,"tv":56.0,"id":206388}]}]}
{"op":"mcm","clk":"11978647441","pt":1724793328715,"mc":[{"id":"1.232352477","rc":[{"batb":[[0,2.34,30.16],[1,1.03,200],[2,1.02,200]],"ltp":2.42,"tv":56.0,"id":206388}]}]}
{"op":"mcm","clk":"11978647593","pt":1724793331702,"mc":[{"id":"1.232352477","rc":[{"batb":[[0,2.36,5],[1,2.34,30.16],[2,1.03,200]],"ltp":2.42,"tv":56.0,"id":206388}]}]}
{"op":"mcm","clk":"11978647757","pt":1724793335102,"mc":[{"id":"1.232352477","rc":[{"batb":[[0,2.34,30.16],[1,1.03,200],[2,1.02,200]],"ltp":2.42,"tv":56.0,"id":206388}]}]}
{"op":"mcm","clk":"11978647940","pt":1724793338541,"mc":[{"id":"1.232352477","rc":[{"batb":[[0,2.36,5],[1,2.34,30.16],[2,1.03,200]],"ltp":2.42,"tv":56.0,"id":206388}]}]}
{"op":"mcm","clk":"11978648134","pt":1724793341934,"mc":[{"id":"1.232352477","rc":[{"batb":[[0,2.34,30.16],[1,1.03,200],[2,1.02,200]],"ltp":2.42,"tv":56.0,"id":206388}]}]}
{"op":"mcm","clk":"11978648342","pt":1724793345817,"mc":[{"id":"1.232352477","rc":[{"batb":[[0,2.36,5],[1,2.34,30.16],[2,1.03,200]],"ltp":2.42,"tv":56.0,"id":206388}]}]}
{"op":"mcm","clk":"11978648517","pt":1724793349008,"mc":[{"id":"1.232352477","rc":[{"batb":[[0,2.34,30.16],[1,1.03,200],[2,1.02,200]],"ltp":2.42,"tv":56.0,"id":206388}]}]}
{"op":"mcm","clk":"11978648644","pt":1724793351640,"mc":[{"id":"1.232352477","rc":[{"batb":[[0,2.36,5],[1,2.34,30.16],[2,1.03,200]],"ltp":2.42,"tv":56.0,"id":206388}]}]}
{"op":"mcm","clk":"11978648822","pt":1724793354938,"mc":[{"id":"1.232352477","rc":[{"batb":[[0,2.34,30.16],[1,1.03,200],[2,1.02,200]],"ltp":2.42,"tv":56.0,"id":206388}]}]}
{"op":"mcm","clk":"11978648947","pt":1724793357618,"mc":[{"id":"1.232352477","rc":[{"batb":[[0,2.36,5],[1,2.34,30.16],[2,1.03,200]],"ltp":2.42,"tv":56.0,"id":206388}]}]}
{"op":"mcm","clk":"11978649105","pt":1724793361065,"mc":[{"id":"1.232352477","rc":[{"batb":[[0,2.34,30.16],[1,1.03,200],[2,1.02,200]],"ltp":2.42,"tv":56.0,"id":206388}]}]}
{"op":"mcm","clk":"11978649236","pt":1724793363956,"mc":[{"id":"1.232352477","rc":[{"batb":[[0,2.36,5],[1,2.34,30.16],[2,1.03,200]],"ltp":2.42,"tv":56.0,"id":206388}]}]}
{"op":"mcm","clk":"11978649384","pt":1724793367349,"mc":[{"id":"1.232352477","rc":[{"batb":[[0,2.34,30.16],[1,1.03,200],[2,1.02,200]],"ltp":2.42,"tv":56.0,"id":206388}]}]}
{"op":"mcm","clk":"11978649568","pt":1724793371264,"mc":[{"id":"1.232352477","rc":[{"batb":[[0,2.36,5],[1,2.34,30.16],[2,1.03,200]],"ltp":2.42,"tv":56.0,"id":206388}]}]}
{"op":"mcm","clk":"11978649715","pt":1724793374677,"mc":[{"id":"1.232352477","rc":[{"batb":[[0,2.34,30.16],[1,1.03,200],[2,1.02,200]],"ltp":2.42,"tv":56.0,"id":206388}]}]}
{"op":"mcm","clk":"11978649819","pt":1724793376947,"mc":[{"id":"1.232352477","rc":[{"batb":[[0,2.36,5],[1,2.34,30.16],[2,1.03,200]],"ltp":2.42,"tv":56.0,"id":206388}]}]}
{"op":"mcm","clk":"11978649995","pt":1724793380349,"mc":[{"id":"1.232352477","rc":[{"batb":[[0,2.34,30.16],[1,1.03,200],[2,1.02,200]],"ltp":2.42,"tv":56.0,"id":206388}]}]}
{"op":"mcm","clk":"11978650132","pt":1724793382978,"mc":[{"id":"1.232352477","rc":[{"batb":[[0,2.36,5],[1,2.34,30.16],[2,1.03,200]],"ltp":2.42,"tv":56.0,"id":206388}]}]}
{"op":"mcm","clk":"11978650308","pt":1724793386077,"mc":[{"id":"1.232352477","rc":[{"batb":[[0,2.34,30.16],[1,1.03,200],[2,1.02,200]],"ltp":2.42,"tv":56.0,"id":206388}]}]}
{"op":"mcm","clk":"11978650459","pt":1724793389061,"mc":[{"id":"1.232352477","rc":[{"batb":[[0,2.36,5],[1,2.34,30.16],[2,1.03,200]],"ltp":2.42,"tv":56.0,"id":206388}]}]}
{"op":"mcm","clk":"11978650621","pt":1724793392358,"mc":[{"id":"1.232352477","rc":[{"batb":[[0,2.34,30.16],[1,1.03,200],[2,1.02,200]],"ltp":2.42,"tv":56.0,"id":206388}]}]}
{"op":"mcm","clk":"11978650771","pt":1724793394779,"mc":[{"id":"1.232352477","rc":[{"batb":[[0,2.36,5],[1,2.34,30.16],[2,1.03,200]],"ltp":2.42,"tv":56.0,"id":206388}]}]}
{"op":"mcm","clk":"11978650964","pt":1724793398081,"mc":[{"id":"1.232352477","rc":[{"batb":[[0,2.34,30.16],[1,1.03,200],[2,1.02,200]],"ltp":2.42,"tv":56.0,"id":206388}]}]}
{"op":"mcm","clk":"11978651092","pt":1724793400605,"mc":[{"id":"1.232352477","rc":[{"batb":[[0,2.36,5],[1,2.34,30.16],[2,1.03,200]],"ltp":2.42,"tv":56.0,"id":206388}]}]}
{"op":"mcm","clk":"11978651284","pt":1724793403975,"mc":[{"id":"1.232352477","rc":[{"batb":[[0,2.34,30.16],[1,1.03,200],[2,1.02,200]],"ltp":2.42,"tv":56.0,"id":206388}]}]}
{"op":"mcm","clk":"11978651405","pt":1724793406410,"mc":[{"id":"1.232352477","rc":[{"batb":[[0,2.36,5],[1,2.34,30.16],[2,1.03,200]],"ltp":2.42,"tv":56.0,"id":206388}]}]}
{"op":"mcm","clk":"11978651580","pt":1724793409911,"mc":[{"id":"1.232352477","rc":[{"batb":[[0,2.34,30.16],[1,1.03,200],[2,1.02,200]],"ltp":2.42,"tv":56.0,"id":206388}]}]}
{"op":"mcm","clk":"11978651973","pt":1724793416509,"mc":[{"id":"1.232352477","rc":[{"batb":[[0,2.36,5],[1,2.34,30.16],[2,1.03,200]],"ltp":2.42,"tv":56.0,"id":206388}]}]}
{"op":"mcm","clk":"11978652181","pt":1724793419802,"mc":[{"id":"1.232352477","rc":[{"batb":[[0,2.34,30.16],[1,1.03,200],[2,1.02,200]],"ltp":2.42,"tv":56.0,"id":206388}]}]}
{"op":"mcm","clk":"11978652369","pt":1724793422493,"mc":[{"id":"1.232352477","rc":[{"batb":[[0,2.36,5],[1,2.34,30.16],[2,1.03,200]],"ltp":2.42,"tv":56.0,"id":206388}]}]}
{"op":"mcm","clk":"11978652564","pt":1724793425939,"mc":[{"id":"1.232352477","rc":[{"batb":[[0,2.34,30.16],[1,1.03,200],[2,1.02,200]],"ltp":2.42,"tv":56.0,"id":206388}]}]}
{"op":"mcm","clk":"11978652734","pt":1724793428311,"mc":[{"id":"1.232352477","rc":[{"batb":[[0,2.36,5],[1,2.34,30.16],[2,1.03,200]],"ltp":2.42,"tv":56.0,"id":206388}]}]}
{"op":"mcm","clk":"11978652913","pt":1724793431610,"mc":[{"id":"1.232352477","rc":[{"batb":[[0,2.34,30.16],[1,1.03,200],[2,1.02,200]],"ltp":2.42,"tv":56.0,"id":206388}]}]}
{"op":"mcm","clk":"11978653052","pt":1724793434130,"mc":[{"id":"1.232352477","rc":[{"batb":[[0,2.36,5],[1,2.34,30.16],[2,1.03,200]],"ltp":2.42,"tv":56.0,"id":206388}]}]}
{"op":"mcm","clk":"11978653216","pt":1724793437429,"mc":[{"id":"1.232352477","rc":[{"batb":[[0,2.34,30.16],[1,1.03,200],[2,1.02,200]],"ltp":2.42,"tv":56.0,"id":206388}]}]}
{"op":"mcm","clk":"11978653346","pt":1724793439947,"mc":[{"id":"1.232352477","rc":[{"batb":[[0,2.36,5],[1,2.34,30.16],[2,1.03,200]],"ltp":2.42,"tv":56.0,"id":206388}]}]}
{"op":"mcm","clk":"11978653509","pt":1724793443244,"mc":[{"id":"1.232352477","rc":[{"batb":[[0,2.34,30.16],[1,1.03,200],[2,1.02,200]],"ltp":2.42,"tv":56.0,"id":206388}]}]}
{"op":"mcm","clk":"11978653621","pt":1724793445611,"mc":[{"id":"1.232352477","rc":[{"batb":[[0,2.36,5],[1,2.34,30.16],[2,1.03,200]],"ltp":2.42,"tv":56.0,"id":206388}]}]}
{"op":"mcm","clk":"11978653809","pt":1724793449037,"mc":[{"id":"1.232352477","rc":[{"batb":[[0,2.34,30.16],[1,1.03,200],[2,1.02,200]],"ltp":2.42,"tv":56.0,"id":206388}]}]}
{"op":"mcm","clk":"11978654159","pt":1724793454962,"mc":[{"id":"1.232352477","rc":[{"batb":[[0,2.36,5],[1,2.34,30.16],[2,1.03,200]],"ltp":2.42,"tv":56.0,"id":206388}]}]}
{"op":"mcm","clk":"11978654329","pt":1724793458354,"mc":[{"id":"1.232352477","rc":[{"batb":[[0,2.34,30.16],[1,1.03,200],[2,1.02,200]],"ltp":2.42,"tv":56.0,"id":206388}]}]}
{"op":"mcm","clk":"11978654472","pt":1724793460977,"mc":[{"id":"1.232352477","rc":[{"batb":[[0,2.36,5],[1,2.34,30.16],[2,1.03,200]],"ltp":2.42,"tv":56.0,"id":206388}]}]}
{"op":"mcm","clk":"11978654712","pt":1724793464578,"mc":[{"id":"1.232352477","rc":[{"batb":[[0,2.34,30.16],[1,1.03,200],[2,1.02,200]],"ltp":2.42,"tv":56.0,"id":206388}]}]}
{"op":"mcm","clk":"11978654833","pt":1724793466860,"mc":[{"id":"1.232352477","rc":[{"batb":[[0,2.36,5],[1,2.34,30.16],[2,1.03,200]],"ltp":2.42,"tv":56.0,"id":206388}]}]}
{"op":"mcm","clk":"11978655008","pt":1724793470357,"mc":[{"id":"1.232352477","rc":[{"batb":[[0,2.34,30.16],[1,1.03,200],[2,1.02,200]],"ltp":2.42,"tv":56.0,"id":206388}]}]}
{"op":"mcm","clk":"11978655213","pt":1724793473856,"mc":[{"id":"1.232352477","rc":[{"batb":[[0,2.36,5],[1,2.34,30.16],[2,1.03,200]],"ltp":2.42,"tv":56.0,"id":206388}]}]}
{"op":"mcm","clk":"11978655391","pt":1724793477163,"mc":[{"id":"1.232352477","rc":[{"batb":[[0,2.34,30.16],[1,1.03,200],[2,1.02,200]],"ltp":2.42,"tv":56.0,"id":206388}]}]}
{"op":"mcm","clk":"11978655554","pt":1724793480226,"mc":[{"id":"1.232352477","rc":[{"batb":[[0,2.36,5],[1,2.34,30.16],[2,1.03,200]],"ltp":2.42,"tv":56.0,"id":206388}]}]}
{"op":"mcm","clk":"11978655721","pt":1724793483576,"mc":[{"id":"1.232352477","rc":[{"batb":[[0,2.34,30.16],[1,1.03,200],[2,1.02,200]],"ltp":2.42,"tv":56.0,"id":206388}]}]}
{"op":"mcm","clk":"11978655819","pt":1724793485689,"mc":[{"id":"1.232352477","rc":[{"batb":[[0,2.36,5],[1,2.34,30.16],[2,1.03,200]],"ltp":2.42,"tv":56.0,"id":206388}]}]}
{"op":"mcm","clk":"11978655999","pt":1724793488984,"mc":[{"id":"1.232352477","rc":[{"batb":[[0,2.34,30.16],[1,1.03,200],[2,1.02,200]],"ltp":2.42,"tv":56.0,"id":206388}]}]}
{"op":"mcm","clk":"11978656130","pt":1724793491510,"mc":[{"id":"1.232352477","rc":[{"batb":[[0,2.36,5],[1,2.34,30.16],[2,1.03,200]],"ltp":2.42,"tv":56.0,"id":206388}]}]}
{"op":"mcm","clk":"11978656304","pt":1724793494907,"mc":[{"id":"1.232352477","rc":[{"batb":[[0,2.34,30.16],[1,1.03,200],[2,1.02,200]],"ltp":2.42,"tv":56.0,"id":206388}]}]}
{"op":"mcm","clk":"11978656414","pt":1724793497629,"mc":[{"id":"1.232352477","rc":[{"batb":[[0,2.36,5],[1,2.34,30.16],[2,1.03,200]],"ltp":2.42,"tv":56.0,"id":206388}]}]}
{"op":"mcm","clk":"11978656566","pt":1724793500921,"mc":[{"id":"1.232352477","rc":[{"batb":[[0,2.34,30.16],[1,1.03,200],[2,1.02,200]],"ltp":2.42,"tv":56.0,"id":206388}]}]}
{"op":"mcm","clk":"11978656691","pt":1724793503393,"mc":[{"id":"1.232352477","rc":[{"batb":[[0,2.36,5],[1,2.34,30.16],[2,1.03,200]],"ltp":2.42,"tv":56.0,"id":206388}]}]}
{"op":"mcm","clk":"11978656873","pt":1724793506938,"mc":[{"id":"1.232352477","rc":[{"batb":[[0,2.34,30.16],[1,1.03,200],[2,1.02,200]],"ltp":2.42,"tv":56.0,"id":206388}]}]}
{"op":"mcm","clk":"11978657060","pt":1724793510443,"mc":[{"id":"1.232352477","rc":[{"batb":[[0,2.36,5],[1,2.34,30.16],[2,1.03,200]],"ltp":2.42,"tv":56.0,"id":206388}]}]}
{"op":"mcm","clk":"11978657233","pt":1724793513847,"mc":[{"id":"1.232352477","rc":[{"batb":[[0,2.34,30.16],[1,1.03,200],[2,1.02,200]],"ltp":2.42,"tv":56.0,"id":206388}]}]}
{"op":"mcm","clk":"11978657375","pt":1724793516525,"mc":[{"id":"1.232352477","rc":[{"batb":[[0,2.36,5],[1,2.34,30.16],[2,1.03,200]],"ltp":2.42,"tv":56.0,"id":206388}]}]}
{"op":"mcm","clk":"11978657534","pt":1724793519811,"mc":[{"id":"1.232352477","rc":[{"batb":[[0,2.34,30.16],[1,1.03,200],[2,1.02,200]],"ltp":2.42,"tv":56.0,"id":206388}]}]}
{"op":"mcm","clk":"11978657686","pt":1724793522848,"mc":[{"id":"1.232352477","rc":[{"batb":[[0,2.36,5],[1,2.34,30.16],[2,1.03,200]],"ltp":2.42,"tv":56.0,"id":206388}]}]}
{"op":"mcm","clk":"11978657829","pt":1724793526138,"mc":[{"id":"1.232352477","rc":[{"batb":[[0,2.34,30.16],[1,1.03,200],[2,1.02,200]],"ltp":2.42,"tv":56.0,"id":206388}]}]}
{"op":"mcm","clk":"11978657947","pt":1724793529129,"mc":[{"id":"1.232352477","rc":[{"batb":[[0,2.36,5],[1,2.34,30.16],[2,1.03,200]],"ltp":2.42,"tv":56.0,"id":206388}]}]}
{"op":"mcm","clk":"11978658081","pt":1724793532571,"mc":[{"id":"1.232352477","rc":[{"batb":[[0,2.34,30.16],[1,1.03,200],[2,1.02,200]],"ltp":2.42,"tv":56.0,"id":206388}]}]}
{"op":"mcm","clk":"11978658188","pt":1724793535051,"mc":[{"id":"1.232352477","rc":[{"batb":[[0,2.36,5],[1,2.34,30.16],[2,1.03,200]],"ltp":2.42,"tv":56.0,"id":206388}]}]}
{"op":"mcm","clk":"11978658363","pt":1724793538360,"mc":[{"id":"1.232352477","rc":[{"batb":[[0,2.34,30.16],[1,1.03,200],[2,1.02,200]],"ltp":2.42,"tv":56.0,"id":206388}]}]}
{"op":"mcm","clk":"11978658511","pt":1724793540675,"mc":[{"id":"1.232352477","rc":[{"batb":[[0,2.36,5],[1,2.34,30.16],[2,1.03,200]],"ltp":2.42,"tv":56.0,"id":206388}]}]}
{"op":"mcm","clk":"11978658709","pt":1724793544148,"mc":[{"id":"1.232352477","rc":[{"batb":[[0,2.34,30.16],[1,1.03,200],[2,1.02,200]],"ltp":2.42,"tv":56.0,"id":206388}]}]}
{"op":"mcm","clk":"11978658883","pt":1724793547651,"mc":[{"id":"1.232352477","rc":[{"batb":[[0,2.36,5],[1,2.34,30.16],[2,1.03,200]],"ltp":2.42,"tv":56.0,"id":206388}]}]}
{"op":"mcm","clk":"11978659066","pt":1724793551155,"mc":[{"id":"1.232352477","rc":[{"batb":[[0,2.34,30.16],[1,1.03,200],[2,1.02,200]],"ltp":2.42,"tv":56.0,"id":206388}]}]}
{"op":"mcm","clk":"11978659303","pt":1724793555654,"mc":[{"id":"1.232352477","rc":[{"batb":[[0,2.36,5],[1,2.34,30.16],[2,1.03,200]],"ltp":2.42,"tv":56.0,"id":206388}]}]}
{"op":"mcm","clk":"11978659455","pt":1724793559259,"mc":[{"id":"1.232352477","rc":[{"batb":[[0,2.34,30.16],[1,1.03,200],[2,1.02,200]],"ltp":2.42,"tv":56.0,"id":206388}]}]}
{"op":"mcm","clk":"11978659605","pt":1724793562252,"mc":[{"id":"1.232352477","rc":[{"batb":[[0,2.36,5],[1,2.34,30.16],[2,1.03,200]],"ltp":2.42,"tv":56.0,"id":206388}]}]}
{"op":"mcm","clk":"11978659788","pt":1724793565805,"mc":[{"id":"1.232352477","rc":[{"batb":[[0,2.34,30.16],[1,1.03,200],[2,1.02,200]],"ltp":2.42,"tv":56.0,"id":206388}]}]}
{"op":"mcm","clk":"11978660109","pt":1724793571897,"mc":[{"id":"1.232352477","rc":[{"batb":[[0,2.36,5],[1,2.34,30.16],[2,1.03,200]],"ltp":2.42,"tv":56.0,"id":206388}]}]}
{"op":"mcm","clk":"11978660261","pt":1724793575192,"mc":[{"id":"1.232352477","rc":[{"batb":[[0,2.34,30.16],[1,1.03,200],[2,1.02,200]],"ltp":2.42,"tv":56.0,"id":206388}]}]}
{"op":"mcm","clk":"11978660584","pt":1724793581018,"mc":[{"id":"1.232352477","rc":[{"batb":[[0,2.36,5],[1,2.34,30.16],[2,1.03,200]],"ltp":2.42,"tv":56.0,"id":206388}]}]}
{"op":"mcm","clk":"11978660796","pt":1724793584618,"mc":[{"id":"1.232352477","rc":[{"batb":[[0,2.34,30.16],[1,1.03,200],[2,1.02,200]],"ltp":2.42,"tv":56.0,"id":206388}]}]}
{"op":"mcm","clk":"11978660914","pt":1724793587091,"mc":[{"id":"1.232352477","rc":[{"batb":[[0,2.36,5],[1,2.34,30.16],[2,1.03,200]],"ltp":2.42,"tv":56.0,"id":206388}]}]}
{"op":"mcm","clk":"11978661077","pt":1724793590593,"mc":[{"id":"1.232352477","rc":[{"batb":[[0,2.34,30.16],[1,1.03,200],[2,1.02,200]],"ltp":2.42,"tv":56.0,"id":206388}]}]}
{"op":"mcm","clk":"11978661272","pt":1724793594386,"mc":[{"id":"1.232352477","rc":[{"batb":[[0,2.36,5],[1,2.34,30.16],[2,1.03,200]],"ltp":2.42,"tv":56.0,"id":206388}]}]}
{"op":"mcm","clk":"11978661458","pt":1724793597730,"mc":[{"id":"1.232352477","rc":[{"batb":[[0,2.34,30.16],[1,1.03,200],[2,1.02,200]],"ltp":2.42,"tv":56.0,"id":206388}]}]}
{"op":"mcm","clk":"11978661579","pt":1724793600310,"mc":[{"id":"1.232352477","rc":[{"batb":[[0,2.36,5],[1,2.34,30.16],[2,1.03,200]],"ltp":2.42,"tv":56.0,"id":206388}]}]}
{"op":"mcm","clk":"11978661760","pt":1724793603613,"mc":[{"id":"1.232352477","rc":[{"batb":[[0,2.34,30.16],[1,1.03,200],[2,1.02,200]],"ltp":2.42,"tv":56.0,"id":206388}]}]}
{"op":"mcm","clk":"11978662045","pt":1724793608449,"mc":[{"id":"1.232352477","rc":[{"batb":[[0,2.36,5],[1,2.34,30.16],[2,1.03,200]],"ltp":2.42,"tv":56.0,"id":206388}]}]}
{"op":"mcm","clk":"11978662253","pt":1724793611750,"mc":[{"id":"1.232352477","rc":[{"batb":[[0,2.34,30.16],[1,1.03,200],[2,1.02,200]],"ltp":2.42,"tv":56.0,"id":206388}]}]}
{"op":"mcm","clk":"11978662410","pt":1724793614326,"mc":[{"id":"1.232352477","rc":[{"batb":[[0,2.36,5],[1,2.34,30.16],[2,1.03,200]],"ltp":2.42,"tv":56.0,"id":206388}]}]}
{"op":"mcm","clk":"11978662556","pt":1724793617526,"mc":[{"id":"1.232352477","rc":[{"batb":[[0,2.34,30.16],[1,1.03,200],[2,1.02,200]],"ltp":2.42,"tv":56.0,"id":206388}]}]}
{"op":"mcm","clk":"11978662852","pt":1724793622624,"mc":[{"id":"1.232352477","rc":[{"batb":[[0,2.36,5],[1,2.34,30.16],[2,1.03,200]],"ltp":2.42,"tv":56.0,"id":206388}]}]}
{"op":"mcm","clk":"11978663001","pt":1724793625855,"mc":[{"id":"1.232352477","rc":[{"batb":[[0,2.34,30.16],[1,1.03,200],[2,1.02,200]],"ltp":2.42,"tv":56.0,"id":206388}]}]}
{"op":"mcm","clk":"11978663151","pt":1724793629146,"mc":[{"id":"1.232352477","rc":[{"batb":[[0,2.36,5],[1,2.34,30.16],[2,1.03,200]],"ltp":2.42,"tv":56.0,"id":206388}]}]}
{"op":"mcm","clk":"11978663313","pt":1724793632543,"mc":[{"id":"1.232352477","rc":[{"batb":[[0,2.34,30.16],[1,1.03,200],[2,1.02,200]],"ltp":2.42,"tv":56.0,"id":206388}]}]}
{"op":"mcm","clk":"11978663570","pt":1724793637853,"mc":[{"id":"1.232352477","rc":[{"batb":[[0,2.36,5],[1,2.34,30.16],[2,1.03,200]],"ltp":2.42,"tv":56.0,"id":206388}]}]}
{"op":"mcm","clk":"11978663768","pt":1724793641149,"mc":[{"id":"1.232352477","rc":[{"batb":[[0,2.34,30.16],[1,1.03,200],[2,1.02,200]],"ltp":2.42,"tv":56.0,"id":206388}]}]}
{"op":"mcm","clk":"11978663901","pt":1724793643463,"mc":[{"id":"1.232352477","rc":[{"batb":[[0,2.36,5],[1,2.34,30.16],[2,1.03,200]],"ltp":2.42,"tv":56.0,"id":206388}]}]}
{"op":"mcm","clk":"11978664067","pt":1724793646869,"mc":[{"id":"1.232352477","rc":[{"batb":[[0,2.34,30.16],[1,1.03,200],[2,1.02,200]],"ltp":2.42,"tv":56.0,"id":206388}]}]}
{"op":"mcm","clk":"11978664236","pt":1724793650372,"mc":[{"id":"1.232352477","rc":[{"batb":[[0,2.36,5],[1,2.34,30.16],[2,1.03,200]],"ltp":2.42,"tv":56.0,"id":206388}]}]}
{"op":"mcm","clk":"11978664400","pt":1724793653770,"mc":[{"id":"1.232352477","rc":[{"batb":[[0,2.34,30.16],[1,1.03,200],[2,1.02,200]],"ltp":2.42,"tv":56.0,"id":206388}]}]}
{"op":"mcm","clk":"11978664536","pt":1724793656662,"mc":[{"id":"1.232352477","rc":[{"batb":[[0,2.36,5],[1,2.34,30.16],[2,1.03,200]],"ltp":2.42,"tv":56.0,"id":206388}]}]}
{"op":"mcm","clk":"11978664700","pt":1724793659952,"mc":[{"id":"1.232352477","rc":[{"batb":[[0,2.34,30.16],[1,1.03,200],[2,1.02,200]],"ltp":2.42,"tv":56.0,"id":206388}]}]}
{"op":"mcm","clk":"11978664815","pt":1724793662379,"mc":[{"id":"1.232352477","rc":[{"batb":[[0,2.36,5],[1,2.34,30.16],[2,1.03,200]],"ltp":2.42,"tv":56.0,"id":206388}]}]}
{"op":"mcm","clk":"11978664993","pt":1724793665776,"mc":[{"id":"1.232352477","rc":[{"batb":[[0,2.34,30.16],[1,1.03,200],[2,1.02,200]],"ltp":2.42,"tv":56.0,"id":206388}]}]}
{"op":"mcm","clk":"11978665212","pt":1724793670086,"mc":[{"id":"1.232352477","rc":[{"batb":[[0,2.36,5],[1,2.34,30.16],[2,1.03,200]],"ltp":2.42,"tv":56.0,"id":206388}]}]}
{"op":"mcm","clk":"11978665388","pt":1724793673570,"mc":[{"id":"1.232352477","rc":[{"batb":[[0,2.34,30.16],[1,1.03,200],[2,1.02,200]],"ltp":2.42,"tv":56.0,"id":206388}]}]}
{"op":"mcm","clk":"11978665632","pt":1724793678104,"mc":[{"id":"1.232352477","rc":[{"batb":[[0,2.36,5],[1,2.34,30.16],[2,1.03,200]],"ltp":2.42,"tv":56.0,"id":206388}]}]}
{"op":"mcm","clk":"11978665815","pt":1724793681592,"mc":[{"id":"1.232352477","rc":[{"batb":[[0,2.34,30.16],[1,1.03,200],[2,1.02,200]],"ltp":2.42,"tv":56.0,"id":206388}]}]}
{"op":"mcm","clk":"11978665929","pt":1724793683897,"mc":[{"id":"1.232352477","rc":[{"batb":[[0,2.36,5],[1,2.34,30.16],[2,1.03,200]],"ltp":2.42,"tv":56.0,"id":206388}]}]}
{"op":"mcm","clk":"11978666076","pt":1724793687283,"mc":[{"id":"1.232352477","rc":[{"batb":[[0,2.34,30.16],[1,1.03,200],[2,1.02,200]],"ltp":2.42,"tv":56.0,"id":206388}]}]}
{"op":"mcm","clk":"11978666191","pt":1724793689492,"mc":[{"id":"1.232352477","rc":[{"batb":[[0,2.36,5],[1,2.34,30.16],[2,1.03,200]],"ltp":2.42,"tv":56.0,"id":206388}]}]}
{"op":"mcm","clk":"11978666461","pt":1724793692984,"mc":[{"id":"1.232352477","rc":[{"batb":[[0,2.34,30.16],[1,1.03,200],[2,1.02,200]],"ltp":2.42,"tv":56.0,"id":206388}]}]}
{"op":"mcm","clk":"11978666853","pt":1724793700417,"mc":[{"id":"1.232352477","rc":[{"batb":[[0,2.36,5],[1,2.34,30.16],[2,1.03,200]],"ltp":2.42,"tv":56.0,"id":206388}]}]}
{"op":"mcm","clk":"11978667046","pt":1724793703817,"mc":[{"id":"1.232352477","rc":[{"batb":[[0,2.34,30.16],[1,1.03,200],[2,1.02,200]],"ltp":2.42,"tv":56.0,"id":206388}]}]}
{"op":"mcm","clk":"11978667296","pt":1724793709625,"mc":[{"id":"1.232352477","rc":[{"batb":[[0,2.36,5],[1,2.34,30.16],[2,1.03,200]],"ltp":2.42,"tv":56.0,"id":206388}]}]}
{"op":"mcm","clk":"11978667466","pt":1724793713098,"mc":[{"id":"1.232352477","rc":[{"batb":[[0,2.34,30.16],[1,1.03,200],[2,1.02,200]],"ltp":2.42,"tv":56.0,"id":206388}]}]}
{"op":"mcm","clk":"11978667695","pt":1724793717017,"mc":[{"id":"1.232352477","rc":[{"batb":[[0,2.36,5],[1,2.34,30.16],[2,1.03,200]],"ltp":2.42,"tv":56.0,"id":206388}]}]}
{"op":"mcm","clk":"11978667856","pt":1724793720310,"mc":[{"id":"1.232352477","rc":[{"batb":[[0,2.34,30.16],[1,1.03,200],[2,1.02,200]],"ltp":2.42,"tv":56.0,"id":206388}]}]}
{"op":"mcm","clk":"11978668008","pt":1724793723137,"mc":[{"id":"1.232352477","rc":[{"batb":[[0,2.36,5],[1,2.34,30.16],[2,1.03,200]],"ltp":2.42,"tv":56.0,"id":206388}]}]}
