{"op":"mcm","clk":"11859413171","pt":1723384047472,"mc":[{"id":"1.231705583","marketDefinition":{"bspMarket":false,"turnInPlayEnabled":true,"persistenceEnabled":true,"marketBaseRate":5.0,"eventId":"33486371","eventTypeId":"4","numberOfWinners":1,"bettingType":"ODDS","marketType":"MATCH_ODDS","marketTime":"2024-08-14T10:00:00.000Z","suspendTime":"2024-08-14T10:00:00.000Z","bspReconciled":false,"complete":true,"inPlay":false,"crossMatching":false,"runnersVoidable":false,"numberOfActiveRunners":2,"betDelay":0,"status":"OPEN","runners":[{"status":"ACTIVE","sortPriority":1,"id":169,"name":"Glamorgan"},{"status":"ACTIVE","sortPriority":2,"id":655,"name":"Yorkshire"}],"regulators":["MR_INT"],"countryCode":"GB","discountAllowed":false,"timezone":"GMT","openDate":"2024-08-14T10:00:00.000Z","version":6069573794,"name":"Match Odds","eventName":"Glamorgan v Yorkshire"},"rc":[{"batb":[[0,1.03,200],[1,1.02,200],[2,1.01,220]],"ltp":0.0,"tv":0.0,"id":655},{"batb":[[0,1.03,200],[1,1.02,200],[2,1.01,220]],"ltp":0.0,"tv":0.0,"id":169}]}]}
{"op":"mcm","clk":"11859413586","pt":1723384050502,"mc":[{"id":"1.231705583","marketDefinition":{"bspMarket":false,"turnInPlayEnabled":true,"persistenceEnabled":true,"marketBaseRate":5.0,"eventId":"33486371","eventTypeId":"4","numberOfWinners":1,"bettingType":"ODDS","marketType":"MATCH_ODDS","marketTime":"2024-08-14T10:00:00.000Z","suspendTime":"2024-08-14T10:00:00.000Z","bspReconciled":false,"complete":true,"inPlay":false,"crossMatching":false,"runnersVoidable":false,"numberOfActiveRunners":2,"betDelay":0,"status":"OPEN","runners":[{"status":"ACTIVE","sortPriority":1,"id":169,"name":"Glamorgan"},{"status":"ACTIVE","sortPriority":2,"id":655,"name":"Yorkshire"}],"regulators":["MR_INT"],"countryCode":"GB","discountAllowed":true,"timezone":"GMT","openDate":"2024-08-14T10:00:00.000Z","version":6069573794,"name":"Match Odds","eventName":"Glamorgan v Yorkshire"}}]}
{"op":"mcm","clk":"11859874871","pt":1723386776356,"mc":[{"id":"1.231705583","rc":[{"batb":[[2,1.01,227.85]],"ltp":0.0,"tv":0.0,"id":655},{"batb":[[2,1.01,227.85]],"ltp":0.0,"tv":0.0,"id":169}]}]}
{"op":"mcm","clk":"11859877741","pt":1723386791304,"mc":[{"id":"1.231705583","rc":[{"batb":[[1,1.02,207.85]],"ltp":0.0,"tv":0.0,"id":655},{"batb":[[1,1.02,207.85]],"ltp":0.0,"tv":0.0,"id":169}]}]}
{"op":"mcm","clk":"11859880275","pt":1723386804271,"mc":[{"id":"1.231705583","rc":[{"batb":[[0,1.03,239.27]],"ltp":0.0,"tv":0.0,"id":655},{"batb":[[0,1.03,239.27]],"ltp":0.0,"tv":0.0,"id":169}]}]}
{"op":"mcm","clk":"11859883749","pt":1723386823151,"mc":[{"id":"1.231705583","rc":[{"batb":[[0,1.03,200],[1,1.02,247.13]],"ltp":0.0,"tv":0.0,"id":655},{"batb":[[0,1.03,200],[1,1.02,247.13]],"ltp":0.0,"tv":0.0,"id":169}]}]}
{"op":"mcm","clk":"11859886530","pt":1723386837876,"mc":[{"id":"1.231705583","rc":[{"batb":[[0,1.03,207.85]],"ltp":0.0,"tv":0.0,"id":655},{"batb":[[0,1.03,207.85]],"ltp":0.0,"tv":0.0,"id":169}]}]}
{"op":"mcm","clk":"11859889103","pt":1723386850353,"mc":[{"id":"1.231705583","rc":[{"batb":[[0,1.04,7.85],[1,1.03,207.85],[2,1.02,247.13]],"ltp":0.0,"tv":0.0,"id":655},{"batb":[[0,1.04,7.85],[1,1.03,207.85],[2,1.02,247.13]],"ltp":0.0,"tv":0.0,"id":169}]}]}
{"op":"mcm","clk":"11859891375","pt":1723386861778,"mc":[{"id":"1.231705583","rc":[{"batb":[[0,1.05,7.85],[1,1.04,7.85],[2,1.03,207.85]],"ltp":0.0,"tv":0.0,"id":655},{"batb":[[0,1.05,7.85],[1,1.04,7.85],[2,1.03,207.85]],"ltp":0.0,"tv":0.0,"id":169}]}]}
{"op":"mcm","clk":"11859894028","pt":1723386874388,"mc":[{"id":"1.231705583","rc":[{"batb":[[0,1.06,7.85],[1,1.05,7.85],[2,1.04,7.85]],"ltp":0.0,"tv":0.0,"id":655},{"batb":[[0,1.06,7.85],[1,1.05,7.85],[2,1.04,7.85]],"ltp":0.0,"tv":0.0,"id":169}]}]}
{"op":"mcm","clk":"11859896715","pt":1723386887298,"mc":[{"id":"1.231705583","rc":[{"batb":[[0,1.07,7.85],[1,1.06,7.85],[2,1.05,7.85]],"ltp":0.0,"tv":0.0,"id":655},{"batb":[[0,1.07,7.85],[1,1.06,7.85],[2,1.05,7.85]],"ltp":0.0,"tv":0.0,"id":169}]}]}
{"op":"mcm","clk":"11859899903","pt":1723386903855,"mc":[{"id":"1.231705583","rc":[{"batb":[[0,1.08,7.85],[1,1.07,7.85],[2,1.06,7.85]],"ltp":0.0,"tv":0.0,"id":655},{"batb":[[0,1.08,7.85],[1,1.07,7.85],[2,1.06,7.85]],"ltp":0.0,"tv":0.0,"id":169}]}]}
{"op":"mcm","clk":"11860857649","pt":1723392489733,"mc":[{"id":"1.231705583","rc":[{"batb":[[0,1.09,95.53],[1,1.08,7.85],[2,1.07,7.85]],"ltp":0.0,"tv":0.0,"id":655},{"batb":[[0,1.09,95.53],[1,1.08,7.85],[2,1.07,7.85]],"ltp":0.0,"tv":0.0,"id":169}]}]}
{"op":"mcm","clk":"11860862267","pt":1723392514457,"mc":[{"id":"1.231705583","marketDefinition":{"bspMarket":false,"turnInPlayEnabled":true,"persistenceEnabled":true,"marketBaseRate":5.0,"eventId":"33486371","eventTypeId":"4","numberOfWinners":1,"bettingType":"ODDS","marketType":"MATCH_ODDS","marketTime":"2024-08-14T10:00:00.000Z","suspendTime":"2024-08-14T10:00:00.000Z","bspReconciled":false,"complete":true,"inPlay":false,"crossMatching":true,"runnersVoidable":false,"numberOfActiveRunners":2,"betDelay":0,"status":"OPEN","runners":[{"status":"ACTIVE","sortPriority":1,"id":169,"name":"Glamorgan"},{"status":"ACTIVE","sortPriority":2,"id":655,"name":"Yorkshire"}],"regulators":["MR_INT"],"countryCode":"GB","discountAllowed":true,"timezone":"GMT","openDate":"2024-08-14T10:00:00.000Z","version":6069573794,"name":"Match Odds","eventName":"Glamorgan v Yorkshire"}}]}
{"op":"mcm","clk":"11861165150","pt":1723394290885,"mc":[{"id":"1.231705583","rc":[{"batb":[[0,1.08,7.85],[1,1.07,7.85],[2,1.06,7.85]],"ltp":0.0,"tv":0.0,"id":655},{"batb":[[0,1.08,7.85],[1,1.07,7.85],[2,1.06,7.85]],"ltp":0.0,"tv":0.0,"id":169}]}]}
{"op":"mcm","clk":"11861174606","pt":1723394342817,"mc":[{"id":"1.231705583","rc":[{"batb":[[0,1.09,95.53],[1,1.08,7.85],[2,1.07,7.85]],"ltp":0.0,"tv":0.0,"id":655},{"batb":[[0,1.09,95.53],[1,1.08,7.85],[2,1.07,7.85]],"ltp":0.0,"tv":0.0,"id":169}]}]}
{"op":"mcm","clk":"11861450601","pt":1723396145771,"mc":[{"id":"1.231705583","rc":[{"batb":[[0,1.08,7.85],[1,1.07,7.85],[2,1.06,7.85]],"ltp":0.0,"tv":0.0,"id":655},{"batb":[[0,1.08,7.85],[1,1.07,7.85],[2,1.06,7.85]],"ltp":0.0,"tv":0.0,"id":169}]}]}
{"op":"mcm","clk":"11861456148","pt":1723396177284,"mc":[{"id":"1.231705583","rc":[{"batb":[[0,1.09,95.53],[1,1.08,7.85],[2,1.07,7.85]],"ltp":0.0,"tv":0.0,"id":655},{"batb":[[0,1.09,95.53],[1,1.08,7.85],[2,1.07,7.85]],"ltp":0.0,"tv":0.0,"id":169}]}]}
{"op":"mcm","clk":"11861734667","pt":1723397761494,"mc":[{"id":"1.231705583","rc":[{"batb":[[0,1.25,100],[1,1.09,95.53],[2,1.08,7.85]],"ltp":0.0,"tv":0.0,"id":655},{"batb":[[0,1.25,100],[1,1.09,95.53],[2,1.08,7.85]],"ltp":0.0,"tv":0.0,"id":169}]}]}
{"op":"mcm","clk":"11861773931","pt":1723397977602,"mc":[{"id":"1.231705583","rc":[{"batb":[[1,1.08,7.85],[2,1.07,7.85]],"ltp":0.0,"tv":0.0,"id":655},{"batb":[[1,1.08,7.85],[2,1.07,7.85]],"ltp":0.0,"tv":0.0,"id":169}]}]}
{"op":"mcm","clk":"11861787097","pt":1723398055680,"mc":[{"id":"1.231705583","rc":[{"batb":[[0,1.26,33.07],[1,1.25,100],[2,1.08,7.85]],"ltp":0.0,"tv":0.0,"id":655},{"batb":[[0,1.26,33.07],[1,1.25,100],[2,1.08,7.85]],"ltp":0.0,"tv":0.0,"id":169}]}]}
{"op":"mcm","clk":"11861987873","pt":1723399363290,"mc":[{"id":"1.231705583","rc":[{"batb":[[0,1.27,6.09],[1,1.26,33.07],[2,1.25,100]],"ltp":0.0,"tv":0.0,"id":169}]}]}
{"op":"mcm","clk":"11861987917","pt":1723399363600,"mc":[{"id":"1.231705583","rc":[{"batb":[[0,1.27,6.44],[1,1.26,33.07],[2,1.25,100]],"ltp":0.0,"tv":0.0,"id":655}]}]}
{"op":"mcm","clk":"11862069761","pt":1723399856116,"mc":[{"id":"1.231705583","rc":[{"batb":[[1,1.25,100],[2,1.08,7.85]],"ltp":0.0,"tv":0.0,"id":655},{"batb":[[1,1.25,100],[2,1.08,7.85]],"ltp":0.0,"tv":0.0,"id":169}]}]}
{"op":"mcm","clk":"11862080684","pt":1723399928214,"mc":[{"id":"1.231705583","rc":[{"batb":[[0,1.28,30.71],[1,1.27,6.44],[2,1.25,100]],"ltp":0.0,"tv":0.0,"id":655},{"batb":[[0,1.28,30.71],[1,1.27,6.09],[2,1.25,100]],"ltp":0.0,"tv":0.0,"id":169}]}]}
{"op":"mcm","clk":"11862177255","pt":1723400499849,"mc":[{"id":"1.231705583","rc":[{"batb":[[0,2.28,3.14],[1,1.28,30.71],[2,1.27,6.44]],"ltp":0.0,"tv":0.0,"id":655},{"batb":[[0,1.72,5.59],[1,1.28,30.71],[2,1.27,6.09]],"ltp":0.0,"tv":0.0,"id":169}]}]}
{"op":"mcm","clk":"11862356494","pt":1723401537503,"mc":[{"id":"1.231705583","rc":[{"batb":[[2,1.25,100]],"ltp":0.0,"tv":0.0,"id":169}]}]}
{"op":"mcm","clk":"11862356544","pt":1723401537825,"mc":[{"id":"1.231705583","rc":[{"batb":[[2,1.25,100]],"ltp":0.0,"tv":0.0,"id":655}]}]}
{"op":"mcm","clk":"11862391987","pt":1723401728349,"mc":[{"id":"1.231705583","rc":[{"batb":[[1,1.25,100],[2,1.08,7.85]],"ltp":0.0,"tv":0.0,"id":169}]}]}
{"op":"mcm","clk":"11862392059","pt":1723401728716,"mc":[{"id":"1.231705583","rc":[{"batb":[[1,1.25,100],[2,1.08,7.85]],"ltp":0.0,"tv":0.0,"id":655}]}]}
{"op":"mcm","clk":"11863413539","pt":1723407174973,"mc":[{"id":"1.231705583","rc":[{"batb":[[2,1.08,7.84]],"ltp":0.0,"tv":0.0,"id":655},{"batb":[[2,1.08,7.84]],"ltp":0.0,"tv":0.0,"id":169}]}]}
{"op":"mcm","clk":"11863961740","pt":1723411199432,"mc":[{"id":"1.231705583","rc":[{"batb":[[2,1.08,7.83]],"ltp":0.0,"tv":0.0,"id":655},{"batb":[[2,1.08,7.83]],"ltp":0.0,"tv":0.0,"id":169}]}]}
{"op":"mcm","clk":"11864540998","pt":1723417974934,"mc":[{"id":"1.231705583","rc":[{"batb":[[2,1.08,7.84]],"ltp":0.0,"tv":0.0,"id":655},{"batb":[[2,1.08,7.84]],"ltp":0.0,"tv":0.0,"id":169}]}]}
{"op":"mcm","clk":"11864819571","pt":1723423374955,"mc":[{"id":"1.231705583","rc":[{"batb":[[2,1.08,7.84]],"ltp":0.0,"tv":0.0,"id":655},{"batb":[[2,1.08,7.84]],"ltp":0.0,"tv":0.0,"id":169}]}]}
{"op":"mcm","clk":"11864996286","pt":1723428774948,"mc":[{"id":"1.231705583","rc":[{"batb":[[2,1.08,7.84]],"ltp":0.0,"tv":0.0,"id":655},{"batb":[[2,1.08,7.84]],"ltp":0.0,"tv":0.0,"id":169}]}]}
{"op":"mcm","clk":"11865159518","pt":1723434174948,"mc":[{"id":"1.231705583","rc":[{"batb":[[2,1.08,7.84]],"ltp":0.0,"tv":0.0,"id":655},{"batb":[[2,1.08,7.84]],"ltp":0.0,"tv":0.0,"id":169}]}]}
{"op":"mcm","clk":"11865502488","pt":1723444974928,"mc":[{"id":"1.231705583","rc":[{"batb":[[2,1.08,7.83]],"ltp":0.0,"tv":0.0,"id":655},{"batb":[[2,1.08,7.83]],"ltp":0.0,"tv":0.0,"id":169}]}]}
{"op":"mcm","clk":"11865654969","pt":1723450374993,"mc":[{"id":"1.231705583","rc":[{"batb":[[2,1.08,7.83]],"ltp":0.0,"tv":0.0,"id":655},{"batb":[[2,1.08,7.83]],"ltp":0.0,"tv":0.0,"id":169}]}]}
{"op":"mcm","clk":"11865675342","pt":1723450980880,"mc":[{"id":"1.231705583","rc":[{"trd":[[1.72,0.4]],"batb":[[0,1.72,5.39]],"ltp":1.72,"tv":0.4,"id":169}],"tv":0.4}]}
{"op":"mcm","clk":"11865675457","pt":1723450984421,"mc":[{"id":"1.231705583","rc":[{"batb":[[0,1.72,5.59]],"ltp":1.72,"tv":0.4,"id":169}]}]}
{"op":"mcm","clk":"11865687586","pt":1723451345484,"mc":[{"id":"1.231705583","rc":[{"trd":[[1.72,0.8]],"batb":[[0,1.72,10.98]],"ltp":1.72,"tv":0.8,"id":169}],"tv":0.8}]}
{"op":"mcm","clk":"11865687589","pt":1723451345587,"mc":[{"id":"1.231705583","rc":[{"batb":[[0,1.72,5.59]],"ltp":1.72,"tv":0.8,"id":169}]}]}
{"op":"mcm","clk":"11865690045","pt":1723451415346,"mc":[{"id":"1.231705583","rc":[{"trd":[[1.72,1.2]],"batb":[[0,1.72,5.39]],"ltp":1.72,"tv":1.2,"id":169}],"tv":1.2}]}
{"op":"mcm","clk":"11865690065","pt":1723451415761,"mc":[{"id":"1.231705583","rc":[{"batb":[[0,1.72,5.59]],"ltp":1.72,"tv":1.2,"id":169}]}]}
{"op":"mcm","clk":"11865898902","pt":1723455774936,"mc":[{"id":"1.231705583","rc":[{"batb":[[2,1.08,7.83]],"ltp":0.0,"tv":0.0,"id":655},{"batb":[[2,1.08,7.83]],"ltp":1.72,"tv":1.2,"id":169}]}]}
{"op":"mcm","clk":"11865919054","pt":1723456101846,"mc":[{"id":"1.231705583","rc":[{"batb":[[0,1.45,164.26]],"ltp":0.0,"tv":0.0,"id":655},{"batb":[[0,1.27,188.03]],"ltp":1.72,"tv":1.2,"id":169}]}]}
{"op":"mcm","clk":"11865923819","pt":1723456172318,"mc":[{"id":"1.231705583","rc":[{"batb":[[0,1.46,18.69],[1,1.45,164.26],[2,1.25,100]],"ltp":0.0,"tv":0.0,"id":655},{"batb":[[0,1.28,30.71],[1,1.27,188.03],[2,1.25,100]],"ltp":1.72,"tv":1.2,"id":169}]}]}
{"op":"mcm","clk":"11865937272","pt":1723456431377,"mc":[{"id":"1.231705583","rc":[{"batb":[[0,1.48,160.88],[1,1.46,18.69]],"ltp":0.0,"tv":0.0,"id":655},{"trd":[[1.28,0.4]],"batb":[[0,1.32,180.8],[1,1.28,30.51]],"ltp":1.28,"tv":1.6,"id":169}],"tv":1.6}]}
{"op":"mcm","clk":"11865997140","pt":1723457464759,"mc":[{"id":"1.231705583","rc":[{"batb":[[0,2.28,31.73],[1,1.48,160.88],[2,1.46,18.71]],"ltp":0.0,"tv":0.0,"id":655},{"batb":[[0,1.72,56.42],[1,1.32,180.8],[2,1.28,30.53]],"ltp":1.28,"tv":1.6,"id":169}]}]}
{"op":"mcm","clk":"11866029750","pt":1723457972822,"mc":[{"id":"1.231705583","rc":[{"batb":[[1,1.25,100],[2,1.08,7.84]],"ltp":0.0,"tv":0.0,"id":655},{"batb":[[1,1.25,100],[2,1.08,7.84]],"ltp":1.28,"tv":1.6,"id":169}]}]}
{"op":"mcm","clk":"11866173132","pt":1723460630603,"mc":[{"id":"1.231705583","rc":[{"trd":[[1.72,5.2]],"batb":[[0,1.72,54.42]],"ltp":1.72,"tv":5.6,"id":169}],"tv":5.6}]}
{"op":"mcm","clk":"11866173348","pt":1723460634924,"mc":[{"id":"1.231705583","rc":[{"batb":[[0,1.72,56.42]],"ltp":1.72,"tv":5.6,"id":169}]}]}
{"op":"mcm","clk":"11866250518","pt":1723461849600,"mc":[{"id":"1.231705583","rc":[{"batb":[[1,1.74,1],[2,1.25,100]],"ltp":0.0,"tv":0.0,"id":655},{"batb":[[0,1.74,1],[1,1.72,56.42],[2,1.25,100]],"ltp":1.72,"tv":5.6,"id":169}]}]}
{"op":"mcm","clk":"11866532628","pt":1723467044467,"mc":[{"id":"1.231705583","rc":[{"batb":[[2,1.08,7.83]],"ltp":0.0,"tv":0.0,"id":655},{"batb":[[2,1.08,7.83]],"ltp":1.72,"tv":5.6,"id":169}]}]}
{"op":"mcm","clk":"11866549525","pt":1723467389395,"mc":[{"id":"1.231705583","rc":[{"batb":[[2,1.3,1166.67]],"ltp":0.0,"tv":0.0,"id":655},{"batb":[[2,1.3,1166.67]],"ltp":1.72,"tv":5.6,"id":169}]}]}
{"op":"mcm","clk":"11866552419","pt":1723467458080,"mc":[{"id":"1.231705583","rc":[{"batb":[[2,1.08,7.83]],"ltp":0.0,"tv":0.0,"id":655},{"batb":[[2,1.08,7.83]],"ltp":1.72,"tv":5.6,"id":169}]}]}
{"op":"mcm","clk":"11866553558","pt":1723467485718,"mc":[{"id":"1.231705583","rc":[{"batb":[[2,1.25,100]],"ltp":0.0,"tv":0.0,"id":655},{"batb":[[2,1.25,100]],"ltp":1.72,"tv":5.6,"id":169}]}]}
{"op":"mcm","clk":"11866681567","pt":1723469715460,"mc":[{"id":"1.231705583","rc":[{"batb":[[0,2.28,30.26]],"ltp":0.0,"tv":0.0,"id":655},{"batb":[[1,1.72,53.81]],"ltp":1.72,"tv":5.6,"id":169}]}]}
{"op":"mcm","clk":"11866932310","pt":1723473871478,"mc":[{"id":"1.231705583","rc":[{"trd":[[1.74,2]],"batb":[[0,1.72,53.81],[1,1.25,100],[2,1.08,7.83]],"ltp":1.74,"tv":7.6,"id":169}],"tv":7.6}]}
{"op":"mcm","clk":"11866932889","pt":1723473879652,"mc":[{"id":"1.231705583","rc":[{"trd":[[2.28,0.79]],"batb":[[0,2.28,29.47]],"ltp":2.28,"tv":0.79,"id":655},{"trd":[[1.79,1]],"ltp":1.79,"tv":8.6,"id":169}],"tv":9.39}]}
{"op":"mcm","clk":"11866933144","pt":1723473884365,"mc":[{"id":"1.231705583","rc":[{"batb":[[0,2.28,30.26]],"ltp":2.28,"tv":0.79,"id":655}]}]}
{"op":"mcm","clk":"11866948484","pt":1723474147435,"mc":[{"id":"1.231705583","rc":[{"trd":[[1.72,105.2]],"batb":[[0,1.72,3.81]],"ltp":1.72,"tv":108.6,"id":169}],"tv":109.39}]}
{"op":"mcm","clk":"11866948644","pt":1723474150218,"mc":[{"id":"1.231705583","rc":[{"batb":[[0,1.68,56.97]],"ltp":1.72,"tv":108.6,"id":169}]}]}
{"op":"mcm","clk":"11867178320","pt":1723477374930,"mc":[{"id":"1.231705583","rc":[{"batb":[[2,1.08,7.82]],"ltp":1.72,"tv":108.6,"id":169}],"tv":109.39}]}
{"op":"mcm","clk":"11867591769","pt":1723482775490,"mc":[{"id":"1.231705583","rc":[{"trd":[[1.72,105.2]],"batb":[[2,1.08,7.84]],"ltp":1.72,"tv":108.6,"id":169}],"tv":109.39}]}
{"op":"mcm","clk":"11867607770","pt":1723482923603,"mc":[{"id":"1.231705583","rc":[{"batl":[[0,1.73,50]],"ltp":1.72,"tv":108.6,"id":169}]}]}
{"op":"mcm","clk":"11868060022","pt":1723488174939,"mc":[{"id":"1.231705583","rc":[{"batb":[[2,1.08,7.83]],"ltp":1.72,"tv":108.6,"id":169}]}]}
{"op":"mcm","clk":"11869285609","pt":1723509774941,"mc":[{"id":"1.231705583","rc":[{"batb":[[2,1.08,7.83]],"ltp":1.72,"tv":108.6,"id":169}]}]}
{"op":"mcm","clk":"11869547037","pt":1723515174967,"mc":[{"id":"1.231705583","rc":[{"batb":[[2,1.08,7.83]],"ltp":1.72,"tv":108.6,"id":169}]}]}
{"op":"mcm","clk":"11869954899","pt":1723525974963,"mc":[{"id":"1.231705583","rc":[{"batb":[[2,1.08,7.83]],"ltp":1.72,"tv":108.6,"id":169}]}]}
{"op":"mcm","clk":"11870239976","pt":1723536774992,"mc":[{"id":"1.231705583","rc":[{"trd":[[1.28,0.4],[1.72,105.2]],"batb":[[2,1.08,7.81]],"ltp":1.72,"tv":108.6,"id":169}],"tv":109.39}]}
{"op":"mcm","clk":"11870419538","pt":1723542174989,"mc":[{"id":"1.231705583","rc":[{"batb":[[2,1.08,7.81]],"ltp":1.72,"tv":108.6,"id":169}]}]}
{"op":"mcm","clk":"11870595930","pt":1723546164429,"mc":[{"id":"1.231705583","rc":[{"trd":[[1.73,4.04]],"batb":[[2,1.08,7.82]],"batl":[[0,1.73,47.98]],"ltp":1.73,"tv":112.64,"id":169}],"tv":113.43}]}
{"op":"mcm","clk":"11870604174","pt":1723546350315,"mc":[{"id":"1.231705583","rc":[{"batl":[[0,2.5,1]],"ltp":2.28,"tv":0.79,"id":655}]}]}
{"op":"mcm","clk":"11870618207","pt":1723546802518,"mc":[{"id":"1.231705583","rc":[{"batb":[[0,2.3,10],[1,2.28,30.26],[2,1.74,1]],"ltp":2.28,"tv":0.79,"id":655}]}]}
{"op":"mcm","clk":"11870618415","pt":1723546806516,"mc":[{"id":"1.231705583","rc":[{"batb":[[0,2.28,30.26],[1,1.74,1],[2,1.25,100]],"ltp":2.28,"tv":0.79,"id":655},{"batb":[[2,1.08,7.82]],"ltp":1.73,"tv":112.64,"id":169}]}]}
{"op":"mcm","clk":"11870618579","pt":1723546810245,"mc":[{"id":"1.231705583","rc":[{"batb":[[0,2.3,10],[1,2.28,30.26],[2,1.74,1]],"ltp":2.28,"tv":0.79,"id":655}]}]}
{"op":"mcm","clk":"11870618745","pt":1723546813627,"mc":[{"id":"1.231705583","rc":[{"batb":[[0,2.28,30.26],[1,1.74,1],[2,1.25,100]],"ltp":2.28,"tv":0.79,"id":655}]}]}
{"op":"mcm","clk":"11870619048","pt":1723546819967,"mc":[{"id":"1.231705583","rc":[{"batb":[[0,2.3,10],[1,2.28,30.26],[2,1.74,1]],"ltp":2.28,"tv":0.79,"id":655}]}]}
{"op":"mcm","clk":"11870619219","pt":1723546823539,"mc":[{"id":"1.231705583","rc":[{"batb":[[0,2.28,30.26],[1,1.74,1],[2,1.25,100]],"ltp":2.28,"tv":0.79,"id":655}]}]}
{"op":"mcm","clk":"11870619457","pt":1723546829372,"mc":[{"id":"1.231705583","rc":[{"batb":[[0,2.3,10],[1,2.28,30.26],[2,1.74,1]],"ltp":2.28,"tv":0.79,"id":655}]}]}
{"op":"mcm","clk":"11870619614","pt":1723546832683,"mc":[{"id":"1.231705583","rc":[{"batb":[[0,2.28,30.26],[1,1.74,1],[2,1.25,100]],"ltp":2.28,"tv":0.79,"id":655}]}]}
{"op":"mcm","clk":"11870619760","pt":1723546835586,"mc":[{"id":"1.231705583","rc":[{"batb":[[0,2.3,10],[1,2.28,30.26],[2,1.74,1]],"ltp":2.28,"tv":0.79,"id":655}]}]}
{"op":"mcm","clk":"11870619922","pt":1723546839090,"mc":[{"id":"1.231705583","rc":[{"batb":[[0,2.28,30.26],[1,1.74,1],[2,1.25,100]],"ltp":2.28,"tv":0.79,"id":655}]}]}
{"op":"mcm","clk":"11870620067","pt":1723546842373,"mc":[{"id":"1.231705583","rc":[{"batb":[[0,2.3,10],[1,2.28,30.26],[2,1.74,1]],"ltp":2.28,"tv":0.79,"id":655}]}]}
{"op":"mcm","clk":"11870620184","pt":1723546845883,"mc":[{"id":"1.231705583","rc":[{"batb":[[0,2.28,30.26],[1,1.74,1],[2,1.25,100]],"ltp":2.28,"tv":0.79,"id":655}]}]}
{"op":"mcm","clk":"11870620312","pt":1723546849462,"mc":[{"id":"1.231705583","rc":[{"batb":[[0,2.3,10],[1,2.28,30.26],[2,1.74,1]],"ltp":2.28,"tv":0.79,"id":655}]}]}
{"op":"mcm","clk":"11870620483","pt":1723546853080,"mc":[{"id":"1.231705583","rc":[{"batb":[[0,2.28,30.26],[1,1.74,1],[2,1.25,100]],"ltp":2.28,"tv":0.79,"id":655}]}]}
{"op":"mcm","clk":"11870620645","pt":1723546856592,"mc":[{"id":"1.231705583","rc":[{"batb":[[0,2.3,10],[1,2.28,30.26],[2,1.74,1]],"ltp":2.28,"tv":0.79,"id":655}]}]}
{"op":"mcm","clk":"11870620826","pt":1723546860112,"mc":[{"id":"1.231705583","rc":[{"batb":[[0,2.28,30.26],[1,1.74,1],[2,1.25,100]],"ltp":2.28,"tv":0.79,"id":655}]}]}
{"op":"mcm","clk":"11870621030","pt":1723546865285,"mc":[{"id":"1.231705583","rc":[{"batb":[[0,2.3,10],[1,2.28,30.26],[2,1.74,1]],"ltp":2.28,"tv":0.79,"id":655}]}]}
{"op":"mcm","clk":"11870621196","pt":1723546868791,"mc":[{"id":"1.231705583","rc":[{"batb":[[0,2.28,30.26],[1,1.74,1],[2,1.25,100]],"ltp":2.28,"tv":0.79,"id":655}]}]}
{"op":"mcm","clk":"11870621387","pt":1723546873021,"mc":[{"id":"1.231705583","rc":[{"batb":[[0,2.3,10],[1,2.28,30.26],[2,1.74,1]],"ltp":2.28,"tv":0.79,"id":655}]}]}
{"op":"mcm","clk":"11870621584","pt":1723546876726,"mc":[{"id":"1.231705583","rc":[{"batb":[[0,2.28,30.26],[1,1.74,1],[2,1.25,100]],"ltp":2.28,"tv":0.79,"id":655}]}]}
{"op":"mcm","clk":"11870621951","pt":1723546884634,"mc":[{"id":"1.231705583","rc":[{"batb":[[0,2.3,10],[1,2.28,30.26],[2,1.74,1]],"ltp":2.28,"tv":0.79,"id":655}]}]}
{"op":"mcm","clk":"11870622163","pt":1723546888137,"mc":[{"id":"1.231705583","rc":[{"batb":[[0,2.28,30.26],[1,1.74,1],[2,1.25,100]],"ltp":2.28,"tv":0.79,"id":655}]}]}
{"op":"mcm","clk":"11870622423","pt":1723546894529,"mc":[{"id":"1.231705583","rc":[{"batb":[[0,2.3,10],[1,2.28,30.26],[2,1.74,1]],"ltp":2.28,"tv":0.79,"id":655}]}]}
{"op":"mcm","clk":"11870622560","pt":1723546898023,"mc":[{"id":"1.231705583","rc":[{"batb":[[0,2.28,30.26],[1,1.74,1],[2,1.25,100]],"ltp":2.28,"tv":0.79,"id":655}]}]}
{"op":"mcm","clk":"11870622643","pt":1723546900238,"mc":[{"id":"1.231705583","rc":[{"batb":[[0,2.3,10],[1,2.28,30.26],[2,1.74,1]],"ltp":2.28,"tv":0.79,"id":655}]}]}
{"op":"mcm","clk":"11870622763","pt":1723546903739,"mc":[{"id":"1.231705583","rc":[{"batb":[[0,2.28,30.26],[1,1.74,1],[2,1.25,100]],"ltp":2.28,"tv":0.79,"id":655}]}]}
{"op":"mcm","clk":"11870622939","pt":1723546907741,"mc":[{"id":"1.231705583","rc":[{"batb":[[0,2.3,10],[1,2.28,30.26],[2,1.74,1]],"ltp":2.28,"tv":0.79,"id":655}]}]}
{"op":"mcm","clk":"11870623125","pt":1723546911329,"mc":[{"id":"1.231705583","rc":[{"batb":[[0,2.28,30.26],[1,1.74,1],[2,1.25,100]],"ltp":2.28,"tv":0.79,"id":655}]}]}
{"op":"mcm","clk":"11870623225","pt":1723546913945,"mc":[{"id":"1.231705583","rc":[{"batb":[[0,2.3,10],[1,2.28,30.26],[2,1.74,1]],"ltp":2.28,"tv":0.79,"id":655}]}]}
{"op":"mcm","clk":"11870623414","pt":1723546917351,"mc":[{"id":"1.231705583","rc":[{"batb":[[0,2.28,30.26],[1,1.74,1],[2,1.25,100]],"ltp":2.28,"tv":0.79,"id":655}]}]}
{"op":"mcm","clk":"11870623629","pt":1723546921872,"mc":[{"id":"1.231705583","rc":[{"batb":[[0,2.3,10],[1,2.28,30.26],[2,1.74,1]],"ltp":2.28,"tv":0.79,"id":655}]}]}
{"op":"mcm","clk":"11870623867","pt":1723546926446,"mc":[{"id":"1.231705583","rc":[{"batb":[[0,2.28,30.26],[1,1.74,1],[2,1.25,100]],"ltp":2.28,"tv":0.79,"id":655}]}]}
{"op":"mcm","clk":"11870624151","pt":1723546931736,"mc":[{"id":"1.231705583","rc":[{"batb":[[0,2.3,10],[1,2.28,30.26],[2,1.74,1]],"ltp":2.28,"tv":0.79,"id":655}]}]}
{"op":"mcm","clk":"11870624298","pt":1723546934972,"mc":[{"id":"1.231705583","rc":[{"batb":[[0,2.28,30.26],[1,1.74,1],[2,1.25,100]],"ltp":2.28,"tv":0.79,"id":655}]}]}
{"op":"mcm","clk":"11870624695","pt":1723546942980,"mc":[{"id":"1.231705583","rc":[{"batb":[[0,2.3,10],[1,2.28,30.26],[2,1.74,1]],"ltp":2.28,"tv":0.79,"id":655}]}]}
{"op":"mcm","clk":"11870624887","pt":1723546946575,"mc":[{"id":"1.231705583","rc":[{"batb":[[0,2.28,30.26],[1,1.74,1],[2,1.25,100]],"ltp":2.28,"tv":0.79,"id":655}]}]}
{"op":"mcm","clk":"11870625326","pt":1723546957175,"mc":[{"id":"1.231705583","rc":[{"batb":[[0,2.3,10],[1,2.28,30.26],[2,1.74,1]],"ltp":2.28,"tv":0.79,"id":655}]}]}
{"op":"mcm","clk":"11870625521","pt":1723546960612,"mc":[{"id":"1.231705583","rc":[{"batb":[[0,2.28,30.26],[1,1.74,1],[2,1.25,100]],"ltp":2.28,"tv":0.79,"id":655}]}]}
{"op":"mcm","clk":"11870625751","pt":1723546966799,"mc":[{"id":"1.231705583","rc":[{"batb":[[0,2.3,10],[1,2.28,30.26],[2,1.74,1]],"ltp":2.28,"tv":0.79,"id":655}]}]}
{"op":"mcm","clk":"11870625892","pt":1723546970199,"mc":[{"id":"1.231705583","rc":[{"batb":[[0,2.28,30.26],[1,1.74,1],[2,1.25,100]],"ltp":2.28,"tv":0.79,"id":655}]}]}
{"op":"mcm","clk":"11870626150","pt":1723546976210,"mc":[{"id":"1.231705583","rc":[{"batb":[[0,2.3,10],[1,2.28,30.26],[2,1.74,1]],"ltp":2.28,"tv":0.79,"id":655}]}]}
{"op":"mcm","clk":"11870626304","pt":1723546979532,"mc":[{"id":"1.231705583","rc":[{"batb":[[0,2.28,30.26],[1,1.74,1],[2,1.25,100]],"ltp":2.28,"tv":0.79,"id":655}]}]}
{"op":"mcm","clk":"11870626428","pt":1723546982107,"mc":[{"id":"1.231705583","rc":[{"batb":[[0,2.3,10],[1,2.28,30.26],[2,1.74,1]],"ltp":2.28,"tv":0.79,"id":655}]}]}
{"op":"mcm","clk":"11870626628","pt":1723546985801,"mc":[{"id":"1.231705583","rc":[{"batb":[[0,2.28,30.26],[1,1.74,1],[2,1.25,100]],"ltp":2.28,"tv":0.79,"id":655}]}]}
{"op":"mcm","clk":"11870626778","pt":1723546988730,"mc":[{"id":"1.231705583","rc":[{"batb":[[0,2.3,10],[1,2.28,30.26],[2,1.74,1]],"ltp":2.28,"tv":0.79,"id":655}]}]}
{"op":"mcm","clk":"11870626954","pt":1723546992017,"mc":[{"id":"1.231705583","rc":[{"batb":[[0,2.28,30.26],[1,1.74,1],[2,1.25,100]],"ltp":2.28,"tv":0.79,"id":655}]}]}
{"op":"mcm","clk":"11870627553","pt":1723547000542,"mc":[{"id":"1.231705583","rc":[{"batb":[[0,2.3,10],[1,2.28,30.26],[2,1.74,1]],"ltp":2.28,"tv":0.79,"id":655}]}]}
{"op":"mcm","clk":"11870627738","pt":1723547004031,"mc":[{"id":"1.231705583","rc":[{"batb":[[0,2.28,30.26],[1,1.74,1],[2,1.25,100]],"ltp":2.28,"tv":0.79,"id":655}]}]}
{"op":"mcm","clk":"11870627918","pt":1723547007177,"mc":[{"id":"1.231705583","rc":[{"batb":[[0,2.3,10],[1,2.28,30.26],[2,1.74,1]],"ltp":2.28,"tv":0.79,"id":655}]}]}
{"op":"mcm","clk":"11870628050","pt":1723547010470,"mc":[{"id":"1.231705583","rc":[{"batb":[[0,2.28,30.26],[1,1.74,1],[2,1.25,100]],"ltp":2.28,"tv":0.79,"id":655}]}]}
{"op":"mcm","clk":"11870628309","pt":1723547016077,"mc":[{"id":"1.231705583","rc":[{"batb":[[0,2.3,10],[1,2.28,30.26],[2,1.74,1]],"ltp":2.28,"tv":0.79,"id":655}]}]}
{"op":"mcm","clk":"11870628436","pt":1723547019263,"mc":[{"id":"1.231705583","rc":[{"batb":[[0,2.28,30.26],[1,1.74,1],[2,1.25,100]],"ltp":2.28,"tv":0.79,"id":655}]}]}
{"op":"mcm","clk":"11870628801","pt":1723547026279,"mc":[{"id":"1.231705583","rc":[{"batb":[[0,2.3,10],[1,2.28,30.26],[2,1.74,1]],"ltp":2.28,"tv":0.79,"id":655}]}]}
{"op":"mcm","clk":"11870628976","pt":1723547029775,"mc":[{"id":"1.231705583","rc":[{"batb":[[0,2.28,30.26],[1,1.74,1],[2,1.25,100]],"ltp":2.28,"tv":0.79,"id":655}]}]}
{"op":"mcm","clk":"11870629276","pt":1723547036370,"mc":[{"id":"1.231705583","rc":[{"batb":[[0,2.3,10],[1,2.28,30.26],[2,1.74,1]],"ltp":2.28,"tv":0.79,"id":655}]}]}
{"op":"mcm","clk":"11870629472","pt":1723547039875,"mc":[{"id":"1.231705583","rc":[{"batb":[[0,2.28,30.26],[1,1.74,1],[2,1.25,100]],"ltp":2.28,"tv":0.79,"id":655}]}]}
{"op":"mcm","clk":"11870629620","pt":1723547042914,"mc":[{"id":"1.231705583","rc":[{"batb":[[0,2.3,10],[1,2.28,30.26],[2,1.74,1]],"ltp":2.28,"tv":0.79,"id":655}]}]}
{"op":"mcm","clk":"11870629802","pt":1723547046321,"mc":[{"id":"1.231705583","rc":[{"batb":[[0,2.28,30.26],[1,1.74,1],[2,1.25,100]],"ltp":2.28,"tv":0.79,"id":655}]}]}
{"op":"mcm","clk":"11870629962","pt":1723547049316,"mc":[{"id":"1.231705583","rc":[{"batb":[[0,2.3,10],[1,2.28,30.26],[2,1.74,1]],"ltp":2.28,"tv":0.79,"id":655}]}]}
{"op":"mcm","clk":"11870630141","pt":1723547052714,"mc":[{"id":"1.231705583","rc":[{"batb":[[0,2.28,30.26],[1,1.74,1],[2,1.25,100]],"ltp":2.28,"tv":0.79,"id":655}]}]}
{"op":"mcm","clk":"11870630379","pt":1723547056427,"mc":[{"id":"1.231705583","rc":[{"batb":[[0,2.3,10],[1,2.28,30.26],[2,1.74,1]],"ltp":2.28,"tv":0.79,"id":655}]}]}
{"op":"mcm","clk":"11870630597","pt":1723547059726,"mc":[{"id":"1.231705583","rc":[{"batb":[[0,2.28,30.26],[1,1.74,1],[2,1.25,100]],"ltp":2.28,"tv":0.79,"id":655}]}]}
{"op":"mcm","clk":"11870630806","pt":1723547062413,"mc":[{"id":"1.231705583","rc":[{"batb":[[0,2.3,10],[1,2.28,30.26],[2,1.74,1]],"ltp":2.28,"tv":0.79,"id":655}]}]}
{"op":"mcm","clk":"11870631033","pt":1723547066124,"mc":[{"id":"1.231705583","rc":[{"batb":[[0,2.28,30.26],[1,1.74,1],[2,1.25,100]],"ltp":2.28,"tv":0.79,"id":655}]}]}
{"op":"mcm","clk":"11870631185","pt":1723547068802,"mc":[{"id":"1.231705583","rc":[{"batb":[[0,2.3,10],[1,2.28,30.26],[2,1.74,1]],"ltp":2.28,"tv":0.79,"id":655}]}]}
{"op":"mcm","clk":"11870631372","pt":1723547072205,"mc":[{"id":"1.231705583","rc":[{"batb":[[0,2.28,30.26],[1,1.74,1],[2,1.25,100]],"ltp":2.28,"tv":0.79,"id":655}]}]}
{"op":"mcm","clk":"11870631560","pt":1723547075451,"mc":[{"id":"1.231705583","rc":[{"batb":[[0,2.3,10],[1,2.28,30.26],[2,1.74,1]],"ltp":2.28,"tv":0.79,"id":655}]}]}
{"op":"mcm","clk":"11870631734","pt":1723547078750,"mc":[{"id":"1.231705583","rc":[{"batb":[[0,2.28,30.26],[1,1.74,1],[2,1.25,100]],"ltp":2.28,"tv":0.79,"id":655}]}]}
{"op":"mcm","clk":"11870631999","pt":1723547083363,"mc":[{"id":"1.231705583","rc":[{"batb":[[0,2.3,10],[1,2.28,30.26],[2,1.74,1]],"ltp":2.28,"tv":0.79,"id":655}]}]}
{"op":"mcm","clk":"11870632187","pt":1723547086722,"mc":[{"id":"1.231705583","rc":[{"batb":[[0,2.28,30.26],[1,1.74,1],[2,1.25,100]],"ltp":2.28,"tv":0.79,"id":655}]}]}
{"op":"mcm","clk":"11870632540","pt":1723547093337,"mc":[{"id":"1.231705583","rc":[{"batb":[[0,2.3,10],[1,2.28,30.26],[2,1.74,1]],"ltp":2.28,"tv":0.79,"id":655}]}]}
{"op":"mcm","clk":"11870632704","pt":1723547096537,"mc":[{"id":"1.231705583","rc":[{"batb":[[0,2.28,30.26],[1,1.74,1],[2,1.25,100]],"ltp":2.28,"tv":0.79,"id":655}]}]}
{"op":"mcm","clk":"11870633010","pt":1723547102945,"mc":[{"id":"1.231705583","rc":[{"batb":[[0,2.3,10],[1,2.28,30.26],[2,1.74,1]],"ltp":2.28,"tv":0.79,"id":655}]}]}
{"op":"mcm","clk":"11870633173","pt":1723547106452,"mc":[{"id":"1.231705583","rc":[{"batb":[[0,2.28,30.26],[1,1.74,1],[2,1.25,100]],"ltp":2.28,"tv":0.79,"id":655}]}]}
{"op":"mcm","clk":"11870633483","pt":1723547111886,"mc":[{"id":"1.231705583","rc":[{"batb":[[0,2.3,10],[1,2.28,30.26],[2,1.74,1]],"ltp":2.28,"tv":0.79,"id":655}]}]}
{"op":"mcm","clk":"11870633686","pt":1723547115387,"mc":[{"id":"1.231705583","rc":[{"batb":[[0,2.28,30.26],[1,1.74,1],[2,1.25,100]],"ltp":2.28,"tv":0.79,"id":655}]}]}
{"op":"mcm","clk":"11870633832","pt":1723547117664,"mc":[{"id":"1.231705583","rc":[{"batb":[[0,2.3,10],[1,2.28,30.26],[2,1.74,1]],"ltp":2.28,"tv":0.79,"id":655}]}]}
{"op":"mcm","clk":"11870634021","pt":1723547121063,"mc":[{"id":"1.231705583","rc":[{"batb":[[0,2.28,30.26],[1,1.74,1],[2,1.25,100]],"ltp":2.28,"tv":0.79,"id":655}]}]}
{"op":"mcm","clk":"11870634150","pt":1723547123406,"mc":[{"id":"1.231705583","rc":[{"batb":[[0,2.3,10],[1,2.28,30.26],[2,1.74,1]],"ltp":2.28,"tv":0.79,"id":655}]}]}
{"op":"mcm","clk":"11870634353","pt":1723547126969,"mc":[{"id":"1.231705583","rc":[{"batb":[[0,2.28,30.26],[1,1.74,1],[2,1.25,100]],"ltp":2.28,"tv":0.79,"id":655}]}]}
{"op":"mcm","clk":"11870634500","pt":1723547129590,"mc":[{"id":"1.231705583","rc":[{"batb":[[0,2.3,10],[1,2.28,30.26],[2,1.74,1]],"ltp":2.28,"tv":0.79,"id":655}]}]}
{"op":"mcm","clk":"11870634669","pt":1723547132980,"mc":[{"id":"1.231705583","rc":[{"batb":[[0,2.28,30.26],[1,1.74,1],[2,1.25,100]],"ltp":2.28,"tv":0.79,"id":655}]}]}
{"op":"mcm","clk":"11870634894","pt":1723547136579,"mc":[{"id":"1.231705583","rc":[{"batb":[[0,2.3,10],[1,2.28,30.26],[2,1.74,1]],"ltp":2.28,"tv":0.79,"id":655}]}]}
{"op":"mcm","clk":"11870635050","pt":1723547139913,"mc":[{"id":"1.231705583","rc":[{"batb":[[0,2.28,30.26],[1,1.74,1],[2,1.25,100]],"ltp":2.28,"tv":0.79,"id":655}]}]}
{"op":"mcm","clk":"11870635184","pt":1723547142218,"mc":[{"id":"1.231705583","rc":[{"batb":[[0,2.3,10],[1,2.28,30.26],[2,1.74,1]],"ltp":2.28,"tv":0.79,"id":655}]}]}
{"op":"mcm","clk":"11870635350","pt":1723547145508,"mc":[{"id":"1.231705583","rc":[{"batb":[[0,2.28,30.26],[1,1.74,1],[2,1.25,100]],"ltp":2.28,"tv":0.79,"id":655}]}]}
{"op":"mcm","clk":"11870635560","pt":1723547149307,"mc":[{"id":"1.231705583","rc":[{"batb":[[0,2.3,10],[1,2.28,30.26],[2,1.74,1]],"ltp":2.28,"tv":0.79,"id":655}]}]}
{"op":"mcm","clk":"11870635769","pt":1723547152699,"mc":[{"id":"1.231705583","rc":[{"batb":[[0,2.28,30.26],[1,1.74,1],[2,1.25,100]],"ltp":2.28,"tv":0.79,"id":655}]}]}
{"op":"mcm","clk":"11870635927","pt":1723547155525,"mc":[{"id":"1.231705583","rc":[{"batb":[[0,2.3,10],[1,2.28,30.26],[2,1.74,1]],"ltp":2.28,"tv":0.79,"id":655}]}]}
{"op":"mcm","clk":"11870636127","pt":1723547159038,"mc":[{"id":"1.231705583","rc":[{"batb":[[0,2.28,30.26],[1,1.74,1],[2,1.25,100]],"ltp":2.28,"tv":0.79,"id":655}]}]}
{"op":"mcm","clk":"11870636243","pt":1723547161212,"mc":[{"id":"1.231705583","rc":[{"batb":[[0,2.3,10],[1,2.28,30.26],[2,1.74,1]],"ltp":2.28,"tv":0.79,"id":655}]}]}
{"op":"mcm","clk":"11870636432","pt":1723547164912,"mc":[{"id":"1.231705583","rc":[{"batb":[[0,2.28,30.26],[1,1.74,1],[2,1.25,100]],"ltp":2.28,"tv":0.79,"id":655}]}]}
{"op":"mcm","clk":"11870636630","pt":1723547168716,"mc":[{"id":"1.231705583","rc":[{"batb":[[0,2.3,10],[1,2.28,30.26],[2,1.74,1]],"ltp":2.28,"tv":0.79,"id":655}]}]}
{"op":"mcm","clk":"11870636831","pt":1723547172359,"mc":[{"id":"1.231705583","rc":[{"batb":[[0,2.28,30.26],[1,1.74,1],[2,1.25,100]],"ltp":2.28,"tv":0.79,"id":655}]}]}
{"op":"mcm","clk":"11870637084","pt":1723547176930,"mc":[{"id":"1.231705583","rc":[{"batb":[[0,2.3,10],[1,2.28,30.26],[2,1.74,1]],"ltp":2.28,"tv":0.79,"id":655}]}]}
{"op":"mcm","clk":"11870637289","pt":1723547180270,"mc":[{"id":"1.231705583","rc":[{"batb":[[0,2.28,30.26],[1,1.74,1],[2,1.25,100]],"ltp":2.28,"tv":0.79,"id":655}]}]}
{"op":"mcm","clk":"11870637446","pt":1723547183041,"mc":[{"id":"1.231705583","rc":[{"batb":[[0,2.3,10],[1,2.28,30.26],[2,1.74,1]],"ltp":2.28,"tv":0.79,"id":655}]}]}
{"op":"mcm","clk":"11870637652","pt":1723547186436,"mc":[{"id":"1.231705583","rc":[{"batb":[[0,2.28,30.26],[1,1.74,1],[2,1.25,100]],"ltp":2.28,"tv":0.79,"id":655}]}]}
{"op":"mcm","clk":"11870637970","pt":1723547192652,"mc":[{"id":"1.231705583","rc":[{"batb":[[0,2.3,10],[1,2.28,30.26],[2,1.74,1]],"ltp":2.28,"tv":0.79,"id":655}]}]}
{"op":"mcm","clk":"11870638160","pt":1723547195851,"mc":[{"id":"1.231705583","rc":[{"batb":[[0,2.28,30.26],[1,1.74,1],[2,1.25,100]],"ltp":2.28,"tv":0.79,"id":655}]}]}
{"op":"mcm","clk":"11870638356","pt":1723547199247,"mc":[{"id":"1.231705583","rc":[{"batb":[[0,2.3,10],[1,2.28,30.26],[2,1.74,1]],"ltp":2.28,"tv":0.79,"id":655}]}]}
{"op":"mcm","clk":"11870638533","pt":1723547202477,"mc":[{"id":"1.231705583","rc":[{"batb":[[0,2.28,30.26],[1,1.74,1],[2,1.25,100]],"ltp":2.28,"tv":0.79,"id":655}]}]}
{"op":"mcm","clk":"11870638854","pt":1723547208663,"mc":[{"id":"1.231705583","rc":[{"batb":[[0,2.3,10],[1,2.28,30.26],[2,1.74,1]],"ltp":2.28,"tv":0.79,"id":655}]}]}
{"op":"mcm","clk":"11870639041","pt":1723547212100,"mc":[{"id":"1.231705583","rc":[{"batb":[[0,2.28,30.26],[1,1.74,1],[2,1.25,100]],"ltp":2.28,"tv":0.79,"id":655}]}]}
{"op":"mcm","clk":"11870639186","pt":1723547214670,"mc":[{"id":"1.231705583","rc":[{"batb":[[0,2.3,10],[1,2.28,30.26],[2,1.74,1]],"ltp":2.28,"tv":0.79,"id":655}]}]}
{"op":"mcm","clk":"11870639384","pt":1723547218078,"mc":[{"id":"1.231705583","rc":[{"batb":[[0,2.28,30.26],[1,1.74,1],[2,1.25,100]],"ltp":2.28,"tv":0.79,"id":655}]}]}
{"op":"mcm","clk":"11870639653","pt":1723547222581,"mc":[{"id":"1.231705583","rc":[{"batb":[[0,2.3,10],[1,2.28,30.26],[2,1.74,1]],"ltp":2.28,"tv":0.79,"id":655}]}]}
{"op":"mcm","clk":"11870639884","pt":1723547226194,"mc":[{"id":"1.231705583","rc":[{"batb":[[0,2.28,30.26],[1,1.74,1],[2,1.25,100]],"ltp":2.28,"tv":0.79,"id":655}]}]}
{"op":"mcm","clk":"11870640412","pt":1723547234699,"mc":[{"id":"1.231705583","rc":[{"batb":[[0,2.3,10],[1,2.28,30.26],[2,1.74,1]],"ltp":2.28,"tv":0.79,"id":655}]}]}
{"op":"mcm","clk":"11870640617","pt":1723547238103,"mc":[{"id":"1.231705583","rc":[{"batb":[[0,2.28,30.26],[1,1.74,1],[2,1.25,100]],"ltp":2.28,"tv":0.79,"id":655}]}]}
{"op":"mcm","clk":"11870640815","pt":1723547241136,"mc":[{"id":"1.231705583","rc":[{"batb":[[0,2.3,10],[1,2.28,30.26],[2,1.74,1]],"ltp":2.28,"tv":0.79,"id":655}]}]}
{"op":"mcm","clk":"11870641034","pt":1723547244642,"mc":[{"id":"1.231705583","rc":[{"batb":[[0,2.28,30.26],[1,1.74,1],[2,1.25,100]],"ltp":2.28,"tv":0.79,"id":655}]}]}
{"op":"mcm","clk":"11870641218","pt":1723547247431,"mc":[{"id":"1.231705583","rc":[{"batb":[[0,2.3,10],[1,2.28,30.26],[2,1.74,1]],"ltp":2.28,"tv":0.79,"id":655}]}]}
{"op":"mcm","clk":"11870641377","pt":1723547250836,"mc":[{"id":"1.231705583","rc":[{"batb":[[0,2.28,30.26],[1,1.74,1],[2,1.25,100]],"ltp":2.28,"tv":0.79,"id":655}]}]}
{"op":"mcm","clk":"11870641522","pt":1723547253360,"mc":[{"id":"1.231705583","rc":[{"batb":[[0,2.3,10],[1,2.28,30.26],[2,1.74,1]],"ltp":2.28,"tv":0.79,"id":655}]}]}
{"op":"mcm","clk":"11870641694","pt":1723547256664,"mc":[{"id":"1.231705583","rc":[{"batb":[[0,2.28,30.26],[1,1.74,1],[2,1.25,100]],"ltp":2.28,"tv":0.79,"id":655}]}]}
{"op":"mcm","clk":"11870642082","pt":1723547263059,"mc":[{"id":"1.231705583","rc":[{"batb":[[0,2.3,10],[1,2.28,30.26],[2,1.74,1]],"ltp":2.28,"tv":0.79,"id":655}]}]}
{"op":"mcm","clk":"11870642278","pt":1723547266400,"mc":[{"id":"1.231705583","rc":[{"batb":[[0,2.28,30.26],[1,1.74,1],[2,1.25,100]],"ltp":2.28,"tv":0.79,"id":655}]}]}
{"op":"mcm","clk":"11870642406","pt":1723547268872,"mc":[{"id":"1.231705583","rc":[{"batb":[[0,2.3,10],[1,2.28,30.26],[2,1.74,1]],"ltp":2.28,"tv":0.79,"id":655}]}]}
{"op":"mcm","clk":"11870642615","pt":1723547272284,"mc":[{"id":"1.231705583","rc":[{"batb":[[0,2.28,30.26],[1,1.74,1],[2,1.25,100]],"ltp":2.28,"tv":0.79,"id":655}]}]}
{"op":"mcm","clk":"11870643225","pt":1723547282197,"mc":[{"id":"1.231705583","rc":[{"batb":[[0,2.3,10],[1,2.28,30.26],[2,1.74,1]],"ltp":2.28,"tv":0.79,"id":655}]}]}
{"op":"mcm","clk":"11870643442","pt":1723547285617,"mc":[{"id":"1.231705583","rc":[{"batb":[[0,2.28,30.26],[1,1.74,1],[2,1.25,100]],"ltp":2.28,"tv":0.79,"id":655}]}]}
{"op":"mcm","clk":"11870644092","pt":1723547297597,"mc":[{"id":"1.231705583","rc":[{"batb":[[0,2.3,10],[1,2.28,30.26],[2,1.74,1]],"ltp":2.28,"tv":0.79,"id":655}]}]}
{"op":"mcm","clk":"11870644299","pt":1723547300942,"mc":[{"id":"1.231705583","rc":[{"batb":[[0,2.28,30.26],[1,1.74,1],[2,1.25,100]],"ltp":2.28,"tv":0.79,"id":655}]}]}
{"op":"mcm","clk":"11870644475","pt":1723547303541,"mc":[{"id":"1.231705583","rc":[{"batb":[[0,2.3,10],[1,2.28,30.26],[2,1.74,1]],"ltp":2.28,"tv":0.79,"id":655}]}]}
{"op":"mcm","clk":"11870644687","pt":1723547306946,"mc":[{"id":"1.231705583","rc":[{"batb":[[0,2.28,30.26],[1,1.74,1],[2,1.25,100]],"ltp":2.28,"tv":0.79,"id":655}]}]}
{"op":"mcm","clk":"11870644874","pt":1723547309541,"mc":[{"id":"1.231705583","rc":[{"batb":[[0,2.3,10],[1,2.28,30.26],[2,1.74,1]],"ltp":2.28,"tv":0.79,"id":655}]}]}
{"op":"mcm","clk":"11870645115","pt":1723547313060,"mc":[{"id":"1.231705583","rc":[{"batb":[[0,2.28,30.26],[1,1.74,1],[2,1.25,100]],"ltp":2.28,"tv":0.79,"id":655}]}]}
{"op":"mcm","clk":"11870645390","pt":1723547317161,"mc":[{"id":"1.231705583","rc":[{"batb":[[0,2.3,10],[1,2.28,30.26],[2,1.74,1]],"ltp":2.28,"tv":0.79,"id":655}]}]}
{"op":"mcm","clk":"11870645636","pt":1723547320934,"mc":[{"id":"1.231705583","rc":[{"batb":[[0,2.28,30.26],[1,1.74,1],[2,1.25,100]],"ltp":2.28,"tv":0.79,"id":655}]}]}
{"op":"mcm","clk":"11870645851","pt":1723547324488,"mc":[{"id":"1.231705583","rc":[{"batb":[[0,2.3,10],[1,2.28,30.26],[2,1.74,1]],"ltp":2.28,"tv":0.79,"id":655}]}]}
{"op":"mcm","clk":"11870646050","pt":1723547328086,"mc":[{"id":"1.231705583","rc":[{"batb":[[0,2.28,30.26],[1,1.74,1],[2,1.25,100]],"ltp":2.28,"tv":0.79,"id":655}]}]}
{"op":"mcm","clk":"11870646171","pt":1723547330556,"mc":[{"id":"1.231705583","rc":[{"batb":[[0,2.3,10],[1,2.28,30.26],[2,1.74,1]],"ltp":2.28,"tv":0.79,"id":655}]}]}
{"op":"mcm","clk":"11870646358","pt":1723547334063,"mc":[{"id":"1.231705583","rc":[{"batb":[[0,2.28,30.26],[1,1.74,1],[2,1.25,100]],"ltp":2.28,"tv":0.79,"id":655}]}]}
{"op":"mcm","clk":"11870646545","pt":1723547337473,"mc":[{"id":"1.231705583","rc":[{"batb":[[0,2.3,10],[1,2.28,30.26],[2,1.74,1]],"ltp":2.28,"tv":0.79,"id":655}]}]}
{"op":"mcm","clk":"11870646740","pt":1723547340984,"mc":[{"id":"1.231705583","rc":[{"batb":[[0,2.28,30.26],[1,1.74,1],[2,1.25,100]],"ltp":2.28,"tv":0.79,"id":655}]}]}
{"op":"mcm","clk":"11870647058","pt":1723547347084,"mc":[{"id":"1.231705583","rc":[{"batb":[[0,2.3,10],[1,2.28,30.26],[2,1.74,1]],"ltp":2.28,"tv":0.79,"id":655}]}]}
{"op":"mcm","clk":"11870647250","pt":1723547350484,"mc":[{"id":"1.231705583","rc":[{"batb":[[0,2.28,30.26],[1,1.74,1],[2,1.25,100]],"ltp":2.28,"tv":0.79,"id":655}]}]}
{"op":"mcm","clk":"11870647460","pt":1723547354195,"mc":[{"id":"1.231705583","rc":[{"batb":[[0,2.3,10],[1,2.28,30.26],[2,1.74,1]],"ltp":2.28,"tv":0.79,"id":655}]}]}
{"op":"mcm","clk":"11870647622","pt":1723547357588,"mc":[{"id":"1.231705583","rc":[{"batb":[[0,2.28,30.26],[1,1.74,1],[2,1.25,100]],"ltp":2.28,"tv":0.79,"id":655}]}]}
{"op":"mcm","clk":"11870647847","pt":1723547362224,"mc":[{"id":"1.231705583","rc":[{"batb":[[0,2.3,10],[1,2.28,30.26],[2,1.74,1]],"ltp":2.28,"tv":0.79,"id":655}]}]}
{"op":"mcm","clk":"11870648024","pt":1723547365626,"mc":[{"id":"1.231705583","rc":[{"batb":[[0,2.28,30.26],[1,1.74,1],[2,1.25,100]],"ltp":2.28,"tv":0.79,"id":655}]}]}
{"op":"mcm","clk":"11870648173","pt":1723547368307,"mc":[{"id":"1.231705583","rc":[{"batb":[[0,2.3,10],[1,2.28,30.26],[2,1.74,1]],"ltp":2.28,"tv":0.79,"id":655}]}]}
{"op":"mcm","clk":"11870648363","pt":1723547371910,"mc":[{"id":"1.231705583","rc":[{"batb":[[0,2.28,30.26],[1,1.74,1],[2,1.25,100]],"ltp":2.28,"tv":0.79,"id":655}]}]}
{"op":"mcm","clk":"11870648527","pt":1723547374538,"mc":[{"id":"1.231705583","rc":[{"batb":[[0,2.3,10],[1,2.28,30.26],[2,1.74,1]],"ltp":2.28,"tv":0.79,"id":655}]}]}
{"op":"mcm","clk":"11870648739","pt":1723547378010,"mc":[{"id":"1.231705583","rc":[{"batb":[[0,2.28,30.26],[1,1.74,1],[2,1.25,100]],"ltp":2.28,"tv":0.79,"id":655}]}]}
{"op":"mcm","clk":"11870648886","pt":1723547380539,"mc":[{"id":"1.231705583","rc":[{"batb":[[0,2.3,10],[1,2.28,30.26],[2,1.74,1]],"ltp":2.28,"tv":0.79,"id":655}]}]}
{"op":"mcm","clk":"11870649048","pt":1723547383932,"mc":[{"id":"1.231705583","rc":[{"batb":[[0,2.28,30.26],[1,1.74,1],[2,1.25,100]],"ltp":2.28,"tv":0.79,"id":655}]}]}
{"op":"mcm","clk":"11870649265","pt":1723547388822,"mc":[{"id":"1.231705583","rc":[{"batb":[[0,2.3,10],[1,2.28,30.26],[2,1.74,1]],"ltp":2.28,"tv":0.79,"id":655}]}]}
{"op":"mcm","clk":"11870649427","pt":1723547392325,"mc":[{"id":"1.231705583","rc":[{"batb":[[0,2.28,30.26],[1,1.74,1],[2,1.25,100]],"ltp":2.28,"tv":0.79,"id":655}]}]}
{"op":"mcm","clk":"11870649698","pt":1723547397841,"mc":[{"id":"1.231705583","rc":[{"batb":[[0,2.3,10],[1,2.28,30.26],[2,1.74,1]],"ltp":2.28,"tv":0.79,"id":655}]}]}
{"op":"mcm","clk":"11870649857","pt":1723547401340,"mc":[{"id":"1.231705583","rc":[{"batb":[[0,2.28,30.26],[1,1.74,1],[2,1.25,100]],"ltp":2.28,"tv":0.79,"id":655}]}]}
{"op":"mcm","clk":"11870649996","pt":1723547404537,"mc":[{"id":"1.231705583","rc":[{"batb":[[0,2.3,10],[1,2.28,30.26],[2,1.74,1]],"ltp":2.28,"tv":0.79,"id":655}]}]}
{"op":"mcm","clk":"11870650176","pt":1723547408249,"mc":[{"id":"1.231705583","rc":[{"batb":[[0,2.28,30.26],[1,1.74,1],[2,1.25,100]],"ltp":2.28,"tv":0.79,"id":655}]}]}
{"op":"mcm","clk":"11870650424","pt":1723547414259,"mc":[{"id":"1.231705583","rc":[{"batb":[[0,2.3,10],[1,2.28,30.26],[2,1.74,1]],"ltp":2.28,"tv":0.79,"id":655}]}]}
{"op":"mcm","clk":"11870650567","pt":1723547417655,"mc":[{"id":"1.231705583","rc":[{"batb":[[0,2.28,30.26],[1,1.74,1],[2,1.25,100]],"ltp":2.28,"tv":0.79,"id":655}]}]}
{"op":"mcm","clk":"11870650740","pt":1723547420477,"mc":[{"id":"1.231705583","rc":[{"batb":[[0,2.3,10],[1,2.28,30.26],[2,1.74,1]],"ltp":2.28,"tv":0.79,"id":655}]}]}
{"op":"mcm","clk":"11870650904","pt":1723547423865,"mc":[{"id":"1.231705583","rc":[{"batb":[[0,2.28,30.26],[1,1.74,1],[2,1.25,100]],"ltp":2.28,"tv":0.79,"id":655}]}]}
{"op":"mcm","clk":"11870651284","pt":1723547430703,"mc":[{"id":"1.231705583","rc":[{"batb":[[0,2.3,10],[1,2.28,30.26],[2,1.74,1]],"ltp":2.28,"tv":0.79,"id":655}]}]}
{"op":"mcm","clk":"11870651441","pt":1723547433998,"mc":[{"id":"1.231705583","rc":[{"batb":[[0,2.28,30.26],[1,1.74,1],[2,1.25,100]],"ltp":2.28,"tv":0.79,"id":655}]}]}
{"op":"mcm","clk":"11870651614","pt":1723547437701,"mc":[{"id":"1.231705583","rc":[{"batb":[[0,2.3,10],[1,2.28,30.26],[2,1.74,1]],"ltp":2.28,"tv":0.79,"id":655}]}]}
{"op":"mcm","clk":"11870651795","pt":1723547441004,"mc":[{"id":"1.231705583","rc":[{"batb":[[0,2.28,30.26],[1,1.74,1],[2,1.25,100]],"ltp":2.28,"tv":0.79,"id":655}]}]}
{"op":"mcm","clk":"11870652034","pt":1723547445809,"mc":[{"id":"1.231705583","rc":[{"batb":[[0,2.3,10],[1,2.28,30.26],[2,1.74,1]],"ltp":2.28,"tv":0.79,"id":655}]}]}
{"op":"mcm","clk":"11870652206","pt":1723547449213,"mc":[{"id":"1.231705583","rc":[{"batb":[[0,2.28,30.26],[1,1.74,1],[2,1.25,100]],"ltp":2.28,"tv":0.79,"id":655}]}]}
{"op":"mcm","clk":"11870652372","pt":1723547452822,"mc":[{"id":"1.231705583","rc":[{"batb":[[0,2.3,10],[1,2.28,30.26],[2,1.74,1]],"ltp":2.28,"tv":0.79,"id":655}]}]}
{"op":"mcm","clk":"11870652553","pt":1723547456224,"mc":[{"id":"1.231705583","rc":[{"batb":[[0,2.28,30.26],[1,1.74,1],[2,1.25,100]],"ltp":2.28,"tv":0.79,"id":655}]}]}
{"op":"mcm","clk":"11870652737","pt":1723547459222,"mc":[{"id":"1.231705583","rc":[{"batb":[[0,2.3,10],[1,2.28,30.26],[2,1.74,1]],"ltp":2.28,"tv":0.79,"id":655}]}]}
{"op":"mcm","clk":"11870652929","pt":1723547462534,"mc":[{"id":"1.231705583","rc":[{"batb":[[0,2.28,30.26],[1,1.74,1],[2,1.25,100]],"ltp":2.28,"tv":0.79,"id":655}]}]}
{"op":"mcm","clk":"11870653077","pt":1723547465636,"mc":[{"id":"1.231705583","rc":[{"batb":[[0,2.3,10],[1,2.28,30.26],[2,1.74,1]],"ltp":2.28,"tv":0.79,"id":655}]}]}
{"op":"mcm","clk":"11870653228","pt":1723547468933,"mc":[{"id":"1.231705583","rc":[{"batb":[[0,2.28,30.26],[1,1.74,1],[2,1.25,100]],"ltp":2.28,"tv":0.79,"id":655}]}]}
{"op":"mcm","clk":"11870653374","pt":1723547472338,"mc":[{"id":"1.231705583","rc":[{"batb":[[0,2.3,10],[1,2.28,30.26],[2,1.74,1]],"ltp":2.28,"tv":0.79,"id":655}]}]}
{"op":"mcm","clk":"11870653529","pt":1723547475630,"mc":[{"id":"1.231705583","rc":[{"batb":[[0,2.28,30.26],[1,1.74,1],[2,1.25,100]],"ltp":2.28,"tv":0.79,"id":655}]}]}
{"op":"mcm","clk":"11870653710","pt":1723547479448,"mc":[{"id":"1.231705583","rc":[{"batb":[[0,2.3,10],[1,2.28,30.26],[2,1.74,1]],"ltp":2.28,"tv":0.79,"id":655}]}]}
{"op":"mcm","clk":"11870653892","pt":1723547482845,"mc":[{"id":"1.231705583","rc":[{"batb":[[0,2.28,30.26],[1,1.74,1],[2,1.25,100]],"ltp":2.28,"tv":0.79,"id":655}]}]}
{"op":"mcm","clk":"11870653975","pt":1723547485268,"mc":[{"id":"1.231705583","rc":[{"batb":[[0,2.3,10],[1,2.28,30.26],[2,1.74,1]],"ltp":2.28,"tv":0.79,"id":655}]}]}
{"op":"mcm","clk":"11870654166","pt":1723547488870,"mc":[{"id":"1.231705583","rc":[{"batb":[[0,2.28,30.26],[1,1.74,1],[2,1.25,100]],"ltp":2.28,"tv":0.79,"id":655}]}]}
{"op":"mcm","clk":"11870654276","pt":1723547491045,"mc":[{"id":"1.231705583","rc":[{"batb":[[0,2.3,10],[1,2.28,30.26],[2,1.74,1]],"ltp":2.28,"tv":0.79,"id":655}]}]}
{"op":"mcm","clk":"11870654436","pt":1723547494456,"mc":[{"id":"1.231705583","rc":[{"batb":[[0,2.28,30.26],[1,1.74,1],[2,1.25,100]],"ltp":2.28,"tv":0.79,"id":655}]}]}
{"op":"mcm","clk":"11870654561","pt":1723547497242,"mc":[{"id":"1.231705583","rc":[{"batb":[[0,2.3,10],[1,2.28,30.26],[2,1.74,1]],"ltp":2.28,"tv":0.79,"id":655}]}]}
{"op":"mcm","clk":"11870654720","pt":1723547500459,"mc":[{"id":"1.231705583","rc":[{"batb":[[0,2.28,30.26],[1,1.74,1],[2,1.25,100]],"ltp":2.28,"tv":0.79,"id":655}]}]}
{"op":"mcm","clk":"11870654817","pt":1723547502964,"mc":[{"id":"1.231705583","rc":[{"batb":[[0,2.3,10],[1,2.28,30.26],[2,1.74,1]],"ltp":2.28,"tv":0.79,"id":655}]}]}
{"op":"mcm","clk":"11870654914","pt":1723547506350,"mc":[{"id":"1.231705583","rc":[{"batb":[[0,2.28,30.26],[1,1.74,1],[2,1.25,100]],"ltp":2.28,"tv":0.79,"id":655}]}]}
{"op":"mcm","clk":"11870655024","pt":1723547509484,"mc":[{"id":"1.231705583","rc":[{"batb":[[0,2.3,10],[1,2.28,30.26],[2,1.74,1]],"ltp":2.28,"tv":0.79,"id":655}]}]}
{"op":"mcm","clk":"11870655134","pt":1723547512777,"mc":[{"id":"1.231705583","rc":[{"batb":[[0,2.28,30.26],[1,1.74,1],[2,1.25,100]],"ltp":2.28,"tv":0.79,"id":655}]}]}
{"op":"mcm","clk":"11870655284","pt":1723547516256,"mc":[{"id":"1.231705583","rc":[{"batb":[[0,2.3,10],[1,2.28,30.26],[2,1.74,1]],"ltp":2.28,"tv":0.79,"id":655}]}]}
{"op":"mcm","clk":"11870655399","pt":1723547519652,"mc":[{"id":"1.231705583","rc":[{"batb":[[0,2.28,30.26],[1,1.74,1],[2,1.25,100]],"ltp":2.28,"tv":0.79,"id":655}]}]}
{"op":"mcm","clk":"11870655640","pt":1723547524590,"mc":[{"id":"1.231705583","rc":[{"batb":[[0,2.3,10],[1,2.28,30.26],[2,1.74,1]],"ltp":2.28,"tv":0.79,"id":655}]}]}
{"op":"mcm","clk":"11870655824","pt":1723547527991,"mc":[{"id":"1.231705583","rc":[{"batb":[[0,2.28,30.26],[1,1.74,1],[2,1.25,100]],"ltp":2.28,"tv":0.79,"id":655}]}]}
{"op":"mcm","clk":"11870655959","pt":1723547531083,"mc":[{"id":"1.231705583","rc":[{"batb":[[0,2.3,10],[1,2.28,30.26],[2,1.74,1]],"ltp":2.28,"tv":0.79,"id":655}]}]}
{"op":"mcm","clk":"11870656126","pt":1723547534684,"mc":[{"id":"1.231705583","rc":[{"batb":[[0,2.28,30.26],[1,1.74,1],[2,1.25,100]],"ltp":2.28,"tv":0.79,"id":655}]}]}
{"op":"mcm","clk":"11870656226","pt":1723547537168,"mc":[{"id":"1.231705583","rc":[{"batb":[[0,2.3,10],[1,2.28,30.26],[2,1.74,1]],"ltp":2.28,"tv":0.79,"id":655}]}]}
{"op":"mcm","clk":"11870656354","pt":1723547540675,"mc":[{"id":"1.231705583","rc":[{"batb":[[0,2.28,30.26],[1,1.74,1],[2,1.25,100]],"ltp":2.28,"tv":0.79,"id":655}]}]}
{"op":"mcm","clk":"11870656489","pt":1723547544625,"mc":[{"id":"1.231705583","rc":[{"batb":[[0,2.3,10],[1,2.28,30.26],[2,1.74,1]],"ltp":2.28,"tv":0.79,"id":655}]}]}
{"op":"mcm","clk":"11870656608","pt":1723547547919,"mc":[{"id":"1.231705583","rc":[{"batb":[[0,2.28,30.26],[1,1.74,1],[2,1.25,100]],"ltp":2.28,"tv":0.79,"id":655}]}]}
{"op":"mcm","clk":"11870656754","pt":1723547551622,"mc":[{"id":"1.231705583","rc":[{"batb":[[0,2.3,10],[1,2.28,30.26],[2,1.74,1]],"ltp":2.28,"tv":0.79,"id":655}]}]}
{"op":"mcm","clk":"11870656899","pt":1723547556398,"mc":[{"id":"1.231705583","rc":[{"batb":[[0,2.28,30.26],[1,1.74,1],[2,1.25,100]],"ltp":2.28,"tv":0.79,"id":655}]}]}
{"op":"mcm","clk":"11870656982","pt":1723547558606,"mc":[{"id":"1.231705583","rc":[{"batb":[[0,2.3,10],[1,2.28,30.26],[2,1.74,1]],"ltp":2.28,"tv":0.79,"id":655}]}]}
{"op":"mcm","clk":"11870657103","pt":1723547561903,"mc":[{"id":"1.231705583","rc":[{"batb":[[0,2.28,30.26],[1,1.74,1],[2,1.25,100]],"ltp":2.28,"tv":0.79,"id":655}]}]}
{"op":"mcm","clk":"11870657184","pt":1723547564821,"mc":[{"id":"1.231705583","rc":[{"batb":[[0,2.3,10],[1,2.28,30.26],[2,1.74,1]],"ltp":2.28,"tv":0.79,"id":655}]}]}
{"op":"mcm","clk":"11870657313","pt":1723547568326,"mc":[{"id":"1.231705583","rc":[{"batb":[[0,2.28,30.26],[1,1.74,1],[2,1.25,100]],"ltp":2.28,"tv":0.79,"id":655}]}]}
{"op":"mcm","clk":"11870657475","pt":1723547574030,"mc":[{"id":"1.231705583","rc":[{"batb":[[0,2.3,10],[1,2.28,30.26],[2,1.74,1]],"ltp":2.28,"tv":0.79,"id":655}]}]}
{"op":"mcm","clk":"11870665102","pt":1723547577441,"mc":[{"id":"1.231705583","rc":[{"batb":[[0,2.28,30.26],[1,1.74,1],[2,1.25,100]],"ltp":2.28,"tv":0.79,"id":655}]}]}
{"op":"mcm","clk":"11870665186","pt":1723547579650,"mc":[{"id":"1.231705583","rc":[{"batb":[[0,2.3,10],[1,2.28,30.26],[2,1.74,1]],"ltp":2.28,"tv":0.79,"id":655}]}]}
{"op":"mcm","clk":"11870665310","pt":1723547583164,"mc":[{"id":"1.231705583","rc":[{"batb":[[0,2.28,30.26],[1,1.74,1],[2,1.25,100]],"ltp":2.28,"tv":0.79,"id":655}]}]}
{"op":"mcm","clk":"11870665383","pt":1723547585581,"mc":[{"id":"1.231705583","rc":[{"batb":[[0,2.3,10],[1,2.28,30.26],[2,1.74,1]],"ltp":2.28,"tv":0.79,"id":655}]}]}
{"op":"mcm","clk":"11870665498","pt":1723547588981,"mc":[{"id":"1.231705583","rc":[{"batb":[[0,2.28,30.26],[1,1.74,1],[2,1.25,100]],"ltp":2.28,"tv":0.79,"id":655}]}]}
{"op":"mcm","clk":"11870665651","pt":1723547594164,"mc":[{"id":"1.231705583","rc":[{"batb":[[0,2.3,10],[1,2.28,30.26],[2,1.74,1]],"ltp":2.28,"tv":0.79,"id":655}]}]}
{"op":"mcm","clk":"11870665738","pt":1723547597664,"mc":[{"id":"1.231705583","rc":[{"batb":[[0,2.28,30.26],[1,1.74,1],[2,1.25,100]],"ltp":2.28,"tv":0.79,"id":655}]}]}
{"op":"mcm","clk":"11870665805","pt":1723547600346,"mc":[{"id":"1.231705583","rc":[{"batb":[[0,2.3,10],[1,2.28,30.26],[2,1.74,1]],"ltp":2.28,"tv":0.79,"id":655}]}]}
{"op":"mcm","clk":"11870665889","pt":1723547603539,"mc":[{"id":"1.231705583","rc":[{"batb":[[0,2.28,30.26],[1,1.74,1],[2,1.25,100]],"ltp":2.28,"tv":0.79,"id":655}]}]}
{"op":"mcm","clk":"11870665967","pt":1723547606226,"mc":[{"id":"1.231705583","rc":[{"batb":[[0,2.3,10],[1,2.28,30.26],[2,1.74,1]],"ltp":2.28,"tv":0.79,"id":655}]}]}
{"op":"mcm","clk":"11870666086","pt":1723547609562,"mc":[{"id":"1.231705583","rc":[{"batb":[[0,2.28,30.26],[1,1.74,1],[2,1.25,100]],"ltp":2.28,"tv":0.79,"id":655}]}]}
{"op":"mcm","clk":"11870666247","pt":1723547615273,"mc":[{"id":"1.231705583","rc":[{"batb":[[0,2.3,10],[1,2.28,30.26],[2,1.74,1]],"ltp":2.28,"tv":0.79,"id":655}]}]}
{"op":"mcm","clk":"11870666345","pt":1723547618572,"mc":[{"id":"1.231705583","rc":[{"batb":[[0,2.28,30.26],[1,1.74,1],[2,1.25,100]],"ltp":2.28,"tv":0.79,"id":655}]}]}
{"op":"mcm","clk":"11870666443","pt":1723547622385,"mc":[{"id":"1.231705583","rc":[{"batb":[[0,2.3,10],[1,2.28,30.26],[2,1.74,1]],"ltp":2.28,"tv":0.79,"id":655}]}]}
{"op":"mcm","clk":"11870666564","pt":1723547625878,"mc":[{"id":"1.231705583","rc":[{"batb":[[0,2.28,30.26],[1,1.74,1],[2,1.25,100]],"ltp":2.28,"tv":0.79,"id":655}]}]}
{"op":"mcm","clk":"11870666646","pt":1723547628560,"mc":[{"id":"1.231705583","rc":[{"batb":[[0,2.3,10],[1,2.28,30.26],[2,1.74,1]],"ltp":2.28,"tv":0.79,"id":655}]}]}
{"op":"mcm","clk":"11870666726","pt":1723547631969,"mc":[{"id":"1.231705583","rc":[{"batb":[[0,2.28,30.26],[1,1.74,1],[2,1.25,100]],"ltp":2.28,"tv":0.79,"id":655}]}]}
{"op":"mcm","clk":"11870666867","pt":1723547636200,"mc":[{"id":"1.231705583","rc":[{"batb":[[0,2.3,10],[1,2.28,30.26],[2,1.74,1]],"ltp":2.28,"tv":0.79,"id":655}]}]}
{"op":"mcm","clk":"11870666976","pt":1723547639507,"mc":[{"id":"1.231705583","rc":[{"batb":[[0,2.28,30.26],[1,1.74,1],[2,1.25,100]],"ltp":2.28,"tv":0.79,"id":655}]}]}
{"op":"mcm","clk":"11870667137","pt":1723547644118,"mc":[{"id":"1.231705583","rc":[{"batb":[[0,2.3,10],[1,2.28,30.26],[2,1.74,1]],"ltp":2.28,"tv":0.79,"id":655}]}]}
{"op":"mcm","clk":"11870667255","pt":1723547647620,"mc":[{"id":"1.231705583","rc":[{"batb":[[0,2.28,30.26],[1,1.74,1],[2,1.25,100]],"ltp":2.28,"tv":0.79,"id":655}]}]}
{"op":"mcm","clk":"11870667333","pt":1723547650415,"mc":[{"id":"1.231705583","rc":[{"batb":[[0,2.3,10],[1,2.28,30.26],[2,1.74,1]],"ltp":2.28,"tv":0.79,"id":655}]}]}
{"op":"mcm","clk":"11870667435","pt":1723547653812,"mc":[{"id":"1.231705583","rc":[{"batb":[[0,2.28,30.26],[1,1.74,1],[2,1.25,100]],"ltp":2.28,"tv":0.79,"id":655}]}]}
{"op":"mcm","clk":"11870667519","pt":1723547656088,"mc":[{"id":"1.231705583","rc":[{"batb":[[0,2.3,10],[1,2.28,30.26],[2,1.74,1]],"ltp":2.28,"tv":0.79,"id":655}]}]}
{"op":"mcm","clk":"11870667634","pt":1723547659496,"mc":[{"id":"1.231705583","rc":[{"batb":[[0,2.28,30.26],[1,1.74,1],[2,1.25,100]],"ltp":2.28,"tv":0.79,"id":655}]}]}
{"op":"mcm","clk":"11870667751","pt":1723547662738,"mc":[{"id":"1.231705583","rc":[{"batb":[[0,2.3,10],[1,2.28,30.26],[2,1.74,1]],"ltp":2.28,"tv":0.79,"id":655}]}]}
{"op":"mcm","clk":"11870667840","pt":1723547666144,"mc":[{"id":"1.231705583","rc":[{"batb":[[0,2.28,30.26],[1,1.74,1],[2,1.25,100]],"ltp":2.28,"tv":0.79,"id":655}]}]}
{"op":"mcm","clk":"11870667951","pt":1723547670421,"mc":[{"id":"1.231705583","rc":[{"batb":[[0,2.3,10],[1,2.28,30.26],[2,1.74,1]],"ltp":2.28,"tv":0.79,"id":655}]}]}
{"op":"mcm","clk":"11870668065","pt":1723547673846,"mc":[{"id":"1.231705583","rc":[{"batb":[[0,2.28,30.26],[1,1.74,1],[2,1.25,100]],"ltp":2.28,"tv":0.79,"id":655}]}]}
{"op":"mcm","clk":"11870668176","pt":1723547676742,"mc":[{"id":"1.231705583","rc":[{"batb":[[0,2.3,10],[1,2.28,30.26],[2,1.74,1]],"ltp":2.28,"tv":0.79,"id":655}]}]}
{"op":"mcm","clk":"11870668330","pt":1723547680360,"mc":[{"id":"1.231705583","rc":[{"batb":[[0,2.28,30.26],[1,1.74,1],[2,1.25,100]],"ltp":2.28,"tv":0.79,"id":655}]}]}
{"op":"mcm","clk":"11870668413","pt":1723547682434,"mc":[{"id":"1.231705583","rc":[{"batb":[[0,2.3,10],[1,2.28,30.26],[2,1.74,1]],"ltp":2.28,"tv":0.79,"id":655}]}]}
{"op":"mcm","clk":"11870668519","pt":1723547685929,"mc":[{"id":"1.231705583","rc":[{"batb":[[0,2.28,30.26],[1,1.74,1],[2,1.25,100]],"ltp":2.28,"tv":0.79,"id":655}]}]}
{"op":"mcm","clk":"11870668620","pt":1723547689537,"mc":[{"id":"1.231705583","rc":[{"batb":[[0,2.3,10],[1,2.28,30.26],[2,1.74,1]],"ltp":2.28,"tv":0.79,"id":655}]}]}
{"op":"mcm","clk":"11870668747","pt":1723547693136,"mc":[{"id":"1.231705583","rc":[{"batb":[[0,2.28,30.26],[1,1.74,1],[2,1.25,100]],"ltp":2.28,"tv":0.79,"id":655}]}]}
{"op":"mcm","clk":"11870668867","pt":1723547696838,"mc":[{"id":"1.231705583","rc":[{"batb":[[0,2.3,10],[1,2.28,30.26],[2,1.74,1]],"ltp":2.28,"tv":0.79,"id":655}]}]}
{"op":"mcm","clk":"11870668986","pt":1723547700271,"mc":[{"id":"1.231705583","rc":[{"batb":[[0,2.28,30.26],[1,1.74,1],[2,1.25,100]],"ltp":2.28,"tv":0.79,"id":655}]}]}
{"op":"mcm","clk":"11870669166","pt":1723547703677,"mc":[{"id":"1.231705583","rc":[{"batb":[[0,2.3,10],[1,2.28,30.26],[2,1.74,1]],"ltp":2.28,"tv":0.79,"id":655}]}]}
{"op":"mcm","clk":"11870669328","pt":1723547707072,"mc":[{"id":"1.231705583","rc":[{"batb":[[0,2.28,30.26],[1,1.74,1],[2,1.25,100]],"ltp":2.28,"tv":0.79,"id":655}]}]}
{"op":"mcm","clk":"11870669423","pt":1723547709438,"mc":[{"id":"1.231705583","rc":[{"batb":[[0,2.3,10],[1,2.28,30.26],[2,1.74,1]],"ltp":2.28,"tv":0.79,"id":655}]}]}
{"op":"mcm","clk":"11870669576","pt":1723547712890,"mc":[{"id":"1.231705583","rc":[{"batb":[[0,2.28,30.26],[1,1.74,1],[2,1.25,100]],"ltp":2.28,"tv":0.79,"id":655}]}]}
{"op":"mcm","clk":"11870669686","pt":1723547715871,"mc":[{"id":"1.231705583","rc":[{"batb":[[0,2.3,10],[1,2.28,30.26],[2,1.74,1]],"ltp":2.28,"tv":0.79,"id":655}]}]}
{"op":"mcm","clk":"11870669817","pt":1723547719058,"mc":[{"id":"1.231705583","rc":[{"batb":[[0,2.28,30.26],[1,1.74,1],[2,1.25,100]],"ltp":2.28,"tv":0.79,"id":655}]}]}
{"op":"mcm","clk":"11870669913","pt":1723547722700,"mc":[{"id":"1.231705583","rc":[{"batb":[[0,2.3,10],[1,2.28,30.26],[2,1.74,1]],"ltp":2.28,"tv":0.79,"id":655}]}]}
{"op":"mcm","clk":"11870670039","pt":1723547726092,"mc":[{"id":"1.231705583","rc":[{"batb":[[0,2.28,30.26],[1,1.74,1],[2,1.25,100]],"ltp":2.28,"tv":0.79,"id":655}]}]}
{"op":"mcm","clk":"11870670225","pt":1723547731372,"mc":[{"id":"1.231705583","rc":[{"batb":[[0,2.3,10],[1,2.28,30.26],[2,1.74,1]],"ltp":2.28,"tv":0.79,"id":655}]}]}
{"op":"mcm","clk":"11870670435","pt":1723547737087,"mc":[{"id":"1.231705583","rc":[{"batb":[[0,2.28,30.26],[1,1.74,1],[2,1.25,100]],"ltp":2.28,"tv":0.79,"id":655}]}]}
{"op":"mcm","clk":"11870670570","pt":1723547740793,"mc":[{"id":"1.231705583","rc":[{"batb":[[0,2.3,10],[1,2.28,30.26],[2,1.74,1]],"ltp":2.28,"tv":0.79,"id":655}]}]}
{"op":"mcm","clk":"11870670684","pt":1723547744316,"mc":[{"id":"1.231705583","rc":[{"batb":[[0,2.28,30.26],[1,1.74,1],[2,1.25,100]],"ltp":2.28,"tv":0.79,"id":655}]}]}
{"op":"mcm","clk":"11870670865","pt":1723547749501,"mc":[{"id":"1.231705583","rc":[{"batb":[[0,2.3,10],[1,2.28,30.26],[2,1.74,1]],"ltp":2.28,"tv":0.79,"id":655}]}]}
{"op":"mcm","clk":"11870670960","pt":1723547752835,"mc":[{"id":"1.231705583","rc":[{"batb":[[0,2.28,30.26],[1,1.74,1],[2,1.25,100]],"ltp":2.28,"tv":0.79,"id":655}]}]}
{"op":"mcm","clk":"11870671038","pt":1723547755403,"mc":[{"id":"1.231705583","rc":[{"batb":[[0,2.3,10],[1,2.28,30.26],[2,1.74,1]],"ltp":2.28,"tv":0.79,"id":655}]}]}
{"op":"mcm","clk":"11870671138","pt":1723547758940,"mc":[{"id":"1.231705583","rc":[{"batb":[[0,2.28,30.26],[1,1.74,1],[2,1.25,100]],"ltp":2.28,"tv":0.79,"id":655}]}]}
{"op":"mcm","clk":"11870671276","pt":1723547762356,"mc":[{"id":"1.231705583","rc":[{"batb":[[0,2.3,10],[1,2.28,30.26],[2,1.74,1]],"ltp":2.28,"tv":0.79,"id":655}]}]}
{"op":"mcm","clk":"11870671441","pt":1723547765721,"mc":[{"id":"1.231705583","rc":[{"batb":[[0,2.28,30.26],[1,1.74,1],[2,1.25,100]],"ltp":2.28,"tv":0.79,"id":655}]}]}
{"op":"mcm","clk":"11870671570","pt":1723547769064,"mc":[{"id":"1.231705583","rc":[{"batb":[[0,2.3,10],[1,2.28,30.26],[2,1.74,1]],"ltp":2.28,"tv":0.79,"id":655}]}]}
{"op":"mcm","clk":"11870671713","pt":1723547773443,"mc":[{"id":"1.231705583","rc":[{"batb":[[0,2.28,30.26],[1,1.74,1],[2,1.25,100]],"ltp":2.28,"tv":0.79,"id":655}]}]}
{"op":"mcm","clk":"11870671806","pt":1723547776782,"mc":[{"id":"1.231705583","rc":[{"batb":[[0,2.3,10],[1,2.28,30.26],[2,1.74,1]],"ltp":2.28,"tv":0.79,"id":655}]}]}
{"op":"mcm","clk":"11870671961","pt":1723547780081,"mc":[{"id":"1.231705583","rc":[{"batb":[[0,2.28,30.26],[1,1.74,1],[2,1.25,100]],"ltp":2.28,"tv":0.79,"id":655}]}]}
{"op":"mcm","clk":"11870672050","pt":1723547782859,"mc":[{"id":"1.231705583","rc":[{"batb":[[0,2.3,10],[1,2.28,30.26],[2,1.74,1]],"ltp":2.28,"tv":0.79,"id":655}]}]}
{"op":"mcm","clk":"11870672206","pt":1723547786675,"mc":[{"id":"1.231705583","rc":[{"batb":[[0,2.28,30.26],[1,1.74,1],[2,1.25,100]],"ltp":2.28,"tv":0.79,"id":655}]}]}
{"op":"mcm","clk":"11870672327","pt":1723547790171,"mc":[{"id":"1.231705583","rc":[{"batb":[[0,2.3,10],[1,2.28,30.26],[2,1.74,1]],"ltp":2.28,"tv":0.79,"id":655}]}]}
{"op":"mcm","clk":"11870672430","pt":1723547793471,"mc":[{"id":"1.231705583","rc":[{"batb":[[0,2.28,30.26],[1,1.74,1],[2,1.25,100]],"ltp":2.28,"tv":0.79,"id":655}]}]}
{"op":"mcm","clk":"11870672561","pt":1723547796704,"mc":[{"id":"1.231705583","rc":[{"batb":[[0,2.3,10],[1,2.28,30.26],[2,1.74,1]],"ltp":2.28,"tv":0.79,"id":655}]}]}
{"op":"mcm","clk":"11870672721","pt":1723547800181,"mc":[{"id":"1.231705583","rc":[{"batb":[[0,2.28,30.26],[1,1.74,1],[2,1.25,100]],"ltp":2.28,"tv":0.79,"id":655}]}]}
{"op":"mcm","clk":"11870672815","pt":1723547802702,"mc":[{"id":"1.231705583","rc":[{"batb":[[0,2.3,10],[1,2.28,30.26],[2,1.74,1]],"ltp":2.28,"tv":0.79,"id":655}]}]}
{"op":"mcm","clk":"11870672915","pt":1723547806306,"mc":[{"id":"1.231705583","rc":[{"batb":[[0,2.28,30.26],[1,1.74,1],[2,1.25,100]],"ltp":2.28,"tv":0.79,"id":655}]}]}
{"op":"mcm","clk":"11870673054","pt":1723547810210,"mc":[{"id":"1.231705583","rc":[{"batb":[[0,2.3,10],[1,2.28,30.26],[2,1.74,1]],"ltp":2.28,"tv":0.79,"id":655}]}]}
{"op":"mcm","clk":"11870673178","pt":1723547813621,"mc":[{"id":"1.231705583","rc":[{"batb":[[0,2.28,30.26],[1,1.74,1],[2,1.25,100]],"ltp":2.28,"tv":0.79,"id":655}]}]}
{"op":"mcm","clk":"11870673349","pt":1723547818109,"mc":[{"id":"1.231705583","rc":[{"batb":[[0,2.3,10],[1,2.28,30.26],[2,1.74,1]],"ltp":2.28,"tv":0.79,"id":655}]}]}
{"op":"mcm","clk":"11870673502","pt":1723547821924,"mc":[{"id":"1.231705583","rc":[{"batb":[[0,2.28,30.26],[1,1.74,1],[2,1.25,100]],"ltp":2.28,"tv":0.79,"id":655}]}]}
{"op":"mcm","clk":"11870673598","pt":1723547824301,"mc":[{"id":"1.231705583","rc":[{"batb":[[0,2.3,10],[1,2.28,30.26],[2,1.74,1]],"ltp":2.28,"tv":0.79,"id":655}]}]}
{"op":"mcm","clk":"11870673735","pt":1723547827807,"mc":[{"id":"1.231705583","rc":[{"batb":[[0,2.28,30.26],[1,1.74,1],[2,1.25,100]],"ltp":2.28,"tv":0.79,"id":655}]}]}
{"op":"mcm","clk":"11870673851","pt":1723547830735,"mc":[{"id":"1.231705583","rc":[{"batb":[[0,2.3,10],[1,2.28,30.26],[2,1.74,1]],"ltp":2.28,"tv":0.79,"id":655}]}]}
{"op":"mcm","clk":"11870673974","pt":1723547834339,"mc":[{"id":"1.231705583","rc":[{"batb":[[0,2.28,30.26],[1,1.74,1],[2,1.25,100]],"ltp":2.28,"tv":0.79,"id":655}]}]}
{"op":"mcm","clk":"11870674400","pt":1723547845946,"mc":[{"id":"1.231705583","rc":[{"batb":[[0,2.3,10],[1,2.28,30.26],[2,1.74,1]],"ltp":2.28,"tv":0.79,"id":655}]}]}
{"op":"mcm","clk":"11870674537","pt":1723547849349,"mc":[{"id":"1.231705583","rc":[{"batb":[[0,2.28,30.26],[1,1.74,1],[2,1.25,100]],"ltp":2.28,"tv":0.79,"id":655}]}]}
{"op":"mcm","clk":"11870674626","pt":1723547851769,"mc":[{"id":"1.231705583","rc":[{"batb":[[0,2.3,10],[1,2.28,30.26],[2,1.74,1]],"ltp":2.28,"tv":0.79,"id":655}]}]}
{"op":"mcm","clk":"11870674760","pt":1723547855239,"mc":[{"id":"1.231705583","rc":[{"batb":[[0,2.28,30.26],[1,1.74,1],[2,1.25,100]],"ltp":2.28,"tv":0.79,"id":655}]}]}
{"op":"mcm","clk":"11870674974","pt":1723547860051,"mc":[{"id":"1.231705583","rc":[{"batb":[[0,2.3,10],[1,2.28,30.26],[2,1.74,1]],"ltp":2.28,"tv":0.79,"id":655}]}]}
{"op":"mcm","clk":"11870675110","pt":1723547863965,"mc":[{"id":"1.231705583","rc":[{"batb":[[0,2.28,30.26],[1,1.74,1],[2,1.25,100]],"ltp":2.28,"tv":0.79,"id":655}]}]}
{"op":"mcm","clk":"11870675242","pt":1723547866957,"mc":[{"id":"1.231705583","rc":[{"batb":[[0,2.3,10],[1,2.28,30.26],[2,1.74,1]],"ltp":2.28,"tv":0.79,"id":655}]}]}
{"op":"mcm","clk":"11870675369","pt":1723547870452,"mc":[{"id":"1.231705583","rc":[{"batb":[[0,2.28,30.26],[1,1.74,1],[2,1.25,100]],"ltp":2.28,"tv":0.79,"id":655}]}]}
{"op":"mcm","clk":"11870675587","pt":1723547876099,"mc":[{"id":"1.231705583","rc":[{"batb":[[0,2.3,10],[1,2.28,30.26],[2,1.74,1]],"ltp":2.28,"tv":0.79,"id":655}]}]}
{"op":"mcm","clk":"11870675728","pt":1723547879497,"mc":[{"id":"1.231705583","rc":[{"batb":[[0,2.28,30.26],[1,1.74,1],[2,1.25,100]],"ltp":2.28,"tv":0.79,"id":655}]}]}
{"op":"mcm","clk":"11870675879","pt":1723547882393,"mc":[{"id":"1.231705583","rc":[{"batb":[[0,2.3,10],[1,2.28,30.26],[2,1.74,1]],"ltp":2.28,"tv":0.79,"id":655}]}]}
{"op":"mcm","clk":"11870676009","pt":1723547885892,"mc":[{"id":"1.231705583","rc":[{"batb":[[0,2.28,30.26],[1,1.74,1],[2,1.25,100]],"ltp":2.28,"tv":0.79,"id":655}]}]}
{"op":"mcm","clk":"11870676105","pt":1723547888671,"mc":[{"id":"1.231705583","rc":[{"batb":[[0,2.3,10],[1,2.28,30.26],[2,1.74,1]],"ltp":2.28,"tv":0.79,"id":655}]}]}
{"op":"mcm","clk":"11870676257","pt":1723547892012,"mc":[{"id":"1.231705583","rc":[{"batb":[[0,2.28,30.26],[1,1.74,1],[2,1.25,100]],"ltp":2.28,"tv":0.79,"id":655}]}]}
{"op":"mcm","clk":"11870676358","pt":1723547894587,"mc":[{"id":"1.231705583","rc":[{"batb":[[0,2.3,10],[1,2.28,30.26],[2,1.74,1]],"ltp":2.28,"tv":0.79,"id":655}]}]}
{"op":"mcm","clk":"11870676497","pt":1723547898499,"mc":[{"id":"1.231705583","rc":[{"batb":[[0,2.28,30.26],[1,1.74,1],[2,1.25,100]],"ltp":2.28,"tv":0.79,"id":655}]}]}
{"op":"mcm","clk":"11870676630","pt":1723547902103,"mc":[{"id":"1.231705583","rc":[{"batb":[[0,2.3,10],[1,2.28,30.26],[2,1.74,1]],"ltp":2.28,"tv":0.79,"id":655}]}]}
{"op":"mcm","clk":"11870676770","pt":1723547905497,"mc":[{"id":"1.231705583","rc":[{"batb":[[0,2.28,30.26],[1,1.74,1],[2,1.25,100]],"ltp":2.28,"tv":0.79,"id":655}]}]}
{"op":"mcm","clk":"11870677058","pt":1723547912130,"mc":[{"id":"1.231705583","rc":[{"batb":[[0,2.3,10],[1,2.28,30.26],[2,1.74,1]],"ltp":2.28,"tv":0.79,"id":655}]}]}
{"op":"mcm","clk":"11870677177","pt":1723547915708,"mc":[{"id":"1.231705583","rc":[{"batb":[[0,2.28,30.26],[1,1.74,1],[2,1.25,100]],"ltp":2.28,"tv":0.79,"id":655}]}]}
{"op":"mcm","clk":"11870677330","pt":1723547919928,"mc":[{"id":"1.231705583","rc":[{"batb":[[0,2.3,10],[1,2.28,30.26],[2,1.74,1]],"ltp":2.28,"tv":0.79,"id":655}]}]}
{"op":"mcm","clk":"11870677473","pt":1723547923542,"mc":[{"id":"1.231705583","rc":[{"batb":[[0,2.28,30.26],[1,1.74,1],[2,1.25,100]],"ltp":2.28,"tv":0.79,"id":655}]}]}
{"op":"mcm","clk":"11870677647","pt":1723547928415,"mc":[{"id":"1.231705583","rc":[{"batb":[[0,2.3,10],[1,2.28,30.26],[2,1.74,1]],"ltp":2.28,"tv":0.79,"id":655}]}]}
{"op":"mcm","clk":"11870677777","pt":1723547931809,"mc":[{"id":"1.231705583","rc":[{"batb":[[0,2.28,30.26],[1,1.74,1],[2,1.25,100]],"ltp":2.28,"tv":0.79,"id":655}]}]}
{"op":"mcm","clk":"11870677861","pt":1723547934551,"mc":[{"id":"1.231705583","rc":[{"batb":[[0,2.3,10],[1,2.28,30.26],[2,1.74,1]],"ltp":2.28,"tv":0.79,"id":655}]}]}
{"op":"mcm","clk":"11870677977","pt":1723547938035,"mc":[{"id":"1.231705583","rc":[{"batb":[[0,2.28,30.26],[1,1.74,1],[2,1.25,100]],"ltp":2.28,"tv":0.79,"id":655}]}]}
{"op":"mcm","clk":"11870678073","pt":1723547941166,"mc":[{"id":"1.231705583","rc":[{"batb":[[0,2.3,10],[1,2.28,30.26],[2,1.74,1]],"ltp":2.28,"tv":0.79,"id":655}]}]}
{"op":"mcm","clk":"11870678231","pt":1723547944724,"mc":[{"id":"1.231705583","rc":[{"batb":[[0,2.28,30.26],[1,1.74,1],[2,1.25,100]],"ltp":2.28,"tv":0.79,"id":655}]}]}
{"op":"mcm","clk":"11870678476","pt":1723547950748,"mc":[{"id":"1.231705583","rc":[{"batb":[[0,2.3,10],[1,2.28,30.26],[2,1.74,1]],"ltp":2.28,"tv":0.79,"id":655}]}]}
{"op":"mcm","clk":"11870678566","pt":1723547954146,"mc":[{"id":"1.231705583","rc":[{"batb":[[0,2.28,30.26],[1,1.74,1],[2,1.25,100]],"ltp":2.28,"tv":0.79,"id":655}]}]}
{"op":"mcm","clk":"11870678639","pt":1723547956661,"mc":[{"id":"1.231705583","rc":[{"batb":[[0,2.3,10],[1,2.28,30.26],[2,1.74,1]],"ltp":2.28,"tv":0.79,"id":655}]}]}
{"op":"mcm","clk":"11870678785","pt":1723547960461,"mc":[{"id":"1.231705583","rc":[{"batb":[[0,2.28,30.26],[1,1.74,1],[2,1.25,100]],"ltp":2.28,"tv":0.79,"id":655}]}]}
{"op":"mcm","clk":"11870678900","pt":1723547963553,"mc":[{"id":"1.231705583","rc":[{"batb":[[0,2.3,10],[1,2.28,30.26],[2,1.74,1]],"ltp":2.28,"tv":0.79,"id":655}]}]}
{"op":"mcm","clk":"11870679014","pt":1723547967097,"mc":[{"id":"1.231705583","rc":[{"batb":[[0,2.28,30.26],[1,1.74,1],[2,1.25,100]],"ltp":2.28,"tv":0.79,"id":655}]}]}
{"op":"mcm","clk":"11870679113","pt":1723547969868,"mc":[{"id":"1.231705583","rc":[{"batb":[[0,2.3,10],[1,2.28,30.26],[2,1.74,1]],"ltp":2.28,"tv":0.79,"id":655}]}]}
{"op":"mcm","clk":"11870679244","pt":1723547973309,"mc":[{"id":"1.231705583","rc":[{"batb":[[0,2.28,30.26],[1,1.74,1],[2,1.25,100]],"ltp":2.28,"tv":0.79,"id":655}]}]}
{"op":"mcm","clk":"11870679448","pt":1723547977277,"mc":[{"id":"1.231705583","rc":[{"batb":[[0,2.3,10],[1,2.28,30.26],[2,1.74,1]],"ltp":2.28,"tv":0.79,"id":655}]}]}
{"op":"mcm","clk":"11870679583","pt":1723547980690,"mc":[{"id":"1.231705583","rc":[{"batb":[[0,2.28,30.26],[1,1.74,1],[2,1.25,100]],"ltp":2.28,"tv":0.79,"id":655}]}]}
{"op":"mcm","clk":"11870679754","pt":1723547985992,"mc":[{"id":"1.231705583","rc":[{"batb":[[0,2.3,10],[1,2.28,30.26],[2,1.74,1]],"ltp":2.28,"tv":0.79,"id":655}]}]}
{"op":"mcm","clk":"11870679871","pt":1723547989288,"mc":[{"id":"1.231705583","rc":[{"batb":[[0,2.28,30.26],[1,1.74,1],[2,1.25,100]],"ltp":2.28,"tv":0.79,"id":655}]}]}
{"op":"mcm","clk":"11870679999","pt":1723547992113,"mc":[{"id":"1.231705583","rc":[{"batb":[[0,2.3,10],[1,2.28,30.26],[2,1.74,1]],"ltp":2.28,"tv":0.79,"id":655}]}]}
{"op":"mcm","clk":"11870680123","pt":1723547995404,"mc":[{"id":"1.231705583","rc":[{"batb":[[0,2.28,30.26],[1,1.74,1],[2,1.25,100]],"ltp":2.28,"tv":0.79,"id":655}]}]}
{"op":"mcm","clk":"11870680197","pt":1723547997916,"mc":[{"id":"1.231705583","rc":[{"batb":[[0,2.3,10],[1,2.28,30.26],[2,1.74,1]],"ltp":2.28,"tv":0.79,"id":655}]}]}
{"op":"mcm","clk":"11870680324","pt":1723548001226,"mc":[{"id":"1.231705583","rc":[{"batb":[[0,2.28,30.26],[1,1.74,1],[2,1.25,100]],"ltp":2.28,"tv":0.79,"id":655}]}]}
{"op":"mcm","clk":"11870680606","pt":1723548006440,"mc":[{"id":"1.231705583","rc":[{"batb":[[0,2.3,10],[1,2.28,30.26],[2,1.74,1]],"ltp":2.28,"tv":0.79,"id":655}]}]}
{"op":"mcm","clk":"11870680738","pt":1723548010156,"mc":[{"id":"1.231705583","rc":[{"batb":[[0,2.28,30.26],[1,1.74,1],[2,1.25,100]],"ltp":2.28,"tv":0.79,"id":655}]}]}
{"op":"mcm","clk":"11870680871","pt":1723548014016,"mc":[{"id":"1.231705583","rc":[{"batb":[[0,2.3,10],[1,2.28,30.26],[2,1.74,1]],"ltp":2.28,"tv":0.79,"id":655}]}]}
{"op":"mcm","clk":"11870680993","pt":1723548017354,"mc":[{"id":"1.231705583","rc":[{"batb":[[0,2.28,30.26],[1,1.74,1],[2,1.25,100]],"ltp":2.28,"tv":0.79,"id":655}]}]}
{"op":"mcm","clk":"11870681088","pt":1723548019827,"mc":[{"id":"1.231705583","rc":[{"batb":[[0,2.3,10],[1,2.28,30.26],[2,1.74,1]],"ltp":2.28,"tv":0.79,"id":655}]}]}
{"op":"mcm","clk":"11870681210","pt":1723548023270,"mc":[{"id":"1.231705583","rc":[{"batb":[[0,2.28,30.26],[1,1.74,1],[2,1.25,100]],"ltp":2.28,"tv":0.79,"id":655}]}]}
{"op":"mcm","clk":"11870681628","pt":1723548032855,"mc":[{"id":"1.231705583","rc":[{"batb":[[0,2.3,10],[1,2.28,30.26],[2,1.74,1]],"ltp":2.28,"tv":0.79,"id":655}]}]}
{"op":"mcm","clk":"11870681748","pt":1723548036046,"mc":[{"id":"1.231705583","rc":[{"batb":[[0,2.28,30.26],[1,1.74,1],[2,1.25,100]],"ltp":2.28,"tv":0.79,"id":655}]}]}
{"op":"mcm","clk":"11870682003","pt":1723548041550,"mc":[{"id":"1.231705583","rc":[{"batb":[[0,2.3,10],[1,2.28,30.26],[2,1.74,1]],"ltp":2.28,"tv":0.79,"id":655}]}]}
{"op":"mcm","clk":"11870682130","pt":1723548045565,"mc":[{"id":"1.231705583","rc":[{"batb":[[0,2.28,30.26],[1,1.74,1],[2,1.25,100]],"ltp":2.28,"tv":0.79,"id":655}]}]}
{"op":"mcm","clk":"11870682372","pt":1723548051694,"mc":[{"id":"1.231705583","rc":[{"batb":[[0,2.3,10],[1,2.28,30.26],[2,1.74,1]],"ltp":2.28,"tv":0.79,"id":655}]}]}
{"op":"mcm","clk":"11870682493","pt":1723548055199,"mc":[{"id":"1.231705583","rc":[{"batb":[[0,2.28,30.26],[1,1.74,1],[2,1.25,100]],"ltp":2.28,"tv":0.79,"id":655}]}]}
{"op":"mcm","clk":"11870682599","pt":1723548057681,"mc":[{"id":"1.231705583","rc":[{"batb":[[0,2.3,10],[1,2.28,30.26],[2,1.74,1]],"ltp":2.28,"tv":0.79,"id":655}]}]}
{"op":"mcm","clk":"11870682765","pt":1723548061504,"mc":[{"id":"1.231705583","rc":[{"batb":[[0,2.28,30.26],[1,1.74,1],[2,1.25,100]],"ltp":2.28,"tv":0.79,"id":655}]}]}
{"op":"mcm","clk":"11870682913","pt":1723548065013,"mc":[{"id":"1.231705583","rc":[{"batb":[[0,2.3,10],[1,2.28,30.26],[2,1.74,1]],"ltp":2.28,"tv":0.79,"id":655}]}]}
{"op":"mcm","clk":"11870683105","pt":1723548068622,"mc":[{"id":"1.231705583","rc":[{"batb":[[0,2.28,30.26],[1,1.74,1],[2,1.25,100]],"ltp":2.28,"tv":0.79,"id":655}]}]}
{"op":"mcm","clk":"11870683228","pt":1723548071220,"mc":[{"id":"1.231705583","rc":[{"batb":[[0,2.3,10],[1,2.28,30.26],[2,1.74,1]],"ltp":2.28,"tv":0.79,"id":655}]}]}
{"op":"mcm","clk":"11870683351","pt":1723548074533,"mc":[{"id":"1.231705583","rc":[{"batb":[[0,2.28,30.26],[1,1.74,1],[2,1.25,100]],"ltp":2.28,"tv":0.79,"id":655}]}]}
{"op":"mcm","clk":"11870683536","pt":1723548078915,"mc":[{"id":"1.231705583","rc":[{"batb":[[0,2.3,10],[1,2.28,30.26],[2,1.74,1]],"ltp":2.28,"tv":0.79,"id":655}]}]}
{"op":"mcm","clk":"11870683699","pt":1723548082411,"mc":[{"id":"1.231705583","rc":[{"batb":[[0,2.28,30.26],[1,1.74,1],[2,1.25,100]],"ltp":2.28,"tv":0.79,"id":655}]}]}
{"op":"mcm","clk":"11870683932","pt":1723548087419,"mc":[{"id":"1.231705583","rc":[{"batb":[[0,2.3,10],[1,2.28,30.26],[2,1.74,1]],"ltp":2.28,"tv":0.79,"id":655}]}]}
{"op":"mcm","clk":"11870684109","pt":1723548091022,"mc":[{"id":"1.231705583","rc":[{"batb":[[0,2.28,30.26],[1,1.74,1],[2,1.25,100]],"ltp":2.28,"tv":0.79,"id":655}]}]}
{"op":"mcm","clk":"11870684292","pt":1723548095160,"mc":[{"id":"1.231705583","rc":[{"batb":[[0,2.3,10],[1,2.28,30.26],[2,1.74,1]],"ltp":2.28,"tv":0.79,"id":655}]}]}
{"op":"mcm","clk":"11870684446","pt":1723548098352,"mc":[{"id":"1.231705583","rc":[{"batb":[[0,2.28,30.26],[1,1.74,1],[2,1.25,100]],"ltp":2.28,"tv":0.79,"id":655}]}]}
{"op":"mcm","clk":"11870684595","pt":1723548101965,"mc":[{"id":"1.231705583","rc":[{"batb":[[0,2.3,10],[1,2.28,30.26],[2,1.74,1]],"ltp":2.28,"tv":0.79,"id":655}]}]}
{"op":"mcm","clk":"11870684761","pt":1723548105223,"mc":[{"id":"1.231705583","rc":[{"batb":[[0,2.28,30.26],[1,1.74,1],[2,1.25,100]],"ltp":2.28,"tv":0.79,"id":655}]}]}
{"op":"mcm","clk":"11870684934","pt":1723548108628,"mc":[{"id":"1.231705583","rc":[{"batb":[[0,2.3,10],[1,2.28,30.26],[2,1.74,1]],"ltp":2.28,"tv":0.79,"id":655}]}]}
{"op":"mcm","clk":"11870685060","pt":1723548111868,"mc":[{"id":"1.231705583","rc":[{"batb":[[0,2.28,30.26],[1,1.74,1],[2,1.25,100]],"ltp":2.28,"tv":0.79,"id":655}]}]}
{"op":"mcm","clk":"11870685235","pt":1723548115376,"mc":[{"id":"1.231705583","rc":[{"batb":[[0,2.3,10],[1,2.28,30.26],[2,1.74,1]],"ltp":2.28,"tv":0.79,"id":655}]}]}
{"op":"mcm","clk":"11870685366","pt":1723548118573,"mc":[{"id":"1.231705583","rc":[{"batb":[[0,2.28,30.26],[1,1.74,1],[2,1.25,100]],"ltp":2.28,"tv":0.79,"id":655}]}]}
{"op":"mcm","clk":"11870685479","pt":1723548121052,"mc":[{"id":"1.231705583","rc":[{"batb":[[0,2.3,10],[1,2.28,30.26],[2,1.74,1]],"ltp":2.28,"tv":0.79,"id":655}]}]}
{"op":"mcm","clk":"11870685669","pt":1723548124355,"mc":[{"id":"1.231705583","rc":[{"batb":[[0,2.28,30.26],[1,1.74,1],[2,1.25,100]],"ltp":2.28,"tv":0.79,"id":655}]}]}
{"op":"mcm","clk":"11870685895","pt":1723548128368,"mc":[{"id":"1.231705583","rc":[{"batb":[[0,2.3,10],[1,2.28,30.26],[2,1.74,1]],"ltp":2.28,"tv":0.79,"id":655}]}]}
{"op":"mcm","clk":"11870686045","pt":1723548132176,"mc":[{"id":"1.231705583","rc":[{"batb":[[0,2.28,30.26],[1,1.74,1],[2,1.25,100]],"ltp":2.28,"tv":0.79,"id":655}]}]}
{"op":"mcm","clk":"11870686182","pt":1723548135369,"mc":[{"id":"1.231705583","rc":[{"batb":[[0,2.3,10],[1,2.28,30.26],[2,1.74,1]],"ltp":2.28,"tv":0.79,"id":655}]}]}
{"op":"mcm","clk":"11870686323","pt":1723548138664,"mc":[{"id":"1.231705583","rc":[{"batb":[[0,2.28,30.26],[1,1.74,1],[2,1.25,100]],"ltp":2.28,"tv":0.79,"id":655}]}]}
{"op":"mcm","clk":"11870686472","pt":1723548141596,"mc":[{"id":"1.231705583","rc":[{"batb":[[0,2.3,10],[1,2.28,30.26],[2,1.74,1]],"ltp":2.28,"tv":0.79,"id":655}]}]}
{"op":"mcm","clk":"11870686678","pt":1723548147111,"mc":[{"id":"1.231705583","rc":[{"batb":[[0,2.28,30.26],[1,1.74,1],[2,1.25,100]],"ltp":2.28,"tv":0.79,"id":655}]}]}
{"op":"mcm","clk":"11870686744","pt":1723548149486,"mc":[{"id":"1.231705583","rc":[{"batb":[[0,2.3,10],[1,2.28,30.26],[2,1.74,1]],"ltp":2.28,"tv":0.79,"id":655}]}]}
{"op":"mcm","clk":"11870686871","pt":1723548153081,"mc":[{"id":"1.231705583","rc":[{"batb":[[0,2.28,30.26],[1,1.74,1],[2,1.25,100]],"ltp":2.28,"tv":0.79,"id":655}]}]}
{"op":"mcm","clk":"11870686959","pt":1723548155501,"mc":[{"id":"1.231705583","rc":[{"batb":[[0,2.3,10],[1,2.28,30.26],[2,1.74,1]],"ltp":2.28,"tv":0.79,"id":655}]}]}
{"op":"mcm","clk":"11870687128","pt":1723548158811,"mc":[{"id":"1.231705583","rc":[{"batb":[[0,2.28,30.26],[1,1.74,1],[2,1.25,100]],"ltp":2.28,"tv":0.79,"id":655}]}]}
{"op":"mcm","clk":"11870687246","pt":1723548161493,"mc":[{"id":"1.231705583","rc":[{"batb":[[0,2.3,10],[1,2.28,30.26],[2,1.74,1]],"ltp":2.28,"tv":0.79,"id":655}]}]}
{"op":"mcm","clk":"11870687371","pt":1723548164933,"mc":[{"id":"1.231705583","rc":[{"batb":[[0,2.28,30.26],[1,1.74,1],[2,1.25,100]],"ltp":2.28,"tv":0.79,"id":655}]}]}
{"op":"mcm","clk":"11870687500","pt":1723548167508,"mc":[{"id":"1.231705583","rc":[{"batb":[[0,2.3,10],[1,2.28,30.26],[2,1.74,1]],"ltp":2.28,"tv":0.79,"id":655}]}]}
{"op":"mcm","clk":"11870687643","pt":1723548171041,"mc":[{"id":"1.231705583","rc":[{"batb":[[0,2.28,30.26],[1,1.74,1],[2,1.25,100]],"ltp":2.28,"tv":0.79,"id":655}]}]}
{"op":"mcm","clk":"11870687773","pt":1723548173618,"mc":[{"id":"1.231705583","rc":[{"batb":[[0,2.3,10],[1,2.28,30.26],[2,1.74,1]],"ltp":2.28,"tv":0.79,"id":655}]}]}
{"op":"mcm","clk":"11870687934","pt":1723548177150,"mc":[{"id":"1.231705583","rc":[{"batb":[[0,2.28,30.26],[1,1.74,1],[2,1.25,100]],"ltp":2.28,"tv":0.79,"id":655}]}]}
{"op":"mcm","clk":"11870688117","pt":1723548181523,"mc":[{"id":"1.231705583","rc":[{"batb":[[0,2.3,10],[1,2.28,30.26],[2,1.74,1]],"ltp":2.28,"tv":0.79,"id":655}]}]}
{"op":"mcm","clk":"11870688282","pt":1723548184861,"mc":[{"id":"1.231705583","rc":[{"batb":[[0,2.28,30.26],[1,1.74,1],[2,1.25,100]],"ltp":2.28,"tv":0.79,"id":655}]}]}
{"op":"mcm","clk":"11870688447","pt":1723548188566,"mc":[{"id":"1.231705583","rc":[{"batb":[[0,2.3,10],[1,2.28,30.26],[2,1.74,1]],"ltp":2.28,"tv":0.79,"id":655}]}]}
{"op":"mcm","clk":"11870688588","pt":1723548191854,"mc":[{"id":"1.231705583","rc":[{"batb":[[0,2.28,30.26],[1,1.74,1],[2,1.25,100]],"ltp":2.28,"tv":0.79,"id":655}]}]}
{"op":"mcm","clk":"11870688716","pt":1723548195044,"mc":[{"id":"1.231705583","rc":[{"batb":[[0,2.3,10],[1,2.28,30.26],[2,1.74,1]],"ltp":2.28,"tv":0.79,"id":655}]}]}
{"op":"mcm","clk":"11870688887","pt":1723548198749,"mc":[{"id":"1.231705583","rc":[{"batb":[[0,2.28,30.26],[1,1.74,1],[2,1.25,100]],"ltp":2.28,"tv":0.79,"id":655}]}]}
{"op":"mcm","clk":"11870689033","pt":1723548202541,"mc":[{"id":"1.231705583","rc":[{"batb":[[0,2.3,10],[1,2.28,30.26],[2,1.74,1]],"ltp":2.28,"tv":0.79,"id":655}]}]}
{"op":"mcm","clk":"11870689168","pt":1723548205980,"mc":[{"id":"1.231705583","rc":[{"batb":[[0,2.28,30.26],[1,1.74,1],[2,1.25,100]],"ltp":2.28,"tv":0.79,"id":655}]}]}
{"op":"mcm","clk":"11870689258","pt":1723548208287,"mc":[{"id":"1.231705583","rc":[{"batb":[[0,2.3,10],[1,2.28,30.26],[2,1.74,1]],"ltp":2.28,"tv":0.79,"id":655}]}]}
{"op":"mcm","clk":"11870689384","pt":1723548211683,"mc":[{"id":"1.231705583","rc":[{"batb":[[0,2.28,30.26],[1,1.74,1],[2,1.25,100]],"ltp":2.28,"tv":0.79,"id":655}]}]}
{"op":"mcm","clk":"11870689628","pt":1723548217703,"mc":[{"id":"1.231705583","rc":[{"batb":[[0,2.3,10],[1,2.28,30.26],[2,1.74,1]],"ltp":2.28,"tv":0.79,"id":655}]}]}
{"op":"mcm","clk":"11870689808","pt":1723548220995,"mc":[{"id":"1.231705583","rc":[{"batb":[[0,2.28,30.26],[1,1.74,1],[2,1.25,100]],"ltp":2.28,"tv":0.79,"id":655}]}]}
{"op":"mcm","clk":"11870689956","pt":1723548224695,"mc":[{"id":"1.231705583","rc":[{"batb":[[0,2.3,10],[1,2.28,30.26],[2,1.74,1]],"ltp":2.28,"tv":0.79,"id":655}]}]}
{"op":"mcm","clk":"11870690105","pt":1723548228203,"mc":[{"id":"1.231705583","rc":[{"batb":[[0,2.28,30.26],[1,1.74,1],[2,1.25,100]],"ltp":2.28,"tv":0.79,"id":655}]}]}
{"op":"mcm","clk":"11870690269","pt":1723548232325,"mc":[{"id":"1.231705583","rc":[{"batb":[[0,2.3,10],[1,2.28,30.26],[2,1.74,1]],"ltp":2.28,"tv":0.79,"id":655}]}]}
{"op":"mcm","clk":"11870690427","pt":1723548235713,"mc":[{"id":"1.231705583","rc":[{"batb":[[0,2.28,30.26],[1,1.74,1],[2,1.25,100]],"ltp":2.28,"tv":0.79,"id":655}]}]}
{"op":"mcm","clk":"11870690587","pt":1723548239716,"mc":[{"id":"1.231705583","rc":[{"batb":[[0,2.3,10],[1,2.28,30.26],[2,1.74,1]],"ltp":2.28,"tv":0.79,"id":655}]}]}
{"op":"mcm","clk":"11870690758","pt":1723548243605,"mc":[{"id":"1.231705583","rc":[{"batb":[[0,2.28,30.26],[1,1.74,1],[2,1.25,100]],"ltp":2.28,"tv":0.79,"id":655}]}]}
{"op":"mcm","clk":"11870690900","pt":1723548246299,"mc":[{"id":"1.231705583","rc":[{"batb":[[0,2.3,10],[1,2.28,30.26],[2,1.74,1]],"ltp":2.28,"tv":0.79,"id":655}]}]}
{"op":"mcm","clk":"11870691092","pt":1723548249699,"mc":[{"id":"1.231705583","rc":[{"batb":[[0,2.28,30.26],[1,1.74,1],[2,1.25,100]],"ltp":2.28,"tv":0.79,"id":655}]}]}
{"op":"mcm","clk":"11870691233","pt":1723548252117,"mc":[{"id":"1.231705583","rc":[{"batb":[[0,2.3,10],[1,2.28,30.26],[2,1.74,1]],"ltp":2.28,"tv":0.79,"id":655}]}]}
{"op":"mcm","clk":"11870691436","pt":1723548255835,"mc":[{"id":"1.231705583","rc":[{"batb":[[0,2.28,30.26],[1,1.74,1],[2,1.25,100]],"ltp":2.28,"tv":0.79,"id":655}]}]}
{"op":"mcm","clk":"11870691554","pt":1723548258312,"mc":[{"id":"1.231705583","rc":[{"batb":[[0,2.3,10],[1,2.28,30.26],[2,1.74,1]],"ltp":2.28,"tv":0.79,"id":655}]}]}
{"op":"mcm","clk":"11870691710","pt":1723548261814,"mc":[{"id":"1.231705583","rc":[{"batb":[[0,2.28,30.26],[1,1.74,1],[2,1.25,100]],"ltp":2.28,"tv":0.79,"id":655}]}]}
{"op":"mcm","clk":"11870691819","pt":1723548264125,"mc":[{"id":"1.231705583","rc":[{"batb":[[0,2.3,10],[1,2.28,30.26],[2,1.74,1]],"ltp":2.28,"tv":0.79,"id":655}]}]}
{"op":"mcm","clk":"11870691991","pt":1723548267826,"mc":[{"id":"1.231705583","rc":[{"batb":[[0,2.28,30.26],[1,1.74,1],[2,1.25,100]],"ltp":2.28,"tv":0.79,"id":655}]}]}
{"op":"mcm","clk":"11870692155","pt":1723548271933,"mc":[{"id":"1.231705583","rc":[{"batb":[[0,2.3,10],[1,2.28,30.26],[2,1.74,1]],"ltp":2.28,"tv":0.79,"id":655}]}]}
{"op":"mcm","clk":"11870692306","pt":1723548275232,"mc":[{"id":"1.231705583","rc":[{"batb":[[0,2.28,30.26],[1,1.74,1],[2,1.25,100]],"ltp":2.28,"tv":0.79,"id":655}]}]}
{"op":"mcm","clk":"11870692418","pt":1723548277757,"mc":[{"id":"1.231705583","rc":[{"batb":[[0,2.3,10],[1,2.28,30.26],[2,1.74,1]],"ltp":2.28,"tv":0.79,"id":655}]}]}
{"op":"mcm","clk":"11870692573","pt":1723548280950,"mc":[{"id":"1.231705583","rc":[{"batb":[[0,2.28,30.26],[1,1.74,1],[2,1.25,100]],"ltp":2.28,"tv":0.79,"id":655}]}]}
{"op":"mcm","clk":"11870692776","pt":1723548284456,"mc":[{"id":"1.231705583","rc":[{"batb":[[0,2.3,10],[1,2.28,30.26],[2,1.74,1]],"ltp":2.28,"tv":0.79,"id":655}]}]}
{"op":"mcm","clk":"11870692942","pt":1723548287751,"mc":[{"id":"1.231705583","rc":[{"batb":[[0,2.28,30.26],[1,1.74,1],[2,1.25,100]],"ltp":2.28,"tv":0.79,"id":655}]}]}
{"op":"mcm","clk":"11870693112","pt":1723548291457,"mc":[{"id":"1.231705583","rc":[{"batb":[[0,2.3,10],[1,2.28,30.26],[2,1.74,1]],"ltp":2.28,"tv":0.79,"id":655}]}]}
{"op":"mcm","clk":"11870693309","pt":1723548294871,"mc":[{"id":"1.231705583","rc":[{"batb":[[0,2.28,30.26],[1,1.74,1],[2,1.25,100]],"ltp":2.28,"tv":0.79,"id":655}]}]}
{"op":"mcm","clk":"11870693527","pt":1723548298854,"mc":[{"id":"1.231705583","rc":[{"batb":[[0,2.3,10],[1,2.28,30.26],[2,1.74,1]],"ltp":2.28,"tv":0.79,"id":655}]}]}
{"op":"mcm","clk":"11870693722","pt":1723548302287,"mc":[{"id":"1.231705583","rc":[{"batb":[[0,2.28,30.26],[1,1.74,1],[2,1.25,100]],"ltp":2.28,"tv":0.79,"id":655}]}]}
{"op":"mcm","clk":"11870693982","pt":1723548307091,"mc":[{"id":"1.231705583","rc":[{"batb":[[0,2.3,10],[1,2.28,30.26],[2,1.74,1]],"ltp":2.28,"tv":0.79,"id":655}]}]}
{"op":"mcm","clk":"11870694182","pt":1723548310504,"mc":[{"id":"1.231705583","rc":[{"batb":[[0,2.28,30.26],[1,1.74,1],[2,1.25,100]],"ltp":2.28,"tv":0.79,"id":655}]}]}
{"op":"mcm","clk":"11870694374","pt":1723548314184,"mc":[{"id":"1.231705583","rc":[{"batb":[[0,2.3,10],[1,2.28,30.26],[2,1.74,1]],"ltp":2.28,"tv":0.79,"id":655}]}]}
{"op":"mcm","clk":"11870694553","pt":1723548317595,"mc":[{"id":"1.231705583","rc":[{"batb":[[0,2.28,30.26],[1,1.74,1],[2,1.25,100]],"ltp":2.28,"tv":0.79,"id":655}]}]}
{"op":"mcm","clk":"11870694848","pt":1723548322876,"mc":[{"id":"1.231705583","rc":[{"batb":[[0,2.3,10],[1,2.28,30.26],[2,1.74,1]],"ltp":2.28,"tv":0.79,"id":655}]}]}
{"op":"mcm","clk":"11870695038","pt":1723548326493,"mc":[{"id":"1.231705583","rc":[{"batb":[[0,2.28,30.26],[1,1.74,1],[2,1.25,100]],"ltp":2.28,"tv":0.79,"id":655}]}]}
{"op":"mcm","clk":"11870695547","pt":1723548335831,"mc":[{"id":"1.231705583","rc":[{"batb":[[0,2.3,10],[1,2.28,30.26],[2,1.74,1]],"ltp":2.28,"tv":0.79,"id":655}]}]}
{"op":"mcm","clk":"11870695706","pt":1723548339401,"mc":[{"id":"1.231705583","rc":[{"batb":[[0,2.28,30.26],[1,1.74,1],[2,1.25,100]],"ltp":2.28,"tv":0.79,"id":655}]}]}
{"op":"mcm","clk":"11870695763","pt":1723548340224,"mc":[{"id":"1.231705583","rc":[{"batb":[[0,2.32,29.35]],"ltp":2.28,"tv":0.79,"id":655},{"batb":[[0,1.69,56.15]],"ltp":1.73,"tv":112.64,"id":169}]}]}
{"op":"mcm","clk":"11870695876","pt":1723548342639,"mc":[{"id":"1.231705583","rc":[{"batb":[[0,2.34,10],[1,2.32,29.35],[2,1.74,1]],"ltp":2.28,"tv":0.79,"id":655}]}]}
{"op":"mcm","clk":"11870696081","pt":1723548346030,"mc":[{"id":"1.231705583","rc":[{"batb":[[0,2.32,29.35],[1,1.74,1],[2,1.25,100]],"ltp":2.28,"tv":0.79,"id":655}]}]}
{"op":"mcm","clk":"11870696250","pt":1723548349850,"mc":[{"id":"1.231705583","rc":[{"batb":[[0,2.34,10],[1,2.32,29.35],[2,1.74,1]],"ltp":2.28,"tv":0.79,"id":655}]}]}
{"op":"mcm","clk":"11870696427","pt":1723548353243,"mc":[{"id":"1.231705583","rc":[{"batb":[[0,2.32,29.35],[1,1.74,1],[2,1.25,100]],"ltp":2.28,"tv":0.79,"id":655}]}]}
{"op":"mcm","clk":"11870696519","pt":1723548355516,"mc":[{"id":"1.231705583","rc":[{"batb":[[0,2.34,10],[1,2.32,29.35],[2,1.74,1]],"ltp":2.28,"tv":0.79,"id":655}]}]}
{"op":"mcm","clk":"11870696661","pt":1723548358856,"mc":[{"id":"1.231705583","rc":[{"batb":[[0,2.32,29.35],[1,1.74,1],[2,1.25,100]],"ltp":2.28,"tv":0.79,"id":655}]}]}
{"op":"mcm","clk":"11870696933","pt":1723548363756,"mc":[{"id":"1.231705583","rc":[{"batb":[[0,2.34,10],[1,2.32,29.35],[2,1.74,1]],"ltp":2.28,"tv":0.79,"id":655}]}]}
{"op":"mcm","clk":"11870697142","pt":1723548367660,"mc":[{"id":"1.231705583","rc":[{"batb":[[0,2.32,29.35],[1,1.74,1],[2,1.25,100]],"ltp":2.28,"tv":0.79,"id":655}]}]}
{"op":"mcm","clk":"11870697369","pt":1723548373371,"mc":[{"id":"1.231705583","rc":[{"batb":[[0,2.34,10],[1,2.32,29.35],[2,1.74,1]],"ltp":2.28,"tv":0.79,"id":655}]}]}
{"op":"mcm","clk":"11870697560","pt":1723548376765,"mc":[{"id":"1.231705583","rc":[{"batb":[[0,2.32,29.35],[1,1.74,1],[2,1.25,100]],"ltp":2.28,"tv":0.79,"id":655}]}]}
{"op":"mcm","clk":"11870697762","pt":1723548380771,"mc":[{"id":"1.231705583","rc":[{"batb":[[0,2.34,10],[1,2.32,29.35],[2,1.74,1]],"ltp":2.28,"tv":0.79,"id":655}]}]}
{"op":"mcm","clk":"11870697887","pt":1723548384058,"mc":[{"id":"1.231705583","rc":[{"batb":[[0,2.32,29.35],[1,1.74,1],[2,1.25,100]],"ltp":2.28,"tv":0.79,"id":655}]}]}
{"op":"mcm","clk":"11870698013","pt":1723548387149,"mc":[{"id":"1.231705583","rc":[{"batb":[[0,2.34,10],[1,2.32,29.35],[2,1.74,1]],"ltp":2.28,"tv":0.79,"id":655}]}]}
{"op":"mcm","clk":"11870698171","pt":1723548390553,"mc":[{"id":"1.231705583","rc":[{"batb":[[0,2.32,29.35],[1,1.74,1],[2,1.25,100]],"ltp":2.28,"tv":0.79,"id":655}]}]}
{"op":"mcm","clk":"11870698477","pt":1723548398292,"mc":[{"id":"1.231705583","rc":[{"batb":[[0,2.34,10],[1,2.32,29.35],[2,1.74,1]],"ltp":2.28,"tv":0.79,"id":655}]}]}
{"op":"mcm","clk":"11870698607","pt":1723548401781,"mc":[{"id":"1.231705583","rc":[{"batb":[[0,2.32,29.35],[1,1.74,1],[2,1.25,100]],"ltp":2.28,"tv":0.79,"id":655}]}]}
{"op":"mcm","clk":"11870698728","pt":1723548405693,"mc":[{"id":"1.231705583","rc":[{"batb":[[0,2.34,10],[1,2.32,29.35],[2,1.74,1]],"ltp":2.28,"tv":0.79,"id":655}]}]}
{"op":"mcm","clk":"11870698826","pt":1723548409184,"mc":[{"id":"1.231705583","rc":[{"batb":[[0,2.32,29.35],[1,1.74,1],[2,1.25,100]],"ltp":2.28,"tv":0.79,"id":655}]}]}
{"op":"mcm","clk":"11870698913","pt":1723548412722,"mc":[{"id":"1.231705583","rc":[{"batb":[[0,2.34,10],[1,2.32,29.35],[2,1.74,1]],"ltp":2.28,"tv":0.79,"id":655}]}]}
{"op":"mcm","clk":"11870699019","pt":1723548416114,"mc":[{"id":"1.231705583","rc":[{"batb":[[0,2.32,29.35],[1,1.74,1],[2,1.25,100]],"ltp":2.28,"tv":0.79,"id":655}]}]}
{"op":"mcm","clk":"11870699089","pt":1723548418317,"mc":[{"id":"1.231705583","rc":[{"batb":[[0,2.34,10],[1,2.32,29.35],[2,1.74,1]],"ltp":2.28,"tv":0.79,"id":655}]}]}
{"op":"mcm","clk":"11870699263","pt":1723548422036,"mc":[{"id":"1.231705583","rc":[{"batb":[[0,2.32,29.35],[1,1.74,1],[2,1.25,100]],"ltp":2.28,"tv":0.79,"id":655}]}]}
{"op":"mcm","clk":"11870699399","pt":1723548425637,"mc":[{"id":"1.231705583","rc":[{"batb":[[0,2.34,10],[1,2.32,29.35],[2,1.74,1]],"ltp":2.28,"tv":0.79,"id":655}]}]}
{"op":"mcm","clk":"11870699505","pt":1723548429036,"mc":[{"id":"1.231705583","rc":[{"batb":[[0,2.32,29.35],[1,1.74,1],[2,1.25,100]],"ltp":2.28,"tv":0.79,"id":655}]}]}
{"op":"mcm","clk":"11870699691","pt":1723548433925,"mc":[{"id":"1.231705583","rc":[{"batb":[[0,2.34,10],[1,2.32,29.35],[2,1.74,1]],"ltp":2.28,"tv":0.79,"id":655}]}]}
{"op":"mcm","clk":"11870699824","pt":1723548437316,"mc":[{"id":"1.231705583","rc":[{"batb":[[0,2.32,29.35],[1,1.74,1],[2,1.25,100]],"ltp":2.28,"tv":0.79,"id":655}]}]}
{"op":"mcm","clk":"11870699976","pt":1723548440753,"mc":[{"id":"1.231705583","rc":[{"batb":[[0,2.34,10],[1,2.32,29.35],[2,1.74,1]],"ltp":2.28,"tv":0.79,"id":655}]}]}
{"op":"mcm","clk":"11870700129","pt":1723548444049,"mc":[{"id":"1.231705583","rc":[{"batb":[[0,2.32,29.35],[1,1.74,1],[2,1.25,100]],"ltp":2.28,"tv":0.79,"id":655}]}]}
{"op":"mcm","clk":"11870700305","pt":1723548448260,"mc":[{"id":"1.231705583","rc":[{"batb":[[0,2.34,10],[1,2.32,29.35],[2,1.74,1]],"ltp":2.28,"tv":0.79,"id":655}]}]}
{"op":"mcm","clk":"11870700459","pt":1723548451758,"mc":[{"id":"1.231705583","rc":[{"batb":[[0,2.32,29.35],[1,1.74,1],[2,1.25,100]],"ltp":2.28,"tv":0.79,"id":655}]}]}
{"op":"mcm","clk":"11870700690","pt":1723548458072,"mc":[{"id":"1.231705583","rc":[{"batb":[[0,2.34,10],[1,2.32,29.35],[2,1.74,1]],"ltp":2.28,"tv":0.79,"id":655}]}]}
{"op":"mcm","clk":"11870700817","pt":1723548461457,"mc":[{"id":"1.231705583","rc":[{"batb":[[0,2.32,29.35],[1,1.74,1],[2,1.25,100]],"ltp":2.28,"tv":0.79,"id":655}]}]}
{"op":"mcm","clk":"11870700983","pt":1723548465164,"mc":[{"id":"1.231705583","rc":[{"batb":[[0,2.34,10],[1,2.32,29.35],[2,1.74,1]],"ltp":2.28,"tv":0.79,"id":655}]}]}
{"op":"mcm","clk":"11870701170","pt":1723548468976,"mc":[{"id":"1.231705583","rc":[{"batb":[[0,2.32,29.35],[1,1.74,1],[2,1.25,100]],"ltp":2.28,"tv":0.79,"id":655}]}]}
{"op":"mcm","clk":"11870701426","pt":1723548474678,"mc":[{"id":"1.231705583","rc":[{"batb":[[0,2.34,10],[1,2.32,29.35],[2,1.74,1]],"ltp":2.28,"tv":0.79,"id":655}]}]}
{"op":"mcm","clk":"11870701590","pt":1723548478386,"mc":[{"id":"1.231705583","rc":[{"batb":[[0,2.32,29.35],[1,1.74,1],[2,1.25,100]],"ltp":2.28,"tv":0.79,"id":655}]}]}
{"op":"mcm","clk":"11870702115","pt":1723548487689,"mc":[{"id":"1.231705583","rc":[{"batb":[[0,2.34,10],[1,2.32,29.35],[2,1.74,1]],"ltp":2.28,"tv":0.79,"id":655}]}]}
{"op":"mcm","clk":"11870702271","pt":1723548491205,"mc":[{"id":"1.231705583","rc":[{"batb":[[0,2.32,29.35],[1,1.74,1],[2,1.25,100]],"ltp":2.28,"tv":0.79,"id":655}]}]}
{"op":"mcm","clk":"11870702386","pt":1723548493796,"mc":[{"id":"1.231705583","rc":[{"batb":[[0,2.34,10],[1,2.32,29.35],[2,1.74,1]],"ltp":2.28,"tv":0.79,"id":655}]}]}
{"op":"mcm","clk":"11870702593","pt":1723548497502,"mc":[{"id":"1.231705583","rc":[{"batb":[[0,2.32,29.35],[1,1.74,1],[2,1.25,100]],"ltp":2.28,"tv":0.79,"id":655}]}]}
{"op":"mcm","clk":"11870702724","pt":1723548499718,"mc":[{"id":"1.231705583","rc":[{"batb":[[0,2.34,10],[1,2.32,29.35],[2,1.74,1]],"ltp":2.28,"tv":0.79,"id":655}]}]}
{"op":"mcm","clk":"11870702890","pt":1723548503422,"mc":[{"id":"1.231705583","rc":[{"batb":[[0,2.32,29.35],[1,1.74,1],[2,1.25,100]],"ltp":2.28,"tv":0.79,"id":655}]}]}
{"op":"mcm","clk":"11870703187","pt":1723548509540,"mc":[{"id":"1.231705583","rc":[{"batb":[[0,2.34,10],[1,2.32,29.35],[2,1.74,1]],"ltp":2.28,"tv":0.79,"id":655}]}]}
{"op":"mcm","clk":"11870703409","pt":1723548513517,"mc":[{"id":"1.231705583","rc":[{"batb":[[0,2.32,29.35],[1,1.74,1],[2,1.25,100]],"ltp":2.28,"tv":0.79,"id":655}]}]}
{"op":"mcm","clk":"11870703523","pt":1723548515823,"mc":[{"id":"1.231705583","rc":[{"batb":[[0,2.34,10],[1,2.32,29.35],[2,1.74,1]],"ltp":2.28,"tv":0.79,"id":655}]}]}
{"op":"mcm","clk":"11870703679","pt":1723548519552,"mc":[{"id":"1.231705583","rc":[{"batb":[[0,2.32,29.35],[1,1.74,1],[2,1.25,100]],"ltp":2.28,"tv":0.79,"id":655}]}]}
{"op":"mcm","clk":"11870703852","pt":1723548523721,"mc":[{"id":"1.231705583","rc":[{"batb":[[0,2.34,10],[1,2.32,29.35],[2,1.74,1]],"ltp":2.28,"tv":0.79,"id":655}]}]}
{"op":"mcm","clk":"11870703986","pt":1723548527153,"mc":[{"id":"1.231705583","rc":[{"batb":[[0,2.32,29.35],[1,1.74,1],[2,1.25,100]],"ltp":2.28,"tv":0.79,"id":655}]}]}
{"op":"mcm","clk":"11870704093","pt":1723548530237,"mc":[{"id":"1.231705583","rc":[{"batb":[[0,2.34,10],[1,2.32,29.35],[2,1.74,1]],"ltp":2.28,"tv":0.79,"id":655}]}]}
{"op":"mcm","clk":"11870704221","pt":1723548533940,"mc":[{"id":"1.231705583","rc":[{"batb":[[0,2.32,29.35],[1,1.74,1],[2,1.25,100]],"ltp":2.28,"tv":0.79,"id":655}]}]}
{"op":"mcm","clk":"11870704302","pt":1723548536144,"mc":[{"id":"1.231705583","rc":[{"batb":[[0,2.34,10],[1,2.32,29.35],[2,1.74,1]],"ltp":2.28,"tv":0.79,"id":655}]}]}
{"op":"mcm","clk":"11870704418","pt":1723548539472,"mc":[{"id":"1.231705583","rc":[{"batb":[[0,2.32,29.35],[1,1.74,1],[2,1.25,100]],"ltp":2.28,"tv":0.79,"id":655}]}]}
{"op":"mcm","clk":"11870704639","pt":1723548544879,"mc":[{"id":"1.231705583","rc":[{"batb":[[0,2.34,10],[1,2.32,29.35],[2,1.74,1]],"ltp":2.28,"tv":0.79,"id":655}]}]}
{"op":"mcm","clk":"11870704785","pt":1723548548273,"mc":[{"id":"1.231705583","rc":[{"batb":[[0,2.32,29.35],[1,1.74,1],[2,1.25,100]],"ltp":2.28,"tv":0.79,"id":655}]}]}
{"op":"mcm","clk":"11870705035","pt":1723548553777,"mc":[{"id":"1.231705583","rc":[{"batb":[[0,2.34,10],[1,2.32,29.35],[2,1.74,1]],"ltp":2.28,"tv":0.79,"id":655}]}]}
{"op":"mcm","clk":"11870705201","pt":1723548557068,"mc":[{"id":"1.231705583","rc":[{"batb":[[0,2.32,29.35],[1,1.74,1],[2,1.25,100]],"ltp":2.28,"tv":0.79,"id":655}]}]}
{"op":"mcm","clk":"11870705345","pt":1723548561579,"mc":[{"id":"1.231705583","rc":[{"batb":[[0,2.34,10],[1,2.32,29.35],[2,1.74,1]],"ltp":2.28,"tv":0.79,"id":655}]}]}
{"op":"mcm","clk":"11870705452","pt":1723548564965,"mc":[{"id":"1.231705583","rc":[{"batb":[[0,2.32,29.35],[1,1.74,1],[2,1.25,100]],"ltp":2.28,"tv":0.79,"id":655}]}]}
{"op":"mcm","clk":"11870705572","pt":1723548568091,"mc":[{"id":"1.231705583","rc":[{"batb":[[0,2.34,10],[1,2.32,29.35],[2,1.74,1]],"ltp":2.28,"tv":0.79,"id":655}]}]}
{"op":"mcm","clk":"11870705709","pt":1723548571389,"mc":[{"id":"1.231705583","rc":[{"batb":[[0,2.32,29.35],[1,1.74,1],[2,1.25,100]],"ltp":2.28,"tv":0.79,"id":655}]}]}
{"op":"mcm","clk":"11870705971","pt":1723548578209,"mc":[{"id":"1.231705583","rc":[{"batb":[[0,2.34,10],[1,2.32,29.35],[2,1.74,1]],"ltp":2.28,"tv":0.79,"id":655}]}]}
{"op":"mcm","clk":"11870706097","pt":1723548581610,"mc":[{"id":"1.231705583","rc":[{"batb":[[0,2.32,29.35],[1,1.74,1],[2,1.25,100]],"ltp":2.28,"tv":0.79,"id":655}]}]}
{"op":"mcm","clk":"11870706513","pt":1723548592395,"mc":[{"id":"1.231705583","rc":[{"batb":[[0,2.34,10],[1,2.32,29.35],[2,1.74,1]],"ltp":2.28,"tv":0.79,"id":655}]}]}
{"op":"mcm","clk":"11870706658","pt":1723548595992,"mc":[{"id":"1.231705583","rc":[{"batb":[[0,2.32,29.35],[1,1.74,1],[2,1.25,100]],"ltp":2.28,"tv":0.79,"id":655}]}]}
{"op":"mcm","clk":"11870706788","pt":1723548599524,"mc":[{"id":"1.231705583","rc":[{"batb":[[0,2.34,10],[1,2.32,29.35],[2,1.74,1]],"ltp":2.28,"tv":0.79,"id":655}]}]}
{"op":"mcm","clk":"11870706973","pt":1723548602942,"mc":[{"id":"1.231705583","rc":[{"batb":[[0,2.32,29.35],[1,1.74,1],[2,1.25,100]],"ltp":2.28,"tv":0.79,"id":655}]}]}
{"op":"mcm","clk":"11870707121","pt":1723548605630,"mc":[{"id":"1.231705583","rc":[{"batb":[[0,2.34,10],[1,2.32,29.35],[2,1.74,1]],"ltp":2.28,"tv":0.79,"id":655}]}]}
{"op":"mcm","clk":"11870707288","pt":1723548609427,"mc":[{"id":"1.231705583","rc":[{"batb":[[0,2.32,29.35],[1,1.74,1],[2,1.25,100]],"ltp":2.28,"tv":0.79,"id":655}]}]}
{"op":"mcm","clk":"11870707442","pt":1723548612928,"mc":[{"id":"1.231705583","rc":[{"batb":[[0,2.34,10],[1,2.32,29.35],[2,1.74,1]],"ltp":2.28,"tv":0.79,"id":655}]}]}
{"op":"mcm","clk":"11870707634","pt":1723548616233,"mc":[{"id":"1.231705583","rc":[{"batb":[[0,2.32,29.35],[1,1.74,1],[2,1.25,100]],"ltp":2.28,"tv":0.79,"id":655}]}]}
{"op":"mcm","clk":"11870708117","pt":1723548627236,"mc":[{"id":"1.231705583","rc":[{"batb":[[0,2.34,10],[1,2.32,29.35],[2,1.74,1]],"ltp":2.28,"tv":0.79,"id":655}]}]}
{"op":"mcm","clk":"11870708258","pt":1723548630922,"mc":[{"id":"1.231705583","rc":[{"batb":[[0,2.32,29.35],[1,1.74,1],[2,1.25,100]],"ltp":2.28,"tv":0.79,"id":655}]}]}
{"op":"mcm","clk":"11870708448","pt":1723548636127,"mc":[{"id":"1.231705583","rc":[{"batb":[[0,2.34,10],[1,2.32,29.35],[2,1.74,1]],"ltp":2.28,"tv":0.79,"id":655}]}]}
{"op":"mcm","clk":"11870708573","pt":1723548639677,"mc":[{"id":"1.231705583","rc":[{"batb":[[0,2.32,29.35],[1,1.74,1],[2,1.25,100]],"ltp":2.28,"tv":0.79,"id":655}]}]}
{"op":"mcm","clk":"11870709022","pt":1723548651259,"mc":[{"id":"1.231705583","rc":[{"batb":[[0,2.34,10],[1,2.32,29.35],[2,1.74,1]],"ltp":2.28,"tv":0.79,"id":655}]}]}
{"op":"mcm","clk":"11870709146","pt":1723548654692,"mc":[{"id":"1.231705583","rc":[{"batb":[[0,2.32,29.35],[1,1.74,1],[2,1.25,100]],"ltp":2.28,"tv":0.79,"id":655}]}]}
{"op":"mcm","clk":"11870709335","pt":1723548659477,"mc":[{"id":"1.231705583","rc":[{"batb":[[0,2.34,10],[1,2.32,29.35],[2,1.74,1]],"ltp":2.28,"tv":0.79,"id":655}]}]}
{"op":"mcm","clk":"11870709466","pt":1723548662676,"mc":[{"id":"1.231705583","rc":[{"batb":[[0,2.32,29.35],[1,1.74,1],[2,1.25,100]],"ltp":2.28,"tv":0.79,"id":655}]}]}
{"op":"mcm","clk":"11870709557","pt":1723548665295,"mc":[{"id":"1.231705583","rc":[{"batb":[[0,2.34,10],[1,2.32,29.35],[2,1.74,1]],"ltp":2.28,"tv":0.79,"id":655}]}]}
{"op":"mcm","clk":"11870709663","pt":1723548668691,"mc":[{"id":"1.231705583","rc":[{"batb":[[0,2.32,29.35],[1,1.74,1],[2,1.25,100]],"ltp":2.28,"tv":0.79,"id":655}]}]}
{"op":"mcm","clk":"11870709903","pt":1723548673877,"mc":[{"id":"1.231705583","rc":[{"batb":[[0,2.34,10],[1,2.32,29.35],[2,1.74,1]],"ltp":2.28,"tv":0.79,"id":655}]}]}
{"op":"mcm","clk":"11870710056","pt":1723548677517,"mc":[{"id":"1.231705583","rc":[{"batb":[[0,2.32,29.35],[1,1.74,1],[2,1.25,100]],"ltp":2.28,"tv":0.79,"id":655}]}]}
{"op":"mcm","clk":"11870710239","pt":1723548682915,"mc":[{"id":"1.231705583","rc":[{"batb":[[0,2.34,10],[1,2.32,29.35],[2,1.74,1]],"ltp":2.28,"tv":0.79,"id":655}]}]}
{"op":"mcm","clk":"11870710352","pt":1723548686405,"mc":[{"id":"1.231705583","rc":[{"batb":[[0,2.32,29.35],[1,1.74,1],[2,1.25,100]],"ltp":2.28,"tv":0.79,"id":655}]}]}
{"op":"mcm","clk":"11870710522","pt":1723548689912,"mc":[{"id":"1.231705583","rc":[{"batb":[[0,2.34,10],[1,2.32,29.35],[2,1.74,1]],"ltp":2.28,"tv":0.79,"id":655}]}]}
{"op":"mcm","clk":"11870710671","pt":1723548693812,"mc":[{"id":"1.231705583","rc":[{"batb":[[0,2.32,29.35],[1,1.74,1],[2,1.25,100]],"ltp":2.28,"tv":0.79,"id":655}]}]}
{"op":"mcm","clk":"11870710967","pt":1723548702305,"mc":[{"id":"1.231705583","rc":[{"batb":[[0,2.34,10],[1,2.32,29.35],[2,1.74,1]],"ltp":2.28,"tv":0.79,"id":655}]}]}
{"op":"mcm","clk":"11870711110","pt":1723548705942,"mc":[{"id":"1.231705583","rc":[{"batb":[[0,2.32,29.35],[1,1.74,1],[2,1.25,100]],"ltp":2.28,"tv":0.79,"id":655}]}]}
{"op":"mcm","clk":"11870711663","pt":1723548722144,"mc":[{"id":"1.231705583","rc":[{"batb":[[0,2.34,10],[1,2.32,29.35],[2,1.74,1]],"ltp":2.28,"tv":0.79,"id":655}]}]}
{"op":"mcm","clk":"11870711807","pt":1723548725636,"mc":[{"id":"1.231705583","rc":[{"batb":[[0,2.32,29.35],[1,1.74,1],[2,1.25,100]],"ltp":2.28,"tv":0.79,"id":655}]}]}
{"op":"mcm","clk":"11870711898","pt":1723548728560,"mc":[{"id":"1.231705583","rc":[{"batb":[[0,2.34,10],[1,2.32,29.35],[2,1.74,1]],"ltp":2.28,"tv":0.79,"id":655}]}]}
{"op":"mcm","clk":"11870712001","pt":1723548732154,"mc":[{"id":"1.231705583","rc":[{"batb":[[0,2.32,29.35],[1,1.74,1],[2,1.25,100]],"ltp":2.28,"tv":0.79,"id":655}]}]}
{"op":"mcm","clk":"11870712277","pt":1723548740670,"mc":[{"id":"1.231705583","rc":[{"batb":[[0,2.34,10],[1,2.32,29.35],[2,1.74,1]],"ltp":2.28,"tv":0.79,"id":655}]}]}
{"op":"mcm","clk":"11870712363","pt":1723548744157,"mc":[{"id":"1.231705583","rc":[{"batb":[[0,2.32,29.35],[1,1.74,1],[2,1.25,100]],"ltp":2.28,"tv":0.79,"id":655}]}]}
{"op":"mcm","clk":"11870712426","pt":1723548746273,"mc":[{"id":"1.231705583","rc":[{"batb":[[0,2.34,10],[1,2.32,29.35],[2,1.74,1]],"ltp":2.28,"tv":0.79,"id":655}]}]}
{"op":"mcm","clk":"11870712544","pt":1723548749760,"mc":[{"id":"1.231705583","rc":[{"batb":[[0,2.32,29.35],[1,1.74,1],[2,1.25,100]],"ltp":2.28,"tv":0.79,"id":655}]}]}
{"op":"mcm","clk":"11870712692","pt":1723548754708,"mc":[{"id":"1.231705583","rc":[{"batb":[[0,2.34,10],[1,2.32,29.35],[2,1.74,1]],"ltp":2.28,"tv":0.79,"id":655}]}]}
{"op":"mcm","clk":"11870712846","pt":1723548758107,"mc":[{"id":"1.231705583","rc":[{"batb":[[0,2.32,29.35],[1,1.74,1],[2,1.25,100]],"ltp":2.28,"tv":0.79,"id":655}]}]}
{"op":"mcm","clk":"11870713028","pt":1723548761717,"mc":[{"id":"1.231705583","rc":[{"batb":[[0,2.34,10],[1,2.32,29.35],[2,1.74,1]],"ltp":2.28,"tv":0.79,"id":655}]}]}
{"op":"mcm","clk":"11870713177","pt":1723548765096,"mc":[{"id":"1.231705583","rc":[{"batb":[[0,2.32,29.35],[1,1.74,1],[2,1.25,100]],"ltp":2.28,"tv":0.79,"id":655}]}]}
{"op":"mcm","clk":"11870713297","pt":1723548768493,"mc":[{"id":"1.231705583","rc":[{"batb":[[0,2.34,10],[1,2.32,29.35],[2,1.74,1]],"ltp":2.28,"tv":0.79,"id":655}]}]}
{"op":"mcm","clk":"11870713484","pt":1723548771894,"mc":[{"id":"1.231705583","rc":[{"batb":[[0,2.32,29.35],[1,1.74,1],[2,1.25,100]],"ltp":2.28,"tv":0.79,"id":655}]}]}
{"op":"mcm","clk":"11870713796","pt":1723548778501,"mc":[{"id":"1.231705583","rc":[{"batb":[[0,2.34,10],[1,2.32,29.35],[2,1.74,1]],"ltp":2.28,"tv":0.79,"id":655}]}]}
{"op":"mcm","clk":"11870713928","pt":1723548781700,"mc":[{"id":"1.231705583","rc":[{"batb":[[0,2.32,29.35],[1,1.74,1],[2,1.25,100]],"ltp":2.28,"tv":0.79,"id":655}]}]}
{"op":"mcm","clk":"11870714502","pt":1723548794343,"mc":[{"id":"1.231705583","rc":[{"batb":[[0,2.34,10],[1,2.32,29.35],[2,1.74,1]],"ltp":2.28,"tv":0.79,"id":655}]}]}
{"op":"mcm","clk":"11870714625","pt":1723548797740,"mc":[{"id":"1.231705583","rc":[{"batb":[[0,2.32,29.35],[1,1.74,1],[2,1.25,100]],"ltp":2.28,"tv":0.79,"id":655}]}]}
{"op":"mcm","clk":"11870714756","pt":1723548801142,"mc":[{"id":"1.231705583","rc":[{"batb":[[0,2.34,10],[1,2.32,29.35],[2,1.74,1]],"ltp":2.28,"tv":0.79,"id":655}]}]}
{"op":"mcm","clk":"11870714939","pt":1723548804540,"mc":[{"id":"1.231705583","rc":[{"batb":[[0,2.32,29.35],[1,1.74,1],[2,1.25,100]],"ltp":2.28,"tv":0.79,"id":655}]}]}
{"op":"mcm","clk":"11870715029","pt":1723548807062,"mc":[{"id":"1.231705583","rc":[{"batb":[[0,2.34,10],[1,2.32,29.35],[2,1.74,1]],"ltp":2.28,"tv":0.79,"id":655}]}]}
{"op":"mcm","clk":"11870715175","pt":1723548810664,"mc":[{"id":"1.231705583","rc":[{"batb":[[0,2.32,29.35],[1,1.74,1],[2,1.25,100]],"ltp":2.28,"tv":0.79,"id":655}]}]}
{"op":"mcm","clk":"11870715370","pt":1723548814644,"mc":[{"id":"1.231705583","rc":[{"batb":[[0,2.34,10],[1,2.32,29.35],[2,1.74,1]],"ltp":2.28,"tv":0.79,"id":655}]}]}
{"op":"mcm","clk":"11870715516","pt":1723548818063,"mc":[{"id":"1.231705583","rc":[{"batb":[[0,2.32,29.35],[1,1.74,1],[2,1.25,100]],"ltp":2.28,"tv":0.79,"id":655}]}]}
{"op":"mcm","clk":"11870715829","pt":1723548824398,"mc":[{"id":"1.231705583","rc":[{"batb":[[0,2.34,10],[1,2.32,29.35],[2,1.74,1]],"ltp":2.28,"tv":0.79,"id":655}]}]}
{"op":"mcm","clk":"11870716003","pt":1723548827860,"mc":[{"id":"1.231705583","rc":[{"batb":[[0,2.32,29.35],[1,1.74,1],[2,1.25,100]],"ltp":2.28,"tv":0.79,"id":655}]}]}
{"op":"mcm","clk":"11870716235","pt":1723548832777,"mc":[{"id":"1.231705583","rc":[{"batb":[[0,2.34,10],[1,2.32,29.35],[2,1.74,1]],"ltp":2.28,"tv":0.79,"id":655}]}]}
{"op":"mcm","clk":"11870716365","pt":1723548836484,"mc":[{"id":"1.231705583","rc":[{"batb":[[0,2.32,29.35],[1,1.74,1],[2,1.25,100]],"ltp":2.28,"tv":0.79,"id":655}]}]}
{"op":"mcm","clk":"11870716485","pt":1723548839799,"mc":[{"id":"1.231705583","rc":[{"batb":[[0,2.34,10],[1,2.32,29.35],[2,1.74,1]],"ltp":2.28,"tv":0.79,"id":655}]}]}
{"op":"mcm","clk":"11870716679","pt":1723548843273,"mc":[{"id":"1.231705583","rc":[{"batb":[[0,2.32,29.35],[1,1.74,1],[2,1.25,100]],"ltp":2.28,"tv":0.79,"id":655}]}]}
{"op":"mcm","clk":"11870716837","pt":1723548847188,"mc":[{"id":"1.231705583","rc":[{"batb":[[0,2.34,10],[1,2.32,29.35],[2,1.74,1]],"ltp":2.28,"tv":0.79,"id":655}]}]}
{"op":"mcm","clk":"11870716961","pt":1723548850680,"mc":[{"id":"1.231705583","rc":[{"batb":[[0,2.32,29.35],[1,1.74,1],[2,1.25,100]],"ltp":2.28,"tv":0.79,"id":655}]}]}
{"op":"mcm","clk":"11870717096","pt":1723548854298,"mc":[{"id":"1.231705583","rc":[{"batb":[[0,2.34,10],[1,2.32,29.35],[2,1.74,1]],"ltp":2.28,"tv":0.79,"id":655}]}]}
{"op":"mcm","clk":"11870717261","pt":1723548857895,"mc":[{"id":"1.231705583","rc":[{"batb":[[0,2.32,29.35],[1,1.74,1],[2,1.25,100]],"ltp":2.28,"tv":0.79,"id":655}]}]}
{"op":"mcm","clk":"11870717414","pt":1723548861034,"mc":[{"id":"1.231705583","rc":[{"batb":[[0,2.34,10],[1,2.32,29.35],[2,1.74,1]],"ltp":2.28,"tv":0.79,"id":655}]}]}
{"op":"mcm","clk":"11870717536","pt":1723548864528,"mc":[{"id":"1.231705583","rc":[{"batb":[[0,2.32,29.35],[1,1.74,1],[2,1.25,100]],"ltp":2.28,"tv":0.79,"id":655}]}]}
{"op":"mcm","clk":"11870717656","pt":1723548867811,"mc":[{"id":"1.231705583","rc":[{"batb":[[0,2.34,10],[1,2.32,29.35],[2,1.74,1]],"ltp":2.28,"tv":0.79,"id":655}]}]}
{"op":"mcm","clk":"11870717786","pt":1723548871420,"mc":[{"id":"1.231705583","rc":[{"batb":[[0,2.32,29.35],[1,1.74,1],[2,1.25,100]],"ltp":2.28,"tv":0.79,"id":655}]}]}
{"op":"mcm","clk":"11870717941","pt":1723548875126,"mc":[{"id":"1.231705583","rc":[{"batb":[[0,2.34,10],[1,2.32,29.35],[2,1.74,1]],"ltp":2.28,"tv":0.79,"id":655}]}]}
{"op":"mcm","clk":"11870718117","pt":1723548878525,"mc":[{"id":"1.231705583","rc":[{"batb":[[0,2.32,29.35],[1,1.74,1],[2,1.25,100]],"ltp":2.28,"tv":0.79,"id":655}]}]}
{"op":"mcm","clk":"11870718231","pt":1723548880947,"mc":[{"id":"1.231705583","rc":[{"batb":[[0,2.34,10],[1,2.32,29.35],[2,1.74,1]],"ltp":2.28,"tv":0.79,"id":655}]}]}
{"op":"mcm","clk":"11870718399","pt":1723548884558,"mc":[{"id":"1.231705583","rc":[{"batb":[[0,2.32,29.35],[1,1.74,1],[2,1.25,100]],"ltp":2.28,"tv":0.79,"id":655}]}]}
{"op":"mcm","clk":"11870718510","pt":1723548886928,"mc":[{"id":"1.231705583","rc":[{"batb":[[0,2.34,10],[1,2.32,29.35],[2,1.74,1]],"ltp":2.28,"tv":0.79,"id":655}]}]}
{"op":"mcm","clk":"11870718680","pt":1723548890232,"mc":[{"id":"1.231705583","rc":[{"batb":[[0,2.32,29.35],[1,1.74,1],[2,1.25,100]],"ltp":2.28,"tv":0.79,"id":655}]}]}
{"op":"mcm","clk":"11870718966","pt":1723548896370,"mc":[{"id":"1.231705583","rc":[{"batb":[[0,2.34,10],[1,2.32,29.35],[2,1.74,1]],"ltp":2.28,"tv":0.79,"id":655}]}]}
{"op":"mcm","clk":"11870719137","pt":1723548899940,"mc":[{"id":"1.231705583","rc":[{"batb":[[0,2.32,29.35],[1,1.74,1],[2,1.25,100]],"ltp":2.28,"tv":0.79,"id":655}]}]}
{"op":"mcm","clk":"11870719289","pt":1723548902781,"mc":[{"id":"1.231705583","rc":[{"batb":[[0,2.34,10],[1,2.32,29.35],[2,1.74,1]],"ltp":2.28,"tv":0.79,"id":655}]}]}
{"op":"mcm","clk":"11870719437","pt":1723548906349,"mc":[{"id":"1.231705583","rc":[{"batb":[[0,2.32,29.35],[1,1.74,1],[2,1.25,100]],"ltp":2.28,"tv":0.79,"id":655}]}]}
{"op":"mcm","clk":"11870719618","pt":1723548911258,"mc":[{"id":"1.231705583","rc":[{"batb":[[0,2.34,10],[1,2.32,29.35],[2,1.74,1]],"ltp":2.28,"tv":0.79,"id":655}]}]}
{"op":"mcm","clk":"11870719796","pt":1723548914679,"mc":[{"id":"1.231705583","rc":[{"batb":[[0,2.32,29.35],[1,1.74,1],[2,1.25,100]],"ltp":2.28,"tv":0.79,"id":655}]}]}
{"op":"mcm","clk":"11870719951","pt":1723548917670,"mc":[{"id":"1.231705583","rc":[{"batb":[[0,2.34,10],[1,2.32,29.35],[2,1.74,1]],"ltp":2.28,"tv":0.79,"id":655}]}]}
{"op":"mcm","clk":"11870720081","pt":1723548921071,"mc":[{"id":"1.231705583","rc":[{"batb":[[0,2.32,29.35],[1,1.74,1],[2,1.25,100]],"ltp":2.28,"tv":0.79,"id":655}]}]}
{"op":"mcm","clk":"11870720280","pt":1723548925382,"mc":[{"id":"1.231705583","rc":[{"batb":[[0,2.34,10],[1,2.32,29.35],[2,1.74,1]],"ltp":2.28,"tv":0.79,"id":655}]}]}
{"op":"mcm","clk":"11870720415","pt":1723548928786,"mc":[{"id":"1.231705583","rc":[{"batb":[[0,2.32,29.35],[1,1.74,1],[2,1.25,100]],"ltp":2.28,"tv":0.79,"id":655}]}]}
{"op":"mcm","clk":"11870720680","pt":1723548934879,"mc":[{"id":"1.231705583","rc":[{"batb":[[0,2.34,10],[1,2.32,29.35],[2,1.74,1]],"ltp":2.28,"tv":0.79,"id":655}]}]}
{"op":"mcm","clk":"11870720804","pt":1723548938491,"mc":[{"id":"1.231705583","rc":[{"batb":[[0,2.32,29.35],[1,1.74,1],[2,1.25,100]],"ltp":2.28,"tv":0.79,"id":655}]}]}
{"op":"mcm","clk":"11870720905","pt":1723548941522,"mc":[{"id":"1.231705583","rc":[{"batb":[[0,2.34,10],[1,2.32,29.35],[2,1.74,1]],"ltp":2.28,"tv":0.79,"id":655}]}]}
{"op":"mcm","clk":"11870721066","pt":1723548945488,"mc":[{"id":"1.231705583","rc":[{"batb":[[0,2.32,29.35],[1,1.74,1],[2,1.25,100]],"ltp":2.28,"tv":0.79,"id":655}]}]}
{"op":"mcm","clk":"11870721149","pt":1723548948620,"mc":[{"id":"1.231705583","rc":[{"batb":[[0,2.34,10],[1,2.32,29.35],[2,1.74,1]],"ltp":2.28,"tv":0.79,"id":655}]}]}
{"op":"mcm","clk":"11870721270","pt":1723548952108,"mc":[{"id":"1.231705583","rc":[{"batb":[[0,2.32,29.35],[1,1.74,1],[2,1.25,100]],"ltp":2.28,"tv":0.79,"id":655}]}]}
{"op":"mcm","clk":"11870721362","pt":1723548955293,"mc":[{"id":"1.231705583","rc":[{"batb":[[0,2.34,10],[1,2.32,29.35],[2,1.74,1]],"ltp":2.28,"tv":0.79,"id":655}]}]}
{"op":"mcm","clk":"11870721484","pt":1723548958933,"mc":[{"id":"1.231705583","rc":[{"batb":[[0,2.32,29.35],[1,1.74,1],[2,1.25,100]],"ltp":2.28,"tv":0.79,"id":655}]}]}
{"op":"mcm","clk":"11870721711","pt":1723548961703,"mc":[{"id":"1.231705583","rc":[{"batb":[[0,2.34,10],[1,2.32,29.35],[2,1.74,1]],"ltp":2.28,"tv":0.79,"id":655}]}]}
{"op":"mcm","clk":"11870721855","pt":1723548965305,"mc":[{"id":"1.231705583","rc":[{"batb":[[0,2.32,29.35],[1,1.74,1],[2,1.25,100]],"ltp":2.28,"tv":0.79,"id":655}]}]}
{"op":"mcm","clk":"11870721955","pt":1723548967724,"mc":[{"id":"1.231705583","rc":[{"batb":[[0,2.34,10],[1,2.32,29.35],[2,1.74,1]],"ltp":2.28,"tv":0.79,"id":655}]}]}
{"op":"mcm","clk":"11870722091","pt":1723548971336,"mc":[{"id":"1.231705583","rc":[{"batb":[[0,2.32,29.35],[1,1.74,1],[2,1.25,100]],"ltp":2.28,"tv":0.79,"id":655}]}]}
{"op":"mcm","clk":"11870722167","pt":1723548974429,"mc":[{"id":"1.231705583","rc":[{"batb":[[0,2.34,10],[1,2.32,29.35],[2,1.74,1]],"ltp":2.28,"tv":0.79,"id":655}]}]}
{"op":"mcm","clk":"11870722263","pt":1723548977830,"mc":[{"id":"1.231705583","rc":[{"batb":[[0,2.32,29.35],[1,1.74,1],[2,1.25,100]],"ltp":2.28,"tv":0.79,"id":655}]}]}
{"op":"mcm","clk":"11870722328","pt":1723548980035,"mc":[{"id":"1.231705583","rc":[{"batb":[[0,2.34,10],[1,2.32,29.35],[2,1.74,1]],"ltp":2.28,"tv":0.79,"id":655}]}]}
{"op":"mcm","clk":"11870722407","pt":1723548983431,"mc":[{"id":"1.231705583","rc":[{"batb":[[0,2.32,29.35],[1,1.74,1],[2,1.25,100]],"ltp":2.28,"tv":0.79,"id":655}]}]}
{"op":"mcm","clk":"11870722590","pt":1723548987535,"mc":[{"id":"1.231705583","rc":[{"batb":[[0,2.34,10],[1,2.32,29.35],[2,1.74,1]],"ltp":2.28,"tv":0.79,"id":655}]}]}
{"op":"mcm","clk":"11870722690","pt":1723548990979,"mc":[{"id":"1.231705583","rc":[{"batb":[[0,2.32,29.35],[1,1.74,1],[2,1.25,100]],"ltp":2.28,"tv":0.79,"id":655}]}]}
{"op":"mcm","clk":"11870722786","pt":1723548993973,"mc":[{"id":"1.231705583","rc":[{"batb":[[0,2.34,10],[1,2.32,29.35],[2,1.74,1]],"ltp":2.28,"tv":0.79,"id":655}]}]}
{"op":"mcm","clk":"11870722916","pt":1723548997275,"mc":[{"id":"1.231705583","rc":[{"batb":[[0,2.32,29.35],[1,1.74,1],[2,1.25,100]],"ltp":2.28,"tv":0.79,"id":655}]}]}
{"op":"mcm","clk":"11870723005","pt":1723548999956,"mc":[{"id":"1.231705583","rc":[{"batb":[[0,2.34,10],[1,2.32,29.35],[2,1.74,1]],"ltp":2.28,"tv":0.79,"id":655}]}]}
{"op":"mcm","clk":"11870723139","pt":1723549003770,"mc":[{"id":"1.231705583","rc":[{"batb":[[0,2.32,29.35],[1,1.74,1],[2,1.25,100]],"ltp":2.28,"tv":0.79,"id":655}]}]}
{"op":"mcm","clk":"11870723237","pt":1723549006766,"mc":[{"id":"1.231705583","rc":[{"batb":[[0,2.34,10],[1,2.32,29.35],[2,1.74,1]],"ltp":2.28,"tv":0.79,"id":655}]}]}
{"op":"mcm","clk":"11870723347","pt":1723549010298,"mc":[{"id":"1.231705583","rc":[{"batb":[[0,2.32,29.35],[1,1.74,1],[2,1.25,100]],"ltp":2.28,"tv":0.79,"id":655}]}]}
{"op":"mcm","clk":"11870723418","pt":1723549012712,"mc":[{"id":"1.231705583","rc":[{"batb":[[0,2.34,10],[1,2.32,29.35],[2,1.74,1]],"ltp":2.28,"tv":0.79,"id":655}]}]}
{"op":"mcm","clk":"11870723542","pt":1723549016011,"mc":[{"id":"1.231705583","rc":[{"batb":[[0,2.32,29.35],[1,1.74,1],[2,1.25,100]],"ltp":2.28,"tv":0.79,"id":655}]}]}
{"op":"mcm","clk":"11870723663","pt":1723549020183,"mc":[{"id":"1.231705583","rc":[{"batb":[[0,2.34,10],[1,2.32,29.35],[2,1.74,1]],"ltp":2.28,"tv":0.79,"id":655}]}]}
{"op":"mcm","clk":"11870723752","pt":1723549023499,"mc":[{"id":"1.231705583","rc":[{"batb":[[0,2.32,29.35],[1,1.74,1],[2,1.25,100]],"ltp":2.28,"tv":0.79,"id":655}]}]}
{"op":"mcm","clk":"11870723841","pt":1723549026114,"mc":[{"id":"1.231705583","rc":[{"batb":[[0,2.34,10],[1,2.32,29.35],[2,1.74,1]],"ltp":2.28,"tv":0.79,"id":655}]}]}
{"op":"mcm","clk":"11870723961","pt":1723549029522,"mc":[{"id":"1.231705583","rc":[{"batb":[[0,2.32,29.35],[1,1.74,1],[2,1.25,100]],"ltp":2.28,"tv":0.79,"id":655}]}]}
{"op":"mcm","clk":"11870724050","pt":1723549032100,"mc":[{"id":"1.231705583","rc":[{"batb":[[0,2.34,10],[1,2.32,29.35],[2,1.74,1]],"ltp":2.28,"tv":0.79,"id":655}]}]}
{"op":"mcm","clk":"11870724174","pt":1723549035300,"mc":[{"id":"1.231705583","rc":[{"batb":[[0,2.32,29.35],[1,1.74,1],[2,1.25,100]],"ltp":2.28,"tv":0.79,"id":655}]}]}
{"op":"mcm","clk":"11870724258","pt":1723549038429,"mc":[{"id":"1.231705583","rc":[{"batb":[[0,2.34,10],[1,2.32,29.35],[2,1.74,1]],"ltp":2.28,"tv":0.79,"id":655}]}]}
{"op":"mcm","clk":"11870724356","pt":1723549041714,"mc":[{"id":"1.231705583","rc":[{"batb":[[0,2.32,29.35],[1,1.74,1],[2,1.25,100]],"ltp":2.28,"tv":0.79,"id":655}]}]}
{"op":"mcm","clk":"11870724467","pt":1723549044920,"mc":[{"id":"1.231705583","rc":[{"batb":[[0,2.34,10],[1,2.32,29.35],[2,1.74,1]],"ltp":2.28,"tv":0.79,"id":655}]}]}
{"op":"mcm","clk":"11870724581","pt":1723549048512,"mc":[{"id":"1.231705583","rc":[{"batb":[[0,2.32,29.35],[1,1.74,1],[2,1.25,100]],"ltp":2.28,"tv":0.79,"id":655}]}]}
{"op":"mcm","clk":"11870724700","pt":1723549052029,"mc":[{"id":"1.231705583","rc":[{"batb":[[0,2.34,10],[1,2.32,29.35],[2,1.74,1]],"ltp":2.28,"tv":0.79,"id":655}]}]}
{"op":"mcm","clk":"11870724852","pt":1723549055529,"mc":[{"id":"1.231705583","rc":[{"batb":[[0,2.32,29.35],[1,1.74,1],[2,1.25,100]],"ltp":2.28,"tv":0.79,"id":655}]}]}
{"op":"mcm","clk":"11870725001","pt":1723549058936,"mc":[{"id":"1.231705583","rc":[{"batb":[[0,2.34,10],[1,2.32,29.35],[2,1.74,1]],"ltp":2.28,"tv":0.79,"id":655}]}]}
{"op":"mcm","clk":"11870725161","pt":1723549062247,"mc":[{"id":"1.231705583","rc":[{"batb":[[0,2.32,29.35],[1,1.74,1],[2,1.25,100]],"ltp":2.28,"tv":0.79,"id":655}]}]}
{"op":"mcm","clk":"11870725271","pt":1723549064823,"mc":[{"id":"1.231705583","rc":[{"batb":[[0,2.34,10],[1,2.32,29.35],[2,1.74,1]],"ltp":2.28,"tv":0.79,"id":655}]}]}
{"op":"mcm","clk":"11870725365","pt":1723549068229,"mc":[{"id":"1.231705583","rc":[{"batb":[[0,2.32,29.35],[1,1.74,1],[2,1.25,100]],"ltp":2.28,"tv":0.79,"id":655}]}]}
{"op":"mcm","clk":"11870725525","pt":1723549071950,"mc":[{"id":"1.231705583","rc":[{"batb":[[0,2.34,10],[1,2.32,29.35],[2,1.74,1]],"ltp":2.28,"tv":0.79,"id":655}]}]}
{"op":"mcm","clk":"11870725664","pt":1723549075153,"mc":[{"id":"1.231705583","rc":[{"batb":[[0,2.32,29.35],[1,1.74,1],[2,1.25,100]],"ltp":2.28,"tv":0.79,"id":655}]}]}
{"op":"mcm","clk":"11870725830","pt":1723549078885,"mc":[{"id":"1.231705583","rc":[{"batb":[[0,2.34,10],[1,2.32,29.35],[2,1.74,1]],"ltp":2.28,"tv":0.79,"id":655}]}]}
{"op":"mcm","clk":"11870725951","pt":1723549082294,"mc":[{"id":"1.231705583","rc":[{"batb":[[0,2.32,29.35],[1,1.74,1],[2,1.25,100]],"ltp":2.28,"tv":0.79,"id":655}]}]}
{"op":"mcm","clk":"11870726195","pt":1723549087680,"mc":[{"id":"1.231705583","rc":[{"batb":[[0,2.34,10],[1,2.32,29.35],[2,1.74,1]],"ltp":2.28,"tv":0.79,"id":655}]}]}
{"op":"mcm","clk":"11870726346","pt":1723549091395,"mc":[{"id":"1.231705583","rc":[{"batb":[[0,2.32,29.35],[1,1.74,1],[2,1.25,100]],"ltp":2.28,"tv":0.79,"id":655}]}]}
{"op":"mcm","clk":"11870726452","pt":1723549094082,"mc":[{"id":"1.231705583","rc":[{"batb":[[0,2.34,10],[1,2.32,29.35],[2,1.74,1]],"ltp":2.28,"tv":0.79,"id":655}]}]}
{"op":"mcm","clk":"11870726571","pt":1723549097690,"mc":[{"id":"1.231705583","rc":[{"batb":[[0,2.32,29.35],[1,1.74,1],[2,1.25,100]],"ltp":2.28,"tv":0.79,"id":655}]}]}
{"op":"mcm","clk":"11870726687","pt":1723549100786,"mc":[{"id":"1.231705583","rc":[{"batb":[[0,2.34,10],[1,2.32,29.35],[2,1.74,1]],"ltp":2.28,"tv":0.79,"id":655}]}]}
{"op":"mcm","clk":"11870726824","pt":1723549104192,"mc":[{"id":"1.231705583","rc":[{"batb":[[0,2.32,29.35],[1,1.74,1],[2,1.25,100]],"ltp":2.28,"tv":0.79,"id":655}]}]}
{"op":"mcm","clk":"11870726975","pt":1723549107591,"mc":[{"id":"1.231705583","rc":[{"batb":[[0,2.34,10],[1,2.32,29.35],[2,1.74,1]],"ltp":2.28,"tv":0.79,"id":655}]}]}
{"op":"mcm","clk":"11870727106","pt":1723549110981,"mc":[{"id":"1.231705583","rc":[{"batb":[[0,2.32,29.35],[1,1.74,1],[2,1.25,100]],"ltp":2.28,"tv":0.79,"id":655}]}]}
{"op":"mcm","clk":"11870727225","pt":1723549114375,"mc":[{"id":"1.231705583","rc":[{"batb":[[0,2.34,10],[1,2.32,29.35],[2,1.74,1]],"ltp":2.28,"tv":0.79,"id":655}]}]}
{"op":"mcm","clk":"11870727377","pt":1723549118619,"mc":[{"id":"1.231705583","rc":[{"batb":[[0,2.32,29.35],[1,1.74,1],[2,1.25,100]],"ltp":2.28,"tv":0.79,"id":655}]}]}
{"op":"mcm","clk":"11870727501","pt":1723549121001,"mc":[{"id":"1.231705583","rc":[{"batb":[[0,2.34,10],[1,2.32,29.35],[2,1.74,1]],"ltp":2.28,"tv":0.79,"id":655}]}]}
{"op":"mcm","clk":"11870727670","pt":1723549124312,"mc":[{"id":"1.231705583","rc":[{"batb":[[0,2.32,29.35],[1,1.74,1],[2,1.25,100]],"ltp":2.28,"tv":0.79,"id":655}]}]}
{"op":"mcm","clk":"11870727941","pt":1723549130891,"mc":[{"id":"1.231705583","rc":[{"batb":[[0,2.34,10],[1,2.32,29.35],[2,1.74,1]],"ltp":2.28,"tv":0.79,"id":655}]}]}
{"op":"mcm","clk":"11870728061","pt":1723549134390,"mc":[{"id":"1.231705583","rc":[{"batb":[[0,2.32,29.35],[1,1.74,1],[2,1.25,100]],"ltp":2.28,"tv":0.79,"id":655}]}]}
{"op":"mcm","clk":"11870728254","pt":1723549139217,"mc":[{"id":"1.231705583","rc":[{"batb":[[0,2.34,10],[1,2.32,29.35],[2,1.74,1]],"ltp":2.28,"tv":0.79,"id":655}]}]}
{"op":"mcm","clk":"11870728416","pt":1723549142718,"mc":[{"id":"1.231705583","rc":[{"batb":[[0,2.32,29.35],[1,1.74,1],[2,1.25,100]],"ltp":2.28,"tv":0.79,"id":655}]}]}
{"op":"mcm","clk":"11870728597","pt":1723549147238,"mc":[{"id":"1.231705583","rc":[{"batb":[[0,2.34,10],[1,2.32,29.35],[2,1.74,1]],"ltp":2.28,"tv":0.79,"id":655}]}]}
{"op":"mcm","clk":"11870728709","pt":1723549150830,"mc":[{"id":"1.231705583","rc":[{"batb":[[0,2.32,29.35],[1,1.74,1],[2,1.25,100]],"ltp":2.28,"tv":0.79,"id":655}]}]}
{"op":"mcm","clk":"11870751984","pt":1723549781852,"mc":[{"id":"1.231705583","rc":[{"batb":[[0,2.42,27.28]],"ltp":2.28,"tv":0.79,"id":655},{"batb":[[0,1.65,59.6]],"ltp":1.73,"tv":112.64,"id":169}]}]}
{"op":"mcm","clk":"11870899661","pt":1723552974986,"mc":[{"id":"1.231705583","rc":[{"batb":[[2,1.08,7.82]],"ltp":1.73,"tv":112.64,"id":169}]}]}
{"op":"mcm","clk":"11871031669","pt":1723556116071,"mc":[{"id":"1.231705583","rc":[{"batb":[[0,2.42,26.71]],"ltp":2.28,"tv":0.79,"id":655},{"batb":[[0,1.65,58.37],[2,1.08,7.81]],"ltp":1.73,"tv":112.64,"id":169}],"tv":113.43}]}
{"op":"mcm","clk":"11871155320","pt":1723558375000,"mc":[{"id":"1.231705583","rc":[{"batb":[[2,1.08,7.8]],"ltp":1.73,"tv":112.64,"id":169}]}]}
{"op":"mcm","clk":"11871405559","pt":1723562721126,"mc":[{"id":"1.231705583","rc":[{"trd":[[2.42,10]],"batb":[[0,2.42,21.71]],"ltp":2.42,"tv":10.79,"id":655},{"batb":[[2,1.08,7.8]],"ltp":1.73,"tv":112.64,"id":169}],"tv":123.43}]}
{"op":"mcm","clk":"11871405712","pt":1723562723442,"mc":[{"id":"1.231705583","rc":[{"batb":[[0,2.42,26.71]],"ltp":2.42,"tv":10.79,"id":655}]}]}
{"op":"mcm","clk":"11871444976","pt":1723563282363,"mc":[{"id":"1.231705583","rc":[{"batl":[[1,2.8,5]],"ltp":2.42,"tv":10.79,"id":655}]}]}
{"op":"mcm","clk":"11871833301","pt":1723568086051,"mc":[{"id":"1.231705583","rc":[{"trd":[[2.5,0.66]],"batl":[[0,2.8,5.34],[1,2.8,0]],"ltp":2.5,"tv":11.45,"id":655},{"trd":[[1.66,1]],"batb":[[2,1.08,7.8]],"ltp":1.66,"tv":113.64,"id":169}],"tv":125.09}]}
{"op":"mcm","clk":"11871842711","pt":1723568211108,"mc":[{"id":"1.231705583","rc":[{"batb":[[2,1.08,7.8]],"ltp":2.5,"tv":11.45,"id":655},{"batb":[[1,1.08,7.8],[2,1.07,7.8]],"ltp":1.66,"tv":113.64,"id":169}]}]}
{"op":"mcm","clk":"11871847764","pt":1723568284272,"mc":[{"id":"1.231705583","rc":[{"batb":[[2,1.38,131.58]],"ltp":2.5,"tv":11.45,"id":655},{"batb":[[1,1.38,131.58],[2,1.33,151.52]],"ltp":1.66,"tv":113.64,"id":169}]}]}
{"op":"mcm","clk":"11871938064","pt":1723569175006,"mc":[{"id":"1.231705583","tv":125.08}]}
{"op":"mcm","clk":"11871961065","pt":1723569379631,"mc":[{"id":"1.231705583","rc":[{"batb":[[0,2.44,14],[1,2.42,26.71],[2,1.74,1]],"ltp":2.5,"tv":11.45,"id":655}]}]}
{"op":"mcm","clk":"11871961438","pt":1723569382708,"mc":[{"id":"1.231705583","rc":[{"batb":[[0,2.44,10]],"ltp":2.5,"tv":11.45,"id":655}]}]}
{"op":"mcm","clk":"11871961536","pt":1723569383747,"mc":[{"id":"1.231705583","rc":[{"batb":[[0,2.42,26.71],[1,1.74,1],[2,1.38,131.58]],"ltp":2.5,"tv":11.45,"id":655}]}]}
{"op":"mcm","clk":"11871961808","pt":1723569386340,"mc":[{"id":"1.231705583","rc":[{"batb":[[0,2.46,14],[1,2.42,26.71],[2,1.74,1]],"ltp":2.5,"tv":11.45,"id":655}]}]}
{"op":"mcm","clk":"11871962613","pt":1723569394431,"mc":[{"id":"1.231705583","rc":[{"batb":[[0,2.46,10]],"ltp":2.5,"tv":11.45,"id":655}]}]}
{"op":"mcm","clk":"11871962626","pt":1723569394535,"mc":[{"id":"1.231705583","rc":[{"batb":[[0,2.42,26.71],[1,1.74,1],[2,1.38,131.58]],"ltp":2.5,"tv":11.45,"id":655}]}]}
{"op":"mcm","clk":"11871963103","pt":1723569399509,"mc":[{"id":"1.231705583","rc":[{"batb":[[0,2.48,14],[1,2.42,26.71],[2,1.74,1]],"ltp":2.5,"tv":11.45,"id":655}]}]}
{"op":"mcm","clk":"11871963873","pt":1723569407783,"mc":[{"id":"1.231705583","rc":[{"batb":[[0,2.48,10]],"ltp":2.5,"tv":11.45,"id":655}]}]}
{"op":"mcm","clk":"11871963962","pt":1723569408771,"mc":[{"id":"1.231705583","rc":[{"batb":[[0,2.42,26.71],[1,1.74,1],[2,1.38,131.58]],"ltp":2.5,"tv":11.45,"id":655}]}]}
{"op":"mcm","clk":"11871964448","pt":1723569413460,"mc":[{"id":"1.231705583","rc":[{"trd":[[2.5,1.34]],"batb":[[0,2.5,13.66],[1,2.42,26.71],[2,1.74,1]],"batl":[[0,2.8,5]],"ltp":2.5,"tv":12.12,"id":655}],"tv":125.76}]}
{"op":"mcm","clk":"11871965213","pt":1723569420475,"mc":[{"id":"1.231705583","rc":[{"batb":[[0,2.42,26.71],[1,1.74,1],[2,1.38,131.58]],"ltp":2.5,"tv":12.12,"id":655}]}]}
{"op":"mcm","clk":"11871965597","pt":1723569424298,"mc":[{"id":"1.231705583","rc":[{"batb":[[0,2.52,14],[1,2.42,26.71],[2,1.74,1]],"ltp":2.5,"tv":12.12,"id":655}]}]}
{"op":"mcm","clk":"11871966171","pt":1723569430198,"mc":[{"id":"1.231705583","rc":[{"batb":[[0,2.52,10]],"ltp":2.5,"tv":12.12,"id":655}]}]}
{"op":"mcm","clk":"11871966269","pt":1723569431287,"mc":[{"id":"1.231705583","rc":[{"batb":[[0,2.42,26.71],[1,1.74,1],[2,1.38,131.58]],"ltp":2.5,"tv":12.12,"id":655}]}]}
{"op":"mcm","clk":"11871966603","pt":1723569434478,"mc":[{"id":"1.231705583","rc":[{"trd":[[2.54,10]],"ltp":2.54,"tv":22.13,"id":655},{"trd":[[1.65,15.39]],"ltp":1.65,"tv":129.02,"id":169}],"tv":151.15}]}
{"op":"mcm","clk":"11871966652","pt":1723569434895,"mc":[{"id":"1.231705583","rc":[{"batb":[[0,2.44,4],[1,2.42,26.71],[2,1.74,1]],"ltp":2.54,"tv":22.13,"id":655}]}]}
{"op":"mcm","clk":"11871967265","pt":1723569441282,"mc":[{"id":"1.231705583","rc":[{"batb":[[0,2.42,26.71],[1,1.74,1],[2,1.38,131.58]],"ltp":2.54,"tv":22.13,"id":655}]}]}
{"op":"mcm","clk":"11871967573","pt":1723569444512,"mc":[{"id":"1.231705583","rc":[{"batb":[[0,2.44,10],[1,2.42,26.71],[2,1.74,1]],"ltp":2.54,"tv":22.13,"id":655}]}]}
{"op":"mcm","clk":"11871967632","pt":1723569444612,"mc":[{"id":"1.231705583","rc":[{"batb":[[0,2.44,14]],"ltp":2.54,"tv":22.13,"id":655}]}]}
{"op":"mcm","clk":"11871968076","pt":1723569449329,"mc":[{"id":"1.231705583","rc":[{"batb":[[0,2.44,10]],"ltp":2.54,"tv":22.13,"id":655}]}]}
{"op":"mcm","clk":"11871968188","pt":1723569450107,"mc":[{"id":"1.231705583","rc":[{"batb":[[0,2.42,26.71],[1,1.74,1],[2,1.38,131.58]],"ltp":2.54,"tv":22.13,"id":655}]}]}
{"op":"mcm","clk":"11871968482","pt":1723569452617,"mc":[{"id":"1.231705583","rc":[{"batb":[[0,2.46,14],[1,2.42,26.71],[2,1.74,1]],"ltp":2.54,"tv":22.13,"id":655}]}]}
{"op":"mcm","clk":"11871969200","pt":1723569459420,"mc":[{"id":"1.231705583","rc":[{"batb":[[0,2.46,10]],"ltp":2.54,"tv":22.13,"id":655}]}]}
{"op":"mcm","clk":"11871969304","pt":1723569460418,"mc":[{"id":"1.231705583","rc":[{"batb":[[0,2.42,26.71],[1,1.74,1],[2,1.38,131.58]],"ltp":2.54,"tv":22.13,"id":655}]}]}
{"op":"mcm","clk":"11871969540","pt":1723569462533,"mc":[{"id":"1.231705583","rc":[{"batb":[[0,2.48,4],[1,2.42,26.71],[2,1.74,1]],"ltp":2.54,"tv":22.13,"id":655}]}]}
{"op":"mcm","clk":"11871969658","pt":1723569463625,"mc":[{"id":"1.231705583","rc":[{"batb":[[1,2.44,10],[2,2.42,26.71]],"ltp":2.54,"tv":22.13,"id":655}]}]}
{"op":"mcm","clk":"11871970258","pt":1723569469324,"mc":[{"id":"1.231705583","rc":[{"batb":[[0,2.44,10],[1,2.42,26.71],[2,1.74,1]],"ltp":2.54,"tv":22.13,"id":655}]}]}
{"op":"mcm","clk":"11871970448","pt":1723569471238,"mc":[{"id":"1.231705583","rc":[{"batb":[[0,2.42,26.71],[1,1.74,1],[2,1.38,131.58]],"ltp":2.54,"tv":22.13,"id":655}]}]}
{"op":"mcm","clk":"11871970567","pt":1723569472529,"mc":[{"id":"1.231705583","rc":[{"batb":[[0,2.46,4],[1,2.42,26.71],[2,1.74,1]],"ltp":2.54,"tv":22.13,"id":655}]}]}
{"op":"mcm","clk":"11871970746","pt":1723569474508,"mc":[{"id":"1.231705583","rc":[{"batb":[[1,2.44,10],[2,2.42,26.71]],"ltp":2.54,"tv":22.13,"id":655}]}]}
{"op":"mcm","clk":"11871971011","pt":1723569477317,"mc":[{"id":"1.231705583","rc":[{"batb":[[0,2.44,10],[1,2.42,26.71],[2,1.74,1]],"ltp":2.54,"tv":22.13,"id":655}]}]}
{"op":"mcm","clk":"11871971257","pt":1723569479823,"mc":[{"id":"1.231705583","rc":[{"batb":[[0,2.42,26.71],[1,1.74,1],[2,1.38,131.58]],"ltp":2.54,"tv":22.13,"id":655}]}]}
{"op":"mcm","clk":"11871971601","pt":1723569483124,"mc":[{"id":"1.231705583","rc":[{"batb":[[0,2.44,14],[1,2.42,26.71],[2,1.74,1]],"ltp":2.54,"tv":22.13,"id":655}]}]}
{"op":"mcm","clk":"11871972155","pt":1723569487944,"mc":[{"id":"1.231705583","rc":[{"batb":[[0,2.44,10]],"ltp":2.54,"tv":22.13,"id":655}]}]}
{"op":"mcm","clk":"11871972254","pt":1723569488720,"mc":[{"id":"1.231705583","rc":[{"batb":[[0,2.42,26.71],[1,1.74,1],[2,1.38,131.58]],"ltp":2.54,"tv":22.13,"id":655}]}]}
{"op":"mcm","clk":"11871972521","pt":1723569491258,"mc":[{"id":"1.231705583","rc":[{"batb":[[0,2.44,14],[1,2.42,26.71],[2,1.74,1]],"ltp":2.54,"tv":22.13,"id":655}]}]}
{"op":"mcm","clk":"11871972952","pt":1723569495130,"mc":[{"id":"1.231705583","rc":[{"batb":[[0,2.44,10]],"ltp":2.54,"tv":22.13,"id":655}]}]}
{"op":"mcm","clk":"11871973064","pt":1723569496161,"mc":[{"id":"1.231705583","rc":[{"batb":[[0,2.42,26.71],[1,1.74,1],[2,1.38,131.58]],"ltp":2.54,"tv":22.13,"id":655}]}]}
{"op":"mcm","clk":"11871973216","pt":1723569497459,"mc":[{"id":"1.231705583","rc":[{"batb":[[0,2.46,4],[1,2.42,26.71],[2,1.74,1]],"ltp":2.54,"tv":22.13,"id":655}]}]}
{"op":"mcm","clk":"11871973384","pt":1723569499027,"mc":[{"id":"1.231705583","rc":[{"batb":[[0,2.48,10],[1,2.46,4],[2,2.42,26.71]],"ltp":2.54,"tv":22.13,"id":655}]}]}
{"op":"mcm","clk":"11871973625","pt":1723569501264,"mc":[{"id":"1.231705583","rc":[{"batb":[[1,2.42,26.71],[2,1.74,1]],"ltp":2.54,"tv":22.13,"id":655}]}]}
{"op":"mcm","clk":"11871974001","pt":1723569504659,"mc":[{"id":"1.231705583","rc":[{"batb":[[0,2.42,26.71],[1,1.74,1],[2,1.38,131.58]],"ltp":2.54,"tv":22.13,"id":655}]}]}
{"op":"mcm","clk":"11871974238","pt":1723569506646,"mc":[{"id":"1.231705583","rc":[{"batb":[[0,2.44,4],[1,2.42,26.71],[2,1.74,1]],"ltp":2.54,"tv":22.13,"id":655}]}]}
{"op":"mcm","clk":"11871974472","pt":1723569508557,"mc":[{"id":"1.231705583","rc":[{"batb":[[0,2.46,10],[1,2.44,4],[2,2.42,26.71]],"ltp":2.54,"tv":22.13,"id":655}]}]}
{"op":"mcm","clk":"11871974744","pt":1723569510785,"mc":[{"id":"1.231705583","rc":[{"batb":[[1,2.42,26.71],[2,1.74,1]],"ltp":2.54,"tv":22.13,"id":655}]}]}
{"op":"mcm","clk":"11871975021","pt":1723569513442,"mc":[{"id":"1.231705583","rc":[{"batb":[[0,2.42,26.71],[1,1.74,1],[2,1.38,131.58]],"ltp":2.54,"tv":22.13,"id":655}]}]}
{"op":"mcm","clk":"11871975185","pt":1723569514844,"mc":[{"id":"1.231705583","rc":[{"batb":[[0,2.44,4],[1,2.42,26.71],[2,1.74,1]],"ltp":2.54,"tv":22.13,"id":655}]}]}
{"op":"mcm","clk":"11871975337","pt":1723569516247,"mc":[{"id":"1.231705583","rc":[{"batb":[[0,2.46,10],[1,2.44,4],[2,2.42,26.71]],"ltp":2.54,"tv":22.13,"id":655}]}]}
{"op":"mcm","clk":"11871975579","pt":1723569518472,"mc":[{"id":"1.231705583","rc":[{"batb":[[1,2.42,26.71],[2,1.74,1]],"ltp":2.54,"tv":22.13,"id":655}]}]}
{"op":"mcm","clk":"11871975864","pt":1723569521181,"mc":[{"id":"1.231705583","rc":[{"batb":[[0,2.48,4]],"ltp":2.54,"tv":22.13,"id":655}]}]}
{"op":"mcm","clk":"11871976124","pt":1723569523159,"mc":[{"id":"1.231705583","rc":[{"batb":[[0,2.5,10],[1,2.48,4],[2,2.42,26.71]],"ltp":2.54,"tv":22.13,"id":655}]}]}
{"op":"mcm","clk":"11871976347","pt":1723569525352,"mc":[{"id":"1.231705583","rc":[{"batb":[[1,2.42,26.71],[2,1.74,1]],"ltp":2.54,"tv":22.13,"id":655}]}]}
{"op":"mcm","clk":"11871976607","pt":1723569527798,"mc":[{"id":"1.231705583","rc":[{"batb":[[0,2.52,4],[1,2.5,10],[2,2.42,26.71]],"ltp":2.54,"tv":22.13,"id":655}]}]}
{"op":"mcm","clk":"11871976768","pt":1723569529303,"mc":[{"id":"1.231705583","rc":[{"batb":[[1,2.42,26.71],[2,1.74,1]],"ltp":2.54,"tv":22.13,"id":655}]}]}
{"op":"mcm","clk":"11871977005","pt":1723569531485,"mc":[{"id":"1.231705583","rc":[{"trd":[[2.54,20]],"ltp":2.54,"tv":32.12,"id":655},{"trd":[[1.65,30.78]],"batb":[[0,1.65,42.98]],"ltp":1.65,"tv":144.41,"id":169}],"tv":176.54}]}
{"op":"mcm","clk":"11871977116","pt":1723569532466,"mc":[{"id":"1.231705583","rc":[{"batb":[[0,2.42,26.71],[1,1.74,1],[2,1.38,131.58]],"ltp":2.54,"tv":32.12,"id":655}]}]}
{"op":"mcm","clk":"11871977368","pt":1723569534913,"mc":[{"id":"1.231705583","rc":[{"batb":[[0,1.65,58.37]],"ltp":1.65,"tv":144.41,"id":169}]}]}
{"op":"mcm","clk":"11871977555","pt":1723569536582,"mc":[{"id":"1.231705583","rc":[{"batb":[[0,2.44,14],[1,2.42,26.71],[2,1.74,1]],"ltp":2.54,"tv":32.12,"id":655}]}]}
{"op":"mcm","clk":"11871978025","pt":1723569541309,"mc":[{"id":"1.231705583","rc":[{"batb":[[0,2.44,10]],"ltp":2.54,"tv":32.12,"id":655}]}]}
{"op":"mcm","clk":"11871978124","pt":1723569542295,"mc":[{"id":"1.231705583","rc":[{"batb":[[0,2.42,26.71],[1,1.74,1],[2,1.38,131.58]],"ltp":2.54,"tv":32.12,"id":655}]}]}
{"op":"mcm","clk":"11871978301","pt":1723569543803,"mc":[{"id":"1.231705583","rc":[{"batb":[[0,2.46,4],[1,2.42,26.71],[2,1.74,1]],"ltp":2.54,"tv":32.12,"id":655}]}]}
{"op":"mcm","clk":"11871978493","pt":1723569545696,"mc":[{"id":"1.231705583","rc":[{"batb":[[1,2.44,10],[2,2.42,26.71]],"ltp":2.54,"tv":32.12,"id":655}]}]}
{"op":"mcm","clk":"11871978866","pt":1723569549043,"mc":[{"id":"1.231705583","rc":[{"batb":[[0,2.44,10],[1,2.42,26.71],[2,1.74,1]],"ltp":2.54,"tv":32.12,"id":655}]}]}
{"op":"mcm","clk":"11871979104","pt":1723569551428,"mc":[{"id":"1.231705583","rc":[{"batb":[[0,2.42,26.71],[1,1.74,1],[2,1.38,131.58]],"ltp":2.54,"tv":32.12,"id":655}]}]}
{"op":"mcm","clk":"11871979392","pt":1723569553726,"mc":[{"id":"1.231705583","rc":[{"batb":[[0,2.44,14],[1,2.42,26.71],[2,1.74,1]],"ltp":2.54,"tv":32.12,"id":655}]}]}
{"op":"mcm","clk":"11871979930","pt":1723569558730,"mc":[{"id":"1.231705583","rc":[{"batb":[[0,2.44,10]],"ltp":2.54,"tv":32.12,"id":655}]}]}
{"op":"mcm","clk":"11871980013","pt":1723569559758,"mc":[{"id":"1.231705583","rc":[{"batb":[[0,2.42,26.71],[1,1.74,1],[2,1.38,131.58]],"ltp":2.54,"tv":32.12,"id":655}]}]}
{"op":"mcm","clk":"11871980270","pt":1723569562423,"mc":[{"id":"1.231705583","rc":[{"batb":[[0,2.46,14],[1,2.42,26.71],[2,1.74,1]],"ltp":2.54,"tv":32.12,"id":655}]}]}
{"op":"mcm","clk":"11871980772","pt":1723569567339,"mc":[{"id":"1.231705583","rc":[{"batb":[[0,2.46,10]],"ltp":2.54,"tv":32.12,"id":655}]}]}
{"op":"mcm","clk":"11871980873","pt":1723569568428,"mc":[{"id":"1.231705583","rc":[{"batb":[[0,2.42,26.71],[1,1.74,1],[2,1.38,131.58]],"ltp":2.54,"tv":32.12,"id":655}]}]}
{"op":"mcm","clk":"11871981179","pt":1723569571750,"mc":[{"id":"1.231705583","rc":[{"batb":[[0,2.44,14],[1,2.42,26.71],[2,1.74,1]],"ltp":2.54,"tv":32.12,"id":655}]}]}
{"op":"mcm","clk":"11871981756","pt":1723569577446,"mc":[{"id":"1.231705583","rc":[{"batb":[[0,2.42,26.71],[1,1.74,1],[2,1.38,131.58]],"ltp":2.54,"tv":32.12,"id":655}]}]}
{"op":"mcm","clk":"11871981931","pt":1723569579436,"mc":[{"id":"1.231705583","rc":[{"batb":[[0,2.46,4],[1,2.42,26.71],[2,1.74,1]],"ltp":2.54,"tv":32.12,"id":655}]}]}
{"op":"mcm","clk":"11871981993","pt":1723569580046,"mc":[{"id":"1.231705583","rc":[{"batb":[[1,2.44,10],[2,2.42,26.71]],"ltp":2.54,"tv":32.12,"id":655}]}]}
{"op":"mcm","clk":"11871982398","pt":1723569583732,"mc":[{"id":"1.231705583","rc":[{"batb":[[0,2.44,10],[1,2.42,26.71],[2,1.74,1]],"ltp":2.54,"tv":32.12,"id":655}]}]}
{"op":"mcm","clk":"11871982587","pt":1723569585551,"mc":[{"id":"1.231705583","rc":[{"batb":[[0,2.42,26.71],[1,1.74,1],[2,1.38,131.58]],"ltp":2.54,"tv":32.12,"id":655}]}]}
{"op":"mcm","clk":"11871982824","pt":1723569587745,"mc":[{"id":"1.231705583","rc":[{"batb":[[0,2.44,14],[1,2.42,26.71],[2,1.74,1]],"ltp":2.54,"tv":32.12,"id":655}]}]}
{"op":"mcm","clk":"11871983199","pt":1723569591269,"mc":[{"id":"1.231705583","rc":[{"batb":[[0,2.44,10]],"ltp":2.54,"tv":32.12,"id":655}]}]}
{"op":"mcm","clk":"11871983302","pt":1723569592369,"mc":[{"id":"1.231705583","rc":[{"batb":[[0,2.42,26.71],[1,1.74,1],[2,1.38,131.58]],"ltp":2.54,"tv":32.12,"id":655}]}]}
{"op":"mcm","clk":"11871983460","pt":1723569593990,"mc":[{"id":"1.231705583","rc":[{"batb":[[0,2.44,4],[1,2.42,26.71],[2,1.74,1]],"ltp":2.54,"tv":32.12,"id":655}]}]}
{"op":"mcm","clk":"11871983635","pt":1723569595761,"mc":[{"id":"1.231705583","rc":[{"batb":[[0,2.46,10],[1,2.44,4],[2,2.42,26.71]],"ltp":2.54,"tv":32.12,"id":655}]}]}
{"op":"mcm","clk":"11871983852","pt":1723569597975,"mc":[{"id":"1.231705583","rc":[{"batb":[[1,2.42,26.71],[2,1.74,1]],"ltp":2.54,"tv":32.12,"id":655}]}]}
{"op":"mcm","clk":"11871984070","pt":1723569599973,"mc":[{"id":"1.231705583","rc":[{"batb":[[0,2.42,26.71],[1,1.74,1],[2,1.38,131.58]],"ltp":2.54,"tv":32.12,"id":655}]}]}
{"op":"mcm","clk":"11871984172","pt":1723569601085,"mc":[{"id":"1.231705583","rc":[{"batb":[[0,2.44,4],[1,2.42,26.71],[2,1.74,1]],"ltp":2.54,"tv":32.12,"id":655}]}]}
{"op":"mcm","clk":"11871984383","pt":1723569603092,"mc":[{"id":"1.231705583","rc":[{"batb":[[0,2.46,10],[1,2.44,4],[2,2.42,26.71]],"ltp":2.54,"tv":32.12,"id":655}]}]}
{"op":"mcm","clk":"11871984592","pt":1723569605065,"mc":[{"id":"1.231705583","rc":[{"batb":[[1,2.42,26.71],[2,1.74,1]],"ltp":2.54,"tv":32.12,"id":655}]}]}
{"op":"mcm","clk":"11871984884","pt":1723569608088,"mc":[{"id":"1.231705583","rc":[{"batb":[[0,2.42,26.71],[1,1.74,1],[2,1.38,131.58]],"ltp":2.54,"tv":32.12,"id":655}]}]}
{"op":"mcm","clk":"11871985089","pt":1723569610383,"mc":[{"id":"1.231705583","rc":[{"batb":[[0,2.44,14],[1,2.42,26.71],[2,1.74,1]],"ltp":2.54,"tv":32.12,"id":655}]}]}
{"op":"mcm","clk":"11871985591","pt":1723569614971,"mc":[{"id":"1.231705583","rc":[{"batb":[[0,2.44,10]],"ltp":2.54,"tv":32.12,"id":655}]}]}
{"op":"mcm","clk":"11871985723","pt":1723569616057,"mc":[{"id":"1.231705583","rc":[{"batb":[[0,2.42,26.71],[1,1.74,1],[2,1.38,131.58]],"ltp":2.54,"tv":32.12,"id":655}]}]}
{"op":"mcm","clk":"11871985908","pt":1723569617876,"mc":[{"id":"1.231705583","rc":[{"batb":[[0,2.44,4],[1,2.42,26.71],[2,1.74,1]],"ltp":2.54,"tv":32.12,"id":655}]}]}
{"op":"mcm","clk":"11871986065","pt":1723569619376,"mc":[{"id":"1.231705583","rc":[{"batb":[[0,2.46,10],[1,2.44,4],[2,2.42,26.71]],"ltp":2.54,"tv":32.12,"id":655}]}]}
{"op":"mcm","clk":"11871986259","pt":1723569621491,"mc":[{"id":"1.231705583","rc":[{"batb":[[1,2.42,26.71],[2,1.74,1]],"ltp":2.54,"tv":32.12,"id":655}]}]}
{"op":"mcm","clk":"11871986503","pt":1723569623881,"mc":[{"id":"1.231705583","rc":[{"batb":[[0,2.48,4]],"ltp":2.54,"tv":32.12,"id":655}]}]}
{"op":"mcm","clk":"11871986838","pt":1723569627210,"mc":[{"id":"1.231705583","rc":[{"batb":[[0,2.42,26.71],[1,1.74,1],[2,1.38,131.58]],"ltp":2.54,"tv":32.12,"id":655}]}]}
{"op":"mcm","clk":"11871987042","pt":1723569629300,"mc":[{"id":"1.231705583","rc":[{"batb":[[0,2.44,10],[1,2.42,26.71],[2,1.74,1]],"ltp":2.54,"tv":32.12,"id":655}]}]}
{"op":"mcm","clk":"11871987274","pt":1723569631285,"mc":[{"id":"1.231705583","rc":[{"batb":[[0,2.46,4],[1,2.44,10],[2,2.42,26.71]],"ltp":2.54,"tv":32.12,"id":655}]}]}
{"op":"mcm","clk":"11871987609","pt":1723569634194,"mc":[{"id":"1.231705583","rc":[{"batb":[[1,2.42,26.71],[2,1.74,1]],"ltp":2.54,"tv":32.12,"id":655}]}]}
{"op":"mcm","clk":"11871987703","pt":1723569635192,"mc":[{"id":"1.231705583","rc":[{"batb":[[0,2.42,26.71],[1,1.74,1],[2,1.38,131.58]],"ltp":2.54,"tv":32.12,"id":655}]}]}
{"op":"mcm","clk":"11871987851","pt":1723569636480,"mc":[{"id":"1.231705583","rc":[{"batb":[[0,2.44,10],[1,2.42,26.71],[2,1.74,1]],"ltp":2.54,"tv":32.12,"id":655}]}]}
{"op":"mcm","clk":"11871988074","pt":1723569638905,"mc":[{"id":"1.231705583","rc":[{"batb":[[0,2.46,4],[1,2.44,10],[2,2.42,26.71]],"ltp":2.54,"tv":32.12,"id":655}]}]}
{"op":"mcm","clk":"11871988434","pt":1723569642502,"mc":[{"id":"1.231705583","rc":[{"batb":[[0,2.42,26.71],[1,1.74,1],[2,1.38,131.58]],"ltp":2.54,"tv":32.12,"id":655}]}]}
{"op":"mcm","clk":"11872022801","pt":1723569988714,"mc":[{"id":"1.231705583","rc":[{"batb":[[0,2.44,14],[1,2.42,26.71],[2,1.74,1]],"ltp":2.54,"tv":32.12,"id":655}]}]}
{"op":"mcm","clk":"11872023169","pt":1723569993121,"mc":[{"id":"1.231705583","rc":[{"batb":[[0,2.44,10]],"ltp":2.54,"tv":32.12,"id":655}]}]}
{"op":"mcm","clk":"11872023261","pt":1723569994262,"mc":[{"id":"1.231705583","rc":[{"batb":[[0,2.42,26.71],[1,1.74,1],[2,1.38,131.58]],"ltp":2.54,"tv":32.12,"id":655}]}]}
{"op":"mcm","clk":"11872222247","pt":1723571949082,"mc":[{"id":"1.231705583","rc":[{"batb":[[0,1.7,50],[1,1.65,58.37],[2,1.38,131.58]],"ltp":1.65,"tv":144.41,"id":169}]}]}
{"op":"mcm","clk":"11872265645","pt":1723572336401,"mc":[{"id":"1.231705583","rc":[{"trd":[[2.44,10]],"ltp":2.44,"tv":42.12,"id":655},{"trd":[[1.7,14.35]],"batb":[[0,1.7,35.65]],"ltp":1.7,"tv":158.76,"id":169}],"tv":200.89}]}
{"op":"mcm","clk":"11872266612","pt":1723572342247,"mc":[{"id":"1.231705583","rc":[{"trd":[[2.44,20]],"ltp":2.44,"tv":52.13,"id":655},{"trd":[[1.7,28.7]],"batb":[[0,1.7,21.3]],"ltp":1.7,"tv":173.11,"id":169}],"tv":225.24}]}
{"op":"mcm","clk":"11872329026","pt":1723572796876,"mc":[{"id":"1.231705583","rc":[{"batb":[[0,2.44,14],[1,2.42,26.71],[2,1.74,1]],"ltp":2.44,"tv":52.13,"id":655},{"trd":[[1.7,71.3]],"batb":[[0,1.65,58.37],[1,1.38,131.58],[2,1.33,151.52]],"batl":[[0,1.7,478.7],[1,1.73,47.98]],"ltp":1.7,"tv":215.71,"id":169}],"tv":267.84}]}
{"op":"mcm","clk":"11872329366","pt":1723572799291,"mc":[{"id":"1.231705583","rc":[{"batb":[[0,2.44,10]],"ltp":2.44,"tv":52.13,"id":655}]}]}
{"op":"mcm","clk":"11872329501","pt":1723572800280,"mc":[{"id":"1.231705583","rc":[{"batb":[[0,2.42,26.71],[1,1.74,1],[2,1.38,131.58]],"ltp":2.44,"tv":52.13,"id":655}]}]}
{"op":"mcm","clk":"11872362126","pt":1723573002174,"mc":[{"id":"1.231705583","rc":[{"trd":[[1.65,33.26]],"batb":[[0,1.65,57.13]],"ltp":1.65,"tv":218.2,"id":169}],"tv":270.33}]}
{"op":"mcm","clk":"11872362180","pt":1723573002572,"mc":[{"id":"1.231705583","rc":[{"batb":[[0,2.44,14],[1,2.42,26.71],[2,1.74,1]],"ltp":2.44,"tv":52.13,"id":655}]}]}
{"op":"mcm","clk":"11872362572","pt":1723573004923,"mc":[{"id":"1.231705583","rc":[{"batb":[[0,2.44,10]],"ltp":2.44,"tv":52.13,"id":655}]}]}
{"op":"mcm","clk":"11872362743","pt":1723573005978,"mc":[{"id":"1.231705583","rc":[{"batb":[[0,2.42,26.71],[1,1.74,1],[2,1.38,131.58]],"ltp":2.44,"tv":52.13,"id":655}]}]}
{"op":"mcm","clk":"11872362924","pt":1723573007227,"mc":[{"id":"1.231705583","rc":[{"batb":[[0,2.44,4],[1,2.42,26.71],[2,1.74,1]],"ltp":2.44,"tv":52.13,"id":655},{"batb":[[0,1.65,58.37]],"ltp":1.65,"tv":218.2,"id":169}]}]}
{"op":"mcm","clk":"11872363313","pt":1723573009735,"mc":[{"id":"1.231705583","rc":[{"batb":[[0,2.44,10]],"ltp":2.44,"tv":52.13,"id":655}]}]}
{"op":"mcm","clk":"11872363907","pt":1723573013287,"mc":[{"id":"1.231705583","rc":[{"batb":[[0,2.44,4]],"ltp":2.44,"tv":52.13,"id":655}]}]}
{"op":"mcm","clk":"11872364261","pt":1723573015490,"mc":[{"id":"1.231705583","rc":[{"batb":[[0,2.42,26.71],[1,1.74,1],[2,1.38,131.58]],"ltp":2.44,"tv":52.13,"id":655}]}]}
{"op":"mcm","clk":"11872364280","pt":1723573015591,"mc":[{"id":"1.231705583","rc":[{"batb":[[0,2.44,10],[1,2.42,26.71],[2,1.74,1]],"ltp":2.44,"tv":52.13,"id":655}]}]}
{"op":"mcm","clk":"11872364814","pt":1723573019269,"mc":[{"id":"1.231705583","rc":[{"batb":[[0,2.44,4]],"ltp":2.44,"tv":52.13,"id":655}]}]}
{"op":"mcm","clk":"11872365243","pt":1723573021893,"mc":[{"id":"1.231705583","rc":[{"batb":[[0,2.44,10]],"ltp":2.44,"tv":52.13,"id":655}]}]}
{"op":"mcm","clk":"11872365822","pt":1723573025482,"mc":[{"id":"1.231705583","rc":[{"batb":[[0,2.42,26.71],[1,1.74,1],[2,1.38,131.58]],"ltp":2.44,"tv":52.13,"id":655}]}]}
{"op":"mcm","clk":"11872365854","pt":1723573025684,"mc":[{"id":"1.231705583","rc":[{"batb":[[0,2.44,4],[1,2.42,26.71],[2,1.74,1]],"ltp":2.44,"tv":52.13,"id":655}]}]}
{"op":"mcm","clk":"11872366229","pt":1723573028196,"mc":[{"id":"1.231705583","rc":[{"batb":[[0,2.44,10]],"ltp":2.44,"tv":52.13,"id":655}]}]}
{"op":"mcm","clk":"11872366713","pt":1723573031491,"mc":[{"id":"1.231705583","rc":[{"batb":[[0,2.42,26.71],[1,1.74,1],[2,1.38,131.58]],"ltp":2.44,"tv":52.13,"id":655}]}]}
{"op":"mcm","clk":"11872366754","pt":1723573031806,"mc":[{"id":"1.231705583","rc":[{"batb":[[0,2.44,4],[1,2.42,26.71],[2,1.74,1]],"ltp":2.44,"tv":52.13,"id":655}]}]}
{"op":"mcm","clk":"11872367109","pt":1723573034296,"mc":[{"id":"1.231705583","rc":[{"batb":[[0,2.44,10]],"ltp":2.44,"tv":52.13,"id":655}]}]}
{"op":"mcm","clk":"11872367566","pt":1723573037496,"mc":[{"id":"1.231705583","rc":[{"batb":[[0,2.42,26.71],[1,1.74,1],[2,1.38,131.58]],"ltp":2.44,"tv":52.13,"id":655}]}]}
{"op":"mcm","clk":"11872367598","pt":1723573037695,"mc":[{"id":"1.231705583","rc":[{"batb":[[0,2.44,4],[1,2.42,26.71],[2,1.74,1]],"ltp":2.44,"tv":52.13,"id":655}]}]}
{"op":"mcm","clk":"11872367968","pt":1723573040015,"mc":[{"id":"1.231705583","rc":[{"batb":[[0,2.44,10]],"ltp":2.44,"tv":52.13,"id":655}]}]}
{"op":"mcm","clk":"11872368527","pt":1723573043885,"mc":[{"id":"1.231705583","rc":[{"batb":[[0,2.44,4]],"ltp":2.44,"tv":52.13,"id":655}]}]}
{"op":"mcm","clk":"11872368866","pt":1723573046251,"mc":[{"id":"1.231705583","rc":[{"batb":[[0,2.44,10]],"ltp":2.44,"tv":52.13,"id":655}]}]}
{"op":"mcm","clk":"11872369328","pt":1723573049903,"mc":[{"id":"1.231705583","rc":[{"batb":[[0,2.44,4]],"ltp":2.44,"tv":52.13,"id":655}]}]}
{"op":"mcm","clk":"11872369703","pt":1723573052474,"mc":[{"id":"1.231705583","rc":[{"batb":[[0,2.44,10]],"ltp":2.44,"tv":52.13,"id":655}]}]}
{"op":"mcm","clk":"11872370244","pt":1723573056249,"mc":[{"id":"1.231705583","rc":[{"batb":[[0,2.44,4]],"ltp":2.44,"tv":52.13,"id":655}]}]}
{"op":"mcm","clk":"11872370628","pt":1723573058821,"mc":[{"id":"1.231705583","rc":[{"batb":[[0,2.44,10]],"ltp":2.44,"tv":52.13,"id":655}]}]}
{"op":"mcm","clk":"11872371088","pt":1723573062234,"mc":[{"id":"1.231705583","rc":[{"batb":[[0,2.44,4]],"ltp":2.44,"tv":52.13,"id":655}]}]}
{"op":"mcm","clk":"11872371486","pt":1723573065405,"mc":[{"id":"1.231705583","rc":[{"batb":[[0,2.44,10]],"ltp":2.44,"tv":52.13,"id":655}]}]}
{"op":"mcm","clk":"11872371948","pt":1723573068947,"mc":[{"id":"1.231705583","rc":[{"batb":[[0,2.44,4]],"ltp":2.44,"tv":52.13,"id":655}]}]}
{"op":"mcm","clk":"11872372292","pt":1723573071473,"mc":[{"id":"1.231705583","rc":[{"batb":[[0,2.44,10]],"ltp":2.44,"tv":52.13,"id":655}]}]}
{"op":"mcm","clk":"11872372783","pt":1723573074839,"mc":[{"id":"1.231705583","rc":[{"batb":[[0,2.44,4]],"ltp":2.44,"tv":52.13,"id":655}]}]}
{"op":"mcm","clk":"11872373130","pt":1723573077256,"mc":[{"id":"1.231705583","rc":[{"batb":[[0,2.42,26.71],[1,1.74,1],[2,1.38,131.58]],"ltp":2.44,"tv":52.13,"id":655}]}]}
{"op":"mcm","clk":"11872373221","pt":1723573077569,"mc":[{"id":"1.231705583","rc":[{"batb":[[0,2.44,10],[1,2.42,26.71],[2,1.74,1]],"ltp":2.44,"tv":52.13,"id":655}]}]}
{"op":"mcm","clk":"11872373704","pt":1723573080868,"mc":[{"id":"1.231705583","rc":[{"batb":[[0,2.42,26.71],[1,1.74,1],[2,1.38,131.58]],"ltp":2.44,"tv":52.13,"id":655}]}]}
{"op":"mcm","clk":"11872373858","pt":1723573081857,"mc":[{"id":"1.231705583","rc":[{"batb":[[0,2.44,4],[1,2.42,26.71],[2,1.74,1]],"ltp":2.44,"tv":52.13,"id":655}]}]}
{"op":"mcm","clk":"11872374234","pt":1723573084479,"mc":[{"id":"1.231705583","rc":[{"batb":[[0,2.42,26.71],[1,1.74,1],[2,1.38,131.58]],"ltp":2.44,"tv":52.13,"id":655}]}]}
{"op":"mcm","clk":"11872374305","pt":1723573084950,"mc":[{"id":"1.231705583","rc":[{"batb":[[0,2.44,10],[1,2.42,26.71],[2,1.74,1]],"ltp":2.44,"tv":52.13,"id":655}]}]}
{"op":"mcm","clk":"11872374811","pt":1723573088477,"mc":[{"id":"1.231705583","rc":[{"batb":[[0,2.44,4]],"ltp":2.44,"tv":52.13,"id":655}]}]}
{"op":"mcm","clk":"11872375206","pt":1723573091295,"mc":[{"id":"1.231705583","rc":[{"batb":[[0,2.44,10]],"ltp":2.44,"tv":52.13,"id":655}]}]}
{"op":"mcm","clk":"11872375709","pt":1723573094855,"mc":[{"id":"1.231705583","rc":[{"batb":[[0,2.44,4]],"ltp":2.44,"tv":52.13,"id":655}]}]}
{"op":"mcm","clk":"11872376081","pt":1723573097364,"mc":[{"id":"1.231705583","rc":[{"batb":[[0,2.42,26.71],[1,1.74,1],[2,1.38,131.58]],"ltp":2.44,"tv":52.13,"id":655}]}]}
{"op":"mcm","clk":"11872376134","pt":1723573097782,"mc":[{"id":"1.231705583","rc":[{"batb":[[0,2.44,10],[1,2.42,26.71],[2,1.74,1]],"ltp":2.44,"tv":52.13,"id":655}]}]}
{"op":"mcm","clk":"11872376697","pt":1723573101354,"mc":[{"id":"1.231705583","rc":[{"batb":[[0,2.44,4]],"ltp":2.44,"tv":52.13,"id":655}]}]}
{"op":"mcm","clk":"11872377027","pt":1723573103644,"mc":[{"id":"1.231705583","rc":[{"batb":[[0,2.44,10]],"ltp":2.44,"tv":52.13,"id":655}]}]}
{"op":"mcm","clk":"11872377578","pt":1723573107375,"mc":[{"id":"1.231705583","rc":[{"batb":[[0,2.44,4]],"ltp":2.44,"tv":52.13,"id":655}]}]}
{"op":"mcm","clk":"11872377960","pt":1723573110002,"mc":[{"id":"1.231705583","rc":[{"batb":[[0,2.44,10]],"ltp":2.44,"tv":52.13,"id":655}]}]}
{"op":"mcm","clk":"11872378550","pt":1723573113494,"mc":[{"id":"1.231705583","rc":[{"batb":[[0,2.42,26.71],[1,1.74,1],[2,1.38,131.58]],"ltp":2.44,"tv":52.13,"id":655}]}]}
{"op":"mcm","clk":"11872378569","pt":1723573113596,"mc":[{"id":"1.231705583","rc":[{"batb":[[0,2.44,4],[1,2.42,26.71],[2,1.74,1]],"ltp":2.44,"tv":52.13,"id":655}]}]}
{"op":"mcm","clk":"11872378918","pt":1723573116050,"mc":[{"id":"1.231705583","rc":[{"batb":[[0,2.44,10]],"ltp":2.44,"tv":52.13,"id":655}]}]}
{"op":"mcm","clk":"11872379375","pt":1723573119487,"mc":[{"id":"1.231705583","rc":[{"batb":[[0,2.42,26.71],[1,1.74,1],[2,1.38,131.58]],"ltp":2.44,"tv":52.13,"id":655}]}]}
{"op":"mcm","clk":"11872379408","pt":1723573119789,"mc":[{"id":"1.231705583","rc":[{"batb":[[0,2.44,4],[1,2.42,26.71],[2,1.74,1]],"ltp":2.44,"tv":52.13,"id":655}]}]}
{"op":"mcm","clk":"11872379773","pt":1723573122492,"mc":[{"id":"1.231705583","rc":[{"batb":[[0,2.44,10]],"ltp":2.44,"tv":52.13,"id":655}]}]}
{"op":"mcm","clk":"11872380254","pt":1723573126081,"mc":[{"id":"1.231705583","rc":[{"batb":[[0,2.44,4]],"ltp":2.44,"tv":52.13,"id":655}]}]}
{"op":"mcm","clk":"11872380585","pt":1723573128474,"mc":[{"id":"1.231705583","rc":[{"batb":[[0,2.44,10]],"ltp":2.44,"tv":52.13,"id":655}]}]}
{"op":"mcm","clk":"11872381107","pt":1723573132376,"mc":[{"id":"1.231705583","rc":[{"batb":[[0,2.44,4]],"ltp":2.44,"tv":52.13,"id":655}]}]}
{"op":"mcm","clk":"11872381437","pt":1723573134782,"mc":[{"id":"1.231705583","rc":[{"batb":[[0,2.44,10]],"ltp":2.44,"tv":52.13,"id":655}]}]}
{"op":"mcm","clk":"11872381910","pt":1723573138218,"mc":[{"id":"1.231705583","rc":[{"batb":[[0,2.44,4]],"ltp":2.44,"tv":52.13,"id":655}]}]}
{"op":"mcm","clk":"11872382297","pt":1723573140733,"mc":[{"id":"1.231705583","rc":[{"batb":[[0,2.44,10]],"ltp":2.44,"tv":52.13,"id":655}]}]}
{"op":"mcm","clk":"11872382831","pt":1723573144231,"mc":[{"id":"1.231705583","rc":[{"batb":[[0,2.44,4]],"ltp":2.44,"tv":52.13,"id":655}]}]}
{"op":"mcm","clk":"11872383189","pt":1723573146628,"mc":[{"id":"1.231705583","rc":[{"batb":[[0,2.44,10]],"ltp":2.44,"tv":52.13,"id":655}]}]}
{"op":"mcm","clk":"11872383671","pt":1723573150090,"mc":[{"id":"1.231705583","rc":[{"batb":[[0,2.44,4]],"ltp":2.44,"tv":52.13,"id":655}]}]}
{"op":"mcm","clk":"11872384066","pt":1723573152830,"mc":[{"id":"1.231705583","rc":[{"batb":[[0,2.44,10]],"ltp":2.44,"tv":52.13,"id":655}]}]}
{"op":"mcm","clk":"11872384615","pt":1723573156506,"mc":[{"id":"1.231705583","rc":[{"batb":[[0,2.44,4]],"ltp":2.44,"tv":52.13,"id":655}]}]}
{"op":"mcm","clk":"11872384979","pt":1723573159018,"mc":[{"id":"1.231705583","rc":[{"batb":[[0,2.44,10]],"ltp":2.44,"tv":52.13,"id":655}]}]}
{"op":"mcm","clk":"11872385438","pt":1723573162319,"mc":[{"id":"1.231705583","rc":[{"batb":[[0,2.42,26.71],[1,1.74,1],[2,1.38,131.58]],"ltp":2.44,"tv":52.13,"id":655}]}]}
{"op":"mcm","clk":"11872385471","pt":1723573162524,"mc":[{"id":"1.231705583","rc":[{"batb":[[0,2.44,4],[1,2.42,26.71],[2,1.74,1]],"ltp":2.44,"tv":52.13,"id":655}]}]}
{"op":"mcm","clk":"11872385857","pt":1723573165344,"mc":[{"id":"1.231705583","rc":[{"batb":[[0,2.44,10]],"ltp":2.44,"tv":52.13,"id":655}]}]}
{"op":"mcm","clk":"11872386353","pt":1723573168802,"mc":[{"id":"1.231705583","rc":[{"batb":[[0,2.44,4]],"ltp":2.44,"tv":52.13,"id":655}]}]}
{"op":"mcm","clk":"11872386721","pt":1723573171438,"mc":[{"id":"1.231705583","rc":[{"batb":[[0,2.44,10]],"ltp":2.44,"tv":52.13,"id":655}]}]}
{"op":"mcm","clk":"11872387226","pt":1723573175009,"mc":[{"id":"1.231705583","rc":[{"batb":[[0,2.44,4]],"ltp":2.44,"tv":52.13,"id":655}]}]}
{"op":"mcm","clk":"11872387563","pt":1723573177212,"mc":[{"id":"1.231705583","rc":[{"batb":[[0,2.42,26.71],[1,1.74,1],[2,1.38,131.58]],"ltp":2.44,"tv":52.13,"id":655}]}]}
{"op":"mcm","clk":"11872387625","pt":1723573177632,"mc":[{"id":"1.231705583","rc":[{"batb":[[0,2.44,10],[1,2.42,26.71],[2,1.74,1]],"ltp":2.44,"tv":52.13,"id":655}]}]}
{"op":"mcm","clk":"11872388124","pt":1723573181141,"mc":[{"id":"1.231705583","rc":[{"batb":[[0,2.44,4]],"ltp":2.44,"tv":52.13,"id":655}]}]}
{"op":"mcm","clk":"11872388457","pt":1723573183485,"mc":[{"id":"1.231705583","rc":[{"batb":[[0,2.42,26.71],[1,1.74,1],[2,1.38,131.58]],"ltp":2.44,"tv":52.13,"id":655}]}]}
{"op":"mcm","clk":"11872388513","pt":1723573183869,"mc":[{"id":"1.231705583","rc":[{"batb":[[0,2.44,10],[1,2.42,26.71],[2,1.74,1]],"ltp":2.44,"tv":52.13,"id":655}]}]}
{"op":"mcm","clk":"11872388982","pt":1723573187278,"mc":[{"id":"1.231705583","rc":[{"batb":[[0,2.44,4]],"ltp":2.44,"tv":52.13,"id":655}]}]}
{"op":"mcm","clk":"11872389335","pt":1723573189792,"mc":[{"id":"1.231705583","rc":[{"batb":[[0,2.44,10]],"ltp":2.44,"tv":52.13,"id":655}]}]}
{"op":"mcm","clk":"11872389830","pt":1723573193390,"mc":[{"id":"1.231705583","rc":[{"batb":[[0,2.44,4]],"ltp":2.44,"tv":52.13,"id":655}]}]}
{"op":"mcm","clk":"11872390214","pt":1723573196278,"mc":[{"id":"1.231705583","rc":[{"batb":[[0,2.44,10]],"ltp":2.44,"tv":52.13,"id":655}]}]}
{"op":"mcm","clk":"11872390696","pt":1723573200043,"mc":[{"id":"1.231705583","rc":[{"batb":[[0,2.44,4]],"ltp":2.44,"tv":52.13,"id":655}]}]}
{"op":"mcm","clk":"11872391139","pt":1723573202899,"mc":[{"id":"1.231705583","rc":[{"batb":[[0,2.44,10]],"ltp":2.44,"tv":52.13,"id":655}]}]}
{"op":"mcm","clk":"11872391655","pt":1723573206272,"mc":[{"id":"1.231705583","rc":[{"batb":[[0,2.42,26.71],[1,1.74,1],[2,1.38,131.58]],"ltp":2.44,"tv":52.13,"id":655}]}]}
{"op":"mcm","clk":"11872391703","pt":1723573206582,"mc":[{"id":"1.231705583","rc":[{"batb":[[0,2.44,4],[1,2.42,26.71],[2,1.74,1]],"ltp":2.44,"tv":52.13,"id":655}]}]}
{"op":"mcm","clk":"11872392089","pt":1723573209067,"mc":[{"id":"1.231705583","rc":[{"batb":[[0,2.44,10]],"ltp":2.44,"tv":52.13,"id":655}]}]}
{"op":"mcm","clk":"11872392685","pt":1723573212899,"mc":[{"id":"1.231705583","rc":[{"batb":[[0,2.44,4]],"ltp":2.44,"tv":52.13,"id":655}]}]}
{"op":"mcm","clk":"11872393101","pt":1723573215392,"mc":[{"id":"1.231705583","rc":[{"batb":[[0,2.44,10]],"ltp":2.44,"tv":52.13,"id":655}]}]}
{"op":"mcm","clk":"11872393660","pt":1723573218808,"mc":[{"id":"1.231705583","rc":[{"batb":[[0,2.44,4]],"ltp":2.44,"tv":52.13,"id":655}]}]}
{"op":"mcm","clk":"11872394032","pt":1723573221284,"mc":[{"id":"1.231705583","rc":[{"batb":[[0,2.42,26.71],[1,1.74,1],[2,1.38,131.58]],"ltp":2.44,"tv":52.13,"id":655}]}]}
{"op":"mcm","clk":"11872394077","pt":1723573221600,"mc":[{"id":"1.231705583","rc":[{"batb":[[0,2.44,10],[1,2.42,26.71],[2,1.74,1]],"ltp":2.44,"tv":52.13,"id":655}]}]}
{"op":"mcm","clk":"11872394624","pt":1723573225372,"mc":[{"id":"1.231705583","rc":[{"batb":[[0,2.44,4]],"ltp":2.44,"tv":52.13,"id":655}]}]}
{"op":"mcm","clk":"11872395021","pt":1723573228089,"mc":[{"id":"1.231705583","rc":[{"batb":[[0,2.44,10]],"ltp":2.44,"tv":52.13,"id":655}]}]}
{"op":"mcm","clk":"11872395542","pt":1723573231496,"mc":[{"id":"1.231705583","rc":[{"batb":[[0,2.42,26.71],[1,1.74,1],[2,1.38,131.58]],"ltp":2.44,"tv":52.13,"id":655}]}]}
{"op":"mcm","clk":"11872395682","pt":1723573232328,"mc":[{"id":"1.231705583","rc":[{"batb":[[0,2.44,4],[1,2.42,26.71],[2,1.74,1]],"ltp":2.44,"tv":52.13,"id":655}]}]}
{"op":"mcm","clk":"11872396105","pt":1723573234914,"mc":[{"id":"1.231705583","rc":[{"batb":[[0,2.42,26.71],[1,1.74,1],[2,1.38,131.58]],"ltp":2.44,"tv":52.13,"id":655}]}]}
{"op":"mcm","clk":"11872396201","pt":1723573235529,"mc":[{"id":"1.231705583","rc":[{"batb":[[0,2.44,10],[1,2.42,26.71],[2,1.74,1]],"ltp":2.44,"tv":52.13,"id":655}]}]}
{"op":"mcm","clk":"11872396792","pt":1723573239436,"mc":[{"id":"1.231705583","rc":[{"batb":[[0,2.44,4]],"ltp":2.44,"tv":52.13,"id":655}]}]}
{"op":"mcm","clk":"11872397145","pt":1723573241928,"mc":[{"id":"1.231705583","rc":[{"batb":[[0,2.44,10]],"ltp":2.44,"tv":52.13,"id":655}]}]}
{"op":"mcm","clk":"11872397630","pt":1723573245436,"mc":[{"id":"1.231705583","rc":[{"batb":[[0,2.44,4]],"ltp":2.44,"tv":52.13,"id":655}]}]}
{"op":"mcm","clk":"11872398017","pt":1723573248231,"mc":[{"id":"1.231705583","rc":[{"batb":[[0,2.44,10]],"ltp":2.44,"tv":52.13,"id":655}]}]}
{"op":"mcm","clk":"11872398598","pt":1723573251940,"mc":[{"id":"1.231705583","rc":[{"batb":[[0,2.44,4]],"ltp":2.44,"tv":52.13,"id":655}]}]}
{"op":"mcm","clk":"11872398946","pt":1723573254439,"mc":[{"id":"1.231705583","rc":[{"batb":[[0,2.44,10]],"ltp":2.44,"tv":52.13,"id":655}]}]}
{"op":"mcm","clk":"11872399497","pt":1723573258345,"mc":[{"id":"1.231705583","rc":[{"batb":[[0,2.44,4]],"ltp":2.44,"tv":52.13,"id":655}]}]}
{"op":"mcm","clk":"11872399940","pt":1723573261221,"mc":[{"id":"1.231705583","rc":[{"batb":[[0,2.44,10]],"ltp":2.44,"tv":52.13,"id":655}]}]}
{"op":"mcm","clk":"11872400511","pt":1723573265148,"mc":[{"id":"1.231705583","rc":[{"batb":[[0,2.44,4]],"ltp":2.44,"tv":52.13,"id":655}]}]}
{"op":"mcm","clk":"11872400905","pt":1723573267921,"mc":[{"id":"1.231705583","rc":[{"batb":[[0,2.44,10]],"ltp":2.44,"tv":52.13,"id":655}]}]}
{"op":"mcm","clk":"11872401432","pt":1723573271852,"mc":[{"id":"1.231705583","rc":[{"batb":[[0,2.44,4]],"ltp":2.44,"tv":52.13,"id":655}]}]}
{"op":"mcm","clk":"11872401755","pt":1723573274233,"mc":[{"id":"1.231705583","rc":[{"batb":[[0,2.44,10]],"ltp":2.44,"tv":52.13,"id":655}]}]}
{"op":"mcm","clk":"11872402268","pt":1723573278142,"mc":[{"id":"1.231705583","rc":[{"batb":[[0,2.44,4]],"ltp":2.44,"tv":52.13,"id":655}]}]}
{"op":"mcm","clk":"11872402575","pt":1723573280369,"mc":[{"id":"1.231705583","rc":[{"batb":[[0,2.42,26.71],[1,1.74,1],[2,1.38,131.58]],"ltp":2.44,"tv":52.13,"id":655}]}]}
{"op":"mcm","clk":"11872402618","pt":1723573280629,"mc":[{"id":"1.231705583","rc":[{"batb":[[0,2.44,10],[1,2.42,26.71],[2,1.74,1]],"ltp":2.44,"tv":52.13,"id":655}]}]}
{"op":"mcm","clk":"11872403113","pt":1723573284086,"mc":[{"id":"1.231705583","rc":[{"batb":[[0,2.44,4]],"ltp":2.44,"tv":52.13,"id":655}]}]}
{"op":"mcm","clk":"11872403483","pt":1723573286593,"mc":[{"id":"1.231705583","rc":[{"batb":[[0,2.44,10]],"ltp":2.44,"tv":52.13,"id":655}]}]}
{"op":"mcm","clk":"11872403948","pt":1723573289893,"mc":[{"id":"1.231705583","rc":[{"batb":[[0,2.42,26.71],[1,1.74,1],[2,1.38,131.58]],"ltp":2.44,"tv":52.13,"id":655}]}]}
{"op":"mcm","clk":"11872404023","pt":1723573290520,"mc":[{"id":"1.231705583","rc":[{"batb":[[0,2.44,4],[1,2.42,26.71],[2,1.74,1]],"ltp":2.44,"tv":52.13,"id":655}]}]}
{"op":"mcm","clk":"11872404491","pt":1723573293512,"mc":[{"id":"1.231705583","rc":[{"batb":[[0,2.44,10]],"ltp":2.44,"tv":52.13,"id":655}]}]}
{"op":"mcm","clk":"11872405015","pt":1723573297298,"mc":[{"id":"1.231705583","rc":[{"batb":[[0,2.44,4]],"ltp":2.44,"tv":52.13,"id":655}]}]}
{"op":"mcm","clk":"11872405370","pt":1723573299806,"mc":[{"id":"1.231705583","rc":[{"batb":[[0,2.44,10]],"ltp":2.44,"tv":52.13,"id":655}]}]}
{"op":"mcm","clk":"11872405855","pt":1723573303307,"mc":[{"id":"1.231705583","rc":[{"batb":[[0,2.44,4]],"ltp":2.44,"tv":52.13,"id":655}]}]}
{"op":"mcm","clk":"11872406261","pt":1723573305921,"mc":[{"id":"1.231705583","rc":[{"batb":[[0,2.44,10]],"ltp":2.44,"tv":52.13,"id":655}]}]}
{"op":"mcm","clk":"11872406762","pt":1723573309427,"mc":[{"id":"1.231705583","rc":[{"batb":[[0,2.44,4]],"ltp":2.44,"tv":52.13,"id":655}]}]}
{"op":"mcm","clk":"11872407151","pt":1723573311937,"mc":[{"id":"1.231705583","rc":[{"batb":[[0,2.44,10]],"ltp":2.44,"tv":52.13,"id":655}]}]}
{"op":"mcm","clk":"11872407739","pt":1723573315467,"mc":[{"id":"1.231705583","rc":[{"batb":[[0,2.44,4]],"ltp":2.44,"tv":52.13,"id":655}]}]}
{"op":"mcm","clk":"11872408139","pt":1723573318029,"mc":[{"id":"1.231705583","rc":[{"batb":[[0,2.44,10]],"ltp":2.44,"tv":52.13,"id":655}]}]}
{"op":"mcm","clk":"11872408666","pt":1723573321318,"mc":[{"id":"1.231705583","rc":[{"batb":[[0,2.42,26.71],[1,1.74,1],[2,1.38,131.58]],"ltp":2.44,"tv":52.13,"id":655}]}]}
{"op":"mcm","clk":"11872408729","pt":1723573321740,"mc":[{"id":"1.231705583","rc":[{"batb":[[0,2.44,4],[1,2.42,26.71],[2,1.74,1]],"ltp":2.44,"tv":52.13,"id":655}]}]}
{"op":"mcm","clk":"11872409072","pt":1723573324256,"mc":[{"id":"1.231705583","rc":[{"batb":[[0,2.42,26.71],[1,1.74,1],[2,1.38,131.58]],"ltp":2.44,"tv":52.13,"id":655}]}]}
{"op":"mcm","clk":"11872409124","pt":1723573324738,"mc":[{"id":"1.231705583","rc":[{"batb":[[0,2.44,10],[1,2.42,26.71],[2,1.74,1]],"ltp":2.44,"tv":52.13,"id":655}]}]}
{"op":"mcm","clk":"11872409623","pt":1723573328361,"mc":[{"id":"1.231705583","rc":[{"batb":[[0,2.42,26.71],[1,1.74,1],[2,1.38,131.58]],"ltp":2.44,"tv":52.13,"id":655}]}]}
{"op":"mcm","clk":"11872409652","pt":1723573328566,"mc":[{"id":"1.231705583","rc":[{"batb":[[0,2.44,4],[1,2.42,26.71],[2,1.74,1]],"ltp":2.44,"tv":52.13,"id":655}]}]}
{"op":"mcm","clk":"11872410060","pt":1723573331327,"mc":[{"id":"1.231705583","rc":[{"batb":[[0,2.44,10]],"ltp":2.44,"tv":52.13,"id":655}]}]}
{"op":"mcm","clk":"11872410550","pt":1723573334939,"mc":[{"id":"1.231705583","rc":[{"batb":[[0,2.44,4]],"ltp":2.44,"tv":52.13,"id":655}]}]}
{"op":"mcm","clk":"11872410856","pt":1723573337243,"mc":[{"id":"1.231705583","rc":[{"batb":[[0,2.42,26.71],[1,1.74,1],[2,1.38,131.58]],"ltp":2.44,"tv":52.13,"id":655}]}]}
{"op":"mcm","clk":"11872410910","pt":1723573337669,"mc":[{"id":"1.231705583","rc":[{"batb":[[0,2.44,10],[1,2.42,26.71],[2,1.74,1]],"ltp":2.44,"tv":52.13,"id":655}]}]}
{"op":"mcm","clk":"11872411436","pt":1723573341234,"mc":[{"id":"1.231705583","rc":[{"batb":[[0,2.44,4]],"ltp":2.44,"tv":52.13,"id":655}]}]}
{"op":"mcm","clk":"11872411785","pt":1723573343896,"mc":[{"id":"1.231705583","rc":[{"batb":[[0,2.44,10]],"ltp":2.44,"tv":52.13,"id":655}]}]}
{"op":"mcm","clk":"11872412224","pt":1723573347293,"mc":[{"id":"1.231705583","rc":[{"batb":[[0,2.44,4]],"ltp":2.44,"tv":52.13,"id":655}]}]}
{"op":"mcm","clk":"11872412567","pt":1723573349798,"mc":[{"id":"1.231705583","rc":[{"batb":[[0,2.44,10]],"ltp":2.44,"tv":52.13,"id":655}]}]}
{"op":"mcm","clk":"11872413051","pt":1723573353089,"mc":[{"id":"1.231705583","rc":[{"batb":[[0,2.44,4]],"ltp":2.44,"tv":52.13,"id":655}]}]}
{"op":"mcm","clk":"11872413403","pt":1723573355417,"mc":[{"id":"1.231705583","rc":[{"batb":[[0,2.42,26.71],[1,1.74,1],[2,1.38,131.58]],"ltp":2.44,"tv":52.13,"id":655}]}]}
{"op":"mcm","clk":"11872413463","pt":1723573355815,"mc":[{"id":"1.231705583","rc":[{"batb":[[0,2.44,10],[1,2.42,26.71],[2,1.74,1]],"ltp":2.44,"tv":52.13,"id":655}]}]}
{"op":"mcm","clk":"11872414022","pt":1723573359484,"mc":[{"id":"1.231705583","rc":[{"batb":[[0,2.42,26.71],[1,1.74,1],[2,1.38,131.58]],"ltp":2.44,"tv":52.13,"id":655}]}]}
{"op":"mcm","clk":"11872414064","pt":1723573359811,"mc":[{"id":"1.231705583","rc":[{"batb":[[0,2.44,4],[1,2.42,26.71],[2,1.74,1]],"ltp":2.44,"tv":52.13,"id":655}]}]}
{"op":"mcm","clk":"11872414400","pt":1723573362353,"mc":[{"id":"1.231705583","rc":[{"batb":[[0,2.44,10]],"ltp":2.44,"tv":52.13,"id":655}]}]}
{"op":"mcm","clk":"11872414913","pt":1723573365791,"mc":[{"id":"1.231705583","rc":[{"batb":[[0,2.44,4]],"ltp":2.44,"tv":52.13,"id":655}]}]}
{"op":"mcm","clk":"11872415330","pt":1723573368674,"mc":[{"id":"1.231705583","rc":[{"batb":[[0,2.44,10]],"ltp":2.44,"tv":52.13,"id":655}]}]}
{"op":"mcm","clk":"11872415824","pt":1723573372106,"mc":[{"id":"1.231705583","rc":[{"batb":[[0,2.44,4]],"ltp":2.44,"tv":52.13,"id":655}]}]}
{"op":"mcm","clk":"11872416152","pt":1723573374510,"mc":[{"id":"1.231705583","rc":[{"batb":[[0,2.42,26.71],[1,1.74,1],[2,1.38,131.58]],"ltp":2.44,"tv":52.13,"id":655}]}]}
{"op":"mcm","clk":"11872416169","pt":1723573374614,"mc":[{"id":"1.231705583","rc":[{"batb":[[0,2.44,10],[1,2.42,26.71],[2,1.74,1]],"ltp":2.44,"tv":52.13,"id":655}]}]}
{"op":"mcm","clk":"11872416608","pt":1723573378014,"mc":[{"id":"1.231705583","rc":[{"batb":[[0,2.44,4]],"ltp":2.44,"tv":52.13,"id":655}]}]}
{"op":"mcm","clk":"11872416927","pt":1723573380318,"mc":[{"id":"1.231705583","rc":[{"batb":[[0,2.42,26.71],[1,1.74,1],[2,1.38,131.58]],"ltp":2.44,"tv":52.13,"id":655}]}]}
{"op":"mcm","clk":"11872416994","pt":1723573380797,"mc":[{"id":"1.231705583","rc":[{"batb":[[0,2.44,10],[1,2.42,26.71],[2,1.74,1]],"ltp":2.44,"tv":52.13,"id":655}]}]}
{"op":"mcm","clk":"11872417475","pt":1723573384327,"mc":[{"id":"1.231705583","rc":[{"batb":[[0,2.42,26.71],[1,1.74,1],[2,1.38,131.58]],"ltp":2.44,"tv":52.13,"id":655}]}]}
{"op":"mcm","clk":"11872417548","pt":1723573384801,"mc":[{"id":"1.231705583","rc":[{"batb":[[0,2.44,4],[1,2.42,26.71],[2,1.74,1]],"ltp":2.44,"tv":52.13,"id":655}]}]}
{"op":"mcm","clk":"11872417945","pt":1723573387425,"mc":[{"id":"1.231705583","rc":[{"batb":[[0,2.42,26.71],[1,1.74,1],[2,1.38,131.58]],"ltp":2.44,"tv":52.13,"id":655}]}]}
{"op":"mcm","clk":"11872417989","pt":1723573387690,"mc":[{"id":"1.231705583","rc":[{"batb":[[0,2.44,10],[1,2.42,26.71],[2,1.74,1]],"ltp":2.44,"tv":52.13,"id":655}]}]}
{"op":"mcm","clk":"11872418394","pt":1723573391074,"mc":[{"id":"1.231705583","rc":[{"batb":[[0,2.42,26.71],[1,1.74,1],[2,1.38,131.58]],"ltp":2.44,"tv":52.13,"id":655}]}]}
{"op":"mcm","clk":"11872418452","pt":1723573391520,"mc":[{"id":"1.231705583","rc":[{"batb":[[0,2.44,4],[1,2.42,26.71],[2,1.74,1]],"ltp":2.44,"tv":52.13,"id":655}]}]}
{"op":"mcm","clk":"11872418834","pt":1723573394402,"mc":[{"id":"1.231705583","rc":[{"batb":[[0,2.44,10]],"ltp":2.44,"tv":52.13,"id":655}]}]}
{"op":"mcm","clk":"11872419318","pt":1723573398131,"mc":[{"id":"1.231705583","rc":[{"batb":[[0,2.44,4]],"ltp":2.44,"tv":52.13,"id":655}]}]}
{"op":"mcm","clk":"11872419665","pt":1723573400707,"mc":[{"id":"1.231705583","rc":[{"batb":[[0,2.44,10]],"ltp":2.44,"tv":52.13,"id":655}]}]}
{"op":"mcm","clk":"11872420175","pt":1723573404304,"mc":[{"id":"1.231705583","rc":[{"batb":[[0,2.44,4]],"ltp":2.44,"tv":52.13,"id":655}]}]}
{"op":"mcm","clk":"11872420497","pt":1723573406735,"mc":[{"id":"1.231705583","rc":[{"batb":[[0,2.42,26.71],[1,1.74,1],[2,1.38,131.58]],"ltp":2.44,"tv":52.13,"id":655}]}]}
{"op":"mcm","clk":"11872420710","pt":1723573408211,"mc":[{"id":"1.231705583","rc":[{"batb":[[0,2.44,10],[1,2.42,26.71],[2,1.74,1]],"ltp":2.44,"tv":52.13,"id":655}]}]}
{"op":"mcm","clk":"11872420821","pt":1723573409043,"mc":[{"id":"1.231705583","rc":[{"batb":[[0,2.46,4],[1,2.44,10],[2,2.42,26.71]],"ltp":2.44,"tv":52.13,"id":655}]}]}
{"op":"mcm","clk":"11872421270","pt":1723573412032,"mc":[{"id":"1.231705583","rc":[{"batb":[[0,2.42,26.71],[1,1.74,1],[2,1.38,131.58]],"ltp":2.44,"tv":52.13,"id":655}]}]}
{"op":"mcm","clk":"11872438665","pt":1723573529505,"mc":[{"id":"1.231705583","rc":[{"batb":[[0,2.44,12.07],[1,2.42,26.71],[2,1.74,1]],"ltp":2.44,"tv":52.13,"id":655},{"batl":[[0,1.69,17.13],[1,1.7,478.7],[2,1.73,47.98]],"ltp":1.65,"tv":218.2,"id":169}]}]}
{"op":"mcm","clk":"11872438699","pt":1723573529717,"mc":[{"id":"1.231705583","rc":[{"batb":[[0,2.46,14],[1,2.44,12.07],[2,2.42,26.71]],"ltp":2.44,"tv":52.13,"id":655}]}]}
{"op":"mcm","clk":"11872439023","pt":1723573532097,"mc":[{"id":"1.231705583","rc":[{"batb":[[0,2.46,10]],"ltp":2.44,"tv":52.13,"id":655}]}]}
{"op":"mcm","clk":"11872439169","pt":1723573532980,"mc":[{"id":"1.231705583","rc":[{"batb":[[0,2.44,12.07],[1,2.42,26.71],[2,1.74,1]],"ltp":2.44,"tv":52.13,"id":655}]}]}
{"op":"mcm","clk":"11872527572","pt":1723574122661,"mc":[{"id":"1.231705583","rc":[{"batb":[[0,2.46,14],[1,2.44,12.07],[2,2.42,26.71]],"ltp":2.44,"tv":52.13,"id":655}]}]}
{"op":"mcm","clk":"11872527997","pt":1723574125279,"mc":[{"id":"1.231705583","rc":[{"batb":[[0,2.46,10]],"ltp":2.44,"tv":52.13,"id":655}]}]}
{"op":"mcm","clk":"11872528143","pt":1723574126172,"mc":[{"id":"1.231705583","rc":[{"batb":[[0,2.44,12.07],[1,2.42,26.71],[2,1.74,1]],"ltp":2.44,"tv":52.13,"id":655}]}]}
{"op":"mcm","clk":"11872529990","pt":1723574137894,"mc":[{"id":"1.231705583","rc":[{"batb":[[0,2.46,14],[1,2.44,12.07],[2,2.42,26.71]],"ltp":2.44,"tv":52.13,"id":655}]}]}
{"op":"mcm","clk":"11872530616","pt":1723574141822,"mc":[{"id":"1.231705583","rc":[{"batb":[[0,2.44,12.07],[1,2.42,26.71],[2,1.74,1]],"ltp":2.44,"tv":52.13,"id":655}]}]}
{"op":"mcm","clk":"11872566236","pt":1723574352636,"mc":[{"id":"1.231705583","rc":[{"batb":[[0,2.46,14],[1,2.44,12.07],[2,2.42,26.71]],"ltp":2.44,"tv":52.13,"id":655}]}]}
{"op":"mcm","clk":"11872566678","pt":1723574355055,"mc":[{"id":"1.231705583","rc":[{"batb":[[0,2.46,10]],"ltp":2.44,"tv":52.13,"id":655}]}]}
{"op":"mcm","clk":"11872566859","pt":1723574356061,"mc":[{"id":"1.231705583","rc":[{"batb":[[0,2.44,12.07],[1,2.42,26.71],[2,1.74,1]],"ltp":2.44,"tv":52.13,"id":655}]}]}
{"op":"mcm","clk":"11872591043","pt":1723574495692,"mc":[{"id":"1.231705583","rc":[{"batb":[[0,2.46,14],[1,2.44,12.07],[2,2.42,26.71]],"ltp":2.44,"tv":52.13,"id":655}]}]}
{"op":"mcm","clk":"11872591531","pt":1723574498593,"mc":[{"id":"1.231705583","rc":[{"batb":[[0,2.46,10]],"ltp":2.44,"tv":52.13,"id":655}]}]}
{"op":"mcm","clk":"11872591685","pt":1723574499529,"mc":[{"id":"1.231705583","rc":[{"batb":[[0,2.44,12.07],[1,2.42,26.71],[2,1.74,1]],"ltp":2.44,"tv":52.13,"id":655}]}]}
{"op":"mcm","clk":"11872632352","pt":1723574678628,"mc":[{"id":"1.231705583","rc":[{"batb":[[0,2.46,14],[1,2.44,12.07],[2,2.42,26.71]],"ltp":2.44,"tv":52.13,"id":655}]}]}
{"op":"mcm","clk":"11872632824","pt":1723574681725,"mc":[{"id":"1.231705583","rc":[{"batb":[[0,2.46,10]],"ltp":2.44,"tv":52.13,"id":655}]}]}
{"op":"mcm","clk":"11872633002","pt":1723574682729,"mc":[{"id":"1.231705583","rc":[{"batb":[[0,2.44,12.07],[1,2.42,26.71],[2,1.74,1]],"ltp":2.44,"tv":52.13,"id":655}]}]}
{"op":"mcm","clk":"11872650508","pt":1723574767371,"mc":[{"id":"1.231705583","rc":[{"batb":[[0,2.46,14],[1,2.44,12.07],[2,2.42,26.71]],"ltp":2.44,"tv":52.13,"id":655}]}]}
{"op":"mcm","clk":"11872651215","pt":1723574770438,"mc":[{"id":"1.231705583","rc":[{"batb":[[0,2.46,10]],"ltp":2.44,"tv":52.13,"id":655}]}]}
{"op":"mcm","clk":"11872651257","pt":1723574770650,"mc":[{"id":"1.231705583","rc":[{"batb":[[0,2.44,12.07],[1,2.42,26.71],[2,1.74,1]],"ltp":2.44,"tv":52.13,"id":655}]}]}
{"op":"mcm","clk":"11872651761","pt":1723574772960,"mc":[{"id":"1.231705583","rc":[{"batb":[[0,2.46,14],[1,2.44,12.07],[2,2.42,26.71]],"ltp":2.44,"tv":52.13,"id":655}]}]}
{"op":"mcm","clk":"11872652447","pt":1723574775865,"mc":[{"id":"1.231705583","rc":[{"batb":[[0,2.46,10]],"ltp":2.44,"tv":52.13,"id":655}]}]}
{"op":"mcm","clk":"11872652598","pt":1723574776557,"mc":[{"id":"1.231705583","rc":[{"batb":[[0,2.44,12.07],[1,2.42,26.71],[2,1.74,1]],"ltp":2.44,"tv":52.13,"id":655}]}]}
{"op":"mcm","clk":"11872677196","pt":1723574891002,"mc":[{"id":"1.231705583","rc":[{"batb":[[0,2.46,14],[1,2.44,12.07],[2,2.42,26.71]],"ltp":2.44,"tv":52.13,"id":655}]}]}
{"op":"mcm","clk":"11872677810","pt":1723574894030,"mc":[{"id":"1.231705583","rc":[{"batb":[[0,2.46,10]],"ltp":2.44,"tv":52.13,"id":655}]}]}
{"op":"mcm","clk":"11872678035","pt":1723574895011,"mc":[{"id":"1.231705583","rc":[{"batb":[[0,2.44,12.07],[1,2.42,26.71],[2,1.74,1]],"ltp":2.44,"tv":52.13,"id":655}]}]}
{"op":"mcm","clk":"11872688399","pt":1723574943681,"mc":[{"id":"1.231705583","rc":[{"batb":[[0,2.46,14],[1,2.44,12.07],[2,2.42,26.71]],"ltp":2.44,"tv":52.13,"id":655}]}]}
{"op":"mcm","clk":"11872688970","pt":1723574946415,"mc":[{"id":"1.231705583","rc":[{"batb":[[0,2.46,10]],"ltp":2.44,"tv":52.13,"id":655}]}]}
{"op":"mcm","clk":"11872689192","pt":1723574947433,"mc":[{"id":"1.231705583","rc":[{"batb":[[0,2.44,12.07],[1,2.42,26.71],[2,1.74,1]],"ltp":2.44,"tv":52.13,"id":655}]}]}
{"op":"mcm","clk":"11872725310","pt":1723575141052,"mc":[{"id":"1.231705583","rc":[{"batb":[[0,2.46,14],[1,2.44,12.07],[2,2.42,26.71]],"ltp":2.44,"tv":52.13,"id":655}]}]}
{"op":"mcm","clk":"11872726005","pt":1723575144437,"mc":[{"id":"1.231705583","rc":[{"batb":[[0,2.46,10]],"ltp":2.44,"tv":52.13,"id":655}]}]}
{"op":"mcm","clk":"11872726207","pt":1723575145523,"mc":[{"id":"1.231705583","rc":[{"batb":[[0,2.44,12.07],[1,2.42,26.71],[2,1.74,1]],"ltp":2.44,"tv":52.13,"id":655}]}]}
{"op":"mcm","clk":"11872726609","pt":1723575147635,"mc":[{"id":"1.231705583","rc":[{"batb":[[0,2.46,4],[1,2.44,12.07],[2,2.42,26.71]],"ltp":2.44,"tv":52.13,"id":655}]}]}
{"op":"mcm","clk":"11872727146","pt":1723575150644,"mc":[{"id":"1.231705583","rc":[{"batb":[[0,2.48,10],[1,2.46,4],[2,2.44,12.07]],"ltp":2.44,"tv":52.13,"id":655}]}]}
{"op":"mcm","clk":"11872727628","pt":1723575153464,"mc":[{"id":"1.231705583","rc":[{"batb":[[1,2.44,12.07],[2,2.42,26.71]],"ltp":2.44,"tv":52.13,"id":655},{"batl":[[0,1.7,478.7],[1,1.73,47.98],[2,1.73,0]],"ltp":1.65,"tv":218.2,"id":169}]}]}
{"op":"mcm","clk":"11872727942","pt":1723575155333,"mc":[{"id":"1.231705583","rc":[{"batb":[[0,2.5,4],[1,2.42,26.71],[2,1.74,1]],"ltp":2.44,"tv":52.13,"id":655}]}]}
{"op":"mcm","clk":"11872728145","pt":1723575156453,"mc":[{"id":"1.231705583","rc":[{"batb":[[1,2.44,12.11],[2,2.42,26.71]],"ltp":2.44,"tv":52.13,"id":655},{"batl":[[0,1.69,17.19],[1,1.7,478.7],[2,1.73,47.98]],"ltp":1.65,"tv":218.2,"id":169}]}]}
{"op":"mcm","clk":"11872728335","pt":1723575157677,"mc":[{"id":"1.231705583","rc":[{"batb":[[0,2.46,10]],"ltp":2.44,"tv":52.13,"id":655}]}]}
{"op":"mcm","clk":"11872728931","pt":1723575161056,"mc":[{"id":"1.231705583","rc":[{"batb":[[0,2.44,12.11],[1,2.42,26.71],[2,1.74,1]],"ltp":2.44,"tv":52.13,"id":655}]}]}
{"op":"mcm","clk":"11872729021","pt":1723575161541,"mc":[{"id":"1.231705583","rc":[{"batb":[[0,2.46,4],[1,2.44,12.11],[2,2.42,26.71]],"ltp":2.44,"tv":52.13,"id":655}]}]}
{"op":"mcm","clk":"11872729487","pt":1723575164250,"mc":[{"id":"1.231705583","rc":[{"batb":[[0,2.44,12.11],[1,2.42,26.71],[2,1.74,1]],"ltp":2.44,"tv":52.13,"id":655}]}]}
{"op":"mcm","clk":"11872729607","pt":1723575164570,"mc":[{"id":"1.231705583","rc":[{"batb":[[0,2.46,10],[1,2.44,12.11],[2,2.42,26.71]],"ltp":2.44,"tv":52.13,"id":655}]}]}
{"op":"mcm","clk":"11872730190","pt":1723575167849,"mc":[{"id":"1.231705583","rc":[{"batb":[[0,2.46,4]],"ltp":2.44,"tv":52.13,"id":655}]}]}
{"op":"mcm","clk":"11872730599","pt":1723575170382,"mc":[{"id":"1.231705583","rc":[{"batb":[[0,2.46,10]],"ltp":2.44,"tv":52.13,"id":655}]}]}
{"op":"mcm","clk":"11872731197","pt":1723575173865,"mc":[{"id":"1.231705583","rc":[{"batb":[[0,2.46,4]],"ltp":2.44,"tv":52.13,"id":655}]}]}
{"op":"mcm","clk":"11872731664","pt":1723575176468,"mc":[{"id":"1.231705583","rc":[{"batb":[[0,2.44,12.11],[1,2.42,26.71],[2,1.74,1]],"ltp":2.44,"tv":52.13,"id":655}]}]}
{"op":"mcm","clk":"11872731755","pt":1723575176982,"mc":[{"id":"1.231705583","rc":[{"batb":[[0,2.46,10],[1,2.44,12.11],[2,2.42,26.71]],"ltp":2.44,"tv":52.13,"id":655}]}]}
{"op":"mcm","clk":"11872732410","pt":1723575180667,"mc":[{"id":"1.231705583","rc":[{"batb":[[0,2.46,4]],"ltp":2.44,"tv":52.13,"id":655}]}]}
{"op":"mcm","clk":"11872732938","pt":1723575183488,"mc":[{"id":"1.231705583","rc":[{"batb":[[0,2.46,10]],"ltp":2.44,"tv":52.13,"id":655}]}]}
{"op":"mcm","clk":"11872733606","pt":1723575186975,"mc":[{"id":"1.231705583","rc":[{"batb":[[0,2.46,4]],"ltp":2.44,"tv":52.13,"id":655}]}]}
{"op":"mcm","clk":"11872734050","pt":1723575189481,"mc":[{"id":"1.231705583","rc":[{"batb":[[0,2.44,12.11],[1,2.42,26.71],[2,1.74,1]],"ltp":2.44,"tv":52.13,"id":655}]}]}
{"op":"mcm","clk":"11872734122","pt":1723575189895,"mc":[{"id":"1.231705583","rc":[{"batb":[[0,2.46,10],[1,2.44,12.11],[2,2.42,26.71]],"ltp":2.44,"tv":52.13,"id":655}]}]}
{"op":"mcm","clk":"11872734683","pt":1723575193402,"mc":[{"id":"1.231705583","rc":[{"batb":[[0,2.46,4]],"ltp":2.44,"tv":52.13,"id":655}]}]}
{"op":"mcm","clk":"11872735158","pt":1723575196081,"mc":[{"id":"1.231705583","rc":[{"batb":[[0,2.46,10]],"ltp":2.44,"tv":52.13,"id":655}]}]}
{"op":"mcm","clk":"11872735879","pt":1723575199797,"mc":[{"id":"1.231705583","rc":[{"batb":[[0,2.46,4]],"ltp":2.44,"tv":52.13,"id":655}]}]}
{"op":"mcm","clk":"11872736313","pt":1723575202395,"mc":[{"id":"1.231705583","rc":[{"batb":[[0,2.46,10]],"ltp":2.44,"tv":52.13,"id":655}]}]}
{"op":"mcm","clk":"11872736967","pt":1723575206197,"mc":[{"id":"1.231705583","rc":[{"batb":[[0,2.46,4]],"ltp":2.44,"tv":52.13,"id":655}]}]}
{"op":"mcm","clk":"11872737464","pt":1723575208844,"mc":[{"id":"1.231705583","rc":[{"batb":[[0,2.46,10]],"ltp":2.44,"tv":52.13,"id":655}]}]}
{"op":"mcm","clk":"11872738060","pt":1723575212310,"mc":[{"id":"1.231705583","rc":[{"batb":[[0,2.46,4]],"ltp":2.44,"tv":52.13,"id":655}]}]}
{"op":"mcm","clk":"11872738497","pt":1723575214817,"mc":[{"id":"1.231705583","rc":[{"batb":[[0,2.46,10]],"ltp":2.44,"tv":52.13,"id":655}]}]}
{"op":"mcm","clk":"11872739069","pt":1723575218221,"mc":[{"id":"1.231705583","rc":[{"batb":[[0,2.44,12.11],[1,2.42,26.71],[2,1.74,1]],"ltp":2.44,"tv":52.13,"id":655}]}]}
{"op":"mcm","clk":"11872739136","pt":1723575218599,"mc":[{"id":"1.231705583","rc":[{"batb":[[0,2.46,4],[1,2.44,12.11],[2,2.42,26.71]],"ltp":2.44,"tv":52.13,"id":655}]}]}
{"op":"mcm","clk":"11872739560","pt":1723575221201,"mc":[{"id":"1.231705583","rc":[{"batb":[[0,2.46,10]],"ltp":2.44,"tv":52.13,"id":655}]}]}
{"op":"mcm","clk":"11872740152","pt":1723575224942,"mc":[{"id":"1.231705583","rc":[{"batb":[[0,2.46,4]],"ltp":2.44,"tv":52.13,"id":655}]}]}
{"op":"mcm","clk":"11872740583","pt":1723575227321,"mc":[{"id":"1.231705583","rc":[{"batb":[[0,2.44,12.11],[1,2.42,26.71],[2,1.74,1]],"ltp":2.44,"tv":52.13,"id":655}]}]}
{"op":"mcm","clk":"11872740627","pt":1723575227598,"mc":[{"id":"1.231705583","rc":[{"batb":[[0,2.46,10],[1,2.44,12.11],[2,2.42,26.71]],"ltp":2.44,"tv":52.13,"id":655}]}]}
{"op":"mcm","clk":"11872741140","pt":1723575231016,"mc":[{"id":"1.231705583","rc":[{"batb":[[0,2.46,4]],"ltp":2.44,"tv":52.13,"id":655}]}]}
{"op":"mcm","clk":"11872741550","pt":1723575233513,"mc":[{"id":"1.231705583","rc":[{"batb":[[0,2.46,10]],"ltp":2.44,"tv":52.13,"id":655}]}]}
{"op":"mcm","clk":"11872742136","pt":1723575237203,"mc":[{"id":"1.231705583","rc":[{"batb":[[0,2.46,4]],"ltp":2.44,"tv":52.13,"id":655}]}]}
{"op":"mcm","clk":"11872742559","pt":1723575240021,"mc":[{"id":"1.231705583","rc":[{"batb":[[0,2.46,10]],"ltp":2.44,"tv":52.13,"id":655}]}]}
{"op":"mcm","clk":"11872743193","pt":1723575243853,"mc":[{"id":"1.231705583","rc":[{"batb":[[0,2.46,4]],"ltp":2.44,"tv":52.13,"id":655}]}]}
{"op":"mcm","clk":"11872743702","pt":1723575246418,"mc":[{"id":"1.231705583","rc":[{"batb":[[0,2.46,10]],"ltp":2.44,"tv":52.13,"id":655}]}]}
{"op":"mcm","clk":"11872744315","pt":1723575250060,"mc":[{"id":"1.231705583","rc":[{"batb":[[0,2.46,4]],"ltp":2.44,"tv":52.13,"id":655}]}]}
{"op":"mcm","clk":"11872744696","pt":1723575252447,"mc":[{"id":"1.231705583","rc":[{"batb":[[0,2.44,12.11],[1,2.42,26.71],[2,1.74,1]],"ltp":2.44,"tv":52.13,"id":655}]}]}
{"op":"mcm","clk":"11872744744","pt":1723575252722,"mc":[{"id":"1.231705583","rc":[{"batb":[[0,2.46,10],[1,2.44,12.11],[2,2.42,26.71]],"ltp":2.44,"tv":52.13,"id":655}]}]}
{"op":"mcm","clk":"11872745403","pt":1723575256242,"mc":[{"id":"1.231705583","rc":[{"batb":[[0,2.44,12.11],[1,2.42,26.71],[2,1.74,1]],"ltp":2.44,"tv":52.13,"id":655}]}]}
{"op":"mcm","clk":"11872745457","pt":1723575256560,"mc":[{"id":"1.231705583","rc":[{"batb":[[0,2.46,4],[1,2.44,12.11],[2,2.42,26.71]],"ltp":2.44,"tv":52.13,"id":655}]}]}
{"op":"mcm","clk":"11872745921","pt":1723575259045,"mc":[{"id":"1.231705583","rc":[{"batb":[[0,2.46,10]],"ltp":2.44,"tv":52.13,"id":655}]}]}
{"op":"mcm","clk":"11872746638","pt":1723575262756,"mc":[{"id":"1.231705583","rc":[{"batb":[[0,2.46,4]],"ltp":2.44,"tv":52.13,"id":655}]}]}
{"op":"mcm","clk":"11872747039","pt":1723575265256,"mc":[{"id":"1.231705583","rc":[{"batb":[[0,2.44,12.11],[1,2.42,26.71],[2,1.74,1]],"ltp":2.44,"tv":52.13,"id":655}]}]}
{"op":"mcm","clk":"11872747115","pt":1723575265650,"mc":[{"id":"1.231705583","rc":[{"batb":[[0,2.46,10],[1,2.44,12.11],[2,2.42,26.71]],"ltp":2.44,"tv":52.13,"id":655}]}]}
{"op":"mcm","clk":"11872747780","pt":1723575269355,"mc":[{"id":"1.231705583","rc":[{"batb":[[0,2.46,4]],"ltp":2.44,"tv":52.13,"id":655}]}]}
{"op":"mcm","clk":"11872748231","pt":1723575271957,"mc":[{"id":"1.231705583","rc":[{"batb":[[0,2.46,10]],"ltp":2.44,"tv":52.13,"id":655}]}]}
{"op":"mcm","clk":"11872748813","pt":1723575275280,"mc":[{"id":"1.231705583","rc":[{"batb":[[0,2.44,12.11],[1,2.42,26.71],[2,1.74,1]],"ltp":2.44,"tv":52.13,"id":655}]}]}
{"op":"mcm","clk":"11872748868","pt":1723575275547,"mc":[{"id":"1.231705583","rc":[{"batb":[[0,2.46,4],[1,2.44,12.11],[2,2.42,26.71]],"ltp":2.44,"tv":52.13,"id":655}]}]}
{"op":"mcm","clk":"11872749407","pt":1723575278472,"mc":[{"id":"1.231705583","rc":[{"batb":[[0,2.46,10]],"ltp":2.44,"tv":52.13,"id":655}]}]}
{"op":"mcm","clk":"11872750053","pt":1723575282266,"mc":[{"id":"1.231705583","rc":[{"batb":[[0,2.46,4]],"ltp":2.44,"tv":52.13,"id":655}]}]}
{"op":"mcm","clk":"11872750562","pt":1723575285181,"mc":[{"id":"1.231705583","rc":[{"batb":[[0,2.46,10]],"ltp":2.44,"tv":52.13,"id":655}]}]}
{"op":"mcm","clk":"11872751176","pt":1723575288475,"mc":[{"id":"1.231705583","rc":[{"batb":[[0,2.44,12.11],[1,2.42,26.71],[2,1.74,1]],"ltp":2.44,"tv":52.13,"id":655}]}]}
{"op":"mcm","clk":"11872751259","pt":1723575288888,"mc":[{"id":"1.231705583","rc":[{"batb":[[0,2.46,4],[1,2.44,12.11],[2,2.42,26.71]],"ltp":2.44,"tv":52.13,"id":655}]}]}
{"op":"mcm","clk":"11872751745","pt":1723575291386,"mc":[{"id":"1.231705583","rc":[{"batb":[[0,2.44,12.11],[1,2.42,26.71],[2,1.74,1]],"ltp":2.44,"tv":52.13,"id":655}]}]}
{"op":"mcm","clk":"11872751802","pt":1723575291708,"mc":[{"id":"1.231705583","rc":[{"batb":[[0,2.46,10],[1,2.44,12.11],[2,2.42,26.71]],"ltp":2.44,"tv":52.13,"id":655}]}]}
{"op":"mcm","clk":"11872752445","pt":1723575295276,"mc":[{"id":"1.231705583","rc":[{"batb":[[0,2.46,4]],"ltp":2.44,"tv":52.13,"id":655}]}]}
{"op":"mcm","clk":"11872752915","pt":1723575297774,"mc":[{"id":"1.231705583","rc":[{"batb":[[0,2.46,10]],"ltp":2.44,"tv":52.13,"id":655}]}]}
{"op":"mcm","clk":"11872753605","pt":1723575301496,"mc":[{"id":"1.231705583","rc":[{"batb":[[0,2.46,4]],"ltp":2.44,"tv":52.13,"id":655}]}]}
{"op":"mcm","clk":"11872754113","pt":1723575304115,"mc":[{"id":"1.231705583","rc":[{"batb":[[0,2.44,12.11],[1,2.42,26.71],[2,1.74,1]],"ltp":2.44,"tv":52.13,"id":655}]}]}
{"op":"mcm","clk":"11872754282","pt":1723575305010,"mc":[{"id":"1.231705583","rc":[{"batb":[[0,2.46,10],[1,2.44,12.11],[2,2.42,26.71]],"ltp":2.44,"tv":52.13,"id":655}]}]}
{"op":"mcm","clk":"11872755041","pt":1723575308500,"mc":[{"id":"1.231705583","rc":[{"batb":[[0,2.44,12.11],[1,2.42,26.71],[2,1.74,1]],"ltp":2.44,"tv":52.13,"id":655}]}]}
{"op":"mcm","clk":"11872755100","pt":1723575308816,"mc":[{"id":"1.231705583","rc":[{"batb":[[0,2.46,4],[1,2.44,12.11],[2,2.42,26.71]],"ltp":2.44,"tv":52.13,"id":655}]}]}
{"op":"mcm","clk":"11872755579","pt":1723575311375,"mc":[{"id":"1.231705583","rc":[{"batb":[[0,2.46,10]],"ltp":2.44,"tv":52.13,"id":655}]}]}
{"op":"mcm","clk":"11872756233","pt":1723575314897,"mc":[{"id":"1.231705583","rc":[{"batb":[[0,2.46,4]],"ltp":2.44,"tv":52.13,"id":655}]}]}
{"op":"mcm","clk":"11872756676","pt":1723575317509,"mc":[{"id":"1.231705583","rc":[{"batb":[[0,2.46,10]],"ltp":2.44,"tv":52.13,"id":655}]}]}
{"op":"mcm","clk":"11872757344","pt":1723575321089,"mc":[{"id":"1.231705583","rc":[{"batb":[[0,2.46,4]],"ltp":2.44,"tv":52.13,"id":655}]}]}
{"op":"mcm","clk":"11872757832","pt":1723575323625,"mc":[{"id":"1.231705583","rc":[{"batb":[[0,2.46,10]],"ltp":2.44,"tv":52.13,"id":655}]}]}
{"op":"mcm","clk":"11872758476","pt":1723575327236,"mc":[{"id":"1.231705583","rc":[{"batb":[[0,2.46,4]],"ltp":2.44,"tv":52.13,"id":655}]}]}
{"op":"mcm","clk":"11872758972","pt":1723575329946,"mc":[{"id":"1.231705583","rc":[{"batb":[[0,2.46,10]],"ltp":2.44,"tv":52.13,"id":655}]}]}
{"op":"mcm","clk":"11872759605","pt":1723575333229,"mc":[{"id":"1.231705583","rc":[{"batb":[[0,2.44,12.11],[1,2.42,26.71],[2,1.74,1]],"ltp":2.44,"tv":52.13,"id":655}]}]}
{"op":"mcm","clk":"11872759640","pt":1723575333530,"mc":[{"id":"1.231705583","rc":[{"batb":[[0,2.46,4],[1,2.44,12.11],[2,2.42,26.71]],"ltp":2.44,"tv":52.13,"id":655}]}]}
{"op":"mcm","clk":"11872760103","pt":1723575336150,"mc":[{"id":"1.231705583","rc":[{"batb":[[0,2.46,10]],"ltp":2.44,"tv":52.13,"id":655}]}]}
{"op":"mcm","clk":"11872760683","pt":1723575339859,"mc":[{"id":"1.231705583","rc":[{"batb":[[0,2.46,4]],"ltp":2.44,"tv":52.13,"id":655}]}]}
{"op":"mcm","clk":"11872761198","pt":1723575342868,"mc":[{"id":"1.231705583","rc":[{"batb":[[0,2.46,10]],"ltp":2.44,"tv":52.13,"id":655}]}]}
{"op":"mcm","clk":"11872761873","pt":1723575346756,"mc":[{"id":"1.231705583","rc":[{"batb":[[0,2.46,4]],"ltp":2.44,"tv":52.13,"id":655}]}]}
{"op":"mcm","clk":"11872762312","pt":1723575349359,"mc":[{"id":"1.231705583","rc":[{"batb":[[0,2.46,10]],"ltp":2.44,"tv":52.13,"id":655}]}]}
{"op":"mcm","clk":"11872762829","pt":1723575352763,"mc":[{"id":"1.231705583","rc":[{"batb":[[0,2.46,4]],"ltp":2.44,"tv":52.13,"id":655}]}]}
{"op":"mcm","clk":"11872763230","pt":1723575355335,"mc":[{"id":"1.231705583","rc":[{"batb":[[0,2.46,10]],"ltp":2.44,"tv":52.13,"id":655}]}]}
{"op":"mcm","clk":"11872763860","pt":1723575359246,"mc":[{"id":"1.231705583","rc":[{"batb":[[0,2.46,4]],"ltp":2.44,"tv":52.13,"id":655}]}]}
{"op":"mcm","clk":"11872764295","pt":1723575362059,"mc":[{"id":"1.231705583","rc":[{"batb":[[0,2.46,10]],"ltp":2.44,"tv":52.13,"id":655}]}]}
{"op":"mcm","clk":"11872764933","pt":1723575365782,"mc":[{"id":"1.231705583","rc":[{"batb":[[0,2.46,4]],"ltp":2.44,"tv":52.13,"id":655}]}]}
{"op":"mcm","clk":"11872765333","pt":1723575368254,"mc":[{"id":"1.231705583","rc":[{"batb":[[0,2.44,12.11],[1,2.42,26.71],[2,1.74,1]],"ltp":2.44,"tv":52.13,"id":655}]}]}
{"op":"mcm","clk":"11872765381","pt":1723575368565,"mc":[{"id":"1.231705583","rc":[{"batb":[[0,2.46,10],[1,2.44,12.11],[2,2.42,26.71]],"ltp":2.44,"tv":52.13,"id":655}]}]}
{"op":"mcm","clk":"11872765998","pt":1723575372382,"mc":[{"id":"1.231705583","rc":[{"batb":[[0,2.46,4]],"ltp":2.44,"tv":52.13,"id":655}]}]}
{"op":"mcm","clk":"11872766458","pt":1723575375167,"mc":[{"id":"1.231705583","rc":[{"batb":[[0,2.46,10]],"ltp":2.44,"tv":52.13,"id":655}]}]}
{"op":"mcm","clk":"11872767029","pt":1723575378461,"mc":[{"id":"1.231705583","rc":[{"batb":[[0,2.44,12.11],[1,2.42,26.71],[2,1.74,1]],"ltp":2.44,"tv":52.13,"id":655}]}]}
{"op":"mcm","clk":"11872767062","pt":1723575378676,"mc":[{"id":"1.231705583","rc":[{"batb":[[0,2.46,4],[1,2.44,12.11],[2,2.42,26.71]],"ltp":2.44,"tv":52.13,"id":655}]}]}
{"op":"mcm","clk":"11872767518","pt":1723575381499,"mc":[{"id":"1.231705583","rc":[{"batb":[[0,2.44,12.11],[1,2.42,26.71],[2,1.74,1]],"ltp":2.44,"tv":52.13,"id":655}]}]}
{"op":"mcm","clk":"11872767545","pt":1723575381663,"mc":[{"id":"1.231705583","rc":[{"batb":[[0,2.46,10],[1,2.44,12.11],[2,2.42,26.71]],"ltp":2.44,"tv":52.13,"id":655}]}]}
{"op":"mcm","clk":"11872768083","pt":1723575385309,"mc":[{"id":"1.231705583","rc":[{"batb":[[0,2.46,4]],"ltp":2.44,"tv":52.13,"id":655}]}]}
{"op":"mcm","clk":"11872768503","pt":1723575388111,"mc":[{"id":"1.231705583","rc":[{"batb":[[0,2.46,10]],"ltp":2.44,"tv":52.13,"id":655}]}]}
{"op":"mcm","clk":"11872769040","pt":1723575391504,"mc":[{"id":"1.231705583","rc":[{"batb":[[0,2.44,12.11],[1,2.42,26.71],[2,1.74,1]],"ltp":2.44,"tv":52.13,"id":655}]}]}
{"op":"mcm","clk":"11872769053","pt":1723575391611,"mc":[{"id":"1.231705583","rc":[{"batb":[[0,2.46,4],[1,2.44,12.11],[2,2.42,26.71]],"ltp":2.44,"tv":52.13,"id":655}]}]}
{"op":"mcm","clk":"11872769553","pt":1723575394386,"mc":[{"id":"1.231705583","rc":[{"batb":[[0,2.46,10]],"ltp":2.44,"tv":52.13,"id":655}]}]}
{"op":"mcm","clk":"11872770160","pt":1723575398415,"mc":[{"id":"1.231705583","rc":[{"batb":[[0,2.46,4]],"ltp":2.44,"tv":52.13,"id":655}]}]}
{"op":"mcm","clk":"11872770528","pt":1723575401092,"mc":[{"id":"1.231705583","rc":[{"batb":[[0,2.46,10]],"ltp":2.44,"tv":52.13,"id":655}]}]}
{"op":"mcm","clk":"11872771133","pt":1723575405213,"mc":[{"id":"1.231705583","rc":[{"batb":[[0,2.46,4]],"ltp":2.44,"tv":52.13,"id":655}]}]}
{"op":"mcm","clk":"11872771540","pt":1723575407992,"mc":[{"id":"1.231705583","rc":[{"batb":[[0,2.46,10]],"ltp":2.44,"tv":52.13,"id":655}]}]}
{"op":"mcm","clk":"11872772022","pt":1723575411509,"mc":[{"id":"1.231705583","rc":[{"batb":[[0,2.44,12.11],[1,2.42,26.71],[2,1.74,1]],"ltp":2.44,"tv":52.13,"id":655}]}]}
{"op":"mcm","clk":"11872772066","pt":1723575411820,"mc":[{"id":"1.231705583","rc":[{"batb":[[0,2.46,4],[1,2.44,12.11],[2,2.42,26.71]],"ltp":2.44,"tv":52.13,"id":655}]}]}
{"op":"mcm","clk":"11872772436","pt":1723575414228,"mc":[{"id":"1.231705583","rc":[{"batb":[[0,2.44,12.11],[1,2.42,26.71],[2,1.74,1]],"ltp":2.44,"tv":52.13,"id":655}]}]}
{"op":"mcm","clk":"11872772503","pt":1723575414601,"mc":[{"id":"1.231705583","rc":[{"batb":[[0,2.46,10],[1,2.44,12.11],[2,2.42,26.71]],"ltp":2.44,"tv":52.13,"id":655}]}]}
{"op":"mcm","clk":"11872772985","pt":1723575418381,"mc":[{"id":"1.231705583","rc":[{"batb":[[0,2.46,4]],"ltp":2.44,"tv":52.13,"id":655}]}]}
{"op":"mcm","clk":"11872773396","pt":1723575421010,"mc":[{"id":"1.231705583","rc":[{"batb":[[0,2.46,10]],"ltp":2.44,"tv":52.13,"id":655}]}]}
{"op":"mcm","clk":"11872773911","pt":1723575424426,"mc":[{"id":"1.231705583","rc":[{"batb":[[0,2.44,12.11],[1,2.42,26.71],[2,1.74,1]],"ltp":2.44,"tv":52.13,"id":655}]}]}
{"op":"mcm","clk":"11872773959","pt":1723575424717,"mc":[{"id":"1.231705583","rc":[{"batb":[[0,2.46,4],[1,2.44,12.11],[2,2.42,26.71]],"ltp":2.44,"tv":52.13,"id":655}]}]}
{"op":"mcm","clk":"11872774348","pt":1723575427403,"mc":[{"id":"1.231705583","rc":[{"batb":[[0,2.46,10]],"ltp":2.44,"tv":52.13,"id":655}]}]}
{"op":"mcm","clk":"11872774889","pt":1723575430811,"mc":[{"id":"1.231705583","rc":[{"batb":[[0,2.46,4]],"ltp":2.44,"tv":52.13,"id":655}]}]}
{"op":"mcm","clk":"11872775307","pt":1723575433415,"mc":[{"id":"1.231705583","rc":[{"batb":[[0,2.46,10]],"ltp":2.44,"tv":52.13,"id":655}]}]}
{"op":"mcm","clk":"11872775940","pt":1723575437442,"mc":[{"id":"1.231705583","rc":[{"batb":[[0,2.46,4]],"ltp":2.44,"tv":52.13,"id":655}]}]}
{"op":"mcm","clk":"11872776350","pt":1723575440145,"mc":[{"id":"1.231705583","rc":[{"batb":[[0,2.46,10]],"ltp":2.44,"tv":52.13,"id":655}]}]}
{"op":"mcm","clk":"11872776956","pt":1723575443934,"mc":[{"id":"1.231705583","rc":[{"batb":[[0,2.46,4]],"ltp":2.44,"tv":52.13,"id":655}]}]}
{"op":"mcm","clk":"11872777303","pt":1723575446268,"mc":[{"id":"1.231705583","rc":[{"batb":[[0,2.44,12.11],[1,2.42,26.71],[2,1.74,1]],"ltp":2.44,"tv":52.13,"id":655}]}]}
{"op":"mcm","clk":"11872777347","pt":1723575446855,"mc":[{"id":"1.231705583","rc":[{"batb":[[0,2.46,10],[1,2.44,12.11],[2,2.42,26.71]],"ltp":2.44,"tv":52.13,"id":655}]}]}
{"op":"mcm","clk":"11872777944","pt":1723575450257,"mc":[{"id":"1.231705583","rc":[{"batb":[[0,2.46,4]],"ltp":2.44,"tv":52.13,"id":655}]}]}
{"op":"mcm","clk":"11872778410","pt":1723575453272,"mc":[{"id":"1.231705583","rc":[{"batb":[[0,2.46,10]],"ltp":2.44,"tv":52.13,"id":655}]}]}
{"op":"mcm","clk":"11872778969","pt":1723575456954,"mc":[{"id":"1.231705583","rc":[{"batb":[[0,2.46,4]],"ltp":2.44,"tv":52.13,"id":655}]}]}
{"op":"mcm","clk":"11872779326","pt":1723575459388,"mc":[{"id":"1.231705583","rc":[{"batb":[[0,2.44,12.11],[1,2.42,26.71],[2,1.74,1]],"ltp":2.44,"tv":52.13,"id":655}]}]}
{"op":"mcm","clk":"11872779384","pt":1723575459708,"mc":[{"id":"1.231705583","rc":[{"batb":[[0,2.46,10],[1,2.44,12.11],[2,2.42,26.71]],"ltp":2.44,"tv":52.13,"id":655}]}]}
{"op":"mcm","clk":"11872779954","pt":1723575463456,"mc":[{"id":"1.231705583","rc":[{"batb":[[0,2.46,4]],"ltp":2.44,"tv":52.13,"id":655}]}]}
{"op":"mcm","clk":"11872780304","pt":1723575466006,"mc":[{"id":"1.231705583","rc":[{"batb":[[0,2.46,10]],"ltp":2.44,"tv":52.13,"id":655}]}]}
{"op":"mcm","clk":"11872780808","pt":1723575469322,"mc":[{"id":"1.231705583","rc":[{"batb":[[0,2.44,12.11],[1,2.42,26.71],[2,1.74,1]],"ltp":2.44,"tv":52.13,"id":655}]}]}
{"op":"mcm","clk":"11872780840","pt":1723575469583,"mc":[{"id":"1.231705583","rc":[{"batb":[[0,2.46,4],[1,2.44,12.11],[2,2.42,26.71]],"ltp":2.44,"tv":52.13,"id":655}]}]}
{"op":"mcm","clk":"11872781237","pt":1723575472398,"mc":[{"id":"1.231705583","rc":[{"batb":[[0,2.46,10]],"ltp":2.44,"tv":52.13,"id":655}]}]}
{"op":"mcm","clk":"11872781509","pt":1723575474105,"mc":[{"id":"1.231705583","rc":[{"batb":[[0,2.48,4],[1,2.46,10],[2,2.44,12.11]],"ltp":2.44,"tv":52.13,"id":655}]}]}
{"op":"mcm","clk":"11872781753","pt":1723575475798,"mc":[{"id":"1.231705583","rc":[{"batb":[[1,2.44,12.11],[2,2.42,26.71]],"ltp":2.44,"tv":52.13,"id":655}]}]}
{"op":"mcm","clk":"11872781900","pt":1723575476813,"mc":[{"id":"1.231705583","rc":[{"batb":[[0,2.44,12.11],[1,2.42,26.71],[2,1.74,1]],"ltp":2.44,"tv":52.13,"id":655}]}]}
{"op":"mcm","clk":"11872785388","pt":1723575502312,"mc":[{"id":"1.231705583","rc":[{"batb":[[0,2.46,14],[1,2.44,12.11],[2,2.42,26.71]],"ltp":2.44,"tv":52.13,"id":655}]}]}
{"op":"mcm","clk":"11872785752","pt":1723575504970,"mc":[{"id":"1.231705583","rc":[{"batb":[[0,2.46,10]],"ltp":2.44,"tv":52.13,"id":655}]}]}
{"op":"mcm","clk":"11872785881","pt":1723575505818,"mc":[{"id":"1.231705583","rc":[{"batb":[[0,2.44,12.11],[1,2.42,26.71],[2,1.74,1]],"ltp":2.44,"tv":52.13,"id":655}]}]}
{"op":"mcm","clk":"11872790328","pt":1723575534667,"mc":[{"id":"1.231705583","rc":[{"batb":[[0,2.46,14],[1,2.44,12.11],[2,2.42,26.71]],"ltp":2.44,"tv":52.13,"id":655}]}]}
{"op":"mcm","clk":"11872790745","pt":1723575537479,"mc":[{"id":"1.231705583","rc":[{"batb":[[0,2.46,10]],"ltp":2.44,"tv":52.13,"id":655}]}]}
{"op":"mcm","clk":"11872790901","pt":1723575538487,"mc":[{"id":"1.231705583","rc":[{"batb":[[0,2.44,12.11],[1,2.42,26.71],[2,1.74,1]],"ltp":2.44,"tv":52.13,"id":655}]}]}
{"op":"mcm","clk":"11872797088","pt":1723575576238,"mc":[{"id":"1.231705583","rc":[{"batb":[[0,2.46,14],[1,2.44,12.11],[2,2.42,26.71]],"ltp":2.44,"tv":52.13,"id":655}]}]}
{"op":"mcm","clk":"11872797489","pt":1723575578816,"mc":[{"id":"1.231705583","rc":[{"batb":[[0,2.46,10]],"ltp":2.44,"tv":52.13,"id":655}]}]}
{"op":"mcm","clk":"11872797637","pt":1723575579740,"mc":[{"id":"1.231705583","rc":[{"batb":[[0,2.44,12.11],[1,2.42,26.71],[2,1.74,1]],"ltp":2.44,"tv":52.13,"id":655}]}]}
{"op":"mcm","clk":"11872799011","pt":1723575589143,"mc":[{"id":"1.231705583","rc":[{"batb":[[0,2.46,14],[1,2.44,12.11],[2,2.42,26.71]],"ltp":2.44,"tv":52.13,"id":655}]}]}
{"op":"mcm","clk":"11872799405","pt":1723575591919,"mc":[{"id":"1.231705583","rc":[{"batb":[[0,2.46,10]],"ltp":2.44,"tv":52.13,"id":655}]}]}
{"op":"mcm","clk":"11872799559","pt":1723575592970,"mc":[{"id":"1.231705583","rc":[{"batb":[[0,2.44,12.11],[1,2.42,26.71],[2,1.74,1]],"ltp":2.44,"tv":52.13,"id":655}]}]}
{"op":"mcm","clk":"11872806899","pt":1723575637614,"mc":[{"id":"1.231705583","rc":[{"batb":[[0,2.46,14],[1,2.44,12.12],[2,2.42,26.71]],"ltp":2.44,"tv":52.13,"id":655},{"trd":[[1.65,33.26]],"batl":[[0,1.69,17.21]],"ltp":1.65,"tv":218.2,"id":169}],"tv":270.33}]}
{"op":"mcm","clk":"11872807432","pt":1723575640497,"mc":[{"id":"1.231705583","rc":[{"batb":[[0,2.46,10]],"ltp":2.44,"tv":52.13,"id":655}]}]}
{"op":"mcm","clk":"11872807554","pt":1723575641341,"mc":[{"id":"1.231705583","rc":[{"batb":[[0,2.44,12.12],[1,2.42,26.71],[2,1.74,1]],"ltp":2.44,"tv":52.13,"id":655}]}]}
{"op":"mcm","clk":"11872810910","pt":1723575661879,"mc":[{"id":"1.231705583","rc":[{"batb":[[0,2.46,14],[1,2.44,12.12],[2,2.42,26.71]],"ltp":2.44,"tv":52.13,"id":655}]}]}
{"op":"mcm","clk":"11872811370","pt":1723575664659,"mc":[{"id":"1.231705583","rc":[{"batb":[[0,2.46,10]],"ltp":2.44,"tv":52.13,"id":655}]}]}
{"op":"mcm","clk":"11872811516","pt":1723575665579,"mc":[{"id":"1.231705583","rc":[{"batb":[[0,2.44,12.12],[1,2.42,26.71],[2,1.74,1]],"ltp":2.44,"tv":52.13,"id":655}]}]}
{"op":"mcm","clk":"11872813445","pt":1723575677595,"mc":[{"id":"1.231705583","rc":[{"batb":[[0,2.46,14],[1,2.44,12.12],[2,2.42,26.71]],"ltp":2.44,"tv":52.13,"id":655}]}]}
{"op":"mcm","clk":"11872813907","pt":1723575680683,"mc":[{"id":"1.231705583","rc":[{"batb":[[0,2.46,10]],"ltp":2.44,"tv":52.13,"id":655}]}]}
{"op":"mcm","clk":"11872814077","pt":1723575681798,"mc":[{"id":"1.231705583","rc":[{"batb":[[0,2.44,12.12],[1,2.42,26.71],[2,1.74,1]],"ltp":2.44,"tv":52.13,"id":655}]}]}
{"op":"mcm","clk":"11872816377","pt":1723575697796,"mc":[{"id":"1.231705583","rc":[{"batb":[[0,2.46,14],[1,2.44,12.12],[2,2.42,26.71]],"ltp":2.44,"tv":52.13,"id":655}]}]}
{"op":"mcm","clk":"11872816818","pt":1723575700832,"mc":[{"id":"1.231705583","rc":[{"batb":[[0,2.46,10]],"ltp":2.44,"tv":52.13,"id":655}]}]}
{"op":"mcm","clk":"11872816932","pt":1723575701741,"mc":[{"id":"1.231705583","rc":[{"batb":[[0,2.44,12.12],[1,2.42,26.71],[2,1.74,1]],"ltp":2.44,"tv":52.13,"id":655}]}]}
{"op":"mcm","clk":"11872817584","pt":1723575706118,"mc":[{"id":"1.231705583","rc":[{"batb":[[0,2.46,14],[1,2.44,12.12],[2,2.42,26.71]],"ltp":2.44,"tv":52.13,"id":655}]}]}
{"op":"mcm","clk":"11872818065","pt":1723575709381,"mc":[{"id":"1.231705583","rc":[{"batb":[[0,2.44,12.12],[1,2.42,26.71],[2,1.74,1]],"ltp":2.44,"tv":52.13,"id":655}]}]}
{"op":"mcm","clk":"11872824437","pt":1723575748722,"mc":[{"id":"1.231705583","rc":[{"batb":[[0,2.46,14],[1,2.44,12.12],[2,2.42,26.71]],"ltp":2.44,"tv":52.13,"id":655}]}]}
{"op":"mcm","clk":"11872824839","pt":1723575751185,"mc":[{"id":"1.231705583","rc":[{"batb":[[0,2.46,10]],"ltp":2.44,"tv":52.13,"id":655}]}]}
{"op":"mcm","clk":"11872825034","pt":1723575752301,"mc":[{"id":"1.231705583","rc":[{"batb":[[0,2.44,12.12],[1,2.42,26.71],[2,1.74,1]],"ltp":2.44,"tv":52.13,"id":655}]}]}
{"op":"mcm","clk":"11872825316","pt":1723575753906,"mc":[{"id":"1.231705583","rc":[{"batb":[[0,2.46,4],[1,2.44,12.12],[2,2.42,26.71]],"ltp":2.44,"tv":52.13,"id":655}]}]}
{"op":"mcm","clk":"11872825671","pt":1723575756288,"mc":[{"id":"1.231705583","rc":[{"batb":[[0,2.48,10]],"ltp":2.44,"tv":52.13,"id":655}]}]}
{"op":"mcm","clk":"11872825811","pt":1723575757191,"mc":[{"id":"1.231705583","rc":[{"batl":[[0,1.7,478.7],[1,1.73,47.98],[2,1.73,0]],"ltp":1.65,"tv":218.2,"id":169}]}]}
{"op":"mcm","clk":"11872826118","pt":1723575759208,"mc":[{"id":"1.231705583","rc":[{"batb":[[0,2.5,4],[1,2.48,10]],"ltp":2.44,"tv":52.13,"id":655}]}]}
{"op":"mcm","clk":"11872826202","pt":1723575759694,"mc":[{"id":"1.231705583","rc":[{"batb":[[1,2.42,26.71],[2,1.74,1]],"ltp":2.44,"tv":52.13,"id":655}]}]}
{"op":"mcm","clk":"11872826574","pt":1723575761492,"mc":[{"id":"1.231705583","rc":[{"batb":[[0,2.44,12.16]],"ltp":2.44,"tv":52.13,"id":655},{"batl":[[0,1.69,17.27],[1,1.7,478.7],[2,1.73,47.98]],"ltp":1.65,"tv":218.2,"id":169}]}]}
{"op":"mcm","clk":"11872827730","pt":1723575768306,"mc":[{"id":"1.231705583","rc":[{"batb":[[0,2.46,14],[1,2.44,12.16],[2,2.42,26.71]],"ltp":2.44,"tv":52.13,"id":655}]}]}
{"op":"mcm","clk":"11872828094","pt":1723575770708,"mc":[{"id":"1.231705583","rc":[{"batb":[[0,2.46,10]],"ltp":2.44,"tv":52.13,"id":655}]}]}
{"op":"mcm","clk":"11872828271","pt":1723575771721,"mc":[{"id":"1.231705583","rc":[{"batb":[[0,2.44,12.16],[1,2.42,26.71],[2,1.74,1]],"ltp":2.44,"tv":52.13,"id":655}]}]}
{"op":"mcm","clk":"11872828837","pt":1723575774825,"mc":[{"id":"1.231705583","rc":[{"batb":[[0,2.46,14],[1,2.44,12.16],[2,2.42,26.71]],"ltp":2.44,"tv":52.13,"id":655}]}]}
{"op":"mcm","clk":"11872829239","pt":1723575777002,"mc":[{"id":"1.231705583","rc":[{"batb":[[0,2.46,10]],"ltp":2.44,"tv":52.13,"id":655}]}]}
{"op":"mcm","clk":"11872829465","pt":1723575778424,"mc":[{"id":"1.231705583","rc":[{"batb":[[0,2.44,12.16],[1,2.42,26.71],[2,1.74,1]],"ltp":2.44,"tv":52.13,"id":655}]}]}
{"op":"mcm","clk":"11872830420","pt":1723575784434,"mc":[{"id":"1.231705583","rc":[{"batb":[[0,2.46,14],[1,2.44,12.16],[2,2.42,26.71]],"ltp":2.44,"tv":52.13,"id":655}]}]}
{"op":"mcm","clk":"11872830804","pt":1723575786723,"mc":[{"id":"1.231705583","rc":[{"batb":[[0,2.46,10]],"ltp":2.44,"tv":52.13,"id":655}]}]}
{"op":"mcm","clk":"11872830976","pt":1723575787831,"mc":[{"id":"1.231705583","rc":[{"batb":[[0,2.44,12.16],[1,2.42,26.71],[2,1.74,1]],"ltp":2.44,"tv":52.13,"id":655}]}]}
{"op":"mcm","clk":"11872833727","pt":1723575803654,"mc":[{"id":"1.231705583","rc":[{"batb":[[0,2.46,14],[1,2.44,12.16],[2,2.42,26.71]],"ltp":2.44,"tv":52.13,"id":655}]}]}
{"op":"mcm","clk":"11872834266","pt":1723575806637,"mc":[{"id":"1.231705583","rc":[{"batb":[[0,2.46,10]],"ltp":2.44,"tv":52.13,"id":655}]}]}
{"op":"mcm","clk":"11872834464","pt":1723575807797,"mc":[{"id":"1.231705583","rc":[{"batb":[[0,2.44,12.16],[1,2.42,26.71],[2,1.74,1]],"ltp":2.44,"tv":52.13,"id":655}]}]}
{"op":"mcm","clk":"11872836692","pt":1723575821477,"mc":[{"id":"1.231705583","rc":[{"batb":[[0,2.46,14],[1,2.44,12.16],[2,2.42,26.71]],"ltp":2.44,"tv":52.13,"id":655}]}]}
{"op":"mcm","clk":"11872837156","pt":1723575824276,"mc":[{"id":"1.231705583","rc":[{"batb":[[0,2.46,10]],"ltp":2.44,"tv":52.13,"id":655}]}]}
{"op":"mcm","clk":"11872837327","pt":1723575825288,"mc":[{"id":"1.231705583","rc":[{"batb":[[0,2.44,12.16],[1,2.42,26.71],[2,1.74,1]],"ltp":2.44,"tv":52.13,"id":655}]}]}
{"op":"mcm","clk":"11872838884","pt":1723575833910,"mc":[{"id":"1.231705583","rc":[{"batb":[[0,2.46,14],[1,2.44,12.16],[2,2.42,26.71]],"ltp":2.44,"tv":52.13,"id":655}]}]}
{"op":"mcm","clk":"11872839306","pt":1723575836294,"mc":[{"id":"1.231705583","rc":[{"batb":[[0,2.46,10]],"ltp":2.44,"tv":52.13,"id":655}]}]}
{"op":"mcm","clk":"11872839458","pt":1723575837202,"mc":[{"id":"1.231705583","rc":[{"batb":[[0,2.44,12.16],[1,2.42,26.71],[2,1.74,1]],"ltp":2.44,"tv":52.13,"id":655}]}]}
{"op":"mcm","clk":"11872843005","pt":1723575858014,"mc":[{"id":"1.231705583","rc":[{"batb":[[0,2.46,14],[1,2.44,12.16],[2,2.42,26.71]],"ltp":2.44,"tv":52.13,"id":655}]}]}
{"op":"mcm","clk":"11872843459","pt":1723575860741,"mc":[{"id":"1.231705583","rc":[{"batb":[[0,2.46,10]],"ltp":2.44,"tv":52.13,"id":655}]}]}
