{"op":"mcm","clk":"11876790360","pt":1723646191241,"mc":[{"id":"1.231812839","marketDefinition":{"bspMarket":false,"turnInPlayEnabled":true,"persistenceEnabled":true,"marketBaseRate":5.0,"eventId":"33494843","eventTypeId":"4","numberOfWinners":1,"bettingType":"ODDS","marketType":"MATCH_ODDS","marketTime":"2024-08-22T10:00:00.000Z","suspendTime":"2024-08-22T10:00:00.000Z","bspReconciled":false,"complete":true,"inPlay":false,"crossMatching":false,"runnersVoidable":false,"numberOfActiveRunners":3,"betDelay":0,"status":"OPEN","runners":[{"status":"ACTIVE","sortPriority":1,"id":3961,"name":"Hampshire"},{"status":"ACTIVE","sortPriority":2,"id":31376,"name":"Essex"},{"status":"ACTIVE","sortPriority":3,"id":60443,"name":"The Draw"}],"regulators":["MR_INT"],"countryCode":"GB","discountAllowed":false,"timezone":"GMT","openDate":"2024-08-22T10:00:00.000Z","version":6074361933,"name":"Match Odds","eventName":"Hampshire v Essex"},"rc":[{"batb":[[0,1.01,20]],"ltp":0.0,"tv":0.0,"id":3961},{"batb":[[0,1.01,20]],"ltp":0.0,"tv":0.0,"id":60443},{"batb":[[0,1.01,20]],"ltp":0.0,"tv":0.0,"id":31376}]}]}
{"op":"mcm","clk":"11876790409","pt":1723646191962,"mc":[{"id":"1.231812839","rc":[{"batb":[[0,1.03,200],[1,1.02,200],[2,1.01,220]],"ltp":0.0,"tv":0.0,"id":3961},{"batb":[[0,1.03,200],[1,1.02,200],[2,1.01,220]],"ltp":0.0,"tv":0.0,"id":60443},{"batb":[[0,1.03,200],[1,1.02,200],[2,1.01,220]],"ltp":0.0,"tv":0.0,"id":31376}]}]}
{"op":"mcm","clk":"11876790545","pt":1723646193769,"mc":[{"id":"1.231812839","marketDefinition":{"bspMarket":false,"turnInPlayEnabled":true,"persistenceEnabled":true,"marketBaseRate":5.0,"eventId":"33494843","eventTypeId":"4","numberOfWinners":1,"bettingType":"ODDS","marketType":"MATCH_ODDS","marketTime":"2024-08-22T10:00:00.000Z","suspendTime":"2024-08-22T10:00:00.000Z","bspReconciled":false,"complete":true,"inPlay":false,"crossMatching":false,"runnersVoidable":false,"numberOfActiveRunners":3,"betDelay":0,"status":"OPEN","runners":[{"status":"ACTIVE","sortPriority":1,"id":3961,"name":"Hampshire"},{"status":"ACTIVE","sortPriority":2,"id":31376,"name":"Essex"},{"status":"ACTIVE","sortPriority":3,"id":60443,"name":"The Draw"}],"regulators":["MR_INT"],"countryCode":"GB","discountAllowed":true,"timezone":"GMT","openDate":"2024-08-22T10:00:00.000Z","version":6074361933,"name":"Match Odds","eventName":"Hampshire v Essex"}}]}
{"op":"mcm","clk":"11877072535","pt":1723649460582,"mc":[{"id":"1.231812839","rc":[{"batb":[[2,1.01,481.27]],"ltp":0.0,"tv":0.0,"id":3961}]}]}
{"op":"mcm","clk":"11877072577","pt":1723649461056,"mc":[{"id":"1.231812839","rc":[{"batb":[[2,1.01,481.27]],"ltp":0.0,"tv":0.0,"id":60443},{"batb":[[2,1.01,481.27]],"ltp":0.0,"tv":0.0,"id":31376}]}]}
{"op":"mcm","clk":"11877712394","pt":1723655575124,"mc":[{"id":"1.231812839","rc":[{"batb":[[2,1.01,480.82]],"ltp":0.0,"tv":0.0,"id":3961},{"batb":[[2,1.01,480.82]],"ltp":0.0,"tv":0.0,"id":60443},{"batb":[[2,1.01,480.82]],"ltp":0.0,"tv":0.0,"id":31376}]}]}
{"op":"mcm","clk":"11877886331","pt":1723657121489,"mc":[{"id":"1.231812839","rc":[{"batb":[[0,1.04,250],[1,1.03,200],[2,1.02,200]],"batl":[[0,95,5],[1,990,5]],"ltp":0.0,"tv":0.0,"id":3961},{"batb":[[0,1.04,250],[1,1.03,200],[2,1.02,200]],"batl":[[0,95,5],[1,990,5]],"ltp":0.0,"tv":0.0,"id":60443},{"batb":[[0,1.04,250],[1,1.03,200],[2,1.02,200]],"batl":[[0,95,5],[1,990,5]],"ltp":0.0,"tv":0.0,"id":31376}]}]}
{"op":"mcm","clk":"11877889985","pt":1723657148524,"mc":[{"id":"1.231812839","marketDefinition":{"bspMarket":false,"turnInPlayEnabled":true,"persistenceEnabled":true,"marketBaseRate":5.0,"eventId":"33494843","eventTypeId":"4","numberOfWinners":1,"bettingType":"ODDS","marketType":"MATCH_ODDS","marketTime":"2024-08-22T10:00:00.000Z","suspendTime":"2024-08-22T10:00:00.000Z","bspReconciled":false,"complete":true,"inPlay":false,"crossMatching":true,"runnersVoidable":false,"numberOfActiveRunners":3,"betDelay":0,"status":"OPEN","runners":[{"status":"ACTIVE","sortPriority":1,"id":3961,"name":"Hampshire"},{"status":"ACTIVE","sortPriority":2,"id":31376,"name":"Essex"},{"status":"ACTIVE","sortPriority":3,"id":60443,"name":"The Draw"}],"regulators":["MR_INT"],"countryCode":"GB","discountAllowed":true,"timezone":"GMT","openDate":"2024-08-22T10:00:00.000Z","version":6074361933,"name":"Match Odds","eventName":"Hampshire v Essex"}}]}
{"op":"mcm","clk":"11878530667","pt":1723662705111,"mc":[{"id":"1.231812839","rc":[{"batb":[[0,1.05,74.5],[1,1.04,250],[2,1.03,200]],"ltp":0.0,"tv":0.0,"id":3961}]}]}
{"op":"mcm","clk":"11878536076","pt":1723662760086,"mc":[{"id":"1.231812839","rc":[{"batb":[[0,1.05,74.5],[1,1.04,250],[2,1.03,200]],"ltp":0.0,"tv":0.0,"id":31376}]}]}
{"op":"mcm","clk":"11878537092","pt":1723662770286,"mc":[{"id":"1.231812839","rc":[{"batb":[[0,1.05,74.5],[1,1.04,250],[2,1.03,200]],"ltp":0.0,"tv":0.0,"id":60443}]}]}
{"op":"mcm","clk":"11878870350","pt":1723666375135,"mc":[{"id":"1.231812839","rc":[{"batb":[[0,1.05,74.49]],"ltp":0.0,"tv":0.0,"id":3961},{"batb":[[0,1.05,74.49]],"ltp":0.0,"tv":0.0,"id":60443},{"batb":[[0,1.05,74.49]],"ltp":0.0,"tv":0.0,"id":31376}]}]}
{"op":"mcm","clk":"11879118666","pt":1723671775086,"mc":[{"id":"1.231812839","rc":[{"batb":[[0,1.05,74.47]],"ltp":0.0,"tv":0.0,"id":3961},{"batb":[[0,1.05,74.47]],"ltp":0.0,"tv":0.0,"id":60443},{"batb":[[0,1.05,74.47]],"ltp":0.0,"tv":0.0,"id":31376}]}]}
{"op":"mcm","clk":"11879383867","pt":1723677175100,"mc":[{"id":"1.231812839","rc":[{"batb":[[0,1.05,74.49]],"ltp":0.0,"tv":0.0,"id":3961},{"batb":[[0,1.05,74.49]],"ltp":0.0,"tv":0.0,"id":60443},{"batb":[[0,1.05,74.49]],"ltp":0.0,"tv":0.0,"id":31376}]}]}
{"op":"mcm","clk":"11879745286","pt":1723682575138,"mc":[{"id":"1.231812839","rc":[{"batb":[[0,1.05,74.46]],"ltp":0.0,"tv":0.0,"id":3961},{"batb":[[0,1.05,74.46]],"ltp":0.0,"tv":0.0,"id":60443},{"batb":[[0,1.05,74.46]],"ltp":0.0,"tv":0.0,"id":31376}]}]}
{"op":"mcm","clk":"11879998573","pt":1723687975163,"mc":[{"id":"1.231812839","rc":[{"batb":[[0,1.05,74.44]],"ltp":0.0,"tv":0.0,"id":3961},{"batb":[[0,1.05,74.44]],"ltp":0.0,"tv":0.0,"id":60443},{"batb":[[0,1.05,74.44]],"ltp":0.0,"tv":0.0,"id":31376}]}]}
{"op":"mcm","clk":"11880220612","pt":1723693375188,"mc":[{"id":"1.231812839","rc":[{"batb":[[0,1.05,74.45]],"ltp":0.0,"tv":0.0,"id":3961},{"batb":[[0,1.05,74.45]],"ltp":0.0,"tv":0.0,"id":60443},{"batb":[[0,1.05,74.45]],"ltp":0.0,"tv":0.0,"id":31376}]}]}
{"op":"mcm","clk":"11880463481","pt":1723698775195,"mc":[{"id":"1.231812839","rc":[{"batb":[[0,1.05,74.43]],"ltp":0.0,"tv":0.0,"id":3961},{"batb":[[0,1.05,74.43]],"ltp":0.0,"tv":0.0,"id":60443},{"batb":[[0,1.05,74.43]],"ltp":0.0,"tv":0.0,"id":31376}]}]}
{"op":"mcm","clk":"11880591528","pt":1723701407462,"mc":[{"id":"1.231812839","marketDefinition":{"bspMarket":false,"turnInPlayEnabled":true,"persistenceEnabled":true,"marketBaseRate":5.0,"eventId":"33494843","eventTypeId":"4","numberOfWinners":1,"bettingType":"ODDS","marketType":"MATCH_ODDS","marketTime":"2024-08-22T10:00:00.000Z","suspendTime":"2024-08-22T10:00:00.000Z","bspReconciled":false,"complete":true,"inPlay":false,"crossMatching":true,"runnersVoidable":false,"numberOfActiveRunners":3,"betDelay":0,"status":"OPEN","runners":[{"status":"ACTIVE","sortPriority":1,"id":3961,"name":"Hampshire"},{"status":"ACTIVE","sortPriority":2,"id":31376,"name":"Essex"},{"status":"ACTIVE","sortPriority":3,"id":60443,"name":"The Draw"}],"regulators":["MR_INT"],"countryCode":"GB","discountAllowed":true,"timezone":"GMT","openDate":"2024-08-22T10:00:00.000Z","version":6075395108,"name":"Match Odds","eventName":"Hampshire v Essex"}}]}
{"op":"mcm","clk":"11880658543","pt":1723702843219,"mc":[{"id":"1.231812839","rc":[{"batb":[[0,1.04,250],[1,1.03,200],[2,1.02,200]],"ltp":0.0,"tv":0.0,"id":3961},{"batb":[[0,1.04,250],[1,1.03,200],[2,1.02,200]],"ltp":0.0,"tv":0.0,"id":60443},{"batb":[[0,1.04,250],[1,1.03,200],[2,1.02,200]],"ltp":0.0,"tv":0.0,"id":31376}]}]}
{"op":"mcm","clk":"11881969543","pt":1723723807577,"mc":[{"id":"1.231812839","rc":[{"trd":[[1.04,2]],"batb":[[0,1.04,249]],"ltp":1.04,"tv":2.0,"id":3961}],"tv":2.0}]}
{"op":"mcm","clk":"11882764786","pt":1723733705676,"mc":[{"id":"1.231812839","rc":[{"batl":[[0,95,5.19]],"ltp":0.0,"tv":0.0,"id":60443}]}]}
{"op":"mcm","clk":"11882936455","pt":1723735186110,"mc":[{"id":"1.231812839","rc":[{"batl":[[0,18,1.15],[1,95,5],[2,990,5]],"ltp":0.0,"tv":0.0,"id":60443}]}]}
{"op":"mcm","clk":"11882937496","pt":1723735196123,"mc":[{"id":"1.231812839","rc":[{"batl":[[0,95,5.95]],"ltp":0.0,"tv":0.0,"id":31376}]}]}
{"op":"mcm","clk":"11882938780","pt":1723735207262,"mc":[{"id":"1.231812839","rc":[{"batl":[[0,95,5.95]],"ltp":1.04,"tv":2.0,"id":3961}]}]}
{"op":"mcm","clk":"11882956216","pt":1723735368212,"mc":[{"id":"1.231812839","rc":[{"batb":[[0,1.29,10],[1,1.04,250],[2,1.03,200]],"ltp":0.0,"tv":0.0,"id":31376}]}]}
{"op":"mcm","clk":"11883033196","pt":1723736108947,"mc":[{"id":"1.231812839","rc":[{"batb":[[0,1.03,200],[1,1.02,200],[2,1.01,479.35]],"ltp":0.0,"tv":0.0,"id":60443}]}]}
{"op":"mcm","clk":"11883033359","pt":1723736110449,"mc":[{"id":"1.231812839","rc":[{"batb":[[0,1.03,200],[1,1.02,200],[2,1.01,479.35]],"ltp":1.04,"tv":2.0,"id":3961}]}]}
{"op":"mcm","clk":"11883033855","pt":1723736114710,"mc":[{"id":"1.231812839","rc":[{"batb":[[1,1.03,200],[2,1.02,200]],"ltp":0.0,"tv":0.0,"id":31376}]}]}
{"op":"mcm","clk":"11883048399","pt":1723736243994,"mc":[{"id":"1.231812839","rc":[{"batb":[[0,1.13,138.46],[1,1.03,200],[2,1.02,200]],"ltp":1.04,"tv":2.0,"id":3961},{"batb":[[0,1.13,138.46],[1,1.03,200],[2,1.02,200]],"ltp":0.0,"tv":0.0,"id":60443},{"batb":[[1,1.13,138.46],[2,1.03,200]],"ltp":0.0,"tv":0.0,"id":31376}]}]}
{"op":"mcm","clk":"11887440495","pt":1723774375213,"mc":[{"id":"1.231812839","rc":[{"batl":[[0,95,5.95]],"ltp":1.04,"tv":2.0,"id":3961},{"batl":[[0,18,1.14]],"ltp":0.0,"tv":0.0,"id":60443},{"batl":[[0,95,5.95]],"ltp":0.0,"tv":0.0,"id":31376}]}]}
{"op":"mcm","clk":"11887844261","pt":1723785684780,"mc":[{"id":"1.231812839","rc":[{"batb":[[0,1.14,61.26],[1,1.13,138.46],[2,1.03,200]],"ltp":1.04,"tv":2.0,"id":3961},{"batb":[[0,1.14,61.26],[1,1.13,138.46],[2,1.03,200]],"ltp":0.0,"tv":0.0,"id":60443},{"batb":[[0,1.3,28.59],[1,1.29,10],[2,1.13,138.46]],"ltp":0.0,"tv":0.0,"id":31376}]}]}
{"op":"mcm","clk":"11887889947","pt":1723787485414,"mc":[{"id":"1.231812839","rc":[{"batb":[[0,1.13,138.46],[1,1.03,200],[2,1.02,200]],"ltp":1.04,"tv":2.0,"id":3961},{"batb":[[0,1.13,138.46],[1,1.03,200],[2,1.02,200]],"ltp":0.0,"tv":0.0,"id":60443},{"batb":[[0,1.29,10],[1,1.13,138.46],[2,1.03,200]],"ltp":0.0,"tv":0.0,"id":31376}]}]}
{"op":"mcm","clk":"11887892551","pt":1723787575915,"mc":[{"id":"1.231812839","rc":[{"batb":[[0,1.14,61.26],[1,1.13,138.46],[2,1.03,200]],"ltp":1.04,"tv":2.0,"id":3961},{"batb":[[0,1.14,61.26],[1,1.13,138.46],[2,1.03,200]],"ltp":0.0,"tv":0.0,"id":60443},{"batb":[[0,1.3,28.59],[1,1.29,10],[2,1.13,138.46]],"ltp":0.0,"tv":0.0,"id":31376}]}]}
{"op":"mcm","clk":"11887939908","pt":1723789376517,"mc":[{"id":"1.231812839","rc":[{"batb":[[0,1.13,138.46],[1,1.03,200],[2,1.02,200]],"ltp":1.04,"tv":2.0,"id":3961},{"batb":[[0,1.13,138.46],[1,1.03,200],[2,1.02,200]],"ltp":0.0,"tv":0.0,"id":60443},{"batb":[[0,1.29,10],[1,1.13,138.46],[2,1.03,200]],"ltp":0.0,"tv":0.0,"id":31376}]}]}
{"op":"mcm","clk":"11887942274","pt":1723789467558,"mc":[{"id":"1.231812839","rc":[{"batb":[[0,1.14,61.25],[1,1.13,138.46],[2,1.03,200]],"ltp":1.04,"tv":2.0,"id":3961},{"batb":[[0,1.14,61.25],[1,1.13,138.46],[2,1.03,200]],"ltp":0.0,"tv":0.0,"id":60443},{"batb":[[0,1.3,28.58],[1,1.29,10],[2,1.13,138.46]],"ltp":0.0,"tv":0.0,"id":31376}]}]}
{"op":"mcm","clk":"11888012070","pt":1723791267986,"mc":[{"id":"1.231812839","rc":[{"batb":[[0,1.13,138.46],[1,1.03,200],[2,1.02,200]],"ltp":1.04,"tv":2.0,"id":3961},{"batb":[[0,1.29,10],[1,1.13,138.46],[2,1.03,200]],"ltp":0.0,"tv":0.0,"id":31376}]}]}
{"op":"mcm","clk":"11888012131","pt":1723791269386,"mc":[{"id":"1.231812839","rc":[{"batb":[[0,1.13,138.46],[1,1.03,200],[2,1.02,200]],"ltp":0.0,"tv":0.0,"id":60443}]}]}
{"op":"mcm","clk":"11888015427","pt":1723791363878,"mc":[{"id":"1.231812839","rc":[{"batb":[[0,1.14,61.25],[1,1.13,138.46],[2,1.03,200]],"ltp":1.04,"tv":2.0,"id":3961},{"batb":[[0,1.14,61.25],[1,1.13,138.46],[2,1.03,200]],"ltp":0.0,"tv":0.0,"id":60443},{"batb":[[0,1.3,28.58],[1,1.29,10],[2,1.13,138.46]],"ltp":0.0,"tv":0.0,"id":31376}]}]}
{"op":"mcm","clk":"11888090574","pt":1723793164325,"mc":[{"id":"1.231812839","rc":[{"batb":[[0,1.13,138.46],[1,1.03,200],[2,1.02,200]],"ltp":1.04,"tv":2.0,"id":3961},{"batb":[[0,1.13,138.46],[1,1.03,200],[2,1.02,200]],"ltp":0.0,"tv":0.0,"id":60443},{"batb":[[0,1.29,10],[1,1.13,138.46],[2,1.03,200]],"ltp":0.0,"tv":0.0,"id":31376}]}]}
{"op":"mcm","clk":"11888094457","pt":1723793256910,"mc":[{"id":"1.231812839","rc":[{"batb":[[0,1.14,61.24],[1,1.13,138.46],[2,1.03,200]],"ltp":1.04,"tv":2.0,"id":3961},{"batb":[[0,1.14,61.24],[1,1.13,138.46],[2,1.03,200]],"ltp":0.0,"tv":0.0,"id":60443},{"batb":[[0,1.3,28.58],[1,1.29,10],[2,1.13,138.46]],"ltp":0.0,"tv":0.0,"id":31376}]}]}
{"op":"mcm","clk":"11888177427","pt":1723795057543,"mc":[{"id":"1.231812839","rc":[{"batb":[[0,1.13,138.46],[1,1.03,200],[2,1.02,200]],"ltp":1.04,"tv":2.0,"id":3961},{"batb":[[0,1.13,138.46],[1,1.03,200],[2,1.02,200]],"ltp":0.0,"tv":0.0,"id":60443},{"batb":[[0,1.29,10],[1,1.13,138.46],[2,1.03,200]],"ltp":0.0,"tv":0.0,"id":31376}]}]}
{"op":"mcm","clk":"11888181417","pt":1723795147345,"mc":[{"id":"1.231812839","rc":[{"batb":[[0,1.14,61.24],[1,1.13,138.46],[2,1.03,200]],"ltp":1.04,"tv":2.0,"id":3961},{"batb":[[0,1.14,61.24],[1,1.13,138.46],[2,1.03,200]],"ltp":0.0,"tv":0.0,"id":60443},{"batb":[[0,1.3,28.58],[1,1.29,10],[2,1.13,138.46]],"ltp":0.0,"tv":0.0,"id":31376}]}]}
{"op":"mcm","clk":"11888238517","pt":1723795975224,"mc":[{"id":"1.231812839","rc":[{"batb":[[0,1.14,61.23]],"ltp":1.04,"tv":2.0,"id":3961},{"batb":[[0,1.14,61.23]],"ltp":0.0,"tv":0.0,"id":60443},{"batb":[[0,1.3,28.58]],"ltp":0.0,"tv":0.0,"id":31376}]}]}
{"op":"mcm","clk":"11888297363","pt":1723796947574,"mc":[{"id":"1.231812839","rc":[{"batb":[[0,1.13,138.46],[1,1.03,200],[2,1.02,200]],"ltp":1.04,"tv":2.0,"id":3961},{"batb":[[0,1.13,138.46],[1,1.03,200],[2,1.02,200]],"ltp":0.0,"tv":0.0,"id":60443}]}]}
{"op":"mcm","clk":"11888297383","pt":1723796947782,"mc":[{"id":"1.231812839","rc":[{"batb":[[0,1.29,10],[1,1.13,138.46],[2,1.03,200]],"ltp":0.0,"tv":0.0,"id":31376}]}]}
{"op":"mcm","clk":"11888302849","pt":1723797036745,"mc":[{"id":"1.231812839","rc":[{"batb":[[0,1.14,61.23],[1,1.13,138.46],[2,1.03,200]],"ltp":1.04,"tv":2.0,"id":3961},{"batb":[[0,1.14,61.23],[1,1.13,138.46],[2,1.03,200]],"ltp":0.0,"tv":0.0,"id":60443},{"batb":[[0,1.3,28.58],[1,1.29,10],[2,1.13,138.46]],"ltp":0.0,"tv":0.0,"id":31376}]}]}
{"op":"mcm","clk":"11888432148","pt":1723798837203,"mc":[{"id":"1.231812839","rc":[{"batb":[[0,1.13,138.46],[1,1.03,200],[2,1.02,200]],"ltp":1.04,"tv":2.0,"id":3961},{"batb":[[0,1.13,138.46],[1,1.03,200],[2,1.02,200]],"ltp":0.0,"tv":0.0,"id":60443},{"batb":[[0,1.29,10],[1,1.13,138.46],[2,1.03,200]],"ltp":0.0,"tv":0.0,"id":31376}]}]}
{"op":"mcm","clk":"11888438606","pt":1723798924326,"mc":[{"id":"1.231812839","rc":[{"batb":[[0,1.14,61.19],[1,1.13,138.46],[2,1.03,200]],"ltp":1.04,"tv":2.0,"id":3961},{"batb":[[0,1.14,61.19],[1,1.13,138.46],[2,1.03,200]],"ltp":0.0,"tv":0.0,"id":60443},{"batb":[[0,1.3,28.55],[1,1.29,10],[2,1.13,138.46]],"ltp":0.0,"tv":0.0,"id":31376}]}]}
{"op":"mcm","clk":"11888562017","pt":1723800423808,"mc":[{"id":"1.231812839","rc":[{"batb":[[1,1.03,200],[2,1.02,200]],"ltp":1.04,"tv":2.0,"id":3961},{"batb":[[1,1.03,200],[2,1.02,200]],"ltp":0.0,"tv":0.0,"id":60443},{"batb":[[2,1.03,200]],"ltp":0.0,"tv":0.0,"id":31376}]}]}
{"op":"mcm","clk":"11888567527","pt":1723800487699,"mc":[{"id":"1.231812839","rc":[{"batb":[[0,1.15,133.33],[1,1.14,61.19],[2,1.03,200]],"ltp":1.04,"tv":2.0,"id":3961}]}]}
{"op":"mcm","clk":"11888567760","pt":1723800490320,"mc":[{"id":"1.231812839","rc":[{"batb":[[0,1.15,133.33],[1,1.14,61.19],[2,1.03,200]],"ltp":0.0,"tv":0.0,"id":60443}]}]}
{"op":"mcm","clk":"11888568256","pt":1723800495200,"mc":[{"id":"1.231812839","rc":[{"batb":[[0,1.31,64.52],[1,1.3,28.55],[2,1.29,10]],"ltp":0.0,"tv":0.0,"id":31376}]}]}
{"op":"mcm","clk":"11888587940","pt":1723800724564,"mc":[{"id":"1.231812839","rc":[{"batb":[[1,1.03,200],[2,1.02,200]],"ltp":1.04,"tv":2.0,"id":3961},{"batb":[[1,1.03,200],[2,1.02,200]],"ltp":0.0,"tv":0.0,"id":60443}]}]}
{"op":"mcm","clk":"11888588007","pt":1723800725283,"mc":[{"id":"1.231812839","rc":[{"batb":[[1,1.29,10],[2,1.03,200]],"ltp":0.0,"tv":0.0,"id":31376}]}]}
{"op":"mcm","clk":"11888594068","pt":1723800811747,"mc":[{"id":"1.231812839","rc":[{"batb":[[0,1.16,53.54],[1,1.15,133.33],[2,1.03,200]],"ltp":1.04,"tv":2.0,"id":3961},{"batb":[[0,1.16,53.54],[1,1.15,133.33],[2,1.03,200]],"ltp":0.0,"tv":0.0,"id":60443},{"batb":[[0,1.32,26.77],[1,1.31,64.52],[2,1.29,10]],"ltp":0.0,"tv":0.0,"id":31376}]}]}
{"op":"mcm","clk":"11888700337","pt":1723801949748,"mc":[{"id":"1.231812839","rc":[{"batb":[[2,1.03,200]],"ltp":0.0,"tv":0.0,"id":31376}]}]}
{"op":"mcm","clk":"11888700348","pt":1723801949850,"mc":[{"id":"1.231812839","rc":[{"batb":[[0,1.33,10],[1,1.32,26.77],[2,1.31,64.52]],"ltp":0.0,"tv":0.0,"id":31376}]}]}
{"op":"mcm","clk":"11888755629","pt":1723802543124,"mc":[{"id":"1.231812839","rc":[{"batb":[[0,1.16,53.5]],"batl":[[0,95,5.95]],"ltp":1.04,"tv":2.0,"id":3961},{"batb":[[0,1.16,53.5]],"batl":[[0,18,1.14]],"ltp":0.0,"tv":0.0,"id":60443},{"batb":[[0,1.33,17.45],[1,1.32,26.75]],"batl":[[0,95,5.95]],"ltp":0.0,"tv":0.0,"id":31376}]}]}
{"op":"mcm","clk":"11888762118","pt":1723802612090,"mc":[{"id":"1.231812839","rc":[{"batb":[[0,1.15,133.33],[1,1.03,200],[2,1.02,200]],"ltp":1.04,"tv":2.0,"id":3961},{"batb":[[0,1.15,133.33],[1,1.03,200],[2,1.02,200]],"ltp":0.0,"tv":0.0,"id":60443},{"batb":[[1,1.31,64.52],[2,1.03,200]],"ltp":0.0,"tv":0.0,"id":31376}]}]}
{"op":"mcm","clk":"11888770341","pt":1723802695906,"mc":[{"id":"1.231812839","rc":[{"batb":[[0,1.16,53.5],[1,1.15,133.33],[2,1.03,200]],"ltp":1.04,"tv":2.0,"id":3961},{"batb":[[0,1.16,53.5],[1,1.15,133.33],[2,1.03,200]],"ltp":0.0,"tv":0.0,"id":60443},{"batb":[[0,1.34,25.18],[1,1.33,17.45],[2,1.31,64.52]],"ltp":0.0,"tv":0.0,"id":31376}]}]}
{"op":"mcm","clk":"11888937419","pt":1723804496403,"mc":[{"id":"1.231812839","rc":[{"batb":[[0,1.15,133.33],[1,1.03,200],[2,1.02,200]],"ltp":1.04,"tv":2.0,"id":3961},{"batb":[[0,1.15,133.33],[1,1.03,200],[2,1.02,200]],"ltp":0.0,"tv":0.0,"id":60443},{"batb":[[0,1.33,17.45],[1,1.31,64.52],[2,1.03,200]],"ltp":0.0,"tv":0.0,"id":31376}]}]}
{"op":"mcm","clk":"11888944683","pt":1723804572586,"mc":[{"id":"1.231812839","rc":[{"batb":[[0,1.16,53.5],[1,1.15,133.33],[2,1.03,200]],"ltp":1.04,"tv":2.0,"id":3961},{"batb":[[0,1.16,53.5],[1,1.15,133.33],[2,1.03,200]],"ltp":0.0,"tv":0.0,"id":60443},{"batb":[[0,1.34,25.18],[1,1.33,17.45],[2,1.31,64.52]],"ltp":0.0,"tv":0.0,"id":31376}]}]}
{"op":"mcm","clk":"11889105433","pt":1723806373164,"mc":[{"id":"1.231812839","rc":[{"batb":[[0,1.15,133.33],[1,1.03,200],[2,1.02,200]],"ltp":1.04,"tv":2.0,"id":3961},{"batb":[[0,1.15,133.33],[1,1.03,200],[2,1.02,200]],"ltp":0.0,"tv":0.0,"id":60443},{"batb":[[0,1.33,17.44],[1,1.31,64.52],[2,1.03,200]],"ltp":0.0,"tv":0.0,"id":31376}]}]}
{"op":"mcm","clk":"11889108532","pt":1723806404083,"mc":[{"id":"1.231812839","rc":[{"batb":[[0,1.33,10],[1,1.32,7.44],[2,1.31,64.52]],"ltp":0.0,"tv":0.0,"id":31376}]}]}
{"op":"mcm","clk":"11889121695","pt":1723806539747,"mc":[{"id":"1.231812839","rc":[{"batb":[[0,1.16,53.5],[1,1.15,133.33],[2,1.03,200]],"ltp":1.04,"tv":2.0,"id":3961},{"batb":[[0,1.16,53.5],[1,1.15,133.33],[2,1.03,200]],"ltp":0.0,"tv":0.0,"id":60443},{"batb":[[0,1.34,25.18],[1,1.33,10],[2,1.32,7.44]],"ltp":0.0,"tv":0.0,"id":31376}]}]}
{"op":"mcm","clk":"11889303248","pt":1723808340459,"mc":[{"id":"1.231812839","rc":[{"batb":[[0,1.15,133.33],[1,1.03,200],[2,1.02,200]],"ltp":1.04,"tv":2.0,"id":3961},{"batb":[[0,1.15,133.33],[1,1.03,200],[2,1.02,200]],"ltp":0.0,"tv":0.0,"id":60443},{"batb":[[0,1.33,10],[1,1.32,7.44],[2,1.31,64.52]],"ltp":0.0,"tv":0.0,"id":31376}]}]}
{"op":"mcm","clk":"11889321640","pt":1723808502061,"mc":[{"id":"1.231812839","rc":[{"batb":[[0,1.16,53.5],[1,1.15,133.33],[2,1.03,200]],"ltp":1.04,"tv":2.0,"id":3961},{"batb":[[0,1.16,53.5],[1,1.15,133.33],[2,1.03,200]],"ltp":0.0,"tv":0.0,"id":60443},{"batb":[[0,1.34,25.18],[1,1.33,10],[2,1.32,7.44]],"ltp":0.0,"tv":0.0,"id":31376}]}]}
{"op":"mcm","clk":"11889506464","pt":1723810302357,"mc":[{"id":"1.231812839","rc":[{"batb":[[0,1.15,133.33],[1,1.03,200],[2,1.02,200]],"ltp":1.04,"tv":2.0,"id":3961},{"batb":[[0,1.15,133.33],[1,1.03,200],[2,1.02,200]],"ltp":0.0,"tv":0.0,"id":60443},{"batb":[[0,1.33,10],[1,1.32,7.44],[2,1.31,64.52]],"ltp":0.0,"tv":0.0,"id":31376}]}]}
{"op":"mcm","clk":"11889509729","pt":1723810335399,"mc":[{"id":"1.231812839","rc":[{"batb":[[1,1.31,64.52],[2,1.03,200]],"ltp":0.0,"tv":0.0,"id":31376}]}]}
{"op":"mcm","clk":"11889528925","pt":1723810517290,"mc":[{"id":"1.231812839","rc":[{"batb":[[0,1.16,53.49],[1,1.15,133.33],[2,1.03,200]],"ltp":1.04,"tv":2.0,"id":3961},{"batb":[[0,1.16,53.49],[1,1.15,133.33],[2,1.03,200]],"ltp":0.0,"tv":0.0,"id":60443},{"batb":[[0,1.34,25.17],[1,1.33,10],[2,1.31,64.52]],"ltp":0.0,"tv":0.0,"id":31376}]}]}
{"op":"mcm","clk":"11889626152","pt":1723811489434,"mc":[{"id":"1.231812839","rc":[{"batb":[[1,1.03,200],[2,1.02,200]],"ltp":0.0,"tv":0.0,"id":60443}]}]}
{"op":"mcm","clk":"11889626239","pt":1723811490211,"mc":[{"id":"1.231812839","rc":[{"batb":[[0,1.17,117.65],[1,1.16,53.49],[2,1.03,200]],"ltp":0.0,"tv":0.0,"id":60443}]}]}
{"op":"mcm","clk":"11889627004","pt":1723811498315,"mc":[{"id":"1.231812839","rc":[{"batb":[[2,1.03,200]],"ltp":0.0,"tv":0.0,"id":31376}]}]}
{"op":"mcm","clk":"11889627071","pt":1723811499196,"mc":[{"id":"1.231812839","rc":[{"batb":[[0,1.35,57.14],[1,1.34,25.17],[2,1.33,10]],"ltp":0.0,"tv":0.0,"id":31376}]}]}
{"op":"mcm","clk":"11889630467","pt":1723811529961,"mc":[{"id":"1.231812839","rc":[{"trd":[[1.16,2]],"batb":[[0,1.16,52.49]],"ltp":1.16,"tv":3.99,"id":3961}],"tv":3.99}]}
{"op":"mcm","clk":"11889722250","pt":1723812317698,"mc":[{"id":"1.231812839","rc":[{"batb":[[0,1.15,133.33],[1,1.03,200],[2,1.02,200]],"ltp":1.16,"tv":3.99,"id":3961},{"batb":[[1,1.03,200],[2,1.02,200]],"ltp":0.0,"tv":0.0,"id":60443},{"batb":[[1,1.33,10],[2,1.03,200]],"ltp":0.0,"tv":0.0,"id":31376}]}]}
{"op":"mcm","clk":"11889745272","pt":1723812522470,"mc":[{"id":"1.231812839","rc":[{"batb":[[0,1.18,47.55],[1,1.17,117.65],[2,1.03,200]],"ltp":0.0,"tv":0.0,"id":60443},{"batb":[[0,1.36,23.77],[1,1.35,57.14],[2,1.33,10]],"ltp":0.0,"tv":0.0,"id":31376}]}]}
{"op":"mcm","clk":"11889919544","pt":1723814322680,"mc":[{"id":"1.231812839","rc":[{"trd":[[1.16,2]],"ltp":1.16,"tv":4.0,"id":3961},{"batb":[[0,1.18,47.6]],"batl":[[0,18,1.14]],"ltp":0.0,"tv":0.0,"id":60443},{"batb":[[0,1.35,57.14],[1,1.33,10],[2,1.03,200]],"ltp":0.0,"tv":0.0,"id":31376}],"tv":4.0}]}
{"op":"mcm","clk":"11889919559","pt":1723814322890,"mc":[{"id":"1.231812839","rc":[{"batb":[[0,1.17,117.65],[1,1.03,200],[2,1.02,200]],"ltp":0.0,"tv":0.0,"id":60443}]}]}
{"op":"mcm","clk":"11889937423","pt":1723814514993,"mc":[{"id":"1.231812839","rc":[{"batb":[[0,1.18,47.6],[1,1.17,117.65],[2,1.03,200]],"ltp":0.0,"tv":0.0,"id":60443},{"batb":[[0,1.36,23.8],[1,1.35,57.14],[2,1.33,10]],"ltp":0.0,"tv":0.0,"id":31376}]}]}
{"op":"mcm","clk":"11890040873","pt":1723815616819,"mc":[{"id":"1.231812839","rc":[{"trd":[[1.15,2]],"batb":[[0,1.15,132.33]],"ltp":1.15,"tv":6.0,"id":3961}],"tv":6.0}]}
{"op":"mcm","clk":"11890105670","pt":1723816315342,"mc":[{"id":"1.231812839","rc":[{"batb":[[0,1.17,117.65],[1,1.03,200],[2,1.02,200]],"ltp":0.0,"tv":0.0,"id":60443},{"batb":[[0,1.35,57.14],[1,1.33,10],[2,1.03,200]],"ltp":0.0,"tv":0.0,"id":31376}]}]}
{"op":"mcm","clk":"11890122015","pt":1723816498371,"mc":[{"id":"1.231812839","rc":[{"batb":[[0,1.18,47.6],[1,1.17,117.65],[2,1.03,200]],"ltp":0.0,"tv":0.0,"id":60443},{"batb":[[0,1.36,23.8],[1,1.35,57.14],[2,1.33,10]],"ltp":0.0,"tv":0.0,"id":31376}]}]}
{"op":"mcm","clk":"11890229986","pt":1723817575199,"mc":[{"id":"1.231812839","rc":[{"batb":[[0,1.18,47.61]],"ltp":0.0,"tv":0.0,"id":60443},{"batb":[[0,1.36,23.8]],"ltp":0.0,"tv":0.0,"id":31376}]}]}
{"op":"mcm","clk":"11890285051","pt":1723818298713,"mc":[{"id":"1.231812839","rc":[{"batb":[[0,1.17,117.65],[1,1.03,200],[2,1.02,200]],"ltp":0.0,"tv":0.0,"id":60443},{"batb":[[0,1.35,57.14],[1,1.33,10],[2,1.03,200]],"ltp":0.0,"tv":0.0,"id":31376}]}]}
{"op":"mcm","clk":"11890298818","pt":1723818470328,"mc":[{"id":"1.231812839","rc":[{"batb":[[0,1.18,47.61],[1,1.17,117.65],[2,1.03,200]],"ltp":0.0,"tv":0.0,"id":60443},{"batb":[[0,1.36,23.8],[1,1.35,57.14],[2,1.33,10]],"ltp":0.0,"tv":0.0,"id":31376}]}]}
{"op":"mcm","clk":"11890309897","pt":1723818607952,"mc":[{"id":"1.231812839","rc":[{"batl":[[0,95,5]],"ltp":1.15,"tv":6.0,"id":3961},{"batl":[[0,95,5.19],[1,990,5],[2,990,0]],"ltp":0.0,"tv":0.0,"id":60443},{"batl":[[0,95,5]],"ltp":0.0,"tv":0.0,"id":31376}]}]}
{"op":"mcm","clk":"11890447099","pt":1723820270704,"mc":[{"id":"1.231812839","rc":[{"batb":[[0,1.17,117.65],[1,1.03,200],[2,1.02,200]],"ltp":0.0,"tv":0.0,"id":60443},{"batb":[[0,1.35,57.14],[1,1.33,10],[2,1.03,200]],"ltp":0.0,"tv":0.0,"id":31376}]}]}
{"op":"mcm","clk":"11890460897","pt":1723820431228,"mc":[{"id":"1.231812839","rc":[{"batb":[[0,1.18,47.62],[1,1.17,117.65],[2,1.03,200]],"ltp":0.0,"tv":0.0,"id":60443},{"batb":[[0,1.36,23.81],[1,1.35,57.14],[2,1.33,10]],"ltp":0.0,"tv":0.0,"id":31376}]}]}
{"op":"mcm","clk":"11890645154","pt":1723822231643,"mc":[{"id":"1.231812839","rc":[{"batb":[[0,1.17,117.65],[1,1.03,200],[2,1.02,200]],"ltp":0.0,"tv":0.0,"id":60443},{"batb":[[0,1.35,57.14],[1,1.33,10],[2,1.03,200]],"ltp":0.0,"tv":0.0,"id":31376}]}]}
{"op":"mcm","clk":"11890661851","pt":1723822385155,"mc":[{"id":"1.231812839","rc":[{"batb":[[0,1.18,47.62],[1,1.17,117.65],[2,1.03,200]],"ltp":0.0,"tv":0.0,"id":60443},{"batb":[[0,1.36,23.81],[1,1.35,57.14],[2,1.33,10]],"ltp":0.0,"tv":0.0,"id":31376}]}]}
{"op":"mcm","clk":"11890866121","pt":1723824185594,"mc":[{"id":"1.231812839","rc":[{"batb":[[0,1.17,117.65],[1,1.03,200],[2,1.02,200]],"ltp":0.0,"tv":0.0,"id":60443},{"batb":[[0,1.35,57.14],[1,1.33,10],[2,1.03,200]],"ltp":0.0,"tv":0.0,"id":31376}]}]}
{"op":"mcm","clk":"11890884864","pt":1723824334529,"mc":[{"id":"1.231812839","rc":[{"batb":[[0,1.18,47.59],[1,1.17,117.65],[2,1.03,200]],"ltp":0.0,"tv":0.0,"id":60443},{"batb":[[0,1.36,23.79],[1,1.35,57.14],[2,1.33,10]],"ltp":0.0,"tv":0.0,"id":31376}]}]}
{"op":"mcm","clk":"11891144544","pt":1723826134732,"mc":[{"id":"1.231812839","rc":[{"batb":[[0,1.17,117.65],[1,1.03,200],[2,1.02,200]],"ltp":0.0,"tv":0.0,"id":60443}]}]}
{"op":"mcm","clk":"11891144575","pt":1723826134947,"mc":[{"id":"1.231812839","rc":[{"batb":[[0,1.35,57.14],[1,1.33,10],[2,1.03,200]],"ltp":0.0,"tv":0.0,"id":31376}]}]}
{"op":"mcm","clk":"11891166620","pt":1723826273253,"mc":[{"id":"1.231812839","rc":[{"batb":[[0,1.18,47.59],[1,1.17,117.65],[2,1.03,200]],"ltp":0.0,"tv":0.0,"id":60443},{"batb":[[0,1.36,23.79],[1,1.35,57.14],[2,1.33,10]],"ltp":0.0,"tv":0.0,"id":31376}]}]}
{"op":"mcm","clk":"11891432171","pt":1723828073621,"mc":[{"id":"1.231812839","rc":[{"batb":[[0,1.17,117.65],[1,1.03,200],[2,1.02,200]],"ltp":0.0,"tv":0.0,"id":60443},{"batb":[[0,1.35,57.14],[1,1.33,10],[2,1.03,200]],"ltp":0.0,"tv":0.0,"id":31376}]}]}
{"op":"mcm","clk":"11891456763","pt":1723828214027,"mc":[{"id":"1.231812839","rc":[{"batb":[[0,1.18,47.56],[1,1.17,117.65],[2,1.03,200]],"ltp":0.0,"tv":0.0,"id":60443},{"batb":[[0,1.36,23.78],[1,1.35,57.14],[2,1.33,10]],"ltp":0.0,"tv":0.0,"id":31376}]}]}
{"op":"mcm","clk":"11891783432","pt":1723829974563,"mc":[{"id":"1.231812839","rc":[{"batb":[[0,1.37,10],[1,1.36,23.78],[2,1.35,57.14]],"ltp":0.0,"tv":0.0,"id":31376}]}]}
{"op":"mcm","clk":"11891791404","pt":1723830014348,"mc":[{"id":"1.231812839","rc":[{"batb":[[0,1.17,117.65],[1,1.03,200],[2,1.02,200]],"ltp":0.0,"tv":0.0,"id":60443},{"batb":[[1,1.35,57.14],[2,1.03,200]],"ltp":0.0,"tv":0.0,"id":31376}]}]}
{"op":"mcm","clk":"11891813887","pt":1723830135605,"mc":[{"id":"1.231812839","rc":[{"batb":[[0,1.18,47.56],[1,1.17,117.65],[2,1.03,200]],"ltp":0.0,"tv":0.0,"id":60443},{"batb":[[0,1.38,22.53],[1,1.37,10],[2,1.35,57.14]],"ltp":0.0,"tv":0.0,"id":31376}]}]}
{"op":"mcm","clk":"11891928480","pt":1723830767932,"mc":[{"id":"1.231812839","rc":[{"batb":[[1,1.03,200],[2,1.02,200]],"ltp":0.0,"tv":0.0,"id":60443}]}]}
{"op":"mcm","clk":"11891928716","pt":1723830769349,"mc":[{"id":"1.231812839","rc":[{"batb":[[0,1.19,105.26],[1,1.18,47.56],[2,1.03,200]],"ltp":0.0,"tv":0.0,"id":60443}]}]}
{"op":"mcm","clk":"11891929012","pt":1723830771243,"mc":[{"id":"1.231812839","rc":[{"batb":[[2,1.03,200]],"ltp":0.0,"tv":0.0,"id":31376}]}]}
{"op":"mcm","clk":"11891929383","pt":1723830773549,"mc":[{"id":"1.231812839","rc":[{"batb":[[0,1.39,51.28],[1,1.38,22.53],[2,1.37,10]],"ltp":0.0,"tv":0.0,"id":31376}]}]}
{"op":"mcm","clk":"11891929694","pt":1723830775573,"mc":[{"id":"1.231812839","rc":[{"batb":[[0,1.03,200],[1,1.02,200],[2,1.01,478.42]],"ltp":1.15,"tv":5.99,"id":3961}]}]}
{"op":"mcm","clk":"11891930787","pt":1723830782806,"mc":[{"id":"1.231812839","rc":[{"batb":[[0,1.1,200],[1,1.03,200],[2,1.02,200]],"ltp":1.15,"tv":5.99,"id":3961}]}]}
{"op":"mcm","clk":"11892043671","pt":1723831442849,"mc":[{"id":"1.231812839","rc":[{"batb":[[0,1.2,6],[1,1.19,105.26],[2,1.18,47.57]],"ltp":0.0,"tv":0.0,"id":60443},{"batb":[[1,1.38,22.53]],"ltp":0.0,"tv":0.0,"id":31376}]}]}
{"op":"mcm","clk":"11892144511","pt":1723831936046,"mc":[{"id":"1.231812839","rc":[{"batb":[[2,1.03,200]],"ltp":0.0,"tv":0.0,"id":60443},{"batb":[[1,1.37,10],[2,1.03,200]],"ltp":0.0,"tv":0.0,"id":31376}]}]}
{"op":"mcm","clk":"11892165271","pt":1723832029565,"mc":[{"id":"1.231812839","rc":[{"batb":[[0,1.21,40.77],[1,1.2,6],[2,1.19,105.26]],"ltp":0.0,"tv":0.0,"id":60443},{"batb":[[0,1.4,21.4],[1,1.39,51.28],[2,1.37,10]],"ltp":0.0,"tv":0.0,"id":31376}]}]}
{"op":"mcm","clk":"11892592591","pt":1723833856540,"mc":[{"id":"1.231812839","rc":[{"batb":[[0,1.2,6],[1,1.19,105.26],[2,1.03,200]],"ltp":0.0,"tv":0.0,"id":60443},{"batb":[[0,1.39,51.28],[1,1.37,10],[2,1.03,200]],"ltp":0.0,"tv":0.0,"id":31376}]}]}
{"op":"mcm","clk":"11892598294","pt":1723833884748,"mc":[{"id":"1.231812839","rc":[{"batb":[[0,1.4,21.4],[1,1.39,51.28],[2,1.37,10]],"ltp":0.0,"tv":0.0,"id":31376}]}]}
{"op":"mcm","clk":"11892598310","pt":1723833884862,"mc":[{"id":"1.231812839","rc":[{"batb":[[0,1.21,40.77],[1,1.2,6],[2,1.19,105.26]],"ltp":0.0,"tv":0.0,"id":60443}]}]}
{"op":"mcm","clk":"11892933048","pt":1723835685137,"mc":[{"id":"1.231812839","rc":[{"batb":[[0,1.2,6],[1,1.19,105.26],[2,1.03,200]],"ltp":0.0,"tv":0.0,"id":60443},{"batb":[[0,1.39,51.28],[1,1.37,10],[2,1.03,200]],"ltp":0.0,"tv":0.0,"id":31376}]}]}
{"op":"mcm","clk":"11892935715","pt":1723835700780,"mc":[{"id":"1.231812839","rc":[{"batb":[[0,1.21,40.76],[1,1.2,6],[2,1.19,105.26]],"ltp":0.0,"tv":0.0,"id":60443},{"batb":[[0,1.4,21.4],[1,1.39,51.28],[2,1.37,10]],"ltp":0.0,"tv":0.0,"id":31376}]}]}
{"op":"mcm","clk":"11892975974","pt":1723835938215,"mc":[{"id":"1.231812839","rc":[{"batb":[[0,1.22,6],[1,1.21,40.76]],"ltp":0.0,"tv":0.0,"id":60443}]}]}
{"op":"mcm","clk":"11893219023","pt":1723837501220,"mc":[{"id":"1.231812839","rc":[{"batb":[[1,1.19,105.26],[2,1.03,200]],"ltp":0.0,"tv":0.0,"id":60443},{"batb":[[0,1.39,51.28],[1,1.37,10],[2,1.03,200]],"ltp":0.0,"tv":0.0,"id":31376}]}]}
{"op":"mcm","clk":"11893239710","pt":1723837639126,"mc":[{"id":"1.231812839","rc":[{"batb":[[0,1.23,37.22],[1,1.22,6],[2,1.19,105.26]],"ltp":0.0,"tv":0.0,"id":60443},{"batb":[[0,1.4,21.4],[1,1.39,51.28],[2,1.37,10]],"ltp":0.0,"tv":0.0,"id":31376}]}]}
{"op":"mcm","clk":"11893433484","pt":1723839175230,"mc":[{"id":"1.231812839","rc":[{"batb":[[0,1.23,37.22]],"ltp":0.0,"tv":0.0,"id":60443},{"batb":[[0,1.4,21.4]],"ltp":0.0,"tv":0.0,"id":31376}]}]}
{"op":"mcm","clk":"11893461373","pt":1723839439520,"mc":[{"id":"1.231812839","rc":[{"batb":[[0,1.22,6],[1,1.19,105.26],[2,1.03,200]],"ltp":0.0,"tv":0.0,"id":60443},{"batb":[[0,1.39,51.28],[1,1.37,10],[2,1.03,200]],"ltp":0.0,"tv":0.0,"id":31376}]}]}
{"op":"mcm","clk":"11893484754","pt":1723839674822,"mc":[{"id":"1.231812839","rc":[{"batb":[[0,1.23,37.22],[1,1.22,6],[2,1.19,105.26]],"ltp":0.0,"tv":0.0,"id":60443},{"batb":[[0,1.4,21.4],[1,1.39,51.28],[2,1.37,10]],"ltp":0.0,"tv":0.0,"id":31376}]}]}
{"op":"mcm","clk":"11893528177","pt":1723840104259,"mc":[{"id":"1.231812839","rc":[{"batb":[[0,1.24,6],[1,1.23,37.22]],"ltp":0.0,"tv":0.0,"id":60443}]}]}
{"op":"mcm","clk":"11893628839","pt":1723841475430,"mc":[{"id":"1.231812839","rc":[{"batb":[[1,1.19,105.26],[2,1.03,200]],"ltp":0.0,"tv":0.0,"id":60443},{"batb":[[0,1.39,51.28],[1,1.37,10],[2,1.03,200]],"ltp":0.0,"tv":0.0,"id":31376}]}]}
{"op":"mcm","clk":"11893638699","pt":1723841657135,"mc":[{"id":"1.231812839","rc":[{"batb":[[0,1.25,34.24],[1,1.24,6],[2,1.19,105.26]],"ltp":0.0,"tv":0.0,"id":60443},{"batb":[[0,1.4,21.4],[1,1.39,51.28],[2,1.37,10]],"ltp":0.0,"tv":0.0,"id":31376}]}]}
{"op":"mcm","clk":"11893729957","pt":1723843457577,"mc":[{"id":"1.231812839","rc":[{"batb":[[0,1.24,5.99],[1,1.19,105.26],[2,1.03,200]],"ltp":0.0,"tv":0.0,"id":60443},{"batb":[[0,1.39,51.28],[1,1.37,10],[2,1.03,200]],"ltp":0.0,"tv":0.0,"id":31376}]}]}
{"op":"mcm","clk":"11893736037","pt":1723843595506,"mc":[{"id":"1.231812839","rc":[{"batb":[[0,1.25,34.26],[1,1.24,5.99],[2,1.19,105.26]],"ltp":0.0,"tv":0.0,"id":60443},{"batb":[[0,1.4,21.41],[1,1.39,51.28],[2,1.37,10]],"ltp":0.0,"tv":0.0,"id":31376}]}]}
{"op":"mcm","clk":"11893823640","pt":1723845396109,"mc":[{"id":"1.231812839","rc":[{"batb":[[0,1.24,5.99],[1,1.19,105.26],[2,1.03,200]],"ltp":0.0,"tv":0.0,"id":60443},{"batb":[[0,1.39,51.28],[1,1.37,10],[2,1.03,200]],"ltp":0.0,"tv":0.0,"id":31376}]}]}
{"op":"mcm","clk":"11893830452","pt":1723845508920,"mc":[{"id":"1.231812839","rc":[{"batb":[[0,1.25,34.26],[1,1.24,5.99],[2,1.19,105.26]],"ltp":0.0,"tv":0.0,"id":60443},{"batb":[[0,1.4,21.41],[1,1.39,51.28],[2,1.37,10]],"ltp":0.0,"tv":0.0,"id":31376}]}]}
{"op":"mcm","clk":"11893870799","pt":1723846413669,"mc":[{"id":"1.231812839","rc":[{"batb":[[0,1.25,34.24],[1,1.19,105.26],[2,1.03,200]],"ltp":0.0,"tv":0.0,"id":60443},{"batb":[[0,1.4,21.4]],"ltp":0.0,"tv":0.0,"id":31376}]}]}
{"op":"mcm","clk":"11893870803","pt":1723846413773,"mc":[{"id":"1.231812839","rc":[{"batb":[[0,1.26,5.99],[1,1.25,34.24],[2,1.19,105.26]],"ltp":0.0,"tv":0.0,"id":60443}]}]}
{"op":"mcm","clk":"11893908041","pt":1723847309350,"mc":[{"id":"1.231812839","rc":[{"batb":[[1,1.19,105.26],[2,1.03,200]],"ltp":0.0,"tv":0.0,"id":60443},{"batb":[[0,1.39,51.28],[1,1.37,10],[2,1.03,200]],"ltp":0.0,"tv":0.0,"id":31376}]}]}
{"op":"mcm","clk":"11893912443","pt":1723847418076,"mc":[{"id":"1.231812839","rc":[{"batb":[[0,1.27,31.7],[1,1.26,5.99],[2,1.19,105.26]],"ltp":0.0,"tv":0.0,"id":60443},{"batb":[[0,1.4,21.4],[1,1.39,51.28],[2,1.37,10]],"ltp":0.0,"tv":0.0,"id":31376}]}]}
{"op":"mcm","clk":"11893982974","pt":1723849218534,"mc":[{"id":"1.231812839","rc":[{"batb":[[0,1.26,5.99],[1,1.19,105.26],[2,1.03,200]],"ltp":0.0,"tv":0.0,"id":60443},{"batb":[[0,1.39,51.28],[1,1.37,10],[2,1.03,200]],"ltp":0.0,"tv":0.0,"id":31376}]}]}
{"op":"mcm","clk":"11893987539","pt":1723849317112,"mc":[{"id":"1.231812839","rc":[{"batb":[[0,1.27,31.7],[1,1.26,5.99],[2,1.19,105.26]],"ltp":0.0,"tv":0.0,"id":60443},{"batb":[[0,1.4,21.4],[1,1.39,51.28],[2,1.37,10]],"ltp":0.0,"tv":0.0,"id":31376}]}]}
{"op":"mcm","clk":"11894097757","pt":1723851117518,"mc":[{"id":"1.231812839","rc":[{"batb":[[0,1.26,5.99],[1,1.19,105.26],[2,1.03,200]],"ltp":0.0,"tv":0.0,"id":60443},{"batb":[[0,1.39,51.28],[1,1.37,10],[2,1.03,200]],"ltp":0.0,"tv":0.0,"id":31376}]}]}
{"op":"mcm","clk":"11894102781","pt":1723851206988,"mc":[{"id":"1.231812839","rc":[{"batb":[[0,1.27,31.7],[1,1.26,5.99],[2,1.19,105.26]],"ltp":0.0,"tv":0.0,"id":60443},{"batb":[[0,1.4,21.4],[1,1.39,51.28],[2,1.37,10]],"ltp":0.0,"tv":0.0,"id":31376}]}]}
{"op":"mcm","clk":"11894208133","pt":1723853007384,"mc":[{"id":"1.231812839","rc":[{"batb":[[0,1.26,5.99],[1,1.19,105.26],[2,1.03,200]],"ltp":0.0,"tv":0.0,"id":60443},{"batb":[[0,1.39,51.28],[1,1.37,10],[2,1.03,200]],"ltp":0.0,"tv":0.0,"id":31376}]}]}
{"op":"mcm","clk":"11894213676","pt":1723853088453,"mc":[{"id":"1.231812839","rc":[{"batb":[[0,1.27,31.7],[1,1.26,5.99],[2,1.19,105.26]],"ltp":0.0,"tv":0.0,"id":60443},{"batb":[[0,1.4,21.4],[1,1.39,51.28],[2,1.37,10]],"ltp":0.0,"tv":0.0,"id":31376}]}]}
{"op":"mcm","clk":"11894333206","pt":1723854888623,"mc":[{"id":"1.231812839","rc":[{"batb":[[0,1.26,5.99],[1,1.19,105.26],[2,1.03,200]],"ltp":0.0,"tv":0.0,"id":60443}]}]}
{"op":"mcm","clk":"11894333219","pt":1723854888777,"mc":[{"id":"1.231812839","rc":[{"batb":[[0,1.39,51.28],[1,1.37,10],[2,1.03,200]],"ltp":0.0,"tv":0.0,"id":31376}]}]}
{"op":"mcm","clk":"11894338234","pt":1723854958988,"mc":[{"id":"1.231812839","rc":[{"batb":[[0,1.27,31.7],[1,1.26,5.99],[2,1.19,105.26]],"ltp":0.0,"tv":0.0,"id":60443},{"batb":[[0,1.4,21.4],[1,1.39,51.28],[2,1.37,10]],"ltp":0.0,"tv":0.0,"id":31376}]}]}
{"op":"mcm","clk":"11894475064","pt":1723856759377,"mc":[{"id":"1.231812839","rc":[{"batb":[[0,1.26,5.99],[1,1.19,105.26],[2,1.03,200]],"ltp":0.0,"tv":0.0,"id":60443},{"batb":[[0,1.39,51.28],[1,1.37,10],[2,1.03,200]],"ltp":0.0,"tv":0.0,"id":31376}]}]}
{"op":"mcm","clk":"11894480249","pt":1723856824784,"mc":[{"id":"1.231812839","rc":[{"batb":[[0,1.27,31.7],[1,1.26,5.99],[2,1.19,105.26]],"ltp":0.0,"tv":0.0,"id":60443},{"batb":[[0,1.4,21.4],[1,1.39,51.28],[2,1.37,10]],"ltp":0.0,"tv":0.0,"id":31376}]}]}
{"op":"mcm","clk":"11894598925","pt":1723858625235,"mc":[{"id":"1.231812839","rc":[{"batb":[[0,1.26,5.99],[1,1.19,105.26],[2,1.03,200]],"ltp":0.0,"tv":0.0,"id":60443},{"batb":[[0,1.39,51.28],[1,1.37,10],[2,1.03,200]],"ltp":0.0,"tv":0.0,"id":31376}]}]}
{"op":"mcm","clk":"11894602572","pt":1723858683262,"mc":[{"id":"1.231812839","rc":[{"batb":[[0,1.27,31.7],[1,1.26,5.99],[2,1.19,105.26]],"ltp":0.0,"tv":0.0,"id":60443},{"batb":[[0,1.4,21.4],[1,1.39,51.28],[2,1.37,10]],"ltp":0.0,"tv":0.0,"id":31376}]}]}
{"op":"mcm","clk":"11894697933","pt":1723860483692,"mc":[{"id":"1.231812839","rc":[{"batb":[[0,1.26,5.99],[1,1.19,105.26],[2,1.03,200]],"ltp":0.0,"tv":0.0,"id":60443},{"batb":[[0,1.39,51.28],[1,1.37,10],[2,1.03,200]],"ltp":0.0,"tv":0.0,"id":31376}]}]}
{"op":"mcm","clk":"11894700885","pt":1723860530747,"mc":[{"id":"1.231812839","rc":[{"batb":[[0,1.27,31.7],[1,1.26,5.99],[2,1.19,105.26]],"ltp":0.0,"tv":0.0,"id":60443},{"batb":[[0,1.4,21.4],[1,1.39,51.28],[2,1.37,10]],"ltp":0.0,"tv":0.0,"id":31376}]}]}
{"op":"mcm","clk":"11894810752","pt":1723862331175,"mc":[{"id":"1.231812839","rc":[{"batb":[[0,1.26,5.99],[1,1.19,105.26],[2,1.03,200]],"ltp":0.0,"tv":0.0,"id":60443},{"batb":[[0,1.39,51.28],[1,1.37,10],[2,1.03,200]],"ltp":0.0,"tv":0.0,"id":31376}]}]}
{"op":"mcm","clk":"11894812277","pt":1723862362980,"mc":[{"id":"1.231812839","rc":[{"batb":[[0,1.27,31.7],[1,1.26,5.99],[2,1.19,105.26]],"ltp":0.0,"tv":0.0,"id":60443},{"batb":[[0,1.4,21.4],[1,1.39,51.28],[2,1.37,10]],"ltp":0.0,"tv":0.0,"id":31376}]}]}
{"op":"mcm","clk":"11894891275","pt":1723864163325,"mc":[{"id":"1.231812839","rc":[{"batb":[[0,1.26,5.99],[1,1.19,105.26],[2,1.03,200]],"ltp":0.0,"tv":0.0,"id":60443},{"batb":[[0,1.39,51.28],[1,1.37,10],[2,1.03,200]],"ltp":0.0,"tv":0.0,"id":31376}]}]}
{"op":"mcm","clk":"11894891598","pt":1723864173152,"mc":[{"id":"1.231812839","rc":[{"batb":[[0,1.27,31.7],[1,1.26,5.99],[2,1.19,105.26]],"ltp":0.0,"tv":0.0,"id":60443},{"batb":[[0,1.4,21.4],[1,1.39,51.28],[2,1.37,10]],"ltp":0.0,"tv":0.0,"id":31376}]}]}
{"op":"mcm","clk":"11894960106","pt":1723865973511,"mc":[{"id":"1.231812839","rc":[{"batb":[[0,1.26,5.99],[1,1.19,105.26],[2,1.03,200]],"ltp":0.0,"tv":0.0,"id":60443},{"batb":[[0,1.39,51.28],[1,1.37,10],[2,1.03,200]],"ltp":0.0,"tv":0.0,"id":31376}]}]}
{"op":"mcm","clk":"11894960152","pt":1723865974794,"mc":[{"id":"1.231812839","rc":[{"batb":[[0,1.27,31.7],[1,1.26,5.99],[2,1.19,105.26]],"ltp":0.0,"tv":0.0,"id":60443},{"batb":[[0,1.4,21.4],[1,1.39,51.28],[2,1.37,10]],"ltp":0.0,"tv":0.0,"id":31376}]}]}
{"op":"mcm","clk":"11895053722","pt":1723867775323,"mc":[{"id":"1.231812839","rc":[{"batb":[[0,1.26,5.99],[1,1.19,105.26],[2,1.03,200]],"ltp":0.0,"tv":0.0,"id":60443},{"batb":[[0,1.39,51.28],[1,1.37,10],[2,1.03,200]],"ltp":0.0,"tv":0.0,"id":31376}]}]}
{"op":"mcm","clk":"11895064627","pt":1723867988458,"mc":[{"id":"1.231812839","rc":[{"batb":[[0,1.27,31.7],[1,1.26,5.99],[2,1.19,105.26]],"ltp":0.0,"tv":0.0,"id":60443},{"batb":[[0,1.4,21.4],[1,1.39,51.28],[2,1.37,10]],"ltp":0.0,"tv":0.0,"id":31376}]}]}
{"op":"mcm","clk":"11895134310","pt":1723869788651,"mc":[{"id":"1.231812839","rc":[{"batb":[[0,1.26,5.99],[1,1.19,105.26],[2,1.03,200]],"ltp":0.0,"tv":0.0,"id":60443}]}]}
{"op":"mcm","clk":"11895134321","pt":1723869788854,"mc":[{"id":"1.231812839","rc":[{"batb":[[0,1.39,51.28],[1,1.37,10],[2,1.03,200]],"ltp":0.0,"tv":0.0,"id":31376}]}]}
{"op":"mcm","clk":"11895140652","pt":1723869989279,"mc":[{"id":"1.231812839","rc":[{"batb":[[0,1.27,31.7],[1,1.26,5.99],[2,1.19,105.26]],"ltp":0.0,"tv":0.0,"id":60443},{"batb":[[0,1.4,21.4],[1,1.39,51.28],[2,1.37,10]],"ltp":0.0,"tv":0.0,"id":31376}]}]}
{"op":"mcm","clk":"11895212284","pt":1723871789535,"mc":[{"id":"1.231812839","rc":[{"batb":[[0,1.39,51.28],[1,1.37,10],[2,1.03,200]],"ltp":0.0,"tv":0.0,"id":31376}]}]}
{"op":"mcm","clk":"11895212297","pt":1723871789840,"mc":[{"id":"1.231812839","rc":[{"batb":[[0,1.26,5.99],[1,1.19,105.26],[2,1.03,200]],"ltp":0.0,"tv":0.0,"id":60443}]}]}
{"op":"mcm","clk":"11895221924","pt":1723871979366,"mc":[{"id":"1.231812839","rc":[{"batb":[[0,1.27,31.7],[1,1.26,5.99],[2,1.19,105.26]],"ltp":0.0,"tv":0.0,"id":60443},{"batb":[[0,1.4,21.4],[1,1.39,51.28],[2,1.37,10]],"ltp":0.0,"tv":0.0,"id":31376}]}]}
{"op":"mcm","clk":"11895277331","pt":1723873779746,"mc":[{"id":"1.231812839","rc":[{"batb":[[0,1.26,5.99],[1,1.19,105.26],[2,1.03,200]],"ltp":0.0,"tv":0.0,"id":60443},{"batb":[[0,1.39,51.28],[1,1.37,10],[2,1.03,200]],"ltp":0.0,"tv":0.0,"id":31376}]}]}
{"op":"mcm","clk":"11895285837","pt":1723873966556,"mc":[{"id":"1.231812839","rc":[{"batb":[[0,1.27,31.7],[1,1.26,5.99],[2,1.19,105.26]],"ltp":0.0,"tv":0.0,"id":60443},{"batb":[[0,1.4,21.4],[1,1.39,51.28],[2,1.37,10]],"ltp":0.0,"tv":0.0,"id":31376}]}]}
{"op":"mcm","clk":"11895357444","pt":1723875767004,"mc":[{"id":"1.231812839","rc":[{"batb":[[0,1.26,5.99],[1,1.19,105.26],[2,1.03,200]],"ltp":0.0,"tv":0.0,"id":60443},{"batb":[[0,1.39,51.28],[1,1.37,10],[2,1.03,200]],"ltp":0.0,"tv":0.0,"id":31376}]}]}
{"op":"mcm","clk":"11895365288","pt":1723875953805,"mc":[{"id":"1.231812839","rc":[{"batb":[[0,1.27,31.7],[1,1.26,5.99],[2,1.19,105.26]],"ltp":0.0,"tv":0.0,"id":60443},{"batb":[[0,1.4,21.4],[1,1.39,51.28],[2,1.37,10]],"ltp":0.0,"tv":0.0,"id":31376}]}]}
{"op":"mcm","clk":"11895457466","pt":1723877754234,"mc":[{"id":"1.231812839","rc":[{"batb":[[0,1.26,5.99],[1,1.19,105.26],[2,1.03,200]],"ltp":0.0,"tv":0.0,"id":60443},{"batb":[[0,1.39,51.28],[1,1.37,10],[2,1.03,200]],"ltp":0.0,"tv":0.0,"id":31376}]}]}
{"op":"mcm","clk":"11895467146","pt":1723877937158,"mc":[{"id":"1.231812839","rc":[{"batb":[[0,1.27,31.7],[1,1.26,5.99],[2,1.19,105.26]],"ltp":0.0,"tv":0.0,"id":60443},{"batb":[[0,1.4,21.4],[1,1.39,51.28],[2,1.37,10]],"ltp":0.0,"tv":0.0,"id":31376}]}]}
{"op":"mcm","clk":"11895575169","pt":1723879737632,"mc":[{"id":"1.231812839","rc":[{"batb":[[0,1.26,5.99],[1,1.19,105.26],[2,1.03,200]],"ltp":0.0,"tv":0.0,"id":60443},{"batb":[[0,1.39,51.28],[1,1.37,10],[2,1.03,200]],"ltp":0.0,"tv":0.0,"id":31376}]}]}
{"op":"mcm","clk":"11895586747","pt":1723879917026,"mc":[{"id":"1.231812839","rc":[{"batb":[[0,1.27,31.7],[1,1.26,5.99],[2,1.19,105.26]],"ltp":0.0,"tv":0.0,"id":60443},{"batb":[[0,1.4,21.4],[1,1.39,51.28],[2,1.37,10]],"ltp":0.0,"tv":0.0,"id":31376}]}]}
{"op":"mcm","clk":"11895704947","pt":1723881717349,"mc":[{"id":"1.231812839","rc":[{"batb":[[0,1.26,5.99],[1,1.19,105.26],[2,1.03,200]],"ltp":0.0,"tv":0.0,"id":60443},{"batb":[[0,1.39,51.28],[1,1.37,10],[2,1.03,200]],"ltp":0.0,"tv":0.0,"id":31376}]}]}
{"op":"mcm","clk":"11895718363","pt":1723881896848,"mc":[{"id":"1.231812839","rc":[{"batb":[[0,1.27,31.7],[1,1.26,5.99],[2,1.19,105.26]],"ltp":0.0,"tv":0.0,"id":60443},{"batb":[[0,1.4,21.4],[1,1.39,51.28],[2,1.37,10]],"ltp":0.0,"tv":0.0,"id":31376}]}]}
{"op":"mcm","clk":"11895880805","pt":1723883697253,"mc":[{"id":"1.231812839","rc":[{"batb":[[0,1.26,5.99],[1,1.19,105.26],[2,1.03,200]],"ltp":0.0,"tv":0.0,"id":60443},{"batb":[[0,1.39,51.28],[1,1.37,10],[2,1.03,200]],"ltp":0.0,"tv":0.0,"id":31376}]}]}
{"op":"mcm","clk":"11895895637","pt":1723883876067,"mc":[{"id":"1.231812839","rc":[{"batb":[[0,1.27,31.7],[1,1.26,5.99],[2,1.19,105.26]],"ltp":0.0,"tv":0.0,"id":60443},{"batb":[[0,1.4,21.4],[1,1.39,51.28],[2,1.37,10]],"ltp":0.0,"tv":0.0,"id":31376}]}]}
{"op":"mcm","clk":"11896069798","pt":1723885676394,"mc":[{"id":"1.231812839","rc":[{"batb":[[0,1.26,5.99],[1,1.19,105.26],[2,1.03,200]],"ltp":0.0,"tv":0.0,"id":60443},{"batb":[[0,1.39,51.28],[1,1.37,10],[2,1.03,200]],"ltp":0.0,"tv":0.0,"id":31376}]}]}
{"op":"mcm","clk":"11896090748","pt":1723885855567,"mc":[{"id":"1.231812839","rc":[{"batb":[[0,1.27,31.7],[1,1.26,5.99],[2,1.19,105.26]],"ltp":0.0,"tv":0.0,"id":60443},{"batb":[[0,1.4,21.4],[1,1.39,51.28],[2,1.37,10]],"ltp":0.0,"tv":0.0,"id":31376}]}]}
{"op":"mcm","clk":"11896106381","pt":1723885989843,"mc":[{"id":"1.231812839","rc":[{"batl":[[0,1.26,3.86],[1,95,5],[2,990,5]],"ltp":1.15,"tv":5.99,"id":3961}]}]}
{"op":"mcm","clk":"11896107242","pt":1723885997038,"mc":[{"id":"1.231812839","rc":[{"batl":[[0,95,5],[1,990,5],[2,990,0]],"ltp":1.15,"tv":5.99,"id":3961}]}]}
{"op":"mcm","clk":"11896305976","pt":1723887655718,"mc":[{"id":"1.231812839","rc":[{"batb":[[0,1.39,51.28],[1,1.37,10],[2,1.03,200]],"ltp":0.0,"tv":0.0,"id":31376}]}]}
{"op":"mcm","clk":"11896305996","pt":1723887655925,"mc":[{"id":"1.231812839","rc":[{"batb":[[0,1.26,5.99],[1,1.19,105.26],[2,1.03,200]],"ltp":0.0,"tv":0.0,"id":60443}]}]}
{"op":"mcm","clk":"11896342030","pt":1723887834002,"mc":[{"id":"1.231812839","rc":[{"batb":[[0,1.27,31.7],[1,1.26,5.99],[2,1.19,105.26]],"ltp":0.0,"tv":0.0,"id":60443},{"batb":[[0,1.4,21.4],[1,1.39,51.28],[2,1.37,10]],"ltp":0.0,"tv":0.0,"id":31376}]}]}
{"op":"mcm","clk":"11896606068","pt":1723889634396,"mc":[{"id":"1.231812839","rc":[{"batb":[[0,1.26,5.99],[1,1.19,105.26],[2,1.03,200]],"ltp":0.0,"tv":0.0,"id":60443},{"batb":[[0,1.39,51.28],[1,1.37,10],[2,1.03,200]],"ltp":0.0,"tv":0.0,"id":31376}]}]}
{"op":"mcm","clk":"11896633405","pt":1723889798785,"mc":[{"id":"1.231812839","rc":[{"batb":[[0,1.27,31.7],[1,1.26,5.99],[2,1.19,105.26]],"ltp":0.0,"tv":0.0,"id":60443},{"batb":[[0,1.4,21.4],[1,1.39,51.28],[2,1.37,10]],"ltp":0.0,"tv":0.0,"id":31376}]}]}
{"op":"mcm","clk":"11896708273","pt":1723890240903,"mc":[{"id":"1.231812839","rc":[{"batb":[[0,1.41,10],[1,1.4,21.4],[2,1.39,51.28]],"ltp":0.0,"tv":0.0,"id":31376}]}]}
{"op":"mcm","clk":"11896955357","pt":1723891599386,"mc":[{"id":"1.231812839","rc":[{"batb":[[0,1.26,5.99],[1,1.19,105.26],[2,1.03,200]],"ltp":0.0,"tv":0.0,"id":60443},{"batb":[[1,1.39,51.28],[2,1.03,200]],"ltp":0.0,"tv":0.0,"id":31376}]}]}
{"op":"mcm","clk":"11896982825","pt":1723891756942,"mc":[{"id":"1.231812839","rc":[{"batb":[[0,1.27,31.7],[1,1.26,5.99],[2,1.19,105.26]],"ltp":0.0,"tv":0.0,"id":60443},{"batb":[[0,1.42,20.38],[1,1.41,10],[2,1.39,51.28]],"ltp":0.0,"tv":0.0,"id":31376}]}]}
{"op":"mcm","clk":"11897296574","pt":1723893557373,"mc":[{"id":"1.231812839","rc":[{"batb":[[0,1.26,5.99],[1,1.19,105.26],[2,1.03,200]],"ltp":0.0,"tv":0.0,"id":60443},{"batb":[[0,1.41,10],[1,1.39,51.28],[2,1.03,200]],"ltp":0.0,"tv":0.0,"id":31376}]}]}
{"op":"mcm","clk":"11897325933","pt":1723893703526,"mc":[{"id":"1.231812839","rc":[{"batb":[[0,1.27,31.7],[1,1.26,5.99],[2,1.19,105.26]],"ltp":0.0,"tv":0.0,"id":60443},{"batb":[[0,1.42,20.38],[1,1.41,10],[2,1.39,51.28]],"ltp":0.0,"tv":0.0,"id":31376}]}]}
{"op":"mcm","clk":"11897702502","pt":1723895503723,"mc":[{"id":"1.231812839","rc":[{"batb":[[0,1.41,10],[1,1.39,51.28],[2,1.03,200]],"ltp":0.0,"tv":0.0,"id":31376}]}]}
{"op":"mcm","clk":"11897702535","pt":1723895503938,"mc":[{"id":"1.231812839","rc":[{"batb":[[0,1.26,5.99],[1,1.19,105.26],[2,1.03,200]],"ltp":0.0,"tv":0.0,"id":60443}]}]}
{"op":"mcm","clk":"11897725977","pt":1723895634058,"mc":[{"id":"1.231812839","rc":[{"batb":[[0,1.27,31.7],[1,1.26,5.99],[2,1.19,105.26]],"ltp":0.0,"tv":0.0,"id":60443},{"batb":[[0,1.42,20.38],[1,1.41,10],[2,1.39,51.28]],"ltp":0.0,"tv":0.0,"id":31376}]}]}
{"op":"mcm","clk":"11898015487","pt":1723897434446,"mc":[{"id":"1.231812839","rc":[{"batb":[[0,1.26,5.99],[1,1.19,105.26],[2,1.03,200]],"ltp":0.0,"tv":0.0,"id":60443},{"batb":[[0,1.41,10],[1,1.39,51.28],[2,1.03,200]],"ltp":0.0,"tv":0.0,"id":31376}]}]}
{"op":"mcm","clk":"11898029281","pt":1723897520963,"mc":[{"id":"1.231812839","rc":[{"batb":[[0,1.27,31.7],[1,1.26,5.99],[2,1.19,105.26]],"ltp":0.0,"tv":0.0,"id":60443},{"batb":[[0,1.42,20.38],[1,1.41,10],[2,1.39,51.28]],"ltp":0.0,"tv":0.0,"id":31376}]}]}
{"op":"mcm","clk":"11898327815","pt":1723899321165,"mc":[{"id":"1.231812839","rc":[{"batb":[[0,1.26,5.99],[1,1.19,105.26],[2,1.03,200]],"ltp":0.0,"tv":0.0,"id":60443},{"batb":[[0,1.41,10],[1,1.39,51.28],[2,1.03,200]],"ltp":0.0,"tv":0.0,"id":31376}]}]}
{"op":"mcm","clk":"11898336935","pt":1723899379627,"mc":[{"id":"1.231812839","rc":[{"batb":[[0,1.27,31.7],[1,1.26,5.99],[2,1.19,105.26]],"ltp":0.0,"tv":0.0,"id":60443},{"batb":[[0,1.42,20.38],[1,1.41,10],[2,1.39,51.28]],"ltp":0.0,"tv":0.0,"id":31376}]}]}
{"op":"mcm","clk":"11898479302","pt":1723900221376,"mc":[{"id":"1.231812839","rc":[{"batb":[[0,1.11,19.59],[1,1.1,200],[2,1.03,200]],"batl":[[0,95,5.85]],"ltp":1.15,"tv":5.99,"id":3961},{"batb":[[0,1.28,44.3],[1,1.27,31.7],[2,1.26,5.99]],"batl":[[0,90,1.05],[1,95,5],[2,990,5]],"ltp":0.0,"tv":0.0,"id":60443},{"batb":[[0,1.43,9.37],[1,1.42,20.38],[2,1.41,10]],"batl":[[0,95,5.85]],"ltp":0.0,"tv":0.0,"id":31376}]}]}
{"op":"mcm","clk":"11898642850","pt":1723901180018,"mc":[{"id":"1.231812839","rc":[{"batb":[[1,1.26,5.99],[2,1.19,105.26]],"ltp":0.0,"tv":0.0,"id":60443},{"batb":[[1,1.41,10],[2,1.39,51.28]],"ltp":0.0,"tv":0.0,"id":31376}]}]}
{"op":"mcm","clk":"11898646959","pt":1723901206617,"mc":[{"id":"1.231812839","rc":[{"batb":[[0,1.29,29.52],[1,1.28,44.3],[2,1.26,5.99]],"ltp":0.0,"tv":0.0,"id":60443},{"batb":[[0,1.44,19.45],[1,1.43,9.37],[2,1.41,10]],"ltp":0.0,"tv":0.0,"id":31376}]}]}
{"op":"mcm","clk":"11898722952","pt":1723901675862,"mc":[{"id":"1.231812839","rc":[{"batb":[[2,1.19,105.26]],"ltp":0.0,"tv":0.0,"id":60443}]}]}
{"op":"mcm","clk":"11898923474","pt":1723903006719,"mc":[{"id":"1.231812839","rc":[{"batb":[[0,1.43,9.37],[1,1.41,10],[2,1.39,51.28]],"ltp":0.0,"tv":0.0,"id":31376}]}]}
{"op":"mcm","clk":"11898923506","pt":1723903006934,"mc":[{"id":"1.231812839","rc":[{"batb":[[0,1.28,44.3],[1,1.19,105.26],[2,1.03,200]],"ltp":0.0,"tv":0.0,"id":60443}]}]}
{"op":"mcm","clk":"11898951503","pt":1723903192172,"mc":[{"id":"1.231812839","rc":[{"batb":[[0,1.29,29.52],[1,1.28,44.3],[2,1.19,105.26]],"ltp":0.0,"tv":0.0,"id":60443},{"batb":[[0,1.44,19.45],[1,1.43,9.37],[2,1.41,10]],"ltp":0.0,"tv":0.0,"id":31376}]}]}
{"op":"mcm","clk":"11899448634","pt":1723904992573,"mc":[{"id":"1.231812839","rc":[{"batb":[[0,1.28,44.3],[1,1.19,105.26],[2,1.03,200]],"ltp":0.0,"tv":0.0,"id":60443},{"batb":[[0,1.43,9.37],[1,1.41,10],[2,1.39,51.28]],"ltp":0.0,"tv":0.0,"id":31376}]}]}
{"op":"mcm","clk":"11899485598","pt":1723905125673,"mc":[{"id":"1.231812839","rc":[{"batb":[[0,1.29,29.52],[1,1.28,44.3],[2,1.19,105.26]],"ltp":0.0,"tv":0.0,"id":60443},{"batb":[[0,1.44,19.45],[1,1.43,9.37],[2,1.41,10]],"ltp":0.0,"tv":0.0,"id":31376}]}]}
{"op":"mcm","clk":"11899897951","pt":1723906926058,"mc":[{"id":"1.231812839","rc":[{"batb":[[0,1.28,44.3],[1,1.19,105.26],[2,1.03,200]],"ltp":0.0,"tv":0.0,"id":60443},{"batb":[[0,1.43,9.37],[1,1.41,10],[2,1.39,51.28]],"ltp":0.0,"tv":0.0,"id":31376}]}]}
{"op":"mcm","clk":"11899920926","pt":1723907036334,"mc":[{"id":"1.231812839","rc":[{"batb":[[0,1.29,29.52],[1,1.28,44.3],[2,1.19,105.26]],"ltp":0.0,"tv":0.0,"id":60443},{"batb":[[0,1.44,19.45],[1,1.43,9.37],[2,1.41,10]],"ltp":0.0,"tv":0.0,"id":31376}]}]}
{"op":"mcm","clk":"11900389379","pt":1723908836549,"mc":[{"id":"1.231812839","rc":[{"batb":[[0,1.28,44.3],[1,1.19,105.26],[2,1.03,200]],"ltp":0.0,"tv":0.0,"id":60443}]}]}
{"op":"mcm","clk":"11900389428","pt":1723908836766,"mc":[{"id":"1.231812839","rc":[{"batb":[[0,1.43,9.37],[1,1.41,10],[2,1.39,51.28]],"ltp":0.0,"tv":0.0,"id":31376}]}]}
{"op":"mcm","clk":"11900404141","pt":1723908897756,"mc":[{"id":"1.231812839","rc":[{"batb":[[0,1.29,29.52],[1,1.28,44.3],[2,1.19,105.26]],"ltp":0.0,"tv":0.0,"id":60443},{"batb":[[0,1.44,19.45],[1,1.43,9.37],[2,1.41,10]],"ltp":0.0,"tv":0.0,"id":31376}]}]}
{"op":"mcm","clk":"11900551275","pt":1723909438972,"mc":[{"id":"1.231812839","rc":[{"batb":[[0,1.3,44.3],[1,1.29,29.52]],"ltp":0.0,"tv":0.0,"id":60443},{"batb":[[0,1.45,9.37],[1,1.44,19.45]],"ltp":0.0,"tv":0.0,"id":31376}]}]}
{"op":"mcm","clk":"11900784857","pt":1723910698216,"mc":[{"id":"1.231812839","rc":[{"batb":[[1,1.19,105.26],[2,1.03,200]],"ltp":0.0,"tv":0.0,"id":60443},{"batb":[[1,1.41,10],[2,1.39,51.28]],"ltp":0.0,"tv":0.0,"id":31376}]}]}
{"op":"mcm","clk":"11900814476","pt":1723910860284,"mc":[{"id":"1.231812839","rc":[{"batb":[[0,1.31,27.61],[1,1.3,44.3],[2,1.19,105.26]],"ltp":0.0,"tv":0.0,"id":60443},{"batb":[[0,1.46,18.61],[1,1.45,9.37],[2,1.41,10]],"ltp":0.0,"tv":0.0,"id":31376}]}]}
{"op":"mcm","clk":"11901130138","pt":1723912661378,"mc":[{"id":"1.231812839","rc":[{"batb":[[0,1.3,44.3],[1,1.19,105.26],[2,1.03,200]],"ltp":0.0,"tv":0.0,"id":60443},{"batb":[[0,1.45,9.37],[1,1.41,10],[2,1.39,51.28]],"ltp":0.0,"tv":0.0,"id":31376}]}]}
{"op":"mcm","clk":"11901154472","pt":1723912780064,"mc":[{"id":"1.231812839","rc":[{"batb":[[0,1.31,27.61],[1,1.3,44.3],[2,1.19,105.26]],"ltp":0.0,"tv":0.0,"id":60443},{"batb":[[0,1.46,18.61],[1,1.45,9.37],[2,1.41,10]],"ltp":0.0,"tv":0.0,"id":31376}]}]}
{"op":"mcm","clk":"11901463878","pt":1723914580585,"mc":[{"id":"1.231812839","rc":[{"batb":[[0,1.3,44.3],[1,1.19,105.26],[2,1.03,200]],"ltp":0.0,"tv":0.0,"id":60443},{"batb":[[0,1.45,9.37],[1,1.41,10],[2,1.39,51.28]],"ltp":0.0,"tv":0.0,"id":31376}]}]}
{"op":"mcm","clk":"11901473557","pt":1723914639942,"mc":[{"id":"1.231812839","rc":[{"batb":[[0,1.31,27.61],[1,1.3,44.3],[2,1.19,105.26]],"ltp":0.0,"tv":0.0,"id":60443},{"batb":[[0,1.46,18.61],[1,1.45,9.37],[2,1.41,10]],"ltp":0.0,"tv":0.0,"id":31376}]}]}
{"op":"mcm","clk":"11901808248","pt":1723916440374,"mc":[{"id":"1.231812839","rc":[{"batb":[[0,1.3,44.3],[1,1.19,105.26],[2,1.03,200]],"ltp":0.0,"tv":0.0,"id":60443},{"batb":[[0,1.45,9.37],[1,1.41,10],[2,1.39,51.28]],"ltp":0.0,"tv":0.0,"id":31376}]}]}
{"op":"mcm","clk":"11901809204","pt":1723916445603,"mc":[{"id":"1.231812839","rc":[{"batb":[[0,1.31,27.61],[1,1.3,44.3],[2,1.19,105.26]],"ltp":0.0,"tv":0.0,"id":60443},{"batb":[[0,1.46,18.61],[1,1.45,9.37],[2,1.41,10]],"ltp":0.0,"tv":0.0,"id":31376}]}]}
{"op":"mcm","clk":"11902135265","pt":1723918245685,"mc":[{"id":"1.231812839","rc":[{"batb":[[0,1.45,9.37],[1,1.41,10],[2,1.39,51.28]],"ltp":0.0,"tv":0.0,"id":31376}]}]}
{"op":"mcm","clk":"11902135342","pt":1723918245994,"mc":[{"id":"1.231812839","rc":[{"batb":[[0,1.3,44.3],[1,1.19,105.26],[2,1.03,200]],"ltp":0.0,"tv":0.0,"id":60443}]}]}
{"op":"mcm","clk":"11902157657","pt":1723918352199,"mc":[{"id":"1.231812839","rc":[{"batb":[[0,1.31,27.61],[1,1.3,44.3],[2,1.19,105.26]],"ltp":0.0,"tv":0.0,"id":60443},{"batb":[[0,1.46,18.61],[1,1.45,9.37],[2,1.41,10]],"ltp":0.0,"tv":0.0,"id":31376}]}]}
{"op":"mcm","clk":"11902553870","pt":1723920152583,"mc":[{"id":"1.231812839","rc":[{"batb":[[0,1.3,44.3],[1,1.19,105.26],[2,1.03,200]],"ltp":0.0,"tv":0.0,"id":60443},{"batb":[[0,1.45,9.37],[1,1.41,10],[2,1.39,51.28]],"ltp":0.0,"tv":0.0,"id":31376}]}]}
{"op":"mcm","clk":"11902574027","pt":1723920189842,"mc":[{"id":"1.231812839","rc":[{"batb":[[0,1.31,27.61],[1,1.3,44.3],[2,1.19,105.26]],"ltp":0.0,"tv":0.0,"id":60443},{"batb":[[0,1.46,18.61],[1,1.45,9.37],[2,1.41,10]],"ltp":0.0,"tv":0.0,"id":31376}]}]}
{"op":"mcm","clk":"11902776048","pt":1723921153487,"mc":[{"id":"1.231812839","rc":[{"batb":[[1,1.03,200],[2,1.02,200]],"ltp":1.15,"tv":5.99,"id":3961}]}]}
{"op":"mcm","clk":"11902776447","pt":1723921155717,"mc":[{"id":"1.231812839","rc":[{"batb":[[0,1.12,166.67],[1,1.11,19.59],[2,1.03,200]],"ltp":1.15,"tv":5.99,"id":3961}]}]}
{"op":"mcm","clk":"11902776744","pt":1723921157219,"mc":[{"id":"1.231812839","rc":[{"batb":[[2,1.03,200]],"ltp":0.0,"tv":0.0,"id":60443}]}]}
{"op":"mcm","clk":"11902777051","pt":1723921158705,"mc":[{"id":"1.231812839","rc":[{"batb":[[0,1.32,62.5],[1,1.31,27.61],[2,1.3,44.3]],"ltp":0.0,"tv":0.0,"id":60443}]}]}
{"op":"mcm","clk":"11902944870","pt":1723921990286,"mc":[{"id":"1.231812839","rc":[{"batb":[[1,1.3,44.3],[2,1.03,200]],"ltp":0.0,"tv":0.0,"id":60443},{"batb":[[0,1.45,9.37],[1,1.41,10],[2,1.1,200]],"ltp":0.0,"tv":0.0,"id":31376}]}]}
{"op":"mcm","clk":"11902971158","pt":1723922113198,"mc":[{"id":"1.231812839","rc":[{"batb":[[0,1.33,25.94],[1,1.32,62.5],[2,1.3,44.3]],"ltp":0.0,"tv":0.0,"id":60443},{"batb":[[0,1.46,18.61],[1,1.45,9.37],[2,1.41,10]],"ltp":0.0,"tv":0.0,"id":31376}]}]}
{"op":"mcm","clk":"11903056855","pt":1723922501390,"mc":[{"id":"1.231812839","rc":[{"batb":[[0,1.34,6.32],[1,1.33,25.94],[2,1.32,62.5]],"ltp":0.0,"tv":0.0,"id":60443}]}]}
{"op":"mcm","clk":"11903353289","pt":1723923913629,"mc":[{"id":"1.231812839","rc":[{"batb":[[1,1.32,62.5],[2,1.3,44.3]],"ltp":0.0,"tv":0.0,"id":60443},{"batb":[[0,1.45,9.37],[1,1.41,10],[2,1.1,200]],"ltp":0.0,"tv":0.0,"id":31376}]}]}
{"op":"mcm","clk":"11903368491","pt":1723923996400,"mc":[{"id":"1.231812839","rc":[{"batb":[[0,1.35,24.46],[1,1.34,6.32],[2,1.32,62.5]],"ltp":0.0,"tv":0.0,"id":60443},{"batb":[[0,1.46,18.61],[1,1.45,9.37],[2,1.41,10]],"ltp":0.0,"tv":0.0,"id":31376}]}]}
{"op":"mcm","clk":"11903692013","pt":1723925795704,"mc":[{"id":"1.231812839","rc":[{"batb":[[1,1.33,6.32]],"ltp":0.0,"tv":0.0,"id":60443}]}]}
{"op":"mcm","clk":"11903692153","pt":1723925796602,"mc":[{"id":"1.231812839","rc":[{"batb":[[0,1.33,6.32],[1,1.32,62.5],[2,1.3,44.3]],"ltp":0.0,"tv":0.0,"id":60443}]}]}
{"op":"mcm","clk":"11903692204","pt":1723925796922,"mc":[{"id":"1.231812839","rc":[{"batb":[[0,1.45,9.37],[1,1.41,10],[2,1.1,200]],"ltp":0.0,"tv":0.0,"id":31376}]}]}
{"op":"mcm","clk":"11903695171","pt":1723925814459,"mc":[{"id":"1.231812839","rc":[{"batb":[[0,1.34,25.18],[1,1.33,6.32],[2,1.32,62.5]],"ltp":0.0,"tv":0.0,"id":60443},{"batb":[[0,1.46,18.61],[1,1.45,9.37],[2,1.41,10]],"ltp":0.0,"tv":0.0,"id":31376}]}]}
{"op":"mcm","clk":"11903961931","pt":1723927614719,"mc":[{"id":"1.231812839","rc":[{"batb":[[0,1.33,6.32],[1,1.32,62.5],[2,1.3,44.3]],"ltp":0.0,"tv":0.0,"id":60443}]}]}
{"op":"mcm","clk":"11903961968","pt":1723927614988,"mc":[{"id":"1.231812839","rc":[{"batb":[[0,1.45,9.37],[1,1.41,10],[2,1.1,200]],"ltp":0.0,"tv":0.0,"id":31376}]}]}
{"op":"mcm","clk":"11903969788","pt":1723927679967,"mc":[{"id":"1.231812839","rc":[{"batb":[[0,1.34,25.18],[1,1.33,6.32],[2,1.32,62.5]],"ltp":0.0,"tv":0.0,"id":60443},{"batb":[[0,1.46,18.61],[1,1.45,9.37],[2,1.41,10]],"ltp":0.0,"tv":0.0,"id":31376}]}]}
{"op":"mcm","clk":"11904108168","pt":1723929226587,"mc":[{"id":"1.231812839","rc":[{"batb":[[0,1.35,6.32],[1,1.34,25.18]],"ltp":0.0,"tv":0.0,"id":60443}]}]}
{"op":"mcm","clk":"11904130098","pt":1723929480404,"mc":[{"id":"1.231812839","rc":[{"batb":[[1,1.32,62.5],[2,1.3,44.3]],"ltp":0.0,"tv":0.0,"id":60443},{"batb":[[0,1.45,9.37],[1,1.41,10],[2,1.1,200]],"ltp":0.0,"tv":0.0,"id":31376}]}]}
{"op":"mcm","clk":"11904136950","pt":1723929562687,"mc":[{"id":"1.231812839","rc":[{"batb":[[0,1.36,23.78],[1,1.35,6.32],[2,1.32,62.5]],"ltp":0.0,"tv":0.0,"id":60443},{"batb":[[0,1.46,18.61],[1,1.45,9.37],[2,1.41,10]],"ltp":0.0,"tv":0.0,"id":31376}]}]}
{"op":"mcm","clk":"11904315294","pt":1723931363146,"mc":[{"id":"1.231812839","rc":[{"batb":[[0,1.35,6.32],[1,1.32,62.5],[2,1.3,44.3]],"ltp":0.0,"tv":0.0,"id":60443},{"batb":[[0,1.45,9.37],[1,1.41,10],[2,1.1,200]],"ltp":0.0,"tv":0.0,"id":31376}]}]}
{"op":"mcm","clk":"11904317469","pt":1723931390041,"mc":[{"id":"1.231812839","rc":[{"batb":[[0,1.36,23.78],[1,1.35,6.32],[2,1.32,62.5]],"ltp":0.0,"tv":0.0,"id":60443},{"batb":[[0,1.46,18.61],[1,1.45,9.37],[2,1.41,10]],"ltp":0.0,"tv":0.0,"id":31376}]}]}
{"op":"mcm","clk":"11904401575","pt":1723932495100,"mc":[{"id":"1.231812839","rc":[{"batb":[[1,1.33,6.32]],"ltp":0.0,"tv":0.0,"id":60443}]}]}
{"op":"mcm","clk":"11904454036","pt":1723933190482,"mc":[{"id":"1.231812839","rc":[{"batb":[[0,1.33,6.32],[1,1.32,62.5],[2,1.3,44.3]],"ltp":0.0,"tv":0.0,"id":60443},{"batb":[[0,1.45,9.37],[1,1.41,10],[2,1.1,200]],"ltp":0.0,"tv":0.0,"id":31376}]}]}
{"op":"mcm","clk":"11904460980","pt":1723933294815,"mc":[{"id":"1.231812839","rc":[{"batb":[[0,1.34,25.18],[1,1.33,6.32],[2,1.32,62.5]],"ltp":0.0,"tv":0.0,"id":60443},{"batb":[[0,1.46,18.61],[1,1.45,9.37],[2,1.41,10]],"ltp":0.0,"tv":0.0,"id":31376}]}]}
{"op":"mcm","clk":"11904596080","pt":1723935095311,"mc":[{"id":"1.231812839","rc":[{"batb":[[0,1.33,6.32],[1,1.32,62.5],[2,1.3,44.3]],"ltp":0.0,"tv":0.0,"id":60443},{"batb":[[0,1.45,9.37],[1,1.41,10],[2,1.1,200]],"ltp":0.0,"tv":0.0,"id":31376}]}]}
{"op":"mcm","clk":"11904601064","pt":1723935160005,"mc":[{"id":"1.231812839","rc":[{"batb":[[0,1.34,25.18],[1,1.33,6.32],[2,1.32,62.5]],"ltp":0.0,"tv":0.0,"id":60443},{"batb":[[0,1.46,18.61],[1,1.45,9.37],[2,1.41,10]],"ltp":0.0,"tv":0.0,"id":31376}]}]}
{"op":"mcm","clk":"11904634985","pt":1723935625538,"mc":[{"id":"1.231812839","rc":[{"batb":[[0,1.35,6.32],[1,1.34,25.18]],"ltp":0.0,"tv":0.0,"id":60443}]}]}
{"op":"mcm","clk":"11904748306","pt":1723936960472,"mc":[{"id":"1.231812839","rc":[{"batb":[[1,1.32,62.5],[2,1.3,44.3]],"ltp":0.0,"tv":0.0,"id":60443},{"batb":[[0,1.45,9.37],[1,1.41,10],[2,1.1,200]],"ltp":0.0,"tv":0.0,"id":31376}]}]}
{"op":"mcm","clk":"11904754848","pt":1723937050476,"mc":[{"id":"1.231812839","rc":[{"batb":[[0,1.36,23.78],[1,1.35,6.32],[2,1.32,62.5]],"ltp":0.0,"tv":0.0,"id":60443},{"batb":[[0,1.46,18.61],[1,1.45,9.37],[2,1.41,10]],"ltp":0.0,"tv":0.0,"id":31376}]}]}
{"op":"mcm","clk":"11904877471","pt":1723938850653,"mc":[{"id":"1.231812839","rc":[{"batb":[[0,1.45,9.37],[1,1.41,10],[2,1.1,200]],"ltp":0.0,"tv":0.0,"id":31376}]}]}
{"op":"mcm","clk":"11904877487","pt":1723938850859,"mc":[{"id":"1.231812839","rc":[{"batb":[[0,1.35,6.32],[1,1.32,62.5],[2,1.3,44.3]],"ltp":0.0,"tv":0.0,"id":60443}]}]}
{"op":"mcm","clk":"11904884691","pt":1723938960104,"mc":[{"id":"1.231812839","rc":[{"batb":[[0,1.33,6.32]],"ltp":0.0,"tv":0.0,"id":60443}]}]}
{"op":"mcm","clk":"11904885097","pt":1723938966004,"mc":[{"id":"1.231812839","rc":[{"batb":[[0,1.34,25.18],[1,1.33,6.32],[2,1.32,62.5]],"ltp":0.0,"tv":0.0,"id":60443},{"batb":[[0,1.46,18.61],[1,1.45,9.37],[2,1.41,10]],"ltp":0.0,"tv":0.0,"id":31376}]}]}
{"op":"mcm","clk":"11905036638","pt":1723940766440,"mc":[{"id":"1.231812839","rc":[{"batb":[[0,1.33,6.32],[1,1.32,62.5],[2,1.3,44.3]],"ltp":0.0,"tv":0.0,"id":60443},{"batb":[[0,1.45,9.37],[1,1.41,10],[2,1.1,200]],"ltp":0.0,"tv":0.0,"id":31376}]}]}
{"op":"mcm","clk":"11905046378","pt":1723940875516,"mc":[{"id":"1.231812839","rc":[{"batb":[[0,1.34,25.18],[1,1.33,6.32],[2,1.32,62.5]],"ltp":0.0,"tv":0.0,"id":60443},{"batb":[[0,1.46,18.61],[1,1.45,9.37],[2,1.41,10]],"ltp":0.0,"tv":0.0,"id":31376}]}]}
{"op":"mcm","clk":"11905171792","pt":1723942149040,"mc":[{"id":"1.231812839","rc":[{"batb":[[0,1.35,6.32],[1,1.34,25.18]],"ltp":0.0,"tv":0.0,"id":60443}]}]}
{"op":"mcm","clk":"11905207658","pt":1723942675733,"mc":[{"id":"1.231812839","rc":[{"batb":[[1,1.32,62.5],[2,1.3,44.3]],"ltp":0.0,"tv":0.0,"id":60443}]}]}
{"op":"mcm","clk":"11905207670","pt":1723942675940,"mc":[{"id":"1.231812839","rc":[{"batb":[[0,1.45,9.37],[1,1.41,10],[2,1.1,200]],"ltp":0.0,"tv":0.0,"id":31376}]}]}
{"op":"mcm","clk":"11905213488","pt":1723942769124,"mc":[{"id":"1.231812839","rc":[{"batb":[[0,1.36,23.78],[1,1.35,6.32],[2,1.32,62.5]],"ltp":0.0,"tv":0.0,"id":60443},{"batb":[[0,1.46,18.61],[1,1.45,9.37],[2,1.41,10]],"ltp":0.0,"tv":0.0,"id":31376}]}]}
{"op":"mcm","clk":"11905337667","pt":1723944569611,"mc":[{"id":"1.231812839","rc":[{"batb":[[0,1.35,6.32],[1,1.32,62.5],[2,1.3,44.3]],"ltp":0.0,"tv":0.0,"id":60443},{"batb":[[0,1.45,9.37],[1,1.41,10],[2,1.1,200]],"ltp":0.0,"tv":0.0,"id":31376}]}]}
{"op":"mcm","clk":"11905343340","pt":1723944643902,"mc":[{"id":"1.231812839","rc":[{"batb":[[0,1.36,23.78],[1,1.35,6.32],[2,1.32,62.5]],"ltp":0.0,"tv":0.0,"id":60443},{"batb":[[0,1.46,18.61],[1,1.45,9.37],[2,1.41,10]],"ltp":0.0,"tv":0.0,"id":31376}]}]}
{"op":"mcm","clk":"11905389794","pt":1723945314287,"mc":[{"id":"1.231812839","rc":[{"batb":[[1,1.33,6.32]],"ltp":0.0,"tv":0.0,"id":60443}]}]}
{"op":"mcm","clk":"11905450978","pt":1723946444348,"mc":[{"id":"1.231812839","rc":[{"batb":[[0,1.33,6.32],[1,1.32,62.5],[2,1.3,44.3]],"ltp":0.0,"tv":0.0,"id":60443},{"batb":[[0,1.45,9.37],[1,1.41,10],[2,1.1,200]],"ltp":0.0,"tv":0.0,"id":31376}]}]}
{"op":"mcm","clk":"11905452972","pt":1723946489476,"mc":[{"id":"1.231812839","rc":[{"batb":[[0,1.34,25.18],[1,1.33,6.32],[2,1.32,62.5]],"ltp":0.0,"tv":0.0,"id":60443},{"batb":[[0,1.46,18.61],[1,1.45,9.37],[2,1.41,10]],"ltp":0.0,"tv":0.0,"id":31376}]}]}
{"op":"mcm","clk":"11905552992","pt":1723948289602,"mc":[{"id":"1.231812839","rc":[{"batb":[[0,1.45,9.37],[1,1.41,10],[2,1.1,200]],"ltp":0.0,"tv":0.0,"id":31376}]}]}
{"op":"mcm","clk":"11905553000","pt":1723948289808,"mc":[{"id":"1.231812839","rc":[{"batb":[[0,1.33,6.32],[1,1.32,62.5],[2,1.3,44.3]],"ltp":0.0,"tv":0.0,"id":60443}]}]}
{"op":"mcm","clk":"11905562544","pt":1723948467928,"mc":[{"id":"1.231812839","rc":[{"batb":[[0,1.34,25.18],[1,1.33,6.32],[2,1.32,62.5]],"ltp":0.0,"tv":0.0,"id":60443},{"batb":[[0,1.46,18.61],[1,1.45,9.37],[2,1.41,10]],"ltp":0.0,"tv":0.0,"id":31376}]}]}
{"op":"mcm","clk":"11905565551","pt":1723948525677,"mc":[{"id":"1.231812839","rc":[{"batb":[[0,1.35,6.32],[1,1.34,25.18]],"ltp":0.0,"tv":0.0,"id":60443}]}]}
{"op":"mcm","clk":"11905666378","pt":1723950268512,"mc":[{"id":"1.231812839","rc":[{"batb":[[1,1.32,62.5],[2,1.3,44.3]],"ltp":0.0,"tv":0.0,"id":60443},{"batb":[[0,1.45,9.37],[1,1.41,10],[2,1.1,200]],"ltp":0.0,"tv":0.0,"id":31376}]}]}
{"op":"mcm","clk":"11905675334","pt":1723950426277,"mc":[{"id":"1.231812839","rc":[{"batb":[[0,1.36,23.78],[1,1.35,6.32],[2,1.32,62.5]],"ltp":0.0,"tv":0.0,"id":60443},{"batb":[[0,1.46,18.61],[1,1.45,9.37],[2,1.41,10]],"ltp":0.0,"tv":0.0,"id":31376}]}]}
{"op":"mcm","clk":"11905733197","pt":1723951476711,"mc":[{"id":"1.231812839","rc":[{"batb":[[1,1.33,6.32]],"ltp":0.0,"tv":0.0,"id":60443}]}]}
{"op":"mcm","clk":"11905774831","pt":1723952226742,"mc":[{"id":"1.231812839","rc":[{"batb":[[0,1.33,6.32],[1,1.32,62.5],[2,1.3,44.3]],"ltp":0.0,"tv":0.0,"id":60443},{"batb":[[0,1.45,9.37],[1,1.41,10],[2,1.1,200]],"ltp":0.0,"tv":0.0,"id":31376}]}]}
{"op":"mcm","clk":"11905780722","pt":1723952354797,"mc":[{"id":"1.231812839","rc":[{"batb":[[0,1.34,25.18],[1,1.33,6.32],[2,1.32,62.5]],"ltp":0.0,"tv":0.0,"id":60443},{"batb":[[0,1.46,18.61],[1,1.45,9.37],[2,1.41,10]],"ltp":0.0,"tv":0.0,"id":31376}]}]}
{"op":"mcm","clk":"11905885409","pt":1723954155141,"mc":[{"id":"1.231812839","rc":[{"batb":[[0,1.33,6.32],[1,1.32,62.5],[2,1.3,44.3]],"ltp":0.0,"tv":0.0,"id":60443},{"batb":[[0,1.45,9.37],[1,1.41,10],[2,1.1,200]],"ltp":0.0,"tv":0.0,"id":31376}]}]}
{"op":"mcm","clk":"11905891678","pt":1723954265079,"mc":[{"id":"1.231812839","rc":[{"batb":[[0,1.34,25.18],[1,1.33,6.32],[2,1.32,62.5]],"ltp":0.0,"tv":0.0,"id":60443},{"batb":[[0,1.46,18.61],[1,1.45,9.37],[2,1.41,10]],"ltp":0.0,"tv":0.0,"id":31376}]}]}
{"op":"mcm","clk":"11905906054","pt":1723954556342,"mc":[{"id":"1.231812839","rc":[{"batb":[[0,1.35,6.32],[1,1.34,25.18]],"ltp":0.0,"tv":0.0,"id":60443}]}]}
{"op":"mcm","clk":"11905964661","pt":1723956065554,"mc":[{"id":"1.231812839","rc":[{"batb":[[1,1.32,62.5],[2,1.3,44.3]],"ltp":0.0,"tv":0.0,"id":60443},{"batb":[[0,1.45,9.37],[1,1.41,10],[2,1.1,200]],"ltp":0.0,"tv":0.0,"id":31376}]}]}
{"op":"mcm","clk":"11905968831","pt":1723956155962,"mc":[{"id":"1.231812839","rc":[{"batb":[[0,1.36,23.78],[1,1.35,6.32],[2,1.32,62.5]],"ltp":0.0,"tv":0.0,"id":60443},{"batb":[[0,1.46,18.61],[1,1.45,9.37],[2,1.41,10]],"ltp":0.0,"tv":0.0,"id":31376}]}]}
{"op":"mcm","clk":"11906022655","pt":1723957541007,"mc":[{"id":"1.231812839","rc":[{"batb":[[0,1.13,19.59],[1,1.12,166.67]],"ltp":1.15,"tv":5.99,"id":3961},{"batb":[[0,1.37,44.3],[1,1.36,23.78],[2,1.35,6.32]],"ltp":0.0,"tv":0.0,"id":60443},{"batb":[[0,1.47,9.37],[1,1.46,18.61]],"ltp":0.0,"tv":0.0,"id":31376}]}]}
{"op":"mcm","clk":"11906025394","pt":1723957612763,"mc":[{"id":"1.231812839","rc":[{"batb":[[2,1.32,62.5]],"ltp":0.0,"tv":0.0,"id":60443}]}]}
{"op":"mcm","clk":"11906025398","pt":1723957612864,"mc":[{"id":"1.231812839","rc":[{"batb":[[0,1.38,6.32],[1,1.37,44.3],[2,1.36,23.78]],"ltp":0.0,"tv":0.0,"id":60443}]}]}
{"op":"mcm","clk":"11906042976","pt":1723957956328,"mc":[{"id":"1.231812839","rc":[{"batb":[[2,1.32,62.5]],"ltp":0.0,"tv":0.0,"id":60443},{"batb":[[1,1.41,10],[2,1.1,200]],"ltp":0.0,"tv":0.0,"id":31376}]}]}
{"op":"mcm","clk":"11906057493","pt":1723958043501,"mc":[{"id":"1.231812839","rc":[{"batb":[[0,1.39,21.95],[1,1.38,6.32],[2,1.37,44.3]],"ltp":0.0,"tv":0.0,"id":60443},{"batb":[[0,1.48,17.83],[1,1.47,9.37],[2,1.41,10]],"ltp":0.0,"tv":0.0,"id":31376}]}]}
{"op":"mcm","clk":"11906137773","pt":1723959844168,"mc":[{"id":"1.231812839","rc":[{"batb":[[0,1.38,6.32],[1,1.37,44.3],[2,1.32,62.5]],"ltp":0.0,"tv":0.0,"id":60443},{"batb":[[0,1.47,9.37],[1,1.41,10],[2,1.1,200]],"ltp":0.0,"tv":0.0,"id":31376}]}]}
{"op":"mcm","clk":"11906140324","pt":1723959922049,"mc":[{"id":"1.231812839","rc":[{"batb":[[0,1.39,21.95],[1,1.38,6.32],[2,1.37,44.3]],"ltp":0.0,"tv":0.0,"id":60443},{"batb":[[0,1.48,17.83],[1,1.47,9.37],[2,1.41,10]],"ltp":0.0,"tv":0.0,"id":31376}]}]}
{"op":"mcm","clk":"11906224275","pt":1723961722410,"mc":[{"id":"1.231812839","rc":[{"batb":[[0,1.38,6.32],[1,1.37,44.3],[2,1.32,62.5]],"ltp":0.0,"tv":0.0,"id":60443},{"batb":[[0,1.47,9.37],[1,1.41,10],[2,1.1,200]],"ltp":0.0,"tv":0.0,"id":31376}]}]}
{"op":"mcm","clk":"11906227352","pt":1723961800770,"mc":[{"id":"1.231812839","rc":[{"batb":[[0,1.39,21.95],[1,1.38,6.32],[2,1.37,44.3]],"ltp":0.0,"tv":0.0,"id":60443},{"batb":[[0,1.48,17.83],[1,1.47,9.37],[2,1.41,10]],"ltp":0.0,"tv":0.0,"id":31376}]}]}
{"op":"mcm","clk":"11906252988","pt":1723962441758,"mc":[{"id":"1.231812839","rc":[{"batb":[[0,1.49,10],[1,1.48,17.83],[2,1.47,9.37]],"ltp":0.0,"tv":0.0,"id":31376}]}]}
{"op":"mcm","clk":"11906324476","pt":1723963601226,"mc":[{"id":"1.231812839","rc":[{"batb":[[0,1.38,6.32],[1,1.37,44.3],[2,1.32,62.5]],"ltp":0.0,"tv":0.0,"id":60443},{"batb":[[1,1.47,9.37],[2,1.1,200]],"ltp":0.0,"tv":0.0,"id":31376}]}]}
{"op":"mcm","clk":"11906328239","pt":1723963671826,"mc":[{"id":"1.231812839","rc":[{"batb":[[0,1.39,21.95],[1,1.38,6.32],[2,1.37,44.3]],"ltp":0.0,"tv":0.0,"id":60443},{"batb":[[0,1.5,17.12],[1,1.49,10],[2,1.47,9.37]],"ltp":0.0,"tv":0.0,"id":31376}]}]}
{"op":"mcm","clk":"11906416321","pt":1723965472268,"mc":[{"id":"1.231812839","rc":[{"batb":[[0,1.38,6.32],[1,1.37,44.3],[2,1.32,62.5]],"ltp":0.0,"tv":0.0,"id":60443},{"batb":[[0,1.49,10],[1,1.47,9.37],[2,1.1,200]],"ltp":0.0,"tv":0.0,"id":31376}]}]}
{"op":"mcm","clk":"11906420905","pt":1723965546209,"mc":[{"id":"1.231812839","rc":[{"batb":[[0,1.39,21.95],[1,1.38,6.32],[2,1.37,44.3]],"ltp":0.0,"tv":0.0,"id":60443},{"batb":[[0,1.5,17.12],[1,1.49,10],[2,1.47,9.37]],"ltp":0.0,"tv":0.0,"id":31376}]}]}
{"op":"mcm","clk":"11906538586","pt":1723967346615,"mc":[{"id":"1.231812839","rc":[{"batb":[[0,1.38,6.32],[1,1.37,44.3],[2,1.32,62.5]],"ltp":0.0,"tv":0.0,"id":60443},{"batb":[[0,1.49,10],[1,1.47,9.37],[2,1.1,200]],"ltp":0.0,"tv":0.0,"id":31376}]}]}
{"op":"mcm","clk":"11906547031","pt":1723967465138,"mc":[{"id":"1.231812839","rc":[{"batb":[[0,1.39,21.95],[1,1.38,6.32],[2,1.37,44.3]],"ltp":0.0,"tv":0.0,"id":60443},{"batb":[[0,1.5,17.12],[1,1.49,10],[2,1.47,9.37]],"ltp":0.0,"tv":0.0,"id":31376}]}]}
{"op":"mcm","clk":"11906703550","pt":1723969265566,"mc":[{"id":"1.231812839","rc":[{"batb":[[0,1.38,6.32],[1,1.37,44.3],[2,1.32,62.5]],"ltp":0.0,"tv":0.0,"id":60443},{"batb":[[0,1.49,10],[1,1.47,9.37],[2,1.1,200]],"ltp":0.0,"tv":0.0,"id":31376}]}]}
{"op":"mcm","clk":"11906704841","pt":1723969283211,"mc":[{"id":"1.231812839","rc":[{"batb":[[0,1.39,21.95],[1,1.38,6.32],[2,1.37,44.3]],"ltp":0.0,"tv":0.0,"id":60443},{"batb":[[0,1.5,17.12],[1,1.49,10],[2,1.47,9.37]],"ltp":0.0,"tv":0.0,"id":31376}]}]}
{"op":"mcm","clk":"11906707889","pt":1723969320539,"mc":[{"id":"1.231812839","rc":[{"batb":[[0,1.15,19.59]],"ltp":1.15,"tv":5.99,"id":3961},{"batb":[[0,1.4,44.3],[1,1.39,21.95],[2,1.38,6.32]],"ltp":0.0,"tv":0.0,"id":60443},{"batb":[[0,1.51,9.37],[1,1.5,17.12],[2,1.49,10]],"ltp":0.0,"tv":0.0,"id":31376}]}]}
{"op":"mcm","clk":"11906709352","pt":1723969336622,"mc":[{"id":"1.231812839","rc":[{"batb":[[0,1.51,5.96]],"ltp":0.0,"tv":0.0,"id":31376}]}]}
{"op":"mcm","clk":"11906727725","pt":1723969567575,"mc":[{"id":"1.231812839","rc":[{"batb":[[0,1.41,6.32],[1,1.4,44.3],[2,1.39,21.95]],"ltp":0.0,"tv":0.0,"id":60443}]}]}
{"op":"mcm","clk":"11906769677","pt":1723970021557,"mc":[{"id":"1.231812839","rc":[{"batb":[[0,1.9,30],[1,1.41,6.32],[2,1.4,44.3]],"ltp":0.0,"tv":0.0,"id":60443}]}]}
{"op":"mcm","clk":"11906870561","pt":1723971083560,"mc":[{"id":"1.231812839","rc":[{"batb":[[1,1.49,10],[2,1.1,200]],"ltp":0.0,"tv":0.0,"id":31376}]}]}
{"op":"mcm","clk":"11906872103","pt":1723971099384,"mc":[{"id":"1.231812839","rc":[{"batb":[[0,1.91,9.41],[1,1.9,30],[2,1.41,6.32]],"ltp":0.0,"tv":0.0,"id":60443},{"batb":[[0,1.52,16.46],[1,1.51,5.96],[2,1.49,10]],"ltp":0.0,"tv":0.0,"id":31376}]}]}
{"op":"mcm","clk":"11907041580","pt":1723972582655,"mc":[{"id":"1.231812839","rc":[{"batb":[[2,1.4,44.3]],"ltp":0.0,"tv":0.0,"id":60443}]}]}
{"op":"mcm","clk":"11907080755","pt":1723972899583,"mc":[{"id":"1.231812839","rc":[{"batb":[[0,1.51,5.96],[1,1.49,10],[2,1.1,200]],"ltp":0.0,"tv":0.0,"id":31376}]}]}
{"op":"mcm","clk":"11907080776","pt":1723972899792,"mc":[{"id":"1.231812839","rc":[{"batb":[[0,1.9,30],[1,1.4,44.3],[2,1.32,62.5]],"ltp":0.0,"tv":0.0,"id":60443}]}]}
{"op":"mcm","clk":"11907081858","pt":1723972908692,"mc":[{"id":"1.231812839","rc":[{"batb":[[0,1.52,16.46],[1,1.51,5.96],[2,1.49,10]],"ltp":0.0,"tv":0.0,"id":31376}]}]}
{"op":"mcm","clk":"11907081870","pt":1723972908789,"mc":[{"id":"1.231812839","rc":[{"batb":[[0,1.91,9.41],[1,1.9,30],[2,1.4,44.3]],"ltp":0.0,"tv":0.0,"id":60443}]}]}
{"op":"mcm","clk":"11907156312","pt":1723973527694,"mc":[{"id":"1.231812839","rc":[{"batb":[[0,1.5,20],[1,1.15,19.59],[2,1.12,166.67]],"ltp":1.15,"tv":5.99,"id":3961}]}]}
{"op":"mcm","clk":"11907157456","pt":1723973536621,"mc":[{"id":"1.231812839","rc":[{"batb":[[2,1.5,20]],"ltp":0.0,"tv":0.0,"id":31376}]}]}
{"op":"mcm","clk":"11907312099","pt":1723974709207,"mc":[{"id":"1.231812839","rc":[{"batb":[[0,1.9,30],[1,1.4,44.3],[2,1.32,62.5]],"ltp":0.0,"tv":0.0,"id":60443},{"batb":[[0,1.51,5.96],[1,1.5,20],[2,1.49,10]],"ltp":0.0,"tv":0.0,"id":31376}]}]}
{"op":"mcm","clk":"11907333004","pt":1723974887420,"mc":[{"id":"1.231812839","rc":[{"batb":[[0,1.91,9.41],[1,1.9,30],[2,1.4,44.3]],"ltp":0.0,"tv":0.0,"id":60443},{"batb":[[0,1.52,16.46],[1,1.51,5.96],[2,1.5,20]],"ltp":0.0,"tv":0.0,"id":31376}]}]}
{"op":"mcm","clk":"11907464824","pt":1723975940242,"mc":[{"id":"1.231812839","rc":[{"batb":[[1,1.51,15.96]],"ltp":0.0,"tv":0.0,"id":31376}]}]}
{"op":"mcm","clk":"11907465669","pt":1723975947179,"mc":[{"id":"1.231812839","rc":[{"batb":[[0,1.54,10],[1,1.52,16.46],[2,1.51,5.96]],"ltp":0.0,"tv":0.0,"id":31376}]}]}
{"op":"mcm","clk":"11907556925","pt":1723976687564,"mc":[{"id":"1.231812839","rc":[{"batb":[[0,1.9,30],[1,1.4,44.3],[2,1.32,62.5]],"ltp":0.0,"tv":0.0,"id":60443}]}]}
{"op":"mcm","clk":"11907556941","pt":1723976687774,"mc":[{"id":"1.231812839","rc":[{"batb":[[1,1.51,5.96],[2,1.5,20]],"ltp":0.0,"tv":0.0,"id":31376}]}]}
{"op":"mcm","clk":"11907576313","pt":1723976846890,"mc":[{"id":"1.231812839","rc":[{"batb":[[0,1.91,9.41],[1,1.9,30],[2,1.4,44.3]],"ltp":0.0,"tv":0.0,"id":60443},{"batb":[[0,1.55,15.56],[1,1.54,10],[2,1.51,5.96]],"ltp":0.0,"tv":0.0,"id":31376}]}]}
{"op":"mcm","clk":"11907800667","pt":1723978647193,"mc":[{"id":"1.231812839","rc":[{"batb":[[0,1.9,30],[1,1.4,44.3],[2,1.32,62.5]],"ltp":0.0,"tv":0.0,"id":60443},{"batb":[[0,1.54,10],[1,1.51,5.96],[2,1.5,20]],"ltp":0.0,"tv":0.0,"id":31376}]}]}
{"op":"mcm","clk":"11907814518","pt":1723978787574,"mc":[{"id":"1.231812839","rc":[{"batb":[[0,1.91,9.41],[1,1.9,30],[2,1.4,44.3]],"ltp":0.0,"tv":0.0,"id":60443},{"batb":[[0,1.55,15.56],[1,1.54,10],[2,1.51,5.96]],"ltp":0.0,"tv":0.0,"id":31376}]}]}
{"op":"mcm","clk":"11908061543","pt":1723980587954,"mc":[{"id":"1.231812839","rc":[{"batb":[[0,1.9,30],[1,1.4,44.3],[2,1.32,62.5]],"ltp":0.0,"tv":0.0,"id":60443},{"batb":[[0,1.54,10],[1,1.51,5.96],[2,1.5,20]],"ltp":0.0,"tv":0.0,"id":31376}]}]}
{"op":"mcm","clk":"11908073357","pt":1723980681856,"mc":[{"id":"1.231812839","rc":[{"batb":[[0,1.91,9.41],[1,1.9,30],[2,1.4,44.3]],"ltp":0.0,"tv":0.0,"id":60443},{"batb":[[0,1.55,15.56],[1,1.54,10],[2,1.51,5.96]],"ltp":0.0,"tv":0.0,"id":31376}]}]}
{"op":"mcm","clk":"11908222251","pt":1723981882691,"mc":[{"id":"1.231812839","rc":[{"batb":[[0,1.56,10],[1,1.55,15.56]],"ltp":0.0,"tv":0.0,"id":31376}]}]}
{"op":"mcm","clk":"11908285212","pt":1723982482256,"mc":[{"id":"1.231812839","rc":[{"batb":[[0,1.9,30],[1,1.4,44.3],[2,1.32,62.5]],"ltp":0.0,"tv":0.0,"id":60443},{"batb":[[1,1.51,5.96],[2,1.5,20]],"ltp":0.0,"tv":0.0,"id":31376}]}]}
{"op":"mcm","clk":"11908295980","pt":1723982570144,"mc":[{"id":"1.231812839","rc":[{"batb":[[0,1.91,9.41],[1,1.9,30],[2,1.4,44.3]],"ltp":0.0,"tv":0.0,"id":60443},{"batb":[[0,1.57,15.02],[1,1.56,10],[2,1.51,5.96]],"ltp":0.0,"tv":0.0,"id":31376}]}]}
{"op":"mcm","clk":"11908580565","pt":1723984370746,"mc":[{"id":"1.231812839","rc":[{"batb":[[0,1.9,30],[1,1.4,44.3],[2,1.32,62.5]],"ltp":0.0,"tv":0.0,"id":60443},{"batb":[[0,1.56,10],[1,1.51,5.96],[2,1.5,20]],"ltp":0.0,"tv":0.0,"id":31376}]}]}
{"op":"mcm","clk":"11908589211","pt":1723984425240,"mc":[{"id":"1.231812839","rc":[{"batb":[[0,1.91,9.41],[1,1.9,30],[2,1.4,44.3]],"ltp":0.0,"tv":0.0,"id":60443},{"batb":[[0,1.57,15.02],[1,1.56,10],[2,1.51,5.96]],"ltp":0.0,"tv":0.0,"id":31376}]}]}
{"op":"mcm","clk":"11908846660","pt":1723986225729,"mc":[{"id":"1.231812839","rc":[{"batb":[[0,1.9,30],[1,1.4,44.3],[2,1.32,62.5]],"ltp":0.0,"tv":0.0,"id":60443},{"batb":[[0,1.56,10],[1,1.51,5.96],[2,1.5,20]],"ltp":0.0,"tv":0.0,"id":31376}]}]}
{"op":"mcm","clk":"11908851576","pt":1723986264135,"mc":[{"id":"1.231812839","rc":[{"batb":[[0,1.91,9.41],[1,1.9,30],[2,1.4,44.3]],"ltp":0.0,"tv":0.0,"id":60443},{"batb":[[0,1.57,15.02],[1,1.56,10],[2,1.51,5.96]],"ltp":0.0,"tv":0.0,"id":31376}]}]}
{"op":"mcm","clk":"11909135114","pt":1723988064520,"mc":[{"id":"1.231812839","rc":[{"batb":[[0,1.9,30],[1,1.4,44.3],[2,1.32,62.5]],"ltp":0.0,"tv":0.0,"id":60443},{"batb":[[0,1.56,10],[1,1.51,5.96],[2,1.5,20]],"ltp":0.0,"tv":0.0,"id":31376}]}]}
{"op":"mcm","clk":"11909160418","pt":1723988220289,"mc":[{"id":"1.231812839","rc":[{"batb":[[0,1.91,9.41],[1,1.9,30],[2,1.4,44.3]],"ltp":0.0,"tv":0.0,"id":60443},{"batb":[[0,1.57,15.02],[1,1.56,10],[2,1.51,5.96]],"ltp":0.0,"tv":0.0,"id":31376}]}]}
{"op":"mcm","clk":"11909196820","pt":1723988447837,"mc":[{"id":"1.231812839","rc":[{"batb":[[2,1.32,62.5]],"ltp":0.0,"tv":0.0,"id":60443},{"batb":[[2,1.5,20]],"ltp":0.0,"tv":0.0,"id":31376}]}]}
{"op":"mcm","clk":"11909424032","pt":1723990020731,"mc":[{"id":"1.231812839","rc":[{"batb":[[0,1.9,30],[1,1.32,62.5],[2,1.3,20]],"ltp":0.0,"tv":0.0,"id":60443},{"batb":[[0,1.56,10],[1,1.5,20],[2,1.1,200]],"ltp":0.0,"tv":0.0,"id":31376}]}]}
{"op":"mcm","clk":"11909440179","pt":1723990138228,"mc":[{"id":"1.231812839","rc":[{"batb":[[0,1.91,9.41],[1,1.9,30],[2,1.32,62.5]],"ltp":0.0,"tv":0.0,"id":60443},{"batb":[[0,1.57,15.02],[1,1.56,10],[2,1.5,20]],"ltp":0.0,"tv":0.0,"id":31376}]}]}
{"op":"mcm","clk":"11909722092","pt":1723991938579,"mc":[{"id":"1.231812839","rc":[{"batb":[[0,1.9,30],[1,1.32,62.5],[2,1.3,20]],"ltp":0.0,"tv":0.0,"id":60443},{"batb":[[0,1.56,10],[1,1.5,20],[2,1.1,200]],"ltp":0.0,"tv":0.0,"id":31376}]}]}
{"op":"mcm","clk":"11909738601","pt":1723992038125,"mc":[{"id":"1.231812839","rc":[{"batb":[[0,1.91,9.41],[1,1.9,30],[2,1.32,62.5]],"ltp":0.0,"tv":0.0,"id":60443},{"batb":[[0,1.57,15.02],[1,1.56,10],[2,1.5,20]],"ltp":0.0,"tv":0.0,"id":31376}]}]}
{"op":"mcm","clk":"11910045596","pt":1723993838488,"mc":[{"id":"1.231812839","rc":[{"batb":[[0,1.9,30],[1,1.32,62.5],[2,1.3,20]],"ltp":0.0,"tv":0.0,"id":60443},{"batb":[[0,1.56,10],[1,1.5,20],[2,1.1,200]],"ltp":0.0,"tv":0.0,"id":31376}]}]}
{"op":"mcm","clk":"11910064029","pt":1723993931767,"mc":[{"id":"1.231812839","rc":[{"batb":[[0,1.91,9.41],[1,1.9,30],[2,1.32,62.5]],"ltp":0.0,"tv":0.0,"id":60443},{"batb":[[0,1.57,15.02],[1,1.56,10],[2,1.5,20]],"ltp":0.0,"tv":0.0,"id":31376}]}]}
{"op":"mcm","clk":"11910410608","pt":1723995732281,"mc":[{"id":"1.231812839","rc":[{"batb":[[0,1.9,30],[1,1.32,62.5],[2,1.3,20]],"ltp":0.0,"tv":0.0,"id":60443},{"batb":[[0,1.56,10],[1,1.5,20],[2,1.1,200]],"ltp":0.0,"tv":0.0,"id":31376}]}]}
{"op":"mcm","clk":"11910436949","pt":1723995811558,"mc":[{"id":"1.231812839","rc":[{"batb":[[0,1.91,9.41],[1,1.9,30],[2,1.32,62.5]],"ltp":0.0,"tv":0.0,"id":60443},{"batb":[[0,1.57,15.02],[1,1.56,10],[2,1.5,20]],"ltp":0.0,"tv":0.0,"id":31376}]}]}
{"op":"mcm","clk":"11910784732","pt":1723997612131,"mc":[{"id":"1.231812839","rc":[{"batb":[[0,1.9,30],[1,1.32,62.5],[2,1.3,20]],"ltp":0.0,"tv":0.0,"id":60443},{"batb":[[0,1.56,10],[1,1.5,20],[2,1.1,200]],"ltp":0.0,"tv":0.0,"id":31376}]}]}
{"op":"mcm","clk":"11910791952","pt":1723997648351,"mc":[{"id":"1.231812839","rc":[{"batb":[[0,1.91,9.41],[1,1.9,30],[2,1.32,62.5]],"ltp":0.0,"tv":0.0,"id":60443},{"batb":[[0,1.57,15.02],[1,1.56,10],[2,1.5,20]],"ltp":0.0,"tv":0.0,"id":31376}]}]}
{"op":"mcm","clk":"11911143692","pt":1723999450173,"mc":[{"id":"1.231812839","rc":[{"batb":[[0,1.9,30],[1,1.32,62.5],[2,1.3,20]],"ltp":0.0,"tv":0.0,"id":60443},{"batb":[[0,1.56,10],[1,1.5,20],[2,1.1,200]],"ltp":0.0,"tv":0.0,"id":31376}]}]}
{"op":"mcm","clk":"11911172241","pt":1723999589780,"mc":[{"id":"1.231812839","rc":[{"batb":[[0,1.91,9.41],[1,1.9,30],[2,1.32,62.5]],"ltp":0.0,"tv":0.0,"id":60443},{"batb":[[0,1.57,15.02],[1,1.56,10],[2,1.5,20]],"ltp":0.0,"tv":0.0,"id":31376}]}]}
{"op":"mcm","clk":"11911465612","pt":1724001390319,"mc":[{"id":"1.231812839","rc":[{"batb":[[0,1.9,30],[1,1.32,62.5],[2,1.3,20]],"ltp":0.0,"tv":0.0,"id":60443},{"batb":[[0,1.56,10],[1,1.5,20],[2,1.1,200]],"ltp":0.0,"tv":0.0,"id":31376}]}]}
{"op":"mcm","clk":"11911473177","pt":1724001441066,"mc":[{"id":"1.231812839","rc":[{"batb":[[0,1.91,9.41],[1,1.9,30],[2,1.32,62.5]],"ltp":0.0,"tv":0.0,"id":60443},{"batb":[[0,1.57,15.02],[1,1.56,10],[2,1.5,20]],"ltp":0.0,"tv":0.0,"id":31376}]}]}
{"op":"mcm","clk":"11911734532","pt":1724003241668,"mc":[{"id":"1.231812839","rc":[{"batb":[[0,1.9,30],[1,1.32,62.5],[2,1.3,20]],"ltp":0.0,"tv":0.0,"id":60443},{"batb":[[0,1.56,10],[1,1.5,20],[2,1.1,200]],"ltp":0.0,"tv":0.0,"id":31376}]}]}
{"op":"mcm","clk":"11911747538","pt":1724003347569,"mc":[{"id":"1.231812839","rc":[{"batb":[[0,1.91,9.41],[1,1.9,30],[2,1.32,62.5]],"ltp":0.0,"tv":0.0,"id":60443},{"batb":[[0,1.57,15.02],[1,1.56,10],[2,1.5,20]],"ltp":0.0,"tv":0.0,"id":31376}]}]}
{"op":"mcm","clk":"11912014665","pt":1724005147673,"mc":[{"id":"1.231812839","rc":[{"batb":[[0,1.56,10],[1,1.5,20],[2,1.1,200]],"ltp":0.0,"tv":0.0,"id":31376}]}]}
{"op":"mcm","clk":"11912014708","pt":1724005147887,"mc":[{"id":"1.231812839","rc":[{"batb":[[0,1.9,30],[1,1.32,62.5],[2,1.3,20]],"ltp":0.0,"tv":0.0,"id":60443}]}]}
{"op":"mcm","clk":"11912019636","pt":1724005173933,"mc":[{"id":"1.231812839","rc":[{"batb":[[0,1.91,9.41],[1,1.9,30],[2,1.32,62.5]],"ltp":0.0,"tv":0.0,"id":60443},{"batb":[[0,1.57,15.02],[1,1.56,10],[2,1.5,20]],"ltp":0.0,"tv":0.0,"id":31376}]}]}
{"op":"mcm","clk":"11912380610","pt":1724006974209,"mc":[{"id":"1.231812839","rc":[{"batb":[[0,1.9,30],[1,1.32,62.5],[2,1.3,20]],"ltp":0.0,"tv":0.0,"id":60443},{"batb":[[0,1.56,10],[1,1.5,20],[2,1.1,200]],"ltp":0.0,"tv":0.0,"id":31376}]}]}
{"op":"mcm","clk":"11912394565","pt":1724007055924,"mc":[{"id":"1.231812839","rc":[{"batb":[[0,1.91,9.41],[1,1.9,30],[2,1.32,62.5]],"ltp":0.0,"tv":0.0,"id":60443},{"batb":[[0,1.57,15.02],[1,1.56,10],[2,1.5,20]],"ltp":0.0,"tv":0.0,"id":31376}]}]}
{"op":"mcm","clk":"11912625147","pt":1724008417607,"mc":[{"id":"1.231812839","rc":[{"batb":[[2,1.3,20]],"ltp":0.0,"tv":0.0,"id":60443}]}]}
{"op":"mcm","clk":"11912625874","pt":1724008421235,"mc":[{"id":"1.231812839","rc":[{"batb":[[2,1.03,200]],"ltp":1.15,"tv":5.99,"id":3961}]}]}
{"op":"mcm","clk":"11912626176","pt":1724008422827,"mc":[{"id":"1.231812839","rc":[{"batb":[[2,1.1,200]],"ltp":1.15,"tv":5.99,"id":3961}]}]}
{"op":"mcm","clk":"11912709532","pt":1724008856433,"mc":[{"id":"1.231812839","rc":[{"batb":[[0,1.9,30],[1,1.3,20],[2,1.1,200]],"ltp":0.0,"tv":0.0,"id":60443},{"batb":[[0,1.56,10],[1,1.5,20],[2,1.1,200]],"ltp":0.0,"tv":0.0,"id":31376}]}]}
{"op":"mcm","clk":"11912724481","pt":1724008937314,"mc":[{"id":"1.231812839","rc":[{"batb":[[0,1.91,9.41],[1,1.9,30],[2,1.3,20]],"ltp":0.0,"tv":0.0,"id":60443},{"batb":[[0,1.57,15.02],[1,1.56,10],[2,1.5,20]],"ltp":0.0,"tv":0.0,"id":31376}]}]}
{"op":"mcm","clk":"11913041104","pt":1724010737580,"mc":[{"id":"1.231812839","rc":[{"batb":[[0,1.9,30],[1,1.3,20],[2,1.1,200]],"ltp":0.0,"tv":0.0,"id":60443},{"batb":[[0,1.56,10],[1,1.5,20],[2,1.1,200]],"ltp":0.0,"tv":0.0,"id":31376}]}]}
{"op":"mcm","clk":"11913048775","pt":1724010793964,"mc":[{"id":"1.231812839","rc":[{"batb":[[0,1.91,9.41],[1,1.9,30],[2,1.3,20]],"ltp":0.0,"tv":0.0,"id":60443},{"batb":[[0,1.57,15.02],[1,1.56,10],[2,1.5,20]],"ltp":0.0,"tv":0.0,"id":31376}]}]}
{"op":"mcm","clk":"11913230608","pt":1724011975102,"mc":[{"id":"1.231812839","rc":[{"trd":[[1.16,2]],"batb":[[1,1.15,19.62]],"batl":[[0,95,5.85]],"ltp":1.15,"tv":6.0,"id":3961},{"batb":[[0,1.91,9.42]],"batl":[[0,90,1.05]],"ltp":0.0,"tv":0.0,"id":60443},{"batb":[[0,1.57,15.04]],"batl":[[0,95,5.85]],"ltp":0.0,"tv":0.0,"id":31376}],"tv":6.0}]}
{"op":"mcm","clk":"11913313361","pt":1724012594375,"mc":[{"id":"1.231812839","rc":[{"batb":[[0,1.9,30],[1,1.3,20],[2,1.1,200]],"ltp":0.0,"tv":0.0,"id":60443},{"batb":[[0,1.56,10],[1,1.5,20],[2,1.1,200]],"ltp":0.0,"tv":0.0,"id":31376}]}]}
{"op":"mcm","clk":"11913328948","pt":1724012713590,"mc":[{"id":"1.231812839","rc":[{"batb":[[0,1.91,9.42],[1,1.9,30],[2,1.3,20]],"ltp":0.0,"tv":0.0,"id":60443},{"batb":[[0,1.57,15.04],[1,1.56,10],[2,1.5,20]],"ltp":0.0,"tv":0.0,"id":31376}]}]}
{"op":"mcm","clk":"11913419419","pt":1724013454474,"mc":[{"id":"1.231812839","rc":[{"batb":[[0,1.58,10],[1,1.57,15.04]],"ltp":0.0,"tv":0.0,"id":31376}]}]}
{"op":"mcm","clk":"11913521870","pt":1724014513884,"mc":[{"id":"1.231812839","rc":[{"batb":[[1,1.5,20],[2,1.1,200]],"ltp":0.0,"tv":0.0,"id":31376}]}]}
{"op":"mcm","clk":"11913521937","pt":1724014514765,"mc":[{"id":"1.231812839","rc":[{"batb":[[0,1.9,30],[1,1.3,20],[2,1.1,200]],"ltp":0.0,"tv":0.0,"id":60443}]}]}
{"op":"mcm","clk":"11913529698","pt":1724014617981,"mc":[{"id":"1.231812839","rc":[{"batb":[[0,1.91,9.42],[1,1.9,30],[2,1.3,20]],"ltp":0.0,"tv":0.0,"id":60443},{"batb":[[0,1.59,14.53],[1,1.58,10],[2,1.5,20]],"ltp":0.0,"tv":0.0,"id":31376}]}]}
{"op":"mcm","clk":"11913646953","pt":1724016420668,"mc":[{"id":"1.231812839","rc":[{"batb":[[1,1.15,19.61]],"ltp":1.15,"tv":6.0,"id":3961},{"batb":[[0,1.91,9.42]],"ltp":0.0,"tv":0.0,"id":60443},{"batb":[[0,1.58,10],[1,1.5,20],[2,1.1,200]],"ltp":0.0,"tv":0.0,"id":31376}]}]}
{"op":"mcm","clk":"11913646962","pt":1724016420875,"mc":[{"id":"1.231812839","rc":[{"batb":[[0,1.9,30],[1,1.3,20],[2,1.1,200]],"ltp":0.0,"tv":0.0,"id":60443}]}]}
{"op":"mcm","clk":"11913653659","pt":1724016532778,"mc":[{"id":"1.231812839","rc":[{"batb":[[0,1.91,9.42],[1,1.9,30],[2,1.3,20]],"ltp":0.0,"tv":0.0,"id":60443},{"batb":[[0,1.59,14.52],[1,1.58,10],[2,1.5,20]],"ltp":0.0,"tv":0.0,"id":31376}]}]}
{"op":"mcm","clk":"11913680171","pt":1724016929423,"mc":[{"id":"1.231812839","rc":[{"batb":[[0,1.55,33.25],[1,1.5,20],[2,1.15,19.61]],"ltp":1.15,"tv":6.0,"id":3961}]}]}
{"op":"mcm","clk":"11913682126","pt":1724016956453,"mc":[{"id":"1.231812839","rc":[{"batl":[[0,28,8.31],[1,95,5.85],[2,990,5]],"ltp":1.15,"tv":6.0,"id":3961}]}]}
{"op":"mcm","clk":"11913689544","pt":1724017068571,"mc":[{"id":"1.231812839","rc":[{"batl":[[0,95,5.85],[1,990,5],[2,990,0]],"ltp":1.15,"tv":6.0,"id":3961}]}]}
{"op":"mcm","clk":"11913689811","pt":1724017072592,"mc":[{"id":"1.231812839","rc":[{"batb":[[0,1.5,20],[1,1.15,19.61],[2,1.1,200]],"ltp":1.15,"tv":6.0,"id":3961}]}]}
{"op":"mcm","clk":"11913781556","pt":1724018337393,"mc":[{"id":"1.231812839","rc":[{"batb":[[0,1.9,30],[1,1.3,20],[2,1.1,200]],"ltp":0.0,"tv":0.0,"id":60443},{"batb":[[0,1.58,10],[1,1.5,20],[2,1.1,200]],"ltp":0.0,"tv":0.0,"id":31376}]}]}
{"op":"mcm","clk":"11913784229","pt":1724018384979,"mc":[{"id":"1.231812839","rc":[{"batb":[[0,1.91,9.42],[1,1.9,30],[2,1.3,20]],"ltp":0.0,"tv":0.0,"id":60443},{"batb":[[0,1.59,14.52],[1,1.58,10],[2,1.5,20]],"ltp":0.0,"tv":0.0,"id":31376}]}]}
{"op":"mcm","clk":"11913890806","pt":1724020185382,"mc":[{"id":"1.231812839","rc":[{"batb":[[1,1.15,19.59]],"ltp":1.15,"tv":6.0,"id":3961},{"batb":[[0,1.9,30],[1,1.3,20],[2,1.1,200]],"ltp":0.0,"tv":0.0,"id":60443},{"batb":[[0,1.58,10],[1,1.5,20],[2,1.1,200]],"ltp":0.0,"tv":0.0,"id":31376}]}]}
{"op":"mcm","clk":"11913892223","pt":1724020211039,"mc":[{"id":"1.231812839","rc":[{"batb":[[0,1.91,9.41],[1,1.9,30],[2,1.3,20]],"ltp":0.0,"tv":0.0,"id":60443},{"batb":[[0,1.59,14.52],[1,1.58,10],[2,1.5,20]],"ltp":0.0,"tv":0.0,"id":31376}]}]}
{"op":"mcm","clk":"11913983415","pt":1724022014068,"mc":[{"id":"1.231812839","rc":[{"batb":[[1,1.15,19.59]],"ltp":1.15,"tv":6.0,"id":3961},{"batb":[[0,1.9,30],[1,1.3,20],[2,1.1,200]],"ltp":0.0,"tv":0.0,"id":60443},{"batb":[[0,1.58,10],[1,1.5,20],[2,1.1,200]],"ltp":0.0,"tv":0.0,"id":31376}]}]}
{"op":"mcm","clk":"11913983684","pt":1724022018607,"mc":[{"id":"1.231812839","rc":[{"batb":[[0,1.91,9.41],[1,1.9,30],[2,1.3,20]],"ltp":0.0,"tv":0.0,"id":60443},{"batb":[[0,1.59,14.51],[1,1.58,10],[2,1.5,20]],"ltp":0.0,"tv":0.0,"id":31376}]}]}
{"op":"mcm","clk":"11914084258","pt":1724023820079,"mc":[{"id":"1.231812839","rc":[{"batb":[[0,1.9,30],[1,1.3,20],[2,1.1,200]],"ltp":0.0,"tv":0.0,"id":60443},{"batb":[[0,1.58,10],[1,1.5,20],[2,1.1,200]],"ltp":0.0,"tv":0.0,"id":31376}]}]}
{"op":"mcm","clk":"11914089951","pt":1724023912896,"mc":[{"id":"1.231812839","rc":[{"batb":[[0,1.91,9.41],[1,1.9,30],[2,1.3,20]],"ltp":0.0,"tv":0.0,"id":60443},{"batb":[[0,1.59,14.51],[1,1.58,10],[2,1.5,20]],"ltp":0.0,"tv":0.0,"id":31376}]}]}
{"op":"mcm","clk":"11914186618","pt":1724025716172,"mc":[{"id":"1.231812839","rc":[{"batb":[[1,1.15,19.59]],"ltp":1.15,"tv":5.99,"id":3961},{"batb":[[0,1.9,30],[1,1.3,20],[2,1.1,200]],"ltp":0.0,"tv":0.0,"id":60443},{"batb":[[0,1.58,10],[1,1.5,20],[2,1.1,200]],"ltp":0.0,"tv":0.0,"id":31376}]}]}
{"op":"mcm","clk":"11914189167","pt":1724025766887,"mc":[{"id":"1.231812839","rc":[{"batb":[[0,1.91,9.41],[1,1.9,30],[2,1.3,20]],"ltp":0.0,"tv":0.0,"id":60443},{"batb":[[0,1.59,14.51],[1,1.58,10],[2,1.5,20]],"ltp":0.0,"tv":0.0,"id":31376}]}]}
{"op":"mcm","clk":"11914269236","pt":1724027567357,"mc":[{"id":"1.231812839","rc":[{"batb":[[0,1.9,30],[1,1.3,20],[2,1.1,200]],"ltp":0.0,"tv":0.0,"id":60443},{"batb":[[0,1.58,10],[1,1.5,20],[2,1.1,200]],"ltp":0.0,"tv":0.0,"id":31376}]}]}
{"op":"mcm","clk":"11914271245","pt":1724027603298,"mc":[{"id":"1.231812839","rc":[{"batb":[[0,1.91,9.41],[1,1.9,30],[2,1.3,20]],"ltp":0.0,"tv":0.0,"id":60443},{"batb":[[0,1.59,14.51],[1,1.58,10],[2,1.5,20]],"ltp":0.0,"tv":0.0,"id":31376}]}]}
{"op":"mcm","clk":"11914364875","pt":1724029403639,"mc":[{"id":"1.231812839","rc":[{"batb":[[1,1.15,19.6]],"ltp":1.15,"tv":6.0,"id":3961},{"batb":[[0,1.9,30],[1,1.3,20],[2,1.1,200]],"ltp":0.0,"tv":0.0,"id":60443},{"batb":[[0,1.58,10],[1,1.5,20],[2,1.1,200]],"ltp":0.0,"tv":0.0,"id":31376}]}]}
{"op":"mcm","clk":"11914365865","pt":1724029425942,"mc":[{"id":"1.231812839","rc":[{"batb":[[0,1.91,9.41],[1,1.9,30],[2,1.3,20]],"ltp":0.0,"tv":0.0,"id":60443},{"batb":[[0,1.59,14.52],[1,1.58,10],[2,1.5,20]],"ltp":0.0,"tv":0.0,"id":31376}]}]}
{"op":"mcm","clk":"11914414550","pt":1724031226333,"mc":[{"id":"1.231812839","rc":[{"batb":[[0,1.9,30],[1,1.3,20],[2,1.1,200]],"ltp":0.0,"tv":0.0,"id":60443},{"batb":[[0,1.58,10],[1,1.5,20],[2,1.1,200]],"ltp":0.0,"tv":0.0,"id":31376}]}]}
{"op":"mcm","clk":"11914416849","pt":1724031339972,"mc":[{"id":"1.231812839","rc":[{"batb":[[0,1.91,9.41],[1,1.9,30],[2,1.3,20]],"ltp":0.0,"tv":0.0,"id":60443},{"batb":[[0,1.59,14.52],[1,1.58,10],[2,1.5,20]],"ltp":0.0,"tv":0.0,"id":31376}]}]}
{"op":"mcm","clk":"11914459984","pt":1724033140375,"mc":[{"id":"1.231812839","rc":[{"batb":[[1,1.15,19.59]],"ltp":1.15,"tv":5.99,"id":3961},{"batb":[[0,1.9,30],[1,1.3,20],[2,1.1,200]],"ltp":0.0,"tv":0.0,"id":60443},{"batb":[[0,1.58,10],[1,1.5,20],[2,1.1,200]],"ltp":0.0,"tv":0.0,"id":31376}]}]}
{"op":"mcm","clk":"11914463235","pt":1724033236396,"mc":[{"id":"1.231812839","rc":[{"batb":[[0,1.91,9.41],[1,1.9,30],[2,1.3,20]],"ltp":0.0,"tv":0.0,"id":60443},{"batb":[[0,1.59,14.51],[1,1.58,10],[2,1.5,20]],"ltp":0.0,"tv":0.0,"id":31376}]}]}
{"op":"mcm","clk":"11914526547","pt":1724035036695,"mc":[{"id":"1.231812839","rc":[{"batb":[[0,1.58,10],[1,1.5,20],[2,1.1,200]],"ltp":0.0,"tv":0.0,"id":31376}]}]}
{"op":"mcm","clk":"11914526553","pt":1724035036900,"mc":[{"id":"1.231812839","rc":[{"batb":[[0,1.9,30],[1,1.3,20],[2,1.1,200]],"ltp":0.0,"tv":0.0,"id":60443}]}]}
{"op":"mcm","clk":"11914529765","pt":1724035130408,"mc":[{"id":"1.231812839","rc":[{"batb":[[0,1.91,9.41],[1,1.9,30],[2,1.3,20]],"ltp":0.0,"tv":0.0,"id":60443},{"batb":[[0,1.59,14.51],[1,1.58,10],[2,1.5,20]],"ltp":0.0,"tv":0.0,"id":31376}]}]}
{"op":"mcm","clk":"11914579678","pt":1724036930618,"mc":[{"id":"1.231812839","rc":[{"batb":[[1,1.15,19.59]],"ltp":1.15,"tv":5.99,"id":3961},{"batb":[[0,1.9,30],[1,1.3,20],[2,1.1,200]],"ltp":0.0,"tv":0.0,"id":60443},{"batb":[[0,1.59,14.51]],"ltp":0.0,"tv":0.0,"id":31376}]}]}
{"op":"mcm","clk":"11914579685","pt":1724036930824,"mc":[{"id":"1.231812839","rc":[{"batb":[[0,1.58,10],[1,1.5,20],[2,1.1,200]],"ltp":0.0,"tv":0.0,"id":31376}]}]}
{"op":"mcm","clk":"11914582117","pt":1724037011221,"mc":[{"id":"1.231812839","rc":[{"batb":[[0,1.91,9.41],[1,1.9,30],[2,1.3,20]],"ltp":0.0,"tv":0.0,"id":60443},{"batb":[[0,1.59,14.51],[1,1.58,10],[2,1.5,20]],"ltp":0.0,"tv":0.0,"id":31376}]}]}
{"op":"mcm","clk":"11914638086","pt":1724038811682,"mc":[{"id":"1.231812839","rc":[{"batb":[[0,1.9,30],[1,1.3,20],[2,1.1,200]],"ltp":0.0,"tv":0.0,"id":60443},{"batb":[[0,1.58,10],[1,1.5,20],[2,1.1,200]],"ltp":0.0,"tv":0.0,"id":31376}]}]}
{"op":"mcm","clk":"11914639570","pt":1724038874846,"mc":[{"id":"1.231812839","rc":[{"batb":[[0,1.91,9.41],[1,1.9,30],[2,1.3,20]],"ltp":0.0,"tv":0.0,"id":60443},{"batb":[[0,1.59,14.51],[1,1.58,10],[2,1.5,20]],"ltp":0.0,"tv":0.0,"id":31376}]}]}
{"op":"mcm","clk":"11914697012","pt":1724040675099,"mc":[{"id":"1.231812839","rc":[{"batb":[[1,1.15,19.6]],"ltp":1.15,"tv":6.0,"id":3961},{"batb":[[0,1.9,30],[1,1.3,20],[2,1.1,200]],"ltp":0.0,"tv":0.0,"id":60443},{"batb":[[0,1.58,10],[1,1.5,20],[2,1.1,200]],"ltp":0.0,"tv":0.0,"id":31376}]}]}
{"op":"mcm","clk":"11914698272","pt":1724040735188,"mc":[{"id":"1.231812839","rc":[{"batb":[[0,1.91,9.41],[1,1.9,30],[2,1.3,20]],"ltp":0.0,"tv":0.0,"id":60443},{"batb":[[0,1.59,14.52],[1,1.58,10],[2,1.5,20]],"ltp":0.0,"tv":0.0,"id":31376}]}]}
{"op":"mcm","clk":"11914747309","pt":1724042535581,"mc":[{"id":"1.231812839","rc":[{"batb":[[0,1.9,30],[1,1.3,20],[2,1.1,200]],"ltp":0.0,"tv":0.0,"id":60443},{"batb":[[0,1.58,10],[1,1.5,20],[2,1.1,200]],"ltp":0.0,"tv":0.0,"id":31376}]}]}
{"op":"mcm","clk":"11914748491","pt":1724042585680,"mc":[{"id":"1.231812839","rc":[{"batb":[[0,1.91,9.41],[1,1.9,30],[2,1.3,20]],"ltp":0.0,"tv":0.0,"id":60443},{"batb":[[0,1.59,14.52],[1,1.58,10],[2,1.5,20]],"ltp":0.0,"tv":0.0,"id":31376}]}]}
{"op":"mcm","clk":"11914824548","pt":1724044375113,"mc":[{"id":"1.231812839","rc":[{"batb":[[1,1.15,19.6]],"ltp":1.15,"tv":6.0,"id":3961},{"batb":[[0,1.91,9.41]],"ltp":0.0,"tv":0.0,"id":60443},{"batb":[[0,1.59,14.52]],"ltp":0.0,"tv":0.0,"id":31376}]}]}
{"op":"mcm","clk":"11914825597","pt":1724044386248,"mc":[{"id":"1.231812839","rc":[{"batb":[[0,1.9,30],[1,1.3,20],[2,1.1,200]],"ltp":0.0,"tv":0.0,"id":60443},{"batb":[[0,1.58,10],[1,1.5,20],[2,1.1,200]],"ltp":0.0,"tv":0.0,"id":31376}]}]}
{"op":"mcm","clk":"11914827574","pt":1724044430861,"mc":[{"id":"1.231812839","rc":[{"batb":[[0,1.91,9.41],[1,1.9,30],[2,1.3,20]],"ltp":0.0,"tv":0.0,"id":60443},{"batb":[[0,1.59,14.52],[1,1.58,10],[2,1.5,20]],"ltp":0.0,"tv":0.0,"id":31376}]}]}
{"op":"mcm","clk":"11914901613","pt":1724046231105,"mc":[{"id":"1.231812839","rc":[{"batb":[[0,1.9,30],[1,1.3,20],[2,1.1,200]],"ltp":0.0,"tv":0.0,"id":60443},{"batb":[[0,1.58,10],[1,1.5,20],[2,1.1,200]],"ltp":0.0,"tv":0.0,"id":31376}]}]}
{"op":"mcm","clk":"11914903295","pt":1724046271745,"mc":[{"id":"1.231812839","rc":[{"batb":[[0,1.91,9.41],[1,1.9,30],[2,1.3,20]],"ltp":0.0,"tv":0.0,"id":60443},{"batb":[[0,1.59,14.52],[1,1.58,10],[2,1.5,20]],"ltp":0.0,"tv":0.0,"id":31376}]}]}
{"op":"mcm","clk":"11914983029","pt":1724048072028,"mc":[{"id":"1.231812839","rc":[{"batb":[[1,1.15,19.6]],"ltp":1.15,"tv":6.0,"id":3961},{"batb":[[0,1.9,30],[1,1.3,20],[2,1.1,200]],"ltp":0.0,"tv":0.0,"id":60443},{"batb":[[0,1.58,10],[1,1.5,20],[2,1.1,200]],"ltp":0.0,"tv":0.0,"id":31376}]}]}
{"op":"mcm","clk":"11914984607","pt":1724048111870,"mc":[{"id":"1.231812839","rc":[{"batb":[[0,1.91,9.41],[1,1.9,30],[2,1.3,20]],"ltp":0.0,"tv":0.0,"id":60443},{"batb":[[0,1.59,14.52],[1,1.58,10],[2,1.5,20]],"ltp":0.0,"tv":0.0,"id":31376}]}]}
{"op":"mcm","clk":"11915077006","pt":1724049912287,"mc":[{"id":"1.231812839","rc":[{"batb":[[0,1.9,30],[1,1.3,20],[2,1.1,200]],"ltp":0.0,"tv":0.0,"id":60443},{"batb":[[0,1.58,10],[1,1.5,20],[2,1.1,200]],"ltp":0.0,"tv":0.0,"id":31376}]}]}
{"op":"mcm","clk":"11915078755","pt":1724049947538,"mc":[{"id":"1.231812839","rc":[{"batb":[[0,1.91,9.41],[1,1.9,30],[2,1.3,20]],"ltp":0.0,"tv":0.0,"id":60443},{"batb":[[0,1.59,14.52],[1,1.58,10],[2,1.5,20]],"ltp":0.0,"tv":0.0,"id":31376}]}]}
{"op":"mcm","clk":"11915165611","pt":1724051747759,"mc":[{"id":"1.231812839","rc":[{"batb":[[1,1.15,19.59]],"ltp":1.15,"tv":6.0,"id":3961},{"batb":[[0,1.9,30],[1,1.3,20],[2,1.1,200]],"ltp":0.0,"tv":0.0,"id":60443},{"batb":[[0,1.59,14.51]],"ltp":0.0,"tv":0.0,"id":31376}]}]}
{"op":"mcm","clk":"11915165618","pt":1724051747915,"mc":[{"id":"1.231812839","rc":[{"batb":[[0,1.58,10],[1,1.5,20],[2,1.1,200]],"ltp":0.0,"tv":0.0,"id":31376}]}]}
{"op":"mcm","clk":"11915166668","pt":1724051778465,"mc":[{"id":"1.231812839","rc":[{"batb":[[0,1.91,9.41],[1,1.9,30],[2,1.3,20]],"ltp":0.0,"tv":0.0,"id":60443},{"batb":[[0,1.59,14.51],[1,1.58,10],[2,1.5,20]],"ltp":0.0,"tv":0.0,"id":31376}]}]}
{"op":"mcm","clk":"11915242941","pt":1724053578680,"mc":[{"id":"1.231812839","rc":[{"batb":[[0,1.9,30],[1,1.3,20],[2,1.1,200]],"ltp":0.0,"tv":0.0,"id":60443}]}]}
{"op":"mcm","clk":"11915242950","pt":1724053578882,"mc":[{"id":"1.231812839","rc":[{"batb":[[0,1.58,10],[1,1.5,20],[2,1.1,200]],"ltp":0.0,"tv":0.0,"id":31376}]}]}
{"op":"mcm","clk":"11915244335","pt":1724053608760,"mc":[{"id":"1.231812839","rc":[{"batb":[[0,1.91,9.41],[1,1.9,30],[2,1.3,20]],"ltp":0.0,"tv":0.0,"id":60443},{"batb":[[0,1.59,14.51],[1,1.58,10],[2,1.5,20]],"ltp":0.0,"tv":0.0,"id":31376}]}]}
{"op":"mcm","clk":"11915335893","pt":1724055408969,"mc":[{"id":"1.231812839","rc":[{"batb":[[0,1.9,30],[1,1.3,20],[2,1.1,200]],"ltp":0.0,"tv":0.0,"id":60443},{"batb":[[0,1.58,10],[1,1.5,20],[2,1.1,200]],"ltp":0.0,"tv":0.0,"id":31376}]}]}
{"op":"mcm","clk":"11915336934","pt":1724055435692,"mc":[{"id":"1.231812839","rc":[{"batb":[[0,1.91,9.41],[1,1.9,30],[2,1.3,20]],"ltp":0.0,"tv":0.0,"id":60443},{"batb":[[0,1.59,14.51],[1,1.58,10],[2,1.5,20]],"ltp":0.0,"tv":0.0,"id":31376}]}]}
{"op":"mcm","clk":"11915418157","pt":1724057182653,"mc":[{"id":"1.231812839","rc":[{"batb":[[0,1.92,30],[1,1.91,9.41]],"ltp":0.0,"tv":0.0,"id":60443}]}]}
{"op":"mcm","clk":"11915420046","pt":1724057236131,"mc":[{"id":"1.231812839","rc":[{"batb":[[1,1.3,20],[2,1.1,200]],"ltp":0.0,"tv":0.0,"id":60443},{"batb":[[0,1.58,10],[1,1.5,20],[2,1.1,200]],"ltp":0.0,"tv":0.0,"id":31376}]}]}
{"op":"mcm","clk":"11915420687","pt":1724057251676,"mc":[{"id":"1.231812839","rc":[{"batb":[[0,1.93,9.21],[1,1.92,30],[2,1.3,20]],"ltp":0.0,"tv":0.0,"id":60443},{"batb":[[0,1.59,14.51],[1,1.58,10],[2,1.5,20]],"ltp":0.0,"tv":0.0,"id":31376}]}]}
{"op":"mcm","clk":"11915445017","pt":1724057855212,"mc":[{"id":"1.231812839","rc":[{"batb":[[0,1.94,30],[1,1.93,9.21]],"ltp":0.0,"tv":0.0,"id":60443}]}]}
{"op":"mcm","clk":"11915494312","pt":1724059052160,"mc":[{"id":"1.231812839","rc":[{"trd":[[1.16,2]],"batb":[[1,1.15,19.57]],"ltp":1.15,"tv":5.99,"id":3961},{"batb":[[1,1.3,20],[2,1.1,200]],"ltp":0.0,"tv":0.0,"id":60443},{"batb":[[0,1.58,10],[1,1.5,20],[2,1.1,200]],"ltp":0.0,"tv":0.0,"id":31376}],"tv":5.99}]}
{"op":"mcm","clk":"11915494960","pt":1724059068060,"mc":[{"id":"1.231812839","rc":[{"batb":[[0,1.95,9],[1,1.94,30],[2,1.3,20]],"ltp":0.0,"tv":0.0,"id":60443},{"batb":[[0,1.59,14.5],[1,1.58,10],[2,1.5,20]],"ltp":0.0,"tv":0.0,"id":31376}]}]}
{"op":"mcm","clk":"11915566669","pt":1724060868483,"mc":[{"id":"1.231812839","rc":[{"batb":[[0,1.94,30],[1,1.3,20],[2,1.1,200]],"ltp":0.0,"tv":0.0,"id":60443},{"batb":[[0,1.58,10],[1,1.5,20],[2,1.1,200]],"ltp":0.0,"tv":0.0,"id":31376}]}]}
{"op":"mcm","clk":"11915566911","pt":1724060875874,"mc":[{"id":"1.231812839","rc":[{"batb":[[0,1.95,9],[1,1.94,30],[2,1.3,20]],"ltp":0.0,"tv":0.0,"id":60443},{"batb":[[0,1.59,14.5],[1,1.58,10],[2,1.5,20]],"ltp":0.0,"tv":0.0,"id":31376}]}]}
{"op":"mcm","clk":"11915641280","pt":1724062676221,"mc":[{"id":"1.231812839","rc":[{"batb":[[1,1.15,19.58]],"ltp":1.15,"tv":5.99,"id":3961},{"batb":[[0,1.94,30],[1,1.3,20],[2,1.1,200]],"ltp":0.0,"tv":0.0,"id":60443},{"batb":[[0,1.58,10],[1,1.5,20],[2,1.1,200]],"ltp":0.0,"tv":0.0,"id":31376}]}]}
{"op":"mcm","clk":"11915646325","pt":1724062784204,"mc":[{"id":"1.231812839","rc":[{"batb":[[0,1.95,9.01],[1,1.94,30],[2,1.3,20]],"ltp":0.0,"tv":0.0,"id":60443},{"batb":[[0,1.59,14.5],[1,1.58,10],[2,1.5,20]],"ltp":0.0,"tv":0.0,"id":31376}]}]}
{"op":"mcm","clk":"11915720854","pt":1724064584546,"mc":[{"id":"1.231812839","rc":[{"batb":[[0,1.94,30],[1,1.3,20],[2,1.1,200]],"ltp":0.0,"tv":0.0,"id":60443},{"batb":[[0,1.58,10],[1,1.5,20],[2,1.1,200]],"ltp":0.0,"tv":0.0,"id":31376}]}]}
{"op":"mcm","clk":"11915723464","pt":1724064652555,"mc":[{"id":"1.231812839","rc":[{"batb":[[0,1.95,9.01],[1,1.94,30],[2,1.3,20]],"ltp":0.0,"tv":0.0,"id":60443},{"batb":[[0,1.59,14.5],[1,1.58,10],[2,1.5,20]],"ltp":0.0,"tv":0.0,"id":31376}]}]}
{"op":"mcm","clk":"11915782376","pt":1724065975091,"mc":[{"id":"1.231812839","rc":[{"trd":[[1.16,2]],"batb":[[1,1.15,19.6]],"batl":[[0,95,5.85]],"ltp":1.15,"tv":6.0,"id":3961},{"batb":[[0,1.95,9.02]],"batl":[[0,90,1.05]],"ltp":0.0,"tv":0.0,"id":60443},{"batb":[[0,1.59,14.52]],"batl":[[0,95,5.85]],"ltp":0.0,"tv":0.0,"id":31376}],"tv":6.0}]}
{"op":"mcm","clk":"11915801411","pt":1724066453077,"mc":[{"id":"1.231812839","rc":[{"batb":[[0,1.94,30],[1,1.3,20],[2,1.1,200]],"ltp":0.0,"tv":0.0,"id":60443},{"batb":[[0,1.58,10],[1,1.5,20],[2,1.1,200]],"ltp":0.0,"tv":0.0,"id":31376}]}]}
{"op":"mcm","clk":"11915802634","pt":1724066492920,"mc":[{"id":"1.231812839","rc":[{"batb":[[0,1.95,9.02],[1,1.94,30],[2,1.3,20]],"ltp":0.0,"tv":0.0,"id":60443},{"batb":[[0,1.59,14.52],[1,1.58,10],[2,1.5,20]],"ltp":0.0,"tv":0.0,"id":31376}]}]}
{"op":"mcm","clk":"11915855721","pt":1724068118721,"mc":[{"id":"1.231812839","rc":[{"trd":[[1.5,0.1]],"batb":[[0,1.5,19.95]],"ltp":1.5,"tv":6.1,"id":3961}],"tv":6.1}]}
{"op":"mcm","clk":"11915862050","pt":1724068293396,"mc":[{"id":"1.231812839","rc":[{"batb":[[0,1.94,30],[1,1.3,20],[2,1.1,200]],"ltp":0.0,"tv":0.0,"id":60443},{"batb":[[0,1.58,10],[1,1.5,20],[2,1.1,200]],"ltp":0.0,"tv":0.0,"id":31376}]}]}
{"op":"mcm","clk":"11915863227","pt":1724068328218,"mc":[{"id":"1.231812839","rc":[{"batb":[[0,1.95,9.02],[1,1.94,30],[2,1.3,20]],"ltp":0.0,"tv":0.0,"id":60443},{"batb":[[0,1.59,14.52],[1,1.58,10],[2,1.5,20]],"ltp":0.0,"tv":0.0,"id":31376}]}]}
{"op":"mcm","clk":"11915949385","pt":1724070128590,"mc":[{"id":"1.231812839","rc":[{"batb":[[0,1.94,30],[1,1.3,20],[2,1.1,200]],"ltp":0.0,"tv":0.0,"id":60443},{"batb":[[0,1.58,10],[1,1.5,20],[2,1.1,200]],"ltp":0.0,"tv":0.0,"id":31376}]}]}
{"op":"mcm","clk":"11915950810","pt":1724070157411,"mc":[{"id":"1.231812839","rc":[{"batb":[[0,1.95,9.02],[1,1.94,30],[2,1.3,20]],"ltp":0.0,"tv":0.0,"id":60443},{"batb":[[0,1.59,14.52],[1,1.58,10],[2,1.5,20]],"ltp":0.0,"tv":0.0,"id":31376}]}]}
{"op":"mcm","clk":"11916005323","pt":1724071136903,"mc":[{"id":"1.231812839","rc":[{"batb":[[0,1.67,282],[1,1.59,14.52],[2,1.58,10]],"ltp":0.0,"tv":0.0,"id":31376}]}]}
{"op":"mcm","clk":"11916059735","pt":1724071957703,"mc":[{"id":"1.231812839","rc":[{"batb":[[0,1.94,30],[1,1.3,20],[2,1.1,200]],"ltp":0.0,"tv":0.0,"id":60443},{"batb":[[1,1.58,10],[2,1.5,20]],"ltp":0.0,"tv":0.0,"id":31376}]}]}
{"op":"mcm","clk":"11916060778","pt":1724071982443,"mc":[{"id":"1.231812839","rc":[{"batb":[[0,1.95,9.02],[1,1.94,30],[2,1.3,20]],"ltp":0.0,"tv":0.0,"id":60443},{"batb":[[0,1.68,12.6],[1,1.67,282],[2,1.58,10]],"ltp":0.0,"tv":0.0,"id":31376}]}]}
{"op":"mcm","clk":"11916090969","pt":1724072626470,"mc":[{"id":"1.231812839","rc":[{"batb":[[0,1.95,9.02]],"ltp":0.0,"tv":0.0,"id":60443},{"batb":[[0,1.68,19.02]],"ltp":0.0,"tv":0.0,"id":31376}]}]}
{"op":"mcm","clk":"11916165327","pt":1724073782631,"mc":[{"id":"1.231812839","rc":[{"batb":[[0,1.68,6.42]],"ltp":0.0,"tv":0.0,"id":31376}]}]}
{"op":"mcm","clk":"11916165342","pt":1724073782787,"mc":[{"id":"1.231812839","rc":[{"batb":[[0,1.94,30],[1,1.3,20],[2,1.1,200]],"ltp":0.0,"tv":0.0,"id":60443}]}]}
{"op":"mcm","clk":"11916166799","pt":1724073803724,"mc":[{"id":"1.231812839","rc":[{"batb":[[0,1.95,9.02],[1,1.94,30],[2,1.3,20]],"ltp":0.0,"tv":0.0,"id":60443},{"batb":[[0,1.69,12.42],[1,1.68,6.42],[2,1.67,282]],"ltp":0.0,"tv":0.0,"id":31376}]}]}
{"op":"mcm","clk":"11916289046","pt":1724075604095,"mc":[{"id":"1.231812839","rc":[{"batb":[[0,1.94,30],[1,1.3,20],[2,1.1,200]],"ltp":0.0,"tv":0.0,"id":60443},{"batb":[[0,1.68,6.42],[1,1.67,282],[2,1.58,10]],"ltp":0.0,"tv":0.0,"id":31376}]}]}
{"op":"mcm","clk":"11916290463","pt":1724075625312,"mc":[{"id":"1.231812839","rc":[{"batb":[[0,1.95,9.02],[1,1.94,30],[2,1.3,20]],"ltp":0.0,"tv":0.0,"id":60443},{"batb":[[0,1.69,12.42],[1,1.68,6.42],[2,1.67,282]],"ltp":0.0,"tv":0.0,"id":31376}]}]}
{"op":"mcm","clk":"11916339143","pt":1724076479935,"mc":[{"id":"1.231812839","rc":[{"batb":[[1,1.15,19.6]],"ltp":1.5,"tv":6.09,"id":3961},{"batb":[[0,1.96,30],[1,1.95,9.02]],"ltp":0.0,"tv":0.0,"id":60443},{"batb":[[0,1.69,12.41],[1,1.68,6.42]],"ltp":0.0,"tv":0.0,"id":31376}]}]}
{"op":"mcm","clk":"11916405056","pt":1724077425590,"mc":[{"id":"1.231812839","rc":[{"batb":[[0,1.68,6.42],[1,1.67,282],[2,1.58,10]],"ltp":0.0,"tv":0.0,"id":31376}]}]}
{"op":"mcm","clk":"11916405075","pt":1724077425804,"mc":[{"id":"1.231812839","rc":[{"batb":[[1,1.3,20],[2,1.1,200]],"ltp":0.0,"tv":0.0,"id":60443}]}]}
{"op":"mcm","clk":"11916405478","pt":1724077431215,"mc":[{"id":"1.231812839","rc":[{"batb":[[0,1.97,8.83],[1,1.96,30],[2,1.3,20]],"ltp":0.0,"tv":0.0,"id":60443},{"batb":[[0,1.69,12.41],[1,1.68,6.42],[2,1.67,282]],"ltp":0.0,"tv":0.0,"id":31376}]}]}
{"op":"mcm","clk":"11916518523","pt":1724079231516,"mc":[{"id":"1.231812839","rc":[{"batb":[[0,1.96,30],[1,1.3,20],[2,1.1,200]],"ltp":0.0,"tv":0.0,"id":60443},{"batb":[[0,1.68,6.42],[1,1.67,282],[2,1.58,10]],"ltp":0.0,"tv":0.0,"id":31376}]}]}
{"op":"mcm","clk":"11916529643","pt":1724079380175,"mc":[{"id":"1.231812839","rc":[{"batb":[[0,1.97,8.83],[1,1.96,30],[2,1.3,20]],"ltp":0.0,"tv":0.0,"id":60443},{"batb":[[0,1.69,12.41],[1,1.68,6.42],[2,1.67,282]],"ltp":0.0,"tv":0.0,"id":31376}]}]}
{"op":"mcm","clk":"11916659203","pt":1724080812420,"mc":[{"id":"1.231812839","rc":[{"batb":[[1,1.1,200],[2,1.03,200]],"ltp":1.5,"tv":6.09,"id":3961},{"batb":[[0,1.69,12.41],[1,1.68,6.41]],"ltp":0.0,"tv":0.0,"id":31376}]}]}
{"op":"mcm","clk":"11916701435","pt":1724081180451,"mc":[{"id":"1.231812839","rc":[{"batb":[[0,1.96,30],[1,1.3,20],[2,1.1,200]],"ltp":0.0,"tv":0.0,"id":60443},{"batb":[[0,1.68,6.41],[1,1.67,282],[2,1.58,10]],"ltp":0.0,"tv":0.0,"id":31376}]}]}
{"op":"mcm","clk":"11916701489","pt":1724081180921,"mc":[{"id":"1.231812839","rc":[{"batb":[[0,1.97,8.83],[1,1.96,30],[2,1.3,20]],"ltp":0.0,"tv":0.0,"id":60443},{"batb":[[0,1.69,12.41],[1,1.68,6.41],[2,1.67,282]],"ltp":0.0,"tv":0.0,"id":31376}]}]}
{"op":"mcm","clk":"11916886162","pt":1724082981119,"mc":[{"id":"1.231812839","rc":[{"batb":[[0,1.96,30],[1,1.3,20],[2,1.1,200]],"ltp":0.0,"tv":0.0,"id":60443}]}]}
{"op":"mcm","clk":"11916886253","pt":1724082982243,"mc":[{"id":"1.231812839","rc":[{"batb":[[0,1.68,6.41],[1,1.67,282],[2,1.58,10]],"ltp":0.0,"tv":0.0,"id":31376}]}]}
{"op":"mcm","clk":"11916897977","pt":1724083097580,"mc":[{"id":"1.231812839","rc":[{"batb":[[0,1.97,8.83],[1,1.96,30],[2,1.3,20]],"ltp":0.0,"tv":0.0,"id":60443},{"batb":[[0,1.69,12.41],[1,1.68,6.41],[2,1.67,282]],"ltp":0.0,"tv":0.0,"id":31376}]}]}
{"op":"mcm","clk":"11917134553","pt":1724084897691,"mc":[{"id":"1.231812839","rc":[{"batb":[[0,1.97,8.84]],"ltp":0.0,"tv":0.0,"id":60443},{"batb":[[0,1.68,6.41],[1,1.67,282],[2,1.58,10]],"ltp":0.0,"tv":0.0,"id":31376}]}]}
{"op":"mcm","clk":"11917134572","pt":1724084897893,"mc":[{"id":"1.231812839","rc":[{"batb":[[0,1.96,30],[1,1.3,20],[2,1.1,200]],"ltp":0.0,"tv":0.0,"id":60443}]}]}
{"op":"mcm","clk":"11917141658","pt":1724084948127,"mc":[{"id":"1.231812839","rc":[{"batb":[[0,1.97,8.84],[1,1.96,30],[2,1.3,20]],"ltp":0.0,"tv":0.0,"id":60443},{"batb":[[0,1.69,12.42],[1,1.68,6.41],[2,1.67,282]],"ltp":0.0,"tv":0.0,"id":31376}]}]}
{"op":"mcm","clk":"11917367796","pt":1724086748396,"mc":[{"id":"1.231812839","rc":[{"batb":[[0,1.96,30],[1,1.3,20],[2,1.1,200]],"ltp":0.0,"tv":0.0,"id":60443},{"batb":[[0,1.68,6.41],[1,1.67,282],[2,1.58,10]],"ltp":0.0,"tv":0.0,"id":31376}]}]}
{"op":"mcm","clk":"11917370856","pt":1724086778477,"mc":[{"id":"1.231812839","rc":[{"batb":[[0,1.97,8.84],[1,1.96,30],[2,1.3,20]],"ltp":0.0,"tv":0.0,"id":60443},{"batb":[[0,1.69,12.42],[1,1.68,6.41],[2,1.67,282]],"ltp":0.0,"tv":0.0,"id":31376}]}]}
{"op":"mcm","clk":"11917494769","pt":1724087575080,"mc":[{"id":"1.231812839","rc":[{"batb":[[0,1.97,8.84]],"ltp":0.0,"tv":0.0,"id":60443},{"batb":[[0,1.69,12.43]],"ltp":0.0,"tv":0.0,"id":31376}]}]}
{"op":"mcm","clk":"11917640396","pt":1724088578715,"mc":[{"id":"1.231812839","rc":[{"batb":[[0,1.68,6.41],[1,1.67,282],[2,1.58,10]],"ltp":0.0,"tv":0.0,"id":31376}]}]}
{"op":"mcm","clk":"11917640424","pt":1724088578922,"mc":[{"id":"1.231812839","rc":[{"batb":[[0,1.96,30],[1,1.3,20],[2,1.1,200]],"ltp":0.0,"tv":0.0,"id":60443}]}]}
{"op":"mcm","clk":"11917641034","pt":1724088583011,"mc":[{"id":"1.231812839","rc":[{"batb":[[0,1.97,8.84],[1,1.96,30],[2,1.3,20]],"ltp":0.0,"tv":0.0,"id":60443},{"batb":[[0,1.69,12.43],[1,1.68,6.41],[2,1.67,282]],"ltp":0.0,"tv":0.0,"id":31376}]}]}
{"op":"mcm","clk":"11917898349","pt":1724090383438,"mc":[{"id":"1.231812839","rc":[{"batb":[[0,1.96,30],[1,1.3,20],[2,1.1,200]],"ltp":0.0,"tv":0.0,"id":60443},{"batb":[[0,1.68,6.41],[1,1.67,282],[2,1.58,10]],"ltp":0.0,"tv":0.0,"id":31376}]}]}
{"op":"mcm","clk":"11917918175","pt":1724090524884,"mc":[{"id":"1.231812839","rc":[{"batb":[[0,1.5,20.85]],"ltp":1.5,"tv":6.1,"id":3961},{"batb":[[0,1.68,6.41]],"ltp":0.0,"tv":0.0,"id":31376}]}]}
{"op":"mcm","clk":"11917919916","pt":1724090535908,"mc":[{"id":"1.231812839","rc":[{"batb":[[0,1.97,8.83],[1,1.96,30],[2,1.3,20]],"ltp":0.0,"tv":0.0,"id":60443},{"batb":[[0,1.69,12.42],[1,1.68,6.41],[2,1.67,282]],"ltp":0.0,"tv":0.0,"id":31376}]}]}
{"op":"mcm","clk":"11918194640","pt":1724092336314,"mc":[{"id":"1.231812839","rc":[{"batb":[[0,1.96,30],[1,1.3,20],[2,1.1,200]],"ltp":0.0,"tv":0.0,"id":60443},{"batb":[[0,1.68,6.41],[1,1.67,282],[2,1.58,10]],"ltp":0.0,"tv":0.0,"id":31376}]}]}
{"op":"mcm","clk":"11918212991","pt":1724092443810,"mc":[{"id":"1.231812839","rc":[{"batb":[[0,1.97,8.83],[1,1.96,30],[2,1.3,20]],"ltp":0.0,"tv":0.0,"id":60443},{"batb":[[0,1.69,12.42],[1,1.68,6.41],[2,1.67,282]],"ltp":0.0,"tv":0.0,"id":31376}]}]}
{"op":"mcm","clk":"11918494311","pt":1724094244084,"mc":[{"id":"1.231812839","rc":[{"batb":[[0,1.96,30],[1,1.3,20],[2,1.1,200]],"ltp":0.0,"tv":0.0,"id":60443},{"batb":[[0,1.68,6.4],[1,1.67,282],[2,1.58,10]],"ltp":0.0,"tv":0.0,"id":31376}]}]}
{"op":"mcm","clk":"11918503488","pt":1724094320732,"mc":[{"id":"1.231812839","rc":[{"batb":[[0,1.97,8.84],[1,1.96,30],[2,1.3,20]],"ltp":0.0,"tv":0.0,"id":60443},{"batb":[[0,1.69,12.42],[1,1.68,6.4],[2,1.67,282]],"ltp":0.0,"tv":0.0,"id":31376}]}]}
{"op":"mcm","clk":"11918725220","pt":1724095903009,"mc":[{"id":"1.231812839","rc":[{"batb":[[2,1.58,10]],"ltp":0.0,"tv":0.0,"id":31376}]}]}
{"op":"mcm","clk":"11918756022","pt":1724096121265,"mc":[{"id":"1.231812839","rc":[{"batb":[[0,1.96,30],[1,1.3,20],[2,1.1,200]],"ltp":0.0,"tv":0.0,"id":60443},{"batb":[[0,1.68,6.4],[1,1.58,10],[2,1.5,20]],"ltp":0.0,"tv":0.0,"id":31376}]}]}
{"op":"mcm","clk":"11918763949","pt":1724096180425,"mc":[{"id":"1.231812839","rc":[{"batb":[[0,1.97,8.84],[1,1.96,30],[2,1.3,20]],"ltp":0.0,"tv":0.0,"id":60443},{"batb":[[0,1.69,12.42],[1,1.68,6.4],[2,1.58,10]],"ltp":0.0,"tv":0.0,"id":31376}]}]}
{"op":"mcm","clk":"11918820318","pt":1724096592509,"mc":[{"id":"1.231812839","rc":[{"batb":[[1,1.58,10],[2,1.5,20]],"ltp":0.0,"tv":0.0,"id":31376}]}]}
{"op":"mcm","clk":"11918987375","pt":1724097980683,"mc":[{"id":"1.231812839","rc":[{"batb":[[0,1.96,30],[1,1.3,20],[2,1.1,200]],"ltp":0.0,"tv":0.0,"id":60443},{"batb":[[0,1.69,12.43]],"ltp":0.0,"tv":0.0,"id":31376}]}]}
{"op":"mcm","clk":"11918987392","pt":1724097980841,"mc":[{"id":"1.231812839","rc":[{"batb":[[0,1.58,10],[1,1.5,20],[2,1.1,200]],"ltp":0.0,"tv":0.0,"id":31376}]}]}
{"op":"mcm","clk":"11918994621","pt":1724098074991,"mc":[{"id":"1.231812839","rc":[{"batb":[[0,1.97,8.84],[1,1.96,30],[2,1.3,20]],"ltp":0.0,"tv":0.0,"id":60443},{"batb":[[0,1.59,14.53],[1,1.58,10],[2,1.5,20]],"ltp":0.0,"tv":0.0,"id":31376}]}]}
{"op":"mcm","clk":"11919162578","pt":1724099875473,"mc":[{"id":"1.231812839","rc":[{"batb":[[0,1.96,30],[1,1.3,20],[2,1.1,200]],"ltp":0.0,"tv":0.0,"id":60443},{"batb":[[0,1.58,10],[1,1.5,20],[2,1.1,200]],"ltp":0.0,"tv":0.0,"id":31376}]}]}
{"op":"mcm","clk":"11919165954","pt":1724099914373,"mc":[{"id":"1.231812839","rc":[{"batb":[[0,1.97,8.84],[1,1.96,30],[2,1.3,20]],"ltp":0.0,"tv":0.0,"id":60443},{"batb":[[0,1.59,14.53],[1,1.58,10],[2,1.5,20]],"ltp":0.0,"tv":0.0,"id":31376}]}]}
{"op":"mcm","clk":"11919278491","pt":1724101669200,"mc":[{"id":"1.231812839","rc":[{"batb":[[0,1.6,10],[1,1.59,14.54]],"ltp":0.0,"tv":0.0,"id":31376}]}]}
{"op":"mcm","clk":"11919280871","pt":1724101714751,"mc":[{"id":"1.231812839","rc":[{"batb":[[1,1.5,20],[2,1.1,200]],"ltp":0.0,"tv":0.0,"id":31376}]}]}
{"op":"mcm","clk":"11919280884","pt":1724101714957,"mc":[{"id":"1.231812839","rc":[{"batb":[[0,1.96,30],[1,1.3,20],[2,1.1,200]],"ltp":0.0,"tv":0.0,"id":60443}]}]}
{"op":"mcm","clk":"11919281090","pt":1724101719163,"mc":[{"id":"1.231812839","rc":[{"batb":[[0,1.97,8.84],[1,1.96,30],[2,1.3,20]],"ltp":0.0,"tv":0.0,"id":60443},{"batb":[[0,1.61,14.06],[1,1.6,10],[2,1.5,20]],"ltp":0.0,"tv":0.0,"id":31376}]}]}
{"op":"mcm","clk":"11919352796","pt":1724103519590,"mc":[{"id":"1.231812839","rc":[{"batb":[[0,1.96,30],[1,1.3,20],[2,1.1,200]],"ltp":0.0,"tv":0.0,"id":60443},{"batb":[[0,1.6,10],[1,1.5,20],[2,1.1,200]],"ltp":0.0,"tv":0.0,"id":31376}]}]}
{"op":"mcm","clk":"11919357264","pt":1724103646416,"mc":[{"id":"1.231812839","rc":[{"batb":[[0,1.97,8.84],[1,1.96,30],[2,1.3,20]],"ltp":0.0,"tv":0.0,"id":60443},{"batb":[[0,1.61,14.06],[1,1.6,10],[2,1.5,20]],"ltp":0.0,"tv":0.0,"id":31376}]}]}
{"op":"mcm","clk":"11919437264","pt":1724105446675,"mc":[{"id":"1.231812839","rc":[{"batb":[[0,1.97,8.84]],"ltp":0.0,"tv":0.0,"id":60443},{"batb":[[0,1.6,10],[1,1.5,20],[2,1.1,200]],"ltp":0.0,"tv":0.0,"id":31376}]}]}
{"op":"mcm","clk":"11919437269","pt":1724105446777,"mc":[{"id":"1.231812839","rc":[{"batb":[[0,1.96,30],[1,1.3,20],[2,1.1,200]],"ltp":0.0,"tv":0.0,"id":60443}]}]}
{"op":"mcm","clk":"11919442269","pt":1724105549951,"mc":[{"id":"1.231812839","rc":[{"batb":[[0,1.97,8.84],[1,1.96,30],[2,1.3,20]],"ltp":0.0,"tv":0.0,"id":60443},{"batb":[[0,1.61,14.06],[1,1.6,10],[2,1.5,20]],"ltp":0.0,"tv":0.0,"id":31376}]}]}
{"op":"mcm","clk":"11919534059","pt":1724107350395,"mc":[{"id":"1.231812839","rc":[{"batb":[[0,1.96,30],[1,1.3,20],[2,1.1,200]],"ltp":0.0,"tv":0.0,"id":60443},{"batb":[[0,1.6,10],[1,1.5,20],[2,1.1,200]],"ltp":0.0,"tv":0.0,"id":31376}]}]}
{"op":"mcm","clk":"11919539182","pt":1724107436402,"mc":[{"id":"1.231812839","rc":[{"batb":[[0,1.97,8.84],[1,1.96,30],[2,1.3,20]],"ltp":0.0,"tv":0.0,"id":60443},{"batb":[[0,1.61,14.06],[1,1.6,10],[2,1.5,20]],"ltp":0.0,"tv":0.0,"id":31376}]}]}
{"op":"mcm","clk":"11919640007","pt":1724109236604,"mc":[{"id":"1.231812839","rc":[{"batb":[[0,1.6,10],[1,1.5,20],[2,1.1,200]],"ltp":0.0,"tv":0.0,"id":31376}]}]}
{"op":"mcm","clk":"11919640017","pt":1724109236806,"mc":[{"id":"1.231812839","rc":[{"batb":[[0,1.96,30],[1,1.3,20],[2,1.1,200]],"ltp":0.0,"tv":0.0,"id":60443}]}]}
{"op":"mcm","clk":"11919643912","pt":1724109311691,"mc":[{"id":"1.231812839","rc":[{"batb":[[0,1.61,14.06],[1,1.6,10],[2,1.5,20]],"ltp":0.0,"tv":0.0,"id":31376}]}]}
{"op":"mcm","clk":"11919643924","pt":1724109311786,"mc":[{"id":"1.231812839","rc":[{"batb":[[0,1.97,8.84],[1,1.96,30],[2,1.3,20]],"ltp":0.0,"tv":0.0,"id":60443}]}]}
{"op":"mcm","clk":"11919736528","pt":1724111112124,"mc":[{"id":"1.231812839","rc":[{"batb":[[0,1.96,30],[1,1.3,20],[2,1.1,200]],"ltp":0.0,"tv":0.0,"id":60443},{"batb":[[0,1.6,10],[1,1.5,20],[2,1.1,200]],"ltp":0.0,"tv":0.0,"id":31376}]}]}
{"op":"mcm","clk":"11919739982","pt":1724111173081,"mc":[{"id":"1.231812839","rc":[{"batb":[[0,1.97,8.84],[1,1.96,30],[2,1.3,20]],"ltp":0.0,"tv":0.0,"id":60443},{"batb":[[0,1.61,14.06],[1,1.6,10],[2,1.5,20]],"ltp":0.0,"tv":0.0,"id":31376}]}]}
{"op":"mcm","clk":"11919841614","pt":1724112973451,"mc":[{"id":"1.231812839","rc":[{"batb":[[0,1.96,30],[1,1.3,20],[2,1.1,200]],"ltp":0.0,"tv":0.0,"id":60443},{"batb":[[0,1.6,10],[1,1.5,20],[2,1.1,200]],"ltp":0.0,"tv":0.0,"id":31376}]}]}
{"op":"mcm","clk":"11919843595","pt":1724113010200,"mc":[{"id":"1.231812839","rc":[{"batb":[[0,1.97,8.84],[1,1.96,30],[2,1.3,20]],"ltp":0.0,"tv":0.0,"id":60443},{"batb":[[0,1.61,14.06],[1,1.6,10],[2,1.5,20]],"ltp":0.0,"tv":0.0,"id":31376}]}]}
{"op":"mcm","clk":"11919939023","pt":1724114810628,"mc":[{"id":"1.231812839","rc":[{"batb":[[0,1.96,30],[1,1.3,20],[2,1.1,200]],"ltp":0.0,"tv":0.0,"id":60443},{"batb":[[0,1.6,10],[1,1.5,20],[2,1.1,200]],"ltp":0.0,"tv":0.0,"id":31376}]}]}
{"op":"mcm","clk":"11919939562","pt":1724114823362,"mc":[{"id":"1.231812839","rc":[{"batb":[[0,1.97,8.84],[1,1.96,30],[2,1.3,20]],"ltp":0.0,"tv":0.0,"id":60443},{"batb":[[0,1.61,14.06],[1,1.6,10],[2,1.5,20]],"ltp":0.0,"tv":0.0,"id":31376}]}]}
{"op":"mcm","clk":"11920024459","pt":1724116623730,"mc":[{"id":"1.231812839","rc":[{"batb":[[0,1.96,30],[1,1.3,20],[2,1.1,200]],"ltp":0.0,"tv":0.0,"id":60443},{"batb":[[0,1.6,10],[1,1.5,20],[2,1.1,200]],"ltp":0.0,"tv":0.0,"id":31376}]}]}
{"op":"mcm","clk":"11920030473","pt":1724116757713,"mc":[{"id":"1.231812839","rc":[{"batb":[[0,1.97,8.84],[1,1.96,30],[2,1.3,20]],"ltp":0.0,"tv":0.0,"id":60443},{"batb":[[0,1.61,14.06],[1,1.6,10],[2,1.5,20]],"ltp":0.0,"tv":0.0,"id":31376}]}]}
{"op":"mcm","clk":"11920120265","pt":1724118558192,"mc":[{"id":"1.231812839","rc":[{"batb":[[0,1.96,30],[1,1.3,20],[2,1.1,200]],"ltp":0.0,"tv":0.0,"id":60443},{"batb":[[0,1.6,10],[1,1.5,20],[2,1.1,200]],"ltp":0.0,"tv":0.0,"id":31376}]}]}
{"op":"mcm","clk":"11920125046","pt":1724118648490,"mc":[{"id":"1.231812839","rc":[{"batb":[[0,1.97,8.84],[1,1.96,30],[2,1.3,20]],"ltp":0.0,"tv":0.0,"id":60443},{"batb":[[0,1.61,14.06],[1,1.6,10],[2,1.5,20]],"ltp":0.0,"tv":0.0,"id":31376}]}]}
{"op":"mcm","clk":"11920197108","pt":1724119975137,"mc":[{"id":"1.231812839","rc":[{"batb":[[0,1.97,8.85]],"ltp":0.0,"tv":0.0,"id":60443},{"batb":[[0,1.61,14.07]],"ltp":0.0,"tv":0.0,"id":31376}]}]}
{"op":"mcm","clk":"11920217018","pt":1724120448715,"mc":[{"id":"1.231812839","rc":[{"batb":[[0,1.6,10],[1,1.5,20],[2,1.1,200]],"ltp":0.0,"tv":0.0,"id":31376}]}]}
{"op":"mcm","clk":"11920217027","pt":1724120448919,"mc":[{"id":"1.231812839","rc":[{"batb":[[0,1.96,30],[1,1.3,20],[2,1.1,200]],"ltp":0.0,"tv":0.0,"id":60443}]}]}
{"op":"mcm","clk":"11920219695","pt":1724120512899,"mc":[{"id":"1.231812839","rc":[{"batb":[[0,1.97,8.85],[1,1.96,30],[2,1.3,20]],"ltp":0.0,"tv":0.0,"id":60443},{"batb":[[0,1.61,14.07],[1,1.6,10],[2,1.5,20]],"ltp":0.0,"tv":0.0,"id":31376}]}]}
{"op":"mcm","clk":"11920331007","pt":1724123622119,"mc":[{"id":"1.231812839","rc":[{"batb":[[0,1.96,30],[1,1.3,20],[2,1.1,200]],"ltp":0.0,"tv":0.0,"id":60443},{"batb":[[0,1.6,10],[1,1.5,20],[2,1.1,200]],"ltp":0.0,"tv":0.0,"id":31376}]}]}
{"op":"mcm","clk":"11920334408","pt":1724123739080,"mc":[{"id":"1.231812839","rc":[{"batb":[[0,1.97,8.84],[1,1.96,30],[2,1.3,20]],"ltp":0.0,"tv":0.0,"id":60443},{"batb":[[0,1.61,14.06],[1,1.6,10],[2,1.5,20]],"ltp":0.0,"tv":0.0,"id":31376}]}]}
{"op":"mcm","clk":"11920394525","pt":1724125539588,"mc":[{"id":"1.231812839","rc":[{"batb":[[0,1.96,30],[1,1.3,20],[2,1.1,200]],"ltp":0.0,"tv":0.0,"id":60443},{"batb":[[0,1.6,10],[1,1.5,20],[2,1.1,200]],"ltp":0.0,"tv":0.0,"id":31376}]}]}
{"op":"mcm","clk":"11920394954","pt":1724125556327,"mc":[{"id":"1.231812839","rc":[{"batb":[[0,1.97,8.84],[1,1.96,30],[2,1.3,20]],"ltp":0.0,"tv":0.0,"id":60443},{"batb":[[0,1.61,14.06],[1,1.6,10],[2,1.5,20]],"ltp":0.0,"tv":0.0,"id":31376}]}]}
{"op":"mcm","clk":"11920451326","pt":1724127356730,"mc":[{"id":"1.231812839","rc":[{"batb":[[0,1.6,10],[1,1.5,20],[2,1.1,200]],"ltp":0.0,"tv":0.0,"id":31376}]}]}
{"op":"mcm","clk":"11920451332","pt":1724127356934,"mc":[{"id":"1.231812839","rc":[{"batb":[[0,1.96,30],[1,1.3,20],[2,1.1,200]],"ltp":0.0,"tv":0.0,"id":60443}]}]}
{"op":"mcm","clk":"11920451476","pt":1724127362048,"mc":[{"id":"1.231812839","rc":[{"batb":[[0,1.97,8.84],[1,1.96,30],[2,1.3,20]],"ltp":0.0,"tv":0.0,"id":60443},{"batb":[[0,1.61,14.06],[1,1.6,10],[2,1.5,20]],"ltp":0.0,"tv":0.0,"id":31376}]}]}
{"op":"mcm","clk":"11920511130","pt":1724129162657,"mc":[{"id":"1.231812839","rc":[{"batb":[[0,1.96,30],[1,1.3,20],[2,1.1,200]],"ltp":0.0,"tv":0.0,"id":60443},{"batb":[[0,1.6,10],[1,1.5,20],[2,1.1,200]],"ltp":0.0,"tv":0.0,"id":31376}]}]}
{"op":"mcm","clk":"11920515785","pt":1724129312619,"mc":[{"id":"1.231812839","rc":[{"batb":[[0,1.97,8.84],[1,1.96,30],[2,1.3,20]],"ltp":0.0,"tv":0.0,"id":60443},{"batb":[[0,1.61,14.06],[1,1.6,10],[2,1.5,20]],"ltp":0.0,"tv":0.0,"id":31376}]}]}
{"op":"mcm","clk":"11920593978","pt":1724131113199,"mc":[{"id":"1.231812839","rc":[{"batb":[[0,1.96,30],[1,1.3,20],[2,1.1,200]],"ltp":0.0,"tv":0.0,"id":60443},{"batb":[[0,1.6,10],[1,1.5,20],[2,1.1,200]],"ltp":0.0,"tv":0.0,"id":31376}]}]}
{"op":"mcm","clk":"11920595826","pt":1724131179651,"mc":[{"id":"1.231812839","rc":[{"batb":[[0,1.97,8.84],[1,1.96,30],[2,1.3,20]],"ltp":0.0,"tv":0.0,"id":60443},{"batb":[[0,1.61,14.06],[1,1.6,10],[2,1.5,20]],"ltp":0.0,"tv":0.0,"id":31376}]}]}
{"op":"mcm","clk":"11920659944","pt":1724132979968,"mc":[{"id":"1.231812839","rc":[{"batb":[[0,1.96,30],[1,1.3,20],[2,1.1,200]],"ltp":0.0,"tv":0.0,"id":60443},{"batb":[[0,1.6,10],[1,1.5,20],[2,1.1,200]],"ltp":0.0,"tv":0.0,"id":31376}]}]}
{"op":"mcm","clk":"11920663089","pt":1724133046335,"mc":[{"id":"1.231812839","rc":[{"batb":[[0,1.97,8.84],[1,1.96,30],[2,1.3,20]],"ltp":0.0,"tv":0.0,"id":60443},{"batb":[[0,1.61,14.06],[1,1.6,10],[2,1.5,20]],"ltp":0.0,"tv":0.0,"id":31376}]}]}
{"op":"mcm","clk":"11920717002","pt":1724134846726,"mc":[{"id":"1.231812839","rc":[{"batb":[[0,1.96,30],[1,1.3,20],[2,1.1,200]],"ltp":0.0,"tv":0.0,"id":60443},{"batb":[[0,1.61,14.06]],"ltp":0.0,"tv":0.0,"id":31376}]}]}
{"op":"mcm","clk":"11920717011","pt":1724134847032,"mc":[{"id":"1.231812839","rc":[{"batb":[[0,1.6,10],[1,1.5,20],[2,1.1,200]],"ltp":0.0,"tv":0.0,"id":31376}]}]}
{"op":"mcm","clk":"11920718697","pt":1724134911795,"mc":[{"id":"1.231812839","rc":[{"batb":[[0,1.97,8.84],[1,1.96,30],[2,1.3,20]],"ltp":0.0,"tv":0.0,"id":60443},{"batb":[[0,1.61,14.06],[1,1.6,10],[2,1.5,20]],"ltp":0.0,"tv":0.0,"id":31376}]}]}
{"op":"mcm","clk":"11920783427","pt":1724136712127,"mc":[{"id":"1.231812839","rc":[{"batb":[[0,1.96,30],[1,1.3,20],[2,1.1,200]],"ltp":0.0,"tv":0.0,"id":60443},{"batb":[[0,1.6,10],[1,1.5,20],[2,1.1,200]],"ltp":0.0,"tv":0.0,"id":31376}]}]}
{"op":"mcm","clk":"11920785245","pt":1724136776011,"mc":[{"id":"1.231812839","rc":[{"batb":[[0,1.97,8.84],[1,1.96,30],[2,1.3,20]],"ltp":0.0,"tv":0.0,"id":60443},{"batb":[[0,1.61,14.06],[1,1.6,10],[2,1.5,20]],"ltp":0.0,"tv":0.0,"id":31376}]}]}
{"op":"mcm","clk":"11920846328","pt":1724138576412,"mc":[{"id":"1.231812839","rc":[{"batb":[[0,1.96,30],[1,1.3,20],[2,1.1,200]],"ltp":0.0,"tv":0.0,"id":60443},{"batb":[[0,1.6,10],[1,1.5,20],[2,1.1,200]],"ltp":0.0,"tv":0.0,"id":31376}]}]}
{"op":"mcm","clk":"11920848370","pt":1724138638869,"mc":[{"id":"1.231812839","rc":[{"batb":[[0,1.97,8.84],[1,1.96,30],[2,1.3,20]],"ltp":0.0,"tv":0.0,"id":60443},{"batb":[[0,1.61,14.05],[1,1.6,10],[2,1.5,20]],"ltp":0.0,"tv":0.0,"id":31376}]}]}
{"op":"mcm","clk":"11920902624","pt":1724140439203,"mc":[{"id":"1.231812839","rc":[{"batb":[[0,1.96,30],[1,1.3,20],[2,1.1,200]],"ltp":0.0,"tv":0.0,"id":60443},{"batb":[[0,1.6,10],[1,1.5,20],[2,1.1,200]],"ltp":0.0,"tv":0.0,"id":31376}]}]}
{"op":"mcm","clk":"11920904875","pt":1724140503088,"mc":[{"id":"1.231812839","rc":[{"batb":[[0,1.97,8.84],[1,1.96,30],[2,1.3,20]],"ltp":0.0,"tv":0.0,"id":60443},{"batb":[[0,1.61,14.05],[1,1.6,10],[2,1.5,20]],"ltp":0.0,"tv":0.0,"id":31376}]}]}
{"op":"mcm","clk":"11920944330","pt":1724141575119,"mc":[{"id":"1.231812839","rc":[{"batb":[[0,1.61,14.05]],"ltp":0.0,"tv":0.0,"id":31376}]}]}
{"op":"mcm","clk":"11920965891","pt":1724142303444,"mc":[{"id":"1.231812839","rc":[{"batb":[[0,1.96,30],[1,1.3,20],[2,1.1,200]],"ltp":0.0,"tv":0.0,"id":60443},{"batb":[[0,1.6,10],[1,1.5,20],[2,1.1,200]],"ltp":0.0,"tv":0.0,"id":31376}]}]}
{"op":"mcm","clk":"11920969936","pt":1724142440251,"mc":[{"id":"1.231812839","rc":[{"batb":[[0,1.97,8.83],[1,1.96,30],[2,1.3,20]],"ltp":0.0,"tv":0.0,"id":60443},{"batb":[[0,1.61,14.05],[1,1.6,10],[2,1.5,20]],"ltp":0.0,"tv":0.0,"id":31376}]}]}
{"op":"mcm","clk":"11921033634","pt":1724144240663,"mc":[{"id":"1.231812839","rc":[{"batb":[[0,1.96,30],[1,1.3,20],[2,1.1,200]],"ltp":0.0,"tv":0.0,"id":60443},{"batb":[[0,1.6,10],[1,1.5,20],[2,1.1,200]],"ltp":0.0,"tv":0.0,"id":31376}]}]}
{"op":"mcm","clk":"11921034862","pt":1724144284027,"mc":[{"id":"1.231812839","rc":[{"batb":[[0,1.97,8.83],[1,1.96,30],[2,1.3,20]],"ltp":0.0,"tv":0.0,"id":60443},{"batb":[[0,1.61,14.05],[1,1.6,10],[2,1.5,20]],"ltp":0.0,"tv":0.0,"id":31376}]}]}
{"op":"mcm","clk":"11921099882","pt":1724146084496,"mc":[{"id":"1.231812839","rc":[{"batb":[[0,1.96,30],[1,1.3,20],[2,1.1,200]],"ltp":0.0,"tv":0.0,"id":60443},{"batb":[[0,1.6,10],[1,1.5,20],[2,1.1,200]],"ltp":0.0,"tv":0.0,"id":31376}]}]}
{"op":"mcm","clk":"11921101348","pt":1724146121128,"mc":[{"id":"1.231812839","rc":[{"batb":[[0,1.97,8.83],[1,1.96,30],[2,1.3,20]],"ltp":0.0,"tv":0.0,"id":60443},{"batb":[[0,1.61,14.04],[1,1.6,10],[2,1.5,20]],"ltp":0.0,"tv":0.0,"id":31376}]}]}
{"op":"mcm","clk":"11921185677","pt":1724147921560,"mc":[{"id":"1.231812839","rc":[{"batb":[[0,1.96,30],[1,1.3,20],[2,1.1,200]],"ltp":0.0,"tv":0.0,"id":60443},{"batb":[[0,1.6,10],[1,1.5,20],[2,1.1,200]],"ltp":0.0,"tv":0.0,"id":31376}]}]}
{"op":"mcm","clk":"11921186832","pt":1724147953170,"mc":[{"id":"1.231812839","rc":[{"batb":[[0,1.97,8.83],[1,1.96,30],[2,1.3,20]],"ltp":0.0,"tv":0.0,"id":60443},{"batb":[[0,1.61,14.04],[1,1.6,10],[2,1.5,20]],"ltp":0.0,"tv":0.0,"id":31376}]}]}
{"op":"mcm","clk":"11921271016","pt":1724149753585,"mc":[{"id":"1.231812839","rc":[{"batb":[[0,1.96,30],[1,1.3,20],[2,1.1,200]],"ltp":0.0,"tv":0.0,"id":60443},{"batb":[[0,1.6,10],[1,1.5,20],[2,1.1,200]],"ltp":0.0,"tv":0.0,"id":31376}]}]}
{"op":"mcm","clk":"11921272377","pt":1724149785122,"mc":[{"id":"1.231812839","rc":[{"batb":[[0,1.97,8.83],[1,1.96,30],[2,1.3,20]],"ltp":0.0,"tv":0.0,"id":60443},{"batb":[[0,1.61,14.03],[1,1.6,10],[2,1.5,20]],"ltp":0.0,"tv":0.0,"id":31376}]}]}
{"op":"mcm","clk":"11921301408","pt":1724150497459,"mc":[{"id":"1.231812839","rc":[{"batb":[[2,1.04,40]],"ltp":1.5,"tv":6.09,"id":3961}]}]}
{"op":"mcm","clk":"11921302263","pt":1724150523490,"mc":[{"id":"1.231812839","rc":[{"batb":[[2,1.03,200]],"ltp":1.5,"tv":6.09,"id":3961}]}]}
{"op":"mcm","clk":"11921303535","pt":1724150560830,"mc":[{"id":"1.231812839","rc":[{"batb":[[2,1.04,1.53]],"ltp":1.5,"tv":6.09,"id":3961}]}]}
{"op":"mcm","clk":"11921349576","pt":1724151585718,"mc":[{"id":"1.231812839","rc":[{"batb":[[0,1.96,30],[1,1.3,20],[2,1.1,200]],"ltp":0.0,"tv":0.0,"id":60443},{"batb":[[0,1.6,10],[1,1.5,20],[2,1.1,200]],"ltp":0.0,"tv":0.0,"id":31376}]}]}
{"op":"mcm","clk":"11921350333","pt":1724151601149,"mc":[{"id":"1.231812839","rc":[{"batb":[[0,1.97,8.83],[1,1.96,30],[2,1.3,20]],"ltp":0.0,"tv":0.0,"id":60443},{"batb":[[0,1.61,14.03],[1,1.6,10],[2,1.5,20]],"ltp":0.0,"tv":0.0,"id":31376}]}]}
{"op":"mcm","clk":"11921392210","pt":1724152375056,"mc":[{"id":"1.231812839","rc":[{"batb":[[0,1.97,8.83]],"ltp":0.0,"tv":0.0,"id":60443},{"batb":[[0,1.61,14.04]],"ltp":0.0,"tv":0.0,"id":31376}]}]}
{"op":"mcm","clk":"11921438149","pt":1724153401526,"mc":[{"id":"1.231812839","rc":[{"batb":[[0,1.96,30],[1,1.3,20],[2,1.1,200]],"ltp":0.0,"tv":0.0,"id":60443},{"batb":[[0,1.6,10],[1,1.5,20],[2,1.1,200]],"ltp":0.0,"tv":0.0,"id":31376}]}]}
{"op":"mcm","clk":"11921438250","pt":1724153403143,"mc":[{"id":"1.231812839","rc":[{"batb":[[0,1.97,8.83],[1,1.96,30],[2,1.3,20]],"ltp":0.0,"tv":0.0,"id":60443},{"batb":[[0,1.61,14.04],[1,1.6,10],[2,1.5,20]],"ltp":0.0,"tv":0.0,"id":31376}]}]}
{"op":"mcm","clk":"11921517231","pt":1724155206274,"mc":[{"id":"1.231812839","rc":[{"batb":[[0,1.96,30],[1,1.3,20],[2,1.1,200]],"ltp":0.0,"tv":0.0,"id":60443},{"batb":[[0,1.6,10],[1,1.5,20],[2,1.1,200]],"ltp":0.0,"tv":0.0,"id":31376}]}]}
{"op":"mcm","clk":"11921523916","pt":1724155343922,"mc":[{"id":"1.231812839","rc":[{"batb":[[0,1.97,8.83],[1,1.96,30],[2,1.3,20]],"ltp":0.0,"tv":0.0,"id":60443},{"batb":[[0,1.61,14.03],[1,1.6,10],[2,1.5,20]],"ltp":0.0,"tv":0.0,"id":31376}]}]}
{"op":"mcm","clk":"11921566192","pt":1724156287209,"mc":[{"id":"1.231812839","rc":[{"batb":[[0,1.62,10],[1,1.61,14.03]],"ltp":0.0,"tv":0.0,"id":31376}]}]}
{"op":"mcm","clk":"11921611631","pt":1724157144340,"mc":[{"id":"1.231812839","rc":[{"batb":[[0,1.96,30],[1,1.3,20],[2,1.1,200]],"ltp":0.0,"tv":0.0,"id":60443},{"batb":[[1,1.5,20],[2,1.1,200]],"ltp":0.0,"tv":0.0,"id":31376}]}]}
{"op":"mcm","clk":"11921613373","pt":1724157178986,"mc":[{"id":"1.231812839","rc":[{"batb":[[0,1.97,8.83],[1,1.96,30],[2,1.3,20]],"ltp":0.0,"tv":0.0,"id":60443},{"batb":[[0,1.63,13.59],[1,1.62,10],[2,1.5,20]],"ltp":0.0,"tv":0.0,"id":31376}]}]}
{"op":"mcm","clk":"11921644875","pt":1724157766730,"mc":[{"id":"1.231812839","rc":[{"batb":[[1,1.3,20],[2,1.1,200]],"ltp":0.0,"tv":0.0,"id":60443}]}]}
{"op":"mcm","clk":"11921644880","pt":1724157766832,"mc":[{"id":"1.231812839","rc":[{"batb":[[0,1.98,30],[1,1.97,8.83],[2,1.3,20]],"ltp":0.0,"tv":0.0,"id":60443}]}]}
{"op":"mcm","clk":"11921654981","pt":1724157782594,"mc":[{"id":"1.231812839","rc":[{"batl":[[0,10,9],[1,95,5.85],[2,990,5]],"ltp":1.5,"tv":6.09,"id":3961},{"batl":[[0,11,8],[1,95,5.85],[2,990,5]],"ltp":0.0,"tv":0.0,"id":31376}]}]}
{"op":"mcm","clk":"11921714380","pt":1724158979421,"mc":[{"id":"1.231812839","rc":[{"batb":[[0,1.5,20.84]],"ltp":1.5,"tv":6.09,"id":3961},{"batb":[[1,1.3,20],[2,1.1,200]],"ltp":0.0,"tv":0.0,"id":60443},{"batb":[[0,1.62,10],[1,1.5,20],[2,1.1,200]],"ltp":0.0,"tv":0.0,"id":31376}]}]}
{"op":"mcm","clk":"11921715553","pt":1724159001664,"mc":[{"id":"1.231812839","rc":[{"batb":[[0,1.99,8.65],[1,1.98,30],[2,1.3,20]],"ltp":0.0,"tv":0.0,"id":60443},{"batb":[[0,1.63,13.59],[1,1.62,10],[2,1.5,20]],"ltp":0.0,"tv":0.0,"id":31376}]}]}
{"op":"mcm","clk":"11921815667","pt":1724160802180,"mc":[{"id":"1.231812839","rc":[{"batb":[[0,1.98,30],[1,1.3,20],[2,1.1,200]],"ltp":0.0,"tv":0.0,"id":60443},{"batb":[[0,1.62,10],[1,1.5,20],[2,1.1,200]],"ltp":0.0,"tv":0.0,"id":31376}]}]}
{"op":"mcm","clk":"11921816215","pt":1724160813112,"mc":[{"id":"1.231812839","rc":[{"batb":[[0,1.99,8.65],[1,1.98,30],[2,1.3,20]],"ltp":0.0,"tv":0.0,"id":60443},{"batb":[[0,1.63,13.59],[1,1.62,10],[2,1.5,20]],"ltp":0.0,"tv":0.0,"id":31376}]}]}
{"op":"mcm","clk":"11921911894","pt":1724162613467,"mc":[{"id":"1.231812839","rc":[{"batb":[[0,1.98,30],[1,1.3,20],[2,1.1,200]],"ltp":0.0,"tv":0.0,"id":60443},{"batb":[[0,1.62,10],[1,1.5,20],[2,1.1,200]],"ltp":0.0,"tv":0.0,"id":31376}]}]}
{"op":"mcm","clk":"11921912110","pt":1724162617279,"mc":[{"id":"1.231812839","rc":[{"batb":[[0,1.99,8.65],[1,1.98,30],[2,1.3,20]],"ltp":0.0,"tv":0.0,"id":60443},{"batb":[[0,1.63,13.6],[1,1.62,10],[2,1.5,20]],"ltp":0.0,"tv":0.0,"id":31376}]}]}
{"op":"mcm","clk":"11922023537","pt":1724164417565,"mc":[{"id":"1.231812839","rc":[{"batb":[[0,1.98,30],[1,1.3,20],[2,1.1,200]],"ltp":0.0,"tv":0.0,"id":60443}]}]}
{"op":"mcm","clk":"11922023551","pt":1724164417771,"mc":[{"id":"1.231812839","rc":[{"batb":[[0,1.62,10],[1,1.5,20],[2,1.1,200]],"ltp":0.0,"tv":0.0,"id":31376}]}]}
{"op":"mcm","clk":"11922032977","pt":1724164574827,"mc":[{"id":"1.231812839","rc":[{"batb":[[0,1.99,8.65],[1,1.98,30],[2,1.3,20]],"ltp":0.0,"tv":0.0,"id":60443},{"batb":[[0,1.63,13.6],[1,1.62,10],[2,1.5,20]],"ltp":0.0,"tv":0.0,"id":31376}]}]}
{"op":"mcm","clk":"11922134366","pt":1724166355513,"mc":[{"id":"1.231812839","rc":[{"batb":[[0,1.99,8.66]],"ltp":0.0,"tv":0.0,"id":60443},{"batb":[[0,1.63,13.6]],"ltp":0.0,"tv":0.0,"id":31376}]}]}
{"op":"mcm","clk":"11922134404","pt":1724166355925,"mc":[{"id":"1.231812839","rc":[{"batl":[[1,90,1.02],[2,95,5]],"ltp":1.5,"tv":6.1,"id":3961},{"batl":[[0,90,1.22]],"ltp":0.0,"tv":0.0,"id":60443},{"batl":[[1,90,1.02],[2,95,5]],"ltp":0.0,"tv":0.0,"id":31376}]}]}
{"op":"mcm","clk":"11922134826","pt":1724166361137,"mc":[{"id":"1.231812839","rc":[{"batl":[[2,990,5.17]],"ltp":0.0,"tv":0.0,"id":60443}]}]}
{"op":"mcm","clk":"11922135833","pt":1724166375155,"mc":[{"id":"1.231812839","rc":[{"batb":[[0,1.98,30],[1,1.3,20],[2,1.1,200]],"ltp":0.0,"tv":0.0,"id":60443},{"batb":[[0,1.62,10],[1,1.5,20],[2,1.1,200]],"ltp":0.0,"tv":0.0,"id":31376}]}]}
{"op":"mcm","clk":"11922139444","pt":1724166422796,"mc":[{"id":"1.231812839","rc":[{"batl":[[2,990,5.34]],"ltp":0.0,"tv":0.0,"id":60443}]}]}
{"op":"mcm","clk":"11922141894","pt":1724166458816,"mc":[{"id":"1.231812839","rc":[{"batl":[[2,990,5.51]],"ltp":0.0,"tv":0.0,"id":60443}]}]}
{"op":"mcm","clk":"11922145743","pt":1724166514976,"mc":[{"id":"1.231812839","rc":[{"batb":[[0,1.99,8.66],[1,1.98,30],[2,1.3,20]],"ltp":0.0,"tv":0.0,"id":60443},{"batb":[[0,1.63,13.6],[1,1.62,10],[2,1.5,20]],"ltp":0.0,"tv":0.0,"id":31376}]}]}
{"op":"mcm","clk":"11922281264","pt":1724168315632,"mc":[{"id":"1.231812839","rc":[{"batb":[[0,1.98,30],[1,1.3,20],[2,1.1,200]],"ltp":0.0,"tv":0.0,"id":60443},{"batb":[[0,1.62,10],[1,1.5,20],[2,1.1,200]],"ltp":0.0,"tv":0.0,"id":31376}]}]}
{"op":"mcm","clk":"11922293383","pt":1724168445065,"mc":[{"id":"1.231812839","rc":[{"batb":[[0,1.99,8.66],[1,1.98,30],[2,1.3,20]],"ltp":0.0,"tv":0.0,"id":60443},{"batb":[[0,1.63,13.6],[1,1.62,10],[2,1.5,20]],"ltp":0.0,"tv":0.0,"id":31376}]}]}
{"op":"mcm","clk":"11922472868","pt":1724170245712,"mc":[{"id":"1.231812839","rc":[{"batb":[[0,1.98,30],[1,1.3,20],[2,1.1,200]],"ltp":0.0,"tv":0.0,"id":60443},{"batb":[[0,1.62,10],[1,1.5,20],[2,1.1,200]],"ltp":0.0,"tv":0.0,"id":31376}]}]}
{"op":"mcm","clk":"11922485687","pt":1724170362599,"mc":[{"id":"1.231812839","rc":[{"batb":[[0,1.99,8.66],[1,1.98,30],[2,1.3,20]],"ltp":0.0,"tv":0.0,"id":60443},{"batb":[[0,1.63,13.6],[1,1.62,10],[2,1.5,20]],"ltp":0.0,"tv":0.0,"id":31376}]}]}
{"op":"mcm","clk":"11922681914","pt":1724172163386,"mc":[{"id":"1.231812839","rc":[{"batb":[[0,1.98,30],[1,1.3,20],[2,1.1,200]],"ltp":0.0,"tv":0.0,"id":60443},{"batb":[[0,1.62,10],[1,1.5,20],[2,1.1,200]],"ltp":0.0,"tv":0.0,"id":31376}]}]}
{"op":"mcm","clk":"11922691579","pt":1724172256194,"mc":[{"id":"1.231812839","rc":[{"batb":[[0,1.99,8.66],[1,1.98,30],[2,1.3,20]],"ltp":0.0,"tv":0.0,"id":60443},{"batb":[[0,1.63,13.6],[1,1.62,10],[2,1.5,20]],"ltp":0.0,"tv":0.0,"id":31376}]}]}
{"op":"mcm","clk":"11922882232","pt":1724173975057,"mc":[{"id":"1.231812839","rc":[{"batb":[[0,1.99,8.66]],"ltp":0.0,"tv":0.0,"id":60443},{"batb":[[0,1.63,13.61]],"ltp":0.0,"tv":0.0,"id":31376}]}]}
{"op":"mcm","clk":"11922892497","pt":1724174056752,"mc":[{"id":"1.231812839","rc":[{"batb":[[0,1.98,30],[1,1.3,20],[2,1.1,200]],"ltp":0.0,"tv":0.0,"id":60443}]}]}
{"op":"mcm","clk":"11922892522","pt":1724174056914,"mc":[{"id":"1.231812839","rc":[{"batb":[[0,1.62,10],[1,1.5,20],[2,1.1,200]],"ltp":0.0,"tv":0.0,"id":31376}]}]}
{"op":"mcm","clk":"11922901118","pt":1724174127417,"mc":[{"id":"1.231812839","rc":[{"batb":[[0,1.99,8.66],[1,1.98,30],[2,1.3,20]],"ltp":0.0,"tv":0.0,"id":60443},{"batb":[[0,1.63,13.61],[1,1.62,10],[2,1.5,20]],"ltp":0.0,"tv":0.0,"id":31376}]}]}
{"op":"mcm","clk":"11923103610","pt":1724175927764,"mc":[{"id":"1.231812839","rc":[{"batb":[[0,1.98,30],[1,1.3,20],[2,1.1,200]],"ltp":0.0,"tv":0.0,"id":60443}]}]}
{"op":"mcm","clk":"11923103631","pt":1724175927970,"mc":[{"id":"1.231812839","rc":[{"batb":[[0,1.62,10],[1,1.5,20],[2,1.1,200]],"ltp":0.0,"tv":0.0,"id":31376}]}]}
{"op":"mcm","clk":"11923107989","pt":1724175963409,"mc":[{"id":"1.231812839","rc":[{"batb":[[0,1.99,8.66],[1,1.98,30],[2,1.3,20]],"ltp":0.0,"tv":0.0,"id":60443},{"batb":[[0,1.63,13.61],[1,1.62,10],[2,1.5,20]],"ltp":0.0,"tv":0.0,"id":31376}]}]}
{"op":"mcm","clk":"11923208875","pt":1724176964890,"mc":[{"id":"1.231812839","rc":[{"batl":[[0,9.8,1],[1,10,9],[2,90,1.02]],"ltp":1.5,"tv":6.1,"id":3961},{"batb":[[0,1.99,8.67]],"ltp":0.0,"tv":0.0,"id":60443},{"batb":[[0,1.63,13.62]],"ltp":0.0,"tv":0.0,"id":31376}]}]}
{"op":"mcm","clk":"11923225238","pt":1724177096652,"mc":[{"id":"1.231812839","rc":[{"batl":[[0,85,1.36],[1,95,5.85]],"ltp":0.0,"tv":0.0,"id":60443}]}]}
{"op":"mcm","clk":"11923226029","pt":1724177102355,"mc":[{"id":"1.231812839","rc":[{"batl":[[0,10.5,1],[1,11,8],[2,90,1.02]],"ltp":0.0,"tv":0.0,"id":31376}]}]}
{"op":"mcm","clk":"11923319379","pt":1724177763605,"mc":[{"id":"1.231812839","rc":[{"batb":[[0,1.62,10],[1,1.5,20],[2,1.1,200]],"ltp":0.0,"tv":0.0,"id":31376}]}]}
{"op":"mcm","clk":"11923319406","pt":1724177763811,"mc":[{"id":"1.231812839","rc":[{"batb":[[0,1.98,30],[1,1.3,20],[2,1.1,200]],"ltp":0.0,"tv":0.0,"id":60443}]}]}
{"op":"mcm","clk":"11923320503","pt":1724177771624,"mc":[{"id":"1.231812839","rc":[{"batb":[[0,1.99,8.67],[1,1.98,30],[2,1.3,20]],"ltp":0.0,"tv":0.0,"id":60443},{"batb":[[0,1.63,13.62],[1,1.62,10],[2,1.5,20]],"ltp":0.0,"tv":0.0,"id":31376}]}]}
{"op":"mcm","clk":"11923575924","pt":1724179572043,"mc":[{"id":"1.231812839","rc":[{"batb":[[0,1.98,30],[1,1.3,20],[2,1.1,200]],"ltp":0.0,"tv":0.0,"id":60443},{"batb":[[0,1.62,10],[1,1.5,20],[2,1.1,200]],"ltp":0.0,"tv":0.0,"id":31376}]}]}
{"op":"mcm","clk":"11923593715","pt":1724179676528,"mc":[{"id":"1.231812839","rc":[{"batb":[[0,1.99,8.67],[1,1.98,30],[2,1.3,20]],"ltp":0.0,"tv":0.0,"id":60443},{"batb":[[0,1.63,13.62],[1,1.62,10],[2,1.5,20]],"ltp":0.0,"tv":0.0,"id":31376}]}]}
{"op":"mcm","clk":"11923888967","pt":1724181477278,"mc":[{"id":"1.231812839","rc":[{"batb":[[0,1.98,30],[1,1.3,20],[2,1.1,200]],"ltp":0.0,"tv":0.0,"id":60443},{"batb":[[0,1.62,10],[1,1.5,20],[2,1.1,200]],"ltp":0.0,"tv":0.0,"id":31376}]}]}
{"op":"mcm","clk":"11923899545","pt":1724181537082,"mc":[{"id":"1.231812839","rc":[{"batb":[[0,1.99,8.67],[1,1.98,30],[2,1.3,20]],"ltp":0.0,"tv":0.0,"id":60443},{"batb":[[0,1.63,13.62],[1,1.62,10],[2,1.5,20]],"ltp":0.0,"tv":0.0,"id":31376}]}]}
{"op":"mcm","clk":"11924158769","pt":1724183337750,"mc":[{"id":"1.231812839","rc":[{"batb":[[0,1.98,30],[1,1.3,20],[2,1.1,200]],"ltp":0.0,"tv":0.0,"id":60443},{"batb":[[0,1.62,10],[1,1.5,20],[2,1.1,200]],"ltp":0.0,"tv":0.0,"id":31376}]}]}
{"op":"mcm","clk":"11924164338","pt":1724183377287,"mc":[{"id":"1.231812839","rc":[{"batb":[[0,1.99,8.67],[1,1.98,30],[2,1.3,20]],"ltp":0.0,"tv":0.0,"id":60443},{"batb":[[0,1.63,13.62],[1,1.62,10],[2,1.5,20]],"ltp":0.0,"tv":0.0,"id":31376}]}]}
{"op":"mcm","clk":"11924202499","pt":1724183646091,"mc":[{"id":"1.231812839","rc":[{"batl":[[0,9.6,9],[1,9.8,1]],"ltp":1.5,"tv":6.1,"id":3961},{"batb":[[0,2,30],[1,1.99,8.67]],"ltp":0.0,"tv":0.0,"id":60443},{"batl":[[0,10,8],[1,10.5,1]],"ltp":0.0,"tv":0.0,"id":31376}]}]}
{"op":"mcm","clk":"11924203260","pt":1724183651821,"mc":[{"id":"1.231812839","rc":[{"batl":[[1,90,1.02],[2,95,5]],"ltp":1.5,"tv":6.1,"id":3961},{"batl":[[1,90,1.02],[2,95,5]],"ltp":0.0,"tv":0.0,"id":31376}]}]}
{"op":"mcm","clk":"11924204021","pt":1724183657336,"mc":[{"id":"1.231812839","rc":[{"batl":[[0,9.4,1],[1,9.6,9],[2,90,1.02]],"ltp":1.5,"tv":6.1,"id":3961},{"batl":[[0,9.8,1],[1,10,8],[2,90,1.02]],"ltp":0.0,"tv":0.0,"id":31376}]}]}
{"op":"mcm","clk":"11924354062","pt":1724184775061,"mc":[{"id":"1.231812839","rc":[{"batb":[[1,1.99,8.67]],"ltp":0.0,"tv":0.0,"id":60443},{"batb":[[0,1.63,13.62]],"ltp":0.0,"tv":0.0,"id":31376}]}]}
{"op":"mcm","clk":"11924402032","pt":1724185177985,"mc":[{"id":"1.231812839","rc":[{"batb":[[1,1.3,20],[2,1.1,200]],"ltp":0.0,"tv":0.0,"id":60443},{"batb":[[0,1.62,10],[1,1.5,20],[2,1.1,200]],"ltp":0.0,"tv":0.0,"id":31376}]}]}
{"op":"mcm","clk":"11924417426","pt":1724185305813,"mc":[{"id":"1.231812839","rc":[{"batb":[[0,2.02,8.41],[1,2,30],[2,1.3,20]],"ltp":0.0,"tv":0.0,"id":60443},{"batb":[[0,1.63,13.62],[1,1.62,10],[2,1.5,20]],"ltp":0.0,"tv":0.0,"id":31376}]}]}
{"op":"mcm","clk":"11924563030","pt":1724187106508,"mc":[{"id":"1.231812839","rc":[{"batb":[[0,2,30],[1,1.3,20],[2,1.1,200]],"ltp":0.0,"tv":0.0,"id":60443},{"batb":[[0,1.62,10],[1,1.5,20],[2,1.1,200]],"ltp":0.0,"tv":0.0,"id":31376}]}]}
{"op":"mcm","clk":"11924565176","pt":1724187165501,"mc":[{"id":"1.231812839","rc":[{"batb":[[0,2.02,8.41],[1,2,30],[2,1.3,20]],"ltp":0.0,"tv":0.0,"id":60443},{"batb":[[0,1.63,13.62],[1,1.62,10],[2,1.5,20]],"ltp":0.0,"tv":0.0,"id":31376}]}]}
{"op":"mcm","clk":"11924634961","pt":1724188966238,"mc":[{"id":"1.231812839","rc":[{"batb":[[0,2,30],[1,1.3,20],[2,1.1,200]],"ltp":0.0,"tv":0.0,"id":60443},{"batb":[[0,1.62,10],[1,1.5,20],[2,1.1,200]],"ltp":0.0,"tv":0.0,"id":31376}]}]}
{"op":"mcm","clk":"11924638172","pt":1724189056957,"mc":[{"id":"1.231812839","rc":[{"batb":[[0,2.02,8.41],[1,2,30],[2,1.3,20]],"ltp":0.0,"tv":0.0,"id":60443},{"batb":[[0,1.63,13.62],[1,1.62,10],[2,1.5,20]],"ltp":0.0,"tv":0.0,"id":31376}]}]}
{"op":"mcm","clk":"11924730063","pt":1724190857451,"mc":[{"id":"1.231812839","rc":[{"batb":[[0,2,30],[1,1.3,20],[2,1.1,200]],"ltp":0.0,"tv":0.0,"id":60443},{"batb":[[0,1.62,10],[1,1.5,20],[2,1.1,200]],"ltp":0.0,"tv":0.0,"id":31376}]}]}
{"op":"mcm","clk":"11924732354","pt":1724190909193,"mc":[{"id":"1.231812839","rc":[{"batb":[[0,2.02,8.41],[1,2,30],[2,1.3,20]],"ltp":0.0,"tv":0.0,"id":60443},{"batb":[[0,1.63,13.62],[1,1.62,10],[2,1.5,20]],"ltp":0.0,"tv":0.0,"id":31376}]}]}
{"op":"mcm","clk":"11924764652","pt":1724191525180,"mc":[{"id":"1.231812839","rc":[{"batb":[[0,1.64,10],[1,1.63,13.62]],"ltp":0.0,"tv":0.0,"id":31376}]}]}
{"op":"mcm","clk":"11924833369","pt":1724192709972,"mc":[{"id":"1.231812839","rc":[{"batb":[[0,2,30],[1,1.3,20],[2,1.1,200]],"ltp":0.0,"tv":0.0,"id":60443},{"batb":[[1,1.5,20],[2,1.1,200]],"ltp":0.0,"tv":0.0,"id":31376}]}]}
{"op":"mcm","clk":"11924835233","pt":1724192748047,"mc":[{"id":"1.231812839","rc":[{"batb":[[0,2.02,8.41],[1,2,30],[2,1.3,20]],"ltp":0.0,"tv":0.0,"id":60443},{"batb":[[0,1.65,13.2],[1,1.64,10],[2,1.5,20]],"ltp":0.0,"tv":0.0,"id":31376}]}]}
{"op":"mcm","clk":"11924940248","pt":1724194548597,"mc":[{"id":"1.231812839","rc":[{"batb":[[0,1.64,10],[1,1.5,20],[2,1.1,200]],"ltp":0.0,"tv":0.0,"id":31376}]}]}
{"op":"mcm","clk":"11924940253","pt":1724194548803,"mc":[{"id":"1.231812839","rc":[{"batb":[[0,2,30],[1,1.3,20],[2,1.1,200]],"ltp":0.0,"tv":0.0,"id":60443}]}]}
{"op":"mcm","clk":"11924941301","pt":1724194570263,"mc":[{"id":"1.231812839","rc":[{"batb":[[0,2.02,8.41],[1,2,30],[2,1.3,20]],"ltp":0.0,"tv":0.0,"id":60443},{"batb":[[0,1.65,13.2],[1,1.64,10],[2,1.5,20]],"ltp":0.0,"tv":0.0,"id":31376}]}]}
{"op":"mcm","clk":"11924997866","pt":1724195575134,"mc":[{"id":"1.231812839","rc":[{"batb":[[0,1.65,13.2]],"ltp":0.0,"tv":0.0,"id":31376}]}]}
{"op":"mcm","clk":"11925040455","pt":1724196370672,"mc":[{"id":"1.231812839","rc":[{"batb":[[0,2,30],[1,1.3,20],[2,1.1,200]],"ltp":0.0,"tv":0.0,"id":60443}]}]}
{"op":"mcm","clk":"11925040469","pt":1724196370830,"mc":[{"id":"1.231812839","rc":[{"batb":[[0,1.64,10],[1,1.5,20],[2,1.1,200]],"ltp":0.0,"tv":0.0,"id":31376}]}]}
{"op":"mcm","clk":"11925047506","pt":1724196488959,"mc":[{"id":"1.231812839","rc":[{"batb":[[0,2.02,8.42],[1,2,30],[2,1.3,20]],"ltp":0.0,"tv":0.0,"id":60443},{"batb":[[0,1.65,13.2],[1,1.64,10],[2,1.5,20]],"ltp":0.0,"tv":0.0,"id":31376}]}]}
{"op":"mcm","clk":"11925135664","pt":1724198289556,"mc":[{"id":"1.231812839","rc":[{"batb":[[0,2,30],[1,1.3,20],[2,1.1,200]],"ltp":0.0,"tv":0.0,"id":60443},{"batb":[[0,1.64,10],[1,1.5,20],[2,1.1,200]],"ltp":0.0,"tv":0.0,"id":31376}]}]}
{"op":"mcm","clk":"11925140510","pt":1724198385156,"mc":[{"id":"1.231812839","rc":[{"batb":[[0,2.02,8.42],[1,2,30],[2,1.3,20]],"ltp":0.0,"tv":0.0,"id":60443},{"batb":[[0,1.65,13.2],[1,1.64,10],[2,1.5,20]],"ltp":0.0,"tv":0.0,"id":31376}]}]}
{"op":"mcm","clk":"11925232381","pt":1724200185596,"mc":[{"id":"1.231812839","rc":[{"batb":[[0,2.02,8.41]],"ltp":0.0,"tv":0.0,"id":60443},{"batb":[[0,1.64,10],[1,1.5,20],[2,1.1,200]],"ltp":0.0,"tv":0.0,"id":31376}]}]}
{"op":"mcm","clk":"11925232394","pt":1724200185797,"mc":[{"id":"1.231812839","rc":[{"batb":[[0,2,30],[1,1.3,20],[2,1.1,200]],"ltp":0.0,"tv":0.0,"id":60443}]}]}
{"op":"mcm","clk":"11925236168","pt":1724200241964,"mc":[{"id":"1.231812839","rc":[{"batb":[[0,2.02,8.41],[1,2,30],[2,1.3,20]],"ltp":0.0,"tv":0.0,"id":60443},{"batb":[[0,1.65,13.2],[1,1.64,10],[2,1.5,20]],"ltp":0.0,"tv":0.0,"id":31376}]}]}
{"op":"mcm","clk":"11925377580","pt":1724202042731,"mc":[{"id":"1.231812839","rc":[{"batb":[[0,2,30],[1,1.3,20],[2,1.1,200]],"ltp":0.0,"tv":0.0,"id":60443},{"batb":[[0,1.64,10],[1,1.5,20],[2,1.1,200]],"ltp":0.0,"tv":0.0,"id":31376}]}]}
{"op":"mcm","clk":"11925379810","pt":1724202074266,"mc":[{"id":"1.231812839","rc":[{"batb":[[0,2.02,8.41],[1,2,30],[2,1.3,20]],"ltp":0.0,"tv":0.0,"id":60443},{"batb":[[0,1.65,13.2],[1,1.64,10],[2,1.5,20]],"ltp":0.0,"tv":0.0,"id":31376}]}]}
{"op":"mcm","clk":"11925496873","pt":1724203874554,"mc":[{"id":"1.231812839","rc":[{"batb":[[0,2,30],[1,1.3,20],[2,1.1,200]],"ltp":0.0,"tv":0.0,"id":60443},{"batb":[[0,1.64,10],[1,1.5,20],[2,1.1,200]],"ltp":0.0,"tv":0.0,"id":31376}]}]}
{"op":"mcm","clk":"11925497463","pt":1724203883975,"mc":[{"id":"1.231812839","rc":[{"batb":[[0,2.02,8.41],[1,2,30],[2,1.3,20]],"ltp":0.0,"tv":0.0,"id":60443},{"batb":[[0,1.65,13.2],[1,1.64,10],[2,1.5,20]],"ltp":0.0,"tv":0.0,"id":31376}]}]}
{"op":"mcm","clk":"11925634835","pt":1724205684666,"mc":[{"id":"1.231812839","rc":[{"batb":[[0,2,30],[1,1.3,20],[2,1.1,200]],"ltp":0.0,"tv":0.0,"id":60443},{"batb":[[0,1.64,10],[1,1.5,20],[2,1.1,200]],"ltp":0.0,"tv":0.0,"id":31376}]}]}
{"op":"mcm","clk":"11925642895","pt":1724205781688,"mc":[{"id":"1.231812839","rc":[{"batb":[[0,2.02,8.41],[1,2,30],[2,1.3,20]],"ltp":0.0,"tv":0.0,"id":60443},{"batb":[[0,1.65,13.2],[1,1.64,10],[2,1.5,20]],"ltp":0.0,"tv":0.0,"id":31376}]}]}
{"op":"mcm","clk":"11925760505","pt":1724207582176,"mc":[{"id":"1.231812839","rc":[{"batb":[[0,2,30],[1,1.3,20],[2,1.1,200]],"ltp":0.0,"tv":0.0,"id":60443},{"batb":[[0,1.64,10],[1,1.5,20],[2,1.1,200]],"ltp":0.0,"tv":0.0,"id":31376}]}]}
{"op":"mcm","clk":"11925763317","pt":1724207650491,"mc":[{"id":"1.231812839","rc":[{"batb":[[0,2.02,8.41],[1,2,30],[2,1.3,20]],"ltp":0.0,"tv":0.0,"id":60443},{"batb":[[0,1.65,13.2],[1,1.64,10],[2,1.5,20]],"ltp":0.0,"tv":0.0,"id":31376}]}]}
{"op":"mcm","clk":"11925840187","pt":1724209451019,"mc":[{"id":"1.231812839","rc":[{"batb":[[0,2,30],[1,1.3,20],[2,1.1,200]],"ltp":0.0,"tv":0.0,"id":60443},{"batb":[[0,1.64,10],[1,1.5,20],[2,1.1,200]],"ltp":0.0,"tv":0.0,"id":31376}]}]}
{"op":"mcm","clk":"11925841656","pt":1724209488168,"mc":[{"id":"1.231812839","rc":[{"batb":[[0,2.02,8.41],[1,2,30],[2,1.3,20]],"ltp":0.0,"tv":0.0,"id":60443},{"batb":[[0,1.65,13.2],[1,1.64,10],[2,1.5,20]],"ltp":0.0,"tv":0.0,"id":31376}]}]}
{"op":"mcm","clk":"11925906342","pt":1724211288579,"mc":[{"id":"1.231812839","rc":[{"batb":[[0,2,30],[1,1.3,20],[2,1.1,200]],"ltp":0.0,"tv":0.0,"id":60443}]}]}
{"op":"mcm","clk":"11925906349","pt":1724211288779,"mc":[{"id":"1.231812839","rc":[{"batb":[[0,1.64,10],[1,1.5,20],[2,1.1,200]],"ltp":0.0,"tv":0.0,"id":31376}]}]}
{"op":"mcm","clk":"11925907057","pt":1724211311094,"mc":[{"id":"1.231812839","rc":[{"batb":[[0,2.02,8.41],[1,2,30],[2,1.3,20]],"ltp":0.0,"tv":0.0,"id":60443},{"batb":[[0,1.65,13.2],[1,1.64,10],[2,1.5,20]],"ltp":0.0,"tv":0.0,"id":31376}]}]}
{"op":"mcm","clk":"11925977600","pt":1724213111762,"mc":[{"id":"1.231812839","rc":[{"batb":[[0,2,30],[1,1.3,20],[2,1.1,200]],"ltp":0.0,"tv":0.0,"id":60443},{"batb":[[0,1.64,10],[1,1.5,20],[2,1.1,200]],"ltp":0.0,"tv":0.0,"id":31376}]}]}
{"op":"mcm","clk":"11925978112","pt":1724213125155,"mc":[{"id":"1.231812839","rc":[{"batb":[[0,2.02,8.41],[1,2,30],[2,1.3,20]],"ltp":0.0,"tv":0.0,"id":60443},{"batb":[[0,1.65,13.2],[1,1.64,10],[2,1.5,20]],"ltp":0.0,"tv":0.0,"id":31376}]}]}
{"op":"mcm","clk":"11926033084","pt":1724214925657,"mc":[{"id":"1.231812839","rc":[{"batb":[[0,2,30],[1,1.3,20],[2,1.1,200]],"ltp":0.0,"tv":0.0,"id":60443}]}]}
{"op":"mcm","clk":"11926033092","pt":1724214925862,"mc":[{"id":"1.231812839","rc":[{"batb":[[0,1.64,10],[1,1.5,20],[2,1.1,200]],"ltp":0.0,"tv":0.0,"id":31376}]}]}
{"op":"mcm","clk":"11926035900","pt":1724215020376,"mc":[{"id":"1.231812839","rc":[{"batb":[[0,2.02,8.41],[1,2,30],[2,1.3,20]],"ltp":0.0,"tv":0.0,"id":60443},{"batb":[[0,1.65,13.2],[1,1.64,10],[2,1.5,20]],"ltp":0.0,"tv":0.0,"id":31376}]}]}
{"op":"mcm","clk":"11926112407","pt":1724216820687,"mc":[{"id":"1.231812839","rc":[{"batb":[[0,2,30],[1,1.3,20],[2,1.1,200]],"ltp":0.0,"tv":0.0,"id":60443},{"batb":[[0,1.64,10],[1,1.5,20],[2,1.1,200]],"ltp":0.0,"tv":0.0,"id":31376}]}]}
{"op":"mcm","clk":"11926116550","pt":1724216905579,"mc":[{"id":"1.231812839","rc":[{"batb":[[0,2.02,8.41],[1,2,30],[2,1.3,20]],"ltp":0.0,"tv":0.0,"id":60443},{"batb":[[0,1.65,13.2],[1,1.64,10],[2,1.5,20]],"ltp":0.0,"tv":0.0,"id":31376}]}]}
{"op":"mcm","clk":"11926199625","pt":1724218706257,"mc":[{"id":"1.231812839","rc":[{"batb":[[0,2,30],[1,1.3,20],[2,1.1,200]],"ltp":0.0,"tv":0.0,"id":60443},{"batb":[[0,1.64,10],[1,1.5,20],[2,1.1,200]],"ltp":0.0,"tv":0.0,"id":31376}]}]}
{"op":"mcm","clk":"11926202606","pt":1724218784669,"mc":[{"id":"1.231812839","rc":[{"batb":[[0,2.02,8.41],[1,2,30],[2,1.3,20]],"ltp":0.0,"tv":0.0,"id":60443},{"batb":[[0,1.65,13.2],[1,1.64,10],[2,1.5,20]],"ltp":0.0,"tv":0.0,"id":31376}]}]}
{"op":"mcm","clk":"11926278196","pt":1724220585238,"mc":[{"id":"1.231812839","rc":[{"batb":[[0,2,30],[1,1.3,20],[2,1.1,200]],"ltp":0.0,"tv":0.0,"id":60443},{"batb":[[0,1.64,10],[1,1.5,20],[2,1.1,200]],"ltp":0.0,"tv":0.0,"id":31376}]}]}
{"op":"mcm","clk":"11926281226","pt":1724220659527,"mc":[{"id":"1.231812839","rc":[{"batb":[[0,2.02,8.41],[1,2,30],[2,1.3,20]],"ltp":0.0,"tv":0.0,"id":60443},{"batb":[[0,1.65,13.2],[1,1.64,10],[2,1.5,20]],"ltp":0.0,"tv":0.0,"id":31376}]}]}
{"op":"mcm","clk":"11926300076","pt":1724221104705,"mc":[{"id":"1.231812839","rc":[{"batb":[[1,1.5,20],[2,1.1,200]],"ltp":0.0,"tv":0.0,"id":31376}]}]}
{"op":"mcm","clk":"11926300079","pt":1724221104808,"mc":[{"id":"1.231812839","rc":[{"batb":[[0,1.66,10],[1,1.65,13.2],[2,1.5,20]],"ltp":0.0,"tv":0.0,"id":31376}]}]}
{"op":"mcm","clk":"11926354344","pt":1724222460295,"mc":[{"id":"1.231812839","rc":[{"batb":[[0,2,30],[1,1.3,20],[2,1.1,200]],"ltp":0.0,"tv":0.0,"id":60443},{"batb":[[1,1.5,20],[2,1.1,200]],"ltp":0.0,"tv":0.0,"id":31376}]}]}
{"op":"mcm","clk":"11926357175","pt":1724222530462,"mc":[{"id":"1.231812839","rc":[{"batb":[[0,2.02,8.41],[1,2,30],[2,1.3,20]],"ltp":0.0,"tv":0.0,"id":60443},{"batb":[[0,1.67,12.81],[1,1.66,10],[2,1.5,20]],"ltp":0.0,"tv":0.0,"id":31376}]}]}
{"op":"mcm","clk":"11926441372","pt":1724224331105,"mc":[{"id":"1.231812839","rc":[{"batb":[[0,2,30],[1,1.3,20],[2,1.1,200]],"ltp":0.0,"tv":0.0,"id":60443},{"batb":[[0,1.66,10],[1,1.5,20],[2,1.1,200]],"ltp":0.0,"tv":0.0,"id":31376}]}]}
{"op":"mcm","clk":"11926443977","pt":1724224397961,"mc":[{"id":"1.231812839","rc":[{"batb":[[0,2.02,8.42],[1,2,30],[2,1.3,20]],"ltp":0.0,"tv":0.0,"id":60443},{"batb":[[0,1.67,12.81],[1,1.66,10],[2,1.5,20]],"ltp":0.0,"tv":0.0,"id":31376}]}]}
{"op":"mcm","clk":"11926510637","pt":1724226198488,"mc":[{"id":"1.231812839","rc":[{"batb":[[0,2,30],[1,1.3,20],[2,1.1,200]],"ltp":0.0,"tv":0.0,"id":60443},{"batb":[[0,1.66,10],[1,1.5,20],[2,1.1,200]],"ltp":0.0,"tv":0.0,"id":31376}]}]}
{"op":"mcm","clk":"11926513227","pt":1724226258177,"mc":[{"id":"1.231812839","rc":[{"batb":[[0,2.02,8.42],[1,2,30],[2,1.3,20]],"ltp":0.0,"tv":0.0,"id":60443},{"batb":[[0,1.67,12.81],[1,1.66,10],[2,1.5,20]],"ltp":0.0,"tv":0.0,"id":31376}]}]}
{"op":"mcm","clk":"11926608106","pt":1724228058531,"mc":[{"id":"1.231812839","rc":[{"batb":[[0,2,30],[1,1.3,20],[2,1.1,200]],"ltp":0.0,"tv":0.0,"id":60443},{"batb":[[0,1.66,10],[1,1.5,20],[2,1.1,200]],"ltp":0.0,"tv":0.0,"id":31376}]}]}
{"op":"mcm","clk":"11926611393","pt":1724228124229,"mc":[{"id":"1.231812839","rc":[{"batb":[[0,2.02,8.41],[1,2,30],[2,1.3,20]],"ltp":0.0,"tv":0.0,"id":60443},{"batb":[[0,1.67,12.81],[1,1.66,10],[2,1.5,20]],"ltp":0.0,"tv":0.0,"id":31376}]}]}
{"op":"mcm","clk":"11926703457","pt":1724229924712,"mc":[{"id":"1.231812839","rc":[{"batb":[[0,2,30],[1,1.3,20],[2,1.1,200]],"ltp":0.0,"tv":0.0,"id":60443},{"batb":[[0,1.66,10],[1,1.5,20],[2,1.1,200]],"ltp":0.0,"tv":0.0,"id":31376}]}]}
{"op":"mcm","clk":"11926710162","pt":1724230044781,"mc":[{"id":"1.231812839","rc":[{"batb":[[0,2.02,8.41],[1,2,30],[2,1.3,20]],"ltp":0.0,"tv":0.0,"id":60443},{"batb":[[0,1.67,12.81],[1,1.66,10],[2,1.5,20]],"ltp":0.0,"tv":0.0,"id":31376}]}]}
{"op":"mcm","clk":"11926805311","pt":1724231845231,"mc":[{"id":"1.231812839","rc":[{"batb":[[0,2,30],[1,1.3,20],[2,1.1,200]],"ltp":0.0,"tv":0.0,"id":60443},{"batb":[[0,1.66,10],[1,1.5,20],[2,1.1,200]],"ltp":0.0,"tv":0.0,"id":31376}]}]}
{"op":"mcm","clk":"11926808274","pt":1724231892749,"mc":[{"id":"1.231812839","rc":[{"batb":[[0,2.02,8.42],[1,2,30],[2,1.3,20]],"ltp":0.0,"tv":0.0,"id":60443},{"batb":[[0,1.67,12.82],[1,1.66,10],[2,1.5,20]],"ltp":0.0,"tv":0.0,"id":31376}]}]}
{"op":"mcm","clk":"11926875556","pt":1724232952401,"mc":[{"id":"1.231812839","rc":[{"batb":[[1,1.04,1.53],[2,1.03,200]],"ltp":1.5,"tv":6.1,"id":3961},{"batl":[[1,180,1.03],[2,870,0.34]],"ltp":0.0,"tv":0.0,"id":60443}]}]}
{"op":"mcm","clk":"11926876582","pt":1724232966712,"mc":[{"id":"1.231812839","rc":[{"batb":[[1,1.04,64.03],[2,1.03,283.33]],"ltp":1.5,"tv":6.1,"id":3961}]}]}
{"op":"mcm","clk":"11926876633","pt":1724232967325,"mc":[{"id":"1.231812839","rc":[{"batb":[[1,1.08,31.25],[2,1.07,35.71]],"ltp":1.5,"tv":6.1,"id":3961}]}]}
{"op":"mcm","clk":"11926876947","pt":1724232971528,"mc":[{"id":"1.231812839","rc":[{"batl":[[1,95,5.85],[2,990,5.51]],"ltp":0.0,"tv":0.0,"id":60443}]}]}
{"op":"mcm","clk":"11926936120","pt":1724233693742,"mc":[{"id":"1.231812839","rc":[{"batb":[[0,2,30],[1,1.3,20],[2,1.08,31.25]],"ltp":0.0,"tv":0.0,"id":60443},{"batb":[[0,1.66,10],[1,1.5,20],[2,1.08,31.25]],"ltp":0.0,"tv":0.0,"id":31376}]}]}
{"op":"mcm","clk":"11926939076","pt":1724233738077,"mc":[{"id":"1.231812839","rc":[{"batb":[[0,2.02,8.42],[1,2,30],[2,1.3,20]],"ltp":0.0,"tv":0.0,"id":60443},{"batb":[[0,1.67,12.82],[1,1.66,10],[2,1.5,20]],"ltp":0.0,"tv":0.0,"id":31376}]}]}
{"op":"mcm","clk":"11927095571","pt":1724235538747,"mc":[{"id":"1.231812839","rc":[{"trd":[[1.16,2]],"batl":[[2,90,1.02]],"ltp":1.5,"tv":6.1,"id":3961},{"batb":[[0,2,30],[1,1.3,20],[2,1.08,31.25]],"ltp":0.0,"tv":0.0,"id":60443},{"batb":[[0,1.66,10],[1,1.5,20],[2,1.08,31.25]],"batl":[[2,90,1.02]],"ltp":0.0,"tv":0.0,"id":31376}],"tv":6.1}]}
{"op":"mcm","clk":"11927098863","pt":1724235572226,"mc":[{"id":"1.231812839","rc":[{"batb":[[0,2.02,8.41],[1,2,30],[2,1.3,20]],"ltp":0.0,"tv":0.0,"id":60443},{"batb":[[0,1.67,12.8],[1,1.66,10],[2,1.5,20]],"ltp":0.0,"tv":0.0,"id":31376}]}]}
{"op":"mcm","clk":"11927274739","pt":1724237372626,"mc":[{"id":"1.231812839","rc":[{"batb":[[0,2,30],[1,1.3,20],[2,1.08,31.25]],"ltp":0.0,"tv":0.0,"id":60443},{"batb":[[0,1.66,10],[1,1.5,20],[2,1.08,31.25]],"ltp":0.0,"tv":0.0,"id":31376}]}]}
{"op":"mcm","clk":"11927277383","pt":1724237400030,"mc":[{"id":"1.231812839","rc":[{"batb":[[0,2.02,8.41],[1,2,30],[2,1.3,20]],"ltp":0.0,"tv":0.0,"id":60443},{"batb":[[0,1.67,12.8],[1,1.66,10],[2,1.5,20]],"ltp":0.0,"tv":0.0,"id":31376}]}]}
{"op":"mcm","clk":"11927407222","pt":1724238775087,"mc":[{"id":"1.231812839","rc":[{"batb":[[0,1.5,20.84]],"ltp":1.5,"tv":6.1,"id":3961},{"batb":[[0,2.02,8.41]],"ltp":0.0,"tv":0.0,"id":60443},{"batb":[[0,1.67,12.8]],"ltp":0.0,"tv":0.0,"id":31376}]}]}
{"op":"mcm","clk":"11927452942","pt":1724239200595,"mc":[{"id":"1.231812839","rc":[{"batb":[[0,2,30],[1,1.3,20],[2,1.08,31.25]],"ltp":0.0,"tv":0.0,"id":60443},{"batb":[[0,1.66,10],[1,1.5,20],[2,1.08,31.25]],"ltp":0.0,"tv":0.0,"id":31376}]}]}
{"op":"mcm","clk":"11927456132","pt":1724239231142,"mc":[{"id":"1.231812839","rc":[{"batb":[[0,2.02,8.41],[1,2,30],[2,1.3,20]],"ltp":0.0,"tv":0.0,"id":60443},{"batb":[[0,1.67,12.8],[1,1.66,10],[2,1.5,20]],"ltp":0.0,"tv":0.0,"id":31376}]}]}
{"op":"mcm","clk":"11927622753","pt":1724241031452,"mc":[{"id":"1.231812839","rc":[{"batb":[[0,2,30],[1,1.3,20],[2,1.08,31.25]],"ltp":0.0,"tv":0.0,"id":60443},{"batb":[[0,1.66,10],[1,1.5,20],[2,1.08,31.25]],"ltp":0.0,"tv":0.0,"id":31376}]}]}
{"op":"mcm","clk":"11927630240","pt":1724241134080,"mc":[{"id":"1.231812839","rc":[{"batb":[[0,2.02,8.41],[1,2,30],[2,1.3,20]],"ltp":0.0,"tv":0.0,"id":60443},{"batb":[[0,1.67,12.8],[1,1.66,10],[2,1.5,20]],"ltp":0.0,"tv":0.0,"id":31376}]}]}
{"op":"mcm","clk":"11927678325","pt":1724241781065,"mc":[{"id":"1.231812839","rc":[{"batb":[[0,2.04,30],[1,2.02,8.41]],"ltp":0.0,"tv":0.0,"id":60443}]}]}
{"op":"mcm","clk":"11927678834","pt":1724241788161,"mc":[{"id":"1.231812839","rc":[{"batl":[[0,9.4,10],[1,90,1.02],[2,95,5]],"ltp":1.5,"tv":6.1,"id":3961},{"batl":[[0,9.8,9],[1,90,1.02],[2,95,5]],"ltp":0.0,"tv":0.0,"id":31376}]}]}
{"op":"mcm","clk":"11927757813","pt":1724242934671,"mc":[{"id":"1.231812839","rc":[{"batb":[[1,1.3,20],[2,1.08,31.25]],"ltp":0.0,"tv":0.0,"id":60443}]}]}
{"op":"mcm","clk":"11927757824","pt":1724242934773,"mc":[{"id":"1.231812839","rc":[{"batb":[[0,1.66,10],[1,1.5,20],[2,1.08,31.25]],"ltp":0.0,"tv":0.0,"id":31376}]}]}
{"op":"mcm","clk":"11927763970","pt":1724243014276,"mc":[{"id":"1.231812839","rc":[{"batb":[[0,2.06,8.09],[1,2.04,30],[2,1.3,20]],"ltp":0.0,"tv":0.0,"id":60443},{"batb":[[0,1.67,12.8],[1,1.66,10],[2,1.5,20]],"ltp":0.0,"tv":0.0,"id":31376}]}]}
{"op":"mcm","clk":"11927815705","pt":1724243837189,"mc":[{"id":"1.231812839","rc":[{"batb":[[0,1.78,5.11],[1,1.5,20.84],[2,1.08,31.25]],"ltp":1.5,"tv":6.1,"id":3961}]}]}
{"op":"mcm","clk":"11927882415","pt":1724244814548,"mc":[{"id":"1.231812839","rc":[{"batb":[[0,1.66,10],[1,1.5,20],[2,1.08,31.25]],"ltp":0.0,"tv":0.0,"id":31376}]}]}
{"op":"mcm","clk":"11927882430","pt":1724244814856,"mc":[{"id":"1.231812839","rc":[{"batb":[[0,2.04,30],[1,1.3,20],[2,1.08,31.25]],"ltp":0.0,"tv":0.0,"id":60443}]}]}
{"op":"mcm","clk":"11927886240","pt":1724244870731,"mc":[{"id":"1.231812839","rc":[{"batb":[[0,2.06,8.09],[1,2.04,30],[2,1.3,20]],"ltp":0.0,"tv":0.0,"id":60443},{"batb":[[0,1.67,12.8],[1,1.66,10],[2,1.5,20]],"ltp":0.0,"tv":0.0,"id":31376}]}]}
{"op":"mcm","clk":"11928010282","pt":1724246671384,"mc":[{"id":"1.231812839","rc":[{"batb":[[0,2.04,30],[1,1.3,20],[2,1.08,31.25]],"ltp":0.0,"tv":0.0,"id":60443},{"batb":[[0,1.66,10],[1,1.5,20],[2,1.08,31.25]],"ltp":0.0,"tv":0.0,"id":31376}]}]}
{"op":"mcm","clk":"11928013056","pt":1724246714608,"mc":[{"id":"1.231812839","rc":[{"batb":[[0,2.06,8.09],[1,2.04,30],[2,1.3,20]],"ltp":0.0,"tv":0.0,"id":60443},{"batb":[[0,1.67,12.79],[1,1.66,10],[2,1.5,20]],"ltp":0.0,"tv":0.0,"id":31376}]}]}
{"op":"mcm","clk":"11928129613","pt":1724248515390,"mc":[{"id":"1.231812839","rc":[{"batb":[[0,2.04,30],[1,1.3,20],[2,1.08,31.25]],"ltp":0.0,"tv":0.0,"id":60443},{"batb":[[0,1.66,10],[1,1.5,20],[2,1.08,31.25]],"ltp":0.0,"tv":0.0,"id":31376}]}]}
{"op":"mcm","clk":"11928130913","pt":1724248545348,"mc":[{"id":"1.231812839","rc":[{"batb":[[0,2.06,8.09],[1,2.04,30],[2,1.3,20]],"ltp":0.0,"tv":0.0,"id":60443},{"batb":[[0,1.67,12.79],[1,1.66,10],[2,1.5,20]],"ltp":0.0,"tv":0.0,"id":31376}]}]}
{"op":"mcm","clk":"11928202502","pt":1724249575079,"mc":[{"id":"1.231812839","rc":[{"trd":[[1.16,2]],"batl":[[1,90,1.02]],"ltp":1.5,"tv":6.09,"id":3961},{"batb":[[0,2.06,8.08]],"ltp":0.0,"tv":0.0,"id":60443},{"batb":[[0,1.67,12.78]],"batl":[[1,90,1.02]],"ltp":0.0,"tv":0.0,"id":31376}],"tv":6.09}]}
{"op":"mcm","clk":"11928251211","pt":1724250346221,"mc":[{"id":"1.231812839","rc":[{"batb":[[0,2.04,30],[1,1.3,20],[2,1.08,31.25]],"ltp":0.0,"tv":0.0,"id":60443},{"batb":[[0,1.66,10],[1,1.5,20],[2,1.08,31.25]],"ltp":0.0,"tv":0.0,"id":31376}]}]}
{"op":"mcm","clk":"11928252417","pt":1724250363512,"mc":[{"id":"1.231812839","rc":[{"batb":[[0,2.06,8.08],[1,2.04,30],[2,1.3,20]],"ltp":0.0,"tv":0.0,"id":60443},{"batb":[[0,1.67,12.78],[1,1.66,10],[2,1.5,20]],"ltp":0.0,"tv":0.0,"id":31376}]}]}
{"op":"mcm","clk":"11928350964","pt":1724252077594,"mc":[{"id":"1.231812839","rc":[{"batl":[[0,9.4,10.12]],"ltp":1.5,"tv":6.09,"id":3961}]}]}
{"op":"mcm","clk":"11928351529","pt":1724252088080,"mc":[{"id":"1.231812839","rc":[{"batl":[[0,9.4,10]],"ltp":1.5,"tv":6.09,"id":3961}]}]}
{"op":"mcm","clk":"11928355761","pt":1724252164297,"mc":[{"id":"1.231812839","rc":[{"batb":[[0,2.04,30],[1,1.3,20],[2,1.08,31.25]],"ltp":0.0,"tv":0.0,"id":60443},{"batb":[[0,1.66,10],[1,1.5,20],[2,1.08,31.25]],"ltp":0.0,"tv":0.0,"id":31376}]}]}
{"op":"mcm","clk":"11928363289","pt":1724252294636,"mc":[{"id":"1.231812839","rc":[{"batb":[[0,2.06,8.08],[1,2.04,30],[2,1.3,20]],"ltp":0.0,"tv":0.0,"id":60443},{"batb":[[0,1.67,12.78],[1,1.66,10],[2,1.5,20]],"ltp":0.0,"tv":0.0,"id":31376}]}]}
{"op":"mcm","clk":"11928538976","pt":1724254095238,"mc":[{"id":"1.231812839","rc":[{"batb":[[0,2.04,30],[1,1.3,20],[2,1.08,31.25]],"ltp":0.0,"tv":0.0,"id":60443},{"batb":[[0,1.66,10],[1,1.5,20],[2,1.08,31.25]],"ltp":0.0,"tv":0.0,"id":31376}]}]}
{"op":"mcm","clk":"11928555378","pt":1724254262488,"mc":[{"id":"1.231812839","rc":[{"batb":[[0,2.06,8.08],[1,2.04,30],[2,1.3,20]],"ltp":0.0,"tv":0.0,"id":60443},{"batb":[[0,1.67,12.78],[1,1.66,10],[2,1.5,20]],"ltp":0.0,"tv":0.0,"id":31376}]}]}
{"op":"mcm","clk":"11928788529","pt":1724256063315,"mc":[{"id":"1.231812839","rc":[{"batb":[[1,1.5,20.84]],"ltp":1.5,"tv":6.09,"id":3961},{"batb":[[0,2.04,30],[1,1.3,20],[2,1.08,31.25]],"ltp":0.0,"tv":0.0,"id":60443},{"batb":[[0,1.66,10],[1,1.5,20],[2,1.08,31.25]],"ltp":0.0,"tv":0.0,"id":31376}]}]}
{"op":"mcm","clk":"11928811026","pt":1724256226830,"mc":[{"id":"1.231812839","rc":[{"batb":[[0,2.06,8.08],[1,2.04,30],[2,1.3,20]],"ltp":0.0,"tv":0.0,"id":60443},{"batb":[[0,1.67,12.78],[1,1.66,10],[2,1.5,20]],"ltp":0.0,"tv":0.0,"id":31376}]}]}
{"op":"mcm","clk":"11929065844","pt":1724258028106,"mc":[{"id":"1.231812839","rc":[{"batb":[[0,2.04,30],[1,1.3,20],[2,1.08,31.25]],"ltp":0.0,"tv":0.0,"id":60443},{"batb":[[0,1.66,10],[1,1.5,20],[2,1.08,31.25]],"ltp":0.0,"tv":0.0,"id":31376}]}]}
{"op":"mcm","clk":"11929089532","pt":1724258172125,"mc":[{"id":"1.231812839","rc":[{"batb":[[0,2.06,8.08],[1,2.04,30],[2,1.3,20]],"ltp":0.0,"tv":0.0,"id":60443},{"batb":[[0,1.67,12.78],[1,1.66,10],[2,1.5,20]],"ltp":0.0,"tv":0.0,"id":31376}]}]}
{"op":"mcm","clk":"11929379058","pt":1724259967533,"mc":[{"id":"1.231812839","rc":[{"batb":[[1,1.5,19.95]],"ltp":1.5,"tv":6.09,"id":3961},{"batb":[[0,2.06,8.07]],"ltp":0.0,"tv":0.0,"id":60443},{"batb":[[0,1.67,12.77]],"ltp":0.0,"tv":0.0,"id":31376}]}]}
{"op":"mcm","clk":"11929380920","pt":1724259977618,"mc":[{"id":"1.231812839","rc":[{"batb":[[0,2.04,30],[1,1.3,20],[2,1.08,31.25]],"ltp":0.0,"tv":0.0,"id":60443},{"batb":[[0,1.66,10],[1,1.5,20],[2,1.08,31.25]],"ltp":0.0,"tv":0.0,"id":31376}]}]}
{"op":"mcm","clk":"11929408185","pt":1724260129199,"mc":[{"id":"1.231812839","rc":[{"batb":[[0,2.06,8.07],[1,2.04,30],[2,1.3,20]],"ltp":0.0,"tv":0.0,"id":60443},{"batb":[[0,1.67,12.77],[1,1.66,10],[2,1.5,20]],"ltp":0.0,"tv":0.0,"id":31376}]}]}
{"op":"mcm","clk":"11929714611","pt":1724261929384,"mc":[{"id":"1.231812839","rc":[{"batb":[[0,1.66,10],[1,1.5,20],[2,1.08,31.25]],"ltp":0.0,"tv":0.0,"id":31376}]}]}
{"op":"mcm","clk":"11929714732","pt":1724261930075,"mc":[{"id":"1.231812839","rc":[{"batb":[[0,2.04,30],[1,1.3,20],[2,1.08,31.25]],"ltp":0.0,"tv":0.0,"id":60443}]}]}
{"op":"mcm","clk":"11929733712","pt":1724262042123,"mc":[{"id":"1.231812839","rc":[{"batb":[[0,2.06,8.07],[1,2.04,30],[2,1.3,20]],"ltp":0.0,"tv":0.0,"id":60443},{"batb":[[0,1.67,12.77],[1,1.66,10],[2,1.5,20]],"ltp":0.0,"tv":0.0,"id":31376}]}]}
{"op":"mcm","clk":"11930006967","pt":1724263842579,"mc":[{"id":"1.231812839","rc":[{"batb":[[0,2.06,8.08]],"ltp":0.0,"tv":0.0,"id":60443},{"batb":[[0,1.66,10],[1,1.5,20],[2,1.08,31.25]],"ltp":0.0,"tv":0.0,"id":31376}]}]}
{"op":"mcm","clk":"11930006997","pt":1724263842779,"mc":[{"id":"1.231812839","rc":[{"batb":[[0,2.04,30],[1,1.3,20],[2,1.08,31.25]],"ltp":0.0,"tv":0.0,"id":60443}]}]}
{"op":"mcm","clk":"11930016859","pt":1724263898333,"mc":[{"id":"1.231812839","rc":[{"batb":[[0,2.06,8.08],[1,2.04,30],[2,1.3,20]],"ltp":0.0,"tv":0.0,"id":60443},{"batb":[[0,1.67,12.78],[1,1.66,10],[2,1.5,20]],"ltp":0.0,"tv":0.0,"id":31376}]}]}
{"op":"mcm","clk":"11930096864","pt":1724264344608,"mc":[{"id":"1.231812839","rc":[{"batb":[[0,1.68,10],[1,1.67,12.78]],"ltp":0.0,"tv":0.0,"id":31376}]}]}
{"op":"mcm","clk":"11930326789","pt":1724265698967,"mc":[{"id":"1.231812839","rc":[{"batb":[[0,2.04,30],[1,1.3,20],[2,1.08,31.25]],"ltp":0.0,"tv":0.0,"id":60443},{"batb":[[1,1.5,20],[2,1.08,31.25]],"ltp":0.0,"tv":0.0,"id":31376}]}]}
{"op":"mcm","clk":"11930331233","pt":1724265725893,"mc":[{"id":"1.231812839","rc":[{"batb":[[0,2.06,8.08],[1,2.04,30],[2,1.3,20]],"ltp":0.0,"tv":0.0,"id":60443},{"batb":[[0,1.69,12.41],[1,1.68,10],[2,1.5,20]],"ltp":0.0,"tv":0.0,"id":31376}]}]}
{"op":"mcm","clk":"11930585512","pt":1724267526436,"mc":[{"id":"1.231812839","rc":[{"batb":[[0,2.04,30],[1,1.3,20],[2,1.08,31.25]],"ltp":0.0,"tv":0.0,"id":60443},{"batb":[[0,1.68,10],[1,1.5,20],[2,1.08,31.25]],"ltp":0.0,"tv":0.0,"id":31376}]}]}
{"op":"mcm","clk":"11930607997","pt":1724267696020,"mc":[{"id":"1.231812839","rc":[{"batb":[[0,2.06,8.07],[1,2.04,30],[2,1.3,20]],"ltp":0.0,"tv":0.0,"id":60443},{"batb":[[0,1.69,12.4],[1,1.68,10],[2,1.5,20]],"ltp":0.0,"tv":0.0,"id":31376}]}]}
{"op":"mcm","clk":"11930824092","pt":1724269496642,"mc":[{"id":"1.231812839","rc":[{"batb":[[0,2.04,30],[1,1.3,20],[2,1.08,31.25]],"ltp":0.0,"tv":0.0,"id":60443},{"batb":[[0,1.68,10],[1,1.5,20],[2,1.08,31.25]],"ltp":0.0,"tv":0.0,"id":31376}]}]}
{"op":"mcm","clk":"11930837800","pt":1724269623664,"mc":[{"id":"1.231812839","rc":[{"batb":[[0,2.06,8.07],[1,2.04,30],[2,1.3,20]],"ltp":0.0,"tv":0.0,"id":60443},{"batb":[[0,1.69,12.4],[1,1.68,10],[2,1.5,20]],"ltp":0.0,"tv":0.0,"id":31376}]}]}
{"op":"mcm","clk":"11931004315","pt":1724271175149,"mc":[{"id":"1.231812839","rc":[{"batb":[[0,2.06,8.08]],"ltp":0.0,"tv":0.0,"id":60443},{"batb":[[0,1.69,12.41]],"ltp":0.0,"tv":0.0,"id":31376}]}]}
{"op":"mcm","clk":"11931028012","pt":1724271424266,"mc":[{"id":"1.231812839","rc":[{"batb":[[0,2.04,30],[1,1.3,20],[2,1.08,31.25]],"ltp":0.0,"tv":0.0,"id":60443},{"batb":[[0,1.68,10],[1,1.5,20],[2,1.08,31.25]],"ltp":0.0,"tv":0.0,"id":31376}]}]}
{"op":"mcm","clk":"11931040128","pt":1724271547993,"mc":[{"id":"1.231812839","rc":[{"batb":[[0,2.06,8.08],[1,2.04,30],[2,1.3,20]],"ltp":0.0,"tv":0.0,"id":60443},{"batb":[[0,1.69,12.41],[1,1.68,10],[2,1.5,20]],"ltp":0.0,"tv":0.0,"id":31376}]}]}
{"op":"mcm","clk":"11931121383","pt":1724272460328,"mc":[{"id":"1.231812839","rc":[{"batb":[[0,1.8,62.5],[1,1.78,5.11],[2,1.5,19.95]],"ltp":1.5,"tv":6.09,"id":3961}]}]}
{"op":"mcm","clk":"11931122071","pt":1724272469919,"mc":[{"id":"1.231812839","rc":[{"batb":[[0,1.8,62.5],[1,1.69,12.41],[2,1.68,10]],"ltp":0.0,"tv":0.0,"id":31376}]}]}
{"op":"mcm","clk":"11931198495","pt":1724273348672,"mc":[{"id":"1.231812839","rc":[{"batb":[[0,2.04,30],[1,1.3,20],[2,1.08,31.25]],"ltp":0.0,"tv":0.0,"id":60443},{"batb":[[1,1.68,10],[2,1.5,20]],"ltp":0.0,"tv":0.0,"id":31376}]}]}
{"op":"mcm","clk":"11931202744","pt":1724273407982,"mc":[{"id":"1.231812839","rc":[{"batb":[[0,2.06,8.08],[1,2.04,30],[2,1.3,20]],"ltp":0.0,"tv":0.0,"id":60443},{"batb":[[0,1.81,10.57],[1,1.8,62.5],[2,1.68,10]],"ltp":0.0,"tv":0.0,"id":31376}]}]}
{"op":"mcm","clk":"11931345249","pt":1724275208464,"mc":[{"id":"1.231812839","rc":[{"batb":[[0,2.04,30],[1,1.3,20],[2,1.08,31.25]],"ltp":0.0,"tv":0.0,"id":60443},{"batb":[[0,1.8,62.5],[1,1.68,10],[2,1.5,20]],"ltp":0.0,"tv":0.0,"id":31376}]}]}
{"op":"mcm","clk":"11931346744","pt":1724275227470,"mc":[{"id":"1.231812839","rc":[{"batb":[[0,2.06,8.07],[1,2.04,30],[2,1.3,20]],"ltp":0.0,"tv":0.0,"id":60443},{"batb":[[0,1.81,10.57],[1,1.8,62.5],[2,1.68,10]],"ltp":0.0,"tv":0.0,"id":31376}]}]}
{"op":"mcm","clk":"11931489499","pt":1724277027571,"mc":[{"id":"1.231812839","rc":[{"batb":[[0,2.04,30],[1,1.3,20],[2,1.08,31.25]],"ltp":0.0,"tv":0.0,"id":60443}]}]}
{"op":"mcm","clk":"11931489511","pt":1724277027772,"mc":[{"id":"1.231812839","rc":[{"batb":[[0,1.8,62.5],[1,1.68,10],[2,1.5,20]],"ltp":0.0,"tv":0.0,"id":31376}]}]}
{"op":"mcm","clk":"11931502420","pt":1724277204197,"mc":[{"id":"1.231812839","rc":[{"batb":[[0,2.06,8.07],[1,2.04,30],[2,1.3,20]],"ltp":0.0,"tv":0.0,"id":60443},{"batb":[[0,1.81,10.57],[1,1.8,62.5],[2,1.68,10]],"ltp":0.0,"tv":0.0,"id":31376}]}]}
{"op":"mcm","clk":"11931619192","pt":1724279004624,"mc":[{"id":"1.231812839","rc":[{"batb":[[0,2.06,8.07]],"ltp":0.0,"tv":0.0,"id":60443},{"batb":[[0,1.8,62.5],[1,1.68,10],[2,1.5,20]],"ltp":0.0,"tv":0.0,"id":31376}]}]}
{"op":"mcm","clk":"11931619209","pt":1724279004834,"mc":[{"id":"1.231812839","rc":[{"batb":[[0,2.04,30],[1,1.3,20],[2,1.08,31.25]],"ltp":0.0,"tv":0.0,"id":60443}]}]}
{"op":"mcm","clk":"11931626736","pt":1724279141146,"mc":[{"id":"1.231812839","rc":[{"batb":[[0,2.06,8.07],[1,2.04,30],[2,1.3,20]],"ltp":0.0,"tv":0.0,"id":60443},{"batb":[[0,1.81,10.56],[1,1.8,62.5],[2,1.68,10]],"ltp":0.0,"tv":0.0,"id":31376}]}]}
{"op":"mcm","clk":"11931736990","pt":1724280941679,"mc":[{"id":"1.231812839","rc":[{"batb":[[0,2.04,30],[1,1.3,20],[2,1.08,31.25]],"ltp":0.0,"tv":0.0,"id":60443},{"batb":[[0,1.8,62.5],[1,1.68,10],[2,1.5,20]],"ltp":0.0,"tv":0.0,"id":31376}]}]}
{"op":"mcm","clk":"11931743756","pt":1724281058180,"mc":[{"id":"1.231812839","rc":[{"batb":[[0,2.06,8.07],[1,2.04,30],[2,1.3,20]],"ltp":0.0,"tv":0.0,"id":60443},{"batb":[[0,1.81,10.56],[1,1.8,62.5],[2,1.68,10]],"ltp":0.0,"tv":0.0,"id":31376}]}]}
{"op":"mcm","clk":"11931818896","pt":1724281975173,"mc":[{"id":"1.231812839","rc":[{"batb":[[0,2.06,8.08]],"ltp":0.0,"tv":0.0,"id":60443},{"batb":[[0,1.81,10.57]],"ltp":0.0,"tv":0.0,"id":31376}]}]}
{"op":"mcm","clk":"11931893424","pt":1724282858618,"mc":[{"id":"1.231812839","rc":[{"batb":[[0,2.04,30],[1,1.3,20],[2,1.08,31.25]],"ltp":0.0,"tv":0.0,"id":60443}]}]}
{"op":"mcm","clk":"11931893445","pt":1724282858823,"mc":[{"id":"1.231812839","rc":[{"batb":[[0,1.8,62.5],[1,1.68,10],[2,1.5,20]],"ltp":0.0,"tv":0.0,"id":31376}]}]}
{"op":"mcm","clk":"11931901348","pt":1724282951773,"mc":[{"id":"1.231812839","rc":[{"batb":[[0,2.06,8.08],[1,2.04,30],[2,1.3,20]],"ltp":0.0,"tv":0.0,"id":60443},{"batb":[[0,1.81,10.57],[1,1.8,62.5],[2,1.68,10]],"ltp":0.0,"tv":0.0,"id":31376}]}]}
{"op":"mcm","clk":"11932051694","pt":1724284752272,"mc":[{"id":"1.231812839","rc":[{"batb":[[0,2.04,30],[1,1.3,20],[2,1.08,31.25]],"ltp":0.0,"tv":0.0,"id":60443},{"batb":[[0,1.8,62.5],[1,1.68,10],[2,1.5,20]],"ltp":0.0,"tv":0.0,"id":31376}]}]}
{"op":"mcm","clk":"11932057263","pt":1724284827342,"mc":[{"id":"1.231812839","rc":[{"batb":[[0,2.06,8.08],[1,2.04,30],[2,1.3,20]],"ltp":0.0,"tv":0.0,"id":60443},{"batb":[[0,1.81,10.57],[1,1.8,62.5],[2,1.68,10]],"ltp":0.0,"tv":0.0,"id":31376}]}]}
{"op":"mcm","clk":"11932195449","pt":1724286627574,"mc":[{"id":"1.231812839","rc":[{"batb":[[0,2.04,30],[1,1.3,20],[2,1.08,31.25]],"ltp":0.0,"tv":0.0,"id":60443}]}]}
{"op":"mcm","clk":"11932195470","pt":1724286627775,"mc":[{"id":"1.231812839","rc":[{"batb":[[0,1.8,62.5],[1,1.68,10],[2,1.5,20]],"ltp":0.0,"tv":0.0,"id":31376}]}]}
{"op":"mcm","clk":"11932199269","pt":1724286678190,"mc":[{"id":"1.231812839","rc":[{"batb":[[0,2.06,8.08],[1,2.04,30],[2,1.3,20]],"ltp":0.0,"tv":0.0,"id":60443},{"batb":[[0,1.81,10.57],[1,1.8,62.5],[2,1.68,10]],"ltp":0.0,"tv":0.0,"id":31376}]}]}
{"op":"mcm","clk":"11932354291","pt":1724288478729,"mc":[{"id":"1.231812839","rc":[{"batb":[[0,2.06,8.07]],"ltp":0.0,"tv":0.0,"id":60443},{"batb":[[0,1.8,62.5],[1,1.68,10],[2,1.5,20]],"ltp":0.0,"tv":0.0,"id":31376}]}]}
{"op":"mcm","clk":"11932354311","pt":1724288479039,"mc":[{"id":"1.231812839","rc":[{"batb":[[0,2.04,30],[1,1.3,20],[2,1.08,31.25]],"ltp":0.0,"tv":0.0,"id":60443}]}]}
{"op":"mcm","clk":"11932356452","pt":1724288511094,"mc":[{"id":"1.231812839","rc":[{"batb":[[0,2.06,8.07],[1,2.04,30],[2,1.3,20]],"ltp":0.0,"tv":0.0,"id":60443},{"batb":[[0,1.81,10.56],[1,1.8,62.5],[2,1.68,10]],"ltp":0.0,"tv":0.0,"id":31376}]}]}
{"op":"mcm","clk":"11932477221","pt":1724290311578,"mc":[{"id":"1.231812839","rc":[{"batb":[[0,2.04,30],[1,1.3,20],[2,1.08,31.25]],"ltp":0.0,"tv":0.0,"id":60443},{"batb":[[0,1.8,62.5],[1,1.68,10],[2,1.5,20]],"ltp":0.0,"tv":0.0,"id":31376}]}]}
{"op":"mcm","clk":"11932477855","pt":1724290322466,"mc":[{"id":"1.231812839","rc":[{"batb":[[0,2.06,8.07],[1,2.04,30],[2,1.3,20]],"ltp":0.0,"tv":0.0,"id":60443},{"batb":[[0,1.81,10.56],[1,1.8,62.5],[2,1.68,10]],"ltp":0.0,"tv":0.0,"id":31376}]}]}
{"op":"mcm","clk":"11932587836","pt":1724292123083,"mc":[{"id":"1.231812839","rc":[{"batb":[[0,2.04,30],[1,1.3,20],[2,1.08,31.25]],"ltp":0.0,"tv":0.0,"id":60443},{"batb":[[0,1.8,62.5],[1,1.68,10],[2,1.5,20]],"ltp":0.0,"tv":0.0,"id":31376}]}]}
{"op":"mcm","clk":"11932597893","pt":1724292280459,"mc":[{"id":"1.231812839","rc":[{"batb":[[0,2.06,8.07],[1,2.04,30],[2,1.3,20]],"ltp":0.0,"tv":0.0,"id":60443},{"batb":[[0,1.81,10.56],[1,1.8,62.5],[2,1.68,10]],"ltp":0.0,"tv":0.0,"id":31376}]}]}
{"op":"mcm","clk":"11932715133","pt":1724294080654,"mc":[{"id":"1.231812839","rc":[{"batb":[[0,1.8,62.5],[1,1.68,10],[2,1.5,20]],"ltp":0.0,"tv":0.0,"id":31376}]}]}
{"op":"mcm","clk":"11932715139","pt":1724294080860,"mc":[{"id":"1.231812839","rc":[{"batb":[[0,2.04,30],[1,1.3,20],[2,1.08,31.25]],"ltp":0.0,"tv":0.0,"id":60443}]}]}
{"op":"mcm","clk":"11932721008","pt":1724294215278,"mc":[{"id":"1.231812839","rc":[{"batb":[[0,2.06,8.07],[1,2.04,30],[2,1.3,20]],"ltp":0.0,"tv":0.0,"id":60443},{"batb":[[0,1.81,10.56],[1,1.8,62.5],[2,1.68,10]],"ltp":0.0,"tv":0.0,"id":31376}]}]}
{"op":"mcm","clk":"11932812134","pt":1724296015573,"mc":[{"id":"1.231812839","rc":[{"batb":[[0,1.8,62.5],[1,1.68,10],[2,1.5,20]],"ltp":0.0,"tv":0.0,"id":31376}]}]}
{"op":"mcm","clk":"11932812144","pt":1724296015777,"mc":[{"id":"1.231812839","rc":[{"batb":[[0,2.04,30],[1,1.3,20],[2,1.08,31.25]],"ltp":0.0,"tv":0.0,"id":60443}]}]}
{"op":"mcm","clk":"11932816990","pt":1724296125279,"mc":[{"id":"1.231812839","rc":[{"batb":[[0,2.06,8.07],[1,2.04,30],[2,1.3,20]],"ltp":0.0,"tv":0.0,"id":60443},{"batb":[[0,1.81,10.56],[1,1.8,62.5],[2,1.68,10]],"ltp":0.0,"tv":0.0,"id":31376}]}]}
{"op":"mcm","clk":"11932910995","pt":1724297925759,"mc":[{"id":"1.231812839","rc":[{"batb":[[0,1.8,62.5],[1,1.68,10],[2,1.5,20]],"ltp":0.0,"tv":0.0,"id":31376}]}]}
{"op":"mcm","clk":"11932911000","pt":1724297925862,"mc":[{"id":"1.231812839","rc":[{"batb":[[0,2.04,30],[1,1.3,20],[2,1.08,31.25]],"ltp":0.0,"tv":0.0,"id":60443}]}]}
{"op":"mcm","clk":"11932916631","pt":1724298023678,"mc":[{"id":"1.231812839","rc":[{"batb":[[0,2.06,8.07],[1,2.04,30],[2,1.3,20]],"ltp":0.0,"tv":0.0,"id":60443},{"batb":[[0,1.81,10.56],[1,1.8,62.5],[2,1.68,10]],"ltp":0.0,"tv":0.0,"id":31376}]}]}
{"op":"mcm","clk":"11933023104","pt":1724299824479,"mc":[{"id":"1.231812839","rc":[{"batb":[[0,2.04,30],[1,1.3,20],[2,1.08,31.25]],"ltp":0.0,"tv":0.0,"id":60443},{"batb":[[0,1.8,62.5],[1,1.68,10],[2,1.5,20]],"ltp":0.0,"tv":0.0,"id":31376}]}]}
{"op":"mcm","clk":"11933028446","pt":1724299911874,"mc":[{"id":"1.231812839","rc":[{"batb":[[0,2.06,8.07],[1,2.04,30],[2,1.3,20]],"ltp":0.0,"tv":0.0,"id":60443},{"batb":[[0,1.81,10.57],[1,1.8,62.5],[2,1.68,10]],"ltp":0.0,"tv":0.0,"id":31376}]}]}
{"op":"mcm","clk":"11933119775","pt":1724301712631,"mc":[{"id":"1.231812839","rc":[{"batb":[[0,2.04,30],[1,1.3,20],[2,1.08,31.25]],"ltp":0.0,"tv":0.0,"id":60443},{"batb":[[0,1.8,62.5],[1,1.68,10],[2,1.5,20]],"ltp":0.0,"tv":0.0,"id":31376}]}]}
{"op":"mcm","clk":"11933123637","pt":1724301786827,"mc":[{"id":"1.231812839","rc":[{"batb":[[0,2.06,8.07],[1,2.04,30],[2,1.3,20]],"ltp":0.0,"tv":0.0,"id":60443},{"batb":[[0,1.81,10.57],[1,1.8,62.5],[2,1.68,10]],"ltp":0.0,"tv":0.0,"id":31376}]}]}
{"op":"mcm","clk":"11933235042","pt":1724303575150,"mc":[{"id":"1.231812839","rc":[{"batb":[[0,2.06,8.07]],"ltp":0.0,"tv":0.0,"id":60443},{"batb":[[0,1.81,10.57]],"ltp":0.0,"tv":0.0,"id":31376}]}]}
{"op":"mcm","clk":"11933236047","pt":1724303587486,"mc":[{"id":"1.231812839","rc":[{"batb":[[0,2.04,30],[1,1.3,20],[2,1.08,31.25]],"ltp":0.0,"tv":0.0,"id":60443},{"batb":[[0,1.8,62.5],[1,1.68,10],[2,1.5,20]],"ltp":0.0,"tv":0.0,"id":31376}]}]}
{"op":"mcm","clk":"11933238938","pt":1724303663126,"mc":[{"id":"1.231812839","rc":[{"batb":[[0,2.06,8.07],[1,2.04,30],[2,1.3,20]],"ltp":0.0,"tv":0.0,"id":60443},{"batb":[[0,1.81,10.57],[1,1.8,62.5],[2,1.68,10]],"ltp":0.0,"tv":0.0,"id":31376}]}]}
{"op":"mcm","clk":"11933329797","pt":1724305463686,"mc":[{"id":"1.231812839","rc":[{"batb":[[0,2.04,30],[1,1.3,20],[2,1.08,31.25]],"ltp":0.0,"tv":0.0,"id":60443},{"batb":[[0,1.8,62.5],[1,1.68,10],[2,1.5,20]],"ltp":0.0,"tv":0.0,"id":31376}]}]}
{"op":"mcm","clk":"11933335939","pt":1724305606503,"mc":[{"id":"1.231812839","rc":[{"batb":[[0,2.06,8.07],[1,2.04,30],[2,1.3,20]],"ltp":0.0,"tv":0.0,"id":60443},{"batb":[[0,1.81,10.57],[1,1.8,62.5],[2,1.68,10]],"ltp":0.0,"tv":0.0,"id":31376}]}]}
{"op":"mcm","clk":"11933342670","pt":1724305751469,"mc":[{"id":"1.231812839","rc":[{"batl":[[0,16,1.13],[1,85,1.17],[2,95,5.85]],"ltp":0.0,"tv":0.0,"id":60443}]}]}
{"op":"mcm","clk":"11933342838","pt":1724305754698,"mc":[{"id":"1.231812839","rc":[{"batl":[[1,90,1.02],[2,95,5]],"ltp":0.0,"tv":0.0,"id":60443}]}]}
{"op":"mcm","clk":"11933343107","pt":1724305760303,"mc":[{"id":"1.231812839","rc":[{"batl":[[0,15.5,1.19],[1,48,1.1],[2,95,5.85]],"ltp":0.0,"tv":0.0,"id":60443}]}]}
{"op":"mcm","clk":"11933416602","pt":1724307407110,"mc":[{"id":"1.231812839","rc":[{"batb":[[0,2.04,30],[1,1.3,20],[2,1.08,31.25]],"ltp":0.0,"tv":0.0,"id":60443},{"batb":[[0,1.8,62.5],[1,1.68,10],[2,1.5,20]],"ltp":0.0,"tv":0.0,"id":31376}]}]}
{"op":"mcm","clk":"11933420622","pt":1724307534898,"mc":[{"id":"1.231812839","rc":[{"batb":[[0,2.06,8.07],[1,2.04,30],[2,1.3,20]],"ltp":0.0,"tv":0.0,"id":60443},{"batb":[[0,1.81,10.57],[1,1.8,62.5],[2,1.68,10]],"ltp":0.0,"tv":0.0,"id":31376}]}]}
{"op":"mcm","clk":"11933474304","pt":1724308789852,"mc":[{"id":"1.231812839","rc":[{"batl":[[0,9.4,10.54]],"ltp":1.5,"tv":6.09,"id":3961}]}]}
{"op":"mcm","clk":"11933474563","pt":1724308796217,"mc":[{"id":"1.231812839","rc":[{"batl":[[0,9.8,9.54]],"ltp":0.0,"tv":0.0,"id":31376}]}]}
{"op":"mcm","clk":"11933474866","pt":1724308802737,"mc":[{"id":"1.231812839","rc":[{"batl":[[0,15.5,1.73]],"ltp":0.0,"tv":0.0,"id":60443}]}]}
{"op":"mcm","clk":"11933475145","pt":1724308808841,"mc":[{"id":"1.231812839","rc":[{"batb":[[0,2.06,8.84]],"ltp":0.0,"tv":0.0,"id":60443}]}]}
{"op":"mcm","clk":"11933475379","pt":1724308814473,"mc":[{"id":"1.231812839","rc":[{"batl":[[1,46,1.7],[2,90,1.02]],"ltp":0.0,"tv":0.0,"id":60443}]}]}
{"op":"mcm","clk":"11933505759","pt":1724309335694,"mc":[{"id":"1.231812839","rc":[{"batb":[[0,2.04,30.76],[1,1.3,20],[2,1.08,31.25]],"ltp":0.0,"tv":0.0,"id":60443},{"batb":[[0,1.8,62.5],[1,1.68,10],[2,1.5,20]],"ltp":0.0,"tv":0.0,"id":31376}]}]}
{"op":"mcm","clk":"11933510132","pt":1724309462441,"mc":[{"id":"1.231812839","rc":[{"batb":[[0,2.06,8.84],[1,2.04,30],[2,1.3,20]],"ltp":0.0,"tv":0.0,"id":60443},{"batb":[[0,1.81,10.57],[1,1.8,62.5],[2,1.68,10]],"ltp":0.0,"tv":0.0,"id":31376}]}]}
{"op":"mcm","clk":"11933570414","pt":1724311263031,"mc":[{"id":"1.231812839","rc":[{"batb":[[0,2.04,30.76],[1,1.3,20],[2,1.08,31.25]],"batl":[[1,46,1.7]],"ltp":0.0,"tv":0.0,"id":60443},{"batb":[[0,1.8,62.5],[1,1.68,10],[2,1.5,20]],"ltp":0.0,"tv":0.0,"id":31376}]}]}
{"op":"mcm","clk":"11933574736","pt":1724311386074,"mc":[{"id":"1.231812839","rc":[{"batb":[[0,2.06,8.84],[1,2.04,30],[2,1.3,20]],"ltp":0.0,"tv":0.0,"id":60443},{"batb":[[0,1.81,10.57],[1,1.8,62.5],[2,1.68,10]],"ltp":0.0,"tv":0.0,"id":31376}]}]}
{"op":"mcm","clk":"11933633974","pt":1724313186700,"mc":[{"id":"1.231812839","rc":[{"batb":[[0,2.04,30.76],[1,1.3,20],[2,1.08,31.25]],"ltp":0.0,"tv":0.0,"id":60443},{"batb":[[0,1.8,62.5],[1,1.68,10],[2,1.5,20]],"ltp":0.0,"tv":0.0,"id":31376}]}]}
{"op":"mcm","clk":"11933638689","pt":1724313312415,"mc":[{"id":"1.231812839","rc":[{"batb":[[0,2.06,8.84],[1,2.04,30],[2,1.3,20]],"ltp":0.0,"tv":0.0,"id":60443},{"batb":[[0,1.81,10.57],[1,1.8,62.5],[2,1.68,10]],"ltp":0.0,"tv":0.0,"id":31376}]}]}
{"op":"mcm","clk":"11933644265","pt":1724313450173,"mc":[{"id":"1.231812839","rc":[{"batl":[[0,15.5,2.66],[1,90,1.79],[2,95,5]],"ltp":0.0,"tv":0.0,"id":60443}]}]}
{"op":"mcm","clk":"11933684586","pt":1724314375108,"mc":[{"id":"1.231812839","rc":[{"trd":[[1.16,2]],"batl":[[1,90,1.02]],"ltp":1.5,"tv":6.09,"id":3961},{"batb":[[0,2.06,8.83]],"batl":[[1,90,1.78]],"ltp":0.0,"tv":0.0,"id":60443},{"batb":[[0,1.81,10.55]],"batl":[[1,90,1.02]],"ltp":0.0,"tv":0.0,"id":31376}],"tv":6.09}]}
{"op":"mcm","clk":"11933714839","pt":1724315134520,"mc":[{"id":"1.231812839","rc":[{"batb":[[0,2.04,30.76],[1,1.3,20],[2,1.08,31.25]],"ltp":0.0,"tv":0.0,"id":60443},{"batb":[[0,1.8,62.5],[1,1.68,10],[2,1.5,20]],"ltp":0.0,"tv":0.0,"id":31376}]}]}
{"op":"mcm","clk":"11933718451","pt":1724315240743,"mc":[{"id":"1.231812839","rc":[{"batb":[[0,2.06,8.83],[1,2.04,30],[2,1.3,20]],"ltp":0.0,"tv":0.0,"id":60443},{"batb":[[0,1.81,10.55],[1,1.8,62.5],[2,1.68,10]],"ltp":0.0,"tv":0.0,"id":31376}]}]}
{"op":"mcm","clk":"11933786851","pt":1724317041731,"mc":[{"id":"1.231812839","rc":[{"batb":[[0,1.8,62.5],[1,1.68,10],[2,1.5,20]],"ltp":0.0,"tv":0.0,"id":31376}]}]}
{"op":"mcm","clk":"11933786859","pt":1724317041933,"mc":[{"id":"1.231812839","rc":[{"batb":[[0,2.04,30.76],[1,1.3,20],[2,1.08,31.25]],"ltp":0.0,"tv":0.0,"id":60443}]}]}
{"op":"mcm","clk":"11933791402","pt":1724317167079,"mc":[{"id":"1.231812839","rc":[{"batb":[[0,2.06,8.83],[1,2.04,30],[2,1.3,20]],"ltp":0.0,"tv":0.0,"id":60443},{"batb":[[0,1.81,10.55],[1,1.8,62.5],[2,1.68,10]],"ltp":0.0,"tv":0.0,"id":31376}]}]}
{"op":"mcm","clk":"11933793904","pt":1724317232784,"mc":[{"id":"1.231812839","rc":[{"batb":[[0,2.06,8.82]],"batl":[[0,15.5,2.66],[1,90,1.78]],"ltp":0.0,"tv":0.0,"id":60443},{"trd":[[8,0.32]],"batb":[[0,1.81,10.54]],"batl":[[0,9.8,9.37]],"ltp":8.0,"tv":0.31,"id":31376}],"tv":6.41}]}
{"op":"mcm","clk":"11933794958","pt":1724317257610,"mc":[{"id":"1.231812839","rc":[{"batb":[[0,1.8,62.8]],"batl":[[0,9.4,10.83]],"ltp":1.5,"tv":6.09,"id":3961},{"batb":[[0,2.08,1.06],[1,2.06,8.06],[2,2.04,30]],"batl":[[0,15,1.02],[1,15.5,1.93],[2,90,1.78]],"ltp":0.0,"tv":0.0,"id":60443},{"batb":[[0,1.81,10.84]],"batl":[[0,9.8,9.67]],"ltp":8.0,"tv":0.31,"id":31376}]}]}
{"op":"mcm","clk":"11933795034","pt":1724317258491,"mc":[{"id":"1.231812839","rc":[{"batl":[[1,46,1.69],[2,90,1.02]],"ltp":0.0,"tv":0.0,"id":60443}]}]}
{"op":"mcm","clk":"11933795234","pt":1724317264108,"mc":[{"id":"1.231812839","rc":[{"batl":[[0,14.5,1.53],[1,15.5,1.42],[2,90,1.78]],"ltp":0.0,"tv":0.0,"id":60443}]}]}
{"op":"mcm","clk":"11933807905","pt":1724317563634,"mc":[{"id":"1.231812839","rc":[{"batb":[[0,1.8,62.5]],"ltp":1.5,"tv":6.09,"id":3961},{"batb":[[0,2.06,8.82],[1,2.04,30],[2,1.3,20]],"ltp":0.0,"tv":0.0,"id":60443},{"batb":[[0,1.81,10.54]],"ltp":8.0,"tv":0.31,"id":31376}]}]}
{"op":"mcm","clk":"11933807958","pt":1724317564618,"mc":[{"id":"1.231812839","rc":[{"batl":[[1,15.5,1.12]],"ltp":0.0,"tv":0.0,"id":60443},{"batl":[[0,9.8,9.37]],"ltp":8.0,"tv":0.31,"id":31376}]}]}
{"op":"mcm","clk":"11933807969","pt":1724317564822,"mc":[{"id":"1.231812839","rc":[{"batl":[[0,9.4,10.53]],"ltp":1.5,"tv":6.09,"id":3961}]}]}
{"op":"mcm","clk":"11933808046","pt":1724317566423,"mc":[{"id":"1.231812839","rc":[{"batb":[[0,1.8,62.8]],"batl":[[0,9.4,10.83]],"ltp":1.5,"tv":6.09,"id":3961},{"batb":[[0,2.08,1.06],[1,2.06,8.06],[2,2.04,30]],"batl":[[0,14.5,1.83]],"ltp":0.0,"tv":0.0,"id":60443},{"batb":[[0,1.81,10.84]],"batl":[[0,9.8,9.67]],"ltp":8.0,"tv":0.31,"id":31376}]}]}
{"op":"mcm","clk":"11933811545","pt":1724317644799,"mc":[{"id":"1.231812839","rc":[{"batb":[[0,1.81,20.3],[1,1.8,62.5],[2,1.78,5.11]],"ltp":1.5,"tv":6.09,"id":3961}]}]}
{"op":"mcm","clk":"11933811859","pt":1724317652419,"mc":[{"id":"1.231812839","rc":[{"batb":[[0,1.82,20.3],[1,1.81,10.54],[2,1.8,62.5]],"ltp":8.0,"tv":0.31,"id":31376}]}]}
{"op":"mcm","clk":"11933812284","pt":1724317661816,"mc":[{"id":"1.231812839","rc":[{"batl":[[0,3.95,5],[1,14.5,1.83],[2,15.5,1.12]],"ltp":0.0,"tv":0.0,"id":60443}]}]}
{"op":"mcm","clk":"11933812426","pt":1724317665105,"mc":[{"id":"1.231812839","rc":[{"batl":[[1,15,1.02],[2,46,1.69]],"ltp":0.0,"tv":0.0,"id":60443}]}]}
{"op":"mcm","clk":"11933821317","pt":1724317858638,"mc":[{"id":"1.231812839","rc":[{"batb":[[0,1.81,20.6]],"batl":[[0,9.2,1.13],[1,9.4,10],[2,90,1.02]],"ltp":1.5,"tv":6.09,"id":3961},{"batb":[[0,2.1,1.06],[1,2.06,8.36]],"batl":[[0,3.95,5.3]],"ltp":0.0,"tv":0.0,"id":60443},{"batb":[[0,1.82,20.6]],"batl":[[0,9.8,9.97]],"ltp":8.0,"tv":0.31,"id":31376}]}]}
{"op":"mcm","clk":"11933821394","pt":1724317860140,"mc":[{"id":"1.231812839","rc":[{"batl":[[1,9.4,9]],"ltp":1.5,"tv":6.09,"id":3961}]}]}
{"op":"mcm","clk":"11933821756","pt":1724317868633,"mc":[{"id":"1.231812839","rc":[{"batb":[[0,1.82,20.3]],"ltp":8.0,"tv":0.31,"id":31376}]}]}
{"op":"mcm","clk":"11933821777","pt":1724317869142,"mc":[{"id":"1.231812839","rc":[{"batb":[[0,1.81,20.3]],"ltp":1.5,"tv":6.09,"id":3961},{"batb":[[1,2.06,8.06]],"ltp":0.0,"tv":0.0,"id":60443}]}]}
{"op":"mcm","clk":"11933821848","pt":1724317870329,"mc":[{"id":"1.231812839","rc":[{"batl":[[0,9.4,9.83],[1,90,1.02],[2,95,5]],"ltp":1.5,"tv":6.09,"id":3961},{"batl":[[1,15.5,1.66],[2,90,1.78]],"ltp":0.0,"tv":0.0,"id":60443},{"batl":[[0,9.8,9.67]],"ltp":8.0,"tv":0.31,"id":31376}]}]}
{"op":"mcm","clk":"11933822142","pt":1724317876752,"mc":[{"id":"1.231812839","rc":[{"batl":[[0,9.2,1.83],[1,9.4,9],[2,90,1.02]],"ltp":1.5,"tv":6.09,"id":3961}]}]}
{"op":"mcm","clk":"11933825267","pt":1724317956738,"mc":[{"id":"1.231812839","rc":[{"batl":[[1,46,1.49],[2,90,1.02]],"ltp":0.0,"tv":0.0,"id":60443}]}]}
{"op":"mcm","clk":"11933831688","pt":1724318134267,"mc":[{"id":"1.231812839","rc":[{"batl":[[0,3.95,5]],"ltp":0.0,"tv":0.0,"id":60443}]}]}
{"op":"mcm","clk":"11933831737","pt":1724318135457,"mc":[{"id":"1.231812839","rc":[{"batl":[[0,9.2,1.53]],"ltp":1.5,"tv":6.09,"id":3961},{"batl":[[0,9.8,9.37]],"ltp":8.0,"tv":0.31,"id":31376}]}]}
{"op":"mcm","clk":"11933831957","pt":1724318140623,"mc":[{"id":"1.231812839","rc":[{"batb":[[0,1.81,20.6]],"batl":[[0,9.2,1.83]],"ltp":1.5,"tv":6.09,"id":3961},{"batb":[[0,2.1,1.36]],"batl":[[0,3.95,5.3]],"ltp":0.0,"tv":0.0,"id":60443},{"batb":[[0,1.82,20.6]],"batl":[[0,9.8,9.67]],"ltp":8.0,"tv":0.31,"id":31376}]}]}
{"op":"mcm","clk":"11933832113","pt":1724318143760,"mc":[{"id":"1.231812839","rc":[{"batb":[[0,1.81,20.3]],"ltp":1.5,"tv":6.09,"id":3961},{"batb":[[0,1.82,20.3]],"ltp":8.0,"tv":0.31,"id":31376}]}]}
{"op":"mcm","clk":"11933832122","pt":1724318143965,"mc":[{"id":"1.231812839","rc":[{"batb":[[0,2.1,1.06]],"ltp":0.0,"tv":0.0,"id":60443}]}]}
{"op":"mcm","clk":"11933844183","pt":1724318456592,"mc":[{"id":"1.231812839","rc":[{"batb":[[0,1.81,20.6]],"batl":[[0,9,1.13],[1,9.2,1],[2,9.4,9]],"ltp":1.5,"tv":6.09,"id":3961},{"batb":[[0,2.1,1.36]],"batl":[[0,3.95,5.6]],"ltp":0.0,"tv":0.0,"id":60443},{"batb":[[0,1.82,20.6]],"batl":[[0,9.8,9.97]],"ltp":8.0,"tv":0.31,"id":31376}]}]}
{"op":"mcm","clk":"11933844294","pt":1724318458658,"mc":[{"id":"1.231812839","rc":[{"batb":[[0,1.82,20.3]],"ltp":8.0,"tv":0.31,"id":31376}]}]}
{"op":"mcm","clk":"11933844347","pt":1724318459583,"mc":[{"id":"1.231812839","rc":[{"batb":[[0,1.81,20.3]],"batl":[[0,9.2,1.83],[1,9.4,9],[2,90,1.02]],"ltp":1.5,"tv":6.09,"id":3961},{"batb":[[0,2.1,1.06]],"ltp":0.0,"tv":0.0,"id":60443}]}]}
{"op":"mcm","clk":"11933844362","pt":1724318459894,"mc":[{"id":"1.231812839","rc":[{"batl":[[0,3.95,5.3]],"ltp":0.0,"tv":0.0,"id":60443},{"batl":[[0,9.8,9.67]],"ltp":8.0,"tv":0.31,"id":31376}]}]}
{"op":"mcm","clk":"11933845972","pt":1724318498714,"mc":[{"id":"1.231812839","rc":[{"batb":[[2,1.3,20]],"ltp":0.0,"tv":0.0,"id":60443}]}]}
{"op":"mcm","clk":"11933845976","pt":1724318498819,"mc":[{"id":"1.231812839","rc":[{"batb":[[2,2,30]],"ltp":0.0,"tv":0.0,"id":60443}]}]}
{"op":"mcm","clk":"11933846458","pt":1724318510724,"mc":[{"id":"1.231812839","rc":[{"batb":[[2,1.71,30]],"ltp":0.0,"tv":0.0,"id":60443}]}]}
{"op":"mcm","clk":"11933856196","pt":1724318770439,"mc":[{"id":"1.231812839","rc":[{"trd":[[8,1.06],[9,0.6],[9.2,2]],"batb":[[0,9.2,18.17],[1,1.81,20.3],[2,1.8,62.5]],"batl":[[0,9.4,9],[1,90,1.02],[2,95,5]],"ltp":9.2,"tv":9.76,"id":3961}],"tv":10.07}]}
{"op":"mcm","clk":"11933856339","pt":1724318773749,"mc":[{"id":"1.231812839","rc":[{"trd":[[9.4,1.96]],"batl":[[0,9.4,8.02]],"ltp":9.4,"tv":11.72,"id":3961},{"batb":[[0,2.1,1.36]],"batl":[[0,3.95,5.6]],"ltp":0.0,"tv":0.0,"id":60443},{"batb":[[0,1.82,20.6]],"batl":[[0,9.8,8.97]],"ltp":8.0,"tv":0.31,"id":31376}],"tv":12.03}]}
{"op":"mcm","clk":"11933856542","pt":1724318777663,"mc":[{"id":"1.231812839","rc":[{"batb":[[1,1.81,20]],"ltp":9.4,"tv":11.72,"id":3961},{"batb":[[0,2.1,1.06]],"batl":[[0,3.95,5.3]],"ltp":0.0,"tv":0.0,"id":60443},{"batb":[[0,1.82,20.3]],"batl":[[0,9.8,8.67]],"ltp":8.0,"tv":0.31,"id":31376}]}]}
{"op":"mcm","clk":"11933856812","pt":1724318785362,"mc":[{"id":"1.231812839","rc":[{"batb":[[2,1.78,5.11]],"ltp":9.4,"tv":11.72,"id":3961},{"batb":[[2,1.68,10]],"ltp":8.0,"tv":0.31,"id":31376}]}]}
{"op":"mcm","clk":"11933857055","pt":1724318791443,"mc":[{"id":"1.231812839","rc":[{"trd":[[9.2,38.34]],"batb":[[0,1.81,20],[1,1.78,5.11],[2,1.5,19.95]],"batl":[[0,9.2,1.83],[1,9.4,8.02],[2,90,1.02]],"ltp":9.2,"tv":48.06,"id":3961}],"tv":48.37}]}
{"op":"mcm","clk":"11933857216","pt":1724318795663,"mc":[{"id":"1.231812839","rc":[{"batl":[[0,9,1]],"ltp":9.2,"tv":48.06,"id":3961}]}]}
{"op":"mcm","clk":"11933857222","pt":1724318795765,"mc":[{"id":"1.231812839","rc":[{"batb":[[0,1.81,20.3]],"ltp":9.2,"tv":48.06,"id":3961}]}]}
{"op":"mcm","clk":"11933857429","pt":1724318801155,"mc":[{"id":"1.231812839","rc":[{"batl":[[0,9.6,1.67],[1,9.8,8],[2,90,1.02]],"ltp":8.0,"tv":0.31,"id":31376}]}]}
{"op":"mcm","clk":"11933858510","pt":1724318827978,"mc":[{"id":"1.231812839","rc":[{"batl":[[0,9,1.3]],"ltp":9.2,"tv":48.06,"id":3961}]}]}
{"op":"mcm","clk":"11933865051","pt":1724318967436,"mc":[{"id":"1.231812839","rc":[{"batb":[[1,1.68,10],[2,1.5,20]],"ltp":8.0,"tv":0.31,"id":31376}]}]}
{"op":"mcm","clk":"11933865088","pt":1724318968256,"mc":[{"id":"1.231812839","rc":[{"batb":[[1,1.71,30],[2,1.3,20]],"ltp":0.0,"tv":0.0,"id":60443}]}]}
{"op":"mcm","clk":"11933867143","pt":1724319010478,"mc":[{"id":"1.231812839","rc":[{"batb":[[1,1.72,11.86],[2,1.71,30]],"ltp":0.0,"tv":0.0,"id":60443},{"batb":[[0,1.83,10.59],[1,1.82,20],[2,1.68,10]],"ltp":8.0,"tv":0.31,"id":31376}]}]}
{"op":"mcm","clk":"11933868399","pt":1724319038530,"mc":[{"id":"1.231812839","rc":[{"batb":[[0,3.5,48],[1,1.81,20.3],[2,1.78,5.11]],"ltp":9.2,"tv":48.06,"id":3961}]}]}
{"op":"mcm","clk":"11933868505","pt":1724319040723,"mc":[{"id":"1.231812839","rc":[{"batl":[[0,9.8,8.67],[1,90,1.02],[2,95,5]],"ltp":8.0,"tv":0.31,"id":31376}]}]}
{"op":"mcm","clk":"11933868760","pt":1724319046320,"mc":[{"id":"1.231812839","rc":[{"batl":[[0,7.4,1.3],[1,9.8,8.37],[2,90,1.02]],"ltp":8.0,"tv":0.31,"id":31376}]}]}
{"op":"mcm","clk":"11933869859","pt":1724319067273,"mc":[{"id":"1.231812839","rc":[{"batb":[[0,2,30],[1,1.83,10.59],[2,1.82,20]],"ltp":8.0,"tv":0.31,"id":31376}]}]}
{"op":"mcm","clk":"11933870042","pt":1724319070574,"mc":[{"id":"1.231812839","rc":[{"batl":[[0,9,1.83]],"ltp":9.2,"tv":48.06,"id":3961}]}]}
{"op":"mcm","clk":"11933871267","pt":1724319092681,"mc":[{"id":"1.231812839","rc":[{"batl":[[0,3.95,5.6]],"ltp":0.0,"tv":0.0,"id":60443},{"batl":[[0,7.4,1.6]],"ltp":8.0,"tv":0.31,"id":31376}]}]}
{"op":"mcm","clk":"11933871280","pt":1724319092886,"mc":[{"id":"1.231812839","rc":[{"batb":[[0,2.1,1.36]],"ltp":0.0,"tv":0.0,"id":60443},{"batb":[[0,2,30.3]],"ltp":8.0,"tv":0.31,"id":31376}]}]}
{"op":"mcm","clk":"11933871497","pt":1724319096377,"mc":[{"id":"1.231812839","rc":[{"batl":[[0,9.8,8.97],[1,90,1.02],[2,95,5]],"ltp":8.0,"tv":0.31,"id":31376}]}]}
{"op":"mcm","clk":"11933871785","pt":1724319101710,"mc":[{"id":"1.231812839","rc":[{"batb":[[0,2.1,1.06]],"batl":[[0,3.95,5.3]],"ltp":0.0,"tv":0.0,"id":60443},{"batb":[[1,1.83,10.29]],"ltp":8.0,"tv":0.31,"id":31376}]}]}
{"op":"mcm","clk":"11933871822","pt":1724319102420,"mc":[{"id":"1.231812839","rc":[{"batl":[[0,9.8,8.67]],"ltp":8.0,"tv":0.31,"id":31376}]}]}
{"op":"mcm","clk":"11933872328","pt":1724319112916,"mc":[{"id":"1.231812839","rc":[{"batb":[[1,1.81,20]],"ltp":9.2,"tv":48.06,"id":3961}]}]}
{"op":"mcm","clk":"11933872450","pt":1724319115535,"mc":[{"id":"1.231812839","rc":[{"batb":[[0,3.5,48.3]],"ltp":9.2,"tv":48.06,"id":3961}]}]}
{"op":"mcm","clk":"11933872638","pt":1724319118723,"mc":[{"id":"1.231812839","rc":[{"batl":[[0,7.4,1.3],[1,9.8,8.37],[2,90,1.02]],"ltp":8.0,"tv":0.31,"id":31376}]}]}
{"op":"mcm","clk":"11933873849","pt":1724319141443,"mc":[{"id":"1.231812839","rc":[{"batl":[[0,9,1.53]],"ltp":9.2,"tv":48.06,"id":3961}]}]}
{"op":"mcm","clk":"11933874196","pt":1724319147616,"mc":[{"id":"1.231812839","rc":[{"batl":[[0,9,1.83]],"ltp":9.2,"tv":48.06,"id":3961}]}]}
{"op":"mcm","clk":"11933880363","pt":1724319278990,"mc":[{"id":"1.231812839","rc":[{"trd":[[1.81,16.3],[3.5,96],[3.55,0.6]],"batb":[[0,1.82,10],[1,1.81,11.85]],"ltp":1.81,"tv":160.96,"id":3961},{"batb":[[0,2.02,10.3],[1,2,30],[2,1.83,10.29]],"ltp":8.0,"tv":0.31,"id":31376}],"tv":161.27}]}
{"op":"mcm","clk":"11933880490","pt":1724319282291,"mc":[{"id":"1.231812839","rc":[{"batb":[[0,1.81,11.85],[1,1.78,5.11],[2,1.5,19.95]],"ltp":1.81,"tv":160.96,"id":3961},{"batb":[[0,2,30.3],[1,1.83,10.29],[2,1.82,20]],"ltp":8.0,"tv":0.31,"id":31376}]}]}
{"op":"mcm","clk":"11933880685","pt":1724319286622,"mc":[{"id":"1.231812839","rc":[{"batb":[[0,1.82,10],[1,1.81,11.85],[2,1.78,5.11]],"ltp":1.81,"tv":160.96,"id":3961},{"batb":[[0,2.02,10.3],[1,2,30],[2,1.83,10.29]],"ltp":8.0,"tv":0.31,"id":31376}]}]}
{"op":"mcm","clk":"11933880850","pt":1724319290109,"mc":[{"id":"1.231812839","rc":[{"batb":[[0,1.81,11.85],[1,1.78,5.11],[2,1.5,19.95]],"ltp":1.81,"tv":160.96,"id":3961},{"batb":[[0,2,30.3],[1,1.83,10.29],[2,1.82,20]],"ltp":8.0,"tv":0.31,"id":31376}]}]}
{"op":"mcm","clk":"11933881202","pt":1724319299239,"mc":[{"id":"1.231812839","rc":[{"batb":[[0,1.82,10],[1,1.81,11.85],[2,1.78,5.11]],"ltp":1.81,"tv":160.96,"id":3961},{"batb":[[0,2.02,10.3],[1,2,30],[2,1.83,10.29]],"ltp":8.0,"tv":0.31,"id":31376}]}]}
{"op":"mcm","clk":"11933881362","pt":1724319302735,"mc":[{"id":"1.231812839","rc":[{"batb":[[0,1.81,11.85],[1,1.78,5.11],[2,1.5,19.95]],"ltp":1.81,"tv":160.96,"id":3961},{"batb":[[0,2,30.3],[1,1.83,10.29],[2,1.82,20]],"ltp":8.0,"tv":0.31,"id":31376}]}]}
{"op":"mcm","clk":"11933881997","pt":1724319318030,"mc":[{"id":"1.231812839","rc":[{"batb":[[0,1.82,10],[1,1.81,11.85],[2,1.78,5.11]],"ltp":1.81,"tv":160.96,"id":3961},{"batb":[[0,2.02,10.3],[1,2,30],[2,1.83,10.29]],"ltp":8.0,"tv":0.31,"id":31376}]}]}
{"op":"mcm","clk":"11933882136","pt":1724319321712,"mc":[{"id":"1.231812839","rc":[{"batb":[[0,1.81,11.85],[1,1.78,5.11],[2,1.5,19.95]],"ltp":1.81,"tv":160.96,"id":3961},{"batb":[[0,2,30.3],[1,1.83,10.29],[2,1.82,20]],"ltp":8.0,"tv":0.31,"id":31376}]}]}
{"op":"mcm","clk":"11933882269","pt":1724319326640,"mc":[{"id":"1.231812839","rc":[{"batb":[[0,1.82,10],[1,1.81,11.85],[2,1.78,5.11]],"ltp":1.81,"tv":160.96,"id":3961},{"batb":[[0,2.02,10.3],[1,2,30],[2,1.83,10.29]],"ltp":8.0,"tv":0.31,"id":31376}]}]}
{"op":"mcm","clk":"11933882422","pt":1724319330069,"mc":[{"id":"1.231812839","rc":[{"batb":[[0,1.81,11.85],[1,1.78,5.11],[2,1.5,19.95]],"ltp":1.81,"tv":160.96,"id":3961},{"batb":[[0,2,30.3],[1,1.83,10.29],[2,1.82,20]],"ltp":8.0,"tv":0.31,"id":31376}]}]}
{"op":"mcm","clk":"11933882649","pt":1724319335265,"mc":[{"id":"1.231812839","rc":[{"batb":[[0,1.82,10],[1,1.81,11.85],[2,1.78,5.11]],"ltp":1.81,"tv":160.96,"id":3961},{"batb":[[0,2.02,10.3],[1,2,30],[2,1.83,10.29]],"ltp":8.0,"tv":0.31,"id":31376}]}]}
{"op":"mcm","clk":"11933882762","pt":1724319338551,"mc":[{"id":"1.231812839","rc":[{"batb":[[0,1.81,11.85],[1,1.78,5.11],[2,1.5,19.95]],"ltp":1.81,"tv":160.96,"id":3961},{"batb":[[0,2,30.3],[1,1.83,10.29],[2,1.82,20]],"ltp":8.0,"tv":0.31,"id":31376}]}]}
{"op":"mcm","clk":"11933883406","pt":1724319356162,"mc":[{"id":"1.231812839","rc":[{"batb":[[0,1.82,10],[1,1.81,11.85],[2,1.78,5.11]],"ltp":1.81,"tv":160.96,"id":3961},{"batb":[[0,2.02,10.3],[1,2,30],[2,1.83,10.29]],"ltp":8.0,"tv":0.31,"id":31376}]}]}
{"op":"mcm","clk":"11933883529","pt":1724319359670,"mc":[{"id":"1.231812839","rc":[{"batb":[[0,1.81,11.85],[1,1.78,5.11],[2,1.5,19.95]],"ltp":1.81,"tv":160.96,"id":3961},{"batb":[[0,2,30.3],[1,1.83,10.29],[2,1.82,20]],"ltp":8.0,"tv":0.31,"id":31376}]}]}
{"op":"mcm","clk":"11933883769","pt":1724319366407,"mc":[{"id":"1.231812839","rc":[{"batb":[[0,1.82,10],[1,1.81,11.85],[2,1.78,5.11]],"ltp":1.81,"tv":160.96,"id":3961},{"batb":[[0,2.02,30.3],[1,2,30],[2,1.83,10.29]],"ltp":8.0,"tv":0.31,"id":31376}]}]}
{"op":"mcm","clk":"11933883878","pt":1724319369905,"mc":[{"id":"1.231812839","rc":[{"batb":[[0,1.81,11.85],[1,1.78,5.11],[2,1.5,19.95]],"ltp":1.81,"tv":160.96,"id":3961},{"batb":[[0,2.02,20.3]],"ltp":8.0,"tv":0.31,"id":31376}]}]}
{"op":"mcm","clk":"11933883989","pt":1724319372703,"mc":[{"id":"1.231812839","rc":[{"batb":[[0,1.82,10],[1,1.81,11.85],[2,1.78,5.11]],"ltp":1.81,"tv":160.96,"id":3961},{"batb":[[0,2.04,10],[1,2.02,20.3],[2,2,30]],"ltp":8.0,"tv":0.31,"id":31376}]}]}
{"op":"mcm","clk":"11933884021","pt":1724319373674,"mc":[{"id":"1.231812839","rc":[{"batl":[[0,7.2,1.23],[1,7.4,1],[2,9.8,8.37]],"ltp":8.0,"tv":0.31,"id":31376}]}]}
{"op":"mcm","clk":"11933884065","pt":1724319374806,"mc":[{"id":"1.231812839","rc":[{"batl":[[1,9.8,8.37],[2,90,1.02]],"ltp":8.0,"tv":0.31,"id":31376}]}]}
{"op":"mcm","clk":"11933884114","pt":1724319376202,"mc":[{"id":"1.231812839","rc":[{"batb":[[0,1.81,11.85],[1,1.78,5.11],[2,1.5,19.95]],"ltp":1.81,"tv":160.96,"id":3961},{"batb":[[0,2.02,20.3],[1,2,30],[2,1.83,10.29]],"ltp":8.0,"tv":0.31,"id":31376}]}]}
{"op":"mcm","clk":"11933884265","pt":1724319380410,"mc":[{"id":"1.231812839","rc":[{"batb":[[0,1.82,10],[1,1.81,11.85],[2,1.78,5.11]],"ltp":1.81,"tv":160.96,"id":3961},{"batb":[[0,2.04,10],[1,2.02,20.3],[2,2,30]],"batl":[[0,7,1.93],[1,9.8,8.67]],"ltp":8.0,"tv":0.31,"id":31376}]}]}
{"op":"mcm","clk":"11933884365","pt":1724319383406,"mc":[{"id":"1.231812839","rc":[{"batb":[[0,1.81,11.85],[1,1.78,5.11],[2,1.5,19.95]],"ltp":1.81,"tv":160.96,"id":3961},{"batb":[[0,2.02,20.3],[1,2,30],[2,1.83,10.29]],"ltp":8.0,"tv":0.31,"id":31376}]}]}
