{"op":"mcm","clk":"11833142860","pt":1723108867999,"mc":[{"id":"1.231581624","marketDefinition":{"bspMarket":false,"turnInPlayEnabled":true,"persistenceEnabled":true,"marketBaseRate":5.0,"eventId":"33477743","eventTypeId":"4","numberOfWinners":1,"bettingType":"ODDS","marketType":"MATCH_ODDS","marketTime":"2024-08-11T10:00:00.000Z","suspendTime":"2024-08-11T10:00:00.000Z","bspReconciled":false,"complete":true,"inPlay":false,"crossMatching":false,"runnersVoidable":false,"numberOfActiveRunners":2,"betDelay":0,"status":"OPEN","runners":[{"status":"ACTIVE","sortPriority":1,"id":31378,"name":"Middlesex"},{"status":"ACTIVE","sortPriority":2,"id":5995,"name":"Somerset"}],"regulators":["MR_INT"],"countryCode":"GB","discountAllowed":false,"timezone":"GMT","openDate":"2024-08-11T10:00:00.000Z","version":6061697202,"name":"Match Odds","eventName":"Middlesex v Somerset"},"rc":[{"batb":[[0,1.01,20]],"ltp":0.0,"tv":0.0,"id":31378},{"batb":[[0,1.01,20]],"ltp":0.0,"tv":0.0,"id":5995}]}]}
{"op":"mcm","clk":"11833142895","pt":1723108868545,"mc":[{"id":"1.231581624","marketDefinition":{"bspMarket":false,"turnInPlayEnabled":true,"persistenceEnabled":true,"marketBaseRate":5.0,"eventId":"33477743","eventTypeId":"4","numberOfWinners":1,"bettingType":"ODDS","marketType":"MATCH_ODDS","marketTime":"2024-08-11T10:00:00.000Z","suspendTime":"2024-08-11T10:00:00.000Z","bspReconciled":false,"complete":true,"inPlay":false,"crossMatching":false,"runnersVoidable":false,"numberOfActiveRunners":2,"betDelay":0,"status":"OPEN","runners":[{"status":"ACTIVE","sortPriority":1,"id":31378,"name":"Middlesex"},{"status":"ACTIVE","sortPriority":2,"id":5995,"name":"Somerset"}],"regulators":["MR_INT"],"countryCode":"GB","discountAllowed":true,"timezone":"GMT","openDate":"2024-08-11T10:00:00.000Z","version":6061697202,"name":"Match Odds","eventName":"Middlesex v Somerset"}}]}
{"op":"mcm","clk":"11833142959","pt":1723108869693,"mc":[{"id":"1.231581624","rc":[{"batb":[[0,1.03,200],[1,1.02,200],[2,1.01,220]],"ltp":0.0,"tv":0.0,"id":31378},{"batb":[[0,1.03,200],[1,1.02,200],[2,1.01,220]],"ltp":0.0,"tv":0.0,"id":5995}]}]}
{"op":"mcm","clk":"11833265199","pt":1723111247271,"mc":[{"id":"1.231581624","rc":[{"batb":[[2,1.01,227.89]],"ltp":0.0,"tv":0.0,"id":31378},{"batb":[[2,1.01,227.89]],"ltp":0.0,"tv":0.0,"id":5995}]}]}
{"op":"mcm","clk":"11833266172","pt":1723111265677,"mc":[{"id":"1.231581624","rc":[{"batb":[[1,1.02,207.89]],"ltp":0.0,"tv":0.0,"id":31378},{"batb":[[1,1.02,207.89]],"ltp":0.0,"tv":0.0,"id":5995}]}]}
{"op":"mcm","clk":"11833267939","pt":1723111294519,"mc":[{"id":"1.231581624","rc":[{"batb":[[1,1.02,247.34]],"ltp":0.0,"tv":0.0,"id":31378},{"batb":[[1,1.02,247.34]],"ltp":0.0,"tv":0.0,"id":5995}]}]}
{"op":"mcm","clk":"11833268710","pt":1723111308350,"mc":[{"id":"1.231581624","rc":[{"batb":[[0,1.03,207.89]],"ltp":0.0,"tv":0.0,"id":31378},{"batb":[[0,1.03,207.89]],"ltp":0.0,"tv":0.0,"id":5995}]}]}
{"op":"mcm","clk":"11833298977","pt":1723111758208,"mc":[{"id":"1.231581624","rc":[{"batb":[[0,1.04,7.89],[1,1.03,207.89],[2,1.02,247.34]],"ltp":0.0,"tv":0.0,"id":31378},{"batb":[[0,1.04,7.89],[1,1.03,207.89],[2,1.02,247.34]],"ltp":0.0,"tv":0.0,"id":5995}]}]}
{"op":"mcm","clk":"11833299903","pt":1723111775434,"mc":[{"id":"1.231581624","rc":[{"batb":[[0,1.05,7.89],[1,1.04,7.89],[2,1.03,207.89]],"ltp":0.0,"tv":0.0,"id":31378},{"batb":[[0,1.05,7.89],[1,1.04,7.89],[2,1.03,207.89]],"ltp":0.0,"tv":0.0,"id":5995}]}]}
{"op":"mcm","clk":"11833300922","pt":1723111793255,"mc":[{"id":"1.231581624","rc":[{"batb":[[0,1.06,7.89],[1,1.05,7.89],[2,1.04,7.89]],"ltp":0.0,"tv":0.0,"id":31378},{"batb":[[0,1.06,7.89],[1,1.05,7.89],[2,1.04,7.89]],"ltp":0.0,"tv":0.0,"id":5995}]}]}
{"op":"mcm","clk":"11833302116","pt":1723111812259,"mc":[{"id":"1.231581624","rc":[{"batb":[[0,1.07,7.89],[1,1.06,7.89],[2,1.05,7.89]],"ltp":0.0,"tv":0.0,"id":31378},{"batb":[[0,1.07,7.89],[1,1.06,7.89],[2,1.05,7.89]],"ltp":0.0,"tv":0.0,"id":5995}]}]}
{"op":"mcm","clk":"11833303038","pt":1723111826980,"mc":[{"id":"1.231581624","rc":[{"batb":[[0,1.08,7.89],[1,1.07,7.89],[2,1.06,7.89]],"ltp":0.0,"tv":0.0,"id":31378},{"batb":[[0,1.08,7.89],[1,1.07,7.89],[2,1.06,7.89]],"ltp":0.0,"tv":0.0,"id":5995}]}]}
{"op":"mcm","clk":"11833521644","pt":1723115574844,"mc":[{"id":"1.231581624","rc":[{"batb":[[0,1.08,7.88],[1,1.07,7.88],[2,1.06,7.88]],"ltp":0.0,"tv":0.0,"id":31378},{"batb":[[0,1.08,7.88],[1,1.07,7.88],[2,1.06,7.88]],"ltp":0.0,"tv":0.0,"id":5995}]}]}
{"op":"mcm","clk":"11833543125","pt":1723115799113,"mc":[{"id":"1.231581624","marketDefinition":{"bspMarket":false,"turnInPlayEnabled":true,"persistenceEnabled":true,"marketBaseRate":5.0,"eventId":"33477743","eventTypeId":"4","numberOfWinners":1,"bettingType":"ODDS","marketType":"MATCH_ODDS","marketTime":"2024-08-11T10:00:00.000Z","suspendTime":"2024-08-11T10:00:00.000Z","bspReconciled":false,"complete":true,"inPlay":false,"crossMatching":true,"runnersVoidable":false,"numberOfActiveRunners":2,"betDelay":0,"status":"OPEN","runners":[{"status":"ACTIVE","sortPriority":1,"id":31378,"name":"Middlesex"},{"status":"ACTIVE","sortPriority":2,"id":5995,"name":"Somerset"}],"regulators":["MR_INT"],"countryCode":"GB","discountAllowed":true,"timezone":"GMT","openDate":"2024-08-11T10:00:00.000Z","version":6061697202,"name":"Match Odds","eventName":"Middlesex v Somerset"}}]}
{"op":"mcm","clk":"11833838691","pt":1723120974861,"mc":[{"id":"1.231581624","rc":[{"batb":[[0,1.08,7.88],[1,1.07,7.88],[2,1.06,7.88]],"ltp":0.0,"tv":0.0,"id":31378},{"batb":[[0,1.08,7.88],[1,1.07,7.88],[2,1.06,7.88]],"ltp":0.0,"tv":0.0,"id":5995}]}]}
{"op":"mcm","clk":"11834127371","pt":1723126374884,"mc":[{"id":"1.231581624","rc":[{"batb":[[0,1.08,7.87],[1,1.07,7.87],[2,1.06,7.87]],"ltp":0.0,"tv":0.0,"id":31378},{"batb":[[0,1.08,7.87],[1,1.07,7.87],[2,1.06,7.87]],"ltp":0.0,"tv":0.0,"id":5995}]}]}
{"op":"mcm","clk":"11834341991","pt":1723129858289,"mc":[{"id":"1.231581624","rc":[{"batb":[[0,1.25,100],[1,1.08,7.86],[2,1.07,7.86]],"ltp":0.0,"tv":0.0,"id":31378},{"batb":[[0,1.08,7.86],[1,1.07,7.86],[2,1.06,7.86]],"ltp":0.0,"tv":0.0,"id":5995}]}]}
{"op":"mcm","clk":"11834342031","pt":1723129858703,"mc":[{"id":"1.231581624","rc":[{"batb":[[0,1.25,100],[1,1.08,7.86],[2,1.07,7.86]],"ltp":0.0,"tv":0.0,"id":5995}]}]}
{"op":"mcm","clk":"11835129382","pt":1723137174888,"mc":[{"id":"1.231581624","rc":[{"batb":[[1,1.08,7.85],[2,1.07,7.85]],"ltp":0.0,"tv":0.0,"id":31378},{"batb":[[1,1.08,7.85],[2,1.07,7.85]],"ltp":0.0,"tv":0.0,"id":5995}]}]}
{"op":"mcm","clk":"11836027575","pt":1723142574906,"mc":[{"id":"1.231581624","rc":[{"batb":[[1,1.08,7.85],[2,1.07,7.85]],"ltp":0.0,"tv":0.0,"id":31378},{"batb":[[1,1.08,7.85],[2,1.07,7.85]],"ltp":0.0,"tv":0.0,"id":5995}]}]}
{"op":"mcm","clk":"11836847092","pt":1723151654299,"mc":[{"id":"1.231581624","rc":[{"batb":[[1,1.08,7.84],[2,1.07,7.84]],"ltp":0.0,"tv":0.0,"id":31378},{"batb":[[1,1.08,7.84],[2,1.07,7.84]],"ltp":0.0,"tv":0.0,"id":5995}]}]}
{"op":"mcm","clk":"11837116815","pt":1723158774888,"mc":[{"id":"1.231581624","rc":[{"batb":[[1,1.08,7.85],[2,1.07,7.85]],"ltp":0.0,"tv":0.0,"id":31378},{"batb":[[1,1.08,7.85],[2,1.07,7.85]],"ltp":0.0,"tv":0.0,"id":5995}]}]}
{"op":"mcm","clk":"11837350667","pt":1723164174886,"mc":[{"id":"1.231581624","rc":[{"batb":[[1,1.08,7.84],[2,1.07,7.84]],"ltp":0.0,"tv":0.0,"id":31378},{"batb":[[1,1.08,7.84],[2,1.07,7.84]],"ltp":0.0,"tv":0.0,"id":5995}]}]}
{"op":"mcm","clk":"11837575183","pt":1723169574865,"mc":[{"id":"1.231581624","rc":[{"batb":[[1,1.08,7.84],[2,1.07,7.84]],"ltp":0.0,"tv":0.0,"id":31378},{"batb":[[1,1.08,7.84],[2,1.07,7.84]],"ltp":0.0,"tv":0.0,"id":5995}]}]}
{"op":"mcm","clk":"11837797183","pt":1723174974896,"mc":[{"id":"1.231581624","rc":[{"batb":[[1,1.08,7.84],[2,1.07,7.84]],"ltp":0.0,"tv":0.0,"id":31378},{"batb":[[1,1.08,7.84],[2,1.07,7.84]],"ltp":0.0,"tv":0.0,"id":5995}]}]}
{"op":"mcm","clk":"11838028203","pt":1723180374886,"mc":[{"id":"1.231581624","rc":[{"batb":[[1,1.08,7.84],[2,1.07,7.84]],"ltp":0.0,"tv":0.0,"id":31378},{"batb":[[1,1.08,7.84],[2,1.07,7.84]],"ltp":0.0,"tv":0.0,"id":5995}]}]}
{"op":"mcm","clk":"11838263235","pt":1723185774915,"mc":[{"id":"1.231581624","rc":[{"batb":[[1,1.08,7.84],[2,1.07,7.84]],"ltp":0.0,"tv":0.0,"id":31378},{"batb":[[1,1.08,7.84],[2,1.07,7.84]],"ltp":0.0,"tv":0.0,"id":5995}]}]}
{"op":"mcm","clk":"11838479499","pt":1723189567066,"mc":[{"id":"1.231581624","rc":[{"batb":[[1,1.08,7.83],[2,1.07,7.83]],"batl":[[0,1000,0.02]],"ltp":0.0,"tv":0.0,"id":31378},{"batb":[[1,1.08,7.83],[2,1.07,7.83]],"batl":[[0,1000,0.02]],"ltp":0.0,"tv":0.0,"id":5995}]}]}
{"op":"mcm","clk":"11838568802","pt":1723191174956,"mc":[{"id":"1.231581624","rc":[{"batb":[[1,1.08,7.84],[2,1.07,7.84]],"ltp":0.0,"tv":0.0,"id":31378},{"batb":[[1,1.08,7.84],[2,1.07,7.84]],"ltp":0.0,"tv":0.0,"id":5995}]}]}
{"op":"mcm","clk":"11838855909","pt":1723196574949,"mc":[{"id":"1.231581624","rc":[{"batb":[[1,1.08,7.83],[2,1.07,7.83]],"ltp":0.0,"tv":0.0,"id":31378},{"batb":[[1,1.08,7.83],[2,1.07,7.83]],"ltp":0.0,"tv":0.0,"id":5995}]}]}
{"op":"mcm","clk":"11839222072","pt":1723201974933,"mc":[{"id":"1.231581624","rc":[{"batb":[[1,1.08,7.85],[2,1.07,7.85]],"ltp":0.0,"tv":0.0,"id":31378},{"batb":[[1,1.08,7.85],[2,1.07,7.85]],"ltp":0.0,"tv":0.0,"id":5995}]}]}
{"op":"mcm","clk":"11839679742","pt":1723207374945,"mc":[{"id":"1.231581624","rc":[{"batb":[[1,1.08,7.85],[2,1.07,7.85]],"ltp":0.0,"tv":0.0,"id":31378},{"batb":[[1,1.08,7.85],[2,1.07,7.85]],"ltp":0.0,"tv":0.0,"id":5995}]}]}
{"op":"mcm","clk":"11840163875","pt":1723212774936,"mc":[{"id":"1.231581624","rc":[{"batb":[[1,1.08,7.85],[2,1.07,7.85]],"ltp":0.0,"tv":0.0,"id":31378},{"batb":[[1,1.08,7.85],[2,1.07,7.85]],"ltp":0.0,"tv":0.0,"id":5995}]}]}
{"op":"mcm","clk":"11840188653","pt":1723212927548,"mc":[{"id":"1.231581624","rc":[{"batl":[[0,2.4,22],[1,1000,0.02]],"ltp":0.0,"tv":0.0,"id":31378}]}]}
{"op":"mcm","clk":"11840189412","pt":1723212936039,"mc":[{"id":"1.231581624","rc":[{"batl":[[0,2.54,22]],"ltp":0.0,"tv":0.0,"id":31378}]}]}
{"op":"mcm","clk":"11840719802","pt":1723218174945,"mc":[{"id":"1.231581624","rc":[{"batb":[[1,1.08,7.84],[2,1.07,7.84]],"ltp":0.0,"tv":0.0,"id":31378},{"batb":[[1,1.08,7.84],[2,1.07,7.84]],"ltp":0.0,"tv":0.0,"id":5995}]}]}
{"op":"mcm","clk":"11841163631","pt":1723221507373,"mc":[{"id":"1.231581624","rc":[{"batb":[[0,1.08,7.84],[1,1.07,7.84],[2,1.06,7.84]],"ltp":0.0,"tv":0.0,"id":31378},{"batb":[[0,1.08,7.84],[1,1.07,7.84],[2,1.06,7.84]],"ltp":0.0,"tv":0.0,"id":5995}]}]}
{"op":"mcm","clk":"11841171862","pt":1723221559442,"mc":[{"id":"1.231581624","rc":[{"batb":[[0,1.48,52.08],[1,1.43,58.14],[2,1.38,65.79]],"ltp":0.0,"tv":0.0,"id":31378},{"batb":[[0,1.43,58.14],[1,1.38,65.79],[2,1.33,75.76]],"ltp":0.0,"tv":0.0,"id":5995}]}]}
{"op":"mcm","clk":"11841171874","pt":1723221559541,"mc":[{"id":"1.231581624","rc":[{"batb":[[0,1.48,52.08],[1,1.43,58.14],[2,1.38,65.79]],"ltp":0.0,"tv":0.0,"id":5995}]}]}
{"op":"mcm","clk":"11841306886","pt":1723222458495,"mc":[{"id":"1.231581624","rc":[{"batb":[[0,1.49,6.13],[1,1.48,52.08],[2,1.43,58.14]],"ltp":0.0,"tv":0.0,"id":31378},{"batb":[[0,1.66,7.17],[1,1.48,52.08],[2,1.43,58.14]],"ltp":0.0,"tv":0.0,"id":5995}]}]}
{"op":"mcm","clk":"11841349888","pt":1723222772009,"mc":[{"id":"1.231581624","rc":[{"batb":[[0,2.32,31.65],[1,1.49,6.13],[2,1.48,52.08]],"ltp":0.0,"tv":0.0,"id":31378},{"batb":[[0,1.69,60.56],[1,1.66,7.17],[2,1.48,52.08]],"ltp":0.0,"tv":0.0,"id":5995}]}]}
{"op":"mcm","clk":"11841496590","pt":1723223574963,"mc":[{"id":"1.231581624","rc":[{"batb":[[1,1.49,6.13]],"ltp":0.0,"tv":0.0,"id":31378},{"batb":[[1,1.66,7.17]],"ltp":0.0,"tv":0.0,"id":5995}]}]}
{"op":"mcm","clk":"11841962523","pt":1723226040190,"mc":[{"id":"1.231581624","rc":[{"batb":[[1,1.48,52.08],[2,1.43,58.14]],"ltp":0.0,"tv":0.0,"id":31378},{"batb":[[1,1.48,52.08],[2,1.43,58.14]],"ltp":0.0,"tv":0.0,"id":5995}]}]}
{"op":"mcm","clk":"11843189869","pt":1723231899978,"mc":[{"id":"1.231581624","rc":[{"batb":[[0,1.7,9],[1,1.69,60.56],[2,1.48,52.08]],"ltp":0.0,"tv":0.0,"id":5995}]}]}
{"op":"mcm","clk":"11843632111","pt":1723235157403,"mc":[{"id":"1.231581624","rc":[{"trd":[[1.7,0.14]],"batb":[[0,1.7,8.93]],"ltp":1.7,"tv":0.14,"id":5995}],"tv":0.14}]}
{"op":"mcm","clk":"11843798529","pt":1723237540670,"mc":[{"id":"1.231581624","rc":[{"trd":[[1.7,0.28]],"batb":[[0,1.7,8.86]],"ltp":1.7,"tv":0.28,"id":5995}],"tv":0.28}]}
{"op":"mcm","clk":"11843909722","pt":1723239938546,"mc":[{"id":"1.231581624","rc":[{"trd":[[1.7,0.42]],"batb":[[0,1.7,8.79]],"ltp":1.7,"tv":0.42,"id":5995}],"tv":0.42}]}
{"op":"mcm","clk":"11844465242","pt":1723249539210,"mc":[{"id":"1.231581624","rc":[{"trd":[[1.7,0.56]],"batb":[[0,1.7,8.72]],"ltp":1.7,"tv":0.56,"id":5995}],"tv":0.56}]}
{"op":"mcm","clk":"11844570130","pt":1723250739679,"mc":[{"id":"1.231581624","rc":[{"trd":[[1.7,0.7]],"batb":[[0,1.7,8.65]],"ltp":1.7,"tv":0.7,"id":5995}],"tv":0.7}]}
{"op":"mcm","clk":"11844668703","pt":1723251940188,"mc":[{"id":"1.231581624","rc":[{"trd":[[1.7,0.84]],"batb":[[0,1.7,8.58]],"ltp":1.7,"tv":0.84,"id":5995}],"tv":0.84}]}
{"op":"mcm","clk":"11846418810","pt":1723278734713,"mc":[{"id":"1.231581624","rc":[{"batb":[[1,1.08,7.85],[2,1.07,7.85]],"ltp":0.0,"tv":0.0,"id":31378},{"batb":[[2,1.08,7.85]],"ltp":1.7,"tv":0.84,"id":5995}]}]}
{"op":"mcm","clk":"11846442323","pt":1723278979369,"mc":[{"id":"1.231581624","rc":[{"batb":[[1,1.25,1200],[2,1.08,7.85]],"ltp":0.0,"tv":0.0,"id":31378},{"batb":[[2,1.25,1200]],"ltp":1.7,"tv":0.84,"id":5995}]}]}
{"op":"mcm","clk":"11846449829","pt":1723279056040,"mc":[{"id":"1.231581624","rc":[{"batb":[[1,1.08,7.85],[2,1.07,7.85]],"ltp":0.0,"tv":0.0,"id":31378},{"batb":[[2,1.08,7.85]],"ltp":1.7,"tv":0.84,"id":5995}]}]}
{"op":"mcm","clk":"11846450057","pt":1723279058543,"mc":[{"id":"1.231581624","rc":[{"batb":[[1,1.3,1000],[2,1.08,7.85]],"ltp":0.0,"tv":0.0,"id":31378},{"batb":[[2,1.3,1000]],"ltp":1.7,"tv":0.84,"id":5995}]}]}
{"op":"mcm","clk":"11846815428","pt":1723282406438,"mc":[{"id":"1.231581624","rc":[{"trd":[[1.7,13.78]],"batb":[[0,1.7,2.11]],"ltp":1.7,"tv":13.78,"id":5995}],"tv":13.78}]}
{"op":"mcm","clk":"11848610718","pt":1723293769942,"mc":[{"id":"1.231581624","rc":[{"batl":[[0,2.42,22]],"ltp":0.0,"tv":0.0,"id":31378}]}]}
{"op":"mcm","clk":"11849203662","pt":1723297006744,"mc":[{"id":"1.231581624","rc":[{"trd":[[2.42,19.59]],"batb":[[0,2.34,10],[1,2.32,31.65],[2,1.3,1000]],"batl":[[0,2.42,2.41]],"ltp":2.42,"tv":19.59,"id":31378},{"trd":[[1.7,45.89]],"batb":[[0,1.7,10]],"ltp":1.7,"tv":45.89,"id":5995}],"tv":65.48}]}
{"op":"mcm","clk":"11849204418","pt":1723297010460,"mc":[{"id":"1.231581624","rc":[{"batb":[[0,2.32,31.65],[1,1.3,1000],[2,1.08,7.85]],"ltp":2.42,"tv":19.59,"id":31378},{"batb":[[0,1.69,60.56],[1,1.3,1000],[2,1.08,7.85]],"ltp":1.7,"tv":45.89,"id":5995}]}]}
{"op":"mcm","clk":"11849221315","pt":1723297094364,"mc":[{"id":"1.231581624","rc":[{"batb":[[0,2.34,10],[1,2.32,31.65],[2,1.3,1000]],"ltp":2.42,"tv":19.59,"id":31378},{"batb":[[0,1.7,10],[1,1.69,60.56],[2,1.3,1000]],"ltp":1.7,"tv":45.89,"id":5995}]}]}
{"op":"mcm","clk":"11849222029","pt":1723297097839,"mc":[{"id":"1.231581624","rc":[{"batb":[[0,2.32,31.65],[1,1.3,1000],[2,1.08,7.85]],"ltp":2.42,"tv":19.59,"id":31378},{"batb":[[0,1.69,60.56],[1,1.3,1000],[2,1.08,7.85]],"ltp":1.7,"tv":45.89,"id":5995}]}]}
{"op":"mcm","clk":"11849227385","pt":1723297125372,"mc":[{"id":"1.231581624","rc":[{"batb":[[0,2.34,10],[1,2.32,31.65],[2,1.3,1000]],"ltp":2.42,"tv":19.59,"id":31378},{"batb":[[0,1.7,10],[1,1.69,60.56],[2,1.3,1000]],"ltp":1.7,"tv":45.89,"id":5995}]}]}
{"op":"mcm","clk":"11849228158","pt":1723297129368,"mc":[{"id":"1.231581624","rc":[{"batb":[[0,2.32,31.65],[1,1.3,1000],[2,1.08,7.85]],"ltp":2.42,"tv":19.59,"id":31378},{"batb":[[0,1.69,60.56],[1,1.3,1000],[2,1.08,7.85]],"ltp":1.7,"tv":45.89,"id":5995}]}]}
{"op":"mcm","clk":"11849228847","pt":1723297132873,"mc":[{"id":"1.231581624","rc":[{"batb":[[0,2.34,10],[1,2.32,31.65],[2,1.3,1000]],"ltp":2.42,"tv":19.59,"id":31378},{"batb":[[0,1.7,10],[1,1.69,60.56],[2,1.3,1000]],"ltp":1.7,"tv":45.89,"id":5995}]}]}
{"op":"mcm","clk":"11849230466","pt":1723297141395,"mc":[{"id":"1.231581624","rc":[{"batb":[[0,2.32,31.65],[1,1.3,1000],[2,1.08,7.85]],"ltp":2.42,"tv":19.59,"id":31378},{"batb":[[0,1.69,60.56],[1,1.3,1000],[2,1.08,7.85]],"ltp":1.7,"tv":45.89,"id":5995}]}]}
{"op":"mcm","clk":"11849231070","pt":1723297144800,"mc":[{"id":"1.231581624","rc":[{"batb":[[0,2.34,10],[1,2.32,31.65],[2,1.3,1000]],"ltp":2.42,"tv":19.59,"id":31378},{"batb":[[0,1.7,10],[1,1.69,60.56],[2,1.3,1000]],"ltp":1.7,"tv":45.89,"id":5995}]}]}
{"op":"mcm","clk":"11849232141","pt":1723297150404,"mc":[{"id":"1.231581624","rc":[{"batb":[[0,2.32,31.65],[1,1.3,1000],[2,1.08,7.85]],"ltp":2.42,"tv":19.59,"id":31378},{"batb":[[0,1.69,60.56],[1,1.3,1000],[2,1.08,7.85]],"ltp":1.7,"tv":45.89,"id":5995}]}]}
{"op":"mcm","clk":"11849232580","pt":1723297152719,"mc":[{"id":"1.231581624","rc":[{"batb":[[0,2.34,10],[1,2.32,31.65],[2,1.3,1000]],"ltp":2.42,"tv":19.59,"id":31378},{"batb":[[0,1.7,10],[1,1.69,60.56],[2,1.3,1000]],"ltp":1.7,"tv":45.89,"id":5995}]}]}
{"op":"mcm","clk":"11849233491","pt":1723297157648,"mc":[{"id":"1.231581624","rc":[{"batb":[[0,2.32,31.65],[1,1.3,1000],[2,1.08,7.85]],"ltp":2.42,"tv":19.59,"id":31378},{"batb":[[0,1.69,60.56],[1,1.3,1000],[2,1.08,7.85]],"ltp":1.7,"tv":45.89,"id":5995}]}]}
{"op":"mcm","clk":"11849235956","pt":1723297169637,"mc":[{"id":"1.231581624","rc":[{"batb":[[0,2.34,10],[1,2.32,31.65],[2,1.3,1000]],"ltp":2.42,"tv":19.59,"id":31378},{"batb":[[0,1.7,10],[1,1.69,60.56],[2,1.3,1000]],"ltp":1.7,"tv":45.89,"id":5995}]}]}
{"op":"mcm","clk":"11849237259","pt":1723297176654,"mc":[{"id":"1.231581624","rc":[{"batb":[[0,2.32,31.65],[1,1.3,1000],[2,1.08,7.85]],"ltp":2.42,"tv":19.59,"id":31378},{"batb":[[0,1.69,60.56],[1,1.3,1000],[2,1.08,7.85]],"ltp":1.7,"tv":45.89,"id":5995}]}]}
{"op":"mcm","clk":"11849238241","pt":1723297182036,"mc":[{"id":"1.231581624","rc":[{"batb":[[0,2.34,10],[1,2.32,31.65],[2,1.3,1000]],"ltp":2.42,"tv":19.59,"id":31378},{"batb":[[0,1.7,10],[1,1.69,60.56],[2,1.3,1000]],"ltp":1.7,"tv":45.89,"id":5995}]}]}
{"op":"mcm","clk":"11849239601","pt":1723297189343,"mc":[{"id":"1.231581624","rc":[{"batb":[[0,2.32,31.65],[1,1.3,1000],[2,1.08,7.85]],"ltp":2.42,"tv":19.59,"id":31378},{"batb":[[0,1.69,60.56],[1,1.3,1000],[2,1.08,7.85]],"ltp":1.7,"tv":45.89,"id":5995}]}]}
{"op":"mcm","clk":"11849312921","pt":1723297588746,"mc":[{"id":"1.231581624","rc":[{"batb":[[0,2.34,10],[1,2.32,31.65],[2,1.3,1000]],"ltp":2.42,"tv":19.59,"id":31378},{"batb":[[0,1.7,10],[1,1.69,60.56],[2,1.3,1000]],"ltp":1.7,"tv":45.89,"id":5995}]}]}
{"op":"mcm","clk":"11849315292","pt":1723297602159,"mc":[{"id":"1.231581624","rc":[{"batb":[[0,2.32,31.65],[1,1.3,1000],[2,1.08,7.85]],"ltp":2.42,"tv":19.59,"id":31378},{"batb":[[0,1.69,60.56],[1,1.3,1000],[2,1.08,7.85]],"ltp":1.7,"tv":45.89,"id":5995}]}]}
{"op":"mcm","clk":"11849317037","pt":1723297612264,"mc":[{"id":"1.231581624","rc":[{"batb":[[0,2.34,10],[1,2.32,31.65],[2,1.3,1000]],"ltp":2.42,"tv":19.59,"id":31378},{"batb":[[0,1.7,10],[1,1.69,60.56],[2,1.3,1000]],"ltp":1.7,"tv":45.89,"id":5995}]}]}
{"op":"mcm","clk":"11849318895","pt":1723297623382,"mc":[{"id":"1.231581624","rc":[{"batb":[[0,2.32,31.65],[1,1.3,1000],[2,1.08,7.85]],"ltp":2.42,"tv":19.59,"id":31378},{"batb":[[0,1.69,60.56],[1,1.3,1000],[2,1.08,7.85]],"ltp":1.7,"tv":45.89,"id":5995}]}]}
{"op":"mcm","clk":"11849319982","pt":1723297629687,"mc":[{"id":"1.231581624","rc":[{"batb":[[0,2.34,10],[1,2.32,31.65],[2,1.3,1000]],"ltp":2.42,"tv":19.59,"id":31378},{"batb":[[0,1.7,10],[1,1.69,60.56],[2,1.3,1000]],"ltp":1.7,"tv":45.89,"id":5995}]}]}
{"op":"mcm","clk":"11849321671","pt":1723297638688,"mc":[{"id":"1.231581624","rc":[{"batb":[[0,2.32,31.65],[1,1.3,1000],[2,1.08,7.85]],"ltp":2.42,"tv":19.59,"id":31378},{"batb":[[0,1.69,60.56],[1,1.3,1000],[2,1.08,7.85]],"ltp":1.7,"tv":45.89,"id":5995}]}]}
{"op":"mcm","clk":"11849322792","pt":1723297644297,"mc":[{"id":"1.231581624","rc":[{"batb":[[0,2.34,10],[1,2.32,31.65],[2,1.3,1000]],"ltp":2.42,"tv":19.59,"id":31378},{"batb":[[0,1.7,10],[1,1.69,60.56],[2,1.3,1000]],"ltp":1.7,"tv":45.89,"id":5995}]}]}
{"op":"mcm","clk":"11849324203","pt":1723297652236,"mc":[{"id":"1.231581624","rc":[{"batb":[[0,2.32,31.65],[1,1.3,1000],[2,1.08,7.85]],"ltp":2.42,"tv":19.59,"id":31378},{"batb":[[0,1.69,60.56],[1,1.3,1000],[2,1.08,7.85]],"ltp":1.7,"tv":45.89,"id":5995}]}]}
{"op":"mcm","clk":"11849324872","pt":1723297656620,"mc":[{"id":"1.231581624","rc":[{"batb":[[0,2.34,10],[1,2.32,31.65],[2,1.3,1000]],"ltp":2.42,"tv":19.59,"id":31378},{"batb":[[0,1.7,10],[1,1.69,60.56],[2,1.3,1000]],"ltp":1.7,"tv":45.89,"id":5995}]}]}
{"op":"mcm","clk":"11849325998","pt":1723297663508,"mc":[{"id":"1.231581624","rc":[{"batb":[[0,2.32,31.65],[1,1.3,1000],[2,1.08,7.85]],"ltp":2.42,"tv":19.59,"id":31378}]}]}
{"op":"mcm","clk":"11849326017","pt":1723297663615,"mc":[{"id":"1.231581624","rc":[{"batb":[[0,1.69,60.56],[1,1.3,1000],[2,1.08,7.85]],"ltp":1.7,"tv":45.89,"id":5995}]}]}
{"op":"mcm","clk":"11849326531","pt":1723297666725,"mc":[{"id":"1.231581624","rc":[{"batb":[[0,2.34,10],[1,2.32,31.65],[2,1.3,1000]],"ltp":2.42,"tv":19.59,"id":31378},{"batb":[[0,1.71,10],[1,1.69,60.56],[2,1.3,1000]],"ltp":1.7,"tv":45.89,"id":5995}]}]}
{"op":"mcm","clk":"11849327582","pt":1723297673930,"mc":[{"id":"1.231581624","rc":[{"batb":[[0,2.32,31.65],[1,1.3,1000],[2,1.08,7.85]],"ltp":2.42,"tv":19.59,"id":31378},{"batb":[[0,1.69,60.56],[1,1.3,1000],[2,1.08,7.85]],"ltp":1.7,"tv":45.89,"id":5995}]}]}
{"op":"mcm","clk":"11849328163","pt":1723297677734,"mc":[{"id":"1.231581624","rc":[{"batb":[[0,2.34,10],[1,2.32,31.65],[2,1.3,1000]],"ltp":2.42,"tv":19.59,"id":31378},{"batb":[[0,1.7,10],[1,1.69,60.56],[2,1.3,1000]],"ltp":1.7,"tv":45.89,"id":5995}]}]}
{"op":"mcm","clk":"11849329211","pt":1723297684144,"mc":[{"id":"1.231581624","rc":[{"batb":[[0,2.32,31.65],[1,1.3,1000],[2,1.08,7.85]],"ltp":2.42,"tv":19.59,"id":31378},{"batb":[[0,1.69,60.56],[1,1.3,1000],[2,1.08,7.85]],"ltp":1.7,"tv":45.89,"id":5995}]}]}
{"op":"mcm","clk":"11849443805","pt":1723298419112,"mc":[{"id":"1.231581624","rc":[{"batb":[[0,2.34,10],[1,2.32,31.65],[2,1.3,1000]],"ltp":2.42,"tv":19.59,"id":31378},{"batb":[[0,1.7,10],[1,1.69,60.56],[2,1.3,1000]],"ltp":1.7,"tv":45.89,"id":5995}]}]}
{"op":"mcm","clk":"11849445192","pt":1723298426006,"mc":[{"id":"1.231581624","rc":[{"batb":[[0,2.32,31.65],[1,1.3,1000],[2,1.08,7.85]],"ltp":2.42,"tv":19.59,"id":31378},{"batb":[[0,1.69,60.56],[1,1.3,1000],[2,1.08,7.85]],"ltp":1.7,"tv":45.89,"id":5995}]}]}
{"op":"mcm","clk":"11849446415","pt":1723298432342,"mc":[{"id":"1.231581624","rc":[{"batb":[[0,2.34,10],[1,2.32,31.65],[2,1.3,1000]],"ltp":2.42,"tv":19.59,"id":31378},{"batb":[[0,1.7,10],[1,1.69,60.56],[2,1.3,1000]],"ltp":1.7,"tv":45.89,"id":5995}]}]}
{"op":"mcm","clk":"11849447970","pt":1723298441813,"mc":[{"id":"1.231581624","rc":[{"batb":[[0,2.32,31.65],[1,1.3,1000],[2,1.08,7.85]],"ltp":2.42,"tv":19.59,"id":31378},{"batb":[[0,1.69,60.56],[1,1.3,1000],[2,1.08,7.85]],"ltp":1.7,"tv":45.89,"id":5995}]}]}
{"op":"mcm","clk":"11849448857","pt":1723298447312,"mc":[{"id":"1.231581624","rc":[{"batb":[[0,2.34,10],[1,2.32,31.65],[2,1.3,1000]],"ltp":2.42,"tv":19.59,"id":31378},{"batb":[[0,1.7,10],[1,1.69,60.56],[2,1.3,1000]],"ltp":1.7,"tv":45.89,"id":5995}]}]}
{"op":"mcm","clk":"11849451001","pt":1723298459643,"mc":[{"id":"1.231581624","rc":[{"batb":[[0,2.32,31.65],[1,1.3,1000],[2,1.08,7.85]],"ltp":2.42,"tv":19.59,"id":31378},{"batb":[[0,1.69,60.56],[1,1.3,1000],[2,1.08,7.85]],"ltp":1.7,"tv":45.89,"id":5995}]}]}
{"op":"mcm","clk":"11849452536","pt":1723298467244,"mc":[{"id":"1.231581624","rc":[{"batb":[[0,2.34,10],[1,2.32,31.65],[2,1.3,1000]],"ltp":2.42,"tv":19.59,"id":31378},{"batb":[[0,1.7,10],[1,1.69,60.56],[2,1.3,1000]],"ltp":1.7,"tv":45.89,"id":5995}]}]}
{"op":"mcm","clk":"11849454371","pt":1723298476861,"mc":[{"id":"1.231581624","rc":[{"batb":[[0,2.32,31.65],[1,1.3,1000],[2,1.08,7.85]],"ltp":2.42,"tv":19.59,"id":31378},{"batb":[[0,1.69,60.56],[1,1.3,1000],[2,1.08,7.85]],"ltp":1.7,"tv":45.89,"id":5995}]}]}
{"op":"mcm","clk":"11849455280","pt":1723298481357,"mc":[{"id":"1.231581624","rc":[{"batb":[[0,2.34,10],[1,2.32,31.65],[2,1.3,1000]],"ltp":2.42,"tv":19.59,"id":31378},{"batb":[[0,1.7,10],[1,1.69,60.56],[2,1.3,1000]],"ltp":1.7,"tv":45.89,"id":5995}]}]}
{"op":"mcm","clk":"11849456857","pt":1723298489629,"mc":[{"id":"1.231581624","rc":[{"batb":[[0,2.32,31.65],[1,1.3,1000],[2,1.08,7.85]],"ltp":2.42,"tv":19.59,"id":31378},{"batb":[[0,1.69,60.56],[1,1.3,1000],[2,1.08,7.85]],"ltp":1.7,"tv":45.89,"id":5995}]}]}
{"op":"mcm","clk":"11849457546","pt":1723298493018,"mc":[{"id":"1.231581624","rc":[{"batb":[[0,2.34,10],[1,2.32,31.65],[2,1.3,1000]],"ltp":2.42,"tv":19.59,"id":31378},{"batb":[[0,1.7,10],[1,1.69,60.56],[2,1.3,1000]],"ltp":1.7,"tv":45.89,"id":5995}]}]}
{"op":"mcm","clk":"11849458706","pt":1723298498617,"mc":[{"id":"1.231581624","rc":[{"batb":[[0,2.32,31.65],[1,1.3,1000],[2,1.08,7.85]],"ltp":2.42,"tv":19.59,"id":31378},{"batb":[[0,1.69,60.56],[1,1.3,1000],[2,1.08,7.85]],"ltp":1.7,"tv":45.89,"id":5995}]}]}
{"op":"mcm","clk":"11849459490","pt":1723298502383,"mc":[{"id":"1.231581624","rc":[{"batb":[[0,2.34,10],[1,2.32,31.65],[2,1.3,1000]],"ltp":2.42,"tv":19.59,"id":31378},{"batb":[[0,1.7,10],[1,1.69,60.56],[2,1.3,1000]],"ltp":1.7,"tv":45.89,"id":5995}]}]}
{"op":"mcm","clk":"11849460978","pt":1723298510172,"mc":[{"id":"1.231581624","rc":[{"batb":[[0,2.32,31.65],[1,1.3,1000],[2,1.08,7.85]],"ltp":2.42,"tv":19.59,"id":31378},{"batb":[[0,1.69,60.56],[1,1.3,1000],[2,1.08,7.85]],"ltp":1.7,"tv":45.89,"id":5995}]}]}
{"op":"mcm","clk":"11849461432","pt":1723298512684,"mc":[{"id":"1.231581624","rc":[{"batb":[[0,2.34,10],[1,2.32,31.65],[2,1.3,1000]],"ltp":2.42,"tv":19.59,"id":31378},{"batb":[[0,1.71,10],[1,1.69,60.56],[2,1.3,1000]],"ltp":1.7,"tv":45.89,"id":5995}]}]}
{"op":"mcm","clk":"11849462470","pt":1723298517713,"mc":[{"id":"1.231581624","rc":[{"batb":[[0,2.32,31.65],[1,1.3,1000],[2,1.08,7.85]],"ltp":2.42,"tv":19.59,"id":31378},{"batb":[[0,1.69,60.56],[1,1.3,1000],[2,1.08,7.85]],"ltp":1.7,"tv":45.89,"id":5995}]}]}
{"op":"mcm","clk":"11849467170","pt":1723298539216,"mc":[{"id":"1.231581624","rc":[{"batb":[[0,2.34,10],[1,2.32,31.65],[2,1.3,1000]],"ltp":2.42,"tv":19.59,"id":31378},{"batb":[[0,1.7,10],[1,1.69,60.56],[2,1.3,1000]],"ltp":1.7,"tv":45.89,"id":5995}]}]}
{"op":"mcm","clk":"11849468471","pt":1723298544736,"mc":[{"id":"1.231581624","rc":[{"batb":[[0,2.32,31.65],[1,1.3,1000],[2,1.08,7.85]],"ltp":2.42,"tv":19.59,"id":31378},{"batb":[[0,1.69,60.56],[1,1.3,1000],[2,1.08,7.85]],"ltp":1.7,"tv":45.89,"id":5995}]}]}
{"op":"mcm","clk":"11849473607","pt":1723298566589,"mc":[{"id":"1.231581624","rc":[{"batb":[[0,2.34,10],[1,2.32,31.65],[2,1.3,1000]],"ltp":2.42,"tv":19.59,"id":31378},{"batb":[[0,1.7,10],[1,1.69,60.56],[2,1.3,1000]],"ltp":1.7,"tv":45.89,"id":5995}]}]}
{"op":"mcm","clk":"11849474451","pt":1723298570254,"mc":[{"id":"1.231581624","rc":[{"batb":[[0,2.32,31.65],[1,1.3,1000],[2,1.08,7.85]],"ltp":2.42,"tv":19.59,"id":31378},{"batb":[[0,1.69,60.56],[1,1.3,1000],[2,1.08,7.85]],"ltp":1.7,"tv":45.89,"id":5995}]}]}
{"op":"mcm","clk":"11849477355","pt":1723298582594,"mc":[{"id":"1.231581624","rc":[{"batb":[[0,2.34,10],[1,2.32,31.65],[2,1.3,1000]],"ltp":2.42,"tv":19.59,"id":31378},{"batb":[[0,1.7,10],[1,1.69,60.56],[2,1.3,1000]],"ltp":1.7,"tv":45.89,"id":5995}]}]}
{"op":"mcm","clk":"11849478185","pt":1723298586290,"mc":[{"id":"1.231581624","rc":[{"batb":[[0,2.32,31.65],[1,1.3,1000],[2,1.08,7.85]],"ltp":2.42,"tv":19.59,"id":31378},{"batb":[[0,1.69,60.56],[1,1.3,1000],[2,1.08,7.85]],"ltp":1.7,"tv":45.89,"id":5995}]}]}
{"op":"mcm","clk":"11849486305","pt":1723298621903,"mc":[{"id":"1.231581624","rc":[{"batb":[[0,2.34,10],[1,2.32,31.65],[2,1.3,1000]],"ltp":2.42,"tv":19.59,"id":31378},{"batb":[[0,1.7,10],[1,1.69,60.56],[2,1.3,1000]],"ltp":1.7,"tv":45.89,"id":5995}]}]}
{"op":"mcm","clk":"11849487136","pt":1723298625412,"mc":[{"id":"1.231581624","rc":[{"batb":[[0,2.32,31.65],[1,1.3,1000],[2,1.08,7.85]],"ltp":2.42,"tv":19.59,"id":31378},{"batb":[[0,1.69,60.56],[1,1.3,1000],[2,1.08,7.85]],"ltp":1.7,"tv":45.89,"id":5995}]}]}
{"op":"mcm","clk":"11849495992","pt":1723298665347,"mc":[{"id":"1.231581624","rc":[{"batb":[[0,2.34,10],[1,2.32,31.65],[2,1.3,1000]],"ltp":2.42,"tv":19.59,"id":31378},{"batb":[[0,1.7,10],[1,1.69,60.56],[2,1.3,1000]],"ltp":1.7,"tv":45.89,"id":5995}]}]}
{"op":"mcm","clk":"11849496972","pt":1723298670037,"mc":[{"id":"1.231581624","rc":[{"batb":[[0,2.32,31.65],[1,1.3,1000],[2,1.08,7.85]],"ltp":2.42,"tv":19.59,"id":31378},{"batb":[[0,1.69,60.56],[1,1.3,1000],[2,1.08,7.85]],"ltp":1.7,"tv":45.89,"id":5995}]}]}
{"op":"mcm","clk":"11849511971","pt":1723298733758,"mc":[{"id":"1.231581624","rc":[{"batb":[[0,2.34,10],[1,2.32,31.65],[2,1.3,1000]],"ltp":2.42,"tv":19.59,"id":31378},{"batb":[[0,1.7,10],[1,1.69,60.56],[2,1.3,1000]],"ltp":1.7,"tv":45.89,"id":5995}]}]}
{"op":"mcm","clk":"11849512907","pt":1723298737629,"mc":[{"id":"1.231581624","rc":[{"batb":[[0,2.32,31.65],[1,1.3,1000],[2,1.08,7.85]],"ltp":2.42,"tv":19.59,"id":31378},{"batb":[[0,1.69,60.56],[1,1.3,1000],[2,1.08,7.85]],"ltp":1.7,"tv":45.89,"id":5995}]}]}
{"op":"mcm","clk":"11849518677","pt":1723298760039,"mc":[{"id":"1.231581624","rc":[{"batb":[[0,2.34,10],[1,2.32,31.65],[2,1.3,1000]],"ltp":2.42,"tv":19.59,"id":31378},{"batb":[[0,1.7,10],[1,1.69,60.56],[2,1.3,1000]],"ltp":1.7,"tv":45.89,"id":5995}]}]}
{"op":"mcm","clk":"11849519594","pt":1723298763576,"mc":[{"id":"1.231581624","rc":[{"batb":[[0,2.32,31.65],[1,1.3,1000],[2,1.08,7.85]],"ltp":2.42,"tv":19.59,"id":31378},{"batb":[[0,1.69,60.56],[1,1.3,1000],[2,1.08,7.85]],"ltp":1.7,"tv":45.89,"id":5995}]}]}
{"op":"mcm","clk":"11849523342","pt":1723298778188,"mc":[{"id":"1.231581624","rc":[{"batb":[[0,2.34,10],[1,2.32,31.65],[2,1.3,1000]],"ltp":2.42,"tv":19.59,"id":31378},{"batb":[[0,1.7,10],[1,1.69,60.56],[2,1.3,1000]],"ltp":1.7,"tv":45.89,"id":5995}]}]}
{"op":"mcm","clk":"11849524247","pt":1723298781772,"mc":[{"id":"1.231581624","rc":[{"batb":[[0,2.32,31.65],[1,1.3,1000],[2,1.08,7.85]],"ltp":2.42,"tv":19.59,"id":31378},{"batb":[[0,1.69,60.56],[1,1.3,1000],[2,1.08,7.85]],"ltp":1.7,"tv":45.89,"id":5995}]}]}
{"op":"mcm","clk":"11849533260","pt":1723298817027,"mc":[{"id":"1.231581624","rc":[{"batb":[[0,2.34,10],[1,2.32,31.65],[2,1.3,1000]],"ltp":2.42,"tv":19.59,"id":31378},{"batb":[[0,1.7,10],[1,1.69,60.56],[2,1.3,1000]],"ltp":1.7,"tv":45.89,"id":5995}]}]}
{"op":"mcm","clk":"11849534234","pt":1723298820816,"mc":[{"id":"1.231581624","rc":[{"batb":[[0,2.32,31.65],[1,1.3,1000],[2,1.08,7.85]],"ltp":2.42,"tv":19.59,"id":31378},{"batb":[[0,1.69,60.56],[1,1.3,1000],[2,1.08,7.85]],"ltp":1.7,"tv":45.89,"id":5995}]}]}
{"op":"mcm","clk":"11849545091","pt":1723298860083,"mc":[{"id":"1.231581624","rc":[{"batb":[[0,2.34,10],[1,2.32,31.65],[2,1.3,1000]],"ltp":2.42,"tv":19.59,"id":31378},{"batb":[[0,1.7,10],[1,1.69,60.56],[2,1.3,1000]],"ltp":1.7,"tv":45.89,"id":5995}]}]}
{"op":"mcm","clk":"11849546568","pt":1723298864802,"mc":[{"id":"1.231581624","rc":[{"batb":[[0,2.32,31.65],[1,1.3,1000],[2,1.08,7.85]],"ltp":2.42,"tv":19.59,"id":31378},{"batb":[[0,1.69,60.56],[1,1.3,1000],[2,1.08,7.85]],"ltp":1.7,"tv":45.89,"id":5995}]}]}
{"op":"mcm","clk":"11849567955","pt":1723298940778,"mc":[{"id":"1.231581624","rc":[{"batb":[[0,2.34,10],[1,2.32,31.65],[2,1.3,1000]],"ltp":2.42,"tv":19.59,"id":31378},{"batb":[[0,1.7,10],[1,1.69,60.56],[2,1.3,1000]],"ltp":1.7,"tv":45.89,"id":5995}]}]}
{"op":"mcm","clk":"11849568949","pt":1723298944260,"mc":[{"id":"1.231581624","rc":[{"batb":[[0,2.32,31.65],[1,1.3,1000],[2,1.08,7.85]],"ltp":2.42,"tv":19.59,"id":31378},{"batb":[[0,1.69,60.56],[1,1.3,1000],[2,1.08,7.85]],"ltp":1.7,"tv":45.89,"id":5995}]}]}
{"op":"mcm","clk":"11849579544","pt":1723298980896,"mc":[{"id":"1.231581624","rc":[{"batb":[[0,2.34,10],[1,2.32,31.65],[2,1.3,1000]],"ltp":2.42,"tv":19.59,"id":31378},{"batb":[[0,1.7,10],[1,1.69,60.56],[2,1.3,1000]],"ltp":1.7,"tv":45.89,"id":5995}]}]}
{"op":"mcm","clk":"11849580821","pt":1723298985406,"mc":[{"id":"1.231581624","rc":[{"batb":[[0,2.32,31.65],[1,1.3,1000],[2,1.08,7.85]],"ltp":2.42,"tv":19.59,"id":31378},{"batb":[[0,1.69,60.56],[1,1.3,1000],[2,1.08,7.85]],"ltp":1.7,"tv":45.89,"id":5995}]}]}
{"op":"mcm","clk":"11849659384","pt":1723299206569,"mc":[{"id":"1.231581624","rc":[{"batb":[[0,2.34,10],[1,2.32,31.65],[2,1.3,1000]],"ltp":2.42,"tv":19.59,"id":31378},{"batb":[[0,1.7,10],[1,1.69,60.56],[2,1.3,1000]],"ltp":1.7,"tv":45.89,"id":5995}]}]}
{"op":"mcm","clk":"11849660360","pt":1723299209970,"mc":[{"id":"1.231581624","rc":[{"batb":[[0,2.32,31.65],[1,1.3,1000],[2,1.08,7.85]],"ltp":2.42,"tv":19.59,"id":31378},{"batb":[[0,1.69,60.56],[1,1.3,1000],[2,1.08,7.85]],"ltp":1.7,"tv":45.89,"id":5995}]}]}
{"op":"mcm","clk":"11849698974","pt":1723299344224,"mc":[{"id":"1.231581624","rc":[{"batb":[[0,2.34,10],[1,2.32,31.65],[2,1.3,1000]],"ltp":2.42,"tv":19.59,"id":31378},{"batb":[[0,1.7,10],[1,1.69,60.56],[2,1.3,1000]],"ltp":1.7,"tv":45.89,"id":5995}]}]}
{"op":"mcm","clk":"11849700230","pt":1723299348926,"mc":[{"id":"1.231581624","rc":[{"batb":[[0,2.32,31.65],[1,1.3,1000],[2,1.08,7.85]],"ltp":2.42,"tv":19.59,"id":31378},{"batb":[[0,1.69,60.56],[1,1.3,1000],[2,1.08,7.85]],"ltp":1.7,"tv":45.89,"id":5995}]}]}
{"op":"mcm","clk":"11849721157","pt":1723299420639,"mc":[{"id":"1.231581624","rc":[{"batb":[[0,2.34,10],[1,2.32,31.65],[2,1.3,1000]],"ltp":2.42,"tv":19.59,"id":31378},{"batb":[[0,1.7,10],[1,1.69,60.56],[2,1.3,1000]],"ltp":1.7,"tv":45.89,"id":5995}]}]}
{"op":"mcm","clk":"11849722147","pt":1723299424152,"mc":[{"id":"1.231581624","rc":[{"batb":[[0,2.32,31.65],[1,1.3,1000],[2,1.08,7.85]],"ltp":2.42,"tv":19.59,"id":31378},{"batb":[[0,1.69,60.56],[1,1.3,1000],[2,1.08,7.85]],"ltp":1.7,"tv":45.89,"id":5995}]}]}
{"op":"mcm","clk":"11849745546","pt":1723299505253,"mc":[{"id":"1.231581624","rc":[{"batb":[[0,2.34,10],[1,2.32,31.65],[2,1.3,1000]],"ltp":2.42,"tv":19.59,"id":31378},{"batb":[[0,1.7,10],[1,1.69,60.56],[2,1.3,1000]],"ltp":1.7,"tv":45.89,"id":5995}]}]}
{"op":"mcm","clk":"11849746641","pt":1723299509049,"mc":[{"id":"1.231581624","rc":[{"batb":[[0,2.32,31.65],[1,1.3,1000],[2,1.08,7.85]],"ltp":2.42,"tv":19.59,"id":31378},{"batb":[[0,1.69,60.56],[1,1.3,1000],[2,1.08,7.85]],"ltp":1.7,"tv":45.89,"id":5995}]}]}
{"op":"mcm","clk":"11849756920","pt":1723299546584,"mc":[{"id":"1.231581624","rc":[{"batb":[[0,2.34,10],[1,2.32,31.65],[2,1.3,1000]],"ltp":2.42,"tv":19.59,"id":31378},{"batb":[[0,1.7,10],[1,1.69,60.56],[2,1.3,1000]],"ltp":1.7,"tv":45.89,"id":5995}]}]}
{"op":"mcm","clk":"11849758050","pt":1723299550287,"mc":[{"id":"1.231581624","rc":[{"batb":[[0,2.32,31.65],[1,1.3,1000],[2,1.08,7.85]],"ltp":2.42,"tv":19.59,"id":31378},{"batb":[[0,1.69,60.56],[1,1.3,1000],[2,1.08,7.85]],"ltp":1.7,"tv":45.89,"id":5995}]}]}
{"op":"mcm","clk":"11849768744","pt":1723299588928,"mc":[{"id":"1.231581624","rc":[{"batb":[[0,2.34,10],[1,2.32,31.65],[2,1.3,1000]],"ltp":2.42,"tv":19.59,"id":31378},{"batb":[[0,1.7,10],[1,1.69,60.56],[2,1.3,1000]],"ltp":1.7,"tv":45.89,"id":5995}]}]}
{"op":"mcm","clk":"11849770050","pt":1723299593622,"mc":[{"id":"1.231581624","rc":[{"batb":[[0,2.32,31.65],[1,1.3,1000],[2,1.08,7.85]],"ltp":2.42,"tv":19.59,"id":31378},{"batb":[[0,1.69,60.56],[1,1.3,1000],[2,1.08,7.85]],"ltp":1.7,"tv":45.89,"id":5995}]}]}
{"op":"mcm","clk":"11849780711","pt":1723299631032,"mc":[{"id":"1.231581624","rc":[{"batb":[[0,2.34,10],[1,2.32,31.65],[2,1.3,1000]],"ltp":2.42,"tv":19.59,"id":31378},{"batb":[[0,1.7,10],[1,1.69,60.56],[2,1.3,1000]],"ltp":1.7,"tv":45.89,"id":5995}]}]}
{"op":"mcm","clk":"11849781783","pt":1723299634733,"mc":[{"id":"1.231581624","rc":[{"batb":[[0,2.32,31.65],[1,1.3,1000],[2,1.08,7.85]],"ltp":2.42,"tv":19.59,"id":31378},{"batb":[[0,1.69,60.56],[1,1.3,1000],[2,1.08,7.85]],"ltp":1.7,"tv":45.89,"id":5995}]}]}
{"op":"mcm","clk":"11849802161","pt":1723299708167,"mc":[{"id":"1.231581624","rc":[{"batb":[[0,2.34,10],[1,2.32,29.57],[2,1.3,1000]],"ltp":2.42,"tv":19.59,"id":31378},{"batb":[[0,1.7,10],[1,1.69,56.58],[2,1.3,1000]],"ltp":1.7,"tv":45.89,"id":5995}]}]}
{"op":"mcm","clk":"11849803172","pt":1723299711560,"mc":[{"id":"1.231581624","rc":[{"batb":[[0,2.32,29.57],[1,1.3,1000],[2,1.08,7.85]],"ltp":2.42,"tv":19.59,"id":31378},{"batb":[[0,1.69,56.58],[1,1.3,1000],[2,1.08,7.85]],"ltp":1.7,"tv":45.89,"id":5995}]}]}
{"op":"mcm","clk":"11849814432","pt":1723299752025,"mc":[{"id":"1.231581624","rc":[{"batb":[[0,2.34,10],[1,2.32,29.57],[2,1.3,1000]],"ltp":2.42,"tv":19.59,"id":31378},{"batb":[[0,1.7,10],[1,1.69,56.58],[2,1.3,1000]],"ltp":1.7,"tv":45.89,"id":5995}]}]}
{"op":"mcm","clk":"11849815415","pt":1723299755484,"mc":[{"id":"1.231581624","rc":[{"batb":[[0,2.32,29.57],[1,1.3,1000],[2,1.08,7.85]],"ltp":2.42,"tv":19.59,"id":31378},{"batb":[[0,1.69,56.58],[1,1.3,1000],[2,1.08,7.85]],"ltp":1.7,"tv":45.89,"id":5995}]}]}
{"op":"mcm","clk":"11849826034","pt":1723299793833,"mc":[{"id":"1.231581624","rc":[{"batb":[[0,2.34,10],[1,2.32,29.57],[2,1.3,1000]],"ltp":2.42,"tv":19.59,"id":31378},{"batb":[[0,1.7,10],[1,1.69,56.58],[2,1.3,1000]],"ltp":1.7,"tv":45.89,"id":5995}]}]}
{"op":"mcm","clk":"11849826947","pt":1723299797248,"mc":[{"id":"1.231581624","rc":[{"batb":[[0,2.32,29.57],[1,1.3,1000],[2,1.08,7.85]],"ltp":2.42,"tv":19.59,"id":31378},{"batb":[[0,1.69,56.58],[1,1.3,1000],[2,1.08,7.85]],"ltp":1.7,"tv":45.89,"id":5995}]}]}
{"op":"mcm","clk":"11849838072","pt":1723299836899,"mc":[{"id":"1.231581624","rc":[{"batb":[[0,2.34,10],[1,2.32,29.57],[2,1.3,1000]],"ltp":2.42,"tv":19.59,"id":31378},{"batb":[[0,1.7,10],[1,1.69,56.58],[2,1.3,1000]],"ltp":1.7,"tv":45.89,"id":5995}]}]}
{"op":"mcm","clk":"11849839310","pt":1723299841094,"mc":[{"id":"1.231581624","rc":[{"batb":[[0,2.32,29.57],[1,1.3,1000],[2,1.08,7.85]],"ltp":2.42,"tv":19.59,"id":31378},{"batb":[[0,1.69,56.58],[1,1.3,1000],[2,1.08,7.85]],"ltp":1.7,"tv":45.89,"id":5995}]}]}
{"op":"mcm","clk":"11849849823","pt":1723299878442,"mc":[{"id":"1.231581624","rc":[{"batb":[[0,2.34,10],[1,2.32,29.57],[2,1.3,1000]],"ltp":2.42,"tv":19.59,"id":31378},{"batb":[[0,1.7,10],[1,1.69,56.58],[2,1.3,1000]],"ltp":1.7,"tv":45.89,"id":5995}]}]}
{"op":"mcm","clk":"11849851218","pt":1723299883258,"mc":[{"id":"1.231581624","rc":[{"batb":[[0,2.32,29.57],[1,1.3,1000],[2,1.08,7.85]],"ltp":2.42,"tv":19.59,"id":31378},{"batb":[[0,1.69,56.58],[1,1.3,1000],[2,1.08,7.85]],"ltp":1.7,"tv":45.89,"id":5995}]}]}
{"op":"mcm","clk":"11849875363","pt":1723299970182,"mc":[{"id":"1.231581624","rc":[{"batb":[[0,2.34,10],[1,2.32,29.57],[2,1.3,1000]],"ltp":2.42,"tv":19.59,"id":31378},{"batb":[[0,1.7,10],[1,1.69,56.58],[2,1.3,1000]],"ltp":1.7,"tv":45.89,"id":5995}]}]}
{"op":"mcm","clk":"11849876371","pt":1723299973798,"mc":[{"id":"1.231581624","rc":[{"batb":[[0,2.32,29.57],[1,1.3,1000],[2,1.08,7.85]],"ltp":2.42,"tv":19.59,"id":31378},{"batb":[[0,1.69,56.58],[1,1.3,1000],[2,1.08,7.85]],"ltp":1.7,"tv":45.89,"id":5995}]}]}
{"op":"mcm","clk":"11849886975","pt":1723300012011,"mc":[{"id":"1.231581624","rc":[{"batb":[[0,2.34,10],[1,2.32,29.57],[2,1.3,1000]],"ltp":2.42,"tv":19.59,"id":31378},{"batb":[[0,1.7,10],[1,1.69,56.58],[2,1.3,1000]],"ltp":1.7,"tv":45.89,"id":5995}]}]}
{"op":"mcm","clk":"11849887906","pt":1723300015424,"mc":[{"id":"1.231581624","rc":[{"batb":[[0,2.32,29.57],[1,1.3,1000],[2,1.08,7.85]],"ltp":2.42,"tv":19.59,"id":31378},{"batb":[[0,1.69,56.58],[1,1.3,1000],[2,1.08,7.85]],"ltp":1.7,"tv":45.89,"id":5995}]}]}
{"op":"mcm","clk":"11849898645","pt":1723300054593,"mc":[{"id":"1.231581624","rc":[{"batb":[[0,2.34,10],[1,2.32,29.57],[2,1.3,1000]],"ltp":2.42,"tv":19.59,"id":31378},{"batb":[[0,1.7,10],[1,1.69,56.58],[2,1.3,1000]],"ltp":1.7,"tv":45.89,"id":5995}]}]}
{"op":"mcm","clk":"11849899529","pt":1723300058100,"mc":[{"id":"1.231581624","rc":[{"batb":[[0,2.32,29.57],[1,1.3,1000],[2,1.08,7.85]],"ltp":2.42,"tv":19.59,"id":31378},{"batb":[[0,1.69,56.58],[1,1.3,1000],[2,1.08,7.85]],"ltp":1.7,"tv":45.89,"id":5995}]}]}
{"op":"mcm","clk":"11849910269","pt":1723300097963,"mc":[{"id":"1.231581624","rc":[{"batb":[[0,2.34,10],[1,2.32,29.57],[2,1.3,1000]],"ltp":2.42,"tv":19.59,"id":31378},{"batb":[[0,1.7,10],[1,1.69,56.58],[2,1.3,1000]],"ltp":1.7,"tv":45.89,"id":5995}]}]}
{"op":"mcm","clk":"11849911293","pt":1723300101697,"mc":[{"id":"1.231581624","rc":[{"batb":[[0,2.32,29.57],[1,1.3,1000],[2,1.08,7.85]],"ltp":2.42,"tv":19.59,"id":31378},{"batb":[[0,1.69,56.58],[1,1.3,1000],[2,1.08,7.85]],"ltp":1.7,"tv":45.89,"id":5995}]}]}
{"op":"mcm","clk":"11849922079","pt":1723300139734,"mc":[{"id":"1.231581624","rc":[{"batb":[[0,2.34,10],[1,2.32,29.57],[2,1.3,1000]],"ltp":2.42,"tv":19.59,"id":31378},{"batb":[[0,1.7,10],[1,1.69,56.58],[2,1.3,1000]],"ltp":1.7,"tv":45.89,"id":5995}]}]}
{"op":"mcm","clk":"11849923124","pt":1723300143332,"mc":[{"id":"1.231581624","rc":[{"batb":[[0,2.32,29.57],[1,1.3,1000],[2,1.08,7.85]],"ltp":2.42,"tv":19.59,"id":31378},{"batb":[[0,1.69,56.58],[1,1.3,1000],[2,1.08,7.85]],"ltp":1.7,"tv":45.89,"id":5995}]}]}
{"op":"mcm","clk":"11849934081","pt":1723300182229,"mc":[{"id":"1.231581624","rc":[{"batb":[[0,2.34,10],[1,2.32,29.57],[2,1.3,1000]],"ltp":2.42,"tv":19.59,"id":31378},{"batb":[[0,1.7,10],[1,1.69,56.58],[2,1.3,1000]],"ltp":1.7,"tv":45.89,"id":5995}]}]}
{"op":"mcm","clk":"11849935029","pt":1723300185718,"mc":[{"id":"1.231581624","rc":[{"batb":[[0,2.32,29.57],[1,1.3,1000],[2,1.08,7.85]],"ltp":2.42,"tv":19.59,"id":31378},{"batb":[[0,1.69,56.58],[1,1.3,1000],[2,1.08,7.85]],"ltp":1.7,"tv":45.89,"id":5995}]}]}
{"op":"mcm","clk":"11849946812","pt":1723300225608,"mc":[{"id":"1.231581624","rc":[{"batb":[[0,2.34,10],[1,2.32,29.57],[2,1.3,1000]],"ltp":2.42,"tv":19.59,"id":31378},{"batb":[[0,1.7,10],[1,1.69,56.58],[2,1.3,1000]],"ltp":1.7,"tv":45.89,"id":5995}]}]}
{"op":"mcm","clk":"11849947903","pt":1723300229439,"mc":[{"id":"1.231581624","rc":[{"batb":[[0,2.32,29.57],[1,1.3,1000],[2,1.08,7.85]],"ltp":2.42,"tv":19.59,"id":31378},{"batb":[[0,1.69,56.58],[1,1.3,1000],[2,1.08,7.85]],"ltp":1.7,"tv":45.89,"id":5995}]}]}
{"op":"mcm","clk":"11849969586","pt":1723300306821,"mc":[{"id":"1.231581624","rc":[{"batb":[[0,2.34,10],[1,2.32,29.57],[2,1.3,1000]],"ltp":2.42,"tv":19.59,"id":31378},{"batb":[[0,1.7,10],[1,1.69,56.58],[2,1.3,1000]],"ltp":1.7,"tv":45.89,"id":5995}]}]}
{"op":"mcm","clk":"11849970560","pt":1723300310270,"mc":[{"id":"1.231581624","rc":[{"batb":[[0,2.32,29.57],[1,1.3,1000],[2,1.08,7.85]],"ltp":2.42,"tv":19.59,"id":31378},{"batb":[[0,1.69,56.58],[1,1.3,1000],[2,1.08,7.85]],"ltp":1.7,"tv":45.89,"id":5995}]}]}
{"op":"mcm","clk":"11849981462","pt":1723300349045,"mc":[{"id":"1.231581624","rc":[{"batb":[[0,2.34,10],[1,2.32,29.57],[2,1.3,1000]],"ltp":2.42,"tv":19.59,"id":31378},{"batb":[[0,1.7,10],[1,1.69,56.58],[2,1.3,1000]],"ltp":1.7,"tv":45.89,"id":5995}]}]}
{"op":"mcm","clk":"11849982358","pt":1723300352531,"mc":[{"id":"1.231581624","rc":[{"batb":[[0,2.32,29.57],[1,1.3,1000],[2,1.08,7.85]],"ltp":2.42,"tv":19.59,"id":31378},{"batb":[[0,1.69,56.58],[1,1.3,1000],[2,1.08,7.85]],"ltp":1.7,"tv":45.89,"id":5995}]}]}
{"op":"mcm","clk":"11849992536","pt":1723300391208,"mc":[{"id":"1.231581624","rc":[{"batb":[[0,2.34,10],[1,2.32,29.57],[2,1.3,1000]],"ltp":2.42,"tv":19.59,"id":31378},{"batb":[[0,1.7,10],[1,1.69,56.58],[2,1.3,1000]],"ltp":1.7,"tv":45.89,"id":5995}]}]}
{"op":"mcm","clk":"11849993783","pt":1723300395520,"mc":[{"id":"1.231581624","rc":[{"batb":[[0,2.32,29.57],[1,1.3,1000],[2,1.08,7.85]],"ltp":2.42,"tv":19.59,"id":31378},{"batb":[[0,1.69,56.58],[1,1.3,1000],[2,1.08,7.85]],"ltp":1.7,"tv":45.89,"id":5995}]}]}
{"op":"mcm","clk":"11850004264","pt":1723300433882,"mc":[{"id":"1.231581624","rc":[{"batb":[[0,2.34,10],[1,2.32,29.57],[2,1.3,1000]],"ltp":2.42,"tv":19.59,"id":31378},{"batb":[[0,1.7,10],[1,1.69,56.58],[2,1.3,1000]],"ltp":1.7,"tv":45.89,"id":5995}]}]}
{"op":"mcm","clk":"11850005378","pt":1723300437965,"mc":[{"id":"1.231581624","rc":[{"batb":[[0,2.32,29.57],[1,1.3,1000],[2,1.08,7.85]],"ltp":2.42,"tv":19.59,"id":31378},{"batb":[[0,1.69,56.58],[1,1.3,1000],[2,1.08,7.85]],"ltp":1.7,"tv":45.89,"id":5995}]}]}
{"op":"mcm","clk":"11850016193","pt":1723300475803,"mc":[{"id":"1.231581624","rc":[{"batb":[[0,2.34,10],[1,2.32,29.57],[2,1.3,1000]],"ltp":2.42,"tv":19.59,"id":31378},{"batb":[[0,1.7,10],[1,1.69,56.58],[2,1.3,1000]],"ltp":1.7,"tv":45.89,"id":5995}]}]}
{"op":"mcm","clk":"11850017181","pt":1723300479200,"mc":[{"id":"1.231581624","rc":[{"batb":[[0,2.32,29.57],[1,1.3,1000],[2,1.08,7.85]],"ltp":2.42,"tv":19.59,"id":31378},{"batb":[[0,1.69,56.58],[1,1.3,1000],[2,1.08,7.85]],"ltp":1.7,"tv":45.89,"id":5995}]}]}
{"op":"mcm","clk":"11850028154","pt":1723300519249,"mc":[{"id":"1.231581624","rc":[{"batb":[[0,2.34,10],[1,2.32,29.57],[2,1.3,1000]],"ltp":2.42,"tv":19.59,"id":31378},{"batb":[[0,1.7,10],[1,1.69,56.58],[2,1.3,1000]],"ltp":1.7,"tv":45.89,"id":5995}]}]}
{"op":"mcm","clk":"11850029551","pt":1723300524043,"mc":[{"id":"1.231581624","rc":[{"batb":[[0,2.32,29.57],[1,1.3,1000],[2,1.08,7.85]],"ltp":2.42,"tv":19.59,"id":31378},{"batb":[[0,1.69,56.58],[1,1.3,1000],[2,1.08,7.85]],"ltp":1.7,"tv":45.89,"id":5995}]}]}
{"op":"mcm","clk":"11850051524","pt":1723300601700,"mc":[{"id":"1.231581624","rc":[{"batb":[[0,2.34,10],[1,2.32,29.57],[2,1.3,1000]],"ltp":2.42,"tv":19.59,"id":31378},{"batb":[[0,1.7,10],[1,1.69,56.58],[2,1.3,1000]],"ltp":1.7,"tv":45.89,"id":5995}]}]}
{"op":"mcm","clk":"11850052596","pt":1723300605377,"mc":[{"id":"1.231581624","rc":[{"batb":[[0,2.32,29.57],[1,1.3,1000],[2,1.08,7.85]],"ltp":2.42,"tv":19.59,"id":31378},{"batb":[[0,1.69,56.58],[1,1.3,1000],[2,1.08,7.85]],"ltp":1.7,"tv":45.89,"id":5995}]}]}
{"op":"mcm","clk":"11850061962","pt":1723300639459,"mc":[{"id":"1.231581624","rc":[{"batb":[[0,2.34,10],[1,2.32,29.57],[2,1.3,1000]],"ltp":2.42,"tv":19.59,"id":31378},{"batb":[[0,1.7,10],[1,1.69,56.58],[2,1.3,1000]],"ltp":1.7,"tv":45.89,"id":5995}]}]}
{"op":"mcm","clk":"11850063075","pt":1723300643367,"mc":[{"id":"1.231581624","rc":[{"batb":[[0,2.32,29.57],[1,1.3,1000],[2,1.08,7.85]],"ltp":2.42,"tv":19.59,"id":31378},{"batb":[[0,1.69,56.58],[1,1.3,1000],[2,1.08,7.85]],"ltp":1.7,"tv":45.89,"id":5995}]}]}
{"op":"mcm","clk":"11850074004","pt":1723300681838,"mc":[{"id":"1.231581624","rc":[{"batb":[[0,2.34,10],[1,2.32,29.57],[2,1.3,1000]],"ltp":2.42,"tv":19.59,"id":31378},{"batb":[[0,1.7,10],[1,1.69,56.58],[2,1.3,1000]],"ltp":1.7,"tv":45.89,"id":5995}]}]}
{"op":"mcm","clk":"11850075406","pt":1723300686768,"mc":[{"id":"1.231581624","rc":[{"batb":[[0,2.32,29.57],[1,1.3,1000],[2,1.08,7.85]],"ltp":2.42,"tv":19.59,"id":31378},{"batb":[[0,1.69,56.58],[1,1.3,1000],[2,1.08,7.85]],"ltp":1.7,"tv":45.89,"id":5995}]}]}
{"op":"mcm","clk":"11850086012","pt":1723300723049,"mc":[{"id":"1.231581624","rc":[{"batb":[[0,2.34,10],[1,2.32,29.57],[2,1.3,1000]],"ltp":2.42,"tv":19.59,"id":31378},{"batb":[[0,1.7,10],[1,1.69,56.58],[2,1.3,1000]],"ltp":1.7,"tv":45.89,"id":5995}]}]}
{"op":"mcm","clk":"11850087270","pt":1723300727659,"mc":[{"id":"1.231581624","rc":[{"batb":[[0,2.32,29.57],[1,1.3,1000],[2,1.08,7.85]],"ltp":2.42,"tv":19.59,"id":31378},{"batb":[[0,1.69,56.58],[1,1.3,1000],[2,1.08,7.85]],"ltp":1.7,"tv":45.89,"id":5995}]}]}
{"op":"mcm","clk":"11850097360","pt":1723300763497,"mc":[{"id":"1.231581624","rc":[{"batb":[[0,2.34,10],[1,2.32,29.57],[2,1.3,1000]],"ltp":2.42,"tv":19.59,"id":31378},{"batb":[[0,1.7,10],[1,1.69,56.58],[2,1.3,1000]],"ltp":1.7,"tv":45.89,"id":5995}]}]}
{"op":"mcm","clk":"11850098310","pt":1723300766989,"mc":[{"id":"1.231581624","rc":[{"batb":[[0,2.32,29.57],[1,1.3,1000],[2,1.08,7.85]],"ltp":2.42,"tv":19.59,"id":31378},{"batb":[[0,1.69,56.58],[1,1.3,1000],[2,1.08,7.85]],"ltp":1.7,"tv":45.89,"id":5995}]}]}
{"op":"mcm","clk":"11850108991","pt":1723300804762,"mc":[{"id":"1.231581624","rc":[{"batb":[[0,2.34,10],[1,2.32,29.57],[2,1.3,1000]],"ltp":2.42,"tv":19.59,"id":31378},{"batb":[[0,1.7,10],[1,1.69,56.58],[2,1.3,1000]],"ltp":1.7,"tv":45.89,"id":5995}]}]}
{"op":"mcm","clk":"11850110124","pt":1723300808545,"mc":[{"id":"1.231581624","rc":[{"batb":[[0,2.32,29.57],[1,1.3,1000],[2,1.08,7.85]],"ltp":2.42,"tv":19.59,"id":31378},{"batb":[[0,1.69,56.58],[1,1.3,1000],[2,1.08,7.85]],"ltp":1.7,"tv":45.89,"id":5995}]}]}
{"op":"mcm","clk":"11850132282","pt":1723300886999,"mc":[{"id":"1.231581624","rc":[{"batb":[[0,2.34,10],[1,2.32,29.57],[2,1.3,1000]],"ltp":2.42,"tv":19.59,"id":31378},{"batb":[[0,1.7,10],[1,1.69,56.58],[2,1.3,1000]],"ltp":1.7,"tv":45.89,"id":5995}]}]}
{"op":"mcm","clk":"11850133311","pt":1723300890591,"mc":[{"id":"1.231581624","rc":[{"batb":[[0,2.32,29.57],[1,1.3,1000],[2,1.08,7.85]],"ltp":2.42,"tv":19.59,"id":31378},{"batb":[[0,1.69,56.58],[1,1.3,1000],[2,1.08,7.85]],"ltp":1.7,"tv":45.89,"id":5995}]}]}
{"op":"mcm","clk":"11850143646","pt":1723300927852,"mc":[{"id":"1.231581624","rc":[{"batb":[[0,2.34,10],[1,2.32,29.57],[2,1.3,1000]],"ltp":2.42,"tv":19.59,"id":31378},{"batb":[[0,1.7,10],[1,1.69,56.58],[2,1.3,1000]],"ltp":1.7,"tv":45.89,"id":5995}]}]}
{"op":"mcm","clk":"11850144635","pt":1723300931347,"mc":[{"id":"1.231581624","rc":[{"batb":[[0,2.32,29.57],[1,1.3,1000],[2,1.08,7.85]],"ltp":2.42,"tv":19.59,"id":31378},{"batb":[[0,1.69,56.58],[1,1.3,1000],[2,1.08,7.85]],"ltp":1.7,"tv":45.89,"id":5995}]}]}
{"op":"mcm","clk":"11850166079","pt":1723301007416,"mc":[{"id":"1.231581624","rc":[{"batb":[[0,2.34,10],[1,2.32,29.57],[2,1.3,1000]],"ltp":2.42,"tv":19.59,"id":31378},{"batb":[[0,1.7,10],[1,1.69,56.58],[2,1.3,1000]],"ltp":1.7,"tv":45.89,"id":5995}]}]}
{"op":"mcm","clk":"11850167164","pt":1723301011143,"mc":[{"id":"1.231581624","rc":[{"batb":[[0,2.32,29.57],[1,1.3,1000],[2,1.08,7.85]],"ltp":2.42,"tv":19.59,"id":31378},{"batb":[[0,1.69,56.58],[1,1.3,1000],[2,1.08,7.85]],"ltp":1.7,"tv":45.89,"id":5995}]}]}
{"op":"mcm","clk":"11850172223","pt":1723301029098,"mc":[{"id":"1.231581624","rc":[{"batb":[[0,2.34,10],[1,2.32,29.57],[2,1.3,1000]],"ltp":2.42,"tv":19.59,"id":31378},{"batb":[[0,1.7,10],[1,1.69,56.58],[2,1.3,1000]],"ltp":1.7,"tv":45.89,"id":5995}]}]}
{"op":"mcm","clk":"11850173469","pt":1723301033885,"mc":[{"id":"1.231581624","rc":[{"batb":[[0,2.32,29.57],[1,1.3,1000],[2,1.08,7.85]],"ltp":2.42,"tv":19.59,"id":31378},{"batb":[[0,1.69,56.58],[1,1.3,1000],[2,1.08,7.85]],"ltp":1.7,"tv":45.89,"id":5995}]}]}
{"op":"mcm","clk":"11850177545","pt":1723301048718,"mc":[{"id":"1.231581624","rc":[{"batb":[[0,2.34,10],[1,2.32,29.57],[2,1.3,1000]],"ltp":2.42,"tv":19.59,"id":31378},{"batb":[[0,1.7,10],[1,1.69,56.58],[2,1.3,1000]],"ltp":1.7,"tv":45.89,"id":5995}]}]}
{"op":"mcm","clk":"11850178707","pt":1723301052715,"mc":[{"id":"1.231581624","rc":[{"batb":[[0,2.32,29.57],[1,1.3,1000],[2,1.08,7.85]],"ltp":2.42,"tv":19.59,"id":31378},{"batb":[[0,1.69,56.58],[1,1.3,1000],[2,1.08,7.85]],"ltp":1.7,"tv":45.89,"id":5995}]}]}
{"op":"mcm","clk":"11850201016","pt":1723301132104,"mc":[{"id":"1.231581624","rc":[{"batb":[[0,2.34,10],[1,2.32,29.57],[2,1.3,1000]],"ltp":2.42,"tv":19.59,"id":31378},{"batb":[[0,1.7,10],[1,1.69,56.58],[2,1.3,1000]],"ltp":1.7,"tv":45.89,"id":5995}]}]}
{"op":"mcm","clk":"11850201935","pt":1723301135469,"mc":[{"id":"1.231581624","rc":[{"batb":[[0,2.32,29.57],[1,1.3,1000],[2,1.08,7.85]],"ltp":2.42,"tv":19.59,"id":31378},{"batb":[[0,1.69,56.58],[1,1.3,1000],[2,1.08,7.85]],"ltp":1.7,"tv":45.89,"id":5995}]}]}
{"op":"mcm","clk":"11850212888","pt":1723301174737,"mc":[{"id":"1.231581624","rc":[{"batb":[[0,2.34,10],[1,2.32,29.57],[2,1.3,1000]],"ltp":2.42,"tv":19.59,"id":31378},{"batb":[[0,1.7,10],[1,1.69,56.58],[2,1.3,1000]],"ltp":1.7,"tv":45.89,"id":5995}]}]}
{"op":"mcm","clk":"11850214090","pt":1723301178511,"mc":[{"id":"1.231581624","rc":[{"batb":[[0,2.32,29.57],[1,1.3,1000],[2,1.08,7.85]],"ltp":2.42,"tv":19.59,"id":31378},{"batb":[[0,1.69,56.58],[1,1.3,1000],[2,1.08,7.85]],"ltp":1.7,"tv":45.89,"id":5995}]}]}
{"op":"mcm","clk":"11850359184","pt":1723301924227,"mc":[{"id":"1.231581624","rc":[{"batb":[[0,2.34,10],[1,2.32,29.57],[2,1.3,1000]],"ltp":2.42,"tv":19.59,"id":31378},{"batb":[[0,1.7,10],[1,1.69,56.58],[2,1.3,1000]],"ltp":1.7,"tv":45.89,"id":5995}]}]}
{"op":"mcm","clk":"11850359685","pt":1723301927641,"mc":[{"id":"1.231581624","rc":[{"batb":[[0,2.32,29.57],[1,1.3,1000],[2,1.08,7.85]],"ltp":2.42,"tv":19.59,"id":31378},{"batb":[[0,1.69,56.58],[1,1.3,1000],[2,1.08,7.85]],"ltp":1.7,"tv":45.89,"id":5995}]}]}
{"op":"mcm","clk":"11850373105","pt":1723302008370,"mc":[{"id":"1.231581624","rc":[{"batb":[[0,2.34,10],[1,2.32,29.57],[2,1.3,1000]],"ltp":2.42,"tv":19.59,"id":31378},{"batb":[[0,1.7,10],[1,1.69,56.58],[2,1.3,1000]],"ltp":1.7,"tv":45.89,"id":5995}]}]}
{"op":"mcm","clk":"11850373823","pt":1723302011649,"mc":[{"id":"1.231581624","rc":[{"batb":[[0,2.32,29.57],[1,1.3,1000],[2,1.08,7.85]],"ltp":2.42,"tv":19.59,"id":31378},{"batb":[[0,1.69,56.58],[1,1.3,1000],[2,1.08,7.85]],"ltp":1.7,"tv":45.89,"id":5995}]}]}
{"op":"mcm","clk":"11850396446","pt":1723302128684,"mc":[{"id":"1.231581624","rc":[{"batb":[[0,2.34,10],[1,2.32,29.57],[2,1.3,1000]],"ltp":2.42,"tv":19.59,"id":31378},{"batl":[[0,1.75,42.17],[1,1000,0.02]],"ltp":1.7,"tv":45.89,"id":5995}]}]}
{"op":"mcm","clk":"11850397309","pt":1723302131867,"mc":[{"id":"1.231581624","rc":[{"batb":[[0,2.32,29.57],[1,1.3,1000],[2,1.08,7.85]],"ltp":2.42,"tv":19.59,"id":31378}]}]}
{"op":"mcm","clk":"11850415431","pt":1723302205673,"mc":[{"id":"1.231581624","rc":[{"batb":[[0,2.34,10],[1,2.32,29.57],[2,1.3,1000]],"ltp":2.42,"tv":19.59,"id":31378}]}]}
{"op":"mcm","clk":"11850416192","pt":1723302209024,"mc":[{"id":"1.231581624","rc":[{"batb":[[0,2.32,29.57],[1,1.3,1000],[2,1.08,7.85]],"ltp":2.42,"tv":19.59,"id":31378}]}]}
{"op":"mcm","clk":"11850425522","pt":1723302248152,"mc":[{"id":"1.231581624","rc":[{"batb":[[0,2.34,10],[1,2.32,29.57],[2,1.3,1000]],"ltp":2.42,"tv":19.59,"id":31378}]}]}
{"op":"mcm","clk":"11850426357","pt":1723302251439,"mc":[{"id":"1.231581624","rc":[{"batb":[[0,2.32,29.57],[1,1.3,1000],[2,1.08,7.85]],"ltp":2.42,"tv":19.59,"id":31378}]}]}
{"op":"mcm","clk":"11850445297","pt":1723302328283,"mc":[{"id":"1.231581624","rc":[{"batb":[[0,2.34,10],[1,2.32,29.57],[2,1.3,1000]],"ltp":2.42,"tv":19.59,"id":31378}]}]}
{"op":"mcm","clk":"11850446174","pt":1723302331699,"mc":[{"id":"1.231581624","rc":[{"batb":[[0,2.32,29.57],[1,1.3,1000],[2,1.08,7.85]],"ltp":2.42,"tv":19.59,"id":31378}]}]}
{"op":"mcm","clk":"11850455433","pt":1723302368447,"mc":[{"id":"1.231581624","rc":[{"batb":[[0,2.34,10],[1,2.32,29.57],[2,1.3,1000]],"ltp":2.42,"tv":19.59,"id":31378}]}]}
{"op":"mcm","clk":"11850456258","pt":1723302371664,"mc":[{"id":"1.231581624","rc":[{"batb":[[0,2.32,29.57],[1,1.3,1000],[2,1.08,7.85]],"ltp":2.42,"tv":19.59,"id":31378}]}]}
{"op":"mcm","clk":"11850465503","pt":1723302408395,"mc":[{"id":"1.231581624","rc":[{"batb":[[0,2.34,10],[1,2.32,29.57],[2,1.3,1000]],"ltp":2.42,"tv":19.59,"id":31378}]}]}
{"op":"mcm","clk":"11850466268","pt":1723302411700,"mc":[{"id":"1.231581624","rc":[{"batb":[[0,2.32,29.57],[1,1.3,1000],[2,1.08,7.85]],"ltp":2.42,"tv":19.59,"id":31378}]}]}
{"op":"mcm","clk":"11850475999","pt":1723302448538,"mc":[{"id":"1.231581624","rc":[{"batb":[[0,2.34,10],[1,2.32,29.57],[2,1.3,1000]],"ltp":2.42,"tv":19.59,"id":31378}]}]}
{"op":"mcm","clk":"11850476888","pt":1723302451867,"mc":[{"id":"1.231581624","rc":[{"batb":[[0,2.32,29.57],[1,1.3,1000],[2,1.08,7.85]],"ltp":2.42,"tv":19.59,"id":31378}]}]}
{"op":"mcm","clk":"11850486667","pt":1723302488297,"mc":[{"id":"1.231581624","rc":[{"batb":[[0,2.34,10],[1,2.32,29.57],[2,1.3,1000]],"ltp":2.42,"tv":19.59,"id":31378}]}]}
{"op":"mcm","clk":"11850487721","pt":1723302491972,"mc":[{"id":"1.231581624","rc":[{"batb":[[0,2.32,29.57],[1,1.3,1000],[2,1.08,7.85]],"ltp":2.42,"tv":19.59,"id":31378}]}]}
{"op":"mcm","clk":"11850541722","pt":1723302678535,"mc":[{"id":"1.231581624","rc":[{"batb":[[0,2.34,10],[1,2.32,29.57],[2,1.3,1000]],"ltp":2.42,"tv":19.59,"id":31378}]}]}
{"op":"mcm","clk":"11850542637","pt":1723302681761,"mc":[{"id":"1.231581624","rc":[{"batb":[[0,2.32,29.57],[1,1.3,1000],[2,1.08,7.85]],"ltp":2.42,"tv":19.59,"id":31378}]}]}
{"op":"mcm","clk":"11850553494","pt":1723302718679,"mc":[{"id":"1.231581624","rc":[{"batb":[[0,2.34,10],[1,2.32,29.57],[2,1.3,1000]],"ltp":2.42,"tv":19.59,"id":31378}]}]}
{"op":"mcm","clk":"11850554495","pt":1723302722100,"mc":[{"id":"1.231581624","rc":[{"batb":[[0,2.32,29.57],[1,1.3,1000],[2,1.08,7.85]],"ltp":2.42,"tv":19.59,"id":31378}]}]}
{"op":"mcm","clk":"11850565300","pt":1723302759356,"mc":[{"id":"1.231581624","rc":[{"batb":[[0,2.34,10],[1,2.32,29.57],[2,1.3,1000]],"ltp":2.42,"tv":19.59,"id":31378}]}]}
{"op":"mcm","clk":"11850566257","pt":1723302762592,"mc":[{"id":"1.231581624","rc":[{"batb":[[0,2.32,29.57],[1,1.3,1000],[2,1.08,7.85]],"ltp":2.42,"tv":19.59,"id":31378}]}]}
{"op":"mcm","clk":"11850576997","pt":1723302799778,"mc":[{"id":"1.231581624","rc":[{"batb":[[0,2.34,10],[1,2.32,29.57],[2,1.3,1000]],"ltp":2.42,"tv":19.59,"id":31378}]}]}
{"op":"mcm","clk":"11850577960","pt":1723302803157,"mc":[{"id":"1.231581624","rc":[{"batb":[[0,2.32,29.57],[1,1.3,1000],[2,1.08,7.85]],"ltp":2.42,"tv":19.59,"id":31378}]}]}
{"op":"mcm","clk":"11850599789","pt":1723302879367,"mc":[{"id":"1.231581624","rc":[{"batb":[[0,2.34,10],[1,2.32,29.57],[2,1.3,1000]],"ltp":2.42,"tv":19.59,"id":31378}]}]}
{"op":"mcm","clk":"11850601047","pt":1723302883482,"mc":[{"id":"1.231581624","rc":[{"batb":[[0,2.32,29.57],[1,1.3,1000],[2,1.08,7.85]],"ltp":2.42,"tv":19.59,"id":31378}]}]}
{"op":"mcm","clk":"11850611751","pt":1723302919011,"mc":[{"id":"1.231581624","rc":[{"batb":[[0,2.34,10],[1,2.32,29.57],[2,1.3,1000]],"ltp":2.42,"tv":19.59,"id":31378}]}]}
{"op":"mcm","clk":"11850612717","pt":1723302922338,"mc":[{"id":"1.231581624","rc":[{"batb":[[0,2.32,29.57],[1,1.3,1000],[2,1.08,7.85]],"ltp":2.42,"tv":19.59,"id":31378}]}]}
{"op":"mcm","clk":"11850623530","pt":1723302958944,"mc":[{"id":"1.231581624","rc":[{"batb":[[0,2.34,10],[1,2.32,29.57],[2,1.3,1000]],"ltp":2.42,"tv":19.59,"id":31378}]}]}
{"op":"mcm","clk":"11850624465","pt":1723302962152,"mc":[{"id":"1.231581624","rc":[{"batb":[[0,2.32,29.57],[1,1.3,1000],[2,1.08,7.85]],"ltp":2.42,"tv":19.59,"id":31378}]}]}
{"op":"mcm","clk":"11850632628","pt":1723302990188,"mc":[{"id":"1.231581624","rc":[{"batb":[[0,2.34,10],[1,2.32,29.57],[2,1.3,1000]],"ltp":2.42,"tv":19.59,"id":31378}]}]}
{"op":"mcm","clk":"11850633615","pt":1723302993608,"mc":[{"id":"1.231581624","rc":[{"batb":[[0,2.32,29.57],[1,1.3,1000],[2,1.08,7.85]],"ltp":2.42,"tv":19.59,"id":31378}]}]}
{"op":"mcm","clk":"11850634866","pt":1723302997901,"mc":[{"id":"1.231581624","rc":[{"batb":[[0,2.34,10],[1,2.32,29.57],[2,1.3,1000]],"ltp":2.42,"tv":19.59,"id":31378}]}]}
{"op":"mcm","clk":"11850635880","pt":1723303001297,"mc":[{"id":"1.231581624","rc":[{"batb":[[0,2.32,29.57],[1,1.3,1000],[2,1.08,7.85]],"ltp":2.42,"tv":19.59,"id":31378}]}]}
{"op":"mcm","clk":"11850703107","pt":1723303231549,"mc":[{"id":"1.231581624","rc":[{"batb":[[0,2.34,10],[1,2.32,29.57],[2,1.3,1000]],"ltp":2.42,"tv":19.59,"id":31378}]}]}
{"op":"mcm","clk":"11850704168","pt":1723303234963,"mc":[{"id":"1.231581624","rc":[{"batb":[[0,2.32,29.57],[1,1.3,1000],[2,1.08,7.85]],"ltp":2.42,"tv":19.59,"id":31378}]}]}
{"op":"mcm","clk":"11850714855","pt":1723303270929,"mc":[{"id":"1.231581624","rc":[{"batb":[[0,2.34,10],[1,2.32,29.57],[2,1.3,1000]],"ltp":2.42,"tv":19.59,"id":31378}]}]}
{"op":"mcm","clk":"11850715968","pt":1723303274381,"mc":[{"id":"1.231581624","rc":[{"batb":[[0,2.32,29.57],[1,1.3,1000],[2,1.08,7.85]],"ltp":2.42,"tv":19.59,"id":31378}]}]}
{"op":"mcm","clk":"11850726293","pt":1723303309569,"mc":[{"id":"1.231581624","rc":[{"batb":[[0,2.34,10],[1,2.32,29.57],[2,1.3,1000]],"ltp":2.42,"tv":19.59,"id":31378}]}]}
{"op":"mcm","clk":"11850727200","pt":1723303312869,"mc":[{"id":"1.231581624","rc":[{"batb":[[0,2.32,29.57],[1,1.3,1000],[2,1.08,7.85]],"ltp":2.42,"tv":19.59,"id":31378}]}]}
{"op":"mcm","clk":"11850737707","pt":1723303350217,"mc":[{"id":"1.231581624","rc":[{"batb":[[0,2.34,10],[1,2.32,29.57],[2,1.3,1000]],"ltp":2.42,"tv":19.59,"id":31378}]}]}
{"op":"mcm","clk":"11850738692","pt":1723303353610,"mc":[{"id":"1.231581624","rc":[{"batb":[[0,2.32,29.57],[1,1.3,1000],[2,1.08,7.85]],"ltp":2.42,"tv":19.59,"id":31378}]}]}
{"op":"mcm","clk":"11850794393","pt":1723303547974,"mc":[{"id":"1.231581624","rc":[{"batb":[[0,2.34,10],[1,2.32,29.57],[2,1.3,1000]],"ltp":2.42,"tv":19.59,"id":31378}]}]}
{"op":"mcm","clk":"11850795337","pt":1723303551344,"mc":[{"id":"1.231581624","rc":[{"batb":[[0,2.32,29.57],[1,1.3,1000],[2,1.08,7.85]],"ltp":2.42,"tv":19.59,"id":31378}]}]}
{"op":"mcm","clk":"11850805705","pt":1723303588689,"mc":[{"id":"1.231581624","rc":[{"batb":[[0,2.34,10],[1,2.32,29.57],[2,1.3,1000]],"ltp":2.42,"tv":19.59,"id":31378}]}]}
{"op":"mcm","clk":"11850806640","pt":1723303592089,"mc":[{"id":"1.231581624","rc":[{"batb":[[0,2.32,29.57],[1,1.3,1000],[2,1.08,7.85]],"ltp":2.42,"tv":19.59,"id":31378}]}]}
{"op":"mcm","clk":"11850848793","pt":1723303746056,"mc":[{"id":"1.231581624","rc":[{"batb":[[0,2.34,10],[1,2.32,29.57],[2,1.3,1000]],"ltp":2.42,"tv":19.59,"id":31378}]}]}
{"op":"mcm","clk":"11850849595","pt":1723303749341,"mc":[{"id":"1.231581624","rc":[{"batb":[[0,2.32,29.57],[1,1.3,1000],[2,1.08,7.85]],"ltp":2.42,"tv":19.59,"id":31378}]}]}
{"op":"mcm","clk":"11850870193","pt":1723303825922,"mc":[{"id":"1.231581624","rc":[{"batb":[[0,2.34,10],[1,2.32,29.57],[2,1.3,1000]],"ltp":2.42,"tv":19.59,"id":31378}]}]}
{"op":"mcm","clk":"11850871048","pt":1723303829204,"mc":[{"id":"1.231581624","rc":[{"batb":[[0,2.32,29.57],[1,1.3,1000],[2,1.08,7.85]],"ltp":2.42,"tv":19.59,"id":31378}]}]}
{"op":"mcm","clk":"11850890895","pt":1723303906462,"mc":[{"id":"1.231581624","rc":[{"batb":[[0,2.34,10],[1,2.32,29.57],[2,1.3,1000]],"ltp":2.42,"tv":19.59,"id":31378}]}]}
{"op":"mcm","clk":"11850891746","pt":1723303909985,"mc":[{"id":"1.231581624","rc":[{"batb":[[0,2.32,29.57],[1,1.3,1000],[2,1.08,7.85]],"ltp":2.42,"tv":19.59,"id":31378}]}]}
{"op":"mcm","clk":"11850907227","pt":1723303969660,"mc":[{"id":"1.231581624","rc":[{"batb":[[0,2.34,10],[1,2.32,29.57],[2,1.3,1000]],"ltp":2.42,"tv":19.59,"id":31378}]}]}
{"op":"mcm","clk":"11850908025","pt":1723303972946,"mc":[{"id":"1.231581624","rc":[{"batb":[[0,2.32,29.57],[1,1.3,1000],[2,1.08,7.85]],"ltp":2.42,"tv":19.59,"id":31378}]}]}
{"op":"mcm","clk":"11850911117","pt":1723303985022,"mc":[{"id":"1.231581624","rc":[{"batb":[[0,2.34,10],[1,2.32,29.57],[2,1.3,1000]],"ltp":2.42,"tv":19.59,"id":31378}]}]}
{"op":"mcm","clk":"11850911954","pt":1723303988390,"mc":[{"id":"1.231581624","rc":[{"batb":[[0,2.32,29.57],[1,1.3,1000],[2,1.08,7.85]],"ltp":2.42,"tv":19.59,"id":31378}]}]}
{"op":"mcm","clk":"11850930598","pt":1723304062209,"mc":[{"id":"1.231581624","rc":[{"batb":[[0,2.34,10],[1,2.32,29.57],[2,1.3,1000]],"ltp":2.42,"tv":19.59,"id":31378}]}]}
{"op":"mcm","clk":"11850931396","pt":1723304065531,"mc":[{"id":"1.231581624","rc":[{"batb":[[0,2.32,29.57],[1,1.3,1000],[2,1.08,7.85]],"ltp":2.42,"tv":19.59,"id":31378}]}]}
{"op":"mcm","clk":"11850988493","pt":1723304298119,"mc":[{"id":"1.231581624","rc":[{"batb":[[0,2.34,10],[1,2.32,29.57],[2,1.3,1000]],"ltp":2.42,"tv":19.59,"id":31378}]}]}
{"op":"mcm","clk":"11850989383","pt":1723304301548,"mc":[{"id":"1.231581624","rc":[{"batb":[[0,2.32,29.57],[1,1.3,1000],[2,1.08,7.85]],"ltp":2.42,"tv":19.59,"id":31378}]}]}
{"op":"mcm","clk":"11850995988","pt":1723304327975,"mc":[{"id":"1.231581624","rc":[{"batb":[[0,2.34,10],[1,2.32,29.57],[2,1.3,1000]],"ltp":2.42,"tv":19.59,"id":31378},{"batl":[[1,1.8,100],[2,1000,0.02]],"ltp":1.7,"tv":45.89,"id":5995}]}]}
{"op":"mcm","clk":"11850996752","pt":1723304331198,"mc":[{"id":"1.231581624","rc":[{"batb":[[0,2.32,29.57],[1,1.3,1000],[2,1.08,7.85]],"ltp":2.42,"tv":19.59,"id":31378},{"batl":[[2,1.81,200]],"ltp":1.7,"tv":45.89,"id":5995}]}]}
{"op":"mcm","clk":"11850997597","pt":1723304334603,"mc":[{"id":"1.231581624","rc":[{"batb":[[0,2.34,10],[1,2.32,29.57],[2,1.3,1000]],"ltp":2.42,"tv":19.59,"id":31378}]}]}
{"op":"mcm","clk":"11850998378","pt":1723304337893,"mc":[{"id":"1.231581624","rc":[{"batb":[[0,2.32,29.57],[1,1.3,1000],[2,1.08,7.85]],"ltp":2.42,"tv":19.59,"id":31378}]}]}
{"op":"mcm","clk":"11850999016","pt":1723304340555,"mc":[{"id":"1.231581624","rc":[{"batb":[[0,2.34,10],[1,2.32,29.57],[2,1.3,1000]],"ltp":2.42,"tv":19.59,"id":31378}]}]}
{"op":"mcm","clk":"11850999806","pt":1723304344085,"mc":[{"id":"1.231581624","rc":[{"batb":[[0,2.32,29.57],[1,1.3,1000],[2,1.08,7.85]],"ltp":2.42,"tv":19.59,"id":31378}]}]}
{"op":"mcm","clk":"11851205696","pt":1723305250630,"mc":[{"id":"1.231581624","rc":[{"batb":[[0,2.34,10],[1,2.32,29.57],[2,1.3,1000]],"ltp":2.42,"tv":19.59,"id":31378}]}]}
{"op":"mcm","clk":"11851206305","pt":1723305253625,"mc":[{"id":"1.231581624","rc":[{"batb":[[0,2.32,29.57],[1,1.3,1000],[2,1.08,7.85]],"ltp":2.42,"tv":19.59,"id":31378}]}]}
{"op":"mcm","clk":"11851221285","pt":1723305349429,"mc":[{"id":"1.231581624","rc":[{"batb":[[0,2.34,10],[1,2.32,29.57],[2,1.3,1000]],"ltp":2.42,"tv":19.59,"id":31378}]}]}
{"op":"mcm","clk":"11851221731","pt":1723305352172,"mc":[{"id":"1.231581624","rc":[{"batb":[[0,2.32,29.57],[1,1.3,1000],[2,1.08,7.85]],"ltp":2.42,"tv":19.59,"id":31378}]}]}
{"op":"mcm","clk":"11851319222","pt":1723306046494,"mc":[{"id":"1.231581624","rc":[{"batb":[[0,2.34,10],[1,2.32,29.57],[2,1.3,1000]],"ltp":2.42,"tv":19.59,"id":31378},{"batl":[[0,1.74,12.27],[1,1.75,42.17],[2,1.8,100]],"ltp":1.7,"tv":45.89,"id":5995}]}]}
{"op":"mcm","clk":"11851319705","pt":1723306049720,"mc":[{"id":"1.231581624","rc":[{"batb":[[0,2.32,29.57],[1,1.3,1000],[2,1.08,7.85]],"ltp":2.42,"tv":19.59,"id":31378}]}]}
{"op":"mcm","clk":"11851399956","pt":1723306587309,"mc":[{"id":"1.231581624","rc":[{"batb":[[0,2.34,10],[1,2.32,29.57],[2,1.3,1000]],"ltp":2.42,"tv":19.59,"id":31378}]}]}
{"op":"mcm","clk":"11851400559","pt":1723306590750,"mc":[{"id":"1.231581624","rc":[{"batb":[[0,2.32,29.57],[1,1.3,1000],[2,1.08,7.85]],"ltp":2.42,"tv":19.59,"id":31378}]}]}
{"op":"mcm","clk":"11851404442","pt":1723306613640,"mc":[{"id":"1.231581624","rc":[{"batb":[[0,2.34,10],[1,2.32,29.57],[2,1.3,1000]],"ltp":2.42,"tv":19.59,"id":31378}]}]}
{"op":"mcm","clk":"11851405024","pt":1723306616974,"mc":[{"id":"1.231581624","rc":[{"batb":[[0,2.32,29.57],[1,1.3,1000],[2,1.08,7.85]],"ltp":2.42,"tv":19.59,"id":31378}]}]}
{"op":"mcm","clk":"11851425112","pt":1723306735655,"mc":[{"id":"1.231581624","rc":[{"batb":[[0,2.34,10],[1,2.32,29.57],[2,1.3,1000]],"ltp":2.42,"tv":19.59,"id":31378}]}]}
{"op":"mcm","clk":"11851425679","pt":1723306737694,"mc":[{"id":"1.231581624","rc":[{"batb":[[0,2.32,29.57],[1,1.3,1000],[2,1.08,7.85]],"ltp":2.42,"tv":19.59,"id":31378}]}]}
{"op":"mcm","clk":"11851436346","pt":1723306798052,"mc":[{"id":"1.231581624","rc":[{"batb":[[0,2.34,10],[1,2.32,29.57],[2,1.3,1000]],"ltp":2.42,"tv":19.59,"id":31378}]}]}
{"op":"mcm","clk":"11851436957","pt":1723306801352,"mc":[{"id":"1.231581624","rc":[{"batb":[[0,2.32,29.57],[1,1.3,1000],[2,1.08,7.85]],"ltp":2.42,"tv":19.59,"id":31378}]}]}
{"op":"mcm","clk":"11851501290","pt":1723307179718,"mc":[{"id":"1.231581624","rc":[{"batl":[[0,2.36,5],[1,2.42,2.41],[2,1000,0.02]],"ltp":2.42,"tv":19.59,"id":31378}]}]}
{"op":"mcm","clk":"11851628758","pt":1723307802580,"mc":[{"id":"1.231581624","rc":[{"trd":[[1.74,12]],"batl":[[0,1.74,6.27]],"ltp":1.74,"tv":57.89,"id":5995}],"tv":77.48}]}
{"op":"mcm","clk":"11851759546","pt":1723308412443,"mc":[{"id":"1.231581624","rc":[{"trd":[[2.36,5],[2.42,22]],"batl":[[0,1000,0.02],[1,2.42,0],[2,1000,0]],"ltp":2.42,"tv":27.0,"id":31378},{"trd":[[1.7,49.32],[1.73,6.82]],"batl":[[0,1.7,9.75],[1,1.74,6.27],[2,1.75,42.17]],"ltp":1.7,"tv":68.14,"id":5995}],"tv":95.14}]}
{"op":"mcm","clk":"11851759564","pt":1723308412550,"mc":[{"id":"1.231581624","rc":[{"batb":[[0,2.34,10],[1,2.32,29.57],[2,1.3,1000]],"ltp":2.42,"tv":27.0,"id":31378}]}]}
{"op":"mcm","clk":"11851760060","pt":1723308414870,"mc":[{"id":"1.231581624","rc":[{"batl":[[0,1.74,6.27],[1,1.75,42.17],[2,1.8,100]],"ltp":1.7,"tv":68.14,"id":5995}]}]}
{"op":"mcm","clk":"11851760224","pt":1723308415848,"mc":[{"id":"1.231581624","rc":[{"batb":[[0,2.32,29.57],[1,1.3,1000],[2,1.08,7.85]],"ltp":2.42,"tv":27.0,"id":31378}]}]}
{"op":"mcm","clk":"11851811717","pt":1723308674794,"mc":[{"id":"1.231581624","rc":[{"batb":[[0,2.34,10],[1,2.32,29.57],[2,1.3,1000]],"ltp":2.42,"tv":27.0,"id":31378}]}]}
{"op":"mcm","clk":"11851812329","pt":1723308678207,"mc":[{"id":"1.231581624","rc":[{"batb":[[0,2.32,29.57],[1,1.3,1000],[2,1.08,7.85]],"ltp":2.42,"tv":27.0,"id":31378}]}]}
{"op":"mcm","clk":"11851821243","pt":1723308726064,"mc":[{"id":"1.231581624","rc":[{"batb":[[0,2.34,10],[1,2.32,29.57],[2,1.3,1000]],"ltp":2.42,"tv":27.0,"id":31378}]}]}
{"op":"mcm","clk":"11851821862","pt":1723308729361,"mc":[{"id":"1.231581624","rc":[{"batb":[[0,2.32,29.57],[1,1.3,1000],[2,1.08,7.85]],"ltp":2.42,"tv":27.0,"id":31378}]}]}
{"op":"mcm","clk":"11851842773","pt":1723308831607,"mc":[{"id":"1.231581624","rc":[{"batb":[[0,2.34,10],[1,2.32,29.57],[2,1.3,1000]],"ltp":2.42,"tv":27.0,"id":31378}]}]}
{"op":"mcm","clk":"11851843521","pt":1723308835025,"mc":[{"id":"1.231581624","rc":[{"batb":[[0,2.32,29.57],[1,1.3,1000],[2,1.08,7.85]],"ltp":2.42,"tv":27.0,"id":31378}]}]}
{"op":"mcm","clk":"11851845667","pt":1723308844651,"mc":[{"id":"1.231581624","rc":[{"batb":[[0,2.34,10],[1,2.32,29.57],[2,1.3,1000]],"ltp":2.42,"tv":27.0,"id":31378}]}]}
{"op":"mcm","clk":"11851846410","pt":1723308848072,"mc":[{"id":"1.231581624","rc":[{"batb":[[0,2.32,29.57],[1,1.3,1000],[2,1.08,7.85]],"ltp":2.42,"tv":27.0,"id":31378}]}]}
{"op":"mcm","clk":"11851847001","pt":1723308850744,"mc":[{"id":"1.231581624","rc":[{"batb":[[0,2.34,10],[1,2.32,29.57],[2,1.3,1000]],"ltp":2.42,"tv":27.0,"id":31378}]}]}
{"op":"mcm","clk":"11851847673","pt":1723308854141,"mc":[{"id":"1.231581624","rc":[{"batb":[[0,2.32,29.57],[1,1.3,1000],[2,1.08,7.85]],"ltp":2.42,"tv":27.0,"id":31378}]}]}
{"op":"mcm","clk":"11851854250","pt":1723308887151,"mc":[{"id":"1.231581624","rc":[{"batb":[[0,2.34,10],[1,2.32,29.57],[2,1.3,1000]],"ltp":2.42,"tv":27.0,"id":31378}]}]}
{"op":"mcm","clk":"11851854837","pt":1723308890350,"mc":[{"id":"1.231581624","rc":[{"batb":[[0,2.32,29.57],[1,1.3,1000],[2,1.08,7.85]],"ltp":2.42,"tv":27.0,"id":31378}]}]}
{"op":"mcm","clk":"11851864556","pt":1723308941698,"mc":[{"id":"1.231581624","rc":[{"batb":[[0,2.34,10],[1,2.32,29.57],[2,1.3,1000]],"ltp":2.42,"tv":27.0,"id":31378}]}]}
{"op":"mcm","clk":"11851865133","pt":1723308945081,"mc":[{"id":"1.231581624","rc":[{"batb":[[0,2.32,29.57],[1,1.3,1000],[2,1.08,7.85]],"ltp":2.42,"tv":27.0,"id":31378}]}]}
{"op":"mcm","clk":"11851880328","pt":1723309029146,"mc":[{"id":"1.231581624","rc":[{"batb":[[0,2.34,10],[1,2.32,29.57],[2,1.3,1000]],"ltp":2.42,"tv":27.0,"id":31378}]}]}
{"op":"mcm","clk":"11851880994","pt":1723309032567,"mc":[{"id":"1.231581624","rc":[{"batb":[[0,2.32,29.57],[1,1.3,1000],[2,1.08,7.85]],"ltp":2.42,"tv":27.0,"id":31378}]}]}
{"op":"mcm","clk":"11851934670","pt":1723309322381,"mc":[{"id":"1.231581624","rc":[{"batb":[[0,2.34,10],[1,2.32,29.57],[2,1.3,1000]],"ltp":2.42,"tv":27.0,"id":31378}]}]}
{"op":"mcm","clk":"11851935368","pt":1723309325563,"mc":[{"id":"1.231581624","rc":[{"batb":[[0,2.32,29.57],[1,1.3,1000],[2,1.08,7.85]],"ltp":2.42,"tv":27.0,"id":31378}]}]}
{"op":"mcm","clk":"11851941585","pt":1723309358507,"mc":[{"id":"1.231581624","rc":[{"batb":[[0,2.34,10],[1,2.32,29.57],[2,1.3,1000]],"ltp":2.42,"tv":27.0,"id":31378}]}]}
{"op":"mcm","clk":"11851942155","pt":1723309361727,"mc":[{"id":"1.231581624","rc":[{"batb":[[0,2.32,29.57],[1,1.3,1000],[2,1.08,7.85]],"ltp":2.42,"tv":27.0,"id":31378}]}]}
{"op":"mcm","clk":"11851955515","pt":1723309432568,"mc":[{"id":"1.231581624","rc":[{"batb":[[0,2.34,10],[1,2.32,29.57],[2,1.3,1000]],"ltp":2.42,"tv":27.0,"id":31378}]}]}
{"op":"mcm","clk":"11851956127","pt":1723309436005,"mc":[{"id":"1.231581624","rc":[{"batb":[[0,2.32,29.57],[1,1.3,1000],[2,1.08,7.85]],"ltp":2.42,"tv":27.0,"id":31378}]}]}
{"op":"mcm","clk":"11851995649","pt":1723309638393,"mc":[{"id":"1.231581624","rc":[{"batb":[[0,2.34,10],[1,2.32,29.57],[2,1.3,1000]],"ltp":2.42,"tv":27.0,"id":31378}]}]}
{"op":"mcm","clk":"11851996309","pt":1723309641686,"mc":[{"id":"1.231581624","rc":[{"batb":[[0,2.32,29.57],[1,1.3,1000],[2,1.08,7.85]],"ltp":2.42,"tv":27.0,"id":31378}]}]}
{"op":"mcm","clk":"11852002747","pt":1723309673055,"mc":[{"id":"1.231581624","rc":[{"batb":[[0,2.34,10],[1,2.32,29.57],[2,1.3,1000]],"ltp":2.42,"tv":27.0,"id":31378}]}]}
{"op":"mcm","clk":"11852003490","pt":1723309676357,"mc":[{"id":"1.231581624","rc":[{"batb":[[0,2.32,29.57],[1,1.3,1000],[2,1.08,7.85]],"ltp":2.42,"tv":27.0,"id":31378}]}]}
{"op":"mcm","clk":"11852389624","pt":1723311596731,"mc":[{"id":"1.231581624","rc":[{"batb":[[0,2.34,10],[1,2.32,29.57],[2,1.3,1000]],"ltp":2.42,"tv":27.0,"id":31378},{"batl":[[0,1.74,10.41]],"ltp":1.7,"tv":68.14,"id":5995}]}]}
{"op":"mcm","clk":"11852390336","pt":1723311599913,"mc":[{"id":"1.231581624","rc":[{"batb":[[0,2.32,29.57],[1,1.3,1000],[2,1.08,7.85]],"ltp":2.42,"tv":27.0,"id":31378}]}]}
{"op":"mcm","clk":"11852767724","pt":1723313547796,"mc":[{"id":"1.231581624","rc":[{"batb":[[0,2.34,14],[1,2.32,29.57],[2,1.3,1000]],"batl":[[0,2.7,5],[1,1000,0.02]],"ltp":2.42,"tv":27.0,"id":31378}]}]}
{"op":"mcm","clk":"11852768120","pt":1723313549979,"mc":[{"id":"1.231581624","rc":[{"batb":[[0,2.34,10]],"ltp":2.42,"tv":27.0,"id":31378}]}]}
{"op":"mcm","clk":"11852768353","pt":1723313551212,"mc":[{"id":"1.231581624","rc":[{"batb":[[0,2.32,29.57],[1,1.3,1000],[2,1.08,7.85]],"ltp":2.42,"tv":27.0,"id":31378}]}]}
{"op":"mcm","clk":"11852810800","pt":1723313795555,"mc":[{"id":"1.231581624","rc":[{"batb":[[0,2.34,14],[1,2.32,29.57],[2,1.3,1000]],"ltp":2.42,"tv":27.0,"id":31378}]}]}
{"op":"mcm","clk":"11852811178","pt":1723313797872,"mc":[{"id":"1.231581624","rc":[{"batb":[[0,2.34,10]],"ltp":2.42,"tv":27.0,"id":31378}]}]}
{"op":"mcm","clk":"11852811359","pt":1723313798982,"mc":[{"id":"1.231581624","rc":[{"batb":[[0,2.32,29.57],[1,1.3,1000],[2,1.08,7.85]],"ltp":2.42,"tv":27.0,"id":31378}]}]}
{"op":"mcm","clk":"11852877297","pt":1723314199622,"mc":[{"id":"1.231581624","rc":[{"batb":[[0,2.34,14],[1,2.32,29.57],[2,1.3,1000]],"ltp":2.42,"tv":27.0,"id":31378}]}]}
{"op":"mcm","clk":"11852877675","pt":1723314201838,"mc":[{"id":"1.231581624","rc":[{"batb":[[0,2.34,10]],"ltp":2.42,"tv":27.0,"id":31378}]}]}
{"op":"mcm","clk":"11852877882","pt":1723314203032,"mc":[{"id":"1.231581624","rc":[{"batb":[[0,2.32,29.57],[1,1.3,1000],[2,1.08,7.85]],"ltp":2.42,"tv":27.0,"id":31378}]}]}
{"op":"mcm","clk":"11852941456","pt":1723314613231,"mc":[{"id":"1.231581624","rc":[{"batb":[[0,2.34,14],[1,2.32,29.57],[2,1.3,1000]],"ltp":2.42,"tv":27.0,"id":31378},{"batl":[[0,1.73,45],[1,1.74,10.41],[2,1.75,42.17]],"ltp":1.7,"tv":68.14,"id":5995}]}]}
{"op":"mcm","clk":"11852941782","pt":1723314615665,"mc":[{"id":"1.231581624","rc":[{"batb":[[0,2.34,10]],"ltp":2.42,"tv":27.0,"id":31378}]}]}
{"op":"mcm","clk":"11852941927","pt":1723314616690,"mc":[{"id":"1.231581624","rc":[{"batb":[[0,2.32,29.57],[1,1.3,1000],[2,1.08,7.85]],"ltp":2.42,"tv":27.0,"id":31378}]}]}
{"op":"mcm","clk":"11853051085","pt":1723315346497,"mc":[{"id":"1.231581624","rc":[{"batb":[[0,2.34,14],[1,2.32,29.57],[2,1.3,1000]],"ltp":2.42,"tv":27.0,"id":31378}]}]}
{"op":"mcm","clk":"11853051483","pt":1723315348909,"mc":[{"id":"1.231581624","rc":[{"batb":[[0,2.34,10]],"ltp":2.42,"tv":27.0,"id":31378}]}]}
{"op":"mcm","clk":"11853051666","pt":1723315349969,"mc":[{"id":"1.231581624","rc":[{"batb":[[0,2.32,29.57],[1,1.3,1000],[2,1.08,7.85]],"ltp":2.42,"tv":27.0,"id":31378}]}]}
{"op":"mcm","clk":"11853296558","pt":1723316795823,"mc":[{"id":"1.231581624","rc":[{"batb":[[0,2.34,14],[1,2.32,29.57],[2,1.3,1000]],"ltp":2.42,"tv":27.0,"id":31378},{"batb":[[1,1.63,33],[2,1.3,1000]],"ltp":1.7,"tv":68.14,"id":5995}]}]}
{"op":"mcm","clk":"11853297010","pt":1723316798345,"mc":[{"id":"1.231581624","rc":[{"batb":[[0,2.34,10]],"ltp":2.42,"tv":27.0,"id":31378}]}]}
{"op":"mcm","clk":"11853297232","pt":1723316799317,"mc":[{"id":"1.231581624","rc":[{"batb":[[0,2.32,29.57],[1,1.3,1000],[2,1.08,7.85]],"ltp":2.42,"tv":27.0,"id":31378}]}]}
{"op":"mcm","clk":"11853298155","pt":1723316804343,"mc":[{"id":"1.231581624","rc":[{"batb":[[0,2.34,14],[1,2.32,29.57],[2,1.3,1000]],"ltp":2.42,"tv":27.0,"id":31378},{"batl":[[1,1.74,31.2]],"ltp":1.7,"tv":68.14,"id":5995}]}]}
{"op":"mcm","clk":"11853298580","pt":1723316806616,"mc":[{"id":"1.231581624","rc":[{"batb":[[0,2.34,10]],"ltp":2.42,"tv":27.0,"id":31378}]}]}
{"op":"mcm","clk":"11853298770","pt":1723316807677,"mc":[{"id":"1.231581624","rc":[{"batb":[[0,2.32,29.57],[1,1.3,1000],[2,1.08,7.85]],"ltp":2.42,"tv":27.0,"id":31378}]}]}
{"op":"mcm","clk":"11853736247","pt":1723319243801,"mc":[{"id":"1.231581624","rc":[{"trd":[[2.36,6]],"batb":[[0,2.34,14],[1,2.32,29.57],[2,1.3,1000]],"ltp":2.36,"tv":28.0,"id":31378},{"trd":[[1.73,8.18]],"batl":[[0,1.73,43.64]],"ltp":1.73,"tv":69.5,"id":5995}],"tv":97.5}]}
{"op":"mcm","clk":"11853736541","pt":1723319245901,"mc":[{"id":"1.231581624","rc":[{"batb":[[0,2.34,10]],"ltp":2.36,"tv":28.0,"id":31378}]}]}
{"op":"mcm","clk":"11853736768","pt":1723319247325,"mc":[{"id":"1.231581624","rc":[{"batb":[[0,2.32,29.57],[1,1.3,1000],[2,1.08,7.85]],"ltp":2.36,"tv":28.0,"id":31378}]}]}
{"op":"mcm","clk":"11853783629","pt":1723319622357,"mc":[{"id":"1.231581624","rc":[{"batb":[[0,2.34,14],[1,2.32,29.57],[2,1.3,1000]],"ltp":2.36,"tv":28.0,"id":31378}]}]}
{"op":"mcm","clk":"11853783934","pt":1723319624834,"mc":[{"id":"1.231581624","rc":[{"batb":[[0,2.34,10]],"ltp":2.36,"tv":28.0,"id":31378}]}]}
{"op":"mcm","clk":"11853784210","pt":1723319627141,"mc":[{"id":"1.231581624","rc":[{"batb":[[0,2.34,4]],"ltp":2.36,"tv":28.0,"id":31378}]}]}
{"op":"mcm","clk":"11853784572","pt":1723319629716,"mc":[{"id":"1.231581624","rc":[{"batb":[[0,2.34,10]],"ltp":2.36,"tv":28.0,"id":31378}]}]}
{"op":"mcm","clk":"11853785055","pt":1723319633326,"mc":[{"id":"1.231581624","rc":[{"batb":[[0,2.34,4]],"ltp":2.36,"tv":28.0,"id":31378}]}]}
{"op":"mcm","clk":"11853785418","pt":1723319635729,"mc":[{"id":"1.231581624","rc":[{"batb":[[0,2.34,10]],"ltp":2.36,"tv":28.0,"id":31378}]}]}
{"op":"mcm","clk":"11853785917","pt":1723319639335,"mc":[{"id":"1.231581624","rc":[{"batb":[[0,2.34,4]],"ltp":2.36,"tv":28.0,"id":31378}]}]}
{"op":"mcm","clk":"11853786257","pt":1723319641961,"mc":[{"id":"1.231581624","rc":[{"batb":[[0,2.34,10]],"ltp":2.36,"tv":28.0,"id":31378}]}]}
{"op":"mcm","clk":"11853786739","pt":1723319645358,"mc":[{"id":"1.231581624","rc":[{"batb":[[0,2.32,29.57],[1,1.3,1000],[2,1.08,7.85]],"ltp":2.36,"tv":28.0,"id":31378}]}]}
{"op":"mcm","clk":"11853786760","pt":1723319645558,"mc":[{"id":"1.231581624","rc":[{"batb":[[0,2.34,4],[1,2.32,29.57],[2,1.3,1000]],"ltp":2.36,"tv":28.0,"id":31378}]}]}
{"op":"mcm","clk":"11853787092","pt":1723319648057,"mc":[{"id":"1.231581624","rc":[{"batb":[[0,2.34,10]],"ltp":2.36,"tv":28.0,"id":31378}]}]}
{"op":"mcm","clk":"11853787518","pt":1723319651354,"mc":[{"id":"1.231581624","rc":[{"batb":[[0,2.32,29.57],[1,1.3,1000],[2,1.08,7.85]],"ltp":2.36,"tv":28.0,"id":31378}]}]}
{"op":"mcm","clk":"11853787542","pt":1723319651564,"mc":[{"id":"1.231581624","rc":[{"batb":[[0,2.34,4],[1,2.32,29.57],[2,1.3,1000]],"ltp":2.36,"tv":28.0,"id":31378}]}]}
{"op":"mcm","clk":"11853787806","pt":1723319653868,"mc":[{"id":"1.231581624","rc":[{"batb":[[0,2.34,10]],"ltp":2.36,"tv":28.0,"id":31378}]}]}
{"op":"mcm","clk":"11853788224","pt":1723319657277,"mc":[{"id":"1.231581624","rc":[{"batb":[[0,2.34,4]],"ltp":2.36,"tv":28.0,"id":31378}]}]}
{"op":"mcm","clk":"11853788512","pt":1723319659451,"mc":[{"id":"1.231581624","rc":[{"batb":[[0,2.32,29.57],[1,1.3,1000],[2,1.08,7.85]],"ltp":2.36,"tv":28.0,"id":31378}]}]}
{"op":"mcm","clk":"11853788525","pt":1723319659558,"mc":[{"id":"1.231581624","rc":[{"batb":[[0,2.34,10],[1,2.32,29.57],[2,1.3,1000]],"ltp":2.36,"tv":28.0,"id":31378}]}]}
{"op":"mcm","clk":"11853788889","pt":1723319662975,"mc":[{"id":"1.231581624","rc":[{"batb":[[0,2.34,4]],"ltp":2.36,"tv":28.0,"id":31378}]}]}
{"op":"mcm","clk":"11853789163","pt":1723319665378,"mc":[{"id":"1.231581624","rc":[{"batb":[[0,2.34,10]],"ltp":2.36,"tv":28.0,"id":31378}]}]}
{"op":"mcm","clk":"11853789510","pt":1723319668780,"mc":[{"id":"1.231581624","rc":[{"batb":[[0,2.34,4]],"ltp":2.36,"tv":28.0,"id":31378}]}]}
{"op":"mcm","clk":"11853789791","pt":1723319671287,"mc":[{"id":"1.231581624","rc":[{"batb":[[0,2.34,10]],"ltp":2.36,"tv":28.0,"id":31378}]}]}
{"op":"mcm","clk":"11853790176","pt":1723319674760,"mc":[{"id":"1.231581624","rc":[{"batb":[[0,2.34,4]],"ltp":2.36,"tv":28.0,"id":31378}]}]}
{"op":"mcm","clk":"11853790426","pt":1723319677189,"mc":[{"id":"1.231581624","rc":[{"batb":[[0,2.34,10]],"ltp":2.36,"tv":28.0,"id":31378}]}]}
{"op":"mcm","clk":"11853790779","pt":1723319680833,"mc":[{"id":"1.231581624","rc":[{"batb":[[0,2.34,4]],"ltp":2.36,"tv":28.0,"id":31378}]}]}
{"op":"mcm","clk":"11853791038","pt":1723319683124,"mc":[{"id":"1.231581624","rc":[{"batb":[[0,2.34,10]],"ltp":2.36,"tv":28.0,"id":31378}]}]}
{"op":"mcm","clk":"11853791418","pt":1723319686423,"mc":[{"id":"1.231581624","rc":[{"batb":[[0,2.32,29.57],[1,1.3,1000],[2,1.08,7.85]],"ltp":2.36,"tv":28.0,"id":31378}]}]}
{"op":"mcm","clk":"11853791432","pt":1723319686524,"mc":[{"id":"1.231581624","rc":[{"batb":[[0,2.34,4],[1,2.32,29.57],[2,1.3,1000]],"ltp":2.36,"tv":28.0,"id":31378}]}]}
{"op":"mcm","clk":"11853791663","pt":1723319688826,"mc":[{"id":"1.231581624","rc":[{"batb":[[0,2.34,10]],"ltp":2.36,"tv":28.0,"id":31378}]}]}
{"op":"mcm","clk":"11853791965","pt":1723319692307,"mc":[{"id":"1.231581624","rc":[{"batb":[[0,2.34,4]],"ltp":2.36,"tv":28.0,"id":31378}]}]}
{"op":"mcm","clk":"11853792197","pt":1723319694817,"mc":[{"id":"1.231581624","rc":[{"batb":[[0,2.34,10]],"ltp":2.36,"tv":28.0,"id":31378}]}]}
{"op":"mcm","clk":"11853792555","pt":1723319698248,"mc":[{"id":"1.231581624","rc":[{"batb":[[0,2.34,4]],"ltp":2.36,"tv":28.0,"id":31378}]}]}
{"op":"mcm","clk":"11853792791","pt":1723319700659,"mc":[{"id":"1.231581624","rc":[{"batb":[[0,2.34,10]],"ltp":2.36,"tv":28.0,"id":31378}]}]}
{"op":"mcm","clk":"11853793234","pt":1723319704139,"mc":[{"id":"1.231581624","rc":[{"batb":[[0,2.34,4]],"ltp":2.36,"tv":28.0,"id":31378}]}]}
{"op":"mcm","clk":"11853793539","pt":1723319706726,"mc":[{"id":"1.231581624","rc":[{"batb":[[0,2.34,10]],"ltp":2.36,"tv":28.0,"id":31378}]}]}
{"op":"mcm","clk":"11853793976","pt":1723319710271,"mc":[{"id":"1.231581624","rc":[{"batb":[[0,2.34,4]],"ltp":2.36,"tv":28.0,"id":31378}]}]}
{"op":"mcm","clk":"11853794350","pt":1723319712490,"mc":[{"id":"1.231581624","rc":[{"batb":[[0,2.32,29.57],[1,1.3,1000],[2,1.08,7.85]],"ltp":2.36,"tv":28.0,"id":31378}]}]}
{"op":"mcm","clk":"11853794360","pt":1723319712596,"mc":[{"id":"1.231581624","rc":[{"batb":[[0,2.34,10],[1,2.32,29.57],[2,1.3,1000]],"ltp":2.36,"tv":28.0,"id":31378}]}]}
{"op":"mcm","clk":"11853794749","pt":1723319715893,"mc":[{"id":"1.231581624","rc":[{"batb":[[0,2.34,4]],"ltp":2.36,"tv":28.0,"id":31378}]}]}
{"op":"mcm","clk":"11853795026","pt":1723319718415,"mc":[{"id":"1.231581624","rc":[{"batb":[[0,2.34,10]],"ltp":2.36,"tv":28.0,"id":31378}]}]}
{"op":"mcm","clk":"11853795383","pt":1723319721715,"mc":[{"id":"1.231581624","rc":[{"batb":[[0,2.34,4]],"ltp":2.36,"tv":28.0,"id":31378}]}]}
{"op":"mcm","clk":"11853795652","pt":1723319724009,"mc":[{"id":"1.231581624","rc":[{"batb":[[0,2.34,10]],"ltp":2.36,"tv":28.0,"id":31378}]}]}
{"op":"mcm","clk":"11853796004","pt":1723319727305,"mc":[{"id":"1.231581624","rc":[{"batb":[[0,2.34,4]],"ltp":2.36,"tv":28.0,"id":31378}]}]}
{"op":"mcm","clk":"11853796319","pt":1723319729727,"mc":[{"id":"1.231581624","rc":[{"batb":[[0,2.34,10]],"ltp":2.36,"tv":28.0,"id":31378}]}]}
{"op":"mcm","clk":"11853796697","pt":1723319733011,"mc":[{"id":"1.231581624","rc":[{"batb":[[0,2.34,4]],"ltp":2.36,"tv":28.0,"id":31378}]}]}
{"op":"mcm","clk":"11853796970","pt":1723319735407,"mc":[{"id":"1.231581624","rc":[{"batb":[[0,2.32,29.57],[1,1.3,1000],[2,1.08,7.85]],"ltp":2.36,"tv":28.0,"id":31378}]}]}
{"op":"mcm","clk":"11853796998","pt":1723319735616,"mc":[{"id":"1.231581624","rc":[{"batb":[[0,2.34,10],[1,2.32,29.57],[2,1.3,1000]],"ltp":2.36,"tv":28.0,"id":31378}]}]}
{"op":"mcm","clk":"11853797356","pt":1723319739007,"mc":[{"id":"1.231581624","rc":[{"batb":[[0,2.34,4]],"ltp":2.36,"tv":28.0,"id":31378}]}]}
{"op":"mcm","clk":"11853797597","pt":1723319741447,"mc":[{"id":"1.231581624","rc":[{"batb":[[0,2.32,29.57],[1,1.3,1000],[2,1.08,7.85]],"ltp":2.36,"tv":28.0,"id":31378}]}]}
{"op":"mcm","clk":"11853797620","pt":1723319741620,"mc":[{"id":"1.231581624","rc":[{"batb":[[0,2.34,10],[1,2.32,29.57],[2,1.3,1000]],"ltp":2.36,"tv":28.0,"id":31378}]}]}
{"op":"mcm","clk":"11853797986","pt":1723319745018,"mc":[{"id":"1.231581624","rc":[{"batb":[[0,2.34,4]],"ltp":2.36,"tv":28.0,"id":31378}]}]}
{"op":"mcm","clk":"11853798193","pt":1723319747328,"mc":[{"id":"1.231581624","rc":[{"batb":[[0,2.34,10]],"ltp":2.36,"tv":28.0,"id":31378}]}]}
{"op":"mcm","clk":"11853798551","pt":1723319750623,"mc":[{"id":"1.231581624","rc":[{"batb":[[0,2.34,4]],"ltp":2.36,"tv":28.0,"id":31378}]}]}
{"op":"mcm","clk":"11853798776","pt":1723319753029,"mc":[{"id":"1.231581624","rc":[{"batb":[[0,2.34,10]],"ltp":2.36,"tv":28.0,"id":31378}]}]}
{"op":"mcm","clk":"11853799078","pt":1723319756316,"mc":[{"id":"1.231581624","rc":[{"batb":[[0,2.34,4]],"ltp":2.36,"tv":28.0,"id":31378}]}]}
{"op":"mcm","clk":"11853799294","pt":1723319758508,"mc":[{"id":"1.231581624","rc":[{"batb":[[0,2.32,29.57],[1,1.3,1000],[2,1.08,7.85]],"ltp":2.36,"tv":28.0,"id":31378}]}]}
{"op":"mcm","clk":"11853799306","pt":1723319758613,"mc":[{"id":"1.231581624","rc":[{"batb":[[0,2.34,10],[1,2.32,29.57],[2,1.3,1000]],"ltp":2.36,"tv":28.0,"id":31378}]}]}
{"op":"mcm","clk":"11853799635","pt":1723319762125,"mc":[{"id":"1.231581624","rc":[{"batb":[[0,2.34,4]],"ltp":2.36,"tv":28.0,"id":31378}]}]}
{"op":"mcm","clk":"11853799907","pt":1723319764433,"mc":[{"id":"1.231581624","rc":[{"batb":[[0,2.32,29.57],[1,1.3,1000],[2,1.08,7.85]],"ltp":2.36,"tv":28.0,"id":31378}]}]}
{"op":"mcm","clk":"11853799917","pt":1723319764533,"mc":[{"id":"1.231581624","rc":[{"batb":[[0,2.34,10],[1,2.32,29.57],[2,1.3,1000]],"ltp":2.36,"tv":28.0,"id":31378}]}]}
{"op":"mcm","clk":"11853800237","pt":1723319767737,"mc":[{"id":"1.231581624","rc":[{"batb":[[0,2.34,4]],"ltp":2.36,"tv":28.0,"id":31378}]}]}
{"op":"mcm","clk":"11853800460","pt":1723319770160,"mc":[{"id":"1.231581624","rc":[{"batb":[[0,2.34,10]],"ltp":2.36,"tv":28.0,"id":31378}]}]}
{"op":"mcm","clk":"11853800789","pt":1723319773671,"mc":[{"id":"1.231581624","rc":[{"batb":[[0,2.34,4]],"ltp":2.36,"tv":28.0,"id":31378}]}]}
{"op":"mcm","clk":"11853801020","pt":1723319776136,"mc":[{"id":"1.231581624","rc":[{"batb":[[0,2.34,10]],"ltp":2.36,"tv":28.0,"id":31378}]}]}
{"op":"mcm","clk":"11853801346","pt":1723319779426,"mc":[{"id":"1.231581624","rc":[{"batb":[[0,2.34,4]],"ltp":2.36,"tv":28.0,"id":31378}]}]}
{"op":"mcm","clk":"11853801608","pt":1723319781927,"mc":[{"id":"1.231581624","rc":[{"batb":[[0,2.34,10]],"ltp":2.36,"tv":28.0,"id":31378}]}]}
{"op":"mcm","clk":"11853801936","pt":1723319785257,"mc":[{"id":"1.231581624","rc":[{"batb":[[0,2.34,4]],"ltp":2.36,"tv":28.0,"id":31378}]}]}
{"op":"mcm","clk":"11853802140","pt":1723319787451,"mc":[{"id":"1.231581624","rc":[{"batb":[[0,2.32,29.57],[1,1.3,1000],[2,1.08,7.85]],"ltp":2.36,"tv":28.0,"id":31378}]}]}
{"op":"mcm","clk":"11853802157","pt":1723319787560,"mc":[{"id":"1.231581624","rc":[{"batb":[[0,2.34,10],[1,2.32,29.57],[2,1.3,1000]],"ltp":2.36,"tv":28.0,"id":31378}]}]}
{"op":"mcm","clk":"11853802461","pt":1723319790964,"mc":[{"id":"1.231581624","rc":[{"batb":[[0,2.34,4]],"ltp":2.36,"tv":28.0,"id":31378}]}]}
{"op":"mcm","clk":"11853802725","pt":1723319793475,"mc":[{"id":"1.231581624","rc":[{"batb":[[0,2.34,10]],"ltp":2.36,"tv":28.0,"id":31378}]}]}
{"op":"mcm","clk":"11853803073","pt":1723319796859,"mc":[{"id":"1.231581624","rc":[{"batb":[[0,2.34,4]],"ltp":2.36,"tv":28.0,"id":31378}]}]}
{"op":"mcm","clk":"11853803306","pt":1723319799265,"mc":[{"id":"1.231581624","rc":[{"batb":[[0,2.34,10]],"ltp":2.36,"tv":28.0,"id":31378}]}]}
{"op":"mcm","clk":"11853803613","pt":1723319802470,"mc":[{"id":"1.231581624","rc":[{"batb":[[0,2.32,29.57],[1,1.3,1000],[2,1.08,7.85]],"ltp":2.36,"tv":28.0,"id":31378}]}]}
{"op":"mcm","clk":"11853803654","pt":1723319802670,"mc":[{"id":"1.231581624","rc":[{"batb":[[0,2.34,4],[1,2.32,29.57],[2,1.3,1000]],"ltp":2.36,"tv":28.0,"id":31378}]}]}
{"op":"mcm","clk":"11853803886","pt":1723319805183,"mc":[{"id":"1.231581624","rc":[{"batb":[[0,2.34,10]],"ltp":2.36,"tv":28.0,"id":31378}]}]}
{"op":"mcm","clk":"11853804249","pt":1723319808471,"mc":[{"id":"1.231581624","rc":[{"batb":[[0,2.32,29.57],[1,1.3,1000],[2,1.08,7.85]],"ltp":2.36,"tv":28.0,"id":31378}]}]}
{"op":"mcm","clk":"11853804265","pt":1723319808577,"mc":[{"id":"1.231581624","rc":[{"batb":[[0,2.34,4],[1,2.32,29.57],[2,1.3,1000]],"ltp":2.36,"tv":28.0,"id":31378}]}]}
{"op":"mcm","clk":"11853804518","pt":1723319810910,"mc":[{"id":"1.231581624","rc":[{"batb":[[0,2.34,10]],"ltp":2.36,"tv":28.0,"id":31378}]}]}
{"op":"mcm","clk":"11853804863","pt":1723319814300,"mc":[{"id":"1.231581624","rc":[{"batb":[[0,2.34,4]],"ltp":2.36,"tv":28.0,"id":31378}]}]}
{"op":"mcm","clk":"11853805168","pt":1723319816791,"mc":[{"id":"1.231581624","rc":[{"batb":[[0,2.34,10]],"ltp":2.36,"tv":28.0,"id":31378}]}]}
{"op":"mcm","clk":"11853805538","pt":1723319820192,"mc":[{"id":"1.231581624","rc":[{"batb":[[0,2.34,4]],"ltp":2.36,"tv":28.0,"id":31378}]}]}
{"op":"mcm","clk":"11853805777","pt":1723319822494,"mc":[{"id":"1.231581624","rc":[{"batb":[[0,2.34,10]],"ltp":2.36,"tv":28.0,"id":31378}]}]}
{"op":"mcm","clk":"11853806163","pt":1723319825879,"mc":[{"id":"1.231581624","rc":[{"batb":[[0,2.34,4]],"ltp":2.36,"tv":28.0,"id":31378}]}]}
{"op":"mcm","clk":"11853806425","pt":1723319828385,"mc":[{"id":"1.231581624","rc":[{"batb":[[0,2.34,10]],"ltp":2.36,"tv":28.0,"id":31378}]}]}
{"op":"mcm","clk":"11853806774","pt":1723319831884,"mc":[{"id":"1.231581624","rc":[{"batb":[[0,2.34,4]],"ltp":2.36,"tv":28.0,"id":31378}]}]}
{"op":"mcm","clk":"11853807021","pt":1723319834391,"mc":[{"id":"1.231581624","rc":[{"batb":[[0,2.34,10]],"ltp":2.36,"tv":28.0,"id":31378}]}]}
{"op":"mcm","clk":"11853807373","pt":1723319837884,"mc":[{"id":"1.231581624","rc":[{"batb":[[0,2.34,4]],"ltp":2.36,"tv":28.0,"id":31378}]}]}
{"op":"mcm","clk":"11853807615","pt":1723319840505,"mc":[{"id":"1.231581624","rc":[{"batb":[[0,2.34,10]],"ltp":2.36,"tv":28.0,"id":31378}]}]}
{"op":"mcm","clk":"11853807940","pt":1723319843817,"mc":[{"id":"1.231581624","rc":[{"batb":[[0,2.34,4]],"ltp":2.36,"tv":28.0,"id":31378}]}]}
{"op":"mcm","clk":"11853808192","pt":1723319846433,"mc":[{"id":"1.231581624","rc":[{"batb":[[0,2.34,10]],"ltp":2.36,"tv":28.0,"id":31378}]}]}
{"op":"mcm","clk":"11853808524","pt":1723319849649,"mc":[{"id":"1.231581624","rc":[{"batb":[[0,2.34,4]],"ltp":2.36,"tv":28.0,"id":31378}]}]}
{"op":"mcm","clk":"11853808836","pt":1723319852219,"mc":[{"id":"1.231581624","rc":[{"batb":[[0,2.34,10]],"ltp":2.36,"tv":28.0,"id":31378}]}]}
{"op":"mcm","clk":"11853809208","pt":1723319855623,"mc":[{"id":"1.231581624","rc":[{"batb":[[0,2.34,4]],"ltp":2.36,"tv":28.0,"id":31378}]}]}
{"op":"mcm","clk":"11853809455","pt":1723319857923,"mc":[{"id":"1.231581624","rc":[{"batb":[[0,2.34,10]],"ltp":2.36,"tv":28.0,"id":31378}]}]}
{"op":"mcm","clk":"11853809817","pt":1723319861219,"mc":[{"id":"1.231581624","rc":[{"batb":[[0,2.34,4]],"ltp":2.36,"tv":28.0,"id":31378}]}]}
{"op":"mcm","clk":"11853810035","pt":1723319863417,"mc":[{"id":"1.231581624","rc":[{"batb":[[0,2.32,29.57],[1,1.3,1000],[2,1.08,7.85]],"ltp":2.36,"tv":28.0,"id":31378}]}]}
{"op":"mcm","clk":"11853810043","pt":1723319863570,"mc":[{"id":"1.231581624","rc":[{"batb":[[0,2.34,10],[1,2.32,29.57],[2,1.3,1000]],"ltp":2.36,"tv":28.0,"id":31378}]}]}
{"op":"mcm","clk":"11853810440","pt":1723319867052,"mc":[{"id":"1.231581624","rc":[{"batb":[[0,2.34,4]],"ltp":2.36,"tv":28.0,"id":31378}]}]}
{"op":"mcm","clk":"11853810702","pt":1723319869444,"mc":[{"id":"1.231581624","rc":[{"batb":[[0,2.34,10]],"ltp":2.36,"tv":28.0,"id":31378}]}]}
{"op":"mcm","clk":"11853811019","pt":1723319873058,"mc":[{"id":"1.231581624","rc":[{"batb":[[0,2.34,4]],"ltp":2.36,"tv":28.0,"id":31378}]}]}
{"op":"mcm","clk":"11853811245","pt":1723319875658,"mc":[{"id":"1.231581624","rc":[{"batb":[[0,2.34,10]],"ltp":2.36,"tv":28.0,"id":31378}]}]}
{"op":"mcm","clk":"11853811637","pt":1723319879240,"mc":[{"id":"1.231581624","rc":[{"batb":[[0,2.34,4]],"ltp":2.36,"tv":28.0,"id":31378}]}]}
{"op":"mcm","clk":"11853811877","pt":1723319881498,"mc":[{"id":"1.231581624","rc":[{"batb":[[0,2.32,29.57],[1,1.3,1000],[2,1.08,7.85]],"ltp":2.36,"tv":28.0,"id":31378}]}]}
{"op":"mcm","clk":"11853811899","pt":1723319881643,"mc":[{"id":"1.231581624","rc":[{"batb":[[0,2.34,10],[1,2.32,29.57],[2,1.3,1000]],"ltp":2.36,"tv":28.0,"id":31378}]}]}
{"op":"mcm","clk":"11853812366","pt":1723319885072,"mc":[{"id":"1.231581624","rc":[{"batb":[[0,2.34,4]],"ltp":2.36,"tv":28.0,"id":31378}]}]}
{"op":"mcm","clk":"11853812689","pt":1723319887499,"mc":[{"id":"1.231581624","rc":[{"batb":[[0,2.34,10]],"ltp":2.36,"tv":28.0,"id":31378}]}]}
{"op":"mcm","clk":"11853813075","pt":1723319890378,"mc":[{"id":"1.231581624","rc":[{"batb":[[2,1.61,4.56]],"ltp":1.73,"tv":69.5,"id":5995}]}]}
{"op":"mcm","clk":"11853813117","pt":1723319890776,"mc":[{"id":"1.231581624","rc":[{"batb":[[0,2.36,4]],"ltp":2.36,"tv":28.0,"id":31378}]}]}
{"op":"mcm","clk":"11853813382","pt":1723319892884,"mc":[{"id":"1.231581624","rc":[{"batb":[[0,2.34,10]],"ltp":2.36,"tv":28.0,"id":31378}]}]}
{"op":"mcm","clk":"11853813804","pt":1723319896279,"mc":[{"id":"1.231581624","rc":[{"batb":[[0,2.34,4]],"ltp":2.36,"tv":28.0,"id":31378}]}]}
{"op":"mcm","clk":"11853814129","pt":1723319898856,"mc":[{"id":"1.231581624","rc":[{"batb":[[0,2.34,10]],"ltp":2.36,"tv":28.0,"id":31378}]}]}
{"op":"mcm","clk":"11853814485","pt":1723319902204,"mc":[{"id":"1.231581624","rc":[{"batb":[[0,2.34,4]],"ltp":2.36,"tv":28.0,"id":31378}]}]}
{"op":"mcm","clk":"11853814752","pt":1723319904660,"mc":[{"id":"1.231581624","rc":[{"batb":[[0,2.34,10]],"ltp":2.36,"tv":28.0,"id":31378}]}]}
{"op":"mcm","clk":"11853815095","pt":1723319908003,"mc":[{"id":"1.231581624","rc":[{"batb":[[0,2.36,4]],"ltp":2.36,"tv":28.0,"id":31378}]}]}
{"op":"mcm","clk":"11853815298","pt":1723319909781,"mc":[{"id":"1.231581624","rc":[{"batb":[[0,2.32,29.57],[1,1.3,1000],[2,1.08,7.85]],"ltp":2.36,"tv":28.0,"id":31378}]}]}
{"op":"mcm","clk":"11853815495","pt":1723319911603,"mc":[{"id":"1.231581624","rc":[{"batb":[[0,2.34,10],[1,2.32,29.57],[2,1.3,1000]],"ltp":2.36,"tv":28.0,"id":31378}]}]}
{"op":"mcm","clk":"11853815895","pt":1723319915020,"mc":[{"id":"1.231581624","rc":[{"batb":[[0,2.34,4]],"ltp":2.36,"tv":28.0,"id":31378}]}]}
{"op":"mcm","clk":"11853816122","pt":1723319917427,"mc":[{"id":"1.231581624","rc":[{"batb":[[0,2.32,29.57],[1,1.3,1000],[2,1.08,7.85]],"ltp":2.36,"tv":28.0,"id":31378}]}]}
{"op":"mcm","clk":"11853816138","pt":1723319917603,"mc":[{"id":"1.231581624","rc":[{"batb":[[0,2.34,10],[1,2.32,29.57],[2,1.3,1000]],"ltp":2.36,"tv":28.0,"id":31378}]}]}
{"op":"mcm","clk":"11853816448","pt":1723319920832,"mc":[{"id":"1.231581624","rc":[{"batb":[[0,2.34,4]],"ltp":2.36,"tv":28.0,"id":31378}]}]}
{"op":"mcm","clk":"11853816758","pt":1723319923266,"mc":[{"id":"1.231581624","rc":[{"batb":[[0,2.34,10]],"ltp":2.36,"tv":28.0,"id":31378}]}]}
{"op":"mcm","clk":"11853816947","pt":1723319925251,"mc":[{"id":"1.231581624","rc":[{"batb":[[0,2.36,4],[1,2.34,10],[2,2.32,29.57]],"ltp":2.36,"tv":28.0,"id":31378}]}]}
{"op":"mcm","clk":"11853817177","pt":1723319927458,"mc":[{"id":"1.231581624","rc":[{"batb":[[0,2.32,29.57],[1,1.3,1000],[2,1.08,7.85]],"ltp":2.36,"tv":28.0,"id":31378}]}]}
{"op":"mcm","clk":"11853817524","pt":1723319930274,"mc":[{"id":"1.231581624","rc":[{"batb":[[0,2.34,14],[1,2.32,29.57],[2,1.3,1000]],"ltp":2.36,"tv":28.0,"id":31378}]}]}
{"op":"mcm","clk":"11853817728","pt":1723319932578,"mc":[{"id":"1.231581624","rc":[{"batb":[[0,2.34,10]],"ltp":2.36,"tv":28.0,"id":31378}]}]}
{"op":"mcm","clk":"11853817945","pt":1723319934363,"mc":[{"id":"1.231581624","rc":[{"batb":[[0,2.32,29.57],[1,1.3,1000],[2,1.08,7.85]],"ltp":2.36,"tv":28.0,"id":31378}]}]}
{"op":"mcm","clk":"11853818128","pt":1723319936188,"mc":[{"id":"1.231581624","rc":[{"batb":[[0,2.34,14],[1,2.32,29.57],[2,1.3,1000]],"ltp":2.36,"tv":28.0,"id":31378}]}]}
{"op":"mcm","clk":"11853818397","pt":1723319938387,"mc":[{"id":"1.231581624","rc":[{"batb":[[0,2.34,10]],"ltp":2.36,"tv":28.0,"id":31378}]}]}
{"op":"mcm","clk":"11853818529","pt":1723319939490,"mc":[{"id":"1.231581624","rc":[{"batb":[[0,2.32,29.57],[1,1.3,1000],[2,1.08,7.85]],"ltp":2.36,"tv":28.0,"id":31378}]}]}
{"op":"mcm","clk":"11853819109","pt":1723319944486,"mc":[{"id":"1.231581624","rc":[{"batb":[[0,2.34,14],[1,2.32,29.57],[2,1.3,1000]],"ltp":2.36,"tv":28.0,"id":31378}]}]}
{"op":"mcm","clk":"11853819352","pt":1723319946883,"mc":[{"id":"1.231581624","rc":[{"batb":[[0,2.34,10]],"ltp":2.36,"tv":28.0,"id":31378}]}]}
{"op":"mcm","clk":"11853819446","pt":1723319947887,"mc":[{"id":"1.231581624","rc":[{"batb":[[0,2.32,29.57],[1,1.3,1000],[2,1.08,7.85]],"ltp":2.36,"tv":28.0,"id":31378}]}]}
{"op":"mcm","clk":"11853819763","pt":1723319950200,"mc":[{"id":"1.231581624","rc":[{"batb":[[0,2.36,10],[1,2.34,4],[2,2.32,29.57]],"ltp":2.36,"tv":28.0,"id":31378}]}]}
{"op":"mcm","clk":"11853820030","pt":1723319952336,"mc":[{"id":"1.231581624","rc":[{"batb":[[1,2.32,29.57],[2,1.3,1000]],"ltp":2.36,"tv":28.0,"id":31378}]}]}
{"op":"mcm","clk":"11853820134","pt":1723319953392,"mc":[{"id":"1.231581624","rc":[{"batb":[[0,2.32,29.57],[1,1.3,1000],[2,1.08,7.85]],"ltp":2.36,"tv":28.0,"id":31378}]}]}
{"op":"mcm","clk":"11853820386","pt":1723319955604,"mc":[{"id":"1.231581624","rc":[{"batb":[[0,2.34,14],[1,2.32,29.57],[2,1.3,1000]],"ltp":2.36,"tv":28.0,"id":31378}]}]}
{"op":"mcm","clk":"11853820637","pt":1723319957814,"mc":[{"id":"1.231581624","rc":[{"batb":[[0,2.34,10]],"ltp":2.36,"tv":28.0,"id":31378}]}]}
{"op":"mcm","clk":"11853820784","pt":1723319958990,"mc":[{"id":"1.231581624","rc":[{"batb":[[0,2.32,29.57],[1,1.3,1000],[2,1.08,7.85]],"ltp":2.36,"tv":28.0,"id":31378}]}]}
{"op":"mcm","clk":"11853821749","pt":1723319967603,"mc":[{"id":"1.231581624","rc":[{"batb":[[0,2.34,14],[1,2.32,29.57],[2,1.3,1000]],"ltp":2.36,"tv":28.0,"id":31378}]}]}
{"op":"mcm","clk":"11853822033","pt":1723319970007,"mc":[{"id":"1.231581624","rc":[{"batb":[[0,2.34,10]],"ltp":2.36,"tv":28.0,"id":31378}]}]}
{"op":"mcm","clk":"11853822140","pt":1723319971004,"mc":[{"id":"1.231581624","rc":[{"batb":[[0,2.32,29.57],[1,1.3,1000],[2,1.08,7.85]],"ltp":2.36,"tv":28.0,"id":31378}]}]}
{"op":"mcm","clk":"11853822293","pt":1723319972310,"mc":[{"id":"1.231581624","rc":[{"batb":[[0,2.34,4],[1,2.32,29.57],[2,1.3,1000]],"ltp":2.36,"tv":28.0,"id":31378}]}]}
{"op":"mcm","clk":"11853822603","pt":1723319974717,"mc":[{"id":"1.231581624","rc":[{"batb":[[0,2.34,10]],"ltp":2.36,"tv":28.0,"id":31378}]}]}
{"op":"mcm","clk":"11853822995","pt":1723319977943,"mc":[{"id":"1.231581624","rc":[{"batb":[[0,2.36,4]],"ltp":2.36,"tv":28.0,"id":31378}]}]}
{"op":"mcm","clk":"11853823266","pt":1723319980416,"mc":[{"id":"1.231581624","rc":[{"batb":[[0,2.34,10]],"ltp":2.36,"tv":28.0,"id":31378}]}]}
{"op":"mcm","clk":"11853823713","pt":1723319983937,"mc":[{"id":"1.231581624","rc":[{"batb":[[0,2.34,4]],"ltp":2.36,"tv":28.0,"id":31378}]}]}
{"op":"mcm","clk":"11853824003","pt":1723319986359,"mc":[{"id":"1.231581624","rc":[{"batb":[[0,2.32,29.57],[1,1.3,1000],[2,1.08,7.85]],"ltp":2.36,"tv":28.0,"id":31378}]}]}
{"op":"mcm","clk":"11853824029","pt":1723319986521,"mc":[{"id":"1.231581624","rc":[{"batb":[[0,2.34,10],[1,2.32,29.57],[2,1.3,1000]],"ltp":2.36,"tv":28.0,"id":31378}]}]}
{"op":"mcm","clk":"11853824438","pt":1723319990060,"mc":[{"id":"1.231581624","rc":[{"batb":[[0,2.34,4]],"ltp":2.36,"tv":28.0,"id":31378}]}]}
{"op":"mcm","clk":"11853824733","pt":1723319992441,"mc":[{"id":"1.231581624","rc":[{"batb":[[0,2.34,10]],"ltp":2.36,"tv":28.0,"id":31378}]}]}
{"op":"mcm","clk":"11853825072","pt":1723319995839,"mc":[{"id":"1.231581624","rc":[{"batb":[[0,2.34,4]],"ltp":2.36,"tv":28.0,"id":31378}]}]}
{"op":"mcm","clk":"11853825342","pt":1723319998354,"mc":[{"id":"1.231581624","rc":[{"batb":[[0,2.34,10]],"ltp":2.36,"tv":28.0,"id":31378}]}]}
{"op":"mcm","clk":"11853825780","pt":1723320001640,"mc":[{"id":"1.231581624","rc":[{"batb":[[0,2.34,4]],"ltp":2.36,"tv":28.0,"id":31378}]}]}
{"op":"mcm","clk":"11853826177","pt":1723320004072,"mc":[{"id":"1.231581624","rc":[{"batb":[[0,2.34,10]],"ltp":2.36,"tv":28.0,"id":31378}]}]}
{"op":"mcm","clk":"11853826696","pt":1723320007447,"mc":[{"id":"1.231581624","rc":[{"batb":[[0,2.34,4]],"ltp":2.36,"tv":28.0,"id":31378}]}]}
{"op":"mcm","clk":"11853827012","pt":1723320010061,"mc":[{"id":"1.231581624","rc":[{"batb":[[0,2.34,10]],"ltp":2.36,"tv":28.0,"id":31378}]}]}
{"op":"mcm","clk":"11853827453","pt":1723320013456,"mc":[{"id":"1.231581624","rc":[{"batb":[[0,2.32,29.57],[1,1.3,1000],[2,1.08,7.85]],"ltp":2.36,"tv":28.0,"id":31378}]}]}
{"op":"mcm","clk":"11853827465","pt":1723320013555,"mc":[{"id":"1.231581624","rc":[{"batb":[[0,2.34,4],[1,2.32,29.57],[2,1.3,1000]],"ltp":2.36,"tv":28.0,"id":31378}]}]}
{"op":"mcm","clk":"11853827808","pt":1723320015973,"mc":[{"id":"1.231581624","rc":[{"batb":[[0,2.34,10]],"ltp":2.36,"tv":28.0,"id":31378}]}]}
{"op":"mcm","clk":"11853828291","pt":1723320019350,"mc":[{"id":"1.231581624","rc":[{"batb":[[0,2.34,4]],"ltp":2.36,"tv":28.0,"id":31378}]}]}
{"op":"mcm","clk":"11853828619","pt":1723320021767,"mc":[{"id":"1.231581624","rc":[{"batb":[[0,2.34,10]],"ltp":2.36,"tv":28.0,"id":31378}]}]}
{"op":"mcm","clk":"11853829088","pt":1723320025255,"mc":[{"id":"1.231581624","rc":[{"batb":[[0,2.34,4]],"ltp":2.36,"tv":28.0,"id":31378}]}]}
{"op":"mcm","clk":"11853829396","pt":1723320027773,"mc":[{"id":"1.231581624","rc":[{"batb":[[0,2.34,10]],"ltp":2.36,"tv":28.0,"id":31378}]}]}
{"op":"mcm","clk":"11853829923","pt":1723320031194,"mc":[{"id":"1.231581624","rc":[{"batb":[[0,2.34,4]],"ltp":2.36,"tv":28.0,"id":31378}]}]}
{"op":"mcm","clk":"11853830306","pt":1723320033674,"mc":[{"id":"1.231581624","rc":[{"batb":[[0,2.34,10]],"ltp":2.36,"tv":28.0,"id":31378}]}]}
{"op":"mcm","clk":"11853830750","pt":1723320037183,"mc":[{"id":"1.231581624","rc":[{"batb":[[0,2.34,4]],"ltp":2.36,"tv":28.0,"id":31378}]}]}
{"op":"mcm","clk":"11853831075","pt":1723320039484,"mc":[{"id":"1.231581624","rc":[{"batb":[[0,2.32,29.57],[1,1.3,1000],[2,1.08,7.85]],"ltp":2.36,"tv":28.0,"id":31378}]}]}
{"op":"mcm","clk":"11853831095","pt":1723320039676,"mc":[{"id":"1.231581624","rc":[{"batb":[[0,2.34,10],[1,2.32,29.57],[2,1.3,1000]],"ltp":2.36,"tv":28.0,"id":31378}]}]}
{"op":"mcm","clk":"11853831511","pt":1723320042880,"mc":[{"id":"1.231581624","rc":[{"batb":[[0,2.36,4]],"ltp":2.36,"tv":28.0,"id":31378}]}]}
{"op":"mcm","clk":"11853831805","pt":1723320045300,"mc":[{"id":"1.231581624","rc":[{"batb":[[0,2.34,10]],"ltp":2.36,"tv":28.0,"id":31378}]}]}
{"op":"mcm","clk":"11853832287","pt":1723320048792,"mc":[{"id":"1.231581624","rc":[{"batb":[[0,2.34,4]],"ltp":2.36,"tv":28.0,"id":31378}]}]}
{"op":"mcm","clk":"11853832572","pt":1723320051185,"mc":[{"id":"1.231581624","rc":[{"batb":[[0,2.34,10]],"ltp":2.36,"tv":28.0,"id":31378}]}]}
{"op":"mcm","clk":"11853832988","pt":1723320054499,"mc":[{"id":"1.231581624","rc":[{"batb":[[0,2.32,29.57],[1,1.3,1000],[2,1.08,7.85]],"ltp":2.36,"tv":28.0,"id":31378}]}]}
{"op":"mcm","clk":"11853833010","pt":1723320054607,"mc":[{"id":"1.231581624","rc":[{"batb":[[0,2.34,4],[1,2.32,29.57],[2,1.3,1000]],"ltp":2.36,"tv":28.0,"id":31378}]}]}
{"op":"mcm","clk":"11853833370","pt":1723320057217,"mc":[{"id":"1.231581624","rc":[{"batb":[[0,2.34,10]],"ltp":2.36,"tv":28.0,"id":31378}]}]}
{"op":"mcm","clk":"11853833797","pt":1723320060420,"mc":[{"id":"1.231581624","rc":[{"batb":[[0,2.32,29.57],[1,1.3,1000],[2,1.08,7.85]],"ltp":2.36,"tv":28.0,"id":31378}]}]}
{"op":"mcm","clk":"11853833870","pt":1723320060626,"mc":[{"id":"1.231581624","rc":[{"batb":[[0,2.34,4],[1,2.32,29.57],[2,1.3,1000]],"ltp":2.36,"tv":28.0,"id":31378}]}]}
{"op":"mcm","clk":"11853834239","pt":1723320063034,"mc":[{"id":"1.231581624","rc":[{"batb":[[0,2.34,10]],"ltp":2.36,"tv":28.0,"id":31378}]}]}
{"op":"mcm","clk":"11853834759","pt":1723320066413,"mc":[{"id":"1.231581624","rc":[{"batb":[[0,2.34,4]],"ltp":2.36,"tv":28.0,"id":31378}]}]}
{"op":"mcm","clk":"11853835074","pt":1723320068828,"mc":[{"id":"1.231581624","rc":[{"batb":[[0,2.34,10]],"ltp":2.36,"tv":28.0,"id":31378}]}]}
{"op":"mcm","clk":"11853835502","pt":1723320072325,"mc":[{"id":"1.231581624","rc":[{"batb":[[0,2.34,4]],"ltp":2.36,"tv":28.0,"id":31378}]}]}
{"op":"mcm","clk":"11853835887","pt":1723320074958,"mc":[{"id":"1.231581624","rc":[{"batb":[[0,2.34,10]],"ltp":2.36,"tv":28.0,"id":31378}]}]}
{"op":"mcm","clk":"11853836193","pt":1723320077424,"mc":[{"id":"1.231581624","rc":[{"batb":[[0,2.36,4],[1,2.34,10],[2,2.32,29.57]],"ltp":2.36,"tv":28.0,"id":31378}]}]}
{"op":"mcm","clk":"11853836316","pt":1723320078427,"mc":[{"id":"1.231581624","rc":[{"batb":[[1,2.32,29.57],[2,1.3,1000]],"ltp":2.36,"tv":28.0,"id":31378}]}]}
{"op":"mcm","clk":"11853836511","pt":1723320079836,"mc":[{"id":"1.231581624","rc":[{"batb":[[0,2.32,29.57],[1,1.3,1000],[2,1.08,7.85]],"ltp":2.36,"tv":28.0,"id":31378}]}]}
{"op":"mcm","clk":"11853836975","pt":1723320083754,"mc":[{"id":"1.231581624","rc":[{"batb":[[0,2.34,14],[1,2.32,29.57],[2,1.3,1000]],"ltp":2.36,"tv":28.0,"id":31378}]}]}
{"op":"mcm","clk":"11853837260","pt":1723320086232,"mc":[{"id":"1.231581624","rc":[{"batb":[[0,2.34,10]],"ltp":2.36,"tv":28.0,"id":31378}]}]}
{"op":"mcm","clk":"11853837372","pt":1723320087140,"mc":[{"id":"1.231581624","rc":[{"batb":[[0,2.32,29.57],[1,1.3,1000],[2,1.08,7.85]],"ltp":2.36,"tv":28.0,"id":31378}]}]}
{"op":"mcm","clk":"11853838219","pt":1723320094235,"mc":[{"id":"1.231581624","rc":[{"batb":[[0,2.34,14],[1,2.32,29.57],[2,1.3,1000]],"ltp":2.36,"tv":28.0,"id":31378}]}]}
{"op":"mcm","clk":"11853838675","pt":1723320097440,"mc":[{"id":"1.231581624","rc":[{"batb":[[0,2.32,29.57],[1,1.3,1000],[2,1.08,7.85]],"ltp":2.36,"tv":28.0,"id":31378}]}]}
{"op":"mcm","clk":"11853839050","pt":1723320100270,"mc":[{"id":"1.231581624","rc":[{"batb":[[0,2.34,14],[1,2.32,29.57],[2,1.3,1000]],"ltp":2.36,"tv":28.0,"id":31378}]}]}
{"op":"mcm","clk":"11853839350","pt":1723320102667,"mc":[{"id":"1.231581624","rc":[{"batb":[[0,2.34,10]],"ltp":2.36,"tv":28.0,"id":31378}]}]}
{"op":"mcm","clk":"11853839472","pt":1723320103667,"mc":[{"id":"1.231581624","rc":[{"batb":[[0,2.32,29.57],[1,1.3,1000],[2,1.08,7.85]],"ltp":2.36,"tv":28.0,"id":31378}]}]}
{"op":"mcm","clk":"11853839814","pt":1723320106184,"mc":[{"id":"1.231581624","rc":[{"batb":[[0,2.34,14],[1,2.32,29.57],[2,1.3,1000]],"ltp":2.36,"tv":28.0,"id":31378}]}]}
{"op":"mcm","clk":"11853840157","pt":1723320108568,"mc":[{"id":"1.231581624","rc":[{"batb":[[0,2.34,10]],"ltp":2.36,"tv":28.0,"id":31378}]}]}
{"op":"mcm","clk":"11853840279","pt":1723320109602,"mc":[{"id":"1.231581624","rc":[{"batb":[[0,2.32,29.57],[1,1.3,1000],[2,1.08,7.85]],"ltp":2.36,"tv":28.0,"id":31378}]}]}
{"op":"mcm","clk":"11853843563","pt":1723320133292,"mc":[{"id":"1.231581624","rc":[{"batb":[[0,2.34,14],[1,2.32,29.57],[2,1.3,1000]],"ltp":2.36,"tv":28.0,"id":31378}]}]}
{"op":"mcm","clk":"11853843899","pt":1723320135807,"mc":[{"id":"1.231581624","rc":[{"batb":[[0,2.34,10]],"ltp":2.36,"tv":28.0,"id":31378}]}]}
{"op":"mcm","clk":"11853844017","pt":1723320136709,"mc":[{"id":"1.231581624","rc":[{"batb":[[0,2.32,29.57],[1,1.3,1000],[2,1.08,7.85]],"ltp":2.36,"tv":28.0,"id":31378}]}]}
{"op":"mcm","clk":"11853844907","pt":1723320143017,"mc":[{"id":"1.231581624","rc":[{"batb":[[0,2.34,14],[1,2.32,29.57],[2,1.3,1000]],"ltp":2.36,"tv":28.0,"id":31378}]}]}
{"op":"mcm","clk":"11853845273","pt":1723320145610,"mc":[{"id":"1.231581624","rc":[{"batb":[[0,2.34,10]],"ltp":2.36,"tv":28.0,"id":31378}]}]}
{"op":"mcm","clk":"11853845398","pt":1723320146602,"mc":[{"id":"1.231581624","rc":[{"batb":[[0,2.32,29.57],[1,1.3,1000],[2,1.08,7.85]],"ltp":2.36,"tv":28.0,"id":31378}]}]}
{"op":"mcm","clk":"11853845637","pt":1723320148267,"mc":[{"id":"1.231581624","rc":[{"batb":[[0,2.34,4],[1,2.32,29.57],[2,1.3,1000]],"ltp":2.36,"tv":28.0,"id":31378}]}]}
{"op":"mcm","clk":"11853845995","pt":1723320150708,"mc":[{"id":"1.231581624","rc":[{"batb":[[0,2.34,10]],"ltp":2.36,"tv":28.0,"id":31378}]}]}
{"op":"mcm","clk":"11853846473","pt":1723320154222,"mc":[{"id":"1.231581624","rc":[{"batb":[[0,2.34,4]],"ltp":2.36,"tv":28.0,"id":31378}]}]}
{"op":"mcm","clk":"11853846842","pt":1723320156728,"mc":[{"id":"1.231581624","rc":[{"batb":[[0,2.34,10]],"ltp":2.36,"tv":28.0,"id":31378}]}]}
{"op":"mcm","clk":"11853847137","pt":1723320159033,"mc":[{"id":"1.231581624","rc":[{"batb":[[0,2.36,4],[1,2.34,10],[2,2.32,29.57]],"ltp":2.36,"tv":28.0,"id":31378}]}]}
{"op":"mcm","clk":"11853847279","pt":1723320160125,"mc":[{"id":"1.231581624","rc":[{"batb":[[1,2.32,29.57],[2,1.3,1000]],"ltp":2.36,"tv":28.0,"id":31378}]}]}
{"op":"mcm","clk":"11853847446","pt":1723320161434,"mc":[{"id":"1.231581624","rc":[{"batb":[[0,2.32,29.57],[1,1.3,1000],[2,1.08,7.85]],"ltp":2.36,"tv":28.0,"id":31378}]}]}
{"op":"mcm","clk":"11853848421","pt":1723320168750,"mc":[{"id":"1.231581624","rc":[{"batb":[[0,2.34,14],[1,2.32,29.57],[2,1.3,1000]],"ltp":2.36,"tv":28.0,"id":31378}]}]}
{"op":"mcm","clk":"11853848721","pt":1723320171034,"mc":[{"id":"1.231581624","rc":[{"batb":[[0,2.34,10]],"ltp":2.36,"tv":28.0,"id":31378}]}]}
{"op":"mcm","clk":"11853848834","pt":1723320171927,"mc":[{"id":"1.231581624","rc":[{"batb":[[0,2.32,29.57],[1,1.3,1000],[2,1.08,7.85]],"ltp":2.36,"tv":28.0,"id":31378}]}]}
{"op":"mcm","clk":"11853849474","pt":1723320176546,"mc":[{"id":"1.231581624","rc":[{"batb":[[0,2.34,14],[1,2.32,29.57],[2,1.3,1000]],"ltp":2.36,"tv":28.0,"id":31378}]}]}
{"op":"mcm","clk":"11853849838","pt":1723320178952,"mc":[{"id":"1.231581624","rc":[{"batb":[[0,2.34,10]],"ltp":2.36,"tv":28.0,"id":31378}]}]}
{"op":"mcm","clk":"11853849975","pt":1723320179850,"mc":[{"id":"1.231581624","rc":[{"batb":[[0,2.32,29.57],[1,1.3,1000],[2,1.08,7.85]],"ltp":2.36,"tv":28.0,"id":31378}]}]}
{"op":"mcm","clk":"11853850237","pt":1723320181553,"mc":[{"id":"1.231581624","rc":[{"batb":[[0,2.34,4],[1,2.32,29.57],[2,1.3,1000]],"ltp":2.36,"tv":28.0,"id":31378}]}]}
{"op":"mcm","clk":"11853850558","pt":1723320183440,"mc":[{"id":"1.231581624","rc":[{"batb":[[0,2.36,10],[1,2.34,4],[2,2.32,29.57]],"ltp":2.36,"tv":28.0,"id":31378}]}]}
{"op":"mcm","clk":"11853850650","pt":1723320184058,"mc":[{"id":"1.231581624","rc":[{"batb":[[1,2.32,29.57],[2,1.3,1000]],"ltp":2.36,"tv":28.0,"id":31378}]}]}
{"op":"mcm","clk":"11853851127","pt":1723320187067,"mc":[{"id":"1.231581624","rc":[{"batb":[[0,2.34,4]],"ltp":2.36,"tv":28.0,"id":31378}]}]}
{"op":"mcm","clk":"11853851464","pt":1723320189487,"mc":[{"id":"1.231581624","rc":[{"batb":[[0,2.32,29.57],[1,1.3,1000],[2,1.08,7.85]],"ltp":2.36,"tv":28.0,"id":31378}]}]}
{"op":"mcm","clk":"11853851493","pt":1723320189649,"mc":[{"id":"1.231581624","rc":[{"batb":[[0,2.34,10],[1,2.32,29.57],[2,1.3,1000]],"ltp":2.36,"tv":28.0,"id":31378}]}]}
{"op":"mcm","clk":"11853852229","pt":1723320193176,"mc":[{"id":"1.231581624","rc":[{"batb":[[0,2.34,4]],"ltp":2.36,"tv":28.0,"id":31378}]}]}
{"op":"mcm","clk":"11853852629","pt":1723320195967,"mc":[{"id":"1.231581624","rc":[{"batb":[[0,2.36,10]],"ltp":2.36,"tv":28.0,"id":31378}]}]}
{"op":"mcm","clk":"11853853157","pt":1723320198884,"mc":[{"id":"1.231581624","rc":[{"batb":[[0,2.34,4]],"ltp":2.36,"tv":28.0,"id":31378}]}]}
{"op":"mcm","clk":"11853853497","pt":1723320201288,"mc":[{"id":"1.231581624","rc":[{"batb":[[0,2.34,10]],"ltp":2.36,"tv":28.0,"id":31378}]}]}
{"op":"mcm","clk":"11853853954","pt":1723320204662,"mc":[{"id":"1.231581624","rc":[{"batb":[[0,2.34,4]],"ltp":2.36,"tv":28.0,"id":31378}]}]}
{"op":"mcm","clk":"11853854358","pt":1723320207077,"mc":[{"id":"1.231581624","rc":[{"batb":[[0,2.34,10]],"ltp":2.36,"tv":28.0,"id":31378}]}]}
{"op":"mcm","clk":"11853854952","pt":1723320210482,"mc":[{"id":"1.231581624","rc":[{"batb":[[0,2.32,29.57],[1,1.3,1000],[2,1.08,7.85]],"ltp":2.36,"tv":28.0,"id":31378}]}]}
{"op":"mcm","clk":"11853854970","pt":1723320210595,"mc":[{"id":"1.231581624","rc":[{"batb":[[0,2.34,4],[1,2.32,29.57],[2,1.3,1000]],"ltp":2.36,"tv":28.0,"id":31378}]}]}
{"op":"mcm","clk":"11853855379","pt":1723320213105,"mc":[{"id":"1.231581624","rc":[{"batb":[[0,2.34,10]],"ltp":2.36,"tv":28.0,"id":31378}]}]}
{"op":"mcm","clk":"11853856006","pt":1723320216797,"mc":[{"id":"1.231581624","rc":[{"batb":[[0,2.34,4]],"ltp":2.36,"tv":28.0,"id":31378}]}]}
{"op":"mcm","clk":"11853856458","pt":1723320219199,"mc":[{"id":"1.231581624","rc":[{"batb":[[0,2.34,10]],"ltp":2.36,"tv":28.0,"id":31378}]}]}
{"op":"mcm","clk":"11853856938","pt":1723320222108,"mc":[{"id":"1.231581624","rc":[{"batb":[[0,2.36,4],[1,2.34,10],[2,2.32,29.57]],"ltp":2.36,"tv":28.0,"id":31378}]}]}
{"op":"mcm","clk":"11853857044","pt":1723320222609,"mc":[{"id":"1.231581624","rc":[{"batb":[[1,2.32,29.57],[2,1.3,1000]],"ltp":2.36,"tv":28.0,"id":31378}]}]}
{"op":"mcm","clk":"11853857362","pt":1723320224421,"mc":[{"id":"1.231581624","rc":[{"batb":[[0,2.32,29.57],[1,1.3,1000],[2,1.08,7.85]],"ltp":2.36,"tv":28.0,"id":31378}]}]}
{"op":"mcm","clk":"11853857417","pt":1723320224749,"mc":[{"id":"1.231581624","rc":[{"batb":[[0,2.34,10],[1,2.32,29.57],[2,1.3,1000]],"ltp":2.36,"tv":28.0,"id":31378}]}]}
{"op":"mcm","clk":"11853858016","pt":1723320227955,"mc":[{"id":"1.231581624","rc":[{"batb":[[0,2.36,4]],"ltp":2.36,"tv":28.0,"id":31378}]}]}
{"op":"mcm","clk":"11853858422","pt":1723320230321,"mc":[{"id":"1.231581624","rc":[{"batb":[[0,2.34,10]],"ltp":2.36,"tv":28.0,"id":31378}]}]}
{"op":"mcm","clk":"11853858945","pt":1723320233839,"mc":[{"id":"1.231581624","rc":[{"batb":[[0,2.34,4]],"ltp":2.36,"tv":28.0,"id":31378}]}]}
{"op":"mcm","clk":"11853859345","pt":1723320236416,"mc":[{"id":"1.231581624","rc":[{"batb":[[0,2.34,10]],"ltp":2.36,"tv":28.0,"id":31378}]}]}
{"op":"mcm","clk":"11853859842","pt":1723320239830,"mc":[{"id":"1.231581624","rc":[{"batb":[[0,2.34,4]],"ltp":2.36,"tv":28.0,"id":31378}]}]}
{"op":"mcm","clk":"11853860198","pt":1723320242007,"mc":[{"id":"1.231581624","rc":[{"batb":[[0,2.36,10]],"ltp":2.36,"tv":28.0,"id":31378}]}]}
{"op":"mcm","clk":"11853860728","pt":1723320245322,"mc":[{"id":"1.231581624","rc":[{"batb":[[0,2.32,29.57],[1,1.3,1000],[2,1.08,7.85]],"ltp":2.36,"tv":28.0,"id":31378}]}]}
{"op":"mcm","clk":"11853860768","pt":1723320245528,"mc":[{"id":"1.231581624","rc":[{"batb":[[0,2.34,4],[1,2.32,29.57],[2,1.3,1000]],"ltp":2.36,"tv":28.0,"id":31378}]}]}
{"op":"mcm","clk":"11853861087","pt":1723320247837,"mc":[{"id":"1.231581624","rc":[{"batb":[[0,2.36,10]],"ltp":2.36,"tv":28.0,"id":31378}]}]}
{"op":"mcm","clk":"11853861636","pt":1723320251147,"mc":[{"id":"1.231581624","rc":[{"batb":[[0,2.34,4]],"ltp":2.36,"tv":28.0,"id":31378}]}]}
{"op":"mcm","clk":"11853862023","pt":1723320253662,"mc":[{"id":"1.231581624","rc":[{"batb":[[0,2.34,10]],"ltp":2.36,"tv":28.0,"id":31378}]}]}
{"op":"mcm","clk":"11853862717","pt":1723320257363,"mc":[{"id":"1.231581624","rc":[{"batb":[[0,2.36,4]],"ltp":2.36,"tv":28.0,"id":31378}]}]}
{"op":"mcm","clk":"11853863097","pt":1723320259834,"mc":[{"id":"1.231581624","rc":[{"batb":[[0,2.34,10]],"ltp":2.36,"tv":28.0,"id":31378}]}]}
{"op":"mcm","clk":"11853863445","pt":1723320262084,"mc":[{"id":"1.231581624","rc":[{"batb":[[0,2.36,4],[1,2.34,10],[2,2.32,29.57]],"ltp":2.36,"tv":28.0,"id":31378}]}]}
{"op":"mcm","clk":"11853863641","pt":1723320263338,"mc":[{"id":"1.231581624","rc":[{"batb":[[1,2.32,29.57],[2,1.3,1000]],"ltp":2.36,"tv":28.0,"id":31378}]}]}
{"op":"mcm","clk":"11853863802","pt":1723320264365,"mc":[{"id":"1.231581624","rc":[{"batb":[[0,2.32,29.57],[1,1.3,1000],[2,1.08,7.85]],"ltp":2.36,"tv":28.0,"id":31378}]}]}
{"op":"mcm","clk":"11853865306","pt":1723320274265,"mc":[{"id":"1.231581624","rc":[{"batb":[[0,2.34,14],[1,2.32,29.57],[2,1.3,1000]],"ltp":2.36,"tv":28.0,"id":31378}]}]}
{"op":"mcm","clk":"11853865682","pt":1723320276581,"mc":[{"id":"1.231581624","rc":[{"batb":[[0,2.34,10]],"ltp":2.36,"tv":28.0,"id":31378}]}]}
{"op":"mcm","clk":"11853865848","pt":1723320277576,"mc":[{"id":"1.231581624","rc":[{"batb":[[0,2.32,29.57],[1,1.3,1000],[2,1.08,7.85]],"ltp":2.36,"tv":28.0,"id":31378}]}]}
{"op":"mcm","clk":"11853866057","pt":1723320278781,"mc":[{"id":"1.231581624","rc":[{"batb":[[0,2.34,4],[1,2.32,29.57],[2,1.3,1000]],"ltp":2.36,"tv":28.0,"id":31378}]}]}
{"op":"mcm","clk":"11853866445","pt":1723320281187,"mc":[{"id":"1.231581624","rc":[{"batb":[[0,2.34,10]],"ltp":2.36,"tv":28.0,"id":31378}]}]}
{"op":"mcm","clk":"11853867045","pt":1723320284465,"mc":[{"id":"1.231581624","rc":[{"batb":[[0,2.34,4]],"ltp":2.36,"tv":28.0,"id":31378}]}]}
{"op":"mcm","clk":"11853867435","pt":1723320286978,"mc":[{"id":"1.231581624","rc":[{"batb":[[0,2.36,10]],"ltp":2.36,"tv":28.0,"id":31378}]}]}
{"op":"mcm","clk":"11853868009","pt":1723320290495,"mc":[{"id":"1.231581624","rc":[{"batb":[[0,2.34,4]],"ltp":2.36,"tv":28.0,"id":31378}]}]}
{"op":"mcm","clk":"11853868454","pt":1723320292869,"mc":[{"id":"1.231581624","rc":[{"batb":[[0,2.34,10]],"ltp":2.36,"tv":28.0,"id":31378}]}]}
{"op":"mcm","clk":"11853868973","pt":1723320296179,"mc":[{"id":"1.231581624","rc":[{"batb":[[0,2.36,4]],"ltp":2.36,"tv":28.0,"id":31378}]}]}
{"op":"mcm","clk":"11853869217","pt":1723320297899,"mc":[{"id":"1.231581624","rc":[{"batb":[[0,2.32,29.57],[1,1.3,1000],[2,1.08,7.85]],"ltp":2.36,"tv":28.0,"id":31378}]}]}
{"op":"mcm","clk":"11853870132","pt":1723320303617,"mc":[{"id":"1.231581624","rc":[{"batb":[[0,2.34,14],[1,2.32,29.57],[2,1.3,1000]],"ltp":2.36,"tv":28.0,"id":31378}]}]}
{"op":"mcm","clk":"11853870661","pt":1723320306126,"mc":[{"id":"1.231581624","rc":[{"batb":[[0,2.34,10]],"ltp":2.36,"tv":28.0,"id":31378}]}]}
{"op":"mcm","clk":"11853870861","pt":1723320307014,"mc":[{"id":"1.231581624","rc":[{"batb":[[0,2.32,29.57],[1,1.3,1000],[2,1.08,7.85]],"ltp":2.36,"tv":28.0,"id":31378}]}]}
{"op":"mcm","clk":"11853871133","pt":1723320308325,"mc":[{"id":"1.231581624","rc":[{"batb":[[0,2.34,4],[1,2.32,29.57],[2,1.3,1000]],"ltp":2.36,"tv":28.0,"id":31378}]}]}
{"op":"mcm","clk":"11853871499","pt":1723320310622,"mc":[{"id":"1.231581624","rc":[{"batb":[[0,2.34,10]],"ltp":2.36,"tv":28.0,"id":31378}]}]}
{"op":"mcm","clk":"11853872039","pt":1723320314290,"mc":[{"id":"1.231581624","rc":[{"batb":[[0,2.34,4]],"ltp":2.36,"tv":28.0,"id":31378}]}]}
{"op":"mcm","clk":"11853872480","pt":1723320316755,"mc":[{"id":"1.231581624","rc":[{"batb":[[0,2.34,10]],"ltp":2.36,"tv":28.0,"id":31378}]}]}
{"op":"mcm","clk":"11853872889","pt":1723320319327,"mc":[{"id":"1.231581624","rc":[{"batb":[[0,2.36,4],[1,2.34,10],[2,2.32,29.57]],"ltp":2.36,"tv":28.0,"id":31378}]}]}
{"op":"mcm","clk":"11853872990","pt":1723320319953,"mc":[{"id":"1.231581624","rc":[{"batb":[[1,2.32,29.57],[2,1.3,1000]],"ltp":2.36,"tv":28.0,"id":31378}]}]}
{"op":"mcm","clk":"11853873265","pt":1723320321741,"mc":[{"id":"1.231581624","rc":[{"batb":[[0,2.32,29.57],[1,1.3,1000],[2,1.08,7.85]],"ltp":2.36,"tv":28.0,"id":31378}]}]}
{"op":"mcm","clk":"11853874045","pt":1723320326876,"mc":[{"id":"1.231581624","rc":[{"batb":[[0,2.34,14],[1,2.32,29.57],[2,1.3,1000]],"ltp":2.36,"tv":28.0,"id":31378}]}]}
{"op":"mcm","clk":"11853874435","pt":1723320329259,"mc":[{"id":"1.231581624","rc":[{"batb":[[0,2.34,10]],"ltp":2.36,"tv":28.0,"id":31378}]}]}
{"op":"mcm","clk":"11853874605","pt":1723320330274,"mc":[{"id":"1.231581624","rc":[{"batb":[[0,2.32,29.57],[1,1.3,1000],[2,1.08,7.85]],"ltp":2.36,"tv":28.0,"id":31378}]}]}
{"op":"mcm","clk":"11853875137","pt":1723320333246,"mc":[{"id":"1.231581624","rc":[{"batb":[[0,2.34,14],[1,2.32,29.57],[2,1.3,1000]],"ltp":2.36,"tv":28.0,"id":31378}]}]}
{"op":"mcm","clk":"11853875485","pt":1723320335609,"mc":[{"id":"1.231581624","rc":[{"batb":[[0,2.34,10]],"ltp":2.36,"tv":28.0,"id":31378}]}]}
{"op":"mcm","clk":"11853875663","pt":1723320336657,"mc":[{"id":"1.231581624","rc":[{"batb":[[0,2.32,29.57],[1,1.3,1000],[2,1.08,7.85]],"ltp":2.36,"tv":28.0,"id":31378}]}]}
{"op":"mcm","clk":"11853876090","pt":1723320339484,"mc":[{"id":"1.231581624","rc":[{"batb":[[0,2.34,14],[1,2.32,29.57],[2,1.3,1000]],"ltp":2.36,"tv":28.0,"id":31378},{"batb":[[0,1.7,2],[1,1.69,56.58],[2,1.63,33]],"ltp":1.73,"tv":69.5,"id":5995}]}]}
{"op":"mcm","clk":"11853876557","pt":1723320342485,"mc":[{"id":"1.231581624","rc":[{"batb":[[0,2.32,29.57],[1,1.3,1000],[2,1.08,7.85]],"ltp":2.36,"tv":28.0,"id":31378}]}]}
{"op":"mcm","clk":"11853877115","pt":1723320345902,"mc":[{"id":"1.231581624","rc":[{"batb":[[0,2.34,14],[1,2.32,29.57],[2,1.3,1000]],"ltp":2.36,"tv":28.0,"id":31378}]}]}
{"op":"mcm","clk":"11853877482","pt":1723320348225,"mc":[{"id":"1.231581624","rc":[{"batb":[[0,2.34,10]],"ltp":2.36,"tv":28.0,"id":31378}]}]}
{"op":"mcm","clk":"11853877633","pt":1723320349217,"mc":[{"id":"1.231581624","rc":[{"batb":[[0,2.32,29.57],[1,1.3,1000],[2,1.08,7.85]],"ltp":2.36,"tv":28.0,"id":31378}]}]}
{"op":"mcm","clk":"11853878501","pt":1723320354414,"mc":[{"id":"1.231581624","rc":[{"batb":[[0,2.34,14],[1,2.32,29.57],[2,1.3,1000]],"ltp":2.36,"tv":28.0,"id":31378}]}]}
{"op":"mcm","clk":"11853878867","pt":1723320356724,"mc":[{"id":"1.231581624","rc":[{"batb":[[0,2.34,10]],"ltp":2.36,"tv":28.0,"id":31378}]}]}
{"op":"mcm","clk":"11853879055","pt":1723320357932,"mc":[{"id":"1.231581624","rc":[{"batb":[[0,2.32,29.57],[1,1.3,1000],[2,1.08,7.85]],"ltp":2.36,"tv":28.0,"id":31378}]}]}
{"op":"mcm","clk":"11853879917","pt":1723320362955,"mc":[{"id":"1.231581624","rc":[{"batb":[[0,2.34,14],[1,2.32,29.57],[2,1.3,1000]],"ltp":2.36,"tv":28.0,"id":31378}]}]}
{"op":"mcm","clk":"11853880426","pt":1723320365423,"mc":[{"id":"1.231581624","rc":[{"batb":[[0,2.34,10]],"ltp":2.36,"tv":28.0,"id":31378}]}]}
{"op":"mcm","clk":"11853880616","pt":1723320366312,"mc":[{"id":"1.231581624","rc":[{"batb":[[0,2.32,29.57],[1,1.3,1000],[2,1.08,7.85]],"ltp":2.36,"tv":28.0,"id":31378}]}]}
{"op":"mcm","clk":"11853882295","pt":1723320376066,"mc":[{"id":"1.231581624","rc":[{"batb":[[0,2.34,14],[1,2.32,29.57],[2,1.3,1000]],"ltp":2.36,"tv":28.0,"id":31378}]}]}
{"op":"mcm","clk":"11853882688","pt":1723320378536,"mc":[{"id":"1.231581624","rc":[{"batb":[[0,2.34,10]],"ltp":2.36,"tv":28.0,"id":31378}]}]}
{"op":"mcm","clk":"11853882858","pt":1723320379580,"mc":[{"id":"1.231581624","rc":[{"batb":[[0,2.32,29.57],[1,1.3,1000],[2,1.08,7.85]],"ltp":2.36,"tv":28.0,"id":31378}]}]}
{"op":"mcm","clk":"11853883214","pt":1723320381951,"mc":[{"id":"1.231581624","rc":[{"batb":[[0,2.34,14],[1,2.32,29.57],[2,1.3,1000]],"ltp":2.36,"tv":28.0,"id":31378}]}]}
{"op":"mcm","clk":"11853883609","pt":1723320384145,"mc":[{"id":"1.231581624","rc":[{"batb":[[0,2.34,10]],"ltp":2.36,"tv":28.0,"id":31378}]}]}
{"op":"mcm","clk":"11853883802","pt":1723320385269,"mc":[{"id":"1.231581624","rc":[{"batb":[[0,2.32,29.57],[1,1.3,1000],[2,1.08,7.85]],"ltp":2.36,"tv":28.0,"id":31378}]}]}
{"op":"mcm","clk":"11853884271","pt":1723320388054,"mc":[{"id":"1.231581624","rc":[{"batb":[[0,2.34,14],[1,2.32,29.57],[2,1.3,1000]],"ltp":2.36,"tv":28.0,"id":31378}]}]}
{"op":"mcm","clk":"11853884665","pt":1723320390273,"mc":[{"id":"1.231581624","rc":[{"batb":[[0,2.34,10]],"ltp":2.36,"tv":28.0,"id":31378}]}]}
{"op":"mcm","clk":"11853884909","pt":1723320391457,"mc":[{"id":"1.231581624","rc":[{"batb":[[0,2.32,29.57],[1,1.3,1000],[2,1.08,7.85]],"ltp":2.36,"tv":28.0,"id":31378}]}]}
{"op":"mcm","clk":"11853885168","pt":1723320392769,"mc":[{"id":"1.231581624","rc":[{"batb":[[0,2.34,4],[1,2.32,29.57],[2,1.3,1000]],"ltp":2.36,"tv":28.0,"id":31378}]}]}
{"op":"mcm","clk":"11853885562","pt":1723320395084,"mc":[{"id":"1.231581624","rc":[{"batb":[[0,2.36,10]],"ltp":2.36,"tv":28.0,"id":31378}]}]}
{"op":"mcm","clk":"11853886096","pt":1723320398246,"mc":[{"id":"1.231581624","rc":[{"batb":[[0,2.34,4]],"ltp":2.36,"tv":28.0,"id":31378}]}]}
{"op":"mcm","clk":"11853886488","pt":1723320400662,"mc":[{"id":"1.231581624","rc":[{"batb":[[0,2.34,10]],"ltp":2.36,"tv":28.0,"id":31378}]}]}
{"op":"mcm","clk":"11853887095","pt":1723320404208,"mc":[{"id":"1.231581624","rc":[{"batb":[[0,2.34,4]],"ltp":2.36,"tv":28.0,"id":31378}]}]}
{"op":"mcm","clk":"11853887516","pt":1723320406797,"mc":[{"id":"1.231581624","rc":[{"batb":[[0,2.34,10]],"ltp":2.36,"tv":28.0,"id":31378}]}]}
{"op":"mcm","clk":"11853888025","pt":1723320410294,"mc":[{"id":"1.231581624","rc":[{"batb":[[0,2.34,4]],"ltp":2.36,"tv":28.0,"id":31378}]}]}
{"op":"mcm","clk":"11853888404","pt":1723320412456,"mc":[{"id":"1.231581624","rc":[{"batb":[[0,2.32,29.57],[1,1.3,1000],[2,1.08,7.85]],"ltp":2.36,"tv":28.0,"id":31378}]}]}
{"op":"mcm","clk":"11853888436","pt":1723320412670,"mc":[{"id":"1.231581624","rc":[{"batb":[[0,2.34,10],[1,2.32,29.57],[2,1.3,1000]],"ltp":2.36,"tv":28.0,"id":31378}]}]}
{"op":"mcm","clk":"11853888797","pt":1723320414990,"mc":[{"id":"1.231581624","rc":[{"batb":[[0,2.36,4],[1,2.34,10],[2,2.32,29.57]],"ltp":2.36,"tv":28.0,"id":31378}]}]}
{"op":"mcm","clk":"11853889034","pt":1723320416087,"mc":[{"id":"1.231581624","rc":[{"batb":[[1,2.32,29.57],[2,1.3,1000]],"ltp":2.36,"tv":28.0,"id":31378}]}]}
{"op":"mcm","clk":"11853889256","pt":1723320417313,"mc":[{"id":"1.231581624","rc":[{"batb":[[0,2.32,29.57],[1,1.3,1000],[2,1.08,7.85]],"ltp":2.36,"tv":28.0,"id":31378}]}]}
{"op":"mcm","clk":"11853889955","pt":1723320421925,"mc":[{"id":"1.231581624","rc":[{"batb":[[0,2.34,14],[1,2.32,29.57],[2,1.3,1000]],"ltp":2.36,"tv":28.0,"id":31378}]}]}
{"op":"mcm","clk":"11853890376","pt":1723320424181,"mc":[{"id":"1.231581624","rc":[{"batb":[[0,2.34,10]],"ltp":2.36,"tv":28.0,"id":31378}]}]}
{"op":"mcm","clk":"11853890514","pt":1723320425076,"mc":[{"id":"1.231581624","rc":[{"batb":[[0,2.32,29.57],[1,1.3,1000],[2,1.08,7.85]],"ltp":2.36,"tv":28.0,"id":31378}]}]}
{"op":"mcm","clk":"11853891667","pt":1723320432274,"mc":[{"id":"1.231581624","rc":[{"batb":[[0,2.34,14],[1,2.32,29.57],[2,1.3,1000]],"ltp":2.36,"tv":28.0,"id":31378}]}]}
{"op":"mcm","clk":"11853892042","pt":1723320434689,"mc":[{"id":"1.231581624","rc":[{"batb":[[0,2.34,10]],"ltp":2.36,"tv":28.0,"id":31378}]}]}
{"op":"mcm","clk":"11853892208","pt":1723320435689,"mc":[{"id":"1.231581624","rc":[{"batb":[[0,2.32,29.57],[1,1.3,1000],[2,1.08,7.85]],"ltp":2.36,"tv":28.0,"id":31378}]}]}
{"op":"mcm","clk":"11853892432","pt":1723320437080,"mc":[{"id":"1.231581624","rc":[{"batb":[[0,2.34,4],[1,2.32,29.57],[2,1.3,1000]],"ltp":2.36,"tv":28.0,"id":31378}]}]}
{"op":"mcm","clk":"11853892803","pt":1723320439493,"mc":[{"id":"1.231581624","rc":[{"batb":[[0,2.34,10]],"ltp":2.36,"tv":28.0,"id":31378}]}]}
{"op":"mcm","clk":"11853893370","pt":1723320442896,"mc":[{"id":"1.231581624","rc":[{"batb":[[0,2.36,4]],"ltp":2.36,"tv":28.0,"id":31378}]}]}
{"op":"mcm","clk":"11853893848","pt":1723320445440,"mc":[{"id":"1.231581624","rc":[{"batb":[[0,2.34,10]],"ltp":2.36,"tv":28.0,"id":31378}]}]}
{"op":"mcm","clk":"11853894410","pt":1723320448801,"mc":[{"id":"1.231581624","rc":[{"batb":[[0,2.34,4]],"ltp":2.36,"tv":28.0,"id":31378}]}]}
{"op":"mcm","clk":"11853894854","pt":1723320451239,"mc":[{"id":"1.231581624","rc":[{"batb":[[0,2.34,10]],"ltp":2.36,"tv":28.0,"id":31378}]}]}
{"op":"mcm","clk":"11853895268","pt":1723320453607,"mc":[{"id":"1.231581624","rc":[{"batb":[[0,2.36,4],[1,2.34,10],[2,2.32,29.57]],"ltp":2.36,"tv":28.0,"id":31378}]}]}
{"op":"mcm","clk":"11853895452","pt":1723320454602,"mc":[{"id":"1.231581624","rc":[{"batb":[[1,2.32,29.57],[2,1.3,1000]],"ltp":2.36,"tv":28.0,"id":31378}]}]}
{"op":"mcm","clk":"11853895672","pt":1723320455813,"mc":[{"id":"1.231581624","rc":[{"batb":[[0,2.32,29.57],[1,1.3,1000],[2,1.08,7.85]],"ltp":2.36,"tv":28.0,"id":31378}]}]}
{"op":"mcm","clk":"11853895961","pt":1723320457516,"mc":[{"id":"1.231581624","rc":[{"batb":[[0,2.34,10],[1,2.32,29.57],[2,1.3,1000]],"ltp":2.36,"tv":28.0,"id":31378}]}]}
{"op":"mcm","clk":"11853896541","pt":1723320460929,"mc":[{"id":"1.231581624","rc":[{"batb":[[0,2.34,4]],"ltp":2.36,"tv":28.0,"id":31378}]}]}
{"op":"mcm","clk":"11853896953","pt":1723320463463,"mc":[{"id":"1.231581624","rc":[{"batb":[[0,2.34,10]],"ltp":2.36,"tv":28.0,"id":31378}]}]}
{"op":"mcm","clk":"11853897453","pt":1723320466348,"mc":[{"id":"1.231581624","rc":[{"batb":[[0,2.36,4],[1,2.34,10],[2,2.32,29.57]],"ltp":2.36,"tv":28.0,"id":31378}]}]}
{"op":"mcm","clk":"11853897523","pt":1723320466725,"mc":[{"id":"1.231581624","rc":[{"batb":[[1,2.32,29.57],[2,1.3,1000]],"ltp":2.36,"tv":28.0,"id":31378}]}]}
{"op":"mcm","clk":"11853897826","pt":1723320468654,"mc":[{"id":"1.231581624","rc":[{"batb":[[0,2.32,29.57],[1,1.3,1000],[2,1.08,7.85]],"ltp":2.36,"tv":28.0,"id":31378}]}]}
{"op":"mcm","clk":"11853898316","pt":1723320471542,"mc":[{"id":"1.231581624","rc":[{"batb":[[0,2.34,14],[1,2.32,29.57],[2,1.3,1000]],"ltp":2.36,"tv":28.0,"id":31378}]}]}
{"op":"mcm","clk":"11853898710","pt":1723320473841,"mc":[{"id":"1.231581624","rc":[{"batb":[[0,2.34,10]],"ltp":2.36,"tv":28.0,"id":31378}]}]}
{"op":"mcm","clk":"11853898934","pt":1723320475057,"mc":[{"id":"1.231581624","rc":[{"batb":[[0,2.32,29.57],[1,1.3,1000],[2,1.08,7.85]],"ltp":2.36,"tv":28.0,"id":31378}]}]}
{"op":"mcm","clk":"11853899173","pt":1723320476330,"mc":[{"id":"1.231581624","rc":[{"batb":[[0,2.34,4],[1,2.32,29.57],[2,1.3,1000]],"ltp":2.36,"tv":28.0,"id":31378}]}]}
{"op":"mcm","clk":"11853899555","pt":1723320478731,"mc":[{"id":"1.231581624","rc":[{"batb":[[0,2.34,10]],"ltp":2.36,"tv":28.0,"id":31378}]}]}
{"op":"mcm","clk":"11853899935","pt":1723320480834,"mc":[{"id":"1.231581624","rc":[{"batb":[[0,2.36,4],[1,2.34,10],[2,2.32,29.57]],"ltp":2.36,"tv":28.0,"id":31378}]}]}
{"op":"mcm","clk":"11853900134","pt":1723320482051,"mc":[{"id":"1.231581624","rc":[{"batb":[[1,2.32,29.57],[2,1.3,1000]],"ltp":2.36,"tv":28.0,"id":31378}]}]}
{"op":"mcm","clk":"11853900320","pt":1723320483158,"mc":[{"id":"1.231581624","rc":[{"batb":[[0,2.32,29.57],[1,1.3,1000],[2,1.08,7.85]],"ltp":2.36,"tv":28.0,"id":31378}]}]}
{"op":"mcm","clk":"11853900517","pt":1723320484371,"mc":[{"id":"1.231581624","rc":[{"batb":[[0,2.34,10],[1,2.32,29.57],[2,1.3,1000]],"ltp":2.36,"tv":28.0,"id":31378}]}]}
{"op":"mcm","clk":"11853900775","pt":1723320485946,"mc":[{"id":"1.231581624","rc":[{"batb":[[0,2.36,4],[1,2.34,10],[2,2.32,29.57]],"ltp":2.36,"tv":28.0,"id":31378}]}]}
{"op":"mcm","clk":"11853901188","pt":1723320488368,"mc":[{"id":"1.231581624","rc":[{"batb":[[0,2.32,29.57],[1,1.3,1000],[2,1.08,7.85]],"ltp":2.36,"tv":28.0,"id":31378}]}]}
{"op":"mcm","clk":"11853901813","pt":1723320491956,"mc":[{"id":"1.231581624","rc":[{"batb":[[0,2.34,14],[1,2.32,29.57],[2,1.3,1000]],"ltp":2.36,"tv":28.0,"id":31378}]}]}
{"op":"mcm","clk":"11853902222","pt":1723320494326,"mc":[{"id":"1.231581624","rc":[{"batb":[[0,2.34,10]],"ltp":2.36,"tv":28.0,"id":31378}]}]}
{"op":"mcm","clk":"11853902428","pt":1723320495382,"mc":[{"id":"1.231581624","rc":[{"batb":[[0,2.32,29.57],[1,1.3,1000],[2,1.08,7.85]],"ltp":2.36,"tv":28.0,"id":31378}]}]}
{"op":"mcm","clk":"11853902633","pt":1723320496452,"mc":[{"id":"1.231581624","rc":[{"batb":[[0,2.34,4],[1,2.32,29.57],[2,1.3,1000]],"ltp":2.36,"tv":28.0,"id":31378}]}]}
{"op":"mcm","clk":"11853903022","pt":1723320498868,"mc":[{"id":"1.231581624","rc":[{"batb":[[0,2.34,10]],"ltp":2.36,"tv":28.0,"id":31378}]}]}
{"op":"mcm","clk":"11853903594","pt":1723320502184,"mc":[{"id":"1.231581624","rc":[{"batb":[[0,2.36,4]],"ltp":2.36,"tv":28.0,"id":31378}]}]}
{"op":"mcm","clk":"11853903954","pt":1723320504383,"mc":[{"id":"1.231581624","rc":[{"batb":[[0,2.34,10]],"ltp":2.36,"tv":28.0,"id":31378}]}]}
{"op":"mcm","clk":"11853904548","pt":1723320507878,"mc":[{"id":"1.231581624","rc":[{"batb":[[0,2.36,4]],"ltp":2.36,"tv":28.0,"id":31378}]}]}
{"op":"mcm","clk":"11853904980","pt":1723320510296,"mc":[{"id":"1.231581624","rc":[{"batb":[[0,2.34,10]],"ltp":2.36,"tv":28.0,"id":31378}]}]}
{"op":"mcm","clk":"11853905311","pt":1723320512302,"mc":[{"id":"1.231581624","rc":[{"batb":[[0,2.36,4],[1,2.34,10],[2,2.32,29.57]],"ltp":2.36,"tv":28.0,"id":31378}]}]}
{"op":"mcm","clk":"11853905584","pt":1723320513892,"mc":[{"id":"1.231581624","rc":[{"batb":[[1,2.32,29.57],[2,1.3,1000]],"ltp":2.36,"tv":28.0,"id":31378}]}]}
{"op":"mcm","clk":"11853905721","pt":1723320514686,"mc":[{"id":"1.231581624","rc":[{"batb":[[0,2.32,29.57],[1,1.3,1000],[2,1.08,7.85]],"ltp":2.36,"tv":28.0,"id":31378}]}]}
{"op":"mcm","clk":"11853906560","pt":1723320519672,"mc":[{"id":"1.231581624","rc":[{"batb":[[0,2.34,14],[1,2.32,29.57],[2,1.3,1000]],"ltp":2.36,"tv":28.0,"id":31378}]}]}
{"op":"mcm","clk":"11853906956","pt":1723320522185,"mc":[{"id":"1.231581624","rc":[{"batb":[[0,2.34,10]],"ltp":2.36,"tv":28.0,"id":31378}]}]}
{"op":"mcm","clk":"11853907102","pt":1723320523086,"mc":[{"id":"1.231581624","rc":[{"batb":[[0,2.32,29.57],[1,1.3,1000],[2,1.08,7.85]],"ltp":2.36,"tv":28.0,"id":31378}]}]}
{"op":"mcm","clk":"11853907852","pt":1723320527476,"mc":[{"id":"1.231581624","rc":[{"batb":[[0,2.34,14],[1,2.32,29.57],[2,1.3,1000]],"ltp":2.36,"tv":28.0,"id":31378}]}]}
{"op":"mcm","clk":"11853908254","pt":1723320529891,"mc":[{"id":"1.231581624","rc":[{"batb":[[0,2.34,10]],"ltp":2.36,"tv":28.0,"id":31378}]}]}
{"op":"mcm","clk":"11853908418","pt":1723320530886,"mc":[{"id":"1.231581624","rc":[{"batb":[[0,2.32,29.57],[1,1.3,1000],[2,1.08,7.85]],"ltp":2.36,"tv":28.0,"id":31378}]}]}
{"op":"mcm","clk":"11853908715","pt":1723320532715,"mc":[{"id":"1.231581624","rc":[{"batb":[[0,2.34,4],[1,2.32,29.57],[2,1.3,1000]],"ltp":2.36,"tv":28.0,"id":31378}]}]}
{"op":"mcm","clk":"11853909105","pt":1723320535192,"mc":[{"id":"1.231581624","rc":[{"batb":[[0,2.34,10]],"ltp":2.36,"tv":28.0,"id":31378}]}]}
{"op":"mcm","clk":"11853909667","pt":1723320538498,"mc":[{"id":"1.231581624","rc":[{"batb":[[0,2.34,4]],"ltp":2.36,"tv":28.0,"id":31378}]}]}
{"op":"mcm","clk":"11853910106","pt":1723320541022,"mc":[{"id":"1.231581624","rc":[{"batb":[[0,2.34,10]],"ltp":2.36,"tv":28.0,"id":31378}]}]}
{"op":"mcm","clk":"11853910701","pt":1723320544445,"mc":[{"id":"1.231581624","rc":[{"batb":[[0,2.34,4]],"ltp":2.36,"tv":28.0,"id":31378}]}]}
{"op":"mcm","clk":"11853911169","pt":1723320546917,"mc":[{"id":"1.231581624","rc":[{"batb":[[0,2.34,10]],"ltp":2.36,"tv":28.0,"id":31378}]}]}
{"op":"mcm","clk":"11853911628","pt":1723320549455,"mc":[{"id":"1.231581624","rc":[{"batb":[[0,2.36,4],[1,2.34,10],[2,2.32,29.57]],"ltp":2.36,"tv":28.0,"id":31378}]}]}
{"op":"mcm","clk":"11853911765","pt":1723320550246,"mc":[{"id":"1.231581624","rc":[{"batb":[[1,2.32,29.57],[2,1.3,1000]],"ltp":2.36,"tv":28.0,"id":31378}]}]}
{"op":"mcm","clk":"11853912008","pt":1723320551718,"mc":[{"id":"1.231581624","rc":[{"batb":[[0,2.32,29.57],[1,1.3,1000],[2,1.08,7.85]],"ltp":2.36,"tv":28.0,"id":31378}]}]}
{"op":"mcm","clk":"11853912394","pt":1723320554132,"mc":[{"id":"1.231581624","rc":[{"batb":[[0,2.34,14],[1,2.32,29.57],[2,1.3,1000]],"ltp":2.36,"tv":28.0,"id":31378}]}]}
{"op":"mcm","clk":"11853912771","pt":1723320556354,"mc":[{"id":"1.231581624","rc":[{"batb":[[0,2.34,10]],"ltp":2.36,"tv":28.0,"id":31378}]}]}
{"op":"mcm","clk":"11853912952","pt":1723320557409,"mc":[{"id":"1.231581624","rc":[{"batb":[[0,2.32,29.57],[1,1.3,1000],[2,1.08,7.85]],"ltp":2.36,"tv":28.0,"id":31378}]}]}
{"op":"mcm","clk":"11853913157","pt":1723320558620,"mc":[{"id":"1.231581624","rc":[{"batb":[[0,2.34,4],[1,2.32,29.57],[2,1.3,1000]],"ltp":2.36,"tv":28.0,"id":31378}]}]}
{"op":"mcm","clk":"11853913569","pt":1723320561150,"mc":[{"id":"1.231581624","rc":[{"batb":[[0,2.34,10]],"ltp":2.36,"tv":28.0,"id":31378}]}]}
{"op":"mcm","clk":"11853914064","pt":1723320563533,"mc":[{"id":"1.231581624","rc":[{"batb":[[0,2.36,4],[1,2.34,10],[2,2.32,29.57]],"ltp":2.36,"tv":28.0,"id":31378}]}]}
{"op":"mcm","clk":"11853914247","pt":1723320564539,"mc":[{"id":"1.231581624","rc":[{"batb":[[1,2.32,29.57],[2,1.3,1000]],"ltp":2.36,"tv":28.0,"id":31378}]}]}
{"op":"mcm","clk":"11853914508","pt":1723320566041,"mc":[{"id":"1.231581624","rc":[{"batb":[[0,2.32,29.57],[1,1.3,1000],[2,1.08,7.85]],"ltp":2.36,"tv":28.0,"id":31378}]}]}
{"op":"mcm","clk":"11853915222","pt":1723320570131,"mc":[{"id":"1.231581624","rc":[{"batb":[[0,2.34,14],[1,2.32,29.57],[2,1.3,1000]],"ltp":2.36,"tv":28.0,"id":31378}]}]}
{"op":"mcm","clk":"11853915625","pt":1723320572542,"mc":[{"id":"1.231581624","rc":[{"batb":[[0,2.34,10]],"ltp":2.36,"tv":28.0,"id":31378}]}]}
{"op":"mcm","clk":"11853915819","pt":1723320573627,"mc":[{"id":"1.231581624","rc":[{"batb":[[0,2.32,29.57],[1,1.3,1000],[2,1.08,7.85]],"ltp":2.36,"tv":28.0,"id":31378}]}]}
{"op":"mcm","clk":"11853916441","pt":1723320577152,"mc":[{"id":"1.231581624","rc":[{"batb":[[0,2.34,14],[1,2.32,29.57],[2,1.3,1000]],"ltp":2.36,"tv":28.0,"id":31378}]}]}
{"op":"mcm","clk":"11853916888","pt":1723320579730,"mc":[{"id":"1.231581624","rc":[{"batb":[[0,2.34,10]],"ltp":2.36,"tv":28.0,"id":31378}]}]}
{"op":"mcm","clk":"11853917040","pt":1723320580678,"mc":[{"id":"1.231581624","rc":[{"batb":[[0,2.32,29.57],[1,1.3,1000],[2,1.08,7.85]],"ltp":2.36,"tv":28.0,"id":31378}]}]}
{"op":"mcm","clk":"11853917303","pt":1723320582266,"mc":[{"id":"1.231581624","rc":[{"batb":[[0,2.34,4],[1,2.32,29.57],[2,1.3,1000]],"ltp":2.36,"tv":28.0,"id":31378}]}]}
{"op":"mcm","clk":"11853917708","pt":1723320584637,"mc":[{"id":"1.231581624","rc":[{"batb":[[0,2.36,10]],"ltp":2.36,"tv":28.0,"id":31378}]}]}
{"op":"mcm","clk":"11853918104","pt":1723320587247,"mc":[{"id":"1.231581624","rc":[{"batb":[[0,2.38,4],[1,2.36,10],[2,2.32,29.57]],"ltp":2.36,"tv":28.0,"id":31378}]}]}
{"op":"mcm","clk":"11853918235","pt":1723320588030,"mc":[{"id":"1.231581624","rc":[{"batb":[[1,2.32,29.57],[2,1.3,1000]],"ltp":2.36,"tv":28.0,"id":31378}]}]}
{"op":"mcm","clk":"11853918475","pt":1723320589561,"mc":[{"id":"1.231581624","rc":[{"batb":[[0,2.32,29.57],[1,1.3,1000],[2,1.08,7.85]],"ltp":2.36,"tv":28.0,"id":31378}]}]}
{"op":"mcm","clk":"11853918752","pt":1723320591072,"mc":[{"id":"1.231581624","rc":[{"batb":[[0,2.34,10],[1,2.32,29.57],[2,1.3,1000]],"ltp":2.36,"tv":28.0,"id":31378}]}]}
{"op":"mcm","clk":"11853919041","pt":1723320592854,"mc":[{"id":"1.231581624","rc":[{"batb":[[0,2.36,4],[1,2.34,10],[2,2.32,29.57]],"ltp":2.36,"tv":28.0,"id":31378}]}]}
{"op":"mcm","clk":"11853919401","pt":1723320595057,"mc":[{"id":"1.231581624","rc":[{"batb":[[0,2.32,29.57],[1,1.3,1000],[2,1.08,7.85]],"ltp":2.36,"tv":28.0,"id":31378}]}]}
{"op":"mcm","clk":"11853919752","pt":1723320597361,"mc":[{"id":"1.231581624","rc":[{"batb":[[0,2.34,14],[1,2.32,29.57],[2,1.3,1000]],"ltp":2.36,"tv":28.0,"id":31378}]}]}
{"op":"mcm","clk":"11853920161","pt":1723320599673,"mc":[{"id":"1.231581624","rc":[{"batb":[[0,2.34,10]],"ltp":2.36,"tv":28.0,"id":31378}]}]}
{"op":"mcm","clk":"11853920350","pt":1723320600576,"mc":[{"id":"1.231581624","rc":[{"batb":[[0,2.32,29.57],[1,1.3,1000],[2,1.08,7.85]],"ltp":2.36,"tv":28.0,"id":31378}]}]}
{"op":"mcm","clk":"11853920721","pt":1723320602433,"mc":[{"id":"1.231581624","rc":[{"batb":[[0,2.34,4],[1,2.32,29.57],[2,1.3,1000]],"ltp":2.36,"tv":28.0,"id":31378}]}]}
{"op":"mcm","clk":"11853920940","pt":1723320603654,"mc":[{"id":"1.231581624","rc":[{"batb":[[0,2.36,10],[1,2.34,4],[2,2.32,29.57]],"ltp":2.36,"tv":28.0,"id":31378}]}]}
{"op":"mcm","clk":"11853921154","pt":1723320604864,"mc":[{"id":"1.231581624","rc":[{"batb":[[1,2.32,29.57],[2,1.3,1000]],"ltp":2.36,"tv":28.0,"id":31378}]}]}
{"op":"mcm","clk":"11853921510","pt":1723320606959,"mc":[{"id":"1.231581624","rc":[{"batb":[[0,2.34,4]],"ltp":2.36,"tv":28.0,"id":31378}]}]}
{"op":"mcm","clk":"11853921948","pt":1723320609354,"mc":[{"id":"1.231581624","rc":[{"batb":[[0,2.34,10]],"ltp":2.36,"tv":28.0,"id":31378}]}]}
{"op":"mcm","clk":"11853922350","pt":1723320611980,"mc":[{"id":"1.231581624","rc":[{"batb":[[0,2.36,4],[1,2.34,10],[2,2.32,29.57]],"ltp":2.36,"tv":28.0,"id":31378}]}]}
{"op":"mcm","clk":"11853922495","pt":1723320612768,"mc":[{"id":"1.231581624","rc":[{"batb":[[1,2.32,29.57],[2,1.3,1000]],"ltp":2.36,"tv":28.0,"id":31378}]}]}
{"op":"mcm","clk":"11853922721","pt":1723320614287,"mc":[{"id":"1.231581624","rc":[{"batb":[[0,2.32,29.57],[1,1.3,1000],[2,1.08,7.85]],"ltp":2.36,"tv":28.0,"id":31378}]}]}
{"op":"mcm","clk":"11853922930","pt":1723320615460,"mc":[{"id":"1.231581624","rc":[{"batb":[[0,2.34,10],[1,2.32,29.57],[2,1.3,1000]],"ltp":2.36,"tv":28.0,"id":31378}]}]}
{"op":"mcm","clk":"11853923131","pt":1723320616667,"mc":[{"id":"1.231581624","rc":[{"batb":[[0,2.36,4],[1,2.34,10],[2,2.32,29.57]],"ltp":2.36,"tv":28.0,"id":31378}]}]}
{"op":"mcm","clk":"11853923523","pt":1723320618974,"mc":[{"id":"1.231581624","rc":[{"batb":[[0,2.32,29.57],[1,1.3,1000],[2,1.08,7.85]],"ltp":2.36,"tv":28.0,"id":31378}]}]}
{"op":"mcm","clk":"11853924428","pt":1723320624188,"mc":[{"id":"1.231581624","rc":[{"batb":[[0,2.34,14],[1,2.32,29.57],[2,1.3,1000]],"ltp":2.36,"tv":28.0,"id":31378}]}]}
{"op":"mcm","clk":"11853924817","pt":1723320626455,"mc":[{"id":"1.231581624","rc":[{"batb":[[0,2.34,10]],"ltp":2.36,"tv":28.0,"id":31378}]}]}
{"op":"mcm","clk":"11853925012","pt":1723320627560,"mc":[{"id":"1.231581624","rc":[{"batb":[[0,2.32,29.57],[1,1.3,1000],[2,1.08,7.85]],"ltp":2.36,"tv":28.0,"id":31378}]}]}
{"op":"mcm","clk":"11853926138","pt":1723320634299,"mc":[{"id":"1.231581624","rc":[{"batb":[[0,2.34,14],[1,2.32,29.57],[2,1.3,1000]],"ltp":2.36,"tv":28.0,"id":31378}]}]}
{"op":"mcm","clk":"11853926658","pt":1723320637462,"mc":[{"id":"1.231581624","rc":[{"batb":[[0,2.32,29.57],[1,1.3,1000],[2,1.08,7.85]],"ltp":2.36,"tv":28.0,"id":31378}]}]}
{"op":"mcm","clk":"11853926859","pt":1723320638788,"mc":[{"id":"1.231581624","rc":[{"batb":[[0,2.34,4],[1,2.32,29.57],[2,1.3,1000]],"ltp":2.36,"tv":28.0,"id":31378}]}]}
{"op":"mcm","clk":"11853927090","pt":1723320640201,"mc":[{"id":"1.231581624","rc":[{"batb":[[0,2.36,10],[1,2.34,4],[2,2.32,29.57]],"ltp":2.36,"tv":28.0,"id":31378}]}]}
{"op":"mcm","clk":"11853927265","pt":1723320641202,"mc":[{"id":"1.231581624","rc":[{"batb":[[1,2.32,29.57],[2,1.3,1000]],"ltp":2.36,"tv":28.0,"id":31378}]}]}
{"op":"mcm","clk":"11853927715","pt":1723320643706,"mc":[{"id":"1.231581624","rc":[{"batb":[[0,2.34,4]],"ltp":2.36,"tv":28.0,"id":31378}]}]}
{"op":"mcm","clk":"11853928145","pt":1723320646282,"mc":[{"id":"1.231581624","rc":[{"batb":[[0,2.34,10]],"ltp":2.36,"tv":28.0,"id":31378}]}]}
{"op":"mcm","clk":"11853928708","pt":1723320649708,"mc":[{"id":"1.231581624","rc":[{"batb":[[0,2.34,4]],"ltp":2.36,"tv":28.0,"id":31378}]}]}
{"op":"mcm","clk":"11853929167","pt":1723320652122,"mc":[{"id":"1.231581624","rc":[{"batb":[[0,2.34,10]],"ltp":2.36,"tv":28.0,"id":31378}]}]}
{"op":"mcm","clk":"11853929831","pt":1723320655909,"mc":[{"id":"1.231581624","rc":[{"batb":[[0,2.36,4]],"ltp":2.36,"tv":28.0,"id":31378}]}]}
{"op":"mcm","clk":"11853930292","pt":1723320658392,"mc":[{"id":"1.231581624","rc":[{"batb":[[0,2.34,10]],"ltp":2.36,"tv":28.0,"id":31378}]}]}
{"op":"mcm","clk":"11853930621","pt":1723320660491,"mc":[{"id":"1.231581624","rc":[{"batb":[[0,2.36,4],[1,2.34,10],[2,2.32,29.57]],"ltp":2.36,"tv":28.0,"id":31378}]}]}
{"op":"mcm","clk":"11853930817","pt":1723320661805,"mc":[{"id":"1.231581624","rc":[{"batb":[[1,2.32,29.57],[2,1.3,1000]],"ltp":2.36,"tv":28.0,"id":31378}]}]}
{"op":"mcm","clk":"11853930994","pt":1723320662808,"mc":[{"id":"1.231581624","rc":[{"batb":[[0,2.32,29.57],[1,1.3,1000],[2,1.08,7.85]],"ltp":2.36,"tv":28.0,"id":31378}]}]}
{"op":"mcm","clk":"11853931807","pt":1723320667296,"mc":[{"id":"1.231581624","rc":[{"batb":[[0,2.34,14],[1,2.32,29.57],[2,1.3,1000]],"ltp":2.36,"tv":28.0,"id":31378}]}]}
{"op":"mcm","clk":"11853932172","pt":1723320669624,"mc":[{"id":"1.231581624","rc":[{"batb":[[0,2.34,10]],"ltp":2.36,"tv":28.0,"id":31378}]}]}
{"op":"mcm","clk":"11853932344","pt":1723320670632,"mc":[{"id":"1.231581624","rc":[{"batb":[[0,2.32,29.57],[1,1.3,1000],[2,1.08,7.85]],"ltp":2.36,"tv":28.0,"id":31378}]}]}
{"op":"mcm","clk":"11853932594","pt":1723320672050,"mc":[{"id":"1.231581624","rc":[{"batb":[[0,2.34,4],[1,2.32,29.57],[2,1.3,1000]],"ltp":2.36,"tv":28.0,"id":31378}]}]}
{"op":"mcm","clk":"11853932810","pt":1723320673225,"mc":[{"id":"1.231581624","rc":[{"batb":[[0,2.36,10],[1,2.34,4],[2,2.32,29.57]],"ltp":2.36,"tv":28.0,"id":31378}]}]}
{"op":"mcm","clk":"11853933032","pt":1723320674416,"mc":[{"id":"1.231581624","rc":[{"batb":[[1,2.32,29.57],[2,1.3,1000]],"ltp":2.36,"tv":28.0,"id":31378}]}]}
{"op":"mcm","clk":"11853933444","pt":1723320676628,"mc":[{"id":"1.231581624","rc":[{"batb":[[0,2.34,4]],"ltp":2.36,"tv":28.0,"id":31378}]}]}
{"op":"mcm","clk":"11853933949","pt":1723320679419,"mc":[{"id":"1.231581624","rc":[{"batb":[[0,2.36,10]],"ltp":2.36,"tv":28.0,"id":31378}]}]}
{"op":"mcm","clk":"11853934484","pt":1723320682319,"mc":[{"id":"1.231581624","rc":[{"batb":[[0,2.38,4],[1,2.36,10],[2,2.32,29.57]],"ltp":2.36,"tv":28.0,"id":31378}]}]}
{"op":"mcm","clk":"11853934563","pt":1723320682847,"mc":[{"id":"1.231581624","rc":[{"batb":[[1,2.32,29.57],[2,1.3,1000]],"ltp":2.36,"tv":28.0,"id":31378}]}]}
{"op":"mcm","clk":"11853934847","pt":1723320684633,"mc":[{"id":"1.231581624","rc":[{"batb":[[0,2.32,29.57],[1,1.3,1000],[2,1.08,7.85]],"ltp":2.36,"tv":28.0,"id":31378}]}]}
{"op":"mcm","clk":"11853935050","pt":1723320685752,"mc":[{"id":"1.231581624","rc":[{"batb":[[0,2.34,10],[1,2.32,29.57],[2,1.3,1000]],"ltp":2.36,"tv":28.0,"id":31378}]}]}
{"op":"mcm","clk":"11853935612","pt":1723320689232,"mc":[{"id":"1.231581624","rc":[{"batb":[[0,2.36,4]],"ltp":2.36,"tv":28.0,"id":31378}]}]}
{"op":"mcm","clk":"11853935993","pt":1723320691419,"mc":[{"id":"1.231581624","rc":[{"batb":[[0,2.32,29.57],[1,1.3,1000],[2,1.08,7.85]],"ltp":2.36,"tv":28.0,"id":31378}]}]}
{"op":"mcm","clk":"11853936056","pt":1723320691836,"mc":[{"id":"1.231581624","rc":[{"batb":[[0,2.34,10],[1,2.32,29.57],[2,1.3,1000]],"ltp":2.36,"tv":28.0,"id":31378}]}]}
{"op":"mcm","clk":"11853936614","pt":1723320695234,"mc":[{"id":"1.231581624","rc":[{"batb":[[0,2.34,4]],"ltp":2.36,"tv":28.0,"id":31378}]}]}
{"op":"mcm","clk":"11853937025","pt":1723320697445,"mc":[{"id":"1.231581624","rc":[{"batb":[[0,2.32,29.57],[1,1.3,1000],[2,1.08,7.85]],"ltp":2.36,"tv":28.0,"id":31378}]}]}
{"op":"mcm","clk":"11853937044","pt":1723320697557,"mc":[{"id":"1.231581624","rc":[{"batb":[[0,2.34,10],[1,2.32,29.57],[2,1.3,1000]],"ltp":2.36,"tv":28.0,"id":31378}]}]}
{"op":"mcm","clk":"11853937614","pt":1723320700870,"mc":[{"id":"1.231581624","rc":[{"batb":[[0,2.36,4]],"ltp":2.36,"tv":28.0,"id":31378}]}]}
{"op":"mcm","clk":"11853938043","pt":1723320703357,"mc":[{"id":"1.231581624","rc":[{"batb":[[0,2.34,10]],"ltp":2.36,"tv":28.0,"id":31378}]}]}
{"op":"mcm","clk":"11853938453","pt":1723320705739,"mc":[{"id":"1.231581624","rc":[{"batb":[[0,2.36,4],[1,2.34,10],[2,2.32,29.57]],"ltp":2.36,"tv":28.0,"id":31378}]}]}
{"op":"mcm","clk":"11853938660","pt":1723320706991,"mc":[{"id":"1.231581624","rc":[{"batb":[[1,2.32,29.57],[2,1.3,1000]],"ltp":2.36,"tv":28.0,"id":31378}]}]}
{"op":"mcm","clk":"11853938834","pt":1723320707950,"mc":[{"id":"1.231581624","rc":[{"batb":[[0,2.32,29.57],[1,1.3,1000],[2,1.08,7.85]],"ltp":2.36,"tv":28.0,"id":31378}]}]}
{"op":"mcm","clk":"11853939350","pt":1723320711144,"mc":[{"id":"1.231581624","rc":[{"batb":[[0,2.34,14],[1,2.32,29.57],[2,1.3,1000]],"ltp":2.36,"tv":28.0,"id":31378}]}]}
{"op":"mcm","clk":"11853939758","pt":1723320713459,"mc":[{"id":"1.231581624","rc":[{"batb":[[0,2.34,10]],"ltp":2.36,"tv":28.0,"id":31378}]}]}
{"op":"mcm","clk":"11853939893","pt":1723320714348,"mc":[{"id":"1.231581624","rc":[{"batb":[[0,2.32,29.57],[1,1.3,1000],[2,1.08,7.85]],"ltp":2.36,"tv":28.0,"id":31378}]}]}
{"op":"mcm","clk":"11853940258","pt":1723320716658,"mc":[{"id":"1.231581624","rc":[{"batb":[[0,2.34,14],[1,2.32,29.57],[2,1.3,1000]],"ltp":2.36,"tv":28.0,"id":31378}]}]}
{"op":"mcm","clk":"11853940662","pt":1723320718962,"mc":[{"id":"1.231581624","rc":[{"batb":[[0,2.34,10]],"ltp":2.36,"tv":28.0,"id":31378}]}]}
{"op":"mcm","clk":"11853940831","pt":1723320719977,"mc":[{"id":"1.231581624","rc":[{"batb":[[0,2.32,29.57],[1,1.3,1000],[2,1.08,7.85]],"ltp":2.36,"tv":28.0,"id":31378}]}]}
{"op":"mcm","clk":"11853942025","pt":1723320727073,"mc":[{"id":"1.231581624","rc":[{"batb":[[0,2.34,14],[1,2.32,29.57],[2,1.3,1000]],"ltp":2.36,"tv":28.0,"id":31378}]}]}
{"op":"mcm","clk":"11853942397","pt":1723320729395,"mc":[{"id":"1.231581624","rc":[{"batb":[[0,2.34,10]],"ltp":2.36,"tv":28.0,"id":31378}]}]}
{"op":"mcm","clk":"11853942550","pt":1723320730395,"mc":[{"id":"1.231581624","rc":[{"batb":[[0,2.32,29.57],[1,1.3,1000],[2,1.08,7.85]],"ltp":2.36,"tv":28.0,"id":31378}]}]}
{"op":"mcm","clk":"11853942872","pt":1723320732303,"mc":[{"id":"1.231581624","rc":[{"batb":[[0,2.34,4],[1,2.32,29.57],[2,1.3,1000]],"ltp":2.36,"tv":28.0,"id":31378}]}]}
{"op":"mcm","clk":"11853943163","pt":1723320733886,"mc":[{"id":"1.231581624","rc":[{"batb":[[0,2.36,10],[1,2.34,4],[2,2.32,29.57]],"ltp":2.36,"tv":28.0,"id":31378}]}]}
{"op":"mcm","clk":"11853943300","pt":1723320734684,"mc":[{"id":"1.231581624","rc":[{"batb":[[1,2.32,29.57],[2,1.3,1000]],"ltp":2.36,"tv":28.0,"id":31378}]}]}
{"op":"mcm","clk":"11853943795","pt":1723320737483,"mc":[{"id":"1.231581624","rc":[{"batb":[[0,2.34,4]],"ltp":2.36,"tv":28.0,"id":31378}]}]}
{"op":"mcm","clk":"11853944203","pt":1723320739908,"mc":[{"id":"1.231581624","rc":[{"batb":[[0,2.34,10]],"ltp":2.36,"tv":28.0,"id":31378}]}]}
{"op":"mcm","clk":"11853944789","pt":1723320743277,"mc":[{"id":"1.231581624","rc":[{"batb":[[0,2.34,4]],"ltp":2.36,"tv":28.0,"id":31378}]}]}
{"op":"mcm","clk":"11853945186","pt":1723320745702,"mc":[{"id":"1.231581624","rc":[{"batb":[[0,2.34,10]],"ltp":2.36,"tv":28.0,"id":31378}]}]}
{"op":"mcm","clk":"11853945741","pt":1723320748986,"mc":[{"id":"1.231581624","rc":[{"batb":[[0,2.34,4]],"ltp":2.36,"tv":28.0,"id":31378}]}]}
{"op":"mcm","clk":"11853946166","pt":1723320751473,"mc":[{"id":"1.231581624","rc":[{"batb":[[0,2.34,10]],"ltp":2.36,"tv":28.0,"id":31378}]}]}
{"op":"mcm","clk":"11853946738","pt":1723320755010,"mc":[{"id":"1.231581624","rc":[{"batb":[[0,2.34,4]],"ltp":2.36,"tv":28.0,"id":31378}]}]}
{"op":"mcm","clk":"11853947147","pt":1723320757492,"mc":[{"id":"1.231581624","rc":[{"batb":[[0,2.32,29.57],[1,1.3,1000],[2,1.08,7.85]],"ltp":2.36,"tv":28.0,"id":31378}]}]}
{"op":"mcm","clk":"11853947162","pt":1723320757600,"mc":[{"id":"1.231581624","rc":[{"batb":[[0,2.34,10],[1,2.32,29.57],[2,1.3,1000]],"ltp":2.36,"tv":28.0,"id":31378}]}]}
{"op":"mcm","clk":"11853947565","pt":1723320760011,"mc":[{"id":"1.231581624","rc":[{"batb":[[0,2.36,4],[1,2.34,10],[2,2.32,29.57]],"ltp":2.36,"tv":28.0,"id":31378}]}]}
{"op":"mcm","clk":"11853947722","pt":1723320760986,"mc":[{"id":"1.231581624","rc":[{"batb":[[1,2.32,29.57],[2,1.3,1000]],"ltp":2.36,"tv":28.0,"id":31378}]}]}
{"op":"mcm","clk":"11853947935","pt":1723320762300,"mc":[{"id":"1.231581624","rc":[{"batb":[[0,2.32,29.57],[1,1.3,1000],[2,1.08,7.85]],"ltp":2.36,"tv":28.0,"id":31378}]}]}
{"op":"mcm","clk":"11853948277","pt":1723320764406,"mc":[{"id":"1.231581624","rc":[{"batb":[[0,2.34,14],[1,2.32,29.57],[2,1.3,1000]],"ltp":2.36,"tv":28.0,"id":31378}]}]}
{"op":"mcm","clk":"11853948666","pt":1723320766824,"mc":[{"id":"1.231581624","rc":[{"batb":[[0,2.34,10]],"ltp":2.36,"tv":28.0,"id":31378}]}]}
{"op":"mcm","clk":"11853948812","pt":1723320767725,"mc":[{"id":"1.231581624","rc":[{"batb":[[0,2.32,29.57],[1,1.3,1000],[2,1.08,7.85]],"ltp":2.36,"tv":28.0,"id":31378}]}]}
{"op":"mcm","clk":"11853949307","pt":1723320770824,"mc":[{"id":"1.231581624","rc":[{"batb":[[0,2.34,14],[1,2.32,29.57],[2,1.3,1000]],"ltp":2.36,"tv":28.0,"id":31378}]}]}
{"op":"mcm","clk":"11853949701","pt":1723320773312,"mc":[{"id":"1.231581624","rc":[{"batb":[[0,2.34,10]],"ltp":2.36,"tv":28.0,"id":31378}]}]}
{"op":"mcm","clk":"11853949827","pt":1723320774211,"mc":[{"id":"1.231581624","rc":[{"batb":[[0,2.32,29.57],[1,1.3,1000],[2,1.08,7.85]],"ltp":2.36,"tv":28.0,"id":31378}]}]}
{"op":"mcm","clk":"11853962657","pt":1723320781616,"mc":[{"id":"1.231581624","rc":[{"batb":[[0,2.34,14],[1,2.32,29.57],[2,1.3,1000]],"ltp":2.36,"tv":28.0,"id":31378}]}]}
{"op":"mcm","clk":"11853963034","pt":1723320783938,"mc":[{"id":"1.231581624","rc":[{"batb":[[0,2.34,10]],"ltp":2.36,"tv":28.0,"id":31378}]}]}
{"op":"mcm","clk":"11853963197","pt":1723320784936,"mc":[{"id":"1.231581624","rc":[{"batb":[[0,2.32,29.57],[1,1.3,1000],[2,1.08,7.85]],"ltp":2.36,"tv":28.0,"id":31378}]}]}
{"op":"mcm","clk":"11853963466","pt":1723320786618,"mc":[{"id":"1.231581624","rc":[{"batb":[[0,2.34,4],[1,2.32,29.57],[2,1.3,1000]],"ltp":2.36,"tv":28.0,"id":31378}]}]}
{"op":"mcm","clk":"11853963879","pt":1723320789041,"mc":[{"id":"1.231581624","rc":[{"batb":[[0,2.36,10]],"ltp":2.36,"tv":28.0,"id":31378}]}]}
{"op":"mcm","clk":"11853964415","pt":1723320792242,"mc":[{"id":"1.231581624","rc":[{"batb":[[0,2.34,4]],"ltp":2.36,"tv":28.0,"id":31378}]}]}
{"op":"mcm","clk":"11853964782","pt":1723320794511,"mc":[{"id":"1.231581624","rc":[{"batb":[[0,2.32,29.57],[1,1.3,1000],[2,1.08,7.85]],"ltp":2.36,"tv":28.0,"id":31378}]}]}
{"op":"mcm","clk":"11853964872","pt":1723320795032,"mc":[{"id":"1.231581624","rc":[{"batb":[[0,2.34,10],[1,2.32,29.57],[2,1.3,1000]],"ltp":2.36,"tv":28.0,"id":31378}]}]}
{"op":"mcm","clk":"11853965425","pt":1723320798350,"mc":[{"id":"1.231581624","rc":[{"batb":[[0,2.32,29.57],[1,1.3,1000],[2,1.08,7.85]],"ltp":2.36,"tv":28.0,"id":31378}]}]}
{"op":"mcm","clk":"11853965455","pt":1723320798557,"mc":[{"id":"1.231581624","rc":[{"batb":[[0,2.34,4],[1,2.32,29.57],[2,1.3,1000]],"ltp":2.36,"tv":28.0,"id":31378}]}]}
{"op":"mcm","clk":"11853965867","pt":1723320800935,"mc":[{"id":"1.231581624","rc":[{"batb":[[0,2.34,10]],"ltp":2.36,"tv":28.0,"id":31378}]}]}
{"op":"mcm","clk":"11853966433","pt":1723320804455,"mc":[{"id":"1.231581624","rc":[{"batb":[[0,2.34,4]],"ltp":2.36,"tv":28.0,"id":31378}]}]}
{"op":"mcm","clk":"11853966865","pt":1723320806852,"mc":[{"id":"1.231581624","rc":[{"batb":[[0,2.34,10]],"ltp":2.36,"tv":28.0,"id":31378}]}]}
{"op":"mcm","clk":"11853967425","pt":1723320810267,"mc":[{"id":"1.231581624","rc":[{"batb":[[0,2.36,4]],"ltp":2.36,"tv":28.0,"id":31378}]}]}
{"op":"mcm","clk":"11853967792","pt":1723320812447,"mc":[{"id":"1.231581624","rc":[{"batb":[[0,2.34,10]],"ltp":2.36,"tv":28.0,"id":31378}]}]}
{"op":"mcm","clk":"11853968155","pt":1723320814790,"mc":[{"id":"1.231581624","rc":[{"batb":[[0,2.36,4],[1,2.34,10],[2,2.32,29.57]],"ltp":2.36,"tv":28.0,"id":31378}]}]}
{"op":"mcm","clk":"11853968321","pt":1723320815745,"mc":[{"id":"1.231581624","rc":[{"batb":[[1,2.32,29.57],[2,1.3,1000]],"ltp":2.36,"tv":28.0,"id":31378}]}]}
{"op":"mcm","clk":"11853968564","pt":1723320817168,"mc":[{"id":"1.231581624","rc":[{"batb":[[0,2.32,29.57],[1,1.3,1000],[2,1.08,7.85]],"ltp":2.36,"tv":28.0,"id":31378}]}]}
{"op":"mcm","clk":"11853968916","pt":1723320819346,"mc":[{"id":"1.231581624","rc":[{"batb":[[0,2.34,14],[1,2.32,29.57],[2,1.3,1000]],"ltp":2.36,"tv":28.0,"id":31378}]}]}
{"op":"mcm","clk":"11853969289","pt":1723320821762,"mc":[{"id":"1.231581624","rc":[{"batb":[[0,2.34,10]],"ltp":2.36,"tv":28.0,"id":31378}]}]}
{"op":"mcm","clk":"11853969471","pt":1723320822772,"mc":[{"id":"1.231581624","rc":[{"batb":[[0,2.32,29.57],[1,1.3,1000],[2,1.08,7.85]],"ltp":2.36,"tv":28.0,"id":31378}]}]}
{"op":"mcm","clk":"11853970114","pt":1723320826651,"mc":[{"id":"1.231581624","rc":[{"batb":[[0,2.34,14],[1,2.32,29.57],[2,1.3,1000]],"ltp":2.36,"tv":28.0,"id":31378}]}]}
{"op":"mcm","clk":"11853970524","pt":1723320829068,"mc":[{"id":"1.231581624","rc":[{"batb":[[0,2.34,10]],"ltp":2.36,"tv":28.0,"id":31378}]}]}
{"op":"mcm","clk":"11853970682","pt":1723320830065,"mc":[{"id":"1.231581624","rc":[{"batb":[[0,2.32,29.57],[1,1.3,1000],[2,1.08,7.85]],"ltp":2.36,"tv":28.0,"id":31378}]}]}
{"op":"mcm","clk":"11853970950","pt":1723320831607,"mc":[{"id":"1.231581624","rc":[{"batb":[[0,2.34,4],[1,2.32,29.57],[2,1.3,1000]],"ltp":2.36,"tv":28.0,"id":31378}]}]}
{"op":"mcm","clk":"11853971154","pt":1723320832774,"mc":[{"id":"1.231581624","rc":[{"batb":[[0,2.36,10],[1,2.34,4],[2,2.32,29.57]],"ltp":2.36,"tv":28.0,"id":31378}]}]}
{"op":"mcm","clk":"11853971324","pt":1723320833988,"mc":[{"id":"1.231581624","rc":[{"batb":[[1,2.32,29.57],[2,1.3,1000]],"ltp":2.36,"tv":28.0,"id":31378}]}]}
{"op":"mcm","clk":"11853971678","pt":1723320836265,"mc":[{"id":"1.231581624","rc":[{"batb":[[0,2.34,4]],"ltp":2.36,"tv":28.0,"id":31378}]}]}
{"op":"mcm","clk":"11853972110","pt":1723320838867,"mc":[{"id":"1.231581624","rc":[{"batb":[[0,2.34,10]],"ltp":2.36,"tv":28.0,"id":31378}]}]}
{"op":"mcm","clk":"11853972504","pt":1723320841292,"mc":[{"id":"1.231581624","rc":[{"batb":[[0,2.36,4],[1,2.34,10],[2,2.32,29.57]],"ltp":2.36,"tv":28.0,"id":31378}]}]}
{"op":"mcm","clk":"11853972664","pt":1723320842194,"mc":[{"id":"1.231581624","rc":[{"batb":[[1,2.32,29.57],[2,1.3,1000]],"ltp":2.36,"tv":28.0,"id":31378}]}]}
{"op":"mcm","clk":"11853972914","pt":1723320843681,"mc":[{"id":"1.231581624","rc":[{"batb":[[0,2.32,29.57],[1,1.3,1000],[2,1.08,7.85]],"ltp":2.36,"tv":28.0,"id":31378}]}]}
{"op":"mcm","clk":"11853973709","pt":1723320848163,"mc":[{"id":"1.231581624","rc":[{"batb":[[0,2.34,14],[1,2.32,29.57],[2,1.3,1000]],"ltp":2.36,"tv":28.0,"id":31378}]}]}
{"op":"mcm","clk":"11853974093","pt":1723320850485,"mc":[{"id":"1.231581624","rc":[{"batb":[[0,2.34,10]],"ltp":2.36,"tv":28.0,"id":31378}]}]}
{"op":"mcm","clk":"11853974250","pt":1723320851506,"mc":[{"id":"1.231581624","rc":[{"batb":[[0,2.32,29.57],[1,1.3,1000],[2,1.08,7.85]],"ltp":2.36,"tv":28.0,"id":31378}]}]}
{"op":"mcm","clk":"11853974652","pt":1723320853991,"mc":[{"id":"1.231581624","rc":[{"batb":[[0,2.34,14],[1,2.32,29.57],[2,1.3,1000]],"ltp":2.36,"tv":28.0,"id":31378}]}]}
{"op":"mcm","clk":"11853975037","pt":1723320856299,"mc":[{"id":"1.231581624","rc":[{"batb":[[0,2.34,10]],"ltp":2.36,"tv":28.0,"id":31378}]}]}
{"op":"mcm","clk":"11853975188","pt":1723320857297,"mc":[{"id":"1.231581624","rc":[{"batb":[[0,2.32,29.57],[1,1.3,1000],[2,1.08,7.85]],"ltp":2.36,"tv":28.0,"id":31378}]}]}
{"op":"mcm","clk":"11853975900","pt":1723320862012,"mc":[{"id":"1.231581624","rc":[{"batb":[[0,2.34,14],[1,2.32,29.57],[2,1.3,1000]],"ltp":2.36,"tv":28.0,"id":31378}]}]}
{"op":"mcm","clk":"11853976294","pt":1723320864493,"mc":[{"id":"1.231581624","rc":[{"batb":[[0,2.34,10]],"ltp":2.36,"tv":28.0,"id":31378}]}]}
{"op":"mcm","clk":"11853976461","pt":1723320865498,"mc":[{"id":"1.231581624","rc":[{"batb":[[0,2.32,29.57],[1,1.3,1000],[2,1.08,7.85]],"ltp":2.36,"tv":28.0,"id":31378}]}]}
{"op":"mcm","clk":"11853976841","pt":1723320867825,"mc":[{"id":"1.231581624","rc":[{"batb":[[0,2.34,14],[1,2.32,29.57],[2,1.3,1000]],"ltp":2.36,"tv":28.0,"id":31378}]}]}
{"op":"mcm","clk":"11853977232","pt":1723320870183,"mc":[{"id":"1.231581624","rc":[{"batb":[[0,2.34,10]],"ltp":2.36,"tv":28.0,"id":31378}]}]}
{"op":"mcm","clk":"11853977405","pt":1723320871101,"mc":[{"id":"1.231581624","rc":[{"batb":[[0,2.32,29.57],[1,1.3,1000],[2,1.08,7.85]],"ltp":2.36,"tv":28.0,"id":31378}]}]}
{"op":"mcm","clk":"11853977862","pt":1723320873713,"mc":[{"id":"1.231581624","rc":[{"batb":[[0,2.34,14],[1,2.32,29.57],[2,1.3,1000]],"ltp":2.36,"tv":28.0,"id":31378}]}]}
{"op":"mcm","clk":"11853978256","pt":1723320876196,"mc":[{"id":"1.231581624","rc":[{"batb":[[0,2.34,10]],"ltp":2.36,"tv":28.0,"id":31378}]}]}
{"op":"mcm","clk":"11853978414","pt":1723320877198,"mc":[{"id":"1.231581624","rc":[{"batb":[[0,2.32,29.57],[1,1.3,1000],[2,1.08,7.85]],"ltp":2.36,"tv":28.0,"id":31378}]}]}
{"op":"mcm","clk":"11853978713","pt":1723320879127,"mc":[{"id":"1.231581624","rc":[{"batb":[[0,2.34,4],[1,2.32,29.57],[2,1.3,1000]],"ltp":2.36,"tv":28.0,"id":31378}]}]}
{"op":"mcm","clk":"11853978874","pt":1723320880229,"mc":[{"id":"1.231581624","rc":[{"batb":[[0,2.36,10],[1,2.34,4],[2,2.32,29.57]],"ltp":2.36,"tv":28.0,"id":31378}]}]}
{"op":"mcm","clk":"11853979079","pt":1723320881494,"mc":[{"id":"1.231581624","rc":[{"batb":[[1,2.32,29.57],[2,1.3,1000]],"ltp":2.36,"tv":28.0,"id":31378}]}]}
{"op":"mcm","clk":"11853979410","pt":1723320883640,"mc":[{"id":"1.231581624","rc":[{"batb":[[0,2.34,4]],"ltp":2.36,"tv":28.0,"id":31378}]}]}
{"op":"mcm","clk":"11853979796","pt":1723320885956,"mc":[{"id":"1.231581624","rc":[{"batb":[[0,2.34,10]],"ltp":2.36,"tv":28.0,"id":31378}]}]}
{"op":"mcm","clk":"11853980376","pt":1723320889480,"mc":[{"id":"1.231581624","rc":[{"batb":[[0,2.36,4]],"ltp":2.36,"tv":28.0,"id":31378}]}]}
{"op":"mcm","clk":"11853980624","pt":1723320891017,"mc":[{"id":"1.231581624","rc":[{"batb":[[0,2.32,29.57],[1,1.3,1000],[2,1.08,7.85]],"ltp":2.36,"tv":28.0,"id":31378}]}]}
{"op":"mcm","clk":"11853981125","pt":1723320894332,"mc":[{"id":"1.231581624","rc":[{"batb":[[0,2.34,14],[1,2.32,29.57],[2,1.3,1000]],"ltp":2.36,"tv":28.0,"id":31378}]}]}
{"op":"mcm","clk":"11853981480","pt":1723320896745,"mc":[{"id":"1.231581624","rc":[{"batb":[[0,2.34,10]],"ltp":2.36,"tv":28.0,"id":31378}]}]}
{"op":"mcm","clk":"11853981628","pt":1723320897734,"mc":[{"id":"1.231581624","rc":[{"batb":[[0,2.32,29.57],[1,1.3,1000],[2,1.08,7.85]],"ltp":2.36,"tv":28.0,"id":31378}]}]}
{"op":"mcm","clk":"11853981993","pt":1723320900150,"mc":[{"id":"1.231581624","rc":[{"batb":[[0,2.34,14],[1,2.32,29.57],[2,1.3,1000]],"ltp":2.36,"tv":28.0,"id":31378}]}]}
{"op":"mcm","clk":"11853982334","pt":1723320902330,"mc":[{"id":"1.231581624","rc":[{"batb":[[0,2.34,10]],"ltp":2.36,"tv":28.0,"id":31378}]}]}
{"op":"mcm","clk":"11853982526","pt":1723320903537,"mc":[{"id":"1.231581624","rc":[{"batb":[[0,2.32,29.57],[1,1.3,1000],[2,1.08,7.85]],"ltp":2.36,"tv":28.0,"id":31378}]}]}
{"op":"mcm","clk":"11853982741","pt":1723320904757,"mc":[{"id":"1.231581624","rc":[{"batb":[[0,2.34,4],[1,2.32,29.57],[2,1.3,1000]],"ltp":2.36,"tv":28.0,"id":31378}]}]}
{"op":"mcm","clk":"11853983116","pt":1723320907075,"mc":[{"id":"1.231581624","rc":[{"batb":[[0,2.36,10]],"ltp":2.36,"tv":28.0,"id":31378}]}]}
{"op":"mcm","clk":"11853983620","pt":1723320910272,"mc":[{"id":"1.231581624","rc":[{"batb":[[0,2.34,4]],"ltp":2.36,"tv":28.0,"id":31378}]}]}
{"op":"mcm","clk":"11853984007","pt":1723320912737,"mc":[{"id":"1.231581624","rc":[{"batb":[[0,2.34,10]],"ltp":2.36,"tv":28.0,"id":31378}]}]}
{"op":"mcm","clk":"11853984611","pt":1723320916166,"mc":[{"id":"1.231581624","rc":[{"batb":[[0,2.34,4]],"ltp":2.36,"tv":28.0,"id":31378}]}]}
{"op":"mcm","clk":"11853984947","pt":1723320918388,"mc":[{"id":"1.231581624","rc":[{"batb":[[0,2.32,29.57],[1,1.3,1000],[2,1.08,7.85]],"ltp":2.36,"tv":28.0,"id":31378}]}]}
{"op":"mcm","clk":"11853984978","pt":1723320918560,"mc":[{"id":"1.231581624","rc":[{"batb":[[0,2.34,10],[1,2.32,29.57],[2,1.3,1000]],"ltp":2.36,"tv":28.0,"id":31378}]}]}
{"op":"mcm","clk":"11853985577","pt":1723320922168,"mc":[{"id":"1.231581624","rc":[{"batb":[[0,2.34,4]],"ltp":2.36,"tv":28.0,"id":31378}]}]}
{"op":"mcm","clk":"11853985946","pt":1723320924380,"mc":[{"id":"1.231581624","rc":[{"batb":[[0,2.32,29.57],[1,1.3,1000],[2,1.08,7.85]],"ltp":2.36,"tv":28.0,"id":31378}]}]}
{"op":"mcm","clk":"11853985990","pt":1723320924548,"mc":[{"id":"1.231581624","rc":[{"batb":[[0,2.34,10],[1,2.32,29.57],[2,1.3,1000]],"ltp":2.36,"tv":28.0,"id":31378}]}]}
{"op":"mcm","clk":"11853986405","pt":1723320927087,"mc":[{"id":"1.231581624","rc":[{"batb":[[0,2.36,4],[1,2.34,10],[2,2.32,29.57]],"ltp":2.36,"tv":28.0,"id":31378}]}]}
{"op":"mcm","clk":"11853986522","pt":1723320927770,"mc":[{"id":"1.231581624","rc":[{"batb":[[1,2.32,29.57],[2,1.3,1000]],"ltp":2.36,"tv":28.0,"id":31378}]}]}
{"op":"mcm","clk":"11853986784","pt":1723320929463,"mc":[{"id":"1.231581624","rc":[{"batb":[[0,2.32,29.57],[1,1.3,1000],[2,1.08,7.85]],"ltp":2.36,"tv":28.0,"id":31378}]}]}
{"op":"mcm","clk":"11853987134","pt":1723320931862,"mc":[{"id":"1.231581624","rc":[{"batb":[[0,2.36,4],[1,2.34,10],[2,2.32,29.57]],"ltp":2.36,"tv":28.0,"id":31378}]}]}
{"op":"mcm","clk":"11853987492","pt":1723320934175,"mc":[{"id":"1.231581624","rc":[{"batb":[[0,2.34,10],[1,2.32,29.57],[2,1.3,1000]],"ltp":2.36,"tv":28.0,"id":31378}]}]}
{"op":"mcm","clk":"11853987624","pt":1723320934967,"mc":[{"id":"1.231581624","rc":[{"batb":[[0,2.32,29.57],[1,1.3,1000],[2,1.08,7.85]],"ltp":2.36,"tv":28.0,"id":31378}]}]}
{"op":"mcm","clk":"11853988126","pt":1723320938380,"mc":[{"id":"1.231581624","rc":[{"batb":[[0,2.34,14],[1,2.32,29.57],[2,1.3,1000]],"ltp":2.36,"tv":28.0,"id":31378}]}]}
{"op":"mcm","clk":"11853988466","pt":1723320940700,"mc":[{"id":"1.231581624","rc":[{"batb":[[0,2.34,10]],"ltp":2.36,"tv":28.0,"id":31378}]}]}
{"op":"mcm","clk":"11853988613","pt":1723320941792,"mc":[{"id":"1.231581624","rc":[{"batb":[[0,2.32,29.57],[1,1.3,1000],[2,1.08,7.85]],"ltp":2.36,"tv":28.0,"id":31378}]}]}
{"op":"mcm","clk":"11853988809","pt":1723320943209,"mc":[{"id":"1.231581624","rc":[{"batb":[[0,2.34,4],[1,2.32,29.57],[2,1.3,1000]],"ltp":2.36,"tv":28.0,"id":31378}]}]}
{"op":"mcm","clk":"11853989130","pt":1723320945483,"mc":[{"id":"1.231581624","rc":[{"batb":[[0,2.32,29.57],[1,1.3,1000],[2,1.08,7.85]],"ltp":2.36,"tv":28.0,"id":31378}]}]}
{"op":"mcm","clk":"11853989161","pt":1723320945689,"mc":[{"id":"1.231581624","rc":[{"batb":[[0,2.34,10],[1,2.32,29.57],[2,1.3,1000]],"ltp":2.36,"tv":28.0,"id":31378}]}]}
{"op":"mcm","clk":"11853989490","pt":1723320947903,"mc":[{"id":"1.231581624","rc":[{"batb":[[0,2.36,4],[1,2.34,10],[2,2.32,29.57]],"ltp":2.36,"tv":28.0,"id":31378}]}]}
{"op":"mcm","clk":"11853989651","pt":1723320949098,"mc":[{"id":"1.231581624","rc":[{"batb":[[1,2.32,29.57],[2,1.3,1000]],"ltp":2.36,"tv":28.0,"id":31378}]}]}
{"op":"mcm","clk":"11853989811","pt":1723320950197,"mc":[{"id":"1.231581624","rc":[{"batb":[[0,2.32,29.57],[1,1.3,1000],[2,1.08,7.85]],"ltp":2.36,"tv":28.0,"id":31378}]}]}
{"op":"mcm","clk":"11853990230","pt":1723320953093,"mc":[{"id":"1.231581624","rc":[{"batb":[[0,2.34,14],[1,2.32,29.57],[2,1.3,1000]],"ltp":2.36,"tv":28.0,"id":31378}]}]}
{"op":"mcm","clk":"11853990619","pt":1723320955605,"mc":[{"id":"1.231581624","rc":[{"batb":[[0,2.34,10]],"ltp":2.36,"tv":28.0,"id":31378}]}]}
{"op":"mcm","clk":"11853990775","pt":1723320956612,"mc":[{"id":"1.231581624","rc":[{"batb":[[0,2.32,29.57],[1,1.3,1000],[2,1.08,7.85]],"ltp":2.36,"tv":28.0,"id":31378}]}]}
{"op":"mcm","clk":"11853991435","pt":1723320960887,"mc":[{"id":"1.231581624","rc":[{"batb":[[0,2.34,14],[1,2.32,29.57],[2,1.3,1000]],"ltp":2.36,"tv":28.0,"id":31378}]}]}
{"op":"mcm","clk":"11853991828","pt":1723320963321,"mc":[{"id":"1.231581624","rc":[{"batb":[[0,2.34,10]],"ltp":2.36,"tv":28.0,"id":31378}]}]}
{"op":"mcm","clk":"11853991996","pt":1723320964305,"mc":[{"id":"1.231581624","rc":[{"batb":[[0,2.32,29.57],[1,1.3,1000],[2,1.08,7.85]],"ltp":2.36,"tv":28.0,"id":31378}]}]}
{"op":"mcm","clk":"11853992330","pt":1723320966216,"mc":[{"id":"1.231581624","rc":[{"batb":[[0,2.34,4],[1,2.32,29.57],[2,1.3,1000]],"ltp":2.36,"tv":28.0,"id":31378}]}]}
{"op":"mcm","clk":"11853992714","pt":1723320968739,"mc":[{"id":"1.231581624","rc":[{"batb":[[0,2.34,10]],"ltp":2.36,"tv":28.0,"id":31378}]}]}
{"op":"mcm","clk":"11853993146","pt":1723320971511,"mc":[{"id":"1.231581624","rc":[{"batb":[[0,2.36,4],[1,2.34,10],[2,2.32,29.57]],"ltp":2.36,"tv":28.0,"id":31378}]}]}
{"op":"mcm","clk":"11853993281","pt":1723320972336,"mc":[{"id":"1.231581624","rc":[{"batb":[[1,2.32,29.57],[2,1.3,1000]],"ltp":2.36,"tv":28.0,"id":31378}]}]}
{"op":"mcm","clk":"11853993516","pt":1723320973817,"mc":[{"id":"1.231581624","rc":[{"batb":[[0,2.32,29.57],[1,1.3,1000],[2,1.08,7.85]],"ltp":2.36,"tv":28.0,"id":31378}]}]}
{"op":"mcm","clk":"11853994338","pt":1723320978914,"mc":[{"id":"1.231581624","rc":[{"batb":[[0,2.34,14],[1,2.32,29.57],[2,1.3,1000]],"ltp":2.36,"tv":28.0,"id":31378}]}]}
{"op":"mcm","clk":"11853994685","pt":1723320981228,"mc":[{"id":"1.231581624","rc":[{"batb":[[0,2.34,10]],"ltp":2.36,"tv":28.0,"id":31378}]}]}
{"op":"mcm","clk":"11853994845","pt":1723320982324,"mc":[{"id":"1.231581624","rc":[{"batb":[[0,2.32,29.57],[1,1.3,1000],[2,1.08,7.85]],"ltp":2.36,"tv":28.0,"id":31378}]}]}
{"op":"mcm","clk":"11853995245","pt":1723320985021,"mc":[{"id":"1.231581624","rc":[{"batb":[[0,2.34,14],[1,2.32,29.57],[2,1.3,1000]],"ltp":2.36,"tv":28.0,"id":31378}]}]}
{"op":"mcm","clk":"11853995600","pt":1723320987424,"mc":[{"id":"1.231581624","rc":[{"batb":[[0,2.34,10]],"ltp":2.36,"tv":28.0,"id":31378}]}]}
{"op":"mcm","clk":"11853995751","pt":1723320988443,"mc":[{"id":"1.231581624","rc":[{"batb":[[0,2.32,29.57],[1,1.3,1000],[2,1.08,7.85]],"ltp":2.36,"tv":28.0,"id":31378}]}]}
{"op":"mcm","clk":"11853996278","pt":1723320991851,"mc":[{"id":"1.231581624","rc":[{"batb":[[0,2.34,14],[1,2.32,29.57],[2,1.3,1000]],"ltp":2.36,"tv":28.0,"id":31378}]}]}
{"op":"mcm","clk":"11853996631","pt":1723320994156,"mc":[{"id":"1.231581624","rc":[{"batb":[[0,2.34,10]],"ltp":2.36,"tv":28.0,"id":31378}]}]}
{"op":"mcm","clk":"11853996798","pt":1723320995157,"mc":[{"id":"1.231581624","rc":[{"batb":[[0,2.32,29.57],[1,1.3,1000],[2,1.08,7.85]],"ltp":2.36,"tv":28.0,"id":31378}]}]}
{"op":"mcm","clk":"11853997610","pt":1723321000560,"mc":[{"id":"1.231581624","rc":[{"batb":[[0,2.34,14],[1,2.32,29.57],[2,1.3,1000]],"ltp":2.36,"tv":28.0,"id":31378}]}]}
{"op":"mcm","clk":"11853997921","pt":1723321002868,"mc":[{"id":"1.231581624","rc":[{"batb":[[0,2.34,10]],"ltp":2.36,"tv":28.0,"id":31378}]}]}
{"op":"mcm","clk":"11853998082","pt":1723321003861,"mc":[{"id":"1.231581624","rc":[{"batb":[[0,2.32,29.57],[1,1.3,1000],[2,1.08,7.85]],"ltp":2.36,"tv":28.0,"id":31378}]}]}
{"op":"mcm","clk":"11853998447","pt":1723321006276,"mc":[{"id":"1.231581624","rc":[{"batb":[[0,2.34,14],[1,2.32,29.57],[2,1.3,1000]],"ltp":2.36,"tv":28.0,"id":31378}]}]}
{"op":"mcm","clk":"11853998799","pt":1723321008549,"mc":[{"id":"1.231581624","rc":[{"batb":[[0,2.34,10]],"ltp":2.36,"tv":28.0,"id":31378}]}]}
{"op":"mcm","clk":"11853998951","pt":1723321009646,"mc":[{"id":"1.231581624","rc":[{"batb":[[0,2.32,29.57],[1,1.3,1000],[2,1.08,7.85]],"ltp":2.36,"tv":28.0,"id":31378}]}]}
{"op":"mcm","clk":"11853999142","pt":1723321010960,"mc":[{"id":"1.231581624","rc":[{"batb":[[0,2.34,4],[1,2.32,29.57],[2,1.3,1000]],"ltp":2.36,"tv":28.0,"id":31378}]}]}
{"op":"mcm","clk":"11853999357","pt":1723321012447,"mc":[{"id":"1.231581624","rc":[{"batb":[[0,2.36,10],[1,2.34,4],[2,2.32,29.57]],"ltp":2.36,"tv":28.0,"id":31378}]}]}
{"op":"mcm","clk":"11853999491","pt":1723321013266,"mc":[{"id":"1.231581624","rc":[{"batb":[[1,2.32,29.57],[2,1.3,1000]],"ltp":2.36,"tv":28.0,"id":31378}]}]}
{"op":"mcm","clk":"11853999949","pt":1723321016057,"mc":[{"id":"1.231581624","rc":[{"batb":[[0,2.34,4]],"ltp":2.36,"tv":28.0,"id":31378}]}]}
{"op":"mcm","clk":"11854000316","pt":1723321018254,"mc":[{"id":"1.231581624","rc":[{"batb":[[0,2.36,10]],"ltp":2.36,"tv":28.0,"id":31378}]}]}
{"op":"mcm","clk":"11854000780","pt":1723321021643,"mc":[{"id":"1.231581624","rc":[{"batb":[[0,2.38,4]],"ltp":2.36,"tv":28.0,"id":31378}]}]}
{"op":"mcm","clk":"11854001164","pt":1723321024171,"mc":[{"id":"1.231581624","rc":[{"batb":[[0,2.34,10]],"ltp":2.36,"tv":28.0,"id":31378}]}]}
{"op":"mcm","clk":"11854001513","pt":1723321026365,"mc":[{"id":"1.231581624","rc":[{"batb":[[0,2.36,4],[1,2.34,10],[2,2.32,29.57]],"ltp":2.36,"tv":28.0,"id":31378}]}]}
{"op":"mcm","clk":"11854001674","pt":1723321027462,"mc":[{"id":"1.231581624","rc":[{"batb":[[1,2.32,29.57],[2,1.3,1000]],"ltp":2.36,"tv":28.0,"id":31378}]}]}
{"op":"mcm","clk":"11854001883","pt":1723321028876,"mc":[{"id":"1.231581624","rc":[{"batb":[[0,2.32,29.57],[1,1.3,1000],[2,1.08,7.85]],"ltp":2.36,"tv":28.0,"id":31378}]}]}
{"op":"mcm","clk":"11854002542","pt":1723321032953,"mc":[{"id":"1.231581624","rc":[{"batb":[[0,2.34,14],[1,2.32,29.57],[2,1.3,1000]],"ltp":2.36,"tv":28.0,"id":31378}]}]}
{"op":"mcm","clk":"11854002918","pt":1723321035365,"mc":[{"id":"1.231581624","rc":[{"batb":[[0,2.34,10]],"ltp":2.36,"tv":28.0,"id":31378}]}]}
{"op":"mcm","clk":"11854003068","pt":1723321036416,"mc":[{"id":"1.231581624","rc":[{"batb":[[0,2.32,29.57],[1,1.3,1000],[2,1.08,7.85]],"ltp":2.36,"tv":28.0,"id":31378}]}]}
{"op":"mcm","clk":"11854004565","pt":1723321046088,"mc":[{"id":"1.231581624","rc":[{"batb":[[0,2.34,14],[1,2.32,29.57],[2,1.3,1000]],"ltp":2.36,"tv":28.0,"id":31378}]}]}
{"op":"mcm","clk":"11854004933","pt":1723321048396,"mc":[{"id":"1.231581624","rc":[{"batb":[[0,2.34,10]],"ltp":2.36,"tv":28.0,"id":31378}]}]}
{"op":"mcm","clk":"11854005124","pt":1723321049592,"mc":[{"id":"1.231581624","rc":[{"batb":[[0,2.32,29.57],[1,1.3,1000],[2,1.08,7.85]],"ltp":2.36,"tv":28.0,"id":31378}]}]}
{"op":"mcm","clk":"11854005819","pt":1723321054087,"mc":[{"id":"1.231581624","rc":[{"batb":[[0,2.34,14],[1,2.32,29.57],[2,1.3,1000]],"ltp":2.36,"tv":28.0,"id":31378}]}]}
{"op":"mcm","clk":"11854006366","pt":1723321057505,"mc":[{"id":"1.231581624","rc":[{"batb":[[0,2.32,29.57],[1,1.3,1000],[2,1.08,7.85]],"ltp":2.36,"tv":28.0,"id":31378}]}]}
{"op":"mcm","clk":"11854006790","pt":1723321060316,"mc":[{"id":"1.231581624","rc":[{"batb":[[0,2.34,14],[1,2.32,29.57],[2,1.3,1000]],"ltp":2.36,"tv":28.0,"id":31378}]}]}
{"op":"mcm","clk":"11854007138","pt":1723321062585,"mc":[{"id":"1.231581624","rc":[{"batb":[[0,2.34,10]],"ltp":2.36,"tv":28.0,"id":31378}]}]}
{"op":"mcm","clk":"11854007325","pt":1723321063801,"mc":[{"id":"1.231581624","rc":[{"batb":[[0,2.32,29.57],[1,1.3,1000],[2,1.08,7.85]],"ltp":2.36,"tv":28.0,"id":31378}]}]}
{"op":"mcm","clk":"11854007555","pt":1723321065320,"mc":[{"id":"1.231581624","rc":[{"batb":[[0,2.34,4],[1,2.32,29.57],[2,1.3,1000]],"ltp":2.36,"tv":28.0,"id":31378}]}]}
{"op":"mcm","clk":"11854007749","pt":1723321066700,"mc":[{"id":"1.231581624","rc":[{"batb":[[0,2.36,10],[1,2.34,4],[2,2.32,29.57]],"ltp":2.36,"tv":28.0,"id":31378}]}]}
{"op":"mcm","clk":"11854007897","pt":1723321067697,"mc":[{"id":"1.231581624","rc":[{"batb":[[1,2.32,29.57],[2,1.3,1000]],"ltp":2.36,"tv":28.0,"id":31378}]}]}
{"op":"mcm","clk":"11854008292","pt":1723321070315,"mc":[{"id":"1.231581624","rc":[{"batb":[[0,2.34,4]],"ltp":2.36,"tv":28.0,"id":31378}]}]}
{"op":"mcm","clk":"11854008648","pt":1723321072620,"mc":[{"id":"1.231581624","rc":[{"batb":[[0,2.36,10]],"ltp":2.36,"tv":28.0,"id":31378}]}]}
{"op":"mcm","clk":"11854009195","pt":1723321076022,"mc":[{"id":"1.231581624","rc":[{"batb":[[0,2.34,4]],"ltp":2.36,"tv":28.0,"id":31378}]}]}
{"op":"mcm","clk":"11854009538","pt":1723321078428,"mc":[{"id":"1.231581624","rc":[{"batb":[[0,2.34,10]],"ltp":2.36,"tv":28.0,"id":31378}]}]}
{"op":"mcm","clk":"11854009908","pt":1723321081022,"mc":[{"id":"1.231581624","rc":[{"batb":[[0,2.36,4],[1,2.34,10],[2,2.32,29.57]],"ltp":2.36,"tv":28.0,"id":31378}]}]}
{"op":"mcm","clk":"11854010031","pt":1723321081704,"mc":[{"id":"1.231581624","rc":[{"batb":[[1,2.32,29.57],[2,1.3,1000]],"ltp":2.36,"tv":28.0,"id":31378}]}]}
{"op":"mcm","clk":"11854010276","pt":1723321083428,"mc":[{"id":"1.231581624","rc":[{"batb":[[0,2.32,29.57],[1,1.3,1000],[2,1.08,7.85]],"ltp":2.36,"tv":28.0,"id":31378}]}]}
{"op":"mcm","clk":"11854010501","pt":1723321084610,"mc":[{"id":"1.231581624","rc":[{"batb":[[0,2.34,10],[1,2.32,29.57],[2,1.3,1000]],"ltp":2.36,"tv":28.0,"id":31378}]}]}
{"op":"mcm","clk":"11854010776","pt":1723321086514,"mc":[{"id":"1.231581624","rc":[{"batb":[[0,2.36,4],[1,2.34,10],[2,2.32,29.57]],"ltp":2.36,"tv":28.0,"id":31378}]}]}
{"op":"mcm","clk":"11854011011","pt":1723321088125,"mc":[{"id":"1.231581624","rc":[{"batb":[[1,2.32,29.57],[2,1.3,1000]],"ltp":2.36,"tv":28.0,"id":31378}]}]}
{"op":"mcm","clk":"11854011132","pt":1723321088928,"mc":[{"id":"1.231581624","rc":[{"batb":[[0,2.32,29.57],[1,1.3,1000],[2,1.08,7.85]],"ltp":2.36,"tv":28.0,"id":31378}]}]}
{"op":"mcm","clk":"11854011857","pt":1723321093552,"mc":[{"id":"1.231581624","rc":[{"batb":[[0,2.34,14],[1,2.32,29.57],[2,1.3,1000]],"ltp":2.36,"tv":28.0,"id":31378}]}]}
{"op":"mcm","clk":"11854012235","pt":1723321095936,"mc":[{"id":"1.231581624","rc":[{"batb":[[0,2.34,10]],"ltp":2.36,"tv":28.0,"id":31378}]}]}
{"op":"mcm","clk":"11854012390","pt":1723321096886,"mc":[{"id":"1.231581624","rc":[{"batb":[[0,2.32,29.57],[1,1.3,1000],[2,1.08,7.85]],"ltp":2.36,"tv":28.0,"id":31378}]}]}
{"op":"mcm","clk":"11854012782","pt":1723321099249,"mc":[{"id":"1.231581624","rc":[{"batb":[[0,2.34,14],[1,2.32,29.57],[2,1.3,1000]],"ltp":2.36,"tv":28.0,"id":31378}]}]}
{"op":"mcm","clk":"11854013199","pt":1723321101732,"mc":[{"id":"1.231581624","rc":[{"batb":[[0,2.34,10]],"ltp":2.36,"tv":28.0,"id":31378}]}]}
{"op":"mcm","clk":"11854013353","pt":1723321102665,"mc":[{"id":"1.231581624","rc":[{"batb":[[0,2.32,29.57],[1,1.3,1000],[2,1.08,7.85]],"ltp":2.36,"tv":28.0,"id":31378}]}]}
{"op":"mcm","clk":"11854014730","pt":1723321111877,"mc":[{"id":"1.231581624","rc":[{"batb":[[0,2.34,14],[1,2.32,29.57],[2,1.3,1000]],"ltp":2.36,"tv":28.0,"id":31378}]}]}
{"op":"mcm","clk":"11854015131","pt":1723321114279,"mc":[{"id":"1.231581624","rc":[{"batb":[[0,2.34,10]],"ltp":2.36,"tv":28.0,"id":31378}]}]}
{"op":"mcm","clk":"11854015276","pt":1723321115174,"mc":[{"id":"1.231581624","rc":[{"batb":[[0,2.32,29.57],[1,1.3,1000],[2,1.08,7.85]],"ltp":2.36,"tv":28.0,"id":31378}]}]}
{"op":"mcm","clk":"11854015629","pt":1723321117376,"mc":[{"id":"1.231581624","rc":[{"batb":[[0,2.34,14],[1,2.32,29.57],[2,1.3,1000]],"ltp":2.36,"tv":28.0,"id":31378}]}]}
{"op":"mcm","clk":"11854015967","pt":1723321119582,"mc":[{"id":"1.231581624","rc":[{"batb":[[0,2.34,10]],"ltp":2.36,"tv":28.0,"id":31378}]}]}
{"op":"mcm","clk":"11854016148","pt":1723321120784,"mc":[{"id":"1.231581624","rc":[{"batb":[[0,2.32,29.57],[1,1.3,1000],[2,1.08,7.85]],"ltp":2.36,"tv":28.0,"id":31378}]}]}
{"op":"mcm","clk":"11854016836","pt":1723321125167,"mc":[{"id":"1.231581624","rc":[{"batb":[[0,2.34,14],[1,2.32,29.57],[2,1.3,1000]],"ltp":2.36,"tv":28.0,"id":31378}]}]}
{"op":"mcm","clk":"11854017179","pt":1723321127476,"mc":[{"id":"1.231581624","rc":[{"batb":[[0,2.34,10]],"ltp":2.36,"tv":28.0,"id":31378}]}]}
{"op":"mcm","clk":"11854017345","pt":1723321128485,"mc":[{"id":"1.231581624","rc":[{"batb":[[0,2.32,29.57],[1,1.3,1000],[2,1.08,7.85]],"ltp":2.36,"tv":28.0,"id":31378}]}]}
{"op":"mcm","clk":"11854017521","pt":1723321129598,"mc":[{"id":"1.231581624","rc":[{"batb":[[0,2.34,4],[1,2.32,29.57],[2,1.3,1000]],"ltp":2.36,"tv":28.0,"id":31378}]}]}
{"op":"mcm","clk":"11854017810","pt":1723321131491,"mc":[{"id":"1.231581624","rc":[{"batb":[[0,2.36,10],[1,2.34,4],[2,2.32,29.57]],"ltp":2.36,"tv":28.0,"id":31378}]}]}
{"op":"mcm","clk":"11854017873","pt":1723321131899,"mc":[{"id":"1.231581624","rc":[{"batb":[[1,2.32,29.57],[2,1.3,1000]],"ltp":2.36,"tv":28.0,"id":31378}]}]}
{"op":"mcm","clk":"11854018365","pt":1723321134993,"mc":[{"id":"1.231581624","rc":[{"batb":[[0,2.38,4]],"ltp":2.36,"tv":28.0,"id":31378}]}]}
{"op":"mcm","clk":"11854018682","pt":1723321137202,"mc":[{"id":"1.231581624","rc":[{"batb":[[0,2.34,10]],"ltp":2.36,"tv":28.0,"id":31378}]}]}
{"op":"mcm","clk":"11854019050","pt":1723321139595,"mc":[{"id":"1.231581624","rc":[{"batb":[[0,2.36,4],[1,2.34,10],[2,2.32,29.57]],"ltp":2.36,"tv":28.0,"id":31378}]}]}
{"op":"mcm","clk":"11854019226","pt":1723321140701,"mc":[{"id":"1.231581624","rc":[{"batb":[[1,2.32,29.57],[2,1.3,1000]],"ltp":2.36,"tv":28.0,"id":31378}]}]}
{"op":"mcm","clk":"11854019398","pt":1723321141908,"mc":[{"id":"1.231581624","rc":[{"batb":[[0,2.32,29.57],[1,1.3,1000],[2,1.08,7.85]],"ltp":2.36,"tv":28.0,"id":31378}]}]}
{"op":"mcm","clk":"11854019768","pt":1723321144182,"mc":[{"id":"1.231581624","rc":[{"batb":[[0,2.34,14],[1,2.32,29.57],[2,1.3,1000]],"ltp":2.36,"tv":28.0,"id":31378}]}]}
{"op":"mcm","clk":"11854020126","pt":1723321146400,"mc":[{"id":"1.231581624","rc":[{"batb":[[0,2.34,10]],"ltp":2.36,"tv":28.0,"id":31378}]}]}
{"op":"mcm","clk":"11854020331","pt":1723321147701,"mc":[{"id":"1.231581624","rc":[{"batb":[[0,2.32,29.57],[1,1.3,1000],[2,1.08,7.85]],"ltp":2.36,"tv":28.0,"id":31378}]}]}
{"op":"mcm","clk":"11854020521","pt":1723321148903,"mc":[{"id":"1.231581624","rc":[{"batb":[[0,2.34,4],[1,2.32,29.57],[2,1.3,1000]],"ltp":2.36,"tv":28.0,"id":31378}]}]}
{"op":"mcm","clk":"11854020932","pt":1723321151397,"mc":[{"id":"1.231581624","rc":[{"batb":[[0,2.34,10]],"ltp":2.36,"tv":28.0,"id":31378}]}]}
{"op":"mcm","clk":"11854021358","pt":1723321153993,"mc":[{"id":"1.231581624","rc":[{"batb":[[0,2.36,4],[1,2.34,10],[2,2.32,29.57]],"ltp":2.36,"tv":28.0,"id":31378}]}]}
{"op":"mcm","clk":"11854021483","pt":1723321154790,"mc":[{"id":"1.231581624","rc":[{"batb":[[1,2.32,29.57],[2,1.3,1000]],"ltp":2.36,"tv":28.0,"id":31378}]}]}
{"op":"mcm","clk":"11854021728","pt":1723321156281,"mc":[{"id":"1.231581624","rc":[{"batb":[[0,2.32,29.57],[1,1.3,1000],[2,1.08,7.85]],"ltp":2.36,"tv":28.0,"id":31378}]}]}
{"op":"mcm","clk":"11854022258","pt":1723321159601,"mc":[{"id":"1.231581624","rc":[{"batb":[[0,2.34,14],[1,2.32,29.57],[2,1.3,1000]],"ltp":2.36,"tv":28.0,"id":31378}]}]}
{"op":"mcm","clk":"11854022624","pt":1723321161922,"mc":[{"id":"1.231581624","rc":[{"batb":[[0,2.34,10]],"ltp":2.36,"tv":28.0,"id":31378}]}]}
{"op":"mcm","clk":"11854022776","pt":1723321162824,"mc":[{"id":"1.231581624","rc":[{"batb":[[0,2.32,29.57],[1,1.3,1000],[2,1.08,7.85]],"ltp":2.36,"tv":28.0,"id":31378}]}]}
{"op":"mcm","clk":"11854022982","pt":1723321164126,"mc":[{"id":"1.231581624","rc":[{"batb":[[0,2.34,4],[1,2.32,29.57],[2,1.3,1000]],"ltp":2.36,"tv":28.0,"id":31378}]}]}
{"op":"mcm","clk":"11854023179","pt":1723321165331,"mc":[{"id":"1.231581624","rc":[{"batb":[[0,2.36,10],[1,2.34,4],[2,2.32,29.57]],"ltp":2.36,"tv":28.0,"id":31378}]}]}
{"op":"mcm","clk":"11854023389","pt":1723321166595,"mc":[{"id":"1.231581624","rc":[{"batb":[[1,2.32,29.57],[2,1.3,1000]],"ltp":2.36,"tv":28.0,"id":31378}]}]}
{"op":"mcm","clk":"11854023740","pt":1723321168811,"mc":[{"id":"1.231581624","rc":[{"batb":[[0,2.34,4]],"ltp":2.36,"tv":28.0,"id":31378}]}]}
{"op":"mcm","clk":"11854024110","pt":1723321171233,"mc":[{"id":"1.231581624","rc":[{"batb":[[0,2.36,10]],"ltp":2.36,"tv":28.0,"id":31378}]}]}
{"op":"mcm","clk":"11854024643","pt":1723321174429,"mc":[{"id":"1.231581624","rc":[{"batb":[[0,2.32,29.57],[1,1.3,1000],[2,1.08,7.85]],"ltp":2.36,"tv":28.0,"id":31378}]}]}
{"op":"mcm","clk":"11854024676","pt":1723321174632,"mc":[{"id":"1.231581624","rc":[{"batb":[[0,2.34,4],[1,2.32,29.57],[2,1.3,1000]],"ltp":2.36,"tv":28.0,"id":31378}]}]}
{"op":"mcm","clk":"11854025017","pt":1723321177041,"mc":[{"id":"1.231581624","rc":[{"batb":[[0,2.36,10]],"ltp":2.36,"tv":28.0,"id":31378}]}]}
{"op":"mcm","clk":"11854025393","pt":1723321179327,"mc":[{"id":"1.231581624","rc":[{"batb":[[0,2.38,4],[1,2.36,10],[2,2.32,29.57]],"ltp":2.36,"tv":28.0,"id":31378}]}]}
{"op":"mcm","clk":"11854025526","pt":1723321180220,"mc":[{"id":"1.231581624","rc":[{"batb":[[1,2.32,29.57],[2,1.3,1000]],"ltp":2.36,"tv":28.0,"id":31378}]}]}
{"op":"mcm","clk":"11854025773","pt":1723321181956,"mc":[{"id":"1.231581624","rc":[{"batb":[[0,2.32,29.57],[1,1.3,1000],[2,1.08,7.85]],"ltp":2.36,"tv":28.0,"id":31378}]}]}
{"op":"mcm","clk":"11854026022","pt":1723321183817,"mc":[{"id":"1.231581624","rc":[{"batb":[[0,2.34,10],[1,2.32,29.57],[2,1.3,1000]],"ltp":2.36,"tv":28.0,"id":31378}]}]}
{"op":"mcm","clk":"11854026231","pt":1723321185232,"mc":[{"id":"1.231581624","rc":[{"batb":[[0,2.36,4],[1,2.34,10],[2,2.32,29.57]],"ltp":2.36,"tv":28.0,"id":31378}]}]}
{"op":"mcm","clk":"11854026590","pt":1723321187464,"mc":[{"id":"1.231581624","rc":[{"batb":[[0,2.32,29.57],[1,1.3,1000],[2,1.08,7.85]],"ltp":2.36,"tv":28.0,"id":31378}]}]}
{"op":"mcm","clk":"11854026929","pt":1723321189837,"mc":[{"id":"1.231581624","rc":[{"batb":[[0,2.34,14],[1,2.32,29.57],[2,1.3,1000]],"ltp":2.36,"tv":28.0,"id":31378}]}]}
{"op":"mcm","clk":"11854027311","pt":1723321192357,"mc":[{"id":"1.231581624","rc":[{"batb":[[0,2.34,10]],"ltp":2.36,"tv":28.0,"id":31378}]}]}
{"op":"mcm","clk":"11854027440","pt":1723321193257,"mc":[{"id":"1.231581624","rc":[{"batb":[[0,2.32,29.57],[1,1.3,1000],[2,1.08,7.85]],"ltp":2.36,"tv":28.0,"id":31378}]}]}
{"op":"mcm","clk":"11854027780","pt":1723321195446,"mc":[{"id":"1.231581624","rc":[{"batb":[[0,2.34,14],[1,2.32,29.57],[2,1.3,1000]],"ltp":2.36,"tv":28.0,"id":31378}]}]}
{"op":"mcm","clk":"11854028140","pt":1723321197854,"mc":[{"id":"1.231581624","rc":[{"batb":[[0,2.34,10]],"ltp":2.36,"tv":28.0,"id":31378}]}]}
{"op":"mcm","clk":"11854028294","pt":1723321198849,"mc":[{"id":"1.231581624","rc":[{"batb":[[0,2.32,29.57],[1,1.3,1000],[2,1.08,7.85]],"ltp":2.36,"tv":28.0,"id":31378}]}]}
{"op":"mcm","clk":"11854029044","pt":1723321203560,"mc":[{"id":"1.231581624","rc":[{"batb":[[0,2.34,14],[1,2.32,29.57],[2,1.3,1000]],"ltp":2.36,"tv":28.0,"id":31378}]}]}
{"op":"mcm","clk":"11854029440","pt":1723321205956,"mc":[{"id":"1.231581624","rc":[{"batb":[[0,2.34,10]],"ltp":2.36,"tv":28.0,"id":31378}]}]}
{"op":"mcm","clk":"11854029603","pt":1723321207005,"mc":[{"id":"1.231581624","rc":[{"batb":[[0,2.32,29.57],[1,1.3,1000],[2,1.08,7.85]],"ltp":2.36,"tv":28.0,"id":31378}]}]}
{"op":"mcm","clk":"11854029867","pt":1723321208544,"mc":[{"id":"1.231581624","rc":[{"batb":[[0,2.34,4],[1,2.32,29.57],[2,1.3,1000]],"ltp":2.36,"tv":28.0,"id":31378}]}]}
{"op":"mcm","clk":"11854030043","pt":1723321209761,"mc":[{"id":"1.231581624","rc":[{"batb":[[0,2.36,10],[1,2.34,4],[2,2.32,29.57]],"ltp":2.36,"tv":28.0,"id":31378}]}]}
{"op":"mcm","clk":"11854030258","pt":1723321211058,"mc":[{"id":"1.231581624","rc":[{"batb":[[1,2.32,29.57],[2,1.3,1000]],"ltp":2.36,"tv":28.0,"id":31378}]}]}
{"op":"mcm","clk":"11854030619","pt":1723321213372,"mc":[{"id":"1.231581624","rc":[{"batb":[[0,2.34,4]],"ltp":2.36,"tv":28.0,"id":31378}]}]}
{"op":"mcm","clk":"11854031019","pt":1723321215753,"mc":[{"id":"1.231581624","rc":[{"batb":[[0,2.34,10]],"ltp":2.36,"tv":28.0,"id":31378}]}]}
{"op":"mcm","clk":"11854031433","pt":1723321218369,"mc":[{"id":"1.231581624","rc":[{"batb":[[0,2.36,4],[1,2.34,10],[2,2.32,29.57]],"ltp":2.36,"tv":28.0,"id":31378}]}]}
{"op":"mcm","clk":"11854031554","pt":1723321219064,"mc":[{"id":"1.231581624","rc":[{"batb":[[1,2.32,29.57],[2,1.3,1000]],"ltp":2.36,"tv":28.0,"id":31378}]}]}
{"op":"mcm","clk":"11854031822","pt":1723321220666,"mc":[{"id":"1.231581624","rc":[{"batb":[[0,2.32,29.57],[1,1.3,1000],[2,1.08,7.85]],"ltp":2.36,"tv":28.0,"id":31378}]}]}
{"op":"mcm","clk":"11854032168","pt":1723321222859,"mc":[{"id":"1.231581624","rc":[{"batb":[[0,2.34,14],[1,2.32,29.57],[2,1.3,1000]],"ltp":2.36,"tv":28.0,"id":31378}]}]}
{"op":"mcm","clk":"11854032527","pt":1723321225169,"mc":[{"id":"1.231581624","rc":[{"batb":[[0,2.34,10]],"ltp":2.36,"tv":28.0,"id":31378}]}]}
{"op":"mcm","clk":"11854032684","pt":1723321226185,"mc":[{"id":"1.231581624","rc":[{"batb":[[0,2.32,29.57],[1,1.3,1000],[2,1.08,7.85]],"ltp":2.36,"tv":28.0,"id":31378}]}]}
{"op":"mcm","clk":"11854032894","pt":1723321227682,"mc":[{"id":"1.231581624","rc":[{"batb":[[0,2.34,4],[1,2.32,29.57],[2,1.3,1000]],"ltp":2.36,"tv":28.0,"id":31378}]}]}
{"op":"mcm","clk":"11854033262","pt":1723321230058,"mc":[{"id":"1.231581624","rc":[{"batb":[[0,2.36,10]],"ltp":2.36,"tv":28.0,"id":31378}]}]}
{"op":"mcm","clk":"11854033755","pt":1723321233372,"mc":[{"id":"1.231581624","rc":[{"batb":[[0,2.32,29.57],[1,1.3,1000],[2,1.08,7.85]],"ltp":2.36,"tv":28.0,"id":31378}]}]}
{"op":"mcm","clk":"11854033787","pt":1723321233574,"mc":[{"id":"1.231581624","rc":[{"batb":[[0,2.34,4],[1,2.32,29.57],[2,1.3,1000]],"ltp":2.36,"tv":28.0,"id":31378}]}]}
{"op":"mcm","clk":"11854034153","pt":1723321235994,"mc":[{"id":"1.231581624","rc":[{"batb":[[0,2.34,10]],"ltp":2.36,"tv":28.0,"id":31378}]}]}
{"op":"mcm","clk":"11854034523","pt":1723321238409,"mc":[{"id":"1.231581624","rc":[{"batb":[[0,2.36,4],[1,2.34,10],[2,2.32,29.57]],"ltp":2.36,"tv":28.0,"id":31378}]}]}
{"op":"mcm","clk":"11854034643","pt":1723321239203,"mc":[{"id":"1.231581624","rc":[{"batb":[[1,2.32,29.57],[2,1.3,1000]],"ltp":2.36,"tv":28.0,"id":31378}]}]}
{"op":"mcm","clk":"11854034900","pt":1723321240789,"mc":[{"id":"1.231581624","rc":[{"batb":[[0,2.32,29.57],[1,1.3,1000],[2,1.08,7.85]],"ltp":2.36,"tv":28.0,"id":31378}]}]}
{"op":"mcm","clk":"11854035076","pt":1723321241987,"mc":[{"id":"1.231581624","rc":[{"batb":[[0,2.34,10],[1,2.32,29.57],[2,1.3,1000]],"ltp":2.36,"tv":28.0,"id":31378}]}]}
{"op":"mcm","clk":"11854035255","pt":1723321243187,"mc":[{"id":"1.231581624","rc":[{"batb":[[0,2.36,4],[1,2.34,10],[2,2.32,29.57]],"ltp":2.36,"tv":28.0,"id":31378}]}]}
{"op":"mcm","clk":"11854035577","pt":1723321245395,"mc":[{"id":"1.231581624","rc":[{"batb":[[1,2.32,29.57],[2,1.3,1000]],"ltp":2.36,"tv":28.0,"id":31378}]}]}
{"op":"mcm","clk":"11854035608","pt":1723321245604,"mc":[{"id":"1.231581624","rc":[{"batb":[[0,2.32,29.57],[1,1.3,1000],[2,1.08,7.85]],"ltp":2.36,"tv":28.0,"id":31378}]}]}
{"op":"mcm","clk":"11854035952","pt":1723321247794,"mc":[{"id":"1.231581624","rc":[{"batb":[[0,2.34,14],[1,2.32,29.57],[2,1.3,1000]],"ltp":2.36,"tv":28.0,"id":31378}]}]}
{"op":"mcm","clk":"11854036335","pt":1723321250201,"mc":[{"id":"1.231581624","rc":[{"batb":[[0,2.34,10]],"ltp":2.36,"tv":28.0,"id":31378}]}]}
{"op":"mcm","clk":"11854036470","pt":1723321251095,"mc":[{"id":"1.231581624","rc":[{"batb":[[0,2.32,29.57],[1,1.3,1000],[2,1.08,7.85]],"ltp":2.36,"tv":28.0,"id":31378}]}]}
{"op":"mcm","clk":"11854036681","pt":1723321252712,"mc":[{"id":"1.231581624","rc":[{"batb":[[0,2.34,4],[1,2.32,29.57],[2,1.3,1000]],"ltp":2.36,"tv":28.0,"id":31378}]}]}
{"op":"mcm","clk":"11854037019","pt":1723321255016,"mc":[{"id":"1.231581624","rc":[{"batb":[[0,2.36,10]],"ltp":2.36,"tv":28.0,"id":31378}]}]}
{"op":"mcm","clk":"11854037478","pt":1723321258207,"mc":[{"id":"1.231581624","rc":[{"batb":[[0,2.34,4]],"ltp":2.36,"tv":28.0,"id":31378}]}]}
{"op":"mcm","clk":"11854037884","pt":1723321260699,"mc":[{"id":"1.231581624","rc":[{"batb":[[0,2.34,10]],"ltp":2.36,"tv":28.0,"id":31378}]}]}
{"op":"mcm","clk":"11854038423","pt":1723321264215,"mc":[{"id":"1.231581624","rc":[{"batb":[[0,2.36,4]],"ltp":2.36,"tv":28.0,"id":31378}]}]}
{"op":"mcm","clk":"11854038815","pt":1723321266698,"mc":[{"id":"1.231581624","rc":[{"batb":[[0,2.34,10]],"ltp":2.36,"tv":28.0,"id":31378}]}]}
{"op":"mcm","clk":"11854039367","pt":1723321270027,"mc":[{"id":"1.231581624","rc":[{"batb":[[0,2.36,4]],"ltp":2.36,"tv":28.0,"id":31378}]}]}
{"op":"mcm","clk":"11854039664","pt":1723321271974,"mc":[{"id":"1.231581624","rc":[{"batb":[[0,2.32,29.57],[1,1.3,1000],[2,1.08,7.85]],"ltp":2.36,"tv":28.0,"id":31378}]}]}
{"op":"mcm","clk":"11854040097","pt":1723321274646,"mc":[{"id":"1.231581624","rc":[{"batb":[[0,2.34,14],[1,2.32,29.57],[2,1.3,1000]],"ltp":2.36,"tv":28.0,"id":31378}]}]}
{"op":"mcm","clk":"11854040494","pt":1723321277113,"mc":[{"id":"1.231581624","rc":[{"batb":[[0,2.34,10]],"ltp":2.36,"tv":28.0,"id":31378}]}]}
{"op":"mcm","clk":"11854040645","pt":1723321278123,"mc":[{"id":"1.231581624","rc":[{"batb":[[0,2.32,29.57],[1,1.3,1000],[2,1.08,7.85]],"ltp":2.36,"tv":28.0,"id":31378}]}]}
{"op":"mcm","clk":"11854041034","pt":1723321280448,"mc":[{"id":"1.231581624","rc":[{"batb":[[0,2.34,10],[1,2.32,29.57],[2,1.3,1000]],"ltp":2.36,"tv":28.0,"id":31378}]}]}
{"op":"mcm","clk":"11854041054","pt":1723321280512,"mc":[{"id":"1.231581624","rc":[{"batb":[[0,2.34,14]],"ltp":2.36,"tv":28.0,"id":31378}]}]}
{"op":"mcm","clk":"11854041410","pt":1723321282932,"mc":[{"id":"1.231581624","rc":[{"batb":[[0,2.34,10]],"ltp":2.36,"tv":28.0,"id":31378}]}]}
{"op":"mcm","clk":"11854041569","pt":1723321283840,"mc":[{"id":"1.231581624","rc":[{"batb":[[0,2.32,29.57],[1,1.3,1000],[2,1.08,7.85]],"ltp":2.36,"tv":28.0,"id":31378}]}]}
{"op":"mcm","clk":"11854041930","pt":1723321286059,"mc":[{"id":"1.231581624","rc":[{"batb":[[0,2.34,14],[1,2.32,29.57],[2,1.3,1000]],"ltp":2.36,"tv":28.0,"id":31378}]}]}
{"op":"mcm","clk":"11854042265","pt":1723321288330,"mc":[{"id":"1.231581624","rc":[{"batb":[[0,2.34,10]],"ltp":2.36,"tv":28.0,"id":31378}]}]}
{"op":"mcm","clk":"11854042425","pt":1723321289438,"mc":[{"id":"1.231581624","rc":[{"batb":[[0,2.32,29.57],[1,1.3,1000],[2,1.08,7.85]],"ltp":2.36,"tv":28.0,"id":31378}]}]}
{"op":"mcm","clk":"11854042574","pt":1723321290545,"mc":[{"id":"1.231581624","rc":[{"batb":[[0,2.34,4],[1,2.32,29.57],[2,1.3,1000]],"ltp":2.36,"tv":28.0,"id":31378}]}]}
{"op":"mcm","clk":"11854042816","pt":1723321292262,"mc":[{"id":"1.231581624","rc":[{"batb":[[0,2.36,10],[1,2.34,4],[2,2.32,29.57]],"ltp":2.36,"tv":28.0,"id":31378}]}]}
{"op":"mcm","clk":"11854042923","pt":1723321292947,"mc":[{"id":"1.231581624","rc":[{"batb":[[1,2.32,29.57],[2,1.3,1000]],"ltp":2.36,"tv":28.0,"id":31378}]}]}
{"op":"mcm","clk":"11854043322","pt":1723321295846,"mc":[{"id":"1.231581624","rc":[{"batb":[[0,2.34,4]],"ltp":2.36,"tv":28.0,"id":31378}]}]}
{"op":"mcm","clk":"11854043683","pt":1723321298256,"mc":[{"id":"1.231581624","rc":[{"batb":[[0,2.34,10]],"ltp":2.36,"tv":28.0,"id":31378}]}]}
{"op":"mcm","clk":"11854044028","pt":1723321300567,"mc":[{"id":"1.231581624","rc":[{"batb":[[0,2.36,4],[1,2.34,10],[2,2.32,29.57]],"ltp":2.36,"tv":28.0,"id":31378}]}]}
{"op":"mcm","clk":"11854044188","pt":1723321301668,"mc":[{"id":"1.231581624","rc":[{"batb":[[1,2.32,29.57],[2,1.3,1000]],"ltp":2.36,"tv":28.0,"id":31378}]}]}
{"op":"mcm","clk":"11854044393","pt":1723321303049,"mc":[{"id":"1.231581624","rc":[{"batb":[[0,2.32,29.57],[1,1.3,1000],[2,1.08,7.85]],"ltp":2.36,"tv":28.0,"id":31378}]}]}
{"op":"mcm","clk":"11854045083","pt":1723321307768,"mc":[{"id":"1.231581624","rc":[{"batb":[[0,2.34,14],[1,2.32,29.57],[2,1.3,1000]],"ltp":2.36,"tv":28.0,"id":31378}]}]}
{"op":"mcm","clk":"11854045466","pt":1723321310263,"mc":[{"id":"1.231581624","rc":[{"batb":[[0,2.34,10]],"ltp":2.36,"tv":28.0,"id":31378}]}]}
{"op":"mcm","clk":"11854045605","pt":1723321311271,"mc":[{"id":"1.231581624","rc":[{"batb":[[0,2.32,29.57],[1,1.3,1000],[2,1.08,7.85]],"ltp":2.36,"tv":28.0,"id":31378}]}]}
{"op":"mcm","clk":"11854045770","pt":1723321312455,"mc":[{"id":"1.231581624","rc":[{"batb":[[0,2.34,4],[1,2.32,29.57],[2,1.3,1000]],"ltp":2.36,"tv":28.0,"id":31378}]}]}
{"op":"mcm","clk":"11854046026","pt":1723321314380,"mc":[{"id":"1.231581624","rc":[{"batb":[[0,2.36,10],[1,2.34,4],[2,2.32,29.57]],"ltp":2.36,"tv":28.0,"id":31378}]}]}
{"op":"mcm","clk":"11854046095","pt":1723321314862,"mc":[{"id":"1.231581624","rc":[{"batb":[[1,2.32,29.57],[2,1.3,1000]],"ltp":2.36,"tv":28.0,"id":31378}]}]}
{"op":"mcm","clk":"11854046390","pt":1723321317070,"mc":[{"id":"1.231581624","rc":[{"batb":[[0,2.38,4],[1,2.36,10],[2,2.32,29.57]],"ltp":2.36,"tv":28.0,"id":31378}]}]}
{"op":"mcm","clk":"11854046478","pt":1723321317742,"mc":[{"id":"1.231581624","rc":[{"batb":[[1,2.32,29.57],[2,1.3,1000]],"ltp":2.36,"tv":28.0,"id":31378}]}]}
{"op":"mcm","clk":"11854046729","pt":1723321319461,"mc":[{"id":"1.231581624","rc":[{"batb":[[0,2.32,29.57],[1,1.3,1000],[2,1.08,7.85]],"ltp":2.36,"tv":28.0,"id":31378}]}]}
{"op":"mcm","clk":"11854046923","pt":1723321320683,"mc":[{"id":"1.231581624","rc":[{"batb":[[0,2.34,10],[1,2.32,29.57],[2,1.3,1000]],"ltp":2.36,"tv":28.0,"id":31378}]}]}
{"op":"mcm","clk":"11854047449","pt":1723321324083,"mc":[{"id":"1.231581624","rc":[{"batb":[[0,2.36,4]],"ltp":2.36,"tv":28.0,"id":31378}]}]}
{"op":"mcm","clk":"11854047756","pt":1723321325980,"mc":[{"id":"1.231581624","rc":[{"batb":[[0,2.32,29.57],[1,1.3,1000],[2,1.08,7.85]],"ltp":2.36,"tv":28.0,"id":31378}]}]}
{"op":"mcm","clk":"11854048000","pt":1723321327675,"mc":[{"id":"1.231581624","rc":[{"batb":[[0,2.34,10],[1,2.32,29.57],[2,1.3,1000]],"ltp":2.36,"tv":28.0,"id":31378}]}]}
{"op":"mcm","clk":"11854048181","pt":1723321328886,"mc":[{"id":"1.231581624","rc":[{"batb":[[0,2.36,4],[1,2.34,10],[2,2.32,29.57]],"ltp":2.36,"tv":28.0,"id":31378}]}]}
{"op":"mcm","clk":"11854048570","pt":1723321331324,"mc":[{"id":"1.231581624","rc":[{"batb":[[0,2.32,29.57],[1,1.3,1000],[2,1.08,7.85]],"ltp":2.36,"tv":28.0,"id":31378}]}]}
{"op":"mcm","clk":"11854049179","pt":1723321335687,"mc":[{"id":"1.231581624","rc":[{"batb":[[0,2.34,14],[1,2.32,29.57],[2,1.3,1000]],"ltp":2.36,"tv":28.0,"id":31378}]}]}
{"op":"mcm","clk":"11854049522","pt":1723321338100,"mc":[{"id":"1.231581624","rc":[{"batb":[[0,2.34,10]],"ltp":2.36,"tv":28.0,"id":31378}]}]}
{"op":"mcm","clk":"11854049672","pt":1723321339099,"mc":[{"id":"1.231581624","rc":[{"batb":[[0,2.32,29.57],[1,1.3,1000],[2,1.08,7.85]],"ltp":2.36,"tv":28.0,"id":31378}]}]}
{"op":"mcm","clk":"11854050189","pt":1723321342201,"mc":[{"id":"1.231581624","rc":[{"batb":[[0,2.34,14],[1,2.32,29.57],[2,1.3,1000]],"ltp":2.36,"tv":28.0,"id":31378}]}]}
{"op":"mcm","clk":"11854050550","pt":1723321344678,"mc":[{"id":"1.231581624","rc":[{"batb":[[0,2.34,10]],"ltp":2.36,"tv":28.0,"id":31378}]}]}
{"op":"mcm","clk":"11854050707","pt":1723321345688,"mc":[{"id":"1.231581624","rc":[{"batb":[[0,2.32,29.57],[1,1.3,1000],[2,1.08,7.85]],"ltp":2.36,"tv":28.0,"id":31378}]}]}
{"op":"mcm","clk":"11854050923","pt":1723321347094,"mc":[{"id":"1.231581624","rc":[{"batb":[[0,2.34,4],[1,2.32,29.57],[2,1.3,1000]],"ltp":2.36,"tv":28.0,"id":31378}]}]}
{"op":"mcm","clk":"11854051264","pt":1723321349499,"mc":[{"id":"1.231581624","rc":[{"batb":[[0,2.34,10]],"ltp":2.36,"tv":28.0,"id":31378}]}]}
{"op":"mcm","clk":"11854051820","pt":1723321352987,"mc":[{"id":"1.231581624","rc":[{"batb":[[0,2.34,4]],"ltp":2.36,"tv":28.0,"id":31378}]}]}
{"op":"mcm","clk":"11854052170","pt":1723321355395,"mc":[{"id":"1.231581624","rc":[{"batb":[[0,2.34,10]],"ltp":2.36,"tv":28.0,"id":31378}]}]}
{"op":"mcm","clk":"11854052671","pt":1723321358911,"mc":[{"id":"1.231581624","rc":[{"batb":[[0,2.34,4]],"ltp":2.36,"tv":28.0,"id":31378}]}]}
{"op":"mcm","clk":"11854053056","pt":1723321361511,"mc":[{"id":"1.231581624","rc":[{"batb":[[0,2.34,10]],"ltp":2.36,"tv":28.0,"id":31378}]}]}
{"op":"mcm","clk":"11854053537","pt":1723321364818,"mc":[{"id":"1.231581624","rc":[{"batb":[[0,2.34,4]],"ltp":2.36,"tv":28.0,"id":31378}]}]}
{"op":"mcm","clk":"11854053941","pt":1723321367401,"mc":[{"id":"1.231581624","rc":[{"batb":[[0,2.34,10]],"ltp":2.36,"tv":28.0,"id":31378}]}]}
{"op":"mcm","clk":"11854054417","pt":1723321370498,"mc":[{"id":"1.231581624","rc":[{"batb":[[0,2.36,4],[1,2.34,10],[2,2.32,29.57]],"ltp":2.36,"tv":28.0,"id":31378}]}]}
{"op":"mcm","clk":"11854054445","pt":1723321370709,"mc":[{"id":"1.231581624","rc":[{"batb":[[1,2.32,29.57],[2,1.3,1000]],"ltp":2.36,"tv":28.0,"id":31378}]}]}
{"op":"mcm","clk":"11854054781","pt":1723321372927,"mc":[{"id":"1.231581624","rc":[{"batb":[[0,2.34,10]],"ltp":2.36,"tv":28.0,"id":31378}]}]}
{"op":"mcm","clk":"11854055086","pt":1723321374923,"mc":[{"id":"1.231581624","rc":[{"batb":[[0,2.36,4],[1,2.34,10],[2,2.32,29.57]],"ltp":2.36,"tv":28.0,"id":31378}]}]}
{"op":"mcm","clk":"11854055284","pt":1723321376136,"mc":[{"id":"1.231581624","rc":[{"batb":[[1,2.32,29.57],[2,1.3,1000]],"ltp":2.36,"tv":28.0,"id":31378}]}]}
{"op":"mcm","clk":"11854055463","pt":1723321377352,"mc":[{"id":"1.231581624","rc":[{"batb":[[0,2.32,29.57],[1,1.3,1000],[2,1.08,7.85]],"ltp":2.36,"tv":28.0,"id":31378}]}]}
{"op":"mcm","clk":"11854055890","pt":1723321380152,"mc":[{"id":"1.231581624","rc":[{"batb":[[0,2.34,14],[1,2.32,29.57],[2,1.3,1000]],"ltp":2.36,"tv":28.0,"id":31378}]}]}
{"op":"mcm","clk":"11854056272","pt":1723321382521,"mc":[{"id":"1.231581624","rc":[{"batb":[[0,2.34,10]],"ltp":2.36,"tv":28.0,"id":31378}]}]}
{"op":"mcm","clk":"11854056439","pt":1723321383532,"mc":[{"id":"1.231581624","rc":[{"batb":[[0,2.32,29.57],[1,1.3,1000],[2,1.08,7.85]],"ltp":2.36,"tv":28.0,"id":31378}]}]}
{"op":"mcm","clk":"11854056636","pt":1723321384725,"mc":[{"id":"1.231581624","rc":[{"batb":[[0,2.34,4],[1,2.32,29.57],[2,1.3,1000]],"ltp":2.36,"tv":28.0,"id":31378}]}]}
{"op":"mcm","clk":"11854056868","pt":1723321386144,"mc":[{"id":"1.231581624","rc":[{"batb":[[0,2.36,10],[1,2.34,4],[2,2.32,29.57]],"ltp":2.36,"tv":28.0,"id":31378}]}]}
{"op":"mcm","clk":"11854057028","pt":1723321387043,"mc":[{"id":"1.231581624","rc":[{"batb":[[1,2.32,29.57],[2,1.3,1000]],"ltp":2.36,"tv":28.0,"id":31378}]}]}
{"op":"mcm","clk":"11854057378","pt":1723321389446,"mc":[{"id":"1.231581624","rc":[{"batb":[[0,2.32,29.57],[1,1.3,1000],[2,1.08,7.85]],"ltp":2.36,"tv":28.0,"id":31378}]}]}
{"op":"mcm","clk":"11854057392","pt":1723321389535,"mc":[{"id":"1.231581624","rc":[{"batb":[[0,2.34,4],[1,2.32,29.57],[2,1.3,1000]],"ltp":2.36,"tv":28.0,"id":31378}]}]}
{"op":"mcm","clk":"11854057789","pt":1723321392135,"mc":[{"id":"1.231581624","rc":[{"batb":[[0,2.34,10]],"ltp":2.36,"tv":28.0,"id":31378}]}]}
{"op":"mcm","clk":"11854058327","pt":1723321395442,"mc":[{"id":"1.231581624","rc":[{"batb":[[0,2.32,29.57],[1,1.3,1000],[2,1.08,7.85]],"ltp":2.36,"tv":28.0,"id":31378}]}]}
{"op":"mcm","clk":"11854058358","pt":1723321395645,"mc":[{"id":"1.231581624","rc":[{"batb":[[0,2.34,4],[1,2.32,29.57],[2,1.3,1000]],"ltp":2.36,"tv":28.0,"id":31378}]}]}
{"op":"mcm","clk":"11854058773","pt":1723321398150,"mc":[{"id":"1.231581624","rc":[{"batb":[[0,2.34,10]],"ltp":2.36,"tv":28.0,"id":31378}]}]}
{"op":"mcm","clk":"11854059282","pt":1723321401457,"mc":[{"id":"1.231581624","rc":[{"batb":[[0,2.36,4]],"ltp":2.36,"tv":28.0,"id":31378}]}]}
{"op":"mcm","clk":"11854059520","pt":1723321402937,"mc":[{"id":"1.231581624","rc":[{"batb":[[0,2.32,29.57],[1,1.3,1000],[2,1.08,7.85]],"ltp":2.36,"tv":28.0,"id":31378}]}]}
{"op":"mcm","clk":"11854059780","pt":1723321404454,"mc":[{"id":"1.231581624","rc":[{"batb":[[0,2.34,10],[1,2.32,29.57],[2,1.3,1000]],"ltp":2.36,"tv":28.0,"id":31378}]}]}
{"op":"mcm","clk":"11854059982","pt":1723321405665,"mc":[{"id":"1.231581624","rc":[{"batb":[[0,2.36,4],[1,2.34,10],[2,2.32,29.57]],"ltp":2.36,"tv":28.0,"id":31378}]}]}
{"op":"mcm","clk":"11854060342","pt":1723321408096,"mc":[{"id":"1.231581624","rc":[{"batb":[[0,2.32,29.57],[1,1.3,1000],[2,1.08,7.85]],"ltp":2.36,"tv":28.0,"id":31378}]}]}
