{"op":"mcm","clk":"11846299711","pt":1723636787870,"mc":[{"id":"1.231804628","marketDefinition":{"bspMarket":false,"turnInPlayEnabled":true,"persistenceEnabled":true,"marketBaseRate":5.0,"eventId":"33494389","eventTypeId":"4","numberOfWinners":1,"bettingType":"ODDS","marketType":"MATCH_ODDS","marketTime":"2024-08-22T10:00:00.000Z","suspendTime":"2024-08-22T10:00:00.000Z","bspReconciled":false,"complete":true,"inPlay":false,"crossMatching":false,"runnersVoidable":false,"numberOfActiveRunners":3,"betDelay":0,"status":"OPEN","runners":[{"status":"ACTIVE","sortPriority":1,"id":2120,"name":"Warwickshire"},{"status":"ACTIVE","sortPriority":2,"id":5995,"name":"Somerset"},{"status":"ACTIVE","sortPriority":3,"id":60443,"name":"The Draw"}],"regulators":["MR_INT"],"countryCode":"GB","discountAllowed":false,"timezone":"GMT","openDate":"2024-08-22T10:00:00.000Z","version":6074268195,"name":"Match Odds","eventName":"Warwickshire v Somerset"},"rc":[{"batb":[[0,1.03,200],[1,1.02,200],[2,1.01,220]],"ltp":0.0,"tv":0.0,"id":5995},{"batb":[[0,1.03,200],[1,1.02,200],[2,1.01,220]],"ltp":0.0,"tv":0.0,"id":2120},{"batb":[[0,1.03,200],[1,1.02,200],[2,1.01,220]],"ltp":0.0,"tv":0.0,"id":60443}]}]}
{"op":"mcm","clk":"11846299839","pt":1723636789526,"mc":[{"id":"1.231804628","marketDefinition":{"bspMarket":false,"turnInPlayEnabled":true,"persistenceEnabled":true,"marketBaseRate":5.0,"eventId":"33494389","eventTypeId":"4","numberOfWinners":1,"bettingType":"ODDS","marketType":"MATCH_ODDS","marketTime":"2024-08-22T10:00:00.000Z","suspendTime":"2024-08-22T10:00:00.000Z","bspReconciled":false,"complete":true,"inPlay":false,"crossMatching":false,"runnersVoidable":false,"numberOfActiveRunners":3,"betDelay":0,"status":"OPEN","runners":[{"status":"ACTIVE","sortPriority":1,"id":2120,"name":"Warwickshire"},{"status":"ACTIVE","sortPriority":2,"id":5995,"name":"Somerset"},{"status":"ACTIVE","sortPriority":3,"id":60443,"name":"The Draw"}],"regulators":["MR_INT"],"countryCode":"GB","discountAllowed":true,"timezone":"GMT","openDate":"2024-08-22T10:00:00.000Z","version":6074268195,"name":"Match Odds","eventName":"Warwickshire v Somerset"}}]}
{"op":"mcm","clk":"11846505844","pt":1723639567497,"mc":[{"id":"1.231804628","rc":[{"batb":[[2,1.01,481.64]],"ltp":0.0,"tv":0.0,"id":5995},{"batb":[[2,1.01,481.64]],"ltp":0.0,"tv":0.0,"id":2120},{"batb":[[2,1.01,481.64]],"ltp":0.0,"tv":0.0,"id":60443}]}]}
{"op":"mcm","clk":"11846694804","pt":1723642974886,"mc":[{"id":"1.231804628","rc":[{"batb":[[2,1.01,482]],"ltp":0.0,"tv":0.0,"id":5995},{"batb":[[2,1.01,482]],"ltp":0.0,"tv":0.0,"id":2120},{"batb":[[2,1.01,482]],"ltp":0.0,"tv":0.0,"id":60443}]}]}
{"op":"mcm","clk":"11847172445","pt":1723648374901,"mc":[{"id":"1.231804628","rc":[{"batb":[[2,1.01,481.27]],"ltp":0.0,"tv":0.0,"id":5995},{"batb":[[2,1.01,481.27]],"ltp":0.0,"tv":0.0,"id":2120},{"batb":[[2,1.01,481.27]],"ltp":0.0,"tv":0.0,"id":60443}]}]}
{"op":"mcm","clk":"11847706787","pt":1723652694165,"mc":[{"id":"1.231804628","rc":[{"batb":[[2,1.01,480.83]],"ltp":0.0,"tv":0.0,"id":5995},{"trd":[[1.03,2]],"batb":[[0,1.03,199],[2,1.01,480.83]],"ltp":1.03,"tv":2.0,"id":2120},{"batb":[[2,1.01,480.83]],"ltp":0.0,"tv":0.0,"id":60443}],"tv":2.0}]}
{"op":"mcm","clk":"11848293153","pt":1723657008197,"mc":[{"id":"1.231804628","rc":[{"batb":[[2,1.01,480.82]],"batl":[[0,990,5]],"ltp":0.0,"tv":0.0,"id":5995},{"batb":[[2,1.01,480.82]],"batl":[[0,990,5]],"ltp":1.03,"tv":2.0,"id":2120},{"batb":[[2,1.01,480.82]],"batl":[[0,990,5]],"ltp":0.0,"tv":0.0,"id":60443}]}]}
{"op":"mcm","clk":"11848296083","pt":1723657027196,"mc":[{"id":"1.231804628","marketDefinition":{"bspMarket":false,"turnInPlayEnabled":true,"persistenceEnabled":true,"marketBaseRate":5.0,"eventId":"33494389","eventTypeId":"4","numberOfWinners":1,"bettingType":"ODDS","marketType":"MATCH_ODDS","marketTime":"2024-08-22T10:00:00.000Z","suspendTime":"2024-08-22T10:00:00.000Z","bspReconciled":false,"complete":true,"inPlay":false,"crossMatching":true,"runnersVoidable":false,"numberOfActiveRunners":3,"betDelay":0,"status":"OPEN","runners":[{"status":"ACTIVE","sortPriority":1,"id":2120,"name":"Warwickshire"},{"status":"ACTIVE","sortPriority":2,"id":5995,"name":"Somerset"},{"status":"ACTIVE","sortPriority":3,"id":60443,"name":"The Draw"}],"regulators":["MR_INT"],"countryCode":"GB","discountAllowed":true,"timezone":"GMT","openDate":"2024-08-22T10:00:00.000Z","version":6074268195,"name":"Match Odds","eventName":"Warwickshire v Somerset"}}]}
{"op":"mcm","clk":"11848306154","pt":1723657094500,"mc":[{"id":"1.231804628","rc":[{"batl":[[0,95,5],[1,990,5]],"ltp":0.0,"tv":0.0,"id":5995}]}]}
{"op":"mcm","clk":"11848306242","pt":1723657095006,"mc":[{"id":"1.231804628","rc":[{"batb":[[0,1.04,250],[1,1.03,200],[2,1.02,200]],"ltp":0.0,"tv":0.0,"id":5995},{"batb":[[0,1.04,250],[1,1.03,199],[2,1.02,200]],"batl":[[0,95,5],[1,990,5]],"ltp":1.03,"tv":2.0,"id":2120},{"batb":[[0,1.04,250],[1,1.03,200],[2,1.02,200]],"batl":[[0,95,5],[1,990,5]],"ltp":0.0,"tv":0.0,"id":60443}]}]}
{"op":"mcm","clk":"11852112869","pt":1723729142265,"mc":[{"id":"1.231804628","rc":[{"batl":[[0,95,5.18]],"ltp":1.03,"tv":2.0,"id":2120}]}]}
{"op":"mcm","clk":"11852116316","pt":1723729192062,"mc":[{"id":"1.231804628","rc":[{"batl":[[0,95,5]],"ltp":1.03,"tv":2.0,"id":2120}]}]}
{"op":"mcm","clk":"11852121347","pt":1723729256146,"mc":[{"id":"1.231804628","rc":[{"batl":[[0,95,5.18]],"ltp":1.03,"tv":2.0,"id":2120}]}]}
{"op":"mcm","clk":"11852123045","pt":1723729281005,"mc":[{"id":"1.231804628","rc":[{"batl":[[0,95,5]],"ltp":1.03,"tv":2.0,"id":2120}]}]}
{"op":"mcm","clk":"11852178518","pt":1723729954431,"mc":[{"id":"1.231804628","rc":[{"trd":[[1.04,0.95]],"batb":[[0,1.04,249.52]],"ltp":1.04,"tv":2.95,"id":2120}],"tv":2.95}]}
{"op":"mcm","clk":"11852179756","pt":1723729974168,"mc":[{"id":"1.231804628","rc":[{"trd":[[1.04,1.43]],"batb":[[0,1.04,249.28]],"ltp":1.04,"tv":3.42,"id":2120}],"tv":3.42}]}
{"op":"mcm","clk":"11852180008","pt":1723729978756,"mc":[{"id":"1.231804628","rc":[{"trd":[[1.04,1.91]],"batb":[[0,1.04,249.04]],"ltp":1.04,"tv":3.9,"id":2120}],"tv":3.9}]}
{"op":"mcm","clk":"11852180690","pt":1723729989880,"mc":[{"id":"1.231804628","rc":[{"trd":[[1.04,2.38]],"batb":[[0,1.04,248.8]],"ltp":1.04,"tv":4.38,"id":2120}],"tv":4.38}]}
{"op":"mcm","clk":"11852181683","pt":1723730006217,"mc":[{"id":"1.231804628","rc":[{"trd":[[1.04,0.48]],"batb":[[0,1.04,249.76]],"ltp":1.04,"tv":0.47,"id":5995}],"tv":4.85}]}
{"op":"mcm","clk":"11852291623","pt":1723731523826,"mc":[{"id":"1.231804628","rc":[{"trd":[[1.04,0.92]],"batb":[[0,1.04,249.54]],"ltp":1.04,"tv":0.91,"id":5995},{"trd":[[1.04,2.38]],"ltp":1.04,"tv":4.37,"id":2120}],"tv":5.29}]}
{"op":"mcm","clk":"11852540562","pt":1723734774945,"mc":[{"id":"1.231804628","rc":[{"trd":[[1.04,2.38]],"ltp":1.04,"tv":4.37,"id":2120}],"tv":5.29}]}
{"op":"mcm","clk":"11852578119","pt":1723735093131,"mc":[{"id":"1.231804628","rc":[{"batl":[[0,95,5.95]],"ltp":0.0,"tv":0.0,"id":60443}]}]}
{"op":"mcm","clk":"11852579194","pt":1723735104162,"mc":[{"id":"1.231804628","rc":[{"batl":[[0,95,5.95]],"ltp":1.04,"tv":0.91,"id":5995}]}]}
{"op":"mcm","clk":"11852580268","pt":1723735115182,"mc":[{"id":"1.231804628","rc":[{"batl":[[0,95,5.95]],"ltp":1.04,"tv":4.37,"id":2120}]}]}
{"op":"mcm","clk":"11852671110","pt":1723736130315,"mc":[{"id":"1.231804628","rc":[{"batb":[[0,1.03,199],[1,1.02,200],[2,1.01,480.13]],"ltp":1.04,"tv":4.37,"id":2120}]}]}
{"op":"mcm","clk":"11852671308","pt":1723736131994,"mc":[{"id":"1.231804628","rc":[{"batb":[[0,1.03,200],[1,1.02,200],[2,1.01,480.13]],"ltp":1.04,"tv":0.91,"id":5995}]}]}
{"op":"mcm","clk":"11852671617","pt":1723736134973,"mc":[{"id":"1.231804628","rc":[{"batb":[[0,1.03,200],[1,1.02,200],[2,1.01,480.13]],"ltp":0.0,"tv":0.0,"id":60443}]}]}
{"op":"mcm","clk":"11852682461","pt":1723736244149,"mc":[{"id":"1.231804628","rc":[{"batb":[[0,1.13,138.46],[1,1.03,200],[2,1.02,200]],"ltp":1.04,"tv":0.91,"id":5995},{"batb":[[0,1.13,138.46],[1,1.03,199],[2,1.02,200]],"ltp":1.04,"tv":4.37,"id":2120},{"batb":[[0,1.13,138.46],[1,1.03,200],[2,1.02,200]],"ltp":0.0,"tv":0.0,"id":60443}]}]}
{"op":"mcm","clk":"11853127134","pt":1723740174944,"mc":[{"id":"1.231804628","rc":[{"batl":[[0,95,5.95]],"ltp":1.04,"tv":0.91,"id":5995},{"trd":[[1.04,2.38]],"batl":[[0,95,5.95]],"ltp":1.04,"tv":4.37,"id":2120},{"batl":[[0,95,5.95]],"ltp":0.0,"tv":0.0,"id":60443}],"tv":5.29}]}
{"op":"mcm","clk":"11853776738","pt":1723745574948,"mc":[{"id":"1.231804628","tv":5.29}]}
{"op":"mcm","clk":"11854018480","pt":1723747459027,"mc":[{"id":"1.231804628","rc":[{"trd":[[1.13,2.56]],"batb":[[0,1.13,137.18]],"ltp":1.13,"tv":6.93,"id":2120}],"tv":7.85}]}
{"op":"mcm","clk":"11854240767","pt":1723749233134,"mc":[{"id":"1.231804628","rc":[{"batb":[[0,1.14,3.61],[1,1.13,137.18],[2,1.03,199]],"ltp":1.13,"tv":6.93,"id":2120}],"tv":7.85}]}
{"op":"mcm","clk":"11854242884","pt":1723749251188,"mc":[{"id":"1.231804628","rc":[{"batb":[[0,1.14,3.61],[1,1.13,138.46],[2,1.03,200]],"ltp":1.04,"tv":0.91,"id":5995}]}]}
{"op":"mcm","clk":"11854501475","pt":1723751108261,"mc":[{"id":"1.231804628","rc":[{"batb":[[0,1.13,138.46],[1,1.03,200],[2,1.02,200]],"ltp":1.04,"tv":0.91,"id":5995},{"batb":[[0,1.13,137.18],[1,1.03,199],[2,1.02,200]],"ltp":1.13,"tv":6.93,"id":2120}]}]}
{"op":"mcm","clk":"11854980437","pt":1723756374932,"mc":[{"id":"1.231804628","tv":7.85}]}
{"op":"mcm","clk":"11855560766","pt":1723767174898,"mc":[{"id":"1.231804628","tv":7.85}]}
{"op":"mcm","clk":"11855729940","pt":1723772574935,"mc":[{"id":"1.231804628","tv":7.84}]}
{"op":"mcm","clk":"11855970067","pt":1723777974909,"mc":[{"id":"1.231804628","tv":7.84}]}
{"op":"mcm","clk":"11856190797","pt":1723783374955,"mc":[{"id":"1.231804628","tv":7.84}]}
{"op":"mcm","clk":"11856290394","pt":1723785685194,"mc":[{"id":"1.231804628","rc":[{"batb":[[0,1.14,61.26],[1,1.13,138.46],[2,1.03,200]],"ltp":1.04,"tv":0.91,"id":5995},{"batb":[[0,1.14,61.26],[1,1.13,137.18],[2,1.03,199]],"ltp":1.13,"tv":6.93,"id":2120},{"batb":[[0,1.14,61.26],[1,1.13,138.46],[2,1.03,200]],"ltp":0.0,"tv":0.0,"id":60443}]}]}
{"op":"mcm","clk":"11856366910","pt":1723787486394,"mc":[{"id":"1.231804628","rc":[{"batb":[[0,1.13,138.46],[1,1.03,200],[2,1.02,200]],"ltp":1.04,"tv":0.91,"id":5995},{"batb":[[0,1.13,138.46],[1,1.03,200],[2,1.02,200]],"ltp":0.0,"tv":0.0,"id":60443}]}]}
{"op":"mcm","clk":"11856366918","pt":1723787486603,"mc":[{"id":"1.231804628","rc":[{"batb":[[0,1.13,137.18],[1,1.03,199],[2,1.02,200]],"ltp":1.13,"tv":6.93,"id":2120}]}]}
{"op":"mcm","clk":"11856370450","pt":1723787576322,"mc":[{"id":"1.231804628","rc":[{"batb":[[0,1.14,61.26],[1,1.13,138.46],[2,1.03,200]],"ltp":1.04,"tv":0.91,"id":5995},{"batb":[[0,1.14,61.26],[1,1.13,137.18],[2,1.03,199]],"ltp":1.13,"tv":6.93,"id":2120},{"batb":[[0,1.14,61.26],[1,1.13,138.46],[2,1.03,200]],"ltp":0.0,"tv":0.0,"id":60443}]}]}
{"op":"mcm","clk":"11856425744","pt":1723788774929,"mc":[{"id":"1.231804628","rc":[{"batb":[[0,1.14,61.25]],"ltp":1.04,"tv":0.91,"id":5995},{"batb":[[0,1.14,61.25]],"ltp":1.13,"tv":6.93,"id":2120},{"batb":[[0,1.14,61.25]],"ltp":0.0,"tv":0.0,"id":60443}],"tv":7.84}]}
{"op":"mcm","clk":"11856461872","pt":1723789377128,"mc":[{"id":"1.231804628","rc":[{"batb":[[0,1.13,138.46],[1,1.03,200],[2,1.02,200]],"ltp":1.04,"tv":0.91,"id":5995},{"batb":[[0,1.13,137.18],[1,1.03,199],[2,1.02,200]],"ltp":1.13,"tv":6.93,"id":2120},{"batb":[[0,1.13,138.46],[1,1.03,200],[2,1.02,200]],"ltp":0.0,"tv":0.0,"id":60443}]}]}
{"op":"mcm","clk":"11856465982","pt":1723789467971,"mc":[{"id":"1.231804628","rc":[{"batb":[[0,1.14,61.25],[1,1.13,138.46],[2,1.03,200]],"ltp":1.04,"tv":0.91,"id":5995},{"batb":[[0,1.14,61.25],[1,1.13,137.18],[2,1.03,199]],"ltp":1.13,"tv":6.93,"id":2120},{"batb":[[0,1.14,61.25],[1,1.13,138.46],[2,1.03,200]],"ltp":0.0,"tv":0.0,"id":60443}]}]}
{"op":"mcm","clk":"11856551107","pt":1723791268448,"mc":[{"id":"1.231804628","rc":[{"batb":[[0,1.13,138.46],[1,1.03,200],[2,1.02,200]],"ltp":1.04,"tv":0.91,"id":5995},{"batb":[[0,1.13,138.46],[1,1.03,200],[2,1.02,200]],"ltp":0.0,"tv":0.0,"id":60443}]}]}
{"op":"mcm","clk":"11856551118","pt":1723791268654,"mc":[{"id":"1.231804628","rc":[{"batb":[[0,1.13,137.18],[1,1.03,199],[2,1.02,200]],"ltp":1.13,"tv":6.93,"id":2120}]}]}
{"op":"mcm","clk":"11856555315","pt":1723791364295,"mc":[{"id":"1.231804628","rc":[{"batb":[[0,1.14,61.25],[1,1.13,138.46],[2,1.03,200]],"ltp":1.04,"tv":0.91,"id":5995},{"batb":[[0,1.14,61.25],[1,1.13,137.18],[2,1.03,199]],"ltp":1.13,"tv":6.93,"id":2120},{"batb":[[0,1.14,61.25],[1,1.13,138.46],[2,1.03,200]],"ltp":0.0,"tv":0.0,"id":60443}]}]}
{"op":"mcm","clk":"11856621863","pt":1723793166217,"mc":[{"id":"1.231804628","rc":[{"batb":[[0,1.13,138.46],[1,1.03,200],[2,1.02,200]],"ltp":1.04,"tv":0.91,"id":5995},{"batb":[[0,1.13,137.18],[1,1.03,199],[2,1.02,200]],"ltp":1.13,"tv":6.93,"id":2120},{"batb":[[0,1.13,138.46],[1,1.03,200],[2,1.02,200]],"ltp":0.0,"tv":0.0,"id":60443}]}]}
{"op":"mcm","clk":"11856625591","pt":1723793257424,"mc":[{"id":"1.231804628","rc":[{"batb":[[0,1.14,61.24],[1,1.13,138.46],[2,1.03,200]],"ltp":1.04,"tv":0.91,"id":5995},{"batb":[[0,1.14,61.24],[1,1.13,137.18],[2,1.03,199]],"ltp":1.13,"tv":6.93,"id":2120},{"batb":[[0,1.14,61.24],[1,1.13,138.46],[2,1.03,200]],"ltp":0.0,"tv":0.0,"id":60443}]}]}
{"op":"mcm","clk":"11856701659","pt":1723795058113,"mc":[{"id":"1.231804628","rc":[{"batb":[[0,1.13,138.46],[1,1.03,200],[2,1.02,200]],"ltp":1.04,"tv":0.91,"id":5995},{"batb":[[0,1.13,137.18],[1,1.03,199],[2,1.02,200]],"ltp":1.13,"tv":6.93,"id":2120},{"batb":[[0,1.13,138.46],[1,1.03,200],[2,1.02,200]],"ltp":0.0,"tv":0.0,"id":60443}]}]}
{"op":"mcm","clk":"11856704829","pt":1723795147750,"mc":[{"id":"1.231804628","rc":[{"batb":[[0,1.14,61.24],[1,1.13,138.46],[2,1.03,200]],"ltp":1.04,"tv":0.91,"id":5995},{"batb":[[0,1.14,61.24],[1,1.13,137.18],[2,1.03,199]],"ltp":1.13,"tv":6.93,"id":2120},{"batb":[[0,1.14,61.24],[1,1.13,138.46],[2,1.03,200]],"ltp":0.0,"tv":0.0,"id":60443}]}]}
{"op":"mcm","clk":"11856771529","pt":1723796948243,"mc":[{"id":"1.231804628","rc":[{"batb":[[0,1.13,138.46],[1,1.03,200],[2,1.02,200]],"ltp":1.04,"tv":0.91,"id":5995},{"batb":[[0,1.13,137.18],[1,1.03,199],[2,1.02,200]],"ltp":1.13,"tv":6.93,"id":2120},{"batb":[[0,1.14,61.23]],"ltp":0.0,"tv":0.0,"id":60443}]}]}
{"op":"mcm","clk":"11856771545","pt":1723796948555,"mc":[{"id":"1.231804628","rc":[{"batb":[[0,1.13,138.46],[1,1.03,200],[2,1.02,200]],"ltp":0.0,"tv":0.0,"id":60443}]}]}
{"op":"mcm","clk":"11856775824","pt":1723797037154,"mc":[{"id":"1.231804628","rc":[{"batb":[[0,1.14,61.23],[1,1.13,138.46],[2,1.03,200]],"ltp":1.04,"tv":0.91,"id":5995},{"batb":[[0,1.14,61.23],[1,1.13,137.18],[2,1.03,199]],"ltp":1.13,"tv":6.93,"id":2120},{"batb":[[0,1.14,61.23],[1,1.13,138.46],[2,1.03,200]],"ltp":0.0,"tv":0.0,"id":60443}]}]}
{"op":"mcm","clk":"11856853172","pt":1723798837447,"mc":[{"id":"1.231804628","rc":[{"batb":[[0,1.14,61.19]],"ltp":1.04,"tv":0.91,"id":5995},{"batb":[[0,1.13,137.18],[1,1.03,199],[2,1.02,200]],"ltp":1.13,"tv":6.92,"id":2120},{"batb":[[0,1.14,61.19]],"ltp":0.0,"tv":0.0,"id":60443}],"tv":7.84}]}
{"op":"mcm","clk":"11856853185","pt":1723798837857,"mc":[{"id":"1.231804628","rc":[{"batb":[[0,1.13,138.46],[1,1.03,200],[2,1.02,200]],"ltp":1.04,"tv":0.91,"id":5995},{"batb":[[0,1.13,138.46],[1,1.03,200],[2,1.02,200]],"ltp":0.0,"tv":0.0,"id":60443}]}]}
{"op":"mcm","clk":"11856856510","pt":1723798924787,"mc":[{"id":"1.231804628","rc":[{"batb":[[0,1.14,61.19],[1,1.13,138.46],[2,1.03,200]],"ltp":1.04,"tv":0.91,"id":5995},{"batb":[[0,1.14,61.19],[1,1.13,137.18],[2,1.03,199]],"ltp":1.13,"tv":6.92,"id":2120},{"batb":[[0,1.14,61.19],[1,1.13,138.46],[2,1.03,200]],"ltp":0.0,"tv":0.0,"id":60443}]}]}
{"op":"mcm","clk":"11856928670","pt":1723800423760,"mc":[{"id":"1.231804628","rc":[{"batb":[[1,1.03,200],[2,1.02,200]],"ltp":1.04,"tv":0.91,"id":5995},{"batb":[[1,1.03,199],[2,1.02,200]],"ltp":1.13,"tv":6.92,"id":2120},{"batb":[[1,1.03,200],[2,1.02,200]],"ltp":0.0,"tv":0.0,"id":60443}]}]}
{"op":"mcm","clk":"11856932690","pt":1723800511353,"mc":[{"id":"1.231804628","rc":[{"batb":[[0,1.15,133.33],[1,1.14,61.19],[2,1.03,199]],"ltp":1.13,"tv":6.92,"id":2120}]}]}
{"op":"mcm","clk":"11856932791","pt":1723800513252,"mc":[{"id":"1.231804628","rc":[{"batb":[[0,1.15,133.33],[1,1.14,61.19],[2,1.03,200]],"ltp":1.04,"tv":0.91,"id":5995}]}]}
{"op":"mcm","clk":"11856932921","pt":1723800516072,"mc":[{"id":"1.231804628","rc":[{"batb":[[0,1.15,133.33],[1,1.14,61.19],[2,1.03,200]],"ltp":0.0,"tv":0.0,"id":60443}]}]}
{"op":"mcm","clk":"11856944701","pt":1723800726407,"mc":[{"id":"1.231804628","rc":[{"batb":[[1,1.03,200],[2,1.02,200]],"ltp":1.04,"tv":0.91,"id":5995},{"batb":[[1,1.03,199],[2,1.02,200]],"ltp":1.13,"tv":6.92,"id":2120},{"batb":[[1,1.03,200],[2,1.02,200]],"ltp":0.0,"tv":0.0,"id":60443}]}]}
{"op":"mcm","clk":"11856949330","pt":1723800812054,"mc":[{"id":"1.231804628","rc":[{"batb":[[0,1.16,53.54],[1,1.15,133.33],[2,1.03,200]],"ltp":1.04,"tv":0.91,"id":5995},{"batb":[[0,1.16,53.54],[1,1.15,133.33],[2,1.03,199]],"ltp":1.13,"tv":6.92,"id":2120},{"batb":[[0,1.16,53.54],[1,1.15,133.33],[2,1.03,200]],"ltp":0.0,"tv":0.0,"id":60443}]}]}
{"op":"mcm","clk":"11857038274","pt":1723802612456,"mc":[{"id":"1.231804628","rc":[{"batb":[[0,1.15,133.33],[1,1.03,200],[2,1.02,200]],"batl":[[0,95,5.95]],"ltp":1.04,"tv":0.91,"id":5995},{"trd":[[1.04,2.37],[1.13,2.55]],"batb":[[0,1.15,133.33],[1,1.03,199],[2,1.02,200]],"batl":[[0,95,5.95]],"ltp":1.13,"tv":6.92,"id":2120},{"batb":[[0,1.15,133.33],[1,1.03,200],[2,1.02,200]],"batl":[[0,95,5.95]],"ltp":0.0,"tv":0.0,"id":60443}],"tv":7.84}]}
{"op":"mcm","clk":"11857043074","pt":1723802696266,"mc":[{"id":"1.231804628","rc":[{"batb":[[0,1.16,53.5],[1,1.15,133.33],[2,1.03,200]],"ltp":1.04,"tv":0.91,"id":5995},{"batb":[[0,1.16,53.5],[1,1.15,133.33],[2,1.03,199]],"ltp":1.13,"tv":6.92,"id":2120},{"batb":[[0,1.16,53.5],[1,1.15,133.33],[2,1.03,200]],"ltp":0.0,"tv":0.0,"id":60443}]}]}
{"op":"mcm","clk":"11857137354","pt":1723804497167,"mc":[{"id":"1.231804628","rc":[{"batb":[[0,1.15,133.33],[1,1.03,200],[2,1.02,200]],"ltp":1.04,"tv":0.91,"id":5995},{"batb":[[0,1.15,133.33],[1,1.03,199],[2,1.02,200]],"ltp":1.13,"tv":6.92,"id":2120},{"batb":[[0,1.15,133.33],[1,1.03,200],[2,1.02,200]],"ltp":0.0,"tv":0.0,"id":60443}]}]}
{"op":"mcm","clk":"11857142725","pt":1723804573041,"mc":[{"id":"1.231804628","rc":[{"batb":[[0,1.16,53.5],[1,1.15,133.33],[2,1.03,200]],"ltp":1.04,"tv":0.91,"id":5995},{"batb":[[0,1.16,53.5],[1,1.15,133.33],[2,1.03,199]],"ltp":1.13,"tv":6.92,"id":2120},{"batb":[[0,1.16,53.5],[1,1.15,133.33],[2,1.03,200]],"ltp":0.0,"tv":0.0,"id":60443}]}]}
{"op":"mcm","clk":"11857274991","pt":1723806374246,"mc":[{"id":"1.231804628","rc":[{"batb":[[0,1.15,133.33],[1,1.03,200],[2,1.02,200]],"ltp":1.04,"tv":0.91,"id":5995},{"batb":[[0,1.15,133.33],[1,1.03,199],[2,1.02,200]],"ltp":1.13,"tv":6.92,"id":2120},{"batb":[[0,1.15,133.33],[1,1.03,200],[2,1.02,200]],"ltp":0.0,"tv":0.0,"id":60443}],"tv":7.83}]}
{"op":"mcm","clk":"11857286589","pt":1723806540211,"mc":[{"id":"1.231804628","rc":[{"batb":[[0,1.16,53.5],[1,1.15,133.33],[2,1.03,200]],"ltp":1.04,"tv":0.91,"id":5995},{"batb":[[0,1.16,53.5],[1,1.15,133.33],[2,1.03,199]],"ltp":1.13,"tv":6.92,"id":2120},{"batb":[[0,1.16,53.5],[1,1.15,133.33],[2,1.03,200]],"ltp":0.0,"tv":0.0,"id":60443}]}]}
{"op":"mcm","clk":"11857414542","pt":1723808340889,"mc":[{"id":"1.231804628","rc":[{"batb":[[0,1.15,133.33],[1,1.03,200],[2,1.02,200]],"ltp":1.04,"tv":0.91,"id":5995},{"batb":[[0,1.15,133.33],[1,1.03,199],[2,1.02,200]],"ltp":1.13,"tv":6.92,"id":2120},{"batb":[[0,1.15,133.33],[1,1.03,200],[2,1.02,200]],"ltp":0.0,"tv":0.0,"id":60443}]}]}
{"op":"mcm","clk":"11857425442","pt":1723808502480,"mc":[{"id":"1.231804628","rc":[{"batb":[[0,1.16,53.5],[1,1.15,133.33],[2,1.03,200]],"ltp":1.04,"tv":0.91,"id":5995},{"batb":[[0,1.16,53.5],[1,1.15,133.33],[2,1.03,199]],"ltp":1.13,"tv":6.92,"id":2120},{"batb":[[0,1.16,53.5],[1,1.15,133.33],[2,1.03,200]],"ltp":0.0,"tv":0.0,"id":60443}]}]}
{"op":"mcm","clk":"11857564891","pt":1723810303086,"mc":[{"id":"1.231804628","rc":[{"batb":[[0,1.15,133.33],[1,1.03,200],[2,1.02,200]],"ltp":1.04,"tv":0.91,"id":5995},{"batb":[[0,1.15,133.33],[1,1.03,199],[2,1.02,200]],"ltp":1.13,"tv":6.92,"id":2120},{"batb":[[0,1.15,133.33],[1,1.03,200],[2,1.02,200]],"ltp":0.0,"tv":0.0,"id":60443}]}]}
{"op":"mcm","clk":"11857594576","pt":1723810517654,"mc":[{"id":"1.231804628","rc":[{"batb":[[0,1.16,53.49],[1,1.15,133.33],[2,1.03,200]],"ltp":1.04,"tv":0.91,"id":5995},{"batb":[[0,1.16,53.49],[1,1.15,133.33],[2,1.03,199]],"ltp":1.13,"tv":6.92,"id":2120},{"batb":[[0,1.16,53.49],[1,1.15,133.33],[2,1.03,200]],"ltp":0.0,"tv":0.0,"id":60443}]}]}
{"op":"mcm","clk":"11857677116","pt":1723811526904,"mc":[{"id":"1.231804628","rc":[{"batb":[[1,1.03,199],[2,1.02,200]],"ltp":1.13,"tv":6.92,"id":2120}]}]}
{"op":"mcm","clk":"11857677179","pt":1723811527692,"mc":[{"id":"1.231804628","rc":[{"batb":[[0,1.17,117.65],[1,1.16,53.49],[2,1.03,199]],"ltp":1.13,"tv":6.92,"id":2120}]}]}
{"op":"mcm","clk":"11857677571","pt":1723811533272,"mc":[{"id":"1.231804628","rc":[{"batb":[[1,1.03,200],[2,1.02,200]],"ltp":1.04,"tv":0.91,"id":5995}]}]}
{"op":"mcm","clk":"11857677636","pt":1723811534105,"mc":[{"id":"1.231804628","rc":[{"batb":[[0,1.17,117.65],[1,1.16,53.49],[2,1.03,200]],"ltp":1.04,"tv":0.91,"id":5995}]}]}
{"op":"mcm","clk":"11857678106","pt":1723811541712,"mc":[{"id":"1.231804628","rc":[{"batb":[[1,1.03,200],[2,1.02,200]],"ltp":0.0,"tv":0.0,"id":60443}]}]}
{"op":"mcm","clk":"11857678159","pt":1723811542603,"mc":[{"id":"1.231804628","rc":[{"batb":[[0,1.17,117.65],[1,1.16,53.49],[2,1.03,200]],"ltp":0.0,"tv":0.0,"id":60443}]}]}
{"op":"mcm","clk":"11857740141","pt":1723812318314,"mc":[{"id":"1.231804628","rc":[{"batb":[[1,1.03,200],[2,1.02,200]],"ltp":1.04,"tv":0.91,"id":5995},{"batb":[[1,1.03,199],[2,1.02,200]],"ltp":1.13,"tv":6.92,"id":2120},{"batb":[[1,1.03,200],[2,1.02,200]],"ltp":0.0,"tv":0.0,"id":60443}]}]}
{"op":"mcm","clk":"11857756618","pt":1723812522959,"mc":[{"id":"1.231804628","rc":[{"batb":[[0,1.18,47.55],[1,1.17,117.65],[2,1.03,200]],"ltp":1.04,"tv":0.91,"id":5995},{"batb":[[0,1.18,47.55],[1,1.17,117.65],[2,1.03,199]],"ltp":1.13,"tv":6.92,"id":2120},{"batb":[[0,1.18,47.55],[1,1.17,117.65],[2,1.03,200]],"ltp":0.0,"tv":0.0,"id":60443}]}]}
{"op":"mcm","clk":"11857889098","pt":1723814323460,"mc":[{"id":"1.231804628","rc":[{"batb":[[0,1.17,117.65],[1,1.03,200],[2,1.02,200]],"ltp":1.04,"tv":0.91,"id":5995},{"trd":[[1.04,2.37],[1.13,2.55]],"batb":[[0,1.17,117.65],[1,1.03,199],[2,1.02,200]],"ltp":1.13,"tv":6.92,"id":2120},{"batb":[[0,1.17,117.65],[1,1.03,200],[2,1.02,200]],"ltp":0.0,"tv":0.0,"id":60443}],"tv":7.84}]}
{"op":"mcm","clk":"11857903228","pt":1723814515354,"mc":[{"id":"1.231804628","rc":[{"batb":[[0,1.18,47.6],[1,1.17,117.65],[2,1.03,200]],"ltp":1.04,"tv":0.91,"id":5995},{"batb":[[0,1.18,47.6],[1,1.17,117.65],[2,1.03,199]],"ltp":1.13,"tv":6.92,"id":2120},{"batb":[[0,1.18,47.6],[1,1.17,117.65],[2,1.03,200]],"ltp":0.0,"tv":0.0,"id":60443}]}]}
{"op":"mcm","clk":"11858051316","pt":1723816315967,"mc":[{"id":"1.231804628","rc":[{"batb":[[0,1.17,117.65],[1,1.03,200],[2,1.02,200]],"ltp":1.04,"tv":0.91,"id":5995},{"batb":[[0,1.17,117.65],[1,1.03,199],[2,1.02,200]],"ltp":1.13,"tv":6.92,"id":2120},{"batb":[[0,1.17,117.65],[1,1.03,200],[2,1.02,200]],"ltp":0.0,"tv":0.0,"id":60443}]}]}
{"op":"mcm","clk":"11858062583","pt":1723816498796,"mc":[{"id":"1.231804628","rc":[{"batb":[[0,1.18,47.6],[1,1.17,117.65],[2,1.03,200]],"ltp":1.04,"tv":0.91,"id":5995},{"batb":[[0,1.18,47.6],[1,1.17,117.65],[2,1.03,199]],"ltp":1.13,"tv":6.92,"id":2120},{"batb":[[0,1.18,47.6],[1,1.17,117.65],[2,1.03,200]],"ltp":0.0,"tv":0.0,"id":60443}]}]}
{"op":"mcm","clk":"11858194020","pt":1723818299402,"mc":[{"id":"1.231804628","rc":[{"batb":[[0,1.17,117.65],[1,1.03,200],[2,1.02,200]],"ltp":1.04,"tv":0.91,"id":5995},{"batb":[[0,1.17,117.65],[1,1.03,199],[2,1.02,200]],"ltp":1.13,"tv":6.92,"id":2120},{"batb":[[0,1.17,117.65],[1,1.03,200],[2,1.02,200]],"ltp":0.0,"tv":0.0,"id":60443}],"tv":7.84}]}
{"op":"mcm","clk":"11858206131","pt":1723818470637,"mc":[{"id":"1.231804628","rc":[{"batb":[[0,1.18,47.61],[1,1.17,117.65],[2,1.03,200]],"ltp":1.04,"tv":0.91,"id":5995},{"batb":[[0,1.18,47.61],[1,1.17,117.65],[2,1.03,199]],"ltp":1.13,"tv":6.92,"id":2120},{"batb":[[0,1.18,47.61],[1,1.17,117.65],[2,1.03,200]],"ltp":0.0,"tv":0.0,"id":60443}]}]}
{"op":"mcm","clk":"11858215662","pt":1723818607483,"mc":[{"id":"1.231804628","rc":[{"batl":[[0,95,5]],"ltp":1.04,"tv":0.91,"id":5995},{"batl":[[0,95,5]],"ltp":1.13,"tv":6.92,"id":2120},{"batl":[[0,95,5]],"ltp":0.0,"tv":0.0,"id":60443}]}]}
{"op":"mcm","clk":"11858335660","pt":1723820271015,"mc":[{"id":"1.231804628","rc":[{"batb":[[0,1.17,117.65],[1,1.03,200],[2,1.02,200]],"ltp":1.04,"tv":0.91,"id":5995},{"batb":[[0,1.17,117.65],[1,1.03,199],[2,1.02,200]],"ltp":1.13,"tv":6.92,"id":2120},{"batb":[[0,1.17,117.65],[1,1.03,200],[2,1.02,200]],"ltp":0.0,"tv":0.0,"id":60443}]}]}
{"op":"mcm","clk":"11858349477","pt":1723820431589,"mc":[{"id":"1.231804628","rc":[{"batb":[[0,1.18,47.62],[1,1.17,117.65],[2,1.03,200]],"ltp":1.04,"tv":0.91,"id":5995},{"trd":[[1.04,2.37],[1.13,2.55]],"batb":[[0,1.18,47.62],[1,1.17,117.65],[2,1.03,199]],"ltp":1.13,"tv":6.92,"id":2120},{"batb":[[0,1.18,47.62],[1,1.17,117.65],[2,1.03,200]],"ltp":0.0,"tv":0.0,"id":60443}],"tv":7.84}]}
{"op":"mcm","clk":"11858515691","pt":1723822232164,"mc":[{"id":"1.231804628","rc":[{"batb":[[0,1.17,117.65],[1,1.03,200],[2,1.02,200]],"ltp":1.04,"tv":0.91,"id":5995},{"batb":[[0,1.17,117.65],[1,1.03,199],[2,1.02,200]],"ltp":1.13,"tv":6.92,"id":2120},{"batb":[[0,1.17,117.65],[1,1.03,200],[2,1.02,200]],"ltp":0.0,"tv":0.0,"id":60443}]}]}
{"op":"mcm","clk":"11858530802","pt":1723822385568,"mc":[{"id":"1.231804628","rc":[{"batb":[[0,1.18,47.62],[1,1.17,117.65],[2,1.03,200]],"ltp":1.04,"tv":0.91,"id":5995},{"batb":[[0,1.18,47.62],[1,1.17,117.65],[2,1.03,199]],"ltp":1.13,"tv":6.92,"id":2120},{"batb":[[0,1.18,47.62],[1,1.17,117.65],[2,1.03,200]],"ltp":0.0,"tv":0.0,"id":60443}]}]}
{"op":"mcm","clk":"11858716572","pt":1723824186279,"mc":[{"id":"1.231804628","rc":[{"batb":[[0,1.17,117.65],[1,1.03,200],[2,1.02,200]],"ltp":1.04,"tv":0.91,"id":5995},{"trd":[[1.04,2.37],[1.13,2.55]],"batb":[[0,1.17,117.65],[1,1.03,199],[2,1.02,200]],"ltp":1.13,"tv":6.92,"id":2120},{"batb":[[0,1.17,117.65],[1,1.03,200],[2,1.02,200]],"ltp":0.0,"tv":0.0,"id":60443}],"tv":7.84}]}
{"op":"mcm","clk":"11858732319","pt":1723824334935,"mc":[{"id":"1.231804628","rc":[{"batb":[[0,1.18,47.59],[1,1.17,117.65],[2,1.03,200]],"ltp":1.04,"tv":0.91,"id":5995},{"batb":[[0,1.18,47.59],[1,1.17,117.65],[2,1.03,199]],"ltp":1.13,"tv":6.92,"id":2120},{"batb":[[0,1.18,47.59],[1,1.17,117.65],[2,1.03,200]],"ltp":0.0,"tv":0.0,"id":60443}]}]}
{"op":"mcm","clk":"11858960721","pt":1723826135361,"mc":[{"id":"1.231804628","rc":[{"batb":[[0,1.17,117.65],[1,1.03,200],[2,1.02,200]],"ltp":1.04,"tv":0.91,"id":5995},{"batb":[[0,1.17,117.65],[1,1.03,200],[2,1.02,200]],"ltp":0.0,"tv":0.0,"id":60443}]}]}
{"op":"mcm","clk":"11858960748","pt":1723826135573,"mc":[{"id":"1.231804628","rc":[{"batb":[[0,1.17,117.65],[1,1.03,199],[2,1.02,200]],"ltp":1.13,"tv":6.92,"id":2120}]}]}
{"op":"mcm","clk":"11858978828","pt":1723826273627,"mc":[{"id":"1.231804628","rc":[{"batb":[[0,1.18,47.59],[1,1.17,117.65],[2,1.03,200]],"ltp":1.04,"tv":0.91,"id":5995},{"batb":[[0,1.18,47.59],[1,1.17,117.65],[2,1.03,199]],"ltp":1.13,"tv":6.92,"id":2120},{"batb":[[0,1.18,47.59],[1,1.17,117.65],[2,1.03,200]],"ltp":0.0,"tv":0.0,"id":60443}]}]}
{"op":"mcm","clk":"11859228364","pt":1723828074248,"mc":[{"id":"1.231804628","rc":[{"batb":[[0,1.17,117.65],[1,1.03,200],[2,1.02,200]],"ltp":1.04,"tv":0.91,"id":5995},{"trd":[[1.04,2.37],[1.13,2.55]],"batb":[[0,1.17,117.65],[1,1.03,199],[2,1.02,200]],"ltp":1.13,"tv":6.92,"id":2120},{"batb":[[0,1.17,117.65],[1,1.03,200],[2,1.02,200]],"ltp":0.0,"tv":0.0,"id":60443}],"tv":7.83}]}
{"op":"mcm","clk":"11859252779","pt":1723828214444,"mc":[{"id":"1.231804628","rc":[{"batb":[[0,1.18,47.56],[1,1.17,117.65],[2,1.03,200]],"ltp":1.04,"tv":0.91,"id":5995},{"batb":[[0,1.18,47.56],[1,1.17,117.65],[2,1.03,199]],"ltp":1.13,"tv":6.92,"id":2120},{"batb":[[0,1.18,47.56],[1,1.17,117.65],[2,1.03,200]],"ltp":0.0,"tv":0.0,"id":60443}]}]}
{"op":"mcm","clk":"11859550890","pt":1723830014898,"mc":[{"id":"1.231804628","rc":[{"batb":[[0,1.17,117.65],[1,1.03,200],[2,1.02,200]],"ltp":1.04,"tv":0.91,"id":5995},{"batb":[[0,1.17,117.65],[1,1.03,199],[2,1.02,200]],"ltp":1.13,"tv":6.92,"id":2120},{"batb":[[0,1.17,117.65],[1,1.03,200],[2,1.02,200]],"ltp":0.0,"tv":0.0,"id":60443}]}]}
{"op":"mcm","clk":"11859571819","pt":1723830136219,"mc":[{"id":"1.231804628","rc":[{"batb":[[0,1.18,47.56],[1,1.17,117.65],[2,1.03,200]],"ltp":1.04,"tv":0.91,"id":5995},{"batb":[[0,1.18,47.56],[1,1.17,117.65],[2,1.03,199]],"ltp":1.13,"tv":6.92,"id":2120},{"batb":[[0,1.18,47.56],[1,1.17,117.65],[2,1.03,200]],"ltp":0.0,"tv":0.0,"id":60443}]}]}
{"op":"mcm","clk":"11859681546","pt":1723830829327,"mc":[{"id":"1.231804628","rc":[{"batb":[[1,1.03,200],[2,1.02,200]],"ltp":1.04,"tv":0.91,"id":5995}]}]}
{"op":"mcm","clk":"11859681831","pt":1723830831427,"mc":[{"id":"1.231804628","rc":[{"batb":[[0,1.19,105.26],[1,1.18,47.56],[2,1.03,200]],"ltp":1.04,"tv":0.91,"id":5995}]}]}
{"op":"mcm","clk":"11859682024","pt":1723830832847,"mc":[{"id":"1.231804628","rc":[{"batb":[[1,1.03,199],[2,1.02,200]],"ltp":1.13,"tv":6.92,"id":2120}]}]}
{"op":"mcm","clk":"11859682138","pt":1723830833842,"mc":[{"id":"1.231804628","rc":[{"batb":[[0,1.19,105.26],[1,1.18,47.56],[2,1.03,199]],"ltp":1.13,"tv":6.92,"id":2120}]}]}
{"op":"mcm","clk":"11859682766","pt":1723830838234,"mc":[{"id":"1.231804628","rc":[{"batb":[[1,1.03,200],[2,1.02,200]],"ltp":0.0,"tv":0.0,"id":60443}]}]}
{"op":"mcm","clk":"11859682972","pt":1723830839683,"mc":[{"id":"1.231804628","rc":[{"batb":[[0,1.19,105.26],[1,1.18,47.56],[2,1.03,200]],"ltp":0.0,"tv":0.0,"id":60443}]}]}
{"op":"mcm","clk":"11859894931","pt":1723831936374,"mc":[{"id":"1.231804628","rc":[{"batb":[[1,1.03,200],[2,1.02,200]],"ltp":1.04,"tv":0.91,"id":5995},{"batb":[[1,1.18,47.57]],"ltp":1.13,"tv":6.92,"id":2120},{"batb":[[1,1.18,47.57]],"ltp":0.0,"tv":0.0,"id":60443}],"tv":7.83}]}
{"op":"mcm","clk":"11859895151","pt":1723831937376,"mc":[{"id":"1.231804628","rc":[{"batb":[[1,1.03,199],[2,1.02,200]],"ltp":1.13,"tv":6.92,"id":2120},{"batb":[[1,1.03,200],[2,1.02,200]],"ltp":0.0,"tv":0.0,"id":60443}]}]}
{"op":"mcm","clk":"11859929823","pt":1723832030003,"mc":[{"id":"1.231804628","rc":[{"batb":[[0,1.2,42.81],[1,1.19,105.26],[2,1.03,200]],"ltp":1.04,"tv":0.91,"id":5995},{"batb":[[0,1.2,42.81],[1,1.19,105.26],[2,1.03,199]],"ltp":1.13,"tv":6.92,"id":2120},{"batb":[[0,1.2,42.81],[1,1.19,105.26],[2,1.03,200]],"ltp":0.0,"tv":0.0,"id":60443}]}]}
{"op":"mcm","clk":"11860337978","pt":1723833856173,"mc":[{"id":"1.231804628","rc":[{"batb":[[0,1.19,105.26],[1,1.03,200],[2,1.02,200]],"ltp":1.04,"tv":0.91,"id":5995},{"batb":[[0,1.19,105.26],[1,1.03,199],[2,1.02,200]],"ltp":1.13,"tv":6.92,"id":2120},{"batb":[[0,1.19,105.26],[1,1.03,200],[2,1.02,200]],"ltp":0.0,"tv":0.0,"id":60443}]}]}
{"op":"mcm","clk":"11860344105","pt":1723833885212,"mc":[{"id":"1.231804628","rc":[{"batb":[[0,1.2,42.81],[1,1.19,105.26],[2,1.03,200]],"ltp":1.04,"tv":0.91,"id":5995},{"batb":[[0,1.2,42.81],[1,1.19,105.26],[2,1.03,199]],"ltp":1.13,"tv":6.92,"id":2120},{"batb":[[0,1.2,42.81],[1,1.19,105.26],[2,1.03,200]],"ltp":0.0,"tv":0.0,"id":60443}]}]}
{"op":"mcm","clk":"11860572230","pt":1723835087374,"mc":[{"id":"1.231804628","rc":[{"batb":[[0,1.21,6.88],[1,1.2,42.8],[2,1.19,105.26]],"ltp":1.04,"tv":0.91,"id":5995},{"trd":[[1.04,2.37],[1.13,2.55]],"batb":[[0,1.21,6.07],[1,1.2,42.8],[2,1.19,105.26]],"ltp":1.13,"tv":6.91,"id":2120},{"batb":[[0,1.2,42.8]],"ltp":0.0,"tv":0.0,"id":60443}],"tv":7.83}]}
{"op":"mcm","clk":"11860572284","pt":1723835087697,"mc":[{"id":"1.231804628","rc":[{"batb":[[0,1.21,6.2],[1,1.2,42.8],[2,1.19,105.26]],"ltp":0.0,"tv":0.0,"id":60443}]}]}
{"op":"mcm","clk":"11860693859","pt":1723835685505,"mc":[{"id":"1.231804628","rc":[{"batb":[[1,1.19,105.26],[2,1.03,199]],"ltp":1.13,"tv":6.91,"id":2120}]}]}
{"op":"mcm","clk":"11860693931","pt":1723835685876,"mc":[{"id":"1.231804628","rc":[{"batb":[[1,1.19,105.26],[2,1.03,200]],"ltp":1.04,"tv":0.91,"id":5995},{"batb":[[1,1.19,105.26],[2,1.03,200]],"ltp":0.0,"tv":0.0,"id":60443}]}]}
{"op":"mcm","clk":"11860697002","pt":1723835701211,"mc":[{"id":"1.231804628","rc":[{"batb":[[0,1.22,38.91],[1,1.21,6.88],[2,1.19,105.26]],"ltp":1.04,"tv":0.91,"id":5995},{"batb":[[0,1.22,38.91],[1,1.21,6.07],[2,1.19,105.26]],"ltp":1.13,"tv":6.91,"id":2120},{"batb":[[0,1.22,38.91],[1,1.21,6.2],[2,1.19,105.26]],"ltp":0.0,"tv":0.0,"id":60443}]}]}
{"op":"mcm","clk":"11861033748","pt":1723837502060,"mc":[{"id":"1.231804628","rc":[{"batb":[[0,1.21,6.88],[1,1.19,105.26],[2,1.03,200]],"ltp":1.04,"tv":0.91,"id":5995},{"batb":[[0,1.21,6.07],[1,1.19,105.26],[2,1.03,199]],"ltp":1.13,"tv":6.91,"id":2120},{"batb":[[0,1.21,6.2],[1,1.19,105.26],[2,1.03,200]],"ltp":0.0,"tv":0.0,"id":60443}]}]}
{"op":"mcm","clk":"11861054367","pt":1723837639503,"mc":[{"id":"1.231804628","rc":[{"batb":[[0,1.22,38.91],[1,1.21,6.88],[2,1.19,105.26]],"ltp":1.04,"tv":0.91,"id":5995},{"batb":[[0,1.22,38.91],[1,1.21,6.07],[2,1.19,105.26]],"ltp":1.13,"tv":6.91,"id":2120},{"batb":[[0,1.22,38.91],[1,1.21,6.2],[2,1.19,105.26]],"ltp":0.0,"tv":0.0,"id":60443}]}]}
{"op":"mcm","clk":"11861286235","pt":1723839413477,"mc":[{"id":"1.231804628","rc":[{"batb":[[0,1.22,38.91],[1,1.21,6.88]],"ltp":1.04,"tv":0.91,"id":5995},{"batb":[[0,1.23,6.06],[1,1.22,38.91]],"ltp":1.13,"tv":6.91,"id":2120},{"batb":[[0,1.22,38.91]],"ltp":0.0,"tv":0.0,"id":60443}]}]}
{"op":"mcm","clk":"11861286326","pt":1723839414365,"mc":[{"id":"1.231804628","rc":[{"batb":[[0,1.23,6.88],[1,1.22,38.91]],"ltp":1.04,"tv":0.91,"id":5995},{"batb":[[0,1.23,6.2],[1,1.22,38.91]],"ltp":0.0,"tv":0.0,"id":60443}]}]}
{"op":"mcm","clk":"11861289216","pt":1723839440472,"mc":[{"id":"1.231804628","rc":[{"batb":[[1,1.19,105.26],[2,1.03,200]],"ltp":1.04,"tv":0.91,"id":5995},{"batb":[[1,1.19,105.26],[2,1.03,199]],"ltp":1.13,"tv":6.91,"id":2120}]}]}
{"op":"mcm","clk":"11861289229","pt":1723839440618,"mc":[{"id":"1.231804628","rc":[{"batb":[[1,1.19,105.26],[2,1.03,200]],"ltp":0.0,"tv":0.0,"id":60443}]}]}
{"op":"mcm","clk":"11861313581","pt":1723839675146,"mc":[{"id":"1.231804628","rc":[{"batb":[[0,1.24,35.67],[1,1.23,6.88],[2,1.19,105.26]],"ltp":1.04,"tv":0.91,"id":5995},{"batb":[[0,1.24,35.67],[1,1.23,6.06],[2,1.19,105.26]],"ltp":1.13,"tv":6.91,"id":2120},{"batb":[[0,1.24,35.67],[1,1.23,6.2],[2,1.19,105.26]],"ltp":0.0,"tv":0.0,"id":60443}]}]}
{"op":"mcm","clk":"11861466730","pt":1723841476092,"mc":[{"id":"1.231804628","rc":[{"batb":[[0,1.23,6.88],[1,1.19,105.26],[2,1.03,200]],"ltp":1.04,"tv":0.91,"id":5995},{"batb":[[0,1.23,6.06],[1,1.19,105.26],[2,1.03,199]],"ltp":1.13,"tv":6.91,"id":2120},{"batb":[[0,1.23,6.2],[1,1.19,105.26],[2,1.03,200]],"ltp":0.0,"tv":0.0,"id":60443}]}]}
{"op":"mcm","clk":"11861478501","pt":1723841657542,"mc":[{"id":"1.231804628","rc":[{"batb":[[0,1.24,35.67],[1,1.23,6.88],[2,1.19,105.26]],"ltp":1.04,"tv":0.91,"id":5995},{"batb":[[0,1.24,35.67],[1,1.23,6.06],[2,1.19,105.26]],"ltp":1.13,"tv":6.91,"id":2120},{"batb":[[0,1.24,35.67],[1,1.23,6.2],[2,1.19,105.26]],"ltp":0.0,"tv":0.0,"id":60443}]}]}
{"op":"mcm","clk":"11861557285","pt":1723842774939,"mc":[{"id":"1.231804628","rc":[{"batb":[[0,1.24,35.68]],"ltp":1.04,"tv":0.91,"id":5995},{"batb":[[0,1.24,35.68]],"ltp":1.13,"tv":6.91,"id":2120},{"batb":[[0,1.24,35.68]],"ltp":0.0,"tv":0.0,"id":60443}]}]}
{"op":"mcm","clk":"11861602296","pt":1723843458039,"mc":[{"id":"1.231804628","rc":[{"batb":[[0,1.23,6.88],[1,1.19,105.26],[2,1.03,200]],"ltp":1.04,"tv":0.91,"id":5995},{"batb":[[0,1.23,6.06],[1,1.19,105.26],[2,1.03,199]],"ltp":1.13,"tv":6.91,"id":2120},{"batb":[[0,1.23,6.2],[1,1.19,105.26],[2,1.03,200]],"ltp":0.0,"tv":0.0,"id":60443}]}]}
{"op":"mcm","clk":"11861607708","pt":1723843595556,"mc":[{"id":"1.231804628","rc":[{"batb":[[0,1.24,35.68],[1,1.23,6.88],[2,1.19,105.26]],"ltp":1.04,"tv":0.91,"id":5995},{"batb":[[0,1.24,35.68],[1,1.23,6.06],[2,1.19,105.26]],"ltp":1.13,"tv":6.91,"id":2120},{"batb":[[0,1.24,35.68],[1,1.23,6.2],[2,1.19,105.26]],"ltp":0.0,"tv":0.0,"id":60443}]}]}
{"op":"mcm","clk":"11861663531","pt":1723844887471,"mc":[{"id":"1.231804628","rc":[{"batb":[[0,1.25,6.88],[1,1.24,35.68]],"ltp":1.04,"tv":0.91,"id":5995},{"batb":[[0,1.25,6.06],[1,1.24,35.68]],"ltp":1.13,"tv":6.91,"id":2120},{"batb":[[0,1.25,6.2],[1,1.24,35.68]],"ltp":0.0,"tv":0.0,"id":60443}]}]}
{"op":"mcm","clk":"11861688469","pt":1723845396315,"mc":[{"id":"1.231804628","rc":[{"batb":[[1,1.19,105.26],[2,1.03,200]],"ltp":1.04,"tv":0.91,"id":5995},{"batb":[[1,1.19,105.26],[2,1.03,199]],"ltp":1.13,"tv":6.91,"id":2120}]}]}
{"op":"mcm","clk":"11861688505","pt":1723845396577,"mc":[{"id":"1.231804628","rc":[{"batb":[[1,1.19,105.26],[2,1.03,200]],"ltp":0.0,"tv":0.0,"id":60443}]}]}
{"op":"mcm","clk":"11861694574","pt":1723845509330,"mc":[{"id":"1.231804628","rc":[{"batb":[[0,1.26,32.94],[1,1.25,6.88],[2,1.19,105.26]],"ltp":1.04,"tv":0.91,"id":5995},{"batb":[[0,1.26,32.94],[1,1.25,6.06],[2,1.19,105.26]],"ltp":1.13,"tv":6.91,"id":2120},{"batb":[[0,1.26,32.94],[1,1.25,6.2],[2,1.19,105.26]],"ltp":0.0,"tv":0.0,"id":60443}]}]}
{"op":"mcm","clk":"11861785548","pt":1723847310044,"mc":[{"id":"1.231804628","rc":[{"batb":[[0,1.25,6.88],[1,1.19,105.26],[2,1.03,200]],"ltp":1.04,"tv":0.91,"id":5995},{"batb":[[0,1.25,6.06],[1,1.19,105.26],[2,1.03,199]],"ltp":1.13,"tv":6.91,"id":2120},{"batb":[[0,1.25,6.19],[1,1.19,105.26],[2,1.03,200]],"ltp":0.0,"tv":0.0,"id":60443}],"tv":7.83}]}
{"op":"mcm","clk":"11861792253","pt":1723847418389,"mc":[{"id":"1.231804628","rc":[{"batb":[[0,1.26,32.92],[1,1.25,6.88],[2,1.19,105.26]],"ltp":1.04,"tv":0.91,"id":5995},{"batb":[[0,1.26,32.92],[1,1.25,6.06],[2,1.19,105.26]],"ltp":1.13,"tv":6.91,"id":2120},{"batb":[[0,1.26,32.92],[1,1.25,6.19],[2,1.19,105.26]],"ltp":0.0,"tv":0.0,"id":60443}]}]}
{"op":"mcm","clk":"11861914788","pt":1723849219303,"mc":[{"id":"1.231804628","rc":[{"batb":[[0,1.25,6.88],[1,1.19,105.26],[2,1.03,200]],"ltp":1.04,"tv":0.91,"id":5995},{"batb":[[0,1.25,6.06],[1,1.19,105.26],[2,1.03,199]],"ltp":1.13,"tv":6.91,"id":2120},{"batb":[[0,1.25,6.19],[1,1.19,105.26],[2,1.03,200]],"ltp":0.0,"tv":0.0,"id":60443}]}]}
{"op":"mcm","clk":"11861916100","pt":1723849239395,"mc":[{"id":"1.231804628","rc":[{"batb":[[0,1.2,6.88]],"ltp":1.04,"tv":0.91,"id":5995},{"batb":[[0,1.2,6.06]],"ltp":1.13,"tv":6.91,"id":2120}]}]}
{"op":"mcm","clk":"11861916124","pt":1723849239798,"mc":[{"id":"1.231804628","rc":[{"batb":[[0,1.2,6.19]],"ltp":0.0,"tv":0.0,"id":60443}]}]}
{"op":"mcm","clk":"11861921758","pt":1723849317574,"mc":[{"id":"1.231804628","rc":[{"batb":[[0,1.21,40.76],[1,1.2,6.88],[2,1.19,105.26]],"ltp":1.04,"tv":0.91,"id":5995},{"batb":[[0,1.21,40.76],[1,1.2,6.06],[2,1.19,105.26]],"ltp":1.13,"tv":6.91,"id":2120},{"batb":[[0,1.21,40.76],[1,1.2,6.19],[2,1.19,105.26]],"ltp":0.0,"tv":0.0,"id":60443}]}]}
{"op":"mcm","clk":"11862059056","pt":1723851118192,"mc":[{"id":"1.231804628","rc":[{"batb":[[0,1.2,6.88],[1,1.19,105.26],[2,1.03,200]],"ltp":1.04,"tv":0.91,"id":5995},{"batb":[[0,1.2,6.06],[1,1.19,105.26],[2,1.03,199]],"ltp":1.13,"tv":6.91,"id":2120},{"batb":[[0,1.2,6.19],[1,1.19,105.26],[2,1.03,200]],"ltp":0.0,"tv":0.0,"id":60443}]}]}
{"op":"mcm","clk":"11862066548","pt":1723851207502,"mc":[{"id":"1.231804628","rc":[{"batb":[[0,1.21,40.76],[1,1.2,6.88],[2,1.19,105.26]],"ltp":1.04,"tv":0.91,"id":5995},{"batb":[[0,1.21,40.76],[1,1.2,6.06],[2,1.19,105.26]],"ltp":1.13,"tv":6.91,"id":2120},{"batb":[[0,1.21,40.76],[1,1.2,6.19],[2,1.19,105.26]],"ltp":0.0,"tv":0.0,"id":60443}]}]}
{"op":"mcm","clk":"11862136469","pt":1723852068344,"mc":[{"id":"1.231804628","rc":[{"batb":[[0,1.22,6.88],[1,1.21,40.76]],"ltp":1.04,"tv":0.91,"id":5995},{"batb":[[0,1.22,6.06],[1,1.21,40.76]],"ltp":1.13,"tv":6.91,"id":2120},{"batb":[[0,1.22,6.19],[1,1.21,40.76]],"ltp":0.0,"tv":0.0,"id":60443}]}]}
{"op":"mcm","clk":"11862198994","pt":1723853008154,"mc":[{"id":"1.231804628","rc":[{"batb":[[1,1.19,105.26],[2,1.03,200]],"ltp":1.04,"tv":0.91,"id":5995},{"batb":[[1,1.19,105.26],[2,1.03,199]],"ltp":1.13,"tv":6.91,"id":2120},{"batb":[[1,1.19,105.26],[2,1.03,200]],"ltp":0.0,"tv":0.0,"id":60443}]}]}
{"op":"mcm","clk":"11862203890","pt":1723853088756,"mc":[{"id":"1.231804628","rc":[{"batb":[[0,1.23,37.22],[1,1.22,6.88],[2,1.19,105.26]],"ltp":1.04,"tv":0.91,"id":5995},{"batb":[[0,1.23,37.22],[1,1.22,6.06],[2,1.19,105.26]],"ltp":1.13,"tv":6.91,"id":2120},{"batb":[[0,1.23,37.22],[1,1.22,6.19],[2,1.19,105.26]],"ltp":0.0,"tv":0.0,"id":60443}]}]}
{"op":"mcm","clk":"11862328200","pt":1723854889245,"mc":[{"id":"1.231804628","rc":[{"batb":[[0,1.22,6.88],[1,1.19,105.26],[2,1.03,200]],"ltp":1.04,"tv":0.91,"id":5995},{"batb":[[0,1.22,6.06],[1,1.19,105.26],[2,1.03,199]],"ltp":1.13,"tv":6.91,"id":2120}]}]}
{"op":"mcm","clk":"11862328216","pt":1723854889558,"mc":[{"id":"1.231804628","rc":[{"batb":[[0,1.22,6.19],[1,1.19,105.26],[2,1.03,200]],"ltp":0.0,"tv":0.0,"id":60443}]}]}
{"op":"mcm","clk":"11862332818","pt":1723854959452,"mc":[{"id":"1.231804628","rc":[{"batb":[[0,1.23,37.22],[1,1.22,6.88],[2,1.19,105.26]],"ltp":1.04,"tv":0.91,"id":5995},{"batb":[[0,1.23,37.22],[1,1.22,6.06],[2,1.19,105.26]],"ltp":1.13,"tv":6.91,"id":2120},{"batb":[[0,1.23,37.22],[1,1.22,6.19],[2,1.19,105.26]],"ltp":0.0,"tv":0.0,"id":60443}]}]}
{"op":"mcm","clk":"11862428212","pt":1723856554437,"mc":[{"id":"1.231804628","rc":[{"batb":[[1,1.19,105.26],[2,1.03,200]],"ltp":1.04,"tv":0.91,"id":5995},{"batb":[[0,1.24,6.06],[1,1.23,37.22]],"ltp":1.13,"tv":6.91,"id":2120}]}]}
{"op":"mcm","clk":"11862428240","pt":1723856554951,"mc":[{"id":"1.231804628","rc":[{"batb":[[0,1.24,6.88],[1,1.23,37.22],[2,1.19,105.26]],"ltp":1.04,"tv":0.91,"id":5995},{"batb":[[0,1.24,6.19],[1,1.23,37.22]],"ltp":0.0,"tv":0.0,"id":60443}]}]}
{"op":"mcm","clk":"11862438073","pt":1723856759993,"mc":[{"id":"1.231804628","rc":[{"batb":[[1,1.19,105.26],[2,1.03,200]],"ltp":1.04,"tv":0.91,"id":5995},{"batb":[[1,1.19,105.26],[2,1.03,199]],"ltp":1.13,"tv":6.91,"id":2120},{"batb":[[1,1.19,105.26],[2,1.03,200]],"ltp":0.0,"tv":0.0,"id":60443}]}]}
{"op":"mcm","clk":"11862441395","pt":1723856825157,"mc":[{"id":"1.231804628","rc":[{"batb":[[0,1.25,34.24],[1,1.24,6.88],[2,1.19,105.26]],"ltp":1.04,"tv":0.91,"id":5995},{"batb":[[0,1.25,34.24],[1,1.24,6.06],[2,1.19,105.26]],"ltp":1.13,"tv":6.91,"id":2120},{"batb":[[0,1.25,34.24],[1,1.24,6.19],[2,1.19,105.26]],"ltp":0.0,"tv":0.0,"id":60443}]}]}
{"op":"mcm","clk":"11862539789","pt":1723858625497,"mc":[{"id":"1.231804628","rc":[{"batb":[[0,1.24,6.06],[1,1.19,105.26],[2,1.03,199]],"ltp":1.13,"tv":6.91,"id":2120}]}]}
{"op":"mcm","clk":"11862539818","pt":1723858625908,"mc":[{"id":"1.231804628","rc":[{"batb":[[0,1.24,6.88],[1,1.19,105.26],[2,1.03,200]],"ltp":1.04,"tv":0.91,"id":5995},{"batb":[[0,1.24,6.19],[1,1.19,105.26],[2,1.03,200]],"ltp":0.0,"tv":0.0,"id":60443}]}]}
{"op":"mcm","clk":"11862543102","pt":1723858683666,"mc":[{"id":"1.231804628","rc":[{"batb":[[0,1.25,34.24],[1,1.24,6.88],[2,1.19,105.26]],"ltp":1.04,"tv":0.91,"id":5995},{"batb":[[0,1.25,34.24],[1,1.24,6.06],[2,1.19,105.26]],"ltp":1.13,"tv":6.91,"id":2120},{"batb":[[0,1.25,34.24],[1,1.24,6.19],[2,1.19,105.26]],"ltp":0.0,"tv":0.0,"id":60443}]}]}
{"op":"mcm","clk":"11862661749","pt":1723860484366,"mc":[{"id":"1.231804628","rc":[{"batb":[[0,1.24,6.88],[1,1.19,105.26],[2,1.03,200]],"ltp":1.04,"tv":0.91,"id":5995},{"batb":[[0,1.24,6.06],[1,1.19,105.26],[2,1.03,199]],"ltp":1.13,"tv":6.91,"id":2120},{"batb":[[0,1.24,6.19],[1,1.19,105.26],[2,1.03,200]],"ltp":0.0,"tv":0.0,"id":60443}]}]}
{"op":"mcm","clk":"11862664360","pt":1723860531160,"mc":[{"id":"1.231804628","rc":[{"batb":[[0,1.25,34.24],[1,1.24,6.88],[2,1.19,105.26]],"ltp":1.04,"tv":0.91,"id":5995},{"batb":[[0,1.25,34.24],[1,1.24,6.06],[2,1.19,105.26]],"ltp":1.13,"tv":6.91,"id":2120},{"batb":[[0,1.25,34.24],[1,1.24,6.19],[2,1.19,105.26]],"ltp":0.0,"tv":0.0,"id":60443}]}]}
{"op":"mcm","clk":"11862692943","pt":1723861045378,"mc":[{"id":"1.231804628","rc":[{"batb":[[0,1.26,6.06],[1,1.25,34.24]],"ltp":1.13,"tv":6.91,"id":2120}]}]}
{"op":"mcm","clk":"11862692999","pt":1723861046167,"mc":[{"id":"1.231804628","rc":[{"batb":[[0,1.26,6.88],[1,1.25,34.24]],"ltp":1.04,"tv":0.91,"id":5995},{"batb":[[0,1.26,6.19],[1,1.25,34.24]],"ltp":0.0,"tv":0.0,"id":60443}]}]}
{"op":"mcm","clk":"11862776006","pt":1723862331483,"mc":[{"id":"1.231804628","rc":[{"batb":[[1,1.19,105.26],[2,1.03,200]],"ltp":1.04,"tv":0.91,"id":5995},{"batb":[[1,1.19,105.26],[2,1.03,200]],"ltp":0.0,"tv":0.0,"id":60443}]}]}
{"op":"mcm","clk":"11862776016","pt":1723862331687,"mc":[{"id":"1.231804628","rc":[{"batb":[[1,1.19,105.26],[2,1.03,199]],"ltp":1.13,"tv":6.91,"id":2120}]}]}
{"op":"mcm","clk":"11862777825","pt":1723862363333,"mc":[{"id":"1.231804628","rc":[{"batb":[[0,1.27,31.7],[1,1.26,6.88],[2,1.19,105.26]],"ltp":1.04,"tv":0.91,"id":5995},{"batb":[[0,1.27,31.7],[1,1.26,6.06],[2,1.19,105.26]],"ltp":1.13,"tv":6.91,"id":2120},{"batb":[[0,1.27,31.7],[1,1.26,6.19],[2,1.19,105.26]],"ltp":0.0,"tv":0.0,"id":60443}]}]}
{"op":"mcm","clk":"11862886589","pt":1723864163938,"mc":[{"id":"1.231804628","rc":[{"batb":[[0,1.26,6.88],[1,1.19,105.26],[2,1.03,200]],"ltp":1.04,"tv":0.91,"id":5995},{"batb":[[0,1.26,6.06],[1,1.19,105.26],[2,1.03,199]],"ltp":1.13,"tv":6.91,"id":2120},{"batb":[[0,1.26,6.19],[1,1.19,105.26],[2,1.03,200]],"ltp":0.0,"tv":0.0,"id":60443}]}]}
{"op":"mcm","clk":"11862887193","pt":1723864173543,"mc":[{"id":"1.231804628","rc":[{"batb":[[0,1.27,31.7],[1,1.26,6.88],[2,1.19,105.26]],"ltp":1.04,"tv":0.91,"id":5995},{"batb":[[0,1.27,31.7],[1,1.26,6.06],[2,1.19,105.26]],"ltp":1.13,"tv":6.91,"id":2120},{"batb":[[0,1.27,31.7],[1,1.26,6.19],[2,1.19,105.26]],"ltp":0.0,"tv":0.0,"id":60443}]}]}
{"op":"mcm","clk":"11863001759","pt":1723865974228,"mc":[{"id":"1.231804628","rc":[{"batb":[[0,1.26,6.88],[1,1.19,105.26],[2,1.03,200]],"ltp":1.04,"tv":0.91,"id":5995},{"batb":[[0,1.26,6.06],[1,1.19,105.26],[2,1.03,199]],"ltp":1.13,"tv":6.91,"id":2120},{"batb":[[0,1.26,6.19],[1,1.19,105.26],[2,1.03,200]],"ltp":0.0,"tv":0.0,"id":60443}]}]}
{"op":"mcm","clk":"11863001834","pt":1723865975204,"mc":[{"id":"1.231804628","rc":[{"batb":[[0,1.27,31.7],[1,1.26,6.88],[2,1.19,105.26]],"ltp":1.04,"tv":0.91,"id":5995},{"batb":[[0,1.27,31.7],[1,1.26,6.06],[2,1.19,105.26]],"ltp":1.13,"tv":6.91,"id":2120},{"batb":[[0,1.27,31.7],[1,1.26,6.19],[2,1.19,105.26]],"ltp":0.0,"tv":0.0,"id":60443}]}]}
{"op":"mcm","clk":"11863104147","pt":1723867775478,"mc":[{"id":"1.231804628","rc":[{"batb":[[0,1.26,6.19],[1,1.19,105.26],[2,1.03,200]],"ltp":0.0,"tv":0.0,"id":60443}]}]}
{"op":"mcm","clk":"11863104173","pt":1723867775945,"mc":[{"id":"1.231804628","rc":[{"batb":[[0,1.26,6.88],[1,1.19,105.26],[2,1.03,200]],"ltp":1.04,"tv":0.91,"id":5995},{"batb":[[0,1.26,6.06],[1,1.19,105.26],[2,1.03,199]],"ltp":1.13,"tv":6.91,"id":2120}]}]}
{"op":"mcm","clk":"11863117728","pt":1723867988923,"mc":[{"id":"1.231804628","rc":[{"batb":[[0,1.27,31.7],[1,1.26,6.88],[2,1.19,105.26]],"ltp":1.04,"tv":0.91,"id":5995},{"batb":[[0,1.27,31.7],[1,1.26,6.06],[2,1.19,105.26]],"ltp":1.13,"tv":6.91,"id":2120},{"batb":[[0,1.27,31.7],[1,1.26,6.19],[2,1.19,105.26]],"ltp":0.0,"tv":0.0,"id":60443}]}]}
{"op":"mcm","clk":"11863233072","pt":1723869789366,"mc":[{"id":"1.231804628","rc":[{"batb":[[0,1.26,6.06],[1,1.19,105.26],[2,1.03,199]],"ltp":1.13,"tv":6.91,"id":2120},{"batb":[[0,1.26,6.19],[1,1.19,105.26],[2,1.03,200]],"ltp":0.0,"tv":0.0,"id":60443}]}]}
{"op":"mcm","clk":"11863233078","pt":1723869789571,"mc":[{"id":"1.231804628","rc":[{"batb":[[0,1.26,6.88],[1,1.19,105.26],[2,1.03,200]],"ltp":1.04,"tv":0.91,"id":5995}]}]}
{"op":"mcm","clk":"11863243938","pt":1723869988493,"mc":[{"id":"1.231804628","rc":[{"batb":[[0,1.2,6.88]],"ltp":1.04,"tv":0.91,"id":5995},{"batb":[[0,1.2,6.06]],"ltp":1.13,"tv":6.91,"id":2120},{"batb":[[0,1.2,6.19]],"ltp":0.0,"tv":0.0,"id":60443}]}]}
{"op":"mcm","clk":"11863244030","pt":1723869989743,"mc":[{"id":"1.231804628","rc":[{"batb":[[0,1.21,40.76],[1,1.2,6.88],[2,1.19,105.26]],"ltp":1.04,"tv":0.91,"id":5995},{"batb":[[0,1.21,40.76],[1,1.2,6.06],[2,1.19,105.26]],"ltp":1.13,"tv":6.91,"id":2120},{"batb":[[0,1.21,40.76],[1,1.2,6.19],[2,1.19,105.26]],"ltp":0.0,"tv":0.0,"id":60443}]}]}
{"op":"mcm","clk":"11863338105","pt":1723871790356,"mc":[{"id":"1.231804628","rc":[{"batb":[[0,1.2,6.88],[1,1.19,105.26],[2,1.03,200]],"ltp":1.04,"tv":0.91,"id":5995},{"batb":[[0,1.2,6.06],[1,1.19,105.26],[2,1.03,199]],"ltp":1.13,"tv":6.91,"id":2120},{"batb":[[0,1.2,6.19],[1,1.19,105.26],[2,1.03,200]],"ltp":0.0,"tv":0.0,"id":60443}]}]}
{"op":"mcm","clk":"11863349478","pt":1723871979833,"mc":[{"id":"1.231804628","rc":[{"batb":[[0,1.21,40.76],[1,1.2,6.88],[2,1.19,105.26]],"ltp":1.04,"tv":0.91,"id":5995},{"batb":[[0,1.21,40.76],[1,1.2,6.06],[2,1.19,105.26]],"ltp":1.13,"tv":6.91,"id":2120},{"batb":[[0,1.21,40.76],[1,1.2,6.19],[2,1.19,105.26]],"ltp":0.0,"tv":0.0,"id":60443}]}]}
{"op":"mcm","clk":"11863435975","pt":1723873780464,"mc":[{"id":"1.231804628","rc":[{"batb":[[0,1.2,6.88],[1,1.19,105.26],[2,1.03,200]],"ltp":1.04,"tv":0.91,"id":5995},{"batb":[[0,1.2,6.06],[1,1.19,105.26],[2,1.03,199]],"ltp":1.13,"tv":6.91,"id":2120},{"batb":[[0,1.2,6.19],[1,1.19,105.26],[2,1.03,200]],"ltp":0.0,"tv":0.0,"id":60443}]}]}
{"op":"mcm","clk":"11863445922","pt":1723873966965,"mc":[{"id":"1.231804628","rc":[{"batb":[[0,1.21,40.76],[1,1.2,6.88],[2,1.19,105.26]],"ltp":1.04,"tv":0.91,"id":5995},{"batb":[[0,1.21,40.76],[1,1.2,6.06],[2,1.19,105.26]],"ltp":1.13,"tv":6.91,"id":2120},{"batb":[[0,1.21,40.76],[1,1.2,6.19],[2,1.19,105.26]],"ltp":0.0,"tv":0.0,"id":60443}]}]}
{"op":"mcm","clk":"11863475055","pt":1723874444459,"mc":[{"id":"1.231804628","rc":[{"batb":[[0,1.22,6.06],[1,1.21,40.76]],"ltp":1.13,"tv":6.91,"id":2120}]}]}
{"op":"mcm","clk":"11863475109","pt":1723874445291,"mc":[{"id":"1.231804628","rc":[{"batb":[[0,1.22,6.88],[1,1.21,40.76]],"ltp":1.04,"tv":0.91,"id":5995},{"batb":[[1,1.19,105.26],[2,1.03,200]],"ltp":0.0,"tv":0.0,"id":60443}]}]}
{"op":"mcm","clk":"11863475134","pt":1723874445592,"mc":[{"id":"1.231804628","rc":[{"batb":[[0,1.22,6.19],[1,1.21,40.76],[2,1.19,105.26]],"ltp":0.0,"tv":0.0,"id":60443}]}]}
{"op":"mcm","clk":"11863560972","pt":1723875767430,"mc":[{"id":"1.231804628","rc":[{"batb":[[1,1.19,105.26],[2,1.03,199]],"ltp":1.13,"tv":6.91,"id":2120},{"batb":[[1,1.19,105.26],[2,1.03,200]],"ltp":0.0,"tv":0.0,"id":60443}]}]}
{"op":"mcm","clk":"11863560983","pt":1723875767626,"mc":[{"id":"1.231804628","rc":[{"batb":[[1,1.19,105.26],[2,1.03,200]],"ltp":1.04,"tv":0.91,"id":5995}]}]}
{"op":"mcm","clk":"11863569787","pt":1723875954157,"mc":[{"id":"1.231804628","rc":[{"batb":[[0,1.23,37.22],[1,1.22,6.88],[2,1.19,105.26]],"ltp":1.04,"tv":0.91,"id":5995},{"batb":[[0,1.23,37.22],[1,1.22,6.06],[2,1.19,105.26]],"ltp":1.13,"tv":6.91,"id":2120},{"batb":[[0,1.23,37.22],[1,1.22,6.19],[2,1.19,105.26]],"ltp":0.0,"tv":0.0,"id":60443}]}]}
{"op":"mcm","clk":"11863678305","pt":1723877754445,"mc":[{"id":"1.231804628","rc":[{"batb":[[0,1.22,6.06],[1,1.19,105.26],[2,1.03,199]],"ltp":1.13,"tv":6.91,"id":2120}]}]}
{"op":"mcm","clk":"11863678333","pt":1723877754801,"mc":[{"id":"1.231804628","rc":[{"batb":[[0,1.22,6.88],[1,1.19,105.26],[2,1.03,200]],"ltp":1.04,"tv":0.91,"id":5995},{"batb":[[0,1.22,6.19],[1,1.19,105.26],[2,1.03,200]],"ltp":0.0,"tv":0.0,"id":60443}]}]}
{"op":"mcm","clk":"11863688775","pt":1723877937574,"mc":[{"id":"1.231804628","rc":[{"batb":[[0,1.23,37.22],[1,1.22,6.88],[2,1.19,105.26]],"ltp":1.04,"tv":0.91,"id":5995},{"batb":[[0,1.23,37.22],[1,1.22,6.06],[2,1.19,105.26]],"ltp":1.13,"tv":6.91,"id":2120},{"batb":[[0,1.23,37.22],[1,1.22,6.19],[2,1.19,105.26]],"ltp":0.0,"tv":0.0,"id":60443}]}]}
{"op":"mcm","clk":"11863752720","pt":1723878901459,"mc":[{"id":"1.231804628","rc":[{"batb":[[1,1.19,105.26],[2,1.03,200]],"ltp":1.04,"tv":0.91,"id":5995},{"batb":[[0,1.24,6.06],[1,1.23,37.22]],"ltp":1.13,"tv":6.91,"id":2120}]}]}
{"op":"mcm","clk":"11863752763","pt":1723878901975,"mc":[{"id":"1.231804628","rc":[{"batb":[[0,1.24,6.88],[1,1.23,37.22],[2,1.19,105.26]],"ltp":1.04,"tv":0.91,"id":5995},{"batb":[[0,1.24,6.19],[1,1.23,37.22]],"ltp":0.0,"tv":0.0,"id":60443}]}]}
{"op":"mcm","clk":"11863805098","pt":1723879738307,"mc":[{"id":"1.231804628","rc":[{"batb":[[1,1.19,105.26],[2,1.03,200]],"ltp":1.04,"tv":0.91,"id":5995},{"batb":[[1,1.19,105.26],[2,1.03,199]],"ltp":1.13,"tv":6.91,"id":2120},{"batb":[[1,1.19,105.26],[2,1.03,200]],"ltp":0.0,"tv":0.0,"id":60443}]}]}
{"op":"mcm","clk":"11863815809","pt":1723879917429,"mc":[{"id":"1.231804628","rc":[{"batb":[[0,1.25,34.24],[1,1.24,6.88],[2,1.19,105.26]],"ltp":1.04,"tv":0.91,"id":5995},{"batb":[[0,1.25,34.24],[1,1.24,6.06],[2,1.19,105.26]],"ltp":1.13,"tv":6.91,"id":2120},{"batb":[[0,1.25,34.24],[1,1.24,6.19],[2,1.19,105.26]],"ltp":0.0,"tv":0.0,"id":60443}]}]}
{"op":"mcm","clk":"11863929061","pt":1723881717865,"mc":[{"id":"1.231804628","rc":[{"batb":[[0,1.24,6.88],[1,1.19,105.26],[2,1.03,200]],"ltp":1.04,"tv":0.91,"id":5995},{"batb":[[0,1.24,6.06],[1,1.19,105.26],[2,1.03,199]],"ltp":1.13,"tv":6.91,"id":2120}]}]}
{"op":"mcm","clk":"11863929129","pt":1723881718591,"mc":[{"id":"1.231804628","rc":[{"batb":[[0,1.24,6.19],[1,1.19,105.26],[2,1.03,200]],"ltp":0.0,"tv":0.0,"id":60443}]}]}
{"op":"mcm","clk":"11863943196","pt":1723881897311,"mc":[{"id":"1.231804628","rc":[{"batb":[[0,1.25,34.24],[1,1.24,6.88],[2,1.19,105.26]],"ltp":1.04,"tv":0.91,"id":5995},{"batb":[[0,1.25,34.24],[1,1.24,6.06],[2,1.19,105.26]],"ltp":1.13,"tv":6.91,"id":2120},{"batb":[[0,1.25,34.24],[1,1.24,6.19],[2,1.19,105.26]],"ltp":0.0,"tv":0.0,"id":60443}]}]}
{"op":"mcm","clk":"11864060562","pt":1723883353318,"mc":[{"id":"1.231804628","rc":[{"batb":[[0,1.26,6.88],[1,1.25,34.24]],"ltp":1.04,"tv":0.91,"id":5995},{"batb":[[0,1.26,6.06],[1,1.25,34.24]],"ltp":1.13,"tv":6.91,"id":2120}]}]}
{"op":"mcm","clk":"11864060595","pt":1723883353725,"mc":[{"id":"1.231804628","rc":[{"batb":[[0,1.26,6.19],[1,1.25,34.24]],"ltp":0.0,"tv":0.0,"id":60443}]}]}
{"op":"mcm","clk":"11864090464","pt":1723883697920,"mc":[{"id":"1.231804628","rc":[{"batb":[[1,1.19,105.26],[2,1.03,200]],"ltp":1.04,"tv":0.91,"id":5995},{"batb":[[1,1.19,105.26],[2,1.03,199]],"ltp":1.13,"tv":6.91,"id":2120},{"batb":[[1,1.19,105.26],[2,1.03,200]],"ltp":0.0,"tv":0.0,"id":60443}]}]}
{"op":"mcm","clk":"11864105884","pt":1723883876429,"mc":[{"id":"1.231804628","rc":[{"batb":[[0,1.27,31.7],[1,1.26,6.88],[2,1.19,105.26]],"ltp":1.04,"tv":0.91,"id":5995},{"batb":[[0,1.27,31.7],[1,1.26,6.06],[2,1.19,105.26]],"ltp":1.13,"tv":6.91,"id":2120},{"batb":[[0,1.27,31.7],[1,1.26,6.19],[2,1.19,105.26]],"ltp":0.0,"tv":0.0,"id":60443}]}]}
{"op":"mcm","clk":"11864265355","pt":1723885676911,"mc":[{"id":"1.231804628","rc":[{"batb":[[0,1.26,6.88],[1,1.19,105.26],[2,1.03,200]],"ltp":1.04,"tv":0.91,"id":5995},{"batb":[[0,1.26,6.06],[1,1.19,105.26],[2,1.03,199]],"ltp":1.13,"tv":6.91,"id":2120},{"batb":[[0,1.26,6.19],[1,1.19,105.26],[2,1.03,200]],"ltp":0.0,"tv":0.0,"id":60443}]}]}
{"op":"mcm","clk":"11864288046","pt":1723885856034,"mc":[{"id":"1.231804628","rc":[{"batb":[[0,1.27,31.7],[1,1.26,6.88],[2,1.19,105.26]],"ltp":1.04,"tv":0.91,"id":5995},{"batb":[[0,1.27,31.7],[1,1.26,6.06],[2,1.19,105.26]],"ltp":1.13,"tv":6.91,"id":2120},{"batb":[[0,1.27,31.7],[1,1.26,6.19],[2,1.19,105.26]],"ltp":0.0,"tv":0.0,"id":60443}]}]}
{"op":"mcm","clk":"11864533352","pt":1723887656451,"mc":[{"id":"1.231804628","rc":[{"batb":[[0,1.26,6.06],[1,1.19,105.26],[2,1.03,199]],"ltp":1.13,"tv":6.91,"id":2120},{"batb":[[0,1.26,6.19],[1,1.19,105.26],[2,1.03,200]],"ltp":0.0,"tv":0.0,"id":60443}]}]}
{"op":"mcm","clk":"11864533376","pt":1723887656654,"mc":[{"id":"1.231804628","rc":[{"batb":[[0,1.26,6.88],[1,1.19,105.26],[2,1.03,200]],"ltp":1.04,"tv":0.91,"id":5995}]}]}
{"op":"mcm","clk":"11864555478","pt":1723887810335,"mc":[{"id":"1.231804628","rc":[{"batb":[[0,1.2,6.06]],"ltp":1.13,"tv":6.91,"id":2120}]}]}
{"op":"mcm","clk":"11864555568","pt":1723887811057,"mc":[{"id":"1.231804628","rc":[{"batb":[[0,1.2,6.88]],"ltp":1.04,"tv":0.91,"id":5995},{"batb":[[0,1.2,6.19]],"ltp":0.0,"tv":0.0,"id":60443}]}]}
{"op":"mcm","clk":"11864558549","pt":1723887834466,"mc":[{"id":"1.231804628","rc":[{"batb":[[0,1.21,40.76],[1,1.2,6.88],[2,1.19,105.26]],"ltp":1.04,"tv":0.91,"id":5995},{"batb":[[0,1.21,40.76],[1,1.2,6.06],[2,1.19,105.26]],"ltp":1.13,"tv":6.91,"id":2120},{"batb":[[0,1.21,40.76],[1,1.2,6.19],[2,1.19,105.26]],"ltp":0.0,"tv":0.0,"id":60443}]}]}
{"op":"mcm","clk":"11864821698","pt":1723889634974,"mc":[{"id":"1.231804628","rc":[{"batb":[[0,1.2,6.88],[1,1.19,105.26],[2,1.03,200]],"ltp":1.04,"tv":0.91,"id":5995},{"batb":[[0,1.2,6.06],[1,1.19,105.26],[2,1.03,199]],"ltp":1.13,"tv":6.91,"id":2120},{"batb":[[0,1.2,6.19],[1,1.19,105.26],[2,1.03,200]],"ltp":0.0,"tv":0.0,"id":60443}]}]}
{"op":"mcm","clk":"11864851952","pt":1723889799150,"mc":[{"id":"1.231804628","rc":[{"batb":[[0,1.21,40.76],[1,1.2,6.88],[2,1.19,105.26]],"ltp":1.04,"tv":0.91,"id":5995},{"batb":[[0,1.21,40.76],[1,1.2,6.06],[2,1.19,105.26]],"ltp":1.13,"tv":6.91,"id":2120},{"batb":[[0,1.21,40.76],[1,1.2,6.19],[2,1.19,105.26]],"ltp":0.0,"tv":0.0,"id":60443}]}]}
{"op":"mcm","clk":"11865195389","pt":1723891600374,"mc":[{"id":"1.231804628","rc":[{"batb":[[0,1.2,6.88],[1,1.19,105.26],[2,1.03,200]],"ltp":1.04,"tv":0.91,"id":5995},{"batb":[[0,1.2,6.06],[1,1.19,105.26],[2,1.03,199]],"ltp":1.13,"tv":6.91,"id":2120}]}]}
{"op":"mcm","clk":"11865195424","pt":1723891600600,"mc":[{"id":"1.231804628","rc":[{"batb":[[0,1.2,6.19],[1,1.19,105.26],[2,1.03,200]],"ltp":0.0,"tv":0.0,"id":60443}]}]}
{"op":"mcm","clk":"11865223877","pt":1723891757341,"mc":[{"id":"1.231804628","rc":[{"batb":[[0,1.21,40.76],[1,1.2,6.88],[2,1.19,105.26]],"ltp":1.04,"tv":0.91,"id":5995},{"batb":[[0,1.21,40.76],[1,1.2,6.06],[2,1.19,105.26]],"ltp":1.13,"tv":6.91,"id":2120},{"batb":[[0,1.21,40.76],[1,1.2,6.19],[2,1.19,105.26]],"ltp":0.0,"tv":0.0,"id":60443}]}]}
{"op":"mcm","clk":"11865304821","pt":1723892236133,"mc":[{"id":"1.231804628","rc":[{"batb":[[0,1.22,6.06],[1,1.21,40.76]],"ltp":1.13,"tv":6.91,"id":2120}]}]}
{"op":"mcm","clk":"11865304986","pt":1723892237274,"mc":[{"id":"1.231804628","rc":[{"batb":[[0,1.22,6.88],[1,1.21,40.76]],"ltp":1.04,"tv":0.91,"id":5995},{"batb":[[0,1.22,6.19],[1,1.21,40.76]],"ltp":0.0,"tv":0.0,"id":60443}]}]}
{"op":"mcm","clk":"11865531796","pt":1723893558005,"mc":[{"id":"1.231804628","rc":[{"batb":[[1,1.19,105.26],[2,1.03,200]],"ltp":1.04,"tv":0.91,"id":5995},{"batb":[[1,1.19,105.26],[2,1.03,199]],"ltp":1.13,"tv":6.91,"id":2120},{"batb":[[1,1.19,105.26],[2,1.03,200]],"ltp":0.0,"tv":0.0,"id":60443}]}]}
{"op":"mcm","clk":"11865557864","pt":1723893703861,"mc":[{"id":"1.231804628","rc":[{"batb":[[0,1.23,37.22],[1,1.22,6.88],[2,1.19,105.26]],"ltp":1.04,"tv":0.91,"id":5995},{"batb":[[0,1.23,37.22],[1,1.22,6.06],[2,1.19,105.26]],"ltp":1.13,"tv":6.91,"id":2120},{"batb":[[0,1.23,37.22],[1,1.22,6.19],[2,1.19,105.26]],"ltp":0.0,"tv":0.0,"id":60443}]}]}
{"op":"mcm","clk":"11865867274","pt":1723895504354,"mc":[{"id":"1.231804628","rc":[{"batb":[[0,1.22,6.88],[1,1.19,105.26],[2,1.03,200]],"ltp":1.04,"tv":0.91,"id":5995},{"batb":[[0,1.22,6.19],[1,1.19,105.26],[2,1.03,200]],"ltp":0.0,"tv":0.0,"id":60443}]}]}
{"op":"mcm","clk":"11865867296","pt":1723895504567,"mc":[{"id":"1.231804628","rc":[{"batb":[[0,1.22,6.06],[1,1.19,105.26],[2,1.03,199]],"ltp":1.13,"tv":6.91,"id":2120}]}]}
{"op":"mcm","clk":"11865887579","pt":1723895634479,"mc":[{"id":"1.231804628","rc":[{"batb":[[0,1.23,37.22],[1,1.22,6.88],[2,1.19,105.26]],"ltp":1.04,"tv":0.91,"id":5995},{"batb":[[0,1.23,37.22],[1,1.22,6.06],[2,1.19,105.26]],"ltp":1.13,"tv":6.91,"id":2120},{"batb":[[0,1.23,37.22],[1,1.22,6.19],[2,1.19,105.26]],"ltp":0.0,"tv":0.0,"id":60443}]}]}
{"op":"mcm","clk":"11866050911","pt":1723896603468,"mc":[{"id":"1.231804628","rc":[{"batb":[[1,1.19,105.26],[2,1.03,200]],"ltp":1.04,"tv":0.91,"id":5995},{"batb":[[0,1.24,6.06],[1,1.23,37.22]],"ltp":1.13,"tv":6.91,"id":2120}]}]}
{"op":"mcm","clk":"11866051024","pt":1723896603954,"mc":[{"id":"1.231804628","rc":[{"batb":[[0,1.24,6.88],[1,1.23,37.22],[2,1.19,105.26]],"ltp":1.04,"tv":0.91,"id":5995},{"batb":[[0,1.24,6.19],[1,1.23,37.22]],"ltp":0.0,"tv":0.0,"id":60443}]}]}
{"op":"mcm","clk":"11866217940","pt":1723897435125,"mc":[{"id":"1.231804628","rc":[{"batb":[[1,1.19,105.26],[2,1.03,200]],"ltp":1.04,"tv":0.91,"id":5995},{"batb":[[1,1.19,105.26],[2,1.03,199]],"ltp":1.13,"tv":6.91,"id":2120},{"batb":[[1,1.19,105.26],[2,1.03,200]],"ltp":0.0,"tv":0.0,"id":60443}]}]}
{"op":"mcm","clk":"11866234300","pt":1723897521399,"mc":[{"id":"1.231804628","rc":[{"batb":[[0,1.25,34.24],[1,1.24,6.88],[2,1.19,105.26]],"ltp":1.04,"tv":0.91,"id":5995},{"batb":[[0,1.25,34.24],[1,1.24,6.06],[2,1.19,105.26]],"ltp":1.13,"tv":6.91,"id":2120},{"batb":[[0,1.25,34.24],[1,1.24,6.19],[2,1.19,105.26]],"ltp":0.0,"tv":0.0,"id":60443}]}]}
{"op":"mcm","clk":"11866555054","pt":1723899321983,"mc":[{"id":"1.231804628","rc":[{"batb":[[0,1.24,6.88],[1,1.19,105.26],[2,1.03,200]],"ltp":1.04,"tv":0.91,"id":5995},{"batb":[[0,1.24,6.06],[1,1.19,105.26],[2,1.03,199]],"ltp":1.13,"tv":6.91,"id":2120},{"batb":[[0,1.24,6.19],[1,1.19,105.26],[2,1.03,200]],"ltp":0.0,"tv":0.0,"id":60443}]}]}
{"op":"mcm","clk":"11866564315","pt":1723899380150,"mc":[{"id":"1.231804628","rc":[{"batb":[[0,1.25,34.24],[1,1.24,6.88],[2,1.19,105.26]],"ltp":1.04,"tv":0.91,"id":5995},{"batb":[[0,1.25,34.24],[1,1.24,6.06],[2,1.19,105.26]],"ltp":1.13,"tv":6.91,"id":2120},{"batb":[[0,1.25,34.24],[1,1.24,6.19],[2,1.19,105.26]],"ltp":0.0,"tv":0.0,"id":60443}]}]}
{"op":"mcm","clk":"11866754929","pt":1723900418394,"mc":[{"id":"1.231804628","rc":[{"batb":[[0,1.26,11.93],[1,1.25,34.24],[2,1.24,6.88]],"batl":[[0,95,5.85]],"ltp":1.04,"tv":0.91,"id":5995},{"batb":[[0,1.26,35.78],[1,1.25,34.24],[2,1.24,6.06]],"batl":[[0,95,5.85]],"ltp":1.13,"tv":6.91,"id":2120},{"batb":[[0,1.26,55.37],[1,1.25,34.24],[2,1.24,6.19]],"batl":[[0,95,5.85]],"ltp":0.0,"tv":0.0,"id":60443}]}]}
{"op":"mcm","clk":"11866876618","pt":1723900993470,"mc":[{"id":"1.231804628","rc":[{"batb":[[0,1.27,6.06],[1,1.26,35.78],[2,1.25,34.24]],"ltp":1.13,"tv":6.91,"id":2120}]}]}
{"op":"mcm","clk":"11866876804","pt":1723900994268,"mc":[{"id":"1.231804628","rc":[{"batb":[[0,1.26,18.8],[2,1.19,105.26]],"ltp":1.04,"tv":0.91,"id":5995},{"batb":[[0,1.27,6.19],[1,1.26,55.37],[2,1.25,34.24]],"ltp":0.0,"tv":0.0,"id":60443}]}]}
{"op":"mcm","clk":"11866913730","pt":1723901180382,"mc":[{"id":"1.231804628","rc":[{"batb":[[2,1.19,105.26]],"ltp":1.13,"tv":6.91,"id":2120}]}]}
{"op":"mcm","clk":"11866913800","pt":1723901180822,"mc":[{"id":"1.231804628","rc":[{"batb":[[1,1.19,105.26],[2,1.03,200]],"ltp":1.04,"tv":0.91,"id":5995},{"batb":[[2,1.19,105.26]],"ltp":0.0,"tv":0.0,"id":60443}]}]}
{"op":"mcm","clk":"11866918563","pt":1723901206922,"mc":[{"id":"1.231804628","rc":[{"batb":[[0,1.27,31.7],[1,1.26,18.8],[2,1.19,105.26]],"ltp":1.04,"tv":0.91,"id":5995},{"batb":[[0,1.28,30.57],[1,1.27,6.06],[2,1.26,35.78]],"ltp":1.13,"tv":6.91,"id":2120},{"batb":[[0,1.28,30.57],[1,1.27,6.19],[2,1.26,55.37]],"ltp":0.0,"tv":0.0,"id":60443}]}]}
{"op":"mcm","clk":"11867286749","pt":1723903007237,"mc":[{"id":"1.231804628","rc":[{"batb":[[0,1.26,18.8],[1,1.19,105.26],[2,1.03,200]],"ltp":1.04,"tv":0.91,"id":5995},{"batb":[[0,1.27,6.06],[1,1.26,35.78],[2,1.19,105.26]],"ltp":1.13,"tv":6.91,"id":2120}]}]}
{"op":"mcm","clk":"11867286893","pt":1723903008085,"mc":[{"id":"1.231804628","rc":[{"batb":[[0,1.27,6.19],[1,1.26,55.37],[2,1.19,105.26]],"ltp":0.0,"tv":0.0,"id":60443}]}]}
{"op":"mcm","clk":"11867318934","pt":1723903192613,"mc":[{"id":"1.231804628","rc":[{"batb":[[0,1.27,31.7],[1,1.26,18.8],[2,1.19,105.26]],"ltp":1.04,"tv":0.91,"id":5995},{"batb":[[0,1.28,30.57],[1,1.27,6.06],[2,1.26,35.78]],"ltp":1.13,"tv":6.91,"id":2120},{"batb":[[0,1.28,30.57],[1,1.27,6.19],[2,1.26,55.37]],"ltp":0.0,"tv":0.0,"id":60443}]}]}
{"op":"mcm","clk":"11867822816","pt":1723904993150,"mc":[{"id":"1.231804628","rc":[{"batb":[[0,1.26,18.8],[1,1.19,105.26],[2,1.03,200]],"ltp":1.04,"tv":0.91,"id":5995},{"batb":[[0,1.27,6.06],[1,1.26,35.78],[2,1.19,105.26]],"ltp":1.13,"tv":6.91,"id":2120},{"batb":[[0,1.27,6.19],[1,1.26,55.37],[2,1.19,105.26]],"ltp":0.0,"tv":0.0,"id":60443}]}]}
{"op":"mcm","clk":"11867860917","pt":1723905126101,"mc":[{"id":"1.231804628","rc":[{"batb":[[0,1.27,31.7],[1,1.26,18.8],[2,1.19,105.26]],"ltp":1.04,"tv":0.91,"id":5995},{"batb":[[0,1.28,30.57],[1,1.27,6.06],[2,1.26,35.78]],"ltp":1.13,"tv":6.91,"id":2120},{"batb":[[0,1.28,30.57],[1,1.27,6.19],[2,1.26,55.37]],"ltp":0.0,"tv":0.0,"id":60443}]}]}
{"op":"mcm","clk":"11867897357","pt":1723905250458,"mc":[{"id":"1.231804628","rc":[{"batb":[[1,1.26,35.78],[2,1.19,105.26]],"ltp":1.13,"tv":6.91,"id":2120}]}]}
{"op":"mcm","clk":"11867897488","pt":1723905250876,"mc":[{"id":"1.231804628","rc":[{"batb":[[0,1.29,6.19],[1,1.28,30.57]],"ltp":0.0,"tv":0.0,"id":60443}]}]}
{"op":"mcm","clk":"11868303305","pt":1723906926437,"mc":[{"id":"1.231804628","rc":[{"batb":[[0,1.26,18.8],[1,1.19,105.26],[2,1.03,200]],"ltp":1.04,"tv":0.91,"id":5995},{"batb":[[0,1.26,35.78],[1,1.19,105.26],[2,1.03,199]],"ltp":1.13,"tv":6.91,"id":2120}]}]}
{"op":"mcm","clk":"11868303342","pt":1723906926650,"mc":[{"id":"1.231804628","rc":[{"batb":[[1,1.26,55.37],[2,1.19,105.26]],"ltp":0.0,"tv":0.0,"id":60443}]}]}
{"op":"mcm","clk":"11868327175","pt":1723907036711,"mc":[{"id":"1.231804628","rc":[{"batb":[[0,1.27,31.7],[1,1.26,18.8],[2,1.19,105.26]],"ltp":1.04,"tv":0.91,"id":5995},{"batb":[[0,1.27,31.7],[1,1.26,35.78],[2,1.19,105.26]],"ltp":1.13,"tv":6.91,"id":2120},{"batb":[[0,1.3,28.53],[1,1.29,6.19],[2,1.26,55.37]],"ltp":0.0,"tv":0.0,"id":60443}]}]}
{"op":"mcm","clk":"11868831832","pt":1723908837313,"mc":[{"id":"1.231804628","rc":[{"batb":[[0,1.26,18.8],[1,1.19,105.26],[2,1.03,200]],"ltp":1.04,"tv":0.91,"id":5995},{"batb":[[0,1.26,35.78],[1,1.19,105.26],[2,1.03,199]],"ltp":1.13,"tv":6.91,"id":2120},{"batb":[[0,1.29,6.19],[1,1.26,55.37],[2,1.19,105.26]],"ltp":0.0,"tv":0.0,"id":60443}]}]}
{"op":"mcm","clk":"11868847859","pt":1723908898166,"mc":[{"id":"1.231804628","rc":[{"batb":[[0,1.27,31.7],[1,1.26,18.8],[2,1.19,105.26]],"ltp":1.04,"tv":0.91,"id":5995},{"batb":[[0,1.27,31.7],[1,1.26,35.78],[2,1.19,105.26]],"ltp":1.13,"tv":6.91,"id":2120},{"batb":[[0,1.3,28.53],[1,1.29,6.19],[2,1.26,55.37]],"ltp":0.0,"tv":0.0,"id":60443}]}]}
{"op":"mcm","clk":"11868986745","pt":1723909442493,"mc":[{"id":"1.231804628","rc":[{"batb":[[0,1.31,6.19],[1,1.3,28.53]],"ltp":0.0,"tv":0.0,"id":60443}]}]}
{"op":"mcm","clk":"11869010787","pt":1723909537813,"mc":[{"id":"1.231804628","rc":[{"batb":[[0,1.28,11.93],[1,1.27,31.7],[2,1.26,6.88]],"ltp":1.04,"tv":0.91,"id":5995},{"batb":[[0,1.28,35.78],[1,1.27,31.7]],"ltp":1.13,"tv":6.91,"id":2120},{"batb":[[0,1.32,55.37],[1,1.31,6.19],[2,1.3,28.53]],"ltp":0.0,"tv":0.0,"id":60443}]}]}
{"op":"mcm","clk":"11869226835","pt":1723910698485,"mc":[{"id":"1.231804628","rc":[{"batb":[[1,1.26,6.88],[2,1.19,105.26]],"ltp":1.04,"tv":0.91,"id":5995},{"batb":[[1,1.19,105.26],[2,1.03,199]],"ltp":1.13,"tv":6.91,"id":2120}]}]}
{"op":"mcm","clk":"11869226862","pt":1723910698698,"mc":[{"id":"1.231804628","rc":[{"batb":[[2,1.19,105.26]],"ltp":0.0,"tv":0.0,"id":60443}]}]}
{"op":"mcm","clk":"11869254458","pt":1723910860817,"mc":[{"id":"1.231804628","rc":[{"batb":[[0,1.29,29.52],[1,1.28,11.93],[2,1.26,6.88]],"ltp":1.04,"tv":0.91,"id":5995},{"batb":[[0,1.29,29.52],[1,1.28,35.78],[2,1.19,105.26]],"ltp":1.13,"tv":6.91,"id":2120},{"batb":[[0,1.33,25.94],[1,1.32,55.37],[2,1.31,6.19]],"ltp":0.0,"tv":0.0,"id":60443}]}]}
{"op":"mcm","clk":"11869583229","pt":1723912661486,"mc":[{"id":"1.231804628","rc":[{"batb":[[0,1.28,11.93],[1,1.26,6.88],[2,1.19,105.26]],"ltp":1.04,"tv":0.91,"id":5995},{"batb":[[0,1.28,35.78],[1,1.19,105.26],[2,1.03,199]],"ltp":1.13,"tv":6.91,"id":2120}]}]}
{"op":"mcm","clk":"11869583316","pt":1723912661541,"mc":[{"id":"1.231804628","rc":[{"batb":[[0,1.32,55.37],[1,1.31,6.19],[2,1.19,105.26]],"ltp":0.0,"tv":0.0,"id":60443}]}]}
{"op":"mcm","clk":"11869607405","pt":1723912780492,"mc":[{"id":"1.231804628","rc":[{"batb":[[0,1.29,29.52],[1,1.28,35.78],[2,1.19,105.26]],"ltp":1.13,"tv":6.91,"id":2120}]}]}
{"op":"mcm","clk":"11869607425","pt":1723912780607,"mc":[{"id":"1.231804628","rc":[{"batb":[[0,1.29,29.52],[1,1.28,11.93],[2,1.26,6.88]],"ltp":1.04,"tv":0.91,"id":5995},{"batb":[[0,1.33,25.94],[1,1.32,55.37],[2,1.31,6.19]],"ltp":0.0,"tv":0.0,"id":60443}]}]}
{"op":"mcm","clk":"11869920749","pt":1723914318441,"mc":[{"id":"1.231804628","rc":[{"batb":[[2,1.19,105.26]],"ltp":1.04,"tv":0.91,"id":5995},{"batb":[[0,1.34,6.19],[1,1.33,25.94],[2,1.32,55.37]],"ltp":0.0,"tv":0.0,"id":60443}]}]}
{"op":"mcm","clk":"11869970989","pt":1723914580811,"mc":[{"id":"1.231804628","rc":[{"batb":[[0,1.28,35.78],[1,1.19,105.26],[2,1.03,199]],"ltp":1.13,"tv":6.91,"id":2120}]}]}
{"op":"mcm","clk":"11869971255","pt":1723914581889,"mc":[{"id":"1.231804628","rc":[{"batb":[[0,1.28,11.93],[1,1.19,105.26],[2,1.03,200]],"ltp":1.04,"tv":0.91,"id":5995},{"batb":[[1,1.32,55.37],[2,1.19,105.26]],"ltp":0.0,"tv":0.0,"id":60443}]}]}
{"op":"mcm","clk":"11869981656","pt":1723914640356,"mc":[{"id":"1.231804628","rc":[{"batb":[[0,1.29,29.52],[1,1.28,11.93],[2,1.19,105.26]],"ltp":1.04,"tv":0.91,"id":5995},{"batb":[[0,1.29,29.52],[1,1.28,35.78],[2,1.19,105.26]],"ltp":1.13,"tv":6.91,"id":2120},{"batb":[[0,1.35,24.46],[1,1.34,6.19],[2,1.32,55.37]],"ltp":0.0,"tv":0.0,"id":60443}]}]}
{"op":"mcm","clk":"11870315717","pt":1723916441069,"mc":[{"id":"1.231804628","rc":[{"batb":[[0,1.28,11.93],[1,1.19,105.26],[2,1.03,200]],"ltp":1.04,"tv":0.91,"id":5995},{"batb":[[0,1.28,35.78],[1,1.19,105.26],[2,1.03,199]],"ltp":1.13,"tv":6.91,"id":2120},{"batb":[[0,1.34,6.19],[1,1.32,55.37],[2,1.19,105.26]],"ltp":0.0,"tv":0.0,"id":60443}]}]}
{"op":"mcm","clk":"11870316853","pt":1723916446191,"mc":[{"id":"1.231804628","rc":[{"batb":[[0,1.29,29.52],[1,1.28,11.93],[2,1.19,105.26]],"ltp":1.04,"tv":0.91,"id":5995},{"batb":[[0,1.29,29.52],[1,1.28,35.78],[2,1.19,105.26]],"ltp":1.13,"tv":6.91,"id":2120},{"batb":[[0,1.35,24.46],[1,1.34,6.19],[2,1.32,55.37]],"ltp":0.0,"tv":0.0,"id":60443}]}]}
{"op":"mcm","clk":"11870582051","pt":1723917839344,"mc":[{"id":"1.231804628","rc":[{"batb":[[1,1.33,6.19]],"ltp":0.0,"tv":0.0,"id":60443}]}]}
{"op":"mcm","clk":"11870673673","pt":1723918246438,"mc":[{"id":"1.231804628","rc":[{"batb":[[0,1.33,6.19],[1,1.32,55.37],[2,1.19,105.26]],"ltp":0.0,"tv":0.0,"id":60443}]}]}
{"op":"mcm","clk":"11870673782","pt":1723918246852,"mc":[{"id":"1.231804628","rc":[{"batb":[[0,1.28,11.93],[1,1.19,105.26],[2,1.03,200]],"ltp":1.04,"tv":0.91,"id":5995},{"batb":[[0,1.28,35.78],[1,1.19,105.26],[2,1.03,199]],"ltp":1.13,"tv":6.91,"id":2120}]}]}
{"op":"mcm","clk":"11870698674","pt":1723918352694,"mc":[{"id":"1.231804628","rc":[{"batb":[[0,1.29,29.52],[1,1.28,11.93],[2,1.19,105.26]],"ltp":1.04,"tv":0.91,"id":5995},{"batb":[[0,1.29,29.52],[1,1.28,35.78],[2,1.19,105.26]],"ltp":1.13,"tv":6.91,"id":2120},{"batb":[[0,1.34,25.18],[1,1.33,6.19],[2,1.32,55.37]],"ltp":0.0,"tv":0.0,"id":60443}]}]}
{"op":"mcm","clk":"11871100449","pt":1723920153331,"mc":[{"id":"1.231804628","rc":[{"batb":[[0,1.28,11.93],[1,1.19,105.26],[2,1.03,200]],"ltp":1.04,"tv":0.91,"id":5995},{"batb":[[0,1.28,35.78],[1,1.19,105.26],[2,1.03,199]],"ltp":1.13,"tv":6.91,"id":2120},{"batb":[[0,1.33,6.19],[1,1.32,55.37],[2,1.19,105.26]],"ltp":0.0,"tv":0.0,"id":60443}]}]}
{"op":"mcm","clk":"11871108638","pt":1723920190215,"mc":[{"id":"1.231804628","rc":[{"batb":[[0,1.29,29.52],[1,1.28,11.93],[2,1.19,105.26]],"ltp":1.04,"tv":0.91,"id":5995},{"batb":[[0,1.29,29.52],[1,1.28,35.78],[2,1.19,105.26]],"ltp":1.13,"tv":6.91,"id":2120},{"batb":[[0,1.34,25.18],[1,1.33,6.19],[2,1.32,55.37]],"ltp":0.0,"tv":0.0,"id":60443}]}]}
{"op":"mcm","clk":"11871323908","pt":1723921197636,"mc":[{"id":"1.231804628","rc":[{"batb":[[2,1.03,200]],"ltp":1.04,"tv":0.91,"id":5995}]}]}
{"op":"mcm","clk":"11871324175","pt":1723921199131,"mc":[{"id":"1.231804628","rc":[{"batb":[[2,1.03,199]],"ltp":1.13,"tv":6.91,"id":2120}]}]}
{"op":"mcm","clk":"11871324556","pt":1723921200908,"mc":[{"id":"1.231804628","rc":[{"batb":[[0,1.3,66.67],[1,1.29,29.52],[2,1.28,35.78]],"ltp":1.13,"tv":6.91,"id":2120}]}]}
{"op":"mcm","clk":"11871324848","pt":1723921202098,"mc":[{"id":"1.231804628","rc":[{"batb":[[0,1.3,66.67],[1,1.29,29.52],[2,1.28,11.93]],"ltp":1.04,"tv":0.91,"id":5995}]}]}
{"op":"mcm","clk":"11871326238","pt":1723921208402,"mc":[{"id":"1.231804628","rc":[{"batb":[[0,1.35,57.14],[1,1.34,25.18],[2,1.33,6.19]],"ltp":0.0,"tv":0.0,"id":60443}]}]}
{"op":"mcm","clk":"11871352759","pt":1723921338504,"mc":[{"id":"1.231804628","rc":[{"batb":[[0,1.31,6.13],[1,1.3,66.67],[2,1.29,29.52]],"ltp":1.04,"tv":0.91,"id":5995},{"batb":[[0,1.31,5.88],[1,1.3,66.67],[2,1.29,29.52]],"ltp":1.13,"tv":6.91,"id":2120}]}]}
{"op":"mcm","clk":"11871352833","pt":1723921338874,"mc":[{"id":"1.231804628","rc":[{"batb":[[0,1.36,6.19],[1,1.35,57.14],[2,1.34,25.18]],"ltp":0.0,"tv":0.0,"id":60443}]}]}
{"op":"mcm","clk":"11871503585","pt":1723921990506,"mc":[{"id":"1.231804628","rc":[{"batb":[[2,1.28,11.93]],"ltp":1.04,"tv":0.91,"id":5995}]}]}
{"op":"mcm","clk":"11871503679","pt":1723921990930,"mc":[{"id":"1.231804628","rc":[{"batb":[[2,1.28,35.78]],"ltp":1.13,"tv":6.91,"id":2120},{"batb":[[2,1.32,55.37]],"ltp":0.0,"tv":0.0,"id":60443}]}]}
{"op":"mcm","clk":"11871531242","pt":1723922113522,"mc":[{"id":"1.231804628","rc":[{"batb":[[0,1.32,26.75],[1,1.31,6.13],[2,1.3,66.67]],"ltp":1.04,"tv":0.91,"id":5995},{"batb":[[0,1.32,26.75],[1,1.31,5.88],[2,1.3,66.67]],"ltp":1.13,"tv":6.91,"id":2120},{"batb":[[0,1.37,23.13],[1,1.36,6.19],[2,1.35,57.14]],"ltp":0.0,"tv":0.0,"id":60443}]}]}
{"op":"mcm","clk":"11871892267","pt":1723923914338,"mc":[{"id":"1.231804628","rc":[{"batb":[[0,1.31,6.13],[1,1.3,66.67],[2,1.28,11.93]],"ltp":1.04,"tv":0.91,"id":5995},{"batb":[[0,1.31,5.88],[1,1.3,66.67],[2,1.28,35.78]],"ltp":1.13,"tv":6.91,"id":2120},{"batb":[[0,1.36,6.19],[1,1.35,57.14],[2,1.32,55.37]],"ltp":0.0,"tv":0.0,"id":60443}]}]}
{"op":"mcm","clk":"11871906836","pt":1723923996810,"mc":[{"id":"1.231804628","rc":[{"batb":[[0,1.32,26.75],[1,1.31,6.13],[2,1.3,66.67]],"ltp":1.04,"tv":0.91,"id":5995},{"batb":[[0,1.32,26.75],[1,1.31,5.88],[2,1.3,66.67]],"ltp":1.13,"tv":6.91,"id":2120},{"batb":[[0,1.37,23.13],[1,1.36,6.19],[2,1.35,57.14]],"ltp":0.0,"tv":0.0,"id":60443}]}]}
{"op":"mcm","clk":"11872031946","pt":1723924814160,"mc":[{"id":"1.231804628","rc":[{"batb":[[0,1.33,6.13],[1,1.32,26.75]],"ltp":1.04,"tv":0.91,"id":5995},{"batb":[[0,1.33,5.88],[1,1.32,26.75]],"ltp":1.13,"tv":6.91,"id":2120}]}]}
{"op":"mcm","clk":"11872182671","pt":1723925797497,"mc":[{"id":"1.231804628","rc":[{"batb":[[1,1.3,66.67],[2,1.28,11.93]],"ltp":1.04,"tv":0.91,"id":5995},{"batb":[[1,1.3,66.67],[2,1.28,35.78]],"ltp":1.13,"tv":6.91,"id":2120},{"batb":[[0,1.36,6.19],[1,1.35,57.14],[2,1.32,55.37]],"ltp":0.0,"tv":0.0,"id":60443}]}]}
{"op":"mcm","clk":"11872185363","pt":1723925814823,"mc":[{"id":"1.231804628","rc":[{"batb":[[0,1.34,25.18],[1,1.33,6.13],[2,1.3,66.67]],"ltp":1.04,"tv":0.91,"id":5995},{"batb":[[0,1.34,25.18],[1,1.33,5.88],[2,1.3,66.67]],"ltp":1.13,"tv":6.91,"id":2120},{"batb":[[0,1.37,23.13],[1,1.36,6.19],[2,1.35,57.14]],"ltp":0.0,"tv":0.0,"id":60443}]}]}
{"op":"mcm","clk":"11872417528","pt":1723927615436,"mc":[{"id":"1.231804628","rc":[{"batb":[[0,1.33,6.13],[1,1.3,66.67],[2,1.28,11.93]],"ltp":1.04,"tv":0.91,"id":5995},{"batb":[[0,1.33,5.88],[1,1.3,66.67],[2,1.28,35.78]],"ltp":1.13,"tv":6.91,"id":2120}]}]}
{"op":"mcm","clk":"11872417550","pt":1723927615639,"mc":[{"id":"1.231804628","rc":[{"batb":[[0,1.36,6.19],[1,1.35,57.14],[2,1.32,55.37]],"ltp":0.0,"tv":0.0,"id":60443}]}]}
{"op":"mcm","clk":"11872424475","pt":1723927680526,"mc":[{"id":"1.231804628","rc":[{"batb":[[0,1.34,25.18],[1,1.33,6.13],[2,1.3,66.67]],"ltp":1.04,"tv":0.91,"id":5995},{"batb":[[0,1.34,25.18],[1,1.33,5.88],[2,1.3,66.67]],"ltp":1.13,"tv":6.91,"id":2120},{"batb":[[0,1.37,23.13],[1,1.36,6.19],[2,1.35,57.14]],"ltp":0.0,"tv":0.0,"id":60443}]}]}
{"op":"mcm","clk":"11872466829","pt":1723928200283,"mc":[{"id":"1.231804628","rc":[{"batb":[[0,1.35,6.13],[1,1.34,25.18]],"ltp":1.04,"tv":0.91,"id":5995},{"batb":[[0,1.35,5.88],[1,1.34,25.18]],"ltp":1.13,"tv":6.91,"id":2120}]}]}
{"op":"mcm","clk":"11872578397","pt":1723929480865,"mc":[{"id":"1.231804628","rc":[{"batb":[[1,1.3,66.67],[2,1.28,11.93]],"ltp":1.04,"tv":0.91,"id":5995},{"batb":[[0,1.36,6.19],[1,1.35,57.14],[2,1.32,55.37]],"ltp":0.0,"tv":0.0,"id":60443}]}]}
{"op":"mcm","clk":"11872578450","pt":1723929481691,"mc":[{"id":"1.231804628","rc":[{"batb":[[1,1.3,66.67],[2,1.28,35.78]],"ltp":1.13,"tv":6.91,"id":2120}]}]}
{"op":"mcm","clk":"11872585157","pt":1723929563092,"mc":[{"id":"1.231804628","rc":[{"batb":[[0,1.36,23.78],[1,1.35,6.13],[2,1.3,66.67]],"ltp":1.04,"tv":0.91,"id":5995},{"batb":[[0,1.36,23.78],[1,1.35,5.88],[2,1.3,66.67]],"ltp":1.13,"tv":6.91,"id":2120},{"batb":[[0,1.37,23.13],[1,1.36,6.19],[2,1.35,57.14]],"ltp":0.0,"tv":0.0,"id":60443}]}]}
{"op":"mcm","clk":"11872736318","pt":1723931363511,"mc":[{"id":"1.231804628","rc":[{"batb":[[0,1.35,5.88],[1,1.3,66.67],[2,1.28,35.78]],"ltp":1.13,"tv":6.91,"id":2120},{"batb":[[0,1.36,6.19],[1,1.35,57.14],[2,1.32,55.37]],"ltp":0.0,"tv":0.0,"id":60443}]}]}
{"op":"mcm","clk":"11872736327","pt":1723931363617,"mc":[{"id":"1.231804628","rc":[{"batb":[[0,1.35,6.13],[1,1.3,66.67],[2,1.28,11.93]],"ltp":1.04,"tv":0.91,"id":5995}]}]}
{"op":"mcm","clk":"11872738276","pt":1723931390456,"mc":[{"id":"1.231804628","rc":[{"batb":[[0,1.36,23.78],[1,1.35,6.13],[2,1.3,66.67]],"ltp":1.04,"tv":0.91,"id":5995},{"batb":[[0,1.36,23.78],[1,1.35,5.88],[2,1.3,66.67]],"ltp":1.13,"tv":6.91,"id":2120},{"batb":[[0,1.37,23.13],[1,1.36,6.19],[2,1.35,57.14]],"ltp":0.0,"tv":0.0,"id":60443}]}]}
{"op":"mcm","clk":"11872758834","pt":1723931679483,"mc":[{"id":"1.231804628","rc":[{"batb":[[1,1.3,66.67],[2,1.28,35.78]],"ltp":1.13,"tv":6.91,"id":2120}]}]}
{"op":"mcm","clk":"11872758873","pt":1723931679948,"mc":[{"id":"1.231804628","rc":[{"batb":[[1,1.31,6.13]],"ltp":1.04,"tv":0.91,"id":5995},{"batb":[[1,1.31,5.88],[2,1.3,66.67]],"ltp":1.13,"tv":6.91,"id":2120}]}]}
{"op":"mcm","clk":"11872865066","pt":1723933191146,"mc":[{"id":"1.231804628","rc":[{"batb":[[0,1.31,6.13],[1,1.3,66.67],[2,1.28,11.93]],"ltp":1.04,"tv":0.91,"id":5995},{"batb":[[0,1.31,5.88],[1,1.3,66.67],[2,1.28,35.78]],"ltp":1.13,"tv":6.91,"id":2120},{"batb":[[0,1.36,6.19],[1,1.35,57.14],[2,1.32,55.37]],"ltp":0.0,"tv":0.0,"id":60443}]}]}
{"op":"mcm","clk":"11872871551","pt":1723933295180,"mc":[{"id":"1.231804628","rc":[{"batb":[[0,1.32,26.75],[1,1.31,6.13],[2,1.3,66.67]],"ltp":1.04,"tv":0.91,"id":5995},{"batb":[[0,1.32,26.75],[1,1.31,5.88],[2,1.3,66.67]],"ltp":1.13,"tv":6.91,"id":2120},{"batb":[[0,1.37,23.13],[1,1.36,6.19],[2,1.35,57.14]],"ltp":0.0,"tv":0.0,"id":60443}]}]}
{"op":"mcm","clk":"11872977903","pt":1723934788415,"mc":[{"id":"1.231804628","rc":[{"batb":[[0,1.33,6.13],[1,1.32,26.75]],"ltp":1.04,"tv":0.91,"id":5995},{"batb":[[0,1.33,5.88],[1,1.32,26.75]],"ltp":1.13,"tv":6.91,"id":2120}]}]}
{"op":"mcm","clk":"11872998407","pt":1723935095977,"mc":[{"id":"1.231804628","rc":[{"batb":[[1,1.3,66.67],[2,1.28,11.93]],"ltp":1.04,"tv":0.91,"id":5995},{"batb":[[1,1.3,66.67],[2,1.28,35.78]],"ltp":1.13,"tv":6.91,"id":2120},{"batb":[[0,1.36,6.19],[1,1.35,57.14],[2,1.32,55.37]],"ltp":0.0,"tv":0.0,"id":60443}]}]}
{"op":"mcm","clk":"11873002930","pt":1723935160420,"mc":[{"id":"1.231804628","rc":[{"batb":[[0,1.34,25.18],[1,1.33,6.13],[2,1.3,66.67]],"ltp":1.04,"tv":0.91,"id":5995},{"batb":[[0,1.34,25.18],[1,1.33,5.88],[2,1.3,66.67]],"ltp":1.13,"tv":6.91,"id":2120},{"batb":[[0,1.37,23.13],[1,1.36,6.19],[2,1.35,57.14]],"ltp":0.0,"tv":0.0,"id":60443}]}]}
{"op":"mcm","clk":"11873124694","pt":1723936961139,"mc":[{"id":"1.231804628","rc":[{"batb":[[0,1.33,6.13],[1,1.3,66.67],[2,1.28,11.93]],"ltp":1.04,"tv":0.91,"id":5995},{"batb":[[0,1.33,5.88],[1,1.3,66.67],[2,1.28,35.78]],"ltp":1.13,"tv":6.91,"id":2120},{"batb":[[0,1.36,6.19],[1,1.35,57.14],[2,1.32,55.37]],"ltp":0.0,"tv":0.0,"id":60443}]}]}
{"op":"mcm","clk":"11873131141","pt":1723937050935,"mc":[{"id":"1.231804628","rc":[{"batb":[[0,1.34,25.18],[1,1.33,6.13],[2,1.3,66.67]],"ltp":1.04,"tv":0.91,"id":5995},{"batb":[[0,1.34,25.18],[1,1.33,5.88],[2,1.3,66.67]],"ltp":1.13,"tv":6.91,"id":2120},{"batb":[[0,1.37,23.13],[1,1.36,6.19],[2,1.35,57.14]],"ltp":0.0,"tv":0.0,"id":60443}]}]}
{"op":"mcm","clk":"11873216058","pt":1723938163486,"mc":[{"id":"1.231804628","rc":[{"batb":[[0,1.35,5.88],[1,1.34,25.18]],"ltp":1.13,"tv":6.91,"id":2120}]}]}
{"op":"mcm","clk":"11873216093","pt":1723938163998,"mc":[{"id":"1.231804628","rc":[{"batb":[[0,1.35,6.13],[1,1.34,25.18]],"ltp":1.04,"tv":0.91,"id":5995}]}]}
{"op":"mcm","clk":"11873271790","pt":1723938851327,"mc":[{"id":"1.231804628","rc":[{"batb":[[1,1.3,66.67],[2,1.28,35.78]],"ltp":1.13,"tv":6.91,"id":2120},{"batb":[[0,1.36,6.19],[1,1.35,57.14],[2,1.32,55.37]],"ltp":0.0,"tv":0.0,"id":60443}]}]}
{"op":"mcm","clk":"11873271809","pt":1723938851534,"mc":[{"id":"1.231804628","rc":[{"batb":[[1,1.3,66.67],[2,1.28,11.93]],"ltp":1.04,"tv":0.91,"id":5995}]}]}
{"op":"mcm","clk":"11873281344","pt":1723938966425,"mc":[{"id":"1.231804628","rc":[{"batb":[[0,1.36,23.78],[1,1.35,6.13],[2,1.3,66.67]],"ltp":1.04,"tv":0.91,"id":5995},{"batb":[[0,1.36,23.78],[1,1.35,5.88],[2,1.3,66.67]],"ltp":1.13,"tv":6.91,"id":2120},{"batb":[[0,1.37,23.13],[1,1.36,6.19],[2,1.35,57.14]],"ltp":0.0,"tv":0.0,"id":60443}]}]}
{"op":"mcm","clk":"11873452115","pt":1723940767108,"mc":[{"id":"1.231804628","rc":[{"batb":[[0,1.35,6.13],[1,1.3,66.67],[2,1.28,11.93]],"ltp":1.04,"tv":0.91,"id":5995},{"batb":[[0,1.35,5.88],[1,1.3,66.67],[2,1.28,35.78]],"ltp":1.13,"tv":6.91,"id":2120},{"batb":[[0,1.36,6.19],[1,1.35,57.14],[2,1.32,55.37]],"ltp":0.0,"tv":0.0,"id":60443}]}]}
{"op":"mcm","clk":"11873461050","pt":1723940875886,"mc":[{"id":"1.231804628","rc":[{"batb":[[0,1.36,23.78],[1,1.35,6.13],[2,1.3,66.67]],"ltp":1.04,"tv":0.91,"id":5995},{"batb":[[0,1.36,23.78],[1,1.35,5.88],[2,1.3,66.67]],"ltp":1.13,"tv":6.91,"id":2120},{"batb":[[0,1.37,23.13],[1,1.36,6.19],[2,1.35,57.14]],"ltp":0.0,"tv":0.0,"id":60443}]}]}
{"op":"mcm","clk":"11873499496","pt":1723941355191,"mc":[{"id":"1.231804628","rc":[{"batb":[[1,1.31,6.13]],"ltp":1.04,"tv":0.91,"id":5995},{"batb":[[1,1.31,5.88]],"ltp":1.13,"tv":6.91,"id":2120}]}]}
{"op":"mcm","clk":"11873607168","pt":1723942676400,"mc":[{"id":"1.231804628","rc":[{"batb":[[0,1.31,6.13],[1,1.3,66.67],[2,1.28,11.93]],"ltp":1.04,"tv":0.91,"id":5995},{"batb":[[0,1.36,6.19],[1,1.35,57.14],[2,1.32,55.37]],"ltp":0.0,"tv":0.0,"id":60443}]}]}
{"op":"mcm","clk":"11873607181","pt":1723942676606,"mc":[{"id":"1.231804628","rc":[{"batb":[[0,1.31,5.88],[1,1.3,66.67],[2,1.28,35.78]],"ltp":1.13,"tv":6.91,"id":2120}]}]}
{"op":"mcm","clk":"11873614348","pt":1723942769487,"mc":[{"id":"1.231804628","rc":[{"batb":[[0,1.32,26.75],[1,1.31,6.13],[2,1.3,66.67]],"ltp":1.04,"tv":0.91,"id":5995},{"batb":[[0,1.32,26.75],[1,1.31,5.88],[2,1.3,66.67]],"ltp":1.13,"tv":6.91,"id":2120},{"batb":[[0,1.37,23.13],[1,1.36,6.19],[2,1.35,57.14]],"ltp":0.0,"tv":0.0,"id":60443}]}]}
{"op":"mcm","clk":"11873752424","pt":1723944513279,"mc":[{"id":"1.231804628","rc":[{"batb":[[0,1.33,5.88],[1,1.32,26.75]],"ltp":1.13,"tv":6.91,"id":2120}]}]}
{"op":"mcm","clk":"11873752467","pt":1723944513692,"mc":[{"id":"1.231804628","rc":[{"batb":[[0,1.33,6.13],[1,1.32,26.75]],"ltp":1.04,"tv":0.91,"id":5995}]}]}
{"op":"mcm","clk":"11873757497","pt":1723944570276,"mc":[{"id":"1.231804628","rc":[{"batb":[[1,1.3,66.67],[2,1.28,11.93]],"ltp":1.04,"tv":0.91,"id":5995},{"batb":[[1,1.3,66.67],[2,1.28,35.78]],"ltp":1.13,"tv":6.91,"id":2120},{"batb":[[0,1.36,6.19],[1,1.35,57.14],[2,1.32,55.37]],"ltp":0.0,"tv":0.0,"id":60443}]}]}
{"op":"mcm","clk":"11873763049","pt":1723944644363,"mc":[{"id":"1.231804628","rc":[{"batb":[[0,1.34,25.18],[1,1.33,6.13],[2,1.3,66.67]],"ltp":1.04,"tv":0.91,"id":5995},{"batb":[[0,1.34,25.18],[1,1.33,5.88],[2,1.3,66.67]],"ltp":1.13,"tv":6.91,"id":2120},{"batb":[[0,1.37,23.13],[1,1.36,6.19],[2,1.35,57.14]],"ltp":0.0,"tv":0.0,"id":60443}]}]}
{"op":"mcm","clk":"11873905591","pt":1723946444506,"mc":[{"id":"1.231804628","rc":[{"batb":[[0,1.33,5.88],[1,1.3,66.67],[2,1.28,35.78]],"ltp":1.13,"tv":6.91,"id":2120}]}]}
{"op":"mcm","clk":"11873905610","pt":1723946444913,"mc":[{"id":"1.231804628","rc":[{"batb":[[0,1.33,6.13],[1,1.3,66.67],[2,1.28,11.93]],"ltp":1.04,"tv":0.91,"id":5995},{"batb":[[0,1.36,6.19],[1,1.35,57.14],[2,1.32,55.37]],"ltp":0.0,"tv":0.0,"id":60443}]}]}
{"op":"mcm","clk":"11873908807","pt":1723946490090,"mc":[{"id":"1.231804628","rc":[{"batb":[[0,1.34,25.18],[1,1.33,6.13],[2,1.3,66.67]],"ltp":1.04,"tv":0.91,"id":5995},{"batb":[[0,1.34,25.18],[1,1.33,5.88],[2,1.3,66.67]],"ltp":1.13,"tv":6.91,"id":2120},{"batb":[[0,1.37,23.13],[1,1.36,6.19],[2,1.35,57.14]],"ltp":0.0,"tv":0.0,"id":60443}]}]}
{"op":"mcm","clk":"11873991404","pt":1723947549340,"mc":[{"id":"1.231804628","rc":[{"batb":[[0,1.35,5.88],[1,1.34,25.18]],"ltp":1.13,"tv":6.91,"id":2120}]}]}
{"op":"mcm","clk":"11873991441","pt":1723947549751,"mc":[{"id":"1.231804628","rc":[{"batb":[[0,1.35,6.13],[1,1.34,25.18]],"ltp":1.04,"tv":0.91,"id":5995}]}]}
{"op":"mcm","clk":"11874053198","pt":1723948290426,"mc":[{"id":"1.231804628","rc":[{"batb":[[1,1.3,66.67],[2,1.28,11.93]],"ltp":1.04,"tv":0.91,"id":5995},{"batb":[[1,1.3,66.67],[2,1.28,35.78]],"ltp":1.13,"tv":6.91,"id":2120}]}]}
{"op":"mcm","clk":"11874053264","pt":1723948291252,"mc":[{"id":"1.231804628","rc":[{"batb":[[0,1.36,6.19],[1,1.35,57.14],[2,1.32,55.37]],"ltp":0.0,"tv":0.0,"id":60443}]}]}
{"op":"mcm","clk":"11874069119","pt":1723948468341,"mc":[{"id":"1.231804628","rc":[{"batb":[[0,1.36,23.78],[1,1.35,6.13],[2,1.3,66.67]],"ltp":1.04,"tv":0.91,"id":5995},{"batb":[[0,1.36,23.78],[1,1.35,5.88],[2,1.3,66.67]],"ltp":1.13,"tv":6.91,"id":2120},{"batb":[[0,1.37,23.13],[1,1.36,6.19],[2,1.35,57.14]],"ltp":0.0,"tv":0.0,"id":60443}]}]}
{"op":"mcm","clk":"11874194244","pt":1723950269482,"mc":[{"id":"1.231804628","rc":[{"batb":[[0,1.35,5.88],[1,1.3,66.67],[2,1.28,35.78]],"ltp":1.13,"tv":6.91,"id":2120},{"batb":[[0,1.36,6.19],[1,1.35,57.14],[2,1.32,55.37]],"ltp":0.0,"tv":0.0,"id":60443}]}]}
{"op":"mcm","clk":"11874194254","pt":1723950269686,"mc":[{"id":"1.231804628","rc":[{"batb":[[0,1.35,6.13],[1,1.3,66.67],[2,1.28,11.93]],"ltp":1.04,"tv":0.91,"id":5995}]}]}
{"op":"mcm","clk":"11874202951","pt":1723950426584,"mc":[{"id":"1.231804628","rc":[{"batb":[[0,1.36,23.78],[1,1.35,6.13],[2,1.3,66.67]],"ltp":1.04,"tv":0.91,"id":5995},{"batb":[[0,1.36,23.78],[1,1.35,5.88],[2,1.3,66.67]],"ltp":1.13,"tv":6.91,"id":2120},{"batb":[[0,1.37,23.13],[1,1.36,6.19],[2,1.35,57.14]],"ltp":0.0,"tv":0.0,"id":60443}]}]}
{"op":"mcm","clk":"11874217505","pt":1723950693177,"mc":[{"id":"1.231804628","rc":[{"batb":[[1,1.31,6.13]],"ltp":1.04,"tv":0.91,"id":5995},{"batb":[[1,1.31,5.88]],"ltp":1.13,"tv":6.91,"id":2120}]}]}
{"op":"mcm","clk":"11874315698","pt":1723952227409,"mc":[{"id":"1.231804628","rc":[{"batb":[[0,1.31,6.13],[1,1.3,66.67],[2,1.28,11.93]],"ltp":1.04,"tv":0.91,"id":5995},{"batb":[[0,1.31,5.88],[1,1.3,66.67],[2,1.28,35.78]],"ltp":1.13,"tv":6.91,"id":2120},{"batb":[[0,1.36,6.19],[1,1.35,57.14],[2,1.32,55.37]],"ltp":0.0,"tv":0.0,"id":60443}]}]}
{"op":"mcm","clk":"11874322893","pt":1723952355206,"mc":[{"id":"1.231804628","rc":[{"batb":[[0,1.32,26.75],[1,1.31,6.13],[2,1.3,66.67]],"ltp":1.04,"tv":0.91,"id":5995},{"batb":[[0,1.32,26.75],[1,1.31,5.88],[2,1.3,66.67]],"ltp":1.13,"tv":6.91,"id":2120},{"batb":[[0,1.37,23.13],[1,1.36,6.19],[2,1.35,57.14]],"ltp":0.0,"tv":0.0,"id":60443}]}]}
{"op":"mcm","clk":"11874405329","pt":1723953773501,"mc":[{"id":"1.231804628","rc":[{"batb":[[0,1.33,6.13],[1,1.32,26.75]],"ltp":1.04,"tv":0.91,"id":5995},{"batb":[[0,1.33,5.88],[1,1.32,26.75]],"ltp":1.13,"tv":6.91,"id":2120}]}]}
{"op":"mcm","clk":"11874422622","pt":1723954155450,"mc":[{"id":"1.231804628","rc":[{"batb":[[1,1.3,66.67],[2,1.28,11.93]],"ltp":1.04,"tv":0.91,"id":5995},{"batb":[[1,1.3,66.67],[2,1.28,35.78]],"ltp":1.13,"tv":6.91,"id":2120}]}]}
{"op":"mcm","clk":"11874422635","pt":1723954155655,"mc":[{"id":"1.231804628","rc":[{"batb":[[0,1.36,6.19],[1,1.35,57.14],[2,1.32,55.37]],"ltp":0.0,"tv":0.0,"id":60443}]}]}
{"op":"mcm","clk":"11874428014","pt":1723954265508,"mc":[{"id":"1.231804628","rc":[{"batb":[[0,1.34,25.18],[1,1.33,6.13],[2,1.3,66.67]],"ltp":1.04,"tv":0.91,"id":5995},{"batb":[[0,1.34,25.18],[1,1.33,5.88],[2,1.3,66.67]],"ltp":1.13,"tv":6.91,"id":2120},{"batb":[[0,1.37,23.13],[1,1.36,6.19],[2,1.35,57.14]],"ltp":0.0,"tv":0.0,"id":60443}]}]}
{"op":"mcm","clk":"11874511679","pt":1723956066123,"mc":[{"id":"1.231804628","rc":[{"batb":[[0,1.33,6.13],[1,1.3,66.67],[2,1.28,11.93]],"ltp":1.04,"tv":0.91,"id":5995},{"batb":[[0,1.33,5.88],[1,1.3,66.67],[2,1.28,35.78]],"ltp":1.13,"tv":6.91,"id":2120},{"batb":[[0,1.36,6.19],[1,1.35,57.14],[2,1.32,55.37]],"ltp":0.0,"tv":0.0,"id":60443}]}]}
{"op":"mcm","clk":"11874514639","pt":1723956156375,"mc":[{"id":"1.231804628","rc":[{"batb":[[0,1.34,25.18],[1,1.33,6.13],[2,1.3,66.67]],"ltp":1.04,"tv":0.91,"id":5995},{"batb":[[0,1.34,25.18],[1,1.33,5.88],[2,1.3,66.67]],"ltp":1.13,"tv":6.91,"id":2120},{"batb":[[0,1.37,23.13],[1,1.36,6.19],[2,1.35,57.14]],"ltp":0.0,"tv":0.0,"id":60443}]}]}
{"op":"mcm","clk":"11874542353","pt":1723956788226,"mc":[{"id":"1.231804628","rc":[{"batb":[[0,1.35,6.13],[1,1.34,25.18]],"ltp":1.04,"tv":0.91,"id":5995},{"batb":[[0,1.35,5.88],[1,1.34,25.18]],"ltp":1.13,"tv":6.91,"id":2120}]}]}
{"op":"mcm","clk":"11874570010","pt":1723957613633,"mc":[{"id":"1.231804628","rc":[{"batb":[[0,1.36,11.93],[1,1.35,6.13],[2,1.34,25.18]],"ltp":1.04,"tv":0.91,"id":5995},{"batb":[[0,1.36,35.78],[1,1.35,5.88],[2,1.34,25.18]],"ltp":1.13,"tv":6.91,"id":2120},{"batb":[[0,1.38,55.37],[1,1.37,23.13],[2,1.36,6.19]],"ltp":0.0,"tv":0.0,"id":60443}]}]}
{"op":"mcm","clk":"11874570993","pt":1723957638061,"mc":[{"id":"1.231804628","rc":[{"batb":[[0,1.36,9.37]],"ltp":1.13,"tv":6.91,"id":2120}]}]}
{"op":"mcm","clk":"11874579299","pt":1723957956942,"mc":[{"id":"1.231804628","rc":[{"batb":[[2,1.3,66.67]],"ltp":1.04,"tv":0.91,"id":5995},{"batb":[[2,1.3,66.67]],"ltp":1.13,"tv":6.91,"id":2120},{"batb":[[1,1.36,6.19],[2,1.35,57.14]],"ltp":0.0,"tv":0.0,"id":60443}]}]}
{"op":"mcm","clk":"11874581069","pt":1723958043861,"mc":[{"id":"1.231804628","rc":[{"batb":[[0,1.37,23.13],[1,1.36,11.93],[2,1.35,6.13]],"ltp":1.04,"tv":0.91,"id":5995},{"batb":[[0,1.37,23.13],[1,1.36,9.37],[2,1.35,5.88]],"ltp":1.13,"tv":6.91,"id":2120},{"batb":[[0,1.39,21.95],[1,1.38,55.37],[2,1.36,6.19]],"ltp":0.0,"tv":0.0,"id":60443}]}]}
{"op":"mcm","clk":"11874627812","pt":1723959785450,"mc":[{"id":"1.231804628","rc":[{"batb":[[2,1.31,5.88]],"ltp":1.13,"tv":6.91,"id":2120}]}]}
{"op":"mcm","clk":"11874627835","pt":1723959786164,"mc":[{"id":"1.231804628","rc":[{"batb":[[2,1.31,6.13]],"ltp":1.04,"tv":0.91,"id":5995},{"batb":[[0,1.39,28.14],[2,1.35,57.14]],"ltp":0.0,"tv":0.0,"id":60443}]}]}
{"op":"mcm","clk":"11874629188","pt":1723959845343,"mc":[{"id":"1.231804628","rc":[{"batb":[[0,1.36,11.93],[1,1.31,6.13],[2,1.3,66.67]],"ltp":1.04,"tv":0.91,"id":5995},{"batb":[[0,1.36,9.37],[1,1.31,5.88],[2,1.3,66.67]],"ltp":1.13,"tv":6.91,"id":2120},{"batb":[[0,1.39,6.19]],"ltp":0.0,"tv":0.0,"id":60443}]}]}
{"op":"mcm","clk":"11874631154","pt":1723959922409,"mc":[{"id":"1.231804628","rc":[{"batb":[[0,1.37,23.13],[1,1.36,11.93],[2,1.31,6.13]],"ltp":1.04,"tv":0.91,"id":5995},{"batb":[[0,1.37,23.13],[1,1.36,9.37],[2,1.31,5.88]],"ltp":1.13,"tv":6.91,"id":2120},{"batb":[[0,1.4,21.4],[1,1.39,6.19],[2,1.38,55.37]],"ltp":0.0,"tv":0.0,"id":60443}]}]}
{"op":"mcm","clk":"11874680124","pt":1723961722842,"mc":[{"id":"1.231804628","rc":[{"batb":[[0,1.36,11.93],[1,1.31,6.13],[2,1.3,66.67]],"ltp":1.04,"tv":0.91,"id":5995},{"batb":[[0,1.36,9.37],[1,1.31,5.88],[2,1.3,66.67]],"ltp":1.13,"tv":6.91,"id":2120}]}]}
{"op":"mcm","clk":"11874680156","pt":1723961723662,"mc":[{"id":"1.231804628","rc":[{"batb":[[0,1.39,6.19],[1,1.38,55.37],[2,1.35,57.14]],"ltp":0.0,"tv":0.0,"id":60443}]}]}
{"op":"mcm","clk":"11874682073","pt":1723961801177,"mc":[{"id":"1.231804628","rc":[{"batb":[[0,1.37,23.13],[1,1.36,11.93],[2,1.31,6.13]],"ltp":1.04,"tv":0.91,"id":5995},{"batb":[[0,1.37,23.13],[1,1.36,9.37],[2,1.31,5.88]],"ltp":1.13,"tv":6.91,"id":2120},{"batb":[[0,1.4,21.4],[1,1.39,6.19],[2,1.38,55.37]],"ltp":0.0,"tv":0.0,"id":60443}]}]}
{"op":"mcm","clk":"11874707517","pt":1723962800370,"mc":[{"id":"1.231804628","rc":[{"batb":[[2,1.3,66.67]],"ltp":1.13,"tv":6.91,"id":2120}]}]}
{"op":"mcm","clk":"11874707524","pt":1723962800675,"mc":[{"id":"1.231804628","rc":[{"batb":[[2,1.3,66.67]],"ltp":1.04,"tv":0.91,"id":5995}]}]}
{"op":"mcm","clk":"11874708857","pt":1723962846487,"mc":[{"id":"1.231804628","rc":[{"batb":[[0,1.39,12],[1,1.37,23.13],[2,1.36,11.93]],"ltp":1.04,"tv":0.91,"id":5995},{"batb":[[0,1.38,11],[1,1.37,23.13],[2,1.36,9.37]],"ltp":1.13,"tv":6.91,"id":2120}]}]}
{"op":"mcm","clk":"11874726473","pt":1723963601433,"mc":[{"id":"1.231804628","rc":[{"batb":[[0,1.39,6.19],[1,1.38,55.37],[2,1.35,57.14]],"ltp":0.0,"tv":0.0,"id":60443}]}]}
{"op":"mcm","clk":"11874726479","pt":1723963601843,"mc":[{"id":"1.231804628","rc":[{"batb":[[1,1.36,11.93],[2,1.3,66.67]],"ltp":1.04,"tv":0.91,"id":5995},{"batb":[[1,1.36,9.37],[2,1.3,66.67]],"ltp":1.13,"tv":6.91,"id":2120}]}]}
{"op":"mcm","clk":"11874728563","pt":1723963672437,"mc":[{"id":"1.231804628","rc":[{"batb":[[0,1.4,21.4],[1,1.39,12],[2,1.36,11.93]],"ltp":1.04,"tv":0.91,"id":5995},{"batb":[[0,1.39,21.95],[1,1.38,11],[2,1.36,9.37]],"ltp":1.13,"tv":6.91,"id":2120}]}]}
{"op":"mcm","clk":"11874728566","pt":1723963672539,"mc":[{"id":"1.231804628","rc":[{"batb":[[0,1.4,21.4],[1,1.39,6.19],[2,1.38,55.37]],"ltp":0.0,"tv":0.0,"id":60443}]}]}
{"op":"mcm","clk":"11874781718","pt":1723965473340,"mc":[{"id":"1.231804628","rc":[{"batb":[[0,1.39,12],[1,1.36,11.93],[2,1.3,66.67]],"ltp":1.04,"tv":0.91,"id":5995},{"batb":[[0,1.38,11],[1,1.36,9.37],[2,1.3,66.67]],"ltp":1.13,"tv":6.91,"id":2120},{"batb":[[0,1.39,6.19],[1,1.38,55.37],[2,1.35,57.14]],"ltp":0.0,"tv":0.0,"id":60443}]}]}
{"op":"mcm","clk":"11874783411","pt":1723965546670,"mc":[{"id":"1.231804628","rc":[{"batb":[[0,1.4,21.4],[1,1.39,12],[2,1.36,11.93]],"ltp":1.04,"tv":0.91,"id":5995},{"batb":[[0,1.39,21.95],[1,1.38,11],[2,1.36,9.37]],"ltp":1.13,"tv":6.91,"id":2120},{"batb":[[0,1.4,21.4],[1,1.39,6.19],[2,1.38,55.37]],"ltp":0.0,"tv":0.0,"id":60443}]}]}
{"op":"mcm","clk":"11874852012","pt":1723967347190,"mc":[{"id":"1.231804628","rc":[{"batb":[[0,1.39,12],[1,1.36,11.93],[2,1.3,66.67]],"ltp":1.04,"tv":0.91,"id":5995},{"batb":[[0,1.38,11],[1,1.36,9.37],[2,1.3,66.67]],"ltp":1.13,"tv":6.91,"id":2120},{"batb":[[0,1.39,6.19],[1,1.38,55.37],[2,1.35,57.14]],"ltp":0.0,"tv":0.0,"id":60443}]}]}
{"op":"mcm","clk":"11874856307","pt":1723967465497,"mc":[{"id":"1.231804628","rc":[{"batb":[[0,1.4,21.4],[1,1.39,12],[2,1.36,11.93]],"ltp":1.04,"tv":0.91,"id":5995},{"batb":[[0,1.39,21.95],[1,1.38,11],[2,1.36,9.37]],"ltp":1.13,"tv":6.91,"id":2120},{"batb":[[0,1.4,21.4],[1,1.39,6.19],[2,1.38,55.37]],"ltp":0.0,"tv":0.0,"id":60443}]}]}
{"op":"mcm","clk":"11874950250","pt":1723969266186,"mc":[{"id":"1.231804628","rc":[{"batb":[[0,1.39,12],[1,1.36,11.93],[2,1.3,66.67]],"ltp":1.04,"tv":0.91,"id":5995},{"batb":[[0,1.38,11],[1,1.36,9.37],[2,1.3,66.67]],"ltp":1.13,"tv":6.91,"id":2120},{"batb":[[0,1.39,6.19],[1,1.38,55.37],[2,1.35,57.14]],"ltp":0.0,"tv":0.0,"id":60443}]}]}
{"op":"mcm","clk":"11874951492","pt":1723969283626,"mc":[{"id":"1.231804628","rc":[{"batb":[[0,1.4,21.4],[1,1.39,12],[2,1.36,11.93]],"ltp":1.04,"tv":0.91,"id":5995},{"batb":[[0,1.39,21.95],[1,1.38,11],[2,1.36,9.37]],"ltp":1.13,"tv":6.91,"id":2120},{"batb":[[0,1.4,21.4],[1,1.39,6.19],[2,1.38,55.37]],"ltp":0.0,"tv":0.0,"id":60443}]}]}
{"op":"mcm","clk":"11874988288","pt":1723969852019,"mc":[{"id":"1.231804628","rc":[{"batb":[[0,1.41,11.93],[1,1.4,21.4],[2,1.39,12]],"ltp":1.04,"tv":0.91,"id":5995},{"batb":[[0,1.4,9.37],[1,1.39,21.95],[2,1.38,11]],"ltp":1.13,"tv":6.91,"id":2120},{"batb":[[0,1.41,55.37],[1,1.4,21.4],[2,1.39,6.19]],"ltp":0.0,"tv":0.0,"id":60443}]}]}
{"op":"mcm","clk":"11875074985","pt":1723971084122,"mc":[{"id":"1.231804628","rc":[{"batb":[[1,1.39,12],[2,1.3,66.67]],"ltp":1.04,"tv":0.91,"id":5995},{"batb":[[1,1.38,11],[2,1.3,66.67]],"ltp":1.13,"tv":6.91,"id":2120},{"batb":[[1,1.39,6.19],[2,1.35,57.14]],"ltp":0.0,"tv":0.0,"id":60443}]}]}
{"op":"mcm","clk":"11875075959","pt":1723971099736,"mc":[{"id":"1.231804628","rc":[{"batb":[[0,1.42,20.38],[1,1.41,11.93],[2,1.39,12]],"ltp":1.04,"tv":0.91,"id":5995},{"batb":[[0,1.41,20.88],[1,1.4,9.37],[2,1.38,11]],"ltp":1.13,"tv":6.91,"id":2120},{"batb":[[0,1.42,20.38],[1,1.41,55.37],[2,1.39,6.19]],"ltp":0.0,"tv":0.0,"id":60443}]}]}
{"op":"mcm","clk":"11875124821","pt":1723971798677,"mc":[{"id":"1.231804628","rc":[{"batb":[[0,1.42,26.57],[2,1.35,57.14]],"ltp":0.0,"tv":0.0,"id":60443}]}]}
{"op":"mcm","clk":"11875226658","pt":1723972900154,"mc":[{"id":"1.231804628","rc":[{"batb":[[0,1.41,11.93],[1,1.39,12],[2,1.3,66.67]],"ltp":1.04,"tv":0.91,"id":5995},{"batb":[[0,1.4,9.37],[1,1.38,11],[2,1.3,66.67]],"ltp":1.13,"tv":6.91,"id":2120},{"batb":[[0,1.42,6.19]],"ltp":0.0,"tv":0.0,"id":60443}]}]}
{"op":"mcm","clk":"11875227416","pt":1723972909052,"mc":[{"id":"1.231804628","rc":[{"batb":[[0,1.42,20.38],[1,1.41,11.93],[2,1.39,12]],"ltp":1.04,"tv":0.91,"id":5995},{"batb":[[0,1.41,20.88],[1,1.4,9.37],[2,1.38,11]],"ltp":1.13,"tv":6.91,"id":2120},{"batb":[[0,1.43,19.91],[1,1.42,6.19],[2,1.41,55.37]],"ltp":0.0,"tv":0.0,"id":60443}]}]}
{"op":"mcm","clk":"11875278785","pt":1723973498756,"mc":[{"id":"1.231804628","rc":[{"batb":[[0,1.5,20],[1,1.41,20.88],[2,1.4,9.37]],"ltp":1.13,"tv":6.91,"id":2120}]}]}
{"op":"mcm","clk":"11875279518","pt":1723973507432,"mc":[{"id":"1.231804628","rc":[{"batb":[[0,1.5,20],[1,1.42,20.38],[2,1.41,11.93]],"ltp":1.04,"tv":0.91,"id":5995}]}]}
{"op":"mcm","clk":"11875386714","pt":1723974709408,"mc":[{"id":"1.231804628","rc":[{"batb":[[1,1.41,11.93],[2,1.39,12]],"ltp":1.04,"tv":0.91,"id":5995}]}]}
{"op":"mcm","clk":"11875386745","pt":1723974709775,"mc":[{"id":"1.231804628","rc":[{"batb":[[1,1.4,9.37],[2,1.38,11]],"ltp":1.13,"tv":6.91,"id":2120},{"batb":[[0,1.42,6.19],[1,1.41,55.37],[2,1.35,57.14]],"ltp":0.0,"tv":0.0,"id":60443}]}]}
{"op":"mcm","clk":"11875399323","pt":1723974888126,"mc":[{"id":"1.231804628","rc":[{"batb":[[0,1.51,16.78],[1,1.5,20],[2,1.41,11.93]],"ltp":1.04,"tv":0.91,"id":5995},{"batb":[[0,1.51,16.78],[1,1.5,20],[2,1.4,9.37]],"ltp":1.13,"tv":6.91,"id":2120},{"batb":[[0,1.43,19.91],[1,1.42,6.19],[2,1.41,55.37]],"ltp":0.0,"tv":0.0,"id":60443}]}]}
{"op":"mcm","clk":"11875444512","pt":1723975473261,"mc":[{"id":"1.231804628","rc":[{"batb":[[0,1.52,12],[1,1.51,16.78],[2,1.5,20]],"ltp":1.04,"tv":0.91,"id":5995},{"batb":[[0,1.52,11],[1,1.51,16.78],[2,1.5,20]],"ltp":1.13,"tv":6.91,"id":2120}]}]}
{"op":"mcm","clk":"11875560314","pt":1723976688347,"mc":[{"id":"1.231804628","rc":[{"batb":[[1,1.5,20],[2,1.41,11.93]],"ltp":1.04,"tv":0.91,"id":5995},{"batb":[[0,1.42,6.19],[1,1.41,55.37],[2,1.35,57.14]],"ltp":0.0,"tv":0.0,"id":60443}]}]}
{"op":"mcm","clk":"11875560341","pt":1723976688561,"mc":[{"id":"1.231804628","rc":[{"batb":[[1,1.5,20],[2,1.4,9.37]],"ltp":1.13,"tv":6.91,"id":2120}]}]}
{"op":"mcm","clk":"11875575717","pt":1723976847311,"mc":[{"id":"1.231804628","rc":[{"batb":[[0,1.53,16.15],[1,1.52,12],[2,1.5,20]],"ltp":1.04,"tv":0.91,"id":5995},{"batb":[[0,1.53,16.15],[1,1.52,11],[2,1.5,20]],"ltp":1.13,"tv":6.91,"id":2120},{"batb":[[0,1.43,19.91],[1,1.42,6.19],[2,1.41,55.37]],"ltp":0.0,"tv":0.0,"id":60443}]}]}
{"op":"mcm","clk":"11875756616","pt":1723978647450,"mc":[{"id":"1.231804628","rc":[{"batb":[[0,1.42,6.19],[1,1.41,55.37],[2,1.35,57.14]],"ltp":0.0,"tv":0.0,"id":60443}]}]}
{"op":"mcm","clk":"11875756640","pt":1723978647761,"mc":[{"id":"1.231804628","rc":[{"batb":[[0,1.52,12],[1,1.5,20],[2,1.41,11.93]],"ltp":1.04,"tv":0.91,"id":5995},{"batb":[[0,1.52,11],[1,1.5,20],[2,1.4,9.37]],"ltp":1.13,"tv":6.91,"id":2120}]}]}
{"op":"mcm","clk":"11875766733","pt":1723978787987,"mc":[{"id":"1.231804628","rc":[{"batb":[[0,1.53,16.15],[1,1.52,12],[2,1.5,20]],"ltp":1.04,"tv":0.91,"id":5995},{"batb":[[0,1.53,16.15],[1,1.52,11],[2,1.5,20]],"ltp":1.13,"tv":6.91,"id":2120},{"batb":[[0,1.43,19.91],[1,1.42,6.19],[2,1.41,55.37]],"ltp":0.0,"tv":0.0,"id":60443}]}]}
{"op":"mcm","clk":"11875929676","pt":1723980588523,"mc":[{"id":"1.231804628","rc":[{"batb":[[0,1.52,12],[1,1.5,20],[2,1.41,11.93]],"ltp":1.04,"tv":0.91,"id":5995},{"batb":[[0,1.52,11],[1,1.5,20],[2,1.4,9.37]],"ltp":1.13,"tv":6.91,"id":2120}]}]}
{"op":"mcm","clk":"11875929700","pt":1723980588730,"mc":[{"id":"1.231804628","rc":[{"batb":[[0,1.42,6.19],[1,1.41,55.37],[2,1.35,57.14]],"ltp":0.0,"tv":0.0,"id":60443}]}]}
{"op":"mcm","clk":"11875940323","pt":1723980682229,"mc":[{"id":"1.231804628","rc":[{"batb":[[0,1.53,16.15],[1,1.52,12],[2,1.5,20]],"ltp":1.04,"tv":0.91,"id":5995},{"batb":[[0,1.53,16.15],[1,1.52,11],[2,1.5,20]],"ltp":1.13,"tv":6.91,"id":2120},{"batb":[[0,1.43,19.91],[1,1.42,6.19],[2,1.41,55.37]],"ltp":0.0,"tv":0.0,"id":60443}]}]}
{"op":"mcm","clk":"11876083691","pt":1723981895071,"mc":[{"id":"1.231804628","rc":[{"batb":[[0,1.54,12],[1,1.53,16.15]],"ltp":1.04,"tv":0.91,"id":5995},{"batb":[[0,1.54,11],[1,1.53,16.15]],"ltp":1.13,"tv":6.91,"id":2120}]}]}
{"op":"mcm","clk":"11876140371","pt":1723982482475,"mc":[{"id":"1.231804628","rc":[{"batb":[[0,1.42,6.19],[1,1.41,55.37],[2,1.35,57.14]],"ltp":0.0,"tv":0.0,"id":60443}]}]}
{"op":"mcm","clk":"11876140400","pt":1723982482878,"mc":[{"id":"1.231804628","rc":[{"batb":[[1,1.5,20],[2,1.41,11.93]],"ltp":1.04,"tv":0.91,"id":5995},{"batb":[[1,1.5,20],[2,1.4,9.37]],"ltp":1.13,"tv":6.91,"id":2120}]}]}
{"op":"mcm","clk":"11876148025","pt":1723982570611,"mc":[{"id":"1.231804628","rc":[{"batb":[[0,1.55,15.56],[1,1.54,12],[2,1.5,20]],"ltp":1.04,"tv":0.91,"id":5995},{"batb":[[0,1.55,15.56],[1,1.54,11],[2,1.5,20]],"ltp":1.13,"tv":6.91,"id":2120},{"batb":[[0,1.43,19.91],[1,1.42,6.19],[2,1.41,55.37]],"ltp":0.0,"tv":0.0,"id":60443}]}]}
{"op":"mcm","clk":"11876363100","pt":1723984371425,"mc":[{"id":"1.231804628","rc":[{"batb":[[0,1.54,12],[1,1.5,20],[2,1.41,11.93]],"ltp":1.04,"tv":0.91,"id":5995},{"batb":[[0,1.54,11],[1,1.5,20],[2,1.4,9.37]],"ltp":1.13,"tv":6.91,"id":2120},{"batb":[[0,1.42,6.19],[1,1.41,55.37],[2,1.35,57.14]],"ltp":0.0,"tv":0.0,"id":60443}]}]}
{"op":"mcm","clk":"11876369950","pt":1723984425660,"mc":[{"id":"1.231804628","rc":[{"batb":[[0,1.55,15.56],[1,1.54,12],[2,1.5,20]],"ltp":1.04,"tv":0.91,"id":5995},{"batb":[[0,1.55,15.56],[1,1.54,11],[2,1.5,20]],"ltp":1.13,"tv":6.91,"id":2120},{"batb":[[0,1.43,19.91],[1,1.42,6.19],[2,1.41,55.37]],"ltp":0.0,"tv":0.0,"id":60443}]}]}
{"op":"mcm","clk":"11876619747","pt":1723986226440,"mc":[{"id":"1.231804628","rc":[{"batb":[[0,1.54,12],[1,1.5,20],[2,1.41,11.93]],"ltp":1.04,"tv":0.91,"id":5995},{"batb":[[0,1.54,11],[1,1.5,20],[2,1.4,9.37]],"ltp":1.13,"tv":6.91,"id":2120},{"batb":[[0,1.42,6.19],[1,1.41,55.37],[2,1.35,57.14]],"ltp":0.0,"tv":0.0,"id":60443}]}]}
{"op":"mcm","clk":"11876625879","pt":1723986264559,"mc":[{"id":"1.231804628","rc":[{"batb":[[0,1.55,15.56],[1,1.54,12],[2,1.5,20]],"ltp":1.04,"tv":0.91,"id":5995},{"batb":[[0,1.55,15.56],[1,1.54,11],[2,1.5,20]],"ltp":1.13,"tv":6.91,"id":2120},{"batb":[[0,1.43,19.91],[1,1.42,6.19],[2,1.41,55.37]],"ltp":0.0,"tv":0.0,"id":60443}]}]}
{"op":"mcm","clk":"11876920382","pt":1723988065139,"mc":[{"id":"1.231804628","rc":[{"batb":[[0,1.54,12],[1,1.5,20],[2,1.41,11.93]],"ltp":1.04,"tv":0.91,"id":5995},{"batb":[[0,1.54,11],[1,1.5,20],[2,1.4,9.37]],"ltp":1.13,"tv":6.91,"id":2120},{"batb":[[0,1.42,6.19],[1,1.41,55.37],[2,1.35,57.14]],"ltp":0.0,"tv":0.0,"id":60443}]}]}
{"op":"mcm","clk":"11876943973","pt":1723988220976,"mc":[{"id":"1.231804628","rc":[{"batb":[[0,1.55,15.56],[1,1.54,12],[2,1.5,20]],"ltp":1.04,"tv":0.91,"id":5995},{"batb":[[0,1.55,15.56],[1,1.54,11],[2,1.5,20]],"ltp":1.13,"tv":6.91,"id":2120},{"batb":[[0,1.43,19.91],[1,1.42,6.19],[2,1.41,55.37]],"ltp":0.0,"tv":0.0,"id":60443}]}]}
{"op":"mcm","clk":"11876988693","pt":1723988508943,"mc":[{"id":"1.231804628","rc":[{"batb":[[0,1.44,55.37],[1,1.43,19.91],[2,1.42,6.19]],"ltp":0.0,"tv":0.0,"id":60443}]}]}
{"op":"mcm","clk":"11877023815","pt":1723988647846,"mc":[{"id":"1.231804628","rc":[{"batb":[[0,1.45,6.19],[1,1.44,55.37],[2,1.43,19.91]],"ltp":0.0,"tv":0.0,"id":60443}]}]}
{"op":"mcm","clk":"11877238046","pt":1723990021416,"mc":[{"id":"1.231804628","rc":[{"batb":[[0,1.54,12],[1,1.5,20],[2,1.3,66.67]],"ltp":1.04,"tv":0.91,"id":5995},{"batb":[[0,1.54,11],[1,1.5,20],[2,1.3,66.67]],"ltp":1.13,"tv":6.91,"id":2120}]}]}
{"op":"mcm","clk":"11877238210","pt":1723990022101,"mc":[{"id":"1.231804628","rc":[{"batb":[[2,1.35,57.14]],"ltp":0.0,"tv":0.0,"id":60443}]}]}
{"op":"mcm","clk":"11877261337","pt":1723990138692,"mc":[{"id":"1.231804628","rc":[{"batb":[[0,1.55,15.56],[1,1.54,12],[2,1.5,20]],"ltp":1.04,"tv":0.91,"id":5995},{"batb":[[0,1.55,15.56],[1,1.54,11],[2,1.5,20]],"ltp":1.13,"tv":6.91,"id":2120},{"batb":[[0,1.46,18.61],[1,1.45,6.19],[2,1.44,55.37]],"ltp":0.0,"tv":0.0,"id":60443}]}]}
{"op":"mcm","clk":"11877573175","pt":1723991939307,"mc":[{"id":"1.231804628","rc":[{"batb":[[0,1.54,12],[1,1.5,20],[2,1.3,66.67]],"ltp":1.04,"tv":0.91,"id":5995},{"batb":[[0,1.54,11],[1,1.5,20],[2,1.3,66.67]],"ltp":1.13,"tv":6.91,"id":2120},{"batb":[[0,1.45,6.19],[1,1.44,55.37],[2,1.35,57.14]],"ltp":0.0,"tv":0.0,"id":60443}]}]}
{"op":"mcm","clk":"11877589282","pt":1723992038444,"mc":[{"id":"1.231804628","rc":[{"batb":[[0,1.55,15.56],[1,1.54,12],[2,1.5,20]],"ltp":1.04,"tv":0.91,"id":5995},{"batb":[[0,1.55,15.56],[1,1.54,11],[2,1.5,20]],"ltp":1.13,"tv":6.91,"id":2120},{"batb":[[0,1.46,18.61],[1,1.45,6.19],[2,1.44,55.37]],"ltp":0.0,"tv":0.0,"id":60443}]}]}
{"op":"mcm","clk":"11877842489","pt":1723993839278,"mc":[{"id":"1.231804628","rc":[{"batb":[[0,1.54,12],[1,1.5,20],[2,1.3,66.67]],"ltp":1.04,"tv":0.91,"id":5995},{"batb":[[0,1.54,11],[1,1.5,20],[2,1.3,66.67]],"ltp":1.13,"tv":6.91,"id":2120},{"batb":[[0,1.45,6.19],[1,1.44,55.37],[2,1.35,57.14]],"ltp":0.0,"tv":0.0,"id":60443}]}]}
{"op":"mcm","clk":"11877857725","pt":1723993932194,"mc":[{"id":"1.231804628","rc":[{"batb":[[0,1.55,15.56],[1,1.54,12],[2,1.5,20]],"ltp":1.04,"tv":0.91,"id":5995},{"batb":[[0,1.55,15.56],[1,1.54,11],[2,1.5,20]],"ltp":1.13,"tv":6.91,"id":2120},{"batb":[[0,1.46,18.61],[1,1.45,6.19],[2,1.44,55.37]],"ltp":0.0,"tv":0.0,"id":60443}]}]}
{"op":"mcm","clk":"11878152009","pt":1723995733037,"mc":[{"id":"1.231804628","rc":[{"batb":[[0,1.54,12],[1,1.5,20],[2,1.3,66.67]],"ltp":1.04,"tv":0.91,"id":5995},{"batb":[[0,1.54,11],[1,1.5,20],[2,1.3,66.67]],"ltp":1.13,"tv":6.91,"id":2120},{"batb":[[0,1.45,6.19],[1,1.44,55.37],[2,1.35,57.14]],"ltp":0.0,"tv":0.0,"id":60443}]}]}
{"op":"mcm","clk":"11878164738","pt":1723995811924,"mc":[{"id":"1.231804628","rc":[{"batb":[[0,1.55,15.56],[1,1.54,12],[2,1.5,20]],"ltp":1.04,"tv":0.91,"id":5995},{"batb":[[0,1.55,15.56],[1,1.54,11],[2,1.5,20]],"ltp":1.13,"tv":6.91,"id":2120},{"batb":[[0,1.46,18.61],[1,1.45,6.19],[2,1.44,55.37]],"ltp":0.0,"tv":0.0,"id":60443}]}]}
{"op":"mcm","clk":"11878400854","pt":1723997612381,"mc":[{"id":"1.231804628","rc":[{"batb":[[0,1.54,11],[1,1.5,20],[2,1.3,66.67]],"ltp":1.13,"tv":6.91,"id":2120}]}]}
{"op":"mcm","clk":"11878400899","pt":1723997612808,"mc":[{"id":"1.231804628","rc":[{"batb":[[0,1.54,12],[1,1.5,20],[2,1.3,66.67]],"ltp":1.04,"tv":0.91,"id":5995},{"batb":[[0,1.45,6.19],[1,1.44,55.37],[2,1.35,57.14]],"ltp":0.0,"tv":0.0,"id":60443}]}]}
{"op":"mcm","clk":"11878405357","pt":1723997648832,"mc":[{"id":"1.231804628","rc":[{"batb":[[0,1.55,15.56],[1,1.54,12],[2,1.5,20]],"ltp":1.04,"tv":0.91,"id":5995},{"batb":[[0,1.55,15.56],[1,1.54,11],[2,1.5,20]],"ltp":1.13,"tv":6.91,"id":2120},{"batb":[[0,1.46,18.61],[1,1.45,6.19],[2,1.44,55.37]],"ltp":0.0,"tv":0.0,"id":60443}]}]}
{"op":"mcm","clk":"11878643518","pt":1723999450298,"mc":[{"id":"1.231804628","rc":[{"batb":[[0,1.54,12],[1,1.5,20],[2,1.3,66.67]],"ltp":1.04,"tv":0.91,"id":5995},{"batb":[[0,1.54,11],[1,1.5,20],[2,1.3,66.67]],"ltp":1.13,"tv":6.91,"id":2120},{"batb":[[0,1.45,6.19],[1,1.44,55.37],[2,1.35,57.14]],"ltp":0.0,"tv":0.0,"id":60443}]}]}
{"op":"mcm","clk":"11878665701","pt":1723999590259,"mc":[{"id":"1.231804628","rc":[{"batb":[[0,1.55,15.56],[1,1.54,12],[2,1.5,20]],"ltp":1.04,"tv":0.91,"id":5995},{"batb":[[0,1.55,15.56],[1,1.54,11],[2,1.5,20]],"ltp":1.13,"tv":6.91,"id":2120},{"batb":[[0,1.46,18.61],[1,1.45,6.19],[2,1.44,55.37]],"ltp":0.0,"tv":0.0,"id":60443}]}]}
{"op":"mcm","clk":"11878942042","pt":1724001390491,"mc":[{"id":"1.231804628","rc":[{"batb":[[0,1.45,6.19],[1,1.44,55.37],[2,1.35,57.14]],"ltp":0.0,"tv":0.0,"id":60443}]}]}
{"op":"mcm","clk":"11878942107","pt":1724001390926,"mc":[{"id":"1.231804628","rc":[{"batb":[[0,1.54,12],[1,1.5,20],[2,1.3,66.67]],"ltp":1.04,"tv":0.91,"id":5995},{"batb":[[0,1.54,11],[1,1.5,20],[2,1.3,66.67]],"ltp":1.13,"tv":6.91,"id":2120}]}]}
{"op":"mcm","clk":"11878950249","pt":1724001441596,"mc":[{"id":"1.231804628","rc":[{"batb":[[0,1.55,15.56],[1,1.54,12],[2,1.5,20]],"ltp":1.04,"tv":0.91,"id":5995},{"batb":[[0,1.55,15.56],[1,1.54,11],[2,1.5,20]],"ltp":1.13,"tv":6.91,"id":2120},{"batb":[[0,1.46,18.61],[1,1.45,6.19],[2,1.44,55.37]],"ltp":0.0,"tv":0.0,"id":60443}]}]}
{"op":"mcm","clk":"11879227960","pt":1724003242352,"mc":[{"id":"1.231804628","rc":[{"batb":[[0,1.54,12],[1,1.5,20],[2,1.3,66.67]],"ltp":1.04,"tv":0.91,"id":5995},{"batb":[[0,1.54,11],[1,1.5,20],[2,1.3,66.67]],"ltp":1.13,"tv":6.91,"id":2120},{"batb":[[0,1.45,6.19],[1,1.44,55.37],[2,1.35,57.14]],"ltp":0.0,"tv":0.0,"id":60443}]}]}
{"op":"mcm","clk":"11879243628","pt":1724003348020,"mc":[{"id":"1.231804628","rc":[{"batb":[[0,1.55,15.56],[1,1.54,12],[2,1.5,20]],"ltp":1.04,"tv":0.91,"id":5995},{"batb":[[0,1.55,15.56],[1,1.54,11],[2,1.5,20]],"ltp":1.13,"tv":6.91,"id":2120},{"batb":[[0,1.46,18.61],[1,1.45,6.19],[2,1.44,55.37]],"ltp":0.0,"tv":0.0,"id":60443}]}]}
{"op":"mcm","clk":"11879552296","pt":1724005148501,"mc":[{"id":"1.231804628","rc":[{"batb":[[0,1.54,12],[1,1.5,20],[2,1.3,66.67]],"ltp":1.04,"tv":0.91,"id":5995},{"batb":[[0,1.45,6.19],[1,1.44,55.37],[2,1.35,57.14]],"ltp":0.0,"tv":0.0,"id":60443}]}]}
{"op":"mcm","clk":"11879552341","pt":1724005148666,"mc":[{"id":"1.231804628","rc":[{"batb":[[0,1.54,11],[1,1.5,20],[2,1.3,66.67]],"ltp":1.13,"tv":6.91,"id":2120}]}]}
{"op":"mcm","clk":"11879557685","pt":1724005174411,"mc":[{"id":"1.231804628","rc":[{"batb":[[0,1.55,15.56],[1,1.54,12],[2,1.5,20]],"ltp":1.04,"tv":0.91,"id":5995},{"batb":[[0,1.55,15.56],[1,1.54,11],[2,1.5,20]],"ltp":1.13,"tv":6.91,"id":2120},{"batb":[[0,1.46,18.61],[1,1.45,6.19],[2,1.44,55.37]],"ltp":0.0,"tv":0.0,"id":60443}]}]}
{"op":"mcm","clk":"11879922014","pt":1724006975280,"mc":[{"id":"1.231804628","rc":[{"batb":[[0,1.54,12],[1,1.5,20],[2,1.3,66.67]],"ltp":1.04,"tv":0.91,"id":5995},{"batb":[[0,1.54,11],[1,1.5,20],[2,1.3,66.67]],"ltp":1.13,"tv":6.91,"id":2120},{"batb":[[0,1.45,6.19],[1,1.44,55.37],[2,1.35,57.14]],"ltp":0.0,"tv":0.0,"id":60443}]}]}
{"op":"mcm","clk":"11879935736","pt":1724007056316,"mc":[{"id":"1.231804628","rc":[{"batb":[[0,1.55,15.56],[1,1.54,12],[2,1.5,20]],"ltp":1.04,"tv":0.91,"id":5995},{"batb":[[0,1.55,15.56],[1,1.54,11],[2,1.5,20]],"ltp":1.13,"tv":6.91,"id":2120},{"batb":[[0,1.46,18.61],[1,1.45,6.19],[2,1.44,55.37]],"ltp":0.0,"tv":0.0,"id":60443}]}]}
{"op":"mcm","clk":"11880272926","pt":1724008857066,"mc":[{"id":"1.231804628","rc":[{"batb":[[0,1.54,12],[1,1.5,20],[2,1.09,222.22]],"ltp":1.04,"tv":0.91,"id":5995},{"batb":[[0,1.54,11],[1,1.5,20],[2,1.09,222.22]],"ltp":1.13,"tv":6.91,"id":2120},{"batb":[[0,1.45,6.19],[1,1.44,55.37],[2,1.3,20]],"ltp":0.0,"tv":0.0,"id":60443}]}]}
{"op":"mcm","clk":"11880288289","pt":1724008937729,"mc":[{"id":"1.231804628","rc":[{"batb":[[0,1.55,15.56],[1,1.54,12],[2,1.5,20]],"ltp":1.04,"tv":0.91,"id":5995},{"batb":[[0,1.55,15.56],[1,1.54,11],[2,1.5,20]],"ltp":1.13,"tv":6.91,"id":2120},{"batb":[[0,1.46,18.61],[1,1.45,6.19],[2,1.44,55.37]],"ltp":0.0,"tv":0.0,"id":60443}]}]}
{"op":"mcm","clk":"11880354399","pt":1724009293656,"mc":[{"id":"1.231804628","rc":[{"batb":[[1,1.44,55.37],[2,1.3,20]],"ltp":0.0,"tv":0.0,"id":60443}]}]}
{"op":"mcm","clk":"11880647095","pt":1724010738361,"mc":[{"id":"1.231804628","rc":[{"batb":[[0,1.54,12],[1,1.5,20],[2,1.09,222.22]],"ltp":1.04,"tv":0.91,"id":5995},{"batb":[[0,1.54,11],[1,1.5,20],[2,1.09,222.22]],"ltp":1.13,"tv":6.91,"id":2120},{"batb":[[0,1.44,55.37],[1,1.3,20],[2,1.09,222.22]],"ltp":0.0,"tv":0.0,"id":60443}]}]}
{"op":"mcm","clk":"11880656842","pt":1724010794435,"mc":[{"id":"1.231804628","rc":[{"batb":[[0,1.55,15.56],[1,1.54,12],[2,1.5,20]],"ltp":1.04,"tv":0.91,"id":5995},{"batb":[[0,1.55,15.56],[1,1.54,11],[2,1.5,20]],"ltp":1.13,"tv":6.91,"id":2120},{"batb":[[0,1.45,19.02],[1,1.44,55.37],[2,1.3,20]],"ltp":0.0,"tv":0.0,"id":60443}]}]}
{"op":"mcm","clk":"11880947199","pt":1724012595090,"mc":[{"id":"1.231804628","rc":[{"batb":[[0,1.54,12],[1,1.5,20],[2,1.09,222.22]],"batl":[[0,95,5.85]],"ltp":1.04,"tv":0.91,"id":5995},{"batb":[[0,1.54,11],[1,1.5,20],[2,1.09,222.22]],"batl":[[0,95,5.85]],"ltp":1.13,"tv":6.91,"id":2120},{"batb":[[0,1.44,55.44],[1,1.3,20],[2,1.09,222.22]],"batl":[[0,95,5.85]],"ltp":0.0,"tv":0.0,"id":60443}]}]}
{"op":"mcm","clk":"11880960938","pt":1724012713894,"mc":[{"id":"1.231804628","rc":[{"batb":[[0,1.55,15.59],[1,1.54,12],[2,1.5,20]],"ltp":1.04,"tv":0.91,"id":5995},{"batb":[[0,1.55,15.59],[1,1.54,11],[2,1.5,20]],"ltp":1.13,"tv":6.91,"id":2120},{"batb":[[0,1.45,19.06],[1,1.44,55.44],[2,1.3,20]],"ltp":0.0,"tv":0.0,"id":60443}]}]}
{"op":"mcm","clk":"11881043130","pt":1724013445898,"mc":[{"id":"1.231804628","rc":[{"batb":[[0,1.56,12],[1,1.55,15.59]],"ltp":1.04,"tv":0.91,"id":5995},{"batb":[[0,1.56,11],[1,1.55,15.59]],"ltp":1.13,"tv":6.91,"id":2120}]}]}
{"op":"mcm","clk":"11881161852","pt":1724014514508,"mc":[{"id":"1.231804628","rc":[{"batb":[[1,1.5,20],[2,1.09,222.22]],"ltp":1.04,"tv":0.91,"id":5995},{"batb":[[1,1.5,20],[2,1.09,222.22]],"ltp":1.13,"tv":6.91,"id":2120},{"batb":[[0,1.44,55.44],[1,1.3,20],[2,1.09,222.22]],"ltp":0.0,"tv":0.0,"id":60443}]}]}
{"op":"mcm","clk":"11881170228","pt":1724014618444,"mc":[{"id":"1.231804628","rc":[{"batb":[[0,1.57,15.04],[1,1.56,12],[2,1.5,20]],"ltp":1.04,"tv":0.91,"id":5995},{"batb":[[0,1.57,15.04],[1,1.56,11],[2,1.5,20]],"ltp":1.13,"tv":6.91,"id":2120},{"batb":[[0,1.45,19.06],[1,1.44,55.44],[2,1.3,20]],"ltp":0.0,"tv":0.0,"id":60443}]}]}
{"op":"mcm","clk":"11881247528","pt":1724015574879,"mc":[{"id":"1.231804628","rc":[{"batb":[[0,1.57,15.03]],"ltp":1.04,"tv":0.91,"id":5995},{"trd":[[1.04,2.37],[1.13,2.55]],"batb":[[0,1.57,15.03]],"ltp":1.13,"tv":6.91,"id":2120},{"batb":[[0,1.45,19.04],[1,1.44,55.41]],"ltp":0.0,"tv":0.0,"id":60443}],"tv":7.83}]}
{"op":"mcm","clk":"11881328237","pt":1724016420410,"mc":[{"id":"1.231804628","rc":[{"batb":[[0,1.56,12],[1,1.5,20],[2,1.09,222.22]],"ltp":1.04,"tv":0.91,"id":5995},{"batb":[[0,1.56,11],[1,1.5,20],[2,1.09,222.22]],"ltp":1.13,"tv":6.91,"id":2120},{"batb":[[0,1.44,55.41],[1,1.3,20],[2,1.09,222.22]],"ltp":0.0,"tv":0.0,"id":60443}]}]}
{"op":"mcm","clk":"11881337034","pt":1724016533137,"mc":[{"id":"1.231804628","rc":[{"batb":[[0,1.57,15.03],[1,1.56,12],[2,1.5,20]],"ltp":1.04,"tv":0.91,"id":5995},{"batb":[[0,1.57,15.03],[1,1.56,11],[2,1.5,20]],"ltp":1.13,"tv":6.91,"id":2120},{"batb":[[0,1.45,19.04],[1,1.44,55.41],[2,1.3,20]],"ltp":0.0,"tv":0.0,"id":60443}]}]}
{"op":"mcm","clk":"11881486646","pt":1724018336516,"mc":[{"id":"1.231804628","rc":[{"batb":[[0,1.56,11],[1,1.5,20],[2,1.09,222.22]],"ltp":1.13,"tv":6.91,"id":2120}]}]}
{"op":"mcm","clk":"11881486675","pt":1724018336928,"mc":[{"id":"1.231804628","rc":[{"batb":[[0,1.56,12],[1,1.5,20],[2,1.09,222.22]],"ltp":1.04,"tv":0.91,"id":5995},{"batb":[[0,1.44,55.41],[1,1.3,20],[2,1.09,222.22]],"ltp":0.0,"tv":0.0,"id":60443}]}]}
{"op":"mcm","clk":"11881490452","pt":1724018385394,"mc":[{"id":"1.231804628","rc":[{"batb":[[0,1.57,15.03],[1,1.56,12],[2,1.5,20]],"ltp":1.04,"tv":0.91,"id":5995},{"batb":[[0,1.57,15.03],[1,1.56,11],[2,1.5,20]],"ltp":1.13,"tv":6.91,"id":2120},{"batb":[[0,1.45,19.04],[1,1.44,55.41],[2,1.3,20]],"ltp":0.0,"tv":0.0,"id":60443}]}]}
{"op":"mcm","clk":"11881624532","pt":1724020185948,"mc":[{"id":"1.231804628","rc":[{"batb":[[0,1.56,12],[1,1.5,20],[2,1.09,222.22]],"ltp":1.04,"tv":0.91,"id":5995},{"batb":[[0,1.56,11],[1,1.5,20],[2,1.09,222.22]],"ltp":1.13,"tv":6.91,"id":2120},{"batb":[[0,1.44,55.37],[1,1.3,20],[2,1.09,222.22]],"ltp":0.0,"tv":0.0,"id":60443}]}]}
{"op":"mcm","clk":"11881626215","pt":1724020211411,"mc":[{"id":"1.231804628","rc":[{"batb":[[0,1.57,15.02],[1,1.56,12],[2,1.5,20]],"ltp":1.04,"tv":0.91,"id":5995},{"batb":[[0,1.57,15.02],[1,1.56,11],[2,1.5,20]],"ltp":1.13,"tv":6.91,"id":2120},{"batb":[[0,1.45,19.03],[1,1.44,55.37],[2,1.3,20]],"ltp":0.0,"tv":0.0,"id":60443}]}]}
{"op":"mcm","clk":"11881752025","pt":1724022013502,"mc":[{"id":"1.231804628","rc":[{"batb":[[0,1.56,12],[1,1.5,20],[2,1.09,222.22]],"ltp":1.04,"tv":0.91,"id":5995},{"batb":[[0,1.56,11],[1,1.5,20],[2,1.09,222.22]],"ltp":1.13,"tv":6.91,"id":2120},{"batb":[[1,1.44,55.37]],"ltp":0.0,"tv":0.0,"id":60443}]}]}
{"op":"mcm","clk":"11881752045","pt":1724022013711,"mc":[{"id":"1.231804628","rc":[{"batb":[[0,1.44,55.37],[1,1.3,20],[2,1.09,222.22]],"ltp":0.0,"tv":0.0,"id":60443}]}]}
{"op":"mcm","clk":"11881752439","pt":1724022019019,"mc":[{"id":"1.231804628","rc":[{"batb":[[0,1.57,15.02],[1,1.56,12],[2,1.5,20]],"ltp":1.04,"tv":0.91,"id":5995},{"batb":[[0,1.57,15.02],[1,1.56,11],[2,1.5,20]],"ltp":1.13,"tv":6.91,"id":2120},{"batb":[[0,1.45,19.03],[1,1.44,55.37],[2,1.3,20]],"ltp":0.0,"tv":0.0,"id":60443}]}]}
{"op":"mcm","clk":"11881883617","pt":1724023819461,"mc":[{"id":"1.231804628","rc":[{"batb":[[0,1.56,12],[1,1.5,20],[2,1.09,222.22]],"ltp":1.04,"tv":0.91,"id":5995},{"batb":[[0,1.44,55.37],[1,1.3,20],[2,1.09,222.22]],"ltp":0.0,"tv":0.0,"id":60443}]}]}
{"op":"mcm","clk":"11881883635","pt":1724023819679,"mc":[{"id":"1.231804628","rc":[{"batb":[[0,1.56,11],[1,1.5,20],[2,1.09,222.22]],"ltp":1.13,"tv":6.91,"id":2120}]}]}
{"op":"mcm","clk":"11881890171","pt":1724023913364,"mc":[{"id":"1.231804628","rc":[{"batb":[[0,1.57,15.02],[1,1.56,12],[2,1.5,20]],"ltp":1.04,"tv":0.91,"id":5995},{"batb":[[0,1.57,15.02],[1,1.56,11],[2,1.5,20]],"ltp":1.13,"tv":6.91,"id":2120},{"batb":[[0,1.45,19.03],[1,1.44,55.37],[2,1.3,20]],"ltp":0.0,"tv":0.0,"id":60443}]}]}
{"op":"mcm","clk":"11881993942","pt":1724025715452,"mc":[{"id":"1.231804628","rc":[{"batb":[[0,1.56,12],[1,1.5,20],[2,1.09,222.22]],"ltp":1.04,"tv":0.91,"id":5995},{"batb":[[0,1.56,11],[1,1.5,20],[2,1.09,222.22]],"ltp":1.13,"tv":6.91,"id":2120},{"batb":[[0,1.45,19.02],[1,1.44,55.36]],"ltp":0.0,"tv":0.0,"id":60443}],"tv":7.83}]}
{"op":"mcm","clk":"11881993959","pt":1724025715760,"mc":[{"id":"1.231804628","rc":[{"batb":[[0,1.44,55.36],[1,1.3,20],[2,1.09,222.22]],"ltp":0.0,"tv":0.0,"id":60443}]}]}
{"op":"mcm","clk":"11881996654","pt":1724025767398,"mc":[{"id":"1.231804628","rc":[{"batb":[[0,1.57,15.02],[1,1.56,12],[2,1.5,20]],"ltp":1.04,"tv":0.91,"id":5995},{"batb":[[0,1.57,15.02],[1,1.56,11],[2,1.5,20]],"ltp":1.13,"tv":6.91,"id":2120},{"batb":[[0,1.45,19.02],[1,1.44,55.36],[2,1.3,20]],"ltp":0.0,"tv":0.0,"id":60443}]}]}
{"op":"mcm","clk":"11882109276","pt":1724027568026,"mc":[{"id":"1.231804628","rc":[{"batb":[[0,1.56,12],[1,1.5,20],[2,1.09,222.22]],"ltp":1.04,"tv":0.91,"id":5995},{"batb":[[0,1.56,11],[1,1.5,20],[2,1.09,222.22]],"ltp":1.13,"tv":6.91,"id":2120},{"batb":[[0,1.44,55.36],[1,1.3,20],[2,1.09,222.22]],"ltp":0.0,"tv":0.0,"id":60443}]}]}
{"op":"mcm","clk":"11882111488","pt":1724027603760,"mc":[{"id":"1.231804628","rc":[{"batb":[[0,1.57,15.02],[1,1.56,12],[2,1.5,20]],"ltp":1.04,"tv":0.91,"id":5995},{"batb":[[0,1.57,15.02],[1,1.56,11],[2,1.5,20]],"ltp":1.13,"tv":6.91,"id":2120},{"batb":[[0,1.45,19.02],[1,1.44,55.36],[2,1.3,20]],"ltp":0.0,"tv":0.0,"id":60443}]}]}
{"op":"mcm","clk":"11882208232","pt":1724029404405,"mc":[{"id":"1.231804628","rc":[{"batb":[[0,1.56,12],[1,1.5,20],[2,1.09,222.22]],"ltp":1.04,"tv":0.91,"id":5995},{"batb":[[0,1.56,11],[1,1.5,20],[2,1.09,222.22]],"ltp":1.13,"tv":6.91,"id":2120},{"batb":[[0,1.44,55.39],[1,1.3,20],[2,1.09,222.22]],"ltp":0.0,"tv":0.0,"id":60443}]}]}
{"op":"mcm","clk":"11882209367","pt":1724029426350,"mc":[{"id":"1.231804628","rc":[{"batb":[[0,1.57,15.03],[1,1.56,12],[2,1.5,20]],"ltp":1.04,"tv":0.91,"id":5995},{"batb":[[0,1.57,15.03],[1,1.56,11],[2,1.5,20]],"ltp":1.13,"tv":6.91,"id":2120},{"batb":[[0,1.45,19.04],[1,1.44,55.39],[2,1.3,20]],"ltp":0.0,"tv":0.0,"id":60443}]}]}
{"op":"mcm","clk":"11882288405","pt":1724031226946,"mc":[{"id":"1.231804628","rc":[{"batb":[[0,1.56,12],[1,1.5,20],[2,1.09,222.22]],"ltp":1.04,"tv":0.91,"id":5995},{"batb":[[0,1.56,11],[1,1.5,20],[2,1.09,222.22]],"ltp":1.13,"tv":6.91,"id":2120},{"batb":[[0,1.44,55.39],[1,1.3,20],[2,1.09,222.22]],"ltp":0.0,"tv":0.0,"id":60443}]}]}
{"op":"mcm","clk":"11882293564","pt":1724031340432,"mc":[{"id":"1.231804628","rc":[{"batb":[[0,1.57,15.03],[1,1.56,12],[2,1.5,20]],"ltp":1.04,"tv":0.91,"id":5995},{"batb":[[0,1.57,15.03],[1,1.56,11],[2,1.5,20]],"ltp":1.13,"tv":6.91,"id":2120},{"batb":[[0,1.45,19.04],[1,1.44,55.39],[2,1.3,20]],"ltp":0.0,"tv":0.0,"id":60443}]}]}
{"op":"mcm","clk":"11882369553","pt":1724033140680,"mc":[{"id":"1.231804628","rc":[{"batb":[[0,1.57,15.02]],"ltp":1.04,"tv":0.91,"id":5995},{"batb":[[0,1.56,11],[1,1.5,20],[2,1.09,222.22]],"ltp":1.13,"tv":6.91,"id":2120},{"batb":[[0,1.45,19.03],[1,1.44,55.36]],"ltp":0.0,"tv":0.0,"id":60443}]}]}
{"op":"mcm","clk":"11882369592","pt":1724033141760,"mc":[{"id":"1.231804628","rc":[{"batb":[[0,1.56,12],[1,1.5,20],[2,1.09,222.22]],"ltp":1.04,"tv":0.91,"id":5995},{"batb":[[0,1.44,55.36],[1,1.3,20],[2,1.09,222.22]],"ltp":0.0,"tv":0.0,"id":60443}]}]}
{"op":"mcm","clk":"11882372955","pt":1724033236910,"mc":[{"id":"1.231804628","rc":[{"batb":[[0,1.57,15.02],[1,1.56,12],[2,1.5,20]],"ltp":1.04,"tv":0.91,"id":5995},{"batb":[[0,1.57,15.02],[1,1.56,11],[2,1.5,20]],"ltp":1.13,"tv":6.91,"id":2120},{"batb":[[0,1.45,19.03],[1,1.44,55.36],[2,1.3,20]],"ltp":0.0,"tv":0.0,"id":60443}]}]}
{"op":"mcm","clk":"11882443144","pt":1724035037516,"mc":[{"id":"1.231804628","rc":[{"batb":[[0,1.56,12],[1,1.5,20],[2,1.09,222.22]],"ltp":1.04,"tv":0.91,"id":5995},{"batb":[[0,1.56,11],[1,1.5,20],[2,1.09,222.22]],"ltp":1.13,"tv":6.91,"id":2120},{"batb":[[0,1.44,55.36],[1,1.3,20],[2,1.09,222.22]],"ltp":0.0,"tv":0.0,"id":60443}]}]}
{"op":"mcm","clk":"11882446138","pt":1724035130819,"mc":[{"id":"1.231804628","rc":[{"batb":[[0,1.57,15.02],[1,1.56,12],[2,1.5,20]],"ltp":1.04,"tv":0.91,"id":5995},{"batb":[[0,1.57,15.02],[1,1.56,11],[2,1.5,20]],"ltp":1.13,"tv":6.91,"id":2120},{"batb":[[0,1.45,19.03],[1,1.44,55.36],[2,1.3,20]],"ltp":0.0,"tv":0.0,"id":60443}]}]}
{"op":"mcm","clk":"11882501134","pt":1724036931436,"mc":[{"id":"1.231804628","rc":[{"batb":[[0,1.56,12],[1,1.5,20],[2,1.09,222.22]],"ltp":1.04,"tv":0.91,"id":5995},{"batb":[[0,1.56,11],[1,1.5,20],[2,1.09,222.22]],"ltp":1.13,"tv":6.91,"id":2120},{"batb":[[0,1.44,55.35],[1,1.3,20],[2,1.09,222.22]],"ltp":0.0,"tv":0.0,"id":60443}]}]}
{"op":"mcm","clk":"11882503018","pt":1724037011630,"mc":[{"id":"1.231804628","rc":[{"batb":[[0,1.57,15.02],[1,1.56,12],[2,1.5,20]],"ltp":1.04,"tv":0.91,"id":5995},{"batb":[[0,1.57,15.02],[1,1.56,11],[2,1.5,20]],"ltp":1.13,"tv":6.91,"id":2120},{"batb":[[0,1.45,19.02],[1,1.44,55.35],[2,1.3,20]],"ltp":0.0,"tv":0.0,"id":60443}]}]}
{"op":"mcm","clk":"11882559167","pt":1724038812246,"mc":[{"id":"1.231804628","rc":[{"batb":[[0,1.56,12],[1,1.5,20],[2,1.09,222.22]],"ltp":1.04,"tv":0.91,"id":5995},{"batb":[[0,1.56,11],[1,1.5,20],[2,1.09,222.22]],"ltp":1.13,"tv":6.91,"id":2120},{"batb":[[0,1.44,55.35],[1,1.3,20],[2,1.09,222.22]],"ltp":0.0,"tv":0.0,"id":60443}]}]}
{"op":"mcm","clk":"11882561086","pt":1724038875253,"mc":[{"id":"1.231804628","rc":[{"batb":[[0,1.57,15.02],[1,1.56,12],[2,1.5,20]],"ltp":1.04,"tv":0.91,"id":5995},{"batb":[[0,1.57,15.02],[1,1.56,11],[2,1.5,20]],"ltp":1.13,"tv":6.91,"id":2120},{"batb":[[0,1.45,19.02],[1,1.44,55.35],[2,1.3,20]],"ltp":0.0,"tv":0.0,"id":60443}]}]}
{"op":"mcm","clk":"11882605174","pt":1724040675506,"mc":[{"id":"1.231804628","rc":[{"batb":[[0,1.57,15.03]],"ltp":1.04,"tv":0.91,"id":5995},{"batb":[[0,1.56,11],[1,1.5,20],[2,1.09,222.22]],"ltp":1.13,"tv":6.91,"id":2120},{"batb":[[0,1.45,19.04],[1,1.44,55.39]],"ltp":0.0,"tv":0.0,"id":60443}]}]}
{"op":"mcm","clk":"11882605178","pt":1724040675909,"mc":[{"id":"1.231804628","rc":[{"batb":[[0,1.56,12],[1,1.5,20],[2,1.09,222.22]],"ltp":1.04,"tv":0.91,"id":5995},{"batb":[[0,1.44,55.39],[1,1.3,20],[2,1.09,222.22]],"ltp":0.0,"tv":0.0,"id":60443}]}]}
{"op":"mcm","clk":"11882606121","pt":1724040735698,"mc":[{"id":"1.231804628","rc":[{"batb":[[0,1.57,15.03],[1,1.56,12],[2,1.5,20]],"ltp":1.04,"tv":0.91,"id":5995},{"batb":[[0,1.57,15.03],[1,1.56,11],[2,1.5,20]],"ltp":1.13,"tv":6.91,"id":2120},{"batb":[[0,1.45,19.04],[1,1.44,55.39],[2,1.3,20]],"ltp":0.0,"tv":0.0,"id":60443}]}]}
{"op":"mcm","clk":"11882638405","pt":1724042536295,"mc":[{"id":"1.231804628","rc":[{"batb":[[0,1.56,12],[1,1.5,20],[2,1.09,222.22]],"ltp":1.04,"tv":0.91,"id":5995},{"batb":[[0,1.56,11],[1,1.5,20],[2,1.09,222.22]],"ltp":1.13,"tv":6.91,"id":2120},{"batb":[[0,1.44,55.39],[1,1.3,20],[2,1.09,222.22]],"ltp":0.0,"tv":0.0,"id":60443}]}]}
{"op":"mcm","clk":"11882647749","pt":1724042586088,"mc":[{"id":"1.231804628","rc":[{"batb":[[0,1.57,15.03],[1,1.56,12],[2,1.5,20]],"ltp":1.04,"tv":0.91,"id":5995},{"batb":[[0,1.57,15.03],[1,1.56,11],[2,1.5,20]],"ltp":1.13,"tv":6.91,"id":2120},{"batb":[[0,1.45,19.04],[1,1.44,55.39],[2,1.3,20]],"ltp":0.0,"tv":0.0,"id":60443}]}]}
{"op":"mcm","clk":"11882689784","pt":1724044386457,"mc":[{"id":"1.231804628","rc":[{"batb":[[0,1.57,15.03]],"ltp":1.04,"tv":0.91,"id":5995},{"batb":[[0,1.56,11],[1,1.5,20],[2,1.09,222.22]],"ltp":1.13,"tv":6.91,"id":2120},{"batb":[[0,1.44,55.4],[1,1.3,20],[2,1.09,222.22]],"ltp":0.0,"tv":0.0,"id":60443}]}]}
{"op":"mcm","clk":"11882689788","pt":1724044386556,"mc":[{"id":"1.231804628","rc":[{"batb":[[0,1.56,12],[1,1.5,20],[2,1.09,222.22]],"ltp":1.04,"tv":0.91,"id":5995}]}]}
{"op":"mcm","clk":"11882690917","pt":1724044431372,"mc":[{"id":"1.231804628","rc":[{"batb":[[0,1.57,15.03],[1,1.56,12],[2,1.5,20]],"ltp":1.04,"tv":0.91,"id":5995},{"batb":[[0,1.57,15.03],[1,1.56,11],[2,1.5,20]],"ltp":1.13,"tv":6.91,"id":2120},{"batb":[[0,1.45,19.04],[1,1.44,55.4],[2,1.3,20]],"ltp":0.0,"tv":0.0,"id":60443}]}]}
{"op":"mcm","clk":"11882739362","pt":1724046231517,"mc":[{"id":"1.231804628","rc":[{"batb":[[0,1.56,12],[1,1.5,20],[2,1.09,222.22]],"ltp":1.04,"tv":0.91,"id":5995}]}]}
{"op":"mcm","clk":"11882739379","pt":1724046232028,"mc":[{"id":"1.231804628","rc":[{"batb":[[0,1.56,11],[1,1.5,20],[2,1.09,222.22]],"ltp":1.13,"tv":6.91,"id":2120},{"batb":[[0,1.44,55.4],[1,1.3,20],[2,1.09,222.22]],"ltp":0.0,"tv":0.0,"id":60443}]}]}
{"op":"mcm","clk":"11882740391","pt":1724046272155,"mc":[{"id":"1.231804628","rc":[{"batb":[[0,1.57,15.03],[1,1.56,12],[2,1.5,20]],"ltp":1.04,"tv":0.91,"id":5995},{"batb":[[0,1.57,15.03],[1,1.56,11],[2,1.5,20]],"ltp":1.13,"tv":6.91,"id":2120},{"batb":[[0,1.45,19.04],[1,1.44,55.4],[2,1.3,20]],"ltp":0.0,"tv":0.0,"id":60443}]}]}
{"op":"mcm","clk":"11882782288","pt":1724047974872,"mc":[{"id":"1.231804628","rc":[{"trd":[[1.13,2.55]],"ltp":1.13,"tv":6.91,"id":2120},{"batb":[[1,1.44,55.39]],"ltp":0.0,"tv":0.0,"id":60443}],"tv":7.82}]}
{"op":"mcm","clk":"11882790838","pt":1724048072381,"mc":[{"id":"1.231804628","rc":[{"batb":[[0,1.44,55.39],[1,1.3,20],[2,1.09,222.22]],"ltp":0.0,"tv":0.0,"id":60443}]}]}
{"op":"mcm","clk":"11882790850","pt":1724048072790,"mc":[{"id":"1.231804628","rc":[{"batb":[[0,1.56,12],[1,1.5,20],[2,1.09,222.22]],"ltp":1.04,"tv":0.91,"id":5995},{"batb":[[0,1.56,11],[1,1.5,20],[2,1.09,222.22]],"ltp":1.13,"tv":6.91,"id":2120}]}]}
{"op":"mcm","clk":"11882792092","pt":1724048112331,"mc":[{"id":"1.231804628","rc":[{"batb":[[0,1.57,15.03],[1,1.56,12],[2,1.5,20]],"ltp":1.04,"tv":0.91,"id":5995},{"batb":[[0,1.57,15.03],[1,1.56,11],[2,1.5,20]],"ltp":1.13,"tv":6.91,"id":2120},{"batb":[[0,1.45,19.04],[1,1.44,55.39],[2,1.3,20]],"ltp":0.0,"tv":0.0,"id":60443}]}]}
{"op":"mcm","clk":"11882836518","pt":1724049913055,"mc":[{"id":"1.231804628","rc":[{"batb":[[0,1.56,12],[1,1.5,20],[2,1.09,222.22]],"ltp":1.04,"tv":0.91,"id":5995},{"batb":[[0,1.56,11],[1,1.5,20],[2,1.09,222.22]],"ltp":1.13,"tv":6.91,"id":2120},{"batb":[[0,1.44,55.39],[1,1.3,20],[2,1.09,222.22]],"ltp":0.0,"tv":0.0,"id":60443}]}]}
{"op":"mcm","clk":"11882837755","pt":1724049947997,"mc":[{"id":"1.231804628","rc":[{"batb":[[0,1.57,15.03],[1,1.56,12],[2,1.5,20]],"ltp":1.04,"tv":0.91,"id":5995},{"batb":[[0,1.57,15.03],[1,1.56,11],[2,1.5,20]],"ltp":1.13,"tv":6.91,"id":2120},{"batb":[[0,1.45,19.04],[1,1.44,55.39],[2,1.3,20]],"ltp":0.0,"tv":0.0,"id":60443}]}]}
{"op":"mcm","clk":"11882881749","pt":1724051748428,"mc":[{"id":"1.231804628","rc":[{"batb":[[0,1.56,12],[1,1.5,20],[2,1.09,222.22]],"ltp":1.04,"tv":0.91,"id":5995},{"batb":[[0,1.56,11],[1,1.5,20],[2,1.09,222.22]],"ltp":1.13,"tv":6.91,"id":2120},{"batb":[[0,1.45,19.03],[1,1.44,55.37]],"ltp":0.0,"tv":0.0,"id":60443}]}]}
{"op":"mcm","clk":"11882881765","pt":1724051749197,"mc":[{"id":"1.231804628","rc":[{"batb":[[0,1.44,55.37],[1,1.3,20],[2,1.09,222.22]],"ltp":0.0,"tv":0.0,"id":60443}]}]}
{"op":"mcm","clk":"11882882419","pt":1724051778925,"mc":[{"id":"1.231804628","rc":[{"batb":[[0,1.57,15.02],[1,1.56,12],[2,1.5,20]],"ltp":1.04,"tv":0.91,"id":5995},{"batb":[[0,1.57,15.02],[1,1.56,11],[2,1.5,20]],"ltp":1.13,"tv":6.91,"id":2120},{"batb":[[0,1.45,19.03],[1,1.44,55.37],[2,1.3,20]],"ltp":0.0,"tv":0.0,"id":60443}]}]}
{"op":"mcm","clk":"11882925113","pt":1724053579292,"mc":[{"id":"1.231804628","rc":[{"batb":[[0,1.56,12],[1,1.5,20],[2,1.09,222.22]],"ltp":1.04,"tv":0.91,"id":5995},{"batb":[[0,1.56,11],[1,1.5,20],[2,1.09,222.22]],"ltp":1.13,"tv":6.91,"id":2120}]}]}
{"op":"mcm","clk":"11882925135","pt":1724053580008,"mc":[{"id":"1.231804628","rc":[{"batb":[[0,1.44,55.37],[1,1.3,20],[2,1.09,222.22]],"ltp":0.0,"tv":0.0,"id":60443}]}]}
{"op":"mcm","clk":"11882925642","pt":1724053609144,"mc":[{"id":"1.231804628","rc":[{"batb":[[0,1.57,15.02],[1,1.56,12],[2,1.5,20]],"ltp":1.04,"tv":0.91,"id":5995},{"batb":[[0,1.57,15.02],[1,1.56,11],[2,1.5,20]],"ltp":1.13,"tv":6.91,"id":2120},{"batb":[[0,1.45,19.03],[1,1.44,55.37],[2,1.3,20]],"ltp":0.0,"tv":0.0,"id":60443}]}]}
{"op":"mcm","clk":"11882964249","pt":1724055409378,"mc":[{"id":"1.231804628","rc":[{"batb":[[0,1.56,11],[1,1.5,20],[2,1.09,222.22]],"ltp":1.13,"tv":6.91,"id":2120},{"batb":[[0,1.45,19.03]],"ltp":0.0,"tv":0.0,"id":60443}]}]}
{"op":"mcm","clk":"11882964275","pt":1724055410408,"mc":[{"id":"1.231804628","rc":[{"batb":[[0,1.56,12],[1,1.5,20],[2,1.09,222.22]],"ltp":1.04,"tv":0.91,"id":5995},{"batb":[[0,1.44,55.37],[1,1.3,20],[2,1.09,222.22]],"ltp":0.0,"tv":0.0,"id":60443}]}]}
{"op":"mcm","clk":"11882965032","pt":1724055436101,"mc":[{"id":"1.231804628","rc":[{"batb":[[0,1.57,15.02],[1,1.56,12],[2,1.5,20]],"ltp":1.04,"tv":0.91,"id":5995},{"batb":[[0,1.57,15.02],[1,1.56,11],[2,1.5,20]],"ltp":1.13,"tv":6.91,"id":2120},{"batb":[[0,1.45,19.03],[1,1.44,55.37],[2,1.3,20]],"ltp":0.0,"tv":0.0,"id":60443}]}]}
{"op":"mcm","clk":"11883016314","pt":1724057236385,"mc":[{"id":"1.231804628","rc":[{"batb":[[0,1.56,12],[1,1.5,20],[2,1.09,222.22]],"ltp":1.04,"tv":0.91,"id":5995}]}]}
{"op":"mcm","clk":"11883016338","pt":1724057237254,"mc":[{"id":"1.231804628","rc":[{"batb":[[0,1.56,11],[1,1.5,20],[2,1.09,222.22]],"ltp":1.13,"tv":6.91,"id":2120},{"batb":[[0,1.44,55.37],[1,1.3,20],[2,1.09,222.22]],"ltp":0.0,"tv":0.0,"id":60443}]}]}
{"op":"mcm","clk":"11883016773","pt":1724057252086,"mc":[{"id":"1.231804628","rc":[{"batb":[[0,1.57,15.02],[1,1.56,12],[2,1.5,20]],"ltp":1.04,"tv":0.91,"id":5995},{"batb":[[0,1.57,15.02],[1,1.56,11],[2,1.5,20]],"ltp":1.13,"tv":6.91,"id":2120},{"batb":[[0,1.45,19.03],[1,1.44,55.37],[2,1.3,20]],"ltp":0.0,"tv":0.0,"id":60443}]}]}
{"op":"mcm","clk":"11883085500","pt":1724058774868,"mc":[{"id":"1.231804628","rc":[{"batb":[[0,1.57,15.01]],"ltp":1.04,"tv":0.91,"id":5995},{"batb":[[0,1.57,15.01]],"ltp":1.13,"tv":6.91,"id":2120},{"batb":[[0,1.45,19.01],[1,1.44,55.31]],"ltp":0.0,"tv":0.0,"id":60443}],"tv":7.82}]}
{"op":"mcm","clk":"11883100894","pt":1724059052520,"mc":[{"id":"1.231804628","rc":[{"batb":[[0,1.56,11],[1,1.5,20],[2,1.09,222.22]],"ltp":1.13,"tv":6.91,"id":2120},{"batb":[[0,1.44,55.31],[1,1.3,20],[2,1.09,222.22]],"ltp":0.0,"tv":0.0,"id":60443}]}]}
{"op":"mcm","clk":"11883100901","pt":1724059052726,"mc":[{"id":"1.231804628","rc":[{"batb":[[0,1.56,12],[1,1.5,20],[2,1.09,222.22]],"ltp":1.04,"tv":0.91,"id":5995}]}]}
{"op":"mcm","clk":"11883101538","pt":1724059068468,"mc":[{"id":"1.231804628","rc":[{"batb":[[0,1.57,15.01],[1,1.56,12],[2,1.5,20]],"ltp":1.04,"tv":0.91,"id":5995},{"batb":[[0,1.57,15.01],[1,1.56,11],[2,1.5,20]],"ltp":1.13,"tv":6.91,"id":2120},{"batb":[[0,1.45,19.01],[1,1.44,55.31],[2,1.3,20]],"ltp":0.0,"tv":0.0,"id":60443}]}]}
{"op":"mcm","clk":"11883182964","pt":1724060869406,"mc":[{"id":"1.231804628","rc":[{"batb":[[0,1.56,12],[1,1.5,20],[2,1.09,222.22]],"ltp":1.04,"tv":0.91,"id":5995},{"batb":[[0,1.56,11],[1,1.5,20],[2,1.09,222.22]],"ltp":1.13,"tv":6.91,"id":2120},{"batb":[[0,1.44,55.31],[1,1.3,20],[2,1.09,222.22]],"ltp":0.0,"tv":0.0,"id":60443}]}]}
{"op":"mcm","clk":"11883183247","pt":1724060876333,"mc":[{"id":"1.231804628","rc":[{"batb":[[0,1.57,15.01],[1,1.56,12],[2,1.5,20]],"ltp":1.04,"tv":0.91,"id":5995},{"batb":[[0,1.57,15.01],[1,1.56,11],[2,1.5,20]],"ltp":1.13,"tv":6.91,"id":2120}]}]}
{"op":"mcm","clk":"11883183259","pt":1724060876539,"mc":[{"id":"1.231804628","rc":[{"batb":[[0,1.45,19.01],[1,1.44,55.31],[2,1.3,20]],"ltp":0.0,"tv":0.0,"id":60443}]}]}
{"op":"mcm","clk":"11883266880","pt":1724062677513,"mc":[{"id":"1.231804628","rc":[{"batb":[[0,1.56,12],[1,1.5,20],[2,1.09,222.22]],"ltp":1.04,"tv":0.91,"id":5995},{"batb":[[0,1.56,11],[1,1.5,20],[2,1.09,222.22]],"ltp":1.13,"tv":6.91,"id":2120},{"batb":[[0,1.44,55.33],[1,1.3,20],[2,1.09,222.22]],"ltp":0.0,"tv":0.0,"id":60443}],"tv":7.82}]}
{"op":"mcm","clk":"11883272335","pt":1724062784614,"mc":[{"id":"1.231804628","rc":[{"batb":[[0,1.57,15.01],[1,1.56,12],[2,1.5,20]],"ltp":1.04,"tv":0.91,"id":5995},{"batb":[[0,1.57,15.01],[1,1.56,11],[2,1.5,20]],"ltp":1.13,"tv":6.91,"id":2120},{"batb":[[0,1.45,19.01],[1,1.44,55.33],[2,1.3,20]],"ltp":0.0,"tv":0.0,"id":60443}]}]}
{"op":"mcm","clk":"11883365938","pt":1724064585165,"mc":[{"id":"1.231804628","rc":[{"batb":[[0,1.56,12],[1,1.5,20],[2,1.09,222.22]],"ltp":1.04,"tv":0.91,"id":5995},{"batb":[[0,1.56,11],[1,1.5,20],[2,1.09,222.22]],"ltp":1.13,"tv":6.91,"id":2120},{"batb":[[0,1.44,55.33],[1,1.3,20],[2,1.09,222.22]],"ltp":0.0,"tv":0.0,"id":60443}]}]}
{"op":"mcm","clk":"11883369541","pt":1724064652967,"mc":[{"id":"1.231804628","rc":[{"batb":[[0,1.57,15.01],[1,1.56,12],[2,1.5,20]],"ltp":1.04,"tv":0.91,"id":5995},{"batb":[[0,1.57,15.01],[1,1.56,11],[2,1.5,20]],"ltp":1.13,"tv":6.91,"id":2120},{"batb":[[0,1.45,19.01],[1,1.44,55.33],[2,1.3,20]],"ltp":0.0,"tv":0.0,"id":60443}]}]}
{"op":"mcm","clk":"11883448521","pt":1724066453492,"mc":[{"id":"1.231804628","rc":[{"batb":[[0,1.56,12],[1,1.5,20],[2,1.09,222.22]],"batl":[[0,95,5.85]],"ltp":1.04,"tv":0.91,"id":5995},{"trd":[[1.04,2.37],[1.13,2.55]],"batb":[[0,1.56,11],[1,1.5,20],[2,1.09,222.22]],"batl":[[0,95,5.85]],"ltp":1.13,"tv":6.91,"id":2120},{"batb":[[0,1.44,55.4],[1,1.3,20],[2,1.09,222.22]],"batl":[[0,95,5.85]],"ltp":0.0,"tv":0.0,"id":60443}],"tv":7.83}]}
{"op":"mcm","clk":"11883450277","pt":1724066493336,"mc":[{"id":"1.231804628","rc":[{"batb":[[0,1.57,15.03],[1,1.56,12],[2,1.5,20]],"ltp":1.04,"tv":0.91,"id":5995},{"batb":[[0,1.57,15.03],[1,1.56,11],[2,1.5,20]],"ltp":1.13,"tv":6.91,"id":2120},{"batb":[[0,1.45,19.04],[1,1.44,55.4],[2,1.3,20]],"ltp":0.0,"tv":0.0,"id":60443}]}]}
{"op":"mcm","clk":"11883534791","pt":1724068293811,"mc":[{"id":"1.231804628","rc":[{"batb":[[0,1.56,12],[1,1.5,20],[2,1.09,222.22]],"ltp":1.04,"tv":0.91,"id":5995},{"batb":[[0,1.56,11],[1,1.5,20],[2,1.09,222.22]],"ltp":1.13,"tv":6.91,"id":2120},{"batb":[[0,1.44,55.4],[1,1.3,20],[2,1.09,222.22]],"ltp":0.0,"tv":0.0,"id":60443}]}]}
{"op":"mcm","clk":"11883536258","pt":1724068328576,"mc":[{"id":"1.231804628","rc":[{"batb":[[0,1.57,15.03],[1,1.56,12],[2,1.5,20]],"ltp":1.04,"tv":0.91,"id":5995},{"batb":[[0,1.57,15.03],[1,1.56,11],[2,1.5,20]],"ltp":1.13,"tv":6.91,"id":2120},{"batb":[[0,1.45,19.04],[1,1.44,55.4],[2,1.3,20]],"ltp":0.0,"tv":0.0,"id":60443}]}]}
{"op":"mcm","clk":"11883595831","pt":1724069574855,"mc":[{"id":"1.231804628","rc":[{"batb":[[0,1.57,15.03]],"ltp":1.04,"tv":0.91,"id":5995},{"batb":[[0,1.57,15.03]],"ltp":1.13,"tv":6.91,"id":2120},{"batb":[[0,1.45,19.04]],"ltp":0.0,"tv":0.0,"id":60443}],"tv":7.82}]}
{"op":"mcm","clk":"11883627973","pt":1724070129110,"mc":[{"id":"1.231804628","rc":[{"batb":[[0,1.56,12],[1,1.5,20],[2,1.09,222.22]],"ltp":1.04,"tv":0.91,"id":5995},{"batb":[[0,1.56,11],[1,1.5,20],[2,1.09,222.22]],"ltp":1.13,"tv":6.91,"id":2120},{"batb":[[0,1.44,55.4],[1,1.3,20],[2,1.09,222.22]],"ltp":0.0,"tv":0.0,"id":60443}]}]}
{"op":"mcm","clk":"11883629259","pt":1724070157721,"mc":[{"id":"1.231804628","rc":[{"batb":[[0,1.57,15.03],[1,1.56,12],[2,1.5,20]],"ltp":1.04,"tv":0.91,"id":5995},{"batb":[[0,1.57,15.03],[1,1.56,11],[2,1.5,20]],"ltp":1.13,"tv":6.91,"id":2120},{"batb":[[0,1.45,19.04],[1,1.44,55.4],[2,1.3,20]],"ltp":0.0,"tv":0.0,"id":60443}]}]}
{"op":"mcm","clk":"11883705802","pt":1724071958273,"mc":[{"id":"1.231804628","rc":[{"batb":[[0,1.56,12],[1,1.5,20],[2,1.09,222.22]],"ltp":1.04,"tv":0.91,"id":5995},{"batb":[[0,1.56,11],[1,1.5,20],[2,1.09,222.22]],"ltp":1.13,"tv":6.91,"id":2120},{"batb":[[0,1.44,55.4],[1,1.3,20],[2,1.09,222.22]],"ltp":0.0,"tv":0.0,"id":60443}]}]}
{"op":"mcm","clk":"11883706892","pt":1724071982809,"mc":[{"id":"1.231804628","rc":[{"batb":[[0,1.57,15.03],[1,1.56,12],[2,1.5,20]],"ltp":1.04,"tv":0.91,"id":5995},{"batb":[[0,1.57,15.03],[1,1.56,11],[2,1.5,20]],"ltp":1.13,"tv":6.91,"id":2120},{"batb":[[0,1.45,19.04],[1,1.44,55.4],[2,1.3,20]],"ltp":0.0,"tv":0.0,"id":60443}]}]}
{"op":"mcm","clk":"11883766651","pt":1724073783463,"mc":[{"id":"1.231804628","rc":[{"batb":[[0,1.56,12],[1,1.5,20],[2,1.09,222.22]],"ltp":1.04,"tv":0.91,"id":5995},{"batb":[[0,1.56,11],[1,1.5,20],[2,1.09,222.22]],"ltp":1.13,"tv":6.91,"id":2120},{"batb":[[0,1.44,55.4],[1,1.3,20],[2,1.09,222.22]],"ltp":0.0,"tv":0.0,"id":60443}],"tv":7.83}]}
{"op":"mcm","clk":"11883767419","pt":1724073804085,"mc":[{"id":"1.231804628","rc":[{"batb":[[0,1.57,15.03],[1,1.56,12],[2,1.5,20]],"ltp":1.04,"tv":0.91,"id":5995},{"batb":[[0,1.57,15.03],[1,1.56,11],[2,1.5,20]],"ltp":1.13,"tv":6.91,"id":2120},{"batb":[[0,1.45,19.04],[1,1.44,55.4],[2,1.3,20]],"ltp":0.0,"tv":0.0,"id":60443}]}]}
{"op":"mcm","clk":"11883837805","pt":1724075604403,"mc":[{"id":"1.231804628","rc":[{"batb":[[0,1.44,55.4],[1,1.3,20],[2,1.09,222.22]],"ltp":0.0,"tv":0.0,"id":60443}]}]}
{"op":"mcm","clk":"11883837822","pt":1724075604772,"mc":[{"id":"1.231804628","rc":[{"batb":[[0,1.56,12],[1,1.5,20],[2,1.09,222.22]],"ltp":1.04,"tv":0.91,"id":5995},{"batb":[[0,1.56,11],[1,1.5,20],[2,1.09,222.22]],"ltp":1.13,"tv":6.91,"id":2120}]}]}
{"op":"mcm","clk":"11883838495","pt":1724075625818,"mc":[{"id":"1.231804628","rc":[{"batb":[[0,1.57,15.03],[1,1.56,12],[2,1.5,20]],"ltp":1.04,"tv":0.91,"id":5995},{"batb":[[0,1.57,15.03],[1,1.56,11],[2,1.5,20]],"ltp":1.13,"tv":6.91,"id":2120},{"batb":[[0,1.45,19.04],[1,1.44,55.4],[2,1.3,20]],"ltp":0.0,"tv":0.0,"id":60443}]}]}
{"op":"mcm","clk":"11883908995","pt":1724077426366,"mc":[{"id":"1.231804628","rc":[{"batb":[[0,1.56,12],[1,1.5,20],[2,1.09,222.22]],"ltp":1.04,"tv":0.91,"id":5995},{"batb":[[0,1.56,11],[1,1.5,20],[2,1.09,222.22]],"ltp":1.13,"tv":6.91,"id":2120},{"batb":[[0,1.44,55.39],[1,1.3,20],[2,1.09,222.22]],"ltp":0.0,"tv":0.0,"id":60443}],"tv":7.82}]}
{"op":"mcm","clk":"11883909244","pt":1724077431614,"mc":[{"id":"1.231804628","rc":[{"batb":[[0,1.57,15.03],[1,1.56,12],[2,1.5,20]],"ltp":1.04,"tv":0.91,"id":5995},{"batb":[[0,1.57,15.03],[1,1.56,11],[2,1.5,20]],"ltp":1.13,"tv":6.91,"id":2120},{"batb":[[0,1.45,19.03],[1,1.44,55.39],[2,1.3,20]],"ltp":0.0,"tv":0.0,"id":60443}]}]}
{"op":"mcm","clk":"11883990032","pt":1724079232329,"mc":[{"id":"1.231804628","rc":[{"batb":[[0,1.56,12],[1,1.5,20],[2,1.09,222.22]],"ltp":1.04,"tv":0.91,"id":5995},{"batb":[[0,1.56,11],[1,1.5,20],[2,1.09,222.22]],"ltp":1.13,"tv":6.91,"id":2120}]}]}
{"op":"mcm","clk":"11883990038","pt":1724079232537,"mc":[{"id":"1.231804628","rc":[{"batb":[[0,1.44,55.39],[1,1.3,20],[2,1.09,222.22]],"ltp":0.0,"tv":0.0,"id":60443}]}]}
{"op":"mcm","clk":"11883995021","pt":1724079380489,"mc":[{"id":"1.231804628","rc":[{"batb":[[0,1.57,15.03],[1,1.56,11],[2,1.5,20]],"ltp":1.13,"tv":6.91,"id":2120},{"batb":[[0,1.45,19.03],[1,1.44,55.39],[2,1.3,20]],"ltp":0.0,"tv":0.0,"id":60443}]}]}
{"op":"mcm","clk":"11883995027","pt":1724079380585,"mc":[{"id":"1.231804628","rc":[{"batb":[[0,1.57,15.03],[1,1.56,12],[2,1.5,20]],"ltp":1.04,"tv":0.91,"id":5995}]}]}
{"op":"mcm","clk":"11884047777","pt":1724080374862,"mc":[{"id":"1.231804628","rc":[{"batb":[[0,1.57,15.02]],"ltp":1.04,"tv":0.91,"id":5995},{"trd":[[1.04,2.37],[1.13,2.54]],"batb":[[0,1.57,15.02]],"ltp":1.13,"tv":6.91,"id":2120},{"batb":[[0,1.45,19.03]],"ltp":0.0,"tv":0.0,"id":60443}],"tv":7.82}]}
{"op":"mcm","clk":"11884087857","pt":1724080842858,"mc":[{"id":"1.231804628","rc":[{"batb":[[0,1.46,55.39],[1,1.45,19.03]],"ltp":0.0,"tv":0.0,"id":60443}]}]}
{"op":"mcm","clk":"11884113185","pt":1724081181482,"mc":[{"id":"1.231804628","rc":[{"batb":[[0,1.56,12],[1,1.5,20],[2,1.09,222.22]],"ltp":1.04,"tv":0.91,"id":5995},{"batb":[[0,1.47,18.22],[1,1.46,55.39]],"ltp":0.0,"tv":0.0,"id":60443}]}]}
{"op":"mcm","clk":"11884122731","pt":1724081331249,"mc":[{"id":"1.231804628","rc":[{"batb":[[0,1.57,15.02],[1,1.56,12],[2,1.5,20]],"ltp":1.04,"tv":0.91,"id":5995}]}]}
{"op":"mcm","clk":"11884238824","pt":1724082981985,"mc":[{"id":"1.231804628","rc":[{"batb":[[0,1.56,11],[1,1.5,20],[2,1.09,222.22]],"ltp":1.13,"tv":6.91,"id":2120},{"batb":[[0,1.46,55.39],[1,1.3,20],[2,1.09,222.22]],"ltp":0.0,"tv":0.0,"id":60443}]}]}
{"op":"mcm","clk":"11884246390","pt":1724083097896,"mc":[{"id":"1.231804628","rc":[{"batb":[[0,1.57,15.02],[1,1.56,11],[2,1.5,20]],"ltp":1.13,"tv":6.91,"id":2120},{"batb":[[0,1.47,18.22],[1,1.46,55.39],[2,1.3,20]],"ltp":0.0,"tv":0.0,"id":60443}]}]}
{"op":"mcm","clk":"11884248638","pt":1724083131521,"mc":[{"id":"1.231804628","rc":[{"batb":[[0,1.56,12],[1,1.5,20],[2,1.09,222.22]],"ltp":1.04,"tv":0.91,"id":5995}]}]}
{"op":"mcm","clk":"11884258303","pt":1724083266018,"mc":[{"id":"1.231804628","rc":[{"batb":[[0,1.57,15.04],[1,1.56,12],[2,1.5,20]],"ltp":1.04,"tv":0.91,"id":5995},{"batb":[[0,1.57,15.04]],"ltp":1.13,"tv":6.91,"id":2120},{"batb":[[0,1.47,18.23],[1,1.46,55.42]],"ltp":0.0,"tv":0.0,"id":60443}],"tv":7.82}]}
{"op":"mcm","clk":"11884384728","pt":1724084898308,"mc":[{"id":"1.231804628","rc":[{"batb":[[0,1.56,11],[1,1.5,20],[2,1.09,222.22]],"ltp":1.13,"tv":6.91,"id":2120},{"batb":[[0,1.46,55.42],[1,1.3,20],[2,1.09,222.22]],"ltp":0.0,"tv":0.0,"id":60443}]}]}
{"op":"mcm","clk":"11884388680","pt":1724084948481,"mc":[{"id":"1.231804628","rc":[{"batb":[[0,1.57,15.04],[1,1.56,11],[2,1.5,20]],"ltp":1.13,"tv":6.91,"id":2120},{"batb":[[0,1.47,18.23],[1,1.46,55.42],[2,1.3,20]],"ltp":0.0,"tv":0.0,"id":60443}]}]}
{"op":"mcm","clk":"11884398635","pt":1724085066278,"mc":[{"id":"1.231804628","rc":[{"batb":[[0,1.56,12],[1,1.5,20],[2,1.09,222.22]],"ltp":1.04,"tv":0.91,"id":5995}]}]}
{"op":"mcm","clk":"11884402962","pt":1724085114856,"mc":[{"id":"1.231804628","rc":[{"batb":[[0,1.57,15.04],[1,1.56,12],[2,1.5,20]],"ltp":1.04,"tv":0.91,"id":5995}]}]}
{"op":"mcm","clk":"11884537675","pt":1724086748968,"mc":[{"id":"1.231804628","rc":[{"batb":[[0,1.56,11],[1,1.5,20],[2,1.09,222.22]],"ltp":1.13,"tv":6.91,"id":2120},{"batb":[[0,1.46,55.42],[1,1.3,20],[2,1.09,222.22]],"ltp":0.0,"tv":0.0,"id":60443}]}]}
{"op":"mcm","clk":"11884539963","pt":1724086778890,"mc":[{"id":"1.231804628","rc":[{"batb":[[0,1.57,15.04],[1,1.56,11],[2,1.5,20]],"ltp":1.13,"tv":6.91,"id":2120},{"batb":[[0,1.47,18.23],[1,1.46,55.42],[2,1.3,20]],"ltp":0.0,"tv":0.0,"id":60443}]}]}
{"op":"mcm","clk":"11884552857","pt":1724086915098,"mc":[{"id":"1.231804628","rc":[{"batb":[[0,1.56,12],[1,1.5,20],[2,1.09,222.22]],"ltp":1.04,"tv":0.91,"id":5995},{"batb":[[0,1.57,15.04]],"ltp":1.13,"tv":6.91,"id":2120},{"batb":[[0,1.47,18.24],[1,1.46,55.45]],"ltp":0.0,"tv":0.0,"id":60443}]}]}
{"op":"mcm","clk":"11884555727","pt":1724086944014,"mc":[{"id":"1.231804628","rc":[{"batb":[[0,1.57,15.04],[1,1.56,12],[2,1.5,20]],"ltp":1.04,"tv":0.91,"id":5995}]}]}
{"op":"mcm","clk":"11884727131","pt":1724088579291,"mc":[{"id":"1.231804628","rc":[{"batb":[[0,1.56,11],[1,1.5,20],[2,1.09,222.22]],"ltp":1.13,"tv":6.91,"id":2120},{"batb":[[0,1.46,55.45],[1,1.3,20],[2,1.09,222.22]],"ltp":0.0,"tv":0.0,"id":60443}]}]}
{"op":"mcm","clk":"11884727619","pt":1724088583423,"mc":[{"id":"1.231804628","rc":[{"batb":[[0,1.57,15.04],[1,1.56,11],[2,1.5,20]],"ltp":1.13,"tv":6.91,"id":2120},{"batb":[[0,1.47,18.24],[1,1.46,55.45],[2,1.3,20]],"ltp":0.0,"tv":0.0,"id":60443}]}]}
{"op":"mcm","clk":"11884747663","pt":1724088744123,"mc":[{"id":"1.231804628","rc":[{"batb":[[0,1.56,12],[1,1.5,20],[2,1.09,222.22]],"ltp":1.04,"tv":0.91,"id":5995}]}]}
{"op":"mcm","clk":"11884747941","pt":1724088746638,"mc":[{"id":"1.231804628","rc":[{"batb":[[0,1.57,15.04],[1,1.56,12],[2,1.5,20]],"ltp":1.04,"tv":0.91,"id":5995}]}]}
{"op":"mcm","clk":"11884912891","pt":1724090383799,"mc":[{"id":"1.231804628","rc":[{"batb":[[0,1.56,11],[1,1.5,20],[2,1.09,222.22]],"ltp":1.13,"tv":6.91,"id":2120},{"batb":[[0,1.46,55.45],[1,1.3,20],[2,1.09,222.22]],"ltp":0.0,"tv":0.0,"id":60443}]}]}
{"op":"mcm","clk":"11884922921","pt":1724090500537,"mc":[{"id":"1.231804628","rc":[{"batb":[[0,1.57,15.03]],"ltp":1.04,"tv":0.91,"id":5995},{"batb":[[0,1.46,56.32]],"ltp":0.0,"tv":0.0,"id":60443}],"tv":7.82}]}
{"op":"mcm","clk":"11884926383","pt":1724090536271,"mc":[{"id":"1.231804628","rc":[{"batb":[[0,1.57,15.03],[1,1.56,11],[2,1.5,20]],"ltp":1.13,"tv":6.91,"id":2120},{"batb":[[0,1.47,19.13],[1,1.46,55.42],[2,1.3,20]],"ltp":0.0,"tv":0.0,"id":60443}]}]}
{"op":"mcm","clk":"11884927378","pt":1724090546866,"mc":[{"id":"1.231804628","rc":[{"batb":[[0,1.56,12],[1,1.5,20],[2,1.09,222.22]],"ltp":1.04,"tv":0.91,"id":5995}]}]}
{"op":"mcm","clk":"11884940697","pt":1724090696153,"mc":[{"id":"1.231804628","rc":[{"batb":[[0,1.57,15.03],[1,1.56,12],[2,1.5,20]],"ltp":1.04,"tv":0.91,"id":5995}]}]}
{"op":"mcm","clk":"11885152854","pt":1724092336949,"mc":[{"id":"1.231804628","rc":[{"batb":[[0,1.56,11],[1,1.5,20],[2,1.09,222.22]],"ltp":1.13,"tv":6.91,"id":2120},{"batb":[[0,1.46,56.32],[1,1.3,20],[2,1.09,222.22]],"ltp":0.0,"tv":0.0,"id":60443}]}]}
{"op":"mcm","clk":"11885166427","pt":1724092444278,"mc":[{"id":"1.231804628","rc":[{"batb":[[0,1.57,15.03],[1,1.56,11],[2,1.5,20]],"ltp":1.13,"tv":6.91,"id":2120},{"batb":[[0,1.47,19.13],[1,1.46,55.42],[2,1.3,20]],"ltp":0.0,"tv":0.0,"id":60443}]}]}
{"op":"mcm","clk":"11885173032","pt":1724092501137,"mc":[{"id":"1.231804628","rc":[{"batb":[[0,1.56,12],[1,1.5,20],[2,1.09,222.22]],"ltp":1.04,"tv":0.91,"id":5995}]}]}
{"op":"mcm","clk":"11885186007","pt":1724092601435,"mc":[{"id":"1.231804628","rc":[{"batb":[[0,1.57,15.03],[1,1.56,12],[2,1.5,20]],"ltp":1.04,"tv":0.91,"id":5995}]}]}
{"op":"mcm","clk":"11885367448","pt":1724094244408,"mc":[{"id":"1.231804628","rc":[{"batb":[[0,1.57,15.04]],"ltp":1.04,"tv":0.91,"id":5995},{"batb":[[0,1.56,11],[1,1.5,20],[2,1.09,222.22]],"ltp":1.13,"tv":6.91,"id":2120},{"batb":[[0,1.47,19.13],[1,1.46,55.44]],"ltp":0.0,"tv":0.0,"id":60443}]}]}
{"op":"mcm","clk":"11885367468","pt":1724094244617,"mc":[{"id":"1.231804628","rc":[{"batb":[[0,1.46,56.34],[1,1.3,20],[2,1.09,222.22]],"ltp":0.0,"tv":0.0,"id":60443}]}]}
{"op":"mcm","clk":"11885375027","pt":1724094321104,"mc":[{"id":"1.231804628","rc":[{"batb":[[0,1.57,15.04],[1,1.56,11],[2,1.5,20]],"ltp":1.13,"tv":6.91,"id":2120},{"batb":[[0,1.47,19.13],[1,1.46,55.44],[2,1.3,20]],"ltp":0.0,"tv":0.0,"id":60443}]}]}
{"op":"mcm","clk":"11885384006","pt":1724094401588,"mc":[{"id":"1.231804628","rc":[{"batb":[[0,1.56,12],[1,1.5,20],[2,1.09,222.22]],"ltp":1.04,"tv":0.91,"id":5995}]}]}
{"op":"mcm","clk":"11885391567","pt":1724094473797,"mc":[{"id":"1.231804628","rc":[{"batb":[[0,1.57,15.04],[1,1.56,12],[2,1.5,20]],"ltp":1.04,"tv":0.91,"id":5995}]}]}
{"op":"mcm","clk":"11885573976","pt":1724096121419,"mc":[{"id":"1.231804628","rc":[{"batb":[[0,1.56,11],[1,1.5,20],[2,1.09,222.22]],"ltp":1.13,"tv":6.91,"id":2120}]}]}
{"op":"mcm","clk":"11885573998","pt":1724096121629,"mc":[{"id":"1.231804628","rc":[{"batb":[[0,1.46,56.34],[1,1.3,20],[2,1.09,222.22]],"ltp":0.0,"tv":0.0,"id":60443}]}]}
{"op":"mcm","clk":"11885580567","pt":1724096180898,"mc":[{"id":"1.231804628","rc":[{"batb":[[0,1.57,15.04],[1,1.56,11],[2,1.5,20]],"ltp":1.13,"tv":6.91,"id":2120},{"batb":[[0,1.47,19.13],[1,1.46,55.44],[2,1.3,20]],"ltp":0.0,"tv":0.0,"id":60443}]}]}
{"op":"mcm","clk":"11885589032","pt":1724096274033,"mc":[{"id":"1.231804628","rc":[{"batb":[[0,1.56,12],[1,1.5,20],[2,1.09,222.22]],"ltp":1.04,"tv":0.91,"id":5995}]}]}
{"op":"mcm","clk":"11885595119","pt":1724096341119,"mc":[{"id":"1.231804628","rc":[{"batb":[[0,1.57,15.04],[1,1.56,12],[2,1.5,20]],"ltp":1.04,"tv":0.91,"id":5995}]}]}
{"op":"mcm","clk":"11885740658","pt":1724097981263,"mc":[{"id":"1.231804628","rc":[{"batb":[[0,1.57,15.04]],"ltp":1.04,"tv":0.91,"id":5995},{"batb":[[0,1.56,11],[1,1.5,20],[2,1.09,222.22]],"ltp":1.13,"tv":6.91,"id":2120},{"batb":[[0,1.46,56.36],[1,1.3,20],[2,1.09,222.22]],"ltp":0.0,"tv":0.0,"id":60443}]}]}
{"op":"mcm","clk":"11885748158","pt":1724098075461,"mc":[{"id":"1.231804628","rc":[{"batb":[[0,1.57,15.04],[1,1.56,11],[2,1.5,20]],"ltp":1.13,"tv":6.91,"id":2120},{"batb":[[0,1.47,19.14],[1,1.46,55.46],[2,1.3,20]],"ltp":0.0,"tv":0.0,"id":60443}]}]}
{"op":"mcm","clk":"11885754527","pt":1724098141325,"mc":[{"id":"1.231804628","rc":[{"batb":[[0,1.56,12],[1,1.5,20],[2,1.09,222.22]],"ltp":1.04,"tv":0.91,"id":5995}]}]}
{"op":"mcm","clk":"11885762196","pt":1724098230458,"mc":[{"id":"1.231804628","rc":[{"batb":[[0,1.57,15.04],[1,1.56,12],[2,1.5,20]],"ltp":1.04,"tv":0.91,"id":5995}]}]}
{"op":"mcm","clk":"11885900667","pt":1724099876209,"mc":[{"id":"1.231804628","rc":[{"batb":[[0,1.56,11],[1,1.5,20],[2,1.09,222.22]],"ltp":1.13,"tv":6.91,"id":2120},{"batb":[[0,1.46,56.36],[1,1.3,20],[2,1.09,222.22]],"ltp":0.0,"tv":0.0,"id":60443}]}]}
{"op":"mcm","clk":"11885904132","pt":1724099914838,"mc":[{"id":"1.231804628","rc":[{"batb":[[0,1.57,15.04],[1,1.56,11],[2,1.5,20]],"ltp":1.13,"tv":6.91,"id":2120},{"batb":[[0,1.47,19.14],[1,1.46,55.46],[2,1.3,20]],"ltp":0.0,"tv":0.0,"id":60443}]}]}
{"op":"mcm","clk":"11885913969","pt":1724100030626,"mc":[{"id":"1.231804628","rc":[{"batb":[[0,1.56,12],[1,1.5,20],[2,1.09,222.22]],"ltp":1.04,"tv":0.91,"id":5995}]}]}
{"op":"mcm","clk":"11885917132","pt":1724100067290,"mc":[{"id":"1.231804628","rc":[{"batb":[[0,1.57,15.04],[1,1.56,12],[2,1.5,20]],"ltp":1.04,"tv":0.91,"id":5995}]}]}
{"op":"mcm","clk":"11885999013","pt":1724101682958,"mc":[{"id":"1.231804628","rc":[{"batb":[[0,1.58,12],[1,1.57,15.05]],"ltp":1.04,"tv":0.91,"id":5995},{"batb":[[0,1.58,11],[1,1.57,15.05]],"ltp":1.13,"tv":6.91,"id":2120},{"batb":[[0,1.47,19.14]],"ltp":0.0,"tv":0.0,"id":60443}]}]}
{"op":"mcm","clk":"11886000278","pt":1724101715368,"mc":[{"id":"1.231804628","rc":[{"batb":[[1,1.5,20],[2,1.09,222.22]],"ltp":1.13,"tv":6.91,"id":2120}]}]}
{"op":"mcm","clk":"11886000284","pt":1724101715573,"mc":[{"id":"1.231804628","rc":[{"batb":[[0,1.46,56.36],[1,1.3,20],[2,1.09,222.22]],"ltp":0.0,"tv":0.0,"id":60443}]}]}
{"op":"mcm","clk":"11886000421","pt":1724101719580,"mc":[{"id":"1.231804628","rc":[{"batb":[[0,1.59,14.54],[1,1.58,11],[2,1.5,20]],"ltp":1.13,"tv":6.91,"id":2120},{"batb":[[0,1.47,19.14],[1,1.46,55.46],[2,1.3,20]],"ltp":0.0,"tv":0.0,"id":60443}]}]}
{"op":"mcm","clk":"11886006084","pt":1724101867549,"mc":[{"id":"1.231804628","rc":[{"batb":[[1,1.5,20],[2,1.09,222.22]],"ltp":1.04,"tv":0.91,"id":5995}]}]}
{"op":"mcm","clk":"11886006126","pt":1724101868676,"mc":[{"id":"1.231804628","rc":[{"batb":[[0,1.59,14.54],[1,1.58,12],[2,1.5,20]],"ltp":1.04,"tv":0.91,"id":5995}]}]}
{"op":"mcm","clk":"11886086103","pt":1724103520002,"mc":[{"id":"1.231804628","rc":[{"batb":[[0,1.58,11],[1,1.5,20],[2,1.09,222.22]],"ltp":1.13,"tv":6.91,"id":2120},{"batb":[[0,1.46,56.36],[1,1.3,20],[2,1.09,222.22]],"ltp":0.0,"tv":0.0,"id":60443}]}]}
{"op":"mcm","clk":"11886091620","pt":1724103646879,"mc":[{"id":"1.231804628","rc":[{"batb":[[0,1.59,14.54],[1,1.58,11],[2,1.5,20]],"ltp":1.13,"tv":6.91,"id":2120},{"batb":[[0,1.47,19.14],[1,1.46,55.46],[2,1.3,20]],"ltp":0.0,"tv":0.0,"id":60443}]}]}
{"op":"mcm","clk":"11886092643","pt":1724103668904,"mc":[{"id":"1.231804628","rc":[{"batb":[[0,1.58,12],[1,1.5,20],[2,1.09,222.22]],"ltp":1.04,"tv":0.91,"id":5995}]}]}
{"op":"mcm","clk":"11886098133","pt":1724103794153,"mc":[{"id":"1.231804628","rc":[{"batb":[[0,1.59,14.54],[1,1.58,12],[2,1.5,20]],"ltp":1.04,"tv":0.91,"id":5995}]}]}
{"op":"mcm","clk":"11886174618","pt":1724105447293,"mc":[{"id":"1.231804628","rc":[{"batb":[[0,1.59,14.54]],"ltp":1.04,"tv":0.91,"id":5995},{"batb":[[0,1.58,11],[1,1.5,20],[2,1.09,222.22]],"ltp":1.13,"tv":6.91,"id":2120},{"batb":[[0,1.46,56.36],[1,1.3,20],[2,1.09,222.22]],"ltp":0.0,"tv":0.0,"id":60443}]}]}
{"op":"mcm","clk":"11886179001","pt":1724105550312,"mc":[{"id":"1.231804628","rc":[{"batb":[[0,1.59,14.54],[1,1.58,11],[2,1.5,20]],"ltp":1.13,"tv":6.91,"id":2120},{"batb":[[0,1.47,19.14],[1,1.46,55.47],[2,1.3,20]],"ltp":0.0,"tv":0.0,"id":60443}]}]}
{"op":"mcm","clk":"11886180761","pt":1724105594387,"mc":[{"id":"1.231804628","rc":[{"batb":[[0,1.58,12],[1,1.5,20],[2,1.09,222.22]],"ltp":1.04,"tv":0.91,"id":5995}]}]}
{"op":"mcm","clk":"11886187154","pt":1724105695595,"mc":[{"id":"1.231804628","rc":[{"batb":[[0,1.59,14.54],[1,1.58,12],[2,1.5,20]],"ltp":1.04,"tv":0.91,"id":5995}]}]}
{"op":"mcm","clk":"11886245408","pt":1724107350652,"mc":[{"id":"1.231804628","rc":[{"batb":[[0,1.58,11],[1,1.5,20],[2,1.09,222.22]],"ltp":1.13,"tv":6.91,"id":2120},{"batb":[[0,1.46,56.36],[1,1.3,20],[2,1.09,222.22]],"ltp":0.0,"tv":0.0,"id":60443}]}]}
{"op":"mcm","clk":"11886256356","pt":1724107436859,"mc":[{"id":"1.231804628","rc":[{"batb":[[0,1.59,14.54],[1,1.58,11],[2,1.5,20]],"ltp":1.13,"tv":6.91,"id":2120},{"batb":[[0,1.47,19.14],[1,1.46,55.47],[2,1.3,20]],"ltp":0.0,"tv":0.0,"id":60443}]}]}
{"op":"mcm","clk":"11886258262","pt":1724107495860,"mc":[{"id":"1.231804628","rc":[{"batb":[[0,1.58,12],[1,1.5,20],[2,1.09,222.22]],"ltp":1.04,"tv":0.91,"id":5995}]}]}
{"op":"mcm","clk":"11886260974","pt":1724107581240,"mc":[{"id":"1.231804628","rc":[{"batb":[[0,1.59,14.54],[1,1.58,12],[2,1.5,20]],"ltp":1.04,"tv":0.91,"id":5995}]}]}
{"op":"mcm","clk":"11886323715","pt":1724109237269,"mc":[{"id":"1.231804628","rc":[{"batb":[[0,1.58,11],[1,1.5,20],[2,1.09,222.22]],"ltp":1.13,"tv":6.91,"id":2120},{"batb":[[0,1.46,56.37],[1,1.3,20],[2,1.09,222.22]],"ltp":0.0,"tv":0.0,"id":60443}]}]}
{"op":"mcm","clk":"11886327000","pt":1724109312148,"mc":[{"id":"1.231804628","rc":[{"batb":[[0,1.59,14.54],[1,1.58,11],[2,1.5,20]],"ltp":1.13,"tv":6.91,"id":2120},{"batb":[[0,1.47,19.14],[1,1.46,55.47],[2,1.3,20]],"ltp":0.0,"tv":0.0,"id":60443}]}]}
{"op":"mcm","clk":"11886329679","pt":1724109381517,"mc":[{"id":"1.231804628","rc":[{"batb":[[0,1.58,12],[1,1.5,20],[2,1.09,222.22]],"ltp":1.04,"tv":0.91,"id":5995}]}]}
{"op":"mcm","clk":"11886332550","pt":1724109456639,"mc":[{"id":"1.231804628","rc":[{"batb":[[0,1.59,14.54],[1,1.58,12],[2,1.5,20]],"ltp":1.04,"tv":0.91,"id":5995}]}]}
{"op":"mcm","clk":"11886404453","pt":1724111112337,"mc":[{"id":"1.231804628","rc":[{"batb":[[0,1.46,56.37],[1,1.3,20],[2,1.09,222.22]],"ltp":0.0,"tv":0.0,"id":60443}]}]}
{"op":"mcm","clk":"11886404464","pt":1724111112538,"mc":[{"id":"1.231804628","rc":[{"batb":[[0,1.58,11],[1,1.5,20],[2,1.09,222.22]],"ltp":1.13,"tv":6.91,"id":2120}]}]}
{"op":"mcm","clk":"11886407118","pt":1724111173595,"mc":[{"id":"1.231804628","rc":[{"batb":[[0,1.59,14.54],[1,1.58,11],[2,1.5,20]],"ltp":1.13,"tv":6.91,"id":2120},{"batb":[[0,1.47,19.14],[1,1.46,55.47],[2,1.3,20]],"ltp":0.0,"tv":0.0,"id":60443}]}]}
{"op":"mcm","clk":"11886410567","pt":1724111256914,"mc":[{"id":"1.231804628","rc":[{"batb":[[0,1.58,12],[1,1.5,20],[2,1.09,222.22]],"ltp":1.04,"tv":0.91,"id":5995}]}]}
{"op":"mcm","clk":"11886413132","pt":1724111316189,"mc":[{"id":"1.231804628","rc":[{"batb":[[0,1.59,14.54],[1,1.58,12],[2,1.5,20]],"ltp":1.04,"tv":0.91,"id":5995}]}]}
{"op":"mcm","clk":"11886496696","pt":1724112973975,"mc":[{"id":"1.231804628","rc":[{"batb":[[0,1.58,11],[1,1.5,20],[2,1.09,222.22]],"ltp":1.13,"tv":6.91,"id":2120},{"batb":[[0,1.46,56.37],[1,1.3,20],[2,1.09,222.22]],"ltp":0.0,"tv":0.0,"id":60443}]}]}
{"op":"mcm","clk":"11886498405","pt":1724113010624,"mc":[{"id":"1.231804628","rc":[{"batb":[[0,1.59,14.54],[1,1.58,11],[2,1.5,20]],"ltp":1.13,"tv":6.91,"id":2120},{"batb":[[0,1.47,19.15],[1,1.46,55.47],[2,1.3,20]],"ltp":0.0,"tv":0.0,"id":60443}]}]}
{"op":"mcm","clk":"11886503371","pt":1724113116339,"mc":[{"id":"1.231804628","rc":[{"batb":[[0,1.58,12],[1,1.5,20],[2,1.09,222.22]],"ltp":1.04,"tv":0.91,"id":5995}]}]}
{"op":"mcm","clk":"11886504835","pt":1724113150583,"mc":[{"id":"1.231804628","rc":[{"batb":[[0,1.59,14.54],[1,1.58,12],[2,1.5,20]],"ltp":1.04,"tv":0.91,"id":5995}]}]}
{"op":"mcm","clk":"11886580729","pt":1724114811091,"mc":[{"id":"1.231804628","rc":[{"batb":[[0,1.58,11],[1,1.5,20],[2,1.09,222.22]],"ltp":1.13,"tv":6.91,"id":2120},{"batb":[[0,1.46,56.37],[1,1.3,20],[2,1.09,222.22]],"ltp":0.0,"tv":0.0,"id":60443}]}]}
{"op":"mcm","clk":"11886581209","pt":1724114823827,"mc":[{"id":"1.231804628","rc":[{"batb":[[0,1.59,14.54],[1,1.58,11],[2,1.5,20]],"ltp":1.13,"tv":6.91,"id":2120},{"batb":[[0,1.47,19.15],[1,1.46,55.47],[2,1.3,20]],"ltp":0.0,"tv":0.0,"id":60443}]}]}
{"op":"mcm","clk":"11886586357","pt":1724114950780,"mc":[{"id":"1.231804628","rc":[{"batb":[[0,1.58,12],[1,1.5,20],[2,1.09,222.22]],"ltp":1.04,"tv":0.91,"id":5995}]}]}
{"op":"mcm","clk":"11886586758","pt":1724114962095,"mc":[{"id":"1.231804628","rc":[{"batb":[[0,1.59,14.54],[1,1.58,12],[2,1.5,20]],"ltp":1.04,"tv":0.91,"id":5995}]}]}
{"op":"mcm","clk":"11886661834","pt":1724116624192,"mc":[{"id":"1.231804628","rc":[{"batb":[[0,1.58,11],[1,1.5,20],[2,1.09,222.22]],"ltp":1.13,"tv":6.91,"id":2120},{"batb":[[0,1.46,56.37],[1,1.3,20],[2,1.09,222.22]],"ltp":0.0,"tv":0.0,"id":60443}]}]}
{"op":"mcm","clk":"11886667669","pt":1724116758124,"mc":[{"id":"1.231804628","rc":[{"batb":[[0,1.59,14.54],[1,1.58,11],[2,1.5,20]],"ltp":1.13,"tv":6.91,"id":2120},{"batb":[[0,1.47,19.15],[1,1.46,55.47],[2,1.3,20]],"ltp":0.0,"tv":0.0,"id":60443}]}]}
{"op":"mcm","clk":"11886667816","pt":1724116762284,"mc":[{"id":"1.231804628","rc":[{"batb":[[0,1.58,12],[1,1.5,20],[2,1.09,222.22]],"ltp":1.04,"tv":0.91,"id":5995}]}]}
{"op":"mcm","clk":"11886673582","pt":1724116894037,"mc":[{"id":"1.231804628","rc":[{"batb":[[0,1.59,14.54],[1,1.58,12],[2,1.5,20]],"ltp":1.04,"tv":0.91,"id":5995}]}]}
{"op":"mcm","clk":"11886751018","pt":1724118558448,"mc":[{"id":"1.231804628","rc":[{"batb":[[0,1.58,11],[1,1.5,20],[2,1.09,222.22]],"ltp":1.13,"tv":6.91,"id":2120},{"batb":[[0,1.46,56.37],[1,1.3,20],[2,1.09,222.22]],"ltp":0.0,"tv":0.0,"id":60443}]}]}
{"op":"mcm","clk":"11886755294","pt":1724118649058,"mc":[{"id":"1.231804628","rc":[{"batb":[[0,1.59,14.54],[1,1.58,11],[2,1.5,20]],"ltp":1.13,"tv":6.91,"id":2120},{"batb":[[0,1.47,19.15],[1,1.46,55.47],[2,1.3,20]],"ltp":0.0,"tv":0.0,"id":60443}]}]}
{"op":"mcm","clk":"11886758639","pt":1724118694600,"mc":[{"id":"1.231804628","rc":[{"batb":[[0,1.58,12],[1,1.5,20],[2,1.09,222.22]],"ltp":1.04,"tv":0.91,"id":5995}]}]}
{"op":"mcm","clk":"11886762766","pt":1724118782853,"mc":[{"id":"1.231804628","rc":[{"batb":[[0,1.59,14.54],[1,1.58,12],[2,1.5,20]],"ltp":1.04,"tv":0.91,"id":5995}]}]}
{"op":"mcm","clk":"11886823676","pt":1724120449279,"mc":[{"id":"1.231804628","rc":[{"batb":[[0,1.59,14.54]],"ltp":1.04,"tv":0.91,"id":5995},{"batb":[[0,1.58,11],[1,1.5,20],[2,1.09,222.22]],"ltp":1.13,"tv":6.91,"id":2120},{"batb":[[0,1.46,56.39],[1,1.3,20],[2,1.09,222.22]],"ltp":0.0,"tv":0.0,"id":60443}],"tv":7.82}]}
{"op":"mcm","clk":"11886825496","pt":1724120513468,"mc":[{"id":"1.231804628","rc":[{"batb":[[0,1.59,14.54],[1,1.58,11],[2,1.5,20]],"ltp":1.13,"tv":6.91,"id":2120},{"batb":[[0,1.47,19.15],[1,1.46,55.49],[2,1.3,20]],"ltp":0.0,"tv":0.0,"id":60443}]}]}
{"op":"mcm","clk":"11886827638","pt":1724120583044,"mc":[{"id":"1.231804628","rc":[{"batb":[[0,1.58,12],[1,1.5,20],[2,1.09,222.22]],"ltp":1.04,"tv":0.91,"id":5995}]}]}
{"op":"mcm","clk":"11886829940","pt":1724120646031,"mc":[{"id":"1.231804628","rc":[{"batb":[[0,1.59,14.54],[1,1.58,12],[2,1.5,20]],"ltp":1.04,"tv":0.91,"id":5995}]}]}
{"op":"mcm","clk":"11886921516","pt":1724123574904,"mc":[{"id":"1.231804628","rc":[{"batb":[[0,1.59,14.54]],"ltp":1.04,"tv":0.91,"id":5995},{"batb":[[0,1.59,14.54]],"ltp":1.13,"tv":6.91,"id":2120},{"batb":[[0,1.47,19.14],[1,1.46,55.47]],"ltp":0.0,"tv":0.0,"id":60443}]}]}
{"op":"mcm","clk":"11886928627","pt":1724123619658,"mc":[{"id":"1.231804628","rc":[{"batb":[[0,1.58,12],[1,1.5,20],[2,1.09,222.22]],"ltp":1.04,"tv":0.91,"id":5995}]}]}
{"op":"mcm","clk":"11886928684","pt":1724123621496,"mc":[{"id":"1.231804628","rc":[{"batb":[[0,1.46,56.37],[1,1.3,20],[2,1.09,222.22]],"ltp":0.0,"tv":0.0,"id":60443}]}]}
{"op":"mcm","clk":"11886928691","pt":1724123621700,"mc":[{"id":"1.231804628","rc":[{"batb":[[0,1.58,11],[1,1.5,20],[2,1.09,222.22]],"ltp":1.13,"tv":6.91,"id":2120}]}]}
{"op":"mcm","clk":"11886932266","pt":1724123739387,"mc":[{"id":"1.231804628","rc":[{"batb":[[0,1.59,14.54],[1,1.58,12],[2,1.5,20]],"ltp":1.04,"tv":0.91,"id":5995},{"batb":[[0,1.59,14.54],[1,1.58,11],[2,1.5,20]],"ltp":1.13,"tv":6.91,"id":2120},{"batb":[[0,1.47,19.14],[1,1.46,55.47],[2,1.3,20]],"ltp":0.0,"tv":0.0,"id":60443}]}]}
{"op":"mcm","clk":"11886990270","pt":1724125540514,"mc":[{"id":"1.231804628","rc":[{"batb":[[0,1.58,11],[1,1.5,20],[2,1.09,222.22]],"ltp":1.13,"tv":6.91,"id":2120},{"batb":[[0,1.46,56.37],[1,1.3,20],[2,1.09,222.22]],"ltp":0.0,"tv":0.0,"id":60443}]}]}
{"op":"mcm","clk":"11886990278","pt":1724125540720,"mc":[{"id":"1.231804628","rc":[{"batb":[[0,1.58,12],[1,1.5,20],[2,1.09,222.22]],"ltp":1.04,"tv":0.91,"id":5995}]}]}
{"op":"mcm","clk":"11886990515","pt":1724125556789,"mc":[{"id":"1.231804628","rc":[{"batb":[[0,1.59,14.54],[1,1.58,12],[2,1.5,20]],"ltp":1.04,"tv":0.91,"id":5995},{"batb":[[0,1.59,14.54],[1,1.58,11],[2,1.5,20]],"ltp":1.13,"tv":6.91,"id":2120},{"batb":[[0,1.47,19.14],[1,1.46,55.47],[2,1.3,20]],"ltp":0.0,"tv":0.0,"id":60443}]}]}
{"op":"mcm","clk":"11887045777","pt":1724127357498,"mc":[{"id":"1.231804628","rc":[{"batb":[[0,1.58,12],[1,1.5,20],[2,1.09,222.22]],"ltp":1.04,"tv":0.91,"id":5995},{"batb":[[0,1.58,11],[1,1.5,20],[2,1.09,222.22]],"ltp":1.13,"tv":6.91,"id":2120},{"batb":[[0,1.46,56.37],[1,1.3,20],[2,1.09,222.22]],"ltp":0.0,"tv":0.0,"id":60443}]}]}
{"op":"mcm","clk":"11887045869","pt":1724127362511,"mc":[{"id":"1.231804628","rc":[{"batb":[[0,1.59,14.54],[1,1.58,12],[2,1.5,20]],"ltp":1.04,"tv":0.91,"id":5995},{"batb":[[0,1.59,14.54],[1,1.58,11],[2,1.5,20]],"ltp":1.13,"tv":6.91,"id":2120},{"batb":[[0,1.47,19.14],[1,1.46,55.47],[2,1.3,20]],"ltp":0.0,"tv":0.0,"id":60443}]}]}
{"op":"mcm","clk":"11887111288","pt":1724129165216,"mc":[{"id":"1.231804628","rc":[{"batb":[[0,1.58,12],[1,1.5,20],[2,1.09,222.22]],"ltp":1.04,"tv":0.91,"id":5995},{"batb":[[0,1.58,11],[1,1.5,20],[2,1.09,222.22]],"ltp":1.13,"tv":6.91,"id":2120},{"batb":[[0,1.46,56.37],[1,1.3,20],[2,1.09,222.22]],"ltp":0.0,"tv":0.0,"id":60443}]}]}
{"op":"mcm","clk":"11887116857","pt":1724129313062,"mc":[{"id":"1.231804628","rc":[{"batb":[[0,1.59,14.54],[1,1.58,12],[2,1.5,20]],"ltp":1.04,"tv":0.91,"id":5995},{"batb":[[0,1.59,14.54],[1,1.58,11],[2,1.5,20]],"ltp":1.13,"tv":6.91,"id":2120},{"batb":[[0,1.47,19.14],[1,1.46,55.47],[2,1.3,20]],"ltp":0.0,"tv":0.0,"id":60443}]}]}
{"op":"mcm","clk":"11887186115","pt":1724131113932,"mc":[{"id":"1.231804628","rc":[{"batb":[[0,1.58,12],[1,1.5,20],[2,1.09,222.22]],"ltp":1.04,"tv":0.91,"id":5995},{"batb":[[0,1.58,11],[1,1.5,20],[2,1.09,222.22]],"ltp":1.13,"tv":6.91,"id":2120},{"batb":[[0,1.46,56.37],[1,1.3,20],[2,1.09,222.22]],"ltp":0.0,"tv":0.0,"id":60443}]}]}
{"op":"mcm","clk":"11887189763","pt":1724131180008,"mc":[{"id":"1.231804628","rc":[{"batb":[[0,1.59,14.54],[1,1.58,12],[2,1.5,20]],"ltp":1.04,"tv":0.91,"id":5995},{"batb":[[0,1.59,14.54],[1,1.58,11],[2,1.5,20]],"ltp":1.13,"tv":6.91,"id":2120},{"batb":[[0,1.47,19.14],[1,1.46,55.47],[2,1.3,20]],"ltp":0.0,"tv":0.0,"id":60443}]}]}
{"op":"mcm","clk":"11887253363","pt":1724132980376,"mc":[{"id":"1.231804628","rc":[{"batb":[[0,1.58,12],[1,1.5,20],[2,1.09,222.22]],"ltp":1.04,"tv":0.91,"id":5995},{"batb":[[0,1.58,11],[1,1.5,20],[2,1.09,222.22]],"ltp":1.13,"tv":6.91,"id":2120}]}]}
{"op":"mcm","clk":"11887253406","pt":1724132981502,"mc":[{"id":"1.231804628","rc":[{"batb":[[0,1.46,56.37],[1,1.3,20],[2,1.09,222.22]],"ltp":0.0,"tv":0.0,"id":60443}]}]}
{"op":"mcm","clk":"11887255548","pt":1724133046748,"mc":[{"id":"1.231804628","rc":[{"batb":[[0,1.59,14.54],[1,1.58,12],[2,1.5,20]],"ltp":1.04,"tv":0.91,"id":5995},{"batb":[[0,1.59,14.54],[1,1.58,11],[2,1.5,20]],"ltp":1.13,"tv":6.91,"id":2120},{"batb":[[0,1.47,19.14],[1,1.46,55.47],[2,1.3,20]],"ltp":0.0,"tv":0.0,"id":60443}]}]}
{"op":"mcm","clk":"11887312544","pt":1724134374901,"mc":[{"id":"1.231804628","rc":[{"batb":[[0,1.59,14.54]],"ltp":1.04,"tv":0.91,"id":5995},{"batb":[[0,1.59,14.54]],"ltp":1.13,"tv":6.91,"id":2120},{"batb":[[0,1.47,19.14],[1,1.46,55.47]],"ltp":0.0,"tv":0.0,"id":60443}]}]}
{"op":"mcm","clk":"11887335150","pt":1724134847441,"mc":[{"id":"1.231804628","rc":[{"batb":[[0,1.58,11],[1,1.5,20],[2,1.09,222.22]],"ltp":1.13,"tv":6.91,"id":2120}]}]}
{"op":"mcm","clk":"11887335165","pt":1724134847955,"mc":[{"id":"1.231804628","rc":[{"batb":[[0,1.58,12],[1,1.5,20],[2,1.09,222.22]],"ltp":1.04,"tv":0.91,"id":5995},{"batb":[[0,1.46,56.36],[1,1.3,20],[2,1.09,222.22]],"ltp":0.0,"tv":0.0,"id":60443}]}]}
{"op":"mcm","clk":"11887337289","pt":1724134912304,"mc":[{"id":"1.231804628","rc":[{"batb":[[0,1.59,14.54],[1,1.58,12],[2,1.5,20]],"ltp":1.04,"tv":0.91,"id":5995},{"batb":[[0,1.59,14.54],[1,1.58,11],[2,1.5,20]],"ltp":1.13,"tv":6.91,"id":2120},{"batb":[[0,1.47,19.14],[1,1.46,55.47],[2,1.3,20]],"ltp":0.0,"tv":0.0,"id":60443}]}]}
{"op":"mcm","clk":"11887409895","pt":1724136712946,"mc":[{"id":"1.231804628","rc":[{"batb":[[0,1.58,12],[1,1.5,20],[2,1.09,222.22]],"ltp":1.04,"tv":0.91,"id":5995},{"batb":[[0,1.58,11],[1,1.5,20],[2,1.09,222.22]],"ltp":1.13,"tv":6.91,"id":2120},{"batb":[[0,1.46,56.36],[1,1.3,20],[2,1.09,222.22]],"ltp":0.0,"tv":0.0,"id":60443}]}]}
{"op":"mcm","clk":"11887411739","pt":1724136776417,"mc":[{"id":"1.231804628","rc":[{"batb":[[0,1.59,14.54],[1,1.58,12],[2,1.5,20]],"ltp":1.04,"tv":0.91,"id":5995},{"batb":[[0,1.59,14.54],[1,1.58,11],[2,1.5,20]],"ltp":1.13,"tv":6.91,"id":2120},{"batb":[[0,1.47,19.14],[1,1.46,55.47],[2,1.3,20]],"ltp":0.0,"tv":0.0,"id":60443}]}]}
{"op":"mcm","clk":"11887488427","pt":1724138577438,"mc":[{"id":"1.231804628","rc":[{"batb":[[0,1.58,12],[1,1.5,20],[2,1.09,222.22]],"ltp":1.04,"tv":0.91,"id":5995},{"trd":[[1.04,2.37],[1.13,2.54]],"batb":[[0,1.58,11],[1,1.5,20],[2,1.09,222.22]],"ltp":1.13,"tv":6.91,"id":2120},{"batb":[[0,1.46,56.33],[1,1.3,20],[2,1.09,222.22]],"ltp":0.0,"tv":0.0,"id":60443}],"tv":7.82}]}
{"op":"mcm","clk":"11887490646","pt":1724138639275,"mc":[{"id":"1.231804628","rc":[{"batb":[[0,1.59,14.53],[1,1.58,12],[2,1.5,20]],"ltp":1.04,"tv":0.91,"id":5995},{"batb":[[0,1.59,14.53],[1,1.58,11],[2,1.5,20]],"ltp":1.13,"tv":6.91,"id":2120},{"batb":[[0,1.47,19.13],[1,1.46,55.43],[2,1.3,20]],"ltp":0.0,"tv":0.0,"id":60443}]}]}
{"op":"mcm","clk":"11887573170","pt":1724140440129,"mc":[{"id":"1.231804628","rc":[{"batb":[[0,1.58,12],[1,1.5,20],[2,1.09,222.22]],"ltp":1.04,"tv":0.91,"id":5995},{"batb":[[0,1.58,11],[1,1.5,20],[2,1.09,222.22]],"ltp":1.13,"tv":6.91,"id":2120},{"batb":[[0,1.46,56.33],[1,1.3,20],[2,1.09,222.22]],"ltp":0.0,"tv":0.0,"id":60443}]}]}
{"op":"mcm","clk":"11887575624","pt":1724140503499,"mc":[{"id":"1.231804628","rc":[{"batb":[[0,1.59,14.53],[1,1.58,12],[2,1.5,20]],"ltp":1.04,"tv":0.91,"id":5995},{"batb":[[0,1.59,14.53],[1,1.58,11],[2,1.5,20]],"ltp":1.13,"tv":6.91,"id":2120},{"batb":[[0,1.47,19.13],[1,1.46,55.43],[2,1.3,20]],"ltp":0.0,"tv":0.0,"id":60443}]}]}
{"op":"mcm","clk":"11887662434","pt":1724142304017,"mc":[{"id":"1.231804628","rc":[{"batb":[[0,1.58,12],[1,1.5,20],[2,1.09,222.22]],"ltp":1.04,"tv":0.91,"id":5995},{"batb":[[0,1.58,11],[1,1.5,20],[2,1.09,222.22]],"ltp":1.13,"tv":6.9,"id":2120},{"batb":[[0,1.46,56.32],[1,1.3,20],[2,1.09,222.22]],"ltp":0.0,"tv":0.0,"id":60443}],"tv":7.82}]}
{"op":"mcm","clk":"11887669321","pt":1724142440714,"mc":[{"id":"1.231804628","rc":[{"batb":[[0,1.59,14.53],[1,1.58,12],[2,1.5,20]],"ltp":1.04,"tv":0.91,"id":5995},{"batb":[[0,1.59,14.53],[1,1.58,11],[2,1.5,20]],"ltp":1.13,"tv":6.9,"id":2120},{"batb":[[0,1.47,19.13],[1,1.46,55.42],[2,1.3,20]],"ltp":0.0,"tv":0.0,"id":60443}]}]}
{"op":"mcm","clk":"11887755927","pt":1724144241279,"mc":[{"id":"1.231804628","rc":[{"batb":[[0,1.58,12],[1,1.5,20],[2,1.09,222.22]],"ltp":1.04,"tv":0.91,"id":5995},{"batb":[[0,1.58,11],[1,1.5,20],[2,1.09,222.22]],"ltp":1.13,"tv":6.9,"id":2120},{"batb":[[0,1.46,56.32],[1,1.3,20],[2,1.09,222.22]],"ltp":0.0,"tv":0.0,"id":60443}]}]}
{"op":"mcm","clk":"11887757935","pt":1724144284394,"mc":[{"id":"1.231804628","rc":[{"batb":[[0,1.59,14.53],[1,1.58,12],[2,1.5,20]],"ltp":1.04,"tv":0.91,"id":5995},{"batb":[[0,1.59,14.53],[1,1.58,11],[2,1.5,20]],"ltp":1.13,"tv":6.9,"id":2120},{"batb":[[0,1.47,19.13],[1,1.46,55.42],[2,1.3,20]],"ltp":0.0,"tv":0.0,"id":60443}]}]}
{"op":"mcm","clk":"11887800490","pt":1724145174908,"mc":[{"id":"1.231804628","rc":[{"batb":[[0,1.59,14.52]],"ltp":1.04,"tv":0.91,"id":5995},{"batb":[[0,1.59,14.52]],"ltp":1.13,"tv":6.9,"id":2120},{"batb":[[0,1.47,19.12],[1,1.46,55.4]],"ltp":0.0,"tv":0.0,"id":60443}]}]}
{"op":"mcm","clk":"11887842054","pt":1724146085057,"mc":[{"id":"1.231804628","rc":[{"batb":[[0,1.58,12],[1,1.5,20],[2,1.09,222.22]],"ltp":1.04,"tv":0.91,"id":5995},{"batb":[[0,1.58,11],[1,1.5,20],[2,1.09,222.22]],"ltp":1.13,"tv":6.9,"id":2120},{"batb":[[0,1.46,56.29],[1,1.3,20],[2,1.09,222.22]],"ltp":0.0,"tv":0.0,"id":60443}]}]}
{"op":"mcm","clk":"11887843467","pt":1724146121588,"mc":[{"id":"1.231804628","rc":[{"batb":[[0,1.59,14.52],[1,1.58,12],[2,1.5,20]],"ltp":1.04,"tv":0.91,"id":5995},{"batb":[[0,1.59,14.52],[1,1.58,11],[2,1.5,20]],"ltp":1.13,"tv":6.9,"id":2120},{"batb":[[0,1.47,19.12],[1,1.46,55.4],[2,1.3,20]],"ltp":0.0,"tv":0.0,"id":60443}]}]}
{"op":"mcm","clk":"11887928013","pt":1724147923417,"mc":[{"id":"1.231804628","rc":[{"batb":[[0,1.58,12],[1,1.5,20],[2,1.09,222.22]],"ltp":1.04,"tv":0.91,"id":5995},{"batb":[[0,1.46,56.29],[1,1.3,20],[2,1.09,222.22]],"ltp":0.0,"tv":0.0,"id":60443}]}]}
{"op":"mcm","clk":"11887928020","pt":1724147923577,"mc":[{"id":"1.231804628","rc":[{"batb":[[0,1.58,11],[1,1.5,20],[2,1.09,222.22]],"ltp":1.13,"tv":6.9,"id":2120}]}]}
{"op":"mcm","clk":"11887929459","pt":1724147953531,"mc":[{"id":"1.231804628","rc":[{"batb":[[0,1.59,14.52],[1,1.58,12],[2,1.5,20]],"ltp":1.04,"tv":0.91,"id":5995},{"batb":[[0,1.59,14.52],[1,1.58,11],[2,1.5,20]],"ltp":1.13,"tv":6.9,"id":2120},{"batb":[[0,1.47,19.12],[1,1.46,55.4],[2,1.3,20]],"ltp":0.0,"tv":0.0,"id":60443}]}]}
{"op":"mcm","clk":"11888021491","pt":1724149754151,"mc":[{"id":"1.231804628","rc":[{"batb":[[0,1.58,12],[1,1.5,20],[2,1.09,222.22]],"ltp":1.04,"tv":0.91,"id":5995},{"batb":[[0,1.58,11],[1,1.5,20],[2,1.09,222.22]],"ltp":1.13,"tv":6.9,"id":2120},{"batb":[[0,1.46,56.26],[1,1.3,20],[2,1.09,222.22]],"ltp":0.0,"tv":0.0,"id":60443}]}]}
{"op":"mcm","clk":"11888022880","pt":1724149785383,"mc":[{"id":"1.231804628","rc":[{"batb":[[0,1.59,14.51],[1,1.58,12],[2,1.5,20]],"ltp":1.04,"tv":0.91,"id":5995},{"batb":[[0,1.59,14.51],[1,1.58,11],[2,1.5,20]],"ltp":1.13,"tv":6.9,"id":2120},{"batb":[[0,1.47,19.11],[1,1.46,55.37],[2,1.3,20]],"ltp":0.0,"tv":0.0,"id":60443}]}]}
{"op":"mcm","clk":"11888116387","pt":1724151587209,"mc":[{"id":"1.231804628","rc":[{"batb":[[0,1.58,12],[1,1.5,20],[2,1.09,222.22]],"ltp":1.04,"tv":0.91,"id":5995},{"batb":[[0,1.58,11],[1,1.5,20],[2,1.09,222.22]],"ltp":1.13,"tv":6.9,"id":2120},{"batb":[[0,1.46,56.26],[1,1.3,20],[2,1.09,222.22]],"ltp":0.0,"tv":0.0,"id":60443}]}]}
{"op":"mcm","clk":"11888117056","pt":1724151601615,"mc":[{"id":"1.231804628","rc":[{"batb":[[0,1.59,14.51],[1,1.58,12],[2,1.5,20]],"ltp":1.04,"tv":0.91,"id":5995},{"batb":[[0,1.59,14.51],[1,1.58,11],[2,1.5,20]],"ltp":1.13,"tv":6.9,"id":2120},{"batb":[[0,1.47,19.11],[1,1.46,55.37],[2,1.3,20]],"ltp":0.0,"tv":0.0,"id":60443}]}]}
{"op":"mcm","clk":"11888212533","pt":1724153402155,"mc":[{"id":"1.231804628","rc":[{"batb":[[0,1.58,12],[1,1.5,20],[2,1.09,222.22]],"ltp":1.04,"tv":0.91,"id":5995},{"batb":[[0,1.58,11],[1,1.5,20],[2,1.09,222.22]],"ltp":1.13,"tv":6.9,"id":2120},{"batb":[[0,1.46,56.29],[1,1.3,20],[2,1.09,222.22]],"ltp":0.0,"tv":0.0,"id":60443}]}]}
{"op":"mcm","clk":"11888212604","pt":1724153403453,"mc":[{"id":"1.231804628","rc":[{"batb":[[0,1.59,14.52],[1,1.58,12],[2,1.5,20]],"ltp":1.04,"tv":0.91,"id":5995},{"batb":[[0,1.59,14.52],[1,1.58,11],[2,1.5,20]],"ltp":1.13,"tv":6.9,"id":2120},{"batb":[[0,1.47,19.12],[1,1.46,55.39],[2,1.3,20]],"ltp":0.0,"tv":0.0,"id":60443}]}]}
{"op":"mcm","clk":"11888295328","pt":1724155205298,"mc":[{"id":"1.231804628","rc":[{"batb":[[0,1.59,14.51]],"ltp":1.04,"tv":0.91,"id":5995},{"batb":[[0,1.59,14.51]],"ltp":1.13,"tv":6.9,"id":2120},{"batb":[[0,1.46,56.26],[1,1.3,20],[2,1.09,222.22]],"ltp":0.0,"tv":0.0,"id":60443}],"tv":7.81}]}
{"op":"mcm","clk":"11888295350","pt":1724155205813,"mc":[{"id":"1.231804628","rc":[{"batb":[[0,1.58,12],[1,1.5,20],[2,1.09,222.22]],"ltp":1.04,"tv":0.91,"id":5995},{"batb":[[0,1.58,11],[1,1.5,20],[2,1.09,222.22]],"ltp":1.13,"tv":6.9,"id":2120}]}]}
{"op":"mcm","clk":"11888300870","pt":1724155344281,"mc":[{"id":"1.231804628","rc":[{"batb":[[0,1.59,14.51],[1,1.58,12],[2,1.5,20]],"ltp":1.04,"tv":0.91,"id":5995},{"batb":[[0,1.59,14.51],[1,1.58,11],[2,1.5,20]],"ltp":1.13,"tv":6.9,"id":2120},{"batb":[[0,1.47,19.11],[1,1.46,55.36],[2,1.3,20]],"ltp":0.0,"tv":0.0,"id":60443}]}]}
{"op":"mcm","clk":"11888353249","pt":1724156300462,"mc":[{"id":"1.231804628","rc":[{"batb":[[0,1.6,12],[1,1.59,14.51]],"ltp":1.04,"tv":0.91,"id":5995},{"batb":[[0,1.6,11],[1,1.59,14.51]],"ltp":1.13,"tv":6.9,"id":2120}]}]}
{"op":"mcm","clk":"11888393843","pt":1724157145007,"mc":[{"id":"1.231804628","rc":[{"batb":[[1,1.5,20],[2,1.09,222.22]],"ltp":1.04,"tv":0.91,"id":5995},{"batb":[[1,1.5,20],[2,1.09,222.22]],"ltp":1.13,"tv":6.9,"id":2120},{"batb":[[0,1.46,56.26],[1,1.3,20],[2,1.09,222.22]],"ltp":0.0,"tv":0.0,"id":60443}]}]}
{"op":"mcm","clk":"11888395576","pt":1724157179349,"mc":[{"id":"1.231804628","rc":[{"batb":[[0,1.61,14.03],[1,1.6,12],[2,1.5,20]],"ltp":1.04,"tv":0.91,"id":5995},{"batb":[[0,1.61,14.03],[1,1.6,11],[2,1.5,20]],"ltp":1.13,"tv":6.9,"id":2120},{"batb":[[0,1.47,19.11],[1,1.46,55.36],[2,1.3,20]],"ltp":0.0,"tv":0.0,"id":60443}]}]}
{"op":"mcm","clk":"11888475478","pt":1724158981301,"mc":[{"id":"1.231804628","rc":[{"trd":[[1.04,2.36],[1.13,2.54]],"ltp":1.13,"tv":6.9,"id":2120},{"batb":[[0,1.46,56.26],[1,1.3,20],[2,1.09,222.22]],"ltp":0.0,"tv":0.0,"id":60443}],"tv":7.81}]}
{"op":"mcm","clk":"11888475496","pt":1724158981670,"mc":[{"id":"1.231804628","rc":[{"batb":[[0,1.6,12],[1,1.5,20],[2,1.09,222.22]],"ltp":1.04,"tv":0.91,"id":5995},{"batb":[[0,1.6,11],[1,1.5,20],[2,1.09,222.22]],"ltp":1.13,"tv":6.9,"id":2120}]}]}
{"op":"mcm","clk":"11888476441","pt":1724159002085,"mc":[{"id":"1.231804628","rc":[{"batb":[[0,1.61,14.03],[1,1.6,12],[2,1.5,20]],"ltp":1.04,"tv":0.91,"id":5995},{"batb":[[0,1.61,14.03],[1,1.6,11],[2,1.5,20]],"ltp":1.13,"tv":6.9,"id":2120},{"batb":[[0,1.47,19.11],[1,1.46,55.37],[2,1.3,20]],"ltp":0.0,"tv":0.0,"id":60443}]}]}
{"op":"mcm","clk":"11888568855","pt":1724160802383,"mc":[{"id":"1.231804628","rc":[{"batb":[[0,1.46,56.26],[1,1.3,20],[2,1.09,222.22]],"ltp":0.0,"tv":0.0,"id":60443}]}]}
{"op":"mcm","clk":"11888568869","pt":1724160802796,"mc":[{"id":"1.231804628","rc":[{"batb":[[0,1.6,12],[1,1.5,20],[2,1.09,222.22]],"ltp":1.04,"tv":0.91,"id":5995},{"batb":[[0,1.6,11],[1,1.5,20],[2,1.09,222.22]],"ltp":1.13,"tv":6.9,"id":2120}]}]}
{"op":"mcm","clk":"11888569372","pt":1724160813371,"mc":[{"id":"1.231804628","rc":[{"batb":[[0,1.61,14.03],[1,1.6,12],[2,1.5,20]],"ltp":1.04,"tv":0.91,"id":5995},{"batb":[[0,1.61,14.03],[1,1.6,11],[2,1.5,20]],"ltp":1.13,"tv":6.9,"id":2120},{"batb":[[0,1.47,19.11],[1,1.46,55.37],[2,1.3,20]],"ltp":0.0,"tv":0.0,"id":60443}]}]}
{"op":"mcm","clk":"11888615850","pt":1724161553437,"mc":[{"id":"1.231804628","rc":[{"batb":[[0,1.47,18.21]],"ltp":0.0,"tv":0.0,"id":60443}]}]}
{"op":"mcm","clk":"11888667645","pt":1724162614035,"mc":[{"id":"1.231804628","rc":[{"batb":[[0,1.6,12],[1,1.5,20],[2,1.09,222.22]],"ltp":1.04,"tv":0.91,"id":5995},{"batb":[[0,1.6,11],[1,1.5,20],[2,1.09,222.22]],"ltp":1.13,"tv":6.9,"id":2120},{"batb":[[0,1.46,55.39],[1,1.3,20],[2,1.09,222.22]],"ltp":0.0,"tv":0.0,"id":60443}]}]}
{"op":"mcm","clk":"11888667859","pt":1724162617641,"mc":[{"id":"1.231804628","rc":[{"batb":[[0,1.61,14.04],[1,1.6,12],[2,1.5,20]],"ltp":1.04,"tv":0.91,"id":5995},{"batb":[[0,1.61,14.04],[1,1.6,11],[2,1.5,20]],"ltp":1.13,"tv":6.9,"id":2120},{"batb":[[0,1.47,18.22],[1,1.46,55.39],[2,1.3,20]],"ltp":0.0,"tv":0.0,"id":60443}]}]}
{"op":"mcm","clk":"11888769791","pt":1724164418286,"mc":[{"id":"1.231804628","rc":[{"batb":[[0,1.6,12],[1,1.5,20],[2,1.09,222.22]],"ltp":1.04,"tv":0.91,"id":5995},{"batb":[[0,1.6,11],[1,1.5,20],[2,1.09,222.22]],"ltp":1.13,"tv":6.9,"id":2120},{"batb":[[0,1.46,55.39],[1,1.3,20],[2,1.09,222.22]],"ltp":0.0,"tv":0.0,"id":60443}]}]}
{"op":"mcm","clk":"11888780350","pt":1724164575142,"mc":[{"id":"1.231804628","rc":[{"batb":[[0,1.61,14.04],[1,1.6,12],[2,1.5,20]],"ltp":1.04,"tv":0.91,"id":5995},{"batb":[[0,1.61,14.04],[1,1.6,11],[2,1.5,20]],"ltp":1.13,"tv":6.9,"id":2120},{"batb":[[0,1.47,18.22],[1,1.46,55.39],[2,1.3,20]],"ltp":0.0,"tv":0.0,"id":60443}]}]}
{"op":"mcm","clk":"11888893943","pt":1724166315354,"mc":[{"id":"1.231804628","rc":[{"batb":[[0,1.61,14.05]],"batl":[[2,1000,0.17]],"ltp":1.04,"tv":0.91,"id":5995},{"batb":[[0,1.61,14.05]],"batl":[[2,1000,0.17]],"ltp":1.13,"tv":6.9,"id":2120},{"batb":[[0,1.47,18.23],[1,1.46,55.43]],"batl":[[2,1000,0.17]],"ltp":0.0,"tv":0.0,"id":60443}]}]}
{"op":"mcm","clk":"11888893979","pt":1724166315769,"mc":[{"id":"1.231804628","rc":[{"batl":[[0,90,1.02],[1,95,5],[2,990,5]],"ltp":1.04,"tv":0.91,"id":5995},{"batl":[[0,90,1.02],[1,95,5],[2,990,5]],"ltp":1.13,"tv":6.9,"id":2120},{"batl":[[0,90,1.02],[1,95,5],[2,990,5]],"ltp":0.0,"tv":0.0,"id":60443}]}]}
{"op":"mcm","clk":"11888897749","pt":1724166375314,"mc":[{"id":"1.231804628","rc":[{"batb":[[0,1.6,12],[1,1.5,20],[2,1.09,222.22]],"ltp":1.04,"tv":0.91,"id":5995}]}]}
{"op":"mcm","clk":"11888897770","pt":1724166375727,"mc":[{"id":"1.231804628","rc":[{"batb":[[0,1.6,11],[1,1.5,20],[2,1.09,222.22]],"ltp":1.13,"tv":6.9,"id":2120},{"batb":[[0,1.46,55.43],[1,1.3,20],[2,1.09,222.22]],"ltp":0.0,"tv":0.0,"id":60443}]}]}
{"op":"mcm","clk":"11888898242","pt":1724166383550,"mc":[{"id":"1.231804628","rc":[{"batl":[[2,990,5.17]],"ltp":1.04,"tv":0.91,"id":5995},{"batl":[[2,990,5.17]],"ltp":1.13,"tv":6.9,"id":2120},{"batl":[[2,990,5.17]],"ltp":0.0,"tv":0.0,"id":60443}]}]}
{"op":"mcm","clk":"11888899667","pt":1724166405245,"mc":[{"id":"1.231804628","rc":[{"batl":[[2,990,5.34]],"ltp":1.04,"tv":0.91,"id":5995},{"batl":[[2,990,5.34]],"ltp":1.13,"tv":6.9,"id":2120},{"batl":[[2,990,5.34]],"ltp":0.0,"tv":0.0,"id":60443}]}]}
{"op":"mcm","clk":"11888904219","pt":1724166471400,"mc":[{"id":"1.231804628","rc":[{"batl":[[2,990,5.51]],"ltp":1.04,"tv":0.91,"id":5995},{"batl":[[2,990,5.51]],"ltp":1.13,"tv":6.9,"id":2120},{"batl":[[2,990,5.51]],"ltp":0.0,"tv":0.0,"id":60443}]}]}
{"op":"mcm","clk":"11888907154","pt":1724166515337,"mc":[{"id":"1.231804628","rc":[{"batb":[[0,1.61,14.05],[1,1.6,12],[2,1.5,20]],"ltp":1.04,"tv":0.91,"id":5995},{"batb":[[0,1.61,14.05],[1,1.6,11],[2,1.5,20]],"ltp":1.13,"tv":6.9,"id":2120},{"batb":[[0,1.47,18.23],[1,1.46,55.43],[2,1.3,20]],"ltp":0.0,"tv":0.0,"id":60443}]}]}
{"op":"mcm","clk":"11889069676","pt":1724168316409,"mc":[{"id":"1.231804628","rc":[{"batb":[[0,1.6,12],[1,1.5,20],[2,1.09,222.22]],"ltp":1.04,"tv":0.91,"id":5995},{"batb":[[0,1.6,11],[1,1.5,20],[2,1.09,222.22]],"ltp":1.13,"tv":6.9,"id":2120},{"batb":[[0,1.46,55.43],[1,1.3,20],[2,1.09,222.22]],"ltp":0.0,"tv":0.0,"id":60443}]}]}
{"op":"mcm","clk":"11889080924","pt":1724168445467,"mc":[{"id":"1.231804628","rc":[{"batb":[[0,1.61,14.05],[1,1.6,12],[2,1.5,20]],"ltp":1.04,"tv":0.91,"id":5995},{"batb":[[0,1.61,14.05],[1,1.6,11],[2,1.5,20]],"ltp":1.13,"tv":6.9,"id":2120},{"batb":[[0,1.47,18.23],[1,1.46,55.43],[2,1.3,20]],"ltp":0.0,"tv":0.0,"id":60443}]}]}
{"op":"mcm","clk":"11889242518","pt":1724170246389,"mc":[{"id":"1.231804628","rc":[{"batb":[[0,1.6,12],[1,1.5,20],[2,1.09,222.22]],"ltp":1.04,"tv":0.91,"id":5995},{"batb":[[0,1.6,11],[1,1.5,20],[2,1.09,222.22]],"ltp":1.13,"tv":6.9,"id":2120},{"batb":[[0,1.46,55.42],[1,1.3,20],[2,1.09,222.22]],"ltp":0.0,"tv":0.0,"id":60443}],"tv":7.81}]}
{"op":"mcm","clk":"11889253719","pt":1724170363012,"mc":[{"id":"1.231804628","rc":[{"batb":[[0,1.61,14.05],[1,1.6,12],[2,1.5,20]],"ltp":1.04,"tv":0.91,"id":5995},{"batb":[[0,1.61,14.05],[1,1.6,11],[2,1.5,20]],"ltp":1.13,"tv":6.9,"id":2120},{"batb":[[0,1.47,18.23],[1,1.46,55.42],[2,1.3,20]],"ltp":0.0,"tv":0.0,"id":60443}]}]}
{"op":"mcm","clk":"11889413988","pt":1724172164315,"mc":[{"id":"1.231804628","rc":[{"batb":[[0,1.6,11],[1,1.5,20],[2,1.09,222.22]],"ltp":1.13,"tv":6.9,"id":2120},{"batb":[[0,1.46,55.42],[1,1.3,20],[2,1.09,222.22]],"ltp":0.0,"tv":0.0,"id":60443}]}]}
{"op":"mcm","clk":"11889414007","pt":1724172164529,"mc":[{"id":"1.231804628","rc":[{"batb":[[0,1.6,12],[1,1.5,20],[2,1.09,222.22]],"ltp":1.04,"tv":0.91,"id":5995}]}]}
{"op":"mcm","clk":"11889434405","pt":1724172256722,"mc":[{"id":"1.231804628","rc":[{"batb":[[0,1.61,14.05],[1,1.6,12],[2,1.5,20]],"ltp":1.04,"tv":0.91,"id":5995},{"batb":[[0,1.61,14.05],[1,1.6,11],[2,1.5,20]],"ltp":1.13,"tv":6.9,"id":2120},{"batb":[[0,1.47,18.23],[1,1.46,55.42],[2,1.3,20]],"ltp":0.0,"tv":0.0,"id":60443}]}]}
{"op":"mcm","clk":"11889632335","pt":1724174057959,"mc":[{"id":"1.231804628","rc":[{"batb":[[0,1.6,12],[1,1.5,20],[2,1.09,222.22]],"ltp":1.04,"tv":0.91,"id":5995},{"batb":[[0,1.6,11],[1,1.5,20],[2,1.09,222.22]],"ltp":1.13,"tv":6.9,"id":2120},{"batb":[[0,1.46,55.47],[1,1.3,20],[2,1.09,222.22]],"ltp":0.0,"tv":0.0,"id":60443}]}]}
{"op":"mcm","clk":"11889641447","pt":1724174127837,"mc":[{"id":"1.231804628","rc":[{"batb":[[0,1.61,14.06],[1,1.6,12],[2,1.5,20]],"ltp":1.04,"tv":0.91,"id":5995},{"batb":[[0,1.61,14.06],[1,1.6,11],[2,1.5,20]],"ltp":1.13,"tv":6.9,"id":2120},{"batb":[[0,1.47,18.25],[1,1.46,55.47],[2,1.3,20]],"ltp":0.0,"tv":0.0,"id":60443}]}]}
{"op":"mcm","clk":"11889867231","pt":1724175928388,"mc":[{"id":"1.231804628","rc":[{"batb":[[0,1.6,12],[1,1.5,20],[2,1.09,222.22]],"ltp":1.04,"tv":0.91,"id":5995},{"batb":[[0,1.6,11],[1,1.5,20],[2,1.09,222.22]],"ltp":1.13,"tv":6.9,"id":2120},{"batb":[[0,1.46,55.47],[1,1.3,20],[2,1.09,222.22]],"ltp":0.0,"tv":0.0,"id":60443}]}]}
{"op":"mcm","clk":"11889872166","pt":1724175963826,"mc":[{"id":"1.231804628","rc":[{"batb":[[0,1.61,14.06],[1,1.6,12],[2,1.5,20]],"ltp":1.04,"tv":0.91,"id":5995},{"batb":[[0,1.61,14.06],[1,1.6,11],[2,1.5,20]],"ltp":1.13,"tv":6.9,"id":2120},{"batb":[[0,1.47,18.25],[1,1.46,55.47],[2,1.3,20]],"ltp":0.0,"tv":0.0,"id":60443}]}]}
{"op":"mcm","clk":"11890006346","pt":1724176990117,"mc":[{"id":"1.231804628","rc":[{"batb":[[0,1.61,14.07]],"ltp":1.04,"tv":0.91,"id":5995},{"batb":[[0,1.61,14.07]],"batl":[[0,85,1.17],[1,95,5.85]],"ltp":1.13,"tv":6.9,"id":2120},{"batb":[[0,1.47,18.26],[1,1.46,55.49]],"ltp":0.0,"tv":0.0,"id":60443}],"tv":7.81}]}
{"op":"mcm","clk":"11890017070","pt":1724177064636,"mc":[{"id":"1.231804628","rc":[{"batl":[[0,85,1.17],[1,95,5.85]],"ltp":1.04,"tv":0.91,"id":5995}]}]}
{"op":"mcm","clk":"11890023403","pt":1724177109083,"mc":[{"id":"1.231804628","rc":[{"batl":[[0,85,1.17],[1,95,5.85]],"ltp":0.0,"tv":0.0,"id":60443}]}]}
{"op":"mcm","clk":"11890137126","pt":1724177764920,"mc":[{"id":"1.231804628","rc":[{"batb":[[0,1.6,12],[1,1.5,20],[2,1.09,222.22]],"ltp":1.04,"tv":0.91,"id":5995},{"batb":[[0,1.6,11],[1,1.5,20],[2,1.09,222.22]],"ltp":1.13,"tv":6.9,"id":2120},{"batb":[[0,1.46,55.49],[1,1.3,20],[2,1.09,222.22]],"ltp":0.0,"tv":0.0,"id":60443}]}]}
{"op":"mcm","clk":"11890138327","pt":1724177772032,"mc":[{"id":"1.231804628","rc":[{"batb":[[0,1.61,14.07],[1,1.6,12],[2,1.5,20]],"ltp":1.04,"tv":0.91,"id":5995},{"batb":[[0,1.61,14.07],[1,1.6,11],[2,1.5,20]],"ltp":1.13,"tv":6.9,"id":2120},{"batb":[[0,1.47,18.26],[1,1.46,55.49],[2,1.3,20]],"ltp":0.0,"tv":0.0,"id":60443}]}]}
{"op":"mcm","clk":"11890401655","pt":1724179572520,"mc":[{"id":"1.231804628","rc":[{"batb":[[0,1.6,12],[1,1.5,20],[2,1.09,222.22]],"ltp":1.04,"tv":0.91,"id":5995},{"batb":[[0,1.46,55.49],[1,1.3,20],[2,1.09,222.22]],"ltp":0.0,"tv":0.0,"id":60443}]}]}
{"op":"mcm","clk":"11890401700","pt":1724179572845,"mc":[{"id":"1.231804628","rc":[{"batb":[[0,1.6,11],[1,1.5,20],[2,1.09,222.22]],"ltp":1.13,"tv":6.9,"id":2120}]}]}
{"op":"mcm","clk":"11890421813","pt":1724179676959,"mc":[{"id":"1.231804628","rc":[{"batb":[[0,1.61,14.07],[1,1.6,12],[2,1.5,20]],"ltp":1.04,"tv":0.91,"id":5995},{"batb":[[0,1.61,14.07],[1,1.6,11],[2,1.5,20]],"ltp":1.13,"tv":6.9,"id":2120},{"batb":[[0,1.47,18.26],[1,1.46,55.49],[2,1.3,20]],"ltp":0.0,"tv":0.0,"id":60443}]}]}
{"op":"mcm","clk":"11890767228","pt":1724181478517,"mc":[{"id":"1.231804628","rc":[{"batb":[[0,1.6,12],[1,1.5,20],[2,1.09,222.22]],"ltp":1.04,"tv":0.91,"id":5995},{"batb":[[0,1.6,11],[1,1.5,20],[2,1.09,222.22]],"ltp":1.13,"tv":6.9,"id":2120},{"batb":[[0,1.46,55.47],[1,1.3,20],[2,1.09,222.22]],"ltp":0.0,"tv":0.0,"id":60443}],"tv":7.81}]}
{"op":"mcm","clk":"11890779127","pt":1724181537510,"mc":[{"id":"1.231804628","rc":[{"batb":[[0,1.61,14.06],[1,1.6,12],[2,1.5,20]],"ltp":1.04,"tv":0.91,"id":5995},{"batb":[[0,1.61,14.06],[1,1.6,11],[2,1.5,20]],"ltp":1.13,"tv":6.9,"id":2120},{"batb":[[0,1.47,18.25],[1,1.46,55.47],[2,1.3,20]],"ltp":0.0,"tv":0.0,"id":60443}]}]}
{"op":"mcm","clk":"11891087617","pt":1724183338378,"mc":[{"id":"1.231804628","rc":[{"batb":[[0,1.6,12],[1,1.5,20],[2,1.09,222.22]],"ltp":1.04,"tv":0.91,"id":5995}]}]}
{"op":"mcm","clk":"11891087679","pt":1724183338795,"mc":[{"id":"1.231804628","rc":[{"batb":[[0,1.6,11],[1,1.5,20],[2,1.09,222.22]],"ltp":1.13,"tv":6.9,"id":2120},{"batb":[[0,1.46,55.47],[1,1.3,20],[2,1.09,222.22]],"ltp":0.0,"tv":0.0,"id":60443}]}]}
{"op":"mcm","clk":"11891094031","pt":1724183377754,"mc":[{"id":"1.231804628","rc":[{"batb":[[0,1.61,14.06],[1,1.6,12],[2,1.5,20]],"ltp":1.04,"tv":0.91,"id":5995},{"batb":[[0,1.61,14.06],[1,1.6,11],[2,1.5,20]],"ltp":1.13,"tv":6.9,"id":2120},{"batb":[[0,1.47,18.25],[1,1.46,55.47],[2,1.3,20]],"ltp":0.0,"tv":0.0,"id":60443}]}]}
{"op":"mcm","clk":"11891385939","pt":1724185178868,"mc":[{"id":"1.231804628","rc":[{"batb":[[0,1.6,12],[1,1.5,20],[2,1.09,222.22]],"ltp":1.04,"tv":0.91,"id":5995},{"batb":[[0,1.6,11],[1,1.5,20],[2,1.09,222.22]],"ltp":1.13,"tv":6.9,"id":2120},{"batb":[[0,1.46,55.48],[1,1.3,20],[2,1.09,222.22]],"ltp":0.0,"tv":0.0,"id":60443}]}]}
{"op":"mcm","clk":"11891406521","pt":1724185306231,"mc":[{"id":"1.231804628","rc":[{"batb":[[0,1.61,14.06],[1,1.6,12],[2,1.5,20]],"ltp":1.04,"tv":0.91,"id":5995},{"batb":[[0,1.61,14.06],[1,1.6,11],[2,1.5,20]],"ltp":1.13,"tv":6.9,"id":2120},{"batb":[[0,1.47,18.25],[1,1.46,55.48],[2,1.3,20]],"ltp":0.0,"tv":0.0,"id":60443}]}]}
{"op":"mcm","clk":"11891593326","pt":1724187107387,"mc":[{"id":"1.231804628","rc":[{"batb":[[0,1.6,12],[1,1.5,20],[2,1.09,222.22]],"ltp":1.04,"tv":0.91,"id":5995},{"batb":[[0,1.6,11],[1,1.5,20],[2,1.09,222.22]],"ltp":1.13,"tv":6.9,"id":2120}]}]}
{"op":"mcm","clk":"11891593342","pt":1724187107591,"mc":[{"id":"1.231804628","rc":[{"batb":[[0,1.46,55.48],[1,1.3,20],[2,1.09,222.22]],"ltp":0.0,"tv":0.0,"id":60443}]}]}
{"op":"mcm","clk":"11891596865","pt":1724187165921,"mc":[{"id":"1.231804628","rc":[{"batb":[[0,1.61,14.06],[1,1.6,12],[2,1.5,20]],"ltp":1.04,"tv":0.91,"id":5995},{"batb":[[0,1.61,14.06],[1,1.6,11],[2,1.5,20]],"ltp":1.13,"tv":6.9,"id":2120},{"batb":[[0,1.47,18.25],[1,1.46,55.48],[2,1.3,20]],"ltp":0.0,"tv":0.0,"id":60443}]}]}
{"op":"mcm","clk":"11891674000","pt":1724188374965,"mc":[{"id":"1.231804628","rc":[{"batb":[[0,1.61,14.07]],"ltp":1.04,"tv":0.91,"id":5995},{"batb":[[0,1.61,14.07]],"ltp":1.13,"tv":6.9,"id":2120},{"batb":[[0,1.47,18.26],[1,1.46,55.5]],"ltp":0.0,"tv":0.0,"id":60443}]}]}
{"op":"mcm","clk":"11891712197","pt":1724188967463,"mc":[{"id":"1.231804628","rc":[{"batb":[[0,1.6,12],[1,1.5,20],[2,1.09,222.22]],"ltp":1.04,"tv":0.91,"id":5995},{"batb":[[0,1.46,55.5],[1,1.3,20],[2,1.09,222.22]],"ltp":0.0,"tv":0.0,"id":60443}]}]}
{"op":"mcm","clk":"11891712208","pt":1724188967668,"mc":[{"id":"1.231804628","rc":[{"batb":[[0,1.6,11],[1,1.5,20],[2,1.09,222.22]],"ltp":1.13,"tv":6.9,"id":2120}]}]}
{"op":"mcm","clk":"11891717122","pt":1724189057315,"mc":[{"id":"1.231804628","rc":[{"batb":[[0,1.61,14.07],[1,1.6,12],[2,1.5,20]],"ltp":1.04,"tv":0.91,"id":5995},{"batb":[[0,1.61,14.07],[1,1.6,11],[2,1.5,20]],"ltp":1.13,"tv":6.9,"id":2120},{"batb":[[0,1.47,18.26],[1,1.46,55.5],[2,1.3,20]],"ltp":0.0,"tv":0.0,"id":60443}]}]}
{"op":"mcm","clk":"11891815229","pt":1724190858032,"mc":[{"id":"1.231804628","rc":[{"batb":[[0,1.6,12],[1,1.5,20],[2,1.09,222.22]],"ltp":1.04,"tv":0.91,"id":5995},{"batb":[[0,1.6,11],[1,1.5,20],[2,1.09,222.22]],"ltp":1.13,"tv":6.9,"id":2120},{"batb":[[0,1.46,55.5],[1,1.3,20],[2,1.09,222.22]],"ltp":0.0,"tv":0.0,"id":60443}]}]}
{"op":"mcm","clk":"11891818448","pt":1724190909660,"mc":[{"id":"1.231804628","rc":[{"batb":[[0,1.61,14.07],[1,1.6,12],[2,1.5,20]],"ltp":1.04,"tv":0.91,"id":5995},{"batb":[[0,1.61,14.07],[1,1.6,11],[2,1.5,20]],"ltp":1.13,"tv":6.9,"id":2120},{"batb":[[0,1.47,18.26],[1,1.46,55.5],[2,1.3,20]],"ltp":0.0,"tv":0.0,"id":60443}]}]}
{"op":"mcm","clk":"11891854935","pt":1724191588464,"mc":[{"id":"1.231804628","rc":[{"batb":[[0,1.62,12],[1,1.61,14.07]],"ltp":1.04,"tv":0.91,"id":5995},{"batb":[[0,1.62,11],[1,1.61,14.07]],"ltp":1.13,"tv":6.9,"id":2120}]}]}
{"op":"mcm","clk":"11891904007","pt":1724192711000,"mc":[{"id":"1.231804628","rc":[{"batb":[[1,1.5,20],[2,1.09,222.22]],"ltp":1.04,"tv":0.91,"id":5995},{"batb":[[1,1.5,20],[2,1.09,222.22]],"ltp":1.13,"tv":6.9,"id":2120},{"batb":[[0,1.46,55.5],[1,1.3,20],[2,1.09,222.22]],"ltp":0.0,"tv":0.0,"id":60443}]}]}
{"op":"mcm","clk":"11891905596","pt":1724192748507,"mc":[{"id":"1.231804628","rc":[{"batb":[[0,1.63,13.62],[1,1.62,12],[2,1.5,20]],"ltp":1.04,"tv":0.91,"id":5995},{"batb":[[0,1.63,13.62],[1,1.62,11],[2,1.5,20]],"ltp":1.13,"tv":6.9,"id":2120},{"batb":[[0,1.47,18.26],[1,1.46,55.5],[2,1.3,20]],"ltp":0.0,"tv":0.0,"id":60443}]}]}
{"op":"mcm","clk":"11891999911","pt":1724194549517,"mc":[{"id":"1.231804628","rc":[{"batb":[[0,1.62,12],[1,1.5,20],[2,1.09,222.22]],"ltp":1.04,"tv":0.91,"id":5995}]}]}
{"op":"mcm","clk":"11891999933","pt":1724194550003,"mc":[{"id":"1.231804628","rc":[{"batb":[[0,1.62,11],[1,1.5,20],[2,1.09,222.22]],"ltp":1.13,"tv":6.9,"id":2120},{"batb":[[0,1.46,55.5],[1,1.3,20],[2,1.09,222.22]],"ltp":0.0,"tv":0.0,"id":60443}]}]}
{"op":"mcm","clk":"11892001009","pt":1724194570731,"mc":[{"id":"1.231804628","rc":[{"batb":[[0,1.63,13.62],[1,1.62,12],[2,1.5,20]],"ltp":1.04,"tv":0.91,"id":5995},{"batb":[[0,1.63,13.62],[1,1.62,11],[2,1.5,20]],"ltp":1.13,"tv":6.9,"id":2120},{"batb":[[0,1.47,18.26],[1,1.46,55.5],[2,1.3,20]],"ltp":0.0,"tv":0.0,"id":60443}]}]}
{"op":"mcm","clk":"11892097247","pt":1724196371344,"mc":[{"id":"1.231804628","rc":[{"batb":[[0,1.62,12],[1,1.5,20],[2,1.09,222.22]],"ltp":1.04,"tv":0.91,"id":5995},{"batb":[[0,1.62,11],[1,1.5,20],[2,1.09,222.22]],"ltp":1.13,"tv":6.9,"id":2120},{"batb":[[0,1.47,18.26],[1,1.46,55.51]],"ltp":0.0,"tv":0.0,"id":60443}]}]}
{"op":"mcm","clk":"11892097259","pt":1724196371546,"mc":[{"id":"1.231804628","rc":[{"batb":[[0,1.46,55.51],[1,1.3,20],[2,1.09,222.22]],"ltp":0.0,"tv":0.0,"id":60443}]}]}
{"op":"mcm","clk":"11892103881","pt":1724196489486,"mc":[{"id":"1.231804628","rc":[{"batb":[[0,1.63,13.63],[1,1.62,12],[2,1.5,20]],"ltp":1.04,"tv":0.91,"id":5995},{"batb":[[0,1.63,13.63],[1,1.62,11],[2,1.5,20]],"ltp":1.13,"tv":6.9,"id":2120},{"batb":[[0,1.47,18.26],[1,1.46,55.51],[2,1.3,20]],"ltp":0.0,"tv":0.0,"id":60443}]}]}
{"op":"mcm","clk":"11892202146","pt":1724198290117,"mc":[{"id":"1.231804628","rc":[{"batb":[[0,1.62,12],[1,1.5,20],[2,1.09,222.22]],"ltp":1.04,"tv":0.91,"id":5995},{"batb":[[0,1.62,11],[1,1.5,20],[2,1.09,222.22]],"ltp":1.13,"tv":6.9,"id":2120},{"batb":[[0,1.46,55.51],[1,1.3,20],[2,1.09,222.22]],"ltp":0.0,"tv":0.0,"id":60443}]}]}
{"op":"mcm","clk":"11892207425","pt":1724198385660,"mc":[{"id":"1.231804628","rc":[{"batb":[[0,1.63,13.63],[1,1.62,12],[2,1.5,20]],"ltp":1.04,"tv":0.91,"id":5995},{"batb":[[0,1.63,13.63],[1,1.62,11],[2,1.5,20]],"ltp":1.13,"tv":6.9,"id":2120},{"batb":[[0,1.47,18.26],[1,1.46,55.51],[2,1.3,20]],"ltp":0.0,"tv":0.0,"id":60443}]}]}
{"op":"mcm","clk":"11892257342","pt":1724199175046,"mc":[{"id":"1.231804628","rc":[{"batb":[[0,1.63,13.62]],"ltp":1.04,"tv":0.91,"id":5995},{"batb":[[0,1.63,13.62]],"ltp":1.13,"tv":6.9,"id":2120},{"batb":[[0,1.47,18.26],[1,1.46,55.49]],"ltp":0.0,"tv":0.0,"id":60443}]}]}
{"op":"mcm","clk":"11892325566","pt":1724200186367,"mc":[{"id":"1.231804628","rc":[{"batb":[[0,1.62,12],[1,1.5,20],[2,1.09,222.22]],"ltp":1.04,"tv":0.91,"id":5995},{"batb":[[0,1.62,11],[1,1.5,20],[2,1.09,222.22]],"ltp":1.13,"tv":6.9,"id":2120},{"batb":[[0,1.46,55.49],[1,1.3,20],[2,1.09,222.22]],"ltp":0.0,"tv":0.0,"id":60443}]}]}
{"op":"mcm","clk":"11892329296","pt":1724200242373,"mc":[{"id":"1.231804628","rc":[{"batb":[[0,1.63,13.62],[1,1.62,12],[2,1.5,20]],"ltp":1.04,"tv":0.91,"id":5995},{"batb":[[0,1.63,13.62],[1,1.62,11],[2,1.5,20]],"ltp":1.13,"tv":6.9,"id":2120},{"batb":[[0,1.47,18.26],[1,1.46,55.49],[2,1.3,20]],"ltp":0.0,"tv":0.0,"id":60443}]}]}
{"op":"mcm","clk":"11892429417","pt":1724202043293,"mc":[{"id":"1.231804628","rc":[{"batb":[[0,1.62,12],[1,1.5,20],[2,1.09,222.22]],"ltp":1.04,"tv":0.91,"id":5995},{"batb":[[0,1.63,13.62]],"ltp":1.13,"tv":6.9,"id":2120},{"batb":[[0,1.47,18.26],[1,1.46,55.49]],"ltp":0.0,"tv":0.0,"id":60443}]}]}
{"op":"mcm","clk":"11892429447","pt":1724202043807,"mc":[{"id":"1.231804628","rc":[{"batb":[[0,1.62,11],[1,1.5,20],[2,1.09,222.22]],"ltp":1.13,"tv":6.9,"id":2120},{"batb":[[0,1.46,55.49],[1,1.3,20],[2,1.09,222.22]],"ltp":0.0,"tv":0.0,"id":60443}]}]}
{"op":"mcm","clk":"11892430995","pt":1724202074618,"mc":[{"id":"1.231804628","rc":[{"batb":[[0,1.63,13.62],[1,1.62,12],[2,1.5,20]],"ltp":1.04,"tv":0.91,"id":5995},{"batb":[[0,1.63,13.62],[1,1.62,11],[2,1.5,20]],"ltp":1.13,"tv":6.9,"id":2120},{"batb":[[0,1.47,18.26],[1,1.46,55.49],[2,1.3,20]],"ltp":0.0,"tv":0.0,"id":60443}]}]}
{"op":"mcm","clk":"11892525772","pt":1724203875270,"mc":[{"id":"1.231804628","rc":[{"batb":[[0,1.62,12],[1,1.5,20],[2,1.09,222.22]],"ltp":1.04,"tv":0.91,"id":5995},{"batb":[[0,1.62,11],[1,1.5,20],[2,1.09,222.22]],"ltp":1.13,"tv":6.9,"id":2120},{"batb":[[0,1.46,55.49],[1,1.3,20],[2,1.09,222.22]],"ltp":0.0,"tv":0.0,"id":60443}]}]}
{"op":"mcm","clk":"11892526208","pt":1724203884384,"mc":[{"id":"1.231804628","rc":[{"batb":[[0,1.63,13.62],[1,1.62,12],[2,1.5,20]],"ltp":1.04,"tv":0.91,"id":5995},{"batb":[[0,1.63,13.62],[1,1.62,11],[2,1.5,20]],"ltp":1.13,"tv":6.9,"id":2120},{"batb":[[0,1.47,18.26],[1,1.46,55.49],[2,1.3,20]],"ltp":0.0,"tv":0.0,"id":60443}]}]}
{"op":"mcm","clk":"11892620043","pt":1724205685345,"mc":[{"id":"1.231804628","rc":[{"batb":[[0,1.63,13.62]],"ltp":1.04,"tv":0.91,"id":5995},{"batb":[[0,1.62,11],[1,1.5,20],[2,1.09,222.22]],"ltp":1.13,"tv":6.9,"id":2120},{"batb":[[0,1.47,18.26],[1,1.46,55.5]],"ltp":0.0,"tv":0.0,"id":60443}]}]}
{"op":"mcm","clk":"11892620065","pt":1724205685774,"mc":[{"id":"1.231804628","rc":[{"batb":[[0,1.62,12],[1,1.5,20],[2,1.09,222.22]],"ltp":1.04,"tv":0.91,"id":5995},{"batb":[[0,1.46,55.5],[1,1.3,20],[2,1.09,222.22]],"ltp":0.0,"tv":0.0,"id":60443}]}]}
{"op":"mcm","clk":"11892623643","pt":1724205781984,"mc":[{"id":"1.231804628","rc":[{"batb":[[0,1.63,13.62],[1,1.62,12],[2,1.5,20]],"ltp":1.04,"tv":0.91,"id":5995},{"batb":[[0,1.63,13.62],[1,1.62,11],[2,1.5,20]],"ltp":1.13,"tv":6.9,"id":2120},{"batb":[[0,1.47,18.26],[1,1.46,55.5],[2,1.3,20]],"ltp":0.0,"tv":0.0,"id":60443}]}]}
{"op":"mcm","clk":"11892697011","pt":1724207582481,"mc":[{"id":"1.231804628","rc":[{"batb":[[0,1.62,12],[1,1.5,20],[2,1.09,222.22]],"ltp":1.04,"tv":0.91,"id":5995}]}]}
{"op":"mcm","clk":"11892697028","pt":1724207582797,"mc":[{"id":"1.231804628","rc":[{"batb":[[0,1.62,11],[1,1.5,20],[2,1.09,222.22]],"ltp":1.13,"tv":6.9,"id":2120},{"batb":[[0,1.46,55.5],[1,1.3,20],[2,1.09,222.22]],"ltp":0.0,"tv":0.0,"id":60443}]}]}
{"op":"mcm","clk":"11892699288","pt":1724207650955,"mc":[{"id":"1.231804628","rc":[{"batb":[[0,1.63,13.62],[1,1.62,12],[2,1.5,20]],"ltp":1.04,"tv":0.91,"id":5995},{"batb":[[0,1.63,13.62],[1,1.62,11],[2,1.5,20]],"ltp":1.13,"tv":6.9,"id":2120},{"batb":[[0,1.47,18.26],[1,1.46,55.5],[2,1.3,20]],"ltp":0.0,"tv":0.0,"id":60443}]}]}
{"op":"mcm","clk":"11892766833","pt":1724209451440,"mc":[{"id":"1.231804628","rc":[{"batb":[[0,1.62,12],[1,1.5,20],[2,1.09,222.22]],"ltp":1.04,"tv":0.91,"id":5995},{"batb":[[0,1.63,13.62]],"ltp":1.13,"tv":6.9,"id":2120},{"batb":[[0,1.46,55.49],[1,1.3,20],[2,1.09,222.22]],"ltp":0.0,"tv":0.0,"id":60443}]}]}
{"op":"mcm","clk":"11892766850","pt":1724209451748,"mc":[{"id":"1.231804628","rc":[{"batb":[[0,1.62,11],[1,1.5,20],[2,1.09,222.22]],"ltp":1.13,"tv":6.9,"id":2120}]}]}
{"op":"mcm","clk":"11892768486","pt":1724209488572,"mc":[{"id":"1.231804628","rc":[{"batb":[[0,1.63,13.62],[1,1.62,12],[2,1.5,20]],"ltp":1.04,"tv":0.91,"id":5995},{"batb":[[0,1.63,13.62],[1,1.62,11],[2,1.5,20]],"ltp":1.13,"tv":6.9,"id":2120},{"batb":[[0,1.47,18.26],[1,1.46,55.49],[2,1.3,20]],"ltp":0.0,"tv":0.0,"id":60443}]}]}
{"op":"mcm","clk":"11892861959","pt":1724211289500,"mc":[{"id":"1.231804628","rc":[{"batb":[[0,1.62,12],[1,1.5,20],[2,1.09,222.22]],"ltp":1.04,"tv":0.91,"id":5995},{"batb":[[0,1.62,11],[1,1.5,20],[2,1.09,222.22]],"ltp":1.13,"tv":6.9,"id":2120},{"batb":[[0,1.46,55.49],[1,1.3,20],[2,1.09,222.22]],"ltp":0.0,"tv":0.0,"id":60443}]}]}
{"op":"mcm","clk":"11892862874","pt":1724211311452,"mc":[{"id":"1.231804628","rc":[{"batb":[[0,1.63,13.62],[1,1.62,12],[2,1.5,20]],"ltp":1.04,"tv":0.91,"id":5995},{"batb":[[0,1.63,13.62],[1,1.62,11],[2,1.5,20]],"ltp":1.13,"tv":6.9,"id":2120},{"batb":[[0,1.47,18.26],[1,1.46,55.49],[2,1.3,20]],"ltp":0.0,"tv":0.0,"id":60443}]}]}
{"op":"mcm","clk":"11892967263","pt":1724213112330,"mc":[{"id":"1.231804628","rc":[{"batb":[[0,1.62,12],[1,1.5,20],[2,1.09,222.22]],"ltp":1.04,"tv":0.91,"id":5995},{"batb":[[0,1.63,13.62]],"ltp":1.13,"tv":6.9,"id":2120},{"batb":[[0,1.47,18.25],[1,1.46,55.48]],"ltp":0.0,"tv":0.0,"id":60443}]}]}
{"op":"mcm","clk":"11892967281","pt":1724213112740,"mc":[{"id":"1.231804628","rc":[{"batb":[[0,1.62,11],[1,1.5,20],[2,1.09,222.22]],"ltp":1.13,"tv":6.9,"id":2120},{"batb":[[0,1.46,55.48],[1,1.3,20],[2,1.09,222.22]],"ltp":0.0,"tv":0.0,"id":60443}]}]}
{"op":"mcm","clk":"11892967990","pt":1724213125566,"mc":[{"id":"1.231804628","rc":[{"batb":[[0,1.63,13.62],[1,1.62,12],[2,1.5,20]],"ltp":1.04,"tv":0.91,"id":5995},{"batb":[[0,1.63,13.62],[1,1.62,11],[2,1.5,20]],"ltp":1.13,"tv":6.9,"id":2120},{"batb":[[0,1.47,18.25],[1,1.46,55.48],[2,1.3,20]],"ltp":0.0,"tv":0.0,"id":60443}]}]}
{"op":"mcm","clk":"11893063956","pt":1724214926426,"mc":[{"id":"1.231804628","rc":[{"batb":[[0,1.46,55.48],[1,1.3,20],[2,1.09,222.22]],"ltp":0.0,"tv":0.0,"id":60443}]}]}
{"op":"mcm","clk":"11893063977","pt":1724214926836,"mc":[{"id":"1.231804628","rc":[{"batb":[[0,1.62,12],[1,1.5,20],[2,1.09,222.22]],"ltp":1.04,"tv":0.91,"id":5995},{"batb":[[0,1.62,11],[1,1.5,20],[2,1.09,222.22]],"ltp":1.13,"tv":6.9,"id":2120}]}]}
{"op":"mcm","clk":"11893068721","pt":1724215020735,"mc":[{"id":"1.231804628","rc":[{"batb":[[0,1.63,13.62],[1,1.62,12],[2,1.5,20]],"ltp":1.04,"tv":0.91,"id":5995},{"batb":[[0,1.63,13.62],[1,1.62,11],[2,1.5,20]],"ltp":1.13,"tv":6.9,"id":2120},{"batb":[[0,1.47,18.25],[1,1.46,55.48],[2,1.3,20]],"ltp":0.0,"tv":0.0,"id":60443}]}]}
