{"op":"mcm","clk":"11771402027","pt":1722755881138,"mc":[{"id":"1.231426403","marketDefinition":{"bspMarket":false,"turnInPlayEnabled":true,"persistenceEnabled":true,"marketBaseRate":5.0,"eventId":"33466782","eventTypeId":"4","numberOfWinners":1,"bettingType":"ODDS","marketType":"MATCH_ODDS","marketTime":"2024-08-05T20:00:00.000Z","suspendTime":"2024-08-05T20:00:00.000Z","bspReconciled":false,"complete":true,"inPlay":false,"crossMatching":true,"runnersVoidable":false,"numberOfActiveRunners":2,"betDelay":0,"status":"OPEN","runners":[{"status":"ACTIVE","sortPriority":1,"id":19144236,"name":"Toronto Nationals"},{"status":"ACTIVE","sortPriority":2,"id":19144241,"name":"Montreal Tigers"}],"regulators":["MR_INT"],"countryCode":"GB","discountAllowed":false,"timezone":"GMT","openDate":"2024-08-05T20:00:00.000Z","version":6055950746,"name":"Match Odds","eventName":"Toronto Nationals v Montreal Tigers"},"rc":[{"batb":[[0,1.03,200],[1,1.02,200],[2,1.01,220]],"ltp":0.0,"tv":0.0,"id":19144236},{"batb":[[0,1.03,200],[1,1.02,200],[2,1.01,220]],"ltp":0.0,"tv":0.0,"id":19144241}]}]}
{"op":"mcm","clk":"11771402115","pt":1722755882835,"mc":[{"id":"1.231426403","marketDefinition":{"bspMarket":false,"turnInPlayEnabled":true,"persistenceEnabled":true,"marketBaseRate":5.0,"eventId":"33466782","eventTypeId":"4","numberOfWinners":1,"bettingType":"ODDS","marketType":"MATCH_ODDS","marketTime":"2024-08-05T20:00:00.000Z","suspendTime":"2024-08-05T20:00:00.000Z","bspReconciled":false,"complete":true,"inPlay":false,"crossMatching":true,"runnersVoidable":false,"numberOfActiveRunners":2,"betDelay":0,"status":"OPEN","runners":[{"status":"ACTIVE","sortPriority":1,"id":19144236,"name":"Toronto Nationals"},{"status":"ACTIVE","sortPriority":2,"id":19144241,"name":"Montreal Tigers"}],"regulators":["MR_INT"],"countryCode":"GB","discountAllowed":true,"timezone":"GMT","openDate":"2024-08-05T20:00:00.000Z","version":6055950746,"name":"Match Odds","eventName":"Toronto Nationals v Montreal Tigers"}}]}
{"op":"mcm","clk":"11771406356","pt":1722755969796,"mc":[{"id":"1.231426403","rc":[{"batb":[[1,1.02,3378.41],[2,1.01,6390.05]],"ltp":0.0,"tv":0.0,"id":19144236}]}]}
{"op":"mcm","clk":"11771406401","pt":1722755970518,"mc":[{"id":"1.231426403","rc":[{"batb":[[0,1.04,1626.3],[1,1.03,2352.48],[2,1.02,3378.41]],"ltp":0.0,"tv":0.0,"id":19144236},{"batb":[[0,1.04,1626.3],[1,1.03,2352.48],[2,1.02,3378.41]],"ltp":0.0,"tv":0.0,"id":19144241}]}]}
{"op":"mcm","clk":"11771566827","pt":1722759216466,"mc":[{"id":"1.231426403","rc":[{"batb":[[0,1.03,200],[1,1.02,200],[2,1.01,220]],"ltp":0.0,"tv":0.0,"id":19144236},{"batb":[[0,1.03,200],[1,1.02,200],[2,1.01,220]],"ltp":0.0,"tv":0.0,"id":19144241}]}]}
{"op":"mcm","clk":"11771580738","pt":1722759440995,"mc":[{"id":"1.231426403","rc":[{"batl":[[0,6,0.96]],"ltp":0.0,"tv":0.0,"id":19144236}]}]}
{"op":"mcm","clk":"11771581609","pt":1722759454897,"mc":[{"id":"1.231426403","rc":[{"batl":[[0,6,0.96]],"ltp":0.0,"tv":0.0,"id":19144241}]}]}
{"op":"mcm","clk":"11771630204","pt":1722760153920,"mc":[{"id":"1.231426403","rc":[{"batb":[[0,1.03,200.51]],"ltp":0.0,"tv":0.0,"id":19144236}]}]}
{"op":"mcm","clk":"11771631151","pt":1722760167917,"mc":[{"id":"1.231426403","rc":[{"batb":[[0,1.03,200.51]],"ltp":0.0,"tv":0.0,"id":19144241}]}]}
{"op":"mcm","clk":"11771637004","pt":1722760249686,"mc":[{"id":"1.231426403","rc":[{"batb":[[2,1.01,478.41]],"ltp":0.0,"tv":0.0,"id":19144236},{"batb":[[2,1.01,478.41]],"ltp":0.0,"tv":0.0,"id":19144241}]}]}
{"op":"mcm","clk":"11771770025","pt":1722761817559,"mc":[{"id":"1.231426403","rc":[{"batb":[[0,1.25,100.51],[1,1.03,200],[2,1.02,200]],"ltp":0.0,"tv":0.0,"id":19144236},{"batb":[[0,1.25,100.51],[1,1.03,200],[2,1.02,200]],"ltp":0.0,"tv":0.0,"id":19144241}]}]}
{"op":"mcm","clk":"11772192381","pt":1722766570971,"mc":[{"id":"1.231426403","rc":[{"batb":[[0,1.25,100]],"ltp":0.0,"tv":0.0,"id":19144236}]}]}
{"op":"mcm","clk":"11772192772","pt":1722766574197,"mc":[{"id":"1.231426403","rc":[{"batb":[[0,1.25,100]],"ltp":0.0,"tv":0.0,"id":19144241}]}]}
{"op":"mcm","clk":"11772302164","pt":1722767781812,"mc":[{"id":"1.231426403","rc":[{"batb":[[0,1.26,32.95],[1,1.25,100],[2,1.03,200]],"ltp":0.0,"tv":0.0,"id":19144236},{"batb":[[0,1.26,32.95],[1,1.25,100],[2,1.03,200]],"ltp":0.0,"tv":0.0,"id":19144241}]}]}
{"op":"mcm","clk":"11772332276","pt":1722768127616,"mc":[{"id":"1.231426403","rc":[{"batb":[[0,1.27,6.54],[1,1.26,32.95],[2,1.25,100]],"ltp":0.0,"tv":0.0,"id":19144236}]}]}
{"op":"mcm","clk":"11772332304","pt":1722768127925,"mc":[{"id":"1.231426403","rc":[{"batb":[[0,1.27,6.08],[1,1.26,32.95],[2,1.25,100]],"ltp":0.0,"tv":0.0,"id":19144241}]}]}
{"op":"mcm","clk":"11772465590","pt":1722769582616,"mc":[{"id":"1.231426403","rc":[{"batb":[[1,1.25,100],[2,1.03,200]],"ltp":0.0,"tv":0.0,"id":19144236},{"batb":[[1,1.25,100],[2,1.03,200]],"ltp":0.0,"tv":0.0,"id":19144241}]}]}
{"op":"mcm","clk":"11772469026","pt":1722769612028,"mc":[{"id":"1.231426403","rc":[{"batb":[[0,1.28,30.59],[1,1.27,6.54],[2,1.25,100]],"ltp":0.0,"tv":0.0,"id":19144236},{"batb":[[0,1.28,30.59],[1,1.27,6.08],[2,1.25,100]],"ltp":0.0,"tv":0.0,"id":19144241}]}]}
{"op":"mcm","clk":"11772666823","pt":1722771413324,"mc":[{"id":"1.231426403","rc":[{"batb":[[0,1.27,6.54],[1,1.25,100],[2,1.03,200]],"ltp":0.0,"tv":0.0,"id":19144236},{"batb":[[0,1.27,6.08],[1,1.25,100],[2,1.03,200]],"ltp":0.0,"tv":0.0,"id":19144241}]}]}
{"op":"mcm","clk":"11772668777","pt":1722771430158,"mc":[{"id":"1.231426403","rc":[{"batb":[[0,1.28,30.59],[1,1.27,6.54],[2,1.25,100]],"ltp":0.0,"tv":0.0,"id":19144236},{"batb":[[0,1.28,30.59],[1,1.27,6.08],[2,1.25,100]],"ltp":0.0,"tv":0.0,"id":19144241}]}]}
{"op":"mcm","clk":"11772731069","pt":1722771879733,"mc":[{"id":"1.231426403","rc":[{"batb":[[0,1.29,6.54],[1,1.28,30.59]],"ltp":0.0,"tv":0.0,"id":19144236},{"batb":[[0,1.29,6.08],[1,1.28,30.59]],"ltp":0.0,"tv":0.0,"id":19144241}]}]}
{"op":"mcm","clk":"11772890023","pt":1722773230640,"mc":[{"id":"1.231426403","rc":[{"batb":[[1,1.25,100],[2,1.03,200]],"ltp":0.0,"tv":0.0,"id":19144241}]}]}
{"op":"mcm","clk":"11772890052","pt":1722773230851,"mc":[{"id":"1.231426403","rc":[{"batb":[[1,1.25,100],[2,1.03,200]],"ltp":0.0,"tv":0.0,"id":19144236}]}]}
{"op":"mcm","clk":"11772892097","pt":1722773245280,"mc":[{"id":"1.231426403","rc":[{"batb":[[0,1.3,28.55],[1,1.29,6.54],[2,1.25,100]],"ltp":0.0,"tv":0.0,"id":19144236},{"batb":[[0,1.3,28.55],[1,1.29,6.08],[2,1.25,100]],"ltp":0.0,"tv":0.0,"id":19144241}]}]}
{"op":"mcm","clk":"11773107688","pt":1722774808701,"mc":[{"id":"1.231426403","rc":[{"batb":[[0,1.31,6.54],[1,1.3,28.55]],"ltp":0.0,"tv":0.0,"id":19144236},{"batb":[[0,1.31,6.08],[1,1.3,28.55]],"ltp":0.0,"tv":0.0,"id":19144241}]}]}
{"op":"mcm","clk":"11773143330","pt":1722775046443,"mc":[{"id":"1.231426403","rc":[{"batb":[[1,1.25,100],[2,1.03,200]],"ltp":0.0,"tv":0.0,"id":19144236},{"batb":[[1,1.25,100],[2,1.03,200]],"ltp":0.0,"tv":0.0,"id":19144241}]}]}
{"op":"mcm","clk":"11773144257","pt":1722775052751,"mc":[{"id":"1.231426403","rc":[{"batb":[[0,1.32,26.77],[1,1.31,6.54],[2,1.25,100]],"ltp":0.0,"tv":0.0,"id":19144236}]}]}
{"op":"mcm","clk":"11773144275","pt":1722775052852,"mc":[{"id":"1.231426403","rc":[{"batb":[[0,1.32,26.77],[1,1.31,6.08],[2,1.25,100]],"ltp":0.0,"tv":0.0,"id":19144241}]}]}
{"op":"mcm","clk":"11773386043","pt":1722776800027,"mc":[{"id":"1.231426403","rc":[{"batb":[[0,1.32,27.31]],"ltp":0.0,"tv":0.0,"id":19144236}]}]}
{"op":"mcm","clk":"11773387684","pt":1722776810006,"mc":[{"id":"1.231426403","rc":[{"batb":[[0,1.32,27.31]],"ltp":0.0,"tv":0.0,"id":19144241}]}]}
{"op":"mcm","clk":"11773395170","pt":1722776853674,"mc":[{"id":"1.231426403","rc":[{"batb":[[0,1.31,7.09],[1,1.25,100],[2,1.03,200]],"ltp":0.0,"tv":0.0,"id":19144236},{"batb":[[0,1.31,6.63],[1,1.25,100],[2,1.03,200]],"ltp":0.0,"tv":0.0,"id":19144241}]}]}
{"op":"mcm","clk":"11773413609","pt":1722776973192,"mc":[{"id":"1.231426403","rc":[{"batb":[[0,1.32,27.31],[1,1.31,6.54],[2,1.25,100]],"ltp":0.0,"tv":0.0,"id":19144236},{"batb":[[0,1.32,27.31],[1,1.31,6.08],[2,1.25,100]],"ltp":0.0,"tv":0.0,"id":19144241}]}]}
{"op":"mcm","clk":"11773527725","pt":1722777688391,"mc":[{"id":"1.231426403","rc":[{"batb":[[0,1.33,7.09],[1,1.32,26.77]],"ltp":0.0,"tv":0.0,"id":19144236},{"batb":[[0,1.33,6.63],[1,1.32,26.77]],"ltp":0.0,"tv":0.0,"id":19144241}]}]}
{"op":"mcm","clk":"11773570480","pt":1722778008098,"mc":[{"id":"1.231426403","rc":[{"batb":[[0,1.33,6.54]],"ltp":0.0,"tv":0.0,"id":19144236},{"batb":[[0,1.33,6.08]],"ltp":0.0,"tv":0.0,"id":19144241}]}]}
{"op":"mcm","clk":"11773672463","pt":1722778774502,"mc":[{"id":"1.231426403","rc":[{"batb":[[1,1.25,100],[2,1.03,200]],"ltp":0.0,"tv":0.0,"id":19144236},{"batb":[[1,1.25,100],[2,1.03,200]],"ltp":0.0,"tv":0.0,"id":19144241}]}]}
{"op":"mcm","clk":"11773682886","pt":1722778850698,"mc":[{"id":"1.231426403","rc":[{"batb":[[0,1.34,25.19],[1,1.33,6.54],[2,1.25,100]],"ltp":0.0,"tv":0.0,"id":19144236},{"batb":[[0,1.34,25.19],[1,1.33,6.08],[2,1.25,100]],"ltp":0.0,"tv":0.0,"id":19144241}]}]}
{"op":"mcm","clk":"11773898634","pt":1722780507791,"mc":[{"id":"1.231426403","rc":[{"batb":[[0,1.35,6.54],[1,1.34,25.19]],"ltp":0.0,"tv":0.0,"id":19144236},{"batb":[[1,1.25,100],[2,1.03,200]],"ltp":0.0,"tv":0.0,"id":19144241}]}]}
{"op":"mcm","clk":"11773898650","pt":1722780507892,"mc":[{"id":"1.231426403","rc":[{"batb":[[0,1.35,6.08],[1,1.34,25.19],[2,1.25,100]],"ltp":0.0,"tv":0.0,"id":19144241}]}]}
{"op":"mcm","clk":"11773919846","pt":1722780651049,"mc":[{"id":"1.231426403","rc":[{"batb":[[1,1.25,100],[2,1.03,200]],"ltp":0.0,"tv":0.0,"id":19144236},{"batb":[[1,1.25,100],[2,1.03,200]],"ltp":0.0,"tv":0.0,"id":19144241}]}]}
{"op":"mcm","clk":"11773925691","pt":1722780688648,"mc":[{"id":"1.231426403","rc":[{"batb":[[0,1.36,23.79],[1,1.35,6.54],[2,1.25,100]],"ltp":0.0,"tv":0.0,"id":19144236},{"batb":[[0,1.36,23.79],[1,1.35,6.08],[2,1.25,100]],"ltp":0.0,"tv":0.0,"id":19144241}]}]}
{"op":"mcm","clk":"11774182574","pt":1722782489067,"mc":[{"id":"1.231426403","rc":[{"batb":[[0,1.35,6.54],[1,1.25,100],[2,1.03,200]],"ltp":0.0,"tv":0.0,"id":19144236},{"batb":[[0,1.35,6.08],[1,1.25,100],[2,1.03,200]],"ltp":0.0,"tv":0.0,"id":19144241}]}]}
{"op":"mcm","clk":"11774208227","pt":1722782604248,"mc":[{"id":"1.231426403","rc":[{"batb":[[0,1.36,23.79],[1,1.35,6.54],[2,1.25,100]],"ltp":0.0,"tv":0.0,"id":19144236},{"batb":[[0,1.36,23.79],[1,1.35,6.08],[2,1.25,100]],"ltp":0.0,"tv":0.0,"id":19144241}]}]}
{"op":"mcm","clk":"11774278903","pt":1722783130637,"mc":[{"id":"1.231426403","rc":[{"batb":[[1,1.26,6.54]],"ltp":0.0,"tv":0.0,"id":19144236},{"batb":[[1,1.26,6.08]],"ltp":0.0,"tv":0.0,"id":19144241}]}]}
{"op":"mcm","clk":"11774462020","pt":1722784404609,"mc":[{"id":"1.231426403","rc":[{"batb":[[0,1.26,6.08],[1,1.25,100],[2,1.03,200]],"ltp":0.0,"tv":0.0,"id":19144241}]}]}
{"op":"mcm","clk":"11774462072","pt":1722784404936,"mc":[{"id":"1.231426403","rc":[{"batb":[[0,1.26,6.54],[1,1.25,100],[2,1.03,200]],"ltp":0.0,"tv":0.0,"id":19144236}]}]}
{"op":"mcm","clk":"11774470594","pt":1722784455177,"mc":[{"id":"1.231426403","rc":[{"batb":[[0,1.27,31.73],[1,1.26,6.54],[2,1.25,100]],"ltp":0.0,"tv":0.0,"id":19144236},{"batb":[[0,1.27,31.73],[1,1.26,6.08],[2,1.25,100]],"ltp":0.0,"tv":0.0,"id":19144241}]}]}
{"op":"mcm","clk":"11774656249","pt":1722785653980,"mc":[{"id":"1.231426403","rc":[{"batb":[[0,1.27,32.27]],"ltp":0.0,"tv":0.0,"id":19144236}]}]}
{"op":"mcm","clk":"11774657965","pt":1722785664056,"mc":[{"id":"1.231426403","rc":[{"batb":[[0,1.27,32.27]],"ltp":0.0,"tv":0.0,"id":19144241}]}]}
{"op":"mcm","clk":"11774684248","pt":1722785818560,"mc":[{"id":"1.231426403","rc":[{"batb":[[0,1.28,7.09],[1,1.27,31.73]],"ltp":0.0,"tv":0.0,"id":19144236},{"batb":[[0,1.28,6.63],[1,1.27,31.73]],"ltp":0.0,"tv":0.0,"id":19144241}]}]}
{"op":"mcm","clk":"11774753715","pt":1722786256285,"mc":[{"id":"1.231426403","rc":[{"batb":[[1,1.25,100],[2,1.03,200]],"ltp":0.0,"tv":0.0,"id":19144236},{"batb":[[1,1.25,100],[2,1.03,200]],"ltp":0.0,"tv":0.0,"id":19144241}]}]}
{"op":"mcm","clk":"11774754139","pt":1722786258817,"mc":[{"id":"1.231426403","rc":[{"batb":[[0,1.29,30.08],[1,1.28,6.54],[2,1.25,100]],"ltp":0.0,"tv":0.0,"id":19144236}]}]}
{"op":"mcm","clk":"11774754159","pt":1722786258924,"mc":[{"id":"1.231426403","rc":[{"batb":[[0,1.29,30.08],[1,1.28,6.08],[2,1.25,100]],"ltp":0.0,"tv":0.0,"id":19144241}]}]}
{"op":"mcm","clk":"11775010019","pt":1722788060098,"mc":[{"id":"1.231426403","rc":[{"batb":[[0,1.28,7.09],[1,1.25,100],[2,1.03,200]],"ltp":0.0,"tv":0.0,"id":19144236},{"batb":[[0,1.28,6.63],[1,1.25,100],[2,1.03,200]],"ltp":0.0,"tv":0.0,"id":19144241}]}]}
{"op":"mcm","clk":"11775020804","pt":1722788140116,"mc":[{"id":"1.231426403","rc":[{"batb":[[0,1.29,30.08],[1,1.28,6.54],[2,1.25,100]],"ltp":0.0,"tv":0.0,"id":19144236},{"batb":[[0,1.29,30.08],[1,1.28,6.08],[2,1.25,100]],"ltp":0.0,"tv":0.0,"id":19144241}]}]}
{"op":"mcm","clk":"11775050742","pt":1722788382572,"mc":[{"id":"1.231426403","rc":[{"batb":[[0,1.3,7.09],[1,1.29,29.54]],"ltp":0.0,"tv":0.0,"id":19144236},{"batb":[[0,1.3,6.63],[1,1.29,29.54]],"ltp":0.0,"tv":0.0,"id":19144241}]}]}
{"op":"mcm","clk":"11775266258","pt":1722789940710,"mc":[{"id":"1.231426403","rc":[{"batb":[[1,1.25,100],[2,1.03,200]],"ltp":0.0,"tv":0.0,"id":19144236},{"batb":[[1,1.25,100],[2,1.03,200]],"ltp":0.0,"tv":0.0,"id":19144241}]}]}
{"op":"mcm","clk":"11775271063","pt":1722789974359,"mc":[{"id":"1.231426403","rc":[{"batb":[[0,1.31,28.18],[1,1.3,6.54],[2,1.25,100]],"ltp":0.0,"tv":0.0,"id":19144236},{"batb":[[0,1.31,28.18],[1,1.3,6.08],[2,1.25,100]],"ltp":0.0,"tv":0.0,"id":19144241}]}]}
{"op":"mcm","clk":"11775379693","pt":1722790821768,"mc":[{"id":"1.231426403","rc":[{"batb":[[0,1.32,7.09],[1,1.31,27.63]],"ltp":0.0,"tv":0.0,"id":19144236},{"batb":[[0,1.32,6.63],[1,1.31,27.63]],"ltp":0.0,"tv":0.0,"id":19144241}]}]}
{"op":"mcm","clk":"11775506445","pt":1722791775715,"mc":[{"id":"1.231426403","rc":[{"batb":[[1,1.25,100],[2,1.04,1.56]],"ltp":0.0,"tv":0.0,"id":19144241}]}]}
{"op":"mcm","clk":"11775506478","pt":1722791775883,"mc":[{"id":"1.231426403","rc":[{"batb":[[1,1.25,100],[2,1.04,1.56]],"ltp":0.0,"tv":0.0,"id":19144236}]}]}
{"op":"mcm","clk":"11775513131","pt":1722791819553,"mc":[{"id":"1.231426403","rc":[{"batb":[[0,1.33,26.5],[1,1.32,6.54],[2,1.25,100]],"ltp":0.0,"tv":0.0,"id":19144236},{"batb":[[0,1.33,26.5],[1,1.32,6.08],[2,1.25,100]],"ltp":0.0,"tv":0.0,"id":19144241}]}]}
{"op":"mcm","clk":"11775560259","pt":1722792142735,"mc":[{"id":"1.231426403","rc":[{"batb":[[0,1.34,7.09],[1,1.33,25.96]],"ltp":0.0,"tv":0.0,"id":19144236}]}]}
{"op":"mcm","clk":"11775560358","pt":1722792143257,"mc":[{"id":"1.231426403","rc":[{"batb":[[0,1.34,6.63],[1,1.33,25.96]],"ltp":0.0,"tv":0.0,"id":19144241}]}]}
{"op":"mcm","clk":"11775785267","pt":1722793619423,"mc":[{"id":"1.231426403","rc":[{"batb":[[1,1.25,100],[2,1.04,1.56]],"ltp":0.0,"tv":0.0,"id":19144236},{"batb":[[1,1.25,100],[2,1.04,1.56]],"ltp":0.0,"tv":0.0,"id":19144241}]}]}
{"op":"mcm","clk":"11775792478","pt":1722793668380,"mc":[{"id":"1.231426403","rc":[{"batb":[[0,1.35,25.02],[1,1.34,6.54],[2,1.25,100]],"ltp":0.0,"tv":0.0,"id":19144236},{"batb":[[0,1.35,25.02],[1,1.34,6.08],[2,1.25,100]],"ltp":0.0,"tv":0.0,"id":19144241}]}]}
{"op":"mcm","clk":"11775821632","pt":1722793872996,"mc":[{"id":"1.231426403","rc":[{"batb":[[0,1.35,24.47]],"ltp":0.0,"tv":0.0,"id":19144236},{"batb":[[0,1.35,24.47]],"ltp":0.0,"tv":0.0,"id":19144241}]}]}
{"op":"mcm","clk":"11775890317","pt":1722794383640,"mc":[{"id":"1.231426403","rc":[{"batb":[[1,1.26,6.54]],"ltp":0.0,"tv":0.0,"id":19144236}]}]}
{"op":"mcm","clk":"11775890373","pt":1722794384014,"mc":[{"id":"1.231426403","rc":[{"batb":[[1,1.26,6.08]],"ltp":0.0,"tv":0.0,"id":19144241}]}]}
{"op":"mcm","clk":"11776086742","pt":1722795468625,"mc":[{"id":"1.231426403","rc":[{"batb":[[0,1.26,6.08],[1,1.25,100],[2,1.04,1.56]],"ltp":0.0,"tv":0.0,"id":19144241}]}]}
{"op":"mcm","clk":"11776086865","pt":1722795469205,"mc":[{"id":"1.231426403","rc":[{"batb":[[0,1.26,6.54],[1,1.25,100],[2,1.04,1.56]],"ltp":0.0,"tv":0.0,"id":19144236}]}]}
{"op":"mcm","clk":"11776100541","pt":1722795540312,"mc":[{"id":"1.231426403","rc":[{"batb":[[0,1.27,31.73],[1,1.26,6.54],[2,1.25,100]],"ltp":0.0,"tv":0.0,"id":19144236},{"batb":[[0,1.27,31.73],[1,1.26,6.08],[2,1.25,100]],"ltp":0.0,"tv":0.0,"id":19144241}]}]}
{"op":"mcm","clk":"11776278330","pt":1722796420950,"mc":[{"id":"1.231426403","rc":[{"batb":[[0,1.28,4.54],[1,1.27,31.73],[2,1.26,6.54]],"ltp":0.0,"tv":0.0,"id":19144236}]}]}
{"op":"mcm","clk":"11776280262","pt":1722796429970,"mc":[{"id":"1.231426403","rc":[{"batb":[[0,1.28,4.54],[1,1.27,31.73],[2,1.26,6.08]],"ltp":0.0,"tv":0.0,"id":19144241}]}]}
{"op":"mcm","clk":"11776308223","pt":1722796566784,"mc":[{"id":"1.231426403","rc":[{"batb":[[2,1.25,100]],"ltp":0.0,"tv":0.0,"id":19144236}]}]}
{"op":"mcm","clk":"11776308354","pt":1722796567410,"mc":[{"id":"1.231426403","rc":[{"batb":[[0,1.28,11.09]],"ltp":0.0,"tv":0.0,"id":19144236},{"batb":[[0,1.28,10.63],[2,1.25,100]],"ltp":0.0,"tv":0.0,"id":19144241}]}]}
{"op":"mcm","clk":"11776321641","pt":1722796632534,"mc":[{"id":"1.231426403","rc":[{"batb":[[0,1.29,4.54],[1,1.28,6.54],[2,1.27,31.73]],"ltp":0.0,"tv":0.0,"id":19144236}]}]}
{"op":"mcm","clk":"11776324816","pt":1722796647252,"mc":[{"id":"1.231426403","rc":[{"batb":[[0,1.29,4.54],[1,1.28,6.08],[2,1.27,31.73]],"ltp":0.0,"tv":0.0,"id":19144241}]}]}
{"op":"mcm","clk":"11776468631","pt":1722797340682,"mc":[{"id":"1.231426403","rc":[{"batb":[[2,1.25,100]],"ltp":0.0,"tv":0.0,"id":19144236},{"batb":[[2,1.25,100]],"ltp":0.0,"tv":0.0,"id":19144241}]}]}
{"op":"mcm","clk":"11776470536","pt":1722797350406,"mc":[{"id":"1.231426403","rc":[{"batb":[[0,1.3,28.55],[1,1.29,4.54],[2,1.28,6.54]],"ltp":0.0,"tv":0.0,"id":19144236},{"batb":[[0,1.3,28.55],[1,1.29,4.54],[2,1.28,6.08]],"ltp":0.0,"tv":0.0,"id":19144241}]}]}
{"op":"mcm","clk":"11776575360","pt":1722797965169,"mc":[{"id":"1.231426403","rc":[{"batl":[[0,1.34,3.12]],"ltp":0.0,"tv":0.0,"id":19144241}]}]}
{"op":"mcm","clk":"11776632443","pt":1722798297587,"mc":[{"id":"1.231426403","rc":[{"trd":[[1.3,0.14]],"batb":[[0,1.3,28.48]],"ltp":1.3,"tv":0.13,"id":19144236}],"tv":0.13}]}
{"op":"mcm","clk":"11776701557","pt":1722798692709,"mc":[{"id":"1.231426403","rc":[{"batb":[[0,1.31,6.54],[1,1.3,28.48],[2,1.29,4.54]],"ltp":1.3,"tv":0.13,"id":19144236}]}]}
{"op":"mcm","clk":"11776701635","pt":1722798693180,"mc":[{"id":"1.231426403","rc":[{"batb":[[0,1.31,6.08],[1,1.3,28.55],[2,1.29,4.54]],"ltp":0.0,"tv":0.0,"id":19144241}]}]}
{"op":"mcm","clk":"11776787126","pt":1722799096047,"mc":[{"id":"1.231426403","rc":[{"batb":[[2,1.25,100]],"ltp":1.3,"tv":0.13,"id":19144236}]}]}
{"op":"mcm","clk":"11776787649","pt":1722799099059,"mc":[{"id":"1.231426403","rc":[{"batb":[[2,1.25,100]],"ltp":0.0,"tv":0.0,"id":19144241}]}]}
{"op":"mcm","clk":"11776796866","pt":1722799150735,"mc":[{"id":"1.231426403","rc":[{"batb":[[1,1.25,100],[2,1.04,1.56]],"ltp":1.3,"tv":0.13,"id":19144236}]}]}
{"op":"mcm","clk":"11776796938","pt":1722799151121,"mc":[{"id":"1.231426403","rc":[{"batb":[[1,1.25,100],[2,1.04,1.56]],"ltp":0.0,"tv":0.0,"id":19144241}]}]}
{"op":"mcm","clk":"11776798989","pt":1722799162246,"mc":[{"id":"1.231426403","rc":[{"batb":[[0,1.32,26.77],[1,1.31,6.08],[2,1.25,100]],"ltp":0.0,"tv":0.0,"id":19144241}]}]}
{"op":"mcm","clk":"11776935053","pt":1722799948620,"mc":[{"id":"1.231426403","rc":[{"batb":[[0,1.32,20],[1,1.31,6.54],[2,1.25,100]],"ltp":1.3,"tv":0.13,"id":19144236},{"batb":[[0,1.33,20],[1,1.32,26.77],[2,1.31,6.08]],"ltp":0.0,"tv":0.0,"id":19144241}]}]}
{"op":"mcm","clk":"11777073657","pt":1722800720759,"mc":[{"id":"1.231426403","rc":[{"batb":[[1,1.25,100],[2,1.04,1.56]],"ltp":1.3,"tv":0.13,"id":19144236}]}]}
{"op":"mcm","clk":"11777073755","pt":1722800721383,"mc":[{"id":"1.231426403","rc":[{"batb":[[1,1.26,6.54],[2,1.25,100]],"ltp":1.3,"tv":0.13,"id":19144236},{"batb":[[0,1.33,26.08],[2,1.25,100]],"ltp":0.0,"tv":0.0,"id":19144241}]}]}
{"op":"mcm","clk":"11777115693","pt":1722800962328,"mc":[{"id":"1.231426403","rc":[{"batb":[[1,1.25,100],[2,1.04,1.56]],"ltp":0.0,"tv":0.0,"id":19144241}]}]}
{"op":"mcm","clk":"11777124990","pt":1722801019199,"mc":[{"id":"1.231426403","rc":[{"batb":[[0,1.34,25.19],[1,1.33,26.08],[2,1.25,100]],"ltp":0.0,"tv":0.0,"id":19144241}]}]}
{"op":"mcm","clk":"11777133454","pt":1722801072743,"mc":[{"id":"1.231426403","rc":[{"batb":[[0,1.32,20.78]],"ltp":1.3,"tv":0.13,"id":19144236}]}]}
{"op":"mcm","clk":"11777135692","pt":1722801086957,"mc":[{"id":"1.231426403","rc":[{"batb":[[0,1.32,20]],"ltp":1.3,"tv":0.13,"id":19144236}]}]}
{"op":"mcm","clk":"11777146723","pt":1722801155928,"mc":[{"id":"1.231426403","rc":[{"batb":[[0,1.34,2.34],[1,1.32,20],[2,1.26,6.54]],"ltp":1.3,"tv":0.13,"id":19144236}]}]}
{"op":"mcm","clk":"11777148602","pt":1722801168151,"mc":[{"id":"1.231426403","rc":[{"batb":[[0,1.32,20],[1,1.26,6.54],[2,1.25,100]],"ltp":1.3,"tv":0.13,"id":19144236}]}]}
{"op":"mcm","clk":"11777316424","pt":1722802684570,"mc":[{"id":"1.231426403","rc":[{"batb":[[1,1.25,100],[2,1.04,1.56]],"ltp":1.3,"tv":0.13,"id":19144236},{"batb":[[0,1.35,6.08],[1,1.34,25.21],[2,1.33,20]],"ltp":0.0,"tv":0.0,"id":19144241}]}]}
{"op":"mcm","clk":"11777328206","pt":1722802819411,"mc":[{"id":"1.231426403","rc":[{"batb":[[1,1.33,20],[2,1.25,100]],"ltp":0.0,"tv":0.0,"id":19144241}]}]}
{"op":"mcm","clk":"11777332236","pt":1722802866569,"mc":[{"id":"1.231426403","rc":[{"batb":[[0,1.36,23.81],[1,1.35,6.08],[2,1.33,20]],"ltp":0.0,"tv":0.0,"id":19144241}]}]}
{"op":"mcm","clk":"11777479058","pt":1722804542273,"mc":[{"id":"1.231426403","rc":[{"batb":[[1,1.33,20],[2,1.26,6.08]],"ltp":0.0,"tv":0.0,"id":19144241}]}]}
{"op":"mcm","clk":"11777488973","pt":1722804666703,"mc":[{"id":"1.231426403","rc":[{"batb":[[0,1.33,20],[1,1.26,6.08],[2,1.25,100]],"ltp":0.0,"tv":0.0,"id":19144241}]}]}
{"op":"mcm","clk":"11777489801","pt":1722804677612,"mc":[{"id":"1.231426403","rc":[{"batb":[[0,1.34,25.21],[1,1.33,20],[2,1.26,6.08]],"ltp":0.0,"tv":0.0,"id":19144241}]}]}
{"op":"mcm","clk":"11777504620","pt":1722804864399,"mc":[{"id":"1.231426403","rc":[{"batb":[[0,1.34,20]],"ltp":1.3,"tv":0.13,"id":19144236},{"batb":[[0,1.35,20],[1,1.34,25.21]],"ltp":0.0,"tv":0.0,"id":19144241}]}]}
{"op":"mcm","clk":"11777615953","pt":1722806328743,"mc":[{"id":"1.231426403","rc":[{"batb":[[0,1.35,26.08],[2,1.25,100]],"ltp":0.0,"tv":0.0,"id":19144241}]}]}
{"op":"mcm","clk":"11777625690","pt":1722806478015,"mc":[{"id":"1.231426403","rc":[{"batb":[[1,1.25,100],[2,1.04,1.56]],"ltp":0.0,"tv":0.0,"id":19144241}]}]}
{"op":"mcm","clk":"11777625894","pt":1722806481071,"mc":[{"id":"1.231426403","rc":[{"batb":[[0,1.36,23.81],[1,1.35,26.08],[2,1.25,100]],"ltp":0.0,"tv":0.0,"id":19144241}]}]}
{"op":"mcm","clk":"11777740627","pt":1722808000793,"mc":[{"id":"1.231426403","rc":[{"batb":[[1,1.35,20],[2,1.26,6.08]],"ltp":0.0,"tv":0.0,"id":19144241}]}]}
{"op":"mcm","clk":"11777765678","pt":1722808281342,"mc":[{"id":"1.231426403","rc":[{"batb":[[0,1.35,20],[1,1.26,6.08],[2,1.25,100]],"ltp":0.0,"tv":0.0,"id":19144241}]}]}
{"op":"mcm","clk":"11777770949","pt":1722808339197,"mc":[{"id":"1.231426403","rc":[{"batb":[[0,1.36,23.81],[1,1.35,20],[2,1.26,6.08]],"ltp":0.0,"tv":0.0,"id":19144241}]}]}
{"op":"mcm","clk":"11777880385","pt":1722809574949,"mc":[{"id":"1.231426403","rc":[{"batb":[[0,1.36,23.8]],"ltp":0.0,"tv":0.0,"id":19144241}]}]}
{"op":"mcm","clk":"11777889524","pt":1722809658247,"mc":[{"id":"1.231426403","rc":[{"batb":[[2,1.25,100]],"ltp":0.0,"tv":0.0,"id":19144241}]}]}
{"op":"mcm","clk":"11777904795","pt":1722809816741,"mc":[{"id":"1.231426403","rc":[{"batb":[[1,1.25,100],[2,1.04,1.56]],"ltp":0.0,"tv":0.0,"id":19144241}]}]}
{"op":"mcm","clk":"11777904803","pt":1722809816846,"mc":[{"id":"1.231426403","rc":[{"batb":[[0,1.37,20],[1,1.36,23.8],[2,1.25,100]],"ltp":0.0,"tv":0.0,"id":19144241}]}]}
{"op":"mcm","clk":"11777935923","pt":1722810139416,"mc":[{"id":"1.231426403","rc":[{"batb":[[1,1.25,100],[2,1.04,1.56]],"ltp":0.0,"tv":0.0,"id":19144241}]}]}
{"op":"mcm","clk":"11777937210","pt":1722810153041,"mc":[{"id":"1.231426403","rc":[{"batb":[[0,1.38,22.55],[1,1.37,20],[2,1.25,100]],"ltp":0.0,"tv":0.0,"id":19144241}]}]}
{"op":"mcm","clk":"11778091712","pt":1722811953241,"mc":[{"id":"1.231426403","rc":[{"batb":[[0,1.37,20],[1,1.25,100],[2,1.04,1.56]],"ltp":0.0,"tv":0.0,"id":19144241}]}]}
{"op":"mcm","clk":"11778094112","pt":1722811982677,"mc":[{"id":"1.231426403","rc":[{"batb":[[0,1.38,22.55],[1,1.37,20],[2,1.25,100]],"ltp":0.0,"tv":0.0,"id":19144241}]}]}
{"op":"mcm","clk":"11778235913","pt":1722813782936,"mc":[{"id":"1.231426403","rc":[{"batb":[[2,1.04,1.56]],"ltp":1.3,"tv":0.13,"id":19144236},{"batb":[[0,1.37,20],[1,1.25,100],[2,1.04,1.56]],"ltp":0.0,"tv":0.0,"id":19144241}]}]}
{"op":"mcm","clk":"11778238688","pt":1722813820573,"mc":[{"id":"1.231426403","rc":[{"batb":[[0,1.38,22.55],[1,1.37,20],[2,1.25,100]],"ltp":0.0,"tv":0.0,"id":19144241}]}]}
{"op":"mcm","clk":"11778363940","pt":1722815620746,"mc":[{"id":"1.231426403","rc":[{"batb":[[0,1.37,20],[1,1.25,100],[2,1.04,1.56]],"ltp":0.0,"tv":0.0,"id":19144241}]}]}
{"op":"mcm","clk":"11778365806","pt":1722815655787,"mc":[{"id":"1.231426403","rc":[{"batb":[[0,1.38,22.55],[1,1.37,20],[2,1.25,100]],"ltp":0.0,"tv":0.0,"id":19144241}]}]}
{"op":"mcm","clk":"11778481864","pt":1722817455982,"mc":[{"id":"1.231426403","rc":[{"batb":[[0,1.37,20],[1,1.25,100],[2,1.04,1.56]],"ltp":0.0,"tv":0.0,"id":19144241}]}]}
{"op":"mcm","clk":"11778485989","pt":1722817511464,"mc":[{"id":"1.231426403","rc":[{"batb":[[0,1.38,22.57],[1,1.37,20],[2,1.25,100]],"ltp":0.0,"tv":0.0,"id":19144241}]}]}
{"op":"mcm","clk":"11778495635","pt":1722817649590,"mc":[{"id":"1.231426403","rc":[{"batb":[[0,1.51,1],[1,1.34,20],[2,1.25,100]],"ltp":1.3,"tv":0.13,"id":19144236}]}]}
{"op":"mcm","clk":"11778498072","pt":1722817682429,"mc":[{"id":"1.231426403","rc":[{"batb":[[0,1.51,1],[1,1.38,22.57],[2,1.37,20]],"ltp":0.0,"tv":0.0,"id":19144241}]}]}
{"op":"mcm","clk":"11778606270","pt":1722819311907,"mc":[{"id":"1.231426403","rc":[{"batb":[[1,1.37,20],[2,1.25,100]],"ltp":0.0,"tv":0.0,"id":19144241}]}]}
{"op":"mcm","clk":"11778608027","pt":1722819346136,"mc":[{"id":"1.231426403","rc":[{"batb":[[1,1.38,22.57],[2,1.37,20]],"ltp":0.0,"tv":0.0,"id":19144241}]}]}
{"op":"mcm","clk":"11778623595","pt":1722819665058,"mc":[{"id":"1.231426403","rc":[{"batb":[[2,1.26,5.38]],"ltp":1.3,"tv":0.13,"id":19144236},{"batb":[[1,1.38,22.59]],"ltp":0.0,"tv":0.0,"id":19144241}]}]}
{"op":"mcm","clk":"11778705293","pt":1722821146357,"mc":[{"id":"1.231426403","rc":[{"batb":[[1,1.37,20],[2,1.26,5.38]],"ltp":0.0,"tv":0.0,"id":19144241}]}]}
{"op":"mcm","clk":"11778708263","pt":1722821197717,"mc":[{"id":"1.231426403","rc":[{"batb":[[1,1.38,22.59],[2,1.37,20]],"ltp":0.0,"tv":0.0,"id":19144241}]}]}
{"op":"mcm","clk":"11778785928","pt":1722822563745,"mc":[{"id":"1.231426403","rc":[{"trd":[[1.51,1.02]],"batb":[[0,1.34,20.49],[1,1.26,5.38],[2,1.25,100]],"ltp":1.51,"tv":1.15,"id":19144236}],"tv":1.15}]}
{"op":"mcm","clk":"11778811731","pt":1722822998011,"mc":[{"id":"1.231426403","rc":[{"batb":[[1,1.37,20],[2,1.26,5.38]],"ltp":0.0,"tv":0.0,"id":19144241}]}]}
{"op":"mcm","clk":"11778813144","pt":1722823023738,"mc":[{"id":"1.231426403","rc":[{"batb":[[1,1.38,22.59],[2,1.37,20]],"ltp":0.0,"tv":0.0,"id":19144241}]}]}
{"op":"mcm","clk":"11778831734","pt":1722823422232,"mc":[{"id":"1.231426403","rc":[{"trd":[[2.98,0.51]],"batb":[[0,1.34,20.99],[1,1.26,5.38]],"ltp":2.98,"tv":1.66,"id":19144236},{"trd":[[1.51,1]],"batb":[[0,1.38,22.58],[1,1.37,20],[2,1.26,5.38]],"ltp":1.51,"tv":1.0,"id":19144241}],"tv":2.66}]}
{"op":"mcm","clk":"11778831880","pt":1722823426399,"mc":[{"id":"1.231426403","rc":[{"batb":[[0,1.34,20.49]],"ltp":2.98,"tv":1.66,"id":19144236}]}]}
{"op":"mcm","clk":"11778832295","pt":1722823438481,"mc":[{"id":"1.231426403","rc":[{"batb":[[0,3.45,1.01],[1,1.34,20.49],[2,1.26,5.38]],"ltp":2.98,"tv":1.66,"id":19144236}]}]}
{"op":"mcm","clk":"11778832766","pt":1722823449611,"mc":[{"id":"1.231426403","rc":[{"batb":[[0,1.34,20.49],[1,1.26,5.38],[2,1.25,100]],"ltp":2.98,"tv":1.66,"id":19144236}]}]}
{"op":"mcm","clk":"11778833266","pt":1722823464740,"mc":[{"id":"1.231426403","rc":[{"trd":[[1.51,1.51]],"batb":[[0,1.34,20]],"ltp":1.51,"tv":2.15,"id":19144236},{"trd":[[2.98,0.25]],"batb":[[0,1.38,23.34]],"ltp":2.98,"tv":1.24,"id":19144241}],"tv":3.4}]}
{"op":"mcm","clk":"11778833356","pt":1722823467922,"mc":[{"id":"1.231426403","rc":[{"batb":[[0,1.38,22.58]],"ltp":2.98,"tv":1.24,"id":19144241}]}]}
{"op":"mcm","clk":"11778833754","pt":1722823478758,"mc":[{"id":"1.231426403","rc":[{"batb":[[0,3.5,1.01],[1,1.38,22.58],[2,1.37,20]],"ltp":2.98,"tv":1.24,"id":19144241}]}]}
{"op":"mcm","clk":"11778834197","pt":1722823491165,"mc":[{"id":"1.231426403","rc":[{"batb":[[0,1.38,22.58],[1,1.37,20],[2,1.26,5.38]],"ltp":2.98,"tv":1.24,"id":19144241}]}]}
{"op":"mcm","clk":"11778834625","pt":1722823503243,"mc":[{"id":"1.231426403","rc":[{"batb":[[0,3.45,1.01],[1,1.34,20],[2,1.26,5.38]],"ltp":1.51,"tv":2.15,"id":19144236}]}]}
{"op":"mcm","clk":"11778835047","pt":1722823515695,"mc":[{"id":"1.231426403","rc":[{"batb":[[0,1.34,20],[1,1.26,5.38],[2,1.25,100]],"ltp":1.51,"tv":2.15,"id":19144236}]}]}
{"op":"mcm","clk":"11778835611","pt":1722823530674,"mc":[{"id":"1.231426403","rc":[{"batb":[[0,3.5,1.01],[1,1.38,22.58],[2,1.37,20]],"ltp":2.98,"tv":1.24,"id":19144241}]}]}
{"op":"mcm","clk":"11778836663","pt":1722823559197,"mc":[{"id":"1.231426403","rc":[{"batb":[[0,1.38,22.58],[1,1.37,20],[2,1.26,5.38]],"ltp":2.98,"tv":1.24,"id":19144241}]}]}
{"op":"mcm","clk":"11778837275","pt":1722823574761,"mc":[{"id":"1.231426403","rc":[{"batb":[[0,3.5,1.01],[1,1.38,22.58],[2,1.37,20]],"ltp":2.98,"tv":1.24,"id":19144241}]}]}
{"op":"mcm","clk":"11778837708","pt":1722823586046,"mc":[{"id":"1.231426403","rc":[{"batb":[[0,1.38,22.58],[1,1.37,20],[2,1.26,5.38]],"ltp":2.98,"tv":1.24,"id":19144241}]}]}
{"op":"mcm","clk":"11778838103","pt":1722823595829,"mc":[{"id":"1.231426403","rc":[{"batb":[[0,3.45,1.01],[1,1.34,20],[2,1.26,5.38]],"ltp":1.51,"tv":2.15,"id":19144236}]}]}
{"op":"mcm","clk":"11778839041","pt":1722823618893,"mc":[{"id":"1.231426403","rc":[{"batb":[[0,1.34,20],[1,1.26,5.38],[2,1.25,100]],"ltp":1.51,"tv":2.15,"id":19144236}]}]}
{"op":"mcm","clk":"11778839544","pt":1722823631674,"mc":[{"id":"1.231426403","rc":[{"batb":[[0,3.5,1.01],[1,1.38,22.58],[2,1.37,20]],"ltp":2.98,"tv":1.24,"id":19144241}]}]}
{"op":"mcm","clk":"11778841466","pt":1722823681253,"mc":[{"id":"1.231426403","rc":[{"batb":[[0,1.38,22.58],[1,1.37,20],[2,1.26,5.38]],"ltp":2.98,"tv":1.24,"id":19144241}]}]}
{"op":"mcm","clk":"11778841876","pt":1722823693444,"mc":[{"id":"1.231426403","rc":[{"batb":[[0,3.45,1.01],[1,1.34,20],[2,1.26,5.38]],"ltp":1.51,"tv":2.15,"id":19144236}]}]}
{"op":"mcm","clk":"11778842973","pt":1722823726191,"mc":[{"id":"1.231426403","rc":[{"batb":[[0,1.34,20],[1,1.26,5.38],[2,1.25,100]],"ltp":1.51,"tv":2.15,"id":19144236}]}]}
{"op":"mcm","clk":"11778882065","pt":1722824823878,"mc":[{"id":"1.231426403","rc":[{"batb":[[0,1.37,20],[1,1.26,5.38],[2,1.25,100]],"ltp":2.98,"tv":1.24,"id":19144241}]}]}
{"op":"mcm","clk":"11778884023","pt":1722824875945,"mc":[{"id":"1.231426403","rc":[{"batb":[[0,1.38,22.58],[1,1.37,20],[2,1.26,5.38]],"ltp":2.98,"tv":1.24,"id":19144241}]}]}
{"op":"mcm","clk":"11778954101","pt":1722826413949,"mc":[{"id":"1.231426403","rc":[{"batl":[[0,3.5,0.57]],"ltp":1.51,"tv":2.15,"id":19144236}]}]}
{"op":"mcm","clk":"11778954718","pt":1722826427956,"mc":[{"id":"1.231426403","rc":[{"batl":[[0,3.8,0.57]],"ltp":2.98,"tv":1.24,"id":19144241}]}]}
{"op":"mcm","clk":"11778964772","pt":1722826676062,"mc":[{"id":"1.231426403","rc":[{"batb":[[0,1.37,20],[1,1.26,5.38],[2,1.25,100]],"ltp":2.98,"tv":1.24,"id":19144241}]}]}
{"op":"mcm","clk":"11778966749","pt":1722826722294,"mc":[{"id":"1.231426403","rc":[{"batb":[[0,1.38,22.58],[1,1.37,20],[2,1.26,5.38]],"ltp":2.98,"tv":1.24,"id":19144241}]}]}
{"op":"mcm","clk":"11778981289","pt":1722827108824,"mc":[{"id":"1.231426403","rc":[{"trd":[[3.5,0.03]],"batb":[[1,1.26,5.38]],"batl":[[0,3.5,0.54]],"ltp":3.5,"tv":2.18,"id":19144236},{"trd":[[1.4,0.07]],"batb":[[0,1.38,22.57],[2,1.26,5.38]],"ltp":1.4,"tv":1.31,"id":19144241}],"tv":3.5}]}
{"op":"mcm","clk":"11779001614","pt":1722827646928,"mc":[{"id":"1.231426403","rc":[{"batl":[[0,3.5,1.5]],"ltp":3.5,"tv":2.18,"id":19144236}]}]}
{"op":"mcm","clk":"11779002055","pt":1722827657951,"mc":[{"id":"1.231426403","rc":[{"batl":[[0,3.8,1.53]],"ltp":1.4,"tv":1.31,"id":19144241}]}]}
{"op":"mcm","clk":"11779022788","pt":1722828170206,"mc":[{"id":"1.231426403","rc":[{"batb":[[0,1.73,222],[1,1.38,22.57],[2,1.37,20]],"ltp":1.4,"tv":1.31,"id":19144241}]}]}
{"op":"mcm","clk":"11779036632","pt":1722828522409,"mc":[{"id":"1.231426403","rc":[{"batb":[[1,1.37,20],[2,1.26,5.38]],"ltp":1.4,"tv":1.31,"id":19144241}]}]}
{"op":"mcm","clk":"11779037425","pt":1722828547261,"mc":[{"id":"1.231426403","rc":[{"batb":[[0,1.74,11.59],[1,1.73,222],[2,1.37,20]],"ltp":1.4,"tv":1.31,"id":19144241}]}]}
{"op":"mcm","clk":"11779039481","pt":1722828606471,"mc":[{"id":"1.231426403","rc":[{"batb":[[0,1.74,18.51]],"ltp":1.4,"tv":1.31,"id":19144241}]}]}
{"op":"mcm","clk":"11779046357","pt":1722828797008,"mc":[{"id":"1.231426403","rc":[{"batb":[[0,1.39,3.16],[1,1.34,20],[2,1.26,5.38]],"ltp":3.5,"tv":2.18,"id":19144236}]}]}
{"op":"mcm","clk":"11779049978","pt":1722828888616,"mc":[{"id":"1.231426403","rc":[{"batb":[[1,1.37,20],[2,1.26,5.38]],"ltp":1.4,"tv":1.31,"id":19144241}]}]}
{"op":"mcm","clk":"11779102146","pt":1722830138312,"mc":[{"id":"1.231426403","rc":[{"batb":[[0,1.74,11.59],[2,1.26,12.3]],"ltp":1.4,"tv":1.31,"id":19144241}]}]}
{"op":"mcm","clk":"11779110281","pt":1722830347458,"mc":[{"id":"1.231426403","rc":[{"batb":[[0,1.37,20],[1,1.26,12.3],[2,1.25,100]],"ltp":1.4,"tv":1.31,"id":19144241}]}]}
{"op":"mcm","clk":"11779110933","pt":1722830363103,"mc":[{"id":"1.231426403","rc":[{"batb":[[0,1.41,20.92],[1,1.37,20],[2,1.26,12.3]],"ltp":1.4,"tv":1.31,"id":19144241}]}]}
{"op":"mcm","clk":"11779125441","pt":1722830693210,"mc":[{"id":"1.231426403","rc":[{"batb":[[0,1.39,3.16]],"ltp":3.5,"tv":2.18,"id":19144236},{"batb":[[0,1.41,20.93],[2,1.26,12.3]],"ltp":1.4,"tv":1.31,"id":19144241}]}]}
{"op":"mcm","clk":"11779173587","pt":1722831666354,"mc":[{"id":"1.231426403","rc":[{"batb":[[2,1.26,5.38]],"ltp":1.4,"tv":1.31,"id":19144241}]}]}
{"op":"mcm","clk":"11779192748","pt":1722832163370,"mc":[{"id":"1.231426403","rc":[{"batb":[[0,1.37,20],[1,1.26,5.38],[2,1.25,100]],"ltp":1.4,"tv":1.31,"id":19144241}]}]}
{"op":"mcm","clk":"11779193009","pt":1722832171255,"mc":[{"id":"1.231426403","rc":[{"batb":[[0,1.51,16.83],[1,1.37,20],[2,1.26,5.38]],"ltp":1.4,"tv":1.31,"id":19144241}]}]}
{"op":"mcm","clk":"11779264113","pt":1722833971569,"mc":[{"id":"1.231426403","rc":[{"batb":[[0,1.37,20],[1,1.26,5.38],[2,1.25,100]],"ltp":1.4,"tv":1.31,"id":19144241}]}]}
{"op":"mcm","clk":"11779266089","pt":1722834025738,"mc":[{"id":"1.231426403","rc":[{"batb":[[2,1.26,5.37]],"ltp":3.5,"tv":2.18,"id":19144236},{"batb":[[0,1.51,16.83],[1,1.37,20],[2,1.26,5.37]],"ltp":1.4,"tv":1.31,"id":19144241}]}]}
{"op":"mcm","clk":"11779331524","pt":1722835591648,"mc":[{"id":"1.231426403","rc":[{"batb":[[0,1.4,123.08],[1,1.39,3.16],[2,1.34,20]],"ltp":3.5,"tv":2.18,"id":19144236}]}]}
{"op":"mcm","clk":"11779336506","pt":1722835723161,"mc":[{"id":"1.231426403","rc":[{"batl":[[0,3.8,1.53]],"ltp":1.4,"tv":1.31,"id":19144241}]}]}
{"op":"mcm","clk":"11779340464","pt":1722835825989,"mc":[{"id":"1.231426403","rc":[{"batb":[[0,1.37,20],[1,1.26,5.37],[2,1.25,100]],"ltp":1.4,"tv":1.31,"id":19144241}]}]}
{"op":"mcm","clk":"11779342379","pt":1722835878869,"mc":[{"id":"1.231426403","rc":[{"batb":[[0,1.51,16.83],[1,1.37,20],[2,1.26,5.37]],"ltp":1.4,"tv":1.31,"id":19144241}]}]}
{"op":"mcm","clk":"11779345539","pt":1722835965140,"mc":[{"id":"1.231426403","rc":[{"batb":[[0,1.41,3.15],[1,1.4,123.08]],"ltp":3.5,"tv":2.18,"id":19144236}]}]}
{"op":"mcm","clk":"11779361039","pt":1722836383211,"mc":[{"id":"1.231426403","rc":[{"batb":[[0,1.41,9.47]],"ltp":3.5,"tv":2.18,"id":19144236}]}]}
{"op":"mcm","clk":"11779361480","pt":1722836394629,"mc":[{"id":"1.231426403","rc":[{"batb":[[0,1.41,16]],"ltp":3.5,"tv":2.18,"id":19144236}]}]}
{"op":"mcm","clk":"11779361499","pt":1722836395135,"mc":[{"id":"1.231426403","rc":[{"batb":[[0,1.41,9.69]],"ltp":3.5,"tv":2.18,"id":19144236}]}]}
{"op":"mcm","clk":"11779414093","pt":1722837493463,"mc":[{"id":"1.231426403","rc":[{"batb":[[1,1.34,20],[2,1.26,5.37]],"ltp":3.5,"tv":2.18,"id":19144236}]}]}
{"op":"mcm","clk":"11779420707","pt":1722837679112,"mc":[{"id":"1.231426403","rc":[{"trd":[[1.51,1.5],[2.98,0.51]],"batb":[[0,1.41,9.73],[2,1.26,5.33]],"batl":[[0,3.5,1.51]],"ltp":3.5,"tv":2.17,"id":19144236},{"batb":[[0,1.37,20],[1,1.26,5.33],[2,1.25,100]],"batl":[[0,3.8,1.53]],"ltp":1.4,"tv":1.31,"id":19144241}],"tv":3.49}]}
{"op":"mcm","clk":"11779422460","pt":1722837728258,"mc":[{"id":"1.231426403","rc":[{"batb":[[0,1.51,16.87],[1,1.37,20],[2,1.26,5.33]],"ltp":1.4,"tv":1.31,"id":19144241}]}]}
{"op":"mcm","clk":"11779434332","pt":1722838036986,"mc":[{"id":"1.231426403","rc":[{"batb":[[0,1.41,3.17],[2,1.26,11.89]],"ltp":3.5,"tv":2.17,"id":19144236}]}]}
{"op":"mcm","clk":"11779472847","pt":1722838985119,"mc":[{"id":"1.231426403","rc":[{"batb":[[0,1.94,8.31],[1,1.41,3.17],[2,1.34,20]],"ltp":3.5,"tv":2.17,"id":19144236},{"batb":[[0,1.83,8.81],[1,1.51,16.87],[2,1.37,20]],"ltp":1.4,"tv":1.31,"id":19144241}]}]}
{"op":"mcm","clk":"11779492823","pt":1722839528401,"mc":[{"id":"1.231426403","rc":[{"batb":[[1,1.37,20],[2,1.26,5.33]],"ltp":1.4,"tv":1.31,"id":19144241}]}]}
{"op":"mcm","clk":"11779512728","pt":1722840079987,"mc":[{"id":"1.231426403","rc":[{"batb":[[2,1.26,5.33]],"ltp":3.5,"tv":2.17,"id":19144236},{"batb":[[1,1.26,5.33],[2,1.25,100]],"ltp":1.4,"tv":1.31,"id":19144241}]}]}
{"op":"mcm","clk":"11779565783","pt":1722841975000,"mc":[{"id":"1.231426403","rc":[{"trd":[[1.51,1.5]],"batb":[[0,1.94,8.31],[1,1.41,3.17],[2,1.26,5.32]],"ltp":3.5,"tv":2.17,"id":19144236},{"batb":[[0,1.83,8.81],[1,1.26,5.32]],"ltp":1.4,"tv":1.31,"id":19144241}]}]}
{"op":"mcm","clk":"11779597865","pt":1722843420508,"mc":[{"id":"1.231426403","rc":[{"batb":[[0,2.2,1.03],[1,1.94,8.31],[2,1.41,3.17]],"ltp":3.5,"tv":2.17,"id":19144236}]}]}
{"op":"mcm","clk":"11779601247","pt":1722843566592,"mc":[{"id":"1.231426403","rc":[{"batb":[[0,1.94,8.31],[1,1.41,3.17],[2,1.26,5.32]],"ltp":3.5,"tv":2.17,"id":19144236}]}]}
{"op":"mcm","clk":"11779602407","pt":1722843608847,"mc":[{"id":"1.231426403","rc":[{"batl":[[0,1.95,1.03],[1,3.5,1.51]],"ltp":3.5,"tv":2.17,"id":19144236}]}]}
{"op":"mcm","clk":"11779604311","pt":1722843686086,"mc":[{"id":"1.231426403","rc":[{"batl":[[0,3.5,1.51],[1,3.5,0]],"ltp":3.5,"tv":2.17,"id":19144236}]}]}
{"op":"mcm","clk":"11779605358","pt":1722843727177,"mc":[{"id":"1.231426403","rc":[{"batb":[[0,2.06,1.03],[1,1.83,8.81],[2,1.26,5.32]],"ltp":1.4,"tv":1.31,"id":19144241}]}]}
{"op":"mcm","clk":"11779606360","pt":1722843766724,"mc":[{"id":"1.231426403","rc":[{"batb":[[0,1.83,8.81],[1,1.26,5.32],[2,1.25,100]],"ltp":1.4,"tv":1.31,"id":19144241}]}]}
{"op":"mcm","clk":"11779606899","pt":1722843786633,"mc":[{"id":"1.231426403","rc":[{"batb":[[0,2.2,1.03],[1,1.94,8.31],[2,1.41,3.17]],"ltp":3.5,"tv":2.17,"id":19144236}]}]}
{"op":"mcm","clk":"11779607995","pt":1722843830000,"mc":[{"id":"1.231426403","rc":[{"trd":[[2.2,1.03]],"batb":[[0,1.94,8.31],[1,1.41,3.17],[2,1.26,5.32]],"ltp":2.2,"tv":3.2,"id":19144236},{"trd":[[1.84,1.23]],"batb":[[0,1.84,2.43],[1,1.83,8.81],[2,1.26,5.32]],"ltp":1.84,"tv":2.54,"id":19144241}],"tv":5.75}]}
{"op":"mcm","clk":"11779608105","pt":1722843833959,"mc":[{"id":"1.231426403","rc":[{"batb":[[0,1.83,8.81],[1,1.26,5.32],[2,1.25,100]],"ltp":1.84,"tv":2.54,"id":19144241}]}]}
{"op":"mcm","clk":"11779608238","pt":1722843839393,"mc":[{"id":"1.231426403","rc":[{"trd":[[1.94,2.33]],"batb":[[0,1.94,7.15]],"ltp":1.94,"tv":5.53,"id":19144236}],"tv":8.08}]}
{"op":"mcm","clk":"11779608305","pt":1722843842070,"mc":[{"id":"1.231426403","rc":[{"batb":[[0,1.94,8.31]],"ltp":1.94,"tv":5.53,"id":19144236}]}]}
{"op":"mcm","clk":"11779642736","pt":1722845484728,"mc":[{"id":"1.231426403","rc":[{"trd":[[1.51,1.5],[1.94,2.53],[2.2,1.02],[2.98,0.51]],"batb":[[0,1.94,8.21],[1,1.41,3.15],[2,1.26,5.34]],"batl":[[0,3.5,1.5]],"ltp":1.94,"tv":5.72,"id":19144236},{"trd":[[1.84,1.22]],"batb":[[0,1.83,8.81],[1,1.26,5.34]],"batl":[[0,3.8,1.53]],"ltp":1.84,"tv":2.54,"id":19144241}],"tv":8.27}]}
{"op":"mcm","clk":"11779644349","pt":1722845591790,"mc":[{"id":"1.231426403","rc":[{"batb":[[0,1.41,3.15],[1,1.26,5.34],[2,1.25,100]],"ltp":1.94,"tv":5.72,"id":19144236},{"batb":[[0,1.26,5.34],[1,1.25,100],[2,1.2,11]],"ltp":1.84,"tv":2.54,"id":19144241}]}]}
{"op":"mcm","clk":"11779644696","pt":1722845615619,"mc":[{"id":"1.231426403","rc":[{"batb":[[0,1.51,16.87],[1,1.26,5.34],[2,1.25,100]],"ltp":1.84,"tv":2.54,"id":19144241}]}]}
{"op":"mcm","clk":"11779645392","pt":1722845654149,"mc":[{"id":"1.231426403","rc":[{"batb":[[0,1.98,8.15],[1,1.41,3.15],[2,1.26,5.34]],"ltp":1.94,"tv":5.72,"id":19144236},{"batb":[[0,1.8,8.97],[1,1.51,16.87],[2,1.26,5.34]],"ltp":1.84,"tv":2.54,"id":19144241}]}]}
{"op":"mcm","clk":"11779648709","pt":1722845830059,"mc":[{"id":"1.231426403","rc":[{"batl":[[0,3.5,0.54]],"ltp":1.94,"tv":5.72,"id":19144236}]}]}
{"op":"mcm","clk":"11779648802","pt":1722845834066,"mc":[{"id":"1.231426403","rc":[{"batb":[[1,1.26,5.34],[2,1.25,100]],"ltp":1.94,"tv":5.72,"id":19144236}]}]}
{"op":"mcm","clk":"11779648898","pt":1722845836957,"mc":[{"id":"1.231426403","rc":[{"batl":[[0,3.8,0.57]],"ltp":1.84,"tv":2.54,"id":19144241}]}]}
{"op":"mcm","clk":"11779652304","pt":1722845956946,"mc":[{"id":"1.231426403","rc":[{"batl":[[0,3.5,1.5]],"ltp":1.94,"tv":5.72,"id":19144236}]}]}
{"op":"mcm","clk":"11779666504","pt":1722846472781,"mc":[{"id":"1.231426403","rc":[{"batb":[[2,1.2,11]],"ltp":1.94,"tv":5.72,"id":19144236}]}]}
{"op":"mcm","clk":"11779670405","pt":1722846702767,"mc":[{"id":"1.231426403","rc":[{"batl":[[0,3.5,0.54]],"ltp":1.94,"tv":5.72,"id":19144236}]}]}
{"op":"mcm","clk":"11779671052","pt":1722846747900,"mc":[{"id":"1.231426403","rc":[{"batl":[[0,3.5,1.5]],"ltp":1.94,"tv":5.72,"id":19144236}]}]}
{"op":"mcm","clk":"11779689933","pt":1722847415798,"mc":[{"id":"1.231426403","rc":[{"batb":[[1,1.26,5.34],[2,1.2,11]],"ltp":1.84,"tv":2.54,"id":19144241}]}]}
{"op":"mcm","clk":"11779720661","pt":1722848683001,"mc":[{"id":"1.231426403","rc":[{"trd":[[1.51,1.51],[1.94,2.53],[2.2,1.03],[2.98,0.51]],"batb":[[0,1.98,8.17],[1,1.26,5.35]],"batl":[[0,3.5,0.54]],"ltp":1.94,"tv":5.74,"id":19144236},{"trd":[[1.84,1.23]],"batb":[[0,1.8,8.99],[1,1.26,5.35]],"batl":[[0,3.8,0.57]],"ltp":1.84,"tv":2.54,"id":19144241}],"tv":8.28}]}
{"op":"mcm","clk":"11779723931","pt":1722848774008,"mc":[{"id":"1.231426403","rc":[{"batl":[[0,3.5,1.5]],"ltp":1.94,"tv":5.74,"id":19144236}]}]}
{"op":"mcm","clk":"11779724121","pt":1722848778992,"mc":[{"id":"1.231426403","rc":[{"batl":[[0,3.5,0.54]],"ltp":1.94,"tv":5.74,"id":19144236}]}]}
{"op":"mcm","clk":"11779732373","pt":1722849009977,"mc":[{"id":"1.231426403","rc":[{"batl":[[0,3.5,1.5]],"ltp":1.94,"tv":5.74,"id":19144236}]}]}
{"op":"mcm","clk":"11779770870","pt":1722850087688,"mc":[{"id":"1.231426403","rc":[{"batb":[[0,1.26,5.35],[1,1.2,11],[2,1.1,11]],"ltp":1.94,"tv":5.74,"id":19144236},{"batb":[[0,1.26,5.35],[1,1.2,11],[2,1.1,11]],"ltp":1.84,"tv":2.54,"id":19144241}]}]}
{"op":"mcm","clk":"11779770900","pt":1722850088108,"mc":[{"id":"1.231426403","rc":[{"batl":[[0,2.98,25.2],[1,3.5,0.54]],"ltp":1.94,"tv":5.74,"id":19144236},{"batl":[[0,2.7,23.92],[1,3.8,0.57]],"ltp":1.84,"tv":2.54,"id":19144241}]}]}
{"op":"mcm","clk":"11779772195","pt":1722850122624,"mc":[{"id":"1.231426403","rc":[{"batb":[[0,1.51,16.91],[1,1.26,5.35],[2,1.2,11]],"ltp":1.84,"tv":2.54,"id":19144241}]}]}
{"op":"mcm","clk":"11779776196","pt":1722850229672,"mc":[{"id":"1.231426403","rc":[{"batb":[[0,1.98,8.15],[1,1.26,5.35],[2,1.2,11]],"batl":[[0,3.5,1.5],[1,3.5,0]],"ltp":1.94,"tv":5.74,"id":19144236},{"batb":[[0,1.79,9.01],[1,1.62,44.54],[2,1.51,16.91]],"ltp":1.84,"tv":2.54,"id":19144241}]}]}
{"op":"mcm","clk":"11779781928","pt":1722850388350,"mc":[{"id":"1.231426403","rc":[{"batb":[[1,1.51,16.91],[2,1.26,5.35]],"batl":[[0,3.8,0.57],[1,3.8,0]],"ltp":1.84,"tv":2.54,"id":19144241}]}]}
{"op":"mcm","clk":"11779819761","pt":1722851307534,"mc":[{"id":"1.231426403","rc":[{"trd":[[1.98,4]],"batb":[[0,1.98,6.15]],"ltp":1.98,"tv":9.73,"id":19144236}],"tv":12.28}]}
{"op":"mcm","clk":"11779819893","pt":1722851311644,"mc":[{"id":"1.231426403","rc":[{"batb":[[0,1.98,8.15]],"ltp":1.98,"tv":9.73,"id":19144236}]}]}
{"op":"mcm","clk":"11779822607","pt":1722851400035,"mc":[{"id":"1.231426403","rc":[{"batl":[[0,3.5,0.54]],"ltp":1.98,"tv":9.73,"id":19144236}]}]}
{"op":"mcm","clk":"11779823420","pt":1722851426952,"mc":[{"id":"1.231426403","rc":[{"batb":[[1,1.55,5.67],[2,1.51,16.91]],"ltp":1.84,"tv":2.54,"id":19144241}]}]}
{"op":"mcm","clk":"11779842138","pt":1722851922813,"mc":[{"id":"1.231426403","rc":[{"batb":[[2,1.26,5.35]],"ltp":1.84,"tv":2.54,"id":19144241}]}]}
{"op":"mcm","clk":"11779867533","pt":1722852483010,"mc":[{"id":"1.231426403","rc":[{"trd":[[1.94,2.54],[1.98,4]],"batb":[[0,1.98,8.16],[1,1.26,5.36]],"ltp":1.98,"tv":9.74,"id":19144236},{"trd":[[1.79,8],[1.84,1.23]],"batb":[[0,1.79,5.02],[1,1.55,5.68],[2,1.26,5.36]],"ltp":1.79,"tv":10.54,"id":19144241}],"tv":20.29}]}
{"op":"mcm","clk":"11779867831","pt":1722852489433,"mc":[{"id":"1.231426403","rc":[{"batb":[[0,1.79,9.02]],"ltp":1.79,"tv":10.54,"id":19144241}]}]}
{"op":"mcm","clk":"11779893043","pt":1722852992620,"mc":[{"id":"1.231426403","rc":[{"batb":[[0,1.8,10],[1,1.79,9.02],[2,1.55,5.68]],"ltp":1.79,"tv":10.54,"id":19144241}]}]}
{"op":"mcm","clk":"11780016623","pt":1722855898805,"mc":[{"id":"1.231426403","rc":[{"trd":[[1.94,2.53],[1.98,4]],"batb":[[0,1.26,5.36],[1,1.2,11],[2,1.1,11]],"ltp":1.98,"tv":9.74,"id":19144236},{"trd":[[1.79,8]],"batb":[[1,1.55,5.68],[2,1.26,5.36]],"ltp":1.79,"tv":10.54,"id":19144241}],"tv":20.28}]}
{"op":"mcm","clk":"11780016638","pt":1722855899014,"mc":[{"id":"1.231426403","rc":[{"batl":[[0,2.68,24.19],[1,3.8,0.57]],"ltp":1.79,"tv":10.54,"id":19144241}]}]}
{"op":"mcm","clk":"11780018590","pt":1722855939159,"mc":[{"id":"1.231426403","rc":[{"batl":[[0,2.68,25.15]],"ltp":1.79,"tv":10.54,"id":19144241}]}]}
{"op":"mcm","clk":"11780018966","pt":1722855946983,"mc":[{"id":"1.231426403","rc":[{"batb":[[1,1.26,5.36],[2,1.2,11]],"ltp":1.79,"tv":10.54,"id":19144241}]}]}
{"op":"mcm","clk":"11780020299","pt":1722855975111,"mc":[{"id":"1.231426403","rc":[{"batb":[[0,1.98,8.15],[1,1.26,5.36],[2,1.2,11]],"ltp":1.98,"tv":9.74,"id":19144236},{"batb":[[1,1.79,9.01],[2,1.26,5.36]],"ltp":1.79,"tv":10.54,"id":19144241}]}]}
{"op":"mcm","clk":"11780021866","pt":1722856008413,"mc":[{"id":"1.231426403","rc":[{"batb":[[2,1.55,5.68]],"batl":[[0,3.8,1.53],[1,3.8,0]],"ltp":1.79,"tv":10.54,"id":19144241}]}]}
{"op":"mcm","clk":"11780037222","pt":1722856399984,"mc":[{"id":"1.231426403","rc":[{"batb":[[1,1.8,83.4],[2,1.26,5.36]],"ltp":1.98,"tv":9.74,"id":19144236}]}]}
{"op":"mcm","clk":"11780037506","pt":1722856406964,"mc":[{"id":"1.231426403","rc":[{"batb":[[2,1.65,102.65]],"ltp":1.79,"tv":10.54,"id":19144241}]}]}
{"op":"mcm","clk":"11780065428","pt":1722857014602,"mc":[{"id":"1.231426403","rc":[{"batb":[[2,1.74,17.32]],"ltp":1.98,"tv":9.74,"id":19144236}]}]}
{"op":"mcm","clk":"11780065942","pt":1722857021836,"mc":[{"id":"1.231426403","rc":[{"batb":[[2,1.74,17.32]],"ltp":1.79,"tv":10.54,"id":19144241}]}]}
{"op":"mcm","clk":"11780074028","pt":1722857190401,"mc":[{"id":"1.231426403","rc":[{"batb":[[1,1.81,4.5],[2,1.8,83.4]],"ltp":1.98,"tv":9.74,"id":19144236}]}]}
{"op":"mcm","clk":"11780074067","pt":1722857191219,"mc":[{"id":"1.231426403","rc":[{"batb":[[1,1.8,83.4],[2,1.74,17.32]],"ltp":1.98,"tv":9.74,"id":19144236}]}]}
{"op":"mcm","clk":"11780080492","pt":1722857313355,"mc":[{"id":"1.231426403","rc":[{"batb":[[1,1.81,4.5],[2,1.8,83.4]],"ltp":1.98,"tv":9.74,"id":19144236}]}]}
{"op":"mcm","clk":"11780080553","pt":1722857314542,"mc":[{"id":"1.231426403","rc":[{"batb":[[1,1.8,83.4],[2,1.74,17.32]],"ltp":1.98,"tv":9.74,"id":19144236}]}]}
{"op":"mcm","clk":"11780086438","pt":1722857433265,"mc":[{"id":"1.231426403","rc":[{"batb":[[1,1.81,4.5],[2,1.8,83.4]],"ltp":1.98,"tv":9.74,"id":19144236}]}]}
{"op":"mcm","clk":"11780086561","pt":1722857435281,"mc":[{"id":"1.231426403","rc":[{"batb":[[1,1.8,83.4],[2,1.74,17.32]],"ltp":1.98,"tv":9.74,"id":19144236}]}]}
{"op":"mcm","clk":"11780088017","pt":1722857462321,"mc":[{"id":"1.231426403","rc":[{"batb":[[0,1.82,35.57]],"ltp":1.98,"tv":9.74,"id":19144236},{"batb":[[1,1.74,17.32],[2,1.65,102.65]],"ltp":1.79,"tv":10.54,"id":19144241}]}]}
{"op":"mcm","clk":"11780089654","pt":1722857491964,"mc":[{"id":"1.231426403","rc":[{"batb":[[0,1.85,2],[1,1.82,35.57],[2,1.8,83.4]],"ltp":1.98,"tv":9.74,"id":19144236}]}]}
{"op":"mcm","clk":"11780095409","pt":1722857592066,"mc":[{"id":"1.231426403","rc":[{"batb":[[0,1.96,8.24],[1,1.85,2]],"ltp":1.98,"tv":9.74,"id":19144236},{"batb":[[0,1.81,8.92],[1,1.8,10],[2,1.74,17.32]],"ltp":1.79,"tv":10.54,"id":19144241}]}]}
{"op":"mcm","clk":"11780096239","pt":1722857609257,"mc":[{"id":"1.231426403","rc":[{"batb":[[0,1.97,31],[1,1.96,8.24],[2,1.85,2]],"ltp":1.98,"tv":9.74,"id":19144236}]}]}
{"op":"mcm","clk":"11780096724","pt":1722857619252,"mc":[{"id":"1.231426403","rc":[{"batl":[[0,2.24,30.07],[1,3.5,0.54]],"ltp":1.98,"tv":9.74,"id":19144236}]}]}
{"op":"mcm","clk":"11780097826","pt":1722857642513,"mc":[{"id":"1.231426403","rc":[{"batb":[[1,1.85,2],[2,1.8,83.4]],"ltp":1.98,"tv":9.74,"id":19144236},{"batb":[[0,1.8,10],[1,1.74,17.32],[2,1.65,102.65]],"ltp":1.79,"tv":10.54,"id":19144241}]}]}
{"op":"mcm","clk":"11780106118","pt":1722857829708,"mc":[{"id":"1.231426403","rc":[{"batb":[[0,2.02,43.47],[1,1.97,31],[2,1.85,2]],"ltp":1.98,"tv":9.74,"id":19144236},{"batb":[[0,1.9,49.27],[1,1.8,10],[2,1.74,17.32]],"ltp":1.79,"tv":10.54,"id":19144241}]}]}
{"op":"mcm","clk":"11780135690","pt":1722858342472,"mc":[{"id":"1.231426403","rc":[{"batb":[[1,1.97,39.2]],"ltp":1.98,"tv":9.74,"id":19144236},{"batb":[[1,1.8,18.97]],"ltp":1.79,"tv":10.54,"id":19144241}]}]}
{"op":"mcm","clk":"11780146627","pt":1722858585459,"mc":[{"id":"1.231426403","rc":[{"batb":[[1,1.97,31]],"ltp":1.98,"tv":9.74,"id":19144236},{"batb":[[1,1.8,10]],"ltp":1.79,"tv":10.54,"id":19144241}]}]}
{"op":"mcm","clk":"11780161680","pt":1722858948740,"mc":[{"id":"1.231426403","rc":[{"trd":[[2.02,4]],"batb":[[0,2.02,84.94]],"ltp":2.02,"tv":13.74,"id":19144236}],"tv":24.28}]}
{"op":"mcm","clk":"11780161685","pt":1722858948841,"mc":[{"id":"1.231426403","rc":[{"batb":[[0,2.02,43.47]],"ltp":2.02,"tv":13.74,"id":19144236}]}]}
{"op":"mcm","clk":"11780166154","pt":1722859051725,"mc":[{"id":"1.231426403","rc":[{"batb":[[0,1.91,6],[1,1.9,49.27],[2,1.8,10]],"ltp":1.79,"tv":10.54,"id":19144241}]}]}
{"op":"mcm","clk":"11780168238","pt":1722859097892,"mc":[{"id":"1.231426403","rc":[{"batb":[[2,1.8,18.97]],"ltp":1.79,"tv":10.54,"id":19144241}]}]}
{"op":"mcm","clk":"11780191875","pt":1722859552532,"mc":[{"id":"1.231426403","rc":[{"trd":[[1.51,1.5],[1.94,2.53],[1.98,4]],"ltp":2.02,"tv":13.74,"id":19144236},{"trd":[[1.79,8]],"batb":[[2,1.8,10]],"ltp":1.79,"tv":10.54,"id":19144241}],"tv":24.28}]}
{"op":"mcm","clk":"11780193447","pt":1722859582031,"mc":[{"id":"1.231426403","rc":[{"batb":[[2,1.8,18.98]],"ltp":1.79,"tv":10.54,"id":19144241}]}]}
{"op":"mcm","clk":"11780197014","pt":1722859642598,"mc":[{"id":"1.231426403","rc":[{"batb":[[2,1.8,10]],"ltp":1.79,"tv":10.54,"id":19144241}]}]}
{"op":"mcm","clk":"11780201739","pt":1722859718002,"mc":[{"id":"1.231426403","rc":[{"batl":[[0,3.8,0.57]],"ltp":1.79,"tv":10.54,"id":19144241}]}]}
{"op":"mcm","clk":"11780207375","pt":1722859825580,"mc":[{"id":"1.231426403","rc":[{"batb":[[2,1.8,18.98]],"ltp":1.79,"tv":10.54,"id":19144241}]}]}
{"op":"mcm","clk":"11780249239","pt":1722860734994,"mc":[{"id":"1.231426403","rc":[{"batb":[[2,1.8,10]],"ltp":1.79,"tv":10.54,"id":19144241}]}]}
{"op":"mcm","clk":"11780252155","pt":1722860807042,"mc":[{"id":"1.231426403","rc":[{"batl":[[0,2.22,1.01],[1,2.24,30.07],[2,3.5,0.54]],"ltp":2.02,"tv":13.74,"id":19144236},{"batl":[[0,3.8,1.07]],"ltp":1.79,"tv":10.54,"id":19144241}]}]}
{"op":"mcm","clk":"11780254016","pt":1722860855465,"mc":[{"id":"1.231426403","rc":[{"batb":[[2,1.8,18.98]],"ltp":1.79,"tv":10.54,"id":19144241}]}]}
{"op":"mcm","clk":"11780276405","pt":1722861407674,"mc":[{"id":"1.231426403","rc":[{"batl":[[0,2.24,30.07],[1,3.5,0.54],[2,3.5,0]],"ltp":2.02,"tv":13.74,"id":19144236},{"batl":[[0,3.8,0.57]],"ltp":1.79,"tv":10.54,"id":19144241}]}]}
{"op":"mcm","clk":"11780276569","pt":1722861411494,"mc":[{"id":"1.231426403","rc":[{"batl":[[0,2.22,1.01],[1,2.24,30.07],[2,3.5,0.54]],"ltp":2.02,"tv":13.74,"id":19144236},{"batl":[[0,3.8,1.07]],"ltp":1.79,"tv":10.54,"id":19144241}]}]}
{"op":"mcm","clk":"11780293298","pt":1722862012034,"mc":[{"id":"1.231426403","rc":[{"batl":[[0,2.24,30.07],[1,3.5,0.54],[2,3.5,0]],"ltp":2.02,"tv":13.74,"id":19144236},{"batl":[[0,3.8,0.57]],"ltp":1.79,"tv":10.54,"id":19144241}]}]}
{"op":"mcm","clk":"11780293429","pt":1722862016826,"mc":[{"id":"1.231426403","rc":[{"batl":[[0,2.22,1.01],[1,2.24,30.07],[2,3.5,0.54]],"ltp":2.02,"tv":13.74,"id":19144236},{"batl":[[0,3.8,1.07]],"ltp":1.79,"tv":10.54,"id":19144241}]}]}
{"op":"mcm","clk":"11780295737","pt":1722862123766,"mc":[{"id":"1.231426403","rc":[{"batb":[[2,1.8,10]],"ltp":1.79,"tv":10.54,"id":19144241}]}]}
{"op":"mcm","clk":"11780296341","pt":1722862154202,"mc":[{"id":"1.231426403","rc":[{"batb":[[2,1.81,8.93]],"ltp":1.79,"tv":10.54,"id":19144241}]}]}
{"op":"mcm","clk":"11780305411","pt":1722862489512,"mc":[{"id":"1.231426403","rc":[{"batb":[[2,1.8,10]],"ltp":1.79,"tv":10.54,"id":19144241}]}]}
{"op":"mcm","clk":"11780308959","pt":1722862617555,"mc":[{"id":"1.231426403","rc":[{"batl":[[0,2.24,30.07],[1,3.5,0.54],[2,3.5,0]],"ltp":2.02,"tv":13.74,"id":19144236},{"batl":[[0,3.8,0.57]],"ltp":1.79,"tv":10.54,"id":19144241}]}]}
{"op":"mcm","clk":"11780308970","pt":1722862617959,"mc":[{"id":"1.231426403","rc":[{"batl":[[0,3.8,1.07]],"ltp":1.79,"tv":10.54,"id":19144241}]}]}
{"op":"mcm","clk":"11780309149","pt":1722862623736,"mc":[{"id":"1.231426403","rc":[{"batl":[[0,2.22,1.01],[1,2.24,30.07],[2,3.5,0.54]],"ltp":2.02,"tv":13.74,"id":19144236}]}]}
{"op":"mcm","clk":"11780312472","pt":1722862744990,"mc":[{"id":"1.231426403","rc":[{"batb":[[2,1.81,8.93]],"ltp":1.79,"tv":10.54,"id":19144241}]}]}
{"op":"mcm","clk":"11780327499","pt":1722863218465,"mc":[{"id":"1.231426403","rc":[{"trd":[[1.94,2.53],[1.98,4.01],[2.2,1.02],[2.98,0.5]],"ltp":2.02,"tv":13.73,"id":19144236},{"trd":[[1.79,8.02],[1.84,1.23],[2.98,0.25]],"batb":[[2,1.81,8.96]],"batl":[[0,3.8,0.57]],"ltp":1.79,"tv":10.55,"id":19144241}]}]}
{"op":"mcm","clk":"11780327587","pt":1722863220986,"mc":[{"id":"1.231426403","rc":[{"batl":[[0,3.8,1.07]],"ltp":1.79,"tv":10.55,"id":19144241}]}]}
{"op":"mcm","clk":"11780327708","pt":1722863224301,"mc":[{"id":"1.231426403","rc":[{"batl":[[0,2.24,30.07],[1,3.5,0.54],[2,3.5,0]],"ltp":2.02,"tv":13.73,"id":19144236}]}]}
{"op":"mcm","clk":"11780327797","pt":1722863226983,"mc":[{"id":"1.231426403","rc":[{"batl":[[0,2.22,1.01],[1,2.24,30.07],[2,3.5,0.54]],"ltp":2.02,"tv":13.73,"id":19144236}]}]}
{"op":"mcm","clk":"11780335822","pt":1722863436805,"mc":[{"id":"1.231426403","rc":[{"batb":[[0,1.98,45.25]],"ltp":2.02,"tv":13.73,"id":19144236},{"batb":[[0,1.94,47.17],[1,1.91,6]],"ltp":1.79,"tv":10.55,"id":19144241}]}]}
{"op":"mcm","clk":"11780336503","pt":1722863450119,"mc":[{"id":"1.231426403","rc":[{"batb":[[2,1.8,10]],"ltp":1.79,"tv":10.55,"id":19144241}]}]}
{"op":"mcm","clk":"11780337793","pt":1722863477850,"mc":[{"id":"1.231426403","rc":[{"batb":[[2,1.96,8.27]],"ltp":2.02,"tv":13.73,"id":19144236},{"batb":[[2,1.81,8.96]],"ltp":1.79,"tv":10.55,"id":19144241}]}]}
{"op":"mcm","clk":"11780338479","pt":1722863494743,"mc":[{"id":"1.231426403","rc":[{"batl":[[2,2.78,4.04]],"ltp":2.02,"tv":13.73,"id":19144236}]}]}
{"op":"mcm","clk":"11780341116","pt":1722863568678,"mc":[{"id":"1.231426403","rc":[{"batb":[[2,1.85,2]],"ltp":2.02,"tv":13.73,"id":19144236},{"batb":[[2,1.8,10]],"ltp":1.79,"tv":10.55,"id":19144241}]}]}
{"op":"mcm","clk":"11780356666","pt":1722863827251,"mc":[{"id":"1.231426403","rc":[{"batl":[[0,2.24,30.07],[1,2.78,4.04],[2,3.5,0.54]],"ltp":2.02,"tv":13.73,"id":19144236}]}]}
{"op":"mcm","clk":"11780356739","pt":1722863829432,"mc":[{"id":"1.231426403","rc":[{"batl":[[0,2.22,1.01],[1,2.24,30.07],[2,2.78,4.04]],"ltp":2.02,"tv":13.73,"id":19144236}]}]}
{"op":"mcm","clk":"11780358988","pt":1722863908757,"mc":[{"id":"1.231426403","rc":[{"batb":[[0,1.99,10],[1,1.98,45.25],[2,1.97,31]],"ltp":2.02,"tv":13.73,"id":19144236},{"trd":[[1.94,94]],"batb":[[0,1.92,12.17],[2,1.9,49.27]],"ltp":1.94,"tv":104.55,"id":19144241}],"tv":118.28}]}
{"op":"mcm","clk":"11780358991","pt":1722863908858,"mc":[{"id":"1.231426403","rc":[{"batb":[[0,1.92,12]],"ltp":1.94,"tv":104.55,"id":19144241}]}]}
{"op":"mcm","clk":"11780359045","pt":1722863910768,"mc":[{"id":"1.231426403","rc":[{"batb":[[0,1.92,10]],"ltp":1.94,"tv":104.55,"id":19144241}]}]}
{"op":"mcm","clk":"11780359078","pt":1722863911857,"mc":[{"id":"1.231426403","rc":[{"batb":[[0,1.98,45.25],[1,1.97,31],[2,1.85,2]],"ltp":2.02,"tv":13.73,"id":19144236},{"batb":[[0,1.91,6],[1,1.9,49.27],[2,1.8,10]],"ltp":1.94,"tv":104.55,"id":19144241}]}]}
{"op":"mcm","clk":"11780359277","pt":1722863918055,"mc":[{"id":"1.231426403","rc":[{"batb":[[0,1.99,10],[1,1.98,45.25],[2,1.97,31]],"ltp":2.02,"tv":13.73,"id":19144236},{"batb":[[0,1.92,12],[1,1.91,6],[2,1.9,49.27]],"ltp":1.94,"tv":104.55,"id":19144241}]}]}
{"op":"mcm","clk":"11780359367","pt":1722863920676,"mc":[{"id":"1.231426403","rc":[{"batb":[[0,1.92,10]],"ltp":1.94,"tv":104.55,"id":19144241}]}]}
{"op":"mcm","clk":"11780359397","pt":1722863921660,"mc":[{"id":"1.231426403","rc":[{"batb":[[0,1.98,45.25],[1,1.97,31],[2,1.85,2]],"ltp":2.02,"tv":13.73,"id":19144236},{"batb":[[0,1.91,6],[1,1.9,49.27],[2,1.8,10]],"ltp":1.94,"tv":104.55,"id":19144241}]}]}
{"op":"mcm","clk":"11780359777","pt":1722863932982,"mc":[{"id":"1.231426403","rc":[{"batb":[[0,1.99,10],[1,1.98,45.25],[2,1.97,31]],"ltp":2.02,"tv":13.73,"id":19144236},{"batb":[[0,1.92,12],[1,1.91,6],[2,1.9,49.27]],"ltp":1.94,"tv":104.55,"id":19144241}]}]}
{"op":"mcm","clk":"11780359863","pt":1722863935399,"mc":[{"id":"1.231426403","rc":[{"batb":[[0,1.92,10]],"ltp":1.94,"tv":104.55,"id":19144241}]}]}
{"op":"mcm","clk":"11780359900","pt":1722863936380,"mc":[{"id":"1.231426403","rc":[{"batb":[[0,1.98,45.25],[1,1.97,31],[2,1.96,8.27]],"ltp":2.02,"tv":13.73,"id":19144236},{"batb":[[0,1.91,6],[1,1.9,49.27],[2,1.81,8.96]],"ltp":1.94,"tv":104.55,"id":19144241}]}]}
{"op":"mcm","clk":"11780359941","pt":1722863937670,"mc":[{"id":"1.231426403","rc":[{"batb":[[0,1.92,2],[1,1.91,6],[2,1.9,49.27]],"ltp":1.94,"tv":104.55,"id":19144241}]}]}
{"op":"mcm","clk":"11780360028","pt":1722863940493,"mc":[{"id":"1.231426403","rc":[{"batb":[[0,1.99,10],[1,1.98,45.25],[2,1.97,31]],"ltp":2.02,"tv":13.73,"id":19144236},{"batb":[[0,1.92,10]],"ltp":1.94,"tv":104.55,"id":19144241}]}]}
{"op":"mcm","clk":"11780360163","pt":1722863944206,"mc":[{"id":"1.231426403","rc":[{"batb":[[0,1.98,45.25],[1,1.97,31],[2,1.96,8.27]],"ltp":2.02,"tv":13.73,"id":19144236},{"batb":[[0,1.92,2]],"ltp":1.94,"tv":104.55,"id":19144241}]}]}
{"op":"mcm","clk":"11780360229","pt":1722863946682,"mc":[{"id":"1.231426403","rc":[{"batb":[[0,1.99,10],[1,1.98,45.25],[2,1.97,31]],"ltp":2.02,"tv":13.73,"id":19144236},{"batb":[[0,1.92,10]],"ltp":1.94,"tv":104.55,"id":19144241}]}]}
{"op":"mcm","clk":"11780360358","pt":1722863950295,"mc":[{"id":"1.231426403","rc":[{"batb":[[0,1.98,45.25],[1,1.97,31],[2,1.96,8.27]],"ltp":2.02,"tv":13.73,"id":19144236},{"batb":[[0,1.92,2]],"ltp":1.94,"tv":104.55,"id":19144241}]}]}
{"op":"mcm","clk":"11780360436","pt":1722863952808,"mc":[{"id":"1.231426403","rc":[{"batb":[[0,1.99,10],[1,1.98,45.25],[2,1.97,31]],"ltp":2.02,"tv":13.73,"id":19144236},{"batb":[[0,1.92,10]],"ltp":1.94,"tv":104.55,"id":19144241}]}]}
{"op":"mcm","clk":"11780360557","pt":1722863956388,"mc":[{"id":"1.231426403","rc":[{"batb":[[0,1.98,45.25],[1,1.97,31],[2,1.96,8.27]],"ltp":2.02,"tv":13.73,"id":19144236},{"batb":[[0,1.92,2]],"ltp":1.94,"tv":104.55,"id":19144241}]}]}
{"op":"mcm","clk":"11780360625","pt":1722863958699,"mc":[{"id":"1.231426403","rc":[{"batb":[[0,1.91,6],[1,1.9,49.27],[2,1.81,8.96]],"ltp":1.94,"tv":104.55,"id":19144241}]}]}
{"op":"mcm","clk":"11780360629","pt":1722863958907,"mc":[{"id":"1.231426403","rc":[{"batb":[[0,1.99,10],[1,1.98,45.25],[2,1.97,31]],"ltp":2.02,"tv":13.73,"id":19144236},{"batb":[[0,1.92,10],[1,1.91,6],[2,1.9,49.27]],"ltp":1.94,"tv":104.55,"id":19144241}]}]}
{"op":"mcm","clk":"11780360758","pt":1722863962414,"mc":[{"id":"1.231426403","rc":[{"batb":[[0,1.98,45.25],[1,1.97,31],[2,1.96,8.27]],"ltp":2.02,"tv":13.73,"id":19144236},{"batb":[[0,1.92,2]],"ltp":1.94,"tv":104.55,"id":19144241}]}]}
{"op":"mcm","clk":"11780360828","pt":1722863964729,"mc":[{"id":"1.231426403","rc":[{"batb":[[0,1.99,10],[1,1.98,45.25],[2,1.97,31]],"ltp":2.02,"tv":13.73,"id":19144236},{"batb":[[0,1.91,6],[1,1.9,49.27],[2,1.81,8.96]],"ltp":1.94,"tv":104.55,"id":19144241}]}]}
{"op":"mcm","clk":"11780360841","pt":1722863965000,"mc":[{"id":"1.231426403","rc":[{"batb":[[0,1.92,10],[1,1.91,6],[2,1.9,49.27]],"ltp":1.94,"tv":104.55,"id":19144241}]}]}
{"op":"mcm","clk":"11780360951","pt":1722863968336,"mc":[{"id":"1.231426403","rc":[{"batb":[[0,1.98,45.25],[1,1.97,31],[2,1.96,8.27]],"ltp":2.02,"tv":13.73,"id":19144236},{"batb":[[0,1.93,2]],"ltp":1.94,"tv":104.55,"id":19144241}]}]}
{"op":"mcm","clk":"11780361043","pt":1722863970613,"mc":[{"id":"1.231426403","rc":[{"batb":[[0,1.99,10],[1,1.98,45.25],[2,1.97,31]],"ltp":2.02,"tv":13.73,"id":19144236},{"batb":[[0,1.92,10]],"ltp":1.94,"tv":104.55,"id":19144241}]}]}
{"op":"mcm","clk":"11780361153","pt":1722863974015,"mc":[{"id":"1.231426403","rc":[{"batb":[[0,1.98,45.25],[1,1.97,31],[2,1.96,8.27]],"ltp":2.02,"tv":13.73,"id":19144236},{"batb":[[0,1.92,2]],"ltp":1.94,"tv":104.55,"id":19144241}]}]}
{"op":"mcm","clk":"11780361233","pt":1722863976429,"mc":[{"id":"1.231426403","rc":[{"batb":[[0,1.99,10],[1,1.98,45.25],[2,1.97,31]],"ltp":2.02,"tv":13.73,"id":19144236},{"batb":[[0,1.92,10]],"ltp":1.94,"tv":104.55,"id":19144241}]}]}
{"op":"mcm","clk":"11780361333","pt":1722863979728,"mc":[{"id":"1.231426403","rc":[{"batb":[[0,1.98,45.25],[1,1.97,31],[2,1.96,8.27]],"ltp":2.02,"tv":13.73,"id":19144236},{"batb":[[0,1.91,6],[1,1.9,49.27],[2,1.81,8.96]],"ltp":1.94,"tv":104.55,"id":19144241}]}]}
{"op":"mcm","clk":"11780361339","pt":1722863979936,"mc":[{"id":"1.231426403","rc":[{"batb":[[0,1.92,2],[1,1.91,6],[2,1.9,49.27]],"ltp":1.94,"tv":104.55,"id":19144241}]}]}
{"op":"mcm","clk":"11780361420","pt":1722863982413,"mc":[{"id":"1.231426403","rc":[{"batb":[[0,1.99,10],[1,1.98,45.25],[2,1.97,31]],"ltp":2.02,"tv":13.73,"id":19144236},{"batb":[[0,1.92,10]],"ltp":1.94,"tv":104.55,"id":19144241}]}]}
{"op":"mcm","clk":"11780361518","pt":1722863985816,"mc":[{"id":"1.231426403","rc":[{"batb":[[0,1.98,45.25],[1,1.97,31],[2,1.96,8.27]],"ltp":2.02,"tv":13.73,"id":19144236},{"batb":[[0,1.93,2]],"ltp":1.94,"tv":104.55,"id":19144241}]}]}
{"op":"mcm","clk":"11780361608","pt":1722863988642,"mc":[{"id":"1.231426403","rc":[{"batb":[[0,1.99,10],[1,1.98,45.25],[2,1.97,31]],"ltp":2.02,"tv":13.73,"id":19144236},{"batb":[[0,1.92,10]],"ltp":1.94,"tv":104.55,"id":19144241}]}]}
{"op":"mcm","clk":"11780361706","pt":1722863992242,"mc":[{"id":"1.231426403","rc":[{"batb":[[0,1.98,45.25],[1,1.97,31],[2,1.96,8.27]],"ltp":2.02,"tv":13.73,"id":19144236},{"batb":[[0,1.92,2]],"ltp":1.94,"tv":104.55,"id":19144241}]}]}
{"op":"mcm","clk":"11780361793","pt":1722863994739,"mc":[{"id":"1.231426403","rc":[{"batb":[[0,1.99,10],[1,1.98,45.25],[2,1.97,31]],"ltp":2.02,"tv":13.73,"id":19144236},{"batb":[[0,1.92,10]],"ltp":1.94,"tv":104.55,"id":19144241}]}]}
{"op":"mcm","clk":"11780361905","pt":1722863998350,"mc":[{"id":"1.231426403","rc":[{"batb":[[0,1.98,45.25],[1,1.97,31],[2,1.96,8.27]],"ltp":2.02,"tv":13.73,"id":19144236},{"batb":[[0,1.92,2]],"ltp":1.94,"tv":104.55,"id":19144241}]}]}
{"op":"mcm","clk":"11780361990","pt":1722864000753,"mc":[{"id":"1.231426403","rc":[{"batb":[[0,1.91,6],[1,1.9,49.27],[2,1.81,8.96]],"ltp":1.94,"tv":104.55,"id":19144241}]}]}
{"op":"mcm","clk":"11780362002","pt":1722864000969,"mc":[{"id":"1.231426403","rc":[{"batb":[[0,1.99,10],[1,1.98,45.25],[2,1.97,31]],"ltp":2.02,"tv":13.73,"id":19144236},{"batb":[[0,1.92,10],[1,1.91,6],[2,1.9,49.27]],"ltp":1.94,"tv":104.55,"id":19144241}]}]}
{"op":"mcm","clk":"11780362113","pt":1722864004478,"mc":[{"id":"1.231426403","rc":[{"batb":[[0,1.98,45.25],[1,1.97,31],[2,1.96,8.27]],"ltp":2.02,"tv":13.73,"id":19144236},{"batb":[[0,1.92,2]],"ltp":1.94,"tv":104.55,"id":19144241}]}]}
{"op":"mcm","clk":"11780362197","pt":1722864006754,"mc":[{"id":"1.231426403","rc":[{"batb":[[0,1.91,6],[1,1.9,49.27],[2,1.81,8.96]],"ltp":1.94,"tv":104.55,"id":19144241}]}]}
{"op":"mcm","clk":"11780362207","pt":1722864006961,"mc":[{"id":"1.231426403","rc":[{"batb":[[0,1.99,10],[1,1.98,45.25],[2,1.97,31]],"ltp":2.02,"tv":13.73,"id":19144236},{"batb":[[0,1.92,10],[1,1.91,6],[2,1.9,49.27]],"ltp":1.94,"tv":104.55,"id":19144241}]}]}
{"op":"mcm","clk":"11780362291","pt":1722864009244,"mc":[{"id":"1.231426403","rc":[{"batb":[[0,1.93,2],[1,1.92,10],[2,1.91,6]],"ltp":1.94,"tv":104.55,"id":19144241}]}]}
{"op":"mcm","clk":"11780362330","pt":1722864010381,"mc":[{"id":"1.231426403","rc":[{"batb":[[0,1.98,45.25],[1,1.97,31],[2,1.96,8.27]],"ltp":2.02,"tv":13.73,"id":19144236},{"batb":[[1,1.91,6],[2,1.9,49.27]],"ltp":1.94,"tv":104.55,"id":19144241}]}]}
{"op":"mcm","clk":"11780362368","pt":1722864011775,"mc":[{"id":"1.231426403","rc":[{"batb":[[0,1.91,6],[1,1.9,49.27],[2,1.81,8.96]],"ltp":1.94,"tv":104.55,"id":19144241}]}]}
{"op":"mcm","clk":"11780362595","pt":1722864019565,"mc":[{"id":"1.231426403","rc":[{"batb":[[0,1.99,10],[1,1.98,45.25],[2,1.97,31]],"ltp":2.02,"tv":13.73,"id":19144236},{"batb":[[0,1.92,12],[1,1.91,6],[2,1.9,49.27]],"ltp":1.94,"tv":104.55,"id":19144241}]}]}
{"op":"mcm","clk":"11780362643","pt":1722864021986,"mc":[{"id":"1.231426403","rc":[{"batb":[[0,1.92,10]],"ltp":1.94,"tv":104.55,"id":19144241}]}]}
{"op":"mcm","clk":"11780362672","pt":1722864023074,"mc":[{"id":"1.231426403","rc":[{"batb":[[0,1.98,45.25],[1,1.97,31],[2,1.96,8.27]],"ltp":2.02,"tv":13.73,"id":19144236},{"batb":[[0,1.91,6],[1,1.9,49.27],[2,1.81,8.96]],"ltp":1.94,"tv":104.55,"id":19144241}]}]}
{"op":"mcm","clk":"11780363480","pt":1722864058297,"mc":[{"id":"1.231426403","rc":[{"batb":[[0,1.99,10],[1,1.98,45.25],[2,1.97,31]],"ltp":2.02,"tv":13.73,"id":19144236},{"batb":[[0,1.92,12],[1,1.91,6],[2,1.9,49.27]],"ltp":1.94,"tv":104.55,"id":19144241}]}]}
{"op":"mcm","clk":"11780363573","pt":1722864061600,"mc":[{"id":"1.231426403","rc":[{"batb":[[0,1.98,45.25],[1,1.97,31],[2,1.96,8.27]],"ltp":2.02,"tv":13.73,"id":19144236},{"batb":[[0,1.91,6],[1,1.9,49.27],[2,1.81,8.96]],"ltp":1.94,"tv":104.55,"id":19144241}]}]}
{"op":"mcm","clk":"11780363796","pt":1722864068409,"mc":[{"id":"1.231426403","rc":[{"batb":[[0,1.99,10],[1,1.98,45.25],[2,1.97,31]],"ltp":2.02,"tv":13.73,"id":19144236},{"batb":[[0,1.92,12],[1,1.91,6],[2,1.9,49.27]],"ltp":1.94,"tv":104.55,"id":19144241}]}]}
{"op":"mcm","clk":"11780363877","pt":1722864070932,"mc":[{"id":"1.231426403","rc":[{"batb":[[0,1.92,10]],"ltp":1.94,"tv":104.55,"id":19144241}]}]}
{"op":"mcm","clk":"11780363912","pt":1722864072122,"mc":[{"id":"1.231426403","rc":[{"batb":[[0,1.98,45.25],[1,1.97,31],[2,1.96,8.27]],"ltp":2.02,"tv":13.73,"id":19144236},{"batb":[[0,1.91,6],[1,1.9,49.27],[2,1.81,8.96]],"ltp":1.94,"tv":104.55,"id":19144241}]}]}
{"op":"mcm","clk":"11780363943","pt":1722864073661,"mc":[{"id":"1.231426403","rc":[{"batb":[[0,1.92,2],[1,1.91,6],[2,1.9,49.27]],"ltp":1.94,"tv":104.55,"id":19144241}]}]}
{"op":"mcm","clk":"11780364020","pt":1722864076235,"mc":[{"id":"1.231426403","rc":[{"batb":[[0,1.99,10],[1,1.98,45.25],[2,1.97,31]],"ltp":2.02,"tv":13.73,"id":19144236},{"batb":[[0,1.92,10]],"ltp":1.94,"tv":104.55,"id":19144241}]}]}
{"op":"mcm","clk":"11780364116","pt":1722864079745,"mc":[{"id":"1.231426403","rc":[{"batb":[[0,1.98,45.25],[1,1.97,31],[2,1.96,8.27]],"ltp":2.02,"tv":13.73,"id":19144236},{"batb":[[0,1.92,2]],"ltp":1.94,"tv":104.55,"id":19144241}]}]}
{"op":"mcm","clk":"11780364186","pt":1722864082366,"mc":[{"id":"1.231426403","rc":[{"batb":[[0,1.99,10],[1,1.98,45.25],[2,1.97,31]],"ltp":2.02,"tv":13.73,"id":19144236},{"batb":[[0,1.92,10]],"ltp":1.94,"tv":104.55,"id":19144241}]}]}
{"op":"mcm","clk":"11780364275","pt":1722864085553,"mc":[{"id":"1.231426403","rc":[{"batb":[[0,1.98,45.25],[1,1.97,31],[2,1.96,8.27]],"ltp":2.02,"tv":13.73,"id":19144236},{"batb":[[0,1.91,6],[1,1.9,49.27],[2,1.81,8.96]],"ltp":1.94,"tv":104.55,"id":19144241}]}]}
{"op":"mcm","clk":"11780364288","pt":1722864085862,"mc":[{"id":"1.231426403","rc":[{"batb":[[0,1.92,2],[1,1.91,6],[2,1.9,49.27]],"ltp":1.94,"tv":104.55,"id":19144241}]}]}
{"op":"mcm","clk":"11780364372","pt":1722864088346,"mc":[{"id":"1.231426403","rc":[{"batb":[[0,1.99,10],[1,1.98,45.25],[2,1.97,31]],"ltp":2.02,"tv":13.73,"id":19144236},{"batb":[[0,1.92,10]],"ltp":1.94,"tv":104.55,"id":19144241}]}]}
{"op":"mcm","clk":"11780364472","pt":1722864091639,"mc":[{"id":"1.231426403","rc":[{"batb":[[0,1.98,45.25],[1,1.97,31],[2,1.96,8.27]],"ltp":2.02,"tv":13.73,"id":19144236},{"batb":[[0,1.91,6],[1,1.9,49.27],[2,1.81,8.96]],"ltp":1.94,"tv":104.55,"id":19144241}]}]}
{"op":"mcm","clk":"11780364477","pt":1722864091848,"mc":[{"id":"1.231426403","rc":[{"batb":[[0,1.92,2],[1,1.91,6],[2,1.9,49.27]],"ltp":1.94,"tv":104.55,"id":19144241}]}]}
{"op":"mcm","clk":"11780364536","pt":1722864094377,"mc":[{"id":"1.231426403","rc":[{"batb":[[0,1.99,10],[1,1.98,45.25],[2,1.97,31]],"ltp":2.02,"tv":13.73,"id":19144236},{"batb":[[0,1.92,10]],"ltp":1.94,"tv":104.55,"id":19144241}]}]}
{"op":"mcm","clk":"11780364628","pt":1722864097741,"mc":[{"id":"1.231426403","rc":[{"batb":[[0,1.98,45.25],[1,1.97,31],[2,1.96,8.27]],"ltp":2.02,"tv":13.73,"id":19144236}]}]}
{"op":"mcm","clk":"11780364630","pt":1722864097846,"mc":[{"id":"1.231426403","rc":[{"batb":[[0,1.93,2]],"ltp":1.94,"tv":104.55,"id":19144241}]}]}
{"op":"mcm","clk":"11780364703","pt":1722864100480,"mc":[{"id":"1.231426403","rc":[{"batb":[[0,1.99,10],[1,1.98,45.25],[2,1.97,31]],"ltp":2.02,"tv":13.73,"id":19144236},{"batb":[[0,1.92,10]],"ltp":1.94,"tv":104.55,"id":19144241}]}]}
{"op":"mcm","clk":"11780364792","pt":1722864104070,"mc":[{"id":"1.231426403","rc":[{"batb":[[0,1.98,45.25],[1,1.97,31],[2,1.96,8.27]],"ltp":2.02,"tv":13.73,"id":19144236},{"batb":[[0,1.92,2]],"ltp":1.94,"tv":104.55,"id":19144241}]}]}
{"op":"mcm","clk":"11780364872","pt":1722864106588,"mc":[{"id":"1.231426403","rc":[{"batb":[[0,1.99,10],[1,1.98,45.25],[2,1.97,31]],"ltp":2.02,"tv":13.73,"id":19144236},{"batb":[[0,1.92,10]],"ltp":1.94,"tv":104.55,"id":19144241}]}]}
{"op":"mcm","clk":"11780364952","pt":1722864109881,"mc":[{"id":"1.231426403","rc":[{"batb":[[0,1.98,45.25],[1,1.97,31],[2,1.96,8.27]],"ltp":2.02,"tv":13.73,"id":19144236},{"batb":[[0,1.93,2]],"ltp":1.94,"tv":104.55,"id":19144241}]}]}
{"op":"mcm","clk":"11780365046","pt":1722864112462,"mc":[{"id":"1.231426403","rc":[{"batb":[[0,1.99,10],[1,1.98,45.25],[2,1.97,31]],"ltp":2.02,"tv":13.73,"id":19144236},{"batb":[[0,1.92,10]],"ltp":1.94,"tv":104.55,"id":19144241}]}]}
{"op":"mcm","clk":"11780365146","pt":1722864116077,"mc":[{"id":"1.231426403","rc":[{"batb":[[0,1.98,45.25],[1,1.97,31],[2,1.96,8.27]],"ltp":2.02,"tv":13.73,"id":19144236},{"batb":[[0,1.92,2]],"ltp":1.94,"tv":104.55,"id":19144241}]}]}
{"op":"mcm","clk":"11780365215","pt":1722864118560,"mc":[{"id":"1.231426403","rc":[{"batb":[[0,1.99,10],[1,1.98,45.25],[2,1.97,31]],"ltp":2.02,"tv":13.73,"id":19144236},{"batb":[[0,1.92,10]],"ltp":1.94,"tv":104.55,"id":19144241}]}]}
{"op":"mcm","clk":"11780365303","pt":1722864122070,"mc":[{"id":"1.231426403","rc":[{"batb":[[0,1.98,45.25],[1,1.97,31],[2,1.96,8.27]],"ltp":2.02,"tv":13.73,"id":19144236},{"batb":[[0,1.92,2]],"ltp":1.94,"tv":104.55,"id":19144241}]}]}
{"op":"mcm","clk":"11780365390","pt":1722864124652,"mc":[{"id":"1.231426403","rc":[{"batb":[[0,1.99,10],[1,1.98,45.25],[2,1.97,31]],"ltp":2.02,"tv":13.73,"id":19144236},{"batb":[[0,1.92,10]],"ltp":1.94,"tv":104.55,"id":19144241}]}]}
{"op":"mcm","clk":"11780365501","pt":1722864127798,"mc":[{"id":"1.231426403","rc":[{"batb":[[0,1.98,45.25],[1,1.97,31],[2,1.96,8.27]],"ltp":2.02,"tv":13.73,"id":19144236},{"batb":[[0,1.93,2],[1,1.92,10],[2,1.91,6]],"ltp":1.94,"tv":104.55,"id":19144241}]}]}
{"op":"mcm","clk":"11780365504","pt":1722864127899,"mc":[{"id":"1.231426403","rc":[{"batb":[[1,1.91,6],[2,1.9,49.27]],"ltp":1.94,"tv":104.55,"id":19144241}]}]}
{"op":"mcm","clk":"11780365564","pt":1722864130374,"mc":[{"id":"1.231426403","rc":[{"batb":[[0,1.99,10],[1,1.98,45.25],[2,1.97,31]],"ltp":2.02,"tv":13.73,"id":19144236},{"batb":[[0,1.92,10]],"ltp":1.94,"tv":104.55,"id":19144241}]}]}
{"op":"mcm","clk":"11780365637","pt":1722864133677,"mc":[{"id":"1.231426403","rc":[{"batb":[[0,1.98,45.25],[1,1.97,31],[2,1.96,8.27]],"ltp":2.02,"tv":13.73,"id":19144236},{"batb":[[0,1.91,6],[1,1.9,49.27],[2,1.81,8.96]],"ltp":1.94,"tv":104.55,"id":19144241}]}]}
{"op":"mcm","clk":"11780365641","pt":1722864133883,"mc":[{"id":"1.231426403","rc":[{"batb":[[0,1.92,2],[1,1.91,6],[2,1.9,49.27]],"ltp":1.94,"tv":104.55,"id":19144241}]}]}
{"op":"mcm","clk":"11780365695","pt":1722864136307,"mc":[{"id":"1.231426403","rc":[{"batb":[[0,1.99,10],[1,1.98,45.25],[2,1.97,31]],"ltp":2.02,"tv":13.73,"id":19144236},{"batb":[[0,1.92,10]],"ltp":1.94,"tv":104.55,"id":19144241}]}]}
{"op":"mcm","clk":"11780365789","pt":1722864139764,"mc":[{"id":"1.231426403","rc":[{"batb":[[0,1.98,45.25],[1,1.97,31],[2,1.96,8.27]],"ltp":2.02,"tv":13.73,"id":19144236},{"batb":[[0,1.92,2]],"ltp":1.94,"tv":104.55,"id":19144241}]}]}
{"op":"mcm","clk":"11780365855","pt":1722864142192,"mc":[{"id":"1.231426403","rc":[{"batb":[[0,1.99,10],[1,1.98,45.25],[2,1.97,31]],"ltp":2.02,"tv":13.73,"id":19144236},{"batb":[[0,1.92,10]],"ltp":1.94,"tv":104.55,"id":19144241}]}]}
{"op":"mcm","clk":"11780365937","pt":1722864145699,"mc":[{"id":"1.231426403","rc":[{"batb":[[0,1.98,45.25],[1,1.97,31],[2,1.96,8.27]],"ltp":2.02,"tv":13.73,"id":19144236},{"batb":[[0,1.92,2]],"ltp":1.94,"tv":104.55,"id":19144241}]}]}
{"op":"mcm","clk":"11780365994","pt":1722864148117,"mc":[{"id":"1.231426403","rc":[{"batb":[[0,1.99,10],[1,1.98,45.25],[2,1.97,31]],"ltp":2.02,"tv":13.73,"id":19144236},{"batb":[[0,1.92,10]],"ltp":1.94,"tv":104.55,"id":19144241}]}]}
{"op":"mcm","clk":"11780366083","pt":1722864151729,"mc":[{"id":"1.231426403","rc":[{"batb":[[0,1.98,45.25],[1,1.97,31],[2,1.96,8.27]],"ltp":2.02,"tv":13.73,"id":19144236},{"batb":[[0,1.92,2]],"ltp":1.94,"tv":104.55,"id":19144241}]}]}
{"op":"mcm","clk":"11780366142","pt":1722864154303,"mc":[{"id":"1.231426403","rc":[{"batb":[[0,1.99,10],[1,1.98,45.25],[2,1.97,31]],"ltp":2.02,"tv":13.73,"id":19144236},{"batb":[[0,1.92,10]],"ltp":1.94,"tv":104.55,"id":19144241}]}]}
{"op":"mcm","clk":"11780366212","pt":1722864157710,"mc":[{"id":"1.231426403","rc":[{"batb":[[0,1.98,45.25],[1,1.97,31],[2,1.96,8.27]],"ltp":2.02,"tv":13.73,"id":19144236},{"batb":[[0,1.91,6],[1,1.9,49.27],[2,1.81,8.96]],"ltp":1.94,"tv":104.55,"id":19144241}]}]}
{"op":"mcm","clk":"11780366215","pt":1722864157917,"mc":[{"id":"1.231426403","rc":[{"batb":[[0,1.92,2],[1,1.91,6],[2,1.9,49.27]],"ltp":1.94,"tv":104.55,"id":19144241}]}]}
{"op":"mcm","clk":"11780366277","pt":1722864160391,"mc":[{"id":"1.231426403","rc":[{"batb":[[0,1.99,10],[1,1.98,45.25],[2,1.97,31]],"ltp":2.02,"tv":13.73,"id":19144236},{"batb":[[0,1.92,10]],"ltp":1.94,"tv":104.55,"id":19144241}]}]}
{"op":"mcm","clk":"11780366345","pt":1722864163807,"mc":[{"id":"1.231426403","rc":[{"batb":[[0,1.98,45.25],[1,1.97,31],[2,1.96,8.27]],"ltp":2.02,"tv":13.73,"id":19144236},{"batb":[[0,1.92,2]],"ltp":1.94,"tv":104.55,"id":19144241}]}]}
{"op":"mcm","clk":"11780366395","pt":1722864166329,"mc":[{"id":"1.231426403","rc":[{"batb":[[0,1.99,10],[1,1.98,45.25],[2,1.97,31]],"ltp":2.02,"tv":13.73,"id":19144236},{"batb":[[0,1.92,10]],"ltp":1.94,"tv":104.55,"id":19144241}]}]}
{"op":"mcm","clk":"11780366454","pt":1722864169627,"mc":[{"id":"1.231426403","rc":[{"batb":[[0,1.98,45.25],[1,1.97,31],[2,1.96,8.27]],"ltp":2.02,"tv":13.73,"id":19144236},{"batb":[[0,1.92,2]],"ltp":1.94,"tv":104.55,"id":19144241}]}]}
{"op":"mcm","clk":"11780366514","pt":1722864172207,"mc":[{"id":"1.231426403","rc":[{"batb":[[0,1.99,10],[1,1.98,45.25],[2,1.97,31]],"ltp":2.02,"tv":13.73,"id":19144236},{"batb":[[0,1.92,10]],"ltp":1.94,"tv":104.55,"id":19144241}]}]}
{"op":"mcm","clk":"11780366568","pt":1722864174599,"mc":[{"id":"1.231426403","rc":[{"batb":[[0,1.93,2],[1,1.92,10],[2,1.91,6]],"ltp":1.94,"tv":104.55,"id":19144241}]}]}
{"op":"mcm","clk":"11780366589","pt":1722864175429,"mc":[{"id":"1.231426403","rc":[{"batb":[[0,1.98,45.25],[1,1.97,31],[2,1.96,8.27]],"ltp":2.02,"tv":13.73,"id":19144236},{"batb":[[1,1.91,6],[2,1.9,49.27]],"ltp":1.94,"tv":104.55,"id":19144241}]}]}
{"op":"mcm","clk":"11780366609","pt":1722864176923,"mc":[{"id":"1.231426403","rc":[{"batb":[[0,1.91,6],[1,1.9,49.27],[2,1.81,8.96]],"ltp":1.94,"tv":104.55,"id":19144241}]}]}
{"op":"mcm","clk":"11780367324","pt":1722864203735,"mc":[{"id":"1.231426403","rc":[{"batb":[[0,1.99,10],[1,1.98,45.25],[2,1.97,31]],"ltp":2.02,"tv":13.73,"id":19144236},{"batb":[[0,1.92,10],[1,1.91,6],[2,1.9,49.27]],"ltp":1.94,"tv":104.55,"id":19144241}]}]}
{"op":"mcm","clk":"11780367328","pt":1722864203835,"mc":[{"id":"1.231426403","rc":[{"batb":[[0,1.92,12]],"ltp":1.94,"tv":104.55,"id":19144241}]}]}
{"op":"mcm","clk":"11780367378","pt":1722864206348,"mc":[{"id":"1.231426403","rc":[{"batb":[[0,1.92,10]],"ltp":1.94,"tv":104.55,"id":19144241}]}]}
{"op":"mcm","clk":"11780367391","pt":1722864207017,"mc":[{"id":"1.231426403","rc":[{"batb":[[0,1.98,45.25],[1,1.97,31],[2,1.96,8.27]],"ltp":2.02,"tv":13.73,"id":19144236},{"batb":[[0,1.91,6],[1,1.9,49.27],[2,1.81,8.96]],"ltp":1.94,"tv":104.55,"id":19144241}]}]}
{"op":"mcm","clk":"11780368252","pt":1722864241953,"mc":[{"id":"1.231426403","rc":[{"batb":[[0,1.99,10],[1,1.98,45.25],[2,1.97,31]],"ltp":2.02,"tv":13.73,"id":19144236},{"batb":[[0,1.92,12],[1,1.91,6],[2,1.9,49.27]],"ltp":1.94,"tv":104.55,"id":19144241}]}]}
{"op":"mcm","clk":"11780368336","pt":1722864244357,"mc":[{"id":"1.231426403","rc":[{"batb":[[0,1.92,10]],"ltp":1.94,"tv":104.55,"id":19144241}]}]}
{"op":"mcm","clk":"11780368376","pt":1722864245494,"mc":[{"id":"1.231426403","rc":[{"batb":[[0,1.98,45.25],[1,1.97,31],[2,1.96,8.27]],"ltp":2.02,"tv":13.73,"id":19144236},{"batb":[[0,1.91,6],[1,1.9,49.27],[2,1.81,8.96]],"ltp":1.94,"tv":104.55,"id":19144241}]}]}
{"op":"mcm","clk":"11780368747","pt":1722864257180,"mc":[{"id":"1.231426403","rc":[{"batb":[[0,1.99,10],[1,1.98,45.25],[2,1.97,31]],"ltp":2.02,"tv":13.73,"id":19144236},{"batb":[[0,1.92,12],[1,1.91,6],[2,1.9,49.27]],"ltp":1.94,"tv":104.55,"id":19144241}]}]}
{"op":"mcm","clk":"11780368830","pt":1722864259674,"mc":[{"id":"1.231426403","rc":[{"batb":[[0,1.92,10]],"ltp":1.94,"tv":104.55,"id":19144241}]}]}
{"op":"mcm","clk":"11780368861","pt":1722864260700,"mc":[{"id":"1.231426403","rc":[{"batb":[[0,1.98,45.25],[1,1.97,31],[2,1.96,8.27]],"ltp":2.02,"tv":13.73,"id":19144236},{"batb":[[0,1.91,6],[1,1.9,49.27],[2,1.81,8.96]],"ltp":1.94,"tv":104.55,"id":19144241}]}]}
{"op":"mcm","clk":"11780369074","pt":1722864267701,"mc":[{"id":"1.231426403","rc":[{"batb":[[0,1.99,10],[1,1.98,45.25],[2,1.97,31]],"ltp":2.02,"tv":13.73,"id":19144236},{"batb":[[0,1.92,12],[1,1.91,6],[2,1.9,49.27]],"ltp":1.94,"tv":104.55,"id":19144241}]}]}
{"op":"mcm","clk":"11780369146","pt":1722864270014,"mc":[{"id":"1.231426403","rc":[{"batb":[[0,1.92,10]],"ltp":1.94,"tv":104.55,"id":19144241}]}]}
{"op":"mcm","clk":"11780369176","pt":1722864270993,"mc":[{"id":"1.231426403","rc":[{"batb":[[0,1.98,45.25],[1,1.97,31],[2,1.96,8.27]],"ltp":2.02,"tv":13.73,"id":19144236},{"batb":[[0,1.91,6],[1,1.9,49.27],[2,1.81,8.96]],"ltp":1.94,"tv":104.55,"id":19144241}]}]}
{"op":"mcm","clk":"11780369226","pt":1722864272692,"mc":[{"id":"1.231426403","rc":[{"batb":[[0,1.92,2],[1,1.91,6],[2,1.9,49.27]],"ltp":1.94,"tv":104.55,"id":19144241}]}]}
{"op":"mcm","clk":"11780369335","pt":1722864275411,"mc":[{"id":"1.231426403","rc":[{"batb":[[0,1.99,10],[1,1.98,45.25],[2,1.97,31]],"ltp":2.02,"tv":13.73,"id":19144236},{"batb":[[0,1.92,10]],"ltp":1.94,"tv":104.55,"id":19144241}]}]}
{"op":"mcm","clk":"11780369446","pt":1722864278607,"mc":[{"id":"1.231426403","rc":[{"batb":[[0,1.98,45.25],[1,1.97,31],[2,1.96,8.27]],"ltp":2.02,"tv":13.73,"id":19144236},{"batb":[[0,1.93,2]],"ltp":1.94,"tv":104.55,"id":19144241}]}]}
{"op":"mcm","clk":"11780369518","pt":1722864280814,"mc":[{"id":"1.231426403","rc":[{"batb":[[0,1.91,6],[1,1.9,49.27],[2,1.81,8.96]],"ltp":1.94,"tv":104.55,"id":19144241}]}]}
{"op":"mcm","clk":"11780369520","pt":1722864280914,"mc":[{"id":"1.231426403","rc":[{"batb":[[0,1.99,10],[1,1.98,45.25],[2,1.97,31]],"ltp":2.02,"tv":13.73,"id":19144236},{"batb":[[0,1.92,10],[1,1.91,6],[2,1.9,49.27]],"ltp":1.94,"tv":104.55,"id":19144241}]}]}
{"op":"mcm","clk":"11780369628","pt":1722864284214,"mc":[{"id":"1.231426403","rc":[{"batb":[[0,1.98,45.25],[1,1.97,31],[2,1.96,8.27]],"ltp":2.02,"tv":13.73,"id":19144236},{"batb":[[0,1.93,2]],"ltp":1.94,"tv":104.55,"id":19144241}]}]}
{"op":"mcm","clk":"11780369711","pt":1722864286733,"mc":[{"id":"1.231426403","rc":[{"batb":[[0,1.99,10],[1,1.98,45.25],[2,1.97,31]],"ltp":2.02,"tv":13.73,"id":19144236},{"batb":[[0,1.92,10]],"ltp":1.94,"tv":104.55,"id":19144241}]}]}
{"op":"mcm","clk":"11780369832","pt":1722864290329,"mc":[{"id":"1.231426403","rc":[{"batb":[[0,1.98,45.25],[1,1.97,31],[2,1.96,8.27]],"ltp":2.02,"tv":13.73,"id":19144236},{"batb":[[0,1.92,2]],"ltp":1.94,"tv":104.55,"id":19144241}]}]}
{"op":"mcm","clk":"11780369908","pt":1722864292740,"mc":[{"id":"1.231426403","rc":[{"batb":[[0,1.99,10],[1,1.98,45.25],[2,1.97,31]],"ltp":2.02,"tv":13.73,"id":19144236},{"batb":[[0,1.92,10]],"ltp":1.94,"tv":104.55,"id":19144241}]}]}
{"op":"mcm","clk":"11780370003","pt":1722864296026,"mc":[{"id":"1.231426403","rc":[{"batb":[[0,1.98,45.25],[1,1.97,31],[2,1.96,8.27]],"ltp":2.02,"tv":13.73,"id":19144236},{"batb":[[0,1.92,2]],"ltp":1.94,"tv":104.55,"id":19144241}]}]}
{"op":"mcm","clk":"11780370096","pt":1722864298542,"mc":[{"id":"1.231426403","rc":[{"batb":[[0,1.99,10],[1,1.98,45.25],[2,1.97,31]],"ltp":2.02,"tv":13.73,"id":19144236},{"batb":[[0,1.92,10]],"ltp":1.94,"tv":104.55,"id":19144241}]}]}
{"op":"mcm","clk":"11780370215","pt":1722864301758,"mc":[{"id":"1.231426403","rc":[{"batb":[[0,1.98,45.25],[1,1.97,31],[2,1.96,8.27]],"batl":[[2,2.54,4.04]],"ltp":2.02,"tv":13.73,"id":19144236},{"batb":[[0,1.93,2]],"ltp":1.94,"tv":104.55,"id":19144241}]}]}
{"op":"mcm","clk":"11780370278","pt":1722864303261,"mc":[{"id":"1.231426403","rc":[{"batb":[[0,1.91,6],[1,1.9,49.27],[2,1.81,8.96]],"ltp":1.94,"tv":104.55,"id":19144241}]}]}
{"op":"mcm","clk":"11780370431","pt":1722864307451,"mc":[{"id":"1.231426403","rc":[{"batb":[[0,1.99,10],[1,1.98,45.25],[2,1.97,31]],"ltp":2.02,"tv":13.73,"id":19144236},{"batb":[[0,1.92,12],[1,1.91,6],[2,1.9,49.27]],"ltp":1.94,"tv":104.55,"id":19144241}]}]}
{"op":"mcm","clk":"11780370558","pt":1722864310662,"mc":[{"id":"1.231426403","rc":[{"batb":[[0,1.98,45.25],[1,1.97,31],[2,1.96,8.27]],"ltp":2.02,"tv":13.73,"id":19144236},{"batb":[[0,1.91,6],[1,1.9,49.27],[2,1.81,8.96]],"ltp":1.94,"tv":104.55,"id":19144241}]}]}
{"op":"mcm","clk":"11780370625","pt":1722864312678,"mc":[{"id":"1.231426403","rc":[{"batb":[[0,1.92,2],[1,1.91,6],[2,1.9,49.27]],"ltp":1.94,"tv":104.55,"id":19144241}]}]}
{"op":"mcm","clk":"11780370695","pt":1722864315154,"mc":[{"id":"1.231426403","rc":[{"batb":[[0,1.99,10],[1,1.98,45.25],[2,1.97,31]],"ltp":2.02,"tv":13.73,"id":19144236},{"batb":[[0,1.92,10]],"ltp":1.94,"tv":104.55,"id":19144241}]}]}
{"op":"mcm","clk":"11780370787","pt":1722864318766,"mc":[{"id":"1.231426403","rc":[{"batb":[[0,1.98,45.25],[1,1.97,31],[2,1.96,8.27]],"ltp":2.02,"tv":13.73,"id":19144236},{"batb":[[0,1.92,2]],"ltp":1.94,"tv":104.55,"id":19144241}]}]}
{"op":"mcm","clk":"11780370855","pt":1722864321446,"mc":[{"id":"1.231426403","rc":[{"batb":[[0,1.99,10],[1,1.98,45.25],[2,1.97,31]],"ltp":2.02,"tv":13.73,"id":19144236},{"batb":[[0,1.92,10]],"ltp":1.94,"tv":104.55,"id":19144241}]}]}
{"op":"mcm","clk":"11780370959","pt":1722864324789,"mc":[{"id":"1.231426403","rc":[{"batb":[[0,1.98,45.25],[1,1.97,31],[2,1.96,8.27]],"ltp":2.02,"tv":13.73,"id":19144236},{"batb":[[0,1.92,2]],"ltp":1.94,"tv":104.55,"id":19144241}]}]}
{"op":"mcm","clk":"11780371026","pt":1722864327163,"mc":[{"id":"1.231426403","rc":[{"batb":[[0,1.99,10],[1,1.98,45.25],[2,1.97,31]],"ltp":2.02,"tv":13.73,"id":19144236},{"batb":[[0,1.92,10]],"ltp":1.94,"tv":104.55,"id":19144241}]}]}
{"op":"mcm","clk":"11780371083","pt":1722864329480,"mc":[{"id":"1.231426403","rc":[{"batb":[[0,1.93,2],[1,1.92,10],[2,1.91,6]],"ltp":1.94,"tv":104.55,"id":19144241}]}]}
{"op":"mcm","clk":"11780371109","pt":1722864330509,"mc":[{"id":"1.231426403","rc":[{"batb":[[0,1.98,45.25],[1,1.97,31],[2,1.96,8.27]],"ltp":2.02,"tv":13.73,"id":19144236},{"batb":[[1,1.91,6],[2,1.9,49.27]],"ltp":1.94,"tv":104.55,"id":19144241}]}]}
{"op":"mcm","clk":"11780371163","pt":1722864331706,"mc":[{"id":"1.231426403","rc":[{"batb":[[0,1.91,6],[1,1.9,49.27],[2,1.81,8.96]],"ltp":1.94,"tv":104.55,"id":19144241}]}]}
{"op":"mcm","clk":"11780371255","pt":1722864334966,"mc":[{"id":"1.231426403","rc":[{"batb":[[0,1.99,10],[1,1.98,45.25],[2,1.97,31]],"ltp":2.02,"tv":13.73,"id":19144236},{"batb":[[0,1.92,12],[1,1.91,6],[2,1.9,49.27]],"ltp":1.94,"tv":104.55,"id":19144241}]}]}
{"op":"mcm","clk":"11780371325","pt":1722864337292,"mc":[{"id":"1.231426403","rc":[{"batb":[[0,1.92,10]],"ltp":1.94,"tv":104.55,"id":19144241}]}]}
{"op":"mcm","clk":"11780371349","pt":1722864338273,"mc":[{"id":"1.231426403","rc":[{"batb":[[0,1.98,45.25],[1,1.97,31],[2,1.96,8.27]],"ltp":2.02,"tv":13.73,"id":19144236},{"batb":[[0,1.91,6],[1,1.9,49.27],[2,1.81,8.96]],"ltp":1.94,"tv":104.55,"id":19144241}]}]}
{"op":"mcm","clk":"11780371789","pt":1722864351824,"mc":[{"id":"1.231426403","rc":[{"batb":[[2,1.85,2]],"ltp":2.02,"tv":13.73,"id":19144236},{"batb":[[2,1.8,10]],"ltp":1.94,"tv":104.55,"id":19144241}]}]}
{"op":"mcm","clk":"11780371793","pt":1722864351927,"mc":[{"id":"1.231426403","rc":[{"batb":[[0,1.99,10],[1,1.98,45.25],[2,1.97,31]],"ltp":2.02,"tv":13.73,"id":19144236},{"batb":[[0,1.92,12],[1,1.91,6],[2,1.9,49.27]],"ltp":1.94,"tv":104.55,"id":19144241}]}]}
{"op":"mcm","clk":"11780371886","pt":1722864354095,"mc":[{"id":"1.231426403","rc":[{"batb":[[0,1.92,10]],"ltp":1.94,"tv":104.55,"id":19144241}]}]}
{"op":"mcm","clk":"11780371927","pt":1722864355125,"mc":[{"id":"1.231426403","rc":[{"batb":[[0,1.98,45.25],[1,1.97,31],[2,1.85,2]],"ltp":2.02,"tv":13.73,"id":19144236},{"batb":[[0,1.91,6],[1,1.9,49.27],[2,1.8,10]],"ltp":1.94,"tv":104.55,"id":19144241}]}]}
{"op":"mcm","clk":"11780372171","pt":1722864361019,"mc":[{"id":"1.231426403","rc":[{"batb":[[0,1.99,10],[1,1.98,45.25],[2,1.97,31]],"ltp":2.02,"tv":13.73,"id":19144236},{"batb":[[0,1.92,12],[1,1.91,6],[2,1.9,49.27]],"ltp":1.94,"tv":104.55,"id":19144241}]}]}
{"op":"mcm","clk":"11780372277","pt":1722864363446,"mc":[{"id":"1.231426403","rc":[{"batb":[[0,1.92,10]],"ltp":1.94,"tv":104.55,"id":19144241}]}]}
{"op":"mcm","clk":"11780372320","pt":1722864364426,"mc":[{"id":"1.231426403","rc":[{"batb":[[0,1.98,45.25],[1,1.97,31],[2,1.85,2]],"ltp":2.02,"tv":13.73,"id":19144236},{"batb":[[0,1.91,6],[1,1.9,49.27],[2,1.8,10]],"ltp":1.94,"tv":104.55,"id":19144241}]}]}
{"op":"mcm","clk":"11780373413","pt":1722864395463,"mc":[{"id":"1.231426403","rc":[{"batb":[[0,1.99,10],[1,1.98,45.25],[2,1.97,31]],"ltp":2.02,"tv":13.73,"id":19144236},{"batb":[[0,1.92,12],[1,1.91,6],[2,1.9,49.27]],"ltp":1.94,"tv":104.55,"id":19144241}]}]}
{"op":"mcm","clk":"11780373490","pt":1722864397777,"mc":[{"id":"1.231426403","rc":[{"batb":[[0,1.92,10]],"ltp":1.94,"tv":104.55,"id":19144241}]}]}
{"op":"mcm","clk":"11780373534","pt":1722864398956,"mc":[{"id":"1.231426403","rc":[{"batb":[[0,1.98,45.25],[1,1.97,31],[2,1.85,2]],"ltp":2.02,"tv":13.73,"id":19144236},{"batb":[[0,1.91,6],[1,1.9,49.27],[2,1.8,10]],"ltp":1.94,"tv":104.55,"id":19144241}]}]}
{"op":"mcm","clk":"11780374139","pt":1722864415102,"mc":[{"id":"1.231426403","rc":[{"batb":[[0,1.99,10],[1,1.98,45.25],[2,1.97,31]],"ltp":2.02,"tv":13.73,"id":19144236},{"batb":[[0,1.92,12],[1,1.91,6],[2,1.9,49.27]],"ltp":1.94,"tv":104.55,"id":19144241}]}]}
{"op":"mcm","clk":"11780374243","pt":1722864417470,"mc":[{"id":"1.231426403","rc":[{"batb":[[0,1.92,10]],"ltp":1.94,"tv":104.55,"id":19144241}]}]}
{"op":"mcm","clk":"11780374281","pt":1722864418601,"mc":[{"id":"1.231426403","rc":[{"batb":[[0,1.98,45.25],[1,1.97,31],[2,1.85,2]],"ltp":2.02,"tv":13.73,"id":19144236},{"batb":[[0,1.91,6],[1,1.9,49.27],[2,1.8,10]],"ltp":1.94,"tv":104.55,"id":19144241}]}]}
{"op":"mcm","clk":"11780374417","pt":1722864422213,"mc":[{"id":"1.231426403","rc":[{"batb":[[0,1.99,10],[1,1.98,45.25],[2,1.97,31]],"ltp":2.02,"tv":13.73,"id":19144236},{"batb":[[0,1.92,10],[1,1.91,6],[2,1.9,49.27]],"batl":[[0,3.8,0.57]],"ltp":1.94,"tv":104.55,"id":19144241}]}]}
{"op":"mcm","clk":"11780374572","pt":1722864425729,"mc":[{"id":"1.231426403","rc":[{"batb":[[0,1.98,45.25],[1,1.97,31],[2,1.85,2]],"ltp":2.02,"tv":13.73,"id":19144236},{"batb":[[0,1.91,6],[1,1.9,49.27],[2,1.8,10]],"batl":[[0,3.8,1.07]],"ltp":1.94,"tv":104.55,"id":19144241}]}]}
{"op":"mcm","clk":"11780374578","pt":1722864425833,"mc":[{"id":"1.231426403","rc":[{"batb":[[0,1.92,2],[1,1.91,6],[2,1.9,49.27]],"ltp":1.94,"tv":104.55,"id":19144241}]}]}
{"op":"mcm","clk":"11780374670","pt":1722864428427,"mc":[{"id":"1.231426403","rc":[{"batb":[[0,1.99,10],[1,1.98,45.25],[2,1.97,31]],"ltp":2.02,"tv":13.73,"id":19144236},{"batb":[[0,1.92,10]],"ltp":1.94,"tv":104.55,"id":19144241}]}]}
{"op":"mcm","clk":"11780374735","pt":1722864429820,"mc":[{"id":"1.231426403","rc":[{"batl":[[0,2.24,30.07],[1,2.54,4.04],[2,3.5,0.54]],"ltp":2.02,"tv":13.73,"id":19144236}]}]}
{"op":"mcm","clk":"11780374814","pt":1722864431731,"mc":[{"id":"1.231426403","rc":[{"batb":[[0,1.98,45.25],[1,1.97,31],[2,1.96,8.27]],"batl":[[0,2.22,1.01],[1,2.24,30.07],[2,2.54,4.04]],"ltp":2.02,"tv":13.73,"id":19144236},{"batb":[[0,1.93,2]],"ltp":1.94,"tv":104.55,"id":19144241}]}]}
{"op":"mcm","clk":"11780374880","pt":1722864433431,"mc":[{"id":"1.231426403","rc":[{"batb":[[0,1.91,6],[1,1.9,49.27],[2,1.81,8.96]],"ltp":1.94,"tv":104.55,"id":19144241}]}]}
{"op":"mcm","clk":"11780374935","pt":1722864434721,"mc":[{"id":"1.231426403","rc":[{"batb":[[0,1.99,10],[1,1.98,45.25],[2,1.97,31]],"ltp":2.02,"tv":13.73,"id":19144236},{"batb":[[0,1.92,10],[1,1.91,6],[2,1.9,49.27]],"ltp":1.94,"tv":104.55,"id":19144241}]}]}
{"op":"mcm","clk":"11780375085","pt":1722864438330,"mc":[{"id":"1.231426403","rc":[{"batb":[[0,1.98,45.25],[1,1.97,31],[2,1.96,8.27]],"ltp":2.02,"tv":13.73,"id":19144236},{"batb":[[0,1.92,2]],"ltp":1.94,"tv":104.55,"id":19144241}]}]}
{"op":"mcm","clk":"11780375170","pt":1722864440701,"mc":[{"id":"1.231426403","rc":[{"batb":[[0,1.91,6],[1,1.9,49.27],[2,1.81,8.96]],"ltp":1.94,"tv":104.55,"id":19144241}]}]}
{"op":"mcm","clk":"11780375179","pt":1722864440909,"mc":[{"id":"1.231426403","rc":[{"batb":[[0,1.99,10],[1,1.98,45.25],[2,1.97,31]],"ltp":2.02,"tv":13.73,"id":19144236},{"batb":[[0,1.92,10],[1,1.91,6],[2,1.9,49.27]],"ltp":1.94,"tv":104.55,"id":19144241}]}]}
{"op":"mcm","clk":"11780375328","pt":1722864444535,"mc":[{"id":"1.231426403","rc":[{"batb":[[0,1.98,45.25],[1,1.97,31],[2,1.96,8.27]],"ltp":2.02,"tv":13.73,"id":19144236},{"batb":[[0,1.92,2]],"ltp":1.94,"tv":104.55,"id":19144241}]}]}
{"op":"mcm","clk":"11780375405","pt":1722864446647,"mc":[{"id":"1.231426403","rc":[{"batb":[[0,1.99,10],[1,1.98,45.25],[2,1.97,31]],"ltp":2.02,"tv":13.73,"id":19144236}]}]}
{"op":"mcm","clk":"11780375418","pt":1722864447011,"mc":[{"id":"1.231426403","rc":[{"batb":[[0,1.92,10]],"ltp":1.94,"tv":104.55,"id":19144241}]}]}
{"op":"mcm","clk":"11780375546","pt":1722864450366,"mc":[{"id":"1.231426403","rc":[{"batb":[[0,1.98,45.25],[1,1.97,31],[2,1.96,8.27]],"ltp":2.02,"tv":13.73,"id":19144236},{"batb":[[0,1.93,2]],"ltp":1.94,"tv":104.55,"id":19144241}]}]}
{"op":"mcm","clk":"11780375639","pt":1722864452627,"mc":[{"id":"1.231426403","rc":[{"batb":[[0,1.99,10],[1,1.98,45.25],[2,1.97,31]],"ltp":2.02,"tv":13.73,"id":19144236},{"batb":[[0,1.92,10]],"ltp":1.94,"tv":104.55,"id":19144241}]}]}
{"op":"mcm","clk":"11780375749","pt":1722864455766,"mc":[{"id":"1.231426403","rc":[{"batb":[[0,1.98,45.25],[1,1.97,31],[2,1.96,8.27]],"ltp":2.02,"tv":13.73,"id":19144236}]}]}
{"op":"mcm","clk":"11780375760","pt":1722864455923,"mc":[{"id":"1.231426403","rc":[{"batb":[[0,1.93,2]],"ltp":1.94,"tv":104.55,"id":19144241}]}]}
{"op":"mcm","clk":"11780375884","pt":1722864458462,"mc":[{"id":"1.231426403","rc":[{"batb":[[0,1.99,10],[1,1.98,45.25],[2,1.97,31]],"ltp":2.02,"tv":13.73,"id":19144236},{"batb":[[0,1.92,10]],"ltp":1.94,"tv":104.55,"id":19144241}]}]}
{"op":"mcm","clk":"11780375976","pt":1722864460774,"mc":[{"id":"1.231426403","rc":[{"batb":[[0,1.93,2],[1,1.92,10],[2,1.91,6]],"ltp":1.94,"tv":104.55,"id":19144241}]}]}
{"op":"mcm","clk":"11780376022","pt":1722864461881,"mc":[{"id":"1.231426403","rc":[{"batb":[[0,1.98,45.25],[1,1.97,31],[2,1.96,8.27]],"ltp":2.02,"tv":13.73,"id":19144236},{"batb":[[1,1.91,6],[2,1.9,49.27]],"ltp":1.94,"tv":104.55,"id":19144241}]}]}
{"op":"mcm","clk":"11780376077","pt":1722864463175,"mc":[{"id":"1.231426403","rc":[{"batb":[[0,1.91,6],[1,1.9,49.27],[2,1.81,8.96]],"ltp":1.94,"tv":104.55,"id":19144241}]}]}
{"op":"mcm","clk":"11780376475","pt":1722864472985,"mc":[{"id":"1.231426403","rc":[{"batb":[[0,1.99,10],[1,1.98,45.25],[2,1.97,31]],"ltp":2.02,"tv":13.73,"id":19144236},{"batb":[[0,1.92,12],[1,1.91,6],[2,1.9,49.27]],"ltp":1.94,"tv":104.55,"id":19144241}]}]}
{"op":"mcm","clk":"11780376576","pt":1722864475771,"mc":[{"id":"1.231426403","rc":[{"batb":[[0,1.92,10]],"ltp":1.94,"tv":104.55,"id":19144241}]}]}
{"op":"mcm","clk":"11780376607","pt":1722864476597,"mc":[{"id":"1.231426403","rc":[{"batb":[[0,1.98,45.25],[1,1.97,31],[2,1.96,8.27]],"ltp":2.02,"tv":13.73,"id":19144236},{"batb":[[0,1.91,6],[1,1.9,49.27],[2,1.81,8.96]],"ltp":1.94,"tv":104.55,"id":19144241}]}]}
{"op":"mcm","clk":"11780376751","pt":1722864480383,"mc":[{"id":"1.231426403","rc":[{"batb":[[0,1.99,10],[1,1.98,45.25],[2,1.97,31]],"ltp":2.02,"tv":13.73,"id":19144236},{"batb":[[0,1.92,12],[1,1.91,6],[2,1.9,49.27]],"ltp":1.94,"tv":104.55,"id":19144241}]}]}
{"op":"mcm","clk":"11780376864","pt":1722864483002,"mc":[{"id":"1.231426403","rc":[{"batb":[[0,1.92,10]],"ltp":1.94,"tv":104.55,"id":19144241}]}]}
{"op":"mcm","clk":"11780376907","pt":1722864484092,"mc":[{"id":"1.231426403","rc":[{"batb":[[0,1.98,45.25],[1,1.97,31],[2,1.96,8.27]],"ltp":2.02,"tv":13.73,"id":19144236},{"batb":[[0,1.91,6],[1,1.9,49.27],[2,1.81,8.96]],"ltp":1.94,"tv":104.55,"id":19144241}]}]}
{"op":"mcm","clk":"11780376947","pt":1722864485291,"mc":[{"id":"1.231426403","rc":[{"batb":[[0,1.92,2],[1,1.91,6],[2,1.9,49.27]],"ltp":1.94,"tv":104.55,"id":19144241}]}]}
{"op":"mcm","clk":"11780376996","pt":1722864486489,"mc":[{"id":"1.231426403","rc":[{"batb":[[0,1.99,10],[1,1.98,45.25],[2,1.97,31]],"ltp":2.02,"tv":13.73,"id":19144236}]}]}
{"op":"mcm","clk":"11780377046","pt":1722864487696,"mc":[{"id":"1.231426403","rc":[{"batb":[[0,1.91,6],[1,1.9,49.27],[2,1.81,8.96]],"ltp":1.94,"tv":104.55,"id":19144241}]}]}
{"op":"mcm","clk":"11780377057","pt":1722864488007,"mc":[{"id":"1.231426403","rc":[{"batb":[[0,1.92,10],[1,1.91,6],[2,1.9,49.27]],"ltp":1.94,"tv":104.55,"id":19144241}]}]}
{"op":"mcm","clk":"11780377159","pt":1722864490295,"mc":[{"id":"1.231426403","rc":[{"batb":[[0,1.98,45.25],[1,1.97,31],[2,1.96,8.27]],"ltp":2.02,"tv":13.73,"id":19144236},{"batb":[[0,1.93,2],[1,1.92,10],[2,1.91,6]],"ltp":1.94,"tv":104.55,"id":19144241}]}]}
{"op":"mcm","clk":"11780377194","pt":1722864491386,"mc":[{"id":"1.231426403","rc":[{"batb":[[1,1.91,6],[2,1.9,49.27]],"ltp":1.94,"tv":104.55,"id":19144241}]}]}
{"op":"mcm","clk":"11780377234","pt":1722864492684,"mc":[{"id":"1.231426403","rc":[{"batb":[[0,1.91,6],[1,1.9,49.27],[2,1.81,8.96]],"ltp":1.94,"tv":104.55,"id":19144241}]}]}
{"op":"mcm","clk":"11780377240","pt":1722864492901,"mc":[{"id":"1.231426403","rc":[{"batb":[[0,1.99,10],[1,1.98,45.25],[2,1.97,31]],"ltp":2.02,"tv":13.73,"id":19144236}]}]}
{"op":"mcm","clk":"11780377309","pt":1722864495084,"mc":[{"id":"1.231426403","rc":[{"batb":[[0,1.92,12],[1,1.91,6],[2,1.9,49.27]],"ltp":1.94,"tv":104.55,"id":19144241}]}]}
{"op":"mcm","clk":"11780377357","pt":1722864496223,"mc":[{"id":"1.231426403","rc":[{"batb":[[0,1.98,45.25],[1,1.97,31],[2,1.96,8.27]],"ltp":2.02,"tv":13.73,"id":19144236}]}]}
{"op":"mcm","clk":"11780377403","pt":1722864497414,"mc":[{"id":"1.231426403","rc":[{"batb":[[0,1.92,10]],"ltp":1.94,"tv":104.55,"id":19144241}]}]}
{"op":"mcm","clk":"11780377453","pt":1722864498821,"mc":[{"id":"1.231426403","rc":[{"batb":[[0,1.99,10],[1,1.98,45.25],[2,1.97,31]],"ltp":2.02,"tv":13.73,"id":19144236},{"batb":[[0,1.91,6],[1,1.9,49.27],[2,1.81,8.96]],"ltp":1.94,"tv":104.55,"id":19144241}]}]}
{"op":"mcm","clk":"11780377597","pt":1722864502521,"mc":[{"id":"1.231426403","rc":[{"batb":[[0,1.98,45.25],[1,1.97,31],[2,1.96,8.27]],"ltp":2.02,"tv":13.73,"id":19144236},{"batb":[[0,1.92,12],[1,1.91,6],[2,1.9,49.27]],"ltp":1.94,"tv":104.55,"id":19144241}]}]}
{"op":"mcm","clk":"11780377708","pt":1722864504795,"mc":[{"id":"1.231426403","rc":[{"batb":[[0,1.92,10]],"ltp":1.94,"tv":104.55,"id":19144241}]}]}
{"op":"mcm","clk":"11780377741","pt":1722864505825,"mc":[{"id":"1.231426403","rc":[{"batb":[[0,1.99,10],[1,1.98,45.25],[2,1.97,31]],"ltp":2.02,"tv":13.73,"id":19144236},{"batb":[[0,1.91,6],[1,1.9,49.27],[2,1.81,8.96]],"ltp":1.94,"tv":104.55,"id":19144241}]}]}
{"op":"mcm","clk":"11780377843","pt":1722864508528,"mc":[{"id":"1.231426403","rc":[{"batb":[[0,1.98,45.25],[1,1.97,31],[2,1.96,8.27]],"ltp":2.02,"tv":13.73,"id":19144236},{"batb":[[0,1.92,12],[1,1.91,6],[2,1.9,49.27]],"ltp":1.94,"tv":104.55,"id":19144241}]}]}
{"op":"mcm","clk":"11780377924","pt":1722864510811,"mc":[{"id":"1.231426403","rc":[{"batb":[[0,1.92,10]],"ltp":1.94,"tv":104.55,"id":19144241}]}]}
{"op":"mcm","clk":"11780377973","pt":1722864511800,"mc":[{"id":"1.231426403","rc":[{"batb":[[0,1.99,10],[1,1.98,45.25],[2,1.97,31]],"ltp":2.02,"tv":13.73,"id":19144236},{"batb":[[0,1.91,6],[1,1.9,49.27],[2,1.81,8.96]],"ltp":1.94,"tv":104.55,"id":19144241}]}]}
{"op":"mcm","clk":"11780378072","pt":1722864514614,"mc":[{"id":"1.231426403","rc":[{"batb":[[0,1.98,45.25],[1,1.97,31],[2,1.96,8.27]],"ltp":2.02,"tv":13.73,"id":19144236},{"batb":[[0,1.92,12],[1,1.91,6],[2,1.9,49.27]],"ltp":1.94,"tv":104.55,"id":19144241}]}]}
{"op":"mcm","clk":"11780378155","pt":1722864516939,"mc":[{"id":"1.231426403","rc":[{"batb":[[0,1.99,10],[1,1.98,45.25],[2,1.97,31]],"ltp":2.02,"tv":13.73,"id":19144236},{"batb":[[0,1.92,10]],"ltp":1.94,"tv":104.55,"id":19144241}]}]}
{"op":"mcm","clk":"11780378195","pt":1722864518034,"mc":[{"id":"1.231426403","rc":[{"batb":[[0,1.91,6],[1,1.9,49.27],[2,1.81,8.96]],"ltp":1.94,"tv":104.55,"id":19144241}]}]}
{"op":"mcm","clk":"11780378287","pt":1722864520627,"mc":[{"id":"1.231426403","rc":[{"batb":[[0,1.98,45.25],[1,1.97,31],[2,1.96,8.27]],"ltp":2.02,"tv":13.73,"id":19144236},{"batb":[[0,1.92,12],[1,1.91,6],[2,1.9,49.27]],"ltp":1.94,"tv":104.55,"id":19144241}]}]}
{"op":"mcm","clk":"11780378377","pt":1722864523224,"mc":[{"id":"1.231426403","rc":[{"batb":[[0,1.99,10],[1,1.98,45.25],[2,1.97,31]],"ltp":2.02,"tv":13.73,"id":19144236},{"batb":[[0,1.92,10]],"ltp":1.94,"tv":104.55,"id":19144241}]}]}
{"op":"mcm","clk":"11780378407","pt":1722864524047,"mc":[{"id":"1.231426403","rc":[{"batb":[[0,1.91,6],[1,1.9,49.27],[2,1.81,8.96]],"ltp":1.94,"tv":104.55,"id":19144241}]}]}
{"op":"mcm","clk":"11780378495","pt":1722864526643,"mc":[{"id":"1.231426403","rc":[{"batb":[[0,1.98,45.25],[1,1.97,31],[2,1.96,8.27]],"ltp":2.02,"tv":13.73,"id":19144236}]}]}
{"op":"mcm","clk":"11780378502","pt":1722864526855,"mc":[{"id":"1.231426403","rc":[{"batb":[[0,1.92,12],[1,1.91,6],[2,1.9,49.27]],"ltp":1.94,"tv":104.55,"id":19144241}]}]}
{"op":"mcm","clk":"11780378609","pt":1722864529135,"mc":[{"id":"1.231426403","rc":[{"batb":[[0,1.99,10],[1,1.98,45.25],[2,1.97,31]],"ltp":2.02,"tv":13.73,"id":19144236},{"batb":[[0,1.92,10]],"ltp":1.94,"tv":104.55,"id":19144241}]}]}
{"op":"mcm","clk":"11780378648","pt":1722864530120,"mc":[{"id":"1.231426403","rc":[{"batb":[[0,1.91,6],[1,1.9,49.27],[2,1.81,8.96]],"ltp":1.94,"tv":104.55,"id":19144241}]}]}
{"op":"mcm","clk":"11780378741","pt":1722864532721,"mc":[{"id":"1.231426403","rc":[{"batb":[[0,1.98,45.25],[1,1.97,31],[2,1.96,8.27]],"ltp":2.02,"tv":13.73,"id":19144236}]}]}
{"op":"mcm","clk":"11780378753","pt":1722864532982,"mc":[{"id":"1.231426403","rc":[{"batb":[[0,1.92,12],[1,1.91,6],[2,1.9,49.27]],"ltp":1.94,"tv":104.55,"id":19144241}]}]}
{"op":"mcm","clk":"11780378852","pt":1722864535366,"mc":[{"id":"1.231426403","rc":[{"batb":[[0,1.99,10],[1,1.98,45.25],[2,1.97,31]],"ltp":2.02,"tv":13.73,"id":19144236},{"batb":[[0,1.92,10]],"ltp":1.94,"tv":104.55,"id":19144241}]}]}
{"op":"mcm","clk":"11780378892","pt":1722864536355,"mc":[{"id":"1.231426403","rc":[{"batb":[[0,1.91,6],[1,1.9,49.27],[2,1.81,8.96]],"ltp":1.94,"tv":104.55,"id":19144241}]}]}
{"op":"mcm","clk":"11780378976","pt":1722864538670,"mc":[{"id":"1.231426403","rc":[{"batb":[[0,1.98,45.25],[1,1.97,31],[2,1.96,8.27]],"ltp":2.02,"tv":13.73,"id":19144236}]}]}
{"op":"mcm","clk":"11780378983","pt":1722864538878,"mc":[{"id":"1.231426403","rc":[{"batb":[[0,1.92,12],[1,1.91,6],[2,1.9,49.27]],"ltp":1.94,"tv":104.55,"id":19144241}]}]}
{"op":"mcm","clk":"11780379084","pt":1722864541538,"mc":[{"id":"1.231426403","rc":[{"batb":[[0,1.99,10],[1,1.98,45.25],[2,1.97,31]],"ltp":2.02,"tv":13.73,"id":19144236},{"batb":[[0,1.92,10]],"ltp":1.94,"tv":104.55,"id":19144241}]}]}
{"op":"mcm","clk":"11780379111","pt":1722864542376,"mc":[{"id":"1.231426403","rc":[{"batb":[[0,1.91,6],[1,1.9,49.27],[2,1.81,8.96]],"ltp":1.94,"tv":104.55,"id":19144241}]}]}
{"op":"mcm","clk":"11780379212","pt":1722864545236,"mc":[{"id":"1.231426403","rc":[{"batb":[[0,1.98,45.25],[1,1.97,31],[2,1.96,8.27]],"ltp":2.02,"tv":13.73,"id":19144236},{"batb":[[0,1.92,12],[1,1.91,6],[2,1.9,49.27]],"ltp":1.94,"tv":104.55,"id":19144241}]}]}
{"op":"mcm","clk":"11780379310","pt":1722864547778,"mc":[{"id":"1.231426403","rc":[{"batb":[[0,1.99,10],[1,1.98,45.25],[2,1.97,31]],"ltp":2.02,"tv":13.73,"id":19144236},{"batb":[[0,1.92,10]],"ltp":1.94,"tv":104.55,"id":19144241}]}]}
{"op":"mcm","clk":"11780379346","pt":1722864548562,"mc":[{"id":"1.231426403","rc":[{"batb":[[0,1.91,6],[1,1.9,49.27],[2,1.81,8.96]],"ltp":1.94,"tv":104.55,"id":19144241}]}]}
{"op":"mcm","clk":"11780379429","pt":1722864551158,"mc":[{"id":"1.231426403","rc":[{"batb":[[0,1.98,45.25],[1,1.97,31],[2,1.96,8.27]],"ltp":2.02,"tv":13.73,"id":19144236},{"batb":[[0,1.92,12],[1,1.91,6],[2,1.9,49.27]],"ltp":1.94,"tv":104.55,"id":19144241}]}]}
{"op":"mcm","clk":"11780379514","pt":1722864553648,"mc":[{"id":"1.231426403","rc":[{"batb":[[0,1.99,10],[1,1.98,45.25],[2,1.97,31]],"ltp":2.02,"tv":13.73,"id":19144236},{"batb":[[0,1.92,10]],"ltp":1.94,"tv":104.55,"id":19144241}]}]}
{"op":"mcm","clk":"11780379541","pt":1722864554382,"mc":[{"id":"1.231426403","rc":[{"batb":[[0,1.91,6],[1,1.9,49.27],[2,1.81,8.96]],"ltp":1.94,"tv":104.55,"id":19144241}]}]}
{"op":"mcm","clk":"11780379643","pt":1722864557382,"mc":[{"id":"1.231426403","rc":[{"batb":[[0,1.98,45.25],[1,1.97,31],[2,1.96,8.27]],"ltp":2.02,"tv":13.73,"id":19144236},{"batb":[[0,1.92,12],[1,1.91,6],[2,1.9,49.27]],"ltp":1.94,"tv":104.55,"id":19144241}]}]}
{"op":"mcm","clk":"11780379738","pt":1722864559662,"mc":[{"id":"1.231426403","rc":[{"batb":[[0,1.92,10]],"ltp":1.94,"tv":104.55,"id":19144241}]}]}
{"op":"mcm","clk":"11780379780","pt":1722864560761,"mc":[{"id":"1.231426403","rc":[{"batb":[[0,1.99,10],[1,1.98,45.25],[2,1.97,31]],"ltp":2.02,"tv":13.73,"id":19144236},{"batb":[[0,1.91,6],[1,1.9,49.27],[2,1.81,8.96]],"ltp":1.94,"tv":104.55,"id":19144241}]}]}
{"op":"mcm","clk":"11780379870","pt":1722864563447,"mc":[{"id":"1.231426403","rc":[{"batb":[[0,1.98,45.25],[1,1.97,31],[2,1.96,8.27]],"ltp":2.02,"tv":13.73,"id":19144236},{"batb":[[0,1.92,12],[1,1.91,6],[2,1.9,49.27]],"ltp":1.94,"tv":104.55,"id":19144241}]}]}
{"op":"mcm","clk":"11780379967","pt":1722864565777,"mc":[{"id":"1.231426403","rc":[{"batb":[[0,1.92,10]],"ltp":1.94,"tv":104.55,"id":19144241}]}]}
{"op":"mcm","clk":"11780379997","pt":1722864566786,"mc":[{"id":"1.231426403","rc":[{"batb":[[0,1.99,10],[1,1.98,45.25],[2,1.97,31]],"ltp":2.02,"tv":13.73,"id":19144236},{"batb":[[0,1.91,6],[1,1.9,49.27],[2,1.81,8.96]],"ltp":1.94,"tv":104.55,"id":19144241}]}]}
{"op":"mcm","clk":"11780380062","pt":1722864569450,"mc":[{"id":"1.231426403","rc":[{"batb":[[0,1.98,45.25],[1,1.97,31],[2,1.96,8.27]],"ltp":2.02,"tv":13.73,"id":19144236},{"batb":[[0,1.92,12],[1,1.91,6],[2,1.9,49.27]],"ltp":1.94,"tv":104.55,"id":19144241}]}]}
{"op":"mcm","clk":"11780380132","pt":1722864572092,"mc":[{"id":"1.231426403","rc":[{"batb":[[0,1.99,10],[1,1.98,45.25],[2,1.97,31]],"ltp":2.02,"tv":13.73,"id":19144236},{"batb":[[0,1.92,10]],"ltp":1.94,"tv":104.55,"id":19144241}]}]}
{"op":"mcm","clk":"11780380145","pt":1722864572871,"mc":[{"id":"1.231426403","rc":[{"batb":[[0,1.91,6],[1,1.9,49.27],[2,1.81,8.96]],"ltp":1.94,"tv":104.55,"id":19144241}]}]}
{"op":"mcm","clk":"11780380173","pt":1722864574472,"mc":[{"id":"1.231426403","rc":[{"batb":[[0,1.92,2],[1,1.91,6],[2,1.9,49.27]],"ltp":1.94,"tv":104.55,"id":19144241}]}]}
{"op":"mcm","clk":"11780380189","pt":1722864575297,"mc":[{"id":"1.231426403","rc":[{"batb":[[0,1.98,45.25],[1,1.97,31],[2,1.96,8.27]],"ltp":2.02,"tv":13.73,"id":19144236}]}]}
{"op":"mcm","clk":"11780380226","pt":1722864577157,"mc":[{"id":"1.231426403","rc":[{"batb":[[0,1.92,10]],"ltp":1.94,"tv":104.55,"id":19144241}]}]}
{"op":"mcm","clk":"11780380303","pt":1722864580503,"mc":[{"id":"1.231426403","rc":[{"batb":[[0,1.99,10],[1,1.98,45.25],[2,1.97,31]],"ltp":2.02,"tv":13.73,"id":19144236},{"batb":[[0,1.93,2]],"ltp":1.94,"tv":104.55,"id":19144241}]}]}
{"op":"mcm","clk":"11780380350","pt":1722864582785,"mc":[{"id":"1.231426403","rc":[{"batb":[[0,1.91,6],[1,1.9,49.27],[2,1.81,8.96]],"ltp":1.94,"tv":104.55,"id":19144241}]}]}
{"op":"mcm","clk":"11780380368","pt":1722864583779,"mc":[{"id":"1.231426403","rc":[{"batb":[[0,1.98,45.25],[1,1.97,31],[2,1.96,8.27]],"ltp":2.02,"tv":13.73,"id":19144236},{"batb":[[0,1.92,10],[1,1.91,6],[2,1.9,49.27]],"ltp":1.94,"tv":104.55,"id":19144241}]}]}
{"op":"mcm","clk":"11780380401","pt":1722864586379,"mc":[{"id":"1.231426403","rc":[{"batb":[[0,1.99,10],[1,1.98,45.25],[2,1.97,31]],"ltp":2.02,"tv":13.73,"id":19144236},{"batb":[[0,1.92,2]],"ltp":1.94,"tv":104.55,"id":19144241}]}]}
{"op":"mcm","clk":"11780380453","pt":1722864589107,"mc":[{"id":"1.231426403","rc":[{"batb":[[0,1.92,10]],"ltp":1.94,"tv":104.55,"id":19144241}]}]}
{"op":"mcm","clk":"11780380463","pt":1722864589881,"mc":[{"id":"1.231426403","rc":[{"batb":[[0,1.98,45.25],[1,1.97,31],[2,1.96,8.27]],"ltp":2.02,"tv":13.73,"id":19144236}]}]}
{"op":"mcm","clk":"11780380517","pt":1722864592680,"mc":[{"id":"1.231426403","rc":[{"batb":[[0,1.99,10],[1,1.98,45.25],[2,1.97,31]],"ltp":2.02,"tv":13.73,"id":19144236},{"batb":[[0,1.92,2]],"ltp":1.94,"tv":104.55,"id":19144241}]}]}
{"op":"mcm","clk":"11780380561","pt":1722864595207,"mc":[{"id":"1.231426403","rc":[{"batb":[[0,1.92,10]],"ltp":1.94,"tv":104.55,"id":19144241}]}]}
{"op":"mcm","clk":"11780380573","pt":1722864595983,"mc":[{"id":"1.231426403","rc":[{"batb":[[0,1.98,45.25],[1,1.97,31],[2,1.96,8.27]],"ltp":2.02,"tv":13.73,"id":19144236}]}]}
{"op":"mcm","clk":"11780380623","pt":1722864598635,"mc":[{"id":"1.231426403","rc":[{"batb":[[0,1.99,10],[1,1.98,45.25],[2,1.97,31]],"ltp":2.02,"tv":13.73,"id":19144236},{"batb":[[0,1.92,2]],"ltp":1.94,"tv":104.55,"id":19144241}]}]}
{"op":"mcm","clk":"11780380695","pt":1722864601097,"mc":[{"id":"1.231426403","rc":[{"batb":[[0,1.92,10]],"ltp":1.94,"tv":104.55,"id":19144241}]}]}
{"op":"mcm","clk":"11780380724","pt":1722864601933,"mc":[{"id":"1.231426403","rc":[{"batb":[[0,1.98,45.25],[1,1.97,31],[2,1.96,8.27]],"ltp":2.02,"tv":13.73,"id":19144236}]}]}
{"op":"mcm","clk":"11780380810","pt":1722864604527,"mc":[{"id":"1.231426403","rc":[{"batb":[[0,1.99,10],[1,1.98,45.25],[2,1.97,31]],"ltp":2.02,"tv":13.73,"id":19144236},{"batb":[[0,1.92,2]],"ltp":1.94,"tv":104.55,"id":19144241}]}]}
{"op":"mcm","clk":"11780380877","pt":1722864606812,"mc":[{"id":"1.231426403","rc":[{"batb":[[0,1.91,6],[1,1.9,49.27],[2,1.81,8.96]],"ltp":1.94,"tv":104.55,"id":19144241}]}]}
{"op":"mcm","clk":"11780380897","pt":1722864607745,"mc":[{"id":"1.231426403","rc":[{"batb":[[0,1.98,45.25],[1,1.97,31],[2,1.96,8.27]],"ltp":2.02,"tv":13.73,"id":19144236},{"batb":[[0,1.92,10],[1,1.91,6],[2,1.9,49.27]],"ltp":1.94,"tv":104.55,"id":19144241}]}]}
{"op":"mcm","clk":"11780380940","pt":1722864609409,"mc":[{"id":"1.231426403","rc":[{"batb":[[0,1.93,2],[1,1.92,10],[2,1.91,6]],"ltp":1.94,"tv":104.55,"id":19144241}]}]}
{"op":"mcm","clk":"11780380965","pt":1722864610448,"mc":[{"id":"1.231426403","rc":[{"batb":[[0,1.99,10],[1,1.98,45.25],[2,1.97,31]],"ltp":2.02,"tv":13.73,"id":19144236},{"batb":[[1,1.91,6],[2,1.9,49.27]],"ltp":1.94,"tv":104.55,"id":19144241}]}]}
{"op":"mcm","clk":"11780380993","pt":1722864611952,"mc":[{"id":"1.231426403","rc":[{"batb":[[0,1.91,6],[1,1.9,49.27],[2,1.81,8.96]],"ltp":1.94,"tv":104.55,"id":19144241}]}]}
{"op":"mcm","clk":"11780381036","pt":1722864613711,"mc":[{"id":"1.231426403","rc":[{"batb":[[0,1.98,45.25],[1,1.97,31],[2,1.85,2]],"ltp":2.02,"tv":13.73,"id":19144236},{"batb":[[0,1.92,10],[1,1.91,6],[2,1.9,49.27]],"ltp":1.94,"tv":104.55,"id":19144241}]}]}
{"op":"mcm","clk":"11780381049","pt":1722864615053,"mc":[{"id":"1.231426403","rc":[{"batb":[[0,1.93,2],[1,1.92,10],[2,1.91,6]],"ltp":1.94,"tv":104.55,"id":19144241}]}]}
{"op":"mcm","clk":"11780381116","pt":1722864617548,"mc":[{"id":"1.231426403","rc":[{"batb":[[0,1.99,10],[1,1.98,45.25],[2,1.97,31]],"ltp":2.02,"tv":13.73,"id":19144236},{"batb":[[0,1.91,6],[1,1.9,49.27],[2,1.8,10]],"ltp":1.94,"tv":104.55,"id":19144241}]}]}
{"op":"mcm","clk":"11780381188","pt":1722864620817,"mc":[{"id":"1.231426403","rc":[{"batb":[[0,1.98,45.25],[1,1.97,31],[2,1.85,2]],"ltp":2.02,"tv":13.73,"id":19144236},{"batb":[[0,1.92,12],[1,1.91,6],[2,1.9,49.27]],"ltp":1.94,"tv":104.55,"id":19144241}]}]}
{"op":"mcm","clk":"11780381210","pt":1722864621956,"mc":[{"id":"1.231426403","rc":[{"batl":[[0,2,1.13],[1,3.8,1.07]],"ltp":1.94,"tv":104.55,"id":19144241}]}]}
{"op":"mcm","clk":"11780381238","pt":1722864623455,"mc":[{"id":"1.231426403","rc":[{"batb":[[0,1.99,10],[1,1.98,45.25],[2,1.97,31]],"ltp":2.02,"tv":13.73,"id":19144236},{"batb":[[0,1.92,10]],"ltp":1.94,"tv":104.55,"id":19144241}]}]}
{"op":"mcm","clk":"11780381264","pt":1722864624124,"mc":[{"id":"1.231426403","rc":[{"batb":[[0,1.91,6],[1,1.9,49.27],[2,1.8,10]],"ltp":1.94,"tv":104.55,"id":19144241}]}]}
{"op":"mcm","clk":"11780381349","pt":1722864627146,"mc":[{"id":"1.231426403","rc":[{"batb":[[0,1.98,45.25],[1,1.97,31],[2,1.85,2]],"ltp":2.02,"tv":13.73,"id":19144236},{"batb":[[0,1.92,10],[1,1.91,6],[2,1.9,49.27]],"ltp":1.94,"tv":104.55,"id":19144241}]}]}
{"op":"mcm","clk":"11780381427","pt":1722864630765,"mc":[{"id":"1.231426403","rc":[{"batb":[[0,1.99,10],[1,1.98,45.25],[2,1.97,31]],"ltp":2.02,"tv":13.73,"id":19144236},{"batb":[[0,1.91,6],[1,1.9,49.27],[2,1.8,10]],"ltp":1.94,"tv":104.55,"id":19144241}]}]}
{"op":"mcm","clk":"11780381504","pt":1722864634552,"mc":[{"id":"1.231426403","rc":[{"batb":[[0,1.98,45.25],[1,1.97,31],[2,1.85,2]],"ltp":2.02,"tv":13.73,"id":19144236},{"batb":[[0,1.92,10],[1,1.91,6],[2,1.9,49.27]],"ltp":1.94,"tv":104.55,"id":19144241}]}]}
{"op":"mcm","clk":"11780381555","pt":1722864638070,"mc":[{"id":"1.231426403","rc":[{"batb":[[0,1.99,10],[1,1.98,45.25],[2,1.97,31]],"ltp":2.02,"tv":13.73,"id":19144236},{"batb":[[0,1.91,6],[1,1.9,49.27],[2,1.8,10]],"ltp":1.94,"tv":104.55,"id":19144241}]}]}
{"op":"mcm","clk":"11780381633","pt":1722864641580,"mc":[{"id":"1.231426403","rc":[{"batb":[[0,1.98,45.25],[1,1.97,31],[2,1.85,2]],"ltp":2.02,"tv":13.73,"id":19144236},{"batb":[[0,1.92,10],[1,1.91,6],[2,1.9,49.27]],"ltp":1.94,"tv":104.55,"id":19144241}]}]}
{"op":"mcm","clk":"11780381743","pt":1722864645047,"mc":[{"id":"1.231426403","rc":[{"batb":[[0,1.99,10],[1,1.98,45.25],[2,1.97,31]],"ltp":2.02,"tv":13.73,"id":19144236},{"batb":[[0,1.91,6],[1,1.9,49.27],[2,1.8,10]],"ltp":1.94,"tv":104.55,"id":19144241}]}]}
{"op":"mcm","clk":"11780381812","pt":1722864648450,"mc":[{"id":"1.231426403","rc":[{"batb":[[0,1.98,45.25],[1,1.97,31],[2,1.85,2]],"ltp":2.02,"tv":13.73,"id":19144236},{"batb":[[0,1.92,10],[1,1.91,6],[2,1.9,49.27]],"ltp":1.94,"tv":104.55,"id":19144241}]}]}
{"op":"mcm","clk":"11780381865","pt":1722864651755,"mc":[{"id":"1.231426403","rc":[{"batb":[[0,1.91,6],[1,1.9,49.27],[2,1.8,10]],"ltp":1.94,"tv":104.55,"id":19144241}]}]}
{"op":"mcm","clk":"11780381869","pt":1722864651963,"mc":[{"id":"1.231426403","rc":[{"batb":[[0,1.99,10],[1,1.98,45.25],[2,1.97,31]],"ltp":2.02,"tv":13.73,"id":19144236}]}]}
{"op":"mcm","clk":"11780381955","pt":1722864655583,"mc":[{"id":"1.231426403","rc":[{"batb":[[0,1.98,45.25],[1,1.97,31],[2,1.85,2]],"ltp":2.02,"tv":13.73,"id":19144236},{"batb":[[0,1.92,10],[1,1.91,6],[2,1.9,49.27]],"ltp":1.94,"tv":104.55,"id":19144241}]}]}
{"op":"mcm","clk":"11780382046","pt":1722864659151,"mc":[{"id":"1.231426403","rc":[{"batb":[[0,1.99,10],[1,1.98,45.25],[2,1.97,31]],"ltp":2.02,"tv":13.73,"id":19144236},{"batb":[[0,1.91,6],[1,1.9,49.27],[2,1.8,10]],"ltp":1.94,"tv":104.55,"id":19144241}]}]}
{"op":"mcm","clk":"11780382141","pt":1722864662666,"mc":[{"id":"1.231426403","rc":[{"batb":[[0,1.98,45.25],[1,1.97,31],[2,1.85,2]],"ltp":2.02,"tv":13.73,"id":19144236},{"batb":[[0,1.92,10],[1,1.91,6],[2,1.9,49.27]],"ltp":1.94,"tv":104.55,"id":19144241}]}]}
{"op":"mcm","clk":"11780382196","pt":1722864665094,"mc":[{"id":"1.231426403","rc":[{"batb":[[0,1.99,10],[1,1.98,45.25],[2,1.97,31]],"ltp":2.02,"tv":13.73,"id":19144236}]}]}
{"op":"mcm","clk":"11780382230","pt":1722864666190,"mc":[{"id":"1.231426403","rc":[{"batb":[[0,1.91,6],[1,1.9,49.27],[2,1.8,10]],"ltp":1.94,"tv":104.55,"id":19144241}]}]}
{"op":"mcm","clk":"11780382301","pt":1722864668581,"mc":[{"id":"1.231426403","rc":[{"batb":[[0,1.98,45.25],[1,1.97,31],[2,1.85,2]],"ltp":2.02,"tv":13.73,"id":19144236},{"batb":[[0,1.92,10],[1,1.91,6],[2,1.9,49.27]],"ltp":1.94,"tv":104.55,"id":19144241}]}]}
{"op":"mcm","clk":"11780382400","pt":1722864671964,"mc":[{"id":"1.231426403","rc":[{"batb":[[0,1.99,10],[1,1.98,45.25],[2,1.97,31]],"ltp":2.02,"tv":13.73,"id":19144236},{"batb":[[0,1.91,6],[1,1.9,49.27],[2,1.8,10]],"ltp":1.94,"tv":104.55,"id":19144241}]}]}
{"op":"mcm","clk":"11780382454","pt":1722864674075,"mc":[{"id":"1.231426403","rc":[{"batb":[[0,1.92,10],[1,1.91,6],[2,1.9,49.27]],"ltp":1.94,"tv":104.55,"id":19144241}]}]}
{"op":"mcm","clk":"11780382481","pt":1722864675314,"mc":[{"id":"1.231426403","rc":[{"batb":[[0,1.98,45.25],[1,1.97,31],[2,1.85,2]],"ltp":2.02,"tv":13.73,"id":19144236}]}]}
{"op":"mcm","clk":"11780382545","pt":1722864677693,"mc":[{"id":"1.231426403","rc":[{"batb":[[0,1.99,10],[1,1.98,45.25],[2,1.97,31]],"ltp":2.02,"tv":13.73,"id":19144236},{"batb":[[0,1.91,6],[1,1.9,49.27],[2,1.8,10]],"ltp":1.94,"tv":104.55,"id":19144241}]}]}
{"op":"mcm","clk":"11780382648","pt":1722864681209,"mc":[{"id":"1.231426403","rc":[{"batb":[[0,1.98,45.25],[1,1.97,31],[2,1.85,2]],"ltp":2.02,"tv":13.73,"id":19144236},{"batb":[[0,1.92,10],[1,1.91,6],[2,1.9,49.27]],"ltp":1.94,"tv":104.55,"id":19144241}]}]}
{"op":"mcm","clk":"11780382699","pt":1722864683225,"mc":[{"id":"1.231426403","rc":[{"batb":[[0,1.99,10],[1,1.98,45.25],[2,1.97,31]],"ltp":2.02,"tv":13.73,"id":19144236}]}]}
{"op":"mcm","clk":"11780382747","pt":1722864684531,"mc":[{"id":"1.231426403","rc":[{"batb":[[0,1.91,6],[1,1.9,49.27],[2,1.8,10]],"ltp":1.94,"tv":104.55,"id":19144241}]}]}
{"op":"mcm","clk":"11780382805","pt":1722864687108,"mc":[{"id":"1.231426403","rc":[{"batb":[[0,1.98,45.25],[1,1.97,31],[2,1.85,2]],"ltp":2.02,"tv":13.73,"id":19144236},{"batb":[[0,1.92,10],[1,1.91,6],[2,1.9,49.27]],"ltp":1.94,"tv":104.55,"id":19144241}]}]}
{"op":"mcm","clk":"11780382889","pt":1722864690727,"mc":[{"id":"1.231426403","rc":[{"batb":[[0,1.99,10],[1,1.98,45.25],[2,1.97,31]],"ltp":2.02,"tv":13.73,"id":19144236},{"batb":[[0,1.91,6],[1,1.9,49.27],[2,1.8,10]],"ltp":1.94,"tv":104.55,"id":19144241}]}]}
{"op":"mcm","clk":"11780382971","pt":1722864694308,"mc":[{"id":"1.231426403","rc":[{"batb":[[0,1.98,45.25],[1,1.97,31],[2,1.85,2]],"ltp":2.02,"tv":13.73,"id":19144236},{"batb":[[0,1.92,10],[1,1.91,6],[2,1.9,49.27]],"ltp":1.94,"tv":104.55,"id":19144241}]}]}
{"op":"mcm","clk":"11780383034","pt":1722864697731,"mc":[{"id":"1.231426403","rc":[{"batb":[[0,1.91,6],[1,1.9,49.27],[2,1.8,10]],"ltp":1.94,"tv":104.55,"id":19144241}]}]}
{"op":"mcm","clk":"11780383040","pt":1722864697991,"mc":[{"id":"1.231426403","rc":[{"batb":[[0,1.99,10],[1,1.98,45.25],[2,1.97,31]],"ltp":2.02,"tv":13.73,"id":19144236}]}]}
{"op":"mcm","clk":"11780383124","pt":1722864701609,"mc":[{"id":"1.231426403","rc":[{"batb":[[0,1.98,45.25],[1,1.97,31],[2,1.85,2]],"ltp":2.02,"tv":13.73,"id":19144236},{"batb":[[0,1.92,10],[1,1.91,6],[2,1.9,49.27]],"ltp":1.94,"tv":104.55,"id":19144241}]}]}
{"op":"mcm","clk":"11780383200","pt":1722864705123,"mc":[{"id":"1.231426403","rc":[{"batb":[[0,1.99,10],[1,1.98,45.25],[2,1.97,31]],"ltp":2.02,"tv":13.73,"id":19144236},{"batb":[[0,1.91,6],[1,1.9,49.27],[2,1.8,10]],"ltp":1.94,"tv":104.55,"id":19144241}]}]}
{"op":"mcm","clk":"11780383272","pt":1722864707727,"mc":[{"id":"1.231426403","rc":[{"batb":[[0,1.92,10],[1,1.91,6],[2,1.9,49.27]],"ltp":1.94,"tv":104.55,"id":19144241}]}]}
{"op":"mcm","clk":"11780383281","pt":1722864708347,"mc":[{"id":"1.231426403","rc":[{"batb":[[0,1.98,45.25],[1,1.97,31],[2,1.85,2]],"ltp":2.02,"tv":13.73,"id":19144236}]}]}
{"op":"mcm","clk":"11780383353","pt":1722864711320,"mc":[{"id":"1.231426403","rc":[{"batb":[[0,1.99,10],[1,1.98,45.25],[2,1.97,31]],"ltp":2.02,"tv":13.73,"id":19144236},{"batb":[[0,1.91,6],[1,1.9,49.27],[2,1.8,10]],"ltp":1.94,"tv":104.55,"id":19144241}]}]}
{"op":"mcm","clk":"11780383452","pt":1722864714636,"mc":[{"id":"1.231426403","rc":[{"batb":[[0,1.98,45.25],[1,1.97,31],[2,1.85,2]],"ltp":2.02,"tv":13.73,"id":19144236},{"batb":[[0,1.92,10],[1,1.91,6],[2,1.9,49.27]],"ltp":1.94,"tv":104.55,"id":19144241}]}]}
{"op":"mcm","clk":"11780383592","pt":1722864718252,"mc":[{"id":"1.231426403","rc":[{"batb":[[0,1.99,10],[1,1.98,45.25],[2,1.97,31]],"ltp":2.02,"tv":13.73,"id":19144236},{"batb":[[0,1.91,6],[1,1.9,49.27],[2,1.8,10]],"ltp":1.94,"tv":104.55,"id":19144241}]}]}
{"op":"mcm","clk":"11780383701","pt":1722864721762,"mc":[{"id":"1.231426403","rc":[{"batb":[[0,1.98,45.25],[1,1.97,31],[2,1.85,2]],"ltp":2.02,"tv":13.73,"id":19144236},{"batb":[[0,1.92,10],[1,1.91,6],[2,1.9,49.27]],"ltp":1.94,"tv":104.55,"id":19144241}]}]}
{"op":"mcm","clk":"11780383796","pt":1722864725351,"mc":[{"id":"1.231426403","rc":[{"batb":[[0,1.99,10],[1,1.98,45.25],[2,1.97,31]],"ltp":2.02,"tv":13.73,"id":19144236},{"batb":[[0,1.91,6],[1,1.9,49.27],[2,1.8,10]],"ltp":1.94,"tv":104.55,"id":19144241}]}]}
{"op":"mcm","clk":"11780383884","pt":1722864728737,"mc":[{"id":"1.231426403","rc":[{"batb":[[0,1.98,45.25],[1,1.97,31],[2,1.85,2]],"ltp":2.02,"tv":13.73,"id":19144236}]}]}
{"op":"mcm","clk":"11780383887","pt":1722864728841,"mc":[{"id":"1.231426403","rc":[{"batb":[[0,1.92,10],[1,1.91,6],[2,1.9,49.27]],"ltp":1.94,"tv":104.55,"id":19144241}]}]}
{"op":"mcm","clk":"11780383983","pt":1722864732376,"mc":[{"id":"1.231426403","rc":[{"batb":[[0,1.99,10],[1,1.98,45.25],[2,1.97,31]],"ltp":2.02,"tv":13.73,"id":19144236},{"batb":[[0,1.91,6],[1,1.9,49.27],[2,1.8,10]],"ltp":1.94,"tv":104.55,"id":19144241}]}]}
{"op":"mcm","clk":"11780384079","pt":1722864735667,"mc":[{"id":"1.231426403","rc":[{"batb":[[0,1.98,45.25],[1,1.97,31],[2,1.85,2]],"ltp":2.02,"tv":13.73,"id":19144236}]}]}
{"op":"mcm","clk":"11780384084","pt":1722864735876,"mc":[{"id":"1.231426403","rc":[{"batb":[[0,1.92,10],[1,1.91,6],[2,1.9,49.27]],"ltp":1.94,"tv":104.55,"id":19144241}]}]}
{"op":"mcm","clk":"11780384180","pt":1722864739480,"mc":[{"id":"1.231426403","rc":[{"batb":[[0,1.99,10],[1,1.98,45.25],[2,1.97,31]],"ltp":2.02,"tv":13.73,"id":19144236},{"batb":[[0,1.91,6],[1,1.9,49.27],[2,1.8,10]],"ltp":1.94,"tv":104.55,"id":19144241}]}]}
{"op":"mcm","clk":"11780384294","pt":1722864743063,"mc":[{"id":"1.231426403","rc":[{"batb":[[0,1.98,45.25],[1,1.97,31],[2,1.85,2]],"ltp":2.02,"tv":13.73,"id":19144236},{"batb":[[0,1.92,10],[1,1.91,6],[2,1.9,49.27]],"ltp":1.94,"tv":104.55,"id":19144241}]}]}
{"op":"mcm","clk":"11780384382","pt":1722864746376,"mc":[{"id":"1.231426403","rc":[{"batb":[[0,1.99,10],[1,1.98,45.25],[2,1.97,31]],"ltp":2.02,"tv":13.73,"id":19144236},{"batb":[[0,1.91,6],[1,1.9,49.27],[2,1.8,10]],"ltp":1.94,"tv":104.55,"id":19144241}]}]}
{"op":"mcm","clk":"11780384498","pt":1722864749672,"mc":[{"id":"1.231426403","rc":[{"batb":[[0,1.98,45.25],[1,1.97,31],[2,1.85,2]],"ltp":2.02,"tv":13.73,"id":19144236}]}]}
{"op":"mcm","clk":"11780384503","pt":1722864749878,"mc":[{"id":"1.231426403","rc":[{"batb":[[0,1.92,10],[1,1.91,6],[2,1.9,49.27]],"ltp":1.94,"tv":104.55,"id":19144241}]}]}
{"op":"mcm","clk":"11780384580","pt":1722864753296,"mc":[{"id":"1.231426403","rc":[{"batb":[[0,1.99,10],[1,1.98,45.25],[2,1.97,31]],"ltp":2.02,"tv":13.73,"id":19144236},{"batb":[[0,1.91,6],[1,1.9,49.27],[2,1.8,10]],"ltp":1.94,"tv":104.55,"id":19144241}]}]}
{"op":"mcm","clk":"11780384635","pt":1722864755459,"mc":[{"id":"1.231426403","rc":[{"batb":[[0,1.92,10],[1,1.91,6],[2,1.9,49.27]],"ltp":1.94,"tv":104.55,"id":19144241}]}]}
{"op":"mcm","clk":"11780384667","pt":1722864756496,"mc":[{"id":"1.231426403","rc":[{"batb":[[0,1.98,45.25],[1,1.97,31],[2,1.85,2]],"ltp":2.02,"tv":13.73,"id":19144236}]}]}
{"op":"mcm","clk":"11780384754","pt":1722864758976,"mc":[{"id":"1.231426403","rc":[{"batb":[[0,1.99,10],[1,1.98,45.25],[2,1.97,31]],"ltp":2.02,"tv":13.73,"id":19144236},{"batb":[[0,1.91,6],[1,1.9,49.27],[2,1.8,10]],"ltp":1.94,"tv":104.55,"id":19144241}]}]}
{"op":"mcm","clk":"11780384852","pt":1722864762691,"mc":[{"id":"1.231426403","rc":[{"batb":[[0,1.98,45.25],[1,1.97,31],[2,1.85,2]],"ltp":2.02,"tv":13.73,"id":19144236},{"batb":[[0,1.92,10],[1,1.91,6],[2,1.9,49.27]],"ltp":1.94,"tv":104.55,"id":19144241}]}]}
{"op":"mcm","clk":"11780384936","pt":1722864766093,"mc":[{"id":"1.231426403","rc":[{"batb":[[0,1.99,10],[1,1.98,45.25],[2,1.97,31]],"ltp":2.02,"tv":13.73,"id":19144236},{"batb":[[0,1.91,6],[1,1.9,49.27],[2,1.8,10]],"ltp":1.94,"tv":104.55,"id":19144241}]}]}
{"op":"mcm","clk":"11780385021","pt":1722864769809,"mc":[{"id":"1.231426403","rc":[{"batb":[[0,1.98,45.25],[1,1.97,31],[2,1.85,2]],"ltp":2.02,"tv":13.73,"id":19144236},{"batb":[[0,1.92,10],[1,1.91,6],[2,1.9,49.27]],"ltp":1.94,"tv":104.55,"id":19144241}]}]}
{"op":"mcm","clk":"11780385075","pt":1722864772308,"mc":[{"id":"1.231426403","rc":[{"batb":[[0,1.99,10],[1,1.98,45.25],[2,1.97,31]],"ltp":2.02,"tv":13.73,"id":19144236}]}]}
{"op":"mcm","clk":"11780385096","pt":1722864773190,"mc":[{"id":"1.231426403","rc":[{"batb":[[0,1.91,6],[1,1.9,49.27],[2,1.8,10]],"ltp":1.94,"tv":104.55,"id":19144241}]}]}
{"op":"mcm","clk":"11780385144","pt":1722864775728,"mc":[{"id":"1.231426403","rc":[{"batb":[[0,1.98,45.25],[1,1.97,31],[2,1.85,2]],"ltp":2.02,"tv":13.73,"id":19144236}]}]}
{"op":"mcm","clk":"11780385149","pt":1722864775883,"mc":[{"id":"1.231426403","rc":[{"batb":[[0,1.92,10],[1,1.91,6],[2,1.9,49.27]],"ltp":1.94,"tv":104.55,"id":19144241}]}]}
{"op":"mcm","clk":"11780385228","pt":1722864779398,"mc":[{"id":"1.231426403","rc":[{"batb":[[0,1.99,10],[1,1.98,45.25],[2,1.97,31]],"ltp":2.02,"tv":13.73,"id":19144236},{"batb":[[0,1.91,6],[1,1.9,49.27],[2,1.8,10]],"ltp":1.94,"tv":104.55,"id":19144241}]}]}
{"op":"mcm","clk":"11780385320","pt":1722864782794,"mc":[{"id":"1.231426403","rc":[{"batb":[[0,1.98,45.25],[1,1.97,31],[2,1.85,2]],"ltp":2.02,"tv":13.73,"id":19144236}]}]}
{"op":"mcm","clk":"11780385329","pt":1722864783001,"mc":[{"id":"1.231426403","rc":[{"batb":[[0,1.92,10],[1,1.91,6],[2,1.9,49.27]],"ltp":1.94,"tv":104.55,"id":19144241}]}]}
{"op":"mcm","clk":"11780385413","pt":1722864786539,"mc":[{"id":"1.231426403","rc":[{"batb":[[0,1.99,10],[1,1.98,45.25],[2,1.97,31]],"ltp":2.02,"tv":13.73,"id":19144236},{"batb":[[0,1.91,6],[1,1.9,49.27],[2,1.8,10]],"ltp":1.94,"tv":104.55,"id":19144241}]}]}
{"op":"mcm","clk":"11780385502","pt":1722864789812,"mc":[{"id":"1.231426403","rc":[{"batb":[[0,1.98,45.25],[1,1.97,31],[2,1.85,2]],"ltp":2.02,"tv":13.73,"id":19144236}]}]}
{"op":"mcm","clk":"11780385507","pt":1722864790021,"mc":[{"id":"1.231426403","rc":[{"batb":[[0,1.92,10],[1,1.91,6],[2,1.9,49.27]],"ltp":1.94,"tv":104.55,"id":19144241}]}]}
{"op":"mcm","clk":"11780385598","pt":1722864793657,"mc":[{"id":"1.231426403","rc":[{"batb":[[0,1.99,10],[1,1.98,45.25],[2,1.97,31]],"ltp":2.02,"tv":13.73,"id":19144236},{"batb":[[0,1.91,6],[1,1.9,49.27],[2,1.8,10]],"ltp":1.94,"tv":104.55,"id":19144241}]}]}
{"op":"mcm","clk":"11780385733","pt":1722864797042,"mc":[{"id":"1.231426403","rc":[{"batb":[[0,1.98,45.25],[1,1.97,31],[2,1.85,2]],"ltp":2.02,"tv":13.73,"id":19144236},{"batb":[[0,1.92,10],[1,1.91,6],[2,1.9,49.27]],"ltp":1.94,"tv":104.55,"id":19144241}]}]}
{"op":"mcm","clk":"11780385850","pt":1722864800356,"mc":[{"id":"1.231426403","rc":[{"batb":[[0,1.99,10],[1,1.98,45.25],[2,1.97,31]],"ltp":2.02,"tv":13.73,"id":19144236},{"batb":[[0,1.91,6],[1,1.9,49.27],[2,1.8,10]],"ltp":1.94,"tv":104.55,"id":19144241}]}]}
{"op":"mcm","clk":"11780385976","pt":1722864803730,"mc":[{"id":"1.231426403","rc":[{"batb":[[0,1.98,45.25],[1,1.97,31],[2,1.85,2]],"ltp":2.02,"tv":13.73,"id":19144236},{"batb":[[0,1.92,10],[1,1.91,6],[2,1.9,49.27]],"ltp":1.94,"tv":104.55,"id":19144241}]}]}
{"op":"mcm","clk":"11780386074","pt":1722864807356,"mc":[{"id":"1.231426403","rc":[{"batb":[[0,1.99,10],[1,1.98,45.25],[2,1.97,31]],"ltp":2.02,"tv":13.73,"id":19144236},{"batb":[[0,1.91,6],[1,1.9,49.27],[2,1.8,10]],"ltp":1.94,"tv":104.55,"id":19144241}]}]}
{"op":"mcm","clk":"11780386156","pt":1722864810626,"mc":[{"id":"1.231426403","rc":[{"batb":[[0,1.98,45.25],[1,1.97,31],[2,1.85,2]],"ltp":2.02,"tv":13.73,"id":19144236},{"batb":[[0,1.92,10],[1,1.91,6],[2,1.9,49.27]],"ltp":1.94,"tv":104.55,"id":19144241}]}]}
{"op":"mcm","clk":"11780386281","pt":1722864814255,"mc":[{"id":"1.231426403","rc":[{"batb":[[0,1.99,10],[1,1.98,45.25],[2,1.97,31]],"ltp":2.02,"tv":13.73,"id":19144236},{"batb":[[0,1.91,6],[1,1.9,49.27],[2,1.8,10]],"ltp":1.94,"tv":104.55,"id":19144241}]}]}
{"op":"mcm","clk":"11780386391","pt":1722864817780,"mc":[{"id":"1.231426403","rc":[{"batb":[[0,1.98,45.25],[1,1.97,31],[2,1.85,2]],"ltp":2.02,"tv":13.73,"id":19144236},{"batb":[[0,1.92,10],[1,1.91,6],[2,1.9,49.27]],"ltp":1.94,"tv":104.55,"id":19144241}]}]}
{"op":"mcm","clk":"11780386505","pt":1722864821043,"mc":[{"id":"1.231426403","rc":[{"batb":[[0,1.99,10],[1,1.98,45.25],[2,1.97,31]],"ltp":2.02,"tv":13.73,"id":19144236},{"batb":[[0,1.91,6],[1,1.9,49.27],[2,1.8,10]],"ltp":1.94,"tv":104.55,"id":19144241}]}]}
{"op":"mcm","clk":"11780386553","pt":1722864822650,"mc":[{"id":"1.231426403","rc":[{"batb":[[2,1.81,8.96]],"ltp":1.94,"tv":104.55,"id":19144241}]}]}
{"op":"mcm","clk":"11780386626","pt":1722864824773,"mc":[{"id":"1.231426403","rc":[{"batb":[[0,1.98,45.25],[1,1.97,31],[2,1.96,8.27]],"ltp":2.02,"tv":13.73,"id":19144236},{"batb":[[0,1.92,10],[1,1.91,6],[2,1.9,49.27]],"ltp":1.94,"tv":104.55,"id":19144241}]}]}
{"op":"mcm","clk":"11780386719","pt":1722864828194,"mc":[{"id":"1.231426403","rc":[{"batb":[[0,1.99,10],[1,1.98,45.25],[2,1.97,31]],"ltp":2.02,"tv":13.73,"id":19144236},{"batb":[[0,1.91,6],[1,1.9,49.27],[2,1.81,8.96]],"ltp":1.94,"tv":104.55,"id":19144241}]}]}
{"op":"mcm","clk":"11780386858","pt":1722864831675,"mc":[{"id":"1.231426403","rc":[{"batb":[[0,1.98,45.25],[1,1.97,31],[2,1.96,8.27]],"ltp":2.02,"tv":13.73,"id":19144236},{"batb":[[0,1.92,10],[1,1.91,6],[2,1.9,49.27]],"ltp":1.94,"tv":104.55,"id":19144241}]}]}
{"op":"mcm","clk":"11780386960","pt":1722864835161,"mc":[{"id":"1.231426403","rc":[{"batb":[[0,1.99,10],[1,1.98,45.25],[2,1.97,31]],"ltp":2.02,"tv":13.73,"id":19144236},{"batb":[[0,1.91,6],[1,1.9,49.27],[2,1.81,8.96]],"ltp":1.94,"tv":104.55,"id":19144241}]}]}
{"op":"mcm","clk":"11780387064","pt":1722864838593,"mc":[{"id":"1.231426403","rc":[{"batb":[[0,1.98,45.25],[1,1.97,31],[2,1.96,8.27]],"ltp":2.02,"tv":13.73,"id":19144236},{"batb":[[0,1.92,10],[1,1.91,6],[2,1.9,49.27]],"ltp":1.94,"tv":104.55,"id":19144241}]}]}
{"op":"mcm","clk":"11780387189","pt":1722864842178,"mc":[{"id":"1.231426403","rc":[{"batb":[[0,1.99,10],[1,1.98,45.25],[2,1.97,31]],"ltp":2.02,"tv":13.73,"id":19144236},{"batb":[[0,1.91,6],[1,1.9,49.27],[2,1.81,8.96]],"ltp":1.94,"tv":104.55,"id":19144241}]}]}
{"op":"mcm","clk":"11780387309","pt":1722864845711,"mc":[{"id":"1.231426403","rc":[{"batb":[[0,1.98,45.25],[1,1.97,31],[2,1.96,8.27]],"ltp":2.02,"tv":13.73,"id":19144236},{"batb":[[0,1.92,10],[1,1.91,6],[2,1.9,49.27]],"ltp":1.94,"tv":104.55,"id":19144241}]}]}
{"op":"mcm","clk":"11780387406","pt":1722864849325,"mc":[{"id":"1.231426403","rc":[{"batb":[[0,1.99,10],[1,1.98,45.25],[2,1.97,31]],"ltp":2.02,"tv":13.73,"id":19144236},{"batb":[[0,1.91,6],[1,1.9,49.27],[2,1.81,8.96]],"ltp":1.94,"tv":104.55,"id":19144241}]}]}
{"op":"mcm","clk":"11780387623","pt":1722864853113,"mc":[{"id":"1.231426403","rc":[{"batb":[[0,1.98,45.25],[1,1.97,31],[2,1.96,8.27]],"ltp":2.02,"tv":13.73,"id":19144236},{"batb":[[0,1.92,10],[1,1.91,6],[2,1.9,49.27]],"ltp":1.94,"tv":104.55,"id":19144241}]}]}
{"op":"mcm","clk":"11780387775","pt":1722864856611,"mc":[{"id":"1.231426403","rc":[{"batb":[[0,1.99,10],[1,1.98,45.25],[2,1.97,31]],"ltp":2.02,"tv":13.73,"id":19144236},{"batb":[[0,1.91,6],[1,1.9,49.27],[2,1.81,8.96]],"ltp":1.94,"tv":104.55,"id":19144241}]}]}
{"op":"mcm","clk":"11780387924","pt":1722864860133,"mc":[{"id":"1.231426403","rc":[{"batb":[[0,1.98,45.25],[1,1.97,31],[2,1.96,8.27]],"ltp":2.02,"tv":13.73,"id":19144236},{"batb":[[0,1.92,10],[1,1.91,6],[2,1.9,49.27]],"ltp":1.94,"tv":104.55,"id":19144241}]}]}
{"op":"mcm","clk":"11780388060","pt":1722864863511,"mc":[{"id":"1.231426403","rc":[{"batb":[[0,1.99,10],[1,1.98,45.25],[2,1.97,31]],"ltp":2.02,"tv":13.73,"id":19144236},{"batb":[[0,1.91,6],[1,1.9,49.27],[2,1.81,8.96]],"ltp":1.94,"tv":104.55,"id":19144241}]}]}
{"op":"mcm","clk":"11780388188","pt":1722864866817,"mc":[{"id":"1.231426403","rc":[{"batb":[[0,1.98,45.25],[1,1.97,31],[2,1.96,8.27]],"ltp":2.02,"tv":13.73,"id":19144236}]}]}
{"op":"mcm","clk":"11780388200","pt":1722864867035,"mc":[{"id":"1.231426403","rc":[{"batb":[[0,1.92,10],[1,1.91,6],[2,1.9,49.27]],"ltp":1.94,"tv":104.55,"id":19144241}]}]}
{"op":"mcm","clk":"11780388346","pt":1722864870748,"mc":[{"id":"1.231426403","rc":[{"batb":[[0,1.99,10],[1,1.98,45.25],[2,1.97,31]],"ltp":2.02,"tv":13.73,"id":19144236},{"batb":[[0,1.91,6],[1,1.9,49.27],[2,1.81,8.96]],"ltp":1.94,"tv":104.55,"id":19144241}]}]}
{"op":"mcm","clk":"11780388488","pt":1722864874252,"mc":[{"id":"1.231426403","rc":[{"batb":[[0,1.98,45.25],[1,1.97,31],[2,1.96,8.27]],"ltp":2.02,"tv":13.73,"id":19144236},{"batb":[[0,1.92,10],[1,1.91,6],[2,1.9,49.27]],"ltp":1.94,"tv":104.55,"id":19144241}]}]}
{"op":"mcm","clk":"11780388616","pt":1722864877633,"mc":[{"id":"1.231426403","rc":[{"batb":[[0,1.99,10],[1,1.98,45.25],[2,1.97,31]],"ltp":2.02,"tv":13.73,"id":19144236},{"batb":[[0,1.91,6],[1,1.9,49.27],[2,1.81,8.96]],"ltp":1.94,"tv":104.55,"id":19144241}]}]}
{"op":"mcm","clk":"11780388721","pt":1722864880346,"mc":[{"id":"1.231426403","rc":[{"batb":[[0,1.92,10],[1,1.91,6],[2,1.9,49.27]],"ltp":1.94,"tv":104.55,"id":19144241}]}]}
{"op":"mcm","clk":"11780388740","pt":1722864880960,"mc":[{"id":"1.231426403","rc":[{"batb":[[0,1.98,45.25],[1,1.97,31],[2,1.96,8.27]],"ltp":2.02,"tv":13.73,"id":19144236}]}]}
{"op":"mcm","clk":"11780388850","pt":1722864883645,"mc":[{"id":"1.231426403","rc":[{"batb":[[2,1.85,2]],"ltp":2.02,"tv":13.73,"id":19144236},{"batb":[[0,1.91,6],[1,1.9,49.27],[2,1.8,10]],"ltp":1.94,"tv":104.55,"id":19144241}]}]}
{"op":"mcm","clk":"11780388858","pt":1722864883851,"mc":[{"id":"1.231426403","rc":[{"batb":[[0,1.99,10],[1,1.98,45.25],[2,1.97,31]],"ltp":2.02,"tv":13.73,"id":19144236}]}]}
{"op":"mcm","clk":"11780389018","pt":1722864887533,"mc":[{"id":"1.231426403","rc":[{"batb":[[0,1.98,45.25],[1,1.97,31],[2,1.85,2]],"ltp":2.02,"tv":13.73,"id":19144236},{"batb":[[0,1.92,10],[1,1.91,6],[2,1.9,49.27]],"ltp":1.94,"tv":104.55,"id":19144241}]}]}
{"op":"mcm","clk":"11780389099","pt":1722864889753,"mc":[{"id":"1.231426403","rc":[{"batb":[[0,1.99,10],[1,1.98,45.25],[2,1.97,31]],"ltp":2.02,"tv":13.73,"id":19144236}]}]}
{"op":"mcm","clk":"11780389143","pt":1722864890831,"mc":[{"id":"1.231426403","rc":[{"batb":[[0,1.91,6],[1,1.9,49.27],[2,1.8,10]],"ltp":1.94,"tv":104.55,"id":19144241}]}]}
{"op":"mcm","clk":"11780389245","pt":1722864893332,"mc":[{"id":"1.231426403","rc":[{"batb":[[0,1.98,45.25],[1,1.97,31],[2,1.85,2]],"ltp":2.02,"tv":13.73,"id":19144236},{"batb":[[0,1.92,10],[1,1.91,6],[2,1.9,49.27]],"ltp":1.94,"tv":104.55,"id":19144241}]}]}
{"op":"mcm","clk":"11780389391","pt":1722864896745,"mc":[{"id":"1.231426403","rc":[{"batb":[[0,1.91,6],[1,1.9,49.27],[2,1.8,10]],"ltp":1.94,"tv":104.55,"id":19144241}]}]}
{"op":"mcm","clk":"11780389397","pt":1722864896949,"mc":[{"id":"1.231426403","rc":[{"batb":[[0,1.99,10],[1,1.98,45.25],[2,1.97,31]],"ltp":2.02,"tv":13.73,"id":19144236}]}]}
{"op":"mcm","clk":"11780389532","pt":1722864900651,"mc":[{"id":"1.231426403","rc":[{"batb":[[0,1.98,45.25],[1,1.97,31],[2,1.85,2]],"ltp":2.02,"tv":13.73,"id":19144236},{"batb":[[0,1.92,10],[1,1.91,6],[2,1.9,49.27]],"ltp":1.94,"tv":104.55,"id":19144241}]}]}
{"op":"mcm","clk":"11780389667","pt":1722864904084,"mc":[{"id":"1.231426403","rc":[{"batb":[[0,1.99,10],[1,1.98,45.25],[2,1.97,31]],"ltp":2.02,"tv":13.73,"id":19144236},{"batb":[[0,1.91,6],[1,1.9,49.27],[2,1.8,10]],"ltp":1.94,"tv":104.55,"id":19144241}]}]}
{"op":"mcm","clk":"11780389799","pt":1722864907583,"mc":[{"id":"1.231426403","rc":[{"batb":[[0,1.98,45.25],[1,1.97,31],[2,1.85,2]],"ltp":2.02,"tv":13.73,"id":19144236},{"batb":[[0,1.92,10],[1,1.91,6],[2,1.9,49.27]],"ltp":1.94,"tv":104.55,"id":19144241}]}]}
{"op":"mcm","clk":"11780389941","pt":1722864911173,"mc":[{"id":"1.231426403","rc":[{"batb":[[0,1.99,10],[1,1.98,45.25],[2,1.97,31]],"ltp":2.02,"tv":13.73,"id":19144236},{"batb":[[0,1.91,6],[1,1.9,49.27],[2,1.8,10]],"ltp":1.94,"tv":104.55,"id":19144241}]}]}
{"op":"mcm","clk":"11780390038","pt":1722864914479,"mc":[{"id":"1.231426403","rc":[{"batb":[[0,1.98,45.25],[1,1.97,31],[2,1.85,2]],"ltp":2.02,"tv":13.73,"id":19144236},{"batb":[[0,1.92,10],[1,1.91,6],[2,1.9,49.27]],"ltp":1.94,"tv":104.55,"id":19144241}]}]}
{"op":"mcm","clk":"11780390159","pt":1722864917691,"mc":[{"id":"1.231426403","rc":[{"batb":[[0,1.99,10],[1,1.98,45.25],[2,1.97,31]],"ltp":2.02,"tv":13.73,"id":19144236},{"batb":[[0,1.91,6],[1,1.9,49.27],[2,1.8,10]],"ltp":1.94,"tv":104.55,"id":19144241}]}]}
{"op":"mcm","clk":"11780390292","pt":1722864921273,"mc":[{"id":"1.231426403","rc":[{"batb":[[0,1.98,45.25],[1,1.97,31],[2,1.85,2]],"ltp":2.02,"tv":13.73,"id":19144236},{"batb":[[0,1.92,10],[1,1.91,6],[2,1.9,49.27]],"ltp":1.94,"tv":104.55,"id":19144241}]}]}
{"op":"mcm","clk":"11780390391","pt":1722864923699,"mc":[{"id":"1.231426403","rc":[{"batb":[[0,1.99,10],[1,1.98,45.25],[2,1.97,31]],"ltp":2.02,"tv":13.73,"id":19144236}]}]}
{"op":"mcm","clk":"11780390443","pt":1722864924788,"mc":[{"id":"1.231426403","rc":[{"batb":[[0,1.91,6],[1,1.9,49.27],[2,1.8,10]],"ltp":1.94,"tv":104.55,"id":19144241}]}]}
{"op":"mcm","clk":"11780390552","pt":1722864927172,"mc":[{"id":"1.231426403","rc":[{"batb":[[0,1.98,45.25],[1,1.97,31],[2,1.85,2]],"ltp":2.02,"tv":13.73,"id":19144236},{"batb":[[0,1.92,10],[1,1.91,6],[2,1.9,49.27]],"ltp":1.94,"tv":104.55,"id":19144241}]}]}
{"op":"mcm","clk":"11780390665","pt":1722864930578,"mc":[{"id":"1.231426403","rc":[{"batb":[[0,1.99,10],[1,1.98,45.25],[2,1.97,31]],"ltp":2.02,"tv":13.73,"id":19144236},{"batb":[[0,1.91,6],[1,1.9,49.27],[2,1.8,10]],"ltp":1.94,"tv":104.55,"id":19144241}]}]}
{"op":"mcm","clk":"11780390778","pt":1722864933991,"mc":[{"id":"1.231426403","rc":[{"batb":[[0,1.98,45.25],[1,1.97,31],[2,1.85,2]],"ltp":2.02,"tv":13.73,"id":19144236},{"batb":[[0,1.92,10],[1,1.91,6],[2,1.9,49.27]],"ltp":1.94,"tv":104.55,"id":19144241}]}]}
{"op":"mcm","clk":"11780390882","pt":1722864937515,"mc":[{"id":"1.231426403","rc":[{"batb":[[0,1.99,10],[1,1.98,45.25],[2,1.97,31]],"ltp":2.02,"tv":13.73,"id":19144236},{"batb":[[0,1.91,6],[1,1.9,49.27],[2,1.8,10]],"ltp":1.94,"tv":104.55,"id":19144241}]}]}
{"op":"mcm","clk":"11780391005","pt":1722864940716,"mc":[{"id":"1.231426403","rc":[{"batb":[[0,1.98,45.25],[1,1.97,31],[2,1.85,2]],"ltp":2.02,"tv":13.73,"id":19144236}]}]}
{"op":"mcm","clk":"11780391020","pt":1722864940881,"mc":[{"id":"1.231426403","rc":[{"batb":[[0,1.92,10],[1,1.91,6],[2,1.9,49.27]],"ltp":1.94,"tv":104.55,"id":19144241}]}]}
{"op":"mcm","clk":"11780391142","pt":1722864944385,"mc":[{"id":"1.231426403","rc":[{"batb":[[0,1.99,10],[1,1.98,45.25],[2,1.97,31]],"ltp":2.02,"tv":13.73,"id":19144236},{"batb":[[0,1.91,6],[1,1.9,49.27],[2,1.8,10]],"ltp":1.94,"tv":104.55,"id":19144241}]}]}
{"op":"mcm","clk":"11780391210","pt":1722864946699,"mc":[{"id":"1.231426403","rc":[{"batb":[[0,1.92,10],[1,1.91,6],[2,1.9,49.27]],"ltp":1.94,"tv":104.55,"id":19144241}]}]}
{"op":"mcm","clk":"11780391250","pt":1722864947783,"mc":[{"id":"1.231426403","rc":[{"batb":[[0,1.98,45.25],[1,1.97,31],[2,1.85,2]],"ltp":2.02,"tv":13.73,"id":19144236}]}]}
{"op":"mcm","clk":"11780391336","pt":1722864950408,"mc":[{"id":"1.231426403","rc":[{"batb":[[0,1.99,10],[1,1.98,45.25],[2,1.97,31]],"ltp":2.02,"tv":13.73,"id":19144236},{"batb":[[0,1.91,6],[1,1.9,49.27],[2,1.8,10]],"ltp":1.94,"tv":104.55,"id":19144241}]}]}
{"op":"mcm","clk":"11780391400","pt":1722864952476,"mc":[{"id":"1.231426403","rc":[{"batb":[[0,1.92,10],[1,1.91,6],[2,1.9,49.27]],"ltp":1.94,"tv":104.55,"id":19144241}]}]}
{"op":"mcm","clk":"11780391437","pt":1722864953774,"mc":[{"id":"1.231426403","rc":[{"batb":[[0,1.98,45.25],[1,1.97,31],[2,1.85,2]],"ltp":2.02,"tv":13.73,"id":19144236}]}]}
{"op":"mcm","clk":"11780391520","pt":1722864956146,"mc":[{"id":"1.231426403","rc":[{"batb":[[0,1.99,10],[1,1.98,45.25],[2,1.97,31]],"ltp":2.02,"tv":13.73,"id":19144236},{"batb":[[0,1.91,6],[1,1.9,49.27],[2,1.8,10]],"ltp":1.94,"tv":104.55,"id":19144241}]}]}
{"op":"mcm","clk":"11780391644","pt":1722864959654,"mc":[{"id":"1.231426403","rc":[{"batb":[[0,1.98,45.25],[1,1.97,31],[2,1.85,2]],"ltp":2.02,"tv":13.73,"id":19144236},{"batb":[[0,1.92,10],[1,1.91,6],[2,1.9,49.27]],"ltp":1.94,"tv":104.55,"id":19144241}]}]}
{"op":"mcm","clk":"11780391760","pt":1722864963375,"mc":[{"id":"1.231426403","rc":[{"batb":[[0,1.99,10],[1,1.98,45.25],[2,1.97,31]],"ltp":2.02,"tv":13.73,"id":19144236},{"batb":[[0,1.91,6],[1,1.9,49.27],[2,1.8,10]],"ltp":1.94,"tv":104.55,"id":19144241}]}]}
{"op":"mcm","clk":"11780391870","pt":1722864966777,"mc":[{"id":"1.231426403","rc":[{"batb":[[0,1.98,45.25],[1,1.97,31],[2,1.85,2]],"ltp":2.02,"tv":13.73,"id":19144236}]}]}
{"op":"mcm","clk":"11780391874","pt":1722864966985,"mc":[{"id":"1.231426403","rc":[{"batb":[[0,1.92,10],[1,1.91,6],[2,1.9,49.27]],"ltp":1.94,"tv":104.55,"id":19144241}]}]}
{"op":"mcm","clk":"11780391947","pt":1722864970386,"mc":[{"id":"1.231426403","rc":[{"batb":[[0,1.99,10],[1,1.98,45.25],[2,1.97,31]],"ltp":2.02,"tv":13.73,"id":19144236},{"batb":[[0,1.91,6],[1,1.9,49.27],[2,1.8,10]],"ltp":1.94,"tv":104.55,"id":19144241}]}]}
{"op":"mcm","clk":"11780392067","pt":1722864974163,"mc":[{"id":"1.231426403","rc":[{"batb":[[0,1.98,45.25],[1,1.97,31],[2,1.85,2]],"ltp":2.02,"tv":13.73,"id":19144236},{"batb":[[0,1.92,10],[1,1.91,6],[2,1.9,49.27]],"ltp":1.94,"tv":104.55,"id":19144241}]}]}
{"op":"mcm","clk":"11780392157","pt":1722864977696,"mc":[{"id":"1.231426403","rc":[{"batb":[[0,1.99,10],[1,1.98,45.25],[2,1.97,31]],"ltp":2.02,"tv":13.73,"id":19144236},{"batb":[[0,1.91,6],[1,1.9,49.27],[2,1.8,10]],"ltp":1.94,"tv":104.55,"id":19144241}]}]}
{"op":"mcm","clk":"11780392218","pt":1722864980076,"mc":[{"id":"1.231426403","rc":[{"batb":[[0,1.92,10],[1,1.91,6],[2,1.9,49.27]],"ltp":1.94,"tv":104.55,"id":19144241}]}]}
{"op":"mcm","clk":"11780392251","pt":1722864980895,"mc":[{"id":"1.231426403","rc":[{"batb":[[0,1.98,45.25],[1,1.97,31],[2,1.85,2]],"ltp":2.02,"tv":13.73,"id":19144236}]}]}
{"op":"mcm","clk":"11780392360","pt":1722864983691,"mc":[{"id":"1.231426403","rc":[{"batb":[[0,1.91,6],[1,1.9,49.27],[2,1.8,10]],"ltp":1.94,"tv":104.55,"id":19144241}]}]}
{"op":"mcm","clk":"11780392367","pt":1722864983896,"mc":[{"id":"1.231426403","rc":[{"batb":[[0,1.99,10],[1,1.98,45.25],[2,1.97,31]],"ltp":2.02,"tv":13.73,"id":19144236}]}]}
{"op":"mcm","clk":"11780392471","pt":1722864987374,"mc":[{"id":"1.231426403","rc":[{"batb":[[0,1.98,45.25],[1,1.97,31],[2,1.85,2]],"ltp":2.02,"tv":13.73,"id":19144236},{"batb":[[0,1.92,10],[1,1.91,6],[2,1.9,49.27]],"ltp":1.94,"tv":104.55,"id":19144241}]}]}
{"op":"mcm","clk":"11780392506","pt":1722864989473,"mc":[{"id":"1.231426403","rc":[{"batb":[[0,1.99,10],[1,1.98,45.25],[2,1.97,31]],"ltp":2.02,"tv":13.73,"id":19144236}]}]}
{"op":"mcm","clk":"11780392535","pt":1722864990707,"mc":[{"id":"1.231426403","rc":[{"batb":[[0,1.91,6],[1,1.9,49.27],[2,1.8,10]],"ltp":1.94,"tv":104.55,"id":19144241}]}]}
{"op":"mcm","clk":"11780392607","pt":1722864993189,"mc":[{"id":"1.231426403","rc":[{"batb":[[0,1.98,45.25],[1,1.97,31],[2,1.85,2]],"ltp":2.02,"tv":13.73,"id":19144236},{"batb":[[0,1.92,10],[1,1.91,6],[2,1.9,49.27]],"ltp":1.94,"tv":104.55,"id":19144241}]}]}
{"op":"mcm","clk":"11780392728","pt":1722864996801,"mc":[{"id":"1.231426403","rc":[{"batb":[[0,1.99,10],[1,1.98,45.25],[2,1.97,31]],"ltp":2.02,"tv":13.73,"id":19144236},{"batb":[[0,1.91,6],[1,1.9,49.27],[2,1.8,10]],"ltp":1.94,"tv":104.55,"id":19144241}]}]}
{"op":"mcm","clk":"11780392818","pt":1722865000412,"mc":[{"id":"1.231426403","rc":[{"batb":[[0,1.98,45.25],[1,1.97,31],[2,1.85,2]],"ltp":2.02,"tv":13.73,"id":19144236},{"batb":[[0,1.92,10],[1,1.91,6],[2,1.9,49.27]],"ltp":1.94,"tv":104.55,"id":19144241}]}]}
{"op":"mcm","clk":"11780392909","pt":1722865003716,"mc":[{"id":"1.231426403","rc":[{"batb":[[0,1.91,6],[1,1.9,49.27],[2,1.8,10]],"ltp":1.94,"tv":104.55,"id":19144241}]}]}
{"op":"mcm","clk":"11780392914","pt":1722865003916,"mc":[{"id":"1.231426403","rc":[{"batb":[[0,1.99,10],[1,1.98,45.25],[2,1.97,31]],"ltp":2.02,"tv":13.73,"id":19144236}]}]}
{"op":"mcm","clk":"11780392937","pt":1722865005313,"mc":[{"id":"1.231426403","rc":[{"batb":[[2,1.81,8.96]],"ltp":1.94,"tv":104.55,"id":19144241}]}]}
{"op":"mcm","clk":"11780392975","pt":1722865006507,"mc":[{"id":"1.231426403","rc":[{"batb":[[0,1.92,10],[1,1.91,6],[2,1.9,49.27]],"ltp":1.94,"tv":104.55,"id":19144241}]}]}
{"op":"mcm","clk":"11780392984","pt":1722865007221,"mc":[{"id":"1.231426403","rc":[{"batb":[[0,1.98,45.25],[1,1.97,31],[2,1.96,8.27]],"ltp":2.02,"tv":13.73,"id":19144236}]}]}
{"op":"mcm","clk":"11780393060","pt":1722865010299,"mc":[{"id":"1.231426403","rc":[{"batb":[[0,1.99,10],[1,1.98,45.25],[2,1.97,31]],"ltp":2.02,"tv":13.73,"id":19144236},{"batb":[[0,1.91,6],[1,1.9,49.27],[2,1.81,8.96]],"ltp":1.94,"tv":104.55,"id":19144241}]}]}
{"op":"mcm","clk":"11780393156","pt":1722865013605,"mc":[{"id":"1.231426403","rc":[{"batb":[[0,1.98,45.25],[1,1.97,31],[2,1.85,2]],"ltp":2.02,"tv":13.73,"id":19144236},{"batb":[[0,1.92,10],[1,1.91,6],[2,1.9,49.27]],"ltp":1.94,"tv":104.55,"id":19144241}]}]}
{"op":"mcm","clk":"11780393209","pt":1722865016534,"mc":[{"id":"1.231426403","rc":[{"batb":[[0,1.99,10],[1,1.98,45.25],[2,1.97,31]],"ltp":2.02,"tv":13.73,"id":19144236},{"batb":[[0,1.91,6],[1,1.9,49.27],[2,1.8,10]],"ltp":1.94,"tv":104.55,"id":19144241}]}]}
{"op":"mcm","clk":"11780393292","pt":1722865020237,"mc":[{"id":"1.231426403","rc":[{"batb":[[0,1.98,45.25],[1,1.97,31],[2,1.85,2]],"ltp":2.02,"tv":13.73,"id":19144236},{"batb":[[0,1.92,10],[1,1.91,6],[2,1.9,49.27]],"ltp":1.94,"tv":104.55,"id":19144241}]}]}
{"op":"mcm","clk":"11780393403","pt":1722865023644,"mc":[{"id":"1.231426403","rc":[{"batb":[[0,1.91,6],[1,1.9,49.27],[2,1.8,10]],"ltp":1.94,"tv":104.55,"id":19144241}]}]}
{"op":"mcm","clk":"11780393406","pt":1722865023904,"mc":[{"id":"1.231426403","rc":[{"batb":[[0,1.99,10],[1,1.98,45.25],[2,1.97,31]],"ltp":2.02,"tv":13.73,"id":19144236}]}]}
{"op":"mcm","clk":"11780393488","pt":1722865026239,"mc":[{"id":"1.231426403","rc":[{"batb":[[0,1.92,10],[1,1.91,6],[2,1.9,49.27]],"batl":[[1,3.8,0.57]],"ltp":1.94,"tv":104.55,"id":19144241}]}]}
{"op":"mcm","clk":"11780393528","pt":1722865027228,"mc":[{"id":"1.231426403","rc":[{"batb":[[0,1.98,45.25],[1,1.97,31],[2,1.85,2]],"ltp":2.02,"tv":13.73,"id":19144236}]}]}
{"op":"mcm","clk":"11780393623","pt":1722865029743,"mc":[{"id":"1.231426403","rc":[{"batb":[[0,1.99,10],[1,1.98,45.25],[2,1.97,31]],"ltp":2.02,"tv":13.73,"id":19144236},{"batb":[[0,1.91,6],[1,1.9,49.27],[2,1.8,10]],"ltp":1.94,"tv":104.55,"id":19144241}]}]}
{"op":"mcm","clk":"11780393666","pt":1722865031439,"mc":[{"id":"1.231426403","rc":[{"batl":[[0,2.24,30.07],[1,2.54,4.04],[2,3.5,0.54]],"ltp":2.02,"tv":13.73,"id":19144236}]}]}
{"op":"mcm","clk":"11780393704","pt":1722865033351,"mc":[{"id":"1.231426403","rc":[{"batb":[[0,1.98,45.25],[1,1.97,31],[2,1.85,2]],"ltp":2.02,"tv":13.73,"id":19144236},{"batb":[[0,1.92,10],[1,1.91,6],[2,1.9,49.27]],"ltp":1.94,"tv":104.55,"id":19144241}]}]}
{"op":"mcm","clk":"11780393742","pt":1722865034847,"mc":[{"id":"1.231426403","rc":[{"batl":[[0,2.22,1.01],[1,2.24,30.07],[2,2.54,4.04]],"ltp":2.02,"tv":13.73,"id":19144236}]}]}
{"op":"mcm","clk":"11780393791","pt":1722865036647,"mc":[{"id":"1.231426403","rc":[{"batb":[[0,1.91,6],[1,1.9,49.27],[2,1.8,10]],"ltp":1.94,"tv":104.55,"id":19144241}]}]}
{"op":"mcm","clk":"11780393797","pt":1722865036855,"mc":[{"id":"1.231426403","rc":[{"batb":[[0,1.99,10],[1,1.98,45.25],[2,1.97,31]],"ltp":2.02,"tv":13.73,"id":19144236}]}]}
{"op":"mcm","clk":"11780393880","pt":1722865040356,"mc":[{"id":"1.231426403","rc":[{"batb":[[0,1.98,45.25],[1,1.97,31],[2,1.85,2]],"ltp":2.02,"tv":13.73,"id":19144236},{"batb":[[0,1.92,10],[1,1.91,6],[2,1.9,49.27]],"ltp":1.94,"tv":104.55,"id":19144241}]}]}
{"op":"mcm","clk":"11780393961","pt":1722865043647,"mc":[{"id":"1.231426403","rc":[{"batb":[[0,1.99,10],[1,1.98,45.25],[2,1.97,31]],"ltp":2.02,"tv":13.73,"id":19144236},{"batb":[[0,1.91,6],[1,1.9,49.27],[2,1.81,8.96]],"ltp":1.94,"tv":104.55,"id":19144241}]}]}
{"op":"mcm","clk":"11780394043","pt":1722865046735,"mc":[{"id":"1.231426403","rc":[{"batb":[[0,1.98,45.25],[1,1.97,31],[2,1.96,8.27]],"ltp":2.02,"tv":13.73,"id":19144236}]}]}
{"op":"mcm","clk":"11780394047","pt":1722865046938,"mc":[{"id":"1.231426403","rc":[{"batb":[[0,1.92,10],[1,1.91,6],[2,1.9,49.27]],"ltp":1.94,"tv":104.55,"id":19144241}]}]}
{"op":"mcm","clk":"11780394119","pt":1722865050444,"mc":[{"id":"1.231426403","rc":[{"batb":[[0,1.99,10],[1,1.98,45.25],[2,1.97,31]],"ltp":2.02,"tv":13.73,"id":19144236},{"batb":[[0,1.91,6],[1,1.9,49.27],[2,1.81,8.96]],"ltp":1.94,"tv":104.55,"id":19144241}]}]}
{"op":"mcm","clk":"11780394208","pt":1722865053938,"mc":[{"id":"1.231426403","rc":[{"batb":[[0,1.98,45.25],[1,1.97,31],[2,1.96,8.27]],"ltp":2.02,"tv":13.73,"id":19144236},{"batb":[[0,1.92,10],[1,1.91,6],[2,1.9,49.27]],"ltp":1.94,"tv":104.55,"id":19144241}]}]}
{"op":"mcm","clk":"11780394291","pt":1722865057334,"mc":[{"id":"1.231426403","rc":[{"batb":[[0,1.99,10],[1,1.98,45.25],[2,1.97,31]],"ltp":2.02,"tv":13.73,"id":19144236},{"batb":[[0,1.91,6],[1,1.9,49.27],[2,1.81,8.96]],"ltp":1.94,"tv":104.55,"id":19144241}]}]}
{"op":"mcm","clk":"11780394348","pt":1722865060673,"mc":[{"id":"1.231426403","rc":[{"batb":[[0,1.98,45.25],[1,1.97,31],[2,1.96,8.27]],"ltp":2.02,"tv":13.73,"id":19144236}]}]}
{"op":"mcm","clk":"11780394351","pt":1722865060840,"mc":[{"id":"1.231426403","rc":[{"batb":[[0,1.92,10],[1,1.91,6],[2,1.9,49.27]],"ltp":1.94,"tv":104.55,"id":19144241}]}]}
{"op":"mcm","clk":"11780394429","pt":1722865064244,"mc":[{"id":"1.231426403","rc":[{"batb":[[0,1.99,10],[1,1.98,45.25],[2,1.97,31]],"ltp":2.02,"tv":13.73,"id":19144236},{"batb":[[0,1.91,6],[1,1.9,49.27],[2,1.81,8.96]],"ltp":1.94,"tv":104.55,"id":19144241}]}]}
{"op":"mcm","clk":"11780394498","pt":1722865067738,"mc":[{"id":"1.231426403","rc":[{"batb":[[0,1.98,45.25],[1,1.97,31],[2,1.96,8.27]],"ltp":2.02,"tv":13.73,"id":19144236},{"batb":[[0,1.92,10],[1,1.91,6],[2,1.9,49.27]],"ltp":1.94,"tv":104.55,"id":19144241}]}]}
{"op":"mcm","clk":"11780394567","pt":1722865071350,"mc":[{"id":"1.231426403","rc":[{"batb":[[0,1.99,10],[1,1.98,45.25],[2,1.97,31]],"ltp":2.02,"tv":13.73,"id":19144236},{"batb":[[0,1.91,6],[1,1.9,49.27],[2,1.81,8.96]],"ltp":1.94,"tv":104.55,"id":19144241}]}]}
{"op":"mcm","clk":"11780394651","pt":1722865074655,"mc":[{"id":"1.231426403","rc":[{"batb":[[0,1.98,45.25],[1,1.97,31],[2,1.96,8.27]],"ltp":2.02,"tv":13.73,"id":19144236}]}]}
{"op":"mcm","clk":"11780394658","pt":1722865074863,"mc":[{"id":"1.231426403","rc":[{"batb":[[0,1.92,10],[1,1.91,6],[2,1.9,49.27]],"ltp":1.94,"tv":104.55,"id":19144241}]}]}
{"op":"mcm","clk":"11780394738","pt":1722865078375,"mc":[{"id":"1.231426403","rc":[{"batb":[[0,1.99,10],[1,1.98,45.25],[2,1.97,31]],"ltp":2.02,"tv":13.73,"id":19144236},{"batb":[[0,1.91,6],[1,1.9,49.27],[2,1.81,8.96]],"ltp":1.94,"tv":104.55,"id":19144241}]}]}
{"op":"mcm","clk":"11780394815","pt":1722865081678,"mc":[{"id":"1.231426403","rc":[{"batb":[[0,1.98,45.25],[1,1.97,31],[2,1.96,8.27]],"ltp":2.02,"tv":13.73,"id":19144236}]}]}
{"op":"mcm","clk":"11780394822","pt":1722865081883,"mc":[{"id":"1.231426403","rc":[{"batb":[[0,1.92,10],[1,1.91,6],[2,1.9,49.27]],"ltp":1.94,"tv":104.55,"id":19144241}]}]}
{"op":"mcm","clk":"11780394916","pt":1722865085396,"mc":[{"id":"1.231426403","rc":[{"batb":[[0,1.99,10],[1,1.98,45.25],[2,1.97,31]],"ltp":2.02,"tv":13.73,"id":19144236},{"batb":[[0,1.91,6],[1,1.9,49.27],[2,1.81,8.96]],"ltp":1.94,"tv":104.55,"id":19144241}]}]}
{"op":"mcm","clk":"11780395029","pt":1722865088708,"mc":[{"id":"1.231426403","rc":[{"batb":[[0,1.98,45.25],[1,1.97,31],[2,1.96,8.27]],"ltp":2.02,"tv":13.73,"id":19144236}]}]}
{"op":"mcm","clk":"11780395038","pt":1722865088898,"mc":[{"id":"1.231426403","rc":[{"batb":[[0,1.92,10],[1,1.91,6],[2,1.9,49.27]],"ltp":1.94,"tv":104.55,"id":19144241}]}]}
{"op":"mcm","clk":"11780395153","pt":1722865092411,"mc":[{"id":"1.231426403","rc":[{"batb":[[0,1.99,10],[1,1.98,45.25],[2,1.97,31]],"ltp":2.02,"tv":13.73,"id":19144236},{"batb":[[0,1.91,6],[1,1.9,49.27],[2,1.81,8.96]],"ltp":1.94,"tv":104.55,"id":19144241}]}]}
{"op":"mcm","clk":"11780395248","pt":1722865095983,"mc":[{"id":"1.231426403","rc":[{"batb":[[0,1.98,45.25],[1,1.97,31],[2,1.96,8.27]],"ltp":2.02,"tv":13.73,"id":19144236},{"batb":[[0,1.92,10],[1,1.91,6],[2,1.9,49.27]],"ltp":1.94,"tv":104.55,"id":19144241}]}]}
{"op":"mcm","clk":"11780395334","pt":1722865099597,"mc":[{"id":"1.231426403","rc":[{"batb":[[0,1.99,10],[1,1.98,45.25],[2,1.97,31]],"ltp":2.02,"tv":13.73,"id":19144236},{"batb":[[0,1.91,6],[1,1.9,49.27],[2,1.81,8.96]],"ltp":1.94,"tv":104.55,"id":19144241}]}]}
{"op":"mcm","clk":"11780395419","pt":1722865103206,"mc":[{"id":"1.231426403","rc":[{"batb":[[0,1.98,45.25],[1,1.97,31],[2,1.96,8.27]],"ltp":2.02,"tv":13.73,"id":19144236},{"batb":[[0,1.92,10],[1,1.91,6],[2,1.9,49.27]],"ltp":1.94,"tv":104.55,"id":19144241}]}]}
{"op":"mcm","clk":"11780395512","pt":1722865106407,"mc":[{"id":"1.231426403","rc":[{"batb":[[0,1.99,10],[1,1.98,45.25],[2,1.97,31]],"ltp":2.02,"tv":13.73,"id":19144236},{"batb":[[0,1.91,6],[1,1.9,49.27],[2,1.81,8.96]],"ltp":1.94,"tv":104.55,"id":19144241}]}]}
{"op":"mcm","clk":"11780395605","pt":1722865109826,"mc":[{"id":"1.231426403","rc":[{"batb":[[0,1.98,45.25],[1,1.97,31],[2,1.96,8.27]],"ltp":2.02,"tv":13.73,"id":19144236}]}]}
{"op":"mcm","clk":"11780395610","pt":1722865110031,"mc":[{"id":"1.231426403","rc":[{"batb":[[0,1.92,10],[1,1.91,6],[2,1.9,49.27]],"ltp":1.94,"tv":104.55,"id":19144241}]}]}
{"op":"mcm","clk":"11780395670","pt":1722865113435,"mc":[{"id":"1.231426403","rc":[{"batb":[[0,1.99,10],[1,1.98,45.25],[2,1.97,31]],"ltp":2.02,"tv":13.73,"id":19144236},{"batb":[[0,1.91,6],[1,1.9,49.27],[2,1.81,8.96]],"ltp":1.94,"tv":104.55,"id":19144241}]}]}
{"op":"mcm","clk":"11780395752","pt":1722865116737,"mc":[{"id":"1.231426403","rc":[{"batb":[[0,1.98,45.25],[1,1.97,31],[2,1.96,8.27]],"ltp":2.02,"tv":13.73,"id":19144236}]}]}
{"op":"mcm","clk":"11780395759","pt":1722865117000,"mc":[{"id":"1.231426403","rc":[{"batb":[[0,1.92,10],[1,1.91,6],[2,1.9,49.27]],"ltp":1.94,"tv":104.55,"id":19144241}]}]}
{"op":"mcm","clk":"11780395841","pt":1722865120512,"mc":[{"id":"1.231426403","rc":[{"batb":[[0,1.99,10],[1,1.98,45.25],[2,1.97,31]],"ltp":2.02,"tv":13.73,"id":19144236},{"batb":[[0,1.91,6],[1,1.9,49.27],[2,1.81,8.96]],"ltp":1.94,"tv":104.55,"id":19144241}]}]}
{"op":"mcm","clk":"11780395925","pt":1722865124056,"mc":[{"id":"1.231426403","rc":[{"batb":[[0,1.98,45.25],[1,1.97,31],[2,1.96,8.27]],"ltp":2.02,"tv":13.73,"id":19144236},{"batb":[[0,1.92,10],[1,1.91,6],[2,1.9,49.27]],"ltp":1.94,"tv":104.55,"id":19144241}]}]}
{"op":"mcm","clk":"11780396016","pt":1722865127657,"mc":[{"id":"1.231426403","rc":[{"batb":[[0,1.99,10],[1,1.98,45.25],[2,1.97,31]],"ltp":2.02,"tv":13.73,"id":19144236},{"batb":[[0,1.91,6],[1,1.9,49.27],[2,1.81,8.96]],"ltp":1.94,"tv":104.55,"id":19144241}]}]}
{"op":"mcm","clk":"11780396097","pt":1722865131439,"mc":[{"id":"1.231426403","rc":[{"batb":[[0,1.98,45.25],[1,1.97,31],[2,1.96,8.27]],"ltp":2.02,"tv":13.73,"id":19144236},{"batb":[[0,1.92,10],[1,1.91,6],[2,1.9,49.27]],"ltp":1.94,"tv":104.55,"id":19144241}]}]}
{"op":"mcm","clk":"11780396169","pt":1722865134019,"mc":[{"id":"1.231426403","rc":[{"batb":[[0,1.99,10],[1,1.98,45.25],[2,1.97,31]],"ltp":2.02,"tv":13.73,"id":19144236}]}]}
{"op":"mcm","clk":"11780396194","pt":1722865134841,"mc":[{"id":"1.231426403","rc":[{"batb":[[0,1.91,6],[1,1.9,49.27],[2,1.81,8.96]],"ltp":1.94,"tv":104.55,"id":19144241}]}]}
{"op":"mcm","clk":"11780396271","pt":1722865137787,"mc":[{"id":"1.231426403","rc":[{"batb":[[0,1.98,45.25],[1,1.97,31],[2,1.96,8.27]],"ltp":2.02,"tv":13.73,"id":19144236},{"batb":[[0,1.92,10],[1,1.91,6],[2,1.9,49.27]],"ltp":1.94,"tv":104.55,"id":19144241}]}]}
{"op":"mcm","clk":"11780396389","pt":1722865141453,"mc":[{"id":"1.231426403","rc":[{"batb":[[0,1.99,10],[1,1.98,45.25],[2,1.97,31]],"ltp":2.02,"tv":13.73,"id":19144236},{"batb":[[0,1.91,6],[1,1.9,49.27],[2,1.81,8.96]],"ltp":1.94,"tv":104.55,"id":19144241}]}]}
{"op":"mcm","clk":"11780396493","pt":1722865145064,"mc":[{"id":"1.231426403","rc":[{"batb":[[0,1.98,45.25],[1,1.97,31],[2,1.96,8.27]],"ltp":2.02,"tv":13.73,"id":19144236},{"batb":[[0,1.92,10],[1,1.91,6],[2,1.9,49.27]],"ltp":1.94,"tv":104.55,"id":19144241}]}]}
{"op":"mcm","clk":"11780396606","pt":1722865148775,"mc":[{"id":"1.231426403","rc":[{"batb":[[0,1.99,10],[1,1.98,45.25],[2,1.97,31]],"ltp":2.02,"tv":13.73,"id":19144236},{"batb":[[0,1.91,6],[1,1.9,49.27],[2,1.81,8.96]],"ltp":1.94,"tv":104.55,"id":19144241}]}]}
{"op":"mcm","clk":"11780396721","pt":1722865151773,"mc":[{"id":"1.231426403","rc":[{"batb":[[0,1.92,10],[1,1.91,6],[2,1.9,49.27]],"ltp":1.94,"tv":104.55,"id":19144241}]}]}
{"op":"mcm","clk":"11780396726","pt":1722865152080,"mc":[{"id":"1.231426403","rc":[{"batb":[[0,1.98,45.25],[1,1.97,31],[2,1.96,8.27]],"ltp":2.02,"tv":13.73,"id":19144236}]}]}
{"op":"mcm","clk":"11780396852","pt":1722865155393,"mc":[{"id":"1.231426403","rc":[{"batb":[[0,1.99,10],[1,1.98,45.25],[2,1.97,31]],"ltp":2.02,"tv":13.73,"id":19144236},{"batb":[[0,1.91,6],[1,1.9,49.27],[2,1.81,8.96]],"ltp":1.94,"tv":104.55,"id":19144241}]}]}
{"op":"mcm","clk":"11780397037","pt":1722865158653,"mc":[{"id":"1.231426403","rc":[{"batb":[[0,1.98,45.25],[1,1.97,31],[2,1.96,8.27]],"ltp":2.02,"tv":13.73,"id":19144236},{"batb":[[0,1.92,10],[1,1.91,6],[2,1.9,49.27]],"ltp":1.94,"tv":104.55,"id":19144241}]}]}
{"op":"mcm","clk":"11780397172","pt":1722865161668,"mc":[{"id":"1.231426403","rc":[{"batb":[[0,1.91,6],[1,1.9,49.27],[2,1.81,8.96]],"ltp":1.94,"tv":104.55,"id":19144241}]}]}
{"op":"mcm","clk":"11780397182","pt":1722865161869,"mc":[{"id":"1.231426403","rc":[{"batb":[[0,1.99,10],[1,1.98,45.25],[2,1.97,31]],"ltp":2.02,"tv":13.73,"id":19144236}]}]}
{"op":"mcm","clk":"11780397330","pt":1722865165259,"mc":[{"id":"1.231426403","rc":[{"batb":[[0,1.98,45.25],[1,1.97,31],[2,1.96,8.27]],"ltp":2.02,"tv":13.73,"id":19144236},{"batb":[[0,1.92,10],[1,1.91,6],[2,1.9,49.27]],"ltp":1.94,"tv":104.55,"id":19144241}]}]}
{"op":"mcm","clk":"11780397467","pt":1722865168770,"mc":[{"id":"1.231426403","rc":[{"batb":[[0,1.99,10],[1,1.98,45.25],[2,1.97,31]],"ltp":2.02,"tv":13.73,"id":19144236},{"batb":[[0,1.91,6],[1,1.9,49.27],[2,1.81,8.96]],"ltp":1.94,"tv":104.55,"id":19144241}]}]}
{"op":"mcm","clk":"11780397589","pt":1722865172181,"mc":[{"id":"1.231426403","rc":[{"batb":[[0,1.98,45.25],[1,1.97,31],[2,1.96,8.27]],"ltp":2.02,"tv":13.73,"id":19144236},{"batb":[[0,1.92,10],[1,1.91,6],[2,1.9,49.27]],"ltp":1.94,"tv":104.55,"id":19144241}]}]}
{"op":"mcm","clk":"11780397721","pt":1722865175698,"mc":[{"id":"1.231426403","rc":[{"batb":[[0,1.99,10],[1,1.98,45.25],[2,1.97,31]],"ltp":2.02,"tv":13.73,"id":19144236},{"batb":[[0,1.91,6],[1,1.9,49.27],[2,1.81,8.96]],"ltp":1.94,"tv":104.55,"id":19144241}]}]}
{"op":"mcm","clk":"11780397838","pt":1722865179391,"mc":[{"id":"1.231426403","rc":[{"batb":[[0,1.98,45.25],[1,1.97,31],[2,1.96,8.27]],"ltp":2.02,"tv":13.73,"id":19144236},{"batb":[[0,1.92,10],[1,1.91,6],[2,1.9,49.27]],"ltp":1.94,"tv":104.55,"id":19144241}]}]}
{"op":"mcm","clk":"11780397969","pt":1722865182788,"mc":[{"id":"1.231426403","rc":[{"batb":[[0,1.99,10],[1,1.98,45.25],[2,1.97,31]],"ltp":2.02,"tv":13.73,"id":19144236},{"batb":[[0,1.91,6],[1,1.9,49.27],[2,1.81,8.96]],"ltp":1.94,"tv":104.55,"id":19144241}]}]}
{"op":"mcm","clk":"11780398054","pt":1722865185309,"mc":[{"id":"1.231426403","rc":[{"batb":[[0,1.92,10],[1,1.91,6],[2,1.9,49.27]],"ltp":1.94,"tv":104.55,"id":19144241}]}]}
{"op":"mcm","clk":"11780398080","pt":1722865186088,"mc":[{"id":"1.231426403","rc":[{"batb":[[0,1.98,45.25],[1,1.97,31],[2,1.96,8.27]],"ltp":2.02,"tv":13.73,"id":19144236}]}]}
{"op":"mcm","clk":"11780398191","pt":1722865188718,"mc":[{"id":"1.231426403","rc":[{"batb":[[0,1.99,10],[1,1.98,45.25],[2,1.97,31]],"ltp":2.02,"tv":13.73,"id":19144236},{"batb":[[0,1.91,6],[1,1.9,49.27],[2,1.81,8.96]],"ltp":1.94,"tv":104.55,"id":19144241}]}]}
{"op":"mcm","clk":"11780398324","pt":1722865192288,"mc":[{"id":"1.231426403","rc":[{"batb":[[0,1.98,45.25],[1,1.97,31],[2,1.96,8.27]],"ltp":2.02,"tv":13.73,"id":19144236},{"batb":[[0,1.92,10],[1,1.91,6],[2,1.9,49.27]],"ltp":1.94,"tv":104.55,"id":19144241}]}]}
{"op":"mcm","clk":"11780398442","pt":1722865195807,"mc":[{"id":"1.231426403","rc":[{"batb":[[0,1.99,10],[1,1.98,45.25],[2,1.97,31]],"ltp":2.02,"tv":13.73,"id":19144236},{"batb":[[0,1.91,6],[1,1.9,49.27],[2,1.81,8.96]],"ltp":1.94,"tv":104.55,"id":19144241}]}]}
{"op":"mcm","clk":"11780398540","pt":1722865199424,"mc":[{"id":"1.231426403","rc":[{"batb":[[0,1.98,45.25],[1,1.97,31],[2,1.96,8.27]],"ltp":2.02,"tv":13.73,"id":19144236},{"batb":[[0,1.92,10],[1,1.91,6],[2,1.9,49.27]],"ltp":1.94,"tv":104.55,"id":19144241}]}]}
{"op":"mcm","clk":"11780398659","pt":1722865203107,"mc":[{"id":"1.231426403","rc":[{"batb":[[0,1.99,10],[1,1.98,45.25],[2,1.97,31]],"ltp":2.02,"tv":13.73,"id":19144236},{"batb":[[0,1.91,6],[1,1.9,49.27],[2,1.81,8.96]],"ltp":1.94,"tv":104.55,"id":19144241}]}]}
{"op":"mcm","clk":"11780398759","pt":1722865206535,"mc":[{"id":"1.231426403","rc":[{"batb":[[0,1.98,45.25],[1,1.97,31],[2,1.96,8.27]],"ltp":2.02,"tv":13.73,"id":19144236},{"batb":[[0,1.92,10],[1,1.91,6],[2,1.9,49.27]],"ltp":1.94,"tv":104.55,"id":19144241}]}]}
{"op":"mcm","clk":"11780398866","pt":1722865210126,"mc":[{"id":"1.231426403","rc":[{"batb":[[0,1.99,10],[1,1.98,45.25],[2,1.97,31]],"ltp":2.02,"tv":13.73,"id":19144236},{"batb":[[0,1.91,6],[1,1.9,49.27],[2,1.81,8.96]],"ltp":1.94,"tv":104.55,"id":19144241}]}]}
{"op":"mcm","clk":"11780399010","pt":1722865213712,"mc":[{"id":"1.231426403","rc":[{"batb":[[0,1.98,45.25],[1,1.97,31],[2,1.96,8.27]],"ltp":2.02,"tv":13.73,"id":19144236},{"batb":[[0,1.92,10],[1,1.91,6],[2,1.9,49.27]],"ltp":1.94,"tv":104.55,"id":19144241}]}]}
{"op":"mcm","clk":"11780399116","pt":1722865217209,"mc":[{"id":"1.231426403","rc":[{"batb":[[0,1.99,10],[1,1.98,45.25],[2,1.97,31]],"ltp":2.02,"tv":13.73,"id":19144236},{"batb":[[0,1.91,6],[1,1.9,49.27],[2,1.81,8.96]],"ltp":1.94,"tv":104.55,"id":19144241}]}]}
{"op":"mcm","clk":"11780399273","pt":1722865220629,"mc":[{"id":"1.231426403","rc":[{"batb":[[0,1.98,45.25],[1,1.97,31],[2,1.96,8.27]],"ltp":2.02,"tv":13.73,"id":19144236},{"batb":[[0,1.92,10],[1,1.91,6],[2,1.9,49.27]],"ltp":1.94,"tv":104.55,"id":19144241}]}]}
{"op":"mcm","clk":"11780399391","pt":1722865223955,"mc":[{"id":"1.231426403","rc":[{"batb":[[0,1.99,10],[1,1.98,45.25],[2,1.97,31]],"ltp":2.02,"tv":13.73,"id":19144236},{"batb":[[0,1.91,6],[1,1.9,49.27],[2,1.81,8.96]],"ltp":1.94,"tv":104.55,"id":19144241}]}]}
{"op":"mcm","clk":"11780399505","pt":1722865227429,"mc":[{"id":"1.231426403","rc":[{"batb":[[0,1.98,45.25],[1,1.97,31],[2,1.96,8.27]],"ltp":2.02,"tv":13.73,"id":19144236},{"batb":[[0,1.92,10],[1,1.91,6],[2,1.9,49.27]],"ltp":1.94,"tv":104.55,"id":19144241}]}]}
{"op":"mcm","clk":"11780399640","pt":1722865230956,"mc":[{"id":"1.231426403","rc":[{"batb":[[0,1.99,10],[1,1.98,45.25],[2,1.97,31]],"ltp":2.02,"tv":13.73,"id":19144236},{"batb":[[0,1.91,6],[1,1.9,49.27],[2,1.81,8.96]],"ltp":1.94,"tv":104.55,"id":19144241}]}]}
{"op":"mcm","clk":"11780399771","pt":1722865234547,"mc":[{"id":"1.231426403","rc":[{"batb":[[0,1.98,45.25],[1,1.97,31],[2,1.96,8.27]],"ltp":2.02,"tv":13.73,"id":19144236},{"batb":[[0,1.92,10],[1,1.91,6],[2,1.9,49.27]],"ltp":1.94,"tv":104.55,"id":19144241}]}]}
{"op":"mcm","clk":"11780399882","pt":1722865238219,"mc":[{"id":"1.231426403","rc":[{"batb":[[0,1.99,10],[1,1.98,45.25],[2,1.97,31]],"ltp":2.02,"tv":13.73,"id":19144236},{"batb":[[0,1.91,6],[1,1.9,49.27],[2,1.81,8.96]],"ltp":1.94,"tv":104.55,"id":19144241}]}]}
{"op":"mcm","clk":"11780400030","pt":1722865241650,"mc":[{"id":"1.231426403","rc":[{"batb":[[0,1.98,45.25],[1,1.97,31],[2,1.96,8.27]],"ltp":2.02,"tv":13.73,"id":19144236},{"batb":[[0,1.92,10],[1,1.91,6],[2,1.9,49.27]],"ltp":1.94,"tv":104.55,"id":19144241}]}]}
{"op":"mcm","clk":"11780400178","pt":1722865245170,"mc":[{"id":"1.231426403","rc":[{"batb":[[0,1.99,10],[1,1.98,45.25],[2,1.97,31]],"ltp":2.02,"tv":13.73,"id":19144236},{"batb":[[0,1.91,6],[1,1.9,49.27],[2,1.81,8.96]],"ltp":1.94,"tv":104.55,"id":19144241}]}]}
{"op":"mcm","clk":"11780400309","pt":1722865248736,"mc":[{"id":"1.231426403","rc":[{"batb":[[0,1.98,45.25],[1,1.97,31],[2,1.96,8.27]],"ltp":2.02,"tv":13.73,"id":19144236},{"batb":[[0,1.92,10],[1,1.91,6],[2,1.9,49.27]],"ltp":1.94,"tv":104.55,"id":19144241}]}]}
{"op":"mcm","clk":"11780400440","pt":1722865252157,"mc":[{"id":"1.231426403","rc":[{"batb":[[0,1.99,10],[1,1.98,45.25],[2,1.97,31]],"ltp":2.02,"tv":13.73,"id":19144236},{"batb":[[0,1.91,6],[1,1.9,49.27],[2,1.81,8.96]],"ltp":1.94,"tv":104.55,"id":19144241}]}]}
{"op":"mcm","clk":"11780400565","pt":1722865255764,"mc":[{"id":"1.231426403","rc":[{"batb":[[0,1.98,45.25],[1,1.97,31],[2,1.96,8.27]],"ltp":2.02,"tv":13.73,"id":19144236},{"batb":[[0,1.92,10],[1,1.91,6],[2,1.9,49.27]],"ltp":1.94,"tv":104.55,"id":19144241}]}]}
{"op":"mcm","clk":"11780400678","pt":1722865259271,"mc":[{"id":"1.231426403","rc":[{"batb":[[0,1.99,10],[1,1.98,45.25],[2,1.97,31]],"ltp":2.02,"tv":13.73,"id":19144236},{"batb":[[0,1.91,6],[1,1.9,49.27],[2,1.81,8.96]],"ltp":1.94,"tv":104.55,"id":19144241}]}]}
{"op":"mcm","clk":"11780400814","pt":1722865262647,"mc":[{"id":"1.231426403","rc":[{"batb":[[0,1.98,45.25],[1,1.97,31],[2,1.96,8.27]],"ltp":2.02,"tv":13.73,"id":19144236}]}]}
{"op":"mcm","clk":"11780400817","pt":1722865262850,"mc":[{"id":"1.231426403","rc":[{"batb":[[0,1.92,10],[1,1.91,6],[2,1.9,49.27]],"ltp":1.94,"tv":104.55,"id":19144241}]}]}
{"op":"mcm","clk":"11780400975","pt":1722865266371,"mc":[{"id":"1.231426403","rc":[{"batb":[[0,1.99,10],[1,1.98,45.25],[2,1.97,31]],"ltp":2.02,"tv":13.73,"id":19144236},{"batb":[[0,1.91,6],[1,1.9,49.27],[2,1.81,8.96]],"ltp":1.94,"tv":104.55,"id":19144241}]}]}
{"op":"mcm","clk":"11780401112","pt":1722865269800,"mc":[{"id":"1.231426403","rc":[{"batb":[[0,1.98,45.25],[1,1.97,31],[2,1.96,8.27]],"ltp":2.02,"tv":13.73,"id":19144236},{"batb":[[0,1.92,10],[1,1.91,6],[2,1.9,49.27]],"ltp":1.94,"tv":104.55,"id":19144241}]}]}
{"op":"mcm","clk":"11780401235","pt":1722865273271,"mc":[{"id":"1.231426403","rc":[{"batb":[[0,1.99,10],[1,1.98,45.25],[2,1.97,31]],"ltp":2.02,"tv":13.73,"id":19144236},{"batb":[[0,1.91,6],[1,1.9,49.27],[2,1.81,8.96]],"ltp":1.94,"tv":104.55,"id":19144241}]}]}
{"op":"mcm","clk":"11780401351","pt":1722865276794,"mc":[{"id":"1.231426403","rc":[{"batb":[[0,1.98,45.25],[1,1.97,31],[2,1.96,8.27]],"ltp":2.02,"tv":13.73,"id":19144236},{"batb":[[0,1.92,10],[1,1.91,6],[2,1.9,49.27]],"ltp":1.94,"tv":104.55,"id":19144241}]}]}
{"op":"mcm","clk":"11780401453","pt":1722865280362,"mc":[{"id":"1.231426403","rc":[{"batb":[[0,1.99,10],[1,1.98,45.25],[2,1.97,31]],"ltp":2.02,"tv":13.73,"id":19144236},{"batb":[[0,1.91,6],[1,1.9,49.27],[2,1.81,8.96]],"ltp":1.94,"tv":104.55,"id":19144241}]}]}
{"op":"mcm","clk":"11780401572","pt":1722865283669,"mc":[{"id":"1.231426403","rc":[{"batb":[[0,1.98,45.25],[1,1.97,31],[2,1.96,8.27]],"ltp":2.02,"tv":13.73,"id":19144236},{"batb":[[0,1.92,10],[1,1.91,6],[2,1.9,49.27]],"ltp":1.94,"tv":104.55,"id":19144241}]}]}
{"op":"mcm","clk":"11780401669","pt":1722865287273,"mc":[{"id":"1.231426403","rc":[{"batb":[[0,1.99,10],[1,1.98,45.25],[2,1.97,31]],"ltp":2.02,"tv":13.73,"id":19144236},{"batb":[[0,1.91,6],[1,1.9,49.27],[2,1.81,8.96]],"ltp":1.94,"tv":104.55,"id":19144241}]}]}
{"op":"mcm","clk":"11780401802","pt":1722865290777,"mc":[{"id":"1.231426403","rc":[{"batb":[[0,1.98,45.25],[1,1.97,31],[2,1.96,8.27]],"ltp":2.02,"tv":13.73,"id":19144236}]}]}
{"op":"mcm","clk":"11780401810","pt":1722865290982,"mc":[{"id":"1.231426403","rc":[{"batb":[[0,1.92,10],[1,1.91,6],[2,1.9,49.27]],"ltp":1.94,"tv":104.55,"id":19144241}]}]}
{"op":"mcm","clk":"11780401951","pt":1722865294385,"mc":[{"id":"1.231426403","rc":[{"batb":[[0,1.99,10],[1,1.98,45.25],[2,1.97,31]],"ltp":2.02,"tv":13.73,"id":19144236},{"batb":[[0,1.91,6],[1,1.9,49.27],[2,1.81,8.96]],"ltp":1.94,"tv":104.55,"id":19144241}]}]}
{"op":"mcm","clk":"11780402075","pt":1722865297775,"mc":[{"id":"1.231426403","rc":[{"batb":[[0,1.98,45.25],[1,1.97,31],[2,1.96,8.27]],"ltp":2.02,"tv":13.73,"id":19144236}]}]}
{"op":"mcm","clk":"11780402080","pt":1722865297982,"mc":[{"id":"1.231426403","rc":[{"batb":[[0,1.92,10],[1,1.91,6],[2,1.9,49.27]],"ltp":1.94,"tv":104.55,"id":19144241}]}]}
{"op":"mcm","clk":"11780402202","pt":1722865301783,"mc":[{"id":"1.231426403","rc":[{"batb":[[0,1.99,10],[1,1.98,45.25],[2,1.97,31]],"ltp":2.02,"tv":13.73,"id":19144236},{"batb":[[0,1.91,6],[1,1.9,49.27],[2,1.81,8.96]],"ltp":1.94,"tv":104.55,"id":19144241}]}]}
{"op":"mcm","clk":"11780402315","pt":1722865305393,"mc":[{"id":"1.231426403","rc":[{"batb":[[0,1.98,45.25],[1,1.97,31],[2,1.96,8.27]],"ltp":2.02,"tv":13.73,"id":19144236},{"batb":[[0,1.92,10],[1,1.91,6],[2,1.9,49.27]],"ltp":1.94,"tv":104.55,"id":19144241}]}]}
{"op":"mcm","clk":"11780402441","pt":1722865308792,"mc":[{"id":"1.231426403","rc":[{"batb":[[0,1.91,6],[1,1.9,49.27],[2,1.81,8.96]],"ltp":1.94,"tv":104.55,"id":19144241}]}]}
{"op":"mcm","clk":"11780402445","pt":1722865308996,"mc":[{"id":"1.231426403","rc":[{"batb":[[0,1.99,10],[1,1.98,45.25],[2,1.97,31]],"ltp":2.02,"tv":13.73,"id":19144236}]}]}
{"op":"mcm","clk":"11780402599","pt":1722865312500,"mc":[{"id":"1.231426403","rc":[{"batb":[[0,1.98,45.25],[1,1.97,31],[2,1.96,8.27]],"ltp":2.02,"tv":13.73,"id":19144236},{"batb":[[0,1.92,10],[1,1.91,6],[2,1.9,49.27]],"ltp":1.94,"tv":104.55,"id":19144241}]}]}
{"op":"mcm","clk":"11780402705","pt":1722865315800,"mc":[{"id":"1.231426403","rc":[{"batb":[[0,1.91,6],[1,1.9,49.27],[2,1.81,8.96]],"ltp":1.94,"tv":104.55,"id":19144241}]}]}
{"op":"mcm","clk":"11780402710","pt":1722865316004,"mc":[{"id":"1.231426403","rc":[{"batb":[[0,1.99,10],[1,1.98,45.25],[2,1.97,31]],"ltp":2.02,"tv":13.73,"id":19144236}]}]}
{"op":"mcm","clk":"11780402807","pt":1722865319551,"mc":[{"id":"1.231426403","rc":[{"batb":[[0,1.98,45.25],[1,1.97,31],[2,1.96,8.27]],"ltp":2.02,"tv":13.73,"id":19144236},{"batb":[[0,1.92,10],[1,1.91,6],[2,1.9,49.27]],"ltp":1.94,"tv":104.55,"id":19144241}]}]}
{"op":"mcm","clk":"11780402924","pt":1722865322807,"mc":[{"id":"1.231426403","rc":[{"batb":[[0,1.99,10],[1,1.98,45.25],[2,1.97,31]],"ltp":2.02,"tv":13.73,"id":19144236},{"batb":[[0,1.91,6],[1,1.9,49.27],[2,1.81,8.96]],"ltp":1.94,"tv":104.55,"id":19144241}]}]}
{"op":"mcm","clk":"11780403036","pt":1722865326414,"mc":[{"id":"1.231426403","rc":[{"batb":[[0,1.98,45.25],[1,1.97,31],[2,1.96,8.27]],"ltp":2.02,"tv":13.73,"id":19144236},{"batb":[[0,1.92,10],[1,1.91,6],[2,1.9,49.27]],"ltp":1.94,"tv":104.55,"id":19144241}]}]}
{"op":"mcm","clk":"11780403153","pt":1722865329623,"mc":[{"id":"1.231426403","rc":[{"batb":[[0,1.91,6],[1,1.9,49.27],[2,1.81,8.96]],"ltp":1.94,"tv":104.55,"id":19144241}]}]}
{"op":"mcm","clk":"11780403159","pt":1722865329833,"mc":[{"id":"1.231426403","rc":[{"batb":[[0,1.99,10],[1,1.98,45.25],[2,1.97,31]],"ltp":2.02,"tv":13.73,"id":19144236}]}]}
{"op":"mcm","clk":"11780403285","pt":1722865333236,"mc":[{"id":"1.231426403","rc":[{"batb":[[0,1.98,45.25],[1,1.97,31],[2,1.96,8.27]],"ltp":2.02,"tv":13.73,"id":19144236},{"batb":[[0,1.92,10],[1,1.91,6],[2,1.9,49.27]],"ltp":1.94,"tv":104.55,"id":19144241}]}]}
{"op":"mcm","clk":"11780403408","pt":1722865336638,"mc":[{"id":"1.231426403","rc":[{"batb":[[0,1.91,6],[1,1.9,49.27],[2,1.81,8.96]],"ltp":1.94,"tv":104.55,"id":19144241}]}]}
{"op":"mcm","clk":"11780403416","pt":1722865336865,"mc":[{"id":"1.231426403","rc":[{"batb":[[0,1.99,10],[1,1.98,45.25],[2,1.97,31]],"ltp":2.02,"tv":13.73,"id":19144236}]}]}
{"op":"mcm","clk":"11780403558","pt":1722865340160,"mc":[{"id":"1.231426403","rc":[{"batb":[[0,1.98,45.25],[1,1.97,31],[2,1.96,8.27]],"ltp":2.02,"tv":13.73,"id":19144236},{"batb":[[0,1.92,10],[1,1.91,6],[2,1.9,49.27]],"ltp":1.94,"tv":104.55,"id":19144241}]}]}
{"op":"mcm","clk":"11780403695","pt":1722865343667,"mc":[{"id":"1.231426403","rc":[{"batb":[[0,1.99,10],[1,1.98,45.25],[2,1.97,31]],"ltp":2.02,"tv":13.73,"id":19144236},{"batb":[[0,1.91,6],[1,1.9,49.27],[2,1.81,8.96]],"ltp":1.94,"tv":104.55,"id":19144241}]}]}
{"op":"mcm","clk":"11780403809","pt":1722865347039,"mc":[{"id":"1.231426403","rc":[{"batb":[[0,1.98,45.25],[1,1.97,31],[2,1.96,8.27]],"ltp":2.02,"tv":13.73,"id":19144236},{"batb":[[0,1.92,10],[1,1.91,6],[2,1.9,49.27]],"ltp":1.94,"tv":104.55,"id":19144241}]}]}
{"op":"mcm","clk":"11780403950","pt":1722865350759,"mc":[{"id":"1.231426403","rc":[{"batb":[[0,1.99,10],[1,1.98,45.25],[2,1.97,31]],"ltp":2.02,"tv":13.73,"id":19144236},{"batb":[[0,1.91,6],[1,1.9,49.27],[2,1.81,8.96]],"ltp":1.94,"tv":104.55,"id":19144241}]}]}
{"op":"mcm","clk":"11780404107","pt":1722865354482,"mc":[{"id":"1.231426403","rc":[{"batb":[[0,1.98,45.25],[1,1.97,31],[2,1.96,8.27]],"ltp":2.02,"tv":13.73,"id":19144236},{"batb":[[0,1.92,10],[1,1.91,6],[2,1.9,49.27]],"ltp":1.94,"tv":104.55,"id":19144241}]}]}
{"op":"mcm","clk":"11780404250","pt":1722865357750,"mc":[{"id":"1.231426403","rc":[{"batb":[[0,1.91,6],[1,1.9,49.27],[2,1.81,8.96]],"ltp":1.94,"tv":104.55,"id":19144241}]}]}
{"op":"mcm","clk":"11780404259","pt":1722865357963,"mc":[{"id":"1.231426403","rc":[{"batb":[[0,1.99,10],[1,1.98,45.25],[2,1.97,31]],"ltp":2.02,"tv":13.73,"id":19144236}]}]}
{"op":"mcm","clk":"11780404417","pt":1722865361644,"mc":[{"id":"1.231426403","rc":[{"batb":[[0,1.98,45.25],[1,1.97,31],[2,1.96,8.27]],"ltp":2.02,"tv":13.73,"id":19144236},{"batb":[[0,1.92,10],[1,1.91,6],[2,1.9,49.27]],"ltp":1.94,"tv":104.55,"id":19144241}]}]}
{"op":"mcm","clk":"11780404567","pt":1722865365162,"mc":[{"id":"1.231426403","rc":[{"batb":[[0,1.99,10],[1,1.98,45.25],[2,1.97,31]],"ltp":2.02,"tv":13.73,"id":19144236},{"batb":[[0,1.91,6],[1,1.9,49.27],[2,1.81,8.96]],"ltp":1.94,"tv":104.55,"id":19144241}]}]}
{"op":"mcm","clk":"11780404752","pt":1722865368582,"mc":[{"id":"1.231426403","rc":[{"batb":[[0,1.98,45.25],[1,1.97,31],[2,1.96,8.27]],"ltp":2.02,"tv":13.73,"id":19144236},{"batb":[[0,1.92,10],[1,1.91,6],[2,1.9,49.27]],"ltp":1.94,"tv":104.55,"id":19144241}]}]}
{"op":"mcm","clk":"11780404903","pt":1722865371777,"mc":[{"id":"1.231426403","rc":[{"batb":[[0,1.91,6],[1,1.9,49.27],[2,1.81,8.96]],"ltp":1.94,"tv":104.55,"id":19144241}]}]}
{"op":"mcm","clk":"11780404910","pt":1722865371982,"mc":[{"id":"1.231426403","rc":[{"batb":[[0,1.99,10],[1,1.98,45.25],[2,1.97,31]],"ltp":2.02,"tv":13.73,"id":19144236}]}]}
{"op":"mcm","clk":"11780405057","pt":1722865375386,"mc":[{"id":"1.231426403","rc":[{"batb":[[0,1.98,45.25],[1,1.97,31],[2,1.96,8.27]],"ltp":2.02,"tv":13.73,"id":19144236},{"batb":[[0,1.92,10],[1,1.91,6],[2,1.9,49.27]],"ltp":1.94,"tv":104.55,"id":19144241}]}]}
{"op":"mcm","clk":"11780405188","pt":1722865378790,"mc":[{"id":"1.231426403","rc":[{"batb":[[0,1.99,10],[1,1.98,45.25],[2,1.97,31]],"ltp":2.02,"tv":13.73,"id":19144236},{"batb":[[0,1.91,6],[1,1.9,49.27],[2,1.81,8.96]],"ltp":1.94,"tv":104.55,"id":19144241}]}]}
{"op":"mcm","clk":"11780405346","pt":1722865382388,"mc":[{"id":"1.231426403","rc":[{"batb":[[0,1.98,45.25],[1,1.97,31],[2,1.96,8.27]],"ltp":2.02,"tv":13.73,"id":19144236},{"batb":[[0,1.92,10],[1,1.91,6],[2,1.9,49.27]],"ltp":1.94,"tv":104.55,"id":19144241}]}]}
{"op":"mcm","clk":"11780405529","pt":1722865385775,"mc":[{"id":"1.231426403","rc":[{"batb":[[0,1.99,10],[1,1.98,45.25],[2,1.97,31]],"ltp":2.02,"tv":13.73,"id":19144236},{"batb":[[0,1.91,6],[1,1.9,49.27],[2,1.81,8.96]],"ltp":1.94,"tv":104.55,"id":19144241}]}]}
{"op":"mcm","clk":"11780405701","pt":1722865388799,"mc":[{"id":"1.231426403","rc":[{"batb":[[0,1.98,45.25],[1,1.97,31],[2,1.96,8.27]],"ltp":2.02,"tv":13.73,"id":19144236}]}]}
{"op":"mcm","clk":"11780405714","pt":1722865389010,"mc":[{"id":"1.231426403","rc":[{"batb":[[0,1.92,10],[1,1.91,6],[2,1.9,49.27]],"ltp":1.94,"tv":104.55,"id":19144241}]}]}
{"op":"mcm","clk":"11780405875","pt":1722865392392,"mc":[{"id":"1.231426403","rc":[{"batb":[[0,1.99,10],[1,1.98,45.25],[2,1.97,31]],"ltp":2.02,"tv":13.73,"id":19144236},{"batb":[[0,1.91,6],[1,1.9,49.27],[2,1.81,8.96]],"ltp":1.94,"tv":104.55,"id":19144241}]}]}
{"op":"mcm","clk":"11780406012","pt":1722865396090,"mc":[{"id":"1.231426403","rc":[{"batb":[[0,1.98,45.25],[1,1.97,31],[2,1.96,8.27]],"ltp":2.02,"tv":13.73,"id":19144236},{"batb":[[0,1.92,10],[1,1.91,6],[2,1.9,49.27]],"ltp":1.94,"tv":104.55,"id":19144241}]}]}
{"op":"mcm","clk":"11780406157","pt":1722865399633,"mc":[{"id":"1.231426403","rc":[{"batb":[[0,1.99,10],[1,1.98,45.25],[2,1.97,31]],"ltp":2.02,"tv":13.73,"id":19144236},{"batb":[[0,1.91,6],[1,1.9,49.27],[2,1.81,8.96]],"ltp":1.94,"tv":104.55,"id":19144241}]}]}
{"op":"mcm","clk":"11780406322","pt":1722865403199,"mc":[{"id":"1.231426403","rc":[{"batb":[[0,1.98,45.25],[1,1.97,31],[2,1.96,8.27]],"ltp":2.02,"tv":13.73,"id":19144236},{"batb":[[0,1.92,10],[1,1.91,6],[2,1.9,49.27]],"ltp":1.94,"tv":104.55,"id":19144241}]}]}
{"op":"mcm","clk":"11780406473","pt":1722865406822,"mc":[{"id":"1.231426403","rc":[{"batb":[[0,1.99,10],[1,1.98,45.25],[2,1.97,31]],"ltp":2.02,"tv":13.73,"id":19144236},{"batb":[[0,1.91,6],[1,1.9,49.27],[2,1.81,8.96]],"ltp":1.94,"tv":104.55,"id":19144241}]}]}
{"op":"mcm","clk":"11780406603","pt":1722865410129,"mc":[{"id":"1.231426403","rc":[{"batb":[[0,1.98,45.25],[1,1.97,31],[2,1.96,8.27]],"ltp":2.02,"tv":13.73,"id":19144236},{"batb":[[0,1.92,10],[1,1.91,6],[2,1.9,49.27]],"ltp":1.94,"tv":104.55,"id":19144241}]}]}
{"op":"mcm","clk":"11780406730","pt":1722865413407,"mc":[{"id":"1.231426403","rc":[{"batb":[[0,1.99,10],[1,1.98,45.25],[2,1.97,31]],"ltp":2.02,"tv":13.73,"id":19144236},{"batb":[[0,1.91,6],[1,1.9,49.27],[2,1.81,8.96]],"ltp":1.94,"tv":104.55,"id":19144241}]}]}
{"op":"mcm","clk":"11780406869","pt":1722865416707,"mc":[{"id":"1.231426403","rc":[{"batb":[[0,1.98,45.25],[1,1.97,31],[2,1.96,8.27]],"ltp":2.02,"tv":13.73,"id":19144236}]}]}
{"op":"mcm","clk":"11780406878","pt":1722865416915,"mc":[{"id":"1.231426403","rc":[{"batb":[[0,1.92,10],[1,1.91,6],[2,1.9,49.27]],"ltp":1.94,"tv":104.55,"id":19144241}]}]}
{"op":"mcm","clk":"11780406978","pt":1722865419516,"mc":[{"id":"1.231426403","rc":[{"batb":[[0,1.99,10],[1,1.98,45.25],[2,1.97,31]],"ltp":2.02,"tv":13.73,"id":19144236}]}]}
{"op":"mcm","clk":"11780407016","pt":1722865420238,"mc":[{"id":"1.231426403","rc":[{"batb":[[0,1.91,6],[1,1.9,49.27],[2,1.81,8.96]],"ltp":1.94,"tv":104.55,"id":19144241}]}]}
{"op":"mcm","clk":"11780407161","pt":1722865423038,"mc":[{"id":"1.231426403","rc":[{"batb":[[0,1.98,45.25],[1,1.97,31],[2,1.96,8.27]],"ltp":2.02,"tv":13.73,"id":19144236},{"batb":[[0,1.92,10],[1,1.91,6],[2,1.9,49.27]],"ltp":1.94,"tv":104.55,"id":19144241}]}]}
{"op":"mcm","clk":"11780407313","pt":1722865426536,"mc":[{"id":"1.231426403","rc":[{"batb":[[0,1.99,10],[1,1.98,45.25],[2,1.97,31]],"ltp":2.02,"tv":13.73,"id":19144236},{"batb":[[0,1.91,6],[1,1.9,49.27],[2,1.81,8.96]],"ltp":1.94,"tv":104.55,"id":19144241}]}]}
{"op":"mcm","clk":"11780407467","pt":1722865429899,"mc":[{"id":"1.231426403","rc":[{"batb":[[0,1.98,45.25],[1,1.97,31],[2,1.96,8.27]],"ltp":2.02,"tv":13.73,"id":19144236},{"batb":[[0,1.92,10],[1,1.91,6],[2,1.9,49.27]],"ltp":1.94,"tv":104.55,"id":19144241}]}]}
{"op":"mcm","clk":"11780407620","pt":1722865433218,"mc":[{"id":"1.231426403","rc":[{"batb":[[0,1.99,10],[1,1.98,45.25],[2,1.97,31]],"ltp":2.02,"tv":13.73,"id":19144236},{"batb":[[0,1.91,6],[1,1.9,49.27],[2,1.81,8.96]],"ltp":1.94,"tv":104.55,"id":19144241}]}]}
{"op":"mcm","clk":"11780407783","pt":1722865436643,"mc":[{"id":"1.231426403","rc":[{"batb":[[0,1.98,45.25],[1,1.97,31],[2,1.96,8.27]],"ltp":2.02,"tv":13.73,"id":19144236},{"batb":[[0,1.92,10],[1,1.91,6],[2,1.9,49.27]],"ltp":1.94,"tv":104.55,"id":19144241}]}]}
{"op":"mcm","clk":"11780407921","pt":1722865440120,"mc":[{"id":"1.231426403","rc":[{"batb":[[0,1.99,10],[1,1.98,45.25],[2,1.97,31]],"ltp":2.02,"tv":13.73,"id":19144236},{"batb":[[0,1.91,6],[1,1.9,49.27],[2,1.81,8.96]],"ltp":1.94,"tv":104.55,"id":19144241}]}]}
{"op":"mcm","clk":"11780408063","pt":1722865443553,"mc":[{"id":"1.231426403","rc":[{"batb":[[0,1.98,45.25],[1,1.97,31],[2,1.96,8.27]],"ltp":2.02,"tv":13.73,"id":19144236},{"batb":[[0,1.92,10],[1,1.91,6],[2,1.9,49.27]],"ltp":1.94,"tv":104.55,"id":19144241}]}]}
{"op":"mcm","clk":"11780408236","pt":1722865447039,"mc":[{"id":"1.231426403","rc":[{"batb":[[0,1.99,10],[1,1.98,45.25],[2,1.97,31]],"ltp":2.02,"tv":13.73,"id":19144236},{"batb":[[0,1.91,6],[1,1.9,49.27],[2,1.81,8.96]],"ltp":1.94,"tv":104.55,"id":19144241}]}]}
{"op":"mcm","clk":"11780408382","pt":1722865450459,"mc":[{"id":"1.231426403","rc":[{"batb":[[0,1.98,45.25],[1,1.97,31],[2,1.96,8.27]],"ltp":2.02,"tv":13.73,"id":19144236},{"batb":[[0,1.92,10],[1,1.91,6],[2,1.9,49.27]],"ltp":1.94,"tv":104.55,"id":19144241}]}]}
{"op":"mcm","clk":"11780408490","pt":1722865453761,"mc":[{"id":"1.231426403","rc":[{"batb":[[0,1.91,6],[1,1.9,49.27],[2,1.81,8.96]],"ltp":1.94,"tv":104.55,"id":19144241}]}]}
{"op":"mcm","clk":"11780408496","pt":1722865453928,"mc":[{"id":"1.231426403","rc":[{"batb":[[0,1.99,10],[1,1.98,45.25],[2,1.97,31]],"ltp":2.02,"tv":13.73,"id":19144236}]}]}
{"op":"mcm","clk":"11780408623","pt":1722865457437,"mc":[{"id":"1.231426403","rc":[{"batb":[[0,1.98,45.25],[1,1.97,31],[2,1.96,8.27]],"ltp":2.02,"tv":13.73,"id":19144236},{"batb":[[0,1.92,10],[1,1.91,6],[2,1.9,49.27]],"ltp":1.94,"tv":104.55,"id":19144241}]}]}
{"op":"mcm","clk":"11780408730","pt":1722865460732,"mc":[{"id":"1.231426403","rc":[{"batb":[[0,1.91,6],[1,1.9,49.27],[2,1.81,8.96]],"ltp":1.94,"tv":104.55,"id":19144241}]}]}
{"op":"mcm","clk":"11780408736","pt":1722865460942,"mc":[{"id":"1.231426403","rc":[{"batb":[[0,1.99,10],[1,1.98,45.25],[2,1.97,31]],"ltp":2.02,"tv":13.73,"id":19144236}]}]}
{"op":"mcm","clk":"11780408886","pt":1722865464457,"mc":[{"id":"1.231426403","rc":[{"batb":[[0,1.98,45.25],[1,1.97,31],[2,1.85,2]],"ltp":2.02,"tv":13.73,"id":19144236},{"batb":[[0,1.92,10],[1,1.91,6],[2,1.9,49.27]],"ltp":1.94,"tv":104.55,"id":19144241}]}]}
{"op":"mcm","clk":"11780408979","pt":1722865467742,"mc":[{"id":"1.231426403","rc":[{"batb":[[0,1.91,6],[1,1.9,49.27],[2,1.8,10]],"ltp":1.94,"tv":104.55,"id":19144241}]}]}
{"op":"mcm","clk":"11780408985","pt":1722865467949,"mc":[{"id":"1.231426403","rc":[{"batb":[[0,1.99,10],[1,1.98,45.25],[2,1.97,31]],"ltp":2.02,"tv":13.73,"id":19144236}]}]}
{"op":"mcm","clk":"11780409103","pt":1722865471450,"mc":[{"id":"1.231426403","rc":[{"batb":[[0,1.98,45.25],[1,1.97,31],[2,1.85,2]],"ltp":2.02,"tv":13.73,"id":19144236},{"batb":[[0,1.92,10],[1,1.91,6],[2,1.9,49.27]],"ltp":1.94,"tv":104.55,"id":19144241}]}]}
{"op":"mcm","clk":"11780409234","pt":1722865474747,"mc":[{"id":"1.231426403","rc":[{"batb":[[0,1.91,6],[1,1.9,49.27],[2,1.8,10]],"ltp":1.94,"tv":104.55,"id":19144241}]}]}
{"op":"mcm","clk":"11780409244","pt":1722865474954,"mc":[{"id":"1.231426403","rc":[{"batb":[[0,1.99,10],[1,1.98,45.25],[2,1.97,31]],"ltp":2.02,"tv":13.73,"id":19144236}]}]}
{"op":"mcm","clk":"11780409385","pt":1722865478574,"mc":[{"id":"1.231426403","rc":[{"batb":[[0,1.98,45.25],[1,1.97,31],[2,1.85,2]],"ltp":2.02,"tv":13.73,"id":19144236},{"batb":[[0,1.92,10],[1,1.91,6],[2,1.9,49.27]],"ltp":1.94,"tv":104.55,"id":19144241}]}]}
{"op":"mcm","clk":"11780409633","pt":1722865485082,"mc":[{"id":"1.231426403","rc":[{"batb":[[0,1.99,10],[1,1.98,45.25],[2,1.97,31]],"ltp":2.02,"tv":13.73,"id":19144236},{"batb":[[0,1.91,6],[1,1.9,49.27],[2,1.8,10]],"ltp":1.94,"tv":104.55,"id":19144241}]}]}
{"op":"mcm","clk":"11780409786","pt":1722865489062,"mc":[{"id":"1.231426403","rc":[{"batb":[[0,1.98,45.25],[1,1.97,31],[2,1.85,2]],"ltp":2.02,"tv":13.73,"id":19144236},{"batb":[[0,1.92,10],[1,1.91,6],[2,1.9,49.27]],"ltp":1.94,"tv":104.55,"id":19144241}]}]}
{"op":"mcm","clk":"11780409930","pt":1722865492579,"mc":[{"id":"1.231426403","rc":[{"batb":[[0,1.99,10],[1,1.98,45.25],[2,1.97,31]],"ltp":2.02,"tv":13.73,"id":19144236},{"batb":[[0,1.91,6],[1,1.9,49.27],[2,1.8,10]],"ltp":1.94,"tv":104.55,"id":19144241}]}]}
{"op":"mcm","clk":"11780410034","pt":1722865495685,"mc":[{"id":"1.231426403","rc":[{"batb":[[0,1.92,10],[1,1.91,6],[2,1.9,49.27]],"ltp":1.94,"tv":104.55,"id":19144241}]}]}
{"op":"mcm","clk":"11780410043","pt":1722865495898,"mc":[{"id":"1.231426403","rc":[{"batb":[[0,1.98,45.25],[1,1.97,31],[2,1.96,8.27]],"ltp":2.02,"tv":13.73,"id":19144236}]}]}
{"op":"mcm","clk":"11780410146","pt":1722865499402,"mc":[{"id":"1.231426403","rc":[{"batb":[[0,1.99,10],[1,1.98,45.25],[2,1.97,31]],"ltp":2.02,"tv":13.73,"id":19144236},{"batb":[[0,1.91,6],[1,1.9,49.27],[2,1.81,8.96]],"ltp":1.94,"tv":104.55,"id":19144241}]}]}
{"op":"mcm","clk":"11780410278","pt":1722865502704,"mc":[{"id":"1.231426403","rc":[{"batb":[[0,1.98,45.25],[1,1.97,31],[2,1.96,8.27]],"ltp":2.02,"tv":13.73,"id":19144236}]}]}
{"op":"mcm","clk":"11780410288","pt":1722865502900,"mc":[{"id":"1.231426403","rc":[{"batb":[[0,1.92,10],[1,1.91,6],[2,1.9,49.27]],"ltp":1.94,"tv":104.55,"id":19144241}]}]}
{"op":"mcm","clk":"11780410462","pt":1722865506390,"mc":[{"id":"1.231426403","rc":[{"batb":[[0,1.99,10],[1,1.98,45.25],[2,1.97,31]],"ltp":2.02,"tv":13.73,"id":19144236},{"batb":[[0,1.91,6],[1,1.9,49.27],[2,1.81,8.96]],"ltp":1.94,"tv":104.55,"id":19144241}]}]}
{"op":"mcm","clk":"11780410632","pt":1722865509700,"mc":[{"id":"1.231426403","rc":[{"batb":[[0,1.98,45.25],[1,1.97,31],[2,1.96,8.27]],"ltp":2.02,"tv":13.73,"id":19144236},{"batb":[[0,1.92,10],[1,1.91,6],[2,1.9,49.27]],"ltp":1.94,"tv":104.55,"id":19144241}]}]}
{"op":"mcm","clk":"11780410651","pt":1722865510014,"mc":[{"id":"1.231426403","rc":[{"batl":[[1,3.8,0]],"ltp":1.94,"tv":104.55,"id":19144241}]}]}
{"op":"mcm","clk":"11780410827","pt":1722865513408,"mc":[{"id":"1.231426403","rc":[{"batb":[[0,1.99,10],[1,1.98,45.25],[2,1.97,31]],"ltp":2.02,"tv":13.73,"id":19144236},{"batb":[[0,1.91,6],[1,1.9,49.27],[2,1.81,8.96]],"ltp":1.94,"tv":104.55,"id":19144241}]}]}
{"op":"mcm","clk":"11780410970","pt":1722865516725,"mc":[{"id":"1.231426403","rc":[{"batb":[[0,1.98,45.25],[1,1.97,31],[2,1.96,8.27]],"ltp":2.02,"tv":13.73,"id":19144236}]}]}
{"op":"mcm","clk":"11780410981","pt":1722865516911,"mc":[{"id":"1.231426403","rc":[{"batb":[[0,1.92,10],[1,1.91,6],[2,1.9,49.27]],"ltp":1.94,"tv":104.55,"id":19144241}]}]}
{"op":"mcm","clk":"11780411169","pt":1722865520429,"mc":[{"id":"1.231426403","rc":[{"batb":[[0,1.99,10],[1,1.98,45.25],[2,1.97,31]],"ltp":2.02,"tv":13.73,"id":19144236},{"batb":[[0,1.91,6],[1,1.9,49.27],[2,1.81,8.96]],"ltp":1.94,"tv":104.55,"id":19144241}]}]}
{"op":"mcm","clk":"11780411338","pt":1722865523718,"mc":[{"id":"1.231426403","rc":[{"batb":[[0,1.98,45.25],[1,1.97,31],[2,1.96,8.27]],"ltp":2.02,"tv":13.73,"id":19144236}]}]}
{"op":"mcm","clk":"11780411353","pt":1722865524016,"mc":[{"id":"1.231426403","rc":[{"batb":[[0,1.92,10],[1,1.91,6],[2,1.9,49.27]],"ltp":1.94,"tv":104.55,"id":19144241}]}]}
{"op":"mcm","clk":"11780411504","pt":1722865527534,"mc":[{"id":"1.231426403","rc":[{"batb":[[0,1.99,10],[1,1.98,45.25],[2,1.97,31]],"ltp":2.02,"tv":13.73,"id":19144236},{"batb":[[0,1.91,6],[1,1.9,49.27],[2,1.81,8.96]],"ltp":1.94,"tv":104.55,"id":19144241}]}]}
{"op":"mcm","clk":"11780411631","pt":1722865531012,"mc":[{"id":"1.231426403","rc":[{"batb":[[0,1.98,45.25],[1,1.97,31],[2,1.96,8.27]],"ltp":2.02,"tv":13.73,"id":19144236},{"batb":[[0,1.92,10],[1,1.91,6],[2,1.9,49.27]],"ltp":1.94,"tv":104.55,"id":19144241}]}]}
{"op":"mcm","clk":"11780411765","pt":1722865534739,"mc":[{"id":"1.231426403","rc":[{"batb":[[0,1.99,10],[1,1.98,45.25],[2,1.97,31]],"ltp":2.02,"tv":13.73,"id":19144236},{"batb":[[0,1.91,6],[1,1.9,49.27],[2,1.81,8.96]],"ltp":1.94,"tv":104.55,"id":19144241}]}]}
{"op":"mcm","clk":"11780411901","pt":1722865538141,"mc":[{"id":"1.231426403","rc":[{"batb":[[0,1.98,45.25],[1,1.97,31],[2,1.96,8.27]],"ltp":2.02,"tv":13.73,"id":19144236},{"batb":[[0,1.92,10],[1,1.91,6],[2,1.9,49.27]],"ltp":1.94,"tv":104.55,"id":19144241}]}]}
{"op":"mcm","clk":"11780412074","pt":1722865541635,"mc":[{"id":"1.231426403","rc":[{"batb":[[0,1.99,10],[1,1.98,45.25],[2,1.97,31]],"ltp":2.02,"tv":13.73,"id":19144236},{"batb":[[0,1.91,6],[1,1.9,49.27],[2,1.81,8.96]],"ltp":1.94,"tv":104.55,"id":19144241}]}]}
{"op":"mcm","clk":"11780412199","pt":1722865545251,"mc":[{"id":"1.231426403","rc":[{"batb":[[0,1.98,45.25],[1,1.97,31],[2,1.96,8.27]],"ltp":2.02,"tv":13.73,"id":19144236},{"batb":[[0,1.92,10],[1,1.91,6],[2,1.9,49.27]],"ltp":1.94,"tv":104.55,"id":19144241}]}]}
{"op":"mcm","clk":"11780412358","pt":1722865548731,"mc":[{"id":"1.231426403","rc":[{"batb":[[0,1.99,10],[1,1.98,45.25],[2,1.97,31]],"ltp":2.02,"tv":13.73,"id":19144236},{"batb":[[0,1.91,6],[1,1.9,49.27],[2,1.81,8.96]],"ltp":1.94,"tv":104.55,"id":19144241}]}]}
{"op":"mcm","clk":"11780412519","pt":1722865552344,"mc":[{"id":"1.231426403","rc":[{"batb":[[0,1.98,45.25],[1,1.97,31],[2,1.96,8.27]],"ltp":2.02,"tv":13.73,"id":19144236},{"batb":[[0,1.92,10],[1,1.91,6],[2,1.9,49.27]],"ltp":1.94,"tv":104.55,"id":19144241}]}]}
{"op":"mcm","clk":"11780412642","pt":1722865555768,"mc":[{"id":"1.231426403","rc":[{"batb":[[0,1.99,10],[1,1.98,45.25],[2,1.97,31]],"ltp":2.02,"tv":13.73,"id":19144236},{"batb":[[0,1.91,6],[1,1.9,49.27],[2,1.8,10]],"ltp":1.94,"tv":104.55,"id":19144241}]}]}
{"op":"mcm","clk":"11780412773","pt":1722865558725,"mc":[{"id":"1.231426403","rc":[{"batb":[[0,1.98,45.25],[1,1.97,31],[2,1.85,2]],"ltp":2.02,"tv":13.73,"id":19144236},{"batb":[[0,1.92,10],[1,1.91,6],[2,1.9,49.27]],"ltp":1.94,"tv":104.55,"id":19144241}]}]}
{"op":"mcm","clk":"11780412919","pt":1722865561740,"mc":[{"id":"1.231426403","rc":[{"batb":[[0,1.99,10],[1,1.98,45.25],[2,1.97,31]],"ltp":2.02,"tv":13.73,"id":19144236},{"batb":[[0,1.91,6],[1,1.9,49.27],[2,1.8,10]],"ltp":1.94,"tv":104.55,"id":19144241}]}]}
{"op":"mcm","clk":"11780413075","pt":1722865565364,"mc":[{"id":"1.231426403","rc":[{"batb":[[0,1.98,45.25],[1,1.97,31],[2,1.85,2]],"ltp":2.02,"tv":13.73,"id":19144236},{"batb":[[0,1.92,10],[1,1.91,6],[2,1.9,49.27]],"ltp":1.94,"tv":104.55,"id":19144241}]}]}
{"op":"mcm","clk":"11780413210","pt":1722865568649,"mc":[{"id":"1.231426403","rc":[{"batb":[[0,1.91,6],[1,1.9,49.27],[2,1.8,10]],"ltp":1.94,"tv":104.55,"id":19144241}]}]}
{"op":"mcm","clk":"11780413217","pt":1722865568852,"mc":[{"id":"1.231426403","rc":[{"batb":[[0,1.99,10],[1,1.98,45.25],[2,1.97,31]],"ltp":2.02,"tv":13.73,"id":19144236}]}]}
{"op":"mcm","clk":"11780413378","pt":1722865572372,"mc":[{"id":"1.231426403","rc":[{"batb":[[0,1.98,45.25],[1,1.97,31],[2,1.85,2]],"ltp":2.02,"tv":13.73,"id":19144236},{"batb":[[0,1.92,10],[1,1.91,6],[2,1.9,49.27]],"ltp":1.94,"tv":104.55,"id":19144241}]}]}
{"op":"mcm","clk":"11780413513","pt":1722865575680,"mc":[{"id":"1.231426403","rc":[{"batb":[[0,1.91,6],[1,1.9,49.27],[2,1.8,10]],"ltp":1.94,"tv":104.55,"id":19144241}]}]}
{"op":"mcm","clk":"11780413521","pt":1722865575879,"mc":[{"id":"1.231426403","rc":[{"batb":[[0,1.99,10],[1,1.98,45.25],[2,1.97,31]],"ltp":2.02,"tv":13.73,"id":19144236}]}]}
{"op":"mcm","clk":"11780413694","pt":1722865579360,"mc":[{"id":"1.231426403","rc":[{"batb":[[0,1.98,45.25],[1,1.97,31],[2,1.85,2]],"ltp":2.02,"tv":13.73,"id":19144236},{"batb":[[0,1.92,10],[1,1.91,6],[2,1.9,49.27]],"ltp":1.94,"tv":104.55,"id":19144241}]}]}
{"op":"mcm","clk":"11780413840","pt":1722865582665,"mc":[{"id":"1.231426403","rc":[{"batb":[[0,1.91,6],[1,1.9,49.27],[2,1.8,10]],"ltp":1.94,"tv":104.55,"id":19144241}]}]}
{"op":"mcm","clk":"11780413852","pt":1722865582868,"mc":[{"id":"1.231426403","rc":[{"batb":[[0,1.99,10],[1,1.98,45.25],[2,1.97,31]],"ltp":2.02,"tv":13.73,"id":19144236}]}]}
{"op":"mcm","clk":"11780413991","pt":1722865586389,"mc":[{"id":"1.231426403","rc":[{"batb":[[0,1.98,45.25],[1,1.97,31],[2,1.85,2]],"ltp":2.02,"tv":13.73,"id":19144236},{"batb":[[0,1.92,10],[1,1.91,6],[2,1.9,49.27]],"ltp":1.94,"tv":104.55,"id":19144241}]}]}
{"op":"mcm","clk":"11780414144","pt":1722865589760,"mc":[{"id":"1.231426403","rc":[{"batb":[[0,1.91,6],[1,1.9,49.27],[2,1.8,10]],"ltp":1.94,"tv":104.55,"id":19144241}]}]}
{"op":"mcm","clk":"11780414151","pt":1722865589864,"mc":[{"id":"1.231426403","rc":[{"batb":[[0,1.99,10],[1,1.98,45.25],[2,1.97,31]],"ltp":2.02,"tv":13.73,"id":19144236}]}]}
{"op":"mcm","clk":"11780414327","pt":1722865593484,"mc":[{"id":"1.231426403","rc":[{"batb":[[0,1.98,45.25],[1,1.97,31],[2,1.85,2]],"ltp":2.02,"tv":13.73,"id":19144236},{"batb":[[0,1.92,10],[1,1.91,6],[2,1.9,49.27]],"ltp":1.94,"tv":104.55,"id":19144241}]}]}
{"op":"mcm","clk":"11780414480","pt":1722865596770,"mc":[{"id":"1.231426403","rc":[{"batb":[[0,1.91,6],[1,1.9,49.27],[2,1.8,10]],"ltp":1.94,"tv":104.55,"id":19144241}]}]}
{"op":"mcm","clk":"11780414490","pt":1722865596982,"mc":[{"id":"1.231426403","rc":[{"batb":[[0,1.99,10],[1,1.98,45.25],[2,1.97,31]],"ltp":2.02,"tv":13.73,"id":19144236}]}]}
{"op":"mcm","clk":"11780414628","pt":1722865600303,"mc":[{"id":"1.231426403","rc":[{"batb":[[0,1.98,45.25],[1,1.97,31],[2,1.85,2]],"ltp":2.02,"tv":13.73,"id":19144236},{"batb":[[0,1.92,10],[1,1.91,6],[2,1.9,49.27]],"ltp":1.94,"tv":104.55,"id":19144241}]}]}
{"op":"mcm","clk":"11780414763","pt":1722865603671,"mc":[{"id":"1.231426403","rc":[{"batb":[[0,1.99,10],[1,1.98,45.25],[2,1.97,31]],"ltp":2.02,"tv":13.73,"id":19144236},{"batb":[[0,1.91,6],[1,1.9,49.27],[2,1.8,10]],"ltp":1.94,"tv":104.55,"id":19144241}]}]}
{"op":"mcm","clk":"11780414906","pt":1722865607404,"mc":[{"id":"1.231426403","rc":[{"batb":[[0,1.98,45.25],[1,1.97,31],[2,1.85,2]],"ltp":2.02,"tv":13.73,"id":19144236},{"batb":[[0,1.92,10],[1,1.91,6],[2,1.9,49.27]],"ltp":1.94,"tv":104.55,"id":19144241}]}]}
{"op":"mcm","clk":"11780415056","pt":1722865610679,"mc":[{"id":"1.231426403","rc":[{"batb":[[0,1.91,6],[1,1.9,49.27],[2,1.8,10]],"ltp":1.94,"tv":104.55,"id":19144241}]}]}
{"op":"mcm","clk":"11780415071","pt":1722865610990,"mc":[{"id":"1.231426403","rc":[{"batb":[[0,1.99,10],[1,1.98,45.25],[2,1.97,31]],"ltp":2.02,"tv":13.73,"id":19144236}]}]}
{"op":"mcm","clk":"11780415262","pt":1722865614515,"mc":[{"id":"1.231426403","rc":[{"batb":[[0,1.98,45.25],[1,1.97,31],[2,1.85,2]],"ltp":2.02,"tv":13.73,"id":19144236},{"batb":[[0,1.92,10],[1,1.91,6],[2,1.9,49.27]],"ltp":1.94,"tv":104.55,"id":19144241}]}]}
{"op":"mcm","clk":"11780415326","pt":1722865616012,"mc":[{"id":"1.231426403","rc":[{"batb":[[2,1.96,8.27]],"ltp":2.02,"tv":13.73,"id":19144236}]}]}
{"op":"mcm","clk":"11780415404","pt":1722865617823,"mc":[{"id":"1.231426403","rc":[{"batb":[[0,1.91,6],[1,1.9,49.27],[2,1.81,8.96]],"ltp":1.94,"tv":104.55,"id":19144241}]}]}
{"op":"mcm","clk":"11780415408","pt":1722865617877,"mc":[{"id":"1.231426403","rc":[{"batb":[[0,1.99,10],[1,1.98,45.25],[2,1.97,31]],"ltp":2.02,"tv":13.73,"id":19144236}]}]}
{"op":"mcm","clk":"11780415552","pt":1722865621506,"mc":[{"id":"1.231426403","rc":[{"batb":[[0,1.98,45.25],[1,1.97,31],[2,1.96,8.27]],"ltp":2.02,"tv":13.73,"id":19144236},{"batb":[[0,1.92,10],[1,1.91,6],[2,1.9,49.27]],"ltp":1.94,"tv":104.55,"id":19144241}]}]}
{"op":"mcm","clk":"11780415703","pt":1722865625087,"mc":[{"id":"1.231426403","rc":[{"batb":[[0,1.99,10],[1,1.98,45.25],[2,1.97,31]],"ltp":2.02,"tv":13.73,"id":19144236},{"batb":[[0,1.91,6],[1,1.9,49.27],[2,1.81,8.96]],"ltp":1.94,"tv":104.55,"id":19144241}]}]}
{"op":"mcm","clk":"11780415830","pt":1722865628502,"mc":[{"id":"1.231426403","rc":[{"batb":[[0,1.98,45.25],[1,1.97,31],[2,1.96,8.27]],"ltp":2.02,"tv":13.73,"id":19144236},{"batb":[[0,1.92,10],[1,1.91,6],[2,1.9,49.27]],"ltp":1.94,"tv":104.55,"id":19144241}]}]}
{"op":"mcm","clk":"11780415970","pt":1722865632118,"mc":[{"id":"1.231426403","rc":[{"batb":[[0,1.99,10],[1,1.98,45.25],[2,1.97,31]],"ltp":2.02,"tv":13.73,"id":19144236},{"batb":[[0,1.91,6],[1,1.9,49.27],[2,1.81,8.96]],"ltp":1.94,"tv":104.55,"id":19144241}]}]}
{"op":"mcm","clk":"11780416089","pt":1722865635424,"mc":[{"id":"1.231426403","rc":[{"batb":[[0,1.98,45.25],[1,1.97,31],[2,1.96,8.27]],"batl":[[0,2.24,30.07],[1,2.54,4.04],[2,2.54,0]],"ltp":2.02,"tv":13.73,"id":19144236},{"batb":[[0,1.92,10],[1,1.91,6],[2,1.9,49.27]],"ltp":1.94,"tv":104.55,"id":19144241}]}]}
{"op":"mcm","clk":"11780416188","pt":1722865637695,"mc":[{"id":"1.231426403","rc":[{"batl":[[0,2.22,1.01],[1,2.24,30.07],[2,2.54,4.04]],"ltp":2.02,"tv":13.73,"id":19144236}]}]}
{"op":"mcm","clk":"11780416230","pt":1722865638726,"mc":[{"id":"1.231426403","rc":[{"batb":[[0,1.99,10],[1,1.98,45.25],[2,1.97,31]],"ltp":2.02,"tv":13.73,"id":19144236},{"batb":[[0,1.91,6],[1,1.9,49.27],[2,1.81,8.96]],"ltp":1.94,"tv":104.55,"id":19144241}]}]}
{"op":"mcm","clk":"11780416347","pt":1722865641505,"mc":[{"id":"1.231426403","rc":[{"batb":[[0,1.98,45.25],[1,1.97,31],[2,1.96,8.27]],"ltp":2.02,"tv":13.73,"id":19144236},{"batb":[[0,1.92,10],[1,1.91,6],[2,1.9,49.27]],"ltp":1.94,"tv":104.55,"id":19144241}]}]}
{"op":"mcm","clk":"11780416510","pt":1722865644805,"mc":[{"id":"1.231426403","rc":[{"batb":[[0,1.91,6],[1,1.9,49.27],[2,1.81,8.96]],"ltp":1.94,"tv":104.55,"id":19144241}]}]}
{"op":"mcm","clk":"11780416519","pt":1722865645008,"mc":[{"id":"1.231426403","rc":[{"batb":[[0,1.99,10],[1,1.98,45.25],[2,1.97,31]],"ltp":2.02,"tv":13.73,"id":19144236}]}]}
{"op":"mcm","clk":"11780416669","pt":1722865648553,"mc":[{"id":"1.231426403","rc":[{"batb":[[0,1.98,45.25],[1,1.97,31],[2,1.96,8.27]],"ltp":2.02,"tv":13.73,"id":19144236},{"batb":[[0,1.92,10],[1,1.91,6],[2,1.9,49.27]],"ltp":1.94,"tv":104.55,"id":19144241}]}]}
{"op":"mcm","clk":"11780416839","pt":1722865652060,"mc":[{"id":"1.231426403","rc":[{"batb":[[0,1.99,10],[1,1.98,45.25],[2,1.97,31]],"ltp":2.02,"tv":13.73,"id":19144236},{"batb":[[0,1.91,6],[1,1.9,49.27],[2,1.81,8.96]],"ltp":1.94,"tv":104.55,"id":19144241}]}]}
{"op":"mcm","clk":"11780417000","pt":1722865655525,"mc":[{"id":"1.231426403","rc":[{"batb":[[0,1.98,45.25],[1,1.97,31],[2,1.96,8.27]],"ltp":2.02,"tv":13.73,"id":19144236},{"batb":[[0,1.92,10],[1,1.91,6],[2,1.9,49.27]],"ltp":1.94,"tv":104.55,"id":19144241}]}]}
{"op":"mcm","clk":"11780417139","pt":1722865658824,"mc":[{"id":"1.231426403","rc":[{"batb":[[0,1.91,6],[1,1.9,49.27],[2,1.81,8.96]],"ltp":1.94,"tv":104.55,"id":19144241}]}]}
{"op":"mcm","clk":"11780417148","pt":1722865659027,"mc":[{"id":"1.231426403","rc":[{"batb":[[0,1.99,10],[1,1.98,45.25],[2,1.97,31]],"ltp":2.02,"tv":13.73,"id":19144236}]}]}
{"op":"mcm","clk":"11780417314","pt":1722865662548,"mc":[{"id":"1.231426403","rc":[{"batb":[[0,1.98,45.25],[1,1.97,31],[2,1.85,2]],"ltp":2.02,"tv":13.73,"id":19144236},{"batb":[[0,1.92,10],[1,1.91,6],[2,1.9,49.27]],"ltp":1.94,"tv":104.55,"id":19144241}]}]}
{"op":"mcm","clk":"11780417483","pt":1722865666060,"mc":[{"id":"1.231426403","rc":[{"batb":[[0,1.99,10],[1,1.98,45.25],[2,1.97,31]],"ltp":2.02,"tv":13.73,"id":19144236},{"batb":[[0,1.91,6],[1,1.9,49.27],[2,1.8,10]],"ltp":1.94,"tv":104.55,"id":19144241}]}]}
{"op":"mcm","clk":"11780417636","pt":1722865669542,"mc":[{"id":"1.231426403","rc":[{"batb":[[0,1.98,45.25],[1,1.97,31],[2,1.85,2]],"ltp":2.02,"tv":13.73,"id":19144236},{"batb":[[0,1.92,10],[1,1.91,6],[2,1.9,49.27]],"ltp":1.94,"tv":104.55,"id":19144241}]}]}
{"op":"mcm","clk":"11780417769","pt":1722865673054,"mc":[{"id":"1.231426403","rc":[{"batb":[[0,1.99,10],[1,1.98,45.25],[2,1.97,31]],"ltp":2.02,"tv":13.73,"id":19144236},{"batb":[[0,1.91,6],[1,1.9,49.27],[2,1.8,10]],"ltp":1.94,"tv":104.55,"id":19144241}]}]}
{"op":"mcm","clk":"11780417927","pt":1722865676466,"mc":[{"id":"1.231426403","rc":[{"batb":[[0,1.98,45.25],[1,1.97,31],[2,1.85,2]],"ltp":2.02,"tv":13.73,"id":19144236},{"batb":[[0,1.92,10],[1,1.91,6],[2,1.9,49.27]],"ltp":1.94,"tv":104.55,"id":19144241}]}]}
{"op":"mcm","clk":"11780418091","pt":1722865679980,"mc":[{"id":"1.231426403","rc":[{"batb":[[0,1.99,10],[1,1.98,45.25],[2,1.97,31]],"ltp":2.02,"tv":13.73,"id":19144236},{"batb":[[0,1.91,6],[1,1.9,49.27],[2,1.8,10]],"ltp":1.94,"tv":104.55,"id":19144241}]}]}
{"op":"mcm","clk":"11780418275","pt":1722865683570,"mc":[{"id":"1.231426403","rc":[{"batb":[[0,1.98,45.25],[1,1.97,31],[2,1.85,2]],"ltp":2.02,"tv":13.73,"id":19144236},{"batb":[[0,1.92,10],[1,1.91,6],[2,1.9,49.27]],"ltp":1.94,"tv":104.55,"id":19144241}]}]}
{"op":"mcm","clk":"11780418446","pt":1722865687195,"mc":[{"id":"1.231426403","rc":[{"batb":[[0,1.99,10],[1,1.98,45.25],[2,1.97,31]],"ltp":2.02,"tv":13.73,"id":19144236},{"batb":[[0,1.91,6],[1,1.9,49.27],[2,1.8,10]],"ltp":1.94,"tv":104.55,"id":19144241}]}]}
{"op":"mcm","clk":"11780418636","pt":1722865690825,"mc":[{"id":"1.231426403","rc":[{"batb":[[0,1.98,45.25],[1,1.97,31],[2,1.85,2]],"ltp":2.02,"tv":13.73,"id":19144236},{"batb":[[0,1.92,10],[1,1.91,6],[2,1.9,49.27]],"ltp":1.94,"tv":104.55,"id":19144241}]}]}
{"op":"mcm","clk":"11780418762","pt":1722865694773,"mc":[{"id":"1.231426403","rc":[{"batb":[[0,1.99,10],[1,1.98,45.25],[2,1.97,31]],"ltp":2.02,"tv":13.73,"id":19144236},{"batb":[[0,1.91,6],[1,1.9,49.27],[2,1.81,8.96]],"ltp":1.94,"tv":104.55,"id":19144241}]}]}
{"op":"mcm","clk":"11780418830","pt":1722865697667,"mc":[{"id":"1.231426403","rc":[{"batb":[[0,1.98,45.25],[1,1.97,31],[2,1.96,8.27]],"ltp":2.02,"tv":13.73,"id":19144236}]}]}
{"op":"mcm","clk":"11780418839","pt":1722865697871,"mc":[{"id":"1.231426403","rc":[{"batb":[[0,1.92,10],[1,1.91,6],[2,1.9,49.27]],"ltp":1.94,"tv":104.55,"id":19144241}]}]}
{"op":"mcm","clk":"11780418958","pt":1722865701383,"mc":[{"id":"1.231426403","rc":[{"batb":[[0,1.99,10],[1,1.98,45.25],[2,1.97,31]],"ltp":2.02,"tv":13.73,"id":19144236},{"batb":[[0,1.91,6],[1,1.9,49.27],[2,1.81,8.96]],"ltp":1.94,"tv":104.55,"id":19144241}]}]}
{"op":"mcm","clk":"11780419055","pt":1722865704798,"mc":[{"id":"1.231426403","rc":[{"batb":[[0,1.98,45.25],[1,1.97,31],[2,1.96,8.27]],"ltp":2.02,"tv":13.73,"id":19144236},{"batb":[[0,1.92,10],[1,1.91,6],[2,1.9,49.27]],"ltp":1.94,"tv":104.55,"id":19144241}]}]}
{"op":"mcm","clk":"11780419143","pt":1722865708275,"mc":[{"id":"1.231426403","rc":[{"batb":[[0,1.99,10],[1,1.98,45.25],[2,1.97,31]],"ltp":2.02,"tv":13.73,"id":19144236},{"batb":[[0,1.91,6],[1,1.9,49.27],[2,1.81,8.96]],"ltp":1.94,"tv":104.55,"id":19144241}]}]}
{"op":"mcm","clk":"11780419236","pt":1722865711793,"mc":[{"id":"1.231426403","rc":[{"batb":[[0,1.98,45.25],[1,1.97,31],[2,1.96,8.27]],"ltp":2.02,"tv":13.73,"id":19144236},{"batb":[[0,1.92,10],[1,1.91,6],[2,1.9,49.27]],"ltp":1.94,"tv":104.55,"id":19144241}]}]}
