{"op":"mcm","clk":"11801853018","pt":1722680415433,"mc":[{"id":"1.231398046","marketDefinition":{"bspMarket":false,"turnInPlayEnabled":true,"persistenceEnabled":true,"marketBaseRate":5.0,"eventId":"33465104","eventTypeId":"4","numberOfWinners":1,"bettingType":"ODDS","marketType":"MATCH_ODDS","marketTime":"2024-08-05T14:00:00.000Z","suspendTime":"2024-08-05T14:00:00.000Z","bspReconciled":false,"complete":true,"inPlay":false,"crossMatching":true,"runnersVoidable":false,"numberOfActiveRunners":2,"betDelay":0,"status":"OPEN","runners":[{"status":"ACTIVE","sortPriority":1,"id":40096581,"name":"Welsh Fire Women"},{"status":"ACTIVE","sortPriority":2,"id":40096579,"name":"Southern Brave Women"}],"regulators":["MR_INT"],"countryCode":"GB","discountAllowed":false,"timezone":"GMT","openDate":"2024-08-05T14:00:00.000Z","version":6053011875,"name":"Match Odds","eventName":"Welsh Fire Women v Southern Brave Women"},"rc":[{"batb":[[0,1.03,200],[1,1.02,200],[2,1.01,220]],"ltp":0.0,"tv":0.0,"id":40096579},{"batb":[[0,1.03,200],[1,1.02,200],[2,1.01,220]],"ltp":0.0,"tv":0.0,"id":40096581}]}]}
{"op":"mcm","clk":"11801853171","pt":1722680416529,"mc":[{"id":"1.231398046","marketDefinition":{"bspMarket":false,"turnInPlayEnabled":true,"persistenceEnabled":true,"marketBaseRate":5.0,"eventId":"33465104","eventTypeId":"4","numberOfWinners":1,"bettingType":"ODDS","marketType":"MATCH_ODDS","marketTime":"2024-08-05T14:00:00.000Z","suspendTime":"2024-08-05T14:00:00.000Z","bspReconciled":false,"complete":true,"inPlay":false,"crossMatching":true,"runnersVoidable":false,"numberOfActiveRunners":2,"betDelay":0,"status":"OPEN","runners":[{"status":"ACTIVE","sortPriority":1,"id":40096581,"name":"Welsh Fire Women"},{"status":"ACTIVE","sortPriority":2,"id":40096579,"name":"Southern Brave Women"}],"regulators":["MR_INT"],"countryCode":"GB","discountAllowed":true,"timezone":"GMT","openDate":"2024-08-05T14:00:00.000Z","version":6053011875,"name":"Match Odds","eventName":"Welsh Fire Women v Southern Brave Women"}}]}
{"op":"mcm","clk":"11802075228","pt":1722681968076,"mc":[{"id":"1.231398046","rc":[{"batb":[[0,1.25,100],[1,1.03,200],[2,1.02,200]],"ltp":0.0,"tv":0.0,"id":40096579},{"batb":[[0,1.25,100],[1,1.03,200],[2,1.02,200]],"ltp":0.0,"tv":0.0,"id":40096581}]}]}
{"op":"mcm","clk":"11802493068","pt":1722684929133,"mc":[{"id":"1.231398046","rc":[{"batb":[[1,1.1,25000],[2,1.09,25000]],"ltp":0.0,"tv":0.0,"id":40096579},{"batb":[[1,1.1,25000],[2,1.09,25000]],"ltp":0.0,"tv":0.0,"id":40096581}]}]}
{"op":"mcm","clk":"11802494839","pt":1722684940342,"mc":[{"id":"1.231398046","rc":[{"batb":[[1,1.08,25000],[2,1.07,25000]],"ltp":0.0,"tv":0.0,"id":40096581}]}]}
{"op":"mcm","clk":"11802494991","pt":1722684941351,"mc":[{"id":"1.231398046","rc":[{"batb":[[1,1.06,15000],[2,1.05,25000]],"ltp":0.0,"tv":0.0,"id":40096581}]}]}
{"op":"mcm","clk":"11802495151","pt":1722684942349,"mc":[{"id":"1.231398046","rc":[{"batb":[[1,1.05,10000],[2,1.04,25000]],"ltp":0.0,"tv":0.0,"id":40096581}]}]}
{"op":"mcm","clk":"11802495183","pt":1722684942548,"mc":[{"id":"1.231398046","rc":[{"batb":[[1,1.04,25000],[2,1.03,25200]],"ltp":0.0,"tv":0.0,"id":40096581}]}]}
{"op":"mcm","clk":"11802495836","pt":1722684946466,"mc":[{"id":"1.231398046","rc":[{"batb":[[1,1.08,25000],[2,1.07,25000]],"ltp":0.0,"tv":0.0,"id":40096579}]}]}
{"op":"mcm","clk":"11802495969","pt":1722684947357,"mc":[{"id":"1.231398046","rc":[{"batb":[[1,1.07,10000],[2,1.06,25000]],"ltp":0.0,"tv":0.0,"id":40096579}]}]}
{"op":"mcm","clk":"11802496068","pt":1722684948162,"mc":[{"id":"1.231398046","rc":[{"batb":[[1,1.06,25000],[2,1.04,25000]],"ltp":0.0,"tv":0.0,"id":40096579}]}]}
{"op":"mcm","clk":"11802496317","pt":1722684949852,"mc":[{"id":"1.231398046","rc":[{"batb":[[1,1.04,25000],[2,1.03,25200]],"ltp":0.0,"tv":0.0,"id":40096579}]}]}
{"op":"mcm","clk":"11803009265","pt":1722688272322,"mc":[{"id":"1.231398046","rc":[{"batb":[[2,1.03,25200.78]],"ltp":0.0,"tv":0.0,"id":40096579},{"batb":[[2,1.03,25200.78]],"ltp":0.0,"tv":0.0,"id":40096581}]}]}
{"op":"mcm","clk":"11803011045","pt":1722688283960,"mc":[{"id":"1.231398046","rc":[{"batb":[[1,1.04,25000.78]],"ltp":0.0,"tv":0.0,"id":40096579},{"batb":[[1,1.04,25000.78]],"ltp":0.0,"tv":0.0,"id":40096581}]}]}
{"op":"mcm","clk":"11803012914","pt":1722688297333,"mc":[{"id":"1.231398046","rc":[{"batb":[[1,1.04,25001.56]],"ltp":0.0,"tv":0.0,"id":40096579},{"batb":[[1,1.04,25001.56]],"ltp":0.0,"tv":0.0,"id":40096581}]}]}
{"op":"mcm","clk":"11803014805","pt":1722688311664,"mc":[{"id":"1.231398046","rc":[{"batl":[[0,5,0.78]],"ltp":0.0,"tv":0.0,"id":40096579},{"batl":[[0,5,0.78]],"ltp":0.0,"tv":0.0,"id":40096581}]}]}
{"op":"mcm","clk":"11803015934","pt":1722688320601,"mc":[{"id":"1.231398046","rc":[{"batl":[[0,6,1.56]],"ltp":0.0,"tv":0.0,"id":40096579},{"batl":[[0,6,1.56]],"ltp":0.0,"tv":0.0,"id":40096581}]}]}
{"op":"mcm","clk":"11803017032","pt":1722688329185,"mc":[{"id":"1.231398046","rc":[{"batl":[[1,8,0.78]],"ltp":0.0,"tv":0.0,"id":40096579},{"batl":[[1,8,0.78]],"ltp":0.0,"tv":0.0,"id":40096581}]}]}
{"op":"mcm","clk":"11803611560","pt":1722691902200,"mc":[{"id":"1.231398046","rc":[{"batb":[[2,1.03,25208.59]],"ltp":0.0,"tv":0.0,"id":40096579},{"batb":[[2,1.03,25208.59]],"ltp":0.0,"tv":0.0,"id":40096581}]}]}
{"op":"mcm","clk":"11806583539","pt":1722705001255,"mc":[{"id":"1.231398046","rc":[{"batb":[[0,1.86,46.96],[1,1.25,100],[2,1.04,25001.56]],"ltp":0.0,"tv":0.0,"id":40096579},{"batb":[[0,2.06,38.1],[1,1.25,100],[2,1.04,25001.56]],"ltp":0.0,"tv":0.0,"id":40096581}]}]}
{"op":"mcm","clk":"11807504082","pt":1722709877357,"mc":[{"id":"1.231398046","rc":[{"batb":[[1,1.74,17.32],[2,1.25,100]],"ltp":0.0,"tv":0.0,"id":40096579},{"batb":[[1,1.74,17.32],[2,1.25,100]],"ltp":0.0,"tv":0.0,"id":40096581}]}]}
{"op":"mcm","clk":"11810516760","pt":1722742586508,"mc":[{"id":"1.231398046","rc":[{"batb":[[0,1.74,17.32],[1,1.25,100],[2,1.04,25001.56]],"ltp":0.0,"tv":0.0,"id":40096579},{"batb":[[0,1.74,17.32],[1,1.25,100],[2,1.04,25001.56]],"ltp":0.0,"tv":0.0,"id":40096581}]}]}
{"op":"mcm","clk":"11810614187","pt":1722744745928,"mc":[{"id":"1.231398046","rc":[{"batb":[[0,1.86,46.96],[1,1.74,17.32],[2,1.25,100]],"ltp":0.0,"tv":0.0,"id":40096579},{"batb":[[0,2.06,38.1],[1,1.74,17.32],[2,1.25,100]],"ltp":0.0,"tv":0.0,"id":40096581}]}]}
{"op":"mcm","clk":"11810720644","pt":1722748928689,"mc":[{"id":"1.231398046","rc":[{"batb":[[1,1.8,222],[2,1.74,17.32]],"ltp":0.0,"tv":0.0,"id":40096581}]}]}
{"op":"mcm","clk":"11810720979","pt":1722748941883,"mc":[{"id":"1.231398046","rc":[{"batb":[[2,1.72,333]],"ltp":0.0,"tv":0.0,"id":40096579}]}]}
{"op":"mcm","clk":"11810785409","pt":1722751652444,"mc":[{"id":"1.231398046","rc":[{"trd":[[2.06,5.6]],"ltp":2.06,"tv":5.6,"id":40096581}],"tv":5.6}]}
{"op":"mcm","clk":"11810791938","pt":1722752005047,"mc":[{"id":"1.231398046","rc":[{"batl":[[0,1.94,2],[1,6,1.56],[2,8,0.78]],"ltp":0.0,"tv":0.0,"id":40096579}]}]}
{"op":"mcm","clk":"11811880085","pt":1722770951784,"mc":[{"id":"1.231398046","rc":[{"batb":[[0,1.74,17.32],[1,1.72,333],[2,1.7,10]],"ltp":0.0,"tv":0.0,"id":40096579},{"batb":[[0,1.8,222],[1,1.74,17.32],[2,1.7,10]],"ltp":2.06,"tv":5.6,"id":40096581}]}]}
{"op":"mcm","clk":"11811966710","pt":1722771754003,"mc":[{"id":"1.231398046","rc":[{"batb":[[0,1.81,10.99],[1,1.8,222],[2,1.74,17.32]],"ltp":2.06,"tv":5.6,"id":40096581}]}]}
{"op":"mcm","clk":"11812028631","pt":1722772342170,"mc":[{"id":"1.231398046","rc":[{"batl":[[1,2.24,8.68],[2,6,1.56]],"ltp":0.0,"tv":0.0,"id":40096579}]}]}
{"op":"mcm","clk":"11812072895","pt":1722772803409,"mc":[{"id":"1.231398046","rc":[{"trd":[[1.94,0.83]],"batl":[[0,1.94,1.17]],"ltp":1.94,"tv":0.83,"id":40096579},{"trd":[[2.06,6.38]],"ltp":2.06,"tv":6.37,"id":40096581}],"tv":7.2}]}
{"op":"mcm","clk":"11812178310","pt":1722773637333,"mc":[{"id":"1.231398046","rc":[{"batb":[[0,1.86,46.96],[1,1.74,17.32],[2,1.72,333]],"ltp":1.94,"tv":0.83,"id":40096579},{"batb":[[0,2.06,38.1],[1,1.81,10.99],[2,1.8,222]],"ltp":2.06,"tv":6.37,"id":40096581}]}]}
{"op":"mcm","clk":"11812178470","pt":1722773638426,"mc":[{"id":"1.231398046","rc":[{"batl":[[1,6,1.56],[2,8,0.78]],"ltp":1.94,"tv":0.83,"id":40096579},{"batb":[[1,1.8,222],[2,1.74,17.32]],"ltp":2.06,"tv":6.37,"id":40096581}]}]}
{"op":"mcm","clk":"11812644070","pt":1722777278281,"mc":[{"id":"1.231398046","rc":[{"batb":[[0,1.87,1],[1,1.86,46.96],[2,1.74,17.32]],"ltp":1.94,"tv":0.83,"id":40096579}]}]}
{"op":"mcm","clk":"11813139298","pt":1722781312341,"mc":[{"id":"1.231398046","rc":[{"batb":[[1,1.86,51.56]],"ltp":1.94,"tv":0.83,"id":40096579},{"batb":[[0,2.06,41.83]],"ltp":2.06,"tv":6.37,"id":40096581}]}]}
{"op":"mcm","clk":"11813207874","pt":1722781937335,"mc":[{"id":"1.231398046","rc":[{"batb":[[2,1.85,3.35]],"ltp":1.94,"tv":0.83,"id":40096579}]}]}
{"op":"mcm","clk":"11813207987","pt":1722781938550,"mc":[{"id":"1.231398046","rc":[{"batb":[[2,1.74,17.32]],"ltp":1.94,"tv":0.83,"id":40096579}]}]}
{"op":"mcm","clk":"11814405862","pt":1722791455845,"mc":[{"id":"1.231398046","rc":[{"batb":[[1,2,30],[2,1.8,222]],"ltp":2.06,"tv":6.37,"id":40096581}]}]}
{"op":"mcm","clk":"11814406752","pt":1722791462374,"mc":[{"id":"1.231398046","rc":[{"batl":[[0,2.24,30],[1,6,1.56],[2,8,0.78]],"ltp":2.06,"tv":6.37,"id":40096581}]}]}
{"op":"mcm","clk":"11815156455","pt":1722797450733,"mc":[{"id":"1.231398046","rc":[{"trd":[[2.06,7.08]],"batb":[[0,2.06,41.48]],"ltp":2.06,"tv":7.07,"id":40096581}],"tv":7.9}]}
{"op":"mcm","clk":"11815156557","pt":1722797451832,"mc":[{"id":"1.231398046","rc":[{"batb":[[0,2.06,41.83]],"ltp":2.06,"tv":7.07,"id":40096581}]}]}
{"op":"mcm","clk":"11815217606","pt":1722798083716,"mc":[{"id":"1.231398046","rc":[{"batl":[[0,2.1,10],[1,2.24,30],[2,6,1.56]],"ltp":2.06,"tv":7.07,"id":40096581}]}]}
{"op":"mcm","clk":"11815646348","pt":1722801547351,"mc":[{"id":"1.231398046","rc":[{"trd":[[1.94,1.01]],"batl":[[0,5,1.77],[1,8,1.56],[2,8,0]],"ltp":1.94,"tv":1.01,"id":40096579},{"trd":[[2.06,90.91]],"batb":[[0,2.02,10]],"ltp":2.06,"tv":90.9,"id":40096581}],"tv":91.91}]}
{"op":"mcm","clk":"11815646463","pt":1722801548439,"mc":[{"id":"1.231398046","rc":[{"batb":[[2,1.99,44.79]],"ltp":2.06,"tv":90.9,"id":40096581}]}]}
{"op":"mcm","clk":"11815646718","pt":1722801550628,"mc":[{"id":"1.231398046","rc":[{"batb":[[0,2,30],[1,1.99,44.79],[2,1.8,222]],"ltp":2.06,"tv":90.9,"id":40096581}]}]}
{"op":"mcm","clk":"11815646952","pt":1722801552971,"mc":[{"id":"1.231398046","rc":[{"batb":[[0,2.02,10],[1,2,30],[2,1.99,44.79]],"ltp":2.06,"tv":90.9,"id":40096581}]}]}
{"op":"mcm","clk":"11815647291","pt":1722801556350,"mc":[{"id":"1.231398046","rc":[{"batb":[[0,2,30],[1,1.99,44.79],[2,1.8,222]],"ltp":2.06,"tv":90.9,"id":40096581}]}]}
{"op":"mcm","clk":"11815647577","pt":1722801558868,"mc":[{"id":"1.231398046","rc":[{"batb":[[0,2.02,10],[1,2,30],[2,1.99,44.79]],"ltp":2.06,"tv":90.9,"id":40096581}]}]}
{"op":"mcm","clk":"11815647926","pt":1722801562249,"mc":[{"id":"1.231398046","rc":[{"batb":[[0,2,30],[1,1.99,44.79],[2,1.8,222]],"ltp":2.06,"tv":90.9,"id":40096581}]}]}
{"op":"mcm","clk":"11815648468","pt":1722801568374,"mc":[{"id":"1.231398046","rc":[{"batb":[[0,2.02,10],[1,2,30],[2,1.99,44.79]],"ltp":2.06,"tv":90.9,"id":40096581}]}]}
{"op":"mcm","clk":"11815648733","pt":1722801571489,"mc":[{"id":"1.231398046","rc":[{"batb":[[0,2,30],[1,1.99,44.79],[2,1.8,222]],"ltp":2.06,"tv":90.9,"id":40096581}]}]}
{"op":"mcm","clk":"11815649075","pt":1722801575488,"mc":[{"id":"1.231398046","rc":[{"trd":[[1.94,2]],"batl":[[0,6,1.56],[1,8,0.78]],"ltp":1.94,"tv":2.0,"id":40096579},{"trd":[[2.06,91.84]],"batb":[[0,2.02,10],[1,2,30],[2,1.99,44.79]],"batl":[[0,2.04,10.07],[1,2.1,10],[2,2.24,30]],"ltp":2.06,"tv":91.83,"id":40096581}],"tv":93.83}]}
{"op":"mcm","clk":"11815649345","pt":1722801578494,"mc":[{"id":"1.231398046","rc":[{"batb":[[0,2,30],[1,1.99,44.79],[2,1.8,222]],"ltp":2.06,"tv":91.83,"id":40096581}]}]}
{"op":"mcm","clk":"11815655543","pt":1722801641473,"mc":[{"id":"1.231398046","rc":[{"trd":[[2.06,91.83]],"batl":[[0,2.1,10],[1,2.24,30],[2,6,1.56]],"ltp":2.06,"tv":91.83,"id":40096581}],"tv":93.83}]}
{"op":"mcm","clk":"11815655554","pt":1722801641575,"mc":[{"id":"1.231398046","rc":[{"trd":[[2.02,20]],"batl":[[0,2.1,10.07]],"ltp":2.02,"tv":111.83,"id":40096581}],"tv":113.83}]}
{"op":"mcm","clk":"11815656328","pt":1722801650075,"mc":[{"id":"1.231398046","rc":[{"trd":[[2,0.14]],"batb":[[0,2.02,10],[1,2,29.93],[2,1.99,44.79]],"batl":[[0,2.1,10]],"ltp":2.0,"tv":111.97,"id":40096581}],"tv":113.97}]}
{"op":"mcm","clk":"11815656643","pt":1722801653347,"mc":[{"id":"1.231398046","rc":[{"batb":[[0,2,29.93],[1,1.99,44.79],[2,1.8,222]],"ltp":2.0,"tv":111.97,"id":40096581}]}]}
{"op":"mcm","clk":"11815662981","pt":1722801719933,"mc":[{"id":"1.231398046","rc":[{"batb":[[0,2.02,10],[1,2,29.93],[2,1.99,44.79]],"ltp":2.0,"tv":111.97,"id":40096581}]}]}
{"op":"mcm","clk":"11815663333","pt":1722801723371,"mc":[{"id":"1.231398046","rc":[{"batb":[[0,2,29.93],[1,1.99,44.79],[2,1.8,222]],"ltp":2.0,"tv":111.97,"id":40096581}]}]}
{"op":"mcm","clk":"11815664768","pt":1722801737834,"mc":[{"id":"1.231398046","rc":[{"batb":[[0,2.02,10],[1,2,29.93],[2,1.99,44.79]],"ltp":2.0,"tv":111.97,"id":40096581}]}]}
{"op":"mcm","clk":"11815665104","pt":1722801741153,"mc":[{"id":"1.231398046","rc":[{"batb":[[0,2,29.93],[1,1.99,44.79],[2,1.8,222]],"ltp":2.0,"tv":111.97,"id":40096581}]}]}
{"op":"mcm","clk":"11815672806","pt":1722801830805,"mc":[{"id":"1.231398046","rc":[{"batb":[[0,2.02,10],[1,2,29.93],[2,1.99,44.79]],"ltp":2.0,"tv":111.97,"id":40096581}]}]}
{"op":"mcm","clk":"11815673177","pt":1722801833056,"mc":[{"id":"1.231398046","rc":[{"batb":[[0,2,29.93],[1,1.99,44.79],[2,1.8,222]],"ltp":2.0,"tv":111.97,"id":40096581}]}]}
{"op":"mcm","clk":"11815677575","pt":1722801878475,"mc":[{"id":"1.231398046","rc":[{"batl":[[0,1.98,37.02],[1,6,1.56],[2,8,0.78]],"ltp":1.94,"tv":2.0,"id":40096579},{"batb":[[0,2.02,10],[1,2,29.93],[2,1.99,44.79]],"ltp":2.0,"tv":111.97,"id":40096581}]}]}
{"op":"mcm","clk":"11815677913","pt":1722801881898,"mc":[{"id":"1.231398046","rc":[{"batb":[[0,2,29.93],[1,1.99,44.79],[2,1.8,222]],"ltp":2.0,"tv":111.97,"id":40096581}]}]}
{"op":"mcm","clk":"11815685268","pt":1722801951486,"mc":[{"id":"1.231398046","rc":[{"batb":[[0,2.02,10],[1,2,29.93],[2,1.99,44.79]],"ltp":2.0,"tv":111.97,"id":40096581}]}]}
{"op":"mcm","clk":"11815685634","pt":1722801954777,"mc":[{"id":"1.231398046","rc":[{"batb":[[0,2,29.93],[1,1.99,44.79],[2,1.8,222]],"ltp":2.0,"tv":111.97,"id":40096581}]}]}
{"op":"mcm","clk":"11815692497","pt":1722802013328,"mc":[{"id":"1.231398046","rc":[{"batb":[[0,2.02,10],[1,2,29.93],[2,1.99,44.79]],"ltp":2.0,"tv":111.97,"id":40096581}]}]}
{"op":"mcm","clk":"11815692950","pt":1722802016845,"mc":[{"id":"1.231398046","rc":[{"batb":[[0,2,29.93],[1,1.99,44.79],[2,1.8,222]],"ltp":2.0,"tv":111.97,"id":40096581}]}]}
{"op":"mcm","clk":"11815697343","pt":1722802052868,"mc":[{"id":"1.231398046","rc":[{"batb":[[0,2.02,10],[1,2,29.93],[2,1.99,44.79]],"ltp":2.0,"tv":111.97,"id":40096581}]}]}
{"op":"mcm","clk":"11815697721","pt":1722802056256,"mc":[{"id":"1.231398046","rc":[{"batb":[[0,2,29.93],[1,1.99,44.79],[2,1.8,222]],"ltp":2.0,"tv":111.97,"id":40096581}]}]}
{"op":"mcm","clk":"11815699633","pt":1722802072790,"mc":[{"id":"1.231398046","rc":[{"batb":[[0,2.02,10],[1,2,29.93],[2,1.99,44.79]],"ltp":2.0,"tv":111.97,"id":40096581}]}]}
{"op":"mcm","clk":"11815700035","pt":1722802076084,"mc":[{"id":"1.231398046","rc":[{"batb":[[0,2,29.93],[1,1.99,44.79],[2,1.8,222]],"ltp":2.0,"tv":111.97,"id":40096581}]}]}
{"op":"mcm","clk":"11815700357","pt":1722802078865,"mc":[{"id":"1.231398046","rc":[{"batb":[[0,2.02,10],[1,2,29.93],[2,1.99,44.79]],"ltp":2.0,"tv":111.97,"id":40096581}]}]}
{"op":"mcm","clk":"11815700769","pt":1722802082180,"mc":[{"id":"1.231398046","rc":[{"batb":[[0,2,29.93],[1,1.99,44.79],[2,1.8,222]],"ltp":2.0,"tv":111.97,"id":40096581}]}]}
{"op":"mcm","clk":"11815706513","pt":1722802131395,"mc":[{"id":"1.231398046","rc":[{"trd":[[1.9,11.05]],"batl":[[0,1.9,788.95],[1,1.98,37.02],[2,6,1.56]],"ltp":1.9,"tv":13.05,"id":40096579},{"trd":[[2.1,10]],"batb":[[0,2.02,10],[1,2,29.93],[2,1.99,44.79]],"batl":[[0,2.24,30],[1,6,1.56],[2,8,0.78]],"ltp":2.1,"tv":121.97,"id":40096581}],"tv":135.02}]}
{"op":"mcm","clk":"11815706906","pt":1722802134783,"mc":[{"id":"1.231398046","rc":[{"batb":[[0,2,29.93],[1,1.99,44.79],[2,1.8,222]],"ltp":2.1,"tv":121.97,"id":40096581}]}]}
{"op":"mcm","clk":"11815708602","pt":1722802149232,"mc":[{"id":"1.231398046","rc":[{"batl":[[1,1.95,800],[2,1.98,37.02]],"ltp":1.9,"tv":13.05,"id":40096579},{"batb":[[0,2.02,10],[1,2,29.93],[2,1.99,44.79]],"ltp":2.1,"tv":121.97,"id":40096581}]}]}
{"op":"mcm","clk":"11815709013","pt":1722802152637,"mc":[{"id":"1.231398046","rc":[{"batb":[[0,2,29.93],[1,1.99,44.79],[2,1.8,222]],"ltp":2.1,"tv":121.97,"id":40096581}]}]}
{"op":"mcm","clk":"11815716304","pt":1722802216087,"mc":[{"id":"1.231398046","rc":[{"batb":[[0,2.02,10],[1,2,29.93],[2,1.99,44.79]],"ltp":2.1,"tv":121.97,"id":40096581}]}]}
{"op":"mcm","clk":"11815716713","pt":1722802219486,"mc":[{"id":"1.231398046","rc":[{"batb":[[0,2,29.93],[1,1.99,44.79],[2,1.8,222]],"ltp":2.1,"tv":121.97,"id":40096581}]}]}
{"op":"mcm","clk":"11815728782","pt":1722802324262,"mc":[{"id":"1.231398046","rc":[{"batb":[[0,1.87,101]],"ltp":1.9,"tv":13.05,"id":40096579},{"batb":[[0,2.02,10],[1,2,29.93],[2,1.99,44.79]],"ltp":2.1,"tv":121.97,"id":40096581}]}]}
{"op":"mcm","clk":"11815729182","pt":1722802327563,"mc":[{"id":"1.231398046","rc":[{"batb":[[0,2,29.93],[1,1.99,44.79],[2,1.8,222]],"ltp":2.1,"tv":121.97,"id":40096581}]}]}
{"op":"mcm","clk":"11815730151","pt":1722802335475,"mc":[{"id":"1.231398046","rc":[{"batb":[[2,1.81,100]],"ltp":1.9,"tv":13.05,"id":40096579},{"batb":[[0,2.02,10],[1,2,29.93],[2,1.99,44.79]],"ltp":2.1,"tv":121.97,"id":40096581}]}]}
{"op":"mcm","clk":"11815730565","pt":1722802338887,"mc":[{"id":"1.231398046","rc":[{"batb":[[0,2,29.93],[1,1.99,44.79],[2,1.8,222]],"ltp":2.1,"tv":121.97,"id":40096581}]}]}
{"op":"mcm","clk":"11815732206","pt":1722802352896,"mc":[{"id":"1.231398046","rc":[{"batb":[[0,2.02,10],[1,2,29.93],[2,1.99,44.79]],"ltp":2.1,"tv":121.97,"id":40096581}]}]}
{"op":"mcm","clk":"11815732599","pt":1722802356295,"mc":[{"id":"1.231398046","rc":[{"batb":[[0,2,29.93],[1,1.99,44.79],[2,1.8,222]],"ltp":2.1,"tv":121.97,"id":40096581}]}]}
{"op":"mcm","clk":"11815769645","pt":1722802627608,"mc":[{"id":"1.231398046","rc":[{"batb":[[0,2.02,10],[1,2,29.93],[2,1.99,44.79]],"ltp":2.1,"tv":121.97,"id":40096581}]}]}
{"op":"mcm","clk":"11815769944","pt":1722802630936,"mc":[{"id":"1.231398046","rc":[{"batb":[[0,2,29.93],[1,1.99,44.79],[2,1.8,222]],"ltp":2.1,"tv":121.97,"id":40096581}]}]}
{"op":"mcm","clk":"11815780238","pt":1722802728850,"mc":[{"id":"1.231398046","rc":[{"trd":[[1.87,202]],"batb":[[0,1.86,51.56],[1,1.81,100],[2,1.75,800]],"batl":[[0,1.87,2.87],[1,1.9,788.95],[2,1.95,800]],"ltp":1.87,"tv":215.05,"id":40096579},{"batb":[[0,2.02,10],[1,2,29.93],[2,1.99,44.79]],"ltp":2.1,"tv":121.97,"id":40096581}],"tv":337.02}]}
{"op":"mcm","clk":"11815780541","pt":1722802732080,"mc":[{"id":"1.231398046","rc":[{"batb":[[0,2,29.93],[1,1.99,44.79],[2,1.8,222]],"ltp":2.1,"tv":121.97,"id":40096581}]}]}
{"op":"mcm","clk":"11815780929","pt":1722802735982,"mc":[{"id":"1.231398046","rc":[{"trd":[[1.86,103.12]],"batb":[[0,1.81,100],[1,1.75,800],[2,1.74,17.32]],"batl":[[0,1.87,3.24]],"ltp":1.86,"tv":318.17,"id":40096579},{"batb":[[0,2.02,10],[1,2,29.93],[2,1.99,44.79]],"ltp":2.1,"tv":121.97,"id":40096581}],"tv":440.14}]}
{"op":"mcm","clk":"11815781111","pt":1722802737994,"mc":[{"id":"1.231398046","rc":[{"batb":[[0,1.82,54.08],[1,1.81,100],[2,1.75,800]],"ltp":1.86,"tv":318.17,"id":40096579}]}]}
{"op":"mcm","clk":"11815781283","pt":1722802739196,"mc":[{"id":"1.231398046","rc":[{"batb":[[0,2,29.93],[1,1.99,44.79],[2,1.8,222]],"ltp":2.1,"tv":121.97,"id":40096581}]}]}
{"op":"mcm","clk":"11815782864","pt":1722802756211,"mc":[{"id":"1.231398046","rc":[{"batl":[[0,1.9,789.32],[1,1.95,800],[2,1.98,37.02]],"ltp":1.86,"tv":318.17,"id":40096579},{"batb":[[0,2.02,10],[1,2,29.93],[2,1.99,44.79]],"ltp":2.1,"tv":121.97,"id":40096581}]}]}
{"op":"mcm","clk":"11815783206","pt":1722802759394,"mc":[{"id":"1.231398046","rc":[{"batl":[[0,1.9,788.95]],"ltp":1.86,"tv":318.17,"id":40096579},{"batb":[[0,2,29.93],[1,1.99,44.79],[2,1.8,222]],"ltp":2.1,"tv":121.97,"id":40096581}]}]}
{"op":"mcm","clk":"11815783483","pt":1722802762316,"mc":[{"id":"1.231398046","rc":[{"trd":[[1.9,800]],"batl":[[0,1.95,800],[1,1.98,37.02],[2,6,1.56]],"ltp":1.9,"tv":1107.12,"id":40096579},{"trd":[[2.1,723.81]],"batb":[[0,2.02,10],[1,2,29.93],[2,1.99,44.79]],"batl":[[0,2.1,1.19],[1,2.24,30],[2,6,1.56]],"ltp":2.1,"tv":835.78,"id":40096581}],"tv":1942.9}]}
{"op":"mcm","clk":"11815783807","pt":1722802765698,"mc":[{"id":"1.231398046","rc":[{"batb":[[0,2,29.93],[1,1.99,44.79],[2,1.8,222]],"ltp":2.1,"tv":835.78,"id":40096581}]}]}
{"op":"mcm","clk":"11815785448","pt":1722802782020,"mc":[{"id":"1.231398046","rc":[{"trd":[[1.9,801.25]],"ltp":1.9,"tv":1108.36,"id":40096579},{"trd":[[2.1,724.94]],"batb":[[0,2.02,10],[1,2,29.93],[2,1.99,44.79]],"batl":[[0,2.24,30.06],[1,6,1.56],[2,8,0.78]],"ltp":2.1,"tv":836.91,"id":40096581}],"tv":1945.27}]}
{"op":"mcm","clk":"11815785817","pt":1722802785525,"mc":[{"id":"1.231398046","rc":[{"batb":[[0,2,29.93],[1,1.99,44.79],[2,1.8,222]],"ltp":2.1,"tv":836.91,"id":40096581}]}]}
{"op":"mcm","clk":"11815787287","pt":1722802799755,"mc":[{"id":"1.231398046","rc":[{"batl":[[0,1.94,21.64],[1,1.95,800],[2,1.98,37.02]],"ltp":1.9,"tv":1108.36,"id":40096579},{"batb":[[0,2.02,10],[1,2,29.93],[2,1.99,44.79]],"ltp":2.1,"tv":836.91,"id":40096581}]}]}
{"op":"mcm","clk":"11815787635","pt":1722802802964,"mc":[{"id":"1.231398046","rc":[{"batb":[[0,2,29.93],[1,1.99,44.79],[2,1.8,222]],"ltp":2.1,"tv":836.91,"id":40096581}]}]}
{"op":"mcm","clk":"11815794561","pt":1722802864326,"mc":[{"id":"1.231398046","rc":[{"trd":[[1.94,23.24]],"batl":[[0,1.95,800.4],[1,1.98,37.02],[2,6,1.56]],"ltp":1.94,"tv":1129.6,"id":40096579},{"trd":[[2.06,111.83]],"ltp":2.06,"tv":856.91,"id":40096581}],"tv":1986.51}]}
{"op":"mcm","clk":"11815794582","pt":1722802864524,"mc":[{"id":"1.231398046","rc":[{"batb":[[0,2.02,10],[1,2,29.93],[2,1.99,44.79]],"ltp":2.06,"tv":856.91,"id":40096581}]}]}
{"op":"mcm","clk":"11815794934","pt":1722802867749,"mc":[{"id":"1.231398046","rc":[{"batb":[[0,2,29.93],[1,1.99,44.79],[2,1.8,222]],"ltp":2.06,"tv":856.91,"id":40096581}]}]}
{"op":"mcm","clk":"11815797114","pt":1722802886155,"mc":[{"id":"1.231398046","rc":[{"batb":[[0,1.84,15.33],[1,1.82,54.08],[2,1.81,100]],"ltp":1.94,"tv":1129.6,"id":40096579},{"batb":[[0,2.02,10],[1,2,29.93],[2,1.99,44.79]],"ltp":2.06,"tv":856.91,"id":40096581}]}]}
{"op":"mcm","clk":"11815797534","pt":1722802889359,"mc":[{"id":"1.231398046","rc":[{"batb":[[0,2,29.93],[1,1.99,44.79],[2,1.8,222]],"ltp":2.06,"tv":856.91,"id":40096581}]}]}
{"op":"mcm","clk":"11815799435","pt":1722802906356,"mc":[{"id":"1.231398046","rc":[{"batl":[[0,1.92,800],[1,1.95,800.4],[2,1.98,37.02]],"ltp":1.94,"tv":1129.6,"id":40096579},{"batb":[[0,2.02,10],[1,2,29.93],[2,1.99,44.79]],"ltp":2.06,"tv":856.91,"id":40096581}]}]}
{"op":"mcm","clk":"11815799850","pt":1722802909653,"mc":[{"id":"1.231398046","rc":[{"batb":[[0,2,29.93],[1,1.99,44.79],[2,1.8,222]],"ltp":2.06,"tv":856.91,"id":40096581}]}]}
{"op":"mcm","clk":"11815800854","pt":1722802918477,"mc":[{"id":"1.231398046","rc":[{"batl":[[1,1.98,37.42],[2,6,1.56]],"ltp":1.94,"tv":1129.6,"id":40096579},{"batb":[[0,2.02,10],[1,2,29.93],[2,1.99,44.79]],"ltp":2.06,"tv":856.91,"id":40096581}]}]}
{"op":"mcm","clk":"11815801245","pt":1722802921699,"mc":[{"id":"1.231398046","rc":[{"batb":[[0,2,29.93],[1,1.99,44.79],[2,1.8,222]],"ltp":2.06,"tv":856.91,"id":40096581}]}]}
{"op":"mcm","clk":"11815801889","pt":1722802927087,"mc":[{"id":"1.231398046","rc":[{"trd":[[1.9,801.32]],"batl":[[0,1.9,799.93],[1,1.92,800],[2,1.98,37.42]],"ltp":1.9,"tv":1129.67,"id":40096579},{"trd":[[2.1,725]],"batb":[[0,2.02,10],[1,2,29.93],[2,1.99,44.79]],"batl":[[0,2.24,30]],"ltp":2.1,"tv":856.97,"id":40096581}],"tv":1986.64}]}
{"op":"mcm","clk":"11815802242","pt":1722802930292,"mc":[{"id":"1.231398046","rc":[{"batb":[[0,2,29.93],[1,1.99,44.79],[2,1.8,222]],"ltp":2.1,"tv":856.97,"id":40096581}]}]}
{"op":"mcm","clk":"11815803735","pt":1722802943052,"mc":[{"id":"1.231398046","rc":[{"trd":[[1.9,802.43]],"batb":[[0,1.82,54.08],[1,1.81,100],[2,1.75,800]],"batl":[[0,1.9,798.82]],"ltp":1.9,"tv":1130.78,"id":40096579},{"trd":[[2.1,726]],"batb":[[0,2.02,10],[1,2,29.93],[2,1.99,44.79]],"ltp":2.1,"tv":857.97,"id":40096581}],"tv":1988.75}]}
{"op":"mcm","clk":"11815804082","pt":1722802945937,"mc":[{"id":"1.231398046","rc":[{"batb":[[0,2,29.93],[1,1.99,44.79],[2,1.8,222]],"ltp":2.1,"tv":857.97,"id":40096581}]}]}
{"op":"mcm","clk":"11815805234","pt":1722802955974,"mc":[{"id":"1.231398046","rc":[{"batb":[[0,1.83,9.02],[1,1.82,54.08],[2,1.81,100]],"ltp":1.9,"tv":1130.78,"id":40096579},{"batb":[[0,2.02,10],[1,2,29.93],[2,1.99,44.79]],"ltp":2.1,"tv":857.97,"id":40096581}]}]}
{"op":"mcm","clk":"11815805626","pt":1722802959400,"mc":[{"id":"1.231398046","rc":[{"batb":[[0,2,29.93],[1,1.99,44.79],[2,1.8,222]],"ltp":2.1,"tv":857.97,"id":40096581}]}]}
{"op":"mcm","clk":"11815811996","pt":1722803019359,"mc":[{"id":"1.231398046","rc":[{"batl":[[1,1.98,37.42],[2,6,1.56]],"ltp":1.9,"tv":1130.78,"id":40096579},{"batb":[[0,2.02,10],[1,2,29.93],[2,1.99,44.79]],"ltp":2.1,"tv":857.97,"id":40096581}]}]}
{"op":"mcm","clk":"11815812350","pt":1722803022653,"mc":[{"id":"1.231398046","rc":[{"batb":[[0,2,29.93],[1,1.99,44.79],[2,1.8,222]],"ltp":2.1,"tv":857.97,"id":40096581}]}]}
{"op":"mcm","clk":"11815813644","pt":1722803035161,"mc":[{"id":"1.231398046","rc":[{"batb":[[0,2.02,10],[1,2,29.93],[2,1.99,44.79]],"ltp":2.1,"tv":857.97,"id":40096581}]}]}
{"op":"mcm","clk":"11815814024","pt":1722803038670,"mc":[{"id":"1.231398046","rc":[{"batb":[[0,2,29.93],[1,1.99,44.79],[2,1.8,222]],"ltp":2.1,"tv":857.97,"id":40096581}]}]}
{"op":"mcm","clk":"11815815530","pt":1722803051999,"mc":[{"id":"1.231398046","rc":[{"batb":[[0,2.02,10],[1,2,29.93],[2,1.99,44.79]],"ltp":2.1,"tv":857.97,"id":40096581}]}]}
{"op":"mcm","clk":"11815815865","pt":1722803055283,"mc":[{"id":"1.231398046","rc":[{"batb":[[0,2,29.93],[1,1.99,44.79],[2,1.8,222]],"ltp":2.1,"tv":857.97,"id":40096581}]}]}
{"op":"mcm","clk":"11815827627","pt":1722803174318,"mc":[{"id":"1.231398046","rc":[{"batl":[[1,1.96,18.44],[2,1.98,37.02]],"ltp":1.9,"tv":1130.78,"id":40096579}]}]}
{"op":"mcm","clk":"11815827647","pt":1722803174520,"mc":[{"id":"1.231398046","rc":[{"batb":[[0,2.02,10],[1,2,29.93],[2,1.99,44.79]],"ltp":2.1,"tv":857.97,"id":40096581}]}]}
{"op":"mcm","clk":"11815827978","pt":1722803177709,"mc":[{"id":"1.231398046","rc":[{"batb":[[0,2,29.93],[1,1.99,44.79],[2,1.8,222]],"ltp":2.1,"tv":857.97,"id":40096581}]}]}
{"op":"mcm","clk":"11815828711","pt":1722803184820,"mc":[{"id":"1.231398046","rc":[{"batl":[[0,1.89,16.84],[1,1.9,798.82],[2,1.96,18.44]],"ltp":1.9,"tv":1130.78,"id":40096579},{"batb":[[0,2.14,10],[1,2.12,15.31],[2,2,29.93]],"ltp":2.1,"tv":857.97,"id":40096581}]}]}
{"op":"mcm","clk":"11815829018","pt":1722803188007,"mc":[{"id":"1.231398046","rc":[{"batb":[[0,2.12,15.31],[1,2,29.93],[2,1.99,44.79]],"ltp":2.1,"tv":857.97,"id":40096581}]}]}
{"op":"mcm","clk":"11815830576","pt":1722803203838,"mc":[{"id":"1.231398046","rc":[{"batb":[[0,2.14,10],[1,2.12,15.31],[2,2,29.93]],"ltp":2.1,"tv":857.97,"id":40096581}]}]}
{"op":"mcm","clk":"11815830875","pt":1722803207131,"mc":[{"id":"1.231398046","rc":[{"batb":[[0,2.12,15.31],[1,2,29.93],[2,1.99,44.79]],"ltp":2.1,"tv":857.97,"id":40096581}]}]}
{"op":"mcm","clk":"11815831930","pt":1722803217769,"mc":[{"id":"1.231398046","rc":[{"batb":[[0,2.14,10],[1,2.12,15.31],[2,2,29.93]],"ltp":2.1,"tv":857.97,"id":40096581}]}]}
{"op":"mcm","clk":"11815832309","pt":1722803220962,"mc":[{"id":"1.231398046","rc":[{"batb":[[0,2.12,15.31],[1,2,29.93],[2,1.99,44.79]],"ltp":2.1,"tv":857.97,"id":40096581}]}]}
{"op":"mcm","clk":"11815839411","pt":1722803291221,"mc":[{"id":"1.231398046","rc":[{"batl":[[2,1.94,7.61]],"ltp":1.9,"tv":1130.78,"id":40096579},{"batb":[[0,2.14,10],[1,2.12,15.31],[2,2,29.93]],"ltp":2.1,"tv":857.97,"id":40096581}]}]}
{"op":"mcm","clk":"11815839748","pt":1722803294631,"mc":[{"id":"1.231398046","rc":[{"batb":[[0,2.12,15.31],[1,2,29.93],[2,1.99,44.79]],"ltp":2.1,"tv":857.97,"id":40096581}]}]}
{"op":"mcm","clk":"11815841920","pt":1722803316541,"mc":[{"id":"1.231398046","rc":[{"batb":[[0,2.14,10],[1,2.12,15.31],[2,2,29.93]],"ltp":2.1,"tv":857.97,"id":40096581}]}]}
{"op":"mcm","clk":"11815842276","pt":1722803320148,"mc":[{"id":"1.231398046","rc":[{"batb":[[0,2.12,15.31],[1,2,29.93],[2,1.99,44.79]],"ltp":2.1,"tv":857.97,"id":40096581}]}]}
{"op":"mcm","clk":"11815844895","pt":1722803347588,"mc":[{"id":"1.231398046","rc":[{"batb":[[0,2.14,10],[1,2.12,15.31],[2,2,29.93]],"ltp":2.1,"tv":857.97,"id":40096581}]}]}
{"op":"mcm","clk":"11815845200","pt":1722803350773,"mc":[{"id":"1.231398046","rc":[{"batb":[[0,2.12,15.31],[1,2,29.93],[2,1.99,44.79]],"ltp":2.1,"tv":857.97,"id":40096581}]}]}
{"op":"mcm","clk":"11815847608","pt":1722803375930,"mc":[{"id":"1.231398046","rc":[{"batb":[[0,2.14,10],[1,2.12,15.31],[2,2,29.93]],"ltp":2.1,"tv":857.97,"id":40096581}]}]}
{"op":"mcm","clk":"11815847895","pt":1722803379208,"mc":[{"id":"1.231398046","rc":[{"batb":[[0,2.12,15.31],[1,2,29.93],[2,1.99,44.79]],"ltp":2.1,"tv":857.97,"id":40096581}]}]}
{"op":"mcm","clk":"11815849912","pt":1722803400166,"mc":[{"id":"1.231398046","rc":[{"batl":[[2,1.94,327.61]],"ltp":1.9,"tv":1130.78,"id":40096579},{"batb":[[0,2.14,10],[1,2.12,15.31],[2,2,29.93]],"ltp":2.1,"tv":857.97,"id":40096581}]}]}
{"op":"mcm","clk":"11815850293","pt":1722803403550,"mc":[{"id":"1.231398046","rc":[{"batb":[[0,2.12,15.31],[1,2,29.93],[2,1.99,44.79]],"ltp":2.1,"tv":857.97,"id":40096581}]}]}
{"op":"mcm","clk":"11815852192","pt":1722803423704,"mc":[{"id":"1.231398046","rc":[{"batb":[[0,2.14,10],[1,2.12,15.31],[2,2,29.93]],"ltp":2.1,"tv":857.97,"id":40096581}]}]}
{"op":"mcm","clk":"11815852504","pt":1722803427043,"mc":[{"id":"1.231398046","rc":[{"batb":[[0,2.12,15.31],[1,2,29.93],[2,1.99,44.79]],"ltp":2.1,"tv":857.97,"id":40096581}]}]}
{"op":"mcm","clk":"11815857107","pt":1722803475411,"mc":[{"id":"1.231398046","rc":[{"batb":[[0,2.14,10],[1,2.12,15.31],[2,2,29.93]],"ltp":2.1,"tv":857.97,"id":40096581}]}]}
{"op":"mcm","clk":"11815857410","pt":1722803478824,"mc":[{"id":"1.231398046","rc":[{"batb":[[0,2.12,15.31],[1,2,29.93],[2,1.99,44.79]],"ltp":2.1,"tv":857.97,"id":40096581}]}]}
{"op":"mcm","clk":"11815858201","pt":1722803487737,"mc":[{"id":"1.231398046","rc":[{"batb":[[0,2.14,10],[1,2.12,15.31],[2,2,29.93]],"ltp":2.1,"tv":857.97,"id":40096581}]}]}
{"op":"mcm","clk":"11815858519","pt":1722803491129,"mc":[{"id":"1.231398046","rc":[{"batb":[[0,2.12,15.31],[1,2,29.93],[2,1.99,44.79]],"ltp":2.1,"tv":857.97,"id":40096581}]}]}
{"op":"mcm","clk":"11815858865","pt":1722803495045,"mc":[{"id":"1.231398046","rc":[{"batl":[[0,1.89,336.84]],"ltp":1.9,"tv":1130.78,"id":40096579},{"batb":[[0,2.14,10],[1,2.12,15.31],[2,2,29.93]],"ltp":2.1,"tv":857.97,"id":40096581}]}]}
{"op":"mcm","clk":"11815859234","pt":1722803498557,"mc":[{"id":"1.231398046","rc":[{"batb":[[0,2.12,15.31],[1,2,29.93],[2,1.99,44.79]],"ltp":2.1,"tv":857.97,"id":40096581}]}]}
{"op":"mcm","clk":"11815859494","pt":1722803501462,"mc":[{"id":"1.231398046","rc":[{"batb":[[0,2.14,10],[1,2.12,15.31],[2,2,29.93]],"ltp":2.1,"tv":857.97,"id":40096581}]}]}
{"op":"mcm","clk":"11815859775","pt":1722803504654,"mc":[{"id":"1.231398046","rc":[{"batb":[[0,2.12,15.31],[1,2,29.93],[2,1.99,44.79]],"ltp":2.1,"tv":857.97,"id":40096581}]}]}
{"op":"mcm","clk":"11815862745","pt":1722803535273,"mc":[{"id":"1.231398046","rc":[{"batb":[[0,2.14,10],[1,2.12,15.31],[2,2,29.93]],"ltp":2.1,"tv":857.97,"id":40096581}]}]}
{"op":"mcm","clk":"11815863065","pt":1722803538766,"mc":[{"id":"1.231398046","rc":[{"batb":[[0,2.12,15.31],[1,2,29.93],[2,1.99,44.79]],"ltp":2.1,"tv":857.97,"id":40096581}]}]}
{"op":"mcm","clk":"11815883359","pt":1722803770132,"mc":[{"id":"1.231398046","rc":[{"batb":[[0,2.14,10],[1,2.12,15.31],[2,2,29.93]],"ltp":2.1,"tv":857.97,"id":40096581}]}]}
{"op":"mcm","clk":"11815883615","pt":1722803773402,"mc":[{"id":"1.231398046","rc":[{"batb":[[0,2.12,15.31],[1,2,29.93],[2,1.99,44.79]],"ltp":2.1,"tv":857.97,"id":40096581}]}]}
{"op":"mcm","clk":"11815891750","pt":1722803860431,"mc":[{"id":"1.231398046","rc":[{"batb":[[0,2.14,10],[1,2.12,15.31],[2,2,29.93]],"ltp":2.1,"tv":857.97,"id":40096581}]}]}
{"op":"mcm","clk":"11815892037","pt":1722803863825,"mc":[{"id":"1.231398046","rc":[{"batb":[[0,2.12,15.31],[1,2,29.93],[2,1.99,44.79]],"ltp":2.1,"tv":857.97,"id":40096581}]}]}
{"op":"mcm","clk":"11815893219","pt":1722803877410,"mc":[{"id":"1.231398046","rc":[{"batb":[[0,2.16,10],[1,2.14,87],[2,2.12,15.31]],"ltp":2.1,"tv":857.97,"id":40096581}]}]}
{"op":"mcm","clk":"11815893290","pt":1722803878131,"mc":[{"id":"1.231398046","rc":[{"batb":[[1,1.81,100],[2,1.77,809.02]],"batl":[[0,1.87,4.86],[1,1.89,320],[2,1.9,798.82]],"ltp":1.9,"tv":1130.78,"id":40096579},{"batb":[[2,2,29.93]],"ltp":2.1,"tv":857.97,"id":40096581}]}]}
{"op":"mcm","clk":"11815893512","pt":1722803880741,"mc":[{"id":"1.231398046","rc":[{"batb":[[0,2.14,87],[1,2,29.93],[2,1.8,222]],"ltp":2.1,"tv":857.97,"id":40096581}]}]}
{"op":"mcm","clk":"11815893741","pt":1722803883354,"mc":[{"id":"1.231398046","rc":[{"batb":[[1,1.82,54.08],[2,1.81,100]],"ltp":1.9,"tv":1130.78,"id":40096579},{"batb":[[0,2.16,10],[1,2.14,87],[2,2,29.93]],"ltp":2.1,"tv":857.97,"id":40096581}]}]}
{"op":"mcm","clk":"11815894040","pt":1722803886847,"mc":[{"id":"1.231398046","rc":[{"batb":[[0,2.14,87],[1,2,29.93],[2,1.99,44.79]],"ltp":2.1,"tv":857.97,"id":40096581}]}]}
{"op":"mcm","clk":"11815895101","pt":1722803899353,"mc":[{"id":"1.231398046","rc":[{"batb":[[0,2.16,10],[1,2.14,87],[2,2,29.93]],"ltp":2.1,"tv":857.97,"id":40096581}]}]}
{"op":"mcm","clk":"11815895391","pt":1722803902857,"mc":[{"id":"1.231398046","rc":[{"batb":[[0,2.14,87],[1,2,29.93],[2,1.99,44.79]],"ltp":2.1,"tv":857.97,"id":40096581}]}]}
{"op":"mcm","clk":"11815896182","pt":1722803911764,"mc":[{"id":"1.231398046","rc":[{"batb":[[0,2.16,10],[1,2.14,87],[2,2,29.93]],"ltp":2.1,"tv":857.97,"id":40096581}]}]}
{"op":"mcm","clk":"11815896306","pt":1722803913276,"mc":[{"id":"1.231398046","rc":[{"batb":[[1,1.81,100],[2,1.77,809.02]],"ltp":1.9,"tv":1130.78,"id":40096579}]}]}
{"op":"mcm","clk":"11815896463","pt":1722803914963,"mc":[{"id":"1.231398046","rc":[{"batb":[[0,2.14,87],[1,2,29.93],[2,1.8,222]],"ltp":2.1,"tv":857.97,"id":40096581}]}]}
{"op":"mcm","clk":"11815896765","pt":1722803918296,"mc":[{"id":"1.231398046","rc":[{"batb":[[1,1.82,54.08],[2,1.81,100]],"ltp":1.9,"tv":1130.78,"id":40096579},{"batb":[[2,1.99,44.79]],"ltp":2.1,"tv":857.97,"id":40096581}]}]}
{"op":"mcm","clk":"11815896791","pt":1722803918559,"mc":[{"id":"1.231398046","rc":[{"batb":[[0,2.16,10],[1,2.14,87],[2,2,29.93]],"ltp":2.1,"tv":857.97,"id":40096581}]}]}
{"op":"mcm","clk":"11815897094","pt":1722803921895,"mc":[{"id":"1.231398046","rc":[{"batb":[[0,2.14,87],[1,2,29.93],[2,1.99,44.79]],"ltp":2.1,"tv":857.97,"id":40096581}]}]}
{"op":"mcm","clk":"11815898307","pt":1722803936380,"mc":[{"id":"1.231398046","rc":[{"batb":[[0,2.16,10],[1,2.14,87],[2,2,29.93]],"ltp":2.1,"tv":857.97,"id":40096581}]}]}
{"op":"mcm","clk":"11815898480","pt":1722803938479,"mc":[{"id":"1.231398046","rc":[{"batb":[[1,1.81,100],[2,1.77,809.02]],"ltp":1.9,"tv":1130.78,"id":40096579}]}]}
{"op":"mcm","clk":"11815898578","pt":1722803939677,"mc":[{"id":"1.231398046","rc":[{"batb":[[0,2.14,87],[1,2,29.93],[2,1.8,222]],"ltp":2.1,"tv":857.97,"id":40096581}]}]}
{"op":"mcm","clk":"11815898925","pt":1722803943489,"mc":[{"id":"1.231398046","rc":[{"batb":[[1,1.82,54.08],[2,1.81,100]],"ltp":1.9,"tv":1130.78,"id":40096579},{"batb":[[0,2.16,10],[1,2.14,87],[2,2,29.93]],"ltp":2.1,"tv":857.97,"id":40096581}]}]}
{"op":"mcm","clk":"11815899249","pt":1722803946793,"mc":[{"id":"1.231398046","rc":[{"batb":[[0,2.14,87],[1,2,29.93],[2,1.99,44.79]],"ltp":2.1,"tv":857.97,"id":40096581}]}]}
{"op":"mcm","clk":"11815905529","pt":1722804020239,"mc":[{"id":"1.231398046","rc":[{"batb":[[0,2.16,10],[1,2.14,87],[2,2,29.93]],"ltp":2.1,"tv":857.97,"id":40096581}]}]}
{"op":"mcm","clk":"11815905801","pt":1722804023547,"mc":[{"id":"1.231398046","rc":[{"batb":[[0,2.14,87],[1,2,29.93],[2,1.99,44.79]],"ltp":2.1,"tv":857.97,"id":40096581}]}]}
{"op":"mcm","clk":"11815907742","pt":1722804045847,"mc":[{"id":"1.231398046","rc":[{"batb":[[0,2.16,10],[1,2.14,87],[2,2,29.93]],"ltp":2.1,"tv":857.97,"id":40096581}]}]}
{"op":"mcm","clk":"11815908023","pt":1722804049135,"mc":[{"id":"1.231398046","rc":[{"batb":[[1,1.81,100],[2,1.77,809.02]],"ltp":1.9,"tv":1130.78,"id":40096579},{"batb":[[0,2.14,87],[1,2,29.93],[2,1.8,222]],"ltp":2.1,"tv":857.97,"id":40096581}]}]}
{"op":"mcm","clk":"11815908360","pt":1722804053363,"mc":[{"id":"1.231398046","rc":[{"batb":[[0,2.16,10],[1,2.14,87],[2,2,29.93]],"ltp":2.1,"tv":857.97,"id":40096581}]}]}
{"op":"mcm","clk":"11815908616","pt":1722804056678,"mc":[{"id":"1.231398046","rc":[{"batb":[[0,2.14,87],[1,2,29.93],[2,1.8,222]],"ltp":2.1,"tv":857.97,"id":40096581}]}]}
{"op":"mcm","clk":"11815908816","pt":1722804059192,"mc":[{"id":"1.231398046","rc":[{"batb":[[1,1.82,54.08],[2,1.81,100]],"ltp":1.9,"tv":1130.78,"id":40096579},{"batb":[[0,2.16,10],[1,2.14,87],[2,2,29.93]],"ltp":2.1,"tv":857.97,"id":40096581}]}]}
{"op":"mcm","clk":"11815909094","pt":1722804062676,"mc":[{"id":"1.231398046","rc":[{"batb":[[0,2.14,87],[1,2,29.93],[2,1.99,44.79]],"ltp":2.1,"tv":857.97,"id":40096581}]}]}
{"op":"mcm","clk":"11815909924","pt":1722804072887,"mc":[{"id":"1.231398046","rc":[{"batb":[[0,2.16,10],[1,2.14,87],[2,2,29.93]],"ltp":2.1,"tv":857.97,"id":40096581}]}]}
{"op":"mcm","clk":"11815910034","pt":1722804074183,"mc":[{"id":"1.231398046","rc":[{"batb":[[1,1.81,100],[2,1.77,809.02]],"ltp":1.9,"tv":1130.78,"id":40096579}]}]}
{"op":"mcm","clk":"11815910236","pt":1722804076282,"mc":[{"id":"1.231398046","rc":[{"batb":[[0,2.14,87],[1,2,29.93],[2,1.8,222]],"ltp":2.1,"tv":857.97,"id":40096581}]}]}
{"op":"mcm","clk":"11815910483","pt":1722804079194,"mc":[{"id":"1.231398046","rc":[{"batb":[[1,1.82,54.08],[2,1.81,100]],"ltp":1.9,"tv":1130.78,"id":40096579},{"batb":[[0,2.16,10],[1,2.14,87],[2,2,29.93]],"ltp":2.1,"tv":857.97,"id":40096581}]}]}
{"op":"mcm","clk":"11815910785","pt":1722804082487,"mc":[{"id":"1.231398046","rc":[{"batb":[[0,2.14,87],[1,2,29.93],[2,1.99,44.79]],"ltp":2.1,"tv":857.97,"id":40096581}]}]}
{"op":"mcm","clk":"11815911783","pt":1722804093010,"mc":[{"id":"1.231398046","rc":[{"batb":[[0,2.16,10],[1,2.14,87],[2,2,29.93]],"ltp":2.1,"tv":857.97,"id":40096581}]}]}
{"op":"mcm","clk":"11815911884","pt":1722804094203,"mc":[{"id":"1.231398046","rc":[{"batb":[[1,1.81,100],[2,1.77,809.02]],"ltp":1.9,"tv":1130.78,"id":40096579}]}]}
{"op":"mcm","clk":"11815912089","pt":1722804096537,"mc":[{"id":"1.231398046","rc":[{"batb":[[0,2.14,87],[1,2,29.93],[2,1.8,222]],"ltp":2.1,"tv":857.97,"id":40096581}]}]}
{"op":"mcm","clk":"11815912337","pt":1722804099323,"mc":[{"id":"1.231398046","rc":[{"batb":[[1,1.82,54.08],[2,1.81,100]],"ltp":1.9,"tv":1130.78,"id":40096579},{"batb":[[0,2.16,10],[1,2.14,87],[2,2,29.93]],"ltp":2.1,"tv":857.97,"id":40096581}]}]}
{"op":"mcm","clk":"11815912607","pt":1722804102614,"mc":[{"id":"1.231398046","rc":[{"batb":[[0,2.14,87],[1,2,29.93],[2,1.99,44.79]],"ltp":2.1,"tv":857.97,"id":40096581}]}]}
{"op":"mcm","clk":"11815914082","pt":1722804118142,"mc":[{"id":"1.231398046","rc":[{"batb":[[0,2.16,4.48],[1,2.14,87],[2,2,29.93]],"ltp":2.1,"tv":857.97,"id":40096581}]}]}
{"op":"mcm","clk":"11815917979","pt":1722804163256,"mc":[{"id":"1.231398046","rc":[{"batl":[[0,1.87,12.3]],"ltp":1.9,"tv":1130.78,"id":40096579},{"batb":[[0,2.16,11.67]],"ltp":2.1,"tv":857.97,"id":40096581}]}]}
{"op":"mcm","clk":"11815918066","pt":1722804164459,"mc":[{"id":"1.231398046","rc":[{"batb":[[1,1.81,100],[2,1.77,809.02]],"ltp":1.9,"tv":1130.78,"id":40096579}]}]}
{"op":"mcm","clk":"11815918165","pt":1722804165690,"mc":[{"id":"1.231398046","rc":[{"batb":[[1,1.82,4.91],[2,1.81,100]],"ltp":1.9,"tv":1130.78,"id":40096579},{"batl":[[0,2.22,5.81],[1,2.24,30],[2,6,1.56]],"ltp":2.1,"tv":857.97,"id":40096581}]}]}
{"op":"mcm","clk":"11815920028","pt":1722804187504,"mc":[{"id":"1.231398046","rc":[{"batb":[[0,1.82,4.91],[1,1.81,100],[2,1.77,809.02]],"ltp":1.9,"tv":1130.78,"id":40096579}]}]}
{"op":"mcm","clk":"11815920217","pt":1722804189380,"mc":[{"id":"1.231398046","rc":[{"batb":[[0,1.82,58.99]],"ltp":1.9,"tv":1130.78,"id":40096579}]}]}
{"op":"mcm","clk":"11815922907","pt":1722804221199,"mc":[{"id":"1.231398046","rc":[{"batb":[[0,1.83,4.43],[1,1.82,58.99],[2,1.81,100]],"ltp":1.9,"tv":1130.78,"id":40096579}]}]}
{"op":"mcm","clk":"11815925778","pt":1722804254049,"mc":[{"id":"1.231398046","rc":[{"batl":[[0,2.2,4.34],[1,2.22,5.81],[2,2.24,30]],"ltp":2.1,"tv":857.97,"id":40096581}]}]}
{"op":"mcm","clk":"11815931220","pt":1722804320703,"mc":[{"id":"1.231398046","rc":[{"batl":[[0,2.18,10],[1,2.2,4.34],[2,2.22,5.81]],"ltp":2.1,"tv":857.97,"id":40096581}]}]}
{"op":"mcm","clk":"11815931341","pt":1722804322214,"mc":[{"id":"1.231398046","rc":[{"batb":[[1,1.82,54.08]],"ltp":1.9,"tv":1130.78,"id":40096579},{"batl":[[1,2.22,5.81],[2,2.24,30]],"ltp":2.1,"tv":857.97,"id":40096581}]}]}
{"op":"mcm","clk":"11815941982","pt":1722804456340,"mc":[{"id":"1.231398046","rc":[{"batl":[[0,2.22,5.81],[1,2.24,30],[2,6,1.56]],"ltp":2.1,"tv":857.97,"id":40096581}]}]}
{"op":"mcm","clk":"11816001770","pt":1722805417357,"mc":[{"id":"1.231398046","rc":[{"batb":[[2,1.99,44.79]],"batl":[[1,6,1.56],[2,8,0.78]],"ltp":2.1,"tv":857.97,"id":40096581}]}]}
{"op":"mcm","clk":"11816003629","pt":1722805453097,"mc":[{"id":"1.231398046","rc":[{"trd":[[1.82,8.64],[1.83,8.86]],"batb":[[0,1.82,49.76],[1,1.81,100],[2,1.79,9.02]],"ltp":1.82,"tv":1148.28,"id":40096579}],"tv":2006.25}]}
{"op":"mcm","clk":"11816003664","pt":1722805453920,"mc":[{"id":"1.231398046","rc":[{"batb":[[0,1.82,54.08]],"ltp":1.82,"tv":1148.28,"id":40096579}]}]}
{"op":"mcm","clk":"11816024101","pt":1722805840494,"mc":[{"id":"1.231398046","rc":[{"batb":[[0,1.84,52.79]],"ltp":1.82,"tv":1148.28,"id":40096579},{"batb":[[2,2.08,41.06]],"ltp":2.1,"tv":857.97,"id":40096581}]}]}
{"op":"mcm","clk":"11816024153","pt":1722805841472,"mc":[{"id":"1.231398046","rc":[{"batl":[[0,6,1.56],[1,8,0.78],[2,8,0]],"ltp":2.1,"tv":857.97,"id":40096581}]}]}
{"op":"mcm","clk":"11816024159","pt":1722805841579,"mc":[{"id":"1.231398046","rc":[{"batb":[[0,2.18,10],[1,2.16,11.67],[2,2.14,87]],"ltp":2.1,"tv":857.97,"id":40096581}]}]}
{"op":"mcm","clk":"11816024228","pt":1722805843476,"mc":[{"id":"1.231398046","rc":[{"batb":[[1,2.16,7.19]],"ltp":2.1,"tv":857.97,"id":40096581}]}]}
{"op":"mcm","clk":"11816024277","pt":1722805844404,"mc":[{"id":"1.231398046","rc":[{"batb":[[1,2.14,87],[2,2.08,41.06]],"ltp":2.1,"tv":857.97,"id":40096581}]}]}
{"op":"mcm","clk":"11816024306","pt":1722805845179,"mc":[{"id":"1.231398046","rc":[{"batb":[[0,2.16,4.8]],"ltp":2.1,"tv":857.97,"id":40096581}]}]}
{"op":"mcm","clk":"11816024349","pt":1722805846063,"mc":[{"id":"1.231398046","rc":[{"batl":[[0,1.87,19.74]],"ltp":1.82,"tv":1148.28,"id":40096579},{"batb":[[0,2.16,12.5]],"ltp":2.1,"tv":857.97,"id":40096581}]}]}
{"op":"mcm","clk":"11816024921","pt":1722805857504,"mc":[{"id":"1.231398046","rc":[{"batb":[[0,2.18,10],[1,2.16,7.7],[2,2.14,87]],"ltp":2.1,"tv":857.97,"id":40096581}]}]}
{"op":"mcm","clk":"11816024951","pt":1722805858181,"mc":[{"id":"1.231398046","rc":[{"batb":[[1,2.14,87],[2,2.08,41.06]],"ltp":2.1,"tv":857.97,"id":40096581}]}]}
{"op":"mcm","clk":"11816025077","pt":1722805860412,"mc":[{"id":"1.231398046","rc":[{"batb":[[0,2.14,87],[1,2.08,41.06],[2,1.9,259.67]],"ltp":2.1,"tv":857.97,"id":40096581}]}]}
{"op":"mcm","clk":"11816026211","pt":1722805880767,"mc":[{"id":"1.231398046","rc":[{"batb":[[0,2.18,10],[1,2.16,7.83],[2,2.14,87]],"ltp":2.1,"tv":857.97,"id":40096581}]}]}
{"op":"mcm","clk":"11816026315","pt":1722805882522,"mc":[{"id":"1.231398046","rc":[{"batb":[[1,2.14,87],[2,2.08,41.06]],"ltp":2.1,"tv":857.97,"id":40096581}]}]}
{"op":"mcm","clk":"11816026391","pt":1722805884030,"mc":[{"id":"1.231398046","rc":[{"batb":[[0,2.14,87],[1,2.08,41.06],[2,1.9,259.67]],"ltp":2.1,"tv":857.97,"id":40096581}]}]}
{"op":"mcm","clk":"11816027265","pt":1722805901330,"mc":[{"id":"1.231398046","rc":[{"batb":[[0,2.16,10],[1,2.14,87],[2,2.08,41.06]],"ltp":2.1,"tv":857.97,"id":40096581}]}]}
{"op":"mcm","clk":"11816027419","pt":1722805904644,"mc":[{"id":"1.231398046","rc":[{"batb":[[0,2.14,87],[1,2.08,41.06],[2,1.9,259.67]],"ltp":2.1,"tv":857.97,"id":40096581}]}]}
{"op":"mcm","clk":"11816027723","pt":1722805910866,"mc":[{"id":"1.231398046","rc":[{"batb":[[0,2.16,10],[1,2.14,87],[2,2.08,41.06]],"ltp":2.1,"tv":857.97,"id":40096581}]}]}
{"op":"mcm","clk":"11816027876","pt":1722805914382,"mc":[{"id":"1.231398046","rc":[{"batb":[[0,2.14,87],[1,2.08,41.06],[2,1.9,259.67]],"ltp":2.1,"tv":857.97,"id":40096581}]}]}
{"op":"mcm","clk":"11816027905","pt":1722805914853,"mc":[{"id":"1.231398046","rc":[{"batb":[[0,2.16,7.83],[1,2.14,87],[2,2.08,41.06]],"ltp":2.1,"tv":857.97,"id":40096581}]}]}
{"op":"mcm","clk":"11816028160","pt":1722805920675,"mc":[{"id":"1.231398046","rc":[{"batb":[[0,2.18,10],[1,2.16,13.33],[2,2.14,87]],"ltp":2.1,"tv":857.97,"id":40096581}]}]}
{"op":"mcm","clk":"11816028230","pt":1722805921982,"mc":[{"id":"1.231398046","rc":[{"batb":[[1,2.16,7.83]],"ltp":2.1,"tv":857.97,"id":40096581}]}]}
{"op":"mcm","clk":"11816028276","pt":1722805922867,"mc":[{"id":"1.231398046","rc":[{"batb":[[1,2.14,87],[2,2.08,41.06]],"ltp":2.1,"tv":857.97,"id":40096581}]}]}
{"op":"mcm","clk":"11816028342","pt":1722805923953,"mc":[{"id":"1.231398046","rc":[{"batb":[[0,2.14,87],[1,2.08,41.06],[2,1.9,259.67]],"ltp":2.1,"tv":857.97,"id":40096581}]}]}
{"op":"mcm","clk":"11816029555","pt":1722805948478,"mc":[{"id":"1.231398046","rc":[{"batb":[[0,2.18,10],[1,2.16,7.83],[2,2.14,87]],"ltp":2.1,"tv":857.97,"id":40096581}]}]}
{"op":"mcm","clk":"11816029626","pt":1722805950182,"mc":[{"id":"1.231398046","rc":[{"batb":[[1,2.14,87],[2,2.08,41.06]],"ltp":2.1,"tv":857.97,"id":40096581}]}]}
{"op":"mcm","clk":"11816029720","pt":1722805951782,"mc":[{"id":"1.231398046","rc":[{"batb":[[0,2.14,87],[1,2.08,41.06],[2,1.9,259.67]],"ltp":2.1,"tv":857.97,"id":40096581}]}]}
{"op":"mcm","clk":"11816031238","pt":1722805983449,"mc":[{"id":"1.231398046","rc":[{"batb":[[0,2.18,10],[1,2.16,7.83],[2,2.14,87]],"ltp":2.1,"tv":857.97,"id":40096581}]}]}
{"op":"mcm","clk":"11816031318","pt":1722805984935,"mc":[{"id":"1.231398046","rc":[{"batb":[[1,2.14,87],[2,2.08,41.06]],"ltp":2.1,"tv":857.97,"id":40096581}]}]}
{"op":"mcm","clk":"11816031416","pt":1722805986835,"mc":[{"id":"1.231398046","rc":[{"batb":[[0,2.14,87],[1,2.08,41.06],[2,1.9,259.67]],"ltp":2.1,"tv":857.97,"id":40096581}]}]}
{"op":"mcm","clk":"11816031836","pt":1722805995840,"mc":[{"id":"1.231398046","rc":[{"batb":[[0,2.18,10],[1,2.16,5.12],[2,2.14,87]],"ltp":2.1,"tv":857.97,"id":40096581}]}]}
{"op":"mcm","clk":"11816031931","pt":1722805997546,"mc":[{"id":"1.231398046","rc":[{"batb":[[1,2.14,87],[2,2.08,41.06]],"ltp":2.1,"tv":857.97,"id":40096581}]}]}
{"op":"mcm","clk":"11816032012","pt":1722805999152,"mc":[{"id":"1.231398046","rc":[{"batb":[[0,2.14,87],[1,2.08,41.06],[2,1.9,259.67]],"ltp":2.1,"tv":857.97,"id":40096581}]}]}
{"op":"mcm","clk":"11816032719","pt":1722806014371,"mc":[{"id":"1.231398046","rc":[{"batb":[[0,2.16,10],[1,2.14,87],[2,2.08,41.06]],"ltp":2.1,"tv":857.97,"id":40096581}]}]}
{"op":"mcm","clk":"11816032805","pt":1722806015701,"mc":[{"id":"1.231398046","rc":[{"batb":[[0,2.16,17.83]],"ltp":2.1,"tv":857.97,"id":40096581}]}]}
{"op":"mcm","clk":"11816032916","pt":1722806017672,"mc":[{"id":"1.231398046","rc":[{"batb":[[0,2.16,7.83]],"ltp":2.1,"tv":857.97,"id":40096581}]}]}
{"op":"mcm","clk":"11816033105","pt":1722806021279,"mc":[{"id":"1.231398046","rc":[{"batb":[[0,2.18,10]],"ltp":2.1,"tv":857.97,"id":40096581}]}]}
{"op":"mcm","clk":"11816033264","pt":1722806024269,"mc":[{"id":"1.231398046","rc":[{"batb":[[0,2.14,87],[1,2.08,41.06],[2,1.9,259.67]],"ltp":2.1,"tv":857.97,"id":40096581}]}]}
{"op":"mcm","clk":"11816033581","pt":1722806030977,"mc":[{"id":"1.231398046","rc":[{"batb":[[0,2.16,10],[1,2.14,87],[2,2.08,41.06]],"ltp":2.1,"tv":857.97,"id":40096581}]}]}
{"op":"mcm","clk":"11816033754","pt":1722806034381,"mc":[{"id":"1.231398046","rc":[{"batb":[[0,2.14,87],[1,2.08,41.06],[2,1.9,259.67]],"ltp":2.1,"tv":857.97,"id":40096581}]}]}
{"op":"mcm","clk":"11816034302","pt":1722806044198,"mc":[{"id":"1.231398046","rc":[{"batb":[[0,2.16,10],[1,2.14,87],[2,2.08,41.06]],"ltp":2.1,"tv":857.97,"id":40096581}]}]}
{"op":"mcm","clk":"11816034481","pt":1722806047504,"mc":[{"id":"1.231398046","rc":[{"batb":[[0,2.14,87],[1,2.08,41.06],[2,1.9,259.67]],"ltp":2.1,"tv":857.97,"id":40096581}]}]}
{"op":"mcm","clk":"11816034626","pt":1722806050245,"mc":[{"id":"1.231398046","rc":[{"batb":[[0,2.16,17.83],[1,2.14,87],[2,2.08,41.06]],"ltp":2.1,"tv":857.97,"id":40096581}]}]}
{"op":"mcm","clk":"11816034803","pt":1722806053448,"mc":[{"id":"1.231398046","rc":[{"batb":[[0,2.16,7.83]],"ltp":2.1,"tv":857.97,"id":40096581}]}]}
{"op":"mcm","clk":"11816035009","pt":1722806058248,"mc":[{"id":"1.231398046","rc":[{"batb":[[0,2.18,10],[1,2.16,7.83],[2,2.14,87]],"ltp":2.1,"tv":857.97,"id":40096581}]}]}
{"op":"mcm","clk":"11816035053","pt":1722806058921,"mc":[{"id":"1.231398046","rc":[{"batb":[[1,2.14,87],[2,2.08,41.06]],"ltp":2.1,"tv":857.97,"id":40096581}]}]}
{"op":"mcm","clk":"11816035181","pt":1722806061652,"mc":[{"id":"1.231398046","rc":[{"batb":[[0,2.14,87],[1,2.08,41.06],[2,1.9,259.67]],"ltp":2.1,"tv":857.97,"id":40096581}]}]}
{"op":"mcm","clk":"11816035516","pt":1722806067955,"mc":[{"id":"1.231398046","rc":[{"batb":[[0,2.16,10],[1,2.14,87],[2,2.08,41.06]],"ltp":2.1,"tv":857.97,"id":40096581}]}]}
{"op":"mcm","clk":"11816035697","pt":1722806071354,"mc":[{"id":"1.231398046","rc":[{"batb":[[0,2.16,5.12]],"ltp":2.1,"tv":857.97,"id":40096581}]}]}
{"op":"mcm","clk":"11816035864","pt":1722806074144,"mc":[{"id":"1.231398046","rc":[{"batb":[[0,2.18,10],[1,2.16,5.12],[2,2.14,87]],"ltp":2.1,"tv":857.97,"id":40096581}]}]}
{"op":"mcm","clk":"11816035912","pt":1722806074934,"mc":[{"id":"1.231398046","rc":[{"batb":[[1,2.14,87],[2,2.08,41.06]],"ltp":2.1,"tv":857.97,"id":40096581}]}]}
{"op":"mcm","clk":"11816036056","pt":1722806077671,"mc":[{"id":"1.231398046","rc":[{"batb":[[0,2.14,87],[1,2.08,41.06],[2,1.9,259.67]],"ltp":2.1,"tv":857.97,"id":40096581}]}]}
{"op":"mcm","clk":"11816036200","pt":1722806080458,"mc":[{"id":"1.231398046","rc":[{"batb":[[0,2.16,10],[1,2.14,87],[2,2.08,41.06]],"ltp":2.1,"tv":857.97,"id":40096581}]}]}
{"op":"mcm","clk":"11816036373","pt":1722806083976,"mc":[{"id":"1.231398046","rc":[{"batb":[[0,2.16,7.83]],"ltp":2.1,"tv":857.97,"id":40096581}]}]}
{"op":"mcm","clk":"11816036499","pt":1722806086564,"mc":[{"id":"1.231398046","rc":[{"batb":[[0,2.18,10],[1,2.16,7.83],[2,2.14,87]],"ltp":2.1,"tv":857.97,"id":40096581}]}]}
{"op":"mcm","clk":"11816036554","pt":1722806087752,"mc":[{"id":"1.231398046","rc":[{"batb":[[1,2.14,87],[2,2.08,41.06]],"ltp":2.1,"tv":857.97,"id":40096581}]}]}
{"op":"mcm","clk":"11816036656","pt":1722806089978,"mc":[{"id":"1.231398046","rc":[{"batb":[[0,2.14,87],[1,2.08,41.06],[2,1.9,259.67]],"ltp":2.1,"tv":857.97,"id":40096581}]}]}
{"op":"mcm","clk":"11816037217","pt":1722806102293,"mc":[{"id":"1.231398046","rc":[{"batb":[[0,2.16,10],[1,2.14,87],[2,2.08,41.06]],"ltp":2.1,"tv":857.97,"id":40096581}]}]}
{"op":"mcm","clk":"11816037404","pt":1722806105814,"mc":[{"id":"1.231398046","rc":[{"batb":[[0,2.14,87],[1,2.08,41.06],[2,1.9,259.67]],"ltp":2.1,"tv":857.97,"id":40096581}]}]}
{"op":"mcm","clk":"11816037520","pt":1722806107988,"mc":[{"id":"1.231398046","rc":[{"batb":[[0,2.16,10],[1,2.14,87],[2,2.08,41.06]],"ltp":2.1,"tv":857.97,"id":40096581}]}]}
{"op":"mcm","clk":"11816037715","pt":1722806111288,"mc":[{"id":"1.231398046","rc":[{"batb":[[0,2.14,87],[1,2.08,41.06],[2,1.9,259.67]],"ltp":2.1,"tv":857.97,"id":40096581}]}]}
{"op":"mcm","clk":"11816038063","pt":1722806118216,"mc":[{"id":"1.231398046","rc":[{"batb":[[0,2.18,10],[1,2.16,7.83],[2,2.14,87]],"ltp":2.1,"tv":857.97,"id":40096581}]}]}
{"op":"mcm","clk":"11816038144","pt":1722806119825,"mc":[{"id":"1.231398046","rc":[{"batb":[[1,2.14,87],[2,2.08,41.06]],"ltp":2.1,"tv":857.97,"id":40096581}]}]}
{"op":"mcm","clk":"11816038220","pt":1722806121431,"mc":[{"id":"1.231398046","rc":[{"batb":[[0,2.14,87],[1,2.08,41.06],[2,1.9,259.67]],"ltp":2.1,"tv":857.97,"id":40096581}]}]}
{"op":"mcm","clk":"11816039061","pt":1722806139844,"mc":[{"id":"1.231398046","rc":[{"batb":[[0,2.16,10],[1,2.14,87],[2,2.08,41.06]],"ltp":2.1,"tv":857.97,"id":40096581}]}]}
{"op":"mcm","clk":"11816039217","pt":1722806143244,"mc":[{"id":"1.231398046","rc":[{"batb":[[0,2.14,87],[1,2.08,41.06],[2,1.9,259.67]],"ltp":2.1,"tv":857.97,"id":40096581}]}]}
{"op":"mcm","clk":"11816039343","pt":1722806145517,"mc":[{"id":"1.231398046","rc":[{"batb":[[0,2.16,10],[1,2.14,87],[2,2.08,41.06]],"ltp":2.1,"tv":857.97,"id":40096581}]}]}
{"op":"mcm","clk":"11816039493","pt":1722806148465,"mc":[{"id":"1.231398046","rc":[{"batb":[[0,2.16,15.12]],"ltp":2.1,"tv":857.97,"id":40096581}]}]}
{"op":"mcm","clk":"11816039527","pt":1722806149038,"mc":[{"id":"1.231398046","rc":[{"batb":[[0,2.16,5.12]],"ltp":2.1,"tv":857.97,"id":40096581}]}]}
{"op":"mcm","clk":"11816039648","pt":1722806151472,"mc":[{"id":"1.231398046","rc":[{"batb":[[0,2.16,13.33]],"ltp":2.1,"tv":857.97,"id":40096581}]}]}
{"op":"mcm","clk":"11816039680","pt":1722806152144,"mc":[{"id":"1.231398046","rc":[{"batb":[[0,2.18,10],[1,2.16,8.21],[2,2.14,87]],"ltp":2.1,"tv":857.97,"id":40096581}]}]}
{"op":"mcm","clk":"11816039729","pt":1722806153073,"mc":[{"id":"1.231398046","rc":[{"batb":[[1,2.14,87],[2,2.08,41.06]],"ltp":2.1,"tv":857.97,"id":40096581}]}]}
{"op":"mcm","clk":"11816039827","pt":1722806155037,"mc":[{"id":"1.231398046","rc":[{"batb":[[0,2.14,87],[1,2.08,41.06],[2,1.9,259.67]],"ltp":2.1,"tv":857.97,"id":40096581}]}]}
{"op":"mcm","clk":"11816040249","pt":1722806163681,"mc":[{"id":"1.231398046","rc":[{"batb":[[0,2.16,10],[1,2.14,87],[2,2.08,41.06]],"ltp":2.1,"tv":857.97,"id":40096581}]}]}
{"op":"mcm","clk":"11816040424","pt":1722806166960,"mc":[{"id":"1.231398046","rc":[{"batb":[[0,2.14,87],[1,2.08,41.06],[2,1.9,259.67]],"ltp":2.1,"tv":857.97,"id":40096581}]}]}
{"op":"mcm","clk":"11816040592","pt":1722806170289,"mc":[{"id":"1.231398046","rc":[{"batb":[[0,2.16,10],[1,2.14,87],[2,2.08,41.06]],"ltp":2.1,"tv":857.97,"id":40096581}]}]}
{"op":"mcm","clk":"11816040755","pt":1722806173452,"mc":[{"id":"1.231398046","rc":[{"batb":[[0,2.14,87],[1,2.08,41.06],[2,1.9,259.67]],"ltp":2.1,"tv":857.97,"id":40096581}]}]}
{"op":"mcm","clk":"11816041262","pt":1722806183285,"mc":[{"id":"1.231398046","rc":[{"batb":[[0,2.16,17.83],[1,2.14,87],[2,2.08,41.06]],"ltp":2.1,"tv":857.97,"id":40096581}]}]}
{"op":"mcm","clk":"11816041425","pt":1722806186397,"mc":[{"id":"1.231398046","rc":[{"batb":[[0,2.16,7.83]],"ltp":2.1,"tv":857.97,"id":40096581}]}]}
{"op":"mcm","clk":"11816041997","pt":1722806198494,"mc":[{"id":"1.231398046","rc":[{"batb":[[0,2.18,10]],"ltp":2.1,"tv":857.97,"id":40096581}]}]}
{"op":"mcm","clk":"11816042128","pt":1722806201128,"mc":[{"id":"1.231398046","rc":[{"batb":[[0,2.14,87],[1,2.08,41.06],[2,1.9,259.67]],"ltp":2.1,"tv":857.97,"id":40096581}]}]}
{"op":"mcm","clk":"11816042382","pt":1722806205416,"mc":[{"id":"1.231398046","rc":[{"batb":[[0,2.16,10],[1,2.14,87],[2,2.08,41.06]],"ltp":2.1,"tv":857.97,"id":40096581}]}]}
{"op":"mcm","clk":"11816042521","pt":1722806208712,"mc":[{"id":"1.231398046","rc":[{"batb":[[0,2.14,87],[1,2.08,41.06],[2,1.9,259.67]],"ltp":2.1,"tv":857.97,"id":40096581}]}]}
{"op":"mcm","clk":"11816042862","pt":1722806216344,"mc":[{"id":"1.231398046","rc":[{"batb":[[0,2.16,10],[1,2.14,87],[2,2.08,41.06]],"ltp":2.1,"tv":857.97,"id":40096581}]}]}
{"op":"mcm","clk":"11816042880","pt":1722806216655,"mc":[{"id":"1.231398046","rc":[{"batb":[[0,2.16,17.83]],"ltp":2.1,"tv":857.97,"id":40096581}]}]}
{"op":"mcm","clk":"11816043024","pt":1722806219545,"mc":[{"id":"1.231398046","rc":[{"batb":[[0,2.16,7.83]],"ltp":2.1,"tv":857.97,"id":40096581}]}]}
{"op":"mcm","clk":"11816043320","pt":1722806225433,"mc":[{"id":"1.231398046","rc":[{"batb":[[0,2.18,10],[1,2.16,13.33],[2,2.14,87]],"ltp":2.1,"tv":857.97,"id":40096581}]}]}
{"op":"mcm","clk":"11816043363","pt":1722806226533,"mc":[{"id":"1.231398046","rc":[{"batb":[[1,2.16,7.83]],"ltp":2.1,"tv":857.97,"id":40096581}]}]}
{"op":"mcm","clk":"11816043421","pt":1722806227922,"mc":[{"id":"1.231398046","rc":[{"batb":[[1,2.14,87],[2,2.08,41.06]],"ltp":2.1,"tv":857.97,"id":40096581}]}]}
{"op":"mcm","clk":"11816043456","pt":1722806228742,"mc":[{"id":"1.231398046","rc":[{"batb":[[0,2.14,87],[1,2.08,41.06],[2,1.9,259.67]],"ltp":2.1,"tv":857.97,"id":40096581}]}]}
{"op":"mcm","clk":"11816043959","pt":1722806238749,"mc":[{"id":"1.231398046","rc":[{"batb":[[0,2.16,10],[1,2.14,87],[2,2.08,41.06]],"ltp":2.1,"tv":857.97,"id":40096581}]}]}
{"op":"mcm","clk":"11816044179","pt":1722806242266,"mc":[{"id":"1.231398046","rc":[{"batb":[[0,2.14,87],[1,2.08,41.06],[2,1.9,259.67]],"ltp":2.1,"tv":857.97,"id":40096581}]}]}
{"op":"mcm","clk":"11816044325","pt":1722806244950,"mc":[{"id":"1.231398046","rc":[{"batb":[[0,2.16,10],[1,2.14,87],[2,2.08,41.06]],"ltp":2.1,"tv":857.97,"id":40096581}]}]}
{"op":"mcm","clk":"11816044482","pt":1722806248400,"mc":[{"id":"1.231398046","rc":[{"batb":[[0,2.14,87],[1,2.08,41.06],[2,1.9,259.67]],"ltp":2.1,"tv":857.97,"id":40096581}]}]}
{"op":"mcm","clk":"11816044538","pt":1722806249741,"mc":[{"id":"1.231398046","rc":[{"batb":[[0,2.16,7.83],[1,2.14,87],[2,2.08,41.06]],"ltp":2.1,"tv":857.97,"id":40096581}]}]}
{"op":"mcm","clk":"11816045430","pt":1722806264397,"mc":[{"id":"1.231398046","rc":[{"batb":[[0,2.18,10],[1,2.16,7.83],[2,2.14,87]],"ltp":2.1,"tv":857.97,"id":40096581}]}]}
{"op":"mcm","clk":"11816045458","pt":1722806264911,"mc":[{"id":"1.231398046","rc":[{"batb":[[1,2.14,87],[2,2.08,41.06]],"ltp":2.1,"tv":857.97,"id":40096581}]}]}
{"op":"mcm","clk":"11816045647","pt":1722806267812,"mc":[{"id":"1.231398046","rc":[{"batb":[[0,2.14,87],[1,2.08,41.06],[2,1.9,259.67]],"ltp":2.1,"tv":857.97,"id":40096581}]}]}
{"op":"mcm","clk":"11816045826","pt":1722806271126,"mc":[{"id":"1.231398046","rc":[{"batb":[[0,2.16,10],[1,2.14,87],[2,2.08,41.06]],"ltp":2.1,"tv":857.97,"id":40096581}]}]}
{"op":"mcm","clk":"11816046026","pt":1722806274333,"mc":[{"id":"1.231398046","rc":[{"batb":[[0,2.14,87],[1,2.08,41.06],[2,1.9,259.67]],"ltp":2.1,"tv":857.97,"id":40096581}]}]}
{"op":"mcm","clk":"11816046432","pt":1722806281545,"mc":[{"id":"1.231398046","rc":[{"batb":[[0,2.16,10],[1,2.14,87],[2,2.08,41.06]],"ltp":2.1,"tv":857.97,"id":40096581}]}]}
{"op":"mcm","clk":"11816046504","pt":1722806282837,"mc":[{"id":"1.231398046","rc":[{"batb":[[0,2.16,17.83]],"ltp":2.1,"tv":857.97,"id":40096581}]}]}
{"op":"mcm","clk":"11816046623","pt":1722806284921,"mc":[{"id":"1.231398046","rc":[{"batb":[[0,2.16,7.83]],"ltp":2.1,"tv":857.97,"id":40096581}]}]}
{"op":"mcm","clk":"11816046957","pt":1722806291263,"mc":[{"id":"1.231398046","rc":[{"batb":[[0,2.18,10],[1,2.16,7.83],[2,2.14,87]],"ltp":2.1,"tv":857.97,"id":40096581}]}]}
{"op":"mcm","clk":"11816047021","pt":1722806292146,"mc":[{"id":"1.231398046","rc":[{"batb":[[1,2.14,87],[2,2.08,41.06]],"ltp":2.1,"tv":857.97,"id":40096581}]}]}
{"op":"mcm","clk":"11816047214","pt":1722806295350,"mc":[{"id":"1.231398046","rc":[{"batb":[[0,2.14,87],[1,2.08,41.06],[2,1.9,259.67]],"ltp":2.1,"tv":857.97,"id":40096581}]}]}
{"op":"mcm","clk":"11816047390","pt":1722806299166,"mc":[{"id":"1.231398046","rc":[{"batb":[[0,2.18,10],[1,2.16,5.12],[2,2.14,87]],"ltp":2.1,"tv":857.97,"id":40096581}]}]}
{"op":"mcm","clk":"11816047487","pt":1722806300565,"mc":[{"id":"1.231398046","rc":[{"batb":[[1,2.14,87],[2,2.08,41.06]],"ltp":2.1,"tv":857.97,"id":40096581}]}]}
{"op":"mcm","clk":"11816047594","pt":1722806302481,"mc":[{"id":"1.231398046","rc":[{"batb":[[0,2.14,87],[1,2.08,41.06],[2,1.9,259.67]],"ltp":2.1,"tv":857.97,"id":40096581}]}]}
{"op":"mcm","clk":"11816048205","pt":1722806314169,"mc":[{"id":"1.231398046","rc":[{"trd":[[2.14,50]],"batb":[[0,2.16,10],[1,2.14,62],[2,2.08,41.06]],"ltp":2.14,"tv":907.97,"id":40096581}],"tv":2056.25}]}
{"op":"mcm","clk":"11816048315","pt":1722806315877,"mc":[{"id":"1.231398046","rc":[{"batb":[[0,2.16,15.95]],"ltp":2.14,"tv":907.97,"id":40096581}]}]}
{"op":"mcm","clk":"11816048400","pt":1722806317577,"mc":[{"id":"1.231398046","rc":[{"batb":[[0,2.16,5.95]],"ltp":2.14,"tv":907.97,"id":40096581}]}]}
{"op":"mcm","clk":"11816048815","pt":1722806325277,"mc":[{"id":"1.231398046","rc":[{"batb":[[0,2.18,10]],"ltp":2.14,"tv":907.97,"id":40096581}]}]}
{"op":"mcm","clk":"11816048958","pt":1722806328178,"mc":[{"id":"1.231398046","rc":[{"batb":[[0,2.14,62],[1,2.08,41.06],[2,1.9,259.67]],"ltp":2.14,"tv":907.97,"id":40096581}]}]}
{"op":"mcm","clk":"11816049151","pt":1722806331896,"mc":[{"id":"1.231398046","rc":[{"batb":[[0,2.16,10],[1,2.14,62],[2,2.08,41.06]],"ltp":2.14,"tv":907.97,"id":40096581}]}]}
{"op":"mcm","clk":"11816049316","pt":1722806335411,"mc":[{"id":"1.231398046","rc":[{"batb":[[0,2.14,62],[1,2.08,41.06],[2,1.9,259.67]],"ltp":2.14,"tv":907.97,"id":40096581}]}]}
{"op":"mcm","clk":"11816049627","pt":1722806340690,"mc":[{"id":"1.231398046","rc":[{"batb":[[0,2.16,10],[1,2.14,62],[2,2.08,41.06]],"ltp":2.14,"tv":907.97,"id":40096581}]}]}
{"op":"mcm","clk":"11816049804","pt":1722806344220,"mc":[{"id":"1.231398046","rc":[{"batb":[[0,2.14,62],[1,2.08,41.06],[2,1.9,259.67]],"ltp":2.14,"tv":907.97,"id":40096581}]}]}
{"op":"mcm","clk":"11816050083","pt":1722806349903,"mc":[{"id":"1.231398046","rc":[{"batb":[[0,2.18,10],[1,2.16,5.95],[2,2.14,62]],"ltp":2.14,"tv":907.97,"id":40096581}]}]}
{"op":"mcm","clk":"11816050154","pt":1722806351610,"mc":[{"id":"1.231398046","rc":[{"batb":[[1,2.14,62],[2,2.08,41.06]],"ltp":2.14,"tv":907.97,"id":40096581}]}]}
{"op":"mcm","clk":"11816050250","pt":1722806353313,"mc":[{"id":"1.231398046","rc":[{"batb":[[0,2.14,62],[1,2.08,41.06],[2,1.9,259.67]],"ltp":2.14,"tv":907.97,"id":40096581}]}]}
{"op":"mcm","clk":"11816050459","pt":1722806357547,"mc":[{"id":"1.231398046","rc":[{"batb":[[0,2.16,10],[1,2.14,62],[2,2.08,41.06]],"ltp":2.14,"tv":907.97,"id":40096581}]}]}
{"op":"mcm","clk":"11816050650","pt":1722806360815,"mc":[{"id":"1.231398046","rc":[{"batb":[[0,2.14,62],[1,2.08,41.06],[2,1.9,259.67]],"ltp":2.14,"tv":907.97,"id":40096581}]}]}
{"op":"mcm","clk":"11816050719","pt":1722806363032,"mc":[{"id":"1.231398046","rc":[{"batb":[[0,2.16,10],[1,2.14,62],[2,2.08,41.06]],"ltp":2.14,"tv":907.97,"id":40096581}]}]}
{"op":"mcm","clk":"11816050865","pt":1722806366331,"mc":[{"id":"1.231398046","rc":[{"batb":[[0,2.14,62],[1,2.08,41.06],[2,1.9,259.67]],"ltp":2.14,"tv":907.97,"id":40096581}]}]}
{"op":"mcm","clk":"11816051632","pt":1722806382677,"mc":[{"id":"1.231398046","rc":[{"batb":[[0,2.18,10],[1,2.16,5.95],[2,2.14,62]],"ltp":2.14,"tv":907.97,"id":40096581}]}]}
{"op":"mcm","clk":"11816051711","pt":1722806384275,"mc":[{"id":"1.231398046","rc":[{"batb":[[1,2.14,62],[2,2.08,41.06]],"ltp":2.14,"tv":907.97,"id":40096581}]}]}
{"op":"mcm","clk":"11816051802","pt":1722806385976,"mc":[{"id":"1.231398046","rc":[{"batb":[[0,2.14,62],[1,2.08,41.06],[2,1.9,259.67]],"ltp":2.14,"tv":907.97,"id":40096581}]}]}
{"op":"mcm","clk":"11816052342","pt":1722806396953,"mc":[{"id":"1.231398046","rc":[{"batb":[[0,2.16,10],[1,2.14,62],[2,2.08,41.06]],"ltp":2.14,"tv":907.97,"id":40096581}]}]}
{"op":"mcm","clk":"11816052517","pt":1722806400360,"mc":[{"id":"1.231398046","rc":[{"batb":[[0,2.14,62],[1,2.08,41.06],[2,1.9,259.67]],"ltp":2.14,"tv":907.97,"id":40096581}]}]}
{"op":"mcm","clk":"11816053438","pt":1722806416170,"mc":[{"id":"1.231398046","rc":[{"batb":[[0,2.18,10],[1,2.16,5.95],[2,2.14,62]],"ltp":2.14,"tv":907.97,"id":40096581}]}]}
{"op":"mcm","clk":"11816053512","pt":1722806417713,"mc":[{"id":"1.231398046","rc":[{"batb":[[1,2.14,62],[2,2.08,41.06]],"ltp":2.14,"tv":907.97,"id":40096581}]}]}
{"op":"mcm","clk":"11816053598","pt":1722806419513,"mc":[{"id":"1.231398046","rc":[{"batb":[[0,2.14,62],[1,2.08,41.06],[2,1.9,259.67]],"ltp":2.14,"tv":907.97,"id":40096581}]}]}
{"op":"mcm","clk":"11816055217","pt":1722806450030,"mc":[{"id":"1.231398046","rc":[{"batb":[[0,2.18,10],[1,2.16,5.95],[2,2.14,62]],"ltp":2.14,"tv":907.97,"id":40096581}]}]}
{"op":"mcm","clk":"11816055296","pt":1722806451524,"mc":[{"id":"1.231398046","rc":[{"batb":[[1,2.14,62],[2,2.08,41.06]],"ltp":2.14,"tv":907.97,"id":40096581}]}]}
{"op":"mcm","clk":"11816055376","pt":1722806453330,"mc":[{"id":"1.231398046","rc":[{"batb":[[0,2.14,62],[1,2.08,41.06],[2,1.9,259.67]],"ltp":2.14,"tv":907.97,"id":40096581}]}]}
{"op":"mcm","clk":"11816056845","pt":1722806483077,"mc":[{"id":"1.231398046","rc":[{"batb":[[0,2.18,10],[1,2.16,5.95],[2,2.14,62]],"ltp":2.14,"tv":907.97,"id":40096581}]}]}
{"op":"mcm","clk":"11816056916","pt":1722806484469,"mc":[{"id":"1.231398046","rc":[{"batb":[[1,2.14,62],[2,2.08,41.06]],"ltp":2.14,"tv":907.97,"id":40096581}]}]}
{"op":"mcm","clk":"11816057004","pt":1722806486477,"mc":[{"id":"1.231398046","rc":[{"batb":[[0,2.14,62],[1,2.08,41.06],[2,1.9,259.67]],"ltp":2.14,"tv":907.97,"id":40096581}]}]}
{"op":"mcm","clk":"11816057806","pt":1722806502618,"mc":[{"id":"1.231398046","rc":[{"batb":[[0,2.16,10],[1,2.14,62],[2,2.08,41.06]],"ltp":2.14,"tv":907.97,"id":40096581}]}]}
{"op":"mcm","clk":"11816058007","pt":1722806506017,"mc":[{"id":"1.231398046","rc":[{"batb":[[0,2.14,62],[1,2.08,41.06],[2,1.9,259.67]],"ltp":2.14,"tv":907.97,"id":40096581}]}]}
{"op":"mcm","clk":"11816058684","pt":1722806517742,"mc":[{"id":"1.231398046","rc":[{"batb":[[0,2.18,10],[1,2.16,5.95],[2,2.14,62]],"ltp":2.14,"tv":907.97,"id":40096581}]}]}
{"op":"mcm","clk":"11816058748","pt":1722806519236,"mc":[{"id":"1.231398046","rc":[{"batb":[[1,2.14,62],[2,2.08,41.06]],"ltp":2.14,"tv":907.97,"id":40096581}]}]}
{"op":"mcm","clk":"11816058835","pt":1722806521050,"mc":[{"id":"1.231398046","rc":[{"batb":[[0,2.14,62],[1,2.08,41.06],[2,1.9,259.67]],"ltp":2.14,"tv":907.97,"id":40096581}]}]}
{"op":"mcm","clk":"11816059405","pt":1722806530865,"mc":[{"id":"1.231398046","rc":[{"batb":[[0,2.16,10],[1,2.14,62],[2,2.08,41.06]],"ltp":2.14,"tv":907.97,"id":40096581}]}]}
{"op":"mcm","clk":"11816059576","pt":1722806534268,"mc":[{"id":"1.231398046","rc":[{"batb":[[0,2.14,62],[1,2.08,41.06],[2,1.9,259.67]],"ltp":2.14,"tv":907.97,"id":40096581}]}]}
{"op":"mcm","clk":"11816060752","pt":1722806551492,"mc":[{"id":"1.231398046","rc":[{"batb":[[0,2.16,5.95],[1,2.14,62],[2,2.08,41.06]],"ltp":2.14,"tv":907.97,"id":40096581}]}]}
{"op":"mcm","clk":"11816060758","pt":1722806551595,"mc":[{"id":"1.231398046","rc":[{"batb":[[0,2.18,10],[1,2.16,5.95],[2,2.14,62]],"ltp":2.14,"tv":907.97,"id":40096581}]}]}
{"op":"mcm","clk":"11816060832","pt":1722806553091,"mc":[{"id":"1.231398046","rc":[{"batb":[[1,2.14,62],[2,2.08,41.06]],"ltp":2.14,"tv":907.97,"id":40096581}]}]}
{"op":"mcm","clk":"11816060933","pt":1722806554899,"mc":[{"id":"1.231398046","rc":[{"batb":[[0,2.14,62],[1,2.08,41.06],[2,1.9,259.67]],"ltp":2.14,"tv":907.97,"id":40096581}]}]}
{"op":"mcm","clk":"11816061694","pt":1722806569301,"mc":[{"id":"1.231398046","rc":[{"batb":[[0,2.16,10],[1,2.14,62],[2,2.08,41.06]],"ltp":2.14,"tv":907.97,"id":40096581}]}]}
{"op":"mcm","clk":"11816061906","pt":1722806572704,"mc":[{"id":"1.231398046","rc":[{"batb":[[0,2.14,62],[1,2.08,41.06],[2,1.9,259.67]],"ltp":2.14,"tv":907.97,"id":40096581}]}]}
{"op":"mcm","clk":"11816062574","pt":1722806586410,"mc":[{"id":"1.231398046","rc":[{"batb":[[0,2.18,10],[1,2.16,5.95],[2,2.14,62]],"ltp":2.14,"tv":907.97,"id":40096581}]}]}
{"op":"mcm","clk":"11816062669","pt":1722806588016,"mc":[{"id":"1.231398046","rc":[{"batb":[[1,2.14,62],[2,2.08,41.06]],"ltp":2.14,"tv":907.97,"id":40096581}]}]}
{"op":"mcm","clk":"11816062762","pt":1722806589714,"mc":[{"id":"1.231398046","rc":[{"batb":[[0,2.14,62],[1,2.08,41.06],[2,1.9,259.67]],"ltp":2.14,"tv":907.97,"id":40096581}]}]}
{"op":"mcm","clk":"11816063822","pt":1722806608958,"mc":[{"id":"1.231398046","rc":[{"batb":[[0,2.16,10],[1,2.14,62],[2,2.08,41.06]],"ltp":2.14,"tv":907.97,"id":40096581}]}]}
{"op":"mcm","clk":"11816063987","pt":1722806612259,"mc":[{"id":"1.231398046","rc":[{"batb":[[0,2.14,62],[1,2.08,41.06],[2,1.9,259.67]],"ltp":2.14,"tv":907.97,"id":40096581}]}]}
{"op":"mcm","clk":"11816064438","pt":1722806621071,"mc":[{"id":"1.231398046","rc":[{"batb":[[0,2.18,10],[1,2.16,5.95],[2,2.14,62]],"ltp":2.14,"tv":907.97,"id":40096581}]}]}
{"op":"mcm","clk":"11816064522","pt":1722806622771,"mc":[{"id":"1.231398046","rc":[{"batb":[[1,2.14,62],[2,2.08,41.06]],"ltp":2.14,"tv":907.97,"id":40096581}]}]}
{"op":"mcm","clk":"11816064615","pt":1722806624368,"mc":[{"id":"1.231398046","rc":[{"batb":[[0,2.14,62],[1,2.08,41.06],[2,1.9,259.67]],"ltp":2.14,"tv":907.97,"id":40096581}]}]}
{"op":"mcm","clk":"11816065323","pt":1722806636310,"mc":[{"id":"1.231398046","rc":[{"batb":[[0,2.16,10],[1,2.14,62],[2,2.08,41.06]],"ltp":2.14,"tv":907.97,"id":40096581}]}]}
{"op":"mcm","clk":"11816065496","pt":1722806639699,"mc":[{"id":"1.231398046","rc":[{"batb":[[0,2.14,62],[1,2.08,41.06],[2,1.9,259.67]],"ltp":2.14,"tv":907.97,"id":40096581}]}]}
{"op":"mcm","clk":"11816066351","pt":1722806656304,"mc":[{"id":"1.231398046","rc":[{"batb":[[0,2.18,10],[1,2.16,5.95],[2,2.14,62]],"ltp":2.14,"tv":907.97,"id":40096581}]}]}
{"op":"mcm","clk":"11816066438","pt":1722806658050,"mc":[{"id":"1.231398046","rc":[{"batb":[[1,2.14,62],[2,2.08,41.06]],"ltp":2.14,"tv":907.97,"id":40096581}]}]}
{"op":"mcm","clk":"11816066508","pt":1722806659646,"mc":[{"id":"1.231398046","rc":[{"batb":[[0,2.14,62],[1,2.08,41.06],[2,1.9,259.67]],"ltp":2.14,"tv":907.97,"id":40096581}]}]}
{"op":"mcm","clk":"11816066967","pt":1722806667840,"mc":[{"id":"1.231398046","rc":[{"batb":[[0,2.16,10],[1,2.14,62],[2,2.08,41.06]],"ltp":2.14,"tv":907.97,"id":40096581}]}]}
{"op":"mcm","clk":"11816067156","pt":1722806671244,"mc":[{"id":"1.231398046","rc":[{"batb":[[0,2.14,62],[1,2.08,41.06],[2,1.9,259.67]],"ltp":2.14,"tv":907.97,"id":40096581}]}]}
{"op":"mcm","clk":"11816067604","pt":1722806679355,"mc":[{"id":"1.231398046","rc":[{"batb":[[0,2.16,10],[1,2.14,62],[2,2.08,41.06]],"ltp":2.14,"tv":907.97,"id":40096581}]}]}
{"op":"mcm","clk":"11816067776","pt":1722806682861,"mc":[{"id":"1.231398046","rc":[{"batb":[[0,2.14,62],[1,2.08,41.06],[2,1.9,259.67]],"ltp":2.14,"tv":907.97,"id":40096581}]}]}
{"op":"mcm","clk":"11816068219","pt":1722806690648,"mc":[{"id":"1.231398046","rc":[{"batb":[[0,2.18,10],[1,2.16,5.95],[2,2.14,62]],"ltp":2.14,"tv":907.97,"id":40096581}]}]}
{"op":"mcm","clk":"11816068309","pt":1722806692194,"mc":[{"id":"1.231398046","rc":[{"batb":[[1,2.14,62],[2,2.08,41.06]],"ltp":2.14,"tv":907.97,"id":40096581}]}]}
{"op":"mcm","clk":"11816068408","pt":1722806693898,"mc":[{"id":"1.231398046","rc":[{"batb":[[0,2.14,62],[1,2.08,41.06],[2,1.9,259.67]],"ltp":2.14,"tv":907.97,"id":40096581}]}]}
{"op":"mcm","clk":"11816068531","pt":1722806696265,"mc":[{"id":"1.231398046","rc":[{"batb":[[0,2.16,10],[1,2.14,62],[2,2.08,41.06]],"ltp":2.14,"tv":907.97,"id":40096581}]}]}
{"op":"mcm","clk":"11816068723","pt":1722806699775,"mc":[{"id":"1.231398046","rc":[{"batb":[[0,2.14,62],[1,2.08,41.06],[2,1.9,259.67]],"ltp":2.14,"tv":907.97,"id":40096581}]}]}
{"op":"mcm","clk":"11816069582","pt":1722806714188,"mc":[{"id":"1.231398046","rc":[{"batb":[[0,2.16,10],[1,2.14,62],[2,2.08,41.06]],"ltp":2.14,"tv":907.97,"id":40096581}]}]}
{"op":"mcm","clk":"11816069764","pt":1722806717692,"mc":[{"id":"1.231398046","rc":[{"batb":[[0,2.14,62],[1,2.08,41.06],[2,1.9,259.67]],"ltp":2.14,"tv":907.97,"id":40096581}]}]}
{"op":"mcm","clk":"11816070159","pt":1722806725421,"mc":[{"id":"1.231398046","rc":[{"batb":[[0,2.18,10],[1,2.16,5.95],[2,2.14,62]],"ltp":2.14,"tv":907.97,"id":40096581}]}]}
{"op":"mcm","clk":"11816070281","pt":1722806727126,"mc":[{"id":"1.231398046","rc":[{"batb":[[1,2.14,62],[2,2.08,41.06]],"ltp":2.14,"tv":907.97,"id":40096581}]}]}
{"op":"mcm","clk":"11816070367","pt":1722806728824,"mc":[{"id":"1.231398046","rc":[{"batb":[[0,2.14,62],[1,2.08,41.06],[2,1.9,259.67]],"ltp":2.14,"tv":907.97,"id":40096581}]}]}
{"op":"mcm","clk":"11816071472","pt":1722806750740,"mc":[{"id":"1.231398046","rc":[{"batb":[[0,2.16,10],[1,2.14,62],[2,2.08,41.06]],"ltp":2.14,"tv":907.97,"id":40096581}]}]}
{"op":"mcm","clk":"11816071672","pt":1722806754241,"mc":[{"id":"1.231398046","rc":[{"batb":[[0,2.14,62],[1,2.08,41.06],[2,1.9,259.67]],"ltp":2.14,"tv":907.97,"id":40096581}]}]}
{"op":"mcm","clk":"11816071969","pt":1722806760372,"mc":[{"id":"1.231398046","rc":[{"batb":[[0,2.16,15.95],[1,2.14,62],[2,2.08,41.06]],"ltp":2.14,"tv":907.97,"id":40096581}]}]}
{"op":"mcm","clk":"11816072188","pt":1722806763736,"mc":[{"id":"1.231398046","rc":[{"batb":[[0,2.16,5.95]],"ltp":2.14,"tv":907.97,"id":40096581}]}]}
{"op":"mcm","clk":"11816072484","pt":1722806768273,"mc":[{"id":"1.231398046","rc":[{"batb":[[0,2.18,10],[1,2.16,5.95],[2,2.14,62]],"ltp":2.14,"tv":907.97,"id":40096581}]}]}
{"op":"mcm","clk":"11816072529","pt":1722806769255,"mc":[{"id":"1.231398046","rc":[{"batb":[[1,2.14,62],[2,2.08,41.06]],"ltp":2.14,"tv":907.97,"id":40096581}]}]}
{"op":"mcm","clk":"11816072657","pt":1722806771680,"mc":[{"id":"1.231398046","rc":[{"batb":[[0,2.14,62],[1,2.08,41.06],[2,1.9,259.67]],"ltp":2.14,"tv":907.97,"id":40096581}]}]}
{"op":"mcm","clk":"11816073049","pt":1722806778756,"mc":[{"id":"1.231398046","rc":[{"batb":[[0,2.16,10],[1,2.14,62],[2,2.08,41.06]],"ltp":2.14,"tv":907.97,"id":40096581}]}]}
{"op":"mcm","clk":"11816073252","pt":1722806782190,"mc":[{"id":"1.231398046","rc":[{"batb":[[0,2.14,62],[1,2.08,41.06],[2,1.9,259.67]],"ltp":2.14,"tv":907.97,"id":40096581}]}]}
{"op":"mcm","clk":"11816073470","pt":1722806785498,"mc":[{"id":"1.231398046","rc":[{"batb":[[0,2.16,10],[1,2.14,62],[2,2.08,41.06]],"ltp":2.14,"tv":907.97,"id":40096581}]}]}
{"op":"mcm","clk":"11816073659","pt":1722806788800,"mc":[{"id":"1.231398046","rc":[{"batb":[[0,2.14,62],[1,2.08,41.06],[2,1.9,259.67]],"ltp":2.14,"tv":907.97,"id":40096581}]}]}
{"op":"mcm","clk":"11816073909","pt":1722806793777,"mc":[{"id":"1.231398046","rc":[{"batb":[[0,2.18,10],[1,2.16,5.95],[2,2.14,62]],"ltp":2.14,"tv":907.97,"id":40096581}]}]}
{"op":"mcm","clk":"11816073995","pt":1722806795481,"mc":[{"id":"1.231398046","rc":[{"batb":[[1,2.14,62],[2,2.08,41.06]],"ltp":2.14,"tv":907.97,"id":40096581}]}]}
{"op":"mcm","clk":"11816074089","pt":1722806797183,"mc":[{"id":"1.231398046","rc":[{"batb":[[0,2.14,62],[1,2.08,41.06],[2,1.9,259.67]],"ltp":2.14,"tv":907.97,"id":40096581}]}]}
{"op":"mcm","clk":"11816074629","pt":1722806806918,"mc":[{"id":"1.231398046","rc":[{"batb":[[0,2.16,10],[1,2.14,62],[2,2.08,41.06]],"ltp":2.14,"tv":907.97,"id":40096581}]}]}
{"op":"mcm","clk":"11816074799","pt":1722806810328,"mc":[{"id":"1.231398046","rc":[{"batb":[[0,2.14,62],[1,2.08,41.06],[2,1.9,259.67]],"ltp":2.14,"tv":907.97,"id":40096581}]}]}
{"op":"mcm","clk":"11816075741","pt":1722806826455,"mc":[{"id":"1.231398046","rc":[{"batb":[[0,2.16,10],[1,2.14,62],[2,2.08,41.06]],"ltp":2.14,"tv":907.97,"id":40096581}]}]}
{"op":"mcm","clk":"11816075826","pt":1722806828105,"mc":[{"id":"1.231398046","rc":[{"batb":[[0,2.16,15.95]],"ltp":2.14,"tv":907.97,"id":40096581}]}]}
{"op":"mcm","clk":"11816075905","pt":1722806829854,"mc":[{"id":"1.231398046","rc":[{"batb":[[0,2.16,5.95]],"ltp":2.14,"tv":907.97,"id":40096581}]}]}
{"op":"mcm","clk":"11816076045","pt":1722806833255,"mc":[{"id":"1.231398046","rc":[{"batb":[[0,2.18,10],[1,2.16,5.95],[2,2.14,62]],"ltp":2.14,"tv":907.97,"id":40096581}]}]}
{"op":"mcm","clk":"11816076116","pt":1722806834444,"mc":[{"id":"1.231398046","rc":[{"batb":[[1,2.14,62],[2,2.08,41.06]],"ltp":2.14,"tv":907.97,"id":40096581}]}]}
{"op":"mcm","clk":"11816076246","pt":1722806836660,"mc":[{"id":"1.231398046","rc":[{"batb":[[0,2.14,62],[1,2.08,41.06],[2,1.9,259.67]],"ltp":2.14,"tv":907.97,"id":40096581}]}]}
{"op":"mcm","clk":"11816077469","pt":1722806861970,"mc":[{"id":"1.231398046","rc":[{"batb":[[0,2.18,10],[1,2.16,5.95],[2,2.14,62]],"ltp":2.14,"tv":907.97,"id":40096581}]}]}
{"op":"mcm","clk":"11816077537","pt":1722806863565,"mc":[{"id":"1.231398046","rc":[{"batb":[[1,2.14,62],[2,2.08,41.06]],"ltp":2.14,"tv":907.97,"id":40096581}]}]}
{"op":"mcm","clk":"11816077597","pt":1722806865261,"mc":[{"id":"1.231398046","rc":[{"batb":[[0,2.14,62],[1,2.08,41.06],[2,1.9,259.67]],"ltp":2.14,"tv":907.97,"id":40096581}]}]}
{"op":"mcm","clk":"11816077742","pt":1722806868655,"mc":[{"id":"1.231398046","rc":[{"batb":[[0,2.16,10],[1,2.14,62],[2,2.08,41.06]],"ltp":2.14,"tv":907.97,"id":40096581}]}]}
{"op":"mcm","clk":"11816077884","pt":1722806872006,"mc":[{"id":"1.231398046","rc":[{"batb":[[0,2.14,62],[1,2.08,41.06],[2,1.9,259.67]],"ltp":2.14,"tv":907.97,"id":40096581}]}]}
{"op":"mcm","clk":"11816078274","pt":1722806879672,"mc":[{"id":"1.231398046","rc":[{"batb":[[0,2.16,10],[1,2.14,62],[2,2.08,41.06]],"ltp":2.14,"tv":907.97,"id":40096581}]}]}
{"op":"mcm","clk":"11816078456","pt":1722806883080,"mc":[{"id":"1.231398046","rc":[{"batb":[[0,2.14,62],[1,2.08,41.06],[2,1.9,259.67]],"ltp":2.14,"tv":907.97,"id":40096581}]}]}
{"op":"mcm","clk":"11816079096","pt":1722806894826,"mc":[{"id":"1.231398046","rc":[{"batb":[[0,2.16,10],[1,2.14,62],[2,2.08,41.06]],"ltp":2.14,"tv":907.97,"id":40096581}]}]}
{"op":"mcm","clk":"11816079249","pt":1722806897198,"mc":[{"id":"1.231398046","rc":[{"batb":[[0,2.16,15.95]],"ltp":2.14,"tv":907.97,"id":40096581}]}]}
{"op":"mcm","clk":"11816079288","pt":1722806898230,"mc":[{"id":"1.231398046","rc":[{"batb":[[0,2.16,5.95]],"ltp":2.14,"tv":907.97,"id":40096581}]}]}
{"op":"mcm","clk":"11816080520","pt":1722806920612,"mc":[{"id":"1.231398046","rc":[{"batb":[[0,2.18,10],[1,2.16,5.95],[2,2.14,62]],"ltp":2.14,"tv":907.97,"id":40096581}]}]}
{"op":"mcm","clk":"11816080565","pt":1722806921539,"mc":[{"id":"1.231398046","rc":[{"batb":[[1,2.14,62],[2,2.08,41.06]],"ltp":2.14,"tv":907.97,"id":40096581}]}]}
{"op":"mcm","clk":"11816080721","pt":1722806923966,"mc":[{"id":"1.231398046","rc":[{"batb":[[0,2.14,62],[1,2.08,41.06],[2,1.9,259.67]],"ltp":2.14,"tv":907.97,"id":40096581}]}]}
{"op":"mcm","clk":"11816080923","pt":1722806928140,"mc":[{"id":"1.231398046","rc":[{"batb":[[0,2.16,10],[1,2.14,62],[2,2.08,41.06]],"ltp":2.14,"tv":907.97,"id":40096581}]}]}
{"op":"mcm","clk":"11816081099","pt":1722806931443,"mc":[{"id":"1.231398046","rc":[{"batb":[[0,2.16,5.95]],"ltp":2.14,"tv":907.97,"id":40096581}]}]}
{"op":"mcm","clk":"11816082609","pt":1722806958295,"mc":[{"id":"1.231398046","rc":[{"batb":[[0,2.18,10],[1,2.16,5.95],[2,2.14,62]],"ltp":2.14,"tv":907.97,"id":40096581}]}]}
{"op":"mcm","clk":"11816082640","pt":1722806959023,"mc":[{"id":"1.231398046","rc":[{"batb":[[1,2.14,62],[2,2.08,41.06]],"ltp":2.14,"tv":907.97,"id":40096581}]}]}
{"op":"mcm","clk":"11816082788","pt":1722806961598,"mc":[{"id":"1.231398046","rc":[{"batb":[[0,2.14,62],[1,2.08,41.06],[2,1.9,259.67]],"ltp":2.14,"tv":907.97,"id":40096581}]}]}
{"op":"mcm","clk":"11816082967","pt":1722806965006,"mc":[{"id":"1.231398046","rc":[{"batb":[[0,2.18,10],[1,2.16,5.95],[2,2.14,62]],"ltp":2.14,"tv":907.97,"id":40096581}]}]}
{"op":"mcm","clk":"11816083081","pt":1722806966805,"mc":[{"id":"1.231398046","rc":[{"batb":[[1,2.14,62],[2,2.08,41.06]],"ltp":2.14,"tv":907.97,"id":40096581}]}]}
{"op":"mcm","clk":"11816083177","pt":1722806968409,"mc":[{"id":"1.231398046","rc":[{"batb":[[0,2.14,62],[1,2.08,41.06],[2,1.9,259.67]],"ltp":2.14,"tv":907.97,"id":40096581}]}]}
{"op":"mcm","clk":"11816083477","pt":1722806973422,"mc":[{"id":"1.231398046","rc":[{"batb":[[0,2.16,10],[1,2.14,62],[2,2.08,41.06]],"ltp":2.14,"tv":907.97,"id":40096581}]}]}
{"op":"mcm","clk":"11816083677","pt":1722806976717,"mc":[{"id":"1.231398046","rc":[{"batb":[[0,2.14,62],[1,2.08,41.06],[2,1.9,259.67]],"ltp":2.14,"tv":907.97,"id":40096581}]}]}
{"op":"mcm","clk":"11816084846","pt":1722806998647,"mc":[{"id":"1.231398046","rc":[{"batb":[[0,2.18,10],[1,2.16,5.95],[2,2.14,62]],"ltp":2.14,"tv":907.97,"id":40096581}]}]}
{"op":"mcm","clk":"11816084929","pt":1722807000142,"mc":[{"id":"1.231398046","rc":[{"batb":[[1,2.14,62],[2,2.08,41.06]],"ltp":2.14,"tv":907.97,"id":40096581}]}]}
{"op":"mcm","clk":"11816085071","pt":1722807001950,"mc":[{"id":"1.231398046","rc":[{"batb":[[0,2.14,62],[1,2.08,41.06],[2,1.9,259.67]],"ltp":2.14,"tv":907.97,"id":40096581}]}]}
{"op":"mcm","clk":"11816086864","pt":1722807033228,"mc":[{"id":"1.231398046","rc":[{"batb":[[0,2.18,10],[1,2.16,5.95],[2,2.14,62]],"ltp":2.14,"tv":907.97,"id":40096581}]}]}
{"op":"mcm","clk":"11816086943","pt":1722807034724,"mc":[{"id":"1.231398046","rc":[{"batb":[[1,2.14,62],[2,2.08,41.06]],"ltp":2.14,"tv":907.97,"id":40096581}]}]}
{"op":"mcm","clk":"11816087041","pt":1722807036524,"mc":[{"id":"1.231398046","rc":[{"batb":[[0,2.14,62],[1,2.08,41.06],[2,1.9,259.67]],"ltp":2.14,"tv":907.97,"id":40096581}]}]}
{"op":"mcm","clk":"11816087267","pt":1722807040300,"mc":[{"id":"1.231398046","rc":[{"batb":[[0,2.16,10],[1,2.14,62],[2,2.08,41.06]],"ltp":2.14,"tv":907.97,"id":40096581}]}]}
{"op":"mcm","clk":"11816087487","pt":1722807043803,"mc":[{"id":"1.231398046","rc":[{"batb":[[0,2.14,62],[1,2.08,41.06],[2,1.9,259.67]],"ltp":2.14,"tv":907.97,"id":40096581}]}]}
{"op":"mcm","clk":"11816087771","pt":1722807048522,"mc":[{"id":"1.231398046","rc":[{"batb":[[0,2.16,10],[1,2.14,62],[2,2.08,41.06]],"ltp":2.14,"tv":907.97,"id":40096581}]}]}
{"op":"mcm","clk":"11816087996","pt":1722807051924,"mc":[{"id":"1.231398046","rc":[{"batb":[[0,2.14,62],[1,2.08,41.06],[2,1.9,259.67]],"ltp":2.14,"tv":907.97,"id":40096581}]}]}
{"op":"mcm","clk":"11816088496","pt":1722807059725,"mc":[{"id":"1.231398046","rc":[{"batb":[[0,2.16,10],[1,2.14,62],[2,2.08,41.06]],"ltp":2.14,"tv":907.97,"id":40096581}]}]}
{"op":"mcm","clk":"11816088732","pt":1722807063144,"mc":[{"id":"1.231398046","rc":[{"batb":[[0,2.14,62],[1,2.08,41.06],[2,1.9,259.67]],"ltp":2.14,"tv":907.97,"id":40096581}]}]}
{"op":"mcm","clk":"11816088986","pt":1722807067440,"mc":[{"id":"1.231398046","rc":[{"batb":[[0,2.16,5.95],[1,2.14,62],[2,2.08,41.06]],"ltp":2.14,"tv":907.97,"id":40096581}]}]}
{"op":"mcm","clk":"11816088992","pt":1722807067545,"mc":[{"id":"1.231398046","rc":[{"batb":[[0,2.18,10],[1,2.16,5.95],[2,2.14,62]],"ltp":2.14,"tv":907.97,"id":40096581}]}]}
{"op":"mcm","clk":"11816089122","pt":1722807069454,"mc":[{"id":"1.231398046","rc":[{"batb":[[1,2.14,62],[2,2.08,41.06]],"ltp":2.14,"tv":907.97,"id":40096581}]}]}
{"op":"mcm","clk":"11816089210","pt":1722807070860,"mc":[{"id":"1.231398046","rc":[{"batb":[[0,2.14,62],[1,2.08,41.06],[2,1.9,259.67]],"ltp":2.14,"tv":907.97,"id":40096581}]}]}
{"op":"mcm","clk":"11816089843","pt":1722807081168,"mc":[{"id":"1.231398046","rc":[{"batb":[[0,2.16,10],[1,2.14,62],[2,2.08,41.06]],"ltp":2.14,"tv":907.97,"id":40096581}]}]}
{"op":"mcm","clk":"11816090096","pt":1722807084791,"mc":[{"id":"1.231398046","rc":[{"batb":[[0,2.14,62],[1,2.08,41.06],[2,1.9,259.67]],"ltp":2.14,"tv":907.97,"id":40096581}]}]}
{"op":"mcm","clk":"11816091261","pt":1722807102416,"mc":[{"id":"1.231398046","rc":[{"batb":[[0,2.18,10],[1,2.16,5.95],[2,2.14,62]],"ltp":2.14,"tv":907.97,"id":40096581}]}]}
{"op":"mcm","clk":"11816091356","pt":1722807104016,"mc":[{"id":"1.231398046","rc":[{"batb":[[1,2.14,62],[2,2.08,41.06]],"ltp":2.14,"tv":907.97,"id":40096581}]}]}
{"op":"mcm","clk":"11816091461","pt":1722807105783,"mc":[{"id":"1.231398046","rc":[{"batb":[[0,2.14,62],[1,2.08,41.06],[2,1.9,259.67]],"ltp":2.14,"tv":907.97,"id":40096581}]}]}
{"op":"mcm","clk":"11816093748","pt":1722807137947,"mc":[{"id":"1.231398046","rc":[{"batb":[[0,2.18,10],[1,2.16,5.95],[2,2.14,62]],"ltp":2.14,"tv":907.97,"id":40096581}]}]}
{"op":"mcm","clk":"11816093845","pt":1722807139609,"mc":[{"id":"1.231398046","rc":[{"batb":[[1,2.14,62],[2,2.08,41.06]],"ltp":2.14,"tv":907.97,"id":40096581}]}]}
{"op":"mcm","clk":"11816093983","pt":1722807141214,"mc":[{"id":"1.231398046","rc":[{"batb":[[0,2.14,62],[1,2.08,41.06],[2,1.9,259.67]],"ltp":2.14,"tv":907.97,"id":40096581}]}]}
{"op":"mcm","clk":"11816095080","pt":1722807156739,"mc":[{"id":"1.231398046","rc":[{"batb":[[0,2.16,10],[1,2.14,62],[2,2.08,41.06]],"ltp":2.14,"tv":907.97,"id":40096581}]}]}
{"op":"mcm","clk":"11816095311","pt":1722807160249,"mc":[{"id":"1.231398046","rc":[{"batb":[[0,2.14,62],[1,2.08,41.06],[2,1.9,259.67]],"ltp":2.14,"tv":907.97,"id":40096581}]}]}
{"op":"mcm","clk":"11816096235","pt":1722807173375,"mc":[{"id":"1.231398046","rc":[{"batb":[[0,2.18,10],[1,2.16,5.95],[2,2.14,62]],"ltp":2.14,"tv":907.97,"id":40096581}]}]}
{"op":"mcm","clk":"11816096345","pt":1722807175076,"mc":[{"id":"1.231398046","rc":[{"batb":[[1,2.14,62],[2,2.08,41.06]],"ltp":2.14,"tv":907.97,"id":40096581}]}]}
{"op":"mcm","clk":"11816096407","pt":1722807175954,"mc":[{"id":"1.231398046","rc":[{"batb":[[1,2.14,88]],"ltp":2.14,"tv":907.97,"id":40096581}]}]}
{"op":"mcm","clk":"11816096460","pt":1722807176780,"mc":[{"id":"1.231398046","rc":[{"batb":[[0,2.14,88],[1,2.08,41.06],[2,1.9,259.67]],"ltp":2.14,"tv":907.97,"id":40096581}]}]}
{"op":"mcm","clk":"11816096532","pt":1722807177758,"mc":[{"id":"1.231398046","rc":[{"batb":[[0,2.16,5.17],[1,2.14,88],[2,2.08,41.06]],"ltp":2.14,"tv":907.97,"id":40096581}]}]}
{"op":"mcm","clk":"11816098051","pt":1722807198882,"mc":[{"id":"1.231398046","rc":[{"batb":[[0,2.18,10],[1,2.16,5.17],[2,2.14,88]],"ltp":2.14,"tv":907.97,"id":40096581}]}]}
{"op":"mcm","clk":"11816098158","pt":1722807200690,"mc":[{"id":"1.231398046","rc":[{"batb":[[1,2.14,88],[2,2.08,41.06]],"ltp":2.14,"tv":907.97,"id":40096581}]}]}
{"op":"mcm","clk":"11816098261","pt":1722807202290,"mc":[{"id":"1.231398046","rc":[{"batb":[[0,2.14,88],[1,2.08,41.06],[2,1.9,259.67]],"ltp":2.14,"tv":907.97,"id":40096581}]}]}
{"op":"mcm","clk":"11816098586","pt":1722807207481,"mc":[{"id":"1.231398046","rc":[{"batb":[[0,2.16,7.91],[1,2.14,88],[2,2.08,41.06]],"ltp":2.14,"tv":907.97,"id":40096581}]}]}
{"op":"mcm","clk":"11816098598","pt":1722807207677,"mc":[{"id":"1.231398046","rc":[{"batb":[[0,2.18,10],[1,2.16,7.91],[2,2.14,88]],"ltp":2.14,"tv":907.97,"id":40096581}]}]}
{"op":"mcm","clk":"11816098709","pt":1722807209387,"mc":[{"id":"1.231398046","rc":[{"batb":[[1,2.14,88],[2,2.08,41.06]],"ltp":2.14,"tv":907.97,"id":40096581}]}]}
{"op":"mcm","clk":"11816098816","pt":1722807211110,"mc":[{"id":"1.231398046","rc":[{"batb":[[0,2.14,88],[1,2.08,41.06],[2,1.9,259.67]],"ltp":2.14,"tv":907.97,"id":40096581}]}]}
{"op":"mcm","clk":"11816100900","pt":1722807242999,"mc":[{"id":"1.231398046","rc":[{"batb":[[0,2.18,10],[1,2.16,7.91],[2,2.14,88]],"ltp":2.14,"tv":907.97,"id":40096581}]}]}
{"op":"mcm","clk":"11816101018","pt":1722807244744,"mc":[{"id":"1.231398046","rc":[{"batb":[[1,2.14,88],[2,2.08,41.06]],"ltp":2.14,"tv":907.97,"id":40096581}]}]}
{"op":"mcm","clk":"11816101149","pt":1722807246405,"mc":[{"id":"1.231398046","rc":[{"batb":[[0,2.14,88],[1,2.08,41.06],[2,1.9,259.67]],"ltp":2.14,"tv":907.97,"id":40096581}]}]}
{"op":"mcm","clk":"11816101939","pt":1722807257941,"mc":[{"id":"1.231398046","rc":[{"batb":[[0,2.18,10],[1,2.16,5.17],[2,2.14,88]],"ltp":2.14,"tv":907.97,"id":40096581}]}]}
{"op":"mcm","clk":"11816102020","pt":1722807259138,"mc":[{"id":"1.231398046","rc":[{"batb":[[1,2.14,88],[2,2.08,41.06]],"ltp":2.14,"tv":907.97,"id":40096581}]}]}
{"op":"mcm","clk":"11816102179","pt":1722807261315,"mc":[{"id":"1.231398046","rc":[{"batb":[[0,2.14,88],[1,2.08,41.06],[2,1.9,259.67]],"ltp":2.14,"tv":907.97,"id":40096581}]}]}
{"op":"mcm","clk":"11816102711","pt":1722807269133,"mc":[{"id":"1.231398046","rc":[{"batb":[[0,2.16,10],[1,2.14,88],[2,2.08,41.06]],"ltp":2.14,"tv":907.97,"id":40096581}]}]}
{"op":"mcm","clk":"11816102918","pt":1722807272538,"mc":[{"id":"1.231398046","rc":[{"batb":[[0,2.14,88],[1,2.08,41.06],[2,1.9,259.67]],"ltp":2.14,"tv":907.97,"id":40096581}]}]}
{"op":"mcm","clk":"11816103010","pt":1722807274060,"mc":[{"id":"1.231398046","rc":[{"batl":[[0,1.87,179.74]],"ltp":1.82,"tv":1148.28,"id":40096579}]}]}
{"op":"mcm","clk":"11816103214","pt":1722807277072,"mc":[{"id":"1.231398046","rc":[{"batb":[[0,2.18,10],[1,2.16,14.96],[2,2.14,88]],"ltp":2.14,"tv":907.97,"id":40096581}]}]}
{"op":"mcm","clk":"11816103321","pt":1722807278671,"mc":[{"id":"1.231398046","rc":[{"batb":[[1,2.14,88],[2,2.08,41.06]],"ltp":2.14,"tv":907.97,"id":40096581}]}]}
{"op":"mcm","clk":"11816103431","pt":1722807280382,"mc":[{"id":"1.231398046","rc":[{"batb":[[0,2.14,88],[1,2.08,41.06],[2,1.9,259.67]],"ltp":2.14,"tv":907.97,"id":40096581}]}]}
{"op":"mcm","clk":"11816105371","pt":1722807308300,"mc":[{"id":"1.231398046","rc":[{"batb":[[0,2.16,10],[1,2.14,88],[2,2.08,41.06]],"ltp":2.14,"tv":907.97,"id":40096581}]}]}
{"op":"mcm","clk":"11816105602","pt":1722807311620,"mc":[{"id":"1.231398046","rc":[{"batb":[[0,2.14,88],[1,2.08,41.06],[2,1.9,259.67]],"ltp":2.14,"tv":907.97,"id":40096581}]}]}
{"op":"mcm","clk":"11816105682","pt":1722807312607,"mc":[{"id":"1.231398046","rc":[{"batb":[[0,2.16,14.96],[1,2.14,88],[2,2.08,41.06]],"ltp":2.14,"tv":907.97,"id":40096581}]}]}
{"op":"mcm","clk":"11816106073","pt":1722807317888,"mc":[{"id":"1.231398046","rc":[{"batb":[[0,2.18,10],[1,2.16,14.96],[2,2.14,88]],"ltp":2.14,"tv":907.97,"id":40096581}]}]}
{"op":"mcm","clk":"11816106184","pt":1722807319440,"mc":[{"id":"1.231398046","rc":[{"batb":[[1,2.14,88],[2,2.08,41.06]],"ltp":2.14,"tv":907.97,"id":40096581}]}]}
{"op":"mcm","clk":"11816106334","pt":1722807321517,"mc":[{"id":"1.231398046","rc":[{"batb":[[0,2.14,88],[1,2.08,41.06],[2,1.9,259.67]],"ltp":2.14,"tv":907.97,"id":40096581}]}]}
{"op":"mcm","clk":"11816106850","pt":1722807329215,"mc":[{"id":"1.231398046","rc":[{"batb":[[0,2.16,10],[1,2.14,88],[2,2.08,41.06]],"ltp":2.14,"tv":907.97,"id":40096581}]}]}
{"op":"mcm","clk":"11816107080","pt":1722807332530,"mc":[{"id":"1.231398046","rc":[{"batb":[[0,2.14,88],[1,2.08,41.06],[2,1.9,259.67]],"ltp":2.14,"tv":907.97,"id":40096581}]}]}
{"op":"mcm","clk":"11816107448","pt":1722807338030,"mc":[{"id":"1.231398046","rc":[{"batb":[[0,2.18,10],[1,2.16,12.03],[2,2.14,88]],"ltp":2.14,"tv":907.97,"id":40096581}]}]}
{"op":"mcm","clk":"11816107525","pt":1722807339432,"mc":[{"id":"1.231398046","rc":[{"batb":[[1,2.14,88],[2,2.08,41.06]],"ltp":2.14,"tv":907.97,"id":40096581}]}]}
{"op":"mcm","clk":"11816107649","pt":1722807341408,"mc":[{"id":"1.231398046","rc":[{"batb":[[0,2.14,88],[1,2.08,41.06],[2,1.9,259.67]],"ltp":2.14,"tv":907.97,"id":40096581}]}]}
{"op":"mcm","clk":"11816108018","pt":1722807347118,"mc":[{"id":"1.231398046","rc":[{"batb":[[0,2.18,10],[1,2.16,14.96],[2,2.14,88]],"ltp":2.14,"tv":907.97,"id":40096581}]}]}
{"op":"mcm","clk":"11816108127","pt":1722807348719,"mc":[{"id":"1.231398046","rc":[{"batb":[[1,2.14,88],[2,2.08,41.06]],"ltp":2.14,"tv":907.97,"id":40096581}]}]}
{"op":"mcm","clk":"11816108245","pt":1722807350426,"mc":[{"id":"1.231398046","rc":[{"batb":[[0,2.14,88],[1,2.08,41.06],[2,1.9,259.67]],"ltp":2.14,"tv":907.97,"id":40096581}]}]}
{"op":"mcm","clk":"11816110322","pt":1722807381187,"mc":[{"id":"1.231398046","rc":[{"batb":[[0,2.18,10],[1,2.16,14.96],[2,2.14,88]],"ltp":2.14,"tv":907.97,"id":40096581}]}]}
{"op":"mcm","clk":"11816110424","pt":1722807382660,"mc":[{"id":"1.231398046","rc":[{"batb":[[1,2.14,88],[2,2.08,41.06]],"ltp":2.14,"tv":907.97,"id":40096581}]}]}
{"op":"mcm","clk":"11816110528","pt":1722807384370,"mc":[{"id":"1.231398046","rc":[{"batb":[[0,2.14,88],[1,2.08,41.06],[2,1.9,259.67]],"ltp":2.14,"tv":907.97,"id":40096581}]}]}
{"op":"mcm","clk":"11816111559","pt":1722807398572,"mc":[{"id":"1.231398046","rc":[{"batb":[[0,2.16,10],[1,2.14,88],[2,2.08,41.06]],"ltp":2.14,"tv":907.97,"id":40096581}]}]}
{"op":"mcm","clk":"11816111813","pt":1722807401985,"mc":[{"id":"1.231398046","rc":[{"batb":[[0,2.14,88],[1,2.08,41.06],[2,1.9,259.67]],"ltp":2.14,"tv":907.97,"id":40096581}]}]}
{"op":"mcm","clk":"11816112415","pt":1722807410592,"mc":[{"id":"1.231398046","rc":[{"batb":[[0,2.16,10],[1,2.14,88],[2,2.08,41.06]],"ltp":2.14,"tv":907.97,"id":40096581}]}]}
{"op":"mcm","clk":"11816112669","pt":1722807414111,"mc":[{"id":"1.231398046","rc":[{"batb":[[0,2.14,88],[1,2.08,41.06],[2,1.9,259.67]],"ltp":2.14,"tv":907.97,"id":40096581}]}]}
{"op":"mcm","clk":"11816112733","pt":1722807415201,"mc":[{"id":"1.231398046","rc":[{"batb":[[0,2.16,14.96],[1,2.14,88],[2,2.08,41.06]],"ltp":2.14,"tv":907.97,"id":40096581}]}]}
{"op":"mcm","clk":"11816113011","pt":1722807419105,"mc":[{"id":"1.231398046","rc":[{"batb":[[0,2.18,10],[1,2.16,26.99],[2,2.14,88]],"ltp":2.14,"tv":907.97,"id":40096581}]}]}
{"op":"mcm","clk":"11816113099","pt":1722807420500,"mc":[{"id":"1.231398046","rc":[{"batb":[[1,2.16,14.96]],"ltp":2.14,"tv":907.97,"id":40096581}]}]}
{"op":"mcm","clk":"11816113225","pt":1722807422117,"mc":[{"id":"1.231398046","rc":[{"batl":[[0,1.87,19.74]],"ltp":1.82,"tv":1148.28,"id":40096579},{"batb":[[1,2.14,88],[2,2.08,41.06]],"ltp":2.14,"tv":907.97,"id":40096581}]}]}
{"op":"mcm","clk":"11816113255","pt":1722807422529,"mc":[{"id":"1.231398046","rc":[{"batb":[[0,2.14,88],[1,2.08,41.06],[2,1.9,259.67]],"ltp":2.14,"tv":907.97,"id":40096581}]}]}
{"op":"mcm","clk":"11816113863","pt":1722807429899,"mc":[{"id":"1.231398046","rc":[{"batb":[[0,2.16,10],[1,2.14,88],[2,2.08,41.06]],"ltp":2.14,"tv":907.97,"id":40096581}]}]}
{"op":"mcm","clk":"11816114143","pt":1722807433214,"mc":[{"id":"1.231398046","rc":[{"batb":[[0,2.14,88],[1,2.08,41.06],[2,1.9,259.67]],"ltp":2.14,"tv":907.97,"id":40096581}]}]}
{"op":"mcm","clk":"11816114336","pt":1722807435824,"mc":[{"id":"1.231398046","rc":[{"batb":[[0,2.16,10],[1,2.14,88],[2,2.08,41.06]],"ltp":2.14,"tv":907.97,"id":40096581}]}]}
{"op":"mcm","clk":"11816114602","pt":1722807439344,"mc":[{"id":"1.231398046","rc":[{"batb":[[0,2.14,88],[1,2.08,41.06],[2,1.9,259.67]],"ltp":2.14,"tv":907.97,"id":40096581}]}]}
{"op":"mcm","clk":"11816115231","pt":1722807448055,"mc":[{"id":"1.231398046","rc":[{"batb":[[0,2.16,10],[1,2.14,88],[2,2.08,41.06]],"ltp":2.14,"tv":907.97,"id":40096581}]}]}
{"op":"mcm","clk":"11816115347","pt":1722807449512,"mc":[{"id":"1.231398046","rc":[{"batb":[[0,2.16,17.91]],"ltp":2.14,"tv":907.97,"id":40096581}]}]}
{"op":"mcm","clk":"11816115532","pt":1722807451533,"mc":[{"id":"1.231398046","rc":[{"batb":[[0,2.16,7.91]],"ltp":2.14,"tv":907.97,"id":40096581}]}]}
{"op":"mcm","clk":"11816116302","pt":1722807462642,"mc":[{"id":"1.231398046","rc":[{"batb":[[0,2.18,10],[1,2.16,7.91],[2,2.14,88]],"ltp":2.14,"tv":907.97,"id":40096581}]}]}
{"op":"mcm","clk":"11816116407","pt":1722807464040,"mc":[{"id":"1.231398046","rc":[{"batb":[[1,2.14,88],[2,2.08,41.06]],"ltp":2.14,"tv":907.97,"id":40096581}]}]}
{"op":"mcm","clk":"11816116533","pt":1722807465947,"mc":[{"id":"1.231398046","rc":[{"batb":[[0,2.14,88],[1,2.08,41.06],[2,1.9,259.67]],"ltp":2.14,"tv":907.97,"id":40096581}]}]}
{"op":"mcm","clk":"11816117776","pt":1722807483974,"mc":[{"id":"1.231398046","rc":[{"batb":[[0,2.18,10],[1,2.16,7.91],[2,2.14,88]],"ltp":2.14,"tv":907.97,"id":40096581}]}]}
{"op":"mcm","clk":"11816117915","pt":1722807485845,"mc":[{"id":"1.231398046","rc":[{"batb":[[1,2.14,88],[2,2.08,41.06]],"ltp":2.14,"tv":907.97,"id":40096581}]}]}
{"op":"mcm","clk":"11816118011","pt":1722807487269,"mc":[{"id":"1.231398046","rc":[{"batb":[[0,2.14,88],[1,2.08,41.06],[2,1.9,259.67]],"ltp":2.14,"tv":907.97,"id":40096581}]}]}
{"op":"mcm","clk":"11816118173","pt":1722807489579,"mc":[{"id":"1.231398046","rc":[{"batb":[[0,2.16,10],[1,2.14,88],[2,2.08,41.06]],"ltp":2.14,"tv":907.97,"id":40096581}]}]}
{"op":"mcm","clk":"11816118395","pt":1722807492896,"mc":[{"id":"1.231398046","rc":[{"batb":[[0,2.14,88],[1,2.08,41.06],[2,1.9,259.67]],"ltp":2.14,"tv":907.97,"id":40096581}]}]}
{"op":"mcm","clk":"11816118853","pt":1722807498907,"mc":[{"id":"1.231398046","rc":[{"batb":[[0,2.18,10],[1,2.16,5.17],[2,2.14,88]],"ltp":2.14,"tv":907.97,"id":40096581}]}]}
{"op":"mcm","clk":"11816119051","pt":1722807501300,"mc":[{"id":"1.231398046","rc":[{"batb":[[1,2.14,88],[2,2.08,41.06]],"ltp":2.14,"tv":907.97,"id":40096581}]}]}
{"op":"mcm","clk":"11816119125","pt":1722807502393,"mc":[{"id":"1.231398046","rc":[{"batb":[[0,2.14,88],[1,2.08,41.06],[2,1.9,259.67]],"ltp":2.14,"tv":907.97,"id":40096581}]}]}
{"op":"mcm","clk":"11816119979","pt":1722807514619,"mc":[{"id":"1.231398046","rc":[{"batb":[[0,2.16,10],[1,2.14,88],[2,2.08,41.06]],"ltp":2.14,"tv":907.97,"id":40096581}]}]}
{"op":"mcm","clk":"11816120222","pt":1722807518077,"mc":[{"id":"1.231398046","rc":[{"batb":[[0,2.16,7.91]],"ltp":2.14,"tv":907.97,"id":40096581}]}]}
{"op":"mcm","clk":"11816120506","pt":1722807522191,"mc":[{"id":"1.231398046","rc":[{"batb":[[0,2.18,10],[1,2.16,7.91],[2,2.14,88]],"ltp":2.14,"tv":907.97,"id":40096581}]}]}
{"op":"mcm","clk":"11816120553","pt":1722807523019,"mc":[{"id":"1.231398046","rc":[{"batb":[[1,2.14,88],[2,2.08,41.06]],"ltp":2.14,"tv":907.97,"id":40096581}]}]}
{"op":"mcm","clk":"11816120716","pt":1722807525614,"mc":[{"id":"1.231398046","rc":[{"batb":[[0,2.14,88],[1,2.08,41.06],[2,1.9,259.67]],"ltp":2.14,"tv":907.97,"id":40096581}]}]}
{"op":"mcm","clk":"11816122278","pt":1722807546626,"mc":[{"id":"1.231398046","rc":[{"batb":[[0,2.16,10],[1,2.14,88],[2,2.08,41.06]],"ltp":2.14,"tv":907.97,"id":40096581}]}]}
{"op":"mcm","clk":"11816122508","pt":1722807550051,"mc":[{"id":"1.231398046","rc":[{"batb":[[0,2.14,88],[1,2.08,41.06],[2,1.9,259.67]],"ltp":2.14,"tv":907.97,"id":40096581}]}]}
{"op":"mcm","clk":"11816122771","pt":1722807553134,"mc":[{"id":"1.231398046","rc":[{"batb":[[0,2.18,10],[1,2.16,7.91],[2,2.14,88]],"ltp":2.14,"tv":907.97,"id":40096581}]}]}
{"op":"mcm","clk":"11816122860","pt":1722807554835,"mc":[{"id":"1.231398046","rc":[{"batb":[[1,2.14,88],[2,2.08,41.06]],"ltp":2.14,"tv":907.97,"id":40096581}]}]}
{"op":"mcm","clk":"11816122986","pt":1722807556554,"mc":[{"id":"1.231398046","rc":[{"batb":[[0,2.14,88],[1,2.08,41.06],[2,1.9,259.67]],"ltp":2.14,"tv":907.97,"id":40096581}]}]}
{"op":"mcm","clk":"11816123930","pt":1722807569653,"mc":[{"id":"1.231398046","rc":[{"batb":[[0,2.16,10],[1,2.14,88],[2,2.08,41.06]],"ltp":2.14,"tv":907.97,"id":40096581}]}]}
{"op":"mcm","clk":"11816124226","pt":1722807573284,"mc":[{"id":"1.231398046","rc":[{"batb":[[0,2.14,88],[1,2.08,41.06],[2,1.9,259.67]],"ltp":2.14,"tv":907.97,"id":40096581}]}]}
{"op":"mcm","clk":"11816124515","pt":1722807577480,"mc":[{"id":"1.231398046","rc":[{"batb":[[0,2.16,10],[1,2.14,88],[2,2.08,41.06]],"ltp":2.14,"tv":907.97,"id":40096581}]}]}
{"op":"mcm","clk":"11816124646","pt":1722807579493,"mc":[{"id":"1.231398046","rc":[{"batb":[[0,2.16,15.17]],"ltp":2.14,"tv":907.97,"id":40096581}]}]}
{"op":"mcm","clk":"11816124750","pt":1722807580891,"mc":[{"id":"1.231398046","rc":[{"batb":[[0,2.16,5.17]],"ltp":2.14,"tv":907.97,"id":40096581}]}]}
{"op":"mcm","clk":"11816125194","pt":1722807588505,"mc":[{"id":"1.231398046","rc":[{"batb":[[0,2.18,10],[1,2.16,8.29],[2,2.14,88]],"ltp":2.14,"tv":907.97,"id":40096581}]}]}
{"op":"mcm","clk":"11816125277","pt":1722807589906,"mc":[{"id":"1.231398046","rc":[{"batb":[[1,2.14,88],[2,2.08,41.06]],"ltp":2.14,"tv":907.97,"id":40096581}]}]}
{"op":"mcm","clk":"11816125360","pt":1722807591306,"mc":[{"id":"1.231398046","rc":[{"batb":[[0,2.14,88],[1,2.08,41.06],[2,1.9,259.67]],"ltp":2.14,"tv":907.97,"id":40096581}]}]}
{"op":"mcm","clk":"11816126329","pt":1722807605188,"mc":[{"id":"1.231398046","rc":[{"batb":[[0,2.16,10],[1,2.14,88],[2,2.08,41.06]],"ltp":2.14,"tv":907.97,"id":40096581}]}]}
{"op":"mcm","clk":"11816126522","pt":1722807608409,"mc":[{"id":"1.231398046","rc":[{"batb":[[0,2.14,88],[1,2.08,41.06],[2,1.9,259.67]],"ltp":2.14,"tv":907.97,"id":40096581}]}]}
{"op":"mcm","clk":"11816126741","pt":1722807612010,"mc":[{"id":"1.231398046","rc":[{"batb":[[0,2.16,10],[1,2.14,88],[2,2.08,41.06]],"ltp":2.14,"tv":907.97,"id":40096581}]}]}
{"op":"mcm","clk":"11816126951","pt":1722807615032,"mc":[{"id":"1.231398046","rc":[{"batb":[[0,2.14,88],[1,2.08,41.06],[2,1.9,259.67]],"ltp":2.14,"tv":907.97,"id":40096581}]}]}
{"op":"mcm","clk":"11816127146","pt":1722807617836,"mc":[{"id":"1.231398046","rc":[{"batb":[[0,2.16,10],[1,2.14,88],[2,2.08,41.06]],"ltp":2.14,"tv":907.97,"id":40096581}]}]}
{"op":"mcm","clk":"11816127346","pt":1722807621208,"mc":[{"id":"1.231398046","rc":[{"batb":[[0,2.14,88],[1,2.08,41.06],[2,1.9,259.67]],"ltp":2.14,"tv":907.97,"id":40096581}]}]}
{"op":"mcm","clk":"11816127408","pt":1722807622318,"mc":[{"id":"1.231398046","rc":[{"batb":[[0,2.16,7.91],[1,2.14,88],[2,2.08,41.06]],"ltp":2.14,"tv":907.97,"id":40096581}]}]}
{"op":"mcm","clk":"11816127809","pt":1722807628027,"mc":[{"id":"1.231398046","rc":[{"batb":[[0,2.18,10],[1,2.16,7.91],[2,2.14,88]],"ltp":2.14,"tv":907.97,"id":40096581}]}]}
{"op":"mcm","clk":"11816127905","pt":1722807629632,"mc":[{"id":"1.231398046","rc":[{"batb":[[1,2.14,88],[2,2.08,41.06]],"ltp":2.14,"tv":907.97,"id":40096581}]}]}
{"op":"mcm","clk":"11816128034","pt":1722807631453,"mc":[{"id":"1.231398046","rc":[{"batb":[[0,2.14,88],[1,2.08,41.06],[2,1.9,259.67]],"ltp":2.14,"tv":907.97,"id":40096581}]}]}
{"op":"mcm","clk":"11816128535","pt":1722807638252,"mc":[{"id":"1.231398046","rc":[{"batb":[[0,2.16,10],[1,2.14,88],[2,2.08,41.06]],"ltp":2.14,"tv":907.97,"id":40096581}]}]}
{"op":"mcm","clk":"11816128771","pt":1722807641568,"mc":[{"id":"1.231398046","rc":[{"batb":[[0,2.14,88],[1,2.08,41.06],[2,1.9,259.67]],"ltp":2.14,"tv":907.97,"id":40096581}]}]}
{"op":"mcm","clk":"11816129273","pt":1722807648524,"mc":[{"id":"1.231398046","rc":[{"batb":[[0,2.16,10],[1,2.14,88],[2,2.08,41.06]],"ltp":2.14,"tv":907.97,"id":40096581}]}]}
{"op":"mcm","clk":"11816129481","pt":1722807651853,"mc":[{"id":"1.231398046","rc":[{"batb":[[0,2.14,88],[1,2.08,41.06],[2,1.9,259.67]],"ltp":2.14,"tv":907.97,"id":40096581}]}]}
{"op":"mcm","clk":"11816129667","pt":1722807654542,"mc":[{"id":"1.231398046","rc":[{"batb":[[0,2.16,10],[1,2.14,88],[2,2.08,41.06]],"ltp":2.14,"tv":907.97,"id":40096581}]}]}
{"op":"mcm","clk":"11816129838","pt":1722807657337,"mc":[{"id":"1.231398046","rc":[{"batb":[[0,2.16,17.91]],"ltp":2.14,"tv":907.97,"id":40096581}]}]}
{"op":"mcm","clk":"11816129875","pt":1722807657955,"mc":[{"id":"1.231398046","rc":[{"batb":[[0,2.16,7.91]],"ltp":2.14,"tv":907.97,"id":40096581}]}]}
{"op":"mcm","clk":"11816130114","pt":1722807661489,"mc":[{"id":"1.231398046","rc":[{"batb":[[0,2.16,13.46]],"ltp":2.14,"tv":907.97,"id":40096581}]}]}
{"op":"mcm","clk":"11816130128","pt":1722807661642,"mc":[{"id":"1.231398046","rc":[{"batb":[[0,2.18,10],[1,2.16,13.46],[2,2.14,88]],"ltp":2.14,"tv":907.97,"id":40096581}]}]}
{"op":"mcm","clk":"11816130207","pt":1722807662780,"mc":[{"id":"1.231398046","rc":[{"batb":[[1,2.16,7.91]],"ltp":2.14,"tv":907.97,"id":40096581}]}]}
{"op":"mcm","clk":"11816130278","pt":1722807663868,"mc":[{"id":"1.231398046","rc":[{"batb":[[1,2.14,88],[2,2.08,41.06]],"ltp":2.14,"tv":907.97,"id":40096581}]}]}
{"op":"mcm","clk":"11816130370","pt":1722807665067,"mc":[{"id":"1.231398046","rc":[{"batb":[[0,2.14,88],[1,2.08,41.06],[2,1.9,259.67]],"ltp":2.14,"tv":907.97,"id":40096581}]}]}
{"op":"mcm","clk":"11816130658","pt":1722807669062,"mc":[{"id":"1.231398046","rc":[{"batb":[[0,2.16,10],[1,2.14,88],[2,2.08,41.06]],"ltp":2.14,"tv":907.97,"id":40096581}]}]}
{"op":"mcm","clk":"11816130878","pt":1722807672585,"mc":[{"id":"1.231398046","rc":[{"batb":[[0,2.14,88],[1,2.08,41.06],[2,1.9,259.67]],"ltp":2.14,"tv":907.97,"id":40096581}]}]}
{"op":"mcm","clk":"11816131018","pt":1722807674767,"mc":[{"id":"1.231398046","rc":[{"batb":[[0,2.16,10],[1,2.14,88],[2,2.08,41.06]],"ltp":2.14,"tv":907.97,"id":40096581}]}]}
{"op":"mcm","clk":"11816131229","pt":1722807678292,"mc":[{"id":"1.231398046","rc":[{"batb":[[0,2.14,88],[1,2.08,41.06],[2,1.9,259.67]],"ltp":2.14,"tv":907.97,"id":40096581}]}]}
{"op":"mcm","clk":"11816131743","pt":1722807686097,"mc":[{"id":"1.231398046","rc":[{"batb":[[0,2.16,10],[1,2.14,88],[2,2.08,41.06]],"ltp":2.14,"tv":907.97,"id":40096581}]}]}
{"op":"mcm","clk":"11816132002","pt":1722807689689,"mc":[{"id":"1.231398046","rc":[{"batb":[[0,2.14,88],[1,2.08,41.06],[2,1.9,259.67]],"ltp":2.14,"tv":907.97,"id":40096581}]}]}
{"op":"mcm","clk":"11816132178","pt":1722807692281,"mc":[{"id":"1.231398046","rc":[{"batb":[[0,2.18,10],[1,2.16,7.91],[2,2.14,88]],"ltp":2.14,"tv":907.97,"id":40096581}]}]}
{"op":"mcm","clk":"11816132284","pt":1722807693786,"mc":[{"id":"1.231398046","rc":[{"batb":[[1,2.14,88],[2,2.08,41.06]],"ltp":2.14,"tv":907.97,"id":40096581}]}]}
{"op":"mcm","clk":"11816132415","pt":1722807695704,"mc":[{"id":"1.231398046","rc":[{"batb":[[0,2.14,88],[1,2.08,41.06],[2,1.9,259.67]],"ltp":2.14,"tv":907.97,"id":40096581}]}]}
{"op":"mcm","clk":"11816132957","pt":1722807703328,"mc":[{"id":"1.231398046","rc":[{"batb":[[0,2.16,10],[1,2.14,88],[2,2.08,41.06]],"ltp":2.14,"tv":907.97,"id":40096581}]}]}
{"op":"mcm","clk":"11816133200","pt":1722807706896,"mc":[{"id":"1.231398046","rc":[{"batb":[[0,2.14,88],[1,2.08,41.06],[2,1.9,259.67]],"ltp":2.14,"tv":907.97,"id":40096581}]}]}
{"op":"mcm","clk":"11816133405","pt":1722807709702,"mc":[{"id":"1.231398046","rc":[{"batb":[[0,2.16,10],[1,2.14,88],[2,2.08,41.06]],"ltp":2.14,"tv":907.97,"id":40096581}]}]}
{"op":"mcm","clk":"11816133666","pt":1722807713331,"mc":[{"id":"1.231398046","rc":[{"batb":[[0,2.14,88],[1,2.08,41.06],[2,1.9,259.67]],"ltp":2.14,"tv":907.97,"id":40096581}]}]}
{"op":"mcm","clk":"11816133843","pt":1722807715821,"mc":[{"id":"1.231398046","rc":[{"batb":[[0,2.16,10],[1,2.14,88],[2,2.08,41.06]],"ltp":2.14,"tv":907.97,"id":40096581}]}]}
{"op":"mcm","clk":"11816134040","pt":1722807719440,"mc":[{"id":"1.231398046","rc":[{"batb":[[0,2.14,88],[1,2.08,41.06],[2,1.9,259.67]],"ltp":2.14,"tv":907.97,"id":40096581}]}]}
{"op":"mcm","clk":"11816134273","pt":1722807722662,"mc":[{"id":"1.231398046","rc":[{"batb":[[0,2.16,10],[1,2.14,88],[2,2.08,41.06]],"ltp":2.14,"tv":907.97,"id":40096581}]}]}
{"op":"mcm","clk":"11816134535","pt":1722807726052,"mc":[{"id":"1.231398046","rc":[{"batb":[[0,2.14,88],[1,2.08,41.06],[2,1.9,259.67]],"ltp":2.14,"tv":907.97,"id":40096581}]}]}
{"op":"mcm","clk":"11816134593","pt":1722807726930,"mc":[{"id":"1.231398046","rc":[{"batb":[[0,2.16,7.91],[1,2.14,88],[2,2.08,41.06]],"ltp":2.14,"tv":907.97,"id":40096581}]}]}
{"op":"mcm","clk":"11816134940","pt":1722807731460,"mc":[{"id":"1.231398046","rc":[{"batb":[[0,2.18,10]],"ltp":2.14,"tv":907.97,"id":40096581}]}]}
{"op":"mcm","clk":"11816135202","pt":1722807734472,"mc":[{"id":"1.231398046","rc":[{"batb":[[0,2.14,88],[1,2.08,41.06],[2,1.9,259.67]],"ltp":2.14,"tv":907.97,"id":40096581}]}]}
{"op":"mcm","clk":"11816135475","pt":1722807738263,"mc":[{"id":"1.231398046","rc":[{"batb":[[0,2.16,10],[1,2.14,88],[2,2.08,41.06]],"ltp":2.14,"tv":907.97,"id":40096581}]}]}
{"op":"mcm","clk":"11816135740","pt":1722807741884,"mc":[{"id":"1.231398046","rc":[{"batb":[[0,2.16,5.17]],"ltp":2.14,"tv":907.97,"id":40096581}]}]}
{"op":"mcm","clk":"11816136444","pt":1722807751886,"mc":[{"id":"1.231398046","rc":[{"batb":[[0,2.18,10],[1,2.16,5.17],[2,2.14,88]],"ltp":2.14,"tv":907.97,"id":40096581}]}]}
{"op":"mcm","clk":"11816136491","pt":1722807752556,"mc":[{"id":"1.231398046","rc":[{"batb":[[1,2.14,88],[2,2.08,41.06]],"ltp":2.14,"tv":907.97,"id":40096581}]}]}
{"op":"mcm","clk":"11816136658","pt":1722807755190,"mc":[{"id":"1.231398046","rc":[{"batb":[[0,2.14,88],[1,2.08,41.06],[2,1.9,259.67]],"ltp":2.14,"tv":907.97,"id":40096581}]}]}
{"op":"mcm","clk":"11816136836","pt":1722807758092,"mc":[{"id":"1.231398046","rc":[{"batb":[[0,2.16,10],[1,2.14,88],[2,2.08,41.06]],"ltp":2.14,"tv":907.97,"id":40096581}]}]}
{"op":"mcm","clk":"11816137101","pt":1722807762177,"mc":[{"id":"1.231398046","rc":[{"batb":[[0,2.16,7.91]],"ltp":2.14,"tv":907.97,"id":40096581}]}]}
{"op":"mcm","clk":"11816137316","pt":1722807765401,"mc":[{"id":"1.231398046","rc":[{"batb":[[0,2.18,10],[1,2.16,7.91],[2,2.14,88]],"ltp":2.14,"tv":907.97,"id":40096581}]}]}
{"op":"mcm","clk":"11816137398","pt":1722807767003,"mc":[{"id":"1.231398046","rc":[{"batb":[[1,2.14,88],[2,2.08,41.06]],"ltp":2.14,"tv":907.97,"id":40096581}]}]}
{"op":"mcm","clk":"11816137498","pt":1722807768778,"mc":[{"id":"1.231398046","rc":[{"batb":[[0,2.14,88],[1,2.08,41.06],[2,1.9,259.67]],"ltp":2.14,"tv":907.97,"id":40096581}]}]}
{"op":"mcm","clk":"11816143917","pt":1722807775084,"mc":[{"id":"1.231398046","rc":[{"batb":[[0,2.16,10],[1,2.14,88],[2,2.08,41.06]],"ltp":2.14,"tv":907.97,"id":40096581}]}]}
{"op":"mcm","clk":"11816144122","pt":1722807778382,"mc":[{"id":"1.231398046","rc":[{"batb":[[0,2.14,88],[1,2.08,41.06],[2,1.9,259.67]],"ltp":2.14,"tv":907.97,"id":40096581}]}]}
{"op":"mcm","clk":"11816144269","pt":1722807780816,"mc":[{"id":"1.231398046","rc":[{"batb":[[0,2.16,10],[1,2.14,88],[2,2.08,41.06]],"ltp":2.14,"tv":907.97,"id":40096581}]}]}
{"op":"mcm","clk":"11816144489","pt":1722807784208,"mc":[{"id":"1.231398046","rc":[{"batb":[[0,2.14,88],[1,2.08,41.06],[2,1.9,259.67]],"ltp":2.14,"tv":907.97,"id":40096581}]}]}
{"op":"mcm","clk":"11816144736","pt":1722807787785,"mc":[{"id":"1.231398046","rc":[{"batb":[[0,2.16,10],[1,2.14,88],[2,2.08,41.06]],"ltp":2.14,"tv":907.97,"id":40096581}]}]}
{"op":"mcm","clk":"11816144937","pt":1722807791096,"mc":[{"id":"1.231398046","rc":[{"batb":[[0,2.14,88],[1,2.08,41.06],[2,1.9,259.67]],"ltp":2.14,"tv":907.97,"id":40096581}]}]}
{"op":"mcm","clk":"11816145127","pt":1722807794107,"mc":[{"id":"1.231398046","rc":[{"batb":[[0,2.16,10],[1,2.14,88],[2,2.08,41.06]],"ltp":2.14,"tv":907.97,"id":40096581}]}]}
{"op":"mcm","clk":"11816145334","pt":1722807797517,"mc":[{"id":"1.231398046","rc":[{"batb":[[0,2.16,7.91]],"ltp":2.14,"tv":907.97,"id":40096581}]}]}
{"op":"mcm","clk":"11816145674","pt":1722807802804,"mc":[{"id":"1.231398046","rc":[{"batb":[[0,2.18,10],[1,2.16,7.91],[2,2.14,88]],"ltp":2.14,"tv":907.97,"id":40096581}]}]}
{"op":"mcm","clk":"11816145776","pt":1722807804415,"mc":[{"id":"1.231398046","rc":[{"batb":[[1,2.14,88],[2,2.08,41.06]],"ltp":2.14,"tv":907.97,"id":40096581}]}]}
{"op":"mcm","clk":"11816145873","pt":1722807806232,"mc":[{"id":"1.231398046","rc":[{"batb":[[0,2.14,88],[1,2.08,41.06],[2,1.9,259.67]],"ltp":2.14,"tv":907.97,"id":40096581}]}]}
{"op":"mcm","clk":"11816146114","pt":1722807810117,"mc":[{"id":"1.231398046","rc":[{"batb":[[0,2.16,10],[1,2.14,88],[2,2.08,41.06]],"ltp":2.14,"tv":907.97,"id":40096581}]}]}
{"op":"mcm","clk":"11816146320","pt":1722807813640,"mc":[{"id":"1.231398046","rc":[{"batb":[[0,2.14,88],[1,2.08,41.06],[2,1.9,259.67]],"ltp":2.14,"tv":907.97,"id":40096581}]}]}
{"op":"mcm","clk":"11816146569","pt":1722807817418,"mc":[{"id":"1.231398046","rc":[{"batb":[[0,2.16,10],[1,2.14,88],[2,2.08,41.06]],"ltp":2.14,"tv":907.97,"id":40096581}]}]}
{"op":"mcm","clk":"11816146774","pt":1722807820962,"mc":[{"id":"1.231398046","rc":[{"batb":[[0,2.14,88],[1,2.08,41.06],[2,1.9,259.67]],"ltp":2.14,"tv":907.97,"id":40096581}]}]}
{"op":"mcm","clk":"11816146854","pt":1722807821949,"mc":[{"id":"1.231398046","rc":[{"batb":[[0,2.16,5.17],[1,2.14,88],[2,2.08,41.06]],"ltp":2.14,"tv":907.97,"id":40096581}]}]}
{"op":"mcm","clk":"11816146932","pt":1722807823145,"mc":[{"id":"1.231398046","rc":[{"batb":[[0,2.18,10],[1,2.16,5.17],[2,2.14,88]],"ltp":2.14,"tv":907.97,"id":40096581}]}]}
{"op":"mcm","clk":"11816147084","pt":1722807824546,"mc":[{"id":"1.231398046","rc":[{"batb":[[1,2.14,88],[2,2.08,41.06]],"ltp":2.14,"tv":907.97,"id":40096581}]}]}
{"op":"mcm","clk":"11816147209","pt":1722807826561,"mc":[{"id":"1.231398046","rc":[{"batb":[[0,2.14,88],[1,2.08,41.06],[2,1.9,259.67]],"ltp":2.14,"tv":907.97,"id":40096581}]}]}
{"op":"mcm","clk":"11816147350","pt":1722807828954,"mc":[{"id":"1.231398046","rc":[{"batb":[[0,2.16,10],[1,2.14,88],[2,2.08,41.06]],"ltp":2.14,"tv":907.97,"id":40096581}]}]}
{"op":"mcm","clk":"11816147514","pt":1722807831429,"mc":[{"id":"1.231398046","rc":[{"batb":[[0,2.16,17.91]],"ltp":2.14,"tv":907.97,"id":40096581}]}]}
{"op":"mcm","clk":"11816147562","pt":1722807832361,"mc":[{"id":"1.231398046","rc":[{"batb":[[0,2.16,7.91]],"ltp":2.14,"tv":907.97,"id":40096581}]}]}
{"op":"mcm","clk":"11816148866","pt":1722807850268,"mc":[{"id":"1.231398046","rc":[{"batb":[[0,2.18,10],[1,2.16,7.91],[2,2.14,88]],"ltp":2.14,"tv":907.97,"id":40096581}]}]}
{"op":"mcm","clk":"11816148923","pt":1722807850990,"mc":[{"id":"1.231398046","rc":[{"batb":[[1,2.14,88],[2,2.08,41.06]],"ltp":2.14,"tv":907.97,"id":40096581}]}]}
{"op":"mcm","clk":"11816149118","pt":1722807853694,"mc":[{"id":"1.231398046","rc":[{"batb":[[0,2.14,88],[1,2.08,41.06],[2,1.9,259.67]],"ltp":2.14,"tv":907.97,"id":40096581}]}]}
{"op":"mcm","clk":"11816149284","pt":1722807856084,"mc":[{"id":"1.231398046","rc":[{"batb":[[0,2.16,10],[1,2.14,88],[2,2.08,41.06]],"ltp":2.14,"tv":907.97,"id":40096581}]}]}
{"op":"mcm","clk":"11816149522","pt":1722807859260,"mc":[{"id":"1.231398046","rc":[{"batb":[[0,2.14,88],[1,2.08,41.06],[2,1.9,259.67]],"ltp":2.14,"tv":907.97,"id":40096581}]}]}
{"op":"mcm","clk":"11816149757","pt":1722807862280,"mc":[{"id":"1.231398046","rc":[{"batb":[[0,2.16,10],[1,2.14,88],[2,2.08,41.06]],"ltp":2.14,"tv":907.97,"id":40096581}]}]}
{"op":"mcm","clk":"11816150007","pt":1722807865909,"mc":[{"id":"1.231398046","rc":[{"batb":[[0,2.16,7.91]],"ltp":2.14,"tv":907.97,"id":40096581}]}]}
{"op":"mcm","clk":"11816150225","pt":1722807868367,"mc":[{"id":"1.231398046","rc":[{"batb":[[0,2.18,10],[1,2.16,7.91],[2,2.14,88]],"ltp":2.14,"tv":907.97,"id":40096581}]}]}
{"op":"mcm","clk":"11816150292","pt":1722807869394,"mc":[{"id":"1.231398046","rc":[{"batb":[[1,2.14,88],[2,2.08,41.06]],"ltp":2.14,"tv":907.97,"id":40096581}]}]}
{"op":"mcm","clk":"11816150481","pt":1722807871782,"mc":[{"id":"1.231398046","rc":[{"batb":[[0,2.14,88],[1,2.08,41.06],[2,1.9,259.67]],"ltp":2.14,"tv":907.97,"id":40096581}]}]}
{"op":"mcm","clk":"11816150930","pt":1722807877502,"mc":[{"id":"1.231398046","rc":[{"batb":[[0,2.16,10],[1,2.14,88],[2,2.08,41.06]],"ltp":2.14,"tv":907.97,"id":40096581}]}]}
{"op":"mcm","clk":"11816151205","pt":1722807880979,"mc":[{"id":"1.231398046","rc":[{"batb":[[0,2.14,88],[1,2.08,41.06],[2,1.9,259.67]],"ltp":2.14,"tv":907.97,"id":40096581}]}]}
{"op":"mcm","clk":"11816151362","pt":1722807883298,"mc":[{"id":"1.231398046","rc":[{"batb":[[0,2.16,10],[1,2.14,88],[2,2.08,41.06]],"ltp":2.14,"tv":907.97,"id":40096581}]}]}
{"op":"mcm","clk":"11816151638","pt":1722807886616,"mc":[{"id":"1.231398046","rc":[{"batb":[[0,2.14,88],[1,2.08,41.06],[2,1.9,259.67]],"ltp":2.14,"tv":907.97,"id":40096581}]}]}
{"op":"mcm","clk":"11816152322","pt":1722807895908,"mc":[{"id":"1.231398046","rc":[{"batb":[[0,2.16,10],[1,2.14,88],[2,2.08,41.06]],"ltp":2.14,"tv":907.97,"id":40096581}]}]}
{"op":"mcm","clk":"11816152575","pt":1722807899328,"mc":[{"id":"1.231398046","rc":[{"batb":[[0,2.14,88],[1,2.08,41.06],[2,1.9,259.67]],"ltp":2.14,"tv":907.97,"id":40096581}]}]}
{"op":"mcm","clk":"11816152769","pt":1722807901630,"mc":[{"id":"1.231398046","rc":[{"batb":[[0,2.18,10],[1,2.16,7.91],[2,2.14,88]],"ltp":2.14,"tv":907.97,"id":40096581}]}]}
{"op":"mcm","clk":"11816152902","pt":1722807903214,"mc":[{"id":"1.231398046","rc":[{"batb":[[1,2.14,88],[2,2.08,41.06]],"ltp":2.14,"tv":907.97,"id":40096581}]}]}
{"op":"mcm","clk":"11816153104","pt":1722807905511,"mc":[{"id":"1.231398046","rc":[{"batb":[[0,2.16,5.17]],"ltp":2.14,"tv":907.97,"id":40096581}]}]}
{"op":"mcm","clk":"11816153288","pt":1722807907018,"mc":[{"id":"1.231398046","rc":[{"batb":[[0,2.18,10],[1,2.16,5.17],[2,2.14,88]],"ltp":2.14,"tv":907.97,"id":40096581}]}]}
{"op":"mcm","clk":"11816153354","pt":1722807908003,"mc":[{"id":"1.231398046","rc":[{"batb":[[1,2.14,88],[2,2.08,41.06]],"ltp":2.14,"tv":907.97,"id":40096581}]}]}
{"op":"mcm","clk":"11816153508","pt":1722807910537,"mc":[{"id":"1.231398046","rc":[{"batb":[[0,2.14,88],[1,2.08,41.06],[2,1.9,259.67]],"ltp":2.14,"tv":907.97,"id":40096581}]}]}
{"op":"mcm","clk":"11816153965","pt":1722807919063,"mc":[{"id":"1.231398046","rc":[{"batb":[[0,2.16,10],[1,2.14,88],[2,2.08,41.06]],"ltp":2.14,"tv":907.97,"id":40096581}]}]}
{"op":"mcm","clk":"11816154146","pt":1722807922331,"mc":[{"id":"1.231398046","rc":[{"batb":[[0,2.14,88],[1,2.08,41.06],[2,1.9,259.67]],"ltp":2.14,"tv":907.97,"id":40096581}]}]}
{"op":"mcm","clk":"11816154659","pt":1722807931151,"mc":[{"id":"1.231398046","rc":[{"batb":[[0,2.16,10],[1,2.14,88],[2,2.08,41.06]],"ltp":2.14,"tv":907.97,"id":40096581}]}]}
{"op":"mcm","clk":"11816154834","pt":1722807934464,"mc":[{"id":"1.231398046","rc":[{"batb":[[0,2.14,88],[1,2.08,41.06],[2,1.9,259.67]],"ltp":2.14,"tv":907.97,"id":40096581}]}]}
{"op":"mcm","clk":"11816154984","pt":1722807937274,"mc":[{"id":"1.231398046","rc":[{"batb":[[0,2.18,10],[1,2.16,7.91],[2,2.14,88]],"ltp":2.14,"tv":907.97,"id":40096581}]}]}
{"op":"mcm","clk":"11816155073","pt":1722807938877,"mc":[{"id":"1.231398046","rc":[{"batb":[[1,2.14,88],[2,2.08,41.06]],"ltp":2.14,"tv":907.97,"id":40096581}]}]}
{"op":"mcm","clk":"11816155194","pt":1722807940688,"mc":[{"id":"1.231398046","rc":[{"batb":[[0,2.14,88],[1,2.08,41.06],[2,1.9,259.67]],"ltp":2.14,"tv":907.97,"id":40096581}]}]}
{"op":"mcm","clk":"11816155635","pt":1722807947764,"mc":[{"id":"1.231398046","rc":[{"batb":[[0,2.16,10],[1,2.14,88],[2,2.08,41.06]],"ltp":2.14,"tv":907.97,"id":40096581}]}]}
{"op":"mcm","clk":"11816155880","pt":1722807951202,"mc":[{"id":"1.231398046","rc":[{"batb":[[0,2.14,88],[1,2.08,41.06],[2,1.9,259.67]],"ltp":2.14,"tv":907.97,"id":40096581}]}]}
{"op":"mcm","clk":"11816156033","pt":1722807953797,"mc":[{"id":"1.231398046","rc":[{"batb":[[0,2.16,10],[1,2.14,88],[2,2.08,41.06]],"ltp":2.14,"tv":907.97,"id":40096581}]}]}
{"op":"mcm","clk":"11816156251","pt":1722807957184,"mc":[{"id":"1.231398046","rc":[{"batb":[[0,2.14,88],[1,2.08,41.06],[2,1.9,259.67]],"ltp":2.14,"tv":907.97,"id":40096581}]}]}
{"op":"mcm","clk":"11816156411","pt":1722807959785,"mc":[{"id":"1.231398046","rc":[{"batb":[[0,2.16,10],[1,2.14,88],[2,2.08,41.06]],"ltp":2.14,"tv":907.97,"id":40096581}]}]}
{"op":"mcm","clk":"11816156622","pt":1722807963186,"mc":[{"id":"1.231398046","rc":[{"batb":[[0,2.14,88],[1,2.08,41.06],[2,1.9,259.67]],"ltp":2.14,"tv":907.97,"id":40096581}]}]}
{"op":"mcm","clk":"11816156837","pt":1722807966405,"mc":[{"id":"1.231398046","rc":[{"batb":[[0,2.16,10],[1,2.14,88],[2,2.08,41.06]],"ltp":2.14,"tv":907.97,"id":40096581}]}]}
{"op":"mcm","clk":"11816157050","pt":1722807969829,"mc":[{"id":"1.231398046","rc":[{"batb":[[0,2.14,88],[1,2.08,41.06],[2,1.9,259.67]],"ltp":2.14,"tv":907.97,"id":40096581}]}]}
{"op":"mcm","clk":"11816157197","pt":1722807972006,"mc":[{"id":"1.231398046","rc":[{"batb":[[0,2.18,10],[1,2.16,7.91],[2,2.14,88]],"ltp":2.14,"tv":907.97,"id":40096581}]}]}
{"op":"mcm","clk":"11816157283","pt":1722807973614,"mc":[{"id":"1.231398046","rc":[{"batb":[[1,2.14,88],[2,2.08,41.06]],"ltp":2.14,"tv":907.97,"id":40096581}]}]}
{"op":"mcm","clk":"11816157374","pt":1722807975321,"mc":[{"id":"1.231398046","rc":[{"batb":[[0,2.14,88],[1,2.08,41.06],[2,1.9,259.67]],"ltp":2.14,"tv":907.97,"id":40096581}]}]}
{"op":"mcm","clk":"11816157600","pt":1722807979303,"mc":[{"id":"1.231398046","rc":[{"batb":[[0,2.16,10],[1,2.14,88],[2,2.08,41.06]],"ltp":2.14,"tv":907.97,"id":40096581}]}]}
{"op":"mcm","clk":"11816157797","pt":1722807982723,"mc":[{"id":"1.231398046","rc":[{"batb":[[0,2.14,88],[1,2.08,41.06],[2,1.9,259.67]],"ltp":2.14,"tv":907.97,"id":40096581}]}]}
{"op":"mcm","clk":"11816158040","pt":1722807986246,"mc":[{"id":"1.231398046","rc":[{"batb":[[0,2.18,10],[1,2.16,5.17],[2,2.14,88]],"ltp":2.14,"tv":907.97,"id":40096581}]}]}
{"op":"mcm","clk":"11816158117","pt":1722807987335,"mc":[{"id":"1.231398046","rc":[{"batb":[[1,2.14,88],[2,2.08,41.06]],"ltp":2.14,"tv":907.97,"id":40096581}]}]}
{"op":"mcm","clk":"11816158263","pt":1722807989660,"mc":[{"id":"1.231398046","rc":[{"batb":[[0,2.14,88],[1,2.08,41.06],[2,1.9,259.67]],"ltp":2.14,"tv":907.97,"id":40096581}]}]}
{"op":"mcm","clk":"11816158869","pt":1722808000066,"mc":[{"id":"1.231398046","rc":[{"batb":[[0,2.16,10],[1,2.14,88],[2,2.08,41.06]],"ltp":2.14,"tv":907.97,"id":40096581}]}]}
{"op":"mcm","clk":"11816159044","pt":1722808003350,"mc":[{"id":"1.231398046","rc":[{"batb":[[0,2.14,88],[1,2.08,41.06],[2,1.9,259.67]],"ltp":2.14,"tv":907.97,"id":40096581}]}]}
{"op":"mcm","clk":"11816159260","pt":1722808006669,"mc":[{"id":"1.231398046","rc":[{"batb":[[0,2.18,10],[1,2.16,7.91],[2,2.14,88]],"ltp":2.14,"tv":907.97,"id":40096581}]}]}
{"op":"mcm","clk":"11816159388","pt":1722808008279,"mc":[{"id":"1.231398046","rc":[{"batb":[[1,2.14,88],[2,2.08,41.06]],"ltp":2.14,"tv":907.97,"id":40096581}]}]}
{"op":"mcm","clk":"11816159516","pt":1722808010046,"mc":[{"id":"1.231398046","rc":[{"batb":[[0,2.14,88],[1,2.08,41.06],[2,1.9,259.67]],"ltp":2.14,"tv":907.97,"id":40096581}]}]}
{"op":"mcm","clk":"11816159925","pt":1722808016275,"mc":[{"id":"1.231398046","rc":[{"batb":[[0,2.16,10],[1,2.14,88],[2,2.08,41.06]],"ltp":2.14,"tv":907.97,"id":40096581}]}]}
{"op":"mcm","clk":"11816160145","pt":1722808019860,"mc":[{"id":"1.231398046","rc":[{"batb":[[0,2.14,88],[1,2.08,41.06],[2,1.9,259.67]],"ltp":2.14,"tv":907.97,"id":40096581}]}]}
{"op":"mcm","clk":"11816160716","pt":1722808028503,"mc":[{"id":"1.231398046","rc":[{"batb":[[0,2.16,10],[1,2.14,88],[2,2.08,41.06]],"ltp":2.14,"tv":907.97,"id":40096581}]}]}
{"op":"mcm","clk":"11816160933","pt":1722808031917,"mc":[{"id":"1.231398046","rc":[{"batb":[[0,2.14,88],[1,2.08,41.06],[2,1.9,259.67]],"ltp":2.14,"tv":907.97,"id":40096581}]}]}
{"op":"mcm","clk":"11816161146","pt":1722808034987,"mc":[{"id":"1.231398046","rc":[{"batb":[[0,2.16,10],[1,2.14,88],[2,2.08,41.06]],"ltp":2.14,"tv":907.97,"id":40096581}]}]}
{"op":"mcm","clk":"11816161368","pt":1722808038510,"mc":[{"id":"1.231398046","rc":[{"batb":[[0,2.14,88],[1,2.08,41.06],[2,1.9,259.67]],"ltp":2.14,"tv":907.97,"id":40096581}]}]}
{"op":"mcm","clk":"11816161508","pt":1722808040911,"mc":[{"id":"1.231398046","rc":[{"batb":[[0,2.18,10],[1,2.16,7.91],[2,2.14,88]],"ltp":2.14,"tv":907.97,"id":40096581}]}]}
{"op":"mcm","clk":"11816161603","pt":1722808042513,"mc":[{"id":"1.231398046","rc":[{"batb":[[1,2.14,88],[2,2.08,41.06]],"ltp":2.14,"tv":907.97,"id":40096581}]}]}
{"op":"mcm","clk":"11816161703","pt":1722808044222,"mc":[{"id":"1.231398046","rc":[{"batb":[[0,2.14,88],[1,2.08,41.06],[2,1.9,259.67]],"ltp":2.14,"tv":907.97,"id":40096581}]}]}
{"op":"mcm","clk":"11816162169","pt":1722808051414,"mc":[{"id":"1.231398046","rc":[{"batb":[[0,2.16,10],[1,2.14,88],[2,2.08,41.06]],"ltp":2.14,"tv":907.97,"id":40096581}]}]}
{"op":"mcm","clk":"11816162397","pt":1722808054741,"mc":[{"id":"1.231398046","rc":[{"batb":[[0,2.14,88],[1,2.08,41.06],[2,1.9,259.67]],"ltp":2.14,"tv":907.97,"id":40096581}]}]}
{"op":"mcm","clk":"11816162802","pt":1722808060551,"mc":[{"id":"1.231398046","rc":[{"batb":[[0,2.16,10],[1,2.14,88],[2,2.08,41.06]],"ltp":2.14,"tv":907.97,"id":40096581}]}]}
{"op":"mcm","clk":"11816163006","pt":1722808063924,"mc":[{"id":"1.231398046","rc":[{"batb":[[0,2.14,88],[1,2.08,41.06],[2,1.9,259.67]],"ltp":2.14,"tv":907.97,"id":40096581}]}]}
{"op":"mcm","clk":"11816163163","pt":1722808066248,"mc":[{"id":"1.231398046","rc":[{"batb":[[0,2.16,10],[1,2.14,88],[2,2.08,41.06]],"ltp":2.14,"tv":907.97,"id":40096581}]}]}
{"op":"mcm","clk":"11816163184","pt":1722808066661,"mc":[{"id":"1.231398046","rc":[{"batb":[[0,2.16,15.17]],"ltp":2.14,"tv":907.97,"id":40096581}]}]}
{"op":"mcm","clk":"11816163395","pt":1722808069532,"mc":[{"id":"1.231398046","rc":[{"batb":[[0,2.16,5.17]],"ltp":2.14,"tv":907.97,"id":40096581}]}]}
{"op":"mcm","clk":"11816163583","pt":1722808072138,"mc":[{"id":"1.231398046","rc":[{"batb":[[0,2.18,10],[1,2.16,5.17],[2,2.14,88]],"ltp":2.14,"tv":907.97,"id":40096581}]}]}
{"op":"mcm","clk":"11816163626","pt":1722808072761,"mc":[{"id":"1.231398046","rc":[{"batb":[[1,2.14,88],[2,2.08,41.06]],"ltp":2.14,"tv":907.97,"id":40096581}]}]}
{"op":"mcm","clk":"11816163870","pt":1722808076058,"mc":[{"id":"1.231398046","rc":[{"batb":[[0,2.16,7.91]],"ltp":2.14,"tv":907.97,"id":40096581}]}]}
{"op":"mcm","clk":"11816164019","pt":1722808078133,"mc":[{"id":"1.231398046","rc":[{"batb":[[0,2.18,10],[1,2.16,7.91],[2,2.14,88]],"ltp":2.14,"tv":907.97,"id":40096581}]}]}
{"op":"mcm","clk":"11816164148","pt":1722808079846,"mc":[{"id":"1.231398046","rc":[{"batb":[[1,2.14,88],[2,2.08,41.06]],"ltp":2.14,"tv":907.97,"id":40096581}]}]}
{"op":"mcm","clk":"11816164253","pt":1722808081562,"mc":[{"id":"1.231398046","rc":[{"batb":[[0,2.14,88],[1,2.08,41.06],[2,1.9,259.67]],"ltp":2.14,"tv":907.97,"id":40096581}]}]}
{"op":"mcm","clk":"11816164418","pt":1722808084053,"mc":[{"id":"1.231398046","rc":[{"batb":[[0,2.16,10],[1,2.14,88],[2,2.08,41.06]],"ltp":2.14,"tv":907.97,"id":40096581}]}]}
{"op":"mcm","clk":"11816164600","pt":1722808087361,"mc":[{"id":"1.231398046","rc":[{"batb":[[0,2.14,88],[1,2.08,41.06],[2,1.9,259.67]],"ltp":2.14,"tv":907.97,"id":40096581}]}]}
{"op":"mcm","clk":"11816165201","pt":1722808097180,"mc":[{"id":"1.231398046","rc":[{"batb":[[0,2.16,10],[1,2.14,88],[2,2.08,41.06]],"ltp":2.14,"tv":907.97,"id":40096581}]}]}
{"op":"mcm","clk":"11816165412","pt":1722808100595,"mc":[{"id":"1.231398046","rc":[{"batb":[[0,2.14,88],[1,2.08,41.06],[2,1.9,259.67]],"ltp":2.14,"tv":907.97,"id":40096581}]}]}
{"op":"mcm","clk":"11816165620","pt":1722808104177,"mc":[{"id":"1.231398046","rc":[{"batb":[[0,2.16,10],[1,2.14,88],[2,2.08,41.06]],"ltp":2.14,"tv":907.97,"id":40096581}]}]}
{"op":"mcm","clk":"11816165832","pt":1722808107589,"mc":[{"id":"1.231398046","rc":[{"batb":[[0,2.14,88],[1,2.08,41.06],[2,1.9,259.67]],"ltp":2.14,"tv":907.97,"id":40096581}]}]}
{"op":"mcm","clk":"11816166014","pt":1722808110485,"mc":[{"id":"1.231398046","rc":[{"batb":[[0,2.18,10],[1,2.16,7.91],[2,2.14,88]],"ltp":2.14,"tv":907.97,"id":40096581}]}]}
{"op":"mcm","clk":"11816166114","pt":1722808111889,"mc":[{"id":"1.231398046","rc":[{"batb":[[1,2.14,88],[2,2.08,41.06]],"ltp":2.14,"tv":907.97,"id":40096581}]}]}
{"op":"mcm","clk":"11816166223","pt":1722808113995,"mc":[{"id":"1.231398046","rc":[{"batb":[[0,2.14,88],[1,2.08,41.06],[2,1.9,259.67]],"ltp":2.14,"tv":907.97,"id":40096581}]}]}
{"op":"mcm","clk":"11816166506","pt":1722808118806,"mc":[{"id":"1.231398046","rc":[{"batb":[[0,2.16,10],[1,2.14,88],[2,2.08,41.06]],"ltp":2.14,"tv":907.97,"id":40096581}]}]}
{"op":"mcm","clk":"11816166729","pt":1722808122128,"mc":[{"id":"1.231398046","rc":[{"batb":[[0,2.14,88],[1,2.08,41.06],[2,1.9,259.67]],"ltp":2.14,"tv":907.97,"id":40096581}]}]}
{"op":"mcm","clk":"11816166917","pt":1722808125228,"mc":[{"id":"1.231398046","rc":[{"batb":[[0,2.16,10],[1,2.14,88],[2,2.08,41.06]],"ltp":2.14,"tv":907.97,"id":40096581}]}]}
{"op":"mcm","clk":"11816167077","pt":1722808128620,"mc":[{"id":"1.231398046","rc":[{"batb":[[0,2.14,88],[1,2.08,41.06],[2,1.9,259.67]],"ltp":2.14,"tv":907.97,"id":40096581}]}]}
{"op":"mcm","clk":"11816167201","pt":1722808131001,"mc":[{"id":"1.231398046","rc":[{"batb":[[0,2.16,10],[1,2.14,88],[2,2.08,41.06]],"ltp":2.14,"tv":907.97,"id":40096581}]}]}
{"op":"mcm","clk":"11816167361","pt":1722808134424,"mc":[{"id":"1.231398046","rc":[{"batb":[[0,2.14,88],[1,2.08,41.06],[2,1.9,259.67]],"ltp":2.14,"tv":907.97,"id":40096581}]}]}
{"op":"mcm","clk":"11816167487","pt":1722808136845,"mc":[{"id":"1.231398046","rc":[{"batb":[[0,2.16,10],[1,2.14,88],[2,2.08,41.06]],"ltp":2.14,"tv":907.97,"id":40096581}]}]}
{"op":"mcm","clk":"11816167652","pt":1722808140151,"mc":[{"id":"1.231398046","rc":[{"batb":[[0,2.14,88],[1,2.08,41.06],[2,1.9,259.67]],"ltp":2.14,"tv":907.97,"id":40096581}]}]}
{"op":"mcm","clk":"11816167845","pt":1722808144136,"mc":[{"id":"1.231398046","rc":[{"batb":[[0,2.16,10],[1,2.14,88],[2,2.08,41.06]],"ltp":2.14,"tv":907.97,"id":40096581}]}]}
{"op":"mcm","clk":"11816167913","pt":1722808145428,"mc":[{"id":"1.231398046","rc":[{"batb":[[0,2.16,17.91]],"ltp":2.14,"tv":907.97,"id":40096581}]}]}
{"op":"mcm","clk":"11816168033","pt":1722808148018,"mc":[{"id":"1.231398046","rc":[{"batb":[[0,2.16,13.46]],"ltp":2.14,"tv":907.97,"id":40096581}]}]}
{"op":"mcm","clk":"11816168237","pt":1722808151443,"mc":[{"id":"1.231398046","rc":[{"batb":[[0,2.18,10],[1,2.16,13.46],[2,2.14,88]],"ltp":2.14,"tv":907.97,"id":40096581}]}]}
{"op":"mcm","clk":"11816168275","pt":1722808152327,"mc":[{"id":"1.231398046","rc":[{"batb":[[1,2.16,7.91]],"ltp":2.14,"tv":907.97,"id":40096581}]}]}
{"op":"mcm","clk":"11816168366","pt":1722808153974,"mc":[{"id":"1.231398046","rc":[{"batb":[[1,2.14,88],[2,2.08,41.06]],"ltp":2.14,"tv":907.97,"id":40096581}]}]}
{"op":"mcm","clk":"11816168408","pt":1722808154751,"mc":[{"id":"1.231398046","rc":[{"batb":[[0,2.14,88],[1,2.08,41.06],[2,1.9,259.67]],"ltp":2.14,"tv":907.97,"id":40096581}]}]}
{"op":"mcm","clk":"11816168810","pt":1722808163072,"mc":[{"id":"1.231398046","rc":[{"batb":[[0,2.16,10],[1,2.14,88],[2,2.08,41.06]],"ltp":2.14,"tv":907.97,"id":40096581}]}]}
{"op":"mcm","clk":"11816168980","pt":1722808166483,"mc":[{"id":"1.231398046","rc":[{"batb":[[0,2.14,88],[1,2.08,41.06],[2,1.9,259.67]],"ltp":2.14,"tv":907.97,"id":40096581}]}]}
{"op":"mcm","clk":"11816169115","pt":1722808168967,"mc":[{"id":"1.231398046","rc":[{"batb":[[0,2.16,10],[1,2.14,88],[2,2.08,41.06]],"ltp":2.14,"tv":907.97,"id":40096581}]}]}
{"op":"mcm","clk":"11816169301","pt":1722808172458,"mc":[{"id":"1.231398046","rc":[{"batb":[[0,2.14,88],[1,2.08,41.06],[2,1.9,259.67]],"ltp":2.14,"tv":907.97,"id":40096581}]}]}
{"op":"mcm","clk":"11816169444","pt":1722808175391,"mc":[{"id":"1.231398046","rc":[{"batb":[[0,2.16,10],[1,2.14,88],[2,2.08,41.06]],"ltp":2.14,"tv":907.97,"id":40096581}]}]}
{"op":"mcm","clk":"11816169597","pt":1722808178804,"mc":[{"id":"1.231398046","rc":[{"batb":[[0,2.14,88],[1,2.08,41.06],[2,1.9,259.67]],"ltp":2.14,"tv":907.97,"id":40096581}]}]}
{"op":"mcm","clk":"11816169654","pt":1722808179993,"mc":[{"id":"1.231398046","rc":[{"batb":[[0,2.16,7.91],[1,2.14,88],[2,2.08,41.06]],"ltp":2.14,"tv":907.97,"id":40096581}]}]}
{"op":"mcm","clk":"11816169756","pt":1722808181909,"mc":[{"id":"1.231398046","rc":[{"batb":[[0,2.18,10],[1,2.16,7.91],[2,2.14,88]],"ltp":2.14,"tv":907.97,"id":40096581}]}]}
{"op":"mcm","clk":"11816169840","pt":1722808183409,"mc":[{"id":"1.231398046","rc":[{"batb":[[1,2.14,88],[2,2.08,41.06]],"ltp":2.14,"tv":907.97,"id":40096581}]}]}
{"op":"mcm","clk":"11816169928","pt":1722808185273,"mc":[{"id":"1.231398046","rc":[{"batb":[[0,2.14,88],[1,2.08,41.06],[2,1.9,259.67]],"ltp":2.14,"tv":907.97,"id":40096581}]}]}
{"op":"mcm","clk":"11816171655","pt":1722808215450,"mc":[{"id":"1.231398046","rc":[{"batb":[[0,2.16,7.91],[1,2.14,88],[2,2.08,41.06]],"ltp":2.14,"tv":907.97,"id":40096581}]}]}
{"op":"mcm","clk":"11816171660","pt":1722808215553,"mc":[{"id":"1.231398046","rc":[{"batb":[[0,2.18,10],[1,2.16,7.91],[2,2.14,88]],"ltp":2.14,"tv":907.97,"id":40096581}]}]}
{"op":"mcm","clk":"11816171744","pt":1722808216951,"mc":[{"id":"1.231398046","rc":[{"batb":[[1,2.14,88],[2,2.08,41.06]],"ltp":2.14,"tv":907.97,"id":40096581}]}]}
{"op":"mcm","clk":"11816171846","pt":1722808218814,"mc":[{"id":"1.231398046","rc":[{"batb":[[0,2.14,88],[1,2.08,41.06],[2,1.9,259.67]],"ltp":2.14,"tv":907.97,"id":40096581}]}]}
{"op":"mcm","clk":"11816172306","pt":1722808227454,"mc":[{"id":"1.231398046","rc":[{"batb":[[0,2.16,5.17],[1,2.14,88],[2,2.08,41.06]],"ltp":2.14,"tv":907.97,"id":40096581}]}]}
{"op":"mcm","clk":"11816172317","pt":1722808227660,"mc":[{"id":"1.231398046","rc":[{"batb":[[0,2.18,10],[1,2.16,5.17],[2,2.14,88]],"ltp":2.14,"tv":907.97,"id":40096581}]}]}
{"op":"mcm","clk":"11816172381","pt":1722808228759,"mc":[{"id":"1.231398046","rc":[{"batb":[[1,2.14,88],[2,2.08,41.06]],"ltp":2.14,"tv":907.97,"id":40096581}]}]}
{"op":"mcm","clk":"11816172523","pt":1722808231141,"mc":[{"id":"1.231398046","rc":[{"batb":[[0,2.14,88],[1,2.08,41.06],[2,1.9,259.67]],"ltp":2.14,"tv":907.97,"id":40096581}]}]}
{"op":"mcm","clk":"11816173635","pt":1722808251482,"mc":[{"id":"1.231398046","rc":[{"batb":[[0,2.18,10],[1,2.16,7.91],[2,2.14,88]],"ltp":2.14,"tv":907.97,"id":40096581}]}]}
{"op":"mcm","clk":"11816173731","pt":1722808253084,"mc":[{"id":"1.231398046","rc":[{"batb":[[1,2.14,88],[2,2.08,41.06]],"ltp":2.14,"tv":907.97,"id":40096581}]}]}
{"op":"mcm","clk":"11816173853","pt":1722808254783,"mc":[{"id":"1.231398046","rc":[{"batb":[[0,2.14,88],[1,2.08,41.06],[2,1.9,259.67]],"ltp":2.14,"tv":907.97,"id":40096581}]}]}
{"op":"mcm","clk":"11816174330","pt":1722808264385,"mc":[{"id":"1.231398046","rc":[{"batb":[[0,2.16,10],[1,2.14,88],[2,2.08,41.06]],"ltp":2.14,"tv":907.97,"id":40096581}]}]}
{"op":"mcm","clk":"11816174502","pt":1722808267692,"mc":[{"id":"1.231398046","rc":[{"batb":[[0,2.14,88],[1,2.08,41.06],[2,1.9,259.67]],"ltp":2.14,"tv":907.97,"id":40096581}]}]}
{"op":"mcm","clk":"11816175412","pt":1722808286109,"mc":[{"id":"1.231398046","rc":[{"batb":[[0,2.18,10],[1,2.16,7.91],[2,2.14,88]],"ltp":2.14,"tv":907.97,"id":40096581}]}]}
{"op":"mcm","clk":"11816175513","pt":1722808287711,"mc":[{"id":"1.231398046","rc":[{"batb":[[1,2.14,88],[2,2.08,41.06]],"ltp":2.14,"tv":907.97,"id":40096581}]}]}
{"op":"mcm","clk":"11816175609","pt":1722808289419,"mc":[{"id":"1.231398046","rc":[{"batb":[[0,2.14,88],[1,2.08,41.06],[2,1.9,259.67]],"ltp":2.14,"tv":907.97,"id":40096581}]}]}
{"op":"mcm","clk":"11816176569","pt":1722808307457,"mc":[{"id":"1.231398046","rc":[{"batb":[[0,2.16,5.17],[1,2.14,88],[2,2.08,41.06]],"ltp":2.14,"tv":907.97,"id":40096581}]}]}
{"op":"mcm","clk":"11816176576","pt":1722808307561,"mc":[{"id":"1.231398046","rc":[{"batb":[[0,2.18,10],[1,2.16,5.17],[2,2.14,88]],"ltp":2.14,"tv":907.97,"id":40096581}]}]}
{"op":"mcm","clk":"11816176668","pt":1722808308754,"mc":[{"id":"1.231398046","rc":[{"batb":[[1,2.14,88],[2,2.08,41.06]],"ltp":2.14,"tv":907.97,"id":40096581}]}]}
{"op":"mcm","clk":"11816176785","pt":1722808310832,"mc":[{"id":"1.231398046","rc":[{"batb":[[0,2.14,88],[1,2.08,41.06],[2,1.9,259.67]],"ltp":2.14,"tv":907.97,"id":40096581}]}]}
{"op":"mcm","clk":"11816177088","pt":1722808316046,"mc":[{"id":"1.231398046","rc":[{"batb":[[0,2.16,10],[1,2.14,88],[2,2.08,41.06]],"ltp":2.14,"tv":907.97,"id":40096581}]}]}
{"op":"mcm","clk":"11816177288","pt":1722808319370,"mc":[{"id":"1.231398046","rc":[{"batb":[[0,2.14,88],[1,2.08,41.06],[2,1.9,259.67]],"ltp":2.14,"tv":907.97,"id":40096581}]}]}
{"op":"mcm","clk":"11816177372","pt":1722808320867,"mc":[{"id":"1.231398046","rc":[{"batb":[[0,2.16,7.91],[1,2.14,88],[2,2.08,41.06]],"ltp":2.14,"tv":907.97,"id":40096581}]}]}
{"op":"mcm","clk":"11816178275","pt":1722808332805,"mc":[{"id":"1.231398046","rc":[{"batb":[[0,2.18,10],[1,2.16,7.91],[2,2.14,88]],"ltp":2.14,"tv":907.97,"id":40096581}]}]}
{"op":"mcm","clk":"11816178400","pt":1722808334075,"mc":[{"id":"1.231398046","rc":[{"batb":[[1,2.14,88],[2,2.08,41.06]],"ltp":2.14,"tv":907.97,"id":40096581}]}]}
{"op":"mcm","clk":"11816178582","pt":1722808336190,"mc":[{"id":"1.231398046","rc":[{"batb":[[0,2.14,88],[1,2.08,41.06],[2,1.9,259.67]],"ltp":2.14,"tv":907.97,"id":40096581}]}]}
{"op":"mcm","clk":"11816179713","pt":1722808350391,"mc":[{"id":"1.231398046","rc":[{"batb":[[0,2.16,10],[1,2.14,88],[2,2.08,41.06]],"ltp":2.14,"tv":907.97,"id":40096581}]}]}
{"op":"mcm","clk":"11816179955","pt":1722808353818,"mc":[{"id":"1.231398046","rc":[{"batb":[[0,2.14,88],[1,2.08,41.06],[2,1.9,259.67]],"ltp":2.14,"tv":907.97,"id":40096581}]}]}
{"op":"mcm","clk":"11816180012","pt":1722808354696,"mc":[{"id":"1.231398046","rc":[{"batb":[[0,2.16,7.91],[1,2.14,88],[2,2.08,41.06]],"ltp":2.14,"tv":907.97,"id":40096581}]}]}
{"op":"mcm","clk":"11816181569","pt":1722808384179,"mc":[{"id":"1.231398046","rc":[{"batb":[[0,2.18,10],[1,2.16,7.91],[2,2.14,88]],"ltp":2.14,"tv":907.97,"id":40096581}]}]}
{"op":"mcm","clk":"11816181650","pt":1722808385940,"mc":[{"id":"1.231398046","rc":[{"batb":[[1,2.14,88],[2,2.08,41.06]],"ltp":2.14,"tv":907.97,"id":40096581}]}]}
{"op":"mcm","clk":"11816181730","pt":1722808387443,"mc":[{"id":"1.231398046","rc":[{"batb":[[0,2.14,88],[1,2.08,41.06],[2,1.9,259.67]],"ltp":2.14,"tv":907.97,"id":40096581}]}]}
{"op":"mcm","clk":"11816181801","pt":1722808388473,"mc":[{"id":"1.231398046","rc":[{"batb":[[0,2.16,5.17],[1,2.14,88],[2,2.08,41.06]],"ltp":2.14,"tv":907.97,"id":40096581}]}]}
{"op":"mcm","clk":"11816181828","pt":1722808388789,"mc":[{"id":"1.231398046","rc":[{"batb":[[0,2.16,13.46]],"ltp":2.14,"tv":907.97,"id":40096581}]}]}
{"op":"mcm","clk":"11816182007","pt":1722808392053,"mc":[{"id":"1.231398046","rc":[{"batb":[[0,2.18,10],[1,2.16,13.46],[2,2.14,88]],"ltp":2.14,"tv":907.97,"id":40096581}]}]}
{"op":"mcm","clk":"11816182086","pt":1722808393761,"mc":[{"id":"1.231398046","rc":[{"batb":[[1,2.16,8.29]],"ltp":2.14,"tv":907.97,"id":40096581}]}]}
{"op":"mcm","clk":"11816182180","pt":1722808395362,"mc":[{"id":"1.231398046","rc":[{"batb":[[0,2.14,88],[1,2.08,41.06],[2,1.9,259.67]],"ltp":2.14,"tv":907.97,"id":40096581}]}]}
{"op":"mcm","clk":"11816183810","pt":1722808423419,"mc":[{"id":"1.231398046","rc":[{"batb":[[0,2.18,10],[1,2.16,7.91],[2,2.14,88]],"ltp":2.14,"tv":907.97,"id":40096581}]}]}
{"op":"mcm","clk":"11816183891","pt":1722808424916,"mc":[{"id":"1.231398046","rc":[{"batb":[[1,2.14,88],[2,2.08,41.06]],"ltp":2.14,"tv":907.97,"id":40096581}]}]}
{"op":"mcm","clk":"11816183981","pt":1722808426830,"mc":[{"id":"1.231398046","rc":[{"batb":[[0,2.14,88],[1,2.08,41.06],[2,1.9,259.67]],"ltp":2.14,"tv":907.97,"id":40096581}]}]}
{"op":"mcm","clk":"11816185614","pt":1722808459055,"mc":[{"id":"1.231398046","rc":[{"batb":[[0,2.18,10],[1,2.16,7.91],[2,2.14,88]],"ltp":2.14,"tv":907.97,"id":40096581}]}]}
{"op":"mcm","clk":"11816185711","pt":1722808460761,"mc":[{"id":"1.231398046","rc":[{"batb":[[1,2.14,88],[2,2.08,41.06]],"ltp":2.14,"tv":907.97,"id":40096581}]}]}
{"op":"mcm","clk":"11816185807","pt":1722808462468,"mc":[{"id":"1.231398046","rc":[{"batb":[[0,2.14,88],[1,2.08,41.06],[2,1.9,259.67]],"ltp":2.14,"tv":907.97,"id":40096581}]}]}
{"op":"mcm","clk":"11816186120","pt":1722808468079,"mc":[{"id":"1.231398046","rc":[{"batb":[[0,2.18,10],[1,2.16,5.17],[2,2.14,88]],"ltp":2.14,"tv":907.97,"id":40096581}]}]}
{"op":"mcm","clk":"11816186207","pt":1722808469590,"mc":[{"id":"1.231398046","rc":[{"batb":[[1,2.14,88],[2,2.08,41.06]],"ltp":2.14,"tv":907.97,"id":40096581}]}]}
{"op":"mcm","clk":"11816186314","pt":1722808471510,"mc":[{"id":"1.231398046","rc":[{"batb":[[0,2.14,88],[1,2.08,41.06],[2,1.9,259.67]],"ltp":2.14,"tv":907.97,"id":40096581}]}]}
{"op":"mcm","clk":"11816187382","pt":1722808493234,"mc":[{"id":"1.231398046","rc":[{"batb":[[0,2.18,10],[1,2.16,7.91],[2,2.14,88]],"ltp":2.14,"tv":907.97,"id":40096581}]}]}
{"op":"mcm","clk":"11816187461","pt":1722808494732,"mc":[{"id":"1.231398046","rc":[{"batb":[[1,2.14,88],[2,2.08,41.06]],"ltp":2.14,"tv":907.97,"id":40096581}]}]}
{"op":"mcm","clk":"11816187554","pt":1722808496541,"mc":[{"id":"1.231398046","rc":[{"batb":[[0,2.14,88],[1,2.08,41.06],[2,1.9,259.67]],"ltp":2.14,"tv":907.97,"id":40096581}]}]}
{"op":"mcm","clk":"11816187815","pt":1722808501641,"mc":[{"id":"1.231398046","rc":[{"batb":[[0,2.16,10],[1,2.14,88],[2,2.08,41.06]],"ltp":2.14,"tv":907.97,"id":40096581}]}]}
{"op":"mcm","clk":"11816188002","pt":1722808504915,"mc":[{"id":"1.231398046","rc":[{"batb":[[0,2.14,88],[1,2.08,41.06],[2,1.9,259.67]],"ltp":2.14,"tv":907.97,"id":40096581}]}]}
{"op":"mcm","clk":"11816189290","pt":1722808527359,"mc":[{"id":"1.231398046","rc":[{"batb":[[0,2.16,8.3],[1,2.14,88],[2,2.08,41.06]],"ltp":2.14,"tv":907.97,"id":40096581}]}]}
{"op":"mcm","clk":"11816189301","pt":1722808527566,"mc":[{"id":"1.231398046","rc":[{"batb":[[0,2.18,10],[1,2.16,8.3],[2,2.14,88]],"ltp":2.14,"tv":907.97,"id":40096581}]}]}
{"op":"mcm","clk":"11816189396","pt":1722808529078,"mc":[{"id":"1.231398046","rc":[{"batb":[[1,2.14,88],[2,2.08,41.06]],"ltp":2.14,"tv":907.97,"id":40096581}]}]}
{"op":"mcm","clk":"11816189479","pt":1722808530882,"mc":[{"id":"1.231398046","rc":[{"batb":[[0,2.14,88],[1,2.08,41.06],[2,1.9,259.67]],"ltp":2.14,"tv":907.97,"id":40096581}]}]}
{"op":"mcm","clk":"11816190465","pt":1722808548864,"mc":[{"id":"1.231398046","rc":[{"batb":[[0,2.18,10],[1,2.16,5.17],[2,2.14,88]],"ltp":2.14,"tv":907.97,"id":40096581}]}]}
{"op":"mcm","clk":"11816190579","pt":1722808550881,"mc":[{"id":"1.231398046","rc":[{"batb":[[1,2.14,88],[2,2.08,41.06]],"ltp":2.14,"tv":907.97,"id":40096581}]}]}
{"op":"mcm","clk":"11816190639","pt":1722808552114,"mc":[{"id":"1.231398046","rc":[{"batb":[[0,2.14,88],[1,2.08,41.06],[2,1.9,259.67]],"ltp":2.14,"tv":907.97,"id":40096581}]}]}
{"op":"mcm","clk":"11816190913","pt":1722808557182,"mc":[{"id":"1.231398046","rc":[{"batb":[[0,2.16,10],[1,2.14,88],[2,2.08,41.06]],"ltp":2.14,"tv":907.97,"id":40096581}]}]}
{"op":"mcm","clk":"11816191093","pt":1722808560501,"mc":[{"id":"1.231398046","rc":[{"batb":[[0,2.14,88],[1,2.08,41.06],[2,1.9,259.67]],"ltp":2.14,"tv":907.97,"id":40096581}]}]}
{"op":"mcm","clk":"11816191163","pt":1722808561825,"mc":[{"id":"1.231398046","rc":[{"batb":[[0,2.16,7.91],[1,2.14,88],[2,2.08,41.06]],"ltp":2.14,"tv":907.97,"id":40096581}]}]}
{"op":"mcm","clk":"11816193262","pt":1722808598441,"mc":[{"id":"1.231398046","rc":[{"batb":[[0,2.18,10]],"ltp":2.14,"tv":907.97,"id":40096581}]}]}
{"op":"mcm","clk":"11816193427","pt":1722808601377,"mc":[{"id":"1.231398046","rc":[{"batb":[[0,2.14,88],[1,2.08,41.06],[2,1.9,259.67]],"ltp":2.14,"tv":907.97,"id":40096581}]}]}
{"op":"mcm","clk":"11816193491","pt":1722808602566,"mc":[{"id":"1.231398046","rc":[{"batb":[[0,2.16,7.91],[1,2.14,88],[2,2.08,41.06]],"ltp":2.14,"tv":907.97,"id":40096581}]}]}
{"op":"mcm","clk":"11816194376","pt":1722808617072,"mc":[{"id":"1.231398046","rc":[{"batb":[[0,2.18,10],[1,2.16,7.91],[2,2.14,88]],"ltp":2.14,"tv":907.97,"id":40096581}]}]}
{"op":"mcm","clk":"11816194437","pt":1722808618411,"mc":[{"id":"1.231398046","rc":[{"batb":[[1,2.14,88],[2,2.08,41.06]],"ltp":2.14,"tv":907.97,"id":40096581}]}]}
{"op":"mcm","clk":"11816194558","pt":1722808620484,"mc":[{"id":"1.231398046","rc":[{"batb":[[0,2.14,88],[1,2.08,41.06],[2,1.9,259.67]],"ltp":2.14,"tv":907.97,"id":40096581}]}]}
{"op":"mcm","clk":"11816195084","pt":1722808629929,"mc":[{"id":"1.231398046","rc":[{"batb":[[0,2.18,10],[1,2.16,5.17],[2,2.14,88]],"ltp":2.14,"tv":907.97,"id":40096581}]}]}
{"op":"mcm","clk":"11816195207","pt":1722808631724,"mc":[{"id":"1.231398046","rc":[{"batb":[[1,2.14,88],[2,2.08,41.06]],"ltp":2.14,"tv":907.97,"id":40096581}]}]}
{"op":"mcm","clk":"11816195307","pt":1722808633324,"mc":[{"id":"1.231398046","rc":[{"batb":[[0,2.14,88],[1,2.08,41.06],[2,1.9,259.67]],"ltp":2.14,"tv":907.97,"id":40096581}]}]}
{"op":"mcm","clk":"11816195567","pt":1722808638143,"mc":[{"id":"1.231398046","rc":[{"batb":[[0,2.16,17.91],[1,2.14,88],[2,2.08,41.06]],"ltp":2.14,"tv":907.97,"id":40096581}]}]}
{"op":"mcm","clk":"11816195791","pt":1722808641612,"mc":[{"id":"1.231398046","rc":[{"batb":[[0,2.16,7.91]],"ltp":2.14,"tv":907.97,"id":40096581}]}]}
{"op":"mcm","clk":"11816197368","pt":1722808669763,"mc":[{"id":"1.231398046","rc":[{"batb":[[0,2.18,10],[1,2.16,7.91],[2,2.14,88]],"ltp":2.14,"tv":907.97,"id":40096581}]}]}
{"op":"mcm","clk":"11816197446","pt":1722808670957,"mc":[{"id":"1.231398046","rc":[{"batb":[[1,2.14,88],[2,2.08,41.06]],"ltp":2.14,"tv":907.97,"id":40096581}]}]}
{"op":"mcm","clk":"11816197588","pt":1722808673385,"mc":[{"id":"1.231398046","rc":[{"batb":[[0,2.14,88],[1,2.08,41.06],[2,1.9,259.67]],"ltp":2.14,"tv":907.97,"id":40096581}]}]}
{"op":"mcm","clk":"11816197658","pt":1722808674571,"mc":[{"id":"1.231398046","rc":[{"batb":[[0,2.16,7.91],[1,2.14,88],[2,2.08,41.06]],"ltp":2.14,"tv":907.97,"id":40096581}]}]}
{"op":"mcm","clk":"11816197829","pt":1722808677467,"mc":[{"id":"1.231398046","rc":[{"batb":[[0,2.18,10]],"ltp":2.14,"tv":907.97,"id":40096581}]}]}
{"op":"mcm","clk":"11816197970","pt":1722808680193,"mc":[{"id":"1.231398046","rc":[{"batb":[[0,2.14,88],[1,2.08,41.06],[2,1.9,259.67]],"ltp":2.14,"tv":907.97,"id":40096581}]}]}
{"op":"mcm","clk":"11816199586","pt":1722808708827,"mc":[{"id":"1.231398046","rc":[{"batb":[[0,2.18,10],[1,2.16,5.17],[2,2.14,88]],"ltp":2.14,"tv":907.97,"id":40096581}]}]}
{"op":"mcm","clk":"11816199677","pt":1722808710222,"mc":[{"id":"1.231398046","rc":[{"batb":[[1,2.14,88],[2,2.08,41.06]],"ltp":2.14,"tv":907.97,"id":40096581}]}]}
{"op":"mcm","clk":"11816199794","pt":1722808712234,"mc":[{"id":"1.231398046","rc":[{"batb":[[0,2.14,88],[1,2.08,41.06],[2,1.9,259.67]],"ltp":2.14,"tv":907.97,"id":40096581}]}]}
{"op":"mcm","clk":"11816199886","pt":1722808713834,"mc":[{"id":"1.231398046","rc":[{"batb":[[0,2.16,7.91],[1,2.14,88],[2,2.08,41.06]],"ltp":2.14,"tv":907.97,"id":40096581}]}]}
{"op":"mcm","clk":"11816201569","pt":1722808742359,"mc":[{"id":"1.231398046","rc":[{"batb":[[0,2.18,10],[1,2.16,7.91],[2,2.14,88]],"ltp":2.14,"tv":907.97,"id":40096581}]}]}
{"op":"mcm","clk":"11816201661","pt":1722808743860,"mc":[{"id":"1.231398046","rc":[{"batb":[[1,2.14,88],[2,2.08,41.06]],"ltp":2.14,"tv":907.97,"id":40096581}]}]}
{"op":"mcm","clk":"11816201801","pt":1722808745835,"mc":[{"id":"1.231398046","rc":[{"batb":[[0,2.14,88],[1,2.08,41.06],[2,1.9,259.67]],"ltp":2.14,"tv":907.97,"id":40096581}]}]}
{"op":"mcm","clk":"11816202007","pt":1722808749050,"mc":[{"id":"1.231398046","rc":[{"batb":[[0,2.18,10],[1,2.16,7.91],[2,2.14,88]],"ltp":2.14,"tv":907.97,"id":40096581}]}]}
{"op":"mcm","clk":"11816202134","pt":1722808750963,"mc":[{"id":"1.231398046","rc":[{"batb":[[1,2.14,88],[2,2.08,41.06]],"ltp":2.14,"tv":907.97,"id":40096581}]}]}
{"op":"mcm","clk":"11816202227","pt":1722808752278,"mc":[{"id":"1.231398046","rc":[{"batb":[[0,2.14,88],[1,2.08,41.06],[2,1.9,259.67]],"ltp":2.14,"tv":907.97,"id":40096581}]}]}
{"op":"mcm","clk":"11816204139","pt":1722808784296,"mc":[{"id":"1.231398046","rc":[{"batb":[[0,2.16,10],[1,2.14,88],[2,2.08,41.06]],"ltp":2.14,"tv":907.97,"id":40096581}]}]}
{"op":"mcm","clk":"11816204176","pt":1722808785016,"mc":[{"id":"1.231398046","rc":[{"batb":[[0,2.16,17.91]],"ltp":2.14,"tv":907.97,"id":40096581}]}]}
{"op":"mcm","clk":"11816204311","pt":1722808787698,"mc":[{"id":"1.231398046","rc":[{"batb":[[0,2.16,7.91]],"ltp":2.14,"tv":907.97,"id":40096581}]}]}
{"op":"mcm","clk":"11816204394","pt":1722808788832,"mc":[{"id":"1.231398046","rc":[{"batb":[[0,2.16,13.46]],"ltp":2.14,"tv":907.97,"id":40096581}]}]}
{"op":"mcm","clk":"11816205540","pt":1722808809141,"mc":[{"id":"1.231398046","rc":[{"trd":[[1.83,8.85]],"batl":[[0,1.87,19.73]],"ltp":1.82,"tv":1148.28,"id":40096579},{"batb":[[0,2.18,10],[1,2.16,13.45],[2,2.14,88]],"ltp":2.14,"tv":907.97,"id":40096581}],"tv":2056.25}]}
{"op":"mcm","clk":"11816205659","pt":1722808811461,"mc":[{"id":"1.231398046","rc":[{"batb":[[1,2.14,88],[2,2.08,41.06]],"ltp":2.14,"tv":907.97,"id":40096581}]}]}
{"op":"mcm","clk":"11816205718","pt":1722808812548,"mc":[{"id":"1.231398046","rc":[{"batb":[[0,2.14,88],[1,2.08,41.06],[2,1.9,259.67]],"ltp":2.14,"tv":907.97,"id":40096581}]}]}
{"op":"mcm","clk":"11816205982","pt":1722808817666,"mc":[{"id":"1.231398046","rc":[{"batb":[[0,2.16,10],[1,2.14,88],[2,2.08,41.06]],"ltp":2.14,"tv":907.97,"id":40096581}]}]}
{"op":"mcm","clk":"11816206165","pt":1722808821137,"mc":[{"id":"1.231398046","rc":[{"batb":[[0,2.14,88],[1,2.08,41.06],[2,1.9,259.67]],"ltp":2.14,"tv":907.97,"id":40096581}]}]}
{"op":"mcm","clk":"11816206330","pt":1722808824357,"mc":[{"id":"1.231398046","rc":[{"batb":[[0,2.18,10],[1,2.16,5.17],[2,2.14,88]],"ltp":2.14,"tv":907.97,"id":40096581}]}]}
{"op":"mcm","clk":"11816206450","pt":1722808826978,"mc":[{"id":"1.231398046","rc":[{"batb":[[1,2.14,88],[2,2.08,41.06]],"ltp":2.14,"tv":907.97,"id":40096581}]}]}
{"op":"mcm","clk":"11816206487","pt":1722808827659,"mc":[{"id":"1.231398046","rc":[{"batb":[[0,2.14,88],[1,2.08,41.06],[2,1.9,259.67]],"ltp":2.14,"tv":907.97,"id":40096581}]}]}
{"op":"mcm","clk":"11816206625","pt":1722808830650,"mc":[{"id":"1.231398046","rc":[{"batb":[[0,2.18,10],[1,2.16,7.9],[2,2.14,88]],"ltp":2.14,"tv":907.97,"id":40096581}]}]}
{"op":"mcm","clk":"11816206797","pt":1722808834066,"mc":[{"id":"1.231398046","rc":[{"batb":[[0,2.14,88],[1,2.08,41.06],[2,1.9,259.67]],"ltp":2.14,"tv":907.97,"id":40096581}]}]}
{"op":"mcm","clk":"11816206967","pt":1722808837578,"mc":[{"id":"1.231398046","rc":[{"batb":[[0,2.16,10],[1,2.14,88],[2,2.08,41.06]],"ltp":2.14,"tv":907.97,"id":40096581}]}]}
{"op":"mcm","clk":"11816207198","pt":1722808840989,"mc":[{"id":"1.231398046","rc":[{"batb":[[0,2.14,88],[1,2.08,41.06],[2,1.9,259.67]],"ltp":2.14,"tv":907.97,"id":40096581}]}]}
{"op":"mcm","clk":"11816208617","pt":1722808867538,"mc":[{"id":"1.231398046","rc":[{"batb":[[0,2.16,10],[1,2.14,88],[2,2.08,41.06]],"ltp":2.14,"tv":907.97,"id":40096581}]}]}
{"op":"mcm","clk":"11816208714","pt":1722808869510,"mc":[{"id":"1.231398046","rc":[{"batb":[[0,2.16,17.9]],"ltp":2.14,"tv":907.97,"id":40096581}]}]}
{"op":"mcm","clk":"11816208777","pt":1722808870908,"mc":[{"id":"1.231398046","rc":[{"batb":[[0,2.16,7.9]],"ltp":2.14,"tv":907.97,"id":40096581}]}]}
{"op":"mcm","clk":"11816209037","pt":1722808876236,"mc":[{"id":"1.231398046","rc":[{"batb":[[0,2.18,10],[1,2.16,13.46],[2,2.14,88]],"ltp":2.14,"tv":907.97,"id":40096581}]}]}
{"op":"mcm","clk":"11816209208","pt":1722808879444,"mc":[{"id":"1.231398046","rc":[{"batb":[[0,2.16,7.9],[1,2.14,88],[2,2.08,41.06]],"ltp":2.14,"tv":907.97,"id":40096581}]}]}
{"op":"mcm","clk":"11816209571","pt":1722808885951,"mc":[{"id":"1.231398046","rc":[{"batb":[[0,2.18,10],[1,2.16,7.9],[2,2.14,88]],"ltp":2.14,"tv":907.97,"id":40096581}]}]}
{"op":"mcm","clk":"11816209604","pt":1722808886565,"mc":[{"id":"1.231398046","rc":[{"batb":[[1,2.14,88],[2,2.08,41.06]],"ltp":2.14,"tv":907.97,"id":40096581}]}]}
{"op":"mcm","clk":"11816209766","pt":1722808889354,"mc":[{"id":"1.231398046","rc":[{"batb":[[0,2.14,88],[1,2.08,41.06],[2,1.9,259.67]],"ltp":2.14,"tv":907.97,"id":40096581}]}]}
{"op":"mcm","clk":"11816210069","pt":1722808894678,"mc":[{"id":"1.231398046","rc":[{"batb":[[0,2.16,10],[1,2.14,88],[2,2.08,41.06]],"ltp":2.14,"tv":907.97,"id":40096581}]}]}
{"op":"mcm","clk":"11816210273","pt":1722808898083,"mc":[{"id":"1.231398046","rc":[{"batb":[[0,2.14,88],[1,2.08,41.06],[2,1.9,259.67]],"ltp":2.14,"tv":907.97,"id":40096581}]}]}
{"op":"mcm","clk":"11816210402","pt":1722808900357,"mc":[{"id":"1.231398046","rc":[{"batb":[[0,2.18,10],[1,2.16,7.9],[2,2.14,88]],"ltp":2.14,"tv":907.97,"id":40096581}]}]}
{"op":"mcm","clk":"11816210478","pt":1722808902065,"mc":[{"id":"1.231398046","rc":[{"batb":[[1,2.14,88],[2,2.08,41.06]],"ltp":2.14,"tv":907.97,"id":40096581}]}]}
{"op":"mcm","clk":"11816210560","pt":1722808903670,"mc":[{"id":"1.231398046","rc":[{"batb":[[0,2.14,88],[1,2.08,41.06],[2,1.9,259.67]],"ltp":2.14,"tv":907.97,"id":40096581}]}]}
{"op":"mcm","clk":"11816211784","pt":1722808926424,"mc":[{"id":"1.231398046","rc":[{"batb":[[0,2.16,10],[1,2.14,88],[2,2.08,41.06]],"ltp":2.14,"tv":907.97,"id":40096581}]}]}
{"op":"mcm","clk":"11816211963","pt":1722808929840,"mc":[{"id":"1.231398046","rc":[{"batb":[[0,2.14,88],[1,2.08,41.06],[2,1.9,259.67]],"ltp":2.14,"tv":907.97,"id":40096581}]}]}
{"op":"mcm","clk":"11816212250","pt":1722808935425,"mc":[{"id":"1.231398046","rc":[{"batb":[[0,2.16,5.17],[1,2.14,88],[2,2.08,41.06]],"ltp":2.14,"tv":907.97,"id":40096581}]}]}
{"op":"mcm","clk":"11816212254","pt":1722808935527,"mc":[{"id":"1.231398046","rc":[{"batb":[[0,2.18,10],[1,2.16,5.17],[2,2.14,88]],"ltp":2.14,"tv":907.97,"id":40096581}]}]}
{"op":"mcm","clk":"11816212368","pt":1722808937827,"mc":[{"id":"1.231398046","rc":[{"batb":[[1,2.14,88],[2,2.08,41.06]],"ltp":2.14,"tv":907.97,"id":40096581}]}]}
{"op":"mcm","clk":"11816212458","pt":1722808939423,"mc":[{"id":"1.231398046","rc":[{"batb":[[0,2.16,7.9]],"ltp":2.14,"tv":907.97,"id":40096581}]}]}
{"op":"mcm","clk":"11816213522","pt":1722808962432,"mc":[{"id":"1.231398046","rc":[{"batb":[[0,2.18,10],[1,2.16,7.9],[2,2.14,88]],"ltp":2.14,"tv":907.97,"id":40096581}]}]}
{"op":"mcm","clk":"11816213551","pt":1722808963164,"mc":[{"id":"1.231398046","rc":[{"batb":[[1,2.14,88],[2,2.08,41.06]],"ltp":2.14,"tv":907.97,"id":40096581}]}]}
{"op":"mcm","clk":"11816213677","pt":1722808965953,"mc":[{"id":"1.231398046","rc":[{"batb":[[0,2.14,88],[1,2.08,41.06],[2,1.9,259.67]],"ltp":2.14,"tv":907.97,"id":40096581}]}]}
{"op":"mcm","clk":"11816214239","pt":1722808977457,"mc":[{"id":"1.231398046","rc":[{"batb":[[0,2.18,10],[1,2.16,7.9],[2,2.14,88]],"ltp":2.14,"tv":907.97,"id":40096581}]}]}
{"op":"mcm","clk":"11816214306","pt":1722808978896,"mc":[{"id":"1.231398046","rc":[{"batb":[[1,2.14,88],[2,2.08,41.06]],"ltp":2.14,"tv":907.97,"id":40096581}]}]}
{"op":"mcm","clk":"11816214411","pt":1722808980902,"mc":[{"id":"1.231398046","rc":[{"batb":[[0,2.14,88],[1,2.08,41.06],[2,1.9,259.67]],"ltp":2.14,"tv":907.97,"id":40096581}]}]}
{"op":"mcm","clk":"11816214707","pt":1722808986803,"mc":[{"id":"1.231398046","rc":[{"batb":[[0,2.16,10],[1,2.14,88],[2,2.08,41.06]],"ltp":2.14,"tv":907.97,"id":40096581}]}]}
{"op":"mcm","clk":"11816214844","pt":1722808990137,"mc":[{"id":"1.231398046","rc":[{"batb":[[0,2.14,88],[1,2.08,41.06],[2,1.9,259.67]],"ltp":2.14,"tv":907.97,"id":40096581}]}]}
{"op":"mcm","clk":"11816215638","pt":1722809005419,"mc":[{"id":"1.231398046","rc":[{"batb":[[0,2.18,10],[1,2.16,5.17],[2,2.14,88]],"ltp":2.14,"tv":907.97,"id":40096581}]}]}
{"op":"mcm","clk":"11816215706","pt":1722809006918,"mc":[{"id":"1.231398046","rc":[{"batb":[[1,2.14,88],[2,2.08,41.06]],"ltp":2.14,"tv":907.97,"id":40096581}]}]}
{"op":"mcm","clk":"11816215814","pt":1722809008834,"mc":[{"id":"1.231398046","rc":[{"batb":[[0,2.14,88],[1,2.08,41.06],[2,1.9,259.67]],"ltp":2.14,"tv":907.97,"id":40096581}]}]}
{"op":"mcm","clk":"11816216026","pt":1722809012469,"mc":[{"id":"1.231398046","rc":[{"batb":[[0,2.18,10],[1,2.16,7.9],[2,2.14,88]],"ltp":2.14,"tv":907.97,"id":40096581}]}]}
{"op":"mcm","clk":"11816216199","pt":1722809015358,"mc":[{"id":"1.231398046","rc":[{"batb":[[1,2.14,88],[2,2.08,41.06]],"ltp":2.14,"tv":907.97,"id":40096581}]}]}
{"op":"mcm","clk":"11816216233","pt":1722809015820,"mc":[{"id":"1.231398046","rc":[{"batb":[[0,2.14,88],[1,2.08,41.06],[2,1.9,259.67]],"ltp":2.14,"tv":907.97,"id":40096581}]}]}
{"op":"mcm","clk":"11816216640","pt":1722809023049,"mc":[{"id":"1.231398046","rc":[{"batb":[[0,2.16,10],[1,2.14,88],[2,2.08,41.06]],"ltp":2.14,"tv":907.97,"id":40096581}]}]}
{"op":"mcm","clk":"11816216826","pt":1722809026351,"mc":[{"id":"1.231398046","rc":[{"batb":[[0,2.14,88],[1,2.08,41.06],[2,1.9,259.67]],"ltp":2.14,"tv":907.97,"id":40096581}]}]}
{"op":"mcm","clk":"11816217102","pt":1722809030483,"mc":[{"id":"1.231398046","rc":[{"batb":[[0,2.16,10],[1,2.14,88],[2,2.08,41.06]],"ltp":2.14,"tv":907.97,"id":40096581}]}]}
{"op":"mcm","clk":"11816217313","pt":1722809033891,"mc":[{"id":"1.231398046","rc":[{"batb":[[0,2.14,88],[1,2.08,41.06],[2,1.9,259.67]],"ltp":2.14,"tv":907.97,"id":40096581}]}]}
{"op":"mcm","clk":"11816217661","pt":1722809039566,"mc":[{"id":"1.231398046","rc":[{"batb":[[0,2.16,10],[1,2.14,88],[2,2.08,41.06]],"ltp":2.14,"tv":907.97,"id":40096581}]}]}
{"op":"mcm","clk":"11816217812","pt":1722809042877,"mc":[{"id":"1.231398046","rc":[{"batb":[[0,2.14,88],[1,2.08,41.06],[2,1.9,259.67]],"ltp":2.14,"tv":907.97,"id":40096581}]}]}
{"op":"mcm","clk":"11816218155","pt":1722809050307,"mc":[{"id":"1.231398046","rc":[{"batb":[[0,2.16,10],[1,2.14,88],[2,2.08,41.06]],"ltp":2.14,"tv":907.97,"id":40096581}]}]}
{"op":"mcm","clk":"11816218352","pt":1722809053672,"mc":[{"id":"1.231398046","rc":[{"batb":[[0,2.14,88],[1,2.08,41.06],[2,1.9,259.67]],"ltp":2.14,"tv":907.97,"id":40096581}]}]}
{"op":"mcm","clk":"11816218487","pt":1722809056715,"mc":[{"id":"1.231398046","rc":[{"batb":[[0,2.18,10],[1,2.16,7.9],[2,2.14,88]],"ltp":2.14,"tv":907.97,"id":40096581}]}]}
{"op":"mcm","clk":"11816218583","pt":1722809058211,"mc":[{"id":"1.231398046","rc":[{"batb":[[1,2.14,88],[2,2.08,41.06]],"ltp":2.14,"tv":907.97,"id":40096581}]}]}
{"op":"mcm","clk":"11816218706","pt":1722809060228,"mc":[{"id":"1.231398046","rc":[{"batb":[[0,2.14,88],[1,2.08,41.06],[2,1.9,259.67]],"ltp":2.14,"tv":907.97,"id":40096581}]}]}
{"op":"mcm","clk":"11816219122","pt":1722809069119,"mc":[{"id":"1.231398046","rc":[{"batb":[[0,2.16,10],[1,2.14,88],[2,2.08,41.06]],"ltp":2.14,"tv":907.97,"id":40096581}]}]}
{"op":"mcm","clk":"11816219309","pt":1722809072419,"mc":[{"id":"1.231398046","rc":[{"batb":[[0,2.14,88],[1,2.08,41.06],[2,1.9,259.67]],"ltp":2.14,"tv":907.97,"id":40096581}]}]}
{"op":"mcm","clk":"11816219909","pt":1722809084755,"mc":[{"id":"1.231398046","rc":[{"batb":[[0,2.18,10],[1,2.16,5.17],[2,2.14,88]],"ltp":2.14,"tv":907.97,"id":40096581}]}]}
{"op":"mcm","clk":"11816219985","pt":1722809086255,"mc":[{"id":"1.231398046","rc":[{"batb":[[1,2.14,88],[2,2.08,41.06]],"ltp":2.14,"tv":907.97,"id":40096581}]}]}
{"op":"mcm","clk":"11816220116","pt":1722809088128,"mc":[{"id":"1.231398046","rc":[{"batb":[[0,2.14,88],[1,2.08,41.06],[2,1.9,259.67]],"ltp":2.14,"tv":907.97,"id":40096581}]}]}
{"op":"mcm","clk":"11816220759","pt":1722809100369,"mc":[{"id":"1.231398046","rc":[{"batb":[[0,2.18,10],[1,2.16,7.9],[2,2.14,88]],"ltp":2.14,"tv":907.97,"id":40096581}]}]}
{"op":"mcm","clk":"11816220863","pt":1722809102072,"mc":[{"id":"1.231398046","rc":[{"batb":[[1,2.14,88],[2,2.08,41.06]],"ltp":2.14,"tv":907.97,"id":40096581}]}]}
{"op":"mcm","clk":"11816220952","pt":1722809103680,"mc":[{"id":"1.231398046","rc":[{"batb":[[0,2.14,88],[1,2.08,41.06],[2,1.9,259.67]],"ltp":2.14,"tv":907.97,"id":40096581}]}]}
{"op":"mcm","clk":"11816223159","pt":1722809143033,"mc":[{"id":"1.231398046","rc":[{"batb":[[0,2.18,10],[1,2.16,7.9],[2,2.14,88]],"ltp":2.14,"tv":907.97,"id":40096581}]}]}
{"op":"mcm","clk":"11816223231","pt":1722809144675,"mc":[{"id":"1.231398046","rc":[{"batb":[[1,2.14,88],[2,2.08,41.06]],"ltp":2.14,"tv":907.97,"id":40096581}]}]}
{"op":"mcm","clk":"11816223304","pt":1722809146378,"mc":[{"id":"1.231398046","rc":[{"batb":[[0,2.14,88],[1,2.08,41.06],[2,1.9,259.67]],"ltp":2.14,"tv":907.97,"id":40096581}]}]}
{"op":"mcm","clk":"11816224467","pt":1722809169313,"mc":[{"id":"1.231398046","rc":[{"batb":[[0,2.18,10],[1,2.16,5.17],[2,2.14,88]],"ltp":2.14,"tv":907.97,"id":40096581}]}]}
{"op":"mcm","clk":"11816224524","pt":1722809170598,"mc":[{"id":"1.231398046","rc":[{"batb":[[1,2.14,88],[2,2.08,41.06]],"ltp":2.14,"tv":907.97,"id":40096581}]}]}
{"op":"mcm","clk":"11816224624","pt":1722809172510,"mc":[{"id":"1.231398046","rc":[{"batb":[[0,2.14,88],[1,2.08,41.06],[2,1.9,259.67]],"ltp":2.14,"tv":907.97,"id":40096581}]}]}
{"op":"mcm","clk":"11816225033","pt":1722809182314,"mc":[{"id":"1.231398046","rc":[{"batb":[[0,2.18,10],[1,2.16,7.9],[2,2.14,88]],"ltp":2.14,"tv":907.97,"id":40096581}]}]}
{"op":"mcm","clk":"11816225110","pt":1722809183911,"mc":[{"id":"1.231398046","rc":[{"batb":[[1,2.14,88],[2,2.08,41.06]],"ltp":2.14,"tv":907.97,"id":40096581}]}]}
{"op":"mcm","clk":"11816225199","pt":1722809185720,"mc":[{"id":"1.231398046","rc":[{"batb":[[0,2.14,88],[1,2.08,41.06],[2,1.9,259.67]],"ltp":2.14,"tv":907.97,"id":40096581}]}]}
{"op":"mcm","clk":"11816227108","pt":1722809224376,"mc":[{"id":"1.231398046","rc":[{"batb":[[0,2.18,10],[1,2.16,7.9],[2,2.14,88]],"ltp":2.14,"tv":907.97,"id":40096581}]}]}
{"op":"mcm","clk":"11816227192","pt":1722809226180,"mc":[{"id":"1.231398046","rc":[{"batb":[[1,2.14,88],[2,2.08,41.06]],"ltp":2.14,"tv":907.97,"id":40096581}]}]}
{"op":"mcm","clk":"11816227321","pt":1722809227885,"mc":[{"id":"1.231398046","rc":[{"batb":[[0,2.14,88],[1,2.08,41.06],[2,1.9,259.67]],"ltp":2.14,"tv":907.97,"id":40096581}]}]}
{"op":"mcm","clk":"11816228951","pt":1722809250194,"mc":[{"id":"1.231398046","rc":[{"batb":[[0,2.18,10],[1,2.16,5.17],[2,2.14,88]],"ltp":2.14,"tv":907.97,"id":40096581}]}]}
{"op":"mcm","clk":"11816229007","pt":1722809251277,"mc":[{"id":"1.231398046","rc":[{"batb":[[1,2.14,88],[2,2.08,41.06]],"ltp":2.14,"tv":907.97,"id":40096581}]}]}
{"op":"mcm","clk":"11816229133","pt":1722809253496,"mc":[{"id":"1.231398046","rc":[{"batb":[[0,2.14,88],[1,2.08,41.06],[2,1.9,259.67]],"ltp":2.14,"tv":907.97,"id":40096581}]}]}
{"op":"mcm","clk":"11816229274","pt":1722809256126,"mc":[{"id":"1.231398046","rc":[{"batb":[[0,2.16,10],[1,2.14,88],[2,2.08,41.06]],"ltp":2.14,"tv":907.97,"id":40096581}]}]}
{"op":"mcm","clk":"11816229446","pt":1722809259429,"mc":[{"id":"1.231398046","rc":[{"batb":[[0,2.14,88],[1,2.08,41.06],[2,1.9,259.67]],"ltp":2.14,"tv":907.97,"id":40096581}]}]}
{"op":"mcm","clk":"11816229726","pt":1722809264103,"mc":[{"id":"1.231398046","rc":[{"batb":[[0,2.18,10],[1,2.16,7.9],[2,2.14,88]],"ltp":2.14,"tv":907.97,"id":40096581}]}]}
{"op":"mcm","clk":"11816229820","pt":1722809265593,"mc":[{"id":"1.231398046","rc":[{"batb":[[1,2.14,88],[2,2.08,41.06]],"ltp":2.14,"tv":907.97,"id":40096581}]}]}
{"op":"mcm","clk":"11816229940","pt":1722809267605,"mc":[{"id":"1.231398046","rc":[{"batb":[[0,2.14,88],[1,2.08,41.06],[2,1.9,259.67]],"ltp":2.14,"tv":907.97,"id":40096581}]}]}
{"op":"mcm","clk":"11816231137","pt":1722809289523,"mc":[{"id":"1.231398046","rc":[{"batb":[[0,2.16,10],[1,2.14,88],[2,2.08,41.06]],"ltp":2.14,"tv":907.97,"id":40096581}]}]}
{"op":"mcm","clk":"11816231307","pt":1722809292835,"mc":[{"id":"1.231398046","rc":[{"batb":[[0,2.14,88],[1,2.08,41.06],[2,1.9,259.67]],"ltp":2.14,"tv":907.97,"id":40096581}]}]}
{"op":"mcm","clk":"11816231771","pt":1722809300857,"mc":[{"id":"1.231398046","rc":[{"batb":[[0,2.16,10],[1,2.14,88],[2,2.08,41.06]],"ltp":2.14,"tv":907.97,"id":40096581}]}]}
{"op":"mcm","clk":"11816231917","pt":1722809303442,"mc":[{"id":"1.231398046","rc":[{"batb":[[0,2.16,17.9]],"ltp":2.14,"tv":907.97,"id":40096581}]}]}
{"op":"mcm","clk":"11816231958","pt":1722809304268,"mc":[{"id":"1.231398046","rc":[{"batb":[[0,2.16,7.9]],"ltp":2.14,"tv":907.97,"id":40096581}]}]}
{"op":"mcm","clk":"11816232327","pt":1722809311452,"mc":[{"id":"1.231398046","rc":[{"batb":[[0,2.18,10],[1,2.16,7.9],[2,2.14,88]],"ltp":2.14,"tv":907.97,"id":40096581}]}]}
{"op":"mcm","clk":"11816232443","pt":1722809313675,"mc":[{"id":"1.231398046","rc":[{"batb":[[1,2.14,88],[2,2.08,41.06]],"ltp":2.14,"tv":907.97,"id":40096581}]}]}
{"op":"mcm","clk":"11816232516","pt":1722809314866,"mc":[{"id":"1.231398046","rc":[{"batb":[[0,2.14,88],[1,2.08,41.06],[2,1.9,259.67]],"ltp":2.14,"tv":907.97,"id":40096581}]}]}
{"op":"mcm","clk":"11816233379","pt":1722809329502,"mc":[{"id":"1.231398046","rc":[{"batb":[[0,2.16,10],[1,2.14,88],[2,2.08,41.06]],"ltp":2.14,"tv":907.97,"id":40096581}]}]}
{"op":"mcm","clk":"11816233508","pt":1722809332801,"mc":[{"id":"1.231398046","rc":[{"batb":[[0,2.14,88],[1,2.08,41.06],[2,1.9,259.67]],"ltp":2.14,"tv":907.97,"id":40096581}]}]}
{"op":"mcm","clk":"11816233561","pt":1722809333992,"mc":[{"id":"1.231398046","rc":[{"batb":[[0,2.16,5.17],[1,2.14,88],[2,2.08,41.06]],"ltp":2.14,"tv":907.97,"id":40096581}]}]}
{"op":"mcm","clk":"11816234167","pt":1722809345415,"mc":[{"id":"1.231398046","rc":[{"batb":[[0,2.16,13.46]],"ltp":2.14,"tv":907.97,"id":40096581}]}]}
{"op":"mcm","clk":"11816234232","pt":1722809346304,"mc":[{"id":"1.231398046","rc":[{"batb":[[0,2.18,10],[1,2.16,8.29],[2,2.14,88]],"ltp":2.14,"tv":907.97,"id":40096581}]}]}
{"op":"mcm","clk":"11816234272","pt":1722809347027,"mc":[{"id":"1.231398046","rc":[{"batb":[[1,2.14,88],[2,2.08,41.06]],"ltp":2.14,"tv":907.97,"id":40096581}]}]}
{"op":"mcm","clk":"11816234406","pt":1722809349005,"mc":[{"id":"1.231398046","rc":[{"batb":[[0,2.14,88],[1,2.08,41.06],[2,1.9,259.67]],"ltp":2.14,"tv":907.97,"id":40096581}]}]}
{"op":"mcm","clk":"11816235782","pt":1722809374046,"mc":[{"id":"1.231398046","rc":[{"batb":[[0,2.16,10],[1,2.14,88],[2,2.08,41.06]],"ltp":2.14,"tv":907.97,"id":40096581}]}]}
{"op":"mcm","clk":"11816235950","pt":1722809377558,"mc":[{"id":"1.231398046","rc":[{"batb":[[0,2.14,88],[1,2.08,41.06],[2,1.9,259.67]],"ltp":2.14,"tv":907.97,"id":40096581}]}]}
{"op":"mcm","clk":"11816236410","pt":1722809386177,"mc":[{"id":"1.231398046","rc":[{"batb":[[0,2.18,10],[1,2.16,7.9],[2,2.14,88]],"ltp":2.14,"tv":907.97,"id":40096581}]}]}
{"op":"mcm","clk":"11816236497","pt":1722809387779,"mc":[{"id":"1.231398046","rc":[{"batb":[[1,2.14,88],[2,2.08,41.06]],"ltp":2.14,"tv":907.97,"id":40096581}]}]}
{"op":"mcm","clk":"11816236582","pt":1722809389681,"mc":[{"id":"1.231398046","rc":[{"batb":[[0,2.14,88],[1,2.08,41.06],[2,1.9,259.67]],"ltp":2.14,"tv":907.97,"id":40096581}]}]}
{"op":"mcm","clk":"11816238007","pt":1722809414798,"mc":[{"id":"1.231398046","rc":[{"batb":[[0,2.18,10],[1,2.16,5.17],[2,2.14,88]],"ltp":2.14,"tv":907.97,"id":40096581}]}]}
{"op":"mcm","clk":"11816238099","pt":1722809416089,"mc":[{"id":"1.231398046","rc":[{"batb":[[1,2.14,88],[2,2.08,41.06]],"ltp":2.14,"tv":907.97,"id":40096581}]}]}
{"op":"mcm","clk":"11816238225","pt":1722809418308,"mc":[{"id":"1.231398046","rc":[{"batb":[[0,2.14,88],[1,2.08,41.06],[2,1.9,259.67]],"ltp":2.14,"tv":907.97,"id":40096581}]}]}
{"op":"mcm","clk":"11816238483","pt":1722809422804,"mc":[{"id":"1.231398046","rc":[{"batb":[[0,2.16,10],[1,2.14,88],[2,2.08,41.06]],"ltp":2.14,"tv":907.97,"id":40096581}]}]}
{"op":"mcm","clk":"11816238674","pt":1722809426310,"mc":[{"id":"1.231398046","rc":[{"batb":[[0,2.16,7.9]],"ltp":2.14,"tv":907.97,"id":40096581}]}]}
{"op":"mcm","clk":"11816239490","pt":1722809442249,"mc":[{"id":"1.231398046","rc":[{"batb":[[0,2.18,10],[1,2.16,7.9],[2,2.14,88]],"ltp":2.14,"tv":907.97,"id":40096581}]}]}
{"op":"mcm","clk":"11816239588","pt":1722809443851,"mc":[{"id":"1.231398046","rc":[{"batb":[[1,2.14,88],[2,2.08,41.06]],"ltp":2.14,"tv":907.97,"id":40096581}]}]}
{"op":"mcm","clk":"11816239669","pt":1722809445554,"mc":[{"id":"1.231398046","rc":[{"batb":[[0,2.14,88],[1,2.08,41.06],[2,1.9,259.67]],"ltp":2.14,"tv":907.97,"id":40096581}]}]}
{"op":"mcm","clk":"11816239895","pt":1722809449272,"mc":[{"id":"1.231398046","rc":[{"batb":[[0,2.16,10],[1,2.14,88],[2,2.08,41.06]],"ltp":2.14,"tv":907.97,"id":40096581}]}]}
{"op":"mcm","clk":"11816240091","pt":1722809452780,"mc":[{"id":"1.231398046","rc":[{"batb":[[0,2.14,88],[1,2.08,41.06],[2,1.9,259.67]],"ltp":2.14,"tv":907.97,"id":40096581}]}]}
{"op":"mcm","clk":"11816240349","pt":1722809458163,"mc":[{"id":"1.231398046","rc":[{"batb":[[0,2.16,10],[1,2.14,88],[2,2.08,41.06]],"ltp":2.14,"tv":907.97,"id":40096581}]}]}
{"op":"mcm","clk":"11816240515","pt":1722809461572,"mc":[{"id":"1.231398046","rc":[{"batb":[[0,2.14,88],[1,2.08,41.06],[2,1.9,259.67]],"ltp":2.14,"tv":907.97,"id":40096581}]}]}
{"op":"mcm","clk":"11816240913","pt":1722809468495,"mc":[{"id":"1.231398046","rc":[{"batb":[[0,2.16,7.9],[1,2.14,88],[2,2.08,41.06]],"ltp":2.14,"tv":907.97,"id":40096581}]}]}
{"op":"mcm","clk":"11816240918","pt":1722809468594,"mc":[{"id":"1.231398046","rc":[{"batb":[[0,2.18,10],[1,2.16,7.9],[2,2.14,88]],"ltp":2.14,"tv":907.97,"id":40096581}]}]}
{"op":"mcm","clk":"11816241042","pt":1722809470717,"mc":[{"id":"1.231398046","rc":[{"batb":[[1,2.14,88],[2,2.08,41.06]],"ltp":2.14,"tv":907.97,"id":40096581}]}]}
{"op":"mcm","clk":"11816241138","pt":1722809472110,"mc":[{"id":"1.231398046","rc":[{"batb":[[0,2.14,88],[1,2.08,41.06],[2,1.9,259.67]],"ltp":2.14,"tv":907.97,"id":40096581}]}]}
{"op":"mcm","clk":"11816241900","pt":1722809486260,"mc":[{"id":"1.231398046","rc":[{"batb":[[0,2.16,10],[1,2.14,88],[2,2.08,41.06]],"ltp":2.14,"tv":907.97,"id":40096581}]}]}
{"op":"mcm","clk":"11816242078","pt":1722809489774,"mc":[{"id":"1.231398046","rc":[{"batb":[[0,2.14,88],[1,2.08,41.06],[2,1.9,259.67]],"ltp":2.14,"tv":907.97,"id":40096581}]}]}
{"op":"mcm","clk":"11816242241","pt":1722809492356,"mc":[{"id":"1.231398046","rc":[{"batb":[[0,2.18,10],[1,2.16,5.17],[2,2.14,88]],"ltp":2.14,"tv":907.97,"id":40096581}]}]}
{"op":"mcm","clk":"11816242342","pt":1722809493959,"mc":[{"id":"1.231398046","rc":[{"batb":[[1,2.14,88],[2,2.08,41.06]],"ltp":2.14,"tv":907.97,"id":40096581}]}]}
{"op":"mcm","clk":"11816242451","pt":1722809495668,"mc":[{"id":"1.231398046","rc":[{"batb":[[0,2.14,88],[1,2.08,41.06],[2,1.9,259.67]],"ltp":2.14,"tv":907.97,"id":40096581}]}]}
{"op":"mcm","clk":"11816243226","pt":1722809509958,"mc":[{"id":"1.231398046","rc":[{"batb":[[0,2.18,10],[1,2.16,7.9],[2,2.14,88]],"ltp":2.14,"tv":907.97,"id":40096581}]}]}
{"op":"mcm","clk":"11816243296","pt":1722809511403,"mc":[{"id":"1.231398046","rc":[{"batb":[[1,2.14,88],[2,2.08,41.06]],"ltp":2.14,"tv":907.97,"id":40096581}]}]}
{"op":"mcm","clk":"11816243415","pt":1722809513370,"mc":[{"id":"1.231398046","rc":[{"batb":[[0,2.14,88],[1,2.08,41.06],[2,1.9,259.67]],"ltp":2.14,"tv":907.97,"id":40096581}]}]}
{"op":"mcm","clk":"11816245570","pt":1722809550220,"mc":[{"id":"1.231398046","rc":[{"batb":[[0,2.18,10],[1,2.16,7.9],[2,2.14,88]],"ltp":2.14,"tv":907.97,"id":40096581}]}]}
{"op":"mcm","clk":"11816245688","pt":1722809552343,"mc":[{"id":"1.231398046","rc":[{"batb":[[1,2.14,88],[2,2.08,41.06]],"ltp":2.14,"tv":907.97,"id":40096581}]}]}
{"op":"mcm","clk":"11816245766","pt":1722809553736,"mc":[{"id":"1.231398046","rc":[{"batb":[[0,2.14,88],[1,2.08,41.06],[2,1.9,259.67]],"ltp":2.14,"tv":907.97,"id":40096581}]}]}
{"op":"mcm","clk":"11816246858","pt":1722809571359,"mc":[{"id":"1.231398046","rc":[{"batb":[[0,2.18,10],[1,2.16,5.17],[2,2.14,88]],"ltp":2.14,"tv":907.97,"id":40096581}]}]}
{"op":"mcm","clk":"11816246937","pt":1722809572549,"mc":[{"id":"1.231398046","rc":[{"batb":[[1,2.14,88],[2,2.08,41.06]],"ltp":2.14,"tv":907.97,"id":40096581}]}]}
{"op":"mcm","clk":"11816247075","pt":1722809574677,"mc":[{"id":"1.231398046","rc":[{"batb":[[0,2.14,88],[1,2.08,41.06],[2,1.9,259.67]],"ltp":2.14,"tv":907.97,"id":40096581}]}]}
{"op":"mcm","clk":"11816248205","pt":1722809592081,"mc":[{"id":"1.231398046","rc":[{"batb":[[0,2.18,10],[1,2.16,7.9],[2,2.14,88]],"ltp":2.14,"tv":907.97,"id":40096581}]}]}
{"op":"mcm","clk":"11816248320","pt":1722809593783,"mc":[{"id":"1.231398046","rc":[{"batb":[[1,2.14,88],[2,2.08,41.06]],"ltp":2.14,"tv":907.97,"id":40096581}]}]}
{"op":"mcm","clk":"11816248420","pt":1722809595607,"mc":[{"id":"1.231398046","rc":[{"batb":[[0,2.14,88],[1,2.08,41.06],[2,1.9,259.67]],"ltp":2.14,"tv":907.97,"id":40096581}]}]}
{"op":"mcm","clk":"11816250502","pt":1722809633412,"mc":[{"id":"1.231398046","rc":[{"batb":[[0,2.18,10],[1,2.16,7.9],[2,2.14,88]],"ltp":2.14,"tv":907.97,"id":40096581}]}]}
{"op":"mcm","clk":"11816250565","pt":1722809634920,"mc":[{"id":"1.231398046","rc":[{"batb":[[1,2.14,88],[2,2.08,41.06]],"ltp":2.14,"tv":907.97,"id":40096581}]}]}
{"op":"mcm","clk":"11816250645","pt":1722809636834,"mc":[{"id":"1.231398046","rc":[{"batb":[[0,2.14,88],[1,2.08,41.06],[2,1.9,259.67]],"ltp":2.14,"tv":907.97,"id":40096581}]}]}
{"op":"mcm","clk":"11816251236","pt":1722809650474,"mc":[{"id":"1.231398046","rc":[{"batb":[[0,2.16,5.17],[1,2.14,88],[2,2.08,41.06]],"ltp":2.14,"tv":907.97,"id":40096581}]}]}
{"op":"mcm","clk":"11816251243","pt":1722809650576,"mc":[{"id":"1.231398046","rc":[{"batb":[[0,2.18,10],[1,2.16,5.17],[2,2.14,88]],"ltp":2.14,"tv":907.97,"id":40096581}]}]}
{"op":"mcm","clk":"11816251318","pt":1722809651766,"mc":[{"id":"1.231398046","rc":[{"batb":[[1,2.14,88],[2,2.08,41.06]],"ltp":2.14,"tv":907.97,"id":40096581}]}]}
{"op":"mcm","clk":"11816251450","pt":1722809653986,"mc":[{"id":"1.231398046","rc":[{"batb":[[0,2.14,88],[1,2.08,41.06],[2,1.9,259.67]],"ltp":2.14,"tv":907.97,"id":40096581}]}]}
{"op":"mcm","clk":"11816252238","pt":1722809672496,"mc":[{"id":"1.231398046","rc":[{"batl":[[2,1.9,923.82]],"ltp":1.82,"tv":1148.28,"id":40096579}]}]}
{"op":"mcm","clk":"11816252244","pt":1722809672599,"mc":[{"id":"1.231398046","rc":[{"batb":[[0,2.16,10],[1,2.14,88],[2,2.08,41.06]],"ltp":2.14,"tv":907.97,"id":40096581}]}]}
{"op":"mcm","clk":"11816252307","pt":1722809674405,"mc":[{"id":"1.231398046","rc":[{"batb":[[0,2.16,17.9]],"ltp":2.14,"tv":907.97,"id":40096581}]}]}
{"op":"mcm","clk":"11816252354","pt":1722809675907,"mc":[{"id":"1.231398046","rc":[{"batb":[[0,2.16,7.9]],"ltp":2.14,"tv":907.97,"id":40096581}]}]}
{"op":"mcm","clk":"11816252459","pt":1722809679511,"mc":[{"id":"1.231398046","rc":[{"batb":[[0,2.18,10]],"ltp":2.14,"tv":907.97,"id":40096581}]}]}
{"op":"mcm","clk":"11816252576","pt":1722809682101,"mc":[{"id":"1.231398046","rc":[{"batb":[[0,2.14,88],[1,2.08,41.06],[2,1.9,259.67]],"ltp":2.14,"tv":907.97,"id":40096581}]}]}
{"op":"mcm","clk":"11816252813","pt":1722809688999,"mc":[{"id":"1.231398046","rc":[{"batb":[[0,2.16,10],[1,2.14,88],[2,2.08,41.06]],"ltp":2.14,"tv":907.97,"id":40096581}]}]}
{"op":"mcm","clk":"11816252969","pt":1722809692412,"mc":[{"id":"1.231398046","rc":[{"batb":[[0,2.14,88],[1,2.08,41.06],[2,1.9,259.67]],"ltp":2.14,"tv":907.97,"id":40096581}]}]}
{"op":"mcm","clk":"11816253098","pt":1722809695305,"mc":[{"id":"1.231398046","rc":[{"batb":[[0,2.16,10],[1,2.14,88],[2,2.08,41.06]],"ltp":2.14,"tv":907.97,"id":40096581}]}]}
{"op":"mcm","clk":"11816253241","pt":1722809698612,"mc":[{"id":"1.231398046","rc":[{"batb":[[0,2.14,88],[1,2.08,41.06],[2,1.9,259.67]],"ltp":2.14,"tv":907.97,"id":40096581}]}]}
{"op":"mcm","clk":"11816253843","pt":1722809713842,"mc":[{"id":"1.231398046","rc":[{"trd":[[2.14,90]],"batb":[[0,2.16,10],[1,2.14,68],[2,2.08,41.06]],"ltp":2.14,"tv":947.97,"id":40096581}],"tv":2096.25}]}
{"op":"mcm","clk":"11816253971","pt":1722809717446,"mc":[{"id":"1.231398046","rc":[{"batb":[[0,2.16,6.4]],"ltp":2.14,"tv":947.97,"id":40096581}]}]}
{"op":"mcm","clk":"11816254398","pt":1722809726727,"mc":[{"id":"1.231398046","rc":[{"batb":[[0,2.18,10],[1,2.16,10.9],[2,2.14,68]],"ltp":2.14,"tv":947.97,"id":40096581}]}]}
{"op":"mcm","clk":"11816254545","pt":1722809730140,"mc":[{"id":"1.231398046","rc":[{"batb":[[0,2.16,10.9],[1,2.14,68],[2,2.08,41.06]],"ltp":2.14,"tv":947.97,"id":40096581}]}]}
{"op":"mcm","clk":"11816255282","pt":1722809747264,"mc":[{"id":"1.231398046","rc":[{"batb":[[0,2.18,10],[1,2.16,10.9],[2,2.14,68]],"ltp":2.14,"tv":947.97,"id":40096581}]}]}
{"op":"mcm","clk":"11816255526","pt":1722809750776,"mc":[{"id":"1.231398046","rc":[{"batb":[[0,2.16,10.9],[1,2.14,68],[2,2.08,41.06]],"ltp":2.14,"tv":947.97,"id":40096581}]}]}
{"op":"mcm","clk":"11816255852","pt":1722809758206,"mc":[{"id":"1.231398046","rc":[{"batb":[[0,2.18,10],[1,2.16,10.9],[2,2.14,68]],"ltp":2.14,"tv":947.97,"id":40096581}]}]}
{"op":"mcm","clk":"11816256033","pt":1722809761606,"mc":[{"id":"1.231398046","rc":[{"batb":[[0,2.16,10.9],[1,2.14,68],[2,2.08,41.06]],"ltp":2.14,"tv":947.97,"id":40096581}]}]}
{"op":"mcm","clk":"11816256702","pt":1722809774631,"mc":[{"id":"1.231398046","rc":[{"batb":[[0,2.18,10],[1,2.16,10.9],[2,2.14,68]],"ltp":2.14,"tv":947.97,"id":40096581}]}]}
{"op":"mcm","clk":"11816256866","pt":1722809778100,"mc":[{"id":"1.231398046","rc":[{"batb":[[0,2.16,10.9],[1,2.14,68],[2,2.08,41.06]],"ltp":2.14,"tv":947.97,"id":40096581}]}]}
{"op":"mcm","clk":"11816257207","pt":1722809785333,"mc":[{"id":"1.231398046","rc":[{"batb":[[0,2.18,10],[1,2.16,10.9],[2,2.14,68]],"ltp":2.14,"tv":947.97,"id":40096581}]}]}
{"op":"mcm","clk":"11816257374","pt":1722809788636,"mc":[{"id":"1.231398046","rc":[{"batb":[[0,2.16,10.9],[1,2.14,68],[2,2.08,41.06]],"ltp":2.14,"tv":947.97,"id":40096581}]}]}
{"op":"mcm","clk":"11816257510","pt":1722809791633,"mc":[{"id":"1.231398046","rc":[{"batb":[[0,2.18,10],[1,2.16,10.9],[2,2.14,68]],"ltp":2.14,"tv":947.97,"id":40096581}]}]}
{"op":"mcm","clk":"11816257682","pt":1722809794941,"mc":[{"id":"1.231398046","rc":[{"batb":[[0,2.16,10.9],[1,2.14,68],[2,2.08,41.06]],"ltp":2.14,"tv":947.97,"id":40096581}]}]}
{"op":"mcm","clk":"11816257974","pt":1722809800050,"mc":[{"id":"1.231398046","rc":[{"batb":[[0,2.18,10],[1,2.16,10.9],[2,2.14,68]],"ltp":2.14,"tv":947.97,"id":40096581}]}]}
{"op":"mcm","clk":"11816258157","pt":1722809803549,"mc":[{"id":"1.231398046","rc":[{"batb":[[0,2.16,10.9],[1,2.14,68],[2,2.08,41.06]],"ltp":2.14,"tv":947.97,"id":40096581}]}]}
{"op":"mcm","clk":"11816258369","pt":1722809807628,"mc":[{"id":"1.231398046","rc":[{"batb":[[0,2.18,10],[1,2.16,10.9],[2,2.14,68]],"ltp":2.14,"tv":947.97,"id":40096581}]}]}
{"op":"mcm","clk":"11816258549","pt":1722809811141,"mc":[{"id":"1.231398046","rc":[{"batb":[[0,2.16,10.9],[1,2.14,68],[2,2.08,41.06]],"ltp":2.14,"tv":947.97,"id":40096581}]}]}
{"op":"mcm","clk":"11816258665","pt":1722809813480,"mc":[{"id":"1.231398046","rc":[{"batb":[[0,2.18,10],[1,2.16,10.9],[2,2.14,68]],"ltp":2.14,"tv":947.97,"id":40096581}]}]}
{"op":"mcm","clk":"11816258852","pt":1722809816852,"mc":[{"id":"1.231398046","rc":[{"batb":[[0,2.16,10.9],[1,2.14,68],[2,2.08,41.06]],"ltp":2.14,"tv":947.97,"id":40096581}]}]}
{"op":"mcm","clk":"11816259853","pt":1722809835605,"mc":[{"id":"1.231398046","rc":[{"batb":[[0,2.18,10],[1,2.16,10.9],[2,2.14,68]],"ltp":2.14,"tv":947.97,"id":40096581}]}]}
{"op":"mcm","clk":"11816260030","pt":1722809838978,"mc":[{"id":"1.231398046","rc":[{"batb":[[0,2.16,10.9],[1,2.14,68],[2,2.08,41.06]],"ltp":2.14,"tv":947.97,"id":40096581}]}]}
{"op":"mcm","clk":"11816260183","pt":1722809842097,"mc":[{"id":"1.231398046","rc":[{"batb":[[0,2.18,10],[1,2.16,10.9],[2,2.14,68]],"ltp":2.14,"tv":947.97,"id":40096581}]}]}
{"op":"mcm","clk":"11816260352","pt":1722809845516,"mc":[{"id":"1.231398046","rc":[{"batb":[[0,2.16,10.9],[1,2.14,68],[2,2.08,41.06]],"ltp":2.14,"tv":947.97,"id":40096581}]}]}
{"op":"mcm","clk":"11816260652","pt":1722809851206,"mc":[{"id":"1.231398046","rc":[{"batb":[[0,2.18,10],[1,2.16,10.9],[2,2.14,68]],"ltp":2.14,"tv":947.97,"id":40096581}]}]}
{"op":"mcm","clk":"11816260839","pt":1722809854621,"mc":[{"id":"1.231398046","rc":[{"batb":[[0,2.16,10.9],[1,2.14,68],[2,2.08,41.06]],"ltp":2.14,"tv":947.97,"id":40096581}]}]}
{"op":"mcm","clk":"11816261157","pt":1722809860829,"mc":[{"id":"1.231398046","rc":[{"batb":[[0,2.18,10],[1,2.16,10.9],[2,2.14,68]],"ltp":2.14,"tv":947.97,"id":40096581}]}]}
{"op":"mcm","clk":"11816261321","pt":1722809864131,"mc":[{"id":"1.231398046","rc":[{"batb":[[0,2.16,10.9],[1,2.14,68],[2,2.08,41.06]],"ltp":2.14,"tv":947.97,"id":40096581}]}]}
{"op":"mcm","clk":"11816261902","pt":1722809876271,"mc":[{"id":"1.231398046","rc":[{"batb":[[0,2.18,10],[1,2.16,10.9],[2,2.14,68]],"ltp":2.14,"tv":947.97,"id":40096581}]}]}
{"op":"mcm","clk":"11816262088","pt":1722809879684,"mc":[{"id":"1.231398046","rc":[{"batb":[[0,2.16,10.9],[1,2.14,68],[2,2.08,41.06]],"ltp":2.14,"tv":947.97,"id":40096581}]}]}
{"op":"mcm","clk":"11816262819","pt":1722809894888,"mc":[{"id":"1.231398046","rc":[{"batb":[[0,2.18,10],[1,2.16,10.9],[2,2.14,68]],"ltp":2.14,"tv":947.97,"id":40096581}]}]}
{"op":"mcm","clk":"11816263007","pt":1722809898396,"mc":[{"id":"1.231398046","rc":[{"batb":[[0,2.16,10.9],[1,2.14,68],[2,2.08,41.06]],"ltp":2.14,"tv":947.97,"id":40096581}]}]}
{"op":"mcm","clk":"11816263429","pt":1722809907501,"mc":[{"id":"1.231398046","rc":[{"batb":[[0,2.18,10],[1,2.16,10.9],[2,2.14,68]],"ltp":2.14,"tv":947.97,"id":40096581}]}]}
{"op":"mcm","clk":"11816263695","pt":1722809912729,"mc":[{"id":"1.231398046","rc":[{"batb":[[0,2.16,10.9],[1,2.14,68],[2,2.08,41.06]],"ltp":2.14,"tv":947.97,"id":40096581}]}]}
{"op":"mcm","clk":"11816272287","pt":1722810108990,"mc":[{"id":"1.231398046","rc":[{"batb":[[0,2.18,10],[1,2.16,10.9],[2,2.14,68]],"ltp":2.14,"tv":947.97,"id":40096581}]}]}
{"op":"mcm","clk":"11816272427","pt":1722810112400,"mc":[{"id":"1.231398046","rc":[{"batb":[[0,2.16,10.9],[1,2.14,68],[2,2.08,41.06]],"ltp":2.14,"tv":947.97,"id":40096581}]}]}
{"op":"mcm","clk":"11816274580","pt":1722810164164,"mc":[{"id":"1.231398046","rc":[{"batb":[[0,2.18,10],[1,2.16,10.9],[2,2.14,68]],"ltp":2.14,"tv":947.97,"id":40096581}]}]}
{"op":"mcm","clk":"11816274783","pt":1722810167673,"mc":[{"id":"1.231398046","rc":[{"batb":[[0,2.16,10.9],[1,2.14,68],[2,2.08,41.06]],"ltp":2.14,"tv":947.97,"id":40096581}]}]}
{"op":"mcm","clk":"11816275185","pt":1722810176385,"mc":[{"id":"1.231398046","rc":[{"batb":[[0,2.18,10],[1,2.16,10.9],[2,2.14,68]],"ltp":2.14,"tv":947.97,"id":40096581}]}]}
{"op":"mcm","clk":"11816275312","pt":1722810179776,"mc":[{"id":"1.231398046","rc":[{"batb":[[0,2.16,10.9],[1,2.14,68],[2,2.08,41.06]],"ltp":2.14,"tv":947.97,"id":40096581}]}]}
{"op":"mcm","clk":"11816277498","pt":1722810227562,"mc":[{"id":"1.231398046","rc":[{"batb":[[0,2.18,10],[1,2.16,10.9],[2,2.14,68]],"ltp":2.14,"tv":947.97,"id":40096581}]}]}
{"op":"mcm","clk":"11816277660","pt":1722810230970,"mc":[{"id":"1.231398046","rc":[{"batb":[[0,2.16,10.9],[1,2.14,68],[2,2.08,41.06]],"ltp":2.14,"tv":947.97,"id":40096581}]}]}
{"op":"mcm","clk":"11816278313","pt":1722810243895,"mc":[{"id":"1.231398046","rc":[{"batb":[[0,2.18,10],[1,2.16,10.9],[2,2.14,68]],"ltp":2.14,"tv":947.97,"id":40096581}]}]}
{"op":"mcm","clk":"11816278472","pt":1722810247201,"mc":[{"id":"1.231398046","rc":[{"batb":[[0,2.16,10.9],[1,2.14,68],[2,2.08,41.06]],"ltp":2.14,"tv":947.97,"id":40096581}]}]}
{"op":"mcm","clk":"11816278588","pt":1722810249991,"mc":[{"id":"1.231398046","rc":[{"batb":[[0,2.18,10],[1,2.16,10.9],[2,2.14,68]],"ltp":2.14,"tv":947.97,"id":40096581}]}]}
{"op":"mcm","clk":"11816278747","pt":1722810253605,"mc":[{"id":"1.231398046","rc":[{"batb":[[0,2.16,10.9],[1,2.14,68],[2,2.08,41.06]],"ltp":2.14,"tv":947.97,"id":40096581}]}]}
{"op":"mcm","clk":"11816278960","pt":1722810258913,"mc":[{"id":"1.231398046","rc":[{"batb":[[0,2.18,10],[1,2.16,10.9],[2,2.14,68]],"ltp":2.14,"tv":947.97,"id":40096581}]}]}
{"op":"mcm","clk":"11816279100","pt":1722810262412,"mc":[{"id":"1.231398046","rc":[{"batb":[[0,2.16,10.9],[1,2.14,68],[2,2.08,41.06]],"ltp":2.14,"tv":947.97,"id":40096581}]}]}
{"op":"mcm","clk":"11816279472","pt":1722810271130,"mc":[{"id":"1.231398046","rc":[{"batb":[[0,2.18,10],[1,2.16,10.9],[2,2.14,68]],"ltp":2.14,"tv":947.97,"id":40096581}]}]}
{"op":"mcm","clk":"11816279652","pt":1722810274641,"mc":[{"id":"1.231398046","rc":[{"batb":[[0,2.16,10.9],[1,2.14,68],[2,2.08,41.06]],"ltp":2.14,"tv":947.97,"id":40096581}]}]}
{"op":"mcm","clk":"11816279917","pt":1722810280533,"mc":[{"id":"1.231398046","rc":[{"batb":[[0,2.18,10],[1,2.16,10.9],[2,2.14,68]],"ltp":2.14,"tv":947.97,"id":40096581}]}]}
{"op":"mcm","clk":"11816280079","pt":1722810284128,"mc":[{"id":"1.231398046","rc":[{"batb":[[0,2.16,10.9],[1,2.14,68],[2,2.08,41.06]],"ltp":2.14,"tv":947.97,"id":40096581}]}]}
{"op":"mcm","clk":"11816280324","pt":1722810289534,"mc":[{"id":"1.231398046","rc":[{"batb":[[0,2.18,10],[1,2.16,10.9],[2,2.14,68]],"ltp":2.14,"tv":947.97,"id":40096581}]}]}
{"op":"mcm","clk":"11816280486","pt":1722810292934,"mc":[{"id":"1.231398046","rc":[{"batb":[[0,2.16,10.9],[1,2.14,68],[2,2.08,41.06]],"ltp":2.14,"tv":947.97,"id":40096581}]}]}
{"op":"mcm","clk":"11816281002","pt":1722810304757,"mc":[{"id":"1.231398046","rc":[{"batb":[[0,2.18,10],[1,2.16,10.9],[2,2.14,68]],"ltp":2.14,"tv":947.97,"id":40096581}]}]}
{"op":"mcm","clk":"11816281143","pt":1722810308271,"mc":[{"id":"1.231398046","rc":[{"batb":[[0,2.16,10.9],[1,2.14,68],[2,2.08,41.06]],"ltp":2.14,"tv":947.97,"id":40096581}]}]}
{"op":"mcm","clk":"11816281745","pt":1722810323268,"mc":[{"id":"1.231398046","rc":[{"batb":[[0,2.18,10],[1,2.16,10.9],[2,2.14,68]],"ltp":2.14,"tv":947.97,"id":40096581}]}]}
{"op":"mcm","clk":"11816281920","pt":1722810326668,"mc":[{"id":"1.231398046","rc":[{"batb":[[0,2.16,10.9],[1,2.14,68],[2,2.08,41.06]],"ltp":2.14,"tv":947.97,"id":40096581}]}]}
{"op":"mcm","clk":"11816282160","pt":1722810332964,"mc":[{"id":"1.231398046","rc":[{"batb":[[0,2.18,10],[1,2.16,10.9],[2,2.14,68]],"ltp":2.14,"tv":947.97,"id":40096581}]}]}
{"op":"mcm","clk":"11816282301","pt":1722810336309,"mc":[{"id":"1.231398046","rc":[{"batb":[[0,2.16,10.9],[1,2.14,68],[2,2.08,41.06]],"ltp":2.14,"tv":947.97,"id":40096581}]}]}
{"op":"mcm","clk":"11816283155","pt":1722810355494,"mc":[{"id":"1.231398046","rc":[{"batb":[[0,2.18,10],[1,2.16,10.9],[2,2.14,68]],"ltp":2.14,"tv":947.97,"id":40096581}]}]}
{"op":"mcm","clk":"11816283282","pt":1722810358702,"mc":[{"id":"1.231398046","rc":[{"batb":[[0,2.16,10.9],[1,2.14,68],[2,2.08,41.06]],"ltp":2.14,"tv":947.97,"id":40096581}]}]}
{"op":"mcm","clk":"11816283428","pt":1722810361503,"mc":[{"id":"1.231398046","rc":[{"batb":[[0,2.18,10],[1,2.16,10.9],[2,2.14,68]],"ltp":2.14,"tv":947.97,"id":40096581}]}]}
{"op":"mcm","clk":"11816283606","pt":1722810364806,"mc":[{"id":"1.231398046","rc":[{"batb":[[0,2.16,10.9],[1,2.14,68],[2,2.08,41.06]],"ltp":2.14,"tv":947.97,"id":40096581}]}]}
{"op":"mcm","clk":"11816283752","pt":1722810367835,"mc":[{"id":"1.231398046","rc":[{"batb":[[0,2.18,10],[1,2.16,10.9],[2,2.14,68]],"ltp":2.14,"tv":947.97,"id":40096581}]}]}
{"op":"mcm","clk":"11816283922","pt":1722810371332,"mc":[{"id":"1.231398046","rc":[{"batb":[[0,2.16,10.9],[1,2.14,68],[2,2.08,41.06]],"ltp":2.14,"tv":947.97,"id":40096581}]}]}
{"op":"mcm","clk":"11816284042","pt":1722810373957,"mc":[{"id":"1.231398046","rc":[{"batb":[[0,2.18,10],[1,2.16,10.9],[2,2.14,68]],"ltp":2.14,"tv":947.97,"id":40096581}]}]}
{"op":"mcm","clk":"11816284198","pt":1722810377451,"mc":[{"id":"1.231398046","rc":[{"batb":[[0,2.16,10.9],[1,2.14,68],[2,2.08,41.06]],"ltp":2.14,"tv":947.97,"id":40096581}]}]}
{"op":"mcm","clk":"11816284660","pt":1722810385762,"mc":[{"id":"1.231398046","rc":[{"batb":[[0,2.18,10],[1,2.16,10.9],[2,2.14,68]],"ltp":2.14,"tv":947.97,"id":40096581}]}]}
{"op":"mcm","clk":"11816284819","pt":1722810389158,"mc":[{"id":"1.231398046","rc":[{"batb":[[0,2.16,10.9],[1,2.14,68],[2,2.08,41.06]],"ltp":2.14,"tv":947.97,"id":40096581}]}]}
{"op":"mcm","clk":"11816285117","pt":1722810395172,"mc":[{"id":"1.231398046","rc":[{"batb":[[0,2.18,10],[1,2.16,10.9],[2,2.14,68]],"ltp":2.14,"tv":947.97,"id":40096581}]}]}
{"op":"mcm","clk":"11816285294","pt":1722810398469,"mc":[{"id":"1.231398046","rc":[{"batb":[[0,2.16,10.9],[1,2.14,68],[2,2.08,41.06]],"ltp":2.14,"tv":947.97,"id":40096581}]}]}
{"op":"mcm","clk":"11816285708","pt":1722810406858,"mc":[{"id":"1.231398046","rc":[{"batb":[[0,2.18,10],[1,2.16,10.9],[2,2.14,68]],"ltp":2.14,"tv":947.97,"id":40096581}]}]}
{"op":"mcm","clk":"11816285919","pt":1722810410091,"mc":[{"id":"1.231398046","rc":[{"batb":[[0,2.16,10.9],[1,2.14,68],[2,2.08,41.06]],"ltp":2.14,"tv":947.97,"id":40096581}]}]}
{"op":"mcm","clk":"11816286123","pt":1722810414321,"mc":[{"id":"1.231398046","rc":[{"batb":[[0,2.18,10],[1,2.16,10.9],[2,2.14,68]],"ltp":2.14,"tv":947.97,"id":40096581}]}]}
{"op":"mcm","clk":"11816286286","pt":1722810417774,"mc":[{"id":"1.231398046","rc":[{"batb":[[0,2.16,10.9],[1,2.14,68],[2,2.08,41.06]],"ltp":2.14,"tv":947.97,"id":40096581}]}]}
{"op":"mcm","clk":"11816286375","pt":1722810419978,"mc":[{"id":"1.231398046","rc":[{"batb":[[0,2.18,10],[1,2.16,10.9],[2,2.14,68]],"ltp":2.14,"tv":947.97,"id":40096581}]}]}
{"op":"mcm","clk":"11816286547","pt":1722810423391,"mc":[{"id":"1.231398046","rc":[{"batb":[[0,2.16,10.9],[1,2.14,68],[2,2.08,41.06]],"ltp":2.14,"tv":947.97,"id":40096581}]}]}
{"op":"mcm","clk":"11816286681","pt":1722810425703,"mc":[{"id":"1.231398046","rc":[{"batb":[[0,2.18,10],[1,2.16,10.9],[2,2.14,68]],"ltp":2.14,"tv":947.97,"id":40096581}]}]}
{"op":"mcm","clk":"11816286855","pt":1722810428997,"mc":[{"id":"1.231398046","rc":[{"batb":[[0,2.16,10.9],[1,2.14,68],[2,2.08,41.06]],"ltp":2.14,"tv":947.97,"id":40096581}]}]}
{"op":"mcm","clk":"11816286982","pt":1722810431823,"mc":[{"id":"1.231398046","rc":[{"batb":[[0,2.18,10],[1,2.16,10.9],[2,2.14,68]],"ltp":2.14,"tv":947.97,"id":40096581}]}]}
{"op":"mcm","clk":"11816287145","pt":1722810435117,"mc":[{"id":"1.231398046","rc":[{"batb":[[0,2.16,10.9],[1,2.14,68],[2,2.08,41.06]],"ltp":2.14,"tv":947.97,"id":40096581}]}]}
{"op":"mcm","clk":"11816287794","pt":1722810447833,"mc":[{"id":"1.231398046","rc":[{"batb":[[0,2.18,10],[1,2.16,10.9],[2,2.14,68]],"ltp":2.14,"tv":947.97,"id":40096581}]}]}
{"op":"mcm","clk":"11816287947","pt":1722810451229,"mc":[{"id":"1.231398046","rc":[{"batb":[[0,2.16,10.9],[1,2.14,68],[2,2.08,41.06]],"ltp":2.14,"tv":947.97,"id":40096581}]}]}
{"op":"mcm","clk":"11816288269","pt":1722810457150,"mc":[{"id":"1.231398046","rc":[{"batb":[[0,2.18,10],[1,2.16,10.9],[2,2.14,68]],"ltp":2.14,"tv":947.97,"id":40096581}]}]}
{"op":"mcm","clk":"11816288423","pt":1722810460549,"mc":[{"id":"1.231398046","rc":[{"batb":[[0,2.16,10.9],[1,2.14,68],[2,2.08,41.06]],"ltp":2.14,"tv":947.97,"id":40096581}]}]}
{"op":"mcm","clk":"11816288899","pt":1722810470840,"mc":[{"id":"1.231398046","rc":[{"batb":[[0,2.18,10],[1,2.16,10.9],[2,2.14,68]],"ltp":2.14,"tv":947.97,"id":40096581}]}]}
{"op":"mcm","clk":"11816289068","pt":1722810474240,"mc":[{"id":"1.231398046","rc":[{"batb":[[0,2.16,10.9],[1,2.14,68],[2,2.08,41.06]],"ltp":2.14,"tv":947.97,"id":40096581}]}]}
{"op":"mcm","clk":"11816289771","pt":1722810489004,"mc":[{"id":"1.231398046","rc":[{"batb":[[0,2.18,10],[1,2.16,10.9],[2,2.14,68]],"ltp":2.14,"tv":947.97,"id":40096581}]}]}
{"op":"mcm","clk":"11816289932","pt":1722810492507,"mc":[{"id":"1.231398046","rc":[{"batb":[[0,2.16,10.9],[1,2.14,68],[2,2.08,41.06]],"ltp":2.14,"tv":947.97,"id":40096581}]}]}
{"op":"mcm","clk":"11816290118","pt":1722810495703,"mc":[{"id":"1.231398046","rc":[{"batb":[[0,2.18,10],[1,2.16,10.9],[2,2.14,68]],"ltp":2.14,"tv":947.97,"id":40096581}]}]}
{"op":"mcm","clk":"11816290319","pt":1722810499101,"mc":[{"id":"1.231398046","rc":[{"batb":[[0,2.16,10.9],[1,2.14,68],[2,2.08,41.06]],"ltp":2.14,"tv":947.97,"id":40096581}]}]}
{"op":"mcm","clk":"11816290441","pt":1722810501210,"mc":[{"id":"1.231398046","rc":[{"batb":[[0,2.18,10],[1,2.16,10.9],[2,2.14,68]],"ltp":2.14,"tv":947.97,"id":40096581}]}]}
{"op":"mcm","clk":"11816290625","pt":1722810504614,"mc":[{"id":"1.231398046","rc":[{"batb":[[0,2.16,10.9],[1,2.14,68],[2,2.08,41.06]],"ltp":2.14,"tv":947.97,"id":40096581}]}]}
{"op":"mcm","clk":"11816291070","pt":1722810513998,"mc":[{"id":"1.231398046","rc":[{"batb":[[0,2.18,10],[1,2.16,10.9],[2,2.14,68]],"ltp":2.14,"tv":947.97,"id":40096581}]}]}
{"op":"mcm","clk":"11816291231","pt":1722810517447,"mc":[{"id":"1.231398046","rc":[{"batb":[[0,2.16,10.9],[1,2.14,68],[2,2.08,41.06]],"ltp":2.14,"tv":947.97,"id":40096581}]}]}
{"op":"mcm","clk":"11816291795","pt":1722810529040,"mc":[{"id":"1.231398046","rc":[{"batb":[[0,2.18,10],[1,2.16,10.9],[2,2.14,68]],"ltp":2.14,"tv":947.97,"id":40096581}]}]}
{"op":"mcm","clk":"11816291993","pt":1722810532546,"mc":[{"id":"1.231398046","rc":[{"batb":[[0,2.16,10.9],[1,2.14,68],[2,2.08,41.06]],"ltp":2.14,"tv":947.97,"id":40096581}]}]}
{"op":"mcm","clk":"11816292184","pt":1722810537178,"mc":[{"id":"1.231398046","rc":[{"batb":[[0,2.18,10],[1,2.16,10.9],[2,2.14,68]],"ltp":2.14,"tv":947.97,"id":40096581}]}]}
{"op":"mcm","clk":"11816292340","pt":1722810540574,"mc":[{"id":"1.231398046","rc":[{"batb":[[0,2.16,10.9],[1,2.14,68],[2,2.08,41.06]],"ltp":2.14,"tv":947.97,"id":40096581}]}]}
{"op":"mcm","clk":"11816293391","pt":1722810561691,"mc":[{"id":"1.231398046","rc":[{"batb":[[0,2.18,10],[1,2.16,10.9],[2,2.14,68]],"ltp":2.14,"tv":947.97,"id":40096581}]}]}
{"op":"mcm","clk":"11816293561","pt":1722810565105,"mc":[{"id":"1.231398046","rc":[{"batb":[[0,2.16,10.9],[1,2.14,68],[2,2.08,41.06]],"ltp":2.14,"tv":947.97,"id":40096581}]}]}
{"op":"mcm","clk":"11816294008","pt":1722810573081,"mc":[{"id":"1.231398046","rc":[{"batb":[[0,2.18,10],[1,2.16,10.9],[2,2.14,68]],"ltp":2.14,"tv":947.97,"id":40096581}]}]}
{"op":"mcm","clk":"11816294187","pt":1722810576597,"mc":[{"id":"1.231398046","rc":[{"batb":[[0,2.16,10.9],[1,2.14,68],[2,2.08,41.06]],"ltp":2.14,"tv":947.97,"id":40096581}]}]}
{"op":"mcm","clk":"11816294695","pt":1722810587482,"mc":[{"id":"1.231398046","rc":[{"batb":[[0,2.18,10],[1,2.16,10.9],[2,2.14,68]],"ltp":2.14,"tv":947.97,"id":40096581}]}]}
{"op":"mcm","clk":"11816294874","pt":1722810590989,"mc":[{"id":"1.231398046","rc":[{"batb":[[0,2.16,10.9],[1,2.14,68],[2,2.08,41.06]],"ltp":2.14,"tv":947.97,"id":40096581}]}]}
{"op":"mcm","clk":"11816294992","pt":1722810593406,"mc":[{"id":"1.231398046","rc":[{"batb":[[0,2.18,10],[1,2.16,10.9],[2,2.14,68]],"ltp":2.14,"tv":947.97,"id":40096581}]}]}
{"op":"mcm","clk":"11816295158","pt":1722810596798,"mc":[{"id":"1.231398046","rc":[{"batb":[[0,2.16,10.9],[1,2.14,68],[2,2.08,41.06]],"ltp":2.14,"tv":947.97,"id":40096581}]}]}
{"op":"mcm","clk":"11816296380","pt":1722810620563,"mc":[{"id":"1.231398046","rc":[{"batb":[[0,2.18,10],[1,2.16,10.9],[2,2.14,68]],"ltp":2.14,"tv":947.97,"id":40096581}]}]}
{"op":"mcm","clk":"11816296550","pt":1722810623863,"mc":[{"id":"1.231398046","rc":[{"batb":[[0,2.16,10.9],[1,2.14,68],[2,2.08,41.06]],"ltp":2.14,"tv":947.97,"id":40096581}]}]}
{"op":"mcm","clk":"11816296800","pt":1722810628825,"mc":[{"id":"1.231398046","rc":[{"batb":[[0,2.18,10],[1,2.16,10.9],[2,2.14,68]],"ltp":2.14,"tv":947.97,"id":40096581}]}]}
{"op":"mcm","clk":"11816296969","pt":1722810632384,"mc":[{"id":"1.231398046","rc":[{"batb":[[0,2.16,10.9],[1,2.14,68],[2,2.08,41.06]],"ltp":2.14,"tv":947.97,"id":40096581}]}]}
{"op":"mcm","clk":"11816297858","pt":1722810652380,"mc":[{"id":"1.231398046","rc":[{"batb":[[0,2.18,10],[1,2.16,10.9],[2,2.14,68]],"ltp":2.14,"tv":947.97,"id":40096581}]}]}
{"op":"mcm","clk":"11816297985","pt":1722810655786,"mc":[{"id":"1.231398046","rc":[{"batb":[[0,2.16,10.9],[1,2.14,68],[2,2.08,41.06]],"ltp":2.14,"tv":947.97,"id":40096581}]}]}
{"op":"mcm","clk":"11816298867","pt":1722810677144,"mc":[{"id":"1.231398046","rc":[{"batl":[[1,1.9,125],[2,1.94,7.61]],"ltp":1.82,"tv":1148.28,"id":40096579},{"batb":[[0,2.18,10],[1,2.16,10.9],[2,2.14,68]],"ltp":2.14,"tv":947.97,"id":40096581}]}]}
{"op":"mcm","clk":"11816298921","pt":1722810678432,"mc":[{"id":"1.231398046","rc":[{"batb":[[1,2.14,68],[2,2.08,41.06]],"ltp":2.14,"tv":947.97,"id":40096581}]}]}
{"op":"mcm","clk":"11816299013","pt":1722810680342,"mc":[{"id":"1.231398046","rc":[{"batb":[[0,2.14,68],[1,2.08,41.06],[2,1.9,259.67]],"ltp":2.14,"tv":947.97,"id":40096581}]}]}
{"op":"mcm","clk":"11816299147","pt":1722810683123,"mc":[{"id":"1.231398046","rc":[{"batb":[[0,2.18,10],[1,2.16,6.4],[2,2.14,68]],"ltp":2.14,"tv":947.97,"id":40096581}]}]}
{"op":"mcm","clk":"11816299213","pt":1722810685024,"mc":[{"id":"1.231398046","rc":[{"batb":[[1,2.14,68],[2,2.08,41.06]],"ltp":2.14,"tv":947.97,"id":40096581}]}]}
{"op":"mcm","clk":"11816299265","pt":1722810686467,"mc":[{"id":"1.231398046","rc":[{"batb":[[0,2.14,68],[1,2.08,41.06],[2,1.9,259.67]],"ltp":2.14,"tv":947.97,"id":40096581}]}]}
{"op":"mcm","clk":"11816299710","pt":1722810697084,"mc":[{"id":"1.231398046","rc":[{"batb":[[0,2.16,10],[1,2.14,68],[2,2.08,41.06]],"ltp":2.14,"tv":947.97,"id":40096581}]}]}
{"op":"mcm","clk":"11816299821","pt":1722810700374,"mc":[{"id":"1.231398046","rc":[{"batb":[[0,2.14,68],[1,2.08,41.06],[2,1.9,259.67]],"ltp":2.14,"tv":947.97,"id":40096581}]}]}
{"op":"mcm","clk":"11816300530","pt":1722810710597,"mc":[{"id":"1.231398046","rc":[{"batb":[[0,2.16,10],[1,2.14,68],[2,2.08,41.06]],"ltp":2.14,"tv":947.97,"id":40096581}]}]}
{"op":"mcm","clk":"11816300783","pt":1722810713991,"mc":[{"id":"1.231398046","rc":[{"batb":[[0,2.14,68],[1,2.08,41.06],[2,1.9,259.67]],"ltp":2.14,"tv":947.97,"id":40096581}]}]}
{"op":"mcm","clk":"11816302018","pt":1722810725000,"mc":[{"id":"1.231398046","rc":[{"batb":[[0,2.18,10],[1,2.16,6.4],[2,2.14,68]],"ltp":2.14,"tv":947.97,"id":40096581}]}]}
{"op":"mcm","clk":"11816302117","pt":1722810727112,"mc":[{"id":"1.231398046","rc":[{"batb":[[1,2.14,68],[2,2.08,41.06]],"ltp":2.14,"tv":947.97,"id":40096581}]}]}
{"op":"mcm","clk":"11816302183","pt":1722810728501,"mc":[{"id":"1.231398046","rc":[{"batb":[[0,2.14,68],[1,2.08,41.06],[2,1.9,259.67]],"ltp":2.14,"tv":947.97,"id":40096581}]}]}
{"op":"mcm","clk":"11816302651","pt":1722810738536,"mc":[{"id":"1.231398046","rc":[{"batb":[[0,2.16,10],[1,2.14,68],[2,2.08,41.06]],"ltp":2.14,"tv":947.97,"id":40096581}]}]}
{"op":"mcm","clk":"11816302793","pt":1722810741829,"mc":[{"id":"1.231398046","rc":[{"batb":[[0,2.14,68],[1,2.08,41.06],[2,1.9,259.67]],"ltp":2.14,"tv":947.97,"id":40096581}]}]}
{"op":"mcm","clk":"11816303946","pt":1722810767046,"mc":[{"id":"1.231398046","rc":[{"batb":[[0,2.18,10],[1,2.16,6.4],[2,2.14,68]],"ltp":2.14,"tv":947.97,"id":40096581}]}]}
{"op":"mcm","clk":"11816304043","pt":1722810768652,"mc":[{"id":"1.231398046","rc":[{"batb":[[1,2.14,68],[2,2.08,41.06]],"ltp":2.14,"tv":947.97,"id":40096581}]}]}
{"op":"mcm","clk":"11816304127","pt":1722810770350,"mc":[{"id":"1.231398046","rc":[{"batb":[[0,2.14,68],[1,2.08,41.06],[2,1.9,259.67]],"ltp":2.14,"tv":947.97,"id":40096581}]}]}
{"op":"mcm","clk":"11816304889","pt":1722810786099,"mc":[{"id":"1.231398046","rc":[{"batb":[[0,2.16,10],[1,2.14,68],[2,2.08,41.06]],"ltp":2.14,"tv":947.97,"id":40096581}]}]}
{"op":"mcm","clk":"11816305066","pt":1722810789492,"mc":[{"id":"1.231398046","rc":[{"batb":[[0,2.14,68],[1,2.08,41.06],[2,1.9,259.67]],"ltp":2.14,"tv":947.97,"id":40096581}]}]}
{"op":"mcm","clk":"11816305252","pt":1722810792888,"mc":[{"id":"1.231398046","rc":[{"batb":[[0,2.16,10],[1,2.14,68],[2,2.08,41.06]],"ltp":2.14,"tv":947.97,"id":40096581}]}]}
{"op":"mcm","clk":"11816305410","pt":1722810796288,"mc":[{"id":"1.231398046","rc":[{"batb":[[0,2.14,68],[1,2.08,41.06],[2,1.9,259.67]],"ltp":2.14,"tv":947.97,"id":40096581}]}]}
{"op":"mcm","clk":"11816305512","pt":1722810798869,"mc":[{"id":"1.231398046","rc":[{"batb":[[0,2.16,10],[1,2.14,68],[2,2.08,41.06]],"ltp":2.14,"tv":947.97,"id":40096581}]}]}
{"op":"mcm","clk":"11816305644","pt":1722810802212,"mc":[{"id":"1.231398046","rc":[{"batb":[[0,2.14,68],[1,2.08,41.06],[2,1.9,259.67]],"ltp":2.14,"tv":947.97,"id":40096581}]}]}
{"op":"mcm","clk":"11816305935","pt":1722810808920,"mc":[{"id":"1.231398046","rc":[{"batb":[[0,2.18,10],[1,2.16,6.4],[2,2.14,68]],"ltp":2.14,"tv":947.97,"id":40096581}]}]}
{"op":"mcm","clk":"11816306011","pt":1722810810713,"mc":[{"id":"1.231398046","rc":[{"batb":[[1,2.14,68],[2,2.08,41.06]],"ltp":2.14,"tv":947.97,"id":40096581}]}]}
{"op":"mcm","clk":"11816306099","pt":1722810812110,"mc":[{"id":"1.231398046","rc":[{"batb":[[0,2.14,68],[1,2.08,41.06],[2,1.9,259.67]],"ltp":2.14,"tv":947.97,"id":40096581}]}]}
{"op":"mcm","clk":"11816306206","pt":1722810814427,"mc":[{"id":"1.231398046","rc":[{"batb":[[0,2.16,10],[1,2.14,68],[2,2.08,41.06]],"ltp":2.14,"tv":947.97,"id":40096581}]}]}
{"op":"mcm","clk":"11816306411","pt":1722810817823,"mc":[{"id":"1.231398046","rc":[{"batb":[[0,2.14,68],[1,2.08,41.06],[2,1.9,259.67]],"ltp":2.14,"tv":947.97,"id":40096581}]}]}
{"op":"mcm","clk":"11816306778","pt":1722810825134,"mc":[{"id":"1.231398046","rc":[{"batb":[[0,2.16,10],[1,2.14,68],[2,2.08,41.06]],"ltp":2.14,"tv":947.97,"id":40096581}]}]}
{"op":"mcm","clk":"11816306931","pt":1722810828627,"mc":[{"id":"1.231398046","rc":[{"batb":[[0,2.14,68],[1,2.08,41.06],[2,1.9,259.67]],"ltp":2.14,"tv":947.97,"id":40096581}]}]}
{"op":"mcm","clk":"11816307227","pt":1722810835059,"mc":[{"id":"1.231398046","rc":[{"batb":[[0,2.16,10],[1,2.14,68],[2,2.08,41.06]],"ltp":2.14,"tv":947.97,"id":40096581}]}]}
{"op":"mcm","clk":"11816307382","pt":1722810838361,"mc":[{"id":"1.231398046","rc":[{"batb":[[0,2.14,68],[1,2.08,41.06],[2,1.9,259.67]],"ltp":2.14,"tv":947.97,"id":40096581}]}]}
{"op":"mcm","clk":"11816307871","pt":1722810848654,"mc":[{"id":"1.231398046","rc":[{"batb":[[0,2.16,10],[1,2.14,68],[2,2.08,41.06]],"ltp":2.14,"tv":947.97,"id":40096581}]}]}
{"op":"mcm","clk":"11816308043","pt":1722810852053,"mc":[{"id":"1.231398046","rc":[{"batb":[[0,2.16,6.4]],"ltp":2.14,"tv":947.97,"id":40096581}]}]}
{"op":"mcm","clk":"11816308092","pt":1722810853087,"mc":[{"id":"1.231398046","rc":[{"batb":[[0,2.16,10.9]],"ltp":2.14,"tv":947.97,"id":40096581}]}]}
{"op":"mcm","clk":"11816308180","pt":1722810854377,"mc":[{"id":"1.231398046","rc":[{"batb":[[0,2.18,10],[1,2.16,6.4],[2,2.14,68]],"ltp":2.14,"tv":947.97,"id":40096581}]}]}
{"op":"mcm","clk":"11816308198","pt":1722810854788,"mc":[{"id":"1.231398046","rc":[{"batb":[[1,2.14,68],[2,2.08,41.06]],"ltp":2.14,"tv":947.97,"id":40096581}]}]}
{"op":"mcm","clk":"11816308351","pt":1722810857777,"mc":[{"id":"1.231398046","rc":[{"batb":[[0,2.14,68],[1,2.08,41.06],[2,1.9,259.67]],"ltp":2.14,"tv":947.97,"id":40096581}]}]}
{"op":"mcm","clk":"11816308543","pt":1722810861390,"mc":[{"id":"1.231398046","rc":[{"batb":[[0,2.16,10],[1,2.14,68],[2,2.08,41.06]],"ltp":2.14,"tv":947.97,"id":40096581}]}]}
{"op":"mcm","clk":"11816308729","pt":1722810864693,"mc":[{"id":"1.231398046","rc":[{"batb":[[0,2.14,68],[1,2.08,41.06],[2,1.9,259.67]],"ltp":2.14,"tv":947.97,"id":40096581}]}]}
{"op":"mcm","clk":"11816309829","pt":1722810886996,"mc":[{"id":"1.231398046","rc":[{"batb":[[0,2.16,10],[1,2.14,68],[2,2.08,41.06]],"ltp":2.14,"tv":947.97,"id":40096581}]}]}
{"op":"mcm","clk":"11816310042","pt":1722810890503,"mc":[{"id":"1.231398046","rc":[{"batb":[[0,2.14,68],[1,2.08,41.06],[2,1.9,259.67]],"ltp":2.14,"tv":947.97,"id":40096581}]}]}
{"op":"mcm","clk":"11816310215","pt":1722810893902,"mc":[{"id":"1.231398046","rc":[{"batb":[[0,2.18,10],[1,2.16,6.4],[2,2.14,68]],"ltp":2.14,"tv":947.97,"id":40096581}]}]}
{"op":"mcm","clk":"11816310312","pt":1722810895500,"mc":[{"id":"1.231398046","rc":[{"batb":[[1,2.14,68],[2,2.08,41.06]],"ltp":2.14,"tv":947.97,"id":40096581}]}]}
{"op":"mcm","clk":"11816310377","pt":1722810897095,"mc":[{"id":"1.231398046","rc":[{"batb":[[0,2.14,68],[1,2.08,41.06],[2,1.9,259.67]],"ltp":2.14,"tv":947.97,"id":40096581}]}]}
{"op":"mcm","clk":"11816312498","pt":1722810936370,"mc":[{"id":"1.231398046","rc":[{"batb":[[0,2.16,10],[1,2.14,68],[2,2.08,41.06]],"ltp":2.14,"tv":947.97,"id":40096581}]}]}
{"op":"mcm","clk":"11816312516","pt":1722810936679,"mc":[{"id":"1.231398046","rc":[{"batb":[[0,2.16,16.4]],"ltp":2.14,"tv":947.97,"id":40096581}]}]}
{"op":"mcm","clk":"11816312682","pt":1722810939757,"mc":[{"id":"1.231398046","rc":[{"batb":[[0,2.16,6.4]],"ltp":2.14,"tv":947.97,"id":40096581}]}]}
