{"op":"mcm","clk":"11941587873","pt":1724422713825,"mc":[{"id":"1.232199708","marketDefinition":{"bspMarket":false,"turnInPlayEnabled":true,"persistenceEnabled":true,"marketBaseRate":5.0,"eventId":"33521414","eventTypeId":"4","numberOfWinners":1,"bettingType":"ODDS","marketType":"MATCH_ODDS","marketTime":"2024-08-29T10:00:00.000Z","suspendTime":"2024-08-29T10:00:00.000Z","bspReconciled":false,"complete":true,"inPlay":false,"crossMatching":false,"runnersVoidable":false,"numberOfActiveRunners":3,"betDelay":0,"status":"OPEN","runners":[{"status":"ACTIVE","sortPriority":1,"id":424679,"name":"Lancashire"},{"status":"ACTIVE","sortPriority":2,"id":3961,"name":"Hampshire"},{"status":"ACTIVE","sortPriority":3,"id":60443,"name":"The Draw"}],"regulators":["MR_INT"],"countryCode":"GB","discountAllowed":false,"timezone":"GMT","openDate":"2024-08-29T10:00:00.000Z","version":6092309208,"name":"Match Odds","eventName":"Lancashire v Hampshire"},"rc":[{"batb":[[0,1.03,200],[1,1.02,200],[2,1.01,220]],"ltp":0.0,"tv":0.0,"id":424679},{"batb":[[0,1.03,200],[1,1.02,200],[2,1.01,220]],"ltp":0.0,"tv":0.0,"id":3961},{"batb":[[0,1.03,200],[1,1.02,200],[2,1.01,220]],"ltp":0.0,"tv":0.0,"id":60443}]}]}
{"op":"mcm","clk":"11941587935","pt":1724422714496,"mc":[{"id":"1.232199708","marketDefinition":{"bspMarket":false,"turnInPlayEnabled":true,"persistenceEnabled":true,"marketBaseRate":5.0,"eventId":"33521414","eventTypeId":"4","numberOfWinners":1,"bettingType":"ODDS","marketType":"MATCH_ODDS","marketTime":"2024-08-29T10:00:00.000Z","suspendTime":"2024-08-29T10:00:00.000Z","bspReconciled":false,"complete":true,"inPlay":false,"crossMatching":false,"runnersVoidable":false,"numberOfActiveRunners":3,"betDelay":0,"status":"OPEN","runners":[{"status":"ACTIVE","sortPriority":1,"id":424679,"name":"Lancashire"},{"status":"ACTIVE","sortPriority":2,"id":3961,"name":"Hampshire"},{"status":"ACTIVE","sortPriority":3,"id":60443,"name":"The Draw"}],"regulators":["MR_INT"],"countryCode":"GB","discountAllowed":true,"timezone":"GMT","openDate":"2024-08-29T10:00:00.000Z","version":6092309208,"name":"Match Odds","eventName":"Lancashire v Hampshire"}}]}
{"op":"mcm","clk":"11942077101","pt":1724428889110,"mc":[{"id":"1.232199708","rc":[{"batb":[[0,1.04,125],[1,1.03,200],[2,1.02,200]],"batl":[[0,95,2.5],[1,990,2.5]],"ltp":0.0,"tv":0.0,"id":424679},{"batb":[[0,1.04,125],[1,1.03,200],[2,1.02,200]],"batl":[[0,95,2.5],[1,990,2.5]],"ltp":0.0,"tv":0.0,"id":3961},{"batb":[[0,1.04,125],[1,1.03,200],[2,1.02,200]],"batl":[[0,95,2.5],[1,990,2.5]],"ltp":0.0,"tv":0.0,"id":60443}]}]}
{"op":"mcm","clk":"11943964256","pt":1724440216460,"mc":[{"id":"1.232199708","rc":[{"batb":[[0,1.04,126.53]],"ltp":0.0,"tv":0.0,"id":424679},{"batb":[[0,1.04,126.53]],"ltp":0.0,"tv":0.0,"id":3961},{"batb":[[0,1.04,126.53]],"ltp":0.0,"tv":0.0,"id":60443}]}]}
{"op":"mcm","clk":"11943970642","pt":1724440247812,"mc":[{"id":"1.232199708","marketDefinition":{"bspMarket":false,"turnInPlayEnabled":true,"persistenceEnabled":true,"marketBaseRate":5.0,"eventId":"33521414","eventTypeId":"4","numberOfWinners":1,"bettingType":"ODDS","marketType":"MATCH_ODDS","marketTime":"2024-08-29T10:00:00.000Z","suspendTime":"2024-08-29T10:00:00.000Z","bspReconciled":false,"complete":true,"inPlay":false,"crossMatching":true,"runnersVoidable":false,"numberOfActiveRunners":3,"betDelay":0,"status":"OPEN","runners":[{"status":"ACTIVE","sortPriority":1,"id":424679,"name":"Lancashire"},{"status":"ACTIVE","sortPriority":2,"id":3961,"name":"Hampshire"},{"status":"ACTIVE","sortPriority":3,"id":60443,"name":"The Draw"}],"regulators":["MR_INT"],"countryCode":"GB","discountAllowed":true,"timezone":"GMT","openDate":"2024-08-29T10:00:00.000Z","version":6092309208,"name":"Match Odds","eventName":"Lancashire v Hampshire"}}]}
{"op":"mcm","clk":"11956687681","pt":1724548211711,"mc":[{"id":"1.232199708","rc":[{"batb":[[0,1.04,127.41]],"ltp":0.0,"tv":0.0,"id":3961}]}]}
{"op":"mcm","clk":"11963607024","pt":1724603454720,"mc":[{"id":"1.232199708","rc":[{"batb":[[0,1.04,126.53]],"ltp":0.0,"tv":0.0,"id":3961}]}]}
{"op":"mcm","clk":"11965631597","pt":1724614629630,"mc":[{"id":"1.232199708","rc":[{"batb":[[0,1.05,40],[1,1.04,126.53],[2,1.03,200]],"ltp":0.0,"tv":0.0,"id":424679},{"batb":[[0,1.06,40],[1,1.04,126.53],[2,1.03,200]],"ltp":0.0,"tv":0.0,"id":3961},{"batb":[[0,1.06,40],[1,1.04,126.53],[2,1.03,200]],"ltp":0.0,"tv":0.0,"id":60443}]}]}
{"op":"mcm","clk":"11967317095","pt":1724647891656,"mc":[{"id":"1.232199708","rc":[{"batl":[[0,95,3.43]],"ltp":0.0,"tv":0.0,"id":60443}]}]}
{"op":"mcm","clk":"11967507217","pt":1724655297366,"mc":[{"id":"1.232199708","rc":[{"batb":[[0,1.1,40]],"ltp":0.0,"tv":0.0,"id":424679},{"batb":[[0,1.11,40]],"ltp":0.0,"tv":0.0,"id":3961},{"batb":[[0,1.1,40]],"ltp":0.0,"tv":0.0,"id":60443}]}]}
{"op":"mcm","clk":"11967540943","pt":1724656481848,"mc":[{"id":"1.232199708","rc":[{"batb":[[0,1.11,27.11],[1,1.1,40],[2,1.04,126.53]],"ltp":0.0,"tv":0.0,"id":424679},{"batb":[[0,1.12,27.11],[1,1.11,40],[2,1.04,126.53]],"ltp":0.0,"tv":0.0,"id":3961},{"batb":[[0,1.11,27.11],[1,1.1,40],[2,1.04,126.53]],"ltp":0.0,"tv":0.0,"id":60443}]}]}
{"op":"mcm","clk":"11967545838","pt":1724656627401,"mc":[{"id":"1.232199708","rc":[{"batl":[[0,95,2.67]],"ltp":0.0,"tv":0.0,"id":424679},{"batl":[[0,95,2.67]],"ltp":0.0,"tv":0.0,"id":3961},{"batl":[[0,90,1.1],[1,95,2.5],[2,990,2.5]],"ltp":0.0,"tv":0.0,"id":60443}]}]}
{"op":"mcm","clk":"11967546321","pt":1724656644947,"mc":[{"id":"1.232199708","rc":[{"batl":[[1,990,2.67]],"ltp":0.0,"tv":0.0,"id":424679},{"batl":[[1,990,2.67]],"ltp":0.0,"tv":0.0,"id":3961},{"batl":[[2,990,2.67]],"ltp":0.0,"tv":0.0,"id":60443}]}]}
{"op":"mcm","clk":"11967551262","pt":1724656785724,"mc":[{"id":"1.232199708","rc":[{"batl":[[1,990,2.84]],"ltp":0.0,"tv":0.0,"id":424679},{"batl":[[1,990,2.84]],"ltp":0.0,"tv":0.0,"id":3961},{"batl":[[2,990,2.84]],"ltp":0.0,"tv":0.0,"id":60443}]}]}
{"op":"mcm","clk":"11967551751","pt":1724656798450,"mc":[{"id":"1.232199708","rc":[{"batl":[[1,990,3.01]],"ltp":0.0,"tv":0.0,"id":424679},{"batl":[[1,990,3.01]],"ltp":0.0,"tv":0.0,"id":3961},{"batl":[[2,990,3.01]],"ltp":0.0,"tv":0.0,"id":60443}]}]}
{"op":"mcm","clk":"11967553852","pt":1724656847884,"mc":[{"id":"1.232199708","rc":[{"batl":[[1,990,3.18]],"ltp":0.0,"tv":0.0,"id":424679},{"batl":[[1,990,3.18]],"ltp":0.0,"tv":0.0,"id":3961},{"batl":[[2,990,3.18]],"ltp":0.0,"tv":0.0,"id":60443}]}]}
{"op":"mcm","clk":"11967554415","pt":1724656862086,"mc":[{"id":"1.232199708","rc":[{"batl":[[1,990,3.35]],"ltp":0.0,"tv":0.0,"id":424679},{"batl":[[1,990,3.35]],"ltp":0.0,"tv":0.0,"id":3961},{"batl":[[2,990,3.35]],"ltp":0.0,"tv":0.0,"id":60443}]}]}
{"op":"mcm","clk":"11967640331","pt":1724659974833,"mc":[{"id":"1.232199708","rc":[{"batb":[[0,1.11,27.11]],"ltp":0.0,"tv":0.0,"id":424679},{"batb":[[0,1.12,27.11]],"ltp":0.0,"tv":0.0,"id":3961},{"batb":[[0,1.11,27.11]],"ltp":0.0,"tv":0.0,"id":60443}]}]}
{"op":"mcm","clk":"11967816259","pt":1724664043719,"mc":[{"id":"1.232199708","rc":[{"batb":[[0,1.11,27.11]],"ltp":0.0,"tv":0.0,"id":424679},{"batb":[[0,1.12,27.11]],"ltp":0.0,"tv":0.0,"id":3961},{"batb":[[0,1.11,27.64]],"ltp":0.0,"tv":0.0,"id":60443}]}]}
{"op":"mcm","clk":"11967816646","pt":1724664051824,"mc":[{"id":"1.232199708","rc":[{"batb":[[0,1.12,27.64]],"ltp":0.0,"tv":0.0,"id":3961}]}]}
{"op":"mcm","clk":"11967817047","pt":1724664059736,"mc":[{"id":"1.232199708","rc":[{"batb":[[0,1.11,27.64]],"ltp":0.0,"tv":0.0,"id":424679}]}]}
{"op":"mcm","clk":"11968181273","pt":1724669599059,"mc":[{"id":"1.232199708","rc":[{"batb":[[0,1.11,27.11]],"ltp":0.0,"tv":0.0,"id":424679},{"batb":[[0,1.12,27.11]],"ltp":0.0,"tv":0.0,"id":3961},{"batb":[[0,1.11,27.11]],"ltp":0.0,"tv":0.0,"id":60443}]}]}
{"op":"mcm","clk":"11968237774","pt":1724670587745,"mc":[{"id":"1.232199708","rc":[{"batb":[[0,1.11,27.08]],"ltp":0.0,"tv":0.0,"id":424679},{"batb":[[0,1.12,27.08],[2,1.04,1.53]],"ltp":0.0,"tv":0.0,"id":3961},{"batb":[[0,1.11,27.08]],"ltp":0.0,"tv":0.0,"id":60443}]}]}
{"op":"mcm","clk":"11968237852","pt":1724670589540,"mc":[{"id":"1.232199708","rc":[{"batb":[[2,1.04,1.53]],"ltp":0.0,"tv":0.0,"id":424679}]}]}
{"op":"mcm","clk":"11968237933","pt":1724670591134,"mc":[{"id":"1.232199708","rc":[{"batb":[[2,1.04,1.53]],"ltp":0.0,"tv":0.0,"id":60443}]}]}
{"op":"mcm","clk":"11968237996","pt":1724670592264,"mc":[{"id":"1.232199708","rc":[{"batb":[[0,1.12,41.67],[1,1.11,27.08],[2,1.1,40]],"ltp":0.0,"tv":0.0,"id":60443}]}]}
{"op":"mcm","clk":"11968238083","pt":1724670593749,"mc":[{"id":"1.232199708","rc":[{"batb":[[0,1.12,41.67],[1,1.11,27.08],[2,1.1,40]],"ltp":0.0,"tv":0.0,"id":424679}]}]}
{"op":"mcm","clk":"11968238152","pt":1724670595037,"mc":[{"id":"1.232199708","rc":[{"batb":[[0,1.13,38.46],[1,1.12,27.08],[2,1.11,40]],"ltp":0.0,"tv":0.0,"id":3961}]}]}
{"op":"mcm","clk":"11968595468","pt":1724675567393,"mc":[{"id":"1.232199708","rc":[{"batb":[[0,1.13,65.46],[1,1.12,41.67],[2,1.11,27.09]],"ltp":0.0,"tv":0.0,"id":424679},{"batb":[[0,1.14,60.78],[1,1.13,38.46],[2,1.12,27.09]],"ltp":0.0,"tv":0.0,"id":3961},{"batb":[[0,1.13,65.46],[1,1.12,41.67],[2,1.11,27.09]],"ltp":0.0,"tv":0.0,"id":60443}]}]}
{"op":"mcm","clk":"11968748150","pt":1724677370421,"mc":[{"id":"1.232199708","rc":[{"batb":[[0,1.12,41.67],[1,1.11,27.06],[2,1.1,40]],"ltp":0.0,"tv":0.0,"id":424679},{"batb":[[0,1.13,38.46],[1,1.12,27.06],[2,1.11,40]],"ltp":0.0,"tv":0.0,"id":3961},{"batb":[[0,1.12,41.67],[1,1.11,27.06],[2,1.1,40]],"ltp":0.0,"tv":0.0,"id":60443}]}]}
{"op":"mcm","clk":"11968761566","pt":1724677521474,"mc":[{"id":"1.232199708","rc":[{"batb":[[0,1.13,65.38],[1,1.12,41.67],[2,1.11,27.06]],"ltp":0.0,"tv":0.0,"id":424679},{"batb":[[0,1.14,60.71],[1,1.13,38.46],[2,1.12,27.06]],"ltp":0.0,"tv":0.0,"id":3961},{"batb":[[0,1.13,65.38],[1,1.12,41.67],[2,1.11,27.06]],"ltp":0.0,"tv":0.0,"id":60443}]}]}
{"op":"mcm","clk":"11968936008","pt":1724679323455,"mc":[{"id":"1.232199708","rc":[{"batb":[[0,1.12,41.67],[1,1.11,27.06],[2,1.1,40]],"ltp":0.0,"tv":0.0,"id":424679},{"batb":[[0,1.13,38.46],[1,1.12,27.06],[2,1.11,40]],"ltp":0.0,"tv":0.0,"id":3961}]}]}
{"op":"mcm","clk":"11968936023","pt":1724679323559,"mc":[{"id":"1.232199708","rc":[{"batb":[[0,1.12,41.67],[1,1.11,27.06],[2,1.1,40]],"ltp":0.0,"tv":0.0,"id":60443}]}]}
{"op":"mcm","clk":"11968952188","pt":1724679473885,"mc":[{"id":"1.232199708","rc":[{"batb":[[0,1.13,65.38],[1,1.12,41.67],[2,1.11,27.06]],"ltp":0.0,"tv":0.0,"id":424679},{"batb":[[0,1.14,60.71],[1,1.13,38.46],[2,1.12,27.06]],"ltp":0.0,"tv":0.0,"id":3961},{"batb":[[0,1.13,65.38],[1,1.12,41.67],[2,1.11,27.06]],"ltp":0.0,"tv":0.0,"id":60443}]}]}
{"op":"mcm","clk":"11969159363","pt":1724681276092,"mc":[{"id":"1.232199708","rc":[{"batb":[[0,1.12,41.67],[1,1.11,27.08],[2,1.1,40]],"ltp":0.0,"tv":0.0,"id":424679},{"batb":[[0,1.13,38.46],[1,1.12,27.08],[2,1.11,40]],"ltp":0.0,"tv":0.0,"id":3961},{"batb":[[0,1.12,41.67],[1,1.11,27.08],[2,1.1,40]],"ltp":0.0,"tv":0.0,"id":60443}]}]}
{"op":"mcm","clk":"11969181168","pt":1724681424927,"mc":[{"id":"1.232199708","rc":[{"batb":[[0,1.13,65.44],[1,1.12,41.67],[2,1.11,27.08]],"ltp":0.0,"tv":0.0,"id":424679},{"batb":[[0,1.14,60.76],[1,1.13,38.46],[2,1.12,27.08]],"ltp":0.0,"tv":0.0,"id":3961},{"batb":[[0,1.13,65.44],[1,1.12,41.67],[2,1.11,27.08]],"ltp":0.0,"tv":0.0,"id":60443}]}]}
{"op":"mcm","clk":"11969466192","pt":1724683226376,"mc":[{"id":"1.232199708","rc":[{"batb":[[0,1.12,41.67],[1,1.11,27.08],[2,1.1,40]],"ltp":0.0,"tv":0.0,"id":424679},{"batb":[[0,1.13,38.46],[1,1.12,27.08],[2,1.11,40]],"ltp":0.0,"tv":0.0,"id":3961}]}]}
{"op":"mcm","clk":"11969466229","pt":1724683226581,"mc":[{"id":"1.232199708","rc":[{"batb":[[0,1.12,41.67],[1,1.11,27.08],[2,1.1,40]],"ltp":0.0,"tv":0.0,"id":60443}]}]}
{"op":"mcm","clk":"11969491792","pt":1724683381443,"mc":[{"id":"1.232199708","rc":[{"batb":[[0,1.13,65.44],[1,1.12,41.67],[2,1.11,27.08]],"ltp":0.0,"tv":0.0,"id":424679},{"batb":[[0,1.14,60.76],[1,1.13,38.46],[2,1.12,27.08]],"ltp":0.0,"tv":0.0,"id":3961},{"batb":[[0,1.13,65.44],[1,1.12,41.67],[2,1.11,27.08]],"ltp":0.0,"tv":0.0,"id":60443}]}]}
{"op":"mcm","clk":"11969684830","pt":1724684941353,"mc":[{"id":"1.232199708","rc":[{"batb":[[0,1.14,27.09],[1,1.13,65.46],[2,1.12,41.67]],"ltp":0.0,"tv":0.0,"id":424679},{"batb":[[0,1.15,27.09],[1,1.14,60.78],[2,1.13,38.46]],"ltp":0.0,"tv":0.0,"id":3961},{"batb":[[0,1.14,27.09],[1,1.13,65.46],[2,1.12,41.67]],"ltp":0.0,"tv":0.0,"id":60443}]}]}
{"op":"mcm","clk":"11969722779","pt":1724685183028,"mc":[{"id":"1.232199708","rc":[{"batb":[[1,1.12,41.67],[2,1.1,40]],"ltp":0.0,"tv":0.0,"id":424679},{"batb":[[1,1.13,38.46],[2,1.11,40]],"ltp":0.0,"tv":0.0,"id":3961},{"batb":[[1,1.12,41.67],[2,1.1,40]],"ltp":0.0,"tv":0.0,"id":60443}]}]}
{"op":"mcm","clk":"11969748340","pt":1724685326395,"mc":[{"id":"1.232199708","rc":[{"batb":[[0,1.15,56.73],[1,1.14,27.09],[2,1.12,41.67]],"ltp":0.0,"tv":0.0,"id":424679},{"batb":[[0,1.16,53.18],[1,1.15,27.09],[2,1.13,38.46]],"ltp":0.0,"tv":0.0,"id":3961},{"batb":[[0,1.15,56.73],[1,1.14,27.09],[2,1.12,41.67]],"ltp":0.0,"tv":0.0,"id":60443}]}]}
{"op":"mcm","clk":"11970040275","pt":1724687126897,"mc":[{"id":"1.232199708","rc":[{"batb":[[0,1.14,27.09],[1,1.12,41.67],[2,1.1,40]],"ltp":0.0,"tv":0.0,"id":424679},{"batb":[[0,1.15,27.09],[1,1.13,38.46],[2,1.11,40]],"ltp":0.0,"tv":0.0,"id":3961},{"batb":[[0,1.14,27.09],[1,1.12,41.67],[2,1.1,40]],"ltp":0.0,"tv":0.0,"id":60443}]}]}
{"op":"mcm","clk":"11970058242","pt":1724687252551,"mc":[{"id":"1.232199708","rc":[{"batb":[[0,1.15,56.73],[1,1.14,27.09],[2,1.12,41.67]],"ltp":0.0,"tv":0.0,"id":424679},{"batb":[[0,1.16,53.18],[1,1.15,27.09],[2,1.13,38.46]],"ltp":0.0,"tv":0.0,"id":3961},{"batb":[[0,1.15,56.73],[1,1.14,27.09],[2,1.12,41.67]],"ltp":0.0,"tv":0.0,"id":60443}]}]}
{"op":"mcm","clk":"11970271271","pt":1724689054257,"mc":[{"id":"1.232199708","rc":[{"batb":[[0,1.14,27.1],[1,1.12,41.67],[2,1.1,40]],"ltp":0.0,"tv":0.0,"id":424679},{"batb":[[0,1.15,27.1],[1,1.13,38.46],[2,1.11,40]],"ltp":0.0,"tv":0.0,"id":3961},{"batb":[[0,1.14,27.1],[1,1.12,41.67],[2,1.1,40]],"batl":[[0,90,1.1]],"ltp":0.0,"tv":0.0,"id":60443}]}]}
{"op":"mcm","clk":"11970278262","pt":1724689124737,"mc":[{"id":"1.232199708","rc":[{"batb":[[0,1.15,56.75],[1,1.14,27.1],[2,1.12,41.67]],"ltp":0.0,"tv":0.0,"id":424679},{"batb":[[0,1.16,53.21],[1,1.15,27.1],[2,1.13,38.46]],"ltp":0.0,"tv":0.0,"id":3961},{"batb":[[0,1.15,56.75],[1,1.14,27.1],[2,1.12,41.67]],"ltp":0.0,"tv":0.0,"id":60443}]}]}
{"op":"mcm","clk":"11970474568","pt":1724690926330,"mc":[{"id":"1.232199708","rc":[{"batb":[[0,1.14,27.1],[1,1.12,41.67],[2,1.1,40]],"ltp":0.0,"tv":0.0,"id":424679},{"batb":[[0,1.15,27.1],[1,1.13,38.46],[2,1.11,40]],"ltp":0.0,"tv":0.0,"id":3961},{"batb":[[0,1.14,27.1],[1,1.12,41.67],[2,1.1,40]],"ltp":0.0,"tv":0.0,"id":60443}]}]}
{"op":"mcm","clk":"11970477573","pt":1724690950593,"mc":[{"id":"1.232199708","rc":[{"batb":[[0,1.15,56.75],[1,1.14,27.1],[2,1.12,41.67]],"ltp":0.0,"tv":0.0,"id":424679},{"batb":[[0,1.16,53.21],[1,1.15,27.1],[2,1.13,38.46]],"ltp":0.0,"tv":0.0,"id":3961},{"batb":[[0,1.15,56.75],[1,1.14,27.1],[2,1.12,41.67]],"ltp":0.0,"tv":0.0,"id":60443}]}]}
{"op":"mcm","clk":"11970669054","pt":1724692374828,"mc":[{"id":"1.232199708","rc":[{"batb":[[0,1.15,56.73],[1,1.14,27.09]],"ltp":0.0,"tv":0.0,"id":424679},{"batb":[[0,1.16,53.18],[1,1.15,27.09]],"ltp":0.0,"tv":0.0,"id":3961},{"batb":[[0,1.15,56.73],[1,1.14,27.09]],"batl":[[0,90,1.1]],"ltp":0.0,"tv":0.0,"id":60443}]}]}
{"op":"mcm","clk":"11970691835","pt":1724692457373,"mc":[{"id":"1.232199708","rc":[{"batb":[[0,1.16,40],[1,1.15,56.73],[2,1.14,27.09]],"ltp":0.0,"tv":0.0,"id":424679},{"batb":[[0,1.17,40],[1,1.16,53.18],[2,1.15,27.09]],"ltp":0.0,"tv":0.0,"id":3961},{"batb":[[0,1.16,40],[1,1.15,56.73],[2,1.14,27.09]],"ltp":0.0,"tv":0.0,"id":60443}]}]}
{"op":"mcm","clk":"11970736590","pt":1724692751106,"mc":[{"id":"1.232199708","rc":[{"batb":[[1,1.14,27.09],[2,1.12,41.67]],"ltp":0.0,"tv":0.0,"id":424679},{"batb":[[1,1.15,27.09],[2,1.13,38.46]],"ltp":0.0,"tv":0.0,"id":3961},{"batb":[[1,1.14,27.09],[2,1.12,41.67]],"ltp":0.0,"tv":0.0,"id":60443}]}]}
{"op":"mcm","clk":"11970739981","pt":1724692772019,"mc":[{"id":"1.232199708","rc":[{"batb":[[0,1.17,50.06],[1,1.16,40],[2,1.14,27.09]],"ltp":0.0,"tv":0.0,"id":424679},{"batb":[[0,1.18,47.27],[1,1.17,40],[2,1.15,27.09]],"ltp":0.0,"tv":0.0,"id":3961},{"batb":[[0,1.17,50.06],[1,1.16,40],[2,1.14,27.09]],"ltp":0.0,"tv":0.0,"id":60443}]}]}
{"op":"mcm","clk":"11971028014","pt":1724694575177,"mc":[{"id":"1.232199708","rc":[{"batb":[[0,1.16,40],[1,1.14,27.09],[2,1.12,41.67]],"ltp":0.0,"tv":0.0,"id":424679},{"batb":[[0,1.17,40],[1,1.15,27.09],[2,1.13,38.46]],"ltp":0.0,"tv":0.0,"id":3961},{"batb":[[0,1.16,40],[1,1.14,27.09],[2,1.12,41.67]],"ltp":0.0,"tv":0.0,"id":60443}]}]}
{"op":"mcm","clk":"11971028246","pt":1724694576586,"mc":[{"id":"1.232199708","rc":[{"batb":[[0,1.17,50.06],[1,1.16,40],[2,1.14,27.09]],"ltp":0.0,"tv":0.0,"id":424679},{"batb":[[0,1.18,47.27],[1,1.17,40],[2,1.15,27.09]],"ltp":0.0,"tv":0.0,"id":3961},{"batb":[[0,1.17,50.06],[1,1.16,40],[2,1.14,27.09]],"ltp":0.0,"tv":0.0,"id":60443}]}]}
{"op":"mcm","clk":"11971307453","pt":1724696379397,"mc":[{"id":"1.232199708","rc":[{"batb":[[0,1.16,40],[1,1.14,27.09],[2,1.12,41.67]],"ltp":0.0,"tv":0.0,"id":424679},{"batb":[[0,1.17,40],[1,1.15,27.09],[2,1.13,38.46]],"ltp":0.0,"tv":0.0,"id":3961},{"batb":[[0,1.16,40],[1,1.14,27.09],[2,1.12,41.67]],"ltp":0.0,"tv":0.0,"id":60443}]}]}
{"op":"mcm","clk":"11971336088","pt":1724696539977,"mc":[{"id":"1.232199708","rc":[{"batb":[[0,1.17,50.06],[1,1.16,40],[2,1.14,27.09]],"ltp":0.0,"tv":0.0,"id":424679},{"batb":[[0,1.18,47.28],[1,1.17,40],[2,1.15,27.09]],"ltp":0.0,"tv":0.0,"id":3961},{"batb":[[0,1.17,50.06],[1,1.16,40],[2,1.14,27.09]],"ltp":0.0,"tv":0.0,"id":60443}]}]}
{"op":"mcm","clk":"11971652674","pt":1724698340320,"mc":[{"id":"1.232199708","rc":[{"batb":[[0,1.17,40],[1,1.15,27.09],[2,1.13,38.46]],"ltp":0.0,"tv":0.0,"id":3961},{"batb":[[0,1.16,40],[1,1.14,27.09],[2,1.12,41.67]],"ltp":0.0,"tv":0.0,"id":60443}]}]}
{"op":"mcm","clk":"11971652703","pt":1724698340527,"mc":[{"id":"1.232199708","rc":[{"batb":[[0,1.16,40],[1,1.14,27.09],[2,1.12,41.67]],"ltp":0.0,"tv":0.0,"id":424679}]}]}
{"op":"mcm","clk":"11971670660","pt":1724698470161,"mc":[{"id":"1.232199708","rc":[{"batb":[[0,1.17,50.06],[1,1.16,40],[2,1.14,27.09]],"ltp":0.0,"tv":0.0,"id":424679},{"batb":[[0,1.18,47.28],[1,1.17,40],[2,1.15,27.09]],"ltp":0.0,"tv":0.0,"id":3961},{"batb":[[0,1.17,50.06],[1,1.16,40],[2,1.14,27.09]],"ltp":0.0,"tv":0.0,"id":60443}]}]}
{"op":"mcm","clk":"11971831361","pt":1724699700309,"mc":[{"id":"1.232199708","rc":[{"batb":[[0,1.18,40],[1,1.17,50.05],[2,1.14,27.08]],"ltp":0.0,"tv":0.0,"id":424679},{"batb":[[0,1.19,40],[1,1.18,47.27],[2,1.15,27.08]],"ltp":0.0,"tv":0.0,"id":3961},{"batb":[[0,1.18,40],[1,1.17,50.05],[2,1.14,27.08]],"ltp":0.0,"tv":0.0,"id":60443}]}]}
{"op":"mcm","clk":"11971909480","pt":1724700272398,"mc":[{"id":"1.232199708","rc":[{"batb":[[1,1.14,27.08],[2,1.12,41.67]],"ltp":0.0,"tv":0.0,"id":424679},{"batb":[[1,1.15,27.08],[2,1.13,38.46]],"ltp":0.0,"tv":0.0,"id":3961},{"batb":[[1,1.14,27.08],[2,1.12,41.67]],"ltp":0.0,"tv":0.0,"id":60443}]}]}
{"op":"mcm","clk":"11971919967","pt":1724700352222,"mc":[{"id":"1.232199708","rc":[{"batb":[[0,1.19,44.78],[1,1.18,40],[2,1.14,27.08]],"ltp":0.0,"tv":0.0,"id":424679},{"batb":[[0,1.2,42.54],[1,1.19,40],[2,1.15,27.08]],"ltp":0.0,"tv":0.0,"id":3961},{"batb":[[0,1.19,44.78],[1,1.18,40],[2,1.14,27.08]],"ltp":0.0,"tv":0.0,"id":60443}]}]}
{"op":"mcm","clk":"11971962687","pt":1724700659782,"mc":[{"id":"1.232199708","rc":[{"batb":[[0,1.2,40],[1,1.19,44.78]],"ltp":0.0,"tv":0.0,"id":424679},{"batb":[[0,1.21,40],[1,1.2,42.54]],"ltp":0.0,"tv":0.0,"id":3961},{"batb":[[0,1.2,40],[1,1.19,44.78]],"ltp":0.0,"tv":0.0,"id":60443}]}]}
{"op":"mcm","clk":"11972150376","pt":1724702152985,"mc":[{"id":"1.232199708","rc":[{"batb":[[1,1.14,27.08],[2,1.12,41.67]],"ltp":0.0,"tv":0.0,"id":424679},{"batb":[[1,1.15,27.08],[2,1.13,38.46]],"ltp":0.0,"tv":0.0,"id":3961},{"batb":[[1,1.14,27.08],[2,1.12,41.67]],"ltp":0.0,"tv":0.0,"id":60443}]}]}
{"op":"mcm","clk":"11972156788","pt":1724702208056,"mc":[{"id":"1.232199708","rc":[{"batb":[[0,1.21,40.52],[1,1.2,40],[2,1.14,27.08]],"ltp":0.0,"tv":0.0,"id":424679},{"batb":[[0,1.22,38.67],[1,1.21,40],[2,1.15,27.08]],"ltp":0.0,"tv":0.0,"id":3961},{"batb":[[0,1.21,40.52],[1,1.2,40],[2,1.14,27.08]],"ltp":0.0,"tv":0.0,"id":60443}]}]}
{"op":"mcm","clk":"11972274217","pt":1724703174814,"mc":[{"id":"1.232199708","rc":[{"batb":[[0,1.21,40.52],[2,1.14,27.09]],"ltp":0.0,"tv":0.0,"id":424679},{"batb":[[0,1.22,38.68],[2,1.15,27.09]],"ltp":0.0,"tv":0.0,"id":3961},{"batb":[[0,1.21,40.52],[2,1.14,27.09]],"ltp":0.0,"tv":0.0,"id":60443}]}]}
{"op":"mcm","clk":"11972300844","pt":1724703311353,"mc":[{"id":"1.232199708","rc":[{"batb":[[0,1.22,6.88],[1,1.21,40.52],[2,1.2,40]],"ltp":0.0,"tv":0.0,"id":424679},{"batb":[[0,1.23,5.95],[1,1.22,38.68],[2,1.21,40]],"ltp":0.0,"tv":0.0,"id":3961},{"batb":[[0,1.22,7.12],[1,1.21,40.52],[2,1.2,40]],"ltp":0.0,"tv":0.0,"id":60443}]}]}
{"op":"mcm","clk":"11972389020","pt":1724704010198,"mc":[{"id":"1.232199708","rc":[{"batb":[[1,1.2,40],[2,1.14,27.09]],"ltp":0.0,"tv":0.0,"id":424679},{"batb":[[1,1.21,40],[2,1.15,27.09]],"ltp":0.0,"tv":0.0,"id":3961},{"batb":[[1,1.2,40],[2,1.14,27.09]],"ltp":0.0,"tv":0.0,"id":60443}]}]}
{"op":"mcm","clk":"11972390798","pt":1724704023921,"mc":[{"id":"1.232199708","rc":[{"batb":[[0,1.23,37],[1,1.22,6.88],[2,1.2,40]],"ltp":0.0,"tv":0.0,"id":424679},{"batb":[[0,1.24,35.46],[1,1.23,5.95],[2,1.21,40]],"ltp":0.0,"tv":0.0,"id":3961},{"batb":[[0,1.23,37],[1,1.22,7.12],[2,1.2,40]],"ltp":0.0,"tv":0.0,"id":60443}]}]}
{"op":"mcm","clk":"11972579045","pt":1724705826984,"mc":[{"id":"1.232199708","rc":[{"batb":[[0,1.22,6.88],[1,1.2,40],[2,1.14,27.09]],"ltp":0.0,"tv":0.0,"id":424679},{"batb":[[0,1.23,5.95],[1,1.21,40],[2,1.15,27.09]],"ltp":0.0,"tv":0.0,"id":3961},{"batb":[[0,1.22,7.12],[1,1.2,40],[2,1.14,27.09]],"ltp":0.0,"tv":0.0,"id":60443}]}]}
{"op":"mcm","clk":"11972589468","pt":1724705982105,"mc":[{"id":"1.232199708","rc":[{"batb":[[0,1.23,37],[1,1.22,6.88],[2,1.2,40]],"ltp":0.0,"tv":0.0,"id":424679},{"batb":[[0,1.24,35.46],[1,1.23,5.95],[2,1.21,40]],"ltp":0.0,"tv":0.0,"id":3961},{"batb":[[0,1.23,37],[1,1.22,7.12],[2,1.2,40]],"ltp":0.0,"tv":0.0,"id":60443}]}]}
{"op":"mcm","clk":"11972656894","pt":1724706844217,"mc":[{"id":"1.232199708","rc":[{"batb":[[0,1.24,6.88],[1,1.23,36.99]],"ltp":0.0,"tv":0.0,"id":424679},{"batb":[[0,1.24,35.45],[1,1.21,40],[2,1.15,27.08]],"ltp":0.0,"tv":0.0,"id":3961},{"batb":[[0,1.23,36.99],[1,1.22,7.12]],"ltp":0.0,"tv":0.0,"id":60443}]}]}
{"op":"mcm","clk":"11972656924","pt":1724706844636,"mc":[{"id":"1.232199708","rc":[{"batb":[[0,1.24,7.12],[1,1.23,36.99]],"ltp":0.0,"tv":0.0,"id":60443}]}]}
{"op":"mcm","clk":"11972721369","pt":1724707784473,"mc":[{"id":"1.232199708","rc":[{"batb":[[1,1.2,40],[2,1.14,27.08]],"ltp":0.0,"tv":0.0,"id":424679},{"batb":[[0,1.21,40],[1,1.15,27.08],[2,1.13,38.46]],"ltp":0.0,"tv":0.0,"id":3961},{"batb":[[1,1.2,40],[2,1.14,27.08]],"ltp":0.0,"tv":0.0,"id":60443}]}]}
{"op":"mcm","clk":"11972728784","pt":1724707891172,"mc":[{"id":"1.232199708","rc":[{"batb":[[0,1.25,34.03],[1,1.24,6.88],[2,1.2,40]],"ltp":0.0,"tv":0.0,"id":424679},{"batb":[[0,1.22,38.67],[1,1.21,40],[2,1.15,27.08]],"ltp":0.0,"tv":0.0,"id":3961},{"batb":[[0,1.25,34.03],[1,1.24,7.12],[2,1.2,40]],"ltp":0.0,"tv":0.0,"id":60443}]}]}
{"op":"mcm","clk":"11972848615","pt":1724709691916,"mc":[{"id":"1.232199708","rc":[{"batb":[[0,1.24,6.88],[1,1.2,40],[2,1.14,27.08]],"ltp":0.0,"tv":0.0,"id":424679},{"batb":[[0,1.21,40],[1,1.15,27.08],[2,1.13,38.46]],"ltp":0.0,"tv":0.0,"id":3961},{"batb":[[0,1.24,7.12],[1,1.2,40],[2,1.14,27.08]],"ltp":0.0,"tv":0.0,"id":60443}]}]}
{"op":"mcm","clk":"11972852868","pt":1724709782784,"mc":[{"id":"1.232199708","rc":[{"batb":[[0,1.25,34.03],[1,1.24,6.88],[2,1.2,40]],"ltp":0.0,"tv":0.0,"id":424679},{"batb":[[0,1.22,38.67],[1,1.21,40],[2,1.15,27.08]],"ltp":0.0,"tv":0.0,"id":3961},{"batb":[[0,1.25,34.03],[1,1.24,7.12],[2,1.2,40]],"ltp":0.0,"tv":0.0,"id":60443}]}]}
{"op":"mcm","clk":"11972886472","pt":1724710422339,"mc":[{"id":"1.232199708","rc":[{"batb":[[1,1.2,40],[2,1.14,27.08]],"ltp":0.0,"tv":0.0,"id":424679}]}]}
{"op":"mcm","clk":"11972886505","pt":1724710422948,"mc":[{"id":"1.232199708","rc":[{"batb":[[0,1.23,5.87],[1,1.22,38.67],[2,1.21,40]],"ltp":0.0,"tv":0.0,"id":3961},{"batb":[[1,1.2,40],[2,1.14,27.08]],"ltp":0.0,"tv":0.0,"id":60443}]}]}
{"op":"mcm","clk":"11972941828","pt":1724711583305,"mc":[{"id":"1.232199708","rc":[{"batb":[[0,1.2,40],[1,1.14,27.08],[2,1.12,41.67]],"ltp":0.0,"tv":0.0,"id":424679},{"batb":[[1,1.21,40],[2,1.15,27.08]],"ltp":0.0,"tv":0.0,"id":3961}]}]}
{"op":"mcm","clk":"11972941837","pt":1724711583510,"mc":[{"id":"1.232199708","rc":[{"batb":[[0,1.2,40],[1,1.14,27.08],[2,1.12,41.67]],"ltp":0.0,"tv":0.0,"id":60443}]}]}
{"op":"mcm","clk":"11972945203","pt":1724711645686,"mc":[{"id":"1.232199708","rc":[{"batb":[[0,1.21,40.51],[1,1.2,40],[2,1.14,27.08]],"ltp":0.0,"tv":0.0,"id":424679},{"batb":[[0,1.24,35.44],[1,1.23,5.87],[2,1.21,40]],"ltp":0.0,"tv":0.0,"id":3961},{"batb":[[0,1.21,40.51],[1,1.2,40],[2,1.14,27.08]],"ltp":0.0,"tv":0.0,"id":60443}]}]}
{"op":"mcm","clk":"11973046876","pt":1724713447310,"mc":[{"id":"1.232199708","rc":[{"batb":[[0,1.2,40],[1,1.14,27.09],[2,1.12,41.67]],"ltp":0.0,"tv":0.0,"id":424679},{"batb":[[0,1.23,5.87],[1,1.21,40],[2,1.15,27.09]],"ltp":0.0,"tv":0.0,"id":3961},{"batb":[[0,1.2,40],[1,1.14,27.09],[2,1.12,41.67]],"ltp":0.0,"tv":0.0,"id":60443}]}]}
{"op":"mcm","clk":"11973049987","pt":1724713497984,"mc":[{"id":"1.232199708","rc":[{"batb":[[0,1.21,40.52],[1,1.2,40],[2,1.14,27.09]],"ltp":0.0,"tv":0.0,"id":424679},{"batb":[[0,1.24,35.45],[1,1.23,5.87],[2,1.21,40]],"ltp":0.0,"tv":0.0,"id":3961},{"batb":[[0,1.21,40.52],[1,1.2,40],[2,1.14,27.09]],"ltp":0.0,"tv":0.0,"id":60443}]}]}
{"op":"mcm","clk":"11973064333","pt":1724713721358,"mc":[{"id":"1.232199708","rc":[{"batb":[[0,1.22,7.42],[1,1.21,40.52],[2,1.2,40]],"ltp":0.0,"tv":0.0,"id":424679},{"batb":[[1,1.21,40],[2,1.15,27.09]],"ltp":0.0,"tv":0.0,"id":3961}]}]}
{"op":"mcm","clk":"11973064352","pt":1724713721570,"mc":[{"id":"1.232199708","rc":[{"batb":[[0,1.22,6.98],[1,1.21,40.52],[2,1.2,40]],"ltp":0.0,"tv":0.0,"id":60443}]}]}
{"op":"mcm","clk":"11973174914","pt":1724715299234,"mc":[{"id":"1.232199708","rc":[{"batb":[[1,1.2,40],[2,1.14,27.09]],"ltp":0.0,"tv":0.0,"id":424679}]}]}
{"op":"mcm","clk":"11973174948","pt":1724715299645,"mc":[{"id":"1.232199708","rc":[{"batb":[[0,1.21,40],[1,1.15,27.09],[2,1.13,38.46]],"ltp":0.0,"tv":0.0,"id":3961},{"batb":[[1,1.2,40],[2,1.14,27.09]],"ltp":0.0,"tv":0.0,"id":60443}]}]}
{"op":"mcm","clk":"11973177185","pt":1724715337492,"mc":[{"id":"1.232199708","rc":[{"batb":[[0,1.23,36.99],[1,1.22,7.42],[2,1.2,40]],"ltp":0.0,"tv":0.0,"id":424679},{"batb":[[0,1.22,38.67],[1,1.21,40],[2,1.15,27.09]],"ltp":0.0,"tv":0.0,"id":3961},{"batb":[[0,1.23,36.99],[1,1.22,6.98],[2,1.2,40]],"ltp":0.0,"tv":0.0,"id":60443}]}]}
{"op":"mcm","clk":"11973254098","pt":1724717138494,"mc":[{"id":"1.232199708","rc":[{"batb":[[0,1.23,36.99],[1,1.22,7.42]],"ltp":0.0,"tv":0.0,"id":424679},{"batb":[[0,1.22,38.67],[2,1.15,27.08]],"ltp":0.0,"tv":0.0,"id":3961},{"batb":[[0,1.22,6.97],[1,1.2,40],[2,1.14,27.08]],"ltp":0.0,"tv":0.0,"id":60443}]}]}
{"op":"mcm","clk":"11973254115","pt":1724717138907,"mc":[{"id":"1.232199708","rc":[{"batb":[[0,1.22,7.42],[1,1.2,40],[2,1.14,27.08]],"ltp":0.0,"tv":0.0,"id":424679},{"batb":[[0,1.21,40],[1,1.15,27.08],[2,1.13,38.46]],"ltp":0.0,"tv":0.0,"id":3961}]}]}
{"op":"mcm","clk":"11973254797","pt":1724717159732,"mc":[{"id":"1.232199708","rc":[{"batb":[[0,1.23,36.99],[1,1.22,7.42],[2,1.2,40]],"ltp":0.0,"tv":0.0,"id":424679},{"batb":[[0,1.22,38.67],[1,1.21,40],[2,1.15,27.08]],"ltp":0.0,"tv":0.0,"id":3961},{"batb":[[0,1.23,36.99],[1,1.22,6.97],[2,1.2,40]],"ltp":0.0,"tv":0.0,"id":60443}]}]}
{"op":"mcm","clk":"11973258841","pt":1724717277491,"mc":[{"id":"1.232199708","rc":[{"batb":[[0,1.24,7.42],[1,1.23,36.99]],"ltp":0.0,"tv":0.0,"id":424679},{"batb":[[0,1.23,6.5],[1,1.22,38.67],[2,1.21,40]],"ltp":0.0,"tv":0.0,"id":3961},{"batb":[[0,1.24,6.97],[1,1.23,36.99]],"ltp":0.0,"tv":0.0,"id":60443}]}]}
{"op":"mcm","clk":"11973320962","pt":1724718961344,"mc":[{"id":"1.232199708","rc":[{"batb":[[1,1.2,40],[2,1.14,27.08]],"ltp":0.0,"tv":0.0,"id":424679},{"batb":[[1,1.21,40],[2,1.15,27.08]],"ltp":0.0,"tv":0.0,"id":3961},{"batb":[[1,1.2,40],[2,1.14,27.08]],"ltp":0.0,"tv":0.0,"id":60443}]}]}
{"op":"mcm","clk":"11973321333","pt":1724718971254,"mc":[{"id":"1.232199708","rc":[{"batb":[[0,1.25,34.03],[1,1.24,7.42],[2,1.2,40]],"ltp":0.0,"tv":0.0,"id":424679},{"batb":[[0,1.24,35.45],[1,1.23,6.5],[2,1.21,40]],"ltp":0.0,"tv":0.0,"id":3961},{"batb":[[0,1.25,34.03],[1,1.24,6.97],[2,1.2,40]],"ltp":0.0,"tv":0.0,"id":60443}]}]}
{"op":"mcm","clk":"11973386668","pt":1724720627485,"mc":[{"id":"1.232199708","rc":[{"batb":[[0,1.25,34.04],[1,1.2,40],[2,1.14,27.09]],"ltp":0.0,"tv":0.0,"id":424679},{"batb":[[0,1.24,35.46],[1,1.23,6.51]],"ltp":0.0,"tv":0.0,"id":3961},{"batb":[[0,1.25,34.04],[1,1.24,6.98]],"ltp":0.0,"tv":0.0,"id":60443}]}]}
{"op":"mcm","clk":"11973386698","pt":1724720628101,"mc":[{"id":"1.232199708","rc":[{"batb":[[1,1.21,40],[2,1.15,27.09]],"ltp":0.0,"tv":0.0,"id":3961},{"batb":[[1,1.2,40],[2,1.14,27.09]],"ltp":0.0,"tv":0.0,"id":60443}]}]}
{"op":"mcm","clk":"11973393069","pt":1724720774482,"mc":[{"id":"1.232199708","rc":[{"batb":[[0,1.21,40],[1,1.15,27.09],[2,1.13,38.46]],"ltp":0.0,"tv":0.0,"id":3961}]}]}
{"op":"mcm","clk":"11973393090","pt":1724720774845,"mc":[{"id":"1.232199708","rc":[{"batb":[[0,1.2,40],[1,1.14,27.09],[2,1.12,41.67]],"ltp":0.0,"tv":0.0,"id":424679},{"batb":[[0,1.2,40],[1,1.14,27.09],[2,1.12,41.67]],"ltp":0.0,"tv":0.0,"id":60443}]}]}
{"op":"mcm","clk":"11973393124","pt":1724720775565,"mc":[{"id":"1.232199708","rc":[{"batb":[[0,1.21,40.53],[1,1.2,40],[2,1.14,27.09]],"ltp":0.0,"tv":0.0,"id":424679},{"batb":[[0,1.22,38.69],[1,1.21,40],[2,1.15,27.09]],"ltp":0.0,"tv":0.0,"id":3961},{"batb":[[0,1.21,40.53],[1,1.2,40],[2,1.14,27.09]],"ltp":0.0,"tv":0.0,"id":60443}]}]}
{"op":"mcm","clk":"11973459543","pt":1724722580379,"mc":[{"id":"1.232199708","rc":[{"batb":[[0,1.2,40],[1,1.14,27.09],[2,1.12,41.67]],"ltp":0.0,"tv":0.0,"id":60443}]}]}
{"op":"mcm","clk":"11973459563","pt":1724722580781,"mc":[{"id":"1.232199708","rc":[{"batb":[[0,1.2,40],[1,1.14,27.09],[2,1.12,41.67]],"ltp":0.0,"tv":0.0,"id":424679},{"batb":[[0,1.21,40],[1,1.15,27.09],[2,1.13,38.46]],"ltp":0.0,"tv":0.0,"id":3961}]}]}
{"op":"mcm","clk":"11973465123","pt":1724722708767,"mc":[{"id":"1.232199708","rc":[{"batb":[[0,1.21,40.53],[1,1.2,40],[2,1.14,27.09]],"ltp":0.0,"tv":0.0,"id":424679},{"batb":[[0,1.22,38.69],[1,1.21,40],[2,1.15,27.09]],"ltp":0.0,"tv":0.0,"id":3961},{"batb":[[0,1.21,40.53],[1,1.2,40],[2,1.14,27.09]],"ltp":0.0,"tv":0.0,"id":60443}]}]}
{"op":"mcm","clk":"11973517395","pt":1724723947379,"mc":[{"id":"1.232199708","rc":[{"batb":[[0,1.22,5.92],[1,1.21,40.53],[2,1.2,40]],"ltp":0.0,"tv":0.0,"id":424679},{"batb":[[0,1.23,7.43],[1,1.22,38.69],[2,1.21,40]],"ltp":0.0,"tv":0.0,"id":3961}]}]}
{"op":"mcm","clk":"11973517406","pt":1724723947585,"mc":[{"id":"1.232199708","rc":[{"batb":[[0,1.22,5.89],[1,1.21,40.53],[2,1.2,40]],"ltp":0.0,"tv":0.0,"id":60443}]}]}
{"op":"mcm","clk":"11973542280","pt":1724724510248,"mc":[{"id":"1.232199708","rc":[{"batb":[[0,1.22,5.91],[1,1.2,40],[2,1.14,27.09]],"ltp":0.0,"tv":0.0,"id":424679},{"batb":[[0,1.23,7.42],[1,1.21,40],[2,1.15,27.09]],"ltp":0.0,"tv":0.0,"id":3961},{"batb":[[0,1.22,5.88],[1,1.2,40],[2,1.14,27.09]],"ltp":0.0,"tv":0.0,"id":60443}]}]}
{"op":"mcm","clk":"11973547012","pt":1724724617777,"mc":[{"id":"1.232199708","rc":[{"batb":[[0,1.23,37],[1,1.22,5.91],[2,1.2,40]],"ltp":0.0,"tv":0.0,"id":424679},{"batb":[[0,1.24,35.46],[1,1.23,7.42],[2,1.21,40]],"ltp":0.0,"tv":0.0,"id":3961},{"batb":[[0,1.23,37],[1,1.22,5.88],[2,1.2,40]],"ltp":0.0,"tv":0.0,"id":60443}]}]}
{"op":"mcm","clk":"11973638368","pt":1724726419288,"mc":[{"id":"1.232199708","rc":[{"batb":[[0,1.22,5.91],[1,1.2,40],[2,1.14,27.09]],"ltp":0.0,"tv":0.0,"id":424679},{"batb":[[0,1.23,7.42],[1,1.21,40],[2,1.15,27.09]],"ltp":0.0,"tv":0.0,"id":3961},{"batb":[[0,1.22,5.88],[1,1.2,40],[2,1.14,27.09]],"ltp":0.0,"tv":0.0,"id":60443}]}]}
{"op":"mcm","clk":"11973642711","pt":1724726510254,"mc":[{"id":"1.232199708","rc":[{"batb":[[0,1.23,37],[1,1.22,5.91],[2,1.2,40]],"ltp":0.0,"tv":0.0,"id":424679},{"batb":[[0,1.24,35.46],[1,1.23,7.42],[2,1.21,40]],"ltp":0.0,"tv":0.0,"id":3961},{"batb":[[0,1.23,37],[1,1.22,5.88],[2,1.2,40]],"ltp":0.0,"tv":0.0,"id":60443}]}]}
{"op":"mcm","clk":"11973672276","pt":1724727273451,"mc":[{"id":"1.232199708","rc":[{"batb":[[0,1.24,5.91],[1,1.23,37]],"ltp":0.0,"tv":0.0,"id":424679},{"batb":[[1,1.21,40],[2,1.15,27.09]],"ltp":0.0,"tv":0.0,"id":3961},{"batb":[[1,1.2,40],[2,1.14,27.09]],"ltp":0.0,"tv":0.0,"id":60443}]}]}
{"op":"mcm","clk":"11973672280","pt":1724727273551,"mc":[{"id":"1.232199708","rc":[{"batb":[[0,1.24,5.88],[1,1.23,37],[2,1.2,40]],"ltp":0.0,"tv":0.0,"id":60443}]}]}
{"op":"mcm","clk":"11973701976","pt":1724728311339,"mc":[{"id":"1.232199708","rc":[{"batb":[[0,1.24,5.91],[1,1.2,40],[2,1.14,27.09]],"ltp":0.0,"tv":0.0,"id":424679},{"batb":[[0,1.24,35.46],[2,1.15,27.09]],"ltp":0.0,"tv":0.0,"id":3961},{"batb":[[0,1.24,5.88],[1,1.23,37]],"ltp":0.0,"tv":0.0,"id":60443}]}]}
{"op":"mcm","clk":"11973701992","pt":1724728311700,"mc":[{"id":"1.232199708","rc":[{"batb":[[0,1.21,40],[1,1.15,27.09],[2,1.13,38.46]],"ltp":0.0,"tv":0.0,"id":3961},{"batb":[[1,1.2,40],[2,1.14,27.09]],"ltp":0.0,"tv":0.0,"id":60443}]}]}
{"op":"mcm","clk":"11973702830","pt":1724728341719,"mc":[{"id":"1.232199708","rc":[{"batl":[[0,95,2.67],[1,990,3.35],[2,990,0]],"ltp":0.0,"tv":0.0,"id":60443}]}]}
{"op":"mcm","clk":"11973703893","pt":1724728376950,"mc":[{"id":"1.232199708","rc":[{"batb":[[0,1.25,34.04],[1,1.24,5.91],[2,1.2,40]],"ltp":0.0,"tv":0.0,"id":424679},{"batb":[[0,1.22,38.69],[1,1.21,40],[2,1.15,27.09]],"ltp":0.0,"tv":0.0,"id":3961},{"batb":[[0,1.25,34.04],[1,1.24,5.88],[2,1.2,40]],"ltp":0.0,"tv":0.0,"id":60443}]}]}
{"op":"mcm","clk":"11973756823","pt":1724730179265,"mc":[{"id":"1.232199708","rc":[{"batb":[[0,1.24,5.91],[1,1.2,40],[2,1.14,27.09]],"ltp":0.0,"tv":0.0,"id":424679},{"batb":[[0,1.21,40],[1,1.15,27.09],[2,1.13,38.46]],"ltp":0.0,"tv":0.0,"id":3961},{"batb":[[0,1.24,5.88],[1,1.2,40],[2,1.14,27.09]],"ltp":0.0,"tv":0.0,"id":60443}]}]}
{"op":"mcm","clk":"11973757670","pt":1724730227995,"mc":[{"id":"1.232199708","rc":[{"batb":[[0,1.25,34.04],[1,1.24,5.91],[2,1.2,40]],"ltp":0.0,"tv":0.0,"id":424679},{"batb":[[0,1.22,38.69],[1,1.21,40],[2,1.15,27.09]],"ltp":0.0,"tv":0.0,"id":3961},{"batb":[[0,1.25,34.04],[1,1.24,5.88],[2,1.2,40]],"ltp":0.0,"tv":0.0,"id":60443}]}]}
{"op":"mcm","clk":"11973764783","pt":1724730586476,"mc":[{"id":"1.232199708","rc":[{"batb":[[1,1.2,40],[2,1.14,27.09]],"ltp":0.0,"tv":0.0,"id":424679}]}]}
{"op":"mcm","clk":"11973764794","pt":1724730586985,"mc":[{"id":"1.232199708","rc":[{"batb":[[0,1.23,6.48],[1,1.22,38.69],[2,1.21,40]],"ltp":0.0,"tv":0.0,"id":3961},{"batb":[[1,1.2,40],[2,1.14,27.09]],"ltp":0.0,"tv":0.0,"id":60443}]}]}
{"op":"mcm","clk":"11973798335","pt":1724732029336,"mc":[{"id":"1.232199708","rc":[{"batb":[[0,1.2,40],[1,1.14,27.09],[2,1.12,41.67]],"ltp":0.0,"tv":0.0,"id":424679},{"batb":[[1,1.21,40],[2,1.15,27.09]],"ltp":0.0,"tv":0.0,"id":3961},{"batb":[[0,1.2,40],[1,1.14,27.09],[2,1.12,41.67]],"ltp":0.0,"tv":0.0,"id":60443}]}]}
{"op":"mcm","clk":"11973799198","pt":1724732067286,"mc":[{"id":"1.232199708","rc":[{"batb":[[0,1.21,40.53],[1,1.2,40],[2,1.14,27.09]],"ltp":0.0,"tv":0.0,"id":424679},{"batb":[[0,1.24,35.46],[1,1.23,6.48],[2,1.21,40]],"ltp":0.0,"tv":0.0,"id":3961},{"batb":[[0,1.21,40.53],[1,1.2,40],[2,1.14,27.09]],"ltp":0.0,"tv":0.0,"id":60443}]}]}
{"op":"mcm","clk":"11973825489","pt":1724733801471,"mc":[{"id":"1.232199708","rc":[{"batb":[[0,1.22,7.34],[1,1.21,40.53],[2,1.2,40]],"ltp":0.0,"tv":0.0,"id":424679},{"batb":[[1,1.21,40],[2,1.15,27.09]],"ltp":0.0,"tv":0.0,"id":3961},{"batb":[[0,1.22,7.35],[1,1.21,40.53],[2,1.2,40]],"ltp":0.0,"tv":0.0,"id":60443}]}]}
{"op":"mcm","clk":"11973826752","pt":1724733868949,"mc":[{"id":"1.232199708","rc":[{"batb":[[1,1.2,40],[2,1.14,27.09]],"ltp":0.0,"tv":0.0,"id":424679},{"batb":[[0,1.21,40],[1,1.15,27.09],[2,1.13,38.46]],"ltp":0.0,"tv":0.0,"id":3961},{"batb":[[1,1.2,40],[2,1.14,27.09]],"ltp":0.0,"tv":0.0,"id":60443}]}]}
{"op":"mcm","clk":"11973827138","pt":1724733891793,"mc":[{"id":"1.232199708","rc":[{"batb":[[0,1.23,37],[1,1.22,7.34],[2,1.2,40]],"ltp":0.0,"tv":0.0,"id":424679},{"batb":[[0,1.22,38.68],[1,1.21,40],[2,1.15,27.09]],"ltp":0.0,"tv":0.0,"id":3961},{"batb":[[0,1.23,37],[1,1.22,7.35],[2,1.2,40]],"ltp":0.0,"tv":0.0,"id":60443}]}]}
{"op":"mcm","clk":"11973853315","pt":1724735574805,"mc":[{"id":"1.232199708","rc":[{"batb":[[0,1.23,37],[1,1.22,7.34]],"ltp":0.0,"tv":0.0,"id":424679},{"batb":[[0,1.22,38.68],[2,1.15,27.09]],"ltp":0.0,"tv":0.0,"id":3961},{"batb":[[0,1.23,37],[1,1.22,7.35]],"ltp":0.0,"tv":0.0,"id":60443}]}]}
{"op":"mcm","clk":"11973863084","pt":1724735693443,"mc":[{"id":"1.232199708","rc":[{"batb":[[0,1.22,7.34],[1,1.2,40],[2,1.14,27.09]],"ltp":0.0,"tv":0.0,"id":424679},{"batb":[[0,1.21,40],[1,1.15,27.09],[2,1.13,38.46]],"ltp":0.0,"tv":0.0,"id":3961},{"batb":[[0,1.22,7.35],[1,1.2,40],[2,1.14,27.09]],"ltp":0.0,"tv":0.0,"id":60443}]}]}
{"op":"mcm","clk":"11973863384","pt":1724735716769,"mc":[{"id":"1.232199708","rc":[{"batb":[[0,1.23,37],[1,1.22,7.34],[2,1.2,40]],"ltp":0.0,"tv":0.0,"id":424679},{"batb":[[0,1.22,38.68],[1,1.21,40],[2,1.15,27.09]],"ltp":0.0,"tv":0.0,"id":3961},{"batb":[[0,1.23,37],[1,1.22,7.35],[2,1.2,40]],"ltp":0.0,"tv":0.0,"id":60443}]}]}
{"op":"mcm","clk":"11973884450","pt":1724737188342,"mc":[{"id":"1.232199708","rc":[{"batb":[[0,1.24,7.34],[1,1.23,37]],"ltp":0.0,"tv":0.0,"id":424679},{"batb":[[0,1.23,7.4],[1,1.22,38.68],[2,1.21,40]],"ltp":0.0,"tv":0.0,"id":3961},{"batb":[[0,1.24,7.35],[1,1.23,37]],"ltp":0.0,"tv":0.0,"id":60443}]}]}
{"op":"mcm","clk":"11973889127","pt":1724737517303,"mc":[{"id":"1.232199708","rc":[{"batb":[[1,1.2,40],[2,1.14,27.09]],"ltp":0.0,"tv":0.0,"id":424679},{"batb":[[1,1.21,40],[2,1.15,27.09]],"ltp":0.0,"tv":0.0,"id":3961},{"batb":[[1,1.2,40],[2,1.14,27.09]],"ltp":0.0,"tv":0.0,"id":60443}]}]}
{"op":"mcm","clk":"11973889339","pt":1724737529882,"mc":[{"id":"1.232199708","rc":[{"batb":[[0,1.25,34.04],[1,1.24,7.34],[2,1.2,40]],"ltp":0.0,"tv":0.0,"id":424679},{"batb":[[0,1.24,35.46],[1,1.23,7.4],[2,1.21,40]],"ltp":0.0,"tv":0.0,"id":3961},{"batb":[[0,1.25,34.04],[1,1.24,7.35],[2,1.2,40]],"ltp":0.0,"tv":0.0,"id":60443}]}]}
{"op":"mcm","clk":"11973923215","pt":1724739332024,"mc":[{"id":"1.232199708","rc":[{"batb":[[0,1.24,7.34],[1,1.2,40],[2,1.14,27.08]],"ltp":0.0,"tv":0.0,"id":424679},{"batb":[[0,1.23,7.4],[1,1.21,40],[2,1.15,27.08]],"ltp":0.0,"tv":0.0,"id":3961},{"batb":[[0,1.24,7.35],[1,1.2,40],[2,1.14,27.08]],"ltp":0.0,"tv":0.0,"id":60443}]}]}
{"op":"mcm","clk":"11973923321","pt":1724739339246,"mc":[{"id":"1.232199708","rc":[{"batb":[[0,1.25,34.03],[1,1.24,7.34],[2,1.2,40]],"ltp":0.0,"tv":0.0,"id":424679},{"batb":[[0,1.24,35.44],[1,1.23,7.4],[2,1.21,40]],"ltp":0.0,"tv":0.0,"id":3961},{"batb":[[0,1.25,34.03],[1,1.24,7.35],[2,1.2,40]],"ltp":0.0,"tv":0.0,"id":60443}]}]}
{"op":"mcm","clk":"11973940962","pt":1724740378095,"mc":[{"id":"1.232199708","rc":[{"batb":[[1,1.2,40],[2,1.14,27.08]],"ltp":0.0,"tv":0.0,"id":424679},{"batb":[[1,1.21,40],[2,1.15,27.08]],"ltp":0.0,"tv":0.0,"id":3961},{"batb":[[1,1.2,40],[2,1.14,27.08]],"ltp":0.0,"tv":0.0,"id":60443}]}]}
{"op":"mcm","clk":"11973965594","pt":1724741139939,"mc":[{"id":"1.232199708","rc":[{"batb":[[0,1.2,40],[1,1.14,27.08],[2,1.12,41.67]],"ltp":0.0,"tv":0.0,"id":424679},{"batb":[[0,1.21,40],[1,1.15,27.08],[2,1.13,38.46]],"ltp":0.0,"tv":0.0,"id":3961},{"batb":[[0,1.2,40],[1,1.14,27.08],[2,1.12,41.67]],"ltp":0.0,"tv":0.0,"id":60443}]}]}
{"op":"mcm","clk":"11973965846","pt":1724741150540,"mc":[{"id":"1.232199708","rc":[{"batb":[[0,1.21,40.51],[1,1.2,40],[2,1.14,27.08]],"ltp":0.0,"tv":0.0,"id":424679},{"batb":[[0,1.22,38.67],[1,1.21,40],[2,1.15,27.08]],"ltp":0.0,"tv":0.0,"id":3961},{"batb":[[0,1.21,40.51],[1,1.2,40],[2,1.14,27.08]],"ltp":0.0,"tv":0.0,"id":60443}]}]}
{"op":"mcm","clk":"11974011372","pt":1724742952035,"mc":[{"id":"1.232199708","rc":[{"batb":[[0,1.2,40],[1,1.14,27.07],[2,1.12,41.67]],"ltp":0.0,"tv":0.0,"id":424679},{"batb":[[0,1.21,40],[1,1.15,27.07],[2,1.13,38.46]],"ltp":0.0,"tv":0.0,"id":3961},{"batb":[[0,1.2,40],[1,1.14,27.07],[2,1.12,41.67]],"ltp":0.0,"tv":0.0,"id":60443}]}]}
{"op":"mcm","clk":"11974011668","pt":1724742960266,"mc":[{"id":"1.232199708","rc":[{"batb":[[0,1.21,40.5],[1,1.2,40],[2,1.14,27.07]],"ltp":0.0,"tv":0.0,"id":424679},{"batb":[[0,1.22,38.66],[1,1.21,40],[2,1.15,27.07]],"ltp":0.0,"tv":0.0,"id":3961},{"batb":[[0,1.21,40.5],[1,1.2,40],[2,1.14,27.07]],"ltp":0.0,"tv":0.0,"id":60443}]}]}
{"op":"mcm","clk":"11974033105","pt":1724743649129,"mc":[{"id":"1.232199708","rc":[{"batb":[[0,1.22,6.26],[1,1.21,40.5],[2,1.2,40]],"ltp":0.0,"tv":0.0,"id":424679},{"batb":[[0,1.23,7.04],[1,1.22,38.66],[2,1.21,40]],"ltp":0.0,"tv":0.0,"id":3961},{"batb":[[0,1.22,6.81],[1,1.21,40.5],[2,1.2,40]],"ltp":0.0,"tv":0.0,"id":60443}]}]}
{"op":"mcm","clk":"11974072875","pt":1724744760943,"mc":[{"id":"1.232199708","rc":[{"batb":[[1,1.2,40],[2,1.14,27.07]],"ltp":0.0,"tv":0.0,"id":424679},{"batb":[[1,1.21,40],[2,1.15,27.07]],"ltp":0.0,"tv":0.0,"id":3961},{"batb":[[1,1.2,40],[2,1.14,27.07]],"ltp":0.0,"tv":0.0,"id":60443}]}]}
{"op":"mcm","clk":"11974073255","pt":1724744771243,"mc":[{"id":"1.232199708","rc":[{"batb":[[0,1.23,36.98],[1,1.22,6.26],[2,1.2,40]],"ltp":0.0,"tv":0.0,"id":424679},{"batb":[[0,1.24,35.43],[1,1.23,7.04],[2,1.21,40]],"ltp":0.0,"tv":0.0,"id":3961},{"batb":[[0,1.23,36.98],[1,1.22,6.81],[2,1.2,40]],"ltp":0.0,"tv":0.0,"id":60443}]}]}
{"op":"mcm","clk":"11974135196","pt":1724746374807,"mc":[{"id":"1.232199708","rc":[{"batb":[[0,1.23,36.97],[1,1.22,6.26]],"ltp":0.0,"tv":0.0,"id":424679},{"batb":[[0,1.24,35.43],[1,1.23,7.04]],"ltp":0.0,"tv":0.0,"id":3961},{"batb":[[0,1.23,36.97],[1,1.22,6.81]],"ltp":0.0,"tv":0.0,"id":60443}]}]}
{"op":"mcm","clk":"11974151725","pt":1724746572392,"mc":[{"id":"1.232199708","rc":[{"batb":[[0,1.22,6.81],[1,1.2,40],[2,1.14,27.07]],"ltp":0.0,"tv":0.0,"id":60443}]}]}
{"op":"mcm","clk":"11974151746","pt":1724746572801,"mc":[{"id":"1.232199708","rc":[{"batb":[[0,1.22,6.26],[1,1.2,40],[2,1.14,27.07]],"ltp":0.0,"tv":0.0,"id":424679},{"batb":[[0,1.23,7.04],[1,1.21,40],[2,1.15,27.07]],"ltp":0.0,"tv":0.0,"id":3961}]}]}
{"op":"mcm","clk":"11974152039","pt":1724746579413,"mc":[{"id":"1.232199708","rc":[{"batb":[[0,1.23,36.97],[1,1.22,6.26],[2,1.2,40]],"ltp":0.0,"tv":0.0,"id":424679},{"batb":[[0,1.23,36.97],[1,1.22,6.81],[2,1.2,40]],"ltp":0.0,"tv":0.0,"id":60443}]}]}
{"op":"mcm","clk":"11974152046","pt":1724746579517,"mc":[{"id":"1.232199708","rc":[{"batb":[[0,1.24,35.43],[1,1.23,7.04],[2,1.21,40]],"ltp":0.0,"tv":0.0,"id":3961}]}]}
{"op":"mcm","clk":"11974164254","pt":1724746921256,"mc":[{"id":"1.232199708","rc":[{"batb":[[0,1.24,6.26],[1,1.23,36.97]],"ltp":0.0,"tv":0.0,"id":424679},{"batb":[[1,1.21,40],[2,1.15,27.07]],"ltp":0.0,"tv":0.0,"id":3961}]}]}
{"op":"mcm","clk":"11974164282","pt":1724746921775,"mc":[{"id":"1.232199708","rc":[{"batb":[[0,1.24,6.81],[1,1.23,36.97]],"ltp":0.0,"tv":0.0,"id":60443}]}]}
{"op":"mcm","clk":"11974224505","pt":1724748381057,"mc":[{"id":"1.232199708","rc":[{"batb":[[1,1.2,40],[2,1.14,27.07]],"ltp":0.0,"tv":0.0,"id":424679},{"batb":[[0,1.21,40],[1,1.15,27.07],[2,1.13,38.46]],"ltp":0.0,"tv":0.0,"id":3961},{"batb":[[1,1.2,40],[2,1.14,27.07]],"ltp":0.0,"tv":0.0,"id":60443}]}]}
{"op":"mcm","clk":"11974224793","pt":1724748386596,"mc":[{"id":"1.232199708","rc":[{"batb":[[0,1.25,34.01],[1,1.24,6.26],[2,1.2,40]],"ltp":0.0,"tv":0.0,"id":424679},{"batb":[[0,1.22,38.65],[1,1.21,40],[2,1.15,27.07]],"ltp":0.0,"tv":0.0,"id":3961},{"batb":[[0,1.25,34.01],[1,1.24,6.81],[2,1.2,40]],"ltp":0.0,"tv":0.0,"id":60443}]}]}
{"op":"mcm","clk":"11974276928","pt":1724749601982,"mc":[{"id":"1.232199708","rc":[{"batb":[[0,1.25,33.97],[1,1.24,6.25]],"batl":[[1,990,3.34]],"ltp":0.0,"tv":0.0,"id":424679},{"batb":[[0,1.22,38.6],[2,1.15,27.04]],"batl":[[1,990,3.34]],"ltp":0.0,"tv":0.0,"id":3961},{"batb":[[0,1.25,33.97],[1,1.24,6.8]],"batl":[[1,990,3.34]],"ltp":0.0,"tv":0.0,"id":60443}]}]}
{"op":"mcm","clk":"11974307739","pt":1724750188024,"mc":[{"id":"1.232199708","rc":[{"batb":[[0,1.24,6.25],[1,1.2,40],[2,1.14,27.04]],"ltp":0.0,"tv":0.0,"id":424679},{"batb":[[0,1.21,40],[1,1.15,27.04],[2,1.04,126.53]],"ltp":0.0,"tv":0.0,"id":3961},{"batb":[[0,1.24,6.8],[1,1.2,40],[2,1.14,27.04]],"ltp":0.0,"tv":0.0,"id":60443}]}]}
{"op":"mcm","clk":"11974307960","pt":1724750193024,"mc":[{"id":"1.232199708","rc":[{"batb":[[0,1.25,33.97],[1,1.24,6.25],[2,1.2,40]],"ltp":0.0,"tv":0.0,"id":424679},{"batb":[[0,1.22,38.6],[1,1.21,40],[2,1.15,27.04]],"ltp":0.0,"tv":0.0,"id":3961},{"batb":[[0,1.25,33.97],[1,1.24,6.8],[2,1.2,40]],"ltp":0.0,"tv":0.0,"id":60443}]}]}
{"op":"mcm","clk":"11974314374","pt":1724750327379,"mc":[{"id":"1.232199708","rc":[{"batb":[[1,1.2,40],[2,1.14,27.04]],"ltp":0.0,"tv":0.0,"id":424679},{"batb":[[0,1.23,5.86],[1,1.22,38.6],[2,1.21,40]],"ltp":0.0,"tv":0.0,"id":3961},{"batb":[[1,1.2,40],[2,1.14,27.04]],"ltp":0.0,"tv":0.0,"id":60443}]}]}
{"op":"mcm","clk":"11974421040","pt":1724751993395,"mc":[{"id":"1.232199708","rc":[{"batb":[[0,1.2,40],[1,1.14,27.04],[2,1.04,126.53]],"ltp":0.0,"tv":0.0,"id":60443}]}]}
{"op":"mcm","clk":"11974421053","pt":1724751993601,"mc":[{"id":"1.232199708","rc":[{"batb":[[0,1.2,40],[1,1.14,27.04],[2,1.04,126.53]],"ltp":0.0,"tv":0.0,"id":424679},{"batb":[[1,1.21,40],[2,1.15,27.04]],"ltp":0.0,"tv":0.0,"id":3961}]}]}
{"op":"mcm","clk":"11974428424","pt":1724752130738,"mc":[{"id":"1.232199708","rc":[{"batb":[[0,1.21,40.44],[1,1.2,40],[2,1.14,27.04]],"ltp":0.0,"tv":0.0,"id":424679},{"batb":[[0,1.24,35.39],[1,1.23,5.86],[2,1.21,40]],"ltp":0.0,"tv":0.0,"id":3961},{"batb":[[0,1.21,40.44],[1,1.2,40],[2,1.14,27.04]],"ltp":0.0,"tv":0.0,"id":60443}]}]}
{"op":"mcm","clk":"11974441512","pt":1724752367376,"mc":[{"id":"1.232199708","rc":[{"trd":[[1.21,1.94]],"batb":[[0,1.21,39.47]],"ltp":1.21,"tv":1.93,"id":424679}],"tv":1.93}]}
{"op":"mcm","clk":"11974530374","pt":1724753663005,"mc":[{"id":"1.232199708","rc":[{"trd":[[1.21,1.94]],"batb":[[0,1.22,7.16],[1,1.21,39.42],[2,1.2,40]],"batl":[[1,990,3.34]],"ltp":1.21,"tv":1.93,"id":424679},{"batb":[[0,1.24,35.34],[1,1.21,40],[2,1.15,27]],"batl":[[1,990,3.34]],"ltp":0.0,"tv":0.0,"id":3961},{"batb":[[0,1.22,6.22],[1,1.21,40.39],[2,1.2,40]],"batl":[[1,990,3.34]],"ltp":0.0,"tv":0.0,"id":60443}],"tv":1.93}]}
{"op":"mcm","clk":"11974549657","pt":1724753932302,"mc":[{"id":"1.232199708","rc":[{"batb":[[1,1.2,40],[2,1.14,27]],"ltp":1.21,"tv":1.93,"id":424679},{"batb":[[1,1.2,40],[2,1.14,27]],"ltp":0.0,"tv":0.0,"id":60443}]}]}
{"op":"mcm","clk":"11974549665","pt":1724753932509,"mc":[{"id":"1.232199708","rc":[{"batb":[[0,1.21,40],[1,1.15,27],[2,1.04,126.53]],"ltp":0.0,"tv":0.0,"id":3961}]}]}
{"op":"mcm","clk":"11974558788","pt":1724754067352,"mc":[{"id":"1.232199708","rc":[{"batb":[[0,1.22,38.56],[1,1.21,40],[2,1.15,27]],"ltp":0.0,"tv":0.0,"id":3961},{"batb":[[0,1.23,36.88],[1,1.22,6.22],[2,1.2,40]],"ltp":0.0,"tv":0.0,"id":60443}]}]}
{"op":"mcm","clk":"11974682362","pt":1724755867652,"mc":[{"id":"1.232199708","rc":[{"batb":[[0,1.21,40],[1,1.15,27],[2,1.04,126.53]],"ltp":0.0,"tv":0.0,"id":3961},{"batb":[[0,1.22,6.22],[1,1.2,40],[2,1.14,27]],"ltp":0.0,"tv":0.0,"id":60443}]}]}
{"op":"mcm","clk":"11974690495","pt":1724756002528,"mc":[{"id":"1.232199708","rc":[{"batb":[[0,1.22,38.56],[1,1.21,40],[2,1.15,27]],"ltp":0.0,"tv":0.0,"id":3961},{"batb":[[0,1.23,36.88],[1,1.22,6.22],[2,1.2,40]],"ltp":0.0,"tv":0.0,"id":60443}]}]}
{"op":"mcm","clk":"11974751581","pt":1724756986278,"mc":[{"id":"1.232199708","rc":[{"trd":[[1.21,1.94]],"batb":[[0,1.21,7.17],[2,1.14,27.04]],"batl":[[1,990,3.34]],"ltp":1.21,"tv":1.93,"id":424679},{"batb":[[0,1.23,6.05],[1,1.22,38.61],[2,1.21,40]],"batl":[[1,990,3.34]],"ltp":0.0,"tv":0.0,"id":3961},{"batb":[[0,1.24,6.23],[1,1.23,36.93]],"batl":[[1,990,3.34]],"ltp":0.0,"tv":0.0,"id":60443}],"tv":1.93}]}
{"op":"mcm","clk":"11974811113","pt":1724757803177,"mc":[{"id":"1.232199708","rc":[{"batb":[[1,1.21,40],[2,1.15,27.04]],"ltp":0.0,"tv":0.0,"id":3961},{"batb":[[1,1.2,40],[2,1.14,27.04]],"ltp":0.0,"tv":0.0,"id":60443}]}]}
{"op":"mcm","clk":"11974818395","pt":1724757926781,"mc":[{"id":"1.232199708","rc":[{"batb":[[0,1.24,35.39],[1,1.23,6.05],[2,1.21,40]],"ltp":0.0,"tv":0.0,"id":3961},{"batb":[[0,1.25,33.97],[1,1.24,6.23],[2,1.2,40]],"ltp":0.0,"tv":0.0,"id":60443}]}]}
{"op":"mcm","clk":"11974930944","pt":1724759727382,"mc":[{"id":"1.232199708","rc":[{"batb":[[0,1.23,6.05],[1,1.21,40],[2,1.15,27.04]],"ltp":0.0,"tv":0.0,"id":3961},{"batb":[[0,1.24,6.23],[1,1.2,40],[2,1.14,27.04]],"ltp":0.0,"tv":0.0,"id":60443}]}]}
{"op":"mcm","clk":"11974938107","pt":1724759840206,"mc":[{"id":"1.232199708","rc":[{"batb":[[0,1.24,35.39],[1,1.23,6.05],[2,1.21,40]],"ltp":0.0,"tv":0.0,"id":3961},{"batb":[[0,1.25,33.97],[1,1.24,6.23],[2,1.2,40]],"ltp":0.0,"tv":0.0,"id":60443}]}]}
{"op":"mcm","clk":"11974961850","pt":1724760157448,"mc":[{"id":"1.232199708","rc":[{"trd":[[1.21,1.94]],"batb":[[0,1.21,7.17],[1,1.14,27.02],[2,1.04,126.53]],"ltp":1.21,"tv":1.93,"id":424679},{"batb":[[0,1.24,35.36],[1,1.23,6.05],[2,1.15,27.02]],"ltp":0.0,"tv":0.0,"id":3961},{"batb":[[0,1.25,33.95],[1,1.24,6.22],[2,1.14,27.02]],"ltp":0.0,"tv":0.0,"id":60443}],"tv":1.93}]}
{"op":"mcm","clk":"11974961861","pt":1724760157553,"mc":[{"id":"1.232199708","rc":[{"batb":[[0,1.22,40],[1,1.21,7.17],[2,1.14,27.02]],"ltp":1.21,"tv":1.93,"id":424679},{"batb":[[0,1.25,40],[1,1.24,35.36],[2,1.23,6.05]],"ltp":0.0,"tv":0.0,"id":3961},{"batb":[[0,1.26,40],[1,1.25,33.95],[2,1.24,6.22]],"ltp":0.0,"tv":0.0,"id":60443}]}]}
{"op":"mcm","clk":"11974979959","pt":1724760385248,"mc":[{"id":"1.232199708","rc":[{"batb":[[1,1.14,27.02],[2,1.04,126.53]],"ltp":1.21,"tv":1.93,"id":424679},{"batb":[[2,1.15,27.02]],"ltp":0.0,"tv":0.0,"id":3961}]}]}
{"op":"mcm","clk":"11974979991","pt":1724760385515,"mc":[{"id":"1.232199708","rc":[{"batb":[[2,1.14,27.02]],"ltp":0.0,"tv":0.0,"id":60443}]}]}
{"op":"mcm","clk":"11975079028","pt":1724761641325,"mc":[{"id":"1.232199708","rc":[{"batb":[[1,1.15,27.02],[2,1.04,126.53]],"ltp":0.0,"tv":0.0,"id":3961},{"batb":[[1,1.14,27.02],[2,1.04,126.53]],"ltp":0.0,"tv":0.0,"id":60443}]}]}
{"op":"mcm","clk":"11975088328","pt":1724761743829,"mc":[{"id":"1.232199708","rc":[{"batb":[[0,1.26,32.64],[1,1.25,40],[2,1.15,27.02]],"ltp":0.0,"tv":0.0,"id":3961},{"batb":[[0,1.27,31.43],[1,1.26,40],[2,1.14,27.02]],"ltp":0.0,"tv":0.0,"id":60443}]}]}
{"op":"mcm","clk":"11975228517","pt":1724763544655,"mc":[{"id":"1.232199708","rc":[{"batb":[[0,1.25,40],[1,1.15,27.02],[2,1.04,126.53]],"ltp":0.0,"tv":0.0,"id":3961},{"batb":[[0,1.26,40],[1,1.14,27.02],[2,1.04,126.53]],"ltp":0.0,"tv":0.0,"id":60443}]}]}
{"op":"mcm","clk":"11975233988","pt":1724763632761,"mc":[{"id":"1.232199708","rc":[{"batb":[[1,1.14,27.02]],"ltp":1.21,"tv":1.93,"id":424679},{"batb":[[0,1.26,32.65],[1,1.25,40],[2,1.15,27.02]],"ltp":0.0,"tv":0.0,"id":3961},{"batb":[[0,1.27,31.44],[1,1.26,40],[2,1.14,27.02]],"ltp":0.0,"tv":0.0,"id":60443}]}]}
{"op":"mcm","clk":"11975384314","pt":1724765433174,"mc":[{"id":"1.232199708","rc":[{"batb":[[0,1.25,40],[1,1.15,27.02],[2,1.04,126.53]],"ltp":0.0,"tv":0.0,"id":3961},{"batb":[[0,1.26,40],[1,1.14,27.02],[2,1.04,126.53]],"ltp":0.0,"tv":0.0,"id":60443}]}]}
{"op":"mcm","clk":"11975388585","pt":1724765490438,"mc":[{"id":"1.232199708","rc":[{"batb":[[0,1.26,32.65],[1,1.25,40],[2,1.15,27.02]],"ltp":0.0,"tv":0.0,"id":3961},{"batb":[[0,1.27,31.44],[1,1.26,40],[2,1.14,27.02]],"ltp":0.0,"tv":0.0,"id":60443}]}]}
{"op":"mcm","clk":"11975550178","pt":1724767291359,"mc":[{"id":"1.232199708","rc":[{"trd":[[1.21,1.94]],"batb":[[1,1.14,27.02]],"ltp":1.21,"tv":1.93,"id":424679},{"batb":[[0,1.25,40],[1,1.15,27.02],[2,1.04,126.53]],"ltp":0.0,"tv":0.0,"id":3961},{"batb":[[0,1.26,40],[1,1.14,27.02],[2,1.04,126.53]],"ltp":0.0,"tv":0.0,"id":60443}],"tv":1.93}]}
{"op":"mcm","clk":"11975561011","pt":1724767444446,"mc":[{"id":"1.232199708","rc":[{"batb":[[0,1.26,32.64],[1,1.25,40],[2,1.15,27.02]],"ltp":0.0,"tv":0.0,"id":3961},{"batb":[[0,1.27,31.43],[1,1.26,40],[2,1.14,27.02]],"ltp":0.0,"tv":0.0,"id":60443}]}]}
{"op":"mcm","clk":"11975726078","pt":1724769245297,"mc":[{"id":"1.232199708","rc":[{"batb":[[0,1.25,40],[1,1.15,27.02],[2,1.04,126.53]],"ltp":0.0,"tv":0.0,"id":3961},{"batb":[[0,1.26,40],[1,1.14,27.02],[2,1.04,126.53]],"ltp":0.0,"tv":0.0,"id":60443}]}]}
{"op":"mcm","clk":"11975740203","pt":1724769394144,"mc":[{"id":"1.232199708","rc":[{"batb":[[0,1.26,32.64],[1,1.25,40],[2,1.15,27.02]],"ltp":0.0,"tv":0.0,"id":3961},{"batb":[[0,1.27,31.43],[1,1.26,40],[2,1.14,27.02]],"ltp":0.0,"tv":0.0,"id":60443}]}]}
{"op":"mcm","clk":"11975921617","pt":1724771194757,"mc":[{"id":"1.232199708","rc":[{"batb":[[1,1.14,27]],"ltp":1.21,"tv":1.93,"id":424679},{"batb":[[0,1.25,40],[1,1.15,27],[2,1.04,126.53]],"ltp":0.0,"tv":0.0,"id":3961},{"batb":[[0,1.26,40],[1,1.14,27],[2,1.04,126.53]],"ltp":0.0,"tv":0.0,"id":60443}]}]}
{"op":"mcm","clk":"11975935940","pt":1724771328297,"mc":[{"id":"1.232199708","rc":[{"batb":[[0,1.26,32.63],[1,1.25,40],[2,1.15,27]],"ltp":0.0,"tv":0.0,"id":3961},{"batb":[[0,1.27,31.42],[1,1.26,40],[2,1.14,27]],"ltp":0.0,"tv":0.0,"id":60443}]}]}
{"op":"mcm","clk":"11975965729","pt":1724771554989,"mc":[{"id":"1.232199708","rc":[{"batb":[[0,1.6,20],[1,1.22,40],[2,1.14,27]],"ltp":1.21,"tv":1.93,"id":424679}]}]}
{"op":"mcm","clk":"11975966769","pt":1724771563166,"mc":[{"id":"1.232199708","rc":[{"batb":[[0,2,20],[1,1.26,32.63],[2,1.25,40]],"ltp":0.0,"tv":0.0,"id":3961}]}]}
{"op":"mcm","clk":"11975967658","pt":1724771569798,"mc":[{"id":"1.232199708","rc":[{"batl":[[0,4.9,2],[1,95,2.67],[2,990,3.34]],"ltp":0.0,"tv":0.0,"id":60443}]}]}
{"op":"mcm","clk":"11976154278","pt":1724773128804,"mc":[{"id":"1.232199708","rc":[{"batb":[[1,1.25,40],[2,1.15,27]],"ltp":0.0,"tv":0.0,"id":3961},{"batb":[[0,1.26,40],[1,1.14,27],[2,1.04,126.53]],"ltp":0.0,"tv":0.0,"id":60443}]}]}
{"op":"mcm","clk":"11976167021","pt":1724773250173,"mc":[{"id":"1.232199708","rc":[{"batb":[[0,2.02,8.32],[1,2,20],[2,1.25,40]],"ltp":0.0,"tv":0.0,"id":3961},{"batb":[[0,1.27,31.42],[1,1.26,40],[2,1.14,27]],"ltp":0.0,"tv":0.0,"id":60443}]}]}
{"op":"mcm","clk":"11976312838","pt":1724774387692,"mc":[{"id":"1.232199708","rc":[{"batb":[[0,1.37,4.25],[1,1.27,31.42],[2,1.26,40]],"ltp":0.0,"tv":0.0,"id":60443}]}]}
{"op":"mcm","clk":"11976339690","pt":1724774628669,"mc":[{"id":"1.232199708","rc":[{"batb":[[1,1.14,26.99],[2,1.04,126.53]],"ltp":1.21,"tv":1.93,"id":424679},{"batb":[[0,2.02,8.31],[2,1.15,26.99]],"ltp":0.0,"tv":0.0,"id":3961},{"batb":[[1,1.27,31.4],[2,1.14,26.99]],"ltp":0.0,"tv":0.0,"id":60443}]}]}
{"op":"mcm","clk":"11976388173","pt":1724775050863,"mc":[{"id":"1.232199708","rc":[{"batb":[[0,2,20],[1,1.15,26.99],[2,1.04,126.53]],"ltp":0.0,"tv":0.0,"id":3961},{"batb":[[1,1.14,26.99],[2,1.04,126.53]],"ltp":0.0,"tv":0.0,"id":60443}]}]}
{"op":"mcm","clk":"11976401856","pt":1724775162602,"mc":[{"id":"1.232199708","rc":[{"batb":[[0,2.02,8.31],[1,2,20],[2,1.15,26.99]],"ltp":0.0,"tv":0.0,"id":3961},{"batb":[[0,1.38,22.31],[1,1.37,4.26],[2,1.14,26.99]],"ltp":0.0,"tv":0.0,"id":60443}]}]}
{"op":"mcm","clk":"11976619512","pt":1724776962727,"mc":[{"id":"1.232199708","rc":[{"batb":[[0,2,20],[1,1.15,26.99],[2,1.04,126.53]],"ltp":0.0,"tv":0.0,"id":3961}]}]}
{"op":"mcm","clk":"11976619625","pt":1724776963565,"mc":[{"id":"1.232199708","rc":[{"batb":[[0,1.37,4.26],[1,1.14,26.99],[2,1.04,126.53]],"ltp":0.0,"tv":0.0,"id":60443}]}]}
{"op":"mcm","clk":"11976632149","pt":1724777061050,"mc":[{"id":"1.232199708","rc":[{"batb":[[0,2.02,8.31],[1,2,20],[2,1.15,26.99]],"ltp":0.0,"tv":0.0,"id":3961},{"batb":[[0,1.38,22.31],[1,1.37,4.26],[2,1.14,26.99]],"ltp":0.0,"tv":0.0,"id":60443}]}]}
{"op":"mcm","clk":"11976862525","pt":1724778774834,"mc":[{"id":"1.232199708","rc":[{"batb":[[1,1.14,27]],"ltp":1.21,"tv":1.93,"id":424679},{"batb":[[0,2.02,8.32],[2,1.15,27]],"ltp":0.0,"tv":0.0,"id":3961},{"batb":[[0,1.38,22.33],[2,1.14,27]],"ltp":0.0,"tv":0.0,"id":60443}]}]}
{"op":"mcm","clk":"11976883292","pt":1724778861709,"mc":[{"id":"1.232199708","rc":[{"batb":[[0,2,20],[1,1.15,27],[2,1.04,126.53]],"ltp":0.0,"tv":0.0,"id":3961},{"batb":[[0,1.37,4.26],[1,1.14,27],[2,1.04,126.53]],"ltp":0.0,"tv":0.0,"id":60443}]}]}
{"op":"mcm","clk":"11976892709","pt":1724778932601,"mc":[{"id":"1.232199708","rc":[{"batb":[[0,2.02,8.32],[1,2,20],[2,1.15,27]],"ltp":0.0,"tv":0.0,"id":3961},{"batb":[[0,1.38,22.33],[1,1.37,4.26],[2,1.14,27]],"ltp":0.0,"tv":0.0,"id":60443}]}]}
{"op":"mcm","clk":"11977118237","pt":1724780733476,"mc":[{"id":"1.232199708","rc":[{"batb":[[0,1.37,4.26],[1,1.14,27],[2,1.04,126.53]],"ltp":0.0,"tv":0.0,"id":60443}]}]}
{"op":"mcm","clk":"11977118253","pt":1724780733582,"mc":[{"id":"1.232199708","rc":[{"batb":[[0,2,20],[1,1.15,27],[2,1.04,126.53]],"ltp":0.0,"tv":0.0,"id":3961}]}]}
{"op":"mcm","clk":"11977122713","pt":1724780765228,"mc":[{"id":"1.232199708","rc":[{"batb":[[0,2.02,8.32],[1,2,20],[2,1.15,27]],"ltp":0.0,"tv":0.0,"id":3961},{"batb":[[0,1.38,22.33],[1,1.37,4.26],[2,1.14,27]],"ltp":0.0,"tv":0.0,"id":60443}]}]}
{"op":"mcm","clk":"11977332968","pt":1724782566222,"mc":[{"id":"1.232199708","rc":[{"batb":[[1,1.14,27.01]],"ltp":1.21,"tv":1.93,"id":424679},{"batb":[[0,2,20],[1,1.15,27.01],[2,1.04,126.53]],"ltp":0.0,"tv":0.0,"id":3961},{"batb":[[0,1.37,4.25],[1,1.14,27.01],[2,1.04,126.53]],"ltp":0.0,"tv":0.0,"id":60443}]}]}
{"op":"mcm","clk":"11977333759","pt":1724782572713,"mc":[{"id":"1.232199708","rc":[{"batb":[[0,2.02,8.32],[1,2,20],[2,1.15,27.01]],"ltp":0.0,"tv":0.0,"id":3961},{"batb":[[0,1.38,22.33],[1,1.37,4.25],[2,1.14,27.01]],"ltp":0.0,"tv":0.0,"id":60443}]}]}
{"op":"mcm","clk":"11977577525","pt":1724784373122,"mc":[{"id":"1.232199708","rc":[{"batb":[[0,2,20],[1,1.15,27.01],[2,1.04,126.53]],"ltp":0.0,"tv":0.0,"id":3961},{"batb":[[0,1.37,4.25],[1,1.14,27.01],[2,1.04,126.53]],"ltp":0.0,"tv":0.0,"id":60443}]}]}
{"op":"mcm","clk":"11977602023","pt":1724784536686,"mc":[{"id":"1.232199708","rc":[{"batb":[[0,2.02,8.32],[1,2,20],[2,1.15,27.01]],"ltp":0.0,"tv":0.0,"id":3961},{"batb":[[0,1.38,22.33],[1,1.37,4.25],[2,1.14,27.01]],"ltp":0.0,"tv":0.0,"id":60443}]}]}
{"op":"mcm","clk":"11977656798","pt":1724784894891,"mc":[{"id":"1.232199708","rc":[{"batb":[[0,2.1,20],[1,2.02,8.32]],"ltp":0.0,"tv":0.0,"id":3961}]}]}
{"op":"mcm","clk":"11977865615","pt":1724786337187,"mc":[{"id":"1.232199708","rc":[{"trd":[[1.21,1.93]],"batb":[[1,1.14,27]],"ltp":1.21,"tv":1.93,"id":424679},{"batb":[[1,1.15,27],[2,1.04,126.53]],"ltp":0.0,"tv":0.0,"id":3961},{"batb":[[0,1.37,4.25],[1,1.14,27],[2,1.04,126.53]],"ltp":0.0,"tv":0.0,"id":60443}],"tv":1.93}]}
{"op":"mcm","clk":"11977882230","pt":1724786451606,"mc":[{"id":"1.232199708","rc":[{"batb":[[0,2.12,7.57],[1,2.1,20],[2,1.15,27]],"ltp":0.0,"tv":0.0,"id":3961},{"batb":[[0,1.38,22.32],[1,1.37,4.25],[2,1.14,27]],"ltp":0.0,"tv":0.0,"id":60443}]}]}
{"op":"mcm","clk":"11978127865","pt":1724788252078,"mc":[{"id":"1.232199708","rc":[{"batb":[[0,2.1,20],[1,1.15,27],[2,1.04,126.53]],"ltp":0.0,"tv":0.0,"id":3961},{"batb":[[0,1.37,4.25],[1,1.14,27],[2,1.04,126.53]],"ltp":0.0,"tv":0.0,"id":60443}]}]}
{"op":"mcm","clk":"11978139459","pt":1724788343891,"mc":[{"id":"1.232199708","rc":[{"batb":[[0,2.12,7.57],[1,2.1,20],[2,1.15,27]],"ltp":0.0,"tv":0.0,"id":3961},{"batb":[[0,1.38,22.32],[1,1.37,4.25],[2,1.14,27]],"ltp":0.0,"tv":0.0,"id":60443}]}]}
{"op":"mcm","clk":"11978310451","pt":1724789574818,"mc":[{"id":"1.232199708","rc":[{"batb":[[1,1.14,26.99]],"ltp":1.21,"tv":1.93,"id":424679},{"batb":[[0,2.12,7.57],[2,1.15,26.99]],"ltp":0.0,"tv":0.0,"id":3961},{"batb":[[0,1.38,22.31],[2,1.14,26.99]],"ltp":0.0,"tv":0.0,"id":60443}]}]}
{"op":"mcm","clk":"11978398419","pt":1724790144821,"mc":[{"id":"1.232199708","rc":[{"batb":[[0,2.1,20],[1,1.15,26.99],[2,1.04,126.53]],"ltp":0.0,"tv":0.0,"id":3961},{"batb":[[0,1.37,4.25],[1,1.14,26.99],[2,1.04,126.53]],"ltp":0.0,"tv":0.0,"id":60443}]}]}
{"op":"mcm","clk":"11978406468","pt":1724790204308,"mc":[{"id":"1.232199708","rc":[{"batb":[[0,2.12,7.57],[1,2.1,20],[2,1.15,26.99]],"ltp":0.0,"tv":0.0,"id":3961},{"batb":[[0,1.38,22.31],[1,1.37,4.25],[2,1.14,26.99]],"ltp":0.0,"tv":0.0,"id":60443}]}]}
{"op":"mcm","clk":"11978578572","pt":1724792005374,"mc":[{"id":"1.232199708","rc":[{"batb":[[0,1.37,4.25],[1,1.14,26.99],[2,1.04,126.53]],"ltp":0.0,"tv":0.0,"id":60443}]}]}
{"op":"mcm","clk":"11978578583","pt":1724792005580,"mc":[{"id":"1.232199708","rc":[{"batb":[[0,2.1,20],[1,1.15,26.99],[2,1.04,126.53]],"ltp":0.0,"tv":0.0,"id":3961}]}]}
{"op":"mcm","clk":"11978588478","pt":1724792161555,"mc":[{"id":"1.232199708","rc":[{"batb":[[0,2.12,7.57],[1,2.1,20],[2,1.15,26.99]],"ltp":0.0,"tv":0.0,"id":3961},{"batb":[[0,1.38,22.31],[1,1.37,4.25],[2,1.14,26.99]],"ltp":0.0,"tv":0.0,"id":60443}]}]}
{"op":"mcm","clk":"11978615231","pt":1724792669274,"mc":[{"id":"1.232199708","rc":[{"batb":[[0,2.16,20],[1,2.12,7.57]],"ltp":0.0,"tv":0.0,"id":3961}]}]}
{"op":"mcm","clk":"11978678211","pt":1724793962174,"mc":[{"id":"1.232199708","rc":[{"batb":[[1,1.15,26.99],[2,1.04,126.53]],"ltp":0.0,"tv":0.0,"id":3961},{"batb":[[0,1.37,4.25],[1,1.14,26.99],[2,1.04,126.53]],"ltp":0.0,"tv":0.0,"id":60443}]}]}
{"op":"mcm","clk":"11978681364","pt":1724794054057,"mc":[{"id":"1.232199708","rc":[{"batb":[[0,2.18,7.19],[1,2.16,20],[2,1.15,26.99]],"ltp":0.0,"tv":0.0,"id":3961},{"batb":[[0,1.38,22.31],[1,1.37,4.25],[2,1.14,26.99]],"ltp":0.0,"tv":0.0,"id":60443}]}]}
{"op":"mcm","clk":"11978769888","pt":1724795855161,"mc":[{"id":"1.232199708","rc":[{"batb":[[0,2.16,20],[1,1.15,26.99],[2,1.04,126.53]],"ltp":0.0,"tv":0.0,"id":3961},{"batb":[[0,1.37,4.25],[1,1.14,26.99],[2,1.04,126.53]],"ltp":0.0,"tv":0.0,"id":60443}]}]}
{"op":"mcm","clk":"11978773562","pt":1724795941891,"mc":[{"id":"1.232199708","rc":[{"batb":[[0,2.18,7.19],[1,2.16,20],[2,1.15,26.99]],"ltp":0.0,"tv":0.0,"id":3961},{"batb":[[0,1.38,22.31],[1,1.37,4.25],[2,1.14,26.99]],"ltp":0.0,"tv":0.0,"id":60443}]}]}
{"op":"mcm","clk":"11978777373","pt":1724796029571,"mc":[{"id":"1.232199708","rc":[{"batb":[[1,1.5,20],[2,1.14,27]],"ltp":1.21,"tv":1.93,"id":424679},{"batb":[[0,2.18,7.19],[2,1.15,27]],"ltp":0.0,"tv":0.0,"id":3961},{"batb":[[0,1.38,22.32],[1,1.37,4.25],[2,1.14,27]],"ltp":0.0,"tv":0.0,"id":60443}]}]}
{"op":"mcm","clk":"11978777732","pt":1724796038171,"mc":[{"id":"1.232199708","rc":[{"batb":[[2,1.5,20]],"ltp":0.0,"tv":0.0,"id":3961}]}]}
{"op":"mcm","clk":"11978778086","pt":1724796046918,"mc":[{"id":"1.232199708","rc":[{"batb":[[2,1.3,20]],"ltp":0.0,"tv":0.0,"id":60443}]}]}
{"op":"mcm","clk":"11978851212","pt":1724797742467,"mc":[{"id":"1.232199708","rc":[{"batb":[[0,2.16,20],[1,1.5,20],[2,1.15,27]],"ltp":0.0,"tv":0.0,"id":3961},{"batb":[[0,1.37,4.25],[1,1.3,20],[2,1.14,27]],"ltp":0.0,"tv":0.0,"id":60443}]}]}
{"op":"mcm","clk":"11978853021","pt":1724797798430,"mc":[{"id":"1.232199708","rc":[{"batb":[[0,2.18,7.19],[1,2.16,20],[2,1.5,20]],"ltp":0.0,"tv":0.0,"id":3961},{"batb":[[0,1.38,22.32],[1,1.37,4.25],[2,1.3,20]],"ltp":0.0,"tv":0.0,"id":60443}]}]}
{"op":"mcm","clk":"11978916726","pt":1724799199557,"mc":[{"id":"1.232199708","rc":[{"trd":[[1.6,0.14]],"batb":[[0,1.6,19.93]],"ltp":1.6,"tv":2.07,"id":424679}],"tv":2.07}]}
{"op":"mcm","clk":"11978937745","pt":1724799599370,"mc":[{"id":"1.232199708","rc":[{"batb":[[0,1.37,4.25],[1,1.3,20],[2,1.14,27]],"ltp":0.0,"tv":0.0,"id":60443}]}]}
{"op":"mcm","clk":"11978937755","pt":1724799599624,"mc":[{"id":"1.232199708","rc":[{"batb":[[0,2.16,20],[1,1.5,20],[2,1.15,27]],"ltp":0.0,"tv":0.0,"id":3961}]}]}
{"op":"mcm","clk":"11978939917","pt":1724799639613,"mc":[{"id":"1.232199708","rc":[{"batb":[[2,1.14,26.99]],"ltp":1.6,"tv":2.07,"id":424679},{"batb":[[0,2.18,7.19],[1,2.16,20],[2,1.5,20]],"ltp":0.0,"tv":0.0,"id":3961},{"batb":[[0,1.38,22.31],[1,1.37,4.25],[2,1.3,20]],"ltp":0.0,"tv":0.0,"id":60443}]}]}
{"op":"mcm","clk":"11979036313","pt":1724801440265,"mc":[{"id":"1.232199708","rc":[{"batb":[[0,2.16,20],[1,1.5,20],[2,1.15,26.99]],"ltp":0.0,"tv":0.0,"id":3961},{"batb":[[0,1.37,4.25],[1,1.3,20],[2,1.14,26.99]],"ltp":0.0,"tv":0.0,"id":60443}]}]}
{"op":"mcm","clk":"11979037260","pt":1724801464365,"mc":[{"id":"1.232199708","rc":[{"batb":[[0,2.18,7.19],[1,2.16,20],[2,1.5,20]],"ltp":0.0,"tv":0.0,"id":3961}]}]}
{"op":"mcm","clk":"11979037270","pt":1724801464574,"mc":[{"id":"1.232199708","rc":[{"batb":[[0,1.38,22.31],[1,1.37,4.25],[2,1.3,20]],"ltp":0.0,"tv":0.0,"id":60443}]}]}
{"op":"mcm","clk":"11979123485","pt":1724803265362,"mc":[{"id":"1.232199708","rc":[{"batb":[[2,1.14,26.98]],"ltp":1.6,"tv":2.07,"id":424679},{"batb":[[0,2.16,20],[1,1.5,20],[2,1.15,26.98]],"ltp":0.0,"tv":0.0,"id":3961},{"batb":[[0,1.37,4.25],[1,1.3,20],[2,1.14,26.98]],"ltp":0.0,"tv":0.0,"id":60443}]}]}
{"op":"mcm","clk":"11979124137","pt":1724803276553,"mc":[{"id":"1.232199708","rc":[{"batb":[[0,2.18,7.18],[1,2.16,20],[2,1.5,20]],"ltp":0.0,"tv":0.0,"id":3961},{"batb":[[0,1.38,22.31],[1,1.37,4.25],[2,1.3,20]],"ltp":0.0,"tv":0.0,"id":60443}]}]}
{"op":"mcm","clk":"11979218025","pt":1724805077032,"mc":[{"id":"1.232199708","rc":[{"batb":[[0,2.16,20],[1,1.5,20],[2,1.15,26.98]],"ltp":0.0,"tv":0.0,"id":3961},{"batb":[[0,1.37,4.25],[1,1.3,20],[2,1.14,26.98]],"ltp":0.0,"tv":0.0,"id":60443}]}]}
{"op":"mcm","clk":"11979226299","pt":1724805220375,"mc":[{"id":"1.232199708","rc":[{"batb":[[0,2.18,7.18],[1,2.16,20],[2,1.5,20]],"ltp":0.0,"tv":0.0,"id":3961},{"batb":[[0,1.38,22.31],[1,1.37,4.25],[2,1.3,20]],"ltp":0.0,"tv":0.0,"id":60443}]}]}
{"op":"mcm","clk":"11979296720","pt":1724806372970,"mc":[{"id":"1.232199708","rc":[{"trd":[[1.6,0.28]],"batb":[[0,1.6,19.86]],"ltp":1.6,"tv":2.21,"id":424679}],"tv":2.21}]}
{"op":"mcm","clk":"11979328492","pt":1724807020922,"mc":[{"id":"1.232199708","rc":[{"batb":[[0,2.16,20],[1,1.5,20],[2,1.15,26.98]],"ltp":0.0,"tv":0.0,"id":3961},{"batb":[[0,1.37,4.25],[1,1.3,20],[2,1.14,26.98]],"ltp":0.0,"tv":0.0,"id":60443}]}]}
{"op":"mcm","clk":"11979334585","pt":1724807144866,"mc":[{"id":"1.232199708","rc":[{"batb":[[0,2.18,7.18],[1,2.16,20],[2,1.5,20]],"ltp":0.0,"tv":0.0,"id":3961},{"batb":[[0,1.38,22.31],[1,1.37,4.25],[2,1.3,20]],"ltp":0.0,"tv":0.0,"id":60443}]}]}
{"op":"mcm","clk":"11979421835","pt":1724808945461,"mc":[{"id":"1.232199708","rc":[{"batb":[[0,2.16,20],[1,1.5,20],[2,1.15,26.98]],"ltp":0.0,"tv":0.0,"id":3961},{"batb":[[0,1.37,4.25],[1,1.3,20],[2,1.14,26.98]],"ltp":0.0,"tv":0.0,"id":60443}]}]}
{"op":"mcm","clk":"11979427097","pt":1724809057893,"mc":[{"id":"1.232199708","rc":[{"batb":[[0,2.18,7.18],[1,2.16,20],[2,1.5,20]],"ltp":0.0,"tv":0.0,"id":3961},{"batb":[[0,1.38,22.31],[1,1.37,4.25],[2,1.3,20]],"ltp":0.0,"tv":0.0,"id":60443}]}]}
{"op":"mcm","clk":"11979508929","pt":1724810858970,"mc":[{"id":"1.232199708","rc":[{"batb":[[2,1.14,26.98]],"ltp":1.6,"tv":2.21,"id":424679},{"batb":[[0,2.16,20],[1,1.5,20],[2,1.15,26.98]],"ltp":0.0,"tv":0.0,"id":3961},{"batb":[[0,1.37,4.25],[1,1.3,20],[2,1.14,26.98]],"ltp":0.0,"tv":0.0,"id":60443}]}]}
{"op":"mcm","clk":"11979511771","pt":1724810952469,"mc":[{"id":"1.232199708","rc":[{"batb":[[0,2.18,7.18],[1,2.16,20],[2,1.5,20]],"ltp":0.0,"tv":0.0,"id":3961},{"batb":[[0,1.38,22.31],[1,1.37,4.25],[2,1.3,20]],"ltp":0.0,"tv":0.0,"id":60443}]}]}
{"op":"mcm","clk":"11979568837","pt":1724812374266,"mc":[{"id":"1.232199708","rc":[{"trd":[[1.6,0.42]],"batb":[[0,1.6,19.79]],"ltp":1.6,"tv":2.35,"id":424679}],"tv":2.35}]}
{"op":"mcm","clk":"11979581674","pt":1724812753333,"mc":[{"id":"1.232199708","rc":[{"batb":[[0,2.16,20],[1,1.5,20],[2,1.15,26.98]],"ltp":0.0,"tv":0.0,"id":3961},{"batb":[[0,1.37,4.25],[1,1.3,20],[2,1.14,26.98]],"ltp":0.0,"tv":0.0,"id":60443}]}]}
{"op":"mcm","clk":"11979583720","pt":1724812821157,"mc":[{"id":"1.232199708","rc":[{"batb":[[0,2.18,7.18],[1,2.16,20],[2,1.5,20]],"ltp":0.0,"tv":0.0,"id":3961},{"batb":[[0,1.38,22.31],[1,1.37,4.25],[2,1.3,20]],"ltp":0.0,"tv":0.0,"id":60443}]}]}
{"op":"mcm","clk":"11979631074","pt":1724814622180,"mc":[{"id":"1.232199708","rc":[{"batb":[[2,1.14,26.98]],"ltp":1.6,"tv":2.35,"id":424679},{"batb":[[0,2.16,20],[1,1.5,20],[2,1.15,26.98]],"ltp":0.0,"tv":0.0,"id":3961},{"batb":[[0,1.37,4.25],[1,1.3,20],[2,1.14,26.98]],"ltp":0.0,"tv":0.0,"id":60443}]}]}
{"op":"mcm","clk":"11979632203","pt":1724814673965,"mc":[{"id":"1.232199708","rc":[{"batb":[[0,2.18,7.18],[1,2.16,20],[2,1.5,20]],"ltp":0.0,"tv":0.0,"id":3961},{"batb":[[0,1.38,22.31],[1,1.37,4.25],[2,1.3,20]],"ltp":0.0,"tv":0.0,"id":60443}]}]}
{"op":"mcm","clk":"11979674051","pt":1724816475033,"mc":[{"id":"1.232199708","rc":[{"batb":[[0,2.16,20],[1,1.5,20],[2,1.15,26.98]],"ltp":0.0,"tv":0.0,"id":3961},{"batb":[[0,1.37,4.25],[1,1.3,20],[2,1.14,26.98]],"ltp":0.0,"tv":0.0,"id":60443}]}]}
{"op":"mcm","clk":"11979674704","pt":1724816516764,"mc":[{"id":"1.232199708","rc":[{"batb":[[0,2.18,7.18],[1,2.16,20],[2,1.5,20]],"ltp":0.0,"tv":0.0,"id":3961},{"batb":[[0,1.38,22.31],[1,1.37,4.25],[2,1.3,20]],"ltp":0.0,"tv":0.0,"id":60443}]}]}
{"op":"mcm","clk":"11979728953","pt":1724818317409,"mc":[{"id":"1.232199708","rc":[{"batb":[[2,1.14,26.97]],"ltp":1.6,"tv":2.35,"id":424679},{"batb":[[0,2.16,20],[1,1.5,20],[2,1.15,26.97]],"ltp":0.0,"tv":0.0,"id":3961},{"batb":[[0,1.37,4.25],[1,1.3,20],[2,1.14,26.97]],"ltp":0.0,"tv":0.0,"id":60443}]}]}
{"op":"mcm","clk":"11979729770","pt":1724818344557,"mc":[{"id":"1.232199708","rc":[{"batb":[[0,2.18,7.18],[1,2.16,20],[2,1.5,20]],"ltp":0.0,"tv":0.0,"id":3961},{"batb":[[0,1.38,22.3],[1,1.37,4.25],[2,1.3,20]],"ltp":0.0,"tv":0.0,"id":60443}]}]}
{"op":"mcm","clk":"11979764993","pt":1724819670722,"mc":[{"id":"1.232199708","rc":[{"batb":[[0,1.38,22.79]],"ltp":0.0,"tv":0.0,"id":60443}]}]}
{"op":"mcm","clk":"11979773318","pt":1724820145183,"mc":[{"id":"1.232199708","rc":[{"batb":[[0,2.16,20],[1,1.5,20],[2,1.15,26.97]],"ltp":0.0,"tv":0.0,"id":3961},{"batb":[[0,1.37,4.74],[1,1.3,20],[2,1.14,26.97]],"ltp":0.0,"tv":0.0,"id":60443}]}]}
{"op":"mcm","clk":"11979773571","pt":1724820161217,"mc":[{"id":"1.232199708","rc":[{"batb":[[0,2.18,7.18],[1,2.16,20],[2,1.5,20]],"ltp":0.0,"tv":0.0,"id":3961},{"batb":[[0,1.38,22.79],[1,1.37,4.25],[2,1.3,20]],"ltp":0.0,"tv":0.0,"id":60443}]}]}
{"op":"mcm","clk":"11979821307","pt":1724821837732,"mc":[{"id":"1.232199708","rc":[{"batb":[[2,1.14,26.97]],"batl":[[0,1.9,1],[1,95,2.67],[2,990,3.34]],"ltp":1.6,"tv":2.35,"id":424679},{"batb":[[0,1.38,22.79],[1,1.37,4.25]],"ltp":0.0,"tv":0.0,"id":60443}]}]}
{"op":"mcm","clk":"11979821619","pt":1724821847312,"mc":[{"id":"1.232199708","rc":[{"batl":[[0,95,2.67],[1,990,3.34],[2,990,0]],"ltp":1.6,"tv":2.35,"id":424679}]}]}
{"op":"mcm","clk":"11979822033","pt":1724821860730,"mc":[{"id":"1.232199708","rc":[{"batl":[[0,1.9,1],[1,95,2.67],[2,990,3.34]],"ltp":1.6,"tv":2.35,"id":424679}]}]}
{"op":"mcm","clk":"11979822484","pt":1724821873950,"mc":[{"id":"1.232199708","rc":[{"batl":[[0,95,2.67],[1,990,3.34],[2,990,0]],"ltp":1.6,"tv":2.35,"id":424679}]}]}
{"op":"mcm","clk":"11979822894","pt":1724821885464,"mc":[{"id":"1.232199708","rc":[{"trd":[[90,0.34],[95,1.66]],"batl":[[0,95,1.67]],"ltp":95.0,"tv":4.35,"id":424679}],"tv":4.35}]}
{"op":"mcm","clk":"11979825804","pt":1724821962122,"mc":[{"id":"1.232199708","rc":[{"batb":[[0,2.16,20],[1,1.5,20],[2,1.15,26.97]],"ltp":0.0,"tv":0.0,"id":3961},{"batb":[[0,1.37,4.74],[1,1.3,20],[2,1.14,26.97]],"ltp":0.0,"tv":0.0,"id":60443}]}]}
{"op":"mcm","clk":"11979826002","pt":1724821967745,"mc":[{"id":"1.232199708","rc":[{"batb":[[0,2.18,7.18],[1,2.16,20],[2,1.5,20]],"ltp":0.0,"tv":0.0,"id":3961},{"batb":[[0,1.38,22.79],[1,1.37,4.25],[2,1.3,20]],"ltp":0.0,"tv":0.0,"id":60443}]}]}
{"op":"mcm","clk":"11979897399","pt":1724823750786,"mc":[{"id":"1.232199708","rc":[{"batl":[[0,95,2.51]],"ltp":95.0,"tv":4.35,"id":424679}]}]}
{"op":"mcm","clk":"11979897679","pt":1724823760889,"mc":[{"id":"1.232199708","rc":[{"batb":[[0,1.61,5.06],[1,1.6,19.79],[2,1.5,20]],"ltp":95.0,"tv":4.35,"id":424679}]}]}
{"op":"mcm","clk":"11979897917","pt":1724823768264,"mc":[{"id":"1.232199708","rc":[{"batb":[[0,2.16,20],[1,1.5,20],[2,1.15,26.97]],"ltp":0.0,"tv":0.0,"id":3961},{"batb":[[0,1.37,4.74],[1,1.3,20],[2,1.14,26.97]],"ltp":0.0,"tv":0.0,"id":60443}]}]}
{"op":"mcm","clk":"11979899353","pt":1724823823525,"mc":[{"id":"1.232199708","rc":[{"batb":[[2,1.04,126.53]],"ltp":0.0,"tv":0.0,"id":3961},{"batb":[[2,1.04,126.53]],"ltp":0.0,"tv":0.0,"id":60443}]}]}
{"op":"mcm","clk":"11979901373","pt":1724823904763,"mc":[{"id":"1.232199708","rc":[{"batb":[[0,2.18,7.18],[1,2.16,20],[2,1.5,20]],"ltp":0.0,"tv":0.0,"id":3961},{"batb":[[0,1.38,22.79],[1,1.37,4.25],[2,1.3,20]],"ltp":0.0,"tv":0.0,"id":60443}]}]}
{"op":"mcm","clk":"11979973126","pt":1724825705440,"mc":[{"id":"1.232199708","rc":[{"batb":[[0,1.61,5.05]],"ltp":95.0,"tv":4.35,"id":424679},{"batb":[[0,2.16,20],[1,1.5,20],[2,1.04,126.53]],"ltp":0.0,"tv":0.0,"id":3961},{"batb":[[0,1.38,22.78],[1,1.37,4.26]],"ltp":0.0,"tv":0.0,"id":60443}]}]}
{"op":"mcm","clk":"11979973134","pt":1724825705596,"mc":[{"id":"1.232199708","rc":[{"batb":[[0,1.37,4.75],[1,1.3,20],[2,1.04,126.53]],"ltp":0.0,"tv":0.0,"id":60443}]}]}
{"op":"mcm","clk":"11979980446","pt":1724825898438,"mc":[{"id":"1.232199708","rc":[{"batb":[[0,2.18,7.18],[1,2.16,20],[2,1.5,20]],"ltp":0.0,"tv":0.0,"id":3961},{"batb":[[0,1.38,22.78],[1,1.37,4.26],[2,1.3,20]],"ltp":0.0,"tv":0.0,"id":60443}]}]}
{"op":"mcm","clk":"11979993756","pt":1724826279475,"mc":[{"id":"1.232199708","rc":[{"batl":[[0,90,1.17],[1,95,2.5],[2,990,3.34]],"ltp":0.0,"tv":0.0,"id":3961}]}]}
{"op":"mcm","clk":"11979993980","pt":1724826285010,"mc":[{"id":"1.232199708","rc":[{"batl":[[0,90,1.84],[1,95,1.67],[2,990,3.34]],"ltp":95.0,"tv":4.35,"id":424679},{"batl":[[0,4.8,1],[1,4.9,2],[2,95,2.67]],"ltp":0.0,"tv":0.0,"id":60443}]}]}
{"op":"mcm","clk":"11980061676","pt":1724827698773,"mc":[{"id":"1.232199708","rc":[{"batb":[[0,2.16,20],[1,1.5,20],[2,1.04,126.53]],"ltp":0.0,"tv":0.0,"id":3961},{"batb":[[0,1.37,4.75],[1,1.3,20],[2,1.04,126.53]],"ltp":0.0,"tv":0.0,"id":60443}]}]}
{"op":"mcm","clk":"11980062289","pt":1724827710799,"mc":[{"id":"1.232199708","rc":[{"batb":[[0,2.18,7.18],[1,2.16,20],[2,1.5,20]],"ltp":0.0,"tv":0.0,"id":3961},{"batb":[[0,1.38,22.78],[1,1.37,4.26],[2,1.3,20]],"ltp":0.0,"tv":0.0,"id":60443}]}]}
{"op":"mcm","clk":"11980134337","pt":1724829511317,"mc":[{"id":"1.232199708","rc":[{"batb":[[0,1.61,5.06]],"ltp":95.0,"tv":4.35,"id":424679},{"batb":[[0,2.16,20],[1,1.5,20],[2,1.04,126.53]],"ltp":0.0,"tv":0.0,"id":3961},{"batb":[[0,1.38,22.79]],"ltp":0.0,"tv":0.0,"id":60443}]}]}
{"op":"mcm","clk":"11980134342","pt":1724829511521,"mc":[{"id":"1.232199708","rc":[{"batb":[[0,1.37,4.75],[1,1.3,20],[2,1.04,126.53]],"ltp":0.0,"tv":0.0,"id":60443}]}]}
{"op":"mcm","clk":"11980134821","pt":1724829525218,"mc":[{"id":"1.232199708","rc":[{"batb":[[0,2.18,7.18],[1,2.16,20],[2,1.5,20]],"ltp":0.0,"tv":0.0,"id":3961},{"batb":[[0,1.38,22.79],[1,1.37,4.26],[2,1.3,20]],"ltp":0.0,"tv":0.0,"id":60443}]}]}
{"op":"mcm","clk":"11980212740","pt":1724831325479,"mc":[{"id":"1.232199708","rc":[{"batb":[[0,1.37,4.75],[1,1.3,20],[2,1.04,126.53]],"ltp":0.0,"tv":0.0,"id":60443}]}]}
{"op":"mcm","clk":"11980212753","pt":1724831325683,"mc":[{"id":"1.232199708","rc":[{"batb":[[0,2.16,20],[1,1.5,20],[2,1.04,126.53]],"ltp":0.0,"tv":0.0,"id":3961}]}]}
{"op":"mcm","clk":"11980213464","pt":1724831342177,"mc":[{"id":"1.232199708","rc":[{"batb":[[0,2.18,7.18],[1,2.16,20],[2,1.5,20]],"ltp":0.0,"tv":0.0,"id":3961},{"batb":[[0,1.38,22.79],[1,1.37,4.26],[2,1.3,20]],"ltp":0.0,"tv":0.0,"id":60443}]}]}
{"op":"mcm","clk":"11980256526","pt":1724832293711,"mc":[{"id":"1.232199708","rc":[{"batb":[[0,1.61,5.06]],"ltp":95.0,"tv":4.35,"id":424679},{"batb":[[0,2.18,7.18]],"ltp":0.0,"tv":0.0,"id":3961},{"batb":[[0,1.38,22.31],[1,1.37,4.26]],"ltp":0.0,"tv":0.0,"id":60443}]}]}
{"op":"mcm","clk":"11980309729","pt":1724833142470,"mc":[{"id":"1.232199708","rc":[{"batb":[[0,1.37,4.26],[1,1.3,20],[2,1.04,126.53]],"ltp":0.0,"tv":0.0,"id":60443}]}]}
{"op":"mcm","clk":"11980309736","pt":1724833142675,"mc":[{"id":"1.232199708","rc":[{"batb":[[0,2.16,20],[1,1.5,20],[2,1.04,126.53]],"ltp":0.0,"tv":0.0,"id":3961}]}]}
{"op":"mcm","clk":"11980310194","pt":1724833150561,"mc":[{"id":"1.232199708","rc":[{"batb":[[0,2.18,7.18],[1,2.16,20],[2,1.5,20]],"ltp":0.0,"tv":0.0,"id":3961},{"batb":[[0,1.38,22.31],[1,1.37,4.26],[2,1.3,20]],"ltp":0.0,"tv":0.0,"id":60443}]}]}
{"op":"mcm","clk":"11980405770","pt":1724834950900,"mc":[{"id":"1.232199708","rc":[{"batb":[[0,2.16,20],[1,1.5,20],[2,1.04,126.53]],"ltp":0.0,"tv":0.0,"id":3961},{"batb":[[0,1.37,4.26],[1,1.3,20],[2,1.04,126.53]],"ltp":0.0,"tv":0.0,"id":60443}]}]}
{"op":"mcm","clk":"11980406145","pt":1724834957803,"mc":[{"id":"1.232199708","rc":[{"batb":[[0,2.18,7.18],[1,2.16,20],[2,1.5,20]],"ltp":0.0,"tv":0.0,"id":3961},{"batb":[[0,1.38,22.31],[1,1.37,4.26],[2,1.3,20]],"ltp":0.0,"tv":0.0,"id":60443}]}]}
{"op":"mcm","clk":"11980490057","pt":1724836442827,"mc":[{"id":"1.232199708","rc":[{"batb":[[0,1.61,5.05]],"ltp":95.0,"tv":4.35,"id":424679},{"batb":[[0,2.18,7.18]],"ltp":0.0,"tv":0.0,"id":3961},{"batb":[[0,1.38,22.29],[1,1.3,20],[2,1.04,126.53]],"ltp":0.0,"tv":0.0,"id":60443}]}]}
{"op":"mcm","clk":"11980506249","pt":1724836758443,"mc":[{"id":"1.232199708","rc":[{"batb":[[0,2.16,20],[1,1.5,20],[2,1.04,126.53]],"ltp":0.0,"tv":0.0,"id":3961},{"batb":[[0,1.3,20],[1,1.04,126.53],[2,1.03,200]],"ltp":0.0,"tv":0.0,"id":60443}]}]}
{"op":"mcm","clk":"11980506448","pt":1724836763460,"mc":[{"id":"1.232199708","rc":[{"batb":[[0,2.18,7.18],[1,2.16,20],[2,1.5,20]],"ltp":0.0,"tv":0.0,"id":3961},{"batb":[[0,1.31,27.32],[1,1.3,20],[2,1.04,126.53]],"ltp":0.0,"tv":0.0,"id":60443}]}]}
{"op":"mcm","clk":"11980553124","pt":1724837592106,"mc":[{"id":"1.232199708","rc":[{"batl":[[0,85,1.67],[1,90,1.84]],"ltp":95.0,"tv":4.35,"id":424679}]}]}
{"op":"mcm","clk":"11980553361","pt":1724837595593,"mc":[{"id":"1.232199708","rc":[{"batl":[[1,160,1.01],[2,990,3.17]],"ltp":95.0,"tv":4.35,"id":424679}]}]}
{"op":"mcm","clk":"11980553729","pt":1724837601110,"mc":[{"id":"1.232199708","rc":[{"batl":[[0,80,1],[1,85,1.67],[2,160,1.01]],"ltp":95.0,"tv":4.35,"id":424679}]}]}
{"op":"mcm","clk":"11980554002","pt":1724837605027,"mc":[{"id":"1.232199708","rc":[{"batb":[[0,1.89,41.72],[1,1.61,5.05],[2,1.6,19.79]],"ltp":95.0,"tv":4.35,"id":424679}]}]}
{"op":"mcm","clk":"11980620456","pt":1724838539373,"mc":[{"id":"1.232199708","rc":[{"batb":[[0,1.61,5.05],[1,1.6,19.79],[2,1.5,20]],"ltp":95.0,"tv":4.35,"id":424679}]}]}
{"op":"mcm","clk":"11980620717","pt":1724838544124,"mc":[{"id":"1.232199708","rc":[{"batb":[[0,2.5,31.54],[1,1.61,5.05],[2,1.6,19.79]],"ltp":95.0,"tv":4.35,"id":424679}]}]}
{"op":"mcm","clk":"11980621262","pt":1724838553310,"mc":[{"id":"1.232199708","rc":[{"batl":[[0,75,1.67],[1,80,1]],"ltp":95.0,"tv":4.35,"id":424679}]}]}
{"op":"mcm","clk":"11980621563","pt":1724838559079,"mc":[{"id":"1.232199708","rc":[{"batl":[[1,160,1.01],[2,990,3.17]],"ltp":95.0,"tv":4.35,"id":424679}]}]}
{"op":"mcm","clk":"11980621858","pt":1724838563927,"mc":[{"id":"1.232199708","rc":[{"batb":[[0,2.16,20],[1,1.5,20],[2,1.04,126.53]],"ltp":0.0,"tv":0.0,"id":3961},{"batb":[[0,1.3,20],[1,1.04,126.53],[2,1.03,200]],"ltp":0.0,"tv":0.0,"id":60443}]}]}
{"op":"mcm","clk":"11980621906","pt":1724838564603,"mc":[{"id":"1.232199708","rc":[{"batl":[[0,70,1],[1,75,1.67],[2,160,1.01]],"ltp":95.0,"tv":4.35,"id":424679}]}]}
{"op":"mcm","clk":"11980634387","pt":1724838747780,"mc":[{"id":"1.232199708","rc":[{"batb":[[0,2.18,7.18],[1,2.16,20],[2,1.5,20]],"ltp":0.0,"tv":0.0,"id":3961},{"batb":[[0,1.31,27.32],[1,1.3,20],[2,1.04,126.53]],"ltp":0.0,"tv":0.0,"id":60443}]}]}
{"op":"mcm","clk":"11980700753","pt":1724839759714,"mc":[{"id":"1.232199708","rc":[{"batb":[[1,1.61,5.05]],"ltp":95.0,"tv":4.35,"id":424679},{"batb":[[0,2.18,7.17]],"ltp":0.0,"tv":0.0,"id":3961},{"batb":[[0,1.7,35],[1,1.31,27.31],[2,1.3,20]],"ltp":0.0,"tv":0.0,"id":60443}]}]}
{"op":"mcm","clk":"11980701663","pt":1724839773521,"mc":[{"id":"1.232199708","rc":[{"batl":[[0,15,7],[1,70,1],[2,75,1.67]],"ltp":95.0,"tv":4.35,"id":424679},{"batl":[[0,11,9],[1,90,1.17],[2,95,2.5]],"ltp":0.0,"tv":0.0,"id":3961}]}]}
{"op":"mcm","clk":"11980701988","pt":1724839778806,"mc":[{"id":"1.232199708","rc":[{"batl":[[1,75,1.67],[2,160,1.01]],"ltp":95.0,"tv":4.35,"id":424679},{"batl":[[1,95,2.67],[2,990,3.34]],"ltp":0.0,"tv":0.0,"id":3961}]}]}
{"op":"mcm","clk":"11980702350","pt":1724839784322,"mc":[{"id":"1.232199708","rc":[{"batl":[[0,14.5,1],[1,15,7],[2,75,1.67]],"ltp":95.0,"tv":4.35,"id":424679},{"batl":[[0,10.5,1],[1,11,9],[2,95,2.67]],"ltp":0.0,"tv":0.0,"id":3961}]}]}
{"op":"mcm","clk":"11980752189","pt":1724840548356,"mc":[{"id":"1.232199708","rc":[{"batb":[[0,2.16,20],[1,1.5,20],[2,1.04,126.53]],"ltp":0.0,"tv":0.0,"id":3961},{"batb":[[1,1.3,20],[2,1.04,126.53]],"ltp":0.0,"tv":0.0,"id":60443}]}]}
{"op":"mcm","clk":"11980762459","pt":1724840715386,"mc":[{"id":"1.232199708","rc":[{"batb":[[0,2.18,7.17],[1,2.16,20],[2,1.5,20]],"ltp":0.0,"tv":0.0,"id":3961},{"batb":[[0,1.71,11.92],[1,1.7,35],[2,1.3,20]],"ltp":0.0,"tv":0.0,"id":60443}]}]}
{"op":"mcm","clk":"11980814514","pt":1724841421320,"mc":[{"id":"1.232199708","rc":[{"batl":[[1,75,1.67],[2,160,1.01]],"ltp":95.0,"tv":4.35,"id":424679},{"batl":[[1,95,2.67],[2,990,3.34]],"ltp":0.0,"tv":0.0,"id":3961},{"batb":[[1,1.3,20],[2,1.04,126.53]],"ltp":0.0,"tv":0.0,"id":60443}]}]}
{"op":"mcm","clk":"11980883716","pt":1724842516045,"mc":[{"id":"1.232199708","rc":[{"batb":[[0,2.16,20],[1,1.5,20],[2,1.04,126.53]],"ltp":0.0,"tv":0.0,"id":3961},{"batb":[[0,1.3,20],[1,1.04,126.53],[2,1.03,200]],"ltp":0.0,"tv":0.0,"id":60443}]}]}
{"op":"mcm","clk":"11980892715","pt":1724842649502,"mc":[{"id":"1.232199708","rc":[{"batl":[[0,14.5,1.01]],"ltp":95.0,"tv":4.35,"id":424679}]}]}
{"op":"mcm","clk":"11980893827","pt":1724842667006,"mc":[{"id":"1.232199708","rc":[{"batb":[[0,2.18,7.17],[1,2.16,20],[2,1.5,20]],"ltp":0.0,"tv":0.0,"id":3961},{"batb":[[0,1.31,27.31],[1,1.3,20],[2,1.04,126.53]],"ltp":0.0,"tv":0.0,"id":60443}]}]}
{"op":"mcm","clk":"11980904580","pt":1724842816673,"mc":[{"id":"1.232199708","rc":[{"trd":[[2.64,0.01]],"batb":[[1,1.61,5.05]],"batl":[[0,14.5,1]],"ltp":2.64,"tv":4.36,"id":424679},{"batb":[[0,2.18,7.17]],"ltp":0.0,"tv":0.0,"id":3961},{"trd":[[1.9,0.01]],"batb":[[0,1.31,27.3]],"ltp":1.9,"tv":0.0,"id":60443}],"tv":4.37}]}
{"op":"mcm","clk":"11981000450","pt":1724844061281,"mc":[{"id":"1.232199708","rc":[{"batb":[[0,1.31,27.99]],"ltp":1.9,"tv":0.0,"id":60443}]}]}
{"op":"mcm","clk":"11981013481","pt":1724844301843,"mc":[{"id":"1.232199708","rc":[{"batl":[[0,2.7,1],[1,4.8,1],[2,4.9,2]],"ltp":1.9,"tv":0.0,"id":60443}]}]}
{"op":"mcm","clk":"11981013737","pt":1724844306234,"mc":[{"id":"1.232199708","rc":[{"batl":[[1,4.9,2],[2,95,2.67]],"ltp":1.9,"tv":0.0,"id":60443}]}]}
{"op":"mcm","clk":"11981014052","pt":1724844311734,"mc":[{"id":"1.232199708","rc":[{"batl":[[0,2.68,1],[1,2.7,1],[2,4.9,2]],"ltp":1.9,"tv":0.0,"id":60443}]}]}
{"op":"mcm","clk":"11981014557","pt":1724844321656,"mc":[{"id":"1.232199708","rc":[{"batl":[[0,2.66,1],[1,2.68,1]],"ltp":1.9,"tv":0.0,"id":60443}]}]}
{"op":"mcm","clk":"11981014618","pt":1724844322955,"mc":[{"id":"1.232199708","rc":[{"batl":[[1,4.9,2],[2,95,2.67]],"ltp":1.9,"tv":0.0,"id":60443}]}]}
{"op":"mcm","clk":"11981014878","pt":1724844328367,"mc":[{"id":"1.232199708","rc":[{"batl":[[0,2.64,1],[1,2.66,1],[2,4.9,2]],"ltp":1.9,"tv":0.0,"id":60443}]}]}
{"op":"mcm","clk":"11981015001","pt":1724844330754,"mc":[{"id":"1.232199708","rc":[{"batl":[[0,2.62,1],[1,2.64,1]],"ltp":1.9,"tv":0.0,"id":60443}]}]}
{"op":"mcm","clk":"11981015476","pt":1724844339683,"mc":[{"id":"1.232199708","rc":[{"batl":[[1,4.9,2],[2,95,2.67]],"ltp":1.9,"tv":0.0,"id":60443}]}]}
{"op":"mcm","clk":"11981016372","pt":1724844356893,"mc":[{"id":"1.232199708","rc":[{"batl":[[0,2.66,1]],"ltp":1.9,"tv":0.0,"id":60443}]}]}
{"op":"mcm","clk":"11981016652","pt":1724844361905,"mc":[{"id":"1.232199708","rc":[{"batl":[[0,2.64,1],[1,2.66,1],[2,4.9,2]],"ltp":1.9,"tv":0.0,"id":60443}]}]}
{"op":"mcm","clk":"11981016831","pt":1724844364928,"mc":[{"id":"1.232199708","rc":[{"trd":[[2.64,2]],"batl":[[0,2.66,1],[1,4.9,2],[2,95,2.67]],"ltp":2.64,"tv":2.0,"id":60443}],"tv":6.37}]}
{"op":"mcm","clk":"11981017198","pt":1724844373030,"mc":[{"id":"1.232199708","rc":[{"batb":[[0,1.32,2.69],[1,1.31,27.3],[2,1.3,20]],"ltp":2.64,"tv":2.0,"id":60443}]}]}
{"op":"mcm","clk":"11981017810","pt":1724844384153,"mc":[{"id":"1.232199708","rc":[{"batl":[[0,2.64,1],[1,2.66,1],[2,4.9,2]],"ltp":2.64,"tv":2.0,"id":60443}]}]}
{"op":"mcm","clk":"11981018003","pt":1724844388027,"mc":[{"id":"1.232199708","rc":[{"trd":[[2.64,4]],"batl":[[0,2.66,1],[1,4.9,2],[2,95,2.67]],"ltp":2.64,"tv":4.0,"id":60443}],"tv":8.37}]}
{"op":"mcm","clk":"11981018215","pt":1724844391511,"mc":[{"id":"1.232199708","rc":[{"batl":[[0,4.9,2],[1,95,2.67],[2,990,3.34]],"ltp":2.64,"tv":4.0,"id":60443}]}]}
{"op":"mcm","clk":"11981022612","pt":1724844467303,"mc":[{"id":"1.232199708","rc":[{"batb":[[0,2.16,20],[1,1.5,20],[2,1.04,126.53]],"ltp":0.0,"tv":0.0,"id":3961}]}]}
{"op":"mcm","clk":"11981022625","pt":1724844467612,"mc":[{"id":"1.232199708","rc":[{"batb":[[1,1.3,20],[2,1.04,126.53]],"ltp":2.64,"tv":4.0,"id":60443}]}]}
{"op":"mcm","clk":"11981027113","pt":1724844549625,"mc":[{"id":"1.232199708","rc":[{"batb":[[0,2.18,7.17],[1,2.16,20],[2,1.5,20]],"ltp":0.0,"tv":0.0,"id":3961},{"batb":[[0,1.33,25.64],[1,1.32,2.69],[2,1.3,20]],"ltp":2.64,"tv":4.0,"id":60443}]}]}
{"op":"mcm","clk":"11981027183","pt":1724844551077,"mc":[{"id":"1.232199708","rc":[{"batb":[[1,1.3,20.69],[2,1.04,126.53]],"ltp":2.64,"tv":4.0,"id":60443}]}]}
{"op":"mcm","clk":"11981027552","pt":1724844556788,"mc":[{"id":"1.232199708","rc":[{"batb":[[0,1.34,3.94],[1,1.33,25.64],[2,1.3,20.69]],"ltp":2.64,"tv":4.0,"id":60443}]}]}
{"op":"mcm","clk":"11981136302","pt":1724846350190,"mc":[{"id":"1.232199708","rc":[{"batb":[[0,2.16,20],[1,1.5,20],[2,1.04,126.53]],"ltp":0.0,"tv":0.0,"id":3961},{"batb":[[1,1.3,20.69],[2,1.04,126.53]],"ltp":2.64,"tv":4.0,"id":60443}]}]}
{"op":"mcm","clk":"11981141654","pt":1724846447087,"mc":[{"id":"1.232199708","rc":[{"batb":[[0,2.18,7.17],[1,2.16,20],[2,1.5,20]],"ltp":0.0,"tv":0.0,"id":3961},{"batb":[[0,1.35,24.19],[1,1.34,3.94],[2,1.3,20.69]],"ltp":2.64,"tv":4.0,"id":60443}]}]}
{"op":"mcm","clk":"11981141776","pt":1724846450064,"mc":[{"id":"1.232199708","rc":[{"batb":[[1,1.3,20.69],[2,1.04,126.53]],"ltp":2.64,"tv":4.0,"id":60443}]}]}
{"op":"mcm","clk":"11981142901","pt":1724846472321,"mc":[{"id":"1.232199708","rc":[{"batb":[[0,1.36,3.88],[1,1.35,24.19],[2,1.3,20.69]],"ltp":2.64,"tv":4.0,"id":60443}]}]}
{"op":"mcm","clk":"11981240657","pt":1724848247480,"mc":[{"id":"1.232199708","rc":[{"batb":[[0,2.16,20],[1,1.5,20],[2,1.04,126.53]],"ltp":0.0,"tv":0.0,"id":3961},{"batb":[[1,1.3,20.69],[2,1.04,126.53]],"ltp":2.64,"tv":4.0,"id":60443}]}]}
{"op":"mcm","clk":"11981245097","pt":1724848329415,"mc":[{"id":"1.232199708","rc":[{"batb":[[0,2.18,7.17],[1,2.16,20],[2,1.5,20]],"ltp":0.0,"tv":0.0,"id":3961},{"batb":[[0,1.37,22.88],[1,1.36,3.88],[2,1.3,20.69]],"ltp":2.64,"tv":4.0,"id":60443}]}]}
{"op":"mcm","clk":"11981245286","pt":1724848332209,"mc":[{"id":"1.232199708","rc":[{"batb":[[1,1.3,20.69],[2,1.04,126.53]],"ltp":2.64,"tv":4.0,"id":60443}]}]}
{"op":"mcm","clk":"11981246395","pt":1724848354580,"mc":[{"id":"1.232199708","rc":[{"batb":[[0,1.38,3.83],[1,1.37,22.88],[2,1.3,20.69]],"ltp":2.64,"tv":4.0,"id":60443}]}]}
{"op":"mcm","clk":"11981264386","pt":1724848659759,"mc":[{"id":"1.232199708","rc":[{"batl":[[1,95,2.51],[2,990,3.34]],"ltp":2.64,"tv":4.36,"id":424679}]}]}
{"op":"mcm","clk":"11981353276","pt":1724850129866,"mc":[{"id":"1.232199708","rc":[{"batb":[[1,1.61,5.05]],"ltp":2.64,"tv":4.36,"id":424679},{"batb":[[0,2.16,20],[1,1.5,20],[2,1.04,126.53]],"ltp":0.0,"tv":0.0,"id":3961},{"batb":[[1,1.3,20.69],[2,1.04,126.53]],"ltp":2.64,"tv":4.0,"id":60443}],"tv":8.37}]}
{"op":"mcm","clk":"11981356465","pt":1724850200184,"mc":[{"id":"1.232199708","rc":[{"batb":[[0,2.18,7.17],[1,2.16,20],[2,1.5,20]],"ltp":0.0,"tv":0.0,"id":3961},{"batb":[[0,1.39,21.69],[1,1.38,3.83],[2,1.3,20.69]],"ltp":2.64,"tv":4.0,"id":60443}]}]}
{"op":"mcm","clk":"11981356589","pt":1724850203371,"mc":[{"id":"1.232199708","rc":[{"batb":[[1,1.3,20.69],[2,1.04,126.53]],"ltp":2.64,"tv":4.0,"id":60443}]}]}
{"op":"mcm","clk":"11981357639","pt":1724850225710,"mc":[{"id":"1.232199708","rc":[{"batb":[[0,1.4,3.77],[1,1.39,21.69],[2,1.3,20.69]],"ltp":2.64,"tv":4.0,"id":60443}]}]}
{"op":"mcm","clk":"11981449939","pt":1724852000772,"mc":[{"id":"1.232199708","rc":[{"batb":[[0,2.16,20],[1,1.5,20],[2,1.04,126.53]],"ltp":0.0,"tv":0.0,"id":3961},{"batb":[[1,1.3,20.69],[2,1.04,126.53]],"ltp":2.64,"tv":4.0,"id":60443}]}]}
{"op":"mcm","clk":"11981453216","pt":1724852058729,"mc":[{"id":"1.232199708","rc":[{"batb":[[0,2.18,7.17],[1,2.16,20],[2,1.5,20]],"ltp":0.0,"tv":0.0,"id":3961},{"batb":[[0,1.41,20.63],[1,1.4,3.77],[2,1.3,20.69]],"ltp":2.64,"tv":4.0,"id":60443}]}]}
{"op":"mcm","clk":"11981453470","pt":1724852063554,"mc":[{"id":"1.232199708","rc":[{"batb":[[1,1.3,20.69],[2,1.04,126.53]],"ltp":2.64,"tv":4.0,"id":60443}]}]}
{"op":"mcm","clk":"11981455761","pt":1724852102581,"mc":[{"id":"1.232199708","rc":[{"batb":[[0,1.42,3.72],[1,1.41,20.63],[2,1.3,20.69]],"ltp":2.64,"tv":4.0,"id":60443}]}]}
{"op":"mcm","clk":"11981560923","pt":1724853859474,"mc":[{"id":"1.232199708","rc":[{"trd":[[1.21,1.94]],"batb":[[1,1.61,5.05]],"ltp":2.64,"tv":4.36,"id":424679},{"batb":[[0,2.18,7.18]],"ltp":0.0,"tv":0.0,"id":3961},{"batb":[[1,1.3,20.69],[2,1.04,126.53]],"ltp":2.64,"tv":4.0,"id":60443}],"tv":8.37}]}
{"op":"mcm","clk":"11981560931","pt":1724853859573,"mc":[{"id":"1.232199708","rc":[{"batb":[[0,2.16,20],[1,1.5,20],[2,1.04,126.53]],"ltp":0.0,"tv":0.0,"id":3961}]}]}
{"op":"mcm","clk":"11981563826","pt":1724853907909,"mc":[{"id":"1.232199708","rc":[{"batb":[[0,2.18,7.18],[1,2.16,20],[2,1.5,20]],"ltp":0.0,"tv":0.0,"id":3961},{"batb":[[0,1.43,19.69],[1,1.42,3.72],[2,1.3,20.69]],"ltp":2.64,"tv":4.0,"id":60443}]}]}
{"op":"mcm","clk":"11981564133","pt":1724853912325,"mc":[{"id":"1.232199708","rc":[{"batb":[[1,1.3,20.69],[2,1.04,126.53]],"ltp":2.64,"tv":4.0,"id":60443}]}]}
{"op":"mcm","clk":"11981566111","pt":1724853945832,"mc":[{"id":"1.232199708","rc":[{"batb":[[0,1.44,3.67],[1,1.43,19.69],[2,1.3,20.69]],"ltp":2.64,"tv":4.0,"id":60443}]}]}
{"op":"mcm","clk":"11981684836","pt":1724855609699,"mc":[{"id":"1.232199708","rc":[{"batb":[[0,1.46,3.4],[1,1.44,3.67],[2,1.43,19.69]],"ltp":2.64,"tv":4.0,"id":60443}]}]}
{"op":"mcm","clk":"11981684938","pt":1724855610940,"mc":[{"id":"1.232199708","rc":[{"batb":[[1,1.43,19.69],[2,1.3,20.69]],"ltp":2.64,"tv":4.0,"id":60443}]}]}
{"op":"mcm","clk":"11981685440","pt":1724855616413,"mc":[{"id":"1.232199708","rc":[{"batb":[[0,1.47,3.59],[1,1.46,3.4],[2,1.43,19.69]],"ltp":2.64,"tv":4.0,"id":60443}]}]}
{"op":"mcm","clk":"11981686547","pt":1724855629847,"mc":[{"id":"1.232199708","rc":[{"batb":[[0,1.49,3.4],[1,1.47,3.59]],"ltp":2.64,"tv":4.0,"id":60443}]}]}
{"op":"mcm","clk":"11981686848","pt":1724855633164,"mc":[{"id":"1.232199708","rc":[{"batb":[[1,1.43,19.69],[2,1.3,20.69]],"ltp":2.64,"tv":4.0,"id":60443}]}]}
{"op":"mcm","clk":"11981687394","pt":1724855638768,"mc":[{"id":"1.232199708","rc":[{"batb":[[0,1.5,3.52],[1,1.49,3.4],[2,1.43,19.69]],"ltp":2.64,"tv":4.0,"id":60443}]}]}
{"op":"mcm","clk":"11981693632","pt":1724855708413,"mc":[{"id":"1.232199708","rc":[{"batb":[[0,2.16,20],[1,1.5,20],[2,1.04,126.53]],"ltp":0.0,"tv":0.0,"id":3961},{"batb":[[2,1.3,20.69]],"ltp":2.64,"tv":4.0,"id":60443}]}]}
{"op":"mcm","clk":"11981698352","pt":1724855756786,"mc":[{"id":"1.232199708","rc":[{"batb":[[0,2.18,7.18],[1,2.16,20],[2,1.5,20]],"ltp":0.0,"tv":0.0,"id":3961},{"batb":[[0,1.51,16.6],[1,1.5,3.52],[2,1.49,3.4]],"ltp":2.64,"tv":4.0,"id":60443}]}]}
{"op":"mcm","clk":"11981698796","pt":1724855761384,"mc":[{"id":"1.232199708","rc":[{"batb":[[1,1.49,3.4],[2,1.3,20.69]],"ltp":2.64,"tv":4.0,"id":60443}]}]}
{"op":"mcm","clk":"11981702207","pt":1724855794704,"mc":[{"id":"1.232199708","rc":[{"batb":[[0,1.52,3.47],[1,1.51,16.6],[2,1.49,3.4]],"ltp":2.64,"tv":4.0,"id":60443}]}]}
{"op":"mcm","clk":"11981864179","pt":1724857557929,"mc":[{"id":"1.232199708","rc":[{"batb":[[1,1.61,5.05]],"ltp":2.64,"tv":4.36,"id":424679},{"batb":[[0,2.16,20],[1,1.5,20],[2,1.04,126.53]],"ltp":0.0,"tv":0.0,"id":3961},{"batb":[[1,1.49,3.4],[2,1.3,20.69]],"ltp":2.64,"tv":4.0,"id":60443}]}]}
{"op":"mcm","clk":"11981866661","pt":1724857583192,"mc":[{"id":"1.232199708","rc":[{"batb":[[0,2.18,7.18],[1,2.16,20],[2,1.5,20]],"ltp":0.0,"tv":0.0,"id":3961},{"batb":[[0,1.53,15.98],[1,1.52,3.47],[2,1.49,3.4]],"ltp":2.64,"tv":4.0,"id":60443}]}]}
{"op":"mcm","clk":"11981867562","pt":1724857593486,"mc":[{"id":"1.232199708","rc":[{"batb":[[1,1.49,3.4],[2,1.3,20.69]],"ltp":2.64,"tv":4.0,"id":60443}]}]}
{"op":"mcm","clk":"11981871215","pt":1724857632457,"mc":[{"id":"1.232199708","rc":[{"batb":[[0,1.54,3.43],[1,1.53,15.98],[2,1.49,3.4]],"ltp":2.64,"tv":4.0,"id":60443}]}]}
{"op":"mcm","clk":"11981884615","pt":1724857766789,"mc":[{"id":"1.232199708","rc":[{"batb":[[0,1.57,3.4],[1,1.54,3.43],[2,1.53,15.98]],"ltp":2.64,"tv":4.0,"id":60443}]}]}
{"op":"mcm","clk":"11981885599","pt":1724857777284,"mc":[{"id":"1.232199708","rc":[{"batb":[[1,1.53,15.98],[2,1.3,20.69]],"ltp":2.64,"tv":4.0,"id":60443}]}]}
{"op":"mcm","clk":"11981886076","pt":1724857782819,"mc":[{"id":"1.232199708","rc":[{"batb":[[0,1.58,3.34],[1,1.57,3.4],[2,1.53,15.98]],"ltp":2.64,"tv":4.0,"id":60443}]}]}
{"op":"mcm","clk":"11982053807","pt":1724859383908,"mc":[{"id":"1.232199708","rc":[{"batb":[[0,2.16,20],[1,1.5,20],[2,1.04,126.53]],"ltp":0.0,"tv":0.0,"id":3961},{"batb":[[2,1.3,20.69]],"ltp":2.64,"tv":4.0,"id":60443}]}]}
{"op":"mcm","clk":"11982055244","pt":1724859396911,"mc":[{"id":"1.232199708","rc":[{"batb":[[0,2.18,7.18],[1,2.16,20],[2,1.5,20]],"ltp":0.0,"tv":0.0,"id":3961},{"batb":[[0,1.59,14.35],[1,1.58,3.34],[2,1.57,3.4]],"ltp":2.64,"tv":4.0,"id":60443}]}]}
{"op":"mcm","clk":"11982055353","pt":1724859397849,"mc":[{"id":"1.232199708","rc":[{"batb":[[1,1.57,3.4],[2,1.3,20.69]],"ltp":2.64,"tv":4.0,"id":60443}]}]}
{"op":"mcm","clk":"11982055974","pt":1724859403453,"mc":[{"id":"1.232199708","rc":[{"batb":[[0,1.6,3.3],[1,1.59,14.35],[2,1.57,3.4]],"ltp":2.64,"tv":4.0,"id":60443}]}]}
{"op":"mcm","clk":"11982229317","pt":1724860769242,"mc":[{"id":"1.232199708","rc":[{"batl":[[2,940,0.84]],"ltp":2.64,"tv":4.36,"id":424679},{"batl":[[1,940,1.01],[2,990,0]],"ltp":0.0,"tv":0.0,"id":3961},{"batl":[[1,940,1.01],[2,990,0]],"ltp":2.64,"tv":4.0,"id":60443}]}]}
{"op":"mcm","clk":"11982230004","pt":1724860774832,"mc":[{"id":"1.232199708","rc":[{"batl":[[1,160,1.01],[2,940,0.67]],"ltp":2.64,"tv":4.36,"id":424679}]}]}
{"op":"mcm","clk":"11982240449","pt":1724860850422,"mc":[{"id":"1.232199708","rc":[{"trd":[[1.21,1.94]],"batb":[[1,1.61,5.06]],"batl":[[1,85,2.5],[2,160,1.01]],"ltp":2.64,"tv":4.36,"id":424679},{"batb":[[0,2.18,7.18]],"batl":[[1,85,2.5],[2,940,1.01]],"ltp":0.0,"tv":0.0,"id":3961},{"batb":[[1,1.59,14.37],[2,1.57,3.4]],"batl":[[1,85,2.5],[2,940,1.01]],"ltp":2.64,"tv":4.0,"id":60443}],"tv":8.37}]}
{"op":"mcm","clk":"11982292835","pt":1724861197427,"mc":[{"id":"1.232199708","rc":[{"batb":[[0,2.16,20],[1,1.5,20],[2,1.04,126.53]],"ltp":0.0,"tv":0.0,"id":3961},{"batb":[[1,1.57,3.4],[2,1.3,20.69]],"ltp":2.64,"tv":4.0,"id":60443}]}]}
{"op":"mcm","clk":"11982293603","pt":1724861202333,"mc":[{"id":"1.232199708","rc":[{"batb":[[0,2.18,7.18],[1,2.16,20],[2,1.5,20]],"ltp":0.0,"tv":0.0,"id":3961},{"batb":[[0,1.61,13.89]],"ltp":2.64,"tv":4.0,"id":60443}]}]}
{"op":"mcm","clk":"11982294456","pt":1724861207866,"mc":[{"id":"1.232199708","rc":[{"batb":[[0,1.62,3.26],[1,1.61,13.89],[2,1.57,3.4]],"ltp":2.64,"tv":4.0,"id":60443}]}]}
{"op":"mcm","clk":"11982322471","pt":1724861379679,"mc":[{"id":"1.232199708","rc":[{"batb":[[0,1.62,3.7]],"ltp":2.64,"tv":4.0,"id":60443}]}]}
{"op":"mcm","clk":"11982553332","pt":1724863002406,"mc":[{"id":"1.232199708","rc":[{"batb":[[0,2.16,20],[1,1.5,20],[2,1.04,126.53]],"ltp":0.0,"tv":0.0,"id":3961},{"batb":[[1,1.57,3.4],[2,1.3,20.69]],"ltp":2.64,"tv":4.0,"id":60443}]}]}
{"op":"mcm","clk":"11982576808","pt":1724863176923,"mc":[{"id":"1.232199708","rc":[{"batb":[[0,2.18,7.18],[1,2.16,20],[2,1.5,20]],"ltp":0.0,"tv":0.0,"id":3961},{"batb":[[0,1.63,13.89],[1,1.62,3.26],[2,1.57,3.4]],"ltp":2.64,"tv":4.0,"id":60443}]}]}
{"op":"mcm","clk":"11982577141","pt":1724863179415,"mc":[{"id":"1.232199708","rc":[{"batb":[[1,1.57,3.4],[2,1.3,20.69]],"ltp":2.64,"tv":4.0,"id":60443}]}]}
{"op":"mcm","clk":"11982580209","pt":1724863201733,"mc":[{"id":"1.232199708","rc":[{"batb":[[0,1.64,3.66],[1,1.63,13.45],[2,1.57,3.4]],"ltp":2.64,"tv":4.0,"id":60443}]}]}
{"op":"mcm","clk":"11982782137","pt":1724864977457,"mc":[{"id":"1.232199708","rc":[{"batb":[[0,2.16,20],[1,1.5,20],[2,1.04,126.53]],"ltp":0.0,"tv":0.0,"id":3961},{"batb":[[1,1.57,3.4],[2,1.3,20.69]],"ltp":2.64,"tv":4.0,"id":60443}],"tv":8.37}]}
{"op":"mcm","clk":"11982797658","pt":1724865112135,"mc":[{"id":"1.232199708","rc":[{"batb":[[0,2.18,7.18],[1,2.16,20],[2,1.5,20]],"ltp":0.0,"tv":0.0,"id":3961},{"batb":[[0,1.65,13.48],[1,1.64,3.22],[2,1.57,3.4]],"ltp":2.64,"tv":4.0,"id":60443}]}]}
{"op":"mcm","clk":"11982798429","pt":1724865117735,"mc":[{"id":"1.232199708","rc":[{"batb":[[1,1.57,3.4],[2,1.3,20.69]],"ltp":2.64,"tv":4.0,"id":60443}]}]}
{"op":"mcm","clk":"11982801282","pt":1724865139981,"mc":[{"id":"1.232199708","rc":[{"batb":[[0,1.66,3.62],[1,1.65,13.04],[2,1.57,3.4]],"ltp":2.64,"tv":4.0,"id":60443}]}]}
{"op":"mcm","clk":"11983024261","pt":1724866912447,"mc":[{"id":"1.232199708","rc":[{"batb":[[1,1.57,3.4],[2,1.3,20.69]],"ltp":2.64,"tv":4.0,"id":60443}]}]}
{"op":"mcm","clk":"11983024297","pt":1724866912718,"mc":[{"id":"1.232199708","rc":[{"batb":[[0,2.16,20],[1,1.5,20],[2,1.04,126.53]],"ltp":0.0,"tv":0.0,"id":3961}]}]}
{"op":"mcm","clk":"11983035891","pt":1724867008004,"mc":[{"id":"1.232199708","rc":[{"batb":[[0,2.18,7.18],[1,2.16,20],[2,1.5,20]],"ltp":0.0,"tv":0.0,"id":3961},{"batb":[[0,1.67,13.09],[1,1.66,3.18],[2,1.57,3.4]],"ltp":2.64,"tv":4.0,"id":60443}]}]}
{"op":"mcm","clk":"11983036287","pt":1724867011400,"mc":[{"id":"1.232199708","rc":[{"batb":[[1,1.57,3.4],[2,1.3,20.69]],"ltp":2.64,"tv":4.0,"id":60443}]}]}
{"op":"mcm","clk":"11983037648","pt":1724867022618,"mc":[{"id":"1.232199708","rc":[{"batb":[[0,1.68,3.58],[1,1.67,12.65],[2,1.57,3.4]],"ltp":2.64,"tv":4.0,"id":60443}]}]}
{"op":"mcm","clk":"11983233749","pt":1724868808435,"mc":[{"id":"1.232199708","rc":[{"trd":[[1.21,1.94]],"batb":[[1,1.61,5.06]],"ltp":2.64,"tv":4.36,"id":424679},{"batb":[[0,2.16,20],[1,1.5,20],[2,1.04,126.53]],"ltp":0.0,"tv":0.0,"id":3961},{"batb":[[1,1.57,3.41],[2,1.3,20.69]],"ltp":2.64,"tv":4.0,"id":60443}],"tv":8.37}]}
{"op":"mcm","clk":"11983238625","pt":1724868854563,"mc":[{"id":"1.232199708","rc":[{"batb":[[0,2.18,7.19],[1,2.16,20],[2,1.5,20]],"ltp":0.0,"tv":0.0,"id":3961},{"batb":[[0,1.69,12.73],[1,1.68,3.14],[2,1.57,3.41]],"ltp":2.64,"tv":4.0,"id":60443}]}]}
{"op":"mcm","clk":"11983239183","pt":1724868860299,"mc":[{"id":"1.232199708","rc":[{"batb":[[1,1.57,3.41],[2,1.3,20.69]],"ltp":2.64,"tv":4.0,"id":60443}]}]}
{"op":"mcm","clk":"11983241247","pt":1724868882537,"mc":[{"id":"1.232199708","rc":[{"batb":[[0,1.7,3.55],[1,1.69,12.29],[2,1.57,3.41]],"ltp":2.64,"tv":4.0,"id":60443}]}]}
{"op":"mcm","clk":"11983446605","pt":1724870654894,"mc":[{"id":"1.232199708","rc":[{"batb":[[0,2.16,20],[1,1.5,20],[2,1.04,126.53]],"ltp":0.0,"tv":0.0,"id":3961},{"batb":[[1,1.57,3.41],[2,1.3,20.69]],"ltp":2.64,"tv":4.0,"id":60443}]}]}
{"op":"mcm","clk":"11983448353","pt":1724870669026,"mc":[{"id":"1.232199708","rc":[{"batb":[[0,2.18,7.19],[1,2.16,20],[2,1.5,20]],"ltp":0.0,"tv":0.0,"id":3961},{"batb":[[0,1.71,11.94],[1,1.7,3.55],[2,1.57,3.41]],"ltp":2.64,"tv":4.0,"id":60443}]}]}
{"op":"mcm","clk":"11983448538","pt":1724870670724,"mc":[{"id":"1.232199708","rc":[{"batb":[[1,1.57,3.85],[2,1.3,20.69]],"ltp":2.64,"tv":4.0,"id":60443}]}]}
{"op":"mcm","clk":"11983449237","pt":1724870676338,"mc":[{"id":"1.232199708","rc":[{"batb":[[0,1.72,3.07],[1,1.71,11.94],[2,1.57,3.85]],"ltp":2.64,"tv":4.0,"id":60443}]}]}
{"op":"mcm","clk":"11983453272","pt":1724870708627,"mc":[{"id":"1.232199708","rc":[{"batb":[[2,1.6,10]],"ltp":2.64,"tv":4.36,"id":424679}]}]}
{"op":"mcm","clk":"11983454807","pt":1724870721492,"mc":[{"id":"1.232199708","rc":[{"batb":[[0,2.52,10],[1,2.5,31.54],[2,1.61,5.06]],"ltp":2.64,"tv":4.36,"id":424679}]}]}
{"op":"mcm","clk":"11983456167","pt":1724870733514,"mc":[{"id":"1.232199708","rc":[{"batb":[[1,1.5,20],[2,1.04,126.53]],"ltp":0.0,"tv":0.0,"id":3961}]}]}
{"op":"mcm","clk":"11983457617","pt":1724870745835,"mc":[{"id":"1.232199708","rc":[{"batb":[[0,2.2,5],[1,2.18,7.19],[2,1.5,20]],"ltp":0.0,"tv":0.0,"id":3961}]}]}
{"op":"mcm","clk":"11983659100","pt":1724872411022,"mc":[{"id":"1.232199708","marketDefinition":{"bspMarket":false,"turnInPlayEnabled":true,"persistenceEnabled":true,"marketBaseRate":5.0,"eventId":"33521414","eventTypeId":"4","numberOfWinners":1,"bettingType":"ODDS","marketType":"MATCH_ODDS","marketTime":"2024-08-29T10:00:00.000Z","suspendTime":"2024-08-29T10:00:00.000Z","bspReconciled":false,"complete":true,"inPlay":false,"crossMatching":true,"runnersVoidable":false,"numberOfActiveRunners":3,"betDelay":0,"status":"OPEN","runners":[{"status":"ACTIVE","sortPriority":1,"id":424679,"name":"Lancashire"},{"status":"ACTIVE","sortPriority":2,"id":3961,"name":"Hampshire"},{"status":"ACTIVE","sortPriority":3,"id":60443,"name":"The Draw"}],"regulators":["MR_INT"],"countryCode":"GB","discountAllowed":true,"timezone":"GMT","openDate":"2024-08-29T10:00:00.000Z","version":6105433804,"name":"Match Odds","eventName":"Lancashire v Hampshire"}}]}
{"op":"mcm","clk":"11983665653","pt":1724872469294,"mc":[{"id":"1.232199708","rc":[{"trd":[[1.21,1.94]],"batb":[[2,1.61,5.06]],"ltp":2.64,"tv":4.36,"id":424679},{"batb":[[1,1.5,20],[2,1.04,126.53]],"ltp":0.0,"tv":0.0,"id":3961},{"batb":[[1,1.71,11.94],[2,1.57,3.84]],"ltp":2.64,"tv":4.0,"id":60443}],"tv":8.37}]}
{"op":"mcm","clk":"11983665681","pt":1724872469495,"mc":[{"id":"1.232199708","rc":[{"batb":[[1,1.57,3.84],[2,1.3,20.69]],"ltp":2.64,"tv":4.0,"id":60443}]}]}
{"op":"mcm","clk":"11983667284","pt":1724872483724,"mc":[{"id":"1.232199708","rc":[{"batb":[[0,2.22,6.95],[1,2.2,5],[2,1.5,20]],"ltp":0.0,"tv":0.0,"id":3961},{"batb":[[0,1.73,11.61],[1,1.72,3.07],[2,1.57,3.84]],"ltp":2.64,"tv":4.0,"id":60443}]}]}
{"op":"mcm","clk":"11983667570","pt":1724872486422,"mc":[{"id":"1.232199708","rc":[{"batb":[[1,1.57,3.84],[2,1.3,20.69]],"ltp":2.64,"tv":4.0,"id":60443}]}]}
{"op":"mcm","clk":"11983668708","pt":1724872497508,"mc":[{"id":"1.232199708","rc":[{"batb":[[0,1.74,3.03],[1,1.73,11.61],[2,1.57,3.84]],"ltp":2.64,"tv":4.0,"id":60443}]}]}
{"op":"mcm","clk":"11983859801","pt":1724874284213,"mc":[{"id":"1.232199708","rc":[{"batb":[[0,2.2,5],[1,1.5,20],[2,1.04,126.53]],"ltp":0.0,"tv":0.0,"id":3961},{"batb":[[1,1.57,3.84],[2,1.3,20.69]],"ltp":2.64,"tv":4.0,"id":60443}]}]}
{"op":"mcm","clk":"11983869214","pt":1724874380776,"mc":[{"id":"1.232199708","rc":[{"batb":[[0,2.22,6.95],[1,2.2,5],[2,1.5,20]],"ltp":0.0,"tv":0.0,"id":3961},{"batb":[[0,1.75,11.3],[1,1.74,3.03],[2,1.57,3.84]],"ltp":2.64,"tv":4.0,"id":60443}]}]}
{"op":"mcm","clk":"11983869664","pt":1724874385489,"mc":[{"id":"1.232199708","rc":[{"batb":[[1,1.57,3.84],[2,1.3,20.69]],"ltp":2.64,"tv":4.0,"id":60443}]}]}
{"op":"mcm","clk":"11983871982","pt":1724874407816,"mc":[{"id":"1.232199708","rc":[{"batb":[[0,1.76,3],[1,1.75,11.3],[2,1.57,3.84]],"ltp":2.64,"tv":4.0,"id":60443}]}]}
{"op":"mcm","clk":"11984036651","pt":1724875974830,"mc":[{"id":"1.232199708","rc":[{"batb":[[2,1.61,5.06]],"ltp":2.64,"tv":4.36,"id":424679},{"batb":[[0,2.22,6.95]],"ltp":0.0,"tv":0.0,"id":3961},{"batb":[[1,1.75,11.3]],"ltp":2.64,"tv":4.0,"id":60443}]}]}
{"op":"mcm","clk":"11984067831","pt":1724876181128,"mc":[{"id":"1.232199708","rc":[{"batb":[[0,2.2,5],[1,1.5,20],[2,1.04,126.53]],"ltp":0.0,"tv":0.0,"id":3961},{"batb":[[1,1.57,3.84],[2,1.3,20.69]],"ltp":2.64,"tv":4.0,"id":60443}]}]}
{"op":"mcm","clk":"11984075695","pt":1724876256617,"mc":[{"id":"1.232199708","rc":[{"batb":[[0,2.22,6.95],[1,2.2,5],[2,1.5,20]],"ltp":0.0,"tv":0.0,"id":3961},{"batb":[[0,1.77,11.01],[1,1.76,3],[2,1.57,3.84]],"ltp":2.64,"tv":4.0,"id":60443}]}]}
{"op":"mcm","clk":"11984076262","pt":1724876262136,"mc":[{"id":"1.232199708","rc":[{"batb":[[1,1.57,3.84],[2,1.3,20.69]],"ltp":2.64,"tv":4.0,"id":60443}]}]}
{"op":"mcm","clk":"11984078440","pt":1724876284423,"mc":[{"id":"1.232199708","rc":[{"batb":[[0,1.78,2.97],[1,1.77,11.01],[2,1.57,3.84]],"ltp":2.64,"tv":4.0,"id":60443}]}]}
{"op":"mcm","clk":"11984219810","pt":1724878056973,"mc":[{"id":"1.232199708","rc":[{"batb":[[0,2.2,5],[1,1.5,20],[2,1.04,126.53]],"ltp":0.0,"tv":0.0,"id":3961},{"batb":[[1,1.57,3.84],[2,1.3,20.69]],"ltp":2.64,"tv":4.0,"id":60443}]}]}
{"op":"mcm","clk":"11984221024","pt":1724878083274,"mc":[{"id":"1.232199708","rc":[{"batb":[[0,2.22,6.95],[1,2.2,5],[2,1.5,20]],"ltp":0.0,"tv":0.0,"id":3961},{"batb":[[0,1.79,10.73]],"ltp":2.64,"tv":4.0,"id":60443}]}]}
{"op":"mcm","clk":"11984221319","pt":1724878088886,"mc":[{"id":"1.232199708","rc":[{"batb":[[0,1.8,2.93],[1,1.79,10.73],[2,1.57,3.84]],"ltp":2.64,"tv":4.0,"id":60443}]}]}
{"op":"mcm","clk":"11984315728","pt":1724879883049,"mc":[{"id":"1.232199708","rc":[{"batb":[[2,1.61,5.06]],"ltp":2.64,"tv":4.36,"id":424679},{"batb":[[0,2.2,5],[1,1.5,20],[2,1.04,126.53]],"ltp":0.0,"tv":0.0,"id":3961},{"batb":[[1,1.57,3.84],[2,1.3,20.69]],"ltp":2.64,"tv":4.0,"id":60443}]}]}
{"op":"mcm","clk":"11984326071","pt":1724880067884,"mc":[{"id":"1.232199708","rc":[{"batb":[[0,2.22,6.95],[1,2.2,5],[2,1.5,20]],"ltp":0.0,"tv":0.0,"id":3961},{"batb":[[0,1.81,10.46],[1,1.8,2.93],[2,1.57,3.84]],"ltp":2.64,"tv":4.0,"id":60443}]}]}
{"op":"mcm","clk":"11984326253","pt":1724880071554,"mc":[{"id":"1.232199708","rc":[{"batb":[[1,1.57,3.84],[2,1.3,20.69]],"ltp":2.64,"tv":4.0,"id":60443}]}]}
{"op":"mcm","clk":"11984326791","pt":1724880082694,"mc":[{"id":"1.232199708","rc":[{"batb":[[0,1.82,2.9],[1,1.81,10.46],[2,1.57,3.84]],"ltp":2.64,"tv":4.0,"id":60443}]}]}
{"op":"mcm","clk":"11984375106","pt":1724881018814,"mc":[{"id":"1.232199708","rc":[{"batb":[[2,1.32,1.13]],"ltp":2.64,"tv":4.0,"id":60443}]}]}
{"op":"mcm","clk":"11984427499","pt":1724881868466,"mc":[{"id":"1.232199708","rc":[{"batb":[[0,2.2,5],[1,1.5,20],[2,1.04,126.53]],"ltp":0.0,"tv":0.0,"id":3961},{"batb":[[1,1.32,1.13],[2,1.3,20]],"ltp":2.64,"tv":4.0,"id":60443}]}]}
{"op":"mcm","clk":"11984433139","pt":1724882017217,"mc":[{"id":"1.232199708","rc":[{"batb":[[0,2.22,6.95],[1,2.2,5],[2,1.5,20]],"ltp":0.0,"tv":0.0,"id":3961},{"batb":[[0,1.83,10.21],[1,1.82,2.9],[2,1.32,1.13]],"ltp":2.64,"tv":4.0,"id":60443}]}]}
{"op":"mcm","clk":"11984433251","pt":1724882020692,"mc":[{"id":"1.232199708","rc":[{"batb":[[1,1.32,1.13],[2,1.3,20]],"ltp":2.64,"tv":4.0,"id":60443}]}]}
{"op":"mcm","clk":"11984433633","pt":1724882031748,"mc":[{"id":"1.232199708","rc":[{"batb":[[0,1.84,2.87],[1,1.83,10.21],[2,1.32,1.13]],"ltp":2.64,"tv":4.0,"id":60443}]}]}
{"op":"mcm","clk":"11984457695","pt":1724882817408,"mc":[{"id":"1.232199708","rc":[{"batb":[[0,2,10],[1,1.84,2.87],[2,1.83,10.21]],"ltp":2.64,"tv":4.0,"id":60443}]}]}
{"op":"mcm","clk":"11984457880","pt":1724882822699,"mc":[{"id":"1.232199708","rc":[{"batl":[[0,85,2.5],[1,940,1.01],[2,990,2.5]],"ltp":0.0,"tv":0.0,"id":3961},{"batb":[[1,1.83,10.21],[2,1.32,1.13]],"ltp":2.64,"tv":4.0,"id":60443}]}]}
{"op":"mcm","clk":"11984458024","pt":1724882828225,"mc":[{"id":"1.232199708","rc":[{"batl":[[0,9.6,1],[1,85,2.5],[2,940,1.01]],"ltp":0.0,"tv":0.0,"id":3961},{"batb":[[0,2.02,2.61],[1,2,10],[2,1.83,10.21]],"ltp":2.64,"tv":4.0,"id":60443}]}]}
{"op":"mcm","clk":"11984489786","pt":1724883817678,"mc":[{"id":"1.232199708","rc":[{"batb":[[0,2.2,5],[1,1.5,20],[2,1.04,126.53]],"ltp":0.0,"tv":0.0,"id":3961},{"batb":[[2,1.32,1.13]],"ltp":2.64,"tv":4.0,"id":60443}]}]}
{"op":"mcm","clk":"11984494479","pt":1724883951063,"mc":[{"id":"1.232199708","rc":[{"batb":[[0,2.22,6.95],[1,2.2,5],[2,1.5,20]],"ltp":0.0,"tv":0.0,"id":3961},{"batb":[[0,2.04,8.15],[1,2.02,2.61],[2,2,10]],"ltp":2.64,"tv":4.0,"id":60443}]}]}
{"op":"mcm","clk":"11984494564","pt":1724883953269,"mc":[{"id":"1.232199708","rc":[{"batl":[[0,85,2.5],[1,940,1.01],[2,990,2.5]],"ltp":0.0,"tv":0.0,"id":3961},{"batb":[[1,2,10],[2,1.32,1.13]],"ltp":2.64,"tv":4.0,"id":60443}]}]}
{"op":"mcm","clk":"11984494759","pt":1724883958968,"mc":[{"id":"1.232199708","rc":[{"batl":[[0,8.8,1],[1,85,2.5],[2,940,1.01]],"ltp":0.0,"tv":0.0,"id":3961},{"batb":[[0,2.06,2.56],[1,2.04,8.15],[2,2,10]],"ltp":2.64,"tv":4.0,"id":60443}]}]}
{"op":"mcm","clk":"11984567197","pt":1724885751307,"mc":[{"id":"1.232199708","rc":[{"batb":[[0,2.2,5],[1,1.5,20],[2,1.04,126.53]],"ltp":0.0,"tv":0.0,"id":3961}]}]}
{"op":"mcm","clk":"11984567201","pt":1724885751512,"mc":[{"id":"1.232199708","rc":[{"batb":[[1,2,10],[2,1.32,1.13]],"ltp":2.64,"tv":4.0,"id":60443}]}]}
{"op":"mcm","clk":"11984571906","pt":1724885869097,"mc":[{"id":"1.232199708","rc":[{"batb":[[0,2.22,6.95],[1,2.2,5],[2,1.5,20]],"ltp":0.0,"tv":0.0,"id":3961},{"batb":[[0,2.08,7.85],[1,2.06,2.56],[2,2,10]],"ltp":2.64,"tv":4.0,"id":60443}]}]}
{"op":"mcm","clk":"11984572118","pt":1724885874659,"mc":[{"id":"1.232199708","rc":[{"batl":[[0,85,2.5],[1,940,1.01],[2,990,2.5]],"ltp":0.0,"tv":0.0,"id":3961},{"batb":[[1,2,10],[2,1.32,1.13]],"ltp":2.64,"tv":4.0,"id":60443}]}]}
{"op":"mcm","clk":"11984572306","pt":1724885880258,"mc":[{"id":"1.232199708","rc":[{"batl":[[0,8,1],[1,85,2.5],[2,940,1.01]],"ltp":0.0,"tv":0.0,"id":3961}]}]}
{"op":"mcm","clk":"11984572889","pt":1724885897009,"mc":[{"id":"1.232199708","rc":[{"batb":[[0,2.1,2.51],[1,2.08,7.85],[2,2,10]],"ltp":2.64,"tv":4.0,"id":60443}]}]}
{"op":"mcm","clk":"11984608438","pt":1724886774819,"mc":[{"id":"1.232199708","rc":[{"batb":[[2,1.61,5.06]],"ltp":2.64,"tv":4.36,"id":424679},{"batb":[[0,2.22,6.95]],"ltp":0.0,"tv":0.0,"id":3961},{"batb":[[1,2.08,7.85]],"ltp":2.64,"tv":4.0,"id":60443}]}]}
{"op":"mcm","clk":"11984661999","pt":1724887669467,"mc":[{"id":"1.232199708","rc":[{"batb":[[0,2.2,5],[1,1.5,20],[2,1.04,126.53]],"ltp":0.0,"tv":0.0,"id":3961},{"batb":[[1,2,10],[2,1.32,1.13]],"ltp":2.64,"tv":4.0,"id":60443}]}]}
{"op":"mcm","clk":"11984667666","pt":1724887775628,"mc":[{"id":"1.232199708","rc":[{"batb":[[0,2.22,6.95],[1,2.2,5],[2,1.5,20]],"ltp":0.0,"tv":0.0,"id":3961},{"batb":[[0,2.12,7.57],[1,2.1,2.51],[2,2,10]],"ltp":2.64,"tv":4.0,"id":60443}]}]}
{"op":"mcm","clk":"11984667861","pt":1724887779440,"mc":[{"id":"1.232199708","rc":[{"batl":[[0,85,2.5],[1,160,1.01],[2,990,3.17]],"ltp":2.64,"tv":4.36,"id":424679},{"batl":[[0,85,2.5],[1,940,1.01],[2,990,2.5]],"ltp":0.0,"tv":0.0,"id":3961},{"batb":[[1,2,10],[2,1.32,1.13]],"ltp":2.64,"tv":4.0,"id":60443}]}]}
{"op":"mcm","clk":"11984668161","pt":1724887785074,"mc":[{"id":"1.232199708","rc":[{"batl":[[0,7.6,1],[1,85,2.5],[2,940,1.01]],"ltp":0.0,"tv":0.0,"id":3961}]}]}
{"op":"mcm","clk":"11984668489","pt":1724887790767,"mc":[{"id":"1.232199708","rc":[{"batl":[[0,12.5,1],[1,85,2.5],[2,160,1.01]],"ltp":2.64,"tv":4.36,"id":424679},{"batb":[[0,2.14,2.47],[1,2.12,7.57],[2,2,10]],"ltp":2.64,"tv":4.0,"id":60443}]}]}
{"op":"mcm","clk":"11984773850","pt":1724889576323,"mc":[{"id":"1.232199708","rc":[{"batb":[[0,2.2,5],[1,1.5,20],[2,1.04,126.53]],"ltp":0.0,"tv":0.0,"id":3961},{"batb":[[1,2,10],[2,1.32,1.13]],"ltp":2.64,"tv":4.0,"id":60443}]}]}
{"op":"mcm","clk":"11984779868","pt":1724889673354,"mc":[{"id":"1.232199708","rc":[{"batb":[[0,2.22,6.95],[1,2.2,5],[2,1.5,20]],"ltp":0.0,"tv":0.0,"id":3961},{"batb":[[0,2.16,7.31],[1,2.14,2.47],[2,2,10]],"ltp":2.64,"tv":4.0,"id":60443}]}]}
{"op":"mcm","clk":"11984780201","pt":1724889678554,"mc":[{"id":"1.232199708","rc":[{"batl":[[0,85,2.5],[1,160,1.01],[2,990,3.17]],"ltp":2.64,"tv":4.36,"id":424679},{"batl":[[0,85,2.5],[1,940,1.01],[2,990,2.5]],"ltp":0.0,"tv":0.0,"id":3961},{"batb":[[1,2,10],[2,1.32,1.13]],"ltp":2.64,"tv":4.0,"id":60443}]}]}
{"op":"mcm","clk":"11984780589","pt":1724889684163,"mc":[{"id":"1.232199708","rc":[{"batl":[[0,7,1],[1,85,2.5],[2,940,1.01]],"ltp":0.0,"tv":0.0,"id":3961}]}]}
{"op":"mcm","clk":"11984780998","pt":1724889689655,"mc":[{"id":"1.232199708","rc":[{"batl":[[0,11.5,1],[1,85,2.5],[2,160,1.01]],"ltp":2.64,"tv":4.36,"id":424679}]}]}
{"op":"mcm","clk":"11984781695","pt":1724889700783,"mc":[{"id":"1.232199708","rc":[{"batb":[[0,2.18,2.42],[1,2.16,7.31],[2,2,10]],"ltp":2.64,"tv":4.0,"id":60443}]}]}
{"op":"mcm","clk":"11984905179","pt":1724891473732,"mc":[{"id":"1.232199708","rc":[{"batb":[[0,2.2,5],[1,1.5,20],[2,1.04,126.53]],"ltp":0.0,"tv":0.0,"id":3961},{"batb":[[1,2,10],[2,1.32,1.13]],"ltp":2.64,"tv":4.0,"id":60443}]}]}
{"op":"mcm","clk":"11984910677","pt":1724891561197,"mc":[{"id":"1.232199708","rc":[{"batb":[[0,2.22,6.95],[1,2.2,5],[2,1.5,20]],"ltp":0.0,"tv":0.0,"id":3961},{"batb":[[0,2.2,7.06],[1,2.18,2.42],[2,2,10]],"ltp":2.64,"tv":4.0,"id":60443}]}]}
{"op":"mcm","clk":"11984911029","pt":1724891566647,"mc":[{"id":"1.232199708","rc":[{"batl":[[0,85,2.5],[1,160,1.01],[2,990,3.17]],"ltp":2.64,"tv":4.36,"id":424679},{"batl":[[0,85,2.5],[1,940,1.01],[2,990,2.5]],"ltp":0.0,"tv":0.0,"id":3961},{"batb":[[1,2,10],[2,1.32,1.13]],"ltp":2.64,"tv":4.0,"id":60443}]}]}
{"op":"mcm","clk":"11984911389","pt":1724891572116,"mc":[{"id":"1.232199708","rc":[{"batl":[[0,6.6,1],[1,85,2.5],[2,940,1.01]],"ltp":0.0,"tv":0.0,"id":3961}]}]}
{"op":"mcm","clk":"11984911721","pt":1724891577616,"mc":[{"id":"1.232199708","rc":[{"batl":[[0,10.5,1],[1,85,2.5],[2,160,1.01]],"ltp":2.64,"tv":4.36,"id":424679}]}]}
{"op":"mcm","clk":"11984912473","pt":1724891588876,"mc":[{"id":"1.232199708","rc":[{"batb":[[0,2.22,2.38],[1,2.2,7.06],[2,2,10]],"ltp":2.64,"tv":4.0,"id":60443}]}]}
{"op":"mcm","clk":"11985037410","pt":1724893361736,"mc":[{"id":"1.232199708","rc":[{"trd":[[1.21,1.94]],"batb":[[2,1.61,5.06]],"ltp":2.64,"tv":4.36,"id":424679},{"batb":[[0,2.2,5],[1,1.5,20],[2,1.04,126.53]],"ltp":0.0,"tv":0.0,"id":3961},{"batb":[[1,2,10],[2,1.32,1.13]],"ltp":2.64,"tv":4.0,"id":60443}],"tv":8.37}]}
{"op":"mcm","clk":"11985041582","pt":1724893425941,"mc":[{"id":"1.232199708","rc":[{"batb":[[0,2.22,6.95],[1,2.2,5],[2,1.5,20]],"ltp":0.0,"tv":0.0,"id":3961},{"batb":[[0,2.24,6.83],[1,2.22,2.38],[2,2,10]],"ltp":2.64,"tv":4.0,"id":60443}]}]}
{"op":"mcm","clk":"11985041623","pt":1724893426617,"mc":[{"id":"1.232199708","rc":[{"batl":[[0,85,2.5],[1,160,1.01],[2,990,3.17]],"ltp":2.64,"tv":4.36,"id":424679},{"batl":[[0,85,2.5],[1,940,1.01],[2,990,2.5]],"ltp":0.0,"tv":0.0,"id":3961},{"batb":[[1,2,10],[2,1.32,1.13]],"ltp":2.64,"tv":4.0,"id":60443}]}]}
{"op":"mcm","clk":"11985041994","pt":1724893432444,"mc":[{"id":"1.232199708","rc":[{"batl":[[0,9.6,1],[1,85,2.5],[2,160,1.01]],"ltp":2.64,"tv":4.36,"id":424679},{"batl":[[0,6.2,1],[1,85,2.5],[2,940,1.01]],"ltp":0.0,"tv":0.0,"id":3961},{"batb":[[0,2.26,2.34],[1,2.24,6.83],[2,2,10]],"ltp":2.64,"tv":4.0,"id":60443}]}]}
{"op":"mcm","clk":"11985148998","pt":1724895226380,"mc":[{"id":"1.232199708","rc":[{"batb":[[0,2.2,5],[1,1.5,20],[2,1.04,126.53]],"ltp":0.0,"tv":0.0,"id":3961},{"batb":[[1,2,10],[2,1.32,1.13]],"ltp":2.64,"tv":4.0,"id":60443}]}]}
{"op":"mcm","clk":"11985151901","pt":1724895278212,"mc":[{"id":"1.232199708","rc":[{"batb":[[0,2.22,6.95],[1,2.2,5],[2,1.5,20]],"ltp":0.0,"tv":0.0,"id":3961},{"batb":[[0,2.28,6.62],[1,2.26,2.34],[2,2,10]],"ltp":2.64,"tv":4.0,"id":60443}]}]}
{"op":"mcm","clk":"11985152043","pt":1724895281043,"mc":[{"id":"1.232199708","rc":[{"batl":[[0,85,2.5],[1,160,1.01],[2,990,3.17]],"ltp":2.64,"tv":4.36,"id":424679},{"batb":[[1,2,10],[2,1.32,1.13]],"ltp":2.64,"tv":4.0,"id":60443}]}]}
{"op":"mcm","clk":"11985152683","pt":1724895292358,"mc":[{"id":"1.232199708","rc":[{"batl":[[0,9,1],[1,85,2.5],[2,160,1.01]],"ltp":2.64,"tv":4.36,"id":424679},{"batb":[[0,2.3,2.3],[1,2.28,6.62],[2,2,10]],"ltp":2.64,"tv":4.0,"id":60443}]}]}
{"op":"mcm","clk":"11985259045","pt":1724897079033,"mc":[{"id":"1.232199708","rc":[{"batb":[[0,2.2,5],[1,1.5,20],[2,1.04,126.53]],"ltp":0.0,"tv":0.0,"id":3961},{"batb":[[1,2,10],[2,1.32,1.13]],"ltp":2.64,"tv":4.0,"id":60443}]}]}
{"op":"mcm","clk":"11985261340","pt":1724897114791,"mc":[{"id":"1.232199708","rc":[{"batb":[[0,2.22,6.95],[1,2.2,5],[2,1.5,20]],"ltp":0.0,"tv":0.0,"id":3961},{"batb":[[0,2.32,6.42],[1,2.3,2.3],[2,2,10]],"ltp":2.64,"tv":4.0,"id":60443}]}]}
{"op":"mcm","clk":"11985261699","pt":1724897119185,"mc":[{"id":"1.232199708","rc":[{"batl":[[0,85,2.5],[1,160,1.01],[2,990,3.17]],"ltp":2.64,"tv":4.36,"id":424679},{"batl":[[0,85,2.5],[1,940,1.01],[2,990,2.5]],"ltp":0.0,"tv":0.0,"id":3961},{"batb":[[1,2,10],[2,1.32,1.13]],"ltp":2.64,"tv":4.0,"id":60443}]}]}
{"op":"mcm","clk":"11985262071","pt":1724897124607,"mc":[{"id":"1.232199708","rc":[{"batl":[[0,5.8,1],[1,85,2.5],[2,940,1.01]],"ltp":0.0,"tv":0.0,"id":3961}]}]}
{"op":"mcm","clk":"11985262421","pt":1724897130217,"mc":[{"id":"1.232199708","rc":[{"batl":[[0,8.4,1],[1,85,2.5],[2,160,1.01]],"ltp":2.64,"tv":4.36,"id":424679}]}]}
{"op":"mcm","clk":"11985263093","pt":1724897141311,"mc":[{"id":"1.232199708","rc":[{"batb":[[0,2.34,2.26],[1,2.32,6.42],[2,2,10]],"ltp":2.64,"tv":4.0,"id":60443}]}]}
{"op":"mcm","clk":"11985370963","pt":1724898915192,"mc":[{"id":"1.232199708","rc":[{"batb":[[0,2.2,5],[1,1.5,20],[2,1.04,126.53]],"ltp":0.0,"tv":0.0,"id":3961},{"batb":[[1,2,10],[2,1.32,1.13]],"ltp":2.64,"tv":4.0,"id":60443}]}]}
{"op":"mcm","clk":"11985372388","pt":1724898943562,"mc":[{"id":"1.232199708","rc":[{"batb":[[0,2.22,6.95],[1,2.2,5],[2,1.5,20]],"ltp":0.0,"tv":0.0,"id":3961},{"batb":[[0,2.36,6.23],[1,2.34,2.26],[2,2,10]],"ltp":2.64,"tv":4.0,"id":60443}]}]}
{"op":"mcm","clk":"11985372485","pt":1724898945564,"mc":[{"id":"1.232199708","rc":[{"batl":[[0,85,2.5],[1,160,1.01],[2,990,3.17]],"ltp":2.64,"tv":4.36,"id":424679},{"batl":[[0,85,2.5],[1,940,1.01],[2,990,2.5]],"ltp":0.0,"tv":0.0,"id":3961},{"batb":[[1,2,10],[2,1.32,1.13]],"ltp":2.64,"tv":4.0,"id":60443}]}]}
{"op":"mcm","clk":"11985372750","pt":1724898951260,"mc":[{"id":"1.232199708","rc":[{"batl":[[0,7.8,1],[1,85,2.5],[2,160,1.01]],"ltp":2.64,"tv":4.36,"id":424679},{"batl":[[0,5.5,1],[1,85,2.5],[2,940,1.01]],"ltp":0.0,"tv":0.0,"id":3961},{"batb":[[0,2.38,2.22],[1,2.36,6.23],[2,2,10]],"ltp":2.64,"tv":4.0,"id":60443}]}]}
{"op":"mcm","clk":"11985463090","pt":1724900743968,"mc":[{"id":"1.232199708","rc":[{"batb":[[2,1.61,5.06]],"ltp":2.64,"tv":4.36,"id":424679},{"batb":[[0,2.2,5],[1,1.5,20],[2,1.04,126.53]],"ltp":0.0,"tv":0.0,"id":3961},{"batb":[[1,2,10],[2,1.32,1.13]],"ltp":2.64,"tv":4.0,"id":60443}]}]}
{"op":"mcm","clk":"11985463807","pt":1724900758978,"mc":[{"id":"1.232199708","rc":[{"batb":[[0,2.22,6.95],[1,2.2,5],[2,1.5,20]],"ltp":0.0,"tv":0.0,"id":3961},{"batb":[[0,2.4,6.05],[1,2.38,2.22],[2,2,10]],"ltp":2.64,"tv":4.0,"id":60443}]}]}
{"op":"mcm","clk":"11985463912","pt":1724900761085,"mc":[{"id":"1.232199708","rc":[{"batl":[[0,85,2.5],[1,160,1.01],[2,990,3.17]],"ltp":2.64,"tv":4.36,"id":424679},{"batl":[[0,85,2.5],[1,940,1.01],[2,990,2.5]],"ltp":0.0,"tv":0.0,"id":3961},{"batb":[[1,2,10],[2,1.32,1.13]],"ltp":2.64,"tv":4.0,"id":60443}]}]}
{"op":"mcm","clk":"11985464234","pt":1724900766678,"mc":[{"id":"1.232199708","rc":[{"batl":[[0,5.3,1],[1,85,2.5],[2,940,1.01]],"ltp":0.0,"tv":0.0,"id":3961}]}]}
{"op":"mcm","clk":"11985464535","pt":1724900772278,"mc":[{"id":"1.232199708","rc":[{"batl":[[0,7.4,1],[1,85,2.5],[2,160,1.01]],"ltp":2.64,"tv":4.36,"id":424679},{"batb":[[0,2.42,2.18],[1,2.4,6.05],[2,2,10]],"ltp":2.64,"tv":4.0,"id":60443}]}]}
{"op":"mcm","clk":"11985521914","pt":1724901929223,"mc":[{"id":"1.232199708","rc":[{"batb":[[0,2.54,1],[1,2.52,10],[2,2.5,31.54]],"ltp":2.64,"tv":4.36,"id":424679},{"batb":[[0,2.22,8.09]],"ltp":0.0,"tv":0.0,"id":3961}]}]}
{"op":"mcm","clk":"11985521941","pt":1724901929529,"mc":[{"id":"1.232199708","rc":[{"batb":[[2,2.02,1.26]],"ltp":2.64,"tv":4.0,"id":60443}]}]}
{"op":"mcm","clk":"11985551586","pt":1724902559202,"mc":[{"id":"1.232199708","rc":[{"batb":[[0,2.22,1.14]],"ltp":0.0,"tv":0.0,"id":3961}]}]}
{"op":"mcm","clk":"11985551602","pt":1724902559609,"mc":[{"id":"1.232199708","rc":[{"batb":[[1,2.02,1.26],[2,2,10]],"ltp":2.64,"tv":4.0,"id":60443}]}]}
{"op":"mcm","clk":"11985558028","pt":1724902735466,"mc":[{"id":"1.232199708","rc":[{"batb":[[0,2.22,8.09]],"ltp":0.0,"tv":0.0,"id":3961},{"batb":[[0,2.44,5.89],[1,2.42,2.18],[2,2.02,1.26]],"ltp":2.64,"tv":4.0,"id":60443}]}]}
{"op":"mcm","clk":"11985558128","pt":1724902738188,"mc":[{"id":"1.232199708","rc":[{"batl":[[0,85,2.5],[1,160,1.01],[2,990,3.17]],"ltp":2.64,"tv":4.36,"id":424679},{"batl":[[0,85,2.5],[1,940,1.01],[2,990,2.5]],"ltp":0.0,"tv":0.0,"id":3961},{"batb":[[1,2.02,1.26],[2,2,10]],"ltp":2.64,"tv":4.0,"id":60443}]}]}
{"op":"mcm","clk":"11985558335","pt":1724902743648,"mc":[{"id":"1.232199708","rc":[{"batl":[[0,5.1,1],[1,85,2.5],[2,940,1.01]],"ltp":0.0,"tv":0.0,"id":3961}]}]}
{"op":"mcm","clk":"11985558543","pt":1724902749298,"mc":[{"id":"1.232199708","rc":[{"batl":[[0,7,1],[1,85,2.5],[2,160,1.01]],"ltp":2.64,"tv":4.36,"id":424679},{"batb":[[0,2.46,2.15],[1,2.44,5.89],[2,2.02,1.26]],"ltp":2.64,"tv":4.0,"id":60443}]}]}
{"op":"mcm","clk":"11985641429","pt":1724904535991,"mc":[{"id":"1.232199708","rc":[{"batb":[[0,2.22,1.14]],"ltp":0.0,"tv":0.0,"id":3961},{"batb":[[1,2.02,1.26],[2,2,10]],"ltp":2.64,"tv":4.0,"id":60443}]}]}
{"op":"mcm","clk":"11985648722","pt":1724904702285,"mc":[{"id":"1.232199708","rc":[{"batb":[[0,2.22,8.09]],"ltp":0.0,"tv":0.0,"id":3961},{"batb":[[0,2.48,5.73],[1,2.46,2.15],[2,2.02,1.26]],"ltp":2.64,"tv":4.0,"id":60443}]}]}
{"op":"mcm","clk":"11985648818","pt":1724904704176,"mc":[{"id":"1.232199708","rc":[{"batb":[[1,2.02,1.26],[2,2,10]],"ltp":2.64,"tv":4.0,"id":60443}]}]}
{"op":"mcm","clk":"11985649012","pt":1724904709657,"mc":[{"id":"1.232199708","rc":[{"batb":[[0,2.5,2.11],[1,2.48,5.73],[2,2.02,1.26]],"ltp":2.64,"tv":4.0,"id":60443}]}]}
{"op":"mcm","clk":"11985649207","pt":1724904715194,"mc":[{"id":"1.232199708","rc":[{"batl":[[0,85,2.5],[1,940,1.01],[2,990,2.5]],"ltp":0.0,"tv":0.0,"id":3961}]}]}
{"op":"mcm","clk":"11985649406","pt":1724904720778,"mc":[{"id":"1.232199708","rc":[{"batl":[[0,4.9,1],[1,85,2.5],[2,940,1.01]],"ltp":0.0,"tv":0.0,"id":3961}]}]}
{"op":"mcm","clk":"11985705682","pt":1724906502797,"mc":[{"id":"1.232199708","rc":[{"batb":[[0,2.22,1.14]],"ltp":0.0,"tv":0.0,"id":3961},{"batb":[[1,2.02,1.26],[2,2,10]],"ltp":2.64,"tv":4.0,"id":60443}]}]}
{"op":"mcm","clk":"11985710683","pt":1724906656579,"mc":[{"id":"1.232199708","rc":[{"batb":[[0,2.22,8.09]],"ltp":0.0,"tv":0.0,"id":3961},{"batb":[[0,2.52,5.58],[1,2.5,2.11],[2,2.02,1.26]],"ltp":2.64,"tv":4.0,"id":60443}]}]}
{"op":"mcm","clk":"11985710798","pt":1724906660661,"mc":[{"id":"1.232199708","rc":[{"batl":[[0,85,2.5],[1,160,1.01],[2,990,3.17]],"ltp":2.64,"tv":4.36,"id":424679},{"batb":[[1,2.02,1.26],[2,2,10]],"ltp":2.64,"tv":4.0,"id":60443}]}]}
{"op":"mcm","clk":"11985711129","pt":1724906671981,"mc":[{"id":"1.232199708","rc":[{"batl":[[0,6.4,1],[1,85,2.5],[2,160,1.01]],"ltp":2.64,"tv":4.36,"id":424679},{"batb":[[0,2.54,2.08],[1,2.52,5.58],[2,2.02,1.26]],"ltp":2.64,"tv":4.0,"id":60443}]}]}
{"op":"mcm","clk":"11985711276","pt":1724906677508,"mc":[{"id":"1.232199708","rc":[{"batl":[[0,85,2.5],[1,940,1.01],[2,990,2.5]],"ltp":0.0,"tv":0.0,"id":3961}]}]}
{"op":"mcm","clk":"11985711457","pt":1724906682869,"mc":[{"id":"1.232199708","rc":[{"batl":[[0,4.7,1],[1,85,2.5],[2,940,1.01]],"ltp":0.0,"tv":0.0,"id":3961}]}]}
{"op":"mcm","clk":"11985764996","pt":1724908374843,"mc":[{"id":"1.232199708","rc":[{"batb":[[0,2.22,8.09]],"ltp":0.0,"tv":0.0,"id":3961},{"batb":[[1,2.52,5.58]],"ltp":2.64,"tv":4.0,"id":60443}]}]}
{"op":"mcm","clk":"11985776857","pt":1724908457009,"mc":[{"id":"1.232199708","rc":[{"batb":[[0,2.22,1.14]],"ltp":0.0,"tv":0.0,"id":3961},{"batb":[[1,2.02,1.26],[2,2,10]],"ltp":2.64,"tv":4.0,"id":60443}]}]}
{"op":"mcm","clk":"11985781235","pt":1724908604237,"mc":[{"id":"1.232199708","rc":[{"batb":[[0,2.22,8.09]],"ltp":0.0,"tv":0.0,"id":3961},{"batb":[[0,2.56,5.43],[1,2.54,2.08],[2,2.02,1.26]],"ltp":2.64,"tv":4.0,"id":60443}]}]}
{"op":"mcm","clk":"11985781462","pt":1724908609850,"mc":[{"id":"1.232199708","rc":[{"batb":[[1,2.02,1.26],[2,2,10]],"ltp":2.64,"tv":4.0,"id":60443}]}]}
{"op":"mcm","clk":"11985781991","pt":1724908626633,"mc":[{"id":"1.232199708","rc":[{"batb":[[0,2.58,2.05],[1,2.56,5.43],[2,2.02,1.26]],"ltp":2.64,"tv":4.0,"id":60443}]}]}
{"op":"mcm","clk":"11985815754","pt":1724909706162,"mc":[{"id":"1.232199708","rc":[{"batb":[[0,2.54,6.06]],"ltp":2.64,"tv":4.36,"id":424679}]}]}
{"op":"mcm","clk":"11985815781","pt":1724909706829,"mc":[{"id":"1.232199708","rc":[{"batl":[[0,85,2.5],[1,940,1.01],[2,990,2.5]],"ltp":0.0,"tv":0.0,"id":3961}]}]}
{"op":"mcm","clk":"11985815970","pt":1724909712327,"mc":[{"id":"1.232199708","rc":[{"batl":[[0,4.5,1],[1,85,2.5],[2,940,1.01]],"ltp":0.0,"tv":0.0,"id":3961}]}]}
{"op":"mcm","clk":"11985838174","pt":1724910404738,"mc":[{"id":"1.232199708","rc":[{"batb":[[0,2.22,1.14]],"ltp":0.0,"tv":0.0,"id":3961},{"batb":[[1,2.02,1.26],[2,2,10]],"ltp":2.64,"tv":4.0,"id":60443}]}]}
{"op":"mcm","clk":"11985838215","pt":1724910405825,"mc":[{"id":"1.232199708","rc":[{"batl":[[0,2.58,2.5],[1,6.4,1],[2,85,2.5]],"ltp":2.64,"tv":4.36,"id":424679}]}]}
{"op":"mcm","clk":"11985838294","pt":1724910408443,"mc":[{"id":"1.232199708","rc":[{"batl":[[1,85,2.5],[2,160,1.01]],"ltp":2.64,"tv":4.36,"id":424679},{"batl":[[0,85,2.5],[1,940,1.01],[2,990,2.5]],"ltp":0.0,"tv":0.0,"id":3961}]}]}
{"op":"mcm","clk":"11985926917","pt":1724913494328,"mc":[{"id":"1.232199708","rc":[{"batb":[[0,2.54,6.06]],"batl":[[0,85,2.5],[1,160,1.01],[2,990,3.17]],"ltp":2.64,"tv":4.36,"id":424679}]}]}
{"op":"mcm","clk":"11985927052","pt":1724913499634,"mc":[{"id":"1.232199708","rc":[{"batl":[[0,21,1],[1,85,2.5],[2,160,1.01]],"ltp":2.64,"tv":4.36,"id":424679},{"batl":[[0,4.5,1],[1,85,2.5],[2,940,1.01]],"ltp":0.0,"tv":0.0,"id":3961}]}]}
{"op":"mcm","clk":"11985929129","pt":1724913578136,"mc":[{"id":"1.232199708","rc":[{"trd":[[2.2,3.72],[2.22,2.28]],"batb":[[0,2.2,3.14],[1,1.5,20],[2,1.04,126.53]],"ltp":2.2,"tv":6.0,"id":3961}],"tv":14.37}]}
{"op":"mcm","clk":"11985929850","pt":1724913603385,"mc":[{"id":"1.232199708","rc":[{"trd":[[2.2,7.32]],"batb":[[0,2.2,1.34]],"ltp":2.2,"tv":9.6,"id":3961}],"tv":17.97}]}
{"op":"mcm","clk":"11985930909","pt":1724913643641,"mc":[{"id":"1.232199708","rc":[{"trd":[[1.5,0.12],[2.2,10]],"batb":[[0,1.5,19.94],[1,1.04,126.53],[2,1.03,200]],"ltp":1.5,"tv":12.39,"id":3961}],"tv":20.77}]}
{"op":"mcm","clk":"11985933573","pt":1724913731315,"mc":[{"id":"1.232199708","rc":[{"batb":[[0,1.51,16.61],[1,1.5,19.94],[2,1.04,126.53]],"ltp":1.5,"tv":12.39,"id":3961},{"batb":[[0,2.6,5.3],[1,2.58,2.05],[2,2.02,1.26]],"ltp":2.64,"tv":4.0,"id":60443}]}]}
{"op":"mcm","clk":"11985933631","pt":1724913733615,"mc":[{"id":"1.232199708","rc":[{"batb":[[1,2.02,1.26],[2,2,10]],"ltp":2.64,"tv":4.0,"id":60443}]}]}
{"op":"mcm","clk":"11985933794","pt":1724913739256,"mc":[{"id":"1.232199708","rc":[{"batb":[[0,2.62,2.02],[1,2.6,5.3],[2,2.02,1.26]],"ltp":2.64,"tv":4.0,"id":60443}]}]}
{"op":"mcm","clk":"11985979025","pt":1724914718556,"mc":[{"id":"1.232199708","rc":[{"batl":[[1,85,3.03]],"ltp":2.64,"tv":4.0,"id":60443}]}]}
{"op":"mcm","clk":"11985979305","pt":1724914726543,"mc":[{"id":"1.232199708","rc":[{"batl":[[0,21,1.53]],"ltp":2.64,"tv":4.36,"id":424679}]}]}
{"op":"mcm","clk":"11985979684","pt":1724914738348,"mc":[{"id":"1.232199708","rc":[{"batb":[[0,1.51,17.14]],"ltp":1.5,"tv":12.39,"id":3961}]}]}
{"op":"mcm","clk":"11986005375","pt":1724915531477,"mc":[{"id":"1.232199708","rc":[{"trd":[[1.21,1.94]],"batb":[[0,2.54,6.05]],"ltp":2.64,"tv":4.36,"id":424679},{"batb":[[0,1.5,20.47],[1,1.04,126.53],[2,1.03,200]],"ltp":1.5,"tv":12.39,"id":3961},{"batb":[[1,2.6,5.29]],"ltp":2.64,"tv":4.0,"id":60443}],"tv":20.77}]}
{"op":"mcm","clk":"11986005380","pt":1724915531681,"mc":[{"id":"1.232199708","rc":[{"batb":[[1,2.02,1.26],[2,2,10]],"ltp":2.64,"tv":4.0,"id":60443}]}]}
{"op":"mcm","clk":"11986009997","pt":1724915671281,"mc":[{"id":"1.232199708","rc":[{"batb":[[0,1.51,17.13],[1,1.5,19.94],[2,1.04,126.53]],"ltp":1.5,"tv":12.39,"id":3961},{"batb":[[0,2.64,5.16],[1,2.62,2.02],[2,2.02,1.26]],"ltp":2.64,"tv":4.0,"id":60443}]}]}
{"op":"mcm","clk":"11986010006","pt":1724915671537,"mc":[{"id":"1.232199708","rc":[{"batl":[[0,85,2.5],[1,940,1.01],[2,990,2.5]],"ltp":1.5,"tv":12.39,"id":3961},{"batb":[[1,2.02,1.26],[2,2,10]],"ltp":2.64,"tv":4.0,"id":60443}]}]}
{"op":"mcm","clk":"11986010179","pt":1724915677072,"mc":[{"id":"1.232199708","rc":[{"batl":[[0,4.3,1],[1,85,2.5],[2,940,1.01]],"ltp":1.5,"tv":12.39,"id":3961}]}]}
{"op":"mcm","clk":"11986010364","pt":1724915682675,"mc":[{"id":"1.232199708","rc":[{"batb":[[0,2.66,1.98],[1,2.64,5.16],[2,2.02,1.26]],"ltp":2.64,"tv":4.0,"id":60443}]}]}
{"op":"mcm","clk":"11986046502","pt":1724916545683,"mc":[{"id":"1.232199708","rc":[{"batl":[[0,16,1.45],[1,21,1],[2,85,2.5]],"ltp":2.64,"tv":4.36,"id":424679}]}]}
{"op":"mcm","clk":"11986046736","pt":1724916551467,"mc":[{"id":"1.232199708","rc":[{"batl":[[1,85,2.5],[2,160,1.01]],"ltp":2.64,"tv":4.36,"id":424679}]}]}
{"op":"mcm","clk":"11986046977","pt":1724916556986,"mc":[{"id":"1.232199708","rc":[{"batl":[[0,15.5,1.92],[1,85,3.03]],"ltp":2.64,"tv":4.36,"id":424679}]}]}
{"op":"mcm","clk":"11986058976","pt":1724916833000,"mc":[{"id":"1.232199708","rc":[{"batl":[[0,4.8,1],[1,4.9,2],[2,85,3.03]],"ltp":2.64,"tv":4.0,"id":60443}]}]}
{"op":"mcm","clk":"11986081752","pt":1724917471704,"mc":[{"id":"1.232199708","rc":[{"batb":[[0,1.5,20.47],[1,1.04,126.53],[2,1.03,200]],"ltp":1.5,"tv":12.39,"id":3961},{"batb":[[1,2.02,1.26],[2,2,10]],"ltp":2.64,"tv":4.0,"id":60443}]}]}
{"op":"mcm","clk":"11986086823","pt":1724917614858,"mc":[{"id":"1.232199708","rc":[{"batb":[[0,1.51,17.13],[1,1.5,19.94],[2,1.04,126.53]],"ltp":1.5,"tv":12.39,"id":3961},{"batb":[[0,2.68,5.04],[1,2.66,1.98],[2,2.02,1.26]],"ltp":2.64,"tv":4.0,"id":60443}]}]}
{"op":"mcm","clk":"11986087014","pt":1724917620790,"mc":[{"id":"1.232199708","rc":[{"batb":[[1,2.02,1.26],[2,2,10]],"ltp":2.64,"tv":4.0,"id":60443}]}]}
{"op":"mcm","clk":"11986087187","pt":1724917626281,"mc":[{"id":"1.232199708","rc":[{"batb":[[0,2.7,1.96],[1,2.68,5.04],[2,2.02,1.26]],"ltp":2.64,"tv":4.0,"id":60443}]}]}
{"op":"mcm","clk":"11986096232","pt":1724917877283,"mc":[{"id":"1.232199708","rc":[{"trd":[[2.7,3.92]],"batb":[[0,2.68,5.04],[1,2.02,1.26],[2,2,10]],"batl":[[0,2.7,3.04],[1,4.8,1],[2,4.9,2]],"ltp":2.7,"tv":7.92,"id":60443}],"tv":24.69}]}
{"op":"mcm","clk":"11986098472","pt":1724917937953,"mc":[{"id":"1.232199708","rc":[{"batl":[[0,4.8,1],[1,4.9,2],[2,85,3.03]],"ltp":2.7,"tv":7.92,"id":60443}]}]}
{"op":"mcm","clk":"11986100323","pt":1724917983783,"mc":[{"id":"1.232199708","rc":[{"trd":[[4.8,2]],"batb":[[0,4.8,2],[1,2.68,5.04],[2,2.02,1.26]],"batl":[[0,4.9,2],[1,85,3.03],[2,940,1.01]],"ltp":4.8,"tv":9.92,"id":60443}],"tv":26.69}]}
{"op":"mcm","clk":"11986100484","pt":1724917988296,"mc":[{"id":"1.232199708","rc":[{"batl":[[0,16,1.45],[1,85,2.5]],"ltp":2.64,"tv":4.36,"id":424679},{"batl":[[0,85,2.5],[1,940,1.01],[2,990,2.5]],"ltp":1.5,"tv":12.39,"id":3961}]}]}
{"op":"mcm","clk":"11986100737","pt":1724917993794,"mc":[{"id":"1.232199708","rc":[{"batl":[[0,7.6,1],[1,16,1.45],[2,85,2.5]],"ltp":2.64,"tv":4.36,"id":424679}]}]}
{"op":"mcm","clk":"11986100873","pt":1724917997492,"mc":[{"id":"1.232199708","rc":[{"batb":[[0,4.4,2]],"ltp":4.8,"tv":9.92,"id":60443}]}]}
{"op":"mcm","clk":"11986101172","pt":1724918005930,"mc":[{"id":"1.232199708","rc":[{"batb":[[0,2.68,5.04],[1,2.02,1.26],[2,2,10]],"ltp":4.8,"tv":9.92,"id":60443}]}]}
{"op":"mcm","clk":"11986101420","pt":1724918010632,"mc":[{"id":"1.232199708","rc":[{"batl":[[0,4.2,1],[1,85,2.5],[2,940,1.01]],"ltp":1.5,"tv":12.39,"id":3961}]}]}
{"op":"mcm","clk":"11986116687","pt":1724918363722,"mc":[{"id":"1.232199708","rc":[{"batb":[[0,1.65,2.1],[1,1.51,17.13],[2,1.5,19.94]],"ltp":1.5,"tv":12.39,"id":3961}]}]}
{"op":"mcm","clk":"11986117064","pt":1724918372820,"mc":[{"id":"1.232199708","rc":[{"batl":[[1,85,3.03],[2,160,1.01]],"ltp":2.64,"tv":4.36,"id":424679}]}]}
{"op":"mcm","clk":"11986145379","pt":1724918986225,"mc":[{"id":"1.232199708","rc":[{"trd":[[1.65,2]],"batb":[[0,1.65,1.09]],"ltp":1.65,"tv":14.39,"id":3961}],"tv":28.69}]}
{"op":"mcm","clk":"11986168263","pt":1724919238648,"mc":[{"id":"1.232199708","rc":[{"batl":[[0,4.2,1.56]],"ltp":1.65,"tv":14.39,"id":3961}]}]}
{"op":"mcm","clk":"11986172168","pt":1724919324725,"mc":[{"id":"1.232199708","rc":[{"batb":[[0,1.51,17.13],[1,1.5,19.94],[2,1.04,126.53]],"ltp":1.65,"tv":14.39,"id":3961}]}]}
{"op":"mcm","clk":"11986177191","pt":1724919415436,"mc":[{"id":"1.232199708","rc":[{"batb":[[0,1.5,20.47],[1,1.04,126.53],[2,1.03,200]],"ltp":1.65,"tv":14.39,"id":3961},{"batb":[[0,2.02,1.26],[1,2,10],[2,1.32,1.13]],"ltp":4.8,"tv":9.92,"id":60443}]}]}
{"op":"mcm","clk":"11986177401","pt":1724919419644,"mc":[{"id":"1.232199708","rc":[{"batl":[[0,4.8,1],[1,4.9,2],[2,85,3.03]],"ltp":4.8,"tv":9.92,"id":60443}]}]}
{"op":"mcm","clk":"11986189608","pt":1724919641126,"mc":[{"id":"1.232199708","rc":[{"batb":[[0,1.52,16.81],[1,1.5,19.94],[2,1.04,126.53]],"ltp":1.65,"tv":14.39,"id":3961},{"batb":[[0,2.02,9.56]],"ltp":4.8,"tv":9.92,"id":60443}]}]}
{"op":"mcm","clk":"11986277917","pt":1724921441298,"mc":[{"id":"1.232199708","rc":[{"batb":[[0,2.02,1.26]],"ltp":4.8,"tv":9.92,"id":60443}]}]}
{"op":"mcm","clk":"11986277932","pt":1724921441505,"mc":[{"id":"1.232199708","rc":[{"batb":[[0,1.5,20.47],[1,1.04,126.53],[2,1.03,200]],"ltp":1.65,"tv":14.39,"id":3961}]}]}
{"op":"mcm","clk":"11986278097","pt":1724921444437,"mc":[{"id":"1.232199708","rc":[{"batb":[[0,1.52,16.81],[1,1.5,19.94],[2,1.04,126.53]],"ltp":1.65,"tv":14.39,"id":3961},{"batb":[[0,2.02,9.56]],"ltp":4.8,"tv":9.92,"id":60443}]}]}
{"op":"mcm","clk":"11986287547","pt":1724921633500,"mc":[{"id":"1.232199708","rc":[{"batl":[[0,3.85,1],[1,4.8,1],[2,4.9,2]],"ltp":4.8,"tv":9.92,"id":60443}]}]}
{"op":"mcm","clk":"11986287678","pt":1724921636322,"mc":[{"id":"1.232199708","rc":[{"batl":[[1,4.9,2],[2,85,3.03]],"ltp":4.8,"tv":9.92,"id":60443}]}]}
{"op":"mcm","clk":"11986296456","pt":1724921794503,"mc":[{"id":"1.232199708","rc":[{"batl":[[0,4.9,2],[1,85,3.03],[2,940,1.01]],"ltp":4.8,"tv":9.92,"id":60443}]}]}
{"op":"mcm","clk":"11986296603","pt":1724921797990,"mc":[{"id":"1.232199708","rc":[{"batl":[[0,4.8,1],[1,4.9,2],[2,85,3.03]],"ltp":4.8,"tv":9.92,"id":60443}]}]}
{"op":"mcm","clk":"11986297726","pt":1724921820848,"mc":[{"id":"1.232199708","rc":[{"batb":[[0,2.02,9.99]],"ltp":4.8,"tv":9.92,"id":60443}]}]}
{"op":"mcm","clk":"11986310234","pt":1724922055398,"mc":[{"id":"1.232199708","rc":[{"batb":[[0,2.54,6.04]],"batl":[[0,7.6,1.3],[1,85,3.03],[2,160,1.01]],"ltp":2.64,"tv":4.36,"id":424679},{"trd":[[1.65,2]],"batb":[[0,1.52,17.08]],"batl":[[0,4.2,1.86],[2,940,1.01]],"ltp":1.65,"tv":14.4,"id":3961},{"batb":[[0,2.02,9.98],[2,1.32,1.13]],"batl":[[0,4.8,1.3],[2,85,3.03]],"ltp":4.8,"tv":9.92,"id":60443}],"tv":28.69}]}
{"op":"mcm","clk":"11986310257","pt":1724922055707,"mc":[{"id":"1.232199708","rc":[{"batb":[[0,2.54,6.34]],"ltp":2.64,"tv":4.36,"id":424679},{"batb":[[0,2.02,10.28]],"ltp":4.8,"tv":9.92,"id":60443}]}]}
{"op":"mcm","clk":"11986319443","pt":1724922292041,"mc":[{"id":"1.232199708","rc":[{"batb":[[0,2.02,9.98]],"ltp":4.8,"tv":9.92,"id":60443}]}]}
{"op":"mcm","clk":"11986319468","pt":1724922292556,"mc":[{"id":"1.232199708","rc":[{"batb":[[0,2.54,6.04]],"ltp":2.64,"tv":4.36,"id":424679}]}]}
{"op":"mcm","clk":"11986319544","pt":1724922294362,"mc":[{"id":"1.232199708","rc":[{"batl":[[0,7.6,1]],"ltp":2.64,"tv":4.36,"id":424679},{"batb":[[0,1.52,16.78]],"ltp":1.65,"tv":14.4,"id":3961}]}]}
{"op":"mcm","clk":"11986319568","pt":1724922294783,"mc":[{"id":"1.232199708","rc":[{"batl":[[0,4.2,1.56]],"ltp":1.65,"tv":14.4,"id":3961},{"batl":[[0,4.8,1]],"ltp":4.8,"tv":9.92,"id":60443}]}]}
{"op":"mcm","clk":"11986319661","pt":1724922297363,"mc":[{"id":"1.232199708","rc":[{"batb":[[0,2.54,6.34]],"batl":[[0,7.6,1.3]],"ltp":2.64,"tv":4.36,"id":424679},{"batb":[[0,1.52,17.08]],"batl":[[0,4.2,1.86]],"ltp":1.65,"tv":14.4,"id":3961},{"batl":[[0,4.8,1.3]],"ltp":4.8,"tv":9.92,"id":60443}]}]}
{"op":"mcm","clk":"11986319673","pt":1724922297671,"mc":[{"id":"1.232199708","rc":[{"batb":[[0,2.02,10.28]],"ltp":4.8,"tv":9.92,"id":60443}]}]}
{"op":"mcm","clk":"11986332847","pt":1724922618441,"mc":[{"id":"1.232199708","rc":[{"batb":[[0,2.54,6.64]],"batl":[[0,7.6,1.6]],"ltp":2.64,"tv":4.36,"id":424679},{"batb":[[0,1.53,1.13],[1,1.52,16.25],[2,1.5,19.94]],"batl":[[0,4.1,1.16],[1,4.2,1],[2,85,2.5]],"ltp":1.65,"tv":14.4,"id":3961},{"batb":[[0,2.04,1.03],[1,2.02,9.55],[2,2,10]],"batl":[[0,4.8,1.6]],"ltp":4.8,"tv":9.92,"id":60443}]}]}
{"op":"mcm","clk":"11986332923","pt":1724922620650,"mc":[{"id":"1.232199708","rc":[{"batb":[[0,2.02,10.28],[1,2,10],[2,1.32,1.13]],"ltp":4.8,"tv":9.92,"id":60443}]}]}
{"op":"mcm","clk":"11986332993","pt":1724922622341,"mc":[{"id":"1.232199708","rc":[{"batl":[[1,85,2.5],[2,940,1.01]],"ltp":1.65,"tv":14.4,"id":3961}]}]}
{"op":"mcm","clk":"11986333013","pt":1724922622744,"mc":[{"id":"1.232199708","rc":[{"batb":[[0,2.54,6.34]],"ltp":2.64,"tv":4.36,"id":424679},{"batb":[[0,1.52,17.08],[1,1.5,19.94],[2,1.04,126.53]],"ltp":1.65,"tv":14.4,"id":3961}]}]}
{"op":"mcm","clk":"11986333061","pt":1724922624264,"mc":[{"id":"1.232199708","rc":[{"batl":[[0,7.6,1.3]],"ltp":2.64,"tv":4.36,"id":424679},{"batl":[[0,85,3.36],[1,940,1.01],[2,990,2.5]],"ltp":1.65,"tv":14.4,"id":3961},{"batl":[[0,4.8,1.3]],"ltp":4.8,"tv":9.92,"id":60443}]}]}
{"op":"mcm","clk":"11986334530","pt":1724922655667,"mc":[{"id":"1.232199708","rc":[{"batl":[[0,8.6,1.86],[1,85,2.5],[2,940,1.01]],"ltp":1.65,"tv":14.4,"id":3961}]}]}
{"op":"mcm","clk":"11986348364","pt":1724922911072,"mc":[{"id":"1.232199708","rc":[{"batb":[[0,2.54,6.64]],"batl":[[0,7.6,1.6]],"ltp":2.64,"tv":4.36,"id":424679},{"batb":[[0,1.54,1.13],[1,1.52,16.25],[2,1.5,19.94]],"batl":[[0,8.4,1.16],[1,8.6,1],[2,85,2.5]],"ltp":1.65,"tv":14.4,"id":3961},{"batb":[[0,2.04,1.03],[1,2.02,9.55],[2,2,10]],"batl":[[0,4.8,1.6]],"ltp":4.8,"tv":9.92,"id":60443}]}]}
{"op":"mcm","clk":"11986348401","pt":1724922911853,"mc":[{"id":"1.232199708","rc":[{"batl":[[1,85,2.5],[2,940,1.01]],"ltp":1.65,"tv":14.4,"id":3961}]}]}
{"op":"mcm","clk":"11986348708","pt":1724922917351,"mc":[{"id":"1.232199708","rc":[{"batl":[[0,8.2,1.86],[1,85,2.8]],"ltp":1.65,"tv":14.4,"id":3961}]}]}
{"op":"mcm","clk":"11986348910","pt":1724922921863,"mc":[{"id":"1.232199708","rc":[{"batb":[[0,1.52,17.08],[1,1.5,19.94],[2,1.04,126.53]],"ltp":1.65,"tv":14.4,"id":3961}]}]}
{"op":"mcm","clk":"11986349074","pt":1724922924472,"mc":[{"id":"1.232199708","rc":[{"batb":[[0,2.02,10.28],[1,2,10],[2,1.32,1.13]],"ltp":4.8,"tv":9.92,"id":60443}]}]}
{"op":"mcm","clk":"11986349131","pt":1724922925354,"mc":[{"id":"1.232199708","rc":[{"batb":[[0,2.54,6.34]],"ltp":2.64,"tv":4.36,"id":424679}]}]}
{"op":"mcm","clk":"11986349179","pt":1724922926280,"mc":[{"id":"1.232199708","rc":[{"batl":[[0,7.6,1.3]],"ltp":2.64,"tv":4.36,"id":424679},{"batl":[[0,8.2,1.56]],"ltp":1.65,"tv":14.4,"id":3961},{"batl":[[0,4.8,1.3]],"ltp":4.8,"tv":9.92,"id":60443}]}]}
{"op":"mcm","clk":"11986363466","pt":1724923167915,"mc":[{"id":"1.232199708","rc":[{"batl":[[0,2.58,2.53],[1,7.6,1.3],[2,85,3.03]],"ltp":2.64,"tv":4.36,"id":424679}]}]}
{"op":"mcm","clk":"11986363753","pt":1724923173436,"mc":[{"id":"1.232199708","rc":[{"batl":[[1,85,3.33],[2,160,1.01]],"ltp":2.64,"tv":4.36,"id":424679}]}]}
{"op":"mcm","clk":"11986365684","pt":1724923211411,"mc":[{"id":"1.232199708","rc":[{"batb":[[0,2.54,6.04]],"ltp":2.64,"tv":4.36,"id":424679}]}]}
{"op":"mcm","clk":"11986365759","pt":1724923213001,"mc":[{"id":"1.232199708","rc":[{"batl":[[1,85,3.03]],"ltp":2.64,"tv":4.36,"id":424679},{"batl":[[1,85,2.5]],"ltp":1.65,"tv":14.4,"id":3961},{"batl":[[0,4.8,1]],"ltp":4.8,"tv":9.92,"id":60443}]}]}
{"op":"mcm","clk":"11986365832","pt":1724923214289,"mc":[{"id":"1.232199708","rc":[{"batb":[[0,2.54,6.34]],"ltp":2.64,"tv":4.36,"id":424679},{"batb":[[2,1.04,126.83]],"batl":[[0,8.2,1.86]],"ltp":1.65,"tv":14.4,"id":3961},{"batl":[[0,4.8,1.3]],"ltp":4.8,"tv":9.92,"id":60443}]}]}
{"op":"mcm","clk":"11986365863","pt":1724923214703,"mc":[{"id":"1.232199708","rc":[{"batb":[[0,1.54,1.13],[1,1.52,16.25],[2,1.5,19.94]],"ltp":1.65,"tv":14.4,"id":3961},{"batb":[[0,2.04,1.03],[1,2.02,9.55],[2,2,10]],"ltp":4.8,"tv":9.92,"id":60443}]}]}
{"op":"mcm","clk":"11986366027","pt":1724923218192,"mc":[{"id":"1.232199708","rc":[{"batb":[[0,1.52,17.08],[1,1.5,19.94],[2,1.04,126.53]],"ltp":1.65,"tv":14.4,"id":3961},{"batb":[[0,2.02,10.28],[1,2,10],[2,1.32,1.13]],"ltp":4.8,"tv":9.92,"id":60443}]}]}
{"op":"mcm","clk":"11986367232","pt":1724923243339,"mc":[{"id":"1.232199708","rc":[{"batl":[[0,85,3.03],[1,160,1.01],[2,990,3.17]],"ltp":2.64,"tv":4.36,"id":424679}]}]}
{"op":"mcm","clk":"11986367309","pt":1724923245136,"mc":[{"id":"1.232199708","rc":[{"batl":[[0,85,3.33]],"ltp":2.64,"tv":4.36,"id":424679},{"batb":[[0,1.5,20.77],[1,1.04,126.53],[2,1.03,200]],"ltp":1.65,"tv":14.4,"id":3961},{"batb":[[0,2.02,1.99]],"ltp":4.8,"tv":9.92,"id":60443}]}]}
{"op":"mcm","clk":"11986367364","pt":1724923246420,"mc":[{"id":"1.232199708","rc":[{"batl":[[0,80,1.83],[1,85,2.5],[2,160,1.01]],"ltp":2.64,"tv":4.36,"id":424679},{"batb":[[0,1.51,17.4],[1,1.5,19.94],[2,1.04,126.53]],"ltp":1.65,"tv":14.4,"id":3961},{"batb":[[0,2.04,8.86],[1,2.02,1.26],[2,2,10]],"ltp":4.8,"tv":9.92,"id":60443}]}]}
{"op":"mcm","clk":"11986373337","pt":1724923358275,"mc":[{"id":"1.232199708","rc":[{"batl":[[0,75,3.03],[1,80,1.3]],"ltp":2.64,"tv":4.36,"id":424679}]}]}
{"op":"mcm","clk":"11986373375","pt":1724923358954,"mc":[{"id":"1.232199708","rc":[{"batl":[[0,2.58,2.53],[1,75,3.03],[2,80,1.3]],"ltp":2.64,"tv":4.36,"id":424679}]}]}
{"op":"mcm","clk":"11986373596","pt":1724923362879,"mc":[{"id":"1.232199708","rc":[{"batl":[[2,90,1.14]],"ltp":2.64,"tv":4.36,"id":424679}]}]}
{"op":"mcm","clk":"11986375502","pt":1724923398286,"mc":[{"id":"1.232199708","rc":[{"trd":[[2.58,5.06]],"batb":[[0,2.58,29.01],[1,2.54,6.34],[2,2.52,10]],"batl":[[0,75,3.03],[1,90,1.14],[2,990,3.34]],"ltp":2.58,"tv":9.42,"id":424679}],"tv":33.75}]}
{"op":"mcm","clk":"11986375690","pt":1724923401880,"mc":[{"id":"1.232199708","rc":[{"batl":[[0,70,1.53],[1,75,2.5],[2,90,1.14]],"ltp":2.58,"tv":9.42,"id":424679}]}]}
{"op":"mcm","clk":"11986376467","pt":1724923417711,"mc":[{"id":"1.232199708","rc":[{"batl":[[0,65,3.03],[1,70,1]],"ltp":2.58,"tv":9.42,"id":424679}]}]}
{"op":"mcm","clk":"11986376505","pt":1724923418529,"mc":[{"id":"1.232199708","rc":[{"batl":[[1,90,1.14],[2,990,3.34]],"ltp":2.58,"tv":9.42,"id":424679}]}]}
{"op":"mcm","clk":"11986376810","pt":1724923424125,"mc":[{"id":"1.232199708","rc":[{"batl":[[0,60,1.53],[1,65,2.5],[2,90,1.14]],"ltp":2.58,"tv":9.42,"id":424679}]}]}
{"op":"mcm","clk":"11986377225","pt":1724923430653,"mc":[{"id":"1.232199708","rc":[{"batl":[[0,15.5,2.5],[1,60,1.53]],"ltp":2.58,"tv":9.42,"id":424679}]}]}
{"op":"mcm","clk":"11986377467","pt":1724923435351,"mc":[{"id":"1.232199708","rc":[{"batl":[[1,90,1.67],[2,990,3.34]],"ltp":2.58,"tv":9.42,"id":424679}]}]}
{"op":"mcm","clk":"11986377773","pt":1724923440846,"mc":[{"id":"1.232199708","rc":[{"batl":[[0,15,1],[1,15.5,2.5],[2,90,1.67]],"ltp":2.58,"tv":9.42,"id":424679}]}]}
{"op":"mcm","clk":"11986378257","pt":1724923449479,"mc":[{"id":"1.232199708","rc":[{"batl":[[1,90,1.67],[2,990,3.34]],"ltp":2.58,"tv":9.42,"id":424679}]}]}
{"op":"mcm","clk":"11986378261","pt":1724923449581,"mc":[{"id":"1.232199708","rc":[{"batl":[[0,14.5,2.5],[1,15,1],[2,90,1.67]],"ltp":2.58,"tv":9.42,"id":424679}]}]}
{"op":"mcm","clk":"11986378412","pt":1724923452073,"mc":[{"id":"1.232199708","rc":[{"batl":[[1,90,1.67],[2,990,3.34]],"ltp":2.58,"tv":9.42,"id":424679}]}]}
{"op":"mcm","clk":"11986378479","pt":1724923453057,"mc":[{"id":"1.232199708","rc":[{"batb":[[0,2.54,6.34],[1,2.52,10],[2,1.5,20]],"ltp":2.58,"tv":9.42,"id":424679}]}]}
{"op":"mcm","clk":"11986378587","pt":1724923455278,"mc":[{"id":"1.232199708","rc":[{"batb":[[2,2.5,28.93]],"ltp":2.58,"tv":9.42,"id":424679}]}]}
{"op":"mcm","clk":"11986378697","pt":1724923457499,"mc":[{"id":"1.232199708","rc":[{"batl":[[0,14,1],[1,14.5,2.5],[2,90,1.67]],"ltp":2.58,"tv":9.42,"id":424679}]}]}
{"op":"mcm","clk":"11986379229","pt":1724923467491,"mc":[{"id":"1.232199708","rc":[{"batl":[[1,90,1.67],[2,990,3.34]],"ltp":2.58,"tv":9.42,"id":424679}]}]}
{"op":"mcm","clk":"11986379233","pt":1724923467592,"mc":[{"id":"1.232199708","rc":[{"batl":[[0,10,2.5],[1,14,1],[2,90,1.67]],"ltp":2.58,"tv":9.42,"id":424679}]}]}
{"op":"mcm","clk":"11986379279","pt":1724923468574,"mc":[{"id":"1.232199708","rc":[{"batl":[[1,90,1.67],[2,990,3.34]],"ltp":2.58,"tv":9.42,"id":424679}]}]}
{"op":"mcm","clk":"11986379519","pt":1724923474293,"mc":[{"id":"1.232199708","rc":[{"batl":[[0,9.8,1],[1,10,2.5],[2,90,1.67]],"ltp":2.58,"tv":9.42,"id":424679}]}]}
{"op":"mcm","clk":"11986380510","pt":1724923494484,"mc":[{"id":"1.232199708","rc":[{"batl":[[1,90,1.67],[2,990,3.34]],"ltp":2.58,"tv":9.42,"id":424679}]}]}
{"op":"mcm","clk":"11986380513","pt":1724923494589,"mc":[{"id":"1.232199708","rc":[{"batl":[[1,85,3.33],[2,160,1.01]],"ltp":2.58,"tv":9.42,"id":424679}]}]}
{"op":"mcm","clk":"11986380879","pt":1724923502600,"mc":[{"id":"1.232199708","rc":[{"batb":[[2,1.5,20]],"ltp":2.58,"tv":9.42,"id":424679}]}]}
{"op":"mcm","clk":"11986380959","pt":1724923503686,"mc":[{"id":"1.232199708","rc":[{"batb":[[0,2.56,28.55],[1,2.54,6.04],[2,2.52,10]],"ltp":2.58,"tv":9.42,"id":424679}]}]}
{"op":"mcm","clk":"11986381695","pt":1724923517414,"mc":[{"id":"1.232199708","rc":[{"batb":[[2,1.04,126.83]],"batl":[[0,8,1.16],[1,8.2,1],[2,85,2.5]],"ltp":1.65,"tv":14.4,"id":3961},{"batl":[[0,4.8,1.6]],"ltp":4.8,"tv":9.92,"id":60443}]}]}
{"op":"mcm","clk":"11986381715","pt":1724923517725,"mc":[{"id":"1.232199708","rc":[{"batb":[[0,2.56,28.85]],"ltp":2.58,"tv":9.42,"id":424679},{"batb":[[0,1.52,1.13],[1,1.51,16.57],[2,1.5,19.94]],"ltp":1.65,"tv":14.4,"id":3961},{"batb":[[0,2.04,9.16]],"ltp":4.8,"tv":9.92,"id":60443}]}]}
{"op":"mcm","clk":"11986381776","pt":1724923518812,"mc":[{"id":"1.232199708","rc":[{"batl":[[1,85,2.5],[2,940,1.01]],"ltp":1.65,"tv":14.4,"id":3961}]}]}
{"op":"mcm","clk":"11986381861","pt":1724923520409,"mc":[{"id":"1.232199708","rc":[{"batb":[[0,2.04,8.86]],"ltp":4.8,"tv":9.92,"id":60443}]}]}
{"op":"mcm","clk":"11986381946","pt":1724923521841,"mc":[{"id":"1.232199708","rc":[{"batb":[[0,1.51,17.4],[1,1.5,19.94],[2,1.04,126.53]],"ltp":1.65,"tv":14.4,"id":3961}]}]}
{"op":"mcm","clk":"11986382020","pt":1724923523331,"mc":[{"id":"1.232199708","rc":[{"batb":[[0,2.56,28.55]],"ltp":2.58,"tv":9.42,"id":424679},{"batl":[[0,4.8,1.3]],"ltp":4.8,"tv":9.92,"id":60443}]}]}
{"op":"mcm","clk":"11986382092","pt":1724923524511,"mc":[{"id":"1.232199708","rc":[{"batl":[[0,85,3.36],[1,940,1.01],[2,990,2.5]],"ltp":1.65,"tv":14.4,"id":3961}]}]}
{"op":"mcm","clk":"11986382629","pt":1724923535547,"mc":[{"id":"1.232199708","rc":[{"batl":[[0,8.2,1.86],[1,85,2.5],[2,940,1.01]],"ltp":1.65,"tv":14.4,"id":3961}]}]}
{"op":"mcm","clk":"11986383072","pt":1724923546443,"mc":[{"id":"1.232199708","rc":[{"batl":[[1,85,3.03]],"ltp":2.58,"tv":9.42,"id":424679}]}]}
{"op":"mcm","clk":"11986383254","pt":1724923550333,"mc":[{"id":"1.232199708","rc":[{"batl":[[0,9.8,1.3]],"ltp":2.58,"tv":9.42,"id":424679}]}]}
{"op":"mcm","clk":"11986397051","pt":1724923817474,"mc":[{"id":"1.232199708","rc":[{"batb":[[0,1.52,1.13],[1,1.51,16.57],[2,1.5,19.94]],"batl":[[0,8,1.16],[1,8.2,1],[2,85,2.5]],"ltp":1.65,"tv":14.4,"id":3961},{"batb":[[0,2.04,9.16]],"batl":[[0,4.8,1.6]],"ltp":4.8,"tv":9.92,"id":60443}]}]}
{"op":"mcm","clk":"11986397073","pt":1724923817882,"mc":[{"id":"1.232199708","rc":[{"batb":[[0,2.56,28.85]],"ltp":2.58,"tv":9.42,"id":424679}]}]}
{"op":"mcm","clk":"11986397155","pt":1724923819475,"mc":[{"id":"1.232199708","rc":[{"batb":[[0,1.51,17.4],[1,1.5,19.94],[2,1.04,126.53]],"ltp":1.65,"tv":14.4,"id":3961}]}]}
{"op":"mcm","clk":"11986397177","pt":1724923819786,"mc":[{"id":"1.232199708","rc":[{"batb":[[0,2.56,28.55]],"ltp":2.58,"tv":9.42,"id":424679},{"batl":[[1,85,2.5],[2,940,1.01]],"ltp":1.65,"tv":14.4,"id":3961}]}]}
{"op":"mcm","clk":"11986397233","pt":1724923820657,"mc":[{"id":"1.232199708","rc":[{"batb":[[0,2.04,8.86]],"ltp":4.8,"tv":9.92,"id":60443}]}]}
{"op":"mcm","clk":"11986397378","pt":1724923823487,"mc":[{"id":"1.232199708","rc":[{"batl":[[0,85,3.36],[1,940,1.01],[2,990,2.5]],"ltp":1.65,"tv":14.4,"id":3961},{"batl":[[0,4.8,1.3]],"ltp":4.8,"tv":9.92,"id":60443}]}]}
{"op":"mcm","clk":"11986397706","pt":1724923830695,"mc":[{"id":"1.232199708","rc":[{"batl":[[0,8.2,1.86],[1,85,2.5],[2,940,1.01]],"ltp":1.65,"tv":14.4,"id":3961}]}]}
{"op":"mcm","clk":"11986399327","pt":1724923859815,"mc":[{"id":"1.232199708","rc":[{"trd":[[2.04,1.4],[2.06,0.6]],"batb":[[0,2.04,7.86]],"ltp":2.04,"tv":11.93,"id":60443}],"tv":35.75}]}
{"op":"mcm","clk":"11986412874","pt":1724924048867,"mc":[{"id":"1.232199708","rc":[{"trd":[[2.58,5.66]],"batb":[[0,2.56,28.25]],"batl":[[0,2.58,2.23],[1,9.8,1.3],[2,85,3.03]],"ltp":2.58,"tv":10.02,"id":424679}],"tv":36.35}]}
{"op":"mcm","clk":"11986413182","pt":1724924053465,"mc":[{"id":"1.232199708","rc":[{"batl":[[1,85,3.33],[2,160,1.01]],"ltp":2.58,"tv":10.02,"id":424679}]}]}
{"op":"mcm","clk":"11986413794","pt":1724924063071,"mc":[{"id":"1.232199708","rc":[{"trd":[[2.58,10.12]],"batb":[[0,2.58,26.02]],"batl":[[0,85,3.33],[1,160,1.01],[2,990,3.17]],"ltp":2.58,"tv":14.48,"id":424679}],"tv":40.81}]}
{"op":"mcm","clk":"11986413925","pt":1724924065398,"mc":[{"id":"1.232199708","rc":[{"batb":[[0,2.56,26.02]],"batl":[[0,80,1.83],[1,85,2.5],[2,160,1.01]],"ltp":2.58,"tv":14.48,"id":424679}]}]}
{"op":"mcm","clk":"11986414399","pt":1724924074174,"mc":[{"id":"1.232199708","rc":[{"batl":[[0,70,3.33],[1,80,1]],"ltp":2.58,"tv":14.48,"id":424679}]}]}
{"op":"mcm","clk":"11986414494","pt":1724924075687,"mc":[{"id":"1.232199708","rc":[{"batl":[[1,160,1.01],[2,990,3.17]],"ltp":2.58,"tv":14.48,"id":424679}]}]}
{"op":"mcm","clk":"11986414806","pt":1724924081293,"mc":[{"id":"1.232199708","rc":[{"batl":[[0,65,1.83],[1,70,2.5],[2,160,1.01]],"ltp":2.58,"tv":14.48,"id":424679}]}]}
{"op":"mcm","clk":"11986415264","pt":1724924088015,"mc":[{"id":"1.232199708","rc":[{"batl":[[0,9.4,2.5],[1,65,1.83]],"ltp":2.58,"tv":14.48,"id":424679}]}]}
{"op":"mcm","clk":"11986415509","pt":1724924092392,"mc":[{"id":"1.232199708","rc":[{"batl":[[1,90,1.67],[2,990,3.34]],"ltp":2.58,"tv":14.48,"id":424679}]}]}
{"op":"mcm","clk":"11986415855","pt":1724924097900,"mc":[{"id":"1.232199708","rc":[{"batl":[[0,9.2,1],[1,9.4,2.5],[2,90,1.67]],"ltp":2.58,"tv":14.48,"id":424679}]}]}
{"op":"mcm","clk":"11986416454","pt":1724924108034,"mc":[{"id":"1.232199708","rc":[{"batl":[[1,80,3.33],[2,160,1.01]],"ltp":2.58,"tv":14.48,"id":424679}]}]}
{"op":"mcm","clk":"11986416616","pt":1724924111124,"mc":[{"id":"1.232199708","rc":[{"batl":[[1,90,4.17],[2,990,3.34]],"ltp":2.58,"tv":14.48,"id":424679}]}]}
{"op":"mcm","clk":"11986417023","pt":1724924117345,"mc":[{"id":"1.232199708","rc":[{"batb":[[2,1.04,126.83]],"batl":[[0,8,1.16],[1,8.2,1],[2,85,2.5]],"ltp":1.65,"tv":14.4,"id":3961},{"batl":[[0,4.8,1.6]],"ltp":2.04,"tv":11.93,"id":60443}]}]}
{"op":"mcm","clk":"11986417051","pt":1724924117752,"mc":[{"id":"1.232199708","rc":[{"batb":[[0,1.52,1.13],[1,1.51,16.57],[2,1.5,19.94]],"ltp":1.65,"tv":14.4,"id":3961},{"batb":[[0,2.04,8.16]],"ltp":2.04,"tv":11.93,"id":60443}]}]}
{"op":"mcm","clk":"11986417202","pt":1724924120123,"mc":[{"id":"1.232199708","rc":[{"batl":[[1,85,2.5],[2,940,1.01]],"ltp":1.65,"tv":14.4,"id":3961}]}]}
{"op":"mcm","clk":"11986417363","pt":1724924122243,"mc":[{"id":"1.232199708","rc":[{"batl":[[0,85,3.36],[1,940,1.01],[2,990,2.5]],"ltp":1.65,"tv":14.4,"id":3961}]}]}
{"op":"mcm","clk":"11986417415","pt":1724924122958,"mc":[{"id":"1.232199708","rc":[{"batb":[[0,2.58,26.02]],"ltp":2.58,"tv":14.48,"id":424679},{"batb":[[0,1.51,17.4],[1,1.5,19.94],[2,1.04,126.53]],"ltp":1.65,"tv":14.4,"id":3961},{"batl":[[0,4.8,1.3]],"ltp":2.04,"tv":11.93,"id":60443}]}]}
{"op":"mcm","clk":"11986417600","pt":1724924125840,"mc":[{"id":"1.232199708","rc":[{"batb":[[0,2.56,26.02]],"ltp":2.58,"tv":14.48,"id":424679}]}]}
{"op":"mcm","clk":"11986417680","pt":1724924127125,"mc":[{"id":"1.232199708","rc":[{"batb":[[0,2.54,6.04],[1,2.52,10],[2,1.5,20]],"ltp":2.58,"tv":14.48,"id":424679}]}]}
{"op":"mcm","clk":"11986417753","pt":1724924128152,"mc":[{"id":"1.232199708","rc":[{"batb":[[0,2.54,6.34]],"ltp":2.58,"tv":14.48,"id":424679}]}]}
{"op":"mcm","clk":"11986418044","pt":1724924132775,"mc":[{"id":"1.232199708","rc":[{"batb":[[0,2.56,26.3],[1,2.54,6.04],[2,2.52,10]],"ltp":2.58,"tv":14.48,"id":424679}]}]}
{"op":"mcm","clk":"11986418353","pt":1724924136942,"mc":[{"id":"1.232199708","rc":[{"batl":[[0,8.2,1.86],[1,85,2.5],[2,940,1.01]],"ltp":1.65,"tv":14.4,"id":3961}]}]}
{"op":"mcm","clk":"11986419040","pt":1724924147966,"mc":[{"id":"1.232199708","rc":[{"batl":[[0,2.58,2.53],[1,9.2,1],[2,90,4.17]],"ltp":2.58,"tv":14.48,"id":424679}]}]}
{"op":"mcm","clk":"11986419204","pt":1724924150772,"mc":[{"id":"1.232199708","rc":[{"batl":[[2,90,3.87]],"ltp":2.58,"tv":14.48,"id":424679}]}]}
{"op":"mcm","clk":"11986419396","pt":1724924153710,"mc":[{"id":"1.232199708","rc":[{"batl":[[1,90,3.87],[2,990,3.34]],"ltp":2.58,"tv":14.48,"id":424679}]}]}
{"op":"mcm","clk":"11986419886","pt":1724924162107,"mc":[{"id":"1.232199708","rc":[{"batl":[[0,90,3.87],[1,990,3.34],[2,990,0]],"ltp":2.58,"tv":14.48,"id":424679}]}]}
{"op":"mcm","clk":"11986420066","pt":1724924164683,"mc":[{"id":"1.232199708","rc":[{"batl":[[0,85,1.53],[1,90,3.34],[2,990,3.34]],"ltp":2.58,"tv":14.48,"id":424679}]}]}
{"op":"mcm","clk":"11986420133","pt":1724924165820,"mc":[{"id":"1.232199708","rc":[{"batl":[[0,85,1.83]],"ltp":2.58,"tv":14.48,"id":424679}]}]}
{"op":"mcm","clk":"11986436299","pt":1724924419882,"mc":[{"id":"1.232199708","rc":[{"batb":[[0,1.51,17.1]],"ltp":1.65,"tv":14.4,"id":3961}]}]}
{"op":"mcm","clk":"11986436403","pt":1724924421480,"mc":[{"id":"1.232199708","rc":[{"batb":[[2,1.07,1]],"ltp":1.65,"tv":14.4,"id":3961},{"batb":[[0,2.04,7.86]],"ltp":2.04,"tv":11.93,"id":60443}]}]}
{"op":"mcm","clk":"11986436435","pt":1724924421894,"mc":[{"id":"1.232199708","rc":[{"batb":[[0,1.51,17.4],[2,1.04,126.53]],"batl":[[0,8,1.16],[1,8.2,1],[2,85,2.5]],"ltp":1.65,"tv":14.4,"id":3961},{"batb":[[0,2.04,8.16]],"batl":[[0,4.8,1.6]],"ltp":2.04,"tv":11.93,"id":60443}]}]}
{"op":"mcm","clk":"11986436497","pt":1724924422792,"mc":[{"id":"1.232199708","rc":[{"batl":[[0,8.2,1.86],[1,85,2.5],[2,940,1.01]],"ltp":1.65,"tv":14.4,"id":3961}]}]}
{"op":"mcm","clk":"11986436548","pt":1724924423800,"mc":[{"id":"1.232199708","rc":[{"batl":[[0,4.8,1.3]],"ltp":2.04,"tv":11.93,"id":60443}]}]}
{"op":"mcm","clk":"11986437085","pt":1724924432716,"mc":[{"id":"1.232199708","rc":[{"batb":[[0,2.56,26.6]],"ltp":2.58,"tv":14.48,"id":424679}]}]}
{"op":"mcm","clk":"11986437378","pt":1724924436995,"mc":[{"id":"1.232199708","rc":[{"batb":[[0,2.56,26.3]],"ltp":2.58,"tv":14.48,"id":424679}]}]}
{"op":"mcm","clk":"11986439094","pt":1724924465146,"mc":[{"id":"1.232199708","rc":[{"batl":[[0,85,1.53]],"ltp":2.58,"tv":14.48,"id":424679}]}]}
{"op":"mcm","clk":"11986439337","pt":1724924468544,"mc":[{"id":"1.232199708","rc":[{"batl":[[0,85,1.83]],"ltp":2.58,"tv":14.48,"id":424679}]}]}
{"op":"mcm","clk":"11986471270","pt":1724924724454,"mc":[{"id":"1.232199708","rc":[{"batb":[[2,1.07,1]],"ltp":1.65,"tv":14.4,"id":3961}]}]}
{"op":"mcm","clk":"11986471328","pt":1724924724923,"mc":[{"id":"1.232199708","rc":[{"batb":[[0,1.52,1.13],[1,1.51,16.57],[2,1.5,19.94]],"batl":[[0,8,1.16],[1,8.2,1],[2,85,2.5]],"ltp":1.65,"tv":14.4,"id":3961},{"batb":[[0,2.04,8.46]],"batl":[[0,4.8,1.6]],"ltp":2.04,"tv":11.93,"id":60443}]}]}
{"op":"mcm","clk":"11986471517","pt":1724924727442,"mc":[{"id":"1.232199708","rc":[{"batb":[[0,1.51,17.4],[1,1.5,19.94],[2,1.04,126.53]],"batl":[[1,85,2.5],[2,940,1.01]],"ltp":1.65,"tv":14.4,"id":3961}]}]}
{"op":"mcm","clk":"11986471564","pt":1724924728123,"mc":[{"id":"1.232199708","rc":[{"batl":[[0,85,3.36],[1,940,1.01],[2,990,2.5]],"ltp":1.65,"tv":14.4,"id":3961},{"batb":[[0,2.04,8.16]],"batl":[[0,4.8,1.3]],"ltp":2.04,"tv":11.93,"id":60443}]}]}
{"op":"mcm","clk":"11986472119","pt":1724924736338,"mc":[{"id":"1.232199708","rc":[{"batb":[[0,2.56,26.6]],"ltp":2.58,"tv":14.48,"id":424679}]}]}
{"op":"mcm","clk":"11986472145","pt":1724924736751,"mc":[{"id":"1.232199708","rc":[{"batb":[[0,2.56,26.3]],"ltp":2.58,"tv":14.48,"id":424679}]}]}
{"op":"mcm","clk":"11986473084","pt":1724924749537,"mc":[{"id":"1.232199708","rc":[{"batl":[[0,8.2,1.86],[1,85,2.5],[2,940,1.01]],"ltp":1.65,"tv":14.4,"id":3961}]}]}
{"op":"mcm","clk":"11986474492","pt":1724924769647,"mc":[{"id":"1.232199708","rc":[{"batl":[[0,85,1.53]],"ltp":2.58,"tv":14.48,"id":424679}]}]}
{"op":"mcm","clk":"11986474837","pt":1724924773463,"mc":[{"id":"1.232199708","rc":[{"batl":[[0,85,1.83]],"ltp":2.58,"tv":14.48,"id":424679}]}]}
{"op":"mcm","clk":"11986495586","pt":1724925000601,"mc":[{"id":"1.232199708","rc":[{"batb":[[0,1.56,5],[1,1.55,5.63],[2,1.51,16.87]],"ltp":1.65,"tv":14.4,"id":3961},{"batb":[[0,2.08,5],[1,2.06,5.4],[2,2.04,7.86]],"ltp":2.04,"tv":11.93,"id":60443}]}]}
{"op":"mcm","clk":"11986496190","pt":1724925005627,"mc":[{"id":"1.232199708","rc":[{"batl":[[0,85,3.36],[1,940,1.01],[2,990,2.5]],"ltp":1.65,"tv":14.4,"id":3961}]}]}
{"op":"mcm","clk":"11986497403","pt":1724925016843,"mc":[{"id":"1.232199708","rc":[{"batl":[[0,7.6,1.56],[1,85,2.8],[2,940,1.01]],"ltp":1.65,"tv":14.4,"id":3961}]}]}
{"op":"mcm","clk":"11986498447","pt":1724925029352,"mc":[{"id":"1.232199708","rc":[{"batb":[[0,1.56,5.3]],"batl":[[0,7.6,1.86]],"ltp":1.65,"tv":14.4,"id":3961},{"batb":[[0,2.08,5.3]],"batl":[[0,4.8,1.6]],"ltp":2.04,"tv":11.93,"id":60443}]}]}
{"op":"mcm","clk":"11986498929","pt":1724925035225,"mc":[{"id":"1.232199708","rc":[{"batb":[[1,2.06,5.1]],"ltp":2.04,"tv":11.93,"id":60443}]}]}
{"op":"mcm","clk":"11986499024","pt":1724925036460,"mc":[{"id":"1.232199708","rc":[{"trd":[[2.58,10.72]],"batb":[[0,2.56,26]],"batl":[[0,2.58,2.23],[1,85,1.83],[2,90,3.34]],"ltp":2.58,"tv":15.08,"id":424679},{"batb":[[0,1.55,5.93],[1,1.51,16.57],[2,1.5,19.94]],"ltp":1.65,"tv":14.4,"id":3961}],"tv":41.41}]}
{"op":"mcm","clk":"11986499066","pt":1724925036949,"mc":[{"id":"1.232199708","rc":[{"batb":[[0,1.51,17.4],[1,1.5,19.94],[2,1.04,126.53]],"batl":[[1,85,2.5]],"ltp":1.65,"tv":14.4,"id":3961},{"batb":[[0,2.04,8.16],[1,2.02,1.26],[2,2,10]],"batl":[[0,4.8,1.3]],"ltp":2.04,"tv":11.93,"id":60443}]}]}
{"op":"mcm","clk":"11986499427","pt":1724925040246,"mc":[{"id":"1.232199708","rc":[{"trd":[[2.58,11.32]],"batl":[[0,2.58,1.93]],"ltp":2.58,"tv":15.68,"id":424679}],"tv":42.01}]}
{"op":"mcm","clk":"11986499885","pt":1724925044767,"mc":[{"id":"1.232199708","rc":[{"batl":[[1,90,4.17],[2,990,3.34]],"ltp":2.58,"tv":15.68,"id":424679}]}]}
{"op":"mcm","clk":"11986500061","pt":1724925046879,"mc":[{"id":"1.232199708","rc":[{"batb":[[0,1.5,20.77],[1,1.04,126.53],[2,1.03,200]],"ltp":1.65,"tv":14.4,"id":3961},{"batb":[[0,2.02,1.56],[1,2,10],[2,1.32,1.13]],"ltp":2.04,"tv":11.93,"id":60443}]}]}
{"op":"mcm","clk":"11986502253","pt":1724925072706,"mc":[{"id":"1.232199708","rc":[{"batl":[[1,90,3.87]],"ltp":2.58,"tv":15.68,"id":424679}]}]}
{"op":"mcm","clk":"11986507457","pt":1724925143882,"mc":[{"id":"1.232199708","rc":[{"trd":[[2.58,11.87]],"batl":[[0,2.58,1.38]],"ltp":2.58,"tv":16.23,"id":424679},{"trd":[[2.5,0.56]],"batl":[[0,7.6,1.3]],"ltp":2.5,"tv":14.96,"id":3961},{"trd":[[4.7,0.3]],"batl":[[0,4.8,1]],"ltp":4.7,"tv":12.23,"id":60443}],"tv":43.43}]}
{"op":"mcm","clk":"11986510716","pt":1724925189123,"mc":[{"id":"1.232199708","rc":[{"batb":[[0,2.48,5],[1,2.46,5.1],[2,1.5,20.77]],"ltp":2.5,"tv":14.96,"id":3961},{"batb":[[0,2.12,5],[1,2.1,5.4],[2,2.02,1.26]],"ltp":4.7,"tv":12.23,"id":60443}]}]}
{"op":"mcm","clk":"11986510744","pt":1724925189527,"mc":[{"id":"1.232199708","rc":[{"batl":[[0,85,2.8],[1,940,1.01],[2,990,2.5]],"ltp":2.5,"tv":14.96,"id":3961}]}]}
{"op":"mcm","clk":"11986511105","pt":1724925195120,"mc":[{"id":"1.232199708","rc":[{"batl":[[0,7.2,1],[1,85,2.8],[2,940,1.01]],"ltp":2.5,"tv":14.96,"id":3961}]}]}
{"op":"mcm","clk":"11986516635","pt":1724925265898,"mc":[{"id":"1.232199708","rc":[{"batl":[[0,90,3.87],[1,990,3.34],[2,990,0]],"ltp":2.58,"tv":16.23,"id":424679}]}]}
{"op":"mcm","clk":"11986516757","pt":1724925267396,"mc":[{"id":"1.232199708","rc":[{"batl":[[0,7.8,1],[1,90,3.87],[2,990,3.34]],"ltp":2.58,"tv":16.23,"id":424679}]}]}
{"op":"mcm","clk":"11986516873","pt":1724925268824,"mc":[{"id":"1.232199708","rc":[{"batl":[[0,7.8,1.3]],"ltp":2.58,"tv":16.23,"id":424679}]}]}
{"op":"mcm","clk":"11986516931","pt":1724925269607,"mc":[{"id":"1.232199708","rc":[{"batb":[[0,2.58,5],[1,2.56,31.1],[2,2.54,6.04]],"ltp":2.58,"tv":16.23,"id":424679}]}]}
{"op":"mcm","clk":"11986517211","pt":1724925273220,"mc":[{"id":"1.232199708","rc":[{"batb":[[0,2.5,5.63],[1,2.48,5],[2,2.46,5.1]],"ltp":2.5,"tv":14.96,"id":3961}]}]}
{"op":"mcm","clk":"11986521700","pt":1724925331985,"mc":[{"id":"1.232199708","rc":[{"batb":[[0,2.5,5.93]],"batl":[[0,7.2,1.3]],"ltp":2.5,"tv":14.96,"id":3961},{"batb":[[0,2.12,5.3]],"batl":[[0,4.8,1.3]],"ltp":4.7,"tv":12.23,"id":60443}]}]}
{"op":"mcm","clk":"11986521815","pt":1724925333372,"mc":[{"id":"1.232199708","rc":[{"trd":[[2.58,16.93]],"batb":[[0,2.58,2.47]],"ltp":2.58,"tv":21.29,"id":424679},{"batb":[[1,2.1,5.1]],"ltp":4.7,"tv":12.23,"id":60443}],"tv":48.49}]}
{"op":"mcm","clk":"11986521894","pt":1724925334397,"mc":[{"id":"1.232199708","rc":[{"batl":[[1,85,2.5]],"ltp":2.5,"tv":14.96,"id":3961}]}]}
{"op":"mcm","clk":"11986522442","pt":1724925342617,"mc":[{"id":"1.232199708","rc":[{"trd":[[2.58,21.39],[2.6,0.6]],"batb":[[0,2.56,31.34],[1,2.54,6.04],[2,2.52,10]],"ltp":2.58,"tv":26.35,"id":424679}],"tv":53.55}]}
{"op":"mcm","clk":"11986523677","pt":1724925359698,"mc":[{"id":"1.232199708","rc":[{"trd":[[2.58,21.87]],"batb":[[0,2.56,31.1]],"batl":[[0,2.58,2.29],[1,7.8,1.3],[2,90,3.87]],"ltp":2.58,"tv":26.83,"id":424679}],"tv":54.03}]}
{"op":"mcm","clk":"11986523865","pt":1724925362127,"mc":[{"id":"1.232199708","rc":[{"batl":[[1,90,4.17],[2,990,3.34]],"ltp":2.58,"tv":26.83,"id":424679}]}]}
{"op":"mcm","clk":"11986524454","pt":1724925369441,"mc":[{"id":"1.232199708","rc":[{"batb":[[1,1.5,20.47],[2,1.04,126.53]],"ltp":2.5,"tv":14.96,"id":3961},{"batb":[[0,2.1,5.4],[1,2.02,1.26],[2,2,10]],"ltp":4.7,"tv":12.23,"id":60443}]}]}
{"op":"mcm","clk":"11986524459","pt":1724925369536,"mc":[{"id":"1.232199708","rc":[{"batb":[[0,2.02,1.56],[1,2,10],[2,1.32,1.13]],"ltp":4.7,"tv":12.23,"id":60443}]}]}
{"op":"mcm","clk":"11986530277","pt":1724925448857,"mc":[{"id":"1.232199708","rc":[{"batb":[[0,2.56,26]],"ltp":2.58,"tv":26.83,"id":424679}]}]}
{"op":"mcm","clk":"11986530841","pt":1724925456466,"mc":[{"id":"1.232199708","rc":[{"batb":[[0,2.54,5.15],[1,2.52,5.5],[2,2.5,5.63]],"ltp":2.5,"tv":14.96,"id":3961},{"batb":[[0,2.16,5.15],[1,2.14,5.5],[2,2.02,1.26]],"ltp":4.7,"tv":12.23,"id":60443}]}]}
{"op":"mcm","clk":"11986530867","pt":1724925456767,"mc":[{"id":"1.232199708","rc":[{"batl":[[0,85,2.8],[1,940,1.01],[2,990,2.5]],"ltp":2.5,"tv":14.96,"id":3961},{"batl":[[0,4.9,2.3],[1,85,3.03],[2,940,1.01]],"ltp":4.7,"tv":12.23,"id":60443}]}]}
{"op":"mcm","clk":"11986531279","pt":1724925462458,"mc":[{"id":"1.232199708","rc":[{"batl":[[0,6.8,1],[1,85,2.8],[2,940,1.01]],"ltp":2.5,"tv":14.96,"id":3961},{"batl":[[0,4.6,1],[1,4.9,2.3],[2,85,3.03]],"ltp":4.7,"tv":12.23,"id":60443}]}]}
{"op":"mcm","clk":"11986532019","pt":1724925472495,"mc":[{"id":"1.232199708","rc":[{"trd":[[2.58,26.45]],"batb":[[0,2.58,1.71],[1,2.56,26],[2,2.54,6.04]],"batl":[[0,90,4.17],[1,990,3.34],[2,990,0]],"ltp":2.58,"tv":31.41,"id":424679}],"tv":58.61}]}
{"op":"mcm","clk":"11986532119","pt":1724925473577,"mc":[{"id":"1.232199708","rc":[{"batl":[[0,6.8,1],[1,90,4.17],[2,990,3.34]],"ltp":2.58,"tv":31.41,"id":424679}]}]}
{"op":"mcm","clk":"11986535708","pt":1724925516337,"mc":[{"id":"1.232199708","rc":[{"batb":[[0,2.5,5.93],[1,1.5,20.47],[2,1.04,126.53]],"ltp":2.5,"tv":14.96,"id":3961},{"batb":[[0,2.02,1.56],[1,2,10],[2,1.32,1.13]],"ltp":4.7,"tv":12.23,"id":60443}]}]}
{"op":"mcm","clk":"11986535972","pt":1724925519842,"mc":[{"id":"1.232199708","rc":[{"batb":[[0,2.54,5.15],[1,2.52,5.5],[2,2.5,5.63]],"ltp":2.5,"tv":14.96,"id":3961},{"batb":[[0,2.16,5.15],[1,2.14,5.5],[2,2.02,1.26]],"ltp":4.7,"tv":12.23,"id":60443}]}]}
{"op":"mcm","clk":"11986540006","pt":1724925569055,"mc":[{"id":"1.232199708","rc":[{"batl":[[1,90,3.87]],"ltp":2.58,"tv":31.41,"id":424679}]}]}
{"op":"mcm","clk":"11986540258","pt":1724925572082,"mc":[{"id":"1.232199708","rc":[{"batl":[[0,6.8,1.3]],"ltp":2.58,"tv":31.41,"id":424679}]}]}
{"op":"mcm","clk":"11986540902","pt":1724925579392,"mc":[{"id":"1.232199708","rc":[{"batb":[[0,2.5,5.93],[1,1.5,20.47],[2,1.04,126.53]],"ltp":2.5,"tv":14.96,"id":3961},{"batb":[[1,2.02,1.56],[2,2,10]],"ltp":4.7,"tv":12.23,"id":60443}]}]}
{"op":"mcm","clk":"11986540917","pt":1724925579594,"mc":[{"id":"1.232199708","rc":[{"batb":[[0,2.02,1.56],[1,2,10],[2,1.32,1.13]],"ltp":4.7,"tv":12.23,"id":60443}]}]}
{"op":"mcm","clk":"11986541218","pt":1724925583107,"mc":[{"id":"1.232199708","rc":[{"batb":[[0,2.54,5.15],[1,2.52,5.5],[2,2.5,5.63]],"ltp":2.5,"tv":14.96,"id":3961},{"batb":[[0,2.16,5.15],[1,2.14,5.5],[2,2.02,1.26]],"ltp":4.7,"tv":12.23,"id":60443}]}]}
{"op":"mcm","clk":"11986543247","pt":1724925607478,"mc":[{"id":"1.232199708","marketDefinition":{"bspMarket":false,"turnInPlayEnabled":true,"persistenceEnabled":true,"marketBaseRate":5.0,"eventId":"33521414","eventTypeId":"4","numberOfWinners":1,"bettingType":"ODDS","marketType":"MATCH_ODDS","marketTime":"2024-08-29T10:00:00.000Z","suspendTime":"2024-08-29T10:00:00.000Z","bspReconciled":false,"complete":true,"inPlay":false,"crossMatching":true,"runnersVoidable":false,"numberOfActiveRunners":3,"betDelay":0,"status":"SUSPENDED","runners":[{"status":"ACTIVE","sortPriority":1,"id":424679,"name":"Lancashire"},{"status":"ACTIVE","sortPriority":2,"id":3961,"name":"Hampshire"},{"status":"ACTIVE","sortPriority":3,"id":60443,"name":"The Draw"}],"regulators":["MR_INT"],"countryCode":"GB","discountAllowed":true,"timezone":"GMT","openDate":"2024-08-29T10:00:00.000Z","version":6106359061,"name":"Match Odds","eventName":"Lancashire v Hampshire"},"rc":[{"batb":[[2,2.54,6.05]],"ltp":2.58,"tv":31.41,"id":424679},{"batb":[[2,2.5,5.64]],"ltp":2.5,"tv":14.96,"id":3961}]}]}
{"op":"mcm","clk":"11986543495","pt":1724925610488,"mc":[{"id":"1.232199708","marketDefinition":{"bspMarket":false,"turnInPlayEnabled":true,"persistenceEnabled":true,"marketBaseRate":5.0,"eventId":"33521414","eventTypeId":"4","numberOfWinners":1,"bettingType":"ODDS","marketType":"MATCH_ODDS","marketTime":"2024-08-29T10:00:00.000Z","suspendTime":"2024-08-29T10:00:00.000Z","bspReconciled":false,"complete":true,"inPlay":true,"crossMatching":true,"runnersVoidable":false,"numberOfActiveRunners":3,"betDelay":5,"status":"OPEN","runners":[{"status":"ACTIVE","sortPriority":1,"id":424679,"name":"Lancashire"},{"status":"ACTIVE","sortPriority":2,"id":3961,"name":"Hampshire"},{"status":"ACTIVE","sortPriority":3,"id":60443,"name":"The Draw"}],"regulators":["MR_INT"],"countryCode":"GB","discountAllowed":true,"timezone":"GMT","openDate":"2024-08-29T10:00:00.000Z","version":6106359114,"name":"Match Odds","eventName":"Lancashire v Hampshire"},"rc":[{"batb":[[0,2.54,5.05],[1,1.5,20],[2,1.04,126.53]],"batl":[[0,90,3.03],[1,990,3.34],[2,990,0]],"ltp":2.58,"tv":31.41,"id":424679},{"batb":[[0,1.5,20.47],[1,1.04,126.53],[2,1.03,200]],"batl":[[0,85,2.5],[1,940,1.01],[2,990,2.5]],"ltp":2.5,"tv":14.96,"id":3961},{"batb":[[0,1.3,20.69],[1,1.04,128.53],[2,1.03,200]],"batl":[[0,85,3.03],[1,940,1.01],[2,990,2.5]],"ltp":4.7,"tv":12.23,"id":60443}]}]}
{"op":"mcm","clk":"11986544726","pt":1724925623843,"mc":[{"id":"1.232199708","rc":[{"batb":[[0,2.56,26],[1,2.54,5.05],[2,1.5,20]],"ltp":2.58,"tv":31.41,"id":424679}]}]}
{"op":"mcm","clk":"11986544912","pt":1724925625955,"mc":[{"id":"1.232199708","rc":[{"batl":[[0,85,3.04]],"ltp":4.7,"tv":12.23,"id":60443}]}]}
{"op":"mcm","clk":"11986546255","pt":1724925641367,"mc":[{"id":"1.232199708","rc":[{"batl":[[0,85,2.8]],"ltp":2.5,"tv":14.96,"id":3961},{"batl":[[0,85,3.34]],"ltp":4.7,"tv":12.23,"id":60443}]}]}
{"op":"mcm","clk":"11986546783","pt":1724925646478,"mc":[{"id":"1.232199708","rc":[{"batb":[[0,1.5,20.77]],"ltp":2.5,"tv":14.96,"id":3961},{"batb":[[1,1.07,1],[2,1.04,128.53]],"ltp":4.7,"tv":12.23,"id":60443}]}]}
{"op":"mcm","clk":"11986547286","pt":1724925652007,"mc":[{"id":"1.232199708","rc":[{"batb":[[1,1.04,128.53],[2,1.03,200]],"ltp":4.7,"tv":12.23,"id":60443}]}]}
{"op":"mcm","clk":"11986547728","pt":1724925657085,"mc":[{"id":"1.232199708","rc":[{"batb":[[0,2.56,26.3]],"ltp":2.58,"tv":31.41,"id":424679},{"batb":[[0,1.3,20.99]],"ltp":4.7,"tv":12.23,"id":60443}]}]}
{"op":"mcm","clk":"11986549223","pt":1724925673412,"mc":[{"id":"1.232199708","rc":[{"batl":[[0,85,1.53],[1,90,2.5],[2,990,3.34]],"ltp":2.58,"tv":31.41,"id":424679}]}]}
{"op":"mcm","clk":"11986549674","pt":1724925679120,"mc":[{"id":"1.232199708","rc":[{"batl":[[0,80,1.3],[1,85,2.5],[2,940,1.01]],"ltp":2.5,"tv":14.96,"id":3961},{"batl":[[0,80,1.84],[1,85,2.5],[2,940,1.01]],"ltp":4.7,"tv":12.23,"id":60443}]}]}
{"op":"mcm","clk":"11986554278","pt":1724925730345,"mc":[{"id":"1.232199708","rc":[{"trd":[[2.56,13.4],[2.58,27.05]],"batb":[[0,2.56,19.3]],"ltp":2.56,"tv":45.41,"id":424679}],"tv":72.61}]}
{"op":"mcm","clk":"11986556693","pt":1724925760225,"mc":[{"id":"1.232199708","rc":[{"batl":[[0,15,5],[1,85,1.53],[2,90,2.5]],"ltp":2.56,"tv":45.41,"id":424679}]}]}
{"op":"mcm","clk":"11986556920","pt":1724925763213,"mc":[{"id":"1.232199708","rc":[{"batl":[[1,90,3.03],[2,990,3.34]],"ltp":2.56,"tv":45.41,"id":424679}]}]}
{"op":"mcm","clk":"11986558119","pt":1724925779331,"mc":[{"id":"1.232199708","rc":[{"batl":[[0,14.5,1],[1,15,5],[2,90,3.03]],"ltp":2.56,"tv":45.41,"id":424679}]}]}
{"op":"mcm","clk":"11986558733","pt":1724925787332,"mc":[{"id":"1.232199708","rc":[{"batl":[[1,90,3.03],[2,990,3.34]],"ltp":2.56,"tv":45.41,"id":424679}]}]}
{"op":"mcm","clk":"11986559143","pt":1724925792447,"mc":[{"id":"1.232199708","rc":[{"batl":[[0,14,5],[1,14.5,1],[2,90,3.03]],"ltp":2.56,"tv":45.41,"id":424679}]}]}
{"op":"mcm","clk":"11986559467","pt":1724925796567,"mc":[{"id":"1.232199708","rc":[{"batl":[[1,90,3.03],[2,990,3.34]],"ltp":2.56,"tv":45.41,"id":424679}]}]}
{"op":"mcm","clk":"11986560247","pt":1724925807188,"mc":[{"id":"1.232199708","rc":[{"batl":[[0,13.5,1],[1,14,5],[2,90,3.03]],"ltp":2.56,"tv":45.41,"id":424679}]}]}
{"op":"mcm","clk":"11986561006","pt":1724925816280,"mc":[{"id":"1.232199708","rc":[{"batl":[[1,90,3.03],[2,990,3.34]],"ltp":2.56,"tv":45.41,"id":424679}]}]}
{"op":"mcm","clk":"11986561429","pt":1724925821355,"mc":[{"id":"1.232199708","rc":[{"batl":[[0,13,5],[1,13.5,1],[2,90,3.03]],"ltp":2.56,"tv":45.41,"id":424679}]}]}
{"op":"mcm","clk":"11986561693","pt":1724925824366,"mc":[{"id":"1.232199708","rc":[{"batl":[[1,90,3.03],[2,990,3.34]],"ltp":2.56,"tv":45.41,"id":424679}]}]}
{"op":"mcm","clk":"11986562567","pt":1724925834978,"mc":[{"id":"1.232199708","rc":[{"batl":[[0,12.5,1],[1,13,5],[2,90,3.03]],"ltp":2.56,"tv":45.41,"id":424679}]}]}
{"op":"mcm","clk":"11986566041","pt":1724925879921,"mc":[{"id":"1.232199708","rc":[{"batl":[[0,12.5,1.3]],"ltp":2.56,"tv":45.41,"id":424679}]}]}
{"op":"mcm","clk":"11986567030","pt":1724925893761,"mc":[{"id":"1.232199708","rc":[{"batl":[[1,90,3.03],[2,990,3.34]],"ltp":2.56,"tv":45.41,"id":424679}]}]}
{"op":"mcm","clk":"11986570764","pt":1724925947533,"mc":[{"id":"1.232199708","rc":[{"batb":[[1,1.07,1],[2,1.04,126.53]],"batl":[[0,80,1.6]],"ltp":2.5,"tv":14.96,"id":3961},{"batb":[[1,1.07,1],[2,1.04,128.53]],"batl":[[0,80,2.14]],"ltp":4.7,"tv":12.23,"id":60443}]}]}
{"op":"mcm","clk":"11986571161","pt":1724925953236,"mc":[{"id":"1.232199708","rc":[{"batb":[[1,1.04,126.53],[2,1.03,200]],"ltp":2.5,"tv":14.96,"id":3961},{"batb":[[1,1.04,128.53],[2,1.03,200]],"ltp":4.7,"tv":12.23,"id":60443}]}]}
{"op":"mcm","clk":"11986571476","pt":1724925958307,"mc":[{"id":"1.232199708","rc":[{"batb":[[0,1.51,1.13],[1,1.5,19.94],[2,1.04,126.53]],"ltp":2.5,"tv":14.96,"id":3961},{"batb":[[0,1.31,1.29],[1,1.3,20],[2,1.04,128.53]],"ltp":4.7,"tv":12.23,"id":60443}]}]}
{"op":"mcm","clk":"11986571802","pt":1724925963259,"mc":[{"id":"1.232199708","rc":[{"batb":[[0,2.56,19.6]],"ltp":2.56,"tv":45.41,"id":424679}]}]}
{"op":"mcm","clk":"11986586566","pt":1724926181753,"mc":[{"id":"1.232199708","rc":[{"batl":[[0,12.5,1.6]],"ltp":2.56,"tv":45.41,"id":424679}]}]}
{"op":"mcm","clk":"11986591696","pt":1724926246737,"mc":[{"id":"1.232199708","rc":[{"batl":[[0,80,1.9]],"ltp":2.5,"tv":14.96,"id":3961}]}]}
{"op":"mcm","clk":"11986592079","pt":1724926252334,"mc":[{"id":"1.232199708","rc":[{"batb":[[2,1.07,1]],"ltp":2.5,"tv":14.96,"id":3961},{"batb":[[2,1.07,1]],"batl":[[0,75,1.14],[1,80,1.3],[2,85,2.5]],"ltp":4.7,"tv":12.23,"id":60443}]}]}
{"op":"mcm","clk":"11986592453","pt":1724926257145,"mc":[{"id":"1.232199708","rc":[{"batb":[[2,1.04,128.53]],"ltp":4.7,"tv":12.23,"id":60443}]}]}
{"op":"mcm","clk":"11986592866","pt":1724926262350,"mc":[{"id":"1.232199708","rc":[{"batb":[[2,1.04,126.83]],"ltp":2.5,"tv":14.96,"id":3961},{"batb":[[0,1.31,1.59]],"ltp":4.7,"tv":12.23,"id":60443}]}]}
{"op":"mcm","clk":"11986592899","pt":1724926262821,"mc":[{"id":"1.232199708","rc":[{"batb":[[0,2.56,19.9]],"ltp":2.56,"tv":45.41,"id":424679},{"batb":[[2,1.04,126.53]],"ltp":2.5,"tv":14.96,"id":3961}]}]}
{"op":"mcm","clk":"11986593041","pt":1724926264462,"mc":[{"id":"1.232199708","rc":[{"batl":[[1,85,2.8],[2,940,1.01]],"ltp":4.7,"tv":12.23,"id":60443}]}]}
{"op":"mcm","clk":"11986593279","pt":1724926267660,"mc":[{"id":"1.232199708","rc":[{"batb":[[0,1.51,1.43]],"ltp":2.5,"tv":14.96,"id":3961}]}]}
{"op":"mcm","clk":"11986593943","pt":1724926275037,"mc":[{"id":"1.232199708","rc":[{"batl":[[0,70,1.54],[1,85,3.4]],"ltp":4.7,"tv":12.23,"id":60443}]}]}
{"op":"mcm","clk":"11986594899","pt":1724926286577,"mc":[{"id":"1.232199708","rc":[{"batl":[[0,15,2],[1,70,1.54],[2,85,3.4]],"ltp":4.7,"tv":12.23,"id":60443}]}]}
{"op":"mcm","clk":"11986595367","pt":1724926292151,"mc":[{"id":"1.232199708","rc":[{"batl":[[1,75,1.14],[2,85,2.8]],"ltp":4.7,"tv":12.23,"id":60443}]}]}
{"op":"mcm","clk":"11986596253","pt":1724926302879,"mc":[{"id":"1.232199708","rc":[{"batl":[[0,14.5,1],[1,15,2],[2,75,1.14]],"ltp":4.7,"tv":12.23,"id":60443}]}]}
{"op":"mcm","clk":"11986596408","pt":1724926305091,"mc":[{"id":"1.232199708","rc":[{"batb":[[0,2.56,19.6]],"ltp":2.56,"tv":45.41,"id":424679}]}]}
{"op":"mcm","clk":"11986596476","pt":1724926305971,"mc":[{"id":"1.232199708","rc":[{"batb":[[0,1.31,1.29]],"ltp":4.7,"tv":12.23,"id":60443}]}]}
{"op":"mcm","clk":"11986596557","pt":1724926306891,"mc":[{"id":"1.232199708","rc":[{"batb":[[0,1.51,1.13]],"ltp":2.5,"tv":14.96,"id":3961}]}]}
{"op":"mcm","clk":"11986596835","pt":1724926310901,"mc":[{"id":"1.232199708","rc":[{"batl":[[0,80,1.6]],"ltp":2.5,"tv":14.96,"id":3961},{"batl":[[2,80,1.14]],"ltp":4.7,"tv":12.23,"id":60443}]}]}
{"op":"mcm","clk":"11986596977","pt":1724926312814,"mc":[{"id":"1.232199708","rc":[{"batl":[[0,12.5,1.3]],"ltp":2.56,"tv":45.41,"id":424679}]}]}
{"op":"mcm","clk":"11986597071","pt":1724926313899,"mc":[{"id":"1.232199708","rc":[{"batb":[[0,1.3,20.99],[1,1.04,128.53],[2,1.03,200]],"ltp":4.7,"tv":12.23,"id":60443}]}]}
{"op":"mcm","clk":"11986597388","pt":1724926318479,"mc":[{"id":"1.232199708","rc":[{"batb":[[0,1.5,20.77],[1,1.04,126.53],[2,1.03,200]],"ltp":2.5,"tv":14.96,"id":3961}]}]}
{"op":"mcm","clk":"11986597532","pt":1724926320382,"mc":[{"id":"1.232199708","rc":[{"batl":[[0,80,1.3]],"ltp":2.5,"tv":14.96,"id":3961},{"batl":[[2,85,3.34]],"ltp":4.7,"tv":12.23,"id":60443}]}]}
{"op":"mcm","clk":"11986598435","pt":1724926330287,"mc":[{"id":"1.232199708","rc":[{"batl":[[0,14,6],[1,80,1.3],[2,85,2.5]],"ltp":2.5,"tv":14.96,"id":3961}]}]}
{"op":"mcm","clk":"11986598519","pt":1724926331219,"mc":[{"id":"1.232199708","rc":[{"batl":[[1,85,2.8],[2,940,1.01]],"ltp":2.5,"tv":14.96,"id":3961}]}]}
{"op":"mcm","clk":"11986599341","pt":1724926341806,"mc":[{"id":"1.232199708","rc":[{"batl":[[0,13.5,1],[1,14,6],[2,85,2.8]],"ltp":2.5,"tv":14.96,"id":3961}]}]}
{"op":"mcm","clk":"11986610756","pt":1724926482862,"mc":[{"id":"1.232199708","rc":[{"batl":[[0,12.5,1]],"ltp":2.56,"tv":45.41,"id":424679}]}]}
{"op":"mcm","clk":"11986611083","pt":1724926487084,"mc":[{"id":"1.232199708","rc":[{"batl":[[0,12.5,1.3]],"ltp":2.56,"tv":45.41,"id":424679}]}]}
{"op":"mcm","clk":"11986616243","pt":1724926550951,"mc":[{"id":"1.232199708","rc":[{"batl":[[2,85,2.5]],"ltp":2.5,"tv":14.96,"id":3961}]}]}
{"op":"mcm","clk":"11986616702","pt":1724926555936,"mc":[{"id":"1.232199708","rc":[{"batb":[[1,1.04,126.83]],"batl":[[0,13.5,1.3]],"ltp":2.5,"tv":14.96,"id":3961},{"batb":[[1,1.07,1],[2,1.04,128.53]],"ltp":4.7,"tv":12.23,"id":60443}]}]}
{"op":"mcm","clk":"11986616807","pt":1724926557023,"mc":[{"id":"1.232199708","rc":[{"batl":[[2,85,3.04]],"ltp":4.7,"tv":12.23,"id":60443}]}]}
{"op":"mcm","clk":"11986617178","pt":1724926561455,"mc":[{"id":"1.232199708","rc":[{"batb":[[1,1.04,126.53]],"ltp":2.5,"tv":14.96,"id":3961},{"batb":[[1,1.04,128.53],[2,1.03,200]],"batl":[[0,14.5,1.3]],"ltp":4.7,"tv":12.23,"id":60443}]}]}
{"op":"mcm","clk":"11986617335","pt":1724926563532,"mc":[{"id":"1.232199708","rc":[{"batb":[[0,1.3,20.69]],"ltp":4.7,"tv":12.23,"id":60443}]}]}
{"op":"mcm","clk":"11986617477","pt":1724926564967,"mc":[{"id":"1.232199708","rc":[{"batb":[[0,2.56,19.3]],"ltp":2.56,"tv":45.41,"id":424679}]}]}
{"op":"mcm","clk":"11986617609","pt":1724926566464,"mc":[{"id":"1.232199708","rc":[{"batb":[[0,2.56,19.6]],"ltp":2.56,"tv":45.41,"id":424679},{"batb":[[0,1.3,20.99]],"ltp":4.7,"tv":12.23,"id":60443}]}]}
{"op":"mcm","clk":"11986617619","pt":1724926566567,"mc":[{"id":"1.232199708","rc":[{"batb":[[0,1.51,1.13],[1,1.5,19.94],[2,1.04,126.53]],"ltp":2.5,"tv":14.96,"id":3961}]}]}
{"op":"mcm","clk":"11986617861","pt":1724926569456,"mc":[{"id":"1.232199708","rc":[{"batb":[[0,1.5,20.77],[1,1.04,126.53],[2,1.03,200]],"ltp":2.5,"tv":14.96,"id":3961}]}]}
{"op":"mcm","clk":"11986634967","pt":1724926787055,"mc":[{"id":"1.232199708","rc":[{"batl":[[0,12.5,1]],"ltp":2.56,"tv":45.41,"id":424679}]}]}
{"op":"mcm","clk":"11986635046","pt":1724926788039,"mc":[{"id":"1.232199708","rc":[{"batl":[[0,12.5,1.3]],"ltp":2.56,"tv":45.41,"id":424679}]}]}
{"op":"mcm","clk":"11986640172","pt":1724926852300,"mc":[{"id":"1.232199708","rc":[{"batb":[[1,1.07,1],[2,1.04,126.53]],"ltp":2.5,"tv":14.96,"id":3961},{"batb":[[1,1.07,1],[2,1.04,128.53]],"ltp":4.7,"tv":12.23,"id":60443}]}]}
{"op":"mcm","clk":"11986640658","pt":1724926858229,"mc":[{"id":"1.232199708","rc":[{"trd":[[2.56,32.8],[2.58,27.65]],"batb":[[0,2.56,9.6]],"ltp":2.56,"tv":65.41,"id":424679},{"batb":[[1,1.04,126.83],[2,1.03,200]],"ltp":2.5,"tv":14.96,"id":3961},{"batb":[[1,1.04,128.53],[2,1.03,200]],"ltp":4.7,"tv":12.23,"id":60443}],"tv":92.61}]}
{"op":"mcm","clk":"11986641035","pt":1724926863301,"mc":[{"id":"1.232199708","rc":[{"batb":[[0,2.58,4.3],[1,2.56,9.6],[2,2.54,5.05]],"ltp":2.56,"tv":65.41,"id":424679},{"batb":[[1,1.04,126.53]],"ltp":2.5,"tv":14.96,"id":3961},{"batb":[[0,1.31,1.29],[1,1.3,20],[2,1.04,128.53]],"batl":[[0,14.5,1.6]],"ltp":4.7,"tv":12.23,"id":60443}]}]}
{"op":"mcm","clk":"11986641284","pt":1724926866292,"mc":[{"id":"1.232199708","rc":[{"batb":[[0,2.56,9.9],[1,2.54,5.05],[2,1.5,20]],"ltp":2.56,"tv":65.41,"id":424679},{"batb":[[0,1.5,20.47]],"ltp":2.5,"tv":14.96,"id":3961},{"batl":[[0,14.5,1.3]],"ltp":4.7,"tv":12.23,"id":60443}]}]}
{"op":"mcm","clk":"11986641444","pt":1724926868301,"mc":[{"id":"1.232199708","rc":[{"batb":[[0,1.5,20.77]],"ltp":2.5,"tv":14.96,"id":3961},{"batb":[[0,1.3,20.99],[1,1.04,128.53],[2,1.03,200]],"ltp":4.7,"tv":12.23,"id":60443}]}]}
{"op":"mcm","clk":"11986641848","pt":1724926873397,"mc":[{"id":"1.232199708","rc":[{"batb":[[0,2.58,4.3],[1,2.56,9.6],[2,2.54,5.05]],"ltp":2.56,"tv":65.41,"id":424679}]}]}
{"op":"mcm","clk":"11986642015","pt":1724926875706,"mc":[{"id":"1.232199708","rc":[{"batb":[[0,2.56,9.9],[1,2.54,5.05],[2,1.5,20]],"ltp":2.56,"tv":65.41,"id":424679}]}]}
{"op":"mcm","clk":"11986642148","pt":1724926877607,"mc":[{"id":"1.232199708","rc":[{"batl":[[0,10,5],[1,12.5,1.3],[2,90,3.03]],"ltp":2.56,"tv":65.41,"id":424679}]}]}
{"op":"mcm","clk":"11986642546","pt":1724926882503,"mc":[{"id":"1.232199708","rc":[{"batl":[[1,90,3.33],[2,990,3.34]],"ltp":2.56,"tv":65.41,"id":424679}]}]}
{"op":"mcm","clk":"11986643338","pt":1724926893114,"mc":[{"id":"1.232199708","rc":[{"batl":[[0,9.8,1],[1,10,5],[2,90,3.33]],"ltp":2.56,"tv":65.41,"id":424679}]}]}
{"op":"mcm","clk":"11986645368","pt":1724926919843,"mc":[{"id":"1.232199708","rc":[{"batl":[[1,90,3.33],[2,990,3.34]],"ltp":2.56,"tv":65.41,"id":424679}]}]}
{"op":"mcm","clk":"11986645765","pt":1724926924979,"mc":[{"id":"1.232199708","rc":[{"batl":[[0,9.4,5],[1,9.8,1],[2,90,3.33]],"ltp":2.56,"tv":65.41,"id":424679}]}]}
{"op":"mcm","clk":"11986645921","pt":1724926927088,"mc":[{"id":"1.232199708","rc":[{"batl":[[1,90,3.33],[2,990,3.34]],"ltp":2.56,"tv":65.41,"id":424679}]}]}
{"op":"mcm","clk":"11986645957","pt":1724926927501,"mc":[{"id":"1.232199708","rc":[{"batl":[[0,90,3.33],[1,990,3.34],[2,990,0]],"ltp":2.56,"tv":65.41,"id":424679}]}]}
{"op":"mcm","clk":"11986646511","pt":1724926934197,"mc":[{"id":"1.232199708","rc":[{"batl":[[0,9,1],[1,90,3.33],[2,990,3.34]],"ltp":2.56,"tv":65.41,"id":424679}]}]}
{"op":"mcm","clk":"11986646635","pt":1724926935900,"mc":[{"id":"1.232199708","rc":[{"batl":[[0,8,1],[1,9,1],[2,90,3.33]],"ltp":2.56,"tv":65.41,"id":424679}]}]}
{"op":"mcm","clk":"11986646737","pt":1724926936982,"mc":[{"id":"1.232199708","rc":[{"batl":[[0,7,1],[1,8,1],[2,9,1]],"ltp":2.56,"tv":65.41,"id":424679}]}]}
{"op":"mcm","clk":"11986646848","pt":1724926938374,"mc":[{"id":"1.232199708","rc":[{"batl":[[0,6,1],[1,7,1],[2,8,1]],"ltp":2.56,"tv":65.41,"id":424679}]}]}
{"op":"mcm","clk":"11986647975","pt":1724926954430,"mc":[{"id":"1.232199708","rc":[{"batl":[[0,5.9,1],[1,6,1],[2,7,1]],"ltp":2.56,"tv":65.41,"id":424679}]}]}
{"op":"mcm","clk":"11986652673","pt":1724927015388,"mc":[{"id":"1.232199708","rc":[{"batl":[[1,7,1],[2,8,1]],"ltp":2.56,"tv":65.41,"id":424679}]}]}
{"op":"mcm","clk":"11986652743","pt":1724927016265,"mc":[{"id":"1.232199708","rc":[{"batl":[[1,8,1],[2,9,1]],"ltp":2.56,"tv":65.41,"id":424679}]}]}
{"op":"mcm","clk":"11986652866","pt":1724927017859,"mc":[{"id":"1.232199708","rc":[{"batl":[[1,9,1],[2,90,3.33]],"ltp":2.56,"tv":65.41,"id":424679}]}]}
{"op":"mcm","clk":"11986652943","pt":1724927018776,"mc":[{"id":"1.232199708","rc":[{"batl":[[1,90,3.33],[2,990,3.34]],"ltp":2.56,"tv":65.41,"id":424679}]}]}
{"op":"mcm","clk":"11986659015","pt":1724927091233,"mc":[{"id":"1.232199708","rc":[{"batl":[[0,5.9,1.3]],"ltp":2.56,"tv":65.41,"id":424679}]}]}
{"op":"mcm","clk":"11986659136","pt":1724927092650,"mc":[{"id":"1.232199708","rc":[{"batl":[[1,90,3.03]],"ltp":2.56,"tv":65.41,"id":424679}]}]}
{"op":"mcm","clk":"11986663587","pt":1724927150294,"mc":[{"id":"1.232199708","rc":[{"batb":[[1,1.07,1],[2,1.04,126.53]],"ltp":2.5,"tv":14.96,"id":3961},{"batb":[[1,1.07,1],[2,1.04,128.53]],"ltp":4.7,"tv":12.23,"id":60443}]}]}
{"op":"mcm","clk":"11986663964","pt":1724927155905,"mc":[{"id":"1.232199708","rc":[{"batb":[[1,1.04,126.53],[2,1.03,200]],"ltp":2.5,"tv":14.96,"id":3961},{"batb":[[1,1.04,128.53],[2,1.03,200]],"ltp":4.7,"tv":12.23,"id":60443}]}]}
{"op":"mcm","clk":"11986664333","pt":1724927160994,"mc":[{"id":"1.232199708","rc":[{"batb":[[0,2.56,10.2]],"ltp":2.56,"tv":65.41,"id":424679},{"batb":[[0,1.51,1.13],[1,1.5,19.94],[2,1.04,126.53]],"batl":[[0,13.5,1.6]],"ltp":2.5,"tv":14.96,"id":3961},{"batb":[[0,1.31,1.29],[1,1.3,20],[2,1.04,128.53]],"batl":[[0,14.5,1.6]],"ltp":4.7,"tv":12.23,"id":60443}]}]}
{"op":"mcm","clk":"11986664680","pt":1724927166100,"mc":[{"id":"1.232199708","rc":[{"batb":[[0,2.56,9.9]],"ltp":2.56,"tv":65.41,"id":424679}]}]}
{"op":"mcm","clk":"11986664723","pt":1724927166614,"mc":[{"id":"1.232199708","rc":[{"batb":[[0,1.3,20.99],[1,1.04,128.53],[2,1.03,200]],"ltp":4.7,"tv":12.23,"id":60443}]}]}
{"op":"mcm","clk":"11986664814","pt":1724927167802,"mc":[{"id":"1.232199708","rc":[{"batl":[[0,13.5,1.3]],"ltp":2.5,"tv":14.96,"id":3961},{"batl":[[0,14.5,1.3]],"ltp":4.7,"tv":12.23,"id":60443}]}]}
{"op":"mcm","clk":"11986664966","pt":1724927169808,"mc":[{"id":"1.232199708","rc":[{"batb":[[0,1.5,20.77],[1,1.04,126.53],[2,1.03,200]],"ltp":2.5,"tv":14.96,"id":3961}]}]}
{"op":"mcm","clk":"11986678524","pt":1724927350983,"mc":[{"id":"1.232199708","rc":[{"batl":[[0,13.5,1.83]],"ltp":2.5,"tv":14.96,"id":3961}]}]}
{"op":"mcm","clk":"11986679901","pt":1724927368715,"mc":[{"id":"1.232199708","rc":[{"batl":[[0,14.5,1.83]],"ltp":4.7,"tv":12.23,"id":60443}]}]}
{"op":"mcm","clk":"11986680517","pt":1724927376502,"mc":[{"id":"1.232199708","rc":[{"batl":[[0,5.9,1.83]],"ltp":2.56,"tv":65.41,"id":424679}]}]}
{"op":"mcm","clk":"11986681314","pt":1724927386413,"mc":[{"id":"1.232199708","rc":[{"batl":[[0,5.9,1.53]],"ltp":2.56,"tv":65.41,"id":424679}]}]}
{"op":"mcm","clk":"11986681782","pt":1724927392707,"mc":[{"id":"1.232199708","rc":[{"batl":[[0,5.9,1.83]],"ltp":2.56,"tv":65.41,"id":424679}]}]}
{"op":"mcm","clk":"11986686991","pt":1724927459018,"mc":[{"id":"1.232199708","rc":[{"batb":[[1,1.07,1],[2,1.04,126.53]],"ltp":2.5,"tv":14.96,"id":3961},{"batb":[[1,1.07,1],[2,1.04,128.53]],"ltp":4.7,"tv":12.23,"id":60443}]}]}
{"op":"mcm","clk":"11986687449","pt":1724927464298,"mc":[{"id":"1.232199708","rc":[{"batb":[[1,1.04,126.83],[2,1.03,200]],"ltp":2.5,"tv":14.96,"id":3961},{"batb":[[1,1.04,128.83],[2,1.03,200]],"ltp":4.7,"tv":12.23,"id":60443}]}]}
{"op":"mcm","clk":"11986687541","pt":1724927465395,"mc":[{"id":"1.232199708","rc":[{"batb":[[0,2.56,9.6]],"ltp":2.56,"tv":65.41,"id":424679},{"batb":[[1,1.04,126.53]],"ltp":2.5,"tv":14.96,"id":3961},{"batb":[[1,1.04,128.53]],"ltp":4.7,"tv":12.23,"id":60443}]}]}
{"op":"mcm","clk":"11986687581","pt":1724927465807,"mc":[{"id":"1.232199708","rc":[{"batl":[[0,13.5,1.53]],"ltp":2.5,"tv":14.96,"id":3961},{"batl":[[0,14.5,1.53]],"ltp":4.7,"tv":12.23,"id":60443}]}]}
{"op":"mcm","clk":"11986687902","pt":1724927469410,"mc":[{"id":"1.232199708","rc":[{"batl":[[0,13.5,1.83]],"ltp":2.5,"tv":14.96,"id":3961},{"batl":[[0,14.5,1.83]],"ltp":4.7,"tv":12.23,"id":60443}]}]}
{"op":"mcm","clk":"11986687953","pt":1724927469825,"mc":[{"id":"1.232199708","rc":[{"batb":[[0,1.51,1.13],[1,1.5,19.94],[2,1.04,126.53]],"ltp":2.5,"tv":14.96,"id":3961},{"batb":[[0,1.32,1.29],[1,1.3,20],[2,1.04,128.53]],"ltp":4.7,"tv":12.23,"id":60443}]}]}
{"op":"mcm","clk":"11986688402","pt":1724927475429,"mc":[{"id":"1.232199708","rc":[{"batb":[[0,2.56,9.9]],"ltp":2.56,"tv":65.41,"id":424679},{"batb":[[0,1.5,20.77],[1,1.04,126.53],[2,1.03,200]],"ltp":2.5,"tv":14.96,"id":3961}]}]}
{"op":"mcm","clk":"11986688450","pt":1724927475695,"mc":[{"id":"1.232199708","rc":[{"batb":[[0,1.3,20.99],[1,1.04,128.53],[2,1.03,200]],"ltp":4.7,"tv":12.23,"id":60443}]}]}
{"op":"mcm","clk":"11986704867","pt":1724927684338,"mc":[{"id":"1.232199708","rc":[{"batl":[[0,5.9,1.53]],"ltp":2.56,"tv":65.41,"id":424679}]}]}
{"op":"mcm","clk":"11986705044","pt":1724927687270,"mc":[{"id":"1.232199708","rc":[{"batl":[[0,5.9,1.83]],"ltp":2.56,"tv":65.41,"id":424679}]}]}
{"op":"mcm","clk":"11986706754","pt":1724927710806,"mc":[{"id":"1.232199708","rc":[{"trd":[[1.5,0.68],[1.51,0.6],[1.55,1.06]],"batb":[[0,1.5,19.66]],"ltp":1.5,"tv":17.19,"id":3961}],"tv":94.83}]}
{"op":"mcm","clk":"11986708038","pt":1724927727591,"mc":[{"id":"1.232199708","rc":[{"batb":[[0,1.52,3.03],[1,1.5,19.66],[2,1.04,126.53]],"ltp":1.5,"tv":17.19,"id":3961}]}]}
{"op":"mcm","clk":"11986709862","pt":1724927755857,"mc":[{"id":"1.232199708","rc":[{"batl":[[0,13,1.13],[1,13.5,1],[2,14,6]],"ltp":1.5,"tv":17.19,"id":3961}]}]}
{"op":"mcm","clk":"11986709943","pt":1724927756940,"mc":[{"id":"1.232199708","rc":[{"batl":[[1,14,6],[2,85,2.5]],"ltp":1.5,"tv":17.19,"id":3961}]}]}
{"op":"mcm","clk":"11986710737","pt":1724927768383,"mc":[{"id":"1.232199708","rc":[{"batb":[[2,1.07,1]],"batl":[[0,12.5,1.83],[1,14,6.3]],"ltp":1.5,"tv":17.19,"id":3961},{"batb":[[1,1.07,1],[2,1.04,128.53]],"ltp":4.7,"tv":12.23,"id":60443}]}]}
{"op":"mcm","clk":"11986711148","pt":1724927774186,"mc":[{"id":"1.232199708","rc":[{"batb":[[2,1.04,126.53]],"ltp":1.5,"tv":17.19,"id":3961},{"batb":[[1,1.04,128.53],[2,1.03,200]],"ltp":4.7,"tv":12.23,"id":60443}]}]}
{"op":"mcm","clk":"11986711515","pt":1724927779303,"mc":[{"id":"1.232199708","rc":[{"batb":[[0,1.52,3.33]],"batl":[[0,12.5,2.13]],"ltp":1.5,"tv":17.19,"id":3961},{"batb":[[0,1.32,1.29],[1,1.3,20],[2,1.04,128.53]],"batl":[[0,14,1.13],[1,14.5,1],[2,15,2]],"ltp":4.7,"tv":12.23,"id":60443}]}]}
{"op":"mcm","clk":"11986711663","pt":1724927781991,"mc":[{"id":"1.232199708","rc":[{"batl":[[1,14,6]],"ltp":1.5,"tv":17.19,"id":3961},{"batl":[[0,14.5,1.83],[1,15,2],[2,85,3.04]],"ltp":4.7,"tv":12.23,"id":60443}]}]}
{"op":"mcm","clk":"11986711806","pt":1724927784308,"mc":[{"id":"1.232199708","rc":[{"batb":[[0,1.3,20.99],[1,1.04,128.53],[2,1.03,200]],"ltp":4.7,"tv":12.23,"id":60443}]}]}
{"op":"mcm","clk":"11986712145","pt":1724927789465,"mc":[{"id":"1.232199708","rc":[{"batb":[[0,2.56,10.2]],"ltp":2.56,"tv":65.41,"id":424679}]}]}
{"op":"mcm","clk":"11986712242","pt":1724927790923,"mc":[{"id":"1.232199708","rc":[{"batb":[[0,2.56,9.9]],"ltp":2.56,"tv":65.41,"id":424679}]}]}
{"op":"mcm","clk":"11986728196","pt":1724928007412,"mc":[{"id":"1.232199708","rc":[{"batl":[[0,5.9,1.53]],"ltp":2.56,"tv":65.41,"id":424679}]}]}
{"op":"mcm","clk":"11986728662","pt":1724928012849,"mc":[{"id":"1.232199708","rc":[{"batl":[[0,5.9,1.83]],"ltp":2.56,"tv":65.41,"id":424679}]}]}
{"op":"mcm","clk":"11986731867","pt":1724928060108,"mc":[{"id":"1.232199708","rc":[{"batb":[[2,1.07,1]],"ltp":1.5,"tv":17.19,"id":3961},{"batb":[[1,1.07,1],[2,1.04,128.53]],"ltp":4.7,"tv":12.23,"id":60443}]}]}
{"op":"mcm","clk":"11986732293","pt":1724928065470,"mc":[{"id":"1.232199708","rc":[{"batb":[[0,2.56,10.2]],"ltp":2.56,"tv":65.41,"id":424679},{"batb":[[0,1.52,3.03],[2,1.04,126.83]],"batl":[[0,12,1.13],[1,12.5,1.3],[2,14,6]],"ltp":1.5,"tv":17.19,"id":3961},{"batb":[[0,1.3,20.69],[1,1.04,128.53],[2,1.03,200]],"batl":[[0,14,1.13],[1,14.5,1],[2,15,2]],"ltp":4.7,"tv":12.23,"id":60443}]}]}
{"op":"mcm","clk":"11986732302","pt":1724928065574,"mc":[{"id":"1.232199708","rc":[{"batb":[[2,1.04,126.53]],"ltp":1.5,"tv":17.19,"id":3961}]}]}
{"op":"mcm","clk":"11986732427","pt":1724928067370,"mc":[{"id":"1.232199708","rc":[{"batl":[[1,12.5,1]],"ltp":1.5,"tv":17.19,"id":3961},{"batl":[[0,14.5,1.83],[1,15,2],[2,85,3.04]],"ltp":4.7,"tv":12.23,"id":60443}]}]}
{"op":"mcm","clk":"11986732554","pt":1724928068779,"mc":[{"id":"1.232199708","rc":[{"batl":[[1,14,6],[2,85,2.5]],"ltp":1.5,"tv":17.19,"id":3961}]}]}
{"op":"mcm","clk":"11986732696","pt":1724928070675,"mc":[{"id":"1.232199708","rc":[{"batb":[[0,1.52,3.33]],"ltp":1.5,"tv":17.19,"id":3961},{"batb":[[0,1.3,20.99]],"ltp":4.7,"tv":12.23,"id":60443}]}]}
{"op":"mcm","clk":"11986732771","pt":1724928071804,"mc":[{"id":"1.232199708","rc":[{"batb":[[0,2.56,9.9]],"ltp":2.56,"tv":65.41,"id":424679}]}]}
{"op":"mcm","clk":"11986733780","pt":1724928084911,"mc":[{"id":"1.232199708","rc":[{"batl":[[0,11.5,1.83],[1,14,6.3]],"ltp":1.5,"tv":17.19,"id":3961}]}]}
{"op":"mcm","clk":"11986735702","pt":1724928109028,"mc":[{"id":"1.232199708","rc":[{"trd":[[1.5,16.3],[1.52,6.06],[1.53,0.6]],"batb":[[0,1.5,11.85],[1,1.04,126.53],[2,1.03,200]],"ltp":1.5,"tv":39.46,"id":3961}],"tv":117.11}]}
{"op":"mcm","clk":"11986739106","pt":1724928150882,"mc":[{"id":"1.232199708","rc":[{"batl":[[0,11,1.36],[1,11.5,1],[2,14,6.3]],"ltp":1.5,"tv":39.46,"id":3961}]}]}
{"op":"mcm","clk":"11986739262","pt":1724928152273,"mc":[{"id":"1.232199708","rc":[{"batl":[[1,14,6.3],[2,85,2.5]],"ltp":1.5,"tv":39.46,"id":3961}]}]}
{"op":"mcm","clk":"11986740552","pt":1724928168511,"mc":[{"id":"1.232199708","rc":[{"batl":[[0,10.5,1.83],[1,14,6.83]],"ltp":1.5,"tv":39.46,"id":3961}]}]}
{"op":"mcm","clk":"11986756662","pt":1724928364337,"mc":[{"id":"1.232199708","rc":[{"batb":[[1,1.07,1],[2,1.04,126.53]],"ltp":1.5,"tv":39.46,"id":3961},{"batb":[[1,1.07,1],[2,1.04,128.53]],"ltp":4.7,"tv":12.23,"id":60443}]}]}
{"op":"mcm","clk":"11986757162","pt":1724928369436,"mc":[{"id":"1.232199708","rc":[{"batb":[[1,1.04,126.83],[2,1.03,200]],"batl":[[0,10,1.13],[1,10.5,1],[2,14,6.83]],"ltp":1.5,"tv":39.46,"id":3961},{"batb":[[1,1.04,128.53],[2,1.03,200]],"ltp":4.7,"tv":12.23,"id":60443}]}]}
{"op":"mcm","clk":"11986757247","pt":1724928370315,"mc":[{"id":"1.232199708","rc":[{"batb":[[1,1.04,126.53]],"ltp":1.5,"tv":39.46,"id":3961}]}]}
{"op":"mcm","clk":"11986757629","pt":1724928374431,"mc":[{"id":"1.232199708","rc":[{"batb":[[0,1.32,1.29],[1,1.3,20],[2,1.04,128.53]],"ltp":4.7,"tv":12.23,"id":60443}]}]}
{"op":"mcm","clk":"11986757692","pt":1724928375048,"mc":[{"id":"1.232199708","rc":[{"batb":[[0,1.5,12.15]],"batl":[[1,14,6.83],[2,85,2.5]],"ltp":1.5,"tv":39.46,"id":3961},{"batl":[[0,14,1.13],[1,14.5,1],[2,15,2]],"ltp":4.7,"tv":12.23,"id":60443}]}]}
{"op":"mcm","clk":"11986757734","pt":1724928375561,"mc":[{"id":"1.232199708","rc":[{"batb":[[0,2.56,10.2]],"ltp":2.56,"tv":65.41,"id":424679}]}]}
{"op":"mcm","clk":"11986758172","pt":1724928380766,"mc":[{"id":"1.232199708","rc":[{"batl":[[1,15,2],[2,85,3.04]],"ltp":4.7,"tv":12.23,"id":60443}]}]}
{"op":"mcm","clk":"11986758321","pt":1724928382453,"mc":[{"id":"1.232199708","rc":[{"batl":[[0,15,2.83],[1,85,3.04],[2,940,1.01]],"ltp":4.7,"tv":12.23,"id":60443}]}]}
{"op":"mcm","clk":"11986758360","pt":1724928382762,"mc":[{"id":"1.232199708","rc":[{"batb":[[0,2.56,9.9]],"ltp":2.56,"tv":65.41,"id":424679},{"batl":[[1,14,6.53]],"ltp":1.5,"tv":39.46,"id":3961}]}]}
{"op":"mcm","clk":"11986758531","pt":1724928384566,"mc":[{"id":"1.232199708","rc":[{"batb":[[0,1.3,20.99],[1,1.04,128.53],[2,1.03,200]],"ltp":4.7,"tv":12.23,"id":60443}]}]}
{"op":"mcm","clk":"11986759565","pt":1724928396777,"mc":[{"id":"1.232199708","rc":[{"batl":[[0,14.5,1.83],[1,15,2],[2,85,3.04]],"ltp":4.7,"tv":12.23,"id":60443}]}]}
{"op":"mcm","clk":"11986760009","pt":1724928402488,"mc":[{"id":"1.232199708","rc":[{"batl":[[0,9.8,1.83],[1,14,6.83]],"ltp":1.5,"tv":39.46,"id":3961}]}]}
{"op":"mcm","clk":"11986782092","pt":1724928672296,"mc":[{"id":"1.232199708","rc":[{"batb":[[1,1.07,1],[2,1.04,126.53]],"ltp":1.5,"tv":39.46,"id":3961},{"batb":[[1,1.07,1],[2,1.04,128.53]],"ltp":4.7,"tv":12.23,"id":60443}]}]}
{"op":"mcm","clk":"11986782251","pt":1724928674310,"mc":[{"id":"1.232199708","rc":[{"batl":[[1,14,6.53]],"ltp":1.5,"tv":39.46,"id":3961}]}]}
{"op":"mcm","clk":"11986782349","pt":1724928675703,"mc":[{"id":"1.232199708","rc":[{"batb":[[0,2.56,9.6]],"ltp":2.56,"tv":65.41,"id":424679}]}]}
{"op":"mcm","clk":"11986782473","pt":1724928677404,"mc":[{"id":"1.232199708","rc":[{"batb":[[0,1.5,11.85],[1,1.04,126.53],[2,1.03,200]],"batl":[[0,9.6,1.13],[1,9.8,1],[2,14,6.53]],"ltp":1.5,"tv":39.46,"id":3961}]}]}
{"op":"mcm","clk":"11986782537","pt":1724928678176,"mc":[{"id":"1.232199708","rc":[{"batb":[[0,1.3,20.69],[1,1.04,128.53],[2,1.03,200]],"ltp":4.7,"tv":12.23,"id":60443}]}]}
{"op":"mcm","clk":"11986782844","pt":1724928682490,"mc":[{"id":"1.232199708","rc":[{"batb":[[0,1.5,12.15]],"ltp":1.5,"tv":39.46,"id":3961}]}]}
{"op":"mcm","clk":"11986782879","pt":1724928682904,"mc":[{"id":"1.232199708","rc":[{"batb":[[0,2.56,9.9]],"ltp":2.56,"tv":65.41,"id":424679},{"batb":[[0,1.3,20.99]],"ltp":4.7,"tv":12.23,"id":60443}]}]}
{"op":"mcm","clk":"11986783187","pt":1724928687024,"mc":[{"id":"1.232199708","rc":[{"batl":[[1,14,6.53],[2,85,2.5]],"ltp":1.5,"tv":39.46,"id":3961}]}]}
{"op":"mcm","clk":"11986783933","pt":1724928697633,"mc":[{"id":"1.232199708","rc":[{"batl":[[0,9.4,1.83],[1,14,6.83]],"ltp":1.5,"tv":39.46,"id":3961}]}]}
{"op":"mcm","clk":"11986797919","pt":1724928904267,"mc":[{"id":"1.232199708","rc":[{"batl":[[0,5.9,1.53]],"ltp":2.56,"tv":65.41,"id":424679}]}]}
{"op":"mcm","clk":"11986798079","pt":1724928906339,"mc":[{"id":"1.232199708","rc":[{"batl":[[0,5.9,1.83]],"ltp":2.56,"tv":65.41,"id":424679}]}]}
{"op":"mcm","clk":"11986802962","pt":1724928971048,"mc":[{"id":"1.232199708","rc":[{"batb":[[1,1.07,1],[2,1.04,126.53]],"ltp":1.5,"tv":39.46,"id":3961}]}]}
{"op":"mcm","clk":"11986803336","pt":1724928976125,"mc":[{"id":"1.232199708","rc":[{"batb":[[1,1.04,126.83],[2,1.03,200]],"ltp":1.5,"tv":39.46,"id":3961},{"batb":[[0,1.32,1.29],[1,1.3,20],[2,1.04,128.53]],"ltp":4.7,"tv":12.23,"id":60443}]}]}
{"op":"mcm","clk":"11986803567","pt":1724928979161,"mc":[{"id":"1.232199708","rc":[{"batl":[[0,14.5,1.53]],"ltp":4.7,"tv":12.23,"id":60443}]}]}
{"op":"mcm","clk":"11986803647","pt":1724928980245,"mc":[{"id":"1.232199708","rc":[{"batl":[[1,14,6.53]],"ltp":1.5,"tv":39.46,"id":3961}]}]}
{"op":"mcm","clk":"11986803733","pt":1724928981234,"mc":[{"id":"1.232199708","rc":[{"batb":[[1,1.04,126.53]],"batl":[[0,9.2,1.13],[1,9.4,1],[2,14,6.53]],"ltp":1.5,"tv":39.46,"id":3961},{"batl":[[0,14.5,1.83]],"ltp":4.7,"tv":12.23,"id":60443}]}]}
{"op":"mcm","clk":"11986803805","pt":1724928982151,"mc":[{"id":"1.232199708","rc":[{"batl":[[1,14,6.53],[2,85,2.5]],"ltp":1.5,"tv":39.46,"id":3961}]}]}
{"op":"mcm","clk":"11986803887","pt":1724928983134,"mc":[{"id":"1.232199708","rc":[{"batb":[[0,1.5,11.85]],"ltp":1.5,"tv":39.46,"id":3961}]}]}
{"op":"mcm","clk":"11986803999","pt":1724928984432,"mc":[{"id":"1.232199708","rc":[{"batb":[[0,1.3,20.99],[1,1.04,128.53],[2,1.03,200]],"ltp":4.7,"tv":12.23,"id":60443}]}]}
{"op":"mcm","clk":"11986804035","pt":1724928984845,"mc":[{"id":"1.232199708","rc":[{"batb":[[0,2.56,9.6]],"ltp":2.56,"tv":65.41,"id":424679}]}]}
{"op":"mcm","clk":"11986804155","pt":1724928986335,"mc":[{"id":"1.232199708","rc":[{"batb":[[0,2.56,9.9]],"ltp":2.56,"tv":65.41,"id":424679},{"batb":[[0,1.5,12.15]],"ltp":1.5,"tv":39.46,"id":3961}]}]}
{"op":"mcm","clk":"11986804646","pt":1724928992857,"mc":[{"id":"1.232199708","rc":[{"batl":[[0,9,1.83],[1,14,6.83]],"ltp":1.5,"tv":39.46,"id":3961}]}]}
{"op":"mcm","clk":"11986815197","pt":1724929127082,"mc":[{"id":"1.232199708","rc":[{"batb":[[0,1.52,3.79],[1,1.5,12.15],[2,1.04,126.53]],"ltp":1.5,"tv":39.46,"id":3961}]}]}
{"op":"mcm","clk":"11986815395","pt":1724929129988,"mc":[{"id":"1.232199708","rc":[{"batl":[[1,14,6.3]],"ltp":1.5,"tv":39.46,"id":3961}]}]}
{"op":"mcm","clk":"11986815699","pt":1724929133688,"mc":[{"id":"1.232199708","rc":[{"trd":[[2.56,33.18],[2.58,28.25]],"batb":[[0,2.56,9.41]],"ltp":2.56,"tv":66.39,"id":424679}],"tv":118.09}]}
{"op":"mcm","clk":"11986815815","pt":1724929135126,"mc":[{"id":"1.232199708","rc":[{"batl":[[0,8,1.36],[1,9,1],[2,14,6.3]],"ltp":1.5,"tv":39.46,"id":3961}]}]}
{"op":"mcm","clk":"11986816036","pt":1724929138085,"mc":[{"id":"1.232199708","rc":[{"batl":[[1,14,6.3],[2,85,2.5]],"ltp":1.5,"tv":39.46,"id":3961}]}]}
{"op":"mcm","clk":"11986816084","pt":1724929138805,"mc":[{"id":"1.232199708","rc":[{"batb":[[0,2.58,4],[1,2.56,9.41],[2,2.54,5.05]],"ltp":2.56,"tv":66.39,"id":424679}]}]}
{"op":"mcm","clk":"11986816309","pt":1724929140994,"mc":[{"id":"1.232199708","rc":[{"batb":[[0,2.56,9.41],[1,2.54,5.05],[2,1.5,20]],"ltp":2.56,"tv":66.39,"id":424679}]}]}
{"op":"mcm","clk":"11986816952","pt":1724929148626,"mc":[{"id":"1.232199708","rc":[{"batl":[[0,7.8,1.83],[1,14,6.83]],"ltp":1.5,"tv":39.46,"id":3961}]}]}
{"op":"mcm","clk":"11986817367","pt":1724929153004,"mc":[{"id":"1.232199708","rc":[{"batb":[[0,2.58,4],[1,2.56,9.41],[2,2.54,5.05]],"ltp":2.56,"tv":66.39,"id":424679}]}]}
{"op":"mcm","clk":"11986817553","pt":1724929155318,"mc":[{"id":"1.232199708","rc":[{"batb":[[0,2.56,9.41],[1,2.54,5.05],[2,1.5,20]],"ltp":2.56,"tv":66.39,"id":424679}]}]}
{"op":"mcm","clk":"11986821616","pt":1724929205982,"mc":[{"id":"1.232199708","rc":[{"batb":[[1,2.54,5.05]],"batl":[[0,5.9,1.53]],"ltp":2.56,"tv":66.39,"id":424679},{"trd":[[1.5,16.3],[1.52,6.06]],"ltp":1.5,"tv":39.47,"id":3961},{"batb":[[2,1.01,279.94]],"ltp":4.7,"tv":12.23,"id":60443}],"tv":118.1}]}
{"op":"mcm","clk":"11986822176","pt":1724929211083,"mc":[{"id":"1.232199708","rc":[{"batl":[[0,5.9,1.83]],"ltp":2.56,"tv":66.39,"id":424679}]}]}
{"op":"mcm","clk":"11986827193","pt":1724929275448,"mc":[{"id":"1.232199708","rc":[{"batb":[[2,1.07,1]],"ltp":1.5,"tv":39.47,"id":3961},{"batb":[[1,1.07,1],[2,1.04,128.53]],"ltp":4.7,"tv":12.23,"id":60443}]}]}
{"op":"mcm","clk":"11986827227","pt":1724929275958,"mc":[{"id":"1.232199708","rc":[{"batb":[[2,1.04,126.53]],"ltp":1.5,"tv":39.47,"id":3961},{"batb":[[1,1.04,128.83],[2,1.01,279.94]],"ltp":4.7,"tv":12.23,"id":60443}]}]}
