{"op":"mcm","clk":"11905870449","pt":1724370070065,"mc":[{"id":"1.232174751","marketDefinition":{"bspMarket":false,"turnInPlayEnabled":true,"persistenceEnabled":true,"marketBaseRate":5.0,"eventId":"33519697","eventTypeId":"4","numberOfWinners":1,"bettingType":"ODDS","marketType":"MATCH_ODDS","marketTime":"2024-08-23T18:30:00.000Z","suspendTime":"2024-08-23T18:30:00.000Z","bspReconciled":false,"complete":true,"inPlay":false,"crossMatching":true,"runnersVoidable":false,"numberOfActiveRunners":2,"betDelay":0,"status":"OPEN","runners":[{"status":"ACTIVE","sortPriority":1,"id":72857115,"name":"Miami Lions"},{"status":"ACTIVE","sortPriority":2,"id":72857116,"name":"Grand Cayman Stingrays"}],"regulators":["MR_INT"],"countryCode":"GB","discountAllowed":false,"timezone":"GMT","openDate":"2024-08-23T18:30:00.000Z","version":6091712287,"name":"Match Odds","eventName":"Miami Lions v Grand Cayman Stingrays"},"rc":[{"batb":[[0,1.03,200],[1,1.02,200],[2,1.01,220]],"ltp":0.0,"tv":0.0,"id":72857115},{"batb":[[0,1.03,200],[1,1.02,200],[2,1.01,220]],"ltp":0.0,"tv":0.0,"id":72857116}]}]}
{"op":"mcm","clk":"11905870542","pt":1724370071645,"mc":[{"id":"1.232174751","marketDefinition":{"bspMarket":false,"turnInPlayEnabled":true,"persistenceEnabled":true,"marketBaseRate":5.0,"eventId":"33519697","eventTypeId":"4","numberOfWinners":1,"bettingType":"ODDS","marketType":"MATCH_ODDS","marketTime":"2024-08-23T18:30:00.000Z","suspendTime":"2024-08-23T18:30:00.000Z","bspReconciled":false,"complete":true,"inPlay":false,"crossMatching":true,"runnersVoidable":false,"numberOfActiveRunners":2,"betDelay":0,"status":"OPEN","runners":[{"status":"ACTIVE","sortPriority":1,"id":72857115,"name":"Miami Lions"},{"status":"ACTIVE","sortPriority":2,"id":72857116,"name":"Grand Cayman Stingrays"}],"regulators":["MR_INT"],"countryCode":"GB","discountAllowed":true,"timezone":"GMT","openDate":"2024-08-23T18:30:00.000Z","version":6091712287,"name":"Match Odds","eventName":"Miami Lions v Grand Cayman Stingrays"}}]}
{"op":"mcm","clk":"11906042768","pt":1724373156136,"mc":[{"id":"1.232174751","rc":[{"batb":[[2,1.01,481]],"ltp":0.0,"tv":0.0,"id":72857115},{"batb":[[2,1.01,481]],"ltp":0.0,"tv":0.0,"id":72857116}]}]}
{"op":"mcm","clk":"11906064581","pt":1724373511529,"mc":[{"id":"1.232174751","rc":[{"batb":[[0,2.72,25.79],[1,1.03,200],[2,1.02,200]],"ltp":0.0,"tv":0.0,"id":72857115},{"batb":[[0,1.53,83.7],[1,1.03,200],[2,1.02,200]],"ltp":0.0,"tv":0.0,"id":72857116}]}]}
{"op":"mcm","clk":"11906109977","pt":1724374251913,"mc":[{"id":"1.232174751","rc":[{"batb":[[1,1.05,5.19],[2,1.03,200]],"ltp":0.0,"tv":0.0,"id":72857116}]}]}
{"op":"mcm","clk":"11906115596","pt":1724374344792,"mc":[{"id":"1.232174751","rc":[{"batb":[[1,1.4,259.67],[2,1.05,5.19]],"ltp":0.0,"tv":0.0,"id":72857116}]}]}
{"op":"mcm","clk":"11906116599","pt":1724374361620,"mc":[{"id":"1.232174751","rc":[{"batb":[[2,1.03,200]],"ltp":0.0,"tv":0.0,"id":72857116}]}]}
{"op":"mcm","clk":"11906556161","pt":1724381835265,"mc":[{"id":"1.232174751","rc":[{"batb":[[0,2.64,27.05]],"ltp":0.0,"tv":0.0,"id":72857115},{"batb":[[0,1.56,79.22]],"ltp":0.0,"tv":0.0,"id":72857116}]}]}
{"op":"mcm","clk":"11906688907","pt":1724383713470,"mc":[{"id":"1.232174751","rc":[{"batb":[[2,1.35,155.8]],"ltp":0.0,"tv":0.0,"id":72857116}]}]}
{"op":"mcm","clk":"11906708422","pt":1724383971481,"mc":[{"id":"1.232174751","rc":[{"batb":[[1,1.41,259.67],[2,1.4,259.67]],"ltp":0.0,"tv":0.0,"id":72857116}]}]}
{"op":"mcm","clk":"11907120884","pt":1724390547857,"mc":[{"id":"1.232174751","rc":[{"batb":[[1,1.21,82.86],[2,1.03,200]],"ltp":0.0,"tv":0.0,"id":72857115}]}]}
{"op":"mcm","clk":"11907304748","pt":1724393574757,"mc":[{"id":"1.232174751","rc":[{"batb":[[1,1.21,82.85]],"ltp":0.0,"tv":0.0,"id":72857115}]}]}
{"op":"mcm","clk":"11907649660","pt":1724398974757,"mc":[{"id":"1.232174751","rc":[{"batb":[[1,1.21,82.84]],"ltp":0.0,"tv":0.0,"id":72857115}]}]}
{"op":"mcm","clk":"11907836643","pt":1724401708561,"mc":[{"id":"1.232174751","rc":[{"trd":[[2.64,1.02]],"batb":[[0,2.64,26.54],[1,1.21,82.51]],"ltp":2.64,"tv":1.02,"id":72857115}],"tv":1.02}]}
{"op":"mcm","clk":"11907836890","pt":1724401712129,"mc":[{"id":"1.232174751","rc":[{"batb":[[0,2.64,27.05]],"ltp":2.64,"tv":1.02,"id":72857115}]}]}
{"op":"mcm","clk":"11907855454","pt":1724402015678,"mc":[{"id":"1.232174751","rc":[{"trd":[[1.56,2]],"batb":[[0,1.56,78.22]],"ltp":1.56,"tv":2.0,"id":72857116}],"tv":3.02}]}
{"op":"mcm","clk":"11907855632","pt":1724402018461,"mc":[{"id":"1.232174751","rc":[{"batb":[[0,1.56,79.22]],"ltp":1.56,"tv":2.0,"id":72857116}]}]}
{"op":"mcm","clk":"11907943490","pt":1724403597301,"mc":[{"id":"1.232174751","rc":[{"batb":[[1,1.48,2],[2,1.21,82.51]],"ltp":2.64,"tv":1.02,"id":72857115}]}]}
{"op":"mcm","clk":"11907945858","pt":1724403614619,"mc":[{"id":"1.232174751","rc":[{"batb":[[2,1.21,82.41]],"ltp":2.64,"tv":1.02,"id":72857115},{"batb":[[1,1.48,2],[2,1.41,259.67]],"ltp":1.56,"tv":2.0,"id":72857116}]}]}
{"op":"mcm","clk":"11908040954","pt":1724404805274,"mc":[{"id":"1.232174751","rc":[{"trd":[[2.64,3.02]],"batb":[[0,2.64,26.05]],"ltp":2.64,"tv":3.02,"id":72857115}],"tv":5.02}]}
{"op":"mcm","clk":"11908041083","pt":1724404807489,"mc":[{"id":"1.232174751","rc":[{"batb":[[0,2.64,27.05]],"ltp":2.64,"tv":3.02,"id":72857115}]}]}
{"op":"mcm","clk":"11908041358","pt":1724404812072,"mc":[{"id":"1.232174751","rc":[{"batl":[[0,2.5,1]],"ltp":1.56,"tv":2.0,"id":72857116}]}]}
{"op":"mcm","clk":"11908201145","pt":1724407095653,"mc":[{"id":"1.232174751","rc":[{"trd":[[1.56,8]],"batb":[[0,1.56,76.22]],"ltp":1.56,"tv":8.0,"id":72857116}],"tv":11.02}]}
{"op":"mcm","clk":"11908201517","pt":1724407099932,"mc":[{"id":"1.232174751","rc":[{"batb":[[0,1.56,79.22]],"ltp":1.56,"tv":8.0,"id":72857116}]}]}
{"op":"mcm","clk":"11908219658","pt":1724407302664,"mc":[{"id":"1.232174751","rc":[{"batb":[[2,1.21,82.35]],"ltp":2.64,"tv":3.02,"id":72857115},{"trd":[[1.56,38.74]],"batb":[[0,1.56,63.85]],"ltp":1.56,"tv":38.74,"id":72857116}],"tv":41.76}]}
{"op":"mcm","clk":"11908219864","pt":1724407305495,"mc":[{"id":"1.232174751","rc":[{"batb":[[0,1.56,79.22]],"ltp":1.56,"tv":38.74,"id":72857116}]}]}
{"op":"mcm","clk":"11908368479","pt":1724409045009,"mc":[{"id":"1.232174751","rc":[{"batl":[[0,1.61,25.62],[1,2.5,1]],"ltp":1.56,"tv":38.74,"id":72857116}]}]}
{"op":"mcm","clk":"11908380941","pt":1724409182763,"mc":[{"id":"1.232174751","rc":[{"trd":[[1.56,44.74]],"batb":[[0,1.56,76.22]],"ltp":1.56,"tv":44.74,"id":72857116}],"tv":47.76}]}
{"op":"mcm","clk":"11908381202","pt":1724409185458,"mc":[{"id":"1.232174751","rc":[{"batb":[[0,1.56,79.22]],"ltp":1.56,"tv":44.74,"id":72857116}]}]}
{"op":"mcm","clk":"11908487854","pt":1724410258125,"mc":[{"id":"1.232174751","rc":[{"batl":[[0,1.6,276.92],[1,1.61,25.62],[2,2.5,1]],"ltp":1.56,"tv":44.74,"id":72857116}]}]}
{"op":"mcm","clk":"11908528190","pt":1724410717904,"mc":[{"id":"1.232174751","rc":[{"batb":[[2,1.25,800]],"ltp":2.64,"tv":3.02,"id":72857115}]}]}
{"op":"mcm","clk":"11908568151","pt":1724411115591,"mc":[{"id":"1.232174751","rc":[{"batb":[[0,2.68,8.18],[1,2.64,27.05],[2,1.48,2]],"ltp":2.64,"tv":3.02,"id":72857115},{"trd":[[1.56,44.75]],"batl":[[0,1.59,13.59],[1,1.6,276.92],[2,1.61,25.64]],"ltp":1.56,"tv":44.75,"id":72857116}],"tv":47.77}]}
{"op":"mcm","clk":"11908964657","pt":1724415013217,"mc":[{"id":"1.232174751","rc":[{"batb":[[0,2.68,8.18]],"ltp":2.64,"tv":3.02,"id":72857115},{"trd":[[1.56,54.76]],"batb":[[0,1.56,74.22]],"batl":[[0,1.59,13.59],[2,1.61,25.65]],"ltp":1.56,"tv":54.76,"id":72857116}],"tv":57.78}]}
{"op":"mcm","clk":"11908965097","pt":1724415017515,"mc":[{"id":"1.232174751","rc":[{"batb":[[0,1.56,79.22]],"ltp":1.56,"tv":54.76,"id":72857116}]}]}
{"op":"mcm","clk":"11909109325","pt":1724416343540,"mc":[{"id":"1.232174751","rc":[{"trd":[[1.56,154.76]],"batb":[[0,1.56,29.22]],"ltp":1.56,"tv":154.76,"id":72857116}],"tv":157.78}]}
{"op":"mcm","clk":"11909109609","pt":1724416345952,"mc":[{"id":"1.232174751","rc":[{"batb":[[0,1.56,79.22]],"ltp":1.56,"tv":154.76,"id":72857116}]}]}
{"op":"mcm","clk":"11909157029","pt":1724416800746,"mc":[{"id":"1.232174751","rc":[{"batb":[[2,1.45,10.62]],"ltp":1.56,"tv":154.76,"id":72857116}]}]}
{"op":"mcm","clk":"11909175799","pt":1724417020082,"mc":[{"id":"1.232174751","rc":[{"batb":[[0,2.7,9],[1,2.68,8.18],[2,2.64,27.05]],"batl":[[0,4,3.08]],"ltp":2.64,"tv":3.02,"id":72857115}]}]}
{"op":"mcm","clk":"11909175971","pt":1724417022195,"mc":[{"id":"1.232174751","rc":[{"batb":[[0,2.7,5]],"ltp":2.64,"tv":3.02,"id":72857115}]}]}
{"op":"mcm","clk":"11909176066","pt":1724417023482,"mc":[{"id":"1.232174751","rc":[{"batb":[[0,2.68,8.18],[1,2.64,27.05],[2,1.99,5.64]],"ltp":2.64,"tv":3.02,"id":72857115}]}]}
{"op":"mcm","clk":"11909176398","pt":1724417027293,"mc":[{"id":"1.232174751","rc":[{"batb":[[0,2.7,9],[1,2.68,8.18],[2,2.64,27.05]],"batl":[[0,3.9,3.08]],"ltp":2.64,"tv":3.02,"id":72857115}]}]}
{"op":"mcm","clk":"11909176584","pt":1724417029509,"mc":[{"id":"1.232174751","rc":[{"batb":[[0,2.7,5]],"ltp":2.64,"tv":3.02,"id":72857115}]}]}
{"op":"mcm","clk":"11909176668","pt":1724417030493,"mc":[{"id":"1.232174751","rc":[{"batb":[[0,2.68,8.18],[1,2.64,27.05],[2,1.99,5.64]],"ltp":2.64,"tv":3.02,"id":72857115}]}]}
{"op":"mcm","clk":"11909181765","pt":1724417091375,"mc":[{"id":"1.232174751","rc":[{"batb":[[0,2.7,9],[1,2.68,8.18],[2,2.64,27.05]],"ltp":2.64,"tv":3.02,"id":72857115}]}]}
{"op":"mcm","clk":"11909181983","pt":1724417093897,"mc":[{"id":"1.232174751","rc":[{"batb":[[0,2.7,5]],"ltp":2.64,"tv":3.02,"id":72857115}]}]}
{"op":"mcm","clk":"11909182072","pt":1724417094774,"mc":[{"id":"1.232174751","rc":[{"batb":[[0,2.68,8.18],[1,2.64,27.05],[2,1.99,5.64]],"ltp":2.64,"tv":3.02,"id":72857115}]}]}
{"op":"mcm","clk":"11909182290","pt":1724417097611,"mc":[{"id":"1.232174751","rc":[{"batb":[[0,2.7,9],[1,2.68,8.18],[2,2.64,27.05]],"ltp":2.64,"tv":3.02,"id":72857115}]}]}
{"op":"mcm","clk":"11909182487","pt":1724417099902,"mc":[{"id":"1.232174751","rc":[{"batb":[[0,2.7,5]],"ltp":2.64,"tv":3.02,"id":72857115}]}]}
{"op":"mcm","clk":"11909182593","pt":1724417100892,"mc":[{"id":"1.232174751","rc":[{"batb":[[0,2.68,8.18],[1,2.64,27.05],[2,1.99,5.64]],"ltp":2.64,"tv":3.02,"id":72857115}]}]}
{"op":"mcm","clk":"11909184472","pt":1724417120949,"mc":[{"id":"1.232174751","rc":[{"batb":[[0,2.7,9],[1,2.68,8.18],[2,2.64,27.05]],"ltp":2.64,"tv":3.02,"id":72857115}]}]}
{"op":"mcm","clk":"11909184698","pt":1724417123423,"mc":[{"id":"1.232174751","rc":[{"batb":[[0,2.7,5]],"ltp":2.64,"tv":3.02,"id":72857115}]}]}
{"op":"mcm","clk":"11909184790","pt":1724417124555,"mc":[{"id":"1.232174751","rc":[{"batb":[[0,2.68,8.18],[1,2.64,27.05],[2,1.99,5.64]],"ltp":2.64,"tv":3.02,"id":72857115}]}]}
{"op":"mcm","clk":"11909185641","pt":1724417134637,"mc":[{"id":"1.232174751","rc":[{"batb":[[0,2.7,9],[1,2.68,8.18],[2,2.64,27.05]],"ltp":2.64,"tv":3.02,"id":72857115}]}]}
{"op":"mcm","clk":"11909185854","pt":1724417136964,"mc":[{"id":"1.232174751","rc":[{"batb":[[0,2.7,5]],"ltp":2.64,"tv":3.02,"id":72857115}]}]}
{"op":"mcm","clk":"11909185950","pt":1724417138049,"mc":[{"id":"1.232174751","rc":[{"batb":[[0,2.68,8.18],[1,2.64,27.05],[2,1.99,5.64]],"ltp":2.64,"tv":3.02,"id":72857115}]}]}
{"op":"mcm","clk":"11909186259","pt":1724417141956,"mc":[{"id":"1.232174751","rc":[{"batb":[[0,2.7,9],[1,2.68,8.18],[2,2.64,27.05]],"ltp":2.64,"tv":3.02,"id":72857115}]}]}
{"op":"mcm","clk":"11909186459","pt":1724417144385,"mc":[{"id":"1.232174751","rc":[{"batb":[[0,2.7,5]],"ltp":2.64,"tv":3.02,"id":72857115}]}]}
{"op":"mcm","clk":"11909186548","pt":1724417145473,"mc":[{"id":"1.232174751","rc":[{"batb":[[0,2.68,8.18],[1,2.64,27.05],[2,1.99,5.64]],"ltp":2.64,"tv":3.02,"id":72857115}]}]}
{"op":"mcm","clk":"11909186852","pt":1724417148486,"mc":[{"id":"1.232174751","rc":[{"batb":[[0,2.7,9],[1,2.68,8.18],[2,2.64,27.05]],"ltp":2.64,"tv":3.02,"id":72857115}]}]}
{"op":"mcm","clk":"11909187046","pt":1724417150715,"mc":[{"id":"1.232174751","rc":[{"batb":[[0,2.7,5]],"ltp":2.64,"tv":3.02,"id":72857115}]}]}
{"op":"mcm","clk":"11909187184","pt":1724417151804,"mc":[{"id":"1.232174751","rc":[{"batb":[[0,2.68,8.18],[1,2.64,27.05],[2,1.99,5.64]],"ltp":2.64,"tv":3.02,"id":72857115}]}]}
{"op":"mcm","clk":"11909188464","pt":1724417164002,"mc":[{"id":"1.232174751","rc":[{"batb":[[0,2.7,9],[1,2.68,8.18],[2,2.64,27.05]],"ltp":2.64,"tv":3.02,"id":72857115}]}]}
{"op":"mcm","clk":"11909188758","pt":1724417166594,"mc":[{"id":"1.232174751","rc":[{"batb":[[0,2.7,5]],"ltp":2.64,"tv":3.02,"id":72857115}]}]}
{"op":"mcm","clk":"11909188872","pt":1724417167689,"mc":[{"id":"1.232174751","rc":[{"batb":[[0,2.68,8.18],[1,2.64,27.05],[2,1.99,5.64]],"ltp":2.64,"tv":3.02,"id":72857115}]}]}
{"op":"mcm","clk":"11909190579","pt":1724417183333,"mc":[{"id":"1.232174751","rc":[{"batb":[[0,2.7,9],[1,2.68,8.18],[2,2.64,27.05]],"ltp":2.64,"tv":3.02,"id":72857115}]}]}
{"op":"mcm","clk":"11909190873","pt":1724417185818,"mc":[{"id":"1.232174751","rc":[{"batb":[[0,2.7,5]],"ltp":2.64,"tv":3.02,"id":72857115}]}]}
{"op":"mcm","clk":"11909190989","pt":1724417186906,"mc":[{"id":"1.232174751","rc":[{"batb":[[0,2.68,8.18],[1,2.64,27.05],[2,1.99,5.64]],"ltp":2.64,"tv":3.02,"id":72857115}]}]}
{"op":"mcm","clk":"11909191533","pt":1724417191715,"mc":[{"id":"1.232174751","rc":[{"batb":[[0,2.7,9],[1,2.68,8.18],[2,2.64,27.05]],"ltp":2.64,"tv":3.02,"id":72857115}]}]}
{"op":"mcm","clk":"11909191858","pt":1724417194638,"mc":[{"id":"1.232174751","rc":[{"batb":[[0,2.7,5]],"ltp":2.64,"tv":3.02,"id":72857115}]}]}
{"op":"mcm","clk":"11909191961","pt":1724417195648,"mc":[{"id":"1.232174751","rc":[{"batb":[[0,2.68,8.18],[1,2.64,27.05],[2,1.99,5.64]],"ltp":2.64,"tv":3.02,"id":72857115}]}]}
{"op":"mcm","clk":"11909192480","pt":1724417200548,"mc":[{"id":"1.232174751","rc":[{"batb":[[0,2.7,9],[1,2.68,8.18],[2,2.64,27.05]],"ltp":2.64,"tv":3.02,"id":72857115}]}]}
{"op":"mcm","clk":"11909192753","pt":1724417203036,"mc":[{"id":"1.232174751","rc":[{"batb":[[0,2.7,5]],"ltp":2.64,"tv":3.02,"id":72857115}]}]}
{"op":"mcm","clk":"11909192861","pt":1724417204017,"mc":[{"id":"1.232174751","rc":[{"batb":[[0,2.68,8.18],[1,2.64,27.05],[2,1.99,5.64]],"ltp":2.64,"tv":3.02,"id":72857115}]}]}
{"op":"mcm","clk":"11909192969","pt":1724417205248,"mc":[{"id":"1.232174751","rc":[{"batb":[[0,2.7,4],[1,2.68,8.18],[2,2.64,27.05]],"ltp":2.64,"tv":3.02,"id":72857115}]}]}
{"op":"mcm","clk":"11909193210","pt":1724417207528,"mc":[{"id":"1.232174751","rc":[{"batb":[[0,2.68,8.18],[1,2.64,27.05],[2,1.99,5.64]],"ltp":2.64,"tv":3.02,"id":72857115}]}]}
{"op":"mcm","clk":"11909193236","pt":1724417207831,"mc":[{"id":"1.232174751","rc":[{"batb":[[0,2.7,5],[1,2.68,8.18],[2,2.64,27.05]],"ltp":2.64,"tv":3.02,"id":72857115}]}]}
{"op":"mcm","clk":"11909193561","pt":1724417211147,"mc":[{"id":"1.232174751","rc":[{"batb":[[0,2.7,4]],"ltp":2.64,"tv":3.02,"id":72857115}]}]}
{"op":"mcm","clk":"11909193790","pt":1724417213527,"mc":[{"id":"1.232174751","rc":[{"batb":[[0,2.7,5]],"ltp":2.64,"tv":3.02,"id":72857115}]}]}
{"op":"mcm","clk":"11909194141","pt":1724417217052,"mc":[{"id":"1.232174751","rc":[{"batb":[[0,2.7,4]],"ltp":2.64,"tv":3.02,"id":72857115}]}]}
{"op":"mcm","clk":"11909194378","pt":1724417219377,"mc":[{"id":"1.232174751","rc":[{"batb":[[0,2.7,5]],"ltp":2.64,"tv":3.02,"id":72857115}]}]}
{"op":"mcm","clk":"11909194727","pt":1724417222968,"mc":[{"id":"1.232174751","rc":[{"batb":[[0,2.7,4]],"ltp":2.64,"tv":3.02,"id":72857115}]}]}
{"op":"mcm","clk":"11909195007","pt":1724417225510,"mc":[{"id":"1.232174751","rc":[{"batb":[[0,2.7,5]],"ltp":2.64,"tv":3.02,"id":72857115}]}]}
{"op":"mcm","clk":"11909195200","pt":1724417227575,"mc":[{"id":"1.232174751","rc":[{"batb":[[0,2.72,4],[1,2.7,5],[2,2.68,8.18]],"ltp":2.64,"tv":3.02,"id":72857115}]}]}
{"op":"mcm","clk":"11909195327","pt":1724417228871,"mc":[{"id":"1.232174751","rc":[{"batb":[[1,2.68,8.18],[2,2.64,27.05]],"ltp":2.64,"tv":3.02,"id":72857115}]}]}
{"op":"mcm","clk":"11909195426","pt":1724417229905,"mc":[{"id":"1.232174751","rc":[{"batb":[[0,2.68,8.18],[1,2.64,27.05],[2,1.99,5.64]],"ltp":2.64,"tv":3.02,"id":72857115}]}]}
{"op":"mcm","clk":"11909196644","pt":1724417242372,"mc":[{"id":"1.232174751","rc":[{"batb":[[0,2.7,9],[1,2.68,8.18],[2,2.64,27.05]],"ltp":2.64,"tv":3.02,"id":72857115}]}]}
{"op":"mcm","clk":"11909196882","pt":1724417244703,"mc":[{"id":"1.232174751","rc":[{"batb":[[0,2.7,5]],"ltp":2.64,"tv":3.02,"id":72857115}]}]}
{"op":"mcm","clk":"11909196997","pt":1724417245686,"mc":[{"id":"1.232174751","rc":[{"batb":[[0,2.68,8.18],[1,2.64,27.05],[2,1.99,5.64]],"ltp":2.64,"tv":3.02,"id":72857115}]}]}
{"op":"mcm","clk":"11909197913","pt":1724417254390,"mc":[{"id":"1.232174751","rc":[{"batb":[[0,2.7,9],[1,2.68,8.18],[2,2.64,27.05]],"ltp":2.64,"tv":3.02,"id":72857115}]}]}
{"op":"mcm","clk":"11909198168","pt":1724417257022,"mc":[{"id":"1.232174751","rc":[{"batb":[[0,2.7,5]],"ltp":2.64,"tv":3.02,"id":72857115}]}]}
{"op":"mcm","clk":"11909198248","pt":1724417257910,"mc":[{"id":"1.232174751","rc":[{"batb":[[0,2.68,8.18],[1,2.64,27.05],[2,1.99,5.64]],"ltp":2.64,"tv":3.02,"id":72857115}]}]}
{"op":"mcm","clk":"11909199027","pt":1724417265807,"mc":[{"id":"1.232174751","rc":[{"batb":[[0,2.7,9],[1,2.68,8.18],[2,2.64,27.05]],"ltp":2.64,"tv":3.02,"id":72857115}]}]}
{"op":"mcm","clk":"11909199245","pt":1724417268445,"mc":[{"id":"1.232174751","rc":[{"batb":[[0,2.7,5]],"ltp":2.64,"tv":3.02,"id":72857115}]}]}
{"op":"mcm","clk":"11909199338","pt":1724417269421,"mc":[{"id":"1.232174751","rc":[{"batb":[[0,2.68,8.18],[1,2.64,27.05],[2,1.99,5.64]],"ltp":2.64,"tv":3.02,"id":72857115}]}]}
{"op":"mcm","clk":"11909200006","pt":1724417276219,"mc":[{"id":"1.232174751","rc":[{"batb":[[0,2.7,9],[1,2.68,8.18],[2,2.64,27.05]],"ltp":2.64,"tv":3.02,"id":72857115}]}]}
{"op":"mcm","clk":"11909200222","pt":1724417278748,"mc":[{"id":"1.232174751","rc":[{"batb":[[0,2.7,5]],"ltp":2.64,"tv":3.02,"id":72857115}]}]}
{"op":"mcm","clk":"11909200327","pt":1724417279833,"mc":[{"id":"1.232174751","rc":[{"batb":[[0,2.68,8.18],[1,2.64,27.05],[2,1.99,5.64]],"ltp":2.64,"tv":3.02,"id":72857115}]}]}
{"op":"mcm","clk":"11909202332","pt":1724417297545,"mc":[{"id":"1.232174751","rc":[{"batb":[[0,2.7,9],[1,2.68,8.18],[2,2.64,27.05]],"ltp":2.64,"tv":3.02,"id":72857115}]}]}
{"op":"mcm","clk":"11909202605","pt":1724417300086,"mc":[{"id":"1.232174751","rc":[{"batb":[[0,2.7,5]],"ltp":2.64,"tv":3.02,"id":72857115}]}]}
{"op":"mcm","clk":"11909202711","pt":1724417301084,"mc":[{"id":"1.232174751","rc":[{"batb":[[0,2.68,8.18],[1,2.64,27.05],[2,1.99,5.64]],"ltp":2.64,"tv":3.02,"id":72857115}]}]}
{"op":"mcm","clk":"11909203145","pt":1724417305077,"mc":[{"id":"1.232174751","rc":[{"batb":[[0,2.7,9],[1,2.68,8.18],[2,2.64,27.05]],"ltp":2.64,"tv":3.02,"id":72857115}]}]}
{"op":"mcm","clk":"11909203405","pt":1724417307466,"mc":[{"id":"1.232174751","rc":[{"batb":[[0,2.7,5]],"ltp":2.64,"tv":3.02,"id":72857115}]}]}
{"op":"mcm","clk":"11909203485","pt":1724417308396,"mc":[{"id":"1.232174751","rc":[{"batb":[[0,2.68,8.18],[1,2.64,27.05],[2,1.99,5.64]],"ltp":2.64,"tv":3.02,"id":72857115}]}]}
{"op":"mcm","clk":"11909206255","pt":1724417336510,"mc":[{"id":"1.232174751","rc":[{"batb":[[0,2.7,9],[1,2.68,8.18],[2,2.64,27.05]],"ltp":2.64,"tv":3.02,"id":72857115}]}]}
{"op":"mcm","clk":"11909206515","pt":1724417339057,"mc":[{"id":"1.232174751","rc":[{"batb":[[0,2.7,5]],"ltp":2.64,"tv":3.02,"id":72857115}]}]}
{"op":"mcm","clk":"11909206639","pt":1724417339995,"mc":[{"id":"1.232174751","rc":[{"batb":[[0,2.68,8.18],[1,2.64,27.05],[2,1.99,5.64]],"ltp":2.64,"tv":3.02,"id":72857115}]}]}
{"op":"mcm","clk":"11909209650","pt":1724417369958,"mc":[{"id":"1.232174751","rc":[{"batb":[[0,2.7,9],[1,2.68,8.18],[2,2.64,27.05]],"ltp":2.64,"tv":3.02,"id":72857115}]}]}
{"op":"mcm","clk":"11909209897","pt":1724417372423,"mc":[{"id":"1.232174751","rc":[{"batb":[[0,2.7,5]],"ltp":2.64,"tv":3.02,"id":72857115}]}]}
{"op":"mcm","clk":"11909209991","pt":1724417373464,"mc":[{"id":"1.232174751","rc":[{"batb":[[0,2.68,8.18],[1,2.64,27.05],[2,1.99,5.64]],"ltp":2.64,"tv":3.02,"id":72857115}]}]}
{"op":"mcm","clk":"11909210201","pt":1724417375332,"mc":[{"id":"1.232174751","rc":[{"batb":[[0,2.7,4],[1,2.68,8.18],[2,2.64,27.05]],"ltp":2.64,"tv":3.02,"id":72857115}]}]}
{"op":"mcm","clk":"11909210487","pt":1724417378135,"mc":[{"id":"1.232174751","rc":[{"batb":[[0,2.7,5]],"ltp":2.64,"tv":3.02,"id":72857115}]}]}
{"op":"mcm","clk":"11909210825","pt":1724417381557,"mc":[{"id":"1.232174751","rc":[{"batb":[[0,2.7,4]],"ltp":2.64,"tv":3.02,"id":72857115}]}]}
{"op":"mcm","clk":"11909211048","pt":1724417384159,"mc":[{"id":"1.232174751","rc":[{"batb":[[0,2.7,5]],"ltp":2.64,"tv":3.02,"id":72857115}]}]}
{"op":"mcm","clk":"11909211357","pt":1724417387483,"mc":[{"id":"1.232174751","rc":[{"batb":[[0,2.7,4]],"ltp":2.64,"tv":3.02,"id":72857115}]}]}
{"op":"mcm","clk":"11909211550","pt":1724417389767,"mc":[{"id":"1.232174751","rc":[{"batb":[[0,2.7,5]],"ltp":2.64,"tv":3.02,"id":72857115}]}]}
{"op":"mcm","clk":"11909211879","pt":1724417393362,"mc":[{"id":"1.232174751","rc":[{"batb":[[0,2.7,4]],"ltp":2.64,"tv":3.02,"id":72857115}]}]}
{"op":"mcm","clk":"11909212057","pt":1724417395544,"mc":[{"id":"1.232174751","rc":[{"batb":[[0,2.68,8.18],[1,2.64,27.05],[2,1.99,5.64]],"ltp":2.64,"tv":3.02,"id":72857115}]}]}
{"op":"mcm","clk":"11909212078","pt":1724417395754,"mc":[{"id":"1.232174751","rc":[{"batb":[[0,2.7,5],[1,2.68,8.18],[2,2.64,27.05]],"ltp":2.64,"tv":3.02,"id":72857115}]}]}
{"op":"mcm","clk":"11909212446","pt":1724417399284,"mc":[{"id":"1.232174751","rc":[{"batb":[[0,2.7,4]],"ltp":2.64,"tv":3.02,"id":72857115}]}]}
{"op":"mcm","clk":"11909212710","pt":1724417401604,"mc":[{"id":"1.232174751","rc":[{"batb":[[0,2.7,5]],"ltp":2.64,"tv":3.02,"id":72857115}]}]}
{"op":"mcm","clk":"11909213174","pt":1724417404900,"mc":[{"id":"1.232174751","rc":[{"batb":[[0,2.7,4]],"ltp":2.64,"tv":3.02,"id":72857115}]}]}
{"op":"mcm","clk":"11909213359","pt":1724417407074,"mc":[{"id":"1.232174751","rc":[{"batb":[[0,2.72,5]],"ltp":2.64,"tv":3.02,"id":72857115}]}]}
{"op":"mcm","clk":"11909213690","pt":1724417410494,"mc":[{"id":"1.232174751","rc":[{"batb":[[0,2.7,4]],"ltp":2.64,"tv":3.02,"id":72857115}]}]}
{"op":"mcm","clk":"11909213966","pt":1724417413089,"mc":[{"id":"1.232174751","rc":[{"batb":[[0,2.7,5]],"ltp":2.64,"tv":3.02,"id":72857115}]}]}
{"op":"mcm","clk":"11909214342","pt":1724417416408,"mc":[{"id":"1.232174751","rc":[{"batb":[[0,2.72,4]],"ltp":2.64,"tv":3.02,"id":72857115}]}]}
{"op":"mcm","clk":"11909214485","pt":1724417417915,"mc":[{"id":"1.232174751","rc":[{"batb":[[0,2.68,8.18],[1,2.64,27.05],[2,1.99,5.64]],"ltp":2.64,"tv":3.02,"id":72857115}]}]}
{"op":"mcm","clk":"11909215147","pt":1724417424618,"mc":[{"id":"1.232174751","rc":[{"batb":[[0,2.7,9],[1,2.68,8.18],[2,2.64,27.05]],"ltp":2.64,"tv":3.02,"id":72857115}]}]}
{"op":"mcm","clk":"11909215368","pt":1724417426952,"mc":[{"id":"1.232174751","rc":[{"batb":[[0,2.7,5]],"ltp":2.64,"tv":3.02,"id":72857115}]}]}
{"op":"mcm","clk":"11909215448","pt":1724417427791,"mc":[{"id":"1.232174751","rc":[{"batb":[[0,2.68,8.18],[1,2.64,27.05],[2,1.99,5.64]],"ltp":2.64,"tv":3.02,"id":72857115}]}]}
{"op":"mcm","clk":"11909216089","pt":1724417434200,"mc":[{"id":"1.232174751","rc":[{"batb":[[0,2.7,9],[1,2.68,8.18],[2,2.64,27.05]],"ltp":2.64,"tv":3.02,"id":72857115}]}]}
{"op":"mcm","clk":"11909216317","pt":1724417436731,"mc":[{"id":"1.232174751","rc":[{"batb":[[0,2.7,5]],"ltp":2.64,"tv":3.02,"id":72857115}]}]}
{"op":"mcm","clk":"11909216397","pt":1724417437721,"mc":[{"id":"1.232174751","rc":[{"batb":[[0,2.68,8.18],[1,2.64,27.05],[2,1.99,5.64]],"ltp":2.64,"tv":3.02,"id":72857115}]}]}
{"op":"mcm","clk":"11909217118","pt":1724417444610,"mc":[{"id":"1.232174751","rc":[{"batb":[[0,2.7,9],[1,2.68,8.18],[2,2.64,27.05]],"ltp":2.64,"tv":3.02,"id":72857115}]}]}
{"op":"mcm","clk":"11909217326","pt":1724417447147,"mc":[{"id":"1.232174751","rc":[{"batb":[[0,2.7,5]],"ltp":2.64,"tv":3.02,"id":72857115}]}]}
{"op":"mcm","clk":"11909217409","pt":1724417448128,"mc":[{"id":"1.232174751","rc":[{"batb":[[0,2.68,8.18],[1,2.64,27.05],[2,1.99,5.64]],"ltp":2.64,"tv":3.02,"id":72857115}]}]}
{"op":"mcm","clk":"11909217730","pt":1724417451640,"mc":[{"id":"1.232174751","rc":[{"batb":[[0,2.7,9],[1,2.68,8.18],[2,2.64,27.05]],"ltp":2.64,"tv":3.02,"id":72857115}]}]}
{"op":"mcm","clk":"11909217918","pt":1724417453913,"mc":[{"id":"1.232174751","rc":[{"batb":[[0,2.7,5]],"ltp":2.64,"tv":3.02,"id":72857115}]}]}
{"op":"mcm","clk":"11909217998","pt":1724417454941,"mc":[{"id":"1.232174751","rc":[{"batb":[[0,2.68,8.18],[1,2.64,27.05],[2,1.99,5.64]],"ltp":2.64,"tv":3.02,"id":72857115}]}]}
{"op":"mcm","clk":"11909224893","pt":1724417522001,"mc":[{"id":"1.232174751","rc":[{"batb":[[0,2.7,9],[1,2.68,8.18],[2,2.64,27.05]],"ltp":2.64,"tv":3.02,"id":72857115}]}]}
{"op":"mcm","clk":"11909225173","pt":1724417524423,"mc":[{"id":"1.232174751","rc":[{"batb":[[0,2.7,5]],"ltp":2.64,"tv":3.02,"id":72857115}]}]}
{"op":"mcm","clk":"11909225320","pt":1724417525521,"mc":[{"id":"1.232174751","rc":[{"batb":[[0,2.68,8.18],[1,2.64,27.05],[2,1.99,5.64]],"ltp":2.64,"tv":3.02,"id":72857115}]}]}
{"op":"mcm","clk":"11909225562","pt":1724417527414,"mc":[{"id":"1.232174751","rc":[{"batb":[[0,2.7,4],[1,2.68,8.18],[2,2.64,27.05]],"ltp":2.64,"tv":3.02,"id":72857115}]}]}
{"op":"mcm","clk":"11909225797","pt":1724417529912,"mc":[{"id":"1.232174751","rc":[{"batb":[[0,2.7,5]],"ltp":2.64,"tv":3.02,"id":72857115}]}]}
{"op":"mcm","clk":"11909226148","pt":1724417533246,"mc":[{"id":"1.232174751","rc":[{"batb":[[0,2.7,4]],"ltp":2.64,"tv":3.02,"id":72857115}]}]}
{"op":"mcm","clk":"11909226426","pt":1724417535619,"mc":[{"id":"1.232174751","rc":[{"batb":[[0,2.68,8.18],[1,2.64,27.05],[2,1.99,5.64]],"ltp":2.64,"tv":3.02,"id":72857115}]}]}
{"op":"mcm","clk":"11909226458","pt":1724417535828,"mc":[{"id":"1.232174751","rc":[{"batb":[[0,2.7,5],[1,2.68,8.18],[2,2.64,27.05]],"ltp":2.64,"tv":3.02,"id":72857115}]}]}
{"op":"mcm","clk":"11909226836","pt":1724417539640,"mc":[{"id":"1.232174751","rc":[{"batb":[[0,2.7,4]],"ltp":2.64,"tv":3.02,"id":72857115}]}]}
{"op":"mcm","clk":"11909227061","pt":1724417541934,"mc":[{"id":"1.232174751","rc":[{"batb":[[0,2.7,5]],"ltp":2.64,"tv":3.02,"id":72857115}]}]}
{"op":"mcm","clk":"11909227406","pt":1724417545434,"mc":[{"id":"1.232174751","rc":[{"batb":[[0,2.7,4]],"ltp":2.64,"tv":3.02,"id":72857115}]}]}
{"op":"mcm","clk":"11909227680","pt":1724417547931,"mc":[{"id":"1.232174751","rc":[{"batb":[[0,2.7,5]],"ltp":2.64,"tv":3.02,"id":72857115}]}]}
{"op":"mcm","clk":"11909227997","pt":1724417551362,"mc":[{"id":"1.232174751","rc":[{"batb":[[0,2.7,4]],"ltp":2.64,"tv":3.02,"id":72857115}]}]}
{"op":"mcm","clk":"11909228196","pt":1724417553560,"mc":[{"id":"1.232174751","rc":[{"batb":[[0,2.68,8.18],[1,2.64,27.05],[2,1.99,5.64]],"ltp":2.64,"tv":3.02,"id":72857115}]}]}
{"op":"mcm","clk":"11909228206","pt":1724417553665,"mc":[{"id":"1.232174751","rc":[{"batb":[[0,2.7,5],[1,2.68,8.18],[2,2.64,27.05]],"ltp":2.64,"tv":3.02,"id":72857115}]}]}
{"op":"mcm","clk":"11909228563","pt":1724417556949,"mc":[{"id":"1.232174751","rc":[{"batb":[[0,2.7,4]],"ltp":2.64,"tv":3.02,"id":72857115}]}]}
{"op":"mcm","clk":"11909228798","pt":1724417559479,"mc":[{"id":"1.232174751","rc":[{"batb":[[0,2.7,5]],"ltp":2.64,"tv":3.02,"id":72857115}]}]}
{"op":"mcm","clk":"11909229118","pt":1724417562582,"mc":[{"id":"1.232174751","rc":[{"batb":[[0,2.68,8.18],[1,2.64,27.05],[2,1.99,5.64]],"ltp":2.64,"tv":3.02,"id":72857115}]}]}
{"op":"mcm","clk":"11909229136","pt":1724417562750,"mc":[{"id":"1.232174751","rc":[{"batb":[[0,2.7,4],[1,2.68,8.18],[2,2.64,27.05]],"ltp":2.64,"tv":3.02,"id":72857115}]}]}
{"op":"mcm","clk":"11909229356","pt":1724417564958,"mc":[{"id":"1.232174751","rc":[{"batb":[[0,2.72,5]],"ltp":2.64,"tv":3.02,"id":72857115}]}]}
{"op":"mcm","clk":"11909229780","pt":1724417568561,"mc":[{"id":"1.232174751","rc":[{"batb":[[0,2.7,4]],"ltp":2.64,"tv":3.02,"id":72857115}]}]}
{"op":"mcm","clk":"11909229986","pt":1724417570775,"mc":[{"id":"1.232174751","rc":[{"batb":[[0,2.72,5]],"ltp":2.64,"tv":3.02,"id":72857115}]}]}
{"op":"mcm","clk":"11909230319","pt":1724417574180,"mc":[{"id":"1.232174751","rc":[{"batb":[[0,2.7,4]],"ltp":2.64,"tv":3.02,"id":72857115}]}]}
{"op":"mcm","clk":"11909230507","pt":1724417576588,"mc":[{"id":"1.232174751","rc":[{"batb":[[0,2.68,8.18],[1,2.64,27.05],[2,1.99,5.64]],"ltp":2.64,"tv":3.02,"id":72857115}]}]}
{"op":"mcm","clk":"11909230516","pt":1724417576695,"mc":[{"id":"1.232174751","rc":[{"batb":[[0,2.7,5],[1,2.68,8.18],[2,2.64,27.05]],"ltp":2.64,"tv":3.02,"id":72857115}]}]}
{"op":"mcm","clk":"11909230825","pt":1724417580093,"mc":[{"id":"1.232174751","rc":[{"batb":[[0,2.7,4]],"ltp":2.64,"tv":3.02,"id":72857115}]}]}
{"op":"mcm","clk":"11909231066","pt":1724417582599,"mc":[{"id":"1.232174751","rc":[{"batb":[[0,2.7,5]],"ltp":2.64,"tv":3.02,"id":72857115}]}]}
{"op":"mcm","clk":"11909231360","pt":1724417585903,"mc":[{"id":"1.232174751","rc":[{"batb":[[0,2.7,4]],"ltp":2.64,"tv":3.02,"id":72857115}]}]}
{"op":"mcm","clk":"11909231563","pt":1724417588389,"mc":[{"id":"1.232174751","rc":[{"batb":[[0,2.7,5]],"ltp":2.64,"tv":3.02,"id":72857115}]}]}
{"op":"mcm","clk":"11909231897","pt":1724417591589,"mc":[{"id":"1.232174751","rc":[{"batb":[[0,2.68,8.18],[1,2.64,27.05],[2,1.99,5.64]],"ltp":2.64,"tv":3.02,"id":72857115}]}]}
{"op":"mcm","clk":"11909231907","pt":1724417591691,"mc":[{"id":"1.232174751","rc":[{"batb":[[0,2.7,4],[1,2.68,8.18],[2,2.64,27.05]],"ltp":2.64,"tv":3.02,"id":72857115}]}]}
{"op":"mcm","clk":"11909232189","pt":1724417594012,"mc":[{"id":"1.232174751","rc":[{"batb":[[0,2.7,5]],"ltp":2.64,"tv":3.02,"id":72857115}]}]}
{"op":"mcm","clk":"11909232502","pt":1724417597321,"mc":[{"id":"1.232174751","rc":[{"batb":[[0,2.7,4]],"ltp":2.64,"tv":3.02,"id":72857115}]}]}
{"op":"mcm","clk":"11909232677","pt":1724417599502,"mc":[{"id":"1.232174751","rc":[{"batb":[[0,2.68,8.18],[1,2.64,27.05],[2,1.99,5.64]],"ltp":2.64,"tv":3.02,"id":72857115}]}]}
{"op":"mcm","clk":"11909232700","pt":1724417599713,"mc":[{"id":"1.232174751","rc":[{"batb":[[0,2.7,5],[1,2.68,8.18],[2,2.64,27.05]],"ltp":2.64,"tv":3.02,"id":72857115}]}]}
{"op":"mcm","clk":"11909233023","pt":1724417603007,"mc":[{"id":"1.232174751","rc":[{"batb":[[0,2.7,4]],"ltp":2.64,"tv":3.02,"id":72857115}]}]}
{"op":"mcm","clk":"11909233270","pt":1724417605634,"mc":[{"id":"1.232174751","rc":[{"batb":[[0,2.7,5]],"ltp":2.64,"tv":3.02,"id":72857115}]}]}
{"op":"mcm","clk":"11909233549","pt":1724417609036,"mc":[{"id":"1.232174751","rc":[{"batb":[[0,2.7,4]],"ltp":2.64,"tv":3.02,"id":72857115}]}]}
{"op":"mcm","clk":"11909233750","pt":1724417611310,"mc":[{"id":"1.232174751","rc":[{"batb":[[0,2.7,5]],"ltp":2.64,"tv":3.02,"id":72857115}]}]}
{"op":"mcm","clk":"11909234076","pt":1724417614524,"mc":[{"id":"1.232174751","rc":[{"batb":[[0,2.68,8.18],[1,2.64,27.05],[2,1.99,5.64]],"ltp":2.64,"tv":3.02,"id":72857115}]}]}
{"op":"mcm","clk":"11909234100","pt":1724417614721,"mc":[{"id":"1.232174751","rc":[{"batb":[[0,2.7,4],[1,2.68,8.18],[2,2.64,27.05]],"ltp":2.64,"tv":3.02,"id":72857115}]}]}
{"op":"mcm","clk":"11909234303","pt":1724417617105,"mc":[{"id":"1.232174751","rc":[{"batb":[[0,2.7,5]],"ltp":2.64,"tv":3.02,"id":72857115}]}]}
{"op":"mcm","clk":"11909234620","pt":1724417620626,"mc":[{"id":"1.232174751","rc":[{"batb":[[0,2.7,4]],"ltp":2.64,"tv":3.02,"id":72857115}]}]}
{"op":"mcm","clk":"11909234847","pt":1724417623149,"mc":[{"id":"1.232174751","rc":[{"batb":[[0,2.7,5]],"ltp":2.64,"tv":3.02,"id":72857115}]}]}
{"op":"mcm","clk":"11909235106","pt":1724417625224,"mc":[{"id":"1.232174751","rc":[{"batb":[[0,2.72,4],[1,2.7,5],[2,2.68,8.18]],"ltp":2.64,"tv":3.02,"id":72857115}]}]}
{"op":"mcm","clk":"11909235326","pt":1724417626530,"mc":[{"id":"1.232174751","rc":[{"batb":[[1,2.68,8.18],[2,2.64,27.05]],"ltp":2.64,"tv":3.02,"id":72857115}]}]}
{"op":"mcm","clk":"11909235443","pt":1724417627411,"mc":[{"id":"1.232174751","rc":[{"batb":[[0,2.68,8.18],[1,2.64,27.05],[2,1.99,5.64]],"ltp":2.64,"tv":3.02,"id":72857115}]}]}
{"op":"mcm","clk":"11909241024","pt":1724417689726,"mc":[{"id":"1.232174751","rc":[{"batb":[[0,2.7,9],[1,2.68,8.18],[2,2.64,27.05]],"ltp":2.64,"tv":3.02,"id":72857115}]}]}
{"op":"mcm","clk":"11909241254","pt":1724417692300,"mc":[{"id":"1.232174751","rc":[{"batb":[[0,2.7,5]],"ltp":2.64,"tv":3.02,"id":72857115}]}]}
{"op":"mcm","clk":"11909241344","pt":1724417693347,"mc":[{"id":"1.232174751","rc":[{"batb":[[0,2.68,8.18],[1,2.64,27.05],[2,1.99,5.64]],"ltp":2.64,"tv":3.02,"id":72857115}]}]}
{"op":"mcm","clk":"11909242698","pt":1724417708413,"mc":[{"id":"1.232174751","rc":[{"batb":[[0,2.7,9],[1,2.68,8.18],[2,2.64,27.05]],"ltp":2.64,"tv":3.02,"id":72857115}]}]}
{"op":"mcm","clk":"11909242903","pt":1724417710739,"mc":[{"id":"1.232174751","rc":[{"batb":[[0,2.7,5]],"ltp":2.64,"tv":3.02,"id":72857115}]}]}
{"op":"mcm","clk":"11909242997","pt":1724417711918,"mc":[{"id":"1.232174751","rc":[{"batb":[[0,2.68,8.18],[1,2.64,27.05],[2,1.99,5.64]],"ltp":2.64,"tv":3.02,"id":72857115}]}]}
{"op":"mcm","clk":"11909243958","pt":1724417719063,"mc":[{"id":"1.232174751","rc":[{"batb":[[0,2.7,9],[1,2.68,8.18],[2,2.64,27.05]],"ltp":2.64,"tv":3.02,"id":72857115}]}]}
{"op":"mcm","clk":"11909244310","pt":1724417721152,"mc":[{"id":"1.232174751","rc":[{"batb":[[0,2.7,5]],"ltp":2.64,"tv":3.02,"id":72857115}]}]}
{"op":"mcm","clk":"11909244486","pt":1724417722550,"mc":[{"id":"1.232174751","rc":[{"batb":[[0,2.68,8.18],[1,2.64,27.05],[2,1.99,5.64]],"ltp":2.64,"tv":3.02,"id":72857115}]}]}
{"op":"mcm","clk":"11909244875","pt":1724417725961,"mc":[{"id":"1.232174751","rc":[{"batb":[[0,2.7,9],[1,2.68,8.18],[2,2.64,27.05]],"ltp":2.64,"tv":3.02,"id":72857115}]}]}
{"op":"mcm","clk":"11909245133","pt":1724417728334,"mc":[{"id":"1.232174751","rc":[{"batb":[[0,2.7,5]],"ltp":2.64,"tv":3.02,"id":72857115}]}]}
{"op":"mcm","clk":"11909245242","pt":1724417729355,"mc":[{"id":"1.232174751","rc":[{"batb":[[0,2.68,8.18],[1,2.64,27.05],[2,1.99,5.64]],"ltp":2.64,"tv":3.02,"id":72857115}]}]}
{"op":"mcm","clk":"11909245968","pt":1724417736350,"mc":[{"id":"1.232174751","rc":[{"batb":[[0,2.7,9],[1,2.68,8.18],[2,2.64,27.05]],"ltp":2.64,"tv":3.02,"id":72857115}]}]}
{"op":"mcm","clk":"11909246235","pt":1724417738879,"mc":[{"id":"1.232174751","rc":[{"batb":[[0,2.7,5]],"ltp":2.64,"tv":3.02,"id":72857115}]}]}
{"op":"mcm","clk":"11909246305","pt":1724417739660,"mc":[{"id":"1.232174751","rc":[{"batb":[[0,2.68,8.18],[1,2.64,27.05],[2,1.99,5.64]],"ltp":2.64,"tv":3.02,"id":72857115}]}]}
{"op":"mcm","clk":"11909247627","pt":1724417751508,"mc":[{"id":"1.232174751","rc":[{"batb":[[0,2.7,9],[1,2.68,8.18],[2,2.64,27.05]],"ltp":2.64,"tv":3.02,"id":72857115}]}]}
{"op":"mcm","clk":"11909247888","pt":1724417753595,"mc":[{"id":"1.232174751","rc":[{"batb":[[0,2.7,5]],"ltp":2.64,"tv":3.02,"id":72857115}]}]}
{"op":"mcm","clk":"11909248026","pt":1724417754997,"mc":[{"id":"1.232174751","rc":[{"batb":[[0,2.68,8.18],[1,2.64,27.05],[2,1.99,5.64]],"ltp":2.64,"tv":3.02,"id":72857115}]}]}
{"op":"mcm","clk":"11909248158","pt":1724417756196,"mc":[{"id":"1.232174751","rc":[{"batb":[[0,2.7,4],[1,2.68,8.18],[2,2.64,27.05]],"ltp":2.64,"tv":3.02,"id":72857115}]}]}
{"op":"mcm","clk":"11909248404","pt":1724417758529,"mc":[{"id":"1.232174751","rc":[{"batb":[[0,2.7,5]],"ltp":2.64,"tv":3.02,"id":72857115}]}]}
{"op":"mcm","clk":"11909248683","pt":1724417760921,"mc":[{"id":"1.232174751","rc":[{"batb":[[0,2.72,4],[1,2.7,5],[2,2.68,8.18]],"ltp":2.64,"tv":3.02,"id":72857115}]}]}
{"op":"mcm","clk":"11909248752","pt":1724417761710,"mc":[{"id":"1.232174751","rc":[{"batb":[[1,2.68,8.18],[2,2.64,27.05]],"ltp":2.64,"tv":3.02,"id":72857115}]}]}
{"op":"mcm","clk":"11909248907","pt":1724417763118,"mc":[{"id":"1.232174751","rc":[{"batb":[[0,2.68,8.18],[1,2.64,27.05],[2,1.99,5.64]],"ltp":2.64,"tv":3.02,"id":72857115}]}]}
{"op":"mcm","clk":"11909249174","pt":1724417765611,"mc":[{"id":"1.232174751","rc":[{"batb":[[0,2.7,9],[1,2.68,8.18],[2,2.64,27.05]],"ltp":2.64,"tv":3.02,"id":72857115}]}]}
{"op":"mcm","clk":"11909249452","pt":1724417768207,"mc":[{"id":"1.232174751","rc":[{"batb":[[0,2.7,5]],"ltp":2.64,"tv":3.02,"id":72857115}]}]}
{"op":"mcm","clk":"11909249542","pt":1724417769126,"mc":[{"id":"1.232174751","rc":[{"batb":[[0,2.68,8.18],[1,2.64,27.05],[2,1.99,5.64]],"ltp":2.64,"tv":3.02,"id":72857115}]}]}
{"op":"mcm","clk":"11909250521","pt":1724417778910,"mc":[{"id":"1.232174751","rc":[{"batb":[[0,2.7,9],[1,2.68,8.18],[2,2.64,27.05]],"ltp":2.64,"tv":3.02,"id":72857115}]}]}
{"op":"mcm","clk":"11909250793","pt":1724417781347,"mc":[{"id":"1.232174751","rc":[{"batb":[[0,2.7,5]],"ltp":2.64,"tv":3.02,"id":72857115}]}]}
{"op":"mcm","clk":"11909250925","pt":1724417782445,"mc":[{"id":"1.232174751","rc":[{"batb":[[0,2.68,8.18],[1,2.64,27.05],[2,1.99,5.64]],"ltp":2.64,"tv":3.02,"id":72857115}]}]}
{"op":"mcm","clk":"11909251281","pt":1724417785951,"mc":[{"id":"1.232174751","rc":[{"batb":[[0,2.7,9],[1,2.68,8.18],[2,2.64,27.05]],"ltp":2.64,"tv":3.02,"id":72857115}]}]}
{"op":"mcm","clk":"11909251551","pt":1724417788439,"mc":[{"id":"1.232174751","rc":[{"batb":[[0,2.7,5]],"ltp":2.64,"tv":3.02,"id":72857115}]}]}
{"op":"mcm","clk":"11909251633","pt":1724417789335,"mc":[{"id":"1.232174751","rc":[{"batb":[[0,2.68,8.18],[1,2.64,27.05],[2,1.99,5.64]],"ltp":2.64,"tv":3.02,"id":72857115}]}]}
{"op":"mcm","clk":"11909251800","pt":1724417791147,"mc":[{"id":"1.232174751","rc":[{"batb":[[0,2.7,4],[1,2.68,8.18],[2,2.64,27.05]],"ltp":2.64,"tv":3.02,"id":72857115}]}]}
{"op":"mcm","clk":"11909252028","pt":1724417793565,"mc":[{"id":"1.232174751","rc":[{"batb":[[0,2.7,5]],"ltp":2.64,"tv":3.02,"id":72857115}]}]}
{"op":"mcm","clk":"11909252480","pt":1724417797039,"mc":[{"id":"1.232174751","rc":[{"batb":[[0,2.7,4]],"ltp":2.64,"tv":3.02,"id":72857115}]}]}
{"op":"mcm","clk":"11909252703","pt":1724417799355,"mc":[{"id":"1.232174751","rc":[{"batb":[[0,2.7,5]],"ltp":2.64,"tv":3.02,"id":72857115}]}]}
{"op":"mcm","clk":"11909253088","pt":1724417802597,"mc":[{"id":"1.232174751","rc":[{"batb":[[0,2.68,8.18],[1,2.64,27.05],[2,1.99,5.64]],"ltp":2.64,"tv":3.02,"id":72857115}]}]}
{"op":"mcm","clk":"11909253112","pt":1724417802764,"mc":[{"id":"1.232174751","rc":[{"batb":[[0,2.7,4],[1,2.68,8.18],[2,2.64,27.05]],"ltp":2.64,"tv":3.02,"id":72857115}]}]}
{"op":"mcm","clk":"11909253359","pt":1724417805258,"mc":[{"id":"1.232174751","rc":[{"batb":[[0,2.7,5]],"ltp":2.64,"tv":3.02,"id":72857115}]}]}
{"op":"mcm","clk":"11909253592","pt":1724417808462,"mc":[{"id":"1.232174751","rc":[{"batb":[[0,2.68,8.18],[1,2.64,27.05],[2,1.99,5.64]],"ltp":2.64,"tv":3.02,"id":72857115}]}]}
{"op":"mcm","clk":"11909253605","pt":1724417808669,"mc":[{"id":"1.232174751","rc":[{"batb":[[0,2.7,4],[1,2.68,8.18],[2,2.64,27.05]],"ltp":2.64,"tv":3.02,"id":72857115}]}]}
{"op":"mcm","clk":"11909253802","pt":1724417811069,"mc":[{"id":"1.232174751","rc":[{"batb":[[0,2.7,5]],"ltp":2.64,"tv":3.02,"id":72857115}]}]}
{"op":"mcm","clk":"11909254108","pt":1724417814360,"mc":[{"id":"1.232174751","rc":[{"batb":[[0,2.7,4]],"ltp":2.64,"tv":3.02,"id":72857115}]}]}
{"op":"mcm","clk":"11909254296","pt":1724417816579,"mc":[{"id":"1.232174751","rc":[{"batb":[[0,2.68,8.18],[1,2.64,27.05],[2,1.99,5.64]],"ltp":2.64,"tv":3.02,"id":72857115}]}]}
{"op":"mcm","clk":"11909254313","pt":1724417816786,"mc":[{"id":"1.232174751","rc":[{"batb":[[0,2.7,5],[1,2.68,8.18],[2,2.64,27.05]],"ltp":2.64,"tv":3.02,"id":72857115}]}]}
{"op":"mcm","clk":"11909254633","pt":1724417820184,"mc":[{"id":"1.232174751","rc":[{"batb":[[0,2.7,4]],"ltp":2.64,"tv":3.02,"id":72857115}]}]}
{"op":"mcm","clk":"11909254877","pt":1724417822596,"mc":[{"id":"1.232174751","rc":[{"batb":[[0,2.7,5]],"ltp":2.64,"tv":3.02,"id":72857115}]}]}
{"op":"mcm","clk":"11909255238","pt":1724417826182,"mc":[{"id":"1.232174751","rc":[{"batb":[[0,2.7,4]],"ltp":2.64,"tv":3.02,"id":72857115}]}]}
{"op":"mcm","clk":"11909255472","pt":1724417828583,"mc":[{"id":"1.232174751","rc":[{"batb":[[0,2.7,5]],"ltp":2.64,"tv":3.02,"id":72857115}]}]}
{"op":"mcm","clk":"11909255800","pt":1724417831990,"mc":[{"id":"1.232174751","rc":[{"batb":[[0,2.7,4]],"ltp":2.64,"tv":3.02,"id":72857115}]}]}
{"op":"mcm","clk":"11909256041","pt":1724417834216,"mc":[{"id":"1.232174751","rc":[{"batb":[[0,2.7,5]],"ltp":2.64,"tv":3.02,"id":72857115}]}]}
{"op":"mcm","clk":"11909256357","pt":1724417837538,"mc":[{"id":"1.232174751","rc":[{"batb":[[0,2.7,4]],"ltp":2.64,"tv":3.02,"id":72857115}]}]}
{"op":"mcm","clk":"11909256586","pt":1724417839904,"mc":[{"id":"1.232174751","rc":[{"batb":[[0,2.7,5]],"ltp":2.64,"tv":3.02,"id":72857115}]}]}
{"op":"mcm","clk":"11909256900","pt":1724417843206,"mc":[{"id":"1.232174751","rc":[{"batb":[[0,2.7,4]],"ltp":2.64,"tv":3.02,"id":72857115}]}]}
{"op":"mcm","clk":"11909257118","pt":1724417845544,"mc":[{"id":"1.232174751","rc":[{"batb":[[0,2.68,8.18],[1,2.64,27.05],[2,1.99,5.64]],"ltp":2.64,"tv":3.02,"id":72857115}]}]}
{"op":"mcm","clk":"11909257137","pt":1724417845706,"mc":[{"id":"1.232174751","rc":[{"batb":[[0,2.7,5],[1,2.68,8.18],[2,2.64,27.05]],"ltp":2.64,"tv":3.02,"id":72857115}]}]}
{"op":"mcm","clk":"11909257491","pt":1724417849133,"mc":[{"id":"1.232174751","rc":[{"batb":[[0,2.72,4]],"ltp":2.64,"tv":3.02,"id":72857115}]}]}
{"op":"mcm","clk":"11909257680","pt":1724417851012,"mc":[{"id":"1.232174751","rc":[{"batb":[[0,2.68,8.18],[1,2.64,27.05],[2,1.99,5.64]],"ltp":2.64,"tv":3.02,"id":72857115}]}]}
{"op":"mcm","clk":"11909257963","pt":1724417854018,"mc":[{"id":"1.232174751","rc":[{"batb":[[0,2.7,9],[1,2.68,8.18],[2,2.64,27.05]],"ltp":2.64,"tv":3.02,"id":72857115}]}]}
{"op":"mcm","clk":"11909258193","pt":1724417856324,"mc":[{"id":"1.232174751","rc":[{"batb":[[0,2.7,5]],"ltp":2.64,"tv":3.02,"id":72857115}]}]}
{"op":"mcm","clk":"11909258276","pt":1724417857245,"mc":[{"id":"1.232174751","rc":[{"batb":[[0,2.68,8.18],[1,2.64,27.05],[2,1.99,5.64]],"ltp":2.64,"tv":3.02,"id":72857115}]}]}
{"op":"mcm","clk":"11909259127","pt":1724417865642,"mc":[{"id":"1.232174751","rc":[{"batb":[[0,2.7,9],[1,2.68,8.18],[2,2.64,27.05]],"ltp":2.64,"tv":3.02,"id":72857115}]}]}
{"op":"mcm","clk":"11909259370","pt":1724417868446,"mc":[{"id":"1.232174751","rc":[{"batb":[[0,2.7,5]],"ltp":2.64,"tv":3.02,"id":72857115}]}]}
{"op":"mcm","clk":"11909259423","pt":1724417869140,"mc":[{"id":"1.232174751","rc":[{"batb":[[0,2.68,8.18],[1,2.64,27.05],[2,1.99,5.64]],"ltp":2.64,"tv":3.02,"id":72857115}]}]}
{"op":"mcm","clk":"11909259589","pt":1724417870742,"mc":[{"id":"1.232174751","rc":[{"batb":[[0,2.7,4],[1,2.68,8.18],[2,2.64,27.05]],"ltp":2.64,"tv":3.02,"id":72857115}]}]}
{"op":"mcm","clk":"11909259810","pt":1724417873063,"mc":[{"id":"1.232174751","rc":[{"batb":[[0,2.7,5]],"ltp":2.64,"tv":3.02,"id":72857115}]}]}
{"op":"mcm","clk":"11909260111","pt":1724417876349,"mc":[{"id":"1.232174751","rc":[{"batb":[[0,2.68,8.18],[1,2.64,27.05],[2,1.99,5.64]],"ltp":2.64,"tv":3.02,"id":72857115}]}]}
{"op":"mcm","clk":"11909260164","pt":1724417876856,"mc":[{"id":"1.232174751","rc":[{"batb":[[0,2.72,4],[1,2.68,8.18],[2,2.64,27.05]],"ltp":2.64,"tv":3.02,"id":72857115}]}]}
{"op":"mcm","clk":"11909260429","pt":1724417879565,"mc":[{"id":"1.232174751","rc":[{"batb":[[0,2.68,8.18],[1,2.64,27.05],[2,1.99,5.64]],"ltp":2.64,"tv":3.02,"id":72857115}]}]}
{"op":"mcm","clk":"11909260454","pt":1724417879763,"mc":[{"id":"1.232174751","rc":[{"batb":[[0,2.7,5],[1,2.68,8.18],[2,2.64,27.05]],"ltp":2.64,"tv":3.02,"id":72857115}]}]}
{"op":"mcm","clk":"11909260751","pt":1724417883277,"mc":[{"id":"1.232174751","rc":[{"batb":[[0,2.7,4]],"ltp":2.64,"tv":3.02,"id":72857115}]}]}
{"op":"mcm","clk":"11909260988","pt":1724417885571,"mc":[{"id":"1.232174751","rc":[{"batb":[[0,2.68,8.18],[1,2.64,27.05],[2,1.99,5.64]],"ltp":2.64,"tv":3.02,"id":72857115}]}]}
{"op":"mcm","clk":"11909261010","pt":1724417885777,"mc":[{"id":"1.232174751","rc":[{"batb":[[0,2.7,5],[1,2.68,8.18],[2,2.64,27.05]],"ltp":2.64,"tv":3.02,"id":72857115}]}]}
{"op":"mcm","clk":"11909261366","pt":1724417889356,"mc":[{"id":"1.232174751","rc":[{"batb":[[0,2.7,4]],"ltp":2.64,"tv":3.02,"id":72857115}]}]}
{"op":"mcm","clk":"11909261570","pt":1724417891581,"mc":[{"id":"1.232174751","rc":[{"batb":[[0,2.68,8.18],[1,2.64,27.05],[2,1.99,5.64]],"ltp":2.64,"tv":3.02,"id":72857115}]}]}
{"op":"mcm","clk":"11909261588","pt":1724417891789,"mc":[{"id":"1.232174751","rc":[{"batb":[[0,2.7,5],[1,2.68,8.18],[2,2.64,27.05]],"ltp":2.64,"tv":3.02,"id":72857115}]}]}
{"op":"mcm","clk":"11909261941","pt":1724417895269,"mc":[{"id":"1.232174751","rc":[{"batb":[[0,2.7,4]],"ltp":2.64,"tv":3.02,"id":72857115}]}]}
{"op":"mcm","clk":"11909262132","pt":1724417897559,"mc":[{"id":"1.232174751","rc":[{"batb":[[0,2.68,8.18],[1,2.64,27.05],[2,1.99,5.64]],"ltp":2.64,"tv":3.02,"id":72857115}]}]}
{"op":"mcm","clk":"11909262142","pt":1724417897661,"mc":[{"id":"1.232174751","rc":[{"batb":[[0,2.7,5],[1,2.68,8.18],[2,2.64,27.05]],"ltp":2.64,"tv":3.02,"id":72857115}]}]}
{"op":"mcm","clk":"11909262343","pt":1724417899891,"mc":[{"id":"1.232174751","rc":[{"batb":[[0,2.72,4],[1,2.7,5],[2,2.68,8.18]],"ltp":2.64,"tv":3.02,"id":72857115}]}]}
{"op":"mcm","clk":"11909262432","pt":1724417900876,"mc":[{"id":"1.232174751","rc":[{"batb":[[1,2.68,8.18],[2,2.64,27.05]],"ltp":2.64,"tv":3.02,"id":72857115}]}]}
{"op":"mcm","clk":"11909262559","pt":1724417902271,"mc":[{"id":"1.232174751","rc":[{"batb":[[0,2.68,8.18],[1,2.64,27.05],[2,1.99,5.64]],"ltp":2.64,"tv":3.02,"id":72857115}]}]}
{"op":"mcm","clk":"11909263165","pt":1724417908605,"mc":[{"id":"1.232174751","rc":[{"batb":[[0,2.7,9],[1,2.68,8.18],[2,2.64,27.05]],"ltp":2.64,"tv":3.02,"id":72857115}]}]}
{"op":"mcm","clk":"11909263431","pt":1724417910901,"mc":[{"id":"1.232174751","rc":[{"batb":[[0,2.7,5]],"ltp":2.64,"tv":3.02,"id":72857115}]}]}
{"op":"mcm","clk":"11909263494","pt":1724417911833,"mc":[{"id":"1.232174751","rc":[{"batb":[[0,2.68,8.18],[1,2.64,27.05],[2,1.99,5.64]],"ltp":2.64,"tv":3.02,"id":72857115}]}]}
{"op":"mcm","clk":"11909265732","pt":1724417934277,"mc":[{"id":"1.232174751","rc":[{"batb":[[0,2.7,9],[1,2.68,8.18],[2,2.64,27.05]],"ltp":2.64,"tv":3.02,"id":72857115}]}]}
{"op":"mcm","clk":"11909265963","pt":1724417936866,"mc":[{"id":"1.232174751","rc":[{"batb":[[0,2.7,5]],"ltp":2.64,"tv":3.02,"id":72857115}]}]}
{"op":"mcm","clk":"11909266052","pt":1724417937897,"mc":[{"id":"1.232174751","rc":[{"batb":[[0,2.68,8.18],[1,2.64,27.05],[2,1.99,5.64]],"ltp":2.64,"tv":3.02,"id":72857115}]}]}
{"op":"mcm","clk":"11909268058","pt":1724417959565,"mc":[{"id":"1.232174751","rc":[{"batb":[[0,2.7,9],[1,2.68,8.18],[2,2.64,27.05]],"ltp":2.64,"tv":3.02,"id":72857115}]}]}
{"op":"mcm","clk":"11909268280","pt":1724417962054,"mc":[{"id":"1.232174751","rc":[{"batb":[[0,2.7,5]],"ltp":2.64,"tv":3.02,"id":72857115}]}]}
{"op":"mcm","clk":"11909268376","pt":1724417963077,"mc":[{"id":"1.232174751","rc":[{"batb":[[0,2.68,8.18],[1,2.64,27.05],[2,1.99,5.64]],"ltp":2.64,"tv":3.02,"id":72857115}]}]}
{"op":"mcm","clk":"11909268671","pt":1724417965871,"mc":[{"id":"1.232174751","rc":[{"batb":[[0,2.7,9],[1,2.68,8.18],[2,2.64,27.05]],"ltp":2.64,"tv":3.02,"id":72857115}]}]}
{"op":"mcm","clk":"11909268852","pt":1724417968149,"mc":[{"id":"1.232174751","rc":[{"batb":[[0,2.7,5]],"ltp":2.64,"tv":3.02,"id":72857115}]}]}
{"op":"mcm","clk":"11909268949","pt":1724417969291,"mc":[{"id":"1.232174751","rc":[{"batb":[[0,2.68,8.18],[1,2.64,27.05],[2,1.99,5.64]],"ltp":2.64,"tv":3.02,"id":72857115}]}]}
{"op":"mcm","clk":"11909269493","pt":1724417975286,"mc":[{"id":"1.232174751","rc":[{"batb":[[0,2.7,9],[1,2.68,8.18],[2,2.64,27.05]],"ltp":2.64,"tv":3.02,"id":72857115}]}]}
{"op":"mcm","clk":"11909269752","pt":1724417978562,"mc":[{"id":"1.232174751","rc":[{"batb":[[0,2.68,8.18],[1,2.64,27.05],[2,1.99,5.64]],"ltp":2.64,"tv":3.02,"id":72857115}]}]}
{"op":"mcm","clk":"11909270196","pt":1724417984061,"mc":[{"id":"1.232174751","rc":[{"batb":[[0,2.7,9],[1,2.68,8.18],[2,2.64,27.05]],"ltp":2.64,"tv":3.02,"id":72857115}]}]}
{"op":"mcm","clk":"11909270400","pt":1724417986396,"mc":[{"id":"1.232174751","rc":[{"batb":[[0,2.7,5]],"ltp":2.64,"tv":3.02,"id":72857115}]}]}
{"op":"mcm","clk":"11909270472","pt":1724417987282,"mc":[{"id":"1.232174751","rc":[{"batb":[[0,2.68,8.18],[1,2.64,27.05],[2,1.99,5.64]],"ltp":2.64,"tv":3.02,"id":72857115}]}]}
{"op":"mcm","clk":"11909271792","pt":1724418001715,"mc":[{"id":"1.232174751","rc":[{"batb":[[0,2.7,9],[1,2.68,8.18],[2,2.64,27.05]],"ltp":2.64,"tv":3.02,"id":72857115}]}]}
{"op":"mcm","clk":"11909272092","pt":1724418004347,"mc":[{"id":"1.232174751","rc":[{"batb":[[0,2.7,5],[1,2.68,8.17]],"ltp":2.64,"tv":3.02,"id":72857115},{"trd":[[1.56,154.76]],"batb":[[2,1.45,10.62]],"batl":[[0,1.59,13.59],[2,1.61,25.65]],"ltp":1.56,"tv":154.76,"id":72857116}],"tv":157.78}]}
{"op":"mcm","clk":"11909272215","pt":1724418005291,"mc":[{"id":"1.232174751","rc":[{"batb":[[0,2.68,8.17],[1,2.64,27.05],[2,1.99,5.64]],"ltp":2.64,"tv":3.02,"id":72857115}]}]}
{"op":"mcm","clk":"11909272342","pt":1724418006631,"mc":[{"id":"1.232174751","rc":[{"batb":[[0,2.7,4],[1,2.68,8.17],[2,2.64,27.05]],"ltp":2.64,"tv":3.02,"id":72857115}]}]}
{"op":"mcm","clk":"11909272590","pt":1724418009122,"mc":[{"id":"1.232174751","rc":[{"batb":[[0,2.7,5]],"ltp":2.64,"tv":3.02,"id":72857115}]}]}
{"op":"mcm","clk":"11909273012","pt":1724418012609,"mc":[{"id":"1.232174751","rc":[{"batb":[[0,2.72,4]],"ltp":2.64,"tv":3.02,"id":72857115}]}]}
{"op":"mcm","clk":"11909273285","pt":1724418014939,"mc":[{"id":"1.232174751","rc":[{"batb":[[0,2.7,5]],"ltp":2.64,"tv":3.02,"id":72857115}]}]}
{"op":"mcm","clk":"11909273638","pt":1724418018315,"mc":[{"id":"1.232174751","rc":[{"batb":[[0,2.72,4]],"ltp":2.64,"tv":3.02,"id":72857115}]}]}
{"op":"mcm","clk":"11909273977","pt":1724418021336,"mc":[{"id":"1.232174751","rc":[{"batb":[[0,2.7,5]],"ltp":2.64,"tv":3.02,"id":72857115}]}]}
{"op":"mcm","clk":"11909274324","pt":1724418024617,"mc":[{"id":"1.232174751","rc":[{"batb":[[0,2.68,8.17],[1,2.64,27.05],[2,1.99,5.64]],"ltp":2.64,"tv":3.02,"id":72857115}]}]}
{"op":"mcm","clk":"11909274348","pt":1724418024825,"mc":[{"id":"1.232174751","rc":[{"batb":[[0,2.7,4],[1,2.68,8.17],[2,2.64,27.05]],"ltp":2.64,"tv":3.02,"id":72857115}]}]}
{"op":"mcm","clk":"11909274554","pt":1724418027267,"mc":[{"id":"1.232174751","rc":[{"batb":[[0,2.7,5]],"ltp":2.64,"tv":3.02,"id":72857115}]}]}
{"op":"mcm","clk":"11909274872","pt":1724418030534,"mc":[{"id":"1.232174751","rc":[{"batb":[[0,2.68,8.17],[1,2.64,27.05],[2,1.99,5.64]],"ltp":2.64,"tv":3.02,"id":72857115}]}]}
{"op":"mcm","clk":"11909274888","pt":1724418030743,"mc":[{"id":"1.232174751","rc":[{"batb":[[0,2.7,4],[1,2.68,8.17],[2,2.64,27.05]],"ltp":2.64,"tv":3.02,"id":72857115}]}]}
{"op":"mcm","clk":"11909275082","pt":1724418033024,"mc":[{"id":"1.232174751","rc":[{"batb":[[0,2.72,5]],"ltp":2.64,"tv":3.02,"id":72857115}]}]}
{"op":"mcm","clk":"11909275264","pt":1724418035148,"mc":[{"id":"1.232174751","rc":[{"batb":[[0,2.74,4],[1,2.72,5],[2,2.68,8.17]],"ltp":2.64,"tv":3.02,"id":72857115}]}]}
{"op":"mcm","clk":"11909275368","pt":1724418036436,"mc":[{"id":"1.232174751","rc":[{"batb":[[1,2.68,8.17],[2,2.64,27.05]],"ltp":2.64,"tv":3.02,"id":72857115}]}]}
{"op":"mcm","clk":"11909275459","pt":1724418037476,"mc":[{"id":"1.232174751","rc":[{"batb":[[0,2.68,8.17],[1,2.64,27.05],[2,1.99,5.64]],"ltp":2.64,"tv":3.02,"id":72857115}]}]}
{"op":"mcm","clk":"11909276908","pt":1724418052972,"mc":[{"id":"1.232174751","rc":[{"batb":[[0,2.7,9],[1,2.68,8.17],[2,2.64,27.05]],"ltp":2.64,"tv":3.02,"id":72857115}]}]}
{"op":"mcm","clk":"11909277140","pt":1724418055440,"mc":[{"id":"1.232174751","rc":[{"batb":[[0,2.7,5]],"ltp":2.64,"tv":3.02,"id":72857115}]}]}
{"op":"mcm","clk":"11909277248","pt":1724418056477,"mc":[{"id":"1.232174751","rc":[{"batb":[[0,2.68,8.17],[1,2.64,27.05],[2,1.99,5.64]],"ltp":2.64,"tv":3.02,"id":72857115}]}]}
{"op":"mcm","clk":"11909277972","pt":1724418063590,"mc":[{"id":"1.232174751","rc":[{"batb":[[0,2.7,9],[1,2.68,8.17],[2,2.64,27.05]],"ltp":2.64,"tv":3.02,"id":72857115}]}]}
{"op":"mcm","clk":"11909278220","pt":1724418065880,"mc":[{"id":"1.232174751","rc":[{"batb":[[0,2.7,5]],"ltp":2.64,"tv":3.02,"id":72857115}]}]}
{"op":"mcm","clk":"11909278321","pt":1724418066762,"mc":[{"id":"1.232174751","rc":[{"batb":[[0,2.68,8.17],[1,2.64,27.05],[2,1.99,5.64]],"ltp":2.64,"tv":3.02,"id":72857115}]}]}
{"op":"mcm","clk":"11909278604","pt":1724418070188,"mc":[{"id":"1.232174751","rc":[{"batb":[[0,2.7,9],[1,2.68,8.17],[2,2.64,27.05]],"ltp":2.64,"tv":3.02,"id":72857115}]}]}
{"op":"mcm","clk":"11909278933","pt":1724418073493,"mc":[{"id":"1.232174751","rc":[{"batb":[[0,2.68,8.17],[1,2.64,27.05],[2,1.99,5.64]],"ltp":2.64,"tv":3.02,"id":72857115}]}]}
{"op":"mcm","clk":"11909279742","pt":1724418081503,"mc":[{"id":"1.232174751","rc":[{"batb":[[0,2.7,9],[1,2.68,8.17],[2,2.64,27.05]],"ltp":2.64,"tv":3.02,"id":72857115}]}]}
{"op":"mcm","clk":"11909279980","pt":1724418083982,"mc":[{"id":"1.232174751","rc":[{"batb":[[0,2.7,5]],"ltp":2.64,"tv":3.02,"id":72857115}]}]}
{"op":"mcm","clk":"11909280074","pt":1724418085016,"mc":[{"id":"1.232174751","rc":[{"batb":[[0,2.68,8.17],[1,2.64,27.05],[2,1.99,5.64]],"ltp":2.64,"tv":3.02,"id":72857115}]}]}
{"op":"mcm","clk":"11909280198","pt":1724418086518,"mc":[{"id":"1.232174751","rc":[{"batb":[[0,2.7,4],[1,2.68,8.17],[2,2.64,27.05]],"ltp":2.64,"tv":3.02,"id":72857115}]}]}
{"op":"mcm","clk":"11909280441","pt":1724418089111,"mc":[{"id":"1.232174751","rc":[{"batb":[[0,2.7,5]],"ltp":2.64,"tv":3.02,"id":72857115}]}]}
{"op":"mcm","clk":"11909280741","pt":1724418092435,"mc":[{"id":"1.232174751","rc":[{"batb":[[0,2.7,4]],"ltp":2.64,"tv":3.02,"id":72857115}]}]}
{"op":"mcm","clk":"11909280953","pt":1724418094600,"mc":[{"id":"1.232174751","rc":[{"batb":[[0,2.68,8.17],[1,2.64,27.05],[2,1.99,5.64]],"ltp":2.64,"tv":3.02,"id":72857115}]}]}
{"op":"mcm","clk":"11909280974","pt":1724418094807,"mc":[{"id":"1.232174751","rc":[{"batb":[[0,2.7,5],[1,2.68,8.17],[2,2.64,27.05]],"ltp":2.64,"tv":3.02,"id":72857115}]}]}
{"op":"mcm","clk":"11909281303","pt":1724418098111,"mc":[{"id":"1.232174751","rc":[{"batb":[[0,2.72,4]],"ltp":2.64,"tv":3.02,"id":72857115}]}]}
{"op":"mcm","clk":"11909281529","pt":1724418100744,"mc":[{"id":"1.232174751","rc":[{"batb":[[0,2.7,5]],"ltp":2.64,"tv":3.02,"id":72857115}]}]}
{"op":"mcm","clk":"11909281751","pt":1724418103019,"mc":[{"id":"1.232174751","rc":[{"batb":[[0,2.72,4],[1,2.7,5],[2,2.68,8.17]],"ltp":2.64,"tv":3.02,"id":72857115}]}]}
{"op":"mcm","clk":"11909281856","pt":1724418104005,"mc":[{"id":"1.232174751","rc":[{"batb":[[1,2.68,8.17],[2,2.64,27.05]],"ltp":2.64,"tv":3.02,"id":72857115}]}]}
{"op":"mcm","clk":"11909281971","pt":1724418105241,"mc":[{"id":"1.232174751","rc":[{"batb":[[0,2.68,8.17],[1,2.64,27.05],[2,1.99,5.64]],"ltp":2.64,"tv":3.02,"id":72857115}]}]}
{"op":"mcm","clk":"11909284031","pt":1724418126357,"mc":[{"id":"1.232174751","rc":[{"batb":[[0,2.7,9],[1,2.68,8.17],[2,2.64,27.05]],"ltp":2.64,"tv":3.02,"id":72857115}]}]}
{"op":"mcm","clk":"11909284287","pt":1724418128956,"mc":[{"id":"1.232174751","rc":[{"batb":[[0,2.7,5]],"ltp":2.64,"tv":3.02,"id":72857115}]}]}
{"op":"mcm","clk":"11909284380","pt":1724418129782,"mc":[{"id":"1.232174751","rc":[{"batb":[[0,2.68,8.17],[1,2.64,27.05],[2,1.99,5.64]],"ltp":2.64,"tv":3.02,"id":72857115}]}]}
{"op":"mcm","clk":"11909286156","pt":1724418147969,"mc":[{"id":"1.232174751","rc":[{"batb":[[0,2.7,9],[1,2.68,8.17],[2,2.64,27.05]],"ltp":2.64,"tv":3.02,"id":72857115}]}]}
{"op":"mcm","clk":"11909286407","pt":1724418150513,"mc":[{"id":"1.232174751","rc":[{"batb":[[0,2.7,5]],"ltp":2.64,"tv":3.02,"id":72857115}]}]}
{"op":"mcm","clk":"11909286497","pt":1724418151509,"mc":[{"id":"1.232174751","rc":[{"batb":[[0,2.68,8.17],[1,2.64,27.05],[2,1.99,5.64]],"ltp":2.64,"tv":3.02,"id":72857115}]}]}
{"op":"mcm","clk":"11909287219","pt":1724418159599,"mc":[{"id":"1.232174751","rc":[{"batb":[[0,2.7,9],[1,2.68,8.17],[2,2.64,27.05]],"ltp":2.64,"tv":3.02,"id":72857115}]}]}
{"op":"mcm","clk":"11909287418","pt":1724418161786,"mc":[{"id":"1.232174751","rc":[{"batb":[[0,2.7,5]],"ltp":2.64,"tv":3.02,"id":72857115}]}]}
{"op":"mcm","clk":"11909287508","pt":1724418162826,"mc":[{"id":"1.232174751","rc":[{"batb":[[0,2.68,8.17],[1,2.64,27.05],[2,1.99,5.64]],"ltp":2.64,"tv":3.02,"id":72857115}]}]}
{"op":"mcm","clk":"11909290965","pt":1724418197147,"mc":[{"id":"1.232174751","rc":[{"batb":[[0,2.7,9],[1,2.68,8.17],[2,2.64,27.05]],"ltp":2.64,"tv":3.02,"id":72857115}]}]}
{"op":"mcm","clk":"11909291301","pt":1724418200460,"mc":[{"id":"1.232174751","rc":[{"batb":[[0,2.68,8.17],[1,2.64,27.05],[2,1.99,5.64]],"ltp":2.64,"tv":3.02,"id":72857115}]}]}
{"op":"mcm","clk":"11909292773","pt":1724418216101,"mc":[{"id":"1.232174751","rc":[{"batb":[[0,2.7,9],[1,2.68,8.17],[2,2.64,27.05]],"ltp":2.64,"tv":3.02,"id":72857115}]}]}
{"op":"mcm","clk":"11909292989","pt":1724418218674,"mc":[{"id":"1.232174751","rc":[{"batb":[[0,2.7,5]],"ltp":2.64,"tv":3.02,"id":72857115}]}]}
{"op":"mcm","clk":"11909293082","pt":1724418219720,"mc":[{"id":"1.232174751","rc":[{"batb":[[0,2.68,8.17],[1,2.64,27.05],[2,1.99,5.64]],"ltp":2.64,"tv":3.02,"id":72857115}]}]}
{"op":"mcm","clk":"11909295321","pt":1724418242040,"mc":[{"id":"1.232174751","rc":[{"batb":[[0,2.7,9],[1,2.68,8.17],[2,2.64,27.05]],"ltp":2.64,"tv":3.02,"id":72857115}]}]}
{"op":"mcm","clk":"11909295563","pt":1724418244265,"mc":[{"id":"1.232174751","rc":[{"batb":[[0,2.7,5]],"ltp":2.64,"tv":3.02,"id":72857115}]}]}
{"op":"mcm","clk":"11909295684","pt":1724418245465,"mc":[{"id":"1.232174751","rc":[{"batb":[[0,2.68,8.17],[1,2.64,27.05],[2,1.99,5.64]],"ltp":2.64,"tv":3.02,"id":72857115}]}]}
{"op":"mcm","clk":"11909296324","pt":1724418251456,"mc":[{"id":"1.232174751","rc":[{"batb":[[0,2.7,9],[1,2.68,8.17],[2,2.64,27.05]],"ltp":2.64,"tv":3.02,"id":72857115}]}]}
{"op":"mcm","clk":"11909296616","pt":1724418254041,"mc":[{"id":"1.232174751","rc":[{"batb":[[0,2.7,5]],"ltp":2.64,"tv":3.02,"id":72857115}]}]}
{"op":"mcm","clk":"11909296710","pt":1724418255070,"mc":[{"id":"1.232174751","rc":[{"batb":[[0,2.68,8.17],[1,2.64,27.05],[2,1.99,5.64]],"ltp":2.64,"tv":3.02,"id":72857115}]}]}
{"op":"mcm","clk":"11909298968","pt":1724418277086,"mc":[{"id":"1.232174751","rc":[{"batb":[[0,2.7,9],[1,2.68,8.17],[2,2.64,27.05]],"ltp":2.64,"tv":3.02,"id":72857115}]}]}
{"op":"mcm","clk":"11909299243","pt":1724418279626,"mc":[{"id":"1.232174751","rc":[{"batb":[[0,2.7,5]],"ltp":2.64,"tv":3.02,"id":72857115}]}]}
{"op":"mcm","clk":"11909299342","pt":1724418280604,"mc":[{"id":"1.232174751","rc":[{"batb":[[0,2.68,8.17],[1,2.64,27.05],[2,1.99,5.64]],"ltp":2.64,"tv":3.02,"id":72857115}]}]}
{"op":"mcm","clk":"11909301160","pt":1724418299003,"mc":[{"id":"1.232174751","rc":[{"batb":[[0,2.7,9],[1,2.68,8.17],[2,2.64,27.05]],"ltp":2.64,"tv":3.02,"id":72857115}]}]}
{"op":"mcm","clk":"11909301474","pt":1724418302539,"mc":[{"id":"1.232174751","rc":[{"batb":[[0,2.68,8.17],[1,2.64,27.05],[2,1.99,5.64]],"ltp":2.64,"tv":3.02,"id":72857115}]}]}
{"op":"mcm","clk":"11909303019","pt":1724418317954,"mc":[{"id":"1.232174751","rc":[{"batb":[[0,2.7,9],[1,2.68,8.17],[2,2.64,27.05]],"ltp":2.64,"tv":3.02,"id":72857115}]}]}
{"op":"mcm","clk":"11909303302","pt":1724418320443,"mc":[{"id":"1.232174751","rc":[{"batb":[[0,2.7,5]],"ltp":2.64,"tv":3.02,"id":72857115}]}]}
{"op":"mcm","clk":"11909303408","pt":1724418321431,"mc":[{"id":"1.232174751","rc":[{"batb":[[0,2.68,8.17],[1,2.64,27.05],[2,1.99,5.64]],"ltp":2.64,"tv":3.02,"id":72857115}]}]}
{"op":"mcm","clk":"11909304484","pt":1724418332165,"mc":[{"id":"1.232174751","rc":[{"batb":[[0,2.7,9],[1,2.68,8.17],[2,2.64,27.05]],"ltp":2.64,"tv":3.02,"id":72857115}]}]}
{"op":"mcm","clk":"11909304735","pt":1724418334545,"mc":[{"id":"1.232174751","rc":[{"batb":[[0,2.7,5]],"ltp":2.64,"tv":3.02,"id":72857115}]}]}
{"op":"mcm","clk":"11909304853","pt":1724418335691,"mc":[{"id":"1.232174751","rc":[{"batb":[[0,2.68,8.17],[1,2.64,27.05],[2,1.99,5.64]],"ltp":2.64,"tv":3.02,"id":72857115}]}]}
{"op":"mcm","clk":"11909305841","pt":1724418345186,"mc":[{"id":"1.232174751","rc":[{"batb":[[0,2.7,9],[1,2.68,8.17],[2,2.64,27.05]],"ltp":2.64,"tv":3.02,"id":72857115}]}]}
{"op":"mcm","clk":"11909306066","pt":1724418347572,"mc":[{"id":"1.232174751","rc":[{"batb":[[0,2.7,5]],"ltp":2.64,"tv":3.02,"id":72857115}]}]}
{"op":"mcm","clk":"11909306146","pt":1724418348604,"mc":[{"id":"1.232174751","rc":[{"batb":[[0,2.68,8.17],[1,2.64,27.05],[2,1.99,5.64]],"ltp":2.64,"tv":3.02,"id":72857115}]}]}
{"op":"mcm","clk":"11909306430","pt":1724418351398,"mc":[{"id":"1.232174751","rc":[{"batb":[[0,2.7,9],[1,2.68,8.17],[2,2.64,27.05]],"ltp":2.64,"tv":3.02,"id":72857115}]}]}
{"op":"mcm","clk":"11909306667","pt":1724418354087,"mc":[{"id":"1.232174751","rc":[{"batb":[[0,2.7,5]],"ltp":2.64,"tv":3.02,"id":72857115}]}]}
{"op":"mcm","clk":"11909306767","pt":1724418355073,"mc":[{"id":"1.232174751","rc":[{"batb":[[0,2.68,8.17],[1,2.64,27.05],[2,1.99,5.64]],"ltp":2.64,"tv":3.02,"id":72857115}]}]}
{"op":"mcm","clk":"11909307123","pt":1724418358383,"mc":[{"id":"1.232174751","rc":[{"batb":[[0,2.7,9],[1,2.68,8.17],[2,2.64,27.05]],"ltp":2.64,"tv":3.02,"id":72857115}]}]}
{"op":"mcm","clk":"11909307356","pt":1724418360908,"mc":[{"id":"1.232174751","rc":[{"batb":[[0,2.7,5]],"ltp":2.64,"tv":3.02,"id":72857115}]}]}
{"op":"mcm","clk":"11909307453","pt":1724418362107,"mc":[{"id":"1.232174751","rc":[{"batb":[[0,2.68,8.17],[1,2.64,27.05],[2,1.99,5.64]],"ltp":2.64,"tv":3.02,"id":72857115}]}]}
{"op":"mcm","clk":"11909308102","pt":1724418368306,"mc":[{"id":"1.232174751","rc":[{"batb":[[0,2.7,9],[1,2.68,8.17],[2,2.64,27.05]],"ltp":2.64,"tv":3.02,"id":72857115}]}]}
{"op":"mcm","clk":"11909308365","pt":1724418370627,"mc":[{"id":"1.232174751","rc":[{"batb":[[0,2.7,5]],"ltp":2.64,"tv":3.02,"id":72857115}]}]}
{"op":"mcm","clk":"11909308482","pt":1724418371714,"mc":[{"id":"1.232174751","rc":[{"batb":[[0,2.68,8.17],[1,2.64,27.05],[2,1.99,5.64]],"ltp":2.64,"tv":3.02,"id":72857115}]}]}
{"op":"mcm","clk":"11909309238","pt":1724418380031,"mc":[{"id":"1.232174751","rc":[{"batb":[[0,2.7,9],[1,2.68,8.17],[2,2.64,27.05]],"ltp":2.64,"tv":3.02,"id":72857115}]}]}
{"op":"mcm","clk":"11909309544","pt":1724418383638,"mc":[{"id":"1.232174751","rc":[{"batb":[[0,2.68,8.17],[1,2.64,27.05],[2,1.99,5.64]],"ltp":2.64,"tv":3.02,"id":72857115}]}]}
{"op":"mcm","clk":"11909309887","pt":1724418387040,"mc":[{"id":"1.232174751","rc":[{"batb":[[0,2.7,9],[1,2.68,8.17],[2,2.64,27.05]],"ltp":2.64,"tv":3.02,"id":72857115}]}]}
{"op":"mcm","clk":"11909310077","pt":1724418389461,"mc":[{"id":"1.232174751","rc":[{"batb":[[0,2.7,5]],"ltp":2.64,"tv":3.02,"id":72857115}]}]}
{"op":"mcm","clk":"11909310172","pt":1724418390547,"mc":[{"id":"1.232174751","rc":[{"batb":[[0,2.68,8.17],[1,2.64,27.05],[2,1.99,5.64]],"ltp":2.64,"tv":3.02,"id":72857115}]}]}
{"op":"mcm","clk":"11909310385","pt":1724418392973,"mc":[{"id":"1.232174751","rc":[{"batb":[[0,2.7,9],[1,2.68,8.17],[2,2.64,27.05]],"ltp":2.64,"tv":3.02,"id":72857115}]}]}
{"op":"mcm","clk":"11909310607","pt":1724418395249,"mc":[{"id":"1.232174751","rc":[{"batb":[[0,2.7,5]],"ltp":2.64,"tv":3.02,"id":72857115}]}]}
{"op":"mcm","clk":"11909310715","pt":1724418396228,"mc":[{"id":"1.232174751","rc":[{"batb":[[0,2.68,8.17],[1,2.64,27.05],[2,1.99,5.64]],"ltp":2.64,"tv":3.02,"id":72857115}]}]}
{"op":"mcm","clk":"11909311708","pt":1724418406976,"mc":[{"id":"1.232174751","rc":[{"batb":[[0,2.7,9],[1,2.68,8.17],[2,2.64,27.05]],"ltp":2.64,"tv":3.02,"id":72857115}]}]}
{"op":"mcm","clk":"11909311935","pt":1724418409245,"mc":[{"id":"1.232174751","rc":[{"batb":[[0,2.7,5]],"ltp":2.64,"tv":3.02,"id":72857115}]}]}
{"op":"mcm","clk":"11909312010","pt":1724418410174,"mc":[{"id":"1.232174751","rc":[{"batb":[[0,2.68,8.17],[1,2.64,27.05],[2,1.99,5.64]],"ltp":2.64,"tv":3.02,"id":72857115}]}]}
{"op":"mcm","clk":"11909313612","pt":1724418426774,"mc":[{"id":"1.232174751","rc":[{"batb":[[0,2.7,9],[1,2.68,8.17],[2,2.64,27.05]],"ltp":2.64,"tv":3.02,"id":72857115}]}]}
{"op":"mcm","clk":"11909313871","pt":1724418429005,"mc":[{"id":"1.232174751","rc":[{"batb":[[0,2.7,5]],"ltp":2.64,"tv":3.02,"id":72857115}]}]}
{"op":"mcm","clk":"11909313950","pt":1724418429996,"mc":[{"id":"1.232174751","rc":[{"batb":[[0,2.68,8.17],[1,2.64,27.05],[2,1.99,5.64]],"ltp":2.64,"tv":3.02,"id":72857115}]}]}
{"op":"mcm","clk":"11909314762","pt":1724418437609,"mc":[{"id":"1.232174751","rc":[{"batb":[[0,2.7,9],[1,2.68,8.17],[2,2.64,27.05]],"ltp":2.64,"tv":3.02,"id":72857115}]}]}
{"op":"mcm","clk":"11909315022","pt":1724418439795,"mc":[{"id":"1.232174751","rc":[{"batb":[[0,2.7,5]],"ltp":2.64,"tv":3.02,"id":72857115}]}]}
{"op":"mcm","clk":"11909315128","pt":1724418441031,"mc":[{"id":"1.232174751","rc":[{"batb":[[0,2.68,8.17],[1,2.64,27.05],[2,1.99,5.64]],"ltp":2.64,"tv":3.02,"id":72857115}]}]}
{"op":"mcm","clk":"11909315238","pt":1724418442424,"mc":[{"id":"1.232174751","rc":[{"batb":[[0,2.7,4],[1,2.68,8.17],[2,2.64,27.05]],"ltp":2.64,"tv":3.02,"id":72857115}]}]}
{"op":"mcm","clk":"11909315463","pt":1724418444909,"mc":[{"id":"1.232174751","rc":[{"batb":[[0,2.7,5]],"ltp":2.64,"tv":3.02,"id":72857115}]}]}
{"op":"mcm","clk":"11909315755","pt":1724418448227,"mc":[{"id":"1.232174751","rc":[{"batb":[[0,2.72,4]],"ltp":2.64,"tv":3.02,"id":72857115}]}]}
{"op":"mcm","clk":"11909315909","pt":1724418449930,"mc":[{"id":"1.232174751","rc":[{"batb":[[0,2.68,8.17],[1,2.64,27.05],[2,1.99,5.64]],"ltp":2.64,"tv":3.02,"id":72857115}]}]}
{"op":"mcm","clk":"11909317076","pt":1724418461645,"mc":[{"id":"1.232174751","rc":[{"batb":[[0,2.7,9],[1,2.68,8.17],[2,2.64,27.05]],"ltp":2.64,"tv":3.02,"id":72857115}]}]}
{"op":"mcm","clk":"11909317291","pt":1724418463921,"mc":[{"id":"1.232174751","rc":[{"batb":[[0,2.7,5]],"ltp":2.64,"tv":3.02,"id":72857115}]}]}
{"op":"mcm","clk":"11909317384","pt":1724418465007,"mc":[{"id":"1.232174751","rc":[{"batb":[[0,2.68,8.17],[1,2.64,27.05],[2,1.99,5.64]],"ltp":2.64,"tv":3.02,"id":72857115}]}]}
{"op":"mcm","clk":"11909317494","pt":1724418466457,"mc":[{"id":"1.232174751","rc":[{"batb":[[0,2.7,4],[1,2.68,8.17],[2,2.64,27.05]],"ltp":2.64,"tv":3.02,"id":72857115}]}]}
{"op":"mcm","clk":"11909317720","pt":1724418469145,"mc":[{"id":"1.232174751","rc":[{"batb":[[0,2.7,5]],"ltp":2.64,"tv":3.02,"id":72857115}]}]}
{"op":"mcm","clk":"11909318024","pt":1724418472517,"mc":[{"id":"1.232174751","rc":[{"batb":[[0,2.72,4]],"ltp":2.64,"tv":3.02,"id":72857115}]}]}
{"op":"mcm","clk":"11909318246","pt":1724418475058,"mc":[{"id":"1.232174751","rc":[{"batb":[[0,2.7,5]],"ltp":2.64,"tv":3.02,"id":72857115}]}]}
{"op":"mcm","clk":"11909318561","pt":1724418478467,"mc":[{"id":"1.232174751","rc":[{"batb":[[0,2.7,4]],"ltp":2.64,"tv":3.02,"id":72857115}]}]}
{"op":"mcm","clk":"11909318827","pt":1724418480935,"mc":[{"id":"1.232174751","rc":[{"batb":[[0,2.7,5]],"ltp":2.64,"tv":3.02,"id":72857115}]}]}
{"op":"mcm","clk":"11909319190","pt":1724418484474,"mc":[{"id":"1.232174751","rc":[{"batb":[[0,2.7,4]],"ltp":2.64,"tv":3.02,"id":72857115}]}]}
{"op":"mcm","clk":"11909319449","pt":1724418487065,"mc":[{"id":"1.232174751","rc":[{"batb":[[0,2.7,5]],"ltp":2.64,"tv":3.02,"id":72857115}]}]}
{"op":"mcm","clk":"11909319683","pt":1724418489185,"mc":[{"id":"1.232174751","rc":[{"batb":[[0,2.72,4],[1,2.7,5],[2,2.68,8.17]],"ltp":2.64,"tv":3.02,"id":72857115}]}]}
{"op":"mcm","clk":"11909319815","pt":1724418490484,"mc":[{"id":"1.232174751","rc":[{"batb":[[1,2.68,8.17],[2,2.64,27.05]],"ltp":2.64,"tv":3.02,"id":72857115}]}]}
{"op":"mcm","clk":"11909319924","pt":1724418491480,"mc":[{"id":"1.232174751","rc":[{"batb":[[0,2.68,8.17],[1,2.64,27.05],[2,1.99,5.64]],"ltp":2.64,"tv":3.02,"id":72857115}]}]}
{"op":"mcm","clk":"11909320605","pt":1724418498780,"mc":[{"id":"1.232174751","rc":[{"batb":[[0,2.7,9],[1,2.68,8.17],[2,2.64,27.05]],"ltp":2.64,"tv":3.02,"id":72857115}]}]}
{"op":"mcm","clk":"11909320837","pt":1724418501315,"mc":[{"id":"1.232174751","rc":[{"batb":[[0,2.7,5]],"ltp":2.64,"tv":3.02,"id":72857115}]}]}
{"op":"mcm","clk":"11909320944","pt":1724418502304,"mc":[{"id":"1.232174751","rc":[{"batb":[[0,2.68,8.17],[1,2.64,27.05],[2,1.99,5.64]],"ltp":2.64,"tv":3.02,"id":72857115}]}]}
{"op":"mcm","clk":"11909321068","pt":1724418503755,"mc":[{"id":"1.232174751","rc":[{"batb":[[0,2.7,4],[1,2.68,8.17],[2,2.64,27.05]],"ltp":2.64,"tv":3.02,"id":72857115}]}]}
{"op":"mcm","clk":"11909321282","pt":1724418506088,"mc":[{"id":"1.232174751","rc":[{"batb":[[0,2.7,5]],"ltp":2.64,"tv":3.02,"id":72857115}]}]}
{"op":"mcm","clk":"11909321615","pt":1724418509496,"mc":[{"id":"1.232174751","rc":[{"batb":[[0,2.72,4]],"ltp":2.64,"tv":3.02,"id":72857115}]}]}
{"op":"mcm","clk":"11909321841","pt":1724418511887,"mc":[{"id":"1.232174751","rc":[{"batb":[[0,2.7,5]],"ltp":2.64,"tv":3.02,"id":72857115}]}]}
{"op":"mcm","clk":"11909322157","pt":1724418515308,"mc":[{"id":"1.232174751","rc":[{"batb":[[0,2.7,4]],"ltp":2.64,"tv":3.02,"id":72857115}]}]}
{"op":"mcm","clk":"11909322398","pt":1724418517907,"mc":[{"id":"1.232174751","rc":[{"batb":[[0,2.7,5]],"ltp":2.64,"tv":3.02,"id":72857115}]}]}
{"op":"mcm","clk":"11909322669","pt":1724418521112,"mc":[{"id":"1.232174751","rc":[{"batb":[[0,2.72,4]],"ltp":2.64,"tv":3.02,"id":72857115}]}]}
{"op":"mcm","clk":"11909322887","pt":1724418523429,"mc":[{"id":"1.232174751","rc":[{"batb":[[0,2.74,5]],"ltp":2.64,"tv":3.02,"id":72857115}]}]}
{"op":"mcm","clk":"11909322977","pt":1724418524411,"mc":[{"id":"1.232174751","rc":[{"batl":[[0,1.6,276.92],[1,1.61,25.65],[2,2.5,1]],"ltp":1.56,"tv":154.76,"id":72857116}]}]}
{"op":"mcm","clk":"11909323149","pt":1724418526526,"mc":[{"id":"1.232174751","rc":[{"batb":[[0,2.76,4]],"ltp":2.64,"tv":3.02,"id":72857115}]}]}
{"op":"mcm","clk":"11909323285","pt":1724418528226,"mc":[{"id":"1.232174751","rc":[{"batb":[[0,2.68,8.17],[1,2.64,27.05],[2,1.99,5.64]],"ltp":2.64,"tv":3.02,"id":72857115}]}]}
{"op":"mcm","clk":"11909323474","pt":1724418530501,"mc":[{"id":"1.232174751","rc":[{"batb":[[0,2.7,9],[1,2.68,8.17],[2,2.64,27.05]],"ltp":2.64,"tv":3.02,"id":72857115}]}]}
{"op":"mcm","clk":"11909323676","pt":1724418532825,"mc":[{"id":"1.232174751","rc":[{"batb":[[0,2.7,5]],"ltp":2.64,"tv":3.02,"id":72857115}]}]}
{"op":"mcm","clk":"11909323757","pt":1724418533805,"mc":[{"id":"1.232174751","rc":[{"batb":[[0,2.68,8.17],[1,2.64,27.05],[2,1.99,5.64]],"ltp":2.64,"tv":3.02,"id":72857115}]}]}
{"op":"mcm","clk":"11909323874","pt":1724418535303,"mc":[{"id":"1.232174751","rc":[{"batb":[[0,2.7,4],[1,2.68,8.17],[2,2.64,27.05]],"ltp":2.64,"tv":3.02,"id":72857115}]}]}
{"op":"mcm","clk":"11909324094","pt":1724418537924,"mc":[{"id":"1.232174751","rc":[{"batb":[[0,2.7,5]],"ltp":2.64,"tv":3.02,"id":72857115}]}]}
{"op":"mcm","clk":"11909324347","pt":1724418540612,"mc":[{"id":"1.232174751","rc":[{"batb":[[0,2.72,4],[1,2.7,5],[2,2.68,8.17]],"ltp":2.64,"tv":3.02,"id":72857115}]}]}
{"op":"mcm","clk":"11909324417","pt":1724418541446,"mc":[{"id":"1.232174751","rc":[{"batb":[[1,2.68,8.17],[2,2.64,27.05]],"ltp":2.64,"tv":3.02,"id":72857115}]}]}
{"op":"mcm","clk":"11909324540","pt":1724418543004,"mc":[{"id":"1.232174751","rc":[{"batb":[[0,2.68,8.17],[1,2.64,27.05],[2,1.99,5.64]],"ltp":2.64,"tv":3.02,"id":72857115}]}]}
{"op":"mcm","clk":"11909324735","pt":1724418545337,"mc":[{"id":"1.232174751","rc":[{"batb":[[0,2.7,9],[1,2.68,8.17],[2,2.64,27.05]],"ltp":2.64,"tv":3.02,"id":72857115}]}]}
{"op":"mcm","clk":"11909324951","pt":1724418547632,"mc":[{"id":"1.232174751","rc":[{"batb":[[0,2.7,5]],"ltp":2.64,"tv":3.02,"id":72857115}]}]}
{"op":"mcm","clk":"11909325040","pt":1724418548508,"mc":[{"id":"1.232174751","rc":[{"batb":[[0,2.68,8.17],[1,2.64,27.05],[2,1.99,5.64]],"ltp":2.64,"tv":3.02,"id":72857115}]}]}
{"op":"mcm","clk":"11909325247","pt":1724418550735,"mc":[{"id":"1.232174751","rc":[{"batb":[[0,2.7,9],[1,2.68,8.17],[2,2.64,27.05]],"ltp":2.64,"tv":3.02,"id":72857115}]}]}
{"op":"mcm","clk":"11909325481","pt":1724418553116,"mc":[{"id":"1.232174751","rc":[{"batb":[[0,2.7,5]],"ltp":2.64,"tv":3.02,"id":72857115},{"batl":[[0,1.59,14.27],[1,1.6,276.92],[2,1.61,25.65]],"ltp":1.56,"tv":154.76,"id":72857116}]}]}
{"op":"mcm","clk":"11909325575","pt":1724418554152,"mc":[{"id":"1.232174751","rc":[{"batb":[[0,2.68,8.17],[1,2.64,27.05],[2,1.99,5.64]],"ltp":2.64,"tv":3.02,"id":72857115}]}]}
{"op":"mcm","clk":"11909325696","pt":1724418555348,"mc":[{"id":"1.232174751","rc":[{"batb":[[0,2.7,4],[1,2.68,8.17],[2,2.64,27.05]],"ltp":2.64,"tv":3.02,"id":72857115}]}]}
{"op":"mcm","clk":"11909325939","pt":1724418557625,"mc":[{"id":"1.232174751","rc":[{"batb":[[0,2.68,8.17],[1,2.64,27.05],[2,1.99,5.64]],"ltp":2.64,"tv":3.02,"id":72857115}]}]}
{"op":"mcm","clk":"11909325959","pt":1724418557830,"mc":[{"id":"1.232174751","rc":[{"batb":[[0,2.7,5],[1,2.68,8.17],[2,2.64,27.05]],"ltp":2.64,"tv":3.02,"id":72857115}]}]}
{"op":"mcm","clk":"11909326255","pt":1724418561255,"mc":[{"id":"1.232174751","rc":[{"batb":[[0,2.7,4]],"ltp":2.64,"tv":3.02,"id":72857115}]}]}
{"op":"mcm","clk":"11909326462","pt":1724418563640,"mc":[{"id":"1.232174751","rc":[{"batb":[[0,2.68,8.17],[1,2.64,27.05],[2,1.99,5.64]],"ltp":2.64,"tv":3.02,"id":72857115}]}]}
{"op":"mcm","clk":"11909326486","pt":1724418563840,"mc":[{"id":"1.232174751","rc":[{"batb":[[0,2.7,5],[1,2.68,8.17],[2,2.64,27.05]],"ltp":2.64,"tv":3.02,"id":72857115}]}]}
{"op":"mcm","clk":"11909326820","pt":1724418567364,"mc":[{"id":"1.232174751","rc":[{"batb":[[0,2.7,4]],"ltp":2.64,"tv":3.02,"id":72857115}]}]}
{"op":"mcm","clk":"11909327016","pt":1724418569531,"mc":[{"id":"1.232174751","rc":[{"batb":[[0,2.68,8.17],[1,2.64,27.05],[2,1.99,5.64]],"ltp":2.64,"tv":3.02,"id":72857115}]}]}
{"op":"mcm","clk":"11909327060","pt":1724418570046,"mc":[{"id":"1.232174751","rc":[{"batb":[[0,2.7,5],[1,2.68,8.17],[2,2.64,27.05]],"ltp":2.64,"tv":3.02,"id":72857115}]}]}
{"op":"mcm","clk":"11909327372","pt":1724418573578,"mc":[{"id":"1.232174751","rc":[{"batb":[[0,2.7,4]],"ltp":2.64,"tv":3.02,"id":72857115}]}]}
{"op":"mcm","clk":"11909327600","pt":1724418576063,"mc":[{"id":"1.232174751","rc":[{"batb":[[0,2.7,5]],"ltp":2.64,"tv":3.02,"id":72857115}]}]}
{"op":"mcm","clk":"11909327941","pt":1724418579490,"mc":[{"id":"1.232174751","rc":[{"batb":[[0,2.7,4]],"ltp":2.64,"tv":3.02,"id":72857115}]}]}
{"op":"mcm","clk":"11909328152","pt":1724418581878,"mc":[{"id":"1.232174751","rc":[{"batb":[[0,2.7,5]],"ltp":2.64,"tv":3.02,"id":72857115}]}]}
{"op":"mcm","clk":"11909328478","pt":1724418585265,"mc":[{"id":"1.232174751","rc":[{"batb":[[0,2.7,4]],"ltp":2.64,"tv":3.02,"id":72857115}]}]}
{"op":"mcm","clk":"11909328676","pt":1724418587509,"mc":[{"id":"1.232174751","rc":[{"batb":[[0,2.68,8.17],[1,2.64,27.05],[2,1.99,5.64]],"ltp":2.64,"tv":3.02,"id":72857115}]}]}
{"op":"mcm","clk":"11909328687","pt":1724418587659,"mc":[{"id":"1.232174751","rc":[{"batb":[[0,2.7,5],[1,2.68,8.17],[2,2.64,27.05]],"ltp":2.64,"tv":3.02,"id":72857115}]}]}
{"op":"mcm","clk":"11909328976","pt":1724418591092,"mc":[{"id":"1.232174751","rc":[{"batb":[[0,2.7,4]],"ltp":2.64,"tv":3.02,"id":72857115}]}]}
{"op":"mcm","clk":"11909329182","pt":1724418593480,"mc":[{"id":"1.232174751","rc":[{"batb":[[0,2.7,5]],"ltp":2.64,"tv":3.02,"id":72857115}]}]}
{"op":"mcm","clk":"11909329461","pt":1724418596389,"mc":[{"id":"1.232174751","rc":[{"batb":[[0,2.72,4],[1,2.7,5],[2,2.68,8.17]],"ltp":2.64,"tv":3.02,"id":72857115}]}]}
{"op":"mcm","clk":"11909329490","pt":1724418596806,"mc":[{"id":"1.232174751","rc":[{"batb":[[1,2.68,8.17],[2,2.64,27.05]],"ltp":2.64,"tv":3.02,"id":72857115}]}]}
{"op":"mcm","clk":"11909329706","pt":1724418599095,"mc":[{"id":"1.232174751","rc":[{"batb":[[0,2.7,5]],"ltp":2.64,"tv":3.02,"id":72857115}]}]}
{"op":"mcm","clk":"11909329994","pt":1724418602600,"mc":[{"id":"1.232174751","rc":[{"batb":[[0,2.7,4]],"ltp":2.64,"tv":3.02,"id":72857115}]}]}
{"op":"mcm","clk":"11909330238","pt":1724418605092,"mc":[{"id":"1.232174751","rc":[{"batb":[[0,2.7,5]],"ltp":2.64,"tv":3.02,"id":72857115}]}]}
{"op":"mcm","clk":"11909330566","pt":1724418608415,"mc":[{"id":"1.232174751","rc":[{"batb":[[0,2.7,4]],"ltp":2.64,"tv":3.02,"id":72857115}]}]}
{"op":"mcm","clk":"11909330845","pt":1724418610908,"mc":[{"id":"1.232174751","rc":[{"batb":[[0,2.7,5]],"ltp":2.64,"tv":3.02,"id":72857115}]}]}
{"op":"mcm","clk":"11909331228","pt":1724418614485,"mc":[{"id":"1.232174751","rc":[{"batb":[[0,2.7,4]],"ltp":2.64,"tv":3.02,"id":72857115}]}]}
{"op":"mcm","clk":"11909331435","pt":1724418616815,"mc":[{"id":"1.232174751","rc":[{"batb":[[0,2.7,5]],"ltp":2.64,"tv":3.02,"id":72857115}]}]}
{"op":"mcm","clk":"11909331739","pt":1724418620130,"mc":[{"id":"1.232174751","rc":[{"batb":[[0,2.7,4]],"ltp":2.64,"tv":3.02,"id":72857115}]}]}
{"op":"mcm","clk":"11909331976","pt":1724418622516,"mc":[{"id":"1.232174751","rc":[{"batb":[[0,2.68,8.17],[1,2.64,27.05],[2,1.99,5.64]],"ltp":2.64,"tv":3.02,"id":72857115}]}]}
{"op":"mcm","clk":"11909331995","pt":1724418622716,"mc":[{"id":"1.232174751","rc":[{"batb":[[0,2.72,5],[1,2.68,8.17],[2,2.64,27.05]],"ltp":2.64,"tv":3.02,"id":72857115}]}]}
{"op":"mcm","clk":"11909332313","pt":1724418626242,"mc":[{"id":"1.232174751","rc":[{"batb":[[0,2.7,4]],"ltp":2.64,"tv":3.02,"id":72857115}]}]}
{"op":"mcm","clk":"11909332540","pt":1724418628526,"mc":[{"id":"1.232174751","rc":[{"batb":[[0,2.68,8.17],[1,2.64,27.05],[2,1.99,5.64]],"ltp":2.64,"tv":3.02,"id":72857115}]}]}
{"op":"mcm","clk":"11909332551","pt":1724418628729,"mc":[{"id":"1.232174751","rc":[{"batb":[[0,2.7,5],[1,2.68,8.17],[2,2.64,27.05]],"ltp":2.64,"tv":3.02,"id":72857115}]}]}
{"op":"mcm","clk":"11909332722","pt":1724418631113,"mc":[{"id":"1.232174751","rc":[{"batb":[[0,2.72,4],[1,2.7,5],[2,2.68,8.17]],"ltp":2.64,"tv":3.02,"id":72857115}]}]}
{"op":"mcm","clk":"11909332788","pt":1724418631949,"mc":[{"id":"1.232174751","rc":[{"batb":[[1,2.68,8.17],[2,2.64,27.05]],"ltp":2.64,"tv":3.02,"id":72857115}]}]}
{"op":"mcm","clk":"11909332933","pt":1724418633455,"mc":[{"id":"1.232174751","rc":[{"batb":[[0,2.68,8.17],[1,2.64,27.05],[2,1.99,5.64]],"ltp":2.64,"tv":3.02,"id":72857115}]}]}
{"op":"mcm","clk":"11909334093","pt":1724418645458,"mc":[{"id":"1.232174751","rc":[{"batb":[[0,2.7,9],[1,2.68,8.17],[2,2.64,27.05]],"ltp":2.64,"tv":3.02,"id":72857115}]}]}
{"op":"mcm","clk":"11909334313","pt":1724418647759,"mc":[{"id":"1.232174751","rc":[{"batb":[[0,2.7,5]],"ltp":2.64,"tv":3.02,"id":72857115}]}]}
{"op":"mcm","clk":"11909334409","pt":1724418648897,"mc":[{"id":"1.232174751","rc":[{"batb":[[0,2.68,8.17],[1,2.64,27.05],[2,1.99,5.64]],"ltp":2.64,"tv":3.02,"id":72857115}]}]}
{"op":"mcm","clk":"11909335487","pt":1724418660285,"mc":[{"id":"1.232174751","rc":[{"batb":[[0,2.7,9],[1,2.68,8.17],[2,2.64,27.05]],"ltp":2.64,"tv":3.02,"id":72857115}]}]}
{"op":"mcm","clk":"11909335755","pt":1724418662885,"mc":[{"id":"1.232174751","rc":[{"batb":[[0,2.7,5]],"ltp":2.64,"tv":3.02,"id":72857115}]}]}
{"op":"mcm","clk":"11909335882","pt":1724418663974,"mc":[{"id":"1.232174751","rc":[{"batb":[[0,2.68,8.17],[1,2.64,27.05],[2,1.99,5.64]],"ltp":2.64,"tv":3.02,"id":72857115}]}]}
{"op":"mcm","clk":"11909336129","pt":1724418666462,"mc":[{"id":"1.232174751","rc":[{"batb":[[0,2.7,9],[1,2.68,8.17],[2,2.64,27.05]],"ltp":2.64,"tv":3.02,"id":72857115}]}]}
{"op":"mcm","clk":"11909336339","pt":1724418668687,"mc":[{"id":"1.232174751","rc":[{"batb":[[0,2.7,5]],"ltp":2.64,"tv":3.02,"id":72857115}]}]}
{"op":"mcm","clk":"11909336432","pt":1724418669776,"mc":[{"id":"1.232174751","rc":[{"batb":[[0,2.68,8.17],[1,2.64,27.05],[2,1.99,5.64]],"ltp":2.64,"tv":3.02,"id":72857115}]}]}
{"op":"mcm","clk":"11909336594","pt":1724418671484,"mc":[{"id":"1.232174751","rc":[{"batb":[[0,2.7,4],[1,2.68,8.17],[2,2.64,27.05]],"ltp":2.64,"tv":3.02,"id":72857115}]}]}
{"op":"mcm","clk":"11909336803","pt":1724418673499,"mc":[{"id":"1.232174751","rc":[{"batb":[[0,2.72,5],[1,2.7,4],[2,2.68,8.17]],"ltp":2.64,"tv":3.02,"id":72857115}]}]}
{"op":"mcm","clk":"11909336840","pt":1724418673764,"mc":[{"id":"1.232174751","rc":[{"batb":[[1,2.68,8.17],[2,2.64,27.05]],"ltp":2.64,"tv":3.02,"id":72857115}]}]}
{"op":"mcm","clk":"11909337158","pt":1724418676987,"mc":[{"id":"1.232174751","rc":[{"batb":[[0,2.7,4]],"ltp":2.64,"tv":3.02,"id":72857115}]}]}
{"op":"mcm","clk":"11909337368","pt":1724418679307,"mc":[{"id":"1.232174751","rc":[{"batb":[[0,2.7,5]],"ltp":2.64,"tv":3.02,"id":72857115}]}]}
{"op":"mcm","clk":"11909337689","pt":1724418682893,"mc":[{"id":"1.232174751","rc":[{"batb":[[0,2.7,4]],"ltp":2.64,"tv":3.02,"id":72857115}]}]}
{"op":"mcm","clk":"11909337887","pt":1724418685325,"mc":[{"id":"1.232174751","rc":[{"batb":[[0,2.7,5]],"ltp":2.64,"tv":3.02,"id":72857115}]}]}
{"op":"mcm","clk":"11909338185","pt":1724418688601,"mc":[{"id":"1.232174751","rc":[{"batb":[[0,2.7,4]],"ltp":2.64,"tv":3.02,"id":72857115}]}]}
{"op":"mcm","clk":"11909338400","pt":1724418691038,"mc":[{"id":"1.232174751","rc":[{"batb":[[0,2.7,5]],"ltp":2.64,"tv":3.02,"id":72857115}]}]}
{"op":"mcm","clk":"11909338677","pt":1724418693527,"mc":[{"id":"1.232174751","rc":[{"batb":[[0,2.72,4],[1,2.7,5],[2,2.68,8.17]],"ltp":2.64,"tv":3.02,"id":72857115}]}]}
{"op":"mcm","clk":"11909338741","pt":1724418694204,"mc":[{"id":"1.232174751","rc":[{"batb":[[1,2.68,8.17],[2,2.64,27.05]],"ltp":2.64,"tv":3.02,"id":72857115}]}]}
{"op":"mcm","clk":"11909338873","pt":1724418695600,"mc":[{"id":"1.232174751","rc":[{"batb":[[0,2.68,8.17],[1,2.64,27.05],[2,1.99,5.64]],"ltp":2.64,"tv":3.02,"id":72857115}]}]}
{"op":"mcm","clk":"11909339570","pt":1724418702844,"mc":[{"id":"1.232174751","rc":[{"batb":[[0,2.7,9],[1,2.68,8.17],[2,2.64,27.05]],"ltp":2.64,"tv":3.02,"id":72857115}]}]}
{"op":"mcm","clk":"11909339837","pt":1724418705427,"mc":[{"id":"1.232174751","rc":[{"batb":[[0,2.7,5]],"ltp":2.64,"tv":3.02,"id":72857115}]}]}
{"op":"mcm","clk":"11909339910","pt":1724418706160,"mc":[{"id":"1.232174751","rc":[{"batb":[[0,2.68,8.17],[1,2.64,27.05],[2,1.99,5.64]],"ltp":2.64,"tv":3.02,"id":72857115}]}]}
{"op":"mcm","clk":"11909340462","pt":1724418712119,"mc":[{"id":"1.232174751","rc":[{"batb":[[0,2.7,9],[1,2.68,8.17],[2,2.64,27.05]],"ltp":2.64,"tv":3.02,"id":72857115}]}]}
{"op":"mcm","clk":"11909340693","pt":1724418714599,"mc":[{"id":"1.232174751","rc":[{"batb":[[0,2.7,5]],"ltp":2.64,"tv":3.02,"id":72857115}]}]}
{"op":"mcm","clk":"11909340761","pt":1724418715422,"mc":[{"id":"1.232174751","rc":[{"batb":[[0,2.68,8.17],[1,2.64,27.05],[2,1.99,5.64]],"ltp":2.64,"tv":3.02,"id":72857115}]}]}
{"op":"mcm","clk":"11909340980","pt":1724418718249,"mc":[{"id":"1.232174751","rc":[{"batb":[[0,2.7,9],[1,2.68,8.17],[2,2.64,27.05]],"ltp":2.64,"tv":3.02,"id":72857115}]}]}
{"op":"mcm","clk":"11909341215","pt":1724418720633,"mc":[{"id":"1.232174751","rc":[{"batb":[[0,2.7,5]],"ltp":2.64,"tv":3.02,"id":72857115}]}]}
{"op":"mcm","clk":"11909341316","pt":1724418721623,"mc":[{"id":"1.232174751","rc":[{"batb":[[0,2.68,8.17],[1,2.64,27.05],[2,1.99,5.64]],"ltp":2.64,"tv":3.02,"id":72857115}]}]}
{"op":"mcm","clk":"11909341450","pt":1724418723176,"mc":[{"id":"1.232174751","rc":[{"batb":[[0,2.7,4],[1,2.68,8.17],[2,2.64,27.05]],"ltp":2.64,"tv":3.02,"id":72857115}]}]}
{"op":"mcm","clk":"11909341680","pt":1724418725951,"mc":[{"id":"1.232174751","rc":[{"batb":[[0,2.7,5]],"ltp":2.64,"tv":3.02,"id":72857115}]}]}
{"op":"mcm","clk":"11909342003","pt":1724418729464,"mc":[{"id":"1.232174751","rc":[{"batb":[[0,2.72,4]],"ltp":2.64,"tv":3.02,"id":72857115}]}]}
{"op":"mcm","clk":"11909342260","pt":1724418731839,"mc":[{"id":"1.232174751","rc":[{"batb":[[0,2.7,5]],"ltp":2.64,"tv":3.02,"id":72857115}]}]}
{"op":"mcm","clk":"11909342438","pt":1724418733851,"mc":[{"id":"1.232174751","rc":[{"batb":[[0,2.72,4],[1,2.7,5],[2,2.68,8.17]],"ltp":2.64,"tv":3.02,"id":72857115}]}]}
{"op":"mcm","clk":"11909342574","pt":1724418735043,"mc":[{"id":"1.232174751","rc":[{"batb":[[1,2.68,8.17],[2,2.64,27.05]],"ltp":2.64,"tv":3.02,"id":72857115}]}]}
{"op":"mcm","clk":"11909342702","pt":1724418736283,"mc":[{"id":"1.232174751","rc":[{"batb":[[0,2.68,8.17],[1,2.64,27.05],[2,1.99,5.64]],"ltp":2.64,"tv":3.02,"id":72857115}]}]}
{"op":"mcm","clk":"11909343669","pt":1724418747656,"mc":[{"id":"1.232174751","rc":[{"batb":[[0,2.7,9],[1,2.68,8.17],[2,2.64,27.05]],"ltp":2.64,"tv":3.02,"id":72857115}]}]}
{"op":"mcm","clk":"11909343965","pt":1724418750218,"mc":[{"id":"1.232174751","rc":[{"batb":[[0,2.7,5]],"ltp":2.64,"tv":3.02,"id":72857115}]}]}
{"op":"mcm","clk":"11909344185","pt":1724418751093,"mc":[{"id":"1.232174751","rc":[{"batb":[[0,2.68,8.17],[1,2.64,27.05],[2,1.99,5.64]],"ltp":2.64,"tv":3.02,"id":72857115}]}]}
{"op":"mcm","clk":"11909345325","pt":1724418760820,"mc":[{"id":"1.232174751","rc":[{"batb":[[0,2.7,9],[1,2.68,8.17],[2,2.64,27.05]],"ltp":2.64,"tv":3.02,"id":72857115}]}]}
{"op":"mcm","clk":"11909345593","pt":1724418763298,"mc":[{"id":"1.232174751","rc":[{"batb":[[0,2.7,5]],"ltp":2.64,"tv":3.02,"id":72857115}]}]}
{"op":"mcm","clk":"11909345716","pt":1724418764437,"mc":[{"id":"1.232174751","rc":[{"batb":[[0,2.68,8.17],[1,2.64,27.05],[2,1.99,5.64]],"ltp":2.64,"tv":3.02,"id":72857115}]}]}
{"op":"mcm","clk":"11909346725","pt":1724418776452,"mc":[{"id":"1.232174751","rc":[{"batb":[[0,2.7,9],[1,2.68,8.17],[2,2.64,27.05]],"ltp":2.64,"tv":3.02,"id":72857115}]}]}
{"op":"mcm","clk":"11909346929","pt":1724418779034,"mc":[{"id":"1.232174751","rc":[{"batb":[[0,2.7,5]],"ltp":2.64,"tv":3.02,"id":72857115}]}]}
{"op":"mcm","clk":"11909347017","pt":1724418780074,"mc":[{"id":"1.232174751","rc":[{"batb":[[0,2.68,8.17],[1,2.64,27.05],[2,1.99,5.64]],"ltp":2.64,"tv":3.02,"id":72857115}]}]}
{"op":"mcm","clk":"11909347318","pt":1724418783149,"mc":[{"id":"1.232174751","rc":[{"batb":[[0,2.7,9],[1,2.68,8.17],[2,2.64,27.05]],"ltp":2.64,"tv":3.02,"id":72857115}]}]}
{"op":"mcm","clk":"11909347540","pt":1724418785592,"mc":[{"id":"1.232174751","rc":[{"batb":[[0,2.7,5]],"ltp":2.64,"tv":3.02,"id":72857115}]}]}
{"op":"mcm","clk":"11909347634","pt":1724418786532,"mc":[{"id":"1.232174751","rc":[{"batb":[[0,2.68,8.17],[1,2.64,27.05],[2,1.99,5.64]],"ltp":2.64,"tv":3.02,"id":72857115}]}]}
{"op":"mcm","clk":"11909348597","pt":1724418796571,"mc":[{"id":"1.232174751","rc":[{"batb":[[0,2.7,9],[1,2.68,8.17],[2,2.64,27.05]],"ltp":2.64,"tv":3.02,"id":72857115}]}]}
{"op":"mcm","clk":"11909348816","pt":1724418799071,"mc":[{"id":"1.232174751","rc":[{"batb":[[0,2.7,5]],"ltp":2.64,"tv":3.02,"id":72857115}]}]}
{"op":"mcm","clk":"11909348910","pt":1724418800105,"mc":[{"id":"1.232174751","rc":[{"batb":[[0,2.68,8.17],[1,2.64,27.05],[2,1.99,5.64]],"ltp":2.64,"tv":3.02,"id":72857115}]}]}
{"op":"mcm","clk":"11909349051","pt":1724418801300,"mc":[{"id":"1.232174751","rc":[{"batb":[[0,2.7,4],[1,2.68,8.17],[2,2.64,27.05]],"ltp":2.64,"tv":3.02,"id":72857115}]}]}
{"op":"mcm","clk":"11909349314","pt":1724418803580,"mc":[{"id":"1.232174751","rc":[{"batb":[[0,2.68,8.17],[1,2.64,27.05],[2,1.99,5.64]],"ltp":2.64,"tv":3.02,"id":72857115}]}]}
{"op":"mcm","clk":"11909349355","pt":1724418803895,"mc":[{"id":"1.232174751","rc":[{"batb":[[0,2.7,5],[1,2.68,8.17],[2,2.64,27.05]],"ltp":2.64,"tv":3.02,"id":72857115}]}]}
{"op":"mcm","clk":"11909349663","pt":1724418807204,"mc":[{"id":"1.232174751","rc":[{"batb":[[0,2.7,4]],"ltp":2.64,"tv":3.02,"id":72857115}]}]}
{"op":"mcm","clk":"11909349857","pt":1724418809487,"mc":[{"id":"1.232174751","rc":[{"batb":[[0,2.7,5]],"ltp":2.64,"tv":3.02,"id":72857115}]}]}
{"op":"mcm","clk":"11909350156","pt":1724418812895,"mc":[{"id":"1.232174751","rc":[{"batb":[[0,2.7,4]],"ltp":2.64,"tv":3.02,"id":72857115}]}]}
{"op":"mcm","clk":"11909350376","pt":1724418815294,"mc":[{"id":"1.232174751","rc":[{"batb":[[0,2.7,5]],"ltp":2.64,"tv":3.02,"id":72857115}]}]}
{"op":"mcm","clk":"11909350588","pt":1724418817619,"mc":[{"id":"1.232174751","rc":[{"batb":[[0,2.72,4],[1,2.7,5],[2,2.68,8.17]],"ltp":2.64,"tv":3.02,"id":72857115}]}]}
{"op":"mcm","clk":"11909350670","pt":1724418818610,"mc":[{"id":"1.232174751","rc":[{"batb":[[1,2.68,8.17],[2,2.64,27.05]],"ltp":2.64,"tv":3.02,"id":72857115}]}]}
{"op":"mcm","clk":"11909350963","pt":1724418821919,"mc":[{"id":"1.232174751","rc":[{"batb":[[0,2.74,5]],"ltp":2.64,"tv":3.02,"id":72857115}]}]}
{"op":"mcm","clk":"11909351212","pt":1724418824215,"mc":[{"id":"1.232174751","rc":[{"batb":[[0,2.76,4],[1,2.74,5],[2,2.68,8.17]],"ltp":2.64,"tv":3.02,"id":72857115},{"batl":[[0,1.6,276.92],[1,1.61,25.65],[2,2.5,1]],"ltp":1.56,"tv":154.76,"id":72857116}]}]}
{"op":"mcm","clk":"11909351274","pt":1724418824939,"mc":[{"id":"1.232174751","rc":[{"batb":[[1,2.68,8.17],[2,2.64,27.05]],"ltp":2.64,"tv":3.02,"id":72857115}]}]}
{"op":"mcm","clk":"11909351459","pt":1724418826615,"mc":[{"id":"1.232174751","rc":[{"batb":[[0,2.68,8.17],[1,2.64,27.05],[2,1.99,5.64]],"ltp":2.64,"tv":3.02,"id":72857115}]}]}
{"op":"mcm","clk":"11909352032","pt":1724418832019,"mc":[{"id":"1.232174751","rc":[{"batb":[[0,2.7,9],[1,2.68,8.17],[2,2.64,27.05]],"ltp":2.64,"tv":3.02,"id":72857115}]}]}
{"op":"mcm","clk":"11909352246","pt":1724418834541,"mc":[{"id":"1.232174751","rc":[{"batb":[[0,2.7,5]],"ltp":2.64,"tv":3.02,"id":72857115}]}]}
{"op":"mcm","clk":"11909352338","pt":1724418835634,"mc":[{"id":"1.232174751","rc":[{"batb":[[0,2.68,8.17],[1,2.64,27.05],[2,1.99,5.64]],"ltp":2.64,"tv":3.02,"id":72857115}]}]}
{"op":"mcm","clk":"11909352479","pt":1724418836934,"mc":[{"id":"1.232174751","rc":[{"batb":[[0,2.7,4],[1,2.68,8.17],[2,2.64,27.05]],"ltp":2.64,"tv":3.02,"id":72857115}]}]}
{"op":"mcm","clk":"11909352603","pt":1724418838139,"mc":[{"id":"1.232174751","rc":[{"batb":[[0,2.72,5],[1,2.7,4],[2,2.68,8.17]],"ltp":2.64,"tv":3.02,"id":72857115}]}]}
{"op":"mcm","clk":"11909352702","pt":1724418839161,"mc":[{"id":"1.232174751","rc":[{"batb":[[1,2.68,8.17],[2,2.64,27.05]],"ltp":2.64,"tv":3.02,"id":72857115}]}]}
{"op":"mcm","clk":"11909352916","pt":1724418841454,"mc":[{"id":"1.232174751","rc":[{"batb":[[0,2.68,8.17],[1,2.64,27.05],[2,1.99,5.64]],"ltp":2.64,"tv":3.02,"id":72857115}]}]}
{"op":"mcm","clk":"11909352934","pt":1724418841663,"mc":[{"id":"1.232174751","rc":[{"batb":[[0,2.7,4],[1,2.68,8.17],[2,2.64,27.05]],"ltp":2.64,"tv":3.02,"id":72857115}]}]}
{"op":"mcm","clk":"11909353203","pt":1724418843954,"mc":[{"id":"1.232174751","rc":[{"batb":[[0,2.7,5]],"ltp":2.64,"tv":3.02,"id":72857115}]}]}
{"op":"mcm","clk":"11909353572","pt":1724418847378,"mc":[{"id":"1.232174751","rc":[{"batb":[[0,2.7,4]],"ltp":2.64,"tv":3.02,"id":72857115}]}]}
{"op":"mcm","clk":"11909353845","pt":1724418849755,"mc":[{"id":"1.232174751","rc":[{"batb":[[0,2.7,5]],"ltp":2.64,"tv":3.02,"id":72857115}]}]}
{"op":"mcm","clk":"11909354222","pt":1724418853164,"mc":[{"id":"1.232174751","rc":[{"batb":[[0,2.7,4]],"ltp":2.64,"tv":3.02,"id":72857115}]}]}
{"op":"mcm","clk":"11909354469","pt":1724418855460,"mc":[{"id":"1.232174751","rc":[{"batb":[[0,2.72,5]],"ltp":2.64,"tv":3.02,"id":72857115},{"batl":[[0,1.59,14.6],[1,1.6,276.92],[2,1.61,25.65]],"ltp":1.56,"tv":154.76,"id":72857116}]}]}
{"op":"mcm","clk":"11909354778","pt":1724418858465,"mc":[{"id":"1.232174751","rc":[{"batb":[[0,2.68,8.17],[1,2.64,27.05],[2,1.99,5.64]],"ltp":2.64,"tv":3.02,"id":72857115}]}]}
{"op":"mcm","clk":"11909354831","pt":1724418858989,"mc":[{"id":"1.232174751","rc":[{"batb":[[0,2.7,4],[1,2.68,8.17],[2,2.64,27.05]],"ltp":2.64,"tv":3.02,"id":72857115}]}]}
{"op":"mcm","clk":"11909355076","pt":1724418861269,"mc":[{"id":"1.232174751","rc":[{"batb":[[0,2.7,5]],"ltp":2.64,"tv":3.02,"id":72857115}]}]}
{"op":"mcm","clk":"11909355436","pt":1724418864639,"mc":[{"id":"1.232174751","rc":[{"batb":[[0,2.7,4]],"ltp":2.64,"tv":3.02,"id":72857115}]}]}
{"op":"mcm","clk":"11909355628","pt":1724418866965,"mc":[{"id":"1.232174751","rc":[{"batb":[[0,2.7,5]],"ltp":2.64,"tv":3.02,"id":72857115}]}]}
{"op":"mcm","clk":"11909355972","pt":1724418870383,"mc":[{"id":"1.232174751","rc":[{"batb":[[0,2.7,4]],"ltp":2.64,"tv":3.02,"id":72857115}]}]}
{"op":"mcm","clk":"11909356208","pt":1724418872571,"mc":[{"id":"1.232174751","rc":[{"batb":[[0,2.68,8.17],[1,2.64,27.05],[2,1.99,5.64]],"ltp":2.64,"tv":3.02,"id":72857115}]}]}
{"op":"mcm","clk":"11909356220","pt":1724418872677,"mc":[{"id":"1.232174751","rc":[{"batb":[[0,2.7,5],[1,2.68,8.17],[2,2.64,27.05]],"ltp":2.64,"tv":3.02,"id":72857115}]}]}
{"op":"mcm","clk":"11909356402","pt":1724418874690,"mc":[{"id":"1.232174751","rc":[{"batb":[[0,2.72,4],[1,2.7,5],[2,2.68,8.17]],"ltp":2.64,"tv":3.02,"id":72857115}]}]}
{"op":"mcm","clk":"11909356507","pt":1724418875887,"mc":[{"id":"1.232174751","rc":[{"batb":[[1,2.68,8.17],[2,2.64,27.05]],"ltp":2.64,"tv":3.02,"id":72857115}]}]}
{"op":"mcm","clk":"11909356628","pt":1724418877083,"mc":[{"id":"1.232174751","rc":[{"batb":[[0,2.68,8.17],[1,2.64,27.05],[2,1.99,5.64]],"ltp":2.64,"tv":3.02,"id":72857115}]}]}
{"op":"mcm","clk":"11909357267","pt":1724418883502,"mc":[{"id":"1.232174751","rc":[{"batb":[[0,2.7,9],[1,2.68,8.17],[2,2.64,27.05]],"ltp":2.64,"tv":3.02,"id":72857115}]}]}
{"op":"mcm","clk":"11909357534","pt":1724418885989,"mc":[{"id":"1.232174751","rc":[{"batb":[[0,2.7,5]],"ltp":2.64,"tv":3.02,"id":72857115}]}]}
{"op":"mcm","clk":"11909357648","pt":1724418887091,"mc":[{"id":"1.232174751","rc":[{"batb":[[0,2.68,8.17],[1,2.64,27.05],[2,1.99,5.64]],"ltp":2.64,"tv":3.02,"id":72857115}]}]}
{"op":"mcm","clk":"11909357769","pt":1724418888311,"mc":[{"id":"1.232174751","rc":[{"batb":[[0,2.7,4],[1,2.68,8.17],[2,2.64,27.05]],"ltp":2.64,"tv":3.02,"id":72857115}]}]}
{"op":"mcm","clk":"11909358002","pt":1724418890905,"mc":[{"id":"1.232174751","rc":[{"batb":[[0,2.7,5]],"ltp":2.64,"tv":3.02,"id":72857115}]}]}
{"op":"mcm","clk":"11909358336","pt":1724418894310,"mc":[{"id":"1.232174751","rc":[{"batb":[[0,2.7,4]],"ltp":2.64,"tv":3.02,"id":72857115}]}]}
{"op":"mcm","clk":"11909358565","pt":1724418896605,"mc":[{"id":"1.232174751","rc":[{"batb":[[0,2.68,8.17],[1,2.64,27.05],[2,1.99,5.64]],"ltp":2.64,"tv":3.02,"id":72857115}]}]}
{"op":"mcm","clk":"11909358583","pt":1724418896808,"mc":[{"id":"1.232174751","rc":[{"batb":[[0,2.7,5],[1,2.68,8.17],[2,2.64,27.05]],"ltp":2.64,"tv":3.02,"id":72857115}]}]}
{"op":"mcm","clk":"11909358959","pt":1724418900317,"mc":[{"id":"1.232174751","rc":[{"batb":[[0,2.7,4]],"ltp":2.64,"tv":3.02,"id":72857115}]}]}
{"op":"mcm","clk":"11909359194","pt":1724418902523,"mc":[{"id":"1.232174751","rc":[{"batb":[[0,2.68,8.17],[1,2.64,27.05],[2,1.99,5.64]],"ltp":2.64,"tv":3.02,"id":72857115}]}]}
{"op":"mcm","clk":"11909359219","pt":1724418902728,"mc":[{"id":"1.232174751","rc":[{"batb":[[0,2.7,5],[1,2.68,8.17],[2,2.64,27.05]],"ltp":2.64,"tv":3.02,"id":72857115}]}]}
{"op":"mcm","clk":"11909359570","pt":1724418906114,"mc":[{"id":"1.232174751","rc":[{"batb":[[0,2.7,4]],"ltp":2.64,"tv":3.02,"id":72857115}]}]}
{"op":"mcm","clk":"11909359827","pt":1724418908494,"mc":[{"id":"1.232174751","rc":[{"batb":[[0,2.7,5]],"ltp":2.64,"tv":3.02,"id":72857115}]}]}
{"op":"mcm","clk":"11909360212","pt":1724418911927,"mc":[{"id":"1.232174751","rc":[{"batb":[[0,2.7,4]],"ltp":2.64,"tv":3.02,"id":72857115}]}]}
{"op":"mcm","clk":"11909360478","pt":1724418914311,"mc":[{"id":"1.232174751","rc":[{"batb":[[0,2.7,5]],"ltp":2.64,"tv":3.02,"id":72857115}]}]}
{"op":"mcm","clk":"11909360853","pt":1724418917562,"mc":[{"id":"1.232174751","rc":[{"batb":[[0,2.68,8.17],[1,2.64,27.05],[2,1.99,5.64]],"ltp":2.64,"tv":3.02,"id":72857115}]}]}
{"op":"mcm","clk":"11909360878","pt":1724418917734,"mc":[{"id":"1.232174751","rc":[{"batb":[[0,2.7,4],[1,2.68,8.17],[2,2.64,27.05]],"ltp":2.64,"tv":3.02,"id":72857115}]}]}
{"op":"mcm","clk":"11909361127","pt":1724418920121,"mc":[{"id":"1.232174751","rc":[{"batb":[[0,2.7,5]],"ltp":2.64,"tv":3.02,"id":72857115}]}]}
{"op":"mcm","clk":"11909361477","pt":1724418923324,"mc":[{"id":"1.232174751","rc":[{"batb":[[0,2.72,4]],"ltp":2.64,"tv":3.02,"id":72857115}]}]}
{"op":"mcm","clk":"11909361719","pt":1724418925957,"mc":[{"id":"1.232174751","rc":[{"batb":[[0,2.7,5]],"ltp":2.64,"tv":3.02,"id":72857115}]}]}
{"op":"mcm","clk":"11909362068","pt":1724418929570,"mc":[{"id":"1.232174751","rc":[{"batb":[[0,2.7,4]],"ltp":2.64,"tv":3.02,"id":72857115}]}]}
{"op":"mcm","clk":"11909362286","pt":1724418931869,"mc":[{"id":"1.232174751","rc":[{"batb":[[0,2.7,5]],"ltp":2.64,"tv":3.02,"id":72857115}]}]}
{"op":"mcm","clk":"11909362604","pt":1724418935252,"mc":[{"id":"1.232174751","rc":[{"batb":[[0,2.7,4]],"ltp":2.64,"tv":3.02,"id":72857115}]}]}
{"op":"mcm","clk":"11909362896","pt":1724418937854,"mc":[{"id":"1.232174751","rc":[{"batb":[[0,2.7,5]],"ltp":2.64,"tv":3.02,"id":72857115}]}]}
{"op":"mcm","clk":"11909363267","pt":1724418941269,"mc":[{"id":"1.232174751","rc":[{"batb":[[0,2.7,4]],"ltp":2.64,"tv":3.02,"id":72857115}]}]}
{"op":"mcm","clk":"11909363546","pt":1724418943548,"mc":[{"id":"1.232174751","rc":[{"batb":[[0,2.68,8.17],[1,2.64,27.05],[2,1.99,5.64]],"ltp":2.64,"tv":3.02,"id":72857115}]}]}
{"op":"mcm","clk":"11909363574","pt":1724418943762,"mc":[{"id":"1.232174751","rc":[{"batb":[[0,2.7,5],[1,2.68,8.17],[2,2.64,27.05]],"ltp":2.64,"tv":3.02,"id":72857115}]}]}
{"op":"mcm","clk":"11909363959","pt":1724418947166,"mc":[{"id":"1.232174751","rc":[{"batb":[[0,2.7,4]],"ltp":2.64,"tv":3.02,"id":72857115}]}]}
{"op":"mcm","clk":"11909364218","pt":1724418949558,"mc":[{"id":"1.232174751","rc":[{"batb":[[0,2.7,5]],"ltp":2.64,"tv":3.02,"id":72857115}]}]}
{"op":"mcm","clk":"11909364512","pt":1724418952282,"mc":[{"id":"1.232174751","rc":[{"batb":[[0,2.72,4],[1,2.7,5],[2,2.68,8.17]],"ltp":2.64,"tv":3.02,"id":72857115}]}]}
{"op":"mcm","clk":"11909364561","pt":1724418952652,"mc":[{"id":"1.232174751","rc":[{"batb":[[1,2.68,8.17],[2,2.64,27.05]],"ltp":2.64,"tv":3.02,"id":72857115}]}]}
{"op":"mcm","clk":"11909364784","pt":1724418954977,"mc":[{"id":"1.232174751","rc":[{"batb":[[0,2.7,5]],"ltp":2.64,"tv":3.02,"id":72857115}]}]}
{"op":"mcm","clk":"11909365166","pt":1724418958400,"mc":[{"id":"1.232174751","rc":[{"batb":[[0,2.7,4]],"ltp":2.64,"tv":3.02,"id":72857115}]}]}
{"op":"mcm","clk":"11909365408","pt":1724418960580,"mc":[{"id":"1.232174751","rc":[{"batb":[[0,2.68,8.17],[1,2.64,27.05],[2,1.99,5.64]],"ltp":2.64,"tv":3.02,"id":72857115}]}]}
{"op":"mcm","clk":"11909365435","pt":1724418960787,"mc":[{"id":"1.232174751","rc":[{"batb":[[0,2.7,5],[1,2.68,8.17],[2,2.64,27.05]],"ltp":2.64,"tv":3.02,"id":72857115}]}]}
{"op":"mcm","clk":"11909365866","pt":1724418964168,"mc":[{"id":"1.232174751","rc":[{"batb":[[0,2.7,4]],"ltp":2.64,"tv":3.02,"id":72857115}]}]}
{"op":"mcm","clk":"11909366118","pt":1724418966590,"mc":[{"id":"1.232174751","rc":[{"batb":[[0,2.7,5]],"ltp":2.64,"tv":3.02,"id":72857115}]}]}
{"op":"mcm","clk":"11909366454","pt":1724418969789,"mc":[{"id":"1.232174751","rc":[{"batb":[[0,2.7,4]],"ltp":2.64,"tv":3.02,"id":72857115}]}]}
{"op":"mcm","clk":"11909366729","pt":1724418972224,"mc":[{"id":"1.232174751","rc":[{"batb":[[0,2.7,5]],"ltp":2.64,"tv":3.02,"id":72857115}]}]}
{"op":"mcm","clk":"11909367111","pt":1724418975604,"mc":[{"id":"1.232174751","rc":[{"batb":[[0,2.72,4]],"ltp":2.64,"tv":3.02,"id":72857115}]}]}
{"op":"mcm","clk":"11909367278","pt":1724418977308,"mc":[{"id":"1.232174751","rc":[{"batb":[[0,2.68,8.17],[1,2.64,27.05],[2,1.99,5.64]],"ltp":2.64,"tv":3.02,"id":72857115}]}]}
{"op":"mcm","clk":"11909368418","pt":1724418988904,"mc":[{"id":"1.232174751","rc":[{"batb":[[0,2.7,9],[1,2.68,8.17],[2,2.64,27.05]],"ltp":2.64,"tv":3.02,"id":72857115}]}]}
{"op":"mcm","clk":"11909368664","pt":1724418991124,"mc":[{"id":"1.232174751","rc":[{"batb":[[0,2.7,5]],"ltp":2.64,"tv":3.02,"id":72857115}]}]}
{"op":"mcm","clk":"11909368792","pt":1724418992593,"mc":[{"id":"1.232174751","rc":[{"batb":[[0,2.68,8.17],[1,2.64,27.05],[2,1.99,5.64]],"ltp":2.64,"tv":3.02,"id":72857115}]}]}
{"op":"mcm","clk":"11909369336","pt":1724418997924,"mc":[{"id":"1.232174751","rc":[{"batb":[[0,2.7,9],[1,2.68,8.17],[2,2.64,27.05]],"ltp":2.64,"tv":3.02,"id":72857115}]}]}
{"op":"mcm","clk":"11909369565","pt":1724419000313,"mc":[{"id":"1.232174751","rc":[{"batb":[[0,2.7,5]],"ltp":2.64,"tv":3.02,"id":72857115}]}]}
{"op":"mcm","clk":"11909369662","pt":1724419001340,"mc":[{"id":"1.232174751","rc":[{"batb":[[0,2.68,8.17],[1,2.64,27.05],[2,1.99,5.64]],"ltp":2.64,"tv":3.02,"id":72857115}]}]}
{"op":"mcm","clk":"11909370047","pt":1724419005010,"mc":[{"id":"1.232174751","rc":[{"batb":[[0,2.7,9],[1,2.68,8.17],[2,2.64,27.05]],"ltp":2.64,"tv":3.02,"id":72857115}]}]}
{"op":"mcm","clk":"11909370294","pt":1724419007421,"mc":[{"id":"1.232174751","rc":[{"batb":[[0,2.7,5]],"ltp":2.64,"tv":3.02,"id":72857115}]}]}
{"op":"mcm","clk":"11909370387","pt":1724419008313,"mc":[{"id":"1.232174751","rc":[{"batb":[[0,2.68,8.17],[1,2.64,27.05],[2,1.99,5.64]],"ltp":2.64,"tv":3.02,"id":72857115}]}]}
{"op":"mcm","clk":"11909371041","pt":1724419014474,"mc":[{"id":"1.232174751","rc":[{"batb":[[0,2.7,9],[1,2.68,8.17],[2,2.64,27.05]],"ltp":2.64,"tv":3.02,"id":72857115}]}]}
{"op":"mcm","clk":"11909371335","pt":1724419016863,"mc":[{"id":"1.232174751","rc":[{"batb":[[0,2.7,5]],"ltp":2.64,"tv":3.02,"id":72857115}]}]}
{"op":"mcm","clk":"11909371430","pt":1724419017969,"mc":[{"id":"1.232174751","rc":[{"batb":[[0,2.68,8.17],[1,2.64,27.05],[2,1.99,5.64]],"ltp":2.64,"tv":3.02,"id":72857115}]}]}
{"op":"mcm","clk":"11909372188","pt":1724419025185,"mc":[{"id":"1.232174751","rc":[{"batb":[[0,2.7,9],[1,2.68,8.17],[2,2.64,27.05]],"ltp":2.64,"tv":3.02,"id":72857115}]}]}
{"op":"mcm","clk":"11909372579","pt":1724419028511,"mc":[{"id":"1.232174751","rc":[{"batb":[[0,2.68,8.17],[1,2.64,27.05],[2,1.99,5.64]],"ltp":2.64,"tv":3.02,"id":72857115}]}]}
{"op":"mcm","clk":"11909373546","pt":1724419037484,"mc":[{"id":"1.232174751","rc":[{"batb":[[0,2.7,9],[1,2.68,8.17],[2,2.64,27.05]],"ltp":2.64,"tv":3.02,"id":72857115}]}]}
{"op":"mcm","clk":"11909373806","pt":1724419040093,"mc":[{"id":"1.232174751","rc":[{"batb":[[0,2.7,5]],"ltp":2.64,"tv":3.02,"id":72857115}]}]}
{"op":"mcm","clk":"11909373900","pt":1724419040875,"mc":[{"id":"1.232174751","rc":[{"batb":[[0,2.68,8.17],[1,2.64,27.05],[2,1.99,5.64]],"ltp":2.64,"tv":3.02,"id":72857115}]}]}
{"op":"mcm","clk":"11909374439","pt":1724419046097,"mc":[{"id":"1.232174751","rc":[{"batb":[[0,2.7,9],[1,2.68,8.17],[2,2.64,27.05]],"ltp":2.64,"tv":3.02,"id":72857115}]}]}
{"op":"mcm","clk":"11909374706","pt":1724419048596,"mc":[{"id":"1.232174751","rc":[{"batb":[[0,2.7,5]],"ltp":2.64,"tv":3.02,"id":72857115}]}]}
{"op":"mcm","clk":"11909374800","pt":1724419049629,"mc":[{"id":"1.232174751","rc":[{"batb":[[0,2.68,8.17],[1,2.64,27.05],[2,1.99,5.64]],"ltp":2.64,"tv":3.02,"id":72857115}]}]}
{"op":"mcm","clk":"11909376036","pt":1724419061095,"mc":[{"id":"1.232174751","rc":[{"batb":[[0,2.7,9],[1,2.68,8.17],[2,2.64,27.05]],"ltp":2.64,"tv":3.02,"id":72857115}]}]}
{"op":"mcm","clk":"11909376296","pt":1724419063633,"mc":[{"id":"1.232174751","rc":[{"batb":[[0,2.7,5]],"ltp":2.64,"tv":3.02,"id":72857115}]}]}
{"op":"mcm","clk":"11909376398","pt":1724419064610,"mc":[{"id":"1.232174751","rc":[{"batb":[[0,2.68,8.17],[1,2.64,27.05],[2,1.99,5.64]],"ltp":2.64,"tv":3.02,"id":72857115}]}]}
{"op":"mcm","clk":"11909377762","pt":1724419077817,"mc":[{"id":"1.232174751","rc":[{"batb":[[0,2.7,9],[1,2.68,8.17],[2,2.64,27.05]],"ltp":2.64,"tv":3.02,"id":72857115}]}]}
{"op":"mcm","clk":"11909378018","pt":1724419080331,"mc":[{"id":"1.232174751","rc":[{"batb":[[0,2.7,5]],"ltp":2.64,"tv":3.02,"id":72857115}]}]}
{"op":"mcm","clk":"11909378123","pt":1724419081255,"mc":[{"id":"1.232174751","rc":[{"batb":[[0,2.68,8.17],[1,2.64,27.05],[2,1.99,5.64]],"ltp":2.64,"tv":3.02,"id":72857115}]}]}
{"op":"mcm","clk":"11909378917","pt":1724419089047,"mc":[{"id":"1.232174751","rc":[{"batb":[[0,2.7,9],[1,2.68,8.17],[2,2.64,27.05]],"ltp":2.64,"tv":3.02,"id":72857115}]}]}
{"op":"mcm","clk":"11909379169","pt":1724419091534,"mc":[{"id":"1.232174751","rc":[{"batb":[[0,2.7,5]],"ltp":2.64,"tv":3.02,"id":72857115}]}]}
{"op":"mcm","clk":"11909379258","pt":1724419092466,"mc":[{"id":"1.232174751","rc":[{"batb":[[0,2.68,8.17],[1,2.64,27.05],[2,1.99,5.64]],"ltp":2.64,"tv":3.02,"id":72857115}]}]}
{"op":"mcm","clk":"11909379566","pt":1724419095265,"mc":[{"id":"1.232174751","rc":[{"batb":[[0,2.7,9],[1,2.68,8.17],[2,2.64,27.05]],"ltp":2.64,"tv":3.02,"id":72857115}]}]}
{"op":"mcm","clk":"11909379832","pt":1724419097968,"mc":[{"id":"1.232174751","rc":[{"batb":[[0,2.7,5]],"ltp":2.64,"tv":3.02,"id":72857115}]}]}
{"op":"mcm","clk":"11909379929","pt":1724419098852,"mc":[{"id":"1.232174751","rc":[{"batb":[[0,2.68,8.17],[1,2.64,27.05],[2,1.99,5.64]],"ltp":2.64,"tv":3.02,"id":72857115}]}]}
{"op":"mcm","clk":"11909381591","pt":1724419113382,"mc":[{"id":"1.232174751","rc":[{"batb":[[0,2.7,9],[1,2.68,8.17],[2,2.64,27.05]],"ltp":2.64,"tv":3.02,"id":72857115}]}]}
{"op":"mcm","clk":"11909381870","pt":1724419115857,"mc":[{"id":"1.232174751","rc":[{"batb":[[0,2.7,5]],"ltp":2.64,"tv":3.02,"id":72857115}]}]}
{"op":"mcm","clk":"11909382009","pt":1724419117079,"mc":[{"id":"1.232174751","rc":[{"batb":[[0,2.68,8.17],[1,2.64,27.05],[2,1.99,5.64]],"ltp":2.64,"tv":3.02,"id":72857115}]}]}
{"op":"mcm","clk":"11909382145","pt":1724419118470,"mc":[{"id":"1.232174751","rc":[{"batb":[[0,2.7,4],[1,2.68,8.17],[2,2.64,27.05]],"ltp":2.64,"tv":3.02,"id":72857115}]}]}
{"op":"mcm","clk":"11909382446","pt":1724419121365,"mc":[{"id":"1.232174751","rc":[{"batb":[[0,2.7,5]],"ltp":2.64,"tv":3.02,"id":72857115}]}]}
{"op":"mcm","clk":"11909382788","pt":1724419124767,"mc":[{"id":"1.232174751","rc":[{"batb":[[0,2.7,4]],"ltp":2.64,"tv":3.02,"id":72857115}]}]}
{"op":"mcm","clk":"11909383042","pt":1724419127204,"mc":[{"id":"1.232174751","rc":[{"batb":[[0,2.7,5]],"ltp":2.64,"tv":3.02,"id":72857115}]}]}
{"op":"mcm","clk":"11909383380","pt":1724419130624,"mc":[{"id":"1.232174751","rc":[{"batb":[[0,2.7,4]],"ltp":2.64,"tv":3.02,"id":72857115}]}]}
{"op":"mcm","clk":"11909383636","pt":1724419133000,"mc":[{"id":"1.232174751","rc":[{"batb":[[0,2.7,5]],"ltp":2.64,"tv":3.02,"id":72857115}]}]}
{"op":"mcm","clk":"11909384017","pt":1724419136525,"mc":[{"id":"1.232174751","rc":[{"batb":[[0,2.7,4]],"ltp":2.64,"tv":3.02,"id":72857115}]}]}
{"op":"mcm","clk":"11909384230","pt":1724419138832,"mc":[{"id":"1.232174751","rc":[{"batb":[[0,2.7,5]],"ltp":2.64,"tv":3.02,"id":72857115}]}]}
{"op":"mcm","clk":"11909384571","pt":1724419142402,"mc":[{"id":"1.232174751","rc":[{"batb":[[0,2.7,4]],"ltp":2.64,"tv":3.02,"id":72857115}]}]}
{"op":"mcm","clk":"11909384790","pt":1724419144590,"mc":[{"id":"1.232174751","rc":[{"batb":[[0,2.68,8.17],[1,2.64,27.05],[2,1.99,5.64]],"ltp":2.64,"tv":3.02,"id":72857115}]}]}
{"op":"mcm","clk":"11909384810","pt":1724419144799,"mc":[{"id":"1.232174751","rc":[{"batb":[[0,2.7,5],[1,2.68,8.17],[2,2.64,27.05]],"ltp":2.64,"tv":3.02,"id":72857115}]}]}
{"op":"mcm","clk":"11909385155","pt":1724419148229,"mc":[{"id":"1.232174751","rc":[{"batb":[[0,2.7,4]],"ltp":2.64,"tv":3.02,"id":72857115}]}]}
{"op":"mcm","clk":"11909385368","pt":1724419150403,"mc":[{"id":"1.232174751","rc":[{"batb":[[0,2.68,8.17],[1,2.64,27.05],[2,1.99,5.64]],"ltp":2.64,"tv":3.02,"id":72857115}]}]}
{"op":"mcm","clk":"11909385396","pt":1724419150662,"mc":[{"id":"1.232174751","rc":[{"batb":[[0,2.7,5],[1,2.68,8.17],[2,2.64,27.05]],"ltp":2.64,"tv":3.02,"id":72857115}]}]}
{"op":"mcm","clk":"11909385764","pt":1724419154103,"mc":[{"id":"1.232174751","rc":[{"batb":[[0,2.7,4]],"ltp":2.64,"tv":3.02,"id":72857115}]}]}
{"op":"mcm","clk":"11909386037","pt":1724419156535,"mc":[{"id":"1.232174751","rc":[{"batb":[[0,2.7,5]],"ltp":2.64,"tv":3.02,"id":72857115}]}]}
{"op":"mcm","clk":"11909386351","pt":1724419159818,"mc":[{"id":"1.232174751","rc":[{"batb":[[0,2.7,4]],"ltp":2.64,"tv":3.02,"id":72857115}]}]}
{"op":"mcm","clk":"11909386622","pt":1724419162230,"mc":[{"id":"1.232174751","rc":[{"batb":[[0,2.7,5]],"ltp":2.64,"tv":3.02,"id":72857115}]}]}
{"op":"mcm","clk":"11909386982","pt":1724419165528,"mc":[{"id":"1.232174751","rc":[{"batb":[[0,2.7,4]],"ltp":2.64,"tv":3.02,"id":72857115}]}]}
{"op":"mcm","clk":"11909387232","pt":1724419167921,"mc":[{"id":"1.232174751","rc":[{"batb":[[0,2.7,5]],"ltp":2.64,"tv":3.02,"id":72857115}]}]}
{"op":"mcm","clk":"11909387540","pt":1724419171161,"mc":[{"id":"1.232174751","rc":[{"batb":[[0,2.72,4]],"ltp":2.64,"tv":3.02,"id":72857115}]}]}
{"op":"mcm","clk":"11909387773","pt":1724419173547,"mc":[{"id":"1.232174751","rc":[{"batb":[[0,2.7,5]],"ltp":2.64,"tv":3.02,"id":72857115}]}]}
{"op":"mcm","clk":"11909388144","pt":1724419177041,"mc":[{"id":"1.232174751","rc":[{"batb":[[0,2.7,4]],"ltp":2.64,"tv":3.02,"id":72857115}]}]}
{"op":"mcm","clk":"11909388419","pt":1724419179464,"mc":[{"id":"1.232174751","rc":[{"batb":[[0,2.68,8.17],[1,2.64,27.05],[2,1.99,5.64]],"ltp":2.64,"tv":3.02,"id":72857115}]}]}
{"op":"mcm","clk":"11909388446","pt":1724419179668,"mc":[{"id":"1.232174751","rc":[{"batb":[[0,2.7,5],[1,2.68,8.17],[2,2.64,27.05]],"ltp":2.64,"tv":3.02,"id":72857115}]}]}
{"op":"mcm","clk":"11909388778","pt":1724419182942,"mc":[{"id":"1.232174751","rc":[{"batb":[[0,2.72,4]],"ltp":2.64,"tv":3.02,"id":72857115}]}]}
{"op":"mcm","clk":"11909389023","pt":1724419185367,"mc":[{"id":"1.232174751","rc":[{"batb":[[0,2.7,5]],"ltp":2.64,"tv":3.02,"id":72857115}]}]}
{"op":"mcm","clk":"11909389731","pt":1724419189110,"mc":[{"id":"1.232174751","rc":[{"batb":[[0,2.7,4]],"ltp":2.64,"tv":3.02,"id":72857115}]}]}
{"op":"mcm","clk":"11909390160","pt":1724419191626,"mc":[{"id":"1.232174751","rc":[{"batb":[[0,2.7,5]],"ltp":2.64,"tv":3.02,"id":72857115}]}]}
{"op":"mcm","clk":"11909390511","pt":1724419195030,"mc":[{"id":"1.232174751","rc":[{"batb":[[0,2.72,4]],"ltp":2.64,"tv":3.02,"id":72857115}]}]}
{"op":"mcm","clk":"11909390775","pt":1724419197457,"mc":[{"id":"1.232174751","rc":[{"batb":[[0,2.7,5]],"ltp":2.64,"tv":3.02,"id":72857115}]}]}
{"op":"mcm","clk":"11909391133","pt":1724419200834,"mc":[{"id":"1.232174751","rc":[{"batb":[[0,2.7,4]],"ltp":2.64,"tv":3.02,"id":72857115}]}]}
{"op":"mcm","clk":"11909391403","pt":1724419203237,"mc":[{"id":"1.232174751","rc":[{"batb":[[0,2.7,5]],"ltp":2.64,"tv":3.02,"id":72857115}]}]}
{"op":"mcm","clk":"11909391775","pt":1724419206553,"mc":[{"id":"1.232174751","rc":[{"batb":[[0,2.68,8.17],[1,2.64,27.05],[2,1.99,5.64]],"ltp":2.64,"tv":3.02,"id":72857115}]}]}
{"op":"mcm","clk":"11909391784","pt":1724419206660,"mc":[{"id":"1.232174751","rc":[{"batb":[[0,2.7,4],[1,2.68,8.17],[2,2.64,27.05]],"ltp":2.64,"tv":3.02,"id":72857115}]}]}
{"op":"mcm","clk":"11909392046","pt":1724419209040,"mc":[{"id":"1.232174751","rc":[{"batb":[[0,2.7,5]],"ltp":2.64,"tv":3.02,"id":72857115}]}]}
{"op":"mcm","clk":"11909392431","pt":1724419212356,"mc":[{"id":"1.232174751","rc":[{"batb":[[0,2.72,4]],"ltp":2.64,"tv":3.02,"id":72857115}]}]}
{"op":"mcm","clk":"11909392632","pt":1724419214064,"mc":[{"id":"1.232174751","rc":[{"batb":[[0,2.68,8.17],[1,2.64,27.05],[2,1.99,5.64]],"ltp":2.64,"tv":3.02,"id":72857115}]}]}
{"op":"mcm","clk":"11909392876","pt":1724419216237,"mc":[{"id":"1.232174751","rc":[{"batb":[[0,2.7,9],[1,2.68,8.17],[2,2.64,27.05]],"ltp":2.64,"tv":3.02,"id":72857115}]}]}
{"op":"mcm","clk":"11909393114","pt":1724419218566,"mc":[{"id":"1.232174751","rc":[{"batb":[[0,2.7,5]],"ltp":2.64,"tv":3.02,"id":72857115}]}]}
{"op":"mcm","clk":"11909393258","pt":1724419219858,"mc":[{"id":"1.232174751","rc":[{"batb":[[0,2.68,8.17],[1,2.64,27.05],[2,1.99,5.64]],"ltp":2.64,"tv":3.02,"id":72857115}]}]}
{"op":"mcm","clk":"11909394121","pt":1724419228295,"mc":[{"id":"1.232174751","rc":[{"batb":[[0,2.7,9],[1,2.68,8.17],[2,2.64,27.05]],"ltp":2.64,"tv":3.02,"id":72857115}]}]}
{"op":"mcm","clk":"11909394371","pt":1724419230785,"mc":[{"id":"1.232174751","rc":[{"batb":[[0,2.7,5]],"ltp":2.64,"tv":3.02,"id":72857115}]}]}
{"op":"mcm","clk":"11909394487","pt":1724419231970,"mc":[{"id":"1.232174751","rc":[{"batb":[[0,2.68,8.17],[1,2.64,27.05],[2,1.99,5.64]],"ltp":2.64,"tv":3.02,"id":72857115}]}]}
{"op":"mcm","clk":"11909394811","pt":1724419235699,"mc":[{"id":"1.232174751","rc":[{"batb":[[0,2.7,9],[1,2.68,8.17],[2,2.64,27.05]],"ltp":2.64,"tv":3.02,"id":72857115}]}]}
{"op":"mcm","clk":"11909395076","pt":1724419238181,"mc":[{"id":"1.232174751","rc":[{"batb":[[0,2.7,5]],"ltp":2.64,"tv":3.02,"id":72857115}]}]}
{"op":"mcm","clk":"11909395150","pt":1724419239003,"mc":[{"id":"1.232174751","rc":[{"batb":[[0,2.68,8.17],[1,2.64,27.05],[2,1.99,5.64]],"ltp":2.64,"tv":3.02,"id":72857115}]}]}
{"op":"mcm","clk":"11909396265","pt":1724419250117,"mc":[{"id":"1.232174751","rc":[{"batb":[[0,2.7,9],[1,2.68,8.17],[2,2.64,27.05]],"ltp":2.64,"tv":3.02,"id":72857115}]}]}
{"op":"mcm","clk":"11909396586","pt":1724419253413,"mc":[{"id":"1.232174751","rc":[{"batb":[[0,2.68,8.17],[1,2.64,27.05],[2,1.99,5.64]],"ltp":2.64,"tv":3.02,"id":72857115}]}]}
{"op":"mcm","clk":"11909397286","pt":1724419261020,"mc":[{"id":"1.232174751","rc":[{"batb":[[0,2.7,9],[1,2.68,8.17],[2,2.64,27.05]],"ltp":2.64,"tv":3.02,"id":72857115}]}]}
{"op":"mcm","clk":"11909397512","pt":1724419263623,"mc":[{"id":"1.232174751","rc":[{"batb":[[0,2.7,5]],"ltp":2.64,"tv":3.02,"id":72857115}]}]}
{"op":"mcm","clk":"11909397633","pt":1724419264736,"mc":[{"id":"1.232174751","rc":[{"batb":[[0,2.68,8.17],[1,2.64,27.05],[2,1.99,5.64]],"ltp":2.64,"tv":3.02,"id":72857115}]}]}
{"op":"mcm","clk":"11909399136","pt":1724419279436,"mc":[{"id":"1.232174751","rc":[{"batb":[[0,2.7,9],[1,2.68,8.17],[2,2.64,27.05]],"ltp":2.64,"tv":3.02,"id":72857115}]}]}
{"op":"mcm","clk":"11909399380","pt":1724419281955,"mc":[{"id":"1.232174751","rc":[{"batb":[[0,2.7,5]],"ltp":2.64,"tv":3.02,"id":72857115}]}]}
{"op":"mcm","clk":"11909399479","pt":1724419283048,"mc":[{"id":"1.232174751","rc":[{"batb":[[0,2.68,8.17],[1,2.64,27.05],[2,1.99,5.64]],"ltp":2.64,"tv":3.02,"id":72857115}]}]}
{"op":"mcm","clk":"11909403113","pt":1724419321565,"mc":[{"id":"1.232174751","rc":[{"batb":[[0,2.7,9],[1,2.68,8.17],[2,2.64,27.05]],"ltp":2.64,"tv":3.02,"id":72857115}]}]}
{"op":"mcm","clk":"11909403360","pt":1724419324048,"mc":[{"id":"1.232174751","rc":[{"batb":[[0,2.7,5]],"ltp":2.64,"tv":3.02,"id":72857115}]}]}
{"op":"mcm","clk":"11909403452","pt":1724419325197,"mc":[{"id":"1.232174751","rc":[{"batb":[[0,2.68,8.17],[1,2.64,27.05],[2,1.99,5.64]],"ltp":2.64,"tv":3.02,"id":72857115}]}]}
{"op":"mcm","clk":"11909404442","pt":1724419335370,"mc":[{"id":"1.232174751","rc":[{"batb":[[0,2.7,9],[1,2.68,8.17],[2,2.64,27.05]],"ltp":2.64,"tv":3.02,"id":72857115}]}]}
{"op":"mcm","clk":"11909404688","pt":1724419337762,"mc":[{"id":"1.232174751","rc":[{"batb":[[0,2.7,5]],"ltp":2.64,"tv":3.02,"id":72857115}]}]}
{"op":"mcm","clk":"11909404770","pt":1724419338796,"mc":[{"id":"1.232174751","rc":[{"batb":[[0,2.68,8.17],[1,2.64,27.05],[2,1.99,5.64]],"ltp":2.64,"tv":3.02,"id":72857115}]}]}
{"op":"mcm","clk":"11909404905","pt":1724419340194,"mc":[{"id":"1.232174751","rc":[{"batb":[[0,2.7,4],[1,2.68,8.17],[2,2.64,27.05]],"ltp":2.64,"tv":3.02,"id":72857115}]}]}
{"op":"mcm","clk":"11909405207","pt":1724419343213,"mc":[{"id":"1.232174751","rc":[{"batb":[[0,2.7,5]],"ltp":2.64,"tv":3.02,"id":72857115}]}]}
{"op":"mcm","clk":"11909405542","pt":1724419346774,"mc":[{"id":"1.232174751","rc":[{"batb":[[0,2.7,4]],"ltp":2.64,"tv":3.02,"id":72857115}]}]}
{"op":"mcm","clk":"11909405757","pt":1724419349204,"mc":[{"id":"1.232174751","rc":[{"batb":[[0,2.68,8.17],[1,2.64,27.05],[2,1.99,5.64]],"ltp":2.64,"tv":3.02,"id":72857115}]}]}
{"op":"mcm","clk":"11909405800","pt":1724419349722,"mc":[{"id":"1.232174751","rc":[{"batb":[[0,2.7,5],[1,2.68,8.17],[2,2.64,27.05]],"ltp":2.64,"tv":3.02,"id":72857115}]}]}
{"op":"mcm","clk":"11909406122","pt":1724419353202,"mc":[{"id":"1.232174751","rc":[{"batb":[[0,2.7,4]],"ltp":2.64,"tv":3.02,"id":72857115}]}]}
{"op":"mcm","clk":"11909406353","pt":1724419355639,"mc":[{"id":"1.232174751","rc":[{"batb":[[0,2.68,8.17],[1,2.64,27.05],[2,1.99,5.64]],"ltp":2.64,"tv":3.02,"id":72857115}]}]}
{"op":"mcm","clk":"11909406371","pt":1724419355804,"mc":[{"id":"1.232174751","rc":[{"batb":[[0,2.7,5],[1,2.68,8.17],[2,2.64,27.05]],"ltp":2.64,"tv":3.02,"id":72857115}]}]}
{"op":"mcm","clk":"11909406745","pt":1724419359340,"mc":[{"id":"1.232174751","rc":[{"batb":[[0,2.7,4]],"ltp":2.64,"tv":3.02,"id":72857115}]}]}
{"op":"mcm","clk":"11909407046","pt":1724419361841,"mc":[{"id":"1.232174751","rc":[{"batb":[[0,2.7,5]],"ltp":2.64,"tv":3.02,"id":72857115}]}]}
{"op":"mcm","clk":"11909407436","pt":1724419365337,"mc":[{"id":"1.232174751","rc":[{"batb":[[0,2.7,4]],"ltp":2.64,"tv":3.02,"id":72857115}]}]}
{"op":"mcm","clk":"11909407667","pt":1724419367516,"mc":[{"id":"1.232174751","rc":[{"batb":[[0,2.68,8.17],[1,2.64,27.05],[2,1.99,5.64]],"ltp":2.64,"tv":3.02,"id":72857115}]}]}
{"op":"mcm","clk":"11909407688","pt":1724419367733,"mc":[{"id":"1.232174751","rc":[{"batb":[[0,2.7,5],[1,2.68,8.17],[2,2.64,27.05]],"ltp":2.64,"tv":3.02,"id":72857115}]}]}
{"op":"mcm","clk":"11909408052","pt":1724419371261,"mc":[{"id":"1.232174751","rc":[{"batb":[[0,2.68,8.17],[1,2.64,27.05],[2,1.99,5.64]],"ltp":2.64,"tv":3.02,"id":72857115}]}]}
{"op":"mcm","clk":"11909408142","pt":1724419372164,"mc":[{"id":"1.232174751","rc":[{"batb":[[0,2.7,4],[1,2.68,8.17],[2,2.64,27.05]],"ltp":2.64,"tv":3.02,"id":72857115}]}]}
{"op":"mcm","clk":"11909408233","pt":1724419373355,"mc":[{"id":"1.232174751","rc":[{"batb":[[0,2.72,5],[1,2.7,4],[2,2.68,8.17]],"ltp":2.64,"tv":3.02,"id":72857115}]}]}
{"op":"mcm","clk":"11909408343","pt":1724419374542,"mc":[{"id":"1.232174751","rc":[{"batb":[[1,2.68,8.17],[2,2.64,27.05]],"ltp":2.64,"tv":3.02,"id":72857115}]}]}
{"op":"mcm","clk":"11909408559","pt":1724419377061,"mc":[{"id":"1.232174751","rc":[{"batb":[[0,2.7,4]],"ltp":2.64,"tv":3.02,"id":72857115}]}]}
{"op":"mcm","clk":"11909408777","pt":1724419379441,"mc":[{"id":"1.232174751","rc":[{"batb":[[0,2.7,5]],"ltp":2.64,"tv":3.02,"id":72857115}]}]}
{"op":"mcm","clk":"11909409097","pt":1724419382957,"mc":[{"id":"1.232174751","rc":[{"batb":[[0,2.7,4]],"ltp":2.64,"tv":3.02,"id":72857115}]}]}
{"op":"mcm","clk":"11909409302","pt":1724419385377,"mc":[{"id":"1.232174751","rc":[{"batb":[[0,2.7,5]],"ltp":2.64,"tv":3.02,"id":72857115}]}]}
{"op":"mcm","clk":"11909409659","pt":1724419388540,"mc":[{"id":"1.232174751","rc":[{"batb":[[0,2.68,8.17],[1,2.64,27.05],[2,1.99,5.64]],"ltp":2.64,"tv":3.02,"id":72857115}]}]}
{"op":"mcm","clk":"11909409683","pt":1724419388745,"mc":[{"id":"1.232174751","rc":[{"batb":[[0,2.7,4],[1,2.68,8.17],[2,2.64,27.05]],"ltp":2.64,"tv":3.02,"id":72857115}]}]}
{"op":"mcm","clk":"11909409964","pt":1724419391478,"mc":[{"id":"1.232174751","rc":[{"batb":[[0,2.7,5]],"ltp":2.64,"tv":3.02,"id":72857115}]}]}
{"op":"mcm","clk":"11909410358","pt":1724419394860,"mc":[{"id":"1.232174751","rc":[{"batb":[[0,2.7,4]],"ltp":2.64,"tv":3.02,"id":72857115}]}]}
{"op":"mcm","clk":"11909410609","pt":1724419397287,"mc":[{"id":"1.232174751","rc":[{"batb":[[0,2.7,5]],"ltp":2.64,"tv":3.02,"id":72857115}]}]}
{"op":"mcm","clk":"11909411028","pt":1724419400898,"mc":[{"id":"1.232174751","rc":[{"batb":[[0,2.7,4]],"ltp":2.64,"tv":3.02,"id":72857115}]}]}
{"op":"mcm","clk":"11909411325","pt":1724419403491,"mc":[{"id":"1.232174751","rc":[{"batb":[[0,2.7,5]],"ltp":2.64,"tv":3.02,"id":72857115}]}]}
{"op":"mcm","clk":"11909411698","pt":1724419406969,"mc":[{"id":"1.232174751","rc":[{"batb":[[0,2.7,4]],"ltp":2.64,"tv":3.02,"id":72857115}]}]}
{"op":"mcm","clk":"11909411934","pt":1724419409400,"mc":[{"id":"1.232174751","rc":[{"batb":[[0,2.7,5]],"ltp":2.64,"tv":3.02,"id":72857115}]}]}
{"op":"mcm","clk":"11909412240","pt":1724419412614,"mc":[{"id":"1.232174751","rc":[{"batb":[[0,2.68,8.17],[1,2.64,27.05],[2,1.99,5.64]],"ltp":2.64,"tv":3.02,"id":72857115}]}]}
{"op":"mcm","clk":"11909412261","pt":1724419412787,"mc":[{"id":"1.232174751","rc":[{"batb":[[0,2.7,4],[1,2.68,8.17],[2,2.64,27.05]],"ltp":2.64,"tv":3.02,"id":72857115}]}]}
{"op":"mcm","clk":"11909412548","pt":1724419415197,"mc":[{"id":"1.232174751","rc":[{"batb":[[0,2.7,5]],"ltp":2.64,"tv":3.02,"id":72857115}]}]}
{"op":"mcm","clk":"11909412928","pt":1724419418509,"mc":[{"id":"1.232174751","rc":[{"batb":[[0,2.68,8.17],[1,2.64,27.05],[2,1.99,5.64]],"ltp":2.64,"tv":3.02,"id":72857115}]}]}
{"op":"mcm","clk":"11909412951","pt":1724419418714,"mc":[{"id":"1.232174751","rc":[{"batb":[[0,2.7,4],[1,2.68,8.17],[2,2.64,27.05]],"ltp":2.64,"tv":3.02,"id":72857115}]}]}
{"op":"mcm","clk":"11909413225","pt":1724419421509,"mc":[{"id":"1.232174751","rc":[{"batb":[[0,2.7,5]],"ltp":2.64,"tv":3.02,"id":72857115}]}]}
{"op":"mcm","clk":"11909413426","pt":1724419423625,"mc":[{"id":"1.232174751","rc":[{"batb":[[0,2.72,4],[1,2.7,5],[2,2.68,8.17]],"ltp":2.64,"tv":3.02,"id":72857115}]}]}
{"op":"mcm","clk":"11909413559","pt":1724419424916,"mc":[{"id":"1.232174751","rc":[{"batb":[[1,2.68,8.17],[2,2.64,27.05]],"ltp":2.64,"tv":3.02,"id":72857115}]}]}
{"op":"mcm","clk":"11909413681","pt":1724419426216,"mc":[{"id":"1.232174751","rc":[{"batb":[[0,2.68,8.17],[1,2.64,27.05],[2,1.99,5.64]],"ltp":2.64,"tv":3.02,"id":72857115}]}]}
{"op":"mcm","clk":"11909415106","pt":1724419442230,"mc":[{"id":"1.232174751","rc":[{"batb":[[0,2.7,9],[1,2.68,8.17],[2,2.64,27.05]],"ltp":2.64,"tv":3.02,"id":72857115}]}]}
{"op":"mcm","clk":"11909415323","pt":1724419444536,"mc":[{"id":"1.232174751","rc":[{"batb":[[0,2.7,5]],"ltp":2.64,"tv":3.02,"id":72857115}]}]}
{"op":"mcm","clk":"11909415429","pt":1724419445539,"mc":[{"id":"1.232174751","rc":[{"batb":[[0,2.68,8.17],[1,2.64,27.05],[2,1.99,5.64]],"ltp":2.64,"tv":3.02,"id":72857115}]}]}
{"op":"mcm","clk":"11909416050","pt":1724419451324,"mc":[{"id":"1.232174751","rc":[{"batb":[[0,2.7,9],[1,2.68,8.17],[2,2.64,27.05]],"ltp":2.64,"tv":3.02,"id":72857115}]}]}
{"op":"mcm","clk":"11909416335","pt":1724419453958,"mc":[{"id":"1.232174751","rc":[{"batb":[[0,2.7,5]],"ltp":2.64,"tv":3.02,"id":72857115}]}]}
{"op":"mcm","clk":"11909416405","pt":1724419454738,"mc":[{"id":"1.232174751","rc":[{"batb":[[0,2.68,8.17],[1,2.64,27.05],[2,1.99,5.64]],"ltp":2.64,"tv":3.02,"id":72857115}]}]}
{"op":"mcm","clk":"11909416612","pt":1724419457131,"mc":[{"id":"1.232174751","rc":[{"batb":[[0,2.7,9],[1,2.68,8.17],[2,2.64,27.05]],"ltp":2.64,"tv":3.02,"id":72857115}]}]}
{"op":"mcm","clk":"11909416840","pt":1724419459450,"mc":[{"id":"1.232174751","rc":[{"batb":[[0,2.7,5]],"ltp":2.64,"tv":3.02,"id":72857115}]}]}
{"op":"mcm","clk":"11909416936","pt":1724419460443,"mc":[{"id":"1.232174751","rc":[{"batb":[[0,2.68,8.17],[1,2.64,27.05],[2,1.99,5.64]],"ltp":2.64,"tv":3.02,"id":72857115}]}]}
{"op":"mcm","clk":"11909417554","pt":1724419466366,"mc":[{"id":"1.232174751","rc":[{"batb":[[0,2.7,9],[1,2.68,8.17],[2,2.64,27.05]],"ltp":2.64,"tv":3.02,"id":72857115}]}]}
{"op":"mcm","clk":"11909417811","pt":1724419468960,"mc":[{"id":"1.232174751","rc":[{"batb":[[0,2.7,5]],"ltp":2.64,"tv":3.02,"id":72857115}]}]}
{"op":"mcm","clk":"11909417918","pt":1724419469945,"mc":[{"id":"1.232174751","rc":[{"batb":[[0,2.68,8.17],[1,2.64,27.05],[2,1.99,5.64]],"ltp":2.64,"tv":3.02,"id":72857115}]}]}
{"op":"mcm","clk":"11909418163","pt":1724419472170,"mc":[{"id":"1.232174751","rc":[{"batb":[[0,2.72,5],[1,2.7,4],[2,2.68,8.17]],"ltp":2.64,"tv":3.02,"id":72857115}]}]}
{"op":"mcm","clk":"11909418391","pt":1724419474249,"mc":[{"id":"1.232174751","rc":[{"batb":[[1,2.68,8.17],[2,2.64,27.05]],"ltp":2.64,"tv":3.02,"id":72857115}]}]}
{"op":"mcm","clk":"11909418530","pt":1724419475443,"mc":[{"id":"1.232174751","rc":[{"batb":[[0,2.68,8.17],[1,2.64,27.05],[2,1.99,5.64]],"ltp":2.64,"tv":3.02,"id":72857115}]}]}
{"op":"mcm","clk":"11909419820","pt":1724419487862,"mc":[{"id":"1.232174751","rc":[{"batb":[[0,2.7,9],[1,2.68,8.17],[2,2.64,27.05]],"ltp":2.64,"tv":3.02,"id":72857115}]}]}
{"op":"mcm","clk":"11909420084","pt":1724419490593,"mc":[{"id":"1.232174751","rc":[{"batb":[[0,2.7,5]],"ltp":2.64,"tv":3.02,"id":72857115}]}]}
{"op":"mcm","clk":"11909420153","pt":1724419491486,"mc":[{"id":"1.232174751","rc":[{"batb":[[0,2.68,8.17],[1,2.64,27.05],[2,1.99,5.64]],"ltp":2.64,"tv":3.02,"id":72857115}]}]}
{"op":"mcm","clk":"11909420360","pt":1724419493969,"mc":[{"id":"1.232174751","rc":[{"batb":[[0,2.7,9],[1,2.68,8.17],[2,2.64,27.05]],"ltp":2.64,"tv":3.02,"id":72857115}]}]}
{"op":"mcm","clk":"11909420581","pt":1724419496298,"mc":[{"id":"1.232174751","rc":[{"batb":[[0,2.7,5]],"ltp":2.64,"tv":3.02,"id":72857115}]}]}
{"op":"mcm","clk":"11909420673","pt":1724419497393,"mc":[{"id":"1.232174751","rc":[{"batb":[[0,2.68,8.17],[1,2.64,27.05],[2,1.99,5.64]],"ltp":2.64,"tv":3.02,"id":72857115}]}]}
{"op":"mcm","clk":"11909421098","pt":1724419501694,"mc":[{"id":"1.232174751","rc":[{"batb":[[0,2.7,9],[1,2.68,8.17],[2,2.64,27.05]],"ltp":2.64,"tv":3.02,"id":72857115}]}]}
{"op":"mcm","clk":"11909421359","pt":1724419503987,"mc":[{"id":"1.232174751","rc":[{"batb":[[0,2.7,5]],"ltp":2.64,"tv":3.02,"id":72857115}]}]}
{"op":"mcm","clk":"11909421460","pt":1724419504808,"mc":[{"id":"1.232174751","rc":[{"batb":[[0,2.68,8.17],[1,2.64,27.05],[2,1.99,5.64]],"ltp":2.64,"tv":3.02,"id":72857115}]}]}
{"op":"mcm","clk":"11909422354","pt":1724419513988,"mc":[{"id":"1.232174751","rc":[{"batb":[[0,2.7,9],[1,2.68,8.17],[2,2.64,27.05]],"ltp":2.64,"tv":3.02,"id":72857115}]}]}
{"op":"mcm","clk":"11909422623","pt":1724419516625,"mc":[{"id":"1.232174751","rc":[{"batb":[[0,2.7,5]],"ltp":2.64,"tv":3.02,"id":72857115}]}]}
{"op":"mcm","clk":"11909422720","pt":1724419517504,"mc":[{"id":"1.232174751","rc":[{"batb":[[0,2.68,8.17],[1,2.64,27.05],[2,1.99,5.64]],"ltp":2.64,"tv":3.02,"id":72857115}]}]}
{"op":"mcm","clk":"11909425801","pt":1724419552163,"mc":[{"id":"1.232174751","rc":[{"batb":[[0,2.7,9],[1,2.68,8.17],[2,2.64,27.05]],"ltp":2.64,"tv":3.02,"id":72857115}]}]}
{"op":"mcm","clk":"11909426049","pt":1724419554754,"mc":[{"id":"1.232174751","rc":[{"batb":[[0,2.7,5]],"ltp":2.64,"tv":3.02,"id":72857115}]}]}
{"op":"mcm","clk":"11909426127","pt":1724419555667,"mc":[{"id":"1.232174751","rc":[{"batb":[[0,2.68,8.17],[1,2.64,27.05],[2,1.99,5.64]],"ltp":2.64,"tv":3.02,"id":72857115}]}]}
{"op":"mcm","clk":"11909426408","pt":1724419559267,"mc":[{"id":"1.232174751","rc":[{"batb":[[0,2.7,9],[1,2.68,8.17],[2,2.64,27.05]],"ltp":2.64,"tv":3.02,"id":72857115}]}]}
{"op":"mcm","clk":"11909426691","pt":1724419561976,"mc":[{"id":"1.232174751","rc":[{"batb":[[0,2.7,5]],"ltp":2.64,"tv":3.02,"id":72857115}]}]}
{"op":"mcm","clk":"11909426749","pt":1724419562684,"mc":[{"id":"1.232174751","rc":[{"batb":[[0,2.68,8.17],[1,2.64,27.05],[2,1.99,5.64]],"ltp":2.64,"tv":3.02,"id":72857115}]}]}
{"op":"mcm","clk":"11909427296","pt":1724419568361,"mc":[{"id":"1.232174751","rc":[{"batb":[[0,2.7,9],[1,2.68,8.17],[2,2.64,27.05]],"ltp":2.64,"tv":3.02,"id":72857115}]}]}
{"op":"mcm","clk":"11909427529","pt":1724419570785,"mc":[{"id":"1.232174751","rc":[{"batb":[[0,2.7,5]],"ltp":2.64,"tv":3.02,"id":72857115}]}]}
{"op":"mcm","clk":"11909427613","pt":1724419571665,"mc":[{"id":"1.232174751","rc":[{"batb":[[0,2.68,8.17],[1,2.64,27.05],[2,1.99,5.64]],"ltp":2.64,"tv":3.02,"id":72857115}]}]}
{"op":"mcm","clk":"11909429043","pt":1724419586134,"mc":[{"id":"1.232174751","rc":[{"batb":[[0,2.7,9],[1,2.68,8.17],[2,2.64,27.05]],"ltp":2.64,"tv":3.02,"id":72857115}]}]}
{"op":"mcm","clk":"11909429391","pt":1724419589570,"mc":[{"id":"1.232174751","rc":[{"batb":[[0,2.68,8.17],[1,2.64,27.05],[2,1.99,5.64]],"ltp":2.64,"tv":3.02,"id":72857115}]}]}
{"op":"mcm","clk":"11909429873","pt":1724419595098,"mc":[{"id":"1.232174751","rc":[{"batb":[[0,2.7,9],[1,2.68,8.17],[2,2.64,27.05]],"ltp":2.64,"tv":3.02,"id":72857115}]}]}
{"op":"mcm","clk":"11909430093","pt":1724419597474,"mc":[{"id":"1.232174751","rc":[{"batb":[[0,2.7,5]],"ltp":2.64,"tv":3.02,"id":72857115}]}]}
{"op":"mcm","clk":"11909430181","pt":1724419598503,"mc":[{"id":"1.232174751","rc":[{"batb":[[0,2.68,8.17],[1,2.64,27.05],[2,1.99,5.64]],"ltp":2.64,"tv":3.02,"id":72857115}]}]}
{"op":"mcm","clk":"11909430838","pt":1724419606109,"mc":[{"id":"1.232174751","rc":[{"batb":[[0,2.7,9],[1,2.68,8.17],[2,2.64,27.05]],"ltp":2.64,"tv":3.02,"id":72857115}]}]}
{"op":"mcm","clk":"11909431037","pt":1724419608393,"mc":[{"id":"1.232174751","rc":[{"batb":[[0,2.7,5]],"ltp":2.64,"tv":3.02,"id":72857115}]}]}
{"op":"mcm","clk":"11909431112","pt":1724419609419,"mc":[{"id":"1.232174751","rc":[{"batb":[[0,2.68,8.17],[1,2.64,27.05],[2,1.99,5.64]],"ltp":2.64,"tv":3.02,"id":72857115}]}]}
{"op":"mcm","clk":"11909431871","pt":1724419618426,"mc":[{"id":"1.232174751","rc":[{"batb":[[0,2.7,9],[1,2.68,8.17],[2,2.64,27.05]],"ltp":2.64,"tv":3.02,"id":72857115}]}]}
{"op":"mcm","clk":"11909432109","pt":1724419621008,"mc":[{"id":"1.232174751","rc":[{"batb":[[0,2.7,5]],"ltp":2.64,"tv":3.02,"id":72857115}]}]}
{"op":"mcm","clk":"11909432196","pt":1724419621946,"mc":[{"id":"1.232174751","rc":[{"batb":[[0,2.68,8.17],[1,2.64,27.05],[2,1.99,5.64]],"ltp":2.64,"tv":3.02,"id":72857115}]}]}
{"op":"mcm","clk":"11909432511","pt":1724419625118,"mc":[{"id":"1.232174751","rc":[{"batb":[[0,2.7,9],[1,2.68,8.17],[2,2.64,27.05]],"ltp":2.64,"tv":3.02,"id":72857115}]}]}
{"op":"mcm","clk":"11909432717","pt":1724419627337,"mc":[{"id":"1.232174751","rc":[{"batb":[[0,2.7,5]],"ltp":2.64,"tv":3.02,"id":72857115}]}]}
{"op":"mcm","clk":"11909432827","pt":1724419628629,"mc":[{"id":"1.232174751","rc":[{"batb":[[0,2.68,8.17],[1,2.64,27.05],[2,1.99,5.64]],"ltp":2.64,"tv":3.02,"id":72857115}]}]}
{"op":"mcm","clk":"11909434189","pt":1724419641935,"mc":[{"id":"1.232174751","rc":[{"batb":[[0,2.7,9],[1,2.68,8.17],[2,2.64,27.05]],"ltp":2.64,"tv":3.02,"id":72857115}]}]}
{"op":"mcm","clk":"11909434414","pt":1724419644461,"mc":[{"id":"1.232174751","rc":[{"batb":[[0,2.7,5]],"ltp":2.64,"tv":3.02,"id":72857115}]}]}
{"op":"mcm","clk":"11909434486","pt":1724419645445,"mc":[{"id":"1.232174751","rc":[{"batb":[[0,2.68,8.17],[1,2.64,27.05],[2,1.99,5.64]],"ltp":2.64,"tv":3.02,"id":72857115}]}]}
{"op":"mcm","clk":"11909435147","pt":1724419652682,"mc":[{"id":"1.232174751","rc":[{"batb":[[0,2.7,9],[1,2.68,8.17],[2,2.64,27.05]],"ltp":2.64,"tv":3.02,"id":72857115}]}]}
{"op":"mcm","clk":"11909435355","pt":1724419654954,"mc":[{"id":"1.232174751","rc":[{"batb":[[0,2.7,5]],"ltp":2.64,"tv":3.02,"id":72857115}]}]}
{"op":"mcm","clk":"11909435442","pt":1724419655984,"mc":[{"id":"1.232174751","rc":[{"batb":[[0,2.68,8.17],[1,2.64,27.05],[2,1.99,5.64]],"ltp":2.64,"tv":3.02,"id":72857115}]}]}
{"op":"mcm","clk":"11909436501","pt":1724419666803,"mc":[{"id":"1.232174751","rc":[{"batb":[[0,2.7,9],[1,2.68,8.17],[2,2.64,27.05]],"ltp":2.64,"tv":3.02,"id":72857115}]}]}
{"op":"mcm","clk":"11909436744","pt":1724419669285,"mc":[{"id":"1.232174751","rc":[{"batb":[[0,2.7,5]],"ltp":2.64,"tv":3.02,"id":72857115}]}]}
{"op":"mcm","clk":"11909436836","pt":1724419670162,"mc":[{"id":"1.232174751","rc":[{"batb":[[0,2.68,8.17],[1,2.64,27.05],[2,1.99,5.64]],"ltp":2.64,"tv":3.02,"id":72857115}]}]}
{"op":"mcm","clk":"11909437520","pt":1724419677590,"mc":[{"id":"1.232174751","rc":[{"batb":[[0,2.7,9],[1,2.68,8.17],[2,2.64,27.05]],"ltp":2.64,"tv":3.02,"id":72857115}]}]}
{"op":"mcm","clk":"11909437736","pt":1724419680106,"mc":[{"id":"1.232174751","rc":[{"batb":[[0,2.7,5]],"ltp":2.64,"tv":3.02,"id":72857115}]}]}
{"op":"mcm","clk":"11909437821","pt":1724419681112,"mc":[{"id":"1.232174751","rc":[{"batb":[[0,2.68,8.17],[1,2.64,27.05],[2,1.99,5.64]],"ltp":2.64,"tv":3.02,"id":72857115}]}]}
{"op":"mcm","clk":"11909438122","pt":1724419684577,"mc":[{"id":"1.232174751","rc":[{"batb":[[0,2.7,9],[1,2.68,8.17],[2,2.64,27.05]],"ltp":2.64,"tv":3.02,"id":72857115}]}]}
{"op":"mcm","clk":"11909438371","pt":1724419687109,"mc":[{"id":"1.232174751","rc":[{"batb":[[0,2.7,5]],"ltp":2.64,"tv":3.02,"id":72857115}]}]}
{"op":"mcm","clk":"11909438472","pt":1724419688190,"mc":[{"id":"1.232174751","rc":[{"batb":[[0,2.68,8.17],[1,2.64,27.05],[2,1.99,5.64]],"ltp":2.64,"tv":3.02,"id":72857115}]}]}
{"op":"mcm","clk":"11909439274","pt":1724419696505,"mc":[{"id":"1.232174751","rc":[{"batb":[[0,2.7,9],[1,2.68,8.17],[2,2.64,27.05]],"ltp":2.64,"tv":3.02,"id":72857115}]}]}
{"op":"mcm","clk":"11909439522","pt":1724419698994,"mc":[{"id":"1.232174751","rc":[{"batb":[[0,2.7,5]],"ltp":2.64,"tv":3.02,"id":72857115}]}]}
{"op":"mcm","clk":"11909439637","pt":1724419700025,"mc":[{"id":"1.232174751","rc":[{"batb":[[0,2.68,8.17],[1,2.64,27.05],[2,1.99,5.64]],"ltp":2.64,"tv":3.02,"id":72857115}]}]}
{"op":"mcm","clk":"11909440362","pt":1724419707306,"mc":[{"id":"1.232174751","rc":[{"batb":[[0,2.7,9],[1,2.68,8.17],[2,2.64,27.05]],"ltp":2.64,"tv":3.02,"id":72857115}]}]}
{"op":"mcm","clk":"11909440597","pt":1724419709643,"mc":[{"id":"1.232174751","rc":[{"batb":[[0,2.7,5]],"ltp":2.64,"tv":3.02,"id":72857115}]}]}
{"op":"mcm","clk":"11909440713","pt":1724419710836,"mc":[{"id":"1.232174751","rc":[{"batb":[[0,2.68,8.17],[1,2.64,27.05],[2,1.99,5.64]],"ltp":2.64,"tv":3.02,"id":72857115}]}]}
{"op":"mcm","clk":"11909440940","pt":1724419713109,"mc":[{"id":"1.232174751","rc":[{"batb":[[0,2.72,5],[1,2.7,4],[2,2.68,8.17]],"ltp":2.64,"tv":3.02,"id":72857115}]}]}
{"op":"mcm","clk":"11909441175","pt":1724419715233,"mc":[{"id":"1.232174751","rc":[{"batb":[[1,2.68,8.17],[2,2.64,27.05]],"ltp":2.64,"tv":3.02,"id":72857115}]}]}
{"op":"mcm","clk":"11909441312","pt":1724419716326,"mc":[{"id":"1.232174751","rc":[{"batb":[[0,2.68,8.17],[1,2.64,27.05],[2,1.99,5.64]],"ltp":2.64,"tv":3.02,"id":72857115}]}]}
{"op":"mcm","clk":"11909441453","pt":1724419717621,"mc":[{"id":"1.232174751","rc":[{"batb":[[0,2.7,4],[1,2.68,8.17],[2,2.64,27.05]],"ltp":2.64,"tv":3.02,"id":72857115}]}]}
{"op":"mcm","clk":"11909441738","pt":1724419720316,"mc":[{"id":"1.232174751","rc":[{"batb":[[0,2.7,5]],"ltp":2.64,"tv":3.02,"id":72857115}]}]}
{"op":"mcm","clk":"11909442059","pt":1724419723627,"mc":[{"id":"1.232174751","rc":[{"batb":[[0,2.7,4]],"ltp":2.64,"tv":3.02,"id":72857115}]}]}
{"op":"mcm","clk":"11909442292","pt":1724419726058,"mc":[{"id":"1.232174751","rc":[{"batb":[[0,2.7,5]],"ltp":2.64,"tv":3.02,"id":72857115}]}]}
{"op":"mcm","clk":"11909442626","pt":1724419729441,"mc":[{"id":"1.232174751","rc":[{"batb":[[0,2.72,4]],"ltp":2.64,"tv":3.02,"id":72857115}]}]}
{"op":"mcm","clk":"11909442851","pt":1724419731773,"mc":[{"id":"1.232174751","rc":[{"batb":[[0,2.74,5]],"ltp":2.64,"tv":3.02,"id":72857115}]}]}
{"op":"mcm","clk":"11909443103","pt":1724419734268,"mc":[{"id":"1.232174751","rc":[{"batb":[[0,2.76,4],[1,2.74,5],[2,2.68,8.17]],"ltp":2.64,"tv":3.02,"id":72857115}]}]}
{"op":"mcm","clk":"11909443201","pt":1724419735155,"mc":[{"id":"1.232174751","rc":[{"batb":[[1,2.68,8.17],[2,2.64,27.05]],"ltp":2.64,"tv":3.02,"id":72857115},{"batl":[[0,1.6,276.92],[1,1.61,25.65],[2,2.5,1]],"ltp":1.56,"tv":154.76,"id":72857116}]}]}
{"op":"mcm","clk":"11909443313","pt":1724419736559,"mc":[{"id":"1.232174751","rc":[{"batb":[[0,2.68,8.17],[1,2.64,27.05],[2,1.99,5.64]],"ltp":2.64,"tv":3.02,"id":72857115}]}]}
{"op":"mcm","clk":"11909443671","pt":1724419739886,"mc":[{"id":"1.232174751","rc":[{"batb":[[0,2.7,9],[1,2.68,8.17],[2,2.64,27.05]],"ltp":2.64,"tv":3.02,"id":72857115}]}]}
{"op":"mcm","clk":"11909443931","pt":1724419742355,"mc":[{"id":"1.232174751","rc":[{"batb":[[0,2.7,5]],"ltp":2.64,"tv":3.02,"id":72857115}]}]}
{"op":"mcm","clk":"11909444025","pt":1724419743388,"mc":[{"id":"1.232174751","rc":[{"batb":[[0,2.68,8.17],[1,2.64,27.05],[2,1.99,5.64]],"ltp":2.64,"tv":3.02,"id":72857115}]}]}
{"op":"mcm","clk":"11909445049","pt":1724419753360,"mc":[{"id":"1.232174751","rc":[{"batb":[[0,2.7,9],[1,2.68,8.17],[2,2.64,27.05]],"ltp":2.64,"tv":3.02,"id":72857115},{"batl":[[0,1.59,14.27],[1,1.6,276.92],[2,1.61,25.65]],"ltp":1.56,"tv":154.76,"id":72857116}]}]}
{"op":"mcm","clk":"11909445270","pt":1724419755561,"mc":[{"id":"1.232174751","rc":[{"batb":[[0,2.7,5]],"ltp":2.64,"tv":3.02,"id":72857115}]}]}
{"op":"mcm","clk":"11909445356","pt":1724419756491,"mc":[{"id":"1.232174751","rc":[{"batb":[[0,2.68,8.17],[1,2.64,27.05],[2,1.99,5.64]],"ltp":2.64,"tv":3.02,"id":72857115}]}]}
{"op":"mcm","clk":"11909445614","pt":1724419759165,"mc":[{"id":"1.232174751","rc":[{"batb":[[0,2.7,9],[1,2.68,8.17],[2,2.64,27.05]],"ltp":2.64,"tv":3.02,"id":72857115}]}]}
{"op":"mcm","clk":"11909445893","pt":1724419761608,"mc":[{"id":"1.232174751","rc":[{"batb":[[0,2.7,5]],"ltp":2.64,"tv":3.02,"id":72857115}]}]}
{"op":"mcm","clk":"11909445982","pt":1724419762587,"mc":[{"id":"1.232174751","rc":[{"batb":[[0,2.68,8.17],[1,2.64,27.05],[2,1.99,5.64]],"ltp":2.64,"tv":3.02,"id":72857115}]}]}
{"op":"mcm","clk":"11909446972","pt":1724419772508,"mc":[{"id":"1.232174751","rc":[{"batb":[[0,2.7,9],[1,2.68,8.17],[2,2.64,27.05]],"ltp":2.64,"tv":3.02,"id":72857115}]}]}
{"op":"mcm","clk":"11909447212","pt":1724419774794,"mc":[{"id":"1.232174751","rc":[{"batb":[[0,2.7,5]],"ltp":2.64,"tv":3.02,"id":72857115}]}]}
{"op":"mcm","clk":"11909447342","pt":1724419776087,"mc":[{"id":"1.232174751","rc":[{"batb":[[0,2.68,8.17],[1,2.64,27.05],[2,1.99,5.64]],"ltp":2.64,"tv":3.02,"id":72857115}]}]}
{"op":"mcm","clk":"11909447607","pt":1724419778574,"mc":[{"id":"1.232174751","rc":[{"batb":[[0,2.7,9],[1,2.68,8.17],[2,2.64,27.05]],"ltp":2.64,"tv":3.02,"id":72857115}]}]}
{"op":"mcm","clk":"11909447864","pt":1724419780910,"mc":[{"id":"1.232174751","rc":[{"batb":[[0,2.7,5]],"ltp":2.64,"tv":3.02,"id":72857115}]}]}
{"op":"mcm","clk":"11909447961","pt":1724419782001,"mc":[{"id":"1.232174751","rc":[{"batb":[[0,2.68,8.17],[1,2.64,27.05],[2,1.99,5.64]],"ltp":2.64,"tv":3.02,"id":72857115}]}]}
{"op":"mcm","clk":"11909450653","pt":1724419806030,"mc":[{"id":"1.232174751","rc":[{"batb":[[0,2.7,9],[1,2.68,8.17],[2,2.64,27.05]],"ltp":2.64,"tv":3.02,"id":72857115}]}]}
{"op":"mcm","clk":"11909450926","pt":1724419808722,"mc":[{"id":"1.232174751","rc":[{"batb":[[0,2.7,5]],"ltp":2.64,"tv":3.02,"id":72857115}]}]}
{"op":"mcm","clk":"11909451027","pt":1724419809650,"mc":[{"id":"1.232174751","rc":[{"batb":[[0,2.68,8.17],[1,2.64,27.05],[2,1.99,5.64]],"ltp":2.64,"tv":3.02,"id":72857115}]}]}
{"op":"mcm","clk":"11909452728","pt":1724419824856,"mc":[{"id":"1.232174751","rc":[{"batb":[[0,2.7,9],[1,2.68,8.17],[2,2.64,27.05]],"ltp":2.64,"tv":3.02,"id":72857115}]}]}
{"op":"mcm","clk":"11909453023","pt":1724419827346,"mc":[{"id":"1.232174751","rc":[{"batb":[[0,2.7,5]],"ltp":2.64,"tv":3.02,"id":72857115}]}]}
{"op":"mcm","clk":"11909453133","pt":1724419828336,"mc":[{"id":"1.232174751","rc":[{"batb":[[0,2.68,8.17],[1,2.64,27.05],[2,1.99,5.64]],"ltp":2.64,"tv":3.02,"id":72857115}]}]}
{"op":"mcm","clk":"11909453291","pt":1724419829635,"mc":[{"id":"1.232174751","rc":[{"batb":[[0,2.7,4],[1,2.68,8.17],[2,2.64,27.05]],"ltp":2.64,"tv":3.02,"id":72857115}]}]}
{"op":"mcm","clk":"11909453564","pt":1724419831972,"mc":[{"id":"1.232174751","rc":[{"batb":[[0,2.72,5]],"ltp":2.64,"tv":3.02,"id":72857115}]}]}
{"op":"mcm","clk":"11909453885","pt":1724419835076,"mc":[{"id":"1.232174751","rc":[{"batb":[[0,2.7,4]],"ltp":2.64,"tv":3.02,"id":72857115}]}]}
{"op":"mcm","clk":"11909454145","pt":1724419837360,"mc":[{"id":"1.232174751","rc":[{"batb":[[0,2.7,5]],"ltp":2.64,"tv":3.02,"id":72857115}]}]}
{"op":"mcm","clk":"11909454482","pt":1724419840579,"mc":[{"id":"1.232174751","rc":[{"batb":[[0,2.68,8.17],[1,2.64,27.05],[2,1.99,5.64]],"ltp":2.64,"tv":3.02,"id":72857115}]}]}
{"op":"mcm","clk":"11909454506","pt":1724419840783,"mc":[{"id":"1.232174751","rc":[{"batb":[[0,2.7,4],[1,2.68,8.17],[2,2.64,27.05]],"ltp":2.64,"tv":3.02,"id":72857115}]}]}
{"op":"mcm","clk":"11909454774","pt":1724419843069,"mc":[{"id":"1.232174751","rc":[{"batb":[[0,2.72,5]],"ltp":2.64,"tv":3.02,"id":72857115}]}]}
{"op":"mcm","clk":"11909455181","pt":1724419846573,"mc":[{"id":"1.232174751","rc":[{"batb":[[0,2.7,4]],"ltp":2.64,"tv":3.02,"id":72857115}]}]}
{"op":"mcm","clk":"11909455446","pt":1724419848773,"mc":[{"id":"1.232174751","rc":[{"batb":[[0,2.72,5]],"ltp":2.64,"tv":3.02,"id":72857115}]}]}
{"op":"mcm","clk":"11909455810","pt":1724419852091,"mc":[{"id":"1.232174751","rc":[{"batb":[[0,2.7,4]],"ltp":2.64,"tv":3.02,"id":72857115}]}]}
{"op":"mcm","clk":"11909456063","pt":1724419854477,"mc":[{"id":"1.232174751","rc":[{"batb":[[0,2.68,8.17],[1,2.64,27.05],[2,1.99,5.64]],"ltp":2.64,"tv":3.02,"id":72857115}]}]}
{"op":"mcm","clk":"11909456085","pt":1724419854684,"mc":[{"id":"1.232174751","rc":[{"batb":[[0,2.7,5],[1,2.68,8.17],[2,2.64,27.05]],"ltp":2.64,"tv":3.02,"id":72857115}]}]}
{"op":"mcm","clk":"11909456433","pt":1724419858078,"mc":[{"id":"1.232174751","rc":[{"batb":[[0,2.7,4]],"ltp":2.64,"tv":3.02,"id":72857115}]}]}
{"op":"mcm","clk":"11909456675","pt":1724419860476,"mc":[{"id":"1.232174751","rc":[{"batb":[[0,2.7,5]],"ltp":2.64,"tv":3.02,"id":72857115}]}]}
{"op":"mcm","clk":"11909457032","pt":1724419864103,"mc":[{"id":"1.232174751","rc":[{"batb":[[0,2.7,4]],"ltp":2.64,"tv":3.02,"id":72857115}]}]}
{"op":"mcm","clk":"11909457256","pt":1724419866397,"mc":[{"id":"1.232174751","rc":[{"batb":[[0,2.7,5]],"ltp":2.64,"tv":3.02,"id":72857115}]}]}
{"op":"mcm","clk":"11909457603","pt":1724419869584,"mc":[{"id":"1.232174751","rc":[{"batb":[[0,2.68,8.17],[1,2.64,27.05],[2,1.99,5.64]],"ltp":2.64,"tv":3.02,"id":72857115}]}]}
{"op":"mcm","clk":"11909457614","pt":1724419869684,"mc":[{"id":"1.232174751","rc":[{"batb":[[0,2.7,4],[1,2.68,8.17],[2,2.64,27.05]],"ltp":2.64,"tv":3.02,"id":72857115}]}]}
{"op":"mcm","clk":"11909457851","pt":1724419872117,"mc":[{"id":"1.232174751","rc":[{"batb":[[0,2.7,5]],"ltp":2.64,"tv":3.02,"id":72857115}]}]}
{"op":"mcm","clk":"11909458196","pt":1724419875399,"mc":[{"id":"1.232174751","rc":[{"batb":[[0,2.72,4]],"ltp":2.64,"tv":3.02,"id":72857115}]}]}
{"op":"mcm","clk":"11909458444","pt":1724419877617,"mc":[{"id":"1.232174751","rc":[{"batb":[[0,2.68,8.17],[1,2.64,27.05],[2,1.99,5.64]],"ltp":2.64,"tv":3.02,"id":72857115}]}]}
{"op":"mcm","clk":"11909458480","pt":1724419877829,"mc":[{"id":"1.232174751","rc":[{"batb":[[0,2.7,5],[1,2.68,8.17],[2,2.64,27.05]],"ltp":2.64,"tv":3.02,"id":72857115}]}]}
{"op":"mcm","clk":"11909458898","pt":1724419881260,"mc":[{"id":"1.232174751","rc":[{"batb":[[0,2.7,4]],"ltp":2.64,"tv":3.02,"id":72857115}]}]}
{"op":"mcm","clk":"11909459164","pt":1724419883633,"mc":[{"id":"1.232174751","rc":[{"batb":[[0,2.7,5]],"ltp":2.64,"tv":3.02,"id":72857115}]}]}
{"op":"mcm","clk":"11909459535","pt":1724419887168,"mc":[{"id":"1.232174751","rc":[{"batb":[[0,2.72,4]],"ltp":2.64,"tv":3.02,"id":72857115}]}]}
{"op":"mcm","clk":"11909459805","pt":1724419889553,"mc":[{"id":"1.232174751","rc":[{"batb":[[0,2.7,5]],"ltp":2.64,"tv":3.02,"id":72857115}]}]}
{"op":"mcm","clk":"11909460028","pt":1724419891582,"mc":[{"id":"1.232174751","rc":[{"batb":[[0,2.72,4],[1,2.7,5],[2,2.68,8.17]],"ltp":2.64,"tv":3.02,"id":72857115}]}]}
{"op":"mcm","clk":"11909460146","pt":1724419892870,"mc":[{"id":"1.232174751","rc":[{"batb":[[1,2.68,8.17],[2,2.64,27.05]],"ltp":2.64,"tv":3.02,"id":72857115}]}]}
{"op":"mcm","clk":"11909460240","pt":1724419893749,"mc":[{"id":"1.232174751","rc":[{"batb":[[0,2.68,8.17],[1,2.64,27.05],[2,1.99,5.64]],"ltp":2.64,"tv":3.02,"id":72857115}]}]}
{"op":"mcm","clk":"11909460413","pt":1724419895361,"mc":[{"id":"1.232174751","rc":[{"batb":[[0,2.7,5],[1,2.68,8.17],[2,2.64,27.05]],"ltp":2.64,"tv":3.02,"id":72857115}]}]}
{"op":"mcm","clk":"11909460678","pt":1724419897547,"mc":[{"id":"1.232174751","rc":[{"batb":[[0,2.72,4],[1,2.7,5],[2,2.68,8.17]],"ltp":2.64,"tv":3.02,"id":72857115}]}]}
{"op":"mcm","clk":"11909460791","pt":1724419898584,"mc":[{"id":"1.232174751","rc":[{"batb":[[1,2.68,8.17],[2,2.64,27.05]],"ltp":2.64,"tv":3.02,"id":72857115}]}]}
{"op":"mcm","clk":"11909460947","pt":1724419899657,"mc":[{"id":"1.232174751","rc":[{"batb":[[0,2.68,8.17],[1,2.64,27.05],[2,1.99,5.64]],"ltp":2.64,"tv":3.02,"id":72857115}]}]}
{"op":"mcm","clk":"11909461287","pt":1724419902567,"mc":[{"id":"1.232174751","rc":[{"batb":[[0,2.7,9],[1,2.68,8.17],[2,2.64,27.05]],"ltp":2.64,"tv":3.02,"id":72857115}]}]}
{"op":"mcm","clk":"11909461587","pt":1724419905173,"mc":[{"id":"1.232174751","rc":[{"batb":[[0,2.7,5]],"ltp":2.64,"tv":3.02,"id":72857115}]}]}
{"op":"mcm","clk":"11909461719","pt":1724419906268,"mc":[{"id":"1.232174751","rc":[{"batb":[[0,2.68,8.17],[1,2.64,27.05],[2,1.99,5.64]],"ltp":2.64,"tv":3.02,"id":72857115}]}]}
{"op":"mcm","clk":"11909462319","pt":1724419911569,"mc":[{"id":"1.232174751","rc":[{"batb":[[0,2.7,9],[1,2.68,8.17],[2,2.64,27.05]],"ltp":2.64,"tv":3.02,"id":72857115}]}]}
{"op":"mcm","clk":"11909462628","pt":1724419914167,"mc":[{"id":"1.232174751","rc":[{"batb":[[0,2.7,5]],"ltp":2.64,"tv":3.02,"id":72857115}]}]}
{"op":"mcm","clk":"11909462747","pt":1724419915054,"mc":[{"id":"1.232174751","rc":[{"batb":[[0,2.68,8.17],[1,2.64,27.05],[2,1.99,5.64]],"ltp":2.64,"tv":3.02,"id":72857115}]}]}
{"op":"mcm","clk":"11909462990","pt":1724419917278,"mc":[{"id":"1.232174751","rc":[{"batb":[[0,2.72,5],[1,2.7,4],[2,2.68,8.17]],"ltp":2.64,"tv":3.02,"id":72857115}]}]}
{"op":"mcm","clk":"11909463199","pt":1724419919396,"mc":[{"id":"1.232174751","rc":[{"batb":[[1,2.68,8.17],[2,2.64,27.05]],"ltp":2.64,"tv":3.02,"id":72857115}]}]}
{"op":"mcm","clk":"11909463353","pt":1724419920598,"mc":[{"id":"1.232174751","rc":[{"batb":[[0,2.68,8.17],[1,2.64,27.05],[2,1.99,5.64]],"ltp":2.64,"tv":3.02,"id":72857115}]}]}
{"op":"mcm","clk":"11909464087","pt":1724419927104,"mc":[{"id":"1.232174751","rc":[{"batb":[[0,2.7,9],[1,2.68,8.17],[2,2.64,27.05]],"ltp":2.64,"tv":3.02,"id":72857115}]}]}
{"op":"mcm","clk":"11909464371","pt":1724419929819,"mc":[{"id":"1.232174751","rc":[{"batb":[[0,2.7,5]],"ltp":2.64,"tv":3.02,"id":72857115}]}]}
{"op":"mcm","clk":"11909464477","pt":1724419930694,"mc":[{"id":"1.232174751","rc":[{"batb":[[0,2.68,8.17],[1,2.64,27.05],[2,1.99,5.64]],"ltp":2.64,"tv":3.02,"id":72857115}]}]}
{"op":"mcm","clk":"11909464835","pt":1724419934117,"mc":[{"id":"1.232174751","rc":[{"batb":[[0,2.7,9],[1,2.68,8.17],[2,2.64,27.05]],"ltp":2.64,"tv":3.02,"id":72857115}]}]}
{"op":"mcm","clk":"11909465139","pt":1724419936710,"mc":[{"id":"1.232174751","rc":[{"batb":[[0,2.7,5]],"ltp":2.64,"tv":3.02,"id":72857115}]}]}
{"op":"mcm","clk":"11909465260","pt":1724419937698,"mc":[{"id":"1.232174751","rc":[{"batb":[[0,2.68,8.17],[1,2.64,27.05],[2,1.99,5.64]],"ltp":2.64,"tv":3.02,"id":72857115}]}]}
{"op":"mcm","clk":"11909465512","pt":1724419939513,"mc":[{"id":"1.232174751","rc":[{"batb":[[0,2.7,4],[1,2.68,8.17],[2,2.64,27.05]],"ltp":2.64,"tv":3.02,"id":72857115}]}]}
{"op":"mcm","clk":"11909465744","pt":1724419941835,"mc":[{"id":"1.232174751","rc":[{"batb":[[0,2.7,5]],"ltp":2.64,"tv":3.02,"id":72857115}]}]}
{"op":"mcm","clk":"11909465988","pt":1724419944537,"mc":[{"id":"1.232174751","rc":[{"batb":[[0,2.72,4],[1,2.7,5],[2,2.68,8.17]],"ltp":2.64,"tv":3.02,"id":72857115}]}]}
{"op":"mcm","clk":"11909466046","pt":1724419945052,"mc":[{"id":"1.232174751","rc":[{"batb":[[1,2.68,8.17],[2,2.64,27.05]],"ltp":2.64,"tv":3.02,"id":72857115}]}]}
{"op":"mcm","clk":"11909466195","pt":1724419946751,"mc":[{"id":"1.232174751","rc":[{"batb":[[0,2.68,8.17],[1,2.64,27.05],[2,1.99,5.64]],"ltp":2.64,"tv":3.02,"id":72857115}]}]}
{"op":"mcm","clk":"11909466536","pt":1724419950017,"mc":[{"id":"1.232174751","rc":[{"batb":[[0,2.7,9],[1,2.68,8.17],[2,2.64,27.05]],"ltp":2.64,"tv":3.02,"id":72857115}]}]}
{"op":"mcm","clk":"11909466802","pt":1724419952349,"mc":[{"id":"1.232174751","rc":[{"batb":[[0,2.7,5]],"ltp":2.64,"tv":3.02,"id":72857115}]}]}
{"op":"mcm","clk":"11909466902","pt":1724419953340,"mc":[{"id":"1.232174751","rc":[{"batb":[[0,2.68,8.17],[1,2.64,27.05],[2,1.99,5.64]],"ltp":2.64,"tv":3.02,"id":72857115}]}]}
{"op":"mcm","clk":"11909467090","pt":1724419954959,"mc":[{"id":"1.232174751","rc":[{"batb":[[0,2.7,4],[1,2.68,8.17],[2,2.64,27.05]],"ltp":2.64,"tv":3.02,"id":72857115}]}]}
{"op":"mcm","clk":"11909467337","pt":1724419957441,"mc":[{"id":"1.232174751","rc":[{"batb":[[0,2.68,8.17],[1,2.64,27.05],[2,1.99,5.64]],"ltp":2.64,"tv":3.02,"id":72857115}]}]}
{"op":"mcm","clk":"11909467371","pt":1724419957850,"mc":[{"id":"1.232174751","rc":[{"batb":[[0,2.7,5],[1,2.68,8.17],[2,2.64,27.05]],"ltp":2.64,"tv":3.02,"id":72857115}]}]}
{"op":"mcm","clk":"11909467585","pt":1724419960020,"mc":[{"id":"1.232174751","rc":[{"batb":[[0,2.72,4],[1,2.7,5],[2,2.68,8.17]],"ltp":2.64,"tv":3.02,"id":72857115}]}]}
{"op":"mcm","clk":"11909467699","pt":1724419961058,"mc":[{"id":"1.232174751","rc":[{"batb":[[1,2.68,8.17],[2,2.64,27.05]],"ltp":2.64,"tv":3.02,"id":72857115}]}]}
{"op":"mcm","clk":"11909467834","pt":1724419962467,"mc":[{"id":"1.232174751","rc":[{"batb":[[0,2.68,8.17],[1,2.64,27.05],[2,1.99,5.64]],"ltp":2.64,"tv":3.02,"id":72857115}]}]}
{"op":"mcm","clk":"11909468159","pt":1724419965254,"mc":[{"id":"1.232174751","rc":[{"batb":[[0,2.7,9],[1,2.68,8.17],[2,2.64,27.05]],"ltp":2.64,"tv":3.02,"id":72857115}]}]}
{"op":"mcm","clk":"11909468411","pt":1724419967637,"mc":[{"id":"1.232174751","rc":[{"batb":[[0,2.7,5]],"ltp":2.64,"tv":3.02,"id":72857115}]}]}
{"op":"mcm","clk":"11909468576","pt":1724419968836,"mc":[{"id":"1.232174751","rc":[{"batb":[[0,2.68,8.17],[1,2.64,27.05],[2,1.99,5.64]],"ltp":2.64,"tv":3.02,"id":72857115}]}]}
{"op":"mcm","clk":"11909468705","pt":1724419970028,"mc":[{"id":"1.232174751","rc":[{"batb":[[0,2.7,4],[1,2.68,8.17],[2,2.64,27.05]],"ltp":2.64,"tv":3.02,"id":72857115}]}]}
{"op":"mcm","clk":"11909468823","pt":1724419971274,"mc":[{"id":"1.232174751","rc":[{"batb":[[0,2.72,5],[1,2.7,4],[2,2.68,8.17]],"ltp":2.64,"tv":3.02,"id":72857115}]}]}
{"op":"mcm","clk":"11909468960","pt":1724419972676,"mc":[{"id":"1.232174751","rc":[{"batb":[[1,2.68,8.17],[2,2.64,27.05]],"ltp":2.64,"tv":3.02,"id":72857115}]}]}
{"op":"mcm","clk":"11909469174","pt":1724419974560,"mc":[{"id":"1.232174751","rc":[{"batb":[[0,2.68,8.17],[1,2.64,27.05],[2,1.99,5.64]],"ltp":2.64,"tv":3.02,"id":72857115}]}]}
{"op":"mcm","clk":"11909469374","pt":1724419976584,"mc":[{"id":"1.232174751","rc":[{"batb":[[0,2.7,4],[1,2.68,8.17],[2,2.64,27.05]],"ltp":2.64,"tv":3.02,"id":72857115}]}]}
{"op":"mcm","clk":"11909469393","pt":1724419976744,"mc":[{"id":"1.232174751","rc":[{"batb":[[0,2.72,5],[1,2.7,4],[2,2.68,8.17]],"ltp":2.64,"tv":3.02,"id":72857115}]}]}
{"op":"mcm","clk":"11909469667","pt":1724419979182,"mc":[{"id":"1.232174751","rc":[{"batb":[[1,2.68,8.17],[2,2.64,27.05]],"ltp":2.64,"tv":3.02,"id":72857115}]}]}
{"op":"mcm","clk":"11909469771","pt":1724419980178,"mc":[{"id":"1.232174751","rc":[{"batb":[[0,2.68,8.17],[1,2.64,27.05],[2,1.99,5.64]],"ltp":2.64,"tv":3.02,"id":72857115}]}]}
{"op":"mcm","clk":"11909469930","pt":1724419981384,"mc":[{"id":"1.232174751","rc":[{"batb":[[0,2.7,4],[1,2.68,8.17],[2,2.64,27.05]],"ltp":2.64,"tv":3.02,"id":72857115}]}]}
{"op":"mcm","clk":"11909470257","pt":1724419984184,"mc":[{"id":"1.232174751","rc":[{"batb":[[0,2.7,5]],"ltp":2.64,"tv":3.02,"id":72857115}]}]}
{"op":"mcm","clk":"11909470633","pt":1724419987574,"mc":[{"id":"1.232174751","rc":[{"batb":[[0,2.68,8.17],[1,2.64,27.05],[2,1.99,5.64]],"ltp":2.64,"tv":3.02,"id":72857115}]}]}
{"op":"mcm","clk":"11909470643","pt":1724419987680,"mc":[{"id":"1.232174751","rc":[{"batb":[[0,2.7,4],[1,2.68,8.17],[2,2.64,27.05]],"ltp":2.64,"tv":3.02,"id":72857115}]}]}
{"op":"mcm","clk":"11909470903","pt":1724419989961,"mc":[{"id":"1.232174751","rc":[{"batb":[[0,2.7,5]],"ltp":2.64,"tv":3.02,"id":72857115}]}]}
{"op":"mcm","clk":"11909471286","pt":1724419993168,"mc":[{"id":"1.232174751","rc":[{"batb":[[0,2.72,4]],"ltp":2.64,"tv":3.02,"id":72857115}]}]}
{"op":"mcm","clk":"11909471541","pt":1724419995553,"mc":[{"id":"1.232174751","rc":[{"batb":[[0,2.7,5]],"ltp":2.64,"tv":3.02,"id":72857115}]}]}
{"op":"mcm","clk":"11909471944","pt":1724419999194,"mc":[{"id":"1.232174751","rc":[{"batb":[[0,2.7,4]],"ltp":2.64,"tv":3.02,"id":72857115}]}]}
{"op":"mcm","clk":"11909472199","pt":1724420001585,"mc":[{"id":"1.232174751","rc":[{"batb":[[0,2.7,5]],"ltp":2.64,"tv":3.02,"id":72857115}]}]}
{"op":"mcm","clk":"11909472561","pt":1724420004899,"mc":[{"id":"1.232174751","rc":[{"batb":[[0,2.7,4]],"ltp":2.64,"tv":3.02,"id":72857115}]}]}
{"op":"mcm","clk":"11909472789","pt":1724420007388,"mc":[{"id":"1.232174751","rc":[{"batb":[[0,2.7,5]],"ltp":2.64,"tv":3.02,"id":72857115}]}]}
{"op":"mcm","clk":"11909473094","pt":1724420010580,"mc":[{"id":"1.232174751","rc":[{"batb":[[0,2.68,8.17],[1,2.64,27.05],[2,1.99,5.64]],"ltp":2.64,"tv":3.02,"id":72857115}]}]}
{"op":"mcm","clk":"11909473104","pt":1724420010683,"mc":[{"id":"1.232174751","rc":[{"batb":[[0,2.7,4],[1,2.68,8.17],[2,2.64,27.05]],"ltp":2.64,"tv":3.02,"id":72857115}]}]}
{"op":"mcm","clk":"11909473333","pt":1724420013117,"mc":[{"id":"1.232174751","rc":[{"batb":[[0,2.7,5]],"ltp":2.64,"tv":3.02,"id":72857115}]}]}
{"op":"mcm","clk":"11909473641","pt":1724420016614,"mc":[{"id":"1.232174751","rc":[{"batb":[[0,2.7,4]],"ltp":2.64,"tv":3.02,"id":72857115}]}]}
{"op":"mcm","clk":"11909473895","pt":1724420019098,"mc":[{"id":"1.232174751","rc":[{"batb":[[0,2.7,5]],"ltp":2.64,"tv":3.02,"id":72857115}]}]}
{"op":"mcm","clk":"11909474258","pt":1724420022621,"mc":[{"id":"1.232174751","rc":[{"batb":[[0,2.7,4]],"ltp":2.64,"tv":3.02,"id":72857115}]}]}
{"op":"mcm","clk":"11909474514","pt":1724420025100,"mc":[{"id":"1.232174751","rc":[{"batb":[[0,2.7,5]],"ltp":2.64,"tv":3.02,"id":72857115}]}]}
{"op":"mcm","clk":"11909474831","pt":1724420028422,"mc":[{"id":"1.232174751","rc":[{"batb":[[0,2.72,4]],"ltp":2.64,"tv":3.02,"id":72857115}]}]}
{"op":"mcm","clk":"11909475026","pt":1724420030193,"mc":[{"id":"1.232174751","rc":[{"batb":[[0,2.68,8.17],[1,2.64,27.05],[2,1.99,5.64]],"ltp":2.64,"tv":3.02,"id":72857115}]}]}
{"op":"mcm","clk":"11909475166","pt":1724420031806,"mc":[{"id":"1.232174751","rc":[{"batb":[[0,2.7,5],[1,2.68,8.17],[2,2.64,27.05]],"ltp":2.64,"tv":3.02,"id":72857115}]}]}
{"op":"mcm","clk":"11909475462","pt":1724420035215,"mc":[{"id":"1.232174751","rc":[{"batb":[[0,2.7,4]],"ltp":2.64,"tv":3.02,"id":72857115}]}]}
{"op":"mcm","clk":"11909475691","pt":1724420037492,"mc":[{"id":"1.232174751","rc":[{"batb":[[0,2.7,5]],"ltp":2.64,"tv":3.02,"id":72857115}]}]}
{"op":"mcm","clk":"11909476066","pt":1724420040916,"mc":[{"id":"1.232174751","rc":[{"batb":[[0,2.7,4]],"ltp":2.64,"tv":3.02,"id":72857115}]}]}
{"op":"mcm","clk":"11909476296","pt":1724420043413,"mc":[{"id":"1.232174751","rc":[{"batb":[[0,2.7,5]],"ltp":2.64,"tv":3.02,"id":72857115}]}]}
{"op":"mcm","clk":"11909476544","pt":1724420046007,"mc":[{"id":"1.232174751","rc":[{"batb":[[0,2.72,4],[1,2.7,5],[2,2.68,8.17]],"ltp":2.64,"tv":3.02,"id":72857115}]}]}
{"op":"mcm","clk":"11909476618","pt":1724420046733,"mc":[{"id":"1.232174751","rc":[{"batb":[[1,2.68,8.17],[2,2.64,27.05]],"ltp":2.64,"tv":3.02,"id":72857115}]}]}
{"op":"mcm","clk":"11909476781","pt":1724420048336,"mc":[{"id":"1.232174751","rc":[{"batb":[[0,2.68,8.17],[1,2.64,27.05],[2,1.99,5.64]],"ltp":2.64,"tv":3.02,"id":72857115}]}]}
{"op":"mcm","clk":"11909477155","pt":1724420051611,"mc":[{"id":"1.232174751","rc":[{"batb":[[0,2.7,9],[1,2.68,8.17],[2,2.64,27.05]],"ltp":2.64,"tv":3.02,"id":72857115}]}]}
{"op":"mcm","clk":"11909477394","pt":1724420054140,"mc":[{"id":"1.232174751","rc":[{"batb":[[0,2.7,5]],"ltp":2.64,"tv":3.02,"id":72857115}]}]}
{"op":"mcm","clk":"11909477471","pt":1724420055024,"mc":[{"id":"1.232174751","rc":[{"batb":[[0,2.68,8.17],[1,2.64,27.05],[2,1.99,5.64]],"ltp":2.64,"tv":3.02,"id":72857115}]}]}
{"op":"mcm","clk":"11909477606","pt":1724420056430,"mc":[{"id":"1.232174751","rc":[{"batb":[[0,2.7,4],[1,2.68,8.17],[2,2.64,27.05]],"ltp":2.64,"tv":3.02,"id":72857115}]}]}
{"op":"mcm","clk":"11909477741","pt":1724420057623,"mc":[{"id":"1.232174751","rc":[{"batb":[[0,2.72,5],[1,2.7,4],[2,2.68,8.17]],"ltp":2.64,"tv":3.02,"id":72857115}]}]}
{"op":"mcm","clk":"11909477875","pt":1724420058817,"mc":[{"id":"1.232174751","rc":[{"batb":[[1,2.68,8.17],[2,2.64,27.05]],"ltp":2.64,"tv":3.02,"id":72857115}]}]}
{"op":"mcm","clk":"11909478094","pt":1724420061033,"mc":[{"id":"1.232174751","rc":[{"batb":[[0,2.7,4]],"ltp":2.64,"tv":3.02,"id":72857115}]}]}
{"op":"mcm","clk":"11909478337","pt":1724420063535,"mc":[{"id":"1.232174751","rc":[{"batb":[[0,2.7,5]],"ltp":2.64,"tv":3.02,"id":72857115}]}]}
{"op":"mcm","clk":"11909478675","pt":1724420066900,"mc":[{"id":"1.232174751","rc":[{"batb":[[0,2.7,4]],"ltp":2.64,"tv":3.02,"id":72857115}]}]}
{"op":"mcm","clk":"11909478899","pt":1724420069229,"mc":[{"id":"1.232174751","rc":[{"batb":[[0,2.7,5]],"ltp":2.64,"tv":3.02,"id":72857115}]}]}
{"op":"mcm","clk":"11909479210","pt":1724420072525,"mc":[{"id":"1.232174751","rc":[{"batb":[[0,2.7,4]],"ltp":2.64,"tv":3.02,"id":72857115}]}]}
{"op":"mcm","clk":"11909479456","pt":1724420074915,"mc":[{"id":"1.232174751","rc":[{"batb":[[0,2.7,5]],"ltp":2.64,"tv":3.02,"id":72857115}]}]}
{"op":"mcm","clk":"11909479821","pt":1724420078337,"mc":[{"id":"1.232174751","rc":[{"batb":[[0,2.7,4]],"ltp":2.64,"tv":3.02,"id":72857115}]}]}
{"op":"mcm","clk":"11909480029","pt":1724420080553,"mc":[{"id":"1.232174751","rc":[{"batb":[[0,2.72,5]],"ltp":2.64,"tv":3.02,"id":72857115}]}]}
{"op":"mcm","clk":"11909480472","pt":1724420084152,"mc":[{"id":"1.232174751","rc":[{"batb":[[0,2.7,4]],"ltp":2.64,"tv":3.02,"id":72857115}]}]}
{"op":"mcm","clk":"11909480828","pt":1724420086453,"mc":[{"id":"1.232174751","rc":[{"batb":[[0,2.68,8.17],[1,2.64,27.05],[2,1.99,5.64]],"ltp":2.64,"tv":3.02,"id":72857115}]}]}
{"op":"mcm","clk":"11909480847","pt":1724420086658,"mc":[{"id":"1.232174751","rc":[{"batb":[[0,2.7,5],[1,2.68,8.17],[2,2.64,27.05]],"ltp":2.64,"tv":3.02,"id":72857115}]}]}
{"op":"mcm","clk":"11909481412","pt":1724420090049,"mc":[{"id":"1.232174751","rc":[{"batb":[[0,2.7,4]],"ltp":2.64,"tv":3.02,"id":72857115}]}]}
{"op":"mcm","clk":"11909481692","pt":1724420092459,"mc":[{"id":"1.232174751","rc":[{"batb":[[0,2.7,5]],"ltp":2.64,"tv":3.02,"id":72857115}]}]}
{"op":"mcm","clk":"11909482046","pt":1724420095749,"mc":[{"id":"1.232174751","rc":[{"batb":[[0,2.7,4]],"ltp":2.64,"tv":3.02,"id":72857115}]}]}
{"op":"mcm","clk":"11909482331","pt":1724420098169,"mc":[{"id":"1.232174751","rc":[{"batb":[[0,2.7,5]],"ltp":2.64,"tv":3.02,"id":72857115}]}]}
{"op":"mcm","clk":"11909482693","pt":1724420101584,"mc":[{"id":"1.232174751","rc":[{"batb":[[0,2.7,4]],"ltp":2.64,"tv":3.02,"id":72857115}]}]}
{"op":"mcm","clk":"11909482971","pt":1724420103948,"mc":[{"id":"1.232174751","rc":[{"batb":[[0,2.7,5]],"ltp":2.64,"tv":3.02,"id":72857115}]}]}
{"op":"mcm","clk":"11909483429","pt":1724420107481,"mc":[{"id":"1.232174751","rc":[{"batb":[[0,2.7,4]],"ltp":2.64,"tv":3.02,"id":72857115}]}]}
{"op":"mcm","clk":"11909483694","pt":1724420109477,"mc":[{"id":"1.232174751","rc":[{"batb":[[0,2.72,5],[1,2.7,4],[2,2.68,8.17]],"ltp":2.64,"tv":3.02,"id":72857115}]}]}
{"op":"mcm","clk":"11909483736","pt":1724420109790,"mc":[{"id":"1.232174751","rc":[{"batb":[[1,2.68,8.17],[2,2.64,27.05]],"ltp":2.64,"tv":3.02,"id":72857115}]}]}
{"op":"mcm","clk":"11909484114","pt":1724420112980,"mc":[{"id":"1.232174751","rc":[{"batb":[[0,2.7,4]],"ltp":2.64,"tv":3.02,"id":72857115}]}]}
{"op":"mcm","clk":"11909484406","pt":1724420115371,"mc":[{"id":"1.232174751","rc":[{"batb":[[0,2.7,5]],"ltp":2.64,"tv":3.02,"id":72857115}]}]}
{"op":"mcm","clk":"11909484571","pt":1724420116879,"mc":[{"id":"1.232174751","rc":[{"batb":[[2,2.64,23.7]],"ltp":2.64,"tv":3.02,"id":72857115},{"batb":[[0,1.56,69.41]],"ltp":1.56,"tv":154.76,"id":72857116}]}]}
{"op":"mcm","clk":"11909484799","pt":1724420118601,"mc":[{"id":"1.232174751","rc":[{"batb":[[0,2.72,4]],"ltp":2.64,"tv":3.02,"id":72857115}]}]}
{"op":"mcm","clk":"11909485071","pt":1724420120998,"mc":[{"id":"1.232174751","rc":[{"batb":[[0,2.7,5]],"ltp":2.64,"tv":3.02,"id":72857115}]}]}
{"op":"mcm","clk":"11909485359","pt":1724420123363,"mc":[{"id":"1.232174751","rc":[{"batb":[[0,2.72,4],[1,2.7,5],[2,2.68,8.17]],"ltp":2.64,"tv":3.02,"id":72857115}]}]}
{"op":"mcm","clk":"11909485480","pt":1724420124460,"mc":[{"id":"1.232174751","rc":[{"batb":[[1,2.68,8.17],[2,2.64,23.7]],"ltp":2.64,"tv":3.02,"id":72857115}]}]}
{"op":"mcm","clk":"11909485611","pt":1724420125760,"mc":[{"id":"1.232174751","rc":[{"batb":[[0,2.68,8.17],[1,2.64,23.7],[2,1.99,5.64]],"ltp":2.64,"tv":3.02,"id":72857115}]}]}
{"op":"mcm","clk":"11909485758","pt":1724420127175,"mc":[{"id":"1.232174751","rc":[{"batb":[[0,2.7,5],[1,2.68,8.17],[2,2.64,23.7]],"ltp":2.64,"tv":3.02,"id":72857115}]}]}
{"op":"mcm","clk":"11909486147","pt":1724420130605,"mc":[{"id":"1.232174751","rc":[{"batb":[[0,2.7,4]],"ltp":2.64,"tv":3.02,"id":72857115}]}]}
{"op":"mcm","clk":"11909486446","pt":1724420133358,"mc":[{"id":"1.232174751","rc":[{"batb":[[0,2.7,5]],"ltp":2.64,"tv":3.02,"id":72857115}]}]}
{"op":"mcm","clk":"11909486857","pt":1724420136906,"mc":[{"id":"1.232174751","rc":[{"batb":[[0,2.7,4]],"ltp":2.64,"tv":3.02,"id":72857115}]}]}
{"op":"mcm","clk":"11909487160","pt":1724420139390,"mc":[{"id":"1.232174751","rc":[{"batb":[[0,2.7,5]],"ltp":2.64,"tv":3.02,"id":72857115}]}]}
{"op":"mcm","clk":"11909487560","pt":1724420142812,"mc":[{"id":"1.232174751","rc":[{"batb":[[0,2.7,4]],"ltp":2.64,"tv":3.02,"id":72857115}]}]}
{"op":"mcm","clk":"11909487814","pt":1724420145204,"mc":[{"id":"1.232174751","rc":[{"batb":[[0,2.7,5]],"ltp":2.64,"tv":3.02,"id":72857115}]}]}
{"op":"mcm","clk":"11909488225","pt":1724420148590,"mc":[{"id":"1.232174751","rc":[{"batb":[[0,2.68,8.17],[1,2.64,23.7],[2,1.99,5.64]],"ltp":2.64,"tv":3.02,"id":72857115}]}]}
{"op":"mcm","clk":"11909488245","pt":1724420148791,"mc":[{"id":"1.232174751","rc":[{"batb":[[0,2.7,4],[1,2.68,8.17],[2,2.64,23.7]],"ltp":2.64,"tv":3.02,"id":72857115}]}]}
{"op":"mcm","clk":"11909488511","pt":1724420151084,"mc":[{"id":"1.232174751","rc":[{"batb":[[0,2.7,5]],"ltp":2.64,"tv":3.02,"id":72857115}]}]}
{"op":"mcm","clk":"11909488910","pt":1724420154515,"mc":[{"id":"1.232174751","rc":[{"batb":[[0,2.68,8.17],[1,2.64,23.7],[2,1.99,5.64]],"ltp":2.64,"tv":3.02,"id":72857115}]}]}
{"op":"mcm","clk":"11909488937","pt":1724420154725,"mc":[{"id":"1.232174751","rc":[{"batb":[[0,2.7,4],[1,2.68,8.17],[2,2.64,23.7]],"ltp":2.64,"tv":3.02,"id":72857115}]}]}
{"op":"mcm","clk":"11909489205","pt":1724420157212,"mc":[{"id":"1.232174751","rc":[{"batb":[[0,2.7,5]],"ltp":2.64,"tv":3.02,"id":72857115}]}]}
{"op":"mcm","clk":"11909489577","pt":1724420160497,"mc":[{"id":"1.232174751","rc":[{"batb":[[0,2.72,4]],"ltp":2.64,"tv":3.02,"id":72857115}]}]}
{"op":"mcm","clk":"11909489748","pt":1724420161999,"mc":[{"id":"1.232174751","rc":[{"batb":[[0,2.68,8.17],[1,2.64,23.7],[2,1.99,5.64]],"ltp":2.64,"tv":3.02,"id":72857115}]}]}
{"op":"mcm","clk":"11909490829","pt":1724420171630,"mc":[{"id":"1.232174751","rc":[{"batb":[[0,2.7,9],[1,2.68,8.17],[2,2.64,23.7]],"ltp":2.64,"tv":3.02,"id":72857115}]}]}
{"op":"mcm","clk":"11909491081","pt":1724420174014,"mc":[{"id":"1.232174751","rc":[{"batb":[[0,2.7,5]],"ltp":2.64,"tv":3.02,"id":72857115}]}]}
{"op":"mcm","clk":"11909491184","pt":1724420175025,"mc":[{"id":"1.232174751","rc":[{"batb":[[0,2.68,8.17],[1,2.64,23.7],[2,1.99,5.64]],"ltp":2.64,"tv":3.02,"id":72857115}]}]}
{"op":"mcm","clk":"11909491526","pt":1724420178112,"mc":[{"id":"1.232174751","rc":[{"batb":[[0,2.7,9],[1,2.68,8.17],[2,2.64,23.7]],"ltp":2.64,"tv":3.02,"id":72857115}]}]}
{"op":"mcm","clk":"11909491760","pt":1724420180541,"mc":[{"id":"1.232174751","rc":[{"batb":[[0,2.7,5]],"ltp":2.64,"tv":3.02,"id":72857115}]}]}
{"op":"mcm","clk":"11909491858","pt":1724420181622,"mc":[{"id":"1.232174751","rc":[{"batb":[[0,2.68,8.17],[1,2.64,23.7],[2,1.99,5.64]],"ltp":2.64,"tv":3.02,"id":72857115}]}]}
{"op":"mcm","clk":"11909492533","pt":1724420188610,"mc":[{"id":"1.232174751","rc":[{"batb":[[0,2.7,9],[1,2.68,8.17],[2,2.64,23.7]],"ltp":2.64,"tv":3.02,"id":72857115}]}]}
{"op":"mcm","clk":"11909492797","pt":1724420191249,"mc":[{"id":"1.232174751","rc":[{"batb":[[0,2.7,5]],"ltp":2.64,"tv":3.02,"id":72857115}]}]}
{"op":"mcm","clk":"11909492899","pt":1724420192232,"mc":[{"id":"1.232174751","rc":[{"batb":[[0,2.68,8.17],[1,2.64,23.7],[2,1.99,5.64]],"ltp":2.64,"tv":3.02,"id":72857115}]}]}
{"op":"mcm","clk":"11909493029","pt":1724420193420,"mc":[{"id":"1.232174751","rc":[{"batb":[[0,2.7,4],[1,2.68,8.17],[2,2.64,23.7]],"ltp":2.64,"tv":3.02,"id":72857115}]}]}
{"op":"mcm","clk":"11909493155","pt":1724420194763,"mc":[{"id":"1.232174751","rc":[{"batb":[[0,2.72,5],[1,2.7,4],[2,2.68,8.17]],"ltp":2.64,"tv":3.02,"id":72857115}]}]}
{"op":"mcm","clk":"11909493257","pt":1724420195851,"mc":[{"id":"1.232174751","rc":[{"batb":[[1,2.68,8.17],[2,2.64,23.7]],"ltp":2.64,"tv":3.02,"id":72857115}]}]}
{"op":"mcm","clk":"11909493512","pt":1724420198448,"mc":[{"id":"1.232174751","rc":[{"batb":[[0,2.7,4]],"ltp":2.64,"tv":3.02,"id":72857115}]}]}
{"op":"mcm","clk":"11909493740","pt":1724420200832,"mc":[{"id":"1.232174751","rc":[{"batb":[[0,2.7,5]],"ltp":2.64,"tv":3.02,"id":72857115}]}]}
{"op":"mcm","clk":"11909494081","pt":1724420204258,"mc":[{"id":"1.232174751","rc":[{"batb":[[0,2.7,4]],"ltp":2.64,"tv":3.02,"id":72857115}]}]}
{"op":"mcm","clk":"11909494315","pt":1724420206439,"mc":[{"id":"1.232174751","rc":[{"batb":[[0,2.68,8.17],[1,2.64,23.7],[2,1.99,5.64]],"ltp":2.64,"tv":3.02,"id":72857115}]}]}
{"op":"mcm","clk":"11909494342","pt":1724420206849,"mc":[{"id":"1.232174751","rc":[{"batb":[[0,2.7,5],[1,2.68,8.17],[2,2.64,23.7]],"ltp":2.64,"tv":3.02,"id":72857115}]}]}
{"op":"mcm","clk":"11909494675","pt":1724420210275,"mc":[{"id":"1.232174751","rc":[{"batb":[[0,2.7,4]],"ltp":2.64,"tv":3.02,"id":72857115}]}]}
{"op":"mcm","clk":"11909494896","pt":1724420212575,"mc":[{"id":"1.232174751","rc":[{"batb":[[0,2.7,5]],"ltp":2.64,"tv":3.02,"id":72857115}]}]}
{"op":"mcm","clk":"11909495254","pt":1724420216248,"mc":[{"id":"1.232174751","rc":[{"batb":[[0,2.72,4]],"ltp":2.64,"tv":3.02,"id":72857115}]}]}
{"op":"mcm","clk":"11909495559","pt":1724420219091,"mc":[{"id":"1.232174751","rc":[{"batb":[[0,2.7,5]],"ltp":2.64,"tv":3.02,"id":72857115}]}]}
{"op":"mcm","clk":"11909495953","pt":1724420222493,"mc":[{"id":"1.232174751","rc":[{"batb":[[0,2.68,8.17],[1,2.64,23.7],[2,1.99,5.64]],"ltp":2.64,"tv":3.02,"id":72857115}]}]}
{"op":"mcm","clk":"11909495978","pt":1724420222698,"mc":[{"id":"1.232174751","rc":[{"batb":[[0,2.7,4],[1,2.68,8.17],[2,2.64,23.7]],"ltp":2.64,"tv":3.02,"id":72857115}]}]}
{"op":"mcm","clk":"11909496234","pt":1724420224993,"mc":[{"id":"1.232174751","rc":[{"batb":[[0,2.7,5]],"ltp":2.64,"tv":3.02,"id":72857115}]}]}
{"op":"mcm","clk":"11909496587","pt":1724420228386,"mc":[{"id":"1.232174751","rc":[{"batb":[[0,2.7,4]],"ltp":2.64,"tv":3.02,"id":72857115}]}]}
{"op":"mcm","clk":"11909496815","pt":1724420230569,"mc":[{"id":"1.232174751","rc":[{"batb":[[0,2.68,8.17],[1,2.64,23.7],[2,1.99,5.64]],"ltp":2.64,"tv":3.02,"id":72857115}]}]}
{"op":"mcm","clk":"11909496841","pt":1724420230775,"mc":[{"id":"1.232174751","rc":[{"batb":[[0,2.7,5],[1,2.68,8.17],[2,2.64,23.7]],"ltp":2.64,"tv":3.02,"id":72857115}]}]}
{"op":"mcm","clk":"11909497205","pt":1724420234403,"mc":[{"id":"1.232174751","rc":[{"batb":[[0,2.7,4]],"ltp":2.64,"tv":3.02,"id":72857115}]}]}
{"op":"mcm","clk":"11909497475","pt":1724420236892,"mc":[{"id":"1.232174751","rc":[{"batb":[[0,2.7,5]],"ltp":2.64,"tv":3.02,"id":72857115}]}]}
{"op":"mcm","clk":"11909497929","pt":1724420240620,"mc":[{"id":"1.232174751","rc":[{"batb":[[0,2.7,4]],"ltp":2.64,"tv":3.02,"id":72857115}]}]}
{"op":"mcm","clk":"11909498173","pt":1724420243018,"mc":[{"id":"1.232174751","rc":[{"batb":[[0,2.7,5]],"ltp":2.64,"tv":3.02,"id":72857115}]}]}
{"op":"mcm","clk":"11909498527","pt":1724420246432,"mc":[{"id":"1.232174751","rc":[{"batb":[[0,2.7,4]],"ltp":2.64,"tv":3.02,"id":72857115}]}]}
{"op":"mcm","clk":"11909498751","pt":1724420248622,"mc":[{"id":"1.232174751","rc":[{"batb":[[0,2.68,8.17],[1,2.64,23.7],[2,1.99,5.64]],"ltp":2.64,"tv":3.02,"id":72857115}]}]}
{"op":"mcm","clk":"11909498772","pt":1724420248826,"mc":[{"id":"1.232174751","rc":[{"batb":[[0,2.7,5],[1,2.68,8.17],[2,2.64,23.7]],"ltp":2.64,"tv":3.02,"id":72857115}]}]}
{"op":"mcm","clk":"11909499159","pt":1724420252241,"mc":[{"id":"1.232174751","rc":[{"batb":[[0,2.7,4]],"ltp":2.64,"tv":3.02,"id":72857115}]}]}
{"op":"mcm","clk":"11909499435","pt":1724420254613,"mc":[{"id":"1.232174751","rc":[{"batb":[[0,2.7,5]],"ltp":2.64,"tv":3.02,"id":72857115}]}]}
{"op":"mcm","clk":"11909499852","pt":1724420258314,"mc":[{"id":"1.232174751","rc":[{"batb":[[0,2.72,4]],"ltp":2.64,"tv":3.02,"id":72857115}]}]}
{"op":"mcm","clk":"11909500146","pt":1724420261100,"mc":[{"id":"1.232174751","rc":[{"batb":[[0,2.7,5]],"ltp":2.64,"tv":3.02,"id":72857115}]}]}
{"op":"mcm","clk":"11909500426","pt":1724420264403,"mc":[{"id":"1.232174751","rc":[{"batb":[[0,2.72,4]],"ltp":2.64,"tv":3.02,"id":72857115}]}]}
{"op":"mcm","clk":"11909500700","pt":1724420266956,"mc":[{"id":"1.232174751","rc":[{"batb":[[0,2.7,5]],"ltp":2.64,"tv":3.02,"id":72857115}]}]}
{"op":"mcm","clk":"11909501058","pt":1724420270318,"mc":[{"id":"1.232174751","rc":[{"batb":[[0,2.7,4]],"ltp":2.64,"tv":3.02,"id":72857115}]}]}
{"op":"mcm","clk":"11909501264","pt":1724420272532,"mc":[{"id":"1.232174751","rc":[{"batb":[[0,2.68,8.17],[1,2.64,23.7],[2,1.99,5.64]],"ltp":2.64,"tv":3.02,"id":72857115}]}]}
{"op":"mcm","clk":"11909501286","pt":1724420272743,"mc":[{"id":"1.232174751","rc":[{"batb":[[0,2.7,5],[1,2.68,8.17],[2,2.64,23.7]],"ltp":2.64,"tv":3.02,"id":72857115}]}]}
{"op":"mcm","clk":"11909501477","pt":1724420275022,"mc":[{"id":"1.232174751","rc":[{"batb":[[0,2.72,4],[1,2.7,5],[2,2.68,8.17]],"ltp":2.64,"tv":3.02,"id":72857115}]}]}
{"op":"mcm","clk":"11909501569","pt":1724420276066,"mc":[{"id":"1.232174751","rc":[{"batb":[[1,2.68,8.17],[2,2.64,23.7]],"ltp":2.64,"tv":3.02,"id":72857115}]}]}
{"op":"mcm","clk":"11909501686","pt":1724420277253,"mc":[{"id":"1.232174751","rc":[{"batb":[[0,2.68,8.17],[1,2.64,23.7],[2,1.99,5.64]],"ltp":2.64,"tv":3.02,"id":72857115}]}]}
{"op":"mcm","clk":"11909502010","pt":1724420279954,"mc":[{"id":"1.232174751","rc":[{"batb":[[0,2.7,9],[1,2.68,8.17],[2,2.64,23.7]],"ltp":2.64,"tv":3.02,"id":72857115}]}]}
{"op":"mcm","clk":"11909502288","pt":1724420282256,"mc":[{"id":"1.232174751","rc":[{"batb":[[0,2.7,5]],"ltp":2.64,"tv":3.02,"id":72857115}]}]}
{"op":"mcm","clk":"11909502416","pt":1724420283138,"mc":[{"id":"1.232174751","rc":[{"batb":[[0,2.68,8.17],[1,2.64,23.7],[2,1.99,5.64]],"ltp":2.64,"tv":3.02,"id":72857115}]}]}
{"op":"mcm","clk":"11909502663","pt":1724420285236,"mc":[{"id":"1.232174751","rc":[{"batb":[[0,2.72,5],[1,2.7,4],[2,2.68,8.17]],"ltp":2.64,"tv":3.02,"id":72857115}]}]}
{"op":"mcm","clk":"11909502874","pt":1724420287469,"mc":[{"id":"1.232174751","rc":[{"batb":[[1,2.68,8.17],[2,2.64,23.7]],"ltp":2.64,"tv":3.02,"id":72857115}]}]}
{"op":"mcm","clk":"11909502986","pt":1724420288649,"mc":[{"id":"1.232174751","rc":[{"batb":[[0,2.68,8.17],[1,2.64,23.7],[2,1.99,5.64]],"ltp":2.64,"tv":3.02,"id":72857115}]}]}
{"op":"mcm","clk":"11909503358","pt":1724420292269,"mc":[{"id":"1.232174751","rc":[{"batb":[[0,2.7,9],[1,2.68,8.17],[2,2.64,23.7]],"ltp":2.64,"tv":3.02,"id":72857115}]}]}
{"op":"mcm","clk":"11909503597","pt":1724420294587,"mc":[{"id":"1.232174751","rc":[{"batb":[[0,2.7,5]],"ltp":2.64,"tv":3.02,"id":72857115}]}]}
{"op":"mcm","clk":"11909503689","pt":1724420295467,"mc":[{"id":"1.232174751","rc":[{"batb":[[0,2.68,8.17],[1,2.64,23.7],[2,1.99,5.64]],"ltp":2.64,"tv":3.02,"id":72857115}]}]}
{"op":"mcm","clk":"11909503810","pt":1724420296762,"mc":[{"id":"1.232174751","rc":[{"batb":[[0,2.7,4],[1,2.68,8.17],[2,2.64,23.7]],"ltp":2.64,"tv":3.02,"id":72857115}]}]}
{"op":"mcm","clk":"11909504021","pt":1724420299178,"mc":[{"id":"1.232174751","rc":[{"batb":[[0,2.7,5]],"ltp":2.64,"tv":3.02,"id":72857115}]}]}
{"op":"mcm","clk":"11909504276","pt":1724420301616,"mc":[{"id":"1.232174751","rc":[{"batb":[[0,2.72,4],[1,2.7,5],[2,2.68,8.17]],"ltp":2.64,"tv":3.02,"id":72857115}]}]}
{"op":"mcm","clk":"11909504353","pt":1724420302386,"mc":[{"id":"1.232174751","rc":[{"batb":[[1,2.68,8.17],[2,2.64,23.7]],"ltp":2.64,"tv":3.02,"id":72857115}]}]}
{"op":"mcm","clk":"11909504478","pt":1724420303886,"mc":[{"id":"1.232174751","rc":[{"batb":[[0,2.68,8.17],[1,2.64,23.7],[2,1.99,5.64]],"ltp":2.64,"tv":3.02,"id":72857115}]}]}
{"op":"mcm","clk":"11909505072","pt":1724420310082,"mc":[{"id":"1.232174751","rc":[{"batb":[[0,2.7,9],[1,2.68,8.17],[2,2.64,23.7]],"ltp":2.64,"tv":3.02,"id":72857115}]}]}
{"op":"mcm","clk":"11909505322","pt":1724420312567,"mc":[{"id":"1.232174751","rc":[{"batb":[[0,2.7,5]],"ltp":2.64,"tv":3.02,"id":72857115}]}]}
{"op":"mcm","clk":"11909505415","pt":1724420313572,"mc":[{"id":"1.232174751","rc":[{"batb":[[0,2.68,8.17],[1,2.64,23.7],[2,1.99,5.64]],"ltp":2.64,"tv":3.02,"id":72857115}]}]}
{"op":"mcm","clk":"11909505624","pt":1724420315794,"mc":[{"id":"1.232174751","rc":[{"batb":[[0,2.72,5],[1,2.7,4],[2,2.68,8.17]],"ltp":2.64,"tv":3.02,"id":72857115}]}]}
{"op":"mcm","clk":"11909505839","pt":1724420318002,"mc":[{"id":"1.232174751","rc":[{"batb":[[1,2.68,8.17],[2,2.64,23.7]],"ltp":2.64,"tv":3.02,"id":72857115}]}]}
{"op":"mcm","clk":"11909505945","pt":1724420319098,"mc":[{"id":"1.232174751","rc":[{"batb":[[0,2.68,8.17],[1,2.64,23.7],[2,1.99,5.64]],"ltp":2.64,"tv":3.02,"id":72857115}]}]}
{"op":"mcm","clk":"11909506360","pt":1724420323691,"mc":[{"id":"1.232174751","rc":[{"batb":[[0,2.7,9],[1,2.68,8.17],[2,2.64,23.7]],"ltp":2.64,"tv":3.02,"id":72857115}]}]}
{"op":"mcm","clk":"11909506611","pt":1724420326018,"mc":[{"id":"1.232174751","rc":[{"batb":[[0,2.7,5]],"ltp":2.64,"tv":3.02,"id":72857115}]}]}
{"op":"mcm","clk":"11909506709","pt":1724420327106,"mc":[{"id":"1.232174751","rc":[{"batb":[[0,2.68,8.17],[1,2.64,23.7],[2,1.99,5.64]],"ltp":2.64,"tv":3.02,"id":72857115}]}]}
{"op":"mcm","clk":"11909506840","pt":1724420328700,"mc":[{"id":"1.232174751","rc":[{"batb":[[0,2.7,4],[1,2.68,8.17],[2,2.64,23.7]],"ltp":2.64,"tv":3.02,"id":72857115}]}]}
{"op":"mcm","clk":"11909507116","pt":1724420331136,"mc":[{"id":"1.232174751","rc":[{"batb":[[0,2.7,5]],"ltp":2.64,"tv":3.02,"id":72857115}]}]}
{"op":"mcm","clk":"11909507441","pt":1724420334445,"mc":[{"id":"1.232174751","rc":[{"batb":[[0,2.7,4]],"ltp":2.64,"tv":3.02,"id":72857115}]}]}
{"op":"mcm","clk":"11909507636","pt":1724420337128,"mc":[{"id":"1.232174751","rc":[{"batb":[[0,2.7,5]],"ltp":2.64,"tv":3.02,"id":72857115}]}]}
{"op":"mcm","clk":"11909507976","pt":1724420340563,"mc":[{"id":"1.232174751","rc":[{"batb":[[0,2.7,4]],"ltp":2.64,"tv":3.02,"id":72857115}]}]}
{"op":"mcm","clk":"11909508237","pt":1724420342949,"mc":[{"id":"1.232174751","rc":[{"batb":[[0,2.7,5]],"ltp":2.64,"tv":3.02,"id":72857115}]}]}
{"op":"mcm","clk":"11909508431","pt":1724420345034,"mc":[{"id":"1.232174751","rc":[{"batb":[[0,2.72,4],[1,2.7,5],[2,2.68,8.17]],"ltp":2.64,"tv":3.02,"id":72857115}]}]}
{"op":"mcm","clk":"11909508561","pt":1724420346256,"mc":[{"id":"1.232174751","rc":[{"batb":[[1,2.68,8.17],[2,2.64,23.7]],"ltp":2.64,"tv":3.02,"id":72857115}]}]}
{"op":"mcm","clk":"11909508687","pt":1724420347760,"mc":[{"id":"1.232174751","rc":[{"batb":[[0,2.68,8.17],[1,2.64,23.7],[2,1.99,5.64]],"ltp":2.64,"tv":3.02,"id":72857115}]}]}
{"op":"mcm","clk":"11909509659","pt":1724420357169,"mc":[{"id":"1.232174751","rc":[{"batb":[[0,2.7,9],[1,2.68,8.17],[2,2.64,23.7]],"ltp":2.64,"tv":3.02,"id":72857115}]}]}
{"op":"mcm","clk":"11909509880","pt":1724420359534,"mc":[{"id":"1.232174751","rc":[{"batb":[[0,2.7,5]],"ltp":2.64,"tv":3.02,"id":72857115}]}]}
{"op":"mcm","clk":"11909509991","pt":1724420360574,"mc":[{"id":"1.232174751","rc":[{"batb":[[0,2.68,8.17],[1,2.64,23.7],[2,1.99,5.64]],"ltp":2.64,"tv":3.02,"id":72857115}]}]}
{"op":"mcm","clk":"11909510146","pt":1724420361950,"mc":[{"id":"1.232174751","rc":[{"batb":[[0,2.7,4],[1,2.68,8.17],[2,2.64,23.7]],"ltp":2.64,"tv":3.02,"id":72857115}]}]}
{"op":"mcm","clk":"11909510410","pt":1724420364375,"mc":[{"id":"1.232174751","rc":[{"batb":[[0,2.7,5]],"ltp":2.64,"tv":3.02,"id":72857115}]}]}
{"op":"mcm","clk":"11909510764","pt":1724420367752,"mc":[{"id":"1.232174751","rc":[{"batb":[[0,2.7,4]],"ltp":2.64,"tv":3.02,"id":72857115}]}]}
{"op":"mcm","clk":"11909510989","pt":1724420370165,"mc":[{"id":"1.232174751","rc":[{"batb":[[0,2.7,5]],"ltp":2.64,"tv":3.02,"id":72857115}]}]}
{"op":"mcm","clk":"11909511326","pt":1724420373582,"mc":[{"id":"1.232174751","rc":[{"batb":[[0,2.7,4]],"ltp":2.64,"tv":3.02,"id":72857115}]}]}
{"op":"mcm","clk":"11909511549","pt":1724420375976,"mc":[{"id":"1.232174751","rc":[{"batb":[[0,2.7,5]],"ltp":2.64,"tv":3.02,"id":72857115}]}]}
{"op":"mcm","clk":"11909511860","pt":1724420379286,"mc":[{"id":"1.232174751","rc":[{"batb":[[0,2.7,4]],"ltp":2.64,"tv":3.02,"id":72857115}]}]}
{"op":"mcm","clk":"11909512076","pt":1724420381575,"mc":[{"id":"1.232174751","rc":[{"batb":[[0,2.68,8.17],[1,2.64,23.7],[2,1.99,5.64]],"ltp":2.64,"tv":3.02,"id":72857115}]}]}
{"op":"mcm","clk":"11909512101","pt":1724420381782,"mc":[{"id":"1.232174751","rc":[{"batb":[[0,2.7,5],[1,2.68,8.17],[2,2.64,23.7]],"ltp":2.64,"tv":3.02,"id":72857115}]}]}
{"op":"mcm","clk":"11909512448","pt":1724420385200,"mc":[{"id":"1.232174751","rc":[{"batb":[[0,2.7,4]],"ltp":2.64,"tv":3.02,"id":72857115}]}]}
{"op":"mcm","clk":"11909512678","pt":1724420387579,"mc":[{"id":"1.232174751","rc":[{"batb":[[0,2.7,5]],"ltp":2.64,"tv":3.02,"id":72857115}]}]}
{"op":"mcm","clk":"11909513037","pt":1724420390995,"mc":[{"id":"1.232174751","rc":[{"batb":[[0,2.7,4]],"ltp":2.64,"tv":3.02,"id":72857115}]}]}
{"op":"mcm","clk":"11909513272","pt":1724420393404,"mc":[{"id":"1.232174751","rc":[{"batb":[[0,2.7,5]],"ltp":2.64,"tv":3.02,"id":72857115}]}]}
{"op":"mcm","clk":"11909513612","pt":1724420397020,"mc":[{"id":"1.232174751","rc":[{"batb":[[0,2.7,4]],"ltp":2.64,"tv":3.02,"id":72857115}]}]}
{"op":"mcm","clk":"11909513845","pt":1724420399600,"mc":[{"id":"1.232174751","rc":[{"batb":[[0,2.7,5]],"ltp":2.64,"tv":3.02,"id":72857115}]}]}
{"op":"mcm","clk":"11909514235","pt":1724420402941,"mc":[{"id":"1.232174751","rc":[{"batb":[[0,2.7,4]],"ltp":2.64,"tv":3.02,"id":72857115}]}]}
{"op":"mcm","clk":"11909514444","pt":1724420405329,"mc":[{"id":"1.232174751","rc":[{"batb":[[0,2.7,5]],"ltp":2.64,"tv":3.02,"id":72857115}]}]}
{"op":"mcm","clk":"11909514739","pt":1724420408598,"mc":[{"id":"1.232174751","rc":[{"batb":[[0,2.7,4]],"ltp":2.64,"tv":3.02,"id":72857115}]}]}
{"op":"mcm","clk":"11909514970","pt":1724420411125,"mc":[{"id":"1.232174751","rc":[{"batb":[[0,2.7,5]],"ltp":2.64,"tv":3.02,"id":72857115}]}]}
{"op":"mcm","clk":"11909515262","pt":1724420414610,"mc":[{"id":"1.232174751","rc":[{"batb":[[0,2.72,4]],"ltp":2.64,"tv":3.02,"id":72857115}]}]}
{"op":"mcm","clk":"11909515473","pt":1724420417029,"mc":[{"id":"1.232174751","rc":[{"batb":[[0,2.7,5]],"ltp":2.64,"tv":3.02,"id":72857115}]}]}
{"op":"mcm","clk":"11909515655","pt":1724420418980,"mc":[{"id":"1.232174751","rc":[{"batb":[[0,2.72,4],[1,2.7,5],[2,2.68,8.17]],"ltp":2.64,"tv":3.02,"id":72857115}]}]}
{"op":"mcm","clk":"11909515770","pt":1724420420271,"mc":[{"id":"1.232174751","rc":[{"batb":[[1,2.68,8.17],[2,2.64,23.7]],"ltp":2.64,"tv":3.02,"id":72857115}]}]}
{"op":"mcm","clk":"11909515852","pt":1724420421202,"mc":[{"id":"1.232174751","rc":[{"batb":[[0,2.68,8.17],[1,2.64,23.7],[2,1.99,5.64]],"ltp":2.64,"tv":3.02,"id":72857115}]}]}
{"op":"mcm","clk":"11909517080","pt":1724420434716,"mc":[{"id":"1.232174751","rc":[{"batb":[[0,2.7,9],[1,2.68,8.17],[2,2.64,23.7]],"ltp":2.64,"tv":3.02,"id":72857115}]}]}
{"op":"mcm","clk":"11909517288","pt":1724420437233,"mc":[{"id":"1.232174751","rc":[{"batb":[[0,2.7,5]],"ltp":2.64,"tv":3.02,"id":72857115}]}]}
{"op":"mcm","clk":"11909517396","pt":1724420438318,"mc":[{"id":"1.232174751","rc":[{"batb":[[0,2.68,8.17],[1,2.64,23.7],[2,1.99,5.64]],"ltp":2.64,"tv":3.02,"id":72857115}]}]}
{"op":"mcm","clk":"11909517696","pt":1724420441637,"mc":[{"id":"1.232174751","rc":[{"batb":[[0,2.7,9],[1,2.68,8.17],[2,2.64,23.7]],"ltp":2.64,"tv":3.02,"id":72857115}]}]}
{"op":"mcm","clk":"11909517916","pt":1724420444126,"mc":[{"id":"1.232174751","rc":[{"batb":[[0,2.7,5]],"ltp":2.64,"tv":3.02,"id":72857115}]}]}
{"op":"mcm","clk":"11909518015","pt":1724420445268,"mc":[{"id":"1.232174751","rc":[{"batb":[[0,2.68,8.17],[1,2.64,23.7],[2,1.99,5.64]],"ltp":2.64,"tv":3.02,"id":72857115}]}]}
{"op":"mcm","clk":"11909518430","pt":1724420449836,"mc":[{"id":"1.232174751","rc":[{"batb":[[0,2.7,9],[1,2.68,8.17],[2,2.64,23.7]],"ltp":2.64,"tv":3.02,"id":72857115}]}]}
{"op":"mcm","clk":"11909518634","pt":1724420452062,"mc":[{"id":"1.232174751","rc":[{"batb":[[0,2.7,5]],"ltp":2.64,"tv":3.02,"id":72857115}]}]}
{"op":"mcm","clk":"11909518731","pt":1724420453146,"mc":[{"id":"1.232174751","rc":[{"batb":[[0,2.68,8.17],[1,2.64,23.7],[2,1.99,5.64]],"ltp":2.64,"tv":3.02,"id":72857115}]}]}
{"op":"mcm","clk":"11909518845","pt":1724420454632,"mc":[{"id":"1.232174751","rc":[{"batb":[[0,2.7,4],[1,2.68,8.17],[2,2.64,23.7]],"ltp":2.64,"tv":3.02,"id":72857115}]}]}
{"op":"mcm","clk":"11909519045","pt":1724420457542,"mc":[{"id":"1.232174751","rc":[{"batb":[[0,2.68,8.17],[1,2.64,23.7],[2,1.99,5.64]],"ltp":2.64,"tv":3.02,"id":72857115}]}]}
{"op":"mcm","clk":"11909519063","pt":1724420457748,"mc":[{"id":"1.232174751","rc":[{"batb":[[0,2.7,5],[1,2.68,8.17],[2,2.64,23.7]],"ltp":2.64,"tv":3.02,"id":72857115}]}]}
{"op":"mcm","clk":"11909519380","pt":1724420461248,"mc":[{"id":"1.232174751","rc":[{"batb":[[0,2.7,4]],"ltp":2.64,"tv":3.02,"id":72857115}]}]}
{"op":"mcm","clk":"11909519615","pt":1724420463787,"mc":[{"id":"1.232174751","rc":[{"batb":[[0,2.7,5]],"ltp":2.64,"tv":3.02,"id":72857115}]}]}
{"op":"mcm","clk":"11909519960","pt":1724420467157,"mc":[{"id":"1.232174751","rc":[{"batb":[[0,2.7,4]],"ltp":2.64,"tv":3.02,"id":72857115}]}]}
{"op":"mcm","clk":"11909520196","pt":1724420469589,"mc":[{"id":"1.232174751","rc":[{"batb":[[0,2.72,5]],"ltp":2.64,"tv":3.02,"id":72857115}]}]}
{"op":"mcm","clk":"11909520408","pt":1724420471754,"mc":[{"id":"1.232174751","rc":[{"batb":[[0,2.74,4],[1,2.72,5],[2,2.68,8.17]],"ltp":2.64,"tv":3.02,"id":72857115}]}]}
{"op":"mcm","clk":"11909520517","pt":1724420472969,"mc":[{"id":"1.232174751","rc":[{"batb":[[1,2.68,8.17],[2,2.64,23.7]],"ltp":2.64,"tv":3.02,"id":72857115}]}]}
{"op":"mcm","clk":"11909520617","pt":1724420474095,"mc":[{"id":"1.232174751","rc":[{"batb":[[0,2.68,8.17],[1,2.64,23.7],[2,1.99,5.64]],"ltp":2.64,"tv":3.02,"id":72857115}]}]}
{"op":"mcm","clk":"11909520913","pt":1724420477159,"mc":[{"id":"1.232174751","rc":[{"batb":[[0,2.7,9],[1,2.68,8.17],[2,2.64,23.7]],"ltp":2.64,"tv":3.02,"id":72857115}]}]}
{"op":"mcm","clk":"11909521159","pt":1724420479707,"mc":[{"id":"1.232174751","rc":[{"batb":[[0,2.7,5]],"ltp":2.64,"tv":3.02,"id":72857115}]}]}
{"op":"mcm","clk":"11909521275","pt":1724420480794,"mc":[{"id":"1.232174751","rc":[{"batb":[[0,2.68,8.17],[1,2.64,23.7],[2,1.99,5.64]],"ltp":2.64,"tv":3.02,"id":72857115}]}]}
{"op":"mcm","clk":"11909521834","pt":1724420486794,"mc":[{"id":"1.232174751","rc":[{"batb":[[0,2.7,9],[1,2.68,8.17],[2,2.64,23.7]],"ltp":2.64,"tv":3.02,"id":72857115}]}]}
{"op":"mcm","clk":"11909522031","pt":1724420489332,"mc":[{"id":"1.232174751","rc":[{"batb":[[0,2.7,5]],"ltp":2.64,"tv":3.02,"id":72857115}]}]}
{"op":"mcm","clk":"11909522169","pt":1724420490513,"mc":[{"id":"1.232174751","rc":[{"batb":[[0,2.68,8.17],[1,2.64,23.7],[2,1.99,5.64]],"ltp":2.64,"tv":3.02,"id":72857115}]}]}
{"op":"mcm","clk":"11909522667","pt":1724420496416,"mc":[{"id":"1.232174751","rc":[{"batb":[[0,2.7,9],[1,2.68,8.17],[2,2.64,23.7]],"ltp":2.64,"tv":3.02,"id":72857115}]}]}
{"op":"mcm","clk":"11909522902","pt":1724420498994,"mc":[{"id":"1.232174751","rc":[{"batb":[[0,2.7,5]],"ltp":2.64,"tv":3.02,"id":72857115}]}]}
{"op":"mcm","clk":"11909522994","pt":1724420500020,"mc":[{"id":"1.232174751","rc":[{"batb":[[0,2.68,8.17],[1,2.64,23.7],[2,1.99,5.64]],"ltp":2.64,"tv":3.02,"id":72857115}]}]}
{"op":"mcm","clk":"11909523551","pt":1724420507630,"mc":[{"id":"1.232174751","rc":[{"batb":[[0,2.7,9],[1,2.68,8.17],[2,2.64,23.7]],"ltp":2.64,"tv":3.02,"id":72857115}]}]}
{"op":"mcm","clk":"11909523750","pt":1724420509898,"mc":[{"id":"1.232174751","rc":[{"batb":[[0,2.7,5]],"ltp":2.64,"tv":3.02,"id":72857115}]}]}
{"op":"mcm","clk":"11909523832","pt":1724420511027,"mc":[{"id":"1.232174751","rc":[{"batb":[[0,2.68,8.17],[1,2.64,23.7],[2,1.99,5.64]],"ltp":2.64,"tv":3.02,"id":72857115}]}]}
{"op":"mcm","clk":"11909525135","pt":1724420526850,"mc":[{"id":"1.232174751","rc":[{"batb":[[0,2.7,9],[1,2.68,8.17],[2,2.64,23.7]],"ltp":2.64,"tv":3.02,"id":72857115}]}]}
{"op":"mcm","clk":"11909525362","pt":1724420529439,"mc":[{"id":"1.232174751","rc":[{"batb":[[0,2.7,5]],"ltp":2.64,"tv":3.02,"id":72857115}]}]}
{"op":"mcm","clk":"11909525476","pt":1724420530531,"mc":[{"id":"1.232174751","rc":[{"batb":[[0,2.68,8.17],[1,2.64,23.7],[2,1.99,5.64]],"ltp":2.64,"tv":3.02,"id":72857115}]}]}
{"op":"mcm","clk":"11909525613","pt":1724420532330,"mc":[{"id":"1.232174751","rc":[{"batb":[[0,2.7,4],[1,2.68,8.17],[2,2.64,23.7]],"ltp":2.64,"tv":3.02,"id":72857115}]}]}
{"op":"mcm","clk":"11909525842","pt":1724420534752,"mc":[{"id":"1.232174751","rc":[{"batb":[[0,2.7,5]],"ltp":2.64,"tv":3.02,"id":72857115}]}]}
{"op":"mcm","clk":"11909526117","pt":1724420538235,"mc":[{"id":"1.232174751","rc":[{"batb":[[0,2.7,4]],"ltp":2.64,"tv":3.02,"id":72857115}]}]}
{"op":"mcm","clk":"11909526342","pt":1724420541065,"mc":[{"id":"1.232174751","rc":[{"batb":[[0,2.7,5]],"ltp":2.64,"tv":3.02,"id":72857115}]}]}
{"op":"mcm","clk":"11909526652","pt":1724420544583,"mc":[{"id":"1.232174751","rc":[{"batb":[[0,2.7,4]],"ltp":2.64,"tv":3.02,"id":72857115}]}]}
{"op":"mcm","clk":"11909526832","pt":1724420546954,"mc":[{"id":"1.232174751","rc":[{"batb":[[0,2.7,5]],"ltp":2.64,"tv":3.02,"id":72857115}]}]}
{"op":"mcm","clk":"11909527113","pt":1724420550276,"mc":[{"id":"1.232174751","rc":[{"batb":[[0,2.72,4]],"ltp":2.64,"tv":3.02,"id":72857115}]}]}
{"op":"mcm","clk":"11909527324","pt":1724420552593,"mc":[{"id":"1.232174751","rc":[{"batb":[[0,2.68,8.17],[1,2.64,23.7],[2,1.99,5.64]],"ltp":2.64,"tv":3.02,"id":72857115}]}]}
{"op":"mcm","clk":"11909527341","pt":1724420552764,"mc":[{"id":"1.232174751","rc":[{"batb":[[0,2.7,5],[1,2.68,8.17],[2,2.64,23.7]],"ltp":2.64,"tv":3.02,"id":72857115}]}]}
{"op":"mcm","clk":"11909527608","pt":1724420556290,"mc":[{"id":"1.232174751","rc":[{"batb":[[0,2.7,4]],"ltp":2.64,"tv":3.02,"id":72857115}]}]}
{"op":"mcm","clk":"11909527793","pt":1724420558504,"mc":[{"id":"1.232174751","rc":[{"batb":[[0,2.68,8.17],[1,2.64,23.7],[2,1.99,5.64]],"ltp":2.64,"tv":3.02,"id":72857115}]}]}
{"op":"mcm","clk":"11909527813","pt":1724420558679,"mc":[{"id":"1.232174751","rc":[{"batb":[[0,2.7,5],[1,2.68,8.17],[2,2.64,23.7]],"ltp":2.64,"tv":3.02,"id":72857115}]}]}
{"op":"mcm","clk":"11909528017","pt":1724420561193,"mc":[{"id":"1.232174751","rc":[{"batb":[[0,2.72,4],[1,2.7,5],[2,2.68,8.17]],"ltp":2.64,"tv":3.02,"id":72857115}]}]}
{"op":"mcm","clk":"11909528065","pt":1724420561904,"mc":[{"id":"1.232174751","rc":[{"batb":[[1,2.68,8.17],[2,2.64,23.7]],"ltp":2.64,"tv":3.02,"id":72857115}]}]}
{"op":"mcm","clk":"11909528210","pt":1724420564200,"mc":[{"id":"1.232174751","rc":[{"batb":[[0,2.7,5]],"ltp":2.64,"tv":3.02,"id":72857115}]}]}
{"op":"mcm","clk":"11909528443","pt":1724420567403,"mc":[{"id":"1.232174751","rc":[{"batb":[[0,2.72,4]],"ltp":2.64,"tv":3.02,"id":72857115}]}]}
{"op":"mcm","clk":"11909528594","pt":1724420569371,"mc":[{"id":"1.232174751","rc":[{"batb":[[0,2.68,8.17],[1,2.64,23.7],[2,1.99,5.64]],"ltp":2.64,"tv":3.02,"id":72857115}]}]}
{"op":"mcm","clk":"11909528617","pt":1724420569684,"mc":[{"id":"1.232174751","rc":[{"batb":[[0,2.7,5],[1,2.68,8.17],[2,2.64,23.7]],"ltp":2.64,"tv":3.02,"id":72857115}]}]}
{"op":"mcm","clk":"11909528898","pt":1724420573205,"mc":[{"id":"1.232174751","rc":[{"batb":[[0,2.7,4]],"ltp":2.64,"tv":3.02,"id":72857115}]}]}
{"op":"mcm","clk":"11909546851","pt":1724420575502,"mc":[{"id":"1.232174751","rc":[{"batb":[[0,2.68,8.17],[1,2.64,23.7],[2,1.99,5.64]],"ltp":2.64,"tv":3.02,"id":72857115}]}]}
{"op":"mcm","clk":"11909546869","pt":1724420575701,"mc":[{"id":"1.232174751","rc":[{"batb":[[0,2.7,5],[1,2.68,8.17],[2,2.64,23.7]],"ltp":2.64,"tv":3.02,"id":72857115}]}]}
{"op":"mcm","clk":"11909547162","pt":1724420579297,"mc":[{"id":"1.232174751","rc":[{"batb":[[0,2.7,4]],"ltp":2.64,"tv":3.02,"id":72857115}]}]}
{"op":"mcm","clk":"11909547369","pt":1724420581518,"mc":[{"id":"1.232174751","rc":[{"batb":[[0,2.68,8.17],[1,2.64,23.7],[2,1.99,5.64]],"ltp":2.64,"tv":3.02,"id":72857115}]}]}
{"op":"mcm","clk":"11909547389","pt":1724420581725,"mc":[{"id":"1.232174751","rc":[{"batb":[[0,2.7,5],[1,2.68,8.17],[2,2.64,23.7]],"ltp":2.64,"tv":3.02,"id":72857115}]}]}
{"op":"mcm","clk":"11909547676","pt":1724420585002,"mc":[{"id":"1.232174751","rc":[{"batb":[[0,2.7,4]],"ltp":2.64,"tv":3.02,"id":72857115}]}]}
{"op":"mcm","clk":"11909547893","pt":1724420587395,"mc":[{"id":"1.232174751","rc":[{"batb":[[0,2.7,5]],"ltp":2.64,"tv":3.02,"id":72857115}]}]}
{"op":"mcm","clk":"11909548194","pt":1724420590910,"mc":[{"id":"1.232174751","rc":[{"batb":[[0,2.7,4]],"ltp":2.64,"tv":3.02,"id":72857115}]}]}
{"op":"mcm","clk":"11909548417","pt":1724420593397,"mc":[{"id":"1.232174751","rc":[{"batb":[[0,2.7,5]],"ltp":2.64,"tv":3.02,"id":72857115}]}]}
{"op":"mcm","clk":"11909548613","pt":1724420595619,"mc":[{"id":"1.232174751","rc":[{"batb":[[0,2.72,4],[1,2.7,5],[2,2.68,8.17]],"ltp":2.64,"tv":3.02,"id":72857115}]}]}
{"op":"mcm","clk":"11909548720","pt":1724420596602,"mc":[{"id":"1.232174751","rc":[{"batb":[[1,2.68,8.17],[2,2.64,23.7]],"ltp":2.64,"tv":3.02,"id":72857115}]}]}
{"op":"mcm","clk":"11909548832","pt":1724420598001,"mc":[{"id":"1.232174751","rc":[{"batb":[[0,2.68,8.17],[1,2.64,23.7],[2,1.99,5.64]],"ltp":2.64,"tv":3.02,"id":72857115}]}]}
{"op":"mcm","clk":"11909549246","pt":1724420603127,"mc":[{"id":"1.232174751","rc":[{"batb":[[0,2.7,9],[1,2.68,8.17],[2,2.64,23.7]],"ltp":2.64,"tv":3.02,"id":72857115}]}]}
{"op":"mcm","clk":"11909549446","pt":1724420605606,"mc":[{"id":"1.232174751","rc":[{"batb":[[0,2.7,5]],"ltp":2.64,"tv":3.02,"id":72857115}]}]}
{"op":"mcm","clk":"11909549521","pt":1724420606530,"mc":[{"id":"1.232174751","rc":[{"batb":[[0,2.68,8.17],[1,2.64,23.7],[2,1.99,5.64]],"ltp":2.64,"tv":3.02,"id":72857115}]}]}
{"op":"mcm","clk":"11909549740","pt":1724420609238,"mc":[{"id":"1.232174751","rc":[{"batb":[[0,2.7,9],[1,2.68,8.17],[2,2.64,23.7]],"ltp":2.64,"tv":3.02,"id":72857115}]}]}
{"op":"mcm","clk":"11909550016","pt":1724420612618,"mc":[{"id":"1.232174751","rc":[{"batb":[[0,2.68,8.17],[1,2.64,23.7],[2,1.99,5.64]],"ltp":2.64,"tv":3.02,"id":72857115}]}]}
{"op":"mcm","clk":"11909550913","pt":1724420623541,"mc":[{"id":"1.232174751","rc":[{"batb":[[0,2.7,9],[1,2.68,8.17],[2,2.64,23.7]],"ltp":2.64,"tv":3.02,"id":72857115}]}]}
{"op":"mcm","clk":"11909551087","pt":1724420625856,"mc":[{"id":"1.232174751","rc":[{"batb":[[0,2.7,5]],"ltp":2.64,"tv":3.02,"id":72857115}]}]}
{"op":"mcm","clk":"11909551171","pt":1724420626840,"mc":[{"id":"1.232174751","rc":[{"batb":[[0,2.68,8.17],[1,2.64,23.7],[2,1.99,5.64]],"ltp":2.64,"tv":3.02,"id":72857115}]}]}
{"op":"mcm","clk":"11909551512","pt":1724420630861,"mc":[{"id":"1.232174751","rc":[{"batb":[[0,2.7,9],[1,2.68,8.17],[2,2.64,23.7]],"ltp":2.64,"tv":3.02,"id":72857115}]}]}
{"op":"mcm","clk":"11909551686","pt":1724420633162,"mc":[{"id":"1.232174751","rc":[{"batb":[[0,2.7,5]],"ltp":2.64,"tv":3.02,"id":72857115}]}]}
{"op":"mcm","clk":"11909551747","pt":1724420634080,"mc":[{"id":"1.232174751","rc":[{"batb":[[0,2.68,8.17],[1,2.64,23.7],[2,1.99,5.64]],"ltp":2.64,"tv":3.02,"id":72857115}]}]}
{"op":"mcm","clk":"11909552012","pt":1724420637253,"mc":[{"id":"1.232174751","rc":[{"batb":[[0,2.7,9],[1,2.68,8.17],[2,2.64,23.7]],"ltp":2.64,"tv":3.02,"id":72857115}]}]}
{"op":"mcm","clk":"11909552216","pt":1724420639875,"mc":[{"id":"1.232174751","rc":[{"batb":[[0,2.7,5]],"ltp":2.64,"tv":3.02,"id":72857115}]}]}
{"op":"mcm","clk":"11909552299","pt":1724420640763,"mc":[{"id":"1.232174751","rc":[{"batb":[[0,2.68,8.17],[1,2.64,23.7],[2,1.99,5.64]],"ltp":2.64,"tv":3.02,"id":72857115}]}]}
{"op":"mcm","clk":"11909552867","pt":1724420648192,"mc":[{"id":"1.232174751","rc":[{"batb":[[0,2.7,9],[1,2.68,8.17],[2,2.64,23.7]],"ltp":2.64,"tv":3.02,"id":72857115}]}]}
{"op":"mcm","clk":"11909553084","pt":1724420650599,"mc":[{"id":"1.232174751","rc":[{"batb":[[0,2.7,5]],"ltp":2.64,"tv":3.02,"id":72857115}]}]}
{"op":"mcm","clk":"11909553156","pt":1724420651593,"mc":[{"id":"1.232174751","rc":[{"batb":[[0,2.68,8.17],[1,2.64,23.7],[2,1.99,5.64]],"ltp":2.64,"tv":3.02,"id":72857115}]}]}
{"op":"mcm","clk":"11909553641","pt":1724420657386,"mc":[{"id":"1.232174751","rc":[{"batb":[[0,2.7,9],[1,2.68,8.17],[2,2.64,23.7]],"ltp":2.64,"tv":3.02,"id":72857115}]}]}
{"op":"mcm","clk":"11909553902","pt":1724420660612,"mc":[{"id":"1.232174751","rc":[{"batb":[[0,2.68,8.17],[1,2.64,23.7],[2,1.99,5.64]],"ltp":2.64,"tv":3.02,"id":72857115}]}]}
{"op":"mcm","clk":"11909554151","pt":1724420663496,"mc":[{"id":"1.232174751","rc":[{"batb":[[0,2.7,9],[1,2.68,8.17],[2,2.64,23.7]],"ltp":2.64,"tv":3.02,"id":72857115}]}]}
{"op":"mcm","clk":"11909554347","pt":1724420665983,"mc":[{"id":"1.232174751","rc":[{"batb":[[0,2.7,5]],"ltp":2.64,"tv":3.02,"id":72857115}]}]}
{"op":"mcm","clk":"11909554404","pt":1724420667013,"mc":[{"id":"1.232174751","rc":[{"batb":[[0,2.68,8.17],[1,2.64,23.7],[2,1.99,5.64]],"ltp":2.64,"tv":3.02,"id":72857115}]}]}
{"op":"mcm","clk":"11909554534","pt":1724420668413,"mc":[{"id":"1.232174751","rc":[{"batb":[[0,2.7,4],[1,2.68,8.17],[2,2.64,23.7]],"ltp":2.64,"tv":3.02,"id":72857115}]}]}
{"op":"mcm","clk":"11909554786","pt":1724420671018,"mc":[{"id":"1.232174751","rc":[{"batb":[[0,2.7,5]],"ltp":2.64,"tv":3.02,"id":72857115}]}]}
{"op":"mcm","clk":"11909555114","pt":1724420674604,"mc":[{"id":"1.232174751","rc":[{"batb":[[0,2.7,4]],"ltp":2.64,"tv":3.02,"id":72857115}]}]}
{"op":"mcm","clk":"11909555302","pt":1724420676891,"mc":[{"id":"1.232174751","rc":[{"batb":[[0,2.7,5]],"ltp":2.64,"tv":3.02,"id":72857115}]}]}
{"op":"mcm","clk":"11909555592","pt":1724420680506,"mc":[{"id":"1.232174751","rc":[{"batb":[[0,2.7,4]],"ltp":2.64,"tv":3.02,"id":72857115}]}]}
{"op":"mcm","clk":"11909555813","pt":1724420682840,"mc":[{"id":"1.232174751","rc":[{"batb":[[0,2.7,5]],"ltp":2.64,"tv":3.02,"id":72857115}]}]}
{"op":"mcm","clk":"11909556026","pt":1724420685428,"mc":[{"id":"1.232174751","rc":[{"batb":[[0,2.72,4],[1,2.7,5],[2,2.68,8.17]],"ltp":2.64,"tv":3.02,"id":72857115}]}]}
{"op":"mcm","clk":"11909556093","pt":1724420686107,"mc":[{"id":"1.232174751","rc":[{"batb":[[1,2.68,8.17],[2,2.64,23.7]],"ltp":2.64,"tv":3.02,"id":72857115}]}]}
{"op":"mcm","clk":"11909556291","pt":1724420688236,"mc":[{"id":"1.232174751","rc":[{"batb":[[0,2.68,8.17],[1,2.64,23.7],[2,1.99,5.64]],"ltp":2.64,"tv":3.02,"id":72857115}]}]}
{"op":"mcm","clk":"11909556326","pt":1724420688647,"mc":[{"id":"1.232174751","rc":[{"batb":[[0,2.7,5],[1,2.68,8.17],[2,2.64,23.7]],"ltp":2.64,"tv":3.02,"id":72857115}]}]}
{"op":"mcm","clk":"11909556643","pt":1724420692106,"mc":[{"id":"1.232174751","rc":[{"batb":[[0,2.7,4]],"ltp":2.64,"tv":3.02,"id":72857115}]}]}
{"op":"mcm","clk":"11909556870","pt":1724420694541,"mc":[{"id":"1.232174751","rc":[{"batb":[[0,2.7,5]],"ltp":2.64,"tv":3.02,"id":72857115}]}]}
{"op":"mcm","clk":"11909557188","pt":1724420698026,"mc":[{"id":"1.232174751","rc":[{"batb":[[0,2.7,4]],"ltp":2.64,"tv":3.02,"id":72857115}]}]}
{"op":"mcm","clk":"11909557391","pt":1724420700449,"mc":[{"id":"1.232174751","rc":[{"batb":[[0,2.7,5]],"ltp":2.64,"tv":3.02,"id":72857115}]}]}
{"op":"mcm","clk":"11909557700","pt":1724420703636,"mc":[{"id":"1.232174751","rc":[{"batb":[[0,2.68,8.17],[1,2.64,23.7],[2,1.99,5.64]],"ltp":2.64,"tv":3.02,"id":72857115}]}]}
{"op":"mcm","clk":"11909557712","pt":1724420703736,"mc":[{"id":"1.232174751","rc":[{"batb":[[0,2.7,4],[1,2.68,8.17],[2,2.64,23.7]],"ltp":2.64,"tv":3.02,"id":72857115}]}]}
{"op":"mcm","clk":"11909557962","pt":1724420706120,"mc":[{"id":"1.232174751","rc":[{"batb":[[0,2.7,5]],"ltp":2.64,"tv":3.02,"id":72857115}]}]}
{"op":"mcm","clk":"11909558160","pt":1724420708144,"mc":[{"id":"1.232174751","rc":[{"batb":[[0,2.72,4],[1,2.7,5],[2,2.68,8.17]],"ltp":2.64,"tv":3.02,"id":72857115}]}]}
{"op":"mcm","clk":"11909558318","pt":1724420709949,"mc":[{"id":"1.232174751","rc":[{"batb":[[1,2.68,8.17],[2,2.64,23.7]],"ltp":2.64,"tv":3.02,"id":72857115}]}]}
{"op":"mcm","clk":"11909558404","pt":1724420710730,"mc":[{"id":"1.232174751","rc":[{"batb":[[0,2.68,8.17],[1,2.64,23.7],[2,1.99,5.64]],"ltp":2.64,"tv":3.02,"id":72857115}]}]}
{"op":"mcm","clk":"11909559965","pt":1724420727891,"mc":[{"id":"1.232174751","rc":[{"batb":[[0,2.7,9],[1,2.68,8.17],[2,2.64,23.7]],"ltp":2.64,"tv":3.02,"id":72857115}]}]}
{"op":"mcm","clk":"11909560193","pt":1724420730369,"mc":[{"id":"1.232174751","rc":[{"batb":[[0,2.7,5]],"ltp":2.64,"tv":3.02,"id":72857115}]}]}
{"op":"mcm","clk":"11909560303","pt":1724420731453,"mc":[{"id":"1.232174751","rc":[{"batb":[[0,2.68,8.17],[1,2.64,23.7],[2,1.99,5.64]],"ltp":2.64,"tv":3.02,"id":72857115}]}]}
{"op":"mcm","clk":"11909561177","pt":1724420741377,"mc":[{"id":"1.232174751","rc":[{"batb":[[0,2.7,9],[1,2.68,8.17],[2,2.64,23.7]],"ltp":2.64,"tv":3.02,"id":72857115}]}]}
{"op":"mcm","clk":"11909561402","pt":1724420743874,"mc":[{"id":"1.232174751","rc":[{"batb":[[0,2.7,5]],"ltp":2.64,"tv":3.02,"id":72857115}]}]}
{"op":"mcm","clk":"11909561484","pt":1724420744895,"mc":[{"id":"1.232174751","rc":[{"batb":[[0,2.68,8.17],[1,2.64,23.7],[2,1.99,5.64]],"ltp":2.64,"tv":3.02,"id":72857115}]}]}
{"op":"mcm","clk":"11909562231","pt":1724420752814,"mc":[{"id":"1.232174751","rc":[{"batb":[[0,2.7,9],[1,2.68,8.17],[2,2.64,23.7]],"ltp":2.64,"tv":3.02,"id":72857115}]}]}
{"op":"mcm","clk":"11909562418","pt":1724420755292,"mc":[{"id":"1.232174751","rc":[{"batb":[[0,2.7,5]],"ltp":2.64,"tv":3.02,"id":72857115}]}]}
{"op":"mcm","clk":"11909562482","pt":1724420756327,"mc":[{"id":"1.232174751","rc":[{"batb":[[0,2.68,8.17],[1,2.64,23.7],[2,1.99,5.64]],"ltp":2.64,"tv":3.02,"id":72857115}]}]}
{"op":"mcm","clk":"11909562999","pt":1724420762135,"mc":[{"id":"1.232174751","rc":[{"batb":[[0,2.7,9],[1,2.68,8.17],[2,2.64,23.7]],"ltp":2.64,"tv":3.02,"id":72857115}]}]}
{"op":"mcm","clk":"11909563202","pt":1724420764407,"mc":[{"id":"1.232174751","rc":[{"batb":[[0,2.7,5]],"ltp":2.64,"tv":3.02,"id":72857115}]}]}
{"op":"mcm","clk":"11909563289","pt":1724420765438,"mc":[{"id":"1.232174751","rc":[{"batb":[[0,2.68,8.17],[1,2.64,23.7],[2,1.99,5.64]],"ltp":2.64,"tv":3.02,"id":72857115}]}]}
{"op":"mcm","clk":"11909564574","pt":1724420780447,"mc":[{"id":"1.232174751","rc":[{"batb":[[0,2.7,9],[1,2.68,8.17],[2,2.64,23.7]],"ltp":2.64,"tv":3.02,"id":72857115}]}]}
{"op":"mcm","clk":"11909564816","pt":1724420782727,"mc":[{"id":"1.232174751","rc":[{"batb":[[0,2.7,5]],"ltp":2.64,"tv":3.02,"id":72857115}]}]}
{"op":"mcm","clk":"11909564929","pt":1724420783964,"mc":[{"id":"1.232174751","rc":[{"batb":[[0,2.68,8.17],[1,2.64,23.7],[2,1.99,5.64]],"ltp":2.64,"tv":3.02,"id":72857115}]}]}
{"op":"mcm","clk":"11909565242","pt":1724420787724,"mc":[{"id":"1.232174751","rc":[{"batb":[[0,2.7,9],[1,2.68,8.17],[2,2.64,23.7]],"ltp":2.64,"tv":3.02,"id":72857115}]}]}
{"op":"mcm","clk":"11909565462","pt":1724420790157,"mc":[{"id":"1.232174751","rc":[{"batb":[[0,2.7,5]],"ltp":2.64,"tv":3.02,"id":72857115}]}]}
{"op":"mcm","clk":"11909565553","pt":1724420791158,"mc":[{"id":"1.232174751","rc":[{"batb":[[0,2.68,8.17],[1,2.64,23.7],[2,1.99,5.64]],"ltp":2.64,"tv":3.02,"id":72857115}]}]}
{"op":"mcm","clk":"11909566209","pt":1724420798055,"mc":[{"id":"1.232174751","rc":[{"batb":[[0,2.7,9],[1,2.68,8.17],[2,2.64,23.7]],"ltp":2.64,"tv":3.02,"id":72857115}]}]}
{"op":"mcm","clk":"11909566403","pt":1724420800392,"mc":[{"id":"1.232174751","rc":[{"batb":[[0,2.7,5]],"ltp":2.64,"tv":3.02,"id":72857115}]}]}
{"op":"mcm","clk":"11909566498","pt":1724420801378,"mc":[{"id":"1.232174751","rc":[{"batb":[[0,2.68,8.17],[1,2.64,23.7],[2,1.99,5.64]],"ltp":2.64,"tv":3.02,"id":72857115}]}]}
{"op":"mcm","clk":"11909566970","pt":1724420807079,"mc":[{"id":"1.232174751","rc":[{"batb":[[0,2.7,9],[1,2.68,8.17],[2,2.64,23.7]],"ltp":2.64,"tv":3.02,"id":72857115}]}]}
{"op":"mcm","clk":"11909567185","pt":1724420809576,"mc":[{"id":"1.232174751","rc":[{"batb":[[0,2.7,5]],"ltp":2.64,"tv":3.02,"id":72857115}]}]}
{"op":"mcm","clk":"11909567286","pt":1724420810607,"mc":[{"id":"1.232174751","rc":[{"batb":[[0,2.68,8.17],[1,2.64,23.7],[2,1.99,5.64]],"ltp":2.64,"tv":3.02,"id":72857115}]}]}
{"op":"mcm","clk":"11909567418","pt":1724420812168,"mc":[{"id":"1.232174751","rc":[{"batb":[[0,2.7,4],[1,2.68,8.17],[2,2.64,23.7]],"ltp":2.64,"tv":3.02,"id":72857115}]}]}
{"op":"mcm","clk":"11909567643","pt":1724420814900,"mc":[{"id":"1.232174751","rc":[{"batb":[[0,2.7,5]],"ltp":2.64,"tv":3.02,"id":72857115}]}]}
{"op":"mcm","clk":"11909567908","pt":1724420818272,"mc":[{"id":"1.232174751","rc":[{"batb":[[0,2.7,4]],"ltp":2.64,"tv":3.02,"id":72857115}]}]}
{"op":"mcm","clk":"11909568079","pt":1724420820491,"mc":[{"id":"1.232174751","rc":[{"batb":[[0,2.68,8.17],[1,2.64,23.7],[2,1.99,5.64]],"ltp":2.64,"tv":3.02,"id":72857115}]}]}
{"op":"mcm","clk":"11909568096","pt":1724420820700,"mc":[{"id":"1.232174751","rc":[{"batb":[[0,2.7,5],[1,2.68,8.17],[2,2.64,23.7]],"ltp":2.64,"tv":3.02,"id":72857115}]}]}
{"op":"mcm","clk":"11909568395","pt":1724420824083,"mc":[{"id":"1.232174751","rc":[{"batb":[[0,2.7,4]],"ltp":2.64,"tv":3.02,"id":72857115}]}]}
{"op":"mcm","clk":"11909568620","pt":1724420826508,"mc":[{"id":"1.232174751","rc":[{"batb":[[0,2.7,5]],"ltp":2.64,"tv":3.02,"id":72857115}]}]}
{"op":"mcm","clk":"11909568879","pt":1724420829826,"mc":[{"id":"1.232174751","rc":[{"batb":[[0,2.72,4]],"ltp":2.64,"tv":3.02,"id":72857115}]}]}
{"op":"mcm","clk":"11909569141","pt":1724420832454,"mc":[{"id":"1.232174751","rc":[{"batb":[[0,2.7,5]],"ltp":2.64,"tv":3.02,"id":72857115}]}]}
{"op":"mcm","clk":"11909569423","pt":1724420835701,"mc":[{"id":"1.232174751","rc":[{"batb":[[0,2.72,4]],"ltp":2.64,"tv":3.02,"id":72857115}]}]}
{"op":"mcm","clk":"11909569671","pt":1724420838406,"mc":[{"id":"1.232174751","rc":[{"batb":[[0,2.7,5]],"ltp":2.64,"tv":3.02,"id":72857115}]}]}
{"op":"mcm","clk":"11909569875","pt":1724420840527,"mc":[{"id":"1.232174751","rc":[{"batb":[[0,2.72,4],[1,2.7,5],[2,2.68,8.17]],"ltp":2.64,"tv":3.02,"id":72857115}]}]}
{"op":"mcm","clk":"11909570000","pt":1724420841560,"mc":[{"id":"1.232174751","rc":[{"batb":[[1,2.68,8.17],[2,2.64,23.7]],"ltp":2.64,"tv":3.02,"id":72857115}]}]}
{"op":"mcm","clk":"11909570145","pt":1724420843044,"mc":[{"id":"1.232174751","rc":[{"batb":[[0,2.68,8.17],[1,2.64,23.7],[2,1.99,5.64]],"ltp":2.64,"tv":3.02,"id":72857115}]}]}
