{"op":"mcm","clk":"11891236395","pt":1723826703484,"mc":[{"id":"1.231893357","marketDefinition":{"bspMarket":false,"turnInPlayEnabled":true,"persistenceEnabled":true,"marketBaseRate":5.0,"eventId":"33500951","eventTypeId":"4","numberOfWinners":1,"bettingType":"ODDS","marketType":"MATCH_ODDS","marketTime":"2024-08-22T10:00:00.000Z","suspendTime":"2024-08-22T10:00:00.000Z","bspReconciled":false,"complete":true,"inPlay":false,"crossMatching":false,"runnersVoidable":false,"numberOfActiveRunners":3,"betDelay":0,"status":"OPEN","runners":[{"status":"ACTIVE","sortPriority":1,"id":31375,"name":"Derbyshire"},{"status":"ACTIVE","sortPriority":2,"id":169,"name":"Glamorgan"},{"status":"ACTIVE","sortPriority":3,"id":60443,"name":"The Draw"}],"regulators":["MR_INT"],"countryCode":"GB","discountAllowed":false,"timezone":"GMT","openDate":"2024-08-22T10:00:00.000Z","version":6077162143,"name":"Match Odds","eventName":"Derbyshire v Glamorgan"},"rc":[{"batb":[[0,1.01,20]],"ltp":0.0,"tv":0.0,"id":169},{"batb":[[0,1.01,20]],"ltp":0.0,"tv":0.0,"id":60443},{"batb":[[0,1.01,20]],"ltp":0.0,"tv":0.0,"id":31375}]}]}
{"op":"mcm","clk":"11891236509","pt":1723826704067,"mc":[{"id":"1.231893357","rc":[{"batb":[[0,1.03,200],[1,1.02,200],[2,1.01,220]],"ltp":0.0,"tv":0.0,"id":169},{"batb":[[0,1.03,200],[1,1.02,200],[2,1.01,220]],"ltp":0.0,"tv":0.0,"id":60443},{"batb":[[0,1.03,200],[1,1.02,200],[2,1.01,220]],"ltp":0.0,"tv":0.0,"id":31375}]}]}
{"op":"mcm","clk":"11891236698","pt":1723826705032,"mc":[{"id":"1.231893357","marketDefinition":{"bspMarket":false,"turnInPlayEnabled":true,"persistenceEnabled":true,"marketBaseRate":5.0,"eventId":"33500951","eventTypeId":"4","numberOfWinners":1,"bettingType":"ODDS","marketType":"MATCH_ODDS","marketTime":"2024-08-22T10:00:00.000Z","suspendTime":"2024-08-22T10:00:00.000Z","bspReconciled":false,"complete":true,"inPlay":false,"crossMatching":false,"runnersVoidable":false,"numberOfActiveRunners":3,"betDelay":0,"status":"OPEN","runners":[{"status":"ACTIVE","sortPriority":1,"id":31375,"name":"Derbyshire"},{"status":"ACTIVE","sortPriority":2,"id":169,"name":"Glamorgan"},{"status":"ACTIVE","sortPriority":3,"id":60443,"name":"The Draw"}],"regulators":["MR_INT"],"countryCode":"GB","discountAllowed":true,"timezone":"GMT","openDate":"2024-08-22T10:00:00.000Z","version":6077162143,"name":"Match Odds","eventName":"Derbyshire v Glamorgan"}}]}
{"op":"mcm","clk":"11891890659","pt":1723830530542,"mc":[{"id":"1.231893357","rc":[{"batb":[[0,1.25,100],[1,1.03,200],[2,1.02,200]],"ltp":0.0,"tv":0.0,"id":169},{"batb":[[0,1.25,100],[1,1.03,200],[2,1.02,200]],"ltp":0.0,"tv":0.0,"id":60443},{"batb":[[0,1.25,100],[1,1.03,200],[2,1.02,200]],"ltp":0.0,"tv":0.0,"id":31375}]}]}
{"op":"mcm","clk":"11891892113","pt":1723830540441,"mc":[{"id":"1.231893357","rc":[{"batb":[[0,1.03,200],[1,1.02,200],[2,1.01,220]],"ltp":0.0,"tv":0.0,"id":169},{"batb":[[0,1.03,200],[1,1.02,200],[2,1.01,220]],"ltp":0.0,"tv":0.0,"id":60443},{"batb":[[0,1.03,200],[1,1.02,200],[2,1.01,220]],"ltp":0.0,"tv":0.0,"id":31375}]}]}
{"op":"mcm","clk":"11891892820","pt":1723830544876,"mc":[{"id":"1.231893357","rc":[{"batl":[[0,95,5]],"ltp":0.0,"tv":0.0,"id":169},{"batl":[[0,95,5]],"ltp":0.0,"tv":0.0,"id":60443},{"batl":[[0,95,5]],"ltp":0.0,"tv":0.0,"id":31375}]}]}
{"op":"mcm","clk":"11891892986","pt":1723830545933,"mc":[{"id":"1.231893357","rc":[{"batb":[[0,1.04,500],[1,1.03,200],[2,1.02,200]],"batl":[[1,990,5]],"ltp":0.0,"tv":0.0,"id":169},{"batb":[[0,1.04,500],[1,1.03,200],[2,1.02,200]],"batl":[[1,990,5]],"ltp":0.0,"tv":0.0,"id":60443},{"batb":[[0,1.04,500],[1,1.03,200],[2,1.02,200]],"batl":[[1,990,5]],"ltp":0.0,"tv":0.0,"id":31375}]}]}
{"op":"mcm","clk":"11893652538","pt":1723841919883,"mc":[{"id":"1.231893357","marketDefinition":{"bspMarket":false,"turnInPlayEnabled":true,"persistenceEnabled":true,"marketBaseRate":5.0,"eventId":"33500951","eventTypeId":"4","numberOfWinners":1,"bettingType":"ODDS","marketType":"MATCH_ODDS","marketTime":"2024-08-22T10:00:00.000Z","suspendTime":"2024-08-22T10:00:00.000Z","bspReconciled":false,"complete":true,"inPlay":false,"crossMatching":true,"runnersVoidable":false,"numberOfActiveRunners":3,"betDelay":0,"status":"OPEN","runners":[{"status":"ACTIVE","sortPriority":1,"id":31375,"name":"Derbyshire"},{"status":"ACTIVE","sortPriority":2,"id":169,"name":"Glamorgan"},{"status":"ACTIVE","sortPriority":3,"id":60443,"name":"The Draw"}],"regulators":["MR_INT"],"countryCode":"GB","discountAllowed":true,"timezone":"GMT","openDate":"2024-08-22T10:00:00.000Z","version":6077162143,"name":"Match Odds","eventName":"Derbyshire v Glamorgan"}}]}
{"op":"mcm","clk":"11898458034","pt":1723900099835,"mc":[{"id":"1.231893357","rc":[{"batb":[[0,1.05,44.3],[1,1.04,500],[2,1.03,200]],"batl":[[0,95,5.85]],"ltp":0.0,"tv":0.0,"id":169},{"batb":[[0,1.05,44.3],[1,1.04,500],[2,1.03,200]],"batl":[[0,95,5.85]],"ltp":0.0,"tv":0.0,"id":60443},{"batb":[[0,1.05,44.3],[1,1.04,500],[2,1.03,200]],"batl":[[0,95,5.85]],"ltp":0.0,"tv":0.0,"id":31375}]}]}
{"op":"mcm","clk":"11898480610","pt":1723900228271,"mc":[{"id":"1.231893357","rc":[{"batb":[[0,1.06,142.66],[1,1.05,44.3],[2,1.04,500]],"ltp":0.0,"tv":0.0,"id":169},{"batb":[[0,1.06,142.66],[1,1.05,44.3],[2,1.04,500]],"ltp":0.0,"tv":0.0,"id":60443},{"batb":[[0,1.06,142.66],[1,1.05,44.3],[2,1.04,500]],"ltp":0.0,"tv":0.0,"id":31375}]}]}
{"op":"mcm","clk":"11898776729","pt":1723902028666,"mc":[{"id":"1.231893357","rc":[{"batb":[[0,1.05,44.3],[1,1.04,500],[2,1.03,200]],"ltp":0.0,"tv":0.0,"id":169},{"batb":[[0,1.05,44.3],[1,1.04,500],[2,1.03,200]],"ltp":0.0,"tv":0.0,"id":60443},{"batb":[[0,1.05,44.3],[1,1.04,500],[2,1.03,200]],"ltp":0.0,"tv":0.0,"id":31375}]}]}
{"op":"mcm","clk":"11898779184","pt":1723902042507,"mc":[{"id":"1.231893357","rc":[{"batb":[[0,1.06,142.66],[1,1.05,44.3],[2,1.04,500]],"ltp":0.0,"tv":0.0,"id":169},{"batb":[[0,1.06,142.66],[1,1.05,44.3],[2,1.04,500]],"ltp":0.0,"tv":0.0,"id":60443},{"batb":[[0,1.06,142.66],[1,1.05,44.3],[2,1.04,500]],"ltp":0.0,"tv":0.0,"id":31375}]}]}
{"op":"mcm","clk":"11899115488","pt":1723903842844,"mc":[{"id":"1.231893357","rc":[{"batb":[[0,1.05,44.3],[1,1.04,500],[2,1.03,200]],"ltp":0.0,"tv":0.0,"id":169}]}]}
{"op":"mcm","clk":"11899115632","pt":1723903843268,"mc":[{"id":"1.231893357","rc":[{"batb":[[0,1.05,44.3],[1,1.04,500],[2,1.03,200]],"ltp":0.0,"tv":0.0,"id":60443},{"batb":[[0,1.05,44.3],[1,1.04,500],[2,1.03,200]],"ltp":0.0,"tv":0.0,"id":31375}]}]}
{"op":"mcm","clk":"11899172731","pt":1723903998168,"mc":[{"id":"1.231893357","rc":[{"batb":[[0,1.06,142.66],[1,1.05,44.3],[2,1.04,500]],"ltp":0.0,"tv":0.0,"id":169},{"batb":[[0,1.06,142.66],[1,1.05,44.3],[2,1.04,500]],"ltp":0.0,"tv":0.0,"id":60443},{"batb":[[0,1.06,142.66],[1,1.05,44.3],[2,1.04,500]],"ltp":0.0,"tv":0.0,"id":31375}]}]}
{"op":"mcm","clk":"11899668064","pt":1723905798894,"mc":[{"id":"1.231893357","rc":[{"batb":[[0,1.05,44.3],[1,1.04,500],[2,1.03,200]],"ltp":0.0,"tv":0.0,"id":169},{"batb":[[0,1.05,44.3],[1,1.04,500],[2,1.03,200]],"ltp":0.0,"tv":0.0,"id":60443},{"batb":[[0,1.05,44.3],[1,1.04,500],[2,1.03,200]],"ltp":0.0,"tv":0.0,"id":31375}]}]}
{"op":"mcm","clk":"11899702607","pt":1723905929599,"mc":[{"id":"1.231893357","rc":[{"batb":[[0,1.06,142.66],[1,1.05,44.3],[2,1.04,500]],"ltp":0.0,"tv":0.0,"id":169},{"batb":[[0,1.06,142.66],[1,1.05,44.3],[2,1.04,500]],"ltp":0.0,"tv":0.0,"id":60443},{"batb":[[0,1.06,142.66],[1,1.05,44.3],[2,1.04,500]],"ltp":0.0,"tv":0.0,"id":31375}]}]}
{"op":"mcm","clk":"11900103392","pt":1723907729963,"mc":[{"id":"1.231893357","rc":[{"batb":[[0,1.05,44.3],[1,1.04,500],[2,1.03,200]],"ltp":0.0,"tv":0.0,"id":60443},{"batb":[[0,1.05,44.3],[1,1.04,500],[2,1.03,200]],"ltp":0.0,"tv":0.0,"id":31375}]}]}
{"op":"mcm","clk":"11900103644","pt":1723907730882,"mc":[{"id":"1.231893357","rc":[{"batb":[[0,1.05,44.3],[1,1.04,500],[2,1.03,200]],"ltp":0.0,"tv":0.0,"id":169}]}]}
{"op":"mcm","clk":"11900127129","pt":1723907817491,"mc":[{"id":"1.231893357","rc":[{"batb":[[0,1.06,142.66],[1,1.05,44.3],[2,1.04,500]],"ltp":0.0,"tv":0.0,"id":169},{"batb":[[0,1.06,142.66],[1,1.05,44.3],[2,1.04,500]],"ltp":0.0,"tv":0.0,"id":60443},{"batb":[[0,1.06,142.66],[1,1.05,44.3],[2,1.04,500]],"ltp":0.0,"tv":0.0,"id":31375}]}]}
{"op":"mcm","clk":"11900519706","pt":1723909369579,"mc":[{"id":"1.231893357","rc":[{"batb":[[0,1.07,44.3],[1,1.06,142.66]],"ltp":0.0,"tv":0.0,"id":169},{"batb":[[0,1.07,44.3],[1,1.06,142.66]],"ltp":0.0,"tv":0.0,"id":60443},{"batb":[[0,1.07,44.3],[1,1.06,142.66]],"ltp":0.0,"tv":0.0,"id":31375}]}]}
{"op":"mcm","clk":"11900596093","pt":1723909617992,"mc":[{"id":"1.231893357","rc":[{"batb":[[1,1.04,500],[2,1.03,200]],"ltp":0.0,"tv":0.0,"id":169},{"batb":[[1,1.04,500],[2,1.03,200]],"ltp":0.0,"tv":0.0,"id":60443},{"batb":[[1,1.04,500],[2,1.03,200]],"ltp":0.0,"tv":0.0,"id":31375}]}]}
{"op":"mcm","clk":"11900606186","pt":1723909664929,"mc":[{"id":"1.231893357","rc":[{"batb":[[0,1.08,106.99],[1,1.07,44.3],[2,1.04,500]],"ltp":0.0,"tv":0.0,"id":169},{"batb":[[0,1.08,106.99],[1,1.07,44.3],[2,1.04,500]],"ltp":0.0,"tv":0.0,"id":60443},{"batb":[[0,1.08,106.99],[1,1.07,44.3],[2,1.04,500]],"ltp":0.0,"tv":0.0,"id":31375}]}]}
{"op":"mcm","clk":"11900927375","pt":1723911465197,"mc":[{"id":"1.231893357","rc":[{"batb":[[0,1.07,44.3],[1,1.04,500],[2,1.03,200]],"ltp":0.0,"tv":0.0,"id":169}]}]}
{"op":"mcm","clk":"11900927580","pt":1723911466394,"mc":[{"id":"1.231893357","rc":[{"batb":[[0,1.07,44.3],[1,1.04,500],[2,1.03,200]],"ltp":0.0,"tv":0.0,"id":60443},{"batb":[[0,1.07,44.3],[1,1.04,500],[2,1.03,200]],"ltp":0.0,"tv":0.0,"id":31375}]}]}
{"op":"mcm","clk":"11900938797","pt":1723911532485,"mc":[{"id":"1.231893357","rc":[{"batb":[[0,1.08,106.99],[1,1.07,44.3],[2,1.04,500]],"ltp":0.0,"tv":0.0,"id":169},{"batb":[[0,1.08,106.99],[1,1.07,44.3],[2,1.04,500]],"ltp":0.0,"tv":0.0,"id":60443},{"batb":[[0,1.08,106.99],[1,1.07,44.3],[2,1.04,500]],"ltp":0.0,"tv":0.0,"id":31375}]}]}
{"op":"mcm","clk":"11901262772","pt":1723913332809,"mc":[{"id":"1.231893357","rc":[{"batb":[[0,1.07,44.3],[1,1.04,500],[2,1.03,200]],"ltp":0.0,"tv":0.0,"id":169},{"batb":[[0,1.07,44.3],[1,1.04,500],[2,1.03,200]],"ltp":0.0,"tv":0.0,"id":31375}]}]}
{"op":"mcm","clk":"11901262949","pt":1723913333700,"mc":[{"id":"1.231893357","rc":[{"batb":[[0,1.07,44.3],[1,1.04,500],[2,1.03,200]],"ltp":0.0,"tv":0.0,"id":60443}]}]}
{"op":"mcm","clk":"11901281179","pt":1723913437414,"mc":[{"id":"1.231893357","rc":[{"batb":[[0,1.08,106.99],[1,1.07,44.3],[2,1.04,500]],"ltp":0.0,"tv":0.0,"id":169},{"batb":[[0,1.08,106.99],[1,1.07,44.3],[2,1.04,500]],"ltp":0.0,"tv":0.0,"id":60443},{"batb":[[0,1.08,106.99],[1,1.07,44.3],[2,1.04,500]],"ltp":0.0,"tv":0.0,"id":31375}]}]}
{"op":"mcm","clk":"11901597761","pt":1723915238023,"mc":[{"id":"1.231893357","rc":[{"batb":[[0,1.07,44.3],[1,1.04,500],[2,1.03,200]],"ltp":0.0,"tv":0.0,"id":169},{"batb":[[0,1.07,44.3],[1,1.04,500],[2,1.03,200]],"ltp":0.0,"tv":0.0,"id":60443},{"batb":[[0,1.07,44.3],[1,1.04,500],[2,1.03,200]],"ltp":0.0,"tv":0.0,"id":31375}]}]}
{"op":"mcm","clk":"11901604659","pt":1723915275768,"mc":[{"id":"1.231893357","rc":[{"batb":[[0,1.08,106.99],[1,1.07,44.3],[2,1.04,500]],"ltp":0.0,"tv":0.0,"id":169},{"batb":[[0,1.08,106.99],[1,1.07,44.3],[2,1.04,500]],"ltp":0.0,"tv":0.0,"id":60443},{"batb":[[0,1.08,106.99],[1,1.07,44.3],[2,1.04,500]],"ltp":0.0,"tv":0.0,"id":31375}]}]}
{"op":"mcm","clk":"11901926975","pt":1723917075976,"mc":[{"id":"1.231893357","rc":[{"batb":[[0,1.07,44.3],[1,1.04,500],[2,1.03,200]],"ltp":0.0,"tv":0.0,"id":60443}]}]}
{"op":"mcm","clk":"11901927037","pt":1723917076252,"mc":[{"id":"1.231893357","rc":[{"batb":[[0,1.07,44.3],[1,1.04,500],[2,1.03,200]],"ltp":0.0,"tv":0.0,"id":169},{"batb":[[0,1.07,44.3],[1,1.04,500],[2,1.03,200]],"ltp":0.0,"tv":0.0,"id":31375}]}]}
{"op":"mcm","clk":"11901951362","pt":1723917210929,"mc":[{"id":"1.231893357","rc":[{"batb":[[0,1.08,106.99],[1,1.07,44.3],[2,1.04,500]],"ltp":0.0,"tv":0.0,"id":169},{"batb":[[0,1.08,106.99],[1,1.07,44.3],[2,1.04,500]],"ltp":0.0,"tv":0.0,"id":60443},{"batb":[[0,1.08,106.99],[1,1.07,44.3],[2,1.04,500]],"ltp":0.0,"tv":0.0,"id":31375}]}]}
{"op":"mcm","clk":"11902303250","pt":1723919011346,"mc":[{"id":"1.231893357","rc":[{"batb":[[0,1.07,44.3],[1,1.04,500],[2,1.03,200]],"ltp":0.0,"tv":0.0,"id":169},{"batb":[[0,1.07,44.3],[1,1.04,500],[2,1.03,200]],"ltp":0.0,"tv":0.0,"id":60443}]}]}
{"op":"mcm","clk":"11902303434","pt":1723919012146,"mc":[{"id":"1.231893357","rc":[{"batb":[[0,1.07,44.3],[1,1.04,500],[2,1.03,200]],"ltp":0.0,"tv":0.0,"id":31375}]}]}
{"op":"mcm","clk":"11902321576","pt":1723919090070,"mc":[{"id":"1.231893357","rc":[{"batb":[[0,1.08,106.99],[1,1.07,44.3],[2,1.04,500]],"ltp":0.0,"tv":0.0,"id":169},{"batb":[[0,1.08,106.99],[1,1.07,44.3],[2,1.04,500]],"ltp":0.0,"tv":0.0,"id":60443},{"batb":[[0,1.08,106.99],[1,1.07,44.3],[2,1.04,500]],"ltp":0.0,"tv":0.0,"id":31375}]}]}
{"op":"mcm","clk":"11902728102","pt":1723920890557,"mc":[{"id":"1.231893357","rc":[{"batb":[[0,1.07,44.3],[1,1.04,500],[2,1.03,200]],"ltp":0.0,"tv":0.0,"id":169},{"batb":[[0,1.07,44.3],[1,1.04,500],[2,1.03,200]],"ltp":0.0,"tv":0.0,"id":31375}]}]}
{"op":"mcm","clk":"11902728224","pt":1723920891169,"mc":[{"id":"1.231893357","rc":[{"batb":[[0,1.07,44.3],[1,1.04,500],[2,1.03,200]],"ltp":0.0,"tv":0.0,"id":60443}]}]}
{"op":"mcm","clk":"11902731465","pt":1723920907886,"mc":[{"id":"1.231893357","rc":[{"batb":[[0,1.08,106.99],[1,1.07,44.3],[2,1.04,500]],"ltp":0.0,"tv":0.0,"id":169},{"batb":[[0,1.08,106.99],[1,1.07,44.3],[2,1.04,500]],"ltp":0.0,"tv":0.0,"id":60443},{"batb":[[0,1.08,106.99],[1,1.07,44.3],[2,1.04,500]],"ltp":0.0,"tv":0.0,"id":31375}]}]}
{"op":"mcm","clk":"11902765127","pt":1723921094465,"mc":[{"id":"1.231893357","rc":[{"batb":[[2,1.03,200]],"ltp":0.0,"tv":0.0,"id":60443}]}]}
{"op":"mcm","clk":"11902765385","pt":1723921095927,"mc":[{"id":"1.231893357","rc":[{"batb":[[2,1.03,200]],"ltp":0.0,"tv":0.0,"id":169}]}]}
{"op":"mcm","clk":"11902765600","pt":1723921097051,"mc":[{"id":"1.231893357","rc":[{"batb":[[2,1.03,200]],"ltp":0.0,"tv":0.0,"id":31375}]}]}
{"op":"mcm","clk":"11902765968","pt":1723921098831,"mc":[{"id":"1.231893357","rc":[{"batb":[[0,1.09,222.22],[1,1.08,106.99],[2,1.07,44.3]],"ltp":0.0,"tv":0.0,"id":31375}]}]}
{"op":"mcm","clk":"11902766286","pt":1723921100638,"mc":[{"id":"1.231893357","rc":[{"batb":[[0,1.09,222.22],[1,1.08,106.99],[2,1.07,44.3]],"ltp":0.0,"tv":0.0,"id":169}]}]}
{"op":"mcm","clk":"11902766576","pt":1723921102253,"mc":[{"id":"1.231893357","rc":[{"batb":[[0,1.09,222.22],[1,1.08,106.99],[2,1.07,44.3]],"ltp":0.0,"tv":0.0,"id":60443}]}]}
{"op":"mcm","clk":"11903104765","pt":1723922708315,"mc":[{"id":"1.231893357","rc":[{"batb":[[1,1.07,44.3],[2,1.03,200]],"ltp":0.0,"tv":0.0,"id":169},{"batb":[[1,1.07,44.3],[2,1.03,200]],"ltp":0.0,"tv":0.0,"id":31375}]}]}
{"op":"mcm","clk":"11903104958","pt":1723922709130,"mc":[{"id":"1.231893357","rc":[{"batb":[[1,1.07,44.3],[2,1.03,200]],"ltp":0.0,"tv":0.0,"id":60443}]}]}
{"op":"mcm","clk":"11903129222","pt":1723922814715,"mc":[{"id":"1.231893357","rc":[{"batb":[[0,1.1,85.6],[1,1.09,222.22],[2,1.07,44.3]],"ltp":0.0,"tv":0.0,"id":169},{"batb":[[0,1.1,85.6],[1,1.09,222.22],[2,1.07,44.3]],"ltp":0.0,"tv":0.0,"id":60443},{"batb":[[0,1.1,85.6],[1,1.09,222.22],[2,1.07,44.3]],"ltp":0.0,"tv":0.0,"id":31375}]}]}
{"op":"mcm","clk":"11903474912","pt":1723924615019,"mc":[{"id":"1.231893357","rc":[{"batb":[[0,1.09,222.22],[1,1.07,44.3],[2,1.03,200]],"ltp":0.0,"tv":0.0,"id":60443}]}]}
{"op":"mcm","clk":"11903475093","pt":1723924616029,"mc":[{"id":"1.231893357","rc":[{"batb":[[0,1.09,222.22],[1,1.07,44.3],[2,1.03,200]],"ltp":0.0,"tv":0.0,"id":169},{"batb":[[0,1.09,222.22],[1,1.07,44.3],[2,1.03,200]],"ltp":0.0,"tv":0.0,"id":31375}]}]}
{"op":"mcm","clk":"11903486090","pt":1723924682930,"mc":[{"id":"1.231893357","rc":[{"batb":[[0,1.1,85.6],[1,1.09,222.22],[2,1.07,44.3]],"ltp":0.0,"tv":0.0,"id":169},{"batb":[[0,1.1,85.6],[1,1.09,222.22],[2,1.07,44.3]],"ltp":0.0,"tv":0.0,"id":60443},{"batb":[[0,1.1,85.6],[1,1.09,222.22],[2,1.07,44.3]],"ltp":0.0,"tv":0.0,"id":31375}]}]}
{"op":"mcm","clk":"11903805576","pt":1723926483955,"mc":[{"id":"1.231893357","rc":[{"batb":[[0,1.09,222.22],[1,1.07,44.3],[2,1.03,200]],"ltp":0.0,"tv":0.0,"id":169},{"batb":[[0,1.09,222.22],[1,1.07,44.3],[2,1.03,200]],"ltp":0.0,"tv":0.0,"id":60443}]}]}
{"op":"mcm","clk":"11903805611","pt":1723926484144,"mc":[{"id":"1.231893357","rc":[{"batb":[[0,1.09,222.22],[1,1.07,44.3],[2,1.03,200]],"ltp":0.0,"tv":0.0,"id":31375}]}]}
{"op":"mcm","clk":"11903821510","pt":1723926591707,"mc":[{"id":"1.231893357","rc":[{"batb":[[0,1.1,85.6],[1,1.09,222.22],[2,1.07,44.3]],"ltp":0.0,"tv":0.0,"id":169},{"batb":[[0,1.1,85.6],[1,1.09,222.22],[2,1.07,44.3]],"ltp":0.0,"tv":0.0,"id":60443},{"batb":[[0,1.1,85.6],[1,1.09,222.22],[2,1.07,44.3]],"ltp":0.0,"tv":0.0,"id":31375}]}]}
{"op":"mcm","clk":"11904035165","pt":1723928392427,"mc":[{"id":"1.231893357","rc":[{"batb":[[0,1.09,222.22],[1,1.07,44.3],[2,1.03,200]],"ltp":0.0,"tv":0.0,"id":169},{"batb":[[0,1.09,222.22],[1,1.07,44.3],[2,1.03,200]],"ltp":0.0,"tv":0.0,"id":60443},{"batb":[[0,1.09,222.22],[1,1.07,44.3],[2,1.03,200]],"ltp":0.0,"tv":0.0,"id":31375}]}]}
{"op":"mcm","clk":"11904038032","pt":1723928423459,"mc":[{"id":"1.231893357","rc":[{"batb":[[0,1.1,85.6],[1,1.09,222.22],[2,1.07,44.3]],"ltp":0.0,"tv":0.0,"id":169},{"batb":[[0,1.1,85.6],[1,1.09,222.22],[2,1.07,44.3]],"ltp":0.0,"tv":0.0,"id":60443},{"batb":[[0,1.1,85.6],[1,1.09,222.22],[2,1.07,44.3]],"ltp":0.0,"tv":0.0,"id":31375}]}]}
{"op":"mcm","clk":"11904192773","pt":1723930223829,"mc":[{"id":"1.231893357","rc":[{"batb":[[0,1.09,222.22],[1,1.07,44.3],[2,1.03,200]],"ltp":0.0,"tv":0.0,"id":60443}]}]}
{"op":"mcm","clk":"11904192833","pt":1723930224199,"mc":[{"id":"1.231893357","rc":[{"batb":[[0,1.09,222.22],[1,1.07,44.3],[2,1.03,200]],"ltp":0.0,"tv":0.0,"id":169},{"batb":[[0,1.09,222.22],[1,1.07,44.3],[2,1.03,200]],"ltp":0.0,"tv":0.0,"id":31375}]}]}
{"op":"mcm","clk":"11904197623","pt":1723930271977,"mc":[{"id":"1.231893357","rc":[{"batb":[[0,1.1,85.6],[1,1.09,222.22],[2,1.07,44.3]],"ltp":0.0,"tv":0.0,"id":169},{"batb":[[0,1.1,85.6],[1,1.09,222.22],[2,1.07,44.3]],"ltp":0.0,"tv":0.0,"id":60443},{"batb":[[0,1.1,85.6],[1,1.09,222.22],[2,1.07,44.3]],"ltp":0.0,"tv":0.0,"id":31375}]}]}
{"op":"mcm","clk":"11904371353","pt":1723932072650,"mc":[{"id":"1.231893357","rc":[{"batb":[[0,1.09,222.22],[1,1.07,44.3],[2,1.03,200]],"ltp":0.0,"tv":0.0,"id":169},{"batb":[[0,1.09,222.22],[1,1.07,44.3],[2,1.03,200]],"ltp":0.0,"tv":0.0,"id":60443},{"batb":[[0,1.09,222.22],[1,1.07,44.3],[2,1.03,200]],"ltp":0.0,"tv":0.0,"id":31375}]}]}
{"op":"mcm","clk":"11904372143","pt":1723932082753,"mc":[{"id":"1.231893357","rc":[{"batb":[[0,1.1,85.6],[1,1.09,222.22],[2,1.07,44.3]],"ltp":0.0,"tv":0.0,"id":169},{"batb":[[0,1.1,85.6],[1,1.09,222.22],[2,1.07,44.3]],"ltp":0.0,"tv":0.0,"id":60443},{"batb":[[0,1.1,85.6],[1,1.09,222.22],[2,1.07,44.3]],"ltp":0.0,"tv":0.0,"id":31375}]}]}
{"op":"mcm","clk":"11904504309","pt":1723933882976,"mc":[{"id":"1.231893357","rc":[{"batb":[[0,1.09,222.22],[1,1.07,44.3],[2,1.03,200]],"ltp":0.0,"tv":0.0,"id":60443}]}]}
{"op":"mcm","clk":"11904504340","pt":1723933883339,"mc":[{"id":"1.231893357","rc":[{"batb":[[0,1.09,222.22],[1,1.07,44.3],[2,1.03,200]],"ltp":0.0,"tv":0.0,"id":169},{"batb":[[0,1.09,222.22],[1,1.07,44.3],[2,1.03,200]],"ltp":0.0,"tv":0.0,"id":31375}]}]}
{"op":"mcm","clk":"11904510982","pt":1723933971259,"mc":[{"id":"1.231893357","rc":[{"batb":[[0,1.1,85.6],[1,1.09,222.22],[2,1.07,44.3]],"ltp":0.0,"tv":0.0,"id":169},{"batb":[[0,1.1,85.6],[1,1.09,222.22],[2,1.07,44.3]],"ltp":0.0,"tv":0.0,"id":60443},{"batb":[[0,1.1,85.6],[1,1.09,222.22],[2,1.07,44.3]],"ltp":0.0,"tv":0.0,"id":31375}]}]}
{"op":"mcm","clk":"11904645691","pt":1723935771912,"mc":[{"id":"1.231893357","rc":[{"batb":[[0,1.09,222.22],[1,1.07,44.3],[2,1.03,200]],"ltp":0.0,"tv":0.0,"id":169},{"batb":[[0,1.09,222.22],[1,1.07,44.3],[2,1.03,200]],"ltp":0.0,"tv":0.0,"id":60443},{"batb":[[0,1.09,222.22],[1,1.07,44.3],[2,1.03,200]],"ltp":0.0,"tv":0.0,"id":31375}]}]}
{"op":"mcm","clk":"11904649906","pt":1723935832880,"mc":[{"id":"1.231893357","rc":[{"batb":[[0,1.1,85.6],[1,1.09,222.22],[2,1.07,44.3]],"ltp":0.0,"tv":0.0,"id":169},{"batb":[[0,1.1,85.6],[1,1.09,222.22],[2,1.07,44.3]],"ltp":0.0,"tv":0.0,"id":60443},{"batb":[[0,1.1,85.6],[1,1.09,222.22],[2,1.07,44.3]],"ltp":0.0,"tv":0.0,"id":31375}]}]}
{"op":"mcm","clk":"11904796573","pt":1723937633410,"mc":[{"id":"1.231893357","rc":[{"batb":[[0,1.09,222.22],[1,1.07,44.3],[2,1.03,200]],"ltp":0.0,"tv":0.0,"id":169},{"batb":[[0,1.09,222.22],[1,1.07,44.3],[2,1.03,200]],"ltp":0.0,"tv":0.0,"id":60443},{"batb":[[0,1.09,222.22],[1,1.07,44.3],[2,1.03,200]],"ltp":0.0,"tv":0.0,"id":31375}]}]}
{"op":"mcm","clk":"11904797281","pt":1723937643169,"mc":[{"id":"1.231893357","rc":[{"batb":[[0,1.1,85.6],[1,1.09,222.22],[2,1.07,44.3]],"ltp":0.0,"tv":0.0,"id":169},{"batb":[[0,1.1,85.6],[1,1.09,222.22],[2,1.07,44.3]],"ltp":0.0,"tv":0.0,"id":60443},{"batb":[[0,1.1,85.6],[1,1.09,222.22],[2,1.07,44.3]],"ltp":0.0,"tv":0.0,"id":31375}]}]}
{"op":"mcm","clk":"11904916778","pt":1723939443685,"mc":[{"id":"1.231893357","rc":[{"batb":[[0,1.09,222.22],[1,1.07,44.3],[2,1.03,200]],"ltp":0.0,"tv":0.0,"id":169},{"batb":[[0,1.09,222.22],[1,1.07,44.3],[2,1.03,200]],"ltp":0.0,"tv":0.0,"id":60443},{"batb":[[0,1.09,222.22],[1,1.07,44.3],[2,1.03,200]],"ltp":0.0,"tv":0.0,"id":31375}]}]}
{"op":"mcm","clk":"11904926290","pt":1723939555595,"mc":[{"id":"1.231893357","rc":[{"batb":[[0,1.1,85.6],[1,1.09,222.22],[2,1.07,44.3]],"ltp":0.0,"tv":0.0,"id":169},{"batb":[[0,1.1,85.6],[1,1.09,222.22],[2,1.07,44.3]],"ltp":0.0,"tv":0.0,"id":60443},{"batb":[[0,1.1,85.6],[1,1.09,222.22],[2,1.07,44.3]],"ltp":0.0,"tv":0.0,"id":31375}]}]}
{"op":"mcm","clk":"11905089958","pt":1723941355915,"mc":[{"id":"1.231893357","rc":[{"batb":[[0,1.09,222.22],[1,1.07,44.3],[2,1.03,200]],"ltp":0.0,"tv":0.0,"id":169},{"batb":[[0,1.09,222.22],[1,1.07,44.3],[2,1.03,200]],"ltp":0.0,"tv":0.0,"id":60443}]}]}
{"op":"mcm","clk":"11905089980","pt":1723941356181,"mc":[{"id":"1.231893357","rc":[{"batb":[[0,1.09,222.22],[1,1.07,44.3],[2,1.03,200]],"ltp":0.0,"tv":0.0,"id":31375}]}]}
{"op":"mcm","clk":"11905099186","pt":1723941459004,"mc":[{"id":"1.231893357","rc":[{"batb":[[0,1.1,85.6],[1,1.09,222.22],[2,1.07,44.3]],"ltp":0.0,"tv":0.0,"id":169},{"batb":[[0,1.1,85.6],[1,1.09,222.22],[2,1.07,44.3]],"ltp":0.0,"tv":0.0,"id":60443},{"batb":[[0,1.1,85.6],[1,1.09,222.22],[2,1.07,44.3]],"ltp":0.0,"tv":0.0,"id":31375}]}]}
{"op":"mcm","clk":"11905245322","pt":1723943259620,"mc":[{"id":"1.231893357","rc":[{"batb":[[0,1.09,222.22],[1,1.07,44.3],[2,1.03,200]],"ltp":0.0,"tv":0.0,"id":169},{"batb":[[0,1.09,222.22],[1,1.07,44.3],[2,1.03,200]],"ltp":0.0,"tv":0.0,"id":60443},{"batb":[[0,1.09,222.22],[1,1.07,44.3],[2,1.03,200]],"ltp":0.0,"tv":0.0,"id":31375}]}]}
{"op":"mcm","clk":"11905251454","pt":1723943349403,"mc":[{"id":"1.231893357","rc":[{"batb":[[0,1.1,85.6],[1,1.09,222.22],[2,1.07,44.3]],"ltp":0.0,"tv":0.0,"id":169},{"batb":[[0,1.1,85.6],[1,1.09,222.22],[2,1.07,44.3]],"ltp":0.0,"tv":0.0,"id":60443},{"batb":[[0,1.1,85.6],[1,1.09,222.22],[2,1.07,44.3]],"ltp":0.0,"tv":0.0,"id":31375}]}]}
{"op":"mcm","clk":"11905379324","pt":1723945149889,"mc":[{"id":"1.231893357","rc":[{"batb":[[0,1.09,222.22],[1,1.07,44.3],[2,1.03,200]],"ltp":0.0,"tv":0.0,"id":169},{"batb":[[0,1.09,222.22],[1,1.07,44.3],[2,1.03,200]],"ltp":0.0,"tv":0.0,"id":60443},{"batb":[[0,1.09,222.22],[1,1.07,44.3],[2,1.03,200]],"ltp":0.0,"tv":0.0,"id":31375}]}]}
{"op":"mcm","clk":"11905383666","pt":1723945217299,"mc":[{"id":"1.231893357","rc":[{"batb":[[0,1.1,85.6],[1,1.09,222.22],[2,1.07,44.3]],"ltp":0.0,"tv":0.0,"id":169},{"batb":[[0,1.1,85.6],[1,1.09,222.22],[2,1.07,44.3]],"ltp":0.0,"tv":0.0,"id":60443},{"batb":[[0,1.1,85.6],[1,1.09,222.22],[2,1.07,44.3]],"ltp":0.0,"tv":0.0,"id":31375}]}]}
{"op":"mcm","clk":"11905477856","pt":1723947017918,"mc":[{"id":"1.231893357","rc":[{"batb":[[0,1.09,222.22],[1,1.07,44.3],[2,1.03,200]],"ltp":0.0,"tv":0.0,"id":169},{"batb":[[0,1.09,222.22],[1,1.07,44.3],[2,1.03,200]],"ltp":0.0,"tv":0.0,"id":60443},{"batb":[[0,1.09,222.22],[1,1.07,44.3],[2,1.03,200]],"ltp":0.0,"tv":0.0,"id":31375}]}]}
{"op":"mcm","clk":"11905479479","pt":1723947048038,"mc":[{"id":"1.231893357","rc":[{"batb":[[0,1.1,85.6],[1,1.09,222.22],[2,1.07,44.3]],"ltp":0.0,"tv":0.0,"id":169},{"batb":[[0,1.1,85.6],[1,1.09,222.22],[2,1.07,44.3]],"ltp":0.0,"tv":0.0,"id":60443},{"batb":[[0,1.1,85.6],[1,1.09,222.22],[2,1.07,44.3]],"ltp":0.0,"tv":0.0,"id":31375}]}]}
{"op":"mcm","clk":"11905582265","pt":1723948848827,"mc":[{"id":"1.231893357","rc":[{"batb":[[0,1.09,222.22],[1,1.07,44.3],[2,1.03,200]],"ltp":0.0,"tv":0.0,"id":169},{"batb":[[0,1.09,222.22],[1,1.07,44.3],[2,1.03,200]],"ltp":0.0,"tv":0.0,"id":60443},{"batb":[[0,1.09,222.22],[1,1.07,44.3],[2,1.03,200]],"ltp":0.0,"tv":0.0,"id":31375}]}]}
{"op":"mcm","clk":"11905591407","pt":1723949016852,"mc":[{"id":"1.231893357","rc":[{"batb":[[0,1.1,85.6],[1,1.09,222.22],[2,1.07,44.3]],"ltp":0.0,"tv":0.0,"id":169},{"batb":[[0,1.1,85.6],[1,1.09,222.22],[2,1.07,44.3]],"ltp":0.0,"tv":0.0,"id":60443},{"batb":[[0,1.1,85.6],[1,1.09,222.22],[2,1.07,44.3]],"ltp":0.0,"tv":0.0,"id":31375}]}]}
{"op":"mcm","clk":"11905697570","pt":1723950817241,"mc":[{"id":"1.231893357","rc":[{"batb":[[0,1.09,222.22],[1,1.07,44.3],[2,1.03,200]],"ltp":0.0,"tv":0.0,"id":169},{"batb":[[0,1.09,222.22],[1,1.07,44.3],[2,1.03,200]],"ltp":0.0,"tv":0.0,"id":60443},{"batb":[[0,1.09,222.22],[1,1.07,44.3],[2,1.03,200]],"ltp":0.0,"tv":0.0,"id":31375}]}]}
{"op":"mcm","clk":"11905706051","pt":1723950968948,"mc":[{"id":"1.231893357","rc":[{"batb":[[0,1.1,85.6],[1,1.09,222.22],[2,1.07,44.3]],"ltp":0.0,"tv":0.0,"id":169},{"batb":[[0,1.1,85.6],[1,1.09,222.22],[2,1.07,44.3]],"ltp":0.0,"tv":0.0,"id":60443},{"batb":[[0,1.1,85.6],[1,1.09,222.22],[2,1.07,44.3]],"ltp":0.0,"tv":0.0,"id":31375}]}]}
{"op":"mcm","clk":"11905811747","pt":1723952770564,"mc":[{"id":"1.231893357","rc":[{"batb":[[0,1.09,222.22],[1,1.07,44.3],[2,1.03,200]],"ltp":0.0,"tv":0.0,"id":169},{"batb":[[0,1.09,222.22],[1,1.07,44.3],[2,1.03,200]],"ltp":0.0,"tv":0.0,"id":60443},{"batb":[[0,1.09,222.22],[1,1.07,44.3],[2,1.03,200]],"ltp":0.0,"tv":0.0,"id":31375}]}]}
{"op":"mcm","clk":"11905817401","pt":1723952890124,"mc":[{"id":"1.231893357","rc":[{"batb":[[0,1.1,85.6],[1,1.09,222.22],[2,1.07,44.3]],"ltp":0.0,"tv":0.0,"id":169},{"batb":[[0,1.1,85.6],[1,1.09,222.22],[2,1.07,44.3]],"ltp":0.0,"tv":0.0,"id":60443},{"batb":[[0,1.1,85.6],[1,1.09,222.22],[2,1.07,44.3]],"ltp":0.0,"tv":0.0,"id":31375}]}]}
{"op":"mcm","clk":"11905911587","pt":1723954690799,"mc":[{"id":"1.231893357","rc":[{"batb":[[0,1.09,222.22],[1,1.07,44.3],[2,1.03,200]],"ltp":0.0,"tv":0.0,"id":169},{"batb":[[0,1.09,222.22],[1,1.07,44.3],[2,1.03,200]],"ltp":0.0,"tv":0.0,"id":60443},{"batb":[[0,1.09,222.22],[1,1.07,44.3],[2,1.03,200]],"ltp":0.0,"tv":0.0,"id":31375}]}]}
{"op":"mcm","clk":"11905915320","pt":1723954795777,"mc":[{"id":"1.231893357","rc":[{"batb":[[0,1.1,85.6],[1,1.09,222.22],[2,1.07,44.3]],"ltp":0.0,"tv":0.0,"id":169},{"batb":[[0,1.1,85.6],[1,1.09,222.22],[2,1.07,44.3]],"ltp":0.0,"tv":0.0,"id":60443},{"batb":[[0,1.1,85.6],[1,1.09,222.22],[2,1.07,44.3]],"ltp":0.0,"tv":0.0,"id":31375}]}]}
{"op":"mcm","clk":"11905989204","pt":1723956595950,"mc":[{"id":"1.231893357","rc":[{"batb":[[0,1.09,222.22],[1,1.07,44.3],[2,1.03,200]],"ltp":0.0,"tv":0.0,"id":60443}]}]}
{"op":"mcm","clk":"11905989244","pt":1723956596561,"mc":[{"id":"1.231893357","rc":[{"batb":[[0,1.09,222.22],[1,1.07,44.3],[2,1.03,200]],"ltp":0.0,"tv":0.0,"id":169},{"batb":[[0,1.09,222.22],[1,1.07,44.3],[2,1.03,200]],"ltp":0.0,"tv":0.0,"id":31375}]}]}
{"op":"mcm","clk":"11905993292","pt":1723956685792,"mc":[{"id":"1.231893357","rc":[{"batb":[[0,1.1,85.6],[1,1.09,222.22],[2,1.07,44.3]],"ltp":0.0,"tv":0.0,"id":169},{"batb":[[0,1.1,85.6],[1,1.09,222.22],[2,1.07,44.3]],"ltp":0.0,"tv":0.0,"id":60443},{"batb":[[0,1.1,85.6],[1,1.09,222.22],[2,1.07,44.3]],"ltp":0.0,"tv":0.0,"id":31375}]}]}
{"op":"mcm","clk":"11906018209","pt":1723957411134,"mc":[{"id":"1.231893357","rc":[{"batb":[[0,1.11,44.3],[1,1.1,85.6],[2,1.09,222.22]],"ltp":0.0,"tv":0.0,"id":169},{"batb":[[0,1.11,44.3],[1,1.1,85.6],[2,1.09,222.22]],"ltp":0.0,"tv":0.0,"id":60443},{"batb":[[0,1.11,44.3],[1,1.1,85.6],[2,1.09,222.22]],"ltp":0.0,"tv":0.0,"id":31375}]}]}
{"op":"mcm","clk":"11906081794","pt":1723958486355,"mc":[{"id":"1.231893357","rc":[{"batb":[[1,1.09,222.22],[2,1.03,200]],"ltp":0.0,"tv":0.0,"id":169},{"batb":[[1,1.09,222.22],[2,1.03,200]],"ltp":0.0,"tv":0.0,"id":60443},{"batb":[[1,1.09,222.22],[2,1.03,200]],"ltp":0.0,"tv":0.0,"id":31375}]}]}
{"op":"mcm","clk":"11906086012","pt":1723958569865,"mc":[{"id":"1.231893357","rc":[{"batb":[[0,1.12,71.33],[1,1.11,44.3],[2,1.09,222.22]],"ltp":0.0,"tv":0.0,"id":169},{"batb":[[0,1.12,71.33],[1,1.11,44.3],[2,1.09,222.22]],"ltp":0.0,"tv":0.0,"id":60443},{"batb":[[0,1.12,71.33],[1,1.11,44.3],[2,1.09,222.22]],"ltp":0.0,"tv":0.0,"id":31375}]}]}
{"op":"mcm","clk":"11906159897","pt":1723960370472,"mc":[{"id":"1.231893357","rc":[{"batb":[[0,1.11,44.3],[1,1.09,222.22],[2,1.03,200]],"ltp":0.0,"tv":0.0,"id":169},{"batb":[[0,1.11,44.3],[1,1.09,222.22],[2,1.03,200]],"ltp":0.0,"tv":0.0,"id":60443},{"batb":[[0,1.11,44.3],[1,1.09,222.22],[2,1.03,200]],"ltp":0.0,"tv":0.0,"id":31375}]}]}
{"op":"mcm","clk":"11906163586","pt":1723960446059,"mc":[{"id":"1.231893357","rc":[{"batb":[[0,1.12,71.33],[1,1.11,44.3],[2,1.09,222.22]],"ltp":0.0,"tv":0.0,"id":169},{"batb":[[0,1.12,71.33],[1,1.11,44.3],[2,1.09,222.22]],"ltp":0.0,"tv":0.0,"id":60443},{"batb":[[0,1.12,71.33],[1,1.11,44.3],[2,1.09,222.22]],"ltp":0.0,"tv":0.0,"id":31375}]}]}
{"op":"mcm","clk":"11906245221","pt":1723962246734,"mc":[{"id":"1.231893357","rc":[{"batb":[[0,1.11,44.3],[1,1.09,222.22],[2,1.03,200]],"ltp":0.0,"tv":0.0,"id":169},{"batb":[[0,1.11,44.3],[1,1.09,222.22],[2,1.03,200]],"ltp":0.0,"tv":0.0,"id":60443},{"batb":[[0,1.11,44.3],[1,1.09,222.22],[2,1.03,200]],"ltp":0.0,"tv":0.0,"id":31375}]}]}
{"op":"mcm","clk":"11906248265","pt":1723962324942,"mc":[{"id":"1.231893357","rc":[{"batb":[[0,1.12,71.33],[1,1.11,44.3],[2,1.09,222.22]],"ltp":0.0,"tv":0.0,"id":169},{"batb":[[0,1.12,71.33],[1,1.11,44.3],[2,1.09,222.22]],"ltp":0.0,"tv":0.0,"id":60443},{"batb":[[0,1.12,71.33],[1,1.11,44.3],[2,1.09,222.22]],"ltp":0.0,"tv":0.0,"id":31375}]}]}
{"op":"mcm","clk":"11906348153","pt":1723964125596,"mc":[{"id":"1.231893357","rc":[{"batb":[[0,1.11,44.3],[1,1.09,222.22],[2,1.03,200]],"ltp":0.0,"tv":0.0,"id":169},{"batb":[[0,1.11,44.3],[1,1.09,222.22],[2,1.03,200]],"ltp":0.0,"tv":0.0,"id":60443},{"batb":[[0,1.11,44.3],[1,1.09,222.22],[2,1.03,200]],"ltp":0.0,"tv":0.0,"id":31375}]}]}
{"op":"mcm","clk":"11906350994","pt":1723964195685,"mc":[{"id":"1.231893357","rc":[{"batb":[[0,1.12,71.33],[1,1.11,44.3],[2,1.09,222.22]],"ltp":0.0,"tv":0.0,"id":169},{"batb":[[0,1.12,71.33],[1,1.11,44.3],[2,1.09,222.22]],"ltp":0.0,"tv":0.0,"id":60443},{"batb":[[0,1.12,71.33],[1,1.11,44.3],[2,1.09,222.22]],"ltp":0.0,"tv":0.0,"id":31375}]}]}
{"op":"mcm","clk":"11906450704","pt":1723965996007,"mc":[{"id":"1.231893357","rc":[{"batb":[[0,1.11,44.3],[1,1.09,222.22],[2,1.03,200]],"ltp":0.0,"tv":0.0,"id":169},{"batb":[[0,1.11,44.3],[1,1.09,222.22],[2,1.03,200]],"ltp":0.0,"tv":0.0,"id":60443}]}]}
{"op":"mcm","clk":"11906450713","pt":1723965996215,"mc":[{"id":"1.231893357","rc":[{"batb":[[0,1.11,44.3],[1,1.09,222.22],[2,1.03,200]],"ltp":0.0,"tv":0.0,"id":31375}]}]}
{"op":"mcm","clk":"11906455327","pt":1723966068966,"mc":[{"id":"1.231893357","rc":[{"batb":[[0,1.12,71.33],[1,1.11,44.3],[2,1.09,222.22]],"ltp":0.0,"tv":0.0,"id":169},{"batb":[[0,1.12,71.33],[1,1.11,44.3],[2,1.09,222.22]],"ltp":0.0,"tv":0.0,"id":31375}]}]}
{"op":"mcm","clk":"11906455332","pt":1723966069068,"mc":[{"id":"1.231893357","rc":[{"batb":[[0,1.12,71.33],[1,1.11,44.3],[2,1.09,222.22]],"ltp":0.0,"tv":0.0,"id":60443}]}]}
{"op":"mcm","clk":"11906578161","pt":1723967869344,"mc":[{"id":"1.231893357","rc":[{"batb":[[0,1.11,44.3],[1,1.09,222.22],[2,1.03,200]],"ltp":0.0,"tv":0.0,"id":169},{"batb":[[0,1.11,44.3],[1,1.09,222.22],[2,1.03,200]],"ltp":0.0,"tv":0.0,"id":31375}]}]}
{"op":"mcm","clk":"11906578222","pt":1723967870164,"mc":[{"id":"1.231893357","rc":[{"batb":[[0,1.11,44.3],[1,1.09,222.22],[2,1.03,200]],"ltp":0.0,"tv":0.0,"id":60443}]}]}
{"op":"mcm","clk":"11906590738","pt":1723968024524,"mc":[{"id":"1.231893357","rc":[{"batb":[[0,1.12,71.33],[1,1.11,44.3],[2,1.09,222.22]],"ltp":0.0,"tv":0.0,"id":169},{"batb":[[0,1.12,71.33],[1,1.11,44.3],[2,1.09,222.22]],"ltp":0.0,"tv":0.0,"id":60443},{"batb":[[0,1.12,71.33],[1,1.11,44.3],[2,1.09,222.22]],"ltp":0.0,"tv":0.0,"id":31375}]}]}
{"op":"mcm","clk":"11906702020","pt":1723969244534,"mc":[{"id":"1.231893357","rc":[{"batb":[[0,1.13,44.3],[1,1.12,71.33]],"ltp":0.0,"tv":0.0,"id":169},{"batb":[[0,1.13,44.3],[1,1.12,71.33]],"ltp":0.0,"tv":0.0,"id":60443},{"batb":[[0,1.13,44.3],[1,1.12,71.33]],"ltp":0.0,"tv":0.0,"id":31375}]}]}
{"op":"mcm","clk":"11906749489","pt":1723969824764,"mc":[{"id":"1.231893357","rc":[{"batb":[[1,1.09,222.22],[2,1.03,200]],"ltp":0.0,"tv":0.0,"id":60443},{"batb":[[1,1.09,222.22],[2,1.03,200]],"ltp":0.0,"tv":0.0,"id":31375}]}]}
{"op":"mcm","clk":"11906749578","pt":1723969825594,"mc":[{"id":"1.231893357","rc":[{"batb":[[1,1.09,222.22],[2,1.03,200]],"ltp":0.0,"tv":0.0,"id":169}]}]}
{"op":"mcm","clk":"11906751009","pt":1723969841113,"mc":[{"id":"1.231893357","rc":[{"batb":[[0,1.14,61.14],[1,1.13,44.3],[2,1.09,222.22]],"ltp":0.0,"tv":0.0,"id":169},{"batb":[[0,1.14,61.14],[1,1.13,44.3],[2,1.09,222.22]],"ltp":0.0,"tv":0.0,"id":60443},{"batb":[[0,1.14,61.14],[1,1.13,44.3],[2,1.09,222.22]],"ltp":0.0,"tv":0.0,"id":31375}]}]}
{"op":"mcm","clk":"11906926609","pt":1723971641569,"mc":[{"id":"1.231893357","rc":[{"batb":[[0,1.13,44.3],[1,1.09,222.22],[2,1.03,200]],"ltp":0.0,"tv":0.0,"id":169},{"batb":[[0,1.13,44.3],[1,1.09,222.22],[2,1.03,200]],"ltp":0.0,"tv":0.0,"id":60443},{"batb":[[0,1.13,44.3],[1,1.09,222.22],[2,1.03,200]],"ltp":0.0,"tv":0.0,"id":31375}]}]}
{"op":"mcm","clk":"11906928290","pt":1723971655491,"mc":[{"id":"1.231893357","rc":[{"batb":[[0,1.14,61.14],[1,1.13,44.3],[2,1.09,222.22]],"ltp":0.0,"tv":0.0,"id":169},{"batb":[[0,1.14,61.14],[1,1.13,44.3],[2,1.09,222.22]],"ltp":0.0,"tv":0.0,"id":60443},{"batb":[[0,1.14,61.14],[1,1.13,44.3],[2,1.09,222.22]],"ltp":0.0,"tv":0.0,"id":31375}]}]}
{"op":"mcm","clk":"11907146899","pt":1723973455793,"mc":[{"id":"1.231893357","rc":[{"batb":[[0,1.13,44.3],[1,1.09,222.22],[2,1.03,200]],"ltp":0.0,"tv":0.0,"id":169},{"batb":[[0,1.13,44.3],[1,1.09,222.22],[2,1.03,200]],"ltp":0.0,"tv":0.0,"id":31375}]}]}
{"op":"mcm","clk":"11907147009","pt":1723973456515,"mc":[{"id":"1.231893357","rc":[{"batb":[[0,1.13,44.3],[1,1.09,222.22],[2,1.03,200]],"ltp":0.0,"tv":0.0,"id":60443}]}]}
{"op":"mcm","clk":"11907147679","pt":1723973461557,"mc":[{"id":"1.231893357","rc":[{"batb":[[0,1.14,61.14],[1,1.13,44.3],[2,1.09,222.22]],"ltp":0.0,"tv":0.0,"id":169},{"batb":[[0,1.14,61.14],[1,1.13,44.3],[2,1.09,222.22]],"ltp":0.0,"tv":0.0,"id":60443},{"batb":[[0,1.14,61.14],[1,1.13,44.3],[2,1.09,222.22]],"ltp":0.0,"tv":0.0,"id":31375}]}]}
{"op":"mcm","clk":"11907178298","pt":1723973702952,"mc":[{"id":"1.231893357","rc":[{"batb":[[0,1.5,20],[1,1.14,61.14],[2,1.13,44.3]],"ltp":0.0,"tv":0.0,"id":31375}]}]}
{"op":"mcm","clk":"11907179502","pt":1723973712004,"mc":[{"id":"1.231893357","rc":[{"batb":[[0,1.5,20],[1,1.14,61.14],[2,1.13,44.3]],"ltp":0.0,"tv":0.0,"id":169}]}]}
{"op":"mcm","clk":"11907180887","pt":1723973721489,"mc":[{"id":"1.231893357","rc":[{"batb":[[0,1.3,20],[1,1.14,61.14],[2,1.13,44.3]],"ltp":0.0,"tv":0.0,"id":60443}]}]}
{"op":"mcm","clk":"11907379325","pt":1723975261925,"mc":[{"id":"1.231893357","rc":[{"batb":[[1,1.13,44.3],[2,1.09,222.22]],"ltp":0.0,"tv":0.0,"id":60443},{"batb":[[1,1.13,44.3],[2,1.09,222.22]],"ltp":0.0,"tv":0.0,"id":31375}]}]}
{"op":"mcm","clk":"11907379350","pt":1723975262124,"mc":[{"id":"1.231893357","rc":[{"batb":[[1,1.13,44.3],[2,1.09,222.22]],"ltp":0.0,"tv":0.0,"id":169}]}]}
{"op":"mcm","clk":"11907401749","pt":1723975437233,"mc":[{"id":"1.231893357","rc":[{"batb":[[0,1.51,16.78],[1,1.5,20],[2,1.13,44.3]],"ltp":0.0,"tv":0.0,"id":169},{"batb":[[0,1.31,27.61],[1,1.3,20],[2,1.13,44.3]],"ltp":0.0,"tv":0.0,"id":60443},{"batb":[[0,1.51,16.78],[1,1.5,20],[2,1.13,44.3]],"ltp":0.0,"tv":0.0,"id":31375}]}]}
{"op":"mcm","clk":"11907628728","pt":1723977237617,"mc":[{"id":"1.231893357","rc":[{"batb":[[0,1.5,20],[1,1.13,44.3],[2,1.09,222.22]],"ltp":0.0,"tv":0.0,"id":169},{"batb":[[0,1.3,20],[1,1.13,44.3],[2,1.09,222.22]],"ltp":0.0,"tv":0.0,"id":60443},{"batb":[[0,1.5,20],[1,1.13,44.3],[2,1.09,222.22]],"ltp":0.0,"tv":0.0,"id":31375}]}]}
{"op":"mcm","clk":"11907650494","pt":1723977389193,"mc":[{"id":"1.231893357","rc":[{"batb":[[0,1.51,16.78],[1,1.5,20],[2,1.13,44.3]],"ltp":0.0,"tv":0.0,"id":169},{"batb":[[0,1.31,27.61],[1,1.3,20],[2,1.13,44.3]],"ltp":0.0,"tv":0.0,"id":60443},{"batb":[[0,1.51,16.78],[1,1.5,20],[2,1.13,44.3]],"ltp":0.0,"tv":0.0,"id":31375}]}]}
{"op":"mcm","clk":"11907867748","pt":1723979189699,"mc":[{"id":"1.231893357","rc":[{"batb":[[0,1.5,20],[1,1.13,44.3],[2,1.09,222.22]],"ltp":0.0,"tv":0.0,"id":169},{"batb":[[0,1.3,20],[1,1.13,44.3],[2,1.09,222.22]],"ltp":0.0,"tv":0.0,"id":60443},{"batb":[[0,1.5,20],[1,1.13,44.3],[2,1.09,222.22]],"ltp":0.0,"tv":0.0,"id":31375}]}]}
{"op":"mcm","clk":"11907885605","pt":1723979318938,"mc":[{"id":"1.231893357","rc":[{"batb":[[0,1.51,16.78],[1,1.5,20],[2,1.13,44.3]],"ltp":0.0,"tv":0.0,"id":169},{"batb":[[0,1.31,27.61],[1,1.3,20],[2,1.13,44.3]],"ltp":0.0,"tv":0.0,"id":60443},{"batb":[[0,1.51,16.78],[1,1.5,20],[2,1.13,44.3]],"ltp":0.0,"tv":0.0,"id":31375}]}]}
{"op":"mcm","clk":"11908128895","pt":1723981119656,"mc":[{"id":"1.231893357","rc":[{"batb":[[0,1.5,20],[1,1.13,44.3],[2,1.09,222.22]],"ltp":0.0,"tv":0.0,"id":169},{"batb":[[0,1.3,20],[1,1.13,44.3],[2,1.09,222.22]],"ltp":0.0,"tv":0.0,"id":60443},{"batb":[[0,1.5,20],[1,1.13,44.3],[2,1.09,222.22]],"ltp":0.0,"tv":0.0,"id":31375}]}]}
{"op":"mcm","clk":"11908141162","pt":1723981211872,"mc":[{"id":"1.231893357","rc":[{"batb":[[0,1.51,16.78],[1,1.5,20],[2,1.13,44.3]],"ltp":0.0,"tv":0.0,"id":169},{"batb":[[0,1.31,27.61],[1,1.3,20],[2,1.13,44.3]],"ltp":0.0,"tv":0.0,"id":60443},{"batb":[[0,1.51,16.78],[1,1.5,20],[2,1.13,44.3]],"ltp":0.0,"tv":0.0,"id":31375}]}]}
{"op":"mcm","clk":"11908360726","pt":1723983012622,"mc":[{"id":"1.231893357","rc":[{"batb":[[0,1.5,20],[1,1.13,44.3],[2,1.09,222.22]],"ltp":0.0,"tv":0.0,"id":169},{"batb":[[0,1.3,20],[1,1.13,44.3],[2,1.09,222.22]],"ltp":0.0,"tv":0.0,"id":60443},{"batb":[[0,1.5,20],[1,1.13,44.3],[2,1.09,222.22]],"ltp":0.0,"tv":0.0,"id":31375}]}]}
{"op":"mcm","clk":"11908373703","pt":1723983089114,"mc":[{"id":"1.231893357","rc":[{"batb":[[0,1.51,16.78],[1,1.5,20],[2,1.13,44.3]],"ltp":0.0,"tv":0.0,"id":169},{"batb":[[0,1.31,27.61],[1,1.3,20],[2,1.13,44.3]],"ltp":0.0,"tv":0.0,"id":60443},{"batb":[[0,1.51,16.78],[1,1.5,20],[2,1.13,44.3]],"ltp":0.0,"tv":0.0,"id":31375}]}]}
{"op":"mcm","clk":"11908659599","pt":1723984889906,"mc":[{"id":"1.231893357","rc":[{"batb":[[0,1.5,20],[1,1.13,44.3],[2,1.09,222.22]],"ltp":0.0,"tv":0.0,"id":169},{"batb":[[0,1.3,20],[1,1.13,44.3],[2,1.09,222.22]],"ltp":0.0,"tv":0.0,"id":60443},{"batb":[[0,1.5,20],[1,1.13,44.3],[2,1.09,222.22]],"ltp":0.0,"tv":0.0,"id":31375}]}]}
{"op":"mcm","clk":"11908668153","pt":1723984943636,"mc":[{"id":"1.231893357","rc":[{"batb":[[0,1.51,16.78],[1,1.5,20],[2,1.13,44.3]],"ltp":0.0,"tv":0.0,"id":169},{"batb":[[0,1.31,27.61],[1,1.3,20],[2,1.13,44.3]],"ltp":0.0,"tv":0.0,"id":60443},{"batb":[[0,1.51,16.78],[1,1.5,20],[2,1.13,44.3]],"ltp":0.0,"tv":0.0,"id":31375}]}]}
{"op":"mcm","clk":"11908922853","pt":1723986743927,"mc":[{"id":"1.231893357","rc":[{"batb":[[0,1.5,20],[1,1.13,44.3],[2,1.09,222.22]],"ltp":0.0,"tv":0.0,"id":169}]}]}
{"op":"mcm","clk":"11908923026","pt":1723986744889,"mc":[{"id":"1.231893357","rc":[{"batb":[[0,1.3,20],[1,1.13,44.3],[2,1.09,222.22]],"ltp":0.0,"tv":0.0,"id":60443},{"batb":[[0,1.5,20],[1,1.13,44.3],[2,1.09,222.22]],"ltp":0.0,"tv":0.0,"id":31375}]}]}
{"op":"mcm","clk":"11908926780","pt":1723986768031,"mc":[{"id":"1.231893357","rc":[{"batb":[[0,1.51,16.78],[1,1.5,20],[2,1.13,44.3]],"ltp":0.0,"tv":0.0,"id":169},{"batb":[[0,1.31,27.61],[1,1.3,20],[2,1.13,44.3]],"ltp":0.0,"tv":0.0,"id":60443},{"batb":[[0,1.51,16.78],[1,1.5,20],[2,1.13,44.3]],"ltp":0.0,"tv":0.0,"id":31375}]}]}
{"op":"mcm","clk":"11909187696","pt":1723988393002,"mc":[{"id":"1.231893357","rc":[{"batb":[[2,1.09,222.22]],"ltp":0.0,"tv":0.0,"id":169},{"batb":[[2,1.09,222.22]],"ltp":0.0,"tv":0.0,"id":60443},{"batb":[[2,1.09,222.22]],"ltp":0.0,"tv":0.0,"id":31375}]}]}
{"op":"mcm","clk":"11909187709","pt":1723988393104,"mc":[{"id":"1.231893357","rc":[{"batb":[[0,1.32,44.3],[1,1.31,27.61],[2,1.3,20]],"ltp":0.0,"tv":0.0,"id":60443}]}]}
{"op":"mcm","clk":"11909216025","pt":1723988569572,"mc":[{"id":"1.231893357","rc":[{"batb":[[0,1.5,20],[1,1.09,222.22],[2,1.03,200]],"ltp":0.0,"tv":0.0,"id":169},{"batb":[[1,1.3,20],[2,1.09,222.22]],"ltp":0.0,"tv":0.0,"id":60443},{"batb":[[0,1.5,20],[1,1.09,222.22],[2,1.03,200]],"ltp":0.0,"tv":0.0,"id":31375}]}]}
{"op":"mcm","clk":"11909244720","pt":1723988715442,"mc":[{"id":"1.231893357","rc":[{"batb":[[0,1.51,16.78],[1,1.5,20],[2,1.09,222.22]],"ltp":0.0,"tv":0.0,"id":169},{"batb":[[0,1.33,25.94],[1,1.32,44.3],[2,1.3,20]],"ltp":0.0,"tv":0.0,"id":60443},{"batb":[[0,1.51,16.78],[1,1.5,20],[2,1.09,222.22]],"ltp":0.0,"tv":0.0,"id":31375}]}]}
{"op":"mcm","clk":"11909349245","pt":1723989455066,"mc":[{"id":"1.231893357","rc":[{"batb":[[0,1.34,6.43],[1,1.33,25.94],[2,1.32,44.3]],"ltp":0.0,"tv":0.0,"id":60443}]}]}
{"op":"mcm","clk":"11909505805","pt":1723990516958,"mc":[{"id":"1.231893357","rc":[{"batb":[[1,1.32,44.3],[2,1.3,20]],"ltp":0.0,"tv":0.0,"id":60443},{"batb":[[0,1.5,20],[1,1.09,222.22],[2,1.03,200]],"ltp":0.0,"tv":0.0,"id":31375}]}]}
{"op":"mcm","clk":"11909505839","pt":1723990517179,"mc":[{"id":"1.231893357","rc":[{"batb":[[0,1.5,20],[1,1.09,222.22],[2,1.03,200]],"ltp":0.0,"tv":0.0,"id":169}]}]}
{"op":"mcm","clk":"11909521278","pt":1723990621795,"mc":[{"id":"1.231893357","rc":[{"batb":[[0,1.51,16.78],[1,1.5,20],[2,1.09,222.22]],"ltp":0.0,"tv":0.0,"id":169},{"batb":[[0,1.35,24.46],[1,1.34,6.43],[2,1.32,44.3]],"ltp":0.0,"tv":0.0,"id":60443},{"batb":[[0,1.51,16.78],[1,1.5,20],[2,1.09,222.22]],"ltp":0.0,"tv":0.0,"id":31375}]}]}
{"op":"mcm","clk":"11909740388","pt":1723992048219,"mc":[{"id":"1.231893357","rc":[{"batb":[[1,1.33,6.43]],"ltp":0.0,"tv":0.0,"id":60443}]}]}
{"op":"mcm","clk":"11909808934","pt":1723992422377,"mc":[{"id":"1.231893357","rc":[{"batb":[[0,1.5,20],[1,1.09,222.22],[2,1.03,200]],"ltp":0.0,"tv":0.0,"id":169},{"batb":[[0,1.33,6.43],[1,1.32,44.3],[2,1.3,20]],"ltp":0.0,"tv":0.0,"id":60443},{"batb":[[0,1.5,20],[1,1.09,222.22],[2,1.03,200]],"ltp":0.0,"tv":0.0,"id":31375}]}]}
{"op":"mcm","clk":"11909827259","pt":1723992530547,"mc":[{"id":"1.231893357","rc":[{"batb":[[0,1.51,16.78],[1,1.5,20],[2,1.09,222.22]],"ltp":0.0,"tv":0.0,"id":169},{"batb":[[0,1.34,25.18],[1,1.33,6.43],[2,1.32,44.3]],"ltp":0.0,"tv":0.0,"id":60443},{"batb":[[0,1.51,16.78],[1,1.5,20],[2,1.09,222.22]],"ltp":0.0,"tv":0.0,"id":31375}]}]}
{"op":"mcm","clk":"11910140974","pt":1723994332558,"mc":[{"id":"1.231893357","rc":[{"batb":[[0,1.5,20],[1,1.09,222.22],[2,1.03,200]],"ltp":0.0,"tv":0.0,"id":169},{"batb":[[0,1.33,6.43],[1,1.32,44.3],[2,1.3,20]],"ltp":0.0,"tv":0.0,"id":60443},{"batb":[[0,1.5,20],[1,1.09,222.22],[2,1.03,200]],"ltp":0.0,"tv":0.0,"id":31375}]}]}
{"op":"mcm","clk":"11910155960","pt":1723994415260,"mc":[{"id":"1.231893357","rc":[{"batb":[[0,1.51,16.78],[1,1.5,20],[2,1.09,222.22]],"ltp":0.0,"tv":0.0,"id":169},{"batb":[[0,1.34,25.18],[1,1.33,6.43],[2,1.32,44.3]],"ltp":0.0,"tv":0.0,"id":60443},{"batb":[[0,1.51,16.78],[1,1.5,20],[2,1.09,222.22]],"ltp":0.0,"tv":0.0,"id":31375}]}]}
{"op":"mcm","clk":"11910178576","pt":1723994536832,"mc":[{"id":"1.231893357","rc":[{"batb":[[0,1.35,6.43],[1,1.34,25.18]],"ltp":0.0,"tv":0.0,"id":60443}]}]}
{"op":"mcm","clk":"11910520908","pt":1723996216003,"mc":[{"id":"1.231893357","rc":[{"batb":[[0,1.5,20],[1,1.09,222.22],[2,1.03,200]],"ltp":0.0,"tv":0.0,"id":169},{"batb":[[1,1.32,44.3],[2,1.3,20]],"ltp":0.0,"tv":0.0,"id":60443},{"batb":[[0,1.5,20],[1,1.09,222.22],[2,1.03,200]],"ltp":0.0,"tv":0.0,"id":31375}]}]}
{"op":"mcm","clk":"11910534977","pt":1723996289961,"mc":[{"id":"1.231893357","rc":[{"batb":[[0,1.51,16.78],[1,1.5,20],[2,1.09,222.22]],"ltp":0.0,"tv":0.0,"id":169},{"batb":[[0,1.36,23.78],[1,1.35,6.43],[2,1.32,44.3]],"ltp":0.0,"tv":0.0,"id":60443},{"batb":[[0,1.51,16.78],[1,1.5,20],[2,1.09,222.22]],"ltp":0.0,"tv":0.0,"id":31375}]}]}
{"op":"mcm","clk":"11910654503","pt":1723996960580,"mc":[{"id":"1.231893357","rc":[{"batb":[[1,1.33,6.43]],"ltp":0.0,"tv":0.0,"id":60443}]}]}
{"op":"mcm","clk":"11910882156","pt":1723998090828,"mc":[{"id":"1.231893357","rc":[{"batb":[[0,1.5,20],[1,1.09,222.22],[2,1.03,200]],"ltp":0.0,"tv":0.0,"id":169},{"batb":[[0,1.33,6.43],[1,1.32,44.3],[2,1.3,20]],"ltp":0.0,"tv":0.0,"id":60443},{"batb":[[0,1.5,20],[1,1.09,222.22],[2,1.03,200]],"ltp":0.0,"tv":0.0,"id":31375}]}]}
{"op":"mcm","clk":"11910886125","pt":1723998111482,"mc":[{"id":"1.231893357","rc":[{"batb":[[0,1.51,16.78],[1,1.5,20],[2,1.09,222.22]],"ltp":0.0,"tv":0.0,"id":169},{"batb":[[0,1.34,25.18],[1,1.33,6.43],[2,1.32,44.3]],"ltp":0.0,"tv":0.0,"id":60443},{"batb":[[0,1.51,16.78],[1,1.5,20],[2,1.09,222.22]],"ltp":0.0,"tv":0.0,"id":31375}]}]}
{"op":"mcm","clk":"11911120019","pt":1723999329849,"mc":[{"id":"1.231893357","rc":[{"batb":[[0,1.35,6.43],[1,1.34,25.18]],"ltp":0.0,"tv":0.0,"id":60443}]}]}
{"op":"mcm","clk":"11911232239","pt":1723999913531,"mc":[{"id":"1.231893357","rc":[{"batb":[[0,1.5,20],[1,1.09,222.22],[2,1.03,200]],"ltp":0.0,"tv":0.0,"id":169},{"batb":[[1,1.32,44.3],[2,1.3,20]],"ltp":0.0,"tv":0.0,"id":60443},{"batb":[[0,1.5,20],[1,1.09,222.22],[2,1.03,200]],"ltp":0.0,"tv":0.0,"id":31375}]}]}
{"op":"mcm","clk":"11911256012","pt":1724000044029,"mc":[{"id":"1.231893357","rc":[{"batb":[[0,1.51,16.78],[1,1.5,20],[2,1.09,222.22]],"ltp":0.0,"tv":0.0,"id":169},{"batb":[[0,1.36,23.78],[1,1.35,6.43],[2,1.32,44.3]],"ltp":0.0,"tv":0.0,"id":60443},{"batb":[[0,1.51,16.78],[1,1.5,20],[2,1.09,222.22]],"ltp":0.0,"tv":0.0,"id":31375}]}]}
{"op":"mcm","clk":"11911498885","pt":1724001607264,"mc":[{"id":"1.231893357","rc":[{"batb":[[1,1.33,6.43]],"ltp":0.0,"tv":0.0,"id":60443}]}]}
{"op":"mcm","clk":"11911535473","pt":1724001845738,"mc":[{"id":"1.231893357","rc":[{"batb":[[0,1.5,20],[1,1.09,222.22],[2,1.03,200]],"ltp":0.0,"tv":0.0,"id":169},{"batb":[[0,1.33,6.43],[1,1.32,44.3],[2,1.3,20]],"ltp":0.0,"tv":0.0,"id":60443},{"batb":[[0,1.5,20],[1,1.09,222.22],[2,1.03,200]],"ltp":0.0,"tv":0.0,"id":31375}]}]}
{"op":"mcm","clk":"11911538827","pt":1724001867168,"mc":[{"id":"1.231893357","rc":[{"batb":[[0,1.51,16.78],[1,1.5,20],[2,1.09,222.22]],"ltp":0.0,"tv":0.0,"id":169},{"batb":[[0,1.34,25.18],[1,1.33,6.43],[2,1.32,44.3]],"ltp":0.0,"tv":0.0,"id":60443},{"batb":[[0,1.51,16.78],[1,1.5,20],[2,1.09,222.22]],"ltp":0.0,"tv":0.0,"id":31375}]}]}
{"op":"mcm","clk":"11911786992","pt":1724003667919,"mc":[{"id":"1.231893357","rc":[{"batb":[[0,1.5,20],[1,1.09,222.22],[2,1.03,200]],"ltp":0.0,"tv":0.0,"id":169},{"batb":[[0,1.33,6.43],[1,1.32,44.3],[2,1.3,20]],"ltp":0.0,"tv":0.0,"id":60443},{"batb":[[0,1.5,20],[1,1.09,222.22],[2,1.03,200]],"ltp":0.0,"tv":0.0,"id":31375}]}]}
{"op":"mcm","clk":"11911797868","pt":1724003758534,"mc":[{"id":"1.231893357","rc":[{"batb":[[0,1.51,16.78],[1,1.5,20],[2,1.09,222.22]],"ltp":0.0,"tv":0.0,"id":169},{"batb":[[0,1.34,25.18],[1,1.33,6.43],[2,1.32,44.3]],"ltp":0.0,"tv":0.0,"id":60443},{"batb":[[0,1.51,16.78],[1,1.5,20],[2,1.09,222.22]],"ltp":0.0,"tv":0.0,"id":31375}]}]}
{"op":"mcm","clk":"11911809692","pt":1724003860355,"mc":[{"id":"1.231893357","rc":[{"batb":[[0,1.35,6.43],[1,1.34,25.18]],"ltp":0.0,"tv":0.0,"id":60443}]}]}
{"op":"mcm","clk":"11912091393","pt":1724005560891,"mc":[{"id":"1.231893357","rc":[{"batb":[[0,1.5,20],[1,1.09,222.22],[2,1.03,200]],"ltp":0.0,"tv":0.0,"id":169},{"batb":[[1,1.32,44.3],[2,1.3,20]],"ltp":0.0,"tv":0.0,"id":60443},{"batb":[[0,1.5,20],[1,1.09,222.22],[2,1.03,200]],"ltp":0.0,"tv":0.0,"id":31375}]}]}
{"op":"mcm","clk":"11912092945","pt":1724005569200,"mc":[{"id":"1.231893357","rc":[{"batb":[[0,1.51,16.78],[1,1.5,20],[2,1.09,222.22]],"ltp":0.0,"tv":0.0,"id":169},{"batb":[[0,1.36,23.78],[1,1.35,6.43],[2,1.32,44.3]],"ltp":0.0,"tv":0.0,"id":60443},{"batb":[[0,1.51,16.78],[1,1.5,20],[2,1.09,222.22]],"ltp":0.0,"tv":0.0,"id":31375}]}]}
{"op":"mcm","clk":"11912146804","pt":1724005847787,"mc":[{"id":"1.231893357","rc":[{"batb":[[1,1.33,6.43]],"ltp":0.0,"tv":0.0,"id":60443}]}]}
{"op":"mcm","clk":"11912441403","pt":1724007370750,"mc":[{"id":"1.231893357","rc":[{"batb":[[0,1.33,6.43],[1,1.32,44.3],[2,1.3,20]],"ltp":0.0,"tv":0.0,"id":60443},{"batb":[[0,1.5,20],[1,1.09,222.22],[2,1.03,200]],"ltp":0.0,"tv":0.0,"id":31375}]}]}
{"op":"mcm","clk":"11912441446","pt":1724007371066,"mc":[{"id":"1.231893357","rc":[{"batb":[[0,1.5,20],[1,1.09,222.22],[2,1.03,200]],"ltp":0.0,"tv":0.0,"id":169}]}]}
{"op":"mcm","clk":"11912449181","pt":1724007427053,"mc":[{"id":"1.231893357","rc":[{"batb":[[0,1.51,16.78],[1,1.5,20],[2,1.09,222.22]],"ltp":0.0,"tv":0.0,"id":169},{"batb":[[0,1.34,25.18],[1,1.33,6.43],[2,1.32,44.3]],"ltp":0.0,"tv":0.0,"id":60443},{"batb":[[0,1.51,16.78],[1,1.5,20],[2,1.09,222.22]],"ltp":0.0,"tv":0.0,"id":31375}]}]}
{"op":"mcm","clk":"11912517839","pt":1724007852471,"mc":[{"id":"1.231893357","rc":[{"batb":[[0,1.35,6.43],[1,1.34,25.18]],"ltp":0.0,"tv":0.0,"id":60443}]}]}
{"op":"mcm","clk":"11912778812","pt":1724009228838,"mc":[{"id":"1.231893357","rc":[{"batb":[[0,1.5,20],[1,1.09,222.22],[2,1.03,200]],"ltp":0.0,"tv":0.0,"id":169},{"batb":[[1,1.32,44.3],[2,1.3,20]],"ltp":0.0,"tv":0.0,"id":60443},{"batb":[[0,1.5,20],[1,1.09,222.22],[2,1.03,200]],"ltp":0.0,"tv":0.0,"id":31375}]}]}
{"op":"mcm","clk":"11912795357","pt":1724009321188,"mc":[{"id":"1.231893357","rc":[{"batb":[[0,1.51,16.78],[1,1.5,20],[2,1.09,222.22]],"ltp":0.0,"tv":0.0,"id":169},{"batb":[[0,1.36,23.78],[1,1.35,6.43],[2,1.32,44.3]],"ltp":0.0,"tv":0.0,"id":60443},{"batb":[[0,1.51,16.78],[1,1.5,20],[2,1.09,222.22]],"ltp":0.0,"tv":0.0,"id":31375}]}]}
{"op":"mcm","clk":"11912896514","pt":1724009879667,"mc":[{"id":"1.231893357","rc":[{"batb":[[1,1.33,6.43]],"ltp":0.0,"tv":0.0,"id":60443}]}]}
{"op":"mcm","clk":"11913104447","pt":1724011123018,"mc":[{"id":"1.231893357","rc":[{"batb":[[0,1.5,20],[1,1.09,222.22],[2,1.03,200]],"ltp":0.0,"tv":0.0,"id":169},{"batb":[[0,1.33,6.43],[1,1.32,44.3],[2,1.3,20]],"ltp":0.0,"tv":0.0,"id":60443}]}]}
{"op":"mcm","clk":"11913104469","pt":1724011123181,"mc":[{"id":"1.231893357","rc":[{"batb":[[0,1.5,20],[1,1.09,222.22],[2,1.03,200]],"ltp":0.0,"tv":0.0,"id":31375}]}]}
{"op":"mcm","clk":"11913110810","pt":1724011169839,"mc":[{"id":"1.231893357","rc":[{"batb":[[0,1.51,16.78],[1,1.5,20],[2,1.09,222.22]],"ltp":0.0,"tv":0.0,"id":169},{"batb":[[0,1.34,25.18],[1,1.33,6.43],[2,1.32,44.3]],"ltp":0.0,"tv":0.0,"id":60443},{"batb":[[0,1.51,16.78],[1,1.5,20],[2,1.09,222.22]],"ltp":0.0,"tv":0.0,"id":31375}]}]}
{"op":"mcm","clk":"11913211818","pt":1724011914001,"mc":[{"id":"1.231893357","rc":[{"batb":[[0,1.51,16.81]],"batl":[[0,95,5.85]],"ltp":0.0,"tv":0.0,"id":169},{"batb":[[0,1.35,6.45],[1,1.34,25.22],[2,1.32,44.35]],"batl":[[0,95,5.85]],"ltp":0.0,"tv":0.0,"id":60443},{"batb":[[0,1.51,16.81]],"batl":[[0,95,5.85]],"ltp":0.0,"tv":0.0,"id":31375}]}]}
{"op":"mcm","clk":"11913360682","pt":1724012971732,"mc":[{"id":"1.231893357","rc":[{"batb":[[0,1.5,20],[1,1.09,222.22],[2,1.03,200]],"ltp":0.0,"tv":0.0,"id":169},{"batb":[[1,1.32,44.35],[2,1.3,20]],"ltp":0.0,"tv":0.0,"id":60443},{"batb":[[0,1.5,20],[1,1.09,222.22],[2,1.03,200]],"ltp":0.0,"tv":0.0,"id":31375}]}]}
{"op":"mcm","clk":"11913366839","pt":1724013021479,"mc":[{"id":"1.231893357","rc":[{"batb":[[0,1.51,16.81],[1,1.5,20],[2,1.09,222.22]],"ltp":0.0,"tv":0.0,"id":169},{"batb":[[0,1.36,23.82],[1,1.35,6.45],[2,1.32,44.35]],"ltp":0.0,"tv":0.0,"id":60443},{"batb":[[0,1.51,16.81],[1,1.5,20],[2,1.09,222.22]],"ltp":0.0,"tv":0.0,"id":31375}]}]}
{"op":"mcm","clk":"11913544739","pt":1724014822854,"mc":[{"id":"1.231893357","rc":[{"batb":[[0,1.5,20],[1,1.09,222.22],[2,1.03,200]],"ltp":0.0,"tv":0.0,"id":169},{"batb":[[0,1.35,6.44],[1,1.32,44.33],[2,1.3,20]],"ltp":0.0,"tv":0.0,"id":60443},{"batb":[[0,1.51,16.8]],"ltp":0.0,"tv":0.0,"id":31375}]}]}
{"op":"mcm","clk":"11913544751","pt":1724014823058,"mc":[{"id":"1.231893357","rc":[{"batb":[[0,1.5,20],[1,1.09,222.22],[2,1.03,200]],"ltp":0.0,"tv":0.0,"id":31375}]}]}
{"op":"mcm","clk":"11913546536","pt":1724014847978,"mc":[{"id":"1.231893357","rc":[{"batb":[[0,1.33,6.44]],"ltp":0.0,"tv":0.0,"id":60443}]}]}
{"op":"mcm","clk":"11913550856","pt":1724014908938,"mc":[{"id":"1.231893357","rc":[{"batb":[[0,1.51,16.8],[1,1.5,20],[2,1.09,222.22]],"ltp":0.0,"tv":0.0,"id":169},{"batb":[[0,1.34,25.2],[1,1.33,6.44],[2,1.32,44.33]],"ltp":0.0,"tv":0.0,"id":60443},{"batb":[[0,1.51,16.8],[1,1.5,20],[2,1.09,222.22]],"ltp":0.0,"tv":0.0,"id":31375}]}]}
{"op":"mcm","clk":"11913666065","pt":1724016710910,"mc":[{"id":"1.231893357","rc":[{"batb":[[0,1.5,20],[1,1.09,222.22],[2,1.03,200]],"ltp":0.0,"tv":0.0,"id":169},{"batb":[[0,1.33,6.44],[1,1.32,44.33],[2,1.3,20]],"ltp":0.0,"tv":0.0,"id":60443},{"batb":[[0,1.5,20],[1,1.09,222.22],[2,1.03,200]],"ltp":0.0,"tv":0.0,"id":31375}]}]}
{"op":"mcm","clk":"11913672661","pt":1724016808505,"mc":[{"id":"1.231893357","rc":[{"batb":[[0,1.51,16.8],[1,1.5,20],[2,1.09,222.22]],"ltp":0.0,"tv":0.0,"id":169},{"batb":[[0,1.34,25.2],[1,1.33,6.44],[2,1.32,44.33]],"ltp":0.0,"tv":0.0,"id":60443},{"batb":[[0,1.51,16.8],[1,1.5,20],[2,1.09,222.22]],"ltp":0.0,"tv":0.0,"id":31375}]}]}
{"op":"mcm","clk":"11913734097","pt":1724017581022,"mc":[{"id":"1.231893357","rc":[{"batb":[[0,1.35,6.44],[1,1.34,25.2]],"ltp":0.0,"tv":0.0,"id":60443}]}]}
{"op":"mcm","clk":"11913801362","pt":1724018610520,"mc":[{"id":"1.231893357","rc":[{"batb":[[0,1.5,20],[1,1.09,222.22],[2,1.03,200]],"ltp":0.0,"tv":0.0,"id":169},{"batb":[[0,1.35,6.44],[1,1.32,44.29],[2,1.3,20]],"ltp":0.0,"tv":0.0,"id":60443},{"batb":[[0,1.5,20],[1,1.09,222.22],[2,1.03,200]],"ltp":0.0,"tv":0.0,"id":31375}]}]}
{"op":"mcm","clk":"11913804619","pt":1724018655563,"mc":[{"id":"1.231893357","rc":[{"batb":[[0,1.51,16.79],[1,1.5,20],[2,1.09,222.22]],"ltp":0.0,"tv":0.0,"id":169},{"batb":[[0,1.36,23.79],[1,1.35,6.44],[2,1.32,44.29]],"ltp":0.0,"tv":0.0,"id":60443},{"batb":[[0,1.51,16.79],[1,1.5,20],[2,1.09,222.22]],"ltp":0.0,"tv":0.0,"id":31375}]}]}
{"op":"mcm","clk":"11913899257","pt":1724020334158,"mc":[{"id":"1.231893357","rc":[{"batb":[[1,1.33,6.44]],"ltp":0.0,"tv":0.0,"id":60443}]}]}
{"op":"mcm","clk":"11913905211","pt":1724020455851,"mc":[{"id":"1.231893357","rc":[{"batb":[[0,1.5,20],[1,1.09,222.22],[2,1.03,200]],"ltp":0.0,"tv":0.0,"id":31375}]}]}
{"op":"mcm","clk":"11913905231","pt":1724020456261,"mc":[{"id":"1.231893357","rc":[{"batb":[[0,1.5,20],[1,1.09,222.22],[2,1.03,200]],"ltp":0.0,"tv":0.0,"id":169},{"batb":[[0,1.33,6.44],[1,1.32,44.29],[2,1.3,20]],"ltp":0.0,"tv":0.0,"id":60443}]}]}
{"op":"mcm","clk":"11913906260","pt":1724020478717,"mc":[{"id":"1.231893357","rc":[{"batb":[[0,1.51,16.79],[1,1.5,20],[2,1.09,222.22]],"ltp":0.0,"tv":0.0,"id":169},{"batb":[[0,1.34,25.19],[1,1.33,6.44],[2,1.32,44.29]],"ltp":0.0,"tv":0.0,"id":60443},{"batb":[[0,1.51,16.79],[1,1.5,20],[2,1.09,222.22]],"ltp":0.0,"tv":0.0,"id":31375}]}]}
{"op":"mcm","clk":"11913996172","pt":1724022278902,"mc":[{"id":"1.231893357","rc":[{"batb":[[2,1.32,44.3]],"ltp":0.0,"tv":0.0,"id":60443},{"batb":[[0,1.5,20],[1,1.09,222.22],[2,1.03,200]],"ltp":0.0,"tv":0.0,"id":31375}]}]}
{"op":"mcm","clk":"11913996191","pt":1724022279309,"mc":[{"id":"1.231893357","rc":[{"batb":[[0,1.5,20],[1,1.09,222.22],[2,1.03,200]],"ltp":0.0,"tv":0.0,"id":169},{"batb":[[0,1.33,6.44],[1,1.32,44.3],[2,1.3,20]],"ltp":0.0,"tv":0.0,"id":60443}]}]}
{"op":"mcm","clk":"11914002000","pt":1724022405436,"mc":[{"id":"1.231893357","rc":[{"batb":[[0,1.51,16.79],[1,1.5,20],[2,1.09,222.22]],"ltp":0.0,"tv":0.0,"id":169},{"batb":[[0,1.34,25.19],[1,1.33,6.44],[2,1.32,44.3]],"ltp":0.0,"tv":0.0,"id":60443},{"batb":[[0,1.51,16.79],[1,1.5,20],[2,1.09,222.22]],"ltp":0.0,"tv":0.0,"id":31375}]}]}
{"op":"mcm","clk":"11914044989","pt":1724023059012,"mc":[{"id":"1.231893357","rc":[{"batb":[[0,1.35,6.44],[1,1.34,25.19]],"ltp":0.0,"tv":0.0,"id":60443}]}]}
{"op":"mcm","clk":"11914106979","pt":1724024206912,"mc":[{"id":"1.231893357","rc":[{"batb":[[0,1.5,20],[1,1.09,222.22],[2,1.03,200]],"ltp":0.0,"tv":0.0,"id":31375}]}]}
{"op":"mcm","clk":"11914107003","pt":1724024207325,"mc":[{"id":"1.231893357","rc":[{"batb":[[0,1.5,20],[1,1.09,222.22],[2,1.03,200]],"ltp":0.0,"tv":0.0,"id":169},{"batb":[[1,1.32,44.3],[2,1.3,20]],"ltp":0.0,"tv":0.0,"id":60443}]}]}
{"op":"mcm","clk":"11914111634","pt":1724024290793,"mc":[{"id":"1.231893357","rc":[{"batb":[[0,1.51,16.79],[1,1.5,20],[2,1.09,222.22]],"ltp":0.0,"tv":0.0,"id":169},{"batb":[[0,1.36,23.79],[1,1.35,6.44],[2,1.32,44.3]],"ltp":0.0,"tv":0.0,"id":60443},{"batb":[[0,1.51,16.79],[1,1.5,20],[2,1.09,222.22]],"ltp":0.0,"tv":0.0,"id":31375}]}]}
{"op":"mcm","clk":"11914189470","pt":1724025773301,"mc":[{"id":"1.231893357","rc":[{"batb":[[0,1.51,16.79]],"ltp":0.0,"tv":0.0,"id":169},{"batb":[[0,1.36,23.78],[1,1.33,6.44],[2,1.32,44.29]],"ltp":0.0,"tv":0.0,"id":60443},{"batb":[[0,1.51,16.79]],"ltp":0.0,"tv":0.0,"id":31375}]}]}
{"op":"mcm","clk":"11914202695","pt":1724026091473,"mc":[{"id":"1.231893357","rc":[{"batb":[[0,1.5,20],[1,1.09,222.22],[2,1.03,200]],"ltp":0.0,"tv":0.0,"id":169},{"batb":[[0,1.33,6.44],[1,1.32,44.29],[2,1.3,20]],"ltp":0.0,"tv":0.0,"id":60443},{"batb":[[0,1.5,20],[1,1.09,222.22],[2,1.03,200]],"ltp":0.0,"tv":0.0,"id":31375}]}]}
{"op":"mcm","clk":"11914204787","pt":1724026142223,"mc":[{"id":"1.231893357","rc":[{"batb":[[0,1.51,16.79],[1,1.5,20],[2,1.09,222.22]],"ltp":0.0,"tv":0.0,"id":169},{"batb":[[0,1.34,25.18],[1,1.33,6.44],[2,1.32,44.29]],"ltp":0.0,"tv":0.0,"id":60443},{"batb":[[0,1.51,16.79],[1,1.5,20],[2,1.09,222.22]],"ltp":0.0,"tv":0.0,"id":31375}]}]}
{"op":"mcm","clk":"11914286164","pt":1724027942907,"mc":[{"id":"1.231893357","rc":[{"batb":[[0,1.5,20],[1,1.09,222.22],[2,1.03,200]],"ltp":0.0,"tv":0.0,"id":169},{"batb":[[0,1.33,6.44],[1,1.32,44.29],[2,1.3,20]],"ltp":0.0,"tv":0.0,"id":60443},{"batb":[[0,1.5,20],[1,1.09,222.22],[2,1.03,200]],"ltp":0.0,"tv":0.0,"id":31375}]}]}
{"op":"mcm","clk":"11914287461","pt":1724027973374,"mc":[{"id":"1.231893357","rc":[{"batb":[[0,1.51,16.79],[1,1.5,20],[2,1.09,222.22]],"ltp":0.0,"tv":0.0,"id":169},{"batb":[[0,1.34,25.18],[1,1.33,6.44],[2,1.32,44.29]],"ltp":0.0,"tv":0.0,"id":60443},{"batb":[[0,1.51,16.79],[1,1.5,20],[2,1.09,222.22]],"ltp":0.0,"tv":0.0,"id":31375}]}]}
{"op":"mcm","clk":"11914318390","pt":1724028446414,"mc":[{"id":"1.231893357","rc":[{"batb":[[0,1.35,6.44],[1,1.34,25.18]],"ltp":0.0,"tv":0.0,"id":60443}]}]}
{"op":"mcm","clk":"11914377663","pt":1724029774814,"mc":[{"id":"1.231893357","rc":[{"batb":[[0,1.5,20],[1,1.09,222.22],[2,1.03,200]],"ltp":0.0,"tv":0.0,"id":169},{"batb":[[1,1.32,44.31],[2,1.3,20]],"ltp":0.0,"tv":0.0,"id":60443},{"batb":[[0,1.5,20],[1,1.09,222.22],[2,1.03,200]],"ltp":0.0,"tv":0.0,"id":31375}]}]}
{"op":"mcm","clk":"11914378102","pt":1724029790748,"mc":[{"id":"1.231893357","rc":[{"batb":[[0,1.51,16.8],[1,1.5,20],[2,1.09,222.22]],"ltp":0.0,"tv":0.0,"id":169},{"batb":[[0,1.36,23.79],[1,1.35,6.43],[2,1.32,44.31]],"ltp":0.0,"tv":0.0,"id":60443},{"batb":[[0,1.51,16.8],[1,1.5,20],[2,1.09,222.22]],"ltp":0.0,"tv":0.0,"id":31375}]}]}
{"op":"mcm","clk":"11914412526","pt":1724031110789,"mc":[{"id":"1.231893357","rc":[{"batb":[[1,1.33,6.43]],"ltp":0.0,"tv":0.0,"id":60443}]}]}
{"op":"mcm","clk":"11914422368","pt":1724031591845,"mc":[{"id":"1.231893357","rc":[{"batb":[[0,1.5,20],[1,1.09,222.22],[2,1.03,200]],"ltp":0.0,"tv":0.0,"id":31375}]}]}
{"op":"mcm","clk":"11914422375","pt":1724031592206,"mc":[{"id":"1.231893357","rc":[{"batb":[[0,1.5,20],[1,1.09,222.22],[2,1.03,200]],"ltp":0.0,"tv":0.0,"id":169},{"batb":[[0,1.33,6.43],[1,1.32,44.31],[2,1.3,20]],"ltp":0.0,"tv":0.0,"id":60443}]}]}
{"op":"mcm","clk":"11914424695","pt":1724031699642,"mc":[{"id":"1.231893357","rc":[{"batb":[[0,1.51,16.8],[1,1.5,20],[2,1.09,222.22]],"ltp":0.0,"tv":0.0,"id":169},{"batb":[[0,1.34,25.19],[1,1.33,6.43],[2,1.32,44.31]],"ltp":0.0,"tv":0.0,"id":60443},{"batb":[[0,1.51,16.8],[1,1.5,20],[2,1.09,222.22]],"ltp":0.0,"tv":0.0,"id":31375}]}]}
{"op":"mcm","clk":"11914472407","pt":1724033499862,"mc":[{"id":"1.231893357","rc":[{"batb":[[0,1.51,16.79]],"ltp":0.0,"tv":0.0,"id":169},{"batb":[[0,1.33,6.43],[1,1.32,44.29],[2,1.3,20]],"ltp":0.0,"tv":0.0,"id":60443},{"batb":[[0,1.51,16.79]],"ltp":0.0,"tv":0.0,"id":31375}]}]}
{"op":"mcm","clk":"11914472422","pt":1724033500273,"mc":[{"id":"1.231893357","rc":[{"batb":[[0,1.5,20],[1,1.09,222.22],[2,1.03,200]],"ltp":0.0,"tv":0.0,"id":169},{"batb":[[0,1.5,20],[1,1.09,222.22],[2,1.03,200]],"ltp":0.0,"tv":0.0,"id":31375}]}]}
{"op":"mcm","clk":"11914485198","pt":1724033594815,"mc":[{"id":"1.231893357","rc":[{"batb":[[0,1.51,16.79],[1,1.5,20],[2,1.09,222.22]],"ltp":0.0,"tv":0.0,"id":169},{"batb":[[0,1.34,25.18],[1,1.33,6.43],[2,1.32,44.29]],"ltp":0.0,"tv":0.0,"id":60443},{"batb":[[0,1.51,16.79],[1,1.5,20],[2,1.09,222.22]],"ltp":0.0,"tv":0.0,"id":31375}]}]}
{"op":"mcm","clk":"11914490962","pt":1724033759548,"mc":[{"id":"1.231893357","rc":[{"batb":[[0,1.35,6.43],[1,1.34,25.18]],"ltp":0.0,"tv":0.0,"id":60443}]}]}
{"op":"mcm","clk":"11914538970","pt":1724035396019,"mc":[{"id":"1.231893357","rc":[{"batb":[[0,1.5,20],[1,1.09,222.22],[2,1.03,200]],"ltp":0.0,"tv":0.0,"id":31375}]}]}
{"op":"mcm","clk":"11914538987","pt":1724035396428,"mc":[{"id":"1.231893357","rc":[{"batb":[[0,1.5,20],[1,1.09,222.22],[2,1.03,200]],"ltp":0.0,"tv":0.0,"id":169},{"batb":[[1,1.32,44.29],[2,1.3,20]],"ltp":0.0,"tv":0.0,"id":60443}]}]}
{"op":"mcm","clk":"11914542174","pt":1724035486652,"mc":[{"id":"1.231893357","rc":[{"batb":[[0,1.51,16.79],[1,1.5,20],[2,1.09,222.22]],"ltp":0.0,"tv":0.0,"id":169},{"batb":[[0,1.36,23.78],[1,1.35,6.43],[2,1.32,44.29]],"ltp":0.0,"tv":0.0,"id":60443},{"batb":[[0,1.51,16.79],[1,1.5,20],[2,1.09,222.22]],"ltp":0.0,"tv":0.0,"id":31375}]}]}
{"op":"mcm","clk":"11914566037","pt":1724036420481,"mc":[{"id":"1.231893357","rc":[{"batb":[[0,1.51,16.78]],"ltp":0.0,"tv":0.0,"id":169},{"batb":[[0,1.36,23.78],[1,1.33,6.43],[2,1.32,44.28]],"ltp":0.0,"tv":0.0,"id":60443},{"batb":[[0,1.51,16.78]],"ltp":0.0,"tv":0.0,"id":31375}]}]}
{"op":"mcm","clk":"11914591473","pt":1724037286873,"mc":[{"id":"1.231893357","rc":[{"batb":[[0,1.5,20],[1,1.09,222.22],[2,1.03,200]],"ltp":0.0,"tv":0.0,"id":31375}]}]}
{"op":"mcm","clk":"11914591489","pt":1724037287283,"mc":[{"id":"1.231893357","rc":[{"batb":[[0,1.5,20],[1,1.09,222.22],[2,1.03,200]],"ltp":0.0,"tv":0.0,"id":169},{"batb":[[0,1.33,6.43],[1,1.32,44.28],[2,1.3,20]],"ltp":0.0,"tv":0.0,"id":60443}]}]}
{"op":"mcm","clk":"11914594132","pt":1724037363177,"mc":[{"id":"1.231893357","rc":[{"batb":[[0,1.51,16.78],[1,1.5,20],[2,1.09,222.22]],"ltp":0.0,"tv":0.0,"id":169},{"batb":[[0,1.34,25.18],[1,1.33,6.43],[2,1.32,44.28]],"ltp":0.0,"tv":0.0,"id":60443},{"batb":[[0,1.51,16.78],[1,1.5,20],[2,1.09,222.22]],"ltp":0.0,"tv":0.0,"id":31375}]}]}
{"op":"mcm","clk":"11914653513","pt":1724039072962,"mc":[{"id":"1.231893357","rc":[{"batb":[[0,1.35,6.43],[1,1.34,25.18]],"ltp":0.0,"tv":0.0,"id":60443}]}]}
{"op":"mcm","clk":"11914655734","pt":1724039164888,"mc":[{"id":"1.231893357","rc":[{"batb":[[0,1.5,20],[1,1.09,222.22],[2,1.03,200]],"ltp":0.0,"tv":0.0,"id":169},{"batb":[[1,1.32,44.28],[2,1.3,20]],"ltp":0.0,"tv":0.0,"id":60443},{"batb":[[0,1.5,20],[1,1.09,222.22],[2,1.03,200]],"ltp":0.0,"tv":0.0,"id":31375}]}]}
{"op":"mcm","clk":"11914657116","pt":1724039225375,"mc":[{"id":"1.231893357","rc":[{"batb":[[0,1.51,16.78],[1,1.5,20],[2,1.09,222.22]],"ltp":0.0,"tv":0.0,"id":169},{"batb":[[0,1.36,23.78],[1,1.35,6.43],[2,1.32,44.28]],"ltp":0.0,"tv":0.0,"id":60443},{"batb":[[0,1.51,16.78],[1,1.5,20],[2,1.09,222.22]],"ltp":0.0,"tv":0.0,"id":31375}]}]}
{"op":"mcm","clk":"11914704399","pt":1724041026808,"mc":[{"id":"1.231893357","rc":[{"batb":[[0,1.5,20],[1,1.09,222.22],[2,1.03,200]],"ltp":0.0,"tv":0.0,"id":169},{"batb":[[0,1.35,6.43],[1,1.32,44.31],[2,1.3,20]],"ltp":0.0,"tv":0.0,"id":60443},{"batb":[[0,1.5,20],[1,1.09,222.22],[2,1.03,200]],"ltp":0.0,"tv":0.0,"id":31375}]}]}
{"op":"mcm","clk":"11914705560","pt":1724041085796,"mc":[{"id":"1.231893357","rc":[{"batb":[[0,1.51,16.8],[1,1.5,20],[2,1.09,222.22]],"ltp":0.0,"tv":0.0,"id":169},{"batb":[[0,1.36,23.79],[1,1.35,6.43],[2,1.32,44.31]],"ltp":0.0,"tv":0.0,"id":60443},{"batb":[[0,1.51,16.8],[1,1.5,20],[2,1.09,222.22]],"ltp":0.0,"tv":0.0,"id":31375}]}]}
{"op":"mcm","clk":"11914722179","pt":1724041693555,"mc":[{"id":"1.231893357","rc":[{"batb":[[1,1.33,6.43]],"ltp":0.0,"tv":0.0,"id":60443}]}]}
{"op":"mcm","clk":"11914755736","pt":1724042886578,"mc":[{"id":"1.231893357","rc":[{"batb":[[0,1.33,6.43],[1,1.32,44.31],[2,1.3,20]],"ltp":0.0,"tv":0.0,"id":60443}]}]}
{"op":"mcm","clk":"11914755766","pt":1724042887600,"mc":[{"id":"1.231893357","rc":[{"batb":[[0,1.5,20],[1,1.09,222.22],[2,1.03,200]],"ltp":0.0,"tv":0.0,"id":169},{"batb":[[0,1.5,20],[1,1.09,222.22],[2,1.03,200]],"ltp":0.0,"tv":0.0,"id":31375}]}]}
{"op":"mcm","clk":"11914757330","pt":1724042934270,"mc":[{"id":"1.231893357","rc":[{"batb":[[0,1.51,16.8],[1,1.5,20],[2,1.09,222.22]],"ltp":0.0,"tv":0.0,"id":169},{"batb":[[0,1.34,25.19],[1,1.33,6.43],[2,1.32,44.31]],"ltp":0.0,"tv":0.0,"id":60443},{"batb":[[0,1.51,16.8],[1,1.5,20],[2,1.09,222.22]],"ltp":0.0,"tv":0.0,"id":31375}]}]}
{"op":"mcm","clk":"11914815352","pt":1724044361999,"mc":[{"id":"1.231893357","rc":[{"batb":[[0,1.51,16.8]],"ltp":0.0,"tv":0.0,"id":169},{"batb":[[0,1.34,25.2],[1,1.32,44.32],[2,1.3,20]],"ltp":0.0,"tv":0.0,"id":60443},{"batb":[[0,1.51,16.8]],"ltp":0.0,"tv":0.0,"id":31375}]}]}
{"op":"mcm","clk":"11914815358","pt":1724044362099,"mc":[{"id":"1.231893357","rc":[{"batb":[[0,1.35,6.43],[1,1.34,25.2],[2,1.32,44.32]],"ltp":0.0,"tv":0.0,"id":60443}]}]}
{"op":"mcm","clk":"11914840522","pt":1724044735843,"mc":[{"id":"1.231893357","rc":[{"batb":[[0,1.5,20],[1,1.09,222.22],[2,1.03,200]],"ltp":0.0,"tv":0.0,"id":31375}]}]}
{"op":"mcm","clk":"11914840535","pt":1724044736252,"mc":[{"id":"1.231893357","rc":[{"batb":[[0,1.5,20],[1,1.09,222.22],[2,1.03,200]],"ltp":0.0,"tv":0.0,"id":169},{"batb":[[1,1.32,44.32],[2,1.3,20]],"ltp":0.0,"tv":0.0,"id":60443}]}]}
{"op":"mcm","clk":"11914842264","pt":1724044778391,"mc":[{"id":"1.231893357","rc":[{"batb":[[0,1.51,16.8],[1,1.5,20],[2,1.09,222.22]],"ltp":0.0,"tv":0.0,"id":169},{"batb":[[0,1.36,23.8],[1,1.35,6.43],[2,1.32,44.32]],"ltp":0.0,"tv":0.0,"id":60443},{"batb":[[0,1.51,16.8],[1,1.5,20],[2,1.09,222.22]],"ltp":0.0,"tv":0.0,"id":31375}]}]}
{"op":"mcm","clk":"11914918674","pt":1724046579707,"mc":[{"id":"1.231893357","rc":[{"batb":[[0,1.5,20],[1,1.09,222.22],[2,1.03,200]],"ltp":0.0,"tv":0.0,"id":169},{"batb":[[0,1.35,6.43],[1,1.32,44.32],[2,1.3,20]],"ltp":0.0,"tv":0.0,"id":60443},{"batb":[[0,1.5,20],[1,1.09,222.22],[2,1.03,200]],"ltp":0.0,"tv":0.0,"id":31375}]}]}
{"op":"mcm","clk":"11914920485","pt":1724046619135,"mc":[{"id":"1.231893357","rc":[{"batb":[[0,1.51,16.8],[1,1.5,20],[2,1.09,222.22]],"ltp":0.0,"tv":0.0,"id":169},{"batb":[[0,1.36,23.8],[1,1.35,6.43],[2,1.32,44.32]],"ltp":0.0,"tv":0.0,"id":60443},{"batb":[[0,1.51,16.8],[1,1.5,20],[2,1.09,222.22]],"ltp":0.0,"tv":0.0,"id":31375}]}]}
{"op":"mcm","clk":"11914937879","pt":1724047034395,"mc":[{"id":"1.231893357","rc":[{"batb":[[1,1.33,6.43]],"ltp":0.0,"tv":0.0,"id":60443}]}]}
{"op":"mcm","clk":"11914996092","pt":1724048419683,"mc":[{"id":"1.231893357","rc":[{"batb":[[0,1.5,20],[1,1.09,222.22],[2,1.03,200]],"ltp":0.0,"tv":0.0,"id":169},{"batb":[[0,1.33,6.43],[1,1.32,44.32],[2,1.3,20]],"ltp":0.0,"tv":0.0,"id":60443},{"batb":[[0,1.5,20],[1,1.09,222.22],[2,1.03,200]],"ltp":0.0,"tv":0.0,"id":31375}]}]}
{"op":"mcm","clk":"11914997601","pt":1724048459186,"mc":[{"id":"1.231893357","rc":[{"batb":[[0,1.51,16.8],[1,1.5,20],[2,1.09,222.22]],"ltp":0.0,"tv":0.0,"id":169},{"batb":[[0,1.34,25.2],[1,1.33,6.43],[2,1.32,44.32]],"ltp":0.0,"tv":0.0,"id":60443},{"batb":[[0,1.51,16.8],[1,1.5,20],[2,1.09,222.22]],"ltp":0.0,"tv":0.0,"id":31375}]}]}
{"op":"mcm","clk":"11915057920","pt":1724049702683,"mc":[{"id":"1.231893357","rc":[{"batb":[[0,1.35,6.43],[1,1.34,25.2]],"ltp":0.0,"tv":0.0,"id":60443}]}]}
{"op":"mcm","clk":"11915093745","pt":1724050261393,"mc":[{"id":"1.231893357","rc":[{"batb":[[0,1.5,20],[1,1.09,222.22],[2,1.03,200]],"ltp":0.0,"tv":0.0,"id":169},{"batb":[[1,1.32,44.32],[2,1.3,20]],"ltp":0.0,"tv":0.0,"id":60443},{"batb":[[0,1.5,20],[1,1.09,222.22],[2,1.03,200]],"ltp":0.0,"tv":0.0,"id":31375}]}]}
{"op":"mcm","clk":"11915095368","pt":1724050293312,"mc":[{"id":"1.231893357","rc":[{"batb":[[0,1.51,16.8],[1,1.5,20],[2,1.09,222.22]],"ltp":0.0,"tv":0.0,"id":169},{"batb":[[0,1.36,23.8],[1,1.35,6.43],[2,1.32,44.32]],"ltp":0.0,"tv":0.0,"id":60443},{"batb":[[0,1.51,16.8],[1,1.5,20],[2,1.09,222.22]],"ltp":0.0,"tv":0.0,"id":31375}]}]}
{"op":"mcm","clk":"11915138248","pt":1724051135268,"mc":[{"id":"1.231893357","rc":[{"batb":[[0,1.51,16.79]],"ltp":0.0,"tv":0.0,"id":169},{"batb":[[0,1.36,23.78],[2,1.32,44.29]],"ltp":0.0,"tv":0.0,"id":60443},{"trd":[[1.51,0.29]],"batb":[[0,1.51,16.65]],"ltp":1.51,"tv":0.28,"id":31375}],"tv":0.28}]}
{"op":"mcm","clk":"11915179909","pt":1724052094923,"mc":[{"id":"1.231893357","rc":[{"batb":[[0,1.35,6.43],[1,1.32,44.29],[2,1.3,20]],"ltp":0.0,"tv":0.0,"id":60443}]}]}
{"op":"mcm","clk":"11915179929","pt":1724052095281,"mc":[{"id":"1.231893357","rc":[{"batb":[[0,1.5,20],[1,1.09,222.22],[2,1.03,200]],"ltp":0.0,"tv":0.0,"id":169},{"batb":[[0,1.5,20],[1,1.09,222.22],[2,1.03,200]],"ltp":1.51,"tv":0.28,"id":31375}]}]}
{"op":"mcm","clk":"11915181355","pt":1724052123830,"mc":[{"id":"1.231893357","rc":[{"batb":[[0,1.51,16.79],[1,1.5,20],[2,1.09,222.22]],"ltp":0.0,"tv":0.0,"id":169},{"batb":[[0,1.36,23.78],[1,1.35,6.43],[2,1.32,44.29]],"ltp":0.0,"tv":0.0,"id":60443}]}]}
{"op":"mcm","clk":"11915192836","pt":1724052373000,"mc":[{"id":"1.231893357","rc":[{"batb":[[1,1.33,6.43]],"ltp":0.0,"tv":0.0,"id":60443}]}]}
{"op":"mcm","clk":"11915259770","pt":1724053924290,"mc":[{"id":"1.231893357","rc":[{"batb":[[0,1.5,20],[1,1.09,222.22],[2,1.03,200]],"ltp":0.0,"tv":0.0,"id":169},{"batb":[[0,1.33,6.43],[1,1.32,44.29],[2,1.3,20]],"ltp":0.0,"tv":0.0,"id":60443}]}]}
{"op":"mcm","clk":"11915261495","pt":1724053954402,"mc":[{"id":"1.231893357","rc":[{"batb":[[0,1.51,16.79],[1,1.5,20],[2,1.09,222.22]],"ltp":0.0,"tv":0.0,"id":169},{"batb":[[0,1.34,25.18],[1,1.33,6.43],[2,1.32,44.29]],"ltp":0.0,"tv":0.0,"id":60443}]}]}
{"op":"mcm","clk":"11915311131","pt":1724055057300,"mc":[{"id":"1.231893357","rc":[{"batb":[[0,1.35,6.42],[1,1.34,25.18]],"ltp":0.0,"tv":0.0,"id":60443}]}]}
{"op":"mcm","clk":"11915351234","pt":1724055755637,"mc":[{"id":"1.231893357","rc":[{"batb":[[0,1.5,20],[1,1.09,222.22],[2,1.03,200]],"ltp":0.0,"tv":0.0,"id":169},{"batb":[[1,1.32,44.29],[2,1.3,20]],"ltp":0.0,"tv":0.0,"id":60443}]}]}
{"op":"mcm","clk":"11915352307","pt":1724055779707,"mc":[{"id":"1.231893357","rc":[{"batb":[[0,1.51,16.79],[1,1.5,20],[2,1.09,222.22]],"ltp":0.0,"tv":0.0,"id":169},{"batb":[[0,1.36,23.78],[1,1.35,6.42],[2,1.32,44.29]],"ltp":0.0,"tv":0.0,"id":60443}]}]}
{"op":"mcm","clk":"11915435029","pt":1724057581408,"mc":[{"id":"1.231893357","rc":[{"batb":[[0,1.5,20],[1,1.09,222.22],[2,1.03,200]],"ltp":0.0,"tv":0.0,"id":169},{"batb":[[0,1.35,6.42],[1,1.32,44.29],[2,1.3,20]],"ltp":0.0,"tv":0.0,"id":60443}]}]}
{"op":"mcm","clk":"11915435421","pt":1724057594208,"mc":[{"id":"1.231893357","rc":[{"batb":[[0,1.51,16.79],[1,1.5,20],[2,1.09,222.22]],"ltp":0.0,"tv":0.0,"id":169},{"batb":[[0,1.36,23.78],[1,1.35,6.42],[2,1.32,44.29]],"ltp":0.0,"tv":0.0,"id":60443}]}]}
{"op":"mcm","clk":"11915440310","pt":1724057724895,"mc":[{"id":"1.231893357","rc":[{"batb":[[1,1.33,6.42]],"ltp":0.0,"tv":0.0,"id":60443}]}]}
{"op":"mcm","clk":"11915506512","pt":1724059394684,"mc":[{"id":"1.231893357","rc":[{"batb":[[0,1.5,20],[1,1.09,222.22],[2,1.03,200]],"ltp":0.0,"tv":0.0,"id":169},{"batb":[[0,1.33,6.42],[1,1.32,44.25],[2,1.3,20]],"ltp":0.0,"tv":0.0,"id":60443}]}]}
{"op":"mcm","clk":"11915506934","pt":1724059409128,"mc":[{"id":"1.231893357","rc":[{"batb":[[0,1.51,16.77],[1,1.5,20],[2,1.09,222.22]],"ltp":0.0,"tv":0.0,"id":169},{"batb":[[0,1.34,25.16],[1,1.33,6.42],[2,1.32,44.25]],"ltp":0.0,"tv":0.0,"id":60443}]}]}
{"op":"mcm","clk":"11915537579","pt":1724060349576,"mc":[{"id":"1.231893357","rc":[{"batb":[[0,1.35,6.42],[1,1.34,25.16]],"ltp":0.0,"tv":0.0,"id":60443}]}]}
{"op":"mcm","clk":"11915579184","pt":1724061209550,"mc":[{"id":"1.231893357","rc":[{"batb":[[0,1.5,20],[1,1.09,222.22],[2,1.03,200]],"ltp":0.0,"tv":0.0,"id":169},{"batb":[[1,1.32,44.25],[2,1.3,20]],"ltp":0.0,"tv":0.0,"id":60443}]}]}
{"op":"mcm","clk":"11915579388","pt":1724061216155,"mc":[{"id":"1.231893357","rc":[{"batb":[[0,1.51,16.77],[1,1.5,20],[2,1.09,222.22]],"ltp":0.0,"tv":0.0,"id":169},{"batb":[[0,1.36,23.76],[1,1.35,6.42],[2,1.32,44.25]],"ltp":0.0,"tv":0.0,"id":60443}]}]}
{"op":"mcm","clk":"11915654531","pt":1724062994541,"mc":[{"id":"1.231893357","rc":[{"batb":[[0,1.51,16.78]],"ltp":0.0,"tv":0.0,"id":169},{"batb":[[0,1.36,23.77],[1,1.33,6.43],[2,1.32,44.26]],"ltp":0.0,"tv":0.0,"id":60443}]}]}
{"op":"mcm","clk":"11915655491","pt":1724063017869,"mc":[{"id":"1.231893357","rc":[{"batb":[[0,1.5,20],[1,1.09,222.22],[2,1.03,200]],"ltp":0.0,"tv":0.0,"id":169},{"batb":[[0,1.33,6.43],[1,1.32,44.26],[2,1.3,20]],"ltp":0.0,"tv":0.0,"id":60443}]}]}
{"op":"mcm","clk":"11915659660","pt":1724063121386,"mc":[{"id":"1.231893357","rc":[{"batb":[[0,1.51,16.78],[1,1.5,20],[2,1.09,222.22]],"ltp":0.0,"tv":0.0,"id":169},{"batb":[[0,1.34,25.16],[1,1.33,6.43],[2,1.32,44.26]],"ltp":0.0,"tv":0.0,"id":60443}]}]}
{"op":"mcm","clk":"11915733503","pt":1724064922960,"mc":[{"id":"1.231893357","rc":[{"batb":[[0,1.5,20],[1,1.09,222.22],[2,1.03,200]],"ltp":0.0,"tv":0.0,"id":169}]}]}
{"op":"mcm","clk":"11915733509","pt":1724064923166,"mc":[{"id":"1.231893357","rc":[{"batb":[[0,1.33,6.43],[1,1.32,44.26],[2,1.3,20]],"ltp":0.0,"tv":0.0,"id":60443}]}]}
{"op":"mcm","clk":"11915734956","pt":1724064962408,"mc":[{"id":"1.231893357","rc":[{"batb":[[0,1.51,16.78],[1,1.5,20],[2,1.09,222.22]],"ltp":0.0,"tv":0.0,"id":169},{"batb":[[0,1.34,25.16],[1,1.33,6.43],[2,1.32,44.26]],"ltp":0.0,"tv":0.0,"id":60443}]}]}
{"op":"mcm","clk":"11915763168","pt":1724065681814,"mc":[{"id":"1.231893357","rc":[{"batb":[[0,1.51,16.8]],"batl":[[0,95,5.85]],"ltp":0.0,"tv":0.0,"id":169},{"batb":[[0,1.35,6.43],[1,1.34,25.2],[2,1.32,44.32]],"batl":[[0,95,5.85]],"ltp":0.0,"tv":0.0,"id":60443},{"batl":[[0,95,5.85]],"ltp":1.51,"tv":0.28,"id":31375}]}]}
{"op":"mcm","clk":"11915813210","pt":1724066763734,"mc":[{"id":"1.231893357","rc":[{"batb":[[0,1.5,20],[1,1.09,222.22],[2,1.03,200]],"ltp":0.0,"tv":0.0,"id":169},{"batb":[[1,1.32,44.32],[2,1.3,20]],"ltp":0.0,"tv":0.0,"id":60443}]}]}
{"op":"mcm","clk":"11915814150","pt":1724066800686,"mc":[{"id":"1.231893357","rc":[{"batb":[[0,1.51,16.8],[1,1.5,20],[2,1.09,222.22]],"ltp":0.0,"tv":0.0,"id":169},{"batb":[[0,1.36,23.8],[1,1.35,6.43],[2,1.32,44.32]],"ltp":0.0,"tv":0.0,"id":60443}]}]}
{"op":"mcm","clk":"11915863887","pt":1724068350525,"mc":[{"id":"1.231893357","rc":[{"batb":[[1,1.33,6.43]],"ltp":0.0,"tv":0.0,"id":60443}]}]}
{"op":"mcm","clk":"11915873995","pt":1724068601023,"mc":[{"id":"1.231893357","rc":[{"batb":[[0,1.33,6.43],[1,1.32,44.32],[2,1.3,20]],"ltp":0.0,"tv":0.0,"id":60443}]}]}
{"op":"mcm","clk":"11915874004","pt":1724068601225,"mc":[{"id":"1.231893357","rc":[{"batb":[[0,1.5,20],[1,1.09,222.22],[2,1.03,200]],"ltp":0.0,"tv":0.0,"id":169}]}]}
{"op":"mcm","clk":"11915875538","pt":1724068635878,"mc":[{"id":"1.231893357","rc":[{"batb":[[0,1.51,16.8],[1,1.5,20],[2,1.09,222.22]],"ltp":0.0,"tv":0.0,"id":169},{"batb":[[0,1.34,25.2],[1,1.33,6.43],[2,1.32,44.32]],"ltp":0.0,"tv":0.0,"id":60443}]}]}
{"op":"mcm","clk":"11915965707","pt":1724070436406,"mc":[{"id":"1.231893357","rc":[{"batb":[[0,1.5,20],[1,1.09,222.22],[2,1.03,200]],"ltp":0.0,"tv":0.0,"id":169},{"batb":[[0,1.33,6.43],[1,1.32,44.32],[2,1.3,20]],"ltp":0.0,"tv":0.0,"id":60443}]}]}
{"op":"mcm","clk":"11915967003","pt":1724070463541,"mc":[{"id":"1.231893357","rc":[{"batb":[[0,1.51,16.8],[1,1.5,20],[2,1.09,222.22]],"ltp":0.0,"tv":0.0,"id":169},{"batb":[[0,1.34,25.19],[1,1.33,6.43],[2,1.32,44.32]],"ltp":0.0,"tv":0.0,"id":60443}]}]}
{"op":"mcm","clk":"11916006153","pt":1724071150238,"mc":[{"id":"1.231893357","rc":[{"batb":[[0,1.35,6.43],[1,1.34,25.19]],"ltp":0.0,"tv":0.0,"id":60443}]}]}
{"op":"mcm","clk":"11916072924","pt":1724072264984,"mc":[{"id":"1.231893357","rc":[{"batb":[[0,1.5,20],[1,1.09,222.22],[2,1.03,200]],"ltp":0.0,"tv":0.0,"id":169},{"batb":[[1,1.32,44.32],[2,1.3,20]],"ltp":0.0,"tv":0.0,"id":60443}]}]}
{"op":"mcm","clk":"11916073931","pt":1724072287983,"mc":[{"id":"1.231893357","rc":[{"batb":[[0,1.51,16.8],[1,1.5,20],[2,1.09,222.22]],"ltp":0.0,"tv":0.0,"id":169}]}]}
{"op":"mcm","clk":"11916073936","pt":1724072288079,"mc":[{"id":"1.231893357","rc":[{"batb":[[0,1.36,23.79],[1,1.35,6.43],[2,1.32,44.32]],"ltp":0.0,"tv":0.0,"id":60443}]}]}
{"op":"mcm","clk":"11916174598","pt":1724073908246,"mc":[{"id":"1.231893357","rc":[{"batb":[[0,1.51,16.8]],"ltp":0.0,"tv":0.0,"id":169},{"batb":[[0,1.36,23.8],[1,1.33,6.43]],"ltp":0.0,"tv":0.0,"id":60443}]}]}
{"op":"mcm","clk":"11916187613","pt":1724074088356,"mc":[{"id":"1.231893357","rc":[{"batb":[[0,1.5,20],[1,1.09,222.22],[2,1.03,200]],"ltp":0.0,"tv":0.0,"id":169}]}]}
{"op":"mcm","clk":"11916187706","pt":1724074089558,"mc":[{"id":"1.231893357","rc":[{"batb":[[0,1.33,6.43],[1,1.32,44.32],[2,1.3,20]],"ltp":0.0,"tv":0.0,"id":60443}]}]}
{"op":"mcm","clk":"11916189117","pt":1724074107852,"mc":[{"id":"1.231893357","rc":[{"batb":[[0,1.51,16.8],[1,1.5,20],[2,1.09,222.22]],"ltp":0.0,"tv":0.0,"id":169},{"batb":[[0,1.34,25.2],[1,1.33,6.43],[2,1.32,44.32]],"ltp":0.0,"tv":0.0,"id":60443}]}]}
{"op":"mcm","clk":"11916257491","pt":1724075121865,"mc":[{"id":"1.231893357","rc":[{"batb":[[0,1.34,26.1]],"ltp":0.0,"tv":0.0,"id":60443}]}]}
{"op":"mcm","clk":"11916306845","pt":1724075908512,"mc":[{"id":"1.231893357","rc":[{"batb":[[0,1.5,20],[1,1.09,222.22],[2,1.03,200]],"ltp":0.0,"tv":0.0,"id":169},{"batb":[[0,1.33,7.33],[1,1.32,44.32],[2,1.3,20]],"ltp":0.0,"tv":0.0,"id":60443}]}]}
{"op":"mcm","clk":"11916308086","pt":1724075930563,"mc":[{"id":"1.231893357","rc":[{"batb":[[0,1.51,16.8],[1,1.5,20],[2,1.09,222.22]],"ltp":0.0,"tv":0.0,"id":169},{"batb":[[0,1.34,26.1],[1,1.33,6.43],[2,1.32,44.32]],"ltp":0.0,"tv":0.0,"id":60443}]}]}
{"op":"mcm","clk":"11916341983","pt":1724076533689,"mc":[{"id":"1.231893357","rc":[{"batb":[[0,1.51,16.79]],"ltp":0.0,"tv":0.0,"id":169},{"batb":[[0,1.35,7.32],[1,1.34,25.19],[2,1.32,44.31]],"ltp":0.0,"tv":0.0,"id":60443}]}]}
{"op":"mcm","clk":"11916424047","pt":1724077731930,"mc":[{"id":"1.231893357","rc":[{"batb":[[1,1.32,44.31],[2,1.3,20]],"ltp":0.0,"tv":0.0,"id":60443}]}]}
{"op":"mcm","clk":"11916424056","pt":1724077732084,"mc":[{"id":"1.231893357","rc":[{"batb":[[0,1.5,20],[1,1.09,222.22],[2,1.03,200]],"ltp":0.0,"tv":0.0,"id":169}]}]}
{"op":"mcm","clk":"11916424152","pt":1724077733432,"mc":[{"id":"1.231893357","rc":[{"batb":[[0,1.51,16.79],[1,1.5,20],[2,1.09,222.22]],"ltp":0.0,"tv":0.0,"id":169},{"batb":[[0,1.36,24.69],[1,1.35,6.43],[2,1.32,44.31]],"ltp":0.0,"tv":0.0,"id":60443}]}]}
{"op":"mcm","clk":"11916528036","pt":1724079359366,"mc":[{"id":"1.231893357","rc":[{"batb":[[1,1.33,6.43]],"ltp":0.0,"tv":0.0,"id":60443}]}]}
{"op":"mcm","clk":"11916541582","pt":1724079533844,"mc":[{"id":"1.231893357","rc":[{"batb":[[0,1.5,20],[1,1.09,222.22],[2,1.03,200]],"ltp":0.0,"tv":0.0,"id":169}]}]}
{"op":"mcm","clk":"11916541598","pt":1724079534046,"mc":[{"id":"1.231893357","rc":[{"batb":[[0,1.33,7.32],[1,1.32,44.31],[2,1.3,20]],"ltp":0.0,"tv":0.0,"id":60443}]}]}
{"op":"mcm","clk":"11916554103","pt":1724079683723,"mc":[{"id":"1.231893357","rc":[{"batb":[[0,1.51,16.79],[1,1.5,20],[2,1.09,222.22]],"ltp":0.0,"tv":0.0,"id":169},{"batb":[[0,1.34,26.08],[1,1.33,6.41],[2,1.32,44.31]],"ltp":0.0,"tv":0.0,"id":60443}]}]}
{"op":"mcm","clk":"11916654317","pt":1724080763687,"mc":[{"id":"1.231893357","rc":[{"batb":[[0,1.35,45.2],[1,1.34,25.19],[2,1.33,6.41]],"ltp":0.0,"tv":0.0,"id":60443}]}]}
{"op":"mcm","clk":"11916734547","pt":1724081485286,"mc":[{"id":"1.231893357","rc":[{"batb":[[0,1.5,20],[1,1.09,222.22],[2,1.03,200]],"ltp":0.0,"tv":0.0,"id":169},{"batb":[[1,1.33,6.41],[2,1.3,20]],"ltp":0.0,"tv":0.0,"id":60443}]}]}
{"op":"mcm","clk":"11916750147","pt":1724081631815,"mc":[{"id":"1.231893357","rc":[{"batb":[[0,1.51,16.79],[1,1.5,20],[2,1.09,222.22]],"ltp":0.0,"tv":0.0,"id":169},{"batb":[[0,1.36,24.68],[1,1.35,44.31],[2,1.33,6.41]],"ltp":0.0,"tv":0.0,"id":60443}]}]}
{"op":"mcm","clk":"11916799121","pt":1724082151514,"mc":[{"id":"1.231893357","rc":[{"batb":[[2,1.3,20]],"ltp":0.0,"tv":0.0,"id":60443}]}]}
{"op":"mcm","clk":"11916936255","pt":1724083432946,"mc":[{"id":"1.231893357","rc":[{"batb":[[0,1.5,20],[1,1.09,222.22],[2,1.03,200]],"ltp":0.0,"tv":0.0,"id":169},{"batb":[[0,1.35,45.23],[1,1.3,20],[2,1.09,222.22]],"ltp":0.0,"tv":0.0,"id":60443}]}]}
{"op":"mcm","clk":"11916936623","pt":1724083435849,"mc":[{"id":"1.231893357","rc":[{"batb":[[0,1.51,16.8],[1,1.5,20],[2,1.09,222.22]],"ltp":0.0,"tv":0.0,"id":169},{"batb":[[0,1.36,24.7],[1,1.35,44.34],[2,1.3,20]],"ltp":0.0,"tv":0.0,"id":60443}]}]}
{"op":"mcm","clk":"11917180812","pt":1724085236891,"mc":[{"id":"1.231893357","rc":[{"batb":[[0,1.5,20],[1,1.09,222.22],[2,1.03,200]],"ltp":0.0,"tv":0.0,"id":169},{"batb":[[0,1.35,45.23],[1,1.3,20],[2,1.09,222.22]],"ltp":0.0,"tv":0.0,"id":60443}]}]}
{"op":"mcm","clk":"11917187163","pt":1724085283005,"mc":[{"id":"1.231893357","rc":[{"batb":[[0,1.51,16.8],[1,1.5,20],[2,1.09,222.22]],"ltp":0.0,"tv":0.0,"id":169},{"batb":[[0,1.36,24.7],[1,1.35,44.34],[2,1.3,20]],"ltp":0.0,"tv":0.0,"id":60443}]}]}
{"op":"mcm","clk":"11917409385","pt":1724087083350,"mc":[{"id":"1.231893357","rc":[{"batb":[[0,1.5,20],[1,1.09,222.22],[2,1.03,200]],"ltp":0.0,"tv":0.0,"id":169},{"batb":[[0,1.35,45.25],[1,1.3,20],[2,1.09,222.22]],"ltp":0.0,"tv":0.0,"id":60443}]}]}
{"op":"mcm","clk":"11917413323","pt":1724087110554,"mc":[{"id":"1.231893357","rc":[{"batb":[[0,1.51,16.81],[1,1.5,20],[2,1.09,222.22]],"ltp":0.0,"tv":0.0,"id":169},{"batb":[[0,1.36,24.71],[1,1.35,44.36],[2,1.3,20]],"ltp":0.0,"tv":0.0,"id":60443}]}]}
{"op":"mcm","clk":"11917688986","pt":1724088911556,"mc":[{"id":"1.231893357","rc":[{"batb":[[0,1.5,20],[1,1.09,222.22],[2,1.03,200]],"ltp":0.0,"tv":0.0,"id":169},{"batb":[[0,1.35,45.25],[1,1.3,20],[2,1.09,222.22]],"ltp":0.0,"tv":0.0,"id":60443}]}]}
{"op":"mcm","clk":"11917689134","pt":1724088912660,"mc":[{"id":"1.231893357","rc":[{"batb":[[0,1.51,16.81],[1,1.5,20],[2,1.09,222.22]],"ltp":0.0,"tv":0.0,"id":169},{"batb":[[0,1.36,24.71],[1,1.35,44.36],[2,1.3,20]],"ltp":0.0,"tv":0.0,"id":60443}]}]}
{"op":"mcm","clk":"11917945565","pt":1724090713961,"mc":[{"id":"1.231893357","rc":[{"batb":[[0,1.5,20],[1,1.09,222.22],[2,1.03,200]],"ltp":0.0,"tv":0.0,"id":169},{"batb":[[0,1.35,45.23],[1,1.3,20],[2,1.09,222.22]],"ltp":0.0,"tv":0.0,"id":60443}]}]}
{"op":"mcm","clk":"11917964733","pt":1724090858186,"mc":[{"id":"1.231893357","rc":[{"batb":[[0,1.51,16.8],[1,1.5,20],[2,1.09,222.22]],"ltp":0.0,"tv":0.0,"id":169},{"batb":[[0,1.36,24.7],[1,1.35,44.34],[2,1.3,20]],"ltp":0.0,"tv":0.0,"id":60443}]}]}
{"op":"mcm","clk":"11918246077","pt":1724092659498,"mc":[{"id":"1.231893357","rc":[{"batb":[[0,1.5,20],[1,1.09,222.22],[2,1.03,200]],"ltp":0.0,"tv":0.0,"id":169},{"batb":[[0,1.35,45.23],[1,1.3,20],[2,1.09,222.22]],"ltp":0.0,"tv":0.0,"id":60443}]}]}
{"op":"mcm","clk":"11918263222","pt":1724092760468,"mc":[{"id":"1.231893357","rc":[{"batb":[[0,1.51,16.8],[1,1.5,20],[2,1.09,222.22]],"ltp":0.0,"tv":0.0,"id":169},{"batb":[[0,1.36,24.7],[1,1.35,44.34],[2,1.3,20]],"ltp":0.0,"tv":0.0,"id":60443}]}]}
{"op":"mcm","clk":"11918533182","pt":1724094561959,"mc":[{"id":"1.231893357","rc":[{"batb":[[0,1.5,20],[1,1.09,222.22],[2,1.03,200]],"ltp":0.0,"tv":0.0,"id":169},{"batb":[[0,1.35,45.25],[1,1.3,20],[2,1.09,222.22]],"ltp":0.0,"tv":0.0,"id":60443}]}]}
{"op":"mcm","clk":"11918542790","pt":1724094629334,"mc":[{"id":"1.231893357","rc":[{"batb":[[0,1.51,16.81],[1,1.5,20],[2,1.09,222.22]],"ltp":0.0,"tv":0.0,"id":169},{"batb":[[0,1.36,24.71],[1,1.35,44.35],[2,1.3,20]],"ltp":0.0,"tv":0.0,"id":60443}]}]}
{"op":"mcm","clk":"11918797647","pt":1724096430675,"mc":[{"id":"1.231893357","rc":[{"batb":[[0,1.5,20],[1,1.09,222.22],[2,1.03,200]],"ltp":0.0,"tv":0.0,"id":169},{"batb":[[0,1.35,45.25],[1,1.3,20],[2,1.09,222.22]],"ltp":0.0,"tv":0.0,"id":60443}]}]}
{"op":"mcm","clk":"11918807717","pt":1724096501976,"mc":[{"id":"1.231893357","rc":[{"batb":[[0,1.51,16.81],[1,1.5,20],[2,1.09,222.22]],"ltp":0.0,"tv":0.0,"id":169},{"batb":[[0,1.36,24.71],[1,1.35,44.35],[2,1.3,20]],"ltp":0.0,"tv":0.0,"id":60443}]}]}
{"op":"mcm","clk":"11919012334","pt":1724098303244,"mc":[{"id":"1.231893357","rc":[{"batb":[[0,1.5,20],[1,1.09,222.22],[2,1.03,200]],"ltp":0.0,"tv":0.0,"id":169},{"batb":[[0,1.35,45.26],[1,1.3,20],[2,1.09,222.22]],"ltp":0.0,"tv":0.0,"id":60443}]}]}
{"op":"mcm","clk":"11919029021","pt":1724098386603,"mc":[{"id":"1.231893357","rc":[{"batb":[[0,1.51,16.81],[1,1.5,20],[2,1.09,222.22]],"ltp":0.0,"tv":0.0,"id":169},{"batb":[[0,1.36,24.72],[1,1.35,44.37],[2,1.3,20]],"ltp":0.0,"tv":0.0,"id":60443}]}]}
{"op":"mcm","clk":"11919186600","pt":1724100187012,"mc":[{"id":"1.231893357","rc":[{"batb":[[0,1.35,45.26],[1,1.3,20],[2,1.09,222.22]],"ltp":0.0,"tv":0.0,"id":60443}]}]}
{"op":"mcm","clk":"11919186615","pt":1724100187219,"mc":[{"id":"1.231893357","rc":[{"batb":[[0,1.5,20],[1,1.09,222.22],[2,1.03,200]],"ltp":0.0,"tv":0.0,"id":169}]}]}
{"op":"mcm","clk":"11919189404","pt":1724100220682,"mc":[{"id":"1.231893357","rc":[{"batb":[[0,1.51,16.81],[1,1.5,20],[2,1.09,222.22]],"ltp":0.0,"tv":0.0,"id":169},{"batb":[[0,1.36,24.72],[1,1.35,44.37],[2,1.3,20]],"ltp":0.0,"tv":0.0,"id":60443}]}]}
{"op":"mcm","clk":"11919294366","pt":1724102021337,"mc":[{"id":"1.231893357","rc":[{"batb":[[0,1.5,20],[1,1.09,222.22],[2,1.03,200]],"ltp":0.0,"tv":0.0,"id":169},{"batb":[[0,1.35,45.26],[1,1.3,20],[2,1.09,222.22]],"ltp":0.0,"tv":0.0,"id":60443}]}]}
{"op":"mcm","clk":"11919299931","pt":1724102169188,"mc":[{"id":"1.231893357","rc":[{"batb":[[0,1.51,16.82],[1,1.5,20],[2,1.09,222.22]],"ltp":0.0,"tv":0.0,"id":169},{"batb":[[0,1.36,24.72],[1,1.35,44.37],[2,1.3,20]],"ltp":0.0,"tv":0.0,"id":60443}]}]}
{"op":"mcm","clk":"11919378599","pt":1724103970271,"mc":[{"id":"1.231893357","rc":[{"batb":[[0,1.5,20],[1,1.09,222.22],[2,1.03,200]],"ltp":0.0,"tv":0.0,"id":169},{"batb":[[0,1.35,45.26],[1,1.3,20],[2,1.09,222.22]],"ltp":0.0,"tv":0.0,"id":60443}]}]}
{"op":"mcm","clk":"11919383353","pt":1724104090862,"mc":[{"id":"1.231893357","rc":[{"batb":[[0,1.51,16.82],[1,1.5,20],[2,1.09,222.22]],"ltp":0.0,"tv":0.0,"id":169},{"batb":[[0,1.36,24.72],[1,1.35,44.37],[2,1.3,20]],"ltp":0.0,"tv":0.0,"id":60443}]}]}
{"op":"mcm","clk":"11919461071","pt":1724105892517,"mc":[{"id":"1.231893357","rc":[{"batb":[[0,1.5,20],[1,1.09,222.22],[2,1.03,200]],"ltp":0.0,"tv":0.0,"id":169},{"batb":[[0,1.35,45.27],[1,1.3,20],[2,1.09,222.22]],"ltp":0.0,"tv":0.0,"id":60443}]}]}
{"op":"mcm","clk":"11919465062","pt":1724105989534,"mc":[{"id":"1.231893357","rc":[{"batb":[[0,1.51,16.82],[1,1.5,20],[2,1.09,222.22]],"ltp":0.0,"tv":0.0,"id":169},{"batb":[[0,1.36,24.72],[1,1.35,44.37],[2,1.3,20]],"ltp":0.0,"tv":0.0,"id":60443}]}]}
{"op":"mcm","clk":"11919558520","pt":1724107790896,"mc":[{"id":"1.231893357","rc":[{"batb":[[0,1.5,20],[1,1.09,222.22],[2,1.03,200]],"ltp":0.0,"tv":0.0,"id":169}]}]}
{"op":"mcm","clk":"11919558530","pt":1724107791099,"mc":[{"id":"1.231893357","rc":[{"batb":[[0,1.35,45.27],[1,1.3,20],[2,1.09,222.22]],"ltp":0.0,"tv":0.0,"id":60443}]}]}
{"op":"mcm","clk":"11919562843","pt":1724107871070,"mc":[{"id":"1.231893357","rc":[{"batb":[[0,1.51,16.82],[1,1.5,20],[2,1.09,222.22]],"ltp":0.0,"tv":0.0,"id":169},{"batb":[[0,1.36,24.72],[1,1.35,44.37],[2,1.3,20]],"ltp":0.0,"tv":0.0,"id":60443}]}]}
{"op":"mcm","clk":"11919629112","pt":1724109174830,"mc":[{"id":"1.231893357","rc":[{"batb":[[1,1.35,44.38]],"ltp":0.0,"tv":0.0,"id":60443}]}]}
{"op":"mcm","clk":"11919662174","pt":1724109671613,"mc":[{"id":"1.231893357","rc":[{"batb":[[0,1.5,20],[1,1.09,222.22],[2,1.03,200]],"ltp":0.0,"tv":0.0,"id":169},{"batb":[[0,1.35,45.27],[1,1.3,20],[2,1.09,222.22]],"ltp":0.0,"tv":0.0,"id":60443}]}]}
{"op":"mcm","clk":"11919665894","pt":1724109744528,"mc":[{"id":"1.231893357","rc":[{"batb":[[0,1.51,16.82],[1,1.5,20],[2,1.09,222.22]],"ltp":0.0,"tv":0.0,"id":169},{"batb":[[0,1.36,24.72],[1,1.35,44.38],[2,1.3,20]],"ltp":0.0,"tv":0.0,"id":60443}]}]}
{"op":"mcm","clk":"11919761744","pt":1724111545788,"mc":[{"id":"1.231893357","rc":[{"batb":[[0,1.35,45.27],[1,1.3,20],[2,1.09,222.22]],"ltp":0.0,"tv":0.0,"id":60443}]}]}
{"op":"mcm","clk":"11919761756","pt":1724111546094,"mc":[{"id":"1.231893357","rc":[{"batb":[[0,1.5,20],[1,1.09,222.22],[2,1.03,200]],"ltp":0.0,"tv":0.0,"id":169}]}]}
{"op":"mcm","clk":"11919764584","pt":1724111600044,"mc":[{"id":"1.231893357","rc":[{"batb":[[0,1.51,16.82],[1,1.5,20],[2,1.09,222.22]],"ltp":0.0,"tv":0.0,"id":169},{"batb":[[0,1.36,24.72],[1,1.35,44.38],[2,1.3,20]],"ltp":0.0,"tv":0.0,"id":60443}]}]}
{"op":"mcm","clk":"11919863623","pt":1724113400601,"mc":[{"id":"1.231893357","rc":[{"batb":[[0,1.5,20],[1,1.09,222.22],[2,1.03,200]],"ltp":0.0,"tv":0.0,"id":169},{"batb":[[0,1.35,45.27],[1,1.3,20],[2,1.09,222.22]],"ltp":0.0,"tv":0.0,"id":60443}]}]}
{"op":"mcm","clk":"11919865944","pt":1724113431050,"mc":[{"id":"1.231893357","rc":[{"batb":[[0,1.51,16.82],[1,1.5,20],[2,1.09,222.22]],"ltp":0.0,"tv":0.0,"id":169},{"batb":[[0,1.36,24.72],[1,1.35,44.38],[2,1.3,20]],"ltp":0.0,"tv":0.0,"id":60443}]}]}
{"op":"mcm","clk":"11919959032","pt":1724115232473,"mc":[{"id":"1.231893357","rc":[{"batb":[[0,1.5,20],[1,1.09,222.22],[2,1.03,200]],"ltp":0.0,"tv":0.0,"id":169},{"batb":[[0,1.35,45.27],[1,1.3,20],[2,1.09,222.22]],"ltp":0.0,"tv":0.0,"id":60443}]}]}
{"op":"mcm","clk":"11919959382","pt":1724115239758,"mc":[{"id":"1.231893357","rc":[{"batb":[[0,1.51,16.82],[1,1.5,20],[2,1.09,222.22]],"ltp":0.0,"tv":0.0,"id":169},{"batb":[[0,1.36,24.72],[1,1.35,44.38],[2,1.3,20]],"ltp":0.0,"tv":0.0,"id":60443}]}]}
{"op":"mcm","clk":"11920043375","pt":1724117040467,"mc":[{"id":"1.231893357","rc":[{"batb":[[0,1.5,20],[1,1.09,222.22],[2,1.03,200]],"ltp":0.0,"tv":0.0,"id":169},{"batb":[[0,1.35,45.27],[1,1.3,20],[2,1.09,222.22]],"ltp":0.0,"tv":0.0,"id":60443}]}]}
{"op":"mcm","clk":"11920049698","pt":1724117167139,"mc":[{"id":"1.231893357","rc":[{"batb":[[0,1.51,16.82],[1,1.5,20],[2,1.09,222.22]],"ltp":0.0,"tv":0.0,"id":169},{"batb":[[0,1.36,24.72],[1,1.35,44.38],[2,1.3,20]],"ltp":0.0,"tv":0.0,"id":60443}]}]}
{"op":"mcm","clk":"11920141844","pt":1724118967670,"mc":[{"id":"1.231893357","rc":[{"batb":[[0,1.5,20],[1,1.09,222.22],[2,1.03,200]],"ltp":0.0,"tv":0.0,"id":169},{"batb":[[0,1.35,45.27],[1,1.3,20],[2,1.09,222.22]],"ltp":0.0,"tv":0.0,"id":60443}]}]}
{"op":"mcm","clk":"11920145824","pt":1724119050948,"mc":[{"id":"1.231893357","rc":[{"batb":[[0,1.51,16.82],[1,1.5,20],[2,1.09,222.22]],"ltp":0.0,"tv":0.0,"id":169},{"batb":[[0,1.36,24.72],[1,1.35,44.38],[2,1.3,20]],"ltp":0.0,"tv":0.0,"id":60443}]}]}
{"op":"mcm","clk":"11920190027","pt":1724119974830,"mc":[{"id":"1.231893357","rc":[{"batb":[[0,1.51,16.82]],"ltp":0.0,"tv":0.0,"id":169},{"batb":[[0,1.36,24.73],[1,1.35,44.39]],"ltp":0.0,"tv":0.0,"id":60443}]}]}
{"op":"mcm","clk":"11920232902","pt":1724120852667,"mc":[{"id":"1.231893357","rc":[{"batb":[[0,1.5,20],[1,1.09,222.22],[2,1.03,200]],"ltp":0.0,"tv":0.0,"id":169},{"batb":[[0,1.35,45.29],[1,1.3,20],[2,1.09,222.22]],"ltp":0.0,"tv":0.0,"id":60443}]}]}
{"op":"mcm","clk":"11920234647","pt":1724120911933,"mc":[{"id":"1.231893357","rc":[{"batb":[[0,1.51,16.82],[1,1.5,20],[2,1.09,222.22]],"ltp":0.0,"tv":0.0,"id":169},{"batb":[[0,1.36,24.73],[1,1.35,44.39],[2,1.3,20]],"ltp":0.0,"tv":0.0,"id":60443}]}]}
{"op":"mcm","clk":"11920330903","pt":1724123617614,"mc":[{"id":"1.231893357","rc":[{"batb":[[0,1.5,20],[1,1.09,222.22],[2,1.03,200]],"ltp":0.0,"tv":0.0,"id":169},{"batb":[[0,1.35,45.27],[1,1.3,20],[2,1.09,222.22]],"ltp":0.0,"tv":0.0,"id":60443}]}]}
{"op":"mcm","clk":"11920334443","pt":1724123740255,"mc":[{"id":"1.231893357","rc":[{"batb":[[0,1.51,16.82],[1,1.5,20],[2,1.09,222.22]],"ltp":0.0,"tv":0.0,"id":169},{"batb":[[0,1.36,24.72],[1,1.35,44.38],[2,1.3,20]],"ltp":0.0,"tv":0.0,"id":60443}]}]}
{"op":"mcm","clk":"11920394572","pt":1724125541485,"mc":[{"id":"1.231893357","rc":[{"batb":[[0,1.5,20],[1,1.09,222.22],[2,1.03,200]],"ltp":0.0,"tv":0.0,"id":169},{"batb":[[0,1.35,45.27],[1,1.3,20],[2,1.09,222.22]],"ltp":0.0,"tv":0.0,"id":60443}]}]}
{"op":"mcm","clk":"11920395014","pt":1724125557608,"mc":[{"id":"1.231893357","rc":[{"batb":[[0,1.51,16.82],[1,1.5,20],[2,1.09,222.22]],"ltp":0.0,"tv":0.0,"id":169},{"batb":[[0,1.36,24.72],[1,1.35,44.38],[2,1.3,20]],"ltp":0.0,"tv":0.0,"id":60443}]}]}
{"op":"mcm","clk":"11920451414","pt":1724127359846,"mc":[{"id":"1.231893357","rc":[{"batb":[[0,1.5,20],[1,1.09,222.22],[2,1.03,200]],"ltp":0.0,"tv":0.0,"id":169}]}]}
{"op":"mcm","clk":"11920451421","pt":1724127360051,"mc":[{"id":"1.231893357","rc":[{"batb":[[0,1.35,45.27],[1,1.3,20],[2,1.09,222.22]],"ltp":0.0,"tv":0.0,"id":60443}]}]}
{"op":"mcm","clk":"11920451527","pt":1724127363332,"mc":[{"id":"1.231893357","rc":[{"batb":[[0,1.51,16.82],[1,1.5,20],[2,1.09,222.22]],"ltp":0.0,"tv":0.0,"id":169},{"batb":[[0,1.36,24.72],[1,1.35,44.38],[2,1.3,20]],"ltp":0.0,"tv":0.0,"id":60443}]}]}
{"op":"mcm","clk":"11920511254","pt":1724129165983,"mc":[{"id":"1.231893357","rc":[{"batb":[[0,1.5,20],[1,1.09,222.22],[2,1.03,200]],"ltp":0.0,"tv":0.0,"id":169},{"batb":[[0,1.35,45.27],[1,1.3,20],[2,1.09,222.22]],"ltp":0.0,"tv":0.0,"id":60443}]}]}
{"op":"mcm","clk":"11920515837","pt":1724129313807,"mc":[{"id":"1.231893357","rc":[{"batb":[[0,1.51,16.82],[1,1.5,20],[2,1.09,222.22]],"ltp":0.0,"tv":0.0,"id":169},{"batb":[[0,1.36,24.72],[1,1.35,44.38],[2,1.3,20]],"ltp":0.0,"tv":0.0,"id":60443}]}]}
{"op":"mcm","clk":"11920594009","pt":1724131114392,"mc":[{"id":"1.231893357","rc":[{"batb":[[0,1.5,20],[1,1.09,222.22],[2,1.03,200]],"ltp":0.0,"tv":0.0,"id":169},{"batb":[[0,1.35,45.27],[1,1.3,20],[2,1.09,222.22]],"ltp":0.0,"tv":0.0,"id":60443}]}]}
{"op":"mcm","clk":"11920595867","pt":1724131180779,"mc":[{"id":"1.231893357","rc":[{"batb":[[0,1.51,16.82],[1,1.5,20],[2,1.09,222.22]],"ltp":0.0,"tv":0.0,"id":169},{"batb":[[0,1.36,24.72],[1,1.35,44.38],[2,1.3,20]],"ltp":0.0,"tv":0.0,"id":60443}]}]}
{"op":"mcm","clk":"11920660048","pt":1724132982371,"mc":[{"id":"1.231893357","rc":[{"batb":[[0,1.5,20],[1,1.09,222.22],[2,1.03,200]],"ltp":0.0,"tv":0.0,"id":169},{"batb":[[0,1.35,45.27],[1,1.3,20],[2,1.09,222.22]],"ltp":0.0,"tv":0.0,"id":60443}]}]}
{"op":"mcm","clk":"11920663155","pt":1724133047668,"mc":[{"id":"1.231893357","rc":[{"batb":[[0,1.51,16.82],[1,1.5,20],[2,1.09,222.22]],"ltp":0.0,"tv":0.0,"id":169},{"batb":[[0,1.36,24.72],[1,1.35,44.38],[2,1.3,20]],"ltp":0.0,"tv":0.0,"id":60443}]}]}
{"op":"mcm","clk":"11920717052","pt":1724134848927,"mc":[{"id":"1.231893357","rc":[{"batb":[[0,1.5,20],[1,1.09,222.22],[2,1.03,200]],"ltp":0.0,"tv":0.0,"id":169},{"batb":[[0,1.35,45.27],[1,1.3,20],[2,1.09,222.22]],"ltp":0.0,"tv":0.0,"id":60443}]}]}
{"op":"mcm","clk":"11920718729","pt":1724134913426,"mc":[{"id":"1.231893357","rc":[{"batb":[[0,1.51,16.82],[1,1.5,20],[2,1.09,222.22]],"ltp":0.0,"tv":0.0,"id":169},{"batb":[[0,1.36,24.72],[1,1.35,44.37],[2,1.3,20]],"ltp":0.0,"tv":0.0,"id":60443}]}]}
{"op":"mcm","clk":"11920783502","pt":1724136714347,"mc":[{"id":"1.231893357","rc":[{"batb":[[0,1.5,20],[1,1.09,222.22],[2,1.03,200]],"ltp":0.0,"tv":0.0,"id":169},{"batb":[[0,1.35,45.27],[1,1.3,20],[2,1.09,222.22]],"ltp":0.0,"tv":0.0,"id":60443}]}]}
{"op":"mcm","clk":"11920785285","pt":1724136777337,"mc":[{"id":"1.231893357","rc":[{"batb":[[0,1.51,16.82],[1,1.5,20],[2,1.09,222.22]],"ltp":0.0,"tv":0.0,"id":169},{"batb":[[0,1.36,24.72],[1,1.35,44.37],[2,1.3,20]],"ltp":0.0,"tv":0.0,"id":60443}]}]}
{"op":"mcm","clk":"11920786424","pt":1724136811481,"mc":[{"id":"1.231893357","rc":[{"batb":[[0,1.5,20.54]],"ltp":1.51,"tv":0.28,"id":31375}]}]}
{"op":"mcm","clk":"11920786747","pt":1724136820465,"mc":[{"id":"1.231893357","rc":[{"batb":[[0,1.51,17.35]],"ltp":0.0,"tv":0.0,"id":169}]}]}
{"op":"mcm","clk":"11920787076","pt":1724136830884,"mc":[{"id":"1.231893357","rc":[{"batb":[[0,1.4,1.43],[1,1.36,23.82],[2,1.35,44.37]],"ltp":0.0,"tv":0.0,"id":60443}]}]}
{"op":"mcm","clk":"11920846362","pt":1724138577843,"mc":[{"id":"1.231893357","rc":[{"batb":[[0,1.5,20.54],[1,1.09,222.22],[2,1.03,200]],"ltp":0.0,"tv":0.0,"id":169},{"batb":[[0,1.4,1.43],[1,1.35,44.35],[2,1.3,20]],"ltp":0.0,"tv":0.0,"id":60443}]}]}
{"op":"mcm","clk":"11920848410","pt":1724138640096,"mc":[{"id":"1.231893357","rc":[{"batb":[[0,1.51,17.34],[1,1.5,20],[2,1.09,222.22]],"ltp":0.0,"tv":0.0,"id":169},{"batb":[[1,1.36,23.81],[2,1.35,44.35]],"ltp":0.0,"tv":0.0,"id":60443}]}]}
{"op":"mcm","clk":"11920902673","pt":1724140440540,"mc":[{"id":"1.231893357","rc":[{"batb":[[0,1.5,20.54],[1,1.09,222.22],[2,1.03,200]],"ltp":0.0,"tv":0.0,"id":169},{"batb":[[1,1.35,44.35],[2,1.3,20]],"ltp":0.0,"tv":0.0,"id":60443}]}]}
{"op":"mcm","clk":"11920904769","pt":1724140500509,"mc":[{"id":"1.231893357","rc":[{"batb":[[0,1.5,20]],"ltp":0.0,"tv":0.0,"id":169},{"batb":[[0,1.35,45.24],[1,1.3,20],[2,1.09,222.22]],"ltp":0.0,"tv":0.0,"id":60443},{"batb":[[0,1.5,20]],"ltp":1.51,"tv":0.28,"id":31375}]}]}
{"op":"mcm","clk":"11920904914","pt":1724140504370,"mc":[{"id":"1.231893357","rc":[{"batb":[[0,1.51,16.81],[1,1.5,20],[2,1.09,222.22]],"ltp":0.0,"tv":0.0,"id":169},{"batb":[[0,1.36,24.7],[1,1.35,44.35],[2,1.3,20]],"ltp":0.0,"tv":0.0,"id":60443}]}]}
{"op":"mcm","clk":"11920937387","pt":1724141574820,"mc":[{"id":"1.231893357","rc":[{"batb":[[0,1.51,16.8]],"ltp":0.0,"tv":0.0,"id":169},{"batb":[[0,1.36,24.7],[1,1.35,44.34]],"ltp":0.0,"tv":0.0,"id":60443}]}]}
{"op":"mcm","clk":"11920965971","pt":1724142305726,"mc":[{"id":"1.231893357","rc":[{"batb":[[0,1.5,20],[1,1.09,222.22],[2,1.03,200]],"ltp":0.0,"tv":0.0,"id":169},{"batb":[[0,1.35,45.23],[1,1.3,20],[2,1.09,222.22]],"ltp":0.0,"tv":0.0,"id":60443}]}]}
{"op":"mcm","clk":"11920969984","pt":1724142441589,"mc":[{"id":"1.231893357","rc":[{"batb":[[0,1.51,16.8],[1,1.5,20],[2,1.09,222.22]],"ltp":0.0,"tv":0.0,"id":169},{"batb":[[0,1.36,24.7],[1,1.35,44.34],[2,1.3,20]],"ltp":0.0,"tv":0.0,"id":60443}]}]}
{"op":"mcm","clk":"11921033737","pt":1724144243288,"mc":[{"id":"1.231893357","rc":[{"batb":[[0,1.5,20],[1,1.09,222.22],[2,1.03,200]],"ltp":0.0,"tv":0.0,"id":169},{"batb":[[0,1.35,45.23],[1,1.3,20],[2,1.09,222.22]],"ltp":0.0,"tv":0.0,"id":60443}]}]}
{"op":"mcm","clk":"11921034905","pt":1724144285222,"mc":[{"id":"1.231893357","rc":[{"batb":[[0,1.51,16.8],[1,1.5,20],[2,1.09,222.22]],"ltp":0.0,"tv":0.0,"id":169},{"batb":[[0,1.36,24.7],[1,1.35,44.34],[2,1.3,20]],"ltp":0.0,"tv":0.0,"id":60443}]}]}
{"op":"mcm","clk":"11921100000","pt":1724146087579,"mc":[{"id":"1.231893357","rc":[{"batb":[[0,1.5,20],[1,1.09,222.22],[2,1.03,200]],"ltp":0.0,"tv":0.0,"id":169},{"batb":[[0,1.35,45.21],[1,1.3,20],[2,1.09,222.22]],"ltp":0.0,"tv":0.0,"id":60443}]}]}
{"op":"mcm","clk":"11921101384","pt":1724146122311,"mc":[{"id":"1.231893357","rc":[{"batb":[[0,1.51,16.8],[1,1.5,20],[2,1.09,222.22]],"ltp":0.0,"tv":0.0,"id":169},{"batb":[[0,1.36,24.69],[1,1.35,44.32],[2,1.3,20]],"ltp":0.0,"tv":0.0,"id":60443}]}]}
{"op":"mcm","clk":"11921185771","pt":1724147924242,"mc":[{"id":"1.231893357","rc":[{"batb":[[0,1.5,20],[1,1.09,222.22],[2,1.03,200]],"ltp":0.0,"tv":0.0,"id":169},{"batb":[[0,1.35,45.21],[1,1.3,20],[2,1.09,222.22]],"ltp":0.0,"tv":0.0,"id":60443}]}]}
{"op":"mcm","clk":"11921186865","pt":1724147954398,"mc":[{"id":"1.231893357","rc":[{"batb":[[0,1.51,16.8],[1,1.5,20],[2,1.09,222.22]],"ltp":0.0,"tv":0.0,"id":169},{"batb":[[0,1.36,24.69],[1,1.35,44.32],[2,1.3,20]],"ltp":0.0,"tv":0.0,"id":60443}]}]}
{"op":"mcm","clk":"11921271105","pt":1724149755911,"mc":[{"id":"1.231893357","rc":[{"batb":[[0,1.5,20],[1,1.09,222.22],[2,1.03,200]],"ltp":0.0,"tv":0.0,"id":169},{"batb":[[0,1.35,45.19],[1,1.3,20],[2,1.09,222.22]],"ltp":0.0,"tv":0.0,"id":60443}]}]}
{"op":"mcm","clk":"11921272436","pt":1724149786105,"mc":[{"id":"1.231893357","rc":[{"batb":[[0,1.51,16.79],[1,1.5,20],[2,1.09,222.22]],"ltp":0.0,"tv":0.0,"id":169},{"batb":[[0,1.36,24.67],[1,1.35,44.29],[2,1.3,20]],"ltp":0.0,"tv":0.0,"id":60443}]}]}
{"op":"mcm","clk":"11921308346","pt":1724150699737,"mc":[{"id":"1.231893357","rc":[{"batb":[[2,1.04,1.53]],"ltp":1.51,"tv":0.28,"id":31375}]}]}
{"op":"mcm","clk":"11921349685","pt":1724151587924,"mc":[{"id":"1.231893357","rc":[{"batb":[[0,1.35,45.19],[1,1.3,20],[2,1.09,222.22]],"ltp":0.0,"tv":0.0,"id":60443}]}]}
{"op":"mcm","clk":"11921349694","pt":1724151588131,"mc":[{"id":"1.231893357","rc":[{"batb":[[0,1.5,20],[1,1.09,222.22],[2,1.04,1.53]],"ltp":0.0,"tv":0.0,"id":169}]}]}
{"op":"mcm","clk":"11921350417","pt":1724151602649,"mc":[{"id":"1.231893357","rc":[{"batb":[[0,1.51,16.79],[1,1.5,20],[2,1.09,222.22]],"ltp":0.0,"tv":0.0,"id":169},{"batb":[[0,1.36,24.67],[1,1.35,44.29],[2,1.3,20]],"ltp":0.0,"tv":0.0,"id":60443}]}]}
{"op":"mcm","clk":"11921385159","pt":1724152374833,"mc":[{"id":"1.231893357","rc":[{"batb":[[0,1.51,16.79]],"ltp":0.0,"tv":0.0,"id":169},{"batb":[[0,1.36,24.69],[1,1.35,44.32]],"ltp":0.0,"tv":0.0,"id":60443}]}]}
{"op":"mcm","clk":"11921438276","pt":1724153403580,"mc":[{"id":"1.231893357","rc":[{"batb":[[0,1.5,20],[1,1.09,222.22],[2,1.04,1.53]],"ltp":0.0,"tv":0.0,"id":169},{"batb":[[0,1.35,45.21],[1,1.3,20],[2,1.09,222.22]],"ltp":0.0,"tv":0.0,"id":60443}]}]}
{"op":"mcm","clk":"11921438309","pt":1724153404227,"mc":[{"id":"1.231893357","rc":[{"batb":[[0,1.51,16.79],[1,1.5,20],[2,1.09,222.22]],"ltp":0.0,"tv":0.0,"id":169},{"batb":[[0,1.36,24.69],[1,1.35,44.32],[2,1.3,20]],"ltp":0.0,"tv":0.0,"id":60443}]}]}
{"op":"mcm","clk":"11921508212","pt":1724155002857,"mc":[{"id":"1.231893357","rc":[{"trd":[[1.5,2]],"batb":[[0,1.5,19]],"ltp":1.5,"tv":2.28,"id":31375}],"tv":2.28}]}
{"op":"mcm","clk":"11921508719","pt":1724155013285,"mc":[{"id":"1.231893357","rc":[{"batl":[[0,1.7,1],[1,95,5.85],[2,990,5]],"ltp":1.5,"tv":2.28,"id":31375}]}]}
{"op":"mcm","clk":"11921517296","pt":1724155207560,"mc":[{"id":"1.231893357","rc":[{"batb":[[0,1.5,20],[1,1.09,222.22],[2,1.04,1.53]],"ltp":0.0,"tv":0.0,"id":169},{"batb":[[0,1.35,45.18],[1,1.3,20],[2,1.09,222.22]],"ltp":0.0,"tv":0.0,"id":60443}]}]}
{"op":"mcm","clk":"11921523976","pt":1724155345212,"mc":[{"id":"1.231893357","rc":[{"batb":[[0,1.51,16.78],[1,1.5,20],[2,1.09,222.22]],"ltp":0.0,"tv":0.0,"id":169},{"batb":[[0,1.36,24.67],[1,1.35,44.29],[2,1.3,20]],"ltp":0.0,"tv":0.0,"id":60443}]}]}
{"op":"mcm","clk":"11921611761","pt":1724157146859,"mc":[{"id":"1.231893357","rc":[{"batb":[[0,1.35,45.18],[1,1.3,20],[2,1.09,222.22]],"ltp":0.0,"tv":0.0,"id":60443}]}]}
{"op":"mcm","clk":"11921611772","pt":1724157147061,"mc":[{"id":"1.231893357","rc":[{"batb":[[0,1.5,20],[1,1.09,222.22],[2,1.04,1.53]],"ltp":0.0,"tv":0.0,"id":169}]}]}
{"op":"mcm","clk":"11921613448","pt":1724157180292,"mc":[{"id":"1.231893357","rc":[{"batb":[[0,1.51,16.78],[1,1.5,20],[2,1.09,222.22]],"ltp":0.0,"tv":0.0,"id":169},{"batb":[[0,1.36,24.67],[1,1.35,44.29],[2,1.3,20]],"ltp":0.0,"tv":0.0,"id":60443}]}]}
{"op":"mcm","clk":"11921714587","pt":1724158982645,"mc":[{"id":"1.231893357","rc":[{"batb":[[0,1.5,20],[1,1.09,222.22],[2,1.04,1.53]],"ltp":0.0,"tv":0.0,"id":169},{"batb":[[0,1.35,45.19],[1,1.3,20],[2,1.09,222.22]],"ltp":0.0,"tv":0.0,"id":60443}]}]}
{"op":"mcm","clk":"11921715624","pt":1724159002860,"mc":[{"id":"1.231893357","rc":[{"batb":[[0,1.51,16.79],[1,1.5,20],[2,1.09,222.22]],"ltp":0.0,"tv":0.0,"id":169},{"batb":[[0,1.36,24.67],[1,1.35,44.29],[2,1.3,20]],"ltp":0.0,"tv":0.0,"id":60443}]}]}
{"op":"mcm","clk":"11921815824","pt":1724160804914,"mc":[{"id":"1.231893357","rc":[{"batb":[[0,1.5,20],[1,1.09,222.22],[2,1.04,1.53]],"ltp":0.0,"tv":0.0,"id":169},{"batb":[[0,1.35,45.19],[1,1.3,20],[2,1.09,222.22]],"ltp":0.0,"tv":0.0,"id":60443}]}]}
{"op":"mcm","clk":"11921816271","pt":1724160814194,"mc":[{"id":"1.231893357","rc":[{"batb":[[0,1.51,16.79],[1,1.5,20],[2,1.09,222.22]],"ltp":0.0,"tv":0.0,"id":169},{"batb":[[0,1.36,24.67],[1,1.35,44.29],[2,1.3,20]],"ltp":0.0,"tv":0.0,"id":60443}]}]}
{"op":"mcm","clk":"11921912033","pt":1724162615943,"mc":[{"id":"1.231893357","rc":[{"batb":[[0,1.5,20],[1,1.09,222.22],[2,1.04,1.53]],"ltp":0.0,"tv":0.0,"id":169},{"batb":[[0,1.35,45.2],[1,1.3,20],[2,1.09,222.22]],"ltp":0.0,"tv":0.0,"id":60443}]}]}
{"op":"mcm","clk":"11921912192","pt":1724162618565,"mc":[{"id":"1.231893357","rc":[{"batb":[[0,1.51,16.79],[1,1.5,20],[2,1.09,222.22]],"ltp":0.0,"tv":0.0,"id":169},{"batb":[[0,1.36,24.68],[1,1.35,44.31],[2,1.3,20]],"ltp":0.0,"tv":0.0,"id":60443}]}]}
{"op":"mcm","clk":"11921961583","pt":1724163295561,"mc":[{"id":"1.231893357","rc":[{"batb":[[0,1.36,23.79]],"ltp":0.0,"tv":0.0,"id":60443}]}]}
{"op":"mcm","clk":"11921962643","pt":1724163314480,"mc":[{"id":"1.231893357","rc":[{"trd":[[1.7,1.78]],"batl":[[0,95,5.96],[1,990,5],[2,990,0]],"ltp":1.7,"tv":4.06,"id":31375}],"tv":4.06}]}
{"op":"mcm","clk":"11922023646","pt":1724164419979,"mc":[{"id":"1.231893357","rc":[{"batb":[[0,1.35,44.31],[1,1.3,20],[2,1.09,222.22]],"ltp":0.0,"tv":0.0,"id":60443}]}]}
{"op":"mcm","clk":"11922023652","pt":1724164420083,"mc":[{"id":"1.231893357","rc":[{"batb":[[0,1.5,20],[1,1.09,222.22],[2,1.04,1.53]],"ltp":0.0,"tv":0.0,"id":169}]}]}
{"op":"mcm","clk":"11922033075","pt":1724164575964,"mc":[{"id":"1.231893357","rc":[{"batb":[[0,1.51,16.79],[1,1.5,20],[2,1.09,222.22]],"ltp":0.0,"tv":0.0,"id":169},{"batb":[[0,1.36,23.79],[1,1.35,44.31],[2,1.3,20]],"ltp":0.0,"tv":0.0,"id":60443}]}]}
{"op":"mcm","clk":"11922130958","pt":1724166311883,"mc":[{"id":"1.231893357","rc":[{"batb":[[0,1.51,16.8]],"batl":[[0,90,1.02],[1,95,5],[2,990,5]],"ltp":0.0,"tv":0.0,"id":169},{"batb":[[0,1.36,23.81],[1,1.35,44.34]],"batl":[[0,90,1.02],[1,95,5],[2,990,5]],"ltp":0.0,"tv":0.0,"id":60443},{"batl":[[0,90,1.13],[1,95,5],[2,990,5]],"ltp":1.7,"tv":4.06,"id":31375}]}]}
{"op":"mcm","clk":"11922135970","pt":1724166376958,"mc":[{"id":"1.231893357","rc":[{"batb":[[0,1.35,44.34],[1,1.3,20],[2,1.09,222.22]],"ltp":0.0,"tv":0.0,"id":60443}]}]}
{"op":"mcm","clk":"11922135978","pt":1724166377065,"mc":[{"id":"1.231893357","rc":[{"batb":[[0,1.5,20],[1,1.09,222.22],[2,1.04,1.53]],"ltp":0.0,"tv":0.0,"id":169}]}]}
{"op":"mcm","clk":"11922136743","pt":1724166387461,"mc":[{"id":"1.231893357","rc":[{"batl":[[2,990,5.17]],"ltp":0.0,"tv":0.0,"id":169},{"batl":[[2,990,5.17]],"ltp":0.0,"tv":0.0,"id":60443},{"batl":[[2,990,5.17]],"ltp":1.7,"tv":4.06,"id":31375}]}]}
{"op":"mcm","clk":"11922137742","pt":1724166401773,"mc":[{"id":"1.231893357","rc":[{"batl":[[2,990,5.34]],"ltp":0.0,"tv":0.0,"id":169},{"batl":[[2,990,5.34]],"ltp":0.0,"tv":0.0,"id":60443},{"batl":[[2,990,5.34]],"ltp":1.7,"tv":4.06,"id":31375}]}]}
{"op":"mcm","clk":"11922142857","pt":1724166474542,"mc":[{"id":"1.231893357","rc":[{"batl":[[2,990,5.51]],"ltp":0.0,"tv":0.0,"id":169},{"batl":[[2,990,5.51]],"ltp":0.0,"tv":0.0,"id":60443},{"batl":[[2,990,5.51]],"ltp":1.7,"tv":4.06,"id":31375}]}]}
{"op":"mcm","clk":"11922145858","pt":1724166516166,"mc":[{"id":"1.231893357","rc":[{"batb":[[0,1.51,16.8],[1,1.5,20],[2,1.09,222.22]],"ltp":0.0,"tv":0.0,"id":169},{"batb":[[0,1.36,23.81],[1,1.35,44.34],[2,1.3,20]],"ltp":0.0,"tv":0.0,"id":60443}]}]}
{"op":"mcm","clk":"11922280155","pt":1724168301815,"mc":[{"id":"1.231893357","rc":[{"batl":[[0,90,1.58]],"ltp":1.7,"tv":4.06,"id":31375}]}]}
{"op":"mcm","clk":"11922281367","pt":1724168316926,"mc":[{"id":"1.231893357","rc":[{"batb":[[0,1.5,20],[1,1.09,222.22],[2,1.04,1.53]],"ltp":0.0,"tv":0.0,"id":169},{"batb":[[0,1.35,44.34],[1,1.3,20],[2,1.09,222.22]],"ltp":0.0,"tv":0.0,"id":60443}]}]}
{"op":"mcm","clk":"11922293507","pt":1724168446300,"mc":[{"id":"1.231893357","rc":[{"batb":[[0,1.51,16.8],[1,1.5,20],[2,1.09,222.22]],"ltp":0.0,"tv":0.0,"id":169},{"batb":[[0,1.36,23.81],[1,1.35,44.34],[2,1.3,20]],"ltp":0.0,"tv":0.0,"id":60443}]}]}
{"op":"mcm","clk":"11922472998","pt":1724170246803,"mc":[{"id":"1.231893357","rc":[{"batb":[[0,1.5,20],[1,1.09,222.22],[2,1.04,1.53]],"ltp":0.0,"tv":0.0,"id":169},{"batb":[[0,1.35,44.34],[1,1.3,20],[2,1.09,222.22]],"ltp":0.0,"tv":0.0,"id":60443}]}]}
{"op":"mcm","clk":"11922485825","pt":1724170363790,"mc":[{"id":"1.231893357","rc":[{"batb":[[0,1.51,16.8],[1,1.5,20],[2,1.09,222.22]],"ltp":0.0,"tv":0.0,"id":169},{"batb":[[0,1.36,23.81],[1,1.35,44.34],[2,1.3,20]],"ltp":0.0,"tv":0.0,"id":60443}]}]}
{"op":"mcm","clk":"11922682141","pt":1724172165605,"mc":[{"id":"1.231893357","rc":[{"batb":[[0,1.5,20],[1,1.09,222.22],[2,1.04,1.53]],"ltp":0.0,"tv":0.0,"id":169},{"batb":[[0,1.35,44.34],[1,1.3,20],[2,1.09,222.22]],"ltp":0.0,"tv":0.0,"id":60443}]}]}
{"op":"mcm","clk":"11922691712","pt":1724172257538,"mc":[{"id":"1.231893357","rc":[{"batb":[[0,1.51,16.8],[1,1.5,20],[2,1.09,222.22]],"ltp":0.0,"tv":0.0,"id":169},{"batb":[[0,1.36,23.81],[1,1.35,44.34],[2,1.3,20]],"ltp":0.0,"tv":0.0,"id":60443}]}]}
{"op":"mcm","clk":"11922826506","pt":1724173591484,"mc":[{"id":"1.231893357","rc":[{"batb":[[0,1.51,16.82]],"ltp":0.0,"tv":0.0,"id":169},{"batb":[[0,1.36,23.82],[1,1.35,44.37]],"ltp":0.0,"tv":0.0,"id":60443},{"batb":[[0,1.5,19.89]],"ltp":1.7,"tv":4.06,"id":31375}]}]}
{"op":"mcm","clk":"11922892745","pt":1724174058843,"mc":[{"id":"1.231893357","rc":[{"batb":[[0,1.5,20],[1,1.09,222.22],[2,1.04,1.53]],"ltp":0.0,"tv":0.0,"id":169}]}]}
{"op":"mcm","clk":"11922892760","pt":1724174059047,"mc":[{"id":"1.231893357","rc":[{"batb":[[0,1.35,44.37],[1,1.3,20],[2,1.09,222.22]],"ltp":0.0,"tv":0.0,"id":60443}]}]}
{"op":"mcm","clk":"11922901272","pt":1724174128618,"mc":[{"id":"1.231893357","rc":[{"batb":[[0,1.51,16.82],[1,1.5,20],[2,1.09,222.22]],"ltp":0.0,"tv":0.0,"id":169},{"batb":[[0,1.36,23.82],[1,1.35,44.37],[2,1.3,20]],"ltp":0.0,"tv":0.0,"id":60443}]}]}
{"op":"mcm","clk":"11923103899","pt":1724175930330,"mc":[{"id":"1.231893357","rc":[{"batb":[[0,1.5,20],[1,1.09,222.22],[2,1.04,1.53]],"ltp":0.0,"tv":0.0,"id":169},{"batb":[[0,1.35,44.37],[1,1.3,20],[2,1.09,222.22]],"ltp":0.0,"tv":0.0,"id":60443}]}]}
{"op":"mcm","clk":"11923108168","pt":1724175964682,"mc":[{"id":"1.231893357","rc":[{"batb":[[0,1.51,16.82],[1,1.5,20],[2,1.09,222.22]],"ltp":0.0,"tv":0.0,"id":169},{"batb":[[0,1.36,23.82],[1,1.35,44.37],[2,1.3,20]],"ltp":0.0,"tv":0.0,"id":60443}]}]}
{"op":"mcm","clk":"11923204553","pt":1724176927487,"mc":[{"id":"1.231893357","rc":[{"batb":[[0,1.51,16.83]],"ltp":0.0,"tv":0.0,"id":169},{"batb":[[0,1.36,23.84],[1,1.35,44.39]],"ltp":0.0,"tv":0.0,"id":60443},{"batl":[[0,85,1.73],[1,95,5.85]],"ltp":1.7,"tv":4.06,"id":31375}]}]}
{"op":"mcm","clk":"11923222827","pt":1724177077610,"mc":[{"id":"1.231893357","rc":[{"batl":[[0,85,1.17],[1,95,5.85]],"ltp":0.0,"tv":0.0,"id":60443}]}]}
{"op":"mcm","clk":"11923223521","pt":1724177083114,"mc":[{"id":"1.231893357","rc":[{"batl":[[0,85,1.17],[1,95,5.85]],"ltp":0.0,"tv":0.0,"id":169}]}]}
{"op":"mcm","clk":"11923319748","pt":1724177766020,"mc":[{"id":"1.231893357","rc":[{"batb":[[0,1.5,20],[1,1.09,222.22],[2,1.04,1.53]],"ltp":0.0,"tv":0.0,"id":169},{"batb":[[0,1.35,44.39],[1,1.3,20],[2,1.09,222.22]],"ltp":0.0,"tv":0.0,"id":60443}]}]}
{"op":"mcm","clk":"11923320651","pt":1724177772830,"mc":[{"id":"1.231893357","rc":[{"batb":[[0,1.51,16.83],[1,1.5,20],[2,1.09,222.22]],"ltp":0.0,"tv":0.0,"id":169},{"batb":[[0,1.36,23.84],[1,1.35,44.39],[2,1.3,20]],"ltp":0.0,"tv":0.0,"id":60443}]}]}
{"op":"mcm","clk":"11923576192","pt":1724179573421,"mc":[{"id":"1.231893357","rc":[{"batb":[[0,1.5,20],[1,1.09,222.22],[2,1.04,1.53]],"ltp":0.0,"tv":0.0,"id":169},{"batb":[[0,1.35,44.39],[1,1.3,20],[2,1.09,222.22]],"ltp":0.0,"tv":0.0,"id":60443}]}]}
{"op":"mcm","clk":"11923593914","pt":1724179677744,"mc":[{"id":"1.231893357","rc":[{"batb":[[0,1.51,16.83],[1,1.5,20],[2,1.09,222.22]],"ltp":0.0,"tv":0.0,"id":169},{"batb":[[0,1.36,23.84],[1,1.35,44.39],[2,1.3,20]],"ltp":0.0,"tv":0.0,"id":60443}]}]}
{"op":"mcm","clk":"11923889402","pt":1724181479694,"mc":[{"id":"1.231893357","rc":[{"batb":[[0,1.5,20],[1,1.09,222.22],[2,1.04,1.53]],"ltp":0.0,"tv":0.0,"id":169},{"batb":[[0,1.35,44.38],[1,1.3,20],[2,1.09,222.22]],"ltp":0.0,"tv":0.0,"id":60443}]}]}
{"op":"mcm","clk":"11923899751","pt":1724181538258,"mc":[{"id":"1.231893357","rc":[{"batb":[[0,1.51,16.82],[1,1.5,20],[2,1.09,222.22]],"ltp":0.0,"tv":0.0,"id":169},{"batb":[[0,1.36,23.83],[1,1.35,44.38],[2,1.3,20]],"ltp":0.0,"tv":0.0,"id":60443}]}]}
{"op":"mcm","clk":"11924159012","pt":1724183339846,"mc":[{"id":"1.231893357","rc":[{"batb":[[0,1.5,20],[1,1.09,222.22],[2,1.04,1.53]],"ltp":0.0,"tv":0.0,"id":169},{"batb":[[0,1.35,44.38],[1,1.3,20],[2,1.09,222.22]],"ltp":0.0,"tv":0.0,"id":60443}]}]}
{"op":"mcm","clk":"11924164516","pt":1724183378487,"mc":[{"id":"1.231893357","rc":[{"batb":[[0,1.51,16.82],[1,1.5,20],[2,1.09,222.22]],"ltp":0.0,"tv":0.0,"id":169},{"batb":[[0,1.36,23.83],[1,1.35,44.38],[2,1.3,20]],"ltp":0.0,"tv":0.0,"id":60443}]}]}
{"op":"mcm","clk":"11924346557","pt":1724184774837,"mc":[{"id":"1.231893357","rc":[{"batb":[[0,1.51,16.82]],"ltp":0.0,"tv":0.0,"id":169},{"batb":[[0,1.36,23.83],[1,1.35,44.39]],"ltp":0.0,"tv":0.0,"id":60443}]}]}
{"op":"mcm","clk":"11924402234","pt":1724185179909,"mc":[{"id":"1.231893357","rc":[{"batb":[[0,1.5,20],[1,1.09,222.22],[2,1.04,1.53]],"ltp":0.0,"tv":0.0,"id":169},{"batb":[[0,1.35,44.39],[1,1.3,20],[2,1.09,222.22]],"ltp":0.0,"tv":0.0,"id":60443}]}]}
{"op":"mcm","clk":"11924417558","pt":1724185307009,"mc":[{"id":"1.231893357","rc":[{"batb":[[0,1.51,16.82],[1,1.5,20],[2,1.09,222.22]],"ltp":0.0,"tv":0.0,"id":169},{"batb":[[0,1.36,23.83],[1,1.35,44.39],[2,1.3,20]],"ltp":0.0,"tv":0.0,"id":60443}]}]}
{"op":"mcm","clk":"11924563120","pt":1724187108616,"mc":[{"id":"1.231893357","rc":[{"batb":[[0,1.5,20],[1,1.09,222.22],[2,1.04,1.53]],"ltp":0.0,"tv":0.0,"id":169},{"batb":[[0,1.35,44.39],[1,1.3,20],[2,1.09,222.22]],"ltp":0.0,"tv":0.0,"id":60443}]}]}
{"op":"mcm","clk":"11924565268","pt":1724187166685,"mc":[{"id":"1.231893357","rc":[{"batb":[[0,1.51,16.82],[1,1.5,20],[2,1.09,222.22]],"ltp":0.0,"tv":0.0,"id":169},{"batb":[[0,1.36,23.83],[1,1.35,44.39],[2,1.3,20]],"ltp":0.0,"tv":0.0,"id":60443}]}]}
{"op":"mcm","clk":"11924635051","pt":1724188968537,"mc":[{"id":"1.231893357","rc":[{"batb":[[0,1.5,20],[1,1.09,222.22],[2,1.04,1.53]],"ltp":0.0,"tv":0.0,"id":169},{"batb":[[0,1.35,44.4],[1,1.3,20],[2,1.09,222.22]],"ltp":0.0,"tv":0.0,"id":60443}]}]}
{"op":"mcm","clk":"11924638221","pt":1724189058137,"mc":[{"id":"1.231893357","rc":[{"batb":[[0,1.51,16.83],[1,1.5,20],[2,1.09,222.22]],"ltp":0.0,"tv":0.0,"id":169},{"batb":[[0,1.36,23.84],[1,1.35,44.4],[2,1.3,20]],"ltp":0.0,"tv":0.0,"id":60443}]}]}
{"op":"mcm","clk":"11924700252","pt":1724190230948,"mc":[{"id":"1.231893357","rc":[{"trd":[[2.54,0.07]],"batl":[[0,1.7,3.93],[1,85,1.17],[2,95,5.85]],"ltp":2.54,"tv":0.07,"id":60443},{"trd":[[1.7,1.89]],"batl":[[0,85,1.62]],"ltp":1.7,"tv":4.17,"id":31375}],"tv":4.24}]}
{"op":"mcm","clk":"11924700459","pt":1724190236331,"mc":[{"id":"1.231893357","rc":[{"batl":[[1,90,1.02],[2,95,5]],"ltp":2.54,"tv":0.07,"id":60443}]}]}
{"op":"mcm","clk":"11924730149","pt":1724190860029,"mc":[{"id":"1.231893357","rc":[{"batb":[[0,1.35,44.4],[1,1.3,20],[2,1.09,222.22]],"ltp":2.54,"tv":0.07,"id":60443}]}]}
{"op":"mcm","clk":"11924730156","pt":1724190860235,"mc":[{"id":"1.231893357","rc":[{"batb":[[0,1.5,20],[1,1.09,222.22],[2,1.04,1.53]],"ltp":0.0,"tv":0.0,"id":169}]}]}
{"op":"mcm","clk":"11924732412","pt":1724190910484,"mc":[{"id":"1.231893357","rc":[{"batb":[[0,2.78,4.82],[1,1.5,20],[2,1.09,222.22]],"ltp":0.0,"tv":0.0,"id":169},{"batb":[[0,1.36,23.84],[1,1.35,44.4],[2,1.3,20]],"ltp":2.54,"tv":0.07,"id":60443}]}]}
{"op":"mcm","clk":"11924833479","pt":1724192711872,"mc":[{"id":"1.231893357","rc":[{"batb":[[0,1.5,20],[1,1.09,222.22],[2,1.04,1.53]],"ltp":0.0,"tv":0.0,"id":169}]}]}
{"op":"mcm","clk":"11924833491","pt":1724192712080,"mc":[{"id":"1.231893357","rc":[{"batb":[[0,1.35,44.4],[1,1.3,20],[2,1.09,222.22]],"ltp":2.54,"tv":0.07,"id":60443}]}]}
{"op":"mcm","clk":"11924835292","pt":1724192749324,"mc":[{"id":"1.231893357","rc":[{"batb":[[0,2.78,4.82],[1,1.5,20],[2,1.09,222.22]],"ltp":0.0,"tv":0.0,"id":169},{"batb":[[0,1.36,23.84],[1,1.35,44.4],[2,1.3,20]],"ltp":2.54,"tv":0.07,"id":60443}]}]}
{"op":"mcm","clk":"11924940367","pt":1724194550927,"mc":[{"id":"1.231893357","rc":[{"batb":[[0,1.5,20],[1,1.09,222.22],[2,1.04,1.53]],"ltp":0.0,"tv":0.0,"id":169}]}]}
{"op":"mcm","clk":"11924940381","pt":1724194551133,"mc":[{"id":"1.231893357","rc":[{"batb":[[0,1.35,44.4],[1,1.3,20],[2,1.09,222.22]],"ltp":2.54,"tv":0.07,"id":60443}]}]}
{"op":"mcm","clk":"11924941381","pt":1724194571497,"mc":[{"id":"1.231893357","rc":[{"batb":[[0,2.78,4.82],[1,1.5,20],[2,1.09,222.22]],"ltp":0.0,"tv":0.0,"id":169},{"batb":[[0,1.36,23.84],[1,1.35,44.4],[2,1.3,20]],"ltp":2.54,"tv":0.07,"id":60443}]}]}
{"op":"mcm","clk":"11924990920","pt":1724195574881,"mc":[{"id":"1.231893357","rc":[{"batb":[[0,1.36,23.84],[1,1.35,44.41]],"ltp":2.54,"tv":0.07,"id":60443}]}]}
{"op":"mcm","clk":"11925040552","pt":1724196371963,"mc":[{"id":"1.231893357","rc":[{"batb":[[0,1.5,20],[1,1.09,222.22],[2,1.04,1.53]],"ltp":0.0,"tv":0.0,"id":169},{"batb":[[0,1.35,44.41],[1,1.3,20],[2,1.09,222.22]],"ltp":2.54,"tv":0.07,"id":60443}]}]}
{"op":"mcm","clk":"11925047596","pt":1724196490153,"mc":[{"id":"1.231893357","rc":[{"batb":[[0,2.78,4.82],[1,1.5,20],[2,1.09,222.22]],"ltp":0.0,"tv":0.0,"id":169},{"batb":[[0,1.36,23.84],[1,1.35,44.41],[2,1.3,20]],"ltp":2.54,"tv":0.07,"id":60443}]}]}
{"op":"mcm","clk":"11925135728","pt":1724198290531,"mc":[{"id":"1.231893357","rc":[{"batb":[[0,1.5,20],[1,1.09,222.22],[2,1.04,1.53]],"ltp":0.0,"tv":0.0,"id":169},{"batb":[[0,1.35,44.41],[1,1.3,20],[2,1.09,222.22]],"ltp":2.54,"tv":0.07,"id":60443}]}]}
{"op":"mcm","clk":"11925140586","pt":1724198386354,"mc":[{"id":"1.231893357","rc":[{"batb":[[0,2.78,4.82],[1,1.5,20],[2,1.09,222.22]],"ltp":0.0,"tv":0.0,"id":169},{"batb":[[0,1.36,23.84],[1,1.35,44.41],[2,1.3,20]],"ltp":2.54,"tv":0.07,"id":60443}]}]}
{"op":"mcm","clk":"11925232492","pt":1724200186785,"mc":[{"id":"1.231893357","rc":[{"batb":[[0,1.5,20],[1,1.09,222.22],[2,1.04,1.53]],"ltp":0.0,"tv":0.0,"id":169},{"batb":[[0,1.35,44.4],[1,1.3,20],[2,1.09,222.22]],"ltp":2.54,"tv":0.07,"id":60443}]}]}
{"op":"mcm","clk":"11925236272","pt":1724200243201,"mc":[{"id":"1.231893357","rc":[{"batb":[[0,2.78,4.82],[1,1.5,20],[2,1.09,222.22]],"ltp":0.0,"tv":0.0,"id":169},{"batb":[[0,1.36,23.84],[1,1.35,44.4],[2,1.3,20]],"ltp":2.54,"tv":0.07,"id":60443}]}]}
{"op":"mcm","clk":"11925377747","pt":1724202044635,"mc":[{"id":"1.231893357","rc":[{"batb":[[0,1.5,20],[1,1.09,222.22],[2,1.04,1.53]],"ltp":0.0,"tv":0.0,"id":169},{"batb":[[0,1.35,44.39],[1,1.3,20],[2,1.09,222.22]],"ltp":2.54,"tv":0.07,"id":60443}]}]}
{"op":"mcm","clk":"11925379880","pt":1724202075437,"mc":[{"id":"1.231893357","rc":[{"batb":[[0,2.78,4.82],[1,1.5,20],[2,1.09,222.22]],"ltp":0.0,"tv":0.0,"id":169},{"batb":[[0,1.36,23.83],[1,1.35,44.39],[2,1.3,20]],"ltp":2.54,"tv":0.07,"id":60443}]}]}
{"op":"mcm","clk":"11925497055","pt":1724203877274,"mc":[{"id":"1.231893357","rc":[{"batb":[[0,1.5,20],[1,1.09,222.22],[2,1.04,1.53]],"ltp":0.0,"tv":0.0,"id":169},{"batb":[[0,1.35,44.39],[1,1.3,20],[2,1.09,222.22]],"ltp":2.54,"tv":0.07,"id":60443}]}]}
{"op":"mcm","clk":"11925497539","pt":1724203885265,"mc":[{"id":"1.231893357","rc":[{"batb":[[0,2.78,4.82],[1,1.5,20],[2,1.09,222.22]],"ltp":0.0,"tv":0.0,"id":169},{"batb":[[0,1.36,23.83],[1,1.35,44.39],[2,1.3,20]],"ltp":2.54,"tv":0.07,"id":60443}]}]}
{"op":"mcm","clk":"11925635011","pt":1724205686728,"mc":[{"id":"1.231893357","rc":[{"batb":[[0,1.5,20],[1,1.09,222.22],[2,1.04,1.53]],"ltp":0.0,"tv":0.0,"id":169},{"batb":[[0,1.35,44.4],[1,1.3,20],[2,1.09,222.22]],"ltp":2.54,"tv":0.07,"id":60443}]}]}
{"op":"mcm","clk":"11925642980","pt":1724205782858,"mc":[{"id":"1.231893357","rc":[{"batb":[[0,2.78,4.82],[1,1.5,20],[2,1.09,222.22]],"ltp":0.0,"tv":0.0,"id":169},{"batb":[[0,1.36,23.84],[1,1.35,44.4],[2,1.3,20]],"ltp":2.54,"tv":0.07,"id":60443}]}]}
{"op":"mcm","clk":"11925760622","pt":1724207584301,"mc":[{"id":"1.231893357","rc":[{"batb":[[0,1.5,20],[1,1.09,222.22],[2,1.04,1.53]],"ltp":0.0,"tv":0.0,"id":169},{"batb":[[0,1.35,44.4],[1,1.3,20],[2,1.09,222.22]],"ltp":2.54,"tv":0.07,"id":60443}]}]}
{"op":"mcm","clk":"11925763379","pt":1724207651679,"mc":[{"id":"1.231893357","rc":[{"batb":[[0,2.78,4.82],[1,1.5,20],[2,1.09,222.22]],"ltp":0.0,"tv":0.0,"id":169},{"batb":[[0,1.36,23.84],[1,1.35,44.4],[2,1.3,20]],"ltp":2.54,"tv":0.07,"id":60443}]}]}
{"op":"mcm","clk":"11925840238","pt":1724209451948,"mc":[{"id":"1.231893357","rc":[{"batb":[[0,1.35,44.4],[1,1.3,20],[2,1.09,222.22]],"ltp":2.54,"tv":0.07,"id":60443}]}]}
{"op":"mcm","clk":"11925840244","pt":1724209452050,"mc":[{"id":"1.231893357","rc":[{"batb":[[0,1.5,20],[1,1.09,222.22],[2,1.04,1.53]],"ltp":0.0,"tv":0.0,"id":169}]}]}
{"op":"mcm","clk":"11925841716","pt":1724209489446,"mc":[{"id":"1.231893357","rc":[{"batb":[[0,2.78,4.82],[1,1.5,20],[2,1.09,222.22]],"ltp":0.0,"tv":0.0,"id":169},{"batb":[[0,1.36,23.83],[1,1.35,44.4],[2,1.3,20]],"ltp":2.54,"tv":0.07,"id":60443}]}]}
{"op":"mcm","clk":"11925906386","pt":1724211289971,"mc":[{"id":"1.231893357","rc":[{"batb":[[0,1.5,20],[1,1.09,222.22],[2,1.04,1.53]],"ltp":0.0,"tv":0.0,"id":169},{"batb":[[0,1.35,44.4],[1,1.3,20],[2,1.09,222.22]],"ltp":2.54,"tv":0.07,"id":60443}]}]}
{"op":"mcm","clk":"11925907095","pt":1724211312491,"mc":[{"id":"1.231893357","rc":[{"batb":[[0,2.78,4.82],[1,1.5,20],[2,1.09,222.22]],"ltp":0.0,"tv":0.0,"id":169},{"batb":[[0,1.36,23.83],[1,1.35,44.4],[2,1.3,20]],"ltp":2.54,"tv":0.07,"id":60443}]}]}
{"op":"mcm","clk":"11925977667","pt":1724213113357,"mc":[{"id":"1.231893357","rc":[{"batb":[[0,1.5,20],[1,1.09,222.22],[2,1.04,1.53]],"ltp":0.0,"tv":0.0,"id":169},{"batb":[[0,1.35,44.39],[1,1.3,20],[2,1.09,222.22]],"ltp":2.54,"tv":0.07,"id":60443}]}]}
{"op":"mcm","clk":"11925978149","pt":1724213126382,"mc":[{"id":"1.231893357","rc":[{"batb":[[0,2.78,4.82],[1,1.5,20],[2,1.09,222.22]],"ltp":0.0,"tv":0.0,"id":169},{"batb":[[0,1.36,23.83],[1,1.35,44.39],[2,1.3,20]],"ltp":2.54,"tv":0.07,"id":60443}]}]}
{"op":"mcm","clk":"11926033148","pt":1724214927861,"mc":[{"id":"1.231893357","rc":[{"batb":[[0,1.5,20],[1,1.09,222.22],[2,1.04,1.53]],"ltp":0.0,"tv":0.0,"id":169},{"batb":[[0,1.35,44.39],[1,1.3,20],[2,1.09,222.22]],"ltp":2.54,"tv":0.07,"id":60443}]}]}
{"op":"mcm","clk":"11926035956","pt":1724215021563,"mc":[{"id":"1.231893357","rc":[{"batb":[[0,2.78,4.82],[1,1.5,20],[2,1.09,222.22]],"ltp":0.0,"tv":0.0,"id":169},{"batb":[[0,1.36,23.83],[1,1.35,44.39],[2,1.3,20]],"ltp":2.54,"tv":0.07,"id":60443}]}]}
{"op":"mcm","clk":"11926112544","pt":1724216822906,"mc":[{"id":"1.231893357","rc":[{"batb":[[0,1.5,20],[1,1.09,222.22],[2,1.04,1.53]],"ltp":0.0,"tv":0.0,"id":169},{"batb":[[0,1.35,44.39],[1,1.3,20],[2,1.09,222.22]],"ltp":2.54,"tv":0.07,"id":60443}]}]}
{"op":"mcm","clk":"11926116599","pt":1724216906921,"mc":[{"id":"1.231893357","rc":[{"batb":[[0,2.78,4.82],[1,1.5,20],[2,1.09,222.22]],"ltp":0.0,"tv":0.0,"id":169},{"batb":[[0,1.36,23.83],[1,1.35,44.39],[2,1.3,20]],"ltp":2.54,"tv":0.07,"id":60443}]}]}
{"op":"mcm","clk":"11926199718","pt":1724218708563,"mc":[{"id":"1.231893357","rc":[{"batb":[[0,1.5,20],[1,1.09,222.22],[2,1.04,1.53]],"ltp":0.0,"tv":0.0,"id":169},{"batb":[[0,1.35,44.39],[1,1.3,20],[2,1.09,222.22]],"ltp":2.54,"tv":0.07,"id":60443}]}]}
{"op":"mcm","clk":"11926202660","pt":1724218785947,"mc":[{"id":"1.231893357","rc":[{"batb":[[0,2.78,4.82],[1,1.5,20],[2,1.09,222.22]],"ltp":0.0,"tv":0.0,"id":169},{"batb":[[0,1.36,23.83],[1,1.35,44.39],[2,1.3,20]],"ltp":2.54,"tv":0.07,"id":60443}]}]}
{"op":"mcm","clk":"11926278250","pt":1724220586981,"mc":[{"id":"1.231893357","rc":[{"batb":[[0,1.5,20],[1,1.09,222.22],[2,1.04,1.53]],"ltp":0.0,"tv":0.0,"id":169},{"batb":[[0,1.36,23.84],[1,1.35,44.4]],"ltp":2.54,"tv":0.07,"id":60443}]}]}
{"op":"mcm","clk":"11926278254","pt":1724220587083,"mc":[{"id":"1.231893357","rc":[{"batb":[[0,1.35,44.4],[1,1.3,20],[2,1.09,222.22]],"ltp":2.54,"tv":0.07,"id":60443}]}]}
{"op":"mcm","clk":"11926281290","pt":1724220660812,"mc":[{"id":"1.231893357","rc":[{"batb":[[0,2.78,4.82],[1,1.5,20],[2,1.09,222.22]],"ltp":0.0,"tv":0.0,"id":169},{"batb":[[0,1.36,23.84],[1,1.35,44.4],[2,1.3,20]],"ltp":2.54,"tv":0.07,"id":60443}]}]}
{"op":"mcm","clk":"11926354419","pt":1724222462010,"mc":[{"id":"1.231893357","rc":[{"batb":[[0,1.5,20],[1,1.09,222.22],[2,1.04,1.53]],"ltp":0.0,"tv":0.0,"id":169}]}]}
{"op":"mcm","clk":"11926354422","pt":1724222462115,"mc":[{"id":"1.231893357","rc":[{"batb":[[0,1.35,44.4],[1,1.3,20],[2,1.09,222.22]],"ltp":2.54,"tv":0.07,"id":60443}]}]}
{"op":"mcm","clk":"11926357262","pt":1724222531637,"mc":[{"id":"1.231893357","rc":[{"batb":[[0,2.78,4.82],[1,1.5,20],[2,1.09,222.22]],"ltp":0.0,"tv":0.0,"id":169},{"batb":[[0,1.36,23.84],[1,1.35,44.4],[2,1.3,20]],"ltp":2.54,"tv":0.07,"id":60443}]}]}
{"op":"mcm","clk":"11926441458","pt":1724224332901,"mc":[{"id":"1.231893357","rc":[{"batb":[[0,1.5,20],[1,1.09,222.22],[2,1.04,1.53]],"ltp":0.0,"tv":0.0,"id":169},{"batb":[[0,1.35,44.41],[1,1.3,20],[2,1.09,222.22]],"ltp":2.54,"tv":0.07,"id":60443}]}]}
{"op":"mcm","clk":"11926444020","pt":1724224399188,"mc":[{"id":"1.231893357","rc":[{"batb":[[0,2.78,4.82],[1,1.5,20],[2,1.09,222.22]],"ltp":0.0,"tv":0.0,"id":169},{"batb":[[0,1.36,23.84],[1,1.35,44.41],[2,1.3,20]],"ltp":2.54,"tv":0.07,"id":60443}]}]}
{"op":"mcm","clk":"11926510793","pt":1724226200905,"mc":[{"id":"1.231893357","rc":[{"batb":[[0,1.5,20],[1,1.09,222.22],[2,1.04,1.53]],"ltp":0.0,"tv":0.0,"id":169},{"batb":[[0,1.35,44.41],[1,1.3,20],[2,1.09,222.22]],"ltp":2.54,"tv":0.07,"id":60443}]}]}
{"op":"mcm","clk":"11926513273","pt":1724226259451,"mc":[{"id":"1.231893357","rc":[{"batb":[[0,2.78,4.82],[1,1.5,20],[2,1.09,222.22]],"ltp":0.0,"tv":0.0,"id":169},{"batb":[[0,1.36,23.84],[1,1.35,44.41],[2,1.3,20]],"ltp":2.54,"tv":0.07,"id":60443}]}]}
{"op":"mcm","clk":"11926596664","pt":1724227974843,"mc":[{"id":"1.231893357","rc":[{"batb":[[0,1.36,23.84],[1,1.35,44.41]],"ltp":2.54,"tv":0.07,"id":60443}]}]}
{"op":"mcm","clk":"11926608234","pt":1724228061264,"mc":[{"id":"1.231893357","rc":[{"batb":[[0,1.5,20],[1,1.09,222.22],[2,1.04,1.53]],"ltp":0.0,"tv":0.0,"id":169},{"batb":[[0,1.35,44.41],[1,1.3,20],[2,1.09,222.22]],"ltp":2.54,"tv":0.07,"id":60443}]}]}
{"op":"mcm","clk":"11926611450","pt":1724228125412,"mc":[{"id":"1.231893357","rc":[{"batb":[[0,2.78,4.82],[1,1.5,20],[2,1.09,222.22]],"ltp":0.0,"tv":0.0,"id":169},{"batb":[[0,1.36,23.84],[1,1.35,44.41],[2,1.3,20]],"ltp":2.54,"tv":0.07,"id":60443}]}]}
{"op":"mcm","clk":"11926703602","pt":1724229927386,"mc":[{"id":"1.231893357","rc":[{"batb":[[0,1.5,20],[1,1.09,222.22],[2,1.04,1.53]],"ltp":0.0,"tv":0.0,"id":169},{"batb":[[0,1.35,44.41],[1,1.3,20],[2,1.09,222.22]],"ltp":2.54,"tv":0.07,"id":60443}]}]}
{"op":"mcm","clk":"11926710218","pt":1724230045968,"mc":[{"id":"1.231893357","rc":[{"batb":[[0,2.78,4.82],[1,1.5,20],[2,1.09,222.22]],"ltp":0.0,"tv":0.0,"id":169},{"batb":[[0,1.36,23.84],[1,1.35,44.41],[2,1.3,20]],"ltp":2.54,"tv":0.07,"id":60443}]}]}
{"op":"mcm","clk":"11926805455","pt":1724231847506,"mc":[{"id":"1.231893357","rc":[{"batb":[[0,1.5,20],[1,1.09,222.22],[2,1.04,1.53]],"ltp":0.0,"tv":0.0,"id":169},{"batb":[[0,1.35,44.43],[1,1.3,20],[2,1.09,222.22]],"ltp":2.54,"tv":0.07,"id":60443}]}]}
{"op":"mcm","clk":"11926808348","pt":1724231893880,"mc":[{"id":"1.231893357","rc":[{"batb":[[0,2.78,4.82],[1,1.5,20],[2,1.09,222.22]],"ltp":0.0,"tv":0.0,"id":169},{"batb":[[0,1.36,23.85],[1,1.35,44.43],[2,1.3,20]],"ltp":2.54,"tv":0.07,"id":60443}]}]}
{"op":"mcm","clk":"11926875559","pt":1724232952401,"mc":[{"id":"1.231893357","rc":[{"batb":[[2,1.04,1.53]],"batl":[[1,180,1.03],[2,870,0.34]],"ltp":0.0,"tv":0.0,"id":169},{"batl":[[2,870,0.51]],"ltp":2.54,"tv":0.07,"id":60443},{"batb":[[1,1.04,1.53],[2,1.03,200]],"batl":[[1,180,1.03],[2,870,0.34]],"ltp":1.7,"tv":4.17,"id":31375}]}]}
{"op":"mcm","clk":"11926876044","pt":1724232959938,"mc":[{"id":"1.231893357","rc":[{"batb":[[2,1.03,283.33]],"ltp":1.7,"tv":4.17,"id":31375}]}]}
{"op":"mcm","clk":"11926876094","pt":1724232960618,"mc":[{"id":"1.231893357","rc":[{"batb":[[2,1.08,31.25]],"ltp":0.0,"tv":0.0,"id":169},{"batb":[[1,1.08,31.25],[2,1.07,35.71]],"ltp":1.7,"tv":4.17,"id":31375}]}]}
{"op":"mcm","clk":"11926876996","pt":1724232972252,"mc":[{"id":"1.231893357","rc":[{"batl":[[1,95,5.85],[2,990,5.51]],"ltp":0.0,"tv":0.0,"id":169},{"batl":[[2,95,5]],"ltp":2.54,"tv":0.07,"id":60443},{"batl":[[1,95,5.85],[2,990,5.51]],"ltp":1.7,"tv":4.17,"id":31375}]}]}
{"op":"mcm","clk":"11926936309","pt":1724233696339,"mc":[{"id":"1.231893357","rc":[{"batb":[[0,1.5,20],[1,1.08,31.25],[2,1.07,35.71]],"ltp":0.0,"tv":0.0,"id":169},{"batb":[[0,1.35,44.43],[1,1.3,20],[2,1.08,31.25]],"ltp":2.54,"tv":0.07,"id":60443}]}]}
{"op":"mcm","clk":"11926939148","pt":1724233739054,"mc":[{"id":"1.231893357","rc":[{"batb":[[0,2.78,4.82],[1,1.5,20],[2,1.08,31.25]],"ltp":0.0,"tv":0.0,"id":169},{"batb":[[0,1.36,23.85],[1,1.35,44.43],[2,1.3,20]],"ltp":2.54,"tv":0.07,"id":60443}]}]}
{"op":"mcm","clk":"11926986872","pt":1724234395877,"mc":[{"id":"1.231893357","rc":[{"batl":[[0,90,1.03],[1,95,5],[2,990,5.51]],"ltp":2.54,"tv":0.07,"id":60443}]}]}
{"op":"mcm","clk":"11926987054","pt":1724234399067,"mc":[{"id":"1.231893357","rc":[{"batl":[[0,85,1.17],[1,95,5.85]],"ltp":2.54,"tv":0.07,"id":60443}]}]}
{"op":"mcm","clk":"11926992012","pt":1724234462784,"mc":[{"id":"1.231893357","rc":[{"batb":[[0,2.78,4.82]],"ltp":0.0,"tv":0.0,"id":169},{"batb":[[0,1.36,23.83],[1,1.35,44.38]],"batl":[[0,1.8,3],[1,85,1.17],[2,95,5.85]],"ltp":2.54,"tv":0.07,"id":60443}],"tv":4.24}]}
{"op":"mcm","clk":"11926992263","pt":1724234465975,"mc":[{"id":"1.231893357","rc":[{"batl":[[1,90,1.02],[2,95,5]],"ltp":2.54,"tv":0.07,"id":60443}]}]}
{"op":"mcm","clk":"11926992884","pt":1724234476376,"mc":[{"id":"1.231893357","rc":[{"batl":[[0,90,1.02],[1,95,5],[2,990,5.51]],"ltp":2.54,"tv":0.07,"id":60443}]}]}
{"op":"mcm","clk":"11926992936","pt":1724234477093,"mc":[{"id":"1.231893357","rc":[{"batl":[[0,85,1.17],[1,95,5.85]],"ltp":2.54,"tv":0.07,"id":60443}]}]}
{"op":"mcm","clk":"11926998044","pt":1724234554967,"mc":[{"id":"1.231893357","rc":[{"batl":[[0,1.8,3],[1,85,1.17],[2,95,5.85]],"ltp":2.54,"tv":0.07,"id":60443}]}]}
{"op":"mcm","clk":"11926998478","pt":1724234560557,"mc":[{"id":"1.231893357","rc":[{"batl":[[1,90,1.02],[2,95,5]],"ltp":2.54,"tv":0.07,"id":60443}]}]}
{"op":"mcm","clk":"11926999332","pt":1724234573967,"mc":[{"id":"1.231893357","rc":[{"batl":[[0,90,1.02],[1,95,5],[2,990,5.51]],"ltp":2.54,"tv":0.07,"id":60443}]}]}
{"op":"mcm","clk":"11926999553","pt":1724234577359,"mc":[{"id":"1.231893357","rc":[{"batl":[[0,85,1.17],[1,95,5.85]],"ltp":2.54,"tv":0.07,"id":60443}]}]}
{"op":"mcm","clk":"11927095814","pt":1724235541129,"mc":[{"id":"1.231893357","rc":[{"batb":[[0,1.5,20],[1,1.08,31.25],[2,1.07,35.71]],"ltp":0.0,"tv":0.0,"id":169},{"batb":[[0,1.35,44.38],[1,1.3,20],[2,1.08,31.25]],"ltp":2.54,"tv":0.07,"id":60443}]}]}
{"op":"mcm","clk":"11927098985","pt":1724235573317,"mc":[{"id":"1.231893357","rc":[{"batb":[[0,1.51,16.82],[1,1.5,20],[2,1.08,31.25]],"ltp":0.0,"tv":0.0,"id":169},{"batb":[[0,1.36,23.83],[1,1.35,44.38],[2,1.3,20]],"ltp":2.54,"tv":0.07,"id":60443}]}]}
{"op":"mcm","clk":"11927275133","pt":1724237376709,"mc":[{"id":"1.231893357","rc":[{"batb":[[0,1.5,20],[1,1.08,31.25],[2,1.07,35.71]],"ltp":0.0,"tv":0.0,"id":169},{"batb":[[0,1.35,44.38],[1,1.3,20],[2,1.08,31.25]],"ltp":2.54,"tv":0.07,"id":60443}]}]}
{"op":"mcm","clk":"11927277496","pt":1724237401129,"mc":[{"id":"1.231893357","rc":[{"batb":[[0,1.51,16.82],[1,1.5,20],[2,1.08,31.25]],"ltp":0.0,"tv":0.0,"id":169},{"batb":[[0,1.36,23.83],[1,1.35,44.38],[2,1.3,20]],"ltp":2.54,"tv":0.07,"id":60443}]}]}
{"op":"mcm","clk":"11927399987","pt":1724238774853,"mc":[{"id":"1.231893357","rc":[{"batb":[[0,1.51,16.81]],"ltp":0.0,"tv":0.0,"id":169},{"batb":[[0,1.36,23.82],[1,1.35,44.35]],"ltp":2.54,"tv":0.07,"id":60443},{"trd":[[1.7,1.89]],"batb":[[0,1.5,19.89]],"ltp":1.7,"tv":4.17,"id":31375}],"tv":4.24}]}
{"op":"mcm","clk":"11927453200","pt":1724239202822,"mc":[{"id":"1.231893357","rc":[{"batb":[[0,1.5,20],[1,1.08,31.25],[2,1.07,35.71]],"ltp":0.0,"tv":0.0,"id":169},{"batb":[[0,1.35,44.35],[1,1.3,20],[2,1.08,31.25]],"ltp":2.54,"tv":0.07,"id":60443}]}]}
{"op":"mcm","clk":"11927456234","pt":1724239232123,"mc":[{"id":"1.231893357","rc":[{"batb":[[0,1.51,16.81],[1,1.5,20],[2,1.08,31.25]],"ltp":0.0,"tv":0.0,"id":169},{"batb":[[0,1.36,23.82],[1,1.35,44.35],[2,1.3,20]],"ltp":2.54,"tv":0.07,"id":60443}]}]}
{"op":"mcm","clk":"11927622889","pt":1724241033147,"mc":[{"id":"1.231893357","rc":[{"batb":[[0,1.5,20],[1,1.08,31.25],[2,1.07,35.71]],"ltp":0.0,"tv":0.0,"id":169},{"batb":[[0,1.35,44.35],[1,1.3,20],[2,1.08,31.25]],"ltp":2.54,"tv":0.07,"id":60443}]}]}
{"op":"mcm","clk":"11927630345","pt":1724241135377,"mc":[{"id":"1.231893357","rc":[{"batb":[[0,1.51,16.81],[1,1.5,20],[2,1.08,31.25]],"ltp":0.0,"tv":0.0,"id":169},{"batb":[[0,1.36,23.82],[1,1.35,44.35],[2,1.3,20]],"ltp":2.54,"tv":0.07,"id":60443}]}]}
{"op":"mcm","clk":"11927758012","pt":1724242936691,"mc":[{"id":"1.231893357","rc":[{"batb":[[0,1.5,20],[1,1.08,31.25],[2,1.07,35.71]],"ltp":0.0,"tv":0.0,"id":169},{"batb":[[0,1.35,44.35],[1,1.3,20],[2,1.08,31.25]],"ltp":2.54,"tv":0.07,"id":60443}]}]}
{"op":"mcm","clk":"11927764094","pt":1724243015998,"mc":[{"id":"1.231893357","rc":[{"batb":[[0,1.51,16.81],[1,1.5,20],[2,1.08,31.25]],"ltp":0.0,"tv":0.0,"id":169},{"batb":[[0,1.36,23.81],[1,1.35,44.35],[2,1.3,20]],"ltp":2.54,"tv":0.07,"id":60443}]}]}
{"op":"mcm","clk":"11927882564","pt":1724244816865,"mc":[{"id":"1.231893357","rc":[{"batb":[[0,1.35,44.35],[1,1.3,20],[2,1.08,31.25]],"ltp":2.54,"tv":0.07,"id":60443}]}]}
{"op":"mcm","clk":"11927882581","pt":1724244817072,"mc":[{"id":"1.231893357","rc":[{"batb":[[0,1.5,20],[1,1.08,31.25],[2,1.07,35.71]],"ltp":0.0,"tv":0.0,"id":169}]}]}
{"op":"mcm","clk":"11927886329","pt":1724244871923,"mc":[{"id":"1.231893357","rc":[{"batb":[[0,1.51,16.81],[1,1.5,20],[2,1.08,31.25]],"ltp":0.0,"tv":0.0,"id":169},{"batb":[[0,1.36,23.81],[1,1.35,44.35],[2,1.3,20]],"ltp":2.54,"tv":0.07,"id":60443}]}]}
{"op":"mcm","clk":"11928010419","pt":1724246673141,"mc":[{"id":"1.231893357","rc":[{"batb":[[0,1.5,20],[1,1.08,31.25],[2,1.07,35.71]],"ltp":0.0,"tv":0.0,"id":169},{"batb":[[0,1.35,44.34],[1,1.3,20],[2,1.08,31.25]],"ltp":2.54,"tv":0.07,"id":60443}],"tv":4.24}]}
{"op":"mcm","clk":"11928013118","pt":1724246715790,"mc":[{"id":"1.231893357","rc":[{"batb":[[0,1.51,16.81],[1,1.5,20],[2,1.08,31.25]],"ltp":0.0,"tv":0.0,"id":169},{"batb":[[0,1.36,23.81],[1,1.35,44.34],[2,1.3,20]],"ltp":2.54,"tv":0.07,"id":60443}]}]}
{"op":"mcm","clk":"11928129701","pt":1724248516924,"mc":[{"id":"1.231893357","rc":[{"batb":[[0,1.35,44.34],[1,1.3,20],[2,1.08,31.25]],"ltp":2.54,"tv":0.07,"id":60443}]}]}
{"op":"mcm","clk":"11928129709","pt":1724248517129,"mc":[{"id":"1.231893357","rc":[{"batb":[[0,1.5,20],[1,1.08,31.25],[2,1.07,35.71]],"ltp":0.0,"tv":0.0,"id":169}]}]}
{"op":"mcm","clk":"11928130988","pt":1724248546639,"mc":[{"id":"1.231893357","rc":[{"batb":[[0,1.51,16.81],[1,1.5,20],[2,1.08,31.25]],"ltp":0.0,"tv":0.0,"id":169},{"batb":[[0,1.36,23.81],[1,1.35,44.34],[2,1.3,20]],"ltp":2.54,"tv":0.07,"id":60443}]}]}
{"op":"mcm","clk":"11928195070","pt":1724249574836,"mc":[{"id":"1.231893357","rc":[{"batb":[[0,1.51,16.78]],"ltp":0.0,"tv":0.0,"id":169},{"batb":[[0,1.36,23.78],[1,1.35,44.3]],"ltp":2.54,"tv":0.07,"id":60443}]}]}
{"op":"mcm","clk":"11928251368","pt":1724250348027,"mc":[{"id":"1.231893357","rc":[{"batb":[[0,1.35,44.3],[1,1.3,20],[2,1.08,31.25]],"ltp":2.54,"tv":0.07,"id":60443}]}]}
{"op":"mcm","clk":"11928251376","pt":1724250348129,"mc":[{"id":"1.231893357","rc":[{"batb":[[0,1.5,20],[1,1.08,31.25],[2,1.07,35.71]],"ltp":0.0,"tv":0.0,"id":169}]}]}
{"op":"mcm","clk":"11928252502","pt":1724250364706,"mc":[{"id":"1.231893357","rc":[{"batb":[[0,1.51,16.78],[1,1.5,20],[2,1.08,31.25]],"ltp":0.0,"tv":0.0,"id":169},{"batb":[[0,1.36,23.78],[1,1.35,44.3],[2,1.3,20]],"ltp":2.54,"tv":0.07,"id":60443}]}]}
{"op":"mcm","clk":"11928355882","pt":1724252166817,"mc":[{"id":"1.231893357","rc":[{"batb":[[0,1.5,20],[1,1.08,31.25],[2,1.07,35.71]],"ltp":0.0,"tv":0.0,"id":169},{"batb":[[0,1.35,44.3],[1,1.3,20],[2,1.08,31.25]],"ltp":2.54,"tv":0.07,"id":60443}]}]}
{"op":"mcm","clk":"11928363361","pt":1724252295869,"mc":[{"id":"1.231893357","rc":[{"batb":[[0,1.51,16.78],[1,1.5,20],[2,1.08,31.25]],"ltp":0.0,"tv":0.0,"id":169},{"batb":[[0,1.36,23.78],[1,1.35,44.3],[2,1.3,20]],"ltp":2.54,"tv":0.07,"id":60443}]}]}
{"op":"mcm","clk":"11928539154","pt":1724254096966,"mc":[{"id":"1.231893357","rc":[{"batb":[[0,1.5,20],[1,1.08,31.25],[2,1.07,35.71]],"ltp":0.0,"tv":0.0,"id":169},{"batb":[[1,1.35,44.3]],"ltp":2.54,"tv":0.07,"id":60443}],"tv":4.24}]}
{"op":"mcm","clk":"11928539172","pt":1724254097158,"mc":[{"id":"1.231893357","rc":[{"batb":[[0,1.35,44.3],[1,1.3,20],[2,1.08,31.25]],"ltp":2.54,"tv":0.07,"id":60443}]}]}
{"op":"mcm","clk":"11928555512","pt":1724254263590,"mc":[{"id":"1.231893357","rc":[{"batb":[[0,1.51,16.79],[1,1.5,20],[2,1.08,31.25]],"ltp":0.0,"tv":0.0,"id":169},{"batb":[[0,1.36,23.78],[1,1.35,44.3],[2,1.3,20]],"ltp":2.54,"tv":0.07,"id":60443}]}]}
{"op":"mcm","clk":"11928789020","pt":1724256066854,"mc":[{"id":"1.231893357","rc":[{"batb":[[0,1.5,20],[1,1.08,31.25],[2,1.07,35.71]],"ltp":0.0,"tv":0.0,"id":169},{"batb":[[0,1.35,44.31],[1,1.3,20],[2,1.08,31.25]],"ltp":2.54,"tv":0.07,"id":60443},{"trd":[[1.7,1.89]],"batb":[[0,1.5,19.89]],"ltp":1.7,"tv":4.17,"id":31375}],"tv":4.24}]}
{"op":"mcm","clk":"11928811186","pt":1724256228138,"mc":[{"id":"1.231893357","rc":[{"batb":[[0,1.51,16.79],[1,1.5,20],[2,1.08,31.25]],"ltp":0.0,"tv":0.0,"id":169},{"batb":[[0,1.36,23.78],[1,1.35,44.31],[2,1.3,20]],"ltp":2.54,"tv":0.07,"id":60443}]}]}
{"op":"mcm","clk":"11929066264","pt":1724258030697,"mc":[{"id":"1.231893357","rc":[{"batb":[[0,1.5,20],[1,1.08,31.25],[2,1.07,35.71]],"ltp":0.0,"tv":0.0,"id":169},{"batb":[[0,1.35,44.31],[1,1.3,20],[2,1.08,31.25]],"ltp":2.54,"tv":0.07,"id":60443}]}]}
{"op":"mcm","clk":"11929089734","pt":1724258173441,"mc":[{"id":"1.231893357","rc":[{"batb":[[0,1.51,16.79],[1,1.5,20],[2,1.08,31.25]],"ltp":0.0,"tv":0.0,"id":169},{"batb":[[0,1.36,23.78],[1,1.35,44.31],[2,1.3,20]],"ltp":2.54,"tv":0.07,"id":60443}]}]}
{"op":"mcm","clk":"11929380468","pt":1724259975248,"mc":[{"id":"1.231893357","rc":[{"batb":[[0,1.5,20],[1,1.08,31.25],[2,1.07,35.71]],"ltp":0.0,"tv":0.0,"id":169},{"batb":[[0,1.35,44.28],[1,1.3,20],[2,1.08,31.25]],"ltp":2.54,"tv":0.07,"id":60443}]}]}
{"op":"mcm","clk":"11929408411","pt":1724260130295,"mc":[{"id":"1.231893357","rc":[{"batb":[[0,1.51,16.78],[1,1.5,20],[2,1.08,31.25]],"ltp":0.0,"tv":0.0,"id":169},{"batb":[[0,1.36,23.77],[1,1.35,44.28],[2,1.3,20]],"ltp":2.54,"tv":0.07,"id":60443}]}]}
{"op":"mcm","clk":"11929715327","pt":1724261933681,"mc":[{"id":"1.231893357","rc":[{"batb":[[0,1.5,20],[1,1.08,31.25],[2,1.07,35.71]],"ltp":0.0,"tv":0.0,"id":169},{"batb":[[0,1.35,44.28],[1,1.3,20],[2,1.08,31.25]],"ltp":2.54,"tv":0.07,"id":60443}]}]}
{"op":"mcm","clk":"11929733944","pt":1724262043424,"mc":[{"id":"1.231893357","rc":[{"batb":[[0,1.51,16.78],[1,1.5,20],[2,1.08,31.25]],"ltp":0.0,"tv":0.0,"id":169},{"batb":[[0,1.36,23.77],[1,1.35,44.28],[2,1.3,20]],"ltp":2.54,"tv":0.07,"id":60443}]}]}
{"op":"mcm","clk":"11930007652","pt":1724263845995,"mc":[{"id":"1.231893357","rc":[{"batb":[[0,1.5,20],[1,1.08,31.25],[2,1.07,35.71]],"ltp":0.0,"tv":0.0,"id":169},{"batb":[[0,1.35,44.29],[1,1.3,20],[2,1.08,31.25]],"ltp":2.54,"tv":0.07,"id":60443}]}]}
{"op":"mcm","clk":"11930017147","pt":1724263899947,"mc":[{"id":"1.231893357","rc":[{"batb":[[0,1.51,16.78],[1,1.5,20],[2,1.08,31.25]],"ltp":0.0,"tv":0.0,"id":169},{"batb":[[0,1.36,23.78],[1,1.35,44.29],[2,1.3,20]],"ltp":2.54,"tv":0.07,"id":60443}]}]}
{"op":"mcm","clk":"11930327406","pt":1724265702564,"mc":[{"id":"1.231893357","rc":[{"batb":[[0,1.5,20],[1,1.08,31.25],[2,1.07,35.71]],"ltp":0.0,"tv":0.0,"id":169},{"batb":[[0,1.35,44.29],[1,1.3,20],[2,1.08,31.25]],"ltp":2.54,"tv":0.07,"id":60443}]}]}
{"op":"mcm","clk":"11930331407","pt":1724265727115,"mc":[{"id":"1.231893357","rc":[{"batb":[[0,1.51,16.78],[1,1.5,20],[2,1.08,31.25]],"ltp":0.0,"tv":0.0,"id":169},{"batb":[[0,1.36,23.78],[1,1.35,44.29],[2,1.3,20]],"ltp":2.54,"tv":0.07,"id":60443}]}]}
{"op":"mcm","clk":"11930585953","pt":1724267529750,"mc":[{"id":"1.231893357","rc":[{"batb":[[0,1.5,20],[1,1.08,31.25],[2,1.07,35.71]],"ltp":0.0,"tv":0.0,"id":169},{"batb":[[0,1.35,44.28],[1,1.3,20],[2,1.08,31.25]],"ltp":2.54,"tv":0.07,"id":60443}]}]}
{"op":"mcm","clk":"11930608152","pt":1724267697318,"mc":[{"id":"1.231893357","rc":[{"batb":[[0,1.51,16.78],[1,1.5,20],[2,1.08,31.25]],"ltp":0.0,"tv":0.0,"id":169},{"batb":[[0,1.36,23.77],[1,1.35,44.28],[2,1.3,20]],"ltp":2.54,"tv":0.07,"id":60443}]}]}
{"op":"mcm","clk":"11930824438","pt":1724269499921,"mc":[{"id":"1.231893357","rc":[{"batb":[[0,1.35,44.28],[1,1.3,20],[2,1.08,31.25]],"ltp":2.54,"tv":0.07,"id":60443}]}]}
{"op":"mcm","clk":"11930824460","pt":1724269500127,"mc":[{"id":"1.231893357","rc":[{"batb":[[0,1.5,20],[1,1.08,31.25],[2,1.07,35.71]],"ltp":0.0,"tv":0.0,"id":169}]}]}
{"op":"mcm","clk":"11930837965","pt":1724269624853,"mc":[{"id":"1.231893357","rc":[{"batb":[[0,1.51,16.78],[1,1.5,20],[2,1.08,31.25]],"ltp":0.0,"tv":0.0,"id":169},{"batb":[[0,1.36,23.77],[1,1.35,44.28],[2,1.3,20]],"ltp":2.54,"tv":0.07,"id":60443}]}]}
{"op":"mcm","clk":"11930996875","pt":1724271174838,"mc":[{"id":"1.231893357","rc":[{"batb":[[0,1.51,16.79]],"ltp":0.0,"tv":0.0,"id":169},{"batb":[[0,1.36,23.78],[1,1.35,44.3]],"ltp":2.54,"tv":0.07,"id":60443}],"tv":4.24}]}
{"op":"mcm","clk":"11931028294","pt":1724271426558,"mc":[{"id":"1.231893357","rc":[{"batb":[[0,1.5,20],[1,1.08,31.25],[2,1.07,35.71]],"ltp":0.0,"tv":0.0,"id":169},{"batb":[[0,1.35,44.3],[1,1.3,20],[2,1.08,31.25]],"ltp":2.54,"tv":0.07,"id":60443}]}]}
{"op":"mcm","clk":"11931040287","pt":1724271549285,"mc":[{"id":"1.231893357","rc":[{"batb":[[0,1.51,16.79],[1,1.5,20],[2,1.08,31.25]],"ltp":0.0,"tv":0.0,"id":169},{"batb":[[0,1.36,23.78],[1,1.35,44.3],[2,1.3,20]],"ltp":2.54,"tv":0.07,"id":60443}]}]}
{"op":"mcm","clk":"11931113507","pt":1724272369720,"mc":[{"id":"1.231893357","rc":[{"batb":[[0,1.8,62.5],[1,1.5,19.89],[2,1.08,31.25]],"ltp":1.7,"tv":4.17,"id":31375}]}]}
{"op":"mcm","clk":"11931115714","pt":1724272396055,"mc":[{"id":"1.231893357","rc":[{"batb":[[0,1.7,71.43],[1,1.51,16.79],[2,1.5,20]],"ltp":0.0,"tv":0.0,"id":169}]}]}
{"op":"mcm","clk":"11931198687","pt":1724273350966,"mc":[{"id":"1.231893357","rc":[{"batb":[[1,1.5,20],[2,1.08,31.25]],"ltp":0.0,"tv":0.0,"id":169},{"batb":[[0,1.35,44.3],[1,1.3,20],[2,1.08,31.25]],"ltp":2.54,"tv":0.07,"id":60443}]}]}
{"op":"mcm","clk":"11931202861","pt":1724273409523,"mc":[{"id":"1.231893357","rc":[{"batb":[[0,1.71,12.06],[1,1.7,71.43],[2,1.5,20]],"ltp":0.0,"tv":0.0,"id":169},{"batb":[[0,1.36,23.78],[1,1.35,44.3],[2,1.3,20]],"ltp":2.54,"tv":0.07,"id":60443}]}]}
{"op":"mcm","clk":"11931345484","pt":1724275211553,"mc":[{"id":"1.231893357","rc":[{"batb":[[0,1.7,71.43],[1,1.5,20],[2,1.08,31.25]],"ltp":0.0,"tv":0.0,"id":169},{"batb":[[0,1.35,44.29],[1,1.3,20],[2,1.08,31.25]],"ltp":2.54,"tv":0.07,"id":60443}]}]}
{"op":"mcm","clk":"11931346869","pt":1724275228860,"mc":[{"id":"1.231893357","rc":[{"batb":[[0,1.71,12.05],[1,1.7,71.43],[2,1.5,20]],"ltp":0.0,"tv":0.0,"id":169},{"batb":[[0,1.36,23.78],[1,1.35,44.29],[2,1.3,20]],"ltp":2.54,"tv":0.07,"id":60443}]}]}
{"op":"mcm","clk":"11931382161","pt":1724275687630,"mc":[{"id":"1.231893357","rc":[{"trd":[[1.71,2]],"batb":[[0,1.71,11.06]],"ltp":1.71,"tv":1.99,"id":169}],"tv":6.24}]}
{"op":"mcm","clk":"11931419258","pt":1724276227910,"mc":[{"id":"1.231893357","rc":[{"batb":[[1,1.35,64.29],[2,1.08,31.25]],"ltp":2.54,"tv":0.07,"id":60443}]}]}
{"op":"mcm","clk":"11931489719","pt":1724277030494,"mc":[{"id":"1.231893357","rc":[{"batb":[[0,1.7,71.43],[1,1.5,20],[2,1.08,31.25]],"ltp":1.71,"tv":1.99,"id":169},{"batb":[[0,1.35,64.29],[1,1.08,31.25],[2,1.07,35.71]],"ltp":2.54,"tv":0.07,"id":60443}]}]}
{"op":"mcm","clk":"11931502504","pt":1724277205378,"mc":[{"id":"1.231893357","rc":[{"batb":[[0,1.36,23.78],[1,1.35,64.29],[2,1.08,31.25]],"ltp":2.54,"tv":0.07,"id":60443}]}]}
{"op":"mcm","clk":"11931619306","pt":1724279006335,"mc":[{"id":"1.231893357","rc":[{"batb":[[0,1.35,64.28],[1,1.08,31.25],[2,1.07,35.71]],"ltp":2.54,"tv":0.07,"id":60443}]}]}
{"op":"mcm","clk":"11931626816","pt":1724279142486,"mc":[{"id":"1.231893357","rc":[{"batb":[[0,1.36,23.77],[1,1.35,64.28],[2,1.08,31.25]],"ltp":2.54,"tv":0.07,"id":60443}]}]}
{"op":"mcm","clk":"11931633766","pt":1724279276598,"mc":[{"id":"1.231893357","rc":[{"batb":[[0,2.1,166],[1,1.8,62.5],[2,1.5,19.89]],"ltp":1.7,"tv":4.17,"id":31375}]}]}
{"op":"mcm","clk":"11931714459","pt":1724280567886,"mc":[{"id":"1.231893357","rc":[{"batb":[[0,2.12,6],[1,2.1,166],[2,1.8,62.5]],"ltp":1.7,"tv":4.17,"id":31375}]}]}
{"op":"mcm","clk":"11931736904","pt":1724280940496,"mc":[{"id":"1.231893357","rc":[{"batb":[[1,1.8,62.5],[2,1.5,19.89]],"ltp":1.7,"tv":4.17,"id":31375}]}]}
{"op":"mcm","clk":"11931737160","pt":1724280944856,"mc":[{"id":"1.231893357","rc":[{"batb":[[0,1.35,64.28],[1,1.08,31.25],[2,1.07,35.71]],"ltp":2.54,"tv":0.07,"id":60443}]}]}
{"op":"mcm","clk":"11931743827","pt":1724281059612,"mc":[{"id":"1.231893357","rc":[{"batb":[[0,1.36,23.77],[1,1.35,64.28],[2,1.08,31.25]],"ltp":2.54,"tv":0.07,"id":60443}]}]}
{"op":"mcm","clk":"11931811826","pt":1724281974889,"mc":[{"id":"1.231893357","rc":[{"batb":[[0,1.36,23.79],[1,1.35,64.31]],"ltp":2.54,"tv":0.07,"id":60443}]}]}
{"op":"mcm","clk":"11931863448","pt":1724282486602,"mc":[{"id":"1.231893357","rc":[{"batb":[[0,1.81,6]],"ltp":1.7,"tv":4.17,"id":31375}]}]}
{"op":"mcm","clk":"11931893551","pt":1724282859907,"mc":[{"id":"1.231893357","rc":[{"batb":[[0,1.35,64.31],[1,1.08,31.25],[2,1.07,35.71]],"ltp":2.54,"tv":0.07,"id":60443}]}]}
{"op":"mcm","clk":"11931901461","pt":1724282953016,"mc":[{"id":"1.231893357","rc":[{"batb":[[0,1.36,23.79],[1,1.35,64.31],[2,1.08,31.25]],"ltp":2.54,"tv":0.07,"id":60443}]}]}
{"op":"mcm","clk":"11932012291","pt":1724284243887,"mc":[{"id":"1.231893357","rc":[{"batb":[[0,1.8,62.5],[1,1.5,19.89],[2,1.08,31.25]],"ltp":1.7,"tv":4.17,"id":31375}]}]}
{"op":"mcm","clk":"11932051914","pt":1724284755199,"mc":[{"id":"1.231893357","rc":[{"batb":[[0,1.35,64.31],[1,1.08,31.25],[2,1.07,35.71]],"ltp":2.54,"tv":0.07,"id":60443}]}]}
{"op":"mcm","clk":"11932057348","pt":1724284828588,"mc":[{"id":"1.231893357","rc":[{"batb":[[0,1.36,23.79],[1,1.35,64.3],[2,1.08,31.25]],"ltp":2.54,"tv":0.07,"id":60443}]}]}
{"op":"mcm","clk":"11932195679","pt":1724286629938,"mc":[{"id":"1.231893357","rc":[{"batb":[[0,1.35,64.3],[1,1.08,31.25],[2,1.07,35.71]],"ltp":2.54,"tv":0.07,"id":60443}]}]}
{"op":"mcm","clk":"11932199365","pt":1724286679484,"mc":[{"id":"1.231893357","rc":[{"batb":[[0,1.36,23.79],[1,1.35,64.3],[2,1.08,31.25]],"ltp":2.54,"tv":0.07,"id":60443}]}]}
{"op":"mcm","clk":"11932354471","pt":1724288481352,"mc":[{"id":"1.231893357","rc":[{"batb":[[0,1.35,64.28],[1,1.08,31.25],[2,1.07,35.71]],"ltp":2.54,"tv":0.07,"id":60443}]}]}
{"op":"mcm","clk":"11932356538","pt":1724288512382,"mc":[{"id":"1.231893357","rc":[{"batb":[[0,1.36,23.77],[1,1.35,64.28],[2,1.08,31.25]],"ltp":2.54,"tv":0.07,"id":60443}]}]}
{"op":"mcm","clk":"11932477412","pt":1724290314760,"mc":[{"id":"1.231893357","rc":[{"batb":[[0,1.35,64.28],[1,1.08,31.25],[2,1.07,35.71]],"ltp":2.54,"tv":0.07,"id":60443}]}]}
{"op":"mcm","clk":"11932477928","pt":1724290323695,"mc":[{"id":"1.231893357","rc":[{"batb":[[0,1.36,23.77],[1,1.35,64.28],[2,1.08,31.25]],"ltp":2.54,"tv":0.07,"id":60443}]}]}
{"op":"mcm","clk":"11932587955","pt":1724292125097,"mc":[{"id":"1.231893357","rc":[{"batb":[[0,1.35,64.28],[1,1.08,31.25],[2,1.07,35.71]],"ltp":2.54,"tv":0.07,"id":60443}]}]}
{"op":"mcm","clk":"11932597974","pt":1724292281701,"mc":[{"id":"1.231893357","rc":[{"batb":[[0,1.36,23.77],[1,1.35,64.28],[2,1.08,31.25]],"ltp":2.54,"tv":0.07,"id":60443}]}]}
{"op":"mcm","clk":"11932715241","pt":1724294083262,"mc":[{"id":"1.231893357","rc":[{"batb":[[0,1.35,64.28],[1,1.08,31.25],[2,1.07,35.71]],"ltp":2.54,"tv":0.07,"id":60443}]}]}
{"op":"mcm","clk":"11932721060","pt":1724294216362,"mc":[{"id":"1.231893357","rc":[{"batb":[[0,1.36,23.77],[1,1.35,64.28],[2,1.08,31.25]],"ltp":2.54,"tv":0.07,"id":60443}]}]}
{"op":"mcm","clk":"11932812187","pt":1724296016597,"mc":[{"id":"1.231893357","rc":[{"batb":[[0,1.35,64.28],[1,1.08,31.25],[2,1.07,35.71]],"ltp":2.54,"tv":0.07,"id":60443}]}]}
{"op":"mcm","clk":"11932817052","pt":1724296126472,"mc":[{"id":"1.231893357","rc":[{"batb":[[0,1.36,23.77],[1,1.35,64.28],[2,1.08,31.25]],"ltp":2.54,"tv":0.07,"id":60443}]}]}
{"op":"mcm","clk":"11932911111","pt":1724297927867,"mc":[{"id":"1.231893357","rc":[{"batb":[[0,1.35,64.28],[1,1.08,31.25],[2,1.07,35.71]],"ltp":2.54,"tv":0.07,"id":60443}]}]}
{"op":"mcm","clk":"11932916706","pt":1724298024972,"mc":[{"id":"1.231893357","rc":[{"batb":[[0,1.36,23.77],[1,1.35,64.28],[2,1.08,31.25]],"ltp":2.54,"tv":0.07,"id":60443}]}]}
{"op":"mcm","clk":"11933023272","pt":1724299827399,"mc":[{"id":"1.231893357","rc":[{"batb":[[0,1.35,64.29],[1,1.08,31.25],[2,1.07,35.71]],"ltp":2.54,"tv":0.07,"id":60443}]}]}
{"op":"mcm","clk":"11933028527","pt":1724299913057,"mc":[{"id":"1.231893357","rc":[{"batb":[[0,1.36,23.77],[1,1.35,64.29],[2,1.08,31.25]],"ltp":2.54,"tv":0.07,"id":60443}]}]}
{"op":"mcm","clk":"11933119875","pt":1724301714338,"mc":[{"id":"1.231893357","rc":[{"batb":[[0,1.35,64.29],[1,1.08,31.25],[2,1.07,35.71]],"ltp":2.54,"tv":0.07,"id":60443}]}]}
{"op":"mcm","clk":"11933123712","pt":1724301788017,"mc":[{"id":"1.231893357","rc":[{"batb":[[0,1.36,23.77],[1,1.35,64.29],[2,1.08,31.25]],"ltp":2.54,"tv":0.07,"id":60443}]}]}
{"op":"mcm","clk":"11933228066","pt":1724303574846,"mc":[{"id":"1.231893357","rc":[{"batb":[[0,1.36,23.77],[1,1.35,64.29]],"ltp":2.54,"tv":0.07,"id":60443}]}]}
{"op":"mcm","clk":"11933236150","pt":1724303589538,"mc":[{"id":"1.231893357","rc":[{"batb":[[0,1.35,64.29],[1,1.08,31.25],[2,1.07,35.71]],"ltp":2.54,"tv":0.07,"id":60443}]}]}
{"op":"mcm","clk":"11933238988","pt":1724303664359,"mc":[{"id":"1.231893357","rc":[{"batb":[[0,1.36,23.77],[1,1.35,64.29],[2,1.08,31.25]],"ltp":2.54,"tv":0.07,"id":60443}]}]}
{"op":"mcm","clk":"11933329874","pt":1724305465386,"mc":[{"id":"1.231893357","rc":[{"batb":[[0,1.35,64.29],[1,1.08,31.25],[2,1.07,35.71]],"ltp":2.54,"tv":0.07,"id":60443}]}]}
{"op":"mcm","clk":"11933335997","pt":1724305607735,"mc":[{"id":"1.231893357","rc":[{"batb":[[0,1.36,23.77],[1,1.35,64.29],[2,1.08,31.25]],"ltp":2.54,"tv":0.07,"id":60443}]}]}
{"op":"mcm","clk":"11933416623","pt":1724307408029,"mc":[{"id":"1.231893357","rc":[{"batb":[[0,1.35,64.29],[1,1.08,31.25],[2,1.07,35.71]],"ltp":2.54,"tv":0.07,"id":60443}]}]}
{"op":"mcm","clk":"11933420652","pt":1724307536176,"mc":[{"id":"1.231893357","rc":[{"batb":[[0,1.36,23.77],[1,1.35,64.29],[2,1.08,31.25]],"ltp":2.54,"tv":0.07,"id":60443}]}]}
{"op":"mcm","clk":"11933448537","pt":1724308230631,"mc":[{"id":"1.231893357","rc":[{"batl":[[0,85,1.55]],"ltp":2.54,"tv":0.07,"id":60443}]}]}
{"op":"mcm","clk":"11933448886","pt":1724308238736,"mc":[{"id":"1.231893357","rc":[{"batl":[[0,85,1.71]],"ltp":1.71,"tv":1.99,"id":169}]}]}
{"op":"mcm","clk":"11933449194","pt":1724308245275,"mc":[{"id":"1.231893357","rc":[{"batl":[[0,48,1.15],[1,85,1],[2,95,5.85]],"ltp":1.7,"tv":4.17,"id":31375}]}]}
{"op":"mcm","clk":"11933449291","pt":1724308247166,"mc":[{"id":"1.231893357","rc":[{"batl":[[1,95,5.85],[2,990,5.51]],"ltp":1.7,"tv":4.17,"id":31375}]}]}
{"op":"mcm","clk":"11933449580","pt":1724308252699,"mc":[{"id":"1.231893357","rc":[{"batl":[[0,46,1.98],[1,90,1.02],[2,95,5]],"ltp":1.7,"tv":4.17,"id":31375}]}]}
{"op":"mcm","clk":"11933449796","pt":1724308257099,"mc":[{"id":"1.231893357","rc":[{"batb":[[0,1.82,3.06],[1,1.8,62.5],[2,1.5,19.89]],"ltp":1.7,"tv":4.17,"id":31375}]}]}
{"op":"mcm","clk":"11933450049","pt":1724308261711,"mc":[{"id":"1.231893357","rc":[{"batb":[[0,1.72,3.06],[1,1.7,71.43],[2,1.5,20]],"ltp":1.71,"tv":1.99,"id":169}]}]}
{"op":"mcm","clk":"11933450474","pt":1724308270316,"mc":[{"id":"1.231893357","rc":[{"batb":[[0,1.4,3.82],[1,1.36,23.77],[2,1.35,64.29]],"ltp":2.54,"tv":0.07,"id":60443}]}]}
{"op":"mcm","clk":"11933499986","pt":1724309179848,"mc":[{"id":"1.231893357","rc":[{"batl":[[0,38,1.32],[1,85,1.17],[2,95,5.85]],"ltp":2.54,"tv":0.07,"id":60443}]}]}
{"op":"mcm","clk":"11933500077","pt":1724309182573,"mc":[{"id":"1.231893357","rc":[{"batl":[[1,90,1.02],[2,95,5]],"ltp":2.54,"tv":0.07,"id":60443}]}]}
{"op":"mcm","clk":"11933500288","pt":1724309188107,"mc":[{"id":"1.231893357","rc":[{"batl":[[0,36,1.93],[1,90,1.4]],"ltp":2.54,"tv":0.07,"id":60443}]}]}
{"op":"mcm","clk":"11933505852","pt":1724309337901,"mc":[{"id":"1.231893357","rc":[{"batb":[[1,1.35,64.29],[2,1.08,31.25]],"ltp":2.54,"tv":0.07,"id":60443}]}]}
{"op":"mcm","clk":"11933510164","pt":1724309463671,"mc":[{"id":"1.231893357","rc":[{"batb":[[0,1.41,20.87],[1,1.4,3.82],[2,1.35,64.29]],"ltp":2.54,"tv":0.07,"id":60443}]}]}
{"op":"mcm","clk":"11933570533","pt":1724311266058,"mc":[{"id":"1.231893357","rc":[{"batb":[[0,1.72,3.06]],"ltp":1.71,"tv":1.99,"id":169},{"batb":[[0,1.4,3.82],[1,1.35,64.28],[2,1.08,31.25]],"ltp":2.54,"tv":0.07,"id":60443},{"batb":[[0,1.82,3.06]],"ltp":1.7,"tv":4.17,"id":31375}]}]}
{"op":"mcm","clk":"11933574787","pt":1724311387408,"mc":[{"id":"1.231893357","rc":[{"batb":[[0,1.41,20.87],[1,1.4,3.82],[2,1.35,64.28]],"ltp":2.54,"tv":0.07,"id":60443}]}]}
{"op":"mcm","clk":"11933634093","pt":1724313189164,"mc":[{"id":"1.231893357","rc":[{"batb":[[0,1.4,3.82],[1,1.35,64.28],[2,1.08,31.25]],"ltp":2.54,"tv":0.07,"id":60443}]}]}
{"op":"mcm","clk":"11933638749","pt":1724313313642,"mc":[{"id":"1.231893357","rc":[{"batb":[[0,1.41,20.87],[1,1.4,3.82],[2,1.35,64.28]],"ltp":2.54,"tv":0.07,"id":60443}]}]}
{"op":"mcm","clk":"11933677706","pt":1724314374839,"mc":[{"id":"1.231893357","rc":[{"trd":[[1.71,2]],"batb":[[0,1.72,3.05]],"batl":[[1,95,5.85]],"ltp":1.71,"tv":1.99,"id":169},{"batb":[[0,1.41,20.84],[1,1.4,3.82],[2,1.35,64.22]],"batl":[[1,90,1.4]],"ltp":2.54,"tv":0.07,"id":60443},{"batb":[[0,1.82,3.05]],"batl":[[1,90,1.02]],"ltp":1.7,"tv":4.17,"id":31375}],"tv":6.23}]}
{"op":"mcm","clk":"11933704699","pt":1724314862503,"mc":[{"id":"1.231893357","rc":[{"batl":[[0,26,1.32],[1,36,1],[2,90,1.02]],"ltp":2.54,"tv":0.07,"id":60443}]}]}
{"op":"mcm","clk":"11933705145","pt":1724314873012,"mc":[{"id":"1.231893357","rc":[{"batl":[[1,90,1.02],[2,95,5]],"ltp":2.54,"tv":0.07,"id":60443}]}]}
{"op":"mcm","clk":"11933705148","pt":1724314873116,"mc":[{"id":"1.231893357","rc":[{"batl":[[0,16,1.47],[1,90,1.4]],"ltp":2.54,"tv":0.07,"id":60443}]}]}
{"op":"mcm","clk":"11933705373","pt":1724314878508,"mc":[{"id":"1.231893357","rc":[{"batl":[[0,15.5,1.53],[1,26,1.32],[2,90,1.02]],"ltp":2.54,"tv":0.07,"id":60443}]}]}
{"op":"mcm","clk":"11933714759","pt":1724315131911,"mc":[{"id":"1.231893357","rc":[{"batb":[[0,1.4,3.82],[1,1.35,64.22],[2,1.08,31.25]],"ltp":2.54,"tv":0.07,"id":60443}]}]}
{"op":"mcm","clk":"11933718506","pt":1724315241932,"mc":[{"id":"1.231893357","rc":[{"batb":[[0,1.41,20.84],[1,1.4,3.82],[2,1.35,64.22]],"ltp":2.54,"tv":0.07,"id":60443}]}]}
{"op":"mcm","clk":"11933786864","pt":1724317042139,"mc":[{"id":"1.231893357","rc":[{"batb":[[0,1.4,3.82],[1,1.35,64.22],[2,1.08,31.25]],"ltp":2.54,"tv":0.07,"id":60443}]}]}
{"op":"mcm","clk":"11933791457","pt":1724317168411,"mc":[{"id":"1.231893357","rc":[{"batb":[[0,1.41,20.84],[1,1.4,3.82],[2,1.35,64.22]],"ltp":2.54,"tv":0.07,"id":60443}]}]}
{"op":"mcm","clk":"11933791923","pt":1724317182323,"mc":[{"id":"1.231893357","rc":[{"batb":[[0,1.42,3.82],[1,1.41,20.84]],"ltp":2.54,"tv":0.07,"id":60443}]}]}
{"op":"mcm","clk":"11933794993","pt":1724317258023,"mc":[{"id":"1.231893357","rc":[{"batb":[[0,1.72,3.05]],"batl":[[0,80,1],[1,85,1],[2,95,5.85]],"ltp":1.71,"tv":1.99,"id":169},{"batb":[[0,1.42,3.81],[1,1.41,20.83],[2,1.35,64.18]],"batl":[[1,26,1.31]],"ltp":2.54,"tv":0.07,"id":60443},{"trd":[[1.7,1.89]],"batb":[[0,1.82,3.05],[2,1.5,19.89]],"batl":[[0,44,1.28],[1,46,1],[2,90,1.02]],"ltp":1.7,"tv":4.16,"id":31375}],"tv":6.23}]}
{"op":"mcm","clk":"11933795024","pt":1724317258334,"mc":[{"id":"1.231893357","rc":[{"batb":[[0,1.72,3.35]],"ltp":1.71,"tv":1.99,"id":169},{"batb":[[0,1.42,4.11]],"batl":[[0,15.5,1.83]],"ltp":2.54,"tv":0.07,"id":60443},{"batb":[[0,1.82,3.35]],"ltp":1.7,"tv":4.16,"id":31375}]}]}
{"op":"mcm","clk":"11933795181","pt":1724317262104,"mc":[{"id":"1.231893357","rc":[{"batl":[[1,95,5.85],[2,990,5.51]],"ltp":1.71,"tv":1.99,"id":169},{"batl":[[1,90,1.02],[2,95,5]],"ltp":1.7,"tv":4.16,"id":31375}]}]}
{"op":"mcm","clk":"11933795362","pt":1724317267713,"mc":[{"id":"1.231893357","rc":[{"batl":[[0,75,1.7],[1,90,1.15],[2,95,5]],"ltp":1.71,"tv":1.99,"id":169},{"batl":[[0,42,1.98],[1,90,1.32]],"ltp":1.7,"tv":4.16,"id":31375}]}]}
{"op":"mcm","clk":"11933808073","pt":1724317566836,"mc":[{"id":"1.231893357","rc":[{"batl":[[0,70,1],[1,75,1],[2,90,1.15]],"ltp":1.71,"tv":1.99,"id":169},{"batl":[[0,40,1.28],[1,42,1],[2,90,1.32]],"ltp":1.7,"tv":4.16,"id":31375}]}]}
{"op":"mcm","clk":"11933808115","pt":1724317567305,"mc":[{"id":"1.231893357","rc":[{"batb":[[0,1.72,3.65]],"ltp":1.71,"tv":1.99,"id":169},{"batb":[[0,1.42,4.41]],"batl":[[0,15,1.13],[1,15.5,1],[2,26,1.31]],"ltp":2.54,"tv":0.07,"id":60443},{"batb":[[0,1.82,3.65]],"ltp":1.7,"tv":4.16,"id":31375}]}]}
{"op":"mcm","clk":"11933808175","pt":1724317568537,"mc":[{"id":"1.231893357","rc":[{"batl":[[1,90,1.15],[2,95,5]],"ltp":1.71,"tv":1.99,"id":169},{"batl":[[1,26,1.31],[2,90,1.02]],"ltp":2.54,"tv":0.07,"id":60443},{"batl":[[1,90,1.32],[2,95,5]],"ltp":1.7,"tv":4.16,"id":31375}]}]}
{"op":"mcm","clk":"11933808220","pt":1724317569622,"mc":[{"id":"1.231893357","rc":[{"batb":[[0,1.72,3.35]],"ltp":1.71,"tv":1.99,"id":169},{"batb":[[0,1.42,4.11]],"ltp":2.54,"tv":0.07,"id":60443},{"batb":[[0,1.82,3.35]],"ltp":1.7,"tv":4.16,"id":31375}]}]}
{"op":"mcm","clk":"11933808263","pt":1724317570647,"mc":[{"id":"1.231893357","rc":[{"batl":[[0,16,1.77],[1,90,1.4],[2,95,5]],"ltp":2.54,"tv":0.07,"id":60443}]}]}
{"op":"mcm","clk":"11933808352","pt":1724317572623,"mc":[{"id":"1.231893357","rc":[{"batl":[[1,95,5.85],[2,990,5.51]],"ltp":1.71,"tv":1.99,"id":169},{"batl":[[1,90,1.02]],"ltp":1.7,"tv":4.16,"id":31375}]}]}
{"op":"mcm","clk":"11933808418","pt":1724317574017,"mc":[{"id":"1.231893357","rc":[{"batl":[[0,65,1.7],[1,90,1.15],[2,95,5]],"ltp":1.71,"tv":1.99,"id":169},{"batl":[[0,38,1.98],[1,90,1.32]],"ltp":1.7,"tv":4.16,"id":31375}]}]}
{"op":"mcm","clk":"11933808424","pt":1724317574122,"mc":[{"id":"1.231893357","rc":[{"batl":[[0,15.5,1.83],[1,26,1.31],[2,90,1.02]],"ltp":2.54,"tv":0.07,"id":60443}]}]}
{"op":"mcm","clk":"11933820917","pt":1724317847100,"mc":[{"id":"1.231893357","rc":[{"batb":[[0,1.84,20],[1,1.82,3.35],[2,1.8,62.5]],"ltp":1.7,"tv":4.16,"id":31375}]}]}
{"op":"mcm","clk":"11933821217","pt":1724317856829,"mc":[{"id":"1.231893357","rc":[{"batb":[[0,1.74,20],[1,1.72,3.35],[2,1.7,71.43]],"ltp":1.71,"tv":1.99,"id":169}]}]}
{"op":"mcm","clk":"11933821328","pt":1724317858846,"mc":[{"id":"1.231893357","rc":[{"batl":[[0,60,1],[1,65,1],[2,90,1.15]],"ltp":1.71,"tv":1.99,"id":169},{"batl":[[0,36,1.28],[1,38,1],[2,90,1.32]],"ltp":1.7,"tv":4.16,"id":31375}]}]}
{"op":"mcm","clk":"11933821358","pt":1724317859315,"mc":[{"id":"1.231893357","rc":[{"batb":[[0,1.74,20.3]],"ltp":1.71,"tv":1.99,"id":169},{"batb":[[0,1.42,4.41]],"batl":[[0,15,1.13],[1,15.5,1],[2,26,1.31]],"ltp":2.54,"tv":0.07,"id":60443},{"batb":[[0,1.84,20.3]],"ltp":1.7,"tv":4.16,"id":31375}]}]}
{"op":"mcm","clk":"11933821539","pt":1724317863918,"mc":[{"id":"1.231893357","rc":[{"batl":[[1,90,1.15],[2,95,5]],"ltp":1.71,"tv":1.99,"id":169},{"batl":[[0,3.95,5],[1,15,1.13]],"ltp":2.54,"tv":0.07,"id":60443},{"batl":[[1,90,1.32],[2,95,5]],"ltp":1.7,"tv":4.16,"id":31375}]}]}
{"op":"mcm","clk":"11933821586","pt":1724317864943,"mc":[{"id":"1.231893357","rc":[{"batb":[[1,1.72,3.05]],"ltp":1.71,"tv":1.99,"id":169},{"batb":[[0,1.42,4.11]],"batl":[[1,16,1.77],[2,90,1.4]],"ltp":2.54,"tv":0.07,"id":60443},{"batb":[[1,1.82,3.05]],"ltp":1.7,"tv":4.16,"id":31375}]}]}
{"op":"mcm","clk":"11933821682","pt":1724317866939,"mc":[{"id":"1.231893357","rc":[{"batl":[[1,95,5.85],[2,990,5.51]],"ltp":1.71,"tv":1.99,"id":169},{"batl":[[1,90,1.02]],"ltp":1.7,"tv":4.16,"id":31375}]}]}
{"op":"mcm","clk":"11933822068","pt":1724317874748,"mc":[{"id":"1.231893357","rc":[{"batl":[[0,3.9,1],[1,3.95,5],[2,16,1.77]],"ltp":2.54,"tv":0.07,"id":60443}]}]}
{"op":"mcm","clk":"11933822877","pt":1724317896990,"mc":[{"id":"1.231893357","rc":[{"batl":[[0,55,1.7],[1,90,1.15],[2,95,5]],"ltp":1.71,"tv":1.99,"id":169}]}]}
{"op":"mcm","clk":"11933823075","pt":1724317902579,"mc":[{"id":"1.231893357","rc":[{"batl":[[0,34,1.98],[1,90,1.32]],"ltp":1.7,"tv":4.16,"id":31375}]}]}
{"op":"mcm","clk":"11933831900","pt":1724318139642,"mc":[{"id":"1.231893357","rc":[{"batb":[[0,1.74,20]],"ltp":1.71,"tv":1.99,"id":169},{"batb":[[0,1.42,3.81]],"ltp":2.54,"tv":0.07,"id":60443},{"batb":[[0,1.84,20]],"ltp":1.7,"tv":4.16,"id":31375}]}]}
{"op":"mcm","clk":"11933831929","pt":1724318140059,"mc":[{"id":"1.231893357","rc":[{"batl":[[2,16,1.47]],"ltp":2.54,"tv":0.07,"id":60443}]}]}
{"op":"mcm","clk":"11933832009","pt":1724318141857,"mc":[{"id":"1.231893357","rc":[{"batb":[[0,1.74,20.3]],"batl":[[0,50,1],[1,55,1],[2,90,1.15]],"ltp":1.71,"tv":1.99,"id":169},{"batb":[[0,1.42,4.11]],"batl":[[0,3.9,1.3]],"ltp":2.54,"tv":0.07,"id":60443},{"batb":[[0,1.84,20.3]],"batl":[[0,32,1.28],[1,34,1],[2,90,1.02]],"ltp":1.7,"tv":4.16,"id":31375}]}]}
{"op":"mcm","clk":"11933832039","pt":1724318142472,"mc":[{"id":"1.231893357","rc":[{"batl":[[1,95,5.85],[2,990,5.51]],"ltp":1.71,"tv":1.99,"id":169},{"batl":[[1,90,1.02],[2,95,5]],"ltp":1.7,"tv":4.16,"id":31375}]}]}
{"op":"mcm","clk":"11933832271","pt":1724318147525,"mc":[{"id":"1.231893357","rc":[{"batl":[[0,48,1.7],[1,90,1.15],[2,95,5]],"ltp":1.71,"tv":1.99,"id":169},{"batl":[[0,30,1.98],[1,90,1.32]],"ltp":1.7,"tv":4.16,"id":31375}]}]}
{"op":"mcm","clk":"11933841850","pt":1724318397999,"mc":[{"id":"1.231893357","rc":[{"batl":[[0,3.85,5.3],[1,3.9,1]],"ltp":2.54,"tv":0.07,"id":60443}]}]}
{"op":"mcm","clk":"11933842076","pt":1724318403784,"mc":[{"id":"1.231893357","rc":[{"batl":[[1,16,1.47],[2,90,1.4]],"ltp":2.54,"tv":0.07,"id":60443}]}]}
{"op":"mcm","clk":"11933842315","pt":1724318409325,"mc":[{"id":"1.231893357","rc":[{"batl":[[0,3.8,1],[1,3.85,5.3],[2,16,1.47]],"ltp":2.54,"tv":0.07,"id":60443}]}]}
{"op":"mcm","clk":"11933843999","pt":1724318451360,"mc":[{"id":"1.231893357","rc":[{"batb":[[0,1.42,3.81]],"ltp":2.54,"tv":0.07,"id":60443}]}]}
{"op":"mcm","clk":"11933844033","pt":1724318452337,"mc":[{"id":"1.231893357","rc":[{"batb":[[0,1.74,20]],"ltp":1.71,"tv":1.99,"id":169},{"batb":[[0,1.84,20]],"ltp":1.7,"tv":4.16,"id":31375}]}]}
{"op":"mcm","clk":"11933844070","pt":1724318453463,"mc":[{"id":"1.231893357","rc":[{"batl":[[1,3.85,5]],"ltp":2.54,"tv":0.07,"id":60443}]}]}
{"op":"mcm","clk":"11933844112","pt":1724318454541,"mc":[{"id":"1.231893357","rc":[{"batl":[[1,90,1.02]],"ltp":1.7,"tv":4.16,"id":31375}]}]}
{"op":"mcm","clk":"11933844139","pt":1724318455563,"mc":[{"id":"1.231893357","rc":[{"batl":[[1,95,5.85],[2,990,5.51]],"ltp":1.71,"tv":1.99,"id":169}]}]}
{"op":"mcm","clk":"11933844202","pt":1724318456949,"mc":[{"id":"1.231893357","rc":[{"batl":[[0,48,2]],"ltp":1.71,"tv":1.99,"id":169}]}]}
{"op":"mcm","clk":"11933844263","pt":1724318457982,"mc":[{"id":"1.231893357","rc":[{"batb":[[0,1.74,20.3]],"ltp":1.71,"tv":1.99,"id":169},{"batb":[[0,1.42,4.11]],"batl":[[0,3.8,1.3]],"ltp":2.54,"tv":0.07,"id":60443},{"batb":[[0,1.84,20.3]],"batl":[[0,29,1.28],[1,30,1],[2,90,1.02]],"ltp":1.7,"tv":4.16,"id":31375}]}]}
{"op":"mcm","clk":"11933844336","pt":1724318459376,"mc":[{"id":"1.231893357","rc":[{"batl":[[1,90,1.02],[2,95,5]],"ltp":1.7,"tv":4.16,"id":31375}]}]}
{"op":"mcm","clk":"11933844886","pt":1724318470573,"mc":[{"id":"1.231893357","rc":[{"batl":[[0,28,1.98],[1,90,1.32]],"ltp":1.7,"tv":4.16,"id":31375}]}]}
{"op":"mcm","clk":"11933856199","pt":1724318770439,"mc":[{"id":"1.231893357","rc":[{"batb":[[0,1.42,3.81]],"ltp":2.54,"tv":0.07,"id":60443}]}]}
{"op":"mcm","clk":"11933856288","pt":1724318772924,"mc":[{"id":"1.231893357","rc":[{"batb":[[0,1.74,20]],"ltp":1.71,"tv":1.99,"id":169},{"batb":[[0,1.84,20]],"batl":[[1,90,1.02]],"ltp":1.7,"tv":4.16,"id":31375}]}]}
{"op":"mcm","clk":"11933856353","pt":1724318773956,"mc":[{"id":"1.231893357","rc":[{"batl":[[0,46,1.13],[1,48,1.17],[2,95,5.85]],"ltp":1.71,"tv":1.99,"id":169},{"batl":[[0,27,1.28],[1,28,1],[2,90,1.02]],"ltp":1.7,"tv":4.16,"id":31375}]}]}
{"op":"mcm","clk":"11933856362","pt":1724318774059,"mc":[{"id":"1.231893357","rc":[{"batb":[[0,1.74,20.3]],"ltp":1.71,"tv":1.99,"id":169},{"batb":[[0,1.42,4.11]],"ltp":2.54,"tv":0.07,"id":60443},{"batb":[[0,1.84,20.3]],"ltp":1.7,"tv":4.16,"id":31375}]}]}
{"op":"mcm","clk":"11933856414","pt":1724318775040,"mc":[{"id":"1.231893357","rc":[{"batl":[[0,48,2],[1,95,5.85],[2,990,5.51]],"ltp":1.71,"tv":1.99,"id":169}]}]}
{"op":"mcm","clk":"11933856710","pt":1724318782542,"mc":[{"id":"1.231893357","rc":[{"batl":[[1,90,1.02],[2,95,5]],"ltp":1.7,"tv":4.16,"id":31375}]}]}
{"op":"mcm","clk":"11933856928","pt":1724318788048,"mc":[{"id":"1.231893357","rc":[{"batl":[[0,26,1.98],[1,90,1.32]],"ltp":1.7,"tv":4.16,"id":31375}]}]}
{"op":"mcm","clk":"11933865171","pt":1724318970067,"mc":[{"id":"1.231893357","rc":[{"batb":[[1,1.35,64.18],[2,1.08,31.25]],"ltp":2.54,"tv":0.07,"id":60443}]}]}
{"op":"mcm","clk":"11933867223","pt":1724319012080,"mc":[{"id":"1.231893357","rc":[{"batb":[[0,1.43,20.16],[1,1.42,3.81],[2,1.35,64.18]],"ltp":2.54,"tv":0.07,"id":60443}]}]}
{"op":"mcm","clk":"11933871349","pt":1724319093760,"mc":[{"id":"1.231893357","rc":[{"batb":[[0,1.74,20.6]],"batl":[[0,46,1.13],[1,48,1.17],[2,95,5.85]],"ltp":1.71,"tv":1.99,"id":169},{"batb":[[0,1.43,20.46]],"batl":[[0,3.8,1.6]],"ltp":2.54,"tv":0.07,"id":60443},{"batb":[[0,1.84,20.6]],"batl":[[0,25,1.28],[1,26,1],[2,90,1.32]],"ltp":1.7,"tv":4.16,"id":31375}]}]}
{"op":"mcm","clk":"11933871383","pt":1724319094375,"mc":[{"id":"1.231893357","rc":[{"batl":[[1,90,1.02],[2,95,5]],"ltp":1.71,"tv":1.99,"id":169},{"batl":[[1,90,1.32],[2,95,5]],"ltp":1.7,"tv":4.16,"id":31375}]}]}
{"op":"mcm","clk":"11933871526","pt":1724319096891,"mc":[{"id":"1.231893357","rc":[{"batb":[[0,1.43,20.16]],"ltp":2.54,"tv":0.07,"id":60443}]}]}
{"op":"mcm","clk":"11933871564","pt":1724319097502,"mc":[{"id":"1.231893357","rc":[{"batb":[[0,1.74,20.3]],"ltp":1.71,"tv":1.99,"id":169},{"batl":[[0,3.8,1.3]],"ltp":2.54,"tv":0.07,"id":60443},{"batb":[[0,1.84,20.3]],"ltp":1.7,"tv":4.16,"id":31375}]}]}
{"op":"mcm","clk":"11933871597","pt":1724319098072,"mc":[{"id":"1.231893357","rc":[{"batl":[[1,90,1.02]],"ltp":1.7,"tv":4.16,"id":31375}]}]}
{"op":"mcm","clk":"11933871697","pt":1724319100016,"mc":[{"id":"1.231893357","rc":[{"batl":[[0,44,1.53],[1,90,1.62]],"ltp":1.71,"tv":1.99,"id":169},{"batl":[[0,24,1.98],[1,90,1.32]],"ltp":1.7,"tv":4.16,"id":31375}]}]}
{"op":"mcm","clk":"11933871738","pt":1724319100695,"mc":[{"id":"1.231893357","rc":[{"batl":[[1,90,1.32]],"ltp":1.71,"tv":1.99,"id":169}]}]}
{"op":"mcm","clk":"11933885320","pt":1724319406653,"mc":[{"id":"1.231893357","rc":[{"batb":[[0,1.74,20.6]],"batl":[[0,44,1.83]],"ltp":1.71,"tv":1.99,"id":169},{"batb":[[0,1.43,20.46]],"batl":[[0,3.8,1.6]],"ltp":2.54,"tv":0.07,"id":60443},{"batb":[[0,1.84,20.6]],"batl":[[0,23,1.28],[1,24,1],[2,90,1.32]],"ltp":1.7,"tv":4.16,"id":31375}]}]}
{"op":"mcm","clk":"11933885510","pt":1724319411820,"mc":[{"id":"1.231893357","rc":[{"batl":[[1,90,1.32],[2,95,5]],"ltp":1.7,"tv":4.16,"id":31375}]}]}
{"op":"mcm","clk":"11933886630","pt":1724319439702,"mc":[{"id":"1.231893357","rc":[{"batl":[[0,22,1.98],[1,90,1.62]],"ltp":1.7,"tv":4.16,"id":31375}]}]}
{"op":"mcm","clk":"11933888841","pt":1724319492011,"mc":[{"id":"1.231893357","rc":[{"batb":[[0,1.74,20.3]],"ltp":1.71,"tv":1.99,"id":169},{"batb":[[0,1.43,20.16]],"ltp":2.54,"tv":0.07,"id":60443}]}]}
{"op":"mcm","clk":"11933888862","pt":1724319492420,"mc":[{"id":"1.231893357","rc":[{"batl":[[0,3.8,1.3]],"ltp":2.54,"tv":0.07,"id":60443},{"batb":[[0,1.84,20.3]],"ltp":1.7,"tv":4.16,"id":31375}]}]}
{"op":"mcm","clk":"11933888895","pt":1724319493138,"mc":[{"id":"1.231893357","rc":[{"batl":[[1,90,1.32]],"ltp":1.7,"tv":4.16,"id":31375}]}]}
{"op":"mcm","clk":"11933888923","pt":1724319494114,"mc":[{"id":"1.231893357","rc":[{"batl":[[1,90,1.02]],"ltp":1.71,"tv":1.99,"id":169}]}]}
{"op":"mcm","clk":"11933889821","pt":1724319517154,"mc":[{"id":"1.231893357","rc":[{"batb":[[2,1.5,20]],"ltp":1.71,"tv":1.99,"id":169},{"batb":[[2,1.5,19.89]],"ltp":1.7,"tv":4.16,"id":31375}]}]}
{"op":"mcm","clk":"11933890471","pt":1724319534682,"mc":[{"id":"1.231893357","rc":[{"batb":[[0,2,50],[1,1.84,20.3],[2,1.82,3.05]],"ltp":1.7,"tv":4.16,"id":31375}]}]}
{"op":"mcm","clk":"11933890936","pt":1724319547479,"mc":[{"id":"1.231893357","rc":[{"batb":[[0,1.8,50],[1,1.74,20.3],[2,1.72,3.05]],"ltp":1.71,"tv":1.99,"id":169}]}]}
{"op":"mcm","clk":"11933895937","pt":1724319691534,"mc":[{"id":"1.231893357","rc":[{"batb":[[0,2.1,20],[1,2,50],[2,1.82,3.35]],"ltp":1.7,"tv":4.16,"id":31375}]}]}
{"op":"mcm","clk":"11933896221","pt":1724319698536,"mc":[{"id":"1.231893357","rc":[{"batb":[[0,2,20],[1,1.8,50],[2,1.72,3.35]],"ltp":1.71,"tv":1.99,"id":169}]}]}
{"op":"mcm","clk":"11933896513","pt":1724319706945,"mc":[{"id":"1.231893357","rc":[{"batl":[[0,3.75,5.3],[1,3.8,1]],"ltp":2.54,"tv":0.07,"id":60443}]}]}
{"op":"mcm","clk":"11933896647","pt":1724319709737,"mc":[{"id":"1.231893357","rc":[{"batb":[[0,2,20.3]],"batl":[[0,42,1.13],[1,44,1],[2,90,1.02]],"ltp":1.71,"tv":1.99,"id":169},{"batb":[[0,1.43,20.46]],"batl":[[0,3.75,5.6]],"ltp":2.54,"tv":0.07,"id":60443},{"batb":[[0,2.1,20.3]],"batl":[[0,21,1.28],[1,22,1],[2,90,1.32]],"ltp":1.7,"tv":4.16,"id":31375}]}]}
{"op":"mcm","clk":"11933896766","pt":1724319712655,"mc":[{"id":"1.231893357","rc":[{"batl":[[1,90,1.02],[2,95,5]],"ltp":1.71,"tv":1.99,"id":169},{"batl":[[1,16,1.47],[2,90,1.4]],"ltp":2.54,"tv":0.07,"id":60443},{"batl":[[1,90,1.32],[2,95,5]],"ltp":1.7,"tv":4.16,"id":31375}]}]}
{"op":"mcm","clk":"11933897002","pt":1724319718161,"mc":[{"id":"1.231893357","rc":[{"batl":[[0,40,1.53],[1,90,1.62]],"ltp":1.71,"tv":1.99,"id":169},{"batl":[[0,3.7,1.3],[1,3.75,5.3],[2,16,1.47]],"ltp":2.54,"tv":0.07,"id":60443}]}]}
{"op":"mcm","clk":"11933897236","pt":1724319723761,"mc":[{"id":"1.231893357","rc":[{"batl":[[0,20,1.98],[1,90,1.62]],"ltp":1.7,"tv":4.16,"id":31375}]}]}
{"op":"mcm","clk":"11933910456","pt":1724319814000,"mc":[{"id":"1.231893357","rc":[{"batb":[[2,1.72,3.05]],"ltp":1.71,"tv":1.99,"id":169}]}]}
{"op":"mcm","clk":"11933910501","pt":1724319814879,"mc":[{"id":"1.231893357","rc":[{"batb":[[0,1.43,20.16]],"ltp":2.54,"tv":0.07,"id":60443},{"batb":[[2,1.82,3.05]],"ltp":1.7,"tv":4.16,"id":31375}]}]}
{"op":"mcm","clk":"11933910530","pt":1724319815601,"mc":[{"id":"1.231893357","rc":[{"batl":[[1,90,1.32]],"ltp":1.7,"tv":4.16,"id":31375}]}]}
{"op":"mcm","clk":"11933910619","pt":1724319817593,"mc":[{"id":"1.231893357","rc":[{"batl":[[1,3.75,5]],"ltp":2.54,"tv":0.07,"id":60443}]}]}
{"op":"mcm","clk":"11933910701","pt":1724319819295,"mc":[{"id":"1.231893357","rc":[{"batl":[[1,90,1.32]],"ltp":1.71,"tv":1.99,"id":169}]}]}
{"op":"mcm","clk":"11933912621","pt":1724319864258,"mc":[{"id":"1.231893357","rc":[{"batl":[[2,870,0.51]],"ltp":1.71,"tv":1.99,"id":169},{"batl":[[2,870,0.51]],"ltp":1.7,"tv":4.16,"id":31375}]}]}
{"op":"mcm","clk":"11933913890","pt":1724319892772,"mc":[{"id":"1.231893357","rc":[{"batl":[[0,3.65,5],[1,3.7,1.3]],"ltp":2.54,"tv":0.07,"id":60443}]}]}
{"op":"mcm","clk":"11933914076","pt":1724319896410,"mc":[{"id":"1.231893357","rc":[{"batl":[[1,16,1.77],[2,90,1.4]],"ltp":2.54,"tv":0.07,"id":60443}]}]}
{"op":"mcm","clk":"11933914290","pt":1724319901883,"mc":[{"id":"1.231893357","rc":[{"batl":[[0,3.6,1],[1,3.65,5],[2,16,1.77]],"ltp":2.54,"tv":0.07,"id":60443}]}]}
{"op":"mcm","clk":"11933917958","pt":1724319978991,"mc":[{"id":"1.231893357","rc":[{"batl":[[0,21,1.53],[1,34,1],[2,40,1]],"ltp":1.71,"tv":1.99,"id":169},{"batl":[[0,15,1],[1,20,1.98],[2,21,1.3]],"ltp":1.7,"tv":4.16,"id":31375}]}]}
{"op":"mcm","clk":"11933918016","pt":1724319979868,"mc":[{"id":"1.231893357","rc":[{"batl":[[0,3.5,1],[1,4,1],[2,5,1]],"ltp":1.71,"tv":1.99,"id":169},{"batl":[[0,3.5,1],[2,4,1.3]],"ltp":2.54,"tv":0.07,"id":60443},{"batl":[[0,3.5,1],[1,4,1],[2,5,1]],"ltp":1.7,"tv":4.16,"id":31375}]}]}
{"op":"mcm","clk":"11933918950","pt":1724319995905,"mc":[{"id":"1.231893357","rc":[{"batb":[[0,2,20]],"ltp":1.71,"tv":1.99,"id":169},{"batb":[[0,1.43,19.86]],"batl":[[2,4,1]],"ltp":2.54,"tv":0.07,"id":60443},{"batb":[[0,2.1,20]],"ltp":1.7,"tv":4.16,"id":31375}]}]}
{"op":"mcm","clk":"11933919237","pt":1724320000597,"mc":[{"id":"1.231893357","rc":[{"batb":[[0,2,20.3]],"batl":[[0,3.5,1.3]],"ltp":1.71,"tv":1.99,"id":169},{"batb":[[0,1.43,20.16]],"batl":[[0,3.5,1.3]],"ltp":2.54,"tv":0.07,"id":60443},{"batb":[[0,2.1,20.3]],"batl":[[0,3.5,1.3]],"ltp":1.7,"tv":4.16,"id":31375}]}]}
{"op":"mcm","clk":"11933924778","pt":1724320110733,"mc":[{"id":"1.231893357","rc":[{"batl":[[0,3.65,5.3],[1,3.95,1]],"ltp":2.54,"tv":0.07,"id":60443}]}]}
{"op":"mcm","clk":"11933924886","pt":1724320112746,"mc":[{"id":"1.231893357","rc":[{"batl":[[2,4.9,1]],"ltp":2.54,"tv":0.07,"id":60443}]}]}
{"op":"mcm","clk":"11933927715","pt":1724320176884,"mc":[{"id":"1.231893357","rc":[{"batl":[[0,48,1],[1,180,1.02],[2,870,0.34]],"ltp":1.71,"tv":1.99,"id":169},{"batl":[[1,16,1.47],[2,90,1.4]],"ltp":2.54,"tv":0.07,"id":60443},{"batl":[[0,20,1.28],[1,90,1.02],[2,870,0.51]],"ltp":1.7,"tv":4.16,"id":31375}]}]}
{"op":"mcm","clk":"11933927854","pt":1724320180588,"mc":[{"id":"1.231893357","rc":[{"batl":[[0,46,1.83],[1,90,1.02],[2,870,0.51]],"ltp":1.71,"tv":1.99,"id":169},{"batl":[[0,3.6,1.3],[1,3.65,5],[2,16,1.47]],"ltp":2.54,"tv":0.07,"id":60443},{"batl":[[0,19.5,1.83],[1,90,1.46]],"ltp":1.7,"tv":4.16,"id":31375}]}]}
{"op":"mcm","clk":"11933928972","pt":1724320206918,"mc":[{"id":"1.231893357","rc":[{"batl":[[0,21,1.83],[1,34,1],[2,46,1]],"ltp":1.71,"tv":1.99,"id":169},{"batl":[[0,15,1.3],[1,19.5,1.53],[2,21,1.44]],"ltp":1.7,"tv":4.16,"id":31375}]}]}
{"op":"mcm","clk":"11933929026","pt":1724320207909,"mc":[{"id":"1.231893357","rc":[{"batl":[[0,3.5,1.3],[1,4,1],[2,5,1]],"ltp":1.71,"tv":1.99,"id":169},{"batl":[[0,3.5,1.3],[1,3.6,1],[2,3.65,5]],"ltp":2.54,"tv":0.07,"id":60443},{"batl":[[0,3.5,1.3],[1,4,1],[2,5,1]],"ltp":1.7,"tv":4.16,"id":31375}]}]}
{"op":"mcm","clk":"11933929043","pt":1724320208203,"mc":[{"id":"1.231893357","rc":[{"batl":[[1,3.65,5],[2,4,1]],"ltp":2.54,"tv":0.07,"id":60443}]}]}
{"op":"mcm","clk":"11933930839","pt":1724320247964,"mc":[{"id":"1.231893357","rc":[{"batl":[[1,4,13.39]],"ltp":1.71,"tv":1.99,"id":169},{"batl":[[1,3.65,17]],"ltp":2.54,"tv":0.07,"id":60443},{"batb":[[1,2,70.29]],"ltp":1.7,"tv":4.16,"id":31375}]}]}
{"op":"mcm","clk":"11933930865","pt":1724320248835,"mc":[{"id":"1.231893357","rc":[{"batl":[[1,3.65,12],[2,4,13.39]],"ltp":1.71,"tv":1.99,"id":169},{"batl":[[1,3.65,29]],"ltp":2.54,"tv":0.07,"id":60443}]}]}
{"op":"mcm","clk":"11933930870","pt":1724320249041,"mc":[{"id":"1.231893357","rc":[{"batl":[[1,3.65,12],[2,4,1]],"ltp":1.7,"tv":4.16,"id":31375}]}]}
{"op":"mcm","clk":"11933933188","pt":1724320299896,"mc":[{"id":"1.231893357","rc":[{"batb":[[0,2,20.6]],"batl":[[0,3.5,1.6]],"ltp":1.71,"tv":1.99,"id":169},{"batb":[[0,1.43,20.46]],"batl":[[0,3.5,1.6]],"ltp":2.54,"tv":0.07,"id":60443},{"batb":[[0,2.1,20.6]],"batl":[[0,3.5,1.6]],"ltp":1.7,"tv":4.16,"id":31375}]}]}
{"op":"mcm","clk":"11933935692","pt":1724320354855,"mc":[{"id":"1.231893357","rc":[{"batb":[[0,2.4,20],[1,2,70.89]],"ltp":1.7,"tv":4.16,"id":31375}]}]}
{"op":"mcm","clk":"11933935752","pt":1724320355836,"mc":[{"id":"1.231893357","rc":[{"batb":[[0,1.43,20.16]],"ltp":2.54,"tv":0.07,"id":60443}]}]}
{"op":"mcm","clk":"11933935816","pt":1724320356964,"mc":[{"id":"1.231893357","rc":[{"batb":[[0,2,20.3]],"ltp":1.71,"tv":1.99,"id":169},{"batb":[[1,2,70.59]],"ltp":1.7,"tv":4.16,"id":31375}]}]}
{"op":"mcm","clk":"11933935908","pt":1724320358966,"mc":[{"id":"1.231893357","rc":[{"batl":[[0,3.5,1.3]],"ltp":1.71,"tv":1.99,"id":169},{"batl":[[0,3.5,1.3]],"ltp":2.54,"tv":0.07,"id":60443},{"batl":[[0,3.5,1.3]],"ltp":1.7,"tv":4.16,"id":31375}]}]}
{"op":"mcm","clk":"11933936499","pt":1724320372883,"mc":[{"id":"1.231893357","rc":[{"batb":[[0,2.4,20],[1,1.8,50.3]],"ltp":1.71,"tv":1.99,"id":169}]}]}
{"op":"mcm","clk":"11933936972","pt":1724320382389,"mc":[{"id":"1.231893357","rc":[{"batl":[[0,3.45,5.3],[1,3.5,1],[2,3.65,24]],"ltp":2.54,"tv":0.07,"id":60443}]}]}
{"op":"mcm","clk":"11933943082","pt":1724320510005,"mc":[{"id":"1.231893357","rc":[{"batb":[[1,2.28,8.19],[2,1.8,50]],"ltp":1.71,"tv":1.99,"id":169},{"batb":[[0,2.22,8.39],[1,1.43,19.86],[2,1.42,3.81]],"ltp":2.54,"tv":0.07,"id":60443},{"batb":[[1,2.28,8.19],[2,2,70.29]],"ltp":1.7,"tv":4.16,"id":31375}]}]}
{"op":"mcm","clk":"11933947698","pt":1724320615357,"mc":[{"id":"1.231893357","rc":[{"batb":[[0,2.4,20.3]],"batl":[[0,3.5,1.6]],"ltp":1.71,"tv":1.99,"id":169},{"batb":[[0,2.22,8.69]],"batl":[[0,3.45,5.6]],"ltp":2.54,"tv":0.07,"id":60443},{"batb":[[0,2.4,20.3]],"batl":[[0,3.5,1.6]],"ltp":1.7,"tv":4.16,"id":31375}]}]}
{"op":"mcm","clk":"11933949499","pt":1724320653899,"mc":[{"id":"1.231893357","rc":[{"batb":[[1,2.28,7.89]],"ltp":1.71,"tv":1.99,"id":169},{"batb":[[0,2.22,8.39]],"ltp":2.54,"tv":0.07,"id":60443}]}]}
{"op":"mcm","clk":"11933949528","pt":1724320654776,"mc":[{"id":"1.231893357","rc":[{"batb":[[1,2.28,7.89]],"ltp":1.7,"tv":4.16,"id":31375}]}]}
{"op":"mcm","clk":"11933949563","pt":1724320655803,"mc":[{"id":"1.231893357","rc":[{"batl":[[0,3.5,1.3]],"ltp":1.71,"tv":1.99,"id":169},{"batl":[[0,3.45,5.3]],"ltp":2.54,"tv":0.07,"id":60443},{"batl":[[0,3.5,1.3]],"ltp":1.7,"tv":4.16,"id":31375}]}]}
{"op":"mcm","clk":"11933956778","pt":1724320807765,"mc":[{"id":"1.231893357","marketDefinition":{"bspMarket":false,"turnInPlayEnabled":true,"persistenceEnabled":true,"marketBaseRate":5.0,"eventId":"33500951","eventTypeId":"4","numberOfWinners":1,"bettingType":"ODDS","marketType":"MATCH_ODDS","marketTime":"2024-08-22T10:00:00.000Z","suspendTime":"2024-08-22T10:00:00.000Z","bspReconciled":false,"complete":true,"inPlay":true,"crossMatching":true,"runnersVoidable":false,"numberOfActiveRunners":3,"betDelay":5,"status":"OPEN","runners":[{"status":"ACTIVE","sortPriority":1,"id":31375,"name":"Derbyshire"},{"status":"ACTIVE","sortPriority":2,"id":169,"name":"Glamorgan"},{"status":"ACTIVE","sortPriority":3,"id":60443,"name":"The Draw"}],"regulators":["MR_INT"],"countryCode":"GB","discountAllowed":true,"timezone":"GMT","openDate":"2024-08-22T10:00:00.000Z","version":6090703957,"name":"Match Odds","eventName":"Derbyshire v Glamorgan"},"rc":[{"batb":[[0,1.72,3.05],[1,1.5,20],[2,1.08,31.25]],"batl":[[0,3.5,1],[1,4,1],[2,5,1]],"ltp":1.71,"tv":1.99,"id":169},{"batb":[[0,1.42,3.81],[1,1.35,20],[2,1.08,31.25]],"batl":[[0,3.5,1],[1,4,1],[2,5,1]],"ltp":2.54,"tv":0.07,"id":60443},{"batb":[[0,1.82,3.05],[1,1.5,19],[2,1.08,31.25]],"batl":[[0,3.5,1],[1,4,1],[2,5,1]],"ltp":1.7,"tv":4.16,"id":31375}],"tv":6.23}]}
{"op":"mcm","clk":"11933961145","pt":1724320886946,"mc":[{"id":"1.231893357","rc":[{"trd":[[2.32,1]],"ltp":2.32,"tv":2.99,"id":169},{"trd":[[3.5,0.66]],"batl":[[0,4,1.34],[1,5,1],[2,6,1]],"ltp":3.5,"tv":0.73,"id":60443},{"trd":[[3.5,0.66]],"batl":[[0,4,1.34],[1,5,1],[2,6,1]],"ltp":3.5,"tv":4.82,"id":31375}],"tv":8.55}]}
{"op":"mcm","clk":"11933961894","pt":1724320903484,"mc":[{"id":"1.231893357","rc":[{"batb":[[1,1.7,1],[2,1.5,20]],"ltp":2.32,"tv":2.99,"id":169}]}]}
{"op":"mcm","clk":"11933963664","pt":1724320946957,"mc":[{"id":"1.231893357","rc":[{"batl":[[0,3.5,1.3]],"ltp":2.32,"tv":2.99,"id":169},{"batl":[[0,4,1.64]],"ltp":3.5,"tv":4.82,"id":31375}]}]}
{"op":"mcm","clk":"11933963686","pt":1724320947364,"mc":[{"id":"1.231893357","rc":[{"batl":[[0,4,1.64]],"ltp":3.5,"tv":0.73,"id":60443}]}]}
{"op":"mcm","clk":"11933964045","pt":1724320955592,"mc":[{"id":"1.231893357","rc":[{"batb":[[0,1.72,3.35]],"ltp":2.32,"tv":2.99,"id":169},{"batb":[[0,1.42,4.11]],"ltp":3.5,"tv":0.73,"id":60443},{"batb":[[0,1.82,3.35]],"ltp":3.5,"tv":4.82,"id":31375}]}]}
{"op":"mcm","clk":"11933976210","pt":1724321257488,"mc":[{"id":"1.231893357","rc":[{"batb":[[0,1.72,3.65]],"batl":[[0,3.5,1.6]],"ltp":2.32,"tv":2.99,"id":169},{"batb":[[0,1.42,4.41]],"batl":[[0,4,1.94]],"ltp":3.5,"tv":0.73,"id":60443},{"batb":[[0,1.82,3.65]],"batl":[[0,4,1.94]],"ltp":3.5,"tv":4.82,"id":31375}]}]}
{"op":"mcm","clk":"11933983073","pt":1724321420102,"mc":[{"id":"1.231893357","rc":[{"trd":[[3.45,0.34]],"batl":[[0,3.5,1.26]],"ltp":3.45,"tv":3.33,"id":169},{"trd":[[3.5,1]],"batl":[[0,4,1.6]],"ltp":3.5,"tv":1.07,"id":60443},{"trd":[[2.34,0.51]],"batl":[[0,3.95,1.43],[1,4,1],[2,5,1]],"ltp":2.34,"tv":5.33,"id":31375}],"tv":9.74}]}
{"op":"mcm","clk":"11933983464","pt":1724321429780,"mc":[{"id":"1.231893357","rc":[{"batb":[[0,2.62,1.33],[1,1.42,4.41],[2,1.35,20]],"ltp":3.5,"tv":1.07,"id":60443}]}]}
{"op":"mcm","clk":"11933983941","pt":1724321439721,"mc":[{"id":"1.231893357","rc":[{"trd":[[3.45,0.6]],"batl":[[0,3.5,1]],"ltp":3.45,"tv":3.59,"id":169},{"trd":[[3.95,0.23]],"batl":[[0,4,1.37]],"ltp":3.95,"tv":1.3,"id":60443},{"trd":[[2.16,0.58],[2.18,1.01]],"batb":[[0,1.82,3.06]],"ltp":2.16,"tv":6.92,"id":31375}],"tv":11.82}]}
{"op":"mcm","clk":"11933989038","pt":1724321552835,"mc":[{"id":"1.231893357","rc":[{"batl":[[0,3.5,1.3]],"ltp":3.45,"tv":3.59,"id":169},{"batl":[[0,3.9,1.13],[1,4,1.6]],"ltp":2.16,"tv":6.92,"id":31375}]}]}
{"op":"mcm","clk":"11933989049","pt":1724321553142,"mc":[{"id":"1.231893357","rc":[{"batb":[[0,1.72,3.95]],"ltp":3.45,"tv":3.59,"id":169},{"batb":[[0,1.82,3.36]],"ltp":2.16,"tv":6.92,"id":31375}]}]}
{"op":"mcm","clk":"11933990573","pt":1724321583877,"mc":[{"id":"1.231893357","rc":[{"batb":[[0,1.72,3.65]],"ltp":3.45,"tv":3.59,"id":169}]}]}
{"op":"mcm","clk":"11933990647","pt":1724321584659,"mc":[{"id":"1.231893357","rc":[{"batb":[[1,1.42,4.11]],"ltp":3.95,"tv":1.3,"id":60443},{"batl":[[1,4,1.3]],"ltp":2.16,"tv":6.92,"id":31375}]}]}
{"op":"mcm","clk":"11933990702","pt":1724321585559,"mc":[{"id":"1.231893357","rc":[{"batl":[[0,4,1.07]],"ltp":3.95,"tv":1.3,"id":60443}]}]}
{"op":"mcm","clk":"11933990978","pt":1724321589987,"mc":[{"id":"1.231893357","rc":[{"batb":[[0,1.72,3.35]],"ltp":3.45,"tv":3.59,"id":169},{"batb":[[1,1.42,3.81]],"ltp":3.95,"tv":1.3,"id":60443}]}]}
{"op":"mcm","clk":"11933990994","pt":1724321590297,"mc":[{"id":"1.231893357","rc":[{"batb":[[0,1.82,3.35]],"ltp":2.16,"tv":6.92,"id":31375}]}]}
{"op":"mcm","clk":"11933991099","pt":1724321592779,"mc":[{"id":"1.231893357","rc":[{"batl":[[0,4,1]],"ltp":3.95,"tv":1.3,"id":60443},{"batl":[[1,4,1]],"ltp":2.16,"tv":6.92,"id":31375}]}]}
{"op":"mcm","clk":"11933993186","pt":1724321633845,"mc":[{"id":"1.231893357","rc":[{"batl":[[0,3.95,5],[1,4,1],[2,5,1]],"ltp":3.95,"tv":1.3,"id":60443}]}]}
{"op":"mcm","clk":"11933993843","pt":1724321646233,"mc":[{"id":"1.231893357","rc":[{"batl":[[0,3.45,5.3],[1,3.5,1],[2,4,1]],"ltp":3.45,"tv":3.59,"id":169}]}]}
{"op":"mcm","clk":"11933994600","pt":1724321659059,"mc":[{"id":"1.231893357","rc":[{"trd":[[2.2,0.98]],"batb":[[0,2.2,9.51],[1,1.82,3.35],[2,1.5,19]],"batl":[[0,4,1.64],[1,5,1],[2,6,1]],"ltp":2.2,"tv":7.9,"id":31375}],"tv":12.8}]}
{"op":"mcm","clk":"11933994818","pt":1724321663285,"mc":[{"id":"1.231893357","rc":[{"batl":[[0,3.5,1.3],[1,4,1],[2,5,1]],"ltp":3.45,"tv":3.59,"id":169},{"batl":[[0,4,1],[1,5,1],[2,6,1]],"ltp":3.95,"tv":1.3,"id":60443},{"batb":[[0,1.82,3.35],[1,1.5,19],[2,1.08,31.25]],"ltp":2.2,"tv":7.9,"id":31375}]}]}
{"op":"mcm","clk":"11933996019","pt":1724321687326,"mc":[{"id":"1.231893357","rc":[{"batl":[[0,2.98,5],[1,3.5,1.3],[2,4,1]],"ltp":3.45,"tv":3.59,"id":169}]}]}
{"op":"mcm","clk":"11933996149","pt":1724321690315,"mc":[{"id":"1.231893357","rc":[{"batl":[[0,3.5,1.3],[1,4,1],[2,5,1]],"ltp":3.45,"tv":3.59,"id":169}]}]}
{"op":"mcm","clk":"11933996894","pt":1724321704912,"mc":[{"id":"1.231893357","rc":[{"batl":[[0,2.98,5],[1,4,1.64],[2,5,1]],"ltp":2.2,"tv":7.9,"id":31375}]}]}
{"op":"mcm","clk":"11934005038","pt":1724321847522,"mc":[{"id":"1.231893357","rc":[{"batb":[[0,1.82,3.05]],"ltp":2.2,"tv":7.9,"id":31375}]}]}
{"op":"mcm","clk":"11934005107","pt":1724321848814,"mc":[{"id":"1.231893357","rc":[{"batb":[[0,1.72,3.05]],"batl":[[0,3.5,1]],"ltp":3.45,"tv":3.59,"id":169},{"batl":[[1,4,1.34]],"ltp":2.2,"tv":7.9,"id":31375}]}]}
{"op":"mcm","clk":"11934005296","pt":1724321852019,"mc":[{"id":"1.231893357","rc":[{"batb":[[0,1.72,3.35]],"batl":[[0,3.5,1.3]],"ltp":3.45,"tv":3.59,"id":169},{"batl":[[0,2.98,5.3]],"ltp":2.2,"tv":7.9,"id":31375}]}]}
{"op":"mcm","clk":"11934005596","pt":1724321857125,"mc":[{"id":"1.231893357","rc":[{"batb":[[0,1.82,3.35]],"ltp":2.2,"tv":7.9,"id":31375}]}]}
{"op":"mcm","clk":"11934019511","pt":1724322134845,"mc":[{"id":"1.231893357","rc":[{"batl":[[0,2.98,5]],"ltp":2.2,"tv":7.9,"id":31375}]}]}
{"op":"mcm","clk":"11934019523","pt":1724322135153,"mc":[{"id":"1.231893357","rc":[{"batl":[[0,3.5,1]],"ltp":3.45,"tv":3.59,"id":169}]}]}
{"op":"mcm","clk":"11934019614","pt":1724322137214,"mc":[{"id":"1.231893357","rc":[{"batb":[[0,1.72,3.05]],"ltp":3.45,"tv":3.59,"id":169}]}]}
{"op":"mcm","clk":"11934019672","pt":1724322138910,"mc":[{"id":"1.231893357","rc":[{"batb":[[0,1.82,3.05]],"ltp":2.2,"tv":7.9,"id":31375}]}]}
{"op":"mcm","clk":"11934019901","pt":1724322144525,"mc":[{"id":"1.231893357","rc":[{"batb":[[0,1.72,3.35]],"batl":[[0,3.5,1.3]],"ltp":3.45,"tv":3.59,"id":169},{"batb":[[0,1.82,3.35]],"batl":[[0,2.98,5.3]],"ltp":2.2,"tv":7.9,"id":31375}]}]}
{"op":"mcm","clk":"11934032715","pt":1724322456467,"mc":[{"id":"1.231893357","rc":[{"batb":[[0,1.72,3.05]],"ltp":3.45,"tv":3.59,"id":169},{"batb":[[0,1.82,3.05]],"ltp":2.2,"tv":7.9,"id":31375}]}]}
{"op":"mcm","clk":"11934032762","pt":1724322457248,"mc":[{"id":"1.231893357","rc":[{"batl":[[0,3.5,1]],"ltp":3.45,"tv":3.59,"id":169},{"batl":[[0,2.98,5]],"ltp":2.2,"tv":7.9,"id":31375}]}]}
{"op":"mcm","clk":"11934033214","pt":1724322466796,"mc":[{"id":"1.231893357","rc":[{"batb":[[0,1.72,3.35]],"batl":[[0,3.5,1.3]],"ltp":3.45,"tv":3.59,"id":169},{"batb":[[0,1.82,3.35]],"batl":[[0,2.98,5.3]],"ltp":2.2,"tv":7.9,"id":31375}]}]}
{"op":"mcm","clk":"11934034582","pt":1724322499520,"mc":[{"id":"1.231893357","rc":[{"trd":[[4,2]],"batb":[[0,4,1],[1,2.62,1.33],[2,1.42,3.81]],"batl":[[0,5,1],[1,6,1],[2,8,1]],"ltp":4.0,"tv":3.3,"id":60443}],"tv":14.8}]}
{"op":"mcm","clk":"11934034836","pt":1724322505314,"mc":[{"id":"1.231893357","rc":[{"batb":[[1,2.82,1.42],[2,2.62,1.33]],"ltp":4.0,"tv":3.3,"id":60443}]}]}
{"op":"mcm","clk":"11934035013","pt":1724322509647,"mc":[{"id":"1.231893357","rc":[{"trd":[[5,2]],"batb":[[0,5,1],[1,4,1],[2,2.82,1.42]],"batl":[[0,6,1],[1,8,1],[2,10,1]],"ltp":5.0,"tv":5.3,"id":60443}],"tv":16.8}]}
{"op":"mcm","clk":"11934035273","pt":1724322515639,"mc":[{"id":"1.231893357","rc":[{"batb":[[2,3.05,1.64]],"ltp":5.0,"tv":5.3,"id":60443}]}]}
{"op":"mcm","clk":"11934035393","pt":1724322518536,"mc":[{"id":"1.231893357","rc":[{"trd":[[3.45,0.9],[3.5,1]],"batl":[[0,4,1],[1,5,1],[2,6,1]],"ltp":3.5,"tv":4.89,"id":169},{"trd":[[6,0.75]],"batl":[[0,8,1.25],[1,10,1],[2,15,1.53]],"ltp":6.0,"tv":6.05,"id":60443},{"trd":[[1.82,8.02],[1.84,0.56],[2.16,1.18]],"batb":[[0,1.5,19],[1,1.08,31.25],[2,1.07,35.71]],"batl":[[0,2.98,5.47]],"ltp":1.82,"tv":17.08,"id":31375}],"tv":28.03}]}
{"op":"mcm","clk":"11934035462","pt":1724322520343,"mc":[{"id":"1.231893357","rc":[{"batl":[[0,2.98,5.3]],"ltp":1.82,"tv":17.08,"id":31375}]}]}
{"op":"mcm","clk":"11934035554","pt":1724322522648,"mc":[{"id":"1.231893357","rc":[{"batb":[[0,3.05,1.64],[1,2.82,1.42],[2,2.62,1.33]],"ltp":6.0,"tv":6.05,"id":60443}]}]}
{"op":"mcm","clk":"11934035659","pt":1724322524554,"mc":[{"id":"1.231893357","rc":[{"batl":[[0,3.95,1],[1,4,1],[2,5,1]],"ltp":3.5,"tv":4.89,"id":169}]}]}
{"op":"mcm","clk":"11934035697","pt":1724322525430,"mc":[{"id":"1.231893357","rc":[{"batb":[[0,2.62,1.33],[1,1.72,3.35],[2,1.7,1]],"ltp":3.5,"tv":4.89,"id":169},{"batb":[[0,3.55,1.27],[1,3.05,1.64],[2,2.82,1.42]],"ltp":6.0,"tv":6.05,"id":60443}]}]}
{"op":"mcm","clk":"11934035934","pt":1724322530762,"mc":[{"id":"1.231893357","rc":[{"batl":[[0,4,1],[1,5,1],[2,6,1]],"ltp":3.5,"tv":4.89,"id":169},{"batl":[[0,7.8,1.25],[1,8,1],[2,10,1]],"ltp":6.0,"tv":6.05,"id":60443}]}]}
{"op":"mcm","clk":"11934036892","pt":1724322548584,"mc":[{"id":"1.231893357","rc":[{"batl":[[0,2.9,9],[1,2.98,5.3],[2,4,1.34]],"ltp":1.82,"tv":17.08,"id":31375}]}]}
{"op":"mcm","clk":"11934037409","pt":1724322560268,"mc":[{"id":"1.231893357","rc":[{"batl":[[2,6,8]],"ltp":3.5,"tv":4.89,"id":169}]}]}
{"op":"mcm","clk":"11934037624","pt":1724322564693,"mc":[{"id":"1.231893357","rc":[{"batl":[[0,2.4,1.52],[1,2.9,9],[2,2.98,5.3]],"ltp":1.82,"tv":17.08,"id":31375}]}]}
{"op":"mcm","clk":"11934037802","pt":1724322568970,"mc":[{"id":"1.231893357","rc":[{"batl":[[0,2.4,2.29]],"ltp":1.82,"tv":17.08,"id":31375}]}]}
{"op":"mcm","clk":"11934038272","pt":1724322578714,"mc":[{"id":"1.231893357","rc":[{"batb":[[1,1.16,18.29],[2,1.08,31.25]],"ltp":1.82,"tv":17.08,"id":31375}]}]}
{"op":"mcm","clk":"11934048151","pt":1724322777908,"mc":[{"id":"1.231893357","rc":[{"batb":[[0,1.5,19.3]],"batl":[[0,2.38,1.06],[1,2.4,1.52],[2,2.9,9]],"ltp":1.82,"tv":17.08,"id":31375}]}]}
{"op":"mcm","clk":"11934048339","pt":1724322781715,"mc":[{"id":"1.231893357","rc":[{"batb":[[1,1.72,3.05]],"ltp":3.5,"tv":4.89,"id":169}]}]}
{"op":"mcm","clk":"11934049583","pt":1724322806337,"mc":[{"id":"1.231893357","rc":[{"batl":[[1,2.9,9.76],[2,2.98,5]],"ltp":1.82,"tv":17.08,"id":31375}]}]}
{"op":"mcm","clk":"11934049686","pt":1724322808138,"mc":[{"id":"1.231893357","rc":[{"batl":[[1,2.9,9]],"ltp":1.82,"tv":17.08,"id":31375}]}]}
{"op":"mcm","clk":"11934050005","pt":1724322813264,"mc":[{"id":"1.231893357","rc":[{"batl":[[0,2.32,1.52],[1,2.9,9.3]],"ltp":1.82,"tv":17.08,"id":31375}]}]}
{"op":"mcm","clk":"11934050192","pt":1724322816854,"mc":[{"id":"1.231893357","rc":[{"batl":[[0,2.2,1.52],[1,2.38,1.06],[2,2.9,9]],"ltp":1.82,"tv":17.08,"id":31375}]}]}
{"op":"mcm","clk":"11934056074","pt":1724322937360,"mc":[{"id":"1.231893357","rc":[{"batb":[[0,3.6,10],[1,3.55,1.27],[2,3.05,1.64]],"ltp":6.0,"tv":6.05,"id":60443}]}]}
{"op":"mcm","clk":"11934057181","pt":1724322960199,"mc":[{"id":"1.231893357","rc":[{"batb":[[0,2.64,10],[1,2.62,1.33],[2,1.72,3.05]],"ltp":3.5,"tv":4.89,"id":169}]}]}
{"op":"mcm","clk":"11934063894","pt":1724323076792,"mc":[{"id":"1.231893357","rc":[{"batl":[[0,2.18,1.06],[1,2.32,1.52]],"ltp":1.82,"tv":17.08,"id":31375}]}]}
{"op":"mcm","clk":"11934071626","pt":1724323236691,"mc":[{"id":"1.231893357","rc":[{"batl":[[2,6,1]],"ltp":3.5,"tv":4.89,"id":169}]}]}
{"op":"mcm","clk":"11934077063","pt":1724323364823,"mc":[{"id":"1.231893357","rc":[{"batb":[[0,1.5,19]],"batl":[[0,2.2,1.52],[1,2.9,9.76],[2,2.98,5]],"ltp":1.82,"tv":17.08,"id":31375}]}]}
{"op":"mcm","clk":"11934077251","pt":1724323369020,"mc":[{"id":"1.231893357","rc":[{"batb":[[0,1.5,19.3]],"batl":[[0,2.16,1.06],[1,2.32,1.52],[2,2.9,9]],"ltp":1.82,"tv":17.08,"id":31375}]}]}
{"op":"mcm","clk":"11934091199","pt":1724323681948,"mc":[{"id":"1.231893357","rc":[{"batb":[[0,1.5,19.6]],"batl":[[0,2.14,1.06],[1,2.2,1.06],[2,2.9,9.76]],"ltp":1.82,"tv":17.08,"id":31375}]}]}
{"op":"mcm","clk":"11934091244","pt":1724323682741,"mc":[{"id":"1.231893357","rc":[{"batb":[[0,1.5,19.3]],"batl":[[1,2.32,1.52],[2,2.9,9]],"ltp":1.82,"tv":17.08,"id":31375}]}]}
{"op":"mcm","clk":"11934106566","pt":1724323986369,"mc":[{"id":"1.231893357","rc":[{"batb":[[0,1.5,19.6]],"batl":[[0,2.12,1.06],[1,2.2,1.06],[2,2.9,9.76]],"ltp":1.82,"tv":17.08,"id":31375}]}]}
{"op":"mcm","clk":"11934106802","pt":1724323990388,"mc":[{"id":"1.231893357","rc":[{"batb":[[0,1.5,19.3]],"batl":[[1,2.32,1.52],[2,2.9,9]],"ltp":1.82,"tv":17.08,"id":31375}]}]}
{"op":"mcm","clk":"11934109238","pt":1724324044344,"mc":[{"id":"1.231893357","rc":[{"batl":[[1,2.9,9.76],[2,2.98,5]],"ltp":1.82,"tv":17.08,"id":31375}]}]}
{"op":"mcm","clk":"11934109455","pt":1724324049457,"mc":[{"id":"1.231893357","rc":[{"batl":[[0,2.1,1.52],[1,2.32,1.06],[2,2.9,9]],"ltp":1.82,"tv":17.08,"id":31375}]}]}
{"op":"mcm","clk":"11934120000","pt":1724324292953,"mc":[{"id":"1.231893357","rc":[{"trd":[[4,1]],"batl":[[0,5,1],[1,6,1],[2,8,1]],"ltp":4.0,"tv":5.89,"id":169},{"trd":[[6,1],[7.8,0.32]],"batl":[[0,8,1.68],[1,10,1],[2,15,1.53]],"ltp":7.8,"tv":6.62,"id":60443},{"trd":[[1.5,40],[1.6,1.55],[1.65,0.6],[1.71,0.88]],"batb":[[0,1.16,18.29],[1,1.08,31.25],[2,1.07,35.71]],"batl":[[0,1.5,6.27],[1,2.1,1.52],[2,2.32,1.06]],"ltp":1.5,"tv":58.11,"id":31375}],"tv":70.63}]}
{"op":"mcm","clk":"11934120053","pt":1724324293940,"mc":[{"id":"1.231893357","rc":[{"batl":[[0,2.1,1.52],[1,2.32,1.06],[2,2.9,9]],"ltp":1.5,"tv":58.11,"id":31375}]}]}
{"op":"mcm","clk":"11934120195","pt":1724324296634,"mc":[{"id":"1.231893357","rc":[{"batb":[[0,1.16,18.59]],"batl":[[0,2.08,1.06],[1,2.12,1.06],[2,2.9,9.76]],"ltp":1.5,"tv":58.11,"id":31375}]}]}
{"op":"mcm","clk":"11934120254","pt":1724324297722,"mc":[{"id":"1.231893357","rc":[{"batb":[[0,2.66,4],[1,2.64,10],[2,2.62,1.33]],"ltp":4.0,"tv":5.89,"id":169},{"batb":[[0,3.65,4],[1,3.6,10],[2,3.55,1.27]],"ltp":7.8,"tv":6.62,"id":60443},{"batl":[[1,2.32,1.52],[2,2.9,9]],"ltp":1.5,"tv":58.11,"id":31375}]}]}
{"op":"mcm","clk":"11934120395","pt":1724324301018,"mc":[{"id":"1.231893357","rc":[{"batb":[[0,2.64,10],[1,2.62,1.33],[2,1.72,3.05]],"ltp":4.0,"tv":5.89,"id":169},{"batb":[[0,3.6,10],[1,3.55,1.27],[2,3.05,1.64]],"ltp":7.8,"tv":6.62,"id":60443}]}]}
{"op":"mcm","clk":"11934120489","pt":1724324302822,"mc":[{"id":"1.231893357","rc":[{"batb":[[0,2.82,1.42],[1,2.64,10],[2,2.62,1.33]],"ltp":4.0,"tv":5.89,"id":169}]}]}
{"op":"mcm","clk":"11934120519","pt":1724324303440,"mc":[{"id":"1.231893357","rc":[{"batl":[[2,2.98,5]],"ltp":1.5,"tv":58.11,"id":31375}]}]}
{"op":"mcm","clk":"11934120663","pt":1724324306633,"mc":[{"id":"1.231893357","rc":[{"batb":[[0,3.6,10.68]],"ltp":7.8,"tv":6.62,"id":60443}]}]}
{"op":"mcm","clk":"11934120721","pt":1724324307929,"mc":[{"id":"1.231893357","rc":[{"batl":[[0,5,1.3]],"ltp":4.0,"tv":5.89,"id":169},{"batb":[[0,3.65,4.68],[1,3.6,10],[2,3.55,1.69]],"ltp":7.8,"tv":6.62,"id":60443}]}]}
{"op":"mcm","clk":"11934120758","pt":1724324308552,"mc":[{"id":"1.231893357","rc":[{"batb":[[0,2.84,4],[1,2.82,1.42],[2,2.64,10]],"ltp":4.0,"tv":5.89,"id":169},{"batl":[[2,2.84,9]],"ltp":1.5,"tv":58.11,"id":31375}]}]}
{"op":"mcm","clk":"11934120833","pt":1724324309739,"mc":[{"id":"1.231893357","rc":[{"batb":[[0,3.6,10.68],[1,3.55,1.69],[2,3.05,1.64]],"ltp":7.8,"tv":6.62,"id":60443}]}]}
{"op":"mcm","clk":"11934120911","pt":1724324310838,"mc":[{"id":"1.231893357","rc":[{"batb":[[0,2.82,1.42],[1,2.64,10],[2,2.62,1.33]],"ltp":4.0,"tv":5.89,"id":169}]}]}
{"op":"mcm","clk":"11934121663","pt":1724324327154,"mc":[{"id":"1.231893357","rc":[{"batl":[[0,2,15.76],[1,2.1,1.06],[2,2.84,9.76]],"ltp":1.5,"tv":58.11,"id":31375}]}]}
{"op":"mcm","clk":"11934122020","pt":1724324335080,"mc":[{"id":"1.231893357","rc":[{"trd":[[4.9,0.3],[5,1]],"batl":[[0,6,1],[1,8,1],[2,9,7]],"ltp":5.0,"tv":7.19,"id":169},{"trd":[[7.8,1],[8,0.15]],"batl":[[0,10,1.85],[1,15,1.53],[2,21,1.01]],"ltp":8.0,"tv":7.45,"id":60443},{"trd":[[1.48,3.39],[1.49,0.99],[1.66,0.6]],"batb":[[0,1.16,18.29]],"batl":[[0,2,16.08]],"ltp":1.48,"tv":63.09,"id":31375}],"tv":77.74}]}
{"op":"mcm","clk":"11934122078","pt":1724324336059,"mc":[{"id":"1.231893357","rc":[{"batl":[[0,2,15.76]],"ltp":1.48,"tv":63.09,"id":31375}]}]}
{"op":"mcm","clk":"11934122284","pt":1724324340176,"mc":[{"id":"1.231893357","rc":[{"batb":[[0,2.84,4],[1,2.82,1.42],[2,2.64,10]],"ltp":5.0,"tv":7.19,"id":169},{"batb":[[0,3.65,4.68],[1,3.6,10],[2,3.55,1.69]],"ltp":8.0,"tv":7.45,"id":60443}]}]}
{"op":"mcm","clk":"11934122351","pt":1724324341473,"mc":[{"id":"1.231893357","rc":[{"batb":[[0,3.05,1.64],[1,2.84,4],[2,2.82,1.42]],"ltp":5.0,"tv":7.19,"id":169}]}]}
{"op":"mcm","clk":"11934122393","pt":1724324342464,"mc":[{"id":"1.231893357","rc":[{"batb":[[1,2.82,1.42],[2,2.64,10]],"ltp":5.0,"tv":7.19,"id":169},{"batb":[[0,3.6,10.68],[1,3.55,1.69],[2,3.05,1.64]],"ltp":8.0,"tv":7.45,"id":60443}]}]}
{"op":"mcm","clk":"11934122565","pt":1724324345597,"mc":[{"id":"1.231893357","rc":[{"batl":[[0,5.9,1],[1,6,1],[2,8,1]],"ltp":5.0,"tv":7.19,"id":169},{"batl":[[0,9.8,1.85],[1,10,1],[2,15,1.53]],"ltp":8.0,"tv":7.45,"id":60443}]}]}
{"op":"mcm","clk":"11934122852","pt":1724324351605,"mc":[{"id":"1.231893357","rc":[{"batl":[[0,6,1],[1,8,1],[2,9,7]],"ltp":5.0,"tv":7.19,"id":169},{"batl":[[0,9.8,2.15]],"ltp":8.0,"tv":7.45,"id":60443}]}]}
{"op":"mcm","clk":"11934123050","pt":1724324355482,"mc":[{"id":"1.231893357","rc":[{"batl":[[2,10,1]],"ltp":5.0,"tv":7.19,"id":169}]}]}
{"op":"mcm","clk":"11934124329","pt":1724324385019,"mc":[{"id":"1.231893357","rc":[{"batb":[[0,3.6,10.98]],"ltp":8.0,"tv":7.45,"id":60443}]}]}
{"op":"mcm","clk":"11934126004","pt":1724324416846,"mc":[{"id":"1.231893357","rc":[{"trd":[[6,0.83]],"batl":[[0,8,1.17],[1,10,1],[2,11,4]],"ltp":6.0,"tv":8.02,"id":169},{"trd":[[8,0.77]],"batl":[[0,9.8,1.53]],"ltp":8.0,"tv":8.07,"id":60443},{"trd":[[1.41,3.54],[1.82,8.02]],"batb":[[0,1.16,18.29]],"ltp":1.41,"tv":66.63,"id":31375}],"tv":82.73}]}
{"op":"mcm","clk":"11934126454","pt":1724324423466,"mc":[{"id":"1.231893357","rc":[{"batl":[[0,7.8,1.17],[1,8,1],[2,10,1]],"ltp":6.0,"tv":8.02,"id":169}]}]}
{"op":"mcm","clk":"11934126681","pt":1724324427361,"mc":[{"id":"1.231893357","rc":[{"batb":[[0,3.55,1.4],[1,3.05,1.64],[2,2.82,1.42]],"ltp":6.0,"tv":8.02,"id":169},{"batb":[[0,4.1,1.5],[1,3.6,10.98],[2,3.55,1.69]],"ltp":8.0,"tv":8.07,"id":60443}]}]}
{"op":"mcm","clk":"11934126820","pt":1724324429685,"mc":[{"id":"1.231893357","rc":[{"batb":[[1,3.6,10.3]],"ltp":8.0,"tv":8.07,"id":60443}]}]}
{"op":"mcm","clk":"11934127229","pt":1724324436787,"mc":[{"id":"1.231893357","rc":[{"batl":[[1,2.32,1.06],[2,2.84,9]],"ltp":1.41,"tv":66.63,"id":31375}]}]}
{"op":"mcm","clk":"11934127401","pt":1724324440171,"mc":[{"id":"1.231893357","rc":[{"batb":[[0,4.2,1.86],[1,4.1,1.5],[2,3.6,10.3]],"ltp":8.0,"tv":8.07,"id":60443}]}]}
{"op":"mcm","clk":"11934127474","pt":1724324441888,"mc":[{"id":"1.231893357","rc":[{"batl":[[0,2,16.52]],"ltp":1.41,"tv":66.63,"id":31375}]}]}
{"op":"mcm","clk":"11934134361","pt":1724324563001,"mc":[{"id":"1.231893357","rc":[{"batb":[[0,1.35,2.29],[1,1.16,18.29],[2,1.08,31.25]],"ltp":1.41,"tv":66.63,"id":31375}]}]}
{"op":"mcm","clk":"11934136186","pt":1724324596636,"mc":[{"id":"1.231893357","rc":[{"batl":[[0,1.99,1.06],[1,2,15.76],[2,2.84,9.76]],"ltp":1.41,"tv":66.63,"id":31375}]}]}
{"op":"mcm","clk":"11934136262","pt":1724324597944,"mc":[{"id":"1.231893357","rc":[{"batb":[[0,1.35,2.59]],"ltp":1.41,"tv":66.63,"id":31375}]}]}
{"op":"mcm","clk":"11934139962","pt":1724324659284,"mc":[{"id":"1.231893357","rc":[{"batl":[[0,9.8,1.23]],"ltp":8.0,"tv":8.07,"id":60443}]}]}
{"op":"mcm","clk":"11934141854","pt":1724324689620,"mc":[{"id":"1.231893357","rc":[{"batb":[[2,3.6,10]],"ltp":8.0,"tv":8.07,"id":60443}]}]}
{"op":"mcm","clk":"11934152246","pt":1724324896375,"mc":[{"id":"1.231893357","rc":[{"batb":[[0,1.35,2.89]],"batl":[[0,1.98,1.06],[1,2,16.06]],"ltp":1.41,"tv":66.63,"id":31375}]}]}
{"op":"mcm","clk":"11934152308","pt":1724324897558,"mc":[{"id":"1.231893357","rc":[{"batl":[[1,2,15.76]],"ltp":1.41,"tv":66.63,"id":31375}]}]}
{"op":"mcm","clk":"11934152408","pt":1724324899256,"mc":[{"id":"1.231893357","rc":[{"batb":[[0,1.35,2.59]],"ltp":1.41,"tv":66.63,"id":31375}]}]}
{"op":"mcm","clk":"11934162640","pt":1724325103671,"mc":[{"id":"1.231893357","rc":[{"batb":[[0,3.55,2.33]],"ltp":6.0,"tv":8.02,"id":169}]}]}
{"op":"mcm","clk":"11934163709","pt":1724325125717,"mc":[{"id":"1.231893357","rc":[{"batb":[[0,3.55,4.3]],"ltp":6.0,"tv":8.02,"id":169}]}]}
{"op":"mcm","clk":"11934164616","pt":1724325148709,"mc":[{"id":"1.231893357","rc":[{"trd":[[6,1]],"batl":[[0,7.8,1]],"ltp":6.0,"tv":8.19,"id":169},{"trd":[[8,0.9]],"batl":[[0,9.8,1.1]],"ltp":8.0,"tv":8.2,"id":60443},{"trd":[[1.41,4.27]],"batl":[[0,1.97,1.56],[1,2,16.06]],"ltp":1.41,"tv":67.36,"id":31375}],"tv":83.76}]}
{"op":"mcm","clk":"11934164731","pt":1724325152153,"mc":[{"id":"1.231893357","rc":[{"batl":[[0,1.98,1.06],[1,2,15.76]],"ltp":1.41,"tv":67.36,"id":31375}]}]}
