{"op":"mcm","clk":"11783707598","pt":1722931682791,"mc":[{"id":"1.231499799","marketDefinition":{"bspMarket":false,"turnInPlayEnabled":true,"persistenceEnabled":true,"marketBaseRate":5.0,"eventId":"33472077","eventTypeId":"4","numberOfWinners":1,"bettingType":"ODDS","marketType":"MATCH_ODDS","marketTime":"2024-08-08T09:00:00.000Z","suspendTime":"2024-08-08T09:00:00.000Z","bspReconciled":false,"complete":true,"inPlay":false,"crossMatching":false,"runnersVoidable":false,"numberOfActiveRunners":2,"betDelay":0,"status":"OPEN","runners":[{"status":"ACTIVE","sortPriority":1,"id":25686043,"name":"Netherlands Women"},{"status":"ACTIVE","sortPriority":2,"id":12482925,"name":"Scotland Women"}],"regulators":["MR_INT"],"countryCode":"GB","discountAllowed":false,"timezone":"GMT","openDate":"2024-08-08T09:00:00.000Z","version":6059436982,"name":"Match Odds","eventName":"Netherlands Women v Scotland Women"},"rc":[{"batb":[[0,1.03,200],[1,1.02,200],[2,1.01,220]],"ltp":0.0,"tv":0.0,"id":25686043},{"batb":[[0,1.03,200],[1,1.02,200],[2,1.01,220]],"ltp":0.0,"tv":0.0,"id":12482925}]}]}
{"op":"mcm","clk":"11783707633","pt":1722931684030,"mc":[{"id":"1.231499799","marketDefinition":{"bspMarket":false,"turnInPlayEnabled":true,"persistenceEnabled":true,"marketBaseRate":5.0,"eventId":"33472077","eventTypeId":"4","numberOfWinners":1,"bettingType":"ODDS","marketType":"MATCH_ODDS","marketTime":"2024-08-08T09:00:00.000Z","suspendTime":"2024-08-08T09:00:00.000Z","bspReconciled":false,"complete":true,"inPlay":false,"crossMatching":false,"runnersVoidable":false,"numberOfActiveRunners":2,"betDelay":0,"status":"OPEN","runners":[{"status":"ACTIVE","sortPriority":1,"id":25686043,"name":"Netherlands Women"},{"status":"ACTIVE","sortPriority":2,"id":12482925,"name":"Scotland Women"}],"regulators":["MR_INT"],"countryCode":"GB","discountAllowed":true,"timezone":"GMT","openDate":"2024-08-08T09:00:00.000Z","version":6059436982,"name":"Match Odds","eventName":"Netherlands Women v Scotland Women"}}]}
{"op":"mcm","clk":"11783709852","pt":1722931768027,"mc":[{"id":"1.231499799","rc":[{"batb":[[0,1.04,1635.23],[1,1.03,2364.29],[2,1.02,3395.85]],"ltp":0.0,"tv":0.0,"id":25686043},{"batb":[[0,1.03,2364.29],[1,1.02,3395.85],[2,1.01,6423.91]],"ltp":0.0,"tv":0.0,"id":12482925}]}]}
{"op":"mcm","clk":"11783709858","pt":1722931768235,"mc":[{"id":"1.231499799","rc":[{"batb":[[0,1.04,1635.23],[1,1.03,2364.29],[2,1.02,3395.85]],"ltp":0.0,"tv":0.0,"id":12482925}]}]}
{"op":"mcm","clk":"11783719065","pt":1722932066829,"mc":[{"id":"1.231499799","rc":[{"batb":[[0,1.1,100],[1,1.04,1635.23],[2,1.03,2364.29]],"ltp":0.0,"tv":0.0,"id":25686043},{"batb":[[0,1.1,100],[1,1.04,1635.23],[2,1.03,2364.29]],"ltp":0.0,"tv":0.0,"id":12482925}]}]}
{"op":"mcm","clk":"11783719337","pt":1722932075677,"mc":[{"id":"1.231499799","marketDefinition":{"bspMarket":false,"turnInPlayEnabled":true,"persistenceEnabled":true,"marketBaseRate":5.0,"eventId":"33472077","eventTypeId":"4","numberOfWinners":1,"bettingType":"ODDS","marketType":"MATCH_ODDS","marketTime":"2024-08-08T09:00:00.000Z","suspendTime":"2024-08-08T09:00:00.000Z","bspReconciled":false,"complete":true,"inPlay":false,"crossMatching":true,"runnersVoidable":false,"numberOfActiveRunners":2,"betDelay":0,"status":"OPEN","runners":[{"status":"ACTIVE","sortPriority":1,"id":25686043,"name":"Netherlands Women"},{"status":"ACTIVE","sortPriority":2,"id":12482925,"name":"Scotland Women"}],"regulators":["MR_INT"],"countryCode":"GB","discountAllowed":true,"timezone":"GMT","openDate":"2024-08-08T09:00:00.000Z","version":6059436982,"name":"Match Odds","eventName":"Netherlands Women v Scotland Women"},"rc":[{"batl":[[0,11,10]],"ltp":0.0,"tv":0.0,"id":25686043},{"batl":[[0,11,10]],"ltp":0.0,"tv":0.0,"id":12482925}]}]}
{"op":"mcm","clk":"11783738386","pt":1722932789798,"mc":[{"id":"1.231499799","rc":[{"batb":[[1,1.05,100],[2,1.04,1635.23]],"ltp":0.0,"tv":0.0,"id":25686043},{"batb":[[0,1.11,20],[1,1.1,100],[2,1.04,1635.23]],"ltp":0.0,"tv":0.0,"id":12482925}]}]}
{"op":"mcm","clk":"11783738724","pt":1722932804625,"mc":[{"id":"1.231499799","rc":[{"batb":[[0,1.11,5],[1,1.1,100],[2,1.05,100]],"ltp":0.0,"tv":0.0,"id":25686043}]}]}
{"op":"mcm","clk":"11783795018","pt":1722934648559,"mc":[{"id":"1.231499799","rc":[{"batb":[[2,1.05,100]],"ltp":0.0,"tv":0.0,"id":12482925}]}]}
{"op":"mcm","clk":"11783866237","pt":1722936781663,"mc":[{"id":"1.231499799","rc":[{"batb":[[1,1.05,100],[2,1.04,1636.77]],"ltp":0.0,"tv":0.0,"id":25686043},{"batb":[[1,1.05,100],[2,1.04,1636.77]],"ltp":0.0,"tv":0.0,"id":12482925}]}]}
{"op":"mcm","clk":"11783887247","pt":1722937320238,"mc":[{"id":"1.231499799","rc":[{"batb":[[0,1.25,100],[1,1.11,5],[2,1.05,100]],"ltp":0.0,"tv":0.0,"id":25686043},{"batb":[[0,1.25,100],[1,1.11,20],[2,1.05,100]],"ltp":0.0,"tv":0.0,"id":12482925}]}]}
{"op":"mcm","clk":"11783892306","pt":1722937437119,"mc":[{"id":"1.231499799","rc":[{"batb":[[0,1.26,10],[1,1.25,100],[2,1.11,20]],"ltp":0.0,"tv":0.0,"id":12482925}]}]}
{"op":"mcm","clk":"11784237746","pt":1722945125635,"mc":[{"id":"1.231499799","rc":[{"batb":[[2,1.05,100.79]],"ltp":0.0,"tv":0.0,"id":25686043}]}]}
{"op":"mcm","clk":"11784843438","pt":1722955375043,"mc":[{"id":"1.231499799","rc":[{"batb":[[2,1.05,100.79]],"ltp":0.0,"tv":0.0,"id":25686043}]}]}
{"op":"mcm","clk":"11785415965","pt":1722960894030,"mc":[{"id":"1.231499799","rc":[{"batb":[[0,1.26,33.27],[1,1.25,100],[2,1.11,5]],"ltp":0.0,"tv":0.0,"id":25686043},{"batb":[[0,1.27,32.04],[1,1.26,10],[2,1.25,100]],"ltp":0.0,"tv":0.0,"id":12482925}]}]}
{"op":"mcm","clk":"11785465427","pt":1722961339959,"mc":[{"id":"1.231499799","rc":[{"batb":[[1,1.25,100],[2,1.11,20]],"ltp":0.0,"tv":0.0,"id":12482925}]}]}
{"op":"mcm","clk":"11785465438","pt":1722961340062,"mc":[{"id":"1.231499799","rc":[{"batb":[[0,1.28,10],[1,1.27,32.04],[2,1.25,100]],"ltp":0.0,"tv":0.0,"id":12482925}]}]}
{"op":"mcm","clk":"11785608726","pt":1722962539018,"mc":[{"id":"1.231499799","rc":[{"batb":[[0,1.27,7.38],[1,1.26,33.27],[2,1.25,100]],"ltp":0.0,"tv":0.0,"id":25686043}]}]}
{"op":"mcm","clk":"11785608768","pt":1722962539316,"mc":[{"id":"1.231499799","rc":[{"batb":[[0,1.28,16.32]],"ltp":0.0,"tv":0.0,"id":12482925}]}]}
{"op":"mcm","clk":"11785627306","pt":1722962694403,"mc":[{"id":"1.231499799","rc":[{"batb":[[1,1.25,100],[2,1.11,5]],"ltp":0.0,"tv":0.0,"id":25686043},{"batb":[[1,1.25,100],[2,1.11,20]],"ltp":0.0,"tv":0.0,"id":12482925}]}]}
{"op":"mcm","clk":"11785635631","pt":1722962756216,"mc":[{"id":"1.231499799","rc":[{"batb":[[0,1.28,30.9],[1,1.27,7.38],[2,1.25,100]],"ltp":0.0,"tv":0.0,"id":25686043},{"batb":[[0,1.29,29.83],[1,1.28,16.32],[2,1.25,100]],"ltp":0.0,"tv":0.0,"id":12482925}]}]}
{"op":"mcm","clk":"11785675245","pt":1722963098545,"mc":[{"id":"1.231499799","rc":[{"batb":[[0,1.98,38.59],[1,1.28,30.9],[2,1.27,7.38]],"ltp":0.0,"tv":0.0,"id":25686043},{"batb":[[0,1.95,39.81],[1,1.29,29.83],[2,1.28,16.32]],"ltp":0.0,"tv":0.0,"id":12482925}]}]}
{"op":"mcm","clk":"11785796448","pt":1722964200016,"mc":[{"id":"1.231499799","rc":[{"batb":[[1,1.28,30.87],[2,1.25,100]],"ltp":0.0,"tv":0.0,"id":25686043},{"batb":[[1,1.29,29.81],[2,1.28,10]],"ltp":0.0,"tv":0.0,"id":12482925}]}]}
{"op":"mcm","clk":"11785842782","pt":1722964557005,"mc":[{"id":"1.231499799","rc":[{"batb":[[1,1.25,100],[2,1.11,5]],"ltp":0.0,"tv":0.0,"id":25686043},{"batb":[[1,1.28,10],[2,1.25,100]],"ltp":0.0,"tv":0.0,"id":12482925}]}]}
{"op":"mcm","clk":"11785918493","pt":1722965166905,"mc":[{"id":"1.231499799","rc":[{"trd":[[1.98,0.4]],"ltp":1.98,"tv":0.4,"id":25686043}],"tv":0.4}]}
{"op":"mcm","clk":"11785969028","pt":1722965533625,"mc":[{"id":"1.231499799","rc":[{"trd":[[1.98,3.76]],"batb":[[0,1.98,36.91]],"ltp":1.98,"tv":3.76,"id":25686043}],"tv":3.76}]}
{"op":"mcm","clk":"11785969757","pt":1722965538438,"mc":[{"id":"1.231499799","rc":[{"batb":[[0,1.98,38.59]],"ltp":1.98,"tv":3.76,"id":25686043}]}]}
{"op":"mcm","clk":"11786001158","pt":1722965755822,"mc":[{"id":"1.231499799","rc":[{"trd":[[1.95,4.04]],"batb":[[0,1.95,37.79]],"ltp":1.95,"tv":4.03,"id":12482925}],"tv":7.8}]}
{"op":"mcm","clk":"11786001638","pt":1722965759321,"mc":[{"id":"1.231499799","rc":[{"batb":[[0,1.95,39.81]],"ltp":1.95,"tv":4.03,"id":12482925}]}]}
{"op":"mcm","clk":"11786823607","pt":1722971574994,"mc":[{"id":"1.231499799","rc":[{"trd":[[1.98,3.77]],"ltp":1.98,"tv":3.76,"id":25686043},{"trd":[[1.95,4.04]],"ltp":1.95,"tv":4.04,"id":12482925}],"tv":7.8}]}
{"op":"mcm","clk":"11787288130","pt":1722976975016,"mc":[{"id":"1.231499799","rc":[{"trd":[[1.95,4.04]],"ltp":1.95,"tv":4.04,"id":12482925}],"tv":7.8}]}
{"op":"mcm","clk":"11788111897","pt":1722993175108,"mc":[{"id":"1.231499799","rc":[{"trd":[[1.98,3.77]],"ltp":1.98,"tv":3.76,"id":25686043},{"trd":[[1.95,4.04]],"ltp":1.95,"tv":4.03,"id":12482925}],"tv":7.8}]}
{"op":"mcm","clk":"11788633808","pt":1723003975079,"mc":[{"id":"1.231499799","rc":[{"trd":[[1.98,3.76]],"ltp":1.98,"tv":3.76,"id":25686043},{"trd":[[1.95,4.04]],"ltp":1.95,"tv":4.03,"id":12482925}],"tv":7.8}]}
{"op":"mcm","clk":"11788830736","pt":1723009375042,"mc":[{"id":"1.231499799","rc":[{"trd":[[1.98,3.76]],"ltp":1.98,"tv":3.76,"id":25686043},{"trd":[[1.95,4.04]],"ltp":1.95,"tv":4.03,"id":12482925}],"tv":7.8}]}
{"op":"mcm","clk":"11788962981","pt":1723012906217,"mc":[{"id":"1.231499799","rc":[{"batb":[[2,1.04,1639.33]],"ltp":1.98,"tv":3.76,"id":25686043},{"batb":[[1,1.25,100],[2,1.04,1639.33]],"ltp":1.95,"tv":4.03,"id":12482925}],"tv":7.8}]}
{"op":"mcm","clk":"11788991793","pt":1723013771755,"mc":[{"id":"1.231499799","rc":[{"batb":[[1,1.74,17.32],[2,1.25,100]],"ltp":1.98,"tv":3.76,"id":25686043},{"batb":[[1,1.74,17.32],[2,1.25,100]],"ltp":1.95,"tv":4.03,"id":12482925}]}]}
{"op":"mcm","clk":"11789008115","pt":1723014233022,"mc":[{"id":"1.231499799","rc":[{"trd":[[1.98,3.76]],"ltp":1.98,"tv":3.76,"id":25686043},{"trd":[[1.95,4.04]],"batl":[[0,2.2,1]],"ltp":1.95,"tv":4.03,"id":12482925}],"tv":7.8}]}
{"op":"mcm","clk":"11789074892","pt":1723015639070,"mc":[{"id":"1.231499799","rc":[{"batl":[[0,2.3,1]],"ltp":1.95,"tv":4.03,"id":12482925}]}]}
{"op":"mcm","clk":"11789139979","pt":1723017093656,"mc":[{"id":"1.231499799","rc":[{"trd":[[1.95,6.04]],"batb":[[0,1.95,38.81]],"ltp":1.95,"tv":6.03,"id":12482925}],"tv":9.8}]}
{"op":"mcm","clk":"11789140106","pt":1723017096227,"mc":[{"id":"1.231499799","rc":[{"batb":[[0,1.95,39.81]],"ltp":1.95,"tv":6.03,"id":12482925}]}]}
{"op":"mcm","clk":"11789245632","pt":1723019041227,"mc":[{"id":"1.231499799","rc":[{"trd":[[1.98,3.77]],"ltp":1.98,"tv":3.76,"id":25686043},{"trd":[[1.95,6.04]],"batl":[[0,2,1]],"ltp":1.95,"tv":6.04,"id":12482925}],"tv":9.8}]}
{"op":"mcm","clk":"11789251673","pt":1723019161583,"mc":[{"id":"1.231499799","rc":[{"batl":[[0,2.2,1]],"ltp":1.95,"tv":6.04,"id":12482925}]}]}
{"op":"mcm","clk":"11789260428","pt":1723019334758,"mc":[{"id":"1.231499799","rc":[{"trd":[[1.95,8.04]],"ltp":1.95,"tv":8.04,"id":12482925}],"tv":11.8}]}
{"op":"mcm","clk":"11789276672","pt":1723019621982,"mc":[{"id":"1.231499799","rc":[{"batl":[[0,2.5,1]],"ltp":1.95,"tv":8.04,"id":12482925}]}]}
{"op":"mcm","clk":"11789280467","pt":1723019683537,"mc":[{"id":"1.231499799","rc":[{"trd":[[1.95,10.04]],"batb":[[0,1.95,38.81]],"ltp":1.95,"tv":10.04,"id":12482925}],"tv":13.8}]}
{"op":"mcm","clk":"11789280624","pt":1723019686178,"mc":[{"id":"1.231499799","rc":[{"batb":[[0,1.95,39.81]],"ltp":1.95,"tv":10.04,"id":12482925}]}]}
{"op":"mcm","clk":"11789356099","pt":1723021023751,"mc":[{"id":"1.231499799","rc":[{"batl":[[0,2.5,1]],"ltp":1.95,"tv":10.04,"id":12482925}]}]}
{"op":"mcm","clk":"11789363779","pt":1723021197583,"mc":[{"id":"1.231499799","rc":[{"trd":[[1.95,12.04]],"batb":[[0,1.95,38.81]],"ltp":1.95,"tv":12.04,"id":12482925}],"tv":15.8}]}
{"op":"mcm","clk":"11789364086","pt":1723021202448,"mc":[{"id":"1.231499799","rc":[{"batb":[[0,1.95,39.81]],"ltp":1.95,"tv":12.04,"id":12482925}]}]}
{"op":"mcm","clk":"11789402911","pt":1723021816703,"mc":[{"id":"1.231499799","rc":[{"trd":[[1.98,3.77]],"ltp":1.98,"tv":3.76,"id":25686043},{"trd":[[1.95,12.04]],"batl":[[0,2.5,1]],"ltp":1.95,"tv":12.03,"id":12482925}],"tv":15.8}]}
{"op":"mcm","clk":"11789406745","pt":1723021861824,"mc":[{"id":"1.231499799","rc":[{"trd":[[1.95,14.04]],"batb":[[0,1.95,38.81]],"ltp":1.95,"tv":14.03,"id":12482925}],"tv":17.8}]}
{"op":"mcm","clk":"11789407133","pt":1723021866537,"mc":[{"id":"1.231499799","rc":[{"batb":[[0,1.95,39.81]],"ltp":1.95,"tv":14.03,"id":12482925}]}]}
{"op":"mcm","clk":"11789481695","pt":1723022971926,"mc":[{"id":"1.231499799","rc":[{"batl":[[0,2.3,1]],"ltp":1.95,"tv":14.03,"id":12482925}]}]}
{"op":"mcm","clk":"11789669419","pt":1723025575015,"mc":[{"id":"1.231499799","rc":[{"trd":[[1.98,3.76]],"ltp":1.98,"tv":3.76,"id":25686043},{"trd":[[1.95,14.04]],"ltp":1.95,"tv":14.03,"id":12482925}],"tv":17.8}]}
{"op":"mcm","clk":"11790075559","pt":1723030975024,"mc":[{"id":"1.231499799","tv":17.8}]}
{"op":"mcm","clk":"11790089880","pt":1723031178775,"mc":[{"id":"1.231499799","rc":[{"batl":[[0,2.02,2],[1,2.3,1]],"ltp":1.95,"tv":14.03,"id":12482925}]}]}
{"op":"mcm","clk":"11790407214","pt":1723036375027,"mc":[{"id":"1.231499799","rc":[{"trd":[[1.98,3.76]],"ltp":1.98,"tv":3.76,"id":25686043},{"trd":[[1.95,14.04]],"ltp":1.95,"tv":14.03,"id":12482925}],"tv":17.79}]}
{"op":"mcm","clk":"11790645317","pt":1723040507798,"mc":[{"id":"1.231499799","rc":[{"batb":[[0,1.98,45.31]],"ltp":1.98,"tv":3.76,"id":25686043},{"batb":[[0,1.95,46.74]],"ltp":1.95,"tv":14.03,"id":12482925}],"tv":17.79}]}
{"op":"mcm","clk":"11790717198","pt":1723041476845,"mc":[{"id":"1.231499799","rc":[{"trd":[[1.95,107.04]],"batb":[[0,1.74,17.56],[1,1.25,100],[2,1.04,1638.76]],"ltp":1.95,"tv":107.03,"id":12482925}],"tv":110.79}]}
{"op":"mcm","clk":"11790717212","pt":1723041477048,"mc":[{"id":"1.231499799","rc":[{"batb":[[0,1.75,10.24],[1,1.74,101.32],[2,1.25,100]],"ltp":1.95,"tv":107.03,"id":12482925}]}]}
{"op":"mcm","clk":"11790717443","pt":1723041480261,"mc":[{"id":"1.231499799","rc":[{"batb":[[0,1.74,101.56],[1,1.25,100],[2,1.04,1638.76]],"ltp":1.95,"tv":107.03,"id":12482925}]}]}
{"op":"mcm","clk":"11790717587","pt":1723041481965,"mc":[{"id":"1.231499799","rc":[{"batb":[[0,1.91,48.8],[1,1.74,101.32],[2,1.25,100]],"ltp":1.95,"tv":107.03,"id":12482925}]}]}
{"op":"mcm","clk":"11790718290","pt":1723041490868,"mc":[{"id":"1.231499799","rc":[{"batb":[[0,1.92,10],[1,1.91,48.8],[2,1.74,17.32]],"ltp":1.95,"tv":107.03,"id":12482925}]}]}
{"op":"mcm","clk":"11790718532","pt":1723041494199,"mc":[{"id":"1.231499799","rc":[{"batb":[[0,1.91,48.8],[1,1.74,17.32],[2,1.25,100]],"ltp":1.95,"tv":107.03,"id":12482925}]}]}
{"op":"mcm","clk":"11790727128","pt":1723041597095,"mc":[{"id":"1.231499799","rc":[{"batb":[[0,1.92,10],[1,1.91,48.8],[2,1.74,17.32]],"ltp":1.95,"tv":107.03,"id":12482925}]}]}
{"op":"mcm","clk":"11790727419","pt":1723041600514,"mc":[{"id":"1.231499799","rc":[{"batb":[[0,1.91,48.8],[1,1.74,17.32],[2,1.25,100]],"ltp":1.95,"tv":107.03,"id":12482925}]}]}
{"op":"mcm","clk":"11790776961","pt":1723042054215,"mc":[{"id":"1.231499799","rc":[{"batb":[[0,1.92,10],[1,1.91,48.8],[2,1.74,17.32]],"ltp":1.95,"tv":107.03,"id":12482925}]}]}
{"op":"mcm","clk":"11790777260","pt":1723042057507,"mc":[{"id":"1.231499799","rc":[{"batb":[[0,1.91,48.8],[1,1.74,17.32],[2,1.25,100]],"ltp":1.95,"tv":107.03,"id":12482925}]}]}
{"op":"mcm","clk":"11790797377","pt":1723042280623,"mc":[{"id":"1.231499799","rc":[{"batl":[[0,1.99,2]],"ltp":1.98,"tv":3.76,"id":25686043},{"batb":[[0,1.92,10],[1,1.91,48.8],[2,1.74,17.32]],"ltp":1.95,"tv":107.03,"id":12482925}]}]}
{"op":"mcm","clk":"11790797639","pt":1723042283841,"mc":[{"id":"1.231499799","rc":[{"batb":[[0,1.91,48.8],[1,1.74,17.32],[2,1.25,100]],"ltp":1.95,"tv":107.03,"id":12482925}]}]}
{"op":"mcm","clk":"11790798683","pt":1723042296554,"mc":[{"id":"1.231499799","rc":[{"trd":[[1.98,7.76]],"batb":[[0,1.98,43.31]],"ltp":1.98,"tv":7.76,"id":25686043},{"batb":[[0,1.92,10],[1,1.91,48.8],[2,1.74,17.32]],"ltp":1.95,"tv":107.03,"id":12482925}],"tv":114.79}]}
{"op":"mcm","clk":"11790798958","pt":1723042299957,"mc":[{"id":"1.231499799","rc":[{"batb":[[0,1.91,48.8],[1,1.74,17.32],[2,1.25,100]],"ltp":1.95,"tv":107.03,"id":12482925}]}]}
{"op":"mcm","clk":"11790799056","pt":1723042301357,"mc":[{"id":"1.231499799","rc":[{"batb":[[0,1.98,45.31]],"ltp":1.98,"tv":7.76,"id":25686043}]}]}
{"op":"mcm","clk":"11790803669","pt":1723042357518,"mc":[{"id":"1.231499799","rc":[{"batb":[[0,1.92,10],[1,1.91,48.8],[2,1.74,17.32]],"ltp":1.95,"tv":107.03,"id":12482925}]}]}
{"op":"mcm","clk":"11790804002","pt":1723042358801,"mc":[{"id":"1.231499799","rc":[{"batb":[[0,1.91,48.8],[1,1.74,17.32],[2,1.25,100]],"ltp":1.95,"tv":107.03,"id":12482925}]}]}
{"op":"mcm","clk":"11790855975","pt":1723042937366,"mc":[{"id":"1.231499799","rc":[{"trd":[[1.98,7.76]],"ltp":1.98,"tv":7.76,"id":25686043},{"trd":[[1.95,107.04]],"batb":[[0,1.92,10],[1,1.91,48.8],[2,1.74,17.32]],"ltp":1.95,"tv":107.03,"id":12482925}],"tv":114.79}]}
{"op":"mcm","clk":"11790856338","pt":1723042940891,"mc":[{"id":"1.231499799","rc":[{"batb":[[0,1.91,48.8],[1,1.74,17.32],[2,1.25,100]],"ltp":1.95,"tv":107.03,"id":12482925}]}]}
{"op":"mcm","clk":"11790903743","pt":1723043394405,"mc":[{"id":"1.231499799","rc":[{"batb":[[0,1.92,10],[1,1.91,48.8],[2,1.74,17.32]],"ltp":1.95,"tv":107.03,"id":12482925}]}]}
{"op":"mcm","clk":"11790904138","pt":1723043398153,"mc":[{"id":"1.231499799","rc":[{"batb":[[0,1.91,48.8],[1,1.74,17.32],[2,1.25,100]],"ltp":1.95,"tv":107.03,"id":12482925}]}]}
{"op":"mcm","clk":"11790941501","pt":1723043776200,"mc":[{"id":"1.231499799","rc":[{"batb":[[0,1.92,10],[1,1.91,48.8],[2,1.74,17.32]],"ltp":1.95,"tv":107.03,"id":12482925}]}]}
{"op":"mcm","clk":"11790941940","pt":1723043779690,"mc":[{"id":"1.231499799","rc":[{"batb":[[0,1.91,48.8],[1,1.74,17.32],[2,1.25,100]],"ltp":1.95,"tv":107.03,"id":12482925}]}]}
{"op":"mcm","clk":"11790981464","pt":1723044165550,"mc":[{"id":"1.231499799","rc":[{"batb":[[0,1.92,10],[1,1.91,48.8],[2,1.74,17.32]],"ltp":1.95,"tv":107.03,"id":12482925}]}]}
{"op":"mcm","clk":"11790981783","pt":1723044168927,"mc":[{"id":"1.231499799","rc":[{"batb":[[0,1.91,48.8],[1,1.74,17.32],[2,1.25,100]],"ltp":1.95,"tv":107.03,"id":12482925}]}]}
{"op":"mcm","clk":"11791024837","pt":1723044646969,"mc":[{"id":"1.231499799","rc":[{"batb":[[0,1.92,10],[1,1.91,48.8],[2,1.74,17.32]],"ltp":1.95,"tv":107.03,"id":12482925}]}]}
{"op":"mcm","clk":"11791025180","pt":1723044650551,"mc":[{"id":"1.231499799","rc":[{"batb":[[0,1.91,48.8],[1,1.74,17.32],[2,1.25,100]],"ltp":1.95,"tv":107.03,"id":12482925}]}]}
{"op":"mcm","clk":"11791076257","pt":1723045165679,"mc":[{"id":"1.231499799","rc":[{"batb":[[0,1.92,10],[1,1.91,48.8],[2,1.74,17.32]],"ltp":1.95,"tv":107.03,"id":12482925}]}]}
{"op":"mcm","clk":"11791076639","pt":1723045169120,"mc":[{"id":"1.231499799","rc":[{"batb":[[0,1.91,48.8],[1,1.74,17.32],[2,1.25,100]],"ltp":1.95,"tv":107.03,"id":12482925}]}]}
{"op":"mcm","clk":"11791130609","pt":1723045701516,"mc":[{"id":"1.231499799","rc":[{"batb":[[0,1.92,10],[1,1.91,48.8],[2,1.74,17.32]],"ltp":1.95,"tv":107.03,"id":12482925}]}]}
{"op":"mcm","clk":"11791130888","pt":1723045705139,"mc":[{"id":"1.231499799","rc":[{"batb":[[0,1.91,48.8],[1,1.74,17.32],[2,1.25,100]],"ltp":1.95,"tv":107.03,"id":12482925}]}]}
{"op":"mcm","clk":"11791146681","pt":1723045893890,"mc":[{"id":"1.231499799","rc":[{"batb":[[0,1.98,46.29]],"ltp":1.98,"tv":7.76,"id":25686043}]}]}
{"op":"mcm","clk":"11791147561","pt":1723045903293,"mc":[{"id":"1.231499799","rc":[{"batb":[[0,1.98,45.31]],"ltp":1.98,"tv":7.76,"id":25686043}]}]}
{"op":"mcm","clk":"11791204155","pt":1723046521257,"mc":[{"id":"1.231499799","rc":[{"trd":[[1.98,7.76]],"ltp":1.98,"tv":7.76,"id":25686043},{"trd":[[1.91,0.02],[1.95,107.04]],"batb":[[0,1.92,10],[1,1.91,48.79],[2,1.74,17.32]],"ltp":1.91,"tv":107.05,"id":12482925}],"tv":114.81}]}
{"op":"mcm","clk":"11791204469","pt":1723046524558,"mc":[{"id":"1.231499799","rc":[{"batb":[[0,1.91,48.79],[1,1.74,17.32],[2,1.25,100]],"ltp":1.91,"tv":107.05,"id":12482925}]}]}
{"op":"mcm","clk":"11791204521","pt":1723046525115,"mc":[{"id":"1.231499799","rc":[{"batb":[[0,1.91,48.8]],"ltp":1.91,"tv":107.05,"id":12482925}]}]}
{"op":"mcm","clk":"11791227791","pt":1723046804741,"mc":[{"id":"1.231499799","rc":[{"batb":[[2,1.04,1639.89]],"ltp":1.98,"tv":7.76,"id":25686043},{"batb":[[0,1.92,10],[1,1.91,48.8],[2,1.74,17.32]],"ltp":1.91,"tv":107.05,"id":12482925}]}]}
{"op":"mcm","clk":"11791228034","pt":1723046808057,"mc":[{"id":"1.231499799","rc":[{"batb":[[0,1.91,48.8],[1,1.74,17.32],[2,1.04,1639.89]],"ltp":1.91,"tv":107.05,"id":12482925}]}]}
{"op":"mcm","clk":"11791231131","pt":1723046842557,"mc":[{"id":"1.231499799","rc":[{"batb":[[2,1.06,166.67]],"ltp":1.98,"tv":7.76,"id":25686043},{"batb":[[0,1.92,10],[1,1.91,48.8],[2,1.74,17.32]],"ltp":1.91,"tv":107.05,"id":12482925}]}]}
{"op":"mcm","clk":"11791231389","pt":1723046845473,"mc":[{"id":"1.231499799","rc":[{"batb":[[0,1.91,48.8],[1,1.74,17.32],[2,1.06,166.67]],"ltp":1.91,"tv":107.05,"id":12482925}]}]}
{"op":"mcm","clk":"11791234347","pt":1723046881704,"mc":[{"id":"1.231499799","rc":[{"batb":[[0,1.92,10],[1,1.91,48.8],[2,1.74,17.32]],"ltp":1.91,"tv":107.05,"id":12482925}]}]}
{"op":"mcm","clk":"11791234641","pt":1723046885224,"mc":[{"id":"1.231499799","rc":[{"batb":[[0,1.91,48.8],[1,1.74,17.32],[2,1.06,166.67]],"ltp":1.91,"tv":107.05,"id":12482925}]}]}
{"op":"mcm","clk":"11791235127","pt":1723046891005,"mc":[{"id":"1.231499799","rc":[{"batb":[[2,1.48,104.17]],"ltp":1.98,"tv":7.76,"id":25686043},{"batb":[[0,1.92,10],[1,1.91,48.8],[2,1.74,17.32]],"ltp":1.91,"tv":107.05,"id":12482925}]}]}
{"op":"mcm","clk":"11791235152","pt":1723046891210,"mc":[{"id":"1.231499799","rc":[{"batb":[[2,1.53,94.34]],"ltp":1.98,"tv":7.76,"id":25686043}]}]}
{"op":"mcm","clk":"11791235404","pt":1723046894019,"mc":[{"id":"1.231499799","rc":[{"batb":[[0,1.91,48.8],[1,1.74,17.32],[2,1.53,94.34]],"ltp":1.91,"tv":107.05,"id":12482925}]}]}
{"op":"mcm","clk":"11791273715","pt":1723047206863,"mc":[{"id":"1.231499799","rc":[{"batb":[[0,1.92,10],[1,1.91,48.8],[2,1.74,17.32]],"ltp":1.91,"tv":107.05,"id":12482925}]}]}
{"op":"mcm","clk":"11791274010","pt":1723047210163,"mc":[{"id":"1.231499799","rc":[{"batb":[[0,1.91,48.8],[1,1.74,17.32],[2,1.53,94.34]],"ltp":1.91,"tv":107.05,"id":12482925}]}]}
{"op":"mcm","clk":"11791287384","pt":1723047336803,"mc":[{"id":"1.231499799","rc":[{"batb":[[0,1.92,10],[1,1.91,48.8],[2,1.74,17.32]],"ltp":1.91,"tv":107.05,"id":12482925}]}]}
{"op":"mcm","clk":"11791287708","pt":1723047340037,"mc":[{"id":"1.231499799","rc":[{"batb":[[0,1.91,48.8],[1,1.74,17.32],[2,1.53,94.34]],"ltp":1.91,"tv":107.05,"id":12482925}]}]}
{"op":"mcm","clk":"11791297983","pt":1723047429840,"mc":[{"id":"1.231499799","rc":[{"batb":[[0,1.92,10],[1,1.91,48.8],[2,1.74,17.32]],"ltp":1.91,"tv":107.05,"id":12482925}]}]}
{"op":"mcm","clk":"11791298363","pt":1723047433435,"mc":[{"id":"1.231499799","rc":[{"batb":[[0,1.91,48.8],[1,1.74,17.32],[2,1.53,94.34]],"ltp":1.91,"tv":107.05,"id":12482925}]}]}
{"op":"mcm","clk":"11791314655","pt":1723047585774,"mc":[{"id":"1.231499799","rc":[{"batb":[[0,1.92,10],[1,1.91,48.8],[2,1.74,17.32]],"ltp":1.91,"tv":107.05,"id":12482925}]}]}
{"op":"mcm","clk":"11791315031","pt":1723047588930,"mc":[{"id":"1.231499799","rc":[{"batb":[[0,1.91,48.8],[1,1.74,17.32],[2,1.53,94.34]],"ltp":1.91,"tv":107.05,"id":12482925}]}]}
{"op":"mcm","clk":"11791338261","pt":1723047817529,"mc":[{"id":"1.231499799","rc":[{"batb":[[0,1.92,10],[1,1.91,48.8],[2,1.74,17.32]],"ltp":1.91,"tv":107.05,"id":12482925}]}]}
{"op":"mcm","clk":"11791338578","pt":1723047820454,"mc":[{"id":"1.231499799","rc":[{"batb":[[0,1.91,48.8],[1,1.74,17.32],[2,1.53,94.34]],"ltp":1.91,"tv":107.05,"id":12482925}]}]}
{"op":"mcm","clk":"11791342330","pt":1723047869182,"mc":[{"id":"1.231499799","rc":[{"batb":[[0,1.92,10],[1,1.91,48.8],[2,1.74,17.32]],"ltp":1.91,"tv":107.05,"id":12482925}]}]}
{"op":"mcm","clk":"11791342564","pt":1723047872449,"mc":[{"id":"1.231499799","rc":[{"batb":[[0,1.91,48.8],[1,1.74,17.32],[2,1.53,94.34]],"ltp":1.91,"tv":107.05,"id":12482925}]}]}
{"op":"mcm","clk":"11791342993","pt":1723047878361,"mc":[{"id":"1.231499799","rc":[{"batb":[[0,1.92,10],[1,1.91,48.8],[2,1.74,17.32]],"ltp":1.91,"tv":107.05,"id":12482925}]}]}
{"op":"mcm","clk":"11791343233","pt":1723047881683,"mc":[{"id":"1.231499799","rc":[{"batb":[[0,1.91,48.8],[1,1.74,17.32],[2,1.53,94.34]],"ltp":1.91,"tv":107.05,"id":12482925}]}]}
{"op":"mcm","clk":"11791349640","pt":1723047955968,"mc":[{"id":"1.231499799","rc":[{"batb":[[0,1.92,10],[1,1.91,48.8],[2,1.74,17.32]],"ltp":1.91,"tv":107.05,"id":12482925}]}]}
{"op":"mcm","clk":"11791349934","pt":1723047959389,"mc":[{"id":"1.231499799","rc":[{"batb":[[0,1.91,48.8],[1,1.74,17.32],[2,1.53,94.34]],"ltp":1.91,"tv":107.05,"id":12482925}]}]}
{"op":"mcm","clk":"11791355948","pt":1723048036497,"mc":[{"id":"1.231499799","rc":[{"batb":[[0,1.92,10],[1,1.91,48.8],[2,1.74,17.32]],"ltp":1.91,"tv":107.05,"id":12482925}]}]}
{"op":"mcm","clk":"11791356198","pt":1723048039769,"mc":[{"id":"1.231499799","rc":[{"batb":[[0,1.91,48.8],[1,1.74,17.32],[2,1.53,94.34]],"ltp":1.91,"tv":107.05,"id":12482925}]}]}
{"op":"mcm","clk":"11791356954","pt":1723048050200,"mc":[{"id":"1.231499799","rc":[{"batb":[[0,1.92,10],[1,1.91,48.8],[2,1.74,17.32]],"ltp":1.91,"tv":107.05,"id":12482925}]}]}
{"op":"mcm","clk":"11791357208","pt":1723048053722,"mc":[{"id":"1.231499799","rc":[{"batb":[[0,1.91,48.8],[1,1.74,17.32],[2,1.53,94.34]],"ltp":1.91,"tv":107.05,"id":12482925}]}]}
{"op":"mcm","clk":"11791358569","pt":1723048071924,"mc":[{"id":"1.231499799","rc":[{"batb":[[0,1.92,10],[1,1.91,48.8],[2,1.74,17.32]],"ltp":1.91,"tv":107.05,"id":12482925}]}]}
{"op":"mcm","clk":"11791358809","pt":1723048075434,"mc":[{"id":"1.231499799","rc":[{"batb":[[0,1.91,48.8],[1,1.74,17.32],[2,1.53,94.34]],"ltp":1.91,"tv":107.05,"id":12482925}]}]}
{"op":"mcm","clk":"11791360514","pt":1723048096946,"mc":[{"id":"1.231499799","rc":[{"batb":[[0,1.92,10],[1,1.91,48.8],[2,1.74,17.32]],"ltp":1.91,"tv":107.05,"id":12482925}]}]}
{"op":"mcm","clk":"11791360762","pt":1723048100266,"mc":[{"id":"1.231499799","rc":[{"batb":[[0,1.91,48.8],[1,1.74,17.32],[2,1.53,94.34]],"ltp":1.91,"tv":107.05,"id":12482925}]}]}
{"op":"mcm","clk":"11791361910","pt":1723048115657,"mc":[{"id":"1.231499799","rc":[{"batb":[[0,1.92,10],[1,1.91,48.8],[2,1.74,17.32]],"ltp":1.91,"tv":107.05,"id":12482925}]}]}
{"op":"mcm","clk":"11791362182","pt":1723048119084,"mc":[{"id":"1.231499799","rc":[{"batb":[[0,1.91,48.8],[1,1.74,17.32],[2,1.53,94.34]],"ltp":1.91,"tv":107.05,"id":12482925}]}]}
{"op":"mcm","clk":"11791363001","pt":1723048129256,"mc":[{"id":"1.231499799","rc":[{"batb":[[0,1.92,10],[1,1.91,48.8],[2,1.74,17.32]],"ltp":1.91,"tv":107.05,"id":12482925}]}]}
{"op":"mcm","clk":"11791363259","pt":1723048132662,"mc":[{"id":"1.231499799","rc":[{"batb":[[0,1.91,48.8],[1,1.74,17.32],[2,1.53,94.34]],"ltp":1.91,"tv":107.05,"id":12482925}]}]}
{"op":"mcm","clk":"11791364332","pt":1723048145881,"mc":[{"id":"1.231499799","rc":[{"batb":[[0,1.92,10],[1,1.91,48.8],[2,1.74,17.32]],"ltp":1.91,"tv":107.05,"id":12482925}]}]}
{"op":"mcm","clk":"11791364658","pt":1723048149269,"mc":[{"id":"1.231499799","rc":[{"batb":[[0,1.91,48.8],[1,1.74,17.32],[2,1.53,94.34]],"ltp":1.91,"tv":107.05,"id":12482925}]}]}
{"op":"mcm","clk":"11791378803","pt":1723048297572,"mc":[{"id":"1.231499799","rc":[{"batb":[[0,1.92,10],[1,1.91,48.8],[2,1.74,17.32]],"ltp":1.91,"tv":107.05,"id":12482925}]}]}
{"op":"mcm","clk":"11791379206","pt":1723048301604,"mc":[{"id":"1.231499799","rc":[{"batb":[[0,1.91,48.8],[1,1.74,17.32],[2,1.53,94.34]],"ltp":1.91,"tv":107.05,"id":12482925}]}]}
{"op":"mcm","clk":"11791389782","pt":1723048407281,"mc":[{"id":"1.231499799","rc":[{"batb":[[0,1.92,10],[1,1.91,48.8],[2,1.74,17.32]],"ltp":1.91,"tv":107.05,"id":12482925}]}]}
{"op":"mcm","clk":"11791390218","pt":1723048410648,"mc":[{"id":"1.231499799","rc":[{"batb":[[0,1.91,48.8],[1,1.74,17.32],[2,1.53,94.34]],"ltp":1.91,"tv":107.05,"id":12482925}]}]}
{"op":"mcm","clk":"11791396872","pt":1723048470651,"mc":[{"id":"1.231499799","rc":[{"batb":[[0,1.92,10],[1,1.91,48.8],[2,1.74,17.32]],"ltp":1.91,"tv":107.05,"id":12482925}]}]}
{"op":"mcm","clk":"11791397207","pt":1723048474131,"mc":[{"id":"1.231499799","rc":[{"batb":[[0,1.91,48.8],[1,1.74,17.32],[2,1.53,94.34]],"ltp":1.91,"tv":107.05,"id":12482925}]}]}
{"op":"mcm","clk":"11791398858","pt":1723048490418,"mc":[{"id":"1.231499799","rc":[{"batb":[[0,1.92,10],[1,1.91,48.8],[2,1.74,17.32]],"ltp":1.91,"tv":107.05,"id":12482925}]}]}
{"op":"mcm","clk":"11791399193","pt":1723048493746,"mc":[{"id":"1.231499799","rc":[{"batb":[[0,1.91,48.8],[1,1.74,17.32],[2,1.53,94.34]],"ltp":1.91,"tv":107.05,"id":12482925}]}]}
{"op":"mcm","clk":"11791412230","pt":1723048620183,"mc":[{"id":"1.231499799","rc":[{"batb":[[0,1.92,10],[1,1.91,48.8],[2,1.74,17.32]],"ltp":1.91,"tv":107.05,"id":12482925}]}]}
{"op":"mcm","clk":"11791412548","pt":1723048623471,"mc":[{"id":"1.231499799","rc":[{"batb":[[0,1.91,48.8],[1,1.74,17.32],[2,1.53,94.34]],"ltp":1.91,"tv":107.05,"id":12482925}]}]}
{"op":"mcm","clk":"11791412949","pt":1723048627167,"mc":[{"id":"1.231499799","rc":[{"batb":[[0,1.92,10],[1,1.91,48.8],[2,1.74,17.32]],"ltp":1.91,"tv":107.05,"id":12482925}]}]}
{"op":"mcm","clk":"11791413280","pt":1723048630358,"mc":[{"id":"1.231499799","rc":[{"batb":[[0,1.91,48.8],[1,1.74,17.32],[2,1.53,94.34]],"ltp":1.91,"tv":107.05,"id":12482925}]}]}
{"op":"mcm","clk":"11791417159","pt":1723048666942,"mc":[{"id":"1.231499799","rc":[{"batb":[[0,1.92,10],[1,1.91,48.8],[2,1.74,17.32]],"ltp":1.91,"tv":107.05,"id":12482925}]}]}
{"op":"mcm","clk":"11791417536","pt":1723048670321,"mc":[{"id":"1.231499799","rc":[{"batb":[[0,1.91,48.8],[1,1.74,17.32],[2,1.53,94.34]],"ltp":1.91,"tv":107.05,"id":12482925}]}]}
{"op":"mcm","clk":"11791418593","pt":1723048680029,"mc":[{"id":"1.231499799","rc":[{"batb":[[0,1.92,10],[1,1.91,48.8],[2,1.74,17.32]],"ltp":1.91,"tv":107.05,"id":12482925}]}]}
{"op":"mcm","clk":"11791418958","pt":1723048683366,"mc":[{"id":"1.231499799","rc":[{"batb":[[0,1.91,48.8],[1,1.74,17.32],[2,1.53,94.34]],"ltp":1.91,"tv":107.05,"id":12482925}]}]}
{"op":"mcm","clk":"11791420798","pt":1723048699996,"mc":[{"id":"1.231499799","rc":[{"batb":[[0,1.92,10],[1,1.91,48.8],[2,1.74,17.32]],"ltp":1.91,"tv":107.05,"id":12482925}]}]}
{"op":"mcm","clk":"11791421132","pt":1723048703188,"mc":[{"id":"1.231499799","rc":[{"batb":[[0,1.91,48.8],[1,1.74,17.32],[2,1.53,94.34]],"ltp":1.91,"tv":107.05,"id":12482925}]}]}
{"op":"mcm","clk":"11791421987","pt":1723048710581,"mc":[{"id":"1.231499799","rc":[{"batb":[[0,1.92,10],[1,1.91,48.8],[2,1.74,17.32]],"ltp":1.91,"tv":107.05,"id":12482925}]}]}
{"op":"mcm","clk":"11791422386","pt":1723048714036,"mc":[{"id":"1.231499799","rc":[{"batb":[[0,1.91,48.8],[1,1.74,17.32],[2,1.53,94.34]],"ltp":1.91,"tv":107.05,"id":12482925}]}]}
{"op":"mcm","clk":"11791425171","pt":1723048740513,"mc":[{"id":"1.231499799","rc":[{"batb":[[0,1.92,10],[1,1.91,48.8],[2,1.74,17.32]],"ltp":1.91,"tv":107.05,"id":12482925}]}]}
{"op":"mcm","clk":"11791425538","pt":1723048743918,"mc":[{"id":"1.231499799","rc":[{"batb":[[0,1.91,48.8],[1,1.74,17.32],[2,1.53,94.34]],"ltp":1.91,"tv":107.05,"id":12482925}]}]}
{"op":"mcm","clk":"11791427576","pt":1723048763656,"mc":[{"id":"1.231499799","rc":[{"batb":[[0,1.92,10],[1,1.91,48.8],[2,1.74,17.32]],"ltp":1.91,"tv":107.05,"id":12482925}]}]}
{"op":"mcm","clk":"11791427815","pt":1723048766969,"mc":[{"id":"1.231499799","rc":[{"batb":[[0,1.91,48.8],[1,1.74,17.32],[2,1.53,94.34]],"ltp":1.91,"tv":107.05,"id":12482925}]}]}
{"op":"mcm","clk":"11791431976","pt":1723048812118,"mc":[{"id":"1.231499799","rc":[{"batb":[[0,1.92,10],[1,1.91,48.8],[2,1.74,17.32]],"ltp":1.91,"tv":107.05,"id":12482925}]}]}
{"op":"mcm","clk":"11791432251","pt":1723048815452,"mc":[{"id":"1.231499799","rc":[{"batb":[[0,1.91,48.8],[1,1.74,17.32],[2,1.53,94.34]],"ltp":1.91,"tv":107.05,"id":12482925}]}]}
{"op":"mcm","clk":"11791433108","pt":1723048824954,"mc":[{"id":"1.231499799","rc":[{"batb":[[0,1.92,10],[1,1.91,48.8],[2,1.74,17.32]],"ltp":1.91,"tv":107.05,"id":12482925}]}]}
{"op":"mcm","clk":"11791433412","pt":1723048828241,"mc":[{"id":"1.231499799","rc":[{"batb":[[0,1.91,48.8],[1,1.74,17.32],[2,1.53,94.34]],"ltp":1.91,"tv":107.05,"id":12482925}]}]}
{"op":"mcm","clk":"11791434052","pt":1723048834538,"mc":[{"id":"1.231499799","rc":[{"batb":[[0,1.92,10],[1,1.91,48.8],[2,1.74,17.32]],"ltp":1.91,"tv":107.05,"id":12482925}]}]}
{"op":"mcm","clk":"11791434362","pt":1723048838068,"mc":[{"id":"1.231499799","rc":[{"batb":[[0,1.91,48.8],[1,1.74,17.32],[2,1.53,94.34]],"ltp":1.91,"tv":107.05,"id":12482925}]}]}
{"op":"mcm","clk":"11791434827","pt":1723048842967,"mc":[{"id":"1.231499799","rc":[{"batb":[[0,1.92,10],[1,1.91,48.8],[2,1.74,17.32]],"ltp":1.91,"tv":107.05,"id":12482925}]}]}
{"op":"mcm","clk":"11791435151","pt":1723048846289,"mc":[{"id":"1.231499799","rc":[{"batb":[[0,1.91,48.8],[1,1.74,17.32],[2,1.53,94.34]],"ltp":1.91,"tv":107.05,"id":12482925}]}]}
{"op":"mcm","clk":"11791435485","pt":1723048849672,"mc":[{"id":"1.231499799","rc":[{"batb":[[0,1.92,10],[1,1.91,48.8],[2,1.74,17.32]],"ltp":1.91,"tv":107.05,"id":12482925}]}]}
{"op":"mcm","clk":"11791435815","pt":1723048853086,"mc":[{"id":"1.231499799","rc":[{"batb":[[0,1.91,48.8],[1,1.74,17.32],[2,1.53,94.34]],"ltp":1.91,"tv":107.05,"id":12482925}]}]}
{"op":"mcm","clk":"11791438835","pt":1723048886540,"mc":[{"id":"1.231499799","rc":[{"batb":[[0,1.92,10],[1,1.91,48.8],[2,1.74,17.32]],"ltp":1.91,"tv":107.05,"id":12482925}]}]}
{"op":"mcm","clk":"11791439115","pt":1723048889809,"mc":[{"id":"1.231499799","rc":[{"batb":[[0,1.91,48.8],[1,1.74,17.32],[2,1.53,94.34]],"ltp":1.91,"tv":107.05,"id":12482925}]}]}
{"op":"mcm","clk":"11791440367","pt":1723048906173,"mc":[{"id":"1.231499799","rc":[{"batb":[[0,1.92,10],[1,1.91,48.8],[2,1.74,17.32]],"ltp":1.91,"tv":107.05,"id":12482925}]}]}
{"op":"mcm","clk":"11791440682","pt":1723048908640,"mc":[{"id":"1.231499799","rc":[{"batb":[[0,1.91,48.8],[1,1.74,17.32],[2,1.53,94.34]],"ltp":1.91,"tv":107.05,"id":12482925}]}]}
{"op":"mcm","clk":"11791441957","pt":1723048925167,"mc":[{"id":"1.231499799","rc":[{"batb":[[0,1.92,10],[1,1.91,48.8],[2,1.74,17.32]],"ltp":1.91,"tv":107.05,"id":12482925}]}]}
{"op":"mcm","clk":"11791442224","pt":1723048928389,"mc":[{"id":"1.231499799","rc":[{"batb":[[0,1.91,48.8],[1,1.74,17.32],[2,1.53,94.34]],"ltp":1.91,"tv":107.05,"id":12482925}]}]}
{"op":"mcm","clk":"11791444643","pt":1723048956529,"mc":[{"id":"1.231499799","rc":[{"batb":[[0,1.92,10],[1,1.91,48.8],[2,1.74,17.32]],"ltp":1.91,"tv":107.05,"id":12482925}]}]}
{"op":"mcm","clk":"11791444967","pt":1723048960238,"mc":[{"id":"1.231499799","rc":[{"batb":[[0,1.91,48.8],[1,1.74,17.32],[2,1.53,94.34]],"ltp":1.91,"tv":107.05,"id":12482925}]}]}
{"op":"mcm","clk":"11791446736","pt":1723048979865,"mc":[{"id":"1.231499799","rc":[{"batb":[[0,1.92,10],[1,1.91,48.8],[2,1.74,17.32]],"ltp":1.91,"tv":107.05,"id":12482925}]}]}
{"op":"mcm","clk":"11791446990","pt":1723048983173,"mc":[{"id":"1.231499799","rc":[{"batb":[[0,1.91,48.8],[1,1.74,17.32],[2,1.53,94.34]],"ltp":1.91,"tv":107.05,"id":12482925}]}]}
{"op":"mcm","clk":"11791447305","pt":1723048987263,"mc":[{"id":"1.231499799","rc":[{"batb":[[0,1.92,10],[1,1.91,48.8],[2,1.74,17.32]],"ltp":1.91,"tv":107.05,"id":12482925}]}]}
{"op":"mcm","clk":"11791447570","pt":1723048990678,"mc":[{"id":"1.231499799","rc":[{"batb":[[0,1.91,48.8],[1,1.74,17.32],[2,1.53,94.34]],"ltp":1.91,"tv":107.05,"id":12482925}]}]}
{"op":"mcm","clk":"11791449002","pt":1723049009473,"mc":[{"id":"1.231499799","rc":[{"batb":[[0,1.92,10],[1,1.91,48.8],[2,1.74,17.32]],"ltp":1.91,"tv":107.05,"id":12482925}]}]}
{"op":"mcm","clk":"11791449266","pt":1723049012807,"mc":[{"id":"1.231499799","rc":[{"batb":[[0,1.91,48.8],[1,1.74,17.32],[2,1.53,94.34]],"ltp":1.91,"tv":107.05,"id":12482925}]}]}
{"op":"mcm","clk":"11791450731","pt":1723049033108,"mc":[{"id":"1.231499799","rc":[{"batb":[[0,1.92,10],[1,1.91,48.8],[2,1.74,17.32]],"ltp":1.91,"tv":107.05,"id":12482925}]}]}
{"op":"mcm","clk":"11791450990","pt":1723049036447,"mc":[{"id":"1.231499799","rc":[{"batb":[[0,1.91,48.8],[1,1.74,17.32],[2,1.53,94.34]],"ltp":1.91,"tv":107.05,"id":12482925}]}]}
{"op":"mcm","clk":"11791452129","pt":1723049049332,"mc":[{"id":"1.231499799","rc":[{"batb":[[0,1.92,10],[1,1.91,48.8],[2,1.74,17.32]],"ltp":1.91,"tv":107.05,"id":12482925}]}]}
{"op":"mcm","clk":"11791452390","pt":1723049052835,"mc":[{"id":"1.231499799","rc":[{"batb":[[0,1.91,48.8],[1,1.74,17.32],[2,1.53,94.34]],"ltp":1.91,"tv":107.05,"id":12482925}]}]}
{"op":"mcm","clk":"11791459916","pt":1723049142968,"mc":[{"id":"1.231499799","rc":[{"batb":[[0,1.92,10],[1,1.91,48.8],[2,1.74,17.32]],"ltp":1.91,"tv":107.05,"id":12482925}]}]}
{"op":"mcm","clk":"11791460219","pt":1723049146139,"mc":[{"id":"1.231499799","rc":[{"batb":[[0,1.91,48.8],[1,1.74,17.32],[2,1.53,94.34]],"ltp":1.91,"tv":107.05,"id":12482925}]}]}
{"op":"mcm","clk":"11791460941","pt":1723049153864,"mc":[{"id":"1.231499799","rc":[{"batb":[[0,1.92,10],[1,1.91,48.8],[2,1.74,17.32]],"ltp":1.91,"tv":107.05,"id":12482925}]}]}
{"op":"mcm","clk":"11791461200","pt":1723049157182,"mc":[{"id":"1.231499799","rc":[{"batb":[[0,1.91,48.8],[1,1.74,17.32],[2,1.53,94.34]],"ltp":1.91,"tv":107.05,"id":12482925}]}]}
{"op":"mcm","clk":"11791462338","pt":1723049170206,"mc":[{"id":"1.231499799","rc":[{"batb":[[0,1.92,10],[1,1.91,48.8],[2,1.74,17.32]],"ltp":1.91,"tv":107.05,"id":12482925}]}]}
{"op":"mcm","clk":"11791462618","pt":1723049173685,"mc":[{"id":"1.231499799","rc":[{"batb":[[0,1.91,48.8],[1,1.74,17.32],[2,1.53,94.34]],"ltp":1.91,"tv":107.05,"id":12482925}]}]}
{"op":"mcm","clk":"11791549707","pt":1723050028098,"mc":[{"id":"1.231499799","rc":[{"trd":[[1.98,7.76]],"ltp":1.98,"tv":7.76,"id":25686043},{"trd":[[1.95,107.04]],"batb":[[0,1.92,10],[1,1.91,48.8],[2,1.74,17.32]],"ltp":1.91,"tv":107.05,"id":12482925}],"tv":114.82}]}
{"op":"mcm","clk":"11791550126","pt":1723050031327,"mc":[{"id":"1.231499799","rc":[{"batb":[[0,1.91,48.8],[1,1.74,17.32],[2,1.53,94.34]],"ltp":1.91,"tv":107.05,"id":12482925}]}]}
{"op":"mcm","clk":"11791553545","pt":1723050059346,"mc":[{"id":"1.231499799","rc":[{"batb":[[0,1.92,10],[1,1.91,48.8],[2,1.74,17.32]],"ltp":1.91,"tv":107.05,"id":12482925}]}]}
{"op":"mcm","clk":"11791553986","pt":1723050062854,"mc":[{"id":"1.231499799","rc":[{"batb":[[0,1.91,48.8],[1,1.74,17.32],[2,1.53,94.34]],"ltp":1.91,"tv":107.05,"id":12482925}]}]}
{"op":"mcm","clk":"11791557077","pt":1723050087993,"mc":[{"id":"1.231499799","rc":[{"batb":[[0,1.92,10],[1,1.91,48.8],[2,1.74,17.32]],"ltp":1.91,"tv":107.05,"id":12482925}]}]}
{"op":"mcm","clk":"11791557436","pt":1723050091078,"mc":[{"id":"1.231499799","rc":[{"batb":[[0,1.91,48.8],[1,1.74,17.32],[2,1.53,94.34]],"ltp":1.91,"tv":107.05,"id":12482925}]}]}
{"op":"mcm","clk":"11791558335","pt":1723050098817,"mc":[{"id":"1.231499799","rc":[{"batb":[[0,1.92,10],[1,1.91,48.8],[2,1.74,17.32]],"ltp":1.91,"tv":107.05,"id":12482925}]}]}
{"op":"mcm","clk":"11791558755","pt":1723050102107,"mc":[{"id":"1.231499799","rc":[{"batb":[[0,1.91,48.8],[1,1.74,17.32],[2,1.53,94.34]],"ltp":1.91,"tv":107.05,"id":12482925}]}]}
{"op":"mcm","clk":"11791559421","pt":1723050108121,"mc":[{"id":"1.231499799","rc":[{"batb":[[0,1.92,10],[1,1.91,48.8],[2,1.74,17.32]],"ltp":1.91,"tv":107.05,"id":12482925}]}]}
{"op":"mcm","clk":"11791559844","pt":1723050111515,"mc":[{"id":"1.231499799","rc":[{"batb":[[0,1.91,48.8],[1,1.74,17.32],[2,1.53,94.34]],"ltp":1.91,"tv":107.05,"id":12482925}]}]}
{"op":"mcm","clk":"11791560139","pt":1723050113816,"mc":[{"id":"1.231499799","rc":[{"batb":[[0,1.92,10],[1,1.91,48.8],[2,1.74,17.32]],"ltp":1.91,"tv":107.05,"id":12482925}]}]}
{"op":"mcm","clk":"11791560593","pt":1723050117195,"mc":[{"id":"1.231499799","rc":[{"batb":[[0,1.91,48.8],[1,1.74,17.32],[2,1.53,94.34]],"ltp":1.91,"tv":107.05,"id":12482925}]}]}
{"op":"mcm","clk":"11791561330","pt":1723050123616,"mc":[{"id":"1.231499799","rc":[{"batb":[[0,1.92,10],[1,1.91,48.8],[2,1.74,17.32]],"ltp":1.91,"tv":107.05,"id":12482925}]}]}
{"op":"mcm","clk":"11791561759","pt":1723050126794,"mc":[{"id":"1.231499799","rc":[{"batb":[[0,1.91,48.8],[1,1.74,17.32],[2,1.53,94.34]],"ltp":1.91,"tv":107.05,"id":12482925}]}]}
{"op":"mcm","clk":"11791562812","pt":1723050135927,"mc":[{"id":"1.231499799","rc":[{"batb":[[0,1.92,10],[1,1.91,48.8],[2,1.74,17.32]],"ltp":1.91,"tv":107.05,"id":12482925}]}]}
{"op":"mcm","clk":"11791563218","pt":1723050139242,"mc":[{"id":"1.231499799","rc":[{"batb":[[0,1.91,48.8],[1,1.74,17.32],[2,1.53,94.34]],"ltp":1.91,"tv":107.05,"id":12482925}]}]}
{"op":"mcm","clk":"11791564594","pt":1723050149682,"mc":[{"id":"1.231499799","rc":[{"batb":[[0,1.92,10],[1,1.91,48.8],[2,1.74,17.32]],"ltp":1.91,"tv":107.05,"id":12482925}]}]}
{"op":"mcm","clk":"11791565019","pt":1723050152901,"mc":[{"id":"1.231499799","rc":[{"batb":[[0,1.91,48.8],[1,1.74,17.32],[2,1.53,94.34]],"ltp":1.91,"tv":107.05,"id":12482925}]}]}
{"op":"mcm","clk":"11791566010","pt":1723050160404,"mc":[{"id":"1.231499799","rc":[{"batb":[[0,1.92,10],[1,1.91,48.8],[2,1.74,17.32]],"ltp":1.91,"tv":107.05,"id":12482925}]}]}
{"op":"mcm","clk":"11791566501","pt":1723050163880,"mc":[{"id":"1.231499799","rc":[{"batb":[[0,1.91,48.8],[1,1.74,17.32],[2,1.53,94.34]],"ltp":1.91,"tv":107.05,"id":12482925}]}]}
{"op":"mcm","clk":"11791566974","pt":1723050167895,"mc":[{"id":"1.231499799","rc":[{"batb":[[0,1.92,10],[1,1.91,48.8],[2,1.74,17.32]],"ltp":1.91,"tv":107.05,"id":12482925}]}]}
{"op":"mcm","clk":"11791567356","pt":1723050171278,"mc":[{"id":"1.231499799","rc":[{"batb":[[0,1.91,48.8],[1,1.74,17.32],[2,1.53,94.34]],"ltp":1.91,"tv":107.05,"id":12482925}]}]}
{"op":"mcm","clk":"11791574341","pt":1723050228132,"mc":[{"id":"1.231499799","rc":[{"batb":[[0,1.92,10],[1,1.91,48.8],[2,1.74,17.32]],"ltp":1.91,"tv":107.05,"id":12482925}]}]}
{"op":"mcm","clk":"11791574761","pt":1723050231521,"mc":[{"id":"1.231499799","rc":[{"batb":[[0,1.91,48.8],[1,1.74,17.32],[2,1.53,94.34]],"ltp":1.91,"tv":107.05,"id":12482925}]}]}
{"op":"mcm","clk":"11791577885","pt":1723050255951,"mc":[{"id":"1.231499799","rc":[{"batb":[[0,1.92,10],[1,1.91,48.8],[2,1.74,17.32]],"ltp":1.91,"tv":107.05,"id":12482925}]}]}
{"op":"mcm","clk":"11791578331","pt":1723050259149,"mc":[{"id":"1.231499799","rc":[{"batb":[[0,1.91,48.8],[1,1.74,17.32],[2,1.53,94.34]],"ltp":1.91,"tv":107.05,"id":12482925}]}]}
{"op":"mcm","clk":"11791583599","pt":1723050299785,"mc":[{"id":"1.231499799","rc":[{"batb":[[0,1.92,10],[1,1.91,48.8],[2,1.74,17.32]],"ltp":1.91,"tv":107.05,"id":12482925}]}]}
{"op":"mcm","clk":"11791584010","pt":1723050303097,"mc":[{"id":"1.231499799","rc":[{"batb":[[0,1.91,48.8],[1,1.74,17.32],[2,1.53,94.34]],"ltp":1.91,"tv":107.05,"id":12482925}]}]}
{"op":"mcm","clk":"11791589893","pt":1723050348150,"mc":[{"id":"1.231499799","rc":[{"batb":[[0,1.92,10],[1,1.91,48.8],[2,1.74,17.32]],"ltp":1.91,"tv":107.05,"id":12482925}]}]}
{"op":"mcm","clk":"11791590376","pt":1723050351649,"mc":[{"id":"1.231499799","rc":[{"batb":[[0,1.91,48.8],[1,1.74,17.32],[2,1.53,94.34]],"ltp":1.91,"tv":107.05,"id":12482925}]}]}
{"op":"mcm","clk":"11791606825","pt":1723050476464,"mc":[{"id":"1.231499799","rc":[{"batb":[[0,1.92,10],[1,1.91,48.8],[2,1.74,17.32]],"ltp":1.91,"tv":107.05,"id":12482925}]}]}
{"op":"mcm","clk":"11791607288","pt":1723050479889,"mc":[{"id":"1.231499799","rc":[{"batb":[[0,1.91,48.8],[1,1.74,17.32],[2,1.53,94.34]],"ltp":1.91,"tv":107.05,"id":12482925}]}]}
{"op":"mcm","clk":"11791608252","pt":1723050486995,"mc":[{"id":"1.231499799","rc":[{"batb":[[0,1.92,10],[1,1.91,48.8],[2,1.74,17.32]],"ltp":1.91,"tv":107.05,"id":12482925}]}]}
{"op":"mcm","clk":"11791608658","pt":1723050490311,"mc":[{"id":"1.231499799","rc":[{"batb":[[0,1.91,48.8],[1,1.74,17.32],[2,1.53,94.34]],"ltp":1.91,"tv":107.05,"id":12482925}]}]}
{"op":"mcm","clk":"11791617391","pt":1723050554860,"mc":[{"id":"1.231499799","rc":[{"batb":[[0,1.92,10],[1,1.91,48.8],[2,1.74,17.32]],"ltp":1.91,"tv":107.05,"id":12482925}]}]}
{"op":"mcm","clk":"11791617839","pt":1723050558157,"mc":[{"id":"1.231499799","rc":[{"batb":[[0,1.91,48.8],[1,1.74,17.32],[2,1.53,94.34]],"ltp":1.91,"tv":107.05,"id":12482925}]}]}
{"op":"mcm","clk":"11791619881","pt":1723050573810,"mc":[{"id":"1.231499799","rc":[{"batb":[[0,1.92,10],[1,1.91,48.8],[2,1.74,17.32]],"ltp":1.91,"tv":107.05,"id":12482925}]}]}
{"op":"mcm","clk":"11791620327","pt":1723050577183,"mc":[{"id":"1.231499799","rc":[{"batb":[[0,1.91,48.8],[1,1.74,17.32],[2,1.53,94.34]],"ltp":1.91,"tv":107.05,"id":12482925}]}]}
{"op":"mcm","clk":"11791620794","pt":1723050580621,"mc":[{"id":"1.231499799","rc":[{"batb":[[0,1.92,10],[1,1.91,48.8],[2,1.74,17.32]],"ltp":1.91,"tv":107.05,"id":12482925}]}]}
{"op":"mcm","clk":"11791621219","pt":1723050583980,"mc":[{"id":"1.231499799","rc":[{"batb":[[0,1.91,48.8],[1,1.74,17.32],[2,1.53,94.34]],"ltp":1.91,"tv":107.05,"id":12482925}]}]}
{"op":"mcm","clk":"11791624399","pt":1723050609059,"mc":[{"id":"1.231499799","rc":[{"batb":[[0,1.92,10],[1,1.91,48.8],[2,1.74,17.32]],"ltp":1.91,"tv":107.05,"id":12482925}]}]}
{"op":"mcm","clk":"11791624880","pt":1723050612481,"mc":[{"id":"1.231499799","rc":[{"batb":[[0,1.91,48.8],[1,1.74,17.32],[2,1.53,94.34]],"ltp":1.91,"tv":107.05,"id":12482925}]}]}
{"op":"mcm","clk":"11791626730","pt":1723050625767,"mc":[{"id":"1.231499799","rc":[{"batb":[[0,1.92,10],[1,1.91,48.8],[2,1.74,17.32]],"ltp":1.91,"tv":107.05,"id":12482925}]}]}
{"op":"mcm","clk":"11791627211","pt":1723050629091,"mc":[{"id":"1.231499799","rc":[{"batb":[[0,1.91,48.8],[1,1.74,17.32],[2,1.53,94.34]],"ltp":1.91,"tv":107.05,"id":12482925}]}]}
{"op":"mcm","clk":"11791629384","pt":1723050644397,"mc":[{"id":"1.231499799","rc":[{"batb":[[0,1.92,10],[1,1.91,48.8],[2,1.74,17.32]],"ltp":1.91,"tv":107.05,"id":12482925}]}]}
{"op":"mcm","clk":"11791629844","pt":1723050647733,"mc":[{"id":"1.231499799","rc":[{"batb":[[0,1.91,48.8],[1,1.74,17.32],[2,1.53,94.34]],"ltp":1.91,"tv":107.05,"id":12482925}]}]}
{"op":"mcm","clk":"11791630724","pt":1723050653835,"mc":[{"id":"1.231499799","rc":[{"batb":[[0,1.92,10],[1,1.91,48.8],[2,1.74,17.32]],"ltp":1.91,"tv":107.05,"id":12482925}]}]}
{"op":"mcm","clk":"11791631147","pt":1723050657134,"mc":[{"id":"1.231499799","rc":[{"batb":[[0,1.91,48.8],[1,1.74,17.32],[2,1.53,94.34]],"ltp":1.91,"tv":107.05,"id":12482925}]}]}
{"op":"mcm","clk":"11791632177","pt":1723050664539,"mc":[{"id":"1.231499799","rc":[{"batb":[[0,1.92,10],[1,1.91,48.8],[2,1.74,17.32]],"ltp":1.91,"tv":107.05,"id":12482925}]}]}
{"op":"mcm","clk":"11791632614","pt":1723050668243,"mc":[{"id":"1.231499799","rc":[{"batb":[[0,1.91,48.8],[1,1.74,17.32],[2,1.53,94.34]],"ltp":1.91,"tv":107.05,"id":12482925}]}]}
{"op":"mcm","clk":"11791634152","pt":1723050679864,"mc":[{"id":"1.231499799","rc":[{"batb":[[0,1.92,10],[1,1.91,48.8],[2,1.74,17.32]],"ltp":1.91,"tv":107.05,"id":12482925}]}]}
{"op":"mcm","clk":"11791634598","pt":1723050683159,"mc":[{"id":"1.231499799","rc":[{"batb":[[0,1.91,48.8],[1,1.74,17.32],[2,1.53,94.34]],"ltp":1.91,"tv":107.05,"id":12482925}]}]}
{"op":"mcm","clk":"11791636301","pt":1723050695974,"mc":[{"id":"1.231499799","rc":[{"batb":[[0,1.92,10],[1,1.91,48.8],[2,1.74,17.32]],"ltp":1.91,"tv":107.05,"id":12482925}]}]}
{"op":"mcm","clk":"11791636699","pt":1723050699289,"mc":[{"id":"1.231499799","rc":[{"batb":[[0,1.91,48.8],[1,1.74,17.32],[2,1.53,94.34]],"ltp":1.91,"tv":107.05,"id":12482925}]}]}
{"op":"mcm","clk":"11791654995","pt":1723050843131,"mc":[{"id":"1.231499799","rc":[{"batb":[[0,1.92,10],[1,1.91,48.8],[2,1.74,17.32]],"ltp":1.91,"tv":107.05,"id":12482925}]}]}
{"op":"mcm","clk":"11791655454","pt":1723050846306,"mc":[{"id":"1.231499799","rc":[{"batb":[[0,1.91,48.8],[1,1.74,17.32],[2,1.53,94.34]],"ltp":1.91,"tv":107.05,"id":12482925}]}]}
{"op":"mcm","clk":"11791655796","pt":1723050849024,"mc":[{"id":"1.231499799","rc":[{"batb":[[0,1.92,10],[1,1.91,48.8],[2,1.74,17.32]],"ltp":1.91,"tv":107.05,"id":12482925}]}]}
{"op":"mcm","clk":"11791656270","pt":1723050852415,"mc":[{"id":"1.231499799","rc":[{"batb":[[0,1.91,48.8],[1,1.74,17.32],[2,1.53,94.34]],"ltp":1.91,"tv":107.05,"id":12482925}]}]}
{"op":"mcm","clk":"11791672703","pt":1723050979062,"mc":[{"id":"1.231499799","rc":[{"batb":[[0,1.92,10],[1,1.91,48.8],[2,1.74,17.32]],"ltp":1.91,"tv":107.05,"id":12482925}]}]}
{"op":"mcm","clk":"11791673156","pt":1723050982355,"mc":[{"id":"1.231499799","rc":[{"batb":[[0,1.91,48.8],[1,1.74,17.32],[2,1.53,94.34]],"ltp":1.91,"tv":107.05,"id":12482925}]}]}
{"op":"mcm","clk":"11791693694","pt":1723051131836,"mc":[{"id":"1.231499799","rc":[{"batb":[[0,1.92,10],[1,1.91,48.8],[2,1.74,17.32]],"ltp":1.91,"tv":107.05,"id":12482925}]}]}
{"op":"mcm","clk":"11791694146","pt":1723051135139,"mc":[{"id":"1.231499799","rc":[{"batb":[[0,1.91,48.8],[1,1.74,17.32],[2,1.53,94.34]],"ltp":1.91,"tv":107.05,"id":12482925}]}]}
{"op":"mcm","clk":"11791702466","pt":1723051193506,"mc":[{"id":"1.231499799","rc":[{"batb":[[0,1.92,10],[1,1.91,48.8],[2,1.74,17.32]],"ltp":1.91,"tv":107.05,"id":12482925}]}]}
{"op":"mcm","clk":"11791703021","pt":1723051197215,"mc":[{"id":"1.231499799","rc":[{"batb":[[0,1.91,48.8],[1,1.74,17.32],[2,1.53,94.34]],"ltp":1.91,"tv":107.05,"id":12482925}]}]}
{"op":"mcm","clk":"11791708493","pt":1723051238342,"mc":[{"id":"1.231499799","rc":[{"batb":[[0,1.92,10],[1,1.91,48.8],[2,1.74,17.32]],"ltp":1.91,"tv":107.05,"id":12482925}]}]}
{"op":"mcm","clk":"11791708960","pt":1723051241658,"mc":[{"id":"1.231499799","rc":[{"batb":[[0,1.91,48.8],[1,1.74,17.32],[2,1.53,94.34]],"ltp":1.91,"tv":107.05,"id":12482925}]}]}
{"op":"mcm","clk":"11791713034","pt":1723051271068,"mc":[{"id":"1.231499799","rc":[{"batb":[[0,1.92,10],[1,1.91,48.8],[2,1.74,17.32]],"ltp":1.91,"tv":107.05,"id":12482925}]}]}
{"op":"mcm","clk":"11791713491","pt":1723051274465,"mc":[{"id":"1.231499799","rc":[{"batb":[[0,1.91,48.8],[1,1.74,17.32],[2,1.53,94.34]],"ltp":1.91,"tv":107.05,"id":12482925}]}]}
{"op":"mcm","clk":"11791717837","pt":1723051303506,"mc":[{"id":"1.231499799","rc":[{"batb":[[0,1.92,10],[1,1.91,48.8],[2,1.74,17.32]],"ltp":1.91,"tv":107.05,"id":12482925}]}]}
{"op":"mcm","clk":"11791718296","pt":1723051306807,"mc":[{"id":"1.231499799","rc":[{"batb":[[0,1.91,48.8],[1,1.74,17.32],[2,1.53,94.34]],"ltp":1.91,"tv":107.05,"id":12482925}]}]}
{"op":"mcm","clk":"11791720605","pt":1723051323637,"mc":[{"id":"1.231499799","rc":[{"batb":[[0,1.92,10],[1,1.91,48.8],[2,1.74,17.32]],"ltp":1.91,"tv":107.05,"id":12482925}]}]}
{"op":"mcm","clk":"11791721110","pt":1723051327028,"mc":[{"id":"1.231499799","rc":[{"batb":[[0,1.91,48.8],[1,1.74,17.32],[2,1.53,94.34]],"ltp":1.91,"tv":107.05,"id":12482925}]}]}
{"op":"mcm","clk":"11791722188","pt":1723051335062,"mc":[{"id":"1.231499799","rc":[{"batb":[[0,1.92,10],[1,1.91,48.8],[2,1.74,17.32]],"ltp":1.91,"tv":107.05,"id":12482925}]}]}
{"op":"mcm","clk":"11791722629","pt":1723051338385,"mc":[{"id":"1.231499799","rc":[{"batb":[[0,1.91,48.8],[1,1.74,17.32],[2,1.53,94.34]],"ltp":1.91,"tv":107.05,"id":12482925}]}]}
{"op":"mcm","clk":"11791725778","pt":1723051359810,"mc":[{"id":"1.231499799","rc":[{"batb":[[0,1.92,10],[1,1.91,48.8],[2,1.74,17.32]],"ltp":1.91,"tv":107.05,"id":12482925}]}]}
{"op":"mcm","clk":"11791726296","pt":1723051363201,"mc":[{"id":"1.231499799","rc":[{"batb":[[0,1.91,48.8],[1,1.74,17.32],[2,1.53,94.34]],"ltp":1.91,"tv":107.05,"id":12482925}]}]}
{"op":"mcm","clk":"11791728307","pt":1723051377131,"mc":[{"id":"1.231499799","rc":[{"batb":[[0,1.92,10],[1,1.91,48.8],[2,1.74,17.32]],"ltp":1.91,"tv":107.05,"id":12482925}]}]}
{"op":"mcm","clk":"11791728753","pt":1723051380423,"mc":[{"id":"1.231499799","rc":[{"batb":[[0,1.91,48.8],[1,1.74,17.32],[2,1.53,94.34]],"ltp":1.91,"tv":107.05,"id":12482925}]}]}
{"op":"mcm","clk":"11791730514","pt":1723051392625,"mc":[{"id":"1.231499799","rc":[{"batb":[[0,1.92,10],[1,1.91,48.8],[2,1.74,17.32]],"ltp":1.91,"tv":107.05,"id":12482925}]}]}
{"op":"mcm","clk":"11791730996","pt":1723051396027,"mc":[{"id":"1.231499799","rc":[{"batb":[[0,1.91,48.8],[1,1.74,17.32],[2,1.53,94.34]],"ltp":1.91,"tv":107.05,"id":12482925}]}]}
{"op":"mcm","clk":"11791732853","pt":1723051408650,"mc":[{"id":"1.231499799","rc":[{"batb":[[0,1.92,10],[1,1.91,48.8],[2,1.74,17.32]],"ltp":1.91,"tv":107.05,"id":12482925}]}]}
{"op":"mcm","clk":"11791733348","pt":1723051411929,"mc":[{"id":"1.231499799","rc":[{"batb":[[0,1.91,48.8],[1,1.74,17.32],[2,1.53,94.34]],"ltp":1.91,"tv":107.05,"id":12482925}]}]}
{"op":"mcm","clk":"11791733714","pt":1723051414650,"mc":[{"id":"1.231499799","rc":[{"batb":[[0,1.92,10],[1,1.91,48.8],[2,1.74,17.32]],"ltp":1.91,"tv":107.05,"id":12482925}]}]}
{"op":"mcm","clk":"11791734207","pt":1723051417944,"mc":[{"id":"1.231499799","rc":[{"batb":[[0,1.91,48.8],[1,1.74,17.32],[2,1.53,94.34]],"ltp":1.91,"tv":107.05,"id":12482925}]}]}
{"op":"mcm","clk":"11791737930","pt":1723051444903,"mc":[{"id":"1.231499799","rc":[{"batb":[[0,1.92,10],[1,1.91,48.8],[2,1.74,17.32]],"ltp":1.91,"tv":107.05,"id":12482925}]}]}
{"op":"mcm","clk":"11791738400","pt":1723051448199,"mc":[{"id":"1.231499799","rc":[{"batb":[[0,1.91,48.8],[1,1.74,17.32],[2,1.53,94.34]],"ltp":1.91,"tv":107.05,"id":12482925}]}]}
{"op":"mcm","clk":"11791739929","pt":1723051459626,"mc":[{"id":"1.231499799","rc":[{"batb":[[0,1.92,10],[1,1.91,48.8],[2,1.74,17.32]],"ltp":1.91,"tv":107.05,"id":12482925}]}]}
{"op":"mcm","clk":"11791740449","pt":1723051463234,"mc":[{"id":"1.231499799","rc":[{"batb":[[0,1.91,48.8],[1,1.74,17.32],[2,1.53,94.34]],"ltp":1.91,"tv":107.05,"id":12482925}]}]}
{"op":"mcm","clk":"11791740939","pt":1723051466520,"mc":[{"id":"1.231499799","rc":[{"batb":[[0,1.92,10],[1,1.91,48.8],[2,1.74,17.32]],"ltp":1.91,"tv":107.05,"id":12482925}]}]}
{"op":"mcm","clk":"11791741379","pt":1723051469821,"mc":[{"id":"1.231499799","rc":[{"batb":[[0,1.91,48.8],[1,1.74,17.32],[2,1.53,94.34]],"ltp":1.91,"tv":107.05,"id":12482925}]}]}
{"op":"mcm","clk":"11791745038","pt":1723051494553,"mc":[{"id":"1.231499799","rc":[{"batb":[[0,1.92,10],[1,1.91,48.8],[2,1.74,17.32]],"ltp":1.91,"tv":107.05,"id":12482925}]}]}
{"op":"mcm","clk":"11791745567","pt":1723051497950,"mc":[{"id":"1.231499799","rc":[{"batb":[[0,1.91,48.8],[1,1.74,17.32],[2,1.53,94.34]],"ltp":1.91,"tv":107.05,"id":12482925}]}]}
{"op":"mcm","clk":"11791745910","pt":1723051500208,"mc":[{"id":"1.231499799","rc":[{"batb":[[0,1.92,10],[1,1.91,48.8],[2,1.74,17.32]],"ltp":1.91,"tv":107.05,"id":12482925}]}]}
{"op":"mcm","clk":"11791746476","pt":1723051503758,"mc":[{"id":"1.231499799","rc":[{"batb":[[0,1.91,48.8],[1,1.74,17.32],[2,1.53,94.34]],"ltp":1.91,"tv":107.05,"id":12482925}]}]}
{"op":"mcm","clk":"11791747843","pt":1723051511659,"mc":[{"id":"1.231499799","rc":[{"batb":[[0,1.92,10],[1,1.91,48.8],[2,1.74,17.32]],"ltp":1.91,"tv":107.05,"id":12482925}]}]}
{"op":"mcm","clk":"11791748357","pt":1723051515156,"mc":[{"id":"1.231499799","rc":[{"batb":[[0,1.91,48.8],[1,1.74,17.32],[2,1.53,94.34]],"ltp":1.91,"tv":107.05,"id":12482925}]}]}
{"op":"mcm","clk":"11791751334","pt":1723051534270,"mc":[{"id":"1.231499799","rc":[{"batb":[[0,1.92,10],[1,1.91,48.8],[2,1.74,17.32]],"ltp":1.91,"tv":107.05,"id":12482925}]}]}
{"op":"mcm","clk":"11791751799","pt":1723051537457,"mc":[{"id":"1.231499799","rc":[{"batb":[[0,1.91,48.8],[1,1.74,17.32],[2,1.53,94.34]],"ltp":1.91,"tv":107.05,"id":12482925}]}]}
{"op":"mcm","clk":"11791752425","pt":1723051541647,"mc":[{"id":"1.231499799","rc":[{"batb":[[0,1.92,10],[1,1.91,48.8],[2,1.74,17.32]],"ltp":1.91,"tv":107.05,"id":12482925}]}]}
{"op":"mcm","clk":"11791752952","pt":1723051545261,"mc":[{"id":"1.231499799","rc":[{"batb":[[0,1.91,48.8],[1,1.74,17.32],[2,1.53,94.34]],"ltp":1.91,"tv":107.05,"id":12482925}]}]}
{"op":"mcm","clk":"11791759241","pt":1723051588511,"mc":[{"id":"1.231499799","rc":[{"trd":[[2.1,0.07]],"ltp":2.1,"tv":7.83,"id":25686043},{"trd":[[1.91,0.1]],"batb":[[0,1.92,10],[1,1.91,48.72],[2,1.74,17.32]],"ltp":1.91,"tv":107.13,"id":12482925}],"tv":114.97}]}
{"op":"mcm","clk":"11791759707","pt":1723051591837,"mc":[{"id":"1.231499799","rc":[{"batb":[[0,1.91,48.8],[1,1.74,17.32],[2,1.53,94.34]],"ltp":1.91,"tv":107.13,"id":12482925}]}]}
{"op":"mcm","clk":"11791761777","pt":1723051606569,"mc":[{"id":"1.231499799","rc":[{"batb":[[0,1.92,10],[1,1.91,48.8],[2,1.74,17.32]],"ltp":1.91,"tv":107.13,"id":12482925}]}]}
{"op":"mcm","clk":"11791762268","pt":1723051609964,"mc":[{"id":"1.231499799","rc":[{"batb":[[0,1.91,48.8],[1,1.74,17.32],[2,1.53,94.34]],"ltp":1.91,"tv":107.13,"id":12482925}]}]}
{"op":"mcm","clk":"11791772055","pt":1723051672412,"mc":[{"id":"1.231499799","rc":[{"batb":[[0,1.92,10],[1,1.91,48.8],[2,1.74,17.32]],"ltp":1.91,"tv":107.13,"id":12482925}]}]}
{"op":"mcm","clk":"11791772577","pt":1723051675751,"mc":[{"id":"1.231499799","rc":[{"batb":[[0,1.91,48.8],[1,1.74,17.32],[2,1.53,94.34]],"ltp":1.91,"tv":107.13,"id":12482925}]}]}
{"op":"mcm","clk":"11791779198","pt":1723051716005,"mc":[{"id":"1.231499799","rc":[{"batb":[[0,1.92,10],[1,1.91,48.8],[2,1.74,17.32]],"ltp":1.91,"tv":107.13,"id":12482925}]}]}
{"op":"mcm","clk":"11791779733","pt":1723051719616,"mc":[{"id":"1.231499799","rc":[{"batb":[[0,1.91,48.8],[1,1.74,17.32],[2,1.53,94.34]],"ltp":1.91,"tv":107.13,"id":12482925}]}]}
{"op":"mcm","clk":"11791783022","pt":1723051741134,"mc":[{"id":"1.231499799","rc":[{"batb":[[0,1.92,10],[1,1.91,48.8],[2,1.74,17.32]],"ltp":1.91,"tv":107.13,"id":12482925}]}]}
{"op":"mcm","clk":"11791783587","pt":1723051744408,"mc":[{"id":"1.231499799","rc":[{"batb":[[0,1.91,48.8],[1,1.74,17.32],[2,1.53,94.34]],"ltp":1.91,"tv":107.13,"id":12482925}]}]}
{"op":"mcm","clk":"11791792333","pt":1723051804381,"mc":[{"id":"1.231499799","rc":[{"batb":[[0,1.92,10],[1,1.91,48.8],[2,1.74,17.32]],"ltp":1.91,"tv":107.13,"id":12482925}]}]}
{"op":"mcm","clk":"11791792872","pt":1723051807788,"mc":[{"id":"1.231499799","rc":[{"batb":[[0,1.91,48.8],[1,1.74,17.32],[2,1.53,94.34]],"ltp":1.91,"tv":107.13,"id":12482925}]}]}
{"op":"mcm","clk":"11791793415","pt":1723051811280,"mc":[{"id":"1.231499799","rc":[{"batb":[[0,1.92,10],[1,1.91,48.8],[2,1.74,17.32]],"ltp":1.91,"tv":107.13,"id":12482925}]}]}
{"op":"mcm","clk":"11791793924","pt":1723051814489,"mc":[{"id":"1.231499799","rc":[{"batb":[[0,1.91,48.8],[1,1.74,17.32],[2,1.53,94.34]],"ltp":1.91,"tv":107.13,"id":12482925}]}]}
{"op":"mcm","clk":"11791794352","pt":1723051816975,"mc":[{"id":"1.231499799","rc":[{"batb":[[0,1.92,10],[1,1.91,48.8],[2,1.74,17.32]],"ltp":1.91,"tv":107.13,"id":12482925}]}]}
{"op":"mcm","clk":"11791794855","pt":1723051820188,"mc":[{"id":"1.231499799","rc":[{"batb":[[0,1.91,48.8],[1,1.74,17.32],[2,1.53,94.34]],"ltp":1.91,"tv":107.13,"id":12482925}]}]}
{"op":"mcm","clk":"11791795661","pt":1723051825602,"mc":[{"id":"1.231499799","rc":[{"batb":[[0,1.92,10],[1,1.91,48.8],[2,1.74,17.32]],"ltp":1.91,"tv":107.13,"id":12482925}]}]}
{"op":"mcm","clk":"11791796176","pt":1723051828912,"mc":[{"id":"1.231499799","rc":[{"batb":[[0,1.91,48.8],[1,1.74,17.32],[2,1.53,94.34]],"ltp":1.91,"tv":107.13,"id":12482925}]}]}
{"op":"mcm","clk":"11791861605","pt":1723052244504,"mc":[{"id":"1.231499799","rc":[{"batb":[[0,1.92,10],[1,1.91,48.8],[2,1.74,17.32]],"ltp":1.91,"tv":107.13,"id":12482925}]}]}
{"op":"mcm","clk":"11791862128","pt":1723052248133,"mc":[{"id":"1.231499799","rc":[{"batb":[[0,1.91,48.8],[1,1.74,17.32],[2,1.53,94.34]],"ltp":1.91,"tv":107.13,"id":12482925}]}]}
{"op":"mcm","clk":"11792069060","pt":1723053635897,"mc":[{"id":"1.231499799","rc":[{"trd":[[1.98,7.77]],"batb":[[1,1.91,28],[2,1.74,17.32]],"ltp":2.1,"tv":7.83,"id":25686043},{"trd":[[1.95,107.04]],"batb":[[0,1.92,10],[1,1.91,48.8],[2,1.74,17.32]],"ltp":1.91,"tv":107.14,"id":12482925}],"tv":114.97}]}
{"op":"mcm","clk":"11792069564","pt":1723053639300,"mc":[{"id":"1.231499799","rc":[{"batb":[[0,1.91,48.8],[1,1.74,17.32],[2,1.53,94.34]],"ltp":1.91,"tv":107.14,"id":12482925}]}]}
{"op":"mcm","clk":"11792070393","pt":1723053644638,"mc":[{"id":"1.231499799","rc":[{"batb":[[0,1.99,10],[1,1.98,45.31],[2,1.91,28]],"batl":[[0,2.14,25.48]],"ltp":2.1,"tv":7.83,"id":25686043},{"batb":[[0,1.92,10],[1,1.91,48.8],[2,1.74,17.32]],"ltp":1.91,"tv":107.14,"id":12482925}]}]}
{"op":"mcm","clk":"11792070945","pt":1723053647992,"mc":[{"id":"1.231499799","rc":[{"batb":[[0,1.98,45.31],[1,1.91,28],[2,1.74,17.32]],"ltp":2.1,"tv":7.83,"id":25686043},{"batb":[[0,1.91,48.8],[1,1.74,17.32],[2,1.53,94.34]],"ltp":1.91,"tv":107.14,"id":12482925}]}]}
{"op":"mcm","clk":"11792114926","pt":1723053917778,"mc":[{"id":"1.231499799","rc":[{"batb":[[0,1.99,10],[1,1.98,45.31],[2,1.91,28]],"ltp":2.1,"tv":7.83,"id":25686043},{"batb":[[0,1.92,10],[1,1.91,48.8],[2,1.74,17.32]],"ltp":1.91,"tv":107.14,"id":12482925}]}]}
{"op":"mcm","clk":"11792115494","pt":1723053921399,"mc":[{"id":"1.231499799","rc":[{"batb":[[0,1.98,45.31],[1,1.91,28],[2,1.74,17.32]],"ltp":2.1,"tv":7.83,"id":25686043},{"batb":[[0,1.91,48.8],[1,1.74,17.32],[2,1.53,94.34]],"ltp":1.91,"tv":107.14,"id":12482925}]}]}
{"op":"mcm","clk":"11792158429","pt":1723054156354,"mc":[{"id":"1.231499799","rc":[{"batb":[[0,1.99,10],[1,1.98,45.31],[2,1.91,28]],"ltp":2.1,"tv":7.83,"id":25686043},{"batb":[[0,1.92,10],[1,1.91,48.8],[2,1.74,17.32]],"ltp":1.91,"tv":107.14,"id":12482925}]}]}
{"op":"mcm","clk":"11792159242","pt":1723054160438,"mc":[{"id":"1.231499799","rc":[{"batb":[[0,1.98,45.31],[1,1.91,28],[2,1.74,17.32]],"ltp":2.1,"tv":7.83,"id":25686043},{"batb":[[0,1.91,48.8],[1,1.74,17.32],[2,1.53,94.34]],"ltp":1.91,"tv":107.14,"id":12482925}]}]}
{"op":"mcm","clk":"11792262663","pt":1723054758941,"mc":[{"id":"1.231499799","rc":[{"batb":[[0,1.99,10],[1,1.98,45.31],[2,1.91,28]],"ltp":2.1,"tv":7.83,"id":25686043},{"batb":[[0,1.92,10],[1,1.91,48.8],[2,1.74,17.32]],"ltp":1.91,"tv":107.14,"id":12482925}]}]}
{"op":"mcm","clk":"11792263184","pt":1723054762278,"mc":[{"id":"1.231499799","rc":[{"batb":[[0,1.98,45.31],[1,1.91,28],[2,1.74,17.32]],"ltp":2.1,"tv":7.83,"id":25686043},{"batb":[[0,1.91,48.8],[1,1.74,17.32],[2,1.53,94.34]],"ltp":1.91,"tv":107.14,"id":12482925}]}]}
{"op":"mcm","clk":"11792382958","pt":1723055492187,"mc":[{"id":"1.231499799","rc":[{"batb":[[0,1.99,10],[1,1.98,45.31],[2,1.91,28]],"ltp":2.1,"tv":7.83,"id":25686043},{"batb":[[0,1.92,10],[1,1.91,48.8],[2,1.74,17.32]],"ltp":1.91,"tv":107.14,"id":12482925}]}]}
{"op":"mcm","clk":"11792383511","pt":1723055496204,"mc":[{"id":"1.231499799","rc":[{"batb":[[0,1.98,45.31],[1,1.91,28],[2,1.74,17.32]],"ltp":2.1,"tv":7.83,"id":25686043},{"batb":[[0,1.91,48.8],[1,1.74,17.32],[2,1.53,94.34]],"ltp":1.91,"tv":107.14,"id":12482925}]}]}
{"op":"mcm","clk":"11792433998","pt":1723055821851,"mc":[{"id":"1.231499799","rc":[{"batb":[[0,1.99,10],[1,1.98,45.31],[2,1.91,28]],"ltp":2.1,"tv":7.83,"id":25686043},{"batb":[[0,1.92,10],[1,1.91,48.8],[2,1.74,17.32]],"ltp":1.91,"tv":107.14,"id":12482925}]}]}
{"op":"mcm","clk":"11792434567","pt":1723055825364,"mc":[{"id":"1.231499799","rc":[{"batb":[[0,1.98,45.31],[1,1.91,28],[2,1.74,17.32]],"ltp":2.1,"tv":7.83,"id":25686043},{"batb":[[0,1.91,48.8],[1,1.74,17.32],[2,1.53,94.34]],"ltp":1.91,"tv":107.14,"id":12482925}]}]}
{"op":"mcm","clk":"11792492556","pt":1723056167879,"mc":[{"id":"1.231499799","rc":[{"batb":[[0,1.99,10],[1,1.98,45.31],[2,1.91,28]],"ltp":2.1,"tv":7.83,"id":25686043},{"batb":[[0,1.92,10],[1,1.91,48.8],[2,1.74,17.32]],"ltp":1.91,"tv":107.14,"id":12482925}]}]}
{"op":"mcm","clk":"11792493215","pt":1723056171863,"mc":[{"id":"1.231499799","rc":[{"batb":[[0,1.98,45.31],[1,1.91,28],[2,1.74,17.32]],"ltp":2.1,"tv":7.83,"id":25686043},{"batb":[[0,1.91,48.8],[1,1.74,17.32],[2,1.53,94.34]],"ltp":1.91,"tv":107.14,"id":12482925}]}]}
{"op":"mcm","clk":"11792538008","pt":1723056471070,"mc":[{"id":"1.231499799","rc":[{"batb":[[0,1.99,10],[1,1.98,45.31],[2,1.91,28]],"ltp":2.1,"tv":7.83,"id":25686043},{"batb":[[0,1.92,10],[1,1.91,48.8],[2,1.74,17.32]],"ltp":1.91,"tv":107.14,"id":12482925}]}]}
{"op":"mcm","clk":"11792538490","pt":1723056474365,"mc":[{"id":"1.231499799","rc":[{"batb":[[0,1.98,45.31],[1,1.91,28],[2,1.74,17.32]],"ltp":2.1,"tv":7.83,"id":25686043},{"batb":[[0,1.91,48.8],[1,1.74,17.32],[2,1.53,94.34]],"ltp":1.91,"tv":107.14,"id":12482925}]}]}
{"op":"mcm","clk":"11792555026","pt":1723056596831,"mc":[{"id":"1.231499799","rc":[{"batb":[[0,1.99,10],[1,1.98,45.31],[2,1.91,28]],"ltp":2.1,"tv":7.83,"id":25686043},{"batb":[[0,1.92,10],[1,1.91,48.8],[2,1.74,17.32]],"ltp":1.91,"tv":107.14,"id":12482925}]}]}
{"op":"mcm","clk":"11792555458","pt":1723056600053,"mc":[{"id":"1.231499799","rc":[{"batb":[[0,1.98,45.31],[1,1.91,28],[2,1.74,17.32]],"ltp":2.1,"tv":7.83,"id":25686043},{"batb":[[0,1.91,48.8],[1,1.74,17.32],[2,1.53,94.34]],"ltp":1.91,"tv":107.14,"id":12482925}]}]}
{"op":"mcm","clk":"11792561467","pt":1723056643930,"mc":[{"id":"1.231499799","rc":[{"batb":[[0,1.99,10],[1,1.98,45.31],[2,1.91,28]],"ltp":2.1,"tv":7.83,"id":25686043},{"batb":[[0,1.92,10],[1,1.91,48.8],[2,1.74,17.32]],"ltp":1.91,"tv":107.14,"id":12482925}]}]}
{"op":"mcm","clk":"11792561967","pt":1723056647460,"mc":[{"id":"1.231499799","rc":[{"batb":[[0,1.98,45.31],[1,1.91,28],[2,1.74,17.32]],"ltp":2.1,"tv":7.83,"id":25686043},{"batb":[[0,1.91,48.8],[1,1.74,17.32],[2,1.53,94.34]],"ltp":1.91,"tv":107.14,"id":12482925}]}]}
{"op":"mcm","clk":"11792662617","pt":1723057553096,"mc":[{"id":"1.231499799","rc":[{"trd":[[1.98,7.77]],"batb":[[0,1.99,10],[1,1.98,45.31],[2,1.91,28]],"ltp":2.1,"tv":7.83,"id":25686043},{"trd":[[1.95,107.04]],"batb":[[0,1.92,10],[1,1.91,48.8],[2,1.74,17.32]],"ltp":1.91,"tv":107.14,"id":12482925}],"tv":114.97}]}
{"op":"mcm","clk":"11792663110","pt":1723057557038,"mc":[{"id":"1.231499799","rc":[{"batb":[[0,1.98,45.31],[1,1.91,28],[2,1.74,17.32]],"ltp":2.1,"tv":7.83,"id":25686043},{"batb":[[0,1.91,48.8],[1,1.74,17.32],[2,1.53,94.34]],"ltp":1.91,"tv":107.14,"id":12482925}]}]}
{"op":"mcm","clk":"11792744702","pt":1723058143246,"mc":[{"id":"1.231499799","rc":[{"batb":[[0,1.99,10],[1,1.98,45.31],[2,1.91,28]],"ltp":2.1,"tv":7.83,"id":25686043},{"batb":[[0,1.92,10],[1,1.91,48.8],[2,1.74,17.32]],"ltp":1.91,"tv":107.14,"id":12482925}]}]}
{"op":"mcm","clk":"11792745275","pt":1723058147652,"mc":[{"id":"1.231499799","rc":[{"batb":[[0,1.98,45.31],[1,1.91,28],[2,1.74,17.32]],"ltp":2.1,"tv":7.83,"id":25686043},{"batb":[[0,1.91,48.8],[1,1.74,17.32],[2,1.53,94.34]],"ltp":1.91,"tv":107.14,"id":12482925}]}]}
{"op":"mcm","clk":"11792801960","pt":1723058699023,"mc":[{"id":"1.231499799","rc":[{"batb":[[0,1.99,10],[1,1.98,45.31],[2,1.91,28]],"ltp":2.1,"tv":7.83,"id":25686043},{"trd":[[1.91,7.42]],"batb":[[0,1.92,10],[1,1.91,45.14],[2,1.74,17.32]],"ltp":1.91,"tv":114.46,"id":12482925}],"tv":122.3}]}
{"op":"mcm","clk":"11792802293","pt":1723058702534,"mc":[{"id":"1.231499799","rc":[{"batb":[[0,1.98,45.31],[1,1.91,28],[2,1.74,17.32]],"ltp":2.1,"tv":7.83,"id":25686043},{"batb":[[0,1.91,45.14],[1,1.74,17.32],[2,1.53,94.34]],"ltp":1.91,"tv":114.46,"id":12482925}]}]}
{"op":"mcm","clk":"11792802448","pt":1723058704011,"mc":[{"id":"1.231499799","rc":[{"batb":[[0,1.91,48.8]],"ltp":1.91,"tv":114.46,"id":12482925}]}]}
{"op":"mcm","clk":"11792822884","pt":1723058935971,"mc":[{"id":"1.231499799","rc":[{"batb":[[2,1.85,4.58]],"ltp":2.1,"tv":7.83,"id":25686043}]}]}
{"op":"mcm","clk":"11792822915","pt":1723058936280,"mc":[{"id":"1.231499799","rc":[{"batb":[[0,1.99,10],[1,1.98,45.31],[2,1.91,28]],"ltp":2.1,"tv":7.83,"id":25686043},{"batb":[[0,1.92,10],[1,1.91,48.8],[2,1.74,17.32]],"ltp":1.91,"tv":114.46,"id":12482925}]}]}
{"op":"mcm","clk":"11792823191","pt":1723058939552,"mc":[{"id":"1.231499799","rc":[{"batb":[[0,1.98,45.31],[1,1.91,28],[2,1.85,4.58]],"ltp":2.1,"tv":7.83,"id":25686043},{"batb":[[0,1.91,48.8],[1,1.74,17.32],[2,1.53,94.34]],"ltp":1.91,"tv":114.46,"id":12482925}]}]}
{"op":"mcm","clk":"11792824267","pt":1723058951301,"mc":[{"id":"1.231499799","rc":[{"batb":[[0,1.99,10],[1,1.98,45.31],[2,1.91,28]],"ltp":2.1,"tv":7.83,"id":25686043},{"batb":[[0,1.92,10],[1,1.91,48.8],[2,1.76,4.58]],"ltp":1.91,"tv":114.46,"id":12482925}]}]}
{"op":"mcm","clk":"11792824532","pt":1723058954677,"mc":[{"id":"1.231499799","rc":[{"batb":[[0,1.98,45.31],[1,1.91,28],[2,1.85,4.58]],"ltp":2.1,"tv":7.83,"id":25686043},{"batb":[[0,1.91,48.8],[1,1.76,4.58],[2,1.74,17.32]],"ltp":1.91,"tv":114.46,"id":12482925}]}]}
{"op":"mcm","clk":"11792825002","pt":1723058959984,"mc":[{"id":"1.231499799","rc":[{"batb":[[2,1.74,17.32]],"ltp":2.1,"tv":7.83,"id":25686043}]}]}
{"op":"mcm","clk":"11792825019","pt":1723058960188,"mc":[{"id":"1.231499799","rc":[{"batb":[[0,1.99,10],[1,1.98,45.31],[2,1.91,28]],"ltp":2.1,"tv":7.83,"id":25686043},{"batb":[[0,1.92,10],[1,1.91,48.8],[2,1.76,4.58]],"ltp":1.91,"tv":114.46,"id":12482925}]}]}
{"op":"mcm","clk":"11792825187","pt":1723058962108,"mc":[{"id":"1.231499799","rc":[{"batb":[[2,1.74,17.32]],"ltp":1.91,"tv":114.46,"id":12482925}]}]}
{"op":"mcm","clk":"11792825307","pt":1723058963521,"mc":[{"id":"1.231499799","rc":[{"batb":[[0,1.98,45.31],[1,1.91,28],[2,1.74,17.32]],"ltp":2.1,"tv":7.83,"id":25686043},{"batb":[[0,1.91,48.8],[1,1.74,17.32],[2,1.53,94.34]],"ltp":1.91,"tv":114.46,"id":12482925}]}]}
{"op":"mcm","clk":"11792863650","pt":1723059351725,"mc":[{"id":"1.231499799","rc":[{"batb":[[0,1.99,10],[1,1.98,45.31],[2,1.91,28]],"ltp":2.1,"tv":7.83,"id":25686043},{"batb":[[0,1.92,10],[1,1.91,48.8],[2,1.74,17.32]],"ltp":1.91,"tv":114.46,"id":12482925}]}]}
{"op":"mcm","clk":"11792863949","pt":1723059355208,"mc":[{"id":"1.231499799","rc":[{"batb":[[0,1.98,45.31],[1,1.91,28],[2,1.74,17.32]],"ltp":2.1,"tv":7.83,"id":25686043},{"batb":[[0,1.91,48.8],[1,1.74,17.32],[2,1.53,94.34]],"ltp":1.91,"tv":114.46,"id":12482925}]}]}
{"op":"mcm","clk":"11792880329","pt":1723059533811,"mc":[{"id":"1.231499799","rc":[{"batb":[[0,1.99,10],[1,1.98,45.31],[2,1.91,28]],"batl":[[0,2.14,87.7]],"ltp":2.1,"tv":7.83,"id":25686043},{"trd":[[1.91,105.02]],"batb":[[0,1.74,17.32],[1,1.53,94.34],[2,1.48,104.17]],"batl":[[0,1.9,108.87],[1,2.02,2],[2,2.3,1]],"ltp":1.91,"tv":212.06,"id":12482925}],"tv":219.89}]}
{"op":"mcm","clk":"11792880621","pt":1723059536822,"mc":[{"id":"1.231499799","rc":[{"batb":[[0,1.98,45.31],[1,1.91,28],[2,1.74,17.32]],"ltp":2.1,"tv":7.83,"id":25686043}]}]}
{"op":"mcm","clk":"11792880697","pt":1723059537707,"mc":[{"id":"1.231499799","rc":[{"batb":[[0,1.87,51.04],[1,1.74,17.32],[2,1.53,94.34]],"ltp":1.91,"tv":212.06,"id":12482925}]}]}
{"op":"mcm","clk":"11792880820","pt":1723059539012,"mc":[{"id":"1.231499799","rc":[{"trd":[[2.14,41.79]],"batb":[[0,1.99,10],[1,1.98,45.31],[2,1.91,28]],"batl":[[0,2.14,45.91]],"ltp":2.14,"tv":49.62,"id":25686043},{"trd":[[1.87,149.9],[1.88,20]],"batb":[[0,1.74,17.32],[1,1.53,94.34],[2,1.48,104.17]],"batl":[[0,2.02,2],[1,2.3,1],[2,2.3,0]],"ltp":1.87,"tv":381.97,"id":12482925}],"tv":431.59}]}
{"op":"mcm","clk":"11792880935","pt":1723059540208,"mc":[{"id":"1.231499799","rc":[{"batb":[[0,1.75,67.05],[1,1.74,17.32],[2,1.53,94.34]],"ltp":1.87,"tv":381.97,"id":12482925}]}]}
{"op":"mcm","clk":"11792881112","pt":1723059542321,"mc":[{"id":"1.231499799","rc":[{"batb":[[0,1.98,45.31],[1,1.91,28],[2,1.74,17.32]],"ltp":2.14,"tv":49.62,"id":25686043},{"batb":[[0,1.76,10],[1,1.75,67.05],[2,1.74,17.32]],"ltp":1.87,"tv":381.97,"id":12482925}]}]}
{"op":"mcm","clk":"11792881421","pt":1723059545596,"mc":[{"id":"1.231499799","rc":[{"batb":[[0,1.75,67.05],[1,1.74,17.32],[2,1.53,94.34]],"ltp":1.87,"tv":381.97,"id":12482925}]}]}
{"op":"mcm","clk":"11792887047","pt":1723059603054,"mc":[{"id":"1.231499799","rc":[{"batb":[[0,1.76,10],[1,1.75,67.05],[2,1.74,17.32]],"ltp":1.87,"tv":381.97,"id":12482925}]}]}
{"op":"mcm","clk":"11792887468","pt":1723059607167,"mc":[{"id":"1.231499799","rc":[{"batb":[[0,1.75,67.05],[1,1.74,17.32],[2,1.53,94.34]],"ltp":1.87,"tv":381.97,"id":12482925}]}]}
{"op":"mcm","clk":"11792910996","pt":1723059845740,"mc":[{"id":"1.231499799","rc":[{"batb":[[1,1.93,8.4],[2,1.91,28]],"ltp":2.14,"tv":49.62,"id":25686043},{"batb":[[0,1.84,8.81],[1,1.76,10],[2,1.75,67.05]],"ltp":1.87,"tv":381.97,"id":12482925}]}]}
{"op":"mcm","clk":"11792911322","pt":1723059849127,"mc":[{"id":"1.231499799","rc":[{"batb":[[1,1.75,67.05],[2,1.74,17.32]],"ltp":1.87,"tv":381.97,"id":12482925}]}]}
{"op":"mcm","clk":"11792928515","pt":1723060040960,"mc":[{"id":"1.231499799","rc":[{"batb":[[0,1.85,10],[1,1.84,8.81]],"ltp":1.87,"tv":381.97,"id":12482925}]}]}
{"op":"mcm","clk":"11792928833","pt":1723060044262,"mc":[{"id":"1.231499799","rc":[{"batb":[[0,1.84,8.81],[1,1.74,17.32],[2,1.53,94.34]],"ltp":1.87,"tv":381.97,"id":12482925}]}]}
{"op":"mcm","clk":"11792951912","pt":1723060279622,"mc":[{"id":"1.231499799","rc":[{"batb":[[0,1.85,10],[1,1.84,8.81],[2,1.74,17.32]],"ltp":1.87,"tv":381.97,"id":12482925}]}]}
{"op":"mcm","clk":"11792952308","pt":1723060283764,"mc":[{"id":"1.231499799","rc":[{"batb":[[0,1.84,8.81],[1,1.74,17.32],[2,1.53,94.34]],"ltp":1.87,"tv":381.97,"id":12482925}]}]}
{"op":"mcm","clk":"11792999442","pt":1723060915374,"mc":[{"id":"1.231499799","rc":[{"trd":[[1.87,149.87],[1.88,20],[1.91,105]],"batb":[[0,1.85,10],[1,1.84,8.81],[2,1.74,17.32]],"ltp":1.87,"tv":381.91,"id":12482925}],"tv":431.54}]}
{"op":"mcm","clk":"11792999659","pt":1723060918795,"mc":[{"id":"1.231499799","rc":[{"batb":[[0,1.84,8.81],[1,1.74,17.32],[2,1.53,94.34]],"ltp":1.87,"tv":381.91,"id":12482925}]}]}
{"op":"mcm","clk":"11792999996","pt":1723060923880,"mc":[{"id":"1.231499799","rc":[{"batb":[[0,1.85,10],[1,1.84,8.81],[2,1.74,17.32]],"ltp":1.87,"tv":381.91,"id":12482925}]}]}
{"op":"mcm","clk":"11793000273","pt":1723060928180,"mc":[{"id":"1.231499799","rc":[{"batb":[[0,1.84,8.81],[1,1.74,17.32],[2,1.53,94.34]],"ltp":1.87,"tv":381.91,"id":12482925}]}]}
{"op":"mcm","clk":"11793014398","pt":1723061179866,"mc":[{"id":"1.231499799","rc":[{"batb":[[1,1.91,28],[2,1.74,17.32]],"ltp":2.14,"tv":49.62,"id":25686043},{"batb":[[0,1.77,66.29],[1,1.75,10],[2,1.74,17.32]],"ltp":1.87,"tv":381.91,"id":12482925}]}]}
{"op":"mcm","clk":"11793014602","pt":1723061183233,"mc":[{"id":"1.231499799","rc":[{"batb":[[1,1.74,17.32],[2,1.53,94.34]],"ltp":1.87,"tv":381.91,"id":12482925}]}]}
{"op":"mcm","clk":"11793030611","pt":1723061451315,"mc":[{"id":"1.231499799","rc":[{"batb":[[0,1.79,10],[1,1.78,4.98],[2,1.77,66.29]],"ltp":1.87,"tv":381.91,"id":12482925}]}]}
{"op":"mcm","clk":"11793030645","pt":1723061452098,"mc":[{"id":"1.231499799","rc":[{"batb":[[1,1.77,66.29],[2,1.74,17.32]],"ltp":1.87,"tv":381.91,"id":12482925}]}]}
{"op":"mcm","clk":"11793030800","pt":1723061454691,"mc":[{"id":"1.231499799","rc":[{"batb":[[0,1.77,66.29],[1,1.74,17.32],[2,1.53,94.34]],"ltp":1.87,"tv":381.91,"id":12482925}]}]}
{"op":"mcm","clk":"11793033197","pt":1723061497963,"mc":[{"id":"1.231499799","rc":[{"batb":[[0,1.78,4.98],[1,1.77,66.29],[2,1.74,17.32]],"ltp":1.87,"tv":381.91,"id":12482925}]}]}
{"op":"mcm","clk":"11793033205","pt":1723061498169,"mc":[{"id":"1.231499799","rc":[{"batb":[[0,1.79,10],[1,1.78,4.98],[2,1.77,66.29]],"ltp":1.87,"tv":381.91,"id":12482925}]}]}
{"op":"mcm","clk":"11793033317","pt":1723061499842,"mc":[{"id":"1.231499799","rc":[{"batb":[[1,1.77,66.29],[2,1.74,17.32]],"ltp":1.87,"tv":381.91,"id":12482925}]}]}
{"op":"mcm","clk":"11793033467","pt":1723061501749,"mc":[{"id":"1.231499799","rc":[{"batb":[[0,1.77,66.29],[1,1.74,17.32],[2,1.53,94.34]],"ltp":1.87,"tv":381.91,"id":12482925}]}]}
{"op":"mcm","clk":"11793036012","pt":1723061548803,"mc":[{"id":"1.231499799","rc":[{"batb":[[0,1.79,10],[1,1.78,4.98],[2,1.77,66.29]],"ltp":1.87,"tv":381.91,"id":12482925}]}]}
{"op":"mcm","clk":"11793036075","pt":1723061550090,"mc":[{"id":"1.231499799","rc":[{"batb":[[1,1.77,66.29],[2,1.74,17.32]],"ltp":1.87,"tv":381.91,"id":12482925}]}]}
{"op":"mcm","clk":"11793036180","pt":1723061552103,"mc":[{"id":"1.231499799","rc":[{"batb":[[0,1.77,66.29],[1,1.74,17.32],[2,1.53,94.34]],"ltp":1.87,"tv":381.91,"id":12482925}]}]}
{"op":"mcm","clk":"11793038808","pt":1723061599617,"mc":[{"id":"1.231499799","rc":[{"batb":[[0,1.79,10],[1,1.78,4.98],[2,1.77,66.29]],"ltp":1.87,"tv":381.91,"id":12482925}]}]}
{"op":"mcm","clk":"11793038840","pt":1723061600241,"mc":[{"id":"1.231499799","rc":[{"batb":[[1,1.77,66.29],[2,1.74,17.32]],"ltp":1.87,"tv":381.91,"id":12482925}]}]}
{"op":"mcm","clk":"11793038969","pt":1723061602951,"mc":[{"id":"1.231499799","rc":[{"batb":[[0,1.77,66.29],[1,1.74,17.32],[2,1.53,94.34]],"ltp":1.87,"tv":381.91,"id":12482925}]}]}
{"op":"mcm","clk":"11793039280","pt":1723061608428,"mc":[{"id":"1.231499799","rc":[{"batb":[[0,1.78,10],[1,1.77,66.29],[2,1.74,17.32]],"ltp":1.87,"tv":381.91,"id":12482925}]}]}
{"op":"mcm","clk":"11793039500","pt":1723061612355,"mc":[{"id":"1.231499799","rc":[{"batb":[[0,1.77,66.29],[1,1.74,17.32],[2,1.53,94.34]],"ltp":1.87,"tv":381.91,"id":12482925}]}]}
{"op":"mcm","clk":"11793041571","pt":1723061650192,"mc":[{"id":"1.231499799","rc":[{"batb":[[0,1.79,10],[1,1.78,4.98],[2,1.77,66.29]],"ltp":1.87,"tv":381.91,"id":12482925}]}]}
{"op":"mcm","clk":"11793041635","pt":1723061651070,"mc":[{"id":"1.231499799","rc":[{"batb":[[1,1.77,66.29],[2,1.74,17.32]],"ltp":1.87,"tv":381.91,"id":12482925}]}]}
{"op":"mcm","clk":"11793041768","pt":1723061653494,"mc":[{"id":"1.231499799","rc":[{"batb":[[0,1.77,66.29],[1,1.74,17.32],[2,1.53,94.34]],"ltp":1.87,"tv":381.91,"id":12482925}]}]}
{"op":"mcm","clk":"11793044349","pt":1723061699836,"mc":[{"id":"1.231499799","rc":[{"batb":[[0,1.79,10],[1,1.78,4.98],[2,1.77,66.29]],"ltp":1.87,"tv":381.91,"id":12482925}]}]}
{"op":"mcm","clk":"11793044470","pt":1723061702078,"mc":[{"id":"1.231499799","rc":[{"batb":[[1,1.77,66.29],[2,1.74,17.32]],"ltp":1.87,"tv":381.91,"id":12482925}]}]}
{"op":"mcm","clk":"11793044523","pt":1723061703078,"mc":[{"id":"1.231499799","rc":[{"batb":[[0,1.77,66.29],[1,1.74,17.32],[2,1.53,94.34]],"ltp":1.87,"tv":381.91,"id":12482925}]}]}
{"op":"mcm","clk":"11793046852","pt":1723061748809,"mc":[{"id":"1.231499799","rc":[{"batb":[[0,1.79,10],[1,1.78,4.98],[2,1.77,66.29]],"ltp":1.87,"tv":381.91,"id":12482925}]}]}
{"op":"mcm","clk":"11793046880","pt":1723061749428,"mc":[{"id":"1.231499799","rc":[{"batb":[[1,1.77,66.29],[2,1.74,17.32]],"ltp":1.87,"tv":381.91,"id":12482925}]}]}
{"op":"mcm","clk":"11793047034","pt":1723061752231,"mc":[{"id":"1.231499799","rc":[{"batb":[[0,1.77,66.29],[1,1.74,17.32],[2,1.53,94.34]],"ltp":1.87,"tv":381.91,"id":12482925}]}]}
{"op":"mcm","clk":"11793049193","pt":1723061796868,"mc":[{"id":"1.231499799","rc":[{"batb":[[0,1.79,10],[1,1.78,4.98],[2,1.77,66.29]],"ltp":1.87,"tv":381.91,"id":12482925}]}]}
{"op":"mcm","clk":"11793049253","pt":1723061798155,"mc":[{"id":"1.231499799","rc":[{"batb":[[1,1.77,66.29],[2,1.74,17.32]],"ltp":1.87,"tv":381.91,"id":12482925}]}]}
{"op":"mcm","clk":"11793049361","pt":1723061800380,"mc":[{"id":"1.231499799","rc":[{"batb":[[0,1.77,66.29],[1,1.74,17.32],[2,1.53,94.34]],"ltp":1.87,"tv":381.91,"id":12482925}]}]}
{"op":"mcm","clk":"11793051856","pt":1723061846929,"mc":[{"id":"1.231499799","rc":[{"batb":[[0,1.78,4.98],[1,1.77,66.29],[2,1.74,17.32]],"ltp":1.87,"tv":381.91,"id":12482925}]}]}
{"op":"mcm","clk":"11793051865","pt":1723061847133,"mc":[{"id":"1.231499799","rc":[{"batb":[[0,1.79,10],[1,1.78,4.98],[2,1.77,66.29]],"ltp":1.87,"tv":381.91,"id":12482925}]}]}
{"op":"mcm","clk":"11793051951","pt":1723061848735,"mc":[{"id":"1.231499799","rc":[{"batb":[[0,1.99,10],[1,1.98,45.31],[2,1.91,28]],"batl":[[0,2.28,4.71]],"ltp":2.14,"tv":49.62,"id":25686043},{"batb":[[1,1.77,66.29],[2,1.74,17.32]],"ltp":1.87,"tv":381.91,"id":12482925}]}]}
{"op":"mcm","clk":"11793052040","pt":1723061850530,"mc":[{"id":"1.231499799","rc":[{"batb":[[0,1.77,66.29],[1,1.74,17.32],[2,1.53,94.34]],"ltp":1.87,"tv":381.91,"id":12482925}]}]}
{"op":"mcm","clk":"11793052135","pt":1723061852127,"mc":[{"id":"1.231499799","rc":[{"batb":[[0,1.98,45.31],[1,1.91,28],[2,1.74,17.32]],"ltp":2.14,"tv":49.62,"id":25686043}]}]}
{"op":"mcm","clk":"11793054202","pt":1723061897597,"mc":[{"id":"1.231499799","rc":[{"batb":[[0,1.79,10],[1,1.78,4.98],[2,1.77,66.29]],"ltp":1.87,"tv":381.91,"id":12482925}]}]}
{"op":"mcm","clk":"11793054331","pt":1723061898990,"mc":[{"id":"1.231499799","rc":[{"batb":[[0,1.99,10],[1,1.98,45.31],[2,1.91,28]],"batl":[[0,2.28,4.71]],"ltp":2.14,"tv":49.62,"id":25686043},{"batb":[[1,1.77,66.29],[2,1.74,17.32]],"ltp":1.87,"tv":381.91,"id":12482925}]}]}
{"op":"mcm","clk":"11793054428","pt":1723061900999,"mc":[{"id":"1.231499799","rc":[{"batb":[[0,1.77,66.29],[1,1.74,17.32],[2,1.53,94.34]],"ltp":1.87,"tv":381.91,"id":12482925}]}]}
{"op":"mcm","clk":"11793054556","pt":1723061903219,"mc":[{"id":"1.231499799","rc":[{"batb":[[0,1.98,45.31],[1,1.91,28],[2,1.74,17.32]],"ltp":2.14,"tv":49.62,"id":25686043},{"batb":[[0,1.78,10],[1,1.77,66.29],[2,1.74,17.32]],"ltp":1.87,"tv":381.91,"id":12482925}]}]}
{"op":"mcm","clk":"11793054711","pt":1723061906626,"mc":[{"id":"1.231499799","rc":[{"batb":[[0,1.77,66.29],[1,1.74,17.32],[2,1.53,94.34]],"ltp":1.87,"tv":381.91,"id":12482925}]}]}
{"op":"mcm","clk":"11793056589","pt":1723061947850,"mc":[{"id":"1.231499799","rc":[{"batb":[[0,1.78,4.98],[1,1.77,66.29],[2,1.74,17.32]],"ltp":1.87,"tv":381.91,"id":12482925}]}]}
{"op":"mcm","clk":"11793056603","pt":1723061948157,"mc":[{"id":"1.231499799","rc":[{"batb":[[0,1.79,10],[1,1.78,4.98],[2,1.77,66.29]],"ltp":1.87,"tv":381.91,"id":12482925}]}]}
{"op":"mcm","clk":"11793056680","pt":1723061949550,"mc":[{"id":"1.231499799","rc":[{"batb":[[0,1.99,10],[1,1.98,45.31],[2,1.91,28]],"batl":[[0,2.28,4.71]],"ltp":2.14,"tv":49.62,"id":25686043},{"batb":[[1,1.77,66.29],[2,1.74,17.32]],"ltp":1.87,"tv":381.91,"id":12482925}]}]}
{"op":"mcm","clk":"11793056778","pt":1723061951559,"mc":[{"id":"1.231499799","rc":[{"batb":[[0,1.77,66.29],[1,1.74,17.32],[2,1.53,94.34]],"ltp":1.87,"tv":381.91,"id":12482925}]}]}
{"op":"mcm","clk":"11793056838","pt":1723061952789,"mc":[{"id":"1.231499799","rc":[{"batb":[[0,1.98,45.31],[1,1.91,28],[2,1.74,17.32]],"ltp":2.14,"tv":49.62,"id":25686043}]}]}
{"op":"mcm","clk":"11793058182","pt":1723061978128,"mc":[{"id":"1.231499799","rc":[{"batb":[[0,1.78,10],[1,1.77,66.29],[2,1.74,17.32]],"ltp":1.87,"tv":381.91,"id":12482925}]}]}
{"op":"mcm","clk":"11793058386","pt":1723061981427,"mc":[{"id":"1.231499799","rc":[{"batb":[[0,1.77,66.29],[1,1.74,17.32],[2,1.53,94.34]],"ltp":1.87,"tv":381.91,"id":12482925}]}]}
{"op":"mcm","clk":"11793059312","pt":1723061998238,"mc":[{"id":"1.231499799","rc":[{"batb":[[0,1.79,10],[1,1.78,4.98],[2,1.77,66.29]],"ltp":1.87,"tv":381.91,"id":12482925}]}]}
{"op":"mcm","clk":"11793059440","pt":1723062000248,"mc":[{"id":"1.231499799","rc":[{"batb":[[0,1.99,10],[1,1.98,45.31],[2,1.91,28]],"batl":[[0,2.28,4.71]],"ltp":2.14,"tv":49.62,"id":25686043},{"batb":[[1,1.77,66.29],[2,1.74,17.32]],"ltp":1.87,"tv":381.91,"id":12482925}]}]}
{"op":"mcm","clk":"11793059499","pt":1723062001484,"mc":[{"id":"1.231499799","rc":[{"batb":[[0,1.77,66.29],[1,1.74,17.32],[2,1.53,94.34]],"ltp":1.87,"tv":381.91,"id":12482925}]}]}
{"op":"mcm","clk":"11793059622","pt":1723062003661,"mc":[{"id":"1.231499799","rc":[{"batb":[[0,1.98,45.31],[1,1.91,28],[2,1.74,17.32]],"ltp":2.14,"tv":49.62,"id":25686043},{"batb":[[0,1.78,10],[1,1.77,66.29],[2,1.74,17.32]],"ltp":1.87,"tv":381.91,"id":12482925}]}]}
{"op":"mcm","clk":"11793059802","pt":1723062007169,"mc":[{"id":"1.231499799","rc":[{"batb":[[0,1.77,66.29],[1,1.74,17.32],[2,1.53,94.34]],"ltp":1.87,"tv":381.91,"id":12482925}]}]}
{"op":"mcm","clk":"11793061172","pt":1723062033389,"mc":[{"id":"1.231499799","rc":[{"batb":[[0,1.78,10],[1,1.77,66.29],[2,1.74,17.32]],"ltp":1.87,"tv":381.91,"id":12482925}]}]}
{"op":"mcm","clk":"11793061382","pt":1723062037112,"mc":[{"id":"1.231499799","rc":[{"batb":[[0,1.77,66.29],[1,1.74,17.32],[2,1.53,94.34]],"ltp":1.87,"tv":381.91,"id":12482925}]}]}
{"op":"mcm","clk":"11793061882","pt":1723062047011,"mc":[{"id":"1.231499799","rc":[{"batb":[[0,1.78,14.98],[1,1.77,66.29],[2,1.74,17.32]],"ltp":1.87,"tv":381.91,"id":12482925}]}]}
{"op":"mcm","clk":"11793062000","pt":1723062049532,"mc":[{"id":"1.231499799","rc":[{"batb":[[0,1.99,10],[1,1.98,45.31],[2,1.91,28]],"batl":[[0,2.28,4.7]],"ltp":2.14,"tv":49.62,"id":25686043}]}]}
{"op":"mcm","clk":"11793062061","pt":1723062050616,"mc":[{"id":"1.231499799","rc":[{"batb":[[0,1.78,4.98]],"ltp":1.87,"tv":381.91,"id":12482925}]}]}
{"op":"mcm","clk":"11793062178","pt":1723062052827,"mc":[{"id":"1.231499799","rc":[{"batb":[[0,1.98,45.31],[1,1.91,28],[2,1.74,17.32]],"ltp":2.14,"tv":49.62,"id":25686043},{"batb":[[0,1.79,10],[1,1.78,4.98],[2,1.77,66.29]],"ltp":1.87,"tv":381.91,"id":12482925}]}]}
{"op":"mcm","clk":"11793062227","pt":1723062054011,"mc":[{"id":"1.231499799","rc":[{"batb":[[1,1.77,66.29],[2,1.74,17.32]],"ltp":1.87,"tv":381.91,"id":12482925}]}]}
{"op":"mcm","clk":"11793062313","pt":1723062056016,"mc":[{"id":"1.231499799","rc":[{"batb":[[0,1.77,66.29],[1,1.74,17.32],[2,1.53,94.34]],"ltp":1.87,"tv":381.91,"id":12482925}]}]}
{"op":"mcm","clk":"11793062702","pt":1723062064118,"mc":[{"id":"1.231499799","rc":[{"batb":[[0,1.78,10],[1,1.77,66.29],[2,1.74,17.32]],"ltp":1.87,"tv":381.91,"id":12482925}]}]}
{"op":"mcm","clk":"11793062907","pt":1723062067619,"mc":[{"id":"1.231499799","rc":[{"batb":[[0,1.77,66.29],[1,1.74,17.32],[2,1.53,94.34]],"ltp":1.87,"tv":381.91,"id":12482925}]}]}
{"op":"mcm","clk":"11793063282","pt":1723062077054,"mc":[{"id":"1.231499799","rc":[{"batb":[[0,1.78,10],[1,1.77,66.29],[2,1.74,17.32]],"ltp":1.87,"tv":381.91,"id":12482925}]}]}
{"op":"mcm","clk":"11793063476","pt":1723062081242,"mc":[{"id":"1.231499799","rc":[{"batb":[[0,1.77,66.29],[1,1.74,17.32],[2,1.53,94.34]],"ltp":1.87,"tv":381.91,"id":12482925}]}]}
{"op":"mcm","clk":"11793063597","pt":1723062083877,"mc":[{"id":"1.231499799","rc":[{"batb":[[0,1.78,10],[1,1.77,66.29],[2,1.74,17.32]],"ltp":1.87,"tv":381.91,"id":12482925}]}]}
{"op":"mcm","clk":"11793063771","pt":1723062087347,"mc":[{"id":"1.231499799","rc":[{"batb":[[0,1.77,66.29],[1,1.74,17.32],[2,1.53,94.34]],"ltp":1.87,"tv":381.91,"id":12482925}]}]}
{"op":"mcm","clk":"11793064096","pt":1723062092588,"mc":[{"id":"1.231499799","rc":[{"batb":[[0,1.78,10],[1,1.77,66.29],[2,1.74,17.32]],"ltp":1.87,"tv":381.91,"id":12482925}]}]}
{"op":"mcm","clk":"11793064320","pt":1723062096498,"mc":[{"id":"1.231499799","rc":[{"batb":[[0,1.78,4.98]],"ltp":1.87,"tv":381.91,"id":12482925}]}]}
{"op":"mcm","clk":"11793064495","pt":1723062099183,"mc":[{"id":"1.231499799","rc":[{"batb":[[0,1.79,10],[1,1.78,4.98],[2,1.77,66.29]],"ltp":1.87,"tv":381.91,"id":12482925}]}]}
{"op":"mcm","clk":"11793064581","pt":1723062100996,"mc":[{"id":"1.231499799","rc":[{"batb":[[1,1.77,66.29],[2,1.74,17.32]],"ltp":1.87,"tv":381.91,"id":12482925}]}]}
{"op":"mcm","clk":"11793064590","pt":1723062101199,"mc":[{"id":"1.231499799","rc":[{"batb":[[0,1.99,10],[1,1.98,45.31],[2,1.91,28]],"batl":[[0,2.28,4.71]],"ltp":2.14,"tv":49.62,"id":25686043}]}]}
{"op":"mcm","clk":"11793064668","pt":1723062102597,"mc":[{"id":"1.231499799","rc":[{"batb":[[0,1.77,66.29],[1,1.74,17.32],[2,1.53,94.34]],"ltp":1.87,"tv":381.91,"id":12482925}]}]}
{"op":"mcm","clk":"11793064797","pt":1723062104507,"mc":[{"id":"1.231499799","rc":[{"batb":[[0,1.98,45.31],[1,1.91,28],[2,1.74,17.32]],"ltp":2.14,"tv":49.62,"id":25686043}]}]}
{"op":"mcm","clk":"11793064904","pt":1723062106883,"mc":[{"id":"1.231499799","rc":[{"batb":[[0,1.78,10],[1,1.77,66.29],[2,1.74,17.32]],"ltp":1.87,"tv":381.91,"id":12482925}]}]}
{"op":"mcm","clk":"11793065087","pt":1723062110195,"mc":[{"id":"1.231499799","rc":[{"batb":[[0,1.77,66.29],[1,1.74,17.32],[2,1.53,94.34]],"ltp":1.87,"tv":381.91,"id":12482925}]}]}
{"op":"mcm","clk":"11793065259","pt":1723062113500,"mc":[{"id":"1.231499799","rc":[{"batb":[[0,1.78,10],[1,1.77,66.29],[2,1.74,17.32]],"ltp":1.87,"tv":381.91,"id":12482925}]}]}
{"op":"mcm","clk":"11793065433","pt":1723062116925,"mc":[{"id":"1.231499799","rc":[{"batb":[[0,1.77,66.29],[1,1.74,17.32],[2,1.53,94.34]],"ltp":1.87,"tv":381.91,"id":12482925}]}]}
{"op":"mcm","clk":"11793065585","pt":1723062119301,"mc":[{"id":"1.231499799","rc":[{"batb":[[0,1.78,10],[1,1.77,66.29],[2,1.74,17.32]],"ltp":1.87,"tv":381.91,"id":12482925}]}]}
{"op":"mcm","clk":"11793065807","pt":1723062122727,"mc":[{"id":"1.231499799","rc":[{"batb":[[0,1.77,66.29],[1,1.74,17.32],[2,1.53,94.34]],"ltp":1.87,"tv":381.91,"id":12482925}]}]}
{"op":"mcm","clk":"11793065982","pt":1723062126235,"mc":[{"id":"1.231499799","rc":[{"batb":[[0,1.78,10],[1,1.77,66.29],[2,1.74,17.32]],"ltp":1.87,"tv":381.91,"id":12482925}]}]}
{"op":"mcm","clk":"11793066170","pt":1723062129548,"mc":[{"id":"1.231499799","rc":[{"batb":[[0,1.77,66.29],[1,1.74,17.32],[2,1.53,94.34]],"ltp":1.87,"tv":381.91,"id":12482925}]}]}
{"op":"mcm","clk":"11793066294","pt":1723062132230,"mc":[{"id":"1.231499799","rc":[{"batb":[[0,1.78,10],[1,1.77,66.29],[2,1.74,17.32]],"ltp":1.87,"tv":381.91,"id":12482925}]}]}
{"op":"mcm","clk":"11793066508","pt":1723062135736,"mc":[{"id":"1.231499799","rc":[{"batb":[[0,1.77,66.29],[1,1.74,17.32],[2,1.53,94.34]],"ltp":1.87,"tv":381.91,"id":12482925}]}]}
{"op":"mcm","clk":"11793066621","pt":1723062138261,"mc":[{"id":"1.231499799","rc":[{"batb":[[0,1.78,10],[1,1.77,66.29],[2,1.74,17.32]],"ltp":1.87,"tv":381.91,"id":12482925}]}]}
{"op":"mcm","clk":"11793066841","pt":1723062141671,"mc":[{"id":"1.231499799","rc":[{"batb":[[0,1.77,66.29],[1,1.74,17.32],[2,1.53,94.34]],"ltp":1.87,"tv":381.91,"id":12482925}]}]}
{"op":"mcm","clk":"11793067051","pt":1723062145133,"mc":[{"id":"1.231499799","rc":[{"batb":[[0,1.78,10],[1,1.77,66.29],[2,1.74,17.32]],"ltp":1.87,"tv":381.91,"id":12482925}]}]}
{"op":"mcm","clk":"11793067248","pt":1723062148946,"mc":[{"id":"1.231499799","rc":[{"batb":[[0,1.77,66.29],[1,1.74,17.32],[2,1.53,94.34]],"ltp":1.87,"tv":381.91,"id":12482925}]}]}
{"op":"mcm","clk":"11793067258","pt":1723062149254,"mc":[{"id":"1.231499799","rc":[{"batb":[[0,1.78,4.98],[1,1.77,66.29],[2,1.74,17.32]],"ltp":1.87,"tv":381.91,"id":12482925}]}]}
{"op":"mcm","clk":"11793067390","pt":1723062151670,"mc":[{"id":"1.231499799","rc":[{"batb":[[0,1.79,10],[1,1.78,4.98],[2,1.77,66.29]],"ltp":1.87,"tv":381.91,"id":12482925}]}]}
{"op":"mcm","clk":"11793067493","pt":1723062153672,"mc":[{"id":"1.231499799","rc":[{"batb":[[0,1.99,10],[1,1.98,45.31],[2,1.91,28]],"batl":[[0,2.28,4.71]],"ltp":2.14,"tv":49.62,"id":25686043},{"batb":[[1,1.77,66.29],[2,1.74,17.32]],"ltp":1.87,"tv":381.91,"id":12482925}]}]}
{"op":"mcm","clk":"11793067586","pt":1723062155578,"mc":[{"id":"1.231499799","rc":[{"batb":[[0,1.77,66.29],[1,1.74,17.32],[2,1.53,94.34]],"ltp":1.87,"tv":381.91,"id":12482925}]}]}
{"op":"mcm","clk":"11793067647","pt":1723062156967,"mc":[{"id":"1.231499799","rc":[{"batb":[[0,1.98,45.31],[1,1.91,28],[2,1.74,17.32]],"ltp":2.14,"tv":49.62,"id":25686043}]}]}
{"op":"mcm","clk":"11793067708","pt":1723062158050,"mc":[{"id":"1.231499799","rc":[{"batb":[[0,1.78,10],[1,1.77,66.29],[2,1.74,17.32]],"ltp":1.87,"tv":381.91,"id":12482925}]}]}
{"op":"mcm","clk":"11793067858","pt":1723062161355,"mc":[{"id":"1.231499799","rc":[{"batb":[[0,1.77,66.29],[1,1.74,17.32],[2,1.53,94.34]],"ltp":1.87,"tv":381.91,"id":12482925}]}]}
{"op":"mcm","clk":"11793067968","pt":1723062164187,"mc":[{"id":"1.231499799","rc":[{"batb":[[0,1.78,10],[1,1.77,66.29],[2,1.74,17.32]],"ltp":1.87,"tv":381.91,"id":12482925}]}]}
{"op":"mcm","clk":"11793068091","pt":1723062167685,"mc":[{"id":"1.231499799","rc":[{"batb":[[0,1.77,66.29],[1,1.74,17.32],[2,1.53,94.34]],"ltp":1.87,"tv":381.91,"id":12482925}]}]}
{"op":"mcm","clk":"11793068209","pt":1723062170273,"mc":[{"id":"1.231499799","rc":[{"batb":[[0,1.78,10],[1,1.77,66.29],[2,1.74,17.32]],"ltp":1.87,"tv":381.91,"id":12482925}]}]}
{"op":"mcm","clk":"11793068436","pt":1723062174588,"mc":[{"id":"1.231499799","rc":[{"batb":[[0,1.77,66.29],[1,1.74,17.32],[2,1.53,94.34]],"ltp":1.87,"tv":381.91,"id":12482925}]}]}
{"op":"mcm","clk":"11793068529","pt":1723062176899,"mc":[{"id":"1.231499799","rc":[{"batb":[[0,1.78,10],[1,1.77,66.29],[2,1.74,17.32]],"ltp":1.87,"tv":381.91,"id":12482925}]}]}
{"op":"mcm","clk":"11793068694","pt":1723062180305,"mc":[{"id":"1.231499799","rc":[{"batb":[[0,1.77,66.29],[1,1.74,17.32],[2,1.53,94.34]],"ltp":1.87,"tv":381.91,"id":12482925}]}]}
{"op":"mcm","clk":"11793068854","pt":1723062183409,"mc":[{"id":"1.231499799","rc":[{"batb":[[0,1.78,10],[1,1.77,66.29],[2,1.74,17.32]],"ltp":1.87,"tv":381.91,"id":12482925}]}]}
{"op":"mcm","clk":"11793069064","pt":1723062187018,"mc":[{"id":"1.231499799","rc":[{"batb":[[0,1.77,66.29],[1,1.74,17.32],[2,1.53,94.34]],"ltp":1.87,"tv":381.91,"id":12482925}]}]}
{"op":"mcm","clk":"11793069158","pt":1723062189542,"mc":[{"id":"1.231499799","rc":[{"batb":[[0,1.78,10],[1,1.77,66.29],[2,1.74,17.32]],"ltp":1.87,"tv":381.91,"id":12482925}]}]}
{"op":"mcm","clk":"11793069332","pt":1723062193145,"mc":[{"id":"1.231499799","rc":[{"batb":[[0,1.77,66.29],[1,1.74,17.32],[2,1.53,94.34]],"ltp":1.87,"tv":381.91,"id":12482925}]}]}
{"op":"mcm","clk":"11793069482","pt":1723062196647,"mc":[{"id":"1.231499799","rc":[{"batb":[[0,1.78,10],[1,1.77,66.29],[2,1.74,17.32]],"ltp":1.87,"tv":381.91,"id":12482925}]}]}
{"op":"mcm","clk":"11793069639","pt":1723062200050,"mc":[{"id":"1.231499799","rc":[{"batb":[[0,1.77,66.29],[1,1.74,17.32],[2,1.53,94.34]],"ltp":1.87,"tv":381.91,"id":12482925}]}]}
{"op":"mcm","clk":"11793069703","pt":1723062201136,"mc":[{"id":"1.231499799","rc":[{"batb":[[0,1.78,4.98],[1,1.77,66.29],[2,1.74,17.32]],"ltp":1.87,"tv":381.91,"id":12482925}]}]}
{"op":"mcm","clk":"11793069762","pt":1723062202324,"mc":[{"id":"1.231499799","rc":[{"batb":[[0,1.79,10],[1,1.78,4.98],[2,1.77,66.29]],"ltp":1.87,"tv":381.91,"id":12482925}]}]}
{"op":"mcm","clk":"11793069913","pt":1723062205922,"mc":[{"id":"1.231499799","rc":[{"batb":[[0,1.99,10],[1,1.98,45.31],[2,1.91,28]],"batl":[[0,2.28,4.71]],"ltp":2.14,"tv":49.62,"id":25686043},{"batb":[[0,1.77,66.29],[1,1.74,17.32],[2,1.53,94.34]],"ltp":1.87,"tv":381.91,"id":12482925}]}]}
{"op":"mcm","clk":"11793070088","pt":1723062209575,"mc":[{"id":"1.231499799","rc":[{"batb":[[0,1.98,45.31],[1,1.91,28],[2,1.74,17.32]],"ltp":2.14,"tv":49.62,"id":25686043},{"batb":[[0,1.78,10],[1,1.77,66.29],[2,1.74,17.32]],"ltp":1.87,"tv":381.91,"id":12482925}]}]}
{"op":"mcm","clk":"11793070261","pt":1723062212973,"mc":[{"id":"1.231499799","rc":[{"batb":[[0,1.77,66.29],[1,1.74,17.32],[2,1.53,94.34]],"ltp":1.87,"tv":381.91,"id":12482925}]}]}
{"op":"mcm","clk":"11793070415","pt":1723062215663,"mc":[{"id":"1.231499799","rc":[{"batb":[[0,1.78,10],[1,1.77,66.29],[2,1.74,17.32]],"ltp":1.87,"tv":381.91,"id":12482925}]}]}
{"op":"mcm","clk":"11793070558","pt":1723062218954,"mc":[{"id":"1.231499799","rc":[{"batb":[[0,1.77,66.29],[1,1.74,17.32],[2,1.53,94.34]],"ltp":1.87,"tv":381.91,"id":12482925}]}]}
{"op":"mcm","clk":"11793070663","pt":1723062221570,"mc":[{"id":"1.231499799","rc":[{"batb":[[0,1.78,10],[1,1.77,66.29],[2,1.74,17.32]],"ltp":1.87,"tv":381.91,"id":12482925}]}]}
{"op":"mcm","clk":"11793070816","pt":1723062225016,"mc":[{"id":"1.231499799","rc":[{"batb":[[0,1.77,66.29],[1,1.74,17.32],[2,1.53,94.34]],"ltp":1.87,"tv":381.91,"id":12482925}]}]}
{"op":"mcm","clk":"11793070930","pt":1723062227635,"mc":[{"id":"1.231499799","rc":[{"batb":[[0,1.78,10],[1,1.77,66.29],[2,1.74,17.32]],"ltp":1.87,"tv":381.91,"id":12482925}]}]}
{"op":"mcm","clk":"11793071094","pt":1723062231127,"mc":[{"id":"1.231499799","rc":[{"batb":[[0,1.77,66.29],[1,1.74,17.32],[2,1.53,94.34]],"ltp":1.87,"tv":381.91,"id":12482925}]}]}
{"op":"mcm","clk":"11793071208","pt":1723062233646,"mc":[{"id":"1.231499799","rc":[{"batb":[[0,1.78,10],[1,1.77,66.29],[2,1.74,17.32]],"ltp":1.87,"tv":381.91,"id":12482925}]}]}
{"op":"mcm","clk":"11793071343","pt":1723062236938,"mc":[{"id":"1.231499799","rc":[{"batb":[[0,1.77,66.29],[1,1.74,17.32],[2,1.53,94.34]],"ltp":1.87,"tv":381.91,"id":12482925}]}]}
{"op":"mcm","clk":"11793071492","pt":1723062240328,"mc":[{"id":"1.231499799","rc":[{"batb":[[0,1.78,10],[1,1.77,66.29],[2,1.74,17.32]],"ltp":1.87,"tv":381.91,"id":12482925}]}]}
{"op":"mcm","clk":"11793071612","pt":1723062243767,"mc":[{"id":"1.231499799","rc":[{"batb":[[0,1.77,66.29],[1,1.74,17.32],[2,1.53,94.34]],"ltp":1.87,"tv":381.91,"id":12482925}]}]}
{"op":"mcm","clk":"11793071779","pt":1723062246759,"mc":[{"id":"1.231499799","rc":[{"batb":[[0,1.78,10],[1,1.77,66.29],[2,1.74,17.32]],"ltp":1.87,"tv":381.91,"id":12482925}]}]}
{"op":"mcm","clk":"11793071912","pt":1723062250056,"mc":[{"id":"1.231499799","rc":[{"batb":[[0,1.77,66.29],[1,1.74,17.32],[2,1.53,94.34]],"ltp":1.87,"tv":381.91,"id":12482925}]}]}
{"op":"mcm","clk":"11793072056","pt":1723062253547,"mc":[{"id":"1.231499799","rc":[{"batb":[[0,1.78,14.98],[1,1.77,66.29],[2,1.74,17.32]],"ltp":1.87,"tv":381.91,"id":12482925}]}]}
{"op":"mcm","clk":"11793072157","pt":1723062256577,"mc":[{"id":"1.231499799","rc":[{"batb":[[0,1.78,4.98]],"ltp":1.87,"tv":381.91,"id":12482925}]}]}
{"op":"mcm","clk":"11793072309","pt":1723062259677,"mc":[{"id":"1.231499799","rc":[{"batb":[[0,1.79,10],[1,1.78,4.98],[2,1.77,66.29]],"ltp":1.87,"tv":381.91,"id":12482925}]}]}
{"op":"mcm","clk":"11793072374","pt":1723062260579,"mc":[{"id":"1.231499799","rc":[{"batb":[[0,1.99,10],[1,1.98,45.31],[2,1.91,28]],"batl":[[0,2.28,4.71]],"ltp":2.14,"tv":49.62,"id":25686043},{"batb":[[1,1.77,66.29],[2,1.74,17.32]],"ltp":1.87,"tv":381.91,"id":12482925}]}]}
{"op":"mcm","clk":"11793072442","pt":1723062261691,"mc":[{"id":"1.231499799","rc":[{"batb":[[0,1.8,102.2],[1,1.79,10],[2,1.77,66.29]],"ltp":1.87,"tv":381.91,"id":12482925}]}]}
{"op":"mcm","clk":"11793072534","pt":1723062263954,"mc":[{"id":"1.231499799","rc":[{"batb":[[0,1.98,45.31],[1,1.91,28],[2,1.74,17.32]],"ltp":2.14,"tv":49.62,"id":25686043},{"batb":[[1,1.74,17.32],[2,1.53,94.34]],"ltp":1.87,"tv":381.91,"id":12482925}]}]}
{"op":"mcm","clk":"11793072672","pt":1723062267161,"mc":[{"id":"1.231499799","rc":[{"batb":[[0,1.81,10],[1,1.8,102.2],[2,1.74,17.32]],"ltp":1.87,"tv":381.91,"id":12482925}]}]}
{"op":"mcm","clk":"11793072818","pt":1723062270390,"mc":[{"id":"1.231499799","rc":[{"batb":[[0,1.8,102.2],[1,1.74,17.32],[2,1.53,94.34]],"ltp":1.87,"tv":381.91,"id":12482925}]}]}
{"op":"mcm","clk":"11793072973","pt":1723062273580,"mc":[{"id":"1.231499799","rc":[{"batb":[[0,1.81,10],[1,1.8,102.2],[2,1.74,17.32]],"ltp":1.87,"tv":381.91,"id":12482925}]}]}
{"op":"mcm","clk":"11793073136","pt":1723062276817,"mc":[{"id":"1.231499799","rc":[{"batb":[[0,1.8,102.2],[1,1.74,17.32],[2,1.53,94.34]],"ltp":1.87,"tv":381.91,"id":12482925}]}]}
{"op":"mcm","clk":"11793073301","pt":1723062280692,"mc":[{"id":"1.231499799","rc":[{"batb":[[0,1.81,10],[1,1.8,102.2],[2,1.74,17.32]],"ltp":1.87,"tv":381.91,"id":12482925}]}]}
{"op":"mcm","clk":"11793073444","pt":1723062284031,"mc":[{"id":"1.231499799","rc":[{"batb":[[0,1.8,102.2],[1,1.74,17.32],[2,1.53,94.34]],"ltp":1.87,"tv":381.91,"id":12482925}]}]}
{"op":"mcm","clk":"11793073564","pt":1723062286403,"mc":[{"id":"1.231499799","rc":[{"batb":[[0,1.81,10],[1,1.8,102.2],[2,1.74,17.32]],"ltp":1.87,"tv":381.91,"id":12482925}]}]}
{"op":"mcm","clk":"11793073714","pt":1723062289846,"mc":[{"id":"1.231499799","rc":[{"batb":[[0,1.8,102.2],[1,1.74,17.32],[2,1.53,94.34]],"ltp":1.87,"tv":381.91,"id":12482925}]}]}
{"op":"mcm","clk":"11793073928","pt":1723062294736,"mc":[{"id":"1.231499799","rc":[{"batb":[[0,1.81,10],[1,1.8,102.2],[2,1.74,17.32]],"ltp":1.87,"tv":381.91,"id":12482925}]}]}
{"op":"mcm","clk":"11793074108","pt":1723062298336,"mc":[{"id":"1.231499799","rc":[{"batb":[[0,1.8,102.2],[1,1.74,17.32],[2,1.53,94.34]],"ltp":1.87,"tv":381.91,"id":12482925}]}]}
{"op":"mcm","clk":"11793074218","pt":1723062300808,"mc":[{"id":"1.231499799","rc":[{"batb":[[0,1.81,10],[1,1.8,102.2],[2,1.74,17.32]],"ltp":1.87,"tv":381.91,"id":12482925}]}]}
{"op":"mcm","clk":"11793074375","pt":1723062304360,"mc":[{"id":"1.231499799","rc":[{"batb":[[0,1.8,102.2],[1,1.74,17.32],[2,1.53,94.34]],"ltp":1.87,"tv":381.91,"id":12482925}]}]}
{"op":"mcm","clk":"11793074508","pt":1723062307761,"mc":[{"id":"1.231499799","rc":[{"batb":[[0,1.81,10],[1,1.8,102.2],[2,1.74,17.32]],"ltp":1.87,"tv":381.91,"id":12482925}]}]}
{"op":"mcm","clk":"11793074635","pt":1723062311153,"mc":[{"id":"1.231499799","rc":[{"batb":[[0,1.8,102.2],[1,1.74,17.32],[2,1.53,94.34]],"ltp":1.87,"tv":381.91,"id":12482925}]}]}
{"op":"mcm","clk":"11793074748","pt":1723062313944,"mc":[{"id":"1.231499799","rc":[{"batb":[[0,1.81,10],[1,1.8,102.2],[2,1.74,17.32]],"ltp":1.87,"tv":381.91,"id":12482925}]}]}
{"op":"mcm","clk":"11793074874","pt":1723062317242,"mc":[{"id":"1.231499799","rc":[{"batb":[[0,1.8,102.2],[1,1.74,17.32],[2,1.53,94.34]],"ltp":1.87,"tv":381.91,"id":12482925}]}]}
{"op":"mcm","clk":"11793074984","pt":1723062319967,"mc":[{"id":"1.231499799","rc":[{"batb":[[0,1.81,10],[1,1.8,102.2],[2,1.74,17.32]],"ltp":1.87,"tv":381.91,"id":12482925}]}]}
{"op":"mcm","clk":"11793075128","pt":1723062323983,"mc":[{"id":"1.231499799","rc":[{"batb":[[0,1.8,102.2],[1,1.74,17.32],[2,1.53,94.34]],"ltp":1.87,"tv":381.91,"id":12482925}]}]}
{"op":"mcm","clk":"11793075231","pt":1723062326350,"mc":[{"id":"1.231499799","rc":[{"batb":[[0,1.81,10],[1,1.8,102.2],[2,1.74,17.32]],"ltp":1.87,"tv":381.91,"id":12482925}]}]}
{"op":"mcm","clk":"11793075361","pt":1723062329919,"mc":[{"id":"1.231499799","rc":[{"batb":[[0,1.8,102.2],[1,1.74,17.32],[2,1.53,94.34]],"ltp":1.87,"tv":381.91,"id":12482925}]}]}
{"op":"mcm","clk":"11793075475","pt":1723062332267,"mc":[{"id":"1.231499799","rc":[{"batb":[[0,1.81,10],[1,1.8,102.2],[2,1.74,17.32]],"ltp":1.87,"tv":381.91,"id":12482925}]}]}
{"op":"mcm","clk":"11793075618","pt":1723062335764,"mc":[{"id":"1.231499799","rc":[{"batb":[[0,1.8,102.2],[1,1.74,17.32],[2,1.53,94.34]],"ltp":1.87,"tv":381.91,"id":12482925}]}]}
{"op":"mcm","clk":"11793075757","pt":1723062338593,"mc":[{"id":"1.231499799","rc":[{"batb":[[0,1.81,10],[1,1.8,102.2],[2,1.74,17.32]],"ltp":1.87,"tv":381.91,"id":12482925}]}]}
{"op":"mcm","clk":"11793075887","pt":1723062341992,"mc":[{"id":"1.231499799","rc":[{"batb":[[0,1.8,102.2],[1,1.74,17.32],[2,1.53,94.34]],"ltp":1.87,"tv":381.91,"id":12482925}]}]}
{"op":"mcm","clk":"11793075993","pt":1723062344772,"mc":[{"id":"1.231499799","rc":[{"batb":[[0,1.81,10],[1,1.8,102.2],[2,1.74,17.32]],"ltp":1.87,"tv":381.91,"id":12482925}]}]}
{"op":"mcm","clk":"11793076162","pt":1723062348227,"mc":[{"id":"1.231499799","rc":[{"batb":[[0,1.8,102.2],[1,1.74,17.32],[2,1.53,94.34]],"ltp":1.87,"tv":381.91,"id":12482925}]}]}
{"op":"mcm","clk":"11793076330","pt":1723062351984,"mc":[{"id":"1.231499799","rc":[{"batb":[[0,1.99,6.51],[1,1.98,45.31],[2,1.91,28]],"ltp":2.14,"tv":49.62,"id":25686043},{"batb":[[0,1.81,17.43],[1,1.8,102.2],[2,1.74,17.32]],"ltp":1.87,"tv":381.91,"id":12482925}]}]}
{"op":"mcm","clk":"11793076440","pt":1723062355234,"mc":[{"id":"1.231499799","rc":[{"batb":[[0,1.81,7.43]],"ltp":1.87,"tv":381.91,"id":12482925}]}]}
{"op":"mcm","clk":"11793076610","pt":1723062358305,"mc":[{"id":"1.231499799","rc":[{"batb":[[0,1.82,10],[1,1.81,7.43],[2,1.8,102.2]],"ltp":1.87,"tv":381.91,"id":12482925}]}]}
{"op":"mcm","clk":"11793076788","pt":1723062362022,"mc":[{"id":"1.231499799","rc":[{"batb":[[0,1.81,7.43],[1,1.8,102.2],[2,1.74,17.32]],"ltp":1.87,"tv":381.91,"id":12482925}]}]}
{"op":"mcm","clk":"11793076910","pt":1723062365214,"mc":[{"id":"1.231499799","rc":[{"batb":[[0,1.82,10],[1,1.81,7.43],[2,1.8,102.2]],"ltp":1.87,"tv":381.91,"id":12482925}]}]}
{"op":"mcm","clk":"11793077041","pt":1723062368545,"mc":[{"id":"1.231499799","rc":[{"batb":[[0,1.81,7.43],[1,1.8,102.2],[2,1.74,17.32]],"ltp":1.87,"tv":381.91,"id":12482925}]}]}
{"op":"mcm","clk":"11793077169","pt":1723062371232,"mc":[{"id":"1.231499799","rc":[{"batb":[[0,1.82,10],[1,1.81,7.43],[2,1.8,102.2]],"ltp":1.87,"tv":381.91,"id":12482925}]}]}
{"op":"mcm","clk":"11793077304","pt":1723062374527,"mc":[{"id":"1.231499799","rc":[{"batb":[[0,1.81,7.43],[1,1.8,102.2],[2,1.74,17.32]],"ltp":1.87,"tv":381.91,"id":12482925}]}]}
{"op":"mcm","clk":"11793077487","pt":1723062378448,"mc":[{"id":"1.231499799","rc":[{"batb":[[0,1.82,10],[1,1.81,7.43],[2,1.8,102.2]],"ltp":1.87,"tv":381.91,"id":12482925}]}]}
{"op":"mcm","clk":"11793077618","pt":1723062381930,"mc":[{"id":"1.231499799","rc":[{"batb":[[0,1.81,7.43],[1,1.8,102.2],[2,1.74,17.32]],"ltp":1.87,"tv":381.91,"id":12482925}]}]}
{"op":"mcm","clk":"11793077704","pt":1723062384246,"mc":[{"id":"1.231499799","rc":[{"batb":[[0,1.82,10],[1,1.81,7.43],[2,1.8,102.2]],"ltp":1.87,"tv":381.91,"id":12482925}]}]}
{"op":"mcm","clk":"11793077841","pt":1723062387761,"mc":[{"id":"1.231499799","rc":[{"batb":[[0,1.81,7.43],[1,1.8,102.2],[2,1.74,17.32]],"ltp":1.87,"tv":381.91,"id":12482925}]}]}
{"op":"mcm","clk":"11793077943","pt":1723062390378,"mc":[{"id":"1.231499799","rc":[{"batb":[[0,1.82,10],[1,1.81,7.43],[2,1.8,102.2]],"ltp":1.87,"tv":381.91,"id":12482925}]}]}
{"op":"mcm","clk":"11793078102","pt":1723062393675,"mc":[{"id":"1.231499799","rc":[{"batb":[[0,1.81,7.43],[1,1.8,102.2],[2,1.74,17.32]],"ltp":1.87,"tv":381.91,"id":12482925}]}]}
{"op":"mcm","clk":"11793078200","pt":1723062396347,"mc":[{"id":"1.231499799","rc":[{"batb":[[0,1.82,10],[1,1.81,7.43],[2,1.8,102.2]],"ltp":1.87,"tv":381.91,"id":12482925}]}]}
{"op":"mcm","clk":"11793078319","pt":1723062399888,"mc":[{"id":"1.231499799","rc":[{"batb":[[0,1.81,7.43],[1,1.8,102.2],[2,1.74,17.32]],"ltp":1.87,"tv":381.91,"id":12482925}]}]}
{"op":"mcm","clk":"11793078650","pt":1723062405752,"mc":[{"id":"1.231499799","rc":[{"batb":[[0,1.82,10],[1,1.81,7.43],[2,1.8,102.2]],"ltp":1.87,"tv":381.91,"id":12482925}]}]}
{"op":"mcm","clk":"11793078796","pt":1723062409297,"mc":[{"id":"1.231499799","rc":[{"batb":[[0,1.81,7.43],[1,1.8,102.2],[2,1.74,17.32]],"ltp":1.87,"tv":381.91,"id":12482925}]}]}
{"op":"mcm","clk":"11793079026","pt":1723062414906,"mc":[{"id":"1.231499799","rc":[{"batb":[[0,1.82,10],[1,1.81,7.43],[2,1.8,102.2]],"ltp":1.87,"tv":381.91,"id":12482925}]}]}
{"op":"mcm","clk":"11793079184","pt":1723062418309,"mc":[{"id":"1.231499799","rc":[{"batb":[[0,1.81,7.43],[1,1.8,102.2],[2,1.74,17.32]],"ltp":1.87,"tv":381.91,"id":12482925}]}]}
{"op":"mcm","clk":"11793079319","pt":1723062421192,"mc":[{"id":"1.231499799","rc":[{"batb":[[0,1.82,10],[1,1.81,7.43],[2,1.8,102.2]],"ltp":1.87,"tv":381.91,"id":12482925}]}]}
{"op":"mcm","clk":"11793079461","pt":1723062424495,"mc":[{"id":"1.231499799","rc":[{"batb":[[0,1.81,7.43],[1,1.8,102.2],[2,1.74,17.32]],"ltp":1.87,"tv":381.91,"id":12482925}]}]}
{"op":"mcm","clk":"11793079680","pt":1723062428518,"mc":[{"id":"1.231499799","rc":[{"batb":[[0,1.82,10],[1,1.81,7.43],[2,1.8,102.2]],"ltp":1.87,"tv":381.91,"id":12482925}]}]}
{"op":"mcm","clk":"11793079879","pt":1723062432793,"mc":[{"id":"1.231499799","rc":[{"batb":[[0,1.81,7.43],[1,1.8,102.2],[2,1.74,17.32]],"ltp":1.87,"tv":381.91,"id":12482925}]}]}
{"op":"mcm","clk":"11793079983","pt":1723062435003,"mc":[{"id":"1.231499799","rc":[{"batb":[[0,1.82,10],[1,1.81,7.43],[2,1.8,102.2]],"ltp":1.87,"tv":381.91,"id":12482925}]}]}
{"op":"mcm","clk":"11793080144","pt":1723062438396,"mc":[{"id":"1.231499799","rc":[{"batb":[[0,1.81,7.43],[1,1.8,102.2],[2,1.74,17.32]],"ltp":1.87,"tv":381.91,"id":12482925}]}]}
{"op":"mcm","clk":"11793080325","pt":1723062441027,"mc":[{"id":"1.231499799","rc":[{"batb":[[0,1.82,10],[1,1.81,7.43],[2,1.8,102.2]],"ltp":1.87,"tv":381.91,"id":12482925}]}]}
{"op":"mcm","clk":"11793080511","pt":1723062444523,"mc":[{"id":"1.231499799","rc":[{"batb":[[0,1.81,7.43],[1,1.8,102.2],[2,1.74,17.32]],"ltp":1.87,"tv":381.91,"id":12482925}]}]}
{"op":"mcm","clk":"11793080613","pt":1723062446816,"mc":[{"id":"1.231499799","rc":[{"batb":[[0,1.82,10],[1,1.81,7.43],[2,1.8,102.2]],"ltp":1.87,"tv":381.91,"id":12482925}]}]}
{"op":"mcm","clk":"11793080794","pt":1723062450013,"mc":[{"id":"1.231499799","rc":[{"batb":[[0,1.81,7.43],[1,1.8,102.2],[2,1.74,17.32]],"ltp":1.87,"tv":381.91,"id":12482925}]}]}
{"op":"mcm","clk":"11793080933","pt":1723062452906,"mc":[{"id":"1.231499799","rc":[{"batb":[[0,1.82,10],[1,1.81,7.43],[2,1.8,102.2]],"ltp":1.87,"tv":381.91,"id":12482925}]}]}
{"op":"mcm","clk":"11793081136","pt":1723062456416,"mc":[{"id":"1.231499799","rc":[{"batb":[[0,1.81,7.43],[1,1.8,102.2],[2,1.74,17.32]],"ltp":1.87,"tv":381.91,"id":12482925}]}]}
{"op":"mcm","clk":"11793081270","pt":1723062458838,"mc":[{"id":"1.231499799","rc":[{"batb":[[0,1.82,10],[1,1.81,7.43],[2,1.8,102.2]],"ltp":1.87,"tv":381.91,"id":12482925}]}]}
{"op":"mcm","clk":"11793081418","pt":1723062462334,"mc":[{"id":"1.231499799","rc":[{"batb":[[0,1.81,7.43],[1,1.8,102.2],[2,1.74,17.32]],"ltp":1.87,"tv":381.91,"id":12482925}]}]}
{"op":"mcm","clk":"11793081612","pt":1723062466357,"mc":[{"id":"1.231499799","rc":[{"batb":[[0,1.82,10],[1,1.81,7.43],[2,1.8,102.2]],"ltp":1.87,"tv":381.91,"id":12482925}]}]}
{"op":"mcm","clk":"11793081776","pt":1723062469663,"mc":[{"id":"1.231499799","rc":[{"batb":[[0,1.81,7.43],[1,1.8,102.2],[2,1.74,17.32]],"ltp":1.87,"tv":381.91,"id":12482925}]}]}
{"op":"mcm","clk":"11793081954","pt":1723062473136,"mc":[{"id":"1.231499799","rc":[{"batb":[[0,1.82,10],[1,1.81,7.43],[2,1.8,102.2]],"ltp":1.87,"tv":381.91,"id":12482925}]}]}
{"op":"mcm","clk":"11793082108","pt":1723062476550,"mc":[{"id":"1.231499799","rc":[{"batb":[[0,1.81,7.43],[1,1.8,102.2],[2,1.74,17.32]],"ltp":1.87,"tv":381.91,"id":12482925}]}]}
{"op":"mcm","clk":"11793082227","pt":1723062479062,"mc":[{"id":"1.231499799","rc":[{"batb":[[0,1.82,10],[1,1.81,7.43],[2,1.8,102.2]],"ltp":1.87,"tv":381.91,"id":12482925}]}]}
{"op":"mcm","clk":"11793082375","pt":1723062482488,"mc":[{"id":"1.231499799","rc":[{"batb":[[0,1.81,7.43],[1,1.8,102.2],[2,1.74,17.32]],"ltp":1.87,"tv":381.91,"id":12482925}]}]}
{"op":"mcm","clk":"11793082499","pt":1723062484969,"mc":[{"id":"1.231499799","rc":[{"batb":[[0,1.82,10],[1,1.81,7.43],[2,1.8,102.2]],"ltp":1.87,"tv":381.91,"id":12482925}]}]}
{"op":"mcm","clk":"11793082698","pt":1723062488683,"mc":[{"id":"1.231499799","rc":[{"batb":[[0,1.81,7.43],[1,1.8,102.2],[2,1.74,17.32]],"ltp":1.87,"tv":381.91,"id":12482925}]}]}
{"op":"mcm","clk":"11793082862","pt":1723062491987,"mc":[{"id":"1.231499799","rc":[{"batb":[[0,1.82,10],[1,1.81,7.43],[2,1.8,102.2]],"ltp":1.87,"tv":381.91,"id":12482925}]}]}
{"op":"mcm","clk":"11793083065","pt":1723062495490,"mc":[{"id":"1.231499799","rc":[{"batb":[[0,1.81,7.43],[1,1.8,102.2],[2,1.74,17.32]],"ltp":1.87,"tv":381.91,"id":12482925}]}]}
{"op":"mcm","clk":"11793083236","pt":1723062498178,"mc":[{"id":"1.231499799","rc":[{"batb":[[0,1.82,10],[1,1.81,7.43],[2,1.8,102.2]],"ltp":1.87,"tv":381.91,"id":12482925}]}]}
{"op":"mcm","clk":"11793083420","pt":1723062501522,"mc":[{"id":"1.231499799","rc":[{"batb":[[0,1.81,7.43],[1,1.8,102.2],[2,1.74,17.32]],"ltp":1.87,"tv":381.91,"id":12482925}]}]}
{"op":"mcm","clk":"11793083569","pt":1723062504820,"mc":[{"id":"1.231499799","rc":[{"batb":[[0,1.82,10],[1,1.81,7.43],[2,1.8,102.2]],"ltp":1.87,"tv":381.91,"id":12482925}]}]}
{"op":"mcm","clk":"11793083682","pt":1723062508307,"mc":[{"id":"1.231499799","rc":[{"batb":[[0,1.81,7.43],[1,1.8,102.2],[2,1.74,17.32]],"ltp":1.87,"tv":381.91,"id":12482925}]}]}
{"op":"mcm","clk":"11793083796","pt":1723062511438,"mc":[{"id":"1.231499799","rc":[{"batb":[[0,1.82,10],[1,1.81,7.43],[2,1.8,102.2]],"ltp":1.87,"tv":381.91,"id":12482925}]}]}
{"op":"mcm","clk":"11793083960","pt":1723062514936,"mc":[{"id":"1.231499799","rc":[{"batb":[[0,1.81,7.43],[1,1.8,102.2],[2,1.74,17.32]],"ltp":1.87,"tv":381.91,"id":12482925}]}]}
{"op":"mcm","clk":"11793084056","pt":1723062517711,"mc":[{"id":"1.231499799","rc":[{"batb":[[0,1.82,10],[1,1.81,7.43],[2,1.8,102.2]],"ltp":1.87,"tv":381.91,"id":12482925}]}]}
{"op":"mcm","clk":"11793084194","pt":1723062521246,"mc":[{"id":"1.231499799","rc":[{"batb":[[0,1.81,7.43],[1,1.8,102.2],[2,1.74,17.32]],"ltp":1.87,"tv":381.91,"id":12482925}]}]}
{"op":"mcm","clk":"11793084301","pt":1723062523816,"mc":[{"id":"1.231499799","rc":[{"batb":[[0,1.82,10],[1,1.81,7.43],[2,1.8,102.2]],"ltp":1.87,"tv":381.91,"id":12482925}]}]}
{"op":"mcm","clk":"11793084400","pt":1723062527455,"mc":[{"id":"1.231499799","rc":[{"batb":[[0,1.81,7.43],[1,1.8,102.2],[2,1.74,17.32]],"ltp":1.87,"tv":381.91,"id":12482925}]}]}
{"op":"mcm","clk":"11793084530","pt":1723062530852,"mc":[{"id":"1.231499799","rc":[{"batb":[[0,1.82,10],[1,1.81,7.43],[2,1.8,102.2]],"ltp":1.87,"tv":381.91,"id":12482925}]}]}
{"op":"mcm","clk":"11793084643","pt":1723062533628,"mc":[{"id":"1.231499799","rc":[{"batb":[[1,1.81,15.67]],"ltp":1.87,"tv":381.91,"id":12482925}]}]}
{"op":"mcm","clk":"11793084667","pt":1723062534249,"mc":[{"id":"1.231499799","rc":[{"batb":[[0,1.81,15.67],[1,1.8,102.2],[2,1.74,17.32]],"ltp":1.87,"tv":381.91,"id":12482925}]}]}
{"op":"mcm","clk":"11793084751","pt":1723062536965,"mc":[{"id":"1.231499799","rc":[{"batb":[[0,1.82,10],[1,1.81,15.67],[2,1.8,102.2]],"ltp":1.87,"tv":381.91,"id":12482925}]}]}
{"op":"mcm","clk":"11793084887","pt":1723062540454,"mc":[{"id":"1.231499799","rc":[{"batb":[[0,1.81,15.67],[1,1.8,102.2],[2,1.74,17.32]],"ltp":1.87,"tv":381.91,"id":12482925}]}]}
{"op":"mcm","clk":"11793085058","pt":1723062545050,"mc":[{"id":"1.231499799","rc":[{"batb":[[0,1.82,10],[1,1.81,15.67],[2,1.8,102.2]],"ltp":1.87,"tv":381.91,"id":12482925}]}]}
{"op":"mcm","clk":"11793085232","pt":1723062548559,"mc":[{"id":"1.231499799","rc":[{"batb":[[0,1.81,15.67],[1,1.8,102.2],[2,1.74,17.32]],"ltp":1.87,"tv":381.91,"id":12482925}]}]}
{"op":"mcm","clk":"11793085400","pt":1723062553081,"mc":[{"id":"1.231499799","rc":[{"batb":[[0,1.82,10],[1,1.81,15.67],[2,1.8,102.2]],"ltp":1.87,"tv":381.91,"id":12482925}]}]}
{"op":"mcm","clk":"11793085506","pt":1723062556464,"mc":[{"id":"1.231499799","rc":[{"batb":[[0,1.81,15.67],[1,1.8,102.2],[2,1.74,17.32]],"ltp":1.87,"tv":381.91,"id":12482925}]}]}
{"op":"mcm","clk":"11793085625","pt":1723062559491,"mc":[{"id":"1.231499799","rc":[{"batb":[[0,1.82,10],[1,1.81,15.67],[2,1.8,102.2]],"ltp":1.87,"tv":381.91,"id":12482925}]}]}
{"op":"mcm","clk":"11793085751","pt":1723062562888,"mc":[{"id":"1.231499799","rc":[{"batb":[[0,1.81,15.67],[1,1.8,102.2],[2,1.74,17.32]],"ltp":1.87,"tv":381.91,"id":12482925}]}]}
{"op":"mcm","clk":"11793085894","pt":1723062566495,"mc":[{"id":"1.231499799","rc":[{"batb":[[0,1.82,10],[1,1.81,15.67],[2,1.8,102.2]],"ltp":1.87,"tv":381.91,"id":12482925}]}]}
{"op":"mcm","clk":"11793086049","pt":1723062569891,"mc":[{"id":"1.231499799","rc":[{"batb":[[0,1.81,15.67],[1,1.8,102.2],[2,1.74,17.32]],"ltp":1.87,"tv":381.91,"id":12482925}]}]}
{"op":"mcm","clk":"11793086200","pt":1723062573389,"mc":[{"id":"1.231499799","rc":[{"batb":[[0,1.82,10],[1,1.81,15.67],[2,1.8,102.2]],"ltp":1.87,"tv":381.91,"id":12482925}]}]}
{"op":"mcm","clk":"11793086383","pt":1723062577197,"mc":[{"id":"1.231499799","rc":[{"batb":[[0,1.81,15.67],[1,1.8,102.2],[2,1.74,17.32]],"ltp":1.87,"tv":381.91,"id":12482925}]}]}
{"op":"mcm","clk":"11793086492","pt":1723062579613,"mc":[{"id":"1.231499799","rc":[{"batb":[[0,1.82,10],[1,1.81,15.67],[2,1.8,102.2]],"ltp":1.87,"tv":381.91,"id":12482925}]}]}
{"op":"mcm","clk":"11793086604","pt":1723062583103,"mc":[{"id":"1.231499799","rc":[{"batb":[[0,1.81,15.67],[1,1.8,102.2],[2,1.74,17.32]],"ltp":1.87,"tv":381.91,"id":12482925}]}]}
{"op":"mcm","clk":"11793086684","pt":1723062585822,"mc":[{"id":"1.231499799","rc":[{"batb":[[0,1.82,10],[1,1.81,15.67],[2,1.8,102.2]],"ltp":1.87,"tv":381.91,"id":12482925}]}]}
{"op":"mcm","clk":"11793086830","pt":1723062589446,"mc":[{"id":"1.231499799","rc":[{"batb":[[0,1.81,15.67],[1,1.8,102.2],[2,1.74,17.32]],"ltp":1.87,"tv":381.91,"id":12482925}]}]}
{"op":"mcm","clk":"11793086922","pt":1723062591705,"mc":[{"id":"1.231499799","rc":[{"batb":[[0,1.82,10],[1,1.81,15.67],[2,1.8,102.2]],"ltp":1.87,"tv":381.91,"id":12482925}]}]}
{"op":"mcm","clk":"11793087027","pt":1723062595143,"mc":[{"id":"1.231499799","rc":[{"batb":[[0,1.81,15.67],[1,1.8,102.2],[2,1.74,17.32]],"ltp":1.87,"tv":381.91,"id":12482925}]}]}
{"op":"mcm","clk":"11793087161","pt":1723062599160,"mc":[{"id":"1.231499799","rc":[{"batb":[[0,1.82,10],[1,1.81,15.67],[2,1.8,102.2]],"ltp":1.87,"tv":381.91,"id":12482925}]}]}
{"op":"mcm","clk":"11793087293","pt":1723062602661,"mc":[{"id":"1.231499799","rc":[{"batb":[[0,1.81,15.67],[1,1.8,102.2],[2,1.74,17.32]],"ltp":1.87,"tv":381.91,"id":12482925}]}]}
{"op":"mcm","clk":"11793087432","pt":1723062605856,"mc":[{"id":"1.231499799","rc":[{"batb":[[0,1.82,10],[1,1.81,15.67],[2,1.8,102.2]],"ltp":1.87,"tv":381.91,"id":12482925}]}]}
{"op":"mcm","clk":"11793087572","pt":1723062609049,"mc":[{"id":"1.231499799","rc":[{"batb":[[0,1.81,15.67],[1,1.8,102.2],[2,1.74,17.32]],"ltp":1.87,"tv":381.91,"id":12482925}]}]}
{"op":"mcm","clk":"11793087722","pt":1723062612038,"mc":[{"id":"1.231499799","rc":[{"batb":[[0,1.82,10],[1,1.81,15.67],[2,1.8,102.2]],"ltp":1.87,"tv":381.91,"id":12482925}]}]}
{"op":"mcm","clk":"11793087845","pt":1723062615484,"mc":[{"id":"1.231499799","rc":[{"batb":[[0,1.81,15.67],[1,1.8,102.2],[2,1.74,17.32]],"ltp":1.87,"tv":381.91,"id":12482925}]}]}
{"op":"mcm","clk":"11793087911","pt":1723062617594,"mc":[{"id":"1.231499799","rc":[{"batb":[[2,1.74,17.32]],"ltp":2.14,"tv":49.62,"id":25686043}]}]}
{"op":"mcm","clk":"11793087937","pt":1723062618366,"mc":[{"id":"1.231499799","rc":[{"batb":[[0,1.82,10],[1,1.81,15.67],[2,1.8,102.2]],"ltp":1.87,"tv":381.91,"id":12482925}]}]}
{"op":"mcm","clk":"11793088078","pt":1723062621865,"mc":[{"id":"1.231499799","rc":[{"batb":[[0,1.81,15.67],[1,1.8,102.2],[2,1.74,17.32]],"ltp":1.87,"tv":381.91,"id":12482925}]}]}
{"op":"mcm","clk":"11793088202","pt":1723062624999,"mc":[{"id":"1.231499799","rc":[{"batb":[[0,2,54.53],[1,1.99,6.51],[2,1.98,45.31]],"ltp":2.14,"tv":49.62,"id":25686043},{"batb":[[0,1.82,10],[1,1.81,15.67],[2,1.8,102.2]],"ltp":1.87,"tv":381.91,"id":12482925}]}]}
{"op":"mcm","clk":"11793088304","pt":1723062628395,"mc":[{"id":"1.231499799","rc":[{"batb":[[0,1.81,15.67],[1,1.8,102.2],[2,1.74,17.32]],"ltp":1.87,"tv":381.91,"id":12482925}]}]}
{"op":"mcm","clk":"11793088448","pt":1723062631994,"mc":[{"id":"1.231499799","rc":[{"batb":[[0,1.82,10],[1,1.81,15.67],[2,1.8,102.2]],"ltp":1.87,"tv":381.91,"id":12482925}]}]}
{"op":"mcm","clk":"11793088576","pt":1723062635393,"mc":[{"id":"1.231499799","rc":[{"batb":[[0,1.81,15.67],[1,1.8,102.2],[2,1.74,17.32]],"ltp":1.87,"tv":381.91,"id":12482925}]}]}
{"op":"mcm","clk":"11793088709","pt":1723062638583,"mc":[{"id":"1.231499799","rc":[{"batb":[[0,1.82,10],[1,1.81,15.67],[2,1.8,102.2]],"ltp":1.87,"tv":381.91,"id":12482925}]}]}
{"op":"mcm","clk":"11793088817","pt":1723062641722,"mc":[{"id":"1.231499799","rc":[{"batb":[[0,1.81,15.67],[1,1.8,102.2],[2,1.74,17.32]],"ltp":1.87,"tv":381.91,"id":12482925}]}]}
{"op":"mcm","clk":"11793088919","pt":1723062644399,"mc":[{"id":"1.231499799","rc":[{"batb":[[0,1.82,10],[1,1.81,15.67],[2,1.8,102.2]],"ltp":1.87,"tv":381.91,"id":12482925}]}]}
{"op":"mcm","clk":"11793089011","pt":1723062647797,"mc":[{"id":"1.231499799","rc":[{"batb":[[0,1.81,15.67],[1,1.8,102.2],[2,1.74,17.32]],"ltp":1.87,"tv":381.91,"id":12482925}]}]}
{"op":"mcm","clk":"11793089114","pt":1723062650526,"mc":[{"id":"1.231499799","rc":[{"batb":[[0,1.82,10],[1,1.81,15.67],[2,1.8,102.2]],"ltp":1.87,"tv":381.91,"id":12482925}]}]}
{"op":"mcm","clk":"11793089245","pt":1723062653718,"mc":[{"id":"1.231499799","rc":[{"batb":[[0,1.81,15.67],[1,1.8,102.2],[2,1.74,17.32]],"ltp":1.87,"tv":381.91,"id":12482925}]}]}
{"op":"mcm","clk":"11793089332","pt":1723062656345,"mc":[{"id":"1.231499799","rc":[{"batb":[[0,2.02,10],[1,2,54.53],[2,1.99,6.51]],"batl":[[0,2.24,6.11]],"ltp":2.14,"tv":49.62,"id":25686043},{"batb":[[0,1.82,10],[1,1.81,15.67],[2,1.8,102.2]],"ltp":1.87,"tv":381.91,"id":12482925}]}]}
{"op":"mcm","clk":"11793089483","pt":1723062659748,"mc":[{"id":"1.231499799","rc":[{"batb":[[0,2,54.53],[1,1.99,6.51],[2,1.98,45.31]],"ltp":2.14,"tv":49.62,"id":25686043},{"batb":[[0,1.81,15.67],[1,1.8,102.2],[2,1.74,17.32]],"ltp":1.87,"tv":381.91,"id":12482925}]}]}
{"op":"mcm","clk":"11793089596","pt":1723062662357,"mc":[{"id":"1.231499799","rc":[{"batb":[[0,2.02,10],[1,2,54.53],[2,1.99,6.51]],"ltp":2.14,"tv":49.62,"id":25686043},{"batb":[[0,1.82,10],[1,1.81,15.67],[2,1.8,102.2]],"ltp":1.87,"tv":381.91,"id":12482925}]}]}
{"op":"mcm","clk":"11793089750","pt":1723062665653,"mc":[{"id":"1.231499799","rc":[{"batb":[[0,2,54.53],[1,1.99,6.51],[2,1.98,45.31]],"ltp":2.14,"tv":49.62,"id":25686043},{"batb":[[0,1.81,15.67],[1,1.8,102.2],[2,1.74,17.32]],"ltp":1.87,"tv":381.91,"id":12482925}]}]}
{"op":"mcm","clk":"11793089972","pt":1723062670225,"mc":[{"id":"1.231499799","rc":[{"batb":[[0,2.02,10],[1,2,54.53],[2,1.99,6.51]],"ltp":2.14,"tv":49.62,"id":25686043},{"batb":[[0,1.82,10],[1,1.81,15.67],[2,1.8,102.2]],"ltp":1.87,"tv":381.91,"id":12482925}]}]}
{"op":"mcm","clk":"11793090108","pt":1723062673557,"mc":[{"id":"1.231499799","rc":[{"batb":[[0,2,54.53],[1,1.99,6.51],[2,1.98,45.31]],"ltp":2.14,"tv":49.62,"id":25686043},{"batb":[[0,1.81,15.67],[1,1.8,102.2],[2,1.74,17.32]],"ltp":1.87,"tv":381.91,"id":12482925}]}]}
{"op":"mcm","clk":"11793090248","pt":1723062676953,"mc":[{"id":"1.231499799","rc":[{"batb":[[0,2.02,10],[1,2,54.53],[2,1.99,6.51]],"ltp":2.14,"tv":49.62,"id":25686043},{"batb":[[0,1.82,10],[1,1.81,15.67],[2,1.8,102.2]],"ltp":1.87,"tv":381.91,"id":12482925}]}]}
{"op":"mcm","clk":"11793090356","pt":1723062680245,"mc":[{"id":"1.231499799","rc":[{"batb":[[0,2,54.53],[1,1.99,6.51],[2,1.98,45.31]],"ltp":2.14,"tv":49.62,"id":25686043},{"batb":[[0,1.81,15.67],[1,1.8,102.2],[2,1.74,17.32]],"ltp":1.87,"tv":381.91,"id":12482925}]}]}
{"op":"mcm","clk":"11793090471","pt":1723062683067,"mc":[{"id":"1.231499799","rc":[{"batb":[[0,2.02,10],[1,2,54.53],[2,1.99,6.51]],"ltp":2.14,"tv":49.62,"id":25686043},{"batb":[[0,1.82,10],[1,1.81,15.67],[2,1.8,102.2]],"ltp":1.87,"tv":381.91,"id":12482925}]}]}
{"op":"mcm","clk":"11793090614","pt":1723062686367,"mc":[{"id":"1.231499799","rc":[{"batb":[[0,2,54.53],[1,1.99,6.51],[2,1.98,45.31]],"ltp":2.14,"tv":49.62,"id":25686043},{"batb":[[0,1.81,15.67],[1,1.8,102.2],[2,1.74,17.32]],"ltp":1.87,"tv":381.91,"id":12482925}]}]}
{"op":"mcm","clk":"11793090707","pt":1723062689247,"mc":[{"id":"1.231499799","rc":[{"batb":[[0,2.02,10],[1,2,54.53],[2,1.99,6.51]],"ltp":2.14,"tv":49.62,"id":25686043},{"batb":[[0,1.82,10],[1,1.81,15.67],[2,1.8,102.2]],"ltp":1.87,"tv":381.91,"id":12482925}]}]}
{"op":"mcm","clk":"11793090858","pt":1723062692786,"mc":[{"id":"1.231499799","rc":[{"batb":[[0,2,54.53],[1,1.99,6.51],[2,1.98,45.31]],"ltp":2.14,"tv":49.62,"id":25686043},{"batb":[[0,1.81,15.67],[1,1.8,102.2],[2,1.74,17.32]],"ltp":1.87,"tv":381.91,"id":12482925}]}]}
{"op":"mcm","clk":"11793090998","pt":1723062696594,"mc":[{"id":"1.231499799","rc":[{"batb":[[0,2.02,10],[1,2,54.53],[2,1.99,6.51]],"ltp":2.14,"tv":49.62,"id":25686043},{"batb":[[0,1.82,10],[1,1.81,15.67],[2,1.8,102.2]],"ltp":1.87,"tv":381.91,"id":12482925}]}]}
{"op":"mcm","clk":"11793091086","pt":1723062699880,"mc":[{"id":"1.231499799","rc":[{"batb":[[0,2,54.53],[1,1.99,6.51],[2,1.98,45.31]],"ltp":2.14,"tv":49.62,"id":25686043},{"batb":[[0,1.81,15.67],[1,1.8,102.2],[2,1.74,17.32]],"ltp":1.87,"tv":381.91,"id":12482925}]}]}
{"op":"mcm","clk":"11793091318","pt":1723062705584,"mc":[{"id":"1.231499799","rc":[{"batb":[[0,2.02,10],[1,2,54.53],[2,1.99,6.51]],"ltp":2.14,"tv":49.62,"id":25686043},{"batb":[[0,1.82,10],[1,1.81,15.67],[2,1.8,102.2]],"ltp":1.87,"tv":381.91,"id":12482925}]}]}
{"op":"mcm","clk":"11793091424","pt":1723062708878,"mc":[{"id":"1.231499799","rc":[{"batb":[[0,2,54.53],[1,1.99,6.51],[2,1.98,45.31]],"ltp":2.14,"tv":49.62,"id":25686043},{"batb":[[0,1.81,15.67],[1,1.8,102.2],[2,1.74,17.32]],"ltp":1.87,"tv":381.91,"id":12482925}]}]}
{"op":"mcm","clk":"11793091603","pt":1723062714079,"mc":[{"id":"1.231499799","rc":[{"batb":[[0,2.02,10],[1,2,54.53],[2,1.99,6.51]],"ltp":2.14,"tv":49.62,"id":25686043},{"batb":[[0,1.82,10],[1,1.81,15.67],[2,1.8,102.2]],"ltp":1.87,"tv":381.91,"id":12482925}]}]}
{"op":"mcm","clk":"11793091704","pt":1723062717420,"mc":[{"id":"1.231499799","rc":[{"batb":[[0,2,54.53],[1,1.99,6.51],[2,1.98,45.31]],"ltp":2.14,"tv":49.62,"id":25686043},{"batb":[[0,1.81,15.67],[1,1.8,102.2],[2,1.74,17.32]],"ltp":1.87,"tv":381.91,"id":12482925}]}]}
{"op":"mcm","clk":"11793091796","pt":1723062719991,"mc":[{"id":"1.231499799","rc":[{"batb":[[0,2.02,10],[1,2,54.53],[2,1.99,6.51]],"ltp":2.14,"tv":49.62,"id":25686043},{"batb":[[0,1.82,10],[1,1.81,15.67],[2,1.8,102.2]],"ltp":1.87,"tv":381.91,"id":12482925}]}]}
{"op":"mcm","clk":"11793091998","pt":1723062723603,"mc":[{"id":"1.231499799","rc":[{"batb":[[0,2,54.53],[1,1.99,6.51],[2,1.98,45.31]],"ltp":2.14,"tv":49.62,"id":25686043},{"batb":[[0,1.81,15.67],[1,1.8,102.2],[2,1.74,17.32]],"ltp":1.87,"tv":381.91,"id":12482925}]}]}
{"op":"mcm","clk":"11793092127","pt":1723062726333,"mc":[{"id":"1.231499799","rc":[{"batb":[[0,2.02,10],[1,2,54.53],[2,1.99,6.51]],"ltp":2.14,"tv":49.62,"id":25686043},{"batb":[[0,1.82,10],[1,1.81,15.67],[2,1.8,102.2]],"ltp":1.87,"tv":381.91,"id":12482925}]}]}
{"op":"mcm","clk":"11793092276","pt":1723062729832,"mc":[{"id":"1.231499799","rc":[{"batb":[[0,2,54.53],[1,1.99,6.51],[2,1.98,45.31]],"ltp":2.14,"tv":49.62,"id":25686043},{"batb":[[0,1.81,15.67],[1,1.8,102.2],[2,1.74,17.32]],"ltp":1.87,"tv":381.91,"id":12482925}]}]}
{"op":"mcm","clk":"11793092408","pt":1723062733125,"mc":[{"id":"1.231499799","rc":[{"batb":[[0,2.02,10],[1,2,54.53],[2,1.99,6.51]],"ltp":2.14,"tv":49.62,"id":25686043},{"batb":[[0,1.82,10],[1,1.81,15.67],[2,1.8,102.2]],"ltp":1.87,"tv":381.91,"id":12482925}]}]}
{"op":"mcm","clk":"11793092523","pt":1723062736523,"mc":[{"id":"1.231499799","rc":[{"batb":[[0,2,54.53],[1,1.99,6.51],[2,1.98,45.31]],"ltp":2.14,"tv":49.62,"id":25686043},{"batb":[[0,1.81,15.67],[1,1.8,102.2],[2,1.74,17.32]],"ltp":1.87,"tv":381.91,"id":12482925}]}]}
{"op":"mcm","clk":"11793092634","pt":1723062739513,"mc":[{"id":"1.231499799","rc":[{"batb":[[0,2.02,10],[1,2,54.53],[2,1.99,6.51]],"ltp":2.14,"tv":49.62,"id":25686043},{"batb":[[0,1.82,10],[1,1.81,15.67],[2,1.8,102.2]],"ltp":1.87,"tv":381.91,"id":12482925}]}]}
{"op":"mcm","clk":"11793092777","pt":1723062742861,"mc":[{"id":"1.231499799","rc":[{"batb":[[0,2,54.53],[1,1.99,6.51],[2,1.98,45.31]],"ltp":2.14,"tv":49.62,"id":25686043},{"batb":[[0,1.81,15.67],[1,1.8,102.2],[2,1.74,17.32]],"ltp":1.87,"tv":381.91,"id":12482925}]}]}
{"op":"mcm","clk":"11793092902","pt":1723062745745,"mc":[{"id":"1.231499799","rc":[{"batb":[[0,2.02,10],[1,2,54.53],[2,1.99,6.51]],"ltp":2.14,"tv":49.62,"id":25686043},{"batb":[[0,1.82,10],[1,1.81,15.67],[2,1.8,102.2]],"ltp":1.87,"tv":381.91,"id":12482925}]}]}
{"op":"mcm","clk":"11793093053","pt":1723062749344,"mc":[{"id":"1.231499799","rc":[{"batb":[[0,2,54.53],[1,1.99,6.51],[2,1.98,45.31]],"ltp":2.14,"tv":49.62,"id":25686043},{"batb":[[0,1.81,15.67],[1,1.8,102.2],[2,1.74,17.32]],"ltp":1.87,"tv":381.91,"id":12482925}]}]}
{"op":"mcm","clk":"11793093145","pt":1723062752068,"mc":[{"id":"1.231499799","rc":[{"batb":[[0,2.02,10],[1,2,54.53],[2,1.99,6.51]],"ltp":2.14,"tv":49.62,"id":25686043},{"batb":[[0,1.82,10],[1,1.81,15.67],[2,1.8,102.2]],"ltp":1.87,"tv":381.91,"id":12482925}]}]}
{"op":"mcm","clk":"11793093303","pt":1723062755371,"mc":[{"id":"1.231499799","rc":[{"batb":[[0,2,54.53],[1,1.99,6.51],[2,1.98,45.31]],"ltp":2.14,"tv":49.62,"id":25686043},{"batb":[[0,1.81,15.67],[1,1.8,102.2],[2,1.74,17.32]],"ltp":1.87,"tv":381.91,"id":12482925}]}]}
{"op":"mcm","clk":"11793093433","pt":1723062757747,"mc":[{"id":"1.231499799","rc":[{"batb":[[0,2.02,10],[1,2,54.53],[2,1.99,6.51]],"ltp":2.14,"tv":49.62,"id":25686043},{"batb":[[0,1.82,10],[1,1.81,15.67],[2,1.8,102.2]],"ltp":1.87,"tv":381.91,"id":12482925}]}]}
{"op":"mcm","clk":"11793093570","pt":1723062761136,"mc":[{"id":"1.231499799","rc":[{"batb":[[0,2,54.53],[1,1.99,6.51],[2,1.98,45.31]],"ltp":2.14,"tv":49.62,"id":25686043},{"batb":[[0,1.81,15.67],[1,1.8,102.2],[2,1.74,17.32]],"ltp":1.87,"tv":381.91,"id":12482925}]}]}
{"op":"mcm","clk":"11793093734","pt":1723062765356,"mc":[{"id":"1.231499799","rc":[{"batb":[[0,2.02,10],[1,2,54.53],[2,1.99,6.51]],"ltp":2.14,"tv":49.62,"id":25686043},{"batb":[[0,1.82,10],[1,1.81,15.67],[2,1.8,102.2]],"ltp":1.87,"tv":381.91,"id":12482925}]}]}
{"op":"mcm","clk":"11793093847","pt":1723062768878,"mc":[{"id":"1.231499799","rc":[{"batb":[[0,2,54.53],[1,1.99,6.51],[2,1.98,45.31]],"ltp":2.14,"tv":49.62,"id":25686043},{"batb":[[0,1.81,15.67],[1,1.8,102.2],[2,1.74,17.32]],"ltp":1.87,"tv":381.91,"id":12482925}]}]}
{"op":"mcm","clk":"11793093964","pt":1723062771855,"mc":[{"id":"1.231499799","rc":[{"batb":[[0,2.02,10],[1,2,54.53],[2,1.99,6.51]],"ltp":2.14,"tv":49.62,"id":25686043},{"batb":[[0,1.82,10],[1,1.81,15.67],[2,1.8,102.2]],"ltp":1.87,"tv":381.91,"id":12482925}]}]}
{"op":"mcm","clk":"11793094086","pt":1723062775296,"mc":[{"id":"1.231499799","rc":[{"batb":[[0,2,54.53],[1,1.99,6.51],[2,1.98,45.31]],"ltp":2.14,"tv":49.62,"id":25686043},{"batb":[[0,1.81,15.67],[1,1.8,102.2],[2,1.74,17.32]],"ltp":1.87,"tv":381.91,"id":12482925}]}]}
{"op":"mcm","clk":"11793094225","pt":1723062778487,"mc":[{"id":"1.231499799","rc":[{"batb":[[0,2.02,10],[1,2,54.53],[2,1.99,6.51]],"ltp":2.14,"tv":49.62,"id":25686043},{"batb":[[0,1.82,10],[1,1.81,15.67],[2,1.8,102.2]],"ltp":1.87,"tv":381.91,"id":12482925}]}]}
{"op":"mcm","clk":"11793094388","pt":1723062782091,"mc":[{"id":"1.231499799","rc":[{"batb":[[0,2,54.53],[1,1.99,6.51],[2,1.98,45.31]],"ltp":2.14,"tv":49.62,"id":25686043},{"batb":[[0,1.81,15.67],[1,1.8,102.2],[2,1.74,17.32]],"ltp":1.87,"tv":381.91,"id":12482925}]}]}
{"op":"mcm","clk":"11793094492","pt":1723062784463,"mc":[{"id":"1.231499799","rc":[{"batb":[[0,2.02,10],[1,2,54.53],[2,1.99,6.51]],"ltp":2.14,"tv":49.62,"id":25686043},{"batb":[[0,1.82,10],[1,1.81,15.67],[2,1.8,102.2]],"ltp":1.87,"tv":381.91,"id":12482925}]}]}
{"op":"mcm","clk":"11793094643","pt":1723062787966,"mc":[{"id":"1.231499799","rc":[{"batb":[[0,2,54.53],[1,1.99,6.51],[2,1.98,45.31]],"ltp":2.14,"tv":49.62,"id":25686043},{"batb":[[0,1.81,15.67],[1,1.8,102.2],[2,1.74,17.32]],"ltp":1.87,"tv":381.91,"id":12482925}]}]}
{"op":"mcm","clk":"11793094683","pt":1723062789200,"mc":[{"id":"1.231499799","rc":[{"batb":[[0,1.99,6.51],[1,1.98,45.31],[2,1.74,17.32]],"ltp":2.14,"tv":49.62,"id":25686043}]}]}
{"op":"mcm","clk":"11793094745","pt":1723062790396,"mc":[{"id":"1.231499799","rc":[{"batb":[[0,2,10],[1,1.99,6.51],[2,1.98,45.31]],"ltp":2.14,"tv":49.62,"id":25686043},{"batb":[[0,1.82,10],[1,1.81,15.67],[2,1.8,102.2]],"ltp":1.87,"tv":381.91,"id":12482925}]}]}
{"op":"mcm","clk":"11793094875","pt":1723062793802,"mc":[{"id":"1.231499799","rc":[{"batb":[[0,1.99,6.51],[1,1.98,45.31],[2,1.74,17.32]],"ltp":2.14,"tv":49.62,"id":25686043},{"batb":[[0,1.81,15.67],[1,1.8,102.2],[2,1.74,17.32]],"ltp":1.87,"tv":381.91,"id":12482925}]}]}
{"op":"mcm","clk":"11793094995","pt":1723062797094,"mc":[{"id":"1.231499799","rc":[{"batb":[[0,2,10],[1,1.99,6.51],[2,1.98,45.31]],"ltp":2.14,"tv":49.62,"id":25686043},{"batb":[[0,1.82,10],[1,1.81,15.67],[2,1.8,102.2]],"ltp":1.87,"tv":381.91,"id":12482925}]}]}
{"op":"mcm","clk":"11793095216","pt":1723062800909,"mc":[{"id":"1.231499799","rc":[{"batb":[[0,1.99,6.51],[1,1.98,45.31],[2,1.74,17.32]],"ltp":2.14,"tv":49.62,"id":25686043},{"batb":[[0,1.81,15.67],[1,1.8,102.2],[2,1.74,17.32]],"ltp":1.87,"tv":381.91,"id":12482925}]}]}
{"op":"mcm","clk":"11793095324","pt":1723062802912,"mc":[{"id":"1.231499799","rc":[{"batb":[[0,2.02,53.46],[1,1.99,6.51],[2,1.98,45.31]],"ltp":2.14,"tv":49.62,"id":25686043}]}]}
{"op":"mcm","clk":"11793095335","pt":1723062803118,"mc":[{"id":"1.231499799","rc":[{"batb":[[0,2.04,10],[1,2.02,53.46],[2,1.99,6.51]],"ltp":2.14,"tv":49.62,"id":25686043},{"batb":[[0,1.82,10],[1,1.81,15.67],[2,1.8,102.2]],"ltp":1.87,"tv":381.91,"id":12482925}]}]}
{"op":"mcm","clk":"11793095478","pt":1723062806407,"mc":[{"id":"1.231499799","rc":[{"batb":[[0,2.02,53.46],[1,1.99,6.51],[2,1.98,45.31]],"ltp":2.14,"tv":49.62,"id":25686043},{"batb":[[0,1.81,15.67],[1,1.8,102.2],[2,1.74,17.32]],"ltp":1.87,"tv":381.91,"id":12482925}]}]}
{"op":"mcm","clk":"11793095650","pt":1723062809910,"mc":[{"id":"1.231499799","rc":[{"batb":[[0,2.04,10],[1,2.02,53.46],[2,1.99,6.51]],"ltp":2.14,"tv":49.62,"id":25686043},{"batb":[[0,1.82,10],[1,1.81,15.67],[2,1.8,102.2]],"ltp":1.87,"tv":381.91,"id":12482925}]}]}
{"op":"mcm","clk":"11793095820","pt":1723062813407,"mc":[{"id":"1.231499799","rc":[{"batb":[[0,2.02,53.46],[1,1.99,6.51],[2,1.98,45.31]],"ltp":2.14,"tv":49.62,"id":25686043},{"batb":[[0,1.81,15.67],[1,1.8,102.2],[2,1.74,17.32]],"ltp":1.87,"tv":381.91,"id":12482925}]}]}
{"op":"mcm","clk":"11793095984","pt":1723062817013,"mc":[{"id":"1.231499799","rc":[{"batb":[[0,2.04,10],[1,2.02,53.46],[2,1.99,6.51]],"ltp":2.14,"tv":49.62,"id":25686043},{"batb":[[0,1.82,10],[1,1.81,15.67],[2,1.8,102.2]],"ltp":1.87,"tv":381.91,"id":12482925}]}]}
{"op":"mcm","clk":"11793096053","pt":1723062818709,"mc":[{"id":"1.231499799","rc":[{"batb":[[1,1.81,7.43],[2,1.74,17.32]],"ltp":1.87,"tv":381.91,"id":12482925}]}]}
{"op":"mcm","clk":"11793096083","pt":1723062819640,"mc":[{"id":"1.231499799","rc":[{"batb":[[1,1.99,59.97],[2,1.98,45.31]],"ltp":2.14,"tv":49.62,"id":25686043}]}]}
{"op":"mcm","clk":"11793096118","pt":1723062820506,"mc":[{"id":"1.231499799","rc":[{"batb":[[0,1.99,59.97],[1,1.98,45.31],[2,1.74,17.32]],"ltp":2.14,"tv":49.62,"id":25686043},{"batb":[[0,1.81,7.43],[1,1.74,17.32],[2,1.53,94.34]],"ltp":1.87,"tv":381.91,"id":12482925}]}]}
{"op":"mcm","clk":"11793096239","pt":1723062823843,"mc":[{"id":"1.231499799","rc":[{"batb":[[0,1.82,10],[1,1.81,7.43],[2,1.74,17.32]],"ltp":1.87,"tv":381.91,"id":12482925}]}]}
{"op":"mcm","clk":"11793096330","pt":1723062826011,"mc":[{"id":"1.231499799","rc":[{"batb":[[0,2.02,53.46],[1,1.99,6.51],[2,1.98,45.31]],"ltp":2.14,"tv":49.62,"id":25686043}]}]}
{"op":"mcm","clk":"11793096360","pt":1723062827137,"mc":[{"id":"1.231499799","rc":[{"batb":[[0,1.81,7.43],[1,1.74,17.32],[2,1.53,94.34]],"ltp":1.87,"tv":381.91,"id":12482925}]}]}
{"op":"mcm","clk":"11793096487","pt":1723062830226,"mc":[{"id":"1.231499799","rc":[{"batb":[[0,1.82,10],[1,1.81,7.43],[2,1.74,17.32]],"ltp":1.87,"tv":381.91,"id":12482925}]}]}
{"op":"mcm","clk":"11793096658","pt":1723062833830,"mc":[{"id":"1.231499799","rc":[{"batb":[[0,1.81,7.43],[1,1.74,17.32],[2,1.53,94.34]],"ltp":1.87,"tv":381.91,"id":12482925}]}]}
{"op":"mcm","clk":"11793096742","pt":1723062836148,"mc":[{"id":"1.231499799","rc":[{"batb":[[0,1.82,10],[1,1.81,7.43],[2,1.74,17.32]],"ltp":1.87,"tv":381.91,"id":12482925}]}]}
{"op":"mcm","clk":"11793096871","pt":1723062839748,"mc":[{"id":"1.231499799","rc":[{"batb":[[0,1.81,7.43],[1,1.74,17.32],[2,1.53,94.34]],"ltp":1.87,"tv":381.91,"id":12482925}]}]}
{"op":"mcm","clk":"11793096989","pt":1723062842634,"mc":[{"id":"1.231499799","rc":[{"batb":[[0,1.82,10],[1,1.81,7.43],[2,1.74,17.32]],"ltp":1.87,"tv":381.91,"id":12482925}]}]}
{"op":"mcm","clk":"11793097118","pt":1723062845949,"mc":[{"id":"1.231499799","rc":[{"batb":[[0,1.81,7.43],[1,1.74,17.32],[2,1.53,94.34]],"ltp":1.87,"tv":381.91,"id":12482925}]}]}
{"op":"mcm","clk":"11793097200","pt":1723062848968,"mc":[{"id":"1.231499799","rc":[{"batb":[[0,1.82,10],[1,1.81,7.43],[2,1.74,17.32]],"ltp":1.87,"tv":381.91,"id":12482925}]}]}
{"op":"mcm","clk":"11793097333","pt":1723062852463,"mc":[{"id":"1.231499799","rc":[{"batb":[[0,1.81,7.43],[1,1.74,17.32],[2,1.53,94.34]],"ltp":1.87,"tv":381.91,"id":12482925}]}]}
{"op":"mcm","clk":"11793097480","pt":1723062855861,"mc":[{"id":"1.231499799","rc":[{"batb":[[0,1.82,10],[1,1.81,7.43],[2,1.74,17.32]],"ltp":1.87,"tv":381.91,"id":12482925}]}]}
{"op":"mcm","clk":"11793097703","pt":1723062859274,"mc":[{"id":"1.231499799","rc":[{"batb":[[0,1.81,7.43],[1,1.74,17.32],[2,1.53,94.34]],"ltp":1.87,"tv":381.91,"id":12482925}]}]}
{"op":"mcm","clk":"11793097828","pt":1723062862188,"mc":[{"id":"1.231499799","rc":[{"batb":[[0,1.82,10],[1,1.81,7.43],[2,1.74,17.32]],"ltp":1.87,"tv":381.91,"id":12482925}]}]}
{"op":"mcm","clk":"11793097967","pt":1723062865685,"mc":[{"id":"1.231499799","rc":[{"batb":[[0,1.81,7.43],[1,1.74,17.32],[2,1.53,94.34]],"ltp":1.87,"tv":381.91,"id":12482925}]}]}
{"op":"mcm","clk":"11793098083","pt":1723062868617,"mc":[{"id":"1.231499799","rc":[{"batb":[[0,1.82,10],[1,1.81,7.43],[2,1.74,17.32]],"ltp":1.87,"tv":381.91,"id":12482925}]}]}
{"op":"mcm","clk":"11793098265","pt":1723062871916,"mc":[{"id":"1.231499799","rc":[{"batb":[[0,1.81,7.43],[1,1.74,17.32],[2,1.53,94.34]],"ltp":1.87,"tv":381.91,"id":12482925}]}]}
{"op":"mcm","clk":"11793098427","pt":1723062875720,"mc":[{"id":"1.231499799","rc":[{"batb":[[0,1.82,10],[1,1.81,7.43],[2,1.74,17.32]],"ltp":1.87,"tv":381.91,"id":12482925}]}]}
{"op":"mcm","clk":"11793098596","pt":1723062879222,"mc":[{"id":"1.231499799","rc":[{"batb":[[0,1.81,7.43],[1,1.74,17.32],[2,1.53,94.34]],"ltp":1.87,"tv":381.91,"id":12482925}]}]}
{"op":"mcm","clk":"11793098686","pt":1723062881787,"mc":[{"id":"1.231499799","rc":[{"batb":[[0,1.82,10],[1,1.81,7.43],[2,1.74,17.32]],"ltp":1.87,"tv":381.91,"id":12482925}]}]}
{"op":"mcm","clk":"11793098815","pt":1723062885118,"mc":[{"id":"1.231499799","rc":[{"batb":[[0,1.81,7.43],[1,1.74,17.32],[2,1.53,94.34]],"ltp":1.87,"tv":381.91,"id":12482925}]}]}
{"op":"mcm","clk":"11793098989","pt":1723062889700,"mc":[{"id":"1.231499799","rc":[{"batb":[[0,1.82,10],[1,1.81,7.43],[2,1.74,17.32]],"ltp":1.87,"tv":381.91,"id":12482925}]}]}
{"op":"mcm","clk":"11793099164","pt":1723062893242,"mc":[{"id":"1.231499799","rc":[{"batb":[[0,1.81,7.43],[1,1.74,17.32],[2,1.53,94.34]],"ltp":1.87,"tv":381.91,"id":12482925}]}]}
{"op":"mcm","clk":"11793099271","pt":1723062896124,"mc":[{"id":"1.231499799","rc":[{"batb":[[0,1.82,10],[1,1.81,7.43],[2,1.74,17.32]],"ltp":1.87,"tv":381.91,"id":12482925}]}]}
{"op":"mcm","clk":"11793099405","pt":1723062899627,"mc":[{"id":"1.231499799","rc":[{"batb":[[0,1.81,7.43],[1,1.74,17.32],[2,1.53,94.34]],"ltp":1.87,"tv":381.91,"id":12482925}]}]}
{"op":"mcm","clk":"11793099533","pt":1723062902724,"mc":[{"id":"1.231499799","rc":[{"batb":[[0,1.82,10],[1,1.81,7.43],[2,1.74,17.32]],"ltp":1.87,"tv":381.91,"id":12482925}]}]}
{"op":"mcm","clk":"11793099652","pt":1723062906213,"mc":[{"id":"1.231499799","rc":[{"batb":[[0,1.81,7.43],[1,1.74,17.32],[2,1.53,94.34]],"ltp":1.87,"tv":381.91,"id":12482925}]}]}
{"op":"mcm","clk":"11793099737","pt":1723062908428,"mc":[{"id":"1.231499799","rc":[{"batb":[[0,1.82,10],[1,1.81,7.43],[2,1.74,17.32]],"ltp":1.87,"tv":381.91,"id":12482925}]}]}
{"op":"mcm","clk":"11793099863","pt":1723062911764,"mc":[{"id":"1.231499799","rc":[{"batb":[[0,1.81,7.43],[1,1.74,17.32],[2,1.53,94.34]],"ltp":1.87,"tv":381.91,"id":12482925}]}]}
{"op":"mcm","clk":"11793099968","pt":1723062914641,"mc":[{"id":"1.231499799","rc":[{"batb":[[0,1.82,10],[1,1.81,7.43],[2,1.74,17.32]],"ltp":1.87,"tv":381.91,"id":12482925}]}]}
{"op":"mcm","clk":"11793100085","pt":1723062918129,"mc":[{"id":"1.231499799","rc":[{"batb":[[0,1.81,7.43],[1,1.74,17.32],[2,1.53,94.34]],"ltp":1.87,"tv":381.91,"id":12482925}]}]}
{"op":"mcm","clk":"11793100208","pt":1723062921565,"mc":[{"id":"1.231499799","rc":[{"batb":[[0,1.82,10],[1,1.81,7.43],[2,1.74,17.32]],"ltp":1.87,"tv":381.91,"id":12482925}]}]}
{"op":"mcm","clk":"11793100332","pt":1723062924851,"mc":[{"id":"1.231499799","rc":[{"batb":[[0,1.81,7.43],[1,1.74,17.32],[2,1.53,94.34]],"ltp":1.87,"tv":381.91,"id":12482925}]}]}
{"op":"mcm","clk":"11793100442","pt":1723062927933,"mc":[{"id":"1.231499799","rc":[{"batb":[[0,1.82,10],[1,1.81,7.43],[2,1.74,17.32]],"ltp":1.87,"tv":381.91,"id":12482925}]}]}
{"op":"mcm","clk":"11793100561","pt":1723062931372,"mc":[{"id":"1.231499799","rc":[{"batb":[[0,1.81,7.43],[1,1.74,17.32],[2,1.53,94.34]],"ltp":1.87,"tv":381.91,"id":12482925}]}]}
{"op":"mcm","clk":"11793100643","pt":1723062933893,"mc":[{"id":"1.231499799","rc":[{"batb":[[0,1.82,10],[1,1.81,7.43],[2,1.74,17.32]],"ltp":1.87,"tv":381.91,"id":12482925}]}]}
{"op":"mcm","clk":"11793100783","pt":1723062937186,"mc":[{"id":"1.231499799","rc":[{"batb":[[0,1.81,7.43],[1,1.74,17.32],[2,1.53,94.34]],"ltp":1.87,"tv":381.91,"id":12482925}]}]}
{"op":"mcm","clk":"11793100961","pt":1723062942886,"mc":[{"id":"1.231499799","rc":[{"batb":[[0,1.82,10],[1,1.81,7.43],[2,1.74,17.32]],"ltp":1.87,"tv":381.91,"id":12482925}]}]}
{"op":"mcm","clk":"11793101043","pt":1723062946285,"mc":[{"id":"1.231499799","rc":[{"batb":[[0,1.81,7.43],[1,1.74,17.32],[2,1.53,94.34]],"ltp":1.87,"tv":381.91,"id":12482925}]}]}
{"op":"mcm","clk":"11793101100","pt":1723062948852,"mc":[{"id":"1.231499799","rc":[{"batb":[[0,1.82,10],[1,1.81,7.43],[2,1.74,17.32]],"ltp":1.87,"tv":381.91,"id":12482925}]}]}
{"op":"mcm","clk":"11793101228","pt":1723062952188,"mc":[{"id":"1.231499799","rc":[{"batb":[[0,1.81,7.43],[1,1.74,17.32],[2,1.53,94.34]],"ltp":1.87,"tv":381.91,"id":12482925}]}]}
{"op":"mcm","clk":"11793101288","pt":1723062954808,"mc":[{"id":"1.231499799","rc":[{"batb":[[0,1.82,10],[1,1.81,7.43],[2,1.74,17.32]],"ltp":1.87,"tv":381.91,"id":12482925}]}]}
{"op":"mcm","clk":"11793101402","pt":1723062958095,"mc":[{"id":"1.231499799","rc":[{"batb":[[0,1.81,7.43],[1,1.74,17.32],[2,1.53,94.34]],"ltp":1.87,"tv":381.91,"id":12482925}]}]}
{"op":"mcm","clk":"11793101524","pt":1723062961491,"mc":[{"id":"1.231499799","rc":[{"batb":[[0,1.82,10],[1,1.81,7.43],[2,1.74,17.32]],"ltp":1.87,"tv":381.91,"id":12482925}]}]}
{"op":"mcm","clk":"11793101655","pt":1723062964788,"mc":[{"id":"1.231499799","rc":[{"batb":[[0,1.81,7.43],[1,1.74,17.32],[2,1.53,94.34]],"ltp":1.87,"tv":381.91,"id":12482925}]}]}
{"op":"mcm","clk":"11793101767","pt":1723062967872,"mc":[{"id":"1.231499799","rc":[{"batb":[[0,1.82,10],[1,1.81,7.43],[2,1.74,17.32]],"ltp":1.87,"tv":381.91,"id":12482925}]}]}
{"op":"mcm","clk":"11793101857","pt":1723062971222,"mc":[{"id":"1.231499799","rc":[{"batb":[[0,1.81,7.43],[1,1.74,17.32],[2,1.53,94.34]],"ltp":1.87,"tv":381.91,"id":12482925}]}]}
{"op":"mcm","clk":"11793101970","pt":1723062974616,"mc":[{"id":"1.231499799","rc":[{"batb":[[0,1.82,10],[1,1.81,7.43],[2,1.74,17.32]],"ltp":1.87,"tv":381.91,"id":12482925}]}]}
{"op":"mcm","clk":"11793102105","pt":1723062978123,"mc":[{"id":"1.231499799","rc":[{"batb":[[0,1.81,7.43],[1,1.74,17.32],[2,1.53,94.34]],"ltp":1.87,"tv":381.91,"id":12482925}]}]}
{"op":"mcm","clk":"11793102216","pt":1723062980636,"mc":[{"id":"1.231499799","rc":[{"batb":[[0,1.82,10],[1,1.81,7.43],[2,1.74,17.32]],"ltp":1.87,"tv":381.91,"id":12482925}]}]}
{"op":"mcm","clk":"11793102348","pt":1723062983728,"mc":[{"id":"1.231499799","rc":[{"batb":[[0,1.81,7.43],[1,1.74,17.32],[2,1.53,94.34]],"ltp":1.87,"tv":381.91,"id":12482925}]}]}
{"op":"mcm","clk":"11793102455","pt":1723062986404,"mc":[{"id":"1.231499799","rc":[{"batb":[[0,1.82,10],[1,1.81,7.43],[2,1.74,17.32]],"ltp":1.87,"tv":381.91,"id":12482925}]}]}
{"op":"mcm","clk":"11793102576","pt":1723062989701,"mc":[{"id":"1.231499799","rc":[{"batb":[[0,1.81,7.43],[1,1.74,17.32],[2,1.53,94.34]],"ltp":1.87,"tv":381.91,"id":12482925}]}]}
{"op":"mcm","clk":"11793102691","pt":1723062992630,"mc":[{"id":"1.231499799","rc":[{"batb":[[0,1.82,10],[1,1.81,7.43],[2,1.74,17.32]],"ltp":1.87,"tv":381.91,"id":12482925}]}]}
{"op":"mcm","clk":"11793102818","pt":1723062996123,"mc":[{"id":"1.231499799","rc":[{"batb":[[0,1.81,7.43],[1,1.74,17.32],[2,1.53,94.34]],"ltp":1.87,"tv":381.91,"id":12482925}]}]}
{"op":"mcm","clk":"11793102928","pt":1723062999509,"mc":[{"id":"1.231499799","rc":[{"batb":[[0,1.82,10],[1,1.81,7.43],[2,1.74,17.32]],"ltp":1.87,"tv":381.91,"id":12482925}]}]}
{"op":"mcm","clk":"11793103023","pt":1723063002840,"mc":[{"id":"1.231499799","rc":[{"batb":[[0,1.81,7.43],[1,1.74,17.32],[2,1.53,94.34]],"ltp":1.87,"tv":381.91,"id":12482925}]}]}
{"op":"mcm","clk":"11793103108","pt":1723063005511,"mc":[{"id":"1.231499799","rc":[{"batb":[[0,1.82,10],[1,1.81,7.43],[2,1.74,17.32]],"ltp":1.87,"tv":381.91,"id":12482925}]}]}
{"op":"mcm","clk":"11793103226","pt":1723063008943,"mc":[{"id":"1.231499799","rc":[{"batb":[[0,1.81,7.43],[1,1.74,17.32],[2,1.53,94.34]],"ltp":1.87,"tv":381.91,"id":12482925}]}]}
{"op":"mcm","clk":"11793103419","pt":1723063013619,"mc":[{"id":"1.231499799","rc":[{"batb":[[0,1.82,10],[1,1.81,7.43],[2,1.74,17.32]],"ltp":1.87,"tv":381.91,"id":12482925}]}]}
{"op":"mcm","clk":"11793103557","pt":1723063017119,"mc":[{"id":"1.231499799","rc":[{"batb":[[0,1.81,7.43],[1,1.74,17.32],[2,1.53,94.34]],"ltp":1.87,"tv":381.91,"id":12482925}]}]}
{"op":"mcm","clk":"11793103697","pt":1723063020361,"mc":[{"id":"1.231499799","rc":[{"batb":[[0,1.82,10],[1,1.81,7.43],[2,1.74,17.32]],"ltp":1.87,"tv":381.91,"id":12482925}]}]}
{"op":"mcm","clk":"11793103799","pt":1723063023655,"mc":[{"id":"1.231499799","rc":[{"batb":[[0,1.81,7.43],[1,1.74,17.32],[2,1.53,94.34]],"ltp":1.87,"tv":381.91,"id":12482925}]}]}
{"op":"mcm","clk":"11793103974","pt":1723063027941,"mc":[{"id":"1.231499799","rc":[{"batb":[[0,1.82,10],[1,1.81,7.43],[2,1.74,17.32]],"ltp":1.87,"tv":381.91,"id":12482925}]}]}
{"op":"mcm","clk":"11793104106","pt":1723063031234,"mc":[{"id":"1.231499799","rc":[{"batb":[[0,1.81,7.43],[1,1.74,17.32],[2,1.53,94.34]],"ltp":1.87,"tv":381.91,"id":12482925}]}]}
{"op":"mcm","clk":"11793104191","pt":1723063034571,"mc":[{"id":"1.231499799","rc":[{"batb":[[0,1.82,10],[1,1.81,7.43],[2,1.74,17.32]],"ltp":1.87,"tv":381.91,"id":12482925}]}]}
{"op":"mcm","clk":"11793104311","pt":1723063038071,"mc":[{"id":"1.231499799","rc":[{"batb":[[0,1.81,7.43],[1,1.74,17.32],[2,1.53,94.34]],"ltp":1.87,"tv":381.91,"id":12482925}]}]}
{"op":"mcm","clk":"11793104438","pt":1723063041577,"mc":[{"id":"1.231499799","rc":[{"batb":[[0,1.82,10],[1,1.81,7.43],[2,1.74,17.32]],"ltp":1.87,"tv":381.91,"id":12482925}]}]}
{"op":"mcm","clk":"11793104558","pt":1723063044968,"mc":[{"id":"1.231499799","rc":[{"batb":[[0,1.81,7.43],[1,1.74,17.32],[2,1.53,94.34]],"ltp":1.87,"tv":381.91,"id":12482925}]}]}
{"op":"mcm","clk":"11793104689","pt":1723063048668,"mc":[{"id":"1.231499799","rc":[{"batb":[[0,1.82,10],[1,1.81,7.43],[2,1.74,17.32]],"ltp":1.87,"tv":381.91,"id":12482925}]}]}
{"op":"mcm","clk":"11793104813","pt":1723063052176,"mc":[{"id":"1.231499799","rc":[{"batb":[[0,1.81,7.43],[1,1.74,17.32],[2,1.53,94.34]],"ltp":1.87,"tv":381.91,"id":12482925}]}]}
{"op":"mcm","clk":"11793104891","pt":1723063054381,"mc":[{"id":"1.231499799","rc":[{"batb":[[0,1.82,10],[1,1.81,7.43],[2,1.74,17.32]],"ltp":1.87,"tv":381.91,"id":12482925}]}]}
{"op":"mcm","clk":"11793105024","pt":1723063057874,"mc":[{"id":"1.231499799","rc":[{"batb":[[0,1.81,7.43],[1,1.74,17.32],[2,1.53,94.34]],"ltp":1.87,"tv":381.91,"id":12482925}]}]}
{"op":"mcm","clk":"11793105138","pt":1723063060699,"mc":[{"id":"1.231499799","rc":[{"batb":[[0,1.82,10],[1,1.81,7.43],[2,1.74,17.32]],"ltp":1.87,"tv":381.91,"id":12482925}]}]}
{"op":"mcm","clk":"11793105244","pt":1723063063985,"mc":[{"id":"1.231499799","rc":[{"batb":[[0,1.81,7.43],[1,1.74,17.32],[2,1.53,94.34]],"ltp":1.87,"tv":381.91,"id":12482925}]}]}
{"op":"mcm","clk":"11793105314","pt":1723063066601,"mc":[{"id":"1.231499799","rc":[{"batb":[[0,1.82,10],[1,1.81,7.43],[2,1.74,17.32]],"ltp":1.87,"tv":381.91,"id":12482925}]}]}
{"op":"mcm","clk":"11793105424","pt":1723063070096,"mc":[{"id":"1.231499799","rc":[{"batb":[[0,1.81,7.43],[1,1.74,17.32],[2,1.53,94.34]],"ltp":1.87,"tv":381.91,"id":12482925}]}]}
{"op":"mcm","clk":"11793105609","pt":1723063074823,"mc":[{"id":"1.231499799","rc":[{"batb":[[0,1.82,10],[1,1.81,7.43],[2,1.74,17.32]],"ltp":1.87,"tv":381.91,"id":12482925}]}]}
{"op":"mcm","clk":"11793105775","pt":1723063079290,"mc":[{"id":"1.231499799","rc":[{"batb":[[0,1.81,7.43],[1,1.74,17.32],[2,1.53,94.34]],"ltp":1.87,"tv":381.91,"id":12482925}]}]}
{"op":"mcm","clk":"11793105890","pt":1723063081711,"mc":[{"id":"1.231499799","rc":[{"batb":[[0,1.82,10],[1,1.81,7.43],[2,1.74,17.32]],"ltp":1.87,"tv":381.91,"id":12482925}]}]}
{"op":"mcm","clk":"11793106025","pt":1723063085097,"mc":[{"id":"1.231499799","rc":[{"batb":[[0,1.81,7.43],[1,1.74,17.32],[2,1.53,94.34]],"ltp":1.87,"tv":381.91,"id":12482925}]}]}
{"op":"mcm","clk":"11793106188","pt":1723063088435,"mc":[{"id":"1.231499799","rc":[{"batb":[[0,1.82,10],[1,1.81,7.43],[2,1.74,17.32]],"ltp":1.87,"tv":381.91,"id":12482925}]}]}
{"op":"mcm","clk":"11793106319","pt":1723063092018,"mc":[{"id":"1.231499799","rc":[{"batb":[[0,1.81,7.43],[1,1.74,17.32],[2,1.53,94.34]],"ltp":1.87,"tv":381.91,"id":12482925}]}]}
{"op":"mcm","clk":"11793106456","pt":1723063095914,"mc":[{"id":"1.231499799","rc":[{"batb":[[0,1.82,10],[1,1.81,7.43],[2,1.74,17.32]],"ltp":1.87,"tv":381.91,"id":12482925}]}]}
{"op":"mcm","clk":"11793106594","pt":1723063099609,"mc":[{"id":"1.231499799","rc":[{"batb":[[0,1.81,7.43],[1,1.74,17.32],[2,1.53,94.34]],"ltp":1.87,"tv":381.91,"id":12482925}]}]}
{"op":"mcm","clk":"11793106678","pt":1723063102022,"mc":[{"id":"1.231499799","rc":[{"batb":[[0,1.82,10],[1,1.81,7.43],[2,1.74,17.32]],"ltp":1.87,"tv":381.91,"id":12482925}]}]}
{"op":"mcm","clk":"11793106807","pt":1723063105417,"mc":[{"id":"1.231499799","rc":[{"batb":[[0,1.81,7.43],[1,1.74,17.32],[2,1.53,94.34]],"ltp":1.87,"tv":381.91,"id":12482925}]}]}
{"op":"mcm","clk":"11793106873","pt":1723063107621,"mc":[{"id":"1.231499799","rc":[{"batb":[[0,1.82,10],[1,1.81,7.43],[2,1.74,17.32]],"ltp":1.87,"tv":381.91,"id":12482925}]}]}
{"op":"mcm","clk":"11793106996","pt":1723063111055,"mc":[{"id":"1.231499799","rc":[{"batb":[[0,1.81,7.43],[1,1.74,17.32],[2,1.53,94.34]],"ltp":1.87,"tv":381.91,"id":12482925}]}]}
{"op":"mcm","clk":"11793107100","pt":1723063113630,"mc":[{"id":"1.231499799","rc":[{"batb":[[0,1.82,10],[1,1.81,7.43],[2,1.74,17.32]],"ltp":1.87,"tv":381.91,"id":12482925}]}]}
{"op":"mcm","clk":"11793107220","pt":1723063117050,"mc":[{"id":"1.231499799","rc":[{"batb":[[0,1.81,7.43],[1,1.74,17.32],[2,1.53,94.34]],"ltp":1.87,"tv":381.91,"id":12482925}]}]}
{"op":"mcm","clk":"11793107383","pt":1723063121742,"mc":[{"id":"1.231499799","rc":[{"batb":[[0,1.82,10],[1,1.81,7.43],[2,1.74,17.32]],"ltp":1.87,"tv":381.91,"id":12482925}]}]}
{"op":"mcm","clk":"11793107477","pt":1723063125063,"mc":[{"id":"1.231499799","rc":[{"batb":[[0,1.81,7.43],[1,1.74,17.32],[2,1.53,94.34]],"ltp":1.87,"tv":381.91,"id":12482925}]}]}
{"op":"mcm","clk":"11793107584","pt":1723063127835,"mc":[{"id":"1.231499799","rc":[{"batb":[[0,1.82,10],[1,1.81,7.43],[2,1.74,17.32]],"ltp":1.87,"tv":381.91,"id":12482925}]}]}
{"op":"mcm","clk":"11793107697","pt":1723063131266,"mc":[{"id":"1.231499799","rc":[{"batb":[[0,1.81,7.43],[1,1.74,17.32],[2,1.53,94.34]],"ltp":1.87,"tv":381.91,"id":12482925}]}]}
{"op":"mcm","clk":"11793107799","pt":1723063134238,"mc":[{"id":"1.231499799","rc":[{"batb":[[0,1.82,10],[1,1.81,7.43],[2,1.74,17.32]],"ltp":1.87,"tv":381.91,"id":12482925}]}]}
{"op":"mcm","clk":"11793107936","pt":1723063137775,"mc":[{"id":"1.231499799","rc":[{"batb":[[0,1.81,7.43],[1,1.74,17.32],[2,1.53,94.34]],"ltp":1.87,"tv":381.91,"id":12482925}]}]}
{"op":"mcm","clk":"11793108099","pt":1723063141159,"mc":[{"id":"1.231499799","rc":[{"batb":[[0,1.82,10],[1,1.81,7.43],[2,1.74,17.32]],"ltp":1.87,"tv":381.91,"id":12482925}]}]}
{"op":"mcm","clk":"11793108257","pt":1723063144753,"mc":[{"id":"1.231499799","rc":[{"batb":[[0,1.81,7.43],[1,1.74,17.32],[2,1.53,94.34]],"ltp":1.87,"tv":381.91,"id":12482925}]}]}
{"op":"mcm","clk":"11793108359","pt":1723063147269,"mc":[{"id":"1.231499799","rc":[{"batb":[[0,1.82,10],[1,1.81,7.43],[2,1.74,17.32]],"ltp":1.87,"tv":381.91,"id":12482925}]}]}
{"op":"mcm","clk":"11793108513","pt":1723063150656,"mc":[{"id":"1.231499799","rc":[{"batb":[[0,1.81,7.43],[1,1.74,17.32],[2,1.53,94.34]],"ltp":1.87,"tv":381.91,"id":12482925}]}]}
{"op":"mcm","clk":"11793108625","pt":1723063153373,"mc":[{"id":"1.231499799","rc":[{"batb":[[0,1.82,10],[1,1.81,7.43],[2,1.74,17.32]],"ltp":1.87,"tv":381.91,"id":12482925}]}]}
{"op":"mcm","clk":"11793108749","pt":1723063156769,"mc":[{"id":"1.231499799","rc":[{"batb":[[0,1.81,7.43],[1,1.74,17.32],[2,1.53,94.34]],"ltp":1.87,"tv":381.91,"id":12482925}]}]}
{"op":"mcm","clk":"11793108846","pt":1723063159278,"mc":[{"id":"1.231499799","rc":[{"batb":[[0,1.82,10],[1,1.81,7.43],[2,1.74,17.32]],"ltp":1.87,"tv":381.91,"id":12482925}]}]}
{"op":"mcm","clk":"11793109002","pt":1723063162881,"mc":[{"id":"1.231499799","rc":[{"batb":[[0,1.81,7.43],[1,1.74,17.32],[2,1.53,94.34]],"ltp":1.87,"tv":381.91,"id":12482925}]}]}
{"op":"mcm","clk":"11793109123","pt":1723063166103,"mc":[{"id":"1.231499799","rc":[{"batb":[[0,1.82,10],[1,1.81,7.43],[2,1.74,17.32]],"ltp":1.87,"tv":381.91,"id":12482925}]}]}
{"op":"mcm","clk":"11793109233","pt":1723063169394,"mc":[{"id":"1.231499799","rc":[{"batb":[[0,1.81,7.43],[1,1.74,17.32],[2,1.53,94.34]],"ltp":1.87,"tv":381.91,"id":12482925}]}]}
{"op":"mcm","clk":"11793109341","pt":1723063172809,"mc":[{"id":"1.231499799","rc":[{"batb":[[0,1.82,10],[1,1.81,7.43],[2,1.74,17.32]],"ltp":1.87,"tv":381.91,"id":12482925}]}]}
{"op":"mcm","clk":"11793109488","pt":1723063176099,"mc":[{"id":"1.231499799","rc":[{"batb":[[0,1.81,7.43],[1,1.74,17.32],[2,1.53,94.34]],"ltp":1.87,"tv":381.91,"id":12482925}]}]}
{"op":"mcm","clk":"11793109591","pt":1723063178669,"mc":[{"id":"1.231499799","rc":[{"batb":[[0,1.82,10],[1,1.81,7.43],[2,1.74,17.32]],"ltp":1.87,"tv":381.91,"id":12482925}]}]}
{"op":"mcm","clk":"11793109709","pt":1723063182312,"mc":[{"id":"1.231499799","rc":[{"batb":[[0,1.81,7.43],[1,1.74,17.32],[2,1.53,94.34]],"ltp":1.87,"tv":381.91,"id":12482925}]}]}
{"op":"mcm","clk":"11793109799","pt":1723063185591,"mc":[{"id":"1.231499799","rc":[{"batb":[[0,1.82,10],[1,1.81,7.43],[2,1.74,17.32]],"ltp":1.87,"tv":381.91,"id":12482925}]}]}
{"op":"mcm","clk":"11793109892","pt":1723063188922,"mc":[{"id":"1.231499799","rc":[{"batb":[[0,1.81,7.43],[1,1.74,17.32],[2,1.53,94.34]],"ltp":1.87,"tv":381.91,"id":12482925}]}]}
{"op":"mcm","clk":"11793109988","pt":1723063191797,"mc":[{"id":"1.231499799","rc":[{"batb":[[0,1.82,10],[1,1.81,7.43],[2,1.74,17.32]],"ltp":1.87,"tv":381.91,"id":12482925}]}]}
{"op":"mcm","clk":"11793110127","pt":1723063195394,"mc":[{"id":"1.231499799","rc":[{"batb":[[0,1.81,7.43],[1,1.74,17.32],[2,1.53,94.34]],"ltp":1.87,"tv":381.91,"id":12482925}]}]}
{"op":"mcm","clk":"11793110237","pt":1723063198626,"mc":[{"id":"1.231499799","rc":[{"batb":[[0,1.82,10],[1,1.81,7.43],[2,1.74,17.32]],"ltp":1.87,"tv":381.91,"id":12482925}]}]}
{"op":"mcm","clk":"11793110361","pt":1723063202021,"mc":[{"id":"1.231499799","rc":[{"batb":[[0,1.81,7.43],[1,1.74,17.32],[2,1.53,94.34]],"ltp":1.87,"tv":381.91,"id":12482925}]}]}
{"op":"mcm","clk":"11793110467","pt":1723063204432,"mc":[{"id":"1.231499799","rc":[{"batb":[[0,1.82,10],[1,1.81,7.43],[2,1.74,17.32]],"ltp":1.87,"tv":381.91,"id":12482925}]}]}
{"op":"mcm","clk":"11793110587","pt":1723063207823,"mc":[{"id":"1.231499799","rc":[{"batb":[[0,1.81,7.43],[1,1.74,17.32],[2,1.53,94.34]],"ltp":1.87,"tv":381.91,"id":12482925}]}]}
{"op":"mcm","clk":"11793110821","pt":1723063213632,"mc":[{"id":"1.231499799","rc":[{"batb":[[0,1.82,10],[1,1.81,7.43],[2,1.74,17.32]],"ltp":1.87,"tv":381.91,"id":12482925}]}]}
{"op":"mcm","clk":"11793110957","pt":1723063216911,"mc":[{"id":"1.231499799","rc":[{"batb":[[0,1.81,7.43],[1,1.74,17.32],[2,1.53,94.34]],"ltp":1.87,"tv":381.91,"id":12482925}]}]}
{"op":"mcm","clk":"11793111038","pt":1723063219437,"mc":[{"id":"1.231499799","rc":[{"batb":[[0,1.82,10],[1,1.81,7.43],[2,1.74,17.32]],"ltp":1.87,"tv":381.91,"id":12482925}]}]}
{"op":"mcm","clk":"11793111169","pt":1723063222825,"mc":[{"id":"1.231499799","rc":[{"batb":[[0,1.81,7.43],[1,1.74,17.32],[2,1.53,94.34]],"ltp":1.87,"tv":381.91,"id":12482925}]}]}
{"op":"mcm","clk":"11793111240","pt":1723063225038,"mc":[{"id":"1.231499799","rc":[{"batb":[[0,1.82,10],[1,1.81,7.43],[2,1.74,17.32]],"ltp":1.87,"tv":381.91,"id":12482925}]}]}
{"op":"mcm","clk":"11793111363","pt":1723063228324,"mc":[{"id":"1.231499799","rc":[{"batb":[[0,1.81,7.43],[1,1.74,17.32],[2,1.53,94.34]],"ltp":1.87,"tv":381.91,"id":12482925}]}]}
{"op":"mcm","clk":"11793111484","pt":1723063231048,"mc":[{"id":"1.231499799","rc":[{"batb":[[0,1.82,10],[1,1.81,7.43],[2,1.74,17.32]],"ltp":1.87,"tv":381.91,"id":12482925}]}]}
{"op":"mcm","clk":"11793111624","pt":1723063234446,"mc":[{"id":"1.231499799","rc":[{"batb":[[0,1.81,7.43],[1,1.74,17.32],[2,1.53,94.34]],"ltp":1.87,"tv":381.91,"id":12482925}]}]}
{"op":"mcm","clk":"11793111800","pt":1723063238255,"mc":[{"id":"1.231499799","rc":[{"batb":[[0,1.82,10],[1,1.81,7.43],[2,1.74,17.32]],"ltp":1.87,"tv":381.91,"id":12482925}]}]}
{"op":"mcm","clk":"11793111940","pt":1723063241641,"mc":[{"id":"1.231499799","rc":[{"batb":[[0,1.81,7.43],[1,1.74,17.32],[2,1.53,94.34]],"ltp":1.87,"tv":381.91,"id":12482925}]}]}
{"op":"mcm","clk":"11793112095","pt":1723063244471,"mc":[{"id":"1.231499799","rc":[{"batb":[[0,1.82,10],[1,1.81,7.43],[2,1.74,17.32]],"ltp":1.87,"tv":381.91,"id":12482925}]}]}
{"op":"mcm","clk":"11793112241","pt":1723063247963,"mc":[{"id":"1.231499799","rc":[{"batb":[[0,1.81,7.43],[1,1.74,17.32],[2,1.53,94.34]],"ltp":1.87,"tv":381.91,"id":12482925}]}]}
{"op":"mcm","clk":"11793112363","pt":1723063250235,"mc":[{"id":"1.231499799","rc":[{"batb":[[0,1.82,10],[1,1.81,7.43],[2,1.74,17.32]],"ltp":1.87,"tv":381.91,"id":12482925}]}]}
{"op":"mcm","clk":"11793112515","pt":1723063253671,"mc":[{"id":"1.231499799","rc":[{"batb":[[0,1.81,7.43],[1,1.74,17.32],[2,1.53,94.34]],"ltp":1.87,"tv":381.91,"id":12482925}]}]}
{"op":"mcm","clk":"11793112588","pt":1723063256548,"mc":[{"id":"1.231499799","rc":[{"batb":[[0,1.82,10],[1,1.81,7.43],[2,1.74,17.32]],"ltp":1.87,"tv":381.91,"id":12482925}]}]}
{"op":"mcm","clk":"11793112737","pt":1723063259986,"mc":[{"id":"1.231499799","rc":[{"batb":[[0,1.81,7.43],[1,1.74,17.32],[2,1.53,94.34]],"ltp":1.87,"tv":381.91,"id":12482925}]}]}
{"op":"mcm","clk":"11793112847","pt":1723063262355,"mc":[{"id":"1.231499799","rc":[{"batb":[[0,1.82,10],[1,1.81,7.43],[2,1.74,17.32]],"ltp":1.87,"tv":381.91,"id":12482925}]}]}
{"op":"mcm","clk":"11793113018","pt":1723063265752,"mc":[{"id":"1.231499799","rc":[{"batb":[[0,1.81,7.43],[1,1.74,17.32],[2,1.53,94.34]],"ltp":1.87,"tv":381.91,"id":12482925}]}]}
{"op":"mcm","clk":"11793113194","pt":1723063269864,"mc":[{"id":"1.231499799","rc":[{"batb":[[0,1.82,10],[1,1.81,7.43],[2,1.74,17.32]],"ltp":1.87,"tv":381.91,"id":12482925}]}]}
{"op":"mcm","clk":"11793113367","pt":1723063273256,"mc":[{"id":"1.231499799","rc":[{"batb":[[0,1.81,7.43],[1,1.74,17.32],[2,1.53,94.34]],"ltp":1.87,"tv":381.91,"id":12482925}]}]}
{"op":"mcm","clk":"11793113438","pt":1723063275359,"mc":[{"id":"1.231499799","rc":[{"batb":[[0,1.82,10],[1,1.81,7.43],[2,1.74,17.32]],"ltp":1.87,"tv":381.91,"id":12482925}]}]}
{"op":"mcm","clk":"11793113570","pt":1723063278797,"mc":[{"id":"1.231499799","rc":[{"batb":[[0,1.81,7.43],[1,1.74,17.32],[2,1.53,94.34]],"ltp":1.87,"tv":381.91,"id":12482925}]}]}
{"op":"mcm","clk":"11793113695","pt":1723063281264,"mc":[{"id":"1.231499799","rc":[{"batb":[[0,1.82,10],[1,1.81,7.43],[2,1.74,17.32]],"ltp":1.87,"tv":381.91,"id":12482925}]}]}
{"op":"mcm","clk":"11793113827","pt":1723063284906,"mc":[{"id":"1.231499799","rc":[{"batb":[[0,1.81,7.43],[1,1.74,17.32],[2,1.53,94.34]],"ltp":1.87,"tv":381.91,"id":12482925}]}]}
{"op":"mcm","clk":"11793113917","pt":1723063287373,"mc":[{"id":"1.231499799","rc":[{"batb":[[0,1.82,10],[1,1.81,7.43],[2,1.74,17.32]],"ltp":1.87,"tv":381.91,"id":12482925}]}]}
{"op":"mcm","clk":"11793114044","pt":1723063290610,"mc":[{"id":"1.231499799","rc":[{"batb":[[0,1.81,7.43],[1,1.74,17.32],[2,1.53,94.34]],"ltp":1.87,"tv":381.91,"id":12482925}]}]}
{"op":"mcm","clk":"11793114155","pt":1723063293285,"mc":[{"id":"1.231499799","rc":[{"batb":[[0,1.82,10],[1,1.81,7.43],[2,1.74,17.32]],"ltp":1.87,"tv":381.91,"id":12482925}]}]}
{"op":"mcm","clk":"11793114303","pt":1723063296679,"mc":[{"id":"1.231499799","rc":[{"batb":[[0,1.81,7.43],[1,1.74,17.32],[2,1.53,94.34]],"ltp":1.87,"tv":381.91,"id":12482925}]}]}
{"op":"mcm","clk":"11793114503","pt":1723063302324,"mc":[{"id":"1.231499799","rc":[{"batb":[[0,1.82,10],[1,1.81,7.43],[2,1.74,17.32]],"ltp":1.87,"tv":381.91,"id":12482925}]}]}
{"op":"mcm","clk":"11793114639","pt":1723063305705,"mc":[{"id":"1.231499799","rc":[{"batb":[[0,1.81,7.43],[1,1.74,17.32],[2,1.53,94.34]],"ltp":1.87,"tv":381.91,"id":12482925}]}]}
{"op":"mcm","clk":"11793114727","pt":1723063308343,"mc":[{"id":"1.231499799","rc":[{"batb":[[0,1.82,10],[1,1.81,7.43],[2,1.74,17.32]],"ltp":1.87,"tv":381.91,"id":12482925}]}]}
{"op":"mcm","clk":"11793114869","pt":1723063311636,"mc":[{"id":"1.231499799","rc":[{"batb":[[0,1.81,7.43],[1,1.74,17.32],[2,1.53,94.34]],"ltp":1.87,"tv":381.91,"id":12482925}]}]}
{"op":"mcm","clk":"11793114976","pt":1723063313946,"mc":[{"id":"1.231499799","rc":[{"batb":[[0,1.82,10],[1,1.81,7.43],[2,1.74,17.32]],"ltp":1.87,"tv":381.91,"id":12482925}]}]}
{"op":"mcm","clk":"11793115113","pt":1723063317232,"mc":[{"id":"1.231499799","rc":[{"batb":[[0,1.81,7.43],[1,1.74,17.32],[2,1.53,94.34]],"ltp":1.87,"tv":381.91,"id":12482925}]}]}
{"op":"mcm","clk":"11793141854","pt":1723063882820,"mc":[{"id":"1.231499799","rc":[{"batb":[[0,2.04,6.51],[1,2.02,53.46]],"ltp":2.14,"tv":49.62,"id":25686043}]}]}
{"op":"mcm","clk":"11793141877","pt":1723063883283,"mc":[{"id":"1.231499799","rc":[{"batb":[[0,1.75,67.02],[2,1.54,7.43]],"ltp":1.87,"tv":381.91,"id":12482925}]}]}
{"op":"mcm","clk":"11793145655","pt":1723064006641,"mc":[{"id":"1.231499799","rc":[{"batb":[[0,1.74,17.32],[1,1.54,7.43],[2,1.53,94.34]],"ltp":1.87,"tv":381.91,"id":12482925}]}]}
{"op":"mcm","clk":"11793147859","pt":1723064030927,"mc":[{"id":"1.231499799","rc":[{"batb":[[0,1.77,66.26],[1,1.74,17.32],[2,1.54,7.43]],"ltp":1.87,"tv":381.91,"id":12482925}]}]}
{"op":"mcm","clk":"11793153757","pt":1723064153832,"mc":[{"id":"1.231499799","rc":[{"batl":[[0,1.98,4.58],[1,2.02,2],[2,2.3,1]],"ltp":1.87,"tv":381.91,"id":12482925}]}]}
{"op":"mcm","clk":"11793153784","pt":1723064154402,"mc":[{"id":"1.231499799","rc":[{"batl":[[0,2.02,2],[1,2.3,1],[2,2.3,0]],"ltp":1.87,"tv":381.91,"id":12482925}]}]}
{"op":"mcm","clk":"11793155846","pt":1723064209885,"mc":[{"id":"1.231499799","rc":[{"batl":[[0,1.98,4.58],[1,2.02,2],[2,2.3,1]],"ltp":1.87,"tv":381.91,"id":12482925}]}]}
{"op":"mcm","clk":"11793155899","pt":1723064212184,"mc":[{"id":"1.231499799","rc":[{"batl":[[0,2.02,2],[1,2.3,1],[2,2.3,0]],"ltp":1.87,"tv":381.91,"id":12482925}]}]}
{"op":"mcm","clk":"11793157861","pt":1723064267060,"mc":[{"id":"1.231499799","rc":[{"batl":[[0,1.98,4.58],[1,2.02,2],[2,2.3,1]],"ltp":1.87,"tv":381.91,"id":12482925}]}]}
{"op":"mcm","clk":"11793157929","pt":1723064269260,"mc":[{"id":"1.231499799","rc":[{"batl":[[0,2.02,2],[1,2.3,1],[2,2.3,0]],"ltp":1.87,"tv":381.91,"id":12482925}]}]}
{"op":"mcm","clk":"11793158042","pt":1723064273558,"mc":[{"id":"1.231499799","rc":[{"batb":[[0,2.04,11.01]],"ltp":2.14,"tv":49.62,"id":25686043}]}]}
{"op":"mcm","clk":"11793158115","pt":1723064275659,"mc":[{"id":"1.231499799","rc":[{"batb":[[0,2.04,6.51]],"ltp":2.14,"tv":49.62,"id":25686043}]}]}
{"op":"mcm","clk":"11793158944","pt":1723064302498,"mc":[{"id":"1.231499799","rc":[{"batb":[[0,1.78,4.98],[1,1.77,66.26],[2,1.74,17.32]],"ltp":1.87,"tv":381.91,"id":12482925}]}]}
{"op":"mcm","clk":"11793159664","pt":1723064326415,"mc":[{"id":"1.231499799","rc":[{"batb":[[0,1.79,65.52],[1,1.78,4.98]],"batl":[[0,1.98,4.58],[1,2.02,2],[2,2.3,1]],"ltp":1.87,"tv":381.91,"id":12482925}]}]}
{"op":"mcm","clk":"11793159721","pt":1723064328408,"mc":[{"id":"1.231499799","rc":[{"batb":[[1,1.74,17.32],[2,1.54,7.43]],"batl":[[0,2.02,2],[1,2.3,1],[2,2.3,0]],"ltp":1.87,"tv":381.91,"id":12482925}]}]}
{"op":"mcm","clk":"11793159817","pt":1723064331026,"mc":[{"id":"1.231499799","rc":[{"batb":[[0,2.04,11.01]],"ltp":2.14,"tv":49.62,"id":25686043}]}]}
{"op":"mcm","clk":"11793159898","pt":1723064333335,"mc":[{"id":"1.231499799","rc":[{"batb":[[0,2.04,6.51]],"ltp":2.14,"tv":49.62,"id":25686043}]}]}
{"op":"mcm","clk":"11793161329","pt":1723064383694,"mc":[{"id":"1.231499799","rc":[{"batl":[[0,1.98,4.58],[1,2.02,2],[2,2.3,1]],"ltp":1.87,"tv":381.91,"id":12482925}]}]}
{"op":"mcm","clk":"11793161368","pt":1723064384617,"mc":[{"id":"1.231499799","rc":[{"batl":[[0,2.02,2],[1,2.3,1],[2,2.3,0]],"ltp":1.87,"tv":381.91,"id":12482925}]}]}
{"op":"mcm","clk":"11793161483","pt":1723064389639,"mc":[{"id":"1.231499799","rc":[{"batb":[[0,2.04,11.01]],"ltp":2.14,"tv":49.62,"id":25686043}]}]}
{"op":"mcm","clk":"11793161544","pt":1723064391736,"mc":[{"id":"1.231499799","rc":[{"batb":[[0,2.04,6.51]],"ltp":2.14,"tv":49.62,"id":25686043}]}]}
{"op":"mcm","clk":"11793161802","pt":1723064400762,"mc":[{"id":"1.231499799","rc":[{"batb":[[0,1.8,10],[1,1.79,65.52],[2,1.74,17.32]],"ltp":1.87,"tv":381.91,"id":12482925}]}]}
{"op":"mcm","clk":"11793161980","pt":1723064404161,"mc":[{"id":"1.231499799","rc":[{"batb":[[0,2.04,6.51]],"ltp":2.14,"tv":49.62,"id":25686043},{"trd":[[1.87,149.84],[1.88,20],[1.91,104.99]],"batb":[[0,1.79,65.52],[1,1.74,17.32],[2,1.54,7.43]],"ltp":1.87,"tv":381.86,"id":12482925}],"tv":431.49}]}
{"op":"mcm","clk":"11793162096","pt":1723064407245,"mc":[{"id":"1.231499799","rc":[{"batb":[[0,1.8,10],[1,1.79,65.52],[2,1.74,17.32]],"ltp":1.87,"tv":381.86,"id":12482925}]}]}
{"op":"mcm","clk":"11793162224","pt":1723064410572,"mc":[{"id":"1.231499799","rc":[{"batb":[[0,1.79,65.52],[1,1.74,17.32],[2,1.54,7.43]],"ltp":1.87,"tv":381.86,"id":12482925}]}]}
{"op":"mcm","clk":"11793162342","pt":1723064414572,"mc":[{"id":"1.231499799","rc":[{"batb":[[0,1.8,10],[1,1.79,65.52],[2,1.74,17.32]],"ltp":1.87,"tv":381.86,"id":12482925}]}]}
{"op":"mcm","clk":"11793162447","pt":1723064417985,"mc":[{"id":"1.231499799","rc":[{"batb":[[0,1.79,65.52],[1,1.74,17.32],[2,1.54,7.43]],"ltp":1.87,"tv":381.86,"id":12482925}]}]}
{"op":"mcm","clk":"11793162575","pt":1723064421370,"mc":[{"id":"1.231499799","rc":[{"batb":[[0,1.8,10],[1,1.79,65.52],[2,1.74,17.32]],"ltp":1.87,"tv":381.86,"id":12482925}]}]}
{"op":"mcm","clk":"11793162680","pt":1723064424799,"mc":[{"id":"1.231499799","rc":[{"batb":[[0,1.79,65.52],[1,1.74,17.32],[2,1.54,7.43]],"ltp":1.87,"tv":381.86,"id":12482925}]}]}
{"op":"mcm","clk":"11793162750","pt":1723064427570,"mc":[{"id":"1.231499799","rc":[{"batb":[[0,1.8,10],[1,1.79,65.52],[2,1.74,17.32]],"ltp":1.87,"tv":381.86,"id":12482925}]}]}
{"op":"mcm","clk":"11793162870","pt":1723064431315,"mc":[{"id":"1.231499799","rc":[{"batb":[[0,1.79,65.52],[1,1.74,17.32],[2,1.54,7.43]],"ltp":1.87,"tv":381.86,"id":12482925}]}]}
{"op":"mcm","clk":"11793162988","pt":1723064434908,"mc":[{"id":"1.231499799","rc":[{"batb":[[0,2.04,11.01]],"ltp":2.14,"tv":49.62,"id":25686043},{"batb":[[0,1.8,10],[1,1.79,65.52],[2,1.74,17.32]],"batl":[[0,1.98,4.58],[1,2.02,2],[2,2.3,1]],"ltp":1.87,"tv":381.86,"id":12482925}]}]}
{"op":"mcm","clk":"11793163080","pt":1723064437572,"mc":[{"id":"1.231499799","rc":[{"batb":[[0,1.79,65.52],[1,1.74,17.32],[2,1.54,7.43]],"ltp":1.87,"tv":381.86,"id":12482925}]}]}
{"op":"mcm","clk":"11793169571","pt":1723064600191,"mc":[{"id":"1.231499799","rc":[{"batb":[[0,1.8,4.92],[1,1.79,65.52],[2,1.74,17.32]],"ltp":1.87,"tv":381.86,"id":12482925}]}]}
{"op":"mcm","clk":"11793170734","pt":1723064628953,"mc":[{"id":"1.231499799","rc":[{"batb":[[0,1.81,20.96],[1,1.8,4.92],[2,1.79,65.52]],"ltp":1.87,"tv":381.86,"id":12482925}]}]}
{"op":"mcm","clk":"11793170742","pt":1723064629158,"mc":[{"id":"1.231499799","rc":[{"batb":[[2,1.74,17.32]],"ltp":1.87,"tv":381.86,"id":12482925}]}]}
{"op":"mcm","clk":"11793170797","pt":1723064630749,"mc":[{"id":"1.231499799","rc":[{"batb":[[1,1.74,17.32],[2,1.54,7.43]],"ltp":1.87,"tv":381.86,"id":12482925}]}]}
{"op":"mcm","clk":"11793171428","pt":1723064646972,"mc":[{"id":"1.231499799","rc":[{"batb":[[2,1.67,29.34]],"ltp":1.87,"tv":381.86,"id":12482925}]}]}
{"op":"mcm","clk":"11793178939","pt":1723064867766,"mc":[{"id":"1.231499799","rc":[{"batl":[[0,1.96,30],[1,1.98,4.58],[2,2.02,2]],"ltp":1.87,"tv":381.86,"id":12482925}]}]}
{"op":"mcm","clk":"11793178946","pt":1723064868074,"mc":[{"id":"1.231499799","rc":[{"batl":[[1,2.02,2],[2,2.3,1]],"ltp":1.87,"tv":381.86,"id":12482925}]}]}
{"op":"mcm","clk":"11793193021","pt":1723065247426,"mc":[{"id":"1.231499799","rc":[{"batb":[[1,2.02,52.46]],"ltp":2.14,"tv":49.62,"id":25686043}]}]}
{"op":"mcm","clk":"11793193120","pt":1723065251112,"mc":[{"id":"1.231499799","rc":[{"batb":[[0,2.04,63.47],[1,1.98,45.31],[2,1.9,16.77]],"ltp":2.14,"tv":49.62,"id":25686043}]}]}
{"op":"mcm","clk":"11793199048","pt":1723065410942,"mc":[{"id":"1.231499799","rc":[{"batb":[[0,2.04,56.96]],"ltp":2.14,"tv":49.62,"id":25686043}]}]}
{"op":"mcm","clk":"11793199545","pt":1723065422131,"mc":[{"id":"1.231499799","rc":[{"batl":[[0,1.95,2],[1,1.96,30]],"ltp":1.87,"tv":381.86,"id":12482925}]}]}
{"op":"mcm","clk":"11793220045","pt":1723065973438,"mc":[{"id":"1.231499799","rc":[{"batb":[[0,2.06,4.3],[1,2.04,56.96],[2,1.98,45.31]],"ltp":2.14,"tv":49.62,"id":25686043}]}]}
{"op":"mcm","clk":"11793231330","pt":1723066275948,"mc":[{"id":"1.231499799","rc":[{"batl":[[0,2.22,14.64]],"ltp":2.14,"tv":49.62,"id":25686043}]}]}
{"op":"mcm","clk":"11793231347","pt":1723066276514,"mc":[{"id":"1.231499799","rc":[{"batb":[[0,2.08,10]],"ltp":2.14,"tv":49.62,"id":25686043}]}]}
{"op":"mcm","clk":"11793231468","pt":1723066279429,"mc":[{"id":"1.231499799","rc":[{"batb":[[0,2.04,56.96],[1,1.98,45.31],[2,1.9,16.77]],"ltp":2.14,"tv":49.62,"id":25686043}]}]}
{"op":"mcm","clk":"11793231614","pt":1723066282753,"mc":[{"id":"1.231499799","rc":[{"batb":[[0,2.06,10],[1,2.04,56.96],[2,1.98,45.31]],"ltp":2.14,"tv":49.62,"id":25686043}]}]}
{"op":"mcm","clk":"11793231759","pt":1723066286453,"mc":[{"id":"1.231499799","rc":[{"batb":[[0,2.06,4.3]],"ltp":2.14,"tv":49.62,"id":25686043}]}]}
{"op":"mcm","clk":"11793231862","pt":1723066288874,"mc":[{"id":"1.231499799","rc":[{"batb":[[0,2.08,10],[1,2.06,4.3],[2,2.04,56.96]],"ltp":2.14,"tv":49.62,"id":25686043}]}]}
{"op":"mcm","clk":"11793231929","pt":1723066290162,"mc":[{"id":"1.231499799","rc":[{"batb":[[1,2.04,56.96],[2,1.98,45.31]],"ltp":2.14,"tv":49.62,"id":25686043}]}]}
{"op":"mcm","clk":"11793232027","pt":1723066292268,"mc":[{"id":"1.231499799","rc":[{"batb":[[0,2.04,56.96],[1,1.98,45.31],[2,1.9,16.77]],"ltp":2.14,"tv":49.62,"id":25686043}]}]}
{"op":"mcm","clk":"11793232145","pt":1723066295047,"mc":[{"id":"1.231499799","rc":[{"batb":[[0,2.06,10],[1,2.04,56.96],[2,1.98,45.31]],"ltp":2.14,"tv":49.62,"id":25686043}]}]}
{"op":"mcm","clk":"11793232304","pt":1723066298680,"mc":[{"id":"1.231499799","rc":[{"batb":[[0,2.04,56.96],[1,1.98,45.31],[2,1.9,16.77]],"ltp":2.14,"tv":49.62,"id":25686043}]}]}
{"op":"mcm","clk":"11793232401","pt":1723066300838,"mc":[{"id":"1.231499799","rc":[{"batb":[[0,2.06,10],[1,2.04,56.96],[2,1.98,45.31]],"ltp":2.14,"tv":49.62,"id":25686043}]}]}
{"op":"mcm","clk":"11793232525","pt":1723066304177,"mc":[{"id":"1.231499799","rc":[{"batb":[[0,2.04,56.96],[1,1.98,45.31],[2,1.9,16.77]],"ltp":2.14,"tv":49.62,"id":25686043}]}]}
{"op":"mcm","clk":"11793232680","pt":1723066307466,"mc":[{"id":"1.231499799","rc":[{"batb":[[0,2.06,10],[1,2.04,56.96],[2,1.98,45.31]],"ltp":2.14,"tv":49.62,"id":25686043}]}]}
{"op":"mcm","clk":"11793232815","pt":1723066310858,"mc":[{"id":"1.231499799","rc":[{"batb":[[0,2.04,56.96],[1,1.98,45.31],[2,1.9,16.77]],"ltp":2.14,"tv":49.62,"id":25686043}]}]}
{"op":"mcm","clk":"11793232932","pt":1723066313978,"mc":[{"id":"1.231499799","rc":[{"batb":[[0,2.06,10],[1,2.04,56.96],[2,1.98,45.31]],"ltp":2.14,"tv":49.62,"id":25686043}]}]}
{"op":"mcm","clk":"11793233065","pt":1723066317309,"mc":[{"id":"1.231499799","rc":[{"batb":[[0,2.04,56.96],[1,1.98,45.31],[2,1.9,16.77]],"ltp":2.14,"tv":49.62,"id":25686043}]}]}
{"op":"mcm","clk":"11793233245","pt":1723066321785,"mc":[{"id":"1.231499799","rc":[{"batb":[[0,2.06,10],[1,2.04,56.96],[2,1.98,45.31]],"ltp":2.14,"tv":49.62,"id":25686043}]}]}
{"op":"mcm","clk":"11793233353","pt":1723066325415,"mc":[{"id":"1.231499799","rc":[{"batb":[[0,2.04,56.96],[1,1.98,45.31],[2,1.9,16.77]],"ltp":2.14,"tv":49.62,"id":25686043}]}]}
{"op":"mcm","clk":"11793233453","pt":1723066328394,"mc":[{"id":"1.231499799","rc":[{"batb":[[0,2.06,10],[1,2.04,56.96],[2,1.98,45.31]],"ltp":2.14,"tv":49.62,"id":25686043}]}]}
{"op":"mcm","clk":"11793233573","pt":1723066331981,"mc":[{"id":"1.231499799","rc":[{"batb":[[0,2.04,56.96],[1,1.98,45.31],[2,1.9,16.77]],"ltp":2.14,"tv":49.62,"id":25686043}]}]}
{"op":"mcm","clk":"11793233718","pt":1723066335213,"mc":[{"id":"1.231499799","rc":[{"batb":[[0,2.06,10],[1,2.04,56.96],[2,1.98,45.31]],"ltp":2.14,"tv":49.62,"id":25686043}]}]}
{"op":"mcm","clk":"11793233854","pt":1723066338601,"mc":[{"id":"1.231499799","rc":[{"batb":[[0,2.04,56.96],[1,1.98,45.31],[2,1.9,16.77]],"ltp":2.14,"tv":49.62,"id":25686043}]}]}
{"op":"mcm","clk":"11793233954","pt":1723066341886,"mc":[{"id":"1.231499799","rc":[{"batb":[[0,2.06,10],[1,2.04,56.96],[2,1.98,45.31]],"ltp":2.14,"tv":49.62,"id":25686043}]}]}
{"op":"mcm","clk":"11793234096","pt":1723066345382,"mc":[{"id":"1.231499799","rc":[{"batb":[[0,2.04,56.96],[1,1.98,45.31],[2,1.9,16.77]],"ltp":2.14,"tv":49.62,"id":25686043}]}]}
{"op":"mcm","clk":"11793234190","pt":1723066348096,"mc":[{"id":"1.231499799","rc":[{"batb":[[0,2.06,10],[1,2.04,56.96],[2,1.98,45.31]],"ltp":2.14,"tv":49.62,"id":25686043}]}]}
{"op":"mcm","clk":"11793234319","pt":1723066351429,"mc":[{"id":"1.231499799","rc":[{"batb":[[0,2.04,56.96],[1,1.98,45.31],[2,1.9,16.77]],"ltp":2.14,"tv":49.62,"id":25686043}]}]}
{"op":"mcm","clk":"11793234460","pt":1723066354614,"mc":[{"id":"1.231499799","rc":[{"batb":[[0,2.06,10],[1,2.04,56.96],[2,1.98,45.31]],"ltp":2.14,"tv":49.62,"id":25686043}]}]}
{"op":"mcm","clk":"11793234606","pt":1723066358049,"mc":[{"id":"1.231499799","rc":[{"batb":[[0,2.04,56.96],[1,1.98,45.31],[2,1.9,16.77]],"ltp":2.14,"tv":49.62,"id":25686043}]}]}
{"op":"mcm","clk":"11793234708","pt":1723066360817,"mc":[{"id":"1.231499799","rc":[{"batb":[[0,2.06,10],[1,2.04,56.96],[2,1.98,45.31]],"ltp":2.14,"tv":49.62,"id":25686043}]}]}
{"op":"mcm","clk":"11793234832","pt":1723066364108,"mc":[{"id":"1.231499799","rc":[{"batb":[[0,2.04,56.96],[1,1.98,45.31],[2,1.9,16.77]],"ltp":2.14,"tv":49.62,"id":25686043}]}]}
{"op":"mcm","clk":"11793234968","pt":1723066366926,"mc":[{"id":"1.231499799","rc":[{"batb":[[0,2.06,10],[1,2.04,56.96],[2,1.98,45.31]],"ltp":2.14,"tv":49.62,"id":25686043}]}]}
{"op":"mcm","clk":"11793235100","pt":1723066370414,"mc":[{"id":"1.231499799","rc":[{"batb":[[0,2.04,56.96],[1,1.98,45.31],[2,1.9,16.77]],"ltp":2.14,"tv":49.62,"id":25686043}]}]}
{"op":"mcm","clk":"11793235262","pt":1723066374661,"mc":[{"id":"1.231499799","rc":[{"batb":[[0,2.06,10],[1,2.04,56.96],[2,1.98,45.31]],"ltp":2.14,"tv":49.62,"id":25686043}]}]}
{"op":"mcm","clk":"11793235389","pt":1723066378254,"mc":[{"id":"1.231499799","rc":[{"batb":[[0,2.04,56.96],[1,1.98,45.31],[2,1.9,16.77]],"ltp":2.14,"tv":49.62,"id":25686043}]}]}
{"op":"mcm","clk":"11793235467","pt":1723066380353,"mc":[{"id":"1.231499799","rc":[{"batb":[[0,2.06,10],[1,2.04,56.96],[2,1.98,45.31]],"ltp":2.14,"tv":49.62,"id":25686043}]}]}
{"op":"mcm","clk":"11793235609","pt":1723066383641,"mc":[{"id":"1.231499799","rc":[{"batb":[[0,2.04,56.96],[1,1.98,45.31],[2,1.9,16.77]],"ltp":2.14,"tv":49.62,"id":25686043}]}]}
{"op":"mcm","clk":"11793235721","pt":1723066387034,"mc":[{"id":"1.231499799","rc":[{"batb":[[0,2.06,10],[1,2.04,56.96],[2,1.98,45.31]],"ltp":2.14,"tv":49.62,"id":25686043}]}]}
{"op":"mcm","clk":"11793235876","pt":1723066390470,"mc":[{"id":"1.231499799","rc":[{"batb":[[0,2.04,56.96],[1,1.98,45.31],[2,1.9,16.77]],"ltp":2.14,"tv":49.62,"id":25686043}]}]}
{"op":"mcm","clk":"11793235926","pt":1723066391958,"mc":[{"id":"1.231499799","rc":[{"batb":[[0,2.06,4.3],[1,2.04,56.96],[2,1.98,45.31]],"ltp":2.14,"tv":49.62,"id":25686043}]}]}
{"op":"mcm","clk":"11793235973","pt":1723066393146,"mc":[{"id":"1.231499799","rc":[{"batb":[[0,2.08,10],[1,2.06,4.3],[2,2.04,56.96]],"ltp":2.14,"tv":49.62,"id":25686043}]}]}
{"op":"mcm","clk":"11793236016","pt":1723066394366,"mc":[{"id":"1.231499799","rc":[{"batb":[[1,2.04,56.96],[2,1.98,45.31]],"ltp":2.14,"tv":49.62,"id":25686043}]}]}
{"op":"mcm","clk":"11793236101","pt":1723066396674,"mc":[{"id":"1.231499799","rc":[{"batb":[[0,2.04,56.96],[1,1.98,45.31],[2,1.9,16.77]],"ltp":2.14,"tv":49.62,"id":25686043}]}]}
{"op":"mcm","clk":"11793236206","pt":1723066399546,"mc":[{"id":"1.231499799","rc":[{"batb":[[0,2.06,10],[1,2.04,56.96],[2,1.98,45.31]],"ltp":2.14,"tv":49.62,"id":25686043}]}]}
{"op":"mcm","clk":"11793236353","pt":1723066403083,"mc":[{"id":"1.231499799","rc":[{"batb":[[0,2.04,56.96],[1,1.98,45.31],[2,1.9,16.77]],"ltp":2.14,"tv":49.62,"id":25686043}]}]}
{"op":"mcm","clk":"11793236464","pt":1723066405751,"mc":[{"id":"1.231499799","rc":[{"batb":[[0,2.06,10],[1,2.04,56.96],[2,1.98,45.31]],"ltp":2.14,"tv":49.62,"id":25686043}]}]}
{"op":"mcm","clk":"11793236609","pt":1723066409190,"mc":[{"id":"1.231499799","rc":[{"batb":[[0,2.04,56.96],[1,1.98,45.31],[2,1.9,16.77]],"ltp":2.14,"tv":49.62,"id":25686043}]}]}
{"op":"mcm","clk":"11793236714","pt":1723066411700,"mc":[{"id":"1.231499799","rc":[{"batb":[[0,2.06,10],[1,2.04,56.96],[2,1.98,45.31]],"ltp":2.14,"tv":49.62,"id":25686043}]}]}
{"op":"mcm","clk":"11793236856","pt":1723066415289,"mc":[{"id":"1.231499799","rc":[{"batb":[[0,2.04,56.96],[1,1.98,45.31],[2,1.9,16.77]],"ltp":2.14,"tv":49.62,"id":25686043}]}]}
{"op":"mcm","clk":"11793236973","pt":1723066418364,"mc":[{"id":"1.231499799","rc":[{"batb":[[0,2.06,10],[1,2.04,56.96],[2,1.98,45.31]],"ltp":2.14,"tv":49.62,"id":25686043}]}]}
{"op":"mcm","clk":"11793237086","pt":1723066421691,"mc":[{"id":"1.231499799","rc":[{"batb":[[0,2.04,56.96],[1,1.98,45.31],[2,1.9,16.77]],"ltp":2.14,"tv":49.62,"id":25686043}]}]}
{"op":"mcm","clk":"11793237214","pt":1723066424878,"mc":[{"id":"1.231499799","rc":[{"batb":[[0,2.06,10],[1,2.04,56.96],[2,1.98,45.31]],"ltp":2.14,"tv":49.62,"id":25686043}]}]}
{"op":"mcm","clk":"11793237356","pt":1723066428410,"mc":[{"id":"1.231499799","rc":[{"batb":[[0,2.04,56.96],[1,1.98,45.31],[2,1.9,16.77]],"ltp":2.14,"tv":49.62,"id":25686043}]}]}
{"op":"mcm","clk":"11793237450","pt":1723066430978,"mc":[{"id":"1.231499799","rc":[{"batb":[[0,2.06,10],[1,2.04,56.96],[2,1.98,45.31]],"ltp":2.14,"tv":49.62,"id":25686043}]}]}
{"op":"mcm","clk":"11793237628","pt":1723066435902,"mc":[{"id":"1.231499799","rc":[{"batb":[[0,2.04,56.96],[1,1.98,45.31],[2,1.9,16.77]],"ltp":2.14,"tv":49.62,"id":25686043}]}]}
{"op":"mcm","clk":"11793237713","pt":1723066438420,"mc":[{"id":"1.231499799","rc":[{"batb":[[0,2.06,10],[1,2.04,56.96],[2,1.98,45.31]],"ltp":2.14,"tv":49.62,"id":25686043}]}]}
{"op":"mcm","clk":"11793237879","pt":1723066442120,"mc":[{"id":"1.231499799","rc":[{"batb":[[0,2.04,56.96],[1,1.98,45.31],[2,1.9,16.77]],"ltp":2.14,"tv":49.62,"id":25686043}]}]}
{"op":"mcm","clk":"11793237955","pt":1723066444429,"mc":[{"id":"1.231499799","rc":[{"batb":[[0,2.06,10],[1,2.04,56.96],[2,1.98,45.31]],"ltp":2.14,"tv":49.62,"id":25686043}]}]}
{"op":"mcm","clk":"11793238087","pt":1723066447917,"mc":[{"id":"1.231499799","rc":[{"batb":[[0,2.04,56.96],[1,1.98,45.31],[2,1.9,16.77]],"ltp":2.14,"tv":49.62,"id":25686043}]}]}
{"op":"mcm","clk":"11793238203","pt":1723066450427,"mc":[{"id":"1.231499799","rc":[{"batb":[[0,2.06,10],[1,2.04,56.96],[2,1.98,45.31]],"ltp":2.14,"tv":49.62,"id":25686043}]}]}
{"op":"mcm","clk":"11793238311","pt":1723066453806,"mc":[{"id":"1.231499799","rc":[{"batb":[[0,2.04,56.96],[1,1.98,45.31],[2,1.9,16.77]],"ltp":2.14,"tv":49.62,"id":25686043}]}]}
{"op":"mcm","clk":"11793238465","pt":1723066457546,"mc":[{"id":"1.231499799","rc":[{"batb":[[0,2.06,10],[1,2.04,56.96],[2,1.98,45.31]],"ltp":2.14,"tv":49.62,"id":25686043}]}]}
{"op":"mcm","clk":"11793238664","pt":1723066462618,"mc":[{"id":"1.231499799","rc":[{"batb":[[0,2.04,56.96],[1,1.98,45.31],[2,1.9,16.77]],"ltp":2.14,"tv":49.62,"id":25686043}]}]}
{"op":"mcm","clk":"11793238775","pt":1723066465133,"mc":[{"id":"1.231499799","rc":[{"batb":[[0,2.06,10],[1,2.04,56.96],[2,1.98,45.31]],"ltp":2.14,"tv":49.62,"id":25686043}]}]}
{"op":"mcm","clk":"11793238904","pt":1723066468521,"mc":[{"id":"1.231499799","rc":[{"batb":[[0,2.04,56.96],[1,1.98,45.31],[2,1.9,16.77]],"ltp":2.14,"tv":49.62,"id":25686043}]}]}
{"op":"mcm","clk":"11793239018","pt":1723066471446,"mc":[{"id":"1.231499799","rc":[{"batb":[[0,2.06,10],[1,2.04,56.96],[2,1.98,45.31]],"ltp":2.14,"tv":49.62,"id":25686043}]}]}
{"op":"mcm","clk":"11793239118","pt":1723066474739,"mc":[{"id":"1.231499799","rc":[{"batb":[[0,2.04,56.96],[1,1.98,45.31],[2,1.9,16.77]],"ltp":2.14,"tv":49.62,"id":25686043}]}]}
{"op":"mcm","clk":"11793239206","pt":1723066477555,"mc":[{"id":"1.231499799","rc":[{"batb":[[0,2.06,10],[1,2.04,56.96],[2,1.98,45.31]],"ltp":2.14,"tv":49.62,"id":25686043}]}]}
{"op":"mcm","clk":"11793239343","pt":1723066481149,"mc":[{"id":"1.231499799","rc":[{"batb":[[0,2.04,56.96],[1,1.98,45.31],[2,1.9,16.77]],"ltp":2.14,"tv":49.62,"id":25686043}]}]}
{"op":"mcm","clk":"11793239472","pt":1723066484947,"mc":[{"id":"1.231499799","rc":[{"batb":[[0,2.06,10],[1,2.04,56.96],[2,1.98,45.31]],"ltp":2.14,"tv":49.62,"id":25686043}]}]}
{"op":"mcm","clk":"11793239601","pt":1723066488534,"mc":[{"id":"1.231499799","rc":[{"batb":[[0,2.04,56.96],[1,1.98,45.31],[2,1.9,16.77]],"ltp":2.14,"tv":49.62,"id":25686043}]}]}
{"op":"mcm","clk":"11793239684","pt":1723066490937,"mc":[{"id":"1.231499799","rc":[{"batb":[[0,2.06,10],[1,2.04,56.96],[2,1.98,45.31]],"ltp":2.14,"tv":49.62,"id":25686043}]}]}
{"op":"mcm","clk":"11793239803","pt":1723066494271,"mc":[{"id":"1.231499799","rc":[{"batb":[[0,2.04,56.96],[1,1.98,45.31],[2,1.9,16.77]],"ltp":2.14,"tv":49.62,"id":25686043}]}]}
{"op":"mcm","clk":"11793239892","pt":1723066497452,"mc":[{"id":"1.231499799","rc":[{"batb":[[0,2.06,10],[1,2.04,56.96],[2,1.98,45.31]],"ltp":2.14,"tv":49.62,"id":25686043}]}]}
{"op":"mcm","clk":"11793239933","pt":1723066498379,"mc":[{"id":"1.231499799","rc":[{"batb":[[0,2.06,14.3]],"ltp":2.14,"tv":49.62,"id":25686043}]}]}
{"op":"mcm","clk":"11793240038","pt":1723066500885,"mc":[{"id":"1.231499799","rc":[{"batb":[[0,2.06,4.3]],"ltp":2.14,"tv":49.62,"id":25686043}]}]}
{"op":"mcm","clk":"11793240168","pt":1723066504590,"mc":[{"id":"1.231499799","rc":[{"batb":[[0,2.08,10],[1,2.06,4.3],[2,2.04,56.96]],"ltp":2.14,"tv":49.62,"id":25686043}]}]}
{"op":"mcm","clk":"11793240185","pt":1723066505265,"mc":[{"id":"1.231499799","rc":[{"batb":[[1,2.04,56.96],[2,1.98,45.31]],"ltp":2.14,"tv":49.62,"id":25686043}]}]}
{"op":"mcm","clk":"11793240274","pt":1723066507880,"mc":[{"id":"1.231499799","rc":[{"batb":[[0,2.04,56.96],[1,1.98,45.31],[2,1.9,16.77]],"ltp":2.14,"tv":49.62,"id":25686043}]}]}
{"op":"mcm","clk":"11793240410","pt":1723066511370,"mc":[{"id":"1.231499799","rc":[{"batb":[[0,2.06,10],[1,2.04,56.96],[2,1.98,45.31]],"ltp":2.14,"tv":49.62,"id":25686043}]}]}
{"op":"mcm","clk":"11793240536","pt":1723066514704,"mc":[{"id":"1.231499799","rc":[{"batb":[[0,2.04,56.96],[1,1.98,45.31],[2,1.9,16.77]],"ltp":2.14,"tv":49.62,"id":25686043}]}]}
{"op":"mcm","clk":"11793240610","pt":1723066516500,"mc":[{"id":"1.231499799","rc":[{"batl":[[0,1.9,100],[1,1.95,2],[2,1.96,30]],"ltp":1.87,"tv":381.86,"id":12482925}]}]}
{"op":"mcm","clk":"11793240704","pt":1723066518764,"mc":[{"id":"1.231499799","rc":[{"batb":[[0,2.06,10],[1,2.04,52.46],[2,1.98,45.31]],"ltp":2.14,"tv":49.62,"id":25686043}]}]}
{"op":"mcm","clk":"11793240837","pt":1723066522071,"mc":[{"id":"1.231499799","rc":[{"batb":[[0,2.04,52.46],[1,1.98,45.31],[2,1.9,16.77]],"ltp":2.14,"tv":49.62,"id":25686043}]}]}
{"op":"mcm","clk":"11793240926","pt":1723066524685,"mc":[{"id":"1.231499799","rc":[{"batb":[[0,2.06,10],[1,2.04,52.46],[2,1.98,45.31]],"ltp":2.14,"tv":49.62,"id":25686043}]}]}
{"op":"mcm","clk":"11793241065","pt":1723066528019,"mc":[{"id":"1.231499799","rc":[{"batb":[[0,2.04,52.46],[1,1.98,45.31],[2,1.9,16.77]],"ltp":2.14,"tv":49.62,"id":25686043}]}]}
{"op":"mcm","clk":"11793241259","pt":1723066532794,"mc":[{"id":"1.231499799","rc":[{"batb":[[0,2.06,10],[1,2.04,52.46],[2,1.98,45.31]],"ltp":2.14,"tv":49.62,"id":25686043}]}]}
{"op":"mcm","clk":"11793241422","pt":1723066536596,"mc":[{"id":"1.231499799","rc":[{"batb":[[0,2.04,52.46],[1,1.98,45.31],[2,1.9,16.77]],"ltp":2.14,"tv":49.62,"id":25686043}]}]}
{"op":"mcm","clk":"11793241506","pt":1723066538795,"mc":[{"id":"1.231499799","rc":[{"batb":[[0,2.06,10],[1,2.04,52.46],[2,1.98,45.31]],"ltp":2.14,"tv":49.62,"id":25686043}]}]}
{"op":"mcm","clk":"11793241645","pt":1723066542235,"mc":[{"id":"1.231499799","rc":[{"batb":[[0,2.04,52.46],[1,1.98,45.31],[2,1.9,16.77]],"ltp":2.14,"tv":49.62,"id":25686043}]}]}
{"op":"mcm","clk":"11793241817","pt":1723066545728,"mc":[{"id":"1.231499799","rc":[{"batb":[[0,2.06,10],[1,2.04,52.46],[2,1.98,45.31]],"ltp":2.14,"tv":49.62,"id":25686043}]}]}
{"op":"mcm","clk":"11793241943","pt":1723066549123,"mc":[{"id":"1.231499799","rc":[{"batb":[[0,2.04,52.46],[1,1.98,45.31],[2,1.9,16.77]],"ltp":2.14,"tv":49.62,"id":25686043}]}]}
{"op":"mcm","clk":"11793242048","pt":1723066551942,"mc":[{"id":"1.231499799","rc":[{"batb":[[0,2.06,10],[1,2.04,52.46],[2,1.98,45.31]],"ltp":2.14,"tv":49.62,"id":25686043}]}]}
{"op":"mcm","clk":"11793242207","pt":1723066555534,"mc":[{"id":"1.231499799","rc":[{"batb":[[0,2.04,52.46],[1,1.98,45.31],[2,1.9,16.77]],"ltp":2.14,"tv":49.62,"id":25686043}]}]}
{"op":"mcm","clk":"11793242293","pt":1723066557950,"mc":[{"id":"1.231499799","rc":[{"batb":[[0,2.06,10],[1,2.04,52.46],[2,1.98,45.31]],"ltp":2.14,"tv":49.62,"id":25686043}]}]}
{"op":"mcm","clk":"11793242456","pt":1723066561439,"mc":[{"id":"1.231499799","rc":[{"batb":[[0,2.04,52.46],[1,1.98,45.31],[2,1.9,16.77]],"ltp":2.14,"tv":49.62,"id":25686043}]}]}
{"op":"mcm","clk":"11793242557","pt":1723066563749,"mc":[{"id":"1.231499799","rc":[{"batb":[[0,2.06,10],[1,2.04,52.46],[2,1.98,45.31]],"ltp":2.14,"tv":49.62,"id":25686043}]}]}
{"op":"mcm","clk":"11793242666","pt":1723066567027,"mc":[{"id":"1.231499799","rc":[{"batb":[[0,2.04,52.46],[1,1.98,45.31],[2,1.9,16.77]],"ltp":2.14,"tv":49.62,"id":25686043}]}]}
{"op":"mcm","clk":"11793242774","pt":1723066569848,"mc":[{"id":"1.231499799","rc":[{"batb":[[0,2.06,10],[1,2.04,52.46],[2,1.98,45.31]],"ltp":2.14,"tv":49.62,"id":25686043}]}]}
{"op":"mcm","clk":"11793242930","pt":1723066573239,"mc":[{"id":"1.231499799","rc":[{"batb":[[0,2.04,52.46],[1,1.98,45.31],[2,1.9,16.77]],"ltp":2.14,"tv":49.62,"id":25686043}]}]}
{"op":"mcm","clk":"11793243029","pt":1723066575600,"mc":[{"id":"1.231499799","rc":[{"batb":[[0,2.06,10],[1,2.04,52.46],[2,1.98,45.31]],"ltp":2.14,"tv":49.62,"id":25686043}]}]}
{"op":"mcm","clk":"11793243162","pt":1723066579135,"mc":[{"id":"1.231499799","rc":[{"batb":[[0,2.04,52.46],[1,1.98,45.31],[2,1.9,16.77]],"ltp":2.14,"tv":49.62,"id":25686043}]}]}
{"op":"mcm","clk":"11793243251","pt":1723066581439,"mc":[{"id":"1.231499799","rc":[{"batb":[[0,2.06,10],[1,2.04,52.46],[2,1.98,45.31]],"ltp":2.14,"tv":49.62,"id":25686043}]}]}
{"op":"mcm","clk":"11793243393","pt":1723066584743,"mc":[{"id":"1.231499799","rc":[{"batb":[[0,2.04,52.46],[1,1.98,45.31],[2,1.9,16.77]],"ltp":2.14,"tv":49.62,"id":25686043}]}]}
{"op":"mcm","clk":"11793243579","pt":1723066590059,"mc":[{"id":"1.231499799","rc":[{"batb":[[0,2.06,10],[1,2.04,52.46],[2,1.98,45.31]],"ltp":2.14,"tv":49.62,"id":25686043}]}]}
{"op":"mcm","clk":"11793243739","pt":1723066593439,"mc":[{"id":"1.231499799","rc":[{"batb":[[0,2.04,52.46],[1,1.98,45.31],[2,1.9,16.77]],"ltp":2.14,"tv":49.62,"id":25686043}]}]}
{"op":"mcm","clk":"11793243857","pt":1723066596267,"mc":[{"id":"1.231499799","rc":[{"batb":[[0,2.06,10],[1,2.04,52.46],[2,1.98,45.31]],"ltp":2.14,"tv":49.62,"id":25686043}]}]}
{"op":"mcm","clk":"11793243998","pt":1723066599663,"mc":[{"id":"1.231499799","rc":[{"batb":[[0,2.04,52.46],[1,1.98,45.31],[2,1.9,16.77]],"ltp":2.14,"tv":49.62,"id":25686043}]}]}
{"op":"mcm","clk":"11793244133","pt":1723066602796,"mc":[{"id":"1.231499799","rc":[{"batb":[[0,2.06,10],[1,2.04,52.46],[2,1.98,45.31]],"ltp":2.14,"tv":49.62,"id":25686043}]}]}
{"op":"mcm","clk":"11793244267","pt":1723066606185,"mc":[{"id":"1.231499799","rc":[{"batb":[[0,2.04,52.46],[1,1.98,45.31],[2,1.9,16.77]],"ltp":2.14,"tv":49.62,"id":25686043}]}]}
{"op":"mcm","clk":"11793244370","pt":1723066609065,"mc":[{"id":"1.231499799","rc":[{"batb":[[0,2.06,10],[1,2.04,52.46],[2,1.98,45.31]],"ltp":2.14,"tv":49.62,"id":25686043}]}]}
{"op":"mcm","clk":"11793244490","pt":1723066612388,"mc":[{"id":"1.231499799","rc":[{"batb":[[0,2.04,52.46],[1,1.98,45.31],[2,1.9,16.77]],"ltp":2.14,"tv":49.62,"id":25686043}]}]}
{"op":"mcm","clk":"11793244602","pt":1723066615570,"mc":[{"id":"1.231499799","rc":[{"batb":[[0,2.06,10],[1,2.04,52.46],[2,1.98,45.31]],"ltp":2.14,"tv":49.62,"id":25686043}]}]}
{"op":"mcm","clk":"11793244740","pt":1723066618960,"mc":[{"id":"1.231499799","rc":[{"batb":[[0,2.04,52.46],[1,1.98,45.31],[2,1.9,16.77]],"ltp":2.14,"tv":49.62,"id":25686043}]}]}
{"op":"mcm","clk":"11793244876","pt":1723066622295,"mc":[{"id":"1.231499799","rc":[{"batb":[[0,2.06,10],[1,2.04,52.46],[2,1.98,45.31]],"ltp":2.14,"tv":49.62,"id":25686043}]}]}
{"op":"mcm","clk":"11793245015","pt":1723066625685,"mc":[{"id":"1.231499799","rc":[{"batb":[[0,2.04,52.46],[1,1.98,45.31],[2,1.9,16.77]],"ltp":2.14,"tv":49.62,"id":25686043}]}]}
{"op":"mcm","clk":"11793245125","pt":1723066628605,"mc":[{"id":"1.231499799","rc":[{"batb":[[0,2.06,10],[1,2.04,52.46],[2,1.98,45.31]],"ltp":2.14,"tv":49.62,"id":25686043}]}]}
{"op":"mcm","clk":"11793245273","pt":1723066632093,"mc":[{"id":"1.231499799","rc":[{"batb":[[0,2.04,52.46],[1,1.98,45.31],[2,1.9,16.77]],"ltp":2.14,"tv":49.62,"id":25686043}]}]}
{"op":"mcm","clk":"11793245348","pt":1723066634503,"mc":[{"id":"1.231499799","rc":[{"batb":[[0,2.06,10],[1,2.04,52.46],[2,1.98,45.31]],"ltp":2.14,"tv":49.62,"id":25686043}]}]}
{"op":"mcm","clk":"11793245462","pt":1723066637989,"mc":[{"id":"1.231499799","rc":[{"batb":[[0,2.04,52.46],[1,1.98,45.31],[2,1.9,16.77]],"ltp":2.14,"tv":49.62,"id":25686043}]}]}
{"op":"mcm","clk":"11793245591","pt":1723066642602,"mc":[{"id":"1.231499799","rc":[{"batb":[[0,2.06,10],[1,2.04,52.46],[2,1.98,45.31]],"ltp":2.14,"tv":49.62,"id":25686043}]}]}
{"op":"mcm","clk":"11793245734","pt":1723066646210,"mc":[{"id":"1.231499799","rc":[{"batb":[[0,2.04,52.46],[1,1.98,45.31],[2,1.9,16.77]],"ltp":2.14,"tv":49.62,"id":25686043}]}]}
{"op":"mcm","clk":"11793245845","pt":1723066648715,"mc":[{"id":"1.231499799","rc":[{"batb":[[0,2.06,10],[1,2.04,52.46],[2,1.98,45.31]],"ltp":2.14,"tv":49.62,"id":25686043}]}]}
{"op":"mcm","clk":"11793245978","pt":1723066652005,"mc":[{"id":"1.231499799","rc":[{"batb":[[0,2.04,52.46],[1,1.98,45.31],[2,1.9,16.77]],"ltp":2.14,"tv":49.62,"id":25686043}]}]}
{"op":"mcm","clk":"11793246076","pt":1723066654623,"mc":[{"id":"1.231499799","rc":[{"batb":[[0,2.06,10],[1,2.04,52.46],[2,1.98,45.31]],"ltp":2.14,"tv":49.62,"id":25686043}]}]}
{"op":"mcm","clk":"11793246187","pt":1723066658209,"mc":[{"id":"1.231499799","rc":[{"batb":[[0,2.04,52.46],[1,1.98,45.31],[2,1.9,16.77]],"ltp":2.14,"tv":49.62,"id":25686043}]}]}
{"op":"mcm","clk":"11793246270","pt":1723066660617,"mc":[{"id":"1.231499799","rc":[{"batb":[[0,2.06,10],[1,2.04,52.46],[2,1.98,45.31]],"ltp":2.14,"tv":49.62,"id":25686043}]}]}
{"op":"mcm","clk":"11793246399","pt":1723066664102,"mc":[{"id":"1.231499799","rc":[{"batb":[[0,2.04,52.46],[1,1.98,45.31],[2,1.9,16.77]],"ltp":2.14,"tv":49.62,"id":25686043}]}]}
{"op":"mcm","clk":"11793246515","pt":1723066667591,"mc":[{"id":"1.231499799","rc":[{"batb":[[0,2.06,10],[1,2.04,52.46],[2,1.98,45.31]],"ltp":2.14,"tv":49.62,"id":25686043}]}]}
{"op":"mcm","clk":"11793246608","pt":1723066670919,"mc":[{"id":"1.231499799","rc":[{"batb":[[0,2.04,52.46],[1,1.98,45.31],[2,1.9,16.77]],"ltp":2.14,"tv":49.62,"id":25686043}]}]}
{"op":"mcm","clk":"11793246728","pt":1723066673996,"mc":[{"id":"1.231499799","rc":[{"batb":[[0,2.06,10],[1,2.04,52.46],[2,1.98,45.31]],"ltp":2.14,"tv":49.62,"id":25686043}]}]}
{"op":"mcm","clk":"11793246865","pt":1723066677792,"mc":[{"id":"1.231499799","rc":[{"batb":[[0,2.04,52.46],[1,1.98,45.31],[2,1.9,16.77]],"ltp":2.14,"tv":49.62,"id":25686043}]}]}
{"op":"mcm","clk":"11793246944","pt":1723066680213,"mc":[{"id":"1.231499799","rc":[{"batb":[[0,2.06,10],[1,2.04,52.46],[2,1.98,45.31]],"ltp":2.14,"tv":49.62,"id":25686043}]}]}
{"op":"mcm","clk":"11793247097","pt":1723066683506,"mc":[{"id":"1.231499799","rc":[{"batb":[[0,2.04,52.46],[1,1.98,45.31],[2,1.9,16.77]],"ltp":2.14,"tv":49.62,"id":25686043}]}]}
{"op":"mcm","clk":"11793247229","pt":1723066686736,"mc":[{"id":"1.231499799","rc":[{"batb":[[0,2.06,10],[1,2.04,52.46],[2,1.98,45.31]],"ltp":2.14,"tv":49.62,"id":25686043}]}]}
{"op":"mcm","clk":"11793247409","pt":1723066690432,"mc":[{"id":"1.231499799","rc":[{"batb":[[0,2.04,52.46],[1,1.98,45.31],[2,1.9,16.77]],"ltp":2.14,"tv":49.62,"id":25686043}]}]}
{"op":"mcm","clk":"11793247538","pt":1723066693414,"mc":[{"id":"1.231499799","rc":[{"batb":[[0,2.06,10],[1,2.04,52.46],[2,1.98,45.31]],"ltp":2.14,"tv":49.62,"id":25686043}]}]}
{"op":"mcm","clk":"11793247690","pt":1723066696754,"mc":[{"id":"1.231499799","rc":[{"batb":[[0,2.04,52.46],[1,1.98,45.31],[2,1.9,16.77]],"ltp":2.14,"tv":49.62,"id":25686043}]}]}
{"op":"mcm","clk":"11793247776","pt":1723066699319,"mc":[{"id":"1.231499799","rc":[{"batb":[[0,2.06,10],[1,2.04,52.46],[2,1.98,45.31]],"ltp":2.14,"tv":49.62,"id":25686043}]}]}
{"op":"mcm","clk":"11793247922","pt":1723066702956,"mc":[{"id":"1.231499799","rc":[{"batb":[[0,2.04,52.46],[1,1.98,45.31],[2,1.9,16.77]],"ltp":2.14,"tv":49.62,"id":25686043}]}]}
{"op":"mcm","clk":"11793248048","pt":1723066705623,"mc":[{"id":"1.231499799","rc":[{"batb":[[0,2.06,10],[1,2.04,52.46],[2,1.98,45.31]],"ltp":2.14,"tv":49.62,"id":25686043}]}]}
{"op":"mcm","clk":"11793248193","pt":1723066709155,"mc":[{"id":"1.231499799","rc":[{"batb":[[0,2.04,52.46],[1,1.98,45.31],[2,1.9,16.77]],"ltp":2.14,"tv":49.62,"id":25686043}]}]}
{"op":"mcm","clk":"11793248375","pt":1723066712751,"mc":[{"id":"1.231499799","rc":[{"batb":[[0,2.06,10],[1,2.04,52.46],[2,1.98,45.31]],"ltp":2.14,"tv":49.62,"id":25686043}]}]}
{"op":"mcm","clk":"11793248518","pt":1723066716083,"mc":[{"id":"1.231499799","rc":[{"batb":[[0,2.04,52.46],[1,1.98,45.31],[2,1.9,16.77]],"ltp":2.14,"tv":49.62,"id":25686043}]}]}
{"op":"mcm","clk":"11793248677","pt":1723066719369,"mc":[{"id":"1.231499799","rc":[{"batb":[[0,2.06,10],[1,2.04,52.46],[2,1.98,45.31]],"ltp":2.14,"tv":49.62,"id":25686043}]}]}
{"op":"mcm","clk":"11793248842","pt":1723066722661,"mc":[{"id":"1.231499799","rc":[{"batb":[[0,2.04,52.46],[1,1.98,45.31],[2,1.9,16.77]],"ltp":2.14,"tv":49.62,"id":25686043}]}]}
{"op":"mcm","clk":"11793248982","pt":1723066725795,"mc":[{"id":"1.231499799","rc":[{"batb":[[0,2.06,10],[1,2.04,52.46],[2,1.98,45.31]],"ltp":2.14,"tv":49.62,"id":25686043}]}]}
{"op":"mcm","clk":"11793249152","pt":1723066729093,"mc":[{"id":"1.231499799","rc":[{"batb":[[0,2.04,52.46],[1,1.98,45.31],[2,1.9,16.77]],"ltp":2.14,"tv":49.62,"id":25686043}]}]}
{"op":"mcm","clk":"11793249275","pt":1723066731665,"mc":[{"id":"1.231499799","rc":[{"batb":[[0,2.06,10],[1,2.04,52.46],[2,1.98,45.31]],"ltp":2.14,"tv":49.62,"id":25686043}]}]}
{"op":"mcm","clk":"11793249437","pt":1723066735203,"mc":[{"id":"1.231499799","rc":[{"batb":[[0,2.04,52.46],[1,1.98,45.31],[2,1.9,16.77]],"ltp":2.14,"tv":49.62,"id":25686043}]}]}
{"op":"mcm","clk":"11793249565","pt":1723066738895,"mc":[{"id":"1.231499799","rc":[{"batb":[[0,2.06,10],[1,2.04,52.46],[2,1.98,45.31]],"ltp":2.14,"tv":49.62,"id":25686043}]}]}
{"op":"mcm","clk":"11793249711","pt":1723066742191,"mc":[{"id":"1.231499799","rc":[{"batb":[[0,2.04,52.46],[1,1.98,45.31],[2,1.9,16.77]],"ltp":2.14,"tv":49.62,"id":25686043}]}]}
{"op":"mcm","clk":"11793249851","pt":1723066745681,"mc":[{"id":"1.231499799","rc":[{"batb":[[0,2.06,10],[1,2.04,52.46],[2,1.98,45.31]],"ltp":2.14,"tv":49.62,"id":25686043}]}]}
{"op":"mcm","clk":"11793250007","pt":1723066749328,"mc":[{"id":"1.231499799","rc":[{"batb":[[0,2.04,52.46],[1,1.98,45.31],[2,1.9,16.77]],"ltp":2.14,"tv":49.62,"id":25686043}]}]}
{"op":"mcm","clk":"11793250113","pt":1723066751590,"mc":[{"id":"1.231499799","rc":[{"batb":[[0,2.06,10],[1,2.04,52.46],[2,1.98,45.31]],"ltp":2.14,"tv":49.62,"id":25686043}]}]}
{"op":"mcm","clk":"11793250240","pt":1723066755122,"mc":[{"id":"1.231499799","rc":[{"batb":[[0,2.04,52.46],[1,1.98,45.31],[2,1.9,16.77]],"ltp":2.14,"tv":49.62,"id":25686043}]}]}
{"op":"mcm","clk":"11793250364","pt":1723066757702,"mc":[{"id":"1.231499799","rc":[{"batb":[[0,2.06,10],[1,2.04,52.46],[2,1.98,45.31]],"ltp":2.14,"tv":49.62,"id":25686043}]}]}
{"op":"mcm","clk":"11793250493","pt":1723066761033,"mc":[{"id":"1.231499799","rc":[{"batb":[[0,2.04,52.46],[1,1.98,45.31],[2,1.9,16.77]],"ltp":2.14,"tv":49.62,"id":25686043}]}]}
{"op":"mcm","clk":"11793250619","pt":1723066764421,"mc":[{"id":"1.231499799","rc":[{"batb":[[0,2.06,10],[1,2.04,52.46],[2,1.98,45.31]],"ltp":2.14,"tv":49.62,"id":25686043}]}]}
{"op":"mcm","clk":"11793250741","pt":1723066767853,"mc":[{"id":"1.231499799","rc":[{"batb":[[0,2.04,52.46],[1,1.98,45.31],[2,1.9,16.77]],"ltp":2.14,"tv":49.62,"id":25686043}]}]}
{"op":"mcm","clk":"11793250868","pt":1723066770734,"mc":[{"id":"1.231499799","rc":[{"batb":[[0,2.06,10],[1,2.04,52.46],[2,1.98,45.31]],"ltp":2.14,"tv":49.62,"id":25686043}]}]}
{"op":"mcm","clk":"11793250993","pt":1723066774124,"mc":[{"id":"1.231499799","rc":[{"batb":[[0,2.04,52.46],[1,1.98,45.31],[2,1.9,16.77]],"ltp":2.14,"tv":49.62,"id":25686043}]}]}
{"op":"mcm","clk":"11793251082","pt":1723066776433,"mc":[{"id":"1.231499799","rc":[{"batb":[[0,2.06,10],[1,2.04,52.46],[2,1.98,45.31]],"ltp":2.14,"tv":49.62,"id":25686043}]}]}
{"op":"mcm","clk":"11793251232","pt":1723066779825,"mc":[{"id":"1.231499799","rc":[{"batb":[[0,2.04,52.46],[1,1.98,45.31],[2,1.9,16.77]],"ltp":2.14,"tv":49.62,"id":25686043}]}]}
{"op":"mcm","clk":"11793251360","pt":1723066782855,"mc":[{"id":"1.231499799","rc":[{"batb":[[0,2.06,10],[1,2.04,52.46],[2,1.98,45.31]],"ltp":2.14,"tv":49.62,"id":25686043}]}]}
{"op":"mcm","clk":"11793251491","pt":1723066786141,"mc":[{"id":"1.231499799","rc":[{"batb":[[0,2.04,52.46],[1,1.98,45.31],[2,1.9,16.77]],"ltp":2.14,"tv":49.62,"id":25686043}]}]}
{"op":"mcm","clk":"11793251631","pt":1723066789167,"mc":[{"id":"1.231499799","rc":[{"batb":[[0,2.06,10],[1,2.04,52.46],[2,1.98,45.31]],"ltp":2.14,"tv":49.62,"id":25686043},{"batl":[[0,1.89,7.51],[1,1.9,100],[2,1.95,2]],"ltp":1.87,"tv":381.86,"id":12482925}]}]}
{"op":"mcm","clk":"11793251799","pt":1723066792661,"mc":[{"id":"1.231499799","rc":[{"batb":[[0,2.04,52.46],[1,1.98,45.31],[2,1.9,16.77]],"ltp":2.14,"tv":49.62,"id":25686043}]}]}
{"op":"mcm","clk":"11793251919","pt":1723066795839,"mc":[{"id":"1.231499799","rc":[{"batb":[[0,2.06,10],[1,2.04,52.46],[2,1.98,45.31]],"ltp":2.14,"tv":49.62,"id":25686043}]}]}
{"op":"mcm","clk":"11793252054","pt":1723066799279,"mc":[{"id":"1.231499799","rc":[{"batb":[[0,2.04,52.46],[1,1.98,45.31],[2,1.9,16.77]],"ltp":2.14,"tv":49.62,"id":25686043}]}]}
{"op":"mcm","clk":"11793256481","pt":1723066909696,"mc":[{"id":"1.231499799","rc":[{"batb":[[0,2.12,7.3],[1,2.04,52.46],[2,1.98,45.31]],"ltp":2.14,"tv":49.62,"id":25686043}]}]}
{"op":"mcm","clk":"11793269878","pt":1723067244960,"mc":[{"id":"1.231499799","rc":[{"batl":[[0,1.89,13.19]],"ltp":1.87,"tv":381.86,"id":12482925}]}]}
{"op":"mcm","clk":"11793280266","pt":1723067493441,"mc":[{"id":"1.231499799","rc":[{"trd":[[2.12,1.03]],"batb":[[0,2.12,6.78]],"ltp":2.12,"tv":50.65,"id":25686043}],"tv":432.52}]}
{"op":"mcm","clk":"11793300753","pt":1723068000899,"mc":[{"id":"1.231499799","rc":[{"batb":[[0,2.14,10],[1,2.12,6.78],[2,2.04,52.46]],"ltp":2.12,"tv":50.65,"id":25686043}]}]}
{"op":"mcm","clk":"11793301059","pt":1723068006822,"mc":[{"id":"1.231499799","rc":[{"batb":[[0,2.12,6.78],[1,2.04,52.46],[2,1.98,45.31]],"batl":[[0,2.22,14.64]],"ltp":2.12,"tv":50.65,"id":25686043},{"trd":[[1.87,149.83],[1.88,20],[1.91,104.98]],"batb":[[0,1.81,20.96],[2,1.67,29.34]],"batl":[[0,1.89,13.19]],"ltp":1.87,"tv":381.84,"id":12482925}],"tv":432.49}]}
{"op":"mcm","clk":"11793301190","pt":1723068009530,"mc":[{"id":"1.231499799","rc":[{"batb":[[0,2.14,10],[1,2.12,6.78],[2,2.04,52.46]],"ltp":2.12,"tv":50.65,"id":25686043}]}]}
{"op":"mcm","clk":"11793301374","pt":1723068012936,"mc":[{"id":"1.231499799","rc":[{"batb":[[0,2.12,6.78],[1,2.04,52.46],[2,1.98,45.31]],"ltp":2.12,"tv":50.65,"id":25686043}]}]}
{"op":"mcm","clk":"11793301566","pt":1723068016745,"mc":[{"id":"1.231499799","rc":[{"batb":[[0,2.14,10],[1,2.12,6.78],[2,2.04,52.46]],"ltp":2.12,"tv":50.65,"id":25686043}]}]}
{"op":"mcm","clk":"11793301775","pt":1723068020964,"mc":[{"id":"1.231499799","rc":[{"batb":[[0,2.12,6.78],[1,2.04,52.46],[2,1.98,45.31]],"ltp":2.12,"tv":50.65,"id":25686043}]}]}
{"op":"mcm","clk":"11793301903","pt":1723068023944,"mc":[{"id":"1.231499799","rc":[{"batb":[[0,2.14,10],[1,2.12,6.78],[2,2.04,52.46]],"ltp":2.12,"tv":50.65,"id":25686043}]}]}
{"op":"mcm","clk":"11793302085","pt":1723068027138,"mc":[{"id":"1.231499799","rc":[{"batb":[[0,2.12,6.78],[1,2.04,52.46],[2,1.98,45.31]],"ltp":2.12,"tv":50.65,"id":25686043}]}]}
{"op":"mcm","clk":"11793302237","pt":1723068029967,"mc":[{"id":"1.231499799","rc":[{"batb":[[0,2.14,10],[1,2.12,6.78],[2,2.04,52.46]],"ltp":2.12,"tv":50.65,"id":25686043}]}]}
{"op":"mcm","clk":"11793302409","pt":1723068033172,"mc":[{"id":"1.231499799","rc":[{"batb":[[0,2.12,6.78],[1,2.04,52.46],[2,1.98,45.31]],"ltp":2.12,"tv":50.65,"id":25686043}]}]}
{"op":"mcm","clk":"11793302611","pt":1723068036537,"mc":[{"id":"1.231499799","rc":[{"batb":[[0,2.14,10],[1,2.12,6.78],[2,2.04,52.46]],"ltp":2.12,"tv":50.65,"id":25686043}]}]}
{"op":"mcm","clk":"11793302817","pt":1723068040061,"mc":[{"id":"1.231499799","rc":[{"batb":[[0,2.12,6.78],[1,2.04,52.46],[2,1.98,45.31]],"ltp":2.12,"tv":50.65,"id":25686043}]}]}
{"op":"mcm","clk":"11793303149","pt":1723068046069,"mc":[{"id":"1.231499799","rc":[{"batb":[[0,2.14,10],[1,2.12,6.78],[2,2.04,52.46]],"ltp":2.12,"tv":50.65,"id":25686043}]}]}
{"op":"mcm","clk":"11793303330","pt":1723068049516,"mc":[{"id":"1.231499799","rc":[{"batb":[[0,2.12,6.78],[1,2.04,52.46],[2,1.98,45.31]],"ltp":2.12,"tv":50.65,"id":25686043}]}]}
