{"op":"mcm","clk":"11801082579","pt":1722671540162,"mc":[{"id":"1.231395388","marketDefinition":{"bspMarket":false,"turnInPlayEnabled":true,"persistenceEnabled":true,"marketBaseRate":5.0,"eventId":"33464867","eventTypeId":"4","numberOfWinners":1,"bettingType":"ODDS","marketType":"MATCH_ODDS","marketTime":"2024-08-04T15:00:00.000Z","suspendTime":"2024-08-04T15:00:00.000Z","bspReconciled":false,"complete":true,"inPlay":false,"crossMatching":true,"runnersVoidable":false,"numberOfActiveRunners":2,"betDelay":0,"status":"OPEN","runners":[{"status":"ACTIVE","sortPriority":1,"id":25173012,"name":"Brampton Wolves"},{"status":"ACTIVE","sortPriority":2,"id":58385184,"name":"Surrey Jaguars"}],"regulators":["MR_INT"],"countryCode":"GB","discountAllowed":false,"timezone":"GMT","openDate":"2024-08-04T15:00:00.000Z","version":6052780293,"name":"Match Odds","eventName":"Brampton Wolves v Surrey Jaguars"},"rc":[{"batb":[[0,1.03,200],[1,1.02,200],[2,1.01,220]],"ltp":0.0,"tv":0.0,"id":58385184},{"batb":[[0,1.03,200],[1,1.02,200],[2,1.01,220]],"ltp":0.0,"tv":0.0,"id":25173012}]}]}
{"op":"mcm","clk":"11801082657","pt":1722671542406,"mc":[{"id":"1.231395388","marketDefinition":{"bspMarket":false,"turnInPlayEnabled":true,"persistenceEnabled":true,"marketBaseRate":5.0,"eventId":"33464867","eventTypeId":"4","numberOfWinners":1,"bettingType":"ODDS","marketType":"MATCH_ODDS","marketTime":"2024-08-04T15:00:00.000Z","suspendTime":"2024-08-04T15:00:00.000Z","bspReconciled":false,"complete":true,"inPlay":false,"crossMatching":true,"runnersVoidable":false,"numberOfActiveRunners":2,"betDelay":0,"status":"OPEN","runners":[{"status":"ACTIVE","sortPriority":1,"id":25173012,"name":"Brampton Wolves"},{"status":"ACTIVE","sortPriority":2,"id":58385184,"name":"Surrey Jaguars"}],"regulators":["MR_INT"],"countryCode":"GB","discountAllowed":true,"timezone":"GMT","openDate":"2024-08-04T15:00:00.000Z","version":6052780293,"name":"Match Odds","eventName":"Brampton Wolves v Surrey Jaguars"}}]}
{"op":"mcm","clk":"11801084824","pt":1722671590314,"mc":[{"id":"1.231395388","rc":[{"batb":[[2,1.01,6390.05]],"ltp":0.0,"tv":0.0,"id":58385184},{"batb":[[0,1.04,1626.3],[1,1.03,2352.48],[2,1.02,3378.41]],"ltp":0.0,"tv":0.0,"id":25173012}]}]}
{"op":"mcm","clk":"11801084867","pt":1722671591197,"mc":[{"id":"1.231395388","rc":[{"batb":[[0,1.04,1626.3],[1,1.03,2352.48],[2,1.02,3378.41]],"ltp":0.0,"tv":0.0,"id":58385184}]}]}
{"op":"mcm","clk":"11801109581","pt":1722672132911,"mc":[{"id":"1.231395388","rc":[{"batl":[[0,6,0.96]],"ltp":0.0,"tv":0.0,"id":58385184}]}]}
{"op":"mcm","clk":"11801110180","pt":1722672143231,"mc":[{"id":"1.231395388","rc":[{"batl":[[0,5,0.96]],"ltp":0.0,"tv":0.0,"id":25173012}]}]}
{"op":"mcm","clk":"11801262438","pt":1722674329691,"mc":[{"id":"1.231395388","rc":[{"batb":[[0,1.26,32.95],[1,1.04,1626.3],[2,1.03,2352.48]],"ltp":0.0,"tv":0.0,"id":58385184},{"batb":[[0,1.21,40.79],[1,1.04,1626.3],[2,1.03,2352.48]],"ltp":0.0,"tv":0.0,"id":25173012}]}]}
{"op":"mcm","clk":"11801397353","pt":1722676130104,"mc":[{"id":"1.231395388","rc":[{"batb":[[0,1.04,1626.3],[1,1.03,2352.48],[2,1.02,3378.41]],"ltp":0.0,"tv":0.0,"id":58385184},{"batb":[[0,1.04,1626.3],[1,1.03,2352.48],[2,1.02,3378.41]],"ltp":0.0,"tv":0.0,"id":25173012}]}]}
{"op":"mcm","clk":"11802075093","pt":1722681967134,"mc":[{"id":"1.231395388","rc":[{"batb":[[0,1.25,100],[1,1.04,1626.3],[2,1.03,2352.48]],"ltp":0.0,"tv":0.0,"id":58385184},{"batb":[[0,1.25,100],[1,1.04,1626.3],[2,1.03,2352.48]],"ltp":0.0,"tv":0.0,"id":25173012}]}]}
{"op":"mcm","clk":"11802093625","pt":1722682095835,"mc":[{"id":"1.231395388","rc":[{"batb":[[0,1.26,32.95],[1,1.25,100],[2,1.04,1626.3]],"ltp":0.0,"tv":0.0,"id":58385184},{"batb":[[0,1.26,32.95],[1,1.25,100],[2,1.04,1626.3]],"ltp":0.0,"tv":0.0,"id":25173012}]}]}
{"op":"mcm","clk":"11802276005","pt":1722683545805,"mc":[{"id":"1.231395388","rc":[{"batl":[[0,4,0.78]],"ltp":0.0,"tv":0.0,"id":58385184},{"batl":[[0,4,0.78]],"ltp":0.0,"tv":0.0,"id":25173012}]}]}
{"op":"mcm","clk":"11802277082","pt":1722683553218,"mc":[{"id":"1.231395388","rc":[{"batl":[[0,5,1.56]],"ltp":0.0,"tv":0.0,"id":58385184},{"batl":[[0,5,1.56]],"ltp":0.0,"tv":0.0,"id":25173012}]}]}
{"op":"mcm","clk":"11802278302","pt":1722683561726,"mc":[{"id":"1.231395388","rc":[{"batl":[[1,6,0.78]],"ltp":0.0,"tv":0.0,"id":58385184},{"batl":[[1,6,0.78]],"ltp":0.0,"tv":0.0,"id":25173012}]}]}
{"op":"mcm","clk":"11802280249","pt":1722683574138,"mc":[{"id":"1.231395388","rc":[{"batb":[[0,1.27,7.18],[1,1.26,32.95],[2,1.25,100]],"ltp":0.0,"tv":0.0,"id":58385184},{"batb":[[0,1.27,6.37],[1,1.26,32.95],[2,1.25,100]],"ltp":0.0,"tv":0.0,"id":25173012}]}]}
{"op":"mcm","clk":"11802342432","pt":1722683896283,"mc":[{"id":"1.231395388","rc":[{"batb":[[1,1.25,100],[2,1.04,1627.08]],"ltp":0.0,"tv":0.0,"id":58385184},{"batb":[[1,1.25,100],[2,1.04,1627.08]],"ltp":0.0,"tv":0.0,"id":25173012}]}]}
{"op":"mcm","clk":"11802358887","pt":1722684002811,"mc":[{"id":"1.231395388","rc":[{"batb":[[0,1.34,25.19],[1,1.27,7.18],[2,1.25,100]],"ltp":0.0,"tv":0.0,"id":58385184},{"batb":[[0,1.34,25.19],[1,1.27,6.37],[2,1.25,100]],"ltp":0.0,"tv":0.0,"id":25173012}]}]}
{"op":"mcm","clk":"11802634941","pt":1722685803157,"mc":[{"id":"1.231395388","rc":[{"batb":[[0,1.27,7.18],[1,1.25,100],[2,1.04,1627.08]],"ltp":0.0,"tv":0.0,"id":58385184},{"batb":[[0,1.27,6.37],[1,1.25,100],[2,1.04,1627.08]],"ltp":0.0,"tv":0.0,"id":25173012}]}]}
{"op":"mcm","clk":"11802649470","pt":1722685885758,"mc":[{"id":"1.231395388","rc":[{"batb":[[0,1.34,25.19],[1,1.27,7.18],[2,1.25,100]],"ltp":0.0,"tv":0.0,"id":58385184},{"batb":[[0,1.34,25.19],[1,1.27,6.37],[2,1.25,100]],"ltp":0.0,"tv":0.0,"id":25173012}]}]}
{"op":"mcm","clk":"11802918314","pt":1722687686389,"mc":[{"id":"1.231395388","rc":[{"batb":[[0,1.27,7.18],[1,1.25,100],[2,1.04,1627.08]],"ltp":0.0,"tv":0.0,"id":58385184},{"batb":[[0,1.27,6.37],[1,1.25,100],[2,1.04,1627.08]],"ltp":0.0,"tv":0.0,"id":25173012}]}]}
{"op":"mcm","clk":"11802924850","pt":1722687731367,"mc":[{"id":"1.231395388","rc":[{"batb":[[0,1.34,25.19],[1,1.27,7.18],[2,1.25,100]],"ltp":0.0,"tv":0.0,"id":58385184},{"batb":[[0,1.34,25.19],[1,1.27,6.37],[2,1.25,100]],"ltp":0.0,"tv":0.0,"id":25173012}]}]}
{"op":"mcm","clk":"11802966793","pt":1722687999286,"mc":[{"id":"1.231395388","rc":[{"batb":[[1,1.25,100],[2,1.04,1627.08]],"ltp":0.0,"tv":0.0,"id":58385184},{"batb":[[0,1.35,6.37],[1,1.34,25.19]],"ltp":0.0,"tv":0.0,"id":25173012}]}]}
{"op":"mcm","clk":"11802966809","pt":1722687999396,"mc":[{"id":"1.231395388","rc":[{"batb":[[0,1.35,7.18],[1,1.34,25.19],[2,1.25,100]],"ltp":0.0,"tv":0.0,"id":58385184}]}]}
{"op":"mcm","clk":"11803213260","pt":1722689531800,"mc":[{"id":"1.231395388","rc":[{"batb":[[1,1.25,100],[2,1.04,1627.08]],"ltp":0.0,"tv":0.0,"id":58385184},{"batb":[[1,1.25,100],[2,1.04,1627.08]],"ltp":0.0,"tv":0.0,"id":25173012}]}]}
{"op":"mcm","clk":"11803215909","pt":1722689550000,"mc":[{"id":"1.231395388","rc":[{"batb":[[0,1.36,23.79],[1,1.35,7.18],[2,1.25,100]],"ltp":0.0,"tv":0.0,"id":58385184},{"batb":[[0,1.36,23.79],[1,1.35,6.37],[2,1.25,100]],"ltp":0.0,"tv":0.0,"id":25173012}]}]}
{"op":"mcm","clk":"11803501699","pt":1722691275210,"mc":[{"id":"1.231395388","rc":[{"batb":[[1,1.26,7.18]],"ltp":0.0,"tv":0.0,"id":58385184},{"batb":[[1,1.26,6.37]],"ltp":0.0,"tv":0.0,"id":25173012}]}]}
{"op":"mcm","clk":"11803514421","pt":1722691350362,"mc":[{"id":"1.231395388","rc":[{"batb":[[0,1.26,7.18],[1,1.25,100],[2,1.04,1627.08]],"ltp":0.0,"tv":0.0,"id":58385184},{"batb":[[0,1.26,6.37],[1,1.25,100],[2,1.04,1627.08]],"ltp":0.0,"tv":0.0,"id":25173012}]}]}
{"op":"mcm","clk":"11803542587","pt":1722691510725,"mc":[{"id":"1.231395388","rc":[{"batb":[[0,1.34,25.19],[1,1.26,7.18],[2,1.25,100]],"ltp":0.0,"tv":0.0,"id":58385184},{"batb":[[0,1.34,25.19],[1,1.26,6.37],[2,1.25,100]],"ltp":0.0,"tv":0.0,"id":25173012}]}]}
{"op":"mcm","clk":"11803848288","pt":1722693311363,"mc":[{"id":"1.231395388","rc":[{"batb":[[0,1.26,7.18],[1,1.25,100],[2,1.04,1627.08]],"ltp":0.0,"tv":0.0,"id":58385184},{"batb":[[0,1.26,6.37],[1,1.25,100],[2,1.04,1627.08]],"ltp":0.0,"tv":0.0,"id":25173012}]}]}
{"op":"mcm","clk":"11803868375","pt":1722693445577,"mc":[{"id":"1.231395388","rc":[{"batb":[[0,1.34,25.19],[1,1.26,7.18],[2,1.25,100]],"ltp":0.0,"tv":0.0,"id":58385184},{"batb":[[0,1.34,25.19],[1,1.26,6.37],[2,1.25,100]],"ltp":0.0,"tv":0.0,"id":25173012}]}]}
{"op":"mcm","clk":"11804098564","pt":1722694355326,"mc":[{"id":"1.231395388","rc":[{"batb":[[0,1.35,7.18],[1,1.34,25.19]],"ltp":0.0,"tv":0.0,"id":58385184},{"batb":[[0,1.35,6.37],[1,1.34,25.19]],"ltp":0.0,"tv":0.0,"id":25173012}]}]}
{"op":"mcm","clk":"11804367175","pt":1722695245951,"mc":[{"id":"1.231395388","rc":[{"batb":[[1,1.25,100],[2,1.04,1627.08]],"ltp":0.0,"tv":0.0,"id":58385184},{"batb":[[1,1.25,100],[2,1.04,1627.08]],"ltp":0.0,"tv":0.0,"id":25173012}]}]}
{"op":"mcm","clk":"11804385624","pt":1722695309316,"mc":[{"id":"1.231395388","rc":[{"batb":[[0,1.36,23.79],[1,1.35,7.18],[2,1.25,100]],"ltp":0.0,"tv":0.0,"id":58385184},{"batb":[[0,1.36,23.79],[1,1.35,6.37],[2,1.25,100]],"ltp":0.0,"tv":0.0,"id":25173012}]}]}
{"op":"mcm","clk":"11804843823","pt":1722697109618,"mc":[{"id":"1.231395388","rc":[{"batb":[[0,1.35,7.18],[1,1.25,100],[2,1.04,1627.08]],"ltp":0.0,"tv":0.0,"id":58385184},{"batb":[[0,1.35,6.37],[1,1.25,100],[2,1.04,1627.08]],"ltp":0.0,"tv":0.0,"id":25173012}]}]}
{"op":"mcm","clk":"11804848809","pt":1722697140386,"mc":[{"id":"1.231395388","rc":[{"batb":[[0,1.36,23.79],[1,1.35,7.18],[2,1.25,100]],"ltp":0.0,"tv":0.0,"id":58385184},{"batb":[[0,1.36,23.79],[1,1.35,6.37],[2,1.25,100]],"ltp":0.0,"tv":0.0,"id":25173012}]}]}
{"op":"mcm","clk":"11804910314","pt":1722697415346,"mc":[{"id":"1.231395388","rc":[{"batb":[[1,1.26,6.37]],"ltp":0.0,"tv":0.0,"id":25173012}]}]}
{"op":"mcm","clk":"11804910433","pt":1722697415771,"mc":[{"id":"1.231395388","rc":[{"batb":[[1,1.26,7.18]],"ltp":0.0,"tv":0.0,"id":58385184}]}]}
{"op":"mcm","clk":"11805379646","pt":1722698962095,"mc":[{"id":"1.231395388","rc":[{"batb":[[0,1.26,7.18],[1,1.25,100],[2,1.04,1627.08]],"ltp":0.0,"tv":0.0,"id":58385184},{"batb":[[0,1.26,6.37],[1,1.25,100],[2,1.04,1627.08]],"ltp":0.0,"tv":0.0,"id":25173012}]}]}
{"op":"mcm","clk":"11805415789","pt":1722699093587,"mc":[{"id":"1.231395388","rc":[{"batb":[[0,1.34,25.19],[1,1.26,7.18],[2,1.25,100]],"ltp":0.0,"tv":0.0,"id":58385184},{"batb":[[0,1.34,25.19],[1,1.26,6.37],[2,1.25,100]],"ltp":0.0,"tv":0.0,"id":25173012}]}]}
{"op":"mcm","clk":"11805766196","pt":1722700302978,"mc":[{"id":"1.231395388","rc":[{"batb":[[0,1.35,7.18],[1,1.34,25.19]],"ltp":0.0,"tv":0.0,"id":58385184},{"batb":[[0,1.35,6.37],[1,1.34,25.19]],"ltp":0.0,"tv":0.0,"id":25173012}]}]}
{"op":"mcm","clk":"11805867279","pt":1722700894084,"mc":[{"id":"1.231395388","rc":[{"batb":[[1,1.25,100],[2,1.04,1627.08]],"ltp":0.0,"tv":0.0,"id":58385184},{"batb":[[1,1.25,100],[2,1.04,1627.08]],"ltp":0.0,"tv":0.0,"id":25173012}]}]}
{"op":"mcm","clk":"11805881327","pt":1722700977088,"mc":[{"id":"1.231395388","rc":[{"batb":[[0,1.36,23.79],[1,1.35,7.18],[2,1.25,100]],"ltp":0.0,"tv":0.0,"id":58385184},{"batb":[[0,1.36,23.79],[1,1.35,6.37],[2,1.25,100]],"ltp":0.0,"tv":0.0,"id":25173012}]}]}
{"op":"mcm","clk":"11806195038","pt":1722702777256,"mc":[{"id":"1.231395388","rc":[{"batb":[[0,1.35,7.18],[1,1.25,100],[2,1.04,1627.08]],"ltp":0.0,"tv":0.0,"id":58385184}]}]}
{"op":"mcm","clk":"11806195158","pt":1722702777999,"mc":[{"id":"1.231395388","rc":[{"batb":[[0,1.35,6.37],[1,1.25,100],[2,1.04,1627.08]],"ltp":0.0,"tv":0.0,"id":25173012}]}]}
{"op":"mcm","clk":"11806204796","pt":1722702833939,"mc":[{"id":"1.231395388","rc":[{"batb":[[0,1.36,23.79],[1,1.35,7.18],[2,1.25,100]],"ltp":0.0,"tv":0.0,"id":58385184},{"batb":[[0,1.36,23.79],[1,1.35,6.37],[2,1.25,100]],"ltp":0.0,"tv":0.0,"id":25173012}]}]}
{"op":"mcm","clk":"11806232854","pt":1722702988165,"mc":[{"id":"1.231395388","rc":[{"batb":[[1,1.26,7.18]],"ltp":0.0,"tv":0.0,"id":58385184},{"batb":[[1,1.26,6.37]],"ltp":0.0,"tv":0.0,"id":25173012}]}]}
{"op":"mcm","clk":"11806515816","pt":1722704634297,"mc":[{"id":"1.231395388","rc":[{"batb":[[0,1.26,7.18],[1,1.25,100],[2,1.04,1627.08]],"ltp":0.0,"tv":0.0,"id":58385184},{"batb":[[0,1.26,6.37],[1,1.25,100],[2,1.04,1627.08]],"ltp":0.0,"tv":0.0,"id":25173012}]}]}
{"op":"mcm","clk":"11806517583","pt":1722704644200,"mc":[{"id":"1.231395388","rc":[{"batb":[[0,1.34,25.19],[1,1.26,7.18],[2,1.25,100]],"ltp":0.0,"tv":0.0,"id":58385184},{"batb":[[0,1.34,25.19],[1,1.26,6.37],[2,1.25,100]],"ltp":0.0,"tv":0.0,"id":25173012}]}]}
{"op":"mcm","clk":"11806675564","pt":1722705462307,"mc":[{"id":"1.231395388","rc":[{"batb":[[0,1.35,7.18],[1,1.34,25.19]],"ltp":0.0,"tv":0.0,"id":58385184},{"batb":[[0,1.35,6.37],[1,1.34,25.19]],"ltp":0.0,"tv":0.0,"id":25173012}]}]}
{"op":"mcm","clk":"11806850262","pt":1722706444363,"mc":[{"id":"1.231395388","rc":[{"batb":[[1,1.25,100],[2,1.04,1627.08]],"ltp":0.0,"tv":0.0,"id":58385184}]}]}
{"op":"mcm","clk":"11806850277","pt":1722706444466,"mc":[{"id":"1.231395388","rc":[{"batb":[[1,1.25,100],[2,1.04,1627.08]],"ltp":0.0,"tv":0.0,"id":25173012}]}]}
{"op":"mcm","clk":"11806859098","pt":1722706496028,"mc":[{"id":"1.231395388","rc":[{"batb":[[0,1.36,23.79],[1,1.35,7.18],[2,1.25,100]],"ltp":0.0,"tv":0.0,"id":58385184},{"batb":[[0,1.36,23.79],[1,1.35,6.37],[2,1.25,100]],"ltp":0.0,"tv":0.0,"id":25173012}]}]}
{"op":"mcm","clk":"11806925434","pt":1722706858970,"mc":[{"id":"1.231395388","rc":[{"batb":[[0,1.36,24.34]],"ltp":0.0,"tv":0.0,"id":25173012}]}]}
{"op":"mcm","clk":"11806927017","pt":1722706867992,"mc":[{"id":"1.231395388","rc":[{"batb":[[0,1.36,24.34]],"ltp":0.0,"tv":0.0,"id":58385184}]}]}
{"op":"mcm","clk":"11806976165","pt":1722707144177,"mc":[{"id":"1.231395388","rc":[{"batb":[[0,1.36,23.79]],"ltp":0.0,"tv":0.0,"id":58385184},{"batb":[[0,1.36,23.79]],"ltp":0.0,"tv":0.0,"id":25173012}]}]}
{"op":"mcm","clk":"11807073535","pt":1722707734924,"mc":[{"id":"1.231395388","rc":[{"batb":[[0,1.36,24.34]],"ltp":0.0,"tv":0.0,"id":25173012}]}]}
{"op":"mcm","clk":"11807075148","pt":1722707744947,"mc":[{"id":"1.231395388","rc":[{"batb":[[0,1.36,24.34]],"ltp":0.0,"tv":0.0,"id":58385184}]}]}
{"op":"mcm","clk":"11807123100","pt":1722708065346,"mc":[{"id":"1.231395388","rc":[{"batb":[[1,1.26,7.18]],"ltp":0.0,"tv":0.0,"id":58385184},{"batb":[[1,1.26,6.37]],"ltp":0.0,"tv":0.0,"id":25173012}]}]}
{"op":"mcm","clk":"11807163823","pt":1722708296340,"mc":[{"id":"1.231395388","rc":[{"batb":[[0,1.26,7.72],[1,1.25,100],[2,1.04,1627.08]],"ltp":0.0,"tv":0.0,"id":58385184},{"batb":[[0,1.26,6.92],[1,1.25,100],[2,1.04,1627.08]],"ltp":0.0,"tv":0.0,"id":25173012}]}]}
{"op":"mcm","clk":"11807188168","pt":1722708413278,"mc":[{"id":"1.231395388","rc":[{"batb":[[0,1.34,25.74],[1,1.26,7.18],[2,1.25,100]],"ltp":0.0,"tv":0.0,"id":58385184},{"batb":[[0,1.34,25.74],[1,1.26,6.37],[2,1.25,100]],"ltp":0.0,"tv":0.0,"id":25173012}]}]}
{"op":"mcm","clk":"11807504252","pt":1722709878217,"mc":[{"id":"1.231395388","rc":[{"batb":[[0,2.12,36.06],[1,1.34,25.74],[2,1.26,7.18]],"ltp":0.0,"tv":0.0,"id":58385184},{"batb":[[0,1.82,49.26],[1,1.34,25.74],[2,1.26,6.37]],"ltp":0.0,"tv":0.0,"id":25173012}]}]}
{"op":"mcm","clk":"11807575795","pt":1722710213726,"mc":[{"id":"1.231395388","rc":[{"batb":[[1,1.26,7.72],[2,1.25,100]],"ltp":0.0,"tv":0.0,"id":58385184},{"batb":[[1,1.26,6.92],[2,1.25,100]],"ltp":0.0,"tv":0.0,"id":25173012}]}]}
{"op":"mcm","clk":"11807654224","pt":1722710569140,"mc":[{"id":"1.231395388","rc":[{"batb":[[1,1.25,100.55],[2,1.04,1627.08]],"ltp":0.0,"tv":0.0,"id":58385184},{"batb":[[1,1.25,100.55],[2,1.04,1627.08]],"ltp":0.0,"tv":0.0,"id":25173012}]}]}
{"op":"mcm","clk":"11807889405","pt":1722711705012,"mc":[{"id":"1.231395388","rc":[{"batb":[[1,1.25,100]],"ltp":0.0,"tv":0.0,"id":25173012}]}]}
{"op":"mcm","clk":"11807890157","pt":1722711709021,"mc":[{"id":"1.231395388","rc":[{"batb":[[1,1.25,100]],"ltp":0.0,"tv":0.0,"id":58385184}]}]}
{"op":"mcm","clk":"11808715723","pt":1722716167817,"mc":[{"id":"1.231395388","rc":[{"batb":[[1,1.81,3.35],[2,1.25,100]],"ltp":0.0,"tv":0.0,"id":25173012}]}]}
{"op":"mcm","clk":"11808715862","pt":1722716168814,"mc":[{"id":"1.231395388","rc":[{"batb":[[1,1.25,100],[2,1.04,1627.08]],"ltp":0.0,"tv":0.0,"id":25173012}]}]}
{"op":"mcm","clk":"11809585823","pt":1722726989305,"mc":[{"id":"1.231395388","rc":[{"trd":[[2.12,1.02]],"batb":[[0,2.12,35.55]],"ltp":2.12,"tv":1.01,"id":58385184}],"tv":1.01}]}
{"op":"mcm","clk":"11809585939","pt":1722726991075,"mc":[{"id":"1.231395388","rc":[{"batb":[[0,2.12,36.06]],"ltp":2.12,"tv":1.01,"id":58385184}]}]}
{"op":"mcm","clk":"11809689724","pt":1722728905955,"mc":[{"id":"1.231395388","rc":[{"batl":[[0,1.89,36.34],[1,5,1.56],[2,6,0.78]],"ltp":0.0,"tv":0.0,"id":25173012}]}]}
{"op":"mcm","clk":"11809690651","pt":1722728922946,"mc":[{"id":"1.231395388","rc":[{"batb":[[1,1.81,36.34],[2,1.25,100]],"ltp":2.12,"tv":1.01,"id":58385184}]}]}
{"op":"mcm","clk":"11809692025","pt":1722728951012,"mc":[{"id":"1.231395388","rc":[{"batb":[[1,1.67,36.34],[2,1.25,100]],"ltp":0.0,"tv":0.0,"id":25173012}]}]}
{"op":"mcm","clk":"11809692674","pt":1722728965024,"mc":[{"id":"1.231395388","rc":[{"batb":[[2,1.54,36.34]],"ltp":0.0,"tv":0.0,"id":25173012}]}]}
{"op":"mcm","clk":"11809935399","pt":1722732921133,"mc":[{"id":"1.231395388","rc":[{"batb":[[0,1.82,353.11]],"ltp":0.0,"tv":0.0,"id":25173012}]}]}
{"op":"mcm","clk":"11809956631","pt":1722733296021,"mc":[{"id":"1.231395388","rc":[{"trd":[[2.12,5.08]],"ltp":2.12,"tv":5.08,"id":58385184}],"tv":5.08}]}
{"op":"mcm","clk":"11809978642","pt":1722733655538,"mc":[{"id":"1.231395388","rc":[{"batl":[[0,2.2,14.22],[1,5,1.56],[2,6,0.78]],"ltp":2.12,"tv":5.08,"id":58385184}]}]}
{"op":"mcm","clk":"11810011896","pt":1722734134880,"mc":[{"id":"1.231395388","rc":[{"batb":[[0,1.82,49.26]],"ltp":0.0,"tv":0.0,"id":25173012}]}]}
{"op":"mcm","clk":"11810011996","pt":1722734136121,"mc":[{"id":"1.231395388","rc":[{"batl":[[0,5,1.56],[1,6,0.78],[2,6,0]],"ltp":2.12,"tv":5.08,"id":58385184}]}]}
{"op":"mcm","clk":"11810514497","pt":1722742544283,"mc":[{"id":"1.231395388","rc":[{"trd":[[1.82,1.02]],"ltp":1.82,"tv":1.01,"id":25173012}],"tv":6.1}]}
{"op":"mcm","clk":"11810516774","pt":1722742586582,"mc":[{"id":"1.231395388","rc":[{"batb":[[0,1.81,36.34],[1,1.25,100],[2,1.04,1627.08]],"ltp":2.12,"tv":5.08,"id":58385184},{"batb":[[0,1.67,36.34],[1,1.54,36.34],[2,1.25,100]],"ltp":1.82,"tv":1.01,"id":25173012}]}]}
{"op":"mcm","clk":"11810562631","pt":1722743309203,"mc":[{"id":"1.231395388","rc":[{"batb":[[0,1.69,3.27],[1,1.67,36.34],[2,1.54,36.34]],"ltp":1.82,"tv":1.01,"id":25173012}]}]}
{"op":"mcm","clk":"11810563399","pt":1722743324128,"mc":[{"id":"1.231395388","rc":[{"batl":[[0,1.87,3.14],[1,1.89,36.34],[2,5,1.56]],"ltp":1.82,"tv":1.01,"id":25173012}]}]}
{"op":"mcm","clk":"11810564034","pt":1722743337915,"mc":[{"id":"1.231395388","rc":[{"batb":[[0,1.69,4.22]],"ltp":1.82,"tv":1.01,"id":25173012}]}]}
{"op":"mcm","clk":"11810564602","pt":1722743348920,"mc":[{"id":"1.231395388","rc":[{"batl":[[0,1.87,4.1]],"ltp":1.82,"tv":1.01,"id":25173012}]}]}
{"op":"mcm","clk":"11810576129","pt":1722743620292,"mc":[{"id":"1.231395388","rc":[{"batb":[[0,1.69,611.92]],"ltp":1.82,"tv":1.01,"id":25173012}]}]}
{"op":"mcm","clk":"11810603034","pt":1722744378641,"mc":[{"id":"1.231395388","rc":[{"batl":[[0,2.44,17.15],[1,5,1.56],[2,6,0.78]],"ltp":2.12,"tv":5.08,"id":58385184},{"batb":[[0,1.7,18.11],[1,1.69,610.97],[2,1.67,36.34]],"ltp":1.82,"tv":1.01,"id":25173012}]}]}
{"op":"mcm","clk":"11810611146","pt":1722744643092,"mc":[{"id":"1.231395388","rc":[{"batb":[[0,1.7,25.51]],"ltp":1.82,"tv":1.01,"id":25173012}]}]}
{"op":"mcm","clk":"11810614193","pt":1722744745977,"mc":[{"id":"1.231395388","rc":[{"batb":[[0,2.12,36.06],[1,1.81,36.34],[2,1.25,100]],"ltp":2.12,"tv":5.08,"id":58385184},{"batb":[[0,1.82,49.26],[1,1.7,25.51],[2,1.69,610.97]],"ltp":1.82,"tv":1.01,"id":25173012}]}]}
{"op":"mcm","clk":"11810614394","pt":1722744750041,"mc":[{"id":"1.231395388","rc":[{"batl":[[0,5,1.56],[1,6,0.78],[2,6,0]],"ltp":2.12,"tv":5.08,"id":58385184},{"batb":[[1,1.7,8.36]],"ltp":1.82,"tv":1.01,"id":25173012}]}]}
{"op":"mcm","clk":"11810670805","pt":1722746821516,"mc":[{"id":"1.231395388","rc":[{"batb":[[1,1.69,611.92],[2,1.67,36.34]],"ltp":1.82,"tv":1.01,"id":25173012}]}]}
{"op":"mcm","clk":"11810685368","pt":1722747479301,"mc":[{"id":"1.231395388","rc":[{"batl":[[0,1.89,37.3],[1,5,1.56],[2,6,0.78]],"ltp":1.82,"tv":1.01,"id":25173012}]}]}
{"op":"mcm","clk":"11810685410","pt":1722747482083,"mc":[{"id":"1.231395388","rc":[{"batb":[[1,1.69,608.66]],"ltp":1.82,"tv":1.01,"id":25173012}]}]}
{"op":"mcm","clk":"11810685498","pt":1722747487102,"mc":[{"id":"1.231395388","rc":[{"batl":[[0,1.89,36.34]],"ltp":1.82,"tv":1.01,"id":25173012}]}]}
{"op":"mcm","clk":"11810685697","pt":1722747500129,"mc":[{"id":"1.231395388","rc":[{"batb":[[1,1.69,611]],"ltp":1.82,"tv":1.01,"id":25173012}]}]}
{"op":"mcm","clk":"11810706209","pt":1722748374969,"mc":[{"id":"1.231395388","rc":[{"trd":[[2.12,5.1]],"ltp":2.12,"tv":5.09,"id":58385184}],"tv":6.11}]}
{"op":"mcm","clk":"11810712985","pt":1722748554041,"mc":[{"id":"1.231395388","rc":[{"batb":[[1,1.69,607.7]],"ltp":1.82,"tv":1.01,"id":25173012}]}]}
{"op":"mcm","clk":"11810713072","pt":1722748558044,"mc":[{"id":"1.231395388","rc":[{"batb":[[1,1.67,36.34],[2,1.54,36.34]],"ltp":1.82,"tv":1.01,"id":25173012}]}]}
{"op":"mcm","clk":"11810713751","pt":1722748596342,"mc":[{"id":"1.231395388","rc":[{"trd":[[2.22,25.33]],"ltp":2.22,"tv":30.42,"id":58385184},{"trd":[[1.82,31.92]],"batb":[[0,1.82,18.36]],"ltp":1.82,"tv":31.91,"id":25173012}],"tv":62.34}]}
{"op":"mcm","clk":"11810713755","pt":1722748596443,"mc":[{"id":"1.231395388","rc":[{"batb":[[0,2.14,10],[1,2.12,36.06],[2,1.81,36.34]],"ltp":2.22,"tv":30.42,"id":58385184}]}]}
{"op":"mcm","clk":"11810713820","pt":1722748600186,"mc":[{"id":"1.231395388","rc":[{"batb":[[0,2.12,36.06],[1,1.81,36.34],[2,1.25,100]],"ltp":2.22,"tv":30.42,"id":58385184},{"batb":[[0,1.82,49.26]],"ltp":1.82,"tv":31.91,"id":25173012}]}]}
{"op":"mcm","clk":"11810713871","pt":1722748602445,"mc":[{"id":"1.231395388","rc":[{"batb":[[0,2.14,10],[1,2.12,36.06],[2,1.81,36.34]],"ltp":2.22,"tv":30.42,"id":58385184}]}]}
{"op":"mcm","clk":"11810713925","pt":1722748605769,"mc":[{"id":"1.231395388","rc":[{"batb":[[0,2.12,36.06],[1,1.81,36.34],[2,1.25,100]],"ltp":2.22,"tv":30.42,"id":58385184}]}]}
{"op":"mcm","clk":"11810713964","pt":1722748607978,"mc":[{"id":"1.231395388","rc":[{"batb":[[0,2.14,10],[1,2.12,36.06],[2,1.81,36.34]],"ltp":2.22,"tv":30.42,"id":58385184}]}]}
{"op":"mcm","clk":"11810713996","pt":1722748611355,"mc":[{"id":"1.231395388","rc":[{"batb":[[0,2.12,36.06],[1,1.81,36.34],[2,1.25,100]],"ltp":2.22,"tv":30.42,"id":58385184}]}]}
{"op":"mcm","clk":"11810714047","pt":1722748614071,"mc":[{"id":"1.231395388","rc":[{"batb":[[0,2.14,10],[1,2.12,36.06],[2,1.81,36.34]],"ltp":2.22,"tv":30.42,"id":58385184}]}]}
{"op":"mcm","clk":"11810714118","pt":1722748617400,"mc":[{"id":"1.231395388","rc":[{"batb":[[0,2.12,36.06],[1,1.81,36.34],[2,1.25,100]],"ltp":2.22,"tv":30.42,"id":58385184}]}]}
{"op":"mcm","clk":"11810714163","pt":1722748619809,"mc":[{"id":"1.231395388","rc":[{"batb":[[0,2.14,10],[1,2.12,36.06],[2,1.81,36.34]],"ltp":2.22,"tv":30.42,"id":58385184}]}]}
{"op":"mcm","clk":"11810714198","pt":1722748623192,"mc":[{"id":"1.231395388","rc":[{"batb":[[0,2.12,36.06],[1,1.81,36.34],[2,1.25,100]],"ltp":2.22,"tv":30.42,"id":58385184}]}]}
{"op":"mcm","clk":"11810714238","pt":1722748625599,"mc":[{"id":"1.231395388","rc":[{"batb":[[0,2.14,10],[1,2.12,36.06],[2,1.81,36.34]],"ltp":2.22,"tv":30.42,"id":58385184}]}]}
{"op":"mcm","clk":"11810714281","pt":1722748628983,"mc":[{"id":"1.231395388","rc":[{"batb":[[0,2.12,36.06],[1,1.81,36.34],[2,1.25,100]],"ltp":2.22,"tv":30.42,"id":58385184}]}]}
{"op":"mcm","clk":"11810714332","pt":1722748631409,"mc":[{"id":"1.231395388","rc":[{"batb":[[0,2.14,10],[1,2.12,36.06],[2,1.81,36.34]],"ltp":2.22,"tv":30.42,"id":58385184}]}]}
{"op":"mcm","clk":"11810714387","pt":1722748634594,"mc":[{"id":"1.231395388","rc":[{"batb":[[0,2.12,36.06],[1,1.81,36.34],[2,1.25,100]],"ltp":2.22,"tv":30.42,"id":58385184}]}]}
{"op":"mcm","clk":"11810714435","pt":1722748636901,"mc":[{"id":"1.231395388","rc":[{"batb":[[0,2.14,10],[1,2.12,36.06],[2,1.81,36.34]],"ltp":2.22,"tv":30.42,"id":58385184}]}]}
{"op":"mcm","clk":"11810714513","pt":1722748640189,"mc":[{"id":"1.231395388","rc":[{"batb":[[0,2.12,36.06],[1,1.81,36.34],[2,1.25,100]],"ltp":2.22,"tv":30.42,"id":58385184}]}]}
{"op":"mcm","clk":"11810714576","pt":1722748643632,"mc":[{"id":"1.231395388","rc":[{"batb":[[0,2.14,10],[1,2.12,36.06],[2,1.81,36.34]],"ltp":2.22,"tv":30.42,"id":58385184}]}]}
{"op":"mcm","clk":"11810714660","pt":1722748647015,"mc":[{"id":"1.231395388","rc":[{"batb":[[0,2.12,36.06],[1,1.81,36.34],[2,1.25,100]],"ltp":2.22,"tv":30.42,"id":58385184}]}]}
{"op":"mcm","clk":"11810714704","pt":1722748649223,"mc":[{"id":"1.231395388","rc":[{"batb":[[0,2.14,10],[1,2.12,36.06],[2,1.81,36.34]],"ltp":2.22,"tv":30.42,"id":58385184}]}]}
{"op":"mcm","clk":"11810714767","pt":1722748652517,"mc":[{"id":"1.231395388","rc":[{"batb":[[0,2.12,36.06],[1,1.81,36.34],[2,1.25,100]],"ltp":2.22,"tv":30.42,"id":58385184}]}]}
{"op":"mcm","clk":"11810714782","pt":1722748654889,"mc":[{"id":"1.231395388","rc":[{"batb":[[0,2.14,10],[1,2.12,36.06],[2,1.81,36.34]],"ltp":2.22,"tv":30.42,"id":58385184}]}]}
{"op":"mcm","clk":"11810714852","pt":1722748658329,"mc":[{"id":"1.231395388","rc":[{"batb":[[0,2.12,36.06],[1,1.81,36.34],[2,1.25,100]],"ltp":2.22,"tv":30.42,"id":58385184}]}]}
{"op":"mcm","clk":"11810714889","pt":1722748660796,"mc":[{"id":"1.231395388","rc":[{"batb":[[0,2.14,10],[1,2.12,36.06],[2,1.81,36.34]],"ltp":2.22,"tv":30.42,"id":58385184}]}]}
{"op":"mcm","clk":"11810714965","pt":1722748664235,"mc":[{"id":"1.231395388","rc":[{"batb":[[0,2.12,36.06],[1,1.81,36.34],[2,1.25,100]],"ltp":2.22,"tv":30.42,"id":58385184}]}]}
{"op":"mcm","clk":"11810715001","pt":1722748666598,"mc":[{"id":"1.231395388","rc":[{"batb":[[0,2.14,10],[1,2.12,36.06],[2,1.81,36.34]],"ltp":2.22,"tv":30.42,"id":58385184}]}]}
{"op":"mcm","clk":"11810715060","pt":1722748669908,"mc":[{"id":"1.231395388","rc":[{"batb":[[0,2.12,36.06],[1,1.81,36.34],[2,1.25,100]],"ltp":2.22,"tv":30.42,"id":58385184}]}]}
{"op":"mcm","clk":"11810715108","pt":1722748672134,"mc":[{"id":"1.231395388","rc":[{"batb":[[0,2.14,10],[1,2.12,36.06],[2,1.81,36.34]],"ltp":2.22,"tv":30.42,"id":58385184}]}]}
{"op":"mcm","clk":"11810715172","pt":1722748675421,"mc":[{"id":"1.231395388","rc":[{"batb":[[0,2.12,36.06],[1,1.81,36.34],[2,1.25,100]],"ltp":2.22,"tv":30.42,"id":58385184}]}]}
{"op":"mcm","clk":"11810715254","pt":1722748679629,"mc":[{"id":"1.231395388","rc":[{"batb":[[0,2.14,10],[1,2.12,36.06],[2,1.81,36.34]],"ltp":2.22,"tv":30.42,"id":58385184}]}]}
{"op":"mcm","clk":"11810715351","pt":1722748683046,"mc":[{"id":"1.231395388","rc":[{"batb":[[0,2.12,36.06],[1,1.81,36.34],[2,1.25,100]],"ltp":2.22,"tv":30.42,"id":58385184}]}]}
{"op":"mcm","clk":"11810715408","pt":1722748685717,"mc":[{"id":"1.231395388","rc":[{"batb":[[0,2.14,10],[1,2.12,36.06],[2,1.81,36.34]],"ltp":2.22,"tv":30.42,"id":58385184}]}]}
{"op":"mcm","clk":"11810715466","pt":1722748688996,"mc":[{"id":"1.231395388","rc":[{"batb":[[0,2.12,36.06],[1,1.81,36.34],[2,1.25,100]],"ltp":2.22,"tv":30.42,"id":58385184}]}]}
{"op":"mcm","clk":"11810715507","pt":1722748691399,"mc":[{"id":"1.231395388","rc":[{"batb":[[0,2.14,10],[1,2.12,36.06],[2,1.81,36.34]],"ltp":2.22,"tv":30.42,"id":58385184}]}]}
{"op":"mcm","clk":"11810715554","pt":1722748694729,"mc":[{"id":"1.231395388","rc":[{"batb":[[0,2.12,36.06],[1,1.81,36.34],[2,1.25,100]],"ltp":2.22,"tv":30.42,"id":58385184}]}]}
{"op":"mcm","clk":"11810715597","pt":1722748698212,"mc":[{"id":"1.231395388","rc":[{"batb":[[0,2.14,10],[1,2.12,36.06],[2,1.81,36.34]],"ltp":2.22,"tv":30.42,"id":58385184}]}]}
{"op":"mcm","clk":"11810715667","pt":1722748701546,"mc":[{"id":"1.231395388","rc":[{"batb":[[0,2.12,36.06],[1,1.81,36.34],[2,1.25,100]],"ltp":2.22,"tv":30.42,"id":58385184}]}]}
{"op":"mcm","clk":"11810715721","pt":1722748704011,"mc":[{"id":"1.231395388","rc":[{"batb":[[0,2.14,10],[1,2.12,36.06],[2,1.81,36.34]],"ltp":2.22,"tv":30.42,"id":58385184}]}]}
{"op":"mcm","clk":"11810715796","pt":1722748707249,"mc":[{"id":"1.231395388","rc":[{"batb":[[0,2.12,36.06],[1,1.81,36.34],[2,1.25,100]],"ltp":2.22,"tv":30.42,"id":58385184}]}]}
{"op":"mcm","clk":"11810715869","pt":1722748711814,"mc":[{"id":"1.231395388","rc":[{"batb":[[0,2.14,10],[1,2.12,36.06],[2,1.81,36.34]],"ltp":2.22,"tv":30.42,"id":58385184}]}]}
{"op":"mcm","clk":"11810715959","pt":1722748715142,"mc":[{"id":"1.231395388","rc":[{"batb":[[0,2.12,36.06],[1,1.81,36.34],[2,1.25,100]],"ltp":2.22,"tv":30.42,"id":58385184}]}]}
{"op":"mcm","clk":"11810716018","pt":1722748717665,"mc":[{"id":"1.231395388","rc":[{"batb":[[0,2.14,10],[1,2.12,36.06],[2,1.81,36.34]],"ltp":2.22,"tv":30.42,"id":58385184}]}]}
{"op":"mcm","clk":"11810716116","pt":1722748721049,"mc":[{"id":"1.231395388","rc":[{"batb":[[0,2.12,36.06],[1,1.81,36.34],[2,1.25,100]],"ltp":2.22,"tv":30.42,"id":58385184}]}]}
{"op":"mcm","clk":"11810716166","pt":1722748723358,"mc":[{"id":"1.231395388","rc":[{"batb":[[0,2.14,10],[1,2.12,36.06],[2,1.81,36.34]],"ltp":2.22,"tv":30.42,"id":58385184}]}]}
{"op":"mcm","clk":"11810716234","pt":1722748726759,"mc":[{"id":"1.231395388","rc":[{"batb":[[0,2.12,36.06],[1,1.81,36.34],[2,1.25,100]],"ltp":2.22,"tv":30.42,"id":58385184}]}]}
{"op":"mcm","clk":"11810716353","pt":1722748730838,"mc":[{"id":"1.231395388","rc":[{"batb":[[0,2.14,10],[1,2.12,36.06],[2,1.81,36.34]],"ltp":2.22,"tv":30.42,"id":58385184}]}]}
{"op":"mcm","clk":"11810716445","pt":1722748734366,"mc":[{"id":"1.231395388","rc":[{"batb":[[0,2.12,36.06],[1,1.81,36.34],[2,1.25,100]],"ltp":2.22,"tv":30.42,"id":58385184}]}]}
{"op":"mcm","clk":"11810716500","pt":1722748737041,"mc":[{"id":"1.231395388","rc":[{"batb":[[0,2.14,10],[1,2.12,36.06],[2,1.81,36.34]],"ltp":2.22,"tv":30.42,"id":58385184}]}]}
{"op":"mcm","clk":"11810716596","pt":1722748740468,"mc":[{"id":"1.231395388","rc":[{"batb":[[0,2.12,36.06],[1,1.81,36.34],[2,1.25,100]],"ltp":2.22,"tv":30.42,"id":58385184}]}]}
{"op":"mcm","clk":"11810716654","pt":1722748743670,"mc":[{"id":"1.231395388","rc":[{"batb":[[0,2.14,10],[1,2.12,36.06],[2,1.81,36.34]],"ltp":2.22,"tv":30.42,"id":58385184}]}]}
{"op":"mcm","clk":"11810716733","pt":1722748747163,"mc":[{"id":"1.231395388","rc":[{"batb":[[0,2.12,36.06],[1,1.81,36.34],[2,1.25,100]],"ltp":2.22,"tv":30.42,"id":58385184}]}]}
{"op":"mcm","clk":"11810716770","pt":1722748749476,"mc":[{"id":"1.231395388","rc":[{"batb":[[0,2.14,10],[1,2.12,36.06],[2,1.81,36.34]],"ltp":2.22,"tv":30.42,"id":58385184}]}]}
{"op":"mcm","clk":"11810716832","pt":1722748752961,"mc":[{"id":"1.231395388","rc":[{"batb":[[0,2.12,36.06],[1,1.81,36.34],[2,1.25,100]],"ltp":2.22,"tv":30.42,"id":58385184}]}]}
{"op":"mcm","clk":"11810716889","pt":1722748755765,"mc":[{"id":"1.231395388","rc":[{"batb":[[0,2.14,10],[1,2.12,36.06],[2,1.81,36.34]],"ltp":2.22,"tv":30.42,"id":58385184}]}]}
{"op":"mcm","clk":"11810716930","pt":1722748759104,"mc":[{"id":"1.231395388","rc":[{"batb":[[0,2.12,36.06],[1,1.81,36.34],[2,1.25,100]],"ltp":2.22,"tv":30.42,"id":58385184}]}]}
{"op":"mcm","clk":"11810716992","pt":1722748762385,"mc":[{"id":"1.231395388","rc":[{"batb":[[0,2.14,10],[1,2.12,36.06],[2,1.81,36.34]],"ltp":2.22,"tv":30.42,"id":58385184}]}]}
{"op":"mcm","clk":"11810717058","pt":1722748765684,"mc":[{"id":"1.231395388","rc":[{"batb":[[0,2.12,36.06],[1,1.81,36.34],[2,1.25,100]],"ltp":2.22,"tv":30.42,"id":58385184}]}]}
{"op":"mcm","clk":"11810717102","pt":1722748767999,"mc":[{"id":"1.231395388","rc":[{"batb":[[0,2.14,10],[1,2.12,36.06],[2,1.81,36.34]],"ltp":2.22,"tv":30.42,"id":58385184}]}]}
{"op":"mcm","clk":"11810717154","pt":1722748771394,"mc":[{"id":"1.231395388","rc":[{"batb":[[0,2.12,36.06],[1,1.81,36.34],[2,1.25,100]],"ltp":2.22,"tv":30.42,"id":58385184}]}]}
{"op":"mcm","clk":"11810717193","pt":1722748773965,"mc":[{"id":"1.231395388","rc":[{"batb":[[0,2.14,10],[1,2.12,36.06],[2,1.81,36.34]],"ltp":2.22,"tv":30.42,"id":58385184}]}]}
{"op":"mcm","clk":"11810717247","pt":1722748777412,"mc":[{"id":"1.231395388","rc":[{"batb":[[0,2.12,36.06],[1,1.81,36.34],[2,1.25,100]],"ltp":2.22,"tv":30.42,"id":58385184}]}]}
{"op":"mcm","clk":"11810717319","pt":1722748780692,"mc":[{"id":"1.231395388","rc":[{"batb":[[0,2.14,10],[1,2.12,36.06],[2,1.81,36.34]],"ltp":2.22,"tv":30.42,"id":58385184}]}]}
{"op":"mcm","clk":"11810717401","pt":1722748784088,"mc":[{"id":"1.231395388","rc":[{"batb":[[0,2.12,36.06],[1,1.81,36.34],[2,1.25,100]],"ltp":2.22,"tv":30.42,"id":58385184}]}]}
{"op":"mcm","clk":"11810717452","pt":1722748786504,"mc":[{"id":"1.231395388","rc":[{"batb":[[0,2.14,10],[1,2.12,36.06],[2,1.81,36.34]],"ltp":2.22,"tv":30.42,"id":58385184}]}]}
{"op":"mcm","clk":"11810717493","pt":1722748789792,"mc":[{"id":"1.231395388","rc":[{"batb":[[0,2.12,36.06],[1,1.81,36.34],[2,1.25,100]],"ltp":2.22,"tv":30.42,"id":58385184}]}]}
{"op":"mcm","clk":"11810717541","pt":1722748792108,"mc":[{"id":"1.231395388","rc":[{"batb":[[0,2.14,10],[1,2.12,36.06],[2,1.81,36.34]],"ltp":2.22,"tv":30.42,"id":58385184}]}]}
{"op":"mcm","clk":"11810717583","pt":1722748795505,"mc":[{"id":"1.231395388","rc":[{"batb":[[0,2.12,36.06],[1,1.81,36.34],[2,1.25,100]],"ltp":2.22,"tv":30.42,"id":58385184}]}]}
{"op":"mcm","clk":"11810717630","pt":1722748798131,"mc":[{"id":"1.231395388","rc":[{"batb":[[0,2.14,10],[1,2.12,36.06],[2,1.81,36.34]],"ltp":2.22,"tv":30.42,"id":58385184}]}]}
{"op":"mcm","clk":"11810717695","pt":1722748801632,"mc":[{"id":"1.231395388","rc":[{"batb":[[0,2.12,36.06],[1,1.81,36.34],[2,1.25,100]],"ltp":2.22,"tv":30.42,"id":58385184}]}]}
{"op":"mcm","clk":"11810717748","pt":1722748803903,"mc":[{"id":"1.231395388","rc":[{"batb":[[0,2.14,10],[1,2.12,36.06],[2,1.81,36.34]],"ltp":2.22,"tv":30.42,"id":58385184}]}]}
{"op":"mcm","clk":"11810717802","pt":1722748807410,"mc":[{"id":"1.231395388","rc":[{"batb":[[0,2.12,36.06],[1,1.81,36.34],[2,1.25,100]],"ltp":2.22,"tv":30.42,"id":58385184}]}]}
{"op":"mcm","clk":"11810717869","pt":1722748809821,"mc":[{"id":"1.231395388","rc":[{"batb":[[0,2.14,10],[1,2.12,36.06],[2,1.81,36.34]],"ltp":2.22,"tv":30.42,"id":58385184}]}]}
{"op":"mcm","clk":"11810717965","pt":1722748813151,"mc":[{"id":"1.231395388","rc":[{"batb":[[0,2.12,36.06],[1,1.81,36.34],[2,1.25,100]],"ltp":2.22,"tv":30.42,"id":58385184}]}]}
{"op":"mcm","clk":"11810718048","pt":1722748815519,"mc":[{"id":"1.231395388","rc":[{"batb":[[0,2.14,10],[1,2.12,36.06],[2,1.81,36.34]],"ltp":2.22,"tv":30.42,"id":58385184}]}]}
{"op":"mcm","clk":"11810718149","pt":1722748818852,"mc":[{"id":"1.231395388","rc":[{"batb":[[0,2.12,36.06],[1,1.81,36.34],[2,1.25,100]],"ltp":2.22,"tv":30.42,"id":58385184}]}]}
{"op":"mcm","clk":"11810718337","pt":1722748824443,"mc":[{"id":"1.231395388","rc":[{"batb":[[0,2.14,10],[1,2.12,36.06],[2,1.81,36.34]],"ltp":2.22,"tv":30.42,"id":58385184}]}]}
{"op":"mcm","clk":"11810718431","pt":1722748827635,"mc":[{"id":"1.231395388","rc":[{"batb":[[0,2.12,36.06],[1,1.81,36.34],[2,1.25,100]],"ltp":2.22,"tv":30.42,"id":58385184}]}]}
{"op":"mcm","clk":"11810718476","pt":1722748830053,"mc":[{"id":"1.231395388","rc":[{"batb":[[0,2.14,10],[1,2.12,36.06],[2,1.81,36.34]],"ltp":2.22,"tv":30.42,"id":58385184}]}]}
{"op":"mcm","clk":"11810718541","pt":1722748833447,"mc":[{"id":"1.231395388","rc":[{"batb":[[0,2.12,36.06],[1,1.81,36.34],[2,1.25,100]],"ltp":2.22,"tv":30.42,"id":58385184}]}]}
{"op":"mcm","clk":"11810718672","pt":1722748838966,"mc":[{"id":"1.231395388","rc":[{"batb":[[0,2.14,10],[1,2.12,36.06],[2,1.81,36.34]],"ltp":2.22,"tv":30.42,"id":58385184}]}]}
{"op":"mcm","clk":"11810718746","pt":1722748842467,"mc":[{"id":"1.231395388","rc":[{"batb":[[0,2.12,36.06],[1,1.81,36.34],[2,1.25,100]],"ltp":2.22,"tv":30.42,"id":58385184}]}]}
{"op":"mcm","clk":"11810718786","pt":1722748844776,"mc":[{"id":"1.231395388","rc":[{"batb":[[0,2.14,10],[1,2.12,36.06],[2,1.81,36.34]],"ltp":2.22,"tv":30.42,"id":58385184}]}]}
{"op":"mcm","clk":"11810718847","pt":1722748848076,"mc":[{"id":"1.231395388","rc":[{"batb":[[0,2.12,36.06],[1,1.81,36.34],[2,1.25,100]],"ltp":2.22,"tv":30.42,"id":58385184}]}]}
{"op":"mcm","clk":"11810718876","pt":1722748850387,"mc":[{"id":"1.231395388","rc":[{"batb":[[0,2.14,10],[1,2.12,36.06],[2,1.81,36.34]],"ltp":2.22,"tv":30.42,"id":58385184}]}]}
{"op":"mcm","clk":"11810718954","pt":1722748853584,"mc":[{"id":"1.231395388","rc":[{"batb":[[0,2.12,36.06],[1,1.81,36.34],[2,1.25,100]],"ltp":2.22,"tv":30.42,"id":58385184}]}]}
{"op":"mcm","clk":"11810719035","pt":1722748857073,"mc":[{"id":"1.231395388","rc":[{"batb":[[0,2.14,10],[1,2.12,36.06],[2,1.81,36.34]],"ltp":2.22,"tv":30.42,"id":58385184}]}]}
{"op":"mcm","clk":"11810719105","pt":1722748860377,"mc":[{"id":"1.231395388","rc":[{"batb":[[0,2.12,36.06],[1,1.81,36.34],[2,1.25,100]],"ltp":2.22,"tv":30.42,"id":58385184}]}]}
{"op":"mcm","clk":"11810719207","pt":1722748864796,"mc":[{"id":"1.231395388","rc":[{"batb":[[0,2.14,10],[1,2.12,36.06],[2,1.81,36.34]],"ltp":2.22,"tv":30.42,"id":58385184}]}]}
{"op":"mcm","clk":"11810719276","pt":1722748868199,"mc":[{"id":"1.231395388","rc":[{"batb":[[0,2.12,36.06],[1,1.81,36.34],[2,1.25,100]],"ltp":2.22,"tv":30.42,"id":58385184}]}]}
{"op":"mcm","clk":"11810719371","pt":1722748873098,"mc":[{"id":"1.231395388","rc":[{"batb":[[0,2.14,10],[1,2.12,36.06],[2,1.81,36.34]],"ltp":2.22,"tv":30.42,"id":58385184}]}]}
{"op":"mcm","clk":"11810719444","pt":1722748876614,"mc":[{"id":"1.231395388","rc":[{"batb":[[0,2.12,36.06],[1,1.81,36.34],[2,1.25,100]],"ltp":2.22,"tv":30.42,"id":58385184}]}]}
{"op":"mcm","clk":"11810719510","pt":1722748879210,"mc":[{"id":"1.231395388","rc":[{"batb":[[0,2.14,10],[1,2.12,36.06],[2,1.81,36.34]],"ltp":2.22,"tv":30.42,"id":58385184}]}]}
{"op":"mcm","clk":"11810719578","pt":1722748882605,"mc":[{"id":"1.231395388","rc":[{"batb":[[0,2.12,36.06],[1,1.81,36.34],[2,1.25,100]],"ltp":2.22,"tv":30.42,"id":58385184}]}]}
{"op":"mcm","clk":"11810719655","pt":1722748884717,"mc":[{"id":"1.231395388","rc":[{"batb":[[0,2.14,10],[1,2.12,36.06],[2,1.81,36.34]],"ltp":2.22,"tv":30.42,"id":58385184}]}]}
{"op":"mcm","clk":"11810719744","pt":1722748888212,"mc":[{"id":"1.231395388","rc":[{"batb":[[0,2.12,36.06],[1,1.81,36.34],[2,1.25,100]],"ltp":2.22,"tv":30.42,"id":58385184}]}]}
{"op":"mcm","clk":"11810719799","pt":1722748890518,"mc":[{"id":"1.231395388","rc":[{"batb":[[0,2.14,10],[1,2.12,36.06],[2,1.81,36.34]],"ltp":2.22,"tv":30.42,"id":58385184}]}]}
{"op":"mcm","clk":"11810719874","pt":1722748893910,"mc":[{"id":"1.231395388","rc":[{"batb":[[0,2.12,36.06],[1,1.81,36.34],[2,1.25,100]],"ltp":2.22,"tv":30.42,"id":58385184}]}]}
{"op":"mcm","clk":"11810719972","pt":1722748897715,"mc":[{"id":"1.231395388","rc":[{"batb":[[0,2.14,10],[1,2.12,36.06],[2,1.81,36.34]],"ltp":2.22,"tv":30.42,"id":58385184}]}]}
{"op":"mcm","clk":"11810720037","pt":1722748900998,"mc":[{"id":"1.231395388","rc":[{"batb":[[0,2.12,36.06],[1,1.81,36.34],[2,1.25,100]],"ltp":2.22,"tv":30.42,"id":58385184}]}]}
{"op":"mcm","clk":"11810720092","pt":1722748903505,"mc":[{"id":"1.231395388","rc":[{"batb":[[0,2.14,10],[1,2.12,36.06],[2,1.81,36.34]],"ltp":2.22,"tv":30.42,"id":58385184}]}]}
{"op":"mcm","clk":"11810720147","pt":1722748906941,"mc":[{"id":"1.231395388","rc":[{"batb":[[0,2.12,36.06],[1,1.81,36.34],[2,1.25,100]],"ltp":2.22,"tv":30.42,"id":58385184}]}]}
{"op":"mcm","clk":"11810720218","pt":1722748910425,"mc":[{"id":"1.231395388","rc":[{"batb":[[0,2.14,10],[1,2.12,36.06],[2,1.81,36.34]],"ltp":2.22,"tv":30.42,"id":58385184}]}]}
{"op":"mcm","clk":"11810720281","pt":1722748913858,"mc":[{"id":"1.231395388","rc":[{"batb":[[0,2.12,36.06],[1,1.81,36.34],[2,1.25,100]],"ltp":2.22,"tv":30.42,"id":58385184}]}]}
{"op":"mcm","clk":"11810720371","pt":1722748917452,"mc":[{"id":"1.231395388","rc":[{"batb":[[0,2.14,10],[1,2.12,36.06],[2,1.81,36.34]],"ltp":2.22,"tv":30.42,"id":58385184}]}]}
{"op":"mcm","clk":"11810720460","pt":1722748921036,"mc":[{"id":"1.231395388","rc":[{"batb":[[0,2.12,36.06],[1,1.81,36.34],[2,1.25,100]],"ltp":2.22,"tv":30.42,"id":58385184}]}]}
{"op":"mcm","clk":"11810720539","pt":1722748924130,"mc":[{"id":"1.231395388","rc":[{"batb":[[0,2.14,10],[1,2.12,36.06],[2,1.81,36.34]],"ltp":2.22,"tv":30.42,"id":58385184}]}]}
{"op":"mcm","clk":"11810720618","pt":1722748927564,"mc":[{"id":"1.231395388","rc":[{"batb":[[0,2.12,36.06],[1,1.81,36.34],[2,1.25,100]],"ltp":2.22,"tv":30.42,"id":58385184}]}]}
{"op":"mcm","clk":"11810720682","pt":1722748929868,"mc":[{"id":"1.231395388","rc":[{"batb":[[0,2.14,10],[1,2.12,36.06],[2,1.81,36.34]],"ltp":2.22,"tv":30.42,"id":58385184}]}]}
{"op":"mcm","clk":"11810720764","pt":1722748933372,"mc":[{"id":"1.231395388","rc":[{"batb":[[0,2.12,36.06],[1,1.81,36.34],[2,1.25,100]],"ltp":2.22,"tv":30.42,"id":58385184}]}]}
{"op":"mcm","clk":"11810720818","pt":1722748935640,"mc":[{"id":"1.231395388","rc":[{"batb":[[0,2.14,10],[1,2.12,36.06],[2,1.81,36.34]],"ltp":2.22,"tv":30.42,"id":58385184}]}]}
{"op":"mcm","clk":"11810720913","pt":1722748939172,"mc":[{"id":"1.231395388","rc":[{"batb":[[0,2.12,36.06],[1,1.81,36.34],[2,1.25,100]],"ltp":2.22,"tv":30.42,"id":58385184}]}]}
{"op":"mcm","clk":"11810721029","pt":1722748944138,"mc":[{"id":"1.231395388","rc":[{"batb":[[0,2.14,10],[1,2.12,36.06],[2,1.81,36.34]],"ltp":2.22,"tv":30.42,"id":58385184}]}]}
{"op":"mcm","clk":"11810721099","pt":1722748947480,"mc":[{"id":"1.231395388","rc":[{"batb":[[0,2.12,36.06],[1,1.81,36.34],[2,1.25,100]],"ltp":2.22,"tv":30.42,"id":58385184}]}]}
{"op":"mcm","clk":"11810721182","pt":1722748950452,"mc":[{"id":"1.231395388","rc":[{"batb":[[0,2.14,10],[1,2.12,36.06],[2,1.81,36.34]],"ltp":2.22,"tv":30.42,"id":58385184}]}]}
{"op":"mcm","clk":"11810721258","pt":1722748953875,"mc":[{"id":"1.231395388","rc":[{"batb":[[0,2.12,36.06],[1,1.81,36.34],[2,1.25,100]],"ltp":2.22,"tv":30.42,"id":58385184}]}]}
{"op":"mcm","clk":"11810721366","pt":1722748958457,"mc":[{"id":"1.231395388","rc":[{"batb":[[0,2.14,10],[1,2.12,36.06],[2,1.81,36.34]],"ltp":2.22,"tv":30.42,"id":58385184}]}]}
{"op":"mcm","clk":"11810721444","pt":1722748961781,"mc":[{"id":"1.231395388","rc":[{"batb":[[0,2.12,36.06],[1,1.81,36.34],[2,1.25,100]],"ltp":2.22,"tv":30.42,"id":58385184}]}]}
{"op":"mcm","clk":"11810721527","pt":1722748964852,"mc":[{"id":"1.231395388","rc":[{"batb":[[0,2.14,10],[1,2.12,36.06],[2,1.81,36.34]],"ltp":2.22,"tv":30.42,"id":58385184}]}]}
{"op":"mcm","clk":"11810721604","pt":1722748968381,"mc":[{"id":"1.231395388","rc":[{"batb":[[0,2.12,36.06],[1,1.81,36.34],[2,1.25,100]],"ltp":2.22,"tv":30.42,"id":58385184}]}]}
{"op":"mcm","clk":"11810721746","pt":1722748973975,"mc":[{"id":"1.231395388","rc":[{"batb":[[0,2.14,10],[1,2.12,36.06],[2,1.81,36.34]],"ltp":2.22,"tv":30.42,"id":58385184}]}]}
{"op":"mcm","clk":"11810721828","pt":1722748977377,"mc":[{"id":"1.231395388","rc":[{"batb":[[0,2.12,36.06],[1,1.81,36.34],[2,1.25,100]],"ltp":2.22,"tv":30.42,"id":58385184}]}]}
{"op":"mcm","clk":"11810721886","pt":1722748979489,"mc":[{"id":"1.231395388","rc":[{"batb":[[0,2.14,10],[1,2.12,36.06],[2,1.81,36.34]],"ltp":2.22,"tv":30.42,"id":58385184}]}]}
{"op":"mcm","clk":"11810721959","pt":1722748982877,"mc":[{"id":"1.231395388","rc":[{"batb":[[0,2.12,36.06],[1,1.81,36.34],[2,1.25,100]],"ltp":2.22,"tv":30.42,"id":58385184}]}]}
{"op":"mcm","clk":"11810722032","pt":1722748985087,"mc":[{"id":"1.231395388","rc":[{"batb":[[0,2.14,10],[1,2.12,36.06],[2,1.81,36.34]],"ltp":2.22,"tv":30.42,"id":58385184}]}]}
{"op":"mcm","clk":"11810722134","pt":1722748988482,"mc":[{"id":"1.231395388","rc":[{"batb":[[0,2.12,36.06],[1,1.81,36.34],[2,1.25,100]],"ltp":2.22,"tv":30.42,"id":58385184}]}]}
{"op":"mcm","clk":"11810722239","pt":1722748992085,"mc":[{"id":"1.231395388","rc":[{"batb":[[0,2.14,10],[1,2.12,36.06],[2,1.81,36.34]],"ltp":2.22,"tv":30.42,"id":58385184}]}]}
{"op":"mcm","clk":"11810722319","pt":1722748995413,"mc":[{"id":"1.231395388","rc":[{"batb":[[0,2.12,36.06],[1,1.81,36.34],[2,1.25,100]],"ltp":2.22,"tv":30.42,"id":58385184}]}]}
{"op":"mcm","clk":"11810722386","pt":1722748997989,"mc":[{"id":"1.231395388","rc":[{"batb":[[0,2.14,10],[1,2.12,36.06],[2,1.81,36.34]],"ltp":2.22,"tv":30.42,"id":58385184}]}]}
{"op":"mcm","clk":"11810722457","pt":1722749001395,"mc":[{"id":"1.231395388","rc":[{"batb":[[0,2.12,36.06],[1,1.81,36.34],[2,1.25,100]],"ltp":2.22,"tv":30.42,"id":58385184}]}]}
{"op":"mcm","clk":"11810722534","pt":1722749003712,"mc":[{"id":"1.231395388","rc":[{"batb":[[0,2.14,10],[1,2.12,36.06],[2,1.81,36.34]],"ltp":2.22,"tv":30.42,"id":58385184}]}]}
{"op":"mcm","clk":"11810722609","pt":1722749007091,"mc":[{"id":"1.231395388","rc":[{"batb":[[0,2.12,36.06],[1,1.81,36.34],[2,1.25,100]],"ltp":2.22,"tv":30.42,"id":58385184}]}]}
{"op":"mcm","clk":"11810722694","pt":1722749010595,"mc":[{"id":"1.231395388","rc":[{"batb":[[0,2.14,10],[1,2.12,36.06],[2,1.81,36.34]],"ltp":2.22,"tv":30.42,"id":58385184}]}]}
{"op":"mcm","clk":"11810722776","pt":1722749014034,"mc":[{"id":"1.231395388","rc":[{"batb":[[0,2.12,36.06],[1,1.81,36.34],[2,1.25,100]],"ltp":2.22,"tv":30.42,"id":58385184}]}]}
{"op":"mcm","clk":"11810722884","pt":1722749018529,"mc":[{"id":"1.231395388","rc":[{"batb":[[0,2.14,10],[1,2.12,36.06],[2,1.81,36.34]],"ltp":2.22,"tv":30.42,"id":58385184}]}]}
{"op":"mcm","clk":"11810722949","pt":1722749022030,"mc":[{"id":"1.231395388","rc":[{"batb":[[0,2.12,36.06],[1,1.81,36.34],[2,1.25,100]],"ltp":2.22,"tv":30.42,"id":58385184}]}]}
{"op":"mcm","clk":"11810723020","pt":1722749024955,"mc":[{"id":"1.231395388","rc":[{"batb":[[0,2.14,10],[1,2.12,36.06],[2,1.81,36.34]],"ltp":2.22,"tv":30.42,"id":58385184}]}]}
{"op":"mcm","clk":"11810723105","pt":1722749028524,"mc":[{"id":"1.231395388","rc":[{"batb":[[0,2.12,36.06],[1,1.81,36.34],[2,1.25,100]],"ltp":2.22,"tv":30.42,"id":58385184}]}]}
{"op":"mcm","clk":"11810723178","pt":1722749031364,"mc":[{"id":"1.231395388","rc":[{"batb":[[0,2.14,10],[1,2.12,36.06],[2,1.81,36.34]],"ltp":2.22,"tv":30.42,"id":58385184}]}]}
{"op":"mcm","clk":"11810723252","pt":1722749034653,"mc":[{"id":"1.231395388","rc":[{"batb":[[0,2.12,36.06],[1,1.81,36.34],[2,1.25,100]],"ltp":2.22,"tv":30.42,"id":58385184}]}]}
{"op":"mcm","clk":"11810723327","pt":1722749037327,"mc":[{"id":"1.231395388","rc":[{"batb":[[0,2.14,10],[1,2.12,36.06],[2,1.81,36.34]],"ltp":2.22,"tv":30.42,"id":58385184}]}]}
{"op":"mcm","clk":"11810723407","pt":1722749041077,"mc":[{"id":"1.231395388","rc":[{"batb":[[0,2.12,36.06],[1,1.81,36.34],[2,1.25,100]],"ltp":2.22,"tv":30.42,"id":58385184}]}]}
{"op":"mcm","clk":"11810723458","pt":1722749043556,"mc":[{"id":"1.231395388","rc":[{"batb":[[0,2.14,10],[1,2.12,36.06],[2,1.81,36.34]],"ltp":2.22,"tv":30.42,"id":58385184}]}]}
{"op":"mcm","clk":"11810723547","pt":1722749046957,"mc":[{"id":"1.231395388","rc":[{"batb":[[0,2.12,36.06],[1,1.81,36.34],[2,1.25,100]],"ltp":2.22,"tv":30.42,"id":58385184}]}]}
{"op":"mcm","clk":"11810723596","pt":1722749049375,"mc":[{"id":"1.231395388","rc":[{"batb":[[0,2.14,10],[1,2.12,36.06],[2,1.81,36.34]],"ltp":2.22,"tv":30.42,"id":58385184}]}]}
{"op":"mcm","clk":"11810723667","pt":1722749052872,"mc":[{"id":"1.231395388","rc":[{"batb":[[0,2.12,36.06],[1,1.81,36.34],[2,1.25,100]],"ltp":2.22,"tv":30.42,"id":58385184}]}]}
{"op":"mcm","clk":"11810723709","pt":1722749055280,"mc":[{"id":"1.231395388","rc":[{"batb":[[0,2.14,10],[1,2.12,36.06],[2,1.81,36.34]],"ltp":2.22,"tv":30.42,"id":58385184}]}]}
{"op":"mcm","clk":"11810723798","pt":1722749058582,"mc":[{"id":"1.231395388","rc":[{"batb":[[0,2.12,36.06],[1,1.81,36.34],[2,1.25,100]],"ltp":2.22,"tv":30.42,"id":58385184}]}]}
{"op":"mcm","clk":"11810723966","pt":1722749064375,"mc":[{"id":"1.231395388","rc":[{"batb":[[0,2.14,10],[1,2.12,36.06],[2,1.81,36.34]],"ltp":2.22,"tv":30.42,"id":58385184}]}]}
{"op":"mcm","clk":"11810724049","pt":1722749067564,"mc":[{"id":"1.231395388","rc":[{"batb":[[0,2.12,36.06],[1,1.81,36.34],[2,1.25,100]],"ltp":2.22,"tv":30.42,"id":58385184}]}]}
{"op":"mcm","clk":"11810724099","pt":1722749069968,"mc":[{"id":"1.231395388","rc":[{"batb":[[0,2.14,10],[1,2.12,36.06],[2,1.81,36.34]],"ltp":2.22,"tv":30.42,"id":58385184}]}]}
{"op":"mcm","clk":"11810724178","pt":1722749073208,"mc":[{"id":"1.231395388","rc":[{"batb":[[0,2.12,36.06],[1,1.81,36.34],[2,1.25,100]],"ltp":2.22,"tv":30.42,"id":58385184}]}]}
{"op":"mcm","clk":"11810724240","pt":1722749075667,"mc":[{"id":"1.231395388","rc":[{"batb":[[0,2.14,10],[1,2.12,36.06],[2,1.81,36.34]],"ltp":2.22,"tv":30.42,"id":58385184}]}]}
{"op":"mcm","clk":"11810724327","pt":1722749079213,"mc":[{"id":"1.231395388","rc":[{"batb":[[0,2.12,36.06],[1,1.81,36.34],[2,1.25,100]],"ltp":2.22,"tv":30.42,"id":58385184}]}]}
{"op":"mcm","clk":"11810724388","pt":1722749081480,"mc":[{"id":"1.231395388","rc":[{"batb":[[0,2.14,10],[1,2.12,36.06],[2,1.81,36.34]],"ltp":2.22,"tv":30.42,"id":58385184}]}]}
{"op":"mcm","clk":"11810724461","pt":1722749084889,"mc":[{"id":"1.231395388","rc":[{"batb":[[0,2.12,36.06],[1,1.81,36.34],[2,1.25,100]],"ltp":2.22,"tv":30.42,"id":58385184}]}]}
{"op":"mcm","clk":"11810724516","pt":1722749087012,"mc":[{"id":"1.231395388","rc":[{"batb":[[0,2.14,10],[1,2.12,36.06],[2,1.81,36.34]],"ltp":2.22,"tv":30.42,"id":58385184}]}]}
{"op":"mcm","clk":"11810724605","pt":1722749090198,"mc":[{"id":"1.231395388","rc":[{"batb":[[0,2.12,36.06],[1,1.81,36.34],[2,1.25,100]],"ltp":2.22,"tv":30.42,"id":58385184}]}]}
{"op":"mcm","clk":"11810724717","pt":1722749093816,"mc":[{"id":"1.231395388","rc":[{"batb":[[0,2.14,10],[1,2.12,36.06],[2,1.81,36.34]],"ltp":2.22,"tv":30.42,"id":58385184}]}]}
{"op":"mcm","clk":"11810724803","pt":1722749097243,"mc":[{"id":"1.231395388","rc":[{"batb":[[0,2.12,36.06],[1,1.81,36.34],[2,1.25,100]],"ltp":2.22,"tv":30.42,"id":58385184}]}]}
{"op":"mcm","clk":"11810724880","pt":1722749100220,"mc":[{"id":"1.231395388","rc":[{"batb":[[0,2.14,10],[1,2.12,36.06],[2,1.81,36.34]],"ltp":2.22,"tv":30.42,"id":58385184}]}]}
{"op":"mcm","clk":"11810724974","pt":1722749103543,"mc":[{"id":"1.231395388","rc":[{"batb":[[0,2.12,36.06],[1,1.81,36.34],[2,1.25,100]],"ltp":2.22,"tv":30.42,"id":58385184}]}]}
{"op":"mcm","clk":"11810725034","pt":1722749105745,"mc":[{"id":"1.231395388","rc":[{"batb":[[0,2.14,10],[1,2.12,36.06],[2,1.81,36.34]],"ltp":2.22,"tv":30.42,"id":58385184}]}]}
{"op":"mcm","clk":"11810725106","pt":1722749109144,"mc":[{"id":"1.231395388","rc":[{"batb":[[0,2.12,36.06],[1,1.81,36.34],[2,1.25,100]],"ltp":2.22,"tv":30.42,"id":58385184}]}]}
{"op":"mcm","clk":"11810725179","pt":1722749111822,"mc":[{"id":"1.231395388","rc":[{"batb":[[0,2.14,10],[1,2.12,36.06],[2,1.81,36.34]],"ltp":2.22,"tv":30.42,"id":58385184}]}]}
{"op":"mcm","clk":"11810725280","pt":1722749115262,"mc":[{"id":"1.231395388","rc":[{"batb":[[0,2.12,36.06],[1,1.81,36.34],[2,1.25,100]],"ltp":2.22,"tv":30.42,"id":58385184}]}]}
{"op":"mcm","clk":"11810725372","pt":1722749118559,"mc":[{"id":"1.231395388","rc":[{"batb":[[0,2.14,10],[1,2.12,36.06],[2,1.81,36.34]],"ltp":2.22,"tv":30.42,"id":58385184}]}]}
{"op":"mcm","clk":"11810725472","pt":1722749121955,"mc":[{"id":"1.231395388","rc":[{"batb":[[0,2.12,36.06],[1,1.81,36.34],[2,1.25,100]],"ltp":2.22,"tv":30.42,"id":58385184}]}]}
{"op":"mcm","clk":"11810725554","pt":1722749124947,"mc":[{"id":"1.231395388","rc":[{"batb":[[0,2.14,10],[1,2.12,36.06],[2,1.81,36.34]],"ltp":2.22,"tv":30.42,"id":58385184}]}]}
{"op":"mcm","clk":"11810725643","pt":1722749128385,"mc":[{"id":"1.231395388","rc":[{"batb":[[0,2.12,36.06],[1,1.81,36.34],[2,1.25,100]],"ltp":2.22,"tv":30.42,"id":58385184}]}]}
{"op":"mcm","clk":"11810725730","pt":1722749131676,"mc":[{"id":"1.231395388","rc":[{"batb":[[0,2.14,10],[1,2.12,36.06],[2,1.81,36.34]],"ltp":2.22,"tv":30.42,"id":58385184}]}]}
{"op":"mcm","clk":"11810725826","pt":1722749135064,"mc":[{"id":"1.231395388","rc":[{"batb":[[0,2.12,36.06],[1,1.81,36.34],[2,1.25,100]],"ltp":2.22,"tv":30.42,"id":58385184}]}]}
{"op":"mcm","clk":"11810725917","pt":1722749139379,"mc":[{"id":"1.231395388","rc":[{"batb":[[0,2.14,10],[1,2.12,36.06],[2,1.81,36.34]],"ltp":2.22,"tv":30.42,"id":58385184}]}]}
{"op":"mcm","clk":"11810726010","pt":1722749142788,"mc":[{"id":"1.231395388","rc":[{"batb":[[0,2.12,36.06],[1,1.81,36.34],[2,1.25,100]],"ltp":2.22,"tv":30.42,"id":58385184}]}]}
{"op":"mcm","clk":"11810726106","pt":1722749145274,"mc":[{"id":"1.231395388","rc":[{"batb":[[0,2.14,10],[1,2.12,36.06],[2,1.81,36.34]],"ltp":2.22,"tv":30.42,"id":58385184}]}]}
{"op":"mcm","clk":"11810726220","pt":1722749148470,"mc":[{"id":"1.231395388","rc":[{"batb":[[0,2.12,36.06],[1,1.81,36.34],[2,1.25,100]],"ltp":2.22,"tv":30.42,"id":58385184}]}]}
{"op":"mcm","clk":"11810726296","pt":1722749151097,"mc":[{"id":"1.231395388","rc":[{"batb":[[0,2.14,10],[1,2.12,36.06],[2,1.81,36.34]],"ltp":2.22,"tv":30.42,"id":58385184}]}]}
{"op":"mcm","clk":"11810726402","pt":1722749154492,"mc":[{"id":"1.231395388","rc":[{"batb":[[0,2.12,36.06],[1,1.81,36.34],[2,1.25,100]],"ltp":2.22,"tv":30.42,"id":58385184}]}]}
{"op":"mcm","clk":"11810726435","pt":1722749156798,"mc":[{"id":"1.231395388","rc":[{"batb":[[0,2.14,10],[1,2.12,36.06],[2,1.81,36.34]],"ltp":2.22,"tv":30.42,"id":58385184}]}]}
{"op":"mcm","clk":"11810726533","pt":1722749160027,"mc":[{"id":"1.231395388","rc":[{"batb":[[0,2.12,36.06],[1,1.81,36.34],[2,1.25,100]],"ltp":2.22,"tv":30.42,"id":58385184}]}]}
{"op":"mcm","clk":"11810726707","pt":1722749162202,"mc":[{"id":"1.231395388","rc":[{"batb":[[0,2.14,10],[1,2.12,36.06],[2,1.81,36.34]],"ltp":2.22,"tv":30.42,"id":58385184}]}]}
{"op":"mcm","clk":"11810726890","pt":1722749165496,"mc":[{"id":"1.231395388","rc":[{"batb":[[0,2.12,36.06],[1,1.81,36.34],[2,1.25,100]],"ltp":2.22,"tv":30.42,"id":58385184}]}]}
{"op":"mcm","clk":"11810727008","pt":1722749170430,"mc":[{"id":"1.231395388","rc":[{"batb":[[0,2.14,10],[1,2.12,36.06],[2,1.81,36.34]],"ltp":2.22,"tv":30.42,"id":58385184}]}]}
{"op":"mcm","clk":"11810727096","pt":1722749173926,"mc":[{"id":"1.231395388","rc":[{"batb":[[0,2.12,36.06],[1,1.81,36.34],[2,1.25,100]],"ltp":2.22,"tv":30.42,"id":58385184}]}]}
{"op":"mcm","clk":"11810727195","pt":1722749177239,"mc":[{"id":"1.231395388","rc":[{"batb":[[0,2.14,10],[1,2.12,36.06],[2,1.81,36.34]],"ltp":2.22,"tv":30.42,"id":58385184}]}]}
{"op":"mcm","clk":"11810727278","pt":1722749180636,"mc":[{"id":"1.231395388","rc":[{"batb":[[0,2.12,36.06],[1,1.81,36.34],[2,1.25,100]],"ltp":2.22,"tv":30.42,"id":58385184}]}]}
{"op":"mcm","clk":"11810727324","pt":1722749182954,"mc":[{"id":"1.231395388","rc":[{"batb":[[0,2.14,10],[1,2.12,36.06],[2,1.81,36.34]],"ltp":2.22,"tv":30.42,"id":58385184}]}]}
{"op":"mcm","clk":"11810727414","pt":1722749186326,"mc":[{"id":"1.231395388","rc":[{"batb":[[0,2.12,36.06],[1,1.81,36.34],[2,1.25,100]],"ltp":2.22,"tv":30.42,"id":58385184}]}]}
{"op":"mcm","clk":"11810727464","pt":1722749188524,"mc":[{"id":"1.231395388","rc":[{"batb":[[0,2.14,10],[1,2.12,36.06],[2,1.81,36.34]],"ltp":2.22,"tv":30.42,"id":58385184}]}]}
{"op":"mcm","clk":"11810727551","pt":1722749192067,"mc":[{"id":"1.231395388","rc":[{"batb":[[0,2.12,36.06],[1,1.81,36.34],[2,1.25,100]],"ltp":2.22,"tv":30.42,"id":58385184}]}]}
{"op":"mcm","clk":"11810727709","pt":1722749197626,"mc":[{"id":"1.231395388","rc":[{"batb":[[0,2.14,10],[1,2.12,36.06],[2,1.81,36.34]],"ltp":2.22,"tv":30.42,"id":58385184}]}]}
{"op":"mcm","clk":"11810727785","pt":1722749200778,"mc":[{"id":"1.231395388","rc":[{"batb":[[0,2.12,36.06],[1,1.81,36.34],[2,1.25,100]],"ltp":2.22,"tv":30.42,"id":58385184}]}]}
{"op":"mcm","clk":"11810727851","pt":1722749202969,"mc":[{"id":"1.231395388","rc":[{"batb":[[0,2.14,10],[1,2.12,36.06],[2,1.81,36.34]],"ltp":2.22,"tv":30.42,"id":58385184}]}]}
{"op":"mcm","clk":"11810727926","pt":1722749206266,"mc":[{"id":"1.231395388","rc":[{"batb":[[0,2.12,36.06],[1,1.81,36.34],[2,1.25,100]],"ltp":2.22,"tv":30.42,"id":58385184}]}]}
{"op":"mcm","clk":"11810727979","pt":1722749208990,"mc":[{"id":"1.231395388","rc":[{"batb":[[0,2.14,10],[1,2.12,36.06],[2,1.81,36.34]],"ltp":2.22,"tv":30.42,"id":58385184}]}]}
{"op":"mcm","clk":"11810728070","pt":1722749212255,"mc":[{"id":"1.231395388","rc":[{"batb":[[0,2.12,36.06],[1,1.81,36.34],[2,1.25,100]],"ltp":2.22,"tv":30.42,"id":58385184}]}]}
{"op":"mcm","clk":"11810728150","pt":1722749215663,"mc":[{"id":"1.231395388","rc":[{"batb":[[0,2.14,10],[1,2.12,36.06],[2,1.81,36.34]],"ltp":2.22,"tv":30.42,"id":58385184}]}]}
{"op":"mcm","clk":"11810728244","pt":1722749218906,"mc":[{"id":"1.231395388","rc":[{"batb":[[0,2.12,36.06],[1,1.81,36.34],[2,1.25,100]],"ltp":2.22,"tv":30.42,"id":58385184}]}]}
{"op":"mcm","clk":"11810728328","pt":1722749221390,"mc":[{"id":"1.231395388","rc":[{"batb":[[0,2.14,10],[1,2.12,36.06],[2,1.81,36.34]],"ltp":2.22,"tv":30.42,"id":58385184}]}]}
{"op":"mcm","clk":"11810728403","pt":1722749224904,"mc":[{"id":"1.231395388","rc":[{"batb":[[0,2.12,36.06],[1,1.81,36.34],[2,1.25,100]],"ltp":2.22,"tv":30.42,"id":58385184}]}]}
{"op":"mcm","clk":"11810728454","pt":1722749227379,"mc":[{"id":"1.231395388","rc":[{"batb":[[0,2.14,10],[1,2.12,36.06],[2,1.81,36.34]],"ltp":2.22,"tv":30.42,"id":58385184}]}]}
{"op":"mcm","clk":"11810728526","pt":1722749230781,"mc":[{"id":"1.231395388","rc":[{"batb":[[0,2.12,36.06],[1,1.81,36.34],[2,1.25,100]],"ltp":2.22,"tv":30.42,"id":58385184}]}]}
{"op":"mcm","clk":"11810728586","pt":1722749233097,"mc":[{"id":"1.231395388","rc":[{"batb":[[0,2.14,10],[1,2.12,36.06],[2,1.81,36.34]],"ltp":2.22,"tv":30.42,"id":58385184}]}]}
{"op":"mcm","clk":"11810728675","pt":1722749236494,"mc":[{"id":"1.231395388","rc":[{"batb":[[0,2.12,36.06],[1,1.81,36.34],[2,1.25,100]],"ltp":2.22,"tv":30.42,"id":58385184}]}]}
{"op":"mcm","clk":"11810728750","pt":1722749238808,"mc":[{"id":"1.231395388","rc":[{"batb":[[0,2.14,10],[1,2.12,36.06],[2,1.81,36.34]],"ltp":2.22,"tv":30.42,"id":58385184}]}]}
{"op":"mcm","clk":"11810728848","pt":1722749242302,"mc":[{"id":"1.231395388","rc":[{"batb":[[0,2.12,36.06],[1,1.81,36.34],[2,1.25,100]],"ltp":2.22,"tv":30.42,"id":58385184}]}]}
{"op":"mcm","clk":"11810728939","pt":1722749245821,"mc":[{"id":"1.231395388","rc":[{"batb":[[0,2.14,10],[1,2.12,36.06],[2,1.81,36.34]],"ltp":2.22,"tv":30.42,"id":58385184}]}]}
{"op":"mcm","clk":"11810729006","pt":1722749249219,"mc":[{"id":"1.231395388","rc":[{"batb":[[0,2.12,36.06],[1,1.81,36.34],[2,1.25,100]],"ltp":2.22,"tv":30.42,"id":58385184}]}]}
{"op":"mcm","clk":"11810729063","pt":1722749251728,"mc":[{"id":"1.231395388","rc":[{"batb":[[0,2.14,10],[1,2.12,36.06],[2,1.81,36.34]],"ltp":2.22,"tv":30.42,"id":58385184}]}]}
{"op":"mcm","clk":"11810729125","pt":1722749255104,"mc":[{"id":"1.231395388","rc":[{"batb":[[0,2.12,36.06],[1,1.81,36.34],[2,1.25,100]],"ltp":2.22,"tv":30.42,"id":58385184}]}]}
{"op":"mcm","clk":"11810729232","pt":1722749259414,"mc":[{"id":"1.231395388","rc":[{"batb":[[0,2.14,10],[1,2.12,36.06],[2,1.81,36.34]],"ltp":2.22,"tv":30.42,"id":58385184}]}]}
{"op":"mcm","clk":"11810729281","pt":1722749262845,"mc":[{"id":"1.231395388","rc":[{"batb":[[0,2.12,36.06],[1,1.81,36.34],[2,1.25,100]],"ltp":2.22,"tv":30.42,"id":58385184}]}]}
{"op":"mcm","clk":"11810729337","pt":1722749265307,"mc":[{"id":"1.231395388","rc":[{"batb":[[0,2.14,10],[1,2.12,36.06],[2,1.81,36.34]],"ltp":2.22,"tv":30.42,"id":58385184}]}]}
{"op":"mcm","clk":"11810729391","pt":1722749268533,"mc":[{"id":"1.231395388","rc":[{"batb":[[0,2.12,36.06],[1,1.81,36.34],[2,1.25,100]],"ltp":2.22,"tv":30.42,"id":58385184}]}]}
{"op":"mcm","clk":"11810729457","pt":1722749271656,"mc":[{"id":"1.231395388","rc":[{"batb":[[0,2.14,10],[1,2.12,36.06],[2,1.81,36.34]],"ltp":2.22,"tv":30.42,"id":58385184}]}]}
{"op":"mcm","clk":"11810729520","pt":1722749275056,"mc":[{"id":"1.231395388","rc":[{"batb":[[0,2.12,36.06],[1,1.81,36.34],[2,1.25,100]],"ltp":2.22,"tv":30.42,"id":58385184}]}]}
{"op":"mcm","clk":"11810729564","pt":1722749277463,"mc":[{"id":"1.231395388","rc":[{"batb":[[0,2.14,10],[1,2.12,36.06],[2,1.81,36.34]],"ltp":2.22,"tv":30.42,"id":58385184}]}]}
{"op":"mcm","clk":"11810729630","pt":1722749280855,"mc":[{"id":"1.231395388","rc":[{"batb":[[0,2.12,36.06],[1,1.81,36.34],[2,1.25,100]],"ltp":2.22,"tv":30.42,"id":58385184}]}]}
{"op":"mcm","clk":"11810729654","pt":1722749283060,"mc":[{"id":"1.231395388","rc":[{"batb":[[0,2.14,10],[1,2.12,36.06],[2,1.81,36.34]],"ltp":2.22,"tv":30.42,"id":58385184}]}]}
{"op":"mcm","clk":"11810729713","pt":1722749286445,"mc":[{"id":"1.231395388","rc":[{"batb":[[0,2.12,36.06],[1,1.81,36.34],[2,1.25,100]],"ltp":2.22,"tv":30.42,"id":58385184}]}]}
{"op":"mcm","clk":"11810729761","pt":1722749289534,"mc":[{"id":"1.231395388","rc":[{"batb":[[0,2.14,10],[1,2.12,36.06],[2,1.81,36.34]],"ltp":2.22,"tv":30.42,"id":58385184}]}]}
{"op":"mcm","clk":"11810729807","pt":1722749292971,"mc":[{"id":"1.231395388","rc":[{"batb":[[0,2.12,36.06],[1,1.81,36.34],[2,1.25,100]],"ltp":2.22,"tv":30.42,"id":58385184}]}]}
{"op":"mcm","clk":"11810729860","pt":1722749296057,"mc":[{"id":"1.231395388","rc":[{"batb":[[0,2.14,10],[1,2.12,36.06],[2,1.81,36.34]],"ltp":2.22,"tv":30.42,"id":58385184}]}]}
{"op":"mcm","clk":"11810729916","pt":1722749299552,"mc":[{"id":"1.231395388","rc":[{"batb":[[0,2.12,36.06],[1,1.81,36.34],[2,1.25,100]],"ltp":2.22,"tv":30.42,"id":58385184}]}]}
{"op":"mcm","clk":"11810730003","pt":1722749303247,"mc":[{"id":"1.231395388","rc":[{"batb":[[0,2.14,10],[1,2.12,36.06],[2,1.81,36.34]],"ltp":2.22,"tv":30.42,"id":58385184}]}]}
{"op":"mcm","clk":"11810730078","pt":1722749306681,"mc":[{"id":"1.231395388","rc":[{"batb":[[0,2.12,36.06],[1,1.81,36.34],[2,1.25,100]],"ltp":2.22,"tv":30.42,"id":58385184}]}]}
{"op":"mcm","clk":"11810730156","pt":1722749309346,"mc":[{"id":"1.231395388","rc":[{"batb":[[0,2.14,10],[1,2.12,36.06],[2,1.81,36.34]],"ltp":2.22,"tv":30.42,"id":58385184}]}]}
{"op":"mcm","clk":"11810730231","pt":1722749312788,"mc":[{"id":"1.231395388","rc":[{"batb":[[0,2.12,36.06],[1,1.81,36.34],[2,1.25,100]],"ltp":2.22,"tv":30.42,"id":58385184}]}]}
{"op":"mcm","clk":"11810730266","pt":1722749315094,"mc":[{"id":"1.231395388","rc":[{"batb":[[0,2.14,10],[1,2.12,36.06],[2,1.81,36.34]],"ltp":2.22,"tv":30.42,"id":58385184}]}]}
{"op":"mcm","clk":"11810730319","pt":1722749318378,"mc":[{"id":"1.231395388","rc":[{"batb":[[0,2.12,36.06],[1,1.81,36.34],[2,1.25,100]],"ltp":2.22,"tv":30.42,"id":58385184}]}]}
{"op":"mcm","clk":"11810730353","pt":1722749320800,"mc":[{"id":"1.231395388","rc":[{"batb":[[0,2.14,10],[1,2.12,36.06],[2,1.81,36.34]],"ltp":2.22,"tv":30.42,"id":58385184}]}]}
{"op":"mcm","clk":"11810730402","pt":1722749324080,"mc":[{"id":"1.231395388","rc":[{"batb":[[0,2.12,36.06],[1,1.81,36.34],[2,1.25,100]],"ltp":2.22,"tv":30.42,"id":58385184}]}]}
{"op":"mcm","clk":"11810730451","pt":1722749326808,"mc":[{"id":"1.231395388","rc":[{"batb":[[0,2.14,10],[1,2.12,36.06],[2,1.81,36.34]],"ltp":2.22,"tv":30.42,"id":58385184}]}]}
{"op":"mcm","clk":"11810730535","pt":1722749330208,"mc":[{"id":"1.231395388","rc":[{"batb":[[0,2.12,36.06],[1,1.81,36.34],[2,1.25,100]],"ltp":2.22,"tv":30.42,"id":58385184}]}]}
{"op":"mcm","clk":"11810730587","pt":1722749332476,"mc":[{"id":"1.231395388","rc":[{"batb":[[0,2.14,10],[1,2.12,36.06],[2,1.81,36.34]],"ltp":2.22,"tv":30.42,"id":58385184}]}]}
{"op":"mcm","clk":"11810730665","pt":1722749335712,"mc":[{"id":"1.231395388","rc":[{"batb":[[0,2.12,36.06],[1,1.81,36.34],[2,1.25,100]],"ltp":2.22,"tv":30.42,"id":58385184}]}]}
{"op":"mcm","clk":"11810730710","pt":1722749338222,"mc":[{"id":"1.231395388","rc":[{"batb":[[0,2.14,10],[1,2.12,36.06],[2,1.81,36.34]],"ltp":2.22,"tv":30.42,"id":58385184}]}]}
{"op":"mcm","clk":"11810730782","pt":1722749341412,"mc":[{"id":"1.231395388","rc":[{"batb":[[0,2.12,36.06],[1,1.81,36.34],[2,1.25,100]],"ltp":2.22,"tv":30.42,"id":58385184}]}]}
{"op":"mcm","clk":"11810730829","pt":1722749344593,"mc":[{"id":"1.231395388","rc":[{"batb":[[0,2.14,10],[1,2.12,36.06],[2,1.81,36.34]],"ltp":2.22,"tv":30.42,"id":58385184}]}]}
{"op":"mcm","clk":"11810730893","pt":1722749348024,"mc":[{"id":"1.231395388","rc":[{"batb":[[0,2.12,36.06],[1,1.81,36.34],[2,1.25,100]],"ltp":2.22,"tv":30.42,"id":58385184}]}]}
{"op":"mcm","clk":"11810730951","pt":1722749352125,"mc":[{"id":"1.231395388","rc":[{"batb":[[0,2.14,10],[1,2.12,36.06],[2,1.81,36.34]],"ltp":2.22,"tv":30.42,"id":58385184}]}]}
{"op":"mcm","clk":"11810731027","pt":1722749355511,"mc":[{"id":"1.231395388","rc":[{"batb":[[0,2.12,36.06],[1,1.81,36.34],[2,1.25,100]],"ltp":2.22,"tv":30.42,"id":58385184}]}]}
{"op":"mcm","clk":"11810731158","pt":1722749361411,"mc":[{"id":"1.231395388","rc":[{"batb":[[0,2.14,10],[1,2.12,36.06],[2,1.81,36.34]],"ltp":2.22,"tv":30.42,"id":58385184}]}]}
{"op":"mcm","clk":"11810731249","pt":1722749364838,"mc":[{"id":"1.231395388","rc":[{"batb":[[0,2.12,36.06],[1,1.81,36.34],[2,1.25,100]],"ltp":2.22,"tv":30.42,"id":58385184}]}]}
{"op":"mcm","clk":"11810731293","pt":1722749367240,"mc":[{"id":"1.231395388","rc":[{"batb":[[0,2.14,10],[1,2.12,36.06],[2,1.81,36.34]],"ltp":2.22,"tv":30.42,"id":58385184}]}]}
{"op":"mcm","clk":"11810731370","pt":1722749370735,"mc":[{"id":"1.231395388","rc":[{"batb":[[0,2.12,36.06],[1,1.81,36.34],[2,1.25,100]],"ltp":2.22,"tv":30.42,"id":58385184}]}]}
{"op":"mcm","clk":"11810731416","pt":1722749373242,"mc":[{"id":"1.231395388","rc":[{"batb":[[0,2.14,10],[1,2.12,36.06],[2,1.81,36.34]],"ltp":2.22,"tv":30.42,"id":58385184}]}]}
{"op":"mcm","clk":"11810731500","pt":1722749376630,"mc":[{"id":"1.231395388","rc":[{"batb":[[0,2.12,36.06],[1,1.81,36.34],[2,1.25,100]],"ltp":2.22,"tv":30.42,"id":58385184}]}]}
{"op":"mcm","clk":"11810731549","pt":1722749378842,"mc":[{"id":"1.231395388","rc":[{"batb":[[0,2.14,10],[1,2.12,36.06],[2,1.81,36.34]],"ltp":2.22,"tv":30.42,"id":58385184}]}]}
{"op":"mcm","clk":"11810731605","pt":1722749382242,"mc":[{"id":"1.231395388","rc":[{"batb":[[0,2.12,36.06],[1,1.81,36.34],[2,1.25,100]],"ltp":2.22,"tv":30.42,"id":58385184}]}]}
{"op":"mcm","clk":"11810731641","pt":1722749384333,"mc":[{"id":"1.231395388","rc":[{"batb":[[0,2.14,10],[1,2.12,36.06],[2,1.81,36.34]],"ltp":2.22,"tv":30.42,"id":58385184}]}]}
{"op":"mcm","clk":"11810731702","pt":1722749387538,"mc":[{"id":"1.231395388","rc":[{"batb":[[0,2.12,36.06],[1,1.81,36.34],[2,1.25,100]],"ltp":2.22,"tv":30.42,"id":58385184}]}]}
{"op":"mcm","clk":"11810731732","pt":1722749389749,"mc":[{"id":"1.231395388","rc":[{"batb":[[0,2.14,10],[1,2.12,36.06],[2,1.81,36.34]],"ltp":2.22,"tv":30.42,"id":58385184}]}]}
{"op":"mcm","clk":"11810731813","pt":1722749393144,"mc":[{"id":"1.231395388","rc":[{"batb":[[0,2.12,36.06],[1,1.81,36.34],[2,1.25,100]],"ltp":2.22,"tv":30.42,"id":58385184}]}]}
{"op":"mcm","clk":"11810731880","pt":1722749396580,"mc":[{"id":"1.231395388","rc":[{"batb":[[0,2.14,10],[1,2.12,36.06],[2,1.81,36.34]],"ltp":2.22,"tv":30.42,"id":58385184}]}]}
{"op":"mcm","clk":"11810731940","pt":1722749399979,"mc":[{"id":"1.231395388","rc":[{"batb":[[0,2.12,36.06],[1,1.81,36.34],[2,1.25,100]],"ltp":2.22,"tv":30.42,"id":58385184}]}]}
{"op":"mcm","clk":"11810732006","pt":1722749402369,"mc":[{"id":"1.231395388","rc":[{"batb":[[0,2.14,10],[1,2.12,36.06],[2,1.81,36.34]],"ltp":2.22,"tv":30.42,"id":58385184}]}]}
{"op":"mcm","clk":"11810732073","pt":1722749405777,"mc":[{"id":"1.231395388","rc":[{"batb":[[0,2.12,36.06],[1,1.81,36.34],[2,1.25,100]],"ltp":2.22,"tv":30.42,"id":58385184}]}]}
{"op":"mcm","clk":"11810732155","pt":1722749410563,"mc":[{"id":"1.231395388","rc":[{"batb":[[0,2.14,10],[1,2.12,36.06],[2,1.81,36.34]],"ltp":2.22,"tv":30.42,"id":58385184}]}]}
{"op":"mcm","clk":"11810732212","pt":1722749413855,"mc":[{"id":"1.231395388","rc":[{"batb":[[0,2.12,36.06],[1,1.81,36.34],[2,1.25,100]],"ltp":2.22,"tv":30.42,"id":58385184}]}]}
{"op":"mcm","clk":"11810732262","pt":1722749416069,"mc":[{"id":"1.231395388","rc":[{"batb":[[0,2.14,10],[1,2.12,36.06],[2,1.81,36.34]],"ltp":2.22,"tv":30.42,"id":58385184}]}]}
{"op":"mcm","clk":"11810732333","pt":1722749419500,"mc":[{"id":"1.231395388","rc":[{"batb":[[0,2.12,36.06],[1,1.81,36.34],[2,1.25,100]],"ltp":2.22,"tv":30.42,"id":58385184}]}]}
{"op":"mcm","clk":"11810732377","pt":1722749421910,"mc":[{"id":"1.231395388","rc":[{"batb":[[0,2.14,10],[1,2.12,36.06],[2,1.81,36.34]],"ltp":2.22,"tv":30.42,"id":58385184}]}]}
{"op":"mcm","clk":"11810732438","pt":1722749425299,"mc":[{"id":"1.231395388","rc":[{"batb":[[0,2.12,36.06],[1,1.81,36.34],[2,1.25,100]],"ltp":2.22,"tv":30.42,"id":58385184}]}]}
{"op":"mcm","clk":"11810732464","pt":1722749427505,"mc":[{"id":"1.231395388","rc":[{"batb":[[0,2.14,10],[1,2.12,36.06],[2,1.81,36.34]],"ltp":2.22,"tv":30.42,"id":58385184}]}]}
{"op":"mcm","clk":"11810732513","pt":1722749430786,"mc":[{"id":"1.231395388","rc":[{"batb":[[0,2.12,36.06],[1,1.81,36.34],[2,1.25,100]],"ltp":2.22,"tv":30.42,"id":58385184}]}]}
{"op":"mcm","clk":"11810732543","pt":1722749433103,"mc":[{"id":"1.231395388","rc":[{"batb":[[0,2.14,10],[1,2.12,36.06],[2,1.81,36.34]],"ltp":2.22,"tv":30.42,"id":58385184}]}]}
{"op":"mcm","clk":"11810732589","pt":1722749436397,"mc":[{"id":"1.231395388","rc":[{"batb":[[0,2.12,36.06],[1,1.81,36.34],[2,1.25,100]],"ltp":2.22,"tv":30.42,"id":58385184}]}]}
{"op":"mcm","clk":"11810732628","pt":1722749439027,"mc":[{"id":"1.231395388","rc":[{"batb":[[0,2.14,10],[1,2.12,36.06],[2,1.81,36.34]],"ltp":2.22,"tv":30.42,"id":58385184}]}]}
{"op":"mcm","clk":"11810732678","pt":1722749442530,"mc":[{"id":"1.231395388","rc":[{"batb":[[0,2.12,36.06],[1,1.81,36.34],[2,1.25,100]],"ltp":2.22,"tv":30.42,"id":58385184}]}]}
{"op":"mcm","clk":"11810732725","pt":1722749444992,"mc":[{"id":"1.231395388","rc":[{"batb":[[0,2.14,10],[1,2.12,36.06],[2,1.81,36.34]],"ltp":2.22,"tv":30.42,"id":58385184}]}]}
{"op":"mcm","clk":"11810732791","pt":1722749448523,"mc":[{"id":"1.231395388","rc":[{"batb":[[0,2.12,36.06],[1,1.81,36.34],[2,1.25,100]],"ltp":2.22,"tv":30.42,"id":58385184}]}]}
{"op":"mcm","clk":"11810732893","pt":1722749451822,"mc":[{"id":"1.231395388","rc":[{"batb":[[0,2.14,10],[1,2.12,36.06],[2,1.81,36.34]],"ltp":2.22,"tv":30.42,"id":58385184}]}]}
{"op":"mcm","clk":"11810732958","pt":1722749455215,"mc":[{"id":"1.231395388","rc":[{"batb":[[0,2.12,36.06],[1,1.81,36.34],[2,1.25,100]],"ltp":2.22,"tv":30.42,"id":58385184}]}]}
{"op":"mcm","clk":"11810733143","pt":1722749460651,"mc":[{"id":"1.231395388","rc":[{"batb":[[0,2.14,10],[1,2.12,36.06],[2,1.81,36.34]],"ltp":2.22,"tv":30.42,"id":58385184}]}]}
{"op":"mcm","clk":"11810733216","pt":1722749464028,"mc":[{"id":"1.231395388","rc":[{"batb":[[0,2.12,36.06],[1,1.81,36.34],[2,1.25,100]],"ltp":2.22,"tv":30.42,"id":58385184}]}]}
{"op":"mcm","clk":"11810733271","pt":1722749466341,"mc":[{"id":"1.231395388","rc":[{"batb":[[0,2.14,10],[1,2.12,36.06],[2,1.81,36.34]],"ltp":2.22,"tv":30.42,"id":58385184}]}]}
{"op":"mcm","clk":"11810733362","pt":1722749469750,"mc":[{"id":"1.231395388","rc":[{"batb":[[0,2.12,36.06],[1,1.81,36.34],[2,1.25,100]],"ltp":2.22,"tv":30.42,"id":58385184}]}]}
{"op":"mcm","clk":"11810733412","pt":1722749471957,"mc":[{"id":"1.231395388","rc":[{"batb":[[0,2.14,10],[1,2.12,36.06],[2,1.81,36.34]],"ltp":2.22,"tv":30.42,"id":58385184}]}]}
{"op":"mcm","clk":"11810733498","pt":1722749475452,"mc":[{"id":"1.231395388","rc":[{"batb":[[0,2.12,36.06],[1,1.81,36.34],[2,1.25,100]],"ltp":2.22,"tv":30.42,"id":58385184}]}]}
{"op":"mcm","clk":"11810733546","pt":1722749478734,"mc":[{"id":"1.231395388","rc":[{"batb":[[0,2.14,10],[1,2.12,36.06],[2,1.81,36.34]],"ltp":2.22,"tv":30.42,"id":58385184}]}]}
{"op":"mcm","clk":"11810733640","pt":1722749482138,"mc":[{"id":"1.231395388","rc":[{"batb":[[0,2.12,36.06],[1,1.81,36.34],[2,1.25,100]],"ltp":2.22,"tv":30.42,"id":58385184}]}]}
{"op":"mcm","clk":"11810733692","pt":1722749484655,"mc":[{"id":"1.231395388","rc":[{"batb":[[0,2.14,10],[1,2.12,36.06],[2,1.81,36.34]],"ltp":2.22,"tv":30.42,"id":58385184}]}]}
{"op":"mcm","clk":"11810733742","pt":1722749488038,"mc":[{"id":"1.231395388","rc":[{"batb":[[0,2.12,36.06],[1,1.81,36.34],[2,1.25,100]],"ltp":2.22,"tv":30.42,"id":58385184}]}]}
{"op":"mcm","clk":"11810733803","pt":1722749491676,"mc":[{"id":"1.231395388","rc":[{"batb":[[0,2.14,10],[1,2.12,36.06],[2,1.81,36.34]],"ltp":2.22,"tv":30.42,"id":58385184}]}]}
{"op":"mcm","clk":"11810733865","pt":1722749494880,"mc":[{"id":"1.231395388","rc":[{"batb":[[0,2.12,36.06],[1,1.81,36.34],[2,1.25,100]],"ltp":2.22,"tv":30.42,"id":58385184}]}]}
{"op":"mcm","clk":"11810733917","pt":1722749497364,"mc":[{"id":"1.231395388","rc":[{"batb":[[0,2.14,10],[1,2.12,36.06],[2,1.81,36.34]],"ltp":2.22,"tv":30.42,"id":58385184}]}]}
{"op":"mcm","clk":"11810733997","pt":1722749500798,"mc":[{"id":"1.231395388","rc":[{"batb":[[0,2.12,36.06],[1,1.81,36.34],[2,1.25,100]],"ltp":2.22,"tv":30.42,"id":58385184}]}]}
{"op":"mcm","clk":"11810734057","pt":1722749503162,"mc":[{"id":"1.231395388","rc":[{"batb":[[0,2.14,10],[1,2.12,36.06],[2,1.81,36.34]],"ltp":2.22,"tv":30.42,"id":58385184}]}]}
{"op":"mcm","clk":"11810734136","pt":1722749506764,"mc":[{"id":"1.231395388","rc":[{"batb":[[0,2.12,36.06],[1,1.81,36.34],[2,1.25,100]],"ltp":2.22,"tv":30.42,"id":58385184}]}]}
{"op":"mcm","clk":"11810734197","pt":1722749509892,"mc":[{"id":"1.231395388","rc":[{"batb":[[0,2.14,10],[1,2.12,36.06],[2,1.81,36.34]],"ltp":2.22,"tv":30.42,"id":58385184}]}]}
{"op":"mcm","clk":"11810734252","pt":1722749513078,"mc":[{"id":"1.231395388","rc":[{"batb":[[0,2.12,36.06],[1,1.81,36.34],[2,1.25,100]],"ltp":2.22,"tv":30.42,"id":58385184}]}]}
{"op":"mcm","clk":"11810734353","pt":1722749517186,"mc":[{"id":"1.231395388","rc":[{"batb":[[0,2.14,10],[1,2.12,36.06],[2,1.81,36.34]],"ltp":2.22,"tv":30.42,"id":58385184}]}]}
{"op":"mcm","clk":"11810734423","pt":1722749520615,"mc":[{"id":"1.231395388","rc":[{"batb":[[0,2.12,36.06],[1,1.81,36.34],[2,1.25,100]],"ltp":2.22,"tv":30.42,"id":58385184}]}]}
{"op":"mcm","clk":"11810734551","pt":1722749525199,"mc":[{"id":"1.231395388","rc":[{"batb":[[0,2.14,10],[1,2.12,36.06],[2,1.81,36.34]],"ltp":2.22,"tv":30.42,"id":58385184}]}]}
{"op":"mcm","clk":"11810734630","pt":1722749528791,"mc":[{"id":"1.231395388","rc":[{"batb":[[0,2.12,36.06],[1,1.81,36.34],[2,1.25,100]],"ltp":2.22,"tv":30.42,"id":58385184}]}]}
{"op":"mcm","clk":"11810734703","pt":1722749532024,"mc":[{"id":"1.231395388","rc":[{"batb":[[0,2.14,10],[1,2.12,36.06],[2,1.81,36.34]],"ltp":2.22,"tv":30.42,"id":58385184}]}]}
{"op":"mcm","clk":"11810734780","pt":1722749535409,"mc":[{"id":"1.231395388","rc":[{"batb":[[0,2.12,36.06],[1,1.81,36.34],[2,1.25,100]],"ltp":2.22,"tv":30.42,"id":58385184}]}]}
{"op":"mcm","clk":"11810734819","pt":1722749538122,"mc":[{"id":"1.231395388","rc":[{"batb":[[0,2.14,10],[1,2.12,36.06],[2,1.81,36.34]],"ltp":2.22,"tv":30.42,"id":58385184}]}]}
{"op":"mcm","clk":"11810734899","pt":1722749541411,"mc":[{"id":"1.231395388","rc":[{"batb":[[0,2.12,36.06],[1,1.81,36.34],[2,1.25,100]],"ltp":2.22,"tv":30.42,"id":58385184}]}]}
{"op":"mcm","clk":"11810734960","pt":1722749544042,"mc":[{"id":"1.231395388","rc":[{"batb":[[0,2.14,10],[1,2.12,36.06],[2,1.81,36.34]],"ltp":2.22,"tv":30.42,"id":58385184}]}]}
{"op":"mcm","clk":"11810735042","pt":1722749547532,"mc":[{"id":"1.231395388","rc":[{"batb":[[0,2.12,36.06],[1,1.81,36.34],[2,1.25,100]],"ltp":2.22,"tv":30.42,"id":58385184}]}]}
{"op":"mcm","clk":"11810735108","pt":1722749550423,"mc":[{"id":"1.231395388","rc":[{"batb":[[0,2.14,10],[1,2.12,36.06],[2,1.81,36.34]],"ltp":2.22,"tv":30.42,"id":58385184}]}]}
{"op":"mcm","clk":"11810735165","pt":1722749553647,"mc":[{"id":"1.231395388","rc":[{"batb":[[0,2.12,36.06],[1,1.81,36.34],[2,1.25,100]],"ltp":2.22,"tv":30.42,"id":58385184}]}]}
{"op":"mcm","clk":"11810735233","pt":1722749556012,"mc":[{"id":"1.231395388","rc":[{"batb":[[0,2.14,10],[1,2.12,36.06],[2,1.81,36.34]],"ltp":2.22,"tv":30.42,"id":58385184}]}]}
{"op":"mcm","clk":"11810735323","pt":1722749559548,"mc":[{"id":"1.231395388","rc":[{"batb":[[0,2.12,36.06],[1,1.81,36.34],[2,1.25,100]],"ltp":2.22,"tv":30.42,"id":58385184}]}]}
{"op":"mcm","clk":"11810735389","pt":1722749562841,"mc":[{"id":"1.231395388","rc":[{"batb":[[0,2.14,10],[1,2.12,36.06],[2,1.81,36.34]],"ltp":2.22,"tv":30.42,"id":58385184}]}]}
{"op":"mcm","clk":"11810735487","pt":1722749566226,"mc":[{"id":"1.231395388","rc":[{"batb":[[0,2.12,36.06],[1,1.81,36.34],[2,1.25,100]],"ltp":2.22,"tv":30.42,"id":58385184}]}]}
{"op":"mcm","clk":"11810735560","pt":1722749569658,"mc":[{"id":"1.231395388","rc":[{"batb":[[0,2.14,10],[1,2.12,36.06],[2,1.81,36.34]],"ltp":2.22,"tv":30.42,"id":58385184}]}]}
{"op":"mcm","clk":"11810735662","pt":1722749573063,"mc":[{"id":"1.231395388","rc":[{"batb":[[0,2.12,36.06],[1,1.81,36.34],[2,1.25,100]],"ltp":2.22,"tv":30.42,"id":58385184}]}]}
{"op":"mcm","clk":"11810735739","pt":1722749576352,"mc":[{"id":"1.231395388","rc":[{"batb":[[0,2.14,10],[1,2.12,36.06],[2,1.81,36.34]],"ltp":2.22,"tv":30.42,"id":58385184}]}]}
{"op":"mcm","clk":"11810735820","pt":1722749579776,"mc":[{"id":"1.231395388","rc":[{"batb":[[0,2.12,36.06],[1,1.81,36.34],[2,1.25,100]],"ltp":2.22,"tv":30.42,"id":58385184}]}]}
{"op":"mcm","clk":"11810735881","pt":1722749583159,"mc":[{"id":"1.231395388","rc":[{"batb":[[0,2.14,10],[1,2.12,36.06],[2,1.81,36.34]],"ltp":2.22,"tv":30.42,"id":58385184}]}]}
{"op":"mcm","clk":"11810735974","pt":1722749586338,"mc":[{"id":"1.231395388","rc":[{"batb":[[0,2.12,36.06],[1,1.81,36.34],[2,1.25,100]],"ltp":2.22,"tv":30.42,"id":58385184}]}]}
{"op":"mcm","clk":"11810736027","pt":1722749588443,"mc":[{"id":"1.231395388","rc":[{"batb":[[0,2.14,10],[1,2.12,36.06],[2,1.81,36.34]],"ltp":2.22,"tv":30.42,"id":58385184}]}]}
{"op":"mcm","clk":"11810736117","pt":1722749591659,"mc":[{"id":"1.231395388","rc":[{"batb":[[0,2.12,36.06],[1,1.81,36.34],[2,1.25,100]],"ltp":2.22,"tv":30.42,"id":58385184}]}]}
{"op":"mcm","clk":"11810736202","pt":1722749594187,"mc":[{"id":"1.231395388","rc":[{"batb":[[0,2.14,10],[1,2.12,36.06],[2,1.81,36.34]],"ltp":2.22,"tv":30.42,"id":58385184}]}]}
{"op":"mcm","clk":"11810736287","pt":1722749597579,"mc":[{"id":"1.231395388","rc":[{"batb":[[0,2.12,36.06],[1,1.81,36.34],[2,1.25,100]],"ltp":2.22,"tv":30.42,"id":58385184}]}]}
{"op":"mcm","clk":"11810736339","pt":1722749599983,"mc":[{"id":"1.231395388","rc":[{"batb":[[0,2.14,10],[1,2.12,36.06],[2,1.81,36.34]],"ltp":2.22,"tv":30.42,"id":58385184}]}]}
{"op":"mcm","clk":"11810736437","pt":1722749603375,"mc":[{"id":"1.231395388","rc":[{"batb":[[0,2.12,36.06],[1,1.81,36.34],[2,1.25,100]],"ltp":2.22,"tv":30.42,"id":58385184}]}]}
{"op":"mcm","clk":"11810736515","pt":1722749607370,"mc":[{"id":"1.231395388","rc":[{"batb":[[0,2.14,10],[1,2.12,36.06],[2,1.81,36.34]],"ltp":2.22,"tv":30.42,"id":58385184}]}]}
{"op":"mcm","clk":"11810736575","pt":1722749610773,"mc":[{"id":"1.231395388","rc":[{"batb":[[0,2.12,36.06],[1,1.81,36.34],[2,1.25,100]],"ltp":2.22,"tv":30.42,"id":58385184}]}]}
{"op":"mcm","clk":"11810736627","pt":1722749612889,"mc":[{"id":"1.231395388","rc":[{"batb":[[0,2.14,10],[1,2.12,36.06],[2,1.81,36.34]],"ltp":2.22,"tv":30.42,"id":58385184}]}]}
{"op":"mcm","clk":"11810736737","pt":1722749616396,"mc":[{"id":"1.231395388","rc":[{"batb":[[0,2.12,36.06],[1,1.81,36.34],[2,1.25,100]],"ltp":2.22,"tv":30.42,"id":58385184}]}]}
{"op":"mcm","clk":"11810736786","pt":1722749619011,"mc":[{"id":"1.231395388","rc":[{"batb":[[0,2.14,10],[1,2.12,36.06],[2,1.81,36.34]],"ltp":2.22,"tv":30.42,"id":58385184}]}]}
{"op":"mcm","clk":"11810736869","pt":1722749622421,"mc":[{"id":"1.231395388","rc":[{"batb":[[0,2.12,36.06],[1,1.81,36.34],[2,1.25,100]],"ltp":2.22,"tv":30.42,"id":58385184}]}]}
{"op":"mcm","clk":"11810736914","pt":1722749624600,"mc":[{"id":"1.231395388","rc":[{"batb":[[0,2.14,10],[1,2.12,36.06],[2,1.81,36.34]],"ltp":2.22,"tv":30.42,"id":58385184}]}]}
{"op":"mcm","clk":"11810737005","pt":1722749627999,"mc":[{"id":"1.231395388","rc":[{"batb":[[0,2.12,36.06],[1,1.81,36.34],[2,1.25,100]],"ltp":2.22,"tv":30.42,"id":58385184}]}]}
{"op":"mcm","clk":"11810737086","pt":1722749632106,"mc":[{"id":"1.231395388","rc":[{"batb":[[0,2.14,10],[1,2.12,36.06],[2,1.81,36.34]],"ltp":2.22,"tv":30.42,"id":58385184}]}]}
{"op":"mcm","clk":"11810737154","pt":1722749635492,"mc":[{"id":"1.231395388","rc":[{"batb":[[0,2.12,36.06],[1,1.81,36.34],[2,1.25,100]],"ltp":2.22,"tv":30.42,"id":58385184}]}]}
{"op":"mcm","clk":"11810737238","pt":1722749638143,"mc":[{"id":"1.231395388","rc":[{"batb":[[0,2.14,10],[1,2.12,36.06],[2,1.81,36.34]],"ltp":2.22,"tv":30.42,"id":58385184}]}]}
{"op":"mcm","clk":"11810737318","pt":1722749641649,"mc":[{"id":"1.231395388","rc":[{"batb":[[0,2.12,36.06],[1,1.81,36.34],[2,1.25,100]],"ltp":2.22,"tv":30.42,"id":58385184}]}]}
{"op":"mcm","clk":"11810737383","pt":1722749644121,"mc":[{"id":"1.231395388","rc":[{"batb":[[0,2.14,10],[1,2.12,36.06],[2,1.81,36.34]],"ltp":2.22,"tv":30.42,"id":58385184}]}]}
{"op":"mcm","clk":"11810737473","pt":1722749647422,"mc":[{"id":"1.231395388","rc":[{"batb":[[0,2.12,36.06],[1,1.81,36.34],[2,1.25,100]],"ltp":2.22,"tv":30.42,"id":58385184}]}]}
{"op":"mcm","clk":"11810737550","pt":1722749650839,"mc":[{"id":"1.231395388","rc":[{"batb":[[0,2.14,10],[1,2.12,36.06],[2,1.81,36.34]],"ltp":2.22,"tv":30.42,"id":58385184}]}]}
{"op":"mcm","clk":"11810737629","pt":1722749654332,"mc":[{"id":"1.231395388","rc":[{"batb":[[0,2.12,36.06],[1,1.81,36.34],[2,1.25,100]],"ltp":2.22,"tv":30.42,"id":58385184}]}]}
{"op":"mcm","clk":"11810737683","pt":1722749656648,"mc":[{"id":"1.231395388","rc":[{"batb":[[0,2.14,10],[1,2.12,36.06],[2,1.81,36.34]],"ltp":2.22,"tv":30.42,"id":58385184}]}]}
{"op":"mcm","clk":"11810737743","pt":1722749659857,"mc":[{"id":"1.231395388","rc":[{"batb":[[0,2.12,36.06],[1,1.81,36.34],[2,1.25,100]],"ltp":2.22,"tv":30.42,"id":58385184}]}]}
{"op":"mcm","clk":"11810737797","pt":1722749662843,"mc":[{"id":"1.231395388","rc":[{"batb":[[0,2.14,10],[1,2.12,36.06],[2,1.81,36.34]],"ltp":2.22,"tv":30.42,"id":58385184}]}]}
{"op":"mcm","clk":"11810737882","pt":1722749666148,"mc":[{"id":"1.231395388","rc":[{"batb":[[0,2.12,36.06],[1,1.81,36.34],[2,1.25,100]],"ltp":2.22,"tv":30.42,"id":58385184}]}]}
{"op":"mcm","clk":"11810737938","pt":1722749669025,"mc":[{"id":"1.231395388","rc":[{"batb":[[0,2.14,10],[1,2.12,36.06],[2,1.81,36.34]],"ltp":2.22,"tv":30.42,"id":58385184}]}]}
{"op":"mcm","clk":"11810737993","pt":1722749672563,"mc":[{"id":"1.231395388","rc":[{"batb":[[0,2.12,36.06],[1,1.81,36.34],[2,1.25,100]],"ltp":2.22,"tv":30.42,"id":58385184}]}]}
{"op":"mcm","clk":"11810738026","pt":1722749674852,"mc":[{"id":"1.231395388","rc":[{"batb":[[0,2.14,10],[1,2.12,36.06],[2,1.81,36.34]],"ltp":2.22,"tv":30.42,"id":58385184}]}]}
{"op":"mcm","clk":"11810738084","pt":1722749678278,"mc":[{"id":"1.231395388","rc":[{"batb":[[0,2.12,36.06],[1,1.81,36.34],[2,1.25,100]],"ltp":2.22,"tv":30.42,"id":58385184}]}]}
{"op":"mcm","clk":"11810738132","pt":1722749680856,"mc":[{"id":"1.231395388","rc":[{"batb":[[0,2.14,10],[1,2.12,36.06],[2,1.81,36.34]],"ltp":2.22,"tv":30.42,"id":58385184}]}]}
{"op":"mcm","clk":"11810738183","pt":1722749684248,"mc":[{"id":"1.231395388","rc":[{"batb":[[0,2.12,36.06],[1,1.81,36.34],[2,1.25,100]],"ltp":2.22,"tv":30.42,"id":58385184}]}]}
{"op":"mcm","clk":"11810738219","pt":1722749686782,"mc":[{"id":"1.231395388","rc":[{"batb":[[0,2.14,10],[1,2.12,36.06],[2,1.81,36.34]],"ltp":2.22,"tv":30.42,"id":58385184}]}]}
{"op":"mcm","clk":"11810738289","pt":1722749690289,"mc":[{"id":"1.231395388","rc":[{"batb":[[0,2.12,36.06],[1,1.81,36.34],[2,1.25,100]],"ltp":2.22,"tv":30.42,"id":58385184}]}]}
{"op":"mcm","clk":"11810738329","pt":1722749692396,"mc":[{"id":"1.231395388","rc":[{"batb":[[0,2.14,10],[1,2.12,36.06],[2,1.81,36.34]],"ltp":2.22,"tv":30.42,"id":58385184}]}]}
{"op":"mcm","clk":"11810738361","pt":1722749695890,"mc":[{"id":"1.231395388","rc":[{"batb":[[0,2.12,36.06],[1,1.81,36.34],[2,1.25,100]],"ltp":2.22,"tv":30.42,"id":58385184}]}]}
{"op":"mcm","clk":"11810738423","pt":1722749698764,"mc":[{"id":"1.231395388","rc":[{"batb":[[0,2.14,10],[1,2.12,36.06],[2,1.81,36.34]],"ltp":2.22,"tv":30.42,"id":58385184}]}]}
{"op":"mcm","clk":"11810738527","pt":1722749702293,"mc":[{"id":"1.231395388","rc":[{"batb":[[0,2.12,36.06],[1,1.81,36.34],[2,1.25,100]],"ltp":2.22,"tv":30.42,"id":58385184}]}]}
{"op":"mcm","clk":"11810738626","pt":1722749705713,"mc":[{"id":"1.231395388","rc":[{"batb":[[0,2.14,10],[1,2.12,36.06],[2,1.81,36.34]],"ltp":2.22,"tv":30.42,"id":58385184}]}]}
{"op":"mcm","clk":"11810738705","pt":1722749708984,"mc":[{"id":"1.231395388","rc":[{"batb":[[0,2.12,36.06],[1,1.81,36.34],[2,1.25,100]],"ltp":2.22,"tv":30.42,"id":58385184}]}]}
{"op":"mcm","clk":"11810738816","pt":1722749713513,"mc":[{"id":"1.231395388","rc":[{"batb":[[0,2.14,10],[1,2.12,36.06],[2,1.81,36.34]],"ltp":2.22,"tv":30.42,"id":58385184}]}]}
{"op":"mcm","clk":"11810738889","pt":1722749717002,"mc":[{"id":"1.231395388","rc":[{"batb":[[0,2.12,36.06],[1,1.81,36.34],[2,1.25,100]],"ltp":2.22,"tv":30.42,"id":58385184}]}]}
{"op":"mcm","clk":"11810738945","pt":1722749719579,"mc":[{"id":"1.231395388","rc":[{"batb":[[0,2.14,10],[1,2.12,36.06],[2,1.81,36.34]],"ltp":2.22,"tv":30.42,"id":58385184}]}]}
{"op":"mcm","clk":"11810739016","pt":1722749722987,"mc":[{"id":"1.231395388","rc":[{"batb":[[0,2.12,36.06],[1,1.81,36.34],[2,1.25,100]],"ltp":2.22,"tv":30.42,"id":58385184}]}]}
{"op":"mcm","clk":"11810739142","pt":1722749728693,"mc":[{"id":"1.231395388","rc":[{"batb":[[0,2.14,10],[1,2.12,36.06],[2,1.81,36.34]],"ltp":2.22,"tv":30.42,"id":58385184}]}]}
{"op":"mcm","clk":"11810739241","pt":1722749731931,"mc":[{"id":"1.231395388","rc":[{"batb":[[0,2.12,36.06],[1,1.81,36.34],[2,1.25,100]],"ltp":2.22,"tv":30.42,"id":58385184}]}]}
{"op":"mcm","clk":"11810739286","pt":1722749734332,"mc":[{"id":"1.231395388","rc":[{"batb":[[0,2.14,10],[1,2.12,36.06],[2,1.81,36.34]],"ltp":2.22,"tv":30.42,"id":58385184}]}]}
{"op":"mcm","clk":"11810739375","pt":1722749737843,"mc":[{"id":"1.231395388","rc":[{"batb":[[0,2.12,36.06],[1,1.81,36.34],[2,1.25,100]],"ltp":2.22,"tv":30.42,"id":58385184}]}]}
{"op":"mcm","clk":"11810739468","pt":1722749741134,"mc":[{"id":"1.231395388","rc":[{"batb":[[0,2.14,10],[1,2.12,36.06],[2,1.81,36.34]],"ltp":2.22,"tv":30.42,"id":58385184}]}]}
{"op":"mcm","clk":"11810739553","pt":1722749744625,"mc":[{"id":"1.231395388","rc":[{"batb":[[0,2.12,36.06],[1,1.81,36.34],[2,1.25,100]],"ltp":2.22,"tv":30.42,"id":58385184}]}]}
{"op":"mcm","clk":"11810739609","pt":1722749746832,"mc":[{"id":"1.231395388","rc":[{"batb":[[0,2.14,10],[1,2.12,36.06],[2,1.81,36.34]],"ltp":2.22,"tv":30.42,"id":58385184}]}]}
{"op":"mcm","clk":"11810739684","pt":1722749750185,"mc":[{"id":"1.231395388","rc":[{"batb":[[0,2.12,36.06],[1,1.81,36.34],[2,1.25,100]],"ltp":2.22,"tv":30.42,"id":58385184}]}]}
{"op":"mcm","clk":"11810739774","pt":1722749754224,"mc":[{"id":"1.231395388","rc":[{"batb":[[0,2.14,10],[1,2.12,36.06],[2,1.81,36.34]],"ltp":2.22,"tv":30.42,"id":58385184}]}]}
{"op":"mcm","clk":"11810739833","pt":1722749757663,"mc":[{"id":"1.231395388","rc":[{"batb":[[0,2.12,36.06],[1,1.81,36.34],[2,1.25,100]],"ltp":2.22,"tv":30.42,"id":58385184}]}]}
{"op":"mcm","clk":"11810739913","pt":1722749761573,"mc":[{"id":"1.231395388","rc":[{"batb":[[0,2.14,10],[1,2.12,36.06],[2,1.81,36.34]],"ltp":2.22,"tv":30.42,"id":58385184}]}]}
{"op":"mcm","clk":"11810739972","pt":1722749765068,"mc":[{"id":"1.231395388","rc":[{"batb":[[0,2.12,36.06],[1,1.81,36.34],[2,1.25,100]],"ltp":2.22,"tv":30.42,"id":58385184}]}]}
{"op":"mcm","clk":"11810740033","pt":1722749767377,"mc":[{"id":"1.231395388","rc":[{"batb":[[0,2.14,10],[1,2.12,36.06],[2,1.81,36.34]],"ltp":2.22,"tv":30.42,"id":58385184}]}]}
{"op":"mcm","clk":"11810740091","pt":1722749770967,"mc":[{"id":"1.231395388","rc":[{"batb":[[0,2.12,36.06],[1,1.81,36.34],[2,1.25,100]],"ltp":2.22,"tv":30.42,"id":58385184}]}]}
{"op":"mcm","clk":"11810740174","pt":1722749774151,"mc":[{"id":"1.231395388","rc":[{"batb":[[0,2.14,10],[1,2.12,36.06],[2,1.81,36.34]],"ltp":2.22,"tv":30.42,"id":58385184}]}]}
{"op":"mcm","clk":"11810740241","pt":1722749777398,"mc":[{"id":"1.231395388","rc":[{"batb":[[0,2.12,36.06],[1,1.81,36.34],[2,1.25,100]],"ltp":2.22,"tv":30.42,"id":58385184}]}]}
{"op":"mcm","clk":"11810740317","pt":1722749779582,"mc":[{"id":"1.231395388","rc":[{"batb":[[0,2.14,10],[1,2.12,36.06],[2,1.81,36.34]],"ltp":2.22,"tv":30.42,"id":58385184}]}]}
{"op":"mcm","clk":"11810740383","pt":1722749782869,"mc":[{"id":"1.231395388","rc":[{"batb":[[0,2.12,36.06],[1,1.81,36.34],[2,1.25,100]],"ltp":2.22,"tv":30.42,"id":58385184}]}]}
{"op":"mcm","clk":"11810740456","pt":1722749785182,"mc":[{"id":"1.231395388","rc":[{"batb":[[0,2.14,10],[1,2.12,36.06],[2,1.81,36.34]],"ltp":2.22,"tv":30.42,"id":58385184}]}]}
{"op":"mcm","clk":"11810740555","pt":1722749788670,"mc":[{"id":"1.231395388","rc":[{"batb":[[0,2.12,36.06],[1,1.81,36.34],[2,1.25,100]],"ltp":2.22,"tv":30.42,"id":58385184}]}]}
{"op":"mcm","clk":"11810740631","pt":1722749791611,"mc":[{"id":"1.231395388","rc":[{"batb":[[0,2.14,10],[1,2.12,36.06],[2,1.81,36.34]],"ltp":2.22,"tv":30.42,"id":58385184}]}]}
{"op":"mcm","clk":"11810740707","pt":1722749794814,"mc":[{"id":"1.231395388","rc":[{"batb":[[0,2.12,36.06],[1,1.81,36.34],[2,1.25,100]],"ltp":2.22,"tv":30.42,"id":58385184}]}]}
{"op":"mcm","clk":"11810740815","pt":1722749798518,"mc":[{"id":"1.231395388","rc":[{"batb":[[0,2.14,10],[1,2.12,36.06],[2,1.81,36.34]],"ltp":2.22,"tv":30.42,"id":58385184}]}]}
{"op":"mcm","clk":"11810740897","pt":1722749801812,"mc":[{"id":"1.231395388","rc":[{"batb":[[0,2.12,36.06],[1,1.81,36.34],[2,1.25,100]],"ltp":2.22,"tv":30.42,"id":58385184}]}]}
{"op":"mcm","clk":"11810740957","pt":1722749804235,"mc":[{"id":"1.231395388","rc":[{"batb":[[0,2.14,10],[1,2.12,36.06],[2,1.81,36.34]],"ltp":2.22,"tv":30.42,"id":58385184}]}]}
{"op":"mcm","clk":"11810741021","pt":1722749807813,"mc":[{"id":"1.231395388","rc":[{"batb":[[0,2.12,36.06],[1,1.81,36.34],[2,1.25,100]],"ltp":2.22,"tv":30.42,"id":58385184}]}]}
{"op":"mcm","clk":"11810741117","pt":1722749812634,"mc":[{"id":"1.231395388","rc":[{"batb":[[0,2.14,10],[1,2.12,36.06],[2,1.81,36.34]],"ltp":2.22,"tv":30.42,"id":58385184}]}]}
{"op":"mcm","clk":"11810741212","pt":1722749816344,"mc":[{"id":"1.231395388","rc":[{"batb":[[0,2.12,36.06],[1,1.81,36.34],[2,1.25,100]],"ltp":2.22,"tv":30.42,"id":58385184}]}]}
{"op":"mcm","clk":"11810741250","pt":1722749819522,"mc":[{"id":"1.231395388","rc":[{"batb":[[0,2.14,10],[1,2.12,36.06],[2,1.81,36.34]],"ltp":2.22,"tv":30.42,"id":58385184}]}]}
{"op":"mcm","clk":"11810741301","pt":1722749822744,"mc":[{"id":"1.231395388","rc":[{"batb":[[0,2.12,36.06],[1,1.81,36.34],[2,1.25,100]],"ltp":2.22,"tv":30.42,"id":58385184}]}]}
{"op":"mcm","clk":"11810741407","pt":1722749827412,"mc":[{"id":"1.231395388","rc":[{"batb":[[0,2.14,10],[1,2.12,36.06],[2,1.81,36.34]],"ltp":2.22,"tv":30.42,"id":58385184}]}]}
{"op":"mcm","clk":"11810741480","pt":1722749830741,"mc":[{"id":"1.231395388","rc":[{"batb":[[0,2.12,36.06],[1,1.81,36.34],[2,1.25,100]],"ltp":2.22,"tv":30.42,"id":58385184}]}]}
{"op":"mcm","clk":"11810741576","pt":1722749835650,"mc":[{"id":"1.231395388","rc":[{"batb":[[0,2.14,10],[1,2.12,36.06],[2,1.81,36.34]],"ltp":2.22,"tv":30.42,"id":58385184}]}]}
{"op":"mcm","clk":"11810741650","pt":1722749838956,"mc":[{"id":"1.231395388","rc":[{"batb":[[0,2.12,36.06],[1,1.81,36.34],[2,1.25,100]],"ltp":2.22,"tv":30.42,"id":58385184}]}]}
{"op":"mcm","clk":"11810741703","pt":1722749841468,"mc":[{"id":"1.231395388","rc":[{"batb":[[0,2.14,10],[1,2.12,36.06],[2,1.81,36.34]],"ltp":2.22,"tv":30.42,"id":58385184}]}]}
{"op":"mcm","clk":"11810741804","pt":1722749844963,"mc":[{"id":"1.231395388","rc":[{"batb":[[0,2.12,36.06],[1,1.81,36.34],[2,1.25,100]],"ltp":2.22,"tv":30.42,"id":58385184}]}]}
{"op":"mcm","clk":"11810741852","pt":1722749847368,"mc":[{"id":"1.231395388","rc":[{"batb":[[0,2.14,10],[1,2.12,36.06],[2,1.81,36.34]],"ltp":2.22,"tv":30.42,"id":58385184}]}]}
{"op":"mcm","clk":"11810741923","pt":1722749850654,"mc":[{"id":"1.231395388","rc":[{"batb":[[0,2.12,36.06],[1,1.81,36.34],[2,1.25,100]],"ltp":2.22,"tv":30.42,"id":58385184}]}]}
{"op":"mcm","clk":"11810741985","pt":1722749853354,"mc":[{"id":"1.231395388","rc":[{"batb":[[0,2.14,10],[1,2.12,36.06],[2,1.81,36.34]],"ltp":2.22,"tv":30.42,"id":58385184}]}]}
{"op":"mcm","clk":"11810742055","pt":1722749856793,"mc":[{"id":"1.231395388","rc":[{"batb":[[0,2.12,36.06],[1,1.81,36.34],[2,1.25,100]],"ltp":2.22,"tv":30.42,"id":58385184}]}]}
{"op":"mcm","clk":"11810742128","pt":1722749861000,"mc":[{"id":"1.231395388","rc":[{"batb":[[0,2.14,10],[1,2.12,36.06],[2,1.81,36.34]],"ltp":2.22,"tv":30.42,"id":58385184}]}]}
{"op":"mcm","clk":"11810742247","pt":1722749864411,"mc":[{"id":"1.231395388","rc":[{"batb":[[0,2.12,36.06],[1,1.81,36.34],[2,1.25,100]],"ltp":2.22,"tv":30.42,"id":58385184}]}]}
{"op":"mcm","clk":"11810742358","pt":1722749868203,"mc":[{"id":"1.231395388","rc":[{"batb":[[0,2.14,10],[1,2.12,36.06],[2,1.81,36.34]],"ltp":2.22,"tv":30.42,"id":58385184}]}]}
{"op":"mcm","clk":"11810742426","pt":1722749871589,"mc":[{"id":"1.231395388","rc":[{"batb":[[0,2.12,36.06],[1,1.81,36.34],[2,1.25,100]],"ltp":2.22,"tv":30.42,"id":58385184}]}]}
{"op":"mcm","clk":"11810742494","pt":1722749874406,"mc":[{"id":"1.231395388","rc":[{"batb":[[0,2.14,10],[1,2.12,36.06],[2,1.81,36.34]],"ltp":2.22,"tv":30.42,"id":58385184}]}]}
{"op":"mcm","clk":"11810742560","pt":1722749877795,"mc":[{"id":"1.231395388","rc":[{"batb":[[0,2.12,36.06],[1,1.81,36.34],[2,1.25,100]],"ltp":2.22,"tv":30.42,"id":58385184}]}]}
{"op":"mcm","clk":"11810742630","pt":1722749880723,"mc":[{"id":"1.231395388","rc":[{"batb":[[0,2.14,10],[1,2.12,36.06],[2,1.81,36.34]],"ltp":2.22,"tv":30.42,"id":58385184}]}]}
{"op":"mcm","clk":"11810742691","pt":1722749884015,"mc":[{"id":"1.231395388","rc":[{"batb":[[0,2.12,36.06],[1,1.81,36.34],[2,1.25,100]],"ltp":2.22,"tv":30.42,"id":58385184}]}]}
{"op":"mcm","clk":"11810742770","pt":1722749887305,"mc":[{"id":"1.231395388","rc":[{"batb":[[0,2.14,10],[1,2.12,36.06],[2,1.81,36.34]],"ltp":2.22,"tv":30.42,"id":58385184}]}]}
{"op":"mcm","clk":"11810742830","pt":1722749890713,"mc":[{"id":"1.231395388","rc":[{"batb":[[0,2.12,36.06],[1,1.81,36.34],[2,1.25,100]],"ltp":2.22,"tv":30.42,"id":58385184}]}]}
{"op":"mcm","clk":"11810742902","pt":1722749894526,"mc":[{"id":"1.231395388","rc":[{"batb":[[0,2.14,10],[1,2.12,36.06],[2,1.81,36.34]],"ltp":2.22,"tv":30.42,"id":58385184}]}]}
{"op":"mcm","clk":"11810742969","pt":1722749898129,"mc":[{"id":"1.231395388","rc":[{"batb":[[0,2.12,36.06],[1,1.81,36.34],[2,1.25,100]],"ltp":2.22,"tv":30.42,"id":58385184}]}]}
{"op":"mcm","clk":"11810743028","pt":1722749900431,"mc":[{"id":"1.231395388","rc":[{"batb":[[0,2.14,10],[1,2.12,36.06],[2,1.81,36.34]],"ltp":2.22,"tv":30.42,"id":58385184}]}]}
{"op":"mcm","clk":"11810743095","pt":1722749903737,"mc":[{"id":"1.231395388","rc":[{"batb":[[0,2.12,36.06],[1,1.81,36.34],[2,1.25,100]],"ltp":2.22,"tv":30.42,"id":58385184}]}]}
{"op":"mcm","clk":"11810743156","pt":1722749906325,"mc":[{"id":"1.231395388","rc":[{"batb":[[0,2.14,10],[1,2.12,36.06],[2,1.81,36.34]],"ltp":2.22,"tv":30.42,"id":58385184}]}]}
{"op":"mcm","clk":"11810743234","pt":1722749909717,"mc":[{"id":"1.231395388","rc":[{"batb":[[0,2.12,36.06],[1,1.81,36.34],[2,1.25,100]],"ltp":2.22,"tv":30.42,"id":58385184}]}]}
{"op":"mcm","clk":"11810743311","pt":1722749913524,"mc":[{"id":"1.231395388","rc":[{"batb":[[0,2.14,10],[1,2.12,36.06],[2,1.81,36.34]],"ltp":2.22,"tv":30.42,"id":58385184}]}]}
{"op":"mcm","clk":"11810743390","pt":1722749917029,"mc":[{"id":"1.231395388","rc":[{"batb":[[0,2.12,36.06],[1,1.81,36.34],[2,1.25,100]],"ltp":2.22,"tv":30.42,"id":58385184}]}]}
{"op":"mcm","clk":"11810743460","pt":1722749919850,"mc":[{"id":"1.231395388","rc":[{"batb":[[0,2.14,10],[1,2.12,36.06],[2,1.81,36.34]],"ltp":2.22,"tv":30.42,"id":58385184}]}]}
{"op":"mcm","clk":"11810743515","pt":1722749923242,"mc":[{"id":"1.231395388","rc":[{"batb":[[0,2.12,36.06],[1,1.81,36.34],[2,1.25,100]],"ltp":2.22,"tv":30.42,"id":58385184}]}]}
{"op":"mcm","clk":"11810743599","pt":1722749927562,"mc":[{"id":"1.231395388","rc":[{"batb":[[0,2.14,10],[1,2.12,36.06],[2,1.81,36.34]],"ltp":2.22,"tv":30.42,"id":58385184}]}]}
{"op":"mcm","clk":"11810743668","pt":1722749931163,"mc":[{"id":"1.231395388","rc":[{"batb":[[0,2.12,36.06],[1,1.81,36.34],[2,1.25,100]],"ltp":2.22,"tv":30.42,"id":58385184}]}]}
{"op":"mcm","clk":"11810743785","pt":1722749936085,"mc":[{"id":"1.231395388","rc":[{"batb":[[0,2.14,10],[1,2.12,36.06],[2,1.81,36.34]],"ltp":2.22,"tv":30.42,"id":58385184}]}]}
{"op":"mcm","clk":"11810743869","pt":1722749939372,"mc":[{"id":"1.231395388","rc":[{"batb":[[0,2.12,36.06],[1,1.81,36.34],[2,1.25,100]],"ltp":2.22,"tv":30.42,"id":58385184}]}]}
{"op":"mcm","clk":"11810743969","pt":1722749942792,"mc":[{"id":"1.231395388","rc":[{"batb":[[0,2.14,10],[1,2.12,36.06],[2,1.81,36.34]],"ltp":2.22,"tv":30.42,"id":58385184}]}]}
{"op":"mcm","clk":"11810744062","pt":1722749946188,"mc":[{"id":"1.231395388","rc":[{"batb":[[0,2.12,36.06],[1,1.81,36.34],[2,1.25,100]],"ltp":2.22,"tv":30.42,"id":58385184}]}]}
{"op":"mcm","clk":"11810744163","pt":1722749949902,"mc":[{"id":"1.231395388","rc":[{"batb":[[0,2.14,10],[1,2.12,36.06],[2,1.81,36.34]],"ltp":2.22,"tv":30.42,"id":58385184}]}]}
{"op":"mcm","clk":"11810744252","pt":1722749953291,"mc":[{"id":"1.231395388","rc":[{"batb":[[0,2.12,36.06],[1,1.81,36.34],[2,1.25,100]],"ltp":2.22,"tv":30.42,"id":58385184}]}]}
{"op":"mcm","clk":"11810744338","pt":1722749957193,"mc":[{"id":"1.231395388","rc":[{"batb":[[0,2.14,10],[1,2.12,36.06],[2,1.81,36.34]],"ltp":2.22,"tv":30.42,"id":58385184}]}]}
{"op":"mcm","clk":"11810744417","pt":1722749960584,"mc":[{"id":"1.231395388","rc":[{"batb":[[0,2.12,36.06],[1,1.81,36.34],[2,1.25,100]],"ltp":2.22,"tv":30.42,"id":58385184}]}]}
{"op":"mcm","clk":"11810744485","pt":1722749963411,"mc":[{"id":"1.231395388","rc":[{"batb":[[0,2.14,10],[1,2.12,36.06],[2,1.81,36.34]],"ltp":2.22,"tv":30.42,"id":58385184}]}]}
{"op":"mcm","clk":"11810744576","pt":1722749966603,"mc":[{"id":"1.231395388","rc":[{"batb":[[0,2.12,36.06],[1,1.81,36.34],[2,1.25,100]],"ltp":2.22,"tv":30.42,"id":58385184}]}]}
{"op":"mcm","clk":"11810744703","pt":1722749971800,"mc":[{"id":"1.231395388","rc":[{"batb":[[0,2.14,10],[1,2.12,36.06],[2,1.81,36.34]],"ltp":2.22,"tv":30.42,"id":58385184}]}]}
{"op":"mcm","clk":"11810744755","pt":1722749975081,"mc":[{"id":"1.231395388","rc":[{"batb":[[0,2.12,36.06],[1,1.81,36.34],[2,1.25,100]],"ltp":2.22,"tv":30.42,"id":58385184}]}]}
{"op":"mcm","clk":"11810744811","pt":1722749978314,"mc":[{"id":"1.231395388","rc":[{"batb":[[0,2.14,10],[1,2.12,36.06],[2,1.81,36.34]],"ltp":2.22,"tv":30.42,"id":58385184}]}]}
{"op":"mcm","clk":"11810744867","pt":1722749981608,"mc":[{"id":"1.231395388","rc":[{"batb":[[0,2.12,36.06],[1,1.81,36.34],[2,1.25,100]],"ltp":2.22,"tv":30.42,"id":58385184}]}]}
{"op":"mcm","clk":"11810744957","pt":1722749985015,"mc":[{"id":"1.231395388","rc":[{"batb":[[0,2.14,10],[1,2.12,36.06],[2,1.81,36.34]],"ltp":2.22,"tv":30.42,"id":58385184}]}]}
{"op":"mcm","clk":"11810745019","pt":1722749988428,"mc":[{"id":"1.231395388","rc":[{"batb":[[0,2.12,36.06],[1,1.81,36.34],[2,1.25,100]],"ltp":2.22,"tv":30.42,"id":58385184}]}]}
{"op":"mcm","clk":"11810745080","pt":1722749992438,"mc":[{"id":"1.231395388","rc":[{"batb":[[0,2.14,10],[1,2.12,36.06],[2,1.81,36.34]],"ltp":2.22,"tv":30.42,"id":58385184}]}]}
{"op":"mcm","clk":"11810745139","pt":1722749995627,"mc":[{"id":"1.231395388","rc":[{"batb":[[0,2.12,36.06],[1,1.81,36.34],[2,1.25,100]],"ltp":2.22,"tv":30.42,"id":58385184}]}]}
{"op":"mcm","clk":"11810745232","pt":1722749998749,"mc":[{"id":"1.231395388","rc":[{"batb":[[0,2.14,10],[1,2.12,36.06],[2,1.81,36.34]],"ltp":2.22,"tv":30.42,"id":58385184}]}]}
{"op":"mcm","clk":"11810745326","pt":1722750002148,"mc":[{"id":"1.231395388","rc":[{"batb":[[0,2.12,36.06],[1,1.81,36.34],[2,1.25,100]],"ltp":2.22,"tv":30.42,"id":58385184}]}]}
{"op":"mcm","clk":"11810745395","pt":1722750004422,"mc":[{"id":"1.231395388","rc":[{"batb":[[0,2.14,10],[1,2.12,36.06],[2,1.81,36.34]],"ltp":2.22,"tv":30.42,"id":58385184}]}]}
{"op":"mcm","clk":"11810745521","pt":1722750007930,"mc":[{"id":"1.231395388","rc":[{"batb":[[0,2.12,36.06],[1,1.81,36.34],[2,1.25,100]],"ltp":2.22,"tv":30.42,"id":58385184}]}]}
{"op":"mcm","clk":"11810745745","pt":1722750015749,"mc":[{"id":"1.231395388","rc":[{"batb":[[0,2.14,10],[1,2.12,36.06],[2,1.81,36.34]],"ltp":2.22,"tv":30.42,"id":58385184}]}]}
{"op":"mcm","clk":"11810745821","pt":1722750019253,"mc":[{"id":"1.231395388","rc":[{"batb":[[0,2.12,36.06],[1,1.81,36.34],[2,1.25,100]],"ltp":2.22,"tv":30.42,"id":58385184}]}]}
{"op":"mcm","clk":"11810745881","pt":1722750021674,"mc":[{"id":"1.231395388","rc":[{"batb":[[0,2.14,10],[1,2.12,36.06],[2,1.81,36.34]],"ltp":2.22,"tv":30.42,"id":58385184}]}]}
{"op":"mcm","clk":"11810745974","pt":1722750025070,"mc":[{"id":"1.231395388","rc":[{"batb":[[0,2.12,36.06],[1,1.81,36.34],[2,1.25,100]],"ltp":2.22,"tv":30.42,"id":58385184}]}]}
{"op":"mcm","clk":"11810746046","pt":1722750027555,"mc":[{"id":"1.231395388","rc":[{"batb":[[0,2.14,10],[1,2.12,36.06],[2,1.81,36.34]],"ltp":2.22,"tv":30.42,"id":58385184}]}]}
{"op":"mcm","clk":"11810746114","pt":1722750030863,"mc":[{"id":"1.231395388","rc":[{"batb":[[0,2.12,36.06],[1,1.81,36.34],[2,1.25,100]],"ltp":2.22,"tv":30.42,"id":58385184}]}]}
{"op":"mcm","clk":"11810746213","pt":1722750035073,"mc":[{"id":"1.231395388","rc":[{"batb":[[0,2.14,10],[1,2.12,36.06],[2,1.81,36.34]],"ltp":2.22,"tv":30.42,"id":58385184}]}]}
{"op":"mcm","clk":"11810746332","pt":1722750038573,"mc":[{"id":"1.231395388","rc":[{"batb":[[0,2.12,36.06],[1,1.81,36.34],[2,1.25,100]],"ltp":2.22,"tv":30.42,"id":58385184}]}]}
{"op":"mcm","clk":"11810746435","pt":1722750041880,"mc":[{"id":"1.231395388","rc":[{"batb":[[0,2.14,10],[1,2.12,36.06],[2,1.81,36.34]],"ltp":2.22,"tv":30.42,"id":58385184}]}]}
{"op":"mcm","clk":"11810746550","pt":1722750045167,"mc":[{"id":"1.231395388","rc":[{"batb":[[0,2.12,36.06],[1,1.81,36.34],[2,1.25,100]],"ltp":2.22,"tv":30.42,"id":58385184}]}]}
{"op":"mcm","clk":"11810746651","pt":1722750048293,"mc":[{"id":"1.231395388","rc":[{"batb":[[0,2.14,10],[1,2.12,36.06],[2,1.81,36.34]],"ltp":2.22,"tv":30.42,"id":58385184}]}]}
{"op":"mcm","clk":"11810746735","pt":1722750051591,"mc":[{"id":"1.231395388","rc":[{"batb":[[0,2.12,36.06],[1,1.81,36.34],[2,1.25,100]],"ltp":2.22,"tv":30.42,"id":58385184}]}]}
{"op":"mcm","clk":"11810746834","pt":1722750054576,"mc":[{"id":"1.231395388","rc":[{"batb":[[0,2.14,10],[1,2.12,36.06],[2,1.81,36.34]],"ltp":2.22,"tv":30.42,"id":58385184}]}]}
{"op":"mcm","clk":"11810746929","pt":1722750058300,"mc":[{"id":"1.231395388","rc":[{"batb":[[0,2.12,36.06],[1,1.81,36.34],[2,1.25,100]],"ltp":2.22,"tv":30.42,"id":58385184}]}]}
{"op":"mcm","clk":"11810746980","pt":1722750060402,"mc":[{"id":"1.231395388","rc":[{"batb":[[0,2.14,10],[1,2.12,36.06],[2,1.81,36.34]],"ltp":2.22,"tv":30.42,"id":58385184}]}]}
{"op":"mcm","clk":"11810747095","pt":1722750063799,"mc":[{"id":"1.231395388","rc":[{"batb":[[0,2.12,36.06],[1,1.81,36.34],[2,1.25,100]],"ltp":2.22,"tv":30.42,"id":58385184}]}]}
{"op":"mcm","clk":"11810747278","pt":1722750070825,"mc":[{"id":"1.231395388","rc":[{"batb":[[0,2.14,10],[1,2.12,36.06],[2,1.81,36.34]],"ltp":2.22,"tv":30.42,"id":58385184}]}]}
{"op":"mcm","clk":"11810747362","pt":1722750074316,"mc":[{"id":"1.231395388","rc":[{"batb":[[0,2.12,36.06],[1,1.81,36.34],[2,1.25,100]],"ltp":2.22,"tv":30.42,"id":58385184}]}]}
{"op":"mcm","clk":"11810747436","pt":1722750077295,"mc":[{"id":"1.231395388","rc":[{"batb":[[0,2.14,10],[1,2.12,36.06],[2,1.81,36.34]],"ltp":2.22,"tv":30.42,"id":58385184}]}]}
{"op":"mcm","clk":"11810747501","pt":1722750081013,"mc":[{"id":"1.231395388","rc":[{"batb":[[0,2.12,36.06],[1,1.81,36.34],[2,1.25,100]],"ltp":2.22,"tv":30.42,"id":58385184}]}]}
{"op":"mcm","clk":"11810747553","pt":1722750083427,"mc":[{"id":"1.231395388","rc":[{"batb":[[0,2.14,10],[1,2.12,36.06],[2,1.81,36.34]],"ltp":2.22,"tv":30.42,"id":58385184}]}]}
{"op":"mcm","clk":"11810747637","pt":1722750086718,"mc":[{"id":"1.231395388","rc":[{"batb":[[0,2.12,36.06],[1,1.81,36.34],[2,1.25,100]],"ltp":2.22,"tv":30.42,"id":58385184}]}]}
{"op":"mcm","clk":"11810747691","pt":1722750089123,"mc":[{"id":"1.231395388","rc":[{"batb":[[0,2.14,10],[1,2.12,36.06],[2,1.81,36.34]],"ltp":2.22,"tv":30.42,"id":58385184}]}]}
{"op":"mcm","clk":"11810747748","pt":1722750092516,"mc":[{"id":"1.231395388","rc":[{"batb":[[0,2.12,36.06],[1,1.81,36.34],[2,1.25,100]],"ltp":2.22,"tv":30.42,"id":58385184}]}]}
{"op":"mcm","clk":"11810747798","pt":1722750095029,"mc":[{"id":"1.231395388","rc":[{"batb":[[0,2.14,10],[1,2.12,36.06],[2,1.81,36.34]],"ltp":2.22,"tv":30.42,"id":58385184}]}]}
{"op":"mcm","clk":"11810747881","pt":1722750098361,"mc":[{"id":"1.231395388","rc":[{"batb":[[0,2.12,36.06],[1,1.81,36.34],[2,1.25,100]],"ltp":2.22,"tv":30.42,"id":58385184}]}]}
{"op":"mcm","clk":"11810747935","pt":1722750101033,"mc":[{"id":"1.231395388","rc":[{"batb":[[0,2.14,10],[1,2.12,36.06],[2,1.81,36.34]],"ltp":2.22,"tv":30.42,"id":58385184}]}]}
{"op":"mcm","clk":"11810748015","pt":1722750104529,"mc":[{"id":"1.231395388","rc":[{"batb":[[0,2.12,36.06],[1,1.81,36.34],[2,1.25,100]],"ltp":2.22,"tv":30.42,"id":58385184}]}]}
{"op":"mcm","clk":"11810748059","pt":1722750106735,"mc":[{"id":"1.231395388","rc":[{"batb":[[0,2.14,10],[1,2.12,36.06],[2,1.81,36.34]],"ltp":2.22,"tv":30.42,"id":58385184}]}]}
{"op":"mcm","clk":"11810748138","pt":1722750110146,"mc":[{"id":"1.231395388","rc":[{"batb":[[0,2.12,36.06],[1,1.81,36.34],[2,1.25,100]],"ltp":2.22,"tv":30.42,"id":58385184}]}]}
{"op":"mcm","clk":"11810748258","pt":1722750114276,"mc":[{"id":"1.231395388","rc":[{"batb":[[0,2.14,10],[1,2.12,36.06],[2,1.81,36.34]],"ltp":2.22,"tv":30.42,"id":58385184}]}]}
{"op":"mcm","clk":"11810748337","pt":1722750117671,"mc":[{"id":"1.231395388","rc":[{"batb":[[0,2.12,36.06],[1,1.81,36.34],[2,1.25,100]],"ltp":2.22,"tv":30.42,"id":58385184}]}]}
{"op":"mcm","clk":"11810748423","pt":1722750120866,"mc":[{"id":"1.231395388","rc":[{"batb":[[0,2.14,10],[1,2.12,36.06],[2,1.81,36.34]],"ltp":2.22,"tv":30.42,"id":58385184}]}]}
{"op":"mcm","clk":"11810748533","pt":1722750124270,"mc":[{"id":"1.231395388","rc":[{"batb":[[0,2.12,36.06],[1,1.81,36.34],[2,1.25,100]],"ltp":2.22,"tv":30.42,"id":58385184}]}]}
{"op":"mcm","clk":"11810748696","pt":1722750129366,"mc":[{"id":"1.231395388","rc":[{"batb":[[0,2.14,10],[1,2.12,36.06],[2,1.81,36.34]],"ltp":2.22,"tv":30.42,"id":58385184}]}]}
{"op":"mcm","clk":"11810748805","pt":1722750132704,"mc":[{"id":"1.231395388","rc":[{"batb":[[0,2.12,36.06],[1,1.81,36.34],[2,1.25,100]],"ltp":2.22,"tv":30.42,"id":58385184}]}]}
{"op":"mcm","clk":"11810748891","pt":1722750136370,"mc":[{"id":"1.231395388","rc":[{"batb":[[0,2.14,10],[1,2.12,36.06],[2,1.81,36.34]],"ltp":2.22,"tv":30.42,"id":58385184}]}]}
{"op":"mcm","clk":"11810748969","pt":1722750139869,"mc":[{"id":"1.231395388","rc":[{"batb":[[0,2.12,36.06],[1,1.81,36.34],[2,1.25,100]],"ltp":2.22,"tv":30.42,"id":58385184}]}]}
{"op":"mcm","clk":"11810749033","pt":1722750142385,"mc":[{"id":"1.231395388","rc":[{"batb":[[0,2.14,10],[1,2.12,36.06],[2,1.81,36.34]],"ltp":2.22,"tv":30.42,"id":58385184}]}]}
{"op":"mcm","clk":"11810749116","pt":1722750145984,"mc":[{"id":"1.231395388","rc":[{"batb":[[0,2.12,36.06],[1,1.81,36.34],[2,1.25,100]],"ltp":2.22,"tv":30.42,"id":58385184}]}]}
{"op":"mcm","clk":"11810749186","pt":1722750148898,"mc":[{"id":"1.231395388","rc":[{"batb":[[0,2.14,10],[1,2.12,36.06],[2,1.81,36.34]],"ltp":2.22,"tv":30.42,"id":58385184}]}]}
{"op":"mcm","clk":"11810749258","pt":1722750152198,"mc":[{"id":"1.231395388","rc":[{"batb":[[0,2.12,36.06],[1,1.81,36.34],[2,1.25,100]],"ltp":2.22,"tv":30.42,"id":58385184}]}]}
{"op":"mcm","clk":"11810749326","pt":1722750155215,"mc":[{"id":"1.231395388","rc":[{"batb":[[0,2.14,10],[1,2.12,36.06],[2,1.81,36.34]],"ltp":2.22,"tv":30.42,"id":58385184}]}]}
{"op":"mcm","clk":"11810749438","pt":1722750158602,"mc":[{"id":"1.231395388","rc":[{"batb":[[0,2.12,36.06],[1,1.81,36.34],[2,1.25,100]],"ltp":2.22,"tv":30.42,"id":58385184}]}]}
{"op":"mcm","clk":"11810749539","pt":1722750162085,"mc":[{"id":"1.231395388","rc":[{"batb":[[0,2.14,10],[1,2.12,36.06],[2,1.81,36.34]],"ltp":2.22,"tv":30.42,"id":58385184}]}]}
{"op":"mcm","clk":"11810749641","pt":1722750165510,"mc":[{"id":"1.231395388","rc":[{"batb":[[0,2.12,36.06],[1,1.81,36.34],[2,1.25,100]],"ltp":2.22,"tv":30.42,"id":58385184}]}]}
{"op":"mcm","clk":"11810749773","pt":1722750169607,"mc":[{"id":"1.231395388","rc":[{"batb":[[0,2.14,10],[1,2.12,36.06],[2,1.81,36.34]],"ltp":2.22,"tv":30.42,"id":58385184}]}]}
{"op":"mcm","clk":"11810749832","pt":1722750173029,"mc":[{"id":"1.231395388","rc":[{"batb":[[0,2.12,36.06],[1,1.81,36.34],[2,1.25,100]],"ltp":2.22,"tv":30.42,"id":58385184}]}]}
{"op":"mcm","clk":"11810749927","pt":1722750176516,"mc":[{"id":"1.231395388","rc":[{"batb":[[0,2.14,10],[1,2.12,36.06],[2,1.81,36.34]],"ltp":2.22,"tv":30.42,"id":58385184}]}]}
{"op":"mcm","clk":"11810750004","pt":1722750180041,"mc":[{"id":"1.231395388","rc":[{"batb":[[0,2.12,36.06],[1,1.81,36.34],[2,1.25,100]],"ltp":2.22,"tv":30.42,"id":58385184}]}]}
{"op":"mcm","clk":"11810750172","pt":1722750185841,"mc":[{"id":"1.231395388","rc":[{"batb":[[0,2.14,10],[1,2.12,36.06],[2,1.81,36.34]],"ltp":2.22,"tv":30.42,"id":58385184}]}]}
{"op":"mcm","clk":"11810750278","pt":1722750189344,"mc":[{"id":"1.231395388","rc":[{"batb":[[0,2.12,36.06],[1,1.81,36.34],[2,1.25,100]],"ltp":2.22,"tv":30.42,"id":58385184}]}]}
{"op":"mcm","clk":"11810750363","pt":1722750192833,"mc":[{"id":"1.231395388","rc":[{"batb":[[0,2.14,10],[1,2.12,36.06],[2,1.81,36.34]],"ltp":2.22,"tv":30.42,"id":58385184}]}]}
{"op":"mcm","clk":"11810750438","pt":1722750196361,"mc":[{"id":"1.231395388","rc":[{"batb":[[0,2.12,36.06],[1,1.81,36.34],[2,1.25,100]],"ltp":2.22,"tv":30.42,"id":58385184}]}]}
{"op":"mcm","clk":"11810750499","pt":1722750199132,"mc":[{"id":"1.231395388","rc":[{"batb":[[0,2.14,10],[1,2.12,36.06],[2,1.81,36.34]],"ltp":2.22,"tv":30.42,"id":58385184}]}]}
{"op":"mcm","clk":"11810750576","pt":1722750202625,"mc":[{"id":"1.231395388","rc":[{"batb":[[0,2.12,36.06],[1,1.81,36.34],[2,1.25,100]],"ltp":2.22,"tv":30.42,"id":58385184}]}]}
{"op":"mcm","clk":"11810750636","pt":1722750205546,"mc":[{"id":"1.231395388","rc":[{"batb":[[0,2.14,10],[1,2.12,36.06],[2,1.81,36.34]],"ltp":2.22,"tv":30.42,"id":58385184}]}]}
{"op":"mcm","clk":"11810750743","pt":1722750208836,"mc":[{"id":"1.231395388","rc":[{"batb":[[0,2.12,36.06],[1,1.81,36.34],[2,1.25,100]],"ltp":2.22,"tv":30.42,"id":58385184}]}]}
{"op":"mcm","clk":"11810750841","pt":1722750212673,"mc":[{"id":"1.231395388","rc":[{"batb":[[0,2.14,10],[1,2.12,36.06],[2,1.81,36.34]],"ltp":2.22,"tv":30.42,"id":58385184}]}]}
{"op":"mcm","clk":"11810750920","pt":1722750216064,"mc":[{"id":"1.231395388","rc":[{"batb":[[0,2.12,36.06],[1,1.81,36.34],[2,1.25,100]],"ltp":2.22,"tv":30.42,"id":58385184}]}]}
{"op":"mcm","clk":"11810750970","pt":1722750218270,"mc":[{"id":"1.231395388","rc":[{"batb":[[0,2.14,10],[1,2.12,36.06],[2,1.81,36.34]],"ltp":2.22,"tv":30.42,"id":58385184}]}]}
{"op":"mcm","clk":"11810751068","pt":1722750221650,"mc":[{"id":"1.231395388","rc":[{"batb":[[0,2.12,36.06],[1,1.81,36.34],[2,1.25,100]],"ltp":2.22,"tv":30.42,"id":58385184}]}]}
{"op":"mcm","clk":"11810751142","pt":1722750224276,"mc":[{"id":"1.231395388","rc":[{"batb":[[0,2.14,10],[1,2.12,36.06],[2,1.81,36.34]],"ltp":2.22,"tv":30.42,"id":58385184}]}]}
{"op":"mcm","clk":"11810751233","pt":1722750227867,"mc":[{"id":"1.231395388","rc":[{"batb":[[0,2.12,36.06],[1,1.81,36.34],[2,1.25,100]],"ltp":2.22,"tv":30.42,"id":58385184}]}]}
{"op":"mcm","clk":"11810751365","pt":1722750232373,"mc":[{"id":"1.231395388","rc":[{"batb":[[0,2.14,10],[1,2.12,36.06],[2,1.81,36.34]],"ltp":2.22,"tv":30.42,"id":58385184}]}]}
{"op":"mcm","clk":"11810751453","pt":1722750235760,"mc":[{"id":"1.231395388","rc":[{"batb":[[0,2.12,36.06],[1,1.81,36.34],[2,1.25,100]],"ltp":2.22,"tv":30.42,"id":58385184}]}]}
{"op":"mcm","clk":"11810751534","pt":1722750238059,"mc":[{"id":"1.231395388","rc":[{"batb":[[0,2.14,10],[1,2.12,36.06],[2,1.81,36.34]],"ltp":2.22,"tv":30.42,"id":58385184}]}]}
{"op":"mcm","clk":"11810751638","pt":1722750241390,"mc":[{"id":"1.231395388","rc":[{"batb":[[0,2.12,36.06],[1,1.81,36.34],[2,1.25,100]],"ltp":2.22,"tv":30.42,"id":58385184}]}]}
{"op":"mcm","clk":"11810751706","pt":1722750243760,"mc":[{"id":"1.231395388","rc":[{"batb":[[0,2.14,10],[1,2.12,36.06],[2,1.81,36.34]],"ltp":2.22,"tv":30.42,"id":58385184}]}]}
{"op":"mcm","clk":"11810751806","pt":1722750247099,"mc":[{"id":"1.231395388","rc":[{"batb":[[0,2.12,36.06],[1,1.81,36.34],[2,1.25,100]],"ltp":2.22,"tv":30.42,"id":58385184}]}]}
{"op":"mcm","clk":"11810751905","pt":1722750250065,"mc":[{"id":"1.231395388","rc":[{"batb":[[0,2.14,10],[1,2.12,36.06],[2,1.81,36.34]],"ltp":2.22,"tv":30.42,"id":58385184}]}]}
{"op":"mcm","clk":"11810752012","pt":1722750253602,"mc":[{"id":"1.231395388","rc":[{"batb":[[0,2.12,36.06],[1,1.81,36.34],[2,1.25,100]],"ltp":2.22,"tv":30.42,"id":58385184}]}]}
{"op":"mcm","clk":"11810752101","pt":1722750256682,"mc":[{"id":"1.231395388","rc":[{"batb":[[0,2.14,10],[1,2.12,36.06],[2,1.81,36.34]],"ltp":2.22,"tv":30.42,"id":58385184}]}]}
{"op":"mcm","clk":"11810752178","pt":1722750259980,"mc":[{"id":"1.231395388","rc":[{"batb":[[0,2.12,36.06],[1,1.81,36.34],[2,1.25,100]],"ltp":2.22,"tv":30.42,"id":58385184}]}]}
{"op":"mcm","clk":"11810752250","pt":1722750263301,"mc":[{"id":"1.231395388","rc":[{"batb":[[0,2.14,10],[1,2.12,36.06],[2,1.81,36.34]],"ltp":2.22,"tv":30.42,"id":58385184}]}]}
{"op":"mcm","clk":"11810752337","pt":1722750266684,"mc":[{"id":"1.231395388","rc":[{"batb":[[0,2.12,36.06],[1,1.81,36.34],[2,1.25,100]],"ltp":2.22,"tv":30.42,"id":58385184}]}]}
{"op":"mcm","clk":"11810752395","pt":1722750269001,"mc":[{"id":"1.231395388","rc":[{"batb":[[0,2.14,10],[1,2.12,36.06],[2,1.81,36.34]],"ltp":2.22,"tv":30.42,"id":58385184}]}]}
{"op":"mcm","clk":"11810752471","pt":1722750272486,"mc":[{"id":"1.231395388","rc":[{"batb":[[0,2.12,36.06],[1,1.81,36.34],[2,1.25,100]],"ltp":2.22,"tv":30.42,"id":58385184}]}]}
{"op":"mcm","clk":"11810752555","pt":1722750276220,"mc":[{"id":"1.231395388","rc":[{"batb":[[0,2.14,10],[1,2.12,36.06],[2,1.81,36.34]],"ltp":2.22,"tv":30.42,"id":58385184}]}]}
{"op":"mcm","clk":"11810752634","pt":1722750279499,"mc":[{"id":"1.231395388","rc":[{"batb":[[0,2.12,36.06],[1,1.81,36.34],[2,1.25,100]],"ltp":2.22,"tv":30.42,"id":58385184}]}]}
{"op":"mcm","clk":"11810752790","pt":1722750285638,"mc":[{"id":"1.231395388","rc":[{"batb":[[0,2.14,10],[1,2.12,36.06],[2,1.81,36.34]],"ltp":2.22,"tv":30.42,"id":58385184}]}]}
{"op":"mcm","clk":"11810752875","pt":1722750289021,"mc":[{"id":"1.231395388","rc":[{"batb":[[0,2.12,36.06],[1,1.81,36.34],[2,1.25,100]],"ltp":2.22,"tv":30.42,"id":58385184}]}]}
{"op":"mcm","clk":"11810752927","pt":1722750291343,"mc":[{"id":"1.231395388","rc":[{"batb":[[0,2.14,10],[1,2.12,36.06],[2,1.81,36.34]],"ltp":2.22,"tv":30.42,"id":58385184}]}]}
{"op":"mcm","clk":"11810753004","pt":1722750294845,"mc":[{"id":"1.231395388","rc":[{"batb":[[0,2.12,36.06],[1,1.81,36.34],[2,1.25,100]],"ltp":2.22,"tv":30.42,"id":58385184}]}]}
{"op":"mcm","clk":"11810753056","pt":1722750297150,"mc":[{"id":"1.231395388","rc":[{"batb":[[0,2.14,10],[1,2.12,36.06],[2,1.81,36.34]],"ltp":2.22,"tv":30.42,"id":58385184}]}]}
{"op":"mcm","clk":"11810753157","pt":1722750300436,"mc":[{"id":"1.231395388","rc":[{"batb":[[0,2.12,36.06],[1,1.81,36.34],[2,1.25,100]],"ltp":2.22,"tv":30.42,"id":58385184}]}]}
{"op":"mcm","clk":"11810753254","pt":1722750304368,"mc":[{"id":"1.231395388","rc":[{"batb":[[0,2.14,10],[1,2.12,36.06],[2,1.81,36.34]],"ltp":2.22,"tv":30.42,"id":58385184}]}]}
{"op":"mcm","clk":"11810753339","pt":1722750307856,"mc":[{"id":"1.231395388","rc":[{"batb":[[0,2.12,36.06],[1,1.81,36.34],[2,1.25,100]],"ltp":2.22,"tv":30.42,"id":58385184}]}]}
{"op":"mcm","clk":"11810753419","pt":1722750310625,"mc":[{"id":"1.231395388","rc":[{"batb":[[0,2.14,10],[1,2.12,36.06],[2,1.81,36.34]],"ltp":2.22,"tv":30.42,"id":58385184}]}]}
{"op":"mcm","clk":"11810753505","pt":1722750313962,"mc":[{"id":"1.231395388","rc":[{"batb":[[0,2.12,36.06],[1,1.81,36.34],[2,1.25,100]],"ltp":2.22,"tv":30.42,"id":58385184}]}]}
{"op":"mcm","clk":"11810753577","pt":1722750317446,"mc":[{"id":"1.231395388","rc":[{"batb":[[0,2.14,10],[1,2.12,36.06],[2,1.81,36.34]],"ltp":2.22,"tv":30.42,"id":58385184}]}]}
{"op":"mcm","clk":"11810753664","pt":1722750321087,"mc":[{"id":"1.231395388","rc":[{"batb":[[0,2.12,36.06],[1,1.81,36.34],[2,1.25,100]],"ltp":2.22,"tv":30.42,"id":58385184}]}]}
{"op":"mcm","clk":"11810753746","pt":1722750324691,"mc":[{"id":"1.231395388","rc":[{"batb":[[0,2.14,10],[1,2.12,36.06],[2,1.81,36.34]],"ltp":2.22,"tv":30.42,"id":58385184}]}]}
{"op":"mcm","clk":"11810753817","pt":1722750328058,"mc":[{"id":"1.231395388","rc":[{"batb":[[0,2.12,36.06],[1,1.81,36.34],[2,1.25,100]],"ltp":2.22,"tv":30.42,"id":58385184}]}]}
{"op":"mcm","clk":"11810753947","pt":1722750332395,"mc":[{"id":"1.231395388","rc":[{"batb":[[0,2.14,10],[1,2.12,36.06],[2,1.81,36.34]],"ltp":2.22,"tv":30.42,"id":58385184}]}]}
{"op":"mcm","clk":"11810754045","pt":1722750335877,"mc":[{"id":"1.231395388","rc":[{"batb":[[0,2.12,36.06],[1,1.81,36.34],[2,1.25,100]],"ltp":2.22,"tv":30.42,"id":58385184}]}]}
{"op":"mcm","clk":"11810754120","pt":1722750338969,"mc":[{"id":"1.231395388","rc":[{"batb":[[0,2.14,10],[1,2.12,36.06],[2,1.81,36.34]],"ltp":2.22,"tv":30.42,"id":58385184}]}]}
{"op":"mcm","clk":"11810754195","pt":1722750342506,"mc":[{"id":"1.231395388","rc":[{"batb":[[0,2.12,36.06],[1,1.81,36.34],[2,1.25,100]],"ltp":2.22,"tv":30.42,"id":58385184}]}]}
{"op":"mcm","clk":"11810754320","pt":1722750346472,"mc":[{"id":"1.231395388","rc":[{"batb":[[0,2.14,10],[1,2.12,36.06],[2,1.81,36.34]],"ltp":2.22,"tv":30.42,"id":58385184}]}]}
{"op":"mcm","clk":"11810754405","pt":1722750349906,"mc":[{"id":"1.231395388","rc":[{"batb":[[0,2.12,36.06],[1,1.81,36.34],[2,1.25,100]],"ltp":2.22,"tv":30.42,"id":58385184}]}]}
{"op":"mcm","clk":"11810754510","pt":1722750353397,"mc":[{"id":"1.231395388","rc":[{"batb":[[0,2.14,10],[1,2.12,36.06],[2,1.81,36.34]],"ltp":2.22,"tv":30.42,"id":58385184}]}]}
{"op":"mcm","clk":"11810754622","pt":1722750356724,"mc":[{"id":"1.231395388","rc":[{"batb":[[0,2.12,36.06],[1,1.81,36.34],[2,1.25,100]],"ltp":2.22,"tv":30.42,"id":58385184}]}]}
{"op":"mcm","clk":"11810754720","pt":1722750359283,"mc":[{"id":"1.231395388","rc":[{"batb":[[0,2.14,10],[1,2.12,36.06],[2,1.81,36.34]],"ltp":2.22,"tv":30.42,"id":58385184}]}]}
{"op":"mcm","clk":"11810754831","pt":1722750362535,"mc":[{"id":"1.231395388","rc":[{"batb":[[0,2.12,36.06],[1,1.81,36.34],[2,1.25,100]],"ltp":2.22,"tv":30.42,"id":58385184}]}]}
{"op":"mcm","clk":"11810754965","pt":1722750366339,"mc":[{"id":"1.231395388","rc":[{"batb":[[0,2.14,10],[1,2.12,36.06],[2,1.81,36.34]],"ltp":2.22,"tv":30.42,"id":58385184}]}]}
{"op":"mcm","clk":"11810755073","pt":1722750369874,"mc":[{"id":"1.231395388","rc":[{"batb":[[0,2.12,36.06],[1,1.81,36.34],[2,1.25,100]],"ltp":2.22,"tv":30.42,"id":58385184}]}]}
{"op":"mcm","clk":"11810755148","pt":1722750372235,"mc":[{"id":"1.231395388","rc":[{"batb":[[0,2.14,10],[1,2.12,36.06],[2,1.81,36.34]],"ltp":2.22,"tv":30.42,"id":58385184}]}]}
{"op":"mcm","clk":"11810755246","pt":1722750375562,"mc":[{"id":"1.231395388","rc":[{"batb":[[0,2.12,36.06],[1,1.81,36.34],[2,1.25,100]],"ltp":2.22,"tv":30.42,"id":58385184}]}]}
{"op":"mcm","clk":"11810755332","pt":1722750378580,"mc":[{"id":"1.231395388","rc":[{"batb":[[0,2.14,10],[1,2.12,36.06],[2,1.81,36.34]],"ltp":2.22,"tv":30.42,"id":58385184}]}]}
{"op":"mcm","clk":"11810755446","pt":1722750381769,"mc":[{"id":"1.231395388","rc":[{"batb":[[0,2.12,36.06],[1,1.81,36.34],[2,1.25,100]],"ltp":2.22,"tv":30.42,"id":58385184}]}]}
{"op":"mcm","clk":"11810755544","pt":1722750384853,"mc":[{"id":"1.231395388","rc":[{"batb":[[0,2.14,10],[1,2.12,36.06],[2,1.81,36.34]],"ltp":2.22,"tv":30.42,"id":58385184}]}]}
{"op":"mcm","clk":"11810755625","pt":1722750388185,"mc":[{"id":"1.231395388","rc":[{"batb":[[0,2.12,36.06],[1,1.81,36.34],[2,1.25,100]],"ltp":2.22,"tv":30.42,"id":58385184}]}]}
{"op":"mcm","clk":"11810755709","pt":1722750390980,"mc":[{"id":"1.231395388","rc":[{"batb":[[0,2.14,10],[1,2.12,36.06],[2,1.81,36.34]],"ltp":2.22,"tv":30.42,"id":58385184}]}]}
{"op":"mcm","clk":"11810755821","pt":1722750394376,"mc":[{"id":"1.231395388","rc":[{"batb":[[0,2.12,36.06],[1,1.81,36.34],[2,1.25,100]],"ltp":2.22,"tv":30.42,"id":58385184}]}]}
{"op":"mcm","clk":"11810755891","pt":1722750396792,"mc":[{"id":"1.231395388","rc":[{"batb":[[0,2.14,10],[1,2.12,36.06],[2,1.81,36.34]],"ltp":2.22,"tv":30.42,"id":58385184}]}]}
{"op":"mcm","clk":"11810755985","pt":1722750400083,"mc":[{"id":"1.231395388","rc":[{"batb":[[0,2.12,36.06],[1,1.81,36.34],[2,1.25,100]],"ltp":2.22,"tv":30.42,"id":58385184}]}]}
{"op":"mcm","clk":"11810756075","pt":1722750402495,"mc":[{"id":"1.231395388","rc":[{"batb":[[0,2.14,10],[1,2.12,36.06],[2,1.81,36.34]],"ltp":2.22,"tv":30.42,"id":58385184}]}]}
{"op":"mcm","clk":"11810756199","pt":1722750406027,"mc":[{"id":"1.231395388","rc":[{"batb":[[0,2.12,36.06],[1,1.81,36.34],[2,1.25,100]],"ltp":2.22,"tv":30.42,"id":58385184}]}]}
{"op":"mcm","clk":"11810756273","pt":1722750408183,"mc":[{"id":"1.231395388","rc":[{"batb":[[0,2.14,10],[1,2.12,36.06],[2,1.81,36.34]],"ltp":2.22,"tv":30.42,"id":58385184}]}]}
{"op":"mcm","clk":"11810756381","pt":1722750411411,"mc":[{"id":"1.231395388","rc":[{"batb":[[0,2.12,36.06],[1,1.81,36.34],[2,1.25,100]],"ltp":2.22,"tv":30.42,"id":58385184}]}]}
{"op":"mcm","clk":"11810756483","pt":1722750414685,"mc":[{"id":"1.231395388","rc":[{"batb":[[0,2.14,10],[1,2.12,36.06],[2,1.81,36.34]],"ltp":2.22,"tv":30.42,"id":58385184}]}]}
{"op":"mcm","clk":"11810756587","pt":1722750418214,"mc":[{"id":"1.231395388","rc":[{"batb":[[0,2.12,36.06],[1,1.81,36.34],[2,1.25,100]],"ltp":2.22,"tv":30.42,"id":58385184}]}]}
{"op":"mcm","clk":"11810756721","pt":1722750421733,"mc":[{"id":"1.231395388","rc":[{"batb":[[0,2.14,10],[1,2.12,36.06],[2,1.81,36.34]],"ltp":2.22,"tv":30.42,"id":58385184}]}]}
{"op":"mcm","clk":"11810756854","pt":1722750425125,"mc":[{"id":"1.231395388","rc":[{"batb":[[0,2.12,36.06],[1,1.81,36.34],[2,1.25,100]],"ltp":2.22,"tv":30.42,"id":58385184}]}]}
{"op":"mcm","clk":"11810756959","pt":1722750427992,"mc":[{"id":"1.231395388","rc":[{"batb":[[0,2.14,10],[1,2.12,36.06],[2,1.81,36.34]],"ltp":2.22,"tv":30.42,"id":58385184}]}]}
{"op":"mcm","clk":"11810757054","pt":1722750431418,"mc":[{"id":"1.231395388","rc":[{"batb":[[0,2.12,36.06],[1,1.81,36.34],[2,1.25,100]],"ltp":2.22,"tv":30.42,"id":58385184}]}]}
{"op":"mcm","clk":"11810757139","pt":1722750434089,"mc":[{"id":"1.231395388","rc":[{"batb":[[0,2.14,10],[1,2.12,36.06],[2,1.81,36.34]],"ltp":2.22,"tv":30.42,"id":58385184}]}]}
{"op":"mcm","clk":"11810757262","pt":1722750437538,"mc":[{"id":"1.231395388","rc":[{"batb":[[0,2.12,36.06],[1,1.81,36.34],[2,1.25,100]],"ltp":2.22,"tv":30.42,"id":58385184}]}]}
{"op":"mcm","clk":"11810757364","pt":1722750440916,"mc":[{"id":"1.231395388","rc":[{"batb":[[0,2.14,10],[1,2.12,36.06],[2,1.81,36.34]],"ltp":2.22,"tv":30.42,"id":58385184}]}]}
{"op":"mcm","clk":"11810757461","pt":1722750444254,"mc":[{"id":"1.231395388","rc":[{"batb":[[0,2.12,36.06],[1,1.81,36.34],[2,1.25,100]],"ltp":2.22,"tv":30.42,"id":58385184}]}]}
{"op":"mcm","clk":"11810757548","pt":1722750446965,"mc":[{"id":"1.231395388","rc":[{"batb":[[0,2.14,10],[1,2.12,36.06],[2,1.81,36.34]],"ltp":2.22,"tv":30.42,"id":58385184}]}]}
{"op":"mcm","clk":"11810757651","pt":1722750450348,"mc":[{"id":"1.231395388","rc":[{"batb":[[0,2.12,36.06],[1,1.81,36.34],[2,1.25,100]],"ltp":2.22,"tv":30.42,"id":58385184}]}]}
{"op":"mcm","clk":"11810757783","pt":1722750455168,"mc":[{"id":"1.231395388","rc":[{"batb":[[0,2.14,10],[1,2.12,36.06],[2,1.81,36.34]],"ltp":2.22,"tv":30.42,"id":58385184}]}]}
{"op":"mcm","clk":"11810757897","pt":1722750458457,"mc":[{"id":"1.231395388","rc":[{"batb":[[0,2.12,36.06],[1,1.81,36.34],[2,1.25,100]],"ltp":2.22,"tv":30.42,"id":58385184}]}]}
{"op":"mcm","clk":"11810757998","pt":1722750461179,"mc":[{"id":"1.231395388","rc":[{"batb":[[0,2.14,10],[1,2.12,36.06],[2,1.81,36.34]],"ltp":2.22,"tv":30.42,"id":58385184}]}]}
{"op":"mcm","clk":"11810758130","pt":1722750464672,"mc":[{"id":"1.231395388","rc":[{"batb":[[0,2.12,36.06],[1,1.81,36.34],[2,1.25,100]],"ltp":2.22,"tv":30.42,"id":58385184}]}]}
{"op":"mcm","clk":"11810758190","pt":1722750466976,"mc":[{"id":"1.231395388","rc":[{"batb":[[0,2.14,10],[1,2.12,36.06],[2,1.81,36.34]],"ltp":2.22,"tv":30.42,"id":58385184}]}]}
{"op":"mcm","clk":"11810758293","pt":1722750470203,"mc":[{"id":"1.231395388","rc":[{"batb":[[0,2.12,36.06],[1,1.81,36.34],[2,1.25,100]],"ltp":2.22,"tv":30.42,"id":58385184}]}]}
{"op":"mcm","clk":"11810758373","pt":1722750472366,"mc":[{"id":"1.231395388","rc":[{"batb":[[0,2.14,10],[1,2.12,36.06],[2,1.81,36.34]],"ltp":2.22,"tv":30.42,"id":58385184}]}]}
{"op":"mcm","clk":"11810758508","pt":1722750475774,"mc":[{"id":"1.231395388","rc":[{"batb":[[0,2.12,36.06],[1,1.81,36.34],[2,1.25,100]],"ltp":2.22,"tv":30.42,"id":58385184}]}]}
{"op":"mcm","clk":"11810758611","pt":1722750478997,"mc":[{"id":"1.231395388","rc":[{"batb":[[0,2.14,10],[1,2.12,36.06],[2,1.81,36.34]],"ltp":2.22,"tv":30.42,"id":58385184}]}]}
{"op":"mcm","clk":"11810758723","pt":1722750482582,"mc":[{"id":"1.231395388","rc":[{"batb":[[0,2.12,36.06],[1,1.81,36.34],[2,1.25,100]],"ltp":2.22,"tv":30.42,"id":58385184}]}]}
{"op":"mcm","clk":"11810758848","pt":1722750486898,"mc":[{"id":"1.231395388","rc":[{"batb":[[0,2.14,10],[1,2.12,36.06],[2,1.81,36.34]],"ltp":2.22,"tv":30.42,"id":58385184}]}]}
{"op":"mcm","clk":"11810758966","pt":1722750490383,"mc":[{"id":"1.231395388","rc":[{"batb":[[0,2.12,36.06],[1,1.81,36.34],[2,1.25,100]],"ltp":2.22,"tv":30.42,"id":58385184}]}]}
{"op":"mcm","clk":"11810759041","pt":1722750492677,"mc":[{"id":"1.231395388","rc":[{"batb":[[0,2.14,10],[1,2.12,36.06],[2,1.81,36.34]],"ltp":2.22,"tv":30.42,"id":58385184}]}]}
{"op":"mcm","clk":"11810759123","pt":1722750496101,"mc":[{"id":"1.231395388","rc":[{"batb":[[0,2.12,36.06],[1,1.81,36.34],[2,1.25,100]],"ltp":2.22,"tv":30.42,"id":58385184}]}]}
{"op":"mcm","clk":"11810759240","pt":1722750500808,"mc":[{"id":"1.231395388","rc":[{"batb":[[0,2.14,10],[1,2.12,36.06],[2,1.81,36.34]],"ltp":2.22,"tv":30.42,"id":58385184}]}]}
{"op":"mcm","clk":"11810759334","pt":1722750504301,"mc":[{"id":"1.231395388","rc":[{"batb":[[0,2.12,36.06],[1,1.81,36.34],[2,1.25,100]],"ltp":2.22,"tv":30.42,"id":58385184}]}]}
{"op":"mcm","clk":"11810759399","pt":1722750506722,"mc":[{"id":"1.231395388","rc":[{"batb":[[0,2.14,10],[1,2.12,36.06],[2,1.81,36.34]],"ltp":2.22,"tv":30.42,"id":58385184}]}]}
{"op":"mcm","clk":"11810759503","pt":1722750510103,"mc":[{"id":"1.231395388","rc":[{"batb":[[0,2.12,36.06],[1,1.81,36.34],[2,1.25,100]],"ltp":2.22,"tv":30.42,"id":58385184}]}]}
{"op":"mcm","clk":"11810759591","pt":1722750512717,"mc":[{"id":"1.231395388","rc":[{"batb":[[0,2.14,10],[1,2.12,36.06],[2,1.81,36.34]],"ltp":2.22,"tv":30.42,"id":58385184}]}]}
{"op":"mcm","clk":"11810759697","pt":1722750516110,"mc":[{"id":"1.231395388","rc":[{"batb":[[0,2.12,36.06],[1,1.81,36.34],[2,1.25,100]],"ltp":2.22,"tv":30.42,"id":58385184}]}]}
{"op":"mcm","clk":"11810759764","pt":1722750518417,"mc":[{"id":"1.231395388","rc":[{"batb":[[0,2.14,10],[1,2.12,36.06],[2,1.81,36.34]],"ltp":2.22,"tv":30.42,"id":58385184}]}]}
{"op":"mcm","clk":"11810759853","pt":1722750521645,"mc":[{"id":"1.231395388","rc":[{"batb":[[0,2.12,36.06],[1,1.81,36.34],[2,1.25,100]],"ltp":2.22,"tv":30.42,"id":58385184}]}]}
{"op":"mcm","clk":"11810760021","pt":1722750527635,"mc":[{"id":"1.231395388","rc":[{"batb":[[0,2.14,10],[1,2.12,36.06],[2,1.81,36.34]],"ltp":2.22,"tv":30.42,"id":58385184}]}]}
{"op":"mcm","clk":"11810760125","pt":1722750531125,"mc":[{"id":"1.231395388","rc":[{"batb":[[0,2.12,36.06],[1,1.81,36.34],[2,1.25,100]],"ltp":2.22,"tv":30.42,"id":58385184}]}]}
{"op":"mcm","clk":"11810760200","pt":1722750533228,"mc":[{"id":"1.231395388","rc":[{"batb":[[0,2.14,10],[1,2.12,36.06],[2,1.81,36.34]],"ltp":2.22,"tv":30.42,"id":58385184}]}]}
{"op":"mcm","clk":"11810760313","pt":1722750536554,"mc":[{"id":"1.231395388","rc":[{"batb":[[0,2.12,36.06],[1,1.81,36.34],[2,1.25,100]],"ltp":2.22,"tv":30.42,"id":58385184}]}]}
{"op":"mcm","clk":"11810760389","pt":1722750539067,"mc":[{"id":"1.231395388","rc":[{"batb":[[0,2.14,10],[1,2.12,36.06],[2,1.81,36.34]],"ltp":2.22,"tv":30.42,"id":58385184}]}]}
{"op":"mcm","clk":"11810760517","pt":1722750542541,"mc":[{"id":"1.231395388","rc":[{"batb":[[0,2.12,36.06],[1,1.81,36.34],[2,1.25,100]],"ltp":2.22,"tv":30.42,"id":58385184}]}]}
{"op":"mcm","clk":"11810760614","pt":1722750545773,"mc":[{"id":"1.231395388","rc":[{"batb":[[0,2.14,10],[1,2.12,36.06],[2,1.81,36.34]],"ltp":2.22,"tv":30.42,"id":58385184}]}]}
{"op":"mcm","clk":"11810760718","pt":1722750548950,"mc":[{"id":"1.231395388","rc":[{"batb":[[0,2.12,36.06],[1,1.81,36.34],[2,1.25,100]],"ltp":2.22,"tv":30.42,"id":58385184}]}]}
{"op":"mcm","clk":"11810760785","pt":1722750551259,"mc":[{"id":"1.231395388","rc":[{"batb":[[0,2.14,10],[1,2.12,36.06],[2,1.81,36.34]],"ltp":2.22,"tv":30.42,"id":58385184}]}]}
{"op":"mcm","clk":"11810760877","pt":1722750554562,"mc":[{"id":"1.231395388","rc":[{"batb":[[0,2.12,36.06],[1,1.81,36.34],[2,1.25,100]],"ltp":2.22,"tv":30.42,"id":58385184}]}]}
{"op":"mcm","clk":"11810760948","pt":1722750556874,"mc":[{"id":"1.231395388","rc":[{"batb":[[0,2.14,10],[1,2.12,36.06],[2,1.81,36.34]],"ltp":2.22,"tv":30.42,"id":58385184}]}]}
{"op":"mcm","clk":"11810761056","pt":1722750560158,"mc":[{"id":"1.231395388","rc":[{"batb":[[0,2.12,36.06],[1,1.81,36.34],[2,1.25,100]],"ltp":2.22,"tv":30.42,"id":58385184}]}]}
{"op":"mcm","clk":"11810761145","pt":1722750562684,"mc":[{"id":"1.231395388","rc":[{"batb":[[0,2.14,10],[1,2.12,36.06],[2,1.81,36.34]],"ltp":2.22,"tv":30.42,"id":58385184}]}]}
{"op":"mcm","clk":"11810761281","pt":1722750565873,"mc":[{"id":"1.231395388","rc":[{"batb":[[0,2.12,36.06],[1,1.81,36.34],[2,1.25,100]],"ltp":2.22,"tv":30.42,"id":58385184}]}]}
{"op":"mcm","clk":"11810761397","pt":1722750568961,"mc":[{"id":"1.231395388","rc":[{"batb":[[0,2.14,10],[1,2.12,36.06],[2,1.81,36.34]],"ltp":2.22,"tv":30.42,"id":58385184}]}]}
{"op":"mcm","clk":"11810761515","pt":1722750572460,"mc":[{"id":"1.231395388","rc":[{"batb":[[0,2.12,36.06],[1,1.81,36.34],[2,1.25,100]],"ltp":2.22,"tv":30.42,"id":58385184}]}]}
{"op":"mcm","clk":"11810761590","pt":1722750574666,"mc":[{"id":"1.231395388","rc":[{"batb":[[0,2.14,10],[1,2.12,36.06],[2,1.81,36.34]],"ltp":2.22,"tv":30.42,"id":58385184}]}]}
{"op":"mcm","clk":"11810761687","pt":1722750577967,"mc":[{"id":"1.231395388","rc":[{"batb":[[0,2.12,36.06],[1,1.81,36.34],[2,1.25,100]],"ltp":2.22,"tv":30.42,"id":58385184}]}]}
{"op":"mcm","clk":"11810761796","pt":1722750580993,"mc":[{"id":"1.231395388","rc":[{"batb":[[0,2.14,10],[1,2.12,36.06],[2,1.81,36.34]],"ltp":2.22,"tv":30.42,"id":58385184}]}]}
{"op":"mcm","clk":"11810761911","pt":1722750584380,"mc":[{"id":"1.231395388","rc":[{"batb":[[0,2.12,36.06],[1,1.81,36.34],[2,1.25,100]],"ltp":2.22,"tv":30.42,"id":58385184}]}]}
{"op":"mcm","clk":"11810761976","pt":1722750586590,"mc":[{"id":"1.231395388","rc":[{"batb":[[0,2.14,10],[1,2.12,36.06],[2,1.81,36.34]],"ltp":2.22,"tv":30.42,"id":58385184}]}]}
{"op":"mcm","clk":"11810762078","pt":1722750589880,"mc":[{"id":"1.231395388","rc":[{"batb":[[0,2.12,36.06],[1,1.81,36.34],[2,1.25,100]],"ltp":2.22,"tv":30.42,"id":58385184}]}]}
{"op":"mcm","clk":"11810762126","pt":1722750591983,"mc":[{"id":"1.231395388","rc":[{"batb":[[0,2.14,10],[1,2.12,36.06],[2,1.81,36.34]],"ltp":2.22,"tv":30.42,"id":58385184}]}]}
{"op":"mcm","clk":"11810762220","pt":1722750595324,"mc":[{"id":"1.231395388","rc":[{"batb":[[0,2.12,36.06],[1,1.81,36.34],[2,1.25,100]],"ltp":2.22,"tv":30.42,"id":58385184}]}]}
{"op":"mcm","clk":"11810762306","pt":1722750598097,"mc":[{"id":"1.231395388","rc":[{"batb":[[0,2.14,10],[1,2.12,36.06],[2,1.81,36.34]],"ltp":2.22,"tv":30.42,"id":58385184}]}]}
{"op":"mcm","clk":"11810762390","pt":1722750600919,"mc":[{"id":"1.231395388","rc":[{"batb":[[0,2.12,36.06],[1,1.81,36.34],[2,1.25,100]],"ltp":2.22,"tv":30.42,"id":58385184}]}]}
{"op":"mcm","clk":"11810762459","pt":1722750603088,"mc":[{"id":"1.231395388","rc":[{"batb":[[0,2.14,10],[1,2.12,36.06],[2,1.81,36.34]],"ltp":2.22,"tv":30.42,"id":58385184}]}]}
{"op":"mcm","clk":"11810762568","pt":1722750606332,"mc":[{"id":"1.231395388","rc":[{"batb":[[0,2.12,36.06],[1,1.81,36.34],[2,1.25,100]],"ltp":2.22,"tv":30.42,"id":58385184}]}]}
{"op":"mcm","clk":"11810762649","pt":1722750608596,"mc":[{"id":"1.231395388","rc":[{"batb":[[0,2.14,10],[1,2.12,36.06],[2,1.81,36.34]],"ltp":2.22,"tv":30.42,"id":58385184}]}]}
{"op":"mcm","clk":"11810762775","pt":1722750612105,"mc":[{"id":"1.231395388","rc":[{"batb":[[0,2.12,36.06],[1,1.81,36.34],[2,1.25,100]],"ltp":2.22,"tv":30.42,"id":58385184}]}]}
{"op":"mcm","clk":"11810762877","pt":1722750615235,"mc":[{"id":"1.231395388","rc":[{"batb":[[0,2.14,10],[1,2.12,36.06],[2,1.81,36.34]],"ltp":2.22,"tv":30.42,"id":58385184}]}]}
{"op":"mcm","clk":"11810762956","pt":1722750618627,"mc":[{"id":"1.231395388","rc":[{"batb":[[0,2.12,36.06],[1,1.81,36.34],[2,1.25,100]],"ltp":2.22,"tv":30.42,"id":58385184}]}]}
{"op":"mcm","clk":"11810763020","pt":1722750620843,"mc":[{"id":"1.231395388","rc":[{"batb":[[0,2.14,10],[1,2.12,36.06],[2,1.81,36.34]],"ltp":2.22,"tv":30.42,"id":58385184}]}]}
{"op":"mcm","clk":"11810763114","pt":1722750624137,"mc":[{"id":"1.231395388","rc":[{"batb":[[0,2.12,36.06],[1,1.81,36.34],[2,1.25,100]],"ltp":2.22,"tv":30.42,"id":58385184}]}]}
{"op":"mcm","clk":"11810763175","pt":1722750626442,"mc":[{"id":"1.231395388","rc":[{"batb":[[0,2.14,10],[1,2.12,36.06],[2,1.81,36.34]],"ltp":2.22,"tv":30.42,"id":58385184}]}]}
{"op":"mcm","clk":"11810763257","pt":1722750629725,"mc":[{"id":"1.231395388","rc":[{"batb":[[0,2.12,36.06],[1,1.81,36.34],[2,1.25,100]],"ltp":2.22,"tv":30.42,"id":58385184}]}]}
{"op":"mcm","clk":"11810763423","pt":1722750635321,"mc":[{"id":"1.231395388","rc":[{"batb":[[0,2.14,10],[1,2.12,36.06],[2,1.81,36.34]],"ltp":2.22,"tv":30.42,"id":58385184}]}]}
{"op":"mcm","clk":"11810763505","pt":1722750638642,"mc":[{"id":"1.231395388","rc":[{"batb":[[0,2.12,36.06],[1,1.81,36.34],[2,1.25,100]],"ltp":2.22,"tv":30.42,"id":58385184}]}]}
{"op":"mcm","clk":"11810763579","pt":1722750641050,"mc":[{"id":"1.231395388","rc":[{"batb":[[0,2.14,10],[1,2.12,36.06],[2,1.81,36.34]],"ltp":2.22,"tv":30.42,"id":58385184}]}]}
{"op":"mcm","clk":"11810763665","pt":1722750644431,"mc":[{"id":"1.231395388","rc":[{"batb":[[0,2.12,36.06],[1,1.81,36.34],[2,1.25,100]],"ltp":2.22,"tv":30.42,"id":58385184}]}]}
{"op":"mcm","clk":"11810763720","pt":1722750646746,"mc":[{"id":"1.231395388","rc":[{"batb":[[0,2.14,10],[1,2.12,36.06],[2,1.81,36.34]],"ltp":2.22,"tv":30.42,"id":58385184}]}]}
{"op":"mcm","clk":"11810763803","pt":1722750650043,"mc":[{"id":"1.231395388","rc":[{"batb":[[0,2.12,36.06],[1,1.81,36.34],[2,1.25,100]],"ltp":2.22,"tv":30.42,"id":58385184}]}]}
{"op":"mcm","clk":"11810763865","pt":1722750652446,"mc":[{"id":"1.231395388","rc":[{"batb":[[0,2.14,10],[1,2.12,36.06],[2,1.81,36.34]],"ltp":2.22,"tv":30.42,"id":58385184}]}]}
{"op":"mcm","clk":"11810763958","pt":1722750655881,"mc":[{"id":"1.231395388","rc":[{"batb":[[0,2.12,36.06],[1,1.81,36.34],[2,1.25,100]],"ltp":2.22,"tv":30.42,"id":58385184}]}]}
{"op":"mcm","clk":"11810764031","pt":1722750658560,"mc":[{"id":"1.231395388","rc":[{"batb":[[0,2.14,10],[1,2.12,36.06],[2,1.81,36.34]],"ltp":2.22,"tv":30.42,"id":58385184}]}]}
{"op":"mcm","clk":"11810764106","pt":1722750661860,"mc":[{"id":"1.231395388","rc":[{"batb":[[0,2.12,36.06],[1,1.81,36.34],[2,1.25,100]],"ltp":2.22,"tv":30.42,"id":58385184}]}]}
{"op":"mcm","clk":"11810764152","pt":1722750663959,"mc":[{"id":"1.231395388","rc":[{"batb":[[0,2.14,10],[1,2.12,36.06],[2,1.81,36.34]],"ltp":2.22,"tv":30.42,"id":58385184}]}]}
{"op":"mcm","clk":"11810764232","pt":1722750667383,"mc":[{"id":"1.231395388","rc":[{"batb":[[0,2.12,36.06],[1,1.81,36.34],[2,1.25,100]],"ltp":2.22,"tv":30.42,"id":58385184}]}]}
{"op":"mcm","clk":"11810764299","pt":1722750670672,"mc":[{"id":"1.231395388","rc":[{"batb":[[0,2.14,10],[1,2.12,36.06],[2,1.81,36.34]],"ltp":2.22,"tv":30.42,"id":58385184}]}]}
{"op":"mcm","clk":"11810764374","pt":1722750674206,"mc":[{"id":"1.231395388","rc":[{"batb":[[0,2.12,36.06],[1,1.81,36.34],[2,1.25,100]],"ltp":2.22,"tv":30.42,"id":58385184}]}]}
{"op":"mcm","clk":"11810764454","pt":1722750677481,"mc":[{"id":"1.231395388","rc":[{"batb":[[0,2.14,10],[1,2.12,36.06],[2,1.81,36.34]],"ltp":2.22,"tv":30.42,"id":58385184}]}]}
{"op":"mcm","clk":"11810764529","pt":1722750680909,"mc":[{"id":"1.231395388","rc":[{"batb":[[0,2.12,36.06],[1,1.81,36.34],[2,1.25,100]],"ltp":2.22,"tv":30.42,"id":58385184}]}]}
{"op":"mcm","clk":"11810764606","pt":1722750683585,"mc":[{"id":"1.231395388","rc":[{"batb":[[0,2.14,10],[1,2.12,36.06],[2,1.81,36.34]],"ltp":2.22,"tv":30.42,"id":58385184}]}]}
{"op":"mcm","clk":"11810764707","pt":1722750687019,"mc":[{"id":"1.231395388","rc":[{"batb":[[0,2.12,36.06],[1,1.81,36.34],[2,1.25,100]],"ltp":2.22,"tv":30.42,"id":58385184}]}]}
{"op":"mcm","clk":"11810764782","pt":1722750690098,"mc":[{"id":"1.231395388","rc":[{"batb":[[0,2.14,10],[1,2.12,36.06],[2,1.81,36.34]],"ltp":2.22,"tv":30.42,"id":58385184}]}]}
{"op":"mcm","clk":"11810764878","pt":1722750693386,"mc":[{"id":"1.231395388","rc":[{"batb":[[0,2.12,36.06],[1,1.81,36.34],[2,1.25,100]],"ltp":2.22,"tv":30.42,"id":58385184}]}]}
{"op":"mcm","clk":"11810764923","pt":1722750696096,"mc":[{"id":"1.231395388","rc":[{"batb":[[0,2.14,10],[1,2.12,36.06],[2,1.81,36.34]],"ltp":2.22,"tv":30.42,"id":58385184}]}]}
{"op":"mcm","clk":"11810764987","pt":1722750699319,"mc":[{"id":"1.231395388","rc":[{"batb":[[0,2.12,36.06],[1,1.81,36.34],[2,1.25,100]],"ltp":2.22,"tv":30.42,"id":58385184}]}]}
{"op":"mcm","clk":"11810765114","pt":1722750704806,"mc":[{"id":"1.231395388","rc":[{"batb":[[0,2.14,10],[1,2.12,36.06],[2,1.81,36.34]],"ltp":2.22,"tv":30.42,"id":58385184}]}]}
{"op":"mcm","clk":"11810765177","pt":1722750708232,"mc":[{"id":"1.231395388","rc":[{"batb":[[0,2.12,36.06],[1,1.81,36.34],[2,1.25,100]],"ltp":2.22,"tv":30.42,"id":58385184}]}]}
{"op":"mcm","clk":"11810765223","pt":1722750710533,"mc":[{"id":"1.231395388","rc":[{"batb":[[0,2.14,10],[1,2.12,36.06],[2,1.81,36.34]],"ltp":2.22,"tv":30.42,"id":58385184}]}]}
{"op":"mcm","clk":"11810765293","pt":1722750713926,"mc":[{"id":"1.231395388","rc":[{"batb":[[0,2.12,36.06],[1,1.81,36.34],[2,1.25,100]],"ltp":2.22,"tv":30.42,"id":58385184}]}]}
{"op":"mcm","clk":"11810765376","pt":1722750716854,"mc":[{"id":"1.231395388","rc":[{"batb":[[0,2.14,10],[1,2.12,36.06],[2,1.81,36.34]],"ltp":2.22,"tv":30.42,"id":58385184}]}]}
{"op":"mcm","clk":"11810765438","pt":1722750720127,"mc":[{"id":"1.231395388","rc":[{"batb":[[0,2.12,36.06],[1,1.81,36.34],[2,1.25,100]],"ltp":2.22,"tv":30.42,"id":58385184}]}]}
{"op":"mcm","clk":"11810765491","pt":1722750722931,"mc":[{"id":"1.231395388","rc":[{"batb":[[0,2.14,10],[1,2.12,36.06],[2,1.81,36.34]],"ltp":2.22,"tv":30.42,"id":58385184}]}]}
{"op":"mcm","clk":"11810765578","pt":1722750726362,"mc":[{"id":"1.231395388","rc":[{"batb":[[0,2.12,36.06],[1,1.81,36.34],[2,1.25,100]],"ltp":2.22,"tv":30.42,"id":58385184}]}]}
{"op":"mcm","clk":"11810765632","pt":1722750728522,"mc":[{"id":"1.231395388","rc":[{"batb":[[0,2.14,10],[1,2.12,36.06],[2,1.81,36.34]],"ltp":2.22,"tv":30.42,"id":58385184}]}]}
{"op":"mcm","clk":"11810765727","pt":1722750731753,"mc":[{"id":"1.231395388","rc":[{"batb":[[0,2.12,36.06],[1,1.81,36.34],[2,1.25,100]],"ltp":2.22,"tv":30.42,"id":58385184}]}]}
{"op":"mcm","clk":"11810765820","pt":1722750735034,"mc":[{"id":"1.231395388","rc":[{"batb":[[0,2.14,10],[1,2.12,36.06],[2,1.81,36.34]],"ltp":2.22,"tv":30.42,"id":58385184}]}]}
{"op":"mcm","clk":"11810765899","pt":1722750738361,"mc":[{"id":"1.231395388","rc":[{"batb":[[0,2.12,36.06],[1,1.81,36.34],[2,1.25,100]],"ltp":2.22,"tv":30.42,"id":58385184}]}]}
{"op":"mcm","clk":"11810765985","pt":1722750741547,"mc":[{"id":"1.231395388","rc":[{"batb":[[0,2.14,10],[1,2.12,36.06],[2,1.81,36.34]],"ltp":2.22,"tv":30.42,"id":58385184}]}]}
{"op":"mcm","clk":"11810766062","pt":1722750744974,"mc":[{"id":"1.231395388","rc":[{"batb":[[0,2.12,36.06],[1,1.81,36.34],[2,1.25,100]],"ltp":2.22,"tv":30.42,"id":58385184}]}]}
{"op":"mcm","clk":"11810766103","pt":1722750747186,"mc":[{"id":"1.231395388","rc":[{"batb":[[0,2.14,10],[1,2.12,36.06],[2,1.81,36.34]],"ltp":2.22,"tv":30.42,"id":58385184}]}]}
{"op":"mcm","clk":"11810766177","pt":1722750750564,"mc":[{"id":"1.231395388","rc":[{"batb":[[0,2.12,36.06],[1,1.81,36.34],[2,1.25,100]],"ltp":2.22,"tv":30.42,"id":58385184}]}]}
{"op":"mcm","clk":"11810766246","pt":1722750753184,"mc":[{"id":"1.231395388","rc":[{"batb":[[0,2.14,10],[1,2.12,36.06],[2,1.81,36.34]],"ltp":2.22,"tv":30.42,"id":58385184}]}]}
{"op":"mcm","clk":"11810766344","pt":1722750756380,"mc":[{"id":"1.231395388","rc":[{"batb":[[0,2.12,36.06],[1,1.81,36.34],[2,1.25,100]],"ltp":2.22,"tv":30.42,"id":58385184}]}]}
{"op":"mcm","clk":"11810766432","pt":1722750758895,"mc":[{"id":"1.231395388","rc":[{"batb":[[0,2.14,10],[1,2.12,36.06],[2,1.81,36.34]],"ltp":2.22,"tv":30.42,"id":58385184}]}]}
{"op":"mcm","clk":"11810766510","pt":1722750762296,"mc":[{"id":"1.231395388","rc":[{"batb":[[0,2.12,36.06],[1,1.81,36.34],[2,1.25,100]],"ltp":2.22,"tv":30.42,"id":58385184}]}]}
{"op":"mcm","clk":"11810766569","pt":1722750765181,"mc":[{"id":"1.231395388","rc":[{"batb":[[0,2.14,10],[1,2.12,36.06],[2,1.81,36.34]],"ltp":2.22,"tv":30.42,"id":58385184}]}]}
{"op":"mcm","clk":"11810766649","pt":1722750768482,"mc":[{"id":"1.231395388","rc":[{"batb":[[0,2.12,36.06],[1,1.81,36.34],[2,1.25,100]],"ltp":2.22,"tv":30.42,"id":58385184}]}]}
{"op":"mcm","clk":"11810766705","pt":1722750770786,"mc":[{"id":"1.231395388","rc":[{"batb":[[0,2.14,10],[1,2.12,36.06],[2,1.81,36.34]],"ltp":2.22,"tv":30.42,"id":58385184}]}]}
{"op":"mcm","clk":"11810766786","pt":1722750774010,"mc":[{"id":"1.231395388","rc":[{"batb":[[0,2.12,36.06],[1,1.81,36.34],[2,1.25,100]],"ltp":2.22,"tv":30.42,"id":58385184}]}]}
{"op":"mcm","clk":"11810766862","pt":1722750777086,"mc":[{"id":"1.231395388","rc":[{"batb":[[0,2.14,10],[1,2.12,36.06],[2,1.81,36.34]],"ltp":2.22,"tv":30.42,"id":58385184}]}]}
{"op":"mcm","clk":"11810766934","pt":1722750780408,"mc":[{"id":"1.231395388","rc":[{"batb":[[0,2.12,36.06],[1,1.81,36.34],[2,1.25,100]],"ltp":2.22,"tv":30.42,"id":58385184}]}]}
{"op":"mcm","clk":"11810766997","pt":1722750782716,"mc":[{"id":"1.231395388","rc":[{"batb":[[0,2.14,10],[1,2.12,36.06],[2,1.81,36.34]],"ltp":2.22,"tv":30.42,"id":58385184}]}]}
{"op":"mcm","clk":"11810767067","pt":1722750786092,"mc":[{"id":"1.231395388","rc":[{"batb":[[0,2.12,36.06],[1,1.81,36.34],[2,1.25,100]],"ltp":2.22,"tv":30.42,"id":58385184}]}]}
{"op":"mcm","clk":"11810767178","pt":1722750789398,"mc":[{"id":"1.231395388","rc":[{"batb":[[0,2.14,10],[1,2.12,36.06],[2,1.81,36.34]],"ltp":2.22,"tv":30.42,"id":58385184}]}]}
{"op":"mcm","clk":"11810767270","pt":1722750792931,"mc":[{"id":"1.231395388","rc":[{"batb":[[0,2.12,36.06],[1,1.81,36.34],[2,1.25,100]],"ltp":2.22,"tv":30.42,"id":58385184}]}]}
{"op":"mcm","clk":"11810767351","pt":1722750796712,"mc":[{"id":"1.231395388","rc":[{"batb":[[0,2.14,10],[1,2.12,36.06],[2,1.81,36.34]],"ltp":2.22,"tv":30.42,"id":58385184}]}]}
{"op":"mcm","clk":"11810767436","pt":1722750800142,"mc":[{"id":"1.231395388","rc":[{"batb":[[0,2.12,36.06],[1,1.81,36.34],[2,1.25,100]],"ltp":2.22,"tv":30.42,"id":58385184}]}]}
{"op":"mcm","clk":"11810767508","pt":1722750803008,"mc":[{"id":"1.231395388","rc":[{"batb":[[0,2.14,10],[1,2.12,36.06],[2,1.81,36.34]],"ltp":2.22,"tv":30.42,"id":58385184}]}]}
{"op":"mcm","clk":"11810767582","pt":1722750806228,"mc":[{"id":"1.231395388","rc":[{"batb":[[0,2.12,36.06],[1,1.81,36.34],[2,1.25,100]],"ltp":2.22,"tv":30.42,"id":58385184}]}]}
{"op":"mcm","clk":"11810767646","pt":1722750808425,"mc":[{"id":"1.231395388","rc":[{"batb":[[0,2.14,10],[1,2.12,36.06],[2,1.81,36.34]],"ltp":2.22,"tv":30.42,"id":58385184}]}]}
{"op":"mcm","clk":"11810767726","pt":1722750811746,"mc":[{"id":"1.231395388","rc":[{"batb":[[0,2.12,36.06],[1,1.81,36.34],[2,1.25,100]],"ltp":2.22,"tv":30.42,"id":58385184}]}]}
{"op":"mcm","clk":"11810767797","pt":1722750814258,"mc":[{"id":"1.231395388","rc":[{"batb":[[0,2.14,10],[1,2.12,36.06],[2,1.81,36.34]],"ltp":2.22,"tv":30.42,"id":58385184}]}]}
{"op":"mcm","clk":"11810767872","pt":1722750817653,"mc":[{"id":"1.231395388","rc":[{"batb":[[0,2.12,36.06],[1,1.81,36.34],[2,1.25,100]],"ltp":2.22,"tv":30.42,"id":58385184}]}]}
{"op":"mcm","clk":"11810767941","pt":1722750820722,"mc":[{"id":"1.231395388","rc":[{"batb":[[0,2.14,10],[1,2.12,36.06],[2,1.81,36.34]],"ltp":2.22,"tv":30.42,"id":58385184}]}]}
{"op":"mcm","clk":"11810768038","pt":1722750824150,"mc":[{"id":"1.231395388","rc":[{"batb":[[0,2.12,36.06],[1,1.81,36.34],[2,1.25,100]],"ltp":2.22,"tv":30.42,"id":58385184}]}]}
{"op":"mcm","clk":"11810768106","pt":1722750826862,"mc":[{"id":"1.231395388","rc":[{"batb":[[0,2.14,10],[1,2.12,36.06],[2,1.81,36.34]],"ltp":2.22,"tv":30.42,"id":58385184}]}]}
{"op":"mcm","clk":"11810768158","pt":1722750830038,"mc":[{"id":"1.231395388","rc":[{"batb":[[0,2.12,36.06],[1,1.81,36.34],[2,1.25,100]],"ltp":2.22,"tv":30.42,"id":58385184}]}]}
{"op":"mcm","clk":"11810768219","pt":1722750832753,"mc":[{"id":"1.231395388","rc":[{"batb":[[0,2.14,10],[1,2.12,36.06],[2,1.81,36.34]],"ltp":2.22,"tv":30.42,"id":58385184}]}]}
{"op":"mcm","clk":"11810768308","pt":1722750836056,"mc":[{"id":"1.231395388","rc":[{"batb":[[0,2.12,36.06],[1,1.81,36.34],[2,1.25,100]],"ltp":2.22,"tv":30.42,"id":58385184}]}]}
{"op":"mcm","clk":"11810768411","pt":1722750840168,"mc":[{"id":"1.231395388","rc":[{"batb":[[0,2.14,10],[1,2.12,36.06],[2,1.81,36.34]],"ltp":2.22,"tv":30.42,"id":58385184}]}]}
{"op":"mcm","clk":"11810768512","pt":1722750843585,"mc":[{"id":"1.231395388","rc":[{"batb":[[0,2.12,36.06],[1,1.81,36.34],[2,1.25,100]],"ltp":2.22,"tv":30.42,"id":58385184}]}]}
{"op":"mcm","clk":"11810768581","pt":1722750846082,"mc":[{"id":"1.231395388","rc":[{"batb":[[0,2.14,10],[1,2.12,36.06],[2,1.81,36.34]],"ltp":2.22,"tv":30.42,"id":58385184}]}]}
{"op":"mcm","clk":"11810768668","pt":1722750849376,"mc":[{"id":"1.231395388","rc":[{"batb":[[0,2.12,36.06],[1,1.81,36.34],[2,1.25,100]],"ltp":2.22,"tv":30.42,"id":58385184}]}]}
{"op":"mcm","clk":"11810768747","pt":1722750852203,"mc":[{"id":"1.231395388","rc":[{"batb":[[0,2.14,10],[1,2.12,36.06],[2,1.81,36.34]],"ltp":2.22,"tv":30.42,"id":58385184}]}]}
{"op":"mcm","clk":"11810768825","pt":1722750855594,"mc":[{"id":"1.231395388","rc":[{"batb":[[0,2.12,36.06],[1,1.81,36.34],[2,1.25,100]],"ltp":2.22,"tv":30.42,"id":58385184}]}]}
{"op":"mcm","clk":"11810768885","pt":1722750857903,"mc":[{"id":"1.231395388","rc":[{"batb":[[0,2.14,10],[1,2.12,36.06],[2,1.81,36.34]],"ltp":2.22,"tv":30.42,"id":58385184}]}]}
{"op":"mcm","clk":"11810769007","pt":1722750861112,"mc":[{"id":"1.231395388","rc":[{"batb":[[0,2.12,36.06],[1,1.81,36.34],[2,1.25,100]],"ltp":2.22,"tv":30.42,"id":58385184}]}]}
{"op":"mcm","clk":"11810769083","pt":1722750863478,"mc":[{"id":"1.231395388","rc":[{"batb":[[0,2.14,10],[1,2.12,36.06],[2,1.81,36.34]],"ltp":2.22,"tv":30.42,"id":58385184}]}]}
{"op":"mcm","clk":"11810769163","pt":1722750866907,"mc":[{"id":"1.231395388","rc":[{"batb":[[0,2.12,36.06],[1,1.81,36.34],[2,1.25,100]],"ltp":2.22,"tv":30.42,"id":58385184}]}]}
{"op":"mcm","clk":"11810769275","pt":1722750870205,"mc":[{"id":"1.231395388","rc":[{"batb":[[0,2.14,10],[1,2.12,36.06],[2,1.81,36.34]],"ltp":2.22,"tv":30.42,"id":58385184}]}]}
{"op":"mcm","clk":"11810769388","pt":1722750873523,"mc":[{"id":"1.231395388","rc":[{"batb":[[0,2.12,36.06],[1,1.81,36.34],[2,1.25,100]],"ltp":2.22,"tv":30.42,"id":58385184}]}]}
{"op":"mcm","clk":"11810769466","pt":1722750876410,"mc":[{"id":"1.231395388","rc":[{"batb":[[0,2.14,10],[1,2.12,36.06],[2,1.81,36.34]],"ltp":2.22,"tv":30.42,"id":58385184}]}]}
{"op":"mcm","clk":"11810769553","pt":1722750879747,"mc":[{"id":"1.231395388","rc":[{"batb":[[0,2.12,36.06],[1,1.81,36.34],[2,1.25,100]],"ltp":2.22,"tv":30.42,"id":58385184}]}]}
{"op":"mcm","clk":"11810769631","pt":1722750882323,"mc":[{"id":"1.231395388","rc":[{"batb":[[0,2.14,10],[1,2.12,36.06],[2,1.81,36.34]],"ltp":2.22,"tv":30.42,"id":58385184}]}]}
{"op":"mcm","clk":"11810769718","pt":1722750885710,"mc":[{"id":"1.231395388","rc":[{"batb":[[0,2.12,36.06],[1,1.81,36.34],[2,1.25,100]],"ltp":2.22,"tv":30.42,"id":58385184}]}]}
{"op":"mcm","clk":"11810769865","pt":1722750890435,"mc":[{"id":"1.231395388","rc":[{"batb":[[0,2.14,10],[1,2.12,36.06],[2,1.81,36.34]],"ltp":2.22,"tv":30.42,"id":58385184}]}]}
{"op":"mcm","clk":"11810769972","pt":1722750893631,"mc":[{"id":"1.231395388","rc":[{"batb":[[0,2.12,36.06],[1,1.81,36.34],[2,1.25,100]],"ltp":2.22,"tv":30.42,"id":58385184}]}]}
{"op":"mcm","clk":"11810770059","pt":1722750896356,"mc":[{"id":"1.231395388","rc":[{"batb":[[0,2.14,10],[1,2.12,36.06],[2,1.81,36.34]],"ltp":2.22,"tv":30.42,"id":58385184}]}]}
{"op":"mcm","clk":"11810770158","pt":1722750899546,"mc":[{"id":"1.231395388","rc":[{"batb":[[0,2.12,36.06],[1,1.81,36.34],[2,1.25,100]],"ltp":2.22,"tv":30.42,"id":58385184}]}]}
{"op":"mcm","clk":"11810770260","pt":1722750902851,"mc":[{"id":"1.231395388","rc":[{"batb":[[0,2.14,10],[1,2.12,36.06],[2,1.81,36.34]],"ltp":2.22,"tv":30.42,"id":58385184}]}]}
{"op":"mcm","clk":"11810770378","pt":1722750906145,"mc":[{"id":"1.231395388","rc":[{"batb":[[0,2.12,36.06],[1,1.81,36.34],[2,1.25,100]],"ltp":2.22,"tv":30.42,"id":58385184}]}]}
{"op":"mcm","clk":"11810770464","pt":1722750909047,"mc":[{"id":"1.231395388","rc":[{"batb":[[0,2.14,10],[1,2.12,36.06],[2,1.81,36.34]],"ltp":2.22,"tv":30.42,"id":58385184}]}]}
{"op":"mcm","clk":"11810770587","pt":1722750912237,"mc":[{"id":"1.231395388","rc":[{"batb":[[0,2.12,36.06],[1,1.81,36.34],[2,1.25,100]],"ltp":2.22,"tv":30.42,"id":58385184}]}]}
{"op":"mcm","clk":"11810770652","pt":1722750914660,"mc":[{"id":"1.231395388","rc":[{"batb":[[0,2.14,10],[1,2.12,36.06],[2,1.81,36.34]],"ltp":2.22,"tv":30.42,"id":58385184}]}]}
{"op":"mcm","clk":"11810770730","pt":1722750918268,"mc":[{"id":"1.231395388","rc":[{"batb":[[0,2.12,36.06],[1,1.81,36.34],[2,1.25,100]],"ltp":2.22,"tv":30.42,"id":58385184}]}]}
{"op":"mcm","clk":"11810770766","pt":1722750920681,"mc":[{"id":"1.231395388","rc":[{"batb":[[0,2.14,10],[1,2.12,36.06],[2,1.81,36.34]],"ltp":2.22,"tv":30.42,"id":58385184}]}]}
{"op":"mcm","clk":"11810770832","pt":1722750924070,"mc":[{"id":"1.231395388","rc":[{"batb":[[0,2.12,36.06],[1,1.81,36.34],[2,1.25,100]],"ltp":2.22,"tv":30.42,"id":58385184}]}]}
{"op":"mcm","clk":"11810770874","pt":1722750926683,"mc":[{"id":"1.231395388","rc":[{"batb":[[0,2.14,10],[1,2.12,36.06],[2,1.81,36.34]],"ltp":2.22,"tv":30.42,"id":58385184}]}]}
{"op":"mcm","clk":"11810770935","pt":1722750930069,"mc":[{"id":"1.231395388","rc":[{"batb":[[0,2.12,36.06],[1,1.81,36.34],[2,1.25,100]],"ltp":2.22,"tv":30.42,"id":58385184}]}]}
{"op":"mcm","clk":"11810770981","pt":1722750932275,"mc":[{"id":"1.231395388","rc":[{"batb":[[0,2.14,10],[1,2.12,36.06],[2,1.81,36.34]],"ltp":2.22,"tv":30.42,"id":58385184}]}]}
{"op":"mcm","clk":"11810771058","pt":1722750935583,"mc":[{"id":"1.231395388","rc":[{"batb":[[0,2.12,36.06],[1,1.81,36.34],[2,1.25,100]],"ltp":2.22,"tv":30.42,"id":58385184}]}]}
{"op":"mcm","clk":"11810771121","pt":1722750938275,"mc":[{"id":"1.231395388","rc":[{"batb":[[0,2.14,10],[1,2.12,36.06],[2,1.81,36.34]],"ltp":2.22,"tv":30.42,"id":58385184}]}]}
{"op":"mcm","clk":"11810771180","pt":1722750941464,"mc":[{"id":"1.231395388","rc":[{"batb":[[0,2.12,36.06],[1,1.81,36.34],[2,1.25,100]],"ltp":2.22,"tv":30.42,"id":58385184}]}]}
{"op":"mcm","clk":"11810771257","pt":1722750944406,"mc":[{"id":"1.231395388","rc":[{"batb":[[0,2.14,10],[1,2.12,36.06],[2,1.81,36.34]],"ltp":2.22,"tv":30.42,"id":58385184}]}]}
{"op":"mcm","clk":"11810771340","pt":1722750947904,"mc":[{"id":"1.231395388","rc":[{"batb":[[0,2.12,36.06],[1,1.81,36.34],[2,1.25,100]],"ltp":2.22,"tv":30.42,"id":58385184}]}]}
{"op":"mcm","clk":"11810771381","pt":1722750950206,"mc":[{"id":"1.231395388","rc":[{"batb":[[0,2.14,10],[1,2.12,36.06],[2,1.81,36.34]],"ltp":2.22,"tv":30.42,"id":58385184}]}]}
{"op":"mcm","clk":"11810771453","pt":1722750953592,"mc":[{"id":"1.231395388","rc":[{"batb":[[0,2.12,36.06],[1,1.81,36.34],[2,1.25,100]],"ltp":2.22,"tv":30.42,"id":58385184}]}]}
{"op":"mcm","clk":"11810771518","pt":1722750956098,"mc":[{"id":"1.231395388","rc":[{"batb":[[0,2.14,10],[1,2.12,36.06],[2,1.81,36.34]],"ltp":2.22,"tv":30.42,"id":58385184}]}]}
{"op":"mcm","clk":"11810771584","pt":1722750959485,"mc":[{"id":"1.231395388","rc":[{"batb":[[0,2.12,36.06],[1,1.81,36.34],[2,1.25,100]],"ltp":2.22,"tv":30.42,"id":58385184}]}]}
{"op":"mcm","clk":"11810771687","pt":1722750964612,"mc":[{"id":"1.231395388","rc":[{"batb":[[0,2.14,10],[1,2.12,36.06],[2,1.81,36.34]],"ltp":2.22,"tv":30.42,"id":58385184}]}]}
{"op":"mcm","clk":"11810771785","pt":1722750968196,"mc":[{"id":"1.231395388","rc":[{"batb":[[0,2.12,36.06],[1,1.81,36.34],[2,1.25,100]],"ltp":2.22,"tv":30.42,"id":58385184}]}]}
{"op":"mcm","clk":"11810771862","pt":1722750971993,"mc":[{"id":"1.231395388","rc":[{"batb":[[0,2.14,10],[1,2.12,36.06],[2,1.81,36.34]],"ltp":2.22,"tv":30.42,"id":58385184}]}]}
{"op":"mcm","clk":"11810771910","pt":1722750975530,"mc":[{"id":"1.231395388","rc":[{"batb":[[0,2.12,36.06],[1,1.81,36.34],[2,1.25,100]],"ltp":2.22,"tv":30.42,"id":58385184}]}]}
{"op":"mcm","clk":"11810771960","pt":1722750978409,"mc":[{"id":"1.231395388","rc":[{"batb":[[0,2.14,10],[1,2.12,36.06],[2,1.81,36.34]],"ltp":2.22,"tv":30.42,"id":58385184}]}]}
{"op":"mcm","clk":"11810772030","pt":1722750981836,"mc":[{"id":"1.231395388","rc":[{"batb":[[0,2.12,36.06],[1,1.81,36.34],[2,1.25,100]],"ltp":2.22,"tv":30.42,"id":58385184}]}]}
{"op":"mcm","clk":"11810772087","pt":1722750984209,"mc":[{"id":"1.231395388","rc":[{"batb":[[0,2.14,10],[1,2.12,36.06],[2,1.81,36.34]],"ltp":2.22,"tv":30.42,"id":58385184}]}]}
{"op":"mcm","clk":"11810772151","pt":1722750987538,"mc":[{"id":"1.231395388","rc":[{"batb":[[0,2.12,36.06],[1,1.81,36.34],[2,1.25,100]],"ltp":2.22,"tv":30.42,"id":58385184}]}]}
{"op":"mcm","clk":"11810772212","pt":1722750989944,"mc":[{"id":"1.231395388","rc":[{"batb":[[0,2.14,10],[1,2.12,36.06],[2,1.81,36.34]],"ltp":2.22,"tv":30.42,"id":58385184}]}]}
{"op":"mcm","clk":"11810772296","pt":1722750993322,"mc":[{"id":"1.231395388","rc":[{"batb":[[0,2.12,36.06],[1,1.81,36.34],[2,1.25,100]],"ltp":2.22,"tv":30.42,"id":58385184}]}]}
{"op":"mcm","clk":"11810772373","pt":1722750996927,"mc":[{"id":"1.231395388","rc":[{"batb":[[0,2.14,10],[1,2.12,36.06],[2,1.81,36.34]],"ltp":2.22,"tv":30.42,"id":58385184}]}]}
{"op":"mcm","clk":"11810772450","pt":1722751000363,"mc":[{"id":"1.231395388","rc":[{"batb":[[0,2.12,36.06],[1,1.81,36.34],[2,1.25,100]],"ltp":2.22,"tv":30.42,"id":58385184}]}]}
{"op":"mcm","clk":"11810772533","pt":1722751003544,"mc":[{"id":"1.231395388","rc":[{"batb":[[0,2.14,10],[1,2.12,36.06],[2,1.81,36.34]],"ltp":2.22,"tv":30.42,"id":58385184}]}]}
{"op":"mcm","clk":"11810772602","pt":1722751006837,"mc":[{"id":"1.231395388","rc":[{"batb":[[0,2.12,36.06],[1,1.81,36.34],[2,1.25,100]],"ltp":2.22,"tv":30.42,"id":58385184}]}]}
{"op":"mcm","clk":"11810772675","pt":1722751009346,"mc":[{"id":"1.231395388","rc":[{"batb":[[0,2.14,10],[1,2.12,36.06],[2,1.81,36.34]],"ltp":2.22,"tv":30.42,"id":58385184}]}]}
{"op":"mcm","clk":"11810772800","pt":1722751012774,"mc":[{"id":"1.231395388","rc":[{"batb":[[0,2.12,36.06],[1,1.81,36.34],[2,1.25,100]],"ltp":2.22,"tv":30.42,"id":58385184}]}]}
{"op":"mcm","clk":"11810772853","pt":1722751015134,"mc":[{"id":"1.231395388","rc":[{"batb":[[0,2.14,10],[1,2.12,36.06],[2,1.81,36.34]],"ltp":2.22,"tv":30.42,"id":58385184}]}]}
{"op":"mcm","clk":"11810772933","pt":1722751018469,"mc":[{"id":"1.231395388","rc":[{"batb":[[0,2.12,36.06],[1,1.81,36.34],[2,1.25,100]],"ltp":2.22,"tv":30.42,"id":58385184}]}]}
{"op":"mcm","clk":"11810773023","pt":1722751021856,"mc":[{"id":"1.231395388","rc":[{"batb":[[0,2.14,10],[1,2.12,36.06],[2,1.81,36.34]],"ltp":2.22,"tv":30.42,"id":58385184}]}]}
{"op":"mcm","clk":"11810773093","pt":1722751025282,"mc":[{"id":"1.231395388","rc":[{"batb":[[0,2.12,36.06],[1,1.81,36.34],[2,1.25,100]],"ltp":2.22,"tv":30.42,"id":58385184}]}]}
{"op":"mcm","clk":"11810773195","pt":1722751029966,"mc":[{"id":"1.231395388","rc":[{"batb":[[0,2.14,10],[1,2.12,36.06],[2,1.81,36.34]],"ltp":2.22,"tv":30.42,"id":58385184}]}]}
{"op":"mcm","clk":"11810773276","pt":1722751033292,"mc":[{"id":"1.231395388","rc":[{"batb":[[0,2.12,36.06],[1,1.81,36.34],[2,1.25,100]],"ltp":2.22,"tv":30.42,"id":58385184}]}]}
{"op":"mcm","clk":"11810773330","pt":1722751036065,"mc":[{"id":"1.231395388","rc":[{"batb":[[0,2.14,10],[1,2.12,36.06],[2,1.81,36.34]],"ltp":2.22,"tv":30.42,"id":58385184}]}]}
{"op":"mcm","clk":"11810773382","pt":1722751039483,"mc":[{"id":"1.231395388","rc":[{"batb":[[0,2.12,36.06],[1,1.81,36.34],[2,1.25,100]],"ltp":2.22,"tv":30.42,"id":58385184}]}]}
{"op":"mcm","clk":"11810773457","pt":1722751044285,"mc":[{"id":"1.231395388","rc":[{"batb":[[0,2.14,10],[1,2.12,36.06],[2,1.81,36.34]],"ltp":2.22,"tv":30.42,"id":58385184}]}]}
{"op":"mcm","clk":"11810773528","pt":1722751047914,"mc":[{"id":"1.231395388","rc":[{"batb":[[0,2.12,36.06],[1,1.81,36.34],[2,1.25,100]],"ltp":2.22,"tv":30.42,"id":58385184}]}]}
{"op":"mcm","clk":"11810773588","pt":1722751050882,"mc":[{"id":"1.231395388","rc":[{"batb":[[0,2.14,10],[1,2.12,36.06],[2,1.81,36.34]],"ltp":2.22,"tv":30.42,"id":58385184}]}]}
{"op":"mcm","clk":"11810773653","pt":1722751054308,"mc":[{"id":"1.231395388","rc":[{"batb":[[0,2.12,36.06],[1,1.81,36.34],[2,1.25,100]],"ltp":2.22,"tv":30.42,"id":58385184}]}]}
{"op":"mcm","clk":"11810773705","pt":1722751056512,"mc":[{"id":"1.231395388","rc":[{"batb":[[0,2.14,10],[1,2.12,36.06],[2,1.81,36.34]],"ltp":2.22,"tv":30.42,"id":58385184}]}]}
{"op":"mcm","clk":"11810773781","pt":1722751059686,"mc":[{"id":"1.231395388","rc":[{"batb":[[0,2.12,36.06],[1,1.81,36.34],[2,1.25,100]],"ltp":2.22,"tv":30.42,"id":58385184}]}]}
{"op":"mcm","clk":"11810773875","pt":1722751063805,"mc":[{"id":"1.231395388","rc":[{"batb":[[0,2.14,10],[1,2.12,36.06],[2,1.81,36.34]],"ltp":2.22,"tv":30.42,"id":58385184}]}]}
{"op":"mcm","clk":"11810773939","pt":1722751067136,"mc":[{"id":"1.231395388","rc":[{"batb":[[0,2.12,36.06],[1,1.81,36.34],[2,1.25,100]],"ltp":2.22,"tv":30.42,"id":58385184}]}]}
{"op":"mcm","clk":"11810774001","pt":1722751070410,"mc":[{"id":"1.231395388","rc":[{"batb":[[0,2.14,10],[1,2.12,36.06],[2,1.81,36.34]],"ltp":2.22,"tv":30.42,"id":58385184}]}]}
{"op":"mcm","clk":"11810774076","pt":1722751073743,"mc":[{"id":"1.231395388","rc":[{"batb":[[0,2.12,36.06],[1,1.81,36.34],[2,1.25,100]],"ltp":2.22,"tv":30.42,"id":58385184}]}]}
{"op":"mcm","clk":"11810774172","pt":1722751078306,"mc":[{"id":"1.231395388","rc":[{"batb":[[0,2.14,10],[1,2.12,36.06],[2,1.81,36.34]],"ltp":2.22,"tv":30.42,"id":58385184}]}]}
{"op":"mcm","clk":"11810774249","pt":1722751081632,"mc":[{"id":"1.231395388","rc":[{"batb":[[0,2.12,36.06],[1,1.81,36.34],[2,1.25,100]],"ltp":2.22,"tv":30.42,"id":58385184}]}]}
{"op":"mcm","clk":"11810774293","pt":1722751084247,"mc":[{"id":"1.231395388","rc":[{"batb":[[0,2.14,10],[1,2.12,36.06],[2,1.81,36.34]],"ltp":2.22,"tv":30.42,"id":58385184}]}]}
{"op":"mcm","clk":"11810774389","pt":1722751087548,"mc":[{"id":"1.231395388","rc":[{"batb":[[0,2.12,36.06],[1,1.81,36.34],[2,1.25,100]],"ltp":2.22,"tv":30.42,"id":58385184}]}]}
{"op":"mcm","clk":"11810774466","pt":1722751089954,"mc":[{"id":"1.231395388","rc":[{"batb":[[0,2.14,10],[1,2.12,36.06],[2,1.81,36.34]],"ltp":2.22,"tv":30.42,"id":58385184}]}]}
{"op":"mcm","clk":"11810774563","pt":1722751093348,"mc":[{"id":"1.231395388","rc":[{"batb":[[0,2.12,36.06],[1,1.81,36.34],[2,1.25,100]],"ltp":2.22,"tv":30.42,"id":58385184}]}]}
{"op":"mcm","clk":"11810774634","pt":1722751097133,"mc":[{"id":"1.231395388","rc":[{"batb":[[0,2.14,10],[1,2.12,36.06],[2,1.81,36.34]],"ltp":2.22,"tv":30.42,"id":58385184}]}]}
{"op":"mcm","clk":"11810774706","pt":1722751100531,"mc":[{"id":"1.231395388","rc":[{"batb":[[0,2.12,36.06],[1,1.81,36.34],[2,1.25,100]],"ltp":2.22,"tv":30.42,"id":58385184}]}]}
{"op":"mcm","clk":"11810774751","pt":1722751103144,"mc":[{"id":"1.231395388","rc":[{"batb":[[0,2.14,10],[1,2.12,36.06],[2,1.81,36.34]],"ltp":2.22,"tv":30.42,"id":58385184}]}]}
{"op":"mcm","clk":"11810774831","pt":1722751106582,"mc":[{"id":"1.231395388","rc":[{"batb":[[0,2.12,36.06],[1,1.81,36.34],[2,1.25,100]],"ltp":2.22,"tv":30.42,"id":58385184}]}]}
{"op":"mcm","clk":"11810774902","pt":1722751109148,"mc":[{"id":"1.231395388","rc":[{"batb":[[0,2.14,10],[1,2.12,36.06],[2,1.81,36.34]],"ltp":2.22,"tv":30.42,"id":58385184}]}]}
{"op":"mcm","clk":"11810774966","pt":1722751112680,"mc":[{"id":"1.231395388","rc":[{"batb":[[0,2.12,36.06],[1,1.81,36.34],[2,1.25,100]],"ltp":2.22,"tv":30.42,"id":58385184}]}]}
{"op":"mcm","clk":"11810775036","pt":1722751116191,"mc":[{"id":"1.231395388","rc":[{"batb":[[0,2.14,10],[1,2.12,36.06],[2,1.81,36.34]],"ltp":2.22,"tv":30.42,"id":58385184}]}]}
{"op":"mcm","clk":"11810775109","pt":1722751119381,"mc":[{"id":"1.231395388","rc":[{"batb":[[0,2.12,36.06],[1,1.81,36.34],[2,1.25,100]],"ltp":2.22,"tv":30.42,"id":58385184}]}]}
{"op":"mcm","clk":"11810775158","pt":1722751121992,"mc":[{"id":"1.231395388","rc":[{"batb":[[0,2.14,10],[1,2.12,36.06],[2,1.81,36.34]],"ltp":2.22,"tv":30.42,"id":58385184}]}]}
{"op":"mcm","clk":"11810775229","pt":1722751125475,"mc":[{"id":"1.231395388","rc":[{"batb":[[0,2.12,36.06],[1,1.81,36.34],[2,1.25,100]],"ltp":2.22,"tv":30.42,"id":58385184}]}]}
{"op":"mcm","clk":"11810775303","pt":1722751128459,"mc":[{"id":"1.231395388","rc":[{"batb":[[0,2.14,10],[1,2.12,36.06],[2,1.81,36.34]],"ltp":2.22,"tv":30.42,"id":58385184}]}]}
{"op":"mcm","clk":"11810775347","pt":1722751131683,"mc":[{"id":"1.231395388","rc":[{"batb":[[0,2.12,36.06],[1,1.81,36.34],[2,1.25,100]],"ltp":2.22,"tv":30.42,"id":58385184}]}]}
{"op":"mcm","clk":"11810775385","pt":1722751134196,"mc":[{"id":"1.231395388","rc":[{"batb":[[0,2.14,10],[1,2.12,36.06],[2,1.81,36.34]],"ltp":2.22,"tv":30.42,"id":58385184}]}]}
{"op":"mcm","clk":"11810775440","pt":1722751137677,"mc":[{"id":"1.231395388","rc":[{"batb":[[0,2.12,36.06],[1,1.81,36.34],[2,1.25,100]],"ltp":2.22,"tv":30.42,"id":58385184}]}]}
{"op":"mcm","clk":"11810775501","pt":1722751140196,"mc":[{"id":"1.231395388","rc":[{"batb":[[0,2.14,10],[1,2.12,36.06],[2,1.81,36.34]],"ltp":2.22,"tv":30.42,"id":58385184}]}]}
{"op":"mcm","clk":"11810775593","pt":1722751143388,"mc":[{"id":"1.231395388","rc":[{"batb":[[0,2.12,36.06],[1,1.81,36.34],[2,1.25,100]],"ltp":2.22,"tv":30.42,"id":58385184}]}]}
{"op":"mcm","clk":"11810775646","pt":1722751146473,"mc":[{"id":"1.231395388","rc":[{"batb":[[0,2.14,10],[1,2.12,36.06],[2,1.81,36.34]],"ltp":2.22,"tv":30.42,"id":58385184}]}]}
{"op":"mcm","clk":"11810775728","pt":1722751149807,"mc":[{"id":"1.231395388","rc":[{"batb":[[0,2.12,36.06],[1,1.81,36.34],[2,1.25,100]],"ltp":2.22,"tv":30.42,"id":58385184}]}]}
{"op":"mcm","clk":"11810775777","pt":1722751152108,"mc":[{"id":"1.231395388","rc":[{"batb":[[0,2.14,10],[1,2.12,36.06],[2,1.81,36.34]],"ltp":2.22,"tv":30.42,"id":58385184}]}]}
{"op":"mcm","clk":"11810775814","pt":1722751155393,"mc":[{"id":"1.231395388","rc":[{"batb":[[0,2.12,36.06],[1,1.81,36.34],[2,1.25,100]],"ltp":2.22,"tv":30.42,"id":58385184}]}]}
{"op":"mcm","clk":"11810775852","pt":1722751157908,"mc":[{"id":"1.231395388","rc":[{"batb":[[0,2.14,10],[1,2.12,36.06],[2,1.81,36.34]],"ltp":2.22,"tv":30.42,"id":58385184}]}]}
{"op":"mcm","clk":"11810775918","pt":1722751161292,"mc":[{"id":"1.231395388","rc":[{"batb":[[0,2.12,36.06],[1,1.81,36.34],[2,1.25,100]],"ltp":2.22,"tv":30.42,"id":58385184}]}]}
{"op":"mcm","clk":"11810775955","pt":1722751164322,"mc":[{"id":"1.231395388","rc":[{"batb":[[0,2.14,10],[1,2.12,36.06],[2,1.81,36.34]],"ltp":2.22,"tv":30.42,"id":58385184}]}]}
{"op":"mcm","clk":"11810776032","pt":1722751167831,"mc":[{"id":"1.231395388","rc":[{"batb":[[0,2.12,36.06],[1,1.81,36.34],[2,1.25,100]],"ltp":2.22,"tv":30.42,"id":58385184}]}]}
{"op":"mcm","clk":"11810776073","pt":1722751170506,"mc":[{"id":"1.231395388","rc":[{"batb":[[0,2.14,10],[1,2.12,36.06],[2,1.81,36.34]],"ltp":2.22,"tv":30.42,"id":58385184}]}]}
{"op":"mcm","clk":"11810776106","pt":1722751173830,"mc":[{"id":"1.231395388","rc":[{"batb":[[0,2.12,36.06],[1,1.81,36.34],[2,1.25,100]],"ltp":2.22,"tv":30.42,"id":58385184}]}]}
{"op":"mcm","clk":"11810776146","pt":1722751176910,"mc":[{"id":"1.231395388","rc":[{"batb":[[0,2.14,10],[1,2.12,36.06],[2,1.81,36.34]],"ltp":2.22,"tv":30.42,"id":58385184}]}]}
{"op":"mcm","clk":"11810776210","pt":1722751180406,"mc":[{"id":"1.231395388","rc":[{"batb":[[0,2.12,36.06],[1,1.81,36.34],[2,1.25,100]],"ltp":2.22,"tv":30.42,"id":58385184}]}]}
{"op":"mcm","clk":"11810776267","pt":1722751183944,"mc":[{"id":"1.231395388","rc":[{"batb":[[0,2.14,10],[1,2.12,36.06],[2,1.81,36.34]],"ltp":2.22,"tv":30.42,"id":58385184}]}]}
{"op":"mcm","clk":"11810776324","pt":1722751187227,"mc":[{"id":"1.231395388","rc":[{"batb":[[0,2.12,36.06],[1,1.81,36.34],[2,1.25,100]],"ltp":2.22,"tv":30.42,"id":58385184}]}]}
{"op":"mcm","clk":"11810776379","pt":1722751189737,"mc":[{"id":"1.231395388","rc":[{"batb":[[0,2.14,10],[1,2.12,36.06],[2,1.81,36.34]],"ltp":2.22,"tv":30.42,"id":58385184}]}]}
{"op":"mcm","clk":"11810776434","pt":1722751193025,"mc":[{"id":"1.231395388","rc":[{"batb":[[0,2.12,36.06],[1,1.81,36.34],[2,1.25,100]],"ltp":2.22,"tv":30.42,"id":58385184}]}]}
{"op":"mcm","clk":"11810776491","pt":1722751196820,"mc":[{"id":"1.231395388","rc":[{"batb":[[0,2.14,10],[1,2.12,36.06],[2,1.81,36.34]],"ltp":2.22,"tv":30.42,"id":58385184}]}]}
{"op":"mcm","clk":"11810776550","pt":1722751200055,"mc":[{"id":"1.231395388","rc":[{"batb":[[0,2.12,36.06],[1,1.81,36.34],[2,1.25,100]],"ltp":2.22,"tv":30.42,"id":58385184}]}]}
{"op":"mcm","clk":"11810776645","pt":1722751202252,"mc":[{"id":"1.231395388","rc":[{"batb":[[0,2.14,10],[1,2.12,36.06],[2,1.81,36.34]],"ltp":2.22,"tv":30.42,"id":58385184}]}]}
{"op":"mcm","clk":"11810776761","pt":1722751205452,"mc":[{"id":"1.231395388","rc":[{"batb":[[0,2.12,36.06],[1,1.81,36.34],[2,1.25,100]],"ltp":2.22,"tv":30.42,"id":58385184}]}]}
{"op":"mcm","clk":"11810776823","pt":1722751208841,"mc":[{"id":"1.231395388","rc":[{"batb":[[0,2.14,10],[1,2.12,36.06],[2,1.81,36.34]],"ltp":2.22,"tv":30.42,"id":58385184}]}]}
{"op":"mcm","clk":"11810776880","pt":1722751212281,"mc":[{"id":"1.231395388","rc":[{"batb":[[0,2.12,36.06],[1,1.81,36.34],[2,1.25,100]],"ltp":2.22,"tv":30.42,"id":58385184}]}]}
{"op":"mcm","clk":"11810776960","pt":1722751215247,"mc":[{"id":"1.231395388","rc":[{"batb":[[0,2.14,10],[1,2.12,36.06],[2,1.81,36.34]],"ltp":2.22,"tv":30.42,"id":58385184}]}]}
{"op":"mcm","clk":"11810777033","pt":1722751218591,"mc":[{"id":"1.231395388","rc":[{"batb":[[0,2.12,36.06],[1,1.81,36.34],[2,1.25,100]],"ltp":2.22,"tv":30.42,"id":58385184}]}]}
{"op":"mcm","clk":"11810777092","pt":1722751221565,"mc":[{"id":"1.231395388","rc":[{"batb":[[0,2.14,10],[1,2.12,36.06],[2,1.81,36.34]],"ltp":2.22,"tv":30.42,"id":58385184}]}]}
{"op":"mcm","clk":"11810777156","pt":1722751224999,"mc":[{"id":"1.231395388","rc":[{"batb":[[0,2.12,36.06],[1,1.81,36.34],[2,1.25,100]],"ltp":2.22,"tv":30.42,"id":58385184}]}]}
{"op":"mcm","clk":"11810777193","pt":1722751227260,"mc":[{"id":"1.231395388","rc":[{"batb":[[0,2.14,10],[1,2.12,36.06],[2,1.81,36.34]],"ltp":2.22,"tv":30.42,"id":58385184}]}]}
{"op":"mcm","clk":"11810777254","pt":1722751230688,"mc":[{"id":"1.231395388","rc":[{"batb":[[0,2.12,36.06],[1,1.81,36.34],[2,1.25,100]],"ltp":2.22,"tv":30.42,"id":58385184}]}]}
{"op":"mcm","clk":"11810777305","pt":1722751232992,"mc":[{"id":"1.231395388","rc":[{"batb":[[0,2.14,10],[1,2.12,36.06],[2,1.81,36.34]],"ltp":2.22,"tv":30.42,"id":58385184}]}]}
{"op":"mcm","clk":"11810777383","pt":1722751236482,"mc":[{"id":"1.231395388","rc":[{"batb":[[0,2.12,36.06],[1,1.81,36.34],[2,1.25,100]],"ltp":2.22,"tv":30.42,"id":58385184}]}]}
{"op":"mcm","clk":"11810777439","pt":1722751239207,"mc":[{"id":"1.231395388","rc":[{"batb":[[0,2.14,10],[1,2.12,36.06],[2,1.81,36.34]],"ltp":2.22,"tv":30.42,"id":58385184}]}]}
{"op":"mcm","clk":"11810777480","pt":1722751242590,"mc":[{"id":"1.231395388","rc":[{"batb":[[0,2.12,36.06],[1,1.81,36.34],[2,1.25,100]],"ltp":2.22,"tv":30.42,"id":58385184}]}]}
{"op":"mcm","clk":"11810777514","pt":1722751244689,"mc":[{"id":"1.231395388","rc":[{"batb":[[0,2.14,10],[1,2.12,36.06],[2,1.81,36.34]],"ltp":2.22,"tv":30.42,"id":58385184}]}]}
{"op":"mcm","clk":"11810777565","pt":1722751248125,"mc":[{"id":"1.231395388","rc":[{"batb":[[0,2.12,36.06],[1,1.81,36.34],[2,1.25,100]],"ltp":2.22,"tv":30.42,"id":58385184}]}]}
{"op":"mcm","clk":"11810777687","pt":1722751254107,"mc":[{"id":"1.231395388","rc":[{"batb":[[0,2.14,10],[1,2.12,36.06],[2,1.81,36.34]],"ltp":2.22,"tv":30.42,"id":58385184}]}]}
{"op":"mcm","clk":"11810777754","pt":1722751257332,"mc":[{"id":"1.231395388","rc":[{"batb":[[0,2.12,36.06],[1,1.81,36.34],[2,1.25,100]],"ltp":2.22,"tv":30.42,"id":58385184}]}]}
{"op":"mcm","clk":"11810777804","pt":1722751260094,"mc":[{"id":"1.231395388","rc":[{"batb":[[0,2.14,10],[1,2.12,36.06],[2,1.81,36.34]],"ltp":2.22,"tv":30.42,"id":58385184}]}]}
{"op":"mcm","clk":"11810777877","pt":1722751263429,"mc":[{"id":"1.231395388","rc":[{"batb":[[0,2.12,36.06],[1,1.81,36.34],[2,1.25,100]],"ltp":2.22,"tv":30.42,"id":58385184}]}]}
{"op":"mcm","clk":"11810777927","pt":1722751265732,"mc":[{"id":"1.231395388","rc":[{"batb":[[0,2.14,10],[1,2.12,36.06],[2,1.81,36.34]],"ltp":2.22,"tv":30.42,"id":58385184}]}]}
{"op":"mcm","clk":"11810777989","pt":1722751268919,"mc":[{"id":"1.231395388","rc":[{"batb":[[0,2.12,36.06],[1,1.81,36.34],[2,1.25,100]],"ltp":2.22,"tv":30.42,"id":58385184}]}]}
{"op":"mcm","clk":"11810778030","pt":1722751271631,"mc":[{"id":"1.231395388","rc":[{"batb":[[0,2.14,10],[1,2.12,36.06],[2,1.81,36.34]],"ltp":2.22,"tv":30.42,"id":58385184}]}]}
{"op":"mcm","clk":"11810778090","pt":1722751274952,"mc":[{"id":"1.231395388","rc":[{"batb":[[0,2.12,36.06],[1,1.81,36.34],[2,1.25,100]],"ltp":2.22,"tv":30.42,"id":58385184}]}]}
{"op":"mcm","clk":"11810778175","pt":1722751278537,"mc":[{"id":"1.231395388","rc":[{"batb":[[0,2.14,10],[1,2.12,36.06],[2,1.81,36.34]],"ltp":2.22,"tv":30.42,"id":58385184}]}]}
{"op":"mcm","clk":"11810778267","pt":1722751281922,"mc":[{"id":"1.231395388","rc":[{"batb":[[0,2.12,36.06],[1,1.81,36.34],[2,1.25,100]],"ltp":2.22,"tv":30.42,"id":58385184}]}]}
{"op":"mcm","clk":"11810778336","pt":1722751284234,"mc":[{"id":"1.231395388","rc":[{"batb":[[0,2.14,10],[1,2.12,36.06],[2,1.81,36.34]],"ltp":2.22,"tv":30.42,"id":58385184}]}]}
{"op":"mcm","clk":"11810778411","pt":1722751287562,"mc":[{"id":"1.231395388","rc":[{"batb":[[0,2.12,36.06],[1,1.81,36.34],[2,1.25,100]],"ltp":2.22,"tv":30.42,"id":58385184}]}]}
{"op":"mcm","clk":"11810778452","pt":1722751289869,"mc":[{"id":"1.231395388","rc":[{"batb":[[0,2.14,10],[1,2.12,36.06],[2,1.81,36.34]],"ltp":2.22,"tv":30.42,"id":58385184}]}]}
{"op":"mcm","clk":"11810778529","pt":1722751293257,"mc":[{"id":"1.231395388","rc":[{"batb":[[0,2.12,36.06],[1,1.81,36.34],[2,1.25,100]],"ltp":2.22,"tv":30.42,"id":58385184}]}]}
{"op":"mcm","clk":"11810778583","pt":1722751295945,"mc":[{"id":"1.231395388","rc":[{"batb":[[0,2.14,10],[1,2.12,36.06],[2,1.81,36.34]],"ltp":2.22,"tv":30.42,"id":58385184}]}]}
{"op":"mcm","clk":"11810778649","pt":1722751299239,"mc":[{"id":"1.231395388","rc":[{"batb":[[0,2.12,36.06],[1,1.81,36.34],[2,1.25,100]],"ltp":2.22,"tv":30.42,"id":58385184}]}]}
{"op":"mcm","clk":"11810778714","pt":1722751301855,"mc":[{"id":"1.231395388","rc":[{"batb":[[0,2.14,10],[1,2.12,36.06],[2,1.81,36.34]],"ltp":2.22,"tv":30.42,"id":58385184}]}]}
{"op":"mcm","clk":"11810778801","pt":1722751305387,"mc":[{"id":"1.231395388","rc":[{"batb":[[0,2.12,36.06],[1,1.81,36.34],[2,1.25,100]],"ltp":2.22,"tv":30.42,"id":58385184}]}]}
{"op":"mcm","clk":"11810778852","pt":1722751307493,"mc":[{"id":"1.231395388","rc":[{"batb":[[0,2.14,10],[1,2.12,36.06],[2,1.81,36.34]],"ltp":2.22,"tv":30.42,"id":58385184}]}]}
{"op":"mcm","clk":"11810778915","pt":1722751310973,"mc":[{"id":"1.231395388","rc":[{"batb":[[0,2.12,36.06],[1,1.81,36.34],[2,1.25,100]],"ltp":2.22,"tv":30.42,"id":58385184}]}]}
{"op":"mcm","clk":"11810778972","pt":1722751313380,"mc":[{"id":"1.231395388","rc":[{"batb":[[0,2.14,10],[1,2.12,36.06],[2,1.81,36.34]],"ltp":2.22,"tv":30.42,"id":58385184}]}]}
{"op":"mcm","clk":"11810779054","pt":1722751316802,"mc":[{"id":"1.231395388","rc":[{"batb":[[0,2.12,36.06],[1,1.81,36.34],[2,1.25,100]],"ltp":2.22,"tv":30.42,"id":58385184}]}]}
{"op":"mcm","clk":"11810779130","pt":1722751319874,"mc":[{"id":"1.231395388","rc":[{"batb":[[0,2.14,10],[1,2.12,36.06],[2,1.81,36.34]],"ltp":2.22,"tv":30.42,"id":58385184}]}]}
{"op":"mcm","clk":"11810779189","pt":1722751323410,"mc":[{"id":"1.231395388","rc":[{"batb":[[0,2.12,36.06],[1,1.81,36.34],[2,1.25,100]],"ltp":2.22,"tv":30.42,"id":58385184}]}]}
{"op":"mcm","clk":"11810779297","pt":1722751327206,"mc":[{"id":"1.231395388","rc":[{"batb":[[0,2.14,10],[1,2.12,36.06],[2,1.81,36.34]],"ltp":2.22,"tv":30.42,"id":58385184}]}]}
{"op":"mcm","clk":"11810779372","pt":1722751330601,"mc":[{"id":"1.231395388","rc":[{"batb":[[0,2.12,36.06],[1,1.81,36.34],[2,1.25,100]],"ltp":2.22,"tv":30.42,"id":58385184}]}]}
{"op":"mcm","clk":"11810779437","pt":1722751333320,"mc":[{"id":"1.231395388","rc":[{"batb":[[0,2.14,10],[1,2.12,36.06],[2,1.81,36.34]],"ltp":2.22,"tv":30.42,"id":58385184}]}]}
{"op":"mcm","clk":"11810779496","pt":1722751336700,"mc":[{"id":"1.231395388","rc":[{"batb":[[0,2.12,36.06],[1,1.81,36.34],[2,1.25,100]],"ltp":2.22,"tv":30.42,"id":58385184}]}]}
{"op":"mcm","clk":"11810779560","pt":1722751339782,"mc":[{"id":"1.231395388","rc":[{"batb":[[0,2.14,10],[1,2.12,36.06],[2,1.81,36.34]],"ltp":2.22,"tv":30.42,"id":58385184}]}]}
{"op":"mcm","clk":"11810779632","pt":1722751343116,"mc":[{"id":"1.231395388","rc":[{"batb":[[0,2.12,36.06],[1,1.81,36.34],[2,1.25,100]],"ltp":2.22,"tv":30.42,"id":58385184}]}]}
{"op":"mcm","clk":"11810779709","pt":1722751347727,"mc":[{"id":"1.231395388","rc":[{"batb":[[0,2.14,10],[1,2.12,36.06],[2,1.81,36.34]],"ltp":2.22,"tv":30.42,"id":58385184}]}]}
{"op":"mcm","clk":"11810779773","pt":1722751351008,"mc":[{"id":"1.231395388","rc":[{"batb":[[0,2.12,36.06],[1,1.81,36.34],[2,1.25,100]],"ltp":2.22,"tv":30.42,"id":58385184}]}]}
{"op":"mcm","clk":"11810779846","pt":1722751353834,"mc":[{"id":"1.231395388","rc":[{"batb":[[0,2.14,10],[1,2.12,36.06],[2,1.81,36.34]],"ltp":2.22,"tv":30.42,"id":58385184}]}]}
{"op":"mcm","clk":"11810779922","pt":1722751357228,"mc":[{"id":"1.231395388","rc":[{"batb":[[0,2.12,36.06],[1,1.81,36.34],[2,1.25,100]],"ltp":2.22,"tv":30.42,"id":58385184}]}]}
{"op":"mcm","clk":"11810779963","pt":1722751359941,"mc":[{"id":"1.231395388","rc":[{"batb":[[0,2.14,10],[1,2.12,36.06],[2,1.81,36.34]],"ltp":2.22,"tv":30.42,"id":58385184}]}]}
{"op":"mcm","clk":"11810780021","pt":1722751363321,"mc":[{"id":"1.231395388","rc":[{"batb":[[0,2.12,36.06],[1,1.81,36.34],[2,1.25,100]],"ltp":2.22,"tv":30.42,"id":58385184}]}]}
{"op":"mcm","clk":"11810780088","pt":1722751366553,"mc":[{"id":"1.231395388","rc":[{"batb":[[0,2.14,10],[1,2.12,36.06],[2,1.81,36.34]],"ltp":2.22,"tv":30.42,"id":58385184}]}]}
{"op":"mcm","clk":"11810780158","pt":1722751369739,"mc":[{"id":"1.231395388","rc":[{"batb":[[0,2.12,36.06],[1,1.81,36.34],[2,1.25,100]],"ltp":2.22,"tv":30.42,"id":58385184}]}]}
{"op":"mcm","clk":"11810780230","pt":1722751373355,"mc":[{"id":"1.231395388","rc":[{"batb":[[0,2.14,10],[1,2.12,36.06],[2,1.81,36.34]],"ltp":2.22,"tv":30.42,"id":58385184}]}]}
{"op":"mcm","clk":"11810780284","pt":1722751376538,"mc":[{"id":"1.231395388","rc":[{"batb":[[0,2.12,36.06],[1,1.81,36.34],[2,1.25,100]],"ltp":2.22,"tv":30.42,"id":58385184}]}]}
{"op":"mcm","clk":"11810780336","pt":1722751379869,"mc":[{"id":"1.231395388","rc":[{"batb":[[0,2.14,10],[1,2.12,36.06],[2,1.81,36.34]],"ltp":2.22,"tv":30.42,"id":58385184}]}]}
{"op":"mcm","clk":"11810780394","pt":1722751383159,"mc":[{"id":"1.231395388","rc":[{"batb":[[0,2.12,36.06],[1,1.81,36.34],[2,1.25,100]],"ltp":2.22,"tv":30.42,"id":58385184}]}]}
{"op":"mcm","clk":"11810780450","pt":1722751385572,"mc":[{"id":"1.231395388","rc":[{"batb":[[0,2.14,10],[1,2.12,36.06],[2,1.81,36.34]],"ltp":2.22,"tv":30.42,"id":58385184}]}]}
{"op":"mcm","clk":"11810780495","pt":1722751388964,"mc":[{"id":"1.231395388","rc":[{"batb":[[0,2.12,36.06],[1,1.81,36.34],[2,1.25,100]],"ltp":2.22,"tv":30.42,"id":58385184}]}]}
{"op":"mcm","clk":"11810780562","pt":1722751392874,"mc":[{"id":"1.231395388","rc":[{"batb":[[0,2.14,10],[1,2.12,36.06],[2,1.81,36.34]],"ltp":2.22,"tv":30.42,"id":58385184}]}]}
{"op":"mcm","clk":"11810780650","pt":1722751396261,"mc":[{"id":"1.231395388","rc":[{"batb":[[0,2.12,36.06],[1,1.81,36.34],[2,1.25,100]],"ltp":2.22,"tv":30.42,"id":58385184}]}]}
{"op":"mcm","clk":"11810780707","pt":1722751399178,"mc":[{"id":"1.231395388","rc":[{"batb":[[0,2.14,10],[1,2.12,36.06],[2,1.81,36.34]],"ltp":2.22,"tv":30.42,"id":58385184}]}]}
{"op":"mcm","clk":"11810780783","pt":1722751402673,"mc":[{"id":"1.231395388","rc":[{"batb":[[0,2.12,36.06],[1,1.81,36.34],[2,1.25,100]],"ltp":2.22,"tv":30.42,"id":58385184}]}]}
{"op":"mcm","clk":"11810780829","pt":1722751405193,"mc":[{"id":"1.231395388","rc":[{"batb":[[0,2.14,10],[1,2.12,36.06],[2,1.81,36.34]],"ltp":2.22,"tv":30.42,"id":58385184}]}]}
{"op":"mcm","clk":"11810780888","pt":1722751408589,"mc":[{"id":"1.231395388","rc":[{"batb":[[0,2.12,36.06],[1,1.81,36.34],[2,1.25,100]],"ltp":2.22,"tv":30.42,"id":58385184}]}]}
{"op":"mcm","clk":"11810780967","pt":1722751412576,"mc":[{"id":"1.231395388","rc":[{"batb":[[0,2.14,10],[1,2.12,36.06],[2,1.81,36.34]],"ltp":2.22,"tv":30.42,"id":58385184}]}]}
{"op":"mcm","clk":"11810781044","pt":1722751415872,"mc":[{"id":"1.231395388","rc":[{"batb":[[0,2.12,36.06],[1,1.81,36.34],[2,1.25,100]],"ltp":2.22,"tv":30.42,"id":58385184}]}]}
{"op":"mcm","clk":"11810781075","pt":1722751418290,"mc":[{"id":"1.231395388","rc":[{"batb":[[0,2.14,10],[1,2.12,36.06],[2,1.81,36.34]],"ltp":2.22,"tv":30.42,"id":58385184}]}]}
{"op":"mcm","clk":"11810781142","pt":1722751421586,"mc":[{"id":"1.231395388","rc":[{"batb":[[0,2.12,36.06],[1,1.81,36.34],[2,1.25,100]],"ltp":2.22,"tv":30.42,"id":58385184}]}]}
{"op":"mcm","clk":"11810781185","pt":1722751425001,"mc":[{"id":"1.231395388","rc":[{"batb":[[0,2.14,10],[1,2.12,36.06],[2,1.81,36.34]],"ltp":2.22,"tv":30.42,"id":58385184}]}]}
{"op":"mcm","clk":"11810781234","pt":1722751428498,"mc":[{"id":"1.231395388","rc":[{"batb":[[0,2.12,36.06],[1,1.81,36.34],[2,1.25,100]],"ltp":2.22,"tv":30.42,"id":58385184}]}]}
{"op":"mcm","clk":"11810781294","pt":1722751431692,"mc":[{"id":"1.231395388","rc":[{"batb":[[0,2.14,10],[1,2.12,36.06],[2,1.81,36.34]],"ltp":2.22,"tv":30.42,"id":58385184}]}]}
{"op":"mcm","clk":"11810781366","pt":1722751435091,"mc":[{"id":"1.231395388","rc":[{"batb":[[0,2.12,36.06],[1,1.81,36.34],[2,1.25,100]],"ltp":2.22,"tv":30.42,"id":58385184}]}]}
{"op":"mcm","clk":"11810781425","pt":1722751437609,"mc":[{"id":"1.231395388","rc":[{"batb":[[0,2.14,10],[1,2.12,36.06],[2,1.81,36.34]],"ltp":2.22,"tv":30.42,"id":58385184}]}]}
{"op":"mcm","clk":"11810781486","pt":1722751441015,"mc":[{"id":"1.231395388","rc":[{"batb":[[0,2.12,36.06],[1,1.81,36.34],[2,1.25,100]],"ltp":2.22,"tv":30.42,"id":58385184}]}]}
{"op":"mcm","clk":"11810781528","pt":1722751443234,"mc":[{"id":"1.231395388","rc":[{"batb":[[0,2.14,10],[1,2.12,36.06],[2,1.81,36.34]],"ltp":2.22,"tv":30.42,"id":58385184}]}]}
{"op":"mcm","clk":"11810781580","pt":1722751446531,"mc":[{"id":"1.231395388","rc":[{"batb":[[0,2.12,36.06],[1,1.81,36.34],[2,1.25,100]],"ltp":2.22,"tv":30.42,"id":58385184}]}]}
{"op":"mcm","clk":"11810781646","pt":1722751450536,"mc":[{"id":"1.231395388","rc":[{"batb":[[0,2.14,10],[1,2.12,36.06],[2,1.81,36.34]],"ltp":2.22,"tv":30.42,"id":58385184}]}]}
{"op":"mcm","clk":"11810781702","pt":1722751453714,"mc":[{"id":"1.231395388","rc":[{"batb":[[0,2.12,36.06],[1,1.81,36.34],[2,1.25,100]],"ltp":2.22,"tv":30.42,"id":58385184}]}]}
{"op":"mcm","clk":"11810781729","pt":1722751456126,"mc":[{"id":"1.231395388","rc":[{"batb":[[0,2.14,10],[1,2.12,36.06],[2,1.81,36.34]],"ltp":2.22,"tv":30.42,"id":58385184}]}]}
{"op":"mcm","clk":"11810781783","pt":1722751459635,"mc":[{"id":"1.231395388","rc":[{"batb":[[0,2.12,36.06],[1,1.81,36.34],[2,1.25,100]],"ltp":2.22,"tv":30.42,"id":58385184}]}]}
{"op":"mcm","clk":"11810781860","pt":1722751462729,"mc":[{"id":"1.231395388","rc":[{"batb":[[0,2.14,10],[1,2.12,36.06],[2,1.81,36.34]],"ltp":2.22,"tv":30.42,"id":58385184}]}]}
{"op":"mcm","clk":"11810781911","pt":1722751466165,"mc":[{"id":"1.231395388","rc":[{"batb":[[0,2.12,36.06],[1,1.81,36.34],[2,1.25,100]],"ltp":2.22,"tv":30.42,"id":58385184}]}]}
{"op":"mcm","clk":"11810781939","pt":1722751468426,"mc":[{"id":"1.231395388","rc":[{"batb":[[0,2.14,10],[1,2.12,36.06],[2,1.81,36.34]],"ltp":2.22,"tv":30.42,"id":58385184}]}]}
{"op":"mcm","clk":"11810781983","pt":1722751471631,"mc":[{"id":"1.231395388","rc":[{"batb":[[0,2.12,36.06],[1,1.81,36.34],[2,1.25,100]],"ltp":2.22,"tv":30.42,"id":58385184}]}]}
{"op":"mcm","clk":"11810782063","pt":1722751475245,"mc":[{"id":"1.231395388","rc":[{"batb":[[0,2.14,10],[1,2.12,36.06],[2,1.81,36.34]],"ltp":2.22,"tv":30.42,"id":58385184}]}]}
{"op":"mcm","clk":"11810782131","pt":1722751478539,"mc":[{"id":"1.231395388","rc":[{"batb":[[0,2.12,36.06],[1,1.81,36.34],[2,1.25,100]],"ltp":2.22,"tv":30.42,"id":58385184}]}]}
{"op":"mcm","clk":"11810782179","pt":1722751480850,"mc":[{"id":"1.231395388","rc":[{"batb":[[0,2.14,10],[1,2.12,36.06],[2,1.81,36.34]],"ltp":2.22,"tv":30.42,"id":58385184}]}]}
{"op":"mcm","clk":"11810782226","pt":1722751484245,"mc":[{"id":"1.231395388","rc":[{"batb":[[0,2.12,36.06],[1,1.81,36.34],[2,1.25,100]],"ltp":2.22,"tv":30.42,"id":58385184}]}]}
{"op":"mcm","clk":"11810782267","pt":1722751486550,"mc":[{"id":"1.231395388","rc":[{"batb":[[0,2.14,10],[1,2.12,36.06],[2,1.81,36.34]],"ltp":2.22,"tv":30.42,"id":58385184}]}]}
{"op":"mcm","clk":"11810782319","pt":1722751489769,"mc":[{"id":"1.231395388","rc":[{"batb":[[0,2.12,36.06],[1,1.81,36.34],[2,1.25,100]],"ltp":2.22,"tv":30.42,"id":58385184}]}]}
{"op":"mcm","clk":"11810782379","pt":1722751492478,"mc":[{"id":"1.231395388","rc":[{"batb":[[0,2.14,10],[1,2.12,36.06],[2,1.81,36.34]],"ltp":2.22,"tv":30.42,"id":58385184}]}]}
{"op":"mcm","clk":"11810782425","pt":1722751495776,"mc":[{"id":"1.231395388","rc":[{"batb":[[0,2.12,36.06],[1,1.81,36.34],[2,1.25,100]],"ltp":2.22,"tv":30.42,"id":58385184}]}]}
{"op":"mcm","clk":"11810782490","pt":1722751499970,"mc":[{"id":"1.231395388","rc":[{"batb":[[0,2.14,10],[1,2.12,36.06],[2,1.81,36.34]],"ltp":2.22,"tv":30.42,"id":58385184}]}]}
{"op":"mcm","clk":"11810782586","pt":1722751503472,"mc":[{"id":"1.231395388","rc":[{"batb":[[0,2.12,36.06],[1,1.81,36.34],[2,1.25,100]],"ltp":2.22,"tv":30.42,"id":58385184}]}]}
{"op":"mcm","clk":"11810782632","pt":1722751506299,"mc":[{"id":"1.231395388","rc":[{"batb":[[0,2.14,10],[1,2.12,36.06],[2,1.81,36.34]],"ltp":2.22,"tv":30.42,"id":58385184}]}]}
{"op":"mcm","clk":"11810782689","pt":1722751509582,"mc":[{"id":"1.231395388","rc":[{"batb":[[0,2.12,36.06],[1,1.81,36.34],[2,1.25,100]],"ltp":2.22,"tv":30.42,"id":58385184}]}]}
{"op":"mcm","clk":"11810782756","pt":1722751512092,"mc":[{"id":"1.231395388","rc":[{"batb":[[0,2.14,10],[1,2.12,36.06],[2,1.81,36.34]],"ltp":2.22,"tv":30.42,"id":58385184}]}]}
{"op":"mcm","clk":"11810782831","pt":1722751515267,"mc":[{"id":"1.231395388","rc":[{"batb":[[0,2.12,36.06],[1,1.81,36.34],[2,1.25,100]],"ltp":2.22,"tv":30.42,"id":58385184}]}]}
{"op":"mcm","clk":"11810782895","pt":1722751517985,"mc":[{"id":"1.231395388","rc":[{"batb":[[0,2.14,10],[1,2.12,36.06],[2,1.81,36.34]],"ltp":2.22,"tv":30.42,"id":58385184}]}]}
{"op":"mcm","clk":"11810782983","pt":1722751521469,"mc":[{"id":"1.231395388","rc":[{"batb":[[0,2.12,36.06],[1,1.81,36.34],[2,1.25,100]],"ltp":2.22,"tv":30.42,"id":58385184}]}]}
{"op":"mcm","clk":"11810783084","pt":1722751524808,"mc":[{"id":"1.231395388","rc":[{"batb":[[0,2.14,10],[1,2.12,36.06],[2,1.81,36.34]],"ltp":2.22,"tv":30.42,"id":58385184}]}]}
{"op":"mcm","clk":"11810783156","pt":1722751528194,"mc":[{"id":"1.231395388","rc":[{"batb":[[0,2.12,36.06],[1,1.81,36.34],[2,1.25,100]],"ltp":2.22,"tv":30.42,"id":58385184}]}]}
{"op":"mcm","clk":"11810783197","pt":1722751530398,"mc":[{"id":"1.231395388","rc":[{"batb":[[0,2.14,10],[1,2.12,36.06],[2,1.81,36.34]],"ltp":2.22,"tv":30.42,"id":58385184}]}]}
{"op":"mcm","clk":"11810783253","pt":1722751533693,"mc":[{"id":"1.231395388","rc":[{"batb":[[0,2.12,36.06],[1,1.81,36.34],[2,1.25,100]],"ltp":2.22,"tv":30.42,"id":58385184}]}]}
{"op":"mcm","clk":"11810783282","pt":1722751536212,"mc":[{"id":"1.231395388","rc":[{"batb":[[0,2.14,10],[1,2.12,36.06],[2,1.81,36.34]],"ltp":2.22,"tv":30.42,"id":58385184}]}]}
{"op":"mcm","clk":"11810783336","pt":1722751539588,"mc":[{"id":"1.231395388","rc":[{"batb":[[0,2.12,36.06],[1,1.81,36.34],[2,1.25,100]],"ltp":2.22,"tv":30.42,"id":58385184}]}]}
{"op":"mcm","clk":"11810783372","pt":1722751541991,"mc":[{"id":"1.231395388","rc":[{"batb":[[0,2.14,10],[1,2.12,36.06],[2,1.81,36.34]],"ltp":2.22,"tv":30.42,"id":58385184}]}]}
{"op":"mcm","clk":"11810783427","pt":1722751545319,"mc":[{"id":"1.231395388","rc":[{"batb":[[0,2.12,36.06],[1,1.81,36.34],[2,1.25,100]],"ltp":2.22,"tv":30.42,"id":58385184}]}]}
{"op":"mcm","clk":"11810783475","pt":1722751547688,"mc":[{"id":"1.231395388","rc":[{"batb":[[0,2.14,10],[1,2.12,36.06],[2,1.81,36.34]],"ltp":2.22,"tv":30.42,"id":58385184}]}]}
{"op":"mcm","clk":"11810783517","pt":1722751551011,"mc":[{"id":"1.231395388","rc":[{"batb":[[0,2.12,36.06],[1,1.81,36.34],[2,1.25,100]],"ltp":2.22,"tv":30.42,"id":58385184}]}]}
{"op":"mcm","clk":"11810783583","pt":1722751553215,"mc":[{"id":"1.231395388","rc":[{"batb":[[0,2.14,10],[1,2.12,36.06],[2,1.81,36.34]],"ltp":2.22,"tv":30.42,"id":58385184}]}]}
{"op":"mcm","clk":"11810783669","pt":1722751556436,"mc":[{"id":"1.231395388","rc":[{"batb":[[0,2.12,36.06],[1,1.81,36.34],[2,1.25,100]],"ltp":2.22,"tv":30.42,"id":58385184}]}]}
{"op":"mcm","clk":"11810783733","pt":1722751559417,"mc":[{"id":"1.231395388","rc":[{"batb":[[0,2.14,10],[1,2.12,36.06],[2,1.81,36.34]],"ltp":2.22,"tv":30.42,"id":58385184}]}]}
{"op":"mcm","clk":"11810783826","pt":1722751562819,"mc":[{"id":"1.231395388","rc":[{"batb":[[0,2.12,36.06],[1,1.81,36.34],[2,1.25,100]],"ltp":2.22,"tv":30.42,"id":58385184}]}]}
{"op":"mcm","clk":"11810783866","pt":1722751565548,"mc":[{"id":"1.231395388","rc":[{"batb":[[0,2.14,10],[1,2.12,36.06],[2,1.81,36.34]],"ltp":2.22,"tv":30.42,"id":58385184}]}]}
{"op":"mcm","clk":"11810783932","pt":1722751568848,"mc":[{"id":"1.231395388","rc":[{"batb":[[0,2.12,36.06],[1,1.81,36.34],[2,1.25,100]],"ltp":2.22,"tv":30.42,"id":58385184}]}]}
{"op":"mcm","clk":"11810784007","pt":1722751573257,"mc":[{"id":"1.231395388","rc":[{"batb":[[0,2.14,10],[1,2.12,36.06],[2,1.81,36.34]],"ltp":2.22,"tv":30.42,"id":58385184}]}]}
{"op":"mcm","clk":"11810784074","pt":1722751576640,"mc":[{"id":"1.231395388","rc":[{"batb":[[0,2.12,36.06],[1,1.81,36.34],[2,1.25,100]],"ltp":2.22,"tv":30.42,"id":58385184}]}]}
{"op":"mcm","clk":"11810784115","pt":1722751578948,"mc":[{"id":"1.231395388","rc":[{"batb":[[0,2.14,10],[1,2.12,36.06],[2,1.81,36.34]],"ltp":2.22,"tv":30.42,"id":58385184}]}]}
{"op":"mcm","clk":"11810784183","pt":1722751582443,"mc":[{"id":"1.231395388","rc":[{"batb":[[0,2.12,36.06],[1,1.81,36.34],[2,1.25,100]],"ltp":2.22,"tv":30.42,"id":58385184}]}]}
{"op":"mcm","clk":"11810784215","pt":1722751584745,"mc":[{"id":"1.231395388","rc":[{"batb":[[0,2.14,10],[1,2.12,36.06],[2,1.81,36.34]],"ltp":2.22,"tv":30.42,"id":58385184}]}]}
{"op":"mcm","clk":"11810784289","pt":1722751588242,"mc":[{"id":"1.231395388","rc":[{"batb":[[0,2.12,36.06],[1,1.81,36.34],[2,1.25,100]],"ltp":2.22,"tv":30.42,"id":58385184}]}]}
{"op":"mcm","clk":"11810784374","pt":1722751591943,"mc":[{"id":"1.231395388","rc":[{"batb":[[0,2.14,10],[1,2.12,36.06],[2,1.81,36.34]],"ltp":2.22,"tv":30.42,"id":58385184}]}]}
{"op":"mcm","clk":"11810784424","pt":1722751595274,"mc":[{"id":"1.231395388","rc":[{"batb":[[0,2.12,36.06],[1,1.81,36.34],[2,1.25,100]],"ltp":2.22,"tv":30.42,"id":58385184}]}]}
{"op":"mcm","clk":"11810784484","pt":1722751598568,"mc":[{"id":"1.231395388","rc":[{"batb":[[0,2.14,10],[1,2.12,36.06],[2,1.81,36.34]],"ltp":2.22,"tv":30.42,"id":58385184}]}]}
{"op":"mcm","clk":"11810784532","pt":1722751602167,"mc":[{"id":"1.231395388","rc":[{"batb":[[0,2.12,36.06],[1,1.81,36.34],[2,1.25,100]],"ltp":2.22,"tv":30.42,"id":58385184}]}]}
{"op":"mcm","clk":"11810784553","pt":1722751604471,"mc":[{"id":"1.231395388","rc":[{"batb":[[0,2.14,10],[1,2.12,36.06],[2,1.81,36.34]],"ltp":2.22,"tv":30.42,"id":58385184}]}]}
{"op":"mcm","clk":"11810784603","pt":1722751607796,"mc":[{"id":"1.231395388","rc":[{"batb":[[0,2.12,36.06],[1,1.81,36.34],[2,1.25,100]],"ltp":2.22,"tv":30.42,"id":58385184}]}]}
{"op":"mcm","clk":"11810784729","pt":1722751613803,"mc":[{"id":"1.231395388","rc":[{"batb":[[0,2.14,10],[1,2.12,36.06],[2,1.81,36.34]],"ltp":2.22,"tv":30.42,"id":58385184}]}]}
{"op":"mcm","clk":"11810784805","pt":1722751617095,"mc":[{"id":"1.231395388","rc":[{"batb":[[0,2.12,36.06],[1,1.81,36.34],[2,1.25,100]],"ltp":2.22,"tv":30.42,"id":58385184}]}]}
{"op":"mcm","clk":"11810784874","pt":1722751620395,"mc":[{"id":"1.231395388","rc":[{"batb":[[0,2.14,10],[1,2.12,36.06],[2,1.81,36.34]],"ltp":2.22,"tv":30.42,"id":58385184}]}]}
{"op":"mcm","clk":"11810784919","pt":1722751623789,"mc":[{"id":"1.231395388","rc":[{"batb":[[0,2.12,36.06],[1,1.81,36.34],[2,1.25,100]],"ltp":2.22,"tv":30.42,"id":58385184}]}]}
{"op":"mcm","clk":"11810784956","pt":1722751626106,"mc":[{"id":"1.231395388","rc":[{"batb":[[0,2.14,10],[1,2.12,36.06],[2,1.81,36.34]],"ltp":2.22,"tv":30.42,"id":58385184}]}]}
{"op":"mcm","clk":"11810785008","pt":1722751629406,"mc":[{"id":"1.231395388","rc":[{"batb":[[0,2.12,36.06],[1,1.81,36.34],[2,1.25,100]],"ltp":2.22,"tv":30.42,"id":58385184}]}]}
{"op":"mcm","clk":"11810785058","pt":1722751632801,"mc":[{"id":"1.231395388","rc":[{"batb":[[0,2.14,10],[1,2.12,36.06],[2,1.81,36.34]],"ltp":2.22,"tv":30.42,"id":58385184}]}]}
{"op":"mcm","clk":"11810785110","pt":1722751636300,"mc":[{"id":"1.231395388","rc":[{"batb":[[0,2.12,36.06],[1,1.81,36.34],[2,1.25,100]],"ltp":2.22,"tv":30.42,"id":58385184}]}]}
{"op":"mcm","clk":"11810785151","pt":1722751638706,"mc":[{"id":"1.231395388","rc":[{"batb":[[0,2.14,10],[1,2.12,36.06],[2,1.81,36.34]],"ltp":2.22,"tv":30.42,"id":58385184}]}]}
{"op":"mcm","clk":"11810785212","pt":1722751642103,"mc":[{"id":"1.231395388","rc":[{"batb":[[0,2.12,36.06],[1,1.81,36.34],[2,1.25,100]],"ltp":2.22,"tv":30.42,"id":58385184}]}]}
{"op":"mcm","clk":"11810785263","pt":1722751644356,"mc":[{"id":"1.231395388","rc":[{"batb":[[0,2.14,10],[1,2.12,36.06],[2,1.81,36.34]],"ltp":2.22,"tv":30.42,"id":58385184}]}]}
{"op":"mcm","clk":"11810785329","pt":1722751647532,"mc":[{"id":"1.231395388","rc":[{"batb":[[0,2.12,36.06],[1,1.81,36.34],[2,1.25,100]],"ltp":2.22,"tv":30.42,"id":58385184}]}]}
{"op":"mcm","clk":"11810785376","pt":1722751650914,"mc":[{"id":"1.231395388","rc":[{"batb":[[0,2.14,10],[1,2.12,36.06],[2,1.81,36.34]],"ltp":2.22,"tv":30.42,"id":58385184}]}]}
{"op":"mcm","clk":"11810785439","pt":1722751654344,"mc":[{"id":"1.231395388","rc":[{"batb":[[0,2.12,36.06],[1,1.81,36.34],[2,1.25,100]],"ltp":2.22,"tv":30.42,"id":58385184}]}]}
{"op":"mcm","clk":"11810785461","pt":1722751656652,"mc":[{"id":"1.231395388","rc":[{"batb":[[0,2.14,10],[1,2.12,36.06],[2,1.81,36.34]],"ltp":2.22,"tv":30.42,"id":58385184}]}]}
{"op":"mcm","clk":"11810785489","pt":1722751659934,"mc":[{"id":"1.231395388","rc":[{"batb":[[0,2.12,36.06],[1,1.81,36.34],[2,1.25,100]],"ltp":2.22,"tv":30.42,"id":58385184}]}]}
{"op":"mcm","clk":"11810785537","pt":1722751664241,"mc":[{"id":"1.231395388","rc":[{"batb":[[0,2.14,10],[1,2.12,36.06],[2,1.81,36.34]],"ltp":2.22,"tv":30.42,"id":58385184}]}]}
{"op":"mcm","clk":"11810785590","pt":1722751667626,"mc":[{"id":"1.231395388","rc":[{"batb":[[0,2.12,36.06],[1,1.81,36.34],[2,1.25,100]],"ltp":2.22,"tv":30.42,"id":58385184}]}]}
{"op":"mcm","clk":"11810785646","pt":1722751670950,"mc":[{"id":"1.231395388","rc":[{"batb":[[0,2.14,10],[1,2.12,36.06],[2,1.81,36.34]],"ltp":2.22,"tv":30.42,"id":58385184}]}]}
{"op":"mcm","clk":"11810785698","pt":1722751674223,"mc":[{"id":"1.231395388","rc":[{"batb":[[0,2.12,36.06],[1,1.81,36.34],[2,1.25,100]],"ltp":2.22,"tv":30.42,"id":58385184}]}]}
{"op":"mcm","clk":"11810785757","pt":1722751677238,"mc":[{"id":"1.231395388","rc":[{"batb":[[0,2.14,10],[1,2.12,36.06],[2,1.81,36.34]],"ltp":2.22,"tv":30.42,"id":58385184}]}]}
{"op":"mcm","clk":"11810785814","pt":1722751680666,"mc":[{"id":"1.231395388","rc":[{"batb":[[0,2.12,36.06],[1,1.81,36.34],[2,1.25,100]],"ltp":2.22,"tv":30.42,"id":58385184}]}]}
{"op":"mcm","clk":"11810785849","pt":1722751682862,"mc":[{"id":"1.231395388","rc":[{"batb":[[0,2.14,10],[1,2.12,36.06],[2,1.81,36.34]],"ltp":2.22,"tv":30.42,"id":58385184}]}]}
{"op":"mcm","clk":"11810785932","pt":1722751686175,"mc":[{"id":"1.231395388","rc":[{"batb":[[0,2.12,36.06],[1,1.81,36.34],[2,1.25,100]],"ltp":2.22,"tv":30.42,"id":58385184}]}]}
{"op":"mcm","clk":"11810785960","pt":1722751688479,"mc":[{"id":"1.231395388","rc":[{"batb":[[0,2.14,10],[1,2.12,36.06],[2,1.81,36.34]],"ltp":2.22,"tv":30.42,"id":58385184}]}]}
{"op":"mcm","clk":"11810786029","pt":1722751691860,"mc":[{"id":"1.231395388","rc":[{"batb":[[0,2.12,36.06],[1,1.81,36.34],[2,1.25,100]],"ltp":2.22,"tv":30.42,"id":58385184}]}]}
{"op":"mcm","clk":"11810786079","pt":1722751695142,"mc":[{"id":"1.231395388","rc":[{"batb":[[0,2.14,10],[1,2.12,36.06],[2,1.81,36.34]],"ltp":2.22,"tv":30.42,"id":58385184}]}]}
{"op":"mcm","clk":"11810786151","pt":1722751698471,"mc":[{"id":"1.231395388","rc":[{"batb":[[0,2.12,36.06],[1,1.81,36.34],[2,1.25,100]],"ltp":2.22,"tv":30.42,"id":58385184}]}]}
{"op":"mcm","clk":"11810786226","pt":1722751702098,"mc":[{"id":"1.231395388","rc":[{"batb":[[0,2.14,10],[1,2.12,36.06],[2,1.81,36.34]],"ltp":2.22,"tv":30.42,"id":58385184}]}]}
{"op":"mcm","clk":"11810786277","pt":1722751705173,"mc":[{"id":"1.231395388","rc":[{"batb":[[0,2.12,36.06],[1,1.81,36.34],[2,1.25,100]],"ltp":2.22,"tv":30.42,"id":58385184}]}]}
{"op":"mcm","clk":"11810786352","pt":1722751708968,"mc":[{"id":"1.231395388","rc":[{"batb":[[0,2.14,10],[1,2.12,36.06],[2,1.81,36.34]],"ltp":2.22,"tv":30.42,"id":58385184}]}]}
{"op":"mcm","clk":"11810786399","pt":1722751712471,"mc":[{"id":"1.231395388","rc":[{"batb":[[0,2.12,36.06],[1,1.81,36.34],[2,1.25,100]],"ltp":2.22,"tv":30.42,"id":58385184}]}]}
{"op":"mcm","clk":"11810786456","pt":1722751715900,"mc":[{"id":"1.231395388","rc":[{"batb":[[0,2.14,10],[1,2.12,36.06],[2,1.81,36.34]],"ltp":2.22,"tv":30.42,"id":58385184}]}]}
{"op":"mcm","clk":"11810786528","pt":1722751719282,"mc":[{"id":"1.231395388","rc":[{"batb":[[0,2.12,36.06],[1,1.81,36.34],[2,1.25,100]],"ltp":2.22,"tv":30.42,"id":58385184}]}]}
{"op":"mcm","clk":"11810786578","pt":1722751722613,"mc":[{"id":"1.231395388","rc":[{"batb":[[0,2.14,10],[1,2.12,36.06],[2,1.81,36.34]],"ltp":2.22,"tv":30.42,"id":58385184}]}]}
{"op":"mcm","clk":"11810786621","pt":1722751725889,"mc":[{"id":"1.231395388","rc":[{"batb":[[0,2.12,36.06],[1,1.81,36.34],[2,1.25,100]],"ltp":2.22,"tv":30.42,"id":58385184}]}]}
{"op":"mcm","clk":"11810786671","pt":1722751728104,"mc":[{"id":"1.231395388","rc":[{"batb":[[0,2.14,10],[1,2.12,36.06],[2,1.81,36.34]],"ltp":2.22,"tv":30.42,"id":58385184}]}]}
{"op":"mcm","clk":"11810786727","pt":1722751731488,"mc":[{"id":"1.231395388","rc":[{"batb":[[0,2.12,36.06],[1,1.81,36.34],[2,1.25,100]],"ltp":2.22,"tv":30.42,"id":58385184}]}]}
{"op":"mcm","clk":"11810786772","pt":1722751733788,"mc":[{"id":"1.231395388","rc":[{"batb":[[0,2.14,10],[1,2.12,36.06],[2,1.81,36.34]],"ltp":2.22,"tv":30.42,"id":58385184}]}]}
{"op":"mcm","clk":"11810786829","pt":1722751737216,"mc":[{"id":"1.231395388","rc":[{"batb":[[0,2.12,36.06],[1,1.81,36.34],[2,1.25,100]],"ltp":2.22,"tv":30.42,"id":58385184}]}]}
{"op":"mcm","clk":"11810786882","pt":1722751740395,"mc":[{"id":"1.231395388","rc":[{"batb":[[0,2.14,10],[1,2.12,36.06],[2,1.81,36.34]],"ltp":2.22,"tv":30.42,"id":58385184}]}]}
{"op":"mcm","clk":"11810786937","pt":1722751743733,"mc":[{"id":"1.231395388","rc":[{"batb":[[0,2.12,36.06],[1,1.81,36.34],[2,1.25,100]],"ltp":2.22,"tv":30.42,"id":58385184}]}]}
{"op":"mcm","clk":"11810786988","pt":1722751746702,"mc":[{"id":"1.231395388","rc":[{"batb":[[0,2.14,10],[1,2.12,36.06],[2,1.81,36.34]],"ltp":2.22,"tv":30.42,"id":58385184}]}]}
{"op":"mcm","clk":"11810787044","pt":1722751750026,"mc":[{"id":"1.231395388","rc":[{"batb":[[0,2.12,36.06],[1,1.81,36.34],[2,1.25,100]],"ltp":2.22,"tv":30.42,"id":58385184}]}]}
{"op":"mcm","clk":"11810787084","pt":1722751752635,"mc":[{"id":"1.231395388","rc":[{"batb":[[0,2.14,10],[1,2.12,36.06],[2,1.81,36.34]],"ltp":2.22,"tv":30.42,"id":58385184}]}]}
{"op":"mcm","clk":"11810787138","pt":1722751756124,"mc":[{"id":"1.231395388","rc":[{"batb":[[0,2.12,36.06],[1,1.81,36.34],[2,1.25,100]],"ltp":2.22,"tv":30.42,"id":58385184}]}]}
{"op":"mcm","clk":"11810787185","pt":1722751759348,"mc":[{"id":"1.231395388","rc":[{"batb":[[0,2.14,10],[1,2.12,36.06],[2,1.81,36.34]],"ltp":2.22,"tv":30.42,"id":58385184}]}]}
{"op":"mcm","clk":"11810787237","pt":1722751762744,"mc":[{"id":"1.231395388","rc":[{"batb":[[0,2.12,36.06],[1,1.81,36.34],[2,1.25,100]],"ltp":2.22,"tv":30.42,"id":58385184}]}]}
{"op":"mcm","clk":"11810787285","pt":1722751766540,"mc":[{"id":"1.231395388","rc":[{"batb":[[0,2.14,10],[1,2.12,36.06],[2,1.81,36.34]],"ltp":2.22,"tv":30.42,"id":58385184}]}]}
{"op":"mcm","clk":"11810787359","pt":1722751769967,"mc":[{"id":"1.231395388","rc":[{"batb":[[0,2.12,36.06],[1,1.81,36.34],[2,1.25,100]],"ltp":2.22,"tv":30.42,"id":58385184}]}]}
{"op":"mcm","clk":"11810787415","pt":1722751773359,"mc":[{"id":"1.231395388","rc":[{"batb":[[0,2.14,10],[1,2.12,36.06],[2,1.81,36.34]],"ltp":2.22,"tv":30.42,"id":58385184}]}]}
{"op":"mcm","clk":"11810787469","pt":1722751776741,"mc":[{"id":"1.231395388","rc":[{"batb":[[0,2.12,36.06],[1,1.81,36.34],[2,1.25,100]],"ltp":2.22,"tv":30.42,"id":58385184}]}]}
{"op":"mcm","clk":"11810787503","pt":1722751779145,"mc":[{"id":"1.231395388","rc":[{"batb":[[0,2.14,10],[1,2.12,36.06],[2,1.81,36.34]],"ltp":2.22,"tv":30.42,"id":58385184}]}]}
{"op":"mcm","clk":"11810787561","pt":1722751782641,"mc":[{"id":"1.231395388","rc":[{"batb":[[0,2.12,36.06],[1,1.81,36.34],[2,1.25,100]],"ltp":2.22,"tv":30.42,"id":58385184}]}]}
{"op":"mcm","clk":"11810787590","pt":1722751784949,"mc":[{"id":"1.231395388","rc":[{"batb":[[0,2.14,10],[1,2.12,36.06],[2,1.81,36.34]],"ltp":2.22,"tv":30.42,"id":58385184}]}]}
{"op":"mcm","clk":"11810787639","pt":1722751788178,"mc":[{"id":"1.231395388","rc":[{"batb":[[0,2.12,36.06],[1,1.81,36.34],[2,1.25,100]],"ltp":2.22,"tv":30.42,"id":58385184}]}]}
{"op":"mcm","clk":"11810787708","pt":1722751791280,"mc":[{"id":"1.231395388","rc":[{"batb":[[0,2.14,10],[1,2.12,36.06],[2,1.81,36.34]],"ltp":2.22,"tv":30.42,"id":58385184}]}]}
{"op":"mcm","clk":"11810787756","pt":1722751794562,"mc":[{"id":"1.231395388","rc":[{"batb":[[0,2.12,36.06],[1,1.81,36.34],[2,1.25,100]],"ltp":2.22,"tv":30.42,"id":58385184}]}]}
{"op":"mcm","clk":"11810787797","pt":1722751797781,"mc":[{"id":"1.231395388","rc":[{"batb":[[0,2.14,10],[1,2.12,36.06],[2,1.81,36.34]],"ltp":2.22,"tv":30.42,"id":58385184}]}]}
{"op":"mcm","clk":"11810787863","pt":1722751801192,"mc":[{"id":"1.231395388","rc":[{"batb":[[0,2.12,36.06],[1,1.81,36.34],[2,1.25,100]],"ltp":2.22,"tv":30.42,"id":58385184}]}]}
{"op":"mcm","clk":"11810787931","pt":1722751804261,"mc":[{"id":"1.231395388","rc":[{"batb":[[0,2.14,10],[1,2.12,36.06],[2,1.81,36.34]],"ltp":2.22,"tv":30.42,"id":58385184}]}]}
{"op":"mcm","clk":"11810788014","pt":1722751807502,"mc":[{"id":"1.231395388","rc":[{"batb":[[0,2.12,36.06],[1,1.81,36.34],[2,1.25,100]],"ltp":2.22,"tv":30.42,"id":58385184}]}]}
{"op":"mcm","clk":"11810788077","pt":1722751809860,"mc":[{"id":"1.231395388","rc":[{"batb":[[0,2.14,10],[1,2.12,36.06],[2,1.81,36.34]],"ltp":2.22,"tv":30.42,"id":58385184}]}]}
{"op":"mcm","clk":"11810788179","pt":1722751813195,"mc":[{"id":"1.231395388","rc":[{"batb":[[0,2.12,36.06],[1,1.81,36.34],[2,1.25,100]],"ltp":2.22,"tv":30.42,"id":58385184}]}]}
{"op":"mcm","clk":"11810788309","pt":1722751819500,"mc":[{"id":"1.231395388","rc":[{"batb":[[0,2.14,10],[1,2.12,36.06],[2,1.81,36.34]],"ltp":2.22,"tv":30.42,"id":58385184}]}]}
{"op":"mcm","clk":"11810788389","pt":1722751822886,"mc":[{"id":"1.231395388","rc":[{"batb":[[0,2.12,36.06],[1,1.81,36.34],[2,1.25,100]],"ltp":2.22,"tv":30.42,"id":58385184}]}]}
{"op":"mcm","clk":"11810788542","pt":1722751829189,"mc":[{"id":"1.231395388","rc":[{"batb":[[0,2.14,10],[1,2.12,36.06],[2,1.81,36.34]],"ltp":2.22,"tv":30.42,"id":58385184}]}]}
{"op":"mcm","clk":"11810788614","pt":1722751832421,"mc":[{"id":"1.231395388","rc":[{"batb":[[0,2.12,36.06],[1,1.81,36.34],[2,1.25,100]],"ltp":2.22,"tv":30.42,"id":58385184}]}]}
{"op":"mcm","clk":"11810788664","pt":1722751835193,"mc":[{"id":"1.231395388","rc":[{"batb":[[0,2.14,10],[1,2.12,36.06],[2,1.81,36.34]],"ltp":2.22,"tv":30.42,"id":58385184}]}]}
{"op":"mcm","clk":"11810788714","pt":1722751838624,"mc":[{"id":"1.231395388","rc":[{"batb":[[0,2.12,36.06],[1,1.81,36.34],[2,1.25,100]],"ltp":2.22,"tv":30.42,"id":58385184}]}]}
{"op":"mcm","clk":"11810788757","pt":1722751840784,"mc":[{"id":"1.231395388","rc":[{"batb":[[0,2.14,10],[1,2.12,36.06],[2,1.81,36.34]],"ltp":2.22,"tv":30.42,"id":58385184}]}]}
